{"receive_ns":1788567705153082000,"stream":"btcusdt@depth@100ms","event_type":"depthUpdate","event_time_ms":1788567705171,"raw_json":"{\"stream\":\"btcusdt@depth@100ms\",\"data\":{\"e\":\"depthUpdate\",\"E\":1788567705171,\"T\":1788567705169,\"s\":\"BTCUSDT\",\"ps\":\"BTCUSDT\",\"U\":11478506760208,\"u\":11478506765416,\"pu\":11478506760109,\"b\":[[\"1000.00\",\"24.604\"],[\"29097.00\",\"0.441\"],[\"29197.00\",\"1.659\"],[\"63678.00\",\"0.000\"],[\"71637.30\",\"0.043\"],[\"78801.00\",\"11.280\"],[\"79543.10\",\"0.203\"],[\"79552.90\",\"0.001\"],[\"79578.60\",\"1.729\"],[\"79579.40\",\"0.000\"],[\"79589.90\",\"0.000\"],[\"79591.70\",\"0.081\"],[\"79597.00\",\"5.134\"]],\"a\":[[\"79598.20\",\"0.002\"],[\"79598.70\",\"0.256\"],[\"79598.80\",\"0.048\"],[\"79598.90\",\"0.044\"],[\"79599.00\",\"0.028\"],[\"79599.20\",\"0.092\"],[\"79600.40\",\"0.084\"],[\"79600.50\",\"0.002\"],[\"79607.50\",\"0.004\"],[\"79608.30\",\"0.019\"],[\"79610.60\",\"0.003\"],[\"79626.50\",\"4.523\"],[\"79692.10\",\"6.001\"],[\"79693.20\",\"0.002\"],[\"79701.80\",\"0.003\"],[\"79702.90\",\"0.001\"],[\"79804.90\",\"0.456\"],[\"79807.00\",\"5.019\"],[\"80393.10\",\"10.523\"],[\"81189.00\",\"10.512\"]],\"st\":1}}"}
{"receive_ns":1788567705239541000,"stream":"btcusdt@bookTicker","event_type":"bookTicker","event_time_ms":1788567705253,"raw_json":"{\"stream\":\"btcusdt@bookTicker\",\"data\":{\"e\":\"bookTicker\",\"u\":11478506769585,\"s\":\"BTCUSDT\",\"ps\":\"BTCUSDT\",\"b\":\"79597.00\",\"B\":\"5.113\",\"a\":\"79597.10\",\"A\":\"5.942\",\"T\":1788567705253,\"E\":1788567705253,\"st\":1}}"}
{"receive_ns":1788567705244969000,"stream":"btcusdt@bookTicker","event_type":"bookTicker","event_time_ms":1788567705256,"raw_json":"{\"stream\":\"btcusdt@bookTicker\",\"data\":{\"e\":\"bookTicker\",\"u\":11478506769726,\"s\":\"BTCUSDT\",\"ps\":\"BTCUSDT\",\"b\":\"79597.00\",\"B\":\"5.135\",\"a\":\"79597.10\",\"A\":\"5.942\",\"T\":1788567705255,\"E\":1788567705256,\"st\":1}}"}
{"receive_ns":1788567705259169000,"stream":"btcusdt@bookTicker","event_type":"bookTicker","event_time_ms":1788567705257,"raw_json":"{\"stream\":\"btcusdt@bookTicker\",\"data\":{\"e\":\"bookTicker\",\"u\":11478506769789,\"s\":\"BTCUSDT\",\"ps\":\"BTCUSDT\",\"b\":\"79597.00\",\"B\":\"5.136\",\"a\":\"79597.10\",\"A\":\"5.942\",\"T\":1788567705257,\"E\":1788567705257,\"st\":1}}"}
{"receive_ns":1788567705270342000,"stream":"btcusdt@depth@100ms","event_type":"depthUpdate","event_time_ms":1788567705273,"raw_json":"{\"stream\":\"btcusdt@depth@100ms\",\"data\":{\"e\":\"depthUpdate\",\"E\":1788567705273,\"T\":1788567705271,\"s\":\"BTCUSDT\",\"ps\":\"BTCUSDT\",\"U\":11478506765491,\"u\":11478506770508,\"pu\":11478506765416,\"b\":[[\"1000.00\",\"24.604\"],[\"29097.00\",\"0.616\"],[\"29197.00\",\"1.484\"],[\"71637.30\",\"0.043\"],[\"71673.00\",\"0.000\"],[\"76413.10\",\"0.000\"],[\"78482.60\",\"30.725\"],[\"78602.00\",\"14.115\"],[\"78641.80\",\"32.677\"],[\"78801.00\",\"11.280\"],[\"79561.80\",\"0.012\"],[\"79564.70\",\"0.678\"],[\"79564.80\",\"1.136\"],[\"79568.00\",\"0.005\"],[\"79597.00\",\"5.136\"]],\"a\":[[\"79598.80\",\"0.022\"],[\"79599.20\",\"0.016\"],[\"79640.20\",\"0.003\"],[\"79640.60\",\"0.163\"],[\"79643.90\",\"0.000\"],[\"79692.10\",\"6.002\"],[\"79702.90\",\"0.002\"],[\"80233.90\",\"6.842\"],[\"80313.60\",\"0.871\"],[\"80393.10\",\"10.523\"],[\"80552.30\",\"26.006\"],[\"80619.60\",\"0.000\"],[\"80711.50\",\"24.381\"]],\"st\":1}}"}
{"receive_ns":1788567705348974000,"stream":"btcusdt@bookTicker","event_type":"bookTicker","event_time_ms":1788567705359,"raw_json":"{\"stream\":\"btcusdt@bookTicker\",\"data\":{\"e\":\"bookTicker\",\"u\":11478506774285,\"s\":\"BTCUSDT\",\"ps\":\"BTCUSDT\",\"b\":\"79597.00\",\"B\":\"5.017\",\"a\":\"79597.10\",\"A\":\"5.942\",\"T\":1788567705359,\"E\":1788567705359,\"st\":1}}"}
{"receive_ns":1788567705356119000,"stream":"btcusdt@bookTicker","event_type":"bookTicker","event_time_ms":1788567705362,"raw_json":"{\"stream\":\"btcusdt@bookTicker\",\"data\":{\"e\":\"bookTicker\",\"u\":11478506774437,\"s\":\"BTCUSDT\",\"ps\":\"BTCUSDT\",\"b\":\"79597.00\",\"B\":\"5.141\",\"a\":\"79597.10\",\"A\":\"5.942\",\"T\":1788567705362,\"E\":1788567705362,\"st\":1}}"}
{"receive_ns":1788567705357498000,"stream":"btcusdt@depth@100ms","event_type":"depthUpdate","event_time_ms":1788567705375,"raw_json":"{\"stream\":\"btcusdt@depth@100ms\",\"data\":{\"e\":\"depthUpdate\",\"E\":1788567705375,\"T\":1788567705373,\"s\":\"BTCUSDT\",\"ps\":\"BTCUSDT\",\"U\":11478506770552,\"u\":11478506774819,\"pu\":11478506770508,\"b\":[[\"29097.00\",\"0.798\"],[\"29197.00\",\"1.302\"],[\"71637.30\",\"0.043\"],[\"76413.10\",\"0.002\"],[\"78801.00\",\"11.280\"],[\"79022.40\",\"0.258\"],[\"79196.60\",\"0.000\"],[\"79199.00\",\"3.678\"],[\"79199.90\",\"0.885\"],[\"79315.60\",\"0.000\"],[\"79316.00\",\"1.020\"],[\"79435.90\",\"1.765\"],[\"79475.30\",\"0.341\"],[\"79477.50\",\"0.000\"],[\"79506.70\",\"5.437\"],[\"79564.30\",\"0.125\"],[\"79564.80\",\"1.011\"],[\"79565.10\",\"0.858\"],[\"79597.00\",\"5.141\"]],\"a\":[[\"79688.10\",\"3.278\"],[\"79719.80\",\"0.360\"],[\"79759.20\",\"1.482\"],[\"79807.00\",\"1.798\"],[\"79818.80\",\"7.141\"],[\"79888.00\",\"25.426\"],[\"79889.20\",\"0.502\"],[\"80008.80\",\"1.102\"],[\"80008.90\",\"3.240\"],[\"80009.00\",\"0.017\"],[\"80185.00\",\"0.000\"],[\"80393.10\",\"10.523\"],[\"80687.60\",\"1.315\"],[\"80830.90\",\"5.190\"],[\"81045.60\",\"0.000\"],[\"81229.20\",\"0.000\"]],\"st\":1}}"}
{"receive_ns":1788567705378752000,"stream":"btcusdt@bookTicker","event_type":"bookTicker","event_time_ms":1788567705395,"raw_json":"{\"stream\":\"btcusdt@bookTicker\",\"data\":{\"e\":\"bookTicker\",\"u\":11478506775866,\"s\":\"BTCUSDT\",\"ps\":\"BTCUSDT\",\"b\":\"79597.00\",\"B\":\"5.141\",\"a\":\"79597.10\",\"A\":\"5.943\",\"T\":1788567705395,\"E\":1788567705395,\"st\":1}}"}
{"receive_ns":1788567705460392000,"stream":"btcusdt@depth@100ms","event_type":"depthUpdate","event_time_ms":1788567705477,"raw_json":"{\"stream\":\"btcusdt@depth@100ms\",\"data\":{\"e\":\"depthUpdate\",\"E\":1788567705477,\"T\":1788567705473,\"s\":\"BTCUSDT\",\"ps\":\"BTCUSDT\",\"U\":11478506774933,\"u\":11478506779339,\"pu\":11478506774819,\"b\":[[\"1000.00\",\"24.604\"],[\"29097.00\",\"0.973\"],[\"29197.00\",\"1.127\"],[\"71637.30\",\"0.043\"],[\"76413.10\",\"0.000\"],[\"78549.00\",\"0.000\"],[\"78628.50\",\"8.891\"],[\"78668.30\",\"4.546\"],[\"78721.40\",\"5.011\"],[\"78801.00\",\"11.280\"],[\"78809.10\",\"0.377\"],[\"79486.30\",\"0.035\"],[\"79563.70\",\"0.465\"],[\"79564.30\",\"0.000\"]],\"a\":[[\"79597.10\",\"5.943\"],[\"79598.70\",\"0.282\"],[\"79640.20\",\"0.128\"],[\"79640.60\",\"0.038\"],[\"79807.00\",\"5.019\"],[\"79995.10\",\"4.116\"],[\"80393.10\",\"10.523\"],[\"80401.50\",\"0.000\"],[\"80592.10\",\"9.144\"],[\"80666.80\",\"0.000\"],[\"80804.40\",\"5.562\"]],\"st\":1}}"}
{"receive_ns":1788567705491114000,"stream":"btcusdt@bookTicker","event_type":"bookTicker","event_time_ms":1788567705478,"raw_json":"{\"stream\":\"btcusdt@bookTicker\",\"data\":{\"e\":\"bookTicker\",\"u\":11478506779521,\"s\":\"BTCUSDT\",\"ps\":\"BTCUSDT\",\"b\":\"79597.00\",\"B\":\"5.107\",\"a\":\"79597.10\",\"A\":\"5.943\",\"T\":1788567705478,\"E\":1788567705478,\"st\":1}}"}
{"receive_ns":1788567705496671000,"stream":"btcusdt@bookTicker","event_type":"bookTicker","event_time_ms":1788567705482,"raw_json":"{\"stream\":\"btcusdt@bookTicker\",\"data\":{\"e\":\"bookTicker\",\"u\":11478506779721,\"s\":\"BTCUSDT\",\"ps\":\"BTCUSDT\",\"b\":\"79597.00\",\"B\":\"5.149\",\"a\":\"79597.10\",\"A\":\"5.943\",\"T\":1788567705481,\"E\":1788567705482,\"st\":1}}"}
{"receive_ns":1788567705539212000,"stream":"btcusdt@bookTicker","event_type":"bookTicker","event_time_ms":1788567705560,"raw_json":"{\"stream\":\"btcusdt@bookTicker\",\"data\":{\"e\":\"bookTicker\",\"u\":11478506783321,\"s\":\"BTCUSDT\",\"ps\":\"BTCUSDT\",\"b\":\"79597.00\",\"B\":\"5.149\",\"a\":\"79597.10\",\"A\":\"5.837\",\"T\":1788567705560,\"E\":1788567705560,\"st\":1}}"}
{"receive_ns":1788567705539771000,"stream":"btcusdt@bookTicker","event_type":"bookTicker","event_time_ms":1788567705560,"raw_json":"{\"stream\":\"btcusdt@bookTicker\",\"data\":{\"e\":\"bookTicker\",\"u\":11478506783333,\"s\":\"BTCUSDT\",\"ps\":\"BTCUSDT\",\"b\":\"79597.00\",\"B\":\"5.149\",\"a\":\"79597.10\",\"A\":\"4.538\",\"T\":1788567705560,\"E\":1788567705560,\"st\":1}}"}
{"receive_ns":1788567705540181000,"stream":"btcusdt@bookTicker","event_type":"bookTicker","event_time_ms":1788567705561,"raw_json":"{\"stream\":\"btcusdt@bookTicker\",\"data\":{\"e\":\"bookTicker\",\"u\":11478506783340,\"s\":\"BTCUSDT\",\"ps\":\"BTCUSDT\",\"b\":\"79597.00\",\"B\":\"5.149\",\"a\":\"79597.10\",\"A\":\"4.520\",\"T\":1788567705560,\"E\":1788567705561,\"st\":1}}"}
{"receive_ns":1788567705546505000,"stream":"btcusdt@bookTicker","event_type":"bookTicker","event_time_ms":1788567705561,"raw_json":"{\"stream\":\"btcusdt@bookTicker\",\"data\":{\"e\":\"bookTicker\",\"u\":11478506783355,\"s\":\"BTCUSDT\",\"ps\":\"BTCUSDT\",\"b\":\"79597.00\",\"B\":\"5.149\",\"a\":\"79597.10\",\"A\":\"4.504\",\"T\":1788567705561,\"E\":1788567705561,\"st\":1}}"}
{"receive_ns":1788567705558495000,"stream":"btcusdt@bookTicker","event_type":"bookTicker","event_time_ms":1788567705574,"raw_json":"{\"stream\":\"btcusdt@bookTicker\",\"data\":{\"e\":\"bookTicker\",\"u\":11478506783965,\"s\":\"BTCUSDT\",\"ps\":\"BTCUSDT\",\"b\":\"79597.00\",\"B\":\"5.149\",\"a\":\"79597.10\",\"A\":\"4.469\",\"T\":1788567705573,\"E\":1788567705574,\"st\":1}}"}
{"receive_ns":1788567705559113000,"stream":"btcusdt@bookTicker","event_type":"bookTicker","event_time_ms":1788567705576,"raw_json":"{\"stream\":\"btcusdt@bookTicker\",\"data\":{\"e\":\"bookTicker\",\"u\":11478506784069,\"s\":\"BTCUSDT\",\"ps\":\"BTCUSDT\",\"b\":\"79597.00\",\"B\":\"5.165\",\"a\":\"79597.10\",\"A\":\"4.469\",\"T\":1788567705576,\"E\":1788567705576,\"st\":1}}"}
{"receive_ns":1788567705559896000,"stream":"btcusdt@depth@100ms","event_type":"depthUpdate","event_time_ms":1788567705579,"raw_json":"{\"stream\":\"btcusdt@depth@100ms\",\"data\":{\"e\":\"depthUpdate\",\"E\":1788567705579,\"T\":1788567705578,\"s\":\"BTCUSDT\",\"ps\":\"BTCUSDT\",\"U\":11478506779502,\"u\":11478506784152,\"pu\":11478506779339,\"b\":[[\"1000.00\",\"24.604\"],[\"29097.00\",\"1.155\"],[\"29197.00\",\"0.945\"],[\"71637.30\",\"0.043\"],[\"76413.10\",\"0.002\"],[\"77354.60\",\"0.515\"],[\"78005.10\",\"10.706\"],[\"78243.90\",\"5.744\"],[\"78721.40\",\"5.201\"],[\"78801.00\",\"11.282\"],[\"78816.10\",\"3.240\"],[\"78888.10\",\"0.648\"],[\"79000.10\",\"0.212\"],[\"79022.50\",\"0.504\"],[\"79196.70\",\"0.344\"],[\"79199.00\",\"3.868\"],[\"79315.70\",\"0.000\"],[\"79558.50\",\"0.101\"],[\"79559.10\",\"2.478\"],[\"79563.40\",\"0.128\"],[\"79563.70\",\"0.340\"],[\"79569.40\",\"0.000\"],[\"79570.50\",\"0.454\"],[\"79571.60\",\"0.001\"],[\"79573.30\",\"0.441\"],[\"79575.70\",\"0.002\"],[\"79576.20\",\"0.247\"],[\"79577.00\",\"0.374\"],[\"79578.10\",\"0.005\"],[\"79592.40\",\"0.004\"],[\"79595.70\",\"0.103\"],[\"79597.00\",\"5.165\"]],\"a\":[[\"79597.10\",\"4.469\"],[\"79598.10\",\"0.000\"],[\"79598.50\",\"0.126\"],[\"79598.70\",\"0.030\"],[\"79598.80\",\"0.022\"],[\"79600.30\",\"0.002\"],[\"79601.10\",\"0.022\"],[\"79602.80\",\"0.078\"],[\"79605.20\",\"0.114\"],[\"79607.50\",\"0.003\"],[\"79608.50\",\"1.106\"],[\"79610.90\",\"0.003\"],[\"79611.60\",\"0.374\"],[\"79613.20\",\"0.005\"],[\"79617.30\",\"0.064\"],[\"79617.40\",\"0.003\"],[\"79618.00\",\"0.376\"],[\"79619.50\",\"0.711\"],[\"79622.20\",\"0.141\"],[\"79629.00\",\"0.319\"],[\"79640.00\",\"0.183\"],[\"79640.10\",\"1.300\"],[\"79640.20\",\"0.003\"],[\"79640.30\",\"0.000\"],[\"79818.80\",\"6.968\"],[\"80008.80\",\"0.021\"],[\"80008.90\",\"0.000\"],[\"80099.90\",\"10.726\"],[\"80300.10\",\"0.187\"],[\"80393.10\",\"10.298\"],[\"80486.00\",\"8.847\"],[\"80565.60\",\"6.820\"],[\"80642.00\",\"0.000\"],[\"80668.80\",\"0.498\"]],\"st\":1}}"}
{"receive_ns":1788567705562241000,"stream":"btcusdt@bookTicker","event_type":"bookTicker","event_time_ms":1788567705581,"raw_json":"{\"stream\":\"btcusdt@bookTicker\",\"data\":{\"e\":\"bookTicker\",\"u\":11478506784241,\"s\":\"BTCUSDT\",\"ps\":\"BTCUSDT\",\"b\":\"79597.00\",\"B\":\"5.164\",\"a\":\"79597.10\",\"A\":\"4.469\",\"T\":1788567705581,\"E\":1788567705581,\"st\":1}}"}
{"receive_ns":1788567705667303000,"stream":"btcusdt@depth@100ms","event_type":"depthUpdate","event_time_ms":1788567705681,"raw_json":"{\"stream\":\"btcusdt@depth@100ms\",\"data\":{\"e\":\"depthUpdate\",\"E\":1788567705681,\"T\":1788567705678,\"s\":\"BTCUSDT\",\"ps\":\"BTCUSDT\",\"U\":11478506784183,\"u\":11478506789963,\"pu\":11478506784152,\"b\":[[\"29097.00\",\"1.330\"],[\"29197.00\",\"0.770\"],[\"71637.30\",\"0.043\"],[\"78801.00\",\"11.280\"],[\"78865.90\",\"0.000\"],[\"79022.50\",\"76.536\"],[\"79196.70\",\"59.359\"],[\"79199.00\",\"3.858\"],[\"79199.90\",\"9.540\"],[\"79315.70\",\"48.037\"],[\"79316.00\",\"8.035\"],[\"79533.20\",\"1.111\"],[\"79597.00\",\"5.164\"]],\"a\":[[\"79597.80\",\"0.370\"],[\"79598.60\",\"0.027\"],[\"79600.20\",\"0.001\"],[\"79636.90\",\"0.066\"],[\"79640.00\",\"0.058\"],[\"79640.10\",\"1.300\"],[\"79640.20\",\"0.003\"],[\"79640.30\",\"0.000\"],[\"79886.70\",\"10.401\"],[\"79887.10\",\"47.036\"],[\"80006.90\",\"60.446\"],[\"80182.90\",\"73.478\"],[\"80393.10\",\"10.298\"]],\"st\":1}}"}
{"receive_ns":1788567705678255000,"stream":"btcusdt@bookTicker","event_type":"bookTicker","event_time_ms":1788567705683,"raw_json":"{\"stream\":\"btcusdt@bookTicker\",\"data\":{\"e\":\"bookTicker\",\"u\":11478506790461,\"s\":\"BTCUSDT\",\"ps\":\"BTCUSDT\",\"b\":\"79597.00\",\"B\":\"5.164\",\"a\":\"79597.10\",\"A\":\"4.468\",\"T\":1788567705683,\"E\":1788567705683,\"st\":1}}"}
{"receive_ns":1788567705772655000,"stream":"btcusdt@depth@100ms","event_type":"depthUpdate","event_time_ms":1788567705783,"raw_json":"{\"stream\":\"btcusdt@depth@100ms\",\"data\":{\"e\":\"depthUpdate\",\"E\":1788567705783,\"T\":1788567705781,\"s\":\"BTCUSDT\",\"ps\":\"BTCUSDT\",\"U\":11478506790362,\"u\":11478506795458,\"pu\":11478506789963,\"b\":[[\"1000.00\",\"24.604\"],[\"29097.00\",\"1.512\"],[\"29197.00\",\"0.588\"],[\"71637.30\",\"0.043\"],[\"76413.10\",\"0.000\"],[\"78243.90\",\"9.573\"],[\"78547.70\",\"0.000\"],[\"78641.80\",\"32.296\"],[\"78801.00\",\"11.280\"],[\"78809.10\",\"94.628\"],[\"78960.20\",\"7.497\"],[\"79506.70\",\"1.202\"],[\"79563.40\",\"0.003\"],[\"79565.40\",\"0.033\"]],\"a\":[[\"79597.10\",\"4.468\"],[\"79688.10\",\"0.024\"],[\"80393.10\",\"10.298\"],[\"80399.40\",\"93.261\"],[\"80724.80\",\"6.190\"]],\"st\":1}}"}
{"receive_ns":1788567705826264000,"stream":"btcusdt@bookTicker","event_type":"bookTicker","event_time_ms":1788567705843,"raw_json":"{\"stream\":\"btcusdt@bookTicker\",\"data\":{\"e\":\"bookTicker\",\"u\":11478506798512,\"s\":\"BTCUSDT\",\"ps\":\"BTCUSDT\",\"b\":\"79597.00\",\"B\":\"5.164\",\"a\":\"79597.10\",\"A\":\"4.466\",\"T\":1788567705843,\"E\":1788567705843,\"st\":1}}"}
{"receive_ns":1788567705870755000,"stream":"btcusdt@depth@100ms","event_type":"depthUpdate","event_time_ms":1788567705885,"raw_json":"{\"stream\":\"btcusdt@depth@100ms\",\"data\":{\"e\":\"depthUpdate\",\"E\":1788567705885,\"T\":1788567705881,\"s\":\"BTCUSDT\",\"ps\":\"BTCUSDT\",\"U\":11478506795565,\"u\":11478506800450,\"pu\":11478506795458,\"b\":[[\"1000.00\",\"24.604\"],[\"29097.00\",\"1.687\"],[\"29197.00\",\"0.413\"],[\"71637.30\",\"0.043\"],[\"76413.10\",\"0.002\"],[\"78628.50\",\"9.526\"],[\"78801.00\",\"11.280\"],[\"78816.10\",\"0.000\"],[\"78866.70\",\"9.601\"],[\"78888.10\",\"0.000\"],[\"79000.10\",\"0.050\"],[\"79022.60\",\"3.240\"],[\"79196.80\",\"0.648\"],[\"79315.80\",\"0.169\"],[\"79453.00\",\"0.600\"],[\"79453.10\",\"17.631\"],[\"79484.10\",\"0.033\"],[\"79506.70\",\"5.615\"],[\"79555.50\",\"1.254\"],[\"79558.70\",\"0.001\"],[\"79575.00\",\"0.058\"],[\"79582.00\",\"0.142\"],[\"79585.10\",\"0.001\"]],\"a\":[[\"79597.10\",\"4.466\"],[\"79597.80\",\"0.344\"],[\"79597.90\",\"0.030\"],[\"79609.60\",\"0.168\"],[\"79612.50\",\"0.002\"],[\"79623.00\",\"1.444\"],[\"79625.80\",\"0.199\"],[\"79688.10\",\"3.284\"],[\"79741.60\",\"17.676\"],[\"79741.80\",\"0.000\"],[\"79818.80\",\"6.963\"],[\"79887.00\",\"0.182\"],[\"79887.90\",\"0.301\"],[\"80006.80\",\"3.240\"],[\"80099.90\",\"7.486\"],[\"80393.10\",\"10.298\"],[\"80538.00\",\"9.048\"],[\"80751.30\",\"12.244\"]],\"st\":1}}"}
{"receive_ns":1788567705974384000,"stream":"btcusdt@depth@100ms","event_type":"depthUpdate","event_time_ms":1788567705987,"raw_json":"{\"stream\":\"btcusdt@depth@100ms\",\"data\":{\"e\":\"depthUpdate\",\"E\":1788567705987,\"T\":1788567705985,\"s\":\"BTCUSDT\",\"ps\":\"BTCUSDT\",\"U\":11478506800601,\"u\":11478506805578,\"pu\":11478506800450,\"b\":[[\"29097.00\",\"1.785\"],[\"29197.00\",\"0.273\"],[\"29497.00\",\"0.042\"],[\"63677.60\",\"0.000\"],[\"71637.30\",\"0.043\"],[\"75617.10\",\"0.018\"],[\"76413.10\",\"0.000\"],[\"78567.80\",\"0.008\"],[\"78583.20\",\"0.000\"],[\"78587.80\",\"0.013\"],[\"78603.20\",\"0.000\"],[\"78607.80\",\"0.005\"],[\"78616.60\",\"0.001\"],[\"78801.00\",\"11.280\"],[\"79199.00\",\"3.994\"],[\"79564.30\",\"0.125\"],[\"79589.70\",\"0.001\"]],\"a\":[[\"79597.70\",\"0.145\"],[\"79600.10\",\"0.002\"],[\"79995.10\",\"4.241\"],[\"80393.10\",\"10.298\"],[\"80552.30\",\"27.246\"],[\"80592.10\",\"9.330\"],[\"81045.20\",\"0.000\"]],\"st\":1}}"}
{"receive_ns":1788567706022873000,"stream":"btcusdt@bookTicker","event_type":"bookTicker","event_time_ms":1788567706039,"raw_json":"{\"stream\":\"btcusdt@bookTicker\",\"data\":{\"e\":\"bookTicker\",\"u\":11478506808360,\"s\":\"BTCUSDT\",\"ps\":\"BTCUSDT\",\"b\":\"79597.00\",\"B\":\"5.116\",\"a\":\"79597.10\",\"A\":\"4.466\",\"T\":1788567706038,\"E\":1788567706039,\"st\":1}}"}
{"receive_ns":1788567706028636000,"stream":"btcusdt@bookTicker","event_type":"bookTicker","event_time_ms":1788567706040,"raw_json":"{\"stream\":\"btcusdt@bookTicker\",\"data\":{\"e\":\"bookTicker\",\"u\":11478506808486,\"s\":\"BTCUSDT\",\"ps\":\"BTCUSDT\",\"b\":\"79597.00\",\"B\":\"5.164\",\"a\":\"79597.10\",\"A\":\"4.466\",\"T\":1788567706040,\"E\":1788567706040,\"st\":1}}"}
{"receive_ns":1788567706080070000,"stream":"btcusdt@depth@100ms","event_type":"depthUpdate","event_time_ms":1788567706089,"raw_json":"{\"stream\":\"btcusdt@depth@100ms\",\"data\":{\"e\":\"depthUpdate\",\"E\":1788567706089,\"T\":1788567706087,\"s\":\"BTCUSDT\",\"ps\":\"BTCUSDT\",\"U\":11478506805630,\"u\":11478506812130,\"pu\":11478506805578,\"b\":[[\"1000.00\",\"24.604\"],[\"29097.00\",\"1.848\"],[\"29197.00\",\"0.154\"],[\"29497.00\",\"0.098\"],[\"71202.30\",\"0.019\"],[\"71637.30\",\"0.043\"],[\"78548.90\",\"5.724\"],[\"78799.30\",\"3.418\"],[\"78801.00\",\"12.549\"],[\"79543.20\",\"0.852\"],[\"79559.10\",\"3.169\"],[\"79564.30\",\"0.000\"],[\"79564.60\",\"0.001\"],[\"79582.70\",\"0.204\"],[\"79597.00\",\"5.164\"]],\"a\":[[\"79597.30\",\"0.102\"],[\"79597.40\",\"0.002\"],[\"79597.60\",\"0.000\"],[\"79597.70\",\"0.171\"],[\"79597.90\",\"0.028\"],[\"79598.40\",\"0.001\"],[\"79610.60\",\"0.694\"],[\"79626.50\",\"5.352\"],[\"79640.10\",\"1.300\"],[\"79640.30\",\"0.000\"],[\"79995.10\",\"4.240\"],[\"80369.20\",\"1.973\"],[\"80393.10\",\"10.298\"],[\"80776.40\",\"0.010\"]],\"st\":1}}"}
{"receive_ns":1788567706139634000,"stream":"btcusdt@bookTicker","event_type":"bookTicker","event_time_ms":1788567706156,"raw_json":"{\"stream\":\"btcusdt@bookTicker\",\"data\":{\"e\":\"bookTicker\",\"u\":11478506817493,\"s\":\"BTCUSDT\",\"ps\":\"BTCUSDT\",\"b\":\"79597.00\",\"B\":\"5.138\",\"a\":\"79597.10\",\"A\":\"4.466\",\"T\":1788567706156,\"E\":1788567706156,\"st\":1}}"}
{"receive_ns":1788567706151446000,"stream":"btcusdt@bookTicker","event_type":"bookTicker","event_time_ms":1788567706157,"raw_json":"{\"stream\":\"btcusdt@bookTicker\",\"data\":{\"e\":\"bookTicker\",\"u\":11478506818024,\"s\":\"BTCUSDT\",\"ps\":\"BTCUSDT\",\"b\":\"79597.00\",\"B\":\"5.138\",\"a\":\"79597.10\",\"A\":\"4.467\",\"T\":1788567706157,\"E\":1788567706157,\"st\":1}}"}
{"receive_ns":1788567706157112000,"stream":"btcusdt@bookTicker","event_type":"bookTicker","event_time_ms":1788567706157,"raw_json":"{\"stream\":\"btcusdt@bookTicker\",\"data\":{\"e\":\"bookTicker\",\"u\":11478506818032,\"s\":\"BTCUSDT\",\"ps\":\"BTCUSDT\",\"b\":\"79597.00\",\"B\":\"5.138\",\"a\":\"79597.10\",\"A\":\"4.466\",\"T\":1788567706157,\"E\":1788567706157,\"st\":1}}"}
{"receive_ns":1788567706162063000,"stream":"btcusdt@bookTicker","event_type":"bookTicker","event_time_ms":1788567706160,"raw_json":"{\"stream\":\"btcusdt@bookTicker\",\"data\":{\"e\":\"bookTicker\",\"u\":11478506818789,\"s\":\"BTCUSDT\",\"ps\":\"BTCUSDT\",\"b\":\"79597.00\",\"B\":\"5.164\",\"a\":\"79597.10\",\"A\":\"4.466\",\"T\":1788567706160,\"E\":1788567706160,\"st\":1}}"}
{"receive_ns":1788567706179146000,"stream":"btcusdt@depth@100ms","event_type":"depthUpdate","event_time_ms":1788567706191,"raw_json":"{\"stream\":\"btcusdt@depth@100ms\",\"data\":{\"e\":\"depthUpdate\",\"E\":1788567706191,\"T\":1788567706189,\"s\":\"BTCUSDT\",\"ps\":\"BTCUSDT\",\"U\":11478506812234,\"u\":11478506820898,\"pu\":11478506812130,\"b\":[[\"1000.00\",\"24.604\"],[\"29097.00\",\"1.904\"],[\"29197.00\",\"0.035\"],[\"29497.00\",\"0.161\"],[\"71202.30\",\"0.000\"],[\"71637.30\",\"0.043\"],[\"76413.10\",\"0.002\"],[\"78005.10\",\"10.709\"],[\"78363.20\",\"9.430\"],[\"78469.30\",\"8.911\"],[\"78801.00\",\"12.547\"],[\"78960.20\",\"7.497\"],[\"79185.00\",\"0.631\"],[\"79199.00\",\"3.995\"],[\"79525.30\",\"0.635\"],[\"79541.20\",\"0.000\"],[\"79541.50\",\"0.170\"],[\"79562.70\",\"0.005\"],[\"79564.30\",\"0.125\"],[\"79573.30\",\"0.002\"],[\"79574.50\",\"0.629\"],[\"79574.60\",\"0.491\"],[\"79575.40\",\"0.017\"],[\"79596.80\",\"0.672\"],[\"79597.00\",\"5.164\"]],\"a\":[[\"79597.10\",\"4.466\"],[\"79597.30\",\"0.100\"],[\"79597.40\",\"0.000\"],[\"79597.60\",\"0.002\"],[\"79597.70\",\"0.145\"],[\"79597.90\",\"0.002\"],[\"79599.20\",\"0.042\"],[\"79599.80\",\"0.001\"],[\"79640.70\",\"0.125\"],[\"79668.80\",\"0.034\"],[\"79672.80\",\"0.001\"],[\"79691.90\",\"0.062\"],[\"80393.10\",\"10.298\"],[\"80798.00\",\"0.628\"]],\"st\":1}}"}
{"receive_ns":1788567706298506000,"stream":"btcusdt@depth@100ms","event_type":"depthUpdate","event_time_ms":1788567706293,"raw_json":"{\"stream\":\"btcusdt@depth@100ms\",\"data\":{\"e\":\"depthUpdate\",\"E\":1788567706293,\"T\":1788567706289,\"s\":\"BTCUSDT\",\"ps\":\"BTCUSDT\",\"U\":11478506821021,\"u\":11478506826377,\"pu\":11478506820898,\"b\":[[\"29097.00\",\"1.799\"],[\"29197.00\",\"0.000\"],[\"29497.00\",\"0.301\"],[\"71637.30\",\"0.043\"],[\"76413.10\",\"0.000\"],[\"78581.90\",\"0.732\"],[\"78624.30\",\"2.664\"],[\"78801.00\",\"12.547\"],[\"79199.00\",\"3.995\"],[\"79565.40\",\"0.027\"]],\"a\":[[\"79640.50\",\"0.141\"],[\"79640.70\",\"0.000\"],[\"79691.80\",\"0.124\"],[\"80393.10\",\"10.298\"],[\"80711.50\",\"25.000\"]],\"st\":1}}"}
{"receive_ns":1788567706325256000,"stream":"btcusdt@bookTicker","event_type":"bookTicker","event_time_ms":1788567706347,"raw_json":"{\"stream\":\"btcusdt@bookTicker\",\"data\":{\"e\":\"bookTicker\",\"u\":11478506828865,\"s\":\"BTCUSDT\",\"ps\":\"BTCUSDT\",\"b\":\"79597.00\",\"B\":\"5.129\",\"a\":\"79597.10\",\"A\":\"4.466\",\"T\":1788567706347,\"E\":1788567706347,\"st\":1}}"}
{"receive_ns":1788567706336607000,"stream":"btcusdt@bookTicker","event_type":"bookTicker","event_time_ms":1788567706350,"raw_json":"{\"stream\":\"btcusdt@bookTicker\",\"data\":{\"e\":\"bookTicker\",\"u\":11478506828973,\"s\":\"BTCUSDT\",\"ps\":\"BTCUSDT\",\"b\":\"79597.00\",\"B\":\"5.174\",\"a\":\"79597.10\",\"A\":\"4.466\",\"T\":1788567706350,\"E\":1788567706350,\"st\":1}}"}
{"receive_ns":1788567706351311000,"stream":"btcusdt@bookTicker","event_type":"bookTicker","event_time_ms":1788567706367,"raw_json":"{\"stream\":\"btcusdt@bookTicker\",\"data\":{\"e\":\"bookTicker\",\"u\":11478506829594,\"s\":\"BTCUSDT\",\"ps\":\"BTCUSDT\",\"b\":\"79597.00\",\"B\":\"5.050\",\"a\":\"79597.10\",\"A\":\"4.466\",\"T\":1788567706366,\"E\":1788567706367,\"st\":1}}"}
{"receive_ns":1788567706362474000,"stream":"btcusdt@bookTicker","event_type":"bookTicker","event_time_ms":1788567706369,"raw_json":"{\"stream\":\"btcusdt@bookTicker\",\"data\":{\"e\":\"bookTicker\",\"u\":11478506829720,\"s\":\"BTCUSDT\",\"ps\":\"BTCUSDT\",\"b\":\"79597.00\",\"B\":\"5.173\",\"a\":\"79597.10\",\"A\":\"4.466\",\"T\":1788567706369,\"E\":1788567706369,\"st\":1}}"}
{"receive_ns":1788567706389545000,"stream":"btcusdt@depth@100ms","event_type":"depthUpdate","event_time_ms":1788567706395,"raw_json":"{\"stream\":\"btcusdt@depth@100ms\",\"data\":{\"e\":\"depthUpdate\",\"E\":1788567706395,\"T\":1788567706394,\"s\":\"BTCUSDT\",\"ps\":\"BTCUSDT\",\"U\":11478506826509,\"u\":11478506830673,\"pu\":11478506826377,\"b\":[[\"1000.00\",\"24.604\"],[\"29097.00\",\"1.617\"],[\"29497.00\",\"0.483\"],[\"63678.00\",\"0.000\"],[\"71637.30\",\"0.043\"],[\"71673.00\",\"0.000\"],[\"75617.20\",\"0.004\"],[\"76413.10\",\"0.002\"],[\"78549.00\",\"114.347\"],[\"78801.00\",\"12.547\"],[\"78840.80\",\"8.828\"],[\"79435.90\",\"2.512\"],[\"79475.30\",\"0.466\"],[\"79506.70\",\"4.414\"],[\"79506.80\",\"1.879\"],[\"79541.20\",\"0.002\"],[\"79562.70\",\"0.003\"],[\"79564.10\",\"0.168\"],[\"79564.30\",\"0.000\"],[\"79591.20\",\"0.010\"],[\"79591.70\",\"0.079\"],[\"79597.00\",\"5.173\"]],\"a\":[[\"79597.20\",\"0.007\"],[\"79597.40\",\"0.002\"],[\"79597.50\",\"0.002\"],[\"79597.60\",\"0.000\"],[\"79598.80\",\"0.005\"],[\"79598.90\",\"0.027\"],[\"79692.70\",\"0.003\"],[\"79719.80\",\"0.463\"],[\"79759.20\",\"2.509\"],[\"79804.90\",\"1.087\"],[\"80006.50\",\"9.872\"],[\"80393.10\",\"10.298\"],[\"80552.30\",\"26.751\"],[\"80565.60\",\"7.440\"],[\"80664.70\",\"114.071\"],[\"80724.70\",\"3.828\"]],\"st\":1}}"}
{"receive_ns":1788567706396815000,"stream":"btcusdt@bookTicker","event_type":"bookTicker","event_time_ms":1788567706397,"raw_json":"{\"stream\":\"btcusdt@bookTicker\",\"data\":{\"e\":\"bookTicker\",\"u\":11478506830891,\"s\":\"BTCUSDT\",\"ps\":\"BTCUSDT\",\"b\":\"79597.00\",\"B\":\"5.151\",\"a\":\"79597.10\",\"A\":\"4.466\",\"T\":1788567706397,\"E\":1788567706397,\"st\":1}}"}
{"receive_ns":1788567706402865000,"stream":"btcusdt@bookTicker","event_type":"bookTicker","event_time_ms":1788567706400,"raw_json":"{\"stream\":\"btcusdt@bookTicker\",\"data\":{\"e\":\"bookTicker\",\"u\":11478506831106,\"s\":\"BTCUSDT\",\"ps\":\"BTCUSDT\",\"b\":\"79597.00\",\"B\":\"5.171\",\"a\":\"79597.10\",\"A\":\"4.466\",\"T\":1788567706400,\"E\":1788567706400,\"st\":1}}"}
{"receive_ns":1788567706485884000,"stream":"btcusdt@depth@100ms","event_type":"depthUpdate","event_time_ms":1788567706497,"raw_json":"{\"stream\":\"btcusdt@depth@100ms\",\"data\":{\"e\":\"depthUpdate\",\"E\":1788567706497,\"T\":1788567706494,\"s\":\"BTCUSDT\",\"ps\":\"BTCUSDT\",\"U\":11478506830753,\"u\":11478506836922,\"pu\":11478506830673,\"b\":[[\"1000.00\",\"24.604\"],[\"29097.00\",\"1.442\"],[\"29497.00\",\"0.658\"],[\"71637.30\",\"0.043\"],[\"76413.10\",\"0.000\"],[\"78665.70\",\"2.658\"],[\"78801.00\",\"12.547\"],[\"79199.00\",\"3.994\"],[\"79448.50\",\"0.032\"],[\"79468.00\",\"0.004\"],[\"79563.70\",\"0.465\"],[\"79563.90\",\"0.004\"],[\"79564.10\",\"0.043\"],[\"79597.00\",\"5.171\"]],\"a\":[[\"79597.30\",\"0.100\"],[\"79597.40\",\"0.000\"],[\"79597.50\",\"0.002\"],[\"79597.60\",\"0.002\"],[\"79598.70\",\"0.047\"],[\"79598.80\",\"0.023\"],[\"80393.10\",\"10.298\"]],\"st\":1}}"}
{"receive_ns":1788567706492354000,"stream":"btcusdt@bookTicker","event_type":"bookTicker","event_time_ms":1788567706503,"raw_json":"{\"stream\":\"btcusdt@bookTicker\",\"data\":{\"e\":\"bookTicker\",\"u\":11478506837582,\"s\":\"BTCUSDT\",\"ps\":\"BTCUSDT\",\"b\":\"79597.00\",\"B\":\"5.171\",\"a\":\"79597.10\",\"A\":\"4.469\",\"T\":1788567706503,\"E\":1788567706503,\"st\":1}}"}
{"receive_ns":1788567706512918000,"stream":"btcusdt@bookTicker","event_type":"bookTicker","event_time_ms":1788567706528,"raw_json":"{\"stream\":\"btcusdt@bookTicker\",\"data\":{\"e\":\"bookTicker\",\"u\":11478506839146,\"s\":\"BTCUSDT\",\"ps\":\"BTCUSDT\",\"b\":\"79597.00\",\"B\":\"5.129\",\"a\":\"79597.10\",\"A\":\"4.469\",\"T\":1788567706528,\"E\":1788567706528,\"st\":1}}"}
{"receive_ns":1788567706518846000,"stream":"btcusdt@bookTicker","event_type":"bookTicker","event_time_ms":1788567706531,"raw_json":"{\"stream\":\"btcusdt@bookTicker\",\"data\":{\"e\":\"bookTicker\",\"u\":11478506839298,\"s\":\"BTCUSDT\",\"ps\":\"BTCUSDT\",\"b\":\"79597.00\",\"B\":\"5.177\",\"a\":\"79597.10\",\"A\":\"4.469\",\"T\":1788567706531,\"E\":1788567706531,\"st\":1}}"}
{"receive_ns":1788567706565172000,"stream":"btcusdt@bookTicker","event_type":"bookTicker","event_time_ms":1788567706582,"raw_json":"{\"stream\":\"btcusdt@bookTicker\",\"data\":{\"e\":\"bookTicker\",\"u\":11478506841676,\"s\":\"BTCUSDT\",\"ps\":\"BTCUSDT\",\"b\":\"79597.00\",\"B\":\"5.178\",\"a\":\"79597.10\",\"A\":\"4.469\",\"T\":1788567706581,\"E\":1788567706582,\"st\":1}}"}
{"receive_ns":1788567706581936000,"stream":"btcusdt@depth@100ms","event_type":"depthUpdate","event_time_ms":1788567706599,"raw_json":"{\"stream\":\"btcusdt@depth@100ms\",\"data\":{\"e\":\"depthUpdate\",\"E\":1788567706599,\"T\":1788567706598,\"s\":\"BTCUSDT\",\"ps\":\"BTCUSDT\",\"U\":11478506837183,\"u\":11478506842664,\"pu\":11478506836922,\"b\":[[\"29097.00\",\"1.260\"],[\"29497.00\",\"0.840\"],[\"63678.00\",\"0.002\"],[\"71637.30\",\"0.043\"],[\"78542.10\",\"1.272\"],[\"78687.90\",\"5.236\"],[\"78801.00\",\"12.547\"],[\"79199.00\",\"3.994\"],[\"79484.10\",\"0.001\"],[\"79573.30\",\"0.000\"],[\"79597.00\",\"5.178\"]],\"a\":[[\"79597.10\",\"4.469\"],[\"79597.30\",\"0.100\"],[\"79597.40\",\"0.000\"],[\"79597.50\",\"0.215\"],[\"79599.60\",\"0.026\"],[\"79613.20\",\"0.003\"],[\"79617.00\",\"0.007\"],[\"79632.40\",\"1.142\"],[\"79723.70\",\"0.034\"],[\"79724.50\",\"2.532\"],[\"79995.10\",\"4.241\"],[\"80219.70\",\"1.352\"],[\"80393.10\",\"10.298\"],[\"80459.30\",\"0.000\"],[\"80552.30\",\"27.123\"]],\"st\":1}}"}
{"receive_ns":1788567706649398000,"stream":"btcusdt@bookTicker","event_type":"bookTicker","event_time_ms":1788567706666,"raw_json":"{\"stream\":\"btcusdt@bookTicker\",\"data\":{\"e\":\"bookTicker\",\"u\":11478506846343,\"s\":\"BTCUSDT\",\"ps\":\"BTCUSDT\",\"b\":\"79597.00\",\"B\":\"5.177\",\"a\":\"79597.10\",\"A\":\"4.469\",\"T\":1788567706666,\"E\":1788567706666,\"st\":1}}"}
{"receive_ns":1788567706679390000,"stream":"btcusdt@depth@100ms","event_type":"depthUpdate","event_time_ms":1788567706701,"raw_json":"{\"stream\":\"btcusdt@depth@100ms\",\"data\":{\"e\":\"depthUpdate\",\"E\":1788567706701,\"T\":1788567706699,\"s\":\"BTCUSDT\",\"ps\":\"BTCUSDT\",\"U\":11478506842679,\"u\":11478506848331,\"pu\":11478506842664,\"b\":[[\"1000.00\",\"24.604\"],[\"29097.00\",\"1.092\"],[\"29497.00\",\"1.008\"],[\"63678.00\",\"0.002\"],[\"71637.30\",\"0.043\"],[\"76413.10\",\"0.002\"],[\"78562.20\",\"8.295\"],[\"78567.80\",\"0.002\"],[\"78570.20\",\"0.010\"],[\"78587.80\",\"0.008\"],[\"78590.10\",\"0.006\"],[\"78607.80\",\"0.000\"],[\"78610.10\",\"0.004\"],[\"78641.80\",\"32.677\"],[\"78729.40\",\"6.269\"],[\"78801.00\",\"12.547\"],[\"78866.70\",\"8.525\"],[\"78960.20\",\"7.750\"],[\"79356.30\",\"0.004\"],[\"79367.50\",\"0.095\"],[\"79569.40\",\"0.000\"],[\"79570.50\",\"0.002\"],[\"79570.90\",\"0.454\"],[\"79573.30\",\"0.441\"],[\"79574.60\",\"0.052\"],[\"79576.20\",\"0.620\"],[\"79577.00\",\"0.001\"],[\"79597.00\",\"5.177\"]],\"a\":[[\"79597.40\",\"0.002\"],[\"79597.50\",\"0.213\"],[\"79598.60\",\"0.001\"],[\"79598.70\",\"0.021\"],[\"79599.70\",\"0.026\"],[\"79599.80\",\"0.027\"],[\"79610.40\",\"0.123\"],[\"79611.90\",\"0.440\"],[\"79613.20\",\"0.005\"],[\"79616.10\",\"0.009\"],[\"79617.20\",\"0.372\"],[\"79618.00\",\"0.004\"],[\"79619.30\",\"0.690\"],[\"79620.50\",\"0.452\"],[\"79620.60\",\"0.002\"],[\"79640.50\",\"0.016\"],[\"80233.90\",\"7.091\"],[\"80393.10\",\"10.298\"],[\"80488.40\",\"0.000\"],[\"80767.20\",\"8.956\"],[\"81189.00\",\"10.515\"]],\"st\":1}}"}
{"receive_ns":1788567706790946000,"stream":"btcusdt@depth@100ms","event_type":"depthUpdate","event_time_ms":1788567706803,"raw_json":"{\"stream\":\"btcusdt@depth@100ms\",\"data\":{\"e\":\"depthUpdate\",\"E\":1788567706803,\"T\":1788567706802,\"s\":\"BTCUSDT\",\"ps\":\"BTCUSDT\",\"U\":11478506848412,\"u\":11478506852078,\"pu\":11478506848331,\"b\":[[\"1000.00\",\"24.604\"],[\"29097.00\",\"0.903\"],[\"29497.00\",\"1.197\"],[\"63678.00\",\"0.000\"],[\"71637.30\",\"0.043\"],[\"76413.10\",\"0.000\"],[\"78482.60\",\"28.816\"],[\"78641.80\",\"31.407\"],[\"78801.00\",\"12.547\"],[\"79562.50\",\"1.893\"],[\"79563.70\",\"0.340\"],[\"79564.00\",\"0.005\"],[\"79564.20\",\"0.004\"],[\"79564.40\",\"0.362\"],[\"79567.70\",\"0.173\"],[\"79583.60\",\"1.468\"],[\"79587.00\",\"0.877\"]],\"a\":[[\"79598.90\",\"0.001\"],[\"79599.00\",\"0.002\"],[\"79599.20\",\"0.016\"],[\"79599.30\",\"0.018\"],[\"79599.50\",\"0.003\"],[\"79599.60\",\"0.000\"],[\"79599.70\",\"0.000\"],[\"79599.80\",\"0.027\"],[\"79599.90\",\"0.030\"],[\"79600.10\",\"0.028\"],[\"79600.20\",\"0.027\"],[\"79600.30\",\"0.028\"],[\"79600.40\",\"0.034\"],[\"79600.50\",\"0.028\"],[\"79600.60\",\"0.026\"],[\"79600.80\",\"0.035\"],[\"79633.20\",\"0.002\"],[\"79638.30\",\"0.001\"],[\"79640.00\",\"0.058\"],[\"79640.10\",\"1.425\"],[\"80393.10\",\"10.298\"]],\"st\":1}}"}
{"receive_ns":1788567706877472000,"stream":"btcusdt@bookTicker","event_type":"bookTicker","event_time_ms":1788567706894,"raw_json":"{\"stream\":\"btcusdt@bookTicker\",\"data\":{\"e\":\"bookTicker\",\"u\":11478506856349,\"s\":\"BTCUSDT\",\"ps\":\"BTCUSDT\",\"b\":\"79597.00\",\"B\":\"5.177\",\"a\":\"79597.10\",\"A\":\"4.468\",\"T\":1788567706894,\"E\":1788567706894,\"st\":1}}"}
{"receive_ns":1788567706878344000,"stream":"btcusdt@trade","event_type":"trade","event_time_ms":1788567706894,"raw_json":"{\"stream\":\"btcusdt@trade\",\"data\":{\"e\":\"trade\",\"E\":1788567706894,\"T\":1788567706894,\"s\":\"BTCUSDT\",\"t\":8054122545,\"p\":\"79597.10\",\"q\":\"0.001\",\"X\":\"MARKET\",\"m\":false,\"st\":1}}"}
{"receive_ns":1788567706884527000,"stream":"btcusdt@depth@100ms","event_type":"depthUpdate","event_time_ms":1788567706905,"raw_json":"{\"stream\":\"btcusdt@depth@100ms\",\"data\":{\"e\":\"depthUpdate\",\"E\":1788567706905,\"T\":1788567706901,\"s\":\"BTCUSDT\",\"ps\":\"BTCUSDT\",\"U\":11478506852164,\"u\":11478506856937,\"pu\":11478506852078,\"b\":[[\"29097.00\",\"0.728\"],[\"29497.00\",\"1.372\"],[\"63678.00\",\"0.004\"],[\"71637.30\",\"0.043\"],[\"76413.10\",\"0.002\"],[\"78687.90\",\"4.729\"],[\"78801.00\",\"12.547\"],[\"79199.00\",\"3.984\"],[\"79470.80\",\"0.475\"],[\"79471.00\",\"0.005\"],[\"79563.20\",\"0.135\"]],\"a\":[[\"79597.10\",\"4.468\"],[\"79829.00\",\"0.613\"],[\"79829.20\",\"0.028\"],[\"79995.10\",\"4.366\"],[\"80233.90\",\"6.842\"],[\"80393.10\",\"10.298\"],[\"80535.10\",\"4.597\"],[\"80620.80\",\"0.000\"],[\"80631.90\",\"4.263\"],[\"80645.20\",\"5.571\"],[\"83576.90\",\"0.047\"]],\"st\":1}}"}
{"receive_ns":1788567707012259000,"stream":"btcusdt@depth@100ms","event_type":"depthUpdate","event_time_ms":1788567707007,"raw_json":"{\"stream\":\"btcusdt@depth@100ms\",\"data\":{\"e\":\"depthUpdate\",\"E\":1788567707007,\"T\":1788567707005,\"s\":\"BTCUSDT\",\"ps\":\"BTCUSDT\",\"U\":11478506857102,\"u\":11478506862565,\"pu\":11478506856937,\"b\":[[\"1000.00\",\"24.604\"],[\"29097.00\",\"0.546\"],[\"29497.00\",\"1.554\"],[\"63677.60\",\"0.000\"],[\"63678.00\",\"0.000\"],[\"71637.30\",\"0.043\"],[\"78801.00\",\"12.547\"],[\"78960.20\",\"7.244\"],[\"79577.10\",\"0.060\"],[\"79596.80\",\"0.673\"]],\"a\":[[\"80393.10\",\"10.298\"],[\"80486.00\",\"8.414\"],[\"80631.90\",\"5.130\"],[\"80830.90\",\"6.055\"]],\"st\":1}}"}
{"receive_ns":1788567707023631000,"stream":"btcusdt@bookTicker","event_type":"bookTicker","event_time_ms":1788567707033,"raw_json":"{\"stream\":\"btcusdt@bookTicker\",\"data\":{\"e\":\"bookTicker\",\"u\":11478506863789,\"s\":\"BTCUSDT\",\"ps\":\"BTCUSDT\",\"b\":\"79597.00\",\"B\":\"5.177\",\"a\":\"79597.10\",\"A\":\"4.473\",\"T\":1788567707033,\"E\":1788567707033,\"st\":1}}"}
{"receive_ns":1788567707093768000,"stream":"btcusdt@depth@100ms","event_type":"depthUpdate","event_time_ms":1788567707109,"raw_json":"{\"stream\":\"btcusdt@depth@100ms\",\"data\":{\"e\":\"depthUpdate\",\"E\":1788567707109,\"T\":1788567707106,\"s\":\"BTCUSDT\",\"ps\":\"BTCUSDT\",\"U\":11478506862646,\"u\":11478506868504,\"pu\":11478506862565,\"b\":[[\"1000.00\",\"24.604\"],[\"29097.00\",\"0.371\"],[\"29497.00\",\"1.729\"],[\"63678.00\",\"0.000\"],[\"71637.30\",\"0.043\"],[\"75617.10\",\"0.016\"],[\"75617.20\",\"0.006\"],[\"76413.10\",\"0.000\"],[\"78729.40\",\"6.775\"],[\"78801.00\",\"12.547\"],[\"78866.30\",\"1.269\"],[\"78960.20\",\"7.749\"],[\"79435.90\",\"2.692\"],[\"79475.30\",\"0.497\"],[\"79582.70\",\"0.204\"]],\"a\":[[\"79597.10\",\"4.473\"],[\"79597.90\",\"0.020\"],[\"79599.20\",\"0.000\"],[\"79639.70\",\"0.172\"],[\"79640.10\",\"1.300\"],[\"79640.20\",\"0.003\"],[\"79719.80\",\"0.493\"],[\"79759.20\",\"2.656\"],[\"79980.90\",\"0.004\"],[\"80233.90\",\"7.091\"],[\"80393.10\",\"10.298\"],[\"80552.30\",\"28.363\"],[\"80711.50\",\"26.856\"],[\"81043.20\",\"4.943\"]],\"st\":1}}"}
{"receive_ns":1788567707118168000,"stream":"btcusdt@bookTicker","event_type":"bookTicker","event_time_ms":1788567707134,"raw_json":"{\"stream\":\"btcusdt@bookTicker\",\"data\":{\"e\":\"bookTicker\",\"u\":11478506869728,\"s\":\"BTCUSDT\",\"ps\":\"BTCUSDT\",\"b\":\"79597.00\",\"B\":\"5.177\",\"a\":\"79597.10\",\"A\":\"4.482\",\"T\":1788567707134,\"E\":1788567707134,\"st\":1}}"}
{"receive_ns":1788567707195800000,"stream":"btcusdt@depth@100ms","event_type":"depthUpdate","event_time_ms":1788567707211,"raw_json":"{\"stream\":\"btcusdt@depth@100ms\",\"data\":{\"e\":\"depthUpdate\",\"E\":1788567707211,\"T\":1788567707209,\"s\":\"BTCUSDT\",\"ps\":\"BTCUSDT\",\"U\":11478506868668,\"u\":11478506873406,\"pu\":11478506868504,\"b\":[[\"29097.00\",\"0.245\"],[\"29397.00\",\"0.056\"],[\"29497.00\",\"1.799\"],[\"71637.30\",\"0.043\"],[\"76413.10\",\"0.002\"],[\"78641.80\",\"32.042\"],[\"78801.00\",\"12.547\"],[\"79199.00\",\"3.983\"],[\"79476.10\",\"0.001\"],[\"79510.70\",\"0.013\"],[\"79583.60\",\"1.052\"],[\"79587.00\",\"0.717\"]],\"a\":[[\"79597.10\",\"4.482\"],[\"79599.10\",\"0.028\"],[\"79599.70\",\"0.026\"],[\"79600.80\",\"0.009\"],[\"79639.70\",\"0.047\"],[\"79640.60\",\"0.163\"],[\"79691.80\",\"0.123\"],[\"79691.90\",\"0.061\"],[\"79692.00\",\"2.253\"],[\"79692.10\",\"6.003\"],[\"79804.90\",\"0.456\"],[\"79807.00\",\"4.868\"],[\"79818.80\",\"7.083\"],[\"79995.10\",\"4.242\"],[\"80393.10\",\"10.298\"],[\"80528.40\",\"2.598\"]],\"st\":1}}"}
{"receive_ns":1788567707505878000,"stream":"btcusdt@depth@100ms","event_type":"depthUpdate","event_time_ms":1788567707313,"raw_json":"{\"stream\":\"btcusdt@depth@100ms\",\"data\":{\"e\":\"depthUpdate\",\"E\":1788567707313,\"T\":1788567707309,\"s\":\"BTCUSDT\",\"ps\":\"BTCUSDT\",\"U\":11478506873484,\"u\":11478506878812,\"pu\":11478506873406,\"b\":[[\"1000.00\",\"24.604\"],[\"29097.00\",\"0.126\"],[\"29397.00\",\"0.112\"],[\"29497.00\",\"1.862\"],[\"71637.30\",\"0.043\"],[\"76413.10\",\"0.000\"],[\"76413.20\",\"0.001\"],[\"77368.30\",\"2.064\"],[\"78641.80\",\"28.233\"],[\"78699.80\",\"0.500\"],[\"78799.30\",\"2.848\"],[\"78801.00\",\"12.547\"],[\"79570.50\",\"0.454\"],[\"79570.90\",\"0.002\"]],\"a\":[[\"79600.50\",\"0.104\"],[\"80300.10\",\"0.000\"],[\"80313.60\",\"1.058\"],[\"80393.10\",\"10.298\"],[\"80671.70\",\"9.611\"],[\"81081.40\",\"0.009\"]],\"st\":1}}"}
{"receive_ns":1788567707523778000,"stream":"btcusdt@bookTicker","event_type":"bookTicker","event_time_ms":1788567707355,"raw_json":"{\"stream\":\"btcusdt@bookTicker\",\"data\":{\"e\":\"bookTicker\",\"u\":11478506880787,\"s\":\"BTCUSDT\",\"ps\":\"BTCUSDT\",\"b\":\"79597.00\",\"B\":\"5.132\",\"a\":\"79597.10\",\"A\":\"4.482\",\"T\":1788567707355,\"E\":1788567707355,\"st\":1}}"}
{"receive_ns":1788567707529751000,"stream":"btcusdt@bookTicker","event_type":"bookTicker","event_time_ms":1788567707358,"raw_json":"{\"stream\":\"btcusdt@bookTicker\",\"data\":{\"e\":\"bookTicker\",\"u\":11478506880890,\"s\":\"BTCUSDT\",\"ps\":\"BTCUSDT\",\"b\":\"79597.00\",\"B\":\"5.180\",\"a\":\"79597.10\",\"A\":\"4.482\",\"T\":1788567707358,\"E\":1788567707358,\"st\":1}}"}
{"receive_ns":1788567707535623000,"stream":"btcusdt@depth@100ms","event_type":"depthUpdate","event_time_ms":1788567707415,"raw_json":"{\"stream\":\"btcusdt@depth@100ms\",\"data\":{\"e\":\"depthUpdate\",\"E\":1788567707415,\"T\":1788567707414,\"s\":\"BTCUSDT\",\"ps\":\"BTCUSDT\",\"U\":11478506879028,\"u\":11478506885736,\"pu\":11478506878812,\"b\":[[\"1000.00\",\"24.604\"],[\"29097.00\",\"0.014\"],[\"29397.00\",\"0.182\"],[\"29497.00\",\"1.904\"],[\"71637.30\",\"0.043\"],[\"71673.00\",\"0.000\"],[\"75617.20\",\"0.004\"],[\"76413.10\",\"0.002\"],[\"78562.20\",\"9.185\"],[\"78801.00\",\"12.547\"],[\"78880.60\",\"3.922\"],[\"79000.00\",\"43.440\"],[\"79199.00\",\"4.109\"],[\"79597.00\",\"5.180\"]],\"a\":[[\"79598.90\",\"0.027\"],[\"79599.10\",\"0.002\"],[\"79600.60\",\"0.000\"],[\"79804.90\",\"1.065\"],[\"80009.80\",\"0.590\"],[\"80393.10\",\"10.298\"],[\"81811.30\",\"0.244\"]],\"st\":1}}"}
{"receive_ns":1788567707538626000,"stream":"btcusdt@depth@100ms","event_type":"depthUpdate","event_time_ms":1788567707517,"raw_json":"{\"stream\":\"btcusdt@depth@100ms\",\"data\":{\"e\":\"depthUpdate\",\"E\":1788567707517,\"T\":1788567707515,\"s\":\"BTCUSDT\",\"ps\":\"BTCUSDT\",\"U\":11478506885890,\"u\":11478506891440,\"pu\":11478506885736,\"b\":[[\"29097.00\",\"0.000\"],[\"29397.00\",\"0.343\"],[\"29497.00\",\"1.757\"],[\"71637.30\",\"0.043\"],[\"78363.20\",\"8.538\"],[\"78442.80\",\"11.568\"],[\"78621.70\",\"0.636\"],[\"78641.80\",\"31.280\"],[\"78681.60\",\"8.001\"],[\"78801.00\",\"12.547\"],[\"78866.70\",\"7.639\"],[\"79199.00\",\"3.994\"],[\"79501.40\",\"0.048\"],[\"79525.30\",\"0.633\"],[\"79541.20\",\"0.000\"]],\"a\":[[\"79597.80\",\"0.361\"],[\"79598.60\",\"0.027\"],[\"79598.80\",\"0.005\"],[\"79668.80\",\"0.034\"],[\"79692.70\",\"0.001\"],[\"79995.10\",\"4.241\"],[\"80393.10\",\"10.298\"],[\"80607.80\",\"0.001\"],[\"80697.20\",\"9.481\"],[\"87556.90\",\"0.000\"]],\"st\":1}}"}
{"receive_ns":1788567707605090000,"stream":"btcusdt@depth@100ms","event_type":"depthUpdate","event_time_ms":1788567707619,"raw_json":"{\"stream\":\"btcusdt@depth@100ms\",\"data\":{\"e\":\"depthUpdate\",\"E\":1788567707619,\"T\":1788567707618,\"s\":\"BTCUSDT\",\"ps\":\"BTCUSDT\",\"U\":11478506891530,\"u\":11478506898551,\"pu\":11478506891440,\"b\":[[\"1000.00\",\"24.604\"],[\"29397.00\",\"0.525\"],[\"29497.00\",\"1.575\"],[\"63678.00\",\"0.000\"],[\"71202.30\",\"0.000\"],[\"71637.30\",\"0.043\"],[\"76413.10\",\"0.000\"],[\"78624.30\",\"2.220\"],[\"78801.00\",\"12.547\"],[\"78880.60\",\"4.112\"],[\"79126.00\",\"0.000\"],[\"79142.30\",\"0.001\"],[\"79176.00\",\"0.070\"],[\"79199.40\",\"0.006\"],[\"79367.40\",\"1.442\"],[\"79390.80\",\"0.052\"],[\"79416.60\",\"0.000\"],[\"79423.40\",\"0.010\"],[\"79440.00\",\"0.261\"],[\"79542.30\",\"0.060\"],[\"79550.40\",\"0.002\"],[\"79573.30\",\"0.439\"]],\"a\":[[\"79598.60\",\"0.001\"],[\"79598.90\",\"0.001\"],[\"79613.20\",\"0.003\"],[\"79640.20\",\"0.128\"],[\"79640.60\",\"0.038\"],[\"79807.00\",\"2.776\"],[\"80393.10\",\"10.298\"],[\"81189.00\",\"10.518\"]],\"st\":1}}"}
{"receive_ns":1788567707626400000,"stream":"btcusdt@bookTicker","event_type":"bookTicker","event_time_ms":1788567707649,"raw_json":"{\"stream\":\"btcusdt@bookTicker\",\"data\":{\"e\":\"bookTicker\",\"u\":11478506900942,\"s\":\"BTCUSDT\",\"ps\":\"BTCUSDT\",\"b\":\"79597.00\",\"B\":\"4.381\",\"a\":\"79597.10\",\"A\":\"4.482\",\"T\":1788567707649,\"E\":1788567707649,\"st\":1}}"}
{"receive_ns":1788567707642317000,"stream":"btcusdt@bookTicker","event_type":"bookTicker","event_time_ms":1788567707658,"raw_json":"{\"stream\":\"btcusdt@bookTicker\",\"data\":{\"e\":\"bookTicker\",\"u\":11478506901701,\"s\":\"BTCUSDT\",\"ps\":\"BTCUSDT\",\"b\":\"79597.00\",\"B\":\"5.176\",\"a\":\"79597.10\",\"A\":\"4.482\",\"T\":1788567707658,\"E\":1788567707658,\"st\":1}}"}
{"receive_ns":1788567707665096000,"stream":"btcusdt@bookTicker","event_type":"bookTicker","event_time_ms":1788567707660,"raw_json":"{\"stream\":\"btcusdt@bookTicker\",\"data\":{\"e\":\"bookTicker\",\"u\":11478506901886,\"s\":\"BTCUSDT\",\"ps\":\"BTCUSDT\",\"b\":\"79597.00\",\"B\":\"5.175\",\"a\":\"79597.10\",\"A\":\"4.482\",\"T\":1788567707659,\"E\":1788567707660,\"st\":1}}"}
{"receive_ns":1788567707670510000,"stream":"btcusdt@bookTicker","event_type":"bookTicker","event_time_ms":1788567707660,"raw_json":"{\"stream\":\"btcusdt@bookTicker\",\"data\":{\"e\":\"bookTicker\",\"u\":11478506901891,\"s\":\"BTCUSDT\",\"ps\":\"BTCUSDT\",\"b\":\"79597.00\",\"B\":\"5.174\",\"a\":\"79597.10\",\"A\":\"4.482\",\"T\":1788567707659,\"E\":1788567707660,\"st\":1}}"}
{"receive_ns":1788567707678163000,"stream":"btcusdt@bookTicker","event_type":"bookTicker","event_time_ms":1788567707661,"raw_json":"{\"stream\":\"btcusdt@bookTicker\",\"data\":{\"e\":\"bookTicker\",\"u\":11478506902080,\"s\":\"BTCUSDT\",\"ps\":\"BTCUSDT\",\"b\":\"79597.00\",\"B\":\"5.175\",\"a\":\"79597.10\",\"A\":\"4.482\",\"T\":1788567707661,\"E\":1788567707661,\"st\":1}}"}
{"receive_ns":1788567707700265000,"stream":"btcusdt@depth@100ms","event_type":"depthUpdate","event_time_ms":1788567707721,"raw_json":"{\"stream\":\"btcusdt@depth@100ms\",\"data\":{\"e\":\"depthUpdate\",\"E\":1788567707721,\"T\":1788567707717,\"s\":\"BTCUSDT\",\"ps\":\"BTCUSDT\",\"U\":11478506898590,\"u\":11478506905865,\"pu\":11478506898551,\"b\":[[\"1000.00\",\"24.604\"],[\"29397.00\",\"0.700\"],[\"29497.00\",\"1.400\"],[\"71637.30\",\"0.043\"],[\"76413.10\",\"0.002\"],[\"78570.20\",\"0.005\"],[\"78572.60\",\"0.018\"],[\"78590.10\",\"0.000\"],[\"78592.40\",\"0.008\"],[\"78624.30\",\"1.776\"],[\"78641.80\",\"32.041\"],[\"78801.00\",\"12.547\"],[\"79199.00\",\"3.995\"],[\"79526.50\",\"0.004\"],[\"79542.50\",\"0.017\"],[\"79543.20\",\"0.023\"],[\"79559.10\",\"2.478\"],[\"79562.50\",\"1.891\"],[\"79562.70\",\"0.001\"],[\"79573.30\",\"0.002\"],[\"79574.60\",\"0.491\"],[\"79589.90\",\"0.000\"],[\"79591.20\",\"0.008\"],[\"79591.70\",\"0.081\"],[\"79592.30\",\"0.002\"],[\"79592.40\",\"0.002\"],[\"79597.00\",\"5.175\"]],\"a\":[[\"79599.70\",\"0.000\"],[\"79600.50\",\"0.104\"],[\"79600.60\",\"0.026\"],[\"79610.60\",\"0.003\"],[\"79613.20\",\"0.005\"],[\"79626.50\",\"4.523\"],[\"79640.20\",\"0.003\"],[\"79640.70\",\"0.000\"],[\"79640.80\",\"0.327\"],[\"79657.10\",\"0.314\"],[\"79665.90\",\"0.000\"],[\"79806.90\",\"5.018\"],[\"79807.00\",\"0.001\"],[\"79818.80\",\"7.082\"],[\"80393.10\",\"10.298\"],[\"80552.30\",\"28.364\"],[\"80751.30\",\"13.110\"],[\"81043.10\",\"3.942\"],[\"83700.00\",\"7.563\"]],\"st\":1}}"}
{"receive_ns":1788567707749337000,"stream":"btcusdt@bookTicker","event_type":"bookTicker","event_time_ms":1788567707760,"raw_json":"{\"stream\":\"btcusdt@bookTicker\",\"data\":{\"e\":\"bookTicker\",\"u\":11478506908432,\"s\":\"BTCUSDT\",\"ps\":\"BTCUSDT\",\"b\":\"79597.00\",\"B\":\"5.163\",\"a\":\"79597.10\",\"A\":\"4.482\",\"T\":1788567707760,\"E\":1788567707760,\"st\":1}}"}
{"receive_ns":1788567707806889000,"stream":"btcusdt@depth@100ms","event_type":"depthUpdate","event_time_ms":1788567707823,"raw_json":"{\"stream\":\"btcusdt@depth@100ms\",\"data\":{\"e\":\"depthUpdate\",\"E\":1788567707823,\"T\":1788567707822,\"s\":\"BTCUSDT\",\"ps\":\"BTCUSDT\",\"U\":11478506906136,\"u\":11478506911749,\"pu\":11478506905865,\"b\":[[\"29397.00\",\"0.882\"],[\"29497.00\",\"1.218\"],[\"71637.30\",\"0.043\"],[\"76413.10\",\"0.000\"],[\"78005.10\",\"10.706\"],[\"78588.10\",\"8.680\"],[\"78665.70\",\"3.101\"],[\"78801.00\",\"12.547\"],[\"78946.20\",\"1.264\"],[\"79199.00\",\"3.995\"],[\"79449.10\",\"0.000\"],[\"79597.00\",\"5.163\"]],\"a\":[[\"80001.00\",\"0.028\"],[\"80393.10\",\"10.298\"],[\"80791.50\",\"0.062\"]],\"st\":1}}"}
{"receive_ns":1788567707861382000,"stream":"btcusdt@bookTicker","event_type":"bookTicker","event_time_ms":1788567707874,"raw_json":"{\"stream\":\"btcusdt@bookTicker\",\"data\":{\"e\":\"bookTicker\",\"u\":11478506914317,\"s\":\"BTCUSDT\",\"ps\":\"BTCUSDT\",\"b\":\"79597.00\",\"B\":\"5.107\",\"a\":\"79597.10\",\"A\":\"4.482\",\"T\":1788567707874,\"E\":1788567707874,\"st\":1}}"}
{"receive_ns":1788567707873056000,"stream":"btcusdt@bookTicker","event_type":"bookTicker","event_time_ms":1788567707878,"raw_json":"{\"stream\":\"btcusdt@bookTicker\",\"data\":{\"e\":\"bookTicker\",\"u\":11478506914511,\"s\":\"BTCUSDT\",\"ps\":\"BTCUSDT\",\"b\":\"79597.00\",\"B\":\"5.162\",\"a\":\"79597.10\",\"A\":\"4.482\",\"T\":1788567707877,\"E\":1788567707878,\"st\":1}}"}
{"receive_ns":1788567707883652000,"stream":"btcusdt@bookTicker","event_type":"bookTicker","event_time_ms":1788567707879,"raw_json":"{\"stream\":\"btcusdt@bookTicker\",\"data\":{\"e\":\"bookTicker\",\"u\":11478506914567,\"s\":\"BTCUSDT\",\"ps\":\"BTCUSDT\",\"b\":\"79597.00\",\"B\":\"5.163\",\"a\":\"79597.10\",\"A\":\"4.482\",\"T\":1788567707878,\"E\":1788567707879,\"st\":1}}"}
{"receive_ns":1788567707911361000,"stream":"btcusdt@depth@100ms","event_type":"depthUpdate","event_time_ms":1788567707925,"raw_json":"{\"stream\":\"btcusdt@depth@100ms\",\"data\":{\"e\":\"depthUpdate\",\"E\":1788567707925,\"T\":1788567707923,\"s\":\"BTCUSDT\",\"ps\":\"BTCUSDT\",\"U\":11478506911806,\"u\":11478506916660,\"pu\":11478506911749,\"b\":[[\"1000.00\",\"24.754\"],[\"29397.00\",\"1.057\"],[\"29497.00\",\"1.043\"],[\"63678.00\",\"0.000\"],[\"71637.30\",\"0.043\"],[\"78514.70\",\"3.261\"],[\"78588.70\",\"5.720\"],[\"78665.70\",\"3.544\"],[\"78801.00\",\"12.547\"],[\"79199.00\",\"4.121\"],[\"79475.30\",\"0.001\"],[\"79597.00\",\"5.163\"]],\"a\":[[\"79598.70\",\"0.004\"],[\"79617.30\",\"0.064\"],[\"79719.80\",\"0.000\"],[\"80160.40\",\"0.000\"],[\"80393.10\",\"10.298\"],[\"80552.30\",\"28.983\"],[\"80804.40\",\"6.180\"]],\"st\":1}}"}
{"receive_ns":1788567708009258000,"stream":"btcusdt@depth@100ms","event_type":"depthUpdate","event_time_ms":1788567708027,"raw_json":"{\"stream\":\"btcusdt@depth@100ms\",\"data\":{\"e\":\"depthUpdate\",\"E\":1788567708027,\"T\":1788567708026,\"s\":\"BTCUSDT\",\"ps\":\"BTCUSDT\",\"U\":11478506916789,\"u\":11478506921885,\"pu\":11478506916660,\"b\":[[\"1000.00\",\"24.604\"],[\"29397.00\",\"1.239\"],[\"29497.00\",\"0.861\"],[\"63677.60\",\"0.000\"],[\"63678.00\",\"0.000\"],[\"71637.30\",\"0.043\"],[\"76413.10\",\"0.002\"],[\"78452.80\",\"0.612\"],[\"78801.00\",\"12.547\"],[\"79361.80\",\"0.617\"],[\"79400.10\",\"0.443\"],[\"79475.30\",\"0.479\"]],\"a\":[[\"79719.80\",\"0.476\"],[\"80319.80\",\"0.001\"],[\"80393.10\",\"10.298\"],[\"80479.20\",\"0.625\"],[\"80577.80\",\"5.234\"],[\"80697.20\",\"9.233\"]],\"st\":1}}"}
{"receive_ns":1788567708024256000,"stream":"btcusdt@bookTicker","event_type":"bookTicker","event_time_ms":1788567708038,"raw_json":"{\"stream\":\"btcusdt@bookTicker\",\"data\":{\"e\":\"bookTicker\",\"u\":11478506922863,\"s\":\"BTCUSDT\",\"ps\":\"BTCUSDT\",\"b\":\"79597.00\",\"B\":\"5.115\",\"a\":\"79597.10\",\"A\":\"4.482\",\"T\":1788567708038,\"E\":1788567708038,\"st\":1}}"}
{"receive_ns":1788567708028085000,"stream":"btcusdt@bookTicker","event_type":"bookTicker","event_time_ms":1788567708040,"raw_json":"{\"stream\":\"btcusdt@bookTicker\",\"data\":{\"e\":\"bookTicker\",\"u\":11478506923038,\"s\":\"BTCUSDT\",\"ps\":\"BTCUSDT\",\"b\":\"79597.00\",\"B\":\"5.163\",\"a\":\"79597.10\",\"A\":\"4.482\",\"T\":1788567708040,\"E\":1788567708040,\"st\":1}}"}
{"receive_ns":1788567708033789000,"stream":"btcusdt@bookTicker","event_type":"bookTicker","event_time_ms":1788567708041,"raw_json":"{\"stream\":\"btcusdt@bookTicker\",\"data\":{\"e\":\"bookTicker\",\"u\":11478506923125,\"s\":\"BTCUSDT\",\"ps\":\"BTCUSDT\",\"b\":\"79597.00\",\"B\":\"5.115\",\"a\":\"79597.10\",\"A\":\"4.482\",\"T\":1788567708041,\"E\":1788567708041,\"st\":1}}"}
{"receive_ns":1788567708040489000,"stream":"btcusdt@bookTicker","event_type":"bookTicker","event_time_ms":1788567708050,"raw_json":"{\"stream\":\"btcusdt@bookTicker\",\"data\":{\"e\":\"bookTicker\",\"u\":11478506923476,\"s\":\"BTCUSDT\",\"ps\":\"BTCUSDT\",\"b\":\"79597.00\",\"B\":\"5.167\",\"a\":\"79597.10\",\"A\":\"4.482\",\"T\":1788567708049,\"E\":1788567708050,\"st\":1}}"}
{"receive_ns":1788567708045914000,"stream":"btcusdt@bookTicker","event_type":"bookTicker","event_time_ms":1788567708057,"raw_json":"{\"stream\":\"btcusdt@bookTicker\",\"data\":{\"e\":\"bookTicker\",\"u\":11478506923772,\"s\":\"BTCUSDT\",\"ps\":\"BTCUSDT\",\"b\":\"79597.00\",\"B\":\"5.167\",\"a\":\"79597.10\",\"A\":\"4.488\",\"T\":1788567708057,\"E\":1788567708057,\"st\":1}}"}
{"receive_ns":1788567708075415000,"stream":"btcusdt@bookTicker","event_type":"bookTicker","event_time_ms":1788567708090,"raw_json":"{\"stream\":\"btcusdt@bookTicker\",\"data\":{\"e\":\"bookTicker\",\"u\":11478506925719,\"s\":\"BTCUSDT\",\"ps\":\"BTCUSDT\",\"b\":\"79597.00\",\"B\":\"5.119\",\"a\":\"79597.10\",\"A\":\"4.488\",\"T\":1788567708090,\"E\":1788567708090,\"st\":1}}"}
{"receive_ns":1788567708085215000,"stream":"btcusdt@bookTicker","event_type":"bookTicker","event_time_ms":1788567708093,"raw_json":"{\"stream\":\"btcusdt@bookTicker\",\"data\":{\"e\":\"bookTicker\",\"u\":11478506925998,\"s\":\"BTCUSDT\",\"ps\":\"BTCUSDT\",\"b\":\"79597.00\",\"B\":\"5.170\",\"a\":\"79597.10\",\"A\":\"4.488\",\"T\":1788567708093,\"E\":1788567708093,\"st\":1}}"}
{"receive_ns":1788567708090827000,"stream":"btcusdt@bookTicker","event_type":"bookTicker","event_time_ms":1788567708106,"raw_json":"{\"stream\":\"btcusdt@bookTicker\",\"data\":{\"e\":\"bookTicker\",\"u\":11478506926894,\"s\":\"BTCUSDT\",\"ps\":\"BTCUSDT\",\"b\":\"79597.00\",\"B\":\"5.170\",\"a\":\"79597.10\",\"A\":\"4.481\",\"T\":1788567708105,\"E\":1788567708106,\"st\":1}}"}
{"receive_ns":1788567708097202000,"stream":"btcusdt@bookTicker","event_type":"bookTicker","event_time_ms":1788567708107,"raw_json":"{\"stream\":\"btcusdt@bookTicker\",\"data\":{\"e\":\"bookTicker\",\"u\":11478506927026,\"s\":\"BTCUSDT\",\"ps\":\"BTCUSDT\",\"b\":\"79597.00\",\"B\":\"5.168\",\"a\":\"79597.10\",\"A\":\"4.481\",\"T\":1788567708107,\"E\":1788567708107,\"st\":1}}"}
{"receive_ns":1788567708103320000,"stream":"btcusdt@bookTicker","event_type":"bookTicker","event_time_ms":1788567708113,"raw_json":"{\"stream\":\"btcusdt@bookTicker\",\"data\":{\"e\":\"bookTicker\",\"u\":11478506927344,\"s\":\"BTCUSDT\",\"ps\":\"BTCUSDT\",\"b\":\"79597.00\",\"B\":\"5.161\",\"a\":\"79597.10\",\"A\":\"4.481\",\"T\":1788567708113,\"E\":1788567708113,\"st\":1}}"}
{"receive_ns":1788567708114122000,"stream":"btcusdt@trade","event_type":"trade","event_time_ms":1788567708113,"raw_json":"{\"stream\":\"btcusdt@trade\",\"data\":{\"e\":\"trade\",\"E\":1788567708113,\"T\":1788567708113,\"s\":\"BTCUSDT\",\"t\":8054122546,\"p\":\"79597.00\",\"q\":\"0.007\",\"X\":\"MARKET\",\"m\":true,\"st\":1}}"}
{"receive_ns":1788567708120615000,"stream":"btcusdt@bookTicker","event_type":"bookTicker","event_time_ms":1788567708115,"raw_json":"{\"stream\":\"btcusdt@bookTicker\",\"data\":{\"e\":\"bookTicker\",\"u\":11478506927519,\"s\":\"BTCUSDT\",\"ps\":\"BTCUSDT\",\"b\":\"79597.00\",\"B\":\"5.120\",\"a\":\"79597.10\",\"A\":\"4.481\",\"T\":1788567708114,\"E\":1788567708115,\"st\":1}}"}
{"receive_ns":1788567708132454000,"stream":"btcusdt@bookTicker","event_type":"bookTicker","event_time_ms":1788567708121,"raw_json":"{\"stream\":\"btcusdt@bookTicker\",\"data\":{\"e\":\"bookTicker\",\"u\":11478506927903,\"s\":\"BTCUSDT\",\"ps\":\"BTCUSDT\",\"b\":\"79597.00\",\"B\":\"5.120\",\"a\":\"79597.10\",\"A\":\"4.479\",\"T\":1788567708121,\"E\":1788567708121,\"st\":1}}"}
{"receive_ns":1788567708132654000,"stream":"btcusdt@trade","event_type":"trade","event_time_ms":1788567708121,"raw_json":"{\"stream\":\"btcusdt@trade\",\"data\":{\"e\":\"trade\",\"E\":1788567708121,\"T\":1788567708121,\"s\":\"BTCUSDT\",\"t\":8054122547,\"p\":\"79597.10\",\"q\":\"0.002\",\"X\":\"MARKET\",\"m\":false,\"st\":1}}"}
{"receive_ns":1788567708138319000,"stream":"btcusdt@depth@100ms","event_type":"depthUpdate","event_time_ms":1788567708129,"raw_json":"{\"stream\":\"btcusdt@depth@100ms\",\"data\":{\"e\":\"depthUpdate\",\"E\":1788567708129,\"T\":1788567708127,\"s\":\"BTCUSDT\",\"ps\":\"BTCUSDT\",\"U\":11478506921980,\"u\":11478506928669,\"pu\":11478506921885,\"b\":[[\"29397.00\",\"1.414\"],[\"29497.00\",\"0.686\"],[\"63678.00\",\"0.000\"],[\"71637.30\",\"0.043\"],[\"76413.10\",\"0.000\"],[\"78005.10\",\"10.697\"],[\"78801.00\",\"12.547\"],[\"79199.00\",\"4.111\"],[\"79417.50\",\"3.142\"],[\"79417.60\",\"0.013\"],[\"79451.70\",\"1.896\"],[\"79451.80\",\"0.000\"],[\"79509.90\",\"0.234\"],[\"79510.00\",\"0.155\"],[\"79582.70\",\"0.204\"],[\"79592.30\",\"0.000\"],[\"79597.00\",\"5.120\"]],\"a\":[[\"79597.10\",\"4.479\"],[\"79597.30\",\"0.100\"],[\"79597.40\",\"0.000\"],[\"79597.50\",\"0.002\"],[\"79597.80\",\"0.577\"],[\"79598.00\",\"0.081\"],[\"79598.50\",\"0.152\"],[\"79598.90\",\"0.001\"],[\"79599.20\",\"0.026\"],[\"79599.70\",\"0.026\"],[\"79600.60\",\"0.000\"],[\"79639.20\",\"0.011\"],[\"79639.70\",\"0.172\"],[\"79639.90\",\"0.013\"],[\"79640.20\",\"0.003\"],[\"79640.80\",\"0.202\"],[\"79657.60\",\"0.023\"],[\"79685.10\",\"0.050\"],[\"79685.20\",\"0.000\"],[\"79693.20\",\"0.001\"],[\"79720.10\",\"2.476\"],[\"79741.40\",\"0.001\"],[\"79741.50\",\"3.541\"],[\"79838.80\",\"0.818\"],[\"79945.40\",\"0.001\"],[\"79998.00\",\"0.708\"],[\"80393.10\",\"10.298\"],[\"80614.60\",\"9.289\"],[\"81189.00\",\"10.515\"]],\"st\":1}}"}
{"receive_ns":1788567708149182000,"stream":"btcusdt@bookTicker","event_type":"bookTicker","event_time_ms":1788567708166,"raw_json":"{\"stream\":\"btcusdt@bookTicker\",\"data\":{\"e\":\"bookTicker\",\"u\":11478506930707,\"s\":\"BTCUSDT\",\"ps\":\"BTCUSDT\",\"b\":\"79597.00\",\"B\":\"4.325\",\"a\":\"79597.10\",\"A\":\"4.479\",\"T\":1788567708166,\"E\":1788567708166,\"st\":1}}"}
{"receive_ns":1788567708160505000,"stream":"btcusdt@bookTicker","event_type":"bookTicker","event_time_ms":1788567708175,"raw_json":"{\"stream\":\"btcusdt@bookTicker\",\"data\":{\"e\":\"bookTicker\",\"u\":11478506931106,\"s\":\"BTCUSDT\",\"ps\":\"BTCUSDT\",\"b\":\"79597.00\",\"B\":\"5.103\",\"a\":\"79597.10\",\"A\":\"4.479\",\"T\":1788567708175,\"E\":1788567708175,\"st\":1}}"}
{"receive_ns":1788567708166284000,"stream":"btcusdt@bookTicker","event_type":"bookTicker","event_time_ms":1788567708176,"raw_json":"{\"stream\":\"btcusdt@bookTicker\",\"data\":{\"e\":\"bookTicker\",\"u\":11478506931161,\"s\":\"BTCUSDT\",\"ps\":\"BTCUSDT\",\"b\":\"79597.00\",\"B\":\"5.102\",\"a\":\"79597.10\",\"A\":\"4.479\",\"T\":1788567708176,\"E\":1788567708176,\"st\":1}}"}
{"receive_ns":1788567708184944000,"stream":"btcusdt@bookTicker","event_type":"bookTicker","event_time_ms":1788567708207,"raw_json":"{\"stream\":\"btcusdt@bookTicker\",\"data\":{\"e\":\"bookTicker\",\"u\":11478506932959,\"s\":\"BTCUSDT\",\"ps\":\"BTCUSDT\",\"b\":\"79597.00\",\"B\":\"5.102\",\"a\":\"79597.10\",\"A\":\"5.761\",\"T\":1788567708207,\"E\":1788567708207,\"st\":1}}"}
{"receive_ns":1788567708196119000,"stream":"btcusdt@bookTicker","event_type":"bookTicker","event_time_ms":1788567708208,"raw_json":"{\"stream\":\"btcusdt@bookTicker\",\"data\":{\"e\":\"bookTicker\",\"u\":11478506933009,\"s\":\"BTCUSDT\",\"ps\":\"BTCUSDT\",\"b\":\"79597.00\",\"B\":\"5.102\",\"a\":\"79597.10\",\"A\":\"5.759\",\"T\":1788567708208,\"E\":1788567708208,\"st\":1}}"}
{"receive_ns":1788567708200779000,"stream":"btcusdt@bookTicker","event_type":"bookTicker","event_time_ms":1788567708208,"raw_json":"{\"stream\":\"btcusdt@bookTicker\",\"data\":{\"e\":\"bookTicker\",\"u\":11478506933024,\"s\":\"BTCUSDT\",\"ps\":\"BTCUSDT\",\"b\":\"79597.00\",\"B\":\"5.103\",\"a\":\"79597.10\",\"A\":\"5.759\",\"T\":1788567708208,\"E\":1788567708208,\"st\":1}}"}
{"receive_ns":1788567708206187000,"stream":"btcusdt@bookTicker","event_type":"bookTicker","event_time_ms":1788567708217,"raw_json":"{\"stream\":\"btcusdt@bookTicker\",\"data\":{\"e\":\"bookTicker\",\"u\":11478506934307,\"s\":\"BTCUSDT\",\"ps\":\"BTCUSDT\",\"b\":\"79597.00\",\"B\":\"5.103\",\"a\":\"79597.10\",\"A\":\"5.771\",\"T\":1788567708217,\"E\":1788567708217,\"st\":1}}"}
{"receive_ns":1788567708217557000,"stream":"btcusdt@bookTicker","event_type":"bookTicker","event_time_ms":1788567708219,"raw_json":"{\"stream\":\"btcusdt@bookTicker\",\"data\":{\"e\":\"bookTicker\",\"u\":11478506934440,\"s\":\"BTCUSDT\",\"ps\":\"BTCUSDT\",\"b\":\"79597.00\",\"B\":\"5.103\",\"a\":\"79597.10\",\"A\":\"5.773\",\"T\":1788567708218,\"E\":1788567708219,\"st\":1}}"}
{"receive_ns":1788567708223914000,"stream":"btcusdt@depth@100ms","event_type":"depthUpdate","event_time_ms":1788567708231,"raw_json":"{\"stream\":\"btcusdt@depth@100ms\",\"data\":{\"e\":\"depthUpdate\",\"E\":1788567708231,\"T\":1788567708229,\"s\":\"BTCUSDT\",\"ps\":\"BTCUSDT\",\"U\":11478506928807,\"u\":11478506935296,\"pu\":11478506928669,\"b\":[[\"1000.00\",\"24.604\"],[\"29397.00\",\"1.596\"],[\"29497.00\",\"0.504\"],[\"71637.30\",\"0.043\"],[\"76413.10\",\"0.002\"],[\"78548.30\",\"8.076\"],[\"78801.00\",\"12.547\"],[\"79570.50\",\"0.454\"],[\"79571.60\",\"0.001\"],[\"79576.20\",\"0.247\"],[\"79577.00\",\"0.374\"],[\"79578.10\",\"0.005\"],[\"79589.50\",\"0.075\"],[\"79591.60\",\"0.002\"],[\"79591.70\",\"0.079\"],[\"79597.00\",\"5.103\"]],\"a\":[[\"79597.10\",\"5.773\"],[\"79597.20\",\"0.007\"],[\"79597.30\",\"0.102\"],[\"79597.40\",\"0.000\"],[\"79597.50\",\"0.000\"],[\"79597.60\",\"0.000\"],[\"79597.80\",\"0.603\"],[\"79597.90\",\"0.021\"],[\"79598.00\",\"0.107\"],[\"79599.00\",\"0.078\"],[\"79600.40\",\"0.008\"],[\"79600.50\",\"0.078\"],[\"79602.80\",\"0.077\"],[\"79617.20\",\"0.000\"],[\"79618.00\",\"0.376\"],[\"79620.50\",\"0.000\"],[\"79621.20\",\"0.532\"],[\"79639.70\",\"0.047\"],[\"79640.00\",\"0.183\"],[\"79640.60\",\"0.038\"],[\"79692.00\",\"2.252\"],[\"79692.10\",\"6.000\"],[\"79693.20\",\"0.000\"],[\"79693.40\",\"0.001\"],[\"79701.80\",\"0.000\"],[\"79702.90\",\"0.000\"],[\"79705.50\",\"0.005\"],[\"79943.60\",\"0.018\"],[\"79995.10\",\"4.240\"],[\"80157.20\",\"0.674\"],[\"80316.40\",\"0.673\"],[\"80393.10\",\"10.298\"],[\"80552.30\",\"29.478\"]],\"st\":1}}"}
{"receive_ns":1788567708251078000,"stream":"btcusdt@bookTicker","event_type":"bookTicker","event_time_ms":1788567708267,"raw_json":"{\"stream\":\"btcusdt@bookTicker\",\"data\":{\"e\":\"bookTicker\",\"u\":11478506937649,\"s\":\"BTCUSDT\",\"ps\":\"BTCUSDT\",\"b\":\"79597.00\",\"B\":\"5.103\",\"a\":\"79597.10\",\"A\":\"5.903\",\"T\":1788567708267,\"E\":1788567708267,\"st\":1}}"}
{"receive_ns":1788567708263141000,"stream":"btcusdt@bookTicker","event_type":"bookTicker","event_time_ms":1788567708268,"raw_json":"{\"stream\":\"btcusdt@bookTicker\",\"data\":{\"e\":\"bookTicker\",\"u\":11478506937778,\"s\":\"BTCUSDT\",\"ps\":\"BTCUSDT\",\"b\":\"79597.00\",\"B\":\"5.103\",\"a\":\"79597.10\",\"A\":\"5.901\",\"T\":1788567708268,\"E\":1788567708268,\"st\":1}}"}
{"receive_ns":1788567708301146000,"stream":"btcusdt@bookTicker","event_type":"bookTicker","event_time_ms":1788567708317,"raw_json":"{\"stream\":\"btcusdt@bookTicker\",\"data\":{\"e\":\"bookTicker\",\"u\":11478506940584,\"s\":\"BTCUSDT\",\"ps\":\"BTCUSDT\",\"b\":\"79597.00\",\"B\":\"5.103\",\"a\":\"79597.10\",\"A\":\"5.914\",\"T\":1788567708316,\"E\":1788567708317,\"st\":1}}"}
{"receive_ns":1788567708312900000,"stream":"btcusdt@bookTicker","event_type":"bookTicker","event_time_ms":1788567708318,"raw_json":"{\"stream\":\"btcusdt@bookTicker\",\"data\":{\"e\":\"bookTicker\",\"u\":11478506940786,\"s\":\"BTCUSDT\",\"ps\":\"BTCUSDT\",\"b\":\"79597.00\",\"B\":\"5.103\",\"a\":\"79597.10\",\"A\":\"5.916\",\"T\":1788567708318,\"E\":1788567708318,\"st\":1}}"}
{"receive_ns":1788567708324987000,"stream":"btcusdt@depth@100ms","event_type":"depthUpdate","event_time_ms":1788567708333,"raw_json":"{\"stream\":\"btcusdt@depth@100ms\",\"data\":{\"e\":\"depthUpdate\",\"E\":1788567708333,\"T\":1788567708332,\"s\":\"BTCUSDT\",\"ps\":\"BTCUSDT\",\"U\":11478506935395,\"u\":11478506941812,\"pu\":11478506935296,\"b\":[[\"29297.00\",\"0.007\"],[\"29397.00\",\"1.757\"],[\"29497.00\",\"0.336\"],[\"71637.30\",\"0.043\"],[\"76413.10\",\"0.000\"],[\"76413.20\",\"0.000\"],[\"78223.80\",\"0.002\"],[\"78462.30\",\"0.000\"],[\"78548.90\",\"6.360\"],[\"78801.00\",\"12.547\"],[\"79000.00\",\"43.490\"],[\"79199.00\",\"4.112\"],[\"79563.20\",\"0.010\"],[\"79567.70\",\"0.167\"],[\"79570.10\",\"0.453\"],[\"79570.30\",\"0.628\"],[\"79570.50\",\"0.002\"],[\"79571.40\",\"1.602\"]],\"a\":[[\"79597.10\",\"5.916\"],[\"79597.30\",\"0.102\"],[\"79597.40\",\"0.002\"],[\"79597.60\",\"0.000\"],[\"79598.60\",\"0.253\"],[\"79606.90\",\"0.002\"],[\"79608.50\",\"1.105\"],[\"79609.30\",\"0.408\"],[\"79610.70\",\"0.104\"],[\"79619.90\",\"0.452\"],[\"79621.20\",\"0.080\"],[\"79640.00\",\"0.058\"],[\"79640.10\",\"1.300\"],[\"79692.30\",\"0.003\"],[\"80233.90\",\"7.340\"],[\"80393.10\",\"10.298\"],[\"80472.70\",\"4.529\"],[\"80663.80\",\"1.653\"],[\"81189.00\",\"10.518\"]],\"st\":1}}"}
{"receive_ns":1788567708355302000,"stream":"btcusdt@bookTicker","event_type":"bookTicker","event_time_ms":1788567708366,"raw_json":"{\"stream\":\"btcusdt@bookTicker\",\"data\":{\"e\":\"bookTicker\",\"u\":11478506943469,\"s\":\"BTCUSDT\",\"ps\":\"BTCUSDT\",\"b\":\"79597.00\",\"B\":\"5.144\",\"a\":\"79597.10\",\"A\":\"5.916\",\"T\":1788567708366,\"E\":1788567708366,\"st\":1}}"}
{"receive_ns":1788567708364841000,"stream":"btcusdt@bookTicker","event_type":"bookTicker","event_time_ms":1788567708372,"raw_json":"{\"stream\":\"btcusdt@bookTicker\",\"data\":{\"e\":\"bookTicker\",\"u\":11478506943696,\"s\":\"BTCUSDT\",\"ps\":\"BTCUSDT\",\"b\":\"79597.00\",\"B\":\"5.021\",\"a\":\"79597.10\",\"A\":\"5.916\",\"T\":1788567708371,\"E\":1788567708372,\"st\":1}}"}
{"receive_ns":1788567708381249000,"stream":"btcusdt@bookTicker","event_type":"bookTicker","event_time_ms":1788567708375,"raw_json":"{\"stream\":\"btcusdt@bookTicker\",\"data\":{\"e\":\"bookTicker\",\"u\":11478506943838,\"s\":\"BTCUSDT\",\"ps\":\"BTCUSDT\",\"b\":\"79597.00\",\"B\":\"5.149\",\"a\":\"79597.10\",\"A\":\"5.916\",\"T\":1788567708375,\"E\":1788567708375,\"st\":1}}"}
{"receive_ns":1788567708399685000,"stream":"btcusdt@bookTicker","event_type":"bookTicker","event_time_ms":1788567708376,"raw_json":"{\"stream\":\"btcusdt@bookTicker\",\"data\":{\"e\":\"bookTicker\",\"u\":11478506943880,\"s\":\"BTCUSDT\",\"ps\":\"BTCUSDT\",\"b\":\"79597.00\",\"B\":\"5.148\",\"a\":\"79597.10\",\"A\":\"5.916\",\"T\":1788567708376,\"E\":1788567708376,\"st\":1}}"}
{"receive_ns":1788567708422541000,"stream":"btcusdt@bookTicker","event_type":"bookTicker","event_time_ms":1788567708377,"raw_json":"{\"stream\":\"btcusdt@bookTicker\",\"data\":{\"e\":\"bookTicker\",\"u\":11478506943924,\"s\":\"BTCUSDT\",\"ps\":\"BTCUSDT\",\"b\":\"79597.00\",\"B\":\"5.148\",\"a\":\"79597.10\",\"A\":\"5.917\",\"T\":1788567708377,\"E\":1788567708377,\"st\":1}}"}
{"receive_ns":1788567708433480000,"stream":"btcusdt@bookTicker","event_type":"bookTicker","event_time_ms":1788567708381,"raw_json":"{\"stream\":\"btcusdt@bookTicker\",\"data\":{\"e\":\"bookTicker\",\"u\":11478506944082,\"s\":\"BTCUSDT\",\"ps\":\"BTCUSDT\",\"b\":\"79597.00\",\"B\":\"5.093\",\"a\":\"79597.10\",\"A\":\"5.917\",\"T\":1788567708381,\"E\":1788567708381,\"st\":1}}"}
{"receive_ns":1788567708452211000,"stream":"btcusdt@bookTicker","event_type":"bookTicker","event_time_ms":1788567708384,"raw_json":"{\"stream\":\"btcusdt@bookTicker\",\"data\":{\"e\":\"bookTicker\",\"u\":11478506944246,\"s\":\"BTCUSDT\",\"ps\":\"BTCUSDT\",\"b\":\"79597.00\",\"B\":\"5.142\",\"a\":\"79597.10\",\"A\":\"5.917\",\"T\":1788567708384,\"E\":1788567708384,\"st\":1}}"}
{"receive_ns":1788567708463192000,"stream":"btcusdt@bookTicker","event_type":"bookTicker","event_time_ms":1788567708385,"raw_json":"{\"stream\":\"btcusdt@bookTicker\",\"data\":{\"e\":\"bookTicker\",\"u\":11478506944343,\"s\":\"BTCUSDT\",\"ps\":\"BTCUSDT\",\"b\":\"79597.00\",\"B\":\"5.116\",\"a\":\"79597.10\",\"A\":\"5.917\",\"T\":1788567708384,\"E\":1788567708385,\"st\":1}}"}
{"receive_ns":1788567708469479000,"stream":"btcusdt@bookTicker","event_type":"bookTicker","event_time_ms":1788567708385,"raw_json":"{\"stream\":\"btcusdt@bookTicker\",\"data\":{\"e\":\"bookTicker\",\"u\":11478506944397,\"s\":\"BTCUSDT\",\"ps\":\"BTCUSDT\",\"b\":\"79597.00\",\"B\":\"5.117\",\"a\":\"79597.10\",\"A\":\"5.917\",\"T\":1788567708385,\"E\":1788567708385,\"st\":1}}"}
{"receive_ns":1788567708481379000,"stream":"btcusdt@bookTicker","event_type":"bookTicker","event_time_ms":1788567708427,"raw_json":"{\"stream\":\"btcusdt@bookTicker\",\"data\":{\"e\":\"bookTicker\",\"u\":11478506946702,\"s\":\"BTCUSDT\",\"ps\":\"BTCUSDT\",\"b\":\"79597.00\",\"B\":\"5.117\",\"a\":\"79597.10\",\"A\":\"5.924\",\"T\":1788567708427,\"E\":1788567708427,\"st\":1}}"}
{"receive_ns":1788567708488047000,"stream":"btcusdt@depth@100ms","event_type":"depthUpdate","event_time_ms":1788567708435,"raw_json":"{\"stream\":\"btcusdt@depth@100ms\",\"data\":{\"e\":\"depthUpdate\",\"E\":1788567708435,\"T\":1788567708434,\"s\":\"BTCUSDT\",\"ps\":\"BTCUSDT\",\"U\":11478506941914,\"u\":11478506947052,\"pu\":11478506941812,\"b\":[[\"29297.00\",\"0.070\"],[\"29397.00\",\"1.813\"],[\"29497.00\",\"0.217\"],[\"71637.30\",\"0.043\"],[\"71673.00\",\"0.003\"],[\"78005.10\",\"10.700\"],[\"78801.00\",\"12.547\"],[\"78880.60\",\"4.302\"],[\"79199.00\",\"4.112\"],[\"79475.30\",\"0.495\"],[\"79541.20\",\"0.002\"],[\"79591.20\",\"0.010\"],[\"79591.60\",\"0.000\"],[\"79596.90\",\"2.408\"],[\"79597.00\",\"5.117\"]],\"a\":[[\"79597.10\",\"5.924\"],[\"79597.30\",\"0.102\"],[\"79597.40\",\"0.002\"],[\"79597.50\",\"0.026\"],[\"79597.60\",\"0.000\"],[\"79597.70\",\"0.171\"],[\"79600.20\",\"0.001\"],[\"79600.30\",\"0.002\"],[\"79617.50\",\"0.004\"],[\"79692.70\",\"0.003\"],[\"79716.50\",\"0.003\"],[\"79719.80\",\"0.476\"],[\"80300.00\",\"49.581\"],[\"80393.10\",\"10.298\"],[\"80486.00\",\"9.034\"]],\"st\":1}}"}
{"receive_ns":1788567708488536000,"stream":"btcusdt@bookTicker","event_type":"bookTicker","event_time_ms":1788567708444,"raw_json":"{\"stream\":\"btcusdt@bookTicker\",\"data\":{\"e\":\"bookTicker\",\"u\":11478506947463,\"s\":\"BTCUSDT\",\"ps\":\"BTCUSDT\",\"b\":\"79597.00\",\"B\":\"5.117\",\"a\":\"79597.10\",\"A\":\"5.950\",\"T\":1788567708443,\"E\":1788567708444,\"st\":1}}"}
{"receive_ns":1788567708500550000,"stream":"btcusdt@bookTicker","event_type":"bookTicker","event_time_ms":1788567708477,"raw_json":"{\"stream\":\"btcusdt@bookTicker\",\"data\":{\"e\":\"bookTicker\",\"u\":11478506949851,\"s\":\"BTCUSDT\",\"ps\":\"BTCUSDT\",\"b\":\"79597.00\",\"B\":\"5.193\",\"a\":\"79597.10\",\"A\":\"5.950\",\"T\":1788567708477,\"E\":1788567708477,\"st\":1}}"}
{"receive_ns":1788567708511563000,"stream":"btcusdt@bookTicker","event_type":"bookTicker","event_time_ms":1788567708478,"raw_json":"{\"stream\":\"btcusdt@bookTicker\",\"data\":{\"e\":\"bookTicker\",\"u\":11478506949917,\"s\":\"BTCUSDT\",\"ps\":\"BTCUSDT\",\"b\":\"79597.00\",\"B\":\"5.192\",\"a\":\"79597.10\",\"A\":\"5.950\",\"T\":1788567708478,\"E\":1788567708478,\"st\":1}}"}
{"receive_ns":1788567708513244000,"stream":"btcusdt@depth@100ms","event_type":"depthUpdate","event_time_ms":1788567708537,"raw_json":"{\"stream\":\"btcusdt@depth@100ms\",\"data\":{\"e\":\"depthUpdate\",\"E\":1788567708537,\"T\":1788567708536,\"s\":\"BTCUSDT\",\"ps\":\"BTCUSDT\",\"U\":11478506947100,\"u\":11478506952261,\"pu\":11478506947052,\"b\":[[\"1000.00\",\"24.604\"],[\"29297.00\",\"0.126\"],[\"29397.00\",\"1.876\"],[\"29497.00\",\"0.098\"],[\"71637.30\",\"0.043\"],[\"71673.00\",\"0.000\"],[\"76413.10\",\"0.002\"],[\"78641.80\",\"33.311\"],[\"78801.00\",\"12.547\"],[\"78880.60\",\"5.188\"],[\"79018.30\",\"0.000\"],[\"79525.30\",\"0.635\"],[\"79564.20\",\"0.129\"],[\"79594.30\",\"0.058\"],[\"79594.40\",\"0.004\"],[\"79594.60\",\"0.103\"],[\"79594.70\",\"0.026\"],[\"79594.80\",\"0.026\"],[\"79595.40\",\"0.028\"],[\"79595.50\",\"0.252\"],[\"79595.60\",\"0.038\"],[\"79595.70\",\"0.103\"],[\"79595.90\",\"0.028\"],[\"79596.00\",\"0.082\"],[\"79596.70\",\"0.000\"],[\"79596.80\",\"0.597\"],[\"79597.00\",\"5.192\"]],\"a\":[[\"79597.10\",\"5.950\"],[\"79597.40\",\"0.002\"],[\"79600.10\",\"0.002\"],[\"79609.80\",\"0.003\"],[\"79640.00\",\"0.058\"],[\"79716.50\",\"0.005\"],[\"79732.50\",\"0.002\"],[\"80393.10\",\"10.298\"]],\"st\":1}}"}
{"receive_ns":1788567708530903000,"stream":"btcusdt@bookTicker","event_type":"bookTicker","event_time_ms":1788567708553,"raw_json":"{\"stream\":\"btcusdt@bookTicker\",\"data\":{\"e\":\"bookTicker\",\"u\":11478506952925,\"s\":\"BTCUSDT\",\"ps\":\"BTCUSDT\",\"b\":\"79597.00\",\"B\":\"5.140\",\"a\":\"79597.10\",\"A\":\"5.950\",\"T\":1788567708553,\"E\":1788567708553,\"st\":1}}"}
{"receive_ns":1788567708548695000,"stream":"btcusdt@bookTicker","event_type":"bookTicker","event_time_ms":1788567708556,"raw_json":"{\"stream\":\"btcusdt@bookTicker\",\"data\":{\"e\":\"bookTicker\",\"u\":11478506953046,\"s\":\"BTCUSDT\",\"ps\":\"BTCUSDT\",\"b\":\"79597.00\",\"B\":\"5.201\",\"a\":\"79597.10\",\"A\":\"5.950\",\"T\":1788567708556,\"E\":1788567708556,\"st\":1}}"}
{"receive_ns":1788567708563470000,"stream":"btcusdt@bookTicker","event_type":"bookTicker","event_time_ms":1788567708557,"raw_json":"{\"stream\":\"btcusdt@bookTicker\",\"data\":{\"e\":\"bookTicker\",\"u\":11478506953117,\"s\":\"BTCUSDT\",\"ps\":\"BTCUSDT\",\"b\":\"79597.00\",\"B\":\"5.202\",\"a\":\"79597.10\",\"A\":\"5.950\",\"T\":1788567708557,\"E\":1788567708557,\"st\":1}}"}
{"receive_ns":1788567708622085000,"stream":"btcusdt@depth@100ms","event_type":"depthUpdate","event_time_ms":1788567708639,"raw_json":"{\"stream\":\"btcusdt@depth@100ms\",\"data\":{\"e\":\"depthUpdate\",\"E\":1788567708639,\"T\":1788567708638,\"s\":\"BTCUSDT\",\"ps\":\"BTCUSDT\",\"U\":11478506952307,\"u\":11478506956423,\"pu\":11478506952261,\"b\":[[\"29297.00\",\"0.210\"],[\"29397.00\",\"1.890\"],[\"29497.00\",\"0.000\"],[\"63678.00\",\"0.000\"],[\"71637.30\",\"0.043\"],[\"76413.10\",\"0.000\"],[\"78104.60\",\"0.000\"],[\"78482.60\",\"30.725\"],[\"78801.00\",\"12.547\"],[\"79199.00\",\"4.111\"],[\"79592.20\",\"0.000\"],[\"79594.60\",\"0.077\"],[\"79596.00\",\"0.108\"],[\"79597.00\",\"5.202\"]],\"a\":[[\"79640.00\",\"0.183\"],[\"80393.10\",\"10.298\"],[\"80632.10\",\"0.867\"]],\"st\":1}}"}
{"receive_ns":1788567708681815000,"stream":"btcusdt@bookTicker","event_type":"bookTicker","event_time_ms":1788567708694,"raw_json":"{\"stream\":\"btcusdt@bookTicker\",\"data\":{\"e\":\"bookTicker\",\"u\":11478506959105,\"s\":\"BTCUSDT\",\"ps\":\"BTCUSDT\",\"b\":\"79597.00\",\"B\":\"5.126\",\"a\":\"79597.10\",\"A\":\"5.950\",\"T\":1788567708694,\"E\":1788567708694,\"st\":1}}"}
{"receive_ns":1788567708694738000,"stream":"btcusdt@bookTicker","event_type":"bookTicker","event_time_ms":1788567708702,"raw_json":"{\"stream\":\"btcusdt@bookTicker\",\"data\":{\"e\":\"bookTicker\",\"u\":11478506959485,\"s\":\"BTCUSDT\",\"ps\":\"BTCUSDT\",\"b\":\"79597.00\",\"B\":\"5.126\",\"a\":\"79597.10\",\"A\":\"5.949\",\"T\":1788567708702,\"E\":1788567708702,\"st\":1}}"}
{"receive_ns":1788567708701480000,"stream":"btcusdt@trade","event_type":"trade","event_time_ms":1788567708702,"raw_json":"{\"stream\":\"btcusdt@trade\",\"data\":{\"e\":\"trade\",\"E\":1788567708702,\"T\":1788567708702,\"s\":\"BTCUSDT\",\"t\":8054122548,\"p\":\"79597.10\",\"q\":\"0.001\",\"X\":\"MARKET\",\"m\":false,\"st\":1}}"}
{"receive_ns":1788567708714589000,"stream":"btcusdt@bookTicker","event_type":"bookTicker","event_time_ms":1788567708712,"raw_json":"{\"stream\":\"btcusdt@bookTicker\",\"data\":{\"e\":\"bookTicker\",\"u\":11478506959851,\"s\":\"BTCUSDT\",\"ps\":\"BTCUSDT\",\"b\":\"79597.00\",\"B\":\"5.202\",\"a\":\"79597.10\",\"A\":\"5.949\",\"T\":1788567708712,\"E\":1788567708712,\"st\":1}}"}
{"receive_ns":1788567708725880000,"stream":"btcusdt@bookTicker","event_type":"bookTicker","event_time_ms":1788567708736,"raw_json":"{\"stream\":\"btcusdt@bookTicker\",\"data\":{\"e\":\"bookTicker\",\"u\":11478506960613,\"s\":\"BTCUSDT\",\"ps\":\"BTCUSDT\",\"b\":\"79597.00\",\"B\":\"5.202\",\"a\":\"79597.10\",\"A\":\"5.923\",\"T\":1788567708736,\"E\":1788567708736,\"st\":1}}"}
{"receive_ns":1788567708743863000,"stream":"btcusdt@depth@100ms","event_type":"depthUpdate","event_time_ms":1788567708741,"raw_json":"{\"stream\":\"btcusdt@depth@100ms\",\"data\":{\"e\":\"depthUpdate\",\"E\":1788567708741,\"T\":1788567708738,\"s\":\"BTCUSDT\",\"ps\":\"BTCUSDT\",\"U\":11478506956477,\"u\":11478506960788,\"pu\":11478506956423,\"b\":[[\"29297.00\",\"0.385\"],[\"29397.00\",\"1.715\"],[\"71637.30\",\"0.043\"],[\"76413.10\",\"0.002\"],[\"78610.10\",\"0.000\"],[\"78614.60\",\"0.008\"],[\"78801.00\",\"12.547\"],[\"79199.00\",\"2.221\"],[\"79471.00\",\"0.002\"],[\"79471.10\",\"0.003\"],[\"79475.30\",\"0.479\"],[\"79498.40\",\"0.021\"],[\"79499.40\",\"0.560\"],[\"79501.40\",\"0.046\"],[\"79506.30\",\"0.038\"],[\"79506.70\",\"4.242\"],[\"79507.30\",\"0.200\"],[\"79522.30\",\"0.002\"],[\"79523.30\",\"0.551\"],[\"79525.30\",\"0.635\"],[\"79541.20\",\"0.000\"],[\"79542.20\",\"0.831\"],[\"79558.10\",\"0.694\"],[\"79570.10\",\"0.001\"],[\"79570.50\",\"0.454\"],[\"79571.60\",\"0.001\"],[\"79573.30\",\"0.002\"],[\"79590.90\",\"0.072\"],[\"79591.20\",\"0.008\"],[\"79594.70\",\"0.000\"],[\"79596.00\",\"0.082\"],[\"79596.30\",\"0.026\"],[\"79596.50\",\"0.031\"],[\"79597.00\",\"5.202\"]],\"a\":[[\"79597.10\",\"5.923\"],[\"79597.70\",\"0.171\"],[\"79610.60\",\"0.694\"],[\"79613.20\",\"0.005\"],[\"79619.90\",\"0.000\"],[\"79621.10\",\"0.582\"],[\"79626.50\",\"5.352\"],[\"79640.00\",\"0.058\"],[\"79640.30\",\"0.000\"],[\"79640.50\",\"0.016\"],[\"79668.80\",\"0.034\"],[\"79688.10\",\"3.345\"],[\"79692.70\",\"0.001\"],[\"79719.80\",\"0.476\"],[\"79732.50\",\"0.000\"],[\"79818.80\",\"7.071\"],[\"79995.10\",\"4.241\"],[\"80299.20\",\"4.603\"],[\"80393.10\",\"10.298\"],[\"81189.00\",\"10.509\"]],\"st\":1}}"}
{"receive_ns":1788567708762743000,"stream":"btcusdt@bookTicker","event_type":"bookTicker","event_time_ms":1788567708760,"raw_json":"{\"stream\":\"btcusdt@bookTicker\",\"data\":{\"e\":\"bookTicker\",\"u\":11478506961746,\"s\":\"BTCUSDT\",\"ps\":\"BTCUSDT\",\"b\":\"79597.00\",\"B\":\"5.214\",\"a\":\"79597.10\",\"A\":\"5.923\",\"T\":1788567708760,\"E\":1788567708760,\"st\":1}}"}
{"receive_ns":1788567708798617000,"stream":"btcusdt@bookTicker","event_type":"bookTicker","event_time_ms":1788567708814,"raw_json":"{\"stream\":\"btcusdt@bookTicker\",\"data\":{\"e\":\"bookTicker\",\"u\":11478506965183,\"s\":\"BTCUSDT\",\"ps\":\"BTCUSDT\",\"b\":\"79597.00\",\"B\":\"5.214\",\"a\":\"79597.10\",\"A\":\"5.793\",\"T\":1788567708814,\"E\":1788567708814,\"st\":1}}"}
{"receive_ns":1788567708807806000,"stream":"btcusdt@bookTicker","event_type":"bookTicker","event_time_ms":1788567708814,"raw_json":"{\"stream\":\"btcusdt@bookTicker\",\"data\":{\"e\":\"bookTicker\",\"u\":11478506965199,\"s\":\"BTCUSDT\",\"ps\":\"BTCUSDT\",\"b\":\"79597.00\",\"B\":\"5.214\",\"a\":\"79597.10\",\"A\":\"5.780\",\"T\":1788567708814,\"E\":1788567708814,\"st\":1}}"}
{"receive_ns":1788567708808274000,"stream":"btcusdt@bookTicker","event_type":"bookTicker","event_time_ms":1788567708814,"raw_json":"{\"stream\":\"btcusdt@bookTicker\",\"data\":{\"e\":\"bookTicker\",\"u\":11478506965206,\"s\":\"BTCUSDT\",\"ps\":\"BTCUSDT\",\"b\":\"79597.00\",\"B\":\"5.214\",\"a\":\"79597.10\",\"A\":\"5.768\",\"T\":1788567708814,\"E\":1788567708814,\"st\":1}}"}
{"receive_ns":1788567708813822000,"stream":"btcusdt@bookTicker","event_type":"bookTicker","event_time_ms":1788567708815,"raw_json":"{\"stream\":\"btcusdt@bookTicker\",\"data\":{\"e\":\"bookTicker\",\"u\":11478506965244,\"s\":\"BTCUSDT\",\"ps\":\"BTCUSDT\",\"b\":\"79597.00\",\"B\":\"5.214\",\"a\":\"79597.10\",\"A\":\"4.486\",\"T\":1788567708815,\"E\":1788567708815,\"st\":1}}"}
{"receive_ns":1788567708824859000,"stream":"btcusdt@bookTicker","event_type":"bookTicker","event_time_ms":1788567708819,"raw_json":"{\"stream\":\"btcusdt@bookTicker\",\"data\":{\"e\":\"bookTicker\",\"u\":11478506965491,\"s\":\"BTCUSDT\",\"ps\":\"BTCUSDT\",\"b\":\"79597.00\",\"B\":\"5.214\",\"a\":\"79597.10\",\"A\":\"4.479\",\"T\":1788567708818,\"E\":1788567708819,\"st\":1}}"}
{"receive_ns":1788567708842374000,"stream":"btcusdt@bookTicker","event_type":"bookTicker","event_time_ms":1788567708819,"raw_json":"{\"stream\":\"btcusdt@bookTicker\",\"data\":{\"e\":\"bookTicker\",\"u\":11478506965515,\"s\":\"BTCUSDT\",\"ps\":\"BTCUSDT\",\"b\":\"79597.00\",\"B\":\"5.214\",\"a\":\"79597.10\",\"A\":\"4.478\",\"T\":1788567708819,\"E\":1788567708819,\"st\":1}}"}
{"receive_ns":1788567708862081000,"stream":"btcusdt@depth@100ms","event_type":"depthUpdate","event_time_ms":1788567708843,"raw_json":"{\"stream\":\"btcusdt@depth@100ms\",\"data\":{\"e\":\"depthUpdate\",\"E\":1788567708843,\"T\":1788567708841,\"s\":\"BTCUSDT\",\"ps\":\"BTCUSDT\",\"U\":11478506960951,\"u\":11478506966586,\"pu\":11478506960788,\"b\":[[\"1000.00\",\"24.604\"],[\"29297.00\",\"0.567\"],[\"29397.00\",\"1.533\"],[\"71637.30\",\"0.043\"],[\"76413.10\",\"0.000\"],[\"78542.10\",\"0.636\"],[\"78801.00\",\"12.547\"],[\"78880.60\",\"6.074\"],[\"79558.10\",\"0.003\"],[\"79594.80\",\"0.000\"],[\"79594.90\",\"0.000\"],[\"79595.00\",\"0.002\"],[\"79596.60\",\"0.026\"],[\"79596.70\",\"0.026\"],[\"79596.90\",\"2.454\"],[\"79597.00\",\"5.214\"]],\"a\":[[\"79597.10\",\"4.478\"],[\"79597.30\",\"0.102\"],[\"79597.40\",\"0.000\"],[\"79597.50\",\"0.000\"],[\"79597.60\",\"0.002\"],[\"79597.70\",\"0.145\"],[\"79597.80\",\"0.577\"],[\"79597.90\",\"0.020\"],[\"79598.00\",\"0.081\"],[\"79598.60\",\"0.279\"],[\"79598.80\",\"0.031\"],[\"79598.90\",\"0.027\"],[\"79599.00\",\"0.002\"],[\"79601.10\",\"0.023\"],[\"79606.90\",\"0.001\"],[\"79608.50\",\"1.106\"],[\"79610.60\",\"0.003\"],[\"79617.50\",\"0.000\"],[\"79626.50\",\"4.523\"],[\"79640.50\",\"0.016\"],[\"80393.10\",\"10.298\"]],\"st\":1}}"}
{"receive_ns":1788567708935110000,"stream":"btcusdt@depth@100ms","event_type":"depthUpdate","event_time_ms":1788567708945,"raw_json":"{\"stream\":\"btcusdt@depth@100ms\",\"data\":{\"e\":\"depthUpdate\",\"E\":1788567708945,\"T\":1788567708944,\"s\":\"BTCUSDT\",\"ps\":\"BTCUSDT\",\"U\":11478506966727,\"u\":11478506973512,\"pu\":11478506966586,\"b\":[[\"29297.00\",\"0.742\"],[\"29397.00\",\"1.358\"],[\"71637.30\",\"0.043\"],[\"75617.10\",\"0.014\"],[\"75617.20\",\"0.006\"],[\"78224.10\",\"0.000\"],[\"78704.60\",\"2.538\"],[\"78801.00\",\"12.547\"],[\"79425.80\",\"0.006\"],[\"79590.90\",\"0.070\"],[\"79591.70\",\"0.081\"],[\"79592.10\",\"0.181\"]],\"a\":[[\"79597.30\",\"0.100\"],[\"79597.50\",\"0.002\"],[\"79598.50\",\"0.126\"],[\"79599.30\",\"0.044\"],[\"79612.70\",\"0.004\"],[\"79617.40\",\"0.000\"],[\"79641.40\",\"0.126\"],[\"79995.10\",\"4.366\"],[\"80194.10\",\"3.738\"],[\"80300.70\",\"0.000\"],[\"80393.10\",\"10.298\"],[\"81085.60\",\"3.815\"]],\"st\":1}}"}
{"receive_ns":1788567709016113000,"stream":"btcusdt@bookTicker","event_type":"bookTicker","event_time_ms":1788567709027,"raw_json":"{\"stream\":\"btcusdt@bookTicker\",\"data\":{\"e\":\"bookTicker\",\"u\":11478506978299,\"s\":\"BTCUSDT\",\"ps\":\"BTCUSDT\",\"b\":\"79597.00\",\"B\":\"5.214\",\"a\":\"79597.10\",\"A\":\"4.480\",\"T\":1788567709027,\"E\":1788567709027,\"st\":1}}"}
{"receive_ns":1788567709033724000,"stream":"btcusdt@depth@100ms","event_type":"depthUpdate","event_time_ms":1788567709047,"raw_json":"{\"stream\":\"btcusdt@depth@100ms\",\"data\":{\"e\":\"depthUpdate\",\"E\":1788567709047,\"T\":1788567709045,\"s\":\"BTCUSDT\",\"ps\":\"BTCUSDT\",\"U\":11478506973528,\"u\":11478506979482,\"pu\":11478506973512,\"b\":[[\"29297.00\",\"0.924\"],[\"29397.00\",\"1.176\"],[\"63677.60\",\"0.000\"],[\"71637.30\",\"0.043\"],[\"76413.10\",\"0.002\"],[\"78383.30\",\"0.836\"],[\"78710.00\",\"2.805\"],[\"78801.00\",\"12.547\"],[\"78840.80\",\"9.397\"],[\"79199.00\",\"4.121\"],[\"79562.30\",\"0.005\"],[\"79582.70\",\"0.208\"]],\"a\":[[\"79597.10\",\"4.480\"],[\"79641.40\",\"0.001\"],[\"79806.90\",\"5.057\"],[\"79818.80\",\"7.110\"],[\"80299.20\",\"4.416\"],[\"80393.10\",\"10.298\"],[\"80638.40\",\"1.238\"]],\"st\":1}}"}
{"receive_ns":1788567709134785000,"stream":"btcusdt@depth@100ms","event_type":"depthUpdate","event_time_ms":1788567709149,"raw_json":"{\"stream\":\"btcusdt@depth@100ms\",\"data\":{\"e\":\"depthUpdate\",\"E\":1788567709149,\"T\":1788567709148,\"s\":\"BTCUSDT\",\"ps\":\"BTCUSDT\",\"U\":11478506979561,\"u\":11478506984328,\"pu\":11478506979482,\"b\":[[\"1000.00\",\"24.604\"],[\"29297.00\",\"1.099\"],[\"29397.00\",\"1.001\"],[\"71637.30\",\"0.043\"],[\"75617.10\",\"0.016\"],[\"76413.10\",\"0.000\"],[\"78681.60\",\"8.763\"],[\"78703.60\",\"0.754\"],[\"78801.00\",\"12.547\"],[\"78866.70\",\"7.449\"],[\"79000.00\",\"44.122\"],[\"79199.00\",\"4.246\"],[\"79475.30\",\"0.001\"],[\"79582.70\",\"0.204\"]],\"a\":[[\"79598.00\",\"0.107\"],[\"79598.60\",\"0.027\"],[\"79598.80\",\"0.005\"],[\"79598.90\",\"0.001\"],[\"79599.10\",\"0.078\"],[\"79600.10\",\"0.028\"],[\"79600.20\",\"0.027\"],[\"79600.30\",\"0.028\"],[\"79601.10\",\"0.022\"],[\"79602.80\",\"0.078\"],[\"79640.90\",\"0.048\"],[\"79641.10\",\"0.252\"],[\"79693.20\",\"0.001\"],[\"79701.60\",\"0.023\"],[\"79702.70\",\"0.053\"],[\"79705.30\",\"0.003\"],[\"79719.80\",\"0.000\"],[\"80313.60\",\"1.245\"],[\"80393.10\",\"10.298\"],[\"80459.10\",\"0.000\"],[\"80577.80\",\"5.085\"],[\"81825.80\",\"2.195\"]],\"st\":1}}"}
{"receive_ns":1788567709167505000,"stream":"btcusdt@bookTicker","event_type":"bookTicker","event_time_ms":1788567709182,"raw_json":"{\"stream\":\"btcusdt@bookTicker\",\"data\":{\"e\":\"bookTicker\",\"u\":11478506985933,\"s\":\"BTCUSDT\",\"ps\":\"BTCUSDT\",\"b\":\"79597.00\",\"B\":\"4.436\",\"a\":\"79597.10\",\"A\":\"4.480\",\"T\":1788567709182,\"E\":1788567709182,\"st\":1}}"}
{"receive_ns":1788567709175884000,"stream":"btcusdt@bookTicker","event_type":"bookTicker","event_time_ms":1788567709191,"raw_json":"{\"stream\":\"btcusdt@bookTicker\",\"data\":{\"e\":\"bookTicker\",\"u\":11478506986401,\"s\":\"BTCUSDT\",\"ps\":\"BTCUSDT\",\"b\":\"79597.00\",\"B\":\"5.223\",\"a\":\"79597.10\",\"A\":\"4.480\",\"T\":1788567709191,\"E\":1788567709191,\"st\":1}}"}
{"receive_ns":1788567709192388000,"stream":"btcusdt@bookTicker","event_type":"bookTicker","event_time_ms":1788567709192,"raw_json":"{\"stream\":\"btcusdt@bookTicker\",\"data\":{\"e\":\"bookTicker\",\"u\":11478506986463,\"s\":\"BTCUSDT\",\"ps\":\"BTCUSDT\",\"b\":\"79597.00\",\"B\":\"5.222\",\"a\":\"79597.10\",\"A\":\"4.480\",\"T\":1788567709192,\"E\":1788567709192,\"st\":1}}"}
{"receive_ns":1788567709243889000,"stream":"btcusdt@depth@100ms","event_type":"depthUpdate","event_time_ms":1788567709251,"raw_json":"{\"stream\":\"btcusdt@depth@100ms\",\"data\":{\"e\":\"depthUpdate\",\"E\":1788567709251,\"T\":1788567709249,\"s\":\"BTCUSDT\",\"ps\":\"BTCUSDT\",\"U\":11478506984355,\"u\":11478506989928,\"pu\":11478506984328,\"b\":[[\"29297.00\",\"1.281\"],[\"29397.00\",\"0.819\"],[\"71637.30\",\"0.043\"],[\"76413.10\",\"0.002\"],[\"78585.20\",\"1.882\"],[\"78628.50\",\"10.161\"],[\"78801.00\",\"12.547\"],[\"78880.60\",\"6.960\"],[\"79199.00\",\"4.246\"],[\"79435.90\",\"2.594\"],[\"79452.00\",\"0.527\"],[\"79475.30\",\"0.479\"],[\"79514.00\",\"0.136\"],[\"79542.20\",\"0.002\"],[\"79551.30\",\"1.568\"],[\"79565.30\",\"0.911\"],[\"79589.90\",\"0.000\"],[\"79591.70\",\"0.081\"],[\"79596.90\",\"2.472\"],[\"79597.00\",\"5.222\"]],\"a\":[[\"79597.30\",\"0.100\"],[\"79597.40\",\"0.000\"],[\"79597.50\",\"0.000\"],[\"79597.60\",\"0.002\"],[\"79598.00\",\"0.081\"],[\"79598.60\",\"0.001\"],[\"79599.10\",\"0.002\"],[\"79641.90\",\"0.139\"],[\"79647.00\",\"3.401\"],[\"79691.90\",\"0.062\"],[\"79692.00\",\"2.253\"],[\"79697.80\",\"0.135\"],[\"79702.70\",\"0.054\"],[\"79719.80\",\"0.476\"],[\"79759.20\",\"2.639\"],[\"79782.40\",\"0.239\"],[\"80393.10\",\"10.298\"],[\"80614.60\",\"7.431\"]],\"st\":1}}"}
{"receive_ns":1788567709344913000,"stream":"btcusdt@depth@100ms","event_type":"depthUpdate","event_time_ms":1788567709353,"raw_json":"{\"stream\":\"btcusdt@depth@100ms\",\"data\":{\"e\":\"depthUpdate\",\"E\":1788567709353,\"T\":1788567709350,\"s\":\"BTCUSDT\",\"ps\":\"BTCUSDT\",\"U\":11478506990008,\"u\":11478506995561,\"pu\":11478506989928,\"b\":[[\"1000.00\",\"24.604\"],[\"29297.00\",\"1.456\"],[\"29397.00\",\"0.644\"],[\"63678.00\",\"0.003\"],[\"71637.30\",\"0.043\"],[\"75617.10\",\"0.014\"],[\"75617.20\",\"0.008\"],[\"78244.10\",\"0.895\"],[\"78363.20\",\"9.430\"],[\"78442.80\",\"12.459\"],[\"78801.00\",\"12.547\"],[\"79199.00\",\"4.245\"]],\"a\":[[\"79657.60\",\"0.016\"],[\"80393.10\",\"10.298\"],[\"80567.60\",\"0.000\"],[\"80605.40\",\"3.717\"],[\"80697.20\",\"8.862\"],[\"80711.50\",\"27.103\"],[\"80798.20\",\"0.000\"]],\"st\":1}}"}
{"receive_ns":1788567709355200000,"stream":"btcusdt@bookTicker","event_type":"bookTicker","event_time_ms":1788567709376,"raw_json":"{\"stream\":\"btcusdt@bookTicker\",\"data\":{\"e\":\"bookTicker\",\"u\":11478506996478,\"s\":\"BTCUSDT\",\"ps\":\"BTCUSDT\",\"b\":\"79597.00\",\"B\":\"5.171\",\"a\":\"79597.10\",\"A\":\"4.480\",\"T\":1788567709376,\"E\":1788567709376,\"st\":1}}"}
{"receive_ns":1788567709367291000,"stream":"btcusdt@bookTicker","event_type":"bookTicker","event_time_ms":1788567709378,"raw_json":"{\"stream\":\"btcusdt@bookTicker\",\"data\":{\"e\":\"bookTicker\",\"u\":11478506996562,\"s\":\"BTCUSDT\",\"ps\":\"BTCUSDT\",\"b\":\"79597.00\",\"B\":\"5.043\",\"a\":\"79597.10\",\"A\":\"4.480\",\"T\":1788567709378,\"E\":1788567709378,\"st\":1}}"}
{"receive_ns":1788567709378478000,"stream":"btcusdt@bookTicker","event_type":"bookTicker","event_time_ms":1788567709379,"raw_json":"{\"stream\":\"btcusdt@bookTicker\",\"data\":{\"e\":\"bookTicker\",\"u\":11478506996590,\"s\":\"BTCUSDT\",\"ps\":\"BTCUSDT\",\"b\":\"79597.00\",\"B\":\"5.097\",\"a\":\"79597.10\",\"A\":\"4.480\",\"T\":1788567709379,\"E\":1788567709379,\"st\":1}}"}
{"receive_ns":1788567709386691000,"stream":"btcusdt@bookTicker","event_type":"bookTicker","event_time_ms":1788567709380,"raw_json":"{\"stream\":\"btcusdt@bookTicker\",\"data\":{\"e\":\"bookTicker\",\"u\":11478506996654,\"s\":\"BTCUSDT\",\"ps\":\"BTCUSDT\",\"b\":\"79597.00\",\"B\":\"5.098\",\"a\":\"79597.10\",\"A\":\"4.480\",\"T\":1788567709380,\"E\":1788567709380,\"st\":1}}"}
{"receive_ns":1788567709404124000,"stream":"btcusdt@bookTicker","event_type":"bookTicker","event_time_ms":1788567709381,"raw_json":"{\"stream\":\"btcusdt@bookTicker\",\"data\":{\"e\":\"bookTicker\",\"u\":11478506996763,\"s\":\"BTCUSDT\",\"ps\":\"BTCUSDT\",\"b\":\"79597.00\",\"B\":\"5.231\",\"a\":\"79597.10\",\"A\":\"4.480\",\"T\":1788567709381,\"E\":1788567709381,\"st\":1}}"}
{"receive_ns":1788567709448463000,"stream":"btcusdt@depth@100ms","event_type":"depthUpdate","event_time_ms":1788567709455,"raw_json":"{\"stream\":\"btcusdt@depth@100ms\",\"data\":{\"e\":\"depthUpdate\",\"E\":1788567709455,\"T\":1788567709454,\"s\":\"BTCUSDT\",\"ps\":\"BTCUSDT\",\"U\":11478506995672,\"u\":11478506999720,\"pu\":11478506995561,\"b\":[[\"1000.00\",\"24.604\"],[\"29297.00\",\"1.638\"],[\"29397.00\",\"0.462\"],[\"63678.00\",\"0.000\"],[\"71637.30\",\"0.043\"],[\"76413.10\",\"0.000\"],[\"78602.00\",\"14.750\"],[\"78801.00\",\"12.547\"],[\"79017.30\",\"0.000\"],[\"79435.90\",\"2.693\"],[\"79475.30\",\"0.495\"],[\"79597.00\",\"5.231\"]],\"a\":[[\"79597.50\",\"0.000\"],[\"79598.40\",\"0.027\"],[\"79641.10\",\"0.252\"],[\"79641.30\",\"0.406\"],[\"79641.40\",\"0.001\"],[\"79641.90\",\"0.014\"],[\"79719.80\",\"0.493\"],[\"79759.20\",\"2.725\"],[\"79995.10\",\"4.367\"],[\"80393.10\",\"10.298\"]],\"st\":1}}"}
{"receive_ns":1788567709463632000,"stream":"btcusdt@trade","event_type":"trade","event_time_ms":1788567709454,"raw_json":"{\"stream\":\"btcusdt@trade\",\"data\":{\"e\":\"trade\",\"E\":1788567709454,\"T\":1788567709454,\"s\":\"BTCUSDT\",\"t\":8054122549,\"p\":\"0\",\"q\":\"0\",\"X\":\"NA\",\"m\":false,\"st\":1}}"}
{"receive_ns":1788567709475239000,"stream":"btcusdt@bookTicker","event_type":"bookTicker","event_time_ms":1788567709457,"raw_json":"{\"stream\":\"btcusdt@bookTicker\",\"data\":{\"e\":\"bookTicker\",\"u\":11478506999861,\"s\":\"BTCUSDT\",\"ps\":\"BTCUSDT\",\"b\":\"79597.00\",\"B\":\"5.208\",\"a\":\"79597.10\",\"A\":\"4.480\",\"T\":1788567709456,\"E\":1788567709457,\"st\":1}}"}
{"receive_ns":1788567709486074000,"stream":"btcusdt@bookTicker","event_type":"bookTicker","event_time_ms":1788567709461,"raw_json":"{\"stream\":\"btcusdt@bookTicker\",\"data\":{\"e\":\"bookTicker\",\"u\":11478507000136,\"s\":\"BTCUSDT\",\"ps\":\"BTCUSDT\",\"b\":\"79597.00\",\"B\":\"5.231\",\"a\":\"79597.10\",\"A\":\"4.480\",\"T\":1788567709461,\"E\":1788567709461,\"st\":1}}"}
{"receive_ns":1788567709498354000,"stream":"btcusdt@bookTicker","event_type":"bookTicker","event_time_ms":1788567709463,"raw_json":"{\"stream\":\"btcusdt@bookTicker\",\"data\":{\"e\":\"bookTicker\",\"u\":11478507000176,\"s\":\"BTCUSDT\",\"ps\":\"BTCUSDT\",\"b\":\"79597.00\",\"B\":\"5.230\",\"a\":\"79597.10\",\"A\":\"4.480\",\"T\":1788567709462,\"E\":1788567709463,\"st\":1}}"}
{"receive_ns":1788567709509994000,"stream":"btcusdt@bookTicker","event_type":"bookTicker","event_time_ms":1788567709470,"raw_json":"{\"stream\":\"btcusdt@bookTicker\",\"data\":{\"e\":\"bookTicker\",\"u\":11478507000453,\"s\":\"BTCUSDT\",\"ps\":\"BTCUSDT\",\"b\":\"79597.00\",\"B\":\"5.235\",\"a\":\"79597.10\",\"A\":\"4.480\",\"T\":1788567709470,\"E\":1788567709470,\"st\":1}}"}
{"receive_ns":1788567709521609000,"stream":"btcusdt@bookTicker","event_type":"bookTicker","event_time_ms":1788567709471,"raw_json":"{\"stream\":\"btcusdt@bookTicker\",\"data\":{\"e\":\"bookTicker\",\"u\":11478507000498,\"s\":\"BTCUSDT\",\"ps\":\"BTCUSDT\",\"b\":\"79597.00\",\"B\":\"5.186\",\"a\":\"79597.10\",\"A\":\"4.480\",\"T\":1788567709471,\"E\":1788567709471,\"st\":1}}"}
{"receive_ns":1788567709533342000,"stream":"btcusdt@bookTicker","event_type":"bookTicker","event_time_ms":1788567709474,"raw_json":"{\"stream\":\"btcusdt@bookTicker\",\"data\":{\"e\":\"bookTicker\",\"u\":11478507000569,\"s\":\"BTCUSDT\",\"ps\":\"BTCUSDT\",\"b\":\"79597.00\",\"B\":\"5.237\",\"a\":\"79597.10\",\"A\":\"4.480\",\"T\":1788567709474,\"E\":1788567709474,\"st\":1}}"}
{"receive_ns":1788567709545802000,"stream":"btcusdt@bookTicker","event_type":"bookTicker","event_time_ms":1788567709475,"raw_json":"{\"stream\":\"btcusdt@bookTicker\",\"data\":{\"e\":\"bookTicker\",\"u\":11478507000594,\"s\":\"BTCUSDT\",\"ps\":\"BTCUSDT\",\"b\":\"79597.00\",\"B\":\"5.238\",\"a\":\"79597.10\",\"A\":\"4.480\",\"T\":1788567709475,\"E\":1788567709475,\"st\":1}}"}
{"receive_ns":1788567709547408000,"stream":"btcusdt@bookTicker","event_type":"bookTicker","event_time_ms":1788567709478,"raw_json":"{\"stream\":\"btcusdt@bookTicker\",\"data\":{\"e\":\"bookTicker\",\"u\":11478507000715,\"s\":\"BTCUSDT\",\"ps\":\"BTCUSDT\",\"b\":\"79597.00\",\"B\":\"5.238\",\"a\":\"79597.10\",\"A\":\"4.479\",\"T\":1788567709478,\"E\":1788567709478,\"st\":1}}"}
{"receive_ns":1788567709563136000,"stream":"btcusdt@trade","event_type":"trade","event_time_ms":1788567709478,"raw_json":"{\"stream\":\"btcusdt@trade\",\"data\":{\"e\":\"trade\",\"E\":1788567709478,\"T\":1788567709478,\"s\":\"BTCUSDT\",\"t\":8054122550,\"p\":\"79597.10\",\"q\":\"0.001\",\"X\":\"MARKET\",\"m\":false,\"st\":1}}"}
{"receive_ns":1788567709569805000,"stream":"btcusdt@bookTicker","event_type":"bookTicker","event_time_ms":1788567709502,"raw_json":"{\"stream\":\"btcusdt@bookTicker\",\"data\":{\"e\":\"bookTicker\",\"u\":11478507002557,\"s\":\"BTCUSDT\",\"ps\":\"BTCUSDT\",\"b\":\"79597.00\",\"B\":\"5.238\",\"a\":\"79597.10\",\"A\":\"4.495\",\"T\":1788567709502,\"E\":1788567709502,\"st\":1}}"}
{"receive_ns":1788567709576255000,"stream":"btcusdt@bookTicker","event_type":"bookTicker","event_time_ms":1788567709503,"raw_json":"{\"stream\":\"btcusdt@bookTicker\",\"data\":{\"e\":\"bookTicker\",\"u\":11478507002583,\"s\":\"BTCUSDT\",\"ps\":\"BTCUSDT\",\"b\":\"79597.00\",\"B\":\"5.238\",\"a\":\"79597.10\",\"A\":\"4.498\",\"T\":1788567709503,\"E\":1788567709503,\"st\":1}}"}
{"receive_ns":1788567709585633000,"stream":"btcusdt@depth@100ms","event_type":"depthUpdate","event_time_ms":1788567709557,"raw_json":"{\"stream\":\"btcusdt@depth@100ms\",\"data\":{\"e\":\"depthUpdate\",\"E\":1788567709557,\"T\":1788567709556,\"s\":\"BTCUSDT\",\"ps\":\"BTCUSDT\",\"U\":11478506999827,\"u\":11478507005098,\"pu\":11478506999720,\"b\":[[\"29197.00\",\"0.021\"],[\"29297.00\",\"1.771\"],[\"29397.00\",\"0.308\"],[\"71637.30\",\"0.043\"],[\"71673.00\",\"0.000\"],[\"75617.10\",\"0.016\"],[\"76413.10\",\"0.002\"],[\"78005.10\",\"10.703\"],[\"78514.70\",\"2.625\"],[\"78522.40\",\"8.153\"],[\"78602.00\",\"14.966\"],[\"78801.00\",\"12.547\"],[\"79199.00\",\"4.245\"],[\"79417.50\",\"3.142\"],[\"79448.50\",\"0.000\"],[\"79448.70\",\"0.032\"],[\"79509.80\",\"0.051\"],[\"79509.90\",\"0.196\"],[\"79564.20\",\"0.004\"],[\"79564.70\",\"0.803\"],[\"79597.00\",\"5.238\"]],\"a\":[[\"79597.10\",\"4.498\"],[\"79597.60\",\"0.002\"],[\"79597.70\",\"0.147\"],[\"79598.10\",\"0.000\"],[\"79639.80\",\"0.028\"],[\"79640.40\",\"0.110\"],[\"79641.30\",\"0.281\"],[\"79641.90\",\"0.139\"],[\"79685.10\",\"0.050\"],[\"79741.50\",\"3.541\"],[\"80393.10\",\"10.298\"],[\"80519.40\",\"0.631\"],[\"80697.20\",\"8.614\"]],\"st\":1}}"}
{"receive_ns":1788567709596706000,"stream":"btcusdt@bookTicker","event_type":"bookTicker","event_time_ms":1788567709562,"raw_json":"{\"stream\":\"btcusdt@bookTicker\",\"data\":{\"e\":\"bookTicker\",\"u\":11478507005353,\"s\":\"BTCUSDT\",\"ps\":\"BTCUSDT\",\"b\":\"79597.00\",\"B\":\"5.177\",\"a\":\"79597.10\",\"A\":\"4.498\",\"T\":1788567709562,\"E\":1788567709562,\"st\":1}}"}
{"receive_ns":1788567709608218000,"stream":"btcusdt@bookTicker","event_type":"bookTicker","event_time_ms":1788567709565,"raw_json":"{\"stream\":\"btcusdt@bookTicker\",\"data\":{\"e\":\"bookTicker\",\"u\":11478507005476,\"s\":\"BTCUSDT\",\"ps\":\"BTCUSDT\",\"b\":\"79597.00\",\"B\":\"5.237\",\"a\":\"79597.10\",\"A\":\"4.498\",\"T\":1788567709565,\"E\":1788567709565,\"st\":1}}"}
{"receive_ns":1788567709646741000,"stream":"btcusdt@depth@100ms","event_type":"depthUpdate","event_time_ms":1788567709659,"raw_json":"{\"stream\":\"btcusdt@depth@100ms\",\"data\":{\"e\":\"depthUpdate\",\"E\":1788567709659,\"T\":1788567709657,\"s\":\"BTCUSDT\",\"ps\":\"BTCUSDT\",\"U\":11478507005157,\"u\":11478507009994,\"pu\":11478507005098,\"b\":[[\"1000.00\",\"24.604\"],[\"29197.00\",\"0.084\"],[\"29297.00\",\"1.827\"],[\"29397.00\",\"0.189\"],[\"63678.00\",\"0.000\"],[\"71637.30\",\"0.043\"],[\"76413.10\",\"0.000\"],[\"77991.20\",\"1.881\"],[\"78466.70\",\"2.142\"],[\"78548.20\",\"1.781\"],[\"78801.00\",\"12.547\"],[\"79448.50\",\"0.032\"],[\"79448.70\",\"0.000\"],[\"79597.00\",\"5.237\"]],\"a\":[[\"79597.70\",\"0.173\"],[\"79598.20\",\"0.028\"],[\"79598.50\",\"0.378\"],[\"79600.30\",\"0.002\"],[\"80393.10\",\"10.298\"],[\"87556.90\",\"0.000\"]],\"st\":1}}"}
{"receive_ns":1788567709657827000,"stream":"btcusdt@bookTicker","event_type":"bookTicker","event_time_ms":1788567709659,"raw_json":"{\"stream\":\"btcusdt@bookTicker\",\"data\":{\"e\":\"bookTicker\",\"u\":11478507010214,\"s\":\"BTCUSDT\",\"ps\":\"BTCUSDT\",\"b\":\"79597.00\",\"B\":\"5.237\",\"a\":\"79597.10\",\"A\":\"4.524\",\"T\":1788567709659,\"E\":1788567709659,\"st\":1}}"}
{"receive_ns":1788567709671608000,"stream":"btcusdt@bookTicker","event_type":"bookTicker","event_time_ms":1788567709661,"raw_json":"{\"stream\":\"btcusdt@bookTicker\",\"data\":{\"e\":\"bookTicker\",\"u\":11478507010318,\"s\":\"BTCUSDT\",\"ps\":\"BTCUSDT\",\"b\":\"79597.00\",\"B\":\"5.237\",\"a\":\"79597.10\",\"A\":\"4.522\",\"T\":1788567709660,\"E\":1788567709661,\"st\":1}}"}
{"receive_ns":1788567709676927000,"stream":"btcusdt@bookTicker","event_type":"bookTicker","event_time_ms":1788567709661,"raw_json":"{\"stream\":\"btcusdt@bookTicker\",\"data\":{\"e\":\"bookTicker\",\"u\":11478507010365,\"s\":\"BTCUSDT\",\"ps\":\"BTCUSDT\",\"b\":\"79597.00\",\"B\":\"5.221\",\"a\":\"79597.10\",\"A\":\"4.522\",\"T\":1788567709661,\"E\":1788567709661,\"st\":1}}"}
{"receive_ns":1788567709699918000,"stream":"btcusdt@bookTicker","event_type":"bookTicker","event_time_ms":1788567709686,"raw_json":"{\"stream\":\"btcusdt@bookTicker\",\"data\":{\"e\":\"bookTicker\",\"u\":11478507011559,\"s\":\"BTCUSDT\",\"ps\":\"BTCUSDT\",\"b\":\"79597.00\",\"B\":\"5.237\",\"a\":\"79597.10\",\"A\":\"4.522\",\"T\":1788567709686,\"E\":1788567709686,\"st\":1}}"}
{"receive_ns":1788567709708876000,"stream":"btcusdt@bookTicker","event_type":"bookTicker","event_time_ms":1788567709687,"raw_json":"{\"stream\":\"btcusdt@bookTicker\",\"data\":{\"e\":\"bookTicker\",\"u\":11478507011644,\"s\":\"BTCUSDT\",\"ps\":\"BTCUSDT\",\"b\":\"79597.00\",\"B\":\"5.237\",\"a\":\"79597.10\",\"A\":\"4.524\",\"T\":1788567709687,\"E\":1788567709687,\"st\":1}}"}
{"receive_ns":1788567709714554000,"stream":"btcusdt@bookTicker","event_type":"bookTicker","event_time_ms":1788567709689,"raw_json":"{\"stream\":\"btcusdt@bookTicker\",\"data\":{\"e\":\"bookTicker\",\"u\":11478507011686,\"s\":\"BTCUSDT\",\"ps\":\"BTCUSDT\",\"b\":\"79597.00\",\"B\":\"5.197\",\"a\":\"79597.10\",\"A\":\"4.524\",\"T\":1788567709689,\"E\":1788567709689,\"st\":1}}"}
{"receive_ns":1788567709743938000,"stream":"btcusdt@depth@100ms","event_type":"depthUpdate","event_time_ms":1788567709761,"raw_json":"{\"stream\":\"btcusdt@depth@100ms\",\"data\":{\"e\":\"depthUpdate\",\"E\":1788567709761,\"T\":1788567709757,\"s\":\"BTCUSDT\",\"ps\":\"BTCUSDT\",\"U\":11478507010119,\"u\":11478507015641,\"pu\":11478507009994,\"b\":[[\"1000.00\",\"24.604\"],[\"29197.00\",\"0.140\"],[\"29297.00\",\"1.890\"],[\"29397.00\",\"0.070\"],[\"63678.00\",\"0.000\"],[\"71637.30\",\"0.043\"],[\"76413.10\",\"0.002\"],[\"78801.00\",\"12.547\"],[\"79277.40\",\"0.000\"],[\"79539.60\",\"0.000\"],[\"79565.30\",\"0.905\"],[\"79568.80\",\"0.011\"],[\"79573.30\",\"0.002\"],[\"79593.70\",\"0.000\"],[\"79594.40\",\"0.004\"],[\"79595.00\",\"0.028\"],[\"79595.10\",\"0.028\"],[\"79595.20\",\"0.028\"],[\"79596.00\",\"0.108\"],[\"79596.20\",\"0.026\"],[\"79596.30\",\"0.000\"],[\"79596.50\",\"0.005\"],[\"79596.60\",\"0.000\"],[\"79596.70\",\"0.000\"],[\"79596.90\",\"2.446\"],[\"79597.00\",\"5.197\"]],\"a\":[[\"79597.10\",\"4.524\"],[\"79597.30\",\"0.102\"],[\"79597.40\",\"0.026\"],[\"79597.60\",\"0.000\"],[\"79599.10\",\"0.078\"],[\"79600.10\",\"0.002\"],[\"79600.20\",\"0.001\"],[\"79613.20\",\"0.005\"],[\"79620.00\",\"0.598\"],[\"79621.10\",\"0.130\"],[\"79641.60\",\"0.002\"],[\"79641.90\",\"0.014\"],[\"79642.60\",\"0.126\"],[\"79657.60\",\"0.023\"],[\"79995.10\",\"4.366\"],[\"80393.10\",\"10.298\"],[\"80711.50\",\"27.350\"]],\"st\":1}}"}
{"receive_ns":1788567709845111000,"stream":"btcusdt@depth@100ms","event_type":"depthUpdate","event_time_ms":1788567709863,"raw_json":"{\"stream\":\"btcusdt@depth@100ms\",\"data\":{\"e\":\"depthUpdate\",\"E\":1788567709863,\"T\":1788567709861,\"s\":\"BTCUSDT\",\"ps\":\"BTCUSDT\",\"U\":11478507015798,\"u\":11478507020119,\"pu\":11478507015641,\"b\":[[\"29197.00\",\"0.252\"],[\"29297.00\",\"1.848\"],[\"29397.00\",\"0.000\"],[\"63678.00\",\"0.000\"],[\"71637.30\",\"0.043\"],[\"78801.00\",\"12.547\"],[\"78859.10\",\"0.008\"],[\"79199.00\",\"4.245\"]],\"a\":[[\"79641.30\",\"0.281\"],[\"79642.50\",\"0.000\"],[\"79642.60\",\"0.001\"],[\"79642.70\",\"0.125\"],[\"79691.90\",\"0.063\"],[\"79806.90\",\"2.833\"],[\"80393.10\",\"10.298\"],[\"80592.10\",\"9.608\"]],\"st\":1}}"}
{"receive_ns":1788567709949095000,"stream":"btcusdt@depth@100ms","event_type":"depthUpdate","event_time_ms":1788567709965,"raw_json":"{\"stream\":\"btcusdt@depth@100ms\",\"data\":{\"e\":\"depthUpdate\",\"E\":1788567709965,\"T\":1788567709964,\"s\":\"BTCUSDT\",\"ps\":\"BTCUSDT\",\"U\":11478507020275,\"u\":11478507026607,\"pu\":11478507020119,\"b\":[[\"1000.00\",\"24.604\"],[\"29197.00\",\"0.427\"],[\"29297.00\",\"1.673\"],[\"63677.60\",\"0.002\"],[\"71637.30\",\"0.043\"],[\"76413.10\",\"0.000\"],[\"78562.20\",\"10.075\"],[\"78801.00\",\"12.547\"],[\"79199.00\",\"4.246\"],[\"79596.20\",\"0.000\"]],\"a\":[[\"79691.90\",\"0.064\"],[\"79806.90\",\"5.057\"],[\"80393.10\",\"10.298\"],[\"80577.80\",\"4.807\"],[\"80631.90\",\"5.316\"],[\"80734.00\",\"2.705\"],[\"80783.10\",\"0.185\"]],\"st\":1}}"}
{"receive_ns":1788567710006183000,"stream":"btcusdt@bookTicker","event_type":"bookTicker","event_time_ms":1788567710025,"raw_json":"{\"stream\":\"btcusdt@bookTicker\",\"data\":{\"e\":\"bookTicker\",\"u\":11478507029292,\"s\":\"BTCUSDT\",\"ps\":\"BTCUSDT\",\"b\":\"79597.00\",\"B\":\"5.197\",\"a\":\"79597.10\",\"A\":\"4.526\",\"T\":1788567710025,\"E\":1788567710025,\"st\":1}}"}
{"receive_ns":1788567710011849000,"stream":"btcusdt@bookTicker","event_type":"bookTicker","event_time_ms":1788567710034,"raw_json":"{\"stream\":\"btcusdt@bookTicker\",\"data\":{\"e\":\"bookTicker\",\"u\":11478507030370,\"s\":\"BTCUSDT\",\"ps\":\"BTCUSDT\",\"b\":\"79597.00\",\"B\":\"5.197\",\"a\":\"79597.10\",\"A\":\"5.876\",\"T\":1788567710034,\"E\":1788567710034,\"st\":1}}"}
{"receive_ns":1788567710017927000,"stream":"btcusdt@bookTicker","event_type":"bookTicker","event_time_ms":1788567710036,"raw_json":"{\"stream\":\"btcusdt@bookTicker\",\"data\":{\"e\":\"bookTicker\",\"u\":11478507030988,\"s\":\"BTCUSDT\",\"ps\":\"BTCUSDT\",\"b\":\"79597.00\",\"B\":\"5.197\",\"a\":\"79597.10\",\"A\":\"5.874\",\"T\":1788567710035,\"E\":1788567710036,\"st\":1}}"}
{"receive_ns":1788567710028838000,"stream":"btcusdt@bookTicker","event_type":"bookTicker","event_time_ms":1788567710036,"raw_json":"{\"stream\":\"btcusdt@bookTicker\",\"data\":{\"e\":\"bookTicker\",\"u\":11478507031088,\"s\":\"BTCUSDT\",\"ps\":\"BTCUSDT\",\"b\":\"79597.00\",\"B\":\"5.196\",\"a\":\"79597.10\",\"A\":\"5.874\",\"T\":1788567710036,\"E\":1788567710036,\"st\":1}}"}
{"receive_ns":1788567710029323000,"stream":"btcusdt@bookTicker","event_type":"bookTicker","event_time_ms":1788567710036,"raw_json":"{\"stream\":\"btcusdt@bookTicker\",\"data\":{\"e\":\"bookTicker\",\"u\":11478507031119,\"s\":\"BTCUSDT\",\"ps\":\"BTCUSDT\",\"b\":\"79597.00\",\"B\":\"5.120\",\"a\":\"79597.10\",\"A\":\"5.874\",\"T\":1788567710036,\"E\":1788567710036,\"st\":1}}"}
{"receive_ns":1788567710029688000,"stream":"btcusdt@bookTicker","event_type":"bookTicker","event_time_ms":1788567710036,"raw_json":"{\"stream\":\"btcusdt@bookTicker\",\"data\":{\"e\":\"bookTicker\",\"u\":11478507031133,\"s\":\"BTCUSDT\",\"ps\":\"BTCUSDT\",\"b\":\"79597.00\",\"B\":\"4.948\",\"a\":\"79597.10\",\"A\":\"5.874\",\"T\":1788567710036,\"E\":1788567710036,\"st\":1}}"}
{"receive_ns":1788567710030023000,"stream":"btcusdt@bookTicker","event_type":"bookTicker","event_time_ms":1788567710036,"raw_json":"{\"stream\":\"btcusdt@bookTicker\",\"data\":{\"e\":\"bookTicker\",\"u\":11478507031152,\"s\":\"BTCUSDT\",\"ps\":\"BTCUSDT\",\"b\":\"79597.00\",\"B\":\"4.894\",\"a\":\"79597.10\",\"A\":\"5.874\",\"T\":1788567710036,\"E\":1788567710036,\"st\":1}}"}
{"receive_ns":1788567710035917000,"stream":"btcusdt@bookTicker","event_type":"bookTicker","event_time_ms":1788567710036,"raw_json":"{\"stream\":\"btcusdt@bookTicker\",\"data\":{\"e\":\"bookTicker\",\"u\":11478507031229,\"s\":\"BTCUSDT\",\"ps\":\"BTCUSDT\",\"b\":\"79597.00\",\"B\":\"4.843\",\"a\":\"79597.10\",\"A\":\"5.874\",\"T\":1788567710036,\"E\":1788567710036,\"st\":1}}"}
{"receive_ns":1788567710041371000,"stream":"btcusdt@bookTicker","event_type":"bookTicker","event_time_ms":1788567710036,"raw_json":"{\"stream\":\"btcusdt@bookTicker\",\"data\":{\"e\":\"bookTicker\",\"u\":11478507031230,\"s\":\"BTCUSDT\",\"ps\":\"BTCUSDT\",\"b\":\"79597.00\",\"B\":\"4.589\",\"a\":\"79597.10\",\"A\":\"5.874\",\"T\":1788567710036,\"E\":1788567710036,\"st\":1}}"}
{"receive_ns":1788567710047905000,"stream":"btcusdt@bookTicker","event_type":"bookTicker","event_time_ms":1788567710037,"raw_json":"{\"stream\":\"btcusdt@bookTicker\",\"data\":{\"e\":\"bookTicker\",\"u\":11478507031668,\"s\":\"BTCUSDT\",\"ps\":\"BTCUSDT\",\"b\":\"79597.00\",\"B\":\"4.589\",\"a\":\"79597.10\",\"A\":\"5.928\",\"T\":1788567710037,\"E\":1788567710037,\"st\":1}}"}
{"receive_ns":1788567710058612000,"stream":"btcusdt@bookTicker","event_type":"bookTicker","event_time_ms":1788567710037,"raw_json":"{\"stream\":\"btcusdt@bookTicker\",\"data\":{\"e\":\"bookTicker\",\"u\":11478507031998,\"s\":\"BTCUSDT\",\"ps\":\"BTCUSDT\",\"b\":\"79597.00\",\"B\":\"4.589\",\"a\":\"79597.10\",\"A\":\"5.930\",\"T\":1788567710037,\"E\":1788567710037,\"st\":1}}"}
{"receive_ns":1788567710064228000,"stream":"btcusdt@bookTicker","event_type":"bookTicker","event_time_ms":1788567710038,"raw_json":"{\"stream\":\"btcusdt@bookTicker\",\"data\":{\"e\":\"bookTicker\",\"u\":11478507032047,\"s\":\"BTCUSDT\",\"ps\":\"BTCUSDT\",\"b\":\"79597.00\",\"B\":\"4.588\",\"a\":\"79597.10\",\"A\":\"5.930\",\"T\":1788567710037,\"E\":1788567710038,\"st\":1}}"}
{"receive_ns":1788567710069904000,"stream":"btcusdt@bookTicker","event_type":"bookTicker","event_time_ms":1788567710038,"raw_json":"{\"stream\":\"btcusdt@bookTicker\",\"data\":{\"e\":\"bookTicker\",\"u\":11478507032126,\"s\":\"BTCUSDT\",\"ps\":\"BTCUSDT\",\"b\":\"79597.00\",\"B\":\"4.589\",\"a\":\"79597.10\",\"A\":\"5.930\",\"T\":1788567710037,\"E\":1788567710038,\"st\":1}}"}
{"receive_ns":1788567710075743000,"stream":"btcusdt@bookTicker","event_type":"bookTicker","event_time_ms":1788567710038,"raw_json":"{\"stream\":\"btcusdt@bookTicker\",\"data\":{\"e\":\"bookTicker\",\"u\":11478507032358,\"s\":\"BTCUSDT\",\"ps\":\"BTCUSDT\",\"b\":\"79597.00\",\"B\":\"4.588\",\"a\":\"79597.10\",\"A\":\"5.930\",\"T\":1788567710038,\"E\":1788567710038,\"st\":1}}"}
{"receive_ns":1788567710076067000,"stream":"btcusdt@bookTicker","event_type":"bookTicker","event_time_ms":1788567710038,"raw_json":"{\"stream\":\"btcusdt@bookTicker\",\"data\":{\"e\":\"bookTicker\",\"u\":11478507032426,\"s\":\"BTCUSDT\",\"ps\":\"BTCUSDT\",\"b\":\"79597.00\",\"B\":\"4.588\",\"a\":\"79597.10\",\"A\":\"5.931\",\"T\":1788567710038,\"E\":1788567710038,\"st\":1}}"}
{"receive_ns":1788567710077744000,"stream":"btcusdt@bookTicker","event_type":"bookTicker","event_time_ms":1788567710038,"raw_json":"{\"stream\":\"btcusdt@bookTicker\",\"data\":{\"e\":\"bookTicker\",\"u\":11478507032478,\"s\":\"BTCUSDT\",\"ps\":\"BTCUSDT\",\"b\":\"79597.00\",\"B\":\"4.588\",\"a\":\"79597.10\",\"A\":\"5.930\",\"T\":1788567710038,\"E\":1788567710038,\"st\":1}}"}
{"receive_ns":1788567710083586000,"stream":"btcusdt@bookTicker","event_type":"bookTicker","event_time_ms":1788567710039,"raw_json":"{\"stream\":\"btcusdt@bookTicker\",\"data\":{\"e\":\"bookTicker\",\"u\":11478507032822,\"s\":\"BTCUSDT\",\"ps\":\"BTCUSDT\",\"b\":\"79597.00\",\"B\":\"4.588\",\"a\":\"79597.10\",\"A\":\"5.931\",\"T\":1788567710038,\"E\":1788567710039,\"st\":1}}"}
{"receive_ns":1788567710090896000,"stream":"btcusdt@depth@100ms","event_type":"depthUpdate","event_time_ms":1788567710067,"raw_json":"{\"stream\":\"btcusdt@depth@100ms\",\"data\":{\"e\":\"depthUpdate\",\"E\":1788567710067,\"T\":1788567710066,\"s\":\"BTCUSDT\",\"ps\":\"BTCUSDT\",\"U\":11478507026649,\"u\":11478507037785,\"pu\":11478507026607,\"b\":[[\"1000.00\",\"24.604\"],[\"29197.00\",\"0.602\"],[\"29297.00\",\"1.498\"],[\"63677.60\",\"0.000\"],[\"63678.00\",\"0.000\"],[\"71637.30\",\"0.043\"],[\"76413.10\",\"0.002\"],[\"78005.10\",\"10.700\"],[\"78801.00\",\"12.547\"],[\"79448.50\",\"0.000\"],[\"79448.70\",\"0.032\"],[\"79525.30\",\"0.633\"],[\"79541.20\",\"0.002\"],[\"79543.90\",\"0.294\"],[\"79559.80\",\"0.001\"],[\"79562.30\",\"0.001\"],[\"79563.90\",\"0.053\"],[\"79573.20\",\"0.536\"],[\"79573.30\",\"0.441\"],[\"79574.60\",\"0.052\"],[\"79577.70\",\"0.628\"],[\"79578.60\",\"1.101\"],[\"79581.10\",\"0.000\"],[\"79582.70\",\"0.204\"],[\"79583.60\",\"1.476\"],[\"79586.60\",\"0.506\"],[\"79587.00\",\"0.866\"],[\"79587.40\",\"0.001\"],[\"79588.90\",\"0.000\"],[\"79589.90\",\"0.002\"],[\"79590.40\",\"0.001\"],[\"79591.70\",\"0.079\"],[\"79593.20\",\"0.026\"],[\"79593.40\",\"0.448\"],[\"79593.50\",\"0.026\"],[\"79593.60\",\"0.029\"],[\"79593.70\",\"0.030\"],[\"79593.80\",\"0.026\"],[\"79593.90\",\"0.026\"],[\"79594.10\",\"0.188\"],[\"79594.20\",\"0.026\"],[\"79594.30\",\"0.084\"],[\"79594.40\",\"0.000\"],[\"79594.80\",\"0.000\"],[\"79595.00\",\"0.002\"],[\"79595.10\",\"0.002\"],[\"79595.20\",\"0.002\"],[\"79595.30\",\"0.001\"],[\"79595.40\",\"0.002\"],[\"79595.50\",\"0.000\"],[\"79595.60\",\"0.012\"],[\"79595.70\",\"0.077\"],[\"79595.90\",\"0.002\"],[\"79596.00\",\"0.082\"],[\"79596.90\",\"2.452\"],[\"79597.00\",\"4.588\"]],\"a\":[[\"79597.10\",\"5.931\"],[\"79597.60\",\"0.076\"],[\"79597.90\",\"0.021\"],[\"79601.20\",\"0.003\"],[\"79601.30\",\"0.256\"],[\"79602.80\",\"0.077\"],[\"79606.90\",\"0.002\"],[\"79608.50\",\"1.105\"],[\"79610.40\",\"0.562\"],[\"79610.60\",\"0.694\"],[\"79611.90\",\"0.001\"],[\"79616.50\",\"1.148\"],[\"79618.00\",\"0.004\"],[\"79621.00\",\"0.025\"],[\"79625.30\",\"0.637\"],[\"79626.30\",\"0.002\"],[\"79626.50\",\"5.352\"],[\"79642.70\",\"0.000\"],[\"79647.00\",\"3.351\"],[\"79647.10\",\"0.430\"],[\"79668.80\",\"0.034\"],[\"80393.10\",\"10.298\"],[\"80458.40\",\"0.558\"],[\"80552.30\",\"28.858\"],[\"80671.70\",\"10.106\"],[\"80711.50\",\"28.092\"],[\"80813.60\",\"2.595\"]],\"st\":1}}"}
{"receive_ns":1788567710101893000,"stream":"btcusdt@bookTicker","event_type":"bookTicker","event_time_ms":1788567710071,"raw_json":"{\"stream\":\"btcusdt@bookTicker\",\"data\":{\"e\":\"bookTicker\",\"u\":11478507038167,\"s\":\"BTCUSDT\",\"ps\":\"BTCUSDT\",\"b\":\"79597.00\",\"B\":\"4.528\",\"a\":\"79597.10\",\"A\":\"5.931\",\"T\":1788567710071,\"E\":1788567710071,\"st\":1}}"}
{"receive_ns":1788567710107699000,"stream":"btcusdt@bookTicker","event_type":"bookTicker","event_time_ms":1788567710081,"raw_json":"{\"stream\":\"btcusdt@bookTicker\",\"data\":{\"e\":\"bookTicker\",\"u\":11478507038943,\"s\":\"BTCUSDT\",\"ps\":\"BTCUSDT\",\"b\":\"79597.00\",\"B\":\"4.582\",\"a\":\"79597.10\",\"A\":\"5.931\",\"T\":1788567710081,\"E\":1788567710081,\"st\":1}}"}
{"receive_ns":1788567710113325000,"stream":"btcusdt@bookTicker","event_type":"bookTicker","event_time_ms":1788567710122,"raw_json":"{\"stream\":\"btcusdt@bookTicker\",\"data\":{\"e\":\"bookTicker\",\"u\":11478507042600,\"s\":\"BTCUSDT\",\"ps\":\"BTCUSDT\",\"b\":\"79597.00\",\"B\":\"3.981\",\"a\":\"79597.10\",\"A\":\"5.931\",\"T\":1788567710122,\"E\":1788567710122,\"st\":1}}"}
{"receive_ns":1788567710124525000,"stream":"btcusdt@trade","event_type":"trade","event_time_ms":1788567710122,"raw_json":"{\"stream\":\"btcusdt@trade\",\"data\":{\"e\":\"trade\",\"E\":1788567710122,\"T\":1788567710122,\"s\":\"BTCUSDT\",\"t\":8054122551,\"p\":\"79597.00\",\"q\":\"0.577\",\"X\":\"MARKET\",\"m\":true,\"st\":1}}"}
{"receive_ns":1788567710124759000,"stream":"btcusdt@trade","event_type":"trade","event_time_ms":1788567710122,"raw_json":"{\"stream\":\"btcusdt@trade\",\"data\":{\"e\":\"trade\",\"E\":1788567710122,\"T\":1788567710122,\"s\":\"BTCUSDT\",\"t\":8054122552,\"p\":\"79597.00\",\"q\":\"0.024\",\"X\":\"MARKET\",\"m\":true,\"st\":1}}"}
{"receive_ns":1788567710130294000,"stream":"btcusdt@bookTicker","event_type":"bookTicker","event_time_ms":1788567710123,"raw_json":"{\"stream\":\"btcusdt@bookTicker\",\"data\":{\"e\":\"bookTicker\",\"u\":11478507042665,\"s\":\"BTCUSDT\",\"ps\":\"BTCUSDT\",\"b\":\"79597.00\",\"B\":\"4.567\",\"a\":\"79597.10\",\"A\":\"5.931\",\"T\":1788567710123,\"E\":1788567710123,\"st\":1}}"}
{"receive_ns":1788567710147334000,"stream":"btcusdt@bookTicker","event_type":"bookTicker","event_time_ms":1788567710124,"raw_json":"{\"stream\":\"btcusdt@bookTicker\",\"data\":{\"e\":\"bookTicker\",\"u\":11478507042700,\"s\":\"BTCUSDT\",\"ps\":\"BTCUSDT\",\"b\":\"79597.00\",\"B\":\"4.568\",\"a\":\"79597.10\",\"A\":\"5.931\",\"T\":1788567710124,\"E\":1788567710124,\"st\":1}}"}
{"receive_ns":1788567710152772000,"stream":"btcusdt@bookTicker","event_type":"bookTicker","event_time_ms":1788567710124,"raw_json":"{\"stream\":\"btcusdt@bookTicker\",\"data\":{\"e\":\"bookTicker\",\"u\":11478507042708,\"s\":\"BTCUSDT\",\"ps\":\"BTCUSDT\",\"b\":\"79597.00\",\"B\":\"4.568\",\"a\":\"79597.10\",\"A\":\"5.932\",\"T\":1788567710124,\"E\":1788567710124,\"st\":1}}"}
{"receive_ns":1788567710153050000,"stream":"btcusdt@bookTicker","event_type":"bookTicker","event_time_ms":1788567710124,"raw_json":"{\"stream\":\"btcusdt@bookTicker\",\"data\":{\"e\":\"bookTicker\",\"u\":11478507042888,\"s\":\"BTCUSDT\",\"ps\":\"BTCUSDT\",\"b\":\"79597.00\",\"B\":\"4.567\",\"a\":\"79597.10\",\"A\":\"5.932\",\"T\":1788567710124,\"E\":1788567710124,\"st\":1}}"}
{"receive_ns":1788567710162068000,"stream":"btcusdt@bookTicker","event_type":"bookTicker","event_time_ms":1788567710125,"raw_json":"{\"stream\":\"btcusdt@bookTicker\",\"data\":{\"e\":\"bookTicker\",\"u\":11478507042907,\"s\":\"BTCUSDT\",\"ps\":\"BTCUSDT\",\"b\":\"79597.00\",\"B\":\"4.566\",\"a\":\"79597.10\",\"A\":\"5.932\",\"T\":1788567710124,\"E\":1788567710125,\"st\":1}}"}
{"receive_ns":1788567710168919000,"stream":"btcusdt@depth@100ms","event_type":"depthUpdate","event_time_ms":1788567710169,"raw_json":"{\"stream\":\"btcusdt@depth@100ms\",\"data\":{\"e\":\"depthUpdate\",\"E\":1788567710169,\"T\":1788567710165,\"s\":\"BTCUSDT\",\"ps\":\"BTCUSDT\",\"U\":11478507037943,\"u\":11478507046223,\"pu\":11478507037785,\"b\":[[\"29197.00\",\"0.784\"],[\"29297.00\",\"1.316\"],[\"63678.00\",\"0.000\"],[\"71637.30\",\"0.043\"],[\"76413.10\",\"0.000\"],[\"78230.50\",\"5.104\"],[\"78469.30\",\"9.547\"],[\"78801.00\",\"12.547\"],[\"79199.00\",\"4.236\"],[\"79538.00\",\"0.001\"],[\"79557.60\",\"0.003\"],[\"79558.70\",\"0.000\"],[\"79565.20\",\"2.566\"],[\"79573.30\",\"0.002\"],[\"79573.40\",\"0.629\"],[\"79573.50\",\"0.440\"],[\"79573.70\",\"0.001\"],[\"79574.50\",\"0.001\"],[\"79574.60\",\"0.052\"],[\"79582.90\",\"0.333\"],[\"79583.20\",\"0.076\"],[\"79584.00\",\"0.012\"],[\"79584.30\",\"0.077\"],[\"79584.60\",\"1.652\"],[\"79585.10\",\"0.000\"],[\"79585.50\",\"0.218\"],[\"79587.20\",\"0.001\"],[\"79587.80\",\"1.590\"],[\"79588.00\",\"0.008\"],[\"79589.50\",\"0.075\"],[\"79589.90\",\"0.000\"],[\"79590.10\",\"0.202\"],[\"79590.60\",\"0.253\"],[\"79590.90\",\"0.070\"],[\"79591.00\",\"0.000\"],[\"79591.20\",\"0.008\"],[\"79591.40\",\"0.003\"],[\"79591.50\",\"0.000\"],[\"79591.60\",\"0.000\"],[\"79591.70\",\"0.105\"],[\"79591.80\",\"1.537\"],[\"79591.90\",\"0.485\"],[\"79592.10\",\"0.207\"],[\"79592.20\",\"0.026\"],[\"79592.30\",\"0.026\"],[\"79592.40\",\"0.028\"],[\"79592.60\",\"0.026\"],[\"79592.90\",\"0.028\"],[\"79593.00\",\"0.081\"],[\"79593.20\",\"0.000\"],[\"79593.30\",\"0.004\"],[\"79593.40\",\"0.001\"],[\"79593.50\",\"0.000\"],[\"79593.60\",\"0.003\"],[\"79593.70\",\"0.000\"],[\"79593.80\",\"0.000\"],[\"79593.90\",\"0.000\"],[\"79594.10\",\"0.162\"],[\"79594.20\",\"0.000\"],[\"79594.30\",\"0.058\"],[\"79594.60\",\"0.001\"],[\"79595.70\",\"0.001\"],[\"79597.00\",\"4.566\"]],\"a\":[[\"79597.10\",\"5.932\"],[\"79607.50\",\"0.004\"],[\"79610.60\",\"0.003\"],[\"79612.50\",\"0.001\"],[\"79617.20\",\"0.628\"],[\"79619.30\",\"0.063\"],[\"79621.00\",\"0.003\"],[\"79626.50\",\"4.523\"],[\"79643.30\",\"0.353\"],[\"79691.90\",\"0.065\"],[\"79701.50\",\"0.343\"],[\"79705.10\",\"0.031\"],[\"79723.70\",\"0.002\"],[\"79723.90\",\"0.598\"],[\"80313.50\",\"0.193\"],[\"80393.10\",\"10.298\"],[\"81189.00\",\"10.509\"]],\"st\":1}}"}
{"receive_ns":1788567710174660000,"stream":"btcusdt@bookTicker","event_type":"bookTicker","event_time_ms":1788567710196,"raw_json":"{\"stream\":\"btcusdt@bookTicker\",\"data\":{\"e\":\"bookTicker\",\"u\":11478507048559,\"s\":\"BTCUSDT\",\"ps\":\"BTCUSDT\",\"b\":\"79597.00\",\"B\":\"4.561\",\"a\":\"79597.10\",\"A\":\"5.932\",\"T\":1788567710196,\"E\":1788567710196,\"st\":1}}"}
{"receive_ns":1788567710185742000,"stream":"btcusdt@bookTicker","event_type":"bookTicker","event_time_ms":1788567710198,"raw_json":"{\"stream\":\"btcusdt@bookTicker\",\"data\":{\"e\":\"bookTicker\",\"u\":11478507048631,\"s\":\"BTCUSDT\",\"ps\":\"BTCUSDT\",\"b\":\"79597.00\",\"B\":\"3.774\",\"a\":\"79597.10\",\"A\":\"5.932\",\"T\":1788567710197,\"E\":1788567710198,\"st\":1}}"}
{"receive_ns":1788567710196629000,"stream":"btcusdt@bookTicker","event_type":"bookTicker","event_time_ms":1788567710199,"raw_json":"{\"stream\":\"btcusdt@bookTicker\",\"data\":{\"e\":\"bookTicker\",\"u\":11478507048713,\"s\":\"BTCUSDT\",\"ps\":\"BTCUSDT\",\"b\":\"79597.00\",\"B\":\"3.774\",\"a\":\"79597.10\",\"A\":\"5.931\",\"T\":1788567710198,\"E\":1788567710199,\"st\":1}}"}
{"receive_ns":1788567710198697000,"stream":"btcusdt@bookTicker","event_type":"bookTicker","event_time_ms":1788567710199,"raw_json":"{\"stream\":\"btcusdt@bookTicker\",\"data\":{\"e\":\"bookTicker\",\"u\":11478507048743,\"s\":\"BTCUSDT\",\"ps\":\"BTCUSDT\",\"b\":\"79597.00\",\"B\":\"3.775\",\"a\":\"79597.10\",\"A\":\"5.931\",\"T\":1788567710199,\"E\":1788567710199,\"st\":1}}"}
{"receive_ns":1788567710204665000,"stream":"btcusdt@bookTicker","event_type":"bookTicker","event_time_ms":1788567710206,"raw_json":"{\"stream\":\"btcusdt@bookTicker\",\"data\":{\"e\":\"bookTicker\",\"u\":11478507049302,\"s\":\"BTCUSDT\",\"ps\":\"BTCUSDT\",\"b\":\"79597.00\",\"B\":\"4.558\",\"a\":\"79597.10\",\"A\":\"5.931\",\"T\":1788567710206,\"E\":1788567710206,\"st\":1}}"}
{"receive_ns":1788567710210904000,"stream":"btcusdt@bookTicker","event_type":"bookTicker","event_time_ms":1788567710208,"raw_json":"{\"stream\":\"btcusdt@bookTicker\",\"data\":{\"e\":\"bookTicker\",\"u\":11478507049449,\"s\":\"BTCUSDT\",\"ps\":\"BTCUSDT\",\"b\":\"79597.00\",\"B\":\"4.557\",\"a\":\"79597.10\",\"A\":\"5.931\",\"T\":1788567710207,\"E\":1788567710208,\"st\":1}}"}
{"receive_ns":1788567710265321000,"stream":"btcusdt@depth@100ms","event_type":"depthUpdate","event_time_ms":1788567710271,"raw_json":"{\"stream\":\"btcusdt@depth@100ms\",\"data\":{\"e\":\"depthUpdate\",\"E\":1788567710271,\"T\":1788567710269,\"s\":\"BTCUSDT\",\"ps\":\"BTCUSDT\",\"U\":11478507046707,\"u\":11478507052991,\"pu\":11478507046223,\"b\":[[\"1000.00\",\"24.604\"],[\"29197.00\",\"0.966\"],[\"29297.00\",\"1.134\"],[\"71637.30\",\"0.043\"],[\"76413.10\",\"0.002\"],[\"78383.10\",\"0.009\"],[\"78691.60\",\"0.003\"],[\"78801.00\",\"12.547\"],[\"79538.00\",\"0.004\"],[\"79564.70\",\"0.678\"],[\"79567.00\",\"0.254\"],[\"79568.80\",\"0.005\"],[\"79569.10\",\"0.628\"],[\"79570.30\",\"0.000\"],[\"79577.00\",\"0.380\"],[\"79578.20\",\"0.002\"],[\"79583.90\",\"0.000\"],[\"79584.60\",\"0.347\"],[\"79584.70\",\"0.001\"],[\"79584.90\",\"0.000\"],[\"79587.90\",\"1.282\"],[\"79588.00\",\"1.662\"],[\"79590.60\",\"0.255\"],[\"79591.10\",\"0.004\"],[\"79591.70\",\"0.079\"],[\"79592.00\",\"0.006\"],[\"79592.90\",\"0.104\"],[\"79593.20\",\"0.026\"],[\"79597.00\",\"4.557\"]],\"a\":[[\"79597.10\",\"5.931\"],[\"79616.80\",\"0.003\"],[\"79622.30\",\"0.091\"],[\"79631.40\",\"0.046\"],[\"79643.30\",\"0.228\"],[\"79655.70\",\"0.000\"],[\"79723.90\",\"0.566\"],[\"79724.60\",\"0.660\"],[\"80393.10\",\"10.298\"]],\"st\":1}}"}
{"receive_ns":1788567710965436000,"stream":"btcusdt@bookTicker","event_type":"bookTicker","event_time_ms":1788567710367,"raw_json":"{\"stream\":\"btcusdt@bookTicker\",\"data\":{\"e\":\"bookTicker\",\"u\":11478507057759,\"s\":\"BTCUSDT\",\"ps\":\"BTCUSDT\",\"b\":\"79597.00\",\"B\":\"4.557\",\"a\":\"79597.10\",\"A\":\"5.838\",\"T\":1788567710367,\"E\":1788567710367,\"st\":1}}"}
{"receive_ns":1788567710965778000,"stream":"btcusdt@trade","event_type":"trade","event_time_ms":1788567710367,"raw_json":"{\"stream\":\"btcusdt@trade\",\"data\":{\"e\":\"trade\",\"E\":1788567710367,\"T\":1788567710367,\"s\":\"BTCUSDT\",\"t\":8054122553,\"p\":\"79597.10\",\"q\":\"0.007\",\"X\":\"MARKET\",\"m\":false,\"st\":1}}"}
{"receive_ns":1788567710971664000,"stream":"btcusdt@trade","event_type":"trade","event_time_ms":1788567710367,"raw_json":"{\"stream\":\"btcusdt@trade\",\"data\":{\"e\":\"trade\",\"E\":1788567710367,\"T\":1788567710367,\"s\":\"BTCUSDT\",\"t\":8054122554,\"p\":\"79597.10\",\"q\":\"0.001\",\"X\":\"MARKET\",\"m\":false,\"st\":1}}"}
{"receive_ns":1788567710971856000,"stream":"btcusdt@trade","event_type":"trade","event_time_ms":1788567710367,"raw_json":"{\"stream\":\"btcusdt@trade\",\"data\":{\"e\":\"trade\",\"E\":1788567710367,\"T\":1788567710367,\"s\":\"BTCUSDT\",\"t\":8054122555,\"p\":\"79597.10\",\"q\":\"0.001\",\"X\":\"MARKET\",\"m\":false,\"st\":1}}"}
{"receive_ns":1788567710972034000,"stream":"btcusdt@trade","event_type":"trade","event_time_ms":1788567710367,"raw_json":"{\"stream\":\"btcusdt@trade\",\"data\":{\"e\":\"trade\",\"E\":1788567710367,\"T\":1788567710367,\"s\":\"BTCUSDT\",\"t\":8054122556,\"p\":\"79597.10\",\"q\":\"0.024\",\"X\":\"MARKET\",\"m\":false,\"st\":1}}"}
{"receive_ns":1788567710972236000,"stream":"btcusdt@trade","event_type":"trade","event_time_ms":1788567710367,"raw_json":"{\"stream\":\"btcusdt@trade\",\"data\":{\"e\":\"trade\",\"E\":1788567710367,\"T\":1788567710367,\"s\":\"BTCUSDT\",\"t\":8054122557,\"p\":\"79597.10\",\"q\":\"0.001\",\"X\":\"MARKET\",\"m\":false,\"st\":1}}"}
{"receive_ns":1788567710972490000,"stream":"btcusdt@trade","event_type":"trade","event_time_ms":1788567710367,"raw_json":"{\"stream\":\"btcusdt@trade\",\"data\":{\"e\":\"trade\",\"E\":1788567710367,\"T\":1788567710367,\"s\":\"BTCUSDT\",\"t\":8054122558,\"p\":\"79597.10\",\"q\":\"0.059\",\"X\":\"MARKET\",\"m\":false,\"st\":1}}"}
{"receive_ns":1788567710978102000,"stream":"btcusdt@bookTicker","event_type":"bookTicker","event_time_ms":1788567710370,"raw_json":"{\"stream\":\"btcusdt@bookTicker\",\"data\":{\"e\":\"bookTicker\",\"u\":11478507057971,\"s\":\"BTCUSDT\",\"ps\":\"BTCUSDT\",\"b\":\"79597.00\",\"B\":\"4.557\",\"a\":\"79597.10\",\"A\":\"5.887\",\"T\":1788567710369,\"E\":1788567710370,\"st\":1}}"}
{"receive_ns":1788567710979229000,"stream":"btcusdt@bookTicker","event_type":"bookTicker","event_time_ms":1788567710370,"raw_json":"{\"stream\":\"btcusdt@bookTicker\",\"data\":{\"e\":\"bookTicker\",\"u\":11478507058018,\"s\":\"BTCUSDT\",\"ps\":\"BTCUSDT\",\"b\":\"79597.00\",\"B\":\"4.558\",\"a\":\"79597.10\",\"A\":\"5.887\",\"T\":1788567710370,\"E\":1788567710370,\"st\":1}}"}
{"receive_ns":1788567710979674000,"stream":"btcusdt@depth@100ms","event_type":"depthUpdate","event_time_ms":1788567710373,"raw_json":"{\"stream\":\"btcusdt@depth@100ms\",\"data\":{\"e\":\"depthUpdate\",\"E\":1788567710373,\"T\":1788567710372,\"s\":\"BTCUSDT\",\"ps\":\"BTCUSDT\",\"U\":11478507053103,\"u\":11478507058128,\"pu\":11478507052991,\"b\":[[\"1000.00\",\"24.604\"],[\"29197.00\",\"1.141\"],[\"29297.00\",\"0.959\"],[\"63678.00\",\"0.000\"],[\"71637.30\",\"0.043\"],[\"75617.20\",\"0.006\"],[\"78108.50\",\"1.149\"],[\"78518.40\",\"0.000\"],[\"78707.50\",\"0.570\"],[\"78801.00\",\"12.547\"],[\"79028.40\",\"0.095\"],[\"79201.10\",\"0.426\"],[\"79475.30\",\"0.001\"],[\"79519.60\",\"0.018\"],[\"79519.70\",\"0.072\"],[\"79566.90\",\"0.001\"],[\"79585.90\",\"0.251\"],[\"79586.60\",\"0.255\"],[\"79587.40\",\"0.003\"],[\"79591.80\",\"1.511\"],[\"79593.90\",\"0.026\"],[\"79594.50\",\"0.000\"],[\"79594.60\",\"0.077\"],[\"79597.00\",\"4.558\"]],\"a\":[[\"79597.10\",\"5.887\"],[\"79610.40\",\"0.123\"],[\"79611.90\",\"0.440\"],[\"79719.80\",\"0.000\"],[\"80393.10\",\"10.298\"],[\"80552.30\",\"29.478\"],[\"80577.80\",\"4.621\"],[\"80718.40\",\"1.250\"]],\"st\":1}}"}
{"receive_ns":1788567710979959000,"stream":"btcusdt@bookTicker","event_type":"bookTicker","event_time_ms":1788567710384,"raw_json":"{\"stream\":\"btcusdt@bookTicker\",\"data\":{\"e\":\"bookTicker\",\"u\":11478507058697,\"s\":\"BTCUSDT\",\"ps\":\"BTCUSDT\",\"b\":\"79597.00\",\"B\":\"4.558\",\"a\":\"79597.10\",\"A\":\"5.886\",\"T\":1788567710384,\"E\":1788567710384,\"st\":1}}"}
{"receive_ns":1788567710990592000,"stream":"btcusdt@bookTicker","event_type":"bookTicker","event_time_ms":1788567710427,"raw_json":"{\"stream\":\"btcusdt@bookTicker\",\"data\":{\"e\":\"bookTicker\",\"u\":11478507061661,\"s\":\"BTCUSDT\",\"ps\":\"BTCUSDT\",\"b\":\"79597.00\",\"B\":\"4.558\",\"a\":\"79597.10\",\"A\":\"7.257\",\"T\":1788567710427,\"E\":1788567710427,\"st\":1}}"}
{"receive_ns":1788567711006983000,"stream":"btcusdt@bookTicker","event_type":"bookTicker","event_time_ms":1788567710428,"raw_json":"{\"stream\":\"btcusdt@bookTicker\",\"data\":{\"e\":\"bookTicker\",\"u\":11478507061724,\"s\":\"BTCUSDT\",\"ps\":\"BTCUSDT\",\"b\":\"79597.00\",\"B\":\"4.558\",\"a\":\"79597.10\",\"A\":\"7.255\",\"T\":1788567710428,\"E\":1788567710428,\"st\":1}}"}
{"receive_ns":1788567711007213000,"stream":"btcusdt@bookTicker","event_type":"bookTicker","event_time_ms":1788567710428,"raw_json":"{\"stream\":\"btcusdt@bookTicker\",\"data\":{\"e\":\"bookTicker\",\"u\":11478507061738,\"s\":\"BTCUSDT\",\"ps\":\"BTCUSDT\",\"b\":\"79597.00\",\"B\":\"4.558\",\"a\":\"79597.10\",\"A\":\"7.256\",\"T\":1788567710428,\"E\":1788567710428,\"st\":1}}"}
{"receive_ns":1788567711019514000,"stream":"btcusdt@bookTicker","event_type":"bookTicker","event_time_ms":1788567710438,"raw_json":"{\"stream\":\"btcusdt@bookTicker\",\"data\":{\"e\":\"bookTicker\",\"u\":11478507062416,\"s\":\"BTCUSDT\",\"ps\":\"BTCUSDT\",\"b\":\"79597.00\",\"B\":\"4.558\",\"a\":\"79597.10\",\"A\":\"7.255\",\"T\":1788567710438,\"E\":1788567710438,\"st\":1}}"}
{"receive_ns":1788567711026273000,"stream":"btcusdt@trade","event_type":"trade","event_time_ms":1788567710438,"raw_json":"{\"stream\":\"btcusdt@trade\",\"data\":{\"e\":\"trade\",\"E\":1788567710438,\"T\":1788567710438,\"s\":\"BTCUSDT\",\"t\":8054122559,\"p\":\"79597.10\",\"q\":\"0.001\",\"X\":\"MARKET\",\"m\":false,\"st\":1}}"}
{"receive_ns":1788567711038221000,"stream":"btcusdt@depth@100ms","event_type":"depthUpdate","event_time_ms":1788567710475,"raw_json":"{\"stream\":\"btcusdt@depth@100ms\",\"data\":{\"e\":\"depthUpdate\",\"E\":1788567710475,\"T\":1788567710473,\"s\":\"BTCUSDT\",\"ps\":\"BTCUSDT\",\"U\":11478507058159,\"u\":11478507064592,\"pu\":11478507058128,\"b\":[[\"29197.00\",\"1.323\"],[\"29297.00\",\"0.777\"],[\"71637.30\",\"0.043\"],[\"76413.10\",\"0.000\"],[\"78104.50\",\"0.600\"],[\"78801.00\",\"12.547\"],[\"79199.00\",\"4.246\"],[\"79448.70\",\"0.000\"],[\"79475.30\",\"0.495\"],[\"79476.20\",\"0.037\"],[\"79525.30\",\"0.635\"],[\"79565.80\",\"0.000\"],[\"79565.90\",\"0.122\"],[\"79566.40\",\"0.252\"],[\"79566.80\",\"0.000\"],[\"79583.60\",\"1.052\"],[\"79587.00\",\"0.717\"],[\"79593.00\",\"0.085\"],[\"79593.30\",\"0.000\"],[\"79594.00\",\"0.076\"],[\"79594.60\",\"0.001\"]],\"a\":[[\"79597.10\",\"7.255\"],[\"79605.60\",\"0.007\"],[\"79606.90\",\"0.001\"],[\"79641.30\",\"0.406\"],[\"79692.70\",\"0.003\"],[\"79719.80\",\"0.493\"],[\"79995.10\",\"4.365\"],[\"80393.10\",\"10.298\"]],\"st\":1}}"}
{"receive_ns":1788567711049576000,"stream":"btcusdt@bookTicker","event_type":"bookTicker","event_time_ms":1788567710497,"raw_json":"{\"stream\":\"btcusdt@bookTicker\",\"data\":{\"e\":\"bookTicker\",\"u\":11478507065898,\"s\":\"BTCUSDT\",\"ps\":\"BTCUSDT\",\"b\":\"79597.00\",\"B\":\"4.558\",\"a\":\"79597.10\",\"A\":\"7.391\",\"T\":1788567710497,\"E\":1788567710497,\"st\":1}}"}
{"receive_ns":1788567711058438000,"stream":"btcusdt@bookTicker","event_type":"bookTicker","event_time_ms":1788567710498,"raw_json":"{\"stream\":\"btcusdt@bookTicker\",\"data\":{\"e\":\"bookTicker\",\"u\":11478507066067,\"s\":\"BTCUSDT\",\"ps\":\"BTCUSDT\",\"b\":\"79597.00\",\"B\":\"4.558\",\"a\":\"79597.10\",\"A\":\"7.393\",\"T\":1788567710498,\"E\":1788567710498,\"st\":1}}"}
{"receive_ns":1788567711075557000,"stream":"btcusdt@bookTicker","event_type":"bookTicker","event_time_ms":1788567710500,"raw_json":"{\"stream\":\"btcusdt@bookTicker\",\"data\":{\"e\":\"bookTicker\",\"u\":11478507066281,\"s\":\"BTCUSDT\",\"ps\":\"BTCUSDT\",\"b\":\"79597.00\",\"B\":\"4.558\",\"a\":\"79597.10\",\"A\":\"7.395\",\"T\":1788567710500,\"E\":1788567710500,\"st\":1}}"}
{"receive_ns":1788567711092662000,"stream":"btcusdt@bookTicker","event_type":"bookTicker","event_time_ms":1788567710547,"raw_json":"{\"stream\":\"btcusdt@bookTicker\",\"data\":{\"e\":\"bookTicker\",\"u\":11478507068872,\"s\":\"BTCUSDT\",\"ps\":\"BTCUSDT\",\"b\":\"79597.00\",\"B\":\"4.558\",\"a\":\"79597.10\",\"A\":\"7.409\",\"T\":1788567710547,\"E\":1788567710547,\"st\":1}}"}
{"receive_ns":1788567711104022000,"stream":"btcusdt@depth@100ms","event_type":"depthUpdate","event_time_ms":1788567710577,"raw_json":"{\"stream\":\"btcusdt@depth@100ms\",\"data\":{\"e\":\"depthUpdate\",\"E\":1788567710577,\"T\":1788567710574,\"s\":\"BTCUSDT\",\"ps\":\"BTCUSDT\",\"U\":11478507064654,\"u\":11478507071666,\"pu\":11478507064592,\"b\":[[\"1000.00\",\"24.604\"],[\"29197.00\",\"1.498\"],[\"29297.00\",\"0.602\"],[\"63678.00\",\"0.000\"],[\"71637.30\",\"0.043\"],[\"71673.00\",\"0.000\"],[\"76413.10\",\"0.002\"],[\"78548.90\",\"6.996\"],[\"78705.50\",\"0.013\"],[\"78801.00\",\"12.547\"],[\"79199.00\",\"4.247\"],[\"79565.40\",\"0.152\"],[\"79565.50\",\"0.000\"],[\"79584.60\",\"0.350\"]],\"a\":[[\"79597.10\",\"7.409\"],[\"79617.20\",\"0.630\"],[\"79617.30\",\"0.066\"],[\"79641.30\",\"0.281\"],[\"79641.40\",\"0.001\"],[\"79641.60\",\"0.127\"],[\"80313.50\",\"0.380\"],[\"80393.10\",\"10.298\"]],\"st\":1}}"}
{"receive_ns":1788567711116434000,"stream":"btcusdt@bookTicker","event_type":"bookTicker","event_time_ms":1788567710592,"raw_json":"{\"stream\":\"btcusdt@bookTicker\",\"data\":{\"e\":\"bookTicker\",\"u\":11478507072622,\"s\":\"BTCUSDT\",\"ps\":\"BTCUSDT\",\"b\":\"79597.00\",\"B\":\"4.504\",\"a\":\"79597.10\",\"A\":\"7.409\",\"T\":1788567710592,\"E\":1788567710592,\"st\":1}}"}
{"receive_ns":1788567711126727000,"stream":"btcusdt@bookTicker","event_type":"bookTicker","event_time_ms":1788567710594,"raw_json":"{\"stream\":\"btcusdt@bookTicker\",\"data\":{\"e\":\"bookTicker\",\"u\":11478507072774,\"s\":\"BTCUSDT\",\"ps\":\"BTCUSDT\",\"b\":\"79597.00\",\"B\":\"4.557\",\"a\":\"79597.10\",\"A\":\"7.409\",\"T\":1788567710594,\"E\":1788567710594,\"st\":1}}"}
{"receive_ns":1788567711142476000,"stream":"btcusdt@bookTicker","event_type":"bookTicker","event_time_ms":1788567710597,"raw_json":"{\"stream\":\"btcusdt@bookTicker\",\"data\":{\"e\":\"bookTicker\",\"u\":11478507072895,\"s\":\"BTCUSDT\",\"ps\":\"BTCUSDT\",\"b\":\"79597.00\",\"B\":\"4.557\",\"a\":\"79597.10\",\"A\":\"7.411\",\"T\":1788567710597,\"E\":1788567710597,\"st\":1}}"}
{"receive_ns":1788567711158287000,"stream":"btcusdt@depth@100ms","event_type":"depthUpdate","event_time_ms":1788567710679,"raw_json":"{\"stream\":\"btcusdt@depth@100ms\",\"data\":{\"e\":\"depthUpdate\",\"E\":1788567710679,\"T\":1788567710677,\"s\":\"BTCUSDT\",\"ps\":\"BTCUSDT\",\"U\":11478507071870,\"u\":11478507077360,\"pu\":11478507071666,\"b\":[[\"1000.00\",\"24.604\"],[\"29197.00\",\"1.680\"],[\"29297.00\",\"0.420\"],[\"63678.00\",\"0.000\"],[\"71637.30\",\"0.043\"],[\"76413.10\",\"0.000\"],[\"78230.50\",\"5.742\"],[\"78699.10\",\"0.000\"],[\"78801.00\",\"12.547\"],[\"79476.20\",\"0.005\"],[\"79476.50\",\"0.038\"],[\"79511.00\",\"0.007\"],[\"79591.90\",\"0.459\"],[\"79592.10\",\"0.181\"],[\"79594.00\",\"0.102\"],[\"79594.20\",\"0.026\"],[\"79597.00\",\"4.557\"]],\"a\":[[\"79597.10\",\"7.411\"],[\"79641.50\",\"0.002\"],[\"79641.60\",\"0.002\"],[\"80313.70\",\"0.872\"],[\"80393.10\",\"10.298\"],[\"81189.00\",\"10.512\"]],\"st\":1}}"}
{"receive_ns":1788567711164444000,"stream":"btcusdt@depth@100ms","event_type":"depthUpdate","event_time_ms":1788567710781,"raw_json":"{\"stream\":\"btcusdt@depth@100ms\",\"data\":{\"e\":\"depthUpdate\",\"E\":1788567710781,\"T\":1788567710778,\"s\":\"BTCUSDT\",\"ps\":\"BTCUSDT\",\"U\":11478507077455,\"u\":11478507082409,\"pu\":11478507077360,\"b\":[[\"29097.00\",\"0.035\"],[\"29197.00\",\"1.785\"],[\"29297.00\",\"0.280\"],[\"71637.30\",\"0.043\"],[\"75617.20\",\"0.004\"],[\"78389.70\",\"1.911\"],[\"78621.50\",\"0.000\"],[\"78721.40\",\"6.470\"],[\"78801.00\",\"12.547\"],[\"79199.00\",\"4.237\"],[\"79565.40\",\"0.027\"],[\"79566.10\",\"0.128\"],[\"79566.30\",\"0.433\"],[\"79566.80\",\"0.000\"],[\"79573.30\",\"0.002\"],[\"79579.30\",\"0.043\"],[\"79582.90\",\"0.293\"]],\"a\":[[\"79613.20\",\"0.005\"],[\"79641.70\",\"0.026\"],[\"79642.10\",\"0.129\"],[\"80194.10\",\"4.361\"],[\"80393.10\",\"10.298\"],[\"80552.30\",\"29.106\"],[\"80558.80\",\"2.729\"],[\"80645.20\",\"6.190\"],[\"80661.00\",\"2.007\"]],\"st\":1}}"}
{"receive_ns":1788567711180966000,"stream":"btcusdt@bookTicker","event_type":"bookTicker","event_time_ms":1788567710804,"raw_json":"{\"stream\":\"btcusdt@bookTicker\",\"data\":{\"e\":\"bookTicker\",\"u\":11478507084045,\"s\":\"BTCUSDT\",\"ps\":\"BTCUSDT\",\"b\":\"79597.00\",\"B\":\"4.537\",\"a\":\"79597.10\",\"A\":\"7.411\",\"T\":1788567710804,\"E\":1788567710804,\"st\":1}}"}
{"receive_ns":1788567711191684000,"stream":"btcusdt@bookTicker","event_type":"bookTicker","event_time_ms":1788567710807,"raw_json":"{\"stream\":\"btcusdt@bookTicker\",\"data\":{\"e\":\"bookTicker\",\"u\":11478507084191,\"s\":\"BTCUSDT\",\"ps\":\"BTCUSDT\",\"b\":\"79597.00\",\"B\":\"4.556\",\"a\":\"79597.10\",\"A\":\"7.411\",\"T\":1788567710807,\"E\":1788567710807,\"st\":1}}"}
{"receive_ns":1788567711193528000,"stream":"btcusdt@bookTicker","event_type":"bookTicker","event_time_ms":1788567710843,"raw_json":"{\"stream\":\"btcusdt@bookTicker\",\"data\":{\"e\":\"bookTicker\",\"u\":11478507086421,\"s\":\"BTCUSDT\",\"ps\":\"BTCUSDT\",\"b\":\"79597.00\",\"B\":\"4.556\",\"a\":\"79597.10\",\"A\":\"7.409\",\"T\":1788567710842,\"E\":1788567710843,\"st\":1}}"}
{"receive_ns":1788567711204566000,"stream":"btcusdt@depth@100ms","event_type":"depthUpdate","event_time_ms":1788567710883,"raw_json":"{\"stream\":\"btcusdt@depth@100ms\",\"data\":{\"e\":\"depthUpdate\",\"E\":1788567710883,\"T\":1788567710881,\"s\":\"BTCUSDT\",\"ps\":\"BTCUSDT\",\"U\":11478507082577,\"u\":11478507088707,\"pu\":11478507082409,\"b\":[[\"1000.00\",\"24.604\"],[\"29097.00\",\"0.098\"],[\"29197.00\",\"1.841\"],[\"29297.00\",\"0.161\"],[\"63678.00\",\"0.000\"],[\"71637.30\",\"0.043\"],[\"75617.10\",\"0.018\"],[\"76413.10\",\"0.002\"],[\"78721.10\",\"0.318\"],[\"78801.00\",\"12.547\"],[\"78880.60\",\"7.150\"],[\"79380.60\",\"2.650\"],[\"79382.70\",\"0.003\"],[\"79435.90\",\"0.084\"],[\"79463.50\",\"2.658\"],[\"79475.30\",\"0.001\"],[\"79476.20\",\"0.037\"],[\"79476.50\",\"0.006\"],[\"79545.00\",\"0.322\"],[\"79546.50\",\"2.773\"],[\"79566.10\",\"0.128\"],[\"79566.50\",\"0.003\"],[\"79567.10\",\"0.001\"],[\"79592.20\",\"0.000\"],[\"79594.90\",\"0.026\"],[\"79597.00\",\"4.556\"]],\"a\":[[\"79597.10\",\"7.409\"],[\"79641.50\",\"0.002\"],[\"79642.10\",\"0.004\"],[\"79719.80\",\"0.000\"],[\"79759.20\",\"0.009\"],[\"79818.80\",\"7.102\"],[\"80313.50\",\"0.567\"],[\"80393.10\",\"10.298\"],[\"80638.40\",\"0.619\"]],\"st\":1}}"}
{"receive_ns":1788567711215775000,"stream":"btcusdt@bookTicker","event_type":"bookTicker","event_time_ms":1788567710968,"raw_json":"{\"stream\":\"btcusdt@bookTicker\",\"data\":{\"e\":\"bookTicker\",\"u\":11478507094474,\"s\":\"BTCUSDT\",\"ps\":\"BTCUSDT\",\"b\":\"79597.00\",\"B\":\"4.502\",\"a\":\"79597.10\",\"A\":\"7.409\",\"T\":1788567710968,\"E\":1788567710968,\"st\":1}}"}
{"receive_ns":1788567711223566000,"stream":"btcusdt@bookTicker","event_type":"bookTicker","event_time_ms":1788567710972,"raw_json":"{\"stream\":\"btcusdt@bookTicker\",\"data\":{\"e\":\"bookTicker\",\"u\":11478507094634,\"s\":\"BTCUSDT\",\"ps\":\"BTCUSDT\",\"b\":\"79597.00\",\"B\":\"4.555\",\"a\":\"79597.10\",\"A\":\"7.409\",\"T\":1788567710972,\"E\":1788567710972,\"st\":1}}"}
{"receive_ns":1788567711234350000,"stream":"btcusdt@depth@100ms","event_type":"depthUpdate","event_time_ms":1788567710985,"raw_json":"{\"stream\":\"btcusdt@depth@100ms\",\"data\":{\"e\":\"depthUpdate\",\"E\":1788567710985,\"T\":1788567710982,\"s\":\"BTCUSDT\",\"ps\":\"BTCUSDT\",\"U\":11478507088813,\"u\":11478507095001,\"pu\":11478507088707,\"b\":[[\"1000.00\",\"24.604\"],[\"29097.00\",\"0.154\"],[\"29197.00\",\"1.904\"],[\"29297.00\",\"0.042\"],[\"63677.60\",\"0.000\"],[\"63678.00\",\"0.002\"],[\"71637.30\",\"0.043\"],[\"76413.10\",\"0.000\"],[\"78452.80\",\"0.459\"],[\"78614.60\",\"0.005\"],[\"78619.10\",\"0.002\"],[\"78801.00\",\"12.547\"],[\"79199.00\",\"4.236\"],[\"79388.10\",\"1.993\"],[\"79592.30\",\"0.000\"],[\"79592.40\",\"0.002\"],[\"79594.00\",\"0.026\"],[\"79594.10\",\"0.238\"],[\"79594.30\",\"0.084\"],[\"79594.40\",\"0.026\"],[\"79594.70\",\"0.026\"],[\"79594.90\",\"0.000\"],[\"79597.00\",\"4.555\"]],\"a\":[[\"79642.70\",\"0.000\"],[\"79804.90\",\"0.456\"],[\"79806.90\",\"0.000\"],[\"80311.00\",\"3.049\"],[\"80393.10\",\"10.298\"],[\"80458.40\",\"0.372\"],[\"80472.70\",\"4.715\"],[\"80592.10\",\"9.757\"]],\"st\":1}}"}
{"receive_ns":1788567711241225000,"stream":"btcusdt@depth@100ms","event_type":"depthUpdate","event_time_ms":1788567711087,"raw_json":"{\"stream\":\"btcusdt@depth@100ms\",\"data\":{\"e\":\"depthUpdate\",\"E\":1788567711087,\"T\":1788567711086,\"s\":\"BTCUSDT\",\"ps\":\"BTCUSDT\",\"U\":11478507095090,\"u\":11478507101735,\"pu\":11478507095001,\"b\":[[\"29097.00\",\"0.294\"],[\"29197.00\",\"1.806\"],[\"29297.00\",\"0.000\"],[\"63678.00\",\"0.000\"],[\"71637.30\",\"0.043\"],[\"76413.10\",\"0.002\"],[\"76413.20\",\"0.001\"],[\"78251.80\",\"1.020\"],[\"78522.40\",\"8.789\"],[\"78801.00\",\"12.547\"],[\"79199.00\",\"4.236\"],[\"79388.20\",\"4.344\"],[\"79435.90\",\"2.659\"],[\"79475.30\",\"0.495\"],[\"79582.70\",\"0.204\"]],\"a\":[[\"79642.60\",\"0.126\"],[\"79719.70\",\"0.500\"],[\"79759.10\",\"14.122\"],[\"79804.90\",\"1.087\"],[\"79806.90\",\"5.017\"],[\"80393.10\",\"10.298\"],[\"80525.80\",\"3.802\"],[\"80565.60\",\"8.060\"],[\"80631.90\",\"7.174\"],[\"80703.50\",\"4.378\"],[\"80711.50\",\"28.462\"],[\"80804.40\",\"6.798\"]],\"st\":1}}"}
{"receive_ns":1788567711247136000,"stream":"btcusdt@bookTicker","event_type":"bookTicker","event_time_ms":1788567711097,"raw_json":"{\"stream\":\"btcusdt@bookTicker\",\"data\":{\"e\":\"bookTicker\",\"u\":11478507102740,\"s\":\"BTCUSDT\",\"ps\":\"BTCUSDT\",\"b\":\"79597.00\",\"B\":\"4.502\",\"a\":\"79597.10\",\"A\":\"7.409\",\"T\":1788567711097,\"E\":1788567711097,\"st\":1}}"}
{"receive_ns":1788567711260350000,"stream":"btcusdt@bookTicker","event_type":"bookTicker","event_time_ms":1788567711100,"raw_json":"{\"stream\":\"btcusdt@bookTicker\",\"data\":{\"e\":\"bookTicker\",\"u\":11478507103001,\"s\":\"BTCUSDT\",\"ps\":\"BTCUSDT\",\"b\":\"79597.00\",\"B\":\"4.556\",\"a\":\"79597.10\",\"A\":\"7.409\",\"T\":1788567711100,\"E\":1788567711100,\"st\":1}}"}
{"receive_ns":1788567711271303000,"stream":"btcusdt@depth@100ms","event_type":"depthUpdate","event_time_ms":1788567711189,"raw_json":"{\"stream\":\"btcusdt@depth@100ms\",\"data\":{\"e\":\"depthUpdate\",\"E\":1788567711189,\"T\":1788567711188,\"s\":\"BTCUSDT\",\"ps\":\"BTCUSDT\",\"U\":11478507101929,\"u\":11478507109063,\"pu\":11478507101735,\"b\":[[\"1000.00\",\"24.604\"],[\"29097.00\",\"0.462\"],[\"29197.00\",\"1.638\"],[\"63678.00\",\"0.000\"],[\"71637.30\",\"0.043\"],[\"76413.10\",\"0.000\"],[\"78005.10\",\"10.697\"],[\"78548.10\",\"1.780\"],[\"78801.00\",\"12.547\"],[\"78960.20\",\"7.749\"],[\"79018.40\",\"6.319\"],[\"79029.20\",\"0.095\"],[\"79542.70\",\"0.829\"],[\"79558.60\",\"0.691\"],[\"79594.10\",\"0.162\"],[\"79594.70\",\"0.000\"],[\"79597.00\",\"4.556\"]],\"a\":[[\"79610.60\",\"0.694\"],[\"79626.50\",\"5.352\"],[\"79642.60\",\"0.126\"],[\"79643.30\",\"0.228\"],[\"79691.90\",\"0.061\"],[\"79692.00\",\"2.252\"],[\"79693.20\",\"0.000\"],[\"79701.50\",\"0.342\"],[\"79701.60\",\"0.022\"],[\"79701.80\",\"0.001\"],[\"79702.70\",\"0.052\"],[\"79705.10\",\"0.030\"],[\"79705.30\",\"0.002\"],[\"79995.10\",\"4.366\"],[\"80393.10\",\"10.298\"],[\"80479.60\",\"0.000\"],[\"80577.80\",\"4.249\"],[\"80711.50\",\"28.709\"],[\"81189.00\",\"10.515\"]],\"st\":1}}"}
{"receive_ns":1788567711278154000,"stream":"btcusdt@depth@100ms","event_type":"depthUpdate","event_time_ms":1788567711291,"raw_json":"{\"stream\":\"btcusdt@depth@100ms\",\"data\":{\"e\":\"depthUpdate\",\"E\":1788567711291,\"T\":1788567711290,\"s\":\"BTCUSDT\",\"ps\":\"BTCUSDT\",\"U\":11478507109229,\"u\":11478507116421,\"pu\":11478507109063,\"b\":[[\"1000.00\",\"24.604\"],[\"29097.00\",\"0.651\"],[\"29197.00\",\"1.449\"],[\"71637.30\",\"0.043\"],[\"78160.20\",\"0.000\"],[\"78514.70\",\"2.117\"],[\"78801.00\",\"12.547\"],[\"79400.10\",\"0.442\"],[\"79438.40\",\"0.619\"],[\"79475.30\",\"0.001\"],[\"79485.50\",\"13.213\"],[\"79525.30\",\"0.635\"],[\"79541.20\",\"0.000\"],[\"79594.00\",\"0.102\"],[\"79594.90\",\"0.026\"]],\"a\":[[\"79642.60\",\"0.001\"],[\"79642.90\",\"0.003\"],[\"79643.10\",\"0.126\"],[\"79668.80\",\"0.034\"],[\"79692.10\",\"6.001\"],[\"79692.70\",\"0.001\"],[\"79702.90\",\"0.001\"],[\"79719.70\",\"0.007\"],[\"79818.80\",\"7.073\"],[\"80233.90\",\"7.091\"],[\"80393.10\",\"10.298\"]],\"st\":1}}"}
{"receive_ns":1788567711378570000,"stream":"btcusdt@depth@100ms","event_type":"depthUpdate","event_time_ms":1788567711393,"raw_json":"{\"stream\":\"btcusdt@depth@100ms\",\"data\":{\"e\":\"depthUpdate\",\"E\":1788567711393,\"T\":1788567711391,\"s\":\"BTCUSDT\",\"ps\":\"BTCUSDT\",\"U\":11478507116586,\"u\":11478507122185,\"pu\":11478507116421,\"b\":[[\"29097.00\",\"0.826\"],[\"29197.00\",\"1.274\"],[\"71637.30\",\"0.043\"],[\"76413.10\",\"0.002\"],[\"78005.10\",\"10.825\"],[\"78801.00\",\"12.547\"],[\"79140.00\",\"0.091\"],[\"79199.00\",\"4.246\"],[\"79475.30\",\"0.495\"],[\"79509.30\",\"0.002\"],[\"79511.80\",\"1.101\"],[\"79537.20\",\"0.000\"],[\"79557.00\",\"0.002\"],[\"79589.50\",\"0.040\"]],\"a\":[[\"79643.10\",\"0.001\"],[\"79643.20\",\"0.239\"],[\"79644.30\",\"0.001\"],[\"79664.20\",\"0.002\"],[\"79692.00\",\"1.357\"],[\"79692.10\",\"0.001\"],[\"79719.70\",\"0.500\"],[\"80148.50\",\"0.000\"],[\"80393.10\",\"10.298\"],[\"80458.40\",\"0.186\"],[\"81273.90\",\"0.001\"]],\"st\":1}}"}
{"receive_ns":1788567711411851000,"stream":"btcusdt@bookTicker","event_type":"bookTicker","event_time_ms":1788567711427,"raw_json":"{\"stream\":\"btcusdt@bookTicker\",\"data\":{\"e\":\"bookTicker\",\"u\":11478507124230,\"s\":\"BTCUSDT\",\"ps\":\"BTCUSDT\",\"b\":\"79597.00\",\"B\":\"4.556\",\"a\":\"79597.10\",\"A\":\"7.410\",\"T\":1788567711427,\"E\":1788567711427,\"st\":1}}"}
{"receive_ns":1788567711440052000,"stream":"btcusdt@bookTicker","event_type":"bookTicker","event_time_ms":1788567711462,"raw_json":"{\"stream\":\"btcusdt@bookTicker\",\"data\":{\"e\":\"bookTicker\",\"u\":11478507126736,\"s\":\"BTCUSDT\",\"ps\":\"BTCUSDT\",\"b\":\"79597.00\",\"B\":\"4.505\",\"a\":\"79597.10\",\"A\":\"7.410\",\"T\":1788567711462,\"E\":1788567711462,\"st\":1}}"}
{"receive_ns":1788567711446469000,"stream":"btcusdt@bookTicker","event_type":"bookTicker","event_time_ms":1788567711465,"raw_json":"{\"stream\":\"btcusdt@bookTicker\",\"data\":{\"e\":\"bookTicker\",\"u\":11478507126959,\"s\":\"BTCUSDT\",\"ps\":\"BTCUSDT\",\"b\":\"79597.00\",\"B\":\"4.560\",\"a\":\"79597.10\",\"A\":\"7.410\",\"T\":1788567711465,\"E\":1788567711465,\"st\":1}}"}
{"receive_ns":1788567711479817000,"stream":"btcusdt@depth@100ms","event_type":"depthUpdate","event_time_ms":1788567711495,"raw_json":"{\"stream\":\"btcusdt@depth@100ms\",\"data\":{\"e\":\"depthUpdate\",\"E\":1788567711495,\"T\":1788567711494,\"s\":\"BTCUSDT\",\"ps\":\"BTCUSDT\",\"U\":11478507122299,\"u\":11478507128060,\"pu\":11478507122185,\"b\":[[\"1000.00\",\"24.604\"],[\"29097.00\",\"1.008\"],[\"29197.00\",\"1.092\"],[\"71637.30\",\"0.043\"],[\"76413.10\",\"0.000\"],[\"78562.20\",\"10.965\"],[\"78582.30\",\"0.000\"],[\"78707.50\",\"0.380\"],[\"78801.00\",\"12.547\"],[\"79199.00\",\"4.245\"],[\"79409.10\",\"0.006\"],[\"79439.40\",\"0.013\"],[\"79469.60\",\"0.002\"],[\"79471.80\",\"1.317\"],[\"79506.70\",\"4.258\"],[\"79582.70\",\"0.194\"],[\"79592.60\",\"0.000\"],[\"79595.00\",\"0.028\"],[\"79596.90\",\"2.462\"],[\"79597.00\",\"4.560\"]],\"a\":[[\"79597.10\",\"7.410\"],[\"79643.20\",\"0.114\"],[\"79643.30\",\"0.353\"],[\"79688.00\",\"3.325\"],[\"79688.10\",\"0.024\"],[\"79728.00\",\"1.007\"],[\"79731.90\",\"0.000\"],[\"79806.90\",\"5.017\"],[\"79818.80\",\"7.055\"],[\"80194.10\",\"3.738\"],[\"80393.10\",\"10.298\"],[\"80957.30\",\"0.013\"],[\"81419.90\",\"0.613\"]],\"st\":1}}"}
{"receive_ns":1788567711491680000,"stream":"btcusdt@bookTicker","event_type":"bookTicker","event_time_ms":1788567711504,"raw_json":"{\"stream\":\"btcusdt@bookTicker\",\"data\":{\"e\":\"bookTicker\",\"u\":11478507128708,\"s\":\"BTCUSDT\",\"ps\":\"BTCUSDT\",\"b\":\"79597.00\",\"B\":\"4.560\",\"a\":\"79597.10\",\"A\":\"7.409\",\"T\":1788567711504,\"E\":1788567711504,\"st\":1}}"}
{"receive_ns":1788567711495868000,"stream":"btcusdt@trade","event_type":"trade","event_time_ms":1788567711504,"raw_json":"{\"stream\":\"btcusdt@trade\",\"data\":{\"e\":\"trade\",\"E\":1788567711504,\"T\":1788567711504,\"s\":\"BTCUSDT\",\"t\":8054122560,\"p\":\"79597.10\",\"q\":\"0.001\",\"X\":\"MARKET\",\"m\":false,\"st\":1}}"}
{"receive_ns":1788567711507065000,"stream":"btcusdt@bookTicker","event_type":"bookTicker","event_time_ms":1788567711506,"raw_json":"{\"stream\":\"btcusdt@bookTicker\",\"data\":{\"e\":\"bookTicker\",\"u\":11478507128891,\"s\":\"BTCUSDT\",\"ps\":\"BTCUSDT\",\"b\":\"79597.00\",\"B\":\"4.559\",\"a\":\"79597.10\",\"A\":\"7.409\",\"T\":1788567711506,\"E\":1788567711506,\"st\":1}}"}
{"receive_ns":1788567711561784000,"stream":"btcusdt@bookTicker","event_type":"bookTicker","event_time_ms":1788567711582,"raw_json":"{\"stream\":\"btcusdt@bookTicker\",\"data\":{\"e\":\"bookTicker\",\"u\":11478507133578,\"s\":\"BTCUSDT\",\"ps\":\"BTCUSDT\",\"b\":\"79597.00\",\"B\":\"4.560\",\"a\":\"79597.10\",\"A\":\"7.409\",\"T\":1788567711581,\"E\":1788567711582,\"st\":1}}"}
{"receive_ns":1788567711581826000,"stream":"btcusdt@depth@100ms","event_type":"depthUpdate","event_time_ms":1788567711597,"raw_json":"{\"stream\":\"btcusdt@depth@100ms\",\"data\":{\"e\":\"depthUpdate\",\"E\":1788567711597,\"T\":1788567711593,\"s\":\"BTCUSDT\",\"ps\":\"BTCUSDT\",\"U\":11478507128207,\"u\":11478507134898,\"pu\":11478507128060,\"b\":[[\"1000.00\",\"24.604\"],[\"29097.00\",\"1.183\"],[\"29197.00\",\"0.917\"],[\"71637.30\",\"0.043\"],[\"71673.00\",\"0.003\"],[\"76413.10\",\"0.002\"],[\"78588.10\",\"8.204\"],[\"78801.00\",\"12.547\"],[\"78869.50\",\"0.193\"],[\"79409.10\",\"0.000\"],[\"79456.90\",\"0.245\"],[\"79511.50\",\"6.001\"],[\"79511.80\",\"1.844\"],[\"79539.30\",\"3.608\"],[\"79559.20\",\"0.572\"],[\"79592.90\",\"0.078\"],[\"79593.80\",\"0.026\"],[\"79594.50\",\"0.026\"],[\"79594.90\",\"0.000\"],[\"79595.00\",\"0.002\"],[\"79595.30\",\"0.001\"],[\"79597.00\",\"4.560\"]],\"a\":[[\"79597.10\",\"7.409\"],[\"79641.60\",\"0.556\"],[\"79661.50\",\"3.500\"],[\"79689.40\",\"6.000\"],[\"79829.20\",\"0.025\"],[\"79829.30\",\"0.003\"],[\"79995.10\",\"4.367\"],[\"80393.10\",\"10.298\"],[\"80830.90\",\"6.920\"]],\"st\":1}}"}
{"receive_ns":1788567711684690000,"stream":"btcusdt@depth@100ms","event_type":"depthUpdate","event_time_ms":1788567711699,"raw_json":"{\"stream\":\"btcusdt@depth@100ms\",\"data\":{\"e\":\"depthUpdate\",\"E\":1788567711699,\"T\":1788567711698,\"s\":\"BTCUSDT\",\"ps\":\"BTCUSDT\",\"U\":11478507135091,\"u\":11478507140890,\"pu\":11478507134898,\"b\":[[\"29097.00\",\"1.365\"],[\"29197.00\",\"0.735\"],[\"71637.30\",\"0.045\"],[\"71673.00\",\"0.000\"],[\"76413.10\",\"0.000\"],[\"78572.60\",\"0.012\"],[\"78581.90\",\"0.737\"],[\"78592.40\",\"0.003\"],[\"78601.60\",\"0.006\"],[\"78801.00\",\"12.547\"],[\"79199.00\",\"4.245\"],[\"79584.70\",\"1.257\"],[\"79587.80\",\"1.588\"],[\"79588.00\",\"0.402\"],[\"79588.10\",\"0.001\"],[\"79588.20\",\"0.004\"],[\"79588.30\",\"0.004\"],[\"79588.70\",\"0.004\"],[\"79588.80\",\"0.255\"],[\"79594.70\",\"0.026\"]],\"a\":[[\"79601.20\",\"0.001\"],[\"79642.90\",\"0.003\"],[\"79643.30\",\"0.228\"],[\"79643.40\",\"3.151\"],[\"80393.10\",\"10.298\"]],\"st\":1}}"}
{"receive_ns":1788567711690472000,"stream":"btcusdt@bookTicker","event_type":"bookTicker","event_time_ms":1788567711714,"raw_json":"{\"stream\":\"btcusdt@bookTicker\",\"data\":{\"e\":\"bookTicker\",\"u\":11478507142094,\"s\":\"BTCUSDT\",\"ps\":\"BTCUSDT\",\"b\":\"79597.00\",\"B\":\"4.584\",\"a\":\"79597.10\",\"A\":\"7.409\",\"T\":1788567711714,\"E\":1788567711714,\"st\":1}}"}
{"receive_ns":1788567711709998000,"stream":"btcusdt@bookTicker","event_type":"bookTicker","event_time_ms":1788567711727,"raw_json":"{\"stream\":\"btcusdt@bookTicker\",\"data\":{\"e\":\"bookTicker\",\"u\":11478507143187,\"s\":\"BTCUSDT\",\"ps\":\"BTCUSDT\",\"b\":\"79597.00\",\"B\":\"4.584\",\"a\":\"79597.10\",\"A\":\"7.411\",\"T\":1788567711727,\"E\":1788567711727,\"st\":1}}"}
{"receive_ns":1788567711772508000,"stream":"btcusdt@bookTicker","event_type":"bookTicker","event_time_ms":1788567711787,"raw_json":"{\"stream\":\"btcusdt@bookTicker\",\"data\":{\"e\":\"bookTicker\",\"u\":11478507147425,\"s\":\"BTCUSDT\",\"ps\":\"BTCUSDT\",\"b\":\"79597.00\",\"B\":\"4.584\",\"a\":\"79597.10\",\"A\":\"7.412\",\"T\":1788567711787,\"E\":1788567711787,\"st\":1}}"}
{"receive_ns":1788567711783470000,"stream":"btcusdt@depth@100ms","event_type":"depthUpdate","event_time_ms":1788567711801,"raw_json":"{\"stream\":\"btcusdt@depth@100ms\",\"data\":{\"e\":\"depthUpdate\",\"E\":1788567711801,\"T\":1788567711799,\"s\":\"BTCUSDT\",\"ps\":\"BTCUSDT\",\"U\":11478507141042,\"u\":11478507148236,\"pu\":11478507140890,\"b\":[[\"1000.00\",\"24.604\"],[\"29097.00\",\"1.540\"],[\"29197.00\",\"0.560\"],[\"71637.30\",\"0.043\"],[\"75617.10\",\"0.016\"],[\"75617.20\",\"0.006\"],[\"78545.50\",\"2.098\"],[\"78548.10\",\"0.890\"],[\"78801.00\",\"12.547\"],[\"79435.00\",\"0.011\"],[\"79471.70\",\"10.040\"],[\"79471.80\",\"2.623\"],[\"79475.30\",\"0.467\"],[\"79573.30\",\"0.002\"],[\"79583.20\",\"0.000\"],[\"79584.70\",\"0.001\"],[\"79584.80\",\"0.004\"],[\"79588.00\",\"0.092\"],[\"79588.10\",\"0.315\"],[\"79588.20\",\"1.260\"],[\"79588.30\",\"0.000\"],[\"79589.30\",\"0.019\"],[\"79593.00\",\"0.059\"],[\"79593.20\",\"0.000\"],[\"79595.00\",\"0.002\"],[\"79595.20\",\"0.078\"],[\"79597.00\",\"4.584\"]],\"a\":[[\"79597.10\",\"7.412\"],[\"79613.20\",\"0.005\"],[\"79616.50\",\"0.776\"],[\"79617.10\",\"0.372\"],[\"79643.10\",\"0.126\"],[\"79643.40\",\"3.026\"],[\"79719.70\",\"0.483\"],[\"79728.00\",\"2.861\"],[\"79729.00\",\"10.466\"],[\"80393.10\",\"10.298\"],[\"80472.70\",\"4.901\"],[\"80592.10\",\"10.035\"],[\"80751.30\",\"14.038\"]],\"st\":1}}"}
{"receive_ns":1788567711831936000,"stream":"btcusdt@bookTicker","event_type":"bookTicker","event_time_ms":1788567711838,"raw_json":"{\"stream\":\"btcusdt@bookTicker\",\"data\":{\"e\":\"bookTicker\",\"u\":11478507150930,\"s\":\"BTCUSDT\",\"ps\":\"BTCUSDT\",\"b\":\"79597.00\",\"B\":\"4.584\",\"a\":\"79597.10\",\"A\":\"7.419\",\"T\":1788567711838,\"E\":1788567711838,\"st\":1}}"}
{"receive_ns":1788567711873142000,"stream":"btcusdt@bookTicker","event_type":"bookTicker","event_time_ms":1788567711894,"raw_json":"{\"stream\":\"btcusdt@bookTicker\",\"data\":{\"e\":\"bookTicker\",\"u\":11478507153944,\"s\":\"BTCUSDT\",\"ps\":\"BTCUSDT\",\"b\":\"79597.00\",\"B\":\"4.451\",\"a\":\"79597.10\",\"A\":\"7.419\",\"T\":1788567711894,\"E\":1788567711894,\"st\":1}}"}
{"receive_ns":1788567711884388000,"stream":"btcusdt@bookTicker","event_type":"bookTicker","event_time_ms":1788567711897,"raw_json":"{\"stream\":\"btcusdt@bookTicker\",\"data\":{\"e\":\"bookTicker\",\"u\":11478507154128,\"s\":\"BTCUSDT\",\"ps\":\"BTCUSDT\",\"b\":\"79597.00\",\"B\":\"4.587\",\"a\":\"79597.10\",\"A\":\"7.419\",\"T\":1788567711897,\"E\":1788567711897,\"st\":1}}"}
{"receive_ns":1788567711894997000,"stream":"btcusdt@bookTicker","event_type":"bookTicker","event_time_ms":1788567711898,"raw_json":"{\"stream\":\"btcusdt@bookTicker\",\"data\":{\"e\":\"bookTicker\",\"u\":11478507154212,\"s\":\"BTCUSDT\",\"ps\":\"BTCUSDT\",\"b\":\"79597.00\",\"B\":\"4.586\",\"a\":\"79597.10\",\"A\":\"7.419\",\"T\":1788567711898,\"E\":1788567711898,\"st\":1}}"}
{"receive_ns":1788567711901386000,"stream":"btcusdt@depth@100ms","event_type":"depthUpdate","event_time_ms":1788567711903,"raw_json":"{\"stream\":\"btcusdt@depth@100ms\",\"data\":{\"e\":\"depthUpdate\",\"E\":1788567711903,\"T\":1788567711902,\"s\":\"BTCUSDT\",\"ps\":\"BTCUSDT\",\"U\":11478507148443,\"u\":11478507154376,\"pu\":11478507148236,\"b\":[[\"1000.00\",\"24.604\"],[\"29097.00\",\"1.715\"],[\"29197.00\",\"0.385\"],[\"71637.30\",\"0.043\"],[\"76413.10\",\"0.002\"],[\"78801.00\",\"12.547\"],[\"79569.40\",\"0.000\"],[\"79570.50\",\"0.002\"],[\"79570.90\",\"0.454\"],[\"79573.50\",\"0.440\"],[\"79575.70\",\"0.002\"],[\"79576.10\",\"0.003\"],[\"79577.00\",\"0.007\"],[\"79577.10\",\"0.433\"],[\"79578.20\",\"0.002\"],[\"79584.30\",\"0.001\"],[\"79584.70\",\"0.001\"],[\"79588.00\",\"0.014\"],[\"79588.20\",\"0.004\"],[\"79588.30\",\"0.000\"],[\"79588.40\",\"0.066\"],[\"79588.50\",\"0.085\"],[\"79588.60\",\"1.264\"],[\"79588.70\",\"0.002\"],[\"79589.20\",\"0.078\"],[\"79589.30\",\"0.035\"],[\"79589.90\",\"0.000\"],[\"79590.10\",\"0.101\"],[\"79591.90\",\"0.560\"],[\"79592.50\",\"0.127\"],[\"79593.00\",\"0.055\"],[\"79593.70\",\"0.004\"],[\"79593.80\",\"0.000\"],[\"79594.60\",\"0.253\"],[\"79595.10\",\"0.028\"],[\"79595.60\",\"0.012\"],[\"79595.70\",\"0.001\"],[\"79596.40\",\"0.002\"],[\"79597.00\",\"4.586\"]],\"a\":[[\"79597.10\",\"7.419\"],[\"79597.20\",\"0.008\"],[\"79597.90\",\"0.020\"],[\"79610.40\",\"0.123\"],[\"79611.90\",\"0.001\"],[\"79612.80\",\"0.442\"],[\"79617.10\",\"0.000\"],[\"79618.10\",\"1.924\"],[\"79620.00\",\"0.146\"],[\"79621.30\",\"0.559\"],[\"79643.10\",\"0.001\"],[\"79643.50\",\"0.787\"],[\"79643.70\",\"2.873\"],[\"79995.10\",\"4.242\"],[\"80300.30\",\"0.196\"],[\"80393.10\",\"10.298\"],[\"80724.80\",\"6.809\"],[\"81036.30\",\"0.017\"],[\"81189.00\",\"10.512\"]],\"st\":1}}"}
{"receive_ns":1788567711945565000,"stream":"btcusdt@bookTicker","event_type":"bookTicker","event_time_ms":1788567711959,"raw_json":"{\"stream\":\"btcusdt@bookTicker\",\"data\":{\"e\":\"bookTicker\",\"u\":11478507157539,\"s\":\"BTCUSDT\",\"ps\":\"BTCUSDT\",\"b\":\"79597.00\",\"B\":\"4.533\",\"a\":\"79597.10\",\"A\":\"7.419\",\"T\":1788567711959,\"E\":1788567711959,\"st\":1}}"}
{"receive_ns":1788567711956075000,"stream":"btcusdt@bookTicker","event_type":"bookTicker","event_time_ms":1788567711962,"raw_json":"{\"stream\":\"btcusdt@bookTicker\",\"data\":{\"e\":\"bookTicker\",\"u\":11478507157750,\"s\":\"BTCUSDT\",\"ps\":\"BTCUSDT\",\"b\":\"79597.00\",\"B\":\"4.587\",\"a\":\"79597.10\",\"A\":\"7.419\",\"T\":1788567711962,\"E\":1788567711962,\"st\":1}}"}
{"receive_ns":1788567711967464000,"stream":"btcusdt@bookTicker","event_type":"bookTicker","event_time_ms":1788567711964,"raw_json":"{\"stream\":\"btcusdt@bookTicker\",\"data\":{\"e\":\"bookTicker\",\"u\":11478507157924,\"s\":\"BTCUSDT\",\"ps\":\"BTCUSDT\",\"b\":\"79597.00\",\"B\":\"4.588\",\"a\":\"79597.10\",\"A\":\"7.419\",\"T\":1788567711964,\"E\":1788567711964,\"st\":1}}"}
{"receive_ns":1788567712024668000,"stream":"btcusdt@depth@100ms","event_type":"depthUpdate","event_time_ms":1788567712005,"raw_json":"{\"stream\":\"btcusdt@depth@100ms\",\"data\":{\"e\":\"depthUpdate\",\"E\":1788567712005,\"T\":1788567712003,\"s\":\"BTCUSDT\",\"ps\":\"BTCUSDT\",\"U\":11478507154515,\"u\":11478507160572,\"pu\":11478507154376,\"b\":[[\"29097.00\",\"1.799\"],[\"29197.00\",\"0.252\"],[\"29497.00\",\"0.049\"],[\"63677.60\",\"0.000\"],[\"71637.30\",\"0.043\"],[\"76413.10\",\"0.000\"],[\"77354.60\",\"0.257\"],[\"78389.70\",\"2.548\"],[\"78514.70\",\"1.609\"],[\"78562.20\",\"11.156\"],[\"78624.30\",\"1.332\"],[\"78801.00\",\"12.547\"],[\"79000.00\",\"43.490\"],[\"79199.00\",\"4.235\"],[\"79584.70\",\"0.001\"],[\"79584.80\",\"1.260\"],[\"79584.90\",\"0.000\"],[\"79588.00\",\"0.088\"],[\"79588.10\",\"0.001\"],[\"79588.20\",\"0.322\"],[\"79588.40\",\"0.000\"],[\"79588.50\",\"0.081\"],[\"79588.60\",\"0.000\"],[\"79588.70\",\"0.002\"],[\"79592.50\",\"0.125\"],[\"79597.00\",\"4.588\"]],\"a\":[[\"79643.50\",\"0.912\"],[\"79643.60\",\"0.253\"],[\"79643.70\",\"2.748\"],[\"80393.10\",\"10.298\"]],\"st\":1}}"}
{"receive_ns":1788567712086292000,"stream":"btcusdt@bookTicker","event_type":"bookTicker","event_time_ms":1788567712104,"raw_json":"{\"stream\":\"btcusdt@bookTicker\",\"data\":{\"e\":\"bookTicker\",\"u\":11478507166660,\"s\":\"BTCUSDT\",\"ps\":\"BTCUSDT\",\"b\":\"79597.00\",\"B\":\"4.534\",\"a\":\"79597.10\",\"A\":\"7.419\",\"T\":1788567712104,\"E\":1788567712104,\"st\":1}}"}
{"receive_ns":1788567712096014000,"stream":"btcusdt@depth@100ms","event_type":"depthUpdate","event_time_ms":1788567712107,"raw_json":"{\"stream\":\"btcusdt@depth@100ms\",\"data\":{\"e\":\"depthUpdate\",\"E\":1788567712107,\"T\":1788567712106,\"s\":\"BTCUSDT\",\"ps\":\"BTCUSDT\",\"U\":11478507160686,\"u\":11478507166771,\"pu\":11478507160572,\"b\":[[\"1000.00\",\"24.604\"],[\"29097.00\",\"1.855\"],[\"29197.00\",\"0.133\"],[\"29497.00\",\"0.112\"],[\"71637.30\",\"0.043\"],[\"76413.10\",\"0.002\"],[\"78721.40\",\"6.660\"],[\"78801.00\",\"12.549\"],[\"79425.80\",\"0.005\"],[\"79582.70\",\"0.194\"],[\"79584.70\",\"1.257\"],[\"79584.80\",\"0.318\"],[\"79584.90\",\"0.000\"],[\"79588.00\",\"0.088\"],[\"79588.10\",\"0.001\"],[\"79588.20\",\"0.008\"],[\"79595.40\",\"0.028\"],[\"79597.00\",\"4.534\"]],\"a\":[[\"79643.50\",\"0.787\"],[\"79643.70\",\"2.873\"],[\"79995.10\",\"4.241\"],[\"80467.50\",\"0.657\"],[\"80592.10\",\"10.221\"]],\"st\":1}}"}
{"receive_ns":1788567712107874000,"stream":"btcusdt@bookTicker","event_type":"bookTicker","event_time_ms":1788567712108,"raw_json":"{\"stream\":\"btcusdt@bookTicker\",\"data\":{\"e\":\"bookTicker\",\"u\":11478507166864,\"s\":\"BTCUSDT\",\"ps\":\"BTCUSDT\",\"b\":\"79597.00\",\"B\":\"4.584\",\"a\":\"79597.10\",\"A\":\"7.419\",\"T\":1788567712108,\"E\":1788567712108,\"st\":1}}"}
{"receive_ns":1788567712119573000,"stream":"btcusdt@bookTicker","event_type":"bookTicker","event_time_ms":1788567712131,"raw_json":"{\"stream\":\"btcusdt@bookTicker\",\"data\":{\"e\":\"bookTicker\",\"u\":11478507168917,\"s\":\"BTCUSDT\",\"ps\":\"BTCUSDT\",\"b\":\"79597.00\",\"B\":\"4.565\",\"a\":\"79597.10\",\"A\":\"7.419\",\"T\":1788567712131,\"E\":1788567712131,\"st\":1}}"}
{"receive_ns":1788567712127957000,"stream":"btcusdt@bookTicker","event_type":"bookTicker","event_time_ms":1788567712133,"raw_json":"{\"stream\":\"btcusdt@bookTicker\",\"data\":{\"e\":\"bookTicker\",\"u\":11478507169331,\"s\":\"BTCUSDT\",\"ps\":\"BTCUSDT\",\"b\":\"79597.00\",\"B\":\"4.583\",\"a\":\"79597.10\",\"A\":\"7.419\",\"T\":1788567712133,\"E\":1788567712133,\"st\":1}}"}
{"receive_ns":1788567712207404000,"stream":"btcusdt@depth@100ms","event_type":"depthUpdate","event_time_ms":1788567712209,"raw_json":"{\"stream\":\"btcusdt@depth@100ms\",\"data\":{\"e\":\"depthUpdate\",\"E\":1788567712209,\"T\":1788567712205,\"s\":\"BTCUSDT\",\"ps\":\"BTCUSDT\",\"U\":11478507166818,\"u\":11478507173887,\"pu\":11478507166771,\"b\":[[\"1000.00\",\"24.604\"],[\"29097.00\",\"1.904\"],[\"29197.00\",\"0.021\"],[\"29497.00\",\"0.175\"],[\"71637.30\",\"0.043\"],[\"78108.50\",\"1.915\"],[\"78522.40\",\"9.386\"],[\"78801.00\",\"12.547\"],[\"79199.00\",\"4.236\"],[\"79475.50\",\"0.032\"],[\"79476.20\",\"0.005\"],[\"79510.10\",\"0.011\"],[\"79523.60\",\"0.038\"],[\"79584.90\",\"0.000\"],[\"79588.00\",\"0.088\"],[\"79595.40\",\"0.002\"],[\"79595.90\",\"0.002\"],[\"79597.00\",\"4.583\"]],\"a\":[[\"79643.70\",\"2.748\"],[\"79644.00\",\"0.006\"],[\"79644.10\",\"0.128\"],[\"79691.80\",\"0.124\"],[\"79691.90\",\"0.062\"],[\"79693.10\",\"0.019\"],[\"79701.50\",\"0.343\"],[\"79702.70\",\"0.053\"],[\"79705.10\",\"0.032\"],[\"79995.10\",\"4.366\"],[\"80393.10\",\"10.298\"],[\"80663.80\",\"1.159\"]],\"st\":1}}"}
{"receive_ns":1788567712299489000,"stream":"btcusdt@depth@100ms","event_type":"depthUpdate","event_time_ms":1788567712311,"raw_json":"{\"stream\":\"btcusdt@depth@100ms\",\"data\":{\"e\":\"depthUpdate\",\"E\":1788567712311,\"T\":1788567712309,\"s\":\"BTCUSDT\",\"ps\":\"BTCUSDT\",\"U\":11478507174080,\"u\":11478507179773,\"pu\":11478507173887,\"b\":[[\"29097.00\",\"1.764\"],[\"29197.00\",\"0.000\"],[\"29497.00\",\"0.336\"],[\"71637.30\",\"0.043\"],[\"76413.10\",\"0.000\"],[\"76413.20\",\"0.000\"],[\"78468.70\",\"9.201\"],[\"78665.70\",\"3.987\"],[\"78801.00\",\"12.547\"],[\"79199.00\",\"4.236\"],[\"79584.90\",\"0.000\"],[\"79588.00\",\"0.088\"],[\"79595.40\",\"0.001\"],[\"79595.90\",\"0.028\"]],\"a\":[[\"79601.30\",\"0.004\"],[\"79804.90\",\"0.456\"],[\"79806.90\",\"1.814\"],[\"80393.10\",\"10.298\"],[\"81189.00\",\"10.515\"],[\"87556.90\",\"0.000\"]],\"st\":1}}"}
{"receive_ns":1788567712380808000,"stream":"btcusdt@bookTicker","event_type":"bookTicker","event_time_ms":1788567712401,"raw_json":"{\"stream\":\"btcusdt@bookTicker\",\"data\":{\"e\":\"bookTicker\",\"u\":11478507185511,\"s\":\"BTCUSDT\",\"ps\":\"BTCUSDT\",\"b\":\"79597.00\",\"B\":\"4.447\",\"a\":\"79597.10\",\"A\":\"7.419\",\"T\":1788567712401,\"E\":1788567712401,\"st\":1}}"}
{"receive_ns":1788567712386240000,"stream":"btcusdt@bookTicker","event_type":"bookTicker","event_time_ms":1788567712403,"raw_json":"{\"stream\":\"btcusdt@bookTicker\",\"data\":{\"e\":\"bookTicker\",\"u\":11478507185644,\"s\":\"BTCUSDT\",\"ps\":\"BTCUSDT\",\"b\":\"79597.00\",\"B\":\"4.580\",\"a\":\"79597.10\",\"A\":\"7.419\",\"T\":1788567712403,\"E\":1788567712403,\"st\":1}}"}
{"receive_ns":1788567712390511000,"stream":"btcusdt@depth@100ms","event_type":"depthUpdate","event_time_ms":1788567712413,"raw_json":"{\"stream\":\"btcusdt@depth@100ms\",\"data\":{\"e\":\"depthUpdate\",\"E\":1788567712413,\"T\":1788567712410,\"s\":\"BTCUSDT\",\"ps\":\"BTCUSDT\",\"U\":11478507179948,\"u\":11478507185932,\"pu\":11478507179773,\"b\":[[\"1000.00\",\"24.604\"],[\"29097.00\",\"1.589\"],[\"29497.00\",\"0.511\"],[\"63678.00\",\"0.000\"],[\"71637.30\",\"0.043\"],[\"75617.20\",\"0.004\"],[\"76413.10\",\"0.002\"],[\"78801.00\",\"12.547\"],[\"78859.20\",\"0.258\"],[\"78866.60\",\"1.974\"],[\"79541.20\",\"0.002\"],[\"79584.70\",\"0.001\"],[\"79584.90\",\"0.000\"],[\"79588.00\",\"1.344\"],[\"79595.30\",\"0.027\"],[\"79595.90\",\"0.002\"],[\"79597.00\",\"4.580\"]],\"a\":[[\"79620.20\",\"0.455\"],[\"79621.30\",\"0.107\"],[\"79692.70\",\"0.003\"],[\"79804.90\",\"1.084\"],[\"79806.90\",\"4.996\"],[\"79818.80\",\"7.074\"],[\"80011.00\",\"0.265\"],[\"80393.10\",\"10.298\"],[\"80798.00\",\"0.010\"],[\"80962.00\",\"0.000\"]],\"st\":1}}"}
{"receive_ns":1788567712454430000,"stream":"btcusdt@bookTicker","event_type":"bookTicker","event_time_ms":1788567712456,"raw_json":"{\"stream\":\"btcusdt@bookTicker\",\"data\":{\"e\":\"bookTicker\",\"u\":11478507187934,\"s\":\"BTCUSDT\",\"ps\":\"BTCUSDT\",\"b\":\"79597.00\",\"B\":\"4.580\",\"a\":\"79597.10\",\"A\":\"7.418\",\"T\":1788567712456,\"E\":1788567712456,\"st\":1}}"}
{"receive_ns":1788567712460027000,"stream":"btcusdt@trade","event_type":"trade","event_time_ms":1788567712456,"raw_json":"{\"stream\":\"btcusdt@trade\",\"data\":{\"e\":\"trade\",\"E\":1788567712456,\"T\":1788567712456,\"s\":\"BTCUSDT\",\"t\":8054122561,\"p\":\"79597.10\",\"q\":\"0.001\",\"X\":\"MARKET\",\"m\":false,\"st\":1}}"}
{"receive_ns":1788567712466630000,"stream":"btcusdt@bookTicker","event_type":"bookTicker","event_time_ms":1788567712457,"raw_json":"{\"stream\":\"btcusdt@bookTicker\",\"data\":{\"e\":\"bookTicker\",\"u\":11478507187983,\"s\":\"BTCUSDT\",\"ps\":\"BTCUSDT\",\"b\":\"79597.00\",\"B\":\"5.112\",\"a\":\"79597.10\",\"A\":\"7.418\",\"T\":1788567712457,\"E\":1788567712457,\"st\":1}}"}
{"receive_ns":1788567712472959000,"stream":"btcusdt@bookTicker","event_type":"bookTicker","event_time_ms":1788567712458,"raw_json":"{\"stream\":\"btcusdt@bookTicker\",\"data\":{\"e\":\"bookTicker\",\"u\":11478507188107,\"s\":\"BTCUSDT\",\"ps\":\"BTCUSDT\",\"b\":\"79597.00\",\"B\":\"5.111\",\"a\":\"79597.10\",\"A\":\"7.418\",\"T\":1788567712458,\"E\":1788567712458,\"st\":1}}"}
{"receive_ns":1788567712478250000,"stream":"btcusdt@bookTicker","event_type":"bookTicker","event_time_ms":1788567712458,"raw_json":"{\"stream\":\"btcusdt@bookTicker\",\"data\":{\"e\":\"bookTicker\",\"u\":11478507188126,\"s\":\"BTCUSDT\",\"ps\":\"BTCUSDT\",\"b\":\"79597.00\",\"B\":\"5.110\",\"a\":\"79597.10\",\"A\":\"7.418\",\"T\":1788567712458,\"E\":1788567712458,\"st\":1}}"}
{"receive_ns":1788567712479299000,"stream":"btcusdt@bookTicker","event_type":"bookTicker","event_time_ms":1788567712459,"raw_json":"{\"stream\":\"btcusdt@bookTicker\",\"data\":{\"e\":\"bookTicker\",\"u\":11478507188175,\"s\":\"BTCUSDT\",\"ps\":\"BTCUSDT\",\"b\":\"79597.00\",\"B\":\"5.111\",\"a\":\"79597.10\",\"A\":\"7.418\",\"T\":1788567712459,\"E\":1788567712459,\"st\":1}}"}
{"receive_ns":1788567712485883000,"stream":"btcusdt@bookTicker","event_type":"bookTicker","event_time_ms":1788567712503,"raw_json":"{\"stream\":\"btcusdt@bookTicker\",\"data\":{\"e\":\"bookTicker\",\"u\":11478507190169,\"s\":\"BTCUSDT\",\"ps\":\"BTCUSDT\",\"b\":\"79597.00\",\"B\":\"5.111\",\"a\":\"79597.10\",\"A\":\"7.421\",\"T\":1788567712503,\"E\":1788567712503,\"st\":1}}"}
{"receive_ns":1788567712492748000,"stream":"btcusdt@depth@100ms","event_type":"depthUpdate","event_time_ms":1788567712515,"raw_json":"{\"stream\":\"btcusdt@depth@100ms\",\"data\":{\"e\":\"depthUpdate\",\"E\":1788567712515,\"T\":1788567712514,\"s\":\"BTCUSDT\",\"ps\":\"BTCUSDT\",\"U\":11478507186047,\"u\":11478507190957,\"pu\":11478507185932,\"b\":[[\"1000.00\",\"24.604\"],[\"29097.00\",\"1.407\"],[\"29497.00\",\"0.693\"],[\"71637.30\",\"0.043\"],[\"76413.10\",\"0.000\"],[\"78628.50\",\"10.796\"],[\"78710.90\",\"0.190\"],[\"78801.00\",\"12.547\"],[\"79471.10\",\"0.000\"],[\"79471.20\",\"0.003\"],[\"79495.10\",\"0.045\"],[\"79545.00\",\"0.321\"],[\"79546.50\",\"2.774\"],[\"79558.60\",\"0.000\"],[\"79565.00\",\"1.171\"],[\"79566.10\",\"0.003\"],[\"79566.20\",\"0.002\"],[\"79566.30\",\"0.433\"],[\"79566.80\",\"0.000\"],[\"79571.30\",\"0.693\"],[\"79584.70\",\"1.257\"],[\"79584.80\",\"0.004\"],[\"79588.00\",\"0.018\"],[\"79588.10\",\"0.315\"],[\"79588.20\",\"0.008\"],[\"79588.30\",\"0.004\"],[\"79588.40\",\"0.062\"],[\"79588.50\",\"0.085\"],[\"79589.20\",\"0.076\"],[\"79590.50\",\"0.078\"],[\"79593.90\",\"0.000\"],[\"79594.00\",\"0.076\"],[\"79595.50\",\"0.026\"],[\"79595.70\",\"0.027\"],[\"79596.20\",\"0.026\"],[\"79597.00\",\"5.111\"]],\"a\":[[\"79597.10\",\"7.421\"],[\"79598.50\",\"0.381\"],[\"79601.20\",\"0.000\"],[\"79610.60\",\"0.003\"],[\"79616.90\",\"0.774\"],[\"79818.80\",\"7.073\"],[\"80393.10\",\"10.298\"],[\"80552.30\",\"29.478\"],[\"80565.60\",\"8.680\"],[\"80638.80\",\"1.238\"]],\"st\":1}}"}
{"receive_ns":1788567712503951000,"stream":"btcusdt@bookTicker","event_type":"bookTicker","event_time_ms":1788567712517,"raw_json":"{\"stream\":\"btcusdt@bookTicker\",\"data\":{\"e\":\"bookTicker\",\"u\":11478507191099,\"s\":\"BTCUSDT\",\"ps\":\"BTCUSDT\",\"b\":\"79597.00\",\"B\":\"5.111\",\"a\":\"79597.10\",\"A\":\"7.467\",\"T\":1788567712517,\"E\":1788567712517,\"st\":1}}"}
{"receive_ns":1788567712514100000,"stream":"btcusdt@bookTicker","event_type":"bookTicker","event_time_ms":1788567712519,"raw_json":"{\"stream\":\"btcusdt@bookTicker\",\"data\":{\"e\":\"bookTicker\",\"u\":11478507191153,\"s\":\"BTCUSDT\",\"ps\":\"BTCUSDT\",\"b\":\"79597.00\",\"B\":\"5.112\",\"a\":\"79597.10\",\"A\":\"7.467\",\"T\":1788567712519,\"E\":1788567712519,\"st\":1}}"}
{"receive_ns":1788567712520615000,"stream":"btcusdt@bookTicker","event_type":"bookTicker","event_time_ms":1788567712519,"raw_json":"{\"stream\":\"btcusdt@bookTicker\",\"data\":{\"e\":\"bookTicker\",\"u\":11478507191154,\"s\":\"BTCUSDT\",\"ps\":\"BTCUSDT\",\"b\":\"79597.00\",\"B\":\"5.112\",\"a\":\"79597.10\",\"A\":\"7.465\",\"T\":1788567712519,\"E\":1788567712519,\"st\":1}}"}
{"receive_ns":1788567712562863000,"stream":"btcusdt@bookTicker","event_type":"bookTicker","event_time_ms":1788567712578,"raw_json":"{\"stream\":\"btcusdt@bookTicker\",\"data\":{\"e\":\"bookTicker\",\"u\":11478507194812,\"s\":\"BTCUSDT\",\"ps\":\"BTCUSDT\",\"b\":\"79597.00\",\"B\":\"5.112\",\"a\":\"79597.10\",\"A\":\"7.470\",\"T\":1788567712577,\"E\":1788567712578,\"st\":1}}"}
{"receive_ns":1788567712610243000,"stream":"btcusdt@depth@100ms","event_type":"depthUpdate","event_time_ms":1788567712617,"raw_json":"{\"stream\":\"btcusdt@depth@100ms\",\"data\":{\"e\":\"depthUpdate\",\"E\":1788567712617,\"T\":1788567712614,\"s\":\"BTCUSDT\",\"ps\":\"BTCUSDT\",\"U\":11478507191027,\"u\":11478507196980,\"pu\":11478507190957,\"b\":[[\"29097.00\",\"1.232\"],[\"29497.00\",\"0.868\"],[\"63678.00\",\"0.000\"],[\"71637.30\",\"0.043\"],[\"76413.10\",\"0.002\"],[\"78801.00\",\"12.547\"],[\"79199.00\",\"4.236\"],[\"79501.40\",\"0.048\"],[\"79525.30\",\"0.633\"],[\"79541.20\",\"0.000\"],[\"79565.00\",\"1.046\"],[\"79566.10\",\"0.003\"],[\"79566.40\",\"0.252\"],[\"79584.70\",\"0.001\"],[\"79584.80\",\"1.658\"],[\"79588.00\",\"0.004\"],[\"79588.10\",\"0.001\"],[\"79588.30\",\"0.000\"],[\"79588.40\",\"0.000\"],[\"79588.50\",\"0.081\"],[\"79595.40\",\"0.002\"],[\"79597.00\",\"5.112\"]],\"a\":[[\"79597.10\",\"7.470\"],[\"79668.80\",\"0.034\"],[\"79692.70\",\"0.001\"],[\"79995.10\",\"4.365\"],[\"80233.90\",\"6.593\"],[\"80353.30\",\"9.592\"],[\"80393.10\",\"10.298\"],[\"80472.70\",\"5.087\"],[\"80713.10\",\"0.592\"],[\"81189.00\",\"10.512\"]],\"st\":1}}"}
{"receive_ns":1788567712702399000,"stream":"btcusdt@depth@100ms","event_type":"depthUpdate","event_time_ms":1788567712719,"raw_json":"{\"stream\":\"btcusdt@depth@100ms\",\"data\":{\"e\":\"depthUpdate\",\"E\":1788567712719,\"T\":1788567712717,\"s\":\"BTCUSDT\",\"ps\":\"BTCUSDT\",\"U\":11478507197259,\"u\":11478507201249,\"pu\":11478507196980,\"b\":[[\"1000.00\",\"24.604\"],[\"29097.00\",\"1.050\"],[\"29497.00\",\"1.050\"],[\"63678.00\",\"0.000\"],[\"71637.30\",\"0.043\"],[\"71673.00\",\"0.000\"],[\"75617.10\",\"0.021\"],[\"75617.20\",\"0.006\"],[\"78588.10\",\"8.052\"],[\"78601.60\",\"0.000\"],[\"78603.90\",\"0.005\"],[\"78801.00\",\"12.547\"],[\"79028.70\",\"0.095\"],[\"79199.00\",\"4.237\"],[\"79417.50\",\"0.001\"],[\"79417.60\",\"3.154\"],[\"79509.80\",\"0.051\"],[\"79565.90\",\"0.247\"],[\"79566.40\",\"0.252\"]],\"a\":[[\"79685.00\",\"0.228\"],[\"79685.10\",\"0.012\"],[\"79741.30\",\"3.142\"],[\"79741.50\",\"0.400\"],[\"79780.00\",\"2.139\"],[\"80393.10\",\"9.677\"],[\"80645.20\",\"6.809\"]],\"st\":1}}"}
{"receive_ns":1788567712735117000,"stream":"btcusdt@bookTicker","event_type":"bookTicker","event_time_ms":1788567712758,"raw_json":"{\"stream\":\"btcusdt@bookTicker\",\"data\":{\"e\":\"bookTicker\",\"u\":11478507203156,\"s\":\"BTCUSDT\",\"ps\":\"BTCUSDT\",\"b\":\"79597.00\",\"B\":\"5.057\",\"a\":\"79597.10\",\"A\":\"7.470\",\"T\":1788567712757,\"E\":1788567712758,\"st\":1}}"}
{"receive_ns":1788567712743014000,"stream":"btcusdt@bookTicker","event_type":"bookTicker","event_time_ms":1788567712760,"raw_json":"{\"stream\":\"btcusdt@bookTicker\",\"data\":{\"e\":\"bookTicker\",\"u\":11478507203337,\"s\":\"BTCUSDT\",\"ps\":\"BTCUSDT\",\"b\":\"79597.00\",\"B\":\"5.110\",\"a\":\"79597.10\",\"A\":\"7.470\",\"T\":1788567712760,\"E\":1788567712760,\"st\":1}}"}
{"receive_ns":1788567712760213000,"stream":"btcusdt@bookTicker","event_type":"bookTicker","event_time_ms":1788567712762,"raw_json":"{\"stream\":\"btcusdt@bookTicker\",\"data\":{\"e\":\"bookTicker\",\"u\":11478507203411,\"s\":\"BTCUSDT\",\"ps\":\"BTCUSDT\",\"b\":\"79597.00\",\"B\":\"5.110\",\"a\":\"79597.10\",\"A\":\"7.472\",\"T\":1788567712762,\"E\":1788567712762,\"st\":1}}"}
{"receive_ns":1788567712804220000,"stream":"btcusdt@depth@100ms","event_type":"depthUpdate","event_time_ms":1788567712821,"raw_json":"{\"stream\":\"btcusdt@depth@100ms\",\"data\":{\"e\":\"depthUpdate\",\"E\":1788567712821,\"T\":1788567712817,\"s\":\"BTCUSDT\",\"ps\":\"BTCUSDT\",\"U\":11478507201321,\"u\":11478507205652,\"pu\":11478507201249,\"b\":[[\"1000.00\",\"24.604\"],[\"29097.00\",\"0.875\"],[\"29497.00\",\"1.225\"],[\"71637.30\",\"0.043\"],[\"76413.10\",\"0.000\"],[\"78466.70\",\"2.295\"],[\"78801.00\",\"12.547\"],[\"79564.70\",\"0.803\"],[\"79565.90\",\"0.122\"],[\"79567.70\",\"0.173\"],[\"79573.30\",\"0.002\"],[\"79587.80\",\"1.587\"],[\"79597.00\",\"5.110\"]],\"a\":[[\"79597.10\",\"7.472\"],[\"79613.20\",\"0.005\"],[\"80393.10\",\"9.677\"],[\"80552.30\",\"28.983\"]],\"st\":1}}"}
{"receive_ns":1788567712860050000,"stream":"btcusdt@bookTicker","event_type":"bookTicker","event_time_ms":1788567712877,"raw_json":"{\"stream\":\"btcusdt@bookTicker\",\"data\":{\"e\":\"bookTicker\",\"u\":11478507208931,\"s\":\"BTCUSDT\",\"ps\":\"BTCUSDT\",\"b\":\"79597.00\",\"B\":\"5.110\",\"a\":\"79597.10\",\"A\":\"7.473\",\"T\":1788567712877,\"E\":1788567712877,\"st\":1}}"}
{"receive_ns":1788567712885819000,"stream":"btcusdt@bookTicker","event_type":"bookTicker","event_time_ms":1788567712902,"raw_json":"{\"stream\":\"btcusdt@bookTicker\",\"data\":{\"e\":\"bookTicker\",\"u\":11478507210507,\"s\":\"BTCUSDT\",\"ps\":\"BTCUSDT\",\"b\":\"79597.00\",\"B\":\"5.110\",\"a\":\"79597.10\",\"A\":\"7.472\",\"T\":1788567712902,\"E\":1788567712902,\"st\":1}}"}
{"receive_ns":1788567712892776000,"stream":"btcusdt@trade","event_type":"trade","event_time_ms":1788567712902,"raw_json":"{\"stream\":\"btcusdt@trade\",\"data\":{\"e\":\"trade\",\"E\":1788567712902,\"T\":1788567712902,\"s\":\"BTCUSDT\",\"t\":8054122562,\"p\":\"79597.10\",\"q\":\"0.001\",\"X\":\"MARKET\",\"m\":false,\"st\":1}}"}
{"receive_ns":1788567712904855000,"stream":"btcusdt@bookTicker","event_type":"bookTicker","event_time_ms":1788567712905,"raw_json":"{\"stream\":\"btcusdt@bookTicker\",\"data\":{\"e\":\"bookTicker\",\"u\":11478507210864,\"s\":\"BTCUSDT\",\"ps\":\"BTCUSDT\",\"b\":\"79597.00\",\"B\":\"5.110\",\"a\":\"79597.10\",\"A\":\"7.446\",\"T\":1788567712905,\"E\":1788567712905,\"st\":1}}"}
{"receive_ns":1788567712910688000,"stream":"btcusdt@depth@100ms","event_type":"depthUpdate","event_time_ms":1788567712923,"raw_json":"{\"stream\":\"btcusdt@depth@100ms\",\"data\":{\"e\":\"depthUpdate\",\"E\":1788567712923,\"T\":1788567712922,\"s\":\"BTCUSDT\",\"ps\":\"BTCUSDT\",\"U\":11478507205762,\"u\":11478507211824,\"pu\":11478507205652,\"b\":[[\"29097.00\",\"0.693\"],[\"29497.00\",\"1.407\"],[\"63678.00\",\"0.000\"],[\"71637.30\",\"0.043\"],[\"76413.10\",\"0.002\"],[\"78562.20\",\"12.046\"],[\"78801.00\",\"12.547\"],[\"79199.00\",\"4.247\"],[\"79569.30\",\"0.002\"],[\"79573.80\",\"0.074\"],[\"79594.20\",\"0.000\"],[\"79596.90\",\"2.491\"]],\"a\":[[\"79597.10\",\"7.446\"],[\"79597.40\",\"0.000\"],[\"80233.90\",\"7.340\"],[\"80393.10\",\"9.677\"],[\"80486.00\",\"9.655\"],[\"80592.10\",\"10.593\"],[\"81189.00\",\"10.515\"]],\"st\":1}}"}
{"receive_ns":1788567712922819000,"stream":"btcusdt@bookTicker","event_type":"bookTicker","event_time_ms":1788567712937,"raw_json":"{\"stream\":\"btcusdt@bookTicker\",\"data\":{\"e\":\"bookTicker\",\"u\":11478507212839,\"s\":\"BTCUSDT\",\"ps\":\"BTCUSDT\",\"b\":\"79597.00\",\"B\":\"5.110\",\"a\":\"79597.10\",\"A\":\"7.460\",\"T\":1788567712937,\"E\":1788567712937,\"st\":1}}"}
{"receive_ns":1788567712948707000,"stream":"btcusdt@bookTicker","event_type":"bookTicker","event_time_ms":1788567712964,"raw_json":"{\"stream\":\"btcusdt@bookTicker\",\"data\":{\"e\":\"bookTicker\",\"u\":11478507214855,\"s\":\"BTCUSDT\",\"ps\":\"BTCUSDT\",\"b\":\"79597.00\",\"B\":\"5.110\",\"a\":\"79597.10\",\"A\":\"6.089\",\"T\":1788567712964,\"E\":1788567712964,\"st\":1}}"}
{"receive_ns":1788567712959495000,"stream":"btcusdt@bookTicker","event_type":"bookTicker","event_time_ms":1788567712964,"raw_json":"{\"stream\":\"btcusdt@bookTicker\",\"data\":{\"e\":\"bookTicker\",\"u\":11478507214858,\"s\":\"BTCUSDT\",\"ps\":\"BTCUSDT\",\"b\":\"79597.00\",\"B\":\"5.110\",\"a\":\"79597.10\",\"A\":\"6.075\",\"T\":1788567712964,\"E\":1788567712964,\"st\":1}}"}
{"receive_ns":1788567712959763000,"stream":"btcusdt@bookTicker","event_type":"bookTicker","event_time_ms":1788567712965,"raw_json":"{\"stream\":\"btcusdt@bookTicker\",\"data\":{\"e\":\"bookTicker\",\"u\":11478507214889,\"s\":\"BTCUSDT\",\"ps\":\"BTCUSDT\",\"b\":\"79597.00\",\"B\":\"5.110\",\"a\":\"79597.10\",\"A\":\"6.073\",\"T\":1788567712965,\"E\":1788567712965,\"st\":1}}"}
{"receive_ns":1788567712959985000,"stream":"btcusdt@bookTicker","event_type":"bookTicker","event_time_ms":1788567712969,"raw_json":"{\"stream\":\"btcusdt@bookTicker\",\"data\":{\"e\":\"bookTicker\",\"u\":11478507215053,\"s\":\"BTCUSDT\",\"ps\":\"BTCUSDT\",\"b\":\"79597.00\",\"B\":\"5.110\",\"a\":\"79597.10\",\"A\":\"6.072\",\"T\":1788567712968,\"E\":1788567712969,\"st\":1}}"}
{"receive_ns":1788567712965603000,"stream":"btcusdt@bookTicker","event_type":"bookTicker","event_time_ms":1788567712969,"raw_json":"{\"stream\":\"btcusdt@bookTicker\",\"data\":{\"e\":\"bookTicker\",\"u\":11478507215057,\"s\":\"BTCUSDT\",\"ps\":\"BTCUSDT\",\"b\":\"79597.00\",\"B\":\"5.110\",\"a\":\"79597.10\",\"A\":\"6.071\",\"T\":1788567712968,\"E\":1788567712969,\"st\":1}}"}
{"receive_ns":1788567712983245000,"stream":"btcusdt@bookTicker","event_type":"bookTicker","event_time_ms":1788567712970,"raw_json":"{\"stream\":\"btcusdt@bookTicker\",\"data\":{\"e\":\"bookTicker\",\"u\":11478507215116,\"s\":\"BTCUSDT\",\"ps\":\"BTCUSDT\",\"b\":\"79597.00\",\"B\":\"5.110\",\"a\":\"79597.10\",\"A\":\"6.064\",\"T\":1788567712969,\"E\":1788567712970,\"st\":1}}"}
{"receive_ns":1788567712983507000,"stream":"btcusdt@bookTicker","event_type":"bookTicker","event_time_ms":1788567712972,"raw_json":"{\"stream\":\"btcusdt@bookTicker\",\"data\":{\"e\":\"bookTicker\",\"u\":11478507215234,\"s\":\"BTCUSDT\",\"ps\":\"BTCUSDT\",\"b\":\"79597.00\",\"B\":\"5.110\",\"a\":\"79597.10\",\"A\":\"6.018\",\"T\":1788567712972,\"E\":1788567712972,\"st\":1}}"}
{"receive_ns":1788567712983770000,"stream":"btcusdt@bookTicker","event_type":"bookTicker","event_time_ms":1788567712973,"raw_json":"{\"stream\":\"btcusdt@bookTicker\",\"data\":{\"e\":\"bookTicker\",\"u\":11478507215243,\"s\":\"BTCUSDT\",\"ps\":\"BTCUSDT\",\"b\":\"79597.00\",\"B\":\"5.110\",\"a\":\"79597.10\",\"A\":\"6.017\",\"T\":1788567712973,\"E\":1788567712973,\"st\":1}}"}
{"receive_ns":1788567712989360000,"stream":"btcusdt@bookTicker","event_type":"bookTicker","event_time_ms":1788567712974,"raw_json":"{\"stream\":\"btcusdt@bookTicker\",\"data\":{\"e\":\"bookTicker\",\"u\":11478507215308,\"s\":\"BTCUSDT\",\"ps\":\"BTCUSDT\",\"b\":\"79597.00\",\"B\":\"5.110\",\"a\":\"79597.10\",\"A\":\"6.003\",\"T\":1788567712973,\"E\":1788567712974,\"st\":1}}"}
{"receive_ns":1788567713005152000,"stream":"btcusdt@bookTicker","event_type":"bookTicker","event_time_ms":1788567712974,"raw_json":"{\"stream\":\"btcusdt@bookTicker\",\"data\":{\"e\":\"bookTicker\",\"u\":11478507215356,\"s\":\"BTCUSDT\",\"ps\":\"BTCUSDT\",\"b\":\"79597.00\",\"B\":\"5.110\",\"a\":\"79597.10\",\"A\":\"5.867\",\"T\":1788567712974,\"E\":1788567712974,\"st\":1}}"}
{"receive_ns":1788567713015888000,"stream":"btcusdt@bookTicker","event_type":"bookTicker","event_time_ms":1788567712979,"raw_json":"{\"stream\":\"btcusdt@bookTicker\",\"data\":{\"e\":\"bookTicker\",\"u\":11478507215633,\"s\":\"BTCUSDT\",\"ps\":\"BTCUSDT\",\"b\":\"79597.00\",\"B\":\"5.110\",\"a\":\"79597.10\",\"A\":\"5.865\",\"T\":1788567712978,\"E\":1788567712979,\"st\":1}}"}
{"receive_ns":1788567713032416000,"stream":"btcusdt@bookTicker","event_type":"bookTicker","event_time_ms":1788567712983,"raw_json":"{\"stream\":\"btcusdt@bookTicker\",\"data\":{\"e\":\"bookTicker\",\"u\":11478507215853,\"s\":\"BTCUSDT\",\"ps\":\"BTCUSDT\",\"b\":\"79597.00\",\"B\":\"5.110\",\"a\":\"79597.10\",\"A\":\"5.860\",\"T\":1788567712982,\"E\":1788567712983,\"st\":1}}"}
{"receive_ns":1788567713044337000,"stream":"btcusdt@depth@100ms","event_type":"depthUpdate","event_time_ms":1788567713025,"raw_json":"{\"stream\":\"btcusdt@depth@100ms\",\"data\":{\"e\":\"depthUpdate\",\"E\":1788567713025,\"T\":1788567713021,\"s\":\"BTCUSDT\",\"ps\":\"BTCUSDT\",\"U\":11478507211904,\"u\":11478507217680,\"pu\":11478507211824,\"b\":[[\"1000.00\",\"24.604\"],[\"29097.00\",\"0.518\"],[\"29497.00\",\"1.582\"],[\"63677.60\",\"0.000\"],[\"63678.00\",\"0.000\"],[\"71637.30\",\"0.043\"],[\"76413.10\",\"0.000\"],[\"78522.40\",\"9.894\"],[\"78801.00\",\"12.547\"],[\"79571.30\",\"0.002\"],[\"79596.50\",\"0.081\"]],\"a\":[[\"79597.10\",\"5.860\"],[\"79597.20\",\"0.007\"],[\"79597.30\",\"0.100\"],[\"79597.50\",\"0.002\"],[\"79597.70\",\"0.147\"],[\"79597.80\",\"0.561\"],[\"79597.90\",\"0.002\"],[\"79598.50\",\"0.407\"],[\"79605.60\",\"0.006\"],[\"79606.90\",\"0.001\"],[\"79607.40\",\"0.057\"],[\"79616.90\",\"0.083\"],[\"79626.50\",\"4.523\"],[\"80393.10\",\"9.677\"],[\"80552.30\",\"29.478\"]],\"st\":1}}"}
{"receive_ns":1788567713070079000,"stream":"btcusdt@bookTicker","event_type":"bookTicker","event_time_ms":1788567713084,"raw_json":"{\"stream\":\"btcusdt@bookTicker\",\"data\":{\"e\":\"bookTicker\",\"u\":11478507222715,\"s\":\"BTCUSDT\",\"ps\":\"BTCUSDT\",\"b\":\"79597.00\",\"B\":\"5.110\",\"a\":\"79597.10\",\"A\":\"5.910\",\"T\":1788567713084,\"E\":1788567713084,\"st\":1}}"}
{"receive_ns":1788567713105885000,"stream":"btcusdt@depth@100ms","event_type":"depthUpdate","event_time_ms":1788567713127,"raw_json":"{\"stream\":\"btcusdt@depth@100ms\",\"data\":{\"e\":\"depthUpdate\",\"E\":1788567713127,\"T\":1788567713125,\"s\":\"BTCUSDT\",\"ps\":\"BTCUSDT\",\"U\":11478507217817,\"u\":11478507225659,\"pu\":11478507217680,\"b\":[[\"1000.00\",\"24.604\"],[\"29097.00\",\"0.343\"],[\"29397.00\",\"0.007\"],[\"29497.00\",\"1.750\"],[\"63678.00\",\"0.000\"],[\"71637.30\",\"0.002\"],[\"78164.30\",\"9.157\"],[\"78801.00\",\"12.547\"],[\"79460.70\",\"0.002\"],[\"79582.70\",\"0.194\"]],\"a\":[[\"79597.10\",\"5.910\"],[\"79597.80\",\"0.345\"],[\"79607.40\",\"0.056\"],[\"79607.90\",\"0.001\"],[\"79701.50\",\"0.344\"],[\"80164.80\",\"0.093\"],[\"80393.10\",\"9.677\"],[\"80472.70\",\"5.273\"],[\"80617.60\",\"12.453\"]],\"st\":1}}"}
{"receive_ns":1788567713121795000,"stream":"btcusdt@bookTicker","event_type":"bookTicker","event_time_ms":1788567713137,"raw_json":"{\"stream\":\"btcusdt@bookTicker\",\"data\":{\"e\":\"bookTicker\",\"u\":11478507226413,\"s\":\"BTCUSDT\",\"ps\":\"BTCUSDT\",\"b\":\"79597.00\",\"B\":\"5.110\",\"a\":\"79597.10\",\"A\":\"7.347\",\"T\":1788567713137,\"E\":1788567713137,\"st\":1}}"}
{"receive_ns":1788567713132688000,"stream":"btcusdt@bookTicker","event_type":"bookTicker","event_time_ms":1788567713138,"raw_json":"{\"stream\":\"btcusdt@bookTicker\",\"data\":{\"e\":\"bookTicker\",\"u\":11478507226472,\"s\":\"BTCUSDT\",\"ps\":\"BTCUSDT\",\"b\":\"79597.00\",\"B\":\"5.110\",\"a\":\"79597.10\",\"A\":\"7.345\",\"T\":1788567713138,\"E\":1788567713138,\"st\":1}}"}
{"receive_ns":1788567713140959000,"stream":"btcusdt@bookTicker","event_type":"bookTicker","event_time_ms":1788567713140,"raw_json":"{\"stream\":\"btcusdt@bookTicker\",\"data\":{\"e\":\"bookTicker\",\"u\":11478507226574,\"s\":\"BTCUSDT\",\"ps\":\"BTCUSDT\",\"b\":\"79597.00\",\"B\":\"5.110\",\"a\":\"79597.10\",\"A\":\"7.421\",\"T\":1788567713140,\"E\":1788567713140,\"st\":1}}"}
{"receive_ns":1788567713141213000,"stream":"btcusdt@bookTicker","event_type":"bookTicker","event_time_ms":1788567713140,"raw_json":"{\"stream\":\"btcusdt@bookTicker\",\"data\":{\"e\":\"bookTicker\",\"u\":11478507226582,\"s\":\"BTCUSDT\",\"ps\":\"BTCUSDT\",\"b\":\"79597.00\",\"B\":\"5.110\",\"a\":\"79597.10\",\"A\":\"7.497\",\"T\":1788567713140,\"E\":1788567713140,\"st\":1}}"}
{"receive_ns":1788567713146640000,"stream":"btcusdt@bookTicker","event_type":"bookTicker","event_time_ms":1788567713140,"raw_json":"{\"stream\":\"btcusdt@bookTicker\",\"data\":{\"e\":\"bookTicker\",\"u\":11478507226598,\"s\":\"BTCUSDT\",\"ps\":\"BTCUSDT\",\"b\":\"79597.00\",\"B\":\"5.110\",\"a\":\"79597.10\",\"A\":\"7.573\",\"T\":1788567713140,\"E\":1788567713140,\"st\":1}}"}
{"receive_ns":1788567713152004000,"stream":"btcusdt@bookTicker","event_type":"bookTicker","event_time_ms":1788567713141,"raw_json":"{\"stream\":\"btcusdt@bookTicker\",\"data\":{\"e\":\"bookTicker\",\"u\":11478507226637,\"s\":\"BTCUSDT\",\"ps\":\"BTCUSDT\",\"b\":\"79597.00\",\"B\":\"5.110\",\"a\":\"79597.10\",\"A\":\"7.575\",\"T\":1788567713141,\"E\":1788567713141,\"st\":1}}"}
{"receive_ns":1788567713157460000,"stream":"btcusdt@bookTicker","event_type":"bookTicker","event_time_ms":1788567713147,"raw_json":"{\"stream\":\"btcusdt@bookTicker\",\"data\":{\"e\":\"bookTicker\",\"u\":11478507226888,\"s\":\"BTCUSDT\",\"ps\":\"BTCUSDT\",\"b\":\"79597.00\",\"B\":\"5.110\",\"a\":\"79597.10\",\"A\":\"7.719\",\"T\":1788567713147,\"E\":1788567713147,\"st\":1}}"}
{"receive_ns":1788567713162975000,"stream":"btcusdt@bookTicker","event_type":"bookTicker","event_time_ms":1788567713148,"raw_json":"{\"stream\":\"btcusdt@bookTicker\",\"data\":{\"e\":\"bookTicker\",\"u\":11478507226948,\"s\":\"BTCUSDT\",\"ps\":\"BTCUSDT\",\"b\":\"79597.00\",\"B\":\"5.110\",\"a\":\"79597.10\",\"A\":\"7.717\",\"T\":1788567713148,\"E\":1788567713148,\"st\":1}}"}
{"receive_ns":1788567713163204000,"stream":"btcusdt@bookTicker","event_type":"bookTicker","event_time_ms":1788567713148,"raw_json":"{\"stream\":\"btcusdt@bookTicker\",\"data\":{\"e\":\"bookTicker\",\"u\":11478507226954,\"s\":\"BTCUSDT\",\"ps\":\"BTCUSDT\",\"b\":\"79597.00\",\"B\":\"5.110\",\"a\":\"79597.10\",\"A\":\"7.718\",\"T\":1788567713148,\"E\":1788567713148,\"st\":1}}"}
{"receive_ns":1788567713197587000,"stream":"btcusdt@bookTicker","event_type":"bookTicker","event_time_ms":1788567713218,"raw_json":"{\"stream\":\"btcusdt@bookTicker\",\"data\":{\"e\":\"bookTicker\",\"u\":11478507231442,\"s\":\"BTCUSDT\",\"ps\":\"BTCUSDT\",\"b\":\"79597.00\",\"B\":\"5.110\",\"a\":\"79597.10\",\"A\":\"7.755\",\"T\":1788567713217,\"E\":1788567713218,\"st\":1}}"}
{"receive_ns":1788567713203325000,"stream":"btcusdt@bookTicker","event_type":"bookTicker","event_time_ms":1788567713219,"raw_json":"{\"stream\":\"btcusdt@bookTicker\",\"data\":{\"e\":\"bookTicker\",\"u\":11478507231573,\"s\":\"BTCUSDT\",\"ps\":\"BTCUSDT\",\"b\":\"79597.00\",\"B\":\"5.110\",\"a\":\"79597.10\",\"A\":\"7.757\",\"T\":1788567713219,\"E\":1788567713219,\"st\":1}}"}
{"receive_ns":1788567713214467000,"stream":"btcusdt@depth@100ms","event_type":"depthUpdate","event_time_ms":1788567713229,"raw_json":"{\"stream\":\"btcusdt@depth@100ms\",\"data\":{\"e\":\"depthUpdate\",\"E\":1788567713229,\"T\":1788567713227,\"s\":\"BTCUSDT\",\"ps\":\"BTCUSDT\",\"U\":11478507225754,\"u\":11478507232184,\"pu\":11478507225659,\"b\":[[\"29097.00\",\"0.224\"],[\"29397.00\",\"0.063\"],[\"29497.00\",\"1.813\"],[\"71637.30\",\"0.002\"],[\"76413.10\",\"0.002\"],[\"78721.40\",\"6.850\"],[\"78801.00\",\"12.547\"],[\"79199.00\",\"4.236\"],[\"79451.70\",\"1.896\"],[\"79542.70\",\"0.000\"],[\"79596.50\",\"0.005\"]],\"a\":[[\"79597.10\",\"7.757\"],[\"79597.90\",\"0.002\"],[\"79598.10\",\"0.026\"],[\"79605.60\",\"0.007\"],[\"79607.90\",\"0.000\"],[\"79610.70\",\"0.543\"],[\"79612.80\",\"0.003\"],[\"79691.80\",\"0.124\"],[\"79691.90\",\"0.063\"],[\"79720.10\",\"2.476\"],[\"80393.10\",\"9.677\"],[\"80963.60\",\"4.939\"]],\"st\":1}}"}
{"receive_ns":1788567713313630000,"stream":"btcusdt@depth@100ms","event_type":"depthUpdate","event_time_ms":1788567713331,"raw_json":"{\"stream\":\"btcusdt@depth@100ms\",\"data\":{\"e\":\"depthUpdate\",\"E\":1788567713331,\"T\":1788567713330,\"s\":\"BTCUSDT\",\"ps\":\"BTCUSDT\",\"U\":11478507232372,\"u\":11478507237393,\"pu\":11478507232184,\"b\":[[\"1000.00\",\"24.754\"],[\"29097.00\",\"0.105\"],[\"29397.00\",\"0.126\"],[\"29497.00\",\"1.869\"],[\"71637.30\",\"0.002\"],[\"76413.10\",\"0.000\"],[\"78588.70\",\"6.355\"],[\"78602.00\",\"15.442\"],[\"78801.00\",\"12.547\"],[\"78866.70\",\"7.259\"],[\"79460.70\",\"0.003\"],[\"79567.70\",\"0.167\"],[\"79575.50\",\"1.593\"]],\"a\":[[\"79597.90\",\"0.028\"],[\"79610.70\",\"0.104\"],[\"79611.90\",\"0.440\"],[\"79995.10\",\"4.366\"],[\"80194.10\",\"4.361\"],[\"80393.10\",\"9.677\"],[\"81427.80\",\"1.104\"]],\"st\":1}}"}
{"receive_ns":1788567713357763000,"stream":"btcusdt@bookTicker","event_type":"bookTicker","event_time_ms":1788567713367,"raw_json":"{\"stream\":\"btcusdt@bookTicker\",\"data\":{\"e\":\"bookTicker\",\"u\":11478507239043,\"s\":\"BTCUSDT\",\"ps\":\"BTCUSDT\",\"b\":\"79597.00\",\"B\":\"5.069\",\"a\":\"79597.10\",\"A\":\"7.757\",\"T\":1788567713366,\"E\":1788567713367,\"st\":1}}"}
{"receive_ns":1788567713395279000,"stream":"btcusdt@bookTicker","event_type":"bookTicker","event_time_ms":1788567713411,"raw_json":"{\"stream\":\"btcusdt@bookTicker\",\"data\":{\"e\":\"bookTicker\",\"u\":11478507241003,\"s\":\"BTCUSDT\",\"ps\":\"BTCUSDT\",\"b\":\"79597.00\",\"B\":\"5.069\",\"a\":\"79597.10\",\"A\":\"7.756\",\"T\":1788567713410,\"E\":1788567713411,\"st\":1}}"}
{"receive_ns":1788567713401655000,"stream":"btcusdt@trade","event_type":"trade","event_time_ms":1788567713411,"raw_json":"{\"stream\":\"btcusdt@trade\",\"data\":{\"e\":\"trade\",\"E\":1788567713411,\"T\":1788567713410,\"s\":\"BTCUSDT\",\"t\":8054122563,\"p\":\"79597.10\",\"q\":\"0.001\",\"X\":\"MARKET\",\"m\":false,\"st\":1}}"}
{"receive_ns":1788567713407331000,"stream":"btcusdt@bookTicker","event_type":"bookTicker","event_time_ms":1788567713412,"raw_json":"{\"stream\":\"btcusdt@bookTicker\",\"data\":{\"e\":\"bookTicker\",\"u\":11478507241140,\"s\":\"BTCUSDT\",\"ps\":\"BTCUSDT\",\"b\":\"79597.00\",\"B\":\"5.057\",\"a\":\"79597.10\",\"A\":\"7.756\",\"T\":1788567713412,\"E\":1788567713412,\"st\":1}}"}
{"receive_ns":1788567713412917000,"stream":"btcusdt@bookTicker","event_type":"bookTicker","event_time_ms":1788567713426,"raw_json":"{\"stream\":\"btcusdt@bookTicker\",\"data\":{\"e\":\"bookTicker\",\"u\":11478507241803,\"s\":\"BTCUSDT\",\"ps\":\"BTCUSDT\",\"b\":\"79597.00\",\"B\":\"5.083\",\"a\":\"79597.10\",\"A\":\"7.756\",\"T\":1788567713426,\"E\":1788567713426,\"st\":1}}"}
{"receive_ns":1788567713413160000,"stream":"btcusdt@bookTicker","event_type":"bookTicker","event_time_ms":1788567713430,"raw_json":"{\"stream\":\"btcusdt@bookTicker\",\"data\":{\"e\":\"bookTicker\",\"u\":11478507241970,\"s\":\"BTCUSDT\",\"ps\":\"BTCUSDT\",\"b\":\"79597.00\",\"B\":\"5.083\",\"a\":\"79597.10\",\"A\":\"7.680\",\"T\":1788567713429,\"E\":1788567713430,\"st\":1}}"}
{"receive_ns":1788567713413356000,"stream":"btcusdt@bookTicker","event_type":"bookTicker","event_time_ms":1788567713430,"raw_json":"{\"stream\":\"btcusdt@bookTicker\",\"data\":{\"e\":\"bookTicker\",\"u\":11478507241972,\"s\":\"BTCUSDT\",\"ps\":\"BTCUSDT\",\"b\":\"79597.00\",\"B\":\"5.083\",\"a\":\"79597.10\",\"A\":\"7.604\",\"T\":1788567713430,\"E\":1788567713430,\"st\":1}}"}
{"receive_ns":1788567713413623000,"stream":"btcusdt@bookTicker","event_type":"bookTicker","event_time_ms":1788567713430,"raw_json":"{\"stream\":\"btcusdt@bookTicker\",\"data\":{\"e\":\"bookTicker\",\"u\":11478507241976,\"s\":\"BTCUSDT\",\"ps\":\"BTCUSDT\",\"b\":\"79597.00\",\"B\":\"5.083\",\"a\":\"79597.10\",\"A\":\"7.528\",\"T\":1788567713430,\"E\":1788567713430,\"st\":1}}"}
{"receive_ns":1788567713429968000,"stream":"btcusdt@depth@100ms","event_type":"depthUpdate","event_time_ms":1788567713433,"raw_json":"{\"stream\":\"btcusdt@depth@100ms\",\"data\":{\"e\":\"depthUpdate\",\"E\":1788567713433,\"T\":1788567713431,\"s\":\"BTCUSDT\",\"ps\":\"BTCUSDT\",\"U\":11478507237455,\"u\":11478507242081,\"pu\":11478507237393,\"b\":[[\"1000.00\",\"24.604\"],[\"29097.00\",\"0.007\"],[\"29397.00\",\"0.203\"],[\"29497.00\",\"1.890\"],[\"71637.30\",\"0.002\"],[\"75617.10\",\"0.023\"],[\"76413.10\",\"0.002\"],[\"78005.10\",\"10.828\"],[\"78542.50\",\"0.073\"],[\"78701.10\",\"0.001\"],[\"78801.00\",\"12.549\"],[\"79495.10\",\"0.024\"],[\"79583.60\",\"1.411\"],[\"79584.80\",\"0.004\"],[\"79587.00\",\"0.852\"],[\"79588.00\",\"1.658\"],[\"79596.90\",\"2.465\"],[\"79597.00\",\"5.083\"]],\"a\":[[\"79597.10\",\"7.528\"],[\"79597.50\",\"0.002\"],[\"79599.90\",\"0.004\"],[\"80393.10\",\"9.681\"]],\"st\":1}}"}
{"receive_ns":1788567713472529000,"stream":"btcusdt@bookTicker","event_type":"bookTicker","event_time_ms":1788567713493,"raw_json":"{\"stream\":\"btcusdt@bookTicker\",\"data\":{\"e\":\"bookTicker\",\"u\":11478507244295,\"s\":\"BTCUSDT\",\"ps\":\"BTCUSDT\",\"b\":\"79597.00\",\"B\":\"4.950\",\"a\":\"79597.10\",\"A\":\"7.528\",\"T\":1788567713493,\"E\":1788567713493,\"st\":1}}"}
{"receive_ns":1788567713478347000,"stream":"btcusdt@bookTicker","event_type":"bookTicker","event_time_ms":1788567713495,"raw_json":"{\"stream\":\"btcusdt@bookTicker\",\"data\":{\"e\":\"bookTicker\",\"u\":11478507244408,\"s\":\"BTCUSDT\",\"ps\":\"BTCUSDT\",\"b\":\"79597.00\",\"B\":\"4.950\",\"a\":\"79597.10\",\"A\":\"7.604\",\"T\":1788567713495,\"E\":1788567713495,\"st\":1}}"}
{"receive_ns":1788567713484069000,"stream":"btcusdt@bookTicker","event_type":"bookTicker","event_time_ms":1788567713495,"raw_json":"{\"stream\":\"btcusdt@bookTicker\",\"data\":{\"e\":\"bookTicker\",\"u\":11478507244416,\"s\":\"BTCUSDT\",\"ps\":\"BTCUSDT\",\"b\":\"79597.00\",\"B\":\"4.950\",\"a\":\"79597.10\",\"A\":\"7.680\",\"T\":1788567713495,\"E\":1788567713495,\"st\":1}}"}
{"receive_ns":1788567713501105000,"stream":"btcusdt@bookTicker","event_type":"bookTicker","event_time_ms":1788567713495,"raw_json":"{\"stream\":\"btcusdt@bookTicker\",\"data\":{\"e\":\"bookTicker\",\"u\":11478507244422,\"s\":\"BTCUSDT\",\"ps\":\"BTCUSDT\",\"b\":\"79597.00\",\"B\":\"5.082\",\"a\":\"79597.10\",\"A\":\"7.680\",\"T\":1788567713495,\"E\":1788567713495,\"st\":1}}"}
{"receive_ns":1788567713519510000,"stream":"btcusdt@bookTicker","event_type":"bookTicker","event_time_ms":1788567713497,"raw_json":"{\"stream\":\"btcusdt@bookTicker\",\"data\":{\"e\":\"bookTicker\",\"u\":11478507244470,\"s\":\"BTCUSDT\",\"ps\":\"BTCUSDT\",\"b\":\"79597.00\",\"B\":\"5.081\",\"a\":\"79597.10\",\"A\":\"7.680\",\"T\":1788567713497,\"E\":1788567713497,\"st\":1}}"}
{"receive_ns":1788567713543984000,"stream":"btcusdt@depth@100ms","event_type":"depthUpdate","event_time_ms":1788567713535,"raw_json":"{\"stream\":\"btcusdt@depth@100ms\",\"data\":{\"e\":\"depthUpdate\",\"E\":1788567713535,\"T\":1788567713533,\"s\":\"BTCUSDT\",\"ps\":\"BTCUSDT\",\"U\":11478507242120,\"u\":11478507246155,\"pu\":11478507242081,\"b\":[[\"29097.00\",\"0.000\"],[\"29397.00\",\"0.378\"],[\"29497.00\",\"1.722\"],[\"71637.30\",\"0.002\"],[\"76413.10\",\"0.000\"],[\"78542.10\",\"0.000\"],[\"78542.40\",\"0.057\"],[\"78548.10\",\"0.000\"],[\"78562.10\",\"1.780\"],[\"78801.00\",\"12.547\"],[\"79199.00\",\"4.236\"],[\"79507.80\",\"0.000\"],[\"79517.40\",\"0.737\"],[\"79531.30\",\"20.402\"],[\"79536.70\",\"0.001\"],[\"79541.00\",\"1.145\"],[\"79541.20\",\"0.002\"],[\"79556.90\",\"1.700\"],[\"79564.70\",\"0.678\"],[\"79567.70\",\"0.292\"],[\"79584.70\",\"0.001\"],[\"79584.80\",\"0.004\"],[\"79588.00\",\"1.344\"],[\"79588.10\",\"0.315\"],[\"79596.70\",\"0.000\"],[\"79597.00\",\"5.081\"]],\"a\":[[\"79597.10\",\"7.680\"],[\"79597.20\",\"0.083\"],[\"79597.70\",\"0.173\"],[\"79597.90\",\"0.045\"],[\"79598.00\",\"0.099\"],[\"79610.60\",\"0.694\"],[\"79626.60\",\"0.834\"],[\"79627.20\",\"0.122\"],[\"79643.90\",\"0.000\"],[\"79644.10\",\"0.003\"],[\"79644.40\",\"0.991\"],[\"79655.10\",\"0.003\"],[\"79692.70\",\"0.003\"],[\"79756.30\",\"0.003\"],[\"80299.20\",\"4.229\"],[\"80393.10\",\"9.677\"],[\"80577.80\",\"3.971\"]],\"st\":1}}"}
{"receive_ns":1788567713554696000,"stream":"btcusdt@bookTicker","event_type":"bookTicker","event_time_ms":1788567713558,"raw_json":"{\"stream\":\"btcusdt@bookTicker\",\"data\":{\"e\":\"bookTicker\",\"u\":11478507247500,\"s\":\"BTCUSDT\",\"ps\":\"BTCUSDT\",\"b\":\"79597.00\",\"B\":\"5.055\",\"a\":\"79597.10\",\"A\":\"7.680\",\"T\":1788567713558,\"E\":1788567713558,\"st\":1}}"}
{"receive_ns":1788567713597597000,"stream":"btcusdt@bookTicker","event_type":"bookTicker","event_time_ms":1788567713613,"raw_json":"{\"stream\":\"btcusdt@bookTicker\",\"data\":{\"e\":\"bookTicker\",\"u\":11478507250420,\"s\":\"BTCUSDT\",\"ps\":\"BTCUSDT\",\"b\":\"79597.00\",\"B\":\"5.055\",\"a\":\"79597.10\",\"A\":\"7.706\",\"T\":1788567713613,\"E\":1788567713613,\"st\":1}}"}
{"receive_ns":1788567713608591000,"stream":"btcusdt@bookTicker","event_type":"bookTicker","event_time_ms":1788567713614,"raw_json":"{\"stream\":\"btcusdt@bookTicker\",\"data\":{\"e\":\"bookTicker\",\"u\":11478507250527,\"s\":\"BTCUSDT\",\"ps\":\"BTCUSDT\",\"b\":\"79597.00\",\"B\":\"5.056\",\"a\":\"79597.10\",\"A\":\"7.706\",\"T\":1788567713614,\"E\":1788567713614,\"st\":1}}"}
{"receive_ns":1788567713619581000,"stream":"btcusdt@bookTicker","event_type":"bookTicker","event_time_ms":1788567713618,"raw_json":"{\"stream\":\"btcusdt@bookTicker\",\"data\":{\"e\":\"bookTicker\",\"u\":11478507250725,\"s\":\"BTCUSDT\",\"ps\":\"BTCUSDT\",\"b\":\"79597.00\",\"B\":\"5.082\",\"a\":\"79597.10\",\"A\":\"7.706\",\"T\":1788567713618,\"E\":1788567713618,\"st\":1}}"}
{"receive_ns":1788567713623315000,"stream":"btcusdt@bookTicker","event_type":"bookTicker","event_time_ms":1788567713619,"raw_json":"{\"stream\":\"btcusdt@bookTicker\",\"data\":{\"e\":\"bookTicker\",\"u\":11478507250759,\"s\":\"BTCUSDT\",\"ps\":\"BTCUSDT\",\"b\":\"79597.00\",\"B\":\"5.082\",\"a\":\"79597.10\",\"A\":\"7.680\",\"T\":1788567713619,\"E\":1788567713619,\"st\":1}}"}
