{"receive_ns":1788567713630198000,"stream":"btcusdt@depth@100ms","event_type":"depthUpdate","event_time_ms":1788567713637,"raw_json":"{\"stream\":\"btcusdt@depth@100ms\",\"data\":{\"e\":\"depthUpdate\",\"E\":1788567713637,\"T\":1788567713633,\"s\":\"BTCUSDT\",\"ps\":\"BTCUSDT\",\"U\":11478507246336,\"u\":11478507251470,\"pu\":11478507246155,\"b\":[[\"1000.00\",\"24.604\"],[\"29397.00\",\"0.553\"],[\"29497.00\",\"1.547\"],[\"63678.00\",\"0.000\"],[\"71637.30\",\"0.002\"],[\"78005.10\",\"10.825\"],[\"78699.80\",\"0.310\"],[\"78801.00\",\"12.547\"],[\"79000.00\",\"44.122\"],[\"79475.30\",\"0.001\"],[\"79507.80\",\"0.006\"],[\"79539.50\",\"1.355\"],[\"79584.70\",\"1.257\"],[\"79588.00\",\"0.018\"],[\"79588.20\",\"0.008\"],[\"79588.30\",\"0.000\"],[\"79588.40\",\"0.062\"],[\"79588.50\",\"0.081\"],[\"79588.60\",\"0.008\"],[\"79596.50\",\"0.005\"],[\"79597.00\",\"5.082\"]],\"a\":[[\"79597.10\",\"7.680\"],[\"79597.30\",\"0.100\"],[\"79597.70\",\"0.147\"],[\"79598.60\",\"0.027\"],[\"79599.70\",\"0.000\"],[\"79599.80\",\"0.001\"],[\"79644.40\",\"0.866\"],[\"79645.10\",\"0.899\"],[\"79719.70\",\"0.007\"],[\"80313.70\",\"1.743\"],[\"80393.10\",\"9.677\"],[\"80617.60\",\"11.586\"],[\"81043.20\",\"5.559\"]],\"st\":1}}"}
{"receive_ns":1788567714224436000,"stream":"btcusdt@depth@100ms","event_type":"depthUpdate","event_time_ms":1788567713739,"raw_json":"{\"stream\":\"btcusdt@depth@100ms\",\"data\":{\"e\":\"depthUpdate\",\"E\":1788567713739,\"T\":1788567713738,\"s\":\"BTCUSDT\",\"ps\":\"BTCUSDT\",\"U\":11478507251711,\"u\":11478507256841,\"pu\":11478507251470,\"b\":[[\"29397.00\",\"0.735\"],[\"29497.00\",\"1.365\"],[\"71637.30\",\"0.002\"],[\"71673.00\",\"0.000\"],[\"76413.10\",\"0.002\"],[\"77368.30\",\"2.322\"],[\"78567.00\",\"1.191\"],[\"78581.90\",\"0.732\"],[\"78586.60\",\"0.074\"],[\"78603.90\",\"0.000\"],[\"78606.20\",\"0.005\"],[\"78619.10\",\"0.000\"],[\"78801.00\",\"12.549\"],[\"79199.00\",\"4.235\"],[\"79460.70\",\"0.004\"],[\"79584.70\",\"0.001\"],[\"79584.80\",\"0.004\"],[\"79588.00\",\"0.398\"],[\"79588.10\",\"0.001\"],[\"79588.20\",\"1.264\"],[\"79588.40\",\"0.000\"],[\"79588.60\",\"0.000\"]],\"a\":[[\"80393.10\",\"9.677\"],[\"80707.00\",\"0.379\"],[\"80715.40\",\"0.000\"],[\"80717.90\",\"0.374\"],[\"80726.70\",\"0.001\"]],\"st\":1}}"}
{"receive_ns":1788567714232361000,"stream":"btcusdt@bookTicker","event_type":"bookTicker","event_time_ms":1788567713761,"raw_json":"{\"stream\":\"btcusdt@bookTicker\",\"data\":{\"e\":\"bookTicker\",\"u\":11478507257899,\"s\":\"BTCUSDT\",\"ps\":\"BTCUSDT\",\"b\":\"79597.00\",\"B\":\"5.094\",\"a\":\"79597.10\",\"A\":\"7.680\",\"T\":1788567713761,\"E\":1788567713761,\"st\":1}}"}
{"receive_ns":1788567714244180000,"stream":"btcusdt@bookTicker","event_type":"bookTicker","event_time_ms":1788567713798,"raw_json":"{\"stream\":\"btcusdt@bookTicker\",\"data\":{\"e\":\"bookTicker\",\"u\":11478507259562,\"s\":\"BTCUSDT\",\"ps\":\"BTCUSDT\",\"b\":\"79597.00\",\"B\":\"5.068\",\"a\":\"79597.10\",\"A\":\"7.680\",\"T\":1788567713797,\"E\":1788567713798,\"st\":1}}"}
{"receive_ns":1788567714255143000,"stream":"btcusdt@depth@100ms","event_type":"depthUpdate","event_time_ms":1788567713841,"raw_json":"{\"stream\":\"btcusdt@depth@100ms\",\"data\":{\"e\":\"depthUpdate\",\"E\":1788567713841,\"T\":1788567713838,\"s\":\"BTCUSDT\",\"ps\":\"BTCUSDT\",\"U\":11478507256856,\"u\":11478507261560,\"pu\":11478507256841,\"b\":[[\"29397.00\",\"0.910\"],[\"29497.00\",\"1.190\"],[\"71637.30\",\"0.002\"],[\"76413.10\",\"0.000\"],[\"78005.10\",\"10.828\"],[\"78468.70\",\"8.946\"],[\"78522.40\",\"10.402\"],[\"78801.00\",\"12.547\"],[\"79199.00\",\"4.245\"],[\"79388.20\",\"2.878\"],[\"79435.90\",\"1.963\"],[\"79475.30\",\"0.370\"],[\"79501.40\",\"0.046\"],[\"79506.70\",\"0.001\"],[\"79506.80\",\"1.190\"],[\"79525.30\",\"0.635\"],[\"79541.20\",\"0.000\"],[\"79573.30\",\"0.000\"],[\"79583.60\",\"1.052\"],[\"79584.70\",\"1.257\"],[\"79584.80\",\"0.402\"],[\"79587.00\",\"0.717\"],[\"79588.00\",\"0.004\"],[\"79588.20\",\"0.008\"],[\"79588.30\",\"0.000\"],[\"79588.40\",\"0.000\"],[\"79596.30\",\"0.000\"],[\"79596.80\",\"0.623\"],[\"79597.00\",\"5.068\"]],\"a\":[[\"79597.20\",\"0.083\"],[\"79597.40\",\"0.000\"],[\"79613.20\",\"0.003\"],[\"79644.90\",\"0.035\"],[\"79645.00\",\"0.002\"],[\"79645.10\",\"0.899\"],[\"79668.80\",\"0.034\"],[\"79688.00\",\"0.003\"],[\"79692.70\",\"0.001\"],[\"79719.70\",\"0.385\"],[\"79759.10\",\"13.228\"],[\"79804.90\",\"0.746\"],[\"79806.90\",\"2.729\"],[\"79995.10\",\"4.367\"],[\"80393.10\",\"9.677\"]],\"st\":1}}"}
{"receive_ns":1788567714255617000,"stream":"btcusdt@depth@100ms","event_type":"depthUpdate","event_time_ms":1788567713943,"raw_json":"{\"stream\":\"btcusdt@depth@100ms\",\"data\":{\"e\":\"depthUpdate\",\"E\":1788567713943,\"T\":1788567713941,\"s\":\"BTCUSDT\",\"ps\":\"BTCUSDT\",\"U\":11478507261643,\"u\":11478507267150,\"pu\":11478507261560,\"b\":[[\"1000.00\",\"24.604\"],[\"29397.00\",\"1.092\"],[\"29497.00\",\"1.008\"],[\"63678.00\",\"0.000\"],[\"71637.30\",\"0.002\"],[\"76413.10\",\"0.002\"],[\"78801.00\",\"12.547\"],[\"79531.30\",\"0.011\"],[\"79536.70\",\"20.384\"],[\"79573.30\",\"0.002\"]],\"a\":[[\"79613.20\",\"0.005\"],[\"79645.10\",\"0.774\"],[\"80393.10\",\"9.677\"],[\"80483.20\",\"1.256\"],[\"80713.10\",\"0.444\"]],\"st\":1}}"}
{"receive_ns":1788567714273854000,"stream":"btcusdt@bookTicker","event_type":"bookTicker","event_time_ms":1788567714042,"raw_json":"{\"stream\":\"btcusdt@bookTicker\",\"data\":{\"e\":\"bookTicker\",\"u\":11478507273245,\"s\":\"BTCUSDT\",\"ps\":\"BTCUSDT\",\"b\":\"79597.00\",\"B\":\"5.020\",\"a\":\"79597.10\",\"A\":\"7.680\",\"T\":1788567714042,\"E\":1788567714042,\"st\":1}}"}
{"receive_ns":1788567714285251000,"stream":"btcusdt@depth@100ms","event_type":"depthUpdate","event_time_ms":1788567714045,"raw_json":"{\"stream\":\"btcusdt@depth@100ms\",\"data\":{\"e\":\"depthUpdate\",\"E\":1788567714045,\"T\":1788567714044,\"s\":\"BTCUSDT\",\"ps\":\"BTCUSDT\",\"U\":11478507267333,\"u\":11478507273386,\"pu\":11478507267150,\"b\":[[\"29397.00\",\"1.267\"],[\"29497.00\",\"0.833\"],[\"63677.60\",\"0.000\"],[\"63678.00\",\"0.000\"],[\"71637.30\",\"0.002\"],[\"76413.10\",\"0.000\"],[\"78482.60\",\"30.979\"],[\"78801.00\",\"12.547\"],[\"79404.30\",\"0.000\"],[\"79405.90\",\"0.196\"],[\"79406.90\",\"0.934\"],[\"79421.90\",\"26.638\"],[\"79453.10\",\"0.011\"],[\"79453.20\",\"17.620\"],[\"79454.60\",\"5.161\"],[\"79495.10\",\"0.024\"],[\"79506.70\",\"4.251\"],[\"79582.70\",\"0.198\"],[\"79596.90\",\"2.485\"],[\"79597.00\",\"5.020\"]],\"a\":[[\"79597.70\",\"0.145\"],[\"79688.00\",\"3.261\"],[\"79740.40\",\"3.574\"],[\"79741.50\",\"17.957\"],[\"79741.60\",\"0.119\"],[\"79772.70\",\"4.573\"],[\"79772.80\",\"26.326\"],[\"79772.90\",\"0.003\"],[\"79776.00\",\"1.586\"],[\"79779.00\",\"0.000\"],[\"79806.90\",\"4.949\"],[\"79818.80\",\"7.124\"],[\"79994.10\",\"0.517\"],[\"79995.10\",\"2.496\"],[\"80393.10\",\"9.677\"],[\"80671.70\",\"10.600\"],[\"80966.20\",\"1.727\"]],\"st\":1}}"}
{"receive_ns":1788567714291329000,"stream":"btcusdt@bookTicker","event_type":"bookTicker","event_time_ms":1788567714045,"raw_json":"{\"stream\":\"btcusdt@bookTicker\",\"data\":{\"e\":\"bookTicker\",\"u\":11478507273391,\"s\":\"BTCUSDT\",\"ps\":\"BTCUSDT\",\"b\":\"79597.00\",\"B\":\"5.068\",\"a\":\"79597.10\",\"A\":\"7.680\",\"T\":1788567714044,\"E\":1788567714045,\"st\":1}}"}
{"receive_ns":1788567714292448000,"stream":"btcusdt@bookTicker","event_type":"bookTicker","event_time_ms":1788567714113,"raw_json":"{\"stream\":\"btcusdt@bookTicker\",\"data\":{\"e\":\"bookTicker\",\"u\":11478507277614,\"s\":\"BTCUSDT\",\"ps\":\"BTCUSDT\",\"b\":\"79597.00\",\"B\":\"5.018\",\"a\":\"79597.10\",\"A\":\"7.680\",\"T\":1788567714113,\"E\":1788567714113,\"st\":1}}"}
{"receive_ns":1788567714297827000,"stream":"btcusdt@bookTicker","event_type":"bookTicker","event_time_ms":1788567714115,"raw_json":"{\"stream\":\"btcusdt@bookTicker\",\"data\":{\"e\":\"bookTicker\",\"u\":11478507277665,\"s\":\"BTCUSDT\",\"ps\":\"BTCUSDT\",\"b\":\"79597.00\",\"B\":\"5.018\",\"a\":\"79597.10\",\"A\":\"7.682\",\"T\":1788567714114,\"E\":1788567714115,\"st\":1}}"}
{"receive_ns":1788567714314691000,"stream":"btcusdt@bookTicker","event_type":"bookTicker","event_time_ms":1788567714116,"raw_json":"{\"stream\":\"btcusdt@bookTicker\",\"data\":{\"e\":\"bookTicker\",\"u\":11478507277782,\"s\":\"BTCUSDT\",\"ps\":\"BTCUSDT\",\"b\":\"79597.00\",\"B\":\"5.058\",\"a\":\"79597.10\",\"A\":\"7.682\",\"T\":1788567714116,\"E\":1788567714116,\"st\":1}}"}
{"receive_ns":1788567714334777000,"stream":"btcusdt@depth@100ms","event_type":"depthUpdate","event_time_ms":1788567714147,"raw_json":"{\"stream\":\"btcusdt@depth@100ms\",\"data\":{\"e\":\"depthUpdate\",\"E\":1788567714147,\"T\":1788567714146,\"s\":\"BTCUSDT\",\"ps\":\"BTCUSDT\",\"U\":11478507273391,\"u\":11478507278988,\"pu\":11478507273386,\"b\":[[\"29397.00\",\"1.449\"],[\"29497.00\",\"0.651\"],[\"63678.00\",\"0.000\"],[\"71637.30\",\"0.002\"],[\"78801.00\",\"12.547\"],[\"78869.40\",\"0.190\"],[\"78880.60\",\"8.036\"],[\"79199.00\",\"4.245\"],[\"79553.50\",\"0.859\"],[\"79582.70\",\"0.194\"],[\"79597.00\",\"5.058\"]],\"a\":[[\"79597.10\",\"7.682\"],[\"79664.00\",\"0.024\"],[\"79691.60\",\"0.001\"],[\"80393.10\",\"9.677\"],[\"80638.50\",\"0.619\"],[\"80645.20\",\"7.428\"],[\"80804.40\",\"7.416\"]],\"st\":1}}"}
{"receive_ns":1788567714341209000,"stream":"btcusdt@depth@100ms","event_type":"depthUpdate","event_time_ms":1788567714249,"raw_json":"{\"stream\":\"btcusdt@depth@100ms\",\"data\":{\"e\":\"depthUpdate\",\"E\":1788567714249,\"T\":1788567714245,\"s\":\"BTCUSDT\",\"ps\":\"BTCUSDT\",\"U\":11478507279064,\"u\":11478507283853,\"pu\":11478507278988,\"b\":[[\"1000.00\",\"24.604\"],[\"29397.00\",\"1.624\"],[\"29497.00\",\"0.476\"],[\"71637.30\",\"0.002\"],[\"76413.10\",\"0.002\"],[\"77209.10\",\"0.017\"],[\"78426.10\",\"1.850\"],[\"78799.30\",\"2.279\"],[\"78801.00\",\"11.913\"],[\"79553.50\",\"0.860\"],[\"79573.50\",\"0.440\"],[\"79575.70\",\"0.002\"],[\"79596.20\",\"0.000\"],[\"79596.80\",\"0.623\"],[\"79596.90\",\"2.511\"]],\"a\":[[\"79597.20\",\"0.083\"],[\"79620.20\",\"0.003\"],[\"79621.10\",\"0.582\"],[\"79627.80\",\"0.009\"],[\"79645.00\",\"0.127\"],[\"79664.00\",\"0.025\"],[\"79994.10\",\"0.732\"],[\"79995.10\",\"4.367\"],[\"80393.10\",\"9.677\"]],\"st\":1}}"}
{"receive_ns":1788567714347054000,"stream":"btcusdt@bookTicker","event_type":"bookTicker","event_time_ms":1788567714255,"raw_json":"{\"stream\":\"btcusdt@bookTicker\",\"data\":{\"e\":\"bookTicker\",\"u\":11478507284471,\"s\":\"BTCUSDT\",\"ps\":\"BTCUSDT\",\"b\":\"79597.00\",\"B\":\"5.004\",\"a\":\"79597.10\",\"A\":\"7.682\",\"T\":1788567714255,\"E\":1788567714255,\"st\":1}}"}
{"receive_ns":1788567714356095000,"stream":"btcusdt@bookTicker","event_type":"bookTicker","event_time_ms":1788567714258,"raw_json":"{\"stream\":\"btcusdt@bookTicker\",\"data\":{\"e\":\"bookTicker\",\"u\":11478507284671,\"s\":\"BTCUSDT\",\"ps\":\"BTCUSDT\",\"b\":\"79597.00\",\"B\":\"5.062\",\"a\":\"79597.10\",\"A\":\"7.682\",\"T\":1788567714258,\"E\":1788567714258,\"st\":1}}"}
{"receive_ns":1788567714361604000,"stream":"btcusdt@depth@100ms","event_type":"depthUpdate","event_time_ms":1788567714351,"raw_json":"{\"stream\":\"btcusdt@depth@100ms\",\"data\":{\"e\":\"depthUpdate\",\"E\":1788567714351,\"T\":1788567714349,\"s\":\"BTCUSDT\",\"ps\":\"BTCUSDT\",\"U\":11478507284087,\"u\":11478507290726,\"pu\":11478507283853,\"b\":[[\"29297.00\",\"0.021\"],[\"29397.00\",\"1.764\"],[\"29497.00\",\"0.315\"],[\"71637.30\",\"0.002\"],[\"76413.10\",\"0.000\"],[\"78801.00\",\"11.913\"],[\"79596.30\",\"0.076\"],[\"79597.00\",\"5.062\"]],\"a\":[[\"79645.00\",\"0.127\"],[\"79995.10\",\"4.366\"],[\"80393.10\",\"9.677\"],[\"80558.80\",\"2.109\"],[\"80559.20\",\"0.620\"]],\"st\":1}}"}
{"receive_ns":1788567714382938000,"stream":"btcusdt@bookTicker","event_type":"bookTicker","event_time_ms":1788567714366,"raw_json":"{\"stream\":\"btcusdt@bookTicker\",\"data\":{\"e\":\"bookTicker\",\"u\":11478507291792,\"s\":\"BTCUSDT\",\"ps\":\"BTCUSDT\",\"b\":\"79597.00\",\"B\":\"5.103\",\"a\":\"79597.10\",\"A\":\"7.682\",\"T\":1788567714366,\"E\":1788567714366,\"st\":1}}"}
{"receive_ns":1788567714387754000,"stream":"btcusdt@bookTicker","event_type":"bookTicker","event_time_ms":1788567714368,"raw_json":"{\"stream\":\"btcusdt@bookTicker\",\"data\":{\"e\":\"bookTicker\",\"u\":11478507291925,\"s\":\"BTCUSDT\",\"ps\":\"BTCUSDT\",\"b\":\"79597.00\",\"B\":\"5.102\",\"a\":\"79597.10\",\"A\":\"7.682\",\"T\":1788567714367,\"E\":1788567714368,\"st\":1}}"}
{"receive_ns":1788567714388093000,"stream":"btcusdt@bookTicker","event_type":"bookTicker","event_time_ms":1788567714368,"raw_json":"{\"stream\":\"btcusdt@bookTicker\",\"data\":{\"e\":\"bookTicker\",\"u\":11478507291931,\"s\":\"BTCUSDT\",\"ps\":\"BTCUSDT\",\"b\":\"79597.00\",\"B\":\"5.102\",\"a\":\"79597.10\",\"A\":\"7.680\",\"T\":1788567714367,\"E\":1788567714368,\"st\":1}}"}
{"receive_ns":1788567714431260000,"stream":"btcusdt@depth@100ms","event_type":"depthUpdate","event_time_ms":1788567714453,"raw_json":"{\"stream\":\"btcusdt@depth@100ms\",\"data\":{\"e\":\"depthUpdate\",\"E\":1788567714453,\"T\":1788567714451,\"s\":\"BTCUSDT\",\"ps\":\"BTCUSDT\",\"U\":11478507290872,\"u\":11478507296777,\"pu\":11478507290726,\"b\":[[\"29297.00\",\"0.077\"],[\"29397.00\",\"1.827\"],[\"29497.00\",\"0.196\"],[\"71637.30\",\"0.002\"],[\"75617.10\",\"0.025\"],[\"76413.10\",\"0.002\"],[\"78545.50\",\"0.191\"],[\"78701.30\",\"0.635\"],[\"78801.00\",\"11.913\"],[\"78840.80\",\"9.966\"],[\"79199.00\",\"4.246\"],[\"79475.30\",\"0.001\"],[\"79566.70\",\"0.046\"],[\"79567.70\",\"0.167\"],[\"79579.70\",\"0.045\"],[\"79596.90\",\"2.529\"],[\"79597.00\",\"5.102\"]],\"a\":[[\"79597.10\",\"7.680\"],[\"79597.70\",\"0.171\"],[\"79628.70\",\"0.047\"],[\"79643.90\",\"0.125\"],[\"79645.00\",\"0.002\"],[\"79719.70\",\"0.007\"],[\"80393.10\",\"9.677\"],[\"80813.60\",\"1.730\"]],\"st\":1}}"}
{"receive_ns":1788567714443960000,"stream":"btcusdt@bookTicker","event_type":"bookTicker","event_time_ms":1788567714457,"raw_json":"{\"stream\":\"btcusdt@bookTicker\",\"data\":{\"e\":\"bookTicker\",\"u\":11478507297032,\"s\":\"BTCUSDT\",\"ps\":\"BTCUSDT\",\"b\":\"79597.00\",\"B\":\"5.102\",\"a\":\"79597.10\",\"A\":\"7.682\",\"T\":1788567714457,\"E\":1788567714457,\"st\":1}}"}
{"receive_ns":1788567714450546000,"stream":"btcusdt@bookTicker","event_type":"bookTicker","event_time_ms":1788567714459,"raw_json":"{\"stream\":\"btcusdt@bookTicker\",\"data\":{\"e\":\"bookTicker\",\"u\":11478507297099,\"s\":\"BTCUSDT\",\"ps\":\"BTCUSDT\",\"b\":\"79597.00\",\"B\":\"5.102\",\"a\":\"79597.10\",\"A\":\"7.684\",\"T\":1788567714458,\"E\":1788567714459,\"st\":1}}"}
{"receive_ns":1788567714462696000,"stream":"btcusdt@bookTicker","event_type":"bookTicker","event_time_ms":1788567714476,"raw_json":"{\"stream\":\"btcusdt@bookTicker\",\"data\":{\"e\":\"bookTicker\",\"u\":11478507297909,\"s\":\"BTCUSDT\",\"ps\":\"BTCUSDT\",\"b\":\"79597.00\",\"B\":\"5.102\",\"a\":\"79597.10\",\"A\":\"7.683\",\"T\":1788567714476,\"E\":1788567714476,\"st\":1}}"}
{"receive_ns":1788567714468635000,"stream":"btcusdt@trade","event_type":"trade","event_time_ms":1788567714476,"raw_json":"{\"stream\":\"btcusdt@trade\",\"data\":{\"e\":\"trade\",\"E\":1788567714476,\"T\":1788567714476,\"s\":\"BTCUSDT\",\"t\":8054122564,\"p\":\"79597.10\",\"q\":\"0.001\",\"X\":\"MARKET\",\"m\":false,\"st\":1}}"}
{"receive_ns":1788567714474239000,"stream":"btcusdt@bookTicker","event_type":"bookTicker","event_time_ms":1788567714483,"raw_json":"{\"stream\":\"btcusdt@bookTicker\",\"data\":{\"e\":\"bookTicker\",\"u\":11478507298551,\"s\":\"BTCUSDT\",\"ps\":\"BTCUSDT\",\"b\":\"79597.00\",\"B\":\"4.970\",\"a\":\"79597.10\",\"A\":\"7.683\",\"T\":1788567714483,\"E\":1788567714483,\"st\":1}}"}
{"receive_ns":1788567714482653000,"stream":"btcusdt@bookTicker","event_type":"bookTicker","event_time_ms":1788567714486,"raw_json":"{\"stream\":\"btcusdt@bookTicker\",\"data\":{\"e\":\"bookTicker\",\"u\":11478507298763,\"s\":\"BTCUSDT\",\"ps\":\"BTCUSDT\",\"b\":\"79597.00\",\"B\":\"5.098\",\"a\":\"79597.10\",\"A\":\"7.683\",\"T\":1788567714486,\"E\":1788567714486,\"st\":1}}"}
{"receive_ns":1788567714482927000,"stream":"btcusdt@bookTicker","event_type":"bookTicker","event_time_ms":1788567714487,"raw_json":"{\"stream\":\"btcusdt@bookTicker\",\"data\":{\"e\":\"bookTicker\",\"u\":11478507298863,\"s\":\"BTCUSDT\",\"ps\":\"BTCUSDT\",\"b\":\"79597.00\",\"B\":\"5.099\",\"a\":\"79597.10\",\"A\":\"7.683\",\"T\":1788567714487,\"E\":1788567714487,\"st\":1}}"}
{"receive_ns":1788567714537980000,"stream":"btcusdt@depth@100ms","event_type":"depthUpdate","event_time_ms":1788567714555,"raw_json":"{\"stream\":\"btcusdt@depth@100ms\",\"data\":{\"e\":\"depthUpdate\",\"E\":1788567714555,\"T\":1788567714554,\"s\":\"BTCUSDT\",\"ps\":\"BTCUSDT\",\"U\":11478507296862,\"u\":11478507302077,\"pu\":11478507296777,\"b\":[[\"1000.00\",\"24.604\"],[\"29297.00\",\"0.140\"],[\"29397.00\",\"1.883\"],[\"29497.00\",\"0.077\"],[\"63678.00\",\"0.010\"],[\"71637.30\",\"0.002\"],[\"75617.10\",\"0.023\"],[\"75617.20\",\"0.008\"],[\"78602.00\",\"15.594\"],[\"78801.00\",\"11.913\"],[\"79475.40\",\"0.466\"],[\"79517.40\",\"0.739\"],[\"79541.20\",\"0.002\"],[\"79566.80\",\"0.125\"],[\"79596.90\",\"2.503\"],[\"79597.00\",\"5.099\"]],\"a\":[[\"79597.10\",\"7.683\"],[\"79597.60\",\"0.102\"],[\"79692.70\",\"0.003\"],[\"79719.70\",\"0.483\"],[\"79796.10\",\"1.875\"],[\"80233.90\",\"6.594\"],[\"80393.10\",\"10.298\"],[\"80504.60\",\"0.124\"],[\"80727.40\",\"2.080\"],[\"81189.00\",\"10.515\"]],\"st\":1}}"}
{"receive_ns":1788567714640507000,"stream":"btcusdt@depth@100ms","event_type":"depthUpdate","event_time_ms":1788567714657,"raw_json":"{\"stream\":\"btcusdt@depth@100ms\",\"data\":{\"e\":\"depthUpdate\",\"E\":1788567714657,\"T\":1788567714653,\"s\":\"BTCUSDT\",\"ps\":\"BTCUSDT\",\"U\":11478507302202,\"u\":11478507308212,\"pu\":11478507302077,\"b\":[[\"29297.00\",\"0.238\"],[\"29397.00\",\"1.862\"],[\"29497.00\",\"0.000\"],[\"63678.00\",\"0.000\"],[\"71637.30\",\"0.002\"],[\"76413.10\",\"0.000\"],[\"78562.20\",\"11.792\"],[\"78801.00\",\"11.913\"],[\"79199.00\",\"4.246\"],[\"79569.20\",\"0.455\"],[\"79570.90\",\"0.002\"],[\"79576.00\",\"0.396\"],[\"79577.10\",\"0.060\"],[\"79594.30\",\"0.058\"],[\"79596.00\",\"0.108\"],[\"79596.20\",\"0.026\"],[\"79596.30\",\"0.000\"],[\"79596.60\",\"0.000\"],[\"79596.80\",\"0.597\"],[\"79596.90\",\"2.503\"]],\"a\":[[\"79597.20\",\"0.109\"],[\"79597.60\",\"0.076\"],[\"79610.40\",\"0.562\"],[\"79611.90\",\"0.001\"],[\"79615.90\",\"0.372\"],[\"79618.10\",\"1.552\"],[\"79619.00\",\"0.905\"],[\"79621.10\",\"0.130\"],[\"80393.10\",\"10.298\"],[\"80776.70\",\"3.467\"],[\"80830.90\",\"7.785\"]],\"st\":1}}"}
{"receive_ns":1788567714663891000,"stream":"btcusdt@bookTicker","event_type":"bookTicker","event_time_ms":1788567714679,"raw_json":"{\"stream\":\"btcusdt@bookTicker\",\"data\":{\"e\":\"bookTicker\",\"u\":11478507309743,\"s\":\"BTCUSDT\",\"ps\":\"BTCUSDT\",\"b\":\"79597.00\",\"B\":\"5.125\",\"a\":\"79597.10\",\"A\":\"7.683\",\"T\":1788567714679,\"E\":1788567714679,\"st\":1}}"}
{"receive_ns":1788567714694662000,"stream":"btcusdt@bookTicker","event_type":"bookTicker","event_time_ms":1788567714715,"raw_json":"{\"stream\":\"btcusdt@bookTicker\",\"data\":{\"e\":\"bookTicker\",\"u\":11478507311276,\"s\":\"BTCUSDT\",\"ps\":\"BTCUSDT\",\"b\":\"79597.00\",\"B\":\"5.099\",\"a\":\"79597.10\",\"A\":\"7.683\",\"T\":1788567714715,\"E\":1788567714715,\"st\":1}}"}
{"receive_ns":1788567714694891000,"stream":"btcusdt@bookTicker","event_type":"bookTicker","event_time_ms":1788567714715,"raw_json":"{\"stream\":\"btcusdt@bookTicker\",\"data\":{\"e\":\"bookTicker\",\"u\":11478507311277,\"s\":\"BTCUSDT\",\"ps\":\"BTCUSDT\",\"b\":\"79597.00\",\"B\":\"5.099\",\"a\":\"79597.10\",\"A\":\"7.709\",\"T\":1788567714715,\"E\":1788567714715,\"st\":1}}"}
{"receive_ns":1788567714700710000,"stream":"btcusdt@bookTicker","event_type":"bookTicker","event_time_ms":1788567714720,"raw_json":"{\"stream\":\"btcusdt@bookTicker\",\"data\":{\"e\":\"bookTicker\",\"u\":11478507311573,\"s\":\"BTCUSDT\",\"ps\":\"BTCUSDT\",\"b\":\"79597.00\",\"B\":\"5.104\",\"a\":\"79597.10\",\"A\":\"7.709\",\"T\":1788567714720,\"E\":1788567714720,\"st\":1}}"}
{"receive_ns":1788567714701109000,"stream":"btcusdt@bookTicker","event_type":"bookTicker","event_time_ms":1788567714721,"raw_json":"{\"stream\":\"btcusdt@bookTicker\",\"data\":{\"e\":\"bookTicker\",\"u\":11478507311682,\"s\":\"BTCUSDT\",\"ps\":\"BTCUSDT\",\"b\":\"79597.00\",\"B\":\"5.104\",\"a\":\"79597.10\",\"A\":\"7.707\",\"T\":1788567714721,\"E\":1788567714721,\"st\":1}}"}
{"receive_ns":1788567714708010000,"stream":"btcusdt@bookTicker","event_type":"bookTicker","event_time_ms":1788567714726,"raw_json":"{\"stream\":\"btcusdt@bookTicker\",\"data\":{\"e\":\"bookTicker\",\"u\":11478507311862,\"s\":\"BTCUSDT\",\"ps\":\"BTCUSDT\",\"b\":\"79597.00\",\"B\":\"5.099\",\"a\":\"79597.10\",\"A\":\"7.707\",\"T\":1788567714726,\"E\":1788567714726,\"st\":1}}"}
{"receive_ns":1788567714709021000,"stream":"btcusdt@bookTicker","event_type":"bookTicker","event_time_ms":1788567714731,"raw_json":"{\"stream\":\"btcusdt@bookTicker\",\"data\":{\"e\":\"bookTicker\",\"u\":11478507312079,\"s\":\"BTCUSDT\",\"ps\":\"BTCUSDT\",\"b\":\"79597.00\",\"B\":\"5.099\",\"a\":\"79597.10\",\"A\":\"7.711\",\"T\":1788567714731,\"E\":1788567714731,\"st\":1}}"}
{"receive_ns":1788567714725582000,"stream":"btcusdt@bookTicker","event_type":"bookTicker","event_time_ms":1788567714732,"raw_json":"{\"stream\":\"btcusdt@bookTicker\",\"data\":{\"e\":\"bookTicker\",\"u\":11478507312148,\"s\":\"BTCUSDT\",\"ps\":\"BTCUSDT\",\"b\":\"79597.00\",\"B\":\"5.099\",\"a\":\"79597.10\",\"A\":\"7.713\",\"T\":1788567714732,\"E\":1788567714732,\"st\":1}}"}
{"receive_ns":1788567714737247000,"stream":"btcusdt@bookTicker","event_type":"bookTicker","event_time_ms":1788567714751,"raw_json":"{\"stream\":\"btcusdt@bookTicker\",\"data\":{\"e\":\"bookTicker\",\"u\":11478507312852,\"s\":\"BTCUSDT\",\"ps\":\"BTCUSDT\",\"b\":\"79597.00\",\"B\":\"5.046\",\"a\":\"79597.10\",\"A\":\"7.713\",\"T\":1788567714751,\"E\":1788567714751,\"st\":1}}"}
{"receive_ns":1788567714748565000,"stream":"btcusdt@bookTicker","event_type":"bookTicker","event_time_ms":1788567714754,"raw_json":"{\"stream\":\"btcusdt@bookTicker\",\"data\":{\"e\":\"bookTicker\",\"u\":11478507312989,\"s\":\"BTCUSDT\",\"ps\":\"BTCUSDT\",\"b\":\"79597.00\",\"B\":\"5.100\",\"a\":\"79597.10\",\"A\":\"7.713\",\"T\":1788567714754,\"E\":1788567714754,\"st\":1}}"}
{"receive_ns":1788567714760501000,"stream":"btcusdt@depth@100ms","event_type":"depthUpdate","event_time_ms":1788567714759,"raw_json":"{\"stream\":\"btcusdt@depth@100ms\",\"data\":{\"e\":\"depthUpdate\",\"E\":1788567714759,\"T\":1788567714757,\"s\":\"BTCUSDT\",\"ps\":\"BTCUSDT\",\"U\":11478507308541,\"u\":11478507313113,\"pu\":11478507308212,\"b\":[[\"1000.00\",\"24.604\"],[\"29297.00\",\"0.420\"],[\"29397.00\",\"1.680\"],[\"71637.30\",\"0.002\"],[\"71673.00\",\"0.003\"],[\"76413.10\",\"0.002\"],[\"78005.10\",\"10.831\"],[\"78801.00\",\"11.913\"],[\"78960.20\",\"7.243\"],[\"79451.70\",\"1.896\"],[\"79559.20\",\"0.574\"],[\"79559.40\",\"0.039\"],[\"79569.20\",\"0.003\"],[\"79570.80\",\"0.476\"],[\"79593.80\",\"0.026\"],[\"79594.00\",\"0.102\"],[\"79594.10\",\"0.188\"],[\"79594.20\",\"0.026\"],[\"79594.30\",\"0.084\"],[\"79595.10\",\"0.002\"],[\"79595.20\",\"0.002\"],[\"79595.30\",\"0.001\"],[\"79595.50\",\"0.000\"],[\"79595.70\",\"0.001\"],[\"79596.00\",\"0.082\"],[\"79596.20\",\"0.000\"],[\"79596.60\",\"0.000\"],[\"79597.00\",\"5.100\"]],\"a\":[[\"79597.10\",\"7.713\"],[\"79597.20\",\"0.083\"],[\"79597.70\",\"0.145\"],[\"79597.90\",\"0.019\"],[\"79598.70\",\"0.030\"],[\"79610.40\",\"0.123\"],[\"79611.90\",\"0.440\"],[\"79615.90\",\"0.000\"],[\"79617.10\",\"0.372\"],[\"79619.00\",\"0.453\"],[\"79620.20\",\"0.455\"],[\"79627.80\",\"0.003\"],[\"79663.30\",\"0.049\"],[\"79664.10\",\"0.003\"],[\"79720.10\",\"2.476\"],[\"80393.10\",\"10.298\"],[\"80512.50\",\"0.496\"],[\"80638.80\",\"0.619\"],[\"81419.90\",\"0.000\"]],\"st\":1}}"}
{"receive_ns":1788567714844046000,"stream":"btcusdt@depth@100ms","event_type":"depthUpdate","event_time_ms":1788567714861,"raw_json":"{\"stream\":\"btcusdt@depth@100ms\",\"data\":{\"e\":\"depthUpdate\",\"E\":1788567714861,\"T\":1788567714858,\"s\":\"BTCUSDT\",\"ps\":\"BTCUSDT\",\"U\":11478507313242,\"u\":11478507317605,\"pu\":11478507313113,\"b\":[[\"1000.00\",\"24.604\"],[\"29297.00\",\"0.595\"],[\"29397.00\",\"1.505\"],[\"71637.30\",\"0.002\"],[\"71673.00\",\"0.000\"],[\"76413.10\",\"0.000\"],[\"78468.70\",\"8.564\"],[\"78588.10\",\"7.767\"],[\"78801.00\",\"11.913\"],[\"78880.60\",\"8.226\"],[\"79573.30\",\"0.000\"],[\"79594.90\",\"0.026\"],[\"79595.10\",\"0.028\"]],\"a\":[[\"79613.20\",\"0.003\"],[\"79643.90\",\"0.000\"],[\"79995.10\",\"4.365\"],[\"80233.90\",\"7.340\"],[\"80307.70\",\"0.000\"],[\"80393.10\",\"10.298\"]],\"st\":1}}"}
{"receive_ns":1788567714947238000,"stream":"btcusdt@depth@100ms","event_type":"depthUpdate","event_time_ms":1788567714963,"raw_json":"{\"stream\":\"btcusdt@depth@100ms\",\"data\":{\"e\":\"depthUpdate\",\"E\":1788567714963,\"T\":1788567714962,\"s\":\"BTCUSDT\",\"ps\":\"BTCUSDT\",\"U\":11478507317943,\"u\":11478507323095,\"pu\":11478507317605,\"b\":[[\"29297.00\",\"0.777\"],[\"29397.00\",\"1.323\"],[\"71637.30\",\"0.002\"],[\"75617.10\",\"0.028\"],[\"76413.10\",\"0.002\"],[\"78005.10\",\"10.828\"],[\"78449.30\",\"5.343\"],[\"78801.00\",\"11.913\"],[\"78960.20\",\"7.749\"],[\"79199.00\",\"4.237\"],[\"79565.80\",\"0.125\"],[\"79566.80\",\"0.000\"],[\"79573.30\",\"0.002\"],[\"79573.50\",\"0.001\"],[\"79575.70\",\"0.441\"],[\"79576.00\",\"0.023\"],[\"79576.80\",\"0.375\"],[\"79578.00\",\"0.701\"],[\"79594.90\",\"0.000\"],[\"79595.10\",\"0.002\"]],\"a\":[[\"79597.20\",\"0.084\"],[\"79597.80\",\"0.344\"],[\"79613.20\",\"0.005\"],[\"79617.10\",\"0.000\"],[\"79617.90\",\"0.630\"],[\"79620.20\",\"0.003\"],[\"79621.10\",\"0.582\"],[\"79643.30\",\"0.228\"],[\"79643.40\",\"3.026\"],[\"80311.00\",\"2.553\"],[\"80393.10\",\"10.298\"],[\"80631.90\",\"8.041\"]],\"st\":1}}"}
{"receive_ns":1788567715019336000,"stream":"btcusdt@bookTicker","event_type":"bookTicker","event_time_ms":1788567715040,"raw_json":"{\"stream\":\"btcusdt@bookTicker\",\"data\":{\"e\":\"bookTicker\",\"u\":11478507327712,\"s\":\"BTCUSDT\",\"ps\":\"BTCUSDT\",\"b\":\"79597.00\",\"B\":\"5.052\",\"a\":\"79597.10\",\"A\":\"7.713\",\"T\":1788567715040,\"E\":1788567715040,\"st\":1}}"}
{"receive_ns":1788567715028506000,"stream":"btcusdt@bookTicker","event_type":"bookTicker","event_time_ms":1788567715042,"raw_json":"{\"stream\":\"btcusdt@bookTicker\",\"data\":{\"e\":\"bookTicker\",\"u\":11478507327900,\"s\":\"BTCUSDT\",\"ps\":\"BTCUSDT\",\"b\":\"79597.00\",\"B\":\"5.100\",\"a\":\"79597.10\",\"A\":\"7.713\",\"T\":1788567715042,\"E\":1788567715042,\"st\":1}}"}
{"receive_ns":1788567715047214000,"stream":"btcusdt@depth@100ms","event_type":"depthUpdate","event_time_ms":1788567715065,"raw_json":"{\"stream\":\"btcusdt@depth@100ms\",\"data\":{\"e\":\"depthUpdate\",\"E\":1788567715065,\"T\":1788567715062,\"s\":\"BTCUSDT\",\"ps\":\"BTCUSDT\",\"U\":11478507323191,\"u\":11478507328805,\"pu\":11478507323095,\"b\":[[\"1000.00\",\"24.604\"],[\"29297.00\",\"0.952\"],[\"29397.00\",\"1.148\"],[\"63677.60\",\"0.000\"],[\"71637.30\",\"0.002\"],[\"78389.20\",\"4.157\"],[\"78801.00\",\"11.913\"],[\"79525.30\",\"0.633\"],[\"79541.20\",\"0.000\"],[\"79573.50\",\"0.440\"],[\"79575.70\",\"0.002\"],[\"79582.70\",\"0.194\"],[\"79597.00\",\"5.100\"]],\"a\":[[\"79610.50\",\"2.328\"],[\"79611.90\",\"0.001\"],[\"79643.70\",\"2.748\"],[\"79643.90\",\"0.125\"],[\"79668.80\",\"0.032\"],[\"79692.70\",\"0.001\"],[\"79700.00\",\"1.494\"],[\"80393.10\",\"10.298\"]],\"st\":1}}"}
{"receive_ns":1788567715142414000,"stream":"btcusdt@depth@100ms","event_type":"depthUpdate","event_time_ms":1788567715167,"raw_json":"{\"stream\":\"btcusdt@depth@100ms\",\"data\":{\"e\":\"depthUpdate\",\"E\":1788567715167,\"T\":1788567715166,\"s\":\"BTCUSDT\",\"ps\":\"BTCUSDT\",\"U\":11478507328915,\"u\":11478507334869,\"pu\":11478507328805,\"b\":[[\"1000.00\",\"24.604\"],[\"29297.00\",\"1.134\"],[\"29397.00\",\"0.966\"],[\"71637.30\",\"0.002\"],[\"76413.10\",\"0.000\"],[\"78490.60\",\"8.238\"],[\"78548.90\",\"7.632\"],[\"78661.90\",\"0.000\"],[\"78708.10\",\"6.346\"],[\"78801.00\",\"11.913\"],[\"79361.80\",\"0.723\"],[\"79541.20\",\"0.002\"]],\"a\":[[\"79643.90\",\"0.000\"],[\"79644.00\",\"0.006\"],[\"79644.20\",\"0.128\"],[\"79668.80\",\"0.034\"],[\"80353.30\",\"10.088\"],[\"80393.10\",\"10.298\"],[\"80592.10\",\"10.871\"]],\"st\":1}}"}
{"receive_ns":1788567715197018000,"stream":"btcusdt@bookTicker","event_type":"bookTicker","event_time_ms":1788567715214,"raw_json":"{\"stream\":\"btcusdt@bookTicker\",\"data\":{\"e\":\"bookTicker\",\"u\":11478507336944,\"s\":\"BTCUSDT\",\"ps\":\"BTCUSDT\",\"b\":\"79597.00\",\"B\":\"4.317\",\"a\":\"79597.10\",\"A\":\"7.713\",\"T\":1788567715214,\"E\":1788567715214,\"st\":1}}"}
{"receive_ns":1788567715208720000,"stream":"btcusdt@bookTicker","event_type":"bookTicker","event_time_ms":1788567715224,"raw_json":"{\"stream\":\"btcusdt@bookTicker\",\"data\":{\"e\":\"bookTicker\",\"u\":11478507337423,\"s\":\"BTCUSDT\",\"ps\":\"BTCUSDT\",\"b\":\"79597.00\",\"B\":\"5.101\",\"a\":\"79597.10\",\"A\":\"7.713\",\"T\":1788567715224,\"E\":1788567715224,\"st\":1}}"}
{"receive_ns":1788567715214156000,"stream":"btcusdt@bookTicker","event_type":"bookTicker","event_time_ms":1788567715225,"raw_json":"{\"stream\":\"btcusdt@bookTicker\",\"data\":{\"e\":\"bookTicker\",\"u\":11478507337460,\"s\":\"BTCUSDT\",\"ps\":\"BTCUSDT\",\"b\":\"79597.00\",\"B\":\"5.100\",\"a\":\"79597.10\",\"A\":\"7.713\",\"T\":1788567715225,\"E\":1788567715225,\"st\":1}}"}
{"receive_ns":1788567715225043000,"stream":"btcusdt@bookTicker","event_type":"bookTicker","event_time_ms":1788567715227,"raw_json":"{\"stream\":\"btcusdt@bookTicker\",\"data\":{\"e\":\"bookTicker\",\"u\":11478507337541,\"s\":\"BTCUSDT\",\"ps\":\"BTCUSDT\",\"b\":\"79597.00\",\"B\":\"5.100\",\"a\":\"79597.10\",\"A\":\"7.637\",\"T\":1788567715227,\"E\":1788567715227,\"st\":1}}"}
{"receive_ns":1788567715230522000,"stream":"btcusdt@bookTicker","event_type":"bookTicker","event_time_ms":1788567715228,"raw_json":"{\"stream\":\"btcusdt@bookTicker\",\"data\":{\"e\":\"bookTicker\",\"u\":11478507337567,\"s\":\"BTCUSDT\",\"ps\":\"BTCUSDT\",\"b\":\"79597.00\",\"B\":\"5.100\",\"a\":\"79597.10\",\"A\":\"7.561\",\"T\":1788567715227,\"E\":1788567715228,\"st\":1}}"}
{"receive_ns":1788567715246442000,"stream":"btcusdt@bookTicker","event_type":"bookTicker","event_time_ms":1788567715267,"raw_json":"{\"stream\":\"btcusdt@bookTicker\",\"data\":{\"e\":\"bookTicker\",\"u\":11478507338844,\"s\":\"BTCUSDT\",\"ps\":\"BTCUSDT\",\"b\":\"79597.00\",\"B\":\"5.046\",\"a\":\"79597.10\",\"A\":\"7.561\",\"T\":1788567715267,\"E\":1788567715267,\"st\":1}}"}
{"receive_ns":1788567715263914000,"stream":"btcusdt@depth@100ms","event_type":"depthUpdate","event_time_ms":1788567715269,"raw_json":"{\"stream\":\"btcusdt@depth@100ms\",\"data\":{\"e\":\"depthUpdate\",\"E\":1788567715269,\"T\":1788567715267,\"s\":\"BTCUSDT\",\"ps\":\"BTCUSDT\",\"U\":11478507334928,\"u\":11478507338844,\"pu\":11478507334869,\"b\":[[\"29297.00\",\"1.309\"],[\"29397.00\",\"0.791\"],[\"63678.00\",\"0.000\"],[\"71637.30\",\"0.002\"],[\"76413.10\",\"0.002\"],[\"78548.90\",\"8.268\"],[\"78562.10\",\"2.670\"],[\"78801.00\",\"11.913\"],[\"79199.00\",\"4.237\"],[\"79475.50\",\"0.000\"],[\"79475.80\",\"0.039\"],[\"79526.80\",\"0.000\"],[\"79541.00\",\"0.316\"],[\"79542.80\",\"1.561\"],[\"79556.90\",\"1.009\"],[\"79584.70\",\"0.001\"],[\"79584.80\",\"0.004\"],[\"79584.90\",\"1.256\"],[\"79588.00\",\"0.402\"],[\"79588.90\",\"0.000\"],[\"79590.50\",\"0.078\"],[\"79590.70\",\"0.001\"],[\"79591.90\",\"0.560\"],[\"79595.00\",\"0.028\"],[\"79597.00\",\"5.046\"]],\"a\":[[\"79597.10\",\"7.561\"],[\"79610.60\",\"0.003\"],[\"79626.60\",\"0.005\"],[\"79644.40\",\"0.866\"],[\"79644.60\",\"0.018\"],[\"80313.50\",\"0.754\"],[\"80393.10\",\"10.298\"]],\"st\":1}}"}
{"receive_ns":1788567715265229000,"stream":"btcusdt@bookTicker","event_type":"bookTicker","event_time_ms":1788567715269,"raw_json":"{\"stream\":\"btcusdt@bookTicker\",\"data\":{\"e\":\"bookTicker\",\"u\":11478507338882,\"s\":\"BTCUSDT\",\"ps\":\"BTCUSDT\",\"b\":\"79597.00\",\"B\":\"5.046\",\"a\":\"79597.10\",\"A\":\"7.559\",\"T\":1788567715268,\"E\":1788567715269,\"st\":1}}"}
{"receive_ns":1788567715271008000,"stream":"btcusdt@bookTicker","event_type":"bookTicker","event_time_ms":1788567715270,"raw_json":"{\"stream\":\"btcusdt@bookTicker\",\"data\":{\"e\":\"bookTicker\",\"u\":11478507338983,\"s\":\"BTCUSDT\",\"ps\":\"BTCUSDT\",\"b\":\"79597.00\",\"B\":\"5.099\",\"a\":\"79597.10\",\"A\":\"7.559\",\"T\":1788567715270,\"E\":1788567715270,\"st\":1}}"}
{"receive_ns":1788567715287342000,"stream":"btcusdt@bookTicker","event_type":"bookTicker","event_time_ms":1788567715271,"raw_json":"{\"stream\":\"btcusdt@bookTicker\",\"data\":{\"e\":\"bookTicker\",\"u\":11478507338999,\"s\":\"BTCUSDT\",\"ps\":\"BTCUSDT\",\"b\":\"79597.00\",\"B\":\"5.099\",\"a\":\"79597.10\",\"A\":\"7.636\",\"T\":1788567715270,\"E\":1788567715271,\"st\":1}}"}
{"receive_ns":1788567715292992000,"stream":"btcusdt@bookTicker","event_type":"bookTicker","event_time_ms":1788567715271,"raw_json":"{\"stream\":\"btcusdt@bookTicker\",\"data\":{\"e\":\"bookTicker\",\"u\":11478507339006,\"s\":\"BTCUSDT\",\"ps\":\"BTCUSDT\",\"b\":\"79597.00\",\"B\":\"5.099\",\"a\":\"79597.10\",\"A\":\"7.713\",\"T\":1788567715270,\"E\":1788567715271,\"st\":1}}"}
{"receive_ns":1788567715298520000,"stream":"btcusdt@bookTicker","event_type":"bookTicker","event_time_ms":1788567715271,"raw_json":"{\"stream\":\"btcusdt@bookTicker\",\"data\":{\"e\":\"bookTicker\",\"u\":11478507339034,\"s\":\"BTCUSDT\",\"ps\":\"BTCUSDT\",\"b\":\"79597.00\",\"B\":\"5.100\",\"a\":\"79597.10\",\"A\":\"7.713\",\"T\":1788567715271,\"E\":1788567715271,\"st\":1}}"}
{"receive_ns":1788567715303932000,"stream":"btcusdt@bookTicker","event_type":"bookTicker","event_time_ms":1788567715272,"raw_json":"{\"stream\":\"btcusdt@bookTicker\",\"data\":{\"e\":\"bookTicker\",\"u\":11478507339061,\"s\":\"BTCUSDT\",\"ps\":\"BTCUSDT\",\"b\":\"79597.00\",\"B\":\"5.100\",\"a\":\"79597.10\",\"A\":\"7.714\",\"T\":1788567715271,\"E\":1788567715272,\"st\":1}}"}
{"receive_ns":1788567715304378000,"stream":"btcusdt@bookTicker","event_type":"bookTicker","event_time_ms":1788567715272,"raw_json":"{\"stream\":\"btcusdt@bookTicker\",\"data\":{\"e\":\"bookTicker\",\"u\":11478507339066,\"s\":\"BTCUSDT\",\"ps\":\"BTCUSDT\",\"b\":\"79597.00\",\"B\":\"5.100\",\"a\":\"79597.10\",\"A\":\"7.637\",\"T\":1788567715271,\"E\":1788567715272,\"st\":1}}"}
{"receive_ns":1788567715315823000,"stream":"btcusdt@bookTicker","event_type":"bookTicker","event_time_ms":1788567715272,"raw_json":"{\"stream\":\"btcusdt@bookTicker\",\"data\":{\"e\":\"bookTicker\",\"u\":11478507339068,\"s\":\"BTCUSDT\",\"ps\":\"BTCUSDT\",\"b\":\"79597.00\",\"B\":\"5.100\",\"a\":\"79597.10\",\"A\":\"7.636\",\"T\":1788567715272,\"E\":1788567715272,\"st\":1}}"}
{"receive_ns":1788567715316054000,"stream":"btcusdt@bookTicker","event_type":"bookTicker","event_time_ms":1788567715272,"raw_json":"{\"stream\":\"btcusdt@bookTicker\",\"data\":{\"e\":\"bookTicker\",\"u\":11478507339073,\"s\":\"BTCUSDT\",\"ps\":\"BTCUSDT\",\"b\":\"79597.00\",\"B\":\"5.100\",\"a\":\"79597.10\",\"A\":\"7.559\",\"T\":1788567715272,\"E\":1788567715272,\"st\":1}}"}
{"receive_ns":1788567715316243000,"stream":"btcusdt@bookTicker","event_type":"bookTicker","event_time_ms":1788567715272,"raw_json":"{\"stream\":\"btcusdt@bookTicker\",\"data\":{\"e\":\"bookTicker\",\"u\":11478507339077,\"s\":\"BTCUSDT\",\"ps\":\"BTCUSDT\",\"b\":\"79597.00\",\"B\":\"5.100\",\"a\":\"79597.10\",\"A\":\"7.557\",\"T\":1788567715272,\"E\":1788567715272,\"st\":1}}"}
{"receive_ns":1788567715357015000,"stream":"btcusdt@depth@100ms","event_type":"depthUpdate","event_time_ms":1788567715371,"raw_json":"{\"stream\":\"btcusdt@depth@100ms\",\"data\":{\"e\":\"depthUpdate\",\"E\":1788567715371,\"T\":1788567715369,\"s\":\"BTCUSDT\",\"ps\":\"BTCUSDT\",\"U\":11478507338877,\"u\":11478507343167,\"pu\":11478507338844,\"b\":[[\"1000.00\",\"24.604\"],[\"29297.00\",\"1.491\"],[\"29397.00\",\"0.609\"],[\"63678.00\",\"0.000\"],[\"71637.30\",\"0.002\"],[\"76413.10\",\"0.000\"],[\"78005.10\",\"10.831\"],[\"78548.90\",\"8.904\"],[\"78801.00\",\"11.913\"],[\"79199.00\",\"4.236\"],[\"79595.80\",\"0.076\"],[\"79596.00\",\"0.108\"],[\"79596.90\",\"2.509\"],[\"79597.00\",\"5.100\"]],\"a\":[[\"79597.10\",\"7.557\"],[\"79597.30\",\"0.102\"],[\"79632.40\",\"1.332\"],[\"79644.40\",\"0.866\"],[\"79644.50\",\"0.000\"],[\"79644.70\",\"0.000\"],[\"80393.10\",\"10.298\"],[\"80458.40\",\"0.000\"],[\"81189.00\",\"10.512\"]],\"st\":1}}"}
{"receive_ns":1788567715456594000,"stream":"btcusdt@depth@100ms","event_type":"depthUpdate","event_time_ms":1788567715473,"raw_json":"{\"stream\":\"btcusdt@depth@100ms\",\"data\":{\"e\":\"depthUpdate\",\"E\":1788567715473,\"T\":1788567715469,\"s\":\"BTCUSDT\",\"ps\":\"BTCUSDT\",\"U\":11478507343257,\"u\":11478507347425,\"pu\":11478507343167,\"b\":[[\"1000.00\",\"24.604\"],[\"29297.00\",\"1.666\"],[\"29397.00\",\"0.434\"],[\"71637.30\",\"0.002\"],[\"76413.10\",\"0.002\"],[\"78710.10\",\"0.227\"],[\"78801.00\",\"11.913\"],[\"79423.80\",\"4.517\"],[\"79506.80\",\"1.675\"],[\"79539.50\",\"4.240\"]],\"a\":[[\"79645.60\",\"0.125\"],[\"79804.90\",\"1.040\"],[\"79818.70\",\"7.118\"],[\"79818.80\",\"0.001\"],[\"79995.10\",\"4.366\"],[\"80393.10\",\"10.298\"],[\"80631.90\",\"8.908\"],[\"80718.40\",\"0.631\"]],\"st\":1}}"}
{"receive_ns":1788567715463894000,"stream":"btcusdt@bookTicker","event_type":"bookTicker","event_time_ms":1788567715490,"raw_json":"{\"stream\":\"btcusdt@bookTicker\",\"data\":{\"e\":\"bookTicker\",\"u\":11478507348358,\"s\":\"BTCUSDT\",\"ps\":\"BTCUSDT\",\"b\":\"79597.00\",\"B\":\"4.972\",\"a\":\"79597.10\",\"A\":\"7.557\",\"T\":1788567715490,\"E\":1788567715490,\"st\":1}}"}
{"receive_ns":1788567715470967000,"stream":"btcusdt@bookTicker","event_type":"bookTicker","event_time_ms":1788567715493,"raw_json":"{\"stream\":\"btcusdt@bookTicker\",\"data\":{\"e\":\"bookTicker\",\"u\":11478507348520,\"s\":\"BTCUSDT\",\"ps\":\"BTCUSDT\",\"b\":\"79597.00\",\"B\":\"5.096\",\"a\":\"79597.10\",\"A\":\"7.557\",\"T\":1788567715493,\"E\":1788567715493,\"st\":1}}"}
{"receive_ns":1788567715477094000,"stream":"btcusdt@bookTicker","event_type":"bookTicker","event_time_ms":1788567715494,"raw_json":"{\"stream\":\"btcusdt@bookTicker\",\"data\":{\"e\":\"bookTicker\",\"u\":11478507348525,\"s\":\"BTCUSDT\",\"ps\":\"BTCUSDT\",\"b\":\"79597.00\",\"B\":\"5.096\",\"a\":\"79597.10\",\"A\":\"7.634\",\"T\":1788567715493,\"E\":1788567715494,\"st\":1}}"}
{"receive_ns":1788567715488749000,"stream":"btcusdt@bookTicker","event_type":"bookTicker","event_time_ms":1788567715494,"raw_json":"{\"stream\":\"btcusdt@bookTicker\",\"data\":{\"e\":\"bookTicker\",\"u\":11478507348531,\"s\":\"BTCUSDT\",\"ps\":\"BTCUSDT\",\"b\":\"79597.00\",\"B\":\"5.096\",\"a\":\"79597.10\",\"A\":\"7.711\",\"T\":1788567715493,\"E\":1788567715494,\"st\":1}}"}
{"receive_ns":1788567715504651000,"stream":"btcusdt@bookTicker","event_type":"bookTicker","event_time_ms":1788567715495,"raw_json":"{\"stream\":\"btcusdt@bookTicker\",\"data\":{\"e\":\"bookTicker\",\"u\":11478507348561,\"s\":\"BTCUSDT\",\"ps\":\"BTCUSDT\",\"b\":\"79597.00\",\"B\":\"5.096\",\"a\":\"79597.10\",\"A\":\"7.713\",\"T\":1788567715494,\"E\":1788567715495,\"st\":1}}"}
{"receive_ns":1788567715515589000,"stream":"btcusdt@bookTicker","event_type":"bookTicker","event_time_ms":1788567715503,"raw_json":"{\"stream\":\"btcusdt@bookTicker\",\"data\":{\"e\":\"bookTicker\",\"u\":11478507348981,\"s\":\"BTCUSDT\",\"ps\":\"BTCUSDT\",\"b\":\"79597.00\",\"B\":\"5.096\",\"a\":\"79597.10\",\"A\":\"7.718\",\"T\":1788567715502,\"E\":1788567715503,\"st\":1}}"}
{"receive_ns":1788567715557071000,"stream":"btcusdt@depth@100ms","event_type":"depthUpdate","event_time_ms":1788567715575,"raw_json":"{\"stream\":\"btcusdt@depth@100ms\",\"data\":{\"e\":\"depthUpdate\",\"E\":1788567715575,\"T\":1788567715573,\"s\":\"BTCUSDT\",\"ps\":\"BTCUSDT\",\"U\":11478507347586,\"u\":11478507351978,\"pu\":11478507347425,\"b\":[[\"29197.00\",\"0.035\"],[\"29297.00\",\"1.778\"],[\"29397.00\",\"0.287\"],[\"71637.30\",\"0.002\"],[\"75617.10\",\"0.030\"],[\"78104.50\",\"0.000\"],[\"78482.60\",\"31.233\"],[\"78801.00\",\"11.913\"],[\"79199.00\",\"4.246\"],[\"79570.10\",\"0.453\"],[\"79570.80\",\"0.024\"],[\"79593.20\",\"0.004\"],[\"79593.70\",\"0.000\"],[\"79597.00\",\"5.096\"]],\"a\":[[\"79597.10\",\"7.718\"],[\"80233.90\",\"7.091\"],[\"80393.10\",\"10.298\"],[\"80577.80\",\"3.693\"],[\"83576.90\",\"0.043\"]],\"st\":1}}"}
{"receive_ns":1788567715585616000,"stream":"btcusdt@bookTicker","event_type":"bookTicker","event_time_ms":1788567715600,"raw_json":"{\"stream\":\"btcusdt@bookTicker\",\"data\":{\"e\":\"bookTicker\",\"u\":11478507353128,\"s\":\"BTCUSDT\",\"ps\":\"BTCUSDT\",\"b\":\"79597.00\",\"B\":\"5.096\",\"a\":\"79597.10\",\"A\":\"7.717\",\"T\":1788567715600,\"E\":1788567715600,\"st\":1}}"}
{"receive_ns":1788567715593045000,"stream":"btcusdt@trade","event_type":"trade","event_time_ms":1788567715600,"raw_json":"{\"stream\":\"btcusdt@trade\",\"data\":{\"e\":\"trade\",\"E\":1788567715600,\"T\":1788567715600,\"s\":\"BTCUSDT\",\"t\":8054122565,\"p\":\"79597.10\",\"q\":\"0.001\",\"X\":\"MARKET\",\"m\":false,\"st\":1}}"}
{"receive_ns":1788567715659515000,"stream":"btcusdt@depth@100ms","event_type":"depthUpdate","event_time_ms":1788567715677,"raw_json":"{\"stream\":\"btcusdt@depth@100ms\",\"data\":{\"e\":\"depthUpdate\",\"E\":1788567715677,\"T\":1788567715676,\"s\":\"BTCUSDT\",\"ps\":\"BTCUSDT\",\"U\":11478507352084,\"u\":11478507356346,\"pu\":11478507351978,\"b\":[[\"1000.00\",\"24.604\"],[\"29197.00\",\"0.091\"],[\"29297.00\",\"1.841\"],[\"29397.00\",\"0.168\"],[\"63678.00\",\"0.000\"],[\"71637.30\",\"0.002\"],[\"76413.10\",\"0.000\"],[\"78801.00\",\"11.913\"],[\"78866.60\",\"1.087\"],[\"79594.70\",\"0.000\"],[\"79594.80\",\"0.000\"],[\"79595.00\",\"0.002\"],[\"79595.20\",\"0.078\"],[\"79595.80\",\"0.000\"],[\"79596.00\",\"0.082\"]],\"a\":[[\"79597.10\",\"7.717\"],[\"79829.30\",\"0.000\"],[\"79829.40\",\"0.003\"],[\"79941.80\",\"0.039\"],[\"79943.60\",\"0.000\"],[\"80393.10\",\"10.298\"],[\"80727.40\",\"2.228\"],[\"81189.00\",\"10.509\"]],\"st\":1}}"}
{"receive_ns":1788567715762786000,"stream":"btcusdt@depth@100ms","event_type":"depthUpdate","event_time_ms":1788567715779,"raw_json":"{\"stream\":\"btcusdt@depth@100ms\",\"data\":{\"e\":\"depthUpdate\",\"E\":1788567715779,\"T\":1788567715777,\"s\":\"BTCUSDT\",\"ps\":\"BTCUSDT\",\"U\":11478507356406,\"u\":11478507361723,\"pu\":11478507356346,\"b\":[[\"1000.00\",\"24.604\"],[\"29197.00\",\"0.154\"],[\"29297.00\",\"1.897\"],[\"29397.00\",\"0.049\"],[\"63678.00\",\"0.000\"],[\"71637.30\",\"0.002\"],[\"76413.10\",\"0.002\"],[\"78514.70\",\"1.100\"],[\"78801.00\",\"11.913\"],[\"78960.20\",\"7.496\"],[\"79536.70\",\"0.001\"],[\"79539.40\",\"20.409\"]],\"a\":[[\"80233.90\",\"7.091\"],[\"80393.10\",\"10.298\"]],\"st\":1}}"}
{"receive_ns":1788567715866617000,"stream":"btcusdt@depth@100ms","event_type":"depthUpdate","event_time_ms":1788567715881,"raw_json":"{\"stream\":\"btcusdt@depth@100ms\",\"data\":{\"e\":\"depthUpdate\",\"E\":1788567715881,\"T\":1788567715879,\"s\":\"BTCUSDT\",\"ps\":\"BTCUSDT\",\"U\":11478507361845,\"u\":11478507366582,\"pu\":11478507361723,\"b\":[[\"29197.00\",\"0.280\"],[\"29297.00\",\"1.820\"],[\"29397.00\",\"0.000\"],[\"71637.30\",\"0.002\"],[\"71673.00\",\"0.000\"],[\"76413.10\",\"0.000\"],[\"78442.80\",\"13.350\"],[\"78588.10\",\"7.551\"],[\"78801.00\",\"11.913\"],[\"79199.00\",\"4.246\"],[\"79531.30\",\"20.365\"],[\"79539.40\",\"0.022\"],[\"79539.50\",\"1.355\"],[\"79573.30\",\"0.000\"]],\"a\":[[\"79613.20\",\"0.003\"],[\"80393.10\",\"10.298\"],[\"80645.20\",\"8.047\"],[\"80718.40\",\"0.012\"]],\"st\":1}}"}
{"receive_ns":1788567715909931000,"stream":"btcusdt@bookTicker","event_type":"bookTicker","event_time_ms":1788567715926,"raw_json":"{\"stream\":\"btcusdt@bookTicker\",\"data\":{\"e\":\"bookTicker\",\"u\":11478507368682,\"s\":\"BTCUSDT\",\"ps\":\"BTCUSDT\",\"b\":\"79597.00\",\"B\":\"5.048\",\"a\":\"79597.10\",\"A\":\"7.717\",\"T\":1788567715926,\"E\":1788567715926,\"st\":1}}"}
{"receive_ns":1788567715921097000,"stream":"btcusdt@bookTicker","event_type":"bookTicker","event_time_ms":1788567715928,"raw_json":"{\"stream\":\"btcusdt@bookTicker\",\"data\":{\"e\":\"bookTicker\",\"u\":11478507368774,\"s\":\"BTCUSDT\",\"ps\":\"BTCUSDT\",\"b\":\"79597.00\",\"B\":\"5.096\",\"a\":\"79597.10\",\"A\":\"7.717\",\"T\":1788567715928,\"E\":1788567715928,\"st\":1}}"}
{"receive_ns":1788567715933393000,"stream":"btcusdt@bookTicker","event_type":"bookTicker","event_time_ms":1788567715929,"raw_json":"{\"stream\":\"btcusdt@bookTicker\",\"data\":{\"e\":\"bookTicker\",\"u\":11478507368798,\"s\":\"BTCUSDT\",\"ps\":\"BTCUSDT\",\"b\":\"79597.00\",\"B\":\"5.096\",\"a\":\"79597.10\",\"A\":\"7.715\",\"T\":1788567715929,\"E\":1788567715929,\"st\":1}}"}
{"receive_ns":1788567715964378000,"stream":"btcusdt@depth@100ms","event_type":"depthUpdate","event_time_ms":1788567715983,"raw_json":"{\"stream\":\"btcusdt@depth@100ms\",\"data\":{\"e\":\"depthUpdate\",\"E\":1788567715983,\"T\":1788567715982,\"s\":\"BTCUSDT\",\"ps\":\"BTCUSDT\",\"U\":11478507366647,\"u\":11478507371154,\"pu\":11478507366582,\"b\":[[\"1000.00\",\"24.604\"],[\"29197.00\",\"0.462\"],[\"29297.00\",\"1.638\"],[\"63678.00\",\"0.000\"],[\"71637.30\",\"0.002\"],[\"75617.20\",\"0.006\"],[\"78452.80\",\"0.306\"],[\"78465.90\",\"0.011\"],[\"78514.70\",\"0.591\"],[\"78801.00\",\"11.915\"],[\"79199.00\",\"4.245\"],[\"79405.90\",\"0.208\"],[\"79421.90\",\"0.197\"],[\"79423.80\",\"0.651\"],[\"79453.20\",\"0.000\"],[\"79454.60\",\"2.887\"],[\"79506.70\",\"0.001\"],[\"79506.80\",\"1.190\"],[\"79531.30\",\"0.011\"],[\"79536.70\",\"20.355\"],[\"79573.30\",\"0.002\"],[\"79593.70\",\"0.026\"],[\"79597.00\",\"5.096\"]],\"a\":[[\"79597.10\",\"7.715\"],[\"79613.20\",\"0.005\"],[\"79688.00\",\"0.003\"],[\"79740.40\",\"0.751\"],[\"79741.50\",\"0.400\"],[\"79772.70\",\"0.644\"],[\"79772.80\",\"0.001\"],[\"79804.90\",\"0.001\"],[\"79806.80\",\"1.857\"],[\"79806.90\",\"0.000\"],[\"80393.10\",\"10.298\"],[\"80565.60\",\"9.920\"],[\"80724.70\",\"3.396\"]],\"st\":1}}"}
{"receive_ns":1788567716053019000,"stream":"btcusdt@bookTicker","event_type":"bookTicker","event_time_ms":1788567716072,"raw_json":"{\"stream\":\"btcusdt@bookTicker\",\"data\":{\"e\":\"bookTicker\",\"u\":11478507375173,\"s\":\"BTCUSDT\",\"ps\":\"BTCUSDT\",\"b\":\"79597.00\",\"B\":\"5.098\",\"a\":\"79597.10\",\"A\":\"7.715\",\"T\":1788567716072,\"E\":1788567716072,\"st\":1}}"}
{"receive_ns":1788567716063946000,"stream":"btcusdt@bookTicker","event_type":"bookTicker","event_time_ms":1788567716082,"raw_json":"{\"stream\":\"btcusdt@bookTicker\",\"data\":{\"e\":\"bookTicker\",\"u\":11478507375951,\"s\":\"BTCUSDT\",\"ps\":\"BTCUSDT\",\"b\":\"79597.00\",\"B\":\"4.512\",\"a\":\"79597.10\",\"A\":\"7.715\",\"T\":1788567716082,\"E\":1788567716082,\"st\":1}}"}
{"receive_ns":1788567716076432000,"stream":"btcusdt@bookTicker","event_type":"bookTicker","event_time_ms":1788567716083,"raw_json":"{\"stream\":\"btcusdt@bookTicker\",\"data\":{\"e\":\"bookTicker\",\"u\":11478507376057,\"s\":\"BTCUSDT\",\"ps\":\"BTCUSDT\",\"b\":\"79597.00\",\"B\":\"4.512\",\"a\":\"79597.10\",\"A\":\"7.717\",\"T\":1788567716083,\"E\":1788567716083,\"st\":1}}"}
{"receive_ns":1788567716082632000,"stream":"btcusdt@bookTicker","event_type":"bookTicker","event_time_ms":1788567716083,"raw_json":"{\"stream\":\"btcusdt@bookTicker\",\"data\":{\"e\":\"bookTicker\",\"u\":11478507376094,\"s\":\"BTCUSDT\",\"ps\":\"BTCUSDT\",\"b\":\"79597.00\",\"B\":\"5.098\",\"a\":\"79597.10\",\"A\":\"7.717\",\"T\":1788567716083,\"E\":1788567716083,\"st\":1}}"}
{"receive_ns":1788567716091423000,"stream":"btcusdt@depth@100ms","event_type":"depthUpdate","event_time_ms":1788567716085,"raw_json":"{\"stream\":\"btcusdt@depth@100ms\",\"data\":{\"e\":\"depthUpdate\",\"E\":1788567716085,\"T\":1788567716084,\"s\":\"BTCUSDT\",\"ps\":\"BTCUSDT\",\"U\":11478507371190,\"u\":11478507376238,\"pu\":11478507371154,\"b\":[[\"1000.00\",\"24.604\"],[\"29197.00\",\"0.637\"],[\"29297.00\",\"1.463\"],[\"63677.60\",\"0.000\"],[\"71637.30\",\"0.002\"],[\"76413.10\",\"0.002\"],[\"78562.20\",\"13.699\"],[\"78567.00\",\"1.186\"],[\"78571.70\",\"0.006\"],[\"78586.60\",\"0.068\"],[\"78591.20\",\"0.005\"],[\"78606.20\",\"0.000\"],[\"78610.80\",\"0.004\"],[\"78801.00\",\"12.547\"],[\"79405.90\",\"0.196\"],[\"79421.90\",\"26.638\"],[\"79448.90\",\"0.032\"],[\"79453.20\",\"17.620\"],[\"79454.60\",\"5.161\"],[\"79475.80\",\"0.007\"],[\"79477.40\",\"0.006\"],[\"79506.70\",\"4.267\"],[\"79514.20\",\"0.004\"],[\"79531.30\",\"20.365\"],[\"79536.70\",\"0.001\"],[\"79550.70\",\"0.265\"],[\"79558.50\",\"0.101\"],[\"79559.20\",\"0.572\"],[\"79562.20\",\"0.253\"],[\"79564.20\",\"0.050\"],[\"79566.40\",\"0.001\"],[\"79566.50\",\"0.631\"],[\"79566.70\",\"0.000\"],[\"79567.10\",\"0.453\"],[\"79569.10\",\"0.000\"],[\"79570.10\",\"0.001\"],[\"79570.50\",\"0.630\"],[\"79571.50\",\"1.422\"],[\"79573.40\",\"0.001\"],[\"79573.50\",\"0.374\"],[\"79574.00\",\"0.009\"],[\"79574.50\",\"0.669\"],[\"79574.60\",\"0.058\"],[\"79574.70\",\"0.021\"],[\"79575.60\",\"0.877\"],[\"79576.80\",\"0.002\"],[\"79576.90\",\"0.341\"],[\"79577.00\",\"0.001\"],[\"79577.70\",\"0.000\"],[\"79578.10\",\"0.002\"],[\"79579.30\",\"0.003\"],[\"79582.10\",\"0.151\"],[\"79582.70\",\"0.194\"],[\"79583.20\",\"0.076\"],[\"79583.50\",\"0.251\"],[\"79584.30\",\"0.077\"],[\"79585.00\",\"0.101\"],[\"79585.90\",\"0.000\"],[\"79586.40\",\"0.001\"],[\"79587.00\",\"0.719\"],[\"79588.00\",\"0.336\"],[\"79589.40\",\"0.026\"],[\"79589.50\",\"0.066\"],[\"79589.60\",\"0.089\"],[\"79589.80\",\"0.026\"],[\"79589.90\",\"0.026\"],[\"79590.00\",\"0.120\"],[\"79590.10\",\"0.127\"],[\"79590.20\",\"0.027\"],[\"79590.30\",\"0.000\"],[\"79590.50\",\"0.080\"],[\"79590.80\",\"0.003\"],[\"79591.10\",\"0.004\"],[\"79591.20\",\"0.031\"],[\"79591.40\",\"0.003\"],[\"79591.50\",\"0.026\"],[\"79591.60\",\"0.000\"],[\"79591.70\",\"0.003\"],[\"79591.80\",\"0.000\"],[\"79591.90\",\"0.178\"],[\"79592.90\",\"0.002\"],[\"79593.20\",\"0.000\"],[\"79593.40\",\"0.161\"],[\"79593.70\",\"0.000\"],[\"79593.80\",\"0.000\"],[\"79594.00\",\"0.000\"],[\"79594.10\",\"0.002\"],[\"79594.20\",\"0.000\"],[\"79594.30\",\"0.058\"],[\"79594.40\",\"0.000\"],[\"79594.50\",\"0.000\"],[\"79594.60\",\"0.001\"],[\"79594.80\",\"0.000\"],[\"79595.10\",\"0.001\"],[\"79595.20\",\"0.000\"],[\"79595.70\",\"0.000\"],[\"79596.80\",\"0.599\"],[\"79597.00\",\"5.097\"]],\"a\":[[\"79597.10\",\"7.717\"],[\"79599.10\",\"0.081\"],[\"79601.10\",\"0.221\"],[\"79601.20\",\"0.002\"],[\"79601.30\",\"0.001\"],[\"79601.90\",\"0.012\"],[\"79603.20\",\"0.007\"],[\"79604.30\",\"0.014\"],[\"79604.60\",\"0.137\"],[\"79605.40\",\"0.084\"],[\"79605.60\",\"0.258\"],[\"79605.80\",\"0.342\"],[\"79606.80\",\"0.255\"],[\"79608.30\",\"0.454\"],[\"79609.10\",\"0.011\"],[\"79609.30\",\"0.157\"],[\"79609.90\",\"0.003\"],[\"79610.50\",\"1.889\"],[\"79613.20\",\"0.002\"],[\"79613.50\",\"0.372\"],[\"79614.30\",\"0.638\"],[\"79614.50\",\"0.065\"],[\"79615.10\",\"0.255\"],[\"79616.30\",\"0.642\"],[\"79616.60\",\"0.031\"],[\"79617.20\",\"0.002\"],[\"79617.60\",\"0.006\"],[\"79617.90\",\"0.258\"],[\"79618.30\",\"0.628\"],[\"79619.20\",\"0.453\"],[\"79619.30\",\"0.001\"],[\"79621.00\",\"0.047\"],[\"79621.10\",\"0.130\"],[\"79622.30\",\"0.718\"],[\"79623.30\",\"0.036\"],[\"79623.80\",\"0.008\"],[\"79625.30\",\"0.010\"],[\"79626.40\",\"1.651\"],[\"79627.30\",\"0.002\"],[\"79628.00\",\"1.542\"],[\"79632.00\",\"0.024\"],[\"79651.20\",\"0.003\"],[\"79653.30\",\"0.201\"],[\"79664.10\",\"0.001\"],[\"79688.00\",\"3.289\"],[\"79698.20\",\"0.004\"],[\"79740.40\",\"3.574\"],[\"79741.50\",\"17.957\"],[\"79772.80\",\"26.326\"],[\"79806.80\",\"5.123\"],[\"79818.70\",\"7.079\"],[\"79995.10\",\"4.367\"],[\"80017.80\",\"0.000\"],[\"80393.10\",\"10.300\"],[\"80552.30\",\"28.238\"],[\"80697.20\",\"8.602\"]],\"st\":1}}"}
{"receive_ns":1788567716097015000,"stream":"btcusdt@bookTicker","event_type":"bookTicker","event_time_ms":1788567716084,"raw_json":"{\"stream\":\"btcusdt@bookTicker\",\"data\":{\"e\":\"bookTicker\",\"u\":11478507376238,\"s\":\"BTCUSDT\",\"ps\":\"BTCUSDT\",\"b\":\"79597.00\",\"B\":\"5.097\",\"a\":\"79597.10\",\"A\":\"7.717\",\"T\":1788567716084,\"E\":1788567716084,\"st\":1}}"}
{"receive_ns":1788567716108902000,"stream":"btcusdt@bookTicker","event_type":"bookTicker","event_time_ms":1788567716112,"raw_json":"{\"stream\":\"btcusdt@bookTicker\",\"data\":{\"e\":\"bookTicker\",\"u\":11478507378249,\"s\":\"BTCUSDT\",\"ps\":\"BTCUSDT\",\"b\":\"79597.00\",\"B\":\"5.096\",\"a\":\"79597.10\",\"A\":\"7.717\",\"T\":1788567716111,\"E\":1788567716112,\"st\":1}}"}
{"receive_ns":1788567716173804000,"stream":"btcusdt@depth@100ms","event_type":"depthUpdate","event_time_ms":1788567716187,"raw_json":"{\"stream\":\"btcusdt@depth@100ms\",\"data\":{\"e\":\"depthUpdate\",\"E\":1788567716187,\"T\":1788567716185,\"s\":\"BTCUSDT\",\"ps\":\"BTCUSDT\",\"U\":11478507376242,\"u\":11478507382093,\"pu\":11478507376238,\"b\":[[\"29197.00\",\"0.819\"],[\"29297.00\",\"1.281\"],[\"63678.00\",\"0.000\"],[\"71637.30\",\"0.002\"],[\"76413.10\",\"0.000\"],[\"78708.10\",\"6.981\"],[\"78801.00\",\"12.547\"],[\"78960.20\",\"7.498\"],[\"79199.00\",\"4.235\"],[\"79514.20\",\"0.002\"],[\"79540.80\",\"0.002\"],[\"79556.80\",\"0.003\"],[\"79564.20\",\"0.004\"],[\"79565.80\",\"0.000\"],[\"79567.00\",\"0.300\"],[\"79567.80\",\"0.001\"],[\"79568.70\",\"0.126\"],[\"79571.50\",\"0.983\"],[\"79572.10\",\"0.440\"],[\"79573.30\",\"0.042\"],[\"79573.50\",\"0.001\"],[\"79573.60\",\"0.000\"],[\"79574.40\",\"0.038\"],[\"79574.50\",\"0.629\"],[\"79575.30\",\"0.510\"],[\"79576.10\",\"0.003\"],[\"79576.20\",\"0.291\"],[\"79579.60\",\"0.080\"],[\"79579.70\",\"0.000\"],[\"79580.40\",\"0.080\"],[\"79583.90\",\"1.658\"],[\"79584.50\",\"0.002\"],[\"79584.90\",\"0.000\"],[\"79585.00\",\"0.035\"],[\"79585.30\",\"0.000\"],[\"79585.50\",\"0.217\"],[\"79586.00\",\"0.003\"],[\"79586.90\",\"0.003\"],[\"79587.30\",\"0.033\"],[\"79587.80\",\"1.589\"],[\"79587.90\",\"0.632\"],[\"79588.00\",\"0.004\"],[\"79588.10\",\"0.102\"],[\"79588.20\",\"0.004\"],[\"79588.80\",\"0.253\"],[\"79589.00\",\"0.198\"],[\"79589.40\",\"0.000\"],[\"79589.50\",\"0.040\"],[\"79589.60\",\"0.063\"],[\"79589.80\",\"0.000\"],[\"79589.90\",\"0.000\"],[\"79590.00\",\"0.094\"],[\"79590.10\",\"0.000\"],[\"79590.20\",\"0.001\"],[\"79590.50\",\"0.076\"],[\"79590.60\",\"0.254\"],[\"79590.80\",\"0.001\"],[\"79591.20\",\"0.007\"],[\"79591.50\",\"0.002\"],[\"79591.70\",\"0.003\"],[\"79591.80\",\"0.000\"],[\"79591.90\",\"0.103\"],[\"79592.00\",\"0.031\"],[\"79592.20\",\"0.026\"],[\"79592.30\",\"0.026\"],[\"79592.40\",\"0.028\"],[\"79592.50\",\"0.151\"],[\"79592.60\",\"0.160\"],[\"79592.70\",\"0.028\"],[\"79592.90\",\"0.028\"],[\"79593.00\",\"0.131\"],[\"79593.10\",\"0.047\"],[\"79593.30\",\"0.026\"],[\"79593.40\",\"0.001\"],[\"79597.00\",\"5.096\"]],\"a\":[[\"79604.00\",\"0.223\"],[\"79605.10\",\"0.263\"],[\"79605.30\",\"0.003\"],[\"79605.40\",\"0.080\"],[\"79605.60\",\"0.007\"],[\"79606.30\",\"0.000\"],[\"79607.20\",\"0.255\"],[\"79607.90\",\"0.004\"],[\"79608.30\",\"0.015\"],[\"79610.40\",\"0.562\"],[\"79613.10\",\"0.192\"],[\"79613.50\",\"0.000\"],[\"79614.30\",\"0.010\"],[\"79614.50\",\"0.002\"],[\"79615.40\",\"0.632\"],[\"79615.90\",\"0.062\"],[\"79616.00\",\"0.381\"],[\"79616.30\",\"0.014\"],[\"79617.80\",\"0.000\"],[\"79618.00\",\"0.631\"],[\"79618.30\",\"0.001\"],[\"79619.50\",\"1.338\"],[\"79622.30\",\"0.091\"],[\"79622.40\",\"0.888\"],[\"79623.70\",\"0.627\"],[\"79623.80\",\"0.002\"],[\"79624.80\",\"0.158\"],[\"79625.30\",\"0.009\"],[\"79627.60\",\"1.884\"],[\"79628.00\",\"1.496\"],[\"79630.70\",\"0.049\"],[\"79658.40\",\"1.844\"],[\"79668.50\",\"5.656\"],[\"79668.80\",\"21.765\"],[\"79671.50\",\"0.001\"],[\"79698.20\",\"0.002\"],[\"80011.40\",\"0.094\"],[\"80311.00\",\"1.994\"],[\"80393.10\",\"10.298\"],[\"80466.70\",\"0.005\"],[\"80617.60\",\"10.719\"],[\"80724.70\",\"2.964\"],[\"80767.20\",\"9.388\"]],\"st\":1}}"}
{"receive_ns":1788567716213821000,"stream":"btcusdt@bookTicker","event_type":"bookTicker","event_time_ms":1788567716230,"raw_json":"{\"stream\":\"btcusdt@bookTicker\",\"data\":{\"e\":\"bookTicker\",\"u\":11478507384399,\"s\":\"BTCUSDT\",\"ps\":\"BTCUSDT\",\"b\":\"79597.00\",\"B\":\"4.312\",\"a\":\"79597.10\",\"A\":\"7.717\",\"T\":1788567716230,\"E\":1788567716230,\"st\":1}}"}
{"receive_ns":1788567716220529000,"stream":"btcusdt@bookTicker","event_type":"bookTicker","event_time_ms":1788567716231,"raw_json":"{\"stream\":\"btcusdt@bookTicker\",\"data\":{\"e\":\"bookTicker\",\"u\":11478507384444,\"s\":\"BTCUSDT\",\"ps\":\"BTCUSDT\",\"b\":\"79597.00\",\"B\":\"4.313\",\"a\":\"79597.10\",\"A\":\"7.717\",\"T\":1788567716231,\"E\":1788567716231,\"st\":1}}"}
{"receive_ns":1788567716220760000,"stream":"btcusdt@bookTicker","event_type":"bookTicker","event_time_ms":1788567716231,"raw_json":"{\"stream\":\"btcusdt@bookTicker\",\"data\":{\"e\":\"bookTicker\",\"u\":11478507384448,\"s\":\"BTCUSDT\",\"ps\":\"BTCUSDT\",\"b\":\"79597.00\",\"B\":\"4.312\",\"a\":\"79597.10\",\"A\":\"7.717\",\"T\":1788567716231,\"E\":1788567716231,\"st\":1}}"}
{"receive_ns":1788567716231484000,"stream":"btcusdt@bookTicker","event_type":"bookTicker","event_time_ms":1788567716232,"raw_json":"{\"stream\":\"btcusdt@bookTicker\",\"data\":{\"e\":\"bookTicker\",\"u\":11478507384505,\"s\":\"BTCUSDT\",\"ps\":\"BTCUSDT\",\"b\":\"79597.00\",\"B\":\"4.313\",\"a\":\"79597.10\",\"A\":\"7.717\",\"T\":1788567716232,\"E\":1788567716232,\"st\":1}}"}
{"receive_ns":1788567716238172000,"stream":"btcusdt@bookTicker","event_type":"bookTicker","event_time_ms":1788567716240,"raw_json":"{\"stream\":\"btcusdt@bookTicker\",\"data\":{\"e\":\"bookTicker\",\"u\":11478507384837,\"s\":\"BTCUSDT\",\"ps\":\"BTCUSDT\",\"b\":\"79597.00\",\"B\":\"5.109\",\"a\":\"79597.10\",\"A\":\"7.717\",\"T\":1788567716239,\"E\":1788567716240,\"st\":1}}"}
{"receive_ns":1788567716246067000,"stream":"btcusdt@bookTicker","event_type":"bookTicker","event_time_ms":1788567716241,"raw_json":"{\"stream\":\"btcusdt@bookTicker\",\"data\":{\"e\":\"bookTicker\",\"u\":11478507384892,\"s\":\"BTCUSDT\",\"ps\":\"BTCUSDT\",\"b\":\"79597.00\",\"B\":\"5.108\",\"a\":\"79597.10\",\"A\":\"7.717\",\"T\":1788567716241,\"E\":1788567716241,\"st\":1}}"}
{"receive_ns":1788567716258758000,"stream":"btcusdt@bookTicker","event_type":"bookTicker","event_time_ms":1788567716255,"raw_json":"{\"stream\":\"btcusdt@bookTicker\",\"data\":{\"e\":\"bookTicker\",\"u\":11478507385571,\"s\":\"BTCUSDT\",\"ps\":\"BTCUSDT\",\"b\":\"79597.00\",\"B\":\"5.050\",\"a\":\"79597.10\",\"A\":\"7.717\",\"T\":1788567716255,\"E\":1788567716255,\"st\":1}}"}
{"receive_ns":1788567716264407000,"stream":"btcusdt@bookTicker","event_type":"bookTicker","event_time_ms":1788567716258,"raw_json":"{\"stream\":\"btcusdt@bookTicker\",\"data\":{\"e\":\"bookTicker\",\"u\":11478507386082,\"s\":\"BTCUSDT\",\"ps\":\"BTCUSDT\",\"b\":\"79597.00\",\"B\":\"5.110\",\"a\":\"79597.10\",\"A\":\"7.717\",\"T\":1788567716258,\"E\":1788567716258,\"st\":1}}"}
{"receive_ns":1788567716277367000,"stream":"btcusdt@bookTicker","event_type":"bookTicker","event_time_ms":1788567716259,"raw_json":"{\"stream\":\"btcusdt@bookTicker\",\"data\":{\"e\":\"bookTicker\",\"u\":11478507386262,\"s\":\"BTCUSDT\",\"ps\":\"BTCUSDT\",\"b\":\"79597.00\",\"B\":\"5.111\",\"a\":\"79597.10\",\"A\":\"7.717\",\"T\":1788567716259,\"E\":1788567716259,\"st\":1}}"}
{"receive_ns":1788567716283635000,"stream":"btcusdt@depth@100ms","event_type":"depthUpdate","event_time_ms":1788567716289,"raw_json":"{\"stream\":\"btcusdt@depth@100ms\",\"data\":{\"e\":\"depthUpdate\",\"E\":1788567716289,\"T\":1788567716286,\"s\":\"BTCUSDT\",\"ps\":\"BTCUSDT\",\"U\":11478507382136,\"u\":11478507388142,\"pu\":11478507382093,\"b\":[[\"1000.00\",\"24.604\"],[\"29197.00\",\"0.994\"],[\"29297.00\",\"1.106\"],[\"71637.30\",\"0.002\"],[\"76413.10\",\"0.002\"],[\"78382.90\",\"0.000\"],[\"78801.00\",\"12.547\"],[\"78960.20\",\"7.496\"],[\"79460.70\",\"0.003\"],[\"79495.10\",\"0.031\"],[\"79526.80\",\"0.000\"],[\"79542.70\",\"0.000\"],[\"79567.10\",\"0.001\"],[\"79570.90\",\"0.454\"],[\"79572.10\",\"0.001\"],[\"79574.60\",\"0.497\"],[\"79575.30\",\"0.137\"],[\"79577.40\",\"0.373\"],[\"79578.90\",\"0.209\"],[\"79590.70\",\"0.002\"],[\"79591.90\",\"0.103\"],[\"79592.00\",\"0.005\"],[\"79592.10\",\"0.207\"],[\"79593.00\",\"0.055\"],[\"79593.10\",\"0.021\"],[\"79593.30\",\"0.000\"],[\"79593.90\",\"0.000\"],[\"79594.10\",\"0.002\"],[\"79597.00\",\"5.111\"]],\"a\":[[\"79604.60\",\"0.140\"],[\"79605.40\",\"0.080\"],[\"79607.80\",\"0.077\"],[\"79607.90\",\"0.004\"],[\"79610.40\",\"0.123\"],[\"79610.60\",\"0.003\"],[\"79611.90\",\"0.440\"],[\"79616.00\",\"0.009\"],[\"79616.30\",\"0.014\"],[\"79617.50\",\"0.372\"],[\"79617.80\",\"0.000\"],[\"79618.00\",\"0.004\"],[\"79619.20\",\"0.001\"],[\"79620.60\",\"0.454\"],[\"79622.70\",\"0.001\"],[\"79623.60\",\"0.627\"],[\"79624.80\",\"0.159\"],[\"79626.60\",\"0.005\"],[\"79627.20\",\"0.121\"],[\"79630.70\",\"0.003\"],[\"79631.90\",\"0.046\"],[\"79665.40\",\"4.866\"],[\"79666.10\",\"0.014\"],[\"79668.50\",\"2.666\"],[\"79668.80\",\"0.035\"],[\"79671.50\",\"21.731\"],[\"79806.80\",\"4.861\"],[\"80393.10\",\"10.298\"],[\"80711.50\",\"28.721\"]],\"st\":1}}"}
{"receive_ns":1788567716370279000,"stream":"btcusdt@depth@100ms","event_type":"depthUpdate","event_time_ms":1788567716391,"raw_json":"{\"stream\":\"btcusdt@depth@100ms\",\"data\":{\"e\":\"depthUpdate\",\"E\":1788567716391,\"T\":1788567716390,\"s\":\"BTCUSDT\",\"ps\":\"BTCUSDT\",\"U\":11478507388427,\"u\":11478507394495,\"pu\":11478507388142,\"b\":[[\"1000.00\",\"24.604\"],[\"29197.00\",\"1.176\"],[\"29297.00\",\"0.924\"],[\"63678.00\",\"0.000\"],[\"71637.30\",\"0.002\"],[\"75617.10\",\"0.035\"],[\"76413.10\",\"0.000\"],[\"78562.20\",\"13.953\"],[\"78801.00\",\"12.547\"],[\"78866.50\",\"1.776\"],[\"79541.20\",\"0.002\"],[\"79568.10\",\"2.687\"],[\"79568.70\",\"0.001\"],[\"79573.30\",\"0.481\"],[\"79574.60\",\"0.058\"],[\"79576.40\",\"0.376\"],[\"79577.40\",\"0.000\"],[\"79583.60\",\"1.460\"],[\"79587.00\",\"0.877\"],[\"79587.30\",\"0.034\"],[\"79591.20\",\"0.008\"],[\"79593.00\",\"0.131\"],[\"79593.70\",\"0.026\"]],\"a\":[[\"79610.40\",\"0.562\"],[\"79611.00\",\"0.954\"],[\"79611.90\",\"0.001\"],[\"79612.00\",\"0.003\"],[\"79616.30\",\"0.641\"],[\"79620.40\",\"0.912\"],[\"79623.60\",\"0.000\"],[\"79665.40\",\"1.810\"],[\"79668.80\",\"21.765\"],[\"79671.50\",\"0.001\"],[\"80353.30\",\"10.646\"],[\"80393.10\",\"10.298\"],[\"80552.30\",\"29.478\"],[\"80767.20\",\"9.820\"],[\"80791.10\",\"5.592\"]],\"st\":1}}"}
{"receive_ns":1788567716475957000,"stream":"btcusdt@depth@100ms","event_type":"depthUpdate","event_time_ms":1788567716493,"raw_json":"{\"stream\":\"btcusdt@depth@100ms\",\"data\":{\"e\":\"depthUpdate\",\"E\":1788567716493,\"T\":1788567716492,\"s\":\"BTCUSDT\",\"ps\":\"BTCUSDT\",\"U\":11478507394615,\"u\":11478507400124,\"pu\":11478507394495,\"b\":[[\"29197.00\",\"1.351\"],[\"29297.00\",\"0.749\"],[\"71637.30\",\"0.002\"],[\"78005.10\",\"10.834\"],[\"78641.80\",\"32.804\"],[\"78801.00\",\"12.547\"],[\"79199.00\",\"4.245\"],[\"79423.80\",\"4.517\"],[\"79448.90\",\"0.000\"],[\"79449.10\",\"0.032\"],[\"79506.80\",\"1.677\"],[\"79531.30\",\"0.011\"],[\"79534.00\",\"20.559\"],[\"79534.50\",\"4.545\"],[\"79566.20\",\"0.127\"],[\"79566.40\",\"0.001\"],[\"79566.80\",\"0.000\"],[\"79583.50\",\"0.000\"],[\"79584.90\",\"0.251\"],[\"79591.20\",\"0.006\"],[\"79592.00\",\"0.007\"],[\"79593.00\",\"0.055\"]],\"a\":[[\"79616.20\",\"0.001\"],[\"79616.30\",\"0.013\"],[\"79623.90\",\"0.637\"],[\"79805.20\",\"0.971\"],[\"79995.10\",\"4.366\"],[\"80233.90\",\"3.981\"],[\"80393.10\",\"10.300\"],[\"80486.00\",\"9.222\"],[\"80645.20\",\"8.666\"],[\"80661.00\",\"1.265\"],[\"80703.50\",\"5.120\"]],\"st\":1}}"}
{"receive_ns":1788567716561261000,"stream":"btcusdt@bookTicker","event_type":"bookTicker","event_time_ms":1788567716581,"raw_json":"{\"stream\":\"btcusdt@bookTicker\",\"data\":{\"e\":\"bookTicker\",\"u\":11478507404338,\"s\":\"BTCUSDT\",\"ps\":\"BTCUSDT\",\"b\":\"79597.00\",\"B\":\"5.110\",\"a\":\"79597.10\",\"A\":\"7.717\",\"T\":1788567716581,\"E\":1788567716581,\"st\":1}}"}
{"receive_ns":1788567716573587000,"stream":"btcusdt@depth@100ms","event_type":"depthUpdate","event_time_ms":1788567716595,"raw_json":"{\"stream\":\"btcusdt@depth@100ms\",\"data\":{\"e\":\"depthUpdate\",\"E\":1788567716595,\"T\":1788567716593,\"s\":\"BTCUSDT\",\"ps\":\"BTCUSDT\",\"U\":11478507400214,\"u\":11478507404941,\"pu\":11478507400124,\"b\":[[\"1000.00\",\"24.604\"],[\"29197.00\",\"1.533\"],[\"29297.00\",\"0.567\"],[\"63678.00\",\"0.002\"],[\"71637.30\",\"0.002\"],[\"75617.10\",\"0.033\"],[\"75617.20\",\"0.008\"],[\"76413.10\",\"0.002\"],[\"78482.60\",\"31.615\"],[\"78602.00\",\"15.879\"],[\"78641.80\",\"33.311\"],[\"78801.00\",\"12.547\"],[\"79199.00\",\"4.120\"],[\"79448.90\",\"0.032\"],[\"79449.10\",\"0.000\"],[\"79460.70\",\"0.002\"],[\"79525.30\",\"0.635\"],[\"79531.30\",\"20.317\"],[\"79534.00\",\"0.253\"],[\"79534.50\",\"2.356\"],[\"79574.70\",\"0.001\"],[\"79587.30\",\"0.054\"],[\"79596.80\",\"0.598\"],[\"79597.00\",\"5.110\"]],\"a\":[[\"79610.60\",\"0.023\"],[\"79617.00\",\"0.002\"],[\"79619.00\",\"0.433\"],[\"79666.10\",\"0.014\"],[\"79668.80\",\"0.035\"],[\"79671.50\",\"21.759\"],[\"79692.70\",\"0.003\"],[\"79835.90\",\"0.000\"],[\"80233.90\",\"7.091\"],[\"80393.10\",\"10.298\"],[\"81427.80\",\"1.717\"],[\"87556.90\",\"0.001\"]],\"st\":1}}"}
{"receive_ns":1788567716682192000,"stream":"btcusdt@depth@100ms","event_type":"depthUpdate","event_time_ms":1788567716697,"raw_json":"{\"stream\":\"btcusdt@depth@100ms\",\"data\":{\"e\":\"depthUpdate\",\"E\":1788567716697,\"T\":1788567716693,\"s\":\"BTCUSDT\",\"ps\":\"BTCUSDT\",\"U\":11478507404997,\"u\":11478507409456,\"pu\":11478507404941,\"b\":[[\"1000.00\",\"24.604\"],[\"29197.00\",\"1.708\"],[\"29297.00\",\"0.392\"],[\"63678.00\",\"0.000\"],[\"71637.30\",\"0.002\"],[\"76413.10\",\"0.000\"],[\"78069.10\",\"0.001\"],[\"78571.70\",\"0.000\"],[\"78574.00\",\"0.250\"],[\"78588.10\",\"7.399\"],[\"78591.20\",\"0.000\"],[\"78593.50\",\"0.007\"],[\"78610.80\",\"0.000\"],[\"78613.00\",\"2.008\"],[\"78801.00\",\"12.547\"],[\"78805.00\",\"0.700\"],[\"79448.90\",\"0.000\"],[\"79449.10\",\"0.032\"],[\"79539.30\",\"0.108\"],[\"79559.20\",\"0.001\"],[\"79583.60\",\"1.052\"],[\"79587.00\",\"0.719\"],[\"79595.10\",\"0.002\"]],\"a\":[[\"79641.60\",\"0.002\"],[\"79661.50\",\"0.000\"],[\"79668.80\",\"21.793\"],[\"79671.50\",\"0.001\"],[\"80324.20\",\"0.186\"],[\"80393.10\",\"10.298\"],[\"80479.20\",\"0.005\"],[\"80528.40\",\"3.031\"],[\"87556.90\",\"0.000\"]],\"st\":1}}"}
{"receive_ns":1788567716748524000,"stream":"btcusdt@bookTicker","event_type":"bookTicker","event_time_ms":1788567716762,"raw_json":"{\"stream\":\"btcusdt@bookTicker\",\"data\":{\"e\":\"bookTicker\",\"u\":11478507413064,\"s\":\"BTCUSDT\",\"ps\":\"BTCUSDT\",\"b\":\"79597.00\",\"B\":\"5.110\",\"a\":\"79597.10\",\"A\":\"7.716\",\"T\":1788567716762,\"E\":1788567716762,\"st\":1}}"}
{"receive_ns":1788567716753515000,"stream":"btcusdt@trade","event_type":"trade","event_time_ms":1788567716762,"raw_json":"{\"stream\":\"btcusdt@trade\",\"data\":{\"e\":\"trade\",\"E\":1788567716762,\"T\":1788567716762,\"s\":\"BTCUSDT\",\"t\":8054122566,\"p\":\"79597.10\",\"q\":\"0.001\",\"X\":\"MARKET\",\"m\":false,\"st\":1}}"}
{"receive_ns":1788567716769688000,"stream":"btcusdt@bookTicker","event_type":"bookTicker","event_time_ms":1788567716785,"raw_json":"{\"stream\":\"btcusdt@bookTicker\",\"data\":{\"e\":\"bookTicker\",\"u\":11478507414061,\"s\":\"BTCUSDT\",\"ps\":\"BTCUSDT\",\"b\":\"79597.00\",\"B\":\"4.986\",\"a\":\"79597.10\",\"A\":\"7.716\",\"T\":1788567716785,\"E\":1788567716785,\"st\":1}}"}
{"receive_ns":1788567716781816000,"stream":"btcusdt@bookTicker","event_type":"bookTicker","event_time_ms":1788567716788,"raw_json":"{\"stream\":\"btcusdt@bookTicker\",\"data\":{\"e\":\"bookTicker\",\"u\":11478507414169,\"s\":\"BTCUSDT\",\"ps\":\"BTCUSDT\",\"b\":\"79597.00\",\"B\":\"5.112\",\"a\":\"79597.10\",\"A\":\"7.716\",\"T\":1788567716788,\"E\":1788567716788,\"st\":1}}"}
{"receive_ns":1788567716782281000,"stream":"btcusdt@depth@100ms","event_type":"depthUpdate","event_time_ms":1788567716799,"raw_json":"{\"stream\":\"btcusdt@depth@100ms\",\"data\":{\"e\":\"depthUpdate\",\"E\":1788567716799,\"T\":1788567716797,\"s\":\"BTCUSDT\",\"ps\":\"BTCUSDT\",\"U\":11478507409775,\"u\":11478507415119,\"pu\":11478507409456,\"b\":[[\"29097.00\",\"0.049\"],[\"29197.00\",\"1.792\"],[\"29297.00\",\"0.259\"],[\"71637.30\",\"0.002\"],[\"76413.10\",\"0.002\"],[\"78403.00\",\"3.642\"],[\"78641.80\",\"32.676\"],[\"78801.00\",\"12.547\"],[\"79199.00\",\"4.110\"],[\"79448.90\",\"0.032\"],[\"79449.10\",\"0.000\"],[\"79475.40\",\"0.000\"],[\"79531.30\",\"0.011\"],[\"79534.00\",\"20.559\"],[\"79539.50\",\"0.130\"],[\"79591.50\",\"0.000\"],[\"79591.90\",\"0.001\"],[\"79592.10\",\"0.181\"],[\"79592.20\",\"0.028\"],[\"79594.20\",\"0.026\"],[\"79594.50\",\"0.026\"],[\"79595.30\",\"0.001\"],[\"79597.00\",\"5.112\"]],\"a\":[[\"79597.10\",\"7.716\"],[\"79617.00\",\"0.007\"],[\"79621.00\",\"0.003\"],[\"79666.10\",\"21.772\"],[\"79668.80\",\"0.035\"],[\"79719.70\",\"0.007\"],[\"79818.70\",\"6.869\"],[\"80393.10\",\"10.298\"],[\"87556.90\",\"0.000\"]],\"st\":1}}"}
{"receive_ns":1788567716813290000,"stream":"btcusdt@bookTicker","event_type":"bookTicker","event_time_ms":1788567716836,"raw_json":"{\"stream\":\"btcusdt@bookTicker\",\"data\":{\"e\":\"bookTicker\",\"u\":11478507417660,\"s\":\"BTCUSDT\",\"ps\":\"BTCUSDT\",\"b\":\"79597.00\",\"B\":\"5.112\",\"a\":\"79597.10\",\"A\":\"7.717\",\"T\":1788567716835,\"E\":1788567716836,\"st\":1}}"}
{"receive_ns":1788567716879657000,"stream":"btcusdt@depth@100ms","event_type":"depthUpdate","event_time_ms":1788567716901,"raw_json":"{\"stream\":\"btcusdt@depth@100ms\",\"data\":{\"e\":\"depthUpdate\",\"E\":1788567716901,\"T\":1788567716899,\"s\":\"BTCUSDT\",\"ps\":\"BTCUSDT\",\"U\":11478507415256,\"u\":11478507420933,\"pu\":11478507415119,\"b\":[[\"1000.00\",\"24.604\"],[\"29097.00\",\"0.105\"],[\"29197.00\",\"1.855\"],[\"29297.00\",\"0.140\"],[\"63678.00\",\"0.002\"],[\"71637.30\",\"0.002\"],[\"76413.10\",\"0.000\"],[\"78668.30\",\"5.181\"],[\"78801.00\",\"12.547\"],[\"79199.00\",\"4.236\"],[\"79460.70\",\"0.001\"],[\"79471.70\",\"0.040\"],[\"79475.40\",\"0.495\"],[\"79511.50\",\"0.001\"],[\"79517.10\",\"0.004\"],[\"79556.80\",\"0.001\"],[\"79573.30\",\"0.479\"],[\"79583.90\",\"1.654\"],[\"79584.80\",\"0.008\"],[\"79589.30\",\"0.001\"]],\"a\":[[\"79597.10\",\"7.717\"],[\"79607.90\",\"0.000\"],[\"79608.30\",\"0.019\"],[\"79610.40\",\"0.123\"],[\"79612.80\",\"0.442\"],[\"79613.20\",\"0.000\"],[\"79615.40\",\"0.004\"],[\"79616.60\",\"0.659\"],[\"79658.40\",\"1.842\"],[\"79661.80\",\"2.761\"],[\"79701.60\",\"0.024\"],[\"79719.70\",\"0.491\"],[\"80307.50\",\"0.000\"],[\"80393.10\",\"10.298\"],[\"80950.30\",\"6.477\"],[\"86000.00\",\"19.844\"]],\"st\":1}}"}
{"receive_ns":1788567716987839000,"stream":"btcusdt@depth@100ms","event_type":"depthUpdate","event_time_ms":1788567717003,"raw_json":"{\"stream\":\"btcusdt@depth@100ms\",\"data\":{\"e\":\"depthUpdate\",\"E\":1788567717003,\"T\":1788567717002,\"s\":\"BTCUSDT\",\"ps\":\"BTCUSDT\",\"U\":11478507421052,\"u\":11478507428034,\"pu\":11478507420933,\"b\":[[\"1000.00\",\"24.604\"],[\"29097.00\",\"0.168\"],[\"29197.00\",\"1.911\"],[\"29297.00\",\"0.021\"],[\"63678.00\",\"0.000\"],[\"71637.30\",\"0.002\"],[\"71673.00\",\"0.000\"],[\"75617.20\",\"0.006\"],[\"78801.00\",\"12.674\"],[\"78866.50\",\"0.889\"],[\"79022.50\",\"0.504\"],[\"79196.70\",\"0.344\"],[\"79199.90\",\"0.885\"],[\"79315.70\",\"0.000\"],[\"79316.00\",\"1.020\"],[\"79448.90\",\"0.000\"],[\"79450.30\",\"1.592\"],[\"79471.80\",\"1.317\"],[\"79511.80\",\"1.101\"],[\"79573.30\",\"0.481\"],[\"79577.10\",\"0.082\"]],\"a\":[[\"79610.90\",\"0.442\"],[\"79612.80\",\"0.003\"],[\"79613.20\",\"0.002\"],[\"79689.40\",\"0.000\"],[\"79728.00\",\"1.007\"],[\"79729.00\",\"0.466\"],[\"79886.70\",\"3.849\"],[\"79887.10\",\"0.001\"],[\"80006.50\",\"0.901\"],[\"80006.90\",\"0.339\"],[\"80182.90\",\"0.194\"],[\"80393.10\",\"10.298\"],[\"80472.70\",\"5.459\"]],\"st\":1}}"}
{"receive_ns":1788567717020568000,"stream":"btcusdt@bookTicker","event_type":"bookTicker","event_time_ms":1788567717042,"raw_json":"{\"stream\":\"btcusdt@bookTicker\",\"data\":{\"e\":\"bookTicker\",\"u\":11478507430372,\"s\":\"BTCUSDT\",\"ps\":\"BTCUSDT\",\"b\":\"79597.00\",\"B\":\"5.064\",\"a\":\"79597.10\",\"A\":\"7.717\",\"T\":1788567717042,\"E\":1788567717042,\"st\":1}}"}
{"receive_ns":1788567717026216000,"stream":"btcusdt@bookTicker","event_type":"bookTicker","event_time_ms":1788567717044,"raw_json":"{\"stream\":\"btcusdt@bookTicker\",\"data\":{\"e\":\"bookTicker\",\"u\":11478507430504,\"s\":\"BTCUSDT\",\"ps\":\"BTCUSDT\",\"b\":\"79597.00\",\"B\":\"5.112\",\"a\":\"79597.10\",\"A\":\"7.717\",\"T\":1788567717044,\"E\":1788567717044,\"st\":1}}"}
{"receive_ns":1788567717113116000,"stream":"btcusdt@depth@100ms","event_type":"depthUpdate","event_time_ms":1788567717105,"raw_json":"{\"stream\":\"btcusdt@depth@100ms\",\"data\":{\"e\":\"depthUpdate\",\"E\":1788567717105,\"T\":1788567717104,\"s\":\"BTCUSDT\",\"ps\":\"BTCUSDT\",\"U\":11478507428122,\"u\":11478507434697,\"pu\":11478507428034,\"b\":[[\"29097.00\",\"0.322\"],[\"29197.00\",\"1.778\"],[\"29297.00\",\"0.000\"],[\"63677.60\",\"0.000\"],[\"63678.00\",\"0.000\"],[\"71637.30\",\"0.002\"],[\"76413.10\",\"0.002\"],[\"77368.00\",\"0.160\"],[\"78641.80\",\"33.311\"],[\"78801.00\",\"12.674\"],[\"79199.00\",\"4.247\"],[\"79400.00\",\"4.811\"],[\"79517.10\",\"0.002\"],[\"79550.00\",\"1.598\"],[\"79556.80\",\"0.003\"],[\"79574.00\",\"0.003\"],[\"79576.50\",\"0.006\"],[\"79582.70\",\"0.194\"],[\"79591.70\",\"0.079\"],[\"79592.00\",\"0.005\"],[\"79592.20\",\"0.002\"],[\"79592.30\",\"0.000\"],[\"79592.80\",\"0.507\"],[\"79595.10\",\"0.001\"],[\"79595.30\",\"0.027\"],[\"79595.70\",\"0.026\"],[\"79596.00\",\"0.108\"],[\"79597.00\",\"5.112\"]],\"a\":[[\"79601.90\",\"0.002\"],[\"79604.30\",\"0.008\"],[\"79609.10\",\"0.002\"],[\"79610.60\",\"0.003\"],[\"79610.90\",\"0.003\"],[\"79611.60\",\"0.374\"],[\"79612.80\",\"0.442\"],[\"79616.60\",\"0.679\"],[\"79619.50\",\"0.711\"],[\"79620.70\",\"0.654\"],[\"79623.90\",\"0.010\"],[\"79624.60\",\"0.709\"],[\"79624.80\",\"0.153\"],[\"79625.90\",\"0.007\"],[\"79661.80\",\"2.763\"],[\"79701.60\",\"0.022\"],[\"79995.10\",\"4.365\"],[\"80393.10\",\"9.056\"],[\"80664.70\",\"0.031\"],[\"80724.80\",\"7.428\"],[\"80935.90\",\"5.651\"],[\"80950.30\",\"10.178\"]],\"st\":1}}"}
{"receive_ns":1788567717190458000,"stream":"btcusdt@depth@100ms","event_type":"depthUpdate","event_time_ms":1788567717207,"raw_json":"{\"stream\":\"btcusdt@depth@100ms\",\"data\":{\"e\":\"depthUpdate\",\"E\":1788567717207,\"T\":1788567717206,\"s\":\"BTCUSDT\",\"ps\":\"BTCUSDT\",\"U\":11478507434739,\"u\":11478507440114,\"pu\":11478507434697,\"b\":[[\"1000.00\",\"24.604\"],[\"29097.00\",\"0.504\"],[\"29197.00\",\"1.596\"],[\"71637.30\",\"0.002\"],[\"76413.10\",\"0.000\"],[\"78549.00\",\"0.000\"],[\"78801.00\",\"12.674\"],[\"78809.10\",\"0.377\"],[\"78816.10\",\"3.240\"],[\"78888.10\",\"0.648\"],[\"79000.10\",\"0.212\"],[\"79022.60\",\"0.000\"],[\"79196.80\",\"0.000\"],[\"79315.80\",\"0.007\"],[\"79561.20\",\"0.019\"],[\"79565.80\",\"0.125\"],[\"79566.20\",\"0.002\"],[\"79591.70\",\"0.003\"],[\"79592.50\",\"0.153\"],[\"79592.80\",\"0.505\"],[\"79594.40\",\"0.026\"],[\"79595.10\",\"0.002\"],[\"79595.30\",\"0.001\"],[\"79595.70\",\"0.026\"],[\"79595.80\",\"0.000\"],[\"79596.00\",\"0.082\"]],\"a\":[[\"79660.60\",\"0.000\"],[\"79671.20\",\"0.014\"],[\"79691.60\",\"0.000\"],[\"79805.20\",\"0.001\"],[\"79806.80\",\"4.861\"],[\"79887.00\",\"0.020\"],[\"79887.90\",\"0.463\"],[\"80006.50\",\"0.005\"],[\"80006.80\",\"0.000\"],[\"80099.90\",\"10.726\"],[\"80299.20\",\"4.042\"],[\"80393.10\",\"9.056\"],[\"80399.40\",\"0.083\"],[\"80694.20\",\"0.001\"]],\"st\":1}}"}
{"receive_ns":1788567717206691000,"stream":"btcusdt@bookTicker","event_type":"bookTicker","event_time_ms":1788567717222,"raw_json":"{\"stream\":\"btcusdt@bookTicker\",\"data\":{\"e\":\"bookTicker\",\"u\":11478507440985,\"s\":\"BTCUSDT\",\"ps\":\"BTCUSDT\",\"b\":\"79597.00\",\"B\":\"4.580\",\"a\":\"79597.10\",\"A\":\"7.717\",\"T\":1788567717222,\"E\":1788567717222,\"st\":1}}"}
{"receive_ns":1788567717213036000,"stream":"btcusdt@bookTicker","event_type":"bookTicker","event_time_ms":1788567717224,"raw_json":"{\"stream\":\"btcusdt@bookTicker\",\"data\":{\"e\":\"bookTicker\",\"u\":11478507442028,\"s\":\"BTCUSDT\",\"ps\":\"BTCUSDT\",\"b\":\"79597.00\",\"B\":\"3.994\",\"a\":\"79597.10\",\"A\":\"7.717\",\"T\":1788567717224,\"E\":1788567717224,\"st\":1}}"}
{"receive_ns":1788567717223697000,"stream":"btcusdt@bookTicker","event_type":"bookTicker","event_time_ms":1788567717226,"raw_json":"{\"stream\":\"btcusdt@bookTicker\",\"data\":{\"e\":\"bookTicker\",\"u\":11478507443655,\"s\":\"BTCUSDT\",\"ps\":\"BTCUSDT\",\"b\":\"79597.00\",\"B\":\"4.580\",\"a\":\"79597.10\",\"A\":\"7.717\",\"T\":1788567717225,\"E\":1788567717226,\"st\":1}}"}
{"receive_ns":1788567717224007000,"stream":"btcusdt@bookTicker","event_type":"bookTicker","event_time_ms":1788567717227,"raw_json":"{\"stream\":\"btcusdt@bookTicker\",\"data\":{\"e\":\"bookTicker\",\"u\":11478507444731,\"s\":\"BTCUSDT\",\"ps\":\"BTCUSDT\",\"b\":\"79597.00\",\"B\":\"4.579\",\"a\":\"79597.10\",\"A\":\"7.717\",\"T\":1788567717227,\"E\":1788567717227,\"st\":1}}"}
{"receive_ns":1788567717224255000,"stream":"btcusdt@bookTicker","event_type":"bookTicker","event_time_ms":1788567717227,"raw_json":"{\"stream\":\"btcusdt@bookTicker\",\"data\":{\"e\":\"bookTicker\",\"u\":11478507444838,\"s\":\"BTCUSDT\",\"ps\":\"BTCUSDT\",\"b\":\"79597.00\",\"B\":\"4.651\",\"a\":\"79597.10\",\"A\":\"7.717\",\"T\":1788567717227,\"E\":1788567717227,\"st\":1}}"}
{"receive_ns":1788567717238105000,"stream":"btcusdt@bookTicker","event_type":"bookTicker","event_time_ms":1788567717228,"raw_json":"{\"stream\":\"btcusdt@bookTicker\",\"data\":{\"e\":\"bookTicker\",\"u\":11478507445702,\"s\":\"BTCUSDT\",\"ps\":\"BTCUSDT\",\"b\":\"79597.00\",\"B\":\"4.652\",\"a\":\"79597.10\",\"A\":\"7.717\",\"T\":1788567717228,\"E\":1788567717228,\"st\":1}}"}
{"receive_ns":1788567717243888000,"stream":"btcusdt@bookTicker","event_type":"bookTicker","event_time_ms":1788567717235,"raw_json":"{\"stream\":\"btcusdt@bookTicker\",\"data\":{\"e\":\"bookTicker\",\"u\":11478507448180,\"s\":\"BTCUSDT\",\"ps\":\"BTCUSDT\",\"b\":\"79597.00\",\"B\":\"4.652\",\"a\":\"79597.10\",\"A\":\"7.716\",\"T\":1788567717235,\"E\":1788567717235,\"st\":1}}"}
{"receive_ns":1788567717255416000,"stream":"btcusdt@trade","event_type":"trade","event_time_ms":1788567717235,"raw_json":"{\"stream\":\"btcusdt@trade\",\"data\":{\"e\":\"trade\",\"E\":1788567717235,\"T\":1788567717235,\"s\":\"BTCUSDT\",\"t\":8054122567,\"p\":\"79597.10\",\"q\":\"0.001\",\"X\":\"MARKET\",\"m\":false,\"st\":1}}"}
{"receive_ns":1788567717260981000,"stream":"btcusdt@bookTicker","event_type":"bookTicker","event_time_ms":1788567717237,"raw_json":"{\"stream\":\"btcusdt@bookTicker\",\"data\":{\"e\":\"bookTicker\",\"u\":11478507448619,\"s\":\"BTCUSDT\",\"ps\":\"BTCUSDT\",\"b\":\"79597.00\",\"B\":\"4.552\",\"a\":\"79597.10\",\"A\":\"7.716\",\"T\":1788567717237,\"E\":1788567717237,\"st\":1}}"}
{"receive_ns":1788567717264447000,"stream":"btcusdt@trade","event_type":"trade","event_time_ms":1788567717237,"raw_json":"{\"stream\":\"btcusdt@trade\",\"data\":{\"e\":\"trade\",\"E\":1788567717237,\"T\":1788567717237,\"s\":\"BTCUSDT\",\"t\":8054122568,\"p\":\"79597.00\",\"q\":\"0.100\",\"X\":\"MARKET\",\"m\":true,\"st\":1}}"}
{"receive_ns":1788567717264705000,"stream":"btcusdt@bookTicker","event_type":"bookTicker","event_time_ms":1788567717277,"raw_json":"{\"stream\":\"btcusdt@bookTicker\",\"data\":{\"e\":\"bookTicker\",\"u\":11478507453855,\"s\":\"BTCUSDT\",\"ps\":\"BTCUSDT\",\"b\":\"79597.00\",\"B\":\"4.991\",\"a\":\"79597.10\",\"A\":\"7.716\",\"T\":1788567717277,\"E\":1788567717277,\"st\":1}}"}
{"receive_ns":1788567717275901000,"stream":"btcusdt@bookTicker","event_type":"bookTicker","event_time_ms":1788567717278,"raw_json":"{\"stream\":\"btcusdt@bookTicker\",\"data\":{\"e\":\"bookTicker\",\"u\":11478507453928,\"s\":\"BTCUSDT\",\"ps\":\"BTCUSDT\",\"b\":\"79597.00\",\"B\":\"4.990\",\"a\":\"79597.10\",\"A\":\"7.716\",\"T\":1788567717278,\"E\":1788567717278,\"st\":1}}"}
{"receive_ns":1788567717282509000,"stream":"btcusdt@bookTicker","event_type":"bookTicker","event_time_ms":1788567717287,"raw_json":"{\"stream\":\"btcusdt@bookTicker\",\"data\":{\"e\":\"bookTicker\",\"u\":11478507454669,\"s\":\"BTCUSDT\",\"ps\":\"BTCUSDT\",\"b\":\"79597.00\",\"B\":\"4.937\",\"a\":\"79597.10\",\"A\":\"7.716\",\"T\":1788567717287,\"E\":1788567717287,\"st\":1}}"}
{"receive_ns":1788567717282796000,"stream":"btcusdt@bookTicker","event_type":"bookTicker","event_time_ms":1788567717290,"raw_json":"{\"stream\":\"btcusdt@bookTicker\",\"data\":{\"e\":\"bookTicker\",\"u\":11478507454884,\"s\":\"BTCUSDT\",\"ps\":\"BTCUSDT\",\"b\":\"79597.00\",\"B\":\"4.987\",\"a\":\"79597.10\",\"A\":\"7.716\",\"T\":1788567717290,\"E\":1788567717290,\"st\":1}}"}
{"receive_ns":1788567717294420000,"stream":"btcusdt@bookTicker","event_type":"bookTicker","event_time_ms":1788567717291,"raw_json":"{\"stream\":\"btcusdt@bookTicker\",\"data\":{\"e\":\"bookTicker\",\"u\":11478507455014,\"s\":\"BTCUSDT\",\"ps\":\"BTCUSDT\",\"b\":\"79597.00\",\"B\":\"4.988\",\"a\":\"79597.10\",\"A\":\"7.716\",\"T\":1788567717291,\"E\":1788567717291,\"st\":1}}"}
{"receive_ns":1788567717296121000,"stream":"btcusdt@bookTicker","event_type":"bookTicker","event_time_ms":1788567717295,"raw_json":"{\"stream\":\"btcusdt@bookTicker\",\"data\":{\"e\":\"bookTicker\",\"u\":11478507455358,\"s\":\"BTCUSDT\",\"ps\":\"BTCUSDT\",\"b\":\"79597.00\",\"B\":\"4.862\",\"a\":\"79597.10\",\"A\":\"7.716\",\"T\":1788567717295,\"E\":1788567717295,\"st\":1}}"}
{"receive_ns":1788567717301964000,"stream":"btcusdt@bookTicker","event_type":"bookTicker","event_time_ms":1788567717298,"raw_json":"{\"stream\":\"btcusdt@bookTicker\",\"data\":{\"e\":\"bookTicker\",\"u\":11478507455636,\"s\":\"BTCUSDT\",\"ps\":\"BTCUSDT\",\"b\":\"79597.00\",\"B\":\"4.987\",\"a\":\"79597.10\",\"A\":\"7.716\",\"T\":1788567717298,\"E\":1788567717298,\"st\":1}}"}
{"receive_ns":1788567717309470000,"stream":"btcusdt@depth@100ms","event_type":"depthUpdate","event_time_ms":1788567717309,"raw_json":"{\"stream\":\"btcusdt@depth@100ms\",\"data\":{\"e\":\"depthUpdate\",\"E\":1788567717309,\"T\":1788567717306,\"s\":\"BTCUSDT\",\"ps\":\"BTCUSDT\",\"U\":11478507440186,\"u\":11478507456355,\"pu\":11478507440114,\"b\":[[\"1000.00\",\"24.604\"],[\"29097.00\",\"0.679\"],[\"29197.00\",\"1.421\"],[\"71637.30\",\"0.002\"],[\"76413.10\",\"0.002\"],[\"78664.80\",\"0.000\"],[\"78701.60\",\"0.000\"],[\"78801.00\",\"12.674\"],[\"78866.60\",\"0.897\"],[\"78880.60\",\"9.112\"],[\"79025.10\",\"74.033\"],[\"79199.30\",\"56.758\"],[\"79199.90\",\"9.260\"],[\"79318.30\",\"46.706\"],[\"79319.30\",\"7.615\"],[\"79513.80\",\"0.002\"],[\"79519.00\",\"0.466\"],[\"79533.10\",\"0.000\"],[\"79534.20\",\"0.099\"],[\"79542.30\",\"0.000\"],[\"79543.90\",\"1.123\"],[\"79553.50\",\"0.860\"],[\"79556.80\",\"0.001\"],[\"79557.20\",\"0.092\"],[\"79557.80\",\"0.234\"],[\"79559.80\",\"0.692\"],[\"79564.70\",\"0.728\"],[\"79565.20\",\"2.476\"],[\"79565.90\",\"0.002\"],[\"79572.80\",\"0.000\"],[\"79576.60\",\"0.078\"],[\"79577.70\",\"0.076\"],[\"79578.80\",\"0.076\"],[\"79579.90\",\"0.124\"],[\"79581.00\",\"0.079\"],[\"79583.90\",\"1.905\"],[\"79584.00\",\"0.016\"],[\"79584.30\",\"0.079\"],[\"79584.40\",\"0.010\"],[\"79584.80\",\"0.004\"],[\"79584.90\",\"0.000\"],[\"79585.40\",\"0.126\"],[\"79585.50\",\"0.293\"],[\"79586.50\",\"0.000\"],[\"79586.60\",\"0.255\"],[\"79586.70\",\"0.076\"],[\"79586.90\",\"0.003\"],[\"79587.10\",\"0.000\"],[\"79587.30\",\"0.054\"],[\"79587.40\",\"0.001\"],[\"79587.50\",\"0.000\"],[\"79587.60\",\"0.000\"],[\"79587.70\",\"0.002\"],[\"79587.80\",\"1.511\"],[\"79588.00\",\"0.004\"],[\"79588.10\",\"0.102\"],[\"79588.20\",\"0.004\"],[\"79588.30\",\"0.026\"],[\"79588.40\",\"0.000\"],[\"79588.50\",\"0.107\"],[\"79588.60\",\"0.026\"],[\"79588.70\",\"0.002\"],[\"79588.80\",\"0.001\"],[\"79588.90\",\"0.026\"],[\"79589.00\",\"0.198\"],[\"79589.10\",\"0.000\"],[\"79589.20\",\"0.026\"],[\"79589.30\",\"0.027\"],[\"79589.50\",\"0.066\"],[\"79589.70\",\"0.027\"],[\"79589.80\",\"0.026\"],[\"79589.90\",\"0.026\"],[\"79590.10\",\"0.160\"],[\"79590.50\",\"0.000\"],[\"79590.60\",\"0.002\"],[\"79590.70\",\"0.001\"],[\"79590.80\",\"0.253\"],[\"79590.90\",\"0.071\"],[\"79591.50\",\"0.004\"],[\"79592.20\",\"0.000\"],[\"79592.30\",\"0.000\"],[\"79592.40\",\"0.002\"],[\"79592.50\",\"0.125\"],[\"79592.60\",\"0.000\"],[\"79592.70\",\"0.002\"],[\"79592.90\",\"0.002\"],[\"79593.70\",\"0.000\"],[\"79594.20\",\"0.000\"],[\"79594.40\",\"0.000\"],[\"79594.50\",\"0.000\"],[\"79594.70\",\"0.000\"],[\"79594.80\",\"0.000\"],[\"79595.70\",\"0.000\"],[\"79596.00\",\"0.082\"],[\"79596.80\",\"0.159\"],[\"79597.00\",\"4.987\"]],\"a\":[[\"79597.10\",\"7.716\"],[\"79597.40\",\"0.002\"],[\"79597.50\",\"0.014\"],[\"79597.60\",\"0.091\"],[\"79601.00\",\"0.186\"],[\"79601.10\",\"0.222\"],[\"79601.20\",\"0.254\"],[\"79605.40\",\"0.084\"],[\"79608.30\",\"0.015\"],[\"79610.60\",\"0.003\"],[\"79610.70\",\"0.543\"],[\"79611.80\",\"0.081\"],[\"79612.80\",\"0.003\"],[\"79616.30\",\"0.641\"],[\"79621.00\",\"0.047\"],[\"79621.20\",\"0.000\"],[\"79621.50\",\"0.005\"],[\"79624.60\",\"0.082\"],[\"79626.60\",\"0.834\"],[\"79627.30\",\"0.003\"],[\"79628.40\",\"0.120\"],[\"79629.90\",\"0.021\"],[\"79630.40\",\"0.000\"],[\"79631.00\",\"0.075\"],[\"79637.20\",\"0.000\"],[\"79638.50\",\"0.005\"],[\"79644.90\",\"0.003\"],[\"79656.20\",\"0.041\"],[\"79659.40\",\"0.000\"],[\"79661.80\",\"2.775\"],[\"79664.40\",\"0.212\"],[\"79667.20\",\"0.225\"],[\"79671.20\",\"0.000\"],[\"79695.80\",\"0.002\"],[\"79806.80\",\"2.809\"],[\"79880.70\",\"7.483\"],[\"79880.80\",\"49.095\"],[\"80000.70\",\"60.863\"],[\"80176.70\",\"77.953\"],[\"80393.10\",\"9.056\"],[\"80592.10\",\"11.149\"],[\"81189.00\",\"10.509\"]],\"st\":1}}"}
{"receive_ns":1788567717393718000,"stream":"btcusdt@depth@100ms","event_type":"depthUpdate","event_time_ms":1788567717411,"raw_json":"{\"stream\":\"btcusdt@depth@100ms\",\"data\":{\"e\":\"depthUpdate\",\"E\":1788567717411,\"T\":1788567717410,\"s\":\"BTCUSDT\",\"ps\":\"BTCUSDT\",\"U\":11478507456832,\"u\":11478507462231,\"pu\":11478507456355,\"b\":[[\"29097.00\",\"0.861\"],[\"29197.00\",\"1.239\"],[\"71637.30\",\"0.002\"],[\"76413.10\",\"0.000\"],[\"78108.50\",\"2.516\"],[\"78801.00\",\"12.674\"],[\"78811.70\",\"92.238\"],[\"79199.00\",\"4.247\"],[\"79513.80\",\"0.000\"],[\"79543.90\",\"1.124\"],[\"79544.00\",\"1.783\"],[\"79544.30\",\"0.001\"],[\"79553.50\",\"0.862\"],[\"79573.30\",\"0.042\"],[\"79575.70\",\"0.441\"],[\"79576.40\",\"0.003\"],[\"79576.60\",\"0.002\"],[\"79576.90\",\"0.714\"],[\"79578.00\",\"0.701\"],[\"79587.80\",\"1.511\"],[\"79588.30\",\"0.000\"],[\"79588.50\",\"0.081\"],[\"79589.20\",\"0.060\"],[\"79590.10\",\"0.186\"],[\"79590.30\",\"0.000\"],[\"79592.70\",\"0.001\"]],\"a\":[[\"79597.50\",\"0.031\"],[\"79597.70\",\"0.163\"],[\"79610.70\",\"0.104\"],[\"79612.80\",\"0.442\"],[\"79621.00\",\"0.003\"],[\"79658.60\",\"0.254\"],[\"79695.80\",\"0.000\"],[\"79806.80\",\"4.861\"],[\"80393.10\",\"106.237\"]],\"st\":1}}"}
{"receive_ns":1788567717503738000,"stream":"btcusdt@depth@100ms","event_type":"depthUpdate","event_time_ms":1788567717513,"raw_json":"{\"stream\":\"btcusdt@depth@100ms\",\"data\":{\"e\":\"depthUpdate\",\"E\":1788567717513,\"T\":1788567717512,\"s\":\"BTCUSDT\",\"ps\":\"BTCUSDT\",\"U\":11478507462260,\"u\":11478507468043,\"pu\":11478507462231,\"b\":[[\"1000.00\",\"24.604\"],[\"29097.00\",\"1.036\"],[\"29197.00\",\"1.064\"],[\"71637.30\",\"0.002\"],[\"78548.20\",\"0.891\"],[\"78681.60\",\"9.525\"],[\"78801.00\",\"12.674\"],[\"78816.10\",\"0.000\"],[\"78888.10\",\"0.000\"],[\"78928.30\",\"0.274\"],[\"78960.20\",\"7.749\"],[\"79000.10\",\"0.050\"],[\"79025.20\",\"3.240\"],[\"79199.40\",\"0.654\"],[\"79318.40\",\"0.162\"],[\"79501.40\",\"0.048\"],[\"79574.60\",\"0.497\"],[\"79575.70\",\"0.002\"],[\"79588.60\",\"0.000\"],[\"79590.20\",\"0.027\"],[\"79590.40\",\"0.027\"],[\"79591.20\",\"0.010\"],[\"79591.50\",\"0.000\"]],\"a\":[[\"79610.70\",\"0.543\"],[\"79612.80\",\"0.003\"],[\"79880.70\",\"7.645\"],[\"79887.90\",\"0.301\"],[\"80000.60\",\"3.241\"],[\"80099.90\",\"7.486\"],[\"80233.90\",\"7.339\"],[\"80393.10\",\"106.237\"],[\"80711.50\",\"30.576\"]],\"st\":1}}"}
{"receive_ns":1788567717566923000,"stream":"btcusdt@bookTicker","event_type":"bookTicker","event_time_ms":1788567717582,"raw_json":"{\"stream\":\"btcusdt@bookTicker\",\"data\":{\"e\":\"bookTicker\",\"u\":11478507471185,\"s\":\"BTCUSDT\",\"ps\":\"BTCUSDT\",\"b\":\"79597.00\",\"B\":\"4.988\",\"a\":\"79597.10\",\"A\":\"7.716\",\"T\":1788567717582,\"E\":1788567717582,\"st\":1}}"}
{"receive_ns":1788567717600612000,"stream":"btcusdt@depth@100ms","event_type":"depthUpdate","event_time_ms":1788567717615,"raw_json":"{\"stream\":\"btcusdt@depth@100ms\",\"data\":{\"e\":\"depthUpdate\",\"E\":1788567717615,\"T\":1788567717613,\"s\":\"BTCUSDT\",\"ps\":\"BTCUSDT\",\"U\":11478507468119,\"u\":11478507473197,\"pu\":11478507468043,\"b\":[[\"1000.00\",\"24.604\"],[\"29097.00\",\"1.218\"],[\"29197.00\",\"0.882\"],[\"71637.30\",\"0.002\"],[\"76413.10\",\"0.002\"],[\"78522.40\",\"10.911\"],[\"78641.80\",\"32.677\"],[\"78801.00\",\"12.674\"],[\"79199.00\",\"4.246\"],[\"79475.40\",\"0.494\"],[\"79477.40\",\"0.000\"],[\"79497.90\",\"0.215\"],[\"79501.40\",\"0.046\"],[\"79519.00\",\"0.256\"],[\"79525.30\",\"0.633\"],[\"79527.80\",\"0.215\"],[\"79539.00\",\"0.849\"],[\"79541.20\",\"0.000\"],[\"79587.80\",\"1.587\"],[\"79588.90\",\"0.000\"],[\"79589.20\",\"0.000\"],[\"79589.30\",\"0.001\"],[\"79589.50\",\"0.040\"],[\"79590.50\",\"0.026\"],[\"79590.80\",\"0.279\"],[\"79591.30\",\"0.126\"],[\"79591.60\",\"0.026\"],[\"79597.00\",\"4.988\"]],\"a\":[[\"79603.90\",\"0.076\"],[\"79665.40\",\"4.839\"],[\"79668.80\",\"0.033\"],[\"79692.70\",\"0.001\"],[\"79719.70\",\"0.473\"],[\"79732.50\",\"0.000\"],[\"79772.70\",\"4.491\"],[\"79805.20\",\"0.001\"],[\"79806.80\",\"2.847\"],[\"80393.10\",\"106.237\"],[\"80559.20\",\"0.000\"],[\"80724.70\",\"3.583\"],[\"80751.30\",\"13.172\"],[\"80830.90\",\"6.920\"]],\"st\":1}}"}
{"receive_ns":1788567717700107000,"stream":"btcusdt@depth@100ms","event_type":"depthUpdate","event_time_ms":1788567717717,"raw_json":"{\"stream\":\"btcusdt@depth@100ms\",\"data\":{\"e\":\"depthUpdate\",\"E\":1788567717717,\"T\":1788567717715,\"s\":\"BTCUSDT\",\"ps\":\"BTCUSDT\",\"U\":11478507473292,\"u\":11478507477790,\"pu\":11478507473197,\"b\":[[\"29097.00\",\"1.393\"],[\"29197.00\",\"0.707\"],[\"71637.30\",\"0.002\"],[\"76413.10\",\"0.000\"],[\"78482.60\",\"33.524\"],[\"78574.00\",\"0.245\"],[\"78576.40\",\"0.006\"],[\"78593.50\",\"0.001\"],[\"78595.80\",\"0.009\"],[\"78602.00\",\"16.095\"],[\"78801.00\",\"12.674\"],[\"79199.00\",\"4.246\"],[\"79436.30\",\"0.002\"],[\"79568.90\",\"0.002\"],[\"79570.80\",\"0.476\"],[\"79570.90\",\"0.002\"],[\"79573.30\",\"0.481\"],[\"79574.60\",\"0.058\"],[\"79576.10\",\"0.376\"],[\"79576.90\",\"0.341\"],[\"79577.70\",\"0.000\"],[\"79587.50\",\"0.002\"],[\"79589.50\",\"0.040\"],[\"79589.70\",\"0.001\"],[\"79589.80\",\"0.000\"],[\"79592.50\",\"0.151\"],[\"79592.70\",\"0.001\"]],\"a\":[[\"79605.40\",\"0.080\"],[\"79607.70\",\"0.004\"],[\"79610.70\",\"0.104\"],[\"79610.90\",\"0.003\"],[\"79612.70\",\"0.443\"],[\"79612.80\",\"0.003\"],[\"79619.30\",\"0.001\"],[\"79620.30\",\"0.471\"],[\"79620.60\",\"0.002\"],[\"79995.10\",\"4.366\"],[\"80393.10\",\"106.237\"]],\"st\":1}}"}
{"receive_ns":1788567717705901000,"stream":"btcusdt@bookTicker","event_type":"bookTicker","event_time_ms":1788567717718,"raw_json":"{\"stream\":\"btcusdt@bookTicker\",\"data\":{\"e\":\"bookTicker\",\"u\":11478507477882,\"s\":\"BTCUSDT\",\"ps\":\"BTCUSDT\",\"b\":\"79597.00\",\"B\":\"4.948\",\"a\":\"79597.10\",\"A\":\"7.716\",\"T\":1788567717718,\"E\":1788567717718,\"st\":1}}"}
{"receive_ns":1788567717717675000,"stream":"btcusdt@bookTicker","event_type":"bookTicker","event_time_ms":1788567717720,"raw_json":"{\"stream\":\"btcusdt@bookTicker\",\"data\":{\"e\":\"bookTicker\",\"u\":11478507478009,\"s\":\"BTCUSDT\",\"ps\":\"BTCUSDT\",\"b\":\"79597.00\",\"B\":\"4.987\",\"a\":\"79597.10\",\"A\":\"7.716\",\"T\":1788567717720,\"E\":1788567717720,\"st\":1}}"}
{"receive_ns":1788567717805834000,"stream":"btcusdt@depth@100ms","event_type":"depthUpdate","event_time_ms":1788567717819,"raw_json":"{\"stream\":\"btcusdt@depth@100ms\",\"data\":{\"e\":\"depthUpdate\",\"E\":1788567717819,\"T\":1788567717818,\"s\":\"BTCUSDT\",\"ps\":\"BTCUSDT\",\"U\":11478507477878,\"u\":11478507482860,\"pu\":11478507477790,\"b\":[[\"1000.00\",\"24.604\"],[\"29097.00\",\"1.568\"],[\"29197.00\",\"0.532\"],[\"71637.30\",\"0.002\"],[\"75617.10\",\"0.031\"],[\"75617.20\",\"0.008\"],[\"76413.10\",\"0.002\"],[\"78466.70\",\"2.448\"],[\"78522.40\",\"11.420\"],[\"78641.80\",\"33.311\"],[\"78801.00\",\"12.674\"],[\"79510.00\",\"6.155\"],[\"79511.80\",\"1.841\"],[\"79537.80\",\"3.500\"],[\"79557.70\",\"1.092\"],[\"79591.20\",\"0.006\"],[\"79592.00\",\"0.009\"],[\"79597.00\",\"4.987\"]],\"a\":[[\"79610.90\",\"0.442\"],[\"79612.70\",\"0.004\"],[\"79628.40\",\"0.126\"],[\"79641.30\",\"0.848\"],[\"79661.30\",\"3.510\"],[\"79689.10\",\"6.000\"],[\"80393.10\",\"106.237\"],[\"80751.30\",\"14.038\"],[\"80830.90\",\"7.785\"]],\"st\":1}}"}
{"receive_ns":1788567717812560000,"stream":"btcusdt@bookTicker","event_type":"bookTicker","event_time_ms":1788567717828,"raw_json":"{\"stream\":\"btcusdt@bookTicker\",\"data\":{\"e\":\"bookTicker\",\"u\":11478507483451,\"s\":\"BTCUSDT\",\"ps\":\"BTCUSDT\",\"b\":\"79597.00\",\"B\":\"4.987\",\"a\":\"79597.10\",\"A\":\"7.717\",\"T\":1788567717827,\"E\":1788567717828,\"st\":1}}"}
{"receive_ns":1788567717821528000,"stream":"btcusdt@bookTicker","event_type":"bookTicker","event_time_ms":1788567717829,"raw_json":"{\"stream\":\"btcusdt@bookTicker\",\"data\":{\"e\":\"bookTicker\",\"u\":11478507483643,\"s\":\"BTCUSDT\",\"ps\":\"BTCUSDT\",\"b\":\"79597.00\",\"B\":\"4.987\",\"a\":\"79597.10\",\"A\":\"7.718\",\"T\":1788567717829,\"E\":1788567717829,\"st\":1}}"}
{"receive_ns":1788567717852140000,"stream":"btcusdt@bookTicker","event_type":"bookTicker","event_time_ms":1788567717867,"raw_json":"{\"stream\":\"btcusdt@bookTicker\",\"data\":{\"e\":\"bookTicker\",\"u\":11478507486111,\"s\":\"BTCUSDT\",\"ps\":\"BTCUSDT\",\"b\":\"79597.00\",\"B\":\"4.987\",\"a\":\"79597.10\",\"A\":\"7.719\",\"T\":1788567717867,\"E\":1788567717867,\"st\":1}}"}
{"receive_ns":1788567717899903000,"stream":"btcusdt@depth@100ms","event_type":"depthUpdate","event_time_ms":1788567717921,"raw_json":"{\"stream\":\"btcusdt@depth@100ms\",\"data\":{\"e\":\"depthUpdate\",\"E\":1788567717921,\"T\":1788567717920,\"s\":\"BTCUSDT\",\"ps\":\"BTCUSDT\",\"U\":11478507482916,\"u\":11478507490085,\"pu\":11478507482860,\"b\":[[\"1000.00\",\"24.604\"],[\"29097.00\",\"1.750\"],[\"29197.00\",\"0.350\"],[\"71637.30\",\"0.002\"],[\"78389.80\",\"0.637\"],[\"78801.00\",\"12.676\"],[\"79470.20\",\"10.003\"],[\"79471.80\",\"2.623\"],[\"79475.40\",\"0.512\"],[\"79573.30\",\"0.479\"]],\"a\":[[\"79597.10\",\"7.718\"],[\"79613.20\",\"0.000\"],[\"79719.70\",\"0.491\"],[\"79728.00\",\"2.861\"],[\"79729.00\",\"10.466\"],[\"80393.10\",\"106.237\"],[\"80422.40\",\"1.813\"],[\"80483.40\",\"0.195\"],[\"80631.90\",\"9.775\"],[\"80751.30\",\"13.172\"]],\"st\":1}}"}
{"receive_ns":1788567717900205000,"stream":"btcusdt@bookTicker","event_type":"bookTicker","event_time_ms":1788567717920,"raw_json":"{\"stream\":\"btcusdt@bookTicker\",\"data\":{\"e\":\"bookTicker\",\"u\":11478507490085,\"s\":\"BTCUSDT\",\"ps\":\"BTCUSDT\",\"b\":\"79597.00\",\"B\":\"4.987\",\"a\":\"79597.10\",\"A\":\"7.718\",\"T\":1788567717920,\"E\":1788567717920,\"st\":1}}"}
{"receive_ns":1788567717911378000,"stream":"btcusdt@trade","event_type":"trade","event_time_ms":1788567717920,"raw_json":"{\"stream\":\"btcusdt@trade\",\"data\":{\"e\":\"trade\",\"E\":1788567717920,\"T\":1788567717920,\"s\":\"BTCUSDT\",\"t\":8054122569,\"p\":\"79597.10\",\"q\":\"0.001\",\"X\":\"MARKET\",\"m\":false,\"st\":1}}"}
{"receive_ns":1788567718007555000,"stream":"btcusdt@depth@100ms","event_type":"depthUpdate","event_time_ms":1788567718023,"raw_json":"{\"stream\":\"btcusdt@depth@100ms\",\"data\":{\"e\":\"depthUpdate\",\"E\":1788567718023,\"T\":1788567718021,\"s\":\"BTCUSDT\",\"ps\":\"BTCUSDT\",\"U\":11478507490133,\"u\":11478507494726,\"pu\":11478507490085,\"b\":[[\"29097.00\",\"1.806\"],[\"29197.00\",\"0.231\"],[\"29497.00\",\"0.063\"],[\"71637.30\",\"0.002\"],[\"71673.00\",\"0.003\"],[\"76413.10\",\"0.000\"],[\"78801.00\",\"12.674\"],[\"79199.00\",\"4.246\"],[\"79449.90\",\"2.080\"],[\"79451.70\",\"0.012\"],[\"79565.70\",\"0.015\"],[\"79565.80\",\"0.000\"],[\"79570.30\",\"0.001\"],[\"79572.70\",\"0.019\"],[\"79573.30\",\"0.481\"],[\"79588.90\",\"0.076\"],[\"79589.40\",\"0.000\"],[\"79589.90\",\"0.000\"],[\"79590.10\",\"0.160\"],[\"79590.20\",\"0.001\"],[\"79590.40\",\"0.001\"],[\"79591.80\",\"0.026\"],[\"79592.00\",\"0.035\"],[\"79592.10\",\"0.207\"],[\"79592.20\",\"0.026\"],[\"79592.30\",\"0.026\"],[\"79592.50\",\"0.151\"]],\"a\":[[\"79607.50\",\"0.003\"],[\"79610.80\",\"4.799\"],[\"79613.20\",\"0.002\"],[\"79718.30\",\"1.884\"],[\"79720.10\",\"0.592\"],[\"80299.30\",\"11.479\"],[\"80393.10\",\"106.237\"],[\"80713.10\",\"0.296\"],[\"81189.00\",\"10.509\"]],\"st\":1}}"}
{"receive_ns":1788567718025304000,"stream":"btcusdt@bookTicker","event_type":"bookTicker","event_time_ms":1788567718039,"raw_json":"{\"stream\":\"btcusdt@bookTicker\",\"data\":{\"e\":\"bookTicker\",\"u\":11478507495571,\"s\":\"BTCUSDT\",\"ps\":\"BTCUSDT\",\"b\":\"79597.00\",\"B\":\"4.987\",\"a\":\"79597.10\",\"A\":\"7.719\",\"T\":1788567718039,\"E\":1788567718039,\"st\":1}}"}
{"receive_ns":1788567718110345000,"stream":"btcusdt@depth@100ms","event_type":"depthUpdate","event_time_ms":1788567718125,"raw_json":"{\"stream\":\"btcusdt@depth@100ms\",\"data\":{\"e\":\"depthUpdate\",\"E\":1788567718125,\"T\":1788567718121,\"s\":\"BTCUSDT\",\"ps\":\"BTCUSDT\",\"U\":11478507494831,\"u\":11478507499702,\"pu\":11478507494726,\"b\":[[\"1000.00\",\"24.604\"],[\"29097.00\",\"1.869\"],[\"29197.00\",\"0.112\"],[\"29497.00\",\"0.119\"],[\"63677.60\",\"0.000\"],[\"71637.30\",\"0.002\"],[\"71673.00\",\"0.000\"],[\"76413.10\",\"0.002\"],[\"78551.70\",\"113.235\"],[\"78801.00\",\"12.674\"],[\"78880.60\",\"9.998\"],[\"79199.00\",\"4.245\"],[\"79436.30\",\"0.003\"],[\"79582.70\",\"0.194\"],[\"79588.90\",\"0.110\"]],\"a\":[[\"79597.10\",\"7.719\"],[\"79597.20\",\"0.008\"],[\"79657.60\",\"0.035\"],[\"79691.80\",\"0.123\"],[\"80393.10\",\"106.237\"],[\"80658.00\",\"130.504\"],[\"80751.30\",\"14.038\"],[\"83576.90\",\"0.040\"]],\"st\":1}}"}
{"receive_ns":1788567718211798000,"stream":"btcusdt@depth@100ms","event_type":"depthUpdate","event_time_ms":1788567718227,"raw_json":"{\"stream\":\"btcusdt@depth@100ms\",\"data\":{\"e\":\"depthUpdate\",\"E\":1788567718227,\"T\":1788567718226,\"s\":\"BTCUSDT\",\"ps\":\"BTCUSDT\",\"U\":11478507499945,\"u\":11478507504414,\"pu\":11478507499702,\"b\":[[\"1000.00\",\"24.604\"],[\"29097.00\",\"1.897\"],[\"29197.00\",\"0.007\"],[\"29497.00\",\"0.196\"],[\"71637.30\",\"0.002\"],[\"74781.80\",\"0.070\"],[\"76413.10\",\"0.000\"],[\"77964.00\",\"2.116\"],[\"78801.00\",\"12.674\"]],\"a\":[[\"80148.40\",\"0.150\"],[\"80393.10\",\"106.237\"],[\"80464.70\",\"8.490\"],[\"80711.50\",\"28.720\"],[\"80725.50\",\"3.193\"]],\"st\":1}}"}
{"receive_ns":1788567718309637000,"stream":"btcusdt@depth@100ms","event_type":"depthUpdate","event_time_ms":1788567718329,"raw_json":"{\"stream\":\"btcusdt@depth@100ms\",\"data\":{\"e\":\"depthUpdate\",\"E\":1788567718329,\"T\":1788567718327,\"s\":\"BTCUSDT\",\"ps\":\"BTCUSDT\",\"U\":11478507504454,\"u\":11478507511074,\"pu\":11478507504414,\"b\":[[\"29097.00\",\"1.736\"],[\"29197.00\",\"0.000\"],[\"29497.00\",\"0.364\"],[\"71637.30\",\"0.002\"],[\"76372.90\",\"0.023\"],[\"76413.10\",\"0.002\"],[\"77168.40\",\"0.955\"],[\"78801.00\",\"12.674\"],[\"79199.00\",\"4.245\"],[\"79565.10\",\"0.858\"],[\"79565.30\",\"0.905\"]],\"a\":[[\"79626.10\",\"0.684\"],[\"79628.40\",\"0.120\"],[\"79691.90\",\"0.064\"],[\"79818.70\",\"6.814\"],[\"80393.10\",\"106.237\"]],\"st\":1}}"}
{"receive_ns":1788567718415111000,"stream":"btcusdt@depth@100ms","event_type":"depthUpdate","event_time_ms":1788567718431,"raw_json":"{\"stream\":\"btcusdt@depth@100ms\",\"data\":{\"e\":\"depthUpdate\",\"E\":1788567718431,\"T\":1788567718430,\"s\":\"BTCUSDT\",\"ps\":\"BTCUSDT\",\"U\":11478507511354,\"u\":11478507520662,\"pu\":11478507511074,\"b\":[[\"1000.00\",\"24.604\"],[\"29097.00\",\"1.554\"],[\"29497.00\",\"0.546\"],[\"71637.30\",\"0.002\"],[\"75577.30\",\"0.000\"],[\"78083.00\",\"0.122\"],[\"78602.00\",\"16.247\"],[\"78801.00\",\"12.674\"],[\"79436.30\",\"0.004\"],[\"79564.80\",\"1.136\"],[\"79565.20\",\"2.476\"],[\"79596.80\",\"0.160\"]],\"a\":[[\"79806.80\",\"2.224\"],[\"79995.10\",\"4.367\"],[\"80233.90\",\"7.091\"],[\"80393.10\",\"106.237\"],[\"80486.00\",\"9.842\"],[\"80751.30\",\"13.172\"]],\"st\":1}}"}
{"receive_ns":1788567718481493000,"stream":"btcusdt@bookTicker","event_type":"bookTicker","event_time_ms":1788567718503,"raw_json":"{\"stream\":\"btcusdt@bookTicker\",\"data\":{\"e\":\"bookTicker\",\"u\":11478507523926,\"s\":\"BTCUSDT\",\"ps\":\"BTCUSDT\",\"b\":\"79597.00\",\"B\":\"4.987\",\"a\":\"79597.10\",\"A\":\"7.722\",\"T\":1788567718503,\"E\":1788567718503,\"st\":1}}"}
{"receive_ns":1788567718481744000,"stream":"btcusdt@bookTicker","event_type":"bookTicker","event_time_ms":1788567718507,"raw_json":"{\"stream\":\"btcusdt@bookTicker\",\"data\":{\"e\":\"bookTicker\",\"u\":11478507524207,\"s\":\"BTCUSDT\",\"ps\":\"BTCUSDT\",\"b\":\"79597.00\",\"B\":\"4.987\",\"a\":\"79597.10\",\"A\":\"7.800\",\"T\":1788567718506,\"E\":1788567718507,\"st\":1}}"}
{"receive_ns":1788567718493569000,"stream":"btcusdt@bookTicker","event_type":"bookTicker","event_time_ms":1788567718508,"raw_json":"{\"stream\":\"btcusdt@bookTicker\",\"data\":{\"e\":\"bookTicker\",\"u\":11478507524282,\"s\":\"BTCUSDT\",\"ps\":\"BTCUSDT\",\"b\":\"79597.00\",\"B\":\"4.987\",\"a\":\"79597.10\",\"A\":\"7.798\",\"T\":1788567718508,\"E\":1788567718508,\"st\":1}}"}
{"receive_ns":1788567718511433000,"stream":"btcusdt@depth@100ms","event_type":"depthUpdate","event_time_ms":1788567718533,"raw_json":"{\"stream\":\"btcusdt@depth@100ms\",\"data\":{\"e\":\"depthUpdate\",\"E\":1788567718533,\"T\":1788567718529,\"s\":\"BTCUSDT\",\"ps\":\"BTCUSDT\",\"U\":11478507520821,\"u\":11478507525467,\"pu\":11478507520662,\"b\":[[\"1000.00\",\"24.604\"],[\"29097.00\",\"1.379\"],[\"29497.00\",\"0.721\"],[\"71637.30\",\"0.002\"],[\"76413.10\",\"0.000\"],[\"78701.30\",\"0.000\"],[\"78801.00\",\"12.674\"],[\"78960.20\",\"4.588\"],[\"79475.40\",\"0.512\"],[\"79539.00\",\"1.295\"],[\"79541.20\",\"0.002\"],[\"79564.80\",\"1.011\"],[\"79588.90\",\"0.034\"],[\"79590.50\",\"0.000\"],[\"79592.60\",\"0.026\"]],\"a\":[[\"79597.10\",\"7.798\"],[\"79610.60\",\"0.694\"],[\"79668.80\",\"0.035\"],[\"79719.60\",\"0.485\"],[\"79719.70\",\"0.007\"],[\"79756.30\",\"0.005\"],[\"79804.90\",\"0.727\"],[\"80000.10\",\"9.962\"],[\"80393.10\",\"106.237\"],[\"80711.50\",\"30.576\"],[\"80940.50\",\"0.000\"]],\"st\":1}}"}
{"receive_ns":1788567718625515000,"stream":"btcusdt@depth@100ms","event_type":"depthUpdate","event_time_ms":1788567718635,"raw_json":"{\"stream\":\"btcusdt@depth@100ms\",\"data\":{\"e\":\"depthUpdate\",\"E\":1788567718635,\"T\":1788567718634,\"s\":\"BTCUSDT\",\"ps\":\"BTCUSDT\",\"U\":11478507525604,\"u\":11478507529598,\"pu\":11478507525467,\"b\":[[\"29097.00\",\"1.197\"],[\"29497.00\",\"0.903\"],[\"63678.00\",\"0.000\"],[\"71637.30\",\"0.002\"],[\"76413.10\",\"0.002\"],[\"78385.60\",\"4.325\"],[\"78801.00\",\"11.407\"],[\"78880.60\",\"10.884\"],[\"79199.00\",\"4.245\"],[\"79497.90\",\"0.209\"],[\"79512.70\",\"0.007\"],[\"79590.80\",\"0.253\"],[\"79593.00\",\"0.081\"]],\"a\":[[\"80324.20\",\"0.372\"],[\"80393.10\",\"106.237\"],[\"80552.30\",\"28.238\"],[\"80711.50\",\"28.720\"],[\"87556.80\",\"0.002\"]],\"st\":1}}"}
{"receive_ns":1788567718685970000,"stream":"btcusdt@bookTicker","event_type":"bookTicker","event_time_ms":1788567718707,"raw_json":"{\"stream\":\"btcusdt@bookTicker\",\"data\":{\"e\":\"bookTicker\",\"u\":11478507532893,\"s\":\"BTCUSDT\",\"ps\":\"BTCUSDT\",\"b\":\"79597.00\",\"B\":\"4.948\",\"a\":\"79597.10\",\"A\":\"7.798\",\"T\":1788567718707,\"E\":1788567718707,\"st\":1}}"}
{"receive_ns":1788567718686230000,"stream":"btcusdt@bookTicker","event_type":"bookTicker","event_time_ms":1788567718711,"raw_json":"{\"stream\":\"btcusdt@bookTicker\",\"data\":{\"e\":\"bookTicker\",\"u\":11478507533025,\"s\":\"BTCUSDT\",\"ps\":\"BTCUSDT\",\"b\":\"79597.00\",\"B\":\"4.990\",\"a\":\"79597.10\",\"A\":\"7.798\",\"T\":1788567718710,\"E\":1788567718711,\"st\":1}}"}
{"receive_ns":1788567718692901000,"stream":"btcusdt@bookTicker","event_type":"bookTicker","event_time_ms":1788567718712,"raw_json":"{\"stream\":\"btcusdt@bookTicker\",\"data\":{\"e\":\"bookTicker\",\"u\":11478507533059,\"s\":\"BTCUSDT\",\"ps\":\"BTCUSDT\",\"b\":\"79597.00\",\"B\":\"4.990\",\"a\":\"79597.10\",\"A\":\"7.800\",\"T\":1788567718711,\"E\":1788567718712,\"st\":1}}"}
{"receive_ns":1788567718719398000,"stream":"btcusdt@depth@100ms","event_type":"depthUpdate","event_time_ms":1788567718737,"raw_json":"{\"stream\":\"btcusdt@depth@100ms\",\"data\":{\"e\":\"depthUpdate\",\"E\":1788567718737,\"T\":1788567718734,\"s\":\"BTCUSDT\",\"ps\":\"BTCUSDT\",\"U\":11478507529709,\"u\":11478507533750,\"pu\":11478507529598,\"b\":[[\"1000.00\",\"24.754\"],[\"29097.00\",\"1.022\"],[\"29497.00\",\"1.078\"],[\"63678.00\",\"0.000\"],[\"71637.30\",\"0.002\"],[\"75617.10\",\"0.029\"],[\"75617.20\",\"0.010\"],[\"76413.10\",\"0.000\"],[\"78576.40\",\"0.000\"],[\"78578.70\",\"0.010\"],[\"78581.90\",\"0.096\"],[\"78595.80\",\"0.004\"],[\"78598.10\",\"0.006\"],[\"78613.00\",\"2.005\"],[\"78617.50\",\"0.015\"],[\"78801.00\",\"10.140\"],[\"78960.20\",\"7.749\"],[\"79000.00\",\"43.490\"],[\"79525.30\",\"0.635\"],[\"79591.70\",\"0.007\"],[\"79592.00\",\"0.031\"],[\"79593.00\",\"0.055\"],[\"79597.00\",\"4.990\"]],\"a\":[[\"79597.10\",\"7.800\"],[\"79605.40\",\"0.084\"],[\"79607.70\",\"0.000\"],[\"79692.70\",\"0.003\"],[\"79796.10\",\"1.877\"],[\"79995.10\",\"4.366\"],[\"80393.10\",\"106.237\"],[\"80707.00\",\"0.005\"],[\"80716.40\",\"0.382\"],[\"80717.90\",\"0.000\"],[\"80727.20\",\"0.374\"],[\"80751.30\",\"14.038\"],[\"87556.80\",\"0.000\"]],\"st\":1}}"}
{"receive_ns":1788567718725207000,"stream":"btcusdt@bookTicker","event_type":"bookTicker","event_time_ms":1788567718739,"raw_json":"{\"stream\":\"btcusdt@bookTicker\",\"data\":{\"e\":\"bookTicker\",\"u\":11478507533899,\"s\":\"BTCUSDT\",\"ps\":\"BTCUSDT\",\"b\":\"79597.00\",\"B\":\"4.990\",\"a\":\"79597.10\",\"A\":\"7.798\",\"T\":1788567718739,\"E\":1788567718739,\"st\":1}}"}
{"receive_ns":1788567718739191000,"stream":"btcusdt@bookTicker","event_type":"bookTicker","event_time_ms":1788567718760,"raw_json":"{\"stream\":\"btcusdt@bookTicker\",\"data\":{\"e\":\"bookTicker\",\"u\":11478507534730,\"s\":\"BTCUSDT\",\"ps\":\"BTCUSDT\",\"b\":\"79597.00\",\"B\":\"4.978\",\"a\":\"79597.10\",\"A\":\"7.798\",\"T\":1788567718760,\"E\":1788567718760,\"st\":1}}"}
{"receive_ns":1788567718812050000,"stream":"btcusdt@bookTicker","event_type":"bookTicker","event_time_ms":1788567718785,"raw_json":"{\"stream\":\"btcusdt@bookTicker\",\"data\":{\"e\":\"bookTicker\",\"u\":11478507535855,\"s\":\"BTCUSDT\",\"ps\":\"BTCUSDT\",\"b\":\"79597.00\",\"B\":\"4.853\",\"a\":\"79597.10\",\"A\":\"7.798\",\"T\":1788567718785,\"E\":1788567718785,\"st\":1}}"}
{"receive_ns":1788567718817683000,"stream":"btcusdt@bookTicker","event_type":"bookTicker","event_time_ms":1788567718788,"raw_json":"{\"stream\":\"btcusdt@bookTicker\",\"data\":{\"e\":\"bookTicker\",\"u\":11478507535946,\"s\":\"BTCUSDT\",\"ps\":\"BTCUSDT\",\"b\":\"79597.00\",\"B\":\"4.977\",\"a\":\"79597.10\",\"A\":\"7.798\",\"T\":1788567718788,\"E\":1788567718788,\"st\":1}}"}
{"receive_ns":1788567718823091000,"stream":"btcusdt@bookTicker","event_type":"bookTicker","event_time_ms":1788567718789,"raw_json":"{\"stream\":\"btcusdt@bookTicker\",\"data\":{\"e\":\"bookTicker\",\"u\":11478507535987,\"s\":\"BTCUSDT\",\"ps\":\"BTCUSDT\",\"b\":\"79597.00\",\"B\":\"4.976\",\"a\":\"79597.10\",\"A\":\"7.798\",\"T\":1788567718789,\"E\":1788567718789,\"st\":1}}"}
{"receive_ns":1788567718837291000,"stream":"btcusdt@bookTicker","event_type":"bookTicker","event_time_ms":1788567718790,"raw_json":"{\"stream\":\"btcusdt@bookTicker\",\"data\":{\"e\":\"bookTicker\",\"u\":11478507535999,\"s\":\"BTCUSDT\",\"ps\":\"BTCUSDT\",\"b\":\"79597.00\",\"B\":\"4.977\",\"a\":\"79597.10\",\"A\":\"7.798\",\"T\":1788567718790,\"E\":1788567718790,\"st\":1}}"}
{"receive_ns":1788567718837547000,"stream":"btcusdt@bookTicker","event_type":"bookTicker","event_time_ms":1788567718802,"raw_json":"{\"stream\":\"btcusdt@bookTicker\",\"data\":{\"e\":\"bookTicker\",\"u\":11478507536450,\"s\":\"BTCUSDT\",\"ps\":\"BTCUSDT\",\"b\":\"79597.00\",\"B\":\"4.977\",\"a\":\"79597.10\",\"A\":\"7.800\",\"T\":1788567718802,\"E\":1788567718802,\"st\":1}}"}
{"receive_ns":1788567718837855000,"stream":"btcusdt@depth@100ms","event_type":"depthUpdate","event_time_ms":1788567718839,"raw_json":"{\"stream\":\"btcusdt@depth@100ms\",\"data\":{\"e\":\"depthUpdate\",\"E\":1788567718839,\"T\":1788567718838,\"s\":\"BTCUSDT\",\"ps\":\"BTCUSDT\",\"U\":11478507533818,\"u\":11478507538081,\"pu\":11478507533750,\"b\":[[\"1000.00\",\"24.604\"],[\"29097.00\",\"0.840\"],[\"29497.00\",\"1.260\"],[\"71637.30\",\"0.002\"],[\"76413.10\",\"0.002\"],[\"78426.90\",\"4.707\"],[\"78801.00\",\"10.140\"],[\"79199.00\",\"4.246\"],[\"79563.90\",\"0.004\"],[\"79573.00\",\"0.337\"],[\"79596.90\",\"2.508\"],[\"79597.00\",\"4.977\"]],\"a\":[[\"79597.10\",\"7.800\"],[\"79626.10\",\"0.678\"],[\"80393.10\",\"107.479\"],[\"80950.30\",\"10.548\"]],\"st\":1}}"}
{"receive_ns":1788567718889744000,"stream":"btcusdt@bookTicker","event_type":"bookTicker","event_time_ms":1788567718909,"raw_json":"{\"stream\":\"btcusdt@bookTicker\",\"data\":{\"e\":\"bookTicker\",\"u\":11478507542512,\"s\":\"BTCUSDT\",\"ps\":\"BTCUSDT\",\"b\":\"79597.00\",\"B\":\"4.977\",\"a\":\"79597.10\",\"A\":\"7.799\",\"T\":1788567718909,\"E\":1788567718909,\"st\":1}}"}
{"receive_ns":1788567718900219000,"stream":"btcusdt@trade","event_type":"trade","event_time_ms":1788567718909,"raw_json":"{\"stream\":\"btcusdt@trade\",\"data\":{\"e\":\"trade\",\"E\":1788567718909,\"T\":1788567718909,\"s\":\"BTCUSDT\",\"t\":8054122570,\"p\":\"79597.10\",\"q\":\"0.001\",\"X\":\"MARKET\",\"m\":false,\"st\":1}}"}
{"receive_ns":1788567718918548000,"stream":"btcusdt@bookTicker","event_type":"bookTicker","event_time_ms":1788567718938,"raw_json":"{\"stream\":\"btcusdt@bookTicker\",\"data\":{\"e\":\"bookTicker\",\"u\":11478507543980,\"s\":\"BTCUSDT\",\"ps\":\"BTCUSDT\",\"b\":\"79597.00\",\"B\":\"4.977\",\"a\":\"79597.10\",\"A\":\"7.797\",\"T\":1788567718938,\"E\":1788567718938,\"st\":1}}"}
{"receive_ns":1788567718924082000,"stream":"btcusdt@trade","event_type":"trade","event_time_ms":1788567718938,"raw_json":"{\"stream\":\"btcusdt@trade\",\"data\":{\"e\":\"trade\",\"E\":1788567718938,\"T\":1788567718938,\"s\":\"BTCUSDT\",\"t\":8054122571,\"p\":\"79597.10\",\"q\":\"0.002\",\"X\":\"MARKET\",\"m\":false,\"st\":1}}"}
{"receive_ns":1788567718935417000,"stream":"btcusdt@depth@100ms","event_type":"depthUpdate","event_time_ms":1788567718941,"raw_json":"{\"stream\":\"btcusdt@depth@100ms\",\"data\":{\"e\":\"depthUpdate\",\"E\":1788567718941,\"T\":1788567718940,\"s\":\"BTCUSDT\",\"ps\":\"BTCUSDT\",\"U\":11478507538212,\"u\":11478507544093,\"pu\":11478507538081,\"b\":[[\"29097.00\",\"0.665\"],[\"29497.00\",\"1.435\"],[\"63678.00\",\"0.000\"],[\"71637.30\",\"0.002\"],[\"75617.10\",\"0.031\"],[\"78005.10\",\"10.837\"],[\"78801.00\",\"10.144\"],[\"78880.60\",\"11.074\"],[\"79199.00\",\"4.246\"],[\"79435.90\",\"0.084\"],[\"79436.00\",\"2.593\"],[\"79475.40\",\"0.514\"],[\"79525.30\",\"0.635\"],[\"79541.20\",\"0.000\"],[\"79564.60\",\"0.126\"],[\"79590.10\",\"0.160\"],[\"79591.40\",\"0.007\"],[\"79591.70\",\"0.003\"],[\"79592.60\",\"0.000\"]],\"a\":[[\"79597.10\",\"7.797\"],[\"79668.80\",\"0.035\"],[\"79692.70\",\"0.001\"],[\"79719.60\",\"0.485\"],[\"79759.00\",\"2.306\"],[\"79759.10\",\"11.420\"],[\"79818.70\",\"6.842\"],[\"80313.50\",\"0.941\"],[\"80393.10\",\"107.479\"],[\"80552.30\",\"29.478\"],[\"80711.50\",\"30.576\"]],\"st\":1}}"}
{"receive_ns":1788567719022184000,"stream":"btcusdt@bookTicker","event_type":"bookTicker","event_time_ms":1788567719037,"raw_json":"{\"stream\":\"btcusdt@bookTicker\",\"data\":{\"e\":\"bookTicker\",\"u\":11478507549295,\"s\":\"BTCUSDT\",\"ps\":\"BTCUSDT\",\"b\":\"79597.00\",\"B\":\"4.977\",\"a\":\"79597.10\",\"A\":\"7.796\",\"T\":1788567719036,\"E\":1788567719037,\"st\":1}}"}
{"receive_ns":1788567719027503000,"stream":"btcusdt@trade","event_type":"trade","event_time_ms":1788567719037,"raw_json":"{\"stream\":\"btcusdt@trade\",\"data\":{\"e\":\"trade\",\"E\":1788567719037,\"T\":1788567719036,\"s\":\"BTCUSDT\",\"t\":8054122572,\"p\":\"79597.10\",\"q\":\"0.001\",\"X\":\"MARKET\",\"m\":false,\"st\":1}}"}
{"receive_ns":1788567719033870000,"stream":"btcusdt@bookTicker","event_type":"bookTicker","event_time_ms":1788567719039,"raw_json":"{\"stream\":\"btcusdt@bookTicker\",\"data\":{\"e\":\"bookTicker\",\"u\":11478507549537,\"s\":\"BTCUSDT\",\"ps\":\"BTCUSDT\",\"b\":\"79597.00\",\"B\":\"4.936\",\"a\":\"79597.10\",\"A\":\"7.796\",\"T\":1788567719038,\"E\":1788567719039,\"st\":1}}"}
{"receive_ns":1788567719045739000,"stream":"btcusdt@bookTicker","event_type":"bookTicker","event_time_ms":1788567719039,"raw_json":"{\"stream\":\"btcusdt@bookTicker\",\"data\":{\"e\":\"bookTicker\",\"u\":11478507549623,\"s\":\"BTCUSDT\",\"ps\":\"BTCUSDT\",\"b\":\"79597.00\",\"B\":\"4.920\",\"a\":\"79597.10\",\"A\":\"7.796\",\"T\":1788567719039,\"E\":1788567719039,\"st\":1}}"}
{"receive_ns":1788567719057753000,"stream":"btcusdt@depth@100ms","event_type":"depthUpdate","event_time_ms":1788567719043,"raw_json":"{\"stream\":\"btcusdt@depth@100ms\",\"data\":{\"e\":\"depthUpdate\",\"E\":1788567719043,\"T\":1788567719042,\"s\":\"BTCUSDT\",\"ps\":\"BTCUSDT\",\"U\":11478507544218,\"u\":11478507549870,\"pu\":11478507544093,\"b\":[[\"1000.00\",\"24.604\"],[\"29097.00\",\"0.483\"],[\"29497.00\",\"1.617\"],[\"63678.00\",\"0.000\"],[\"71637.30\",\"0.002\"],[\"75617.10\",\"0.029\"],[\"75617.20\",\"0.012\"],[\"76413.10\",\"0.000\"],[\"78708.10\",\"7.616\"],[\"78801.00\",\"10.140\"],[\"79000.00\",\"42.858\"],[\"79471.20\",\"0.000\"],[\"79471.30\",\"0.003\"],[\"79573.30\",\"0.481\"],[\"79582.70\",\"0.198\"],[\"79595.40\",\"0.038\"],[\"79597.00\",\"4.920\"]],\"a\":[[\"79597.10\",\"7.796\"],[\"79613.20\",\"0.002\"],[\"80194.10\",\"3.738\"],[\"80393.10\",\"107.479\"]],\"st\":1}}"}
{"receive_ns":1788567719598262000,"stream":"btcusdt@depth@100ms","event_type":"depthUpdate","event_time_ms":1788567719145,"raw_json":"{\"stream\":\"btcusdt@depth@100ms\",\"data\":{\"e\":\"depthUpdate\",\"E\":1788567719145,\"T\":1788567719141,\"s\":\"BTCUSDT\",\"ps\":\"BTCUSDT\",\"U\":11478507549957,\"u\":11478507554980,\"pu\":11478507549870,\"b\":[[\"29097.00\",\"0.322\"],[\"29397.00\",\"0.014\"],[\"29497.00\",\"1.764\"],[\"63677.60\",\"0.000\"],[\"63678.00\",\"0.000\"],[\"71637.30\",\"0.002\"],[\"71673.00\",\"0.000\"],[\"76413.10\",\"0.002\"],[\"78005.10\",\"10.834\"],[\"78801.00\",\"10.140\"],[\"79564.60\",\"0.001\"],[\"79564.90\",\"0.000\"],[\"79582.70\",\"0.194\"],[\"79589.30\",\"0.001\"],[\"79593.50\",\"0.000\"]],\"a\":[[\"80393.10\",\"107.479\"],[\"81189.00\",\"10.506\"],[\"81571.80\",\"0.007\"]],\"st\":1}}"}
{"receive_ns":1788567719604505000,"stream":"btcusdt@bookTicker","event_type":"bookTicker","event_time_ms":1788567719196,"raw_json":"{\"stream\":\"btcusdt@bookTicker\",\"data\":{\"e\":\"bookTicker\",\"u\":11478507557570,\"s\":\"BTCUSDT\",\"ps\":\"BTCUSDT\",\"b\":\"79597.00\",\"B\":\"4.920\",\"a\":\"79597.10\",\"A\":\"7.868\",\"T\":1788567719196,\"E\":1788567719196,\"st\":1}}"}
{"receive_ns":1788567719604765000,"stream":"btcusdt@bookTicker","event_type":"bookTicker","event_time_ms":1788567719215,"raw_json":"{\"stream\":\"btcusdt@bookTicker\",\"data\":{\"e\":\"bookTicker\",\"u\":11478507558377,\"s\":\"BTCUSDT\",\"ps\":\"BTCUSDT\",\"b\":\"79597.00\",\"B\":\"4.920\",\"a\":\"79597.10\",\"A\":\"7.870\",\"T\":1788567719214,\"E\":1788567719215,\"st\":1}}"}
{"receive_ns":1788567719610249000,"stream":"btcusdt@bookTicker","event_type":"bookTicker","event_time_ms":1788567719217,"raw_json":"{\"stream\":\"btcusdt@bookTicker\",\"data\":{\"e\":\"bookTicker\",\"u\":11478507558471,\"s\":\"BTCUSDT\",\"ps\":\"BTCUSDT\",\"b\":\"79597.00\",\"B\":\"4.878\",\"a\":\"79597.10\",\"A\":\"7.870\",\"T\":1788567719216,\"E\":1788567719217,\"st\":1}}"}
{"receive_ns":1788567719622911000,"stream":"btcusdt@bookTicker","event_type":"bookTicker","event_time_ms":1788567719220,"raw_json":"{\"stream\":\"btcusdt@bookTicker\",\"data\":{\"e\":\"bookTicker\",\"u\":11478507558685,\"s\":\"BTCUSDT\",\"ps\":\"BTCUSDT\",\"b\":\"79597.00\",\"B\":\"4.878\",\"a\":\"79597.10\",\"A\":\"7.511\",\"T\":1788567719220,\"E\":1788567719220,\"st\":1}}"}
{"receive_ns":1788567719623140000,"stream":"btcusdt@bookTicker","event_type":"bookTicker","event_time_ms":1788567719220,"raw_json":"{\"stream\":\"btcusdt@bookTicker\",\"data\":{\"e\":\"bookTicker\",\"u\":11478507558714,\"s\":\"BTCUSDT\",\"ps\":\"BTCUSDT\",\"b\":\"79597.00\",\"B\":\"4.922\",\"a\":\"79597.10\",\"A\":\"7.511\",\"T\":1788567719220,\"E\":1788567719220,\"st\":1}}"}
{"receive_ns":1788567719635005000,"stream":"btcusdt@trade","event_type":"trade","event_time_ms":1788567719220,"raw_json":"{\"stream\":\"btcusdt@trade\",\"data\":{\"e\":\"trade\",\"E\":1788567719220,\"T\":1788567719220,\"s\":\"BTCUSDT\",\"t\":8054122573,\"p\":\"79597.10\",\"q\":\"0.359\",\"X\":\"MARKET\",\"m\":false,\"st\":1}}"}
{"receive_ns":1788567719635303000,"stream":"btcusdt@bookTicker","event_type":"bookTicker","event_time_ms":1788567719221,"raw_json":"{\"stream\":\"btcusdt@bookTicker\",\"data\":{\"e\":\"bookTicker\",\"u\":11478507558765,\"s\":\"BTCUSDT\",\"ps\":\"BTCUSDT\",\"b\":\"79597.00\",\"B\":\"4.922\",\"a\":\"79597.10\",\"A\":\"7.512\",\"T\":1788567719221,\"E\":1788567719221,\"st\":1}}"}
{"receive_ns":1788567719635540000,"stream":"btcusdt@bookTicker","event_type":"bookTicker","event_time_ms":1788567719221,"raw_json":"{\"stream\":\"btcusdt@bookTicker\",\"data\":{\"e\":\"bookTicker\",\"u\":11478507558784,\"s\":\"BTCUSDT\",\"ps\":\"BTCUSDT\",\"b\":\"79597.00\",\"B\":\"4.922\",\"a\":\"79597.10\",\"A\":\"7.511\",\"T\":1788567719221,\"E\":1788567719221,\"st\":1}}"}
{"receive_ns":1788567719635729000,"stream":"btcusdt@bookTicker","event_type":"bookTicker","event_time_ms":1788567719221,"raw_json":"{\"stream\":\"btcusdt@bookTicker\",\"data\":{\"e\":\"bookTicker\",\"u\":11478507558788,\"s\":\"BTCUSDT\",\"ps\":\"BTCUSDT\",\"b\":\"79597.00\",\"B\":\"4.923\",\"a\":\"79597.10\",\"A\":\"7.511\",\"T\":1788567719221,\"E\":1788567719221,\"st\":1}}"}
{"receive_ns":1788567719642980000,"stream":"btcusdt@depth@100ms","event_type":"depthUpdate","event_time_ms":1788567719247,"raw_json":"{\"stream\":\"btcusdt@depth@100ms\",\"data\":{\"e\":\"depthUpdate\",\"E\":1788567719247,\"T\":1788567719245,\"s\":\"BTCUSDT\",\"ps\":\"BTCUSDT\",\"U\":11478507555150,\"u\":11478507560040,\"pu\":11478507554980,\"b\":[[\"29097.00\",\"0.203\"],[\"29397.00\",\"0.077\"],[\"29497.00\",\"1.820\"],[\"71637.30\",\"0.002\"],[\"75617.10\",\"0.031\"],[\"76413.10\",\"0.000\"],[\"78005.10\",\"10.831\"],[\"78562.20\",\"14.843\"],[\"78801.00\",\"10.140\"],[\"79199.00\",\"4.246\"],[\"79475.40\",\"0.514\"],[\"79511.00\",\"0.035\"],[\"79541.20\",\"0.002\"],[\"79564.80\",\"1.136\"],[\"79583.60\",\"1.357\"],[\"79587.00\",\"0.809\"],[\"79589.00\",\"0.450\"],[\"79591.00\",\"0.076\"],[\"79593.30\",\"0.026\"],[\"79593.90\",\"0.000\"],[\"79597.00\",\"4.923\"]],\"a\":[[\"79597.10\",\"7.511\"],[\"79601.20\",\"0.252\"],[\"79605.00\",\"0.051\"],[\"79605.10\",\"0.213\"],[\"79605.40\",\"0.080\"],[\"79607.90\",\"0.004\"],[\"79625.70\",\"0.009\"],[\"79691.80\",\"0.124\"],[\"79692.70\",\"0.003\"],[\"79719.60\",\"0.485\"],[\"79806.80\",\"2.683\"],[\"80194.10\",\"3.115\"],[\"80393.10\",\"107.479\"]],\"st\":1}}"}
{"receive_ns":1788567719643268000,"stream":"btcusdt@bookTicker","event_type":"bookTicker","event_time_ms":1788567719248,"raw_json":"{\"stream\":\"btcusdt@bookTicker\",\"data\":{\"e\":\"bookTicker\",\"u\":11478507560150,\"s\":\"BTCUSDT\",\"ps\":\"BTCUSDT\",\"b\":\"79597.00\",\"B\":\"4.127\",\"a\":\"79597.10\",\"A\":\"7.511\",\"T\":1788567719248,\"E\":1788567719248,\"st\":1}}"}
{"receive_ns":1788567719643476000,"stream":"btcusdt@bookTicker","event_type":"bookTicker","event_time_ms":1788567719249,"raw_json":"{\"stream\":\"btcusdt@bookTicker\",\"data\":{\"e\":\"bookTicker\",\"u\":11478507560233,\"s\":\"BTCUSDT\",\"ps\":\"BTCUSDT\",\"b\":\"79597.00\",\"B\":\"4.127\",\"a\":\"79597.10\",\"A\":\"7.510\",\"T\":1788567719249,\"E\":1788567719249,\"st\":1}}"}
{"receive_ns":1788567719643648000,"stream":"btcusdt@bookTicker","event_type":"bookTicker","event_time_ms":1788567719249,"raw_json":"{\"stream\":\"btcusdt@bookTicker\",\"data\":{\"e\":\"bookTicker\",\"u\":11478507560236,\"s\":\"BTCUSDT\",\"ps\":\"BTCUSDT\",\"b\":\"79597.00\",\"B\":\"4.126\",\"a\":\"79597.10\",\"A\":\"7.510\",\"T\":1788567719249,\"E\":1788567719249,\"st\":1}}"}
{"receive_ns":1788567719649016000,"stream":"btcusdt@bookTicker","event_type":"bookTicker","event_time_ms":1788567719257,"raw_json":"{\"stream\":\"btcusdt@bookTicker\",\"data\":{\"e\":\"bookTicker\",\"u\":11478507560575,\"s\":\"BTCUSDT\",\"ps\":\"BTCUSDT\",\"b\":\"79597.00\",\"B\":\"4.965\",\"a\":\"79597.10\",\"A\":\"7.510\",\"T\":1788567719257,\"E\":1788567719257,\"st\":1}}"}
{"receive_ns":1788567719654804000,"stream":"btcusdt@bookTicker","event_type":"bookTicker","event_time_ms":1788567719258,"raw_json":"{\"stream\":\"btcusdt@bookTicker\",\"data\":{\"e\":\"bookTicker\",\"u\":11478507560636,\"s\":\"BTCUSDT\",\"ps\":\"BTCUSDT\",\"b\":\"79597.00\",\"B\":\"4.964\",\"a\":\"79597.10\",\"A\":\"7.510\",\"T\":1788567719258,\"E\":1788567719258,\"st\":1}}"}
{"receive_ns":1788567719660326000,"stream":"btcusdt@bookTicker","event_type":"bookTicker","event_time_ms":1788567719300,"raw_json":"{\"stream\":\"btcusdt@bookTicker\",\"data\":{\"e\":\"bookTicker\",\"u\":11478507561892,\"s\":\"BTCUSDT\",\"ps\":\"BTCUSDT\",\"b\":\"79597.00\",\"B\":\"4.840\",\"a\":\"79597.10\",\"A\":\"7.510\",\"T\":1788567719299,\"E\":1788567719300,\"st\":1}}"}
{"receive_ns":1788567719666030000,"stream":"btcusdt@bookTicker","event_type":"bookTicker","event_time_ms":1788567719302,"raw_json":"{\"stream\":\"btcusdt@bookTicker\",\"data\":{\"e\":\"bookTicker\",\"u\":11478507562016,\"s\":\"BTCUSDT\",\"ps\":\"BTCUSDT\",\"b\":\"79597.00\",\"B\":\"4.962\",\"a\":\"79597.10\",\"A\":\"7.510\",\"T\":1788567719302,\"E\":1788567719302,\"st\":1}}"}
{"receive_ns":1788567719675357000,"stream":"btcusdt@bookTicker","event_type":"bookTicker","event_time_ms":1788567719304,"raw_json":"{\"stream\":\"btcusdt@bookTicker\",\"data\":{\"e\":\"bookTicker\",\"u\":11478507562049,\"s\":\"BTCUSDT\",\"ps\":\"BTCUSDT\",\"b\":\"79597.00\",\"B\":\"4.963\",\"a\":\"79597.10\",\"A\":\"7.510\",\"T\":1788567719304,\"E\":1788567719304,\"st\":1}}"}
{"receive_ns":1788567719681403000,"stream":"btcusdt@depth@100ms","event_type":"depthUpdate","event_time_ms":1788567719349,"raw_json":"{\"stream\":\"btcusdt@depth@100ms\",\"data\":{\"e\":\"depthUpdate\",\"E\":1788567719349,\"T\":1788567719345,\"s\":\"BTCUSDT\",\"ps\":\"BTCUSDT\",\"U\":11478507560140,\"u\":11478507564031,\"pu\":11478507560040,\"b\":[[\"1000.00\",\"24.604\"],[\"29097.00\",\"0.084\"],[\"29397.00\",\"0.133\"],[\"29497.00\",\"1.883\"],[\"71637.30\",\"0.002\"],[\"78621.70\",\"0.001\"],[\"78801.00\",\"10.140\"],[\"79543.90\",\"0.295\"],[\"79559.80\",\"0.001\"],[\"79564.80\",\"1.136\"],[\"79593.60\",\"0.029\"],[\"79597.00\",\"4.963\"]],\"a\":[[\"79597.10\",\"7.510\"],[\"79610.60\",\"0.003\"],[\"79626.60\",\"0.005\"],[\"80194.10\",\"2.492\"],[\"80393.10\",\"107.479\"],[\"80565.60\",\"10.540\"],[\"81189.00\",\"10.509\"]],\"st\":1}}"}
{"receive_ns":1788567719692414000,"stream":"btcusdt@bookTicker","event_type":"bookTicker","event_time_ms":1788567719354,"raw_json":"{\"stream\":\"btcusdt@bookTicker\",\"data\":{\"e\":\"bookTicker\",\"u\":11478507564274,\"s\":\"BTCUSDT\",\"ps\":\"BTCUSDT\",\"b\":\"79597.00\",\"B\":\"4.963\",\"a\":\"79597.10\",\"A\":\"7.508\",\"T\":1788567719354,\"E\":1788567719354,\"st\":1}}"}
{"receive_ns":1788567719703262000,"stream":"btcusdt@trade","event_type":"trade","event_time_ms":1788567719354,"raw_json":"{\"stream\":\"btcusdt@trade\",\"data\":{\"e\":\"trade\",\"E\":1788567719354,\"T\":1788567719354,\"s\":\"BTCUSDT\",\"t\":8054122574,\"p\":\"79597.10\",\"q\":\"0.002\",\"X\":\"MARKET\",\"m\":false,\"st\":1}}"}
{"receive_ns":1788567719711628000,"stream":"btcusdt@bookTicker","event_type":"bookTicker","event_time_ms":1788567719367,"raw_json":"{\"stream\":\"btcusdt@bookTicker\",\"data\":{\"e\":\"bookTicker\",\"u\":11478507564950,\"s\":\"BTCUSDT\",\"ps\":\"BTCUSDT\",\"b\":\"79597.00\",\"B\":\"5.004\",\"a\":\"79597.10\",\"A\":\"7.508\",\"T\":1788567719367,\"E\":1788567719367,\"st\":1}}"}
{"receive_ns":1788567719717509000,"stream":"btcusdt@bookTicker","event_type":"bookTicker","event_time_ms":1788567719422,"raw_json":"{\"stream\":\"btcusdt@bookTicker\",\"data\":{\"e\":\"bookTicker\",\"u\":11478507566860,\"s\":\"BTCUSDT\",\"ps\":\"BTCUSDT\",\"b\":\"79597.00\",\"B\":\"4.944\",\"a\":\"79597.10\",\"A\":\"7.508\",\"T\":1788567719422,\"E\":1788567719422,\"st\":1}}"}
{"receive_ns":1788567719728456000,"stream":"btcusdt@bookTicker","event_type":"bookTicker","event_time_ms":1788567719425,"raw_json":"{\"stream\":\"btcusdt@bookTicker\",\"data\":{\"e\":\"bookTicker\",\"u\":11478507566986,\"s\":\"BTCUSDT\",\"ps\":\"BTCUSDT\",\"b\":\"79597.00\",\"B\":\"5.003\",\"a\":\"79597.10\",\"A\":\"7.508\",\"T\":1788567719425,\"E\":1788567719425,\"st\":1}}"}
{"receive_ns":1788567719735957000,"stream":"btcusdt@depth@100ms","event_type":"depthUpdate","event_time_ms":1788567719451,"raw_json":"{\"stream\":\"btcusdt@depth@100ms\",\"data\":{\"e\":\"depthUpdate\",\"E\":1788567719451,\"T\":1788567719449,\"s\":\"BTCUSDT\",\"ps\":\"BTCUSDT\",\"U\":11478507564137,\"u\":11478507567805,\"pu\":11478507564031,\"b\":[[\"29097.00\",\"0.000\"],[\"29397.00\",\"0.231\"],[\"29497.00\",\"1.869\"],[\"71637.30\",\"0.002\"],[\"76413.10\",\"0.002\"],[\"78801.00\",\"10.140\"],[\"79591.30\",\"0.100\"],[\"79593.90\",\"0.026\"],[\"79596.90\",\"2.528\"],[\"79597.00\",\"5.003\"]],\"a\":[[\"79597.10\",\"7.508\"],[\"79995.10\",\"4.365\"],[\"80393.10\",\"107.479\"]],\"st\":1}}"}
{"receive_ns":1788567719748020000,"stream":"btcusdt@bookTicker","event_type":"bookTicker","event_time_ms":1788567719464,"raw_json":"{\"stream\":\"btcusdt@bookTicker\",\"data\":{\"e\":\"bookTicker\",\"u\":11478507568343,\"s\":\"BTCUSDT\",\"ps\":\"BTCUSDT\",\"b\":\"79597.00\",\"B\":\"4.980\",\"a\":\"79597.10\",\"A\":\"7.508\",\"T\":1788567719464,\"E\":1788567719464,\"st\":1}}"}
{"receive_ns":1788567719754290000,"stream":"btcusdt@bookTicker","event_type":"bookTicker","event_time_ms":1788567719468,"raw_json":"{\"stream\":\"btcusdt@bookTicker\",\"data\":{\"e\":\"bookTicker\",\"u\":11478507568466,\"s\":\"BTCUSDT\",\"ps\":\"BTCUSDT\",\"b\":\"79597.00\",\"B\":\"5.003\",\"a\":\"79597.10\",\"A\":\"7.508\",\"T\":1788567719468,\"E\":1788567719468,\"st\":1}}"}
{"receive_ns":1788567719760651000,"stream":"btcusdt@depth@100ms","event_type":"depthUpdate","event_time_ms":1788567719553,"raw_json":"{\"stream\":\"btcusdt@depth@100ms\",\"data\":{\"e\":\"depthUpdate\",\"E\":1788567719553,\"T\":1788567719550,\"s\":\"BTCUSDT\",\"ps\":\"BTCUSDT\",\"U\":11478507567885,\"u\":11478507571674,\"pu\":11478507567805,\"b\":[[\"29397.00\",\"0.406\"],[\"29497.00\",\"1.694\"],[\"71637.30\",\"0.002\"],[\"76413.10\",\"0.000\"],[\"78801.00\",\"10.140\"],[\"79199.00\",\"4.247\"],[\"79597.00\",\"5.003\"]],\"a\":[[\"80393.10\",\"107.479\"],[\"80577.80\",\"3.507\"],[\"81189.00\",\"10.512\"]],\"st\":1}}"}
{"receive_ns":1788567719766555000,"stream":"btcusdt@bookTicker","event_type":"bookTicker","event_time_ms":1788567719651,"raw_json":"{\"stream\":\"btcusdt@bookTicker\",\"data\":{\"e\":\"bookTicker\",\"u\":11478507576863,\"s\":\"BTCUSDT\",\"ps\":\"BTCUSDT\",\"b\":\"79597.00\",\"B\":\"5.003\",\"a\":\"79597.10\",\"A\":\"7.527\",\"T\":1788567719651,\"E\":1788567719651,\"st\":1}}"}
{"receive_ns":1788567719772819000,"stream":"btcusdt@bookTicker","event_type":"bookTicker","event_time_ms":1788567719653,"raw_json":"{\"stream\":\"btcusdt@bookTicker\",\"data\":{\"e\":\"bookTicker\",\"u\":11478507576909,\"s\":\"BTCUSDT\",\"ps\":\"BTCUSDT\",\"b\":\"79597.00\",\"B\":\"5.003\",\"a\":\"79597.10\",\"A\":\"7.525\",\"T\":1788567719652,\"E\":1788567719653,\"st\":1}}"}
{"receive_ns":1788567719784541000,"stream":"btcusdt@depth@100ms","event_type":"depthUpdate","event_time_ms":1788567719655,"raw_json":"{\"stream\":\"btcusdt@depth@100ms\",\"data\":{\"e\":\"depthUpdate\",\"E\":1788567719655,\"T\":1788567719654,\"s\":\"BTCUSDT\",\"ps\":\"BTCUSDT\",\"U\":11478507572202,\"u\":11478507576971,\"pu\":11478507571674,\"b\":[[\"1000.00\",\"24.604\"],[\"29397.00\",\"0.588\"],[\"29497.00\",\"1.512\"],[\"63678.00\",\"0.000\"],[\"71637.30\",\"0.002\"],[\"76413.10\",\"0.002\"],[\"78801.00\",\"10.140\"],[\"79436.00\",\"0.000\"],[\"79475.40\",\"0.000\"],[\"79512.70\",\"0.001\"],[\"79522.00\",\"0.007\"],[\"79534.50\",\"4.523\"],[\"79539.60\",\"0.028\"],[\"79564.80\",\"1.011\"],[\"79591.60\",\"0.000\"],[\"79591.80\",\"0.000\"],[\"79593.20\",\"0.026\"],[\"79593.90\",\"0.000\"],[\"79594.00\",\"0.000\"],[\"79594.40\",\"0.000\"]],\"a\":[[\"79597.10\",\"7.525\"],[\"79601.20\",\"0.000\"],[\"79719.60\",\"0.001\"],[\"79759.00\",\"0.095\"],[\"79818.70\",\"0.000\"],[\"79818.80\",\"6.852\"],[\"80006.50\",\"0.478\"],[\"80393.10\",\"107.481\"],[\"80577.80\",\"3.358\"],[\"80677.80\",\"0.000\"]],\"st\":1}}"}
{"receive_ns":1788567719795879000,"stream":"btcusdt@bookTicker","event_type":"bookTicker","event_time_ms":1788567719688,"raw_json":"{\"stream\":\"btcusdt@bookTicker\",\"data\":{\"e\":\"bookTicker\",\"u\":11478507578340,\"s\":\"BTCUSDT\",\"ps\":\"BTCUSDT\",\"b\":\"79597.00\",\"B\":\"4.987\",\"a\":\"79597.10\",\"A\":\"7.525\",\"T\":1788567719688,\"E\":1788567719688,\"st\":1}}"}
{"receive_ns":1788567719804065000,"stream":"btcusdt@bookTicker","event_type":"bookTicker","event_time_ms":1788567719714,"raw_json":"{\"stream\":\"btcusdt@bookTicker\",\"data\":{\"e\":\"bookTicker\",\"u\":11478507579403,\"s\":\"BTCUSDT\",\"ps\":\"BTCUSDT\",\"b\":\"79597.00\",\"B\":\"5.003\",\"a\":\"79597.10\",\"A\":\"7.525\",\"T\":1788567719714,\"E\":1788567719714,\"st\":1}}"}
{"receive_ns":1788567719810257000,"stream":"btcusdt@bookTicker","event_type":"bookTicker","event_time_ms":1788567719715,"raw_json":"{\"stream\":\"btcusdt@bookTicker\",\"data\":{\"e\":\"bookTicker\",\"u\":11478507579432,\"s\":\"BTCUSDT\",\"ps\":\"BTCUSDT\",\"b\":\"79597.00\",\"B\":\"5.003\",\"a\":\"79597.10\",\"A\":\"7.527\",\"T\":1788567719714,\"E\":1788567719715,\"st\":1}}"}
{"receive_ns":1788567719815875000,"stream":"btcusdt@depth@100ms","event_type":"depthUpdate","event_time_ms":1788567719757,"raw_json":"{\"stream\":\"btcusdt@depth@100ms\",\"data\":{\"e\":\"depthUpdate\",\"E\":1788567719757,\"T\":1788567719756,\"s\":\"BTCUSDT\",\"ps\":\"BTCUSDT\",\"U\":11478507576993,\"u\":11478507581173,\"pu\":11478507576971,\"b\":[[\"29397.00\",\"0.763\"],[\"29497.00\",\"1.337\"],[\"71637.30\",\"0.002\"],[\"75617.20\",\"0.010\"],[\"76413.10\",\"0.000\"],[\"78801.00\",\"10.140\"],[\"78858.30\",\"0.007\"],[\"79388.20\",\"5.503\"],[\"79436.00\",\"2.665\"],[\"79475.40\",\"0.531\"],[\"79543.50\",\"0.829\"],[\"79559.40\",\"0.730\"],[\"79570.10\",\"0.453\"],[\"79570.80\",\"0.024\"],[\"79573.30\",\"0.042\"],[\"79574.60\",\"0.497\"],[\"79575.70\",\"0.002\"],[\"79576.10\",\"0.003\"],[\"79576.80\",\"0.375\"],[\"79578.00\",\"0.701\"],[\"79589.90\",\"0.076\"],[\"79591.00\",\"0.000\"],[\"79591.70\",\"0.029\"],[\"79591.80\",\"0.026\"],[\"79593.30\",\"0.000\"],[\"79593.60\",\"0.003\"],[\"79596.90\",\"2.546\"],[\"79597.00\",\"5.003\"]],\"a\":[[\"79597.10\",\"7.527\"],[\"79610.60\",\"0.694\"],[\"79610.70\",\"0.543\"],[\"79610.90\",\"0.003\"],[\"79612.80\",\"0.003\"],[\"79619.90\",\"0.452\"],[\"79620.30\",\"0.019\"],[\"79621.20\",\"0.000\"],[\"79625.70\",\"0.003\"],[\"79626.60\",\"0.834\"],[\"79657.60\",\"0.035\"],[\"79719.60\",\"0.485\"],[\"79759.00\",\"2.255\"],[\"79804.90\",\"1.028\"],[\"79806.80\",\"2.809\"],[\"80313.60\",\"2.115\"],[\"80393.10\",\"107.479\"]],\"st\":1}}"}
{"receive_ns":1788567719826795000,"stream":"btcusdt@bookTicker","event_type":"bookTicker","event_time_ms":1788567719760,"raw_json":"{\"stream\":\"btcusdt@bookTicker\",\"data\":{\"e\":\"bookTicker\",\"u\":11478507581293,\"s\":\"BTCUSDT\",\"ps\":\"BTCUSDT\",\"b\":\"79597.00\",\"B\":\"5.015\",\"a\":\"79597.10\",\"A\":\"7.527\",\"T\":1788567719760,\"E\":1788567719760,\"st\":1}}"}
{"receive_ns":1788567719827027000,"stream":"btcusdt@bookTicker","event_type":"bookTicker","event_time_ms":1788567719762,"raw_json":"{\"stream\":\"btcusdt@bookTicker\",\"data\":{\"e\":\"bookTicker\",\"u\":11478507581329,\"s\":\"BTCUSDT\",\"ps\":\"BTCUSDT\",\"b\":\"79597.00\",\"B\":\"5.014\",\"a\":\"79597.10\",\"A\":\"7.527\",\"T\":1788567719761,\"E\":1788567719762,\"st\":1}}"}
{"receive_ns":1788567719827305000,"stream":"btcusdt@bookTicker","event_type":"bookTicker","event_time_ms":1788567719818,"raw_json":"{\"stream\":\"btcusdt@bookTicker\",\"data\":{\"e\":\"bookTicker\",\"u\":11478507583505,\"s\":\"BTCUSDT\",\"ps\":\"BTCUSDT\",\"b\":\"79597.00\",\"B\":\"5.014\",\"a\":\"79597.10\",\"A\":\"7.536\",\"T\":1788567719817,\"E\":1788567719818,\"st\":1}}"}
{"receive_ns":1788567719842896000,"stream":"btcusdt@depth@100ms","event_type":"depthUpdate","event_time_ms":1788567719859,"raw_json":"{\"stream\":\"btcusdt@depth@100ms\",\"data\":{\"e\":\"depthUpdate\",\"E\":1788567719859,\"T\":1788567719857,\"s\":\"BTCUSDT\",\"ps\":\"BTCUSDT\",\"U\":11478507581227,\"u\":11478507584905,\"pu\":11478507581173,\"b\":[[\"29397.00\",\"0.945\"],[\"29497.00\",\"1.155\"],[\"71637.30\",\"0.002\"],[\"75617.20\",\"0.008\"],[\"78801.00\",\"10.140\"],[\"79199.00\",\"4.246\"],[\"79597.00\",\"5.014\"]],\"a\":[[\"79597.10\",\"7.536\"],[\"79601.10\",\"0.221\"],[\"79995.10\",\"4.366\"],[\"80297.40\",\"0.001\"],[\"80393.10\",\"107.479\"],[\"80679.70\",\"0.000\"],[\"80727.40\",\"2.376\"],[\"80966.20\",\"1.110\"]],\"st\":1}}"}
{"receive_ns":1788567719917456000,"stream":"btcusdt@bookTicker","event_type":"bookTicker","event_time_ms":1788567719938,"raw_json":"{\"stream\":\"btcusdt@bookTicker\",\"data\":{\"e\":\"bookTicker\",\"u\":11478507587851,\"s\":\"BTCUSDT\",\"ps\":\"BTCUSDT\",\"b\":\"79597.00\",\"B\":\"5.014\",\"a\":\"79597.10\",\"A\":\"7.537\",\"T\":1788567719937,\"E\":1788567719938,\"st\":1}}"}
{"receive_ns":1788567719941021000,"stream":"btcusdt@depth@100ms","event_type":"depthUpdate","event_time_ms":1788567719961,"raw_json":"{\"stream\":\"btcusdt@depth@100ms\",\"data\":{\"e\":\"depthUpdate\",\"E\":1788567719961,\"T\":1788567719959,\"s\":\"BTCUSDT\",\"ps\":\"BTCUSDT\",\"U\":11478507584977,\"u\":11478507588608,\"pu\":11478507584905,\"b\":[[\"1000.00\",\"24.604\"],[\"29397.00\",\"1.120\"],[\"29497.00\",\"0.980\"],[\"71637.30\",\"0.002\"],[\"76413.10\",\"0.002\"],[\"78468.70\",\"8.551\"],[\"78801.00\",\"10.142\"],[\"78994.30\",\"0.000\"],[\"79017.50\",\"0.000\"],[\"79568.90\",\"0.454\"],[\"79570.10\",\"0.001\"],[\"79573.30\",\"0.481\"],[\"79574.60\",\"0.058\"],[\"79575.90\",\"0.408\"],[\"79576.80\",\"0.002\"],[\"79578.80\",\"0.000\"],[\"79591.20\",\"0.082\"],[\"79593.40\",\"0.027\"]],\"a\":[[\"79597.10\",\"7.537\"],[\"79615.80\",\"0.372\"],[\"79617.50\",\"0.000\"],[\"79818.80\",\"6.854\"],[\"80165.00\",\"0.316\"],[\"80393.10\",\"107.479\"],[\"80719.40\",\"4.328\"],[\"81800.00\",\"13.975\"],[\"83000.00\",\"92.091\"]],\"st\":1}}"}
{"receive_ns":1788567719986428000,"stream":"btcusdt@bookTicker","event_type":"bookTicker","event_time_ms":1788567720008,"raw_json":"{\"stream\":\"btcusdt@bookTicker\",\"data\":{\"e\":\"bookTicker\",\"u\":11478507592809,\"s\":\"BTCUSDT\",\"ps\":\"BTCUSDT\",\"b\":\"79597.00\",\"B\":\"5.002\",\"a\":\"79597.10\",\"A\":\"7.537\",\"T\":1788567720008,\"E\":1788567720008,\"st\":1}}"}
{"receive_ns":1788567720025475000,"stream":"btcusdt@bookTicker","event_type":"bookTicker","event_time_ms":1788567720044,"raw_json":"{\"stream\":\"btcusdt@bookTicker\",\"data\":{\"e\":\"bookTicker\",\"u\":11478507596069,\"s\":\"BTCUSDT\",\"ps\":\"BTCUSDT\",\"b\":\"79597.00\",\"B\":\"5.002\",\"a\":\"79597.10\",\"A\":\"7.536\",\"T\":1788567720044,\"E\":1788567720044,\"st\":1}}"}
{"receive_ns":1788567720025725000,"stream":"btcusdt@trade","event_type":"trade","event_time_ms":1788567720044,"raw_json":"{\"stream\":\"btcusdt@trade\",\"data\":{\"e\":\"trade\",\"E\":1788567720044,\"T\":1788567720044,\"s\":\"BTCUSDT\",\"t\":8054122575,\"p\":\"79597.10\",\"q\":\"0.001\",\"X\":\"MARKET\",\"m\":false,\"st\":1}}"}
{"receive_ns":1788567720031125000,"stream":"btcusdt@bookTicker","event_type":"bookTicker","event_time_ms":1788567720045,"raw_json":"{\"stream\":\"btcusdt@bookTicker\",\"data\":{\"e\":\"bookTicker\",\"u\":11478507596156,\"s\":\"BTCUSDT\",\"ps\":\"BTCUSDT\",\"b\":\"79597.00\",\"B\":\"5.002\",\"a\":\"79597.10\",\"A\":\"7.538\",\"T\":1788567720045,\"E\":1788567720045,\"st\":1}}"}
{"receive_ns":1788567720038025000,"stream":"btcusdt@depth@100ms","event_type":"depthUpdate","event_time_ms":1788567720063,"raw_json":"{\"stream\":\"btcusdt@depth@100ms\",\"data\":{\"e\":\"depthUpdate\",\"E\":1788567720063,\"T\":1788567720062,\"s\":\"BTCUSDT\",\"ps\":\"BTCUSDT\",\"U\":11478507588651,\"u\":11478507597704,\"pu\":11478507588608,\"b\":[[\"29397.00\",\"1.302\"],[\"29497.00\",\"0.798\"],[\"63678.00\",\"0.000\"],[\"71637.30\",\"0.002\"],[\"76413.10\",\"0.000\"],[\"78801.00\",\"10.140\"],[\"79012.70\",\"0.254\"],[\"79199.00\",\"4.246\"],[\"79542.70\",\"0.001\"],[\"79565.10\",\"0.858\"],[\"79565.40\",\"0.026\"],[\"79566.50\",\"0.003\"],[\"79567.00\",\"0.254\"],[\"79567.60\",\"0.046\"],[\"79568.10\",\"3.315\"],[\"79570.50\",\"0.002\"],[\"79572.10\",\"0.629\"],[\"79573.30\",\"0.042\"],[\"79574.50\",\"0.001\"],[\"79574.60\",\"0.052\"],[\"79574.70\",\"0.001\"],[\"79574.80\",\"0.440\"],[\"79575.90\",\"0.035\"],[\"79576.10\",\"0.637\"],[\"79577.00\",\"0.374\"],[\"79577.10\",\"0.082\"],[\"79582.70\",\"0.194\"],[\"79583.90\",\"1.654\"],[\"79584.80\",\"0.255\"],[\"79586.90\",\"0.001\"],[\"79587.70\",\"0.004\"],[\"79591.20\",\"0.006\"],[\"79591.40\",\"0.003\"],[\"79591.60\",\"0.026\"],[\"79592.00\",\"0.035\"],[\"79593.20\",\"0.000\"],[\"79593.40\",\"0.001\"],[\"79597.00\",\"5.002\"]],\"a\":[[\"79597.10\",\"7.538\"],[\"79597.30\",\"0.100\"],[\"79597.90\",\"0.002\"],[\"79598.00\",\"0.081\"],[\"79610.70\",\"0.104\"],[\"79610.90\",\"0.442\"],[\"79612.30\",\"0.003\"],[\"79612.90\",\"0.556\"],[\"79613.20\",\"0.002\"],[\"79615.80\",\"0.000\"],[\"79616.00\",\"0.637\"],[\"79616.30\",\"0.013\"],[\"79616.60\",\"0.051\"],[\"79617.10\",\"0.372\"],[\"79620.00\",\"0.773\"],[\"79620.70\",\"0.027\"],[\"79623.70\",\"0.000\"],[\"79623.80\",\"0.629\"],[\"79623.90\",\"0.637\"],[\"79631.70\",\"0.046\"],[\"79631.90\",\"0.000\"],[\"79660.40\",\"5.665\"],[\"79661.80\",\"2.761\"],[\"79669.80\",\"0.000\"],[\"79829.40\",\"0.000\"],[\"79829.50\",\"0.004\"],[\"80393.10\",\"107.479\"],[\"80535.10\",\"3.357\"],[\"80910.50\",\"3.296\"],[\"81811.30\",\"0.000\"]],\"st\":1}}"}
{"receive_ns":1788567720089737000,"stream":"btcusdt@bookTicker","event_type":"bookTicker","event_time_ms":1788567720102,"raw_json":"{\"stream\":\"btcusdt@bookTicker\",\"data\":{\"e\":\"bookTicker\",\"u\":11478507601209,\"s\":\"BTCUSDT\",\"ps\":\"BTCUSDT\",\"b\":\"79597.00\",\"B\":\"5.002\",\"a\":\"79597.10\",\"A\":\"7.553\",\"T\":1788567720102,\"E\":1788567720102,\"st\":1}}"}
{"receive_ns":1788567720101573000,"stream":"btcusdt@bookTicker","event_type":"bookTicker","event_time_ms":1788567720103,"raw_json":"{\"stream\":\"btcusdt@bookTicker\",\"data\":{\"e\":\"bookTicker\",\"u\":11478507601294,\"s\":\"BTCUSDT\",\"ps\":\"BTCUSDT\",\"b\":\"79597.00\",\"B\":\"5.003\",\"a\":\"79597.10\",\"A\":\"7.553\",\"T\":1788567720103,\"E\":1788567720103,\"st\":1}}"}
{"receive_ns":1788567720113263000,"stream":"btcusdt@bookTicker","event_type":"bookTicker","event_time_ms":1788567720139,"raw_json":"{\"stream\":\"btcusdt@bookTicker\",\"data\":{\"e\":\"bookTicker\",\"u\":11478507604335,\"s\":\"BTCUSDT\",\"ps\":\"BTCUSDT\",\"b\":\"79597.00\",\"B\":\"5.005\",\"a\":\"79597.10\",\"A\":\"7.553\",\"T\":1788567720139,\"E\":1788567720139,\"st\":1}}"}
{"receive_ns":1788567720129307000,"stream":"btcusdt@bookTicker","event_type":"bookTicker","event_time_ms":1788567720145,"raw_json":"{\"stream\":\"btcusdt@bookTicker\",\"data\":{\"e\":\"bookTicker\",\"u\":11478507604738,\"s\":\"BTCUSDT\",\"ps\":\"BTCUSDT\",\"b\":\"79597.00\",\"B\":\"5.005\",\"a\":\"79597.10\",\"A\":\"7.554\",\"T\":1788567720144,\"E\":1788567720145,\"st\":1}}"}
{"receive_ns":1788567720141170000,"stream":"btcusdt@bookTicker","event_type":"bookTicker","event_time_ms":1788567720152,"raw_json":"{\"stream\":\"btcusdt@bookTicker\",\"data\":{\"e\":\"bookTicker\",\"u\":11478507605228,\"s\":\"BTCUSDT\",\"ps\":\"BTCUSDT\",\"b\":\"79597.00\",\"B\":\"5.005\",\"a\":\"79597.10\",\"A\":\"7.562\",\"T\":1788567720152,\"E\":1788567720152,\"st\":1}}"}
{"receive_ns":1788567720143554000,"stream":"btcusdt@depth@100ms","event_type":"depthUpdate","event_time_ms":1788567720165,"raw_json":"{\"stream\":\"btcusdt@depth@100ms\",\"data\":{\"e\":\"depthUpdate\",\"E\":1788567720165,\"T\":1788567720161,\"s\":\"BTCUSDT\",\"ps\":\"BTCUSDT\",\"U\":11478507597871,\"u\":11478507606034,\"pu\":11478507597704,\"b\":[[\"1000.00\",\"24.604\"],[\"29397.00\",\"1.477\"],[\"29497.00\",\"0.623\"],[\"63677.60\",\"0.000\"],[\"63678.00\",\"0.000\"],[\"71637.30\",\"0.002\"],[\"76413.10\",\"0.002\"],[\"78383.30\",\"0.199\"],[\"78384.20\",\"0.003\"],[\"78384.90\",\"0.000\"],[\"78588.10\",\"7.208\"],[\"78801.00\",\"10.140\"],[\"79449.90\",\"2.112\"],[\"79450.30\",\"1.560\"],[\"79525.30\",\"0.633\"],[\"79541.20\",\"0.002\"],[\"79564.50\",\"0.002\"],[\"79564.70\",\"0.728\"],[\"79573.30\",\"0.481\"],[\"79574.80\",\"0.001\"],[\"79574.90\",\"0.000\"],[\"79583.90\",\"1.264\"],[\"79584.00\",\"0.012\"],[\"79584.40\",\"0.261\"],[\"79584.70\",\"2.557\"],[\"79584.80\",\"0.390\"],[\"79584.90\",\"0.008\"],[\"79587.90\",\"0.984\"],[\"79591.60\",\"0.000\"],[\"79591.80\",\"0.030\"],[\"79592.00\",\"0.031\"],[\"79592.60\",\"0.026\"],[\"79592.90\",\"0.028\"],[\"79593.70\",\"0.000\"],[\"79597.00\",\"5.005\"]],\"a\":[[\"79597.10\",\"7.562\"],[\"79605.40\",\"0.080\"],[\"79607.90\",\"0.004\"],[\"79616.30\",\"0.013\"],[\"79623.80\",\"0.629\"],[\"79668.80\",\"0.035\"],[\"79692.70\",\"0.001\"],[\"80233.90\",\"7.339\"],[\"80393.10\",\"107.479\"],[\"80845.10\",\"0.003\"],[\"80845.80\",\"0.000\"],[\"81189.00\",\"10.515\"]],\"st\":1}}"}
{"receive_ns":1788567720187928000,"stream":"btcusdt@bookTicker","event_type":"bookTicker","event_time_ms":1788567720200,"raw_json":"{\"stream\":\"btcusdt@bookTicker\",\"data\":{\"e\":\"bookTicker\",\"u\":11478507608701,\"s\":\"BTCUSDT\",\"ps\":\"BTCUSDT\",\"b\":\"79597.00\",\"B\":\"5.005\",\"a\":\"79597.10\",\"A\":\"7.563\",\"T\":1788567720200,\"E\":1788567720200,\"st\":1}}"}
{"receive_ns":1788567720233154000,"stream":"btcusdt@bookTicker","event_type":"bookTicker","event_time_ms":1788567720253,"raw_json":"{\"stream\":\"btcusdt@bookTicker\",\"data\":{\"e\":\"bookTicker\",\"u\":11478507613392,\"s\":\"BTCUSDT\",\"ps\":\"BTCUSDT\",\"b\":\"79597.00\",\"B\":\"4.961\",\"a\":\"79597.10\",\"A\":\"7.563\",\"T\":1788567720253,\"E\":1788567720253,\"st\":1}}"}
{"receive_ns":1788567720238811000,"stream":"btcusdt@bookTicker","event_type":"bookTicker","event_time_ms":1788567720256,"raw_json":"{\"stream\":\"btcusdt@bookTicker\",\"data\":{\"e\":\"bookTicker\",\"u\":11478507613818,\"s\":\"BTCUSDT\",\"ps\":\"BTCUSDT\",\"b\":\"79597.00\",\"B\":\"5.004\",\"a\":\"79597.10\",\"A\":\"7.563\",\"T\":1788567720256,\"E\":1788567720256,\"st\":1}}"}
{"receive_ns":1788567720255128000,"stream":"btcusdt@depth@100ms","event_type":"depthUpdate","event_time_ms":1788567720267,"raw_json":"{\"stream\":\"btcusdt@depth@100ms\",\"data\":{\"e\":\"depthUpdate\",\"E\":1788567720267,\"T\":1788567720266,\"s\":\"BTCUSDT\",\"ps\":\"BTCUSDT\",\"U\":11478507606202,\"u\":11478507614960,\"pu\":11478507606034,\"b\":[[\"1000.00\",\"24.604\"],[\"29397.00\",\"1.659\"],[\"29497.00\",\"0.441\"],[\"34000.00\",\"0.975\"],[\"71637.30\",\"0.041\"],[\"71673.00\",\"0.000\"],[\"75617.20\",\"0.006\"],[\"78708.10\",\"8.251\"],[\"78801.00\",\"10.140\"],[\"79303.40\",\"0.000\"],[\"79368.00\",\"0.001\"],[\"79384.70\",\"0.000\"],[\"79518.00\",\"0.089\"],[\"79519.70\",\"0.022\"],[\"79564.00\",\"0.130\"],[\"79564.10\",\"0.043\"],[\"79566.60\",\"0.125\"],[\"79567.60\",\"0.000\"],[\"79567.80\",\"0.047\"],[\"79575.40\",\"0.023\"],[\"79575.60\",\"1.505\"],[\"79576.00\",\"0.023\"],[\"79576.10\",\"0.003\"],[\"79577.00\",\"0.001\"],[\"79577.10\",\"0.455\"],[\"79591.50\",\"0.004\"],[\"79591.80\",\"0.026\"],[\"79597.00\",\"5.004\"]],\"a\":[[\"79597.10\",\"7.563\"],[\"79605.40\",\"0.084\"],[\"79607.90\",\"0.000\"],[\"79615.80\",\"0.628\"],[\"79615.90\",\"0.062\"],[\"79616.30\",\"0.013\"],[\"79617.10\",\"0.372\"],[\"79622.70\",\"0.001\"],[\"79623.80\",\"0.002\"],[\"79625.90\",\"0.001\"],[\"79626.30\",\"0.008\"],[\"79630.50\",\"0.000\"],[\"79631.70\",\"0.046\"],[\"79645.50\",\"0.050\"],[\"79647.10\",\"0.380\"],[\"79651.50\",\"0.015\"],[\"79660.40\",\"5.651\"],[\"80393.10\",\"107.479\"],[\"80910.50\",\"4.160\"],[\"80934.30\",\"1.479\"]],\"st\":1}}"}
{"receive_ns":1788567720344951000,"stream":"btcusdt@depth@100ms","event_type":"depthUpdate","event_time_ms":1788567720369,"raw_json":"{\"stream\":\"btcusdt@depth@100ms\",\"data\":{\"e\":\"depthUpdate\",\"E\":1788567720369,\"T\":1788567720368,\"s\":\"BTCUSDT\",\"ps\":\"BTCUSDT\",\"U\":11478507614976,\"u\":11478507624142,\"pu\":11478507614960,\"b\":[[\"29297.00\",\"0.028\"],[\"29397.00\",\"1.778\"],[\"29497.00\",\"0.294\"],[\"71637.30\",\"0.043\"],[\"76413.10\",\"0.000\"],[\"77925.50\",\"0.008\"],[\"78005.10\",\"10.828\"],[\"78467.30\",\"0.002\"],[\"78482.60\",\"33.537\"],[\"78588.80\",\"2.158\"],[\"78623.70\",\"0.002\"],[\"78766.10\",\"0.002\"],[\"78801.00\",\"11.407\"],[\"78895.80\",\"0.002\"],[\"79013.90\",\"0.002\"],[\"79199.00\",\"4.236\"],[\"79308.40\",\"0.002\"],[\"79389.40\",\"0.002\"],[\"79405.00\",\"0.953\"],[\"79463.20\",\"0.002\"],[\"79530.30\",\"0.003\"],[\"79564.00\",\"0.130\"],[\"79566.70\",\"0.046\"],[\"79567.80\",\"0.001\"],[\"79576.10\",\"0.376\"],[\"79577.10\",\"0.082\"],[\"79583.90\",\"1.256\"],[\"79584.80\",\"0.386\"],[\"79584.90\",\"0.020\"],[\"79592.80\",\"0.531\"],[\"79592.90\",\"0.002\"],[\"79595.40\",\"0.037\"]],\"a\":[[\"79610.90\",\"0.442\"],[\"79612.80\",\"0.003\"],[\"79615.80\",\"0.000\"],[\"79616.00\",\"0.637\"],[\"79616.30\",\"0.641\"],[\"79617.10\",\"0.372\"],[\"79622.70\",\"0.001\"],[\"79835.90\",\"0.002\"],[\"80161.50\",\"0.000\"],[\"80221.20\",\"0.188\"],[\"80316.90\",\"0.000\"],[\"80393.10\",\"107.479\"],[\"80438.70\",\"0.000\"],[\"80526.30\",\"0.193\"],[\"80617.60\",\"9.852\"],[\"80622.80\",\"0.001\"],[\"80729.10\",\"0.008\"],[\"80846.20\",\"0.001\"],[\"80975.20\",\"0.000\"],[\"81117.30\",\"0.000\"]],\"st\":1}}"}
{"receive_ns":1788567720456506000,"stream":"btcusdt@depth@100ms","event_type":"depthUpdate","event_time_ms":1788567720471,"raw_json":"{\"stream\":\"btcusdt@depth@100ms\",\"data\":{\"e\":\"depthUpdate\",\"E\":1788567720471,\"T\":1788567720469,\"s\":\"BTCUSDT\",\"ps\":\"BTCUSDT\",\"U\":11478507624423,\"u\":11478507637231,\"pu\":11478507624142,\"b\":[[\"1000.00\",\"24.604\"],[\"29297.00\",\"0.091\"],[\"29397.00\",\"1.834\"],[\"29497.00\",\"0.175\"],[\"63678.00\",\"0.000\"],[\"71637.30\",\"0.043\"],[\"76413.10\",\"0.002\"],[\"78801.00\",\"11.407\"],[\"79323.70\",\"0.010\"],[\"79388.30\",\"0.006\"],[\"79563.90\",\"0.129\"],[\"79564.00\",\"0.005\"],[\"79564.70\",\"0.728\"],[\"79592.80\",\"0.505\"]],\"a\":[[\"79608.30\",\"0.019\"],[\"79608.40\",\"1.826\"],[\"80393.10\",\"107.479\"],[\"80599.00\",\"0.728\"],[\"80830.90\",\"6.920\"]],\"st\":1}}"}
{"receive_ns":1788567720527113000,"stream":"btcusdt@bookTicker","event_type":"bookTicker","event_time_ms":1788567720544,"raw_json":"{\"stream\":\"btcusdt@bookTicker\",\"data\":{\"e\":\"bookTicker\",\"u\":11478507649791,\"s\":\"BTCUSDT\",\"ps\":\"BTCUSDT\",\"b\":\"79597.00\",\"B\":\"4.954\",\"a\":\"79597.10\",\"A\":\"7.563\",\"T\":1788567720544,\"E\":1788567720544,\"st\":1}}"}
{"receive_ns":1788567720538486000,"stream":"btcusdt@bookTicker","event_type":"bookTicker","event_time_ms":1788567720547,"raw_json":"{\"stream\":\"btcusdt@bookTicker\",\"data\":{\"e\":\"bookTicker\",\"u\":11478507650262,\"s\":\"BTCUSDT\",\"ps\":\"BTCUSDT\",\"b\":\"79597.00\",\"B\":\"5.006\",\"a\":\"79597.10\",\"A\":\"7.563\",\"T\":1788567720546,\"E\":1788567720547,\"st\":1}}"}
{"receive_ns":1788567720550566000,"stream":"btcusdt@bookTicker","event_type":"bookTicker","event_time_ms":1788567720547,"raw_json":"{\"stream\":\"btcusdt@bookTicker\",\"data\":{\"e\":\"bookTicker\",\"u\":11478507650380,\"s\":\"BTCUSDT\",\"ps\":\"BTCUSDT\",\"b\":\"79597.00\",\"B\":\"5.006\",\"a\":\"79597.10\",\"A\":\"7.579\",\"T\":1788567720547,\"E\":1788567720547,\"st\":1}}"}
{"receive_ns":1788567720555922000,"stream":"btcusdt@bookTicker","event_type":"bookTicker","event_time_ms":1788567720547,"raw_json":"{\"stream\":\"btcusdt@bookTicker\",\"data\":{\"e\":\"bookTicker\",\"u\":11478507650389,\"s\":\"BTCUSDT\",\"ps\":\"BTCUSDT\",\"b\":\"79597.00\",\"B\":\"5.006\",\"a\":\"79597.10\",\"A\":\"7.596\",\"T\":1788567720547,\"E\":1788567720547,\"st\":1}}"}
{"receive_ns":1788567720565600000,"stream":"btcusdt@depth@100ms","event_type":"depthUpdate","event_time_ms":1788567720573,"raw_json":"{\"stream\":\"btcusdt@depth@100ms\",\"data\":{\"e\":\"depthUpdate\",\"E\":1788567720573,\"T\":1788567720570,\"s\":\"BTCUSDT\",\"ps\":\"BTCUSDT\",\"U\":11478507637836,\"u\":11478507652725,\"pu\":11478507637231,\"b\":[[\"1000.00\",\"24.604\"],[\"29297.00\",\"0.147\"],[\"29397.00\",\"1.897\"],[\"29497.00\",\"0.056\"],[\"63678.00\",\"0.000\"],[\"71637.30\",\"0.043\"],[\"76413.10\",\"0.000\"],[\"78801.00\",\"12.674\"],[\"78960.20\",\"7.496\"],[\"79000.00\",\"43.490\"],[\"79199.00\",\"4.235\"],[\"79456.90\",\"0.239\"],[\"79522.00\",\"0.001\"],[\"79530.50\",\"0.008\"],[\"79563.90\",\"0.004\"],[\"79564.30\",\"0.000\"],[\"79568.90\",\"0.002\"],[\"79570.50\",\"0.454\"],[\"79583.90\",\"0.000\"],[\"79584.80\",\"0.318\"],[\"79584.90\",\"1.318\"],[\"79585.00\",\"0.039\"],[\"79588.00\",\"0.026\"],[\"79592.80\",\"0.531\"],[\"79595.40\",\"0.038\"],[\"79596.90\",\"2.552\"],[\"79597.00\",\"5.006\"]],\"a\":[[\"79597.10\",\"7.596\"],[\"79608.30\",\"0.081\"],[\"79608.40\",\"1.764\"],[\"79619.90\",\"0.000\"],[\"79620.20\",\"0.455\"],[\"80393.10\",\"107.480\"]],\"st\":1}}"}
{"receive_ns":1788567720660283000,"stream":"btcusdt@depth@100ms","event_type":"depthUpdate","event_time_ms":1788567720675,"raw_json":"{\"stream\":\"btcusdt@depth@100ms\",\"data\":{\"e\":\"depthUpdate\",\"E\":1788567720675,\"T\":1788567720674,\"s\":\"BTCUSDT\",\"ps\":\"BTCUSDT\",\"U\":11478507653002,\"u\":11478507661572,\"pu\":11478507652725,\"b\":[[\"29297.00\",\"0.273\"],[\"29397.00\",\"1.827\"],[\"29497.00\",\"0.000\"],[\"71637.30\",\"0.043\"],[\"76413.10\",\"0.002\"],[\"78426.10\",\"0.895\"],[\"78699.30\",\"0.000\"],[\"78801.00\",\"12.674\"],[\"79199.00\",\"4.235\"],[\"79511.00\",\"0.041\"],[\"79564.40\",\"0.362\"],[\"79584.80\",\"0.319\"],[\"79584.90\",\"1.318\"],[\"79585.00\",\"0.039\"],[\"79588.00\",\"0.026\"],[\"79588.10\",\"0.102\"],[\"79591.50\",\"0.030\"],[\"79591.60\",\"0.026\"],[\"79592.50\",\"0.125\"],[\"79592.60\",\"0.000\"],[\"79592.80\",\"0.505\"],[\"79593.00\",\"0.055\"]],\"a\":[[\"79995.10\",\"4.367\"],[\"80393.10\",\"107.480\"]],\"st\":1}}"}
{"receive_ns":1788567720761132000,"stream":"btcusdt@depth@100ms","event_type":"depthUpdate","event_time_ms":1788567720777,"raw_json":"{\"stream\":\"btcusdt@depth@100ms\",\"data\":{\"e\":\"depthUpdate\",\"E\":1788567720777,\"T\":1788567720773,\"s\":\"BTCUSDT\",\"ps\":\"BTCUSDT\",\"U\":11478507661650,\"u\":11478507668467,\"pu\":11478507661572,\"b\":[[\"1000.00\",\"24.604\"],[\"29297.00\",\"0.448\"],[\"29397.00\",\"1.652\"],[\"71637.30\",\"0.043\"],[\"78005.10\",\"10.825\"],[\"79000.00\",\"44.122\"],[\"79436.00\",\"0.000\"],[\"79475.40\",\"0.000\"],[\"79584.90\",\"0.066\"],[\"79585.00\",\"0.035\"],[\"79588.00\",\"1.278\"],[\"79588.10\",\"0.106\"],[\"79588.90\",\"0.035\"],[\"79589.20\",\"0.000\"],[\"79589.90\",\"0.000\"],[\"79591.30\",\"0.126\"],[\"79591.40\",\"0.029\"],[\"79592.20\",\"0.000\"],[\"79592.30\",\"0.000\"]],\"a\":[[\"79621.00\",\"0.034\"],[\"79719.60\",\"0.001\"],[\"79759.00\",\"0.095\"],[\"80194.10\",\"3.115\"],[\"80393.10\",\"107.480\"],[\"80830.90\",\"7.785\"],[\"83576.90\",\"0.037\"],[\"87556.90\",\"0.000\"]],\"st\":1}}"}
{"receive_ns":1788567720861558000,"stream":"btcusdt@depth@100ms","event_type":"depthUpdate","event_time_ms":1788567720879,"raw_json":"{\"stream\":\"btcusdt@depth@100ms\",\"data\":{\"e\":\"depthUpdate\",\"E\":1788567720879,\"T\":1788567720877,\"s\":\"BTCUSDT\",\"ps\":\"BTCUSDT\",\"U\":11478507668721,\"u\":11478507676537,\"pu\":11478507668467,\"b\":[[\"1000.00\",\"24.604\"],[\"29297.00\",\"0.630\"],[\"29397.00\",\"1.470\"],[\"71637.30\",\"0.043\"],[\"76413.10\",\"0.000\"],[\"78801.00\",\"12.674\"],[\"79388.20\",\"5.562\"],[\"79436.00\",\"2.682\"],[\"79475.40\",\"0.531\"],[\"79571.40\",\"2.230\"],[\"79572.10\",\"0.001\"],[\"79576.30\",\"3.115\"],[\"79576.50\",\"0.000\"],[\"79590.40\",\"0.004\"],[\"79591.20\",\"0.036\"],[\"79591.50\",\"0.026\"],[\"79592.10\",\"0.181\"],[\"79592.50\",\"0.122\"],[\"79593.80\",\"0.003\"],[\"79596.90\",\"2.549\"]],\"a\":[[\"79601.00\",\"0.188\"],[\"79601.20\",\"0.252\"],[\"79719.60\",\"0.485\"],[\"79759.00\",\"2.306\"],[\"79804.90\",\"0.302\"],[\"79806.80\",\"2.947\"],[\"79995.10\",\"4.366\"],[\"80393.10\",\"107.480\"],[\"80713.10\",\"0.148\"]],\"st\":1}}"}
{"receive_ns":1788567720864068000,"stream":"btcusdt@bookTicker","event_type":"bookTicker","event_time_ms":1788567720888,"raw_json":"{\"stream\":\"btcusdt@bookTicker\",\"data\":{\"e\":\"bookTicker\",\"u\":11478507677143,\"s\":\"BTCUSDT\",\"ps\":\"BTCUSDT\",\"b\":\"79597.00\",\"B\":\"5.051\",\"a\":\"79597.10\",\"A\":\"7.596\",\"T\":1788567720888,\"E\":1788567720888,\"st\":1}}"}
{"receive_ns":1788567720960468000,"stream":"btcusdt@bookTicker","event_type":"bookTicker","event_time_ms":1788567720977,"raw_json":"{\"stream\":\"btcusdt@bookTicker\",\"data\":{\"e\":\"bookTicker\",\"u\":11478507683842,\"s\":\"BTCUSDT\",\"ps\":\"BTCUSDT\",\"b\":\"79597.00\",\"B\":\"5.051\",\"a\":\"79597.10\",\"A\":\"7.595\",\"T\":1788567720977,\"E\":1788567720977,\"st\":1}}"}
{"receive_ns":1788567720971956000,"stream":"btcusdt@trade","event_type":"trade","event_time_ms":1788567720977,"raw_json":"{\"stream\":\"btcusdt@trade\",\"data\":{\"e\":\"trade\",\"E\":1788567720977,\"T\":1788567720977,\"s\":\"BTCUSDT\",\"t\":8054122576,\"p\":\"79597.10\",\"q\":\"0.001\",\"X\":\"MARKET\",\"m\":false,\"st\":1}}"}
{"receive_ns":1788567720983061000,"stream":"btcusdt@depth@100ms","event_type":"depthUpdate","event_time_ms":1788567720981,"raw_json":"{\"stream\":\"btcusdt@depth@100ms\",\"data\":{\"e\":\"depthUpdate\",\"E\":1788567720981,\"T\":1788567720980,\"s\":\"BTCUSDT\",\"ps\":\"BTCUSDT\",\"U\":11478507676629,\"u\":11478507684221,\"pu\":11478507676537,\"b\":[[\"29297.00\",\"0.805\"],[\"29397.00\",\"1.295\"],[\"71637.30\",\"0.043\"],[\"76413.10\",\"0.002\"],[\"78452.80\",\"0.153\"],[\"78801.00\",\"12.674\"],[\"79199.00\",\"4.246\"],[\"79436.30\",\"0.003\"],[\"79475.40\",\"0.000\"],[\"79525.30\",\"0.635\"],[\"79549.20\",\"0.206\"],[\"79597.00\",\"5.051\"]],\"a\":[[\"79597.10\",\"7.595\"],[\"79601.10\",\"0.222\"],[\"79605.40\",\"0.080\"],[\"79607.70\",\"0.004\"],[\"79692.70\",\"0.003\"],[\"79719.60\",\"0.001\"],[\"80393.10\",\"107.480\"],[\"80458.50\",\"0.001\"]],\"st\":1}}"}
{"receive_ns":1788567721029872000,"stream":"btcusdt@bookTicker","event_type":"bookTicker","event_time_ms":1788567721044,"raw_json":"{\"stream\":\"btcusdt@bookTicker\",\"data\":{\"e\":\"bookTicker\",\"u\":11478507689499,\"s\":\"BTCUSDT\",\"ps\":\"BTCUSDT\",\"b\":\"79597.00\",\"B\":\"5.051\",\"a\":\"79597.10\",\"A\":\"7.588\",\"T\":1788567721044,\"E\":1788567721044,\"st\":1}}"}
{"receive_ns":1788567721035331000,"stream":"btcusdt@trade","event_type":"trade","event_time_ms":1788567721044,"raw_json":"{\"stream\":\"btcusdt@trade\",\"data\":{\"e\":\"trade\",\"E\":1788567721044,\"T\":1788567721044,\"s\":\"BTCUSDT\",\"t\":8054122577,\"p\":\"79597.10\",\"q\":\"0.007\",\"X\":\"MARKET\",\"m\":false,\"st\":1}}"}
{"receive_ns":1788567721064273000,"stream":"btcusdt@depth@100ms","event_type":"depthUpdate","event_time_ms":1788567721083,"raw_json":"{\"stream\":\"btcusdt@depth@100ms\",\"data\":{\"e\":\"depthUpdate\",\"E\":1788567721083,\"T\":1788567721082,\"s\":\"BTCUSDT\",\"ps\":\"BTCUSDT\",\"U\":11478507684257,\"u\":11478507692513,\"pu\":11478507684221,\"b\":[[\"1000.00\",\"24.604\"],[\"29297.00\",\"0.987\"],[\"29397.00\",\"1.113\"],[\"71637.30\",\"0.043\"],[\"76413.10\",\"0.000\"],[\"78801.00\",\"12.674\"],[\"79475.40\",\"0.531\"],[\"79564.00\",\"0.130\"],[\"79565.20\",\"2.477\"],[\"79566.70\",\"0.000\"],[\"79567.60\",\"0.046\"],[\"79567.90\",\"0.628\"],[\"79568.10\",\"2.687\"],[\"79571.40\",\"1.602\"],[\"79571.90\",\"0.630\"],[\"79573.30\",\"0.042\"],[\"79575.60\",\"0.877\"],[\"79575.70\",\"0.447\"],[\"79575.90\",\"0.663\"],[\"79576.10\",\"0.003\"],[\"79576.30\",\"3.109\"],[\"79577.00\",\"0.001\"],[\"79578.00\",\"1.074\"],[\"79582.70\",\"0.194\"],[\"79584.90\",\"0.066\"],[\"79587.70\",\"0.002\"],[\"79587.80\",\"1.589\"],[\"79588.00\",\"0.014\"],[\"79588.10\",\"0.001\"],[\"79588.20\",\"0.012\"],[\"79588.30\",\"1.256\"],[\"79588.50\",\"0.182\"],[\"79589.00\",\"0.526\"],[\"79591.20\",\"0.006\"],[\"79591.60\",\"0.030\"],[\"79592.30\",\"0.026\"],[\"79592.80\",\"0.531\"],[\"79593.10\",\"0.047\"]],\"a\":[[\"79597.10\",\"7.588\"],[\"79605.40\",\"0.084\"],[\"79607.70\",\"0.000\"],[\"79610.70\",\"0.104\"],[\"79610.90\",\"0.003\"],[\"79612.80\",\"0.442\"],[\"79613.20\",\"0.002\"],[\"79616.20\",\"0.629\"],[\"79616.30\",\"0.013\"],[\"79616.90\",\"0.083\"],[\"79617.10\",\"0.000\"],[\"79617.90\",\"0.630\"],[\"79620.20\",\"0.003\"],[\"79621.00\",\"0.455\"],[\"79622.70\",\"0.001\"],[\"79719.60\",\"0.485\"],[\"80194.10\",\"4.361\"],[\"80393.10\",\"107.480\"],[\"80697.20\",\"8.354\"]],\"st\":1}}"}
{"receive_ns":1788567721163638000,"stream":"btcusdt@depth@100ms","event_type":"depthUpdate","event_time_ms":1788567721185,"raw_json":"{\"stream\":\"btcusdt@depth@100ms\",\"data\":{\"e\":\"depthUpdate\",\"E\":1788567721185,\"T\":1788567721184,\"s\":\"BTCUSDT\",\"ps\":\"BTCUSDT\",\"U\":11478507692585,\"u\":11478507700329,\"pu\":11478507692513,\"b\":[[\"1000.00\",\"24.604\"],[\"29297.00\",\"1.162\"],[\"29397.00\",\"0.938\"],[\"63677.60\",\"0.000\"],[\"71637.30\",\"0.043\"],[\"76413.10\",\"0.002\"],[\"77964.00\",\"2.416\"],[\"78252.10\",\"0.511\"],[\"78628.50\",\"11.431\"],[\"78704.60\",\"1.269\"],[\"78801.00\",\"12.674\"],[\"79567.40\",\"0.004\"],[\"79567.60\",\"0.000\"],[\"79568.40\",\"0.047\"],[\"79568.60\",\"0.002\"],[\"79571.60\",\"0.629\"],[\"79571.90\",\"0.002\"],[\"79573.30\",\"0.042\"],[\"79575.60\",\"1.944\"],[\"79575.70\",\"0.008\"],[\"79575.90\",\"0.035\"],[\"79576.70\",\"1.885\"],[\"79577.70\",\"0.373\"],[\"79578.00\",\"0.701\"],[\"79584.90\",\"0.066\"],[\"79587.90\",\"0.983\"],[\"79588.00\",\"0.004\"],[\"79588.20\",\"0.004\"],[\"79588.30\",\"0.000\"],[\"79588.40\",\"0.000\"],[\"79588.50\",\"0.081\"],[\"79588.60\",\"0.000\"],[\"79588.70\",\"0.002\"],[\"79589.00\",\"0.450\"],[\"79589.10\",\"0.113\"],[\"79589.20\",\"0.010\"],[\"79589.30\",\"1.257\"],[\"79592.80\",\"0.505\"],[\"79593.10\",\"0.047\"],[\"79593.20\",\"0.026\"]],\"a\":[[\"79602.20\",\"0.004\"],[\"79604.30\",\"0.005\"],[\"79610.50\",\"1.889\"],[\"79612.80\",\"0.442\"],[\"79615.90\",\"0.062\"],[\"79616.20\",\"0.001\"],[\"79616.60\",\"0.051\"],[\"79617.80\",\"0.372\"],[\"79617.90\",\"0.258\"],[\"79622.70\",\"0.628\"],[\"79623.70\",\"0.000\"],[\"79631.20\",\"0.110\"],[\"79631.70\",\"0.000\"],[\"79632.20\",\"0.065\"],[\"79632.40\",\"1.332\"],[\"79694.00\",\"0.000\"],[\"79995.10\",\"4.366\"],[\"80393.10\",\"107.480\"],[\"80577.80\",\"3.172\"],[\"80592.10\",\"11.298\"],[\"80638.40\",\"0.000\"],[\"80659.90\",\"3.959\"],[\"80757.40\",\"9.008\"],[\"81189.00\",\"10.512\"]],\"st\":1}}"}
{"receive_ns":1788567721175500000,"stream":"btcusdt@bookTicker","event_type":"bookTicker","event_time_ms":1788567721186,"raw_json":"{\"stream\":\"btcusdt@bookTicker\",\"data\":{\"e\":\"bookTicker\",\"u\":11478507700540,\"s\":\"BTCUSDT\",\"ps\":\"BTCUSDT\",\"b\":\"79597.00\",\"B\":\"4.999\",\"a\":\"79597.10\",\"A\":\"7.588\",\"T\":1788567721186,\"E\":1788567721186,\"st\":1}}"}
{"receive_ns":1788567721184391000,"stream":"btcusdt@bookTicker","event_type":"bookTicker","event_time_ms":1788567721189,"raw_json":"{\"stream\":\"btcusdt@bookTicker\",\"data\":{\"e\":\"bookTicker\",\"u\":11478507701220,\"s\":\"BTCUSDT\",\"ps\":\"BTCUSDT\",\"b\":\"79597.00\",\"B\":\"5.046\",\"a\":\"79597.10\",\"A\":\"7.588\",\"T\":1788567721189,\"E\":1788567721189,\"st\":1}}"}
{"receive_ns":1788567721268875000,"stream":"btcusdt@bookTicker","event_type":"bookTicker","event_time_ms":1788567721284,"raw_json":"{\"stream\":\"btcusdt@bookTicker\",\"data\":{\"e\":\"bookTicker\",\"u\":11478507710397,\"s\":\"BTCUSDT\",\"ps\":\"BTCUSDT\",\"b\":\"79597.00\",\"B\":\"5.044\",\"a\":\"79597.10\",\"A\":\"7.588\",\"T\":1788567721284,\"E\":1788567721284,\"st\":1}}"}
{"receive_ns":1788567721285348000,"stream":"btcusdt@depth@100ms","event_type":"depthUpdate","event_time_ms":1788567721287,"raw_json":"{\"stream\":\"btcusdt@depth@100ms\",\"data\":{\"e\":\"depthUpdate\",\"E\":1788567721287,\"T\":1788567721285,\"s\":\"BTCUSDT\",\"ps\":\"BTCUSDT\",\"U\":11478507700365,\"u\":11478507710462,\"pu\":11478507700329,\"b\":[[\"29297.00\",\"1.344\"],[\"29397.00\",\"0.756\"],[\"71637.30\",\"0.043\"],[\"71673.00\",\"0.000\"],[\"77168.40\",\"1.955\"],[\"78392.80\",\"0.000\"],[\"78578.70\",\"0.005\"],[\"78583.40\",\"0.006\"],[\"78598.10\",\"0.000\"],[\"78602.70\",\"0.005\"],[\"78801.00\",\"12.674\"],[\"78960.20\",\"7.496\"],[\"79199.00\",\"4.236\"],[\"79485.50\",\"13.213\"],[\"79567.20\",\"0.048\"],[\"79568.40\",\"0.001\"],[\"79573.30\",\"0.481\"],[\"79575.60\",\"1.505\"],[\"79576.50\",\"0.373\"],[\"79577.70\",\"0.000\"],[\"79584.90\",\"0.088\"],[\"79589.10\",\"0.101\"],[\"79589.20\",\"0.000\"],[\"79592.50\",\"0.148\"],[\"79593.10\",\"0.021\"],[\"79593.20\",\"0.000\"],[\"79597.00\",\"5.044\"]],\"a\":[[\"79610.40\",\"0.562\"],[\"79612.80\",\"0.003\"],[\"79616.50\",\"1.148\"],[\"79617.80\",\"0.000\"],[\"79631.00\",\"0.121\"],[\"79632.20\",\"0.019\"],[\"79806.80\",\"2.809\"],[\"80393.10\",\"107.482\"],[\"80592.10\",\"11.484\"]],\"st\":1}}"}
{"receive_ns":1788567721373808000,"stream":"btcusdt@depth@100ms","event_type":"depthUpdate","event_time_ms":1788567721389,"raw_json":"{\"stream\":\"btcusdt@depth@100ms\",\"data\":{\"e\":\"depthUpdate\",\"E\":1788567721389,\"T\":1788567721386,\"s\":\"BTCUSDT\",\"ps\":\"BTCUSDT\",\"U\":11478507710515,\"u\":11478507718834,\"pu\":11478507710462,\"b\":[[\"1000.00\",\"24.604\"],[\"29297.00\",\"1.519\"],[\"29397.00\",\"0.581\"],[\"63678.00\",\"0.000\"],[\"71637.30\",\"0.043\"],[\"75577.30\",\"3.000\"],[\"76372.90\",\"2.023\"],[\"76413.10\",\"0.000\"],[\"78801.00\",\"12.674\"],[\"79201.10\",\"0.426\"],[\"79436.30\",\"0.002\"],[\"79475.40\",\"0.531\"],[\"79502.20\",\"0.001\"],[\"79525.10\",\"0.000\"],[\"79563.10\",\"0.001\"],[\"79575.10\",\"0.070\"],[\"79584.90\",\"0.072\"],[\"79589.00\",\"0.526\"],[\"79589.40\",\"0.016\"],[\"79591.30\",\"0.100\"],[\"79591.40\",\"0.003\"],[\"79591.50\",\"0.000\"],[\"79592.70\",\"0.027\"],[\"79592.80\",\"0.531\"],[\"79593.00\",\"0.081\"],[\"79593.10\",\"0.047\"]],\"a\":[[\"79622.00\",\"0.002\"],[\"79631.00\",\"0.075\"],[\"79631.70\",\"0.046\"],[\"79633.50\",\"0.001\"],[\"79653.80\",\"0.031\"],[\"79674.20\",\"0.001\"],[\"79719.60\",\"0.485\"],[\"80393.10\",\"107.480\"]],\"st\":1}}"}
{"receive_ns":1788567721389681000,"stream":"btcusdt@bookTicker","event_type":"bookTicker","event_time_ms":1788567721410,"raw_json":"{\"stream\":\"btcusdt@bookTicker\",\"data\":{\"e\":\"bookTicker\",\"u\":11478507720347,\"s\":\"BTCUSDT\",\"ps\":\"BTCUSDT\",\"b\":\"79597.00\",\"B\":\"5.026\",\"a\":\"79597.10\",\"A\":\"7.588\",\"T\":1788567721410,\"E\":1788567721410,\"st\":1}}"}
{"receive_ns":1788567721407892000,"stream":"btcusdt@bookTicker","event_type":"bookTicker","event_time_ms":1788567721414,"raw_json":"{\"stream\":\"btcusdt@bookTicker\",\"data\":{\"e\":\"bookTicker\",\"u\":11478507720660,\"s\":\"BTCUSDT\",\"ps\":\"BTCUSDT\",\"b\":\"79597.00\",\"B\":\"5.043\",\"a\":\"79597.10\",\"A\":\"7.588\",\"T\":1788567721414,\"E\":1788567721414,\"st\":1}}"}
{"receive_ns":1788567721459869000,"stream":"btcusdt@bookTicker","event_type":"bookTicker","event_time_ms":1788567721472,"raw_json":"{\"stream\":\"btcusdt@bookTicker\",\"data\":{\"e\":\"bookTicker\",\"u\":11478507724810,\"s\":\"BTCUSDT\",\"ps\":\"BTCUSDT\",\"b\":\"79597.00\",\"B\":\"4.984\",\"a\":\"79597.10\",\"A\":\"7.588\",\"T\":1788567721471,\"E\":1788567721472,\"st\":1}}"}
{"receive_ns":1788567721471210000,"stream":"btcusdt@bookTicker","event_type":"bookTicker","event_time_ms":1788567721475,"raw_json":"{\"stream\":\"btcusdt@bookTicker\",\"data\":{\"e\":\"bookTicker\",\"u\":11478507725350,\"s\":\"BTCUSDT\",\"ps\":\"BTCUSDT\",\"b\":\"79597.00\",\"B\":\"5.041\",\"a\":\"79597.10\",\"A\":\"7.588\",\"T\":1788567721475,\"E\":1788567721475,\"st\":1}}"}
{"receive_ns":1788567721487753000,"stream":"btcusdt@depth@100ms","event_type":"depthUpdate","event_time_ms":1788567721491,"raw_json":"{\"stream\":\"btcusdt@depth@100ms\",\"data\":{\"e\":\"depthUpdate\",\"E\":1788567721491,\"T\":1788567721490,\"s\":\"BTCUSDT\",\"ps\":\"BTCUSDT\",\"U\":11478507719005,\"u\":11478507726299,\"pu\":11478507718834,\"b\":[[\"1000.00\",\"24.604\"],[\"29297.00\",\"1.701\"],[\"29397.00\",\"0.399\"],[\"71637.30\",\"0.043\"],[\"74781.80\",\"4.070\"],[\"76413.10\",\"0.002\"],[\"78434.10\",\"3.543\"],[\"78801.00\",\"12.674\"],[\"78869.90\",\"0.190\"],[\"79501.40\",\"0.048\"],[\"79525.30\",\"0.633\"],[\"79541.20\",\"0.000\"],[\"79584.80\",\"0.005\"],[\"79584.90\",\"1.318\"],[\"79585.00\",\"0.349\"],[\"79585.10\",\"0.004\"],[\"79587.70\",\"0.004\"],[\"79587.80\",\"1.587\"],[\"79588.00\",\"0.026\"],[\"79589.30\",\"0.001\"],[\"79589.40\",\"0.000\"],[\"79593.10\",\"0.021\"],[\"79597.00\",\"5.041\"]],\"a\":[[\"79668.80\",\"0.035\"],[\"79692.70\",\"0.001\"],[\"80393.10\",\"107.480\"],[\"80671.70\",\"10.971\"],[\"80751.30\",\"14.137\"]],\"st\":1}}"}
{"receive_ns":1788567721491610000,"stream":"btcusdt@bookTicker","event_type":"bookTicker","event_time_ms":1788567721503,"raw_json":"{\"stream\":\"btcusdt@bookTicker\",\"data\":{\"e\":\"bookTicker\",\"u\":11478507727159,\"s\":\"BTCUSDT\",\"ps\":\"BTCUSDT\",\"b\":\"79597.00\",\"B\":\"5.041\",\"a\":\"79597.10\",\"A\":\"7.589\",\"T\":1788567721503,\"E\":1788567721503,\"st\":1}}"}
{"receive_ns":1788567721507295000,"stream":"btcusdt@bookTicker","event_type":"bookTicker","event_time_ms":1788567721522,"raw_json":"{\"stream\":\"btcusdt@bookTicker\",\"data\":{\"e\":\"bookTicker\",\"u\":11478507728559,\"s\":\"BTCUSDT\",\"ps\":\"BTCUSDT\",\"b\":\"79597.00\",\"B\":\"4.998\",\"a\":\"79597.10\",\"A\":\"7.589\",\"T\":1788567721522,\"E\":1788567721522,\"st\":1}}"}
{"receive_ns":1788567721519416000,"stream":"btcusdt@bookTicker","event_type":"bookTicker","event_time_ms":1788567721523,"raw_json":"{\"stream\":\"btcusdt@bookTicker\",\"data\":{\"e\":\"bookTicker\",\"u\":11478507728640,\"s\":\"BTCUSDT\",\"ps\":\"BTCUSDT\",\"b\":\"79597.00\",\"B\":\"4.926\",\"a\":\"79597.10\",\"A\":\"7.589\",\"T\":1788567721523,\"E\":1788567721523,\"st\":1}}"}
{"receive_ns":1788567721524886000,"stream":"btcusdt@bookTicker","event_type":"bookTicker","event_time_ms":1788567721526,"raw_json":"{\"stream\":\"btcusdt@bookTicker\",\"data\":{\"e\":\"bookTicker\",\"u\":11478507728764,\"s\":\"BTCUSDT\",\"ps\":\"BTCUSDT\",\"b\":\"79597.00\",\"B\":\"4.974\",\"a\":\"79597.10\",\"A\":\"7.589\",\"T\":1788567721525,\"E\":1788567721526,\"st\":1}}"}
{"receive_ns":1788567721616955000,"stream":"btcusdt@depth@100ms","event_type":"depthUpdate","event_time_ms":1788567721593,"raw_json":"{\"stream\":\"btcusdt@depth@100ms\",\"data\":{\"e\":\"depthUpdate\",\"E\":1788567721593,\"T\":1788567721592,\"s\":\"BTCUSDT\",\"ps\":\"BTCUSDT\",\"U\":11478507726418,\"u\":11478507736133,\"pu\":11478507726299,\"b\":[[\"29197.00\",\"0.042\"],[\"29297.00\",\"1.792\"],[\"29397.00\",\"0.266\"],[\"63678.00\",\"0.002\"],[\"71637.30\",\"0.043\"],[\"76413.10\",\"0.000\"],[\"77991.20\",\"1.853\"],[\"78079.70\",\"0.000\"],[\"78168.10\",\"0.000\"],[\"78256.50\",\"0.000\"],[\"78344.90\",\"0.000\"],[\"78433.40\",\"0.000\"],[\"78521.80\",\"0.002\"],[\"78588.10\",\"6.923\"],[\"78610.20\",\"0.254\"],[\"78698.60\",\"0.000\"],[\"78787.10\",\"1.066\"],[\"78801.00\",\"12.674\"],[\"79199.00\",\"4.246\"],[\"79475.40\",\"0.000\"],[\"79575.70\",\"0.002\"],[\"79576.40\",\"0.009\"],[\"79584.80\",\"0.385\"],[\"79584.90\",\"0.000\"],[\"79585.00\",\"0.035\"],[\"79585.10\",\"0.000\"],[\"79588.00\",\"0.026\"],[\"79588.10\",\"1.257\"],[\"79589.00\",\"0.450\"],[\"79591.40\",\"0.005\"],[\"79591.60\",\"0.028\"],[\"79593.00\",\"0.055\"],[\"79597.00\",\"4.974\"]],\"a\":[[\"79597.10\",\"7.589\"],[\"79605.40\",\"0.080\"],[\"79607.70\",\"0.004\"],[\"79619.90\",\"0.452\"],[\"79621.00\",\"0.003\"],[\"79719.60\",\"0.001\"],[\"80313.70\",\"1.774\"],[\"80378.70\",\"0.005\"],[\"80393.10\",\"107.479\"],[\"80467.20\",\"0.000\"],[\"80555.60\",\"0.000\"],[\"80644.00\",\"0.000\"],[\"80732.40\",\"0.000\"],[\"80734.00\",\"1.839\"],[\"80820.90\",\"0.000\"],[\"80909.30\",\"0.000\"],[\"80974.10\",\"0.718\"],[\"80997.70\",\"0.000\"],[\"81086.10\",\"0.000\"],[\"81174.60\",\"0.000\"]],\"st\":1}}"}
{"receive_ns":1788567721677632000,"stream":"btcusdt@depth@100ms","event_type":"depthUpdate","event_time_ms":1788567721695,"raw_json":"{\"stream\":\"btcusdt@depth@100ms\",\"data\":{\"e\":\"depthUpdate\",\"E\":1788567721695,\"T\":1788567721694,\"s\":\"BTCUSDT\",\"ps\":\"BTCUSDT\",\"U\":11478507736232,\"u\":11478507743250,\"pu\":11478507736133,\"b\":[[\"1000.00\",\"24.604\"],[\"29197.00\",\"0.105\"],[\"29297.00\",\"1.848\"],[\"29397.00\",\"0.147\"],[\"63678.00\",\"0.000\"],[\"71637.30\",\"0.043\"],[\"78566.50\",\"0.009\"],[\"78583.40\",\"0.000\"],[\"78585.70\",\"0.005\"],[\"78602.70\",\"0.000\"],[\"78605.00\",\"3.007\"],[\"78617.50\",\"0.013\"],[\"78801.00\",\"11.407\"],[\"79029.10\",\"0.095\"],[\"79199.00\",\"4.247\"],[\"79436.00\",\"0.000\"],[\"79436.30\",\"0.001\"],[\"79584.80\",\"0.381\"],[\"79584.90\",\"1.256\"],[\"79585.00\",\"0.039\"],[\"79585.40\",\"0.129\"],[\"79586.20\",\"0.002\"],[\"79587.40\",\"0.004\"],[\"79588.10\",\"0.001\"],[\"79588.20\",\"0.001\"],[\"79589.50\",\"0.040\"],[\"79590.10\",\"0.160\"],[\"79592.20\",\"0.026\"],[\"79592.80\",\"0.505\"]],\"a\":[[\"79605.40\",\"0.084\"],[\"79607.70\",\"0.000\"],[\"79759.00\",\"0.095\"],[\"79804.90\",\"0.776\"],[\"79995.10\",\"4.365\"],[\"80393.10\",\"107.479\"],[\"80687.60\",\"1.809\"],[\"80751.30\",\"15.003\"],[\"81189.00\",\"10.515\"]],\"st\":1}}"}
{"receive_ns":1788567721779768000,"stream":"btcusdt@depth@100ms","event_type":"depthUpdate","event_time_ms":1788567721797,"raw_json":"{\"stream\":\"btcusdt@depth@100ms\",\"data\":{\"e\":\"depthUpdate\",\"E\":1788567721797,\"T\":1788567721795,\"s\":\"BTCUSDT\",\"ps\":\"BTCUSDT\",\"U\":11478507743346,\"u\":11478507750134,\"pu\":11478507743250,\"b\":[[\"1000.00\",\"24.604\"],[\"29197.00\",\"0.161\"],[\"29297.00\",\"1.911\"],[\"29397.00\",\"0.028\"],[\"63678.00\",\"0.000\"],[\"71637.30\",\"0.043\"],[\"75617.20\",\"0.004\"],[\"76413.10\",\"0.002\"],[\"78588.10\",\"6.770\"],[\"78687.90\",\"4.159\"],[\"79388.20\",\"0.000\"],[\"79565.40\",\"0.032\"],[\"79591.50\",\"0.026\"],[\"79592.70\",\"0.001\"]],\"a\":[[\"79645.10\",\"0.899\"],[\"79645.60\",\"0.000\"],[\"79806.80\",\"0.008\"],[\"79818.80\",\"6.793\"],[\"80393.10\",\"107.479\"],[\"80552.30\",\"30.718\"]],\"st\":1}}"}
{"receive_ns":1788567721883173000,"stream":"btcusdt@depth@100ms","event_type":"depthUpdate","event_time_ms":1788567721899,"raw_json":"{\"stream\":\"btcusdt@depth@100ms\",\"data\":{\"e\":\"depthUpdate\",\"E\":1788567721899,\"T\":1788567721894,\"s\":\"BTCUSDT\",\"ps\":\"BTCUSDT\",\"U\":11478507750256,\"u\":11478507755676,\"pu\":11478507750134,\"b\":[[\"29197.00\",\"0.308\"],[\"29297.00\",\"1.792\"],[\"29397.00\",\"0.000\"],[\"63678.00\",\"0.000\"],[\"71637.30\",\"0.043\"],[\"76413.10\",\"0.000\"],[\"78389.70\",\"3.185\"],[\"78602.00\",\"16.438\"],[\"78801.00\",\"11.407\"],[\"79199.00\",\"4.246\"],[\"79361.80\",\"0.829\"],[\"79388.20\",\"5.503\"],[\"79436.00\",\"2.664\"],[\"79475.40\",\"0.531\"],[\"79578.80\",\"0.076\"],[\"79587.80\",\"1.511\"],[\"79588.10\",\"0.077\"],[\"79591.00\",\"0.026\"],[\"79591.20\",\"0.032\"],[\"79591.30\",\"0.126\"],[\"79591.40\",\"0.031\"],[\"79592.00\",\"0.031\"],[\"79592.20\",\"0.000\"],[\"79592.30\",\"0.000\"],[\"79592.50\",\"0.122\"]],\"a\":[[\"79719.60\",\"0.485\"],[\"79759.00\",\"2.255\"],[\"79804.90\",\"0.302\"],[\"79806.80\",\"2.847\"],[\"80299.20\",\"3.855\"],[\"80393.10\",\"107.479\"],[\"80724.70\",\"3.151\"],[\"81825.80\",\"2.439\"]],\"st\":1}}"}
{"receive_ns":1788567721994991000,"stream":"btcusdt@depth@100ms","event_type":"depthUpdate","event_time_ms":1788567722001,"raw_json":"{\"stream\":\"btcusdt@depth@100ms\",\"data\":{\"e\":\"depthUpdate\",\"E\":1788567722001,\"T\":1788567721997,\"s\":\"BTCUSDT\",\"ps\":\"BTCUSDT\",\"U\":11478507755932,\"u\":11478507761944,\"pu\":11478507755676,\"b\":[[\"1000.00\",\"24.604\"],[\"29197.00\",\"0.490\"],[\"29297.00\",\"1.610\"],[\"63678.00\",\"0.000\"],[\"71637.30\",\"0.043\"],[\"76413.10\",\"0.002\"],[\"78426.10\",\"0.004\"],[\"78801.00\",\"11.407\"],[\"78866.70\",\"7.069\"],[\"79578.50\",\"0.010\"],[\"79586.10\",\"0.018\"],[\"79592.20\",\"0.026\"]],\"a\":[[\"79995.10\",\"4.366\"],[\"80767.20\",\"10.252\"]],\"st\":1}}"}
{"receive_ns":1788567722007194000,"stream":"btcusdt@bookTicker","event_type":"bookTicker","event_time_ms":1788567722022,"raw_json":"{\"stream\":\"btcusdt@bookTicker\",\"data\":{\"e\":\"bookTicker\",\"u\":11478507763672,\"s\":\"BTCUSDT\",\"ps\":\"BTCUSDT\",\"b\":\"79597.00\",\"B\":\"4.972\",\"a\":\"79597.10\",\"A\":\"7.589\",\"T\":1788567722022,\"E\":1788567722022,\"st\":1}}"}
{"receive_ns":1788567722029401000,"stream":"btcusdt@bookTicker","event_type":"bookTicker","event_time_ms":1788567722027,"raw_json":"{\"stream\":\"btcusdt@bookTicker\",\"data\":{\"e\":\"bookTicker\",\"u\":11478507764110,\"s\":\"BTCUSDT\",\"ps\":\"BTCUSDT\",\"b\":\"79597.00\",\"B\":\"4.972\",\"a\":\"79597.10\",\"A\":\"7.587\",\"T\":1788567722027,\"E\":1788567722027,\"st\":1}}"}
{"receive_ns":1788567722045857000,"stream":"btcusdt@trade","event_type":"trade","event_time_ms":1788567722027,"raw_json":"{\"stream\":\"btcusdt@trade\",\"data\":{\"e\":\"trade\",\"E\":1788567722027,\"T\":1788567722027,\"s\":\"BTCUSDT\",\"t\":8054122578,\"p\":\"79597.10\",\"q\":\"0.002\",\"X\":\"MARKET\",\"m\":false,\"st\":1}}"}
{"receive_ns":1788567722057714000,"stream":"btcusdt@bookTicker","event_type":"bookTicker","event_time_ms":1788567722029,"raw_json":"{\"stream\":\"btcusdt@bookTicker\",\"data\":{\"e\":\"bookTicker\",\"u\":11478507764342,\"s\":\"BTCUSDT\",\"ps\":\"BTCUSDT\",\"b\":\"79597.00\",\"B\":\"4.971\",\"a\":\"79597.10\",\"A\":\"7.587\",\"T\":1788567722029,\"E\":1788567722029,\"st\":1}}"}
{"receive_ns":1788567722057951000,"stream":"btcusdt@bookTicker","event_type":"bookTicker","event_time_ms":1788567722031,"raw_json":"{\"stream\":\"btcusdt@bookTicker\",\"data\":{\"e\":\"bookTicker\",\"u\":11478507764710,\"s\":\"BTCUSDT\",\"ps\":\"BTCUSDT\",\"b\":\"79597.00\",\"B\":\"4.947\",\"a\":\"79597.10\",\"A\":\"7.587\",\"T\":1788567722031,\"E\":1788567722031,\"st\":1}}"}
{"receive_ns":1788567722058128000,"stream":"btcusdt@bookTicker","event_type":"bookTicker","event_time_ms":1788567722031,"raw_json":"{\"stream\":\"btcusdt@bookTicker\",\"data\":{\"e\":\"bookTicker\",\"u\":11478507764712,\"s\":\"BTCUSDT\",\"ps\":\"BTCUSDT\",\"b\":\"79597.00\",\"B\":\"3.721\",\"a\":\"79597.10\",\"A\":\"7.587\",\"T\":1788567722031,\"E\":1788567722031,\"st\":1}}"}
{"receive_ns":1788567722071434000,"stream":"btcusdt@bookTicker","event_type":"bookTicker","event_time_ms":1788567722034,"raw_json":"{\"stream\":\"btcusdt@bookTicker\",\"data\":{\"e\":\"bookTicker\",\"u\":11478507766497,\"s\":\"BTCUSDT\",\"ps\":\"BTCUSDT\",\"b\":\"79597.00\",\"B\":\"3.781\",\"a\":\"79597.10\",\"A\":\"7.587\",\"T\":1788567722034,\"E\":1788567722034,\"st\":1}}"}
{"receive_ns":1788567722077093000,"stream":"btcusdt@bookTicker","event_type":"bookTicker","event_time_ms":1788567722035,"raw_json":"{\"stream\":\"btcusdt@bookTicker\",\"data\":{\"e\":\"bookTicker\",\"u\":11478507767755,\"s\":\"BTCUSDT\",\"ps\":\"BTCUSDT\",\"b\":\"79597.00\",\"B\":\"3.780\",\"a\":\"79597.10\",\"A\":\"7.587\",\"T\":1788567722035,\"E\":1788567722035,\"st\":1}}"}
{"receive_ns":1788567722089346000,"stream":"btcusdt@bookTicker","event_type":"bookTicker","event_time_ms":1788567722047,"raw_json":"{\"stream\":\"btcusdt@bookTicker\",\"data\":{\"e\":\"bookTicker\",\"u\":11478507773299,\"s\":\"BTCUSDT\",\"ps\":\"BTCUSDT\",\"b\":\"79597.00\",\"B\":\"3.723\",\"a\":\"79597.10\",\"A\":\"7.587\",\"T\":1788567722047,\"E\":1788567722047,\"st\":1}}"}
{"receive_ns":1788567722101423000,"stream":"btcusdt@bookTicker","event_type":"bookTicker","event_time_ms":1788567722050,"raw_json":"{\"stream\":\"btcusdt@bookTicker\",\"data\":{\"e\":\"bookTicker\",\"u\":11478507774163,\"s\":\"BTCUSDT\",\"ps\":\"BTCUSDT\",\"b\":\"79597.00\",\"B\":\"3.723\",\"a\":\"79597.10\",\"A\":\"7.588\",\"T\":1788567722050,\"E\":1788567722050,\"st\":1}}"}
{"receive_ns":1788567722113013000,"stream":"btcusdt@bookTicker","event_type":"bookTicker","event_time_ms":1788567722059,"raw_json":"{\"stream\":\"btcusdt@bookTicker\",\"data\":{\"e\":\"bookTicker\",\"u\":11478507776593,\"s\":\"BTCUSDT\",\"ps\":\"BTCUSDT\",\"b\":\"79597.00\",\"B\":\"3.777\",\"a\":\"79597.10\",\"A\":\"7.588\",\"T\":1788567722059,\"E\":1788567722059,\"st\":1}}"}
{"receive_ns":1788567722126913000,"stream":"btcusdt@bookTicker","event_type":"bookTicker","event_time_ms":1788567722060,"raw_json":"{\"stream\":\"btcusdt@bookTicker\",\"data\":{\"e\":\"bookTicker\",\"u\":11478507776983,\"s\":\"BTCUSDT\",\"ps\":\"BTCUSDT\",\"b\":\"79597.00\",\"B\":\"3.778\",\"a\":\"79597.10\",\"A\":\"7.588\",\"T\":1788567722060,\"E\":1788567722060,\"st\":1}}"}
{"receive_ns":1788567722137989000,"stream":"btcusdt@bookTicker","event_type":"bookTicker","event_time_ms":1788567722063,"raw_json":"{\"stream\":\"btcusdt@bookTicker\",\"data\":{\"e\":\"bookTicker\",\"u\":11478507777523,\"s\":\"BTCUSDT\",\"ps\":\"BTCUSDT\",\"b\":\"79597.00\",\"B\":\"3.778\",\"a\":\"79597.10\",\"A\":\"7.594\",\"T\":1788567722063,\"E\":1788567722063,\"st\":1}}"}
{"receive_ns":1788567722150621000,"stream":"btcusdt@depth@100ms","event_type":"depthUpdate","event_time_ms":1788567722103,"raw_json":"{\"stream\":\"btcusdt@depth@100ms\",\"data\":{\"e\":\"depthUpdate\",\"E\":1788567722103,\"T\":1788567722102,\"s\":\"BTCUSDT\",\"ps\":\"BTCUSDT\",\"U\":11478507762261,\"u\":11478507783636,\"pu\":11478507761944,\"b\":[[\"1000.00\",\"24.604\"],[\"29197.00\",\"0.672\"],[\"29297.00\",\"1.428\"],[\"63678.00\",\"0.002\"],[\"71637.30\",\"0.043\"],[\"75617.10\",\"0.029\"],[\"75617.20\",\"0.006\"],[\"76413.10\",\"0.000\"],[\"78005.10\",\"10.825\"],[\"78729.40\",\"7.345\"],[\"78801.00\",\"11.407\"],[\"79494.90\",\"0.466\"],[\"79499.60\",\"0.008\"],[\"79510.10\",\"0.049\"],[\"79513.80\",\"0.002\"],[\"79514.70\",\"0.115\"],[\"79517.20\",\"0.000\"],[\"79518.60\",\"0.000\"],[\"79518.70\",\"0.001\"],[\"79519.60\",\"0.228\"],[\"79521.30\",\"0.043\"],[\"79525.00\",\"0.000\"],[\"79527.80\",\"0.005\"],[\"79533.10\",\"0.000\"],[\"79536.70\",\"0.000\"],[\"79537.80\",\"3.501\"],[\"79542.60\",\"1.509\"],[\"79543.50\",\"0.000\"],[\"79546.40\",\"0.135\"],[\"79553.50\",\"0.860\"],[\"79554.50\",\"0.052\"],[\"79556.60\",\"0.000\"],[\"79559.40\",\"0.039\"],[\"79562.80\",\"0.001\"],[\"79564.20\",\"0.002\"],[\"79567.20\",\"0.676\"],[\"79567.60\",\"0.000\"],[\"79567.90\",\"0.000\"],[\"79571.00\",\"0.628\"],[\"79571.60\",\"0.001\"],[\"79573.00\",\"0.288\"],[\"79573.30\",\"0.481\"],[\"79574.80\",\"0.021\"],[\"79575.20\",\"0.631\"],[\"79575.60\",\"0.877\"],[\"79576.50\",\"0.373\"],[\"79576.60\",\"0.078\"],[\"79576.90\",\"0.341\"],[\"79577.70\",\"0.076\"],[\"79578.80\",\"0.158\"],[\"79579.60\",\"0.000\"],[\"79582.70\",\"0.194\"],[\"79583.90\",\"0.592\"],[\"79584.00\",\"1.286\"],[\"79584.30\",\"0.078\"],[\"79584.70\",\"0.001\"],[\"79584.80\",\"0.005\"],[\"79584.90\",\"0.000\"],[\"79585.00\",\"0.035\"],[\"79585.50\",\"0.077\"],[\"79586.70\",\"0.000\"],[\"79586.90\",\"0.003\"],[\"79587.30\",\"0.034\"],[\"79587.50\",\"0.000\"],[\"79587.70\",\"0.002\"],[\"79587.90\",\"0.631\"],[\"79588.00\",\"0.004\"],[\"79588.10\",\"0.001\"],[\"79588.20\",\"0.005\"],[\"79589.00\",\"0.002\"],[\"79589.20\",\"0.000\"],[\"79589.30\",\"0.027\"],[\"79589.40\",\"0.026\"],[\"79589.60\",\"0.089\"],[\"79589.70\",\"0.027\"],[\"79589.80\",\"0.026\"],[\"79589.90\",\"0.026\"],[\"79590.00\",\"0.120\"],[\"79590.10\",\"0.160\"],[\"79590.20\",\"0.128\"],[\"79590.30\",\"0.026\"],[\"79590.40\",\"0.030\"],[\"79590.60\",\"0.002\"],[\"79590.70\",\"0.001\"],[\"79590.80\",\"0.001\"],[\"79590.90\",\"0.071\"],[\"79591.00\",\"0.002\"],[\"79591.10\",\"0.006\"],[\"79591.20\",\"0.006\"],[\"79591.30\",\"0.100\"],[\"79591.40\",\"0.003\"],[\"79591.50\",\"0.000\"],[\"79591.60\",\"0.000\"],[\"79591.70\",\"0.003\"],[\"79591.80\",\"0.000\"],[\"79592.00\",\"0.005\"],[\"79592.20\",\"0.000\"],[\"79592.50\",\"0.121\"],[\"79597.00\",\"3.778\"]],\"a\":[[\"79597.10\",\"7.594\"],[\"79610.40\",\"0.562\"],[\"79610.70\",\"0.104\"],[\"79612.50\",\"0.005\"],[\"79613.20\",\"0.002\"],[\"79615.40\",\"0.632\"],[\"79616.00\",\"0.009\"],[\"79616.30\",\"0.641\"],[\"79616.50\",\"0.776\"],[\"79616.80\",\"0.375\"],[\"79619.30\",\"0.628\"],[\"79620.00\",\"0.146\"],[\"79620.50\",\"0.000\"],[\"79621.00\",\"0.109\"],[\"79622.70\",\"0.001\"],[\"79623.10\",\"0.687\"],[\"79623.90\",\"0.010\"],[\"79624.80\",\"0.152\"],[\"79628.90\",\"0.070\"],[\"79629.00\",\"0.326\"],[\"79631.00\",\"0.051\"],[\"79631.70\",\"0.000\"],[\"79633.00\",\"0.082\"],[\"79634.40\",\"0.002\"],[\"79645.10\",\"0.774\"],[\"79646.00\",\"0.180\"],[\"79653.20\",\"0.210\"],[\"79653.50\",\"0.039\"],[\"79658.20\",\"0.001\"],[\"79658.60\",\"0.252\"],[\"79664.40\",\"0.002\"],[\"79665.50\",\"6.300\"],[\"79666.10\",\"21.773\"],[\"79666.70\",\"0.040\"],[\"79667.00\",\"0.041\"],[\"79670.80\",\"0.014\"],[\"79675.10\",\"0.125\"],[\"79696.80\",\"0.004\"],[\"79806.80\",\"2.809\"],[\"80393.10\",\"107.479\"],[\"80631.90\",\"10.642\"]],\"st\":1}}"}
{"receive_ns":1788567722162047000,"stream":"btcusdt@bookTicker","event_type":"bookTicker","event_time_ms":1788567722147,"raw_json":"{\"stream\":\"btcusdt@bookTicker\",\"data\":{\"e\":\"bookTicker\",\"u\":11478507790805,\"s\":\"BTCUSDT\",\"ps\":\"BTCUSDT\",\"b\":\"79597.00\",\"B\":\"3.778\",\"a\":\"79597.10\",\"A\":\"7.593\",\"T\":1788567722147,\"E\":1788567722147,\"st\":1}}"}
{"receive_ns":1788567722183641000,"stream":"btcusdt@trade","event_type":"trade","event_time_ms":1788567722147,"raw_json":"{\"stream\":\"btcusdt@trade\",\"data\":{\"e\":\"trade\",\"E\":1788567722147,\"T\":1788567722147,\"s\":\"BTCUSDT\",\"t\":8054122579,\"p\":\"79597.10\",\"q\":\"0.001\",\"X\":\"MARKET\",\"m\":false,\"st\":1}}"}
{"receive_ns":1788567722199023000,"stream":"btcusdt@depth@100ms","event_type":"depthUpdate","event_time_ms":1788567722205,"raw_json":"{\"stream\":\"btcusdt@depth@100ms\",\"data\":{\"e\":\"depthUpdate\",\"E\":1788567722205,\"T\":1788567722201,\"s\":\"BTCUSDT\",\"ps\":\"BTCUSDT\",\"U\":11478507783922,\"u\":11478507797811,\"pu\":11478507783636,\"b\":[[\"29197.00\",\"0.847\"],[\"29297.00\",\"1.253\"],[\"63677.60\",\"0.000\"],[\"63678.00\",\"0.000\"],[\"71637.30\",\"0.043\"],[\"77925.50\",\"0.264\"],[\"78801.00\",\"11.407\"],[\"79199.00\",\"4.236\"],[\"79513.80\",\"0.000\"],[\"79519.60\",\"0.018\"],[\"79528.40\",\"0.211\"],[\"79549.30\",\"2.987\"],[\"79554.80\",\"0.235\"],[\"79566.70\",\"0.628\"],[\"79567.20\",\"0.048\"],[\"79583.80\",\"0.285\"],[\"79584.10\",\"0.009\"],[\"79584.50\",\"0.004\"],[\"79586.70\",\"0.076\"],[\"79586.90\",\"0.001\"],[\"79588.20\",\"0.001\"],[\"79589.30\",\"0.001\"],[\"79589.40\",\"0.000\"],[\"79590.50\",\"0.026\"],[\"79590.80\",\"0.029\"],[\"79590.90\",\"0.070\"],[\"79591.10\",\"0.004\"],[\"79595.10\",\"0.001\"]],\"a\":[[\"79597.10\",\"7.593\"],[\"79610.40\",\"0.123\"],[\"79610.70\",\"0.543\"],[\"79613.30\",\"0.065\"],[\"79621.00\",\"0.087\"],[\"79656.90\",\"0.170\"],[\"79692.70\",\"0.002\"],[\"79693.80\",\"0.020\"],[\"79696.80\",\"0.001\"],[\"79702.10\",\"0.000\"],[\"79705.30\",\"0.001\"],[\"79940.20\",\"0.018\"],[\"79941.80\",\"0.021\"],[\"80050.80\",\"0.001\"],[\"80393.10\",\"107.479\"],[\"80605.30\",\"0.629\"]],\"st\":1}}"}
{"receive_ns":1788567722210373000,"stream":"btcusdt@bookTicker","event_type":"bookTicker","event_time_ms":1788567722212,"raw_json":"{\"stream\":\"btcusdt@bookTicker\",\"data\":{\"e\":\"bookTicker\",\"u\":11478507799098,\"s\":\"BTCUSDT\",\"ps\":\"BTCUSDT\",\"b\":\"79597.00\",\"B\":\"3.778\",\"a\":\"79597.10\",\"A\":\"7.598\",\"T\":1788567722212,\"E\":1788567722212,\"st\":1}}"}
{"receive_ns":1788567722253675000,"stream":"btcusdt@bookTicker","event_type":"bookTicker","event_time_ms":1788567722269,"raw_json":"{\"stream\":\"btcusdt@bookTicker\",\"data\":{\"e\":\"bookTicker\",\"u\":11478507804918,\"s\":\"BTCUSDT\",\"ps\":\"BTCUSDT\",\"b\":\"79597.00\",\"B\":\"3.778\",\"a\":\"79597.10\",\"A\":\"7.607\",\"T\":1788567722269,\"E\":1788567722269,\"st\":1}}"}
{"receive_ns":1788567722290931000,"stream":"btcusdt@depth@100ms","event_type":"depthUpdate","event_time_ms":1788567722307,"raw_json":"{\"stream\":\"btcusdt@depth@100ms\",\"data\":{\"e\":\"depthUpdate\",\"E\":1788567722307,\"T\":1788567722305,\"s\":\"BTCUSDT\",\"ps\":\"BTCUSDT\",\"U\":11478507798308,\"u\":11478507808751,\"pu\":11478507797811,\"b\":[[\"1000.00\",\"24.604\"],[\"29197.00\",\"1.029\"],[\"29297.00\",\"1.071\"],[\"71637.30\",\"0.043\"],[\"76413.10\",\"0.002\"],[\"78442.80\",\"14.241\"],[\"78801.00\",\"11.407\"],[\"78960.20\",\"6.738\"],[\"79565.40\",\"0.026\"],[\"79567.20\",\"0.002\"],[\"79567.30\",\"0.048\"],[\"79568.40\",\"0.001\"],[\"79573.30\",\"0.481\"],[\"79575.30\",\"0.137\"],[\"79575.70\",\"0.008\"],[\"79576.40\",\"0.003\"],[\"79576.50\",\"0.000\"],[\"79576.70\",\"2.258\"],[\"79577.80\",\"0.001\"]],\"a\":[[\"79597.10\",\"7.607\"],[\"79610.40\",\"0.562\"],[\"79610.70\",\"0.104\"],[\"79612.80\",\"0.003\"],[\"79616.60\",\"0.423\"],[\"79616.80\",\"0.003\"],[\"79617.80\",\"0.000\"],[\"79619.90\",\"0.000\"],[\"79620.90\",\"0.452\"],[\"79631.00\",\"0.005\"],[\"79631.10\",\"0.062\"],[\"79632.20\",\"0.019\"],[\"79806.80\",\"2.809\"],[\"80233.90\",\"7.091\"],[\"80297.20\",\"0.002\"],[\"80393.10\",\"107.479\"],[\"80552.30\",\"29.478\"]],\"st\":1}}"}
{"receive_ns":1788567722357511000,"stream":"btcusdt@bookTicker","event_type":"bookTicker","event_time_ms":1788567722373,"raw_json":"{\"stream\":\"btcusdt@bookTicker\",\"data\":{\"e\":\"bookTicker\",\"u\":11478507815130,\"s\":\"BTCUSDT\",\"ps\":\"BTCUSDT\",\"b\":\"79597.00\",\"B\":\"3.731\",\"a\":\"79597.10\",\"A\":\"7.607\",\"T\":1788567722373,\"E\":1788567722373,\"st\":1}}"}
{"receive_ns":1788567722376187000,"stream":"btcusdt@bookTicker","event_type":"bookTicker","event_time_ms":1788567722376,"raw_json":"{\"stream\":\"btcusdt@bookTicker\",\"data\":{\"e\":\"bookTicker\",\"u\":11478507815432,\"s\":\"BTCUSDT\",\"ps\":\"BTCUSDT\",\"b\":\"79597.00\",\"B\":\"3.780\",\"a\":\"79597.10\",\"A\":\"7.607\",\"T\":1788567722375,\"E\":1788567722376,\"st\":1}}"}
{"receive_ns":1788567722380529000,"stream":"btcusdt@bookTicker","event_type":"bookTicker","event_time_ms":1788567722377,"raw_json":"{\"stream\":\"btcusdt@bookTicker\",\"data\":{\"e\":\"bookTicker\",\"u\":11478507815531,\"s\":\"BTCUSDT\",\"ps\":\"BTCUSDT\",\"b\":\"79597.00\",\"B\":\"3.780\",\"a\":\"79597.10\",\"A\":\"7.605\",\"T\":1788567722377,\"E\":1788567722377,\"st\":1}}"}
{"receive_ns":1788567722396761000,"stream":"btcusdt@bookTicker","event_type":"bookTicker","event_time_ms":1788567722377,"raw_json":"{\"stream\":\"btcusdt@bookTicker\",\"data\":{\"e\":\"bookTicker\",\"u\":11478507815567,\"s\":\"BTCUSDT\",\"ps\":\"BTCUSDT\",\"b\":\"79597.00\",\"B\":\"3.852\",\"a\":\"79597.10\",\"A\":\"7.605\",\"T\":1788567722377,\"E\":1788567722377,\"st\":1}}"}
{"receive_ns":1788567722402383000,"stream":"btcusdt@bookTicker","event_type":"bookTicker","event_time_ms":1788567722378,"raw_json":"{\"stream\":\"btcusdt@bookTicker\",\"data\":{\"e\":\"bookTicker\",\"u\":11478507815654,\"s\":\"BTCUSDT\",\"ps\":\"BTCUSDT\",\"b\":\"79597.00\",\"B\":\"3.851\",\"a\":\"79597.10\",\"A\":\"7.605\",\"T\":1788567722378,\"E\":1788567722378,\"st\":1}}"}
{"receive_ns":1788567722407713000,"stream":"btcusdt@bookTicker","event_type":"bookTicker","event_time_ms":1788567722379,"raw_json":"{\"stream\":\"btcusdt@bookTicker\",\"data\":{\"e\":\"bookTicker\",\"u\":11478507815656,\"s\":\"BTCUSDT\",\"ps\":\"BTCUSDT\",\"b\":\"79597.00\",\"B\":\"3.851\",\"a\":\"79597.10\",\"A\":\"7.607\",\"T\":1788567722378,\"E\":1788567722379,\"st\":1}}"}
{"receive_ns":1788567722414683000,"stream":"btcusdt@depth@100ms","event_type":"depthUpdate","event_time_ms":1788567722409,"raw_json":"{\"stream\":\"btcusdt@depth@100ms\",\"data\":{\"e\":\"depthUpdate\",\"E\":1788567722409,\"T\":1788567722407,\"s\":\"BTCUSDT\",\"ps\":\"BTCUSDT\",\"U\":11478507809014,\"u\":11478507818157,\"pu\":11478507808751,\"b\":[[\"1000.00\",\"24.604\"],[\"29197.00\",\"1.197\"],[\"29297.00\",\"0.903\"],[\"63678.00\",\"0.000\"],[\"71637.30\",\"0.043\"],[\"71673.00\",\"0.003\"],[\"76413.10\",\"0.000\"],[\"78442.80\",\"15.196\"],[\"78641.80\",\"32.741\"],[\"78710.90\",\"0.380\"],[\"78801.00\",\"11.407\"],[\"78960.20\",\"6.991\"],[\"79589.60\",\"0.063\"],[\"79589.70\",\"0.001\"],[\"79589.80\",\"0.000\"],[\"79590.90\",\"0.096\"],[\"79591.00\",\"0.028\"],[\"79591.20\",\"0.032\"],[\"79597.00\",\"3.851\"]],\"a\":[[\"79597.10\",\"7.607\"],[\"79610.40\",\"0.123\"],[\"79610.70\",\"0.543\"],[\"80393.10\",\"107.479\"],[\"80711.50\",\"28.721\"],[\"81189.00\",\"10.512\"]],\"st\":1}}"}
{"receive_ns":1788567722445628000,"stream":"btcusdt@bookTicker","event_type":"bookTicker","event_time_ms":1788567722463,"raw_json":"{\"stream\":\"btcusdt@bookTicker\",\"data\":{\"e\":\"bookTicker\",\"u\":11478507821724,\"s\":\"BTCUSDT\",\"ps\":\"BTCUSDT\",\"b\":\"79597.00\",\"B\":\"3.834\",\"a\":\"79597.10\",\"A\":\"7.607\",\"T\":1788567722462,\"E\":1788567722463,\"st\":1}}"}
{"receive_ns":1788567722458144000,"stream":"btcusdt@bookTicker","event_type":"bookTicker","event_time_ms":1788567722466,"raw_json":"{\"stream\":\"btcusdt@bookTicker\",\"data\":{\"e\":\"bookTicker\",\"u\":11478507821918,\"s\":\"BTCUSDT\",\"ps\":\"BTCUSDT\",\"b\":\"79597.00\",\"B\":\"3.852\",\"a\":\"79597.10\",\"A\":\"7.607\",\"T\":1788567722465,\"E\":1788567722466,\"st\":1}}"}
{"receive_ns":1788567722474348000,"stream":"btcusdt@bookTicker","event_type":"bookTicker","event_time_ms":1788567722466,"raw_json":"{\"stream\":\"btcusdt@bookTicker\",\"data\":{\"e\":\"bookTicker\",\"u\":11478507821967,\"s\":\"BTCUSDT\",\"ps\":\"BTCUSDT\",\"b\":\"79597.00\",\"B\":\"3.853\",\"a\":\"79597.10\",\"A\":\"7.607\",\"T\":1788567722466,\"E\":1788567722466,\"st\":1}}"}
{"receive_ns":1788567722490740000,"stream":"btcusdt@bookTicker","event_type":"bookTicker","event_time_ms":1788567722495,"raw_json":"{\"stream\":\"btcusdt@bookTicker\",\"data\":{\"e\":\"bookTicker\",\"u\":11478507824045,\"s\":\"BTCUSDT\",\"ps\":\"BTCUSDT\",\"b\":\"79597.00\",\"B\":\"3.731\",\"a\":\"79597.10\",\"A\":\"7.607\",\"T\":1788567722495,\"E\":1788567722495,\"st\":1}}"}
{"receive_ns":1788567722507145000,"stream":"btcusdt@bookTicker","event_type":"bookTicker","event_time_ms":1788567722498,"raw_json":"{\"stream\":\"btcusdt@bookTicker\",\"data\":{\"e\":\"bookTicker\",\"u\":11478507824316,\"s\":\"BTCUSDT\",\"ps\":\"BTCUSDT\",\"b\":\"79597.00\",\"B\":\"3.852\",\"a\":\"79597.10\",\"A\":\"7.607\",\"T\":1788567722498,\"E\":1788567722498,\"st\":1}}"}
{"receive_ns":1788567722523638000,"stream":"btcusdt@depth@100ms","event_type":"depthUpdate","event_time_ms":1788567722511,"raw_json":"{\"stream\":\"btcusdt@depth@100ms\",\"data\":{\"e\":\"depthUpdate\",\"E\":1788567722511,\"T\":1788567722509,\"s\":\"BTCUSDT\",\"ps\":\"BTCUSDT\",\"U\":11478507818282,\"u\":11478507824964,\"pu\":11478507818157,\"b\":[[\"29197.00\",\"1.386\"],[\"29297.00\",\"0.714\"],[\"71637.30\",\"0.043\"],[\"71673.00\",\"0.000\"],[\"72800.00\",\"103.112\"],[\"75806.70\",\"0.001\"],[\"76413.10\",\"0.002\"],[\"78801.00\",\"11.407\"],[\"79199.00\",\"4.246\"],[\"79495.10\",\"0.025\"],[\"79589.90\",\"0.000\"],[\"79591.30\",\"0.126\"],[\"79597.00\",\"3.852\"]],\"a\":[[\"79621.00\",\"0.065\"],[\"80393.10\",\"107.479\"],[\"87556.90\",\"0.000\"]],\"st\":1}}"}
{"receive_ns":1788567722569100000,"stream":"btcusdt@bookTicker","event_type":"bookTicker","event_time_ms":1788567722582,"raw_json":"{\"stream\":\"btcusdt@bookTicker\",\"data\":{\"e\":\"bookTicker\",\"u\":11478507831174,\"s\":\"BTCUSDT\",\"ps\":\"BTCUSDT\",\"b\":\"79597.00\",\"B\":\"3.853\",\"a\":\"79597.10\",\"A\":\"7.607\",\"T\":1788567722582,\"E\":1788567722582,\"st\":1}}"}
{"receive_ns":1788567722599479000,"stream":"btcusdt@depth@100ms","event_type":"depthUpdate","event_time_ms":1788567722613,"raw_json":"{\"stream\":\"btcusdt@depth@100ms\",\"data\":{\"e\":\"depthUpdate\",\"E\":1788567722613,\"T\":1788567722610,\"s\":\"BTCUSDT\",\"ps\":\"BTCUSDT\",\"U\":11478507825084,\"u\":11478507833209,\"pu\":11478507824964,\"b\":[[\"1000.00\",\"24.604\"],[\"29197.00\",\"1.561\"],[\"29297.00\",\"0.539\"],[\"63678.00\",\"0.004\"],[\"71637.30\",\"0.043\"],[\"75617.10\",\"0.027\"],[\"75617.20\",\"0.008\"],[\"76413.10\",\"0.000\"],[\"78801.00\",\"11.407\"],[\"78960.20\",\"7.749\"],[\"79530.50\",\"0.002\"],[\"79539.80\",\"0.006\"],[\"79583.80\",\"0.536\"],[\"79583.90\",\"0.530\"],[\"79584.10\",\"0.071\"],[\"79584.40\",\"0.010\"],[\"79587.50\",\"0.002\"],[\"79590.00\",\"0.094\"],[\"79590.20\",\"0.102\"],[\"79590.60\",\"0.254\"],[\"79590.80\",\"0.031\"],[\"79591.00\",\"0.026\"],[\"79591.50\",\"0.026\"],[\"79591.70\",\"0.029\"],[\"79597.00\",\"3.853\"]],\"a\":[[\"79597.20\",\"0.009\"],[\"79605.90\",\"0.254\"],[\"79607.20\",\"0.004\"],[\"80393.10\",\"107.479\"],[\"80472.70\",\"5.645\"],[\"80552.30\",\"30.718\"],[\"80577.80\",\"2.894\"],[\"80598.70\",\"0.000\"],[\"80711.50\",\"30.576\"],[\"81268.60\",\"0.003\"]],\"st\":1}}"}
{"receive_ns":1788567722684348000,"stream":"btcusdt@bookTicker","event_type":"bookTicker","event_time_ms":1788567722699,"raw_json":"{\"stream\":\"btcusdt@bookTicker\",\"data\":{\"e\":\"bookTicker\",\"u\":11478507839353,\"s\":\"BTCUSDT\",\"ps\":\"BTCUSDT\",\"b\":\"79597.00\",\"B\":\"3.799\",\"a\":\"79597.10\",\"A\":\"7.607\",\"T\":1788567722699,\"E\":1788567722699,\"st\":1}}"}
{"receive_ns":1788567722700510000,"stream":"btcusdt@bookTicker","event_type":"bookTicker","event_time_ms":1788567722702,"raw_json":"{\"stream\":\"btcusdt@bookTicker\",\"data\":{\"e\":\"bookTicker\",\"u\":11478507839598,\"s\":\"BTCUSDT\",\"ps\":\"BTCUSDT\",\"b\":\"79597.00\",\"B\":\"3.844\",\"a\":\"79597.10\",\"A\":\"7.607\",\"T\":1788567722701,\"E\":1788567722702,\"st\":1}}"}
{"receive_ns":1788567722710231000,"stream":"btcusdt@depth@100ms","event_type":"depthUpdate","event_time_ms":1788567722715,"raw_json":"{\"stream\":\"btcusdt@depth@100ms\",\"data\":{\"e\":\"depthUpdate\",\"E\":1788567722715,\"T\":1788567722713,\"s\":\"BTCUSDT\",\"ps\":\"BTCUSDT\",\"U\":11478507833424,\"u\":11478507840291,\"pu\":11478507833209,\"b\":[[\"1000.00\",\"24.604\"],[\"29197.00\",\"1.743\"],[\"29297.00\",\"0.357\"],[\"63678.00\",\"0.002\"],[\"71637.30\",\"0.043\"],[\"78466.70\",\"2.601\"],[\"78566.50\",\"0.004\"],[\"78568.80\",\"0.056\"],[\"78605.00\",\"3.001\"],[\"78607.30\",\"0.055\"],[\"78801.00\",\"11.407\"],[\"79199.00\",\"4.245\"],[\"79460.70\",\"0.003\"],[\"79475.40\",\"0.000\"],[\"79501.40\",\"0.046\"],[\"79541.20\",\"0.002\"],[\"79584.60\",\"0.347\"],[\"79597.00\",\"3.844\"]],\"a\":[[\"79668.80\",\"0.035\"],[\"79719.60\",\"0.001\"],[\"79804.90\",\"0.776\"],[\"79995.10\",\"4.367\"],[\"80375.90\",\"1.213\"],[\"80393.10\",\"107.479\"],[\"80465.70\",\"0.186\"],[\"80614.60\",\"7.245\"],[\"80706.50\",\"0.374\"],[\"80716.40\",\"0.008\"],[\"80717.30\",\"0.374\"],[\"80727.20\",\"0.000\"],[\"80727.40\",\"2.524\"],[\"81189.00\",\"10.515\"]],\"st\":1}}"}
{"receive_ns":1788567722727617000,"stream":"btcusdt@bookTicker","event_type":"bookTicker","event_time_ms":1788567722724,"raw_json":"{\"stream\":\"btcusdt@bookTicker\",\"data\":{\"e\":\"bookTicker\",\"u\":11478507841205,\"s\":\"BTCUSDT\",\"ps\":\"BTCUSDT\",\"b\":\"79597.00\",\"B\":\"3.844\",\"a\":\"79597.10\",\"A\":\"7.608\",\"T\":1788567722724,\"E\":1788567722724,\"st\":1}}"}
{"receive_ns":1788567722796535000,"stream":"btcusdt@depth@100ms","event_type":"depthUpdate","event_time_ms":1788567722817,"raw_json":"{\"stream\":\"btcusdt@depth@100ms\",\"data\":{\"e\":\"depthUpdate\",\"E\":1788567722817,\"T\":1788567722816,\"s\":\"BTCUSDT\",\"ps\":\"BTCUSDT\",\"U\":11478507840500,\"u\":11478507848263,\"pu\":11478507840291,\"b\":[[\"29097.00\",\"0.056\"],[\"29197.00\",\"1.806\"],[\"29297.00\",\"0.238\"],[\"55718.00\",\"0.004\"],[\"63678.00\",\"0.000\"],[\"71637.30\",\"0.043\"],[\"76413.10\",\"0.002\"],[\"76413.20\",\"0.000\"],[\"78005.20\",\"1.758\"],[\"78093.60\",\"0.029\"],[\"78144.50\",\"0.000\"],[\"78182.00\",\"0.098\"],[\"78270.50\",\"0.028\"],[\"78358.90\",\"0.028\"],[\"78447.40\",\"0.029\"],[\"78535.80\",\"0.678\"],[\"78622.10\",\"0.001\"],[\"78624.20\",\"0.031\"],[\"78712.70\",\"0.028\"],[\"78801.00\",\"11.407\"],[\"78801.10\",\"0.028\"],[\"79199.00\",\"4.235\"],[\"79475.40\",\"0.470\"],[\"79576.60\",\"0.002\"],[\"79588.00\",\"0.004\"],[\"79588.10\",\"0.077\"],[\"79590.30\",\"0.000\"],[\"79590.40\",\"0.004\"],[\"79592.00\",\"0.031\"],[\"79592.10\",\"0.207\"],[\"79592.30\",\"0.000\"],[\"79592.50\",\"0.121\"]],\"a\":[[\"79597.10\",\"7.608\"],[\"79719.60\",\"0.423\"],[\"79818.80\",\"6.772\"],[\"80107.40\",\"0.000\"],[\"80393.10\",\"107.507\"],[\"80481.50\",\"0.028\"],[\"80570.00\",\"0.864\"],[\"80658.40\",\"0.028\"],[\"80671.70\",\"11.589\"],[\"80711.50\",\"30.823\"],[\"80746.80\",\"0.028\"],[\"80835.30\",\"0.032\"],[\"80923.70\",\"0.028\"]],\"st\":1}}"}
{"receive_ns":1788567722902114000,"stream":"btcusdt@depth@100ms","event_type":"depthUpdate","event_time_ms":1788567722919,"raw_json":"{\"stream\":\"btcusdt@depth@100ms\",\"data\":{\"e\":\"depthUpdate\",\"E\":1788567722919,\"T\":1788567722918,\"s\":\"BTCUSDT\",\"ps\":\"BTCUSDT\",\"U\":11478507848322,\"u\":11478507854712,\"pu\":11478507848263,\"b\":[[\"1000.00\",\"24.604\"],[\"29097.00\",\"0.119\"],[\"29197.00\",\"1.862\"],[\"29297.00\",\"0.119\"],[\"63678.00\",\"0.000\"],[\"71637.30\",\"0.043\"],[\"75617.10\",\"0.022\"],[\"76413.10\",\"0.000\"],[\"78801.00\",\"11.407\"],[\"79475.40\",\"0.000\"],[\"79546.40\",\"0.065\"],[\"79554.50\",\"0.003\"],[\"79557.40\",\"0.071\"],[\"79568.90\",\"0.051\"],[\"79589.30\",\"0.161\"],[\"79590.10\",\"0.000\"],[\"79590.50\",\"0.000\"],[\"79592.20\",\"0.026\"]],\"a\":[[\"79719.60\",\"0.001\"],[\"80393.10\",\"107.507\"],[\"80592.10\",\"11.670\"],[\"80645.20\",\"9.285\"],[\"81012.20\",\"0.028\"],[\"81100.60\",\"0.028\"],[\"81189.00\",\"10.543\"]],\"st\":1}}"}
{"receive_ns":1788567722988979000,"stream":"btcusdt@bookTicker","event_type":"bookTicker","event_time_ms":1788567723004,"raw_json":"{\"stream\":\"btcusdt@bookTicker\",\"data\":{\"e\":\"bookTicker\",\"u\":11478507861433,\"s\":\"BTCUSDT\",\"ps\":\"BTCUSDT\",\"b\":\"79597.00\",\"B\":\"3.844\",\"a\":\"79597.10\",\"A\":\"7.611\",\"T\":1788567723004,\"E\":1788567723004,\"st\":1}}"}
