{"receive_ns":1788567722994262000,"stream":"btcusdt@bookTicker","event_type":"bookTicker","event_time_ms":1788567723013,"raw_json":"{\"stream\":\"btcusdt@bookTicker\",\"data\":{\"e\":\"bookTicker\",\"u\":11478507862238,\"s\":\"BTCUSDT\",\"ps\":\"BTCUSDT\",\"b\":\"79597.00\",\"B\":\"3.796\",\"a\":\"79597.10\",\"A\":\"7.611\",\"T\":1788567723013,\"E\":1788567723013,\"st\":1}}"}
{"receive_ns":1788567723005119000,"stream":"btcusdt@bookTicker","event_type":"bookTicker","event_time_ms":1788567723016,"raw_json":"{\"stream\":\"btcusdt@bookTicker\",\"data\":{\"e\":\"bookTicker\",\"u\":11478507862470,\"s\":\"BTCUSDT\",\"ps\":\"BTCUSDT\",\"b\":\"79597.00\",\"B\":\"3.846\",\"a\":\"79597.10\",\"A\":\"7.611\",\"T\":1788567723016,\"E\":1788567723016,\"st\":1}}"}
{"receive_ns":1788567723021349000,"stream":"btcusdt@bookTicker","event_type":"bookTicker","event_time_ms":1788567723017,"raw_json":"{\"stream\":\"btcusdt@bookTicker\",\"data\":{\"e\":\"bookTicker\",\"u\":11478507862563,\"s\":\"BTCUSDT\",\"ps\":\"BTCUSDT\",\"b\":\"79597.00\",\"B\":\"3.845\",\"a\":\"79597.10\",\"A\":\"7.611\",\"T\":1788567723017,\"E\":1788567723017,\"st\":1}}"}
{"receive_ns":1788567723037259000,"stream":"btcusdt@bookTicker","event_type":"bookTicker","event_time_ms":1788567723019,"raw_json":"{\"stream\":\"btcusdt@bookTicker\",\"data\":{\"e\":\"bookTicker\",\"u\":11478507862685,\"s\":\"BTCUSDT\",\"ps\":\"BTCUSDT\",\"b\":\"79597.00\",\"B\":\"3.846\",\"a\":\"79597.10\",\"A\":\"7.611\",\"T\":1788567723019,\"E\":1788567723019,\"st\":1}}"}
{"receive_ns":1788567723053075000,"stream":"btcusdt@depth@100ms","event_type":"depthUpdate","event_time_ms":1788567723021,"raw_json":"{\"stream\":\"btcusdt@depth@100ms\",\"data\":{\"e\":\"depthUpdate\",\"E\":1788567723021,\"T\":1788567723020,\"s\":\"BTCUSDT\",\"ps\":\"BTCUSDT\",\"U\":11478507854864,\"u\":11478507862800,\"pu\":11478507854712,\"b\":[[\"1000.00\",\"24.604\"],[\"29097.00\",\"0.189\"],[\"29197.00\",\"1.897\"],[\"29297.00\",\"0.014\"],[\"63678.00\",\"0.000\"],[\"71637.30\",\"0.043\"],[\"75617.10\",\"0.024\"],[\"76413.10\",\"0.002\"],[\"78259.80\",\"2.040\"],[\"78721.40\",\"8.119\"],[\"78801.00\",\"11.409\"],[\"79199.00\",\"4.236\"],[\"79436.00\",\"2.682\"],[\"79475.40\",\"0.531\"],[\"79525.30\",\"0.635\"],[\"79549.20\",\"0.208\"],[\"79564.00\",\"0.005\"],[\"79565.10\",\"0.983\"],[\"79565.20\",\"2.477\"],[\"79565.60\",\"0.004\"],[\"79574.80\",\"0.001\"],[\"79584.50\",\"0.002\"],[\"79585.40\",\"0.131\"],[\"79587.10\",\"0.020\"],[\"79588.10\",\"0.077\"],[\"79588.30\",\"0.003\"],[\"79590.40\",\"0.001\"],[\"79592.10\",\"0.207\"],[\"79592.20\",\"0.000\"],[\"79592.30\",\"0.026\"],[\"79597.00\",\"3.846\"]],\"a\":[[\"79597.10\",\"7.611\"],[\"79599.10\",\"0.078\"],[\"79692.70\",\"0.004\"],[\"79719.60\",\"0.485\"],[\"79759.00\",\"2.305\"],[\"79995.10\",\"4.366\"],[\"80393.10\",\"107.507\"],[\"80552.30\",\"29.478\"],[\"80711.50\",\"28.967\"],[\"80751.30\",\"14.137\"]],\"st\":1}}"}
{"receive_ns":1788567723064731000,"stream":"btcusdt@bookTicker","event_type":"bookTicker","event_time_ms":1788567723028,"raw_json":"{\"stream\":\"btcusdt@bookTicker\",\"data\":{\"e\":\"bookTicker\",\"u\":11478507863291,\"s\":\"BTCUSDT\",\"ps\":\"BTCUSDT\",\"b\":\"79597.00\",\"B\":\"3.846\",\"a\":\"79597.10\",\"A\":\"7.625\",\"T\":1788567723027,\"E\":1788567723028,\"st\":1}}"}
{"receive_ns":1788567723070425000,"stream":"btcusdt@bookTicker","event_type":"bookTicker","event_time_ms":1788567723095,"raw_json":"{\"stream\":\"btcusdt@bookTicker\",\"data\":{\"e\":\"bookTicker\",\"u\":11478507868804,\"s\":\"BTCUSDT\",\"ps\":\"BTCUSDT\",\"b\":\"79597.00\",\"B\":\"3.774\",\"a\":\"79597.10\",\"A\":\"7.625\",\"T\":1788567723095,\"E\":1788567723095,\"st\":1}}"}
{"receive_ns":1788567723102300000,"stream":"btcusdt@bookTicker","event_type":"bookTicker","event_time_ms":1788567723120,"raw_json":"{\"stream\":\"btcusdt@bookTicker\",\"data\":{\"e\":\"bookTicker\",\"u\":11478507871013,\"s\":\"BTCUSDT\",\"ps\":\"BTCUSDT\",\"b\":\"79597.00\",\"B\":\"3.774\",\"a\":\"79597.10\",\"A\":\"7.636\",\"T\":1788567723120,\"E\":1788567723120,\"st\":1}}"}
{"receive_ns":1788567723108298000,"stream":"btcusdt@depth@100ms","event_type":"depthUpdate","event_time_ms":1788567723123,"raw_json":"{\"stream\":\"btcusdt@depth@100ms\",\"data\":{\"e\":\"depthUpdate\",\"E\":1788567723123,\"T\":1788567723121,\"s\":\"BTCUSDT\",\"ps\":\"BTCUSDT\",\"U\":11478507862890,\"u\":11478507871178,\"pu\":11478507862800,\"b\":[[\"29097.00\",\"0.357\"],[\"29197.00\",\"1.743\"],[\"29297.00\",\"0.000\"],[\"63678.00\",\"0.000\"],[\"71637.30\",\"0.043\"],[\"78801.00\",\"11.409\"],[\"79199.00\",\"4.246\"],[\"79449.90\",\"2.080\"],[\"79450.00\",\"3.376\"],[\"79542.30\",\"0.829\"],[\"79558.20\",\"0.692\"],[\"79564.70\",\"0.853\"],[\"79565.10\",\"0.858\"],[\"79567.30\",\"0.048\"],[\"79568.50\",\"0.002\"],[\"79573.30\",\"0.481\"],[\"79574.80\",\"0.629\"],[\"79575.20\",\"0.003\"],[\"79575.70\",\"0.008\"],[\"79576.70\",\"2.258\"],[\"79577.90\",\"0.255\"],[\"79582.70\",\"0.194\"],[\"79584.60\",\"0.350\"],[\"79584.90\",\"0.002\"],[\"79585.40\",\"0.129\"],[\"79587.50\",\"0.000\"],[\"79588.10\",\"0.001\"],[\"79590.50\",\"0.002\"],[\"79590.70\",\"0.027\"],[\"79590.80\",\"0.029\"],[\"79592.00\",\"0.005\"],[\"79592.10\",\"0.181\"],[\"79592.30\",\"0.000\"],[\"79592.60\",\"0.000\"],[\"79597.00\",\"3.774\"]],\"a\":[[\"79597.10\",\"7.636\"],[\"79610.50\",\"2.328\"],[\"79610.70\",\"0.104\"],[\"79612.80\",\"0.003\"],[\"79613.20\",\"0.002\"],[\"79616.60\",\"0.423\"],[\"79617.80\",\"0.000\"],[\"79625.30\",\"0.009\"],[\"79625.90\",\"0.007\"],[\"79626.30\",\"0.002\"],[\"79631.10\",\"0.062\"],[\"79632.30\",\"0.001\"],[\"79696.20\",\"0.002\"],[\"79696.70\",\"0.001\"],[\"79696.80\",\"0.000\"],[\"80393.10\",\"107.507\"],[\"80751.30\",\"14.137\"]],\"st\":1}}"}
{"receive_ns":1788567723119738000,"stream":"btcusdt@bookTicker","event_type":"bookTicker","event_time_ms":1788567723137,"raw_json":"{\"stream\":\"btcusdt@bookTicker\",\"data\":{\"e\":\"bookTicker\",\"u\":11478507872027,\"s\":\"BTCUSDT\",\"ps\":\"BTCUSDT\",\"b\":\"79597.00\",\"B\":\"3.774\",\"a\":\"79597.10\",\"A\":\"7.637\",\"T\":1788567723137,\"E\":1788567723137,\"st\":1}}"}
{"receive_ns":1788567723176794000,"stream":"btcusdt@bookTicker","event_type":"bookTicker","event_time_ms":1788567723190,"raw_json":"{\"stream\":\"btcusdt@bookTicker\",\"data\":{\"e\":\"bookTicker\",\"u\":11478507875460,\"s\":\"BTCUSDT\",\"ps\":\"BTCUSDT\",\"b\":\"79597.00\",\"B\":\"3.774\",\"a\":\"79597.10\",\"A\":\"7.636\",\"T\":1788567723190,\"E\":1788567723190,\"st\":1}}"}
{"receive_ns":1788567723182823000,"stream":"btcusdt@trade","event_type":"trade","event_time_ms":1788567723190,"raw_json":"{\"stream\":\"btcusdt@trade\",\"data\":{\"e\":\"trade\",\"E\":1788567723190,\"T\":1788567723190,\"s\":\"BTCUSDT\",\"t\":8054122580,\"p\":\"79597.10\",\"q\":\"0.001\",\"X\":\"MARKET\",\"m\":false,\"st\":1}}"}
{"receive_ns":1788567723209590000,"stream":"btcusdt@depth@100ms","event_type":"depthUpdate","event_time_ms":1788567723225,"raw_json":"{\"stream\":\"btcusdt@depth@100ms\",\"data\":{\"e\":\"depthUpdate\",\"E\":1788567723225,\"T\":1788567723221,\"s\":\"BTCUSDT\",\"ps\":\"BTCUSDT\",\"U\":11478507871258,\"u\":11478507877487,\"pu\":11478507871178,\"b\":[[\"1000.00\",\"24.604\"],[\"29097.00\",\"0.532\"],[\"29197.00\",\"1.568\"],[\"63677.60\",\"0.000\"],[\"71637.30\",\"0.043\"],[\"75617.20\",\"0.006\"],[\"76413.10\",\"0.000\"],[\"78005.10\",\"10.828\"],[\"78801.00\",\"11.407\"],[\"79450.00\",\"3.344\"],[\"79450.20\",\"0.371\"],[\"79471.30\",\"0.000\"],[\"79471.40\",\"0.003\"],[\"79518.00\",\"0.039\"],[\"79518.10\",\"0.050\"],[\"79584.90\",\"0.000\"],[\"79585.30\",\"0.002\"],[\"79588.00\",\"0.080\"],[\"79590.70\",\"0.028\"]],\"a\":[[\"79597.10\",\"7.636\"],[\"79610.50\",\"1.889\"],[\"79610.70\",\"0.543\"],[\"79691.80\",\"0.123\"],[\"79692.70\",\"0.003\"],[\"79692.80\",\"0.001\"],[\"79693.60\",\"0.000\"],[\"79693.70\",\"0.000\"],[\"79701.30\",\"0.001\"],[\"79703.20\",\"0.001\"],[\"79703.30\",\"0.000\"],[\"79704.60\",\"0.041\"],[\"79705.30\",\"0.000\"],[\"79705.60\",\"0.000\"],[\"79806.80\",\"2.809\"],[\"80393.10\",\"107.507\"],[\"81189.00\",\"10.540\"]],\"st\":1}}"}
{"receive_ns":1788567723248733000,"stream":"btcusdt@bookTicker","event_type":"bookTicker","event_time_ms":1788567723264,"raw_json":"{\"stream\":\"btcusdt@bookTicker\",\"data\":{\"e\":\"bookTicker\",\"u\":11478507880259,\"s\":\"BTCUSDT\",\"ps\":\"BTCUSDT\",\"b\":\"79597.00\",\"B\":\"2.935\",\"a\":\"79597.10\",\"A\":\"7.636\",\"T\":1788567723264,\"E\":1788567723264,\"st\":1}}"}
{"receive_ns":1788567723266296000,"stream":"btcusdt@bookTicker","event_type":"bookTicker","event_time_ms":1788567723276,"raw_json":"{\"stream\":\"btcusdt@bookTicker\",\"data\":{\"e\":\"bookTicker\",\"u\":11478507881475,\"s\":\"BTCUSDT\",\"ps\":\"BTCUSDT\",\"b\":\"79597.00\",\"B\":\"3.773\",\"a\":\"79597.10\",\"A\":\"7.636\",\"T\":1788567723276,\"E\":1788567723276,\"st\":1}}"}
{"receive_ns":1788567723272345000,"stream":"btcusdt@bookTicker","event_type":"bookTicker","event_time_ms":1788567723277,"raw_json":"{\"stream\":\"btcusdt@bookTicker\",\"data\":{\"e\":\"bookTicker\",\"u\":11478507881586,\"s\":\"BTCUSDT\",\"ps\":\"BTCUSDT\",\"b\":\"79597.00\",\"B\":\"3.772\",\"a\":\"79597.10\",\"A\":\"7.636\",\"T\":1788567723277,\"E\":1788567723277,\"st\":1}}"}
{"receive_ns":1788567723286735000,"stream":"btcusdt@bookTicker","event_type":"bookTicker","event_time_ms":1788567723278,"raw_json":"{\"stream\":\"btcusdt@bookTicker\",\"data\":{\"e\":\"bookTicker\",\"u\":11478507881702,\"s\":\"BTCUSDT\",\"ps\":\"BTCUSDT\",\"b\":\"79597.00\",\"B\":\"3.844\",\"a\":\"79597.10\",\"A\":\"7.636\",\"T\":1788567723278,\"E\":1788567723278,\"st\":1}}"}
{"receive_ns":1788567723298134000,"stream":"btcusdt@bookTicker","event_type":"bookTicker","event_time_ms":1788567723279,"raw_json":"{\"stream\":\"btcusdt@bookTicker\",\"data\":{\"e\":\"bookTicker\",\"u\":11478507881791,\"s\":\"BTCUSDT\",\"ps\":\"BTCUSDT\",\"b\":\"79597.00\",\"B\":\"3.845\",\"a\":\"79597.10\",\"A\":\"7.636\",\"T\":1788567723279,\"E\":1788567723279,\"st\":1}}"}
{"receive_ns":1788567723311304000,"stream":"btcusdt@depth@100ms","event_type":"depthUpdate","event_time_ms":1788567723327,"raw_json":"{\"stream\":\"btcusdt@depth@100ms\",\"data\":{\"e\":\"depthUpdate\",\"E\":1788567723327,\"T\":1788567723326,\"s\":\"BTCUSDT\",\"ps\":\"BTCUSDT\",\"U\":11478507877729,\"u\":11478507885445,\"pu\":11478507877487,\"b\":[[\"1000.00\",\"24.604\"],[\"29097.00\",\"0.714\"],[\"29197.00\",\"1.386\"],[\"71637.30\",\"0.043\"],[\"76413.10\",\"0.002\"],[\"78602.00\",\"16.723\"],[\"78801.00\",\"11.409\"],[\"79025.80\",\"0.010\"],[\"79039.80\",\"0.081\"],[\"79460.70\",\"0.004\"],[\"79507.80\",\"0.000\"],[\"79542.30\",\"0.000\"],[\"79558.20\",\"0.001\"],[\"79583.90\",\"0.530\"],[\"79584.90\",\"0.002\"],[\"79585.30\",\"0.000\"],[\"79587.30\",\"0.036\"],[\"79588.00\",\"0.004\"],[\"79591.80\",\"0.026\"],[\"79592.70\",\"0.001\"],[\"79595.40\",\"0.002\"],[\"79595.60\",\"0.047\"],[\"79596.70\",\"0.002\"],[\"79596.80\",\"0.158\"],[\"79597.00\",\"3.845\"]],\"a\":[[\"79610.60\",\"0.003\"],[\"79614.50\",\"0.002\"],[\"79614.90\",\"0.628\"],[\"79615.40\",\"0.004\"],[\"79619.70\",\"0.454\"],[\"79620.90\",\"0.000\"],[\"79623.90\",\"0.016\"],[\"79626.60\",\"0.005\"],[\"80194.10\",\"3.738\"],[\"80393.10\",\"107.507\"],[\"80751.30\",\"15.003\"]],\"st\":1}}"}
{"receive_ns":1788567723366914000,"stream":"btcusdt@bookTicker","event_type":"bookTicker","event_time_ms":1788567723378,"raw_json":"{\"stream\":\"btcusdt@bookTicker\",\"data\":{\"e\":\"bookTicker\",\"u\":11478507889689,\"s\":\"BTCUSDT\",\"ps\":\"BTCUSDT\",\"b\":\"79597.00\",\"B\":\"3.796\",\"a\":\"79597.10\",\"A\":\"7.636\",\"T\":1788567723377,\"E\":1788567723378,\"st\":1}}"}
{"receive_ns":1788567723384411000,"stream":"btcusdt@bookTicker","event_type":"bookTicker","event_time_ms":1788567723380,"raw_json":"{\"stream\":\"btcusdt@bookTicker\",\"data\":{\"e\":\"bookTicker\",\"u\":11478507889881,\"s\":\"BTCUSDT\",\"ps\":\"BTCUSDT\",\"b\":\"79597.00\",\"B\":\"3.846\",\"a\":\"79597.10\",\"A\":\"7.636\",\"T\":1788567723380,\"E\":1788567723380,\"st\":1}}"}
{"receive_ns":1788567723411259000,"stream":"btcusdt@depth@100ms","event_type":"depthUpdate","event_time_ms":1788567723429,"raw_json":"{\"stream\":\"btcusdt@depth@100ms\",\"data\":{\"e\":\"depthUpdate\",\"E\":1788567723429,\"T\":1788567723428,\"s\":\"BTCUSDT\",\"ps\":\"BTCUSDT\",\"U\":11478507885614,\"u\":11478507893653,\"pu\":11478507885445,\"b\":[[\"29097.00\",\"0.889\"],[\"29197.00\",\"1.211\"],[\"71637.30\",\"0.043\"],[\"76413.10\",\"0.000\"],[\"78097.20\",\"1.277\"],[\"78602.00\",\"16.875\"],[\"78801.00\",\"11.407\"],[\"79199.00\",\"4.236\"],[\"79283.00\",\"0.500\"],[\"79331.50\",\"0.000\"],[\"79331.80\",\"3.146\"],[\"79380.10\",\"0.000\"],[\"79382.80\",\"0.802\"],[\"79428.70\",\"1.309\"],[\"79477.30\",\"0.002\"],[\"79518.00\",\"0.089\"],[\"79518.10\",\"0.000\"],[\"79566.50\",\"0.049\"],[\"79567.30\",\"0.002\"],[\"79569.00\",\"0.453\"],[\"79570.50\",\"0.002\"],[\"79575.90\",\"0.408\"],[\"79576.70\",\"1.885\"],[\"79580.60\",\"0.000\"],[\"79584.90\",\"0.000\"],[\"79585.40\",\"0.131\"],[\"79587.80\",\"1.587\"],[\"79590.70\",\"0.002\"],[\"79590.80\",\"0.003\"],[\"79590.90\",\"0.070\"],[\"79591.90\",\"0.027\"],[\"79592.00\",\"0.031\"],[\"79592.20\",\"0.026\"],[\"79592.60\",\"0.026\"],[\"79596.90\",\"2.552\"],[\"79597.00\",\"3.846\"]],\"a\":[[\"79615.80\",\"0.372\"],[\"79616.60\",\"0.051\"],[\"79652.00\",\"0.523\"],[\"79655.60\",\"0.085\"],[\"79760.20\",\"0.193\"],[\"79762.10\",\"0.000\"],[\"79810.70\",\"0.000\"],[\"79859.30\",\"0.004\"],[\"79904.40\",\"0.296\"],[\"79904.90\",\"0.000\"],[\"79907.90\",\"0.000\"],[\"79956.40\",\"0.263\"],[\"79956.50\",\"0.027\"],[\"80011.00\",\"0.265\"],[\"80393.10\",\"107.507\"],[\"80552.30\",\"28.238\"],[\"80638.80\",\"0.000\"],[\"80711.50\",\"27.111\"]],\"st\":1}}"}
{"receive_ns":1788567723427519000,"stream":"btcusdt@bookTicker","event_type":"bookTicker","event_time_ms":1788567723432,"raw_json":"{\"stream\":\"btcusdt@bookTicker\",\"data\":{\"e\":\"bookTicker\",\"u\":11478507893965,\"s\":\"BTCUSDT\",\"ps\":\"BTCUSDT\",\"b\":\"79597.00\",\"B\":\"3.846\",\"a\":\"79597.10\",\"A\":\"7.637\",\"T\":1788567723431,\"E\":1788567723432,\"st\":1}}"}
{"receive_ns":1788567723509012000,"stream":"btcusdt@bookTicker","event_type":"bookTicker","event_time_ms":1788567723528,"raw_json":"{\"stream\":\"btcusdt@bookTicker\",\"data\":{\"e\":\"bookTicker\",\"u\":11478507901432,\"s\":\"BTCUSDT\",\"ps\":\"BTCUSDT\",\"b\":\"79597.00\",\"B\":\"3.796\",\"a\":\"79597.10\",\"A\":\"7.637\",\"T\":1788567723527,\"E\":1788567723528,\"st\":1}}"}
{"receive_ns":1788567723525213000,"stream":"btcusdt@depth@100ms","event_type":"depthUpdate","event_time_ms":1788567723531,"raw_json":"{\"stream\":\"btcusdt@depth@100ms\",\"data\":{\"e\":\"depthUpdate\",\"E\":1788567723531,\"T\":1788567723530,\"s\":\"BTCUSDT\",\"ps\":\"BTCUSDT\",\"U\":11478507893802,\"u\":11478507901689,\"pu\":11478507893653,\"b\":[[\"1000.00\",\"24.604\"],[\"29097.00\",\"1.071\"],[\"29197.00\",\"1.029\"],[\"71637.30\",\"0.043\"],[\"71673.00\",\"0.000\"],[\"76413.10\",\"0.002\"],[\"78448.90\",\"8.140\"],[\"78801.00\",\"12.674\"],[\"79501.40\",\"0.048\"],[\"79566.50\",\"0.003\"],[\"79567.60\",\"0.046\"],[\"79573.30\",\"0.042\"],[\"79574.90\",\"0.439\"],[\"79575.90\",\"0.035\"],[\"79577.10\",\"0.455\"],[\"79588.90\",\"0.001\"],[\"79597.00\",\"3.845\"]],\"a\":[[\"79597.10\",\"7.637\"],[\"79615.80\",\"0.000\"],[\"79616.30\",\"0.013\"],[\"79617.10\",\"0.372\"],[\"79618.00\",\"0.631\"],[\"79631.10\",\"0.016\"],[\"79631.70\",\"0.046\"],[\"79732.50\",\"0.002\"],[\"80393.10\",\"107.507\"],[\"80552.30\",\"29.478\"],[\"80711.50\",\"28.967\"],[\"80830.90\",\"6.920\"]],\"st\":1}}"}
{"receive_ns":1788567723542105000,"stream":"btcusdt@bookTicker","event_type":"bookTicker","event_time_ms":1788567723530,"raw_json":"{\"stream\":\"btcusdt@bookTicker\",\"data\":{\"e\":\"bookTicker\",\"u\":11478507901689,\"s\":\"BTCUSDT\",\"ps\":\"BTCUSDT\",\"b\":\"79597.00\",\"B\":\"3.845\",\"a\":\"79597.10\",\"A\":\"7.637\",\"T\":1788567723530,\"E\":1788567723530,\"st\":1}}"}
{"receive_ns":1788567723611457000,"stream":"btcusdt@depth@100ms","event_type":"depthUpdate","event_time_ms":1788567723633,"raw_json":"{\"stream\":\"btcusdt@depth@100ms\",\"data\":{\"e\":\"depthUpdate\",\"E\":1788567723633,\"T\":1788567723632,\"s\":\"BTCUSDT\",\"ps\":\"BTCUSDT\",\"U\":11478507901804,\"u\":11478507909045,\"pu\":11478507901689,\"b\":[[\"1000.00\",\"24.604\"],[\"29097.00\",\"1.246\"],[\"29197.00\",\"0.854\"],[\"71637.30\",\"0.043\"],[\"78801.00\",\"12.674\"],[\"79495.10\",\"0.013\"],[\"79569.00\",\"0.001\"],[\"79570.50\",\"0.454\"],[\"79573.30\",\"0.481\"],[\"79574.90\",\"0.000\"]],\"a\":[[\"79806.70\",\"4.855\"],[\"79806.80\",\"0.008\"],[\"80393.10\",\"107.507\"],[\"80910.50\",\"3.296\"]],\"st\":1}}"}
{"receive_ns":1788567723718513000,"stream":"btcusdt@depth@100ms","event_type":"depthUpdate","event_time_ms":1788567723735,"raw_json":"{\"stream\":\"btcusdt@depth@100ms\",\"data\":{\"e\":\"depthUpdate\",\"E\":1788567723735,\"T\":1788567723733,\"s\":\"BTCUSDT\",\"ps\":\"BTCUSDT\",\"U\":11478507909177,\"u\":11478507915615,\"pu\":11478507909045,\"b\":[[\"29097.00\",\"1.428\"],[\"29197.00\",\"0.672\"],[\"71637.30\",\"0.043\"],[\"76413.10\",\"0.000\"],[\"78482.60\",\"31.628\"],[\"78528.50\",\"0.000\"],[\"78568.80\",\"0.050\"],[\"78571.20\",\"0.005\"],[\"78585.70\",\"0.000\"],[\"78590.40\",\"0.006\"],[\"78607.30\",\"0.050\"],[\"78609.60\",\"0.104\"],[\"78641.80\",\"31.471\"],[\"78801.00\",\"12.674\"],[\"79199.00\",\"4.236\"],[\"79525.90\",\"2.135\"],[\"79526.10\",\"0.674\"],[\"79561.20\",\"0.025\"],[\"79592.60\",\"0.000\"]],\"a\":[[\"79663.40\",\"21.933\"],[\"79664.90\",\"1.990\"],[\"79665.40\",\"1.810\"],[\"79666.10\",\"0.015\"],[\"79806.70\",\"2.806\"],[\"79995.10\",\"4.365\"],[\"80313.50\",\"1.128\"],[\"80393.10\",\"107.507\"],[\"80706.50\",\"0.000\"],[\"80714.80\",\"0.374\"],[\"80717.30\",\"0.000\"],[\"80725.50\",\"3.567\"],[\"80776.70\",\"3.220\"],[\"84500.00\",\"141.158\"]],\"st\":1}}"}
{"receive_ns":1788567723819396000,"stream":"btcusdt@depth@100ms","event_type":"depthUpdate","event_time_ms":1788567723837,"raw_json":"{\"stream\":\"btcusdt@depth@100ms\",\"data\":{\"e\":\"depthUpdate\",\"E\":1788567723837,\"T\":1788567723834,\"s\":\"BTCUSDT\",\"ps\":\"BTCUSDT\",\"U\":11478507915743,\"u\":11478507921160,\"pu\":11478507915615,\"b\":[[\"1000.00\",\"24.604\"],[\"29097.00\",\"1.603\"],[\"29197.00\",\"0.497\"],[\"55717.90\",\"0.002\"],[\"71637.30\",\"0.043\"],[\"76413.10\",\"0.002\"],[\"78801.00\",\"12.674\"],[\"78866.70\",\"6.879\"],[\"78880.60\",\"11.264\"],[\"79185.00\",\"0.000\"],[\"79187.60\",\"0.152\"],[\"79199.00\",\"4.237\"]],\"a\":[[\"79623.90\",\"0.010\"],[\"79663.40\",\"0.000\"],[\"79671.50\",\"21.986\"],[\"80393.10\",\"107.507\"],[\"80830.90\",\"7.785\"],[\"80910.50\",\"4.160\"],[\"81959.40\",\"0.000\"]],\"st\":1}}"}
{"receive_ns":1788567723923284000,"stream":"btcusdt@depth@100ms","event_type":"depthUpdate","event_time_ms":1788567723939,"raw_json":"{\"stream\":\"btcusdt@depth@100ms\",\"data\":{\"e\":\"depthUpdate\",\"E\":1788567723939,\"T\":1788567723937,\"s\":\"BTCUSDT\",\"ps\":\"BTCUSDT\",\"U\":11478507921334,\"u\":11478507927204,\"pu\":11478507921160,\"b\":[[\"1000.00\",\"24.604\"],[\"29097.00\",\"1.757\"],[\"29197.00\",\"0.329\"],[\"29497.00\",\"0.014\"],[\"71637.30\",\"0.043\"],[\"76413.10\",\"0.000\"],[\"78005.10\",\"10.825\"],[\"78482.60\",\"29.720\"],[\"78528.10\",\"0.020\"],[\"78641.80\",\"31.471\"],[\"78801.00\",\"11.407\"],[\"78858.40\",\"1.297\"],[\"79587.80\",\"1.511\"],[\"79590.50\",\"0.028\"],[\"79590.60\",\"0.280\"],[\"79590.70\",\"0.028\"],[\"79590.80\",\"0.029\"],[\"79590.90\",\"0.096\"],[\"79591.50\",\"0.000\"],[\"79591.70\",\"0.003\"],[\"79591.80\",\"0.026\"],[\"79591.90\",\"0.001\"],[\"79592.00\",\"0.031\"],[\"79592.20\",\"0.000\"]],\"a\":[[\"79666.10\",\"22.000\"],[\"79671.50\",\"0.001\"],[\"80233.90\",\"7.339\"],[\"80393.10\",\"107.507\"],[\"80465.70\",\"0.000\"]],\"st\":1}}"}
{"receive_ns":1788567724020104000,"stream":"btcusdt@bookTicker","event_type":"bookTicker","event_time_ms":1788567724039,"raw_json":"{\"stream\":\"btcusdt@bookTicker\",\"data\":{\"e\":\"bookTicker\",\"u\":11478507934890,\"s\":\"BTCUSDT\",\"ps\":\"BTCUSDT\",\"b\":\"79597.00\",\"B\":\"3.796\",\"a\":\"79597.10\",\"A\":\"7.637\",\"T\":1788567724039,\"E\":1788567724039,\"st\":1}}"}
{"receive_ns":1788567724026637000,"stream":"btcusdt@depth@100ms","event_type":"depthUpdate","event_time_ms":1788567724041,"raw_json":"{\"stream\":\"btcusdt@depth@100ms\",\"data\":{\"e\":\"depthUpdate\",\"E\":1788567724041,\"T\":1788567724040,\"s\":\"BTCUSDT\",\"ps\":\"BTCUSDT\",\"U\":11478507927337,\"u\":11478507934931,\"pu\":11478507927204,\"b\":[[\"29097.00\",\"1.820\"],[\"29197.00\",\"0.210\"],[\"29497.00\",\"0.070\"],[\"55718.00\",\"0.002\"],[\"71637.30\",\"0.043\"],[\"76413.10\",\"0.002\"],[\"78482.60\",\"31.629\"],[\"78801.00\",\"11.407\"],[\"79199.00\",\"4.866\"],[\"79501.40\",\"0.046\"],[\"79525.30\",\"0.635\"],[\"79541.20\",\"0.000\"],[\"79582.70\",\"0.198\"],[\"79588.80\",\"0.035\"],[\"79597.00\",\"3.748\"]],\"a\":[[\"79668.80\",\"0.035\"],[\"79692.70\",\"0.001\"],[\"79732.50\",\"0.000\"],[\"80393.10\",\"107.507\"]],\"st\":1}}"}
{"receive_ns":1788567724027003000,"stream":"btcusdt@bookTicker","event_type":"bookTicker","event_time_ms":1788567724040,"raw_json":"{\"stream\":\"btcusdt@bookTicker\",\"data\":{\"e\":\"bookTicker\",\"u\":11478507934931,\"s\":\"BTCUSDT\",\"ps\":\"BTCUSDT\",\"b\":\"79597.00\",\"B\":\"3.748\",\"a\":\"79597.10\",\"A\":\"7.637\",\"T\":1788567724040,\"E\":1788567724040,\"st\":1}}"}
{"receive_ns":1788567724032713000,"stream":"btcusdt@bookTicker","event_type":"bookTicker","event_time_ms":1788567724042,"raw_json":"{\"stream\":\"btcusdt@bookTicker\",\"data\":{\"e\":\"bookTicker\",\"u\":11478507935126,\"s\":\"BTCUSDT\",\"ps\":\"BTCUSDT\",\"b\":\"79597.00\",\"B\":\"3.796\",\"a\":\"79597.10\",\"A\":\"7.637\",\"T\":1788567724042,\"E\":1788567724042,\"st\":1}}"}
{"receive_ns":1788567724032974000,"stream":"btcusdt@bookTicker","event_type":"bookTicker","event_time_ms":1788567724046,"raw_json":"{\"stream\":\"btcusdt@bookTicker\",\"data\":{\"e\":\"bookTicker\",\"u\":11478507935311,\"s\":\"BTCUSDT\",\"ps\":\"BTCUSDT\",\"b\":\"79597.00\",\"B\":\"3.844\",\"a\":\"79597.10\",\"A\":\"7.637\",\"T\":1788567724046,\"E\":1788567724046,\"st\":1}}"}
{"receive_ns":1788567724042254000,"stream":"btcusdt@bookTicker","event_type":"bookTicker","event_time_ms":1788567724047,"raw_json":"{\"stream\":\"btcusdt@bookTicker\",\"data\":{\"e\":\"bookTicker\",\"u\":11478507935626,\"s\":\"BTCUSDT\",\"ps\":\"BTCUSDT\",\"b\":\"79597.00\",\"B\":\"3.843\",\"a\":\"79597.10\",\"A\":\"7.637\",\"T\":1788567724047,\"E\":1788567724047,\"st\":1}}"}
{"receive_ns":1788567724076369000,"stream":"btcusdt@bookTicker","event_type":"bookTicker","event_time_ms":1788567724087,"raw_json":"{\"stream\":\"btcusdt@bookTicker\",\"data\":{\"e\":\"bookTicker\",\"u\":11478507938922,\"s\":\"BTCUSDT\",\"ps\":\"BTCUSDT\",\"b\":\"79597.00\",\"B\":\"3.843\",\"a\":\"79597.10\",\"A\":\"7.636\",\"T\":1788567724087,\"E\":1788567724087,\"st\":1}}"}
{"receive_ns":1788567724129533000,"stream":"btcusdt@depth@100ms","event_type":"depthUpdate","event_time_ms":1788567724143,"raw_json":"{\"stream\":\"btcusdt@depth@100ms\",\"data\":{\"e\":\"depthUpdate\",\"E\":1788567724143,\"T\":1788567724142,\"s\":\"BTCUSDT\",\"ps\":\"BTCUSDT\",\"U\":11478507934973,\"u\":11478507943025,\"pu\":11478507934931,\"b\":[[\"1000.00\",\"24.604\"],[\"29097.00\",\"1.876\"],[\"29197.00\",\"0.091\"],[\"29497.00\",\"0.133\"],[\"71637.30\",\"0.043\"],[\"78005.10\",\"10.828\"],[\"78252.10\",\"0.000\"],[\"78363.20\",\"8.538\"],[\"78482.60\",\"33.537\"],[\"78641.80\",\"33.311\"],[\"78681.60\",\"8.763\"],[\"78801.00\",\"11.407\"],[\"79573.30\",\"0.481\"],[\"79582.70\",\"0.194\"],[\"79585.40\",\"0.129\"],[\"79586.50\",\"0.002\"],[\"79588.10\",\"0.077\"],[\"79589.00\",\"0.254\"],[\"79590.50\",\"0.002\"],[\"79590.60\",\"0.254\"],[\"79590.70\",\"0.002\"],[\"79590.80\",\"0.003\"],[\"79592.30\",\"0.026\"],[\"79592.50\",\"0.147\"],[\"79593.50\",\"0.026\"],[\"79593.70\",\"0.026\"],[\"79597.00\",\"3.843\"]],\"a\":[[\"79597.10\",\"7.636\"],[\"79613.20\",\"0.002\"],[\"79692.60\",\"0.003\"],[\"79693.50\",\"0.005\"],[\"79695.60\",\"0.318\"],[\"79696.70\",\"0.000\"],[\"79702.00\",\"0.018\"],[\"79995.10\",\"4.366\"],[\"80393.10\",\"107.507\"]],\"st\":1}}"}
{"receive_ns":1788567724230229000,"stream":"btcusdt@depth@100ms","event_type":"depthUpdate","event_time_ms":1788567724245,"raw_json":"{\"stream\":\"btcusdt@depth@100ms\",\"data\":{\"e\":\"depthUpdate\",\"E\":1788567724245,\"T\":1788567724241,\"s\":\"BTCUSDT\",\"ps\":\"BTCUSDT\",\"U\":11478507943094,\"u\":11478507949985,\"pu\":11478507943025,\"b\":[[\"29097.00\",\"1.883\"],[\"29197.00\",\"0.000\"],[\"29497.00\",\"0.217\"],[\"63677.60\",\"0.000\"],[\"71637.30\",\"0.043\"],[\"76413.10\",\"0.000\"],[\"78442.80\",\"14.305\"],[\"78681.60\",\"9.525\"],[\"78801.00\",\"11.407\"],[\"79475.40\",\"0.000\"],[\"79542.60\",\"0.560\"],[\"79556.70\",\"0.949\"],[\"79573.30\",\"0.042\"],[\"79574.90\",\"0.439\"],[\"79590.90\",\"0.070\"],[\"79593.90\",\"0.026\"]],\"a\":[[\"79626.70\",\"0.006\"],[\"79691.70\",\"0.003\"],[\"79692.40\",\"0.000\"],[\"79702.00\",\"0.017\"],[\"79702.30\",\"0.001\"],[\"79703.10\",\"0.013\"],[\"79703.20\",\"0.000\"],[\"79704.30\",\"1.126\"],[\"79704.60\",\"0.043\"],[\"79705.20\",\"0.014\"],[\"79719.60\",\"0.001\"],[\"80393.10\",\"106.265\"],[\"80552.30\",\"28.859\"],[\"80592.10\",\"11.948\"]],\"st\":1}}"}
{"receive_ns":1788567724235596000,"stream":"btcusdt@bookTicker","event_type":"bookTicker","event_time_ms":1788567724252,"raw_json":"{\"stream\":\"btcusdt@bookTicker\",\"data\":{\"e\":\"bookTicker\",\"u\":11478507950792,\"s\":\"BTCUSDT\",\"ps\":\"BTCUSDT\",\"b\":\"79597.00\",\"B\":\"3.843\",\"a\":\"79597.10\",\"A\":\"7.635\",\"T\":1788567724252,\"E\":1788567724252,\"st\":1}}"}
{"receive_ns":1788567724235814000,"stream":"btcusdt@trade","event_type":"trade","event_time_ms":1788567724252,"raw_json":"{\"stream\":\"btcusdt@trade\",\"data\":{\"e\":\"trade\",\"E\":1788567724252,\"T\":1788567724252,\"s\":\"BTCUSDT\",\"t\":8054122581,\"p\":\"79597.10\",\"q\":\"0.001\",\"X\":\"MARKET\",\"m\":false,\"st\":1}}"}
{"receive_ns":1788567724246281000,"stream":"btcusdt@bookTicker","event_type":"bookTicker","event_time_ms":1788567724254,"raw_json":"{\"stream\":\"btcusdt@bookTicker\",\"data\":{\"e\":\"bookTicker\",\"u\":11478507950994,\"s\":\"BTCUSDT\",\"ps\":\"BTCUSDT\",\"b\":\"79597.00\",\"B\":\"3.802\",\"a\":\"79597.10\",\"A\":\"7.635\",\"T\":1788567724253,\"E\":1788567724254,\"st\":1}}"}
{"receive_ns":1788567724251713000,"stream":"btcusdt@bookTicker","event_type":"bookTicker","event_time_ms":1788567724254,"raw_json":"{\"stream\":\"btcusdt@bookTicker\",\"data\":{\"e\":\"bookTicker\",\"u\":11478507951005,\"s\":\"BTCUSDT\",\"ps\":\"BTCUSDT\",\"b\":\"79597.00\",\"B\":\"3.790\",\"a\":\"79597.10\",\"A\":\"7.635\",\"T\":1788567724254,\"E\":1788567724254,\"st\":1}}"}
{"receive_ns":1788567724269219000,"stream":"btcusdt@bookTicker","event_type":"bookTicker","event_time_ms":1788567724285,"raw_json":"{\"stream\":\"btcusdt@bookTicker\",\"data\":{\"e\":\"bookTicker\",\"u\":11478507953528,\"s\":\"BTCUSDT\",\"ps\":\"BTCUSDT\",\"b\":\"79597.00\",\"B\":\"2.952\",\"a\":\"79597.10\",\"A\":\"7.635\",\"T\":1788567724285,\"E\":1788567724285,\"st\":1}}"}
{"receive_ns":1788567724274619000,"stream":"btcusdt@bookTicker","event_type":"bookTicker","event_time_ms":1788567724286,"raw_json":"{\"stream\":\"btcusdt@bookTicker\",\"data\":{\"e\":\"bookTicker\",\"u\":11478507953647,\"s\":\"BTCUSDT\",\"ps\":\"BTCUSDT\",\"b\":\"79597.00\",\"B\":\"2.953\",\"a\":\"79597.10\",\"A\":\"7.635\",\"T\":1788567724286,\"E\":1788567724286,\"st\":1}}"}
{"receive_ns":1788567724275971000,"stream":"btcusdt@bookTicker","event_type":"bookTicker","event_time_ms":1788567724294,"raw_json":"{\"stream\":\"btcusdt@bookTicker\",\"data\":{\"e\":\"bookTicker\",\"u\":11478507954126,\"s\":\"BTCUSDT\",\"ps\":\"BTCUSDT\",\"b\":\"79597.00\",\"B\":\"3.941\",\"a\":\"79597.10\",\"A\":\"7.635\",\"T\":1788567724293,\"E\":1788567724294,\"st\":1}}"}
{"receive_ns":1788567724276225000,"stream":"btcusdt@bookTicker","event_type":"bookTicker","event_time_ms":1788567724294,"raw_json":"{\"stream\":\"btcusdt@bookTicker\",\"data\":{\"e\":\"bookTicker\",\"u\":11478507954176,\"s\":\"BTCUSDT\",\"ps\":\"BTCUSDT\",\"b\":\"79597.00\",\"B\":\"3.940\",\"a\":\"79597.10\",\"A\":\"7.635\",\"T\":1788567724294,\"E\":1788567724294,\"st\":1}}"}
{"receive_ns":1788567724276424000,"stream":"btcusdt@bookTicker","event_type":"bookTicker","event_time_ms":1788567724294,"raw_json":"{\"stream\":\"btcusdt@bookTicker\",\"data\":{\"e\":\"bookTicker\",\"u\":11478507954189,\"s\":\"BTCUSDT\",\"ps\":\"BTCUSDT\",\"b\":\"79597.00\",\"B\":\"3.939\",\"a\":\"79597.10\",\"A\":\"7.635\",\"T\":1788567724294,\"E\":1788567724294,\"st\":1}}"}
{"receive_ns":1788567724276662000,"stream":"btcusdt@bookTicker","event_type":"bookTicker","event_time_ms":1788567724296,"raw_json":"{\"stream\":\"btcusdt@bookTicker\",\"data\":{\"e\":\"bookTicker\",\"u\":11478507954256,\"s\":\"BTCUSDT\",\"ps\":\"BTCUSDT\",\"b\":\"79597.00\",\"B\":\"3.940\",\"a\":\"79597.10\",\"A\":\"7.635\",\"T\":1788567724295,\"E\":1788567724296,\"st\":1}}"}
{"receive_ns":1788567724329545000,"stream":"btcusdt@depth@100ms","event_type":"depthUpdate","event_time_ms":1788567724347,"raw_json":"{\"stream\":\"btcusdt@depth@100ms\",\"data\":{\"e\":\"depthUpdate\",\"E\":1788567724347,\"T\":1788567724345,\"s\":\"BTCUSDT\",\"ps\":\"BTCUSDT\",\"U\":11478507950220,\"u\":11478507957498,\"pu\":11478507949985,\"b\":[[\"29097.00\",\"1.701\"],[\"29497.00\",\"0.399\"],[\"71637.30\",\"0.043\"],[\"76413.10\",\"0.002\"],[\"78363.20\",\"9.430\"],[\"78442.80\",\"15.196\"],[\"78588.10\",\"6.617\"],[\"78801.00\",\"11.407\"],[\"79199.00\",\"4.866\"],[\"79475.40\",\"0.529\"],[\"79477.30\",\"1.940\"],[\"79543.90\",\"0.295\"],[\"79559.80\",\"0.001\"],[\"79573.30\",\"0.481\"],[\"79574.90\",\"0.000\"],[\"79576.80\",\"0.375\"],[\"79577.10\",\"0.082\"],[\"79577.70\",\"0.000\"],[\"79584.30\",\"0.078\"],[\"79586.50\",\"0.000\"],[\"79586.60\",\"0.257\"],[\"79588.80\",\"0.001\"],[\"79589.30\",\"0.237\"],[\"79591.00\",\"0.000\"],[\"79591.20\",\"0.006\"],[\"79592.70\",\"0.001\"],[\"79594.20\",\"0.026\"],[\"79594.30\",\"0.084\"],[\"79595.40\",\"0.037\"],[\"79595.60\",\"0.012\"],[\"79596.40\",\"0.016\"],[\"79596.70\",\"0.000\"],[\"79596.80\",\"0.160\"],[\"79597.00\",\"3.940\"]],\"a\":[[\"79597.10\",\"7.635\"],[\"79610.70\",\"0.543\"],[\"79626.60\",\"0.005\"],[\"79712.40\",\"0.647\"],[\"79713.50\",\"1.979\"],[\"79719.60\",\"0.482\"],[\"80299.30\",\"10.608\"],[\"80393.10\",\"106.265\"],[\"80605.40\",\"4.337\"],[\"80813.60\",\"0.865\"]],\"st\":1}}"}
{"receive_ns":1788567724356425000,"stream":"btcusdt@bookTicker","event_type":"bookTicker","event_time_ms":1788567724367,"raw_json":"{\"stream\":\"btcusdt@bookTicker\",\"data\":{\"e\":\"bookTicker\",\"u\":11478507958673,\"s\":\"BTCUSDT\",\"ps\":\"BTCUSDT\",\"b\":\"79597.00\",\"B\":\"3.981\",\"a\":\"79597.10\",\"A\":\"7.635\",\"T\":1788567724367,\"E\":1788567724367,\"st\":1}}"}
{"receive_ns":1788567724365266000,"stream":"btcusdt@bookTicker","event_type":"bookTicker","event_time_ms":1788567724368,"raw_json":"{\"stream\":\"btcusdt@bookTicker\",\"data\":{\"e\":\"bookTicker\",\"u\":11478507958789,\"s\":\"BTCUSDT\",\"ps\":\"BTCUSDT\",\"b\":\"79597.00\",\"B\":\"3.982\",\"a\":\"79597.10\",\"A\":\"7.635\",\"T\":1788567724368,\"E\":1788567724368,\"st\":1}}"}
{"receive_ns":1788567724365501000,"stream":"btcusdt@bookTicker","event_type":"bookTicker","event_time_ms":1788567724384,"raw_json":"{\"stream\":\"btcusdt@bookTicker\",\"data\":{\"e\":\"bookTicker\",\"u\":11478507960098,\"s\":\"BTCUSDT\",\"ps\":\"BTCUSDT\",\"b\":\"79597.00\",\"B\":\"3.932\",\"a\":\"79597.10\",\"A\":\"7.635\",\"T\":1788567724383,\"E\":1788567724384,\"st\":1}}"}
{"receive_ns":1788567724371554000,"stream":"btcusdt@bookTicker","event_type":"bookTicker","event_time_ms":1788567724386,"raw_json":"{\"stream\":\"btcusdt@bookTicker\",\"data\":{\"e\":\"bookTicker\",\"u\":11478507960312,\"s\":\"BTCUSDT\",\"ps\":\"BTCUSDT\",\"b\":\"79597.00\",\"B\":\"3.984\",\"a\":\"79597.10\",\"A\":\"7.635\",\"T\":1788567724386,\"E\":1788567724386,\"st\":1}}"}
{"receive_ns":1788567724429182000,"stream":"btcusdt@depth@100ms","event_type":"depthUpdate","event_time_ms":1788567724449,"raw_json":"{\"stream\":\"btcusdt@depth@100ms\",\"data\":{\"e\":\"depthUpdate\",\"E\":1788567724449,\"T\":1788567724448,\"s\":\"BTCUSDT\",\"ps\":\"BTCUSDT\",\"U\":11478507957565,\"u\":11478507964671,\"pu\":11478507957498,\"b\":[[\"1000.00\",\"24.604\"],[\"29097.00\",\"1.526\"],[\"29497.00\",\"0.574\"],[\"63678.00\",\"0.000\"],[\"71637.30\",\"0.043\"],[\"76413.10\",\"0.000\"],[\"78588.10\",\"6.426\"],[\"78801.00\",\"11.407\"],[\"79475.40\",\"0.529\"],[\"79573.30\",\"0.481\"],[\"79574.80\",\"0.001\"],[\"79574.90\",\"0.000\"],[\"79575.70\",\"0.636\"],[\"79590.50\",\"0.000\"],[\"79590.80\",\"0.001\"],[\"79591.30\",\"0.102\"],[\"79591.50\",\"0.002\"],[\"79592.20\",\"0.026\"],[\"79594.20\",\"0.000\"],[\"79594.30\",\"0.058\"],[\"79594.50\",\"0.000\"],[\"79597.00\",\"3.984\"]],\"a\":[[\"79601.20\",\"0.000\"],[\"79605.90\",\"0.003\"],[\"79607.00\",\"0.251\"],[\"79611.80\",\"0.001\"],[\"79614.90\",\"0.000\"],[\"79615.30\",\"0.815\"],[\"79616.90\",\"0.163\"],[\"79623.10\",\"0.060\"],[\"79623.70\",\"0.627\"],[\"79642.40\",\"0.125\"],[\"79646.00\",\"0.055\"],[\"79719.60\",\"0.482\"],[\"80393.10\",\"107.199\"],[\"80483.70\",\"0.186\"],[\"81268.60\",\"0.249\"]],\"st\":1}}"}
{"receive_ns":1788567724534735000,"stream":"btcusdt@depth@100ms","event_type":"depthUpdate","event_time_ms":1788567724551,"raw_json":"{\"stream\":\"btcusdt@depth@100ms\",\"data\":{\"e\":\"depthUpdate\",\"E\":1788567724551,\"T\":1788567724549,\"s\":\"BTCUSDT\",\"ps\":\"BTCUSDT\",\"U\":11478507964743,\"u\":11478507971331,\"pu\":11478507964671,\"b\":[[\"29097.00\",\"1.344\"],[\"29497.00\",\"0.756\"],[\"71637.30\",\"0.043\"],[\"71673.00\",\"0.000\"],[\"78150.90\",\"5.112\"],[\"78628.50\",\"12.066\"],[\"78681.60\",\"8.763\"],[\"78801.00\",\"11.407\"],[\"79591.70\",\"0.029\"],[\"79593.90\",\"0.000\"]],\"a\":[[\"79642.40\",\"0.000\"],[\"79642.70\",\"0.125\"],[\"79643.00\",\"0.026\"],[\"80393.10\",\"107.197\"],[\"80631.90\",\"10.828\"],[\"80830.90\",\"8.650\"]],\"st\":1}}"}
{"receive_ns":1788567724535054000,"stream":"btcusdt@bookTicker","event_type":"bookTicker","event_time_ms":1788567724556,"raw_json":"{\"stream\":\"btcusdt@bookTicker\",\"data\":{\"e\":\"bookTicker\",\"u\":11478507971665,\"s\":\"BTCUSDT\",\"ps\":\"BTCUSDT\",\"b\":\"79597.00\",\"B\":\"3.936\",\"a\":\"79597.10\",\"A\":\"7.635\",\"T\":1788567724556,\"E\":1788567724556,\"st\":1}}"}
{"receive_ns":1788567724552949000,"stream":"btcusdt@bookTicker","event_type":"bookTicker","event_time_ms":1788567724559,"raw_json":"{\"stream\":\"btcusdt@bookTicker\",\"data\":{\"e\":\"bookTicker\",\"u\":11478507971857,\"s\":\"BTCUSDT\",\"ps\":\"BTCUSDT\",\"b\":\"79597.00\",\"B\":\"3.987\",\"a\":\"79597.10\",\"A\":\"7.635\",\"T\":1788567724559,\"E\":1788567724559,\"st\":1}}"}
{"receive_ns":1788567724634137000,"stream":"btcusdt@depth@100ms","event_type":"depthUpdate","event_time_ms":1788567724653,"raw_json":"{\"stream\":\"btcusdt@depth@100ms\",\"data\":{\"e\":\"depthUpdate\",\"E\":1788567724653,\"T\":1788567724649,\"s\":\"BTCUSDT\",\"ps\":\"BTCUSDT\",\"U\":11478507971429,\"u\":11478507977295,\"pu\":11478507971331,\"b\":[[\"29097.00\",\"1.169\"],[\"29497.00\",\"0.931\"],[\"63678.00\",\"0.000\"],[\"71637.30\",\"0.043\"],[\"75160.00\",\"0.055\"],[\"76413.10\",\"0.002\"],[\"78083.30\",\"0.002\"],[\"78681.60\",\"8.001\"],[\"78801.00\",\"11.407\"],[\"79199.00\",\"4.876\"],[\"79534.00\",\"0.253\"],[\"79536.60\",\"19.755\"],[\"79584.60\",\"0.347\"],[\"79596.90\",\"2.572\"],[\"79597.00\",\"3.987\"]],\"a\":[[\"79601.30\",\"0.253\"],[\"79642.70\",\"0.125\"],[\"80147.50\",\"0.093\"],[\"80393.10\",\"107.197\"]],\"st\":1}}"}
{"receive_ns":1788567724737541000,"stream":"btcusdt@depth@100ms","event_type":"depthUpdate","event_time_ms":1788567724755,"raw_json":"{\"stream\":\"btcusdt@depth@100ms\",\"data\":{\"e\":\"depthUpdate\",\"E\":1788567724755,\"T\":1788567724753,\"s\":\"BTCUSDT\",\"ps\":\"BTCUSDT\",\"U\":11478507977468,\"u\":11478507984400,\"pu\":11478507977295,\"b\":[[\"1000.00\",\"24.604\"],[\"29097.00\",\"0.987\"],[\"29497.00\",\"1.113\"],[\"63678.00\",\"0.000\"],[\"71637.30\",\"0.043\"],[\"76413.10\",\"0.000\"],[\"78442.80\",\"14.305\"],[\"78641.80\",\"32.041\"],[\"78681.60\",\"8.763\"],[\"78801.00\",\"11.407\"],[\"79475.40\",\"0.529\"],[\"79534.50\",\"2.356\"]],\"a\":[[\"79601.00\",\"0.186\"],[\"79642.70\",\"0.000\"],[\"79642.90\",\"0.128\"],[\"79643.00\",\"0.026\"],[\"79665.40\",\"4.885\"],[\"79719.60\",\"0.482\"],[\"80299.30\",\"9.737\"],[\"80393.10\",\"107.197\"],[\"80519.40\",\"0.011\"],[\"80552.30\",\"30.099\"],[\"80577.80\",\"2.683\"],[\"80711.50\",\"30.823\"]],\"st\":1}}"}
{"receive_ns":1788567724743897000,"stream":"btcusdt@bookTicker","event_type":"bookTicker","event_time_ms":1788567724761,"raw_json":"{\"stream\":\"btcusdt@bookTicker\",\"data\":{\"e\":\"bookTicker\",\"u\":11478507985144,\"s\":\"BTCUSDT\",\"ps\":\"BTCUSDT\",\"b\":\"79597.00\",\"B\":\"3.999\",\"a\":\"79597.10\",\"A\":\"7.635\",\"T\":1788567724761,\"E\":1788567724761,\"st\":1}}"}
{"receive_ns":1788567724816728000,"stream":"btcusdt@bookTicker","event_type":"bookTicker","event_time_ms":1788567724832,"raw_json":"{\"stream\":\"btcusdt@bookTicker\",\"data\":{\"e\":\"bookTicker\",\"u\":11478507989665,\"s\":\"BTCUSDT\",\"ps\":\"BTCUSDT\",\"b\":\"79597.00\",\"B\":\"3.999\",\"a\":\"79597.10\",\"A\":\"7.634\",\"T\":1788567724832,\"E\":1788567724832,\"st\":1}}"}
{"receive_ns":1788567724832708000,"stream":"btcusdt@trade","event_type":"trade","event_time_ms":1788567724832,"raw_json":"{\"stream\":\"btcusdt@trade\",\"data\":{\"e\":\"trade\",\"E\":1788567724832,\"T\":1788567724832,\"s\":\"BTCUSDT\",\"t\":8054122582,\"p\":\"79597.10\",\"q\":\"0.001\",\"X\":\"MARKET\",\"m\":false,\"st\":1}}"}
{"receive_ns":1788567724838600000,"stream":"btcusdt@depth@100ms","event_type":"depthUpdate","event_time_ms":1788567724857,"raw_json":"{\"stream\":\"btcusdt@depth@100ms\",\"data\":{\"e\":\"depthUpdate\",\"E\":1788567724857,\"T\":1788567724856,\"s\":\"BTCUSDT\",\"ps\":\"BTCUSDT\",\"U\":11478507984611,\"u\":11478507991423,\"pu\":11478507984400,\"b\":[[\"29097.00\",\"0.812\"],[\"29497.00\",\"1.288\"],[\"71637.30\",\"0.043\"],[\"76413.10\",\"0.002\"],[\"78124.50\",\"2.623\"],[\"78363.20\",\"8.538\"],[\"78442.80\",\"13.414\"],[\"78681.60\",\"8.001\"],[\"78801.00\",\"11.407\"],[\"79199.00\",\"4.875\"],[\"79428.70\",\"3.247\"],[\"79475.40\",\"0.000\"],[\"79588.70\",\"0.037\"],[\"79593.90\",\"0.026\"],[\"79594.00\",\"0.000\"],[\"79596.80\",\"0.159\"],[\"79597.00\",\"3.999\"]],\"a\":[[\"79597.10\",\"7.634\"],[\"79601.10\",\"0.221\"],[\"79642.90\",\"0.003\"],[\"79643.10\",\"0.126\"],[\"79719.60\",\"0.001\"],[\"79760.20\",\"0.458\"],[\"79762.10\",\"1.938\"],[\"80313.70\",\"1.805\"],[\"80393.10\",\"107.197\"],[\"81189.00\",\"10.543\"]],\"st\":1}}"}
{"receive_ns":1788567724943649000,"stream":"btcusdt@depth@100ms","event_type":"depthUpdate","event_time_ms":1788567724959,"raw_json":"{\"stream\":\"btcusdt@depth@100ms\",\"data\":{\"e\":\"depthUpdate\",\"E\":1788567724959,\"T\":1788567724958,\"s\":\"BTCUSDT\",\"ps\":\"BTCUSDT\",\"U\":11478507991609,\"u\":11478507997870,\"pu\":11478507991423,\"b\":[[\"29097.00\",\"0.630\"],[\"29497.00\",\"1.470\"],[\"63678.00\",\"0.000\"],[\"71637.30\",\"0.043\"],[\"75617.10\",\"0.026\"],[\"76413.10\",\"0.000\"],[\"77354.60\",\"0.000\"],[\"78442.80\",\"14.305\"],[\"78641.80\",\"33.311\"],[\"78681.60\",\"9.525\"],[\"78704.60\",\"0.000\"],[\"78801.00\",\"11.407\"],[\"79199.00\",\"4.875\"],[\"79589.30\",\"0.161\"],[\"79591.60\",\"0.026\"],[\"79593.70\",\"0.000\"],[\"79593.90\",\"0.000\"]],\"a\":[[\"79643.10\",\"0.001\"],[\"79643.40\",\"3.151\"],[\"80393.10\",\"107.197\"]],\"st\":1}}"}
{"receive_ns":1788567725022508000,"stream":"btcusdt@bookTicker","event_type":"bookTicker","event_time_ms":1788567725043,"raw_json":"{\"stream\":\"btcusdt@bookTicker\",\"data\":{\"e\":\"bookTicker\",\"u\":11478508003672,\"s\":\"BTCUSDT\",\"ps\":\"BTCUSDT\",\"b\":\"79597.00\",\"B\":\"3.951\",\"a\":\"79597.10\",\"A\":\"7.634\",\"T\":1788567725043,\"E\":1788567725043,\"st\":1}}"}
{"receive_ns":1788567725035512000,"stream":"btcusdt@bookTicker","event_type":"bookTicker","event_time_ms":1788567725045,"raw_json":"{\"stream\":\"btcusdt@bookTicker\",\"data\":{\"e\":\"bookTicker\",\"u\":11478508003828,\"s\":\"BTCUSDT\",\"ps\":\"BTCUSDT\",\"b\":\"79597.00\",\"B\":\"3.999\",\"a\":\"79597.10\",\"A\":\"7.634\",\"T\":1788567725045,\"E\":1788567725045,\"st\":1}}"}
{"receive_ns":1788567725048129000,"stream":"btcusdt@depth@100ms","event_type":"depthUpdate","event_time_ms":1788567725061,"raw_json":"{\"stream\":\"btcusdt@depth@100ms\",\"data\":{\"e\":\"depthUpdate\",\"E\":1788567725061,\"T\":1788567725060,\"s\":\"BTCUSDT\",\"ps\":\"BTCUSDT\",\"U\":11478507997907,\"u\":11478508004789,\"pu\":11478507997870,\"b\":[[\"1000.00\",\"24.604\"],[\"29097.00\",\"0.455\"],[\"29497.00\",\"1.645\"],[\"55717.90\",\"0.000\"],[\"63678.00\",\"0.000\"],[\"71637.30\",\"0.043\"],[\"75617.10\",\"0.028\"],[\"78363.20\",\"8.538\"],[\"78442.80\",\"14.560\"],[\"78482.60\",\"29.719\"],[\"78641.80\",\"30.771\"],[\"78801.00\",\"11.407\"],[\"79199.00\",\"4.876\"],[\"79475.40\",\"0.529\"],[\"79541.20\",\"0.002\"],[\"79582.70\",\"0.194\"],[\"79596.90\",\"2.590\"],[\"79597.00\",\"3.999\"]],\"a\":[[\"79692.70\",\"0.003\"],[\"79719.60\",\"0.482\"],[\"79806.70\",\"2.844\"],[\"79995.10\",\"4.366\"],[\"80194.10\",\"4.361\"],[\"80200.00\",\"15.292\"],[\"80393.10\",\"107.197\"],[\"80558.80\",\"1.489\"],[\"81189.00\",\"10.540\"],[\"87556.90\",\"0.000\"]],\"st\":1}}"}
{"receive_ns":1788567725060380000,"stream":"btcusdt@bookTicker","event_type":"bookTicker","event_time_ms":1788567725063,"raw_json":"{\"stream\":\"btcusdt@bookTicker\",\"data\":{\"e\":\"bookTicker\",\"u\":11478508004918,\"s\":\"BTCUSDT\",\"ps\":\"BTCUSDT\",\"b\":\"79597.00\",\"B\":\"3.948\",\"a\":\"79597.10\",\"A\":\"7.634\",\"T\":1788567725062,\"E\":1788567725063,\"st\":1}}"}
{"receive_ns":1788567725065786000,"stream":"btcusdt@bookTicker","event_type":"bookTicker","event_time_ms":1788567725067,"raw_json":"{\"stream\":\"btcusdt@bookTicker\",\"data\":{\"e\":\"bookTicker\",\"u\":11478508005155,\"s\":\"BTCUSDT\",\"ps\":\"BTCUSDT\",\"b\":\"79597.00\",\"B\":\"3.998\",\"a\":\"79597.10\",\"A\":\"7.634\",\"T\":1788567725066,\"E\":1788567725067,\"st\":1}}"}
{"receive_ns":1788567725148925000,"stream":"btcusdt@depth@100ms","event_type":"depthUpdate","event_time_ms":1788567725163,"raw_json":"{\"stream\":\"btcusdt@depth@100ms\",\"data\":{\"e\":\"depthUpdate\",\"E\":1788567725163,\"T\":1788567725162,\"s\":\"BTCUSDT\",\"ps\":\"BTCUSDT\",\"U\":11478508004867,\"u\":11478508011005,\"pu\":11478508004789,\"b\":[[\"29097.00\",\"0.301\"],[\"29397.00\",\"0.028\"],[\"29497.00\",\"1.771\"],[\"63678.00\",\"0.000\"],[\"71637.30\",\"0.043\"],[\"75617.10\",\"0.030\"],[\"75617.20\",\"0.004\"],[\"76413.10\",\"0.002\"],[\"78108.50\",\"3.129\"],[\"78283.60\",\"4.873\"],[\"78442.80\",\"14.560\"],[\"78681.60\",\"8.763\"],[\"78801.00\",\"11.407\"],[\"78866.70\",\"6.689\"],[\"79573.30\",\"0.481\"],[\"79589.30\",\"0.237\"],[\"79594.00\",\"0.000\"],[\"79597.00\",\"3.998\"]],\"a\":[[\"79613.20\",\"0.002\"],[\"79691.70\",\"0.002\"],[\"79691.90\",\"0.065\"],[\"79692.60\",\"0.002\"],[\"79692.80\",\"0.002\"],[\"79693.50\",\"0.004\"],[\"79695.60\",\"0.317\"],[\"79696.10\",\"1.678\"],[\"79701.30\",\"0.002\"],[\"79702.00\",\"0.016\"],[\"79702.30\",\"0.000\"],[\"79702.60\",\"0.013\"],[\"79703.10\",\"0.012\"],[\"79704.30\",\"1.125\"],[\"79704.60\",\"0.040\"],[\"79704.70\",\"0.015\"],[\"79704.80\",\"0.003\"],[\"80393.10\",\"107.197\"],[\"80645.20\",\"9.904\"],[\"80724.70\",\"2.101\"]],\"st\":1}}"}
{"receive_ns":1788567725234323000,"stream":"btcusdt@bookTicker","event_type":"bookTicker","event_time_ms":1788567725251,"raw_json":"{\"stream\":\"btcusdt@bookTicker\",\"data\":{\"e\":\"bookTicker\",\"u\":11478508017829,\"s\":\"BTCUSDT\",\"ps\":\"BTCUSDT\",\"b\":\"79597.00\",\"B\":\"3.950\",\"a\":\"79597.10\",\"A\":\"7.634\",\"T\":1788567725251,\"E\":1788567725251,\"st\":1}}"}
{"receive_ns":1788567725242193000,"stream":"btcusdt@bookTicker","event_type":"bookTicker","event_time_ms":1788567725254,"raw_json":"{\"stream\":\"btcusdt@bookTicker\",\"data\":{\"e\":\"bookTicker\",\"u\":11478508018001,\"s\":\"BTCUSDT\",\"ps\":\"BTCUSDT\",\"b\":\"79597.00\",\"B\":\"3.998\",\"a\":\"79597.10\",\"A\":\"7.634\",\"T\":1788567725253,\"E\":1788567725254,\"st\":1}}"}
{"receive_ns":1788567725271143000,"stream":"btcusdt@bookTicker","event_type":"bookTicker","event_time_ms":1788567725256,"raw_json":"{\"stream\":\"btcusdt@bookTicker\",\"data\":{\"e\":\"bookTicker\",\"u\":11478508018250,\"s\":\"BTCUSDT\",\"ps\":\"BTCUSDT\",\"b\":\"79597.00\",\"B\":\"3.998\",\"a\":\"79597.10\",\"A\":\"7.635\",\"T\":1788567725256,\"E\":1788567725256,\"st\":1}}"}
{"receive_ns":1788567725280305000,"stream":"btcusdt@depth@100ms","event_type":"depthUpdate","event_time_ms":1788567725265,"raw_json":"{\"stream\":\"btcusdt@depth@100ms\",\"data\":{\"e\":\"depthUpdate\",\"E\":1788567725265,\"T\":1788567725264,\"s\":\"BTCUSDT\",\"ps\":\"BTCUSDT\",\"U\":11478508011021,\"u\":11478508018980,\"pu\":11478508011005,\"b\":[[\"1000.00\",\"24.954\"],[\"29097.00\",\"0.182\"],[\"29397.00\",\"0.084\"],[\"29497.00\",\"1.834\"],[\"63677.60\",\"0.000\"],[\"71637.30\",\"0.043\"],[\"76413.10\",\"0.000\"],[\"78283.60\",\"3.980\"],[\"78363.20\",\"9.430\"],[\"78801.00\",\"11.407\"],[\"79199.00\",\"4.876\"],[\"79436.00\",\"0.000\"],[\"79475.40\",\"0.000\"],[\"79501.40\",\"0.048\"],[\"79505.40\",\"4.281\"],[\"79506.70\",\"0.001\"],[\"79525.30\",\"0.633\"],[\"79541.20\",\"0.000\"],[\"79544.90\",\"0.831\"],[\"79560.80\",\"0.693\"],[\"79594.60\",\"0.027\"],[\"79596.80\",\"0.167\"],[\"79597.00\",\"3.998\"]],\"a\":[[\"79597.10\",\"7.635\"],[\"79610.70\",\"1.234\"],[\"79626.60\",\"0.834\"],[\"79626.70\",\"0.000\"],[\"79632.30\",\"0.401\"],[\"79643.40\",\"3.026\"],[\"79668.80\",\"0.035\"],[\"79688.00\",\"0.003\"],[\"79688.10\",\"3.525\"],[\"79691.80\",\"0.124\"],[\"79692.70\",\"0.001\"],[\"79692.80\",\"0.003\"],[\"79696.10\",\"1.680\"],[\"79701.30\",\"0.003\"],[\"79702.60\",\"0.014\"],[\"79719.60\",\"0.001\"],[\"79759.00\",\"0.095\"],[\"79818.80\",\"6.856\"],[\"80375.90\",\"0.281\"],[\"80393.10\",\"107.197\"]],\"st\":1}}"}
{"receive_ns":1788567725291403000,"stream":"btcusdt@bookTicker","event_type":"bookTicker","event_time_ms":1788567725265,"raw_json":"{\"stream\":\"btcusdt@bookTicker\",\"data\":{\"e\":\"bookTicker\",\"u\":11478508019008,\"s\":\"BTCUSDT\",\"ps\":\"BTCUSDT\",\"b\":\"79597.00\",\"B\":\"3.998\",\"a\":\"79597.10\",\"A\":\"7.636\",\"T\":1788567725265,\"E\":1788567725265,\"st\":1}}"}
{"receive_ns":1788567725308332000,"stream":"btcusdt@bookTicker","event_type":"bookTicker","event_time_ms":1788567725299,"raw_json":"{\"stream\":\"btcusdt@bookTicker\",\"data\":{\"e\":\"bookTicker\",\"u\":11478508021372,\"s\":\"BTCUSDT\",\"ps\":\"BTCUSDT\",\"b\":\"79597.00\",\"B\":\"3.010\",\"a\":\"79597.10\",\"A\":\"7.636\",\"T\":1788567725299,\"E\":1788567725299,\"st\":1}}"}
{"receive_ns":1788567725313873000,"stream":"btcusdt@bookTicker","event_type":"bookTicker","event_time_ms":1788567725308,"raw_json":"{\"stream\":\"btcusdt@bookTicker\",\"data\":{\"e\":\"bookTicker\",\"u\":11478508022230,\"s\":\"BTCUSDT\",\"ps\":\"BTCUSDT\",\"b\":\"79597.00\",\"B\":\"4.001\",\"a\":\"79597.10\",\"A\":\"7.636\",\"T\":1788567725308,\"E\":1788567725308,\"st\":1}}"}
{"receive_ns":1788567725319483000,"stream":"btcusdt@bookTicker","event_type":"bookTicker","event_time_ms":1788567725310,"raw_json":"{\"stream\":\"btcusdt@bookTicker\",\"data\":{\"e\":\"bookTicker\",\"u\":11478508022388,\"s\":\"BTCUSDT\",\"ps\":\"BTCUSDT\",\"b\":\"79597.00\",\"B\":\"4.000\",\"a\":\"79597.10\",\"A\":\"7.636\",\"T\":1788567725309,\"E\":1788567725310,\"st\":1}}"}
{"receive_ns":1788567725352513000,"stream":"btcusdt@depth@100ms","event_type":"depthUpdate","event_time_ms":1788567725367,"raw_json":"{\"stream\":\"btcusdt@depth@100ms\",\"data\":{\"e\":\"depthUpdate\",\"E\":1788567725367,\"T\":1788567725366,\"s\":\"BTCUSDT\",\"ps\":\"BTCUSDT\",\"U\":11478508019008,\"u\":11478508026287,\"pu\":11478508018980,\"b\":[[\"1000.00\",\"24.804\"],[\"29097.00\",\"0.063\"],[\"29397.00\",\"0.147\"],[\"29497.00\",\"1.890\"],[\"71637.30\",\"0.043\"],[\"76413.10\",\"0.002\"],[\"78482.60\",\"31.628\"],[\"78641.80\",\"31.660\"],[\"78801.00\",\"11.407\"],[\"79380.10\",\"1.938\"],[\"79436.00\",\"2.681\"],[\"79475.40\",\"0.529\"],[\"79531.30\",\"19.634\"],[\"79533.30\",\"4.417\"],[\"79536.60\",\"0.080\"],[\"79544.90\",\"0.002\"],[\"79560.80\",\"0.002\"],[\"79584.50\",\"0.002\"],[\"79586.60\",\"0.255\"],[\"79586.90\",\"0.003\"],[\"79592.70\",\"0.001\"],[\"79596.80\",\"0.167\"],[\"79597.00\",\"4.000\"]],\"a\":[[\"79597.10\",\"7.636\"],[\"79601.20\",\"0.001\"],[\"79610.70\",\"0.543\"],[\"79626.60\",\"0.005\"],[\"79628.70\",\"0.001\"],[\"79643.10\",\"0.001\"],[\"79719.60\",\"0.482\"],[\"79759.00\",\"2.254\"],[\"79810.70\",\"1.938\"],[\"80393.10\",\"107.197\"],[\"80767.20\",\"11.302\"]],\"st\":1}}"}
{"receive_ns":1788567725370276000,"stream":"btcusdt@bookTicker","event_type":"bookTicker","event_time_ms":1788567725387,"raw_json":"{\"stream\":\"btcusdt@bookTicker\",\"data\":{\"e\":\"bookTicker\",\"u\":11478508027663,\"s\":\"BTCUSDT\",\"ps\":\"BTCUSDT\",\"b\":\"79597.00\",\"B\":\"3.955\",\"a\":\"79597.10\",\"A\":\"7.636\",\"T\":1788567725387,\"E\":1788567725387,\"st\":1}}"}
{"receive_ns":1788567725393889000,"stream":"btcusdt@bookTicker","event_type":"bookTicker","event_time_ms":1788567725390,"raw_json":"{\"stream\":\"btcusdt@bookTicker\",\"data\":{\"e\":\"bookTicker\",\"u\":11478508027883,\"s\":\"BTCUSDT\",\"ps\":\"BTCUSDT\",\"b\":\"79597.00\",\"B\":\"3.999\",\"a\":\"79597.10\",\"A\":\"7.636\",\"T\":1788567725390,\"E\":1788567725390,\"st\":1}}"}
{"receive_ns":1788567725410668000,"stream":"btcusdt@bookTicker","event_type":"bookTicker","event_time_ms":1788567725391,"raw_json":"{\"stream\":\"btcusdt@bookTicker\",\"data\":{\"e\":\"bookTicker\",\"u\":11478508027959,\"s\":\"BTCUSDT\",\"ps\":\"BTCUSDT\",\"b\":\"79597.00\",\"B\":\"4.000\",\"a\":\"79597.10\",\"A\":\"7.636\",\"T\":1788567725391,\"E\":1788567725391,\"st\":1}}"}
{"receive_ns":1788567725429881000,"stream":"btcusdt@bookTicker","event_type":"bookTicker","event_time_ms":1788567725446,"raw_json":"{\"stream\":\"btcusdt@bookTicker\",\"data\":{\"e\":\"bookTicker\",\"u\":11478508030965,\"s\":\"BTCUSDT\",\"ps\":\"BTCUSDT\",\"b\":\"79597.00\",\"B\":\"4.000\",\"a\":\"79597.10\",\"A\":\"7.635\",\"T\":1788567725446,\"E\":1788567725446,\"st\":1}}"}
{"receive_ns":1788567725436128000,"stream":"btcusdt@trade","event_type":"trade","event_time_ms":1788567725446,"raw_json":"{\"stream\":\"btcusdt@trade\",\"data\":{\"e\":\"trade\",\"E\":1788567725446,\"T\":1788567725446,\"s\":\"BTCUSDT\",\"t\":8054122583,\"p\":\"79597.10\",\"q\":\"0.001\",\"X\":\"MARKET\",\"m\":false,\"st\":1}}"}
{"receive_ns":1788567725454398000,"stream":"btcusdt@depth@100ms","event_type":"depthUpdate","event_time_ms":1788567725469,"raw_json":"{\"stream\":\"btcusdt@depth@100ms\",\"data\":{\"e\":\"depthUpdate\",\"E\":1788567725469,\"T\":1788567725467,\"s\":\"BTCUSDT\",\"ps\":\"BTCUSDT\",\"U\":11478508026410,\"u\":11478508032443,\"pu\":11478508026287,\"b\":[[\"29097.00\",\"0.000\"],[\"29397.00\",\"0.259\"],[\"29497.00\",\"1.841\"],[\"71637.30\",\"0.043\"],[\"76413.10\",\"0.000\"],[\"78283.60\",\"5.766\"],[\"78442.80\",\"15.451\"],[\"78522.40\",\"11.928\"],[\"78681.60\",\"9.525\"],[\"78711.70\",\"2.574\"],[\"78778.10\",\"0.000\"],[\"78801.00\",\"11.407\"],[\"79199.00\",\"4.876\"],[\"79475.40\",\"0.000\"],[\"79531.30\",\"0.011\"],[\"79536.60\",\"19.703\"],[\"79592.80\",\"0.531\"],[\"79592.90\",\"0.028\"],[\"79593.50\",\"0.000\"],[\"79593.60\",\"0.003\"],[\"79594.60\",\"0.001\"],[\"79594.80\",\"0.000\"],[\"79597.00\",\"4.000\"]],\"a\":[[\"79597.10\",\"7.635\"],[\"79605.40\",\"0.080\"],[\"79607.70\",\"0.004\"],[\"79615.30\",\"0.187\"],[\"79615.80\",\"0.628\"],[\"79619.30\",\"0.001\"],[\"79619.90\",\"0.627\"],[\"79628.70\",\"0.046\"],[\"79643.20\",\"0.114\"],[\"79719.60\",\"0.001\"],[\"79829.50\",\"0.001\"],[\"79829.60\",\"0.003\"],[\"80393.10\",\"107.197\"],[\"80791.10\",\"5.839\"]],\"st\":1}}"}
{"receive_ns":1788567725473341000,"stream":"btcusdt@bookTicker","event_type":"bookTicker","event_time_ms":1788567725492,"raw_json":"{\"stream\":\"btcusdt@bookTicker\",\"data\":{\"e\":\"bookTicker\",\"u\":11478508033661,\"s\":\"BTCUSDT\",\"ps\":\"BTCUSDT\",\"b\":\"79597.00\",\"B\":\"3.982\",\"a\":\"79597.10\",\"A\":\"7.635\",\"T\":1788567725492,\"E\":1788567725492,\"st\":1}}"}
{"receive_ns":1788567725491873000,"stream":"btcusdt@bookTicker","event_type":"bookTicker","event_time_ms":1788567725495,"raw_json":"{\"stream\":\"btcusdt@bookTicker\",\"data\":{\"e\":\"bookTicker\",\"u\":11478508034071,\"s\":\"BTCUSDT\",\"ps\":\"BTCUSDT\",\"b\":\"79597.00\",\"B\":\"4.001\",\"a\":\"79597.10\",\"A\":\"7.635\",\"T\":1788567725495,\"E\":1788567725495,\"st\":1}}"}
{"receive_ns":1788567725585428000,"stream":"btcusdt@depth@100ms","event_type":"depthUpdate","event_time_ms":1788567725571,"raw_json":"{\"stream\":\"btcusdt@depth@100ms\",\"data\":{\"e\":\"depthUpdate\",\"E\":1788567725571,\"T\":1788567725570,\"s\":\"BTCUSDT\",\"ps\":\"BTCUSDT\",\"U\":11478508032515,\"u\":11478508038392,\"pu\":11478508032443,\"b\":[[\"1000.00\",\"24.804\"],[\"29397.00\",\"0.441\"],[\"29497.00\",\"1.659\"],[\"71637.30\",\"0.043\"],[\"71673.00\",\"0.000\"],[\"78372.80\",\"1.274\"],[\"78548.90\",\"9.540\"],[\"78588.10\",\"6.274\"],[\"78801.00\",\"12.674\"],[\"78880.60\",\"11.454\"],[\"78928.30\",\"0.270\"],[\"79475.40\",\"0.529\"],[\"79539.80\",\"0.000\"],[\"79548.80\",\"0.007\"],[\"79597.00\",\"4.001\"]],\"a\":[[\"79643.20\",\"0.241\"],[\"79643.30\",\"0.101\"],[\"79644.10\",\"0.128\"],[\"79719.60\",\"0.482\"],[\"80393.10\",\"107.197\"],[\"81951.30\",\"0.055\"],[\"83576.90\",\"0.040\"]],\"st\":1}}"}
{"receive_ns":1788567725656578000,"stream":"btcusdt@depth@100ms","event_type":"depthUpdate","event_time_ms":1788567725673,"raw_json":"{\"stream\":\"btcusdt@depth@100ms\",\"data\":{\"e\":\"depthUpdate\",\"E\":1788567725673,\"T\":1788567725670,\"s\":\"BTCUSDT\",\"ps\":\"BTCUSDT\",\"U\":11478508038443,\"u\":11478508044799,\"pu\":11478508038392,\"b\":[[\"1000.00\",\"24.804\"],[\"29397.00\",\"0.616\"],[\"29497.00\",\"1.484\"],[\"63678.00\",\"0.000\"],[\"71637.30\",\"0.045\"],[\"76413.10\",\"0.002\"],[\"78707.50\",\"0.190\"],[\"78801.00\",\"12.674\"],[\"79554.80\",\"0.233\"],[\"79555.40\",\"1.135\"],[\"79584.60\",\"0.350\"]],\"a\":[[\"79632.40\",\"1.133\"],[\"79656.90\",\"0.168\"],[\"79659.60\",\"1.020\"],[\"80393.10\",\"107.197\"],[\"80483.50\",\"0.188\"]],\"st\":1}}"}
{"receive_ns":1788567725760525000,"stream":"btcusdt@depth@100ms","event_type":"depthUpdate","event_time_ms":1788567725775,"raw_json":"{\"stream\":\"btcusdt@depth@100ms\",\"data\":{\"e\":\"depthUpdate\",\"E\":1788567725775,\"T\":1788567725773,\"s\":\"BTCUSDT\",\"ps\":\"BTCUSDT\",\"U\":11478508044861,\"u\":11478508050416,\"pu\":11478508044799,\"b\":[[\"29397.00\",\"0.798\"],[\"29497.00\",\"1.302\"],[\"71637.30\",\"0.043\"],[\"76413.10\",\"0.000\"],[\"78482.60\",\"29.719\"],[\"78545.50\",\"0.000\"],[\"78701.70\",\"0.000\"],[\"78801.00\",\"12.675\"],[\"78870.50\",\"0.190\"],[\"78928.30\",\"0.266\"],[\"79199.00\",\"4.876\"],[\"79495.10\",\"0.006\"],[\"79539.00\",\"4.166\"],[\"79588.70\",\"0.002\"],[\"79591.60\",\"0.000\"],[\"79593.20\",\"0.026\"],[\"79594.00\",\"0.026\"]],\"a\":[[\"79627.40\",\"0.007\"],[\"80393.10\",\"107.197\"]],\"st\":1}}"}
{"receive_ns":1788567725861926000,"stream":"btcusdt@depth@100ms","event_type":"depthUpdate","event_time_ms":1788567725877,"raw_json":"{\"stream\":\"btcusdt@depth@100ms\",\"data\":{\"e\":\"depthUpdate\",\"E\":1788567725877,\"T\":1788567725873,\"s\":\"BTCUSDT\",\"ps\":\"BTCUSDT\",\"U\":11478508050528,\"u\":11478508056401,\"pu\":11478508050416,\"b\":[[\"1000.00\",\"25.004\"],[\"29397.00\",\"0.973\"],[\"29497.00\",\"1.127\"],[\"63678.00\",\"0.000\"],[\"71637.30\",\"0.043\"],[\"76413.10\",\"0.002\"],[\"78259.80\",\"2.551\"],[\"78801.00\",\"12.675\"],[\"79000.00\",\"43.490\"]],\"a\":[[\"79621.00\",\"0.087\"],[\"80147.50\",\"0.000\"],[\"80393.10\",\"107.197\"]],\"st\":1}}"}
{"receive_ns":1788567725885310000,"stream":"btcusdt@bookTicker","event_type":"bookTicker","event_time_ms":1788567725899,"raw_json":"{\"stream\":\"btcusdt@bookTicker\",\"data\":{\"e\":\"bookTicker\",\"u\":11478508057572,\"s\":\"BTCUSDT\",\"ps\":\"BTCUSDT\",\"b\":\"79597.00\",\"B\":\"4.000\",\"a\":\"79597.10\",\"A\":\"7.635\",\"T\":1788567725899,\"E\":1788567725899,\"st\":1}}"}
{"receive_ns":1788567725890924000,"stream":"btcusdt@trade","event_type":"trade","event_time_ms":1788567725899,"raw_json":"{\"stream\":\"btcusdt@trade\",\"data\":{\"e\":\"trade\",\"E\":1788567725899,\"T\":1788567725899,\"s\":\"BTCUSDT\",\"t\":8054122584,\"p\":\"79597.00\",\"q\":\"0.001\",\"X\":\"MARKET\",\"m\":true,\"st\":1}}"}
{"receive_ns":1788567725968595000,"stream":"btcusdt@depth@100ms","event_type":"depthUpdate","event_time_ms":1788567725979,"raw_json":"{\"stream\":\"btcusdt@depth@100ms\",\"data\":{\"e\":\"depthUpdate\",\"E\":1788567725979,\"T\":1788567725977,\"s\":\"BTCUSDT\",\"ps\":\"BTCUSDT\",\"U\":11478508056596,\"u\":11478508062279,\"pu\":11478508056401,\"b\":[[\"1000.00\",\"25.004\"],[\"29397.00\",\"1.155\"],[\"29497.00\",\"0.945\"],[\"63678.00\",\"0.002\"],[\"71637.30\",\"0.043\"],[\"78482.60\",\"31.628\"],[\"78801.00\",\"12.675\"],[\"79331.50\",\"1.938\"],[\"79475.40\",\"0.000\"],[\"79589.30\",\"0.161\"],[\"79593.40\",\"0.027\"],[\"79594.00\",\"0.000\"],[\"79596.90\",\"2.596\"],[\"79597.00\",\"4.000\"]],\"a\":[[\"79621.00\",\"0.065\"],[\"79719.60\",\"0.001\"],[\"79859.30\",\"1.942\"],[\"80299.20\",\"2.984\"],[\"80393.10\",\"107.197\"]],\"st\":1}}"}
{"receive_ns":1788567726000214000,"stream":"btcusdt@bookTicker","event_type":"bookTicker","event_time_ms":1788567726013,"raw_json":"{\"stream\":\"btcusdt@bookTicker\",\"data\":{\"e\":\"bookTicker\",\"u\":11478508064770,\"s\":\"BTCUSDT\",\"ps\":\"BTCUSDT\",\"b\":\"79597.00\",\"B\":\"4.000\",\"a\":\"79597.10\",\"A\":\"6.935\",\"T\":1788567726013,\"E\":1788567726013,\"st\":1}}"}
{"receive_ns":1788567726005958000,"stream":"btcusdt@trade","event_type":"trade","event_time_ms":1788567726013,"raw_json":"{\"stream\":\"btcusdt@trade\",\"data\":{\"e\":\"trade\",\"E\":1788567726013,\"T\":1788567726013,\"s\":\"BTCUSDT\",\"t\":8054122585,\"p\":\"79597.10\",\"q\":\"0.136\",\"X\":\"MARKET\",\"m\":false,\"st\":1}}"}
{"receive_ns":1788567726011288000,"stream":"btcusdt@trade","event_type":"trade","event_time_ms":1788567726013,"raw_json":"{\"stream\":\"btcusdt@trade\",\"data\":{\"e\":\"trade\",\"E\":1788567726013,\"T\":1788567726013,\"s\":\"BTCUSDT\",\"t\":8054122586,\"p\":\"79597.10\",\"q\":\"0.340\",\"X\":\"MARKET\",\"m\":false,\"st\":1}}"}
{"receive_ns":1788567726025560000,"stream":"btcusdt@trade","event_type":"trade","event_time_ms":1788567726013,"raw_json":"{\"stream\":\"btcusdt@trade\",\"data\":{\"e\":\"trade\",\"E\":1788567726013,\"T\":1788567726013,\"s\":\"BTCUSDT\",\"t\":8054122587,\"p\":\"79597.10\",\"q\":\"0.005\",\"X\":\"MARKET\",\"m\":false,\"st\":1}}"}
{"receive_ns":1788567726031477000,"stream":"btcusdt@trade","event_type":"trade","event_time_ms":1788567726013,"raw_json":"{\"stream\":\"btcusdt@trade\",\"data\":{\"e\":\"trade\",\"E\":1788567726013,\"T\":1788567726013,\"s\":\"BTCUSDT\",\"t\":8054122588,\"p\":\"79597.10\",\"q\":\"0.042\",\"X\":\"MARKET\",\"m\":false,\"st\":1}}"}
{"receive_ns":1788567726037763000,"stream":"btcusdt@trade","event_type":"trade","event_time_ms":1788567726013,"raw_json":"{\"stream\":\"btcusdt@trade\",\"data\":{\"e\":\"trade\",\"E\":1788567726013,\"T\":1788567726013,\"s\":\"BTCUSDT\",\"t\":8054122589,\"p\":\"79597.10\",\"q\":\"0.005\",\"X\":\"MARKET\",\"m\":false,\"st\":1}}"}
{"receive_ns":1788567726043535000,"stream":"btcusdt@trade","event_type":"trade","event_time_ms":1788567726013,"raw_json":"{\"stream\":\"btcusdt@trade\",\"data\":{\"e\":\"trade\",\"E\":1788567726013,\"T\":1788567726013,\"s\":\"BTCUSDT\",\"t\":8054122590,\"p\":\"79597.10\",\"q\":\"0.002\",\"X\":\"MARKET\",\"m\":false,\"st\":1}}"}
{"receive_ns":1788567726049592000,"stream":"btcusdt@trade","event_type":"trade","event_time_ms":1788567726013,"raw_json":"{\"stream\":\"btcusdt@trade\",\"data\":{\"e\":\"trade\",\"E\":1788567726013,\"T\":1788567726013,\"s\":\"BTCUSDT\",\"t\":8054122591,\"p\":\"79597.10\",\"q\":\"0.002\",\"X\":\"MARKET\",\"m\":false,\"st\":1}}"}
{"receive_ns":1788567726050014000,"stream":"btcusdt@trade","event_type":"trade","event_time_ms":1788567726013,"raw_json":"{\"stream\":\"btcusdt@trade\",\"data\":{\"e\":\"trade\",\"E\":1788567726013,\"T\":1788567726013,\"s\":\"BTCUSDT\",\"t\":8054122592,\"p\":\"79597.10\",\"q\":\"0.002\",\"X\":\"MARKET\",\"m\":false,\"st\":1}}"}
{"receive_ns":1788567726065248000,"stream":"btcusdt@trade","event_type":"trade","event_time_ms":1788567726013,"raw_json":"{\"stream\":\"btcusdt@trade\",\"data\":{\"e\":\"trade\",\"E\":1788567726013,\"T\":1788567726013,\"s\":\"BTCUSDT\",\"t\":8054122593,\"p\":\"79597.10\",\"q\":\"0.004\",\"X\":\"MARKET\",\"m\":false,\"st\":1}}"}
{"receive_ns":1788567726071040000,"stream":"btcusdt@trade","event_type":"trade","event_time_ms":1788567726013,"raw_json":"{\"stream\":\"btcusdt@trade\",\"data\":{\"e\":\"trade\",\"E\":1788567726013,\"T\":1788567726013,\"s\":\"BTCUSDT\",\"t\":8054122594,\"p\":\"79597.10\",\"q\":\"0.001\",\"X\":\"MARKET\",\"m\":false,\"st\":1}}"}
{"receive_ns":1788567726076928000,"stream":"btcusdt@trade","event_type":"trade","event_time_ms":1788567726013,"raw_json":"{\"stream\":\"btcusdt@trade\",\"data\":{\"e\":\"trade\",\"E\":1788567726013,\"T\":1788567726013,\"s\":\"BTCUSDT\",\"t\":8054122595,\"p\":\"79597.10\",\"q\":\"0.001\",\"X\":\"MARKET\",\"m\":false,\"st\":1}}"}
{"receive_ns":1788567726082479000,"stream":"btcusdt@trade","event_type":"trade","event_time_ms":1788567726013,"raw_json":"{\"stream\":\"btcusdt@trade\",\"data\":{\"e\":\"trade\",\"E\":1788567726013,\"T\":1788567726013,\"s\":\"BTCUSDT\",\"t\":8054122596,\"p\":\"79597.10\",\"q\":\"0.012\",\"X\":\"MARKET\",\"m\":false,\"st\":1}}"}
{"receive_ns":1788567726088575000,"stream":"btcusdt@trade","event_type":"trade","event_time_ms":1788567726013,"raw_json":"{\"stream\":\"btcusdt@trade\",\"data\":{\"e\":\"trade\",\"E\":1788567726013,\"T\":1788567726013,\"s\":\"BTCUSDT\",\"t\":8054122597,\"p\":\"79597.10\",\"q\":\"0.013\",\"X\":\"MARKET\",\"m\":false,\"st\":1}}"}
{"receive_ns":1788567726094021000,"stream":"btcusdt@trade","event_type":"trade","event_time_ms":1788567726013,"raw_json":"{\"stream\":\"btcusdt@trade\",\"data\":{\"e\":\"trade\",\"E\":1788567726013,\"T\":1788567726013,\"s\":\"BTCUSDT\",\"t\":8054122598,\"p\":\"79597.10\",\"q\":\"0.001\",\"X\":\"MARKET\",\"m\":false,\"st\":1}}"}
{"receive_ns":1788567726110435000,"stream":"btcusdt@trade","event_type":"trade","event_time_ms":1788567726013,"raw_json":"{\"stream\":\"btcusdt@trade\",\"data\":{\"e\":\"trade\",\"E\":1788567726013,\"T\":1788567726013,\"s\":\"BTCUSDT\",\"t\":8054122599,\"p\":\"79597.10\",\"q\":\"0.054\",\"X\":\"MARKET\",\"m\":false,\"st\":1}}"}
{"receive_ns":1788567726110642000,"stream":"btcusdt@trade","event_type":"trade","event_time_ms":1788567726013,"raw_json":"{\"stream\":\"btcusdt@trade\",\"data\":{\"e\":\"trade\",\"E\":1788567726013,\"T\":1788567726013,\"s\":\"BTCUSDT\",\"t\":8054122600,\"p\":\"79597.10\",\"q\":\"0.001\",\"X\":\"MARKET\",\"m\":false,\"st\":1}}"}
{"receive_ns":1788567726110813000,"stream":"btcusdt@trade","event_type":"trade","event_time_ms":1788567726013,"raw_json":"{\"stream\":\"btcusdt@trade\",\"data\":{\"e\":\"trade\",\"E\":1788567726013,\"T\":1788567726013,\"s\":\"BTCUSDT\",\"t\":8054122601,\"p\":\"79597.10\",\"q\":\"0.001\",\"X\":\"MARKET\",\"m\":false,\"st\":1}}"}
{"receive_ns":1788567726117582000,"stream":"btcusdt@trade","event_type":"trade","event_time_ms":1788567726013,"raw_json":"{\"stream\":\"btcusdt@trade\",\"data\":{\"e\":\"trade\",\"E\":1788567726013,\"T\":1788567726013,\"s\":\"BTCUSDT\",\"t\":8054122602,\"p\":\"79597.10\",\"q\":\"0.001\",\"X\":\"MARKET\",\"m\":false,\"st\":1}}"}
{"receive_ns":1788567726124282000,"stream":"btcusdt@trade","event_type":"trade","event_time_ms":1788567726013,"raw_json":"{\"stream\":\"btcusdt@trade\",\"data\":{\"e\":\"trade\",\"E\":1788567726013,\"T\":1788567726013,\"s\":\"BTCUSDT\",\"t\":8054122603,\"p\":\"79597.10\",\"q\":\"0.001\",\"X\":\"MARKET\",\"m\":false,\"st\":1}}"}
{"receive_ns":1788567726124472000,"stream":"btcusdt@trade","event_type":"trade","event_time_ms":1788567726013,"raw_json":"{\"stream\":\"btcusdt@trade\",\"data\":{\"e\":\"trade\",\"E\":1788567726013,\"T\":1788567726013,\"s\":\"BTCUSDT\",\"t\":8054122604,\"p\":\"79597.10\",\"q\":\"0.001\",\"X\":\"MARKET\",\"m\":false,\"st\":1}}"}
{"receive_ns":1788567726129933000,"stream":"btcusdt@trade","event_type":"trade","event_time_ms":1788567726013,"raw_json":"{\"stream\":\"btcusdt@trade\",\"data\":{\"e\":\"trade\",\"E\":1788567726013,\"T\":1788567726013,\"s\":\"BTCUSDT\",\"t\":8054122605,\"p\":\"79597.10\",\"q\":\"0.002\",\"X\":\"MARKET\",\"m\":false,\"st\":1}}"}
{"receive_ns":1788567726135360000,"stream":"btcusdt@trade","event_type":"trade","event_time_ms":1788567726013,"raw_json":"{\"stream\":\"btcusdt@trade\",\"data\":{\"e\":\"trade\",\"E\":1788567726013,\"T\":1788567726013,\"s\":\"BTCUSDT\",\"t\":8054122606,\"p\":\"79597.10\",\"q\":\"0.001\",\"X\":\"MARKET\",\"m\":false,\"st\":1}}"}
{"receive_ns":1788567726140939000,"stream":"btcusdt@trade","event_type":"trade","event_time_ms":1788567726013,"raw_json":"{\"stream\":\"btcusdt@trade\",\"data\":{\"e\":\"trade\",\"E\":1788567726013,\"T\":1788567726013,\"s\":\"BTCUSDT\",\"t\":8054122607,\"p\":\"79597.10\",\"q\":\"0.001\",\"X\":\"MARKET\",\"m\":false,\"st\":1}}"}
{"receive_ns":1788567726155404000,"stream":"btcusdt@trade","event_type":"trade","event_time_ms":1788567726013,"raw_json":"{\"stream\":\"btcusdt@trade\",\"data\":{\"e\":\"trade\",\"E\":1788567726013,\"T\":1788567726013,\"s\":\"BTCUSDT\",\"t\":8054122608,\"p\":\"79597.10\",\"q\":\"0.001\",\"X\":\"MARKET\",\"m\":false,\"st\":1}}"}
{"receive_ns":1788567726155645000,"stream":"btcusdt@trade","event_type":"trade","event_time_ms":1788567726013,"raw_json":"{\"stream\":\"btcusdt@trade\",\"data\":{\"e\":\"trade\",\"E\":1788567726013,\"T\":1788567726013,\"s\":\"BTCUSDT\",\"t\":8054122609,\"p\":\"79597.10\",\"q\":\"0.002\",\"X\":\"MARKET\",\"m\":false,\"st\":1}}"}
{"receive_ns":1788567726155862000,"stream":"btcusdt@trade","event_type":"trade","event_time_ms":1788567726013,"raw_json":"{\"stream\":\"btcusdt@trade\",\"data\":{\"e\":\"trade\",\"E\":1788567726013,\"T\":1788567726013,\"s\":\"BTCUSDT\",\"t\":8054122610,\"p\":\"79597.10\",\"q\":\"0.068\",\"X\":\"MARKET\",\"m\":false,\"st\":1}}"}
{"receive_ns":1788567726162466000,"stream":"btcusdt@bookTicker","event_type":"bookTicker","event_time_ms":1788567726014,"raw_json":"{\"stream\":\"btcusdt@bookTicker\",\"data\":{\"e\":\"bookTicker\",\"u\":11478508064814,\"s\":\"BTCUSDT\",\"ps\":\"BTCUSDT\",\"b\":\"79597.00\",\"B\":\"4.000\",\"a\":\"79597.10\",\"A\":\"7.521\",\"T\":1788567726014,\"E\":1788567726014,\"st\":1}}"}
{"receive_ns":1788567726173087000,"stream":"btcusdt@bookTicker","event_type":"bookTicker","event_time_ms":1788567726015,"raw_json":"{\"stream\":\"btcusdt@bookTicker\",\"data\":{\"e\":\"bookTicker\",\"u\":11478508065125,\"s\":\"BTCUSDT\",\"ps\":\"BTCUSDT\",\"b\":\"79597.00\",\"B\":\"4.000\",\"a\":\"79597.10\",\"A\":\"7.495\",\"T\":1788567726015,\"E\":1788567726015,\"st\":1}}"}
{"receive_ns":1788567726180843000,"stream":"btcusdt@bookTicker","event_type":"bookTicker","event_time_ms":1788567726016,"raw_json":"{\"stream\":\"btcusdt@bookTicker\",\"data\":{\"e\":\"bookTicker\",\"u\":11478508065191,\"s\":\"BTCUSDT\",\"ps\":\"BTCUSDT\",\"b\":\"79597.00\",\"B\":\"4.000\",\"a\":\"79597.10\",\"A\":\"7.493\",\"T\":1788567726015,\"E\":1788567726016,\"st\":1}}"}
{"receive_ns":1788567726181063000,"stream":"btcusdt@bookTicker","event_type":"bookTicker","event_time_ms":1788567726016,"raw_json":"{\"stream\":\"btcusdt@bookTicker\",\"data\":{\"e\":\"bookTicker\",\"u\":11478508065204,\"s\":\"BTCUSDT\",\"ps\":\"BTCUSDT\",\"b\":\"79597.00\",\"B\":\"4.000\",\"a\":\"79597.10\",\"A\":\"7.519\",\"T\":1788567726015,\"E\":1788567726016,\"st\":1}}"}
{"receive_ns":1788567726181323000,"stream":"btcusdt@bookTicker","event_type":"bookTicker","event_time_ms":1788567726016,"raw_json":"{\"stream\":\"btcusdt@bookTicker\",\"data\":{\"e\":\"bookTicker\",\"u\":11478508065215,\"s\":\"BTCUSDT\",\"ps\":\"BTCUSDT\",\"b\":\"79597.00\",\"B\":\"4.000\",\"a\":\"79597.10\",\"A\":\"7.521\",\"T\":1788567726015,\"E\":1788567726016,\"st\":1}}"}
{"receive_ns":1788567726198579000,"stream":"btcusdt@bookTicker","event_type":"bookTicker","event_time_ms":1788567726016,"raw_json":"{\"stream\":\"btcusdt@bookTicker\",\"data\":{\"e\":\"bookTicker\",\"u\":11478508065243,\"s\":\"BTCUSDT\",\"ps\":\"BTCUSDT\",\"b\":\"79597.00\",\"B\":\"4.000\",\"a\":\"79597.10\",\"A\":\"7.585\",\"T\":1788567726016,\"E\":1788567726016,\"st\":1}}"}
{"receive_ns":1788567726210334000,"stream":"btcusdt@bookTicker","event_type":"bookTicker","event_time_ms":1788567726017,"raw_json":"{\"stream\":\"btcusdt@bookTicker\",\"data\":{\"e\":\"bookTicker\",\"u\":11478508065405,\"s\":\"BTCUSDT\",\"ps\":\"BTCUSDT\",\"b\":\"79597.00\",\"B\":\"4.000\",\"a\":\"79597.10\",\"A\":\"7.588\",\"T\":1788567726017,\"E\":1788567726017,\"st\":1}}"}
{"receive_ns":1788567726210589000,"stream":"btcusdt@bookTicker","event_type":"bookTicker","event_time_ms":1788567726017,"raw_json":"{\"stream\":\"btcusdt@bookTicker\",\"data\":{\"e\":\"bookTicker\",\"u\":11478508065493,\"s\":\"BTCUSDT\",\"ps\":\"BTCUSDT\",\"b\":\"79597.00\",\"B\":\"4.000\",\"a\":\"79597.10\",\"A\":\"7.590\",\"T\":1788567726017,\"E\":1788567726017,\"st\":1}}"}
{"receive_ns":1788567726216519000,"stream":"btcusdt@bookTicker","event_type":"bookTicker","event_time_ms":1788567726018,"raw_json":"{\"stream\":\"btcusdt@bookTicker\",\"data\":{\"e\":\"bookTicker\",\"u\":11478508065615,\"s\":\"BTCUSDT\",\"ps\":\"BTCUSDT\",\"b\":\"79597.00\",\"B\":\"4.000\",\"a\":\"79597.10\",\"A\":\"7.564\",\"T\":1788567726018,\"E\":1788567726018,\"st\":1}}"}
{"receive_ns":1788567726230552000,"stream":"btcusdt@bookTicker","event_type":"bookTicker","event_time_ms":1788567726024,"raw_json":"{\"stream\":\"btcusdt@bookTicker\",\"data\":{\"e\":\"bookTicker\",\"u\":11478508066281,\"s\":\"BTCUSDT\",\"ps\":\"BTCUSDT\",\"b\":\"79597.00\",\"B\":\"4.000\",\"a\":\"79597.10\",\"A\":\"7.563\",\"T\":1788567726024,\"E\":1788567726024,\"st\":1}}"}
{"receive_ns":1788567726241724000,"stream":"btcusdt@bookTicker","event_type":"bookTicker","event_time_ms":1788567726038,"raw_json":"{\"stream\":\"btcusdt@bookTicker\",\"data\":{\"e\":\"bookTicker\",\"u\":11478508067203,\"s\":\"BTCUSDT\",\"ps\":\"BTCUSDT\",\"b\":\"79597.00\",\"B\":\"4.000\",\"a\":\"79597.10\",\"A\":\"7.564\",\"T\":1788567726038,\"E\":1788567726038,\"st\":1}}"}
{"receive_ns":1788567726252321000,"stream":"btcusdt@bookTicker","event_type":"bookTicker","event_time_ms":1788567726038,"raw_json":"{\"stream\":\"btcusdt@bookTicker\",\"data\":{\"e\":\"bookTicker\",\"u\":11478508067204,\"s\":\"BTCUSDT\",\"ps\":\"BTCUSDT\",\"b\":\"79597.00\",\"B\":\"4.000\",\"a\":\"79597.10\",\"A\":\"7.565\",\"T\":1788567726038,\"E\":1788567726038,\"st\":1}}"}
{"receive_ns":1788567726269452000,"stream":"btcusdt@bookTicker","event_type":"bookTicker","event_time_ms":1788567726039,"raw_json":"{\"stream\":\"btcusdt@bookTicker\",\"data\":{\"e\":\"bookTicker\",\"u\":11478508067325,\"s\":\"BTCUSDT\",\"ps\":\"BTCUSDT\",\"b\":\"79597.00\",\"B\":\"4.000\",\"a\":\"79597.10\",\"A\":\"7.591\",\"T\":1788567726039,\"E\":1788567726039,\"st\":1}}"}
{"receive_ns":1788567726275813000,"stream":"btcusdt@depth@100ms","event_type":"depthUpdate","event_time_ms":1788567726081,"raw_json":"{\"stream\":\"btcusdt@depth@100ms\",\"data\":{\"e\":\"depthUpdate\",\"E\":1788567726081,\"T\":1788567726079,\"s\":\"BTCUSDT\",\"ps\":\"BTCUSDT\",\"U\":11478508062369,\"u\":11478508070180,\"pu\":11478508062279,\"b\":[[\"29397.00\",\"1.330\"],[\"29497.00\",\"0.770\"],[\"63678.00\",\"0.000\"],[\"71637.30\",\"0.043\"],[\"75617.10\",\"0.028\"],[\"75617.20\",\"0.006\"],[\"76413.10\",\"0.000\"],[\"78562.20\",\"15.034\"],[\"78571.20\",\"0.000\"],[\"78575.90\",\"0.006\"],[\"78590.40\",\"0.000\"],[\"78595.00\",\"0.006\"],[\"78602.00\",\"17.027\"],[\"78609.60\",\"0.100\"],[\"78614.10\",\"0.003\"],[\"78801.00\",\"12.675\"],[\"79199.00\",\"4.865\"],[\"79388.20\",\"0.000\"],[\"79388.30\",\"4.644\"],[\"79436.00\",\"2.681\"],[\"79475.40\",\"0.529\"],[\"79566.70\",\"0.000\"],[\"79568.20\",\"0.630\"],[\"79568.90\",\"0.052\"],[\"79578.80\",\"0.082\"],[\"79582.70\",\"0.194\"],[\"79584.20\",\"0.065\"],[\"79589.20\",\"0.076\"],[\"79591.30\",\"0.100\"],[\"79591.70\",\"0.003\"],[\"79591.80\",\"0.000\"],[\"79591.90\",\"0.077\"],[\"79592.00\",\"0.007\"],[\"79592.30\",\"0.026\"],[\"79592.50\",\"0.147\"],[\"79593.00\",\"0.055\"],[\"79594.00\",\"0.026\"],[\"79594.80\",\"0.252\"],[\"79595.00\",\"0.028\"],[\"79595.40\",\"0.002\"],[\"79595.80\",\"0.034\"],[\"79596.10\",\"0.000\"],[\"79596.70\",\"0.000\"],[\"79596.80\",\"0.167\"]],\"a\":[[\"79597.10\",\"7.591\"],[\"79597.20\",\"0.062\"],[\"79597.30\",\"0.126\"],[\"79597.50\",\"0.057\"],[\"79597.60\",\"0.117\"],[\"79597.80\",\"0.370\"],[\"79597.90\",\"0.028\"],[\"79598.50\",\"0.407\"],[\"79598.60\",\"0.001\"],[\"79598.70\",\"0.004\"],[\"79599.20\",\"0.000\"],[\"79599.30\",\"0.018\"],[\"79601.00\",\"0.123\"],[\"79601.10\",\"0.022\"],[\"79601.20\",\"0.000\"],[\"79601.30\",\"0.001\"],[\"79607.70\",\"0.000\"],[\"79608.30\",\"0.085\"],[\"79616.30\",\"0.013\"],[\"79618.00\",\"0.004\"],[\"79623.90\",\"0.637\"],[\"79624.10\",\"0.001\"],[\"79624.90\",\"0.021\"],[\"79625.70\",\"0.003\"],[\"79643.70\",\"2.748\"],[\"79643.90\",\"0.125\"],[\"79644.10\",\"0.003\"],[\"79656.80\",\"0.021\"],[\"79719.60\",\"0.482\"],[\"79759.00\",\"2.254\"],[\"79806.70\",\"2.806\"],[\"79995.10\",\"4.365\"],[\"80393.10\",\"108.439\"],[\"80552.30\",\"30.718\"],[\"80957.20\",\"0.000\"],[\"81189.00\",\"10.537\"]],\"st\":1}}"}
{"receive_ns":1788567726281978000,"stream":"btcusdt@depth@100ms","event_type":"depthUpdate","event_time_ms":1788567726183,"raw_json":"{\"stream\":\"btcusdt@depth@100ms\",\"data\":{\"e\":\"depthUpdate\",\"E\":1788567726183,\"T\":1788567726181,\"s\":\"BTCUSDT\",\"ps\":\"BTCUSDT\",\"U\":11478508070270,\"u\":11478508077212,\"pu\":11478508070180,\"b\":[[\"1000.00\",\"25.004\"],[\"29397.00\",\"1.512\"],[\"29497.00\",\"0.588\"],[\"63678.00\",\"0.000\"],[\"71637.30\",\"0.043\"],[\"76413.10\",\"0.002\"],[\"78372.40\",\"0.637\"],[\"78380.70\",\"0.223\"],[\"78602.00\",\"17.218\"],[\"78708.60\",\"0.014\"],[\"78801.00\",\"12.675\"],[\"79557.40\",\"0.001\"],[\"79566.50\",\"0.073\"],[\"79573.30\",\"0.481\"],[\"79591.20\",\"0.082\"],[\"79591.90\",\"0.001\"],[\"79592.20\",\"0.000\"],[\"79595.20\",\"0.026\"],[\"79595.40\",\"0.028\"]],\"a\":[[\"79613.20\",\"0.002\"],[\"79643.90\",\"0.000\"],[\"79644.00\",\"0.006\"],[\"79644.20\",\"0.128\"],[\"79691.80\",\"0.123\"],[\"79692.80\",\"0.000\"],[\"79692.90\",\"0.002\"],[\"79701.30\",\"0.000\"],[\"79701.50\",\"0.345\"],[\"79702.60\",\"0.015\"],[\"79704.60\",\"0.042\"],[\"79704.80\",\"0.000\"],[\"79806.70\",\"4.847\"],[\"80313.50\",\"1.998\"],[\"80393.10\",\"108.439\"]],\"st\":1}}"}
{"receive_ns":1788567726293264000,"stream":"btcusdt@bookTicker","event_type":"bookTicker","event_time_ms":1788567726198,"raw_json":"{\"stream\":\"btcusdt@bookTicker\",\"data\":{\"e\":\"bookTicker\",\"u\":11478508078074,\"s\":\"BTCUSDT\",\"ps\":\"BTCUSDT\",\"b\":\"79597.00\",\"B\":\"3.952\",\"a\":\"79597.10\",\"A\":\"7.591\",\"T\":1788567726198,\"E\":1788567726198,\"st\":1}}"}
{"receive_ns":1788567726307774000,"stream":"btcusdt@bookTicker","event_type":"bookTicker","event_time_ms":1788567726200,"raw_json":"{\"stream\":\"btcusdt@bookTicker\",\"data\":{\"e\":\"bookTicker\",\"u\":11478508078205,\"s\":\"BTCUSDT\",\"ps\":\"BTCUSDT\",\"b\":\"79597.00\",\"B\":\"4.000\",\"a\":\"79597.10\",\"A\":\"7.591\",\"T\":1788567726200,\"E\":1788567726200,\"st\":1}}"}
{"receive_ns":1788567726308019000,"stream":"btcusdt@bookTicker","event_type":"bookTicker","event_time_ms":1788567726220,"raw_json":"{\"stream\":\"btcusdt@bookTicker\",\"data\":{\"e\":\"bookTicker\",\"u\":11478508079346,\"s\":\"BTCUSDT\",\"ps\":\"BTCUSDT\",\"b\":\"79597.00\",\"B\":\"4.000\",\"a\":\"79597.10\",\"A\":\"7.589\",\"T\":1788567726220,\"E\":1788567726220,\"st\":1}}"}
{"receive_ns":1788567726314659000,"stream":"btcusdt@bookTicker","event_type":"bookTicker","event_time_ms":1788567726220,"raw_json":"{\"stream\":\"btcusdt@bookTicker\",\"data\":{\"e\":\"bookTicker\",\"u\":11478508079347,\"s\":\"BTCUSDT\",\"ps\":\"BTCUSDT\",\"b\":\"79597.00\",\"B\":\"4.000\",\"a\":\"79597.10\",\"A\":\"7.585\",\"T\":1788567726220,\"E\":1788567726220,\"st\":1}}"}
{"receive_ns":1788567726314885000,"stream":"btcusdt@bookTicker","event_type":"bookTicker","event_time_ms":1788567726220,"raw_json":"{\"stream\":\"btcusdt@bookTicker\",\"data\":{\"e\":\"bookTicker\",\"u\":11478508079348,\"s\":\"BTCUSDT\",\"ps\":\"BTCUSDT\",\"b\":\"79597.00\",\"B\":\"4.000\",\"a\":\"79597.10\",\"A\":\"7.441\",\"T\":1788567726220,\"E\":1788567726220,\"st\":1}}"}
{"receive_ns":1788567726315067000,"stream":"btcusdt@bookTicker","event_type":"bookTicker","event_time_ms":1788567726220,"raw_json":"{\"stream\":\"btcusdt@bookTicker\",\"data\":{\"e\":\"bookTicker\",\"u\":11478508079354,\"s\":\"BTCUSDT\",\"ps\":\"BTCUSDT\",\"b\":\"79597.00\",\"B\":\"4.000\",\"a\":\"79597.10\",\"A\":\"7.404\",\"T\":1788567726220,\"E\":1788567726220,\"st\":1}}"}
{"receive_ns":1788567726326589000,"stream":"btcusdt@bookTicker","event_type":"bookTicker","event_time_ms":1788567726225,"raw_json":"{\"stream\":\"btcusdt@bookTicker\",\"data\":{\"e\":\"bookTicker\",\"u\":11478508079592,\"s\":\"BTCUSDT\",\"ps\":\"BTCUSDT\",\"b\":\"79597.00\",\"B\":\"4.000\",\"a\":\"79597.10\",\"A\":\"5.967\",\"T\":1788567726224,\"E\":1788567726225,\"st\":1}}"}
{"receive_ns":1788567726346503000,"stream":"btcusdt@bookTicker","event_type":"bookTicker","event_time_ms":1788567726226,"raw_json":"{\"stream\":\"btcusdt@bookTicker\",\"data\":{\"e\":\"bookTicker\",\"u\":11478508079724,\"s\":\"BTCUSDT\",\"ps\":\"BTCUSDT\",\"b\":\"79597.00\",\"B\":\"4.000\",\"a\":\"79597.10\",\"A\":\"6.374\",\"T\":1788567726226,\"E\":1788567726226,\"st\":1}}"}
{"receive_ns":1788567726352325000,"stream":"btcusdt@bookTicker","event_type":"bookTicker","event_time_ms":1788567726228,"raw_json":"{\"stream\":\"btcusdt@bookTicker\",\"data\":{\"e\":\"bookTicker\",\"u\":11478508079793,\"s\":\"BTCUSDT\",\"ps\":\"BTCUSDT\",\"b\":\"79597.00\",\"B\":\"4.000\",\"a\":\"79597.10\",\"A\":\"6.372\",\"T\":1788567726227,\"E\":1788567726228,\"st\":1}}"}
{"receive_ns":1788567726358888000,"stream":"btcusdt@bookTicker","event_type":"bookTicker","event_time_ms":1788567726228,"raw_json":"{\"stream\":\"btcusdt@bookTicker\",\"data\":{\"e\":\"bookTicker\",\"u\":11478508079831,\"s\":\"BTCUSDT\",\"ps\":\"BTCUSDT\",\"b\":\"79597.00\",\"B\":\"4.006\",\"a\":\"79597.10\",\"A\":\"6.372\",\"T\":1788567726228,\"E\":1788567726228,\"st\":1}}"}
{"receive_ns":1788567726367909000,"stream":"btcusdt@depth@100ms","event_type":"depthUpdate","event_time_ms":1788567726285,"raw_json":"{\"stream\":\"btcusdt@depth@100ms\",\"data\":{\"e\":\"depthUpdate\",\"E\":1788567726285,\"T\":1788567726281,\"s\":\"BTCUSDT\",\"ps\":\"BTCUSDT\",\"U\":11478508077346,\"u\":11478508083507,\"pu\":11478508077212,\"b\":[[\"1000.00\",\"25.004\"],[\"29397.00\",\"1.687\"],[\"29497.00\",\"0.413\"],[\"63677.60\",\"0.000\"],[\"71637.30\",\"0.043\"],[\"76413.10\",\"0.000\"],[\"78005.10\",\"10.831\"],[\"78801.00\",\"12.675\"],[\"78928.30\",\"0.249\"],[\"78960.20\",\"7.749\"],[\"79199.00\",\"4.866\"],[\"79536.60\",\"19.704\"],[\"79537.80\",\"3.500\"],[\"79540.80\",\"0.001\"],[\"79567.80\",\"0.000\"],[\"79571.00\",\"0.000\"],[\"79572.50\",\"0.884\"],[\"79588.60\",\"0.034\"],[\"79588.80\",\"0.002\"],[\"79591.50\",\"0.000\"],[\"79592.30\",\"0.000\"],[\"79592.40\",\"0.004\"],[\"79592.50\",\"0.148\"],[\"79595.10\",\"0.002\"],[\"79595.60\",\"0.038\"],[\"79597.00\",\"4.006\"]],\"a\":[[\"79597.10\",\"6.372\"],[\"79604.00\",\"0.122\"],[\"79605.60\",\"0.006\"],[\"79606.30\",\"0.001\"],[\"79610.70\",\"0.104\"],[\"79610.90\",\"0.442\"],[\"79612.80\",\"0.003\"],[\"79615.80\",\"0.000\"],[\"79616.40\",\"2.298\"],[\"79619.70\",\"0.002\"],[\"79619.90\",\"0.000\"],[\"79620.10\",\"0.051\"],[\"79620.50\",\"0.628\"],[\"79620.60\",\"0.454\"],[\"79623.70\",\"0.000\"],[\"79624.40\",\"0.627\"],[\"79644.00\",\"0.006\"],[\"79644.30\",\"0.126\"],[\"79644.40\",\"0.866\"],[\"79667.70\",\"3.140\"],[\"79668.80\",\"0.034\"],[\"79995.10\",\"4.366\"],[\"80393.10\",\"108.439\"]],\"st\":1}}"}
{"receive_ns":1788567726374604000,"stream":"btcusdt@bookTicker","event_type":"bookTicker","event_time_ms":1788567726314,"raw_json":"{\"stream\":\"btcusdt@bookTicker\",\"data\":{\"e\":\"bookTicker\",\"u\":11478508086597,\"s\":\"BTCUSDT\",\"ps\":\"BTCUSDT\",\"b\":\"79597.00\",\"B\":\"3.015\",\"a\":\"79597.10\",\"A\":\"6.372\",\"T\":1788567726314,\"E\":1788567726314,\"st\":1}}"}
{"receive_ns":1788567726385291000,"stream":"btcusdt@bookTicker","event_type":"bookTicker","event_time_ms":1788567726315,"raw_json":"{\"stream\":\"btcusdt@bookTicker\",\"data\":{\"e\":\"bookTicker\",\"u\":11478508086684,\"s\":\"BTCUSDT\",\"ps\":\"BTCUSDT\",\"b\":\"79597.00\",\"B\":\"3.015\",\"a\":\"79597.10\",\"A\":\"6.374\",\"T\":1788567726315,\"E\":1788567726315,\"st\":1}}"}
{"receive_ns":1788567726397633000,"stream":"btcusdt@bookTicker","event_type":"bookTicker","event_time_ms":1788567726317,"raw_json":"{\"stream\":\"btcusdt@bookTicker\",\"data\":{\"e\":\"bookTicker\",\"u\":11478508086923,\"s\":\"BTCUSDT\",\"ps\":\"BTCUSDT\",\"b\":\"79597.00\",\"B\":\"3.009\",\"a\":\"79597.10\",\"A\":\"6.374\",\"T\":1788567726317,\"E\":1788567726317,\"st\":1}}"}
{"receive_ns":1788567726415965000,"stream":"btcusdt@bookTicker","event_type":"bookTicker","event_time_ms":1788567726323,"raw_json":"{\"stream\":\"btcusdt@bookTicker\",\"data\":{\"e\":\"bookTicker\",\"u\":11478508087339,\"s\":\"BTCUSDT\",\"ps\":\"BTCUSDT\",\"b\":\"79597.00\",\"B\":\"4.019\",\"a\":\"79597.10\",\"A\":\"6.374\",\"T\":1788567726323,\"E\":1788567726323,\"st\":1}}"}
{"receive_ns":1788567726423459000,"stream":"btcusdt@bookTicker","event_type":"bookTicker","event_time_ms":1788567726324,"raw_json":"{\"stream\":\"btcusdt@bookTicker\",\"data\":{\"e\":\"bookTicker\",\"u\":11478508087396,\"s\":\"BTCUSDT\",\"ps\":\"BTCUSDT\",\"b\":\"79597.00\",\"B\":\"4.018\",\"a\":\"79597.10\",\"A\":\"6.374\",\"T\":1788567726324,\"E\":1788567726324,\"st\":1}}"}
{"receive_ns":1788567726434906000,"stream":"btcusdt@bookTicker","event_type":"bookTicker","event_time_ms":1788567726324,"raw_json":"{\"stream\":\"btcusdt@bookTicker\",\"data\":{\"e\":\"bookTicker\",\"u\":11478508087397,\"s\":\"BTCUSDT\",\"ps\":\"BTCUSDT\",\"b\":\"79597.00\",\"B\":\"4.019\",\"a\":\"79597.10\",\"A\":\"6.374\",\"T\":1788567726324,\"E\":1788567726324,\"st\":1}}"}
{"receive_ns":1788567726440560000,"stream":"btcusdt@bookTicker","event_type":"bookTicker","event_time_ms":1788567726324,"raw_json":"{\"stream\":\"btcusdt@bookTicker\",\"data\":{\"e\":\"bookTicker\",\"u\":11478508087406,\"s\":\"BTCUSDT\",\"ps\":\"BTCUSDT\",\"b\":\"79597.00\",\"B\":\"4.018\",\"a\":\"79597.10\",\"A\":\"6.374\",\"T\":1788567726324,\"E\":1788567726324,\"st\":1}}"}
{"receive_ns":1788567726457182000,"stream":"btcusdt@depth@100ms","event_type":"depthUpdate","event_time_ms":1788567726387,"raw_json":"{\"stream\":\"btcusdt@depth@100ms\",\"data\":{\"e\":\"depthUpdate\",\"E\":1788567726387,\"T\":1788567726385,\"s\":\"BTCUSDT\",\"ps\":\"BTCUSDT\",\"U\":11478508083778,\"u\":11478508091782,\"pu\":11478508083507,\"b\":[[\"29297.00\",\"0.042\"],[\"29397.00\",\"1.785\"],[\"29497.00\",\"0.273\"],[\"71637.30\",\"0.043\"],[\"76413.10\",\"0.002\"],[\"78548.30\",\"7.186\"],[\"78801.00\",\"12.675\"],[\"79199.00\",\"4.866\"],[\"79522.30\",\"0.002\"],[\"79538.20\",\"0.001\"],[\"79576.20\",\"0.247\"],[\"79579.30\",\"0.049\"],[\"79585.30\",\"0.000\"],[\"79586.90\",\"0.003\"],[\"79592.50\",\"0.122\"],[\"79593.10\",\"0.021\"],[\"79595.80\",\"0.000\"],[\"79596.40\",\"0.042\"],[\"79596.80\",\"0.167\"],[\"79597.00\",\"4.018\"]],\"a\":[[\"79597.10\",\"6.374\"],[\"79605.40\",\"0.080\"],[\"79608.10\",\"0.007\"],[\"79608.30\",\"0.081\"],[\"79610.70\",\"0.104\"],[\"79616.30\",\"0.013\"],[\"79623.90\",\"0.010\"],[\"79624.20\",\"0.628\"],[\"79626.60\",\"0.005\"],[\"79629.90\",\"0.001\"],[\"79634.40\",\"0.022\"],[\"79644.30\",\"0.001\"],[\"79645.00\",\"0.127\"],[\"79670.20\",\"3.873\"],[\"79671.50\",\"0.000\"],[\"80000.00\",\"45.478\"],[\"80393.10\",\"108.439\"],[\"80617.70\",\"2.612\"]],\"st\":1}}"}
{"receive_ns":1788567726462774000,"stream":"btcusdt@bookTicker","event_type":"bookTicker","event_time_ms":1788567726390,"raw_json":"{\"stream\":\"btcusdt@bookTicker\",\"data\":{\"e\":\"bookTicker\",\"u\":11478508092223,\"s\":\"BTCUSDT\",\"ps\":\"BTCUSDT\",\"b\":\"79597.00\",\"B\":\"3.897\",\"a\":\"79597.10\",\"A\":\"6.374\",\"T\":1788567726390,\"E\":1788567726390,\"st\":1}}"}
{"receive_ns":1788567726474374000,"stream":"btcusdt@bookTicker","event_type":"bookTicker","event_time_ms":1788567726392,"raw_json":"{\"stream\":\"btcusdt@bookTicker\",\"data\":{\"e\":\"bookTicker\",\"u\":11478508092499,\"s\":\"BTCUSDT\",\"ps\":\"BTCUSDT\",\"b\":\"79597.00\",\"B\":\"4.021\",\"a\":\"79597.10\",\"A\":\"6.374\",\"T\":1788567726392,\"E\":1788567726392,\"st\":1}}"}
{"receive_ns":1788567726486083000,"stream":"btcusdt@bookTicker","event_type":"bookTicker","event_time_ms":1788567726394,"raw_json":"{\"stream\":\"btcusdt@bookTicker\",\"data\":{\"e\":\"bookTicker\",\"u\":11478508092567,\"s\":\"BTCUSDT\",\"ps\":\"BTCUSDT\",\"b\":\"79597.00\",\"B\":\"4.022\",\"a\":\"79597.10\",\"A\":\"6.374\",\"T\":1788567726393,\"E\":1788567726394,\"st\":1}}"}
{"receive_ns":1788567726506419000,"stream":"btcusdt@bookTicker","event_type":"bookTicker","event_time_ms":1788567726458,"raw_json":"{\"stream\":\"btcusdt@bookTicker\",\"data\":{\"e\":\"bookTicker\",\"u\":11478508095816,\"s\":\"BTCUSDT\",\"ps\":\"BTCUSDT\",\"b\":\"79597.00\",\"B\":\"4.018\",\"a\":\"79597.10\",\"A\":\"6.374\",\"T\":1788567726457,\"E\":1788567726458,\"st\":1}}"}
{"receive_ns":1788567726518508000,"stream":"btcusdt@trade","event_type":"trade","event_time_ms":1788567726458,"raw_json":"{\"stream\":\"btcusdt@trade\",\"data\":{\"e\":\"trade\",\"E\":1788567726458,\"T\":1788567726457,\"s\":\"BTCUSDT\",\"t\":8054122611,\"p\":\"79597.00\",\"q\":\"0.001\",\"X\":\"MARKET\",\"m\":true,\"st\":1}}"}
{"receive_ns":1788567726522966000,"stream":"btcusdt@trade","event_type":"trade","event_time_ms":1788567726458,"raw_json":"{\"stream\":\"btcusdt@trade\",\"data\":{\"e\":\"trade\",\"E\":1788567726458,\"T\":1788567726457,\"s\":\"BTCUSDT\",\"t\":8054122612,\"p\":\"79597.00\",\"q\":\"0.001\",\"X\":\"MARKET\",\"m\":true,\"st\":1}}"}
{"receive_ns":1788567726528323000,"stream":"btcusdt@trade","event_type":"trade","event_time_ms":1788567726458,"raw_json":"{\"stream\":\"btcusdt@trade\",\"data\":{\"e\":\"trade\",\"E\":1788567726458,\"T\":1788567726457,\"s\":\"BTCUSDT\",\"t\":8054122613,\"p\":\"79597.00\",\"q\":\"0.002\",\"X\":\"MARKET\",\"m\":true,\"st\":1}}"}
{"receive_ns":1788567726539417000,"stream":"btcusdt@bookTicker","event_type":"bookTicker","event_time_ms":1788567726460,"raw_json":"{\"stream\":\"btcusdt@bookTicker\",\"data\":{\"e\":\"bookTicker\",\"u\":11478508096081,\"s\":\"BTCUSDT\",\"ps\":\"BTCUSDT\",\"b\":\"79597.00\",\"B\":\"4.018\",\"a\":\"79597.10\",\"A\":\"6.348\",\"T\":1788567726460,\"E\":1788567726460,\"st\":1}}"}
{"receive_ns":1788567726545138000,"stream":"btcusdt@depth@100ms","event_type":"depthUpdate","event_time_ms":1788567726489,"raw_json":"{\"stream\":\"btcusdt@depth@100ms\",\"data\":{\"e\":\"depthUpdate\",\"E\":1788567726489,\"T\":1788567726487,\"s\":\"BTCUSDT\",\"ps\":\"BTCUSDT\",\"U\":11478508092046,\"u\":11478508097595,\"pu\":11478508091782,\"b\":[[\"1000.00\",\"25.004\"],[\"29297.00\",\"0.098\"],[\"29397.00\",\"1.848\"],[\"29497.00\",\"0.154\"],[\"71637.30\",\"0.043\"],[\"78371.30\",\"0.000\"],[\"78801.00\",\"12.675\"],[\"79475.40\",\"0.536\"],[\"79592.80\",\"0.505\"],[\"79597.00\",\"4.018\"]],\"a\":[[\"79597.10\",\"6.348\"],[\"79719.60\",\"0.485\"],[\"79904.40\",\"0.552\"],[\"79907.90\",\"1.938\"],[\"80165.10\",\"0.093\"],[\"80313.50\",\"2.868\"],[\"80393.10\",\"108.439\"],[\"80592.10\",\"12.159\"],[\"81189.00\",\"10.540\"]],\"st\":1}}"}
{"receive_ns":1788567726580922000,"stream":"btcusdt@depth@100ms","event_type":"depthUpdate","event_time_ms":1788567726591,"raw_json":"{\"stream\":\"btcusdt@depth@100ms\",\"data\":{\"e\":\"depthUpdate\",\"E\":1788567726591,\"T\":1788567726589,\"s\":\"BTCUSDT\",\"ps\":\"BTCUSDT\",\"U\":11478508097678,\"u\":11478508103680,\"pu\":11478508097595,\"b\":[[\"1000.00\",\"25.004\"],[\"29297.00\",\"0.161\"],[\"29397.00\",\"1.904\"],[\"29497.00\",\"0.035\"],[\"63678.00\",\"0.000\"],[\"71637.30\",\"0.043\"],[\"76413.10\",\"0.000\"],[\"78372.40\",\"0.000\"],[\"78801.00\",\"12.675\"],[\"78928.30\",\"0.179\"],[\"79199.00\",\"4.866\"],[\"79501.40\",\"0.046\"],[\"79541.20\",\"0.002\"]],\"a\":[[\"79597.20\",\"0.088\"],[\"79601.40\",\"0.109\"],[\"79668.80\",\"0.034\"],[\"80393.10\",\"108.439\"],[\"80479.40\",\"0.002\"],[\"80525.80\",\"4.422\"]],\"st\":1}}"}
{"receive_ns":1788567726629512000,"stream":"btcusdt@bookTicker","event_type":"bookTicker","event_time_ms":1788567726636,"raw_json":"{\"stream\":\"btcusdt@bookTicker\",\"data\":{\"e\":\"bookTicker\",\"u\":11478508106210,\"s\":\"BTCUSDT\",\"ps\":\"BTCUSDT\",\"b\":\"79597.00\",\"B\":\"4.018\",\"a\":\"79597.10\",\"A\":\"6.386\",\"T\":1788567726636,\"E\":1788567726636,\"st\":1}}"}
{"receive_ns":1788567726640393000,"stream":"btcusdt@bookTicker","event_type":"bookTicker","event_time_ms":1788567726648,"raw_json":"{\"stream\":\"btcusdt@bookTicker\",\"data\":{\"e\":\"bookTicker\",\"u\":11478508107106,\"s\":\"BTCUSDT\",\"ps\":\"BTCUSDT\",\"b\":\"79597.00\",\"B\":\"4.018\",\"a\":\"79597.10\",\"A\":\"6.385\",\"T\":1788567726648,\"E\":1788567726648,\"st\":1}}"}
{"receive_ns":1788567726647024000,"stream":"btcusdt@trade","event_type":"trade","event_time_ms":1788567726648,"raw_json":"{\"stream\":\"btcusdt@trade\",\"data\":{\"e\":\"trade\",\"E\":1788567726648,\"T\":1788567726648,\"s\":\"BTCUSDT\",\"t\":8054122614,\"p\":\"79597.10\",\"q\":\"0.001\",\"X\":\"MARKET\",\"m\":false,\"st\":1}}"}
{"receive_ns":1788567726676595000,"stream":"btcusdt@depth@100ms","event_type":"depthUpdate","event_time_ms":1788567726693,"raw_json":"{\"stream\":\"btcusdt@depth@100ms\",\"data\":{\"e\":\"depthUpdate\",\"E\":1788567726693,\"T\":1788567726692,\"s\":\"BTCUSDT\",\"ps\":\"BTCUSDT\",\"U\":11478508103764,\"u\":11478508110131,\"pu\":11478508103680,\"b\":[[\"29297.00\",\"0.301\"],[\"29397.00\",\"1.799\"],[\"29497.00\",\"0.000\"],[\"71637.30\",\"0.043\"],[\"71673.00\",\"0.000\"],[\"75617.20\",\"0.004\"],[\"76413.10\",\"0.002\"],[\"78575.90\",\"0.000\"],[\"78578.30\",\"0.005\"],[\"78801.00\",\"12.675\"],[\"78928.30\",\"0.139\"],[\"79199.00\",\"4.876\"],[\"79436.00\",\"0.000\"],[\"79471.40\",\"0.000\"],[\"79471.70\",\"0.043\"],[\"79475.40\",\"0.000\"],[\"79588.60\",\"0.000\"]],\"a\":[[\"79597.10\",\"6.385\"],[\"79616.30\",\"0.641\"],[\"79617.60\",\"0.002\"],[\"79624.10\",\"0.001\"],[\"79624.20\",\"0.001\"],[\"79719.60\",\"0.001\"],[\"79759.00\",\"0.095\"],[\"79829.60\",\"0.000\"],[\"79829.90\",\"0.003\"],[\"79871.50\",\"0.004\"],[\"79944.20\",\"0.000\"],[\"80006.80\",\"0.004\"],[\"80179.50\",\"0.000\"],[\"80245.60\",\"0.004\"],[\"80393.10\",\"107.197\"],[\"80617.60\",\"8.985\"],[\"80639.10\",\"0.000\"]],\"st\":1}}"}
{"receive_ns":1788567726779575000,"stream":"btcusdt@depth@100ms","event_type":"depthUpdate","event_time_ms":1788567726795,"raw_json":"{\"stream\":\"btcusdt@depth@100ms\",\"data\":{\"e\":\"depthUpdate\",\"E\":1788567726795,\"T\":1788567726793,\"s\":\"BTCUSDT\",\"ps\":\"BTCUSDT\",\"U\":11478508110202,\"u\":11478508116747,\"pu\":11478508110131,\"b\":[[\"1000.00\",\"25.004\"],[\"29297.00\",\"0.483\"],[\"29397.00\",\"1.617\"],[\"71637.30\",\"0.043\"],[\"76413.10\",\"0.000\"],[\"77368.30\",\"2.579\"],[\"78097.20\",\"0.639\"],[\"78721.40\",\"9.387\"],[\"78801.00\",\"12.674\"],[\"78928.30\",\"0.129\"],[\"79388.30\",\"4.729\"],[\"79436.00\",\"2.711\"],[\"79475.40\",\"0.536\"]],\"a\":[[\"79624.60\",\"0.088\"],[\"79627.40\",\"0.001\"],[\"79719.60\",\"0.485\"],[\"79759.00\",\"2.779\"],[\"79804.90\",\"1.081\"],[\"79806.70\",\"4.847\"],[\"80393.10\",\"107.197\"],[\"80565.60\",\"11.160\"]],\"st\":1}}"}
{"receive_ns":1788567726876910000,"stream":"btcusdt@depth@100ms","event_type":"depthUpdate","event_time_ms":1788567726897,"raw_json":"{\"stream\":\"btcusdt@depth@100ms\",\"data\":{\"e\":\"depthUpdate\",\"E\":1788567726897,\"T\":1788567726896,\"s\":\"BTCUSDT\",\"ps\":\"BTCUSDT\",\"U\":11478508116831,\"u\":11478508123929,\"pu\":11478508116747,\"b\":[[\"1000.00\",\"25.004\"],[\"29297.00\",\"0.658\"],[\"29397.00\",\"1.442\"],[\"71637.30\",\"0.043\"],[\"78482.60\",\"33.537\"],[\"78567.00\",\"0.550\"],[\"78641.80\",\"32.930\"],[\"78801.00\",\"12.674\"],[\"78928.30\",\"0.069\"],[\"78960.20\",\"7.497\"],[\"79594.80\",\"0.000\"],[\"79595.60\",\"0.012\"],[\"79595.80\",\"0.000\"],[\"79596.40\",\"0.016\"]],\"a\":[[\"80393.10\",\"107.197\"]],\"st\":1}}"}
{"receive_ns":1788567726888993000,"stream":"btcusdt@trade","event_type":"trade","event_time_ms":1788567726904,"raw_json":"{\"stream\":\"btcusdt@trade\",\"data\":{\"e\":\"trade\",\"E\":1788567726904,\"T\":1788567726904,\"s\":\"BTCUSDT\",\"t\":8054122615,\"p\":\"0\",\"q\":\"0\",\"X\":\"NA\",\"m\":false,\"st\":1}}"}
{"receive_ns":1788567726894523000,"stream":"btcusdt@bookTicker","event_type":"bookTicker","event_time_ms":1788567726915,"raw_json":"{\"stream\":\"btcusdt@bookTicker\",\"data\":{\"e\":\"bookTicker\",\"u\":11478508124926,\"s\":\"BTCUSDT\",\"ps\":\"BTCUSDT\",\"b\":\"79597.00\",\"B\":\"4.018\",\"a\":\"79597.10\",\"A\":\"6.371\",\"T\":1788567726915,\"E\":1788567726915,\"st\":1}}"}
{"receive_ns":1788567726900065000,"stream":"btcusdt@trade","event_type":"trade","event_time_ms":1788567726915,"raw_json":"{\"stream\":\"btcusdt@trade\",\"data\":{\"e\":\"trade\",\"E\":1788567726915,\"T\":1788567726915,\"s\":\"BTCUSDT\",\"t\":8054122616,\"p\":\"79597.10\",\"q\":\"0.014\",\"X\":\"MARKET\",\"m\":false,\"st\":1}}"}
{"receive_ns":1788567726983753000,"stream":"btcusdt@depth@100ms","event_type":"depthUpdate","event_time_ms":1788567726999,"raw_json":"{\"stream\":\"btcusdt@depth@100ms\",\"data\":{\"e\":\"depthUpdate\",\"E\":1788567726999,\"T\":1788567726998,\"s\":\"BTCUSDT\",\"ps\":\"BTCUSDT\",\"U\":11478508124018,\"u\":11478508130003,\"pu\":11478508123929,\"b\":[[\"29297.00\",\"0.840\"],[\"29397.00\",\"1.260\"],[\"71637.30\",\"0.043\"],[\"76413.10\",\"0.002\"],[\"78641.80\",\"33.311\"],[\"78707.50\",\"0.000\"],[\"78801.00\",\"12.674\"],[\"78880.60\",\"11.644\"],[\"78928.30\",\"0.062\"],[\"78960.20\",\"7.498\"],[\"79199.00\",\"4.876\"],[\"79436.00\",\"1.932\"],[\"79475.40\",\"0.410\"],[\"79495.10\",\"0.025\"],[\"79505.40\",\"0.000\"],[\"79505.60\",\"4.423\"],[\"79506.80\",\"1.190\"],[\"79562.20\",\"0.002\"],[\"79564.20\",\"0.253\"],[\"79575.70\",\"0.630\"],[\"79576.40\",\"0.009\"],[\"79583.80\",\"0.285\"],[\"79584.90\",\"0.251\"],[\"79592.00\",\"0.005\"],[\"79592.20\",\"0.004\"],[\"79592.40\",\"0.002\"],[\"79593.90\",\"0.026\"]],\"a\":[[\"79597.10\",\"6.371\"],[\"79607.00\",\"0.000\"],[\"79607.20\",\"0.255\"],[\"79617.00\",\"0.002\"],[\"79620.00\",\"0.598\"],[\"79620.60\",\"0.002\"],[\"79688.10\",\"3.432\"],[\"79719.60\",\"0.366\"],[\"79759.00\",\"1.628\"],[\"79804.90\",\"0.302\"],[\"79806.70\",\"4.828\"],[\"79818.80\",\"6.808\"],[\"80393.10\",\"108.129\"],[\"80455.00\",\"0.650\"],[\"80638.50\",\"0.000\"],[\"80813.60\",\"0.000\"]],\"st\":1}}"}
{"receive_ns":1788567726995343000,"stream":"btcusdt@bookTicker","event_type":"bookTicker","event_time_ms":1788567727000,"raw_json":"{\"stream\":\"btcusdt@bookTicker\",\"data\":{\"e\":\"bookTicker\",\"u\":11478508130125,\"s\":\"BTCUSDT\",\"ps\":\"BTCUSDT\",\"b\":\"79597.00\",\"B\":\"4.018\",\"a\":\"79597.10\",\"A\":\"6.318\",\"T\":1788567727000,\"E\":1788567727000,\"st\":1}}"}
{"receive_ns":1788567727007659000,"stream":"btcusdt@bookTicker","event_type":"bookTicker","event_time_ms":1788567727025,"raw_json":"{\"stream\":\"btcusdt@bookTicker\",\"data\":{\"e\":\"bookTicker\",\"u\":11478508131752,\"s\":\"BTCUSDT\",\"ps\":\"BTCUSDT\",\"b\":\"79597.00\",\"B\":\"4.100\",\"a\":\"79597.10\",\"A\":\"6.318\",\"T\":1788567727024,\"E\":1788567727025,\"st\":1}}"}
{"receive_ns":1788567727018737000,"stream":"btcusdt@bookTicker","event_type":"bookTicker","event_time_ms":1788567727026,"raw_json":"{\"stream\":\"btcusdt@bookTicker\",\"data\":{\"e\":\"bookTicker\",\"u\":11478508131841,\"s\":\"BTCUSDT\",\"ps\":\"BTCUSDT\",\"b\":\"79597.00\",\"B\":\"4.099\",\"a\":\"79597.10\",\"A\":\"6.318\",\"T\":1788567727025,\"E\":1788567727026,\"st\":1}}"}
{"receive_ns":1788567727029934000,"stream":"btcusdt@bookTicker","event_type":"bookTicker","event_time_ms":1788567727026,"raw_json":"{\"stream\":\"btcusdt@bookTicker\",\"data\":{\"e\":\"bookTicker\",\"u\":11478508131867,\"s\":\"BTCUSDT\",\"ps\":\"BTCUSDT\",\"b\":\"79597.00\",\"B\":\"4.099\",\"a\":\"79597.10\",\"A\":\"6.316\",\"T\":1788567727026,\"E\":1788567727026,\"st\":1}}"}
{"receive_ns":1788567727036128000,"stream":"btcusdt@bookTicker","event_type":"bookTicker","event_time_ms":1788567727051,"raw_json":"{\"stream\":\"btcusdt@bookTicker\",\"data\":{\"e\":\"bookTicker\",\"u\":11478508133398,\"s\":\"BTCUSDT\",\"ps\":\"BTCUSDT\",\"b\":\"79597.00\",\"B\":\"4.099\",\"a\":\"79597.10\",\"A\":\"6.328\",\"T\":1788567727050,\"E\":1788567727051,\"st\":1}}"}
{"receive_ns":1788567727045963000,"stream":"btcusdt@bookTicker","event_type":"bookTicker","event_time_ms":1788567727052,"raw_json":"{\"stream\":\"btcusdt@bookTicker\",\"data\":{\"e\":\"bookTicker\",\"u\":11478508133488,\"s\":\"BTCUSDT\",\"ps\":\"BTCUSDT\",\"b\":\"79597.00\",\"B\":\"4.100\",\"a\":\"79597.10\",\"A\":\"6.328\",\"T\":1788567727052,\"E\":1788567727052,\"st\":1}}"}
{"receive_ns":1788567727052189000,"stream":"btcusdt@bookTicker","event_type":"bookTicker","event_time_ms":1788567727054,"raw_json":"{\"stream\":\"btcusdt@bookTicker\",\"data\":{\"e\":\"bookTicker\",\"u\":11478508133586,\"s\":\"BTCUSDT\",\"ps\":\"BTCUSDT\",\"b\":\"79597.00\",\"B\":\"4.100\",\"a\":\"79597.10\",\"A\":\"6.250\",\"T\":1788567727054,\"E\":1788567727054,\"st\":1}}"}
{"receive_ns":1788567727058478000,"stream":"btcusdt@bookTicker","event_type":"bookTicker","event_time_ms":1788567727054,"raw_json":"{\"stream\":\"btcusdt@bookTicker\",\"data\":{\"e\":\"bookTicker\",\"u\":11478508133600,\"s\":\"BTCUSDT\",\"ps\":\"BTCUSDT\",\"b\":\"79597.00\",\"B\":\"4.100\",\"a\":\"79597.10\",\"A\":\"6.173\",\"T\":1788567727054,\"E\":1788567727054,\"st\":1}}"}
{"receive_ns":1788567727064078000,"stream":"btcusdt@bookTicker","event_type":"bookTicker","event_time_ms":1788567727054,"raw_json":"{\"stream\":\"btcusdt@bookTicker\",\"data\":{\"e\":\"bookTicker\",\"u\":11478508133618,\"s\":\"BTCUSDT\",\"ps\":\"BTCUSDT\",\"b\":\"79597.00\",\"B\":\"4.100\",\"a\":\"79597.10\",\"A\":\"6.096\",\"T\":1788567727054,\"E\":1788567727054,\"st\":1}}"}
{"receive_ns":1788567727085386000,"stream":"btcusdt@depth@100ms","event_type":"depthUpdate","event_time_ms":1788567727101,"raw_json":"{\"stream\":\"btcusdt@depth@100ms\",\"data\":{\"e\":\"depthUpdate\",\"E\":1788567727101,\"T\":1788567727098,\"s\":\"BTCUSDT\",\"ps\":\"BTCUSDT\",\"U\":11478508130079,\"u\":11478508136018,\"pu\":11478508130003,\"b\":[[\"1000.00\",\"25.004\"],[\"29297.00\",\"1.015\"],[\"29397.00\",\"1.085\"],[\"71637.30\",\"0.043\"],[\"76413.10\",\"0.000\"],[\"78005.10\",\"10.834\"],[\"78624.30\",\"0.888\"],[\"78801.00\",\"12.674\"],[\"78928.30\",\"0.032\"],[\"79506.80\",\"1.700\"],[\"79525.30\",\"0.635\"],[\"79582.70\",\"0.194\"],[\"79597.00\",\"4.100\"]],\"a\":[[\"79597.10\",\"6.096\"],[\"79597.20\",\"0.089\"],[\"79597.70\",\"0.164\"],[\"79606.30\",\"0.000\"],[\"79606.60\",\"0.039\"],[\"79617.00\",\"0.007\"],[\"79692.70\",\"0.003\"],[\"80050.00\",\"5.215\"],[\"80306.70\",\"0.198\"],[\"80393.10\",\"108.129\"],[\"80448.80\",\"0.744\"],[\"80830.90\",\"9.515\"]],\"st\":1}}"}
{"receive_ns":1788567727182356000,"stream":"btcusdt@depth@100ms","event_type":"depthUpdate","event_time_ms":1788567727203,"raw_json":"{\"stream\":\"btcusdt@depth@100ms\",\"data\":{\"e\":\"depthUpdate\",\"E\":1788567727203,\"T\":1788567727202,\"s\":\"BTCUSDT\",\"ps\":\"BTCUSDT\",\"U\":11478508136270,\"u\":11478508144286,\"pu\":11478508136018,\"b\":[[\"1000.00\",\"25.004\"],[\"29297.00\",\"1.197\"],[\"29397.00\",\"0.903\"],[\"63678.00\",\"0.000\"],[\"71637.30\",\"0.043\"],[\"75617.10\",\"0.026\"],[\"75617.20\",\"0.006\"],[\"76413.10\",\"0.002\"],[\"78005.10\",\"10.831\"],[\"78641.80\",\"34.276\"],[\"78801.00\",\"12.674\"],[\"79199.00\",\"4.875\"],[\"79449.90\",\"0.196\"],[\"79450.40\",\"1.900\"],[\"79564.70\",\"0.728\"],[\"79567.00\",\"0.300\"],[\"79567.30\",\"0.127\"],[\"79567.50\",\"0.631\"],[\"79567.60\",\"0.000\"],[\"79568.20\",\"0.002\"],[\"79569.00\",\"0.001\"],[\"79570.10\",\"0.453\"],[\"79570.50\",\"0.002\"],[\"79571.50\",\"1.611\"],[\"79572.50\",\"0.256\"],[\"79573.30\",\"0.481\"],[\"79574.90\",\"0.020\"],[\"79576.40\",\"0.382\"],[\"79576.80\",\"0.002\"],[\"79587.10\",\"0.000\"],[\"79587.30\",\"0.035\"],[\"79588.50\",\"0.114\"],[\"79589.20\",\"0.076\"],[\"79591.20\",\"0.005\"],[\"79591.40\",\"0.007\"],[\"79591.60\",\"0.000\"],[\"79591.70\",\"0.003\"],[\"79591.80\",\"0.026\"],[\"79591.90\",\"0.027\"],[\"79592.00\",\"0.031\"],[\"79592.10\",\"0.207\"],[\"79592.20\",\"0.000\"],[\"79592.30\",\"0.026\"],[\"79592.40\",\"0.028\"],[\"79592.90\",\"0.002\"],[\"79593.10\",\"0.047\"],[\"79593.20\",\"0.000\"],[\"79593.30\",\"0.026\"],[\"79593.40\",\"0.027\"],[\"79593.70\",\"0.026\"],[\"79593.90\",\"0.000\"],[\"79594.00\",\"0.000\"],[\"79595.00\",\"0.002\"],[\"79595.10\",\"0.001\"],[\"79595.20\",\"0.000\"],[\"79595.40\",\"0.002\"]],\"a\":[[\"79605.40\",\"0.084\"],[\"79607.80\",\"0.079\"],[\"79608.10\",\"0.003\"],[\"79613.20\",\"0.002\"],[\"79613.30\",\"0.061\"],[\"79616.30\",\"1.013\"],[\"79617.10\",\"0.000\"],[\"79718.30\",\"0.000\"],[\"79718.80\",\"3.052\"],[\"79995.10\",\"4.365\"],[\"80299.30\",\"8.866\"],[\"80393.10\",\"108.129\"]],\"st\":1}}"}
{"receive_ns":1788567727230009000,"stream":"btcusdt@bookTicker","event_type":"bookTicker","event_time_ms":1788567727252,"raw_json":"{\"stream\":\"btcusdt@bookTicker\",\"data\":{\"e\":\"bookTicker\",\"u\":11478508146920,\"s\":\"BTCUSDT\",\"ps\":\"BTCUSDT\",\"b\":\"79597.00\",\"B\":\"4.050\",\"a\":\"79597.10\",\"A\":\"6.096\",\"T\":1788567727252,\"E\":1788567727252,\"st\":1}}"}
{"receive_ns":1788567727230312000,"stream":"btcusdt@bookTicker","event_type":"bookTicker","event_time_ms":1788567727255,"raw_json":"{\"stream\":\"btcusdt@bookTicker\",\"data\":{\"e\":\"bookTicker\",\"u\":11478508147165,\"s\":\"BTCUSDT\",\"ps\":\"BTCUSDT\",\"b\":\"79597.00\",\"B\":\"4.050\",\"a\":\"79597.10\",\"A\":\"6.176\",\"T\":1788567727255,\"E\":1788567727255,\"st\":1}}"}
{"receive_ns":1788567727230520000,"stream":"btcusdt@bookTicker","event_type":"bookTicker","event_time_ms":1788567727255,"raw_json":"{\"stream\":\"btcusdt@bookTicker\",\"data\":{\"e\":\"bookTicker\",\"u\":11478508147186,\"s\":\"BTCUSDT\",\"ps\":\"BTCUSDT\",\"b\":\"79597.00\",\"B\":\"4.099\",\"a\":\"79597.10\",\"A\":\"6.176\",\"T\":1788567727255,\"E\":1788567727255,\"st\":1}}"}
{"receive_ns":1788567727230726000,"stream":"btcusdt@bookTicker","event_type":"bookTicker","event_time_ms":1788567727255,"raw_json":"{\"stream\":\"btcusdt@bookTicker\",\"data\":{\"e\":\"bookTicker\",\"u\":11478508147193,\"s\":\"BTCUSDT\",\"ps\":\"BTCUSDT\",\"b\":\"79597.00\",\"B\":\"4.099\",\"a\":\"79597.10\",\"A\":\"6.256\",\"T\":1788567727255,\"E\":1788567727255,\"st\":1}}"}
{"receive_ns":1788567727230925000,"stream":"btcusdt@bookTicker","event_type":"bookTicker","event_time_ms":1788567727255,"raw_json":"{\"stream\":\"btcusdt@bookTicker\",\"data\":{\"e\":\"bookTicker\",\"u\":11478508147197,\"s\":\"BTCUSDT\",\"ps\":\"BTCUSDT\",\"b\":\"79597.00\",\"B\":\"4.099\",\"a\":\"79597.10\",\"A\":\"6.336\",\"T\":1788567727255,\"E\":1788567727255,\"st\":1}}"}
{"receive_ns":1788567727242494000,"stream":"btcusdt@bookTicker","event_type":"bookTicker","event_time_ms":1788567727256,"raw_json":"{\"stream\":\"btcusdt@bookTicker\",\"data\":{\"e\":\"bookTicker\",\"u\":11478508147250,\"s\":\"BTCUSDT\",\"ps\":\"BTCUSDT\",\"b\":\"79597.00\",\"B\":\"4.099\",\"a\":\"79597.10\",\"A\":\"6.334\",\"T\":1788567727256,\"E\":1788567727256,\"st\":1}}"}
{"receive_ns":1788567727288586000,"stream":"btcusdt@depth@100ms","event_type":"depthUpdate","event_time_ms":1788567727305,"raw_json":"{\"stream\":\"btcusdt@depth@100ms\",\"data\":{\"e\":\"depthUpdate\",\"E\":1788567727305,\"T\":1788567727304,\"s\":\"BTCUSDT\",\"ps\":\"BTCUSDT\",\"U\":11478508144381,\"u\":11478508149982,\"pu\":11478508144286,\"b\":[[\"29297.00\",\"1.372\"],[\"29397.00\",\"0.728\"],[\"63677.60\",\"0.000\"],[\"71637.30\",\"0.043\"],[\"76413.10\",\"0.000\"],[\"78389.70\",\"3.822\"],[\"78665.70\",\"4.430\"],[\"78801.00\",\"13.624\"],[\"78960.20\",\"7.497\"],[\"79199.00\",\"4.876\"],[\"79567.20\",\"0.127\"],[\"79567.30\",\"0.002\"],[\"79568.00\",\"0.005\"],[\"79597.00\",\"4.099\"]],\"a\":[[\"79597.10\",\"6.334\"],[\"79691.80\",\"0.124\"],[\"79692.80\",\"0.001\"],[\"79692.90\",\"0.003\"],[\"79701.40\",\"0.269\"],[\"79702.50\",\"0.167\"],[\"79704.90\",\"0.003\"],[\"79995.10\",\"4.366\"],[\"80393.10\",\"108.129\"]],\"st\":1}}"}
{"receive_ns":1788567727383666000,"stream":"btcusdt@bookTicker","event_type":"bookTicker","event_time_ms":1788567727396,"raw_json":"{\"stream\":\"btcusdt@bookTicker\",\"data\":{\"e\":\"bookTicker\",\"u\":11478508156470,\"s\":\"BTCUSDT\",\"ps\":\"BTCUSDT\",\"b\":\"79597.00\",\"B\":\"3.975\",\"a\":\"79597.10\",\"A\":\"6.334\",\"T\":1788567727396,\"E\":1788567727396,\"st\":1}}"}
{"receive_ns":1788567727400138000,"stream":"btcusdt@bookTicker","event_type":"bookTicker","event_time_ms":1788567727398,"raw_json":"{\"stream\":\"btcusdt@bookTicker\",\"data\":{\"e\":\"bookTicker\",\"u\":11478508156515,\"s\":\"BTCUSDT\",\"ps\":\"BTCUSDT\",\"b\":\"79597.00\",\"B\":\"3.975\",\"a\":\"79597.10\",\"A\":\"6.336\",\"T\":1788567727398,\"E\":1788567727398,\"st\":1}}"}
{"receive_ns":1788567727414471000,"stream":"btcusdt@bookTicker","event_type":"bookTicker","event_time_ms":1788567727399,"raw_json":"{\"stream\":\"btcusdt@bookTicker\",\"data\":{\"e\":\"bookTicker\",\"u\":11478508156582,\"s\":\"BTCUSDT\",\"ps\":\"BTCUSDT\",\"b\":\"79597.00\",\"B\":\"3.931\",\"a\":\"79597.10\",\"A\":\"6.336\",\"T\":1788567727399,\"E\":1788567727399,\"st\":1}}"}
{"receive_ns":1788567727419938000,"stream":"btcusdt@bookTicker","event_type":"bookTicker","event_time_ms":1788567727399,"raw_json":"{\"stream\":\"btcusdt@bookTicker\",\"data\":{\"e\":\"bookTicker\",\"u\":11478508156612,\"s\":\"BTCUSDT\",\"ps\":\"BTCUSDT\",\"b\":\"79597.00\",\"B\":\"4.060\",\"a\":\"79597.10\",\"A\":\"6.336\",\"T\":1788567727399,\"E\":1788567727399,\"st\":1}}"}
{"receive_ns":1788567727431701000,"stream":"btcusdt@bookTicker","event_type":"bookTicker","event_time_ms":1788567727400,"raw_json":"{\"stream\":\"btcusdt@bookTicker\",\"data\":{\"e\":\"bookTicker\",\"u\":11478508156679,\"s\":\"BTCUSDT\",\"ps\":\"BTCUSDT\",\"b\":\"79597.00\",\"B\":\"4.059\",\"a\":\"79597.10\",\"A\":\"6.336\",\"T\":1788567727400,\"E\":1788567727400,\"st\":1}}"}
{"receive_ns":1788567727445478000,"stream":"btcusdt@bookTicker","event_type":"bookTicker","event_time_ms":1788567727402,"raw_json":"{\"stream\":\"btcusdt@bookTicker\",\"data\":{\"e\":\"bookTicker\",\"u\":11478508156867,\"s\":\"BTCUSDT\",\"ps\":\"BTCUSDT\",\"b\":\"79597.00\",\"B\":\"4.102\",\"a\":\"79597.10\",\"A\":\"6.336\",\"T\":1788567727402,\"E\":1788567727402,\"st\":1}}"}
{"receive_ns":1788567727457748000,"stream":"btcusdt@bookTicker","event_type":"bookTicker","event_time_ms":1788567727403,"raw_json":"{\"stream\":\"btcusdt@bookTicker\",\"data\":{\"e\":\"bookTicker\",\"u\":11478508156992,\"s\":\"BTCUSDT\",\"ps\":\"BTCUSDT\",\"b\":\"79597.00\",\"B\":\"4.103\",\"a\":\"79597.10\",\"A\":\"6.336\",\"T\":1788567727403,\"E\":1788567727403,\"st\":1}}"}
{"receive_ns":1788567727458203000,"stream":"btcusdt@depth@100ms","event_type":"depthUpdate","event_time_ms":1788567727407,"raw_json":"{\"stream\":\"btcusdt@depth@100ms\",\"data\":{\"e\":\"depthUpdate\",\"E\":1788567727407,\"T\":1788567727406,\"s\":\"BTCUSDT\",\"ps\":\"BTCUSDT\",\"U\":11478508150131,\"u\":11478508157240,\"pu\":11478508149982,\"b\":[[\"1000.00\",\"25.004\"],[\"29297.00\",\"1.554\"],[\"29397.00\",\"0.546\"],[\"63678.00\",\"0.000\"],[\"71637.30\",\"0.043\"],[\"78531.50\",\"0.000\"],[\"78602.00\",\"17.370\"],[\"78721.40\",\"9.577\"],[\"78801.00\",\"13.626\"],[\"78928.30\",\"0.012\"],[\"79541.20\",\"0.831\"],[\"79557.10\",\"0.692\"],[\"79567.20\",\"0.127\"],[\"79590.40\",\"0.077\"],[\"79591.80\",\"0.000\"],[\"79591.90\",\"0.001\"],[\"79592.00\",\"0.005\"],[\"79592.10\",\"0.181\"],[\"79594.00\",\"0.026\"],[\"79594.10\",\"0.028\"],[\"79594.30\",\"0.084\"],[\"79595.10\",\"0.027\"],[\"79597.00\",\"4.103\"]],\"a\":[[\"79597.10\",\"6.336\"],[\"79605.40\",\"0.084\"],[\"79608.10\",\"0.003\"],[\"79610.70\",\"0.795\"],[\"79616.30\",\"0.641\"],[\"79616.90\",\"0.535\"],[\"79621.00\",\"0.109\"],[\"79626.60\",\"0.834\"],[\"79645.00\",\"0.002\"],[\"79645.10\",\"0.774\"],[\"79806.70\",\"2.806\"],[\"80393.10\",\"108.129\"],[\"80713.10\",\"0.000\"],[\"81073.60\",\"1.000\"],[\"81572.60\",\"1.652\"]],\"st\":1}}"}
{"receive_ns":1788567727476543000,"stream":"btcusdt@bookTicker","event_type":"bookTicker","event_time_ms":1788567727496,"raw_json":"{\"stream\":\"btcusdt@bookTicker\",\"data\":{\"e\":\"bookTicker\",\"u\":11478508161045,\"s\":\"BTCUSDT\",\"ps\":\"BTCUSDT\",\"b\":\"79597.00\",\"B\":\"4.051\",\"a\":\"79597.10\",\"A\":\"6.336\",\"T\":1788567727495,\"E\":1788567727496,\"st\":1}}"}
{"receive_ns":1788567727482911000,"stream":"btcusdt@bookTicker","event_type":"bookTicker","event_time_ms":1788567727499,"raw_json":"{\"stream\":\"btcusdt@bookTicker\",\"data\":{\"e\":\"bookTicker\",\"u\":11478508161198,\"s\":\"BTCUSDT\",\"ps\":\"BTCUSDT\",\"b\":\"79597.00\",\"B\":\"4.094\",\"a\":\"79597.10\",\"A\":\"6.336\",\"T\":1788567727498,\"E\":1788567727499,\"st\":1}}"}
{"receive_ns":1788567727489676000,"stream":"btcusdt@depth@100ms","event_type":"depthUpdate","event_time_ms":1788567727509,"raw_json":"{\"stream\":\"btcusdt@depth@100ms\",\"data\":{\"e\":\"depthUpdate\",\"E\":1788567727509,\"T\":1788567727508,\"s\":\"BTCUSDT\",\"ps\":\"BTCUSDT\",\"U\":11478508157302,\"u\":11478508161684,\"pu\":11478508157240,\"b\":[[\"1000.00\",\"25.004\"],[\"29297.00\",\"1.729\"],[\"29397.00\",\"0.371\"],[\"71637.30\",\"0.043\"],[\"76413.10\",\"0.002\"],[\"78005.10\",\"10.834\"],[\"78468.70\",\"8.170\"],[\"78708.10\",\"8.885\"],[\"78801.00\",\"13.624\"],[\"79475.40\",\"0.528\"],[\"79587.30\",\"0.036\"],[\"79591.20\",\"0.006\"],[\"79595.10\",\"0.028\"],[\"79597.00\",\"4.094\"]],\"a\":[[\"79645.40\",\"0.147\"],[\"79646.10\",\"2.933\"],[\"79647.00\",\"0.061\"],[\"79719.60\",\"0.485\"],[\"79731.80\",\"0.003\"],[\"79810.70\",\"4.870\"],[\"79816.20\",\"0.000\"],[\"79816.80\",\"0.041\"],[\"80165.10\",\"0.186\"],[\"80329.70\",\"1.848\"],[\"80393.10\",\"108.129\"],[\"87556.90\",\"0.000\"]],\"st\":1}}"}
{"receive_ns":1788567727511963000,"stream":"btcusdt@bookTicker","event_type":"bookTicker","event_time_ms":1788567727534,"raw_json":"{\"stream\":\"btcusdt@bookTicker\",\"data\":{\"e\":\"bookTicker\",\"u\":11478508162826,\"s\":\"BTCUSDT\",\"ps\":\"BTCUSDT\",\"b\":\"79597.00\",\"B\":\"4.094\",\"a\":\"79597.10\",\"A\":\"6.317\",\"T\":1788567727534,\"E\":1788567727534,\"st\":1}}"}
{"receive_ns":1788567727512196000,"stream":"btcusdt@trade","event_type":"trade","event_time_ms":1788567727534,"raw_json":"{\"stream\":\"btcusdt@trade\",\"data\":{\"e\":\"trade\",\"E\":1788567727534,\"T\":1788567727534,\"s\":\"BTCUSDT\",\"t\":8054122617,\"p\":\"79597.10\",\"q\":\"0.019\",\"X\":\"MARKET\",\"m\":false,\"st\":1}}"}
{"receive_ns":1788567727517850000,"stream":"btcusdt@bookTicker","event_type":"bookTicker","event_time_ms":1788567727536,"raw_json":"{\"stream\":\"btcusdt@bookTicker\",\"data\":{\"e\":\"bookTicker\",\"u\":11478508163014,\"s\":\"BTCUSDT\",\"ps\":\"BTCUSDT\",\"b\":\"79597.00\",\"B\":\"4.093\",\"a\":\"79597.10\",\"A\":\"6.317\",\"T\":1788567727536,\"E\":1788567727536,\"st\":1}}"}
{"receive_ns":1788567727573442000,"stream":"btcusdt@bookTicker","event_type":"bookTicker","event_time_ms":1788567727581,"raw_json":"{\"stream\":\"btcusdt@bookTicker\",\"data\":{\"e\":\"bookTicker\",\"u\":11478508165738,\"s\":\"BTCUSDT\",\"ps\":\"BTCUSDT\",\"b\":\"79597.00\",\"B\":\"4.094\",\"a\":\"79597.10\",\"A\":\"6.317\",\"T\":1788567727581,\"E\":1788567727581,\"st\":1}}"}
{"receive_ns":1788567727586393000,"stream":"btcusdt@bookTicker","event_type":"bookTicker","event_time_ms":1788567727589,"raw_json":"{\"stream\":\"btcusdt@bookTicker\",\"data\":{\"e\":\"bookTicker\",\"u\":11478508166245,\"s\":\"BTCUSDT\",\"ps\":\"BTCUSDT\",\"b\":\"79597.00\",\"B\":\"4.096\",\"a\":\"79597.10\",\"A\":\"6.317\",\"T\":1788567727589,\"E\":1788567727589,\"st\":1}}"}
{"receive_ns":1788567727598598000,"stream":"btcusdt@depth@100ms","event_type":"depthUpdate","event_time_ms":1788567727611,"raw_json":"{\"stream\":\"btcusdt@depth@100ms\",\"data\":{\"e\":\"depthUpdate\",\"E\":1788567727611,\"T\":1788567727610,\"s\":\"BTCUSDT\",\"ps\":\"BTCUSDT\",\"U\":11478508161761,\"u\":11478508167249,\"pu\":11478508161684,\"b\":[[\"29197.00\",\"0.056\"],[\"29297.00\",\"1.799\"],[\"29397.00\",\"0.245\"],[\"63678.00\",\"0.000\"],[\"71637.30\",\"0.043\"],[\"76413.10\",\"0.000\"],[\"78202.70\",\"0.640\"],[\"78801.00\",\"13.624\"],[\"78866.60\",\"0.010\"],[\"79199.00\",\"4.876\"],[\"79569.00\",\"0.453\"],[\"79570.10\",\"0.001\"],[\"79575.90\",\"0.035\"],[\"79576.40\",\"0.009\"],[\"79577.10\",\"0.455\"],[\"79579.90\",\"0.048\"],[\"79591.50\",\"0.076\"],[\"79592.30\",\"0.000\"],[\"79592.40\",\"0.002\"],[\"79593.10\",\"0.021\"],[\"79595.60\",\"0.038\"],[\"79596.00\",\"0.108\"],[\"79596.20\",\"0.026\"],[\"79597.00\",\"4.096\"]],\"a\":[[\"79597.10\",\"6.317\"],[\"79605.40\",\"0.080\"],[\"79608.00\",\"0.012\"],[\"79615.80\",\"0.000\"],[\"79616.20\",\"0.629\"],[\"79616.30\",\"0.013\"],[\"79616.90\",\"0.163\"],[\"79617.10\",\"0.372\"],[\"79623.90\",\"0.010\"],[\"79645.20\",\"0.126\"],[\"79645.40\",\"0.022\"],[\"79806.70\",\"2.806\"],[\"80393.10\",\"108.129\"],[\"81189.00\",\"10.537\"]],\"st\":1}}"}
{"receive_ns":1788567727699090000,"stream":"btcusdt@depth@100ms","event_type":"depthUpdate","event_time_ms":1788567727713,"raw_json":"{\"stream\":\"btcusdt@depth@100ms\",\"data\":{\"e\":\"depthUpdate\",\"E\":1788567727713,\"T\":1788567727711,\"s\":\"BTCUSDT\",\"ps\":\"BTCUSDT\",\"U\":11478508167310,\"u\":11478508171895,\"pu\":11478508167249,\"b\":[[\"1000.00\",\"25.004\"],[\"29197.00\",\"0.112\"],[\"29297.00\",\"1.862\"],[\"29397.00\",\"0.126\"],[\"63678.00\",\"0.000\"],[\"71637.30\",\"0.043\"],[\"71673.00\",\"0.000\"],[\"76413.10\",\"0.002\"],[\"78614.10\",\"0.000\"],[\"78618.70\",\"0.002\"],[\"78801.00\",\"13.624\"],[\"79000.00\",\"44.122\"],[\"79569.00\",\"0.001\"],[\"79570.50\",\"0.454\"],[\"79574.90\",\"0.000\"],[\"79587.10\",\"0.020\"],[\"79591.40\",\"0.003\"],[\"79592.00\",\"0.009\"],[\"79596.20\",\"0.000\"]],\"a\":[[\"79616.20\",\"0.001\"],[\"79616.30\",\"0.641\"],[\"79620.00\",\"0.146\"],[\"79620.20\",\"0.455\"],[\"79644.40\",\"0.866\"],[\"79645.00\",\"0.127\"],[\"79645.20\",\"0.001\"],[\"79806.70\",\"4.846\"],[\"80313.50\",\"3.738\"],[\"80329.70\",\"0.616\"],[\"80393.10\",\"108.129\"]],\"st\":1}}"}
{"receive_ns":1788567727788779000,"stream":"btcusdt@bookTicker","event_type":"bookTicker","event_time_ms":1788567727788,"raw_json":"{\"stream\":\"btcusdt@bookTicker\",\"data\":{\"e\":\"bookTicker\",\"u\":11478508176534,\"s\":\"BTCUSDT\",\"ps\":\"BTCUSDT\",\"b\":\"79597.00\",\"B\":\"4.096\",\"a\":\"79597.10\",\"A\":\"6.316\",\"T\":1788567727788,\"E\":1788567727788,\"st\":1}}"}
{"receive_ns":1788567727797535000,"stream":"btcusdt@trade","event_type":"trade","event_time_ms":1788567727788,"raw_json":"{\"stream\":\"btcusdt@trade\",\"data\":{\"e\":\"trade\",\"E\":1788567727788,\"T\":1788567727788,\"s\":\"BTCUSDT\",\"t\":8054122618,\"p\":\"79597.10\",\"q\":\"0.001\",\"X\":\"MARKET\",\"m\":false,\"st\":1}}"}
{"receive_ns":1788567727804748000,"stream":"btcusdt@depth@100ms","event_type":"depthUpdate","event_time_ms":1788567727815,"raw_json":"{\"stream\":\"btcusdt@depth@100ms\",\"data\":{\"e\":\"depthUpdate\",\"E\":1788567727815,\"T\":1788567727813,\"s\":\"BTCUSDT\",\"ps\":\"BTCUSDT\",\"U\":11478508171968,\"u\":11478508178078,\"pu\":11478508171895,\"b\":[[\"1000.00\",\"25.004\"],[\"29197.00\",\"0.182\"],[\"29297.00\",\"1.904\"],[\"29397.00\",\"0.014\"],[\"71637.30\",\"0.043\"],[\"76413.10\",\"0.000\"],[\"78346.50\",\"0.000\"],[\"78801.00\",\"13.624\"],[\"79525.30\",\"0.633\"],[\"79541.20\",\"0.831\"],[\"79596.00\",\"0.082\"]],\"a\":[[\"79597.10\",\"6.316\"],[\"79624.60\",\"0.082\"],[\"79645.00\",\"0.002\"],[\"79668.80\",\"0.034\"],[\"79692.70\",\"0.001\"],[\"79806.70\",\"2.709\"],[\"80306.70\",\"0.011\"],[\"80329.70\",\"0.000\"],[\"80393.10\",\"108.129\"],[\"80469.40\",\"1.242\"],[\"80577.80\",\"2.472\"]],\"st\":1}}"}
{"receive_ns":1788567727826279000,"stream":"btcusdt@bookTicker","event_type":"bookTicker","event_time_ms":1788567727843,"raw_json":"{\"stream\":\"btcusdt@bookTicker\",\"data\":{\"e\":\"bookTicker\",\"u\":11478508181065,\"s\":\"BTCUSDT\",\"ps\":\"BTCUSDT\",\"b\":\"79597.00\",\"B\":\"4.096\",\"a\":\"79597.10\",\"A\":\"6.315\",\"T\":1788567727843,\"E\":1788567727843,\"st\":1}}"}
{"receive_ns":1788567727900277000,"stream":"btcusdt@depth@100ms","event_type":"depthUpdate","event_time_ms":1788567727917,"raw_json":"{\"stream\":\"btcusdt@depth@100ms\",\"data\":{\"e\":\"depthUpdate\",\"E\":1788567727917,\"T\":1788567727915,\"s\":\"BTCUSDT\",\"ps\":\"BTCUSDT\",\"U\":11478508178167,\"u\":11478508187587,\"pu\":11478508178078,\"b\":[[\"29197.00\",\"0.343\"],[\"29297.00\",\"1.757\"],[\"29397.00\",\"0.000\"],[\"71637.30\",\"0.043\"],[\"78389.70\",\"4.459\"],[\"78392.80\",\"0.223\"],[\"78801.00\",\"13.624\"],[\"79199.00\",\"4.866\"],[\"79505.60\",\"0.000\"],[\"79506.80\",\"1.190\"],[\"79591.50\",\"0.000\"],[\"79593.90\",\"0.026\"],[\"79594.60\",\"0.027\"],[\"79595.10\",\"0.002\"],[\"79595.60\",\"0.012\"]],\"a\":[[\"79597.10\",\"6.315\"],[\"79645.20\",\"0.001\"],[\"79688.10\",\"0.024\"],[\"80289.90\",\"0.002\"],[\"80393.10\",\"108.129\"],[\"80963.60\",\"5.556\"]],\"st\":1}}"}
{"receive_ns":1788567727905834000,"stream":"btcusdt@bookTicker","event_type":"bookTicker","event_time_ms":1788567727921,"raw_json":"{\"stream\":\"btcusdt@bookTicker\",\"data\":{\"e\":\"bookTicker\",\"u\":11478508188059,\"s\":\"BTCUSDT\",\"ps\":\"BTCUSDT\",\"b\":\"79597.00\",\"B\":\"4.113\",\"a\":\"79597.10\",\"A\":\"6.315\",\"T\":1788567727921,\"E\":1788567727921,\"st\":1}}"}
{"receive_ns":1788567728003971000,"stream":"btcusdt@depth@100ms","event_type":"depthUpdate","event_time_ms":1788567728019,"raw_json":"{\"stream\":\"btcusdt@depth@100ms\",\"data\":{\"e\":\"depthUpdate\",\"E\":1788567728019,\"T\":1788567728018,\"s\":\"BTCUSDT\",\"ps\":\"BTCUSDT\",\"U\":11478508187779,\"u\":11478508194988,\"pu\":11478508187587,\"b\":[[\"1000.00\",\"25.004\"],[\"29197.00\",\"0.525\"],[\"29297.00\",\"1.575\"],[\"63678.00\",\"0.000\"],[\"71637.30\",\"0.043\"],[\"76413.10\",\"0.002\"],[\"78132.60\",\"0.009\"],[\"78363.20\",\"10.195\"],[\"78641.80\",\"33.769\"],[\"78801.00\",\"13.624\"],[\"79505.60\",\"4.335\"],[\"79595.30\",\"0.027\"],[\"79597.00\",\"4.113\"]],\"a\":[[\"79688.10\",\"3.379\"],[\"79806.70\",\"2.806\"],[\"79818.80\",\"0.001\"],[\"79818.90\",\"6.945\"],[\"80393.10\",\"108.129\"],[\"80675.80\",\"0.494\"],[\"81189.00\",\"10.534\"]],\"st\":1}}"}
{"receive_ns":1788567728080310000,"stream":"btcusdt@bookTicker","event_type":"bookTicker","event_time_ms":1788567728089,"raw_json":"{\"stream\":\"btcusdt@bookTicker\",\"data\":{\"e\":\"bookTicker\",\"u\":11478508198689,\"s\":\"BTCUSDT\",\"ps\":\"BTCUSDT\",\"b\":\"79597.00\",\"B\":\"4.113\",\"a\":\"79597.10\",\"A\":\"6.333\",\"T\":1788567728089,\"E\":1788567728089,\"st\":1}}"}
{"receive_ns":1788567728109673000,"stream":"btcusdt@depth@100ms","event_type":"depthUpdate","event_time_ms":1788567728121,"raw_json":"{\"stream\":\"btcusdt@depth@100ms\",\"data\":{\"e\":\"depthUpdate\",\"E\":1788567728121,\"T\":1788567728118,\"s\":\"BTCUSDT\",\"ps\":\"BTCUSDT\",\"U\":11478508195004,\"u\":11478508200107,\"pu\":11478508194988,\"b\":[[\"1000.00\",\"25.004\"],[\"29197.00\",\"0.700\"],[\"29297.00\",\"1.400\"],[\"63678.00\",\"0.000\"],[\"71637.30\",\"0.043\"],[\"76413.10\",\"0.000\"],[\"78562.20\",\"15.924\"],[\"78801.00\",\"13.624\"],[\"79582.70\",\"0.194\"],[\"79584.20\",\"0.037\"]],\"a\":[[\"79597.10\",\"6.333\"],[\"79597.20\",\"0.090\"],[\"79657.60\",\"0.011\"],[\"79692.80\",\"0.000\"],[\"79692.90\",\"0.001\"],[\"79696.10\",\"1.677\"],[\"79696.20\",\"0.001\"],[\"79704.90\",\"0.000\"],[\"79705.10\",\"0.030\"],[\"79806.70\",\"4.846\"],[\"80393.10\",\"108.129\"]],\"st\":1}}"}
{"receive_ns":1788567728208103000,"stream":"btcusdt@depth@100ms","event_type":"depthUpdate","event_time_ms":1788567728223,"raw_json":"{\"stream\":\"btcusdt@depth@100ms\",\"data\":{\"e\":\"depthUpdate\",\"E\":1788567728223,\"T\":1788567728222,\"s\":\"BTCUSDT\",\"ps\":\"BTCUSDT\",\"U\":11478508200209,\"u\":11478508206138,\"pu\":11478508200107,\"b\":[[\"29197.00\",\"0.882\"],[\"29297.00\",\"1.218\"],[\"71637.30\",\"0.043\"],[\"75617.10\",\"0.024\"],[\"75617.20\",\"0.008\"],[\"76413.10\",\"0.002\"],[\"78389.70\",\"5.096\"],[\"78801.00\",\"13.624\"],[\"79199.00\",\"4.876\"],[\"79573.30\",\"0.481\"],[\"79586.10\",\"0.014\"],[\"79595.40\",\"0.001\"]],\"a\":[[\"79613.20\",\"0.002\"],[\"79645.80\",\"0.000\"],[\"79657.60\",\"0.029\"],[\"79691.80\",\"0.123\"],[\"79691.90\",\"0.061\"],[\"79693.00\",\"0.001\"],[\"79693.10\",\"0.020\"],[\"79701.40\",\"0.266\"],[\"79701.50\",\"0.345\"],[\"79702.50\",\"0.165\"],[\"79702.60\",\"0.012\"],[\"79704.60\",\"0.040\"],[\"80299.30\",\"7.995\"],[\"80393.10\",\"108.129\"],[\"80486.00\",\"9.409\"],[\"80623.90\",\"2.480\"],[\"80632.00\",\"0.867\"]],\"st\":1}}"}
{"receive_ns":1788567728315147000,"stream":"btcusdt@depth@100ms","event_type":"depthUpdate","event_time_ms":1788567728325,"raw_json":"{\"stream\":\"btcusdt@depth@100ms\",\"data\":{\"e\":\"depthUpdate\",\"E\":1788567728325,\"T\":1788567728321,\"s\":\"BTCUSDT\",\"ps\":\"BTCUSDT\",\"U\":11478508206253,\"u\":11478508212041,\"pu\":11478508206138,\"b\":[[\"1000.00\",\"25.004\"],[\"29197.00\",\"1.057\"],[\"29297.00\",\"1.043\"],[\"63677.60\",\"0.000\"],[\"71637.30\",\"0.043\"],[\"75617.10\",\"0.028\"],[\"78389.70\",\"5.733\"],[\"78801.00\",\"13.624\"],[\"78960.20\",\"7.245\"],[\"79199.00\",\"4.875\"],[\"79475.40\",\"0.529\"],[\"79586.10\",\"0.010\"]],\"a\":[[\"79621.00\",\"0.056\"],[\"79624.70\",\"0.127\"],[\"79645.70\",\"0.002\"],[\"79646.30\",\"0.000\"],[\"79646.50\",\"0.125\"],[\"79692.00\",\"1.358\"],[\"79702.70\",\"0.054\"],[\"79719.50\",\"0.514\"],[\"79719.60\",\"0.001\"],[\"79995.10\",\"4.365\"],[\"80393.10\",\"109.371\"],[\"80528.40\",\"3.464\"]],\"st\":1}}"}
{"receive_ns":1788567728412325000,"stream":"btcusdt@depth@100ms","event_type":"depthUpdate","event_time_ms":1788567728427,"raw_json":"{\"stream\":\"btcusdt@depth@100ms\",\"data\":{\"e\":\"depthUpdate\",\"E\":1788567728427,\"T\":1788567728426,\"s\":\"BTCUSDT\",\"ps\":\"BTCUSDT\",\"U\":11478508212199,\"u\":11478508218136,\"pu\":11478508212041,\"b\":[[\"1000.00\",\"25.004\"],[\"29197.00\",\"1.239\"],[\"29297.00\",\"0.861\"],[\"63678.00\",\"0.000\"],[\"71637.30\",\"0.043\"],[\"75617.10\",\"0.030\"],[\"76413.10\",\"0.000\"],[\"78801.00\",\"13.624\"],[\"79567.20\",\"0.002\"],[\"79567.70\",\"0.292\"],[\"79586.10\",\"0.008\"]],\"a\":[[\"80393.10\",\"109.371\"],[\"80486.00\",\"10.030\"],[\"80645.10\",\"0.620\"]],\"st\":1}}"}
{"receive_ns":1788567728487996000,"stream":"btcusdt@bookTicker","event_type":"bookTicker","event_time_ms":1788567728502,"raw_json":"{\"stream\":\"btcusdt@bookTicker\",\"data\":{\"e\":\"bookTicker\",\"u\":11478508222583,\"s\":\"BTCUSDT\",\"ps\":\"BTCUSDT\",\"b\":\"79597.00\",\"B\":\"4.070\",\"a\":\"79597.10\",\"A\":\"6.333\",\"T\":1788567728501,\"E\":1788567728502,\"st\":1}}"}
{"receive_ns":1788567728500398000,"stream":"btcusdt@bookTicker","event_type":"bookTicker","event_time_ms":1788567728505,"raw_json":"{\"stream\":\"btcusdt@bookTicker\",\"data\":{\"e\":\"bookTicker\",\"u\":11478508222867,\"s\":\"BTCUSDT\",\"ps\":\"BTCUSDT\",\"b\":\"79597.00\",\"B\":\"4.110\",\"a\":\"79597.10\",\"A\":\"6.333\",\"T\":1788567728505,\"E\":1788567728505,\"st\":1}}"}
{"receive_ns":1788567728511498000,"stream":"btcusdt@depth@100ms","event_type":"depthUpdate","event_time_ms":1788567728529,"raw_json":"{\"stream\":\"btcusdt@depth@100ms\",\"data\":{\"e\":\"depthUpdate\",\"E\":1788567728529,\"T\":1788567728526,\"s\":\"BTCUSDT\",\"ps\":\"BTCUSDT\",\"U\":11478508218471,\"u\":11478508223794,\"pu\":11478508218136,\"b\":[[\"29197.00\",\"1.414\"],[\"29297.00\",\"0.686\"],[\"71637.30\",\"0.043\"],[\"76413.10\",\"0.002\"],[\"78097.20\",\"0.000\"],[\"78108.50\",\"3.767\"],[\"78801.00\",\"13.624\"],[\"79199.00\",\"4.866\"],[\"79510.00\",\"0.155\"],[\"79525.30\",\"0.635\"],[\"79537.80\",\"0.000\"],[\"79557.70\",\"0.546\"],[\"79566.70\",\"0.000\"],[\"79566.90\",\"0.001\"],[\"79567.70\",\"0.167\"],[\"79570.40\",\"0.001\"],[\"79576.30\",\"3.115\"],[\"79576.40\",\"0.003\"],[\"79595.40\",\"0.002\"],[\"79595.70\",\"0.000\"],[\"79597.00\",\"4.110\"]],\"a\":[[\"79621.00\",\"0.025\"],[\"79634.20\",\"0.003\"],[\"79641.30\",\"0.281\"],[\"79661.30\",\"0.010\"],[\"79689.10\",\"0.000\"],[\"79692.70\",\"0.003\"],[\"79818.90\",\"6.930\"],[\"79995.10\",\"4.366\"],[\"80195.50\",\"0.000\"],[\"80393.10\",\"109.371\"],[\"80631.90\",\"11.695\"]],\"st\":1}}"}
{"receive_ns":1788567728620701000,"stream":"btcusdt@depth@100ms","event_type":"depthUpdate","event_time_ms":1788567728631,"raw_json":"{\"stream\":\"btcusdt@depth@100ms\",\"data\":{\"e\":\"depthUpdate\",\"E\":1788567728631,\"T\":1788567728629,\"s\":\"BTCUSDT\",\"ps\":\"BTCUSDT\",\"U\":11478508223917,\"u\":11478508230668,\"pu\":11478508223794,\"b\":[[\"1000.00\",\"25.004\"],[\"29197.00\",\"1.596\"],[\"29297.00\",\"0.504\"],[\"63678.00\",\"0.000\"],[\"71637.30\",\"0.043\"],[\"76413.10\",\"0.000\"],[\"78588.70\",\"6.991\"],[\"78801.00\",\"13.624\"],[\"79470.20\",\"0.003\"],[\"79495.10\",\"0.046\"],[\"79507.80\",\"0.012\"],[\"79511.00\",\"0.013\"],[\"79511.80\",\"1.101\"],[\"79567.20\",\"0.127\"],[\"79567.60\",\"0.000\"],[\"79568.10\",\"2.686\"]],\"a\":[[\"79634.30\",\"0.002\"],[\"79729.00\",\"0.466\"],[\"80393.10\",\"109.371\"],[\"80519.30\",\"0.128\"],[\"80795.10\",\"0.004\"]],\"st\":1}}"}
{"receive_ns":1788567728709743000,"stream":"btcusdt@depth@100ms","event_type":"depthUpdate","event_time_ms":1788567728733,"raw_json":"{\"stream\":\"btcusdt@depth@100ms\",\"data\":{\"e\":\"depthUpdate\",\"E\":1788567728733,\"T\":1788567728730,\"s\":\"BTCUSDT\",\"ps\":\"BTCUSDT\",\"U\":11478508230799,\"u\":11478508237450,\"pu\":11478508230668,\"b\":[[\"1000.00\",\"25.004\"],[\"29097.00\",\"0.007\"],[\"29197.00\",\"1.757\"],[\"29297.00\",\"0.336\"],[\"71637.30\",\"0.043\"],[\"76413.10\",\"0.002\"],[\"78595.00\",\"0.001\"],[\"78601.90\",\"0.006\"],[\"78721.40\",\"9.767\"],[\"78801.00\",\"13.624\"],[\"78960.20\",\"7.497\"],[\"79471.80\",\"1.317\"],[\"79506.80\",\"0.019\"],[\"79507.30\",\"6.200\"],[\"79507.40\",\"2.752\"],[\"79507.80\",\"0.045\"],[\"79535.20\",\"4.314\"],[\"79539.60\",\"0.000\"],[\"79555.10\",\"0.699\"],[\"79570.10\",\"0.453\"],[\"79570.50\",\"0.002\"],[\"79576.10\",\"0.009\"],[\"79576.30\",\"3.109\"],[\"79576.70\",\"2.258\"],[\"79577.10\",\"0.082\"],[\"79583.90\",\"0.216\"],[\"79584.00\",\"0.022\"],[\"79584.10\",\"0.001\"],[\"79584.60\",\"0.602\"],[\"79584.70\",\"2.557\"],[\"79584.80\",\"1.653\"],[\"79584.90\",\"0.000\"],[\"79586.10\",\"0.006\"],[\"79587.90\",\"1.137\"],[\"79591.80\",\"0.004\"],[\"79592.00\",\"0.005\"],[\"79592.10\",\"0.181\"]],\"a\":[[\"79599.90\",\"0.002\"],[\"79602.70\",\"0.256\"],[\"79605.40\",\"0.084\"],[\"79608.00\",\"0.008\"],[\"79644.20\",\"0.676\"],[\"79664.10\",\"3.501\"],[\"79692.00\",\"7.358\"],[\"79728.00\",\"1.007\"],[\"79804.90\",\"1.081\"],[\"79818.90\",\"6.926\"],[\"80235.00\",\"0.568\"],[\"80299.30\",\"7.124\"],[\"80393.10\",\"109.371\"],[\"80549.00\",\"0.620\"],[\"80645.20\",\"10.523\"]],\"st\":1}}"}
{"receive_ns":1788567728819602000,"stream":"btcusdt@depth@100ms","event_type":"depthUpdate","event_time_ms":1788567728835,"raw_json":"{\"stream\":\"btcusdt@depth@100ms\",\"data\":{\"e\":\"depthUpdate\",\"E\":1788567728835,\"T\":1788567728834,\"s\":\"BTCUSDT\",\"ps\":\"BTCUSDT\",\"U\":11478508237663,\"u\":11478508242870,\"pu\":11478508237450,\"b\":[[\"29097.00\",\"0.070\"],[\"29197.00\",\"1.813\"],[\"29297.00\",\"0.217\"],[\"71637.30\",\"0.043\"],[\"71673.00\",\"0.000\"],[\"78000.00\",\"84.879\"],[\"78385.60\",\"3.880\"],[\"78801.00\",\"13.624\"],[\"79199.00\",\"4.866\"],[\"79576.40\",\"0.001\"],[\"79583.80\",\"0.284\"],[\"79584.00\",\"0.016\"],[\"79584.90\",\"0.006\"]],\"a\":[[\"79621.00\",\"0.003\"],[\"79624.70\",\"0.121\"],[\"80393.10\",\"109.371\"]],\"st\":1}}"}
{"receive_ns":1788567728868398000,"stream":"btcusdt@bookTicker","event_type":"bookTicker","event_time_ms":1788567728883,"raw_json":"{\"stream\":\"btcusdt@bookTicker\",\"data\":{\"e\":\"bookTicker\",\"u\":11478508245865,\"s\":\"BTCUSDT\",\"ps\":\"BTCUSDT\",\"b\":\"79597.00\",\"B\":\"4.110\",\"a\":\"79597.10\",\"A\":\"6.332\",\"T\":1788567728882,\"E\":1788567728883,\"st\":1}}"}
{"receive_ns":1788567728879564000,"stream":"btcusdt@bookTicker","event_type":"bookTicker","event_time_ms":1788567728891,"raw_json":"{\"stream\":\"btcusdt@bookTicker\",\"data\":{\"e\":\"bookTicker\",\"u\":11478508246296,\"s\":\"BTCUSDT\",\"ps\":\"BTCUSDT\",\"b\":\"79597.00\",\"B\":\"4.110\",\"a\":\"79597.10\",\"A\":\"6.331\",\"T\":1788567728891,\"E\":1788567728891,\"st\":1}}"}
{"receive_ns":1788567728898598000,"stream":"btcusdt@trade","event_type":"trade","event_time_ms":1788567728891,"raw_json":"{\"stream\":\"btcusdt@trade\",\"data\":{\"e\":\"trade\",\"E\":1788567728891,\"T\":1788567728891,\"s\":\"BTCUSDT\",\"t\":8054122619,\"p\":\"79597.10\",\"q\":\"0.001\",\"X\":\"MARKET\",\"m\":false,\"st\":1}}"}
{"receive_ns":1788567728909934000,"stream":"btcusdt@bookTicker","event_type":"bookTicker","event_time_ms":1788567728910,"raw_json":"{\"stream\":\"btcusdt@bookTicker\",\"data\":{\"e\":\"bookTicker\",\"u\":11478508247377,\"s\":\"BTCUSDT\",\"ps\":\"BTCUSDT\",\"b\":\"79597.00\",\"B\":\"4.110\",\"a\":\"79597.10\",\"A\":\"6.330\",\"T\":1788567728910,\"E\":1788567728910,\"st\":1}}"}
{"receive_ns":1788567728916307000,"stream":"btcusdt@trade","event_type":"trade","event_time_ms":1788567728910,"raw_json":"{\"stream\":\"btcusdt@trade\",\"data\":{\"e\":\"trade\",\"E\":1788567728910,\"T\":1788567728910,\"s\":\"BTCUSDT\",\"t\":8054122620,\"p\":\"79597.10\",\"q\":\"0.001\",\"X\":\"MARKET\",\"m\":false,\"st\":1}}"}
{"receive_ns":1788567728925279000,"stream":"btcusdt@depth@100ms","event_type":"depthUpdate","event_time_ms":1788567728937,"raw_json":"{\"stream\":\"btcusdt@depth@100ms\",\"data\":{\"e\":\"depthUpdate\",\"E\":1788567728937,\"T\":1788567728935,\"s\":\"BTCUSDT\",\"ps\":\"BTCUSDT\",\"U\":11478508242939,\"u\":11478508248792,\"pu\":11478508242870,\"b\":[[\"1000.00\",\"25.004\"],[\"29097.00\",\"0.126\"],[\"29197.00\",\"1.876\"],[\"29297.00\",\"0.098\"],[\"63678.00\",\"0.000\"],[\"71637.30\",\"0.043\"],[\"76413.10\",\"0.000\"],[\"78380.70\",\"0.000\"],[\"78641.80\",\"33.135\"],[\"78801.00\",\"13.624\"],[\"79467.60\",\"10.011\"],[\"79467.70\",\"2.176\"],[\"79471.70\",\"0.040\"],[\"79471.80\",\"1.320\"],[\"79475.40\",\"0.529\"],[\"79593.20\",\"0.026\"],[\"79594.00\",\"0.000\"],[\"79594.10\",\"0.002\"],[\"79594.30\",\"0.058\"],[\"79594.60\",\"0.001\"],[\"79594.70\",\"0.000\"],[\"79595.30\",\"0.001\"]],\"a\":[[\"79597.10\",\"6.330\"],[\"79601.10\",\"0.009\"],[\"79605.40\",\"0.080\"],[\"79608.10\",\"0.007\"],[\"79719.50\",\"0.514\"],[\"79728.00\",\"2.370\"],[\"79731.70\",\"10.003\"],[\"79806.70\",\"2.805\"],[\"79940.20\",\"0.000\"],[\"80324.20\",\"0.559\"],[\"80393.10\",\"109.373\"],[\"80791.10\",\"5.963\"],[\"81023.00\",\"0.000\"]],\"st\":1}}"}
{"receive_ns":1788567728994770000,"stream":"btcusdt@bookTicker","event_type":"bookTicker","event_time_ms":1788567729011,"raw_json":"{\"stream\":\"btcusdt@bookTicker\",\"data\":{\"e\":\"bookTicker\",\"u\":11478508252572,\"s\":\"BTCUSDT\",\"ps\":\"BTCUSDT\",\"b\":\"79597.00\",\"B\":\"4.109\",\"a\":\"79597.10\",\"A\":\"6.330\",\"T\":1788567729010,\"E\":1788567729011,\"st\":1}}"}
{"receive_ns":1788567729005802000,"stream":"btcusdt@trade","event_type":"trade","event_time_ms":1788567729011,"raw_json":"{\"stream\":\"btcusdt@trade\",\"data\":{\"e\":\"trade\",\"E\":1788567729011,\"T\":1788567729010,\"s\":\"BTCUSDT\",\"t\":8054122621,\"p\":\"79597.00\",\"q\":\"0.001\",\"X\":\"MARKET\",\"m\":true,\"st\":1}}"}
{"receive_ns":1788567729011621000,"stream":"btcusdt@bookTicker","event_type":"bookTicker","event_time_ms":1788567729012,"raw_json":"{\"stream\":\"btcusdt@bookTicker\",\"data\":{\"e\":\"bookTicker\",\"u\":11478508252688,\"s\":\"BTCUSDT\",\"ps\":\"BTCUSDT\",\"b\":\"79597.00\",\"B\":\"4.068\",\"a\":\"79597.10\",\"A\":\"6.330\",\"T\":1788567729012,\"E\":1788567729012,\"st\":1}}"}
{"receive_ns":1788567729020994000,"stream":"btcusdt@bookTicker","event_type":"bookTicker","event_time_ms":1788567729012,"raw_json":"{\"stream\":\"btcusdt@bookTicker\",\"data\":{\"e\":\"bookTicker\",\"u\":11478508252715,\"s\":\"BTCUSDT\",\"ps\":\"BTCUSDT\",\"b\":\"79597.00\",\"B\":\"4.056\",\"a\":\"79597.10\",\"A\":\"6.330\",\"T\":1788567729012,\"E\":1788567729012,\"st\":1}}"}
{"receive_ns":1788567729032630000,"stream":"btcusdt@depth@100ms","event_type":"depthUpdate","event_time_ms":1788567729039,"raw_json":"{\"stream\":\"btcusdt@depth@100ms\",\"data\":{\"e\":\"depthUpdate\",\"E\":1788567729039,\"T\":1788567729037,\"s\":\"BTCUSDT\",\"ps\":\"BTCUSDT\",\"U\":11478508248864,\"u\":11478508254162,\"pu\":11478508248792,\"b\":[[\"1000.00\",\"25.004\"],[\"29097.00\",\"0.210\"],[\"29197.00\",\"1.890\"],[\"29297.00\",\"0.000\"],[\"63678.00\",\"0.000\"],[\"71637.30\",\"0.043\"],[\"76413.10\",\"0.002\"],[\"78426.90\",\"5.152\"],[\"78452.80\",\"0.000\"],[\"78549.00\",\"0.636\"],[\"78801.00\",\"13.624\"],[\"79525.30\",\"0.635\"],[\"79541.20\",\"0.829\"],[\"79582.70\",\"0.198\"],[\"79590.40\",\"0.001\"],[\"79592.60\",\"0.026\"],[\"79592.70\",\"0.027\"],[\"79592.80\",\"0.531\"],[\"79592.90\",\"0.028\"],[\"79593.10\",\"0.047\"],[\"79593.70\",\"0.000\"],[\"79593.90\",\"0.000\"],[\"79597.00\",\"4.056\"]],\"a\":[[\"79668.80\",\"0.034\"],[\"79692.70\",\"0.001\"],[\"79806.70\",\"4.846\"],[\"79938.60\",\"0.270\"],[\"80313.60\",\"2.986\"],[\"80393.10\",\"109.371\"],[\"80617.70\",\"1.745\"],[\"81085.60\",\"4.405\"]],\"st\":1}}"}
{"receive_ns":1788567729123864000,"stream":"btcusdt@depth@100ms","event_type":"depthUpdate","event_time_ms":1788567729141,"raw_json":"{\"stream\":\"btcusdt@depth@100ms\",\"data\":{\"e\":\"depthUpdate\",\"E\":1788567729141,\"T\":1788567729137,\"s\":\"BTCUSDT\",\"ps\":\"BTCUSDT\",\"U\":11478508254313,\"u\":11478508261518,\"pu\":11478508254162,\"b\":[[\"29097.00\",\"0.385\"],[\"29197.00\",\"1.715\"],[\"63678.00\",\"0.000\"],[\"71637.30\",\"0.043\"],[\"76413.10\",\"0.000\"],[\"78801.00\",\"13.624\"],[\"78960.20\",\"7.244\"],[\"79199.00\",\"4.876\"],[\"79450.40\",\"0.016\"],[\"79450.50\",\"1.934\"],[\"79566.80\",\"0.125\"],[\"79567.20\",\"0.002\"],[\"79570.10\",\"0.453\"],[\"79571.30\",\"0.002\"],[\"79573.30\",\"0.481\"],[\"79575.60\",\"0.877\"],[\"79576.70\",\"2.258\"],[\"79577.70\",\"0.000\"],[\"79579.90\",\"0.124\"],[\"79582.70\",\"0.194\"],[\"79589.20\",\"0.000\"],[\"79589.70\",\"0.077\"],[\"79592.50\",\"0.148\"],[\"79593.40\",\"0.001\"],[\"79593.50\",\"0.026\"]],\"a\":[[\"79610.40\",\"0.562\"],[\"79610.90\",\"0.003\"],[\"79612.80\",\"0.003\"],[\"79616.20\",\"0.001\"],[\"79616.30\",\"0.013\"],[\"79616.60\",\"0.423\"],[\"79617.10\",\"0.000\"],[\"79617.80\",\"0.000\"],[\"79620.20\",\"0.003\"],[\"79621.00\",\"0.455\"],[\"79624.00\",\"0.633\"],[\"79693.00\",\"0.002\"],[\"79696.20\",\"0.004\"],[\"79701.50\",\"0.347\"],[\"79704.70\",\"0.017\"],[\"79705.10\",\"0.035\"],[\"79718.80\",\"3.052\"],[\"79806.70\",\"2.843\"],[\"80393.10\",\"109.371\"],[\"80727.40\",\"2.672\"]],\"st\":1}}"}
{"receive_ns":1788567729231442000,"stream":"btcusdt@depth@100ms","event_type":"depthUpdate","event_time_ms":1788567729243,"raw_json":"{\"stream\":\"btcusdt@depth@100ms\",\"data\":{\"e\":\"depthUpdate\",\"E\":1788567729243,\"T\":1788567729241,\"s\":\"BTCUSDT\",\"ps\":\"BTCUSDT\",\"U\":11478508261769,\"u\":11478508267651,\"pu\":11478508261518,\"b\":[[\"1000.00\",\"25.004\"],[\"29097.00\",\"0.567\"],[\"29197.00\",\"1.533\"],[\"71637.30\",\"0.043\"],[\"76413.10\",\"0.002\"],[\"78482.60\",\"33.918\"],[\"78801.00\",\"13.624\"],[\"79361.80\",\"0.628\"],[\"79553.50\",\"0.859\"],[\"79573.30\",\"0.481\"],[\"79584.00\",\"0.012\"],[\"79584.80\",\"0.005\"],[\"79584.90\",\"0.000\"],[\"79586.90\",\"0.001\"],[\"79587.70\",\"0.004\"],[\"79588.00\",\"1.656\"],[\"79588.10\",\"0.083\"],[\"79592.10\",\"0.000\"]],\"a\":[[\"79613.20\",\"0.002\"],[\"79625.90\",\"0.013\"],[\"79664.00\",\"0.024\"],[\"79691.90\",\"0.062\"],[\"79692.00\",\"7.359\"],[\"79693.00\",\"0.003\"],[\"79696.20\",\"0.005\"],[\"79701.50\",\"0.348\"],[\"79702.70\",\"0.056\"],[\"80393.10\",\"109.371\"],[\"80518.60\",\"0.001\"],[\"81029.80\",\"1.576\"],[\"81189.00\",\"10.537\"],[\"81587.00\",\"0.358\"]],\"st\":1}}"}
{"receive_ns":1788567729325615000,"stream":"btcusdt@bookTicker","event_type":"bookTicker","event_time_ms":1788567729330,"raw_json":"{\"stream\":\"btcusdt@bookTicker\",\"data\":{\"e\":\"bookTicker\",\"u\":11478508274892,\"s\":\"BTCUSDT\",\"ps\":\"BTCUSDT\",\"b\":\"79597.00\",\"B\":\"3.046\",\"a\":\"79597.10\",\"A\":\"6.330\",\"T\":1788567729330,\"E\":1788567729330,\"st\":1}}"}
{"receive_ns":1788567729338112000,"stream":"btcusdt@bookTicker","event_type":"bookTicker","event_time_ms":1788567729341,"raw_json":"{\"stream\":\"btcusdt@bookTicker\",\"data\":{\"e\":\"bookTicker\",\"u\":11478508276010,\"s\":\"BTCUSDT\",\"ps\":\"BTCUSDT\",\"b\":\"79597.00\",\"B\":\"4.058\",\"a\":\"79597.10\",\"A\":\"6.330\",\"T\":1788567729341,\"E\":1788567729341,\"st\":1}}"}
{"receive_ns":1788567729344210000,"stream":"btcusdt@bookTicker","event_type":"bookTicker","event_time_ms":1788567729342,"raw_json":"{\"stream\":\"btcusdt@bookTicker\",\"data\":{\"e\":\"bookTicker\",\"u\":11478508276111,\"s\":\"BTCUSDT\",\"ps\":\"BTCUSDT\",\"b\":\"79597.00\",\"B\":\"4.057\",\"a\":\"79597.10\",\"A\":\"6.330\",\"T\":1788567729342,\"E\":1788567729342,\"st\":1}}"}
{"receive_ns":1788567729352360000,"stream":"btcusdt@depth@100ms","event_type":"depthUpdate","event_time_ms":1788567729345,"raw_json":"{\"stream\":\"btcusdt@depth@100ms\",\"data\":{\"e\":\"depthUpdate\",\"E\":1788567729345,\"T\":1788567729344,\"s\":\"BTCUSDT\",\"ps\":\"BTCUSDT\",\"U\":11478508267754,\"u\":11478508276255,\"pu\":11478508267651,\"b\":[[\"1000.00\",\"25.004\"],[\"29097.00\",\"0.742\"],[\"29197.00\",\"1.358\"],[\"63677.60\",\"0.000\"],[\"71637.30\",\"0.043\"],[\"75617.20\",\"0.006\"],[\"78243.90\",\"10.211\"],[\"78369.30\",\"2.661\"],[\"78778.00\",\"0.000\"],[\"78880.60\",\"12.530\"],[\"79361.80\",\"0.425\"],[\"79521.90\",\"1.026\"],[\"79537.80\",\"0.691\"],[\"79541.20\",\"0.002\"],[\"79553.50\",\"0.860\"],[\"79557.10\",\"0.001\"],[\"79566.80\",\"0.000\"],[\"79567.20\",\"0.127\"],[\"79584.80\",\"0.385\"],[\"79587.80\",\"1.512\"],[\"79588.00\",\"1.276\"],[\"79589.60\",\"0.139\"],[\"79589.70\",\"0.001\"],[\"79592.50\",\"0.122\"],[\"79592.70\",\"0.029\"],[\"79594.30\",\"0.084\"],[\"79594.50\",\"0.026\"],[\"79595.20\",\"0.000\"],[\"79596.80\",\"0.165\"],[\"79597.00\",\"4.057\"]],\"a\":[[\"79605.40\",\"0.084\"],[\"79608.10\",\"0.003\"],[\"79610.70\",\"0.104\"],[\"79613.10\",\"0.190\"],[\"79616.30\",\"0.641\"],[\"79624.00\",\"0.006\"],[\"79664.00\",\"0.025\"],[\"79692.70\",\"0.003\"],[\"80393.10\",\"109.373\"],[\"83576.90\",\"0.036\"]],\"st\":1}}"}
{"receive_ns":1788567729357774000,"stream":"btcusdt@bookTicker","event_type":"bookTicker","event_time_ms":1788567729345,"raw_json":"{\"stream\":\"btcusdt@bookTicker\",\"data\":{\"e\":\"bookTicker\",\"u\":11478508276275,\"s\":\"BTCUSDT\",\"ps\":\"BTCUSDT\",\"b\":\"79597.00\",\"B\":\"4.057\",\"a\":\"79597.10\",\"A\":\"6.250\",\"T\":1788567729344,\"E\":1788567729345,\"st\":1}}"}
{"receive_ns":1788567729369482000,"stream":"btcusdt@bookTicker","event_type":"bookTicker","event_time_ms":1788567729345,"raw_json":"{\"stream\":\"btcusdt@bookTicker\",\"data\":{\"e\":\"bookTicker\",\"u\":11478508276280,\"s\":\"BTCUSDT\",\"ps\":\"BTCUSDT\",\"b\":\"79597.00\",\"B\":\"4.057\",\"a\":\"79597.10\",\"A\":\"6.170\",\"T\":1788567729344,\"E\":1788567729345,\"st\":1}}"}
{"receive_ns":1788567729375270000,"stream":"btcusdt@bookTicker","event_type":"bookTicker","event_time_ms":1788567729345,"raw_json":"{\"stream\":\"btcusdt@bookTicker\",\"data\":{\"e\":\"bookTicker\",\"u\":11478508276284,\"s\":\"BTCUSDT\",\"ps\":\"BTCUSDT\",\"b\":\"79597.00\",\"B\":\"4.057\",\"a\":\"79597.10\",\"A\":\"6.090\",\"T\":1788567729345,\"E\":1788567729345,\"st\":1}}"}
{"receive_ns":1788567729383571000,"stream":"btcusdt@bookTicker","event_type":"bookTicker","event_time_ms":1788567729366,"raw_json":"{\"stream\":\"btcusdt@bookTicker\",\"data\":{\"e\":\"bookTicker\",\"u\":11478508277739,\"s\":\"BTCUSDT\",\"ps\":\"BTCUSDT\",\"b\":\"79597.00\",\"B\":\"4.098\",\"a\":\"79597.10\",\"A\":\"6.090\",\"T\":1788567729366,\"E\":1788567729366,\"st\":1}}"}
{"receive_ns":1788567729401771000,"stream":"btcusdt@bookTicker","event_type":"bookTicker","event_time_ms":1788567729367,"raw_json":"{\"stream\":\"btcusdt@bookTicker\",\"data\":{\"e\":\"bookTicker\",\"u\":11478508277821,\"s\":\"BTCUSDT\",\"ps\":\"BTCUSDT\",\"b\":\"79597.00\",\"B\":\"4.099\",\"a\":\"79597.10\",\"A\":\"6.090\",\"T\":1788567729367,\"E\":1788567729367,\"st\":1}}"}
{"receive_ns":1788567729430670000,"stream":"btcusdt@depth@100ms","event_type":"depthUpdate","event_time_ms":1788567729447,"raw_json":"{\"stream\":\"btcusdt@depth@100ms\",\"data\":{\"e\":\"depthUpdate\",\"E\":1788567729447,\"T\":1788567729446,\"s\":\"BTCUSDT\",\"ps\":\"BTCUSDT\",\"U\":11478508276266,\"u\":11478508281630,\"pu\":11478508276255,\"b\":[[\"29097.00\",\"0.924\"],[\"29197.00\",\"1.176\"],[\"71637.30\",\"0.043\"],[\"76413.10\",\"0.000\"],[\"78005.10\",\"10.831\"],[\"78801.00\",\"13.624\"],[\"78960.20\",\"7.497\"],[\"79199.00\",\"4.866\"],[\"79361.80\",\"0.213\"],[\"79521.90\",\"0.197\"],[\"79537.80\",\"0.000\"],[\"79566.50\",\"0.198\"],[\"79567.20\",\"0.002\"],[\"79584.80\",\"0.385\"],[\"79584.90\",\"0.000\"],[\"79588.00\",\"0.008\"],[\"79588.10\",\"0.083\"],[\"79588.20\",\"0.001\"],[\"79588.30\",\"0.003\"],[\"79588.40\",\"0.004\"],[\"79588.50\",\"0.122\"],[\"79588.60\",\"1.256\"],[\"79592.60\",\"0.000\"],[\"79592.70\",\"0.001\"],[\"79594.60\",\"0.279\"],[\"79595.20\",\"0.026\"],[\"79596.80\",\"0.167\"],[\"79597.00\",\"4.099\"]],\"a\":[[\"79597.10\",\"6.090\"],[\"79597.20\",\"0.333\"],[\"79605.40\",\"0.080\"],[\"79608.10\",\"0.007\"],[\"79610.40\",\"0.123\"],[\"79610.70\",\"0.543\"],[\"79616.30\",\"0.013\"],[\"79624.10\",\"0.628\"],[\"79626.60\",\"0.005\"],[\"79660.30\",\"5.001\"],[\"79663.40\",\"22.005\"],[\"79665.40\",\"1.810\"],[\"79666.10\",\"0.015\"],[\"80299.30\",\"6.253\"],[\"80393.10\",\"109.371\"]],\"st\":1}}"}
{"receive_ns":1788567729444993000,"stream":"btcusdt@bookTicker","event_type":"bookTicker","event_time_ms":1788567729464,"raw_json":"{\"stream\":\"btcusdt@bookTicker\",\"data\":{\"e\":\"bookTicker\",\"u\":11478508282858,\"s\":\"BTCUSDT\",\"ps\":\"BTCUSDT\",\"b\":\"79597.00\",\"B\":\"4.099\",\"a\":\"79597.10\",\"A\":\"6.089\",\"T\":1788567729464,\"E\":1788567729464,\"st\":1}}"}
{"receive_ns":1788567729450521000,"stream":"btcusdt@bookTicker","event_type":"bookTicker","event_time_ms":1788567729465,"raw_json":"{\"stream\":\"btcusdt@bookTicker\",\"data\":{\"e\":\"bookTicker\",\"u\":11478508282976,\"s\":\"BTCUSDT\",\"ps\":\"BTCUSDT\",\"b\":\"79597.00\",\"B\":\"4.050\",\"a\":\"79597.10\",\"A\":\"6.089\",\"T\":1788567729465,\"E\":1788567729465,\"st\":1}}"}
{"receive_ns":1788567729450853000,"stream":"btcusdt@bookTicker","event_type":"bookTicker","event_time_ms":1788567729468,"raw_json":"{\"stream\":\"btcusdt@bookTicker\",\"data\":{\"e\":\"bookTicker\",\"u\":11478508283109,\"s\":\"BTCUSDT\",\"ps\":\"BTCUSDT\",\"b\":\"79597.00\",\"B\":\"4.100\",\"a\":\"79597.10\",\"A\":\"6.089\",\"T\":1788567729468,\"E\":1788567729468,\"st\":1}}"}
{"receive_ns":1788567729456228000,"stream":"btcusdt@bookTicker","event_type":"bookTicker","event_time_ms":1788567729468,"raw_json":"{\"stream\":\"btcusdt@bookTicker\",\"data\":{\"e\":\"bookTicker\",\"u\":11478508283123,\"s\":\"BTCUSDT\",\"ps\":\"BTCUSDT\",\"b\":\"79597.00\",\"B\":\"4.077\",\"a\":\"79597.10\",\"A\":\"6.089\",\"T\":1788567729468,\"E\":1788567729468,\"st\":1}}"}
{"receive_ns":1788567729477407000,"stream":"btcusdt@bookTicker","event_type":"bookTicker","event_time_ms":1788567729473,"raw_json":"{\"stream\":\"btcusdt@bookTicker\",\"data\":{\"e\":\"bookTicker\",\"u\":11478508283297,\"s\":\"BTCUSDT\",\"ps\":\"BTCUSDT\",\"b\":\"79597.00\",\"B\":\"4.100\",\"a\":\"79597.10\",\"A\":\"6.089\",\"T\":1788567729473,\"E\":1788567729473,\"st\":1}}"}
{"receive_ns":1788567729485145000,"stream":"btcusdt@bookTicker","event_type":"bookTicker","event_time_ms":1788567729505,"raw_json":"{\"stream\":\"btcusdt@bookTicker\",\"data\":{\"e\":\"bookTicker\",\"u\":11478508285039,\"s\":\"BTCUSDT\",\"ps\":\"BTCUSDT\",\"b\":\"79597.00\",\"B\":\"4.057\",\"a\":\"79597.10\",\"A\":\"6.089\",\"T\":1788567729505,\"E\":1788567729505,\"st\":1}}"}
{"receive_ns":1788567729497398000,"stream":"btcusdt@bookTicker","event_type":"bookTicker","event_time_ms":1788567729508,"raw_json":"{\"stream\":\"btcusdt@bookTicker\",\"data\":{\"e\":\"bookTicker\",\"u\":11478508285390,\"s\":\"BTCUSDT\",\"ps\":\"BTCUSDT\",\"b\":\"79597.00\",\"B\":\"4.017\",\"a\":\"79597.10\",\"A\":\"6.089\",\"T\":1788567729508,\"E\":1788567729508,\"st\":1}}"}
{"receive_ns":1788567729514413000,"stream":"btcusdt@bookTicker","event_type":"bookTicker","event_time_ms":1788567729509,"raw_json":"{\"stream\":\"btcusdt@bookTicker\",\"data\":{\"e\":\"bookTicker\",\"u\":11478508285462,\"s\":\"BTCUSDT\",\"ps\":\"BTCUSDT\",\"b\":\"79597.00\",\"B\":\"4.061\",\"a\":\"79597.10\",\"A\":\"6.089\",\"T\":1788567729509,\"E\":1788567729509,\"st\":1}}"}
{"receive_ns":1788567729514748000,"stream":"btcusdt@bookTicker","event_type":"bookTicker","event_time_ms":1788567729511,"raw_json":"{\"stream\":\"btcusdt@bookTicker\",\"data\":{\"e\":\"bookTicker\",\"u\":11478508285603,\"s\":\"BTCUSDT\",\"ps\":\"BTCUSDT\",\"b\":\"79597.00\",\"B\":\"4.104\",\"a\":\"79597.10\",\"A\":\"6.089\",\"T\":1788567729511,\"E\":1788567729511,\"st\":1}}"}
{"receive_ns":1788567729526640000,"stream":"btcusdt@bookTicker","event_type":"bookTicker","event_time_ms":1788567729513,"raw_json":"{\"stream\":\"btcusdt@bookTicker\",\"data\":{\"e\":\"bookTicker\",\"u\":11478508285713,\"s\":\"BTCUSDT\",\"ps\":\"BTCUSDT\",\"b\":\"79597.00\",\"B\":\"4.103\",\"a\":\"79597.10\",\"A\":\"6.089\",\"T\":1788567729512,\"E\":1788567729513,\"st\":1}}"}
{"receive_ns":1788567729539220000,"stream":"btcusdt@depth@100ms","event_type":"depthUpdate","event_time_ms":1788567729549,"raw_json":"{\"stream\":\"btcusdt@depth@100ms\",\"data\":{\"e\":\"depthUpdate\",\"E\":1788567729549,\"T\":1788567729546,\"s\":\"BTCUSDT\",\"ps\":\"BTCUSDT\",\"U\":11478508281713,\"u\":11478508287447,\"pu\":11478508281630,\"b\":[[\"1000.00\",\"25.004\"],[\"29097.00\",\"1.099\"],[\"29197.00\",\"1.001\"],[\"71637.30\",\"0.043\"],[\"75806.70\",\"0.000\"],[\"76413.10\",\"0.002\"],[\"78801.00\",\"13.624\"],[\"79199.00\",\"4.865\"],[\"79361.80\",\"0.001\"],[\"79475.40\",\"0.529\"],[\"79584.80\",\"0.005\"],[\"79584.90\",\"1.256\"],[\"79586.90\",\"0.001\"],[\"79587.70\",\"0.004\"],[\"79588.00\",\"0.396\"],[\"79588.10\",\"0.087\"],[\"79588.40\",\"0.000\"],[\"79588.50\",\"0.114\"],[\"79588.60\",\"0.000\"],[\"79588.70\",\"0.002\"],[\"79588.80\",\"0.002\"],[\"79591.80\",\"0.000\"],[\"79591.90\",\"0.183\"],[\"79592.10\",\"0.002\"],[\"79592.50\",\"0.124\"],[\"79592.80\",\"0.505\"],[\"79592.90\",\"0.002\"],[\"79595.40\",\"0.028\"],[\"79595.60\",\"0.038\"],[\"79597.00\",\"4.103\"]],\"a\":[[\"79597.10\",\"6.089\"],[\"79597.20\",\"0.090\"],[\"79616.60\",\"0.051\"],[\"79617.10\",\"0.372\"],[\"79719.50\",\"0.514\"],[\"79995.10\",\"4.365\"],[\"80393.10\",\"109.371\"],[\"80485.90\",\"0.621\"],[\"80512.50\",\"0.620\"],[\"81189.00\",\"10.540\"]],\"st\":1}}"}
{"receive_ns":1788567729635347000,"stream":"btcusdt@depth@100ms","event_type":"depthUpdate","event_time_ms":1788567729651,"raw_json":"{\"stream\":\"btcusdt@depth@100ms\",\"data\":{\"e\":\"depthUpdate\",\"E\":1788567729651,\"T\":1788567729650,\"s\":\"BTCUSDT\",\"ps\":\"BTCUSDT\",\"U\":11478508287596,\"u\":11478508293936,\"pu\":11478508287447,\"b\":[[\"29097.00\",\"1.281\"],[\"29197.00\",\"0.819\"],[\"71637.30\",\"0.043\"],[\"76413.10\",\"0.000\"],[\"78540.90\",\"0.000\"],[\"78801.00\",\"13.624\"],[\"79199.00\",\"4.866\"],[\"79377.30\",\"0.125\"]],\"a\":[[\"79644.80\",\"0.365\"],[\"79646.50\",\"0.000\"],[\"79818.90\",\"6.890\"],[\"79995.10\",\"4.366\"],[\"80324.30\",\"0.189\"],[\"80393.10\",\"109.371\"],[\"80538.00\",\"8.491\"],[\"80592.10\",\"12.370\"]],\"st\":1}}"}
{"receive_ns":1788567729694034000,"stream":"btcusdt@bookTicker","event_type":"bookTicker","event_time_ms":1788567729714,"raw_json":"{\"stream\":\"btcusdt@bookTicker\",\"data\":{\"e\":\"bookTicker\",\"u\":11478508298433,\"s\":\"BTCUSDT\",\"ps\":\"BTCUSDT\",\"b\":\"79597.00\",\"B\":\"4.087\",\"a\":\"79597.10\",\"A\":\"6.089\",\"T\":1788567729714,\"E\":1788567729714,\"st\":1}}"}
{"receive_ns":1788567729700364000,"stream":"btcusdt@bookTicker","event_type":"bookTicker","event_time_ms":1788567729717,"raw_json":"{\"stream\":\"btcusdt@bookTicker\",\"data\":{\"e\":\"bookTicker\",\"u\":11478508298639,\"s\":\"BTCUSDT\",\"ps\":\"BTCUSDT\",\"b\":\"79597.00\",\"B\":\"4.087\",\"a\":\"79597.10\",\"A\":\"6.170\",\"T\":1788567729717,\"E\":1788567729717,\"st\":1}}"}
{"receive_ns":1788567729700577000,"stream":"btcusdt@bookTicker","event_type":"bookTicker","event_time_ms":1788567729717,"raw_json":"{\"stream\":\"btcusdt@bookTicker\",\"data\":{\"e\":\"bookTicker\",\"u\":11478508298647,\"s\":\"BTCUSDT\",\"ps\":\"BTCUSDT\",\"b\":\"79597.00\",\"B\":\"4.087\",\"a\":\"79597.10\",\"A\":\"6.251\",\"T\":1788567729717,\"E\":1788567729717,\"st\":1}}"}
{"receive_ns":1788567729706679000,"stream":"btcusdt@bookTicker","event_type":"bookTicker","event_time_ms":1788567729718,"raw_json":"{\"stream\":\"btcusdt@bookTicker\",\"data\":{\"e\":\"bookTicker\",\"u\":11478508298673,\"s\":\"BTCUSDT\",\"ps\":\"BTCUSDT\",\"b\":\"79597.00\",\"B\":\"4.087\",\"a\":\"79597.10\",\"A\":\"6.332\",\"T\":1788567729717,\"E\":1788567729718,\"st\":1}}"}
{"receive_ns":1788567729713030000,"stream":"btcusdt@bookTicker","event_type":"bookTicker","event_time_ms":1788567729718,"raw_json":"{\"stream\":\"btcusdt@bookTicker\",\"data\":{\"e\":\"bookTicker\",\"u\":11478508298700,\"s\":\"BTCUSDT\",\"ps\":\"BTCUSDT\",\"b\":\"79597.00\",\"B\":\"4.087\",\"a\":\"79597.10\",\"A\":\"6.330\",\"T\":1788567729718,\"E\":1788567729718,\"st\":1}}"}
{"receive_ns":1788567729713221000,"stream":"btcusdt@bookTicker","event_type":"bookTicker","event_time_ms":1788567729718,"raw_json":"{\"stream\":\"btcusdt@bookTicker\",\"data\":{\"e\":\"bookTicker\",\"u\":11478508298703,\"s\":\"BTCUSDT\",\"ps\":\"BTCUSDT\",\"b\":\"79597.00\",\"B\":\"4.088\",\"a\":\"79597.10\",\"A\":\"6.330\",\"T\":1788567729718,\"E\":1788567729718,\"st\":1}}"}
{"receive_ns":1788567729725419000,"stream":"btcusdt@bookTicker","event_type":"bookTicker","event_time_ms":1788567729719,"raw_json":"{\"stream\":\"btcusdt@bookTicker\",\"data\":{\"e\":\"bookTicker\",\"u\":11478508298750,\"s\":\"BTCUSDT\",\"ps\":\"BTCUSDT\",\"b\":\"79597.00\",\"B\":\"4.088\",\"a\":\"79597.10\",\"A\":\"6.332\",\"T\":1788567729719,\"E\":1788567729719,\"st\":1}}"}
{"receive_ns":1788567729737313000,"stream":"btcusdt@bookTicker","event_type":"bookTicker","event_time_ms":1788567729740,"raw_json":"{\"stream\":\"btcusdt@bookTicker\",\"data\":{\"e\":\"bookTicker\",\"u\":11478508299910,\"s\":\"BTCUSDT\",\"ps\":\"BTCUSDT\",\"b\":\"79597.00\",\"B\":\"4.104\",\"a\":\"79597.10\",\"A\":\"6.332\",\"T\":1788567729740,\"E\":1788567729740,\"st\":1}}"}
{"receive_ns":1788567729744167000,"stream":"btcusdt@depth@100ms","event_type":"depthUpdate","event_time_ms":1788567729753,"raw_json":"{\"stream\":\"btcusdt@depth@100ms\",\"data\":{\"e\":\"depthUpdate\",\"E\":1788567729753,\"T\":1788567729751,\"s\":\"BTCUSDT\",\"ps\":\"BTCUSDT\",\"U\":11478508293992,\"u\":11478508300423,\"pu\":11478508293936,\"b\":[[\"29097.00\",\"1.456\"],[\"29197.00\",\"0.644\"],[\"71637.30\",\"0.043\"],[\"77000.00\",\"120.118\"],[\"78005.10\",\"10.828\"],[\"78588.10\",\"6.058\"],[\"78641.80\",\"33.642\"],[\"78687.90\",\"3.589\"],[\"78801.00\",\"13.624\"],[\"79199.00\",\"4.876\"],[\"79388.30\",\"0.006\"],[\"79436.00\",\"0.000\"],[\"79456.00\",\"0.006\"],[\"79475.40\",\"0.000\"],[\"79495.80\",\"0.008\"],[\"79535.60\",\"0.002\"],[\"79571.40\",\"1.600\"],[\"79575.40\",\"0.025\"],[\"79578.50\",\"0.002\"],[\"79582.70\",\"0.192\"],[\"79583.40\",\"0.241\"],[\"79591.40\",\"0.003\"],[\"79592.10\",\"0.000\"],[\"79592.20\",\"0.002\"],[\"79592.30\",\"0.002\"],[\"79592.50\",\"0.122\"],[\"79593.10\",\"0.021\"],[\"79595.80\",\"0.026\"],[\"79597.00\",\"4.104\"]],\"a\":[[\"79597.10\",\"6.332\"],[\"79609.90\",\"0.001\"],[\"79610.70\",\"0.545\"],[\"79618.60\",\"0.002\"],[\"79618.70\",\"0.003\"],[\"79620.00\",\"0.598\"],[\"79621.00\",\"0.003\"],[\"79625.90\",\"0.007\"],[\"79628.40\",\"0.126\"],[\"79644.80\",\"0.240\"],[\"79645.00\",\"0.127\"],[\"79657.60\",\"0.029\"],[\"79658.50\",\"0.000\"],[\"79658.60\",\"0.254\"],[\"79698.40\",\"0.000\"],[\"79698.50\",\"0.021\"],[\"79719.50\",\"0.030\"],[\"79738.30\",\"0.000\"],[\"79738.40\",\"0.004\"],[\"79759.00\",\"0.095\"],[\"79804.90\",\"0.302\"],[\"79806.70\",\"0.006\"],[\"79818.80\",\"1.740\"],[\"79995.10\",\"4.242\"],[\"80393.10\",\"109.371\"],[\"80513.30\",\"9.771\"]],\"st\":1}}"}
{"receive_ns":1788567729749675000,"stream":"btcusdt@bookTicker","event_type":"bookTicker","event_time_ms":1788567729754,"raw_json":"{\"stream\":\"btcusdt@bookTicker\",\"data\":{\"e\":\"bookTicker\",\"u\":11478508300580,\"s\":\"BTCUSDT\",\"ps\":\"BTCUSDT\",\"b\":\"79597.00\",\"B\":\"4.102\",\"a\":\"79597.10\",\"A\":\"6.332\",\"T\":1788567729754,\"E\":1788567729754,\"st\":1}}"}
{"receive_ns":1788567729749915000,"stream":"btcusdt@bookTicker","event_type":"bookTicker","event_time_ms":1788567729761,"raw_json":"{\"stream\":\"btcusdt@bookTicker\",\"data\":{\"e\":\"bookTicker\",\"u\":11478508300990,\"s\":\"BTCUSDT\",\"ps\":\"BTCUSDT\",\"b\":\"79597.00\",\"B\":\"4.114\",\"a\":\"79597.10\",\"A\":\"6.332\",\"T\":1788567729761,\"E\":1788567729761,\"st\":1}}"}
{"receive_ns":1788567729750081000,"stream":"btcusdt@bookTicker","event_type":"bookTicker","event_time_ms":1788567729761,"raw_json":"{\"stream\":\"btcusdt@bookTicker\",\"data\":{\"e\":\"bookTicker\",\"u\":11478508301012,\"s\":\"BTCUSDT\",\"ps\":\"BTCUSDT\",\"b\":\"79597.00\",\"B\":\"4.114\",\"a\":\"79597.10\",\"A\":\"6.330\",\"T\":1788567729761,\"E\":1788567729761,\"st\":1}}"}
{"receive_ns":1788567729756635000,"stream":"btcusdt@trade","event_type":"trade","event_time_ms":1788567729761,"raw_json":"{\"stream\":\"btcusdt@trade\",\"data\":{\"e\":\"trade\",\"E\":1788567729761,\"T\":1788567729761,\"s\":\"BTCUSDT\",\"t\":8054122622,\"p\":\"79597.10\",\"q\":\"0.002\",\"X\":\"MARKET\",\"m\":false,\"st\":1}}"}
{"receive_ns":1788567729845639000,"stream":"btcusdt@depth@100ms","event_type":"depthUpdate","event_time_ms":1788567729855,"raw_json":"{\"stream\":\"btcusdt@depth@100ms\",\"data\":{\"e\":\"depthUpdate\",\"E\":1788567729855,\"T\":1788567729854,\"s\":\"BTCUSDT\",\"ps\":\"BTCUSDT\",\"U\":11478508300572,\"u\":11478508306851,\"pu\":11478508300423,\"b\":[[\"1000.00\",\"25.004\"],[\"29097.00\",\"1.638\"],[\"29197.00\",\"0.462\"],[\"71637.30\",\"0.043\"],[\"76413.10\",\"0.002\"],[\"78150.90\",\"5.751\"],[\"78801.00\",\"13.624\"],[\"79388.30\",\"4.641\"],[\"79436.00\",\"2.682\"],[\"79475.40\",\"0.529\"],[\"79591.30\",\"0.176\"],[\"79593.20\",\"0.000\"],[\"79593.30\",\"0.000\"],[\"79596.00\",\"0.108\"],[\"79596.10\",\"0.026\"],[\"79596.90\",\"2.616\"],[\"79597.00\",\"4.114\"]],\"a\":[[\"79597.10\",\"6.330\"],[\"79644.70\",\"0.125\"],[\"79645.00\",\"0.002\"],[\"79719.50\",\"0.514\"],[\"79758.90\",\"2.173\"],[\"79806.70\",\"2.843\"],[\"79829.90\",\"0.000\"],[\"79830.00\",\"0.456\"],[\"80313.60\",\"3.857\"],[\"80393.10\",\"109.371\"],[\"80513.30\",\"9.027\"],[\"80538.00\",\"7.004\"],[\"80687.60\",\"2.304\"]],\"st\":1}}"}
{"receive_ns":1788567729857709000,"stream":"btcusdt@bookTicker","event_type":"bookTicker","event_time_ms":1788567729872,"raw_json":"{\"stream\":\"btcusdt@bookTicker\",\"data\":{\"e\":\"bookTicker\",\"u\":11478508307927,\"s\":\"BTCUSDT\",\"ps\":\"BTCUSDT\",\"b\":\"79597.00\",\"B\":\"4.114\",\"a\":\"79597.10\",\"A\":\"6.329\",\"T\":1788567729872,\"E\":1788567729872,\"st\":1}}"}
{"receive_ns":1788567729869601000,"stream":"btcusdt@trade","event_type":"trade","event_time_ms":1788567729872,"raw_json":"{\"stream\":\"btcusdt@trade\",\"data\":{\"e\":\"trade\",\"E\":1788567729872,\"T\":1788567729872,\"s\":\"BTCUSDT\",\"t\":8054122623,\"p\":\"79597.10\",\"q\":\"0.001\",\"X\":\"MARKET\",\"m\":false,\"st\":1}}"}
{"receive_ns":1788567729941003000,"stream":"btcusdt@depth@100ms","event_type":"depthUpdate","event_time_ms":1788567729957,"raw_json":"{\"stream\":\"btcusdt@depth@100ms\",\"data\":{\"e\":\"depthUpdate\",\"E\":1788567729957,\"T\":1788567729955,\"s\":\"BTCUSDT\",\"ps\":\"BTCUSDT\",\"U\":11478508306930,\"u\":11478508312045,\"pu\":11478508306851,\"b\":[[\"1000.00\",\"24.604\"],[\"29097.00\",\"1.771\"],[\"29197.00\",\"0.308\"],[\"29497.00\",\"0.021\"],[\"71637.30\",\"0.043\"],[\"71673.00\",\"0.000\"],[\"76413.10\",\"0.000\"],[\"78801.00\",\"13.624\"],[\"79584.80\",\"1.261\"],[\"79584.90\",\"0.000\"],[\"79588.00\",\"0.330\"],[\"79588.10\",\"0.087\"],[\"79588.20\",\"0.067\"],[\"79591.30\",\"0.100\"],[\"79594.00\",\"0.026\"],[\"79594.10\",\"0.028\"],[\"79594.20\",\"0.026\"],[\"79595.40\",\"0.002\"],[\"79595.60\",\"0.012\"],[\"79595.80\",\"0.000\"],[\"79596.00\",\"0.082\"],[\"79596.10\",\"0.000\"]],\"a\":[[\"79597.10\",\"6.329\"],[\"79603.50\",\"0.014\"],[\"79644.60\",\"0.143\"],[\"79644.70\",\"0.000\"],[\"79644.90\",\"0.003\"],[\"79660.30\",\"1.977\"],[\"79663.40\",\"0.000\"],[\"79671.50\",\"21.948\"],[\"80353.30\",\"11.889\"],[\"80393.10\",\"109.371\"],[\"80469.00\",\"0.002\"],[\"80513.30\",\"9.771\"],[\"80552.30\",\"31.660\"]],\"st\":1}}"}
{"receive_ns":1788567730033337000,"stream":"btcusdt@bookTicker","event_type":"bookTicker","event_time_ms":1788567730045,"raw_json":"{\"stream\":\"btcusdt@bookTicker\",\"data\":{\"e\":\"bookTicker\",\"u\":11478508317446,\"s\":\"BTCUSDT\",\"ps\":\"BTCUSDT\",\"b\":\"79597.00\",\"B\":\"4.066\",\"a\":\"79597.10\",\"A\":\"6.329\",\"T\":1788567730044,\"E\":1788567730045,\"st\":1}}"}
{"receive_ns":1788567730044024000,"stream":"btcusdt@bookTicker","event_type":"bookTicker","event_time_ms":1788567730047,"raw_json":"{\"stream\":\"btcusdt@bookTicker\",\"data\":{\"e\":\"bookTicker\",\"u\":11478508317596,\"s\":\"BTCUSDT\",\"ps\":\"BTCUSDT\",\"b\":\"79597.00\",\"B\":\"4.114\",\"a\":\"79597.10\",\"A\":\"6.329\",\"T\":1788567730047,\"E\":1788567730047,\"st\":1}}"}
{"receive_ns":1788567730064235000,"stream":"btcusdt@bookTicker","event_type":"bookTicker","event_time_ms":1788567730048,"raw_json":"{\"stream\":\"btcusdt@bookTicker\",\"data\":{\"e\":\"bookTicker\",\"u\":11478508317649,\"s\":\"BTCUSDT\",\"ps\":\"BTCUSDT\",\"b\":\"79597.00\",\"B\":\"4.113\",\"a\":\"79597.10\",\"A\":\"6.329\",\"T\":1788567730048,\"E\":1788567730048,\"st\":1}}"}
{"receive_ns":1788567730070593000,"stream":"btcusdt@depth@100ms","event_type":"depthUpdate","event_time_ms":1788567730059,"raw_json":"{\"stream\":\"btcusdt@depth@100ms\",\"data\":{\"e\":\"depthUpdate\",\"E\":1788567730059,\"T\":1788567730058,\"s\":\"BTCUSDT\",\"ps\":\"BTCUSDT\",\"U\":11478508312145,\"u\":11478508318582,\"pu\":11478508312045,\"b\":[[\"29097.00\",\"1.834\"],[\"29197.00\",\"0.189\"],[\"29497.00\",\"0.077\"],[\"71637.30\",\"0.043\"],[\"76413.10\",\"0.002\"],[\"78801.00\",\"13.624\"],[\"78960.20\",\"7.749\"],[\"79000.00\",\"43.490\"],[\"79199.00\",\"4.866\"],[\"79511.00\",\"0.001\"],[\"79567.50\",\"0.003\"],[\"79568.40\",\"0.629\"],[\"79571.50\",\"0.983\"],[\"79572.30\",\"0.628\"],[\"79582.70\",\"0.192\"],[\"79584.80\",\"0.005\"],[\"79584.90\",\"1.256\"],[\"79588.00\",\"0.406\"],[\"79588.10\",\"0.077\"],[\"79588.20\",\"0.001\"],[\"79588.30\",\"0.003\"],[\"79588.40\",\"0.000\"],[\"79590.80\",\"0.077\"],[\"79597.00\",\"4.113\"]],\"a\":[[\"79645.30\",\"0.090\"],[\"79645.50\",\"0.000\"],[\"79663.40\",\"21.948\"],[\"79666.10\",\"0.015\"],[\"79671.50\",\"0.000\"],[\"79806.70\",\"2.805\"],[\"80393.10\",\"109.371\"],[\"80513.30\",\"9.771\"],[\"81189.00\",\"10.543\"]],\"st\":1}}"}
{"receive_ns":1788567730076500000,"stream":"btcusdt@bookTicker","event_type":"bookTicker","event_time_ms":1788567730060,"raw_json":"{\"stream\":\"btcusdt@bookTicker\",\"data\":{\"e\":\"bookTicker\",\"u\":11478508318680,\"s\":\"BTCUSDT\",\"ps\":\"BTCUSDT\",\"b\":\"79597.00\",\"B\":\"4.243\",\"a\":\"79597.10\",\"A\":\"6.329\",\"T\":1788567730060,\"E\":1788567730060,\"st\":1}}"}
{"receive_ns":1788567730082536000,"stream":"btcusdt@bookTicker","event_type":"bookTicker","event_time_ms":1788567730061,"raw_json":"{\"stream\":\"btcusdt@bookTicker\",\"data\":{\"e\":\"bookTicker\",\"u\":11478508318775,\"s\":\"BTCUSDT\",\"ps\":\"BTCUSDT\",\"b\":\"79597.00\",\"B\":\"4.244\",\"a\":\"79597.10\",\"A\":\"6.329\",\"T\":1788567730061,\"E\":1788567730061,\"st\":1}}"}
{"receive_ns":1788567730102006000,"stream":"btcusdt@bookTicker","event_type":"bookTicker","event_time_ms":1788567730080,"raw_json":"{\"stream\":\"btcusdt@bookTicker\",\"data\":{\"e\":\"bookTicker\",\"u\":11478508319609,\"s\":\"BTCUSDT\",\"ps\":\"BTCUSDT\",\"b\":\"79597.00\",\"B\":\"4.244\",\"a\":\"79597.10\",\"A\":\"6.318\",\"T\":1788567730079,\"E\":1788567730080,\"st\":1}}"}
{"receive_ns":1788567730120008000,"stream":"btcusdt@trade","event_type":"trade","event_time_ms":1788567730080,"raw_json":"{\"stream\":\"btcusdt@trade\",\"data\":{\"e\":\"trade\",\"E\":1788567730080,\"T\":1788567730079,\"s\":\"BTCUSDT\",\"t\":8054122624,\"p\":\"79597.10\",\"q\":\"0.011\",\"X\":\"MARKET\",\"m\":false,\"st\":1}}"}
{"receive_ns":1788567730144710000,"stream":"btcusdt@depth@100ms","event_type":"depthUpdate","event_time_ms":1788567730161,"raw_json":"{\"stream\":\"btcusdt@depth@100ms\",\"data\":{\"e\":\"depthUpdate\",\"E\":1788567730161,\"T\":1788567730157,\"s\":\"BTCUSDT\",\"ps\":\"BTCUSDT\",\"U\":11478508318671,\"u\":11478508324122,\"pu\":11478508318582,\"b\":[[\"1000.00\",\"24.604\"],[\"29097.00\",\"1.890\"],[\"29197.00\",\"0.070\"],[\"29497.00\",\"0.140\"],[\"71637.30\",\"0.043\"],[\"76413.10\",\"0.000\"],[\"78801.00\",\"13.624\"],[\"79566.50\",\"0.073\"],[\"79567.10\",\"0.126\"],[\"79575.70\",\"0.002\"],[\"79576.40\",\"0.629\"],[\"79585.00\",\"0.437\"],[\"79588.00\",\"0.004\"],[\"79588.10\",\"0.077\"],[\"79588.20\",\"0.001\"],[\"79588.30\",\"0.003\"],[\"79597.00\",\"4.244\"]],\"a\":[[\"79597.10\",\"6.318\"],[\"79642.40\",\"0.000\"],[\"79644.10\",\"0.003\"],[\"79644.40\",\"0.991\"],[\"79644.60\",\"0.018\"],[\"79691.90\",\"0.063\"],[\"79692.90\",\"0.003\"],[\"79702.70\",\"0.057\"],[\"80313.50\",\"4.981\"],[\"80393.10\",\"109.371\"],[\"80552.30\",\"33.147\"],[\"81189.00\",\"10.540\"]],\"st\":1}}"}
{"receive_ns":1788567730249826000,"stream":"btcusdt@depth@100ms","event_type":"depthUpdate","event_time_ms":1788567730263,"raw_json":"{\"stream\":\"btcusdt@depth@100ms\",\"data\":{\"e\":\"depthUpdate\",\"E\":1788567730263,\"T\":1788567730262,\"s\":\"BTCUSDT\",\"ps\":\"BTCUSDT\",\"U\":11478508324283,\"u\":11478508328961,\"pu\":11478508324122,\"b\":[[\"29097.00\",\"1.848\"],[\"29197.00\",\"0.000\"],[\"29497.00\",\"0.252\"],[\"71637.30\",\"0.043\"],[\"78588.10\",\"5.906\"],[\"78801.00\",\"13.624\"],[\"79573.30\",\"0.479\"],[\"79584.80\",\"0.381\"],[\"79584.90\",\"0.000\"],[\"79585.00\",\"0.035\"],[\"79588.00\",\"0.010\"],[\"79588.10\",\"0.093\"],[\"79588.20\",\"0.001\"],[\"79588.30\",\"0.007\"],[\"79588.40\",\"1.256\"],[\"79596.90\",\"2.634\"]],\"a\":[[\"79613.20\",\"0.000\"],[\"79644.40\",\"0.866\"],[\"79644.50\",\"0.125\"],[\"79702.60\",\"0.013\"],[\"80299.30\",\"5.382\"],[\"80393.10\",\"109.371\"],[\"80588.90\",\"0.001\"]],\"st\":1}}"}
{"receive_ns":1788567730331881000,"stream":"btcusdt@bookTicker","event_type":"bookTicker","event_time_ms":1788567730349,"raw_json":"{\"stream\":\"btcusdt@bookTicker\",\"data\":{\"e\":\"bookTicker\",\"u\":11478508333694,\"s\":\"BTCUSDT\",\"ps\":\"BTCUSDT\",\"b\":\"79597.00\",\"B\":\"3.232\",\"a\":\"79597.10\",\"A\":\"6.318\",\"T\":1788567730348,\"E\":1788567730349,\"st\":1}}"}
{"receive_ns":1788567730351863000,"stream":"btcusdt@bookTicker","event_type":"bookTicker","event_time_ms":1788567730350,"raw_json":"{\"stream\":\"btcusdt@bookTicker\",\"data\":{\"e\":\"bookTicker\",\"u\":11478508333742,\"s\":\"BTCUSDT\",\"ps\":\"BTCUSDT\",\"b\":\"79597.00\",\"B\":\"3.231\",\"a\":\"79597.10\",\"A\":\"6.318\",\"T\":1788567730349,\"E\":1788567730350,\"st\":1}}"}
{"receive_ns":1788567730369974000,"stream":"btcusdt@bookTicker","event_type":"bookTicker","event_time_ms":1788567730351,"raw_json":"{\"stream\":\"btcusdt@bookTicker\",\"data\":{\"e\":\"bookTicker\",\"u\":11478508333859,\"s\":\"BTCUSDT\",\"ps\":\"BTCUSDT\",\"b\":\"79597.00\",\"B\":\"3.232\",\"a\":\"79597.10\",\"A\":\"6.318\",\"T\":1788567730351,\"E\":1788567730351,\"st\":1}}"}
{"receive_ns":1788567730375619000,"stream":"btcusdt@bookTicker","event_type":"bookTicker","event_time_ms":1788567730357,"raw_json":"{\"stream\":\"btcusdt@bookTicker\",\"data\":{\"e\":\"bookTicker\",\"u\":11478508334185,\"s\":\"BTCUSDT\",\"ps\":\"BTCUSDT\",\"b\":\"79597.00\",\"B\":\"4.251\",\"a\":\"79597.10\",\"A\":\"6.318\",\"T\":1788567730357,\"E\":1788567730357,\"st\":1}}"}
{"receive_ns":1788567730394053000,"stream":"btcusdt@bookTicker","event_type":"bookTicker","event_time_ms":1788567730358,"raw_json":"{\"stream\":\"btcusdt@bookTicker\",\"data\":{\"e\":\"bookTicker\",\"u\":11478508334236,\"s\":\"BTCUSDT\",\"ps\":\"BTCUSDT\",\"b\":\"79597.00\",\"B\":\"4.250\",\"a\":\"79597.10\",\"A\":\"6.318\",\"T\":1788567730358,\"E\":1788567730358,\"st\":1}}"}
{"receive_ns":1788567730405139000,"stream":"btcusdt@depth@100ms","event_type":"depthUpdate","event_time_ms":1788567730365,"raw_json":"{\"stream\":\"btcusdt@depth@100ms\",\"data\":{\"e\":\"depthUpdate\",\"E\":1788567730365,\"T\":1788567730364,\"s\":\"BTCUSDT\",\"ps\":\"BTCUSDT\",\"U\":11478508329019,\"u\":11478508334507,\"pu\":11478508328961,\"b\":[[\"29097.00\",\"1.673\"],[\"29497.00\",\"0.427\"],[\"63677.60\",\"0.000\"],[\"63678.00\",\"0.000\"],[\"71637.30\",\"0.043\"],[\"76413.10\",\"0.002\"],[\"78108.50\",\"4.406\"],[\"78492.70\",\"0.000\"],[\"78801.00\",\"13.626\"],[\"79199.00\",\"4.876\"],[\"79475.40\",\"0.000\"],[\"79475.50\",\"0.529\"],[\"79521.90\",\"0.197\"],[\"79525.30\",\"0.635\"],[\"79537.80\",\"0.000\"],[\"79541.20\",\"0.000\"],[\"79573.30\",\"0.481\"],[\"79584.90\",\"0.004\"],[\"79588.00\",\"0.004\"],[\"79588.10\",\"0.077\"],[\"79588.30\",\"0.003\"],[\"79588.40\",\"0.000\"],[\"79588.50\",\"0.114\"],[\"79588.60\",\"0.000\"],[\"79588.70\",\"0.002\"],[\"79588.80\",\"1.264\"],[\"79592.10\",\"0.002\"],[\"79592.30\",\"0.000\"],[\"79594.50\",\"0.028\"],[\"79595.40\",\"0.028\"],[\"79596.20\",\"0.000\"],[\"79596.80\",\"0.165\"],[\"79597.00\",\"4.250\"]],\"a\":[[\"79610.40\",\"0.562\"],[\"79610.70\",\"0.106\"],[\"79613.20\",\"0.002\"],[\"79616.60\",\"0.051\"],[\"79616.80\",\"0.375\"],[\"79617.10\",\"0.000\"],[\"79626.60\",\"0.005\"],[\"79631.10\",\"0.062\"],[\"79631.70\",\"0.000\"],[\"79644.10\",\"0.003\"],[\"79644.50\",\"0.000\"],[\"79645.00\",\"0.127\"],[\"79668.80\",\"0.034\"],[\"79692.70\",\"0.001\"],[\"79719.50\",\"0.515\"],[\"80219.70\",\"0.357\"],[\"80393.10\",\"109.371\"],[\"80513.30\",\"9.027\"],[\"81189.00\",\"10.543\"]],\"st\":1}}"}
{"receive_ns":1788567730451162000,"stream":"btcusdt@depth@100ms","event_type":"depthUpdate","event_time_ms":1788567730467,"raw_json":"{\"stream\":\"btcusdt@depth@100ms\",\"data\":{\"e\":\"depthUpdate\",\"E\":1788567730467,\"T\":1788567730466,\"s\":\"BTCUSDT\",\"ps\":\"BTCUSDT\",\"U\":11478508334534,\"u\":11478508341404,\"pu\":11478508334507,\"b\":[[\"1000.00\",\"24.604\"],[\"29097.00\",\"1.491\"],[\"29497.00\",\"0.609\"],[\"71637.30\",\"0.043\"],[\"75617.10\",\"0.028\"],[\"75617.20\",\"0.008\"],[\"76413.10\",\"0.000\"],[\"78429.00\",\"0.009\"],[\"78650.90\",\"0.635\"],[\"78801.00\",\"13.624\"],[\"78946.20\",\"0.253\"],[\"79565.80\",\"0.000\"],[\"79566.30\",\"0.433\"],[\"79566.40\",\"0.126\"],[\"79567.10\",\"0.001\"],[\"79584.80\",\"0.005\"],[\"79584.90\",\"1.256\"],[\"79585.00\",\"0.035\"],[\"79588.00\",\"0.386\"],[\"79588.10\",\"0.097\"],[\"79588.80\",\"0.002\"],[\"79589.10\",\"0.101\"]],\"a\":[[\"79603.50\",\"0.016\"],[\"79610.40\",\"0.123\"],[\"79610.70\",\"0.545\"],[\"80393.10\",\"109.371\"],[\"80525.70\",\"0.633\"],[\"80565.50\",\"0.720\"],[\"80951.80\",\"1.481\"]],\"st\":1}}"}
{"receive_ns":1788567730480144000,"stream":"btcusdt@bookTicker","event_type":"bookTicker","event_time_ms":1788567730489,"raw_json":"{\"stream\":\"btcusdt@bookTicker\",\"data\":{\"e\":\"bookTicker\",\"u\":11478508343121,\"s\":\"BTCUSDT\",\"ps\":\"BTCUSDT\",\"b\":\"79597.00\",\"B\":\"4.250\",\"a\":\"79597.10\",\"A\":\"6.337\",\"T\":1788567730489,\"E\":1788567730489,\"st\":1}}"}
{"receive_ns":1788567730496723000,"stream":"btcusdt@bookTicker","event_type":"bookTicker","event_time_ms":1788567730490,"raw_json":"{\"stream\":\"btcusdt@bookTicker\",\"data\":{\"e\":\"bookTicker\",\"u\":11478508343240,\"s\":\"BTCUSDT\",\"ps\":\"BTCUSDT\",\"b\":\"79597.00\",\"B\":\"4.251\",\"a\":\"79597.10\",\"A\":\"6.337\",\"T\":1788567730490,\"E\":1788567730490,\"st\":1}}"}
{"receive_ns":1788567730505471000,"stream":"btcusdt@bookTicker","event_type":"bookTicker","event_time_ms":1788567730505,"raw_json":"{\"stream\":\"btcusdt@bookTicker\",\"data\":{\"e\":\"bookTicker\",\"u\":11478508344198,\"s\":\"BTCUSDT\",\"ps\":\"BTCUSDT\",\"b\":\"79597.00\",\"B\":\"4.251\",\"a\":\"79597.10\",\"A\":\"6.338\",\"T\":1788567730505,\"E\":1788567730505,\"st\":1}}"}
{"receive_ns":1788567730519957000,"stream":"btcusdt@bookTicker","event_type":"bookTicker","event_time_ms":1788567730537,"raw_json":"{\"stream\":\"btcusdt@bookTicker\",\"data\":{\"e\":\"bookTicker\",\"u\":11478508347013,\"s\":\"BTCUSDT\",\"ps\":\"BTCUSDT\",\"b\":\"79597.00\",\"B\":\"4.208\",\"a\":\"79597.10\",\"A\":\"6.338\",\"T\":1788567730536,\"E\":1788567730537,\"st\":1}}"}
{"receive_ns":1788567730525410000,"stream":"btcusdt@bookTicker","event_type":"bookTicker","event_time_ms":1788567730539,"raw_json":"{\"stream\":\"btcusdt@bookTicker\",\"data\":{\"e\":\"bookTicker\",\"u\":11478508347201,\"s\":\"BTCUSDT\",\"ps\":\"BTCUSDT\",\"b\":\"79597.00\",\"B\":\"4.256\",\"a\":\"79597.10\",\"A\":\"6.338\",\"T\":1788567730539,\"E\":1788567730539,\"st\":1}}"}
{"receive_ns":1788567730552017000,"stream":"btcusdt@depth@100ms","event_type":"depthUpdate","event_time_ms":1788567730569,"raw_json":"{\"stream\":\"btcusdt@depth@100ms\",\"data\":{\"e\":\"depthUpdate\",\"E\":1788567730569,\"T\":1788567730567,\"s\":\"BTCUSDT\",\"ps\":\"BTCUSDT\",\"U\":11478508341516,\"u\":11478508348507,\"pu\":11478508341404,\"b\":[[\"29097.00\",\"1.316\"],[\"29497.00\",\"0.784\"],[\"71637.30\",\"0.043\"],[\"76413.10\",\"0.002\"],[\"78385.60\",\"3.435\"],[\"78426.90\",\"5.597\"],[\"78801.00\",\"13.624\"],[\"79199.00\",\"4.875\"],[\"79475.50\",\"0.529\"],[\"79521.50\",\"0.016\"],[\"79529.70\",\"0.034\"],[\"79566.10\",\"0.128\"],[\"79566.40\",\"0.001\"],[\"79585.00\",\"0.035\"],[\"79588.00\",\"0.394\"],[\"79588.10\",\"0.089\"],[\"79594.60\",\"0.027\"],[\"79597.00\",\"4.256\"]],\"a\":[[\"79597.10\",\"6.338\"],[\"79719.50\",\"0.515\"],[\"79995.10\",\"4.241\"],[\"80233.90\",\"8.334\"],[\"80313.50\",\"5.852\"],[\"80393.10\",\"109.371\"],[\"80513.30\",\"9.771\"],[\"80617.70\",\"0.878\"]],\"st\":1}}"}
{"receive_ns":1788567730637067000,"stream":"btcusdt@bookTicker","event_type":"bookTicker","event_time_ms":1788567730652,"raw_json":"{\"stream\":\"btcusdt@bookTicker\",\"data\":{\"e\":\"bookTicker\",\"u\":11478508353254,\"s\":\"BTCUSDT\",\"ps\":\"BTCUSDT\",\"b\":\"79597.00\",\"B\":\"4.206\",\"a\":\"79597.10\",\"A\":\"6.338\",\"T\":1788567730652,\"E\":1788567730652,\"st\":1}}"}
{"receive_ns":1788567730648396000,"stream":"btcusdt@bookTicker","event_type":"bookTicker","event_time_ms":1788567730655,"raw_json":"{\"stream\":\"btcusdt@bookTicker\",\"data\":{\"e\":\"bookTicker\",\"u\":11478508353443,\"s\":\"BTCUSDT\",\"ps\":\"BTCUSDT\",\"b\":\"79597.00\",\"B\":\"4.255\",\"a\":\"79597.10\",\"A\":\"6.338\",\"T\":1788567730655,\"E\":1788567730655,\"st\":1}}"}
{"receive_ns":1788567730660725000,"stream":"btcusdt@depth@100ms","event_type":"depthUpdate","event_time_ms":1788567730671,"raw_json":"{\"stream\":\"btcusdt@depth@100ms\",\"data\":{\"e\":\"depthUpdate\",\"E\":1788567730671,\"T\":1788567730670,\"s\":\"BTCUSDT\",\"ps\":\"BTCUSDT\",\"U\":11478508348617,\"u\":11478508354241,\"pu\":11478508348507,\"b\":[[\"1000.00\",\"24.754\"],[\"29097.00\",\"1.134\"],[\"29497.00\",\"0.966\"],[\"63678.00\",\"0.000\"],[\"71637.30\",\"0.043\"],[\"76413.10\",\"0.000\"],[\"78392.90\",\"0.233\"],[\"78641.80\",\"34.276\"],[\"78801.00\",\"13.624\"],[\"78960.20\",\"8.760\"],[\"79199.00\",\"4.865\"],[\"79475.50\",\"0.000\"],[\"79521.50\",\"0.002\"],[\"79530.30\",\"0.017\"],[\"79588.00\",\"0.390\"],[\"79588.10\",\"0.093\"],[\"79593.50\",\"0.000\"],[\"79595.60\",\"0.038\"],[\"79595.90\",\"0.028\"],[\"79596.20\",\"0.000\"],[\"79596.40\",\"0.002\"],[\"79597.00\",\"4.255\"]],\"a\":[[\"79719.50\",\"0.030\"],[\"80393.10\",\"109.371\"],[\"80513.30\",\"10.515\"],[\"80628.60\",\"1.238\"]],\"st\":1}}"}
{"receive_ns":1788567730749327000,"stream":"btcusdt@bookTicker","event_type":"bookTicker","event_time_ms":1788567730766,"raw_json":"{\"stream\":\"btcusdt@bookTicker\",\"data\":{\"e\":\"bookTicker\",\"u\":11478508360015,\"s\":\"BTCUSDT\",\"ps\":\"BTCUSDT\",\"b\":\"79597.00\",\"B\":\"4.255\",\"a\":\"79597.10\",\"A\":\"6.322\",\"T\":1788567730766,\"E\":1788567730766,\"st\":1}}"}
{"receive_ns":1788567730749576000,"stream":"btcusdt@bookTicker","event_type":"bookTicker","event_time_ms":1788567730766,"raw_json":"{\"stream\":\"btcusdt@bookTicker\",\"data\":{\"e\":\"bookTicker\",\"u\":11478508360023,\"s\":\"BTCUSDT\",\"ps\":\"BTCUSDT\",\"b\":\"79597.00\",\"B\":\"4.255\",\"a\":\"79597.10\",\"A\":\"6.305\",\"T\":1788567730766,\"E\":1788567730766,\"st\":1}}"}
{"receive_ns":1788567730764579000,"stream":"btcusdt@bookTicker","event_type":"bookTicker","event_time_ms":1788567730770,"raw_json":"{\"stream\":\"btcusdt@bookTicker\",\"data\":{\"e\":\"bookTicker\",\"u\":11478508360249,\"s\":\"BTCUSDT\",\"ps\":\"BTCUSDT\",\"b\":\"79597.00\",\"B\":\"4.253\",\"a\":\"79597.10\",\"A\":\"6.305\",\"T\":1788567730769,\"E\":1788567730770,\"st\":1}}"}
{"receive_ns":1788567730770072000,"stream":"btcusdt@trade","event_type":"trade","event_time_ms":1788567730770,"raw_json":"{\"stream\":\"btcusdt@trade\",\"data\":{\"e\":\"trade\",\"E\":1788567730770,\"T\":1788567730769,\"s\":\"BTCUSDT\",\"t\":8054122625,\"p\":\"79597.00\",\"q\":\"0.002\",\"X\":\"MARKET\",\"m\":true,\"st\":1}}"}
{"receive_ns":1788567730781357000,"stream":"btcusdt@depth@100ms","event_type":"depthUpdate","event_time_ms":1788567730773,"raw_json":"{\"stream\":\"btcusdt@depth@100ms\",\"data\":{\"e\":\"depthUpdate\",\"E\":1788567730773,\"T\":1788567730772,\"s\":\"BTCUSDT\",\"ps\":\"BTCUSDT\",\"U\":11478508354278,\"u\":11478508360415,\"pu\":11478508354241,\"b\":[[\"1000.00\",\"24.604\"],[\"29097.00\",\"0.959\"],[\"29497.00\",\"1.141\"],[\"63678.00\",\"0.000\"],[\"71637.30\",\"0.043\"],[\"78466.70\",\"2.754\"],[\"78801.00\",\"13.626\"],[\"79199.00\",\"4.866\"],[\"79475.50\",\"0.529\"],[\"79505.60\",\"0.000\"],[\"79566.10\",\"0.003\"],[\"79566.20\",\"0.127\"],[\"79594.00\",\"0.000\"],[\"79594.50\",\"0.026\"],[\"79594.60\",\"0.041\"],[\"79596.00\",\"0.108\"],[\"79596.80\",\"0.167\"],[\"79597.00\",\"4.253\"]],\"a\":[[\"79597.10\",\"6.305\"],[\"79597.50\",\"0.040\"],[\"79597.70\",\"0.146\"],[\"79628.40\",\"0.120\"],[\"79644.10\",\"0.128\"],[\"79645.00\",\"0.002\"],[\"79660.30\",\"4.993\"],[\"79663.40\",\"0.000\"],[\"79671.50\",\"21.948\"],[\"79688.10\",\"0.024\"],[\"79719.50\",\"0.515\"],[\"79804.90\",\"0.776\"],[\"79995.10\",\"4.242\"],[\"80393.10\",\"109.371\"],[\"80632.00\",\"1.734\"]],\"st\":1}}"}
{"receive_ns":1788567730796486000,"stream":"btcusdt@bookTicker","event_type":"bookTicker","event_time_ms":1788567730812,"raw_json":"{\"stream\":\"btcusdt@bookTicker\",\"data\":{\"e\":\"bookTicker\",\"u\":11478508363167,\"s\":\"BTCUSDT\",\"ps\":\"BTCUSDT\",\"b\":\"79597.00\",\"B\":\"4.253\",\"a\":\"79597.10\",\"A\":\"6.303\",\"T\":1788567730811,\"E\":1788567730812,\"st\":1}}"}
{"receive_ns":1788567730858592000,"stream":"btcusdt@depth@100ms","event_type":"depthUpdate","event_time_ms":1788567730875,"raw_json":"{\"stream\":\"btcusdt@depth@100ms\",\"data\":{\"e\":\"depthUpdate\",\"E\":1788567730875,\"T\":1788567730874,\"s\":\"BTCUSDT\",\"ps\":\"BTCUSDT\",\"U\":11478508360424,\"u\":11478508366822,\"pu\":11478508360415,\"b\":[[\"29097.00\",\"0.777\"],[\"29497.00\",\"1.323\"],[\"71637.30\",\"0.043\"],[\"75617.20\",\"0.006\"],[\"76413.10\",\"0.002\"],[\"78421.00\",\"0.632\"],[\"78801.00\",\"13.624\"],[\"79199.00\",\"4.876\"],[\"79505.80\",\"4.691\"],[\"79590.80\",\"0.001\"],[\"79595.90\",\"0.002\"],[\"79596.00\",\"0.082\"]],\"a\":[[\"79597.10\",\"6.303\"],[\"79644.10\",\"0.003\"],[\"79644.50\",\"0.125\"],[\"79660.30\",\"1.977\"],[\"79666.10\",\"21.862\"],[\"79671.50\",\"0.000\"],[\"79688.10\",\"3.433\"],[\"79818.90\",\"6.840\"]],\"st\":1}}"}
{"receive_ns":1788567730894843000,"stream":"btcusdt@bookTicker","event_type":"bookTicker","event_time_ms":1788567730908,"raw_json":"{\"stream\":\"btcusdt@bookTicker\",\"data\":{\"e\":\"bookTicker\",\"u\":11478508371531,\"s\":\"BTCUSDT\",\"ps\":\"BTCUSDT\",\"b\":\"79597.00\",\"B\":\"4.253\",\"a\":\"79597.10\",\"A\":\"6.302\",\"T\":1788567730908,\"E\":1788567730908,\"st\":1}}"}
{"receive_ns":1788567730900371000,"stream":"btcusdt@trade","event_type":"trade","event_time_ms":1788567730908,"raw_json":"{\"stream\":\"btcusdt@trade\",\"data\":{\"e\":\"trade\",\"E\":1788567730908,\"T\":1788567730908,\"s\":\"BTCUSDT\",\"t\":8054122626,\"p\":\"79597.10\",\"q\":\"0.001\",\"X\":\"MARKET\",\"m\":false,\"st\":1}}"}
{"receive_ns":1788567730916916000,"stream":"btcusdt@bookTicker","event_type":"bookTicker","event_time_ms":1788567730926,"raw_json":"{\"stream\":\"btcusdt@bookTicker\",\"data\":{\"e\":\"bookTicker\",\"u\":11478508373754,\"s\":\"BTCUSDT\",\"ps\":\"BTCUSDT\",\"b\":\"79597.00\",\"B\":\"4.254\",\"a\":\"79597.10\",\"A\":\"6.302\",\"T\":1788567730926,\"E\":1788567730926,\"st\":1}}"}
{"receive_ns":1788567730958817000,"stream":"btcusdt@depth@100ms","event_type":"depthUpdate","event_time_ms":1788567730977,"raw_json":"{\"stream\":\"btcusdt@depth@100ms\",\"data\":{\"e\":\"depthUpdate\",\"E\":1788567730977,\"T\":1788567730975,\"s\":\"BTCUSDT\",\"ps\":\"BTCUSDT\",\"U\":11478508366882,\"u\":11478508376848,\"pu\":11478508366822,\"b\":[[\"1000.00\",\"24.604\"],[\"29097.00\",\"0.602\"],[\"29497.00\",\"1.498\"],[\"63678.00\",\"0.002\"],[\"71637.30\",\"0.043\"],[\"71673.00\",\"0.003\"],[\"76413.10\",\"0.000\"],[\"78801.00\",\"13.624\"],[\"79475.50\",\"0.512\"],[\"79485.50\",\"13.199\"],[\"79576.10\",\"0.637\"],[\"79576.40\",\"0.001\"],[\"79584.80\",\"0.381\"],[\"79584.90\",\"0.004\"],[\"79588.00\",\"0.010\"],[\"79588.10\",\"0.081\"],[\"79588.20\",\"0.001\"],[\"79588.30\",\"0.003\"],[\"79588.40\",\"0.012\"],[\"79588.50\",\"1.370\"],[\"79592.00\",\"0.009\"],[\"79592.10\",\"0.000\"],[\"79592.20\",\"0.000\"],[\"79593.10\",\"0.047\"],[\"79593.20\",\"0.026\"],[\"79593.30\",\"0.026\"],[\"79593.40\",\"0.027\"],[\"79593.50\",\"0.026\"],[\"79593.60\",\"0.029\"],[\"79593.80\",\"0.029\"],[\"79593.90\",\"0.026\"],[\"79594.00\",\"0.000\"],[\"79594.10\",\"0.002\"],[\"79594.20\",\"0.000\"],[\"79594.30\",\"0.058\"],[\"79594.50\",\"0.000\"],[\"79594.60\",\"0.015\"],[\"79595.20\",\"0.000\"],[\"79595.40\",\"0.002\"],[\"79595.60\",\"0.012\"],[\"79597.00\",\"4.254\"]],\"a\":[[\"79597.10\",\"6.302\"],[\"79605.40\",\"0.080\"],[\"79608.00\",\"0.012\"],[\"79608.10\",\"0.003\"],[\"79616.30\",\"0.641\"],[\"79624.10\",\"0.001\"],[\"79644.50\",\"0.000\"],[\"79719.50\",\"0.497\"],[\"79806.70\",\"2.805\"],[\"80393.10\",\"109.297\"],[\"80577.80\",\"2.194\"],[\"80617.70\",\"0.011\"]],\"st\":1}}"}
{"receive_ns":1788567730964466000,"stream":"btcusdt@bookTicker","event_type":"bookTicker","event_time_ms":1788567730982,"raw_json":"{\"stream\":\"btcusdt@bookTicker\",\"data\":{\"e\":\"bookTicker\",\"u\":11478508377498,\"s\":\"BTCUSDT\",\"ps\":\"BTCUSDT\",\"b\":\"79597.00\",\"B\":\"4.125\",\"a\":\"79597.10\",\"A\":\"6.302\",\"T\":1788567730981,\"E\":1788567730982,\"st\":1}}"}
{"receive_ns":1788567730970173000,"stream":"btcusdt@bookTicker","event_type":"bookTicker","event_time_ms":1788567730985,"raw_json":"{\"stream\":\"btcusdt@bookTicker\",\"data\":{\"e\":\"bookTicker\",\"u\":11478508377780,\"s\":\"BTCUSDT\",\"ps\":\"BTCUSDT\",\"b\":\"79597.00\",\"B\":\"4.255\",\"a\":\"79597.10\",\"A\":\"6.302\",\"T\":1788567730985,\"E\":1788567730985,\"st\":1}}"}
{"receive_ns":1788567730981242000,"stream":"btcusdt@trade","event_type":"trade","event_time_ms":1788567730985,"raw_json":"{\"stream\":\"btcusdt@trade\",\"data\":{\"e\":\"trade\",\"E\":1788567730985,\"T\":1788567730985,\"s\":\"BTCUSDT\",\"t\":8054122627,\"p\":\"79597.00\",\"q\":\"0.016\",\"X\":\"MARKET\",\"m\":true,\"st\":1}}"}
{"receive_ns":1788567730987000000,"stream":"btcusdt@trade","event_type":"trade","event_time_ms":1788567730985,"raw_json":"{\"stream\":\"btcusdt@trade\",\"data\":{\"e\":\"trade\",\"E\":1788567730985,\"T\":1788567730985,\"s\":\"BTCUSDT\",\"t\":8054122628,\"p\":\"79597.00\",\"q\":\"0.001\",\"X\":\"MARKET\",\"m\":true,\"st\":1}}"}
{"receive_ns":1788567730987202000,"stream":"btcusdt@trade","event_type":"trade","event_time_ms":1788567730985,"raw_json":"{\"stream\":\"btcusdt@trade\",\"data\":{\"e\":\"trade\",\"E\":1788567730985,\"T\":1788567730985,\"s\":\"BTCUSDT\",\"t\":8054122629,\"p\":\"79597.00\",\"q\":\"0.002\",\"X\":\"MARKET\",\"m\":true,\"st\":1}}"}
{"receive_ns":1788567730987351000,"stream":"btcusdt@trade","event_type":"trade","event_time_ms":1788567730985,"raw_json":"{\"stream\":\"btcusdt@trade\",\"data\":{\"e\":\"trade\",\"E\":1788567730985,\"T\":1788567730985,\"s\":\"BTCUSDT\",\"t\":8054122630,\"p\":\"79597.00\",\"q\":\"0.011\",\"X\":\"MARKET\",\"m\":true,\"st\":1}}"}
{"receive_ns":1788567730987497000,"stream":"btcusdt@trade","event_type":"trade","event_time_ms":1788567730985,"raw_json":"{\"stream\":\"btcusdt@trade\",\"data\":{\"e\":\"trade\",\"E\":1788567730985,\"T\":1788567730985,\"s\":\"BTCUSDT\",\"t\":8054122631,\"p\":\"79597.00\",\"q\":\"0.001\",\"X\":\"MARKET\",\"m\":true,\"st\":1}}"}
{"receive_ns":1788567730997196000,"stream":"btcusdt@trade","event_type":"trade","event_time_ms":1788567730985,"raw_json":"{\"stream\":\"btcusdt@trade\",\"data\":{\"e\":\"trade\",\"E\":1788567730985,\"T\":1788567730985,\"s\":\"BTCUSDT\",\"t\":8054122632,\"p\":\"79597.00\",\"q\":\"0.001\",\"X\":\"MARKET\",\"m\":true,\"st\":1}}"}
{"receive_ns":1788567730997377000,"stream":"btcusdt@trade","event_type":"trade","event_time_ms":1788567730985,"raw_json":"{\"stream\":\"btcusdt@trade\",\"data\":{\"e\":\"trade\",\"E\":1788567730985,\"T\":1788567730985,\"s\":\"BTCUSDT\",\"t\":8054122633,\"p\":\"79597.00\",\"q\":\"0.100\",\"X\":\"MARKET\",\"m\":true,\"st\":1}}"}
{"receive_ns":1788567730997523000,"stream":"btcusdt@trade","event_type":"trade","event_time_ms":1788567730985,"raw_json":"{\"stream\":\"btcusdt@trade\",\"data\":{\"e\":\"trade\",\"E\":1788567730985,\"T\":1788567730985,\"s\":\"BTCUSDT\",\"t\":8054122634,\"p\":\"79597.00\",\"q\":\"0.002\",\"X\":\"MARKET\",\"m\":true,\"st\":1}}"}
{"receive_ns":1788567730997665000,"stream":"btcusdt@trade","event_type":"trade","event_time_ms":1788567730985,"raw_json":"{\"stream\":\"btcusdt@trade\",\"data\":{\"e\":\"trade\",\"E\":1788567730985,\"T\":1788567730985,\"s\":\"BTCUSDT\",\"t\":8054122635,\"p\":\"79597.00\",\"q\":\"0.021\",\"X\":\"MARKET\",\"m\":true,\"st\":1}}"}
{"receive_ns":1788567731003497000,"stream":"btcusdt@trade","event_type":"trade","event_time_ms":1788567730985,"raw_json":"{\"stream\":\"btcusdt@trade\",\"data\":{\"e\":\"trade\",\"E\":1788567730985,\"T\":1788567730985,\"s\":\"BTCUSDT\",\"t\":8054122636,\"p\":\"79597.00\",\"q\":\"0.021\",\"X\":\"MARKET\",\"m\":true,\"st\":1}}"}
{"receive_ns":1788567731009837000,"stream":"btcusdt@trade","event_type":"trade","event_time_ms":1788567730985,"raw_json":"{\"stream\":\"btcusdt@trade\",\"data\":{\"e\":\"trade\",\"E\":1788567730985,\"T\":1788567730985,\"s\":\"BTCUSDT\",\"t\":8054122637,\"p\":\"79597.00\",\"q\":\"0.021\",\"X\":\"MARKET\",\"m\":true,\"st\":1}}"}
{"receive_ns":1788567731015423000,"stream":"btcusdt@trade","event_type":"trade","event_time_ms":1788567730985,"raw_json":"{\"stream\":\"btcusdt@trade\",\"data\":{\"e\":\"trade\",\"E\":1788567730985,\"T\":1788567730985,\"s\":\"BTCUSDT\",\"t\":8054122638,\"p\":\"79597.00\",\"q\":\"0.021\",\"X\":\"MARKET\",\"m\":true,\"st\":1}}"}
{"receive_ns":1788567731021278000,"stream":"btcusdt@trade","event_type":"trade","event_time_ms":1788567730985,"raw_json":"{\"stream\":\"btcusdt@trade\",\"data\":{\"e\":\"trade\",\"E\":1788567730985,\"T\":1788567730985,\"s\":\"BTCUSDT\",\"t\":8054122639,\"p\":\"79597.00\",\"q\":\"0.105\",\"X\":\"MARKET\",\"m\":true,\"st\":1}}"}
{"receive_ns":1788567731026604000,"stream":"btcusdt@trade","event_type":"trade","event_time_ms":1788567730985,"raw_json":"{\"stream\":\"btcusdt@trade\",\"data\":{\"e\":\"trade\",\"E\":1788567730985,\"T\":1788567730985,\"s\":\"BTCUSDT\",\"t\":8054122640,\"p\":\"79597.00\",\"q\":\"0.111\",\"X\":\"MARKET\",\"m\":true,\"st\":1}}"}
{"receive_ns":1788567731035638000,"stream":"btcusdt@trade","event_type":"trade","event_time_ms":1788567730985,"raw_json":"{\"stream\":\"btcusdt@trade\",\"data\":{\"e\":\"trade\",\"E\":1788567730985,\"T\":1788567730985,\"s\":\"BTCUSDT\",\"t\":8054122641,\"p\":\"79597.00\",\"q\":\"0.138\",\"X\":\"MARKET\",\"m\":true,\"st\":1}}"}
{"receive_ns":1788567731041048000,"stream":"btcusdt@trade","event_type":"trade","event_time_ms":1788567730985,"raw_json":"{\"stream\":\"btcusdt@trade\",\"data\":{\"e\":\"trade\",\"E\":1788567730985,\"T\":1788567730985,\"s\":\"BTCUSDT\",\"t\":8054122642,\"p\":\"79597.00\",\"q\":\"0.018\",\"X\":\"MARKET\",\"m\":true,\"st\":1}}"}
{"receive_ns":1788567731047760000,"stream":"btcusdt@trade","event_type":"trade","event_time_ms":1788567730985,"raw_json":"{\"stream\":\"btcusdt@trade\",\"data\":{\"e\":\"trade\",\"E\":1788567730985,\"T\":1788567730985,\"s\":\"BTCUSDT\",\"t\":8054122643,\"p\":\"79597.00\",\"q\":\"0.155\",\"X\":\"MARKET\",\"m\":true,\"st\":1}}"}
{"receive_ns":1788567731053944000,"stream":"btcusdt@trade","event_type":"trade","event_time_ms":1788567730986,"raw_json":"{\"stream\":\"btcusdt@trade\",\"data\":{\"e\":\"trade\",\"E\":1788567730986,\"T\":1788567730985,\"s\":\"BTCUSDT\",\"t\":8054122644,\"p\":\"79597.00\",\"q\":\"0.001\",\"X\":\"MARKET\",\"m\":true,\"st\":1}}"}
{"receive_ns":1788567731060255000,"stream":"btcusdt@trade","event_type":"trade","event_time_ms":1788567730986,"raw_json":"{\"stream\":\"btcusdt@trade\",\"data\":{\"e\":\"trade\",\"E\":1788567730986,\"T\":1788567730985,\"s\":\"BTCUSDT\",\"t\":8054122645,\"p\":\"79597.00\",\"q\":\"0.023\",\"X\":\"MARKET\",\"m\":true,\"st\":1}}"}
{"receive_ns":1788567731066073000,"stream":"btcusdt@trade","event_type":"trade","event_time_ms":1788567730986,"raw_json":"{\"stream\":\"btcusdt@trade\",\"data\":{\"e\":\"trade\",\"E\":1788567730986,\"T\":1788567730985,\"s\":\"BTCUSDT\",\"t\":8054122646,\"p\":\"79597.00\",\"q\":\"0.314\",\"X\":\"MARKET\",\"m\":true,\"st\":1}}"}
{"receive_ns":1788567731067089000,"stream":"btcusdt@trade","event_type":"trade","event_time_ms":1788567730986,"raw_json":"{\"stream\":\"btcusdt@trade\",\"data\":{\"e\":\"trade\",\"E\":1788567730986,\"T\":1788567730985,\"s\":\"BTCUSDT\",\"t\":8054122647,\"p\":\"79597.00\",\"q\":\"0.007\",\"X\":\"MARKET\",\"m\":true,\"st\":1}}"}
{"receive_ns":1788567731078869000,"stream":"btcusdt@trade","event_type":"trade","event_time_ms":1788567730986,"raw_json":"{\"stream\":\"btcusdt@trade\",\"data\":{\"e\":\"trade\",\"E\":1788567730986,\"T\":1788567730985,\"s\":\"BTCUSDT\",\"t\":8054122648,\"p\":\"79597.00\",\"q\":\"0.005\",\"X\":\"MARKET\",\"m\":true,\"st\":1}}"}
{"receive_ns":1788567731085468000,"stream":"btcusdt@trade","event_type":"trade","event_time_ms":1788567730986,"raw_json":"{\"stream\":\"btcusdt@trade\",\"data\":{\"e\":\"trade\",\"E\":1788567730986,\"T\":1788567730985,\"s\":\"BTCUSDT\",\"t\":8054122649,\"p\":\"79597.00\",\"q\":\"0.003\",\"X\":\"MARKET\",\"m\":true,\"st\":1}}"}
{"receive_ns":1788567731092085000,"stream":"btcusdt@trade","event_type":"trade","event_time_ms":1788567730986,"raw_json":"{\"stream\":\"btcusdt@trade\",\"data\":{\"e\":\"trade\",\"E\":1788567730986,\"T\":1788567730985,\"s\":\"BTCUSDT\",\"t\":8054122650,\"p\":\"79597.00\",\"q\":\"0.003\",\"X\":\"MARKET\",\"m\":true,\"st\":1}}"}
{"receive_ns":1788567731097592000,"stream":"btcusdt@trade","event_type":"trade","event_time_ms":1788567730986,"raw_json":"{\"stream\":\"btcusdt@trade\",\"data\":{\"e\":\"trade\",\"E\":1788567730986,\"T\":1788567730985,\"s\":\"BTCUSDT\",\"t\":8054122651,\"p\":\"79597.00\",\"q\":\"0.216\",\"X\":\"MARKET\",\"m\":true,\"st\":1}}"}
{"receive_ns":1788567731103544000,"stream":"btcusdt@trade","event_type":"trade","event_time_ms":1788567730986,"raw_json":"{\"stream\":\"btcusdt@trade\",\"data\":{\"e\":\"trade\",\"E\":1788567730986,\"T\":1788567730985,\"s\":\"BTCUSDT\",\"t\":8054122652,\"p\":\"79597.00\",\"q\":\"0.007\",\"X\":\"MARKET\",\"m\":true,\"st\":1}}"}
{"receive_ns":1788567731113434000,"stream":"btcusdt@trade","event_type":"trade","event_time_ms":1788567730986,"raw_json":"{\"stream\":\"btcusdt@trade\",\"data\":{\"e\":\"trade\",\"E\":1788567730986,\"T\":1788567730985,\"s\":\"BTCUSDT\",\"t\":8054122653,\"p\":\"79597.00\",\"q\":\"0.001\",\"X\":\"MARKET\",\"m\":true,\"st\":1}}"}
{"receive_ns":1788567731118958000,"stream":"btcusdt@trade","event_type":"trade","event_time_ms":1788567730986,"raw_json":"{\"stream\":\"btcusdt@trade\",\"data\":{\"e\":\"trade\",\"E\":1788567730986,\"T\":1788567730985,\"s\":\"BTCUSDT\",\"t\":8054122654,\"p\":\"79597.00\",\"q\":\"0.038\",\"X\":\"MARKET\",\"m\":true,\"st\":1}}"}
{"receive_ns":1788567731125303000,"stream":"btcusdt@trade","event_type":"trade","event_time_ms":1788567730986,"raw_json":"{\"stream\":\"btcusdt@trade\",\"data\":{\"e\":\"trade\",\"E\":1788567730986,\"T\":1788567730985,\"s\":\"BTCUSDT\",\"t\":8054122655,\"p\":\"79597.00\",\"q\":\"0.002\",\"X\":\"MARKET\",\"m\":true,\"st\":1}}"}
{"receive_ns":1788567731131514000,"stream":"btcusdt@trade","event_type":"trade","event_time_ms":1788567730986,"raw_json":"{\"stream\":\"btcusdt@trade\",\"data\":{\"e\":\"trade\",\"E\":1788567730986,\"T\":1788567730985,\"s\":\"BTCUSDT\",\"t\":8054122656,\"p\":\"79597.00\",\"q\":\"0.586\",\"X\":\"MARKET\",\"m\":true,\"st\":1}}"}
{"receive_ns":1788567731136902000,"stream":"btcusdt@trade","event_type":"trade","event_time_ms":1788567730986,"raw_json":"{\"stream\":\"btcusdt@trade\",\"data\":{\"e\":\"trade\",\"E\":1788567730986,\"T\":1788567730985,\"s\":\"BTCUSDT\",\"t\":8054122657,\"p\":\"79597.00\",\"q\":\"0.439\",\"X\":\"MARKET\",\"m\":true,\"st\":1}}"}
{"receive_ns":1788567731143470000,"stream":"btcusdt@trade","event_type":"trade","event_time_ms":1788567730986,"raw_json":"{\"stream\":\"btcusdt@trade\",\"data\":{\"e\":\"trade\",\"E\":1788567730986,\"T\":1788567730985,\"s\":\"BTCUSDT\",\"t\":8054122658,\"p\":\"79597.00\",\"q\":\"0.002\",\"X\":\"MARKET\",\"m\":true,\"st\":1}}"}
{"receive_ns":1788567731148870000,"stream":"btcusdt@trade","event_type":"trade","event_time_ms":1788567730986,"raw_json":"{\"stream\":\"btcusdt@trade\",\"data\":{\"e\":\"trade\",\"E\":1788567730986,\"T\":1788567730985,\"s\":\"BTCUSDT\",\"t\":8054122659,\"p\":\"79597.00\",\"q\":\"0.045\",\"X\":\"MARKET\",\"m\":true,\"st\":1}}"}
{"receive_ns":1788567731157771000,"stream":"btcusdt@trade","event_type":"trade","event_time_ms":1788567730986,"raw_json":"{\"stream\":\"btcusdt@trade\",\"data\":{\"e\":\"trade\",\"E\":1788567730986,\"T\":1788567730985,\"s\":\"BTCUSDT\",\"t\":8054122660,\"p\":\"79597.00\",\"q\":\"0.002\",\"X\":\"MARKET\",\"m\":true,\"st\":1}}"}
{"receive_ns":1788567731163756000,"stream":"btcusdt@trade","event_type":"trade","event_time_ms":1788567730986,"raw_json":"{\"stream\":\"btcusdt@trade\",\"data\":{\"e\":\"trade\",\"E\":1788567730986,\"T\":1788567730985,\"s\":\"BTCUSDT\",\"t\":8054122661,\"p\":\"79597.00\",\"q\":\"0.060\",\"X\":\"MARKET\",\"m\":true,\"st\":1}}"}
{"receive_ns":1788567731169412000,"stream":"btcusdt@trade","event_type":"trade","event_time_ms":1788567730986,"raw_json":"{\"stream\":\"btcusdt@trade\",\"data\":{\"e\":\"trade\",\"E\":1788567730986,\"T\":1788567730985,\"s\":\"BTCUSDT\",\"t\":8054122662,\"p\":\"79597.00\",\"q\":\"0.072\",\"X\":\"MARKET\",\"m\":true,\"st\":1}}"}
{"receive_ns":1788567731176033000,"stream":"btcusdt@trade","event_type":"trade","event_time_ms":1788567730986,"raw_json":"{\"stream\":\"btcusdt@trade\",\"data\":{\"e\":\"trade\",\"E\":1788567730986,\"T\":1788567730985,\"s\":\"BTCUSDT\",\"t\":8054122663,\"p\":\"79597.00\",\"q\":\"0.019\",\"X\":\"MARKET\",\"m\":true,\"st\":1}}"}
{"receive_ns":1788567731182663000,"stream":"btcusdt@trade","event_type":"trade","event_time_ms":1788567730986,"raw_json":"{\"stream\":\"btcusdt@trade\",\"data\":{\"e\":\"trade\",\"E\":1788567730986,\"T\":1788567730985,\"s\":\"BTCUSDT\",\"t\":8054122664,\"p\":\"79597.00\",\"q\":\"0.082\",\"X\":\"MARKET\",\"m\":true,\"st\":1}}"}
{"receive_ns":1788567731188969000,"stream":"btcusdt@trade","event_type":"trade","event_time_ms":1788567730986,"raw_json":"{\"stream\":\"btcusdt@trade\",\"data\":{\"e\":\"trade\",\"E\":1788567730986,\"T\":1788567730985,\"s\":\"BTCUSDT\",\"t\":8054122665,\"p\":\"79597.00\",\"q\":\"0.001\",\"X\":\"MARKET\",\"m\":true,\"st\":1}}"}
{"receive_ns":1788567731206072000,"stream":"btcusdt@bookTicker","event_type":"bookTicker","event_time_ms":1788567730986,"raw_json":"{\"stream\":\"btcusdt@bookTicker\",\"data\":{\"e\":\"bookTicker\",\"u\":11478508377946,\"s\":\"BTCUSDT\",\"ps\":\"BTCUSDT\",\"b\":\"79596.90\",\"B\":\"2.634\",\"a\":\"79597.00\",\"A\":\"1.059\",\"T\":1788567730985,\"E\":1788567730986,\"st\":1}}"}
{"receive_ns":1788567731206390000,"stream":"btcusdt@bookTicker","event_type":"bookTicker","event_time_ms":1788567730986,"raw_json":"{\"stream\":\"btcusdt@bookTicker\",\"data\":{\"e\":\"bookTicker\",\"u\":11478508377951,\"s\":\"BTCUSDT\",\"ps\":\"BTCUSDT\",\"b\":\"79596.90\",\"B\":\"2.634\",\"a\":\"79597.00\",\"A\":\"2.543\",\"T\":1788567730985,\"E\":1788567730986,\"st\":1}}"}
{"receive_ns":1788567731206699000,"stream":"btcusdt@bookTicker","event_type":"bookTicker","event_time_ms":1788567730986,"raw_json":"{\"stream\":\"btcusdt@bookTicker\",\"data\":{\"e\":\"bookTicker\",\"u\":11478508377983,\"s\":\"BTCUSDT\",\"ps\":\"BTCUSDT\",\"b\":\"79596.90\",\"B\":\"2.634\",\"a\":\"79597.00\",\"A\":\"3.312\",\"T\":1788567730986,\"E\":1788567730986,\"st\":1}}"}
{"receive_ns":1788567731206999000,"stream":"btcusdt@trade","event_type":"trade","event_time_ms":1788567730986,"raw_json":"{\"stream\":\"btcusdt@trade\",\"data\":{\"e\":\"trade\",\"E\":1788567730986,\"T\":1788567730985,\"s\":\"BTCUSDT\",\"t\":8054122666,\"p\":\"79597.00\",\"q\":\"0.002\",\"X\":\"MARKET\",\"m\":true,\"st\":1}}"}
{"receive_ns":1788567731213422000,"stream":"btcusdt@trade","event_type":"trade","event_time_ms":1788567730986,"raw_json":"{\"stream\":\"btcusdt@trade\",\"data\":{\"e\":\"trade\",\"E\":1788567730986,\"T\":1788567730985,\"s\":\"BTCUSDT\",\"t\":8054122667,\"p\":\"79597.00\",\"q\":\"0.017\",\"X\":\"MARKET\",\"m\":true,\"st\":1}}"}
{"receive_ns":1788567731219613000,"stream":"btcusdt@trade","event_type":"trade","event_time_ms":1788567730986,"raw_json":"{\"stream\":\"btcusdt@trade\",\"data\":{\"e\":\"trade\",\"E\":1788567730986,\"T\":1788567730985,\"s\":\"BTCUSDT\",\"t\":8054122668,\"p\":\"79597.00\",\"q\":\"0.041\",\"X\":\"MARKET\",\"m\":true,\"st\":1}}"}
{"receive_ns":1788567731219990000,"stream":"btcusdt@trade","event_type":"trade","event_time_ms":1788567730986,"raw_json":"{\"stream\":\"btcusdt@trade\",\"data\":{\"e\":\"trade\",\"E\":1788567730986,\"T\":1788567730985,\"s\":\"BTCUSDT\",\"t\":8054122669,\"p\":\"79597.00\",\"q\":\"0.023\",\"X\":\"MARKET\",\"m\":true,\"st\":1}}"}
{"receive_ns":1788567731220251000,"stream":"btcusdt@trade","event_type":"trade","event_time_ms":1788567730986,"raw_json":"{\"stream\":\"btcusdt@trade\",\"data\":{\"e\":\"trade\",\"E\":1788567730986,\"T\":1788567730985,\"s\":\"BTCUSDT\",\"t\":8054122670,\"p\":\"79597.00\",\"q\":\"0.044\",\"X\":\"MARKET\",\"m\":true,\"st\":1}}"}
{"receive_ns":1788567731220500000,"stream":"btcusdt@trade","event_type":"trade","event_time_ms":1788567730986,"raw_json":"{\"stream\":\"btcusdt@trade\",\"data\":{\"e\":\"trade\",\"E\":1788567730986,\"T\":1788567730985,\"s\":\"BTCUSDT\",\"t\":8054122671,\"p\":\"79597.00\",\"q\":\"0.016\",\"X\":\"MARKET\",\"m\":true,\"st\":1}}"}
{"receive_ns":1788567731220823000,"stream":"btcusdt@trade","event_type":"trade","event_time_ms":1788567730986,"raw_json":"{\"stream\":\"btcusdt@trade\",\"data\":{\"e\":\"trade\",\"E\":1788567730986,\"T\":1788567730985,\"s\":\"BTCUSDT\",\"t\":8054122672,\"p\":\"79597.00\",\"q\":\"0.012\",\"X\":\"MARKET\",\"m\":true,\"st\":1}}"}
{"receive_ns":1788567731226528000,"stream":"btcusdt@trade","event_type":"trade","event_time_ms":1788567730986,"raw_json":"{\"stream\":\"btcusdt@trade\",\"data\":{\"e\":\"trade\",\"E\":1788567730986,\"T\":1788567730985,\"s\":\"BTCUSDT\",\"t\":8054122673,\"p\":\"79597.00\",\"q\":\"0.048\",\"X\":\"MARKET\",\"m\":true,\"st\":1}}"}
{"receive_ns":1788567731226970000,"stream":"btcusdt@trade","event_type":"trade","event_time_ms":1788567730986,"raw_json":"{\"stream\":\"btcusdt@trade\",\"data\":{\"e\":\"trade\",\"E\":1788567730986,\"T\":1788567730985,\"s\":\"BTCUSDT\",\"t\":8054122674,\"p\":\"79597.00\",\"q\":\"0.130\",\"X\":\"MARKET\",\"m\":true,\"st\":1}}"}
{"receive_ns":1788567731233212000,"stream":"btcusdt@trade","event_type":"trade","event_time_ms":1788567730986,"raw_json":"{\"stream\":\"btcusdt@trade\",\"data\":{\"e\":\"trade\",\"E\":1788567730986,\"T\":1788567730985,\"s\":\"BTCUSDT\",\"t\":8054122675,\"p\":\"79597.00\",\"q\":\"0.001\",\"X\":\"MARKET\",\"m\":true,\"st\":1}}"}
{"receive_ns":1788567731238952000,"stream":"btcusdt@trade","event_type":"trade","event_time_ms":1788567730986,"raw_json":"{\"stream\":\"btcusdt@trade\",\"data\":{\"e\":\"trade\",\"E\":1788567730986,\"T\":1788567730985,\"s\":\"BTCUSDT\",\"t\":8054122676,\"p\":\"79597.00\",\"q\":\"1.019\",\"X\":\"MARKET\",\"m\":true,\"st\":1}}"}
{"receive_ns":1788567731244700000,"stream":"btcusdt@trade","event_type":"trade","event_time_ms":1788567730986,"raw_json":"{\"stream\":\"btcusdt@trade\",\"data\":{\"e\":\"trade\",\"E\":1788567730986,\"T\":1788567730985,\"s\":\"BTCUSDT\",\"t\":8054122677,\"p\":\"79597.00\",\"q\":\"0.001\",\"X\":\"MARKET\",\"m\":true,\"st\":1}}"}
{"receive_ns":1788567731250112000,"stream":"btcusdt@trade","event_type":"trade","event_time_ms":1788567730986,"raw_json":"{\"stream\":\"btcusdt@trade\",\"data\":{\"e\":\"trade\",\"E\":1788567730986,\"T\":1788567730985,\"s\":\"BTCUSDT\",\"t\":8054122678,\"p\":\"79597.00\",\"q\":\"0.048\",\"X\":\"MARKET\",\"m\":true,\"st\":1}}"}
{"receive_ns":1788567731255559000,"stream":"btcusdt@trade","event_type":"trade","event_time_ms":1788567730986,"raw_json":"{\"stream\":\"btcusdt@trade\",\"data\":{\"e\":\"trade\",\"E\":1788567730986,\"T\":1788567730985,\"s\":\"BTCUSDT\",\"t\":8054122679,\"p\":\"79597.00\",\"q\":\"0.049\",\"X\":\"MARKET\",\"m\":true,\"st\":1}}"}
