{"receive_ns":1788567552237662000,"stream":"btcusdt@depth@100ms","event_type":"depthUpdate","event_time_ms":1788567552269,"raw_json":"{\"stream\":\"btcusdt@depth@100ms\",\"data\":{\"e\":\"depthUpdate\",\"E\":1788567552269,\"T\":1788567552268,\"s\":\"BTCUSDT\",\"ps\":\"BTCUSDT\",\"U\":11478495809943,\"u\":11478495817718,\"pu\":11478495809808,\"b\":[[\"29394.20\",\"1.659\"],[\"29494.20\",\"0.441\"],[\"71634.70\",\"0.002\"],[\"76410.40\",\"0.002\"],[\"78121.70\",\"0.830\"],[\"78798.30\",\"2.534\"],[\"79592.00\",\"0.003\"]],\"a\":[[\"79594.30\",\"9.174\"],[\"79618.40\",\"0.646\"],[\"79620.60\",\"0.002\"],[\"79745.80\",\"0.032\"],[\"79749.00\",\"0.001\"],[\"80390.20\",\"0.084\"],[\"82669.70\",\"0.000\"]],\"st\":1}}"}
{"receive_ns":1788567552360040000,"stream":"btcusdt@depth@100ms","event_type":"depthUpdate","event_time_ms":1788567552371,"raw_json":"{\"stream\":\"btcusdt@depth@100ms\",\"data\":{\"e\":\"depthUpdate\",\"E\":1788567552371,\"T\":1788567552369,\"s\":\"BTCUSDT\",\"ps\":\"BTCUSDT\",\"U\":11478495817854,\"u\":11478495825908,\"pu\":11478495817718,\"b\":[[\"1000.00\",\"24.604\"],[\"29294.20\",\"0.028\"],[\"29394.20\",\"1.785\"],[\"29494.20\",\"0.287\"],[\"71634.70\",\"0.002\"],[\"75614.50\",\"0.006\"],[\"76410.40\",\"0.000\"],[\"78440.10\",\"3.410\"],[\"78572.70\",\"0.000\"],[\"78798.30\",\"2.534\"],[\"78823.90\",\"0.000\"],[\"79465.70\",\"0.000\"],[\"79465.80\",\"0.505\"]],\"a\":[[\"79664.40\",\"0.022\"],[\"79665.00\",\"0.001\"],[\"79716.20\",\"1.953\"],[\"80390.20\",\"0.082\"],[\"80549.40\",\"7.189\"],[\"80724.50\",\"0.148\"],[\"81043.10\",\"3.326\"]],\"st\":1}}"}
{"receive_ns":1788567552441498000,"stream":"btcusdt@depth@100ms","event_type":"depthUpdate","event_time_ms":1788567552473,"raw_json":"{\"stream\":\"btcusdt@depth@100ms\",\"data\":{\"e\":\"depthUpdate\",\"E\":1788567552473,\"T\":1788567552472,\"s\":\"BTCUSDT\",\"ps\":\"BTCUSDT\",\"U\":11478495826050,\"u\":11478495833339,\"pu\":11478495825908,\"b\":[[\"1000.00\",\"24.604\"],[\"29294.20\",\"0.091\"],[\"29394.20\",\"1.834\"],[\"29494.20\",\"0.175\"],[\"71634.70\",\"0.002\"],[\"76410.40\",\"0.002\"],[\"78458.70\",\"1.526\"],[\"78599.30\",\"3.091\"],[\"78798.30\",\"2.534\"],[\"79196.20\",\"1.513\"],[\"79464.90\",\"1.266\"],[\"79479.30\",\"0.002\"],[\"79485.90\",\"0.203\"],[\"79500.30\",\"0.002\"]],\"a\":[[\"79598.30\",\"0.046\"],[\"80390.20\",\"0.082\"],[\"80590.00\",\"6.173\"],[\"80684.90\",\"1.192\"]],\"st\":1}}"}
{"receive_ns":1788567552543861000,"stream":"btcusdt@depth@100ms","event_type":"depthUpdate","event_time_ms":1788567552575,"raw_json":"{\"stream\":\"btcusdt@depth@100ms\",\"data\":{\"e\":\"depthUpdate\",\"E\":1788567552575,\"T\":1788567552573,\"s\":\"BTCUSDT\",\"ps\":\"BTCUSDT\",\"U\":11478495833412,\"u\":11478495842370,\"pu\":11478495833339,\"b\":[[\"29294.20\",\"0.147\"],[\"29394.20\",\"1.904\"],[\"29494.20\",\"0.049\"],[\"63675.00\",\"0.002\"],[\"71634.70\",\"0.002\"],[\"78091.90\",\"3.260\"],[\"78464.00\",\"0.319\"],[\"78505.70\",\"5.254\"],[\"78618.80\",\"0.750\"],[\"78798.30\",\"2.534\"],[\"79196.20\",\"1.512\"],[\"79427.90\",\"0.499\"],[\"79534.40\",\"0.829\"],[\"79550.30\",\"0.000\"],[\"79582.30\",\"0.152\"],[\"79582.60\",\"0.071\"],[\"79591.10\",\"0.028\"],[\"79593.70\",\"0.000\"],[\"79594.20\",\"2.351\"]],\"a\":[[\"79594.30\",\"9.178\"],[\"79618.70\",\"0.076\"],[\"79634.60\",\"1.024\"],[\"79668.50\",\"2.636\"],[\"79753.70\",\"0.692\"],[\"80390.20\",\"0.082\"],[\"80510.40\",\"18.466\"],[\"80549.60\",\"12.039\"],[\"80716.70\",\"0.371\"],[\"80717.60\",\"31.978\"],[\"83517.60\",\"0.750\"]],\"st\":1}}"}
{"receive_ns":1788567552645733000,"stream":"btcusdt@depth@100ms","event_type":"depthUpdate","event_time_ms":1788567552677,"raw_json":"{\"stream\":\"btcusdt@depth@100ms\",\"data\":{\"e\":\"depthUpdate\",\"E\":1788567552677,\"T\":1788567552676,\"s\":\"BTCUSDT\",\"ps\":\"BTCUSDT\",\"U\":11478495842452,\"u\":11478495849077,\"pu\":11478495842370,\"b\":[[\"1000.00\",\"24.754\"],[\"29294.20\",\"0.273\"],[\"29394.20\",\"1.827\"],[\"29494.20\",\"0.000\"],[\"63675.40\",\"0.000\"],[\"71634.70\",\"0.002\"],[\"76410.40\",\"0.000\"],[\"78424.20\",\"0.445\"],[\"78798.30\",\"2.534\"],[\"79570.50\",\"0.004\"]],\"a\":[[\"79610.40\",\"0.085\"],[\"79745.80\",\"0.000\"],[\"79750.90\",\"0.032\"],[\"79992.30\",\"1.498\"],[\"80390.20\",\"0.082\"],[\"80558.40\",\"17.265\"]],\"st\":1}}"}
{"receive_ns":1788567552747841000,"stream":"btcusdt@depth@100ms","event_type":"depthUpdate","event_time_ms":1788567552779,"raw_json":"{\"stream\":\"btcusdt@depth@100ms\",\"data\":{\"e\":\"depthUpdate\",\"E\":1788567552779,\"T\":1788567552778,\"s\":\"BTCUSDT\",\"ps\":\"BTCUSDT\",\"U\":11478495849108,\"u\":11478495855979,\"pu\":11478495849077,\"b\":[[\"1000.00\",\"24.604\"],[\"29294.20\",\"0.448\"],[\"29394.20\",\"1.652\"],[\"71634.70\",\"0.002\"],[\"71675.00\",\"0.002\"],[\"76410.40\",\"0.002\"],[\"78249.70\",\"2.426\"],[\"78263.60\",\"0.000\"],[\"78798.30\",\"2.534\"],[\"79196.20\",\"1.512\"],[\"79465.80\",\"0.010\"]],\"a\":[[\"79602.90\",\"2.503\"],[\"79618.40\",\"0.640\"],[\"79621.40\",\"0.098\"],[\"79630.20\",\"0.001\"],[\"79630.50\",\"0.205\"],[\"79634.20\",\"0.003\"],[\"79658.00\",\"22.345\"],[\"79683.50\",\"0.772\"],[\"79716.20\",\"1.515\"],[\"80390.20\",\"0.082\"],[\"80590.00\",\"6.793\"],[\"80668.80\",\"1.092\"],[\"80708.60\",\"1.893\"],[\"80801.20\",\"0.000\"],[\"81186.10\",\"4.074\"],[\"81500.00\",\"37.530\"]],\"st\":1}}"}
{"receive_ns":1788567552851969000,"stream":"btcusdt@depth@100ms","event_type":"depthUpdate","event_time_ms":1788567552881,"raw_json":"{\"stream\":\"btcusdt@depth@100ms\",\"data\":{\"e\":\"depthUpdate\",\"E\":1788567552881,\"T\":1788567552873,\"s\":\"BTCUSDT\",\"ps\":\"BTCUSDT\",\"U\":11478495856060,\"u\":11478495865468,\"pu\":11478495855979,\"b\":[[\"29294.20\",\"0.623\"],[\"29394.20\",\"1.477\"],[\"71634.70\",\"0.002\"],[\"76410.40\",\"0.000\"],[\"78798.30\",\"2.534\"],[\"79196.20\",\"1.511\"],[\"79426.30\",\"0.000\"],[\"79427.90\",\"0.192\"],[\"79569.20\",\"0.065\"],[\"79571.10\",\"0.071\"],[\"79573.10\",\"0.265\"],[\"79575.10\",\"0.075\"]],\"a\":[[\"79630.50\",\"0.080\"],[\"79630.60\",\"0.027\"],[\"79630.90\",\"0.136\"],[\"79683.50\",\"0.747\"],[\"79748.70\",\"0.032\"],[\"79750.90\",\"0.000\"],[\"79753.70\",\"0.442\"],[\"79755.60\",\"0.000\"],[\"80231.10\",\"0.749\"],[\"80390.20\",\"0.082\"],[\"80406.60\",\"0.000\"]],\"st\":1}}"}
{"receive_ns":1788567552952427000,"stream":"btcusdt@depth@100ms","event_type":"depthUpdate","event_time_ms":1788567552983,"raw_json":"{\"stream\":\"btcusdt@depth@100ms\",\"data\":{\"e\":\"depthUpdate\",\"E\":1788567552983,\"T\":1788567552981,\"s\":\"BTCUSDT\",\"ps\":\"BTCUSDT\",\"U\":11478495866116,\"u\":11478495872797,\"pu\":11478495865468,\"b\":[[\"1000.00\",\"24.604\"],[\"29294.20\",\"0.812\"],[\"29394.20\",\"1.288\"],[\"71634.70\",\"0.002\"],[\"76410.40\",\"0.002\"],[\"78241.10\",\"4.976\"],[\"78534.40\",\"0.006\"],[\"78798.30\",\"2.534\"],[\"79378.40\",\"0.000\"],[\"79378.80\",\"5.495\"],[\"79426.60\",\"1.970\"],[\"79466.00\",\"0.433\"],[\"79510.10\",\"0.011\"],[\"79511.80\",\"1.134\"],[\"79537.90\",\"0.202\"],[\"79539.00\",\"0.845\"],[\"79557.80\",\"0.114\"],[\"79563.60\",\"2.107\"],[\"79564.50\",\"0.127\"],[\"79568.00\",\"1.621\"],[\"79573.10\",\"0.262\"],[\"79578.80\",\"0.003\"],[\"79594.20\",\"2.351\"]],\"a\":[[\"79594.30\",\"9.179\"],[\"79628.20\",\"0.004\"],[\"79630.60\",\"0.152\"],[\"79630.70\",\"0.003\"],[\"79630.90\",\"0.011\"],[\"79647.00\",\"0.003\"],[\"79666.80\",\"0.398\"],[\"79666.90\",\"0.002\"],[\"79667.40\",\"0.062\"],[\"79694.80\",\"0.000\"],[\"79716.30\",\"1.504\"],[\"79748.70\",\"0.000\"],[\"79754.30\",\"0.039\"],[\"79755.70\",\"1.886\"],[\"79803.40\",\"3.213\"],[\"79992.30\",\"1.499\"],[\"80390.20\",\"0.082\"]],\"st\":1}}"}
{"receive_ns":1788567553053866000,"stream":"btcusdt@depth@100ms","event_type":"depthUpdate","event_time_ms":1788567553085,"raw_json":"{\"stream\":\"btcusdt@depth@100ms\",\"data\":{\"e\":\"depthUpdate\",\"E\":1788567553085,\"T\":1788567553083,\"s\":\"BTCUSDT\",\"ps\":\"BTCUSDT\",\"U\":11478495872874,\"u\":11478495880891,\"pu\":11478495872797,\"b\":[[\"29294.20\",\"0.987\"],[\"29394.20\",\"1.113\"],[\"71634.70\",\"0.002\"],[\"78002.40\",\"0.006\"],[\"78569.30\",\"0.002\"],[\"78571.10\",\"1.897\"],[\"78798.30\",\"2.534\"],[\"78997.20\",\"1.264\"],[\"79196.20\",\"1.511\"],[\"79460.10\",\"0.006\"],[\"79470.30\",\"0.007\"],[\"79470.40\",\"1.508\"],[\"79471.80\",\"1.317\"],[\"79515.00\",\"0.052\"],[\"79515.10\",\"0.016\"],[\"79538.40\",\"0.072\"],[\"79554.40\",\"0.004\"],[\"79568.40\",\"2.804\"],[\"79579.90\",\"0.002\"],[\"79591.80\",\"0.026\"],[\"79594.20\",\"2.410\"]],\"a\":[[\"79594.30\",\"9.183\"],[\"79599.30\",\"0.146\"],[\"79611.40\",\"0.203\"],[\"79622.30\",\"1.303\"],[\"79629.80\",\"0.004\"],[\"79630.40\",\"0.000\"],[\"79630.60\",\"0.027\"],[\"79630.70\",\"0.128\"],[\"79631.30\",\"0.001\"],[\"79689.90\",\"0.002\"],[\"79732.40\",\"0.609\"],[\"79733.30\",\"0.015\"],[\"79751.70\",\"0.032\"],[\"79754.30\",\"0.007\"],[\"80191.30\",\"1.246\"],[\"80390.20\",\"0.082\"],[\"80764.30\",\"1.420\"],[\"87553.80\",\"0.000\"]],\"st\":1}}"}
{"receive_ns":1788567553158642000,"stream":"btcusdt@depth@100ms","event_type":"depthUpdate","event_time_ms":1788567553187,"raw_json":"{\"stream\":\"btcusdt@depth@100ms\",\"data\":{\"e\":\"depthUpdate\",\"E\":1788567553187,\"T\":1788567553186,\"s\":\"BTCUSDT\",\"ps\":\"BTCUSDT\",\"U\":11478495881024,\"u\":11478495888422,\"pu\":11478495880891,\"b\":[[\"29294.20\",\"1.169\"],[\"29394.20\",\"0.931\"],[\"71634.70\",\"0.002\"],[\"76410.40\",\"0.000\"],[\"78611.70\",\"0.000\"],[\"78798.30\",\"2.538\"],[\"79442.00\",\"2.227\"],[\"79442.40\",\"0.000\"],[\"79501.60\",\"6.629\"],[\"79529.40\",\"3.725\"],[\"79538.40\",\"0.074\"],[\"79549.30\",\"3.524\"],[\"79579.00\",\"0.253\"],[\"79579.20\",\"0.040\"],[\"79580.90\",\"0.005\"],[\"79582.30\",\"0.152\"],[\"79591.00\",\"0.027\"],[\"79591.40\",\"0.026\"],[\"79591.80\",\"0.000\"],[\"79592.80\",\"0.002\"],[\"79594.20\",\"2.409\"]],\"a\":[[\"79594.30\",\"9.209\"],[\"79599.30\",\"0.131\"],[\"79602.00\",\"0.022\"],[\"79602.60\",\"0.381\"],[\"79603.70\",\"0.254\"],[\"79604.70\",\"0.000\"],[\"79606.90\",\"1.873\"],[\"79607.00\",\"3.067\"],[\"79611.40\",\"0.223\"],[\"79622.30\",\"1.283\"],[\"79630.30\",\"0.004\"],[\"79630.60\",\"0.027\"],[\"79630.70\",\"0.003\"],[\"79631.10\",\"0.016\"],[\"79631.20\",\"0.236\"],[\"79642.10\",\"0.572\"],[\"79662.00\",\"3.541\"],[\"79689.90\",\"6.002\"],[\"79698.90\",\"0.037\"],[\"79721.10\",\"1.887\"],[\"79721.60\",\"1.507\"],[\"79750.60\",\"0.034\"],[\"79751.70\",\"0.000\"],[\"80390.20\",\"0.082\"],[\"80584.90\",\"0.012\"],[\"80590.00\",\"6.179\"],[\"81186.10\",\"4.077\"],[\"81782.70\",\"1.708\"]],\"st\":1}}"}
{"receive_ns":1788567553258487000,"stream":"btcusdt@depth@100ms","event_type":"depthUpdate","event_time_ms":1788567553289,"raw_json":"{\"stream\":\"btcusdt@depth@100ms\",\"data\":{\"e\":\"depthUpdate\",\"E\":1788567553289,\"T\":1788567553287,\"s\":\"BTCUSDT\",\"ps\":\"BTCUSDT\",\"U\":11478495888445,\"u\":11478495894186,\"pu\":11478495888422,\"b\":[[\"1000.00\",\"24.604\"],[\"29294.20\",\"1.344\"],[\"29394.20\",\"0.756\"],[\"71634.70\",\"0.002\"],[\"76410.40\",\"0.002\"],[\"78798.30\",\"2.534\"],[\"79461.90\",\"10.201\"],[\"79463.80\",\"2.916\"],[\"79466.00\",\"0.000\"],[\"79515.00\",\"0.002\"],[\"79515.10\",\"0.066\"],[\"79583.60\",\"0.012\"],[\"79584.10\",\"0.037\"],[\"79594.20\",\"2.447\"]],\"a\":[[\"79594.30\",\"9.212\"],[\"79619.20\",\"0.012\"],[\"79621.40\",\"0.092\"],[\"79631.10\",\"0.016\"],[\"79631.20\",\"0.111\"],[\"79631.30\",\"0.001\"],[\"79716.30\",\"1.124\"],[\"79728.00\",\"2.371\"],[\"79729.20\",\"10.000\"],[\"79729.70\",\"0.006\"],[\"79749.40\",\"0.032\"],[\"79750.60\",\"0.002\"],[\"80390.20\",\"0.082\"],[\"80684.70\",\"0.743\"],[\"80684.90\",\"1.043\"]],\"st\":1}}"}
{"receive_ns":1788567553362007000,"stream":"btcusdt@depth@100ms","event_type":"depthUpdate","event_time_ms":1788567553391,"raw_json":"{\"stream\":\"btcusdt@depth@100ms\",\"data\":{\"e\":\"depthUpdate\",\"E\":1788567553391,\"T\":1788567553389,\"s\":\"BTCUSDT\",\"ps\":\"BTCUSDT\",\"U\":11478495894313,\"u\":11478495903436,\"pu\":11478495894186,\"b\":[[\"29294.20\",\"1.526\"],[\"29394.20\",\"0.574\"],[\"63675.00\",\"0.002\"],[\"71634.70\",\"0.002\"],[\"76410.40\",\"0.000\"],[\"78441.30\",\"3.503\"],[\"78599.30\",\"3.282\"],[\"78798.30\",\"2.534\"],[\"79196.20\",\"1.511\"],[\"79426.60\",\"0.010\"],[\"79426.70\",\"2.492\"],[\"79460.10\",\"0.000\"],[\"79462.00\",\"0.008\"],[\"79466.00\",\"0.494\"],[\"79583.60\",\"0.012\"],[\"79584.10\",\"0.037\"]],\"a\":[[\"79594.30\",\"9.213\"],[\"79631.50\",\"0.125\"],[\"79716.30\",\"1.562\"],[\"79755.70\",\"2.174\"],[\"80390.20\",\"0.082\"],[\"80549.40\",\"10.535\"],[\"80590.00\",\"6.799\"],[\"82431.40\",\"0.003\"]],\"st\":1}}"}
{"receive_ns":1788567553461706000,"stream":"btcusdt@depth@100ms","event_type":"depthUpdate","event_time_ms":1788567553493,"raw_json":"{\"stream\":\"btcusdt@depth@100ms\",\"data\":{\"e\":\"depthUpdate\",\"E\":1788567553493,\"T\":1788567553489,\"s\":\"BTCUSDT\",\"ps\":\"BTCUSDT\",\"U\":11478495903613,\"u\":11478495911987,\"pu\":11478495903436,\"b\":[[\"29294.20\",\"1.701\"],[\"29394.20\",\"0.399\"],[\"34000.00\",\"0.975\"],[\"71634.70\",\"0.002\"],[\"76410.40\",\"0.002\"],[\"78798.30\",\"2.534\"],[\"78929.10\",\"0.002\"]],\"a\":[[\"79602.00\",\"0.002\"],[\"79602.10\",\"0.068\"],[\"79602.50\",\"0.020\"],[\"79610.60\",\"0.260\"],[\"79611.40\",\"0.096\"],[\"79631.50\",\"0.000\"],[\"79631.60\",\"0.125\"],[\"79749.40\",\"0.000\"],[\"79750.90\",\"0.032\"],[\"80390.20\",\"0.082\"],[\"81068.20\",\"4.043\"],[\"81186.10\",\"4.074\"]],\"st\":1}}"}
{"receive_ns":1788567553565727000,"stream":"btcusdt@depth@100ms","event_type":"depthUpdate","event_time_ms":1788567553595,"raw_json":"{\"stream\":\"btcusdt@depth@100ms\",\"data\":{\"e\":\"depthUpdate\",\"E\":1788567553595,\"T\":1788567553594,\"s\":\"BTCUSDT\",\"ps\":\"BTCUSDT\",\"U\":11478495912226,\"u\":11478495919720,\"pu\":11478495911987,\"b\":[[\"1000.00\",\"24.604\"],[\"29194.20\",\"0.042\"],[\"29294.20\",\"1.799\"],[\"29394.20\",\"0.259\"],[\"63675.00\",\"0.004\"],[\"71634.70\",\"0.002\"],[\"75619.20\",\"0.008\"],[\"75619.30\",\"0.004\"],[\"78147.60\",\"0.511\"],[\"78441.30\",\"3.248\"],[\"78798.30\",\"2.534\"],[\"78807.00\",\"2.471\"],[\"79364.40\",\"0.117\"],[\"79370.80\",\"0.020\"],[\"79426.70\",\"2.493\"],[\"79427.90\",\"0.522\"],[\"79466.00\",\"0.000\"],[\"79466.10\",\"0.494\"],[\"79501.80\",\"0.019\"],[\"79550.10\",\"0.028\"],[\"79564.20\",\"0.007\"],[\"79564.50\",\"0.002\"],[\"79564.60\",\"0.126\"],[\"79565.00\",\"0.258\"],[\"79565.40\",\"0.046\"],[\"79567.20\",\"0.454\"],[\"79568.10\",\"0.003\"],[\"79569.20\",\"0.065\"],[\"79571.50\",\"0.001\"],[\"79572.00\",\"0.445\"],[\"79573.60\",\"0.000\"],[\"79574.40\",\"0.018\"],[\"79574.80\",\"0.374\"],[\"79589.30\",\"0.003\"],[\"79591.60\",\"0.027\"],[\"79594.20\",\"2.481\"]],\"a\":[[\"79594.30\",\"9.215\"],[\"79611.50\",\"0.206\"],[\"79613.50\",\"0.000\"],[\"79614.00\",\"0.633\"],[\"79614.20\",\"0.008\"],[\"79614.30\",\"0.000\"],[\"79614.70\",\"1.501\"],[\"79617.20\",\"0.000\"],[\"79618.30\",\"0.453\"],[\"79618.50\",\"0.002\"],[\"79619.20\",\"0.007\"],[\"79619.30\",\"0.001\"],[\"79628.00\",\"1.502\"],[\"79628.80\",\"0.000\"],[\"79629.20\",\"0.049\"],[\"79716.30\",\"1.562\"],[\"79749.90\",\"0.032\"],[\"79750.90\",\"0.000\"],[\"79753.70\",\"0.692\"],[\"79755.70\",\"2.186\"],[\"80390.20\",\"0.082\"],[\"80399.10\",\"6.983\"],[\"80549.60\",\"11.828\"]],\"st\":1}}"}
{"receive_ns":1788567553668417000,"stream":"btcusdt@depth@100ms","event_type":"depthUpdate","event_time_ms":1788567553697,"raw_json":"{\"stream\":\"btcusdt@depth@100ms\",\"data\":{\"e\":\"depthUpdate\",\"E\":1788567553697,\"T\":1788567553695,\"s\":\"BTCUSDT\",\"ps\":\"BTCUSDT\",\"U\":11478495919798,\"u\":11478495925964,\"pu\":11478495919720,\"b\":[[\"29194.20\",\"0.105\"],[\"29294.20\",\"1.848\"],[\"29394.20\",\"0.147\"],[\"63675.00\",\"0.002\"],[\"63675.40\",\"0.000\"],[\"71634.70\",\"0.002\"],[\"76410.40\",\"0.000\"],[\"78002.40\",\"0.009\"],[\"78599.30\",\"3.567\"],[\"78798.30\",\"2.534\"],[\"79196.20\",\"1.512\"],[\"79426.70\",\"0.001\"],[\"79456.80\",\"0.008\"],[\"79466.10\",\"0.000\"],[\"79555.10\",\"0.341\"],[\"79568.00\",\"0.921\"],[\"79569.00\",\"0.702\"],[\"79570.50\",\"0.002\"],[\"79591.40\",\"0.000\"],[\"79591.60\",\"0.001\"]],\"a\":[[\"79610.40\",\"0.083\"],[\"79716.30\",\"1.124\"],[\"79748.00\",\"0.032\"],[\"79749.90\",\"0.000\"],[\"79755.70\",\"0.000\"],[\"79992.30\",\"1.498\"],[\"80390.20\",\"0.082\"],[\"87553.80\",\"0.000\"]],\"st\":1}}"}
{"receive_ns":1788567553770456000,"stream":"btcusdt@depth@100ms","event_type":"depthUpdate","event_time_ms":1788567553799,"raw_json":"{\"stream\":\"btcusdt@depth@100ms\",\"data\":{\"e\":\"depthUpdate\",\"E\":1788567553799,\"T\":1788567553797,\"s\":\"BTCUSDT\",\"ps\":\"BTCUSDT\",\"U\":11478495926097,\"u\":11478495932348,\"pu\":11478495925964,\"b\":[[\"29194.20\",\"0.161\"],[\"29294.20\",\"1.918\"],[\"29394.20\",\"0.021\"],[\"63675.00\",\"0.002\"],[\"71634.70\",\"0.002\"],[\"71675.00\",\"0.005\"],[\"75614.60\",\"0.000\"],[\"76410.40\",\"0.002\"],[\"78393.60\",\"0.000\"],[\"78798.30\",\"2.534\"],[\"79378.80\",\"0.001\"],[\"79417.40\",\"0.247\"],[\"79427.90\",\"0.192\"],[\"79448.10\",\"0.023\"],[\"79570.50\",\"0.004\"],[\"79594.00\",\"0.089\"]],\"a\":[[\"79610.40\",\"0.085\"],[\"79631.10\",\"0.141\"],[\"79631.60\",\"0.000\"],[\"79640.50\",\"0.016\"],[\"79753.70\",\"0.442\"],[\"79803.40\",\"0.000\"],[\"80390.20\",\"0.082\"]],\"st\":1}}"}
{"receive_ns":1788567553871350000,"stream":"btcusdt@depth@100ms","event_type":"depthUpdate","event_time_ms":1788567553901,"raw_json":"{\"stream\":\"btcusdt@depth@100ms\",\"data\":{\"e\":\"depthUpdate\",\"E\":1788567553901,\"T\":1788567553897,\"s\":\"BTCUSDT\",\"ps\":\"BTCUSDT\",\"U\":11478495932485,\"u\":11478495940451,\"pu\":11478495932348,\"b\":[[\"1000.00\",\"24.604\"],[\"29194.20\",\"0.315\"],[\"29294.20\",\"1.785\"],[\"29394.20\",\"0.000\"],[\"63675.00\",\"0.002\"],[\"71634.70\",\"0.002\"],[\"71675.00\",\"0.002\"],[\"76410.40\",\"0.000\"],[\"78798.30\",\"2.534\"],[\"78814.30\",\"0.002\"],[\"79379.00\",\"5.492\"],[\"79426.70\",\"2.429\"],[\"79466.10\",\"0.485\"]],\"a\":[[\"79631.10\",\"0.141\"],[\"79646.60\",\"0.189\"],[\"79716.30\",\"1.564\"],[\"79748.00\",\"0.000\"],[\"79750.90\",\"0.032\"],[\"79755.70\",\"2.174\"],[\"79803.50\",\"3.233\"],[\"79992.30\",\"1.497\"],[\"81186.10\",\"4.071\"]],\"st\":1}}"}
{"receive_ns":1788567553973490000,"stream":"btcusdt@depth@100ms","event_type":"depthUpdate","event_time_ms":1788567554003,"raw_json":"{\"stream\":\"btcusdt@depth@100ms\",\"data\":{\"e\":\"depthUpdate\",\"E\":1788567554003,\"T\":1788567554002,\"s\":\"BTCUSDT\",\"ps\":\"BTCUSDT\",\"U\":11478495940824,\"u\":11478495950870,\"pu\":11478495940451,\"b\":[[\"29194.20\",\"0.490\"],[\"29294.20\",\"1.610\"],[\"63675.00\",\"0.002\"],[\"71634.70\",\"0.002\"],[\"78599.30\",\"4.520\"],[\"78798.30\",\"2.534\"],[\"79196.20\",\"1.513\"],[\"79589.40\",\"0.026\"],[\"79590.20\",\"0.028\"],[\"79590.90\",\"0.001\"],[\"79591.00\",\"0.001\"]],\"a\":[[\"79631.10\",\"0.016\"],[\"79631.30\",\"0.001\"],[\"79631.50\",\"0.125\"],[\"79746.40\",\"0.032\"],[\"79749.30\",\"0.002\"],[\"79750.90\",\"0.000\"],[\"80390.20\",\"0.084\"],[\"80549.60\",\"11.679\"]],\"st\":1}}"}
{"receive_ns":1788567554074673000,"stream":"btcusdt@depth@100ms","event_type":"depthUpdate","event_time_ms":1788567554105,"raw_json":"{\"stream\":\"btcusdt@depth@100ms\",\"data\":{\"e\":\"depthUpdate\",\"E\":1788567554105,\"T\":1788567554103,\"s\":\"BTCUSDT\",\"ps\":\"BTCUSDT\",\"U\":11478495950929,\"u\":11478495959191,\"pu\":11478495950870,\"b\":[[\"1000.00\",\"24.604\"],[\"29194.20\",\"0.672\"],[\"29294.20\",\"1.428\"],[\"63675.00\",\"0.002\"],[\"71634.70\",\"0.002\"],[\"75614.50\",\"0.008\"],[\"76410.40\",\"0.002\"],[\"78002.40\",\"0.012\"],[\"78798.30\",\"2.534\"],[\"78875.80\",\"0.886\"],[\"79515.00\",\"0.052\"],[\"79515.10\",\"0.016\"],[\"79579.90\",\"0.002\"],[\"79594.20\",\"2.490\"]],\"a\":[[\"79600.20\",\"0.002\"],[\"79631.50\",\"0.000\"],[\"79631.60\",\"0.000\"],[\"79631.70\",\"0.126\"],[\"79686.70\",\"0.000\"],[\"80390.20\",\"0.082\"],[\"82676.10\",\"0.054\"],[\"83546.10\",\"0.004\"]],\"st\":1}}"}
{"receive_ns":1788567554320327000,"stream":"btcusdt@depth@100ms","event_type":"depthUpdate","event_time_ms":1788567554207,"raw_json":"{\"stream\":\"btcusdt@depth@100ms\",\"data\":{\"e\":\"depthUpdate\",\"E\":1788567554207,\"T\":1788567554206,\"s\":\"BTCUSDT\",\"ps\":\"BTCUSDT\",\"U\":11478495959359,\"u\":11478495986880,\"pu\":11478495959191,\"b\":[[\"1000.00\",\"24.604\"],[\"29192.90\",\"0.154\"],[\"29194.20\",\"0.700\"],[\"29294.20\",\"1.246\"],[\"71633.60\",\"0.002\"],[\"71634.70\",\"0.000\"],[\"74918.00\",\"0.001\"],[\"75117.30\",\"0.000\"],[\"76410.40\",\"0.000\"],[\"78001.00\",\"0.385\"],[\"78104.60\",\"0.511\"],[\"78458.70\",\"0.445\"],[\"78676.90\",\"6.795\"],[\"78678.30\",\"0.000\"],[\"78796.30\",\"0.251\"],[\"78797.00\",\"0.002\"],[\"78797.70\",\"2.013\"],[\"78798.30\",\"2.534\"],[\"79396.90\",\"3.148\"],[\"79409.60\",\"0.001\"],[\"79441.10\",\"1.885\"],[\"79442.00\",\"0.342\"],[\"79473.40\",\"0.003\"],[\"79473.50\",\"0.454\"],[\"79473.60\",\"0.001\"],[\"79479.60\",\"0.049\"],[\"79479.80\",\"0.001\"],[\"79481.10\",\"0.001\"],[\"79481.60\",\"3.109\"],[\"79484.50\",\"0.069\"],[\"79484.90\",\"0.000\"],[\"79485.40\",\"0.000\"],[\"79486.60\",\"0.039\"],[\"79487.80\",\"0.038\"],[\"79490.40\",\"0.013\"],[\"79491.10\",\"0.001\"],[\"79491.60\",\"0.047\"],[\"79494.50\",\"0.039\"],[\"79495.20\",\"2.000\"],[\"79495.30\",\"0.002\"],[\"79496.30\",\"0.011\"],[\"79496.70\",\"0.039\"],[\"79497.50\",\"0.022\"],[\"79497.70\",\"0.001\"],[\"79498.50\",\"0.039\"],[\"79500.80\",\"0.552\"],[\"79504.80\",\"0.039\"],[\"79505.30\",\"0.038\"],[\"79505.50\",\"0.000\"],[\"79506.10\",\"0.000\"],[\"79506.80\",\"0.057\"],[\"79507.50\",\"0.051\"],[\"79511.30\",\"0.002\"],[\"79511.50\",\"0.002\"],[\"79511.60\",\"0.000\"],[\"79511.80\",\"1.096\"],[\"79513.20\",\"0.126\"],[\"79513.60\",\"0.041\"],[\"79514.30\",\"0.827\"],[\"79514.90\",\"0.039\"],[\"79515.00\",\"0.052\"],[\"79515.10\",\"0.016\"],[\"79517.10\",\"0.002\"],[\"79518.50\",\"2.967\"],[\"79520.00\",\"1.394\"],[\"79520.40\",\"0.043\"],[\"79520.50\",\"0.210\"],[\"79520.70\",\"0.039\"],[\"79521.10\",\"0.060\"],[\"79521.30\",\"0.005\"],[\"79522.60\",\"0.293\"],[\"79522.90\",\"0.070\"],[\"79523.20\",\"0.139\"],[\"79523.30\",\"0.027\"],[\"79523.80\",\"0.000\"],[\"79524.10\",\"0.015\"],[\"79524.60\",\"0.000\"],[\"79525.60\",\"0.027\"],[\"79525.90\",\"20.423\"],[\"79526.70\",\"0.000\"],[\"79529.30\",\"0.008\"],[\"79529.40\",\"3.726\"],[\"79530.60\",\"0.034\"],[\"79531.30\",\"0.010\"],[\"79531.70\",\"0.433\"],[\"79533.90\",\"0.201\"],[\"79534.40\",\"0.000\"],[\"79535.20\",\"0.787\"],[\"79536.00\",\"0.017\"],[\"79539.50\",\"0.125\"],[\"79544.00\",\"1.854\"],[\"79544.30\",\"0.002\"],[\"79544.90\",\"0.002\"],[\"79545.00\",\"0.322\"],[\"79545.10\",\"0.033\"],[\"79546.10\",\"0.002\"],[\"79546.60\",\"0.003\"],[\"79547.90\",\"0.002\"],[\"79548.20\",\"0.047\"],[\"79548.80\",\"0.128\"],[\"79549.40\",\"0.000\"],[\"79550.10\",\"0.001\"],[\"79550.70\",\"0.255\"],[\"79551.10\",\"0.200\"],[\"79551.30\",\"1.510\"],[\"79552.00\",\"0.046\"],[\"79552.80\",\"0.071\"],[\"79553.40\",\"0.008\"],[\"79554.00\",\"0.002\"],[\"79555.10\",\"0.347\"],[\"79555.80\",\"0.251\"],[\"79556.30\",\"0.368\"],[\"79556.80\",\"0.050\"],[\"79556.90\",\"1.098\"],[\"79558.50\",\"0.001\"],[\"79559.10\",\"0.000\"],[\"79559.50\",\"0.041\"],[\"79560.20\",\"0.104\"],[\"79560.50\",\"0.002\"],[\"79560.80\",\"0.051\"],[\"79561.00\",\"0.033\"],[\"79561.20\",\"0.000\"],[\"79561.30\",\"0.162\"],[\"79561.40\",\"0.002\"],[\"79562.10\",\"0.092\"],[\"79562.50\",\"0.548\"],[\"79563.50\",\"1.621\"],[\"79563.90\",\"0.884\"],[\"79564.00\",\"0.131\"],[\"79564.10\",\"0.001\"],[\"79564.20\",\"0.000\"],[\"79564.80\",\"1.091\"],[\"79565.10\",\"0.453\"],[\"79565.40\",\"0.000\"],[\"79566.00\",\"0.023\"],[\"79566.10\",\"0.003\"],[\"79566.20\",\"0.003\"],[\"79566.30\",\"0.433\"],[\"79567.00\",\"0.260\"],[\"79567.10\",\"0.000\"],[\"79567.20\",\"0.002\"],[\"79567.50\",\"0.001\"],[\"79567.80\",\"2.167\"],[\"79568.00\",\"0.872\"],[\"79568.40\",\"2.801\"],[\"79568.50\",\"0.121\"],[\"79568.80\",\"0.002\"],[\"79569.10\",\"1.887\"],[\"79569.20\",\"0.504\"],[\"79569.50\",\"0.181\"],[\"79570.20\",\"0.039\"],[\"79570.70\",\"0.000\"],[\"79571.10\",\"0.071\"],[\"79571.40\",\"0.000\"],[\"79571.60\",\"0.628\"],[\"79571.80\",\"1.966\"],[\"79572.00\",\"0.132\"],[\"79572.10\",\"0.341\"],[\"79572.20\",\"0.004\"],[\"79572.40\",\"0.003\"],[\"79572.80\",\"0.008\"],[\"79573.00\",\"0.327\"],[\"79573.80\",\"0.010\"],[\"79574.70\",\"0.000\"],[\"79574.80\",\"0.001\"],[\"79574.90\",\"0.011\"],[\"79575.40\",\"0.345\"],[\"79575.70\",\"0.632\"],[\"79575.80\",\"0.251\"],[\"79576.30\",\"0.001\"],[\"79576.40\",\"2.778\"],[\"79576.60\",\"0.001\"],[\"79576.70\",\"2.086\"],[\"79576.80\",\"0.128\"],[\"79577.10\",\"0.002\"],[\"79577.40\",\"0.254\"],[\"79577.50\",\"0.162\"],[\"79577.70\",\"0.082\"],[\"79577.80\",\"0.001\"],[\"79578.10\",\"0.002\"],[\"79578.50\",\"0.253\"],[\"79578.60\",\"0.001\"],[\"79579.00\",\"0.002\"],[\"79579.20\",\"0.020\"],[\"79579.40\",\"0.000\"],[\"79579.50\",\"0.003\"],[\"79580.00\",\"0.143\"],[\"79580.10\",\"0.215\"],[\"79580.60\",\"0.002\"],[\"79580.70\",\"0.002\"],[\"79580.80\",\"0.001\"],[\"79580.90\",\"2.862\"],[\"79581.20\",\"0.127\"],[\"79581.40\",\"0.000\"],[\"79581.50\",\"0.591\"],[\"79581.60\",\"0.010\"],[\"79581.90\",\"0.000\"],[\"79582.10\",\"0.036\"],[\"79582.30\",\"0.070\"],[\"79582.40\",\"0.075\"],[\"79582.50\",\"0.170\"],[\"79582.60\",\"0.071\"],[\"79582.70\",\"0.272\"],[\"79582.80\",\"0.100\"],[\"79582.90\",\"0.070\"],[\"79583.00\",\"0.105\"],[\"79583.10\",\"1.072\"],[\"79583.20\",\"0.002\"],[\"79583.30\",\"0.279\"],[\"79583.40\",\"0.013\"],[\"79583.50\",\"0.000\"],[\"79583.60\",\"0.000\"],[\"79583.70\",\"0.036\"],[\"79583.80\",\"0.074\"],[\"79583.90\",\"0.026\"],[\"79584.00\",\"0.359\"],[\"79584.10\",\"0.142\"],[\"79584.20\",\"0.027\"],[\"79584.30\",\"0.000\"],[\"79584.40\",\"0.089\"],[\"79584.50\",\"0.039\"],[\"79584.60\",\"0.029\"],[\"79584.70\",\"0.001\"],[\"79584.80\",\"0.051\"],[\"79584.90\",\"0.036\"],[\"79585.10\",\"0.026\"],[\"79585.30\",\"0.026\"],[\"79585.40\",\"0.026\"],[\"79585.60\",\"0.028\"],[\"79585.80\",\"0.000\"],[\"79585.90\",\"0.001\"],[\"79586.00\",\"0.004\"],[\"79586.10\",\"0.027\"],[\"79586.20\",\"0.001\"],[\"79586.30\",\"0.026\"],[\"79586.40\",\"0.004\"],[\"79586.50\",\"0.032\"],[\"79586.80\",\"0.000\"],[\"79587.00\",\"0.005\"],[\"79587.10\",\"0.001\"],[\"79587.20\",\"0.006\"],[\"79587.30\",\"0.004\"],[\"79587.60\",\"0.001\"],[\"79587.70\",\"0.006\"],[\"79587.80\",\"1.000\"],[\"79587.90\",\"0.002\"],[\"79588.00\",\"0.001\"],[\"79588.10\",\"0.002\"],[\"79588.20\",\"0.002\"],[\"79588.30\",\"0.076\"],[\"79588.40\",\"0.003\"],[\"79588.50\",\"0.070\"],[\"79588.60\",\"0.000\"],[\"79588.70\",\"0.000\"],[\"79588.80\",\"0.003\"],[\"79589.20\",\"0.412\"],[\"79589.40\",\"0.000\"],[\"79589.50\",\"0.003\"],[\"79589.60\",\"0.078\"],[\"79589.80\",\"0.000\"],[\"79590.00\",\"0.004\"],[\"79590.20\",\"0.002\"],[\"79590.30\",\"0.000\"],[\"79590.40\",\"0.002\"],[\"79590.60\",\"0.000\"],[\"79591.00\",\"0.001\"],[\"79591.10\",\"0.001\"],[\"79591.20\",\"0.004\"],[\"79591.30\",\"0.000\"],[\"79591.60\",\"0.000\"],[\"79591.70\",\"0.439\"],[\"79592.00\",\"0.003\"],[\"79592.10\",\"0.000\"],[\"79592.30\",\"0.077\"],[\"79592.40\",\"0.003\"],[\"79592.60\",\"0.001\"],[\"79592.70\",\"0.002\"],[\"79592.90\",\"2.301\"],[\"79593.00\",\"0.000\"],[\"79593.20\",\"0.000\"],[\"79593.50\",\"0.000\"],[\"79593.80\",\"0.000\"],[\"79593.90\",\"0.000\"],[\"79594.00\",\"0.000\"],[\"79594.10\",\"0.000\"],[\"79594.20\",\"0.000\"]],\"a\":[[\"79593.00\",\"14.932\"],[\"79593.10\",\"0.007\"],[\"79593.20\",\"0.100\"],[\"79593.30\",\"0.000\"],[\"79593.50\",\"0.000\"],[\"79593.60\",\"0.080\"],[\"79593.90\",\"0.000\"],[\"79594.00\",\"0.000\"],[\"79594.10\",\"0.004\"],[\"79594.20\",\"0.502\"],[\"79594.30\",\"0.710\"],[\"79594.40\",\"0.084\"],[\"79594.50\",\"0.001\"],[\"79594.60\",\"0.000\"],[\"79594.70\",\"0.002\"],[\"79594.80\",\"0.001\"],[\"79595.20\",\"0.107\"],[\"79595.50\",\"0.003\"],[\"79595.70\",\"0.003\"],[\"79596.00\",\"0.027\"],[\"79596.10\",\"0.003\"],[\"79596.30\",\"0.162\"],[\"79596.60\",\"0.001\"],[\"79596.80\",\"2.527\"],[\"79596.90\",\"0.001\"],[\"79597.40\",\"0.002\"],[\"79598.00\",\"0.001\"],[\"79598.20\",\"0.003\"],[\"79598.50\",\"0.038\"],[\"79598.80\",\"0.001\"],[\"79598.90\",\"0.264\"],[\"79599.00\",\"0.002\"],[\"79599.30\",\"0.131\"],[\"79599.70\",\"0.051\"],[\"79600.00\",\"0.003\"],[\"79600.10\",\"0.002\"],[\"79600.20\",\"0.001\"],[\"79600.60\",\"0.251\"],[\"79600.80\",\"0.011\"],[\"79601.00\",\"0.062\"],[\"79601.10\",\"0.040\"],[\"79601.50\",\"0.005\"],[\"79601.60\",\"0.255\"],[\"79601.70\",\"0.000\"],[\"79602.10\",\"0.067\"],[\"79602.20\",\"0.051\"],[\"79602.30\",\"0.188\"],[\"79602.40\",\"0.117\"],[\"79602.50\",\"0.076\"],[\"79602.60\",\"0.319\"],[\"79602.70\",\"0.822\"],[\"79602.80\",\"1.622\"],[\"79603.70\",\"0.003\"],[\"79604.60\",\"0.076\"],[\"79604.70\",\"0.001\"],[\"79604.80\",\"0.000\"],[\"79605.50\",\"0.056\"],[\"79605.60\",\"0.005\"],[\"79605.70\",\"0.012\"],[\"79605.80\",\"0.076\"],[\"79606.40\",\"0.001\"],[\"79606.50\",\"0.691\"],[\"79606.60\",\"0.548\"],[\"79606.70\",\"0.131\"],[\"79606.80\",\"0.104\"],[\"79606.90\",\"1.940\"],[\"79607.00\",\"3.373\"],[\"79607.10\",\"0.005\"],[\"79607.40\",\"0.021\"],[\"79607.70\",\"0.000\"],[\"79607.90\",\"0.000\"],[\"79608.00\",\"0.013\"],[\"79608.30\",\"0.128\"],[\"79608.50\",\"0.001\"],[\"79609.20\",\"0.001\"],[\"79609.40\",\"0.001\"],[\"79610.00\",\"0.041\"],[\"79610.40\",\"0.084\"],[\"79610.50\",\"0.001\"],[\"79610.80\",\"0.005\"],[\"79610.90\",\"0.003\"],[\"79611.00\",\"0.910\"],[\"79611.20\",\"2.165\"],[\"79611.40\",\"0.097\"],[\"79611.60\",\"0.281\"],[\"79611.80\",\"0.444\"],[\"79611.90\",\"0.230\"],[\"79612.10\",\"0.521\"],[\"79612.40\",\"0.154\"],[\"79613.40\",\"0.045\"],[\"79613.70\",\"0.000\"],[\"79614.00\",\"0.002\"],[\"79614.20\",\"0.007\"],[\"79614.40\",\"0.001\"],[\"79614.70\",\"1.129\"],[\"79615.30\",\"0.731\"],[\"79615.40\",\"4.613\"],[\"79615.70\",\"0.003\"],[\"79615.80\",\"0.569\"],[\"79616.00\",\"0.004\"],[\"79616.20\",\"0.453\"],[\"79616.60\",\"0.042\"],[\"79616.70\",\"1.339\"],[\"79616.90\",\"0.112\"],[\"79617.00\",\"0.002\"],[\"79617.10\",\"0.030\"],[\"79617.60\",\"0.007\"],[\"79617.80\",\"0.080\"],[\"79618.00\",\"0.003\"],[\"79618.30\",\"0.071\"],[\"79618.70\",\"0.046\"],[\"79618.80\",\"0.203\"],[\"79619.10\",\"0.004\"],[\"79619.50\",\"0.090\"],[\"79620.40\",\"0.894\"],[\"79620.50\",\"0.000\"],[\"79620.70\",\"0.629\"],[\"79620.90\",\"0.000\"],[\"79621.10\",\"0.039\"],[\"79621.40\",\"0.002\"],[\"79621.80\",\"0.002\"],[\"79621.90\",\"0.061\"],[\"79622.10\",\"0.343\"],[\"79622.50\",\"0.032\"],[\"79623.40\",\"0.009\"],[\"79623.50\",\"0.010\"],[\"79623.80\",\"0.005\"],[\"79623.90\",\"0.001\"],[\"79624.00\",\"2.216\"],[\"79624.20\",\"0.013\"],[\"79624.40\",\"0.139\"],[\"79624.70\",\"0.631\"],[\"79624.80\",\"0.007\"],[\"79625.00\",\"0.028\"],[\"79625.10\",\"0.002\"],[\"79625.30\",\"0.003\"],[\"79626.00\",\"0.046\"],[\"79626.10\",\"0.000\"],[\"79626.20\",\"0.037\"],[\"79626.30\",\"0.005\"],[\"79626.70\",\"0.046\"],[\"79627.00\",\"0.052\"],[\"79627.30\",\"0.002\"],[\"79628.10\",\"0.039\"],[\"79628.30\",\"0.001\"],[\"79628.90\",\"0.000\"],[\"79629.20\",\"0.004\"],[\"79629.50\",\"0.000\"],[\"79629.80\",\"0.005\"],[\"79629.90\",\"0.001\"],[\"79631.00\",\"0.673\"],[\"79631.30\",\"0.001\"],[\"79631.60\",\"0.000\"],[\"79631.70\",\"0.001\"],[\"79632.20\",\"0.044\"],[\"79632.80\",\"0.039\"],[\"79633.50\",\"0.001\"],[\"79633.70\",\"0.020\"],[\"79633.80\",\"0.122\"],[\"79634.30\",\"0.000\"],[\"79634.50\",\"1.449\"],[\"79634.60\",\"0.194\"],[\"79634.70\",\"0.000\"],[\"79635.40\",\"0.266\"],[\"79635.90\",\"1.058\"],[\"79637.10\",\"0.252\"],[\"79637.80\",\"0.003\"],[\"79640.90\",\"0.002\"],[\"79641.30\",\"0.058\"],[\"79642.50\",\"0.038\"],[\"79643.10\",\"0.003\"],[\"79644.00\",\"0.007\"],[\"79644.80\",\"0.202\"],[\"79644.90\",\"0.016\"],[\"79645.20\",\"0.038\"],[\"79645.50\",\"0.038\"],[\"79650.00\",\"0.037\"],[\"79651.40\",\"0.038\"],[\"79651.80\",\"0.060\"],[\"79654.80\",\"0.000\"],[\"79655.10\",\"0.041\"],[\"79656.20\",\"0.003\"],[\"79656.60\",\"0.006\"],[\"79656.70\",\"0.064\"],[\"79657.30\",\"0.203\"],[\"79657.60\",\"0.004\"],[\"79657.80\",\"2.355\"],[\"79657.90\",\"0.001\"],[\"79658.00\",\"0.004\"],[\"79658.90\",\"0.000\"],[\"79659.00\",\"0.003\"],[\"79659.40\",\"0.041\"],[\"79659.90\",\"0.064\"],[\"79661.10\",\"0.001\"],[\"79661.20\",\"0.000\"],[\"79662.00\",\"3.503\"],[\"79664.40\",\"0.024\"],[\"79664.50\",\"0.003\"],[\"79664.70\",\"0.014\"],[\"79665.90\",\"0.000\"],[\"79666.10\",\"0.014\"],[\"79666.90\",\"0.001\"],[\"79667.30\",\"0.249\"],[\"79667.40\",\"0.059\"],[\"79667.70\",\"3.138\"],[\"79668.50\",\"5.706\"],[\"79670.20\",\"3.865\"],[\"79671.60\",\"0.013\"],[\"79673.50\",\"0.000\"],[\"79676.40\",\"0.012\"],[\"79676.50\",\"0.000\"],[\"79680.50\",\"0.048\"],[\"79688.80\",\"2.499\"],[\"79689.80\",\"0.062\"],[\"79692.00\",\"3.857\"],[\"79698.90\",\"0.036\"],[\"79704.20\",\"0.002\"],[\"79720.20\",\"1.907\"],[\"79721.10\",\"0.002\"],[\"79746.40\",\"0.000\"],[\"79750.80\",\"0.050\"],[\"79799.80\",\"1.190\"],[\"79799.90\",\"0.002\"],[\"79803.50\",\"3.234\"],[\"79807.40\",\"0.025\"],[\"79821.60\",\"1.190\"],[\"79821.70\",\"0.000\"],[\"79821.90\",\"0.426\"],[\"79822.00\",\"0.196\"],[\"80388.90\",\"0.116\"],[\"80390.20\",\"0.082\"],[\"80587.30\",\"0.016\"],[\"80593.00\",\"0.028\"],[\"80599.30\",\"0.000\"],[\"80620.90\",\"0.002\"],[\"80724.50\",\"0.296\"],[\"81027.00\",\"1.909\"],[\"81184.80\",\"0.006\"]],\"st\":1}}"}
{"receive_ns":1788567554334271000,"stream":"btcusdt@depth@100ms","event_type":"depthUpdate","event_time_ms":1788567554309,"raw_json":"{\"stream\":\"btcusdt@depth@100ms\",\"data\":{\"e\":\"depthUpdate\",\"E\":1788567554309,\"T\":1788567554307,\"s\":\"BTCUSDT\",\"ps\":\"BTCUSDT\",\"U\":11478495986969,\"u\":11478496004047,\"pu\":11478495986880,\"b\":[[\"29192.90\",\"0.329\"],[\"29294.20\",\"1.071\"],[\"71633.60\",\"0.002\"],[\"75613.20\",\"0.005\"],[\"75614.50\",\"0.010\"],[\"76409.10\",\"0.002\"],[\"78647.90\",\"28.979\"],[\"78797.00\",\"0.002\"],[\"79196.20\",\"1.523\"],[\"79399.00\",\"1.112\"],[\"79411.20\",\"0.000\"],[\"79456.80\",\"0.108\"],[\"79497.40\",\"0.002\"],[\"79513.80\",\"0.050\"],[\"79514.30\",\"0.828\"],[\"79515.00\",\"0.002\"],[\"79535.10\",\"0.001\"],[\"79536.40\",\"0.003\"],[\"79537.60\",\"0.000\"],[\"79550.10\",\"0.002\"],[\"79551.00\",\"0.601\"],[\"79555.10\",\"0.346\"],[\"79559.00\",\"0.702\"],[\"79561.90\",\"0.117\"],[\"79564.50\",\"0.127\"],[\"79564.60\",\"0.001\"],[\"79564.70\",\"0.140\"],[\"79566.00\",\"0.004\"],[\"79567.00\",\"0.254\"],[\"79568.90\",\"0.010\"],[\"79569.00\",\"0.002\"],[\"79569.60\",\"0.005\"],[\"79571.00\",\"0.000\"],[\"79571.80\",\"1.967\"],[\"79575.70\",\"0.652\"],[\"79576.70\",\"2.024\"],[\"79576.80\",\"0.194\"],[\"79577.00\",\"0.001\"],[\"79577.50\",\"0.160\"],[\"79581.00\",\"0.000\"],[\"79583.00\",\"0.104\"],[\"79583.40\",\"0.018\"],[\"79583.90\",\"0.000\"],[\"79584.00\",\"0.358\"],[\"79584.10\",\"0.134\"],[\"79584.20\",\"0.001\"],[\"79584.60\",\"0.003\"],[\"79585.10\",\"0.000\"],[\"79585.30\",\"0.000\"],[\"79585.40\",\"0.000\"],[\"79587.00\",\"0.031\"],[\"79587.30\",\"0.030\"],[\"79587.60\",\"0.026\"],[\"79588.30\",\"0.102\"],[\"79588.70\",\"0.026\"],[\"79588.90\",\"0.026\"],[\"79589.20\",\"0.438\"],[\"79592.70\",\"0.006\"],[\"79592.90\",\"1.700\"]],\"a\":[[\"79593.00\",\"15.685\"],[\"79593.10\",\"0.008\"],[\"79594.10\",\"0.000\"],[\"79594.30\",\"0.709\"],[\"79594.40\",\"0.082\"],[\"79598.90\",\"0.267\"],[\"79599.10\",\"0.000\"],[\"79600.00\",\"0.005\"],[\"79600.70\",\"0.006\"],[\"79601.50\",\"0.001\"],[\"79602.50\",\"0.080\"],[\"79602.80\",\"3.507\"],[\"79602.90\",\"2.504\"],[\"79606.30\",\"0.328\"],[\"79606.90\",\"2.120\"],[\"79607.20\",\"0.272\"],[\"79607.40\",\"0.395\"],[\"79607.60\",\"0.182\"],[\"79607.70\",\"0.168\"],[\"79607.80\",\"0.150\"],[\"79610.10\",\"0.046\"],[\"79611.90\",\"0.050\"],[\"79612.60\",\"0.002\"],[\"79615.00\",\"0.011\"],[\"79617.60\",\"0.087\"],[\"79617.90\",\"0.277\"],[\"79618.30\",\"0.001\"],[\"79619.20\",\"0.001\"],[\"79619.80\",\"0.002\"],[\"79621.70\",\"0.546\"],[\"79623.50\",\"0.006\"],[\"79624.70\",\"0.627\"],[\"79626.80\",\"0.292\"],[\"79629.30\",\"0.003\"],[\"79630.50\",\"0.000\"],[\"79637.60\",\"0.010\"],[\"79654.90\",\"0.208\"],[\"79655.30\",\"21.490\"],[\"79655.40\",\"0.012\"],[\"79658.00\",\"0.003\"],[\"79658.10\",\"0.001\"],[\"79667.80\",\"0.076\"],[\"79668.50\",\"2.636\"],[\"79685.40\",\"0.073\"],[\"79748.20\",\"1.877\"],[\"79750.80\",\"0.018\"],[\"79807.40\",\"0.024\"],[\"79980.20\",\"0.019\"],[\"79981.80\",\"0.001\"],[\"80388.90\",\"0.116\"],[\"80954.60\",\"0.005\"],[\"81184.80\",\"0.009\"]],\"st\":1}}"}
{"receive_ns":1788567554387268000,"stream":"btcusdt@depth@100ms","event_type":"depthUpdate","event_time_ms":1788567554411,"raw_json":"{\"stream\":\"btcusdt@depth@100ms\",\"data\":{\"e\":\"depthUpdate\",\"E\":1788567554411,\"T\":1788567554410,\"s\":\"BTCUSDT\",\"ps\":\"BTCUSDT\",\"U\":11478496004204,\"u\":11478496014242,\"pu\":11478496004047,\"b\":[[\"1000.00\",\"24.604\"],[\"29192.90\",\"0.511\"],[\"29294.20\",\"0.889\"],[\"63674.00\",\"0.000\"],[\"71633.60\",\"0.002\"],[\"76409.10\",\"0.000\"],[\"78091.80\",\"0.004\"],[\"78091.90\",\"2.660\"],[\"78423.00\",\"1.555\"],[\"78518.40\",\"0.597\"],[\"78797.00\",\"0.002\"],[\"79497.40\",\"0.000\"],[\"79521.30\",\"0.003\"],[\"79538.40\",\"0.072\"],[\"79553.20\",\"0.002\"],[\"79554.40\",\"0.002\"],[\"79558.90\",\"0.001\"],[\"79562.70\",\"0.126\"],[\"79563.90\",\"0.884\"],[\"79564.50\",\"0.002\"],[\"79564.70\",\"0.140\"],[\"79571.40\",\"0.002\"],[\"79576.70\",\"1.710\"],[\"79576.80\",\"0.128\"],[\"79577.70\",\"0.080\"],[\"79578.50\",\"0.256\"],[\"79581.00\",\"0.380\"],[\"79583.80\",\"0.072\"],[\"79584.90\",\"0.038\"],[\"79585.60\",\"0.002\"],[\"79589.40\",\"0.026\"],[\"79592.80\",\"0.000\"],[\"79592.90\",\"1.764\"]],\"a\":[[\"79593.10\",\"0.010\"],[\"79594.30\",\"0.708\"],[\"79599.60\",\"0.020\"],[\"79604.70\",\"0.043\"],[\"79604.90\",\"1.340\"],[\"79605.10\",\"0.383\"],[\"79605.80\",\"0.111\"],[\"79606.60\",\"0.702\"],[\"79606.80\",\"0.471\"],[\"79607.50\",\"0.154\"],[\"79609.50\",\"0.040\"],[\"79609.80\",\"0.001\"],[\"79610.60\",\"0.258\"],[\"79611.30\",\"0.001\"],[\"79612.00\",\"0.003\"],[\"79612.20\",\"0.205\"],[\"79614.60\",\"0.002\"],[\"79615.40\",\"4.578\"],[\"79620.80\",\"0.126\"],[\"79638.70\",\"0.340\"],[\"79640.20\",\"0.011\"],[\"79663.00\",\"0.000\"],[\"79678.30\",\"0.001\"],[\"79689.90\",\"6.002\"],[\"79729.70\",\"0.004\"],[\"80388.90\",\"0.116\"],[\"80509.10\",\"0.738\"],[\"80510.40\",\"17.728\"],[\"80549.40\",\"11.775\"],[\"80589.20\",\"1.705\"],[\"80756.40\",\"0.247\"]],\"st\":1}}"}
{"receive_ns":1788567554485285000,"stream":"btcusdt@depth@100ms","event_type":"depthUpdate","event_time_ms":1788567554513,"raw_json":"{\"stream\":\"btcusdt@depth@100ms\",\"data\":{\"e\":\"depthUpdate\",\"E\":1788567554513,\"T\":1788567554509,\"s\":\"BTCUSDT\",\"ps\":\"BTCUSDT\",\"U\":11478496014352,\"u\":11478496024389,\"pu\":11478496014242,\"b\":[[\"1000.00\",\"24.604\"],[\"29192.90\",\"0.686\"],[\"29294.20\",\"0.714\"],[\"71633.60\",\"0.002\"],[\"78001.10\",\"0.003\"],[\"78797.00\",\"0.002\"],[\"79564.00\",\"0.005\"],[\"79572.00\",\"0.006\"],[\"79576.80\",\"0.002\"],[\"79577.30\",\"0.002\"],[\"79581.20\",\"0.001\"],[\"79582.60\",\"0.073\"],[\"79586.40\",\"0.003\"],[\"79587.90\",\"0.003\"],[\"79591.70\",\"0.000\"],[\"79592.90\",\"2.204\"]],\"a\":[[\"79593.00\",\"15.692\"],[\"79594.30\",\"0.702\"],[\"79598.30\",\"0.001\"],[\"79603.40\",\"0.077\"],[\"79604.10\",\"0.003\"],[\"79607.30\",\"0.402\"],[\"79607.50\",\"0.308\"],[\"79608.00\",\"0.713\"],[\"79608.70\",\"0.007\"],[\"79609.50\",\"0.000\"],[\"79610.10\",\"0.004\"],[\"79610.60\",\"0.260\"],[\"79611.50\",\"0.246\"],[\"79611.80\",\"0.077\"],[\"79612.10\",\"0.520\"],[\"79612.20\",\"0.005\"],[\"79612.30\",\"0.200\"],[\"79612.40\",\"0.000\"],[\"79612.50\",\"0.231\"],[\"79612.70\",\"0.000\"],[\"79625.00\",\"0.148\"],[\"79633.80\",\"0.002\"],[\"79634.50\",\"1.447\"],[\"79654.30\",\"1.594\"],[\"79655.30\",\"0.002\"],[\"79660.70\",\"21.491\"],[\"79744.20\",\"0.503\"],[\"79748.20\",\"1.845\"],[\"79754.10\",\"0.032\"],[\"80509.10\",\"1.476\"],[\"80510.40\",\"16.990\"],[\"80549.60\",\"11.468\"],[\"83122.80\",\"0.000\"],[\"83131.30\",\"0.100\"],[\"83546.10\",\"0.000\"]],\"st\":1}}"}
{"receive_ns":1788567554591353000,"stream":"btcusdt@depth@100ms","event_type":"depthUpdate","event_time_ms":1788567554615,"raw_json":"{\"stream\":\"btcusdt@depth@100ms\",\"data\":{\"e\":\"depthUpdate\",\"E\":1788567554615,\"T\":1788567554614,\"s\":\"BTCUSDT\",\"ps\":\"BTCUSDT\",\"U\":11478496024692,\"u\":11478496039235,\"pu\":11478496024389,\"b\":[[\"29192.90\",\"0.868\"],[\"29294.20\",\"0.532\"],[\"63674.00\",\"0.000\"],[\"63675.00\",\"0.004\"],[\"71633.60\",\"0.002\"],[\"75613.30\",\"0.002\"],[\"76409.10\",\"0.002\"],[\"78247.90\",\"0.515\"],[\"78797.00\",\"0.002\"],[\"79196.20\",\"1.522\"],[\"79427.90\",\"0.513\"],[\"79525.90\",\"20.442\"],[\"79527.60\",\"4.136\"],[\"79528.90\",\"0.000\"],[\"79529.40\",\"3.707\"],[\"79533.90\",\"0.201\"],[\"79537.90\",\"0.224\"],[\"79541.70\",\"0.007\"],[\"79549.70\",\"0.015\"],[\"79549.80\",\"0.001\"],[\"79554.50\",\"0.003\"],[\"79562.20\",\"0.003\"],[\"79563.00\",\"0.702\"],[\"79564.00\",\"0.005\"],[\"79566.20\",\"0.023\"],[\"79566.60\",\"0.133\"],[\"79567.80\",\"2.166\"],[\"79571.70\",\"0.980\"],[\"79572.00\",\"0.006\"],[\"79572.10\",\"0.002\"],[\"79572.60\",\"1.886\"],[\"79575.60\",\"0.002\"],[\"79575.70\",\"0.632\"],[\"79576.80\",\"0.002\"],[\"79577.20\",\"0.080\"],[\"79579.50\",\"0.002\"],[\"79580.10\",\"0.135\"],[\"79580.30\",\"0.004\"],[\"79581.00\",\"0.380\"],[\"79582.60\",\"0.071\"],[\"79583.40\",\"0.017\"],[\"79585.00\",\"0.004\"],[\"79585.10\",\"0.000\"],[\"79585.30\",\"0.000\"],[\"79585.40\",\"0.026\"],[\"79585.50\",\"0.102\"],[\"79585.60\",\"0.028\"],[\"79585.70\",\"0.026\"],[\"79585.80\",\"0.026\"],[\"79585.90\",\"0.001\"],[\"79586.10\",\"0.027\"],[\"79586.20\",\"0.001\"],[\"79586.30\",\"0.000\"],[\"79586.40\",\"0.029\"],[\"79586.70\",\"0.027\"],[\"79586.90\",\"0.000\"],[\"79587.00\",\"0.005\"],[\"79587.20\",\"0.032\"],[\"79587.30\",\"0.029\"],[\"79587.60\",\"0.000\"],[\"79587.70\",\"0.006\"],[\"79588.20\",\"0.002\"],[\"79588.30\",\"0.076\"],[\"79588.70\",\"0.000\"],[\"79588.90\",\"0.000\"],[\"79589.20\",\"0.412\"],[\"79589.40\",\"0.000\"],[\"79590.50\",\"0.012\"],[\"79591.70\",\"0.000\"],[\"79592.30\",\"0.077\"],[\"79592.90\",\"1.765\"]],\"a\":[[\"79593.00\",\"15.694\"],[\"79596.50\",\"0.072\"],[\"79598.10\",\"0.272\"],[\"79599.10\",\"0.000\"],[\"79599.30\",\"0.207\"],[\"79600.40\",\"0.076\"],[\"79602.30\",\"0.264\"],[\"79607.10\",\"0.152\"],[\"79609.60\",\"0.000\"],[\"79611.00\",\"0.282\"],[\"79611.10\",\"1.662\"],[\"79611.40\",\"0.021\"],[\"79611.50\",\"0.092\"],[\"79612.30\",\"0.000\"],[\"79612.50\",\"0.155\"],[\"79613.60\",\"0.001\"],[\"79614.70\",\"1.053\"],[\"79615.00\",\"0.639\"],[\"79616.50\",\"0.710\"],[\"79616.90\",\"0.134\"],[\"79617.20\",\"0.050\"],[\"79618.60\",\"0.002\"],[\"79621.70\",\"0.568\"],[\"79622.90\",\"0.285\"],[\"79625.40\",\"0.447\"],[\"79626.20\",\"0.006\"],[\"79626.40\",\"0.000\"],[\"79626.80\",\"0.222\"],[\"79627.00\",\"0.002\"],[\"79634.50\",\"1.447\"],[\"79640.90\",\"0.015\"],[\"79642.00\",\"0.002\"],[\"79643.60\",\"0.258\"],[\"79645.70\",\"0.001\"],[\"79646.10\",\"0.231\"],[\"79655.20\",\"0.340\"],[\"79655.40\",\"0.011\"],[\"79656.40\",\"0.000\"],[\"79656.60\",\"0.216\"],[\"79658.00\",\"21.394\"],[\"79658.20\",\"0.016\"],[\"79660.70\",\"0.002\"],[\"79667.30\",\"0.039\"],[\"79669.60\",\"0.000\"],[\"79690.80\",\"0.150\"],[\"79750.80\",\"0.050\"],[\"79753.70\",\"0.695\"],[\"79754.10\",\"0.000\"],[\"79798.50\",\"0.007\"],[\"80388.90\",\"0.116\"],[\"80509.10\",\"3.690\"],[\"80510.40\",\"14.770\"],[\"80588.70\",\"1.228\"],[\"80590.00\",\"5.565\"],[\"83121.60\",\"0.100\"],[\"83131.30\",\"0.000\"]],\"st\":1}}"}
{"receive_ns":1788567554689737000,"stream":"btcusdt@depth@100ms","event_type":"depthUpdate","event_time_ms":1788567554717,"raw_json":"{\"stream\":\"btcusdt@depth@100ms\",\"data\":{\"e\":\"depthUpdate\",\"E\":1788567554717,\"T\":1788567554714,\"s\":\"BTCUSDT\",\"ps\":\"BTCUSDT\",\"U\":11478496039655,\"u\":11478496055369,\"pu\":11478496039235,\"b\":[[\"1000.00\",\"24.604\"],[\"29192.90\",\"1.043\"],[\"29294.20\",\"0.357\"],[\"63674.30\",\"0.000\"],[\"63675.00\",\"0.002\"],[\"71633.60\",\"0.002\"],[\"76409.10\",\"0.000\"],[\"78797.00\",\"0.002\"],[\"78814.80\",\"2.261\"],[\"78827.90\",\"0.000\"],[\"78890.00\",\"0.055\"],[\"78890.20\",\"0.000\"],[\"78905.90\",\"0.001\"],[\"79533.20\",\"1.145\"],[\"79535.10\",\"0.001\"],[\"79545.80\",\"0.000\"],[\"79549.00\",\"1.351\"],[\"79550.10\",\"0.001\"],[\"79551.00\",\"0.601\"],[\"79555.20\",\"0.281\"],[\"79560.20\",\"0.041\"],[\"79564.90\",\"0.003\"],[\"79566.00\",\"0.003\"],[\"79570.50\",\"0.002\"],[\"79575.70\",\"0.633\"],[\"79576.70\",\"1.712\"],[\"79576.80\",\"0.382\"],[\"79576.90\",\"1.339\"],[\"79577.00\",\"0.143\"],[\"79577.20\",\"0.084\"],[\"79579.50\",\"0.002\"],[\"79579.90\",\"0.001\"],[\"79580.00\",\"0.141\"],[\"79580.90\",\"1.606\"],[\"79581.00\",\"0.000\"],[\"79581.60\",\"0.002\"],[\"79583.00\",\"0.102\"],[\"79583.10\",\"0.172\"],[\"79583.40\",\"0.003\"],[\"79584.80\",\"0.001\"],[\"79585.40\",\"0.000\"],[\"79585.50\",\"0.076\"],[\"79586.20\",\"0.000\"],[\"79586.30\",\"0.025\"],[\"79586.50\",\"1.032\"],[\"79587.10\",\"0.026\"],[\"79587.30\",\"0.029\"],[\"79587.40\",\"0.026\"],[\"79587.60\",\"0.026\"],[\"79587.80\",\"0.000\"],[\"79590.00\",\"0.443\"],[\"79591.30\",\"0.150\"],[\"79592.90\",\"1.596\"]],\"a\":[[\"79593.00\",\"15.725\"],[\"79594.30\",\"0.681\"],[\"79596.50\",\"0.026\"],[\"79602.80\",\"3.633\"],[\"79606.70\",\"0.005\"],[\"79610.40\",\"0.082\"],[\"79612.10\",\"0.373\"],[\"79612.50\",\"0.001\"],[\"79633.70\",\"0.240\"],[\"79641.30\",\"0.278\"],[\"79655.30\",\"21.393\"],[\"79658.00\",\"0.003\"],[\"79658.10\",\"0.002\"],[\"79659.10\",\"0.042\"],[\"79750.00\",\"1.277\"],[\"79750.80\",\"0.018\"],[\"79991.00\",\"0.001\"],[\"80388.90\",\"0.116\"],[\"80588.70\",\"1.842\"],[\"80590.00\",\"4.945\"],[\"80684.20\",\"0.094\"],[\"81184.80\",\"0.012\"]],\"st\":1}}"}
{"receive_ns":1788567554788657000,"stream":"btcusdt@depth@100ms","event_type":"depthUpdate","event_time_ms":1788567554819,"raw_json":"{\"stream\":\"btcusdt@depth@100ms\",\"data\":{\"e\":\"depthUpdate\",\"E\":1788567554819,\"T\":1788567554818,\"s\":\"BTCUSDT\",\"ps\":\"BTCUSDT\",\"U\":11478496055572,\"u\":11478496067093,\"pu\":11478496055369,\"b\":[[\"1000.00\",\"24.604\"],[\"29092.90\",\"0.056\"],[\"29192.90\",\"1.169\"],[\"29194.20\",\"0.644\"],[\"29294.20\",\"0.231\"],[\"71633.60\",\"0.002\"],[\"76409.10\",\"0.002\"],[\"78518.50\",\"0.611\"],[\"78797.00\",\"0.002\"],[\"78836.90\",\"0.569\"],[\"78887.70\",\"0.000\"],[\"79464.80\",\"0.519\"],[\"79466.10\",\"0.000\"],[\"79554.00\",\"0.008\"],[\"79555.80\",\"0.000\"],[\"79557.00\",\"0.254\"],[\"79559.00\",\"0.002\"],[\"79561.40\",\"0.048\"],[\"79562.10\",\"0.046\"],[\"79563.00\",\"0.002\"],[\"79564.00\",\"0.705\"],[\"79564.10\",\"0.453\"],[\"79565.10\",\"0.001\"],[\"79565.60\",\"0.004\"],[\"79565.80\",\"0.003\"],[\"79567.80\",\"2.167\"],[\"79568.50\",\"0.560\"],[\"79569.20\",\"0.067\"],[\"79570.90\",\"0.002\"],[\"79571.70\",\"0.981\"],[\"79571.80\",\"1.594\"],[\"79572.20\",\"0.377\"],[\"79575.60\",\"0.003\"],[\"79575.80\",\"0.000\"],[\"79576.40\",\"3.029\"],[\"79576.60\",\"0.003\"],[\"79576.80\",\"0.320\"],[\"79577.10\",\"0.064\"],[\"79579.50\",\"0.003\"],[\"79580.60\",\"0.000\"],[\"79583.40\",\"0.004\"],[\"79583.70\",\"0.034\"],[\"79584.90\",\"0.040\"],[\"79585.60\",\"0.002\"],[\"79587.30\",\"0.030\"],[\"79587.80\",\"0.026\"],[\"79588.80\",\"0.005\"],[\"79589.20\",\"0.915\"],[\"79592.70\",\"0.009\"]],\"a\":[[\"79593.20\",\"0.101\"],[\"79594.40\",\"0.081\"],[\"79598.10\",\"0.196\"],[\"79600.60\",\"0.000\"],[\"79601.10\",\"0.291\"],[\"79604.80\",\"0.000\"],[\"79606.50\",\"0.691\"],[\"79607.00\",\"4.073\"],[\"79608.00\",\"0.013\"],[\"79609.10\",\"0.002\"],[\"79610.10\",\"0.007\"],[\"79610.80\",\"0.005\"],[\"79611.50\",\"0.089\"],[\"79612.10\",\"0.373\"],[\"79614.60\",\"0.002\"],[\"79615.00\",\"0.633\"],[\"79615.70\",\"0.455\"],[\"79616.20\",\"0.001\"],[\"79617.60\",\"0.093\"],[\"79621.60\",\"0.008\"],[\"79623.50\",\"0.000\"],[\"79625.20\",\"0.001\"],[\"79626.70\",\"0.046\"],[\"79640.10\",\"1.337\"],[\"79640.50\",\"0.170\"],[\"79642.20\",\"0.014\"],[\"79651.10\",\"0.002\"],[\"79655.40\",\"0.012\"],[\"79658.10\",\"0.001\"],[\"79690.80\",\"0.148\"],[\"79715.00\",\"0.460\"],[\"79716.30\",\"1.124\"],[\"79748.20\",\"1.877\"],[\"79750.00\",\"1.245\"],[\"80388.90\",\"0.116\"],[\"80509.10\",\"4.428\"],[\"80510.40\",\"14.032\"],[\"80558.40\",\"16.036\"],[\"80588.70\",\"2.456\"],[\"80590.00\",\"4.331\"],[\"81821.60\",\"0.244\"]],\"st\":1}}"}
{"receive_ns":1788567554891906000,"stream":"btcusdt@depth@100ms","event_type":"depthUpdate","event_time_ms":1788567554921,"raw_json":"{\"stream\":\"btcusdt@depth@100ms\",\"data\":{\"e\":\"depthUpdate\",\"E\":1788567554921,\"T\":1788567554918,\"s\":\"BTCUSDT\",\"ps\":\"BTCUSDT\",\"U\":11478496067309,\"u\":11478496082856,\"pu\":11478496067093,\"b\":[[\"29092.90\",\"0.119\"],[\"29192.90\",\"1.281\"],[\"29194.20\",\"0.581\"],[\"29294.20\",\"0.119\"],[\"63674.00\",\"0.000\"],[\"71633.60\",\"0.002\"],[\"76409.10\",\"0.000\"],[\"78637.90\",\"1.272\"],[\"78797.00\",\"0.002\"],[\"79194.90\",\"0.167\"],[\"79196.20\",\"1.512\"],[\"79314.40\",\"3.537\"],[\"79316.00\",\"0.929\"],[\"79462.80\",\"0.000\"],[\"79561.40\",\"0.002\"],[\"79561.90\",\"0.110\"],[\"79564.10\",\"0.001\"],[\"79564.60\",\"0.047\"],[\"79564.90\",\"0.003\"],[\"79565.40\",\"0.044\"],[\"79567.10\",\"0.452\"],[\"79568.50\",\"0.075\"],[\"79569.20\",\"0.506\"],[\"79570.70\",\"0.006\"],[\"79571.80\",\"1.588\"],[\"79571.90\",\"2.205\"],[\"79572.20\",\"0.004\"],[\"79572.80\",\"0.008\"],[\"79574.10\",\"0.376\"],[\"79576.00\",\"0.008\"],[\"79576.80\",\"0.316\"],[\"79577.00\",\"0.143\"],[\"79577.10\",\"0.068\"],[\"79578.60\",\"0.000\"],[\"79583.20\",\"0.254\"],[\"79583.70\",\"0.060\"],[\"79583.80\",\"0.098\"],[\"79583.90\",\"0.026\"],[\"79584.00\",\"0.132\"],[\"79584.20\",\"0.027\"],[\"79584.30\",\"0.028\"],[\"79584.40\",\"0.115\"],[\"79584.50\",\"0.068\"],[\"79584.60\",\"0.029\"],[\"79584.90\",\"0.036\"],[\"79585.40\",\"0.000\"],[\"79585.50\",\"0.076\"],[\"79585.60\",\"0.002\"],[\"79585.70\",\"0.000\"],[\"79585.80\",\"0.000\"],[\"79586.00\",\"0.004\"],[\"79586.10\",\"0.001\"],[\"79586.30\",\"0.025\"],[\"79586.40\",\"0.003\"],[\"79586.70\",\"0.001\"],[\"79587.20\",\"0.005\"],[\"79587.30\",\"0.004\"],[\"79587.40\",\"0.000\"],[\"79587.60\",\"0.000\"],[\"79587.80\",\"0.000\"],[\"79587.90\",\"0.002\"],[\"79590.10\",\"0.001\"],[\"79591.60\",\"0.002\"],[\"79592.90\",\"1.345\"]],\"a\":[[\"79593.00\",\"15.756\"],[\"79596.00\",\"0.105\"],[\"79597.90\",\"0.078\"],[\"79598.40\",\"0.003\"],[\"79599.10\",\"0.000\"],[\"79600.20\",\"0.002\"],[\"79600.70\",\"0.006\"],[\"79602.80\",\"3.632\"],[\"79606.50\",\"0.252\"],[\"79608.50\",\"0.440\"],[\"79608.70\",\"0.008\"],[\"79610.20\",\"0.003\"],[\"79611.40\",\"0.020\"],[\"79612.10\",\"0.001\"],[\"79614.00\",\"0.374\"],[\"79615.70\",\"0.003\"],[\"79616.50\",\"0.640\"],[\"79617.50\",\"0.452\"],[\"79620.30\",\"0.006\"],[\"79621.60\",\"0.002\"],[\"79626.70\",\"0.000\"],[\"79628.40\",\"0.046\"],[\"79629.60\",\"0.076\"],[\"79646.40\",\"0.001\"],[\"79748.20\",\"1.845\"],[\"79750.80\",\"0.050\"],[\"80388.90\",\"0.116\"],[\"80390.20\",\"0.330\"],[\"80588.70\",\"3.070\"],[\"80590.00\",\"3.717\"],[\"80628.90\",\"1.857\"],[\"80724.50\",\"0.444\"],[\"80757.40\",\"12.417\"]],\"st\":1}}"}
{"receive_ns":1788567554992606000,"stream":"btcusdt@depth@100ms","event_type":"depthUpdate","event_time_ms":1788567555023,"raw_json":"{\"stream\":\"btcusdt@depth@100ms\",\"data\":{\"e\":\"depthUpdate\",\"E\":1788567555023,\"T\":1788567555021,\"s\":\"BTCUSDT\",\"ps\":\"BTCUSDT\",\"U\":11478496083269,\"u\":11478496099461,\"pu\":11478496082856,\"b\":[[\"1000.00\",\"24.604\"],[\"29092.90\",\"0.189\"],[\"29192.90\",\"1.393\"],[\"29194.20\",\"0.511\"],[\"29294.20\",\"0.007\"],[\"63675.00\",\"0.002\"],[\"71633.60\",\"0.002\"],[\"71670.00\",\"0.000\"],[\"78478.70\",\"0.385\"],[\"78797.00\",\"0.002\"],[\"79196.20\",\"1.511\"],[\"79374.90\",\"0.005\"],[\"79381.50\",\"0.073\"],[\"79562.70\",\"0.001\"],[\"79563.00\",\"0.048\"],[\"79563.10\",\"0.258\"],[\"79563.80\",\"0.001\"],[\"79564.60\",\"0.001\"],[\"79565.60\",\"0.456\"],[\"79567.10\",\"0.000\"],[\"79567.80\",\"2.173\"],[\"79568.90\",\"0.004\"],[\"79572.40\",\"0.376\"],[\"79574.10\",\"0.003\"],[\"79581.40\",\"0.001\"],[\"79583.40\",\"0.004\"],[\"79583.50\",\"0.000\"],[\"79583.60\",\"0.000\"],[\"79583.70\",\"0.034\"],[\"79583.80\",\"0.072\"],[\"79583.90\",\"0.002\"],[\"79584.00\",\"0.132\"],[\"79584.20\",\"0.029\"],[\"79584.30\",\"0.026\"],[\"79584.40\",\"0.089\"],[\"79584.50\",\"0.066\"],[\"79584.60\",\"0.003\"],[\"79584.80\",\"0.001\"],[\"79584.90\",\"0.036\"],[\"79585.00\",\"0.004\"],[\"79585.10\",\"0.026\"],[\"79585.20\",\"0.027\"],[\"79585.30\",\"0.000\"],[\"79585.40\",\"0.026\"],[\"79585.50\",\"0.102\"],[\"79585.70\",\"0.026\"],[\"79587.30\",\"0.030\"],[\"79590.00\",\"0.004\"],[\"79591.00\",\"0.440\"],[\"79592.90\",\"1.195\"]],\"a\":[[\"79593.00\",\"15.511\"],[\"79596.00\",\"0.029\"],[\"79596.70\",\"0.877\"],[\"79597.00\",\"0.045\"],[\"79599.10\",\"0.004\"],[\"79599.20\",\"2.501\"],[\"79600.70\",\"0.002\"],[\"79602.80\",\"3.633\"],[\"79606.50\",\"0.691\"],[\"79608.50\",\"0.001\"],[\"79612.00\",\"0.375\"],[\"79612.80\",\"0.002\"],[\"79614.00\",\"0.002\"],[\"79626.80\",\"0.268\"],[\"79628.40\",\"0.000\"],[\"79641.00\",\"0.148\"],[\"79744.20\",\"0.535\"],[\"79750.80\",\"0.018\"],[\"80388.90\",\"0.116\"],[\"80509.10\",\"5.166\"],[\"80510.40\",\"13.294\"],[\"80558.30\",\"15.389\"],[\"80558.40\",\"14.796\"],[\"80717.60\",\"30.122\"],[\"82436.60\",\"0.055\"]],\"st\":1}}"}
{"receive_ns":1788567555093972000,"stream":"btcusdt@depth@100ms","event_type":"depthUpdate","event_time_ms":1788567555125,"raw_json":"{\"stream\":\"btcusdt@depth@100ms\",\"data\":{\"e\":\"depthUpdate\",\"E\":1788567555125,\"T\":1788567555124,\"s\":\"BTCUSDT\",\"ps\":\"BTCUSDT\",\"U\":11478496099759,\"u\":11478496114850,\"pu\":11478496099461,\"b\":[[\"1000.00\",\"24.604\"],[\"29092.90\",\"0.357\"],[\"29192.90\",\"1.400\"],[\"29194.20\",\"0.343\"],[\"29294.20\",\"0.000\"],[\"63674.00\",\"0.000\"],[\"71633.60\",\"0.002\"],[\"75614.50\",\"0.008\"],[\"75614.60\",\"0.002\"],[\"76409.10\",\"0.002\"],[\"78369.30\",\"3.566\"],[\"78448.80\",\"0.127\"],[\"78797.00\",\"0.002\"],[\"79470.90\",\"0.008\"],[\"79471.10\",\"0.003\"],[\"79473.40\",\"0.001\"],[\"79487.30\",\"0.002\"],[\"79562.80\",\"0.125\"],[\"79563.10\",\"0.133\"],[\"79578.60\",\"0.000\"],[\"79584.00\",\"0.106\"],[\"79584.20\",\"0.003\"],[\"79584.30\",\"0.000\"],[\"79587.40\",\"0.026\"],[\"79587.70\",\"0.032\"],[\"79587.90\",\"0.028\"],[\"79592.90\",\"1.448\"]],\"a\":[[\"79593.00\",\"15.559\"],[\"79594.30\",\"0.660\"],[\"79596.70\",\"0.923\"],[\"79612.00\",\"0.003\"],[\"79612.40\",\"0.372\"],[\"79688.60\",\"0.019\"],[\"79829.10\",\"0.003\"],[\"79829.20\",\"0.028\"],[\"79991.00\",\"0.002\"],[\"80388.90\",\"0.116\"],[\"80509.10\",\"5.904\"],[\"80510.40\",\"12.556\"],[\"80719.70\",\"0.000\"],[\"80739.50\",\"0.000\"],[\"80747.10\",\"0.870\"],[\"80819.10\",\"0.021\"],[\"81186.10\",\"4.068\"]],\"st\":1}}"}
{"receive_ns":1788567555195638000,"stream":"btcusdt@depth@100ms","event_type":"depthUpdate","event_time_ms":1788567555227,"raw_json":"{\"stream\":\"btcusdt@depth@100ms\",\"data\":{\"e\":\"depthUpdate\",\"E\":1788567555227,\"T\":1788567555226,\"s\":\"BTCUSDT\",\"ps\":\"BTCUSDT\",\"U\":11478496115085,\"u\":11478496131466,\"pu\":11478496114850,\"b\":[[\"29092.90\",\"0.539\"],[\"29194.20\",\"0.161\"],[\"71633.60\",\"0.002\"],[\"76409.10\",\"0.000\"],[\"78160.20\",\"1.149\"],[\"78368.10\",\"0.007\"],[\"78447.60\",\"0.007\"],[\"78797.00\",\"0.002\"],[\"78916.50\",\"1.076\"],[\"79194.90\",\"0.167\"],[\"79448.90\",\"0.032\"],[\"79455.60\",\"0.000\"],[\"79572.40\",\"0.396\"],[\"79574.20\",\"0.139\"],[\"79589.50\",\"0.003\"],[\"79591.00\",\"0.001\"]],\"a\":[[\"79593.00\",\"15.567\"],[\"79744.20\",\"0.503\"],[\"79750.80\",\"0.050\"],[\"80388.90\",\"0.116\"],[\"80509.10\",\"6.642\"],[\"80510.40\",\"11.818\"],[\"80738.30\",\"0.017\"],[\"80817.90\",\"0.009\"]],\"st\":1}}"}
{"receive_ns":1788567555304288000,"stream":"btcusdt@depth@100ms","event_type":"depthUpdate","event_time_ms":1788567555329,"raw_json":"{\"stream\":\"btcusdt@depth@100ms\",\"data\":{\"e\":\"depthUpdate\",\"E\":1788567555329,\"T\":1788567555327,\"s\":\"BTCUSDT\",\"ps\":\"BTCUSDT\",\"U\":11478496131657,\"u\":11478496142477,\"pu\":11478496131466,\"b\":[[\"1000.00\",\"24.604\"],[\"29092.90\",\"0.714\"],[\"29192.90\",\"1.386\"],[\"29194.20\",\"0.000\"],[\"71633.60\",\"0.002\"],[\"76409.10\",\"0.002\"],[\"78478.60\",\"0.255\"],[\"78647.80\",\"9.847\"],[\"78797.00\",\"0.002\"],[\"78814.80\",\"1.696\"],[\"79464.80\",\"0.013\"],[\"79555.30\",\"1.753\"],[\"79589.50\",\"0.442\"]],\"a\":[[\"79593.00\",\"15.566\"],[\"79614.40\",\"0.007\"],[\"79617.60\",\"0.087\"],[\"79658.00\",\"0.005\"],[\"79715.00\",\"0.021\"],[\"79747.20\",\"0.049\"],[\"79750.80\",\"0.018\"],[\"80388.90\",\"0.116\"],[\"80509.10\",\"7.380\"],[\"80510.40\",\"11.080\"],[\"80549.40\",\"12.394\"],[\"80588.70\",\"4.298\"],[\"80590.00\",\"2.489\"],[\"81081.40\",\"0.502\"]],\"st\":1}}"}
{"receive_ns":1788567555402819000,"stream":"btcusdt@depth@100ms","event_type":"depthUpdate","event_time_ms":1788567555431,"raw_json":"{\"stream\":\"btcusdt@depth@100ms\",\"data\":{\"e\":\"depthUpdate\",\"E\":1788567555431,\"T\":1788567555429,\"s\":\"BTCUSDT\",\"ps\":\"BTCUSDT\",\"U\":11478496142903,\"u\":11478496153392,\"pu\":11478496142477,\"b\":[[\"1000.00\",\"24.604\"],[\"29092.90\",\"0.896\"],[\"29192.90\",\"1.204\"],[\"71633.60\",\"0.002\"],[\"76409.10\",\"0.000\"],[\"77327.60\",\"1.294\"],[\"78797.00\",\"0.636\"],[\"79426.70\",\"0.001\"],[\"79427.90\",\"0.192\"],[\"79448.90\",\"0.000\"],[\"79449.70\",\"0.040\"],[\"79562.80\",\"0.125\"],[\"79563.50\",\"1.621\"],[\"79585.00\",\"0.030\"],[\"79587.40\",\"0.000\"],[\"79587.70\",\"0.006\"],[\"79587.90\",\"0.002\"]],\"a\":[[\"79593.90\",\"0.002\"],[\"79596.50\",\"0.102\"],[\"79742.80\",\"0.033\"],[\"79747.20\",\"0.017\"],[\"79753.70\",\"0.442\"],[\"79755.70\",\"0.000\"],[\"80388.90\",\"0.116\"],[\"80390.20\",\"0.951\"],[\"80509.10\",\"8.118\"],[\"80510.40\",\"10.342\"],[\"80549.60\",\"11.319\"],[\"80587.90\",\"0.469\"],[\"80588.70\",\"4.912\"],[\"80590.00\",\"1.875\"],[\"81184.80\",\"0.015\"]],\"st\":1}}"}
{"receive_ns":1788567555503691000,"stream":"btcusdt@depth@100ms","event_type":"depthUpdate","event_time_ms":1788567555533,"raw_json":"{\"stream\":\"btcusdt@depth@100ms\",\"data\":{\"e\":\"depthUpdate\",\"E\":1788567555533,\"T\":1788567555531,\"s\":\"BTCUSDT\",\"ps\":\"BTCUSDT\",\"U\":11478496153562,\"u\":11478496163455,\"pu\":11478496153392,\"b\":[[\"29092.90\",\"1.071\"],[\"29192.90\",\"1.029\"],[\"71633.60\",\"0.002\"],[\"78002.40\",\"0.009\"],[\"78425.40\",\"1.224\"],[\"78430.80\",\"0.382\"],[\"78550.00\",\"6.622\"],[\"78571.10\",\"1.890\"],[\"78574.60\",\"0.015\"],[\"78594.10\",\"0.000\"],[\"78599.20\",\"0.007\"],[\"78617.10\",\"0.001\"],[\"78797.00\",\"0.636\"],[\"78836.80\",\"0.955\"],[\"79194.90\",\"0.157\"],[\"79379.00\",\"0.000\"],[\"79448.90\",\"0.032\"],[\"79449.70\",\"0.008\"],[\"79485.90\",\"0.196\"],[\"79562.50\",\"0.673\"],[\"79562.60\",\"0.001\"],[\"79562.80\",\"0.000\"],[\"79563.50\",\"1.621\"],[\"79589.50\",\"0.003\"],[\"79590.10\",\"0.000\"],[\"79590.40\",\"0.441\"],[\"79592.90\",\"1.449\"]],\"a\":[[\"79593.00\",\"15.558\"],[\"79742.80\",\"0.001\"],[\"79749.30\",\"0.034\"],[\"79803.50\",\"0.001\"],[\"80388.90\",\"0.116\"],[\"80389.00\",\"0.015\"],[\"80509.10\",\"9.594\"],[\"80510.40\",\"8.866\"],[\"80588.70\",\"5.526\"],[\"80590.00\",\"1.261\"],[\"80612.00\",\"0.000\"]],\"st\":1}}"}
{"receive_ns":1788567555608635000,"stream":"btcusdt@depth@100ms","event_type":"depthUpdate","event_time_ms":1788567555635,"raw_json":"{\"stream\":\"btcusdt@depth@100ms\",\"data\":{\"e\":\"depthUpdate\",\"E\":1788567555635,\"T\":1788567555633,\"s\":\"BTCUSDT\",\"ps\":\"BTCUSDT\",\"U\":11478496163626,\"u\":11478496176310,\"pu\":11478496163455,\"b\":[[\"1000.00\",\"24.604\"],[\"29092.90\",\"1.253\"],[\"29192.90\",\"0.847\"],[\"71633.60\",\"0.002\"],[\"76409.10\",\"0.002\"],[\"78637.80\",\"4.444\"],[\"78797.00\",\"0.636\"],[\"78880.50\",\"0.019\"],[\"78881.80\",\"0.000\"],[\"79077.70\",\"0.250\"],[\"79079.00\",\"0.022\"],[\"79377.80\",\"5.204\"],[\"79411.20\",\"0.281\"],[\"79425.60\",\"2.265\"],[\"79448.90\",\"0.000\"],[\"79449.70\",\"0.040\"],[\"79465.00\",\"0.636\"],[\"79484.30\",\"0.001\"],[\"79506.00\",\"0.008\"],[\"79508.10\",\"3.557\"],[\"79509.60\",\"0.001\"],[\"79526.50\",\"0.022\"],[\"79528.00\",\"0.135\"],[\"79531.70\",\"1.067\"],[\"79536.20\",\"0.505\"],[\"79543.90\",\"0.000\"],[\"79553.20\",\"0.002\"],[\"79562.40\",\"0.049\"],[\"79563.00\",\"0.002\"],[\"79567.70\",\"0.798\"],[\"79567.80\",\"1.545\"],[\"79569.50\",\"0.181\"],[\"79571.00\",\"0.373\"],[\"79571.60\",\"0.000\"],[\"79571.70\",\"1.609\"],[\"79572.00\",\"0.006\"],[\"79572.40\",\"0.023\"],[\"79573.40\",\"0.000\"],[\"79575.60\",\"0.631\"],[\"79575.70\",\"0.005\"],[\"79577.50\",\"0.160\"],[\"79578.50\",\"0.259\"],[\"79581.50\",\"0.587\"],[\"79582.90\",\"0.070\"],[\"79583.00\",\"0.128\"],[\"79583.10\",\"0.198\"],[\"79583.20\",\"0.280\"],[\"79583.30\",\"0.305\"],[\"79583.40\",\"0.030\"],[\"79583.50\",\"0.002\"],[\"79583.60\",\"0.026\"],[\"79583.70\",\"0.060\"],[\"79583.90\",\"0.028\"],[\"79584.10\",\"0.134\"],[\"79584.20\",\"0.001\"],[\"79584.30\",\"0.026\"],[\"79584.50\",\"0.066\"],[\"79584.90\",\"0.036\"],[\"79585.00\",\"0.004\"],[\"79585.10\",\"0.000\"],[\"79585.20\",\"0.001\"],[\"79585.40\",\"0.000\"],[\"79585.50\",\"0.076\"],[\"79585.70\",\"0.000\"],[\"79587.30\",\"0.004\"],[\"79588.00\",\"0.001\"],[\"79589.10\",\"0.439\"],[\"79590.40\",\"0.002\"],[\"79590.50\",\"0.013\"],[\"79592.30\",\"0.001\"],[\"79592.40\",\"0.002\"],[\"79592.90\",\"0.863\"]],\"a\":[[\"79593.00\",\"15.563\"],[\"79594.10\",\"0.076\"],[\"79595.30\",\"0.076\"],[\"79599.10\",\"0.004\"],[\"79605.40\",\"0.005\"],[\"79606.70\",\"0.002\"],[\"79607.00\",\"3.997\"],[\"79609.00\",\"0.741\"],[\"79610.90\",\"0.375\"],[\"79612.40\",\"0.000\"],[\"79612.70\",\"0.691\"],[\"79625.80\",\"0.046\"],[\"79626.80\",\"0.222\"],[\"79628.70\",\"1.025\"],[\"79641.00\",\"0.162\"],[\"79651.90\",\"2.848\"],[\"79652.00\",\"0.901\"],[\"79652.10\",\"0.458\"],[\"79655.30\",\"0.002\"],[\"79655.40\",\"0.011\"],[\"79663.10\",\"0.038\"],[\"79663.40\",\"21.391\"],[\"79670.20\",\"3.866\"],[\"79671.60\",\"0.012\"],[\"79688.60\",\"0.044\"],[\"79689.90\",\"6.002\"],[\"79715.00\",\"0.462\"],[\"79749.30\",\"0.002\"],[\"79750.00\",\"1.277\"],[\"79753.70\",\"0.694\"],[\"79754.40\",\"2.781\"],[\"79802.20\",\"3.151\"],[\"80111.40\",\"0.008\"],[\"80112.70\",\"0.000\"],[\"80311.60\",\"0.016\"],[\"80312.90\",\"0.000\"],[\"80388.90\",\"0.116\"],[\"80588.70\",\"6.140\"],[\"80590.00\",\"0.647\"]],\"st\":1}}"}
{"receive_ns":1788567555709194000,"stream":"btcusdt@depth@100ms","event_type":"depthUpdate","event_time_ms":1788567555737,"raw_json":"{\"stream\":\"btcusdt@depth@100ms\",\"data\":{\"e\":\"depthUpdate\",\"E\":1788567555737,\"T\":1788567555736,\"s\":\"BTCUSDT\",\"ps\":\"BTCUSDT\",\"U\":11478496176485,\"u\":11478496193372,\"pu\":11478496176310,\"b\":[[\"1000.00\",\"24.604\"],[\"29092.90\",\"1.428\"],[\"29192.90\",\"0.672\"],[\"63674.30\",\"0.000\"],[\"71633.60\",\"0.002\"],[\"76409.10\",\"0.000\"],[\"77964.00\",\"2.416\"],[\"78052.40\",\"0.385\"],[\"78140.80\",\"0.000\"],[\"78229.20\",\"1.725\"],[\"78317.60\",\"0.001\"],[\"78406.00\",\"0.000\"],[\"78494.40\",\"0.000\"],[\"78582.80\",\"0.038\"],[\"78671.20\",\"0.000\"],[\"78759.50\",\"0.183\"],[\"78797.00\",\"0.891\"],[\"78831.00\",\"0.000\"],[\"79275.40\",\"1.208\"],[\"79276.70\",\"0.003\"],[\"79448.90\",\"0.032\"],[\"79449.70\",\"0.008\"],[\"79473.60\",\"0.003\"],[\"79474.90\",\"0.127\"],[\"79492.30\",\"0.000\"],[\"79494.40\",\"0.034\"],[\"79495.00\",\"0.150\"],[\"79502.30\",\"0.196\"],[\"79502.90\",\"0.787\"],[\"79510.30\",\"0.034\"],[\"79510.90\",\"0.003\"],[\"79518.30\",\"0.617\"],[\"79518.80\",\"0.020\"],[\"79521.00\",\"0.316\"],[\"79533.50\",\"0.137\"],[\"79536.60\",\"0.049\"],[\"79537.40\",\"0.951\"],[\"79537.90\",\"0.202\"],[\"79548.40\",\"0.004\"],[\"79548.80\",\"0.141\"],[\"79549.70\",\"0.002\"],[\"79553.10\",\"0.000\"],[\"79553.60\",\"0.000\"],[\"79557.30\",\"0.001\"],[\"79562.50\",\"0.548\"],[\"79566.00\",\"0.007\"],[\"79566.60\",\"0.129\"],[\"79569.20\",\"0.504\"],[\"79570.70\",\"0.007\"],[\"79571.70\",\"1.270\"],[\"79572.90\",\"0.001\"],[\"79573.00\",\"0.287\"],[\"79578.50\",\"0.256\"],[\"79581.10\",\"0.076\"],[\"79582.70\",\"0.524\"],[\"79583.00\",\"0.102\"],[\"79583.10\",\"0.172\"],[\"79583.20\",\"0.002\"],[\"79583.30\",\"0.279\"],[\"79583.40\",\"0.004\"],[\"79583.60\",\"0.000\"],[\"79583.70\",\"0.034\"],[\"79583.80\",\"0.072\"],[\"79583.90\",\"0.002\"],[\"79584.70\",\"0.027\"],[\"79584.90\",\"0.062\"],[\"79585.00\",\"0.030\"],[\"79585.40\",\"0.026\"],[\"79585.70\",\"0.000\"],[\"79586.00\",\"0.030\"],[\"79586.20\",\"0.026\"],[\"79586.40\",\"0.029\"],[\"79586.50\",\"1.058\"],[\"79588.50\",\"0.071\"],[\"79588.80\",\"0.004\"],[\"79590.80\",\"0.000\"],[\"79592.70\",\"0.006\"],[\"79592.90\",\"0.861\"]],\"a\":[[\"79593.00\",\"15.553\"],[\"79594.30\",\"0.642\"],[\"79595.50\",\"0.003\"],[\"79596.50\",\"0.148\"],[\"79596.60\",\"0.001\"],[\"79596.70\",\"0.877\"],[\"79598.80\",\"0.001\"],[\"79599.10\",\"0.004\"],[\"79608.00\",\"0.014\"],[\"79609.10\",\"0.000\"],[\"79610.90\",\"0.003\"],[\"79611.30\",\"0.373\"],[\"79612.70\",\"0.000\"],[\"79618.10\",\"0.002\"],[\"79620.30\",\"0.028\"],[\"79621.70\",\"0.546\"],[\"79628.70\",\"0.196\"],[\"79630.30\",\"0.004\"],[\"79640.00\",\"0.072\"],[\"79640.80\",\"0.233\"],[\"79640.90\",\"0.002\"],[\"79647.00\",\"0.003\"],[\"79652.10\",\"0.457\"],[\"79655.40\",\"21.635\"],[\"79656.60\",\"0.006\"],[\"79657.80\",\"2.354\"],[\"79658.00\",\"0.216\"],[\"79658.10\",\"0.002\"],[\"79663.40\",\"0.000\"],[\"79678.10\",\"0.015\"],[\"79686.00\",\"0.002\"],[\"79686.10\",\"0.015\"],[\"79701.90\",\"0.001\"],[\"79702.00\",\"0.015\"],[\"79708.70\",\"0.000\"],[\"79712.30\",\"0.018\"],[\"79713.60\",\"0.013\"],[\"79748.60\",\"0.032\"],[\"79750.00\",\"1.245\"],[\"79911.60\",\"0.004\"],[\"79912.90\",\"0.007\"],[\"79991.00\",\"0.001\"],[\"80350.70\",\"0.000\"],[\"80388.90\",\"0.116\"],[\"80439.00\",\"0.616\"],[\"80509.10\",\"11.808\"],[\"80510.40\",\"6.652\"],[\"80527.40\",\"0.674\"],[\"80587.90\",\"0.618\"],[\"80615.80\",\"0.002\"],[\"80704.20\",\"0.000\"],[\"80792.60\",\"0.000\"],[\"80881.00\",\"0.000\"],[\"80969.40\",\"0.069\"],[\"81057.80\",\"0.000\"],[\"81146.20\",\"0.000\"]],\"st\":1}}"}
{"receive_ns":1788567555808172000,"stream":"btcusdt@depth@100ms","event_type":"depthUpdate","event_time_ms":1788567555839,"raw_json":"{\"stream\":\"btcusdt@depth@100ms\",\"data\":{\"e\":\"depthUpdate\",\"E\":1788567555839,\"T\":1788567555837,\"s\":\"BTCUSDT\",\"ps\":\"BTCUSDT\",\"U\":11478496193464,\"u\":11478496205058,\"pu\":11478496193372,\"b\":[[\"29092.90\",\"1.610\"],[\"29192.90\",\"0.490\"],[\"71633.60\",\"0.002\"],[\"76409.10\",\"0.002\"],[\"78797.00\",\"0.889\"],[\"78956.20\",\"0.002\"],[\"79194.90\",\"0.168\"],[\"79555.80\",\"0.251\"],[\"79556.70\",\"0.001\"],[\"79557.00\",\"0.003\"],[\"79565.10\",\"0.453\"],[\"79565.60\",\"0.004\"],[\"79569.20\",\"0.506\"],[\"79575.20\",\"0.254\"],[\"79576.40\",\"2.778\"],[\"79583.50\",\"0.000\"],[\"79583.80\",\"0.076\"],[\"79583.90\",\"0.000\"],[\"79584.30\",\"0.000\"],[\"79584.50\",\"0.040\"],[\"79584.70\",\"0.001\"],[\"79586.60\",\"0.103\"],[\"79586.80\",\"0.026\"],[\"79587.00\",\"0.031\"],[\"79590.80\",\"0.076\"]],\"a\":[[\"79593.00\",\"15.576\"],[\"79596.50\",\"0.102\"],[\"79600.00\",\"0.256\"],[\"79601.10\",\"0.040\"],[\"79609.10\",\"0.002\"],[\"79611.30\",\"0.001\"],[\"79611.70\",\"1.257\"],[\"79615.20\",\"0.453\"],[\"79617.50\",\"0.000\"],[\"79620.30\",\"0.022\"],[\"79620.60\",\"0.008\"],[\"79625.80\",\"0.000\"],[\"79626.40\",\"0.046\"],[\"79655.50\",\"0.004\"],[\"79658.10\",\"0.001\"],[\"79748.50\",\"0.032\"],[\"79748.60\",\"0.000\"],[\"80388.90\",\"0.116\"],[\"80509.10\",\"13.284\"],[\"80510.40\",\"5.176\"],[\"80549.60\",\"11.041\"],[\"81184.80\",\"0.018\"]],\"st\":1}}"}
{"receive_ns":1788567555909888000,"stream":"btcusdt@depth@100ms","event_type":"depthUpdate","event_time_ms":1788567555941,"raw_json":"{\"stream\":\"btcusdt@depth@100ms\",\"data\":{\"e\":\"depthUpdate\",\"E\":1788567555941,\"T\":1788567555939,\"s\":\"BTCUSDT\",\"ps\":\"BTCUSDT\",\"U\":11478496205245,\"u\":11478496217727,\"pu\":11478496205058,\"b\":[[\"1000.00\",\"24.604\"],[\"29092.90\",\"1.757\"],[\"29192.90\",\"0.329\"],[\"29492.90\",\"0.014\"],[\"71633.60\",\"0.002\"],[\"78637.80\",\"5.714\"],[\"78797.00\",\"0.889\"],[\"78956.20\",\"0.000\"],[\"79290.00\",\"0.066\"],[\"79305.90\",\"0.213\"],[\"79313.40\",\"0.000\"],[\"79333.40\",\"0.024\"],[\"79359.60\",\"0.037\"],[\"79367.40\",\"0.321\"],[\"79408.80\",\"0.025\"],[\"79416.60\",\"0.000\"],[\"79562.90\",\"0.004\"],[\"79563.10\",\"0.258\"],[\"79571.00\",\"0.000\"],[\"79571.90\",\"2.578\"],[\"79587.00\",\"0.005\"],[\"79589.10\",\"0.000\"],[\"79589.60\",\"0.517\"],[\"79590.50\",\"0.012\"],[\"79592.80\",\"0.001\"]],\"a\":[[\"79593.10\",\"0.023\"],[\"79638.20\",\"3.389\"],[\"79651.80\",\"0.000\"],[\"79742.80\",\"0.033\"],[\"79748.50\",\"0.000\"],[\"80367.80\",\"0.000\"],[\"80388.90\",\"0.116\"],[\"80588.70\",\"6.754\"],[\"80590.00\",\"0.033\"],[\"80717.60\",\"28.282\"],[\"80948.90\",\"0.988\"]],\"st\":1}}"}
{"receive_ns":1788567556011984000,"stream":"btcusdt@depth@100ms","event_type":"depthUpdate","event_time_ms":1788567556043,"raw_json":"{\"stream\":\"btcusdt@depth@100ms\",\"data\":{\"e\":\"depthUpdate\",\"E\":1788567556043,\"T\":1788567556042,\"s\":\"BTCUSDT\",\"ps\":\"BTCUSDT\",\"U\":11478496218396,\"u\":11478496231536,\"pu\":11478496217727,\"b\":[[\"1000.00\",\"24.604\"],[\"29092.90\",\"1.827\"],[\"29192.90\",\"0.203\"],[\"29492.90\",\"0.070\"],[\"71633.60\",\"0.002\"],[\"76409.10\",\"0.000\"],[\"78560.70\",\"9.195\"],[\"78797.00\",\"0.889\"],[\"78844.70\",\"0.673\"],[\"79205.00\",\"0.546\"],[\"79207.70\",\"0.336\"],[\"79465.00\",\"0.150\"],[\"79465.10\",\"0.505\"],[\"79487.30\",\"0.000\"],[\"79499.70\",\"1.088\"],[\"79521.10\",\"0.000\"],[\"79529.90\",\"0.261\"],[\"79562.40\",\"0.174\"],[\"79563.10\",\"0.133\"],[\"79578.60\",\"0.004\"],[\"79587.10\",\"0.052\"],[\"79589.70\",\"0.001\"],[\"79591.60\",\"0.000\"],[\"79592.90\",\"0.859\"]],\"a\":[[\"79593.00\",\"15.579\"],[\"79715.00\",\"0.021\"],[\"79715.10\",\"0.428\"],[\"79742.80\",\"0.001\"],[\"79750.80\",\"0.050\"],[\"80357.60\",\"0.112\"],[\"80388.90\",\"0.116\"],[\"80509.10\",\"15.498\"],[\"80510.40\",\"2.962\"],[\"80775.40\",\"0.000\"],[\"80938.10\",\"0.492\"]],\"st\":1}}"}
{"receive_ns":1788567556113941000,"stream":"btcusdt@depth@100ms","event_type":"depthUpdate","event_time_ms":1788567556145,"raw_json":"{\"stream\":\"btcusdt@depth@100ms\",\"data\":{\"e\":\"depthUpdate\",\"E\":1788567556145,\"T\":1788567556143,\"s\":\"BTCUSDT\",\"ps\":\"BTCUSDT\",\"U\":11478496231799,\"u\":11478496244815,\"pu\":11478496231536,\"b\":[[\"29092.90\",\"1.876\"],[\"29192.90\",\"0.091\"],[\"29492.90\",\"0.133\"],[\"71633.60\",\"0.002\"],[\"71670.00\",\"0.000\"],[\"76409.10\",\"0.002\"],[\"77327.60\",\"1.036\"],[\"78104.50\",\"1.367\"],[\"78550.00\",\"6.615\"],[\"78551.80\",\"0.006\"],[\"78797.00\",\"0.891\"],[\"79194.90\",\"0.159\"],[\"79497.00\",\"0.020\"],[\"79552.90\",\"0.001\"],[\"79561.40\",\"0.048\"],[\"79561.90\",\"0.110\"],[\"79562.40\",\"0.003\"],[\"79562.90\",\"0.006\"],[\"79563.20\",\"0.166\"],[\"79564.50\",\"0.454\"],[\"79565.10\",\"0.001\"],[\"79568.10\",\"0.442\"],[\"79568.50\",\"0.075\"],[\"79569.20\",\"0.067\"],[\"79570.60\",\"0.453\"],[\"79571.00\",\"0.000\"],[\"79571.50\",\"0.001\"],[\"79571.90\",\"2.205\"],[\"79578.60\",\"0.000\"]],\"a\":[[\"79593.00\",\"15.592\"],[\"79594.30\",\"0.626\"],[\"79604.80\",\"0.439\"],[\"79606.50\",\"0.252\"],[\"79610.80\",\"0.377\"],[\"79611.70\",\"0.885\"],[\"79625.40\",\"0.493\"],[\"79626.40\",\"0.000\"],[\"79664.40\",\"0.004\"],[\"79717.70\",\"0.020\"],[\"79750.00\",\"1.277\"],[\"79750.80\",\"0.018\"],[\"79991.00\",\"0.000\"],[\"80388.90\",\"0.116\"],[\"80710.10\",\"0.534\"],[\"80720.20\",\"0.000\"]],\"st\":1}}"}
{"receive_ns":1788567556218141000,"stream":"btcusdt@depth@100ms","event_type":"depthUpdate","event_time_ms":1788567556247,"raw_json":"{\"stream\":\"btcusdt@depth@100ms\",\"data\":{\"e\":\"depthUpdate\",\"E\":1788567556247,\"T\":1788567556246,\"s\":\"BTCUSDT\",\"ps\":\"BTCUSDT\",\"U\":11478496244955,\"u\":11478496258411,\"pu\":11478496244815,\"b\":[[\"1000.00\",\"24.604\"],[\"29092.90\",\"1.876\"],[\"29192.90\",\"0.000\"],[\"29492.90\",\"0.224\"],[\"71633.60\",\"0.002\"],[\"76409.10\",\"0.000\"],[\"78676.90\",\"6.040\"],[\"78797.00\",\"0.889\"],[\"79532.70\",\"0.015\"],[\"79545.20\",\"0.008\"],[\"79554.90\",\"0.002\"],[\"79560.90\",\"0.046\"],[\"79561.40\",\"0.002\"],[\"79563.00\",\"0.127\"],[\"79563.60\",\"2.559\"],[\"79564.50\",\"0.002\"],[\"79567.80\",\"1.984\"],[\"79568.10\",\"0.003\"],[\"79570.20\",\"0.412\"],[\"79570.60\",\"0.080\"],[\"79582.70\",\"0.454\"],[\"79582.90\",\"0.000\"],[\"79583.00\",\"0.002\"],[\"79583.10\",\"0.002\"],[\"79583.20\",\"0.004\"],[\"79583.30\",\"0.181\"],[\"79583.70\",\"0.002\"],[\"79583.80\",\"0.002\"],[\"79584.00\",\"0.006\"],[\"79584.10\",\"0.102\"],[\"79584.30\",\"0.026\"],[\"79584.50\",\"0.034\"],[\"79584.60\",\"0.029\"],[\"79584.70\",\"0.001\"],[\"79584.80\",\"0.001\"],[\"79584.90\",\"0.004\"],[\"79585.00\",\"0.004\"],[\"79585.40\",\"0.000\"],[\"79586.00\",\"0.004\"],[\"79586.10\",\"0.027\"],[\"79586.20\",\"0.026\"],[\"79586.30\",\"0.051\"],[\"79586.40\",\"0.029\"],[\"79586.50\",\"1.026\"],[\"79586.60\",\"0.077\"],[\"79586.70\",\"0.027\"],[\"79586.80\",\"0.000\"],[\"79587.10\",\"0.026\"],[\"79587.90\",\"0.002\"],[\"79590.80\",\"0.000\"],[\"79592.70\",\"0.007\"],[\"79592.90\",\"0.863\"]],\"a\":[[\"79596.60\",\"0.005\"],[\"79599.10\",\"0.000\"],[\"79600.80\",\"0.015\"],[\"79602.50\",\"0.076\"],[\"79609.90\",\"0.375\"],[\"79610.80\",\"0.005\"],[\"79750.00\",\"1.245\"],[\"79750.80\",\"0.050\"],[\"80388.90\",\"0.116\"],[\"80509.10\",\"17.712\"],[\"80510.40\",\"0.748\"],[\"80587.90\",\"0.829\"],[\"80736.10\",\"0.000\"],[\"80771.10\",\"0.006\"]],\"st\":1}}"}
{"receive_ns":1788567556318102000,"stream":"btcusdt@depth@100ms","event_type":"depthUpdate","event_time_ms":1788567556349,"raw_json":"{\"stream\":\"btcusdt@depth@100ms\",\"data\":{\"e\":\"depthUpdate\",\"E\":1788567556349,\"T\":1788567556348,\"s\":\"BTCUSDT\",\"ps\":\"BTCUSDT\",\"U\":11478496258513,\"u\":11478496270894,\"pu\":11478496258411,\"b\":[[\"1000.00\",\"24.604\"],[\"29092.90\",\"1.701\"],[\"29492.90\",\"0.399\"],[\"71633.60\",\"0.004\"],[\"76409.10\",\"0.002\"],[\"78797.00\",\"0.889\"],[\"78966.20\",\"0.505\"],[\"79194.90\",\"2.059\"],[\"79477.50\",\"0.032\"],[\"79530.00\",\"0.202\"],[\"79560.40\",\"0.047\"],[\"79560.90\",\"0.000\"],[\"79563.00\",\"0.002\"],[\"79563.50\",\"1.622\"],[\"79566.60\",\"0.568\"],[\"79567.80\",\"1.545\"],[\"79569.80\",\"0.373\"],[\"79570.20\",\"0.039\"],[\"79578.30\",\"0.102\"],[\"79579.60\",\"0.948\"],[\"79584.10\",\"0.128\"],[\"79584.20\",\"0.027\"],[\"79586.40\",\"0.003\"],[\"79586.50\",\"1.000\"],[\"79586.70\",\"0.001\"],[\"79592.90\",\"0.836\"]],\"a\":[[\"79593.00\",\"15.601\"],[\"79596.00\",\"0.075\"],[\"79604.70\",\"0.042\"],[\"79609.10\",\"0.003\"],[\"79624.30\",\"0.300\"],[\"79625.40\",\"0.447\"],[\"79627.40\",\"0.202\"],[\"79629.10\",\"0.253\"],[\"79748.40\",\"0.033\"],[\"79750.80\",\"0.018\"],[\"79829.20\",\"0.025\"],[\"79829.30\",\"0.003\"],[\"80239.90\",\"0.498\"],[\"80379.20\",\"0.004\"],[\"80388.90\",\"0.116\"],[\"80509.10\",\"18.450\"],[\"80510.40\",\"0.010\"],[\"80612.30\",\"0.000\"],[\"80699.30\",\"0.718\"],[\"85500.00\",\"13.104\"]],\"st\":1}}"}
{"receive_ns":1788567556419814000,"stream":"btcusdt@depth@100ms","event_type":"depthUpdate","event_time_ms":1788567556451,"raw_json":"{\"stream\":\"btcusdt@depth@100ms\",\"data\":{\"e\":\"depthUpdate\",\"E\":1788567556451,\"T\":1788567556450,\"s\":\"BTCUSDT\",\"ps\":\"BTCUSDT\",\"U\":11478496270901,\"u\":11478496279907,\"pu\":11478496270894,\"b\":[[\"29092.90\",\"1.519\"],[\"29492.90\",\"0.581\"],[\"63674.00\",\"0.000\"],[\"71633.60\",\"0.002\"],[\"78676.80\",\"0.764\"],[\"78797.00\",\"0.889\"],[\"79187.90\",\"0.087\"],[\"79193.90\",\"0.000\"],[\"79480.20\",\"0.032\"],[\"79490.60\",\"0.073\"],[\"79495.80\",\"0.106\"],[\"79496.20\",\"0.071\"],[\"79516.50\",\"0.073\"],[\"79562.30\",\"1.244\"],[\"79571.00\",\"0.628\"],[\"79571.70\",\"0.642\"],[\"79575.10\",\"0.703\"],[\"79575.30\",\"0.800\"],[\"79575.60\",\"0.003\"],[\"79576.90\",\"1.329\"],[\"79577.20\",\"0.080\"],[\"79577.70\",\"0.150\"],[\"79577.90\",\"0.101\"],[\"79578.30\",\"0.172\"],[\"79578.60\",\"0.070\"],[\"79578.90\",\"0.035\"],[\"79581.60\",\"0.016\"],[\"79584.00\",\"0.032\"],[\"79586.30\",\"0.025\"]],\"a\":[[\"79606.00\",\"0.705\"],[\"79607.00\",\"3.297\"],[\"79655.30\",\"0.001\"],[\"79655.40\",\"21.636\"],[\"79748.40\",\"0.001\"],[\"79750.80\",\"0.050\"],[\"80388.90\",\"0.116\"]],\"st\":1}}"}
{"receive_ns":1788567556523426000,"stream":"btcusdt@depth@100ms","event_type":"depthUpdate","event_time_ms":1788567556553,"raw_json":"{\"stream\":\"btcusdt@depth@100ms\",\"data\":{\"e\":\"depthUpdate\",\"E\":1788567556553,\"T\":1788567556550,\"s\":\"BTCUSDT\",\"ps\":\"BTCUSDT\",\"U\":11478496280068,\"u\":11478496289360,\"pu\":11478496279907,\"b\":[[\"1000.00\",\"24.604\"],[\"29092.90\",\"1.344\"],[\"29492.90\",\"0.756\"],[\"71633.60\",\"0.002\"],[\"76409.10\",\"0.000\"],[\"78001.10\",\"0.006\"],[\"78797.00\",\"0.889\"],[\"79465.10\",\"0.001\"],[\"79465.20\",\"0.504\"],[\"79479.60\",\"0.081\"],[\"79480.10\",\"0.032\"],[\"79502.50\",\"0.033\"],[\"79505.10\",\"0.099\"],[\"79516.50\",\"0.003\"],[\"79548.60\",\"0.016\"],[\"79563.00\",\"0.002\"],[\"79570.00\",\"0.010\"],[\"79570.70\",\"0.001\"],[\"79576.90\",\"1.321\"],[\"79578.10\",\"0.072\"],[\"79579.30\",\"0.034\"],[\"79580.10\",\"0.167\"],[\"79580.40\",\"0.032\"],[\"79581.00\",\"0.008\"],[\"79582.90\",\"0.002\"],[\"79583.20\",\"0.002\"],[\"79592.90\",\"0.854\"]],\"a\":[[\"79595.70\",\"0.049\"],[\"79596.00\",\"0.029\"],[\"79715.10\",\"0.428\"],[\"79750.80\",\"0.018\"],[\"79751.30\",\"0.032\"],[\"80388.90\",\"0.116\"],[\"80389.00\",\"0.014\"],[\"80548.10\",\"1.240\"],[\"81186.10\",\"4.065\"]],\"st\":1}}"}
{"receive_ns":1788567556625622000,"stream":"btcusdt@depth@100ms","event_type":"depthUpdate","event_time_ms":1788567556655,"raw_json":"{\"stream\":\"btcusdt@depth@100ms\",\"data\":{\"e\":\"depthUpdate\",\"E\":1788567556655,\"T\":1788567556654,\"s\":\"BTCUSDT\",\"ps\":\"BTCUSDT\",\"U\":11478496289617,\"u\":11478496298602,\"pu\":11478496289360,\"b\":[[\"1000.00\",\"24.604\"],[\"29092.90\",\"1.162\"],[\"29492.90\",\"0.938\"],[\"63675.00\",\"0.002\"],[\"71633.60\",\"0.002\"],[\"76409.10\",\"0.002\"],[\"78797.00\",\"0.889\"],[\"79194.90\",\"2.049\"],[\"79427.90\",\"0.488\"],[\"79465.20\",\"0.000\"],[\"79477.50\",\"0.000\"],[\"79480.20\",\"0.000\"],[\"79495.80\",\"0.006\"],[\"79496.10\",\"0.102\"],[\"79496.20\",\"0.001\"],[\"79505.10\",\"0.029\"],[\"79506.00\",\"0.002\"],[\"79515.30\",\"0.109\"],[\"79517.40\",\"0.643\"],[\"79528.10\",\"0.831\"],[\"79544.00\",\"2.545\"],[\"79555.10\",\"0.319\"],[\"79559.00\",\"0.048\"],[\"79560.40\",\"0.001\"],[\"79562.00\",\"0.555\"],[\"79562.30\",\"1.369\"],[\"79563.60\",\"2.107\"],[\"79564.90\",\"0.442\"],[\"79566.60\",\"0.129\"],[\"79567.00\",\"0.882\"],[\"79567.70\",\"0.170\"],[\"79568.40\",\"3.174\"],[\"79569.80\",\"0.000\"],[\"79576.90\",\"0.069\"],[\"79577.10\",\"0.072\"],[\"79578.20\",\"0.203\"],[\"79581.00\",\"1.256\"],[\"79583.90\",\"0.026\"],[\"79586.20\",\"0.026\"]],\"a\":[[\"79593.00\",\"15.617\"],[\"79603.10\",\"0.441\"],[\"79603.30\",\"0.007\"],[\"79603.40\",\"0.078\"],[\"79604.80\",\"0.000\"],[\"79608.30\",\"0.501\"],[\"79608.70\",\"0.005\"],[\"79609.90\",\"0.003\"],[\"79611.70\",\"1.337\"],[\"79612.80\",\"0.693\"],[\"79615.20\",\"0.001\"],[\"79628.80\",\"0.829\"],[\"79652.00\",\"3.966\"],[\"79652.10\",\"0.458\"],[\"79715.10\",\"0.000\"],[\"79751.30\",\"0.000\"],[\"79754.10\",\"0.032\"],[\"80388.90\",\"0.116\"],[\"83121.60\",\"0.000\"],[\"83131.10\",\"0.100\"]],\"st\":1}}"}
{"receive_ns":1788567556729531000,"stream":"btcusdt@depth@100ms","event_type":"depthUpdate","event_time_ms":1788567556757,"raw_json":"{\"stream\":\"btcusdt@depth@100ms\",\"data\":{\"e\":\"depthUpdate\",\"E\":1788567556757,\"T\":1788567556753,\"s\":\"BTCUSDT\",\"ps\":\"BTCUSDT\",\"U\":11478496298703,\"u\":11478496308572,\"pu\":11478496298602,\"b\":[[\"29092.90\",\"0.987\"],[\"29492.90\",\"1.113\"],[\"63674.30\",\"0.000\"],[\"63675.00\",\"0.002\"],[\"71633.60\",\"0.002\"],[\"75840.10\",\"0.206\"],[\"75841.40\",\"0.000\"],[\"76409.10\",\"0.000\"],[\"78253.90\",\"0.001\"],[\"78797.00\",\"0.889\"],[\"79465.30\",\"0.515\"],[\"79490.60\",\"0.003\"],[\"79515.30\",\"0.009\"],[\"79528.10\",\"0.002\"],[\"79532.10\",\"0.005\"],[\"79544.00\",\"1.854\"],[\"79544.40\",\"0.022\"],[\"79564.90\",\"0.003\"],[\"79567.10\",\"0.439\"],[\"79576.90\",\"0.065\"],[\"79577.10\",\"1.320\"],[\"79577.20\",\"0.084\"],[\"79581.00\",\"0.008\"],[\"79583.90\",\"0.000\"],[\"79584.00\",\"0.006\"],[\"79584.10\",\"0.102\"],[\"79584.20\",\"0.001\"],[\"79585.50\",\"0.102\"],[\"79585.60\",\"0.028\"],[\"79585.80\",\"0.026\"],[\"79586.10\",\"0.027\"],[\"79586.20\",\"0.000\"],[\"79586.30\",\"0.051\"],[\"79586.60\",\"0.103\"],[\"79586.80\",\"0.026\"],[\"79592.90\",\"0.771\"]],\"a\":[[\"79593.00\",\"15.610\"],[\"79595.70\",\"0.003\"],[\"79596.10\",\"0.049\"],[\"79596.60\",\"0.005\"],[\"79598.80\",\"0.001\"],[\"79600.70\",\"0.005\"],[\"79601.10\",\"0.090\"],[\"79602.20\",\"0.001\"],[\"79603.10\",\"0.002\"],[\"79603.40\",\"0.077\"],[\"79603.60\",\"0.041\"],[\"79604.80\",\"0.439\"],[\"79606.30\",\"0.325\"],[\"79608.30\",\"0.128\"],[\"79609.30\",\"0.372\"],[\"79611.70\",\"0.885\"],[\"79612.80\",\"0.002\"],[\"79613.30\",\"0.453\"],[\"79613.90\",\"0.000\"],[\"79614.40\",\"0.001\"],[\"79616.30\",\"0.018\"],[\"79622.40\",\"0.025\"],[\"79628.80\",\"0.000\"],[\"79715.10\",\"0.428\"],[\"79742.80\",\"0.033\"],[\"79754.10\",\"0.000\"],[\"80388.90\",\"0.116\"],[\"80549.60\",\"10.763\"],[\"81184.80\",\"0.021\"],[\"83118.40\",\"0.100\"],[\"83131.10\",\"0.000\"]],\"st\":1}}"}
{"receive_ns":1788567556832026000,"stream":"btcusdt@depth@100ms","event_type":"depthUpdate","event_time_ms":1788567556859,"raw_json":"{\"stream\":\"btcusdt@depth@100ms\",\"data\":{\"e\":\"depthUpdate\",\"E\":1788567556859,\"T\":1788567556858,\"s\":\"BTCUSDT\",\"ps\":\"BTCUSDT\",\"U\":11478496308938,\"u\":11478496318117,\"pu\":11478496308572,\"b\":[[\"1000.00\",\"24.604\"],[\"29092.90\",\"0.805\"],[\"29492.90\",\"1.295\"],[\"71633.60\",\"0.002\"],[\"75613.30\",\"0.004\"],[\"76409.10\",\"0.002\"],[\"78797.00\",\"0.889\"],[\"78999.50\",\"0.050\"],[\"79194.90\",\"2.048\"],[\"79377.80\",\"0.000\"],[\"79378.20\",\"5.115\"],[\"79448.90\",\"0.000\"],[\"79449.70\",\"0.040\"],[\"79465.30\",\"0.389\"],[\"79479.60\",\"0.049\"],[\"79505.90\",\"0.216\"],[\"79517.00\",\"0.483\"],[\"79517.50\",\"0.000\"],[\"79519.20\",\"0.040\"],[\"79520.40\",\"0.005\"],[\"79530.00\",\"0.102\"],[\"79538.90\",\"0.879\"],[\"79555.00\",\"1.715\"],[\"79555.10\",\"0.570\"],[\"79555.60\",\"0.202\"],[\"79555.80\",\"0.000\"],[\"79559.90\",\"2.033\"],[\"79562.00\",\"0.103\"],[\"79562.30\",\"1.244\"],[\"79563.00\",\"0.002\"],[\"79564.00\",\"1.157\"],[\"79568.40\",\"2.801\"],[\"79569.20\",\"0.067\"],[\"79569.60\",\"0.011\"],[\"79570.00\",\"0.004\"],[\"79570.20\",\"0.412\"],[\"79574.60\",\"1.116\"],[\"79575.20\",\"0.003\"],[\"79576.90\",\"0.139\"],[\"79577.10\",\"0.002\"],[\"79577.20\",\"0.080\"],[\"79580.80\",\"0.003\"],[\"79581.00\",\"1.256\"],[\"79582.90\",\"0.004\"],[\"79583.30\",\"0.179\"],[\"79583.40\",\"0.002\"],[\"79584.30\",\"0.000\"],[\"79584.50\",\"0.008\"],[\"79586.90\",\"0.026\"],[\"79587.70\",\"0.032\"],[\"79589.50\",\"0.004\"],[\"79589.60\",\"0.078\"],[\"79590.90\",\"0.440\"],[\"79592.80\",\"0.002\"],[\"79592.90\",\"1.356\"]],\"a\":[[\"79593.00\",\"15.609\"],[\"79596.10\",\"0.049\"],[\"79596.70\",\"0.877\"],[\"79598.10\",\"0.215\"],[\"79603.10\",\"0.002\"],[\"79603.50\",\"0.006\"],[\"79604.80\",\"0.439\"],[\"79609.10\",\"0.003\"],[\"79609.30\",\"0.000\"],[\"79610.10\",\"0.379\"],[\"79613.30\",\"0.001\"],[\"79613.70\",\"0.452\"],[\"79614.00\",\"0.630\"],[\"79615.00\",\"0.005\"],[\"79617.90\",\"0.258\"],[\"79619.30\",\"0.007\"],[\"79620.60\",\"0.002\"],[\"79633.80\",\"0.040\"],[\"79638.20\",\"3.329\"],[\"79640.80\",\"0.201\"],[\"79648.00\",\"0.185\"],[\"79651.40\",\"0.000\"],[\"79652.30\",\"0.060\"],[\"79653.50\",\"0.001\"],[\"79715.10\",\"0.369\"],[\"79742.80\",\"0.001\"],[\"79749.10\",\"0.032\"],[\"79991.00\",\"0.001\"],[\"80388.90\",\"0.116\"],[\"80548.10\",\"2.480\"],[\"80549.60\",\"10.614\"],[\"80707.30\",\"1.856\"],[\"80716.70\",\"0.000\"],[\"81184.80\",\"0.024\"]],\"st\":1}}"}
{"receive_ns":1788567556935026000,"stream":"btcusdt@depth@100ms","event_type":"depthUpdate","event_time_ms":1788567556961,"raw_json":"{\"stream\":\"btcusdt@depth@100ms\",\"data\":{\"e\":\"depthUpdate\",\"E\":1788567556961,\"T\":1788567556959,\"s\":\"BTCUSDT\",\"ps\":\"BTCUSDT\",\"U\":11478496318239,\"u\":11478496328263,\"pu\":11478496318117,\"b\":[[\"1000.00\",\"24.604\"],[\"29092.90\",\"0.630\"],[\"29492.90\",\"1.470\"],[\"63674.00\",\"0.000\"],[\"71633.60\",\"0.002\"],[\"75613.30\",\"0.006\"],[\"77964.10\",\"0.035\"],[\"78052.50\",\"0.028\"],[\"78140.90\",\"0.028\"],[\"78229.30\",\"0.028\"],[\"78317.70\",\"0.028\"],[\"78406.10\",\"0.029\"],[\"78494.50\",\"0.028\"],[\"78582.90\",\"0.028\"],[\"78671.30\",\"0.029\"],[\"78759.60\",\"0.047\"],[\"78797.00\",\"0.891\"],[\"79194.90\",\"2.058\"],[\"79448.90\",\"0.032\"],[\"79449.70\",\"0.008\"],[\"79465.30\",\"0.011\"],[\"79480.10\",\"0.000\"],[\"79496.10\",\"0.002\"],[\"79499.70\",\"1.086\"],[\"79502.50\",\"0.001\"],[\"79512.70\",\"0.021\"],[\"79553.20\",\"0.002\"],[\"79562.40\",\"0.128\"],[\"79563.30\",\"0.454\"],[\"79564.00\",\"0.705\"],[\"79576.70\",\"1.710\"],[\"79577.40\",\"0.256\"],[\"79584.60\",\"0.003\"],[\"79587.90\",\"0.028\"],[\"79590.00\",\"0.019\"],[\"79592.90\",\"1.355\"]],\"a\":[[\"79593.00\",\"15.610\"],[\"79689.90\",\"6.002\"],[\"79715.10\",\"0.000\"],[\"79749.10\",\"0.000\"],[\"79750.00\",\"1.277\"],[\"80350.80\",\"1.747\"],[\"80388.90\",\"0.116\"],[\"80439.10\",\"0.028\"],[\"80527.50\",\"0.028\"],[\"80549.60\",\"10.428\"],[\"80615.90\",\"0.030\"],[\"80704.30\",\"0.028\"],[\"80715.30\",\"0.618\"],[\"80792.70\",\"0.028\"],[\"80881.10\",\"0.037\"],[\"80969.50\",\"0.028\"]],\"st\":1}}"}
{"receive_ns":1788567557033336000,"stream":"btcusdt@depth@100ms","event_type":"depthUpdate","event_time_ms":1788567557063,"raw_json":"{\"stream\":\"btcusdt@depth@100ms\",\"data\":{\"e\":\"depthUpdate\",\"E\":1788567557063,\"T\":1788567557062,\"s\":\"BTCUSDT\",\"ps\":\"BTCUSDT\",\"U\":11478496328370,\"u\":11478496338001,\"pu\":11478496328263,\"b\":[[\"29092.90\",\"0.448\"],[\"29492.90\",\"1.652\"],[\"63675.00\",\"0.002\"],[\"71633.60\",\"0.002\"],[\"76409.10\",\"0.000\"],[\"78002.40\",\"0.006\"],[\"78369.30\",\"3.560\"],[\"78462.70\",\"0.153\"],[\"78475.00\",\"9.282\"],[\"78488.70\",\"28.312\"],[\"78797.00\",\"0.889\"],[\"79465.40\",\"0.500\"],[\"79559.00\",\"0.002\"],[\"79560.50\",\"0.048\"],[\"79562.40\",\"0.003\"],[\"79578.60\",\"0.070\"]],\"a\":[[\"79602.10\",\"0.000\"],[\"79715.10\",\"0.471\"],[\"79750.00\",\"1.245\"],[\"79750.80\",\"0.050\"],[\"80819.10\",\"0.015\"],[\"81057.90\",\"0.029\"],[\"81146.30\",\"3.204\"]],\"st\":1}}"}
{"receive_ns":1788567557134060000,"stream":"btcusdt@depth@100ms","event_type":"depthUpdate","event_time_ms":1788567557165,"raw_json":"{\"stream\":\"btcusdt@depth@100ms\",\"data\":{\"e\":\"depthUpdate\",\"E\":1788567557165,\"T\":1788567557161,\"s\":\"BTCUSDT\",\"ps\":\"BTCUSDT\",\"U\":11478496338185,\"u\":11478496348925,\"pu\":11478496338001,\"b\":[[\"1000.00\",\"24.604\"],[\"29092.90\",\"0.301\"],[\"29392.90\",\"0.028\"],[\"29492.90\",\"1.771\"],[\"63674.00\",\"0.000\"],[\"71633.60\",\"0.002\"],[\"76409.10\",\"0.002\"],[\"77364.30\",\"0.258\"],[\"78368.00\",\"0.503\"],[\"78551.80\",\"0.000\"],[\"78553.60\",\"0.008\"],[\"78599.20\",\"0.000\"],[\"78602.60\",\"0.006\"],[\"78634.10\",\"8.890\"],[\"78797.00\",\"0.889\"],[\"78855.80\",\"0.201\"],[\"78857.10\",\"0.020\"],[\"79194.90\",\"2.057\"],[\"79465.40\",\"0.011\"],[\"79562.30\",\"1.244\"],[\"79562.50\",\"0.548\"],[\"79576.90\",\"0.131\"],[\"79581.10\",\"0.084\"],[\"79585.50\",\"0.076\"],[\"79588.00\",\"0.027\"]],\"a\":[[\"79593.00\",\"15.609\"],[\"79596.60\",\"0.001\"],[\"79599.10\",\"0.004\"],[\"79600.80\",\"0.011\"],[\"79601.10\",\"0.094\"],[\"79698.70\",\"0.003\"],[\"79715.10\",\"0.000\"],[\"79749.10\",\"0.032\"],[\"79750.80\",\"0.018\"],[\"79991.00\",\"0.002\"],[\"80331.20\",\"0.000\"],[\"80388.90\",\"0.116\"]],\"st\":1}}"}
{"receive_ns":1788567557237821000,"stream":"btcusdt@depth@100ms","event_type":"depthUpdate","event_time_ms":1788567557267,"raw_json":"{\"stream\":\"btcusdt@depth@100ms\",\"data\":{\"e\":\"depthUpdate\",\"E\":1788567557267,\"T\":1788567557266,\"s\":\"BTCUSDT\",\"ps\":\"BTCUSDT\",\"U\":11478496349246,\"u\":11478496357582,\"pu\":11478496348925,\"b\":[[\"1000.00\",\"24.604\"],[\"29092.90\",\"0.175\"],[\"29392.90\",\"0.084\"],[\"29492.90\",\"1.841\"],[\"71633.60\",\"0.002\"],[\"71670.00\",\"0.003\"],[\"75614.50\",\"0.006\"],[\"75614.60\",\"0.004\"],[\"75619.30\",\"0.002\"],[\"76409.10\",\"0.000\"],[\"78001.10\",\"0.009\"],[\"78797.00\",\"0.897\"],[\"79194.90\",\"2.057\"],[\"79465.40\",\"0.500\"],[\"79569.70\",\"0.374\"],[\"79570.20\",\"0.039\"],[\"79586.00\",\"0.030\"],[\"79586.60\",\"0.104\"],[\"79589.70\",\"0.000\"],[\"79592.90\",\"1.352\"]],\"a\":[[\"79593.00\",\"18.019\"],[\"79596.10\",\"0.003\"],[\"79596.60\",\"0.005\"],[\"79599.10\",\"0.000\"],[\"79715.10\",\"0.471\"],[\"79742.80\",\"0.033\"],[\"79749.10\",\"0.000\"],[\"80329.90\",\"0.564\"],[\"80388.90\",\"0.118\"],[\"80587.90\",\"0.978\"],[\"80639.20\",\"0.275\"],[\"80817.80\",\"0.012\"],[\"81184.80\",\"0.027\"],[\"87552.30\",\"0.000\"]],\"st\":1}}"}
{"receive_ns":1788567557338759000,"stream":"btcusdt@depth@100ms","event_type":"depthUpdate","event_time_ms":1788567557369,"raw_json":"{\"stream\":\"btcusdt@depth@100ms\",\"data\":{\"e\":\"depthUpdate\",\"E\":1788567557369,\"T\":1788567557365,\"s\":\"BTCUSDT\",\"ps\":\"BTCUSDT\",\"U\":11478496357589,\"u\":11478496365648,\"pu\":11478496357582,\"b\":[[\"29092.90\",\"0.063\"],[\"29392.90\",\"0.147\"],[\"29492.90\",\"1.890\"],[\"71633.60\",\"0.002\"],[\"71670.00\",\"0.000\"],[\"78001.10\",\"0.012\"],[\"78797.00\",\"0.889\"],[\"79537.10\",\"0.013\"],[\"79561.00\",\"0.035\"],[\"79562.50\",\"0.548\"],[\"79576.90\",\"0.139\"],[\"79577.00\",\"0.145\"],[\"79577.10\",\"0.002\"],[\"79577.20\",\"0.080\"],[\"79577.40\",\"0.254\"],[\"79581.00\",\"1.256\"],[\"79581.10\",\"0.076\"],[\"79583.10\",\"0.004\"],[\"79587.40\",\"0.026\"],[\"79587.60\",\"0.000\"],[\"79587.70\",\"0.006\"],[\"79587.90\",\"0.002\"],[\"79588.00\",\"0.001\"]],\"a\":[[\"79593.00\",\"15.597\"],[\"79596.60\",\"0.051\"],[\"79598.80\",\"0.001\"],[\"79672.60\",\"0.002\"],[\"79728.40\",\"0.091\"],[\"79742.80\",\"0.001\"],[\"79749.30\",\"0.034\"],[\"80388.90\",\"0.116\"],[\"80389.70\",\"0.246\"],[\"80391.00\",\"0.196\"],[\"80399.10\",\"5.741\"]],\"st\":1}}"}
{"receive_ns":1788567557441069000,"stream":"btcusdt@depth@100ms","event_type":"depthUpdate","event_time_ms":1788567557471,"raw_json":"{\"stream\":\"btcusdt@depth@100ms\",\"data\":{\"e\":\"depthUpdate\",\"E\":1788567557471,\"T\":1788567557469,\"s\":\"BTCUSDT\",\"ps\":\"BTCUSDT\",\"U\":11478496365894,\"u\":11478496372533,\"pu\":11478496365648,\"b\":[[\"1000.00\",\"24.604\"],[\"29092.90\",\"0.000\"],[\"29392.90\",\"0.266\"],[\"29492.90\",\"1.834\"],[\"71633.60\",\"0.002\"],[\"76409.10\",\"0.002\"],[\"78797.00\",\"0.889\"],[\"79425.60\",\"0.000\"],[\"79427.90\",\"0.192\"],[\"79465.40\",\"0.011\"],[\"79497.00\",\"0.000\"],[\"79499.90\",\"0.002\"],[\"79551.60\",\"0.042\"],[\"79562.70\",\"0.126\"],[\"79592.90\",\"2.778\"]],\"a\":[[\"79593.00\",\"15.598\"],[\"79663.10\",\"0.058\"],[\"79715.10\",\"0.000\"],[\"79717.70\",\"0.000\"],[\"79749.30\",\"0.002\"],[\"79750.80\",\"0.050\"],[\"79753.70\",\"0.442\"],[\"79754.40\",\"0.578\"],[\"80388.90\",\"0.116\"],[\"83118.40\",\"0.000\"],[\"83126.80\",\"0.100\"]],\"st\":1}}"}
{"receive_ns":1788567557541969000,"stream":"btcusdt@depth@100ms","event_type":"depthUpdate","event_time_ms":1788567557573,"raw_json":"{\"stream\":\"btcusdt@depth@100ms\",\"data\":{\"e\":\"depthUpdate\",\"E\":1788567557573,\"T\":1788567557570,\"s\":\"BTCUSDT\",\"ps\":\"BTCUSDT\",\"U\":11478496372619,\"u\":11478496382778,\"pu\":11478496372533,\"b\":[[\"1000.00\",\"24.604\"],[\"29392.90\",\"0.441\"],[\"29492.90\",\"1.659\"],[\"71633.60\",\"0.002\"],[\"76409.10\",\"0.000\"],[\"78560.70\",\"9.004\"],[\"78797.00\",\"0.889\"],[\"79194.90\",\"1.891\"],[\"79195.00\",\"0.419\"],[\"79426.10\",\"2.336\"],[\"79427.90\",\"0.497\"],[\"79465.50\",\"0.489\"],[\"79501.80\",\"0.013\"],[\"79503.70\",\"0.006\"],[\"79514.10\",\"0.007\"],[\"79536.20\",\"0.490\"],[\"79549.00\",\"1.366\"],[\"79560.50\",\"0.002\"],[\"79560.70\",\"0.046\"],[\"79562.00\",\"0.103\"],[\"79562.20\",\"0.003\"],[\"79562.30\",\"1.369\"],[\"79562.70\",\"0.001\"],[\"79566.20\",\"0.003\"],[\"79567.10\",\"0.000\"],[\"79567.90\",\"0.559\"],[\"79568.10\",\"0.003\"],[\"79568.50\",\"0.075\"],[\"79569.20\",\"0.067\"],[\"79569.70\",\"0.001\"],[\"79570.10\",\"0.374\"],[\"79571.30\",\"0.002\"],[\"79575.80\",\"0.020\"],[\"79576.90\",\"0.131\"],[\"79577.00\",\"1.409\"],[\"79577.10\",\"0.014\"],[\"79578.10\",\"0.074\"],[\"79579.50\",\"0.003\"],[\"79581.00\",\"0.000\"],[\"79581.10\",\"0.076\"],[\"79581.60\",\"0.002\"],[\"79582.70\",\"0.706\"],[\"79583.30\",\"0.178\"],[\"79585.60\",\"0.002\"],[\"79585.80\",\"0.000\"],[\"79586.50\",\"0.000\"],[\"79587.50\",\"0.027\"],[\"79587.70\",\"0.032\"],[\"79587.80\",\"0.026\"],[\"79588.20\",\"0.002\"],[\"79588.90\",\"1.000\"],[\"79591.00\",\"0.077\"],[\"79592.90\",\"2.780\"]],\"a\":[[\"79593.00\",\"15.597\"],[\"79594.20\",\"0.460\"],[\"79594.30\",\"0.374\"],[\"79595.70\",\"0.001\"],[\"79596.60\",\"0.005\"],[\"79599.10\",\"0.000\"],[\"79599.60\",\"0.000\"],[\"79602.50\",\"0.074\"],[\"79602.60\",\"0.339\"],[\"79604.80\",\"0.439\"],[\"79605.20\",\"0.004\"],[\"79605.90\",\"0.004\"],[\"79610.00\",\"0.413\"],[\"79610.10\",\"0.007\"],[\"79611.20\",\"2.165\"],[\"79611.50\",\"0.049\"],[\"79611.60\",\"0.281\"],[\"79613.70\",\"0.000\"],[\"79614.90\",\"0.452\"],[\"79615.40\",\"4.618\"],[\"79615.70\",\"0.001\"],[\"79618.40\",\"0.642\"],[\"79619.30\",\"0.001\"],[\"79620.60\",\"0.008\"],[\"79624.30\",\"0.254\"],[\"79624.50\",\"0.048\"],[\"79625.00\",\"0.148\"],[\"79625.80\",\"0.000\"],[\"79657.70\",\"0.939\"],[\"79685.40\",\"0.094\"],[\"79715.10\",\"0.471\"],[\"79753.70\",\"0.670\"],[\"79754.50\",\"2.041\"],[\"80388.90\",\"0.116\"],[\"80587.90\",\"1.256\"],[\"80684.90\",\"0.894\"],[\"80707.30\",\"3.712\"]],\"st\":1}}"}
{"receive_ns":1788567557643796000,"stream":"btcusdt@depth@100ms","event_type":"depthUpdate","event_time_ms":1788567557675,"raw_json":"{\"stream\":\"btcusdt@depth@100ms\",\"data\":{\"e\":\"depthUpdate\",\"E\":1788567557675,\"T\":1788567557673,\"s\":\"BTCUSDT\",\"ps\":\"BTCUSDT\",\"U\":11478496383074,\"u\":11478496390623,\"pu\":11478496382778,\"b\":[[\"29392.90\",\"0.623\"],[\"29492.90\",\"1.477\"],[\"63674.00\",\"0.000\"],[\"71633.60\",\"0.004\"],[\"75613.20\",\"0.010\"],[\"75614.50\",\"0.004\"],[\"75614.60\",\"0.006\"],[\"76409.10\",\"0.002\"],[\"78797.00\",\"0.889\"],[\"79562.30\",\"1.244\"],[\"79567.10\",\"0.439\"],[\"79567.90\",\"0.120\"],[\"79586.00\",\"0.004\"],[\"79587.90\",\"0.028\"]],\"a\":[[\"80388.90\",\"0.116\"],[\"80962.00\",\"0.492\"],[\"87552.30\",\"0.000\"]],\"st\":1}}"}
{"receive_ns":1788567557746124000,"stream":"btcusdt@depth@100ms","event_type":"depthUpdate","event_time_ms":1788567557777,"raw_json":"{\"stream\":\"btcusdt@depth@100ms\",\"data\":{\"e\":\"depthUpdate\",\"E\":1788567557777,\"T\":1788567557774,\"s\":\"BTCUSDT\",\"ps\":\"BTCUSDT\",\"U\":11478496390732,\"u\":11478496398144,\"pu\":11478496390623,\"b\":[[\"1000.00\",\"24.604\"],[\"29392.90\",\"0.798\"],[\"29492.90\",\"1.302\"],[\"63674.30\",\"0.000\"],[\"71633.60\",\"0.002\"],[\"75614.50\",\"0.002\"],[\"75614.60\",\"0.008\"],[\"76409.10\",\"0.000\"],[\"78598.00\",\"0.774\"],[\"78797.00\",\"0.889\"],[\"79426.10\",\"0.010\"],[\"79465.50\",\"0.000\"],[\"79528.10\",\"0.831\"],[\"79543.90\",\"0.001\"],[\"79544.00\",\"2.545\"],[\"79563.20\",\"0.291\"],[\"79576.40\",\"2.920\"],[\"79579.60\",\"0.968\"],[\"79586.10\",\"0.001\"],[\"79586.30\",\"0.025\"],[\"79586.60\",\"0.103\"],[\"79586.80\",\"0.278\"],[\"79588.10\",\"0.028\"],[\"79588.80\",\"0.030\"]],\"a\":[[\"79593.00\",\"15.593\"],[\"79594.10\",\"0.000\"],[\"79594.30\",\"0.373\"],[\"79612.90\",\"2.415\"],[\"79628.80\",\"0.829\"],[\"79715.10\",\"0.000\"],[\"79754.50\",\"0.000\"],[\"79797.00\",\"0.004\"],[\"79991.00\",\"0.001\"],[\"80388.90\",\"0.116\"]],\"st\":1}}"}
{"receive_ns":1788567557852607000,"stream":"btcusdt@depth@100ms","event_type":"depthUpdate","event_time_ms":1788567557879,"raw_json":"{\"stream\":\"btcusdt@depth@100ms\",\"data\":{\"e\":\"depthUpdate\",\"E\":1788567557879,\"T\":1788567557878,\"s\":\"BTCUSDT\",\"ps\":\"BTCUSDT\",\"U\":11478496398492,\"u\":11478496405417,\"pu\":11478496398144,\"b\":[[\"1000.00\",\"24.604\"],[\"29392.90\",\"0.980\"],[\"29492.90\",\"1.120\"],[\"63674.00\",\"0.000\"],[\"71633.60\",\"0.002\"],[\"77364.30\",\"0.516\"],[\"78797.00\",\"0.889\"],[\"79194.90\",\"1.892\"],[\"79426.10\",\"2.352\"],[\"79427.90\",\"0.192\"],[\"79465.50\",\"0.489\"],[\"79563.20\",\"0.166\"],[\"79569.20\",\"0.067\"],[\"79569.60\",\"0.005\"],[\"79570.70\",\"0.007\"],[\"79576.90\",\"0.069\"],[\"79577.10\",\"0.076\"],[\"79580.80\",\"0.001\"],[\"79585.40\",\"0.002\"],[\"79586.60\",\"0.077\"],[\"79589.00\",\"0.027\"]],\"a\":[[\"79609.10\",\"0.003\"],[\"79613.30\",\"0.453\"],[\"79614.90\",\"0.000\"],[\"79715.10\",\"0.471\"],[\"79753.70\",\"0.442\"],[\"79754.50\",\"2.041\"],[\"79757.10\",\"0.000\"],[\"80388.90\",\"0.116\"],[\"80558.30\",\"14.769\"],[\"80800.80\",\"0.290\"]],\"st\":1}}"}
{"receive_ns":1788567557949461000,"stream":"btcusdt@depth@100ms","event_type":"depthUpdate","event_time_ms":1788567557981,"raw_json":"{\"stream\":\"btcusdt@depth@100ms\",\"data\":{\"e\":\"depthUpdate\",\"E\":1788567557981,\"T\":1788567557977,\"s\":\"BTCUSDT\",\"ps\":\"BTCUSDT\",\"U\":11478496405543,\"u\":11478496413894,\"pu\":11478496405417,\"b\":[[\"29392.90\",\"1.155\"],[\"29492.90\",\"0.945\"],[\"63674.00\",\"0.002\"],[\"71633.60\",\"0.002\"],[\"76409.10\",\"0.002\"],[\"78448.90\",\"10.797\"],[\"78797.00\",\"0.889\"],[\"78956.20\",\"0.253\"],[\"79426.10\",\"0.010\"],[\"79465.50\",\"0.000\"],[\"79592.90\",\"2.776\"]],\"a\":[[\"79653.50\",\"0.029\"],[\"79715.10\",\"0.000\"],[\"79748.50\",\"0.032\"],[\"79750.80\",\"0.018\"],[\"79754.50\",\"0.000\"],[\"80229.70\",\"0.250\"],[\"80388.90\",\"0.116\"],[\"80665.00\",\"0.995\"],[\"80798.30\",\"0.216\"]],\"st\":1}}"}
{"receive_ns":1788567558052301000,"stream":"btcusdt@depth@100ms","event_type":"depthUpdate","event_time_ms":1788567558083,"raw_json":"{\"stream\":\"btcusdt@depth@100ms\",\"data\":{\"e\":\"depthUpdate\",\"E\":1788567558083,\"T\":1788567558081,\"s\":\"BTCUSDT\",\"ps\":\"BTCUSDT\",\"U\":11478496414047,\"u\":11478496421556,\"pu\":11478496413894,\"b\":[[\"1000.00\",\"24.754\"],[\"29392.90\",\"1.337\"],[\"29492.90\",\"0.763\"],[\"63674.00\",\"0.000\"],[\"71633.60\",\"0.002\"],[\"76409.10\",\"0.000\"],[\"78797.00\",\"0.889\"],[\"79367.00\",\"0.293\"],[\"79381.00\",\"1.003\"],[\"79405.80\",\"0.000\"],[\"79426.20\",\"2.482\"],[\"79445.70\",\"0.032\"],[\"79448.90\",\"0.000\"],[\"79465.60\",\"0.536\"],[\"79512.70\",\"0.019\"],[\"79524.80\",\"0.002\"],[\"79562.40\",\"0.003\"],[\"79562.60\",\"0.001\"],[\"79578.60\",\"0.070\"],[\"79580.20\",\"0.206\"],[\"79592.90\",\"2.774\"]],\"a\":[[\"79593.00\",\"15.595\"],[\"79715.10\",\"0.471\"],[\"79748.50\",\"0.000\"],[\"79750.00\",\"1.277\"],[\"79754.50\",\"2.046\"],[\"80388.90\",\"0.116\"],[\"80548.10\",\"3.100\"],[\"80637.80\",\"4.303\"],[\"80757.40\",\"11.559\"]],\"st\":1}}"}
{"receive_ns":1788567558156614000,"stream":"btcusdt@depth@100ms","event_type":"depthUpdate","event_time_ms":1788567558185,"raw_json":"{\"stream\":\"btcusdt@depth@100ms\",\"data\":{\"e\":\"depthUpdate\",\"E\":1788567558185,\"T\":1788567558181,\"s\":\"BTCUSDT\",\"ps\":\"BTCUSDT\",\"U\":11478496421690,\"u\":11478496428450,\"pu\":11478496421556,\"b\":[[\"1000.00\",\"24.604\"],[\"29392.90\",\"1.512\"],[\"29492.90\",\"0.588\"],[\"63674.00\",\"0.000\"],[\"71633.60\",\"0.002\"],[\"76409.10\",\"0.002\"],[\"78553.60\",\"0.001\"],[\"78555.00\",\"12.714\"],[\"78797.00\",\"0.889\"],[\"79194.90\",\"1.892\"],[\"79465.60\",\"0.529\"],[\"79467.40\",\"0.016\"],[\"79478.60\",\"0.007\"],[\"79495.50\",\"0.034\"],[\"79537.10\",\"0.013\"],[\"79562.30\",\"1.244\"],[\"79562.50\",\"0.548\"],[\"79563.10\",\"0.131\"]],\"a\":[[\"79688.60\",\"0.046\"],[\"79689.90\",\"6.000\"],[\"79698.70\",\"0.002\"],[\"79712.40\",\"0.449\"],[\"79715.30\",\"0.000\"],[\"79728.40\",\"0.089\"],[\"79742.80\",\"0.033\"],[\"79750.00\",\"1.245\"],[\"79811.60\",\"0.001\"],[\"79991.00\",\"0.000\"],[\"80388.90\",\"0.116\"],[\"80549.60\",\"10.150\"],[\"80710.10\",\"0.160\"],[\"80720.60\",\"0.374\"]],\"st\":1}}"}
{"receive_ns":1788567558256353000,"stream":"btcusdt@depth@100ms","event_type":"depthUpdate","event_time_ms":1788567558287,"raw_json":"{\"stream\":\"btcusdt@depth@100ms\",\"data\":{\"e\":\"depthUpdate\",\"E\":1788567558287,\"T\":1788567558285,\"s\":\"BTCUSDT\",\"ps\":\"BTCUSDT\",\"U\":11478496428729,\"u\":11478496435128,\"pu\":11478496428450,\"b\":[[\"29392.90\",\"1.694\"],[\"29492.90\",\"0.406\"],[\"71633.60\",\"0.002\"],[\"78797.00\",\"0.889\"],[\"78814.80\",\"1.131\"],[\"79194.90\",\"1.893\"],[\"79562.20\",\"0.128\"],[\"79588.80\",\"0.004\"],[\"79589.00\",\"0.001\"]],\"a\":[[\"79593.00\",\"15.597\"],[\"79613.70\",\"0.006\"],[\"79616.30\",\"0.012\"],[\"79742.80\",\"0.001\"],[\"79750.00\",\"1.277\"],[\"80388.90\",\"0.116\"],[\"80747.10\",\"1.736\"],[\"81184.80\",\"0.030\"]],\"st\":1}}"}
{"receive_ns":1788567558359471000,"stream":"btcusdt@depth@100ms","event_type":"depthUpdate","event_time_ms":1788567558389,"raw_json":"{\"stream\":\"btcusdt@depth@100ms\",\"data\":{\"e\":\"depthUpdate\",\"E\":1788567558389,\"T\":1788567558387,\"s\":\"BTCUSDT\",\"ps\":\"BTCUSDT\",\"U\":11478496435295,\"u\":11478496441575,\"pu\":11478496435128,\"b\":[[\"1000.00\",\"24.604\"],[\"29292.90\",\"0.042\"],[\"29392.90\",\"1.785\"],[\"29492.90\",\"0.273\"],[\"71633.60\",\"0.002\"],[\"75614.60\",\"0.006\"],[\"76409.10\",\"0.000\"],[\"78797.00\",\"0.891\"],[\"79465.60\",\"0.000\"],[\"79465.70\",\"0.529\"],[\"79561.90\",\"0.235\"],[\"79562.20\",\"0.003\"],[\"79586.10\",\"0.027\"],[\"79586.20\",\"0.026\"],[\"79586.30\",\"0.051\"],[\"79586.50\",\"0.026\"],[\"79586.60\",\"0.103\"],[\"79586.70\",\"0.027\"],[\"79587.40\",\"0.000\"],[\"79587.50\",\"0.001\"],[\"79587.70\",\"0.006\"],[\"79587.80\",\"0.000\"],[\"79587.90\",\"0.002\"],[\"79588.10\",\"0.002\"],[\"79592.90\",\"2.775\"]],\"a\":[[\"79594.10\",\"0.076\"],[\"79596.10\",\"0.255\"],[\"79596.60\",\"0.001\"],[\"79599.10\",\"0.004\"],[\"79616.90\",\"0.164\"],[\"79617.10\",\"0.000\"],[\"79715.10\",\"0.471\"],[\"79750.00\",\"1.245\"],[\"79753.70\",\"0.474\"],[\"80010.40\",\"0.087\"],[\"80388.90\",\"0.116\"]],\"st\":1}}"}
{"receive_ns":1788567558460074000,"stream":"btcusdt@depth@100ms","event_type":"depthUpdate","event_time_ms":1788567558491,"raw_json":"{\"stream\":\"btcusdt@depth@100ms\",\"data\":{\"e\":\"depthUpdate\",\"E\":1788567558491,\"T\":1788567558489,\"s\":\"BTCUSDT\",\"ps\":\"BTCUSDT\",\"U\":11478496441669,\"u\":11478496453252,\"pu\":11478496441575,\"b\":[[\"29292.90\",\"0.098\"],[\"29392.90\",\"1.855\"],[\"29492.90\",\"0.147\"],[\"71633.60\",\"0.002\"],[\"71670.00\",\"0.000\"],[\"76409.10\",\"0.002\"],[\"78247.80\",\"0.638\"],[\"78441.30\",\"2.993\"],[\"78797.00\",\"0.889\"],[\"78806.90\",\"2.551\"],[\"78836.80\",\"1.524\"],[\"79005.90\",\"3.214\"],[\"79194.90\",\"1.903\"],[\"79465.70\",\"0.529\"],[\"79500.50\",\"0.962\"],[\"79501.60\",\"0.629\"],[\"79529.40\",\"0.207\"],[\"79531.20\",\"1.169\"],[\"79531.70\",\"0.677\"],[\"79549.30\",\"2.981\"],[\"79576.40\",\"2.778\"],[\"79579.60\",\"0.948\"],[\"79582.50\",\"0.171\"],[\"79586.80\",\"0.026\"],[\"79592.90\",\"2.772\"]],\"a\":[[\"79642.10\",\"0.004\"],[\"79662.00\",\"0.003\"],[\"79689.90\",\"0.000\"],[\"79707.70\",\"0.068\"],[\"79715.10\",\"0.471\"],[\"79749.40\",\"0.032\"],[\"79753.70\",\"0.442\"],[\"79932.30\",\"0.003\"],[\"79956.60\",\"0.002\"],[\"80388.90\",\"0.116\"],[\"80587.90\",\"1.534\"]],\"st\":1}}"}
{"receive_ns":1788567558561688000,"stream":"btcusdt@depth@100ms","event_type":"depthUpdate","event_time_ms":1788567558593,"raw_json":"{\"stream\":\"btcusdt@depth@100ms\",\"data\":{\"e\":\"depthUpdate\",\"E\":1788567558593,\"T\":1788567558590,\"s\":\"BTCUSDT\",\"ps\":\"BTCUSDT\",\"U\":11478496453463,\"u\":11478496460370,\"pu\":11478496453252,\"b\":[[\"29292.90\",\"0.161\"],[\"29392.90\",\"1.904\"],[\"29492.90\",\"0.035\"],[\"63674.00\",\"0.000\"],[\"71633.60\",\"0.002\"],[\"76409.10\",\"0.000\"],[\"78797.00\",\"0.889\"],[\"79297.10\",\"0.000\"],[\"79427.90\",\"0.521\"],[\"79460.10\",\"0.006\"],[\"79461.90\",\"0.201\"],[\"79462.00\",\"0.002\"],[\"79463.80\",\"1.446\"],[\"79500.50\",\"0.969\"],[\"79537.40\",\"0.002\"],[\"79550.40\",\"0.951\"],[\"79561.70\",\"0.126\"],[\"79561.90\",\"0.110\"],[\"79583.20\",\"0.004\"],[\"79585.40\",\"0.000\"],[\"79587.40\",\"0.026\"]],\"a\":[[\"79593.00\",\"15.589\"],[\"79728.00\",\"1.007\"],[\"79729.20\",\"0.000\"],[\"79742.00\",\"1.235\"],[\"79749.40\",\"0.000\"],[\"79753.70\",\"0.671\"],[\"80388.90\",\"0.116\"],[\"80587.90\",\"1.683\"],[\"80755.10\",\"0.371\"]],\"st\":1}}"}
{"receive_ns":1788567558666177000,"stream":"btcusdt@depth@100ms","event_type":"depthUpdate","event_time_ms":1788567558695,"raw_json":"{\"stream\":\"btcusdt@depth@100ms\",\"data\":{\"e\":\"depthUpdate\",\"E\":1788567558695,\"T\":1788567558693,\"s\":\"BTCUSDT\",\"ps\":\"BTCUSDT\",\"U\":11478496460545,\"u\":11478496468115,\"pu\":11478496460370,\"b\":[[\"1000.00\",\"24.604\"],[\"29292.90\",\"0.308\"],[\"29392.90\",\"1.792\"],[\"29492.90\",\"0.000\"],[\"63674.00\",\"0.000\"],[\"63674.30\",\"0.000\"],[\"71633.60\",\"0.002\"],[\"76409.10\",\"0.002\"],[\"78797.00\",\"0.889\"],[\"78954.70\",\"0.128\"],[\"79111.00\",\"0.483\"],[\"79143.80\",\"0.000\"],[\"79176.70\",\"0.000\"],[\"79209.60\",\"0.000\"],[\"79242.50\",\"0.002\"],[\"79275.40\",\"1.207\"],[\"79308.30\",\"0.000\"],[\"79341.20\",\"0.000\"],[\"79374.10\",\"0.000\"],[\"79407.00\",\"0.000\"],[\"79426.20\",\"0.000\"],[\"79426.40\",\"2.493\"],[\"79427.90\",\"0.192\"],[\"79439.80\",\"0.000\"],[\"79465.70\",\"0.529\"],[\"79472.70\",\"0.014\"],[\"79498.30\",\"6.000\"],[\"79499.70\",\"1.751\"],[\"79505.60\",\"0.032\"],[\"79526.10\",\"3.500\"],[\"79532.30\",\"0.000\"],[\"79538.50\",\"0.000\"],[\"79544.50\",\"0.003\"],[\"79546.00\",\"0.565\"],[\"79560.70\",\"0.053\"],[\"79586.00\",\"0.030\"],[\"79586.90\",\"0.000\"],[\"79587.10\",\"0.026\"],[\"79587.40\",\"0.000\"],[\"79592.90\",\"2.763\"]],\"a\":[[\"79604.30\",\"0.140\"],[\"79637.20\",\"0.001\"],[\"79638.50\",\"0.566\"],[\"79657.70\",\"1.341\"],[\"79658.40\",\"3.502\"],[\"79670.10\",\"0.185\"],[\"79684.10\",\"2.241\"],[\"79686.30\",\"6.000\"],[\"79703.00\",\"0.044\"],[\"79715.10\",\"0.471\"],[\"79735.80\",\"0.000\"],[\"79742.00\",\"1.203\"],[\"79753.70\",\"0.442\"],[\"79754.10\",\"0.032\"],[\"79754.50\",\"2.033\"],[\"79758.60\",\"0.038\"],[\"79768.70\",\"0.000\"],[\"79801.60\",\"0.001\"],[\"79834.50\",\"0.000\"],[\"79867.40\",\"0.000\"],[\"80239.90\",\"0.250\"],[\"80388.90\",\"0.116\"],[\"81186.10\",\"4.059\"]],\"st\":1}}"}
{"receive_ns":1788567558766819000,"stream":"btcusdt@depth@100ms","event_type":"depthUpdate","event_time_ms":1788567558797,"raw_json":"{\"stream\":\"btcusdt@depth@100ms\",\"data\":{\"e\":\"depthUpdate\",\"E\":1788567558797,\"T\":1788567558796,\"s\":\"BTCUSDT\",\"ps\":\"BTCUSDT\",\"U\":11478496468177,\"u\":11478496475576,\"pu\":11478496468115,\"b\":[[\"29292.90\",\"0.483\"],[\"29392.90\",\"1.617\"],[\"71633.60\",\"0.002\"],[\"78647.90\",\"27.720\"],[\"78797.00\",\"0.889\"],[\"79194.90\",\"1.893\"],[\"79445.70\",\"0.000\"],[\"79446.40\",\"0.058\"],[\"79457.40\",\"0.002\"],[\"79529.20\",\"0.006\"],[\"79533.20\",\"1.143\"],[\"79562.80\",\"0.001\"],[\"79565.00\",\"0.257\"],[\"79576.00\",\"0.009\"],[\"79576.70\",\"1.711\"],[\"79579.20\",\"0.019\"],[\"79586.80\",\"0.278\"],[\"79588.10\",\"0.028\"],[\"79588.60\",\"0.026\"]],\"a\":[[\"79593.00\",\"15.508\"],[\"79594.10\",\"0.000\"],[\"79613.70\",\"0.000\"],[\"79616.90\",\"0.170\"],[\"79630.10\",\"0.001\"],[\"79632.20\",\"0.046\"],[\"79750.80\",\"0.018\"],[\"79750.90\",\"0.032\"],[\"79754.10\",\"0.000\"],[\"80016.50\",\"0.003\"],[\"80040.50\",\"0.000\"],[\"80388.90\",\"0.116\"],[\"80587.90\",\"1.869\"],[\"80675.10\",\"0.000\"],[\"80751.60\",\"0.001\"]],\"st\":1}}"}
{"receive_ns":1788567558869396000,"stream":"btcusdt@depth@100ms","event_type":"depthUpdate","event_time_ms":1788567558899,"raw_json":"{\"stream\":\"btcusdt@depth@100ms\",\"data\":{\"e\":\"depthUpdate\",\"E\":1788567558899,\"T\":1788567558898,\"s\":\"BTCUSDT\",\"ps\":\"BTCUSDT\",\"U\":11478496475729,\"u\":11478496483429,\"pu\":11478496475576,\"b\":[[\"29292.90\",\"0.665\"],[\"29392.90\",\"1.435\"],[\"71633.60\",\"0.002\"],[\"75613.20\",\"0.015\"],[\"76409.10\",\"0.000\"],[\"78478.60\",\"4.073\"],[\"78601.90\",\"0.000\"],[\"78637.80\",\"6.984\"],[\"78797.00\",\"0.889\"],[\"79194.90\",\"1.892\"],[\"79458.50\",\"11.508\"],[\"79561.70\",\"0.001\"],[\"79562.70\",\"0.126\"],[\"79562.80\",\"0.001\"],[\"79563.40\",\"0.003\"],[\"79569.20\",\"0.067\"],[\"79588.60\",\"0.000\"]],\"a\":[[\"79593.00\",\"15.506\"],[\"79609.10\",\"0.003\"],[\"79726.20\",\"10.008\"],[\"79991.00\",\"0.001\"],[\"80388.90\",\"0.116\"],[\"80708.80\",\"2.761\"],[\"80754.80\",\"0.000\"]],\"st\":1}}"}
{"receive_ns":1788567558972841000,"stream":"btcusdt@depth@100ms","event_type":"depthUpdate","event_time_ms":1788567559001,"raw_json":"{\"stream\":\"btcusdt@depth@100ms\",\"data\":{\"e\":\"depthUpdate\",\"E\":1788567559001,\"T\":1788567558998,\"s\":\"BTCUSDT\",\"ps\":\"BTCUSDT\",\"U\":11478496483527,\"u\":11478496490040,\"pu\":11478496483429,\"b\":[[\"1000.00\",\"24.604\"],[\"29292.90\",\"0.840\"],[\"29392.90\",\"1.260\"],[\"71633.60\",\"0.002\"],[\"76409.10\",\"0.002\"],[\"78637.80\",\"8.254\"],[\"78797.00\",\"0.889\"],[\"79218.00\",\"0.004\"],[\"79426.40\",\"0.000\"],[\"79465.70\",\"0.000\"]],\"a\":[[\"79593.00\",\"15.509\"],[\"79715.10\",\"0.000\"],[\"79726.10\",\"0.006\"],[\"79727.40\",\"2.855\"],[\"79749.90\",\"0.032\"],[\"79750.90\",\"0.000\"],[\"79754.50\",\"0.000\"],[\"80200.00\",\"16.869\"],[\"80388.90\",\"0.116\"],[\"80848.10\",\"0.123\"]],\"st\":1}}"}
{"receive_ns":1788567559071947000,"stream":"btcusdt@depth@100ms","event_type":"depthUpdate","event_time_ms":1788567559103,"raw_json":"{\"stream\":\"btcusdt@depth@100ms\",\"data\":{\"e\":\"depthUpdate\",\"E\":1788567559103,\"T\":1788567559101,\"s\":\"BTCUSDT\",\"ps\":\"BTCUSDT\",\"U\":11478496490344,\"u\":11478496497723,\"pu\":11478496490040,\"b\":[[\"29292.90\",\"1.022\"],[\"29392.90\",\"1.078\"],[\"68963.40\",\"0.008\"],[\"71633.60\",\"0.002\"],[\"75613.20\",\"0.020\"],[\"76409.10\",\"0.000\"],[\"78369.30\",\"3.545\"],[\"78673.60\",\"0.002\"],[\"78797.00\",\"0.889\"],[\"79193.00\",\"0.293\"],[\"79194.90\",\"1.892\"],[\"79378.20\",\"0.000\"],[\"79378.70\",\"5.477\"],[\"79426.40\",\"2.492\"],[\"79465.80\",\"0.539\"],[\"79578.60\",\"0.070\"],[\"79587.50\",\"0.027\"],[\"79588.10\",\"0.002\"]],\"a\":[[\"79715.20\",\"0.472\"],[\"79749.90\",\"0.000\"],[\"79750.90\",\"0.032\"],[\"79754.60\",\"2.009\"],[\"79802.20\",\"0.002\"],[\"79802.30\",\"2.806\"],[\"80200.00\",\"16.246\"],[\"80328.20\",\"0.000\"],[\"80388.90\",\"0.116\"],[\"80707.30\",\"6.805\"],[\"80723.20\",\"0.148\"],[\"80747.10\",\"1.860\"],[\"80819.10\",\"0.000\"]],\"st\":1}}"}
{"receive_ns":1788567559173572000,"stream":"btcusdt@depth@100ms","event_type":"depthUpdate","event_time_ms":1788567559205,"raw_json":"{\"stream\":\"btcusdt@depth@100ms\",\"data\":{\"e\":\"depthUpdate\",\"E\":1788567559205,\"T\":1788567559204,\"s\":\"BTCUSDT\",\"ps\":\"BTCUSDT\",\"U\":11478496497902,\"u\":11478496505426,\"pu\":11478496497723,\"b\":[[\"29292.90\",\"1.197\"],[\"29392.90\",\"0.903\"],[\"63674.00\",\"0.000\"],[\"71633.60\",\"0.002\"],[\"76409.10\",\"0.002\"],[\"78002.40\",\"0.003\"],[\"78368.10\",\"0.022\"],[\"78797.00\",\"0.889\"],[\"79005.90\",\"2.582\"],[\"79588.10\",\"0.028\"]],\"a\":[[\"79593.00\",\"15.505\"],[\"79610.90\",\"0.631\"],[\"79614.00\",\"0.002\"],[\"79615.00\",\"0.005\"],[\"79750.90\",\"0.000\"],[\"79752.40\",\"0.032\"],[\"79752.90\",\"0.000\"],[\"79777.10\",\"0.900\"],[\"79777.30\",\"0.000\"],[\"80200.00\",\"15.623\"],[\"80388.90\",\"1.358\"],[\"81184.80\",\"0.027\"]],\"st\":1}}"}
{"receive_ns":1788567559275692000,"stream":"btcusdt@depth@100ms","event_type":"depthUpdate","event_time_ms":1788567559307,"raw_json":"{\"stream\":\"btcusdt@depth@100ms\",\"data\":{\"e\":\"depthUpdate\",\"E\":1788567559307,\"T\":1788567559305,\"s\":\"BTCUSDT\",\"ps\":\"BTCUSDT\",\"U\":11478496505536,\"u\":11478496513273,\"pu\":11478496505426,\"b\":[[\"1000.00\",\"24.604\"],[\"29292.90\",\"1.379\"],[\"29392.90\",\"0.721\"],[\"71633.60\",\"0.002\"],[\"78598.00\",\"0.965\"],[\"78797.00\",\"0.889\"],[\"79194.90\",\"1.891\"],[\"79446.40\",\"0.026\"],[\"79451.30\",\"0.033\"],[\"79465.80\",\"0.541\"],[\"79533.90\",\"0.199\"],[\"79535.70\",\"0.003\"],[\"79562.70\",\"0.001\"],[\"79575.00\",\"0.003\"],[\"79578.40\",\"0.003\"],[\"79586.00\",\"0.004\"],[\"79588.50\",\"0.097\"]],\"a\":[[\"79610.90\",\"0.003\"],[\"79614.20\",\"0.013\"],[\"79615.00\",\"0.633\"],[\"79616.90\",\"0.164\"],[\"79715.20\",\"0.489\"],[\"79991.00\",\"0.002\"],[\"80341.20\",\"0.789\"],[\"80388.90\",\"1.358\"],[\"80817.90\",\"0.024\"]],\"st\":1}}"}
{"receive_ns":1788567559379397000,"stream":"btcusdt@depth@100ms","event_type":"depthUpdate","event_time_ms":1788567559409,"raw_json":"{\"stream\":\"btcusdt@depth@100ms\",\"data\":{\"e\":\"depthUpdate\",\"E\":1788567559409,\"T\":1788567559405,\"s\":\"BTCUSDT\",\"ps\":\"BTCUSDT\",\"U\":11478496513417,\"u\":11478496522392,\"pu\":11478496513273,\"b\":[[\"29292.90\",\"1.554\"],[\"29392.90\",\"0.546\"],[\"71633.60\",\"0.002\"],[\"76409.10\",\"0.000\"],[\"78260.80\",\"0.023\"],[\"78505.70\",\"4.745\"],[\"78637.80\",\"11.682\"],[\"78797.00\",\"0.889\"],[\"79194.90\",\"1.901\"],[\"79447.40\",\"0.032\"],[\"79451.30\",\"0.001\"],[\"79465.80\",\"0.010\"],[\"79465.90\",\"1.142\"],[\"79514.30\",\"0.813\"],[\"79537.10\",\"0.011\"],[\"79562.30\",\"1.369\"],[\"79569.00\",\"0.004\"],[\"79585.80\",\"0.026\"],[\"79585.90\",\"0.027\"],[\"79586.00\",\"0.030\"],[\"79586.70\",\"0.027\"],[\"79586.80\",\"0.000\"],[\"79587.30\",\"0.004\"],[\"79587.50\",\"0.001\"],[\"79588.10\",\"0.002\"],[\"79588.50\",\"0.071\"],[\"79592.90\",\"2.699\"]],\"a\":[[\"79594.10\",\"0.183\"],[\"79594.20\",\"0.415\"],[\"79595.60\",\"0.028\"],[\"79688.60\",\"0.044\"],[\"79715.20\",\"0.489\"],[\"79728.40\",\"0.089\"],[\"79748.70\",\"0.032\"],[\"79752.40\",\"0.000\"],[\"81113.50\",\"0.000\"]],\"st\":1}}"}
{"receive_ns":1788567559480028000,"stream":"btcusdt@depth@100ms","event_type":"depthUpdate","event_time_ms":1788567559511,"raw_json":"{\"stream\":\"btcusdt@depth@100ms\",\"data\":{\"e\":\"depthUpdate\",\"E\":1788567559511,\"T\":1788567559510,\"s\":\"BTCUSDT\",\"ps\":\"BTCUSDT\",\"U\":11478496522747,\"u\":11478496533628,\"pu\":11478496522392,\"b\":[[\"1000.00\",\"24.604\"],[\"29292.90\",\"1.736\"],[\"29392.90\",\"0.364\"],[\"71633.60\",\"0.002\"],[\"76409.10\",\"0.002\"],[\"77327.60\",\"0.778\"],[\"78001.10\",\"0.015\"],[\"78797.00\",\"0.889\"],[\"79447.10\",\"0.032\"],[\"79447.40\",\"0.000\"],[\"79465.90\",\"0.611\"],[\"79561.80\",\"0.847\"],[\"79562.30\",\"1.244\"],[\"79577.30\",\"0.004\"],[\"79578.10\",\"0.072\"],[\"79582.70\",\"0.454\"],[\"79583.10\",\"0.002\"],[\"79585.80\",\"0.026\"],[\"79586.10\",\"0.001\"],[\"79586.20\",\"0.000\"],[\"79586.30\",\"0.025\"],[\"79586.50\",\"0.000\"],[\"79586.60\",\"0.077\"],[\"79586.70\",\"0.001\"],[\"79586.80\",\"0.000\"],[\"79587.10\",\"0.026\"],[\"79591.00\",\"0.001\"],[\"79592.90\",\"2.716\"]],\"a\":[[\"79593.00\",\"15.512\"],[\"79715.20\",\"0.001\"],[\"79748.50\",\"0.032\"],[\"79748.70\",\"0.000\"],[\"80315.80\",\"0.031\"],[\"80388.90\",\"1.358\"],[\"81145.10\",\"0.554\"]],\"st\":1}}"}
{"receive_ns":1788567559582072000,"stream":"btcusdt@depth@100ms","event_type":"depthUpdate","event_time_ms":1788567559613,"raw_json":"{\"stream\":\"btcusdt@depth@100ms\",\"data\":{\"e\":\"depthUpdate\",\"E\":1788567559613,\"T\":1788567559611,\"s\":\"BTCUSDT\",\"ps\":\"BTCUSDT\",\"U\":11478496533813,\"u\":11478496554413,\"pu\":11478496533628,\"b\":[[\"1000.00\",\"24.604\"],[\"29192.90\",\"0.056\"],[\"29292.90\",\"1.799\"],[\"29392.90\",\"0.245\"],[\"63674.00\",\"0.000\"],[\"71633.60\",\"0.002\"],[\"71670.00\",\"0.003\"],[\"76409.10\",\"0.000\"],[\"78438.80\",\"0.891\"],[\"78797.00\",\"0.889\"],[\"78807.10\",\"4.988\"],[\"79426.40\",\"0.000\"],[\"79426.50\",\"2.462\"],[\"79427.90\",\"0.518\"],[\"79465.90\",\"1.142\"],[\"79514.30\",\"0.390\"],[\"79515.40\",\"0.927\"],[\"79515.50\",\"0.673\"],[\"79528.10\",\"0.002\"],[\"79531.30\",\"0.010\"],[\"79544.00\",\"1.854\"],[\"79555.10\",\"0.543\"],[\"79569.50\",\"0.554\"],[\"79570.10\",\"0.001\"],[\"79572.60\",\"1.887\"],[\"79574.50\",\"0.001\"],[\"79574.60\",\"0.251\"],[\"79576.90\",\"0.071\"],[\"79577.30\",\"0.002\"],[\"79583.70\",\"0.002\"],[\"79583.80\",\"0.002\"],[\"79584.00\",\"0.032\"],[\"79584.10\",\"0.128\"],[\"79584.20\",\"0.027\"],[\"79584.30\",\"0.026\"],[\"79584.40\",\"0.115\"],[\"79584.50\",\"0.034\"],[\"79584.80\",\"0.027\"],[\"79585.00\",\"0.030\"],[\"79585.10\",\"0.026\"],[\"79585.20\",\"0.027\"],[\"79585.30\",\"0.000\"],[\"79585.40\",\"0.000\"],[\"79585.50\",\"0.076\"],[\"79585.60\",\"0.002\"],[\"79585.80\",\"0.000\"],[\"79585.90\",\"0.001\"],[\"79586.00\",\"0.004\"],[\"79592.90\",\"2.131\"]],\"a\":[[\"79593.00\",\"15.580\"],[\"79605.80\",\"0.035\"],[\"79618.40\",\"0.712\"],[\"79621.80\",\"0.016\"],[\"79629.60\",\"0.006\"],[\"79634.40\",\"0.002\"],[\"79636.30\",\"0.002\"],[\"79638.20\",\"0.541\"],[\"79649.00\",\"0.016\"],[\"79664.70\",\"0.000\"],[\"79715.20\",\"0.489\"],[\"79724.50\",\"3.702\"],[\"79753.70\",\"0.681\"],[\"79754.60\",\"2.128\"],[\"80336.10\",\"10.294\"],[\"80388.90\",\"1.358\"]],\"st\":1}}"}
{"receive_ns":1788567559868738000,"stream":"btcusdt@depth@100ms","event_type":"depthUpdate","event_time_ms":1788567559715,"raw_json":"{\"stream\":\"btcusdt@depth@100ms\",\"data\":{\"e\":\"depthUpdate\",\"E\":1788567559715,\"T\":1788567559714,\"s\":\"BTCUSDT\",\"ps\":\"BTCUSDT\",\"U\":11478496555041,\"u\":11478496609882,\"pu\":11478496554413,\"b\":[[\"29189.20\",\"0.042\"],[\"29190.90\",\"0.007\"],[\"29192.90\",\"0.063\"],[\"29289.20\",\"0.084\"],[\"29290.60\",\"0.014\"],[\"29291.00\",\"0.007\"],[\"29292.70\",\"0.007\"],[\"29292.90\",\"1.757\"],[\"29392.90\",\"0.119\"],[\"63671.00\",\"0.000\"],[\"63674.30\",\"0.000\"],[\"71630.20\",\"0.002\"],[\"71633.60\",\"0.000\"],[\"71670.00\",\"0.000\"],[\"77997.40\",\"1.153\"],[\"77997.50\",\"0.009\"],[\"77998.70\",\"0.065\"],[\"78001.10\",\"0.012\"],[\"78002.40\",\"0.000\"],[\"78673.20\",\"5.296\"],[\"78673.40\",\"1.510\"],[\"78674.90\",\"1.903\"],[\"78675.00\",\"0.081\"],[\"78675.10\",\"0.762\"],[\"78676.10\",\"0.000\"],[\"78676.80\",\"0.003\"],[\"78676.90\",\"0.000\"],[\"78792.80\",\"0.253\"],[\"78793.30\",\"1.078\"],[\"78793.70\",\"0.444\"],[\"78794.70\",\"0.000\"],[\"78794.90\",\"0.000\"],[\"78795.00\",\"0.157\"],[\"78795.10\",\"0.000\"],[\"78795.40\",\"0.000\"],[\"78796.10\",\"0.000\"],[\"78796.30\",\"0.000\"],[\"78797.00\",\"0.889\"],[\"78811.00\",\"0.084\"],[\"78811.30\",\"1.546\"],[\"79194.90\",\"1.901\"],[\"79227.90\",\"0.075\"],[\"79248.80\",\"1.043\"],[\"79267.80\",\"0.865\"],[\"79369.70\",\"0.003\"],[\"79373.20\",\"7.593\"],[\"79373.60\",\"0.001\"],[\"79375.90\",\"1.712\"],[\"79378.70\",\"0.004\"],[\"79396.20\",\"3.392\"],[\"79396.90\",\"0.007\"],[\"79414.80\",\"0.000\"],[\"79416.00\",\"0.513\"],[\"79432.10\",\"0.002\"],[\"79436.30\",\"1.886\"],[\"79440.80\",\"0.002\"],[\"79441.10\",\"0.000\"],[\"79443.80\",\"0.000\"],[\"79444.10\",\"2.441\"],[\"79460.90\",\"0.004\"],[\"79466.70\",\"0.002\"],[\"79468.30\",\"0.002\"],[\"79469.00\",\"0.002\"],[\"79471.10\",\"0.000\"],[\"79471.20\",\"0.003\"],[\"79473.80\",\"1.195\"],[\"79473.90\",\"0.207\"],[\"79476.90\",\"0.004\"],[\"79479.60\",\"0.011\"],[\"79480.20\",\"0.000\"],[\"79480.50\",\"0.039\"],[\"79480.70\",\"0.038\"],[\"79482.20\",\"0.034\"],[\"79482.50\",\"0.001\"],[\"79482.80\",\"0.039\"],[\"79484.50\",\"0.031\"],[\"79484.70\",\"0.000\"],[\"79485.10\",\"0.017\"],[\"79486.10\",\"0.038\"],[\"79486.40\",\"0.038\"],[\"79486.60\",\"0.001\"],[\"79487.00\",\"0.020\"],[\"79487.80\",\"0.000\"],[\"79491.60\",\"0.009\"],[\"79492.10\",\"0.000\"],[\"79493.70\",\"0.668\"],[\"79494.20\",\"0.001\"],[\"79494.50\",\"0.001\"],[\"79495.50\",\"1.229\"],[\"79495.60\",\"0.000\"],[\"79496.20\",\"0.039\"],[\"79496.50\",\"0.000\"],[\"79496.70\",\"0.001\"],[\"79497.80\",\"0.019\"],[\"79499.00\",\"0.041\"],[\"79500.10\",\"0.000\"],[\"79500.70\",\"0.044\"],[\"79500.80\",\"0.590\"],[\"79501.40\",\"0.106\"],[\"79501.90\",\"0.234\"],[\"79502.30\",\"0.234\"],[\"79502.50\",\"0.020\"],[\"79503.00\",\"0.040\"],[\"79503.30\",\"0.000\"],[\"79503.40\",\"1.288\"],[\"79503.70\",\"0.006\"],[\"79503.80\",\"2.541\"],[\"79504.40\",\"0.011\"],[\"79504.80\",\"0.001\"],[\"79505.10\",\"0.048\"],[\"79505.30\",\"0.000\"],[\"79505.70\",\"3.465\"],[\"79505.90\",\"0.197\"],[\"79506.50\",\"0.002\"],[\"79506.80\",\"0.019\"],[\"79507.50\",\"0.013\"],[\"79508.50\",\"0.119\"],[\"79508.80\",\"0.649\"],[\"79509.00\",\"0.253\"],[\"79509.50\",\"0.614\"],[\"79509.90\",\"0.237\"],[\"79510.00\",\"0.155\"],[\"79510.10\",\"0.061\"],[\"79510.40\",\"0.213\"],[\"79511.10\",\"0.020\"],[\"79511.40\",\"0.039\"],[\"79511.50\",\"0.030\"],[\"79511.70\",\"1.741\"],[\"79513.50\",\"0.002\"],[\"79513.60\",\"0.000\"],[\"79513.80\",\"0.000\"],[\"79513.90\",\"0.235\"],[\"79514.30\",\"0.362\"],[\"79514.60\",\"0.098\"],[\"79514.90\",\"0.001\"],[\"79515.10\",\"0.016\"],[\"79515.40\",\"0.060\"],[\"79515.80\",\"0.016\"],[\"79516.10\",\"0.016\"],[\"79516.20\",\"0.039\"],[\"79516.60\",\"0.000\"],[\"79516.90\",\"0.428\"],[\"79517.00\",\"0.332\"],[\"79517.20\",\"1.195\"],[\"79517.30\",\"0.005\"],[\"79517.40\",\"0.646\"],[\"79518.50\",\"2.929\"],[\"79518.80\",\"0.020\"],[\"79519.40\",\"1.415\"],[\"79520.30\",\"0.419\"],[\"79520.40\",\"0.004\"],[\"79520.50\",\"19.336\"],[\"79520.90\",\"0.001\"],[\"79521.30\",\"0.060\"],[\"79522.00\",\"0.038\"],[\"79522.60\",\"0.312\"],[\"79523.20\",\"0.001\"],[\"79524.10\",\"0.001\"],[\"79524.30\",\"0.001\"],[\"79524.70\",\"0.028\"],[\"79524.80\",\"0.000\"],[\"79525.60\",\"0.032\"],[\"79525.90\",\"0.198\"],[\"79526.10\",\"3.519\"],[\"79527.40\",\"0.003\"],[\"79527.60\",\"1.394\"],[\"79528.70\",\"0.077\"],[\"79528.90\",\"0.007\"],[\"79529.00\",\"0.643\"],[\"79529.30\",\"0.003\"],[\"79529.90\",\"0.201\"],[\"79530.10\",\"0.003\"],[\"79533.20\",\"1.162\"],[\"79533.90\",\"0.196\"],[\"79534.10\",\"0.004\"],[\"79535.10\",\"0.001\"],[\"79535.60\",\"0.145\"],[\"79536.40\",\"0.022\"],[\"79536.60\",\"0.027\"],[\"79536.70\",\"0.002\"],[\"79536.90\",\"0.001\"],[\"79537.70\",\"0.023\"],[\"79537.80\",\"0.010\"],[\"79540.60\",\"0.150\"],[\"79540.80\",\"0.002\"],[\"79541.50\",\"0.004\"],[\"79541.70\",\"0.000\"],[\"79542.20\",\"0.004\"],[\"79542.70\",\"0.001\"],[\"79542.80\",\"1.593\"],[\"79543.10\",\"0.203\"],[\"79543.40\",\"0.002\"],[\"79543.50\",\"0.151\"],[\"79543.80\",\"0.015\"],[\"79544.20\",\"0.094\"],[\"79544.30\",\"0.072\"],[\"79545.10\",\"0.002\"],[\"79546.20\",\"0.001\"],[\"79546.80\",\"0.710\"],[\"79547.00\",\"0.005\"],[\"79548.60\",\"0.016\"],[\"79548.80\",\"0.008\"],[\"79549.00\",\"1.366\"],[\"79549.20\",\"0.052\"],[\"79549.90\",\"0.014\"],[\"79550.70\",\"0.252\"],[\"79551.00\",\"0.600\"],[\"79551.40\",\"0.000\"],[\"79551.60\",\"0.020\"],[\"79552.40\",\"0.026\"],[\"79552.60\",\"0.049\"],[\"79552.70\",\"0.031\"],[\"79552.80\",\"0.001\"],[\"79553.40\",\"0.000\"],[\"79554.20\",\"0.010\"],[\"79554.70\",\"0.002\"],[\"79554.80\",\"0.116\"],[\"79555.00\",\"1.717\"],[\"79555.20\",\"0.005\"],[\"79555.40\",\"2.574\"],[\"79556.10\",\"0.591\"],[\"79556.30\",\"0.356\"],[\"79556.60\",\"0.046\"],[\"79556.70\",\"1.225\"],[\"79556.80\",\"0.003\"],[\"79557.10\",\"0.001\"],[\"79557.40\",\"0.000\"],[\"79558.30\",\"0.294\"],[\"79558.70\",\"0.032\"],[\"79559.00\",\"0.002\"],[\"79559.50\",\"0.001\"],[\"79559.80\",\"0.453\"],[\"79559.90\",\"2.074\"],[\"79560.00\",\"3.528\"],[\"79560.20\",\"0.040\"],[\"79560.50\",\"0.201\"],[\"79560.70\",\"0.000\"],[\"79560.80\",\"0.002\"],[\"79561.00\",\"0.003\"],[\"79561.30\",\"0.002\"],[\"79561.70\",\"0.021\"],[\"79561.80\",\"0.722\"],[\"79562.50\",\"0.548\"],[\"79562.60\",\"0.001\"],[\"79562.70\",\"0.001\"],[\"79562.80\",\"0.000\"],[\"79562.90\",\"0.077\"],[\"79563.20\",\"0.112\"],[\"79563.30\",\"0.002\"],[\"79563.50\",\"2.168\"],[\"79563.60\",\"2.109\"],[\"79563.80\",\"0.001\"],[\"79563.90\",\"0.003\"],[\"79564.10\",\"0.002\"],[\"79564.20\",\"0.007\"],[\"79564.40\",\"0.551\"],[\"79564.50\",\"0.002\"],[\"79564.70\",\"1.482\"],[\"79564.80\",\"0.067\"],[\"79564.90\",\"0.003\"],[\"79565.10\",\"0.637\"],[\"79565.20\",\"0.439\"],[\"79565.50\",\"0.000\"],[\"79565.90\",\"0.037\"],[\"79566.30\",\"0.433\"],[\"79566.50\",\"0.003\"],[\"79566.60\",\"0.128\"],[\"79566.70\",\"0.003\"],[\"79566.80\",\"0.000\"],[\"79567.00\",\"0.254\"],[\"79567.10\",\"0.006\"],[\"79567.30\",\"0.000\"],[\"79567.60\",\"0.374\"],[\"79567.80\",\"1.539\"],[\"79567.90\",\"0.001\"],[\"79568.10\",\"0.003\"],[\"79568.30\",\"0.003\"],[\"79568.60\",\"0.628\"],[\"79568.90\",\"0.003\"],[\"79569.00\",\"0.003\"],[\"79569.10\",\"0.000\"],[\"79569.40\",\"0.000\"],[\"79569.50\",\"0.000\"],[\"79569.60\",\"0.006\"],[\"79570.20\",\"0.004\"],[\"79570.40\",\"0.001\"],[\"79570.60\",\"0.080\"],[\"79570.70\",\"0.161\"],[\"79571.00\",\"0.000\"],[\"79571.10\",\"0.091\"],[\"79571.30\",\"0.001\"],[\"79571.60\",\"0.003\"],[\"79571.70\",\"0.003\"],[\"79571.90\",\"1.569\"],[\"79572.00\",\"0.358\"],[\"79572.10\",\"0.001\"],[\"79572.40\",\"0.003\"],[\"79572.60\",\"2.515\"],[\"79572.70\",\"0.000\"],[\"79572.80\",\"0.008\"],[\"79572.90\",\"0.002\"],[\"79573.30\",\"0.495\"],[\"79573.40\",\"1.720\"],[\"79573.50\",\"0.015\"],[\"79573.60\",\"0.129\"],[\"79574.00\",\"0.003\"],[\"79574.20\",\"0.139\"],[\"79574.40\",\"0.018\"],[\"79574.50\",\"0.076\"],[\"79574.60\",\"0.000\"],[\"79574.70\",\"0.033\"],[\"79574.80\",\"0.001\"],[\"79574.90\",\"0.002\"],[\"79575.10\",\"0.075\"],[\"79575.40\",\"0.080\"],[\"79575.60\",\"0.078\"],[\"79575.80\",\"0.000\"],[\"79576.00\",\"0.004\"],[\"79576.40\",\"0.041\"],[\"79576.50\",\"0.001\"],[\"79576.60\",\"0.103\"],[\"79576.70\",\"0.078\"],[\"79576.80\",\"0.002\"],[\"79576.90\",\"0.004\"],[\"79577.00\",\"0.003\"],[\"79577.10\",\"0.002\"],[\"79577.20\",\"0.080\"],[\"79577.30\",\"0.002\"],[\"79577.40\",\"0.000\"],[\"79577.50\",\"0.000\"],[\"79577.70\",\"0.072\"],[\"79577.80\",\"0.077\"],[\"79577.90\",\"0.353\"],[\"79578.00\",\"1.579\"],[\"79578.10\",\"0.073\"],[\"79578.30\",\"0.197\"],[\"79578.40\",\"0.003\"],[\"79578.50\",\"0.004\"],[\"79578.60\",\"0.110\"],[\"79578.70\",\"0.101\"],[\"79578.80\",\"0.001\"],[\"79578.90\",\"0.111\"],[\"79579.00\",\"0.002\"],[\"79579.10\",\"0.027\"],[\"79579.30\",\"0.060\"],[\"79579.40\",\"0.026\"],[\"79579.50\",\"0.028\"],[\"79579.60\",\"0.585\"],[\"79579.70\",\"0.000\"],[\"79579.80\",\"0.001\"],[\"79579.90\",\"0.001\"],[\"79580.00\",\"0.091\"],[\"79580.10\",\"0.127\"],[\"79580.20\",\"0.105\"],[\"79580.30\",\"0.002\"],[\"79580.40\",\"0.034\"],[\"79580.50\",\"0.002\"],[\"79580.80\",\"0.001\"],[\"79580.90\",\"0.002\"],[\"79581.00\",\"0.000\"],[\"79581.20\",\"0.027\"],[\"79581.40\",\"0.000\"],[\"79581.50\",\"0.001\"],[\"79581.60\",\"0.001\"],[\"79581.70\",\"0.027\"],[\"79582.00\",\"0.027\"],[\"79582.10\",\"0.027\"],[\"79582.20\",\"1.147\"],[\"79582.30\",\"0.099\"],[\"79582.50\",\"0.071\"],[\"79582.60\",\"0.097\"],[\"79582.70\",\"0.202\"],[\"79582.80\",\"0.100\"],[\"79582.90\",\"0.001\"],[\"79583.00\",\"0.003\"],[\"79583.20\",\"0.000\"],[\"79583.30\",\"0.077\"],[\"79583.40\",\"0.001\"],[\"79583.50\",\"0.000\"],[\"79583.60\",\"0.000\"],[\"79583.70\",\"0.023\"],[\"79583.80\",\"0.002\"],[\"79584.00\",\"0.005\"],[\"79584.10\",\"0.000\"],[\"79584.20\",\"0.001\"],[\"79584.30\",\"0.000\"],[\"79584.40\",\"0.013\"],[\"79584.50\",\"0.007\"],[\"79584.60\",\"0.003\"],[\"79584.80\",\"0.003\"],[\"79584.90\",\"0.002\"],[\"79585.00\",\"0.002\"],[\"79585.10\",\"0.000\"],[\"79585.20\",\"0.001\"],[\"79585.30\",\"0.080\"],[\"79585.40\",\"0.503\"],[\"79585.50\",\"0.001\"],[\"79585.70\",\"0.017\"],[\"79585.90\",\"0.001\"],[\"79586.00\",\"0.001\"],[\"79586.10\",\"0.001\"],[\"79586.30\",\"0.000\"],[\"79586.40\",\"0.003\"],[\"79586.50\",\"0.001\"],[\"79586.60\",\"0.001\"],[\"79586.80\",\"0.000\"],[\"79587.00\",\"0.003\"],[\"79587.10\",\"0.000\"],[\"79587.20\",\"0.004\"],[\"79587.30\",\"0.001\"],[\"79587.50\",\"0.000\"],[\"79587.70\",\"0.003\"],[\"79587.80\",\"0.439\"],[\"79587.90\",\"0.001\"],[\"79588.00\",\"0.003\"],[\"79588.10\",\"0.001\"],[\"79588.20\",\"0.001\"],[\"79588.30\",\"0.000\"],[\"79588.40\",\"0.002\"],[\"79588.50\",\"0.000\"],[\"79588.80\",\"0.001\"],[\"79588.90\",\"0.001\"],[\"79589.00\",\"0.001\"],[\"79589.20\",\"1.493\"],[\"79589.30\",\"0.000\"],[\"79589.50\",\"0.000\"],[\"79589.60\",\"0.000\"],[\"79590.00\",\"0.000\"],[\"79590.20\",\"0.000\"],[\"79590.40\",\"0.000\"],[\"79590.50\",\"0.000\"],[\"79590.60\",\"0.000\"],[\"79590.90\",\"0.000\"],[\"79591.00\",\"0.000\"],[\"79591.10\",\"0.000\"],[\"79591.20\",\"0.000\"],[\"79591.30\",\"0.000\"],[\"79592.00\",\"0.000\"],[\"79592.20\",\"0.000\"],[\"79592.30\",\"0.000\"],[\"79592.40\",\"0.000\"],[\"79592.50\",\"0.000\"],[\"79592.60\",\"0.000\"],[\"79592.70\",\"0.000\"],[\"79592.80\",\"0.000\"],[\"79592.90\",\"0.000\"]],\"a\":[[\"79589.30\",\"12.716\"],[\"79589.40\",\"0.004\"],[\"79589.50\",\"0.102\"],[\"79589.60\",\"0.006\"],[\"79589.70\",\"1.319\"],[\"79589.80\",\"0.001\"],[\"79589.90\",\"0.000\"],[\"79590.00\",\"0.001\"],[\"79590.10\",\"0.298\"],[\"79590.20\",\"0.001\"],[\"79590.30\",\"0.000\"],[\"79590.50\",\"0.000\"],[\"79590.60\",\"2.500\"],[\"79590.70\",\"2.097\"],[\"79590.80\",\"0.012\"],[\"79590.90\",\"0.001\"],[\"79591.00\",\"3.753\"],[\"79591.10\",\"0.227\"],[\"79591.20\",\"0.003\"],[\"79591.30\",\"0.002\"],[\"79591.40\",\"1.223\"],[\"79591.50\",\"0.000\"],[\"79591.60\",\"0.001\"],[\"79591.70\",\"0.000\"],[\"79591.80\",\"0.001\"],[\"79592.00\",\"0.080\"],[\"79592.10\",\"0.062\"],[\"79592.20\",\"0.000\"],[\"79592.30\",\"0.000\"],[\"79592.40\",\"0.000\"],[\"79592.50\",\"0.000\"],[\"79592.60\",\"0.000\"],[\"79592.70\",\"0.004\"],[\"79592.80\",\"1.245\"],[\"79592.90\",\"2.510\"],[\"79593.00\",\"3.603\"],[\"79593.10\",\"0.018\"],[\"79593.20\",\"0.001\"],[\"79593.30\",\"0.001\"],[\"79593.50\",\"0.001\"],[\"79593.60\",\"0.002\"],[\"79594.10\",\"0.000\"],[\"79594.20\",\"0.078\"],[\"79594.30\",\"0.369\"],[\"79594.40\",\"0.001\"],[\"79594.80\",\"0.040\"],[\"79594.90\",\"0.028\"],[\"79595.10\",\"0.004\"],[\"79595.20\",\"0.081\"],[\"79595.40\",\"0.000\"],[\"79595.60\",\"0.002\"],[\"79595.80\",\"0.000\"],[\"79595.90\",\"0.049\"],[\"79596.00\",\"0.005\"],[\"79596.10\",\"0.255\"],[\"79596.20\",\"0.000\"],[\"79596.30\",\"0.501\"],[\"79596.50\",\"0.077\"],[\"79596.60\",\"0.005\"],[\"79596.70\",\"0.366\"],[\"79596.80\",\"0.002\"],[\"79596.90\",\"0.001\"],[\"79597.00\",\"0.045\"],[\"79597.10\",\"0.006\"],[\"79597.30\",\"0.039\"],[\"79597.60\",\"0.001\"],[\"79597.70\",\"1.224\"],[\"79598.00\",\"0.001\"],[\"79598.10\",\"0.196\"],[\"79598.20\",\"0.003\"],[\"79598.50\",\"0.000\"],[\"79598.60\",\"0.548\"],[\"79598.70\",\"0.004\"],[\"79598.80\",\"0.003\"],[\"79598.90\",\"0.003\"],[\"79599.10\",\"0.004\"],[\"79599.20\",\"0.001\"],[\"79599.30\",\"0.203\"],[\"79600.00\",\"0.006\"],[\"79600.20\",\"0.001\"],[\"79600.30\",\"0.003\"],[\"79600.80\",\"0.011\"],[\"79601.00\",\"0.004\"],[\"79601.10\",\"0.002\"],[\"79601.30\",\"0.000\"],[\"79601.60\",\"0.000\"],[\"79601.90\",\"0.130\"],[\"79602.40\",\"0.116\"],[\"79602.50\",\"0.321\"],[\"79602.60\",\"0.459\"],[\"79602.70\",\"0.465\"],[\"79602.80\",\"1.622\"],[\"79602.90\",\"0.004\"],[\"79603.00\",\"0.016\"],[\"79603.20\",\"1.002\"],[\"79603.30\",\"0.026\"],[\"79603.40\",\"0.001\"],[\"79603.50\",\"0.005\"],[\"79603.90\",\"0.201\"],[\"79604.00\",\"0.030\"],[\"79604.30\",\"0.141\"],[\"79604.50\",\"0.018\"],[\"79604.60\",\"0.020\"],[\"79604.70\",\"0.042\"],[\"79604.80\",\"0.004\"],[\"79605.00\",\"0.060\"],[\"79605.20\",\"0.002\"],[\"79605.30\",\"0.005\"],[\"79605.50\",\"0.118\"],[\"79605.60\",\"0.318\"],[\"79605.70\",\"0.012\"],[\"79605.80\",\"0.040\"],[\"79605.90\",\"0.064\"],[\"79606.00\",\"0.725\"],[\"79606.40\",\"0.001\"],[\"79606.50\",\"0.880\"],[\"79606.60\",\"0.701\"],[\"79606.70\",\"0.002\"],[\"79606.80\",\"0.472\"],[\"79606.90\",\"2.122\"],[\"79607.10\",\"0.149\"],[\"79607.20\",\"0.271\"],[\"79607.40\",\"0.395\"],[\"79607.50\",\"0.660\"],[\"79607.80\",\"0.330\"],[\"79607.90\",\"0.062\"],[\"79608.00\",\"0.029\"],[\"79608.30\",\"0.066\"],[\"79608.70\",\"0.004\"],[\"79608.80\",\"0.028\"],[\"79608.90\",\"1.920\"],[\"79609.00\",\"0.741\"],[\"79609.10\",\"0.003\"],[\"79609.30\",\"0.001\"],[\"79609.70\",\"0.057\"],[\"79609.80\",\"0.001\"],[\"79609.90\",\"0.066\"],[\"79610.00\",\"0.022\"],[\"79610.60\",\"0.370\"],[\"79611.00\",\"0.753\"],[\"79611.10\",\"1.663\"],[\"79611.20\",\"2.127\"],[\"79611.30\",\"0.004\"],[\"79611.60\",\"0.253\"],[\"79611.70\",\"0.882\"],[\"79611.80\",\"0.012\"],[\"79611.90\",\"0.052\"],[\"79612.00\",\"0.003\"],[\"79612.50\",\"0.002\"],[\"79613.30\",\"0.001\"],[\"79613.50\",\"0.030\"],[\"79613.60\",\"0.031\"],[\"79613.70\",\"0.038\"],[\"79613.80\",\"0.341\"],[\"79614.10\",\"0.001\"],[\"79614.20\",\"0.012\"],[\"79614.30\",\"0.628\"],[\"79614.50\",\"0.074\"],[\"79615.00\",\"0.551\"],[\"79615.10\",\"4.845\"],[\"79615.20\",\"0.002\"],[\"79615.30\",\"0.712\"],[\"79615.40\",\"4.577\"],[\"79615.80\",\"0.507\"],[\"79616.00\",\"0.006\"],[\"79616.40\",\"0.632\"],[\"79616.60\",\"0.004\"],[\"79616.70\",\"0.711\"],[\"79616.90\",\"0.104\"],[\"79617.20\",\"0.088\"],[\"79617.30\",\"0.790\"],[\"79617.40\",\"0.000\"],[\"79617.50\",\"0.006\"],[\"79617.60\",\"0.086\"],[\"79617.70\",\"0.001\"],[\"79618.00\",\"0.201\"],[\"79618.40\",\"0.640\"],[\"79618.50\",\"0.000\"],[\"79618.70\",\"0.065\"],[\"79618.80\",\"0.204\"],[\"79619.00\",\"0.435\"],[\"79619.10\",\"0.003\"],[\"79619.40\",\"0.799\"],[\"79619.50\",\"0.000\"],[\"79619.90\",\"0.000\"],[\"79620.00\",\"0.096\"],[\"79620.10\",\"0.024\"],[\"79620.20\",\"0.003\"],[\"79620.30\",\"0.000\"],[\"79620.50\",\"0.000\"],[\"79620.60\",\"0.370\"],[\"79620.70\",\"0.016\"],[\"79621.10\",\"0.001\"],[\"79621.30\",\"0.745\"],[\"79621.80\",\"0.002\"],[\"79622.10\",\"0.388\"],[\"79622.20\",\"0.003\"],[\"79622.70\",\"0.038\"],[\"79622.90\",\"0.266\"],[\"79623.00\",\"0.016\"],[\"79623.10\",\"0.053\"],[\"79623.30\",\"0.024\"],[\"79623.60\",\"0.001\"],[\"79623.70\",\"0.441\"],[\"79624.30\",\"0.252\"],[\"79624.50\",\"0.002\"],[\"79624.70\",\"0.000\"],[\"79625.00\",\"0.186\"],[\"79625.30\",\"0.004\"],[\"79625.40\",\"0.417\"],[\"79625.70\",\"0.000\"],[\"79626.00\",\"0.008\"],[\"79626.30\",\"0.002\"],[\"79626.80\",\"0.222\"],[\"79627.20\",\"0.159\"],[\"79627.30\",\"0.040\"],[\"79627.60\",\"0.000\"],[\"79627.70\",\"0.225\"],[\"79627.80\",\"0.003\"],[\"79628.00\",\"1.498\"],[\"79628.10\",\"0.001\"],[\"79628.20\",\"0.005\"],[\"79628.80\",\"0.829\"],[\"79628.90\",\"0.000\"],[\"79629.40\",\"0.004\"],[\"79629.90\",\"0.000\"],[\"79630.00\",\"0.040\"],[\"79630.30\",\"0.004\"],[\"79631.00\",\"0.127\"],[\"79631.10\",\"0.017\"],[\"79631.90\",\"0.000\"],[\"79632.20\",\"0.044\"],[\"79632.40\",\"0.002\"],[\"79632.80\",\"0.001\"],[\"79633.50\",\"0.039\"],[\"79634.00\",\"0.166\"],[\"79635.00\",\"0.004\"],[\"79635.50\",\"0.000\"],[\"79635.60\",\"1.748\"],[\"79636.10\",\"0.069\"],[\"79636.80\",\"0.002\"],[\"79637.20\",\"0.000\"],[\"79637.50\",\"0.050\"],[\"79637.70\",\"0.608\"],[\"79638.60\",\"0.257\"],[\"79638.90\",\"0.005\"],[\"79639.90\",\"0.014\"],[\"79640.00\",\"0.059\"],[\"79640.10\",\"1.299\"],[\"79640.70\",\"0.064\"],[\"79641.10\",\"0.265\"],[\"79641.30\",\"0.228\"],[\"79641.40\",\"0.039\"],[\"79641.70\",\"0.000\"],[\"79642.00\",\"0.039\"],[\"79642.50\",\"0.000\"],[\"79642.60\",\"0.085\"],[\"79642.70\",\"0.028\"],[\"79643.00\",\"0.006\"],[\"79643.30\",\"0.086\"],[\"79643.40\",\"1.654\"],[\"79644.10\",\"0.003\"],[\"79645.00\",\"0.001\"],[\"79645.20\",\"0.000\"],[\"79645.50\",\"0.000\"],[\"79645.60\",\"0.038\"],[\"79646.80\",\"0.159\"],[\"79647.10\",\"0.382\"],[\"79647.30\",\"0.011\"],[\"79647.90\",\"0.000\"],[\"79648.00\",\"0.147\"],[\"79649.70\",\"0.007\"],[\"79649.80\",\"0.000\"],[\"79650.40\",\"0.000\"],[\"79650.80\",\"0.103\"],[\"79652.00\",\"0.901\"],[\"79652.10\",\"0.417\"],[\"79652.30\",\"0.000\"],[\"79652.90\",\"0.010\"],[\"79653.30\",\"0.201\"],[\"79653.50\",\"0.001\"],[\"79654.70\",\"0.001\"],[\"79655.40\",\"0.011\"],[\"79655.50\",\"0.003\"],[\"79655.60\",\"2.275\"],[\"79655.70\",\"0.003\"],[\"79656.20\",\"0.053\"],[\"79656.60\",\"0.001\"],[\"79656.70\",\"0.000\"],[\"79658.00\",\"22.278\"],[\"79658.40\",\"3.503\"],[\"79659.40\",\"0.000\"],[\"79659.90\",\"0.000\"],[\"79660.60\",\"0.038\"],[\"79660.70\",\"0.004\"],[\"79661.70\",\"0.003\"],[\"79663.10\",\"0.026\"],[\"79663.50\",\"0.012\"],[\"79663.60\",\"0.252\"],[\"79664.00\",\"0.024\"],[\"79664.50\",\"0.000\"],[\"79666.10\",\"0.014\"],[\"79667.30\",\"0.001\"],[\"79668.60\",\"0.017\"],[\"79668.90\",\"0.016\"],[\"79669.00\",\"0.033\"],[\"79669.30\",\"0.000\"],[\"79673.90\",\"0.000\"],[\"79674.80\",\"0.000\"],[\"79675.60\",\"0.457\"],[\"79676.70\",\"0.057\"],[\"79676.90\",\"0.102\"],[\"79677.20\",\"0.500\"],[\"79678.10\",\"0.015\"],[\"79680.50\",\"0.010\"],[\"79682.30\",\"0.000\"],[\"79684.30\",\"0.024\"],[\"79684.90\",\"0.085\"],[\"79685.00\",\"0.190\"],[\"79685.40\",\"0.009\"],[\"79686.10\",\"0.015\"],[\"79687.20\",\"4.358\"],[\"79687.70\",\"0.062\"],[\"79688.60\",\"0.002\"],[\"79689.60\",\"0.015\"],[\"79690.80\",\"0.148\"],[\"79692.00\",\"2.349\"],[\"79692.90\",\"0.001\"],[\"79699.40\",\"0.001\"],[\"79700.20\",\"0.027\"],[\"79701.60\",\"0.171\"],[\"79702.00\",\"0.015\"],[\"79707.10\",\"0.066\"],[\"79707.70\",\"0.009\"],[\"79711.70\",\"0.032\"],[\"79711.90\",\"0.572\"],[\"79714.50\",\"2.050\"],[\"79716.70\",\"0.000\"],[\"79720.00\",\"1.231\"],[\"79720.20\",\"0.022\"],[\"79720.30\",\"0.504\"],[\"79721.30\",\"0.000\"],[\"79722.70\",\"0.011\"],[\"79724.30\",\"3.141\"],[\"79724.90\",\"0.102\"],[\"79726.10\",\"0.000\"],[\"79729.50\",\"0.011\"],[\"79736.20\",\"0.001\"],[\"79736.30\",\"0.000\"],[\"79738.50\",\"0.166\"],[\"79747.20\",\"0.049\"],[\"79748.50\",\"0.000\"],[\"79758.60\",\"0.019\"],[\"79771.00\",\"0.103\"],[\"79778.00\",\"1.387\"],[\"79778.10\",\"0.609\"],[\"79778.20\",\"0.426\"],[\"79778.30\",\"0.001\"],[\"79791.40\",\"0.001\"],[\"79798.10\",\"2.285\"],[\"79799.80\",\"1.191\"],[\"79800.00\",\"8.416\"],[\"79800.10\",\"0.000\"],[\"79803.50\",\"0.000\"],[\"79808.90\",\"0.250\"],[\"79821.80\",\"0.426\"],[\"79821.90\",\"0.000\"],[\"79827.30\",\"0.012\"],[\"79907.70\",\"0.005\"],[\"79916.00\",\"0.002\"],[\"79934.90\",\"0.500\"],[\"79987.20\",\"0.001\"],[\"79995.60\",\"0.013\"],[\"80001.00\",\"2.695\"],[\"80006.00\",\"0.006\"],[\"80017.90\",\"0.001\"],[\"80033.90\",\"0.000\"],[\"80066.80\",\"0.001\"],[\"80075.20\",\"0.000\"],[\"80146.40\",\"0.001\"],[\"80154.80\",\"0.001\"],[\"80226.00\",\"0.037\"],[\"80234.40\",\"1.645\"],[\"80385.20\",\"2.723\"],[\"80385.60\",\"0.005\"],[\"80386.60\",\"1.985\"],[\"80387.00\",\"0.006\"],[\"80387.30\",\"0.831\"],[\"80388.90\",\"1.358\"],[\"80549.60\",\"9.872\"],[\"80589.70\",\"0.088\"],[\"80591.10\",\"0.028\"],[\"80594.30\",\"2.614\"],[\"80595.20\",\"0.000\"],[\"80596.10\",\"0.000\"],[\"80596.30\",\"5.529\"],[\"80596.40\",\"0.000\"],[\"80667.50\",\"0.522\"],[\"81181.00\",\"0.219\"],[\"81184.80\",\"0.018\"]],\"st\":1}}"}
