{"kind": "depth", "E": 1787080681039, "U": 11315372554450, "u": 11315372562213, "recv_ms": 1787080680987, "bids": [[1000.0, 35.81], [14182.1, 2.758], [14288.9, 0.826], [58213.8, 0.003], [61447.9, 0.0], [62094.8, 0.006], [63522.3, 1.572], [63679.5, 1.099], [63744.4, 2.13], [63841.2, 1.212], [63912.6, 46.907], [63938.3, 1.097], [64035.3, 0.0], [64361.7, 0.0], [64365.4, 0.001], [64491.9, 0.441], [64526.5, 1.925], [64536.1, 0.03], [64647.5, 0.036], [64650.2, 0.498], [64653.4, 0.013], [64662.8, 0.319], [64665.1, 0.002], [64665.8, 2.129], [64665.9, 0.324], [64666.2, 0.702], [64667.3, 0.373], [64669.2, 0.198], [64670.0, 1.353], [64670.5, 0.237], [64673.8, 0.64], [64675.4, 0.626], [64675.5, 0.228], [64675.6, 0.001], [64675.8, 0.054], [64675.9, 0.006], [64677.4, 0.482], [64680.8, 0.086], [64681.7, 0.001], [64682.1, 7.971]], "asks": [[64682.2, 37.769], [64684.2, 0.009], [64684.5, 0.085], [64685.3, 3.505], [64686.2, 0.313], [64686.6, 0.001], [64686.9, 0.091], [64688.9, 0.008], [64689.0, 0.522], [64692.1, 0.009], [64693.6, 0.005], [64694.9, 0.165], [64695.3, 0.58], [64696.0, 0.041], [64697.7, 0.709], [64698.1, 0.0], [64698.3, 1.08], [64698.6, 0.324], [64699.0, 0.014], [64700.9, 0.007], [64701.6, 0.371], [64702.0, 2.958], [64703.5, 0.545], [64711.0, 0.325], [64712.6, 0.156], [64718.8, 0.022], [64737.4, 3.742], [64773.1, 0.211], [64841.9, 0.397], [64850.2, 7.675], [64850.3, 0.021], [64880.7, 0.093], [64889.0, 8.965], [64889.1, 0.149], [64955.2, 0.002], [65329.0, 0.271], [65432.9, 1.448]]}
{"kind": "depth", "E": 1787080681141, "U": 11315372562472, "u": 11315372571152, "recv_ms": 1787080681089, "bids": [[1000.0, 35.81], [14182.1, 3.108], [14288.9, 0.476], [58213.8, 0.003], [61447.9, 0.0], [63380.1, 2.507], [63599.3, 1.435], [63682.1, 0.0], [63737.7, 7.635], [63945.0, 8.907], [64035.3, 0.0], [64365.4, 0.0], [64602.6, 0.0], [64609.8, 0.002], [64609.9, 0.0], [64616.9, 0.33], [64617.0, 0.015], [64627.7, 0.025], [64630.3, 1.783], [64637.7, 0.012], [64640.4, 2.508], [64640.5, 0.002], [64640.6, 0.006], [64649.3, 0.0], [64650.2, 0.498], [64651.9, 0.709], [64652.4, 0.411], [64660.1, 0.928], [64661.2, 0.02], [64664.1, 0.011], [64664.4, 0.063], [64665.1, 0.002], [64665.8, 2.129], [64665.9, 0.324], [64670.5, 0.232], [64673.7, 0.11], [64674.4, 0.047], [64675.1, 1.35], [64675.3, 0.714], [64675.4, 0.125], [64675.5, 0.188], [64675.6, 0.001], [64675.8, 0.054], [64675.9, 0.006], [64677.4, 0.398], [64681.6, 0.087], [64682.1, 8.29]], "asks": [[64682.2, 37.986], [64684.5, 0.001], [64684.9, 0.001], [64685.3, 3.405], [64686.6, 0.001], [64689.6, 0.19], [64690.0, 1.309], [64693.5, 0.194], [64693.8, 0.025], [64695.1, 0.069], [64695.5, 0.008], [64696.3, 0.0], [64696.5, 0.464], [64696.6, 0.078], [64697.5, 0.199], [64698.0, 0.496], [64698.2, 0.778], [64698.3, 1.08], [64701.3, 0.225], [64701.8, 10.03], [64701.9, 0.025], [64702.0, 2.958], [64702.3, 0.139], [64702.8, 0.351], [64703.5, 0.545], [64705.8, 0.117], [64706.0, 0.005], [64712.6, 0.002], [64712.7, 0.006], [64712.8, 0.176], [64745.7, 0.01], [64746.2, 0.733], [64841.9, 10.807], [64850.2, 0.1], [64880.7, 5.735], [64889.0, 0.027], [65005.7, 0.002], [65329.0, 0.271], [65494.2, 1.517], [65498.1, 6.048], [65682.2, 0.001], [65975.8, 0.014]]}
{"kind": "depth", "E": 1787080681243, "U": 11315372571205, "u": 11315372583473, "recv_ms": 1787080681194, "bids": [[14182.1, 3.416], [14188.9, 0.196], [14288.9, 0.168], [14582.1, 0.056], [51746.0, 0.0], [58213.8, 0.003], [61447.9, 0.0], [62094.8, 0.009], [62733.4, 1.001], [63512.0, 4.272], [64035.3, 0.0], [64358.7, 0.015], [64519.5, 0.003], [64603.2, 3.264], [64616.9, 0.329], [64617.0, 0.006], [64627.7, 0.039], [64637.7, 0.007], [64637.8, 0.001], [64640.5, 0.001], [64640.6, 0.005], [64646.9, 0.374], [64647.0, 0.213], [64651.5, 0.011], [64651.9, 0.699], [64656.2, 1.339], [64658.8, 0.476], [64665.7, 0.165], [64669.2, 0.198], [64672.8, 0.642], [64672.9, 0.48], [64673.1, 0.028], [64675.0, 0.158], [64675.1, 1.023], [64675.2, 0.367], [64675.3, 0.307], [64675.4, 0.001], [64675.8, 0.304], [64677.8, 0.085], [64679.5, 0.073], [64679.6, 0.001], [64680.1, 0.002], [64680.5, 0.233], [64681.6, 0.003], [64682.1, 9.504]], "asks": [[64682.2, 38.109], [64683.6, 0.002], [64684.3, 2.504], [64684.4, 0.055], [64684.7, 0.084], [64685.1, 0.007], [64685.3, 3.406], [64686.9, 0.092], [64687.9, 3.124], [64688.0, 1.033], [64688.1, 1.691], [64688.7, 0.034], [64689.0, 0.527], [64690.0, 1.308], [64698.2, 0.778], [64701.8, 10.032], [64702.2, 0.001], [64745.3, 0.012], [64745.7, 0.0], [64767.5, 0.017], [64767.6, 0.028], [64801.9, 0.005], [65329.0, 0.271], [65429.5, 3.965], [65433.4, 1.816], [65433.6, 9.165], [65594.6, 63.934]]}
{"kind": "depth", "E": 1787080681345, "U": 11315372583602, "u": 11315372590589, "recv_ms": 1787080681291, "bids": [[1000.0, 35.81], [14182.1, 3.57], [14188.9, 0.0], [14288.9, 0.014], [14582.1, 0.252], [58213.8, 0.003], [61439.9, 3.0], [62086.7, 2.006], [62094.8, 0.006], [63589.0, 1.918], [63682.1, 0.02], [63905.9, 5.34], [63912.6, 46.127], [63938.3, 2.034], [64035.3, 0.0], [64365.5, 5.22], [64542.6, 0.0], [64585.1, 0.024], [64627.7, 0.039], [64630.6, 0.039], [64643.5, 0.067], [64649.8, 0.007], [64651.2, 1.182], [64651.5, 0.001], [64665.9, 0.326], [64675.4, 0.135], [64675.8, 0.054], [64677.7, 0.251], [64682.1, 9.284]], "asks": [[64682.2, 38.121], [64684.7, 0.085], [64686.6, 0.001], [64702.8, 0.892], [64703.5, 0.004], [64714.5, 0.589], [64725.4, 0.234], [64725.6, 0.001], [64743.6, 0.003], [64745.0, 2.343], [64745.3, 0.002], [64747.3, 0.001], [64766.7, 0.2], [64833.3, 0.073], [65329.0, 0.271], [65494.2, 2.273], [65498.1, 5.292], [65682.2, 0.021], [65786.0, 0.222], [65875.1, 0.0], [66259.7, 0.0]]}
{"kind": "depth", "E": 1787080681447, "U": 11315372590708, "u": 11315372597703, "recv_ms": 1787080681396, "bids": [[1000.0, 35.81], [14182.1, 3.57], [14184.3, 0.0], [14185.2, 0.0], [14185.7, 0.0], [14187.9, 0.0], [14282.1, 0.14], [14284.3, 0.0], [14285.2, 0.0], [14285.7, 0.0], [14288.9, 0.0], [14582.1, 0.49], [51746.0, 0.0], [58213.8, 0.003], [60793.2, 4.0], [61447.9, 0.0], [62094.8, 0.009], [63808.9, 0.783], [64035.3, 0.0], [64171.4, 9.491], [64358.7, 0.17], [64365.6, 1.443], [64486.8, 0.0], [64525.6, 0.0], [64526.5, 1.112], [64627.7, 0.039], [64654.5, 0.013], [64656.5, 0.314], [64656.8, 0.004], [64659.9, 0.003], [64661.5, 0.01], [64663.6, 0.001], [64668.8, 0.188], [64669.4, 0.009], [64670.0, 1.36], [64672.4, 0.0], [64672.8, 0.634], [64673.1, 0.036], [64673.4, 0.31], [64674.9, 0.568], [64675.3, 0.173], [64675.4, 0.001], [64676.2, 0.004], [64677.7, 0.001], [64679.7, 0.009], [64682.1, 9.286]], "asks": [[64682.2, 38.565], [64685.6, 0.0], [64685.8, 1.894], [64688.8, 0.001], [64689.0, 0.561], [64690.4, 0.0], [64691.7, 0.332], [64694.9, 0.09], [64695.4, 0.079], [64701.0, 1.684], [64701.7, 0.01], [64707.5, 0.019], [64714.3, 3.083], [64841.9, 0.397], [64873.5, 0.398], [64880.7, 0.093], [65329.0, 0.271], [65429.5, 4.873], [65433.6, 8.249], [65494.2, 3.029], [65498.1, 4.536]]}
{"kind": "depth", "E": 1787080681549, "U": 11315372597911, "u": 11315372606979, "recv_ms": 1787080681495, "bids": [[14182.1, 3.444], [14282.1, 0.028], [14582.1, 0.728], [58213.8, 0.003], [61447.9, 0.001], [63388.5, 0.009], [63592.8, 10.204], [63682.1, 0.0], [63880.3, 25.378], [63905.9, 6.12], [64035.3, 0.0], [64164.6, 0.31], [64358.7, 0.16], [64569.5, 0.0], [64576.7, 2.319], [64582.5, 0.064], [64617.7, 2.335], [64643.4, 0.817], [64647.9, 0.022], [64651.0, 0.012], [64651.2, 1.172], [64661.4, 0.0], [64662.5, 0.128], [64665.9, 0.326], [64674.8, 0.319], [64674.9, 0.567], [64675.2, 0.233], [64675.3, 0.173], [64675.8, 0.054], [64677.5, 0.002], [64677.7, 0.002], [64678.9, 0.026], [64679.1, 0.085], [64680.2, 0.089], [64681.2, 0.04], [64682.1, 8.693]], "asks": [[64682.2, 38.567], [64683.7, 0.489], [64684.1, 0.084], [64686.6, 0.001], [64687.9, 3.123], [64689.0, 0.407], [64702.8, 0.351], [64703.5, 0.545], [64744.7, 0.077], [64745.0, 2.333], [64760.1, 0.0], [64792.6, 2.319], [64796.4, 0.001], [64797.4, 0.112], [64800.0, 10.888], [64824.4, 0.0], [65329.0, 0.271], [65494.2, 4.541], [65498.1, 3.024], [65682.2, 0.001]]}
{"kind": "depth", "E": 1787080681651, "U": 11315372607219, "u": 11315372614717, "recv_ms": 1787080681599, "bids": [[1000.0, 35.81], [14182.1, 3.136], [14282.1, 0.0], [14582.1, 1.064], [58213.8, 0.003], [61447.9, 0.0], [61454.6, 0.002], [62094.8, 0.006], [63718.6, 9.834], [63841.2, 2.151], [63855.7, 2.658], [63873.6, 0.704], [64035.3, 0.0], [64556.0, 0.248], [64556.7, 0.0], [64562.5, 3.875], [64611.3, 1.097], [64664.6, 0.656], [64672.0, 0.009], [64675.2, 0.233], [64675.8, 0.054], [64678.9, 0.003], [64679.5, 0.054], [64680.4, 0.024], [64680.5, 0.253], [64682.1, 8.59]], "asks": [[64682.2, 38.677], [64685.1, 0.008], [64696.6, 0.541], [64697.1, 1.356], [64697.8, 0.781], [64698.2, 0.315], [64702.8, 0.892], [64703.5, 0.004], [64705.2, 0.618], [64712.8, 0.176], [64753.7, 0.15], [64798.8, 0.0], [64799.1, 0.089], [64818.0, 3.892], [65100.0, 56.781], [65329.0, 0.271], [65429.5, 5.781], [65433.6, 7.333], [65778.2, 0.611]]}
{"kind": "depth", "E": 1787080681753, "U": 11315372614931, "u": 11315372622823, "recv_ms": 1787080681702, "bids": [[1000.0, 35.81], [14182.1, 2.786], [14582.1, 1.414], [51745.7, 0.0], [58213.8, 0.003], [61447.9, 0.0], [62094.8, 0.009], [63000.4, 0.006], [63278.0, 0.003], [63284.6, 0.002], [63582.5, 1.254], [63682.1, 0.02], [64035.3, 0.002], [64418.8, 2.355], [64485.5, 5.248], [64486.8, 15.507], [64525.6, 5.994], [64542.6, 3.723], [64575.1, 0.987], [64624.2, 0.006], [64627.7, 0.025], [64643.4, 0.481], [64647.7, 0.739], [64660.1, 0.371], [64661.6, 0.559], [64664.6, 0.038], [64665.8, 1.203], [64665.9, 0.326], [64666.6, 0.973], [64675.2, 0.269], [64675.8, 0.054], [64677.4, 0.482], [64680.8, 0.002], [64682.1, 8.992]], "asks": [[64683.6, 0.086], [64686.6, 0.001], [64689.0, 0.564], [64689.5, 0.001], [64697.8, 0.163], [64698.3, 0.155], [64699.0, 0.939], [64701.0, 3.312], [64702.0, 2.901], [64702.8, 0.949], [64705.2, 0.0], [64712.8, 0.022], [64712.9, 0.26], [64717.7, 0.006], [64717.8, 0.0], [64717.9, 0.003], [64720.0, 1.865], [64720.7, 0.064], [64720.8, 0.067], [64720.9, 0.237], [64721.5, 0.002], [64721.6, 1.474], [64721.7, 0.0], [64723.7, 0.115], [64723.8, 0.001], [64723.9, 0.0], [64746.2, 1.482], [64753.7, 0.151], [64811.6, 0.0], [64824.9, 5.399], [64841.9, 10.807], [64842.0, 0.634], [64880.7, 5.701], [64953.8, 5.54], [64953.9, 32.489], [65329.0, 0.271], [65426.7, 9.533], [65429.5, 0.333], [65433.6, 6.417], [65491.4, 5.292], [65494.2, 0.005], [65498.1, 2.268], [65682.2, 0.021]]}
{"kind": "depth", "E": 1787080681855, "U": 11315372622846, "u": 11315372632583, "recv_ms": 1787080681804, "bids": [[14182.1, 2.422], [14582.1, 1.778], [51746.0, 0.0], [58213.8, 0.003], [61447.9, 0.0], [61448.0, 0.009], [62094.8, 0.006], [63763.6, 1.412], [63789.4, 2.506], [64035.3, 0.0], [64358.7, 0.17], [64650.6, 0.013], [64650.7, 0.166], [64651.0, 0.002], [64660.6, 0.558], [64661.6, 0.002], [64665.7, 1.091], [64666.6, 0.047], [64669.2, 0.074], [64671.1, 0.009], [64672.7, 0.201], [64672.8, 0.001], [64672.9, 0.542], [64673.1, 1.148], [64673.9, 0.044], [64674.0, 0.004], [64675.2, 0.233], [64675.3, 0.443], [64675.8, 0.054], [64682.1, 8.772]], "asks": [[64696.6, 0.07], [64698.3, 0.618], [64698.7, 0.023], [64702.8, 0.949], [64704.3, 0.126], [64744.4, 0.036], [64744.5, 0.001], [64744.7, 0.067], [64873.5, 0.0], [65329.0, 0.271], [65635.0, 2.892], [65659.3, 19.52]]}
{"kind": "depth", "E": 1787080681957, "U": 11315372633060, "u": 11315372641502, "recv_ms": 1787080681907, "bids": [[1000.0, 35.81], [14182.1, 2.058], [14582.1, 2.142], [58213.8, 0.003], [60879.7, 0.0], [62094.8, 0.009], [63682.1, 0.0], [64035.3, 0.002], [64319.7, 0.001], [64327.6, 0.593], [64542.6, 3.679], [64650.4, 0.639], [64650.6, 0.003], [64669.2, 0.553], [64670.2, 0.011], [64671.1, 0.001], [64672.9, 0.001], [64673.1, 0.027], [64673.2, 0.541], [64673.9, 0.121], [64674.0, 0.004], [64674.1, 0.543], [64675.3, 0.173], [64679.5, 0.032], [64679.6, 0.318], [64680.5, 0.021]], "asks": [[64682.2, 38.677], [64697.0, 1.169], [64702.8, 0.408], [64703.5, 0.545], [64744.2, 0.011], [64744.4, 0.026], [64824.9, 5.399], [64880.7, 5.941], [65012.4, 4.611], [65206.5, 9.335], [65329.0, 0.271], [65426.7, 12.257], [65433.4, 0.0], [65433.6, 5.501], [65682.2, 0.001], [65975.8, 0.017], [68514.0, 1.312]]}
{"kind": "depth", "E": 1787080682059, "U": 11315372641505, "u": 11315372647963, "recv_ms": 1787080682008, "bids": [[1000.0, 35.81], [14182.1, 1.708], [14582.1, 2.492], [58213.8, 0.003], [61447.9, 0.0], [63754.6, 9.185], [63796.0, 0.625], [63873.6, 0.97], [64035.3, 0.0], [64649.9, 0.083], [64650.2, 0.441], [64665.9, 0.326], [64669.1, 0.581], [64669.2, 0.074], [64670.5, 0.232], [64671.1, 0.001], [64671.2, 0.166], [64672.7, 0.742], [64672.8, 1.121], [64673.1, 0.028], [64673.2, 0.0], [64673.9, 0.044], [64674.1, 0.002], [64675.3, 0.443], [64675.4, 0.001], [64682.0, 0.055], [64682.1, 8.69]], "asks": [[64682.8, 0.003], [64686.6, 0.001], [64696.6, 0.078], [64698.1, 0.925], [64698.7, 0.015], [64699.0, 0.014], [64701.7, 0.067], [64702.8, 0.892], [64703.5, 0.004], [64880.7, 5.871], [65005.6, 0.155], [65329.0, 0.271], [65426.7, 14.073], [65433.6, 3.669], [65620.1, 1.065], [66088.2, 1.31]]}
{"kind": "depth", "E": 1787080682161, "U": 11315372648029, "u": 11315372654495, "recv_ms": 1787080682110, "bids": [[14182.1, 1.358], [14582.1, 2.842], [51746.0, 0.0], [58213.8, 0.003], [61447.9, 0.0], [62094.8, 0.006], [63682.1, 0.02], [63694.1, 3.6], [63700.8, 1.721], [63758.8, 2.337], [63760.6, 0.009], [63765.5, 0.002], [63767.3, 0.0], [64035.3, 0.0], [64358.7, 0.16], [64596.1, 0.002], [64603.4, 0.094], [64610.7, 0.002], [64631.1, 0.311], [64633.9, 0.001], [64640.1, 0.004], [64650.3, 0.165], [64650.4, 0.629], [64665.4, 0.926], [64665.7, 0.165], [64665.9, 0.326], [64669.1, 0.581], [64670.1, 0.15], [64670.2, 0.003], [64675.3, 0.443]], "asks": [[64682.2, 38.707], [64682.7, 2.321], [64686.6, 0.001], [64686.9, 0.062], [64687.6, 0.495], [64698.4, 1.154], [64701.7, 0.01], [64702.1, 0.061], [64702.8, 0.351], [64703.5, 0.545], [64744.1, 0.011], [64744.2, 0.001], [65005.7, 0.0], [65329.0, 0.271], [65491.4, 6.048], [65497.6, 21.911], [65498.1, 1.512], [65610.5, 0.032], [65612.3, 0.008], [65677.0, 0.013], [65682.2, 0.021]]}
{"kind": "depth", "E": 1787080682263, "U": 11315372654815, "u": 11315372664760, "recv_ms": 1787080682213, "bids": [[1000.0, 35.81], [14182.1, 0.994], [14582.1, 3.206], [51746.0, 0.0], [58213.8, 0.003], [61447.9, 0.0], [62094.8, 0.009], [63330.4, 3.942], [63744.2, 0.118], [64035.3, 0.0], [64358.6, 0.01], [64633.7, 0.012], [64649.3, 0.0], [64649.9, 0.026], [64650.3, 0.222], [64661.6, 0.118], [64662.5, 0.012], [64665.1, 0.002], [64665.4, 0.0], [64665.7, 0.163], [64666.0, 4.029], [64672.9, 0.009], [64673.1, 0.02], [64674.8, 0.318], [64675.0, 0.159], [64675.2, 0.305], [64675.3, 0.317], [64675.8, 0.054], [64676.8, 0.274], [64680.6, 0.086], [64681.1, 0.087], [64681.6, 0.004], [64682.1, 8.992]], "asks": [[64682.2, 38.677], [64683.6, 0.002], [64684.1, 0.0], [64684.2, 0.093], [64686.9, 0.092], [64687.6, 0.494], [64688.5, 0.141], [64696.6, 0.07], [64697.5, 0.199], [64698.1, 0.0], [64698.2, 0.321], [64698.4, 2.079], [64701.3, 0.225], [64702.1, 0.004], [64702.2, 0.058], [64702.3, 0.139], [64703.5, 0.545], [64760.1, 0.001], [65005.6, 0.309], [65199.7, 0.305], [65329.0, 0.271], [65603.6, 0.009], [65605.4, 0.008], [65637.9, 0.0], [65670.1, 0.025]]}
{"kind": "depth", "E": 1787080682365, "U": 11315372664983, "u": 11315372671444, "recv_ms": 1787080682313, "bids": [[1000.0, 35.81], [14182.1, 0.63], [14582.1, 3.57], [58213.8, 0.003], [62094.8, 0.006], [63682.1, 0.0], [63694.1, 3.61], [63763.6, 1.646], [63987.5, 6.08], [64035.2, 0.056], [64035.3, 0.0], [64627.7, 0.025], [64649.5, 0.002], [64650.2, 0.451], [64650.3, 0.155], [64650.4, 0.686], [64665.1, 0.928], [64665.7, 0.165], [64665.9, 0.326], [64666.0, 3.103], [64669.2, 0.074], [64671.3, 0.157], [64671.4, 0.31], [64672.8, 0.65], [64672.9, 0.001], [64673.1, 0.483], [64673.2, 0.016], [64675.4, 0.145], [64676.8, 0.004], [64681.0, 0.025], [64681.1, 0.087]], "asks": [[64682.2, 38.642], [64685.1, 0.016], [64687.9, 3.104], [64688.0, 1.01], [64688.1, 2.051], [64690.7, 0.539], [64692.1, 0.001], [64696.6, 0.07], [64697.6, 0.218], [64698.2, 0.323], [64698.4, 1.154], [64698.5, 1.45], [64701.3, 0.225], [64702.2, 0.058], [64702.3, 0.139], [64703.5, 0.545], [64744.0, 1.37], [64744.1, 0.001], [64760.1, 0.0], [65329.0, 0.273], [65426.7, 14.981], [65433.6, 2.753], [65491.4, 6.804], [65498.1, 0.756], [65613.3, 0.003], [65634.1, 4.108], [65682.2, 0.001]]}
{"kind": "depth", "E": 1787080682467, "U": 11315372671445, "u": 11315372678890, "recv_ms": 1787080682416, "bids": [[14182.1, 0.364], [14482.1, 0.084], [14582.1, 3.752], [58213.8, 0.003], [61447.9, 0.0], [62094.8, 0.009], [62172.5, 0.0], [63323.8, 0.318], [64035.3, 0.0], [64103.2, 0.016], [64110.0, 5.728], [64263.5, 0.052], [64270.2, 0.001], [64358.7, 0.17], [64424.1, 0.445], [64430.9, 0.0], [64542.6, 0.0], [64585.2, 10.004], [64592.0, 1.263], [64627.7, 0.039], [64665.9, 0.326], [64669.2, 0.553], [64671.3, 0.157], [64672.8, 0.65], [64673.1, 0.02], [64673.2, 0.0], [64673.9, 0.044], [64674.0, 0.004], [64675.2, 0.233], [64675.3, 0.173], [64675.4, 0.001], [64675.8, 0.054], [64677.7, 0.002], [64681.0, 0.002], [64681.1, 0.003], [64681.3, 0.136], [64682.1, 8.91]], "asks": [[64682.2, 38.642], [64688.3, 0.022], [64688.4, 0.023], [64694.4, 0.038], [64695.3, 0.664], [64700.5, 0.04], [64702.3, 0.004], [64779.1, 0.01], [64785.9, 0.003], [64824.9, 0.0], [64941.0, 0.004], [64947.9, 0.094], [65103.4, 1.02], [65110.2, 0.392], [65266.2, 0.017], [65273.0, 0.009], [65329.0, 0.271], [65562.3, 16.829], [65602.7, 27.404], [67220.1, 0.0]]}
{"kind": "depth", "E": 1787080682569, "U": 11315372679018, "u": 11315372684704, "recv_ms": 1787080682517, "bids": [[1000.0, 35.81], [14182.1, 0.238], [14482.1, 0.308], [14582.1, 3.654], [58213.8, 0.003], [63000.4, 0.005], [63682.1, 0.02], [63977.1, 0.702], [64035.3, 0.0], [64650.1, 0.085], [64650.2, 0.441], [64656.5, 0.311], [64662.7, 0.005], [64669.2, 0.074], [64673.1, 0.499], [64675.2, 0.233], [64675.3, 0.308], [64675.8, 0.189], [64680.5, 0.001]], "asks": [[64683.5, 0.003], [64683.7, 0.573], [64698.3, 0.62], [64702.8, 0.892], [64703.5, 0.004], [64743.6, 0.003], [64743.9, 0.01], [64744.0, 1.36], [65329.0, 0.271], [65539.7, 8.384], [65587.8, 2.284], [65670.1, 0.035], [65682.2, 0.021]]}
{"kind": "depth", "E": 1787080682671, "U": 11315372684905, "u": 11315372690452, "recv_ms": 1787080682617, "bids": [[1000.0, 35.81], [14182.1, 0.112], [14482.1, 0.546], [14582.1, 3.542], [58213.8, 0.003], [61447.9, 0.0], [61454.5, 2.459], [61454.6, 0.004], [62094.8, 0.006], [63750.9, 37.605], [64035.3, 0.0], [64164.6, 0.31], [64486.8, 15.507], [64525.6, 5.817], [64542.6, 3.663], [64627.7, 0.025], [64665.4, 0.618], [64672.8, 1.268], [64675.2, 0.377], [64675.3, 0.173], [64675.8, 0.324], [64682.1, 8.951]], "asks": [[64683.7, 0.489], [64684.0, 0.003], [64685.1, 0.016], [64692.2, 0.001], [64698.6, 0.942], [64706.0, 0.623], [64799.1, 0.003], [64824.9, 5.399], [64841.9, 10.807], [64873.5, 0.386], [64880.7, 5.932], [65329.0, 0.271], [65491.4, 7.56], [65498.3, 0.001], [65555.4, 1.341], [65562.3, 16.494]]}
{"kind": "depth", "E": 1787080682773, "U": 11315372690590, "u": 11315372696161, "recv_ms": 1787080682720, "bids": [[14182.1, 0.0], [14482.1, 0.784], [14582.1, 3.416], [51745.7, 0.0], [58213.8, 0.003], [62094.8, 0.009], [63589.2, 14.104], [63682.1, 0.0], [63758.7, 3.29], [63789.4, 1.881], [64035.3, 0.0], [64358.7, 0.325], [64489.6, 3.436], [64526.5, 1.904], [64615.7, 0.101], [64649.3, 0.057], [64650.4, 0.629], [64659.9, 0.56], [64660.6, 0.001], [64664.4, 0.001], [64664.8, 0.065], [64665.9, 0.326], [64669.1, 0.457], [64669.2, 0.198], [64675.8, 0.324], [64681.0, 0.086]], "asks": [[64685.1, 0.016], [64692.0, 0.142], [64692.2, 0.001], [64699.7, 0.002], [64700.2, 0.557], [64701.4, 0.353], [64701.7, 0.003], [64702.3, 0.011], [64704.4, 1.587], [64705.8, 0.001], [64724.1, 1.376], [64724.7, 0.0], [64770.6, 0.475], [64811.6, 0.0], [64841.8, 2.674], [64841.9, 10.807], [64842.0, 0.002], [64849.5, 0.0], [64880.7, 6.033], [64888.3, 0.001], [65329.0, 0.271], [65426.7, 16.797], [65433.6, 0.922], [65682.2, 0.001], [65788.7, 9.235], [65975.8, 0.02]]}
{"kind": "depth", "E": 1787080682875, "U": 11315372696237, "u": 11315372702374, "recv_ms": 1787080682823, "bids": [[1000.0, 35.81], [14482.1, 1.148], [14582.1, 3.052], [58213.8, 0.003], [61447.9, 0.0], [62094.8, 0.006], [63744.2, 1.215], [64035.3, 0.0], [64650.0, 4.958], [64650.1, 0.075], [64663.2, 0.042], [64665.8, 1.163], [64672.8, 0.65], [64675.2, 0.269], [64675.8, 0.054], [64679.6, 0.086], [64680.0, 0.237], [64682.1, 8.91]], "asks": [[64682.2, 38.642], [64685.1, 0.016], [64692.2, 0.001], [64700.2, 0.001], [64701.2, 0.556], [64702.8, 0.351], [64703.5, 0.545], [64704.4, 1.471], [64705.2, 0.116], [64743.8, 0.384], [64743.9, 0.0], [64873.5, 0.0], [65329.0, 0.271], [65426.7, 17.705], [65433.6, 0.006], [65525.5, 1.526], [65555.4, 1.676]]}
{"kind": "depth", "E": 1787080682977, "U": 11315372702435, "u": 11315372708849, "recv_ms": 1787080682928, "bids": [[1000.0, 35.81], [14482.1, 1.498], [14582.1, 2.702], [58213.8, 0.003], [63582.5, 5.966], [63682.1, 0.02], [63744.2, 2.155], [63796.0, 1.25], [64035.3, 0.0], [64327.6, 0.101], [64332.9, 0.493], [64665.8, 0.0], [64665.9, 0.326], [64675.2, 0.269], [64675.3, 0.173], [64675.4, 0.001], [64675.8, 0.189], [64681.1, 0.025]], "asks": [[64700.0, 1.88], [64707.3, 0.002], [64770.6, 0.375], [64880.7, 6.063], [65012.4, 4.457], [65329.0, 0.271], [65465.3, 53.199], [65587.8, 2.74], [65682.2, 0.021], [65781.8, 4.558], [66243.6, 0.668]]}
{"kind": "depth", "E": 1787080683079, "U": 11315372709113, "u": 11315372715087, "recv_ms": 1787080683027, "bids": [[14482.1, 1.862], [14582.1, 2.338], [58213.8, 0.003], [61448.0, 0.011], [62094.8, 0.009], [63682.1, 0.0], [63987.5, 5.379], [64035.3, 0.0], [64358.7, 0.315], [64545.7, 0.002], [64627.7, 0.039], [64649.3, 0.0], [64650.1, 0.132], [64670.5, 0.232], [64675.2, 0.233], [64675.8, 0.324]], "asks": [[64682.2, 38.425], [64684.8, 0.004], [64684.9, 0.002], [64699.6, 0.003], [64702.8, 0.892], [64703.5, 0.004], [65206.5, 9.029], [65329.0, 0.271], [65465.3, 52.589], [65491.4, 8.316], [65498.1, 0.0], [65682.2, 0.001], [65863.1, 1.531], [65982.7, 0.011]]}
{"kind": "depth", "E": 1787080683181, "U": 11315372715158, "u": 11315372728236, "recv_ms": 1787080683129, "bids": [[1000.0, 35.81], [14482.1, 2.212], [14582.1, 1.988], [58213.8, 0.003], [61447.9, 0.0], [61448.0, 0.013], [62094.8, 0.006], [63686.2, 18.35], [63873.6, 1.204], [63910.0, 0.635], [64035.3, 0.0], [64603.4, 0.096], [64610.7, 0.006], [64631.0, 0.033], [64631.1, 0.31], [64633.9, 0.003], [64640.2, 0.082], [64665.4, 0.0], [64669.1, 0.581], [64669.2, 0.074], [64672.7, 0.579], [64674.8, 0.319], [64675.0, 0.158], [64675.3, 0.443], [64675.8, 0.054], [64679.4, 0.317], [64680.0, 0.005], [64680.6, 0.002], [64681.0, 0.002], [64682.1, 8.69]], "asks": [[64682.2, 38.638], [64682.8, 0.004], [64683.5, 0.087], [64684.6, 0.002], [64685.3, 3.406], [64698.6, 0.324], [64706.0, 0.005], [64798.3, 0.085], [65005.6, 0.463], [65329.0, 0.271], [65458.4, 0.458], [65553.3, 2.069]]}
{"kind": "depth", "E": 1787080683283, "U": 11315372728431, "u": 11315372742676, "recv_ms": 1787080683230, "bids": [[1000.0, 35.81], [14482.1, 2.576], [14582.1, 1.624], [58213.8, 0.003], [61447.9, 0.001], [62094.8, 0.009], [63977.1, 1.404], [64035.3, 0.0], [64358.6, 0.008], [64631.0, 0.034], [64632.2, 0.504], [64636.9, 0.825], [64643.2, 3.755], [64649.9, 0.036], [64650.0, 4.948], [64665.7, 0.163], [64665.9, 0.326], [64675.3, 0.443], [64680.7, 0.008], [64682.1, 8.66]], "asks": [[64682.7, 2.321], [64683.5, 0.003], [64683.7, 0.573], [64685.2, 5.437], [64687.0, 0.087], [64694.0, 0.63], [64698.2, 0.321], [64701.6, 0.495], [64743.7, 0.015], [64743.8, 0.374], [64770.5, 0.429], [64780.5, 0.022], [65329.0, 0.271], [65458.4, 1.068], [65627.0, 39.157], [71150.5, 0.0]]}
{"kind": "depth", "E": 1787080683385, "U": 11315372742748, "u": 11315372761009, "recv_ms": 1787080683333, "bids": [[14482.1, 2.926], [14582.1, 1.274], [58213.8, 0.003], [61447.9, 0.0], [62094.8, 0.006], [63682.1, 0.02], [63711.9, 2.374], [64035.2, 0.055], [64035.3, 0.0], [64358.7, 0.325], [64542.6, 3.642], [64643.8, 0.092], [64656.2, 2.382], [64665.7, 0.165], [64665.9, 0.326], [64669.2, 0.09], [64669.3, 0.082], [64669.6, 0.03], [64670.0, 1.353], [64672.8, 0.001], [64673.1, 0.02], [64673.2, 0.0], [64673.9, 0.044], [64674.6, 0.002], [64674.8, 0.318], [64675.3, 0.173], [64675.4, 1.036], [64675.9, 0.003], [64677.1, 0.087], [64680.2, 0.005], [64680.4, 0.001], [64681.2, 0.042], [64682.0, 0.053], [64682.1, 7.778]], "asks": [[64682.2, 38.685], [64683.2, 0.084], [64684.9, 0.005], [64686.9, 0.062], [64689.0, 0.426], [64698.2, 0.323], [64712.6, 0.002], [64712.7, 0.16], [64712.9, 0.106], [64725.2, 0.157], [64725.4, 0.078], [64824.9, 5.399], [64880.7, 5.939], [65005.7, 0.002], [65199.7, 0.611], [65329.0, 0.271], [65555.4, 2.284], [65652.4, 0.297], [65682.2, 0.021], [65975.8, 0.023]]}
{"kind": "depth", "E": 1787080683487, "U": 11315372761052, "u": 11315372768613, "recv_ms": 1787080683433, "bids": [[1000.0, 35.81], [14482.1, 3.29], [14582.1, 0.91], [58213.8, 0.003], [61447.9, 0.0], [63276.8, 0.002], [63278.0, 0.001], [63388.5, 0.012], [63605.8, 1.881], [63679.5, 2.197], [63682.1, 0.0], [63791.0, 21.93], [64035.3, 0.004], [64542.6, 0.0], [64661.2, 0.0], [64668.1, 0.155], [64669.1, 0.457], [64669.2, 0.074], [64669.3, 0.005], [64669.9, 0.264], [64670.1, 0.142], [64672.8, 0.542], [64673.0, 0.777], [64673.1, 0.607], [64673.4, 0.001], [64673.8, 0.641], [64674.6, 0.001], [64675.4, 0.001], [64675.5, 0.188], [64676.7, 0.395], [64679.7, 0.011], [64679.8, 0.0], [64681.2, 0.04], [64682.1, 7.755]], "asks": [[64682.2, 38.686], [64682.8, 0.088], [64688.2, 2.32], [64689.0, 0.383], [64712.7, 0.006], [64712.9, 0.26], [64824.9, 0.0], [64888.0, 168.446], [65329.0, 0.273], [65682.2, 0.001]]}
{"kind": "depth", "E": 1787080683589, "U": 11315372768754, "u": 11315372777514, "recv_ms": 1787080683537, "bids": [[1000.0, 35.81], [14482.1, 3.654], [14582.1, 0.546], [58213.8, 0.003], [61447.9, 0.0], [62094.8, 0.009], [63744.4, 1.739], [64035.3, 0.0], [64525.6, 0.0], [64611.9, 0.314], [64613.7, 0.0], [64614.0, 33.95], [64614.1, 6.386], [64638.5, 2.337], [64639.1, 0.531], [64645.9, 0.336], [64647.7, 0.403], [64665.9, 0.326], [64669.1, 0.581], [64669.2, 0.553], [64671.1, 0.642], [64671.3, 0.003], [64671.4, 0.464], [64672.6, 0.163], [64672.8, 0.001], [64673.1, 0.028], [64673.7, 0.111], [64673.8, 0.64], [64674.7, 0.141], [64675.3, 0.443], [64679.8, 0.084], [64682.1, 7.747]], "asks": [[64682.2, 38.694], [64841.9, 0.397], [65202.7, 0.004], [65329.0, 0.271], [65331.9, 0.394], [65336.3, 0.0], [65620.1, 2.13]]}
{"kind": "depth", "E": 1787080683691, "U": 11315372777608, "u": 11315372784588, "recv_ms": 1787080683639, "bids": [[14382.1, 0.334], [14482.1, 3.752], [14582.1, 0.322], [51745.7, 0.002], [58213.8, 0.003], [61447.9, 0.0], [61632.4, 0.014], [61638.9, 0.0], [62094.8, 0.006], [63595.4, 0.627], [63711.9, 1.12], [63888.1, 2.346], [63938.3, 0.941], [64035.3, 0.0], [64358.7, 0.315], [64486.8, 0.0], [64489.6, 1.287], [64526.5, 1.112], [64665.1, 0.002], [64665.8, 0.926], [64666.5, 0.655], [64669.2, 0.074], [64671.1, 0.101], [64671.2, 0.783], [64671.4, 0.31], [64671.8, 1.921], [64671.9, 0.739], [64672.0, 0.017], [64673.7, 0.111], [64673.9, 0.044], [64674.7, 0.141], [64675.1, 0.709], [64675.3, 0.245], [64675.8, 0.324], [64679.7, 0.009], [64680.2, 0.003], [64681.2, 0.0], [64681.3, 0.176], [64681.8, 0.0], [64681.9, 0.002], [64682.0, 0.054], [64682.1, 7.861]], "asks": [[64682.8, 0.004], [64683.3, 0.003], [64684.9, 0.002], [64699.7, 0.62], [64700.9, 0.009], [64707.0, 1.106], [64798.3, 0.002], [64841.8, 0.429], [64880.7, 0.093], [65329.0, 0.271], [65432.9, 0.38], [65627.0, 38.092], [65659.3, 18.303], [65691.7, 20.974], [67712.5, 0.04], [67719.6, 0.0], [71150.5, 0.0]]}
{"kind": "depth", "E": 1787080683793, "U": 11315372784675, "u": 11315372791931, "recv_ms": 1787080683741, "bids": [[1000.0, 35.81], [14382.1, 0.572], [14482.1, 3.626], [14582.1, 0.21], [51745.7, 0.0], [58213.8, 0.003], [60865.9, 1.641], [61447.9, 0.0], [62094.8, 0.009], [63682.1, 0.02], [63737.7, 8.026], [63747.2, 1.881], [63776.6, 5.481], [64035.3, 0.0], [64486.8, 15.507], [64525.6, 5.826], [64542.6, 3.639], [64659.9, 0.003], [64661.2, 0.557], [64665.9, 0.326], [64672.7, 0.038], [64673.7, 0.11], [64673.9, 0.585], [64674.3, 0.003], [64674.6, 0.001], [64675.3, 0.173], [64675.8, 0.054], [64676.7, 0.311], [64680.2, 0.087], [64680.6, 0.086], [64682.1, 8.082]], "asks": [[64682.2, 38.648], [64683.2, 0.0], [64687.1, 0.033], [64688.0, 1.03], [64688.5, 0.017], [64699.7, 0.002], [64702.8, 0.351], [64703.5, 0.545], [64737.1, 1.513], [64811.6, 0.0], [64824.9, 5.399], [64841.9, 10.807], [64880.7, 5.946], [65329.0, 0.271], [65682.2, 0.021], [68498.4, 1.458]]}
{"kind": "depth", "E": 1787080683895, "U": 11315372792122, "u": 11315372798873, "recv_ms": 1787080683844, "bids": [[14382.1, 0.81], [14482.1, 3.514], [14582.1, 0.084], [58213.8, 0.003], [62094.8, 0.006], [63395.2, 0.065], [63682.1, 0.0], [63783.3, 48.387], [63873.6, 1.986], [63880.3, 25.027], [64035.3, 0.0], [64489.6, 3.436], [64526.5, 1.905], [64551.0, 0.924], [64551.2, 0.377], [64636.9, 0.828], [64650.1, 0.075], [64650.2, 0.498], [64651.1, 0.318], [64661.6, 0.002], [64662.4, 0.285], [64663.3, 0.351], [64665.8, 0.926], [64666.8, 0.013], [64673.1, 0.569], [64673.9, 0.044], [64674.0, 0.004], [64674.3, 0.002], [64674.7, 0.142], [64675.3, 0.173], [64680.6, 0.002], [64682.1, 8.07]], "asks": [[64682.2, 38.648], [64683.3, 0.087], [64687.8, 0.124], [64698.3, 1.545], [64698.5, 0.525], [64699.2, 0.012], [64701.2, 0.0], [64702.1, 0.56], [64702.2, 0.001], [64702.8, 0.892], [64702.9, 0.716], [64703.5, 0.004], [64704.3, 0.126], [64705.2, 0.0], [64706.1, 0.351], [64743.6, 0.003], [64813.5, 1.767], [64845.3, 0.465], [64873.5, 1.763], [65329.0, 0.271], [65490.7, 0.228], [65682.2, 0.001], [65982.7, 0.005]]}
{"kind": "depth", "E": 1787080683997, "U": 11315372798911, "u": 11315372806802, "recv_ms": 1787080683945, "bids": [[14382.1, 1.076], [14482.1, 3.332], [14582.1, 0.0], [58213.8, 0.003], [61447.9, 0.0], [63912.6, 45.503], [64035.3, 0.0], [64171.4, 9.181], [64332.9, 0.001], [64336.2, 0.492], [64358.7, 0.315], [64359.3, 0.11], [64361.2, 0.0], [64365.5, 4.91], [64588.8, 1.014], [64588.9, 0.556], [64649.8, 0.017], [64649.9, 0.026], [64665.9, 0.326], [64673.7, 0.11], [64673.8, 0.641], [64674.7, 0.141], [64675.2, 0.305], [64675.8, 0.054], [64682.1, 8.046]], "asks": [[64685.0, 0.005], [64712.9, 0.26], [64743.6, 0.013], [64743.7, 0.005], [64879.9, 1.186], [64880.0, 6.559], [65206.5, 8.723], [65329.0, 0.273], [65602.7, 25.12], [65620.1, 3.195], [65684.8, 1.833], [65699.7, 1.064]]}
{"kind": "depth", "E": 1787080684099, "U": 11315372806833, "u": 11315372812900, "recv_ms": 1787080684047, "bids": [[1000.0, 35.81], [14382.1, 1.44], [14482.1, 2.968], [58213.8, 0.003], [62094.8, 0.009], [63700.8, 1.71], [63912.6, 44.878], [64035.3, 0.0], [64171.4, 8.87], [64365.5, 4.755], [64610.1, 0.001], [64614.8, 0.009], [64627.7, 0.025], [64663.5, 2.32], [64665.9, 0.326], [64670.5, 0.232], [64673.8, 0.641], [64674.7, 0.141], [64675.8, 0.324]], "asks": [[64701.9, 0.082], [64702.9, 0.659], [64712.8, 0.176], [64712.9, 0.106], [64880.7, 6.092], [65012.4, 4.303], [65329.0, 0.271], [65677.0, 0.002]]}
{"kind": "depth", "E": 1787080684201, "U": 11315372813052, "u": 11315372819615, "recv_ms": 1787080684151, "bids": [[14382.1, 1.804], [14482.1, 2.604], [58213.8, 0.003], [62094.8, 0.006], [63682.1, 0.02], [63694.1, 3.621], [64035.3, 0.0], [64138.8, 0.074], [64358.7, 0.47], [64603.4, 0.097], [64610.7, 0.008], [64631.0, 0.035], [64633.8, 0.001], [64633.9, 0.0], [64640.1, 0.005], [64640.2, 0.08], [64664.6, 0.04], [64669.1, 0.457], [64673.8, 0.641], [64674.7, 0.141], [64675.2, 0.233], [64675.8, 0.054]], "asks": [[64685.1, 0.008], [64688.0, 1.01], [64688.3, 0.002], [64688.4, 0.0], [64688.6, 0.046], [64690.0, 1.309], [64691.0, 0.0], [64691.9, 0.011], [64693.6, 0.015], [64712.8, 0.022], [64713.1, 0.155], [64752.0, 1.108], [64754.7, 39.523], [64755.9, 2.049], [64756.9, 0.027], [64796.9, 0.088], [64880.7, 5.951], [65005.6, 0.617], [65329.0, 0.271], [65497.6, 21.683], [65597.5, 0.764], [65682.2, 0.021], [65684.8, 2.897]]}
{"kind": "depth", "E": 1787080684303, "U": 11315372819650, "u": 11315372826058, "recv_ms": 1787080684251, "bids": [[14382.1, 2.154], [14482.1, 2.254], [51746.0, 0.0], [58213.8, 0.003], [61447.9, 0.0], [61454.5, 2.457], [61454.6, 0.006], [62094.8, 0.009], [62157.4, 1.366], [63851.6, 7.054], [63880.3, 24.762], [63905.9, 7.369], [64032.7, 1.564], [64035.3, 0.0], [64164.6, 0.931], [64167.6, 0.672], [64358.7, 0.78], [64562.5, 0.01], [64563.5, 3.865], [64611.3, 1.097], [64623.8, 0.003], [64627.3, 0.007], [64627.7, 0.039], [64635.2, 1.166], [64650.0, 4.945], [64660.6, 0.558], [64661.2, 0.0], [64663.0, 0.013], [64666.5, 0.037], [64668.8, 0.312], [64675.2, 0.233], [64675.3, 0.173], [64680.2, 0.003], [64681.3, 0.136], [64682.1, 7.826]], "asks": [[64682.2, 38.641], [64685.1, 0.008], [64685.3, 3.408], [64691.9, 0.011], [64701.7, 0.006], [64753.7, 0.151], [64817.9, 3.865], [64818.0, 0.027], [64883.1, 0.0], [65199.7, 0.917], [65329.0, 0.271], [65339.6, 5.356], [65670.1, 0.046], [65975.8, 0.026], [67204.8, 1.263]]}
{"kind": "depth", "E": 1787080684405, "U": 11315372826311, "u": 11315372833714, "recv_ms": 1787080684362, "bids": [[1000.0, 35.81], [14382.1, 2.518], [14482.1, 1.89], [51746.0, 0.0], [58213.8, 0.003], [63395.2, 0.062], [63564.6, 3.38], [63682.1, 0.0], [64035.3, 0.0], [64358.6, 0.01], [64542.6, 0.0], [64585.6, 0.0], [64665.7, 0.165], [64665.9, 0.326], [64675.3, 0.173]], "asks": [[64685.1, 0.016], [64691.0, 0.9], [64691.9, 0.003], [64695.2, 1.263], [64698.2, 0.323], [64702.0, 1.858], [64824.9, 0.0], [65005.7, 0.0], [65329.0, 0.271], [65682.2, 0.001]]}
{"kind": "depth", "E": 1787080684507, "U": 11315372833840, "u": 11315372876099, "recv_ms": 1787080684456, "bids": [[1000.0, 36.01], [14382.1, 2.868], [14482.1, 1.54], [58213.8, 0.003], [61447.9, 0.0], [62094.8, 0.006], [63854.2, 0.009], [64032.7, 1.556], [64035.3, 0.008], [64542.5, 3.717], [64583.6, 0.026], [64615.7, 0.001], [64627.7, 0.025], [64643.0, 2.686], [64643.2, 3.741], [64645.8, 0.015], [64664.8, 0.003], [64665.5, 0.063], [64670.9, 0.021], [64671.0, 0.9], [64671.8, 0.002], [64671.9, 3.058], [64672.0, 2.067], [64673.8, 0.64], [64673.9, 1.281], [64674.0, 0.006], [64674.7, 0.142], [64675.3, 0.173], [64675.7, 0.242], [64677.1, 0.003], [64679.4, 0.085], [64679.9, 0.234], [64680.4, 0.085], [64680.9, 0.084], [64681.5, 0.086], [64682.1, 8.652]], "asks": [[64682.2, 38.64], [64683.3, 0.003], [64683.7, 0.489], [64684.2, 0.009], [64685.0, 0.002], [64685.1, 0.008], [64687.8, 0.084], [64688.1, 2.135], [64691.0, 0.0], [64692.1, 0.009], [64694.5, 0.432], [64701.0, 1.857], [64701.3, 0.167], [64701.8, 0.032], [64702.8, 0.351], [64703.5, 0.545], [64704.7, 10.002], [64707.0, 0.488], [64711.1, 1.047], [64760.1, 0.0], [64824.9, 5.399], [64880.7, 0.093], [64887.5, 8.733], [65326.9, 0.0], [65329.0, 0.271], [65330.1, 0.008]]}
{"kind": "depth", "E": 1787080684609, "U": 11315372876534, "u": 11315372892531, "recv_ms": 1787080684559, "bids": [[14382.1, 3.218], [14482.1, 1.19], [58213.8, 0.003], [61447.9, 0.0], [62094.8, 0.009], [63388.5, 0.015], [63682.1, 0.02], [64035.3, 0.008], [64358.7, 0.79], [64617.3, 0.027], [64617.6, 1.218], [64627.3, 0.003], [64627.7, 0.039], [64634.0, 0.001], [64634.1, 0.006], [64639.9, 0.803], [64645.9, 0.0], [64649.3, 0.0], [64650.2, 0.443], [64650.4, 0.686], [64650.8, 3.894], [64656.1, 0.006], [64661.6, 0.118], [64662.4, 0.169], [64664.9, 0.0], [64665.8, 0.0], [64665.9, 0.326], [64666.0, 4.029], [64672.1, 0.0], [64673.1, 0.569], [64673.9, 1.281], [64675.3, 0.173], [64677.4, 0.398], [64677.7, 0.591], [64681.9, 0.086], [64682.1, 8.651]], "asks": [[64682.2, 33.728], [64682.8, 0.003], [64683.7, 0.122], [64684.4, 0.056], [64684.7, 0.001], [64685.1, 0.016], [64685.2, 5.342], [64687.2, 0.013], [64687.5, 0.097], [64687.8, 0.208], [64688.5, 0.101], [64688.8, 0.368], [64690.7, 0.547], [64692.1, 0.001], [64696.6, 0.078], [64697.5, 0.199], [64698.2, 0.315], [64698.3, 0.62], [64698.5, 1.45], [64700.3, 0.223], [64701.3, 0.723], [64702.1, 0.004], [64702.3, 0.011], [64703.5, 0.545], [64704.4, 1.471], [64704.7, 0.002], [64705.4, 0.117], [64706.1, 0.235], [64707.7, 10.01], [64708.0, 0.102], [64724.1, 0.001], [64724.2, 0.028], [64746.2, 0.733], [64746.8, 0.001], [64760.1, 0.001], [64880.7, 5.653], [64887.5, 0.011], [65329.0, 0.273], [65682.2, 0.021]]}
{"kind": "depth", "E": 1787080684711, "U": 11315372892551, "u": 11315372904102, "recv_ms": 1787080684659, "bids": [[1000.0, 36.01], [14382.1, 3.582], [14482.1, 0.826], [51745.7, 0.0], [58213.8, 0.003], [61447.9, 0.0], [62094.8, 0.006], [63550.2, 3.751], [64035.3, 0.008], [64630.3, 1.412], [64675.3, 0.443], [64681.9, 0.087]], "asks": [[64682.2, 33.726], [64691.0, 0.9], [64701.8, 0.018], [64701.9, 0.098], [64702.2, 0.003], [64752.5, 39.523], [64754.7, 0.0], [64760.1, 0.0], [64779.2, 1.269], [64841.9, 0.397], [64848.6, 9.554], [64880.7, 0.093], [64887.5, 8.544], [65329.0, 0.271]]}
{"kind": "depth", "E": 1787080684813, "U": 11315372904206, "u": 11315372916698, "recv_ms": 1787080684762, "bids": [[14282.1, 0.014], [14382.1, 3.918], [14482.1, 0.476], [58213.8, 0.003], [62094.8, 0.009], [63385.9, 0.016], [63682.1, 0.0], [63709.3, 0.016], [64035.3, 0.008], [64145.5, 0.177], [64578.5, 0.011], [64585.2, 0.004], [64585.3, 0.929], [64611.9, 6.314], [64620.7, 2.253], [64627.7, 0.025], [64634.5, 3.515], [64649.0, 0.62], [64650.7, 1.164], [64665.9, 0.326], [64675.3, 0.443]], "asks": [[64683.3, 0.001], [64685.9, 0.007], [64707.3, 0.993], [64723.5, 3.502], [64724.7, 0.84], [64746.1, 6.001], [64752.0, 7.371], [64752.5, 0.0], [64756.9, 39.55], [64775.6, 0.126], [64777.8, 0.778], [64779.1, 0.002], [64782.3, 2.893], [64811.6, 0.0], [64841.9, 0.397], [64842.0, 0.634], [64848.6, 9.553], [64880.7, 0.093], [64887.4, 8.535], [64887.5, 0.011], [65329.0, 0.271], [65458.8, 8.242], [65520.8, 0.009], [65663.1, 8.372], [65682.2, 0.001], [65986.6, 0.014]]}
{"kind": "depth", "E": 1787080684915, "U": 11315372916882, "u": 11315372925465, "recv_ms": 1787080684863, "bids": [[1000.0, 36.16], [14282.1, 0.182], [14382.1, 3.932], [14482.1, 0.294], [58213.8, 0.003], [63385.9, 0.008], [63709.3, 0.008], [63711.9, 1.128], [63851.6, 7.046], [63896.8, 2.979], [64032.7, 1.548], [64035.3, 0.008], [64236.1, 0.084], [64336.2, 0.0], [64338.4, 0.493], [64358.7, 0.78], [64643.2, 2.698], [64659.1, 1.356], [64675.3, 0.443], [64681.3, 0.159]], "asks": [[64688.6, 0.003], [64688.7, 0.076], [64752.0, 1.108], [64754.7, 39.523], [64756.9, 0.027], [65329.0, 0.271], [65339.6, 5.348], [65511.3, 1.089], [65520.8, 0.001], [65653.6, 0.008], [65663.1, 8.364], [65986.6, 0.006]]}
{"kind": "depth", "E": 1787080685017, "U": 11315372925555, "u": 11315372940443, "recv_ms": 1787080684966, "bids": [[1000.0, 36.01], [14282.1, 0.42], [14382.1, 3.806], [14482.1, 0.182], [58213.8, 0.003], [61447.9, 0.0], [62094.8, 0.006], [63388.5, 0.023], [63682.1, 0.02], [63750.9, 36.508], [64035.3, 0.008], [64145.5, 0.072], [64578.5, 0.003], [64579.6, 10.0], [64579.7, 0.012], [64645.1, 0.119], [64649.3, 0.0], [64650.0, 4.931], [64650.4, 0.629], [64650.7, 1.221], [64650.8, 3.558], [64652.1, 0.111], [64656.2, 2.718], [64662.2, 0.0], [64663.6, 0.003], [64664.9, 0.0], [64665.4, 0.618], [64665.5, 0.001], [64665.9, 0.326], [64666.0, 3.103], [64666.1, 0.065], [64666.3, 0.93], [64671.1, 0.008], [64671.2, 0.166], [64671.6, 0.17], [64671.9, 3.05], [64672.0, 2.059], [64672.1, 0.0], [64672.2, 1.772], [64672.8, 0.619], [64673.0, 0.468], [64673.1, 0.028], [64674.0, 0.856], [64674.1, 0.574], [64675.1, 1.172], [64675.2, 0.305], [64675.3, 0.443], [64675.4, 0.073], [64675.8, 0.324], [64676.0, 0.033], [64677.6, 1.923], [64677.8, 0.22], [64677.9, 0.105], [64681.1, 0.064], [64681.3, 0.047], [64682.1, 8.945]], "asks": [[64682.2, 20.604], [64684.2, 0.009], [64684.4, 0.055], [64685.0, 0.01], [64685.1, 0.442], [64685.3, 3.324], [64685.6, 0.007], [64685.7, 0.0], [64685.8, 1.351], [64686.4, 0.089], [64686.5, 0.0], [64687.5, 0.002], [64687.7, 0.004], [64687.9, 2.979], [64688.1, 1.863], [64688.9, 0.092], [64689.2, 0.087], [64689.5, 0.273], [64690.0, 0.409], [64690.7, 0.547], [64690.9, 0.281], [64691.7, 0.023], [64692.0, 0.15], [64692.2, 0.31], [64693.8, 0.017], [64695.1, 0.618], [64695.2, 1.103], [64695.3, 0.123], [64695.4, 0.002], [64696.1, 0.328], [64696.2, 0.206], [64696.6, 0.667], [64696.8, 0.105], [64697.5, 0.199], [64698.0, 0.176], [64698.1, 0.0], [64698.3, 0.157], [64698.5, 0.525], [64698.6, 0.317], [64698.8, 1.719], [64699.5, 0.007], [64701.1, 0.634], [64701.7, 0.004], [64701.9, 0.041], [64702.0, 0.004], [64702.3, 0.011], [64702.5, 0.064], [64702.8, 0.351], [64703.5, 0.545], [64706.0, 0.005], [64707.7, 0.012], [64708.5, 0.329], [64708.8, 1.187], [64712.0, 11.245], [64716.5, 3.433], [64719.7, 0.001], [64724.3, 0.114], [64727.6, 0.025], [64730.6, 0.486], [64737.3, 0.214], [64752.1, 0.024], [64752.5, 39.523], [64754.7, 0.0], [64777.8, 2.159], [64778.4, 10.027], [64841.9, 0.397], [64848.5, 7.743], [64848.6, 1.811], [64880.7, 0.093], [64887.4, 8.589], [65329.0, 0.273], [65451.9, 1.184], [65682.2, 0.021], [65977.0, 0.092]]}
{"kind": "depth", "E": 1787080685119, "U": 11315372940467, "u": 11315372951068, "recv_ms": 1787080685068, "bids": [[1000.0, 36.21], [14282.1, 0.658], [14382.1, 3.694], [14482.1, 0.056], [51746.0, 0.0], [58213.8, 0.003], [61447.9, 0.0], [61448.0, 0.015], [62094.8, 0.009], [63385.9, 0.0], [63709.3, 0.0], [63851.6, 7.038], [64035.3, 0.008], [64078.0, 10.794], [64138.8, 0.0], [64145.5, 0.037], [64551.0, 0.05], [64551.1, 0.529], [64620.7, 2.153], [64623.8, 0.0], [64629.6, 0.0], [64629.9, 0.0], [64630.2, 1.667], [64630.6, 0.007], [64630.9, 0.001], [64636.8, 1.717], [64636.9, 0.825], [64640.1, 0.006], [64640.6, 0.037], [64642.8, 0.035], [64642.9, 0.001], [64643.0, 2.616], [64643.1, 4.222], [64643.3, 4.189], [64643.4, 0.311], [64643.8, 0.022], [64646.6, 0.018], [64647.1, 0.311], [64647.5, 0.004], [64647.8, 0.001], [64648.1, 0.023], [64648.4, 0.0], [64648.8, 0.212], [64655.2, 0.0], [64655.3, 0.019], [64655.9, 0.47], [64659.7, 0.032], [64668.8, 0.188], [64669.1, 0.581], [64670.5, 0.232], [64671.1, 0.001], [64671.2, 0.32], [64671.9, 2.509], [64672.1, 0.0], [64672.2, 0.008], [64672.9, 0.542], [64673.1, 0.02], [64674.0, 0.315], [64674.1, 0.009], [64674.7, 0.071], [64674.8, 0.248], [64674.9, 0.427], [64675.0, 0.088], [64675.1, 1.073], [64675.2, 0.033], [64675.3, 0.003], [64675.4, 0.041], [64675.5, 1.099], [64675.7, 0.172], [64675.8, 0.054], [64675.9, 0.003], [64676.0, 0.001], [64676.3, 0.001], [64676.4, 0.033], [64676.6, 0.0], [64677.3, 0.002], [64677.8, 0.085], [64677.9, 0.005], [64678.1, 0.002], [64679.5, 0.0], [64682.1, 8.954]], "asks": [[64682.2, 20.621], [64682.6, 0.746], [64684.4, 0.015], [64685.9, 0.003], [64686.1, 0.086], [64687.5, 0.006], [64688.3, 0.003], [64689.0, 0.381], [64690.0, 0.408], [64692.0, 1.05], [64695.1, 0.077], [64695.3, 0.085], [64695.6, 1.478], [64695.8, 0.574], [64695.9, 0.001], [64696.0, 0.582], [64696.2, 0.161], [64696.6, 0.154], [64696.8, 0.0], [64697.0, 0.918], [64697.1, 1.226], [64697.2, 0.146], [64697.3, 0.027], [64697.4, 0.06], [64697.5, 0.002], [64697.6, 0.029], [64697.7, 0.625], [64697.8, 0.002], [64698.3, 0.628], [64708.6, 2.905], [64713.2, 0.23], [64713.5, 0.316], [64713.7, 0.045], [64713.8, 0.004], [64714.1, 0.062], [64714.5, 0.547], [64714.8, 3.539], [64715.3, 0.315], [64716.5, 3.328], [64716.6, 0.003], [64716.7, 0.001], [64716.8, 0.111], [64716.9, 0.182], [64717.0, 0.0], [64717.1, 0.0], [64717.2, 0.001], [64717.3, 1.258], [64717.4, 0.062], [64731.1, 0.004], [64731.4, 0.0], [64731.6, 0.057], [64731.7, 0.021], [64732.0, 0.023], [64732.4, 0.001], [64743.6, 0.01], [64759.9, 0.755], [64796.9, 0.002], [64880.7, 5.656], [64887.4, 0.0], [65329.0, 0.263], [65473.3, 18.7], [65508.0, 0.544], [65510.1, 0.001], [65643.7, 5.475], [65650.3, 0.47], [65652.4, 0.289], [65973.7, 0.0]]}
{"kind": "depth", "E": 1787080685221, "U": 11315372951176, "u": 11315372958965, "recv_ms": 1787080685171, "bids": [[1000.0, 36.21], [14282.1, 0.966], [14382.1, 3.442], [14482.1, 0.0], [51746.0, 0.0], [58213.8, 0.003], [62094.8, 0.006], [63386.4, 0.0], [63391.5, 0.003], [63682.1, 0.0], [63694.0, 8.394], [63709.8, 0.0], [63852.1, 0.0], [64033.2, 0.623], [64035.3, 0.008], [64145.5, 0.0], [64358.7, 0.78], [64494.8, 0.023], [64603.4, 0.098], [64610.7, 0.01], [64631.0, 0.037], [64633.9, 0.002], [64640.1, 0.007], [64641.0, 0.048], [64665.8, 0.926], [64666.3, 0.004], [64672.1, 0.0], [64674.1, 0.48], [64674.2, 0.077], [64674.8, 0.249], [64674.9, 0.497], [64675.0, 0.088], [64675.1, 1.142], [64675.2, 0.86], [64675.3, 0.019], [64675.4, 0.101], [64675.5, 0.018], [64675.6, 0.001], [64676.7, 0.343], [64679.9, 0.002], [64680.3, 0.236], [64680.8, 0.002], [64681.1, 0.042]], "asks": [[64685.4, 0.087], [64687.0, 0.397], [64688.2, 2.319], [64695.2, 1.106], [64695.5, 0.05], [64696.9, 0.274], [64697.1, 1.303], [64697.4, 0.144], [64711.5, 6.032], [64712.0, 11.247], [64713.4, 0.043], [64716.5, 3.448], [64716.7, 0.078], [64717.0, 0.084], [64731.3, 0.211], [65329.0, 0.263], [65397.9, 7.242], [65682.2, 0.001], [65975.8, 0.021]]}
{"kind": "depth", "E": 1787080685323, "U": 11315372959021, "u": 11315372966805, "recv_ms": 1787080685270, "bids": [[1000.0, 36.21], [14282.1, 1.316], [14382.1, 3.092], [58213.8, 0.003], [61447.9, 0.0], [61454.6, 0.004], [62094.8, 0.009], [63388.5, 0.02], [63395.2, 0.004], [63467.1, 0.16], [63539.0, 0.019], [63610.8, 2.395], [63682.7, 0.0], [63744.2, 3.252], [63754.6, 9.127], [63826.5, 0.783], [63898.4, 0.014], [63970.2, 0.0], [64035.3, 0.008], [64042.1, 0.0], [64232.3, 0.012], [64630.3, 1.398], [64632.9, 0.028], [64640.3, 0.042], [64641.3, 0.034], [64645.8, 0.001], [64650.2, 0.5], [64650.7, 1.164], [64653.1, 0.341], [64655.2, 1.973], [64656.2, 2.382], [64662.4, 5.169], [64665.3, 2.297], [64671.2, 0.166], [64672.1, 1.12], [64672.8, 0.001], [64672.9, 0.001], [64673.0, 0.468], [64673.1, 0.02], [64673.2, 0.541], [64674.1, 0.01], [64674.2, 0.0], [64674.8, 0.319], [64675.0, 0.088], [64675.1, 0.749], [64675.2, 0.033], [64675.3, 0.003], [64675.4, 0.171], [64675.5, 0.018], [64675.6, 0.271], [64676.1, 0.032], [64677.1, 0.035], [64681.3, 0.005], [64682.0, 0.076], [64682.1, 8.985]], "asks": [[64684.6, 0.007], [64688.3, 0.002], [64691.5, 0.01], [64695.2, 1.141], [64696.2, 0.203], [64696.8, 0.084], [64697.2, 0.237], [64697.4, 0.221], [64708.2, 10.03], [64712.0, 1.247], [64713.1, 0.19], [64714.0, 0.058], [64716.4, 0.085], [64716.8, 0.202], [64717.0, 0.161], [64731.0, 0.101], [64731.9, 0.044], [65329.0, 0.263], [65335.9, 6.7], [65407.8, 0.02], [65479.6, 0.017], [65551.5, 0.0], [65623.4, 0.155], [65695.3, 0.002], [65767.1, 0.003], [65839.0, 0.012], [65910.9, 0.0], [65982.8, 2.31]]}
{"kind": "depth", "E": 1787080685425, "U": 11315372966900, "u": 11315372974279, "recv_ms": 1787080685373, "bids": [[14282.1, 1.666], [14382.1, 2.742], [58213.8, 0.003], [61447.9, 0.0], [63679.5, 3.295], [63682.1, 0.02], [64035.3, 0.008], [64067.6, 1.4], [64273.8, 0.003], [64358.6, 0.008], [64542.5, 0.079], [64622.8, 0.404], [64641.6, 1.095], [64665.7, 0.165], [64671.5, 0.208], [64672.2, 0.549], [64673.2, 0.0], [64675.1, 0.992], [64675.2, 0.303], [64675.3, 0.147], [64675.5, 0.118], [64675.6, 0.001], [64675.7, 0.272], [64675.8, 0.054], [64677.4, 0.43]], "asks": [[64682.2, 20.62], [64683.3, 0.006], [64684.6, 0.015], [64686.6, 0.003], [64690.1, 0.004], [64691.0, 1.8], [64691.5, 0.002], [64692.0, 0.15], [64694.9, 0.128], [64696.5, 0.624], [64696.7, 2.55], [64698.2, 0.315], [64701.6, 0.566], [64712.7, 0.044], [64714.4, 0.603], [64716.3, 0.313], [64730.6, 0.524], [64824.9, 0.0], [65329.0, 0.263], [65387.2, 0.688], [65458.4, 2.594], [65633.0, 1.299], [65682.2, 0.021], [65844.2, 0.0]]}
{"kind": "depth", "E": 1787080685527, "U": 11315372974406, "u": 11315372995639, "recv_ms": 1787080685478, "bids": [[1000.0, 36.21], [14282.1, 2.03], [14382.1, 2.378], [51746.0, 0.0], [58213.8, 0.003], [61447.9, 0.0], [62094.8, 0.006], [63711.3, 1.588], [64035.3, 0.008], [64236.1, 0.1], [64358.7, 0.79], [64525.5, 6.207], [64525.6, 0.0], [64526.5, 1.112], [64542.5, 3.898], [64623.1, 0.344], [64655.3, 0.089], [64655.4, 0.09], [64665.4, 0.0], [64671.2, 0.32], [64671.5, 0.208], [64675.0, 0.158], [64675.2, 0.133], [64675.3, 0.203], [64675.4, 0.306], [64675.6, 0.171], [64675.8, 0.259], [64681.9, 0.003], [64682.1, 9.046]], "asks": [[64682.2, 20.681], [64684.9, 0.086], [64689.2, 0.003], [64696.4, 0.106], [64696.6, 0.253], [64696.7, 2.68], [64696.9, 0.404], [64697.0, 1.178], [64697.3, 0.118], [64698.3, 0.62], [64714.8, 3.679], [64716.0, 0.11], [64716.2, 0.122], [64716.3, 0.443], [64716.5, 3.578], [64716.6, 0.123], [64716.9, 0.273], [64824.9, 5.399], [64841.9, 10.807], [64848.5, 0.001], [64880.7, 7.119], [65005.7, 0.002], [65329.0, 0.263], [65473.3, 17.174], [65607.6, 4.091], [71150.5, 0.0]]}
{"kind": "depth", "E": 1787080685629, "U": 11315372995778, "u": 11315373006435, "recv_ms": 1787080685576, "bids": [[1000.0, 36.21], [14282.1, 2.38], [14382.1, 2.028], [58213.8, 0.003], [62094.8, 0.009], [63682.1, 0.0], [63873.6, 2.337], [63969.8, 0.001], [64035.3, 0.008], [64171.4, 8.559], [64542.5, 3.898], [64622.4, 1.225], [64623.4, 0.85], [64655.5, 0.089], [64655.8, 0.128], [64675.4, 0.315], [64675.8, 0.394], [64681.9, 0.002], [64682.0, 0.16], [64682.1, 9.108]], "asks": [[64682.2, 20.742], [64684.9, 0.002], [64795.5, 2.703], [64824.9, 5.399], [64880.7, 7.12], [65012.4, 4.149], [65329.0, 0.263], [65458.4, 4.12], [65465.3, 52.131], [65682.2, 0.001]]}
{"kind": "depth", "E": 1787080685731, "U": 11315373006847, "u": 11315373015019, "recv_ms": 1787080685679, "bids": [[14282.1, 2.744], [14382.1, 1.664], [51745.7, 0.0], [51746.0, 0.0], [58213.8, 0.003], [61447.9, 0.0], [62094.8, 0.006], [63776.6, 5.669], [64035.3, 0.008], [64164.6, 1.242], [64623.7, 0.056], [64655.2, 2.043], [64655.5, 0.159], [64655.8, 0.198], [64658.9, 1.999], [64664.7, 0.614], [64675.8, 0.394], [64682.1, 9.096]], "asks": [[64689.9, 0.324], [64692.2, 0.326], [64811.6, 0.0], [65199.7, 1.223], [65329.0, 0.263], [65833.5, 0.758]]}
{"kind": "depth", "E": 1787080685833, "U": 11315373015068, "u": 11315373021999, "recv_ms": 1787080685779, "bids": [[1000.0, 36.21], [14282.1, 3.094], [14382.1, 1.314], [58213.8, 0.003], [61454.6, 0.002], [63682.1, 0.02], [64035.3, 0.01], [64358.7, 0.78], [64525.5, 0.013], [64526.5, 1.112], [64542.5, 0.079], [64582.2, 2.551], [64655.9, 0.57], [64657.8, 0.102], [64668.0, 0.125], [64675.2, 0.205], [64675.8, 0.394], [64678.9, 0.001]], "asks": [[64682.2, 20.802], [64708.1, 3.104], [64752.5, 0.0], [64754.7, 39.649], [64755.9, 2.049], [64756.9, 0.027], [64824.9, 0.0], [64841.8, 0.429], [64841.9, 0.397], [64842.0, 0.002], [65329.0, 0.263], [65538.0, 3.382], [65587.8, 5.024], [65682.2, 0.021]]}
{"kind": "depth", "E": 1787080685935, "U": 11315373022012, "u": 11315373028689, "recv_ms": 1787080685883, "bids": [[1000.0, 36.21], [14282.1, 3.444], [14382.1, 0.964], [58213.8, 0.003], [61447.9, 0.0], [62094.8, 0.009], [63452.3, 0.001], [64035.3, 0.008], [64164.6, 1.553], [64338.4, 0.001], [64339.6, 0.492], [64525.5, 6.206], [64542.5, 3.897], [64630.3, 1.412], [64655.4, 0.16], [64655.6, 0.109], [64655.7, 0.27], [64656.0, 1.063], [64656.2, 2.452], [64657.4, 0.115], [64662.4, 0.169], [64665.3, 1.383], [64671.2, 0.166], [64675.2, 0.133], [64675.8, 0.124], [64682.1, 9.067]], "asks": [[64682.2, 20.803], [64691.0, 0.9], [64692.0, 1.05], [64754.7, 39.667], [64824.9, 5.399], [64841.9, 10.807], [65005.6, 0.771], [65329.0, 0.263], [65365.6, 0.095], [65449.6, 3.739], [65458.4, 4.578], [65490.7, 0.456], [65975.8, 0.024]]}
{"kind": "depth", "E": 1787080686037, "U": 11315373028853, "u": 11315373035665, "recv_ms": 1787080685985, "bids": [[14182.1, 0.042], [14282.1, 3.724], [14382.1, 0.642], [58213.8, 0.001], [61447.9, 0.0], [62094.8, 0.006], [63589.2, 13.712], [63592.8, 9.419], [63682.1, 0.0], [64035.3, 0.008], [64664.7, 1.232], [64670.5, 0.237], [64671.0, 1.054], [64672.1, 1.738], [64675.8, 0.124], [64682.1, 9.057]], "asks": [[64682.2, 20.789], [64687.2, 0.015], [64697.9, 0.734], [64701.6, 0.495], [64705.3, 0.733], [64754.7, 39.649], [65329.0, 0.263], [65682.2, 0.001]]}
{"kind": "depth", "E": 1787080686139, "U": 11315373035686, "u": 11315373041850, "recv_ms": 1787080686088, "bids": [[1000.0, 36.21], [14182.1, 0.238], [14282.1, 3.696], [14382.1, 0.474], [58213.8, 0.003], [61447.9, 0.0], [61448.0, 0.013], [61448.1, 0.002], [62094.8, 0.009], [63582.5, 6.75], [63750.9, 35.411], [63873.6, 2.602], [63912.6, 44.409], [64035.3, 0.008], [64358.7, 0.79], [64563.5, 0.0], [64564.9, 3.866], [64610.7, 0.011], [64611.3, 1.097], [64633.9, 0.003], [64640.1, 0.008], [64645.8, 0.015], [64664.7, 0.614], [64670.5, 0.232], [64671.0, 0.9], [64671.1, 0.001], [64672.1, 1.12], [64673.4, 0.31], [64674.0, 0.006], [64675.2, 0.133], [64675.8, 0.124], [64681.6, 0.145], [64682.1, 8.957]], "asks": [[64682.2, 20.805], [64682.6, 0.752], [64689.6, 0.184], [64691.0, 1.8], [64691.1, 0.005], [64692.0, 0.15], [64753.7, 0.151], [64817.9, 3.865], [65329.0, 0.263], [65439.0, 0.608], [65523.1, 1.126], [65627.0, 37.027], [65975.8, 0.021]]}
{"kind": "depth", "E": 1787080686241, "U": 11315373042003, "u": 11315373051210, "recv_ms": 1787080686188, "bids": [[1000.0, 36.21], [14182.1, 0.476], [14282.1, 3.57], [14382.1, 0.362], [58213.8, 0.003], [62094.8, 0.006], [63000.3, 0.0], [63452.5, 0.335], [63582.5, 7.142], [63682.1, 0.02], [64035.3, 0.008], [64671.2, 0.166], [64674.8, 0.318], [64675.0, 0.159], [64675.2, 0.205], [64675.5, 0.262], [64675.6, 0.315], [64675.8, 0.124], [64677.8, 0.355]], "asks": [[64880.7, 7.129], [65206.5, 8.417], [65329.0, 0.263], [65329.3, 0.535], [65682.2, 0.021]]}
{"kind": "depth", "E": 1787080686343, "U": 11315373051269, "u": 11315373061458, "recv_ms": 1787080686292, "bids": [[14182.1, 0.714], [14282.1, 3.458], [14382.1, 0.236], [51746.0, 0.0], [58213.8, 0.003], [61447.9, 0.0], [61448.0, 0.015], [63744.2, 4.349], [64035.3, 0.016], [64623.8, 0.003], [64631.0, 0.038], [64665.9, 0.327], [64668.8, 0.422], [64669.1, 0.584], [64670.4, 0.24], [64671.0, 0.9], [64671.1, 0.001], [64672.0, 2.292], [64673.6, 0.546], [64675.2, 0.133], [64675.4, 0.171], [64675.5, 0.118], [64675.6, 0.171], [64677.8, 0.085], [64681.6, 0.004], [64681.7, 0.001], [64681.9, 0.086], [64682.0, 0.076], [64682.1, 9.026]], "asks": [[64682.2, 19.816], [64684.9, 0.002], [64697.9, 0.116], [64705.3, 0.115], [64754.7, 39.667], [64792.2, 0.01], [64880.7, 0.093], [64886.8, 9.765], [65329.0, 0.263], [65330.1, 0.016], [65449.6, 3.205], [65620.1, 4.261], [65627.0, 35.962], [65975.8, 0.024]]}
{"kind": "depth", "E": 1787080686445, "U": 11315373061684, "u": 11315373072473, "recv_ms": 1787080686391, "bids": [[1000.0, 36.21], [14182.1, 1.05], [14282.1, 3.15], [14382.1, 0.208], [58213.8, 0.003], [61447.9, 0.0], [61448.0, 0.013], [61448.1, 0.004], [62094.8, 0.009], [63387.6, 0.0], [63390.7, 0.003], [63682.1, 0.0], [63905.9, 7.838], [64035.3, 0.016], [64358.7, 0.78], [64623.8, 0.0], [64636.8, 1.714], [64649.3, 0.057], [64650.2, 0.443], [64664.9, 0.926], [64665.7, 0.165], [64665.8, 0.0], [64671.0, 0.9], [64672.2, 0.008], [64673.7, 0.651], [64675.2, 0.133], [64675.3, 0.203], [64675.4, 0.315], [64675.5, 0.262], [64675.8, 0.124], [64677.7, 0.591], [64677.8, 0.355], [64681.9, 0.087], [64682.1, 9.106]], "asks": [[64682.2, 19.798], [64697.5, 0.002], [64698.2, 0.315], [64698.4, 2.079], [64698.8, 0.794], [64701.2, 0.0], [64702.1, 0.061], [64702.3, 0.011], [64702.5, 0.007], [64703.5, 0.545], [64759.9, 0.752], [64792.2, 0.007], [64841.9, 0.397], [64847.9, 7.734], [64880.6, 0.013], [64886.7, 10.066], [64886.8, 0.014], [65199.7, 1.529], [65329.0, 0.263], [65397.9, 6.556], [65620.1, 5.326], [65682.2, 0.001], [65883.4, 0.0], [65982.7, 0.002], [66047.5, 3.78]]}
{"kind": "depth", "E": 1787080686547, "U": 11315373072563, "u": 11315373078836, "recv_ms": 1787080686493, "bids": [[1000.0, 36.21], [14182.1, 1.4], [14282.1, 2.8], [51746.0, 0.0], [58213.8, 0.003], [61447.9, 0.0], [62094.8, 0.006], [62968.0, 1.001], [63395.1, 2.609], [63467.0, 0.058], [63538.9, 0.063], [63610.8, 2.453], [63682.6, 0.058], [63754.5, 0.058], [63826.4, 0.058], [63898.3, 0.059], [63970.1, 0.292], [64035.3, 0.016], [64042.0, 2.227], [64358.6, 0.01], [64542.5, 0.079], [64661.9, 5.61], [64670.9, 0.175], [64671.0, 0.9], [64672.2, 0.549], [64673.7, 0.11], [64675.2, 0.133], [64675.4, 0.171], [64675.5, 0.118], [64675.6, 0.315], [64677.8, 0.085], [64679.9, 0.234], [64680.3, 0.004], [64682.1, 9.126]], "asks": [[64682.2, 19.797], [64824.9, 0.0], [65005.7, 0.0], [65307.3, 7.274], [65329.0, 0.263], [65329.7, 1.591], [65331.9, 0.015], [65335.8, 0.394], [65387.2, 1.374], [65407.7, 0.287], [65479.5, 0.058], [65551.4, 0.058], [65623.3, 0.972], [65695.2, 0.058], [65767.0, 1.207], [65838.9, 0.286], [65910.8, 0.059], [65982.7, 0.06]]}
{"kind": "depth", "E": 1787080686649, "U": 11315373078982, "u": 11315373084671, "recv_ms": 1787080686597, "bids": [[14182.1, 1.764], [14282.1, 2.436], [51746.0, 0.0], [58213.8, 0.003], [61447.9, 0.0], [62094.8, 0.009], [62744.5, 0.003], [63682.1, 0.02], [63806.3, 0.0], [63854.2, 0.017], [63920.4, 13.826], [64035.3, 0.024], [64358.7, 0.78], [64525.5, 0.013], [64630.3, 1.398], [64645.8, 0.001], [64670.9, 0.175], [64675.2, 0.205], [64675.3, 0.275], [64675.4, 0.315], [64675.5, 0.154], [64675.6, 0.171], [64675.8, 0.124], [64677.7, 0.591], [64677.8, 0.22]], "asks": [[64682.2, 19.689], [64687.9, 2.981], [64847.9, 0.0], [65329.0, 0.263], [65330.1, 0.024], [65439.0, 1.142], [65511.3, 1.097], [65682.2, 0.021], [65891.8, 0.711]]}
{"kind": "depth", "E": 1787080686751, "U": 11315373084742, "u": 11315373091020, "recv_ms": 1787080686699, "bids": [[1000.0, 36.21], [14182.1, 2.114], [14282.1, 2.086], [51745.7, 0.0], [58213.8, 0.003], [62094.8, 0.006], [62741.6, 2.46], [63387.8, 0.321], [63388.5, 0.028], [63711.9, 1.136], [64035.3, 0.024], [64486.8, 0.0], [64489.6, 1.287], [64670.7, 0.326], [64670.9, 0.021], [64675.2, 0.169], [64675.3, 0.203], [64675.5, 0.19], [64677.7, 0.726], [64677.8, 0.085], [64682.1, 9.162]], "asks": [[64811.6, 0.0], [64886.7, 0.0], [65296.7, 0.848], [65329.0, 0.263], [65397.9, 5.87], [65461.4, 2.289], [65653.6, 0.016], [65977.0, 0.1], [66040.5, 0.304]]}
{"kind": "depth", "E": 1787080686853, "U": 11315373091095, "u": 11315373096991, "recv_ms": 1787080686800, "bids": [[1000.0, 36.21], [14182.1, 2.464], [14282.1, 1.736], [58213.8, 0.003], [61448.0, 0.017], [63682.1, 0.0], [63711.9, 1.144], [63854.2, 0.033], [63905.9, 9.401], [63945.0, 7.97], [64035.3, 0.032], [64616.6, 2.745], [64620.7, 2.253], [64623.5, 0.029], [64623.6, 0.001], [64624.2, 0.005], [64634.1, 0.002], [64636.8, 1.717], [64662.3, 2.326], [64675.2, 0.133], [64677.7, 0.861]], "asks": [[64708.5, 0.326], [64723.4, 1.538], [64724.7, 0.0], [64749.5, 0.011], [64750.7, 3.607], [64752.0, 7.394], [64752.1, 0.015], [64753.7, 0.15], [64754.7, 39.649], [64755.0, 0.1], [64842.0, 0.634], [65329.0, 0.263], [65330.1, 0.032], [65511.3, 1.113], [65517.4, 0.0], [65653.6, 0.024], [65682.2, 0.001], [65779.5, 0.026]]}
{"kind": "depth", "E": 1787080686955, "U": 11315373097136, "u": 11315373101967, "recv_ms": 1787080686903, "bids": [[14182.1, 2.828], [14282.1, 1.372], [58213.8, 0.003], [61447.9, 0.0], [62094.8, 0.009], [63388.5, 0.044], [63711.9, 1.152], [63796.0, 1.875], [64035.3, 0.032], [64339.6, 0.0], [64340.4, 0.494], [64358.7, 0.79], [64486.7, 8.23], [64489.6, 3.263], [64525.5, 4.609], [64526.5, 1.722], [64542.4, 3.906], [64627.0, 3.684], [64675.5, 0.118], [64676.8, 0.004], [64677.7, 0.591], [64682.1, 9.141]], "asks": [[64689.0, 0.227], [64824.9, 5.399], [64841.8, 10.839], [64880.6, 10.824], [65329.0, 0.263], [65653.6, 0.032], [65975.8, 0.021], [65977.0, 0.116]]}
{"kind": "depth", "E": 1787080687057, "U": 11315373102155, "u": 11315373110434, "recv_ms": 1787080687005, "bids": [[1000.0, 36.21], [14182.1, 3.178], [14282.1, 1.022], [58213.8, 0.003], [61447.9, 0.0], [62094.8, 0.006], [63682.1, 0.02], [63750.9, 34.315], [63905.1, 0.015], [63908.9, 4.218], [63920.4, 12.263], [63938.3, 1.878], [63945.0, 7.034], [63975.1, 2.166], [64486.7, 15.509], [64525.5, 5.528], [64542.4, 4.11], [64627.0, 3.68], [64634.1, 0.006], [64670.5, 0.232], [64675.2, 0.133], [64675.8, 0.124], [64681.6, 0.144], [64681.9, 0.003], [64682.1, 9.0]], "asks": [[64682.2, 19.689], [64684.9, 0.086], [64689.1, 0.156], [64824.9, 0.0], [64830.9, 4.381], [64841.8, 10.839], [64847.8, 0.212], [64880.6, 9.251], [64886.7, 0.0], [65329.0, 0.263], [65387.2, 2.06], [65458.4, 5.341], [65682.2, 0.021], [66306.2, 1.129]]}
{"kind": "depth", "E": 1787080687261, "U": 11315373118277, "u": 11315373125311, "recv_ms": 1787080687209, "bids": [[14182.1, 3.766], [14282.1, 0.364], [14582.1, 0.07], [51746.0, 0.0], [58213.8, 0.003], [61447.9, 0.0], [63522.3, 0.786], [63682.1, 0.0], [63744.2, 5.445], [63905.9, 11.745], [63912.6, 44.19], [63938.3, 2.814], [64035.3, 0.032], [64228.6, 0.0], [64358.7, 0.79], [64486.7, 5.563], [64489.6, 1.287], [64525.5, 2.914], [64542.4, 2.842], [64616.6, 0.004], [64661.6, 0.002], [64662.3, 2.442], [64672.1, 0.58], [64672.3, 0.546], [64675.8, 0.394], [64681.4, 0.086], [64681.5, 0.002], [64682.1, 8.985]], "asks": [[64684.5, 0.085], [64686.0, 0.006], [64686.4, 0.086], [64687.9, 2.984], [64688.9, 0.008], [64695.5, 0.127], [64696.1, 0.251], [64701.8, 0.025], [64702.3, 0.004], [64750.7, 0.014], [64785.4, 0.027], [64824.9, 0.0], [64830.7, 2.983], [64830.9, 0.0], [64841.8, 0.429], [64847.7, 4.802], [64880.6, 0.013], [64886.5, 9.183], [65329.0, 0.263], [65682.2, 0.001], [66065.0, 0.0]]}
{"kind": "depth", "E": 1787080687363, "U": 11315373125398, "u": 11315373130794, "recv_ms": 1787080687310, "bids": [[1000.0, 36.21], [14182.1, 3.668], [14282.1, 0.238], [14582.1, 0.294], [51746.0, 0.0], [58213.8, 0.003], [62094.8, 0.006], [62735.2, 0.004], [63592.8, 8.634], [63945.0, 6.097], [64035.3, 0.032], [64556.0, 0.135], [64675.2, 0.205], [64675.8, 0.394]], "asks": [[64824.9, 4.988], [64830.7, 0.001], [64841.8, 10.839], [64847.7, 0.0], [64880.5, 7.158], [64880.6, 15.426], [64880.9, 0.001], [64886.5, 0.966], [65329.0, 0.263], [65975.8, 0.024], [66299.3, 0.007]]}
{"kind": "depth", "E": 1787080687465, "U": 11315373131063, "u": 11315373149442, "recv_ms": 1787080687414, "bids": [[1000.0, 36.21], [14182.1, 3.556], [14282.1, 0.112], [14582.1, 0.532], [58213.8, 0.003], [61447.9, 0.0], [62094.8, 0.009], [63388.5, 0.041], [63390.7, 0.0], [63682.1, 0.02], [63969.9, 0.874], [64035.3, 0.032], [64486.7, 12.228], [64525.5, 4.965], [64542.4, 3.873], [64569.0, 13.695], [64569.4, 3.606], [64576.0, 0.007], [64578.4, 1.749], [64586.8, 0.009], [64587.7, 0.016], [64589.2, 0.005], [64611.0, 0.406], [64611.9, 39.439], [64612.2, 0.291], [64614.0, 1.291], [64614.9, 0.062], [64616.6, 2.759], [64617.7, 2.545], [64624.3, 0.029], [64627.7, 0.039], [64630.3, 1.412], [64641.2, 0.075], [64643.2, 2.712], [64644.8, 1.357], [64645.8, 0.015], [64648.4, 0.049], [64648.5, 0.397], [64649.9, 0.076], [64650.1, 0.005], [64651.0, 0.0], [64651.3, 0.199], [64653.1, 0.005], [64653.8, 0.009], [64656.4, 0.347], [64656.5, 0.002], [64657.0, 0.016], [64659.8, 0.005], [64659.9, 0.56], [64660.6, 0.001], [64661.0, 0.032], [64661.4, 0.116], [64661.5, 0.003], [64661.9, 0.61], [64662.2, 0.0], [64662.3, 0.177], [64662.4, 0.169], [64662.9, 0.143], [64663.4, 1.883], [64663.6, 0.001], [64665.7, 0.163], [64666.1, 0.003], [64666.3, 0.006], [64666.5, 0.048], [64668.1, 0.135], [64669.0, 0.001], [64669.1, 0.46], [64670.4, 0.238], [64671.9, 0.19], [64672.0, 1.223], [64672.1, 0.0], [64672.3, 0.006], [64672.4, 2.02], [64672.5, 0.015], [64672.7, 0.031], [64672.9, 0.002], [64673.1, 2.238], [64673.2, 1.012], [64673.4, 0.001], [64673.8, 0.629], [64673.9, 0.044], [64674.0, 0.006], [64674.1, 0.002], [64674.8, 0.318], [64674.9, 0.569], [64675.0, 0.158], [64675.2, 0.133], [64675.4, 0.171], [64675.5, 0.118], [64675.6, 0.255], [64675.7, 0.269], [64675.8, 0.394], [64676.0, 0.085], [64676.1, 0.094], [64676.3, 0.085], [64676.7, 0.427], [64676.8, 0.005], [64677.1, 0.119], [64677.4, 0.514], [64677.6, 0.004], [64677.7, 0.001], [64677.8, 0.085], [64678.6, 0.002], [64678.9, 0.085], [64679.1, 0.001], [64679.2, 0.0], [64679.4, 0.001], [64679.8, 0.0], [64679.9, 0.002], [64680.4, 0.001], [64680.6, 0.02], [64680.9, 0.0], [64681.0, 0.039], [64681.1, 0.0], [64681.2, 0.141], [64681.4, 0.002], [64681.6, 0.003], [64681.8, 0.001], [64681.9, 0.0], [64682.0, 0.055], [64682.1, 8.034]], "asks": [[64682.2, 19.802], [64682.4, 0.085], [64682.6, 0.876], [64682.9, 0.086], [64683.4, 0.084], [64684.0, 0.087], [64684.2, 0.017], [64684.6, 0.022], [64685.0, 0.005], [64685.6, 0.0], [64686.6, 0.004], [64687.4, 0.004], [64687.8, 0.124], [64688.1, 1.779], [64688.5, 0.019], [64690.6, 1.24], [64690.8, 2.42], [64690.9, 0.186], [64691.0, 1.803], [64696.6, 0.716], [64697.4, 1.146], [64698.2, 0.315], [64698.3, 0.157], [64698.4, 1.154], [64699.4, 0.001], [64700.2, 0.557], [64701.0, 2.781], [64701.3, 0.167], [64701.6, 0.566], [64701.9, 0.041], [64702.3, 10.545], [64703.4, 0.311], [64703.5, 0.004], [64704.3, 0.242], [64705.4, 0.001], [64706.3, 0.219], [64708.1, 0.836], [64708.2, 0.03], [64709.6, 0.001], [64716.5, 3.638], [64717.5, 2.557], [64721.1, 0.712], [64724.3, 0.054], [64727.6, 0.0], [64728.6, 0.022], [64737.3, 0.004], [64750.6, 3.592], [64752.9, 0.029], [64756.9, 0.001], [64796.8, 4.371], [64798.2, 14.414], [64800.1, 1.564], [64802.6, 0.0], [64824.9, 0.0], [64830.7, 4.06], [64841.8, 10.839], [64847.7, 0.0], [64880.5, 0.001], [64880.6, 0.013], [64886.5, 14.155], [65008.6, 0.0], [65329.0, 0.263], [65329.1, 0.101], [65607.6, 3.864], [65682.2, 0.021], [65975.8, 0.021], [66629.5, 0.0]]}
{"kind": "depth", "E": 1787080687567, "U": 11315373149547, "u": 11315373166510, "recv_ms": 1787080687515, "bids": [[14182.1, 3.43], [14282.1, 0.0], [14582.1, 0.77], [58213.8, 0.003], [61447.9, 0.0], [62094.8, 0.006], [64035.3, 0.032], [64236.1, 0.016], [64358.6, 0.008], [64358.7, 0.78], [64611.9, 6.314], [64614.0, 34.662], [64620.7, 2.153], [64641.2, 0.005], [64643.2, 2.712], [64644.6, 0.003], [64648.4, 0.07], [64651.3, 0.199], [64655.4, 0.469], [64655.6, 0.158], [64656.4, 0.038], [64656.7, 0.306], [64659.3, 0.56], [64659.7, 0.028], [64659.9, 0.003], [64660.0, 0.164], [64660.4, 0.017], [64661.0, 0.025], [64661.2, 0.116], [64661.4, 0.0], [64662.0, 1.041], [64662.4, 0.045], [64662.9, 0.141], [64665.1, 0.009], [64665.9, 0.777], [64666.2, 0.695], [64668.8, 0.422], [64668.9, 0.09], [64669.6, 0.023], [64671.1, 0.001], [64672.1, 0.85], [64672.2, 0.008], [64672.4, 0.0], [64672.5, 0.008], [64672.7, 0.013], [64672.9, 0.001], [64673.0, 0.469], [64673.1, 1.929], [64673.2, 0.0], [64673.5, 0.128], [64673.9, 0.515], [64674.9, 0.497], [64675.4, 0.171], [64675.8, 0.124], [64675.9, 0.315], [64676.0, 0.085], [64676.1, 2.446], [64676.2, 0.306], [64676.4, 0.095], [64676.7, 0.117], [64677.1, 0.351], [64677.5, 0.002], [64678.2, 0.085], [64678.9, 0.001], [64680.5, 0.023], [64680.7, 0.149], [64681.2, 0.0], [64681.4, 0.014], [64682.0, 0.053], [64682.1, 5.082]], "asks": [[64682.2, 19.799], [64682.4, 0.086], [64683.7, 0.129], [64684.6, 0.015], [64684.7, 0.001], [64684.8, 0.007], [64685.1, 0.99], [64685.5, 0.38], [64686.0, 0.003], [64690.5, 0.312], [64690.7, 0.642], [64690.8, 2.325], [64692.2, 0.017], [64693.9, 0.08], [64695.2, 1.134], [64695.5, 0.05], [64696.0, 0.041], [64699.1, 1.352], [64699.9, 0.113], [64700.2, 0.557], [64700.7, 0.008], [64700.9, 0.068], [64701.5, 10.067], [64701.8, 0.016], [64702.1, 0.004], [64702.3, 0.547], [64702.5, 0.005], [64706.3, 0.17], [64716.5, 3.578], [64723.4, 1.598], [65005.7, 0.001], [65329.0, 0.263], [65643.7, 4.183], [66046.5, 0.159]]}
{"kind": "depth", "E": 1787080687669, "U": 11315373166709, "u": 11315373186174, "recv_ms": 1787080687618, "bids": [[1000.0, 36.21], [14182.1, 3.08], [14582.1, 1.12], [58213.8, 0.003], [58213.9, 0.002], [61447.9, 0.0], [62094.8, 0.009], [63071.7, 1.989], [63682.1, 0.0], [63938.3, 3.751], [64035.3, 0.032], [64164.6, 1.553], [64619.1, 0.312], [64636.8, 1.717], [64637.8, 0.001], [64640.6, 0.373], [64648.5, 0.061], [64648.6, 0.521], [64649.3, 0.0], [64660.0, 0.244], [64660.6, 0.117], [64661.2, 0.0], [64662.1, 0.142], [64664.3, 0.986], [64664.9, 0.0], [64667.2, 0.214], [64667.5, 0.171], [64668.3, 0.322], [64668.9, 0.083], [64670.0, 2.253], [64670.1, 0.142], [64670.2, 2.322], [64671.0, 0.0], [64671.9, 0.015], [64672.0, 1.224], [64672.1, 0.85], [64673.0, 0.468], [64673.2, 0.0], [64673.3, 0.476], [64673.6, 0.236], [64673.9, 0.052], [64674.0, 0.006], [64675.5, 0.118], [64675.8, 0.217], [64675.9, 0.006], [64676.0, 0.085], [64676.1, 2.369], [64676.2, 0.004], [64676.3, 0.085], [64676.4, 0.033], [64677.5, 0.002], [64677.6, 1.923], [64677.7, 0.079], [64677.9, 0.003], [64678.6, 0.002], [64679.7, 0.009], [64679.8, 0.141], [64680.0, 0.027], [64680.1, 0.033], [64680.5, 0.001], [64680.6, 0.001], [64680.7, 0.008], [64681.4, 0.002], [64682.1, 2.731]], "asks": [[64682.2, 35.733], [64682.8, 0.004], [64684.1, 0.0], [64684.2, 0.001], [64685.0, 0.021], [64685.1, 0.442], [64685.5, 0.475], [64685.6, 0.0], [64686.8, 0.275], [64687.1, 0.003], [64687.7, 0.046], [64688.0, 1.01], [64688.7, 0.034], [64689.5, 0.001], [64690.0, 1.324], [64690.5, 0.312], [64690.7, 0.547], [64691.0, 0.003], [64692.0, 1.05], [64692.2, 0.001], [64693.9, 0.628], [64695.1, 0.085], [64696.6, 0.708], [64697.2, 0.244], [64697.7, 10.627], [64698.4, 1.152], [64699.1, 1.303], [64699.5, 0.0], [64701.0, 1.862], [64701.5, 0.608], [64702.3, 0.006], [64705.8, 0.061], [64705.9, 0.113], [64713.1, 0.19], [64714.6, 0.003], [64723.4, 1.538], [64749.5, 0.002], [64841.8, 0.429], [64847.6, 7.543], [64886.4, 12.6], [64886.5, 0.966], [65005.7, 0.002], [65329.0, 0.263], [65682.2, 0.001], [65788.7, 8.947]]}
{"kind": "depth", "E": 1787080687771, "U": 11315373186477, "u": 11315373200518, "recv_ms": 1787080687719, "bids": [[1000.0, 36.21], [14182.1, 2.716], [14582.1, 1.484], [51745.7, 0.0], [51746.0, 0.0], [58213.8, 0.003], [58213.9, 0.0], [61447.9, 0.0], [63065.0, 0.027], [63682.1, 0.02], [64035.3, 0.032], [64642.0, 0.159], [64649.4, 0.081], [64660.0, 0.164], [64661.8, 1.323], [64669.5, 0.084], [64672.0, 1.223], [64673.0, 0.469], [64673.9, 0.052], [64675.3, 0.287], [64675.8, 0.201], [64676.1, 1.821], [64676.2, 0.02], [64676.8, 0.004], [64677.7, 0.611], [64677.8, 0.085], [64677.9, 0.019], [64678.2, 0.001], [64680.0, 0.005], [64680.1, 0.014], [64682.1, 2.205]], "asks": [[64682.2, 36.953], [64683.3, 0.008], [64685.4, 0.182], [64685.5, 0.38], [64687.4, 0.023], [64687.5, 0.028], [64698.7, 0.064], [64701.5, 0.067], [64701.6, 5.568], [64702.3, 0.545], [64705.2, 0.07], [64705.9, 0.064], [64707.5, 1.024], [64711.5, 6.034], [64712.0, 1.245], [64712.9, 0.036], [64746.0, 2.204], [64746.2, 0.001], [64754.7, 0.0], [64756.9, 39.646], [64775.6, 0.026], [64811.6, 0.0], [64841.7, 2.33], [64841.8, 10.839], [64842.0, 0.002], [64847.6, 0.0], [64880.6, 9.076], [64886.4, 0.007], [65329.0, 0.263], [65397.9, 5.413], [65633.0, 2.591], [65682.2, 0.021], [65975.8, 0.018]]}
{"kind": "depth", "E": 1787080687873, "U": 11315373200827, "u": 11315373214704, "recv_ms": 1787080687821, "bids": [[14182.1, 2.366], [14582.1, 1.834], [51746.0, 0.0], [58213.8, 0.003], [61447.9, 0.0], [62094.8, 0.006], [63388.5, 0.044], [63686.2, 17.252], [63750.9, 33.218], [63880.3, 24.263], [64035.3, 0.032], [64358.7, 0.78], [64555.9, 0.142], [64637.1, 0.124], [64648.6, 0.464], [64649.2, 0.07], [64649.9, 0.076], [64660.6, 0.001], [64661.4, 0.116], [64662.2, 0.0], [64664.3, 0.06], [64664.9, 0.926], [64665.7, 0.163], [64666.5, 0.037], [64670.2, 2.333], [64672.1, 0.85], [64673.2, 0.0], [64673.9, 0.052], [64676.2, 0.02], [64677.8, 0.086], [64677.9, 0.019], [64679.2, 0.023], [64679.3, 0.021], [64682.1, 2.205]], "asks": [[64682.2, 36.969], [64683.3, 0.009], [64689.0, 0.211], [64690.3, 0.003], [64691.0, 0.903], [64697.4, 0.221], [64698.2, 1.24], [64700.9, 0.011], [64701.6, 5.816], [64701.8, 0.073], [64702.3, 0.004], [64702.8, 0.892], [64704.3, 0.126], [64705.1, 0.617], [64705.8, 0.001], [64712.7, 0.104], [64727.9, 0.001], [64752.0, 1.108], [64841.7, 0.021], [64841.8, 10.839], [64847.5, 0.003], [64880.6, 9.27], [64886.3, 0.0], [65329.0, 0.263], [65465.3, 51.369]]}
{"kind": "depth", "E": 1787080688077, "U": 11315373227283, "u": 11315373239040, "recv_ms": 1787080688023, "bids": [[1000.0, 35.81], [14182.1, 1.638], [14582.1, 2.562], [34000.0, 1.146], [51746.0, 0.004], [58213.8, 0.003], [61447.9, 0.0], [62094.8, 0.006], [63682.1, 0.0], [64035.3, 0.032], [64171.4, 7.625], [64649.2, 0.013], [64650.8, 3.615], [64664.9, 0.0], [64666.5, 0.963], [64670.5, 0.232], [64672.1, 0.309], [64673.2, 0.541], [64677.7, 0.549], [64677.8, 0.372], [64677.9, 0.065]], "asks": [[64682.2, 36.986], [64682.6, 0.889], [64689.6, 0.171], [64692.5, 1.378], [64694.1, 2.89], [64698.2, 0.315], [64698.9, 2.312], [64699.1, 0.005], [64700.2, 0.001], [64701.0, 1.693], [64701.7, 0.56], [64701.8, 0.016], [64702.6, 0.54], [64702.8, 0.351], [64703.5, 0.545], [64754.7, 39.837], [64756.9, 0.001], [65206.5, 7.192], [65329.0, 0.263], [65602.7, 22.836], [65682.2, 0.001]]}
{"kind": "depth", "E": 1787080688179, "U": 11315373239188, "u": 11315373250081, "recv_ms": 1787080688126, "bids": [[14182.1, 1.288], [14582.1, 2.912], [51746.0, 0.0], [58213.8, 0.003], [63912.4, 0.976], [64035.3, 0.032], [64358.7, 0.935], [64610.7, 0.0], [64631.0, 0.039], [64631.1, 0.31], [64633.8, 0.003], [64633.9, 0.0], [64634.5, 3.501], [64640.0, 0.301], [64640.1, 0.003], [64649.9, 0.083], [64650.8, 3.558], [64664.6, 0.658], [64665.6, 0.934], [64666.5, 0.037], [64671.5, 0.047], [64672.0, 1.841], [64677.8, 0.372], [64682.1, 2.282]], "asks": [[64687.7, 0.047], [64695.1, 0.077], [64696.0, 0.049], [64697.8, 0.62], [64705.1, 1.235], [65005.6, 0.925], [65199.7, 1.835], [65329.0, 0.263], [65458.4, 6.103], [65591.9, 5.083]]}
{"kind": "depth", "E": 1787080688281, "U": 11315373250170, "u": 11315373259473, "recv_ms": 1787080688228, "bids": [[1000.0, 35.81], [14182.1, 0.938], [14582.1, 3.262], [51746.0, 0.0], [58213.8, 0.003], [61447.9, 0.0], [62094.8, 0.009], [63464.5, 1.755], [63653.9, 4.831], [63682.1, 0.02], [63873.6, 3.384], [64035.3, 0.032], [64167.6, 0.361], [64171.4, 7.314], [64365.5, 4.445], [64542.4, 4.512], [64611.9, 6.314], [64614.0, 34.622], [64677.8, 0.102], [64682.1, 2.202]], "asks": [[64686.5, 0.022], [64687.5, 0.006], [64687.7, 0.003], [64701.6, 5.692], [64824.8, 5.775], [64830.7, 0.001], [64880.6, 9.719], [65329.0, 0.263], [65587.8, 7.308], [65682.2, 0.021], [65724.0, 9.402], [67200.0, 21.917]]}
{"kind": "depth", "E": 1787080688383, "U": 11315373259680, "u": 11315373276993, "recv_ms": 1787080688337, "bids": [[1000.0, 35.81], [14182.1, 0.574], [14582.1, 3.626], [58213.8, 0.003], [61447.9, 0.0], [62094.8, 0.006], [64035.3, 0.032], [64164.6, 2.487], [64586.6, 0.011], [64586.8, 0.004], [64594.7, 0.032], [64607.6, 0.088], [64608.6, 0.039], [64611.0, 0.38], [64611.9, 6.314], [64612.2, 0.291], [64614.0, 34.594], [64627.0, 3.653], [64627.7, 0.025], [64640.6, 0.037], [64643.2, 2.698], [64645.0, 0.782], [64649.3, 0.0], [64649.9, 0.026], [64651.2, 1.229], [64652.9, 0.038], [64656.2, 2.455], [64659.3, 0.003], [64661.4, 0.0], [64662.2, 0.557], [64663.9, 0.117], [64664.6, 0.04], [64664.9, 0.0], [64665.6, 0.008], [64666.6, 0.973], [64669.4, 0.006], [64670.0, 1.353], [64670.3, 0.596], [64671.0, 0.9], [64671.1, 0.001], [64672.0, 1.223], [64672.1, 0.309], [64672.2, 0.032], [64672.3, 0.004], [64673.0, 0.468], [64673.1, 0.02], [64673.2, 0.0], [64673.3, 0.013], [64673.4, 0.311], [64673.9, 0.585], [64674.9, 0.497], [64675.0, 0.159], [64675.1, 0.749], [64675.2, 0.133], [64675.3, 0.203], [64675.4, 0.171], [64675.5, 0.428], [64675.8, 0.124], [64675.9, 0.004], [64676.2, 0.004], [64677.5, 0.004], [64677.7, 0.008], [64677.8, 0.643], [64679.0, 0.001], [64679.7, 0.009], [64679.8, 0.0], [64681.0, 0.002], [64681.1, 0.181], [64682.0, 0.053], [64682.1, 8.404]], "asks": [[64682.2, 37.508], [64682.4, 0.086], [64682.9, 0.086], [64683.7, 0.122], [64684.4, 0.022], [64684.8, 0.004], [64685.0, 0.021], [64685.2, 5.437], [64685.3, 3.327], [64685.4, 0.087], [64686.5, 0.0], [64686.8, 0.003], [64686.9, 0.082], [64687.4, 0.004], [64687.8, 0.396], [64693.9, 0.003], [64694.9, 0.753], [64695.1, 0.081], [64696.6, 0.245], [64697.2, 0.237], [64697.5, 0.002], [64697.7, 0.627], [64697.8, 0.002], [64698.2, 0.778], [64698.3, 0.164], [64698.9, 1.387], [64699.0, 0.014], [64699.7, 0.927], [64700.7, 0.001], [64700.8, 0.015], [64701.0, 1.688], [64701.2, 0.0], [64701.5, 10.067], [64701.6, 5.692], [64701.7, 0.004], [64702.3, 0.094], [64702.6, 0.483], [64702.8, 0.358], [64703.1, 0.628], [64703.5, 0.004], [64703.8, 0.057], [64704.3, 0.128], [64705.0, 0.686], [64705.1, 0.501], [64706.9, 0.117], [64713.0, 0.015], [64717.3, 1.257], [64717.6, 0.002], [64721.4, 0.061], [64734.0, 0.004], [64740.4, 0.861], [64745.5, 0.005], [64746.1, 6.003], [64746.9, 0.031], [64750.5, 0.026], [64752.9, 0.003], [64753.3, 2.347], [64759.8, 2.426], [64760.1, 0.0], [64762.9, 1.006], [64769.3, 0.0], [64775.9, 0.989], [64782.0, 0.781], [64841.8, 10.839], [64847.3, 0.001], [64880.6, 7.44], [64886.1, 0.031], [65199.7, 2.754], [65329.0, 0.263], [65458.4, 8.618], [65607.6, 3.637], [65975.8, 0.024]]}
{"kind": "depth", "E": 1787080688485, "U": 11315373277324, "u": 11315373285993, "recv_ms": 1787080688435, "bids": [[14182.1, 0.336], [14482.1, 0.112], [14582.1, 3.752], [58213.8, 0.003], [61447.9, 0.0], [62094.8, 0.009], [63472.5, 0.754], [63647.2, 1.884], [63682.1, 0.0], [63912.6, 43.41], [63945.0, 5.16], [64035.3, 0.032], [64164.6, 2.798], [64171.4, 7.003], [64358.7, 1.09], [64617.7, 2.335], [64624.9, 0.21], [64665.7, 0.163], [64671.1, 0.025], [64672.2, 0.008], [64675.6, 0.525], [64675.7, 0.272], [64677.7, 0.557], [64677.8, 0.086], [64677.9, 0.065], [64678.0, 0.086], [64679.0, 0.085], [64679.7, 0.009], [64681.1, 0.04], [64681.2, 0.141], [64682.1, 8.487]], "asks": [[64682.2, 37.522], [64685.0, 0.018], [64687.1, 0.025], [64696.6, 0.237], [64698.1, 0.008], [64698.2, 0.778], [64700.9, 0.009], [64701.7, 0.006], [64703.5, 0.545], [64705.0, 0.145], [64712.9, 0.003], [64721.1, 0.502], [64727.7, 0.235], [65329.0, 0.263], [65329.1, 0.1], [65581.3, 0.914], [65682.2, 0.001], [65717.1, 1.096], [65975.8, 0.021], [66631.7, 0.001]]}
{"kind": "depth", "E": 1787080688587, "U": 11315373286033, "u": 11315373292394, "recv_ms": 1787080688535, "bids": [[1000.0, 35.81], [14182.1, 0.21], [14482.1, 0.35], [14582.1, 3.64], [58213.8, 0.003], [61447.9, 0.0], [62094.8, 0.006], [63388.5, 0.047], [64035.3, 0.032], [64358.6, 0.009], [64562.4, 4.003], [64564.9, 0.001], [64611.2, 0.059], [64611.3, 1.051], [64644.8, 1.237], [64650.6, 0.06], [64651.2, 1.172], [64652.0, 1.864], [64660.4, 0.01], [64661.2, 0.557], [64662.0, 1.048], [64662.2, 0.0], [64662.6, 0.381], [64663.9, 0.001], [64666.0, 4.029], [64666.6, 0.047], [64668.3, 0.315], [64669.3, 0.012], [64670.3, 0.056], [64671.1, 0.573], [64672.1, 0.548], [64672.6, 0.472], [64675.6, 0.255], [64677.5, 0.002], [64677.7, 0.001], [64677.8, 0.085], [64679.0, 0.001], [64679.7, 0.15], [64681.2, 0.0], [64682.0, 0.055]], "asks": [[64682.2, 37.526], [64685.1, 0.445], [64685.3, 3.324], [64690.5, 0.003], [64691.0, 1.212], [64693.9, 0.08], [64694.9, 0.676], [64696.6, 0.708], [64698.1, 0.0], [64698.2, 0.315], [64698.5, 1.45], [64699.7, 0.002], [64701.4, 0.909], [64702.2, 0.01], [64702.3, 0.151], [64702.8, 0.351], [64703.1, 0.072], [64703.8, 0.0], [64705.4, 0.117], [64706.4, 0.04], [64706.9, 0.001], [64753.6, 1.424], [64753.7, 0.104], [64817.9, 3.865], [65005.7, 0.0], [65329.0, 0.263], [65500.4, 0.763], [66635.4, 2.173]]}
{"kind": "depth", "E": 1787080688689, "U": 11315373292521, "u": 11315373301977, "recv_ms": 1787080688637, "bids": [[1000.0, 35.81], [14182.1, 0.098], [14482.1, 0.588], [14582.1, 3.514], [58213.8, 0.003], [61447.9, 0.0], [63682.1, 0.02], [63744.2, 7.482], [63905.9, 12.525], [63938.3, 4.688], [64035.3, 0.032], [64164.6, 3.109], [64358.6, 0.01], [64627.7, 0.039], [64649.9, 0.083], [64650.6, 0.003], [64660.6, 0.558], [64661.2, 0.0], [64662.1, 0.258], [64662.6, 0.265], [64665.4, 0.926], [64666.0, 3.103], [64670.3, 0.056], [64671.1, 0.001], [64672.1, 0.008], [64672.2, 0.549], [64672.3, 0.004], [64672.4, 0.463], [64673.9, 0.044], [64675.3, 0.287], [64675.7, 0.269], [64676.2, 0.097], [64677.5, 0.004], [64677.7, 0.016], [64677.8, 0.626], [64677.9, 0.066], [64678.4, 0.008], [64682.0, 0.053], [64682.1, 6.233]], "asks": [[64682.2, 37.529], [64702.3, 0.692], [64703.5, 0.004], [64880.6, 7.537], [65329.0, 0.263], [65682.2, 0.021]]}
{"kind": "depth", "E": 1787080688791, "U": 11315373302519, "u": 11315373309636, "recv_ms": 1787080688739, "bids": [[14182.1, 0.0], [14482.1, 0.84], [14582.1, 3.36], [51745.7, 0.0], [58213.8, 0.003], [62094.8, 0.009], [63388.5, 0.044], [63961.5, 0.781], [64035.3, 0.032], [64358.7, 1.09], [64578.9, 0.002], [64627.7, 0.025], [64640.5, 3.209], [64643.2, 2.712], [64646.7, 0.002], [64649.0, 0.677], [64649.9, 0.026], [64659.3, 0.56], [64660.6, 0.001], [64661.2, 0.116], [64662.1, 0.142], [64664.7, 1.54], [64665.4, 0.0], [64670.3, 0.064], [64670.7, 0.172], [64671.0, 0.903], [64672.1, 0.0], [64674.9, 0.496]], "asks": [[64695.1, 1.782], [64695.6, 0.369], [64697.1, 1.303], [64698.1, 0.925], [64698.5, 0.525], [64699.9, 0.113], [64700.9, 0.565], [64701.4, 0.353], [64713.1, 0.036], [64811.6, 0.0], [65329.0, 0.263]]}
{"kind": "depth", "E": 1787080688893, "U": 11315373309779, "u": 11315373315734, "recv_ms": 1787080688840, "bids": [[1000.0, 35.81], [14482.1, 1.204], [14582.1, 2.996], [58213.8, 0.003], [61447.9, 0.0], [62094.8, 0.006], [63508.7, 0.793], [63653.9, 3.733], [63682.1, 0.0], [63750.9, 31.024], [63770.3, 3.518], [63905.2, 0.876], [63905.9, 12.744], [63945.0, 4.223], [64035.3, 0.032], [64489.6, 2.947], [64542.4, 1.21], [64656.0, 1.577], [64682.1, 6.28]], "asks": [[64682.2, 37.529], [64701.0, 3.385], [64752.0, 1.108], [64754.7, 0.0], [64756.9, 39.838], [64824.8, 0.376], [64841.7, 2.33], [64880.9, 4.839], [65329.0, 0.263], [65473.3, 15.648], [65587.8, 7.491], [65682.2, 0.001], [65724.0, 8.338]]}
{"kind": "depth", "E": 1787080688995, "U": 11315373315876, "u": 11315373321924, "recv_ms": 1787080688942, "bids": [[1000.0, 35.81], [14482.1, 1.568], [14582.1, 2.632], [58213.8, 0.003], [61447.9, 0.0], [61448.0, 0.019], [61602.0, 0.007], [62094.8, 0.009], [64035.3, 0.032], [64180.0, 1.264], [64340.9, 0.013], [64341.2, 0.492], [64486.6, 6.402], [64486.7, 0.002], [64525.4, 2.82], [64525.5, 0.013], [64526.5, 1.112], [64542.4, 2.838], [64615.7, 0.101], [64616.6, 0.004], [64636.8, 1.717], [64677.1, 0.119], [64677.9, 0.298]], "asks": [[64682.2, 37.533], [64689.0, 0.207], [64727.5, 0.003], [64750.6, 0.001], [64770.6, 0.475], [64824.8, 5.642], [64841.7, 0.021], [64841.8, 10.839], [65134.2, 0.0], [65329.0, 0.263], [65497.6, 21.425], [65591.9, 4.201], [65750.4, 4.101]]}
{"kind": "depth", "E": 1787080689097, "U": 11315373322037, "u": 11315373329722, "recv_ms": 1787080689044, "bids": [[14482.1, 1.918], [14582.1, 2.282], [58213.8, 0.003], [62094.8, 0.006], [63582.5, 7.927], [63647.2, 2.982], [63682.1, 0.02], [63694.1, 3.613], [63744.2, 8.579], [63758.8, 2.329], [63760.6, 0.001], [63912.6, 41.535], [64035.3, 0.032], [64223.3, 0.477], [64358.7, 1.09], [64486.6, 14.906], [64507.3, 3.208], [64511.2, 0.001], [64525.4, 5.977], [64526.5, 1.928], [64542.4, 4.418], [64562.4, 0.138], [64562.9, 6.184], [64575.1, 0.004], [64575.5, 3.413], [64575.6, 1.494], [64576.7, 0.0], [64611.2, 0.059], [64616.5, 3.038], [64640.1, 0.004], [64643.2, 2.698], [64663.6, 0.063], [64664.7, 0.614], [64666.0, 4.029], [64670.3, 0.157], [64670.4, 0.392], [64670.5, 0.232], [64671.1, 0.464], [64672.2, 0.008], [64672.3, 0.545], [64672.4, 0.0], [64672.7, 0.013], [64673.9, 0.044], [64674.9, 0.58], [64676.2, 0.004], [64677.5, 0.002], [64677.7, 0.557], [64677.8, 0.002], [64677.9, 0.235], [64678.0, 0.086], [64679.7, 0.15], [64681.1, 0.0], [64681.2, 0.0], [64682.0, 0.055], [64682.1, 8.46]], "asks": [[64682.2, 37.527], [64684.9, 0.086], [64686.9, 0.062], [64693.9, 0.003], [64694.8, 0.19], [64696.6, 0.245], [64698.0, 0.639], [64702.3, 0.151], [64703.5, 0.545], [64713.1, 0.19], [64750.3, 3.624], [64753.6, 1.424], [64792.0, 3.635], [64792.6, 0.0], [64817.9, 3.865], [64880.6, 8.307], [65329.0, 0.263], [65603.6, 0.001], [65605.4, 0.0], [65670.1, 0.038], [65682.2, 0.021]]}
{"kind": "depth", "E": 1787080689199, "U": 11315373329928, "u": 11315373337164, "recv_ms": 1787080689147, "bids": [[1000.0, 35.81], [14482.1, 2.282], [14582.1, 1.918], [51746.0, 0.0], [58213.8, 0.001], [61447.9, 0.0], [63694.1, 3.621], [63744.2, 9.676], [63758.9, 0.008], [63760.6, 0.009], [63919.1, 7.501], [63938.3, 5.625], [64035.3, 0.032], [64229.3, 0.088], [64610.7, 0.001], [64631.0, 0.04], [64633.9, 0.002], [64664.8, 0.621], [64670.3, 0.056], [64672.1, 0.093], [64672.2, 0.626], [64672.4, 0.008], [64675.6, 0.525], [64676.7, 0.12], [64677.7, 0.565], [64677.8, 0.002], [64678.0, 0.078], [64678.1, 0.002], [64678.4, 0.092]], "asks": [[64682.2, 37.518], [64690.2, 0.001], [64698.0, 1.257], [64701.9, 0.025], [64703.7, 0.145], [64705.4, 0.735], [64811.6, 0.0], [65329.0, 0.263], [65600.7, 0.455], [65717.1, 2.16], [65739.8, 4.102]]}
{"kind": "depth", "E": 1787080689301, "U": 11315373337169, "u": 11315373343445, "recv_ms": 1787080689251, "bids": [[14482.1, 2.632], [14582.1, 1.568], [58213.8, 0.003], [62094.8, 0.009], [63682.1, 0.0], [63793.4, 8.639], [63845.2, 0.0], [63880.3, 23.998], [63905.9, 14.619], [63912.6, 41.066], [64542.4, 3.906], [64663.6, 0.001], [64664.1, 0.073], [64676.7, 0.117], [64680.8, 0.0], [64682.1, 8.456]], "asks": [[64713.1, 0.036], [64824.8, 5.775], [65005.6, 1.079], [65117.7, 0.012], [65329.0, 0.263], [65581.3, 1.796], [65603.7, 0.008], [65605.5, 0.008], [65670.2, 0.009], [65682.2, 0.001], [65781.8, 4.846]]}
{"kind": "depth", "E": 1787080689403, "U": 11315373343628, "u": 11315373349814, "recv_ms": 1787080689350, "bids": [[14482.1, 2.996], [14582.1, 1.204], [58213.8, 0.003], [61447.9, 0.0], [62094.8, 0.006], [63621.5, 6.517], [63629.3, 0.002], [63783.0, 2.225], [63912.4, 1.914], [64035.3, 0.032], [64358.7, 1.1], [64542.4, 4.418], [64612.2, 0.282], [64645.0, 0.446], [64648.9, 1.281], [64664.8, 0.003], [64672.1, 0.093], [64672.2, 0.008], [64675.6, 0.525], [64677.7, 0.024], [64677.8, 0.543], [64678.4, 0.008], [64679.8, 0.023], [64679.9, 0.021], [64682.1, 8.411]], "asks": [[64682.2, 37.628], [64682.6, 0.765], [64687.0, 0.397], [64687.1, 0.003], [64689.0, 0.202], [64698.0, 0.639], [64701.0, 1.688], [64701.5, 0.067], [64704.9, 10.105], [64705.4, 0.117], [64713.2, 0.384], [64824.8, 5.775], [64880.6, 11.018], [65329.0, 0.263], [65358.8, 0.0], [65587.8, 9.775], [65602.7, 20.552], [65630.7, 10.35]]}
{"kind": "depth", "E": 1787080689505, "U": 11315373350144, "u": 11315373355560, "recv_ms": 1787080689454, "bids": [[1000.0, 35.81], [14482.1, 3.36], [14582.1, 0.84], [51746.0, 0.0], [58213.8, 0.003], [61447.9, 0.0], [61448.1, 0.002], [62094.8, 0.009], [62101.4, 0.005], [63614.8, 1.112], [63682.1, 0.02], [63905.9, 15.088], [64035.3, 0.032], [64665.7, 0.163], [64672.1, 0.101], [64672.4, 0.0], [64675.6, 0.525], [64677.4, 0.694], [64677.7, 0.565], [64677.8, 0.002], [64682.1, 8.408]], "asks": [[64682.2, 37.639], [64687.3, 0.019], [64687.4, 0.026], [64693.9, 0.011], [64695.5, 0.042], [64698.2, 0.315], [64704.3, 0.126], [64704.5, 2.361], [64725.1, 0.183], [64725.2, 0.001], [64754.7, 39.837], [64756.9, 0.001], [65329.0, 0.263], [65620.1, 5.44], [65627.0, 34.897], [65682.2, 0.021], [65975.8, 0.024]]}
{"kind": "depth", "E": 1787080689607, "U": 11315373355643, "u": 11315373360572, "recv_ms": 1787080689555, "bids": [[14382.1, 0.222], [14482.1, 3.682], [14582.1, 0.504], [51746.0, 0.0], [58213.8, 0.003], [61448.1, 0.0], [62094.8, 0.006], [63780.4, 0.815], [63873.6, 3.883], [64035.3, 0.032], [64358.6, 0.009], [64649.0, 0.62], [64650.0, 4.988], [64650.9, 0.007], [64659.3, 0.003], [64660.6, 0.558], [64661.2, 0.0], [64661.3, 0.049], [64661.4, 0.0], [64662.0, 1.041], [64662.2, 0.116], [64663.0, 0.013], [64663.3, 0.353], [64670.3, 0.056], [64671.1, 0.001], [64672.1, 1.105], [64672.2, 0.008], [64672.3, 0.004], [64673.9, 0.044], [64675.6, 0.525], [64677.7, 0.024], [64677.8, 0.543]], "asks": [[64693.9, 0.088], [64694.8, 0.113], [64695.9, 0.002], [64696.6, 0.708], [64698.0, 0.176], [64698.1, 0.0], [64699.0, 0.939], [64700.9, 0.009], [64701.1, 0.633], [64701.5, 0.074], [64701.7, 0.562], [64702.2, 0.003], [64705.4, 0.001], [64705.8, 0.117], [64880.6, 10.918], [65329.0, 0.263], [66180.6, 3.711]]}
{"kind": "depth", "E": 1787080689709, "U": 11315373360684, "u": 11315373365511, "recv_ms": 1787080689656, "bids": [[14382.1, 0.376], [14482.1, 3.724], [14582.1, 0.308], [58213.8, 0.003], [61447.9, 0.001], [63605.8, 1.254], [63614.8, 2.211], [63682.1, 0.0], [63686.2, 16.154], [63750.9, 29.927], [63793.4, 7.732], [64035.3, 0.034], [64358.6, 0.008], [64358.7, 1.1], [64542.4, 1.21], [64660.1, 0.375], [64672.2, 0.572], [64672.7, 0.0], [64675.6, 0.255], [64677.7, 0.001], [64677.8, 0.002], [64682.1, 8.767]], "asks": [[64713.2, 0.384], [64824.8, 0.376], [65005.7, 0.001], [65329.0, 0.263], [65458.8, 7.327], [65620.1, 6.505], [65627.0, 32.767], [65682.2, 0.001]]}
{"kind": "depth", "E": 1787080689811, "U": 11315373365534, "u": 11315373370446, "recv_ms": 1787080689758, "bids": [[1000.0, 35.81], [14382.1, 0.614], [14482.1, 3.612], [14582.1, 0.182], [51745.7, 0.0], [58213.8, 0.003], [61447.9, 0.0], [62094.8, 0.009], [63388.5, 0.041], [63783.3, 48.199], [63920.4, 10.7], [64035.3, 0.032], [64525.4, 4.955], [64526.5, 1.112], [64542.3, 2.697], [64656.2, 1.412], [64665.9, 0.791], [64669.1, 1.503], [64682.1, 8.496]], "asks": [[64682.2, 37.645], [64689.0, 0.196], [64704.4, 2.865], [64713.2, 0.23], [64713.3, 0.154], [64752.0, 6.89], [64824.8, 5.775], [64841.7, 2.33], [64841.8, 10.839], [65005.7, 0.002], [65279.2, 4.513], [65329.0, 0.263]]}
{"kind": "depth", "E": 1787080689913, "U": 11315373370629, "u": 11315373375699, "recv_ms": 1787080689860, "bids": [[14382.1, 0.852], [14482.1, 3.486], [14582.1, 0.07], [58213.8, 0.003], [62094.8, 0.006], [63682.1, 0.02], [63744.2, 10.773], [63783.0, 3.132], [64035.3, 0.032], [64341.0, 16.29], [64341.2, 0.0], [64669.0, 0.008], [64669.3, 0.005]], "asks": [[64752.0, 1.108], [64754.7, 40.188], [64756.9, 0.001], [65329.0, 0.263], [65620.1, 7.571], [65682.2, 0.021], [65756.4, 5.497], [66169.9, 0.956]]}
{"kind": "depth", "E": 1787080690015, "U": 11315373375707, "u": 11315373382135, "recv_ms": 1787080689961, "bids": [[14382.1, 1.146], [14482.1, 3.262], [14582.1, 0.0], [58213.8, 0.003], [61447.9, 0.0], [61512.0, 0.031], [62094.8, 0.009], [63388.5, 0.044], [63679.5, 5.491], [63905.9, 16.651], [64035.3, 0.032], [64164.6, 3.42], [64358.7, 1.09], [64486.5, 5.336], [64486.6, 0.005], [64489.6, 1.895], [64525.4, 2.813], [64542.3, 1.625], [64569.0, 13.347], [64569.4, 1.722], [64616.5, 3.009], [64660.1, 0.371], [64662.6, 0.111], [64665.4, 0.154], [64667.1, 0.227], [64670.4, 0.238], [64675.0, 0.158], [64675.2, 0.134], [64679.3, 0.001], [64682.1, 8.554]], "asks": [[64682.2, 37.653], [64693.9, 0.629], [64694.9, 0.135], [64702.8, 0.892], [64703.5, 0.004], [64704.3, 0.28], [64709.4, 0.003], [64710.7, 0.169], [64716.9, 0.119], [64750.2, 3.675], [64750.3, 0.002], [64796.8, 2.47], [64797.7, 14.573], [64798.2, 0.0], [65005.2, 0.108], [65011.3, 0.004], [65264.3, 2.306], [65329.0, 0.263], [65426.7, 16.797], [65451.9, 2.099], [65620.1, 8.636]]}
{"kind": "depth", "E": 1787080690117, "U": 11315373382297, "u": 11315373388022, "recv_ms": 1787080690064, "bids": [[1000.0, 35.81], [14382.1, 1.496], [14482.1, 2.912], [58213.8, 0.003], [61448.0, 0.017], [61448.1, 0.002], [63682.1, 0.0], [63694.1, 3.611], [64035.3, 0.032], [64486.5, 13.432], [64525.4, 6.2], [64542.3, 3.303], [64610.7, 0.0], [64633.8, 0.004], [64633.9, 0.0], [64639.5, 0.064], [64639.9, 0.742], [64640.1, 0.005], [64649.9, 0.083], [64650.0, 4.931], [64650.8, 3.558], [64665.6, 0.934], [64665.7, 0.163], [64666.0, 3.103], [64666.5, 0.037], [64670.3, 0.056], [64670.5, 0.232], [64672.1, 0.101], [64672.2, 0.008], [64672.3, 1.008], [64673.9, 0.044], [64677.7, 0.565], [64682.1, 8.565]], "asks": [[64698.1, 0.0], [64698.2, 0.315], [64698.5, 1.45], [64698.9, 1.387], [64699.0, 0.014], [64701.8, 0.016], [64702.2, 0.06], [64702.3, 0.094], [64702.7, 0.001], [64702.8, 0.351], [64703.5, 0.545], [64713.3, 0.0], [64743.2, 2.156], [64743.5, 0.002], [64796.8, 4.391], [64880.6, 9.71], [65329.0, 0.263], [65426.7, 17.713], [65600.7, 0.682], [65670.1, 0.028], [65682.2, 0.001]]}
{"kind": "depth", "E": 1787080690219, "U": 11315373388207, "u": 11315373394224, "recv_ms": 1787080690167, "bids": [[14382.1, 1.86], [14482.1, 2.548], [58213.8, 0.003], [61448.0, 0.015], [61448.1, 0.004], [62094.8, 0.006], [63694.1, 3.621], [63718.6, 9.442], [63780.4, 0.032], [64035.3, 0.032], [64610.6, 0.019], [64636.8, 1.717], [64643.2, 2.701], [64670.3, 0.056], [64670.8, 0.002], [64672.0, 1.609], [64672.1, 0.565], [64672.2, 0.008], [64672.3, 0.004], [64672.4, 0.54], [64675.2, 0.133], [64675.4, 0.172], [64677.7, 0.565], [64677.8, 0.086], [64678.0, 0.078], [64678.1, 0.002]], "asks": [[64690.8, 2.327], [64693.9, 0.631], [64713.4, 0.197], [64727.5, 0.003], [64752.8, 0.0], [64755.9, 2.047], [64811.6, 0.0], [65329.0, 0.263], [65458.8, 6.412], [65670.1, 0.038], [65691.7, 19.91], [65749.5, 1.066], [65975.8, 0.021]]}
{"kind": "depth", "E": 1787080690321, "U": 11315373394287, "u": 11315373402066, "recv_ms": 1787080690268, "bids": [[1000.0, 35.81], [14382.1, 2.21], [14482.1, 2.198], [51746.0, 0.0], [58213.8, 0.003], [61648.3, 0.016], [62094.8, 0.009], [63682.1, 0.02], [63754.6, 8.97], [64035.3, 0.032], [64358.7, 1.09], [64667.1, 0.307], [64669.5, 0.004], [64670.6, 0.524], [64670.7, 0.172], [64682.1, 8.555]], "asks": [[64702.8, 0.892], [64703.5, 0.004], [64704.2, 0.469], [65329.0, 0.263], [65682.2, 0.021], [71150.5, 0.0]]}
{"kind": "depth", "E": 1787080690423, "U": 11315373402135, "u": 11315373408956, "recv_ms": 1787080690370, "bids": [[1000.0, 35.81], [14382.1, 2.574], [14482.1, 1.834], [51746.0, 0.0], [58213.8, 0.003], [61447.9, 0.0], [62094.8, 0.006], [63974.6, 0.0], [64035.3, 0.032], [64525.4, 6.13], [64542.3, 3.274], [64575.0, 2.967], [64575.5, 1.094], [64610.6, 0.02], [64617.4, 0.036], [64623.8, 0.003], [64633.8, 0.005], [64640.1, 0.006], [64664.1, 0.011], [64664.5, 0.627], [64664.6, 0.102], [64670.6, 0.37], [64671.9, 0.015], [64672.1, 0.549], [64672.3, 0.313], [64672.5, 0.047], [64672.6, 0.163], [64675.4, 0.171], [64675.6, 0.256], [64677.7, 0.001], [64677.8, 0.085], [64678.0, 0.078], [64678.1, 0.543], [64678.2, 0.085], [64682.1, 8.782]], "asks": [[64682.2, 37.658], [64697.7, 0.627], [64705.1, 0.501], [64713.4, 0.043], [64754.7, 40.502], [64756.9, 0.001], [64759.9, 0.755], [64764.9, 0.687], [64789.8, 0.0], [64791.9, 2.319], [64792.0, 1.316], [64824.8, 5.775], [64841.7, 0.021], [64841.8, 10.839], [64880.6, 10.136], [65329.0, 0.263], [65451.9, 3.014]]}
{"kind": "depth", "E": 1787080690525, "U": 11315373409031, "u": 11315373417650, "recv_ms": 1787080690474, "bids": [[14382.1, 2.938], [14482.1, 1.47], [58213.8, 0.003], [61447.9, 0.0], [62094.8, 0.009], [62101.4, 0.004], [63464.5, 0.811], [63682.1, 0.0], [63770.1, 0.791], [64035.3, 0.032], [64664.5, 0.009], [64665.7, 0.161], [64670.6, 0.524], [64672.5, 0.024], [64675.3, 0.287], [64675.5, 0.429], [64675.6, 0.255], [64677.7, 0.008], [64677.8, 0.085], [64678.0, 0.635], [64678.1, 0.002], [64678.2, 0.001], [64679.2, 0.0], [64680.1, 0.033], [64682.1, 8.705]], "asks": [[64682.2, 37.659], [64698.2, 0.313], [64713.3, 0.0], [64713.4, 0.197], [64754.7, 0.0], [64756.9, 40.503], [65329.0, 0.263], [65682.2, 0.001], [65684.8, 3.961]]}
{"kind": "depth", "E": 1787080690627, "U": 11315373417717, "u": 11315373423696, "recv_ms": 1787080690576, "bids": [[1000.0, 35.81], [14382.1, 3.288], [14482.1, 1.12], [51746.0, 0.0], [58213.8, 0.003], [61447.9, 0.0], [63653.9, 2.635], [63750.9, 28.83], [64035.3, 0.032], [64358.7, 1.09], [64665.7, 0.163], [64667.9, 0.08], [64668.1, 0.139], [64672.2, 0.471], [64672.4, 0.077], [64672.5, 0.024], [64675.4, 0.172], [64675.5, 0.428], [64677.7, 0.008], [64677.8, 0.085], [64678.0, 0.635], [64678.1, 0.002], [64678.3, 0.084], [64680.0, 0.028], [64682.1, 8.715]], "asks": [[64687.3, 0.0], [64687.4, 0.004], [64687.6, 0.536], [64698.2, 0.315], [64701.5, 0.067], [64702.2, 0.067], [64702.8, 0.351], [64703.5, 0.545], [64704.2, 0.465], [64754.7, 40.502], [64756.9, 0.001], [64880.6, 10.135], [65005.7, 0.001], [65329.0, 0.263], [65458.4, 10.144], [65492.0, 0.066], [65724.0, 7.274], [66180.6, 2.958]]}
{"kind": "depth", "E": 1787080690729, "U": 11315373423830, "u": 11315373430857, "recv_ms": 1787080690676, "bids": [[1000.0, 35.81], [14382.1, 3.638], [14482.1, 0.77], [58213.8, 0.003], [61447.9, 0.0], [62094.8, 0.006], [63653.9, 1.537], [63682.1, 0.02], [63686.2, 15.057], [63763.6, 1.88], [64035.3, 0.032], [64358.6, 0.009], [64542.3, 0.0], [64670.6, 0.37], [64670.7, 0.326], [64672.4, 0.641], [64677.7, 0.001], [64678.0, 0.078], [64682.1, 8.79]], "asks": [[64682.2, 37.66], [64702.8, 0.892], [64703.5, 0.004], [64824.8, 0.376], [65329.0, 0.263], [65591.9, 3.319], [65627.0, 31.703], [65630.7, 10.198], [65682.2, 0.021], [65724.0, 6.21]]}
{"kind": "depth", "E": 1787080690831, "U": 11315373430933, "u": 11315373439619, "recv_ms": 1787080690779, "bids": [[14282.1, 0.042], [14382.1, 3.918], [14482.1, 0.448], [51745.7, 0.0], [58213.8, 0.003], [62094.8, 0.009], [63647.2, 4.08], [63744.2, 11.87], [64035.3, 0.032], [64358.6, 0.01], [64526.5, 1.95], [64542.3, 3.304], [64569.4, 3.554], [64660.1, 0.375], [64672.4, 0.077], [64675.0, 0.158], [64675.6, 0.525], [64677.7, 0.008], [64677.8, 0.085], [64678.0, 0.635], [64678.9, 0.003]], "asks": [[64705.1, 0.617], [64705.8, 0.001], [64707.5, 1.419], [64752.0, 6.988], [64824.8, 5.775], [64841.7, 2.33], [64880.5, 9.693], [64880.6, 0.013], [65005.7, 0.0], [65329.0, 0.263], [65490.7, 0.714], [65598.4, 22.228], [65717.1, 3.224], [65975.8, 0.024]]}
{"kind": "depth", "E": 1787080690933, "U": 11315373439827, "u": 11315373446861, "recv_ms": 1787080690881, "bids": [[1000.0, 35.81], [14282.1, 0.224], [14382.1, 3.904], [14482.1, 0.28], [58213.8, 0.003], [61447.9, 0.0], [62094.8, 0.006], [63682.1, 0.0], [63919.1, 6.563], [64035.3, 0.032], [64341.0, 15.798], [64341.2, 0.492], [64358.7, 1.09], [64562.9, 2.319], [64563.9, 3.865], [64575.0, 0.648], [64575.3, 2.323], [64585.1, 0.016], [64611.2, 0.059], [64660.1, 0.371], [64670.5, 0.232], [64670.7, 0.172], [64672.4, 0.625], [64675.4, 0.172], [64675.6, 0.255], [64677.7, 0.009], [64678.0, 0.078], [64678.1, 0.002], [64678.2, 0.086], [64678.3, 0.0], [64682.1, 8.746]], "asks": [[64682.2, 37.659], [64752.0, 1.108], [64753.6, 1.424], [64754.7, 40.502], [64756.9, 0.001], [64791.8, 2.32], [64791.9, 0.0], [64817.8, 5.753], [64817.9, 0.0], [64879.8, 0.003], [64879.9, 1.183], [65329.0, 0.265], [65538.0, 2.468], [65581.3, 2.678], [65682.2, 0.001], [66169.9, 1.709]]}
{"kind": "depth", "E": 1787080691035, "U": 11315373446877, "u": 11315373454241, "recv_ms": 1787080690982, "bids": [[1000.0, 35.81], [14282.1, 0.462], [14382.1, 3.792], [14482.1, 0.154], [58213.8, 0.003], [61447.9, 0.0], [62094.8, 0.009], [63647.2, 5.179], [63679.5, 6.588], [63832.2, 0.782], [63873.6, 4.148], [64035.3, 0.032], [64649.9, 0.083], [64650.9, 0.007], [64651.9, 0.681], [64660.6, 0.558], [64661.4, 0.0], [64662.2, 0.116], [64663.1, 0.311], [64664.7, 0.632], [64665.6, 0.934], [64666.6, 0.047], [64670.3, 0.21], [64670.5, 0.237], [64672.1, 0.0], [64672.4, 0.0], [64672.5, 0.016], [64672.6, 0.797], [64673.9, 0.044], [64675.4, 0.171], [64675.6, 0.256], [64676.2, 0.004], [64677.7, 0.565], [64682.1, 8.752]], "asks": [[64682.2, 37.659], [64690.0, 1.308], [64690.6, 1.258], [64698.1, 0.925], [64698.5, 0.525], [64699.0, 0.014], [64701.8, 0.073], [64702.2, 0.01], [64702.7, 0.001], [64702.8, 0.892], [64703.5, 0.004], [64705.1, 0.501], [64705.9, 0.18], [64880.5, 10.119], [65329.0, 0.263], [65620.1, 9.7], [65717.1, 4.288]]}
{"kind": "depth", "E": 1787080691137, "U": 11315373454456, "u": 11315373462410, "recv_ms": 1787080691084, "bids": [[14282.1, 0.7], [14382.1, 3.68], [14482.1, 0.028], [51746.0, 0.0], [58213.8, 0.003], [61447.9, 0.006], [63388.5, 0.047], [63682.1, 0.02], [63694.1, 3.612], [63791.0, 19.582], [64035.3, 0.032], [64542.3, 0.0], [64610.6, 0.021], [64633.8, 0.006], [64640.1, 0.007], [64670.5, 0.232], [64672.1, 0.541], [64672.4, 0.549], [64672.6, 0.248], [64675.4, 0.172], [64675.6, 0.255], [64677.7, 0.024], [64677.8, 0.085], [64678.0, 0.078], [64682.1, 8.701]], "asks": [[64682.2, 37.639], [64684.8, 0.007], [64685.1, 0.442], [64685.5, 0.381], [64690.2, 0.0], [64824.8, 0.376], [65226.7, 2.6], [65329.0, 0.263], [65670.1, 0.029], [65682.2, 0.021]]}
{"kind": "depth", "E": 1787080691239, "U": 11315373462486, "u": 11315373469976, "recv_ms": 1787080691187, "bids": [[1000.0, 35.81], [14282.1, 1.008], [14382.1, 3.4], [14482.1, 0.0], [51746.0, 0.0], [58213.8, 0.003], [62094.8, 0.006], [63694.1, 3.621], [63912.4, 2.852], [64035.3, 0.032], [64358.7, 1.09], [64542.3, 2.752], [64627.3, 0.007], [64634.1, 0.002], [64672.4, 0.008], [64675.4, 0.171], [64675.6, 0.256], [64677.7, 0.008], [64677.8, 0.085], [64678.0, 0.635], [64682.1, 8.686]], "asks": [[64685.5, 0.38], [64811.6, 0.0], [64824.8, 5.775], [65329.0, 0.263], [65523.1, 2.041], [65670.1, 0.038], [65691.7, 18.847]]}
{"kind": "depth", "E": 1787080691341, "U": 11315373470115, "u": 11315373475960, "recv_ms": 1787080691288, "bids": [[1000.0, 35.81], [14282.1, 1.372], [14382.1, 3.036], [58213.8, 0.003], [61447.9, 0.006], [62094.8, 0.009], [63682.1, 0.0], [63912.6, 40.847], [64035.3, 0.032], [64672.4, 0.549], [64675.4, 0.172], [64675.6, 0.255], [64677.7, 0.024], [64678.0, 0.078]], "asks": [[64682.2, 37.645], [64689.0, 0.19], [65206.5, 6.887], [65329.0, 0.265], [65682.2, 0.001]]}
{"kind": "depth", "E": 1787080691443, "U": 11315373476005, "u": 11315373481599, "recv_ms": 1787080691390, "bids": [[14282.1, 1.736], [14382.1, 2.672], [58213.8, 0.003], [62094.8, 0.006], [63595.4, 1.254], [63750.9, 27.733], [63770.1, 1.574], [64035.3, 0.032], [64486.5, 13.794], [64525.3, 6.297], [64525.4, 0.0], [64542.3, 3.335], [64616.5, 3.044], [64664.6, 0.04], [64665.4, 0.216], [64672.1, 0.0], [64672.4, 0.0], [64672.5, 0.008], [64672.6, 0.163], [64672.8, 0.001], [64672.9, 0.542], [64673.1, 0.028], [64675.1, 0.982], [64675.4, 0.171], [64675.6, 0.256], [64676.2, 0.097], [64677.7, 0.565], [64682.1, 8.727]], "asks": [[64682.2, 37.65], [64682.6, 0.769], [64683.6, 0.009], [64684.4, 0.015], [64684.7, 0.004], [64689.0, 0.185], [64689.8, 0.01], [64698.6, 0.317], [64700.8, 0.017], [64701.7, 0.56], [64704.2, 0.467], [64704.3, 0.282], [64706.0, 0.005], [64750.0, 5.572], [64750.2, 0.002], [64754.7, 0.0], [64756.9, 40.598], [64824.8, 5.547], [64880.5, 9.244], [65329.0, 0.263], [65627.0, 30.638], [65684.8, 5.024], [65975.8, 0.015]]}
{"kind": "depth", "E": 1787080691545, "U": 11315373481637, "u": 11315373487375, "recv_ms": 1787080691496, "bids": [[1000.0, 35.81], [14282.1, 2.1], [14382.1, 2.308], [58213.8, 0.003], [61447.9, 0.006], [63682.1, 0.02], [63776.6, 5.857], [64035.3, 0.032], [64358.7, 1.09], [64611.9, 0.314], [64623.8, 0.0], [64627.3, 0.003], [64627.7, 0.039], [64634.1, 0.006], [64634.5, 0.001], [64636.8, 1.717], [64650.7, 0.166], [64665.7, 0.161], [64668.6, 0.011], [64669.0, 0.001], [64672.1, 0.541], [64672.4, 0.101], [64672.9, 0.001], [64673.1, 0.02], [64675.2, 0.133], [64675.4, 0.171], [64675.6, 0.256], [64676.2, 0.004], [64677.7, 0.557], [64677.8, 0.093], [64677.9, 0.235], [64678.0, 0.078]], "asks": [[64698.2, 0.313], [64707.3, 0.002], [64723.4, 0.09], [64723.5, 0.002], [64727.5, 0.003], [64746.0, 0.629], [64746.1, 0.003], [64754.7, 40.597], [64756.9, 0.001], [64759.9, 0.752], [65329.0, 0.263], [65620.1, 10.766], [65627.0, 29.573], [65682.2, 0.021]]}
{"kind": "depth", "E": 1787080691647, "U": 11315373487445, "u": 11315373493885, "recv_ms": 1787080691596, "bids": [[1000.0, 35.81], [14282.1, 2.45], [14382.1, 1.958], [51746.0, 0.0], [58213.8, 0.003], [61447.9, 0.007], [62094.8, 0.009], [63682.1, 0.0], [64035.3, 0.032], [64358.6, 0.009], [64578.4, 1.757], [64579.6, 0.0], [64579.7, 0.004], [64582.2, 1.609], [64585.1, 0.024], [64610.8, 6.006], [64611.1, 3.654], [64622.4, 1.193], [64622.8, 0.372], [64623.1, 0.312], [64623.4, 0.818], [64623.7, 0.024], [64627.7, 0.025], [64633.5, 4.132], [64640.3, 0.01], [64640.6, 0.005], [64641.0, 0.016], [64641.3, 0.002], [64641.6, 1.063], [64649.6, 0.992], [64655.2, 1.973], [64655.3, 0.019], [64655.4, 0.329], [64655.5, 0.019], [64655.6, 0.058], [64655.7, 0.17], [64655.8, 0.028], [64655.9, 0.47], [64656.0, 1.407], [64656.2, 1.342], [64657.4, 0.015], [64657.8, 0.002], [64665.7, 0.163], [64672.0, 1.918], [64672.3, 0.004], [64672.4, 0.642], [64672.5, 0.031], [64674.8, 0.248], [64674.9, 0.78], [64675.0, 0.019], [64675.1, 0.842], [64675.2, 0.033], [64675.3, 0.087], [64675.4, 0.001], [64675.5, 0.328], [64675.6, 0.085], [64675.7, 0.169], [64675.8, 0.054], [64676.1, 1.789], [64676.4, 0.001], [64676.7, 0.085], [64677.1, 0.087], [64677.4, 0.662], [64677.7, 0.001], [64677.8, 0.085], [64677.9, 0.235], [64682.1, 8.686]], "asks": [[64682.2, 37.762], [64694.9, 0.097], [64695.2, 1.099], [64695.5, 0.0], [64695.8, 0.529], [64696.2, 0.161], [64696.4, 0.001], [64696.5, 0.464], [64696.6, 0.617], [64696.7, 2.4], [64696.8, 0.0], [64696.9, 0.154], [64697.0, 0.918], [64697.1, 1.226], [64697.2, 0.041], [64697.3, 0.027], [64697.4, 0.06], [64698.2, 0.315], [64700.8, 0.573], [64701.7, 0.004], [64704.9, 10.221], [64705.9, 0.064], [64707.2, 1.015], [64712.7, 0.066], [64713.1, 0.001], [64713.4, 0.155], [64713.7, 0.0], [64714.0, 0.016], [64714.4, 0.443], [64714.8, 3.539], [64716.0, 0.005], [64716.2, 0.031], [64716.3, 0.163], [64716.4, 0.001], [64716.5, 0.009], [64716.6, 0.003], [64716.7, 0.001], [64716.8, 0.006], [64716.9, 0.028], [64717.0, 0.0], [64723.4, 3.59], [64730.6, 0.486], [64731.0, 0.066], [64731.3, 0.169], [64731.6, 0.012], [64731.9, 0.002], [64746.1, 6.003], [64777.8, 0.778], [64778.4, 0.027], [65329.0, 0.263], [65682.2, 0.001]]}
{"kind": "depth", "E": 1787080691749, "U": 11315373493909, "u": 11315373502025, "recv_ms": 1787080691696, "bids": [[14282.1, 2.8], [14382.1, 1.608], [51746.0, 0.0], [58213.8, 0.003], [61447.9, 0.013], [62094.8, 0.006], [63744.2, 12.967], [64640.8, 0.032], [64641.8, 0.063], [64674.9, 0.51], [64675.0, 0.089], [64675.2, 0.103], [64675.6, 0.155], [64676.6, 0.032], [64677.5, 0.034], [64682.1, 8.685]], "asks": [[64694.4, 0.076], [64695.4, 0.047], [64696.3, 0.084], [64696.7, 2.491], [64696.9, 0.231], [64712.3, 0.159], [64713.3, 0.045], [64715.9, 0.085], [64716.3, 0.254], [64716.5, 0.086], [64730.2, 0.038], [64731.1, 0.049], [65005.7, 0.001], [65329.0, 0.265], [65975.8, 0.018]]}
{"kind": "depth", "E": 1787080691851, "U": 11315373502071, "u": 11315373508741, "recv_ms": 1787080691799, "bids": [[1000.0, 35.81], [14282.1, 3.164], [14382.1, 1.244], [51745.7, 0.0], [58213.8, 0.003], [61447.9, 0.012], [62094.8, 0.009], [64035.3, 0.032], [64358.6, 0.008], [64358.7, 1.1], [64489.6, 3.079], [64578.4, 0.004], [64578.5, 10.003], [64578.6, 3.246], [64640.5, 3.241], [64641.1, 0.032], [64674.9, 0.78], [64675.2, 0.103], [64675.7, 0.269], [64675.8, 0.124], [64675.9, 0.104], [64676.3, 0.117], [64676.9, 0.038]], "asks": [[64695.0, 0.382], [64695.7, 0.1], [64696.1, 0.502], [64696.3, 0.234], [64712.9, 0.045], [64713.6, 0.049], [64714.0, 0.176], [64715.7, 0.116], [64715.9, 0.235], [64723.3, 1.764], [64730.8, 0.044], [64731.5, 0.098], [64752.0, 7.003], [64777.8, 2.159], [64779.1, 0.01], [64779.2, 11.269], [64782.3, 2.885], [65005.7, 0.002], [65329.0, 0.263], [65566.1, 1.522], [65620.1, 11.832]]}
{"kind": "depth", "E": 1787080691953, "U": 11315373508893, "u": 11315373514297, "recv_ms": 1787080691902, "bids": [[1000.0, 35.81], [14282.1, 3.514], [14382.1, 0.894], [58213.8, 0.003], [61447.9, 0.018], [62094.8, 0.006], [63682.1, 0.02], [63686.2, 13.959], [63711.9, 1.544], [63750.9, 26.636], [63815.6, 20.102], [63839.2, 0.007], [64035.3, 0.032], [64341.2, 0.0], [64341.4, 0.494], [64578.6, 3.238], [64578.7, 0.01], [64617.4, 0.108], [64641.5, 0.033], [64649.3, 0.0], [64649.9, 0.026], [64650.2, 0.5], [64659.8, 0.562], [64660.6, 0.001], [64661.4, 0.0], [64662.2, 0.0], [64662.4, 0.161], [64664.9, 0.0], [64665.6, 0.008], [64665.8, 0.926], [64669.2, 0.003], [64672.5, 0.008], [64674.9, 0.51], [64675.0, 0.088], [64675.1, 0.982], [64675.2, 0.173], [64675.4, 0.202], [64675.5, 0.528], [64675.7, 0.369], [64676.0, 0.155], [64677.2, 0.033], [64677.7, 0.024], [64678.2, 0.085], [64682.1, 8.726]], "asks": [[64694.7, 0.039], [64696.0, 0.155], [64696.2, 0.291], [64696.4, 0.121], [64696.5, 0.734], [64696.6, 0.737], [64696.7, 2.596], [64696.8, 0.091], [64696.9, 0.315], [64697.4, 0.06], [64698.1, 0.0], [64698.3, 1.089], [64701.2, 0.0], [64701.8, 0.016], [64702.0, 0.061], [64702.8, 0.351], [64703.5, 0.545], [64712.6, 0.037], [64714.4, 0.583], [64715.6, 0.599], [64715.8, 0.131], [64716.0, 0.125], [64716.1, 0.203], [64716.2, 0.151], [64716.3, 0.359], [64716.4, 0.092], [64716.5, 0.17], [64730.5, 0.037], [64746.9, 0.032], [64752.0, 1.108], [64754.7, 0.0], [64756.9, 40.598], [65329.0, 0.263], [65465.3, 49.325], [65523.5, 0.0], [65555.4, 2.893], [65682.2, 0.021]]}
{"kind": "depth", "E": 1787080692055, "U": 11315373514420, "u": 11315373519756, "recv_ms": 1787080692002, "bids": [[14182.1, 0.07], [14282.1, 3.738], [14382.1, 0.6], [58213.8, 0.003], [61447.9, 0.018], [61454.6, 0.0], [63621.5, 5.418], [63682.1, 0.0], [63744.2, 13.124], [63750.9, 25.539], [63912.6, 40.145], [64035.3, 0.032], [64358.7, 1.09], [64622.9, 0.035], [64623.9, 0.66], [64627.3, 0.007], [64634.1, 0.002], [64670.5, 0.237], [64675.3, 0.157], [64680.1, 0.021], [64682.1, 8.722]], "asks": [[64682.2, 37.763], [64696.6, 0.814], [64702.8, 0.892], [64703.5, 0.004], [64716.2, 0.228], [65329.0, 0.265], [65627.0, 28.508], [65682.2, 0.001], [65691.7, 17.783]]}
{"kind": "depth", "E": 1787080692259, "U": 11315373527298, "u": 11315373532616, "recv_ms": 1787080692205, "bids": [[1000.0, 35.81], [14182.1, 0.518], [14282.1, 3.556], [14382.1, 0.334], [51746.0, 0.0], [58213.8, 0.003], [61447.9, 0.018], [62094.8, 0.006], [63472.5, 1.698], [63679.5, 7.686], [63744.2, 14.221], [63961.5, 1.562], [64035.3, 0.032], [64052.1, 0.0], [64623.6, 0.033], [64627.3, 0.003], [64634.1, 0.006], [64640.1, 0.009], [64655.9, 0.57], [64656.1, 0.206], [64656.2, 1.412], [64658.0, 1.363], [64682.1, 8.764]], "asks": [[64682.2, 37.788], [64700.8, 0.571], [64701.2, 0.002], [64811.6, 0.0], [65329.0, 0.263], [65670.2, 0.017]]}
{"kind": "depth", "E": 1787080692463, "U": 11315373538093, "u": 11315373543745, "recv_ms": 1787080692423, "bids": [[1000.0, 35.81], [14182.1, 1.106], [14282.1, 3.094], [14382.1, 0.208], [58213.8, 0.003], [61447.9, 0.018], [62094.8, 0.006], [64035.3, 0.032], [64181.7, 3.43], [64525.3, 6.157], [64542.3, 3.275], [64623.8, 0.003], [64655.7, 0.24], [64661.3, 0.009], [64664.8, 0.621], [64667.5, 0.144], [64672.2, 1.089], [64672.3, 0.004], [64674.9, 0.426], [64675.4, 0.201], [64675.7, 0.37], [64677.7, 0.024], [64677.8, 0.626], [64678.7, 0.086], [64679.8, 0.0], [64682.1, 8.743]], "asks": [[64682.2, 37.789], [64688.4, 0.0], [64698.0, 0.794], [64705.4, 0.619], [64759.9, 0.755], [64824.7, 9.183], [64824.8, 0.376], [64841.6, 2.327], [64841.7, 10.431], [64841.8, 0.429], [64880.5, 10.114], [65329.0, 0.263], [65620.1, 13.049]]}
{"kind": "depth", "E": 1787080692565, "U": 11315373543819, "u": 11315373549557, "recv_ms": 1787080692514, "bids": [[1000.0, 35.81], [14182.1, 1.456], [14282.1, 2.744], [58213.8, 0.003], [61447.9, 0.018], [61448.0, 0.013], [63388.5, 0.044], [63682.1, 0.0], [64035.2, 0.056], [64035.3, 0.032], [64137.6, 0.0], [64542.3, 3.305], [64627.3, 0.007], [64634.1, 0.002], [64665.7, 0.161], [64672.3, 0.004], [64674.9, 0.426], [64675.0, 0.088], [64675.5, 0.529], [64675.7, 0.369], [64677.7, 0.024], [64677.8, 0.626]], "asks": [[64682.2, 37.789], [64698.2, 0.313], [64702.8, 0.351], [64703.5, 0.545], [64824.7, 9.183], [64880.5, 9.689], [65329.0, 0.263], [65473.3, 14.122], [65587.8, 10.535], [65682.2, 0.001], [65756.4, 3.371]]}
{"kind": "depth", "E": 1787080692667, "U": 11315373549628, "u": 11315373556689, "recv_ms": 1787080692615, "bids": [[14182.1, 1.82], [14282.1, 2.38], [51746.0, 0.0], [58213.8, 0.003], [61447.9, 0.018], [61448.0, 0.015], [62094.8, 0.009], [63595.4, 1.881], [63750.9, 24.442], [63776.6, 8.205], [64035.3, 0.032], [64138.1, 0.003], [64358.7, 1.09], [64655.1, 0.401], [64659.8, 0.005], [64661.0, 0.582], [64661.6, 0.028], [64665.7, 0.163], [64672.3, 0.004], [64675.4, 0.201], [64675.5, 0.528], [64675.7, 0.37], [64677.7, 0.024], [64677.8, 0.626], [64677.9, 0.003], [64682.1, 8.735]], "asks": [[64682.2, 37.79], [64698.2, 0.315], [64841.7, 0.021], [64845.8, 7.591], [64880.5, 0.001], [64884.6, 12.884], [65329.0, 0.263], [65749.5, 2.129], [65829.1, 0.001]]}
{"kind": "depth", "E": 1787080692769, "U": 11315373556813, "u": 11315373562086, "recv_ms": 1787080692716, "bids": [[1000.0, 35.81], [14182.1, 2.184], [14282.1, 2.016], [58213.8, 0.003], [61447.9, 0.024], [62094.8, 0.006], [63682.1, 0.02], [64035.3, 0.032], [64164.6, 3.42], [64358.6, 0.009], [64542.2, 3.336], [64542.3, 0.0], [64623.8, 0.003], [64636.8, 1.714], [64670.2, 2.487], [64670.3, 0.056], [64672.3, 0.545], [64675.5, 0.529], [64675.7, 0.369], [64677.7, 0.024], [64677.8, 0.085], [64677.9, 0.003], [64682.1, 8.77]], "asks": [[64682.2, 37.791], [64702.8, 0.892], [64703.5, 0.004], [64727.5, 0.003], [64759.9, 0.752], [64824.7, 9.183], [64841.6, 0.014], [64841.7, 10.431], [64845.8, 0.0], [64880.5, 9.235], [64883.3, 2.494], [64884.6, 0.199], [65005.7, 0.001], [65329.0, 0.263], [65682.2, 0.021], [65814.1, 1.262]]}
{"kind": "depth", "E": 1787080692871, "U": 11315373562231, "u": 11315373568077, "recv_ms": 1787080692818, "bids": [[1000.0, 35.81], [14182.1, 2.534], [14282.1, 1.666], [51745.7, 0.0], [58213.8, 0.003], [62094.8, 0.009], [63447.7, 0.001], [63744.2, 16.415], [63919.1, 5.626], [64035.3, 0.032], [64602.0, 7.246], [64608.2, 0.001], [64627.3, 0.003], [64634.1, 0.006], [64645.8, 0.001], [64649.9, 0.083], [64650.2, 0.443], [64677.7, 0.025]], "asks": [[64682.2, 37.787], [64684.7, 0.001], [64714.4, 2.118], [64752.0, 7.003], [64880.5, 9.685], [64883.3, 0.689], [65005.7, 0.0], [65329.0, 0.263], [65458.4, 12.433], [65465.3, 48.716], [65497.6, 21.083], [65749.5, 3.192]]}
{"kind": "depth", "E": 1787080692973, "U": 11315373568289, "u": 11315373573347, "recv_ms": 1787080692922, "bids": [[14182.1, 2.898], [14282.1, 1.302], [58213.8, 0.003], [61447.9, 0.024], [63682.1, 0.0], [63750.9, 23.345], [63880.3, 23.764], [64035.3, 0.032], [64341.4, 0.002], [64341.5, 0.507], [64358.6, 0.01], [64358.7, 1.1], [64645.8, 0.015], [64649.8, 0.074], [64649.9, 0.026], [64650.7, 0.166], [64664.8, 0.003], [64665.5, 0.927], [64665.8, 0.0], [64666.4, 2.32], [64672.1, 0.642], [64672.2, 0.471], [64672.3, 0.004], [64672.4, 0.0], [64673.9, 0.044], [64675.5, 0.799], [64677.7, 0.025], [64677.8, 0.626], [64678.7, 0.002], [64679.7, 0.009], [64679.9, 0.002], [64680.6, 0.024], [64680.7, 0.149], [64682.1, 8.819]], "asks": [[64682.2, 37.791], [64698.0, 0.176], [64698.1, 0.925], [64698.3, 0.164], [64698.8, 0.794], [64700.8, 0.015], [64701.7, 0.617], [64702.0, 0.004], [64702.6, 0.483], [64702.8, 0.892], [64703.5, 0.004], [64704.9, 10.105], [64705.4, 0.001], [64705.8, 0.117], [64754.7, 0.0], [64756.9, 40.464], [65273.6, 0.0], [65329.0, 0.263], [65627.0, 27.443], [65682.2, 0.001], [65691.7, 16.719], [65975.8, 0.024]]}
{"kind": "depth", "E": 1787080693075, "U": 11315373573439, "u": 11315373578573, "recv_ms": 1787080693022, "bids": [[1000.0, 35.81], [14182.1, 3.248], [14282.1, 0.952], [58213.8, 0.003], [61448.0, 0.017], [62094.8, 0.006], [63424.6, 0.0], [63905.9, 16.87], [63912.4, 3.79], [63935.7, 5.63], [64035.3, 0.032], [64222.6, 0.0], [64670.5, 0.232], [64672.1, 0.634], [64672.3, 0.004], [64672.4, 0.008], [64675.5, 0.529], [64675.6, 0.425], [64677.7, 0.566], [64677.8, 0.085]], "asks": [[64752.0, 1.108], [64754.7, 40.455], [64756.9, 0.001], [65199.7, 3.059], [65329.0, 0.263], [65620.1, 14.115], [65684.8, 7.152]]}
{"kind": "depth", "E": 1787080693177, "U": 11315373578790, "u": 11315373585104, "recv_ms": 1787080693124, "bids": [[1000.0, 35.81], [14182.1, 3.598], [14282.1, 0.602], [58213.8, 0.003], [61447.9, 0.024], [62094.8, 0.009], [63682.1, 0.02], [63744.2, 17.512], [63750.9, 22.249], [63880.3, 23.498], [63945.0, 3.286], [64035.3, 0.032], [64610.6, 0.022], [64610.7, 0.0], [64633.9, 0.0], [64640.0, 0.302], [64640.1, 0.003], [64671.6, 0.003], [64682.1, 8.82]], "asks": [[64682.2, 37.809], [64687.7, 0.004], [65329.0, 0.263], [65458.4, 13.042], [65627.0, 26.378], [65682.2, 0.021]]}
{"kind": "depth", "E": 1787080693279, "U": 11315373585361, "u": 11315373591128, "recv_ms": 1787080693227, "bids": [[14182.1, 3.766], [14282.1, 0.336], [14582.1, 0.098], [51746.0, 0.0], [58213.8, 0.003], [61447.9, 0.024], [62094.8, 0.006], [63388.5, 0.041], [63791.0, 17.233], [63925.3, 0.547], [64035.3, 0.032], [64358.7, 1.1], [64486.4, 15.018], [64486.5, 0.158], [64525.2, 6.527], [64525.3, 0.024], [64542.2, 3.44], [64669.9, 0.418], [64670.2, 2.333], [64682.1, 8.74]], "asks": [[64687.7, 0.003], [64811.6, 0.0], [64880.5, 7.552], [65215.7, 0.031], [65329.0, 0.263], [65756.4, 2.308], [65975.8, 0.021]]}
{"kind": "depth", "E": 1787080693381, "U": 11315373591247, "u": 11315373598485, "recv_ms": 1787080693327, "bids": [[1000.0, 35.81], [14182.1, 3.654], [14282.1, 0.21], [14582.1, 0.336], [51746.0, 0.0], [58213.8, 0.003], [61447.9, 0.024], [62094.8, 0.009], [63585.2, 0.001], [63682.1, 0.0], [64035.3, 0.032], [64486.4, 9.862], [64525.2, 6.205], [64542.2, 3.306], [64625.7, 0.028], [64634.1, 0.002], [64650.5, 0.003], [64658.2, 0.04], [64680.0, 0.005], [64680.8, 0.02], [64682.1, 8.731]], "asks": [[64698.1, 0.0], [64698.4, 2.077], [64701.7, 0.56], [64702.1, 0.061], [64702.8, 0.351], [64703.5, 0.545], [64880.5, 9.684], [64956.9, 3.164], [65329.0, 0.263], [65682.2, 0.001], [65975.8, 0.018]]}
{"kind": "depth", "E": 1787080693483, "U": 11315373598503, "u": 11315373604799, "recv_ms": 1787080693431, "bids": [[1000.0, 35.81], [14182.1, 3.528], [14282.1, 0.098], [14582.1, 0.574], [58213.8, 0.003], [63060.1, 0.001], [63682.1, 0.02], [63744.2, 18.609], [63754.6, 8.813], [63938.3, 6.562], [64035.3, 0.032], [64365.5, 4.29], [64555.9, 0.026], [64658.9, 1.997], [64672.3, 0.004], [64675.5, 0.799], [64675.6, 0.155], [64677.7, 0.025], [64677.8, 0.626], [64678.6, 0.086]], "asks": [[64684.6, 0.018], [64702.8, 0.892], [64703.5, 0.004], [64721.5, 0.0], [65329.0, 0.263], [65620.1, 15.18], [65627.0, 25.313], [65682.2, 0.021], [65749.5, 4.255]]}
{"kind": "depth", "E": 1787080693585, "U": 11315373604896, "u": 11315373613284, "recv_ms": 1787080693532, "bids": [[14182.1, 3.374], [14282.1, 0.0], [14582.1, 0.826], [58213.8, 0.003], [61447.9, 0.024], [62094.8, 0.006], [63776.6, 10.554], [64035.2, 0.055], [64035.3, 0.032], [64358.7, 1.09], [64655.2, 0.0], [64658.9, 1.999], [64665.0, 0.63], [64672.1, 0.626], [64672.4, 0.626], [64672.5, 0.016], [64682.1, 8.747]], "asks": [[64682.2, 37.81], [64698.2, 0.933], [64705.5, 1.951], [64719.2, 0.005], [64754.7, 0.0], [64756.9, 40.456], [65329.0, 0.263], [65620.1, 16.246], [71150.5, 0.0]]}
{"kind": "depth", "E": 1787080693687, "U": 11315373614413, "u": 11315373623801, "recv_ms": 1787080693636, "bids": [[1000.0, 35.81], [14182.1, 3.01], [14582.1, 1.19], [58213.8, 0.003], [61447.9, 0.024], [62094.8, 0.009], [63808.9, 1.017], [63987.5, 4.678], [64035.3, 0.032], [64358.6, 0.009], [64588.7, 0.003], [64588.8, 1.011], [64625.7, 0.024], [64634.1, 0.006], [64665.0, 0.012], [64665.7, 0.163], [64672.3, 0.012], [64672.4, 0.008], [64672.5, 0.008], [64674.5, 0.086], [64674.9, 0.51], [64675.4, 0.202], [64675.5, 0.528], [64677.4, 0.578], [64677.8, 0.542], [64678.2, 0.001], [64678.6, 0.002], [64679.5, 0.022], [64679.7, 0.15], [64680.1, 0.002], [64680.2, 0.023], [64680.6, 0.001], [64680.7, 0.008], [64680.8, 0.0], [64680.9, 0.0], [64682.1, 8.474]], "asks": [[64682.2, 37.81], [64698.2, 0.315], [65329.0, 0.263], [65458.4, 13.256], [65516.6, 0.305]]}
{"kind": "depth", "E": 1787080693789, "U": 11315373623945, "u": 11315373630713, "recv_ms": 1787080693737, "bids": [[1000.0, 35.81], [14182.1, 2.646], [14582.1, 1.554], [51746.0, 0.006], [58213.8, 0.003], [58241.0, 0.006], [62094.8, 0.006], [63057.1, 2.943], [63464.5, 0.025], [63682.1, 0.0], [63686.2, 12.861], [63750.9, 21.152], [63770.3, 3.284], [63905.9, 17.572], [63977.1, 2.106], [63987.5, 3.977], [64035.3, 0.032], [64575.3, 0.004], [64575.6, 3.813], [64649.3, 0.057], [64649.8, 0.017], [64659.8, 0.562], [64661.0, 0.025], [64661.4, 0.116], [64662.4, 0.045], [64664.9, 0.926], [64665.5, 0.001], [64669.9, 0.264], [64670.4, 0.392], [64670.5, 0.232], [64677.7, 0.109], [64678.1, 0.086]], "asks": [[64697.4, 0.985], [64698.4, 1.152], [64700.2, 0.557], [64701.2, 0.059], [64701.7, 0.004], [64702.1, 0.004], [64704.3, 0.398], [64705.8, 0.001], [64754.7, 40.455], [64756.9, 0.001], [64791.6, 2.831], [64791.8, 0.001], [65005.7, 0.001], [65329.0, 0.263], [65587.8, 12.819], [65627.0, 24.248], [65653.8, 0.001], [65682.2, 0.001], [71183.5, 0.006]]}
{"kind": "depth", "E": 1787080693891, "U": 11315373630834, "u": 11315373636362, "recv_ms": 1787080693840, "bids": [[14182.1, 2.296], [14582.1, 1.904], [51745.7, 0.0], [51746.0, 0.0], [58213.8, 0.003], [58213.9, 0.002], [58241.0, 0.004], [61447.9, 0.024], [62094.8, 0.009], [63977.1, 2.808], [64035.3, 0.032], [64358.7, 1.09], [64649.3, 0.0], [64650.2, 0.5], [64659.8, 0.005], [64661.4, 0.0], [64661.5, 0.56], [64662.2, 0.116], [64663.2, 0.042], [64664.9, 0.0], [64665.7, 1.089], [64665.8, 0.0], [64666.6, 0.047], [64670.2, 2.487], [64670.4, 0.238], [64672.1, 0.0], [64672.2, 1.012], [64672.3, 0.097], [64673.9, 0.044], [64675.6, 0.425], [64676.2, 0.004], [64681.6, 0.025], [64682.1, 8.514]], "asks": [[64697.4, 0.06], [64698.3, 0.164], [64699.0, 0.939], [64700.2, 0.001], [64701.1, 0.633], [64701.2, 0.002], [64701.9, 0.082], [64702.0, 0.004], [64702.1, 0.56], [64702.7, 0.542], [64702.8, 0.351], [64703.5, 0.004], [64704.3, 0.282], [64705.2, 0.07], [64705.9, 0.18], [64752.0, 1.108], [64754.7, 0.0], [64756.9, 40.456], [64841.6, 2.327], [65329.0, 0.263], [71150.4, 0.002]]}
{"kind": "depth", "E": 1787080693993, "U": 11315373636441, "u": 11315373642757, "recv_ms": 1787080693941, "bids": [[1000.0, 35.81], [14182.1, 1.932], [14582.1, 2.268], [58213.8, 0.003], [58213.9, 0.004], [61447.9, 0.024], [63388.5, 0.044], [63592.8, 8.007], [63679.5, 8.784], [63682.1, 0.02], [63744.2, 19.706], [63987.5, 3.276], [64035.3, 0.032], [64041.7, 1.591], [64341.3, 0.492], [64341.5, 0.015], [64358.6, 0.008], [64542.2, 0.0], [64555.8, 0.112], [64623.8, 0.0], [64636.8, 1.717], [64675.6, 0.425], [64682.1, 8.515]], "asks": [[64682.2, 37.956], [64727.5, 0.003], [64824.7, 3.784], [65329.0, 0.263], [65620.1, 17.312], [65682.2, 0.021], [71183.5, 0.004]]}
{"kind": "depth", "E": 1787080694095, "U": 11315373642842, "u": 11315373649217, "recv_ms": 1787080694043, "bids": [[1000.0, 35.81], [14182.1, 1.582], [14582.1, 2.618], [51746.0, 0.0], [58213.8, 0.003], [62094.8, 0.006], [64035.3, 0.032], [64542.2, 3.277], [64614.8, 0.009], [64627.3, 0.007], [64633.9, 0.001], [64634.1, 0.002], [64670.2, 2.333], [64670.4, 0.392], [64670.5, 0.232], [64675.5, 0.798], [64675.6, 0.155], [64682.1, 8.514]], "asks": [[64682.2, 38.109], [64698.2, 1.24], [64699.0, 0.014], [64754.7, 40.455], [64756.9, 0.001], [64824.7, 9.183], [64880.5, 10.105], [65329.0, 0.263], [65691.7, 15.655], [66635.5, 0.0], [71150.4, 0.004]]}
{"kind": "depth", "E": 1787080694197, "U": 11315373649364, "u": 11315373656585, "recv_ms": 1787080694146, "bids": [[14182.1, 1.232], [14582.1, 2.968], [51746.0, 0.0], [58213.8, 0.003], [61447.9, 0.024], [61448.0, 0.015], [61448.1, 0.01], [62094.8, 0.009], [63388.5, 0.041], [63582.5, 8.554], [63682.1, 0.0], [63730.9, 0.0], [63977.1, 3.51], [64035.3, 0.032], [64078.0, 10.172], [64358.7, 1.1], [64610.7, 0.001], [64640.1, 0.004], [64670.3, 0.21], [64670.4, 0.238], [64678.1, 0.002], [64682.1, 8.514]], "asks": [[64682.2, 38.109], [64687.9, 2.984], [64690.0, 0.905], [64705.5, 1.333], [64811.6, 0.0], [65005.7, 0.002], [65329.0, 0.263], [65548.5, 0.007], [65602.7, 15.984], [65682.2, 0.001], [66630.4, 2.198]]}
{"kind": "depth", "E": 1787080694299, "U": 11315373656623, "u": 11315373663030, "recv_ms": 1787080694247, "bids": [[1000.0, 35.96], [14182.1, 0.868], [14582.1, 3.332], [51746.0, 0.0], [58213.8, 0.003], [62094.8, 0.006], [63621.5, 4.319], [63919.1, 4.688], [64035.3, 0.032], [64675.5, 0.528]], "asks": [[64713.0, 0.169], [64713.4, 0.001], [65329.0, 0.263], [65684.8, 8.216]]}
{"kind": "depth", "E": 1787080694503, "U": 11315373670174, "u": 11315373676349, "recv_ms": 1787080694451, "bids": [[14182.1, 0.308], [14482.1, 0.154], [14582.1, 3.738], [58213.8, 0.003], [62094.8, 0.009], [63467.2, 0.002], [63614.8, 4.409], [63791.0, 14.884], [63841.2, 3.011], [63912.4, 4.728], [64067.6, 2.022], [64358.7, 1.09], [64649.3, 0.0], [64650.2, 0.5], [64664.9, 0.0], [64665.8, 0.926], [64675.5, 0.528], [64675.6, 0.425]], "asks": [[64697.4, 0.06], [64698.3, 1.089], [64701.1, 0.633], [64702.0, 0.061], [64702.3, 0.094], [64702.8, 0.892], [64703.5, 0.004], [65329.0, 0.263], [65691.7, 14.591], [65975.8, 0.018]]}
{"kind": "depth", "E": 1787080694605, "U": 11315373676479, "u": 11315373682782, "recv_ms": 1787080694555, "bids": [[1000.0, 35.81], [14182.1, 0.196], [14482.1, 0.392], [14582.1, 3.612], [58213.8, 0.003], [61447.9, 0.024], [62094.8, 0.006], [63451.9, 0.159], [63605.8, 0.0], [63682.1, 0.0], [63776.6, 12.903], [63873.6, 4.382], [63888.1, 0.782], [63977.1, 4.212], [64035.3, 0.032], [64486.4, 9.625], [64525.2, 4.081], [64542.2, 2.251], [64623.8, 0.003], [64632.9, 0.0], [64664.7, 1.25], [64670.3, 0.056], [64672.1, 0.618], [64675.9, 0.101], [64682.1, 8.513]], "asks": [[64682.2, 38.11], [64697.9, 0.734], [64705.2, 0.688], [64743.0, 0.063], [64743.2, 2.095], [64753.7, 0.101], [64754.7, 0.0], [64756.9, 40.449], [64759.9, 0.755], [64824.7, 9.183], [64841.7, 10.431], [65329.0, 0.263], [65465.3, 48.502], [65682.2, 0.001]]}
{"kind": "depth", "E": 1787080694707, "U": 11315373683217, "u": 11315373689616, "recv_ms": 1787080694655, "bids": [[14182.1, 0.07], [14482.1, 0.63], [14582.1, 3.5], [58213.8, 0.003], [62094.8, 0.009], [63472.5, 2.484], [63741.6, 6.812], [64035.3, 0.032], [64486.4, 13.29], [64525.2, 6.206], [64542.2, 3.307], [64627.3, 0.003], [64634.1, 0.006], [64649.3, 0.0], [64650.2, 0.5], [64661.6, 0.144], [64662.2, 0.0], [64664.7, 0.632], [64664.9, 0.0], [64665.7, 0.163], [64665.8, 0.926], [64665.9, 0.79], [64670.1, 0.296], [64672.1, 0.0], [64677.5, 0.034], [64677.8, 0.774], [64682.1, 8.514]], "asks": [[64686.6, 0.003], [64697.4, 0.06], [64697.9, 0.116], [64698.2, 0.315], [64698.3, 1.089], [64700.3, 0.223], [64701.1, 1.189], [64701.2, 0.002], [64702.0, 0.004], [64702.1, 0.061], [64702.3, 0.094], [64702.8, 0.351], [64703.5, 0.545], [64704.4, 2.865], [64705.2, 0.186], [64705.9, 0.064], [64880.5, 9.679], [65329.0, 0.263], [65490.7, 1.056], [65684.8, 9.28], [71150.4, 0.006]]}
{"kind": "depth", "E": 1787080694809, "U": 11315373689757, "u": 11315373695016, "recv_ms": 1787080694758, "bids": [[14182.1, 0.0], [14482.1, 0.91], [14582.1, 3.29], [58213.8, 0.003], [61447.9, 0.024], [62094.8, 0.006], [63000.4, 0.006], [63595.4, 2.508], [63682.1, 0.02], [63770.3, 3.05], [63873.6, 5.164], [64035.3, 0.032], [64218.8, 0.311], [64358.6, 0.009], [64358.7, 1.09], [64672.3, 0.097], [64675.5, 0.528], [64675.6, 0.155], [64677.7, 0.102], [64677.8, 0.233], [64677.9, 0.551], [64682.1, 8.474]], "asks": [[64682.2, 38.11], [64702.8, 0.892], [64703.5, 0.004], [64743.0, 0.002], [64743.2, 2.156], [64754.7, 40.448], [64756.9, 0.001], [65005.7, 0.001], [65329.0, 0.263], [65682.2, 0.021], [71150.4, 0.004]]}
{"kind": "depth", "E": 1787080694911, "U": 11315373695244, "u": 11315373699843, "recv_ms": 1787080694860, "bids": [[1000.0, 35.81], [14482.1, 1.274], [14582.1, 2.926], [51745.7, 0.0], [58213.8, 0.003], [63411.8, 0.958], [63791.0, 12.535], [64035.3, 0.032], [64341.3, 0.0], [64341.4, 0.494], [64672.3, 0.645], [64675.0, 0.223], [64675.3, 0.158], [64675.4, 0.201], [64675.5, 0.663], [64675.6, 0.155], [64677.9, 0.003]], "asks": [[64752.0, 6.98], [64754.7, 0.0], [64756.9, 40.449], [64880.4, 10.101], [64880.5, 0.001], [65329.0, 0.263], [65497.6, 20.741]]}
{"kind": "depth", "E": 1787080695013, "U": 11315373700078, "u": 11315373706476, "recv_ms": 1787080694962, "bids": [[14482.1, 1.638], [14582.1, 2.562], [58213.8, 0.003], [61447.9, 0.024], [62094.8, 0.009], [63388.5, 0.038], [63621.5, 3.22], [63682.1, 0.0], [63731.3, 1.114], [63873.6, 5.43], [63880.3, 23.233], [64035.3, 0.032], [64359.3, 0.11], [64486.4, 13.292], [64525.2, 6.207], [64542.2, 3.307], [64627.3, 0.007], [64634.1, 0.002], [64649.3, 0.0], [64650.2, 0.443], [64650.3, 0.212], [64663.8, 0.17], [64664.9, 0.926], [64665.8, 0.0], [64672.3, 0.104], [64675.0, 0.223], [64675.5, 0.663], [64677.9, 0.544], [64682.1, 8.288]], "asks": [[64701.6, 5.711], [64702.8, 0.351], [64703.5, 0.545], [64703.7, 0.128], [64752.0, 1.108], [64824.6, 5.399], [64824.7, 3.784], [64880.4, 9.675], [65329.0, 0.263], [65465.3, 48.288], [65627.0, 23.183], [65682.2, 0.001]]}
{"kind": "depth", "E": 1787080695115, "U": 11315373706539, "u": 11315373712319, "recv_ms": 1787080695066, "bids": [[14482.1, 1.988], [14582.1, 2.212], [58213.8, 0.003], [61448.0, 0.013], [61448.1, 0.012], [62094.8, 0.006], [63000.4, 0.005], [63573.4, 0.786], [63614.8, 5.508], [63694.1, 3.61], [63919.1, 3.751], [64035.3, 0.032], [64358.7, 1.09], [64610.8, 0.007], [64633.5, 0.632], [64633.9, 0.002], [64640.2, 0.081], [64649.6, 0.007], [64664.9, 0.0], [64665.8, 0.926], [64670.5, 0.232], [64672.3, 0.104], [64675.0, 0.088], [64675.5, 0.528], [64677.9, 0.544]], "asks": [[64691.8, 0.021], [64702.8, 0.892], [64703.5, 0.004], [64707.2, 0.008], [64723.4, 0.09], [64746.1, 0.003], [64754.7, 40.448], [64756.9, 0.001], [65329.0, 0.263], [65670.1, 0.019]]}
{"kind": "depth", "E": 1787080695217, "U": 11315373712372, "u": 11315373717413, "recv_ms": 1787080695168, "bids": [[1000.0, 35.81], [14482.1, 2.338], [14582.1, 1.862], [58213.8, 0.003], [61447.9, 0.024], [61666.9, 0.002], [62094.8, 0.009], [63388.5, 0.041], [63682.1, 0.02], [63694.1, 3.621], [63744.2, 19.863], [63776.6, 15.252], [64035.3, 0.032], [64358.6, 0.01], [64358.7, 1.245], [64542.2, 3.307], [64578.5, 0.003], [64591.8, 0.0], [64604.4, 4.331], [64611.1, 2.251], [64656.7, 0.275], [64672.3, 0.638], [64677.9, 0.01], [64682.1, 8.507]], "asks": [[64682.2, 38.111], [64702.8, 0.351], [64703.5, 0.545], [64723.3, 1.241], [64779.2, 1.269], [64779.3, 0.03], [64792.2, 0.01], [64811.6, 0.0], [64824.6, 5.399], [65005.7, 0.0], [65329.0, 0.263], [65682.2, 0.021]]}
{"kind": "depth", "E": 1787080695319, "U": 11315373717439, "u": 11315373724654, "recv_ms": 1787080695270, "bids": [[14482.1, 2.702], [14582.1, 1.498], [58213.8, 0.003], [61447.9, 0.024], [61448.1, 0.01], [61454.4, 0.068], [63912.4, 5.666], [64035.3, 0.032], [64578.4, 0.012], [64578.6, 1.745], [64578.7, 0.002], [64604.4, 4.328], [64610.9, 6.0], [64623.8, 0.0], [64633.5, 4.132], [64636.8, 1.714], [64649.7, 0.968], [64667.0, 1.804], [64672.4, 0.031], [64675.3, 0.157], [64675.6, 0.425], [64676.0, 0.156], [64677.7, 0.086], [64677.9, 0.003], [64680.5, 1.976], [64682.1, 8.468]], "asks": [[64682.2, 38.111], [64687.7, 0.004], [64702.8, 0.892], [64703.5, 0.004], [64707.3, 1.002], [64723.4, 3.59], [64727.5, 0.0], [64746.1, 6.003], [64759.9, 0.752], [64777.8, 0.778], [64779.1, 0.002], [64782.3, 2.893], [64792.2, 0.007], [65329.0, 0.263], [65620.1, 18.378], [65670.1, 0.03]]}
{"kind": "depth", "E": 1787080695421, "U": 11315373724762, "u": 11315373731078, "recv_ms": 1787080695373, "bids": [[14482.1, 3.052], [14582.1, 1.148], [58213.8, 0.003], [61448.1, 0.008], [61803.1, 0.013], [62094.8, 0.006], [63682.1, 0.0], [64035.3, 0.032], [64358.7, 1.245], [64575.6, 1.494], [64575.9, 2.332], [64627.3, 0.003], [64634.1, 0.006], [64650.0, 4.988], [64650.3, 0.155]], "asks": [[64791.5, 2.319], [64791.6, 0.512], [64880.4, 9.226], [65069.4, 0.0], [65329.0, 0.263], [65556.7, 0.0], [65682.2, 0.001]]}
{"kind": "depth", "E": 1787080695625, "U": 11315373737483, "u": 11315373743661, "recv_ms": 1787080695577, "bids": [[14382.1, 0.236], [14482.1, 3.71], [14582.1, 0.462], [51746.0, 0.0], [58213.8, 0.003], [58241.0, 0.002], [61447.9, 0.024], [62094.8, 0.006], [63682.1, 0.02], [64035.3, 0.032], [64617.4, 0.11], [64648.9, 0.945], [64669.2, 0.001], [64682.1, 8.471]], "asks": [[64698.4, 2.567], [64700.6, 10.0], [64754.7, 0.0], [64756.9, 40.703], [65052.5, 0.002], [65329.0, 0.263], [65458.8, 5.496], [65497.6, 20.483], [65682.2, 0.021], [65889.5, 2.952], [71150.5, 0.0]]}
{"kind": "depth", "E": 1787080695727, "U": 11315373743742, "u": 11315373749257, "recv_ms": 1787080695676, "bids": [[1000.0, 35.81], [14382.1, 0.418], [14482.1, 3.71], [14582.1, 0.28], [58213.8, 0.003], [58213.9, 0.006], [58241.0, 0.0], [61448.0, 0.011], [61448.1, 0.01], [62094.8, 0.009], [64035.3, 0.032], [64358.7, 1.245], [64525.2, 5.145], [64542.2, 2.779], [64646.6, 0.354], [64664.7, 1.25], [64665.7, 0.163], [64672.1, 0.618], [64675.6, 0.155], [64676.2, 0.274]], "asks": [[64697.9, 0.734], [64698.2, 0.315], [64704.4, 1.471], [64704.9, 0.105], [64705.3, 0.733], [64754.7, 0.0], [64756.9, 40.703], [64824.6, 5.399], [64841.6, 11.183], [64841.7, 0.021], [64880.4, 11.226], [65329.0, 0.263], [65451.9, 3.93], [65523.1, 2.193], [65792.5, 0.91], [65878.8, 0.984]]}
{"kind": "depth", "E": 1787080695829, "U": 11315373749479, "u": 11315373757285, "recv_ms": 1787080695778, "bids": [[1000.0, 35.81], [14382.1, 0.656], [14482.1, 3.584], [14582.1, 0.168], [58213.8, 0.003], [58213.9, 0.008], [61447.9, 0.024], [61448.0, 0.009], [61448.1, 0.012], [63682.1, 0.0], [63920.4, 9.137], [64035.3, 0.032], [64358.6, 0.009], [64486.4, 13.646], [64489.6, 3.08], [64525.2, 6.26], [64542.2, 3.337], [64616.4, 2.754], [64616.5, 0.285], [64627.3, 0.003], [64634.1, 0.006], [64676.2, 0.004], [64679.5, 0.0], [64680.0, 0.028], [64680.3, 0.027], [64682.1, 8.464]], "asks": [[64682.2, 38.132], [64689.0, 0.183], [64749.5, 3.823], [64750.0, 1.899], [64754.7, 40.702], [64756.9, 0.001], [64880.4, 9.251], [65005.7, 0.001], [65329.0, 0.263], [65682.2, 0.001], [65975.8, 0.015], [71183.5, 0.002]]}
{"kind": "depth", "E": 1787080695931, "U": 11315373757539, "u": 11315373765744, "recv_ms": 1787080695881, "bids": [[14382.1, 0.894], [14482.1, 3.472], [14582.1, 0.042], [51745.7, 0.0], [58213.8, 0.003], [61447.9, 0.025], [61454.4, 0.062], [62094.8, 0.006], [63731.9, 0.0], [63738.3, 0.096], [63920.4, 7.574], [64035.3, 0.032], [64341.4, 0.002], [64341.5, 0.507], [64517.0, 0.135], [64664.7, 0.632], [64665.5, 0.927], [64665.8, 0.0], [64672.1, 0.0], [64677.7, 0.002], [64680.5, 1.995], [64682.1, 8.189]], "asks": [[64695.0, 0.39], [64695.7, 0.1], [64696.0, 0.147], [64697.9, 0.116], [64752.0, 7.018], [65329.0, 0.263], [65532.1, 0.777], [65781.8, 5.452], [71150.4, 0.006], [71183.5, 0.0]]}
{"kind": "depth", "E": 1787080696033, "U": 11315373765862, "u": 11315373773125, "recv_ms": 1787080695983, "bids": [[1000.0, 35.81], [14382.1, 1.216], [14482.1, 3.192], [14582.1, 0.0], [58213.8, 0.003], [61447.9, 0.024], [61602.0, 0.006], [62094.8, 0.009], [63682.1, 0.02], [64035.3, 0.032], [64358.7, 1.245], [64670.5, 0.237], [64676.2, 0.004], [64682.0, 0.044], [64682.1, 8.19]], "asks": [[64713.1, 0.155], [64752.0, 1.108], [64754.7, 41.108], [64756.9, 0.001], [65329.0, 0.263], [65682.2, 0.021], [71150.4, 0.008]]}
{"kind": "depth", "E": 1787080696135, "U": 11315373773196, "u": 11315373780572, "recv_ms": 1787080696085, "bids": [[1000.0, 35.81], [14382.1, 1.566], [14482.1, 2.842], [58213.8, 0.003], [62094.8, 0.006], [63682.1, 0.0], [63694.1, 3.613], [63731.3, 2.445], [63758.9, 0.0], [63760.6, 0.001], [63905.9, 19.135], [64035.3, 0.032], [64610.8, 0.008], [64640.2, 0.082], [64670.1, 0.296], [64670.5, 0.232], [64676.2, 0.004]], "asks": [[64682.2, 38.149], [64705.3, 0.115], [65329.0, 0.265], [65603.7, 0.0], [65605.5, 0.0], [65670.2, 0.009], [65682.2, 0.001]]}
{"kind": "depth", "E": 1787080696237, "U": 11315373780627, "u": 11315373787700, "recv_ms": 1787080696191, "bids": [[14382.1, 1.916], [14482.1, 2.492], [58213.8, 0.003], [61447.9, 0.024], [62094.8, 0.009], [63694.1, 3.621], [63758.8, 2.337], [63760.6, 0.009], [64035.3, 0.032], [64358.6, 0.008], [64563.9, 0.0], [64564.1, 10.705], [64611.2, 0.059], [64627.5, 0.0], [64629.8, 0.024], [64630.3, 1.426], [64634.1, 0.002], [64645.8, 0.001], [64650.6, 0.001], [64662.0, 0.141], [64674.5, 0.002], [64675.0, 0.088], [64675.5, 0.528], [64675.8, 0.127], [64676.2, 0.004], [64677.8, 0.317], [64678.8, 0.086], [64679.1, 0.085], [64682.1, 8.416]], "asks": [[64682.2, 33.03], [64682.8, 0.003], [64684.2, 0.017], [64684.4, 0.016], [64684.6, 0.015], [64685.0, 0.55], [64685.2, 5.342], [64687.8, 0.491], [64693.9, 0.09], [64694.9, 0.09], [64695.0, 0.382], [64695.7, 0.1], [64696.1, 0.51], [64702.8, 0.351], [64703.5, 0.545], [64704.5, 2.361], [64746.9, 0.041], [64753.6, 1.424], [64760.1, 0.001], [64811.6, 0.0], [64817.8, 5.753], [65329.0, 0.263], [65605.4, 0.008], [65670.1, 0.038], [65975.8, 0.018]]}
{"kind": "depth", "E": 1787080696339, "U": 11315373787881, "u": 11315373797262, "recv_ms": 1787080696287, "bids": [[1000.0, 35.81], [14382.1, 2.28], [14482.1, 2.128], [51746.0, 0.0], [58213.8, 0.003], [61447.9, 0.024], [63686.2, 11.763], [64035.3, 0.032], [64358.7, 1.245], [64634.3, 0.005], [64672.2, 0.471], [64672.4, 0.031], [64673.9, 0.585], [64676.2, 0.004], [64682.1, 8.415]], "asks": [[64687.6, 0.494], [64698.3, 0.164], [64698.6, 1.242], [64782.2, 1.6], [65005.7, 0.002], [65206.5, 5.968], [65329.0, 0.263], [65458.4, 13.47]]}
{"kind": "depth", "E": 1787080696441, "U": 11315373798367, "u": 11315373807217, "recv_ms": 1787080696390, "bids": [[1000.0, 35.81], [14382.1, 2.63], [14482.1, 1.778], [51746.0, 0.0], [58213.8, 0.003], [61447.9, 0.024], [62094.8, 0.006], [63599.3, 0.808], [63682.1, 0.02], [64035.3, 0.032], [64649.6, 0.064], [64650.0, 4.931], [64665.2, 0.002], [64665.5, 0.001], [64666.0, 4.029], [64670.3, 0.056], [64672.2, 0.008], [64672.3, 0.097], [64672.4, 1.576], [64673.9, 0.044], [64674.9, 0.426], [64675.6, 0.425], [64679.5, 0.084], [64682.0, 0.045], [64682.1, 8.416]], "asks": [[64682.2, 33.139], [64682.4, 0.002], [64688.3, 0.044], [64697.8, 0.002], [64698.4, 3.492], [64698.6, 0.317], [64701.6, 0.711], [64702.3, 0.094], [64703.5, 0.545], [64704.2, 0.465], [64704.3, 0.28], [64713.1, 0.001], [64713.2, 0.384], [64749.5, 3.832], [64760.1, 0.0], [65329.0, 0.263], [65405.7, 1.255], [65603.6, 0.009], [65643.7, 2.891], [65682.2, 0.021]]}
{"kind": "depth", "E": 1787080696543, "U": 11315373807553, "u": 11315373814702, "recv_ms": 1787080696490, "bids": [[14382.1, 2.994], [14482.1, 1.414], [58213.8, 0.003], [61447.9, 0.024], [62094.8, 0.009], [64035.3, 0.032], [64542.2, 0.0], [64600.0, 14.58], [64627.5, 0.004], [64634.3, 0.001], [64682.1, 8.427]], "asks": [[64682.2, 33.137], [64682.4, 0.001], [64682.5, 0.116], [64702.8, 0.892], [64703.5, 0.004], [64824.6, 0.0], [65199.7, 3.978], [65329.0, 0.263], [65490.7, 1.398]]}
{"kind": "depth", "E": 1787080696645, "U": 11315373814826, "u": 11315373820588, "recv_ms": 1787080696592, "bids": [[1000.0, 35.81], [14382.1, 3.358], [14482.1, 1.05], [58213.8, 0.003], [61447.9, 0.025], [62094.8, 0.006], [63388.5, 0.044], [63589.0, 2.545], [63679.5, 9.882], [63682.1, 0.0], [63763.6, 2.348], [64035.3, 0.032], [64358.7, 1.245], [64525.2, 0.001], [64526.5, 1.112], [64585.0, 0.079], [64636.8, 1.717], [64649.2, 0.015], [64649.3, 0.002], [64649.4, 0.083], [64652.6, 0.007], [64652.7, 0.002], [64652.8, 0.391], [64659.7, 0.03], [64666.6, 0.665], [64674.0, 0.624]], "asks": [[64682.2, 33.029], [64699.8, 2.942], [64702.8, 0.351], [64703.5, 0.545], [64707.2, 0.626], [64727.5, 0.003], [64841.6, 0.773], [65329.0, 0.263], [65501.4, 2.287], [65633.0, 3.883], [65682.2, 0.001]]}
{"kind": "depth", "E": 1787080696747, "U": 11315373820618, "u": 11315373825904, "recv_ms": 1787080696694, "bids": [[1000.0, 35.81], [14382.1, 3.708], [14482.1, 0.7], [58213.8, 0.003], [61447.9, 0.024], [63873.6, 5.695], [64035.3, 0.032], [64486.3, 13.288], [64486.4, 0.005], [64489.6, 1.185], [64525.1, 6.19], [64526.5, 1.959], [64542.1, 3.523], [64665.4, 0.154], [64665.7, 0.163], [64666.0, 4.091], [64670.3, 0.056], [64672.1, 1.128], [64672.3, 0.004], [64672.4, 0.541], [64674.0, 0.006], [64675.4, 0.202], [64675.6, 0.425], [64676.0, 0.155], [64676.1, 0.0], [64676.2, 0.004], [64677.7, 0.002]], "asks": [[64682.2, 33.028], [64698.2, 0.315], [64749.5, 3.823], [64770.6, 0.375], [64824.6, 5.399], [64841.6, 11.183], [64880.4, 9.695], [65329.0, 0.263], [65458.4, 13.684], [65975.8, 0.015]]}
{"kind": "depth", "E": 1787080696849, "U": 11315373826148, "u": 11315373833731, "recv_ms": 1787080696796, "bids": [[14282.1, 0.056], [14382.1, 3.96], [14482.1, 0.392], [58213.8, 0.003], [61447.9, 0.024], [62094.8, 0.009], [63682.1, 0.02], [63754.6, 8.696], [63770.3, 2.816], [64035.3, 0.032], [64113.7, 0.002], [64358.6, 0.009], [64542.1, 0.216]], "asks": [[64682.2, 33.028], [64682.5, 0.032], [64824.6, 0.0], [65005.7, 0.001], [65329.0, 0.263], [65490.7, 1.512], [65682.2, 0.021]]}
{"kind": "depth", "E": 1787080696951, "U": 11315373833813, "u": 11315373839271, "recv_ms": 1787080696899, "bids": [[1000.0, 35.81], [14282.1, 0.266], [14382.1, 3.89], [14482.1, 0.252], [51745.7, 0.0], [58213.8, 0.003], [62094.8, 0.006], [63388.5, 0.041], [64035.3, 0.032], [64129.8, 1.093], [64341.4, 0.494], [64341.5, 0.015], [64358.7, 1.255], [64542.1, 3.554], [64578.6, 10.0], [64578.7, 3.248], [64664.9, 0.0], [64665.8, 0.926], [64666.0, 3.165], [64675.6, 0.425]], "asks": [[64697.3, 0.027], [64698.3, 1.089], [64698.4, 2.567], [64701.1, 1.189], [64702.0, 0.061], [64702.1, 0.004], [64702.3, 0.094], [64702.8, 0.892], [64703.5, 0.004], [64723.3, 1.645], [64752.0, 7.078], [64824.6, 5.399], [64880.4, 9.247], [65329.0, 0.263], [65659.3, 17.999], [65724.0, 5.784]]}
{"kind": "depth", "E": 1787080697053, "U": 11315373839462, "u": 11315373849062, "recv_ms": 1787080697001, "bids": [[1000.0, 35.81], [14282.1, 0.504], [14382.1, 3.764], [14482.1, 0.14], [58213.8, 0.003], [62094.8, 0.009], [63682.1, 0.0], [63744.2, 19.981], [64035.3, 0.032], [64578.7, 3.24], [64578.8, 0.164], [64617.4, 0.109], [64670.5, 0.232], [64675.6, 0.425]], "asks": [[64682.2, 32.896], [64746.9, 0.04], [64880.4, 9.242], [65329.0, 0.263], [65682.2, 0.001]]}
{"kind": "depth", "E": 1787080697155, "U": 11315373849080, "u": 11315373855856, "recv_ms": 1787080697107, "bids": [[14282.1, 0.742], [14382.1, 3.652], [14482.1, 0.014], [51746.0, 0.0], [58213.8, 0.003], [61447.9, 0.024], [62094.8, 0.006], [64035.3, 0.032], [64610.8, 0.009], [64627.5, 0.0], [64634.3, 0.005], [64640.2, 0.083], [64646.6, 0.018], [64649.6, 0.007], [64650.2, 0.5], [64650.4, 0.965], [64651.0, 0.0], [64659.7, 0.032], [64659.8, 0.005], [64660.9, 0.906], [64661.6, 0.028], [64661.8, 0.0], [64662.3, 5.177], [64662.4, 2.388], [64663.3, 0.353], [64664.9, 0.0], [64665.8, 0.0], [64666.0, 4.091], [64670.1, 0.296], [64672.2, 0.549], [64672.4, 0.0], [64673.9, 0.044], [64674.9, 0.426], [64675.3, 0.073], [64675.5, 0.528], [64675.6, 0.155], [64675.8, 0.127], [64680.0, 0.112], [64681.6, 0.004], [64682.1, 8.454]], "asks": [[64682.2, 32.896], [64682.9, 0.002], [64687.2, 0.016], [64691.8, 0.02], [64697.5, 0.002], [64698.3, 1.089], [64698.4, 2.567], [64699.2, 0.012], [64701.1, 0.633], [64701.2, 0.002], [64702.0, 0.061], [64702.1, 0.56], [64702.2, 0.01], [64702.8, 0.351], [64702.9, 0.659], [64703.4, 0.852], [64703.5, 0.004], [64704.3, 0.28], [64705.2, 0.07], [64706.1, 0.351], [65329.0, 0.263], [65652.4, 0.593], [65717.1, 4.714], [65975.8, 0.012]]}
{"kind": "depth", "E": 1787080697257, "U": 11315373856084, "u": 11315373861602, "recv_ms": 1787080697205, "bids": [[1000.0, 35.81], [14282.1, 1.078], [14382.1, 3.33], [14482.1, 0.0], [51746.0, 0.0], [58213.8, 0.003], [61447.9, 0.024], [63682.1, 0.02], [63686.2, 10.665], [63855.7, 1.72], [64035.3, 0.032], [64100.0, 73.194], [64358.7, 1.245], [64640.2, 0.084], [64665.9, 0.78], [64670.0, 1.507], [64670.1, 0.142], [64675.8, 0.127], [64682.1, 8.447]], "asks": [[64685.0, 0.009], [64687.2, 0.015], [64688.1, 1.419], [64689.1, 0.002], [64690.7, 0.022], [64693.9, 0.631], [64701.6, 0.64], [64749.5, 3.832], [64775.6, 0.126], [64811.6, 0.0], [65005.7, 0.0], [65279.3, 0.0], [65329.0, 0.263], [65682.2, 0.021]]}
{"kind": "depth", "E": 1787080697359, "U": 11315373861624, "u": 11315373866729, "recv_ms": 1787080697306, "bids": [[1000.0, 35.81], [14282.1, 1.442], [14382.1, 2.966], [58213.8, 0.003], [61447.9, 0.024], [62094.8, 0.009], [63910.4, 0.0], [64035.3, 0.032], [64078.0, 9.472], [64358.6, 0.01], [64525.1, 0.001], [64526.5, 1.112], [64542.1, 0.216], [64665.9, 0.79], [64674.9, 0.426], [64675.8, 0.127], [64679.6, 0.001], [64682.1, 8.445]], "asks": [[64682.2, 32.896], [64683.0, 0.084], [64699.0, 0.127], [64824.6, 0.0], [64841.6, 0.773], [65329.0, 0.263], [65490.7, 1.77], [65497.6, 20.141], [66299.3, 0.609]]}
{"kind": "depth", "E": 1787080697461, "U": 11315373866891, "u": 11315373872383, "recv_ms": 1787080697409, "bids": [[14282.1, 1.792], [14382.1, 2.616], [58213.8, 0.003], [62094.8, 0.006], [63679.5, 10.98], [63682.1, 0.0], [63841.2, 3.95], [64035.3, 0.032], [64358.7, 1.245], [64486.3, 0.004], [64675.8, 0.127], [64680.0, 0.028]], "asks": [[64682.2, 32.866], [64686.9, 0.092], [64880.4, 0.001], [65329.0, 0.263], [65682.2, 0.001]]}
{"kind": "depth", "E": 1787080697563, "U": 11315373872634, "u": 11315373877798, "recv_ms": 1787080697510, "bids": [[1000.0, 35.81], [14282.1, 2.142], [14382.1, 2.266], [51746.0, 0.0], [58213.8, 0.003], [61448.1, 0.01], [62094.8, 0.009], [62101.4, 0.005], [62108.9, 0.003], [63388.5, 0.044], [63754.6, 8.579], [64035.3, 0.032], [64067.6, 2.723], [64486.3, 13.649], [64525.1, 6.262], [64542.1, 3.555], [64645.8, 0.015], [64649.4, 0.14], [64650.2, 0.443], [64660.1, 0.928], [64660.9, 0.349], [64661.3, 0.002], [64661.6, 0.144], [64661.7, 0.507], [64662.1, 0.142], [64662.3, 0.177], [64662.4, 2.272], [64664.9, 0.926], [64665.9, 0.35], [64666.0, 3.165], [64667.5, 0.141], [64671.3, 0.006], [64674.9, 0.426], [64675.8, 0.262], [64679.5, 0.0], [64682.1, 8.425]], "asks": [[64682.3, 0.093], [64690.3, 0.157], [64702.0, 0.061], [64702.3, 0.094], [64703.4, 0.311], [64703.5, 0.545], [64704.4, 1.587], [64706.1, 0.235], [64824.6, 5.399], [64841.6, 11.183], [64880.4, 8.818], [65307.3, 6.663], [65329.0, 0.263], [66619.9, 0.003]]}
{"kind": "depth", "E": 1787080697665, "U": 11315373877987, "u": 11315373883543, "recv_ms": 1787080697612, "bids": [[1000.0, 35.81], [14282.1, 2.506], [14382.1, 1.902], [51746.0, 0.0], [58213.8, 0.003], [61447.9, 0.024], [62094.8, 0.006], [62625.2, 0.014], [63682.1, 0.02], [63905.9, 20.698], [64035.3, 0.034], [64623.6, 0.034], [64627.7, 0.039], [64643.2, 2.715], [64662.4, 0.045], [64665.9, 0.36], [64666.6, 0.047], [64675.3, 0.157], [64675.6, 0.155], [64675.7, 0.369], [64675.8, 0.127], [64677.4, 0.398], [64677.8, 0.085], [64678.2, 0.233], [64679.1, 0.001]], "asks": [[64682.2, 32.896], [64686.9, 0.062], [64690.5, 0.312], [64691.0, 0.903], [64702.8, 0.892], [64703.5, 0.004], [64749.5, 3.823], [64880.4, 9.267], [65296.7, 1.459], [65329.0, 0.263], [65329.1, 0.101], [65682.2, 0.021]]}
{"kind": "depth", "E": 1787080697767, "U": 11315373883571, "u": 11315373888324, "recv_ms": 1787080697716, "bids": [[14282.1, 2.87], [14382.1, 1.538], [51746.0, 0.0], [58213.8, 0.003], [61447.9, 0.024], [63744.2, 20.099], [63912.6, 38.896], [64035.3, 0.032], [64102.8, 0.0], [64164.6, 3.42], [64358.7, 1.255], [64590.2, 0.013], [64597.6, 0.028], [64660.1, 0.371], [64660.6, 0.558], [64661.2, 0.007], [64661.6, 0.028], [64661.7, 0.5], [64662.2, 0.116], [64665.7, 0.163], [64672.1, 1.051], [64672.3, 0.081], [64674.9, 0.51], [64675.3, 0.158], [64675.4, 0.201], [64675.6, 0.29], [64675.7, 0.369], [64675.8, 0.127], [64678.8, 0.002], [64679.7, 0.009], [64680.6, 0.142]], "asks": [[64682.2, 37.545], [64682.8, 0.004], [64684.2, 0.001], [64684.4, 0.015], [64684.6, 0.018], [64684.8, 0.004], [64685.0, 0.018], [64685.4, 0.182], [64687.8, 0.396], [64692.1, 0.619], [64693.8, 0.024], [64695.0, 0.382], [64695.7, 0.108], [64696.1, 0.502], [64698.2, 0.315], [64699.4, 0.619], [64699.8, 2.324], [64700.9, 0.565], [64702.1, 0.004], [64704.4, 1.471], [64705.0, 0.261], [64707.2, 0.008], [64746.9, 0.031], [64754.7, 0.0], [64756.9, 41.326], [65012.4, 3.38], [65329.0, 0.263], [65691.7, 13.527]]}
{"kind": "depth", "E": 1787080697869, "U": 11315373888461, "u": 11315373893635, "recv_ms": 1787080697819, "bids": [[1000.0, 35.81], [14282.1, 3.22], [14382.1, 1.188], [58213.8, 0.003], [61447.9, 0.024], [62094.8, 0.009], [63682.1, 0.0], [64035.3, 0.032], [64358.6, 0.009], [64525.1, 6.191], [64542.1, 3.524], [64636.8, 1.717], [64659.7, 0.028], [64675.2, 0.281], [64675.5, 0.528], [64675.6, 0.155], [64675.7, 0.369], [64675.8, 0.127], [64675.9, 0.236], [64682.1, 8.334]], "asks": [[64682.2, 37.587], [64685.2, 5.437], [64685.4, 0.087], [64727.5, 0.003], [64752.0, 1.108], [64754.7, 41.325], [64756.9, 0.001], [64824.6, 5.399], [64841.6, 11.183], [64927.8, 0.349], [65329.0, 0.263], [65682.2, 0.001]]}
{"kind": "depth", "E": 1787080697971, "U": 11315373893819, "u": 11315373899322, "recv_ms": 1787080697921, "bids": [[1000.0, 35.81], [14282.1, 3.584], [14382.1, 0.824], [51745.7, 0.0], [58213.8, 0.003], [61447.9, 0.024], [62094.8, 0.006], [63599.3, 0.023], [63694.0, 7.296], [64035.3, 0.032], [64099.7, 1.325], [64341.3, 0.492], [64341.4, 0.002], [64526.5, 1.959], [64542.1, 2.996], [64627.5, 0.004], [64634.3, 0.001], [64660.1, 0.928], [64660.6, 0.001], [64661.4, 0.116], [64662.2, 0.0], [64675.8, 0.127], [64675.9, 0.236], [64676.0, 0.155], [64676.1, 0.0], [64678.3, 0.084], [64682.1, 8.438]], "asks": [[64682.2, 37.593], [64701.6, 0.711], [64752.0, 1.108], [64754.7, 0.0], [64756.9, 41.326], [64824.6, 5.399], [64880.4, 10.815], [65005.6, 1.694], [65005.7, 0.001], [65329.0, 0.263], [65750.4, 0.001]]}
{"kind": "depth", "E": 1787080698073, "U": 11315373899496, "u": 11315373904788, "recv_ms": 1787080698023, "bids": [[14182.1, 0.084], [14282.1, 3.78], [14382.1, 0.544], [58213.8, 0.003], [62094.8, 0.009], [63682.1, 0.02], [63905.9, 21.948], [64035.3, 0.032], [64358.7, 1.245], [64649.4, 0.083], [64650.3, 0.212], [64664.9, 0.0], [64665.8, 0.926], [64670.5, 0.232], [64675.2, 0.173], [64675.9, 0.101], [64676.0, 0.155], [64676.1, 0.0]], "asks": [[64702.8, 0.351], [64703.5, 0.545], [64707.3, 0.002], [64754.7, 41.342], [64756.9, 0.001], [64880.4, 6.855], [65329.0, 0.263], [65682.2, 0.021], [65684.8, 10.344]]}
{"kind": "depth", "E": 1787080698175, "U": 11315373904839, "u": 11315373910408, "recv_ms": 1787080698123, "bids": [[1000.0, 35.81], [14182.1, 0.322], [14282.1, 3.654], [14382.1, 0.432], [58213.8, 0.003], [63679.5, 12.078], [64035.3, 0.032], [64622.6, 0.002], [64622.9, 0.003], [64623.2, 0.0], [64623.6, 0.002], [64623.9, 0.628], [64640.2, 0.085], [64640.5, 3.209], [64640.6, 0.037], [64640.8, 0.0], [64641.1, 0.0], [64641.5, 0.001], [64641.8, 0.031], [64649.8, 0.074], [64650.3, 0.155], [64655.4, 0.329], [64655.5, 0.019], [64655.6, 0.058], [64655.7, 0.17], [64655.8, 0.028], [64655.9, 0.47], [64656.0, 1.407], [64656.1, 0.006], [64656.2, 1.342], [64656.4, 0.038], [64657.5, 0.003], [64658.0, 1.263], [64667.1, 0.141], [64672.1, 1.011], [64672.3, 0.121], [64675.0, 0.018], [64675.1, 0.842], [64675.2, 0.033], [64675.3, 0.088], [64675.4, 0.001], [64675.5, 0.328], [64675.6, 0.355], [64675.7, 0.169], [64675.8, 0.057], [64675.9, 0.001], [64676.0, 0.085], [64676.3, 0.085], [64676.4, 0.033], [64676.6, 0.0], [64676.9, 0.006], [64677.2, 0.001], [64677.5, 0.002]], "asks": [[64690.7, 0.023], [64694.4, 0.038], [64694.7, 0.004], [64695.0, 0.34], [64695.2, 1.141], [64695.4, 0.002], [64695.7, 0.066], [64696.0, 0.042], [64696.1, 0.251], [64696.2, 0.161], [64696.3, 0.0], [64696.4, 0.001], [64696.5, 0.464], [64696.6, 0.617], [64696.7, 2.4], [64696.8, 0.0], [64696.9, 0.154], [64702.8, 0.892], [64703.5, 0.004], [64704.2, 0.467], [64708.1, 1.82], [64712.3, 0.121], [64712.6, 0.002], [64712.9, 0.003], [64713.1, 0.043], [64713.3, 0.0], [64713.6, 0.007], [64714.0, 0.016], [64714.4, 1.978], [64715.6, 0.494], [64715.7, 0.025], [64715.8, 0.001], [64715.9, 0.001], [64716.0, 0.005], [64716.1, 0.073], [64716.2, 0.031], [64716.3, 0.163], [64716.4, 0.001], [64716.5, 0.009], [64730.2, 0.0], [64730.5, 0.002], [64730.8, 0.002], [64731.0, 0.108], [64731.1, 0.004], [64731.5, 0.056], [64754.7, 0.0], [64756.9, 41.343], [64880.4, 9.289], [65329.0, 0.263], [65394.4, 0.855], [65497.6, 19.913]]}
{"kind": "depth", "E": 1787080698277, "U": 11315373910545, "u": 11315373915350, "recv_ms": 1787080698226, "bids": [[1000.0, 35.81], [14182.1, 0.56], [14282.1, 3.528], [14382.1, 0.32], [51746.0, 0.0], [58213.8, 0.003], [61447.9, 0.024], [62094.8, 0.006], [63682.1, 0.0], [63694.1, 3.611], [64035.3, 0.032], [64365.5, 3.669], [64641.6, 1.095], [64641.9, 0.361], [64646.6, 0.117], [64649.2, 0.07], [64649.3, 0.0], [64649.4, 0.081], [64649.8, 0.017], [64652.6, 0.005], [64652.7, 0.0], [64652.8, 0.389], [64664.9, 0.926], [64665.8, 0.0], [64674.9, 0.654], [64675.0, 0.019], [64675.2, 0.141], [64675.3, 0.157], [64675.6, 0.455], [64675.8, 0.154], [64675.9, 0.171], [64676.0, 0.185], [64677.4, 0.43], [64677.7, 0.034], [64680.3, 0.004]], "asks": [[64682.2, 37.593], [64692.1, 0.001], [64693.9, 0.669], [64694.2, 0.037], [64695.6, 0.529], [64695.7, 0.287], [64695.8, 0.679], [64696.0, 0.172], [64696.3, 0.091], [64697.3, 0.952], [64698.3, 0.164], [64699.4, 0.001], [64701.1, 0.69], [64701.7, 5.004], [64702.0, 0.004], [64704.2, 0.465], [64711.8, 0.669], [64712.1, 1.282], [64713.5, 0.476], [64715.3, 0.536], [64715.4, 0.163], [64715.6, 0.624], [64715.9, 0.092], [64729.7, 0.052], [64730.0, 0.058], [64811.6, 0.0], [65329.0, 0.263], [65670.1, 0.028], [65682.2, 0.001], [65739.8, 8.203], [65975.8, 0.009]]}
{"kind": "depth", "E": 1787080698583, "U": 11315373928166, "u": 11315373934572, "recv_ms": 1787080698532, "bids": [[1000.0, 35.81], [14182.1, 1.526], [14282.1, 2.674], [51746.0, 0.0], [58213.8, 0.003], [61447.9, 0.025], [62094.8, 0.009], [63791.0, 10.187], [64035.3, 0.032], [64048.2, 1.032], [64067.1, 0.783], [64490.7, 0.001], [64525.8, 0.179], [64623.7, 0.056], [64624.0, 0.236], [64660.0, 0.164], [64664.9, 0.0], [64666.2, 1.621], [64672.2, 0.008], [64673.9, 0.585], [64675.0, 0.018], [64675.1, 0.912], [64675.2, 0.247], [64675.4, 0.142], [64675.8, 0.154], [64675.9, 0.171], [64676.0, 0.32], [64680.4, 0.024], [64682.1, 8.657]], "asks": [[64682.2, 37.592], [64684.6, 0.015], [64684.8, 0.007], [64690.0, 0.005], [64690.5, 0.003], [64690.7, 0.332], [64696.2, 0.329], [64696.4, 0.162], [64696.6, 0.154], [64697.6, 0.492], [64698.1, 0.32], [64698.2, 0.315], [64698.7, 0.989], [64698.8, 0.474], [64702.0, 0.004], [64702.5, 0.062], [64702.8, 0.351], [64703.5, 0.545], [64705.0, 0.145], [64705.8, 0.117], [64715.8, 0.169], [64716.1, 0.15], [64718.3, 0.002], [64760.9, 0.019], [65329.0, 0.263], [65652.4, 0.972]]}
{"kind": "depth", "E": 1787080698685, "U": 11315373934651, "u": 11315373943300, "recv_ms": 1787080698637, "bids": [[14182.1, 1.876], [14282.1, 2.324], [51746.0, 0.0], [58213.8, 0.003], [61447.9, 0.024], [63682.1, 0.0], [63763.6, 2.582], [64035.3, 0.032], [64358.7, 1.876], [64552.7, 0.023], [64623.1, 0.344], [64623.8, 0.003], [64627.5, 0.0], [64634.3, 0.005], [64655.7, 0.24], [64656.0, 1.507], [64656.2, 1.442], [64656.3, 0.216], [64658.1, 0.264], [64672.0, 1.609], [64672.2, 0.549], [64672.6, 0.472], [64673.9, 0.044], [64675.2, 0.103], [64675.4, 0.25], [64675.8, 0.424], [64676.0, 0.185], [64678.2, 0.001], [64678.4, 0.24], [64678.9, 0.003], [64682.1, 8.658]], "asks": [[64682.2, 37.614], [64683.6, 0.002], [64684.1, 0.007], [64685.0, 0.018], [64688.3, 0.002], [64688.7, 0.076], [64691.0, 1.803], [64692.4, 0.003], [64695.7, 0.279], [64696.2, 0.337], [64696.6, 0.146], [64697.8, 0.01], [64740.8, 1.258], [64759.9, 0.755], [64760.9, 0.0], [64775.6, 0.026], [64841.5, 10.432], [64841.6, 0.773], [64844.4, 0.0], [64880.4, 8.758], [64883.2, 0.005], [64883.3, 0.002], [65329.0, 0.263], [65329.1, 0.1], [65682.2, 0.001]]}
{"kind": "depth", "E": 1787080698787, "U": 11315373943308, "u": 11315373953066, "recv_ms": 1787080698738, "bids": [[1000.0, 35.81], [14182.1, 2.24], [14282.1, 1.96], [58213.8, 0.003], [61447.9, 0.024], [61448.1, 0.008], [62094.8, 0.006], [62101.4, 0.004], [63694.0, 6.198], [63776.6, 17.6], [64035.3, 0.032], [64623.4, 0.85], [64627.7, 0.025], [64655.6, 0.128], [64655.7, 0.31], [64655.9, 0.57], [64656.1, 0.106], [64656.5, 0.072], [64657.7, 0.266], [64660.1, 0.371], [64661.0, 0.582], [64661.4, 0.0], [64662.5, 0.128], [64664.7, 1.25], [64665.7, 0.163], [64672.0, 2.227], [64672.4, 0.309], [64672.6, 0.163], [64675.0, 0.018], [64675.2, 0.175], [64675.4, 0.142], [64675.8, 0.424], [64682.1, 8.657]], "asks": [[64682.2, 37.587], [64684.8, 0.004], [64685.0, 0.021], [64687.0, 0.427], [64696.6, 0.154], [64697.6, 0.492], [64697.8, 0.002], [64697.9, 0.734], [64698.2, 0.315], [64700.9, 0.009], [64701.2, 0.558], [64704.2, 0.467], [64705.2, 0.688], [64841.5, 0.022], [64844.4, 7.548], [64880.4, 0.001], [64883.2, 11.938], [65329.0, 0.263]]}
{"kind": "depth", "E": 1787080698889, "U": 11315373953347, "u": 11315373961893, "recv_ms": 1787080698838, "bids": [[1000.0, 35.81], [14182.1, 2.59], [14282.1, 1.61], [51745.7, 0.0], [58213.8, 0.003], [61447.9, 0.024], [62094.8, 0.009], [63682.1, 0.02], [64035.3, 0.032], [64564.1, 6.84], [64565.8, 3.865], [64575.9, 0.013], [64576.3, 2.323], [64611.1, 2.297], [64611.2, 0.013], [64655.8, 0.098], [64656.1, 0.176], [64660.0, 0.166], [64674.9, 0.426], [64675.2, 0.103], [64675.4, 0.285], [64675.8, 0.425], [64677.7, 0.806], [64678.8, 0.086], [64679.2, 0.084], [64680.0, 0.032], [64681.6, 0.003]], "asks": [[64682.2, 37.577], [64682.3, 0.009], [64688.2, 2.71], [64690.8, 2.852], [64704.2, 0.465], [64753.5, 0.094], [64753.6, 1.378], [64791.3, 2.319], [64791.5, 0.0], [64817.8, 5.753], [64841.5, 10.432], [64844.4, 0.0], [64880.4, 7.131], [64883.2, 0.005], [65329.0, 0.263], [65458.8, 4.581], [65682.2, 0.021], [65975.8, 0.012]]}
{"kind": "depth", "E": 1787080698991, "U": 11315373961976, "u": 11315373969878, "recv_ms": 1787080698938, "bids": [[14182.1, 2.954], [14282.1, 1.246], [58213.8, 0.003], [61448.1, 0.006], [62094.8, 0.006], [63880.3, 22.999], [64035.3, 0.032], [64341.3, 0.0], [64341.4, 0.494], [64358.7, 1.876], [64643.2, 2.701], [64655.5, 0.089], [64655.8, 0.168], [64661.1, 1.313], [64675.2, 0.139], [64675.4, 0.249], [64675.8, 0.425]], "asks": [[64696.6, 0.146], [64697.8, 0.01], [64755.9, 7.795], [65005.7, 0.001], [65268.3, 0.044], [65329.0, 0.263]]}
{"kind": "depth", "E": 1787080699093, "U": 11315373970010, "u": 11315373978084, "recv_ms": 1787080699043, "bids": [[1000.0, 35.81], [14182.1, 3.318], [14282.1, 0.882], [58213.8, 0.003], [61447.9, 0.024], [61448.1, 0.004], [62094.8, 0.009], [63388.5, 0.041], [63679.5, 13.176], [63682.1, 0.0], [63844.0, 0.098], [63896.9, 0.782], [64035.3, 0.032], [64358.6, 0.009], [64576.3, 0.004], [64576.5, 3.322], [64604.4, 4.331], [64623.8, 0.0], [64636.8, 1.714], [64645.8, 0.001], [64661.2, 0.0], [64662.0, 0.139], [64662.1, 0.149], [64662.8, 0.321], [64668.6, 0.004], [64669.6, 0.03], [64670.0, 1.353], [64670.3, 0.056], [64670.4, 0.392], [64670.5, 0.232], [64672.0, 1.609], [64672.1, 0.47], [64672.2, 0.549], [64672.3, 0.113], [64673.9, 1.822], [64674.0, 0.014], [64675.2, 0.103], [64675.3, 0.143], [64675.4, 0.141], [64675.6, 0.201], [64675.8, 0.154], [64675.9, 0.17], [64676.0, 0.101], [64676.2, 0.001], [64676.9, 0.005], [64677.1, 0.088], [64677.3, 0.003], [64677.6, 1.926], [64678.2, 0.003], [64678.3, 0.087], [64678.4, 0.008], [64678.7, 0.312], [64679.0, 0.233], [64680.0, 0.116], [64680.3, 0.314], [64680.5, 2.079], [64680.7, 0.009], [64681.2, 0.0], [64681.6, 0.003]], "asks": [[64682.2, 18.106], [64682.6, 0.45], [64682.7, 0.002], [64682.8, 0.002], [64683.0, 0.0], [64683.3, 0.007], [64683.4, 0.0], [64683.7, 0.206], [64684.0, 0.003], [64684.1, 0.084], [64684.2, 0.017], [64684.5, 0.092], [64685.0, 0.002], [64685.1, 0.442], [64685.2, 5.342], [64685.3, 3.324], [64685.6, 0.0], [64685.7, 0.003], [64687.0, 0.117], [64687.4, 0.088], [64687.7, 0.645], [64687.8, 0.48], [64687.9, 2.985], [64689.0, 0.18], [64690.5, 0.003], [64690.6, 0.021], [64690.7, 0.023], [64690.9, 0.281], [64691.0, 0.903], [64691.7, 0.332], [64692.4, 1.24], [64693.8, 0.017], [64693.9, 0.043], [64695.0, 0.34], [64695.9, 0.121], [64696.2, 0.329], [64696.7, 2.32], [64697.6, 0.029], [64697.8, 0.002], [64697.9, 0.116], [64698.1, 0.463], [64698.2, 0.315], [64698.3, 0.172], [64698.5, 0.845], [64698.8, 0.475], [64700.2, 0.081], [64701.2, 0.556], [64701.6, 0.64], [64701.7, 0.004], [64705.0, 0.025], [64705.2, 0.07], [64707.7, 0.008], [64709.3, 0.0], [64711.9, 0.491], [64713.0, 0.169], [64713.2, 0.23], [64723.4, 3.592], [64723.5, 0.0], [64726.2, 1.283], [64727.5, 0.003], [64744.3, 0.01], [64759.9, 0.752], [64791.3, 2.319], [64841.5, 0.022], [64844.3, 7.546], [64880.4, 0.001], [64883.1, 10.444], [65329.0, 0.263], [65451.9, 4.845], [65490.7, 2.112], [65682.2, 0.001], [67269.4, 0.191]]}
{"kind": "depth", "E": 1787080699195, "U": 11315373978191, "u": 11315373984265, "recv_ms": 1787080699143, "bids": [[1000.0, 35.81], [14182.1, 3.668], [14282.1, 0.532], [58213.8, 0.003], [64035.3, 0.032], [64525.8, 0.16], [64630.3, 1.398], [64641.7, 2.137], [64650.0, 4.932], [64658.3, 2.134], [64670.3, 0.056], [64672.1, 0.0], [64672.2, 0.008], [64672.3, 0.004], [64674.0, 0.006], [64674.1, 0.002], [64674.2, 0.007], [64675.1, 0.912], [64675.4, 0.142], [64675.5, 0.428], [64675.6, 0.309], [64675.7, 0.339], [64675.8, 0.154], [64675.9, 1.291], [64677.3, 0.002], [64677.6, 0.007], [64677.7, 0.484], [64677.8, 0.085], [64680.0, 0.093], [64682.1, 8.642]], "asks": [[64687.4, 0.088], [64687.5, 0.006], [64687.7, 0.645], [64688.0, 1.01], [64689.1, 0.005], [64690.7, 0.493], [64691.2, 1.829], [64692.0, 1.95], [64698.1, 0.0], [64698.3, 0.164], [64707.7, 0.012], [64713.0, 0.015], [64713.3, 0.154], [64749.5, 3.832], [64752.1, 0.024], [64754.7, 41.342], [64755.9, 2.047], [64756.9, 0.001], [64770.6, 0.475], [64791.0, 2.13], [64791.1, 0.003], [64795.8, 0.032], [64799.3, 2.137], [64799.4, 0.0], [64807.6, 2.143], [64807.7, 0.018], [64811.6, 0.001], [64841.5, 10.432], [64844.3, 0.0], [64880.3, 6.86], [64883.1, 0.0], [65329.0, 0.263], [71150.5, 0.0]]}
{"kind": "depth", "E": 1787080699297, "U": 11315373984398, "u": 11315373990422, "recv_ms": 1787080699246, "bids": [[14182.1, 3.752], [14282.1, 0.308], [14582.1, 0.14], [51746.0, 0.0], [58213.8, 0.003], [61447.9, 0.024], [62094.8, 0.006], [63388.5, 0.044], [63682.1, 0.02], [63841.0, 1.095], [64035.3, 0.032], [64358.7, 1.866], [64649.7, 1.025], [64650.2, 0.443], [64660.4, 0.567], [64661.0, 0.025], [64661.8, 0.116], [64662.5, 0.012], [64665.3, 2.309], [64666.2, 0.695], [64670.3, 0.526], [64672.1, 0.573], [64672.2, 0.085], [64673.9, 1.281], [64674.0, 0.555], [64674.2, 0.0], [64675.2, 0.103], [64675.7, 0.411], [64675.8, 0.154], [64675.9, 0.17], [64676.0, 0.101], [64677.7, 0.483], [64680.9, 0.084], [64682.0, 0.044], [64682.1, 9.049]], "asks": [[64682.2, 18.201], [64683.7, 0.122], [64689.0, 0.178], [64701.5, 0.067], [64702.2, 0.003], [64702.4, 1.614], [64702.5, 0.005], [64702.8, 0.358], [64704.7, 0.002], [64705.5, 1.449], [64705.8, 0.001], [64811.6, 0.0], [64880.3, 6.578], [65329.0, 0.263], [65682.2, 0.021]]}
{"kind": "depth", "E": 1787080699399, "U": 11315373990525, "u": 11315373995648, "recv_ms": 1787080699346, "bids": [[1000.0, 35.81], [14182.1, 3.626], [14282.1, 0.196], [14582.1, 0.378], [51746.0, 0.0], [58213.8, 0.003], [61447.9, 0.024], [62094.8, 0.698], [64035.3, 0.032], [64617.4, 0.038], [64649.2, 0.015], [64649.3, 0.002], [64649.4, 0.083], [64652.6, 0.007], [64652.7, 0.002], [64652.8, 0.391], [64658.8, 0.461], [64660.0, 0.168], [64662.1, 5.164], [64664.7, 0.632], [64669.2, 0.072], [64671.5, 0.032], [64672.2, 0.626], [64674.0, 0.014], [64675.0, 0.034], [64675.2, 0.103], [64675.4, 0.141], [64675.6, 0.471], [64675.7, 0.339], [64675.8, 0.154], [64677.8, 0.086], [64678.7, 0.002], [64680.5, 1.995], [64680.9, 0.0], [64682.1, 8.745]], "asks": [[64682.2, 18.211], [64683.5, 0.087], [64687.7, 0.955], [64770.6, 0.375], [65329.0, 0.263], [65607.6, 3.41]]}
{"kind": "depth", "E": 1787080699501, "U": 11315373995753, "u": 11315374000026, "recv_ms": 1787080699451, "bids": [[1000.0, 35.81], [14182.1, 3.5], [14282.1, 0.084], [14582.1, 0.616], [58213.8, 0.003], [62094.8, 0.695], [63682.1, 0.0], [63754.6, 8.305], [64035.3, 0.032], [64654.6, 0.277], [64661.4, 0.04], [64662.3, 0.177], [64663.2, 0.002], [64675.6, 0.201], [64675.8, 0.154]], "asks": [[64690.6, 0.003], [64693.2, 0.029], [64701.6, 0.621], [64704.0, 0.149], [65005.7, 0.0], [65329.0, 0.265], [65682.2, 0.001]]}
{"kind": "depth", "E": 1787080699603, "U": 11315374000058, "u": 11315374005469, "recv_ms": 1787080699552, "bids": [[14182.1, 3.304], [14282.1, 0.0], [14582.1, 0.896], [58213.8, 0.003], [61447.9, 0.024], [64035.3, 0.032], [64358.6, 0.01], [64358.7, 1.866], [64542.1, 0.216], [64675.0, 0.034], [64675.2, 0.247], [64675.6, 0.201], [64675.8, 0.154], [64675.9, 0.305], [64682.1, 8.764]], "asks": [[64824.6, 0.0], [65329.0, 0.263], [65551.2, 0.007]]}
{"kind": "depth", "E": 1787080699705, "U": 11315374005694, "u": 11315374011151, "recv_ms": 1787080699653, "bids": [[1000.0, 35.96], [14182.1, 2.954], [14582.1, 1.246], [58213.8, 0.003], [62094.8, 0.698], [62742.6, 0.0], [63589.0, 3.33], [63682.1, 0.02], [64035.3, 0.032], [64078.0, 8.772], [64525.1, 0.001], [64526.5, 1.112], [64670.4, 0.238], [64675.2, 0.247], [64675.6, 0.345], [64675.8, 0.424], [64675.9, 0.17], [64680.9, 0.023]], "asks": [[64701.6, 0.497], [64841.5, 0.022], [65329.0, 0.263], [65682.2, 0.021]]}
{"kind": "depth", "E": 1787080699807, "U": 11315374011269, "u": 11315374016472, "recv_ms": 1787080699754, "bids": [[1000.0, 35.81], [14182.1, 2.59], [14582.1, 1.61], [51746.0, 0.0], [58213.8, 0.003], [61447.9, 0.024], [61448.0, 0.013], [62094.8, 0.695], [62734.1, 2.309], [63744.2, 20.217], [64035.3, 0.032], [64078.0, 7.994], [64486.2, 4.178], [64486.3, 0.004], [64525.1, 1.979], [64526.5, 1.694], [64542.0, 1.419], [64616.4, 0.003], [64655.4, 0.02], [64656.4, 0.347], [64660.4, 0.01], [64660.9, 0.906], [64661.8, 0.0], [64662.4, 0.161], [64665.0, 0.63], [64665.7, 0.161], [64665.9, 0.36], [64670.2, 2.487], [64670.3, 0.063], [64672.3, 0.467], [64672.4, 0.0], [64673.2, 0.309], [64675.2, 0.139], [64675.6, 0.201], [64675.8, 0.289], [64682.0, 0.045], [64682.1, 8.776]], "asks": [[64682.2, 18.211], [64687.5, 0.083], [64687.7, 0.878], [64698.2, 0.313], [64705.1, 0.617], [64705.5, 1.333], [64705.6, 1.735], [64749.5, 0.011], [64754.7, 41.351], [64824.5, 5.434], [64841.5, 10.432], [64880.3, 13.503], [65329.0, 0.263], [65555.4, 3.501]]}
{"kind": "depth", "E": 1787080699909, "U": 11315374016625, "u": 11315374020896, "recv_ms": 1787080699859, "bids": [[14182.1, 2.226], [14582.1, 1.974], [51745.7, 0.0], [58213.8, 0.003], [62094.8, 0.698], [63682.1, 0.0], [63880.3, 22.734], [63883.9, 4.048], [64035.3, 0.034], [64067.6, 3.424], [64358.7, 1.866], [64486.2, 15.507], [64525.1, 6.21], [64542.0, 3.734], [64616.3, 2.762], [64627.5, 0.004], [64634.3, 0.001], [64660.1, 0.928], [64660.9, 0.349], [64661.6, 0.144], [64662.4, 0.045], [64665.7, 0.163], [64675.2, 0.175], [64675.8, 0.154], [64675.9, 0.17], [64676.0, 0.101], [64676.1, 0.205], [64676.2, 0.136], [64676.3, 0.088], [64677.6, 0.004], [64680.3, 0.398]], "asks": [[64697.5, 0.002], [64698.2, 0.315], [64698.4, 3.492], [64698.7, 0.064], [64700.3, 0.223], [64701.2, 0.556], [64702.0, 0.011], [64702.1, 0.061], [64702.3, 0.094], [64702.4, 1.557], [64702.8, 0.351], [64703.5, 0.545], [64704.4, 1.471], [64705.1, 0.501], [64705.4, 0.117], [64749.2, 3.807], [64754.7, 41.342], [64880.3, 6.887], [65329.0, 0.263], [65490.7, 2.34], [65682.2, 0.001], [65788.7, 8.568]]}
{"kind": "depth", "E": 1787080700011, "U": 11315374020909, "u": 11315374025394, "recv_ms": 1787080699958, "bids": [[1000.0, 35.81], [14182.1, 1.876], [14582.1, 2.324], [58213.8, 0.003], [62094.8, 0.695], [62217.2, 0.0], [64035.3, 0.032], [64553.9, 0.02], [64647.7, 0.569], [64661.1, 0.106], [64662.2, 2.209], [64670.3, 0.056], [64672.4, 0.007], [64675.6, 0.345], [64675.8, 0.154], [64675.9, 0.17], [64676.0, 0.236], [64676.1, 0.07], [64676.2, 0.001], [64680.3, 0.314]], "asks": [[64683.1, 0.085], [64687.8, 0.396], [64702.8, 0.892], [64703.5, 0.004], [64752.0, 7.115], [64752.1, 0.015], [64884.7, 0.594]]}
{"kind": "depth", "E": 1787080700113, "U": 11315374025509, "u": 11315374032166, "recv_ms": 1787080700064, "bids": [[14182.1, 1.526], [14582.1, 2.674], [51746.0, 0.0], [58213.8, 0.003], [63388.5, 0.047], [63682.1, 0.02], [63694.1, 3.612], [64035.3, 0.032], [64067.6, 4.202], [64358.6, 0.009], [64610.8, 0.006], [64639.5, 0.003], [64640.0, 0.363], [64640.2, 0.08], [64667.4, 1.547], [64670.5, 0.232], [64670.8, 0.005], [64675.8, 0.154], [64675.9, 0.305], [64676.0, 0.101], [64676.1, 0.07], [64676.2, 0.001], [64680.2, 0.003]], "asks": [[64880.3, 7.052], [65329.0, 0.263], [65670.1, 0.029], [65682.2, 0.021], [65781.8, 5.831]]}
{"kind": "depth", "E": 1787080700215, "U": 11315374032352, "u": 11315374037291, "recv_ms": 1787080700163, "bids": [[14182.1, 1.162], [14582.1, 3.038], [51746.0, 0.0], [58213.8, 0.003], [61447.9, 0.024], [62094.8, 0.698], [62317.4, 0.013], [63694.1, 3.621], [63873.6, 6.008], [64035.3, 0.032], [64358.7, 1.876], [64636.8, 1.717], [64662.1, 0.164], [64662.2, 0.0], [64675.8, 0.289], [64675.9, 0.17], [64676.0, 0.101], [64676.1, 0.07], [64676.2, 0.001], [64679.0, 0.001], [64679.5, 0.232], [64680.4, 0.001]], "asks": [[64682.2, 18.212], [64683.3, 0.009], [64689.5, 0.002], [64743.2, 2.095], [64743.7, 0.066], [64746.9, 0.034], [64759.9, 0.755], [64811.6, 0.0], [65005.7, 0.001], [65329.0, 0.263], [65450.9, 0.793], [65458.4, 13.898]]}
{"kind": "depth", "E": 1787080700317, "U": 11315374037414, "u": 11315374042270, "recv_ms": 1787080700264, "bids": [[1000.0, 35.81], [14182.1, 0.798], [14582.1, 3.402], [51746.0, 0.0], [58213.8, 0.003], [62094.8, 0.695], [63682.1, 0.0], [63905.9, 22.167], [64035.3, 0.032], [64675.6, 0.201], [64675.8, 0.154]], "asks": [[64682.2, 18.212], [65329.0, 0.263], [65670.2, 0.018], [65682.2, 0.001]]}
{"kind": "depth", "E": 1787080700623, "U": 11315374052234, "u": 11315374060499, "recv_ms": 1787080700571, "bids": [[1000.0, 35.81], [14182.1, 0.168], [14482.1, 0.434], [14582.1, 3.598], [58213.8, 0.003], [64035.3, 0.032], [64675.0, 0.033], [64675.1, 0.913], [64675.2, 0.103], [64675.3, 0.143], [64675.8, 0.424], [64681.1, 0.02]], "asks": [[65329.0, 0.263], [65975.8, 0.012], [71150.5, 0.0]]}
{"kind": "depth", "E": 1787080700725, "U": 11315374060590, "u": 11315374068836, "recv_ms": 1787080700674, "bids": [[14182.1, 0.042], [14482.1, 0.672], [14582.1, 3.486], [58213.8, 0.003], [61447.9, 0.024], [61448.0, 0.013], [61448.1, 0.006], [62094.8, 0.698], [63388.5, 0.05], [63682.1, 0.0], [64035.3, 0.032], [64486.2, 15.507], [64525.0, 6.617], [64525.1, 0.001], [64526.5, 1.112], [64542.0, 3.679], [64616.3, 2.808], [64623.8, 0.003], [64650.4, 0.629], [64654.2, 0.338], [64675.8, 0.154], [64681.6, 0.025], [64682.1, 8.799]], "asks": [[64682.2, 18.212], [64689.5, 0.001], [64701.7, 5.004], [64749.1, 4.165], [64759.9, 0.755], [64824.5, 5.233], [64841.5, 10.432], [64880.3, 7.05], [65005.7, 0.002], [65329.0, 0.263], [65677.3, 2.211], [65682.2, 0.001]]}
{"kind": "depth", "E": 1787080700827, "U": 11315374068938, "u": 11315374074789, "recv_ms": 1787080700775, "bids": [[14182.1, 0.0], [14482.1, 0.98], [14582.1, 3.22], [58213.8, 0.003], [62094.8, 0.695], [63873.6, 6.242], [64035.3, 0.032], [64358.7, 1.876], [64591.1, 0.005], [64597.6, 0.028], [64613.8, 0.004], [64625.8, 0.007], [64627.5, 0.0], [64660.1, 0.371], [64660.9, 0.906], [64661.6, 0.028], [64662.4, 0.161], [64665.7, 0.161], [64675.1, 0.912], [64675.4, 0.142], [64675.7, 0.339], [64675.8, 0.154]], "asks": [[64683.3, 0.007], [64683.5, 0.087], [64698.2, 0.313], [64718.1, 0.003], [64723.4, 3.596], [64729.9, 0.079], [64733.5, 0.015], [64774.8, 0.0], [64781.2, 0.013], [64883.0, 0.067], [65329.0, 0.263]]}
{"kind": "depth", "E": 1787080700929, "U": 11315374074936, "u": 11315374080368, "recv_ms": 1787080700876, "bids": [[1000.0, 35.81], [14482.1, 1.33], [14582.1, 2.87], [51745.7, 0.0], [58213.8, 0.003], [62094.8, 0.698], [63682.1, 0.02], [63987.5, 2.108], [64035.3, 0.032], [64525.0, 0.52], [64542.0, 0.213], [64626.2, 0.083], [64632.7, 0.006], [64665.7, 0.163], [64675.1, 0.912], [64675.4, 0.142], [64675.6, 0.201], [64675.7, 0.339], [64675.8, 0.154], [64677.5, 0.002]], "asks": [[64698.2, 0.315], [64824.5, 0.035], [64841.5, 0.022], [65329.0, 0.263], [65682.2, 0.021]]}
{"kind": "depth", "E": 1787080701031, "U": 11315374080498, "u": 11315374087310, "recv_ms": 1787080700980, "bids": [[14482.1, 1.694], [14582.1, 2.506], [58213.8, 0.003], [61447.9, 0.024], [63977.1, 4.679], [64035.3, 0.032], [64486.2, 15.507], [64525.0, 6.617], [64542.0, 3.679], [64585.1, 0.016], [64661.0, 1.229], [64672.1, 1.191], [64675.0, 0.034], [64675.3, 0.143], [64675.4, 0.141], [64675.6, 0.273], [64675.8, 0.424], [64680.5, 1.995], [64682.1, 8.798]], "asks": [[64697.9, 0.734], [64713.1, 0.197], [64713.3, 0.0], [64746.0, 2.209], [64824.5, 5.434], [64841.5, 10.432], [64880.3, 7.05], [65005.2, 0.108], [65329.0, 0.263]]}
{"kind": "depth", "E": 1787080701133, "U": 11315374087429, "u": 11315374094231, "recv_ms": 1787080701081, "bids": [[1000.0, 35.81], [14482.1, 2.044], [14582.1, 2.156], [51746.0, 0.0], [58213.8, 0.003], [61447.9, 0.024], [62094.8, 0.695], [63682.1, 0.0], [63770.3, 2.113], [64035.3, 0.032], [64358.7, 1.876], [64526.5, 1.946], [64610.7, 0.003], [64640.1, 0.005], [64670.5, 0.232], [64672.1, 0.573], [64675.6, 0.201], [64675.8, 0.154], [64680.5, 2.06], [64682.1, 8.698]], "asks": [[64682.2, 18.113], [64689.3, 0.003], [64697.9, 0.116], [64713.1, 0.043], [64713.3, 0.154], [64951.1, 0.002], [65329.0, 0.263], [65600.7, 0.909], [65682.2, 0.001]]}
{"kind": "depth", "E": 1787080701235, "U": 11315374094330, "u": 11315374099783, "recv_ms": 1787080701184, "bids": [[1000.0, 35.81], [14482.1, 2.408], [14582.1, 1.792], [58213.8, 0.003], [62094.8, 0.698], [64035.3, 0.032], [64358.6, 0.009], [64640.1, 0.006], [64665.0, 0.012], [64675.8, 0.154], [64682.1, 8.797]], "asks": [[64682.2, 18.128], [64705.6, 1.117], [64775.6, 0.126], [64811.6, 0.0], [65005.7, 0.001], [65329.0, 0.263], [65458.8, 3.665]]}
{"kind": "depth", "E": 1787080701337, "U": 11315374099892, "u": 11315374105551, "recv_ms": 1787080701286, "bids": [[14482.1, 2.758], [14582.1, 1.442], [58213.8, 0.003], [61447.9, 0.024], [62094.8, 0.695], [63388.5, 0.053], [63682.1, 0.02], [63744.2, 20.374], [64035.3, 0.032], [64486.2, 9.065], [64630.3, 1.426], [64660.1, 0.928], [64660.9, 0.349], [64661.6, 0.144], [64662.4, 0.045], [64664.9, 0.0], [64665.3, 1.383], [64665.8, 0.926], [64675.6, 0.345], [64675.8, 0.154], [64682.1, 8.697]], "asks": [[64682.2, 18.128], [64690.3, 0.003], [64697.5, 0.002], [64698.4, 3.492], [64700.3, 0.223], [64701.2, 0.556], [64702.8, 0.351], [64703.5, 0.545], [64704.4, 1.471], [64705.4, 0.117], [64713.3, 0.0], [64713.4, 0.155], [64880.3, 13.141], [65329.0, 0.263], [65682.2, 0.021], [66006.6, 0.026], [67269.4, 0.178]]}
{"kind": "depth", "E": 1787080701439, "U": 11315374105561, "u": 11315374110914, "recv_ms": 1787080701521, "bids": [[1000.0, 35.81], [14482.1, 3.122], [14582.1, 1.078], [58213.8, 0.003], [62094.8, 0.698], [63682.1, 0.0], [64035.3, 0.032], [64358.7, 1.866], [64486.2, 15.507], [64542.0, 3.653], [64614.0, 1.263], [64616.2, 33.548], [64675.0, 0.033], [64675.2, 0.104], [64675.4, 0.141], [64675.7, 0.339], [64675.8, 0.298], [64677.5, 0.002]], "asks": [[64682.2, 18.129], [64824.5, 5.434], [64880.3, 7.128], [65329.0, 0.263], [65451.9, 5.761], [65682.2, 0.001]]}
{"kind": "depth", "E": 1787080701541, "U": 11315374111368, "u": 11315374117820, "recv_ms": 1787080701523, "bids": [[1000.0, 35.81], [14482.1, 3.472], [14582.1, 0.728], [58213.8, 0.003], [61447.9, 0.024], [61448.0, 0.011], [61448.1, 0.008], [64035.3, 0.032], [64486.2, 9.065], [64614.1, 0.01], [64617.4, 0.056], [64617.6, 6.499], [64664.9, 0.0], [64665.8, 0.926], [64675.0, 0.033], [64675.2, 0.103], [64675.3, 0.144], [64675.7, 0.483], [64675.8, 0.424], [64675.9, 0.44], [64681.8, 0.019], [64681.9, 0.001]], "asks": [[64683.5, 0.003], [64690.3, 0.157], [64697.5, 0.002], [64698.4, 3.492], [64702.3, 0.094], [64703.5, 0.545], [64880.3, 13.141], [65329.0, 0.263]]}
{"kind": "depth", "E": 1787080701643, "U": 11315374118038, "u": 11315374122195, "recv_ms": 1787080701591, "bids": [[14382.1, 0.264], [14482.1, 3.724], [14582.1, 0.42], [51746.0, 0.0], [58213.8, 0.003], [58213.9, 0.01], [61447.9, 0.024], [62094.8, 0.695], [63873.6, 6.507], [64035.3, 0.032], [64542.0, 0.213], [64623.8, 0.003], [64636.8, 1.714], [64675.0, 0.033], [64675.3, 0.144], [64675.7, 0.339], [64675.8, 0.424], [64675.9, 0.17], [64680.5, 1.976], [64682.1, 8.698]], "asks": [[64682.2, 18.237], [64683.7, 0.206], [64727.5, 0.003], [64759.9, 0.752], [64824.5, 0.035], [64951.1, 1.162], [65329.0, 0.263]]}
{"kind": "depth", "E": 1787080701745, "U": 11315374122243, "u": 11315374127035, "recv_ms": 1787080701694, "bids": [[1000.0, 35.81], [14382.1, 0.46], [14482.1, 3.682], [14582.1, 0.266], [58213.8, 0.003], [58213.9, 0.008], [62094.8, 0.698], [63682.1, 0.02], [63909.7, 0.005], [64035.3, 0.034], [64358.7, 1.876], [64486.2, 15.507], [64542.0, 3.735], [64664.9, 0.926], [64665.8, 0.0], [64675.7, 0.411], [64675.8, 0.226], [64675.9, 0.17], [64677.5, 0.272]], "asks": [[64682.2, 18.237], [64697.5, 0.002], [64698.4, 3.492], [64702.3, 0.094], [64703.5, 0.545], [64726.2, 1.241], [64824.5, 5.434], [64880.3, 6.963], [65005.7, 0.0], [65329.0, 0.263], [65682.2, 0.021], [66295.0, 0.528]]}
{"kind": "depth", "E": 1787080701949, "U": 11315374132789, "u": 11315374138143, "recv_ms": 1787080701900, "bids": [[14382.1, 0.936], [14482.1, 3.444], [14582.1, 0.028], [51745.7, 0.0], [58213.8, 0.003], [61447.9, 0.024], [63682.1, 0.0], [64035.3, 0.032], [64542.0, 3.679], [64649.4, 0.14], [64649.7, 0.968], [64650.1, 0.005], [64650.9, 0.007], [64660.1, 0.928], [64660.9, 0.349], [64661.2, 0.007], [64661.6, 0.028], [64661.7, 0.5], [64662.4, 0.161], [64663.2, 0.002], [64663.4, 1.863], [64664.9, 0.926], [64665.7, 0.163], [64665.8, 0.0], [64666.6, 0.047], [64670.5, 0.252], [64672.2, 0.085], [64672.3, 1.008], [64674.0, 0.014], [64675.7, 0.447], [64675.8, 0.19], [64676.3, 0.085], [64677.5, 0.002], [64677.8, 0.356], [64679.6, 0.085], [64681.9, 0.001], [64682.0, 0.047], [64682.1, 8.699]], "asks": [[64697.4, 0.985], [64698.2, 0.315], [64698.4, 2.567], [64699.0, 0.127], [64700.3, 0.223], [64701.1, 0.633], [64701.2, 0.057], [64701.9, 0.581], [64702.1, 0.004], [64702.3, 0.094], [64702.8, 0.892], [64703.4, 0.311], [64703.5, 0.004], [64704.3, 0.28], [64704.4, 1.471], [64705.2, 0.07], [64705.4, 0.001], [64706.0, 0.121], [64726.2, 1.283], [64824.5, 5.434], [64880.3, 7.048], [65435.0, 1.445], [65682.2, 0.001], [66097.3, 0.001]]}
{"kind": "depth", "E": 1787080702051, "U": 11315374138304, "u": 11315374143312, "recv_ms": 1787080701999, "bids": [[1000.0, 35.81], [14382.1, 1.272], [14482.1, 3.136], [14582.1, 0.0], [58213.8, 0.003], [62094.8, 0.698], [64035.3, 0.032], [64358.7, 1.876], [64664.7, 0.632], [64664.9, 0.0], [64666.0, 4.091], [64670.2, 2.333], [64670.5, 0.257], [64670.6, 0.524], [64675.8, 0.424], [64677.8, 0.086], [64680.9, 0.0]], "asks": [[64697.4, 0.06], [64698.5, 1.77], [64701.2, 0.0], [64702.1, 0.061], [64702.8, 0.351], [64703.5, 0.545], [65329.0, 0.263], [65587.8, 17.387]]}
{"kind": "depth", "E": 1787080702153, "U": 11315374143470, "u": 11315374148790, "recv_ms": 1787080702101, "bids": [[1000.0, 35.81], [14382.1, 1.622], [14482.1, 2.786], [58213.8, 0.003], [61448.0, 0.015], [62094.8, 0.695], [63388.5, 0.056], [63682.1, 0.02], [63694.1, 3.621], [63910.1, 0.001], [64035.3, 0.032], [64068.2, 0.701], [64610.7, 0.004], [64617.4, 0.057], [64624.7, 0.002], [64640.1, 0.007], [64665.0, 0.63], [64670.5, 0.252], [64672.1, 0.0], [64672.2, 0.008], [64672.3, 0.545], [64672.4, 0.618], [64674.0, 1.134], [64675.7, 0.339], [64675.8, 0.19], [64675.9, 0.377], [64676.0, 0.32]], "asks": [[64682.2, 18.221], [64698.2, 0.933], [64705.6, 1.735], [64746.9, 0.035], [65329.0, 0.263], [65670.2, 0.01], [65682.2, 0.021], [104929.0, 0.0]]}
{"kind": "depth", "E": 1787080702255, "U": 11315374149154, "u": 11315374154848, "recv_ms": 1787080702203, "bids": [[14382.1, 1.986], [14482.1, 2.422], [51746.0, 0.006], [58213.8, 0.003], [61447.9, 0.024], [61448.1, 0.006], [62094.8, 0.698], [63776.6, 17.788], [64035.3, 0.032], [64067.6, 4.902], [64358.6, 0.009], [64675.6, 0.201], [64675.8, 0.154], [64675.9, 0.17], [64676.0, 0.32], [64682.1, 8.684]], "asks": [[64682.2, 18.221], [64811.6, 0.0], [65329.0, 0.263], [65670.2, 0.018]]}
{"kind": "depth", "E": 1787080702357, "U": 11315374154934, "u": 11315374165245, "recv_ms": 1787080702305, "bids": [[1000.0, 35.81], [14382.1, 2.336], [14482.1, 2.072], [51746.0, 0.002], [58213.8, 0.003], [62094.8, 0.695], [63682.1, 0.0], [64035.3, 0.032], [64049.8, 3.118], [64358.7, 1.876], [64576.5, 1.003], [64577.3, 2.32], [64675.8, 0.154], [64675.9, 0.17], [64676.0, 0.185], [64676.1, 0.205], [64682.1, 8.682]], "asks": [[64682.2, 18.233], [64791.1, 2.322], [64791.3, 0.0], [64880.3, 7.021], [65005.7, 0.001], [65329.0, 0.263], [65682.2, 0.001], [65709.1, 0.0], [104929.0, 0.236]]}
{"kind": "depth", "E": 1787080702459, "U": 11315374166016, "u": 11315374178105, "recv_ms": 1787080702408, "bids": [[1000.0, 35.81], [14382.1, 2.7], [14482.1, 1.708], [51746.0, 0.0], [58213.8, 0.003], [64035.3, 0.101], [64541.9, 3.74], [64542.0, 0.213], [64614.8, 0.0], [64675.8, 0.154], [64675.9, 0.17], [64676.0, 0.32], [64676.1, 0.07]], "asks": [[64824.5, 5.434], [65329.0, 0.263], [65405.7, 0.4], [65470.4, 0.215], [65497.6, 19.655]]}
{"kind": "depth", "E": 1787080702663, "U": 11315374188463, "u": 11315374195331, "recv_ms": 1787080702611, "bids": [[1000.0, 35.81], [14382.1, 3.414], [14482.1, 0.994], [51746.0, 0.0], [58213.8, 0.003], [61447.9, 0.024], [61448.0, 0.017], [62094.8, 0.695], [63388.5, 0.053], [64035.3, 0.101], [64358.7, 1.876], [64541.9, 3.74], [64565.8, 0.0], [64566.8, 5.149], [64611.1, 2.297], [64614.1, 33.608], [64614.8, 0.018], [64616.2, 0.001], [64617.6, 1.218], [64675.6, 0.471], [64681.9, 0.024]], "asks": [[64682.2, 18.233], [64713.4, 0.155], [64753.5, 0.094], [64817.8, 5.753], [64824.5, 5.434], [65329.0, 0.263]]}
{"kind": "depth", "E": 1787080702765, "U": 11315374195432, "u": 11315374200887, "recv_ms": 1787080702713, "bids": [[1000.0, 35.81], [14382.1, 3.778], [14482.1, 0.63], [58213.8, 0.003], [62094.8, 0.698], [63682.1, 0.0], [63877.7, 0.0], [64035.2, 0.056], [64035.3, 0.101], [64164.6, 3.42], [64670.6, 0.37], [64670.7, 0.326]], "asks": [[64691.0, 1.803], [64692.0, 1.05], [64701.6, 0.568], [64713.4, 0.001], [65329.0, 0.263], [65465.3, 47.86], [65682.2, 0.001]]}
{"kind": "depth", "E": 1787080702969, "U": 11315374205447, "u": 11315374209425, "recv_ms": 1787080702917, "bids": [[1000.0, 35.81], [14282.1, 0.308], [14382.1, 3.862], [14482.1, 0.238], [51745.7, 0.0], [58213.8, 0.003], [61454.4, 0.05], [63682.1, 0.02], [63737.7, 3.797], [63791.0, 7.839], [64035.3, 0.101], [64614.2, 7.125], [64623.8, 0.0], [64636.8, 1.717], [64665.7, 0.163], [64670.8, 0.005], [64675.0, 0.033], [64675.3, 0.144], [64675.7, 0.483], [64675.8, 0.154]], "asks": [[64696.0, 0.312], [64698.2, 0.933], [64727.5, 0.003], [64759.9, 0.752], [65005.7, 0.002], [65329.0, 0.263], [65458.8, 2.75], [65607.6, 3.183], [65682.2, 0.021]]}
{"kind": "depth", "E": 1787080703071, "U": 11315374209480, "u": 11315374214736, "recv_ms": 1787080703020, "bids": [[1000.0, 35.81], [14282.1, 0.546], [14382.1, 3.736], [14482.1, 0.126], [58213.8, 0.003], [61447.9, 0.025], [62094.8, 0.698], [63388.5, 0.056], [63694.1, 3.613], [63760.6, 0.001], [64035.3, 0.101], [64566.8, 1.284], [64566.9, 3.865], [64577.2, 2.32], [64577.3, 0.001], [64611.1, 2.297], [64623.8, 0.003], [64645.8, 0.015], [64649.4, 0.083], [64650.1, 0.062], [64650.9, 0.007], [64660.1, 0.928], [64660.9, 0.349], [64661.2, 0.0], [64661.5, 0.01], [64661.6, 0.028], [64662.0, 0.139], [64662.2, 0.116], [64662.4, 0.045], [64663.2, 0.002], [64664.9, 0.0], [64665.8, 0.926], [64666.0, 3.165], [64670.3, 0.056], [64670.5, 0.252], [64670.7, 0.326], [64672.1, 0.541], [64672.3, 0.004], [64672.4, 0.0], [64672.5, 0.008], [64674.0, 0.593], [64674.1, 0.543], [64675.1, 0.912], [64675.2, 0.104], [64675.3, 0.143], [64675.4, 0.141], [64675.6, 0.201], [64675.7, 0.339], [64675.8, 0.154], [64677.8, 0.086], [64679.6, 0.001], [64680.1, 0.002], [64680.4, 0.085], [64681.1, 0.0], [64682.1, 8.624]], "asks": [[64682.2, 18.115], [64682.3, 0.009], [64682.8, 0.002], [64683.2, 0.0], [64685.0, 0.005], [64685.4, 0.09], [64685.7, 0.0], [64689.3, 0.002], [64691.0, 0.903], [64692.0, 1.95], [64697.5, 0.002], [64698.2, 0.315], [64698.3, 0.164], [64698.5, 0.845], [64699.0, 1.052], [64700.3, 0.223], [64701.2, 0.556], [64701.9, 0.025], [64702.1, 0.004], [64702.3, 0.094], [64702.8, 0.949], [64703.5, 0.004], [64704.3, 0.28], [64704.4, 1.471], [64705.2, 0.07], [64706.0, 0.121], [64713.4, 0.001], [64713.5, 0.63], [64726.2, 1.241], [64744.3, 0.001], [64749.5, 0.011], [64753.5, 0.094], [64759.9, 0.755], [64786.1, 0.022], [64791.1, 2.322], [64817.8, 5.753], [65329.0, 0.263], [65451.9, 6.676], [65603.6, 0.001], [65670.1, 0.021], [65975.8, 1.526]]}
{"kind": "depth", "E": 1787080703173, "U": 11315374214849, "u": 11315374221030, "recv_ms": 1787080703122, "bids": [[14282.1, 0.784], [14382.1, 3.624], [14482.1, 0.0], [51746.0, 0.0], [58213.8, 0.003], [61447.9, 0.024], [62094.8, 0.695], [63589.2, 13.398], [63682.1, 0.0], [63694.1, 3.621], [63737.1, 5.34], [63758.8, 2.329], [63758.9, 0.008], [63760.6, 0.009], [64035.3, 0.101], [64358.7, 1.866], [64610.6, 0.018], [64610.7, 0.0], [64631.0, 0.032], [64633.9, 0.0], [64639.9, 0.744], [64640.0, 0.361], [64640.1, 0.003], [64661.6, 0.002], [64663.8, 0.002], [64670.6, 0.524], [64670.7, 0.172], [64672.2, 0.549], [64672.3, 0.583], [64672.4, 0.008], [64674.0, 0.006], [64674.1, 0.002], [64674.2, 0.0], [64675.0, 0.034], [64675.2, 0.103], [64675.6, 0.345], [64675.7, 0.411], [64675.8, 0.154], [64677.5, 0.272]], "asks": [[64682.2, 18.131], [64687.5, 0.084], [64691.0, 1.803], [64692.0, 1.05], [65329.0, 0.263], [65397.9, 4.803], [65605.4, 0.0], [65682.2, 0.001]]}
{"kind": "depth", "E": 1787080703275, "U": 11315374221200, "u": 11315374231578, "recv_ms": 1787080703223, "bids": [[1000.0, 35.81], [14282.1, 1.148], [14382.1, 3.26], [34000.0, 1.146], [58213.8, 0.003], [61447.9, 0.024], [62094.8, 0.698], [63912.6, 37.975], [64035.3, 0.101], [64525.0, 0.52], [64541.9, 0.247], [64670.6, 0.524], [64672.2, 1.167], [64675.2, 0.103], [64677.5, 0.002], [64677.8, 0.356], [64679.9, 0.086], [64680.4, 0.001], [64682.1, 8.629]], "asks": [[64682.2, 18.131], [64682.8, 0.002], [64687.5, 0.083], [64698.0, 0.794], [64720.5, 3.976], [64726.6, 1.059], [64726.7, 0.002], [64789.3, 3.925], [64795.3, 0.442], [64811.6, 0.0], [64824.5, 0.035], [64841.5, 0.022], [64858.2, 4.293], [64864.0, 0.005], [65005.7, 0.001], [65329.0, 0.263], [65594.6, 63.568], [65603.7, 0.008], [65605.5, 0.008], [65670.2, 0.026], [65975.8, 1.523]]}
{"kind": "depth", "E": 1787080703377, "U": 11315374231817, "u": 11315374239834, "recv_ms": 1787080703328, "bids": [[1000.0, 35.81], [14282.1, 1.498], [14382.1, 2.91], [58213.8, 0.003], [61454.4, 0.044], [63582.5, 8.868], [63682.1, 0.02], [63776.6, 20.136], [64035.3, 0.101], [64358.6, 0.009], [64486.2, 0.0], [64526.5, 1.112], [64670.4, 0.392], [64670.6, 0.37], [64675.0, 0.033], [64675.2, 0.103], [64675.3, 0.144], [64675.8, 0.226], [64682.1, 8.639]], "asks": [[64880.3, 0.01], [65329.0, 0.263], [65387.2, 3.127], [65497.6, 19.085], [65682.2, 0.021]]}
{"kind": "depth", "E": 1787080703479, "U": 11315374240077, "u": 11315374258422, "recv_ms": 1787080703428, "bids": [[14282.1, 1.862], [14382.1, 2.546], [58213.8, 0.003], [61447.9, 0.024], [61448.1, 0.004], [62094.8, 0.695], [63388.5, 0.05], [63682.1, 0.0], [63896.2, 0.783], [63905.9, 22.869], [64035.3, 0.101], [64171.4, 6.069], [64358.7, 1.876], [64486.1, 15.507], [64525.0, 6.61], [64526.5, 1.945], [64541.9, 3.735], [64618.9, 0.022], [64630.3, 1.398], [64645.8, 0.001], [64648.4, 0.0], [64650.3, 0.001], [64654.2, 0.002], [64654.6, 0.431], [64655.6, 0.079], [64657.6, 1.5], [64658.7, 0.067], [64663.0, 0.062], [64663.1, 0.647], [64664.7, 0.629], [64665.1, 0.002], [64665.8, 0.0], [64666.8, 0.939], [64666.9, 0.662], [64667.1, 0.061], [64667.9, 0.106], [64669.6, 0.023], [64670.0, 1.356], [64670.3, 0.056], [64670.5, 0.252], [64670.9, 0.025], [64671.1, 0.001], [64671.5, 0.039], [64672.1, 0.0], [64672.2, 0.008], [64672.3, 0.112], [64672.4, 1.004], [64674.0, 0.547], [64674.1, 0.01], [64675.1, 0.971], [64675.3, 0.223], [64675.5, 0.798], [64675.8, 0.229], [64675.9, 0.448], [64676.0, 0.101], [64676.3, 0.001], [64676.7, 0.033], [64677.3, 0.003], [64677.8, 0.086], [64679.1, 0.311], [64679.5, 0.0], [64680.3, 0.088], [64680.6, 1.05], [64681.0, 0.086], [64681.3, 0.237], [64681.5, 0.086], [64681.7, 0.001], [64682.1, 10.672]], "asks": [[64682.2, 10.8], [64682.3, 0.004], [64682.4, 0.0], [64682.6, 0.023], [64683.1, 0.001], [64683.3, 0.007], [64683.7, 0.001], [64684.1, 0.0], [64684.2, 0.38], [64684.3, 0.004], [64684.5, 0.001], [64684.9, 0.002], [64685.0, 0.001], [64685.2, 5.182], [64685.4, 0.003], [64685.5, 0.002], [64685.8, 1.001], [64686.1, 0.002], [64686.7, 0.162], [64687.4, 0.088], [64687.5, 0.006], [64687.7, 0.004], [64687.8, 0.208], [64687.9, 2.984], [64688.1, 1.503], [64688.5, 0.103], [64688.9, 0.092], [64689.2, 0.087], [64690.0, 0.004], [64690.7, 0.022], [64691.0, 0.003], [64691.2, 1.828], [64691.7, 0.023], [64692.7, 0.028], [64693.5, 0.135], [64694.4, 0.037], [64695.0, 0.339], [64695.2, 1.101], [64695.7, 0.259], [64696.2, 0.209], [64697.2, 0.001], [64697.6, 0.028], [64697.9, 0.196], [64698.0, 0.176], [64698.1, 0.16], [64698.3, 0.003], [64698.4, 1.152], [64698.5, 0.525], [64698.7, 0.015], [64698.8, 0.474], [64699.0, 0.127], [64699.2, 0.072], [64700.0, 1.879], [64700.2, 0.001], [64700.6, 0.002], [64700.8, 0.014], [64700.9, 0.329], [64701.2, 0.0], [64701.6, 0.495], [64701.7, 0.004], [64702.0, 0.004], [64702.1, 0.006], [64702.3, 0.004], [64702.6, 0.463], [64702.8, 0.351], [64704.0, 0.148], [64704.3, 0.126], [64705.0, 0.024], [64705.2, 0.0], [64705.6, 1.117], [64706.0, 0.005], [64706.8, 0.081], [64707.2, 0.007], [64707.7, 0.032], [64708.1, 1.834], [64709.1, 0.091], [64710.0, 0.005], [64710.3, 0.183], [64710.4, 3.754], [64710.7, 0.015], [64712.7, 0.006], [64713.2, 0.23], [64716.6, 0.073], [64717.3, 11.257], [64720.5, 3.978], [64720.8, 0.065], [64722.0, 0.533], [64723.6, 0.354], [64727.7, 0.025], [64734.2, 0.521], [64742.8, 0.211], [64752.0, 1.108], [64754.7, 0.009], [64755.9, 7.677], [64756.9, 40.558], [64760.1, 0.001], [64825.6, 2.203], [64826.7, 4.587], [64843.7, 7.296], [64882.5, 37.283], [65329.0, 0.265], [65682.2, 0.001], [65975.8, 1.523]]}
{"kind": "depth", "E": 1787080703581, "U": 11315374258520, "u": 11315374278654, "recv_ms": 1787080703529, "bids": [[1000.0, 35.81], [14282.1, 2.212], [14382.1, 2.196], [58213.8, 0.003], [62094.8, 0.698], [64035.3, 0.101], [64610.5, 0.005], [64630.5, 0.013], [64630.8, 0.237], [64633.8, 0.007], [64639.9, 0.745], [64641.2, 0.03], [64659.2, 2.768], [64661.4, 0.0], [64662.8, 0.319], [64663.9, 0.003], [64666.0, 3.103], [64666.1, 0.065], [64666.4, 3.246], [64666.8, 0.013], [64670.3, 0.519], [64670.5, 0.292], [64671.1, 0.634], [64672.1, 0.016], [64672.3, 0.004], [64672.4, 0.0], [64674.1, 0.002], [64675.6, 0.472], [64675.7, 0.483], [64675.8, 0.435], [64675.9, 0.178], [64676.0, 0.101], [64677.1, 0.087], [64677.3, 0.002], [64677.7, 0.483], [64678.1, 0.002], [64679.2, 0.086], [64680.5, 0.001], [64680.6, 0.629], [64680.7, 0.241], [64680.8, 0.281], [64681.3, 0.005], [64682.0, 0.067], [64682.1, 10.674]], "asks": [[64682.2, 10.795], [64682.3, 0.007], [64682.4, 0.018], [64684.2, 0.0], [64685.0, 0.01], [64685.1, 0.45], [64685.2, 5.18], [64685.3, 3.326], [64685.4, 0.004], [64686.5, 0.007], [64687.3, 0.003], [64687.5, 0.002], [64687.6, 0.002], [64687.8, 0.772], [64690.0, 0.007], [64690.2, 0.272], [64690.4, 0.002], [64690.7, 0.578], [64690.9, 0.186], [64692.0, 1.042], [64692.1, 0.002], [64692.8, 1.259], [64693.2, 0.338], [64695.0, 1.335], [64695.1, 1.774], [64695.5, 0.105], [64697.0, 0.018], [64698.8, 0.482], [64699.2, 0.997], [64699.7, 0.002], [64700.0, 1.88], [64700.2, 0.155], [64700.3, 0.303], [64700.4, 0.027], [64700.9, 0.009], [64701.7, 0.324], [64702.0, 0.56], [64702.1, 0.004], [64702.5, 0.012], [64702.8, 0.353], [64703.0, 0.061], [64703.5, 0.545], [64704.3, 0.126], [64705.0, 0.025], [64705.2, 0.001], [64706.1, 0.351], [64706.7, 0.155], [64706.8, 0.001], [64710.0, 0.006], [64713.1, 0.197], [64713.4, 0.001], [64713.5, 0.63], [64713.7, 0.0], [64722.0, 0.473], [64730.0, 0.118], [64754.7, 40.305], [64755.9, 2.047], [64756.9, 0.001], [64760.1, 0.0], [64841.4, 10.41], [64843.7, 0.003], [64880.2, 7.593], [64882.5, 26.381], [65329.0, 0.263], [65635.0, 1.827], [66299.3, 1.061]]}
{"kind": "depth", "E": 1787080703683, "U": 11315374278743, "u": 11315374298598, "recv_ms": 1787080703634, "bids": [[1000.0, 35.81], [14282.1, 2.576], [14382.1, 1.832], [51746.0, 0.0], [58213.8, 0.003], [61447.9, 0.024], [62094.8, 0.695], [64035.3, 0.101], [64164.6, 4.354], [64586.6, 0.006], [64587.2, 1.451], [64613.4, 0.0], [64614.1, 33.641], [64614.2, 0.63], [64615.7, 0.001], [64616.0, 1.221], [64616.2, 0.001], [64624.9, 0.0], [64632.8, 1.158], [64638.6, 0.454], [64640.6, 0.247], [64642.5, 0.02], [64646.8, 0.003], [64651.6, 0.101], [64652.6, 0.005], [64652.9, 0.04], [64657.9, 1.472], [64659.4, 0.093], [64661.0, 0.025], [64661.2, 5.0], [64661.3, 1.985], [64661.4, 0.032], [64662.1, 0.296], [64663.1, 0.311], [64663.9, 0.337], [64664.9, 0.002], [64665.4, 0.0], [64666.3, 0.004], [64666.4, 2.32], [64666.5, 0.963], [64668.5, 0.157], [64669.1, 1.501], [64669.2, 0.074], [64669.9, 0.256], [64670.3, 0.056], [64670.9, 0.04], [64671.1, 0.001], [64671.2, 0.248], [64671.3, 0.003], [64671.8, 0.135], [64672.1, 0.0], [64672.7, 0.008], [64674.0, 0.547], [64674.6, 0.004], [64675.3, 0.143], [64675.6, 0.202], [64675.7, 0.483], [64675.8, 0.157], [64675.9, 0.178], [64676.1, 1.989], [64676.2, 1.269], [64676.3, 0.145], [64677.5, 0.002], [64677.7, 0.816], [64677.8, 0.356], [64678.2, 0.001], [64678.3, 0.084], [64679.0, 0.001], [64680.0, 0.012], [64680.2, 0.004], [64680.4, 0.003], [64680.7, 0.009], [64681.2, 0.0], [64681.7, 0.001], [64682.1, 10.735]], "asks": [[64682.2, 5.381], [64682.3, 0.006], [64682.4, 0.019], [64683.9, 0.003], [64685.0, 0.011], [64685.2, 1.083], [64685.3, 2.325], [64685.4, 0.003], [64685.8, 0.001], [64686.4, 0.002], [64686.5, 0.0], [64686.6, 0.123], [64686.8, 0.003], [64687.0, 0.033], [64687.2, 0.013], [64687.3, 0.091], [64687.4, 0.004], [64687.7, 0.088], [64687.8, 0.016], [64687.9, 2.985], [64688.0, 1.015], [64688.8, 0.001], [64689.1, 0.002], [64689.6, 0.1], [64690.0, 0.091], [64690.3, 0.241], [64690.5, 0.027], [64690.6, 0.551], [64690.7, 0.175], [64690.9, 0.188], [64691.8, 0.028], [64691.9, 0.466], [64692.0, 1.027], [64692.4, 0.003], [64692.8, 1.259], [64692.9, 0.233], [64693.7, 0.002], [64696.0, 0.293], [64696.4, 0.317], [64697.9, 0.196], [64698.1, 0.179], [64698.3, 0.35], [64698.9, 1.263], [64699.0, 0.127], [64699.1, 0.129], [64699.2, 0.012], [64699.7, 0.927], [64700.3, 0.223], [64700.8, 0.009], [64701.2, 0.02], [64701.4, 0.358], [64702.8, 0.351], [64702.9, 0.699], [64703.3, 0.015], [64703.4, 0.331], [64703.5, 0.004], [64703.9, 0.47], [64704.3, 0.667], [64707.7, 0.012], [64708.3, 0.09], [64710.9, 0.002], [64713.3, 0.0], [64713.5, 0.476], [64713.8, 0.158], [64716.5, 0.007], [64717.3, 11.259], [64721.1, 0.502], [64754.7, 40.305], [64756.9, 0.001], [64760.1, 0.001], [64880.2, 6.863], [65329.0, 0.263], [66081.9, 0.648]]}
{"kind": "depth", "E": 1787080703785, "U": 11315374299226, "u": 11315374314302, "recv_ms": 1787080703735, "bids": [[14282.1, 2.926], [14382.1, 1.482], [51746.0, 0.0], [58213.8, 0.003], [61447.9, 0.024], [62094.8, 0.698], [63388.5, 0.053], [63682.1, 0.02], [63819.2, 2.345], [64035.2, 0.055], [64035.3, 0.101], [64358.7, 1.866], [64609.1, 0.0], [64614.8, 0.0], [64617.1, 0.001], [64617.4, 0.039], [64618.9, 0.035], [64622.1, 0.018], [64625.0, 1.588], [64629.4, 0.212], [64631.3, 0.072], [64632.3, 0.003], [64633.0, 0.065], [64634.0, 0.211], [64634.2, 0.018], [64639.1, 0.522], [64640.4, 2.508], [64640.6, 0.037], [64642.2, 0.019], [64642.5, 0.019], [64643.4, 0.389], [64648.4, 0.006], [64649.0, 0.249], [64649.2, 0.015], [64649.9, 0.029], [64652.1, 0.033], [64653.8, 0.006], [64656.1, 0.17], [64656.2, 1.813], [64657.7, 0.263], [64658.5, 0.237], [64658.7, 0.052], [64658.9, 1.991], [64659.1, 1.356], [64660.7, 1.932], [64660.9, 0.364], [64661.2, 5.002], [64662.0, 0.137], [64662.9, 0.149], [64663.0, 0.062], [64663.3, 0.359], [64663.5, 2.32], [64664.8, 0.006], [64665.0, 0.012], [64665.2, 0.082], [64665.9, 0.359], [64666.1, 0.003], [64666.5, 0.037], [64667.0, 0.903], [64667.3, 1.299], [64667.8, 0.0], [64669.1, 1.501], [64669.2, 0.136], [64669.9, 0.256], [64670.1, 0.05], [64670.3, 0.519], [64670.5, 0.3], [64670.7, 0.18], [64672.0, 2.509], [64672.7, 0.0], [64673.0, 0.473], [64674.0, 2.323], [64674.1, 0.567], [64674.2, 0.641], [64674.3, 0.135], [64674.8, 0.34], [64675.1, 1.298], [64675.2, 0.103], [64675.6, 0.742], [64675.7, 0.339], [64675.8, 0.157], [64676.1, 0.07], [64676.2, 0.005], [64676.3, 0.001], [64676.4, 0.041], [64677.5, 0.002], [64677.6, 0.005], [64677.7, 0.483], [64677.8, 0.088], [64678.0, 0.076], [64678.5, 0.001], [64680.0, 0.011], [64680.2, 0.063], [64680.4, 0.001], [64681.5, 0.087], [64681.8, 0.251], [64682.0, 0.068], [64682.1, 24.271]], "asks": [[64682.2, 4.213], [64682.4, 0.16], [64683.0, 0.814], [64683.5, 0.003], [64684.2, 0.0], [64684.4, 0.004], [64684.9, 0.002], [64685.0, 0.003], [64685.1, 0.442], [64685.3, 0.005], [64686.4, 0.086], [64686.9, 0.146], [64687.0, 0.003], [64687.2, 0.002], [64687.6, 0.097], [64687.7, 2.011], [64687.8, 2.335], [64687.9, 2.985], [64688.0, 1.01], [64688.1, 0.97], [64688.2, 0.391], [64688.3, 0.004], [64688.5, 0.106], [64688.7, 0.042], [64689.3, 0.0], [64689.8, 0.011], [64690.0, 0.088], [64690.2, 0.0], [64690.3, 0.157], [64690.5, 0.019], [64690.6, 0.551], [64690.7, 0.1], [64691.1, 0.276], [64691.7, 0.0], [64691.8, 0.028], [64692.1, 0.001], [64692.4, 0.033], [64692.8, 0.767], [64693.3, 0.001], [64693.8, 0.171], [64693.9, 0.167], [64694.0, 0.002], [64694.9, 0.135], [64695.0, 0.34], [64695.7, 0.229], [64696.0, 0.293], [64696.1, 0.372], [64696.2, 0.169], [64696.6, 0.146], [64697.0, 0.918], [64697.1, 1.226], [64697.9, 0.13], [64698.0, 0.216], [64698.1, 0.019], [64698.3, 0.35], [64698.8, 0.474], [64699.0, 0.127], [64699.6, 0.495], [64699.7, 0.002], [64699.9, 0.033], [64700.2, 0.926], [64700.3, 0.303], [64700.4, 0.081], [64700.5, 0.04], [64700.8, 0.057], [64701.5, 0.228], [64701.6, 0.353], [64701.7, 0.004], [64701.9, 0.025], [64702.3, 0.022], [64702.9, 0.859], [64703.4, 0.311], [64703.6, 1.861], [64703.9, 0.468], [64704.0, 0.148], [64704.3, 0.212], [64704.4, 1.473], [64704.5, 2.367], [64704.9, 0.106], [64705.4, 0.542], [64705.5, 1.653], [64706.5, 0.007], [64706.7, 0.001], [64706.8, 0.016], [64707.7, 0.007], [64708.3, 0.164], [64708.9, 0.215], [64710.1, 0.016], [64710.7, 0.009], [64710.8, 0.114], [64710.9, 0.02], [64711.9, 0.371], [64713.5, 0.47], [64713.8, 0.004], [64719.1, 0.618], [64726.2, 1.243], [64732.2, 0.03], [64754.7, 0.009], [64756.9, 40.297], [64841.4, 10.41], [64843.7, 0.003], [64880.2, 6.863], [64882.5, 26.381], [65329.0, 0.263], [65497.6, 18.857], [65682.2, 0.021]]}
{"kind": "depth", "E": 1787080703887, "U": 11315374314601, "u": 11315374323207, "recv_ms": 1787080703836, "bids": [[1000.0, 35.81], [14282.1, 3.29], [14382.1, 1.118], [58213.8, 0.003], [64035.3, 0.101], [64614.1, 0.01], [64616.2, 33.632], [64656.4, 0.038], [64659.0, 0.427], [64660.1, 0.371], [64660.7, 1.931], [64661.5, 0.003], [64661.8, 0.557], [64662.3, 0.177], [64663.2, 0.009], [64666.3, 0.002], [64667.1, 0.064], [64667.5, 0.141], [64669.6, 0.024], [64670.5, 0.292], [64670.7, 0.172], [64671.5, 0.032], [64672.1, 0.633], [64672.2, 0.024], [64672.4, 0.007], [64672.5, 0.006], [64673.2, 0.0], [64673.7, 0.112], [64674.2, 0.0], [64674.3, 0.676], [64674.4, 0.055], [64675.6, 0.201], [64675.8, 0.538], [64675.9, 0.448], [64681.9, 0.026], [64682.1, 24.273]], "asks": [[64687.5, 0.01], [64687.6, 0.221], [64687.8, 2.327], [64688.2, 0.394], [64688.5, 0.103], [64689.2, 0.09], [64691.8, 0.02], [64691.9, 0.003], [64693.2, 0.029], [64694.0, 0.473], [64694.1, 3.114], [64700.0, 1.752], [64702.0, 0.004], [64702.5, 0.561], [64703.5, 0.011], [64705.2, 0.0], [64708.7, 0.004], [64713.8, 0.004], [64775.6, 0.026], [64841.4, 10.41], [64843.6, 0.0], [64880.2, 6.876], [64882.4, 0.218], [64950.0, 24.292], [65329.0, 0.263], [65620.1, 20.356], [66180.6, 2.354]]}
