{"kind": "depth", "E": 1787080654621, "U": 11315370689121, "u": 11315370693865, "recv_ms": 1787080654592, "bids": [[1000.0, 35.81], [14388.9, 3.066], [14488.9, 1.134], [51751.0, 0.0], [58220.0, 4.018], [63758.7, 7.363], [64042.0, 2.169], [64365.4, 0.002], [64532.4, 6.671], [64549.3, 4.549], [64681.8, 0.268], [64683.0, 0.639], [64683.1, 0.108], [64683.8, 0.149], [64684.6, 0.127]], "asks": [[64718.6, 0.154], [64848.7, 10.414], [64887.5, 6.479], [65335.9, 6.758], [65458.8, 7.326], [65902.5, 0.0]]}
{"kind": "depth", "E": 1787080655131, "U": 11315370716823, "u": 11315370728558, "recv_ms": 1787080655077, "bids": [[14288.9, 0.686], [14388.9, 3.472], [14488.9, 0.042], [51751.0, 0.0], [58220.0, 4.018], [62101.3, 2.785], [63688.9, 0.027], [63700.8, 1.728], [63705.4, 0.0], [63876.5, 3.342], [64042.0, 2.169], [64072.4, 1.325], [64171.4, 8.245], [64179.1, 0.0], [64365.5, 6.052], [64588.3, 0.004], [64588.4, 0.03], [64664.9, 0.0], [64677.3, 0.002], [64679.5, 0.001], [64681.7, 0.178], [64681.8, 0.664], [64681.9, 0.254], [64682.4, 0.022], [64683.0, 0.662], [64683.1, 0.001], [64683.8, 0.399], [64684.5, 0.899], [64684.6, 0.002], [64684.7, 0.003], [64684.8, 0.003], [64685.2, 0.017], [64687.4, 0.087], [64687.5, 0.117], [64687.8, 0.31], [64688.9, 6.905]], "asks": [[64689.0, 12.01], [64693.1, 0.088], [64693.2, 0.287], [64693.3, 0.004], [64694.0, 0.006], [64694.4, 0.032], [64694.9, 0.273], [64706.6, 0.058], [64714.9, 2.326], [64749.0, 0.003], [64749.2, 0.089], [65012.5, 0.002], [65335.9, 6.758], [65677.0, 0.02], [65689.0, 10.035], [65862.5, 1.57], [65982.7, 0.008], [66638.7, 0.645]]}
{"kind": "depth", "E": 1787080655233, "U": 11315370729007, "u": 11315370735130, "recv_ms": 1787080655179, "bids": [[1000.0, 35.81], [14288.9, 1.008], [14388.9, 3.192], [14488.9, 0.0], [51751.0, 0.0], [58220.0, 4.018], [61454.4, 0.012], [62101.3, 2.788], [63071.7, 1.595], [63583.1, 0.005], [63700.9, 0.03], [64042.0, 2.169], [64518.8, 0.068], [64546.4, 0.014], [64549.3, 4.025], [64550.2, 1.534], [64572.0, 3.903], [64617.7, 2.381], [64634.5, 0.029], [64636.9, 0.825], [64662.8, 0.322], [64665.4, 0.745], [64666.7, 0.01], [64668.6, 0.001], [64668.7, 0.106], [64672.5, 0.006], [64672.7, 0.27], [64679.5, 0.001], [64681.7, 0.178], [64681.8, 0.664], [64681.9, 0.188], [64683.0, 0.729], [64683.8, 0.149], [64684.6, 0.002], [64684.7, 0.128], [64688.0, 0.167], [64688.9, 6.915]], "asks": [[64689.0, 11.831], [64690.9, 0.001], [64693.3, 0.001], [64694.0, 0.005], [64694.2, 0.085], [64697.3, 0.697], [64704.7, 0.001], [64705.0, 0.026], [64760.1, 0.047], [64824.4, 3.865], [64831.7, 3.886], [64848.7, 6.622], [64887.5, 7.934], [65335.9, 6.758], [65677.1, 0.068], [65982.7, 0.005]]}
{"kind": "depth", "E": 1787080655335, "U": 11315370735141, "u": 11315370741021, "recv_ms": 1787080655287, "bids": [[1000.0, 35.81], [14288.9, 1.358], [14388.9, 2.842], [51751.1, 0.0], [58220.0, 4.018], [62101.3, 2.785], [63688.9, 0.007], [63783.3, 38.608], [64042.0, 2.169], [64666.3, 1.95], [64672.5, 0.008], [64679.5, 0.464], [64681.7, 0.178], [64681.8, 0.201], [64683.0, 0.662], [64684.6, 0.252], [64684.7, 0.003]], "asks": [[64692.6, 0.613], [64692.7, 0.128], [64694.0, 0.012], [64695.4, 0.001], [64695.5, 0.135], [64696.2, 0.246], [64696.3, 0.482], [64705.0, 0.028], [64749.0, 0.064], [64749.2, 0.028], [64848.7, 6.322], [64887.5, 8.31], [65012.4, 3.843], [65335.9, 6.758], [65465.3, 39.713], [65538.0, 7.952], [65689.0, 10.015]]}
{"kind": "depth", "E": 1787080655437, "U": 11315370741234, "u": 11315370746461, "recv_ms": 1787080655383, "bids": [[14288.9, 1.722], [14388.9, 2.478], [58220.0, 4.018], [61454.4, 0.012], [62101.3, 2.788], [63718.6, 5.08], [64042.0, 2.169], [64171.4, 8.556], [64365.5, 6.042], [64549.3, 4.646], [64634.5, 0.001], [64656.3, 0.059], [64663.6, 0.579], [64664.6, 0.002], [64665.1, 0.559], [64666.1, 1.241], [64667.3, 2.491], [64669.6, 0.043], [64670.1, 1.37], [64671.0, 0.001], [64675.2, 0.574], [64678.7, 0.444], [64679.5, 0.001], [64681.7, 0.641], [64682.4, 0.022], [64683.0, 0.662], [64684.6, 0.127], [64688.0, 0.083], [64688.9, 6.914]], "asks": [[64689.0, 11.827], [64690.8, 0.091], [64692.6, 0.072], [64692.7, 0.128], [64694.0, 0.105], [64695.5, 0.599], [64696.3, 0.466], [64702.9, 0.659], [64703.5, 0.957], [64705.7, 0.0], [64706.3, 0.726], [64706.6, 0.001], [64707.2, 0.607], [64708.5, 0.329], [64709.8, 0.006], [64710.4, 0.124], [64714.9, 2.341], [64736.8, 0.011], [64740.7, 0.069], [64740.8, 1.261], [64829.2, 2.15], [64831.7, 5.399], [64848.7, 10.414], [64887.5, 4.159], [65335.9, 6.758], [65530.0, 22.926], [65982.7, 0.008]]}
{"kind": "depth", "E": 1787080655641, "U": 11315370751277, "u": 11315370757804, "recv_ms": 1787080655587, "bids": [[1000.0, 35.81], [14288.9, 2.422], [14388.9, 1.778], [58220.0, 4.018], [62101.3, 2.785], [63750.9, 35.411], [63939.8, 0.547], [64042.0, 2.169], [64145.5, 0.284], [64365.4, 0.0], [64679.5, 0.464], [64681.7, 0.178], [64681.8, 0.201], [64682.4, 0.156], [64683.0, 0.796], [64683.1, 0.001], [64684.6, 0.127]], "asks": [[64692.7, 0.128], [64694.0, 0.012], [64694.5, 0.014], [64695.4, 0.094], [64848.7, 10.414], [64887.5, 4.159], [65012.4, 3.997], [65335.9, 6.758], [65461.4, 3.737], [65465.3, 40.171], [65596.2, 0.952], [65627.0, 36.419]]}
{"kind": "depth", "E": 1787080655743, "U": 11315370757819, "u": 11315370762465, "recv_ms": 1787080655692, "bids": [[14288.9, 2.786], [14388.9, 1.414], [51751.0, 0.0], [58220.0, 4.018], [61454.4, 0.012], [62101.3, 2.788], [63688.9, 0.007], [63912.6, 39.344], [64042.0, 2.169], [64365.5, 6.042], [64493.5, 0.071], [64493.6, 8.155], [64532.4, 8.66], [64549.3, 4.621], [64623.4, 3.136], [64669.3, 5.126], [64684.6, 0.002], [64688.9, 7.015]], "asks": [[64689.0, 11.827], [64692.7, 0.128], [64694.0, 0.012], [64695.4, 0.094], [64755.1, 3.485], [64755.2, 0.007], [64775.6, 0.026], [64818.4, 0.216], [64831.7, 4.231], [64848.7, 6.365], [64887.5, 11.618], [65012.5, 0.003], [65335.9, 6.758], [65552.0, 0.002], [65689.0, 10.015]]}
{"kind": "depth", "E": 1787080655947, "U": 11315370769725, "u": 11315370774635, "recv_ms": 1787080655893, "bids": [[1000.0, 35.81], [14288.9, 3.5], [14388.9, 0.7], [58220.0, 4.018], [62101.3, 2.788], [63688.9, 0.027], [64042.0, 2.169], [64493.6, 11.091], [64532.4, 9.935], [64549.3, 5.239], [64611.2, 0.0], [64643.6, 0.441], [64679.5, 0.464], [64681.7, 0.178], [64681.9, 0.12], [64683.0, 0.662], [64684.6, 0.002], [64686.5, 0.022], [64687.4, 0.085], [64687.7, 0.543], [64687.8, 0.0], [64688.9, 7.005]], "asks": [[64689.0, 11.827], [64692.7, 0.669], [64694.0, 0.012], [64694.8, 0.04], [64695.5, 0.074], [64718.6, 0.0], [64734.3, 0.303], [64766.7, 0.2], [64887.5, 4.159], [65206.5, 8.11], [65335.9, 6.758], [65588.2, 12.48], [65603.7, 0.227], [65689.0, 10.035]]}
{"kind": "depth", "E": 1787080656049, "U": 11315370774696, "u": 11315370780777, "recv_ms": 1787080655996, "bids": [[14188.9, 0.056], [14288.9, 3.752], [14388.9, 0.392], [58220.0, 4.018], [61454.4, 0.012], [63395.2, 0.086], [63791.0, 33.674], [63827.5, 0.043], [64009.7, 3.273], [64017.5, 5.547], [64042.0, 2.169], [64365.5, 6.042], [64493.6, 11.091], [64532.4, 9.935], [64549.3, 5.239], [64677.3, 0.007], [64679.5, 0.001], [64681.7, 0.641], [64681.9, 0.37], [64688.9, 6.905]], "asks": [[64692.5, 0.08], [64692.6, 0.072], [64692.7, 0.112], [64694.0, 0.037], [64695.5, 0.606], [64718.4, 1.28], [64718.6, 0.0], [64831.7, 5.399], [64848.7, 10.414], [64887.5, 6.523], [65012.5, 0.002], [65335.9, 6.758], [65627.0, 35.354], [65647.9, 4.714], [67276.6, 1.908]]}
{"kind": "depth", "E": 1787080656355, "U": 11315370799632, "u": 11315370807273, "recv_ms": 1787080656301, "bids": [[14188.9, 0.742], [14288.9, 3.444], [14388.9, 0.014], [51751.0, 0.0], [51751.1, 0.0], [58220.0, 4.018], [62101.3, 2.785], [63688.9, 0.027], [63750.9, 34.315], [63766.6, 0.008], [63841.4, 0.274], [63945.0, 8.908], [64042.0, 2.169], [64365.5, 6.042], [64672.5, 0.008], [64679.5, 0.001], [64681.7, 0.641], [64681.8, 0.201], [64681.9, 0.12], [64682.0, 0.173], [64683.8, 0.274], [64684.6, 0.002], [64688.8, 0.156]], "asks": [[64705.0, 0.028], [64718.6, 0.0], [64848.7, 10.414], [64887.5, 4.147], [65335.9, 6.758], [65639.9, 10.797], [65689.0, 10.035]]}
{"kind": "depth", "E": 1787080656457, "U": 11315370807300, "u": 11315370811585, "recv_ms": 1787080656403, "bids": [[1000.0, 35.81], [14188.9, 1.078], [14288.9, 3.122], [14388.9, 0.0], [58220.0, 4.018], [61454.4, 0.006], [64042.0, 2.169], [64550.2, 2.116], [64658.9, 2.9], [64662.1, 0.187], [64668.0, 0.125], [64668.5, 0.016], [64674.9, 1.714], [64675.3, 0.262], [64679.5, 0.464], [64681.7, 0.178], [64681.8, 0.201], [64681.9, 0.105], [64683.8, 0.399], [64688.9, 6.999]], "asks": [[64689.0, 11.827], [64691.1, 0.015], [64718.7, 0.159], [64718.8, 0.022], [64809.8, 0.016], [64809.9, 0.014], [64816.6, 0.015], [64816.9, 0.005], [65335.9, 6.758]]}
{"kind": "depth", "E": 1787080656661, "U": 11315370816306, "u": 11315370820330, "recv_ms": 1787080656608, "bids": [[14188.9, 1.806], [14288.9, 2.394], [51751.0, 0.0], [58220.0, 4.018], [61454.4, 0.006], [62101.3, 2.785], [63065.2, 0.004], [63750.9, 35.411], [63945.0, 9.844], [64042.0, 2.169], [64365.5, 6.052], [64549.3, 5.239], [64559.7, 0.023], [64566.2, 0.002], [64566.5, 0.028], [64573.0, 0.46], [64579.3, 0.831], [64585.2, 0.909], [64591.1, 0.005], [64597.0, 0.127], [64602.9, 0.001], [64608.8, 0.095], [64614.7, 0.0], [64679.5, 0.464], [64679.6, 0.015], [64681.7, 0.17], [64681.8, 0.201], [64681.9, 0.105], [64683.8, 0.274], [64683.9, 0.158], [64688.9, 6.998]], "asks": [[64689.0, 11.718], [64718.7, 0.005], [64718.9, 0.003], [64831.7, 5.399], [65335.9, 6.758], [65863.1, 0.773]]}
{"kind": "depth", "E": 1787080656865, "U": 11315370824608, "u": 11315370834317, "recv_ms": 1787080656812, "bids": [[1000.0, 35.81], [14188.9, 2.506], [14288.9, 1.694], [58220.0, 4.018], [62101.3, 2.785], [63589.2, 16.148], [63696.9, 0.022], [63880.3, 23.347], [64042.0, 2.169], [64171.2, 0.158], [64493.6, 10.599], [64532.4, 8.66], [64549.3, 0.027], [64549.4, 4.594], [64580.1, 0.015], [64586.9, 0.017], [64623.4, 3.154], [64643.6, 0.444], [64679.6, 0.007], [64681.7, 0.178], [64683.8, 0.399], [64683.9, 0.033]], "asks": [[64692.7, 0.112], [64693.7, 0.156], [64694.0, 0.121], [64696.4, 1.409], [64705.5, 1.88], [64706.3, 0.17], [64715.2, 1.256], [64718.7, 0.005], [64718.9, 0.003], [64734.3, 0.306], [64755.1, 3.474], [64831.7, 5.399], [64848.7, 6.366], [64887.5, 8.239], [65335.9, 6.758], [65453.9, 0.537], [65603.7, 0.0], [65699.7, 4.256]]}
{"kind": "depth", "E": 1787080657069, "U": 11315370842184, "u": 11315370848886, "recv_ms": 1787080657017, "bids": [[1000.0, 35.81], [14188.9, 3.22], [14288.9, 0.98], [58220.0, 4.018], [61454.4, 0.006], [62101.3, 2.788], [63395.2, 0.089], [63718.6, 5.433], [63945.0, 8.907], [64042.0, 2.169], [64600.5, 0.167], [64607.3, 2.416], [64642.0, 5.778], [64642.1, 0.008], [64650.3, 2.135], [64650.4, 0.629], [64658.6, 2.511], [64658.7, 0.052], [64672.7, 0.27], [64677.3, 0.002], [64681.9, 0.239], [64682.4, 0.056], [64683.1, 0.001], [64684.6, 0.002], [64687.8, 0.084], [64688.8, 0.258], [64688.9, 6.802]], "asks": [[64689.0, 11.607], [64690.8, 0.007], [64691.1, 0.012], [64691.6, 0.004], [64693.2, 0.287], [64694.0, 0.662], [64694.4, 0.036], [64695.4, 0.464], [64695.5, 0.058], [64696.3, 0.003], [64697.3, 0.543], [64715.2, 2.22], [64791.4, 2.155], [64791.5, 0.0], [64799.7, 2.134], [64799.8, 0.001], [64808.0, 6.42], [64808.1, 0.0], [64879.4, 0.407], [64879.5, 0.006], [64887.5, 4.06], [65305.1, 0.214], [65335.9, 6.759], [65493.8, 3.933], [65691.7, 19.91]]}
{"kind": "depth", "E": 1787080657171, "U": 11315370848942, "u": 11315370857231, "recv_ms": 1787080657121, "bids": [[14188.9, 3.584], [14288.9, 0.616], [58220.0, 4.018], [61454.4, 0.006], [62101.3, 2.785], [63688.9, 0.027], [63711.9, 0.822], [63847.9, 21.658], [63908.9, 4.999], [64042.0, 2.169], [64365.4, 0.001], [64365.5, 5.887], [64614.1, 0.028], [64643.6, 0.444], [64679.5, 0.001], [64681.7, 0.633], [64681.8, 0.209], [64681.9, 0.23], [64682.4, 0.022], [64685.5, 0.088], [64686.5, 0.02], [64687.4, 0.001], [64687.7, 0.253], [64687.8, 0.0], [64688.9, 6.802]], "asks": [[64689.0, 11.609], [64690.0, 0.801], [64690.6, 0.086], [64692.5, 0.621], [64692.6, 0.072], [64692.7, 0.128], [64693.2, 0.29], [64693.7, 0.377], [64694.0, 0.012], [64695.2, 0.015], [64695.4, 0.001], [64695.5, 0.151], [64696.3, 0.466], [64696.4, 1.874], [64697.3, 0.697], [64698.5, 0.525], [64718.5, 0.34], [64718.7, 0.005], [64734.3, 0.306], [64848.7, 6.914], [64887.5, 11.689], [65012.4, 3.843], [65206.5, 8.11], [65335.9, 6.759], [65458.8, 8.241], [65465.3, 39.409], [65689.0, 10.035]]}
{"kind": "depth", "E": 1787080657273, "U": 11315370857977, "u": 11315370867229, "recv_ms": 1787080657220, "bids": [[14188.9, 3.766], [14288.9, 0.35], [14588.9, 0.084], [51751.0, 0.0], [58220.0, 4.018], [61454.4, 0.006], [61454.5, 2.469], [62101.3, 2.788], [63395.2, 0.092], [63688.9, 0.007], [63770.3, 3.985], [64042.0, 2.169], [64365.5, 6.042], [64620.9, 0.015], [64627.7, 0.04], [64667.3, 0.412], [64671.6, 0.043], [64672.4, 0.002], [64672.7, 0.27], [64674.7, 0.071], [64679.5, 0.472], [64681.7, 0.17], [64681.8, 0.201], [64681.9, 0.173], [64682.4, 0.115], [64683.0, 0.569], [64684.6, 0.002], [64687.0, 0.093], [64687.5, 0.024], [64688.8, 0.248]], "asks": [[64689.0, 11.609], [64691.2, 1.143], [64691.7, 0.084], [64692.0, 0.905], [64692.2, 0.095], [64692.5, 0.621], [64692.6, 0.072], [64692.7, 0.128], [64694.0, 0.005], [64695.4, 0.001], [64695.5, 0.135], [64696.3, 0.482], [64699.3, 0.38], [64705.5, 1.324], [64705.8, 0.56], [64718.5, 0.494], [64848.7, 10.414], [64887.5, 4.173], [65012.4, 3.997], [65012.5, 0.002], [65206.5, 8.416], [65297.1, 0.687], [65335.9, 6.759], [65465.3, 40.171], [65493.8, 3.704], [65689.0, 10.015]]}
{"kind": "depth", "E": 1787080657375, "U": 11315370867270, "u": 11315370878812, "recv_ms": 1787080657323, "bids": [[1000.0, 35.81], [14188.9, 3.654], [14288.9, 0.224], [14588.9, 0.322], [51751.0, 0.0], [51751.1, 0.0], [58220.0, 4.018], [61454.5, 2.467], [61454.6, 0.004], [62101.3, 2.785], [63395.2, 0.083], [63945.0, 9.844], [64042.0, 2.169], [64613.7, 1.305], [64615.5, 0.095], [64617.3, 0.025], [64626.1, 0.085], [64627.9, 0.0], [64628.8, 1.141], [64629.7, 0.031], [64630.7, 0.04], [64632.5, 0.01], [64633.9, 0.21], [64634.5, 0.03], [64636.9, 0.844], [64638.8, 0.001], [64640.6, 0.003], [64642.4, 1.628], [64650.0, 2.838], [64651.1, 0.654], [64652.6, 0.019], [64654.2, 0.002], [64658.2, 1.063], [64658.4, 0.12], [64658.9, 2.564], [64660.6, 0.37], [64662.0, 0.207], [64662.5, 0.203], [64663.1, 0.311], [64664.8, 0.61], [64665.1, 0.002], [64665.2, 0.002], [64665.4, 0.007], [64666.1, 1.357], [64666.4, 0.001], [64666.5, 0.037], [64667.0, 0.903], [64667.2, 1.243], [64667.8, 0.479], [64668.3, 0.315], [64668.6, 0.001], [64669.4, 0.01], [64669.6, 0.969], [64670.0, 1.36], [64670.1, 0.444], [64670.3, 0.058], [64670.5, 0.386], [64671.0, 0.007], [64671.6, 0.036], [64672.0, 0.909], [64672.5, 0.008], [64673.8, 0.009], [64674.0, 0.37], [64674.9, 1.714], [64675.1, 1.956], [64675.3, 0.702], [64675.6, 0.0], [64676.0, 0.169], [64677.2, 0.001], [64677.5, 0.321], [64678.5, 1.017], [64678.7, 0.003], [64679.1, 0.0], [64679.3, 0.235], [64679.5, 0.001], [64679.6, 0.002], [64680.3, 0.007], [64681.4, 0.144], [64681.5, 1.127], [64681.6, 2.152], [64681.9, 0.105], [64682.0, 0.257], [64682.3, 0.154], [64682.4, 0.022], [64682.7, 0.089], [64683.0, 0.553], [64683.1, 0.085], [64683.2, 0.002], [64683.5, 0.111], [64683.6, 0.035], [64683.7, 0.0], [64683.8, 0.191], [64684.0, 0.001], [64684.4, 2.006], [64684.5, 0.026], [64684.6, 0.233], [64684.7, 0.002], [64685.0, 0.005], [64685.1, 0.151], [64685.2, 0.11], [64685.5, 0.0], [64686.0, 0.001], [64686.3, 0.0], [64686.6, 0.001], [64686.7, 0.002], [64686.9, 0.0], [64687.0, 0.0], [64687.2, 0.0], [64687.3, 0.001], [64687.5, 0.002], [64687.7, 0.001], [64688.0, 0.003], [64688.8, 0.168], [64688.9, 4.288]], "asks": [[64689.0, 11.712], [64689.3, 0.084], [64689.8, 0.119], [64691.0, 0.003], [64691.1, 0.02], [64691.2, 1.14], [64691.8, 0.648], [64691.9, 0.048], [64692.1, 0.003], [64692.3, 0.819], [64692.5, 0.08], [64692.7, 0.15], [64692.8, 1.002], [64693.1, 0.398], [64694.2, 0.001], [64694.3, 0.023], [64694.5, 0.013], [64695.2, 0.014], [64695.4, 0.31], [64695.5, 0.074], [64696.2, 0.254], [64696.3, 0.466], [64696.4, 1.844], [64696.7, 2.504], [64697.0, 1.068], [64697.3, 0.697], [64697.5, 0.235], [64698.0, 0.124], [64699.1, 0.005], [64700.0, 0.712], [64701.0, 1.691], [64702.0, 2.998], [64702.1, 1.072], [64702.2, 0.001], [64702.5, 0.012], [64702.7, 0.003], [64703.4, 0.322], [64703.5, 0.032], [64703.7, 0.033], [64705.0, 0.603], [64705.3, 0.15], [64705.4, 0.007], [64705.5, 1.343], [64705.8, 0.061], [64706.2, 0.594], [64706.6, 0.001], [64706.8, 0.001], [64707.2, 0.565], [64707.3, 1.264], [64707.5, 2.612], [64707.8, 0.348], [64708.6, 2.924], [64708.7, 0.003], [64709.0, 0.268], [64709.1, 10.155], [64709.2, 0.002], [64709.4, 0.003], [64709.7, 0.004], [64710.1, 0.003], [64712.0, 1.245], [64712.8, 0.022], [64713.2, 0.357], [64713.5, 0.311], [64714.3, 2.286], [64716.2, 0.08], [64718.5, 0.34], [64718.6, 0.154], [64733.0, 0.0], [64735.6, 0.001], [64753.7, 0.105], [64848.7, 7.038], [64887.5, 8.965], [65335.9, 6.759], [65458.8, 9.157], [65465.3, 40.385]]}
{"kind": "depth", "E": 1787080657477, "U": 11315370878977, "u": 11315370885907, "recv_ms": 1787080657426, "bids": [[14188.9, 3.528], [14288.9, 0.112], [14588.9, 0.56], [58220.0, 4.018], [61454.4, 0.006], [63688.9, 0.027], [63919.1, 8.438], [64042.0, 2.169], [64317.2, 0.002], [64319.9, 0.374], [64343.3, 0.0], [64413.8, 0.0], [64415.1, 0.537], [64484.7, 0.0], [64485.5, 1.278], [64625.4, 0.033], [64641.3, 0.017], [64648.1, 0.07], [64653.7, 0.082], [64654.3, 0.166], [64654.9, 0.015], [64667.7, 0.009], [64673.5, 0.009], [64675.1, 1.832], [64680.3, 0.006], [64681.3, 0.001], [64681.7, 0.17], [64681.9, 0.105], [64683.7, 0.31], [64683.8, 0.19], [64684.5, 0.027], [64684.6, 0.001], [64684.7, 0.086], [64685.3, 0.232], [64687.4, 0.103], [64688.8, 0.066], [64688.9, 4.288]], "asks": [[64689.0, 11.595], [64691.1, 0.012], [64691.8, 0.64], [64692.0, 0.005], [64692.2, 0.111], [64693.7, 0.347], [64694.2, 0.002], [64694.7, 0.028], [64695.1, 0.039], [64696.7, 2.424], [64700.0, 0.392], [64700.2, 0.243], [64703.2, 0.715], [64704.0, 0.262], [64706.2, 0.592], [64706.9, 0.003], [64816.6, 0.0], [64848.7, 10.414], [64881.2, 0.002], [64883.3, 0.689], [64883.9, 0.0], [64887.5, 5.041], [64954.7, 1.248], [64955.3, 0.004], [65049.8, 2.924], [65052.7, 0.0], [65335.9, 6.761], [65539.7, 8.384], [65689.0, 10.035]]}
{"kind": "depth", "E": 1787080657579, "U": 11315370885915, "u": 11315370893042, "recv_ms": 1787080657525, "bids": [[14188.9, 3.402], [14288.9, 0.0], [14588.9, 0.798], [58220.0, 4.018], [61454.4, 0.006], [62101.3, 2.788], [63686.2, 17.252], [63876.5, 3.077], [63920.4, 20.078], [64042.0, 2.169], [64053.7, 0.055], [64145.5, 0.308], [64201.4, 0.015], [64365.5, 6.052], [64650.3, 2.149], [64656.0, 0.869], [64656.1, 0.0], [64656.2, 0.001], [64659.4, 0.006], [64659.5, 0.001], [64659.6, 0.0], [64664.1, 0.692], [64664.8, 0.053], [64669.1, 0.928], [64669.6, 0.043], [64675.0, 3.361], [64682.1, 0.117], [64685.3, 0.0], [64685.7, 0.234], [64688.9, 4.29]], "asks": [[64689.0, 11.743], [64694.1, 2.632], [64694.2, 0.025], [64694.3, 0.003], [64694.7, 0.006], [64695.1, 0.054], [64706.1, 0.816], [64707.2, 0.024], [64707.9, 0.055], [64716.2, 0.031], [64816.6, 0.0], [64848.7, 10.414], [64887.5, 5.257], [65169.8, 0.0], [65318.4, 0.0], [65335.9, 6.759], [65465.3, 38.555]]}
{"kind": "depth", "E": 1787080657783, "U": 11315370898425, "u": 11315370904571, "recv_ms": 1787080657728, "bids": [[14188.9, 2.674], [14588.9, 1.526], [34000.0, 1.146], [51751.0, 0.006], [58220.0, 4.018], [61454.4, 0.007], [61454.5, 2.465], [61454.6, 0.006], [62101.3, 2.788], [63653.9, 5.929], [63688.9, 0.007], [64042.0, 2.169], [64053.8, 63.201], [64365.4, 0.0], [64666.8, 0.028], [64673.5, 0.008], [64681.6, 2.277], [64681.7, 0.295], [64682.4, 0.007], [64688.8, 0.217]], "asks": [[64689.0, 11.743], [64694.2, 0.024], [64710.1, 5.003], [64711.6, 0.047], [64818.4, 0.213], [64848.7, 6.865], [64887.5, 9.174], [65012.5, 0.003], [65168.5, 50.71], [65335.9, 6.761], [65689.0, 10.015], [65724.0, 10.466]]}
{"kind": "depth", "E": 1787080657885, "U": 11315370904674, "u": 11315370916611, "recv_ms": 1787080657833, "bids": [[14188.9, 2.324], [14588.9, 1.876], [51751.0, 0.0], [58220.0, 4.018], [61454.4, 0.007], [64042.0, 2.169], [64171.4, 8.245], [64365.5, 6.042], [64630.6, 0.004], [64681.6, 2.152], [64681.7, 0.17], [64682.1, 0.117], [64682.2, 0.171], [64682.3, 0.279], [64688.9, 4.275]], "asks": [[64766.7, 0.203], [64786.1, 0.025], [64887.5, 8.862], [65206.5, 8.416], [65335.9, 6.759], [65433.6, 10.08], [65465.3, 40.385], [65473.3, 27.856], [65497.6, 19.848], [65982.7, 0.011]]}
{"kind": "depth", "E": 1787080657987, "U": 11315370916891, "u": 11315370924110, "recv_ms": 1787080657933, "bids": [[1000.0, 35.81], [14188.9, 1.96], [14588.9, 2.24], [58220.0, 4.018], [61454.4, 0.007], [62101.3, 2.785], [63688.9, 0.027], [63912.6, 42.469], [63945.0, 8.907], [64042.0, 2.169], [64171.4, 8.245], [64365.5, 5.887], [64475.0, 0.113], [64484.9, 0.216], [64620.7, 6.93], [64652.5, 0.071], [64653.7, 0.025], [64663.0, 0.579], [64664.1, 0.135], [64664.7, 1.822], [64665.5, 0.081], [64668.0, 1.051], [64669.1, 0.002], [64682.1, 0.117], [64682.2, 0.296], [64682.3, 0.154], [64684.1, 0.023], [64688.9, 4.38]], "asks": [[64690.9, 0.001], [64691.8, 0.006], [64692.1, 0.02], [64692.2, 0.165], [64694.2, 0.001], [64694.4, 0.013], [64695.5, 0.113], [64696.1, 0.587], [64696.2, 0.254], [64699.1, 0.085], [64700.2, 0.163], [64700.6, 0.0], [64701.3, 1.092], [64702.1, 0.147], [64704.3, 0.126], [64705.2, 0.065], [64705.8, 0.004], [64707.3, 1.264], [64848.7, 10.414], [64887.5, 5.031], [65049.8, 9.065], [65051.4, 43.923], [65335.9, 6.759], [65689.0, 10.035]]}
{"kind": "depth", "E": 1787080658089, "U": 11315370924407, "u": 11315370935311, "recv_ms": 1787080658034, "bids": [[14188.9, 1.596], [14588.9, 2.604], [58220.0, 4.018], [61454.4, 0.006], [62101.3, 2.788], [63700.8, 1.718], [64042.0, 2.169], [64647.2, 0.032], [64663.0, 0.022], [64663.1, 0.868], [64663.7, 0.003], [64664.7, 1.822], [64665.5, 0.081], [64677.3, 0.002], [64682.1, 0.117], [64682.2, 0.171], [64682.3, 0.154], [64683.8, 0.171], [64684.1, 0.046], [64688.9, 4.375]], "asks": [[64692.1, 0.043], [64692.2, 0.745], [64695.3, 0.016], [64695.5, 0.074], [64696.1, 0.046], [64696.2, 0.246], [64696.3, 0.474], [64699.1, 0.005], [64700.2, 0.243], [64703.3, 0.0], [64704.1, 0.493], [64704.2, 1.021], [64705.0, 0.047], [64705.5, 1.257], [64708.3, 0.213], [64709.0, 0.153], [64718.5, 0.34], [64718.6, 0.154], [64848.7, 6.865], [64887.5, 9.151], [65335.9, 6.758], [65465.3, 43.436], [65677.0, 0.01]]}
{"kind": "depth", "E": 1787080658191, "U": 11315370935436, "u": 11315370943186, "recv_ms": 1787080658137, "bids": [[1000.0, 35.81], [14188.9, 1.246], [14588.9, 2.954], [51751.0, 0.0], [58220.0, 4.018], [62101.3, 2.785], [63688.9, 0.007], [63700.8, 1.728], [63726.3, 1.41], [63750.9, 34.314], [64042.0, 2.169], [64145.5, 0.218], [64171.4, 8.556], [64365.5, 6.042], [64666.2, 2.558], [64682.1, 0.117]], "asks": [[64690.8, 0.007], [64690.9, 0.001], [64692.1, 0.043], [64692.2, 0.745], [64695.5, 0.074], [64696.1, 0.046], [64696.2, 0.246], [64696.3, 0.474], [64697.2, 0.275], [64718.6, 0.0], [64718.8, 0.176], [64848.7, 10.414], [64887.5, 5.031], [65012.5, 0.002], [65330.9, 0.19], [65335.9, 6.758], [65647.9, 4.181], [65689.0, 10.015], [65724.0, 9.402]]}
{"kind": "depth", "E": 1787080658293, "U": 11315370943212, "u": 11315370951398, "recv_ms": 1787080658239, "bids": [[1000.0, 35.81], [14188.9, 0.896], [14588.9, 3.304], [51751.0, 0.0], [58220.0, 4.018], [61454.4, 0.006], [62101.3, 2.788], [63653.9, 4.831], [63809.5, 1.409], [63945.0, 9.844], [64042.0, 2.169], [64365.4, 0.001], [64549.4, 5.065], [64550.2, 1.534], [64665.0, 1.122], [64672.4, 0.62], [64682.1, 0.367], [64683.8, 0.149], [64684.6, 0.02], [64688.9, 4.364]], "asks": [[64689.0, 11.623], [64690.8, 0.007], [64690.9, 0.001], [64692.1, 0.043], [64692.2, 0.088], [64696.1, 0.61], [64696.2, 0.339], [64696.9, 0.376], [64700.2, 0.163], [64701.0, 1.771], [64703.2, 0.715], [64704.3, 0.744], [64718.7, 0.159], [64718.8, 0.022], [64726.7, 5.274], [64726.8, 0.002], [64795.3, 4.461], [64795.7, 0.001], [64829.2, 2.15], [64831.7, 5.399], [64864.0, 4.024], [64864.6, 0.005], [64887.5, 4.718], [65335.9, 6.758], [65677.0, 0.02]]}
{"kind": "depth", "E": 1787080658395, "U": 11315370951528, "u": 11315370958205, "recv_ms": 1787080658342, "bids": [[14188.9, 0.532], [14588.9, 3.668], [51751.1, 0.0], [58220.0, 4.018], [61454.4, 0.006], [63459.5, 0.001], [63688.9, 0.027], [63718.6, 7.0], [63750.9, 33.217], [63945.0, 8.907], [64042.0, 2.169], [64549.4, 4.987], [64650.0, 2.852], [64672.4, 0.002], [64672.5, 0.008], [64676.2, 0.043], [64678.4, 1.908], [64681.6, 2.068], [64681.7, 0.17], [64682.1, 0.117], [64684.5, 0.049], [64685.2, 0.11], [64685.7, 0.318], [64688.9, 4.365]], "asks": [[64689.0, 11.632], [64690.9, 0.001], [64692.1, 0.043], [64692.2, 0.172], [64695.5, 0.074], [64696.1, 0.078], [64696.2, 0.787], [64696.3, 0.474], [64705.0, 0.047], [64712.8, 0.042], [64718.7, 0.005], [64718.8, 0.176], [64753.7, 0.123], [64829.2, 1.531], [64831.7, 5.399], [64848.7, 6.865], [64887.5, 9.151], [65323.0, 0.724], [65335.9, 6.758], [65689.0, 10.035]]}
{"kind": "depth", "E": 1787080658497, "U": 11315370958318, "u": 11315370963917, "recv_ms": 1787080658444, "bids": [[1000.0, 35.81], [14188.9, 0.322], [14488.9, 0.14], [14588.9, 3.738], [58220.0, 4.018], [61454.4, 0.006], [62101.3, 2.785], [63499.9, 3.925], [63653.9, 5.929], [63750.9, 34.314], [64042.0, 2.169], [64200.8, 54.43], [64365.5, 6.042], [64630.6, 0.001], [64643.6, 0.444], [64650.0, 2.932], [64651.1, 0.318], [64655.3, 0.355], [64668.0, 0.125], [64669.1, 0.928], [64675.4, 0.008], [64681.6, 2.068], [64681.7, 0.304], [64681.8, 0.335], [64681.9, 0.105], [64682.0, 0.173], [64683.0, 0.005], [64683.1, 0.085], [64683.2, 0.543], [64685.2, 0.267], [64686.2, 0.086], [64686.3, 0.093], [64688.9, 4.59]], "asks": [[64689.0, 11.625], [64689.3, 0.0], [64689.5, 0.007], [64689.8, 0.116], [64690.2, 0.003], [64690.8, 0.007], [64690.9, 0.001], [64692.1, 0.001], [64692.2, 0.629], [64695.1, 0.054], [64695.5, 0.074], [64696.1, 0.069], [64696.2, 0.347], [64696.3, 0.466], [64701.0, 1.691], [64701.3, 0.167], [64701.8, 0.926], [64702.2, 0.081], [64702.5, 0.005], [64703.3, 0.007], [64704.3, 0.126], [64706.1, 0.275], [64707.2, 0.565], [64708.3, 0.098], [64709.0, 0.268], [64718.7, 0.159], [64718.8, 0.022], [64734.3, 0.306], [64766.7, 0.2], [64816.6, 0.0], [64848.7, 10.414], [64887.5, 5.284], [65318.0, 67.384], [65335.9, 6.758], [65575.2, 3.042], [65639.9, 11.33], [65724.0, 10.466], [65982.7, 0.014]]}
{"kind": "depth", "E": 1787080658599, "U": 11315370963996, "u": 11315370969134, "recv_ms": 1787080658546, "bids": [[1000.0, 35.81], [14188.9, 0.196], [14488.9, 0.378], [14588.9, 3.626], [58220.0, 4.018], [62101.3, 2.788], [63492.2, 5.821], [63564.6, 4.637], [63688.9, 0.007], [63815.6, 15.179], [64042.0, 2.169], [64048.2, 0.0], [64156.5, 0.002], [64350.5, 0.045], [64652.5, 0.014], [64654.0, 0.063], [64685.2, 0.017]], "asks": [[64690.2, 0.0], [64690.6, 0.089], [64690.9, 0.017], [64692.1, 0.008], [64695.4, 0.001], [64696.1, 0.046], [64696.2, 0.347], [64696.4, 2.153], [64701.8, 0.001], [64702.3, 1.064], [64705.2, 0.008], [64705.9, 0.215], [64718.7, 0.005], [64848.7, 7.007], [64887.5, 9.17], [65191.4, 0.0], [65335.9, 6.758], [65450.1, 3.051], [65607.6, 4.318], [65655.5, 4.573], [65689.0, 10.015]]}
{"kind": "depth", "E": 1787080658701, "U": 11315370969235, "u": 11315370975972, "recv_ms": 1787080658647, "bids": [[14188.9, 0.07], [14488.9, 0.616], [14588.9, 3.514], [51751.0, 0.0], [58220.0, 4.018], [61454.4, 0.006], [62101.3, 2.785], [63395.2, 0.08], [63750.9, 35.411], [63888.1, 3.909], [63912.6, 40.594], [63945.0, 9.844], [64042.0, 2.169], [64588.4, 0.027], [64588.5, 0.008], [64675.4, 0.008], [64681.6, 2.202], [64681.8, 0.269], [64683.3, 0.034], [64684.5, 0.299]], "asks": [[64689.0, 11.601], [64689.6, 0.112], [64690.9, 0.001], [64692.1, 0.001], [64692.2, 0.088], [64693.2, 0.287], [64695.4, 0.009], [64695.5, 0.615], [64696.1, 0.069], [64696.2, 0.339], [64704.2, 0.465], [64705.2, 0.564], [64708.4, 0.375], [64718.7, 0.159], [64848.7, 10.414], [64887.5, 7.503], [65335.9, 6.758]]}
{"kind": "depth", "E": 1787080658803, "U": 11315370976050, "u": 11315370986083, "recv_ms": 1787080658749, "bids": [[1000.0, 35.81], [14188.9, 0.0], [14488.9, 0.896], [14588.9, 3.304], [58220.0, 4.018], [61454.4, 0.007], [62101.3, 2.788], [63556.8, 7.542], [63688.9, 0.027], [63912.6, 42.688], [64040.2, 1.329], [64042.0, 2.169], [64365.5, 6.052], [64675.4, 0.001], [64681.6, 2.068], [64681.8, 0.201], [64683.3, 0.041], [64684.5, 0.049], [64687.9, 0.046], [64688.8, 0.066], [64688.9, 4.569]], "asks": [[64689.0, 11.601], [64689.5, 0.0], [64690.0, 0.808], [64693.1, 0.418], [64718.7, 0.005], [64718.8, 0.176], [64818.4, 0.213], [65012.5, 0.001], [65335.9, 6.758], [65465.3, 45.265], [65497.6, 20.077], [65689.0, 10.035]]}
{"kind": "depth", "E": 1787080658905, "U": 11315370986254, "u": 11315370991965, "recv_ms": 1787080658851, "bids": [[1000.0, 35.81], [14488.9, 1.246], [14588.9, 2.954], [58220.0, 4.018], [61454.4, 0.006], [63826.2, 0.009], [63880.3, 24.129], [64042.0, 2.169], [64171.4, 9.8], [64365.4, 0.002], [64365.5, 6.828], [64367.8, 1.741], [64658.9, 2.562], [64669.1, 0.002], [64670.2, 0.929], [64675.4, 0.001], [64681.6, 2.202], [64681.7, 0.17], [64683.3, 0.041], [64684.5, 0.299], [64685.7, 0.086], [64686.4, 0.236], [64688.9, 4.57]], "asks": [[64689.0, 11.6], [64689.1, 0.245], [64691.0, 0.003], [64691.3, 0.003], [64692.2, 0.652], [64692.4, 0.005], [64692.7, 0.15], [64695.1, 0.039], [64695.4, 0.001], [64695.5, 0.074], [64696.1, 0.046], [64696.2, 0.347], [64718.8, 0.176], [64721.5, 0.0], [64816.6, 0.015], [64831.7, 3.697], [64848.7, 5.078], [64887.5, 7.589], [65206.5, 9.64], [65335.9, 6.758], [65659.3, 17.679], [65973.6, 0.0]]}
{"kind": "depth", "E": 1787080659007, "U": 11315370992329, "u": 11315370998059, "recv_ms": 1787080658954, "bids": [[14488.9, 1.61], [14588.9, 2.59], [58220.0, 4.018], [61454.4, 0.006], [61454.5, 2.463], [61454.6, 0.008], [62101.3, 2.785], [63621.5, 6.517], [63688.9, 0.007], [63750.9, 34.314], [63797.5, 1.845], [63912.6, 42.219], [64042.0, 2.169], [64365.5, 6.828], [64549.4, 4.351], [64656.0, 0.871], [64656.1, 0.002], [64656.2, 0.003], [64658.9, 2.564], [64659.4, 0.008], [64659.5, 0.003], [64659.6, 0.002], [64675.4, 0.001], [64681.6, 2.068], [64681.7, 0.17], [64683.0, 0.553], [64683.2, 0.002], [64683.3, 0.034], [64684.5, 0.049], [64686.5, 0.119], [64688.9, 4.585]], "asks": [[64692.1, 0.542], [64692.2, 0.111], [64692.7, 0.15], [64693.3, 0.023], [64695.1, 0.054], [64695.5, 0.082], [64696.2, 0.339], [64701.6, 0.039], [64719.9, 0.105], [64721.5, 0.002], [64816.6, 0.0], [65335.9, 6.758], [65497.6, 20.306], [65627.0, 34.289], [65689.0, 10.015], [65982.7, 0.017], [71157.9, 0.0]]}
{"kind": "depth", "E": 1787080659313, "U": 11315371008189, "u": 11315371013067, "recv_ms": 1787080659260, "bids": [[14488.9, 2.688], [14588.9, 1.512], [58220.0, 4.018], [61454.4, 0.006], [63686.2, 17.252], [63750.9, 35.411], [63770.3, 4.454], [63789.7, 16.36], [63880.3, 24.394], [64042.0, 2.169], [64365.4, 0.001], [64365.5, 6.818], [64549.4, 5.104], [64628.9, 0.002], [64629.3, 0.005], [64629.6, 0.0], [64629.9, 0.0], [64630.2, 1.852], [64646.8, 0.003], [64647.2, 0.0], [64647.5, 0.004], [64647.8, 0.001], [64648.1, 0.038], [64652.6, 0.005], [64661.8, 0.009], [64661.9, 0.609], [64662.0, 0.137], [64662.1, 0.017], [64662.2, 0.0], [64662.3, 0.85], [64662.4, 2.363], [64662.5, 0.033], [64662.7, 0.001], [64663.9, 0.001], [64664.3, 0.06], [64664.4, 0.558], [64665.1, 0.002], [64666.1, 1.357], [64666.8, 0.028], [64669.4, 0.936], [64670.2, 0.003], [64672.7, 0.259], [64674.7, 0.689], [64675.4, 0.542], [64675.6, 0.007], [64681.4, 0.004], [64681.5, 1.057], [64681.6, 1.928], [64681.7, 0.101], [64681.8, 0.001], [64681.9, 0.005], [64682.0, 0.003], [64682.1, 0.017], [64682.2, 0.001], [64682.3, 0.0], [64682.6, 0.003], [64682.9, 1.889], [64683.0, 0.005], [64683.2, 0.002], [64683.3, 0.002], [64683.6, 0.003], [64683.9, 0.001], [64684.3, 0.159], [64684.5, 0.049], [64686.8, 0.085]], "asks": [[64689.0, 11.479], [64689.6, 0.028], [64692.0, 0.546], [64692.1, 0.001], [64693.1, 0.108], [64695.1, 0.016], [64695.5, 0.124], [64695.8, 0.002], [64696.1, 0.001], [64696.4, 2.111], [64696.7, 2.319], [64696.8, 0.0], [64696.9, 0.155], [64697.0, 0.918], [64697.1, 0.24], [64697.2, 0.005], [64697.3, 0.577], [64697.4, 0.0], [64697.5, 0.053], [64697.6, 0.045], [64697.7, 0.473], [64699.3, 0.998], [64703.2, 0.395], [64703.3, 0.327], [64706.6, 0.619], [64708.9, 0.215], [64709.6, 0.001], [64709.7, 0.119], [64713.0, 0.0], [64713.3, 0.0], [64713.4, 0.001], [64713.7, 0.0], [64714.0, 0.016], [64714.3, 2.244], [64714.7, 0.001], [64715.1, 0.0], [64716.3, 0.163], [64716.5, 3.328], [64716.6, 0.005], [64716.7, 0.001], [64716.8, 0.058], [64716.9, 0.028], [64717.0, 0.0], [64717.1, 0.0], [64717.2, 0.041], [64717.3, 1.258], [64730.9, 0.002], [64731.2, 1.251], [64731.6, 0.015], [64731.9, 0.003], [64732.2, 0.019], [64733.0, 0.042], [64831.7, 5.399], [64848.7, 10.414], [64879.5, 0.003], [64879.6, 0.121], [64887.5, 4.691], [65012.4, 4.765], [65335.9, 6.758], [65458.8, 8.242], [65469.4, 0.0], [65627.0, 35.354]]}
{"kind": "depth", "E": 1787080659415, "U": 11315371013105, "u": 11315371018406, "recv_ms": 1787080659362, "bids": [[1000.0, 35.81], [14488.9, 3.038], [14588.9, 1.162], [51751.1, 0.0], [58220.0, 4.018], [62101.3, 2.788], [63688.9, 0.007], [63880.3, 24.628], [63912.6, 44.562], [64042.0, 2.169], [64646.9, 0.406], [64647.6, 0.034], [64664.4, 0.001], [64665.1, 0.559], [64666.1, 1.357], [64669.4, 0.01], [64670.2, 0.929], [64671.0, 0.007], [64672.5, 0.008], [64672.7, 0.271], [64673.8, 0.01], [64674.7, 0.071], [64675.2, 0.033], [64675.5, 0.854], [64675.9, 0.023], [64678.7, 0.003], [64679.6, 0.002], [64680.3, 0.006], [64681.3, 0.0], [64681.4, 0.005], [64681.6, 2.132], [64681.9, 0.105], [64682.1, 0.117], [64682.2, 0.171], [64682.3, 0.1], [64682.7, 0.121], [64683.3, 0.034], [64684.3, 0.156], [64684.5, 0.049]], "asks": [[64689.0, 11.488], [64692.0, 0.005], [64692.2, 0.088], [64694.5, 0.014], [64694.8, 0.01], [64695.2, 0.044], [64695.5, 0.587], [64695.9, 0.043], [64696.2, 0.826], [64696.3, 0.003], [64696.5, 0.506], [64696.9, 0.315], [64697.0, 1.139], [64697.1, 0.39], [64697.3, 0.707], [64697.6, 0.129], [64699.3, 0.38], [64702.3, 0.139], [64703.5, 0.957], [64705.0, 0.047], [64705.5, 1.257], [64705.9, 0.158], [64706.3, 0.726], [64707.2, 0.024], [64707.3, 1.862], [64708.5, 0.329], [64709.7, 0.004], [64710.4, 0.124], [64713.8, 0.046], [64714.4, 0.485], [64714.8, 3.699], [64716.6, 0.226], [64716.7, 0.151], [64716.9, 0.158], [64717.2, 0.125], [64731.7, 0.063], [64732.3, 0.061], [64848.7, 6.84], [64887.5, 9.002], [65012.5, 0.002], [65335.9, 6.758], [65433.6, 9.164], [65689.0, 10.015], [65756.4, 5.497]]}
{"kind": "depth", "E": 1787080659517, "U": 11315371018536, "u": 11315371022940, "recv_ms": 1787080659463, "bids": [[1000.0, 35.81], [14488.9, 3.388], [14588.9, 0.812], [58220.0, 4.018], [61454.4, 0.006], [62101.3, 2.785], [63825.9, 0.001], [63850.7, 0.05], [64042.0, 2.169], [64620.7, 6.83], [64647.9, 0.054], [64648.2, 0.032], [64652.8, 0.566], [64665.0, 0.504], [64667.2, 1.241], [64668.4, 0.004], [64674.0, 0.363], [64675.2, 0.04], [64675.4, 0.001], [64675.6, 0.0], [64680.3, 0.006], [64681.4, 0.005], [64681.5, 1.127], [64681.6, 2.068], [64681.7, 0.0], [64681.8, 0.101], [64681.9, 0.205], [64682.0, 0.103], [64682.4, 0.077], [64683.7, 0.342], [64684.0, 0.033], [64684.1, 0.003], [64684.5, 0.597]], "asks": [[64689.0, 11.491], [64692.2, 0.104], [64693.7, 0.377], [64694.8, 0.01], [64695.2, 0.082], [64695.6, 1.514], [64696.2, 0.81], [64696.8, 0.105], [64697.2, 0.125], [64697.3, 0.847], [64697.4, 0.12], [64697.6, 0.227], [64697.7, 0.557], [64706.9, 0.001], [64707.3, 1.864], [64713.1, 0.039], [64713.4, 0.036], [64715.2, 2.36], [64716.4, 0.106], [64716.8, 0.178], [64717.0, 0.12], [64717.2, 0.223], [64717.3, 1.342], [64731.0, 0.104], [64731.3, 0.205], [64829.2, 2.15], [64848.7, 10.414], [64887.5, 4.588], [65335.9, 6.758], [65782.2, 1.819]]}
{"kind": "depth", "E": 1787080659619, "U": 11315371022992, "u": 11315371028285, "recv_ms": 1787080659566, "bids": [[14388.9, 0.028], [14488.9, 3.696], [14588.9, 0.476], [58220.0, 4.018], [61454.4, 0.006], [62101.3, 2.788], [63686.2, 18.35], [63688.9, 0.027], [63841.2, 0.274], [64042.0, 2.169], [64365.5, 6.818], [64549.4, 5.13], [64647.2, 0.032], [64681.6, 2.136], [64681.8, 0.171], [64682.1, 0.187], [64683.0, 0.037], [64684.6, 0.27], [64688.9, 4.588]], "asks": [[64689.0, 11.49], [64692.2, 0.652], [64692.7, 0.15], [64695.2, 0.082], [64695.3, 0.016], [64695.4, 0.001], [64695.5, 0.039], [64696.2, 0.291], [64696.3, 0.567], [64697.2, 0.209], [64697.5, 0.13], [64714.1, 0.104], [64716.8, 0.262], [64717.1, 0.077], [64732.0, 0.068], [64831.7, 4.74], [64848.7, 6.829], [64887.5, 8.666], [65335.9, 6.758], [65433.6, 10.08], [65458.8, 9.157], [65465.7, 0.963], [65521.7, 0.0], [65627.0, 36.419], [65689.0, 10.035], [65756.4, 6.56]]}
{"kind": "depth", "E": 1787080659721, "U": 11315371028428, "u": 11315371033198, "recv_ms": 1787080659666, "bids": [[1000.0, 35.81], [14388.9, 0.196], [14488.9, 3.71], [14588.9, 0.294], [58220.0, 4.022], [61454.5, 2.461], [61454.6, 0.01], [62101.3, 2.785], [63585.4, 0.898], [63726.3, 0.0], [63779.5, 5.63], [63833.1, 0.002], [64042.0, 2.169], [64629.0, 0.041], [64629.7, 0.063], [64643.6, 0.444], [64675.4, 0.542], [64675.5, 0.313], [64678.7, 0.003], [64681.5, 1.197], [64681.6, 2.202], [64681.7, 0.07], [64684.6, 0.02], [64685.2, 0.267], [64686.8, 0.001], [64688.9, 4.589]], "asks": [[64689.7, 0.084], [64692.2, 0.088], [64695.4, 0.024], [64695.5, 0.588], [64696.2, 0.289], [64696.3, 0.559], [64697.5, 0.221], [64697.8, 0.079], [64707.2, 0.565], [64707.3, 1.323], [64708.5, 0.329], [64717.1, 0.168], [64717.4, 0.144], [64734.3, 0.306], [64848.7, 10.414], [64887.5, 4.18], [65335.9, 6.758], [65493.8, 3.446], [66412.0, 0.017]]}
{"kind": "depth", "E": 1787080659823, "U": 11315371033200, "u": 11315371038714, "recv_ms": 1787080659769, "bids": [[1000.0, 35.81], [14388.9, 0.434], [14488.9, 3.598], [14588.9, 0.168], [58220.0, 4.018], [61454.4, 0.006], [63506.0, 0.387], [63688.9, 0.007], [64042.0, 2.169], [64549.4, 5.212], [64550.2, 2.116], [64630.0, 3.104], [64630.3, 1.43], [64662.0, 0.207], [64662.3, 0.95], [64662.5, 0.133], [64662.6, 0.281], [64664.4, 0.101], [64677.9, 0.006], [64681.6, 2.136], [64684.6, 0.27], [64685.2, 0.017], [64688.9, 4.603]], "asks": [[64689.0, 11.497], [64693.6, 0.067], [64693.7, 0.347], [64700.1, 0.005], [64702.7, 0.001], [64706.5, 0.009], [64706.6, 0.621], [64733.0, 0.0], [64818.4, 0.213], [64831.7, 5.092], [64848.7, 7.252], [64887.5, 7.577], [65335.9, 6.758], [65404.7, 0.015], [65689.0, 10.015], [65691.7, 18.846], [65982.7, 0.023]]}
{"kind": "depth", "E": 1787080659925, "U": 11315371038846, "u": 11315371044213, "recv_ms": 1787080659871, "bids": [[14388.9, 0.672], [14488.9, 3.486], [14588.9, 0.042], [58220.0, 4.018], [61454.4, 0.006], [62101.3, 2.788], [63395.2, 0.071], [63688.9, 0.027], [63809.5, 0.627], [63847.9, 21.971], [64042.0, 2.169], [64365.4, 0.0], [64365.5, 6.818], [64621.6, 0.01], [64625.4, 0.133], [64629.4, 0.244], [64650.3, 2.135], [64659.6, 0.016], [64661.9, 0.679], [64662.0, 0.277], [64662.2, 0.1], [64662.4, 2.463], [64662.8, 0.392], [64664.0, 1.484], [64681.6, 2.102], [64684.6, 0.02], [64686.7, 0.086]], "asks": [[64689.0, 11.53], [64750.0, 1.899], [64764.4, 0.026], [64848.7, 10.414], [64887.5, 4.511], [65012.5, 0.003], [65335.9, 6.76], [65401.0, 0.864], [65433.6, 9.164], [65536.9, 0.27], [65689.0, 10.035]]}
{"kind": "depth", "E": 1787080660027, "U": 11315371044216, "u": 11315371049613, "recv_ms": 1787080659975, "bids": [[1000.0, 35.81], [14388.9, 0.98], [14488.9, 3.22], [14588.9, 0.0], [58220.0, 4.018], [61454.4, 0.006], [62101.3, 2.785], [63653.9, 3.733], [63718.6, 8.41], [63750.9, 34.314], [64042.0, 2.169], [64493.6, 10.507], [64532.4, 8.489], [64549.4, 4.522], [64623.4, 3.144], [64624.2, 0.036], [64630.6, 0.004], [64655.7, 0.333], [64662.1, 0.087], [64662.4, 2.533], [64668.5, 0.034], [64669.5, 0.005], [64675.6, 0.541], [64681.6, 2.07], [64681.7, 0.07], [64682.8, 0.002], [64683.0, 0.044], [64684.5, 0.049], [64684.6, 0.02], [64685.3, 0.023], [64685.4, 0.02], [64686.7, 0.002], [64688.9, 4.485]], "asks": [[64689.2, 0.404], [64691.1, 0.014], [64692.2, 0.652], [64692.6, 0.074], [64692.7, 0.15], [64692.8, 1.312], [64693.2, 0.29], [64693.8, 0.005], [64695.4, 0.001], [64695.5, 0.14], [64696.3, 0.466], [64707.9, 0.006], [64708.4, 0.446], [64714.6, 0.053], [64731.0, 0.134], [64731.2, 1.221], [64755.1, 3.573], [64766.7, 0.203], [64818.4, 0.216], [64887.5, 6.824], [65335.9, 6.758], [65433.6, 6.417], [65691.7, 19.91], [65724.0, 8.338], [66408.0, 0.122]]}
{"kind": "depth", "E": 1787080660129, "U": 11315371049715, "u": 11315371055472, "recv_ms": 1787080660074, "bids": [[1000.0, 35.81], [14388.9, 1.33], [14488.9, 2.87], [58220.0, 4.018], [62101.3, 2.788], [63815.6, 15.961], [63874.2, 0.003], [63888.1, 3.128], [64042.0, 2.169], [64129.8, 1.249], [64500.0, 25.293], [64645.3, 0.0], [64645.7, 0.222], [64661.8, 0.079], [64662.1, 0.157], [64677.3, 0.002], [64682.0, 0.237], [64684.5, 0.049]], "asks": [[64690.8, 0.007], [64691.0, 0.006], [64705.5, 1.813], [64706.3, 0.17], [64749.0, 0.003], [64749.3, 1.868], [64848.7, 6.278], [64887.5, 12.028], [65335.9, 6.758], [65433.6, 7.333], [65635.0, 5.935]]}
{"kind": "depth", "E": 1787080660231, "U": 11315371055568, "u": 11315371061407, "recv_ms": 1787080660178, "bids": [[14388.9, 1.694], [14488.9, 2.506], [58220.0, 4.018], [61454.4, 0.006], [62101.3, 2.785], [62101.4, 0.005], [63653.9, 4.831], [63688.9, 0.007], [63750.9, 35.411], [63876.5, 2.609], [64042.0, 2.169], [64126.1, 2.409], [64365.5, 6.818], [64532.4, 9.934], [64549.4, 5.13], [64550.2, 1.534], [64591.9, 0.026], [64619.0, 0.181], [64619.4, 0.015], [64642.0, 2.279], [64650.0, 2.918], [64650.3, 2.136], [64655.3, 0.019], [64658.2, 0.071], [64658.6, 2.512], [64660.0, 0.5], [64666.1, 1.241], [64667.0, 1.019], [64675.6, 0.0], [64682.0, 0.103], [64682.7, 0.037], [64683.0, 0.044], [64684.4, 2.009], [64684.5, 0.59], [64684.6, 0.001], [64685.2, 0.017], [64687.1, 0.085], [64687.9, 0.005], [64688.0, 0.043], [64688.2, 0.0], [64688.3, 0.311], [64688.8, 0.066], [64688.9, 4.588]], "asks": [[64689.0, 10.758], [64689.1, 0.162], [64689.7, 0.0], [64690.0, 0.414], [64690.6, 0.002], [64691.0, 0.09], [64691.2, 1.14], [64691.9, 0.05], [64692.4, 0.003], [64692.8, 1.002], [64692.9, 0.002], [64693.2, 0.287], [64693.8, 0.089], [64694.2, 0.085], [64696.4, 1.802], [64696.8, 0.414], [64706.6, 0.003], [64708.4, 0.375], [64714.6, 0.049], [64715.2, 1.396], [64731.0, 0.104], [64731.2, 1.251], [64731.4, 0.0], [64735.6, 0.043], [64752.0, 1.52], [64754.0, 0.002], [64791.3, 2.13], [64791.4, 0.026], [64799.6, 2.13], [64799.7, 0.005], [64807.9, 2.13], [64808.0, 4.291], [64829.2, 1.531], [64831.7, 5.399], [64848.7, 10.414], [64887.5, 4.818], [65335.9, 6.758], [65421.9, 0.1], [65433.6, 8.248], [65689.0, 10.015], [65982.7, 0.02]]}
{"kind": "depth", "E": 1787080660333, "U": 11315371061483, "u": 11315371066601, "recv_ms": 1787080660281, "bids": [[1000.0, 35.81], [14388.9, 2.044], [14488.9, 2.156], [51751.0, 0.0], [58220.0, 4.018], [63653.9, 5.929], [63880.3, 25.527], [63919.1, 8.437], [64042.0, 2.169], [64587.1, 0.002], [64588.8, 1.011], [64665.0, 1.122], [64672.4, 0.62], [64675.6, 0.541], [64675.7, 0.182], [64682.0, 0.237], [64683.0, 0.037], [64684.4, 2.006], [64684.5, 0.049], [64684.6, 0.001], [64687.9, 0.315], [64688.3, 0.001], [64688.9, 4.589]], "asks": [[64689.0, 10.753], [64690.1, 0.311], [64690.6, 0.086], [64691.1, 0.012], [64692.5, 0.1], [64692.7, 0.173], [64695.1, 0.001], [64696.9, 0.933], [64704.3, 0.744], [64714.5, 0.541], [64784.0, 1.082], [64786.4, 0.0], [64816.6, 0.015], [64848.7, 6.689], [64887.5, 8.869], [65335.9, 6.758], [65433.6, 9.164], [65724.0, 10.466]]}
{"kind": "depth", "E": 1787080660435, "U": 11315371066689, "u": 11315371071344, "recv_ms": 1787080660560, "bids": [[1000.0, 35.81], [14388.9, 2.408], [14488.9, 1.792], [51751.0, 0.0], [51751.1, 0.0], [58220.0, 4.018], [61454.6, 0.008], [62101.3, 2.788], [63688.9, 0.027], [64042.0, 2.169], [64365.4, 0.001], [64549.4, 5.24], [64578.4, 1.757], [64587.2, 1.445], [64617.0, 0.018], [64617.5, 6.0], [64617.6, 3.654], [64640.1, 3.503], [64656.3, 1.011], [64664.6, 0.559], [64665.1, 0.002], [64666.1, 1.357], [64667.0, 0.903], [64669.6, 0.969], [64670.2, 0.003], [64672.5, 0.008], [64675.9, 0.009], [64682.0, 0.103], [64682.1, 0.187], [64683.0, 0.105], [64685.2, 0.017]], "asks": [[64702.0, 2.998], [64702.9, 1.584], [64703.5, 0.032], [64705.0, 0.047], [64708.9, 0.215], [64709.8, 0.121], [64710.4, 0.009], [64713.2, 1.337], [64726.6, 2.379], [64726.7, 4.019], [64729.4, 6.261], [64733.0, 0.014], [64735.6, 0.001], [64751.2, 0.015], [64752.0, 7.52], [64786.3, 0.027], [64787.6, 0.008], [64831.7, 5.399], [64848.7, 10.414], [64887.5, 4.374], [65012.5, 0.002], [65335.9, 6.758], [65627.0, 37.332], [65689.0, 10.035]]}
{"kind": "depth", "E": 1787080660537, "U": 11315371071398, "u": 11315371075730, "recv_ms": 1787080660561, "bids": [[14388.9, 2.758], [14488.9, 1.442], [58220.0, 4.018], [61454.4, 0.006], [61454.5, 2.463], [61454.6, 0.006], [62101.3, 2.785], [63686.2, 17.253], [63919.1, 9.375], [64042.0, 2.169], [64365.5, 6.828], [64585.2, 10.002], [64585.3, 2.764], [64682.0, 0.237], [64683.0, 0.037], [64684.5, 0.299], [64688.0, 0.003], [64688.9, 4.59]], "asks": [[64695.1, 0.016], [64711.6, 0.043], [64784.0, 2.181], [64784.4, 10.016], [64816.6, 0.0], [64829.2, 2.15], [64848.7, 6.81], [64887.5, 8.863], [65335.9, 6.758], [65433.6, 10.08], [65627.0, 36.268], [65691.7, 18.847]]}
{"kind": "depth", "E": 1787080660639, "U": 11315371075910, "u": 11315371087266, "recv_ms": 1787080660585, "bids": [[1000.0, 35.81], [14388.9, 3.108], [14488.9, 1.092], [58220.0, 4.018], [61454.4, 0.007], [62101.3, 2.788], [63688.9, 0.007], [63876.5, 2.258], [64042.0, 2.169], [64578.4, 1.749], [64585.3, 2.772], [64672.4, 0.002], [64675.6, 0.0], [64675.7, 0.175], [64682.0, 0.103], [64684.5, 0.597], [64688.9, 4.59]], "asks": [[64689.0, 10.761], [64689.1, 0.161], [64689.9, 0.003], [64690.0, 0.406], [64691.0, 0.09], [64691.1, 0.012], [64692.2, 0.088], [64692.7, 0.173], [64692.9, 0.0], [64693.6, 0.067], [64694.0, 0.005], [64694.9, 0.001], [64695.0, 0.206], [64695.5, 0.039], [64696.3, 0.583], [64696.8, 0.414], [64696.9, 0.315], [64700.0, 0.391], [64701.1, 0.776], [64702.8, 0.946], [64702.9, 0.659], [64703.3, 0.32], [64704.0, 0.423], [64704.5, 2.321], [64705.0, 0.046], [64705.5, 1.257], [64706.5, 0.002], [64707.2, 0.038], [64707.3, 1.266], [64709.1, 10.001], [64709.7, 0.119], [64709.8, 0.006], [64710.0, 0.121], [64710.6, 0.154], [64711.6, 0.042], [64715.0, 0.816], [64716.9, 0.312], [64717.8, 0.002], [64720.0, 0.153], [64735.6, 0.001], [64848.7, 10.414], [64887.5, 4.487], [65335.9, 6.758], [65689.0, 10.015], [65969.8, 0.606], [65982.7, 0.017]]}
{"kind": "depth", "E": 1787080660945, "U": 11315371100034, "u": 11315371104235, "recv_ms": 1787080660891, "bids": [[1000.0, 35.81], [14288.9, 0.252], [14388.9, 3.682], [14488.9, 0.266], [58220.0, 4.018], [61454.6, 0.004], [62101.3, 2.788], [63847.9, 22.675], [64004.5, 0.001], [64042.0, 2.169], [64365.5, 5.375], [64675.6, 0.0], [64675.7, 0.175], [64684.5, 0.597], [64684.6, 0.251], [64686.9, 0.077]], "asks": [[65012.5, 0.001], [65335.9, 6.758]]}
{"kind": "depth", "E": 1787080661047, "U": 11315371104406, "u": 11315371111450, "recv_ms": 1787080660996, "bids": [[1000.0, 35.81], [14288.9, 0.49], [14388.9, 3.57], [14488.9, 0.14], [58220.0, 4.018], [61454.4, 0.006], [62101.3, 2.785], [63589.2, 16.619], [63688.9, 0.007], [63750.9, 34.314], [63876.5, 2.024], [63996.7, 1.793], [64042.0, 2.169], [64365.4, 0.002], [64549.4, 4.594], [64591.9, 0.034], [64611.2, 0.003], [64630.6, 0.001], [64637.1, 0.196], [64643.6, 0.441], [64675.7, 0.172], [64677.2, 0.004], [64677.3, 0.007], [64684.6, 0.251], [64684.9, 0.005], [64687.7, 0.085], [64687.9, 0.355], [64688.9, 4.59]], "asks": [[64689.0, 10.625], [64690.6, 0.002], [64691.1, 0.014], [64692.6, 0.072], [64692.8, 1.004], [64734.3, 0.306], [64766.7, 0.2], [64829.2, 1.531], [64831.7, 5.399], [64848.7, 6.105], [64887.5, 12.036], [65335.9, 6.758], [65491.3, 0.002], [65617.5, 0.0], [65627.0, 36.267], [65689.0, 10.015], [65982.7, 0.02]]}
{"kind": "depth", "E": 1787080661149, "U": 11315371111535, "u": 11315371117062, "recv_ms": 1787080661097, "bids": [[14288.9, 0.728], [14388.9, 3.458], [14488.9, 0.014], [51751.0, 0.0], [58220.0, 4.018], [61454.5, 2.461], [61454.6, 0.006], [62101.3, 2.788], [63700.9, 0.022], [63765.6, 0.022], [63767.4, 0.011], [63854.4, 0.314], [64042.0, 2.171], [64365.5, 5.375], [64600.0, 14.579], [64677.3, 0.002], [64682.0, 0.103], [64683.0, 0.037], [64684.6, 0.001], [64685.2, 0.017]], "asks": [[64689.1, 0.335], [64690.9, 0.017], [64691.0, 0.99], [64692.1, 0.542], [64692.2, 0.095], [64694.9, 0.002], [64695.5, 0.124], [64697.2, 0.208], [64775.6, 0.026], [64848.7, 10.414], [64887.5, 4.818], [65335.9, 6.758], [65579.0, 0.688], [65610.6, 0.635], [65612.4, 0.015], [65677.1, 0.06]]}
{"kind": "depth", "E": 1787080661251, "U": 11315371117080, "u": 11315371123748, "recv_ms": 1787080661197, "bids": [[1000.0, 35.81], [14288.9, 1.064], [14388.9, 3.136], [14488.9, 0.0], [51751.0, 0.0], [58220.0, 4.018], [61454.4, 0.006], [62101.4, 0.004], [63065.6, 0.004], [63688.9, 0.027], [63700.9, 0.03], [63750.9, 35.411], [63765.6, 0.03], [64042.0, 2.169], [64682.0, 0.103], [64685.2, 0.142], [64688.9, 4.59]], "asks": [[64689.0, 10.625], [64689.1, 0.163], [64690.9, 0.001], [64691.0, 0.09], [64692.0, 0.005], [64692.1, 0.001], [64692.2, 0.652], [64692.7, 0.266], [64694.9, 0.001], [64695.4, 0.001], [64695.5, 0.039], [64696.3, 0.474], [65335.9, 6.758], [65421.8, 0.763], [65610.6, 0.643], [65612.4, 0.023], [65627.0, 37.332], [65677.1, 0.068], [65689.0, 10.035]]}
{"kind": "depth", "E": 1787080661353, "U": 11315371123894, "u": 11315371130188, "recv_ms": 1787080661300, "bids": [[1000.0, 35.81], [14288.9, 1.428], [14388.9, 2.772], [58220.0, 4.018], [61454.4, 0.006], [62101.3, 2.785], [63585.4, 0.506], [63811.9, 1.567], [64042.0, 2.169], [64549.4, 0.0], [64624.2, 0.037], [64671.2, 0.003], [64682.0, 0.237], [64684.6, 0.251], [64685.2, 0.017], [64688.9, 4.59]], "asks": [[64689.0, 10.63], [64692.7, 0.266], [64695.1, 0.016], [64695.5, 0.047], [64696.3, 0.466], [64711.1, 1.42], [64753.7, 0.124], [64831.7, 0.0], [65335.9, 6.758], [65792.6, 0.778]]}
{"kind": "depth", "E": 1787080661455, "U": 11315371130309, "u": 11315371137495, "recv_ms": 1787080661401, "bids": [[14288.9, 1.778], [14388.9, 2.422], [51751.1, 0.0], [58220.0, 4.018], [61454.4, 0.006], [62101.3, 2.788], [63395.2, 0.074], [63688.9, 0.007], [63783.3, 41.145], [64042.0, 2.169], [64365.4, 0.001], [64365.5, 5.385], [64493.6, 11.023], [64495.8, 1.393], [64532.4, 9.738], [64534.1, 1.423], [64549.4, 5.13], [64559.7, 0.008], [64561.6, 1.196], [64566.5, 0.013], [64568.3, 0.019], [64573.3, 0.003], [64580.1, 0.0], [64586.9, 0.002], [64593.7, 2.319], [64600.5, 0.152], [64607.3, 2.401], [64614.1, 0.013], [64620.9, 0.0], [64627.7, 0.025], [64634.5, 0.015], [64641.3, 0.002], [64648.1, 0.023], [64654.9, 0.0], [64661.7, 0.5], [64668.5, 0.019], [64669.8, 0.005], [64672.5, 0.008], [64675.3, 0.687], [64682.0, 0.204], [64682.1, 0.172], [64684.6, 0.251], [64684.9, 0.002], [64687.7, 0.001], [64688.9, 4.59]], "asks": [[64690.3, 0.085], [64692.7, 0.173], [64695.5, 0.14], [64701.8, 0.016], [64701.9, 0.184], [64705.0, 0.047], [64708.5, 0.344], [64708.6, 2.909], [64809.8, 0.001], [64831.7, 4.729], [64848.7, 6.821], [64887.5, 8.993], [65335.9, 6.758], [65575.2, 3.65], [65689.0, 10.015]]}
{"kind": "depth", "E": 1787080661557, "U": 11315371137583, "u": 11315371142782, "recv_ms": 1787080661503, "bids": [[1000.0, 35.81], [14288.9, 2.128], [14388.9, 2.072], [51751.0, 0.0], [58220.0, 4.018], [61454.4, 0.0], [62101.3, 2.785], [63589.2, 17.404], [63621.5, 6.517], [63688.9, 0.027], [63750.9, 34.314], [64042.0, 2.169], [64495.8, 3.277], [64534.1, 2.663], [64549.4, 5.13], [64575.0, 0.648], [64682.0, 0.237], [64684.5, 0.575], [64684.6, 0.001], [64685.2, 0.267], [64688.9, 4.59]], "asks": [[64707.2, 0.024], [64710.1, 0.003], [64711.1, 1.418], [64735.6, 0.029], [64809.7, 0.895], [64831.7, 4.729], [65012.5, 0.002], [65335.9, 6.76], [65473.3, 26.33], [65497.6, 20.564], [65689.0, 10.035], [65801.7, 1.212]]}
{"kind": "depth", "E": 1787080661659, "U": 11315371142800, "u": 11315371147694, "recv_ms": 1787080661604, "bids": [[1000.0, 35.81], [14288.9, 2.492], [14388.9, 1.708], [51751.0, 0.0], [58220.0, 4.018], [64042.0, 2.169], [64532.4, 6.541], [64549.4, 3.305], [64581.7, 0.027], [64588.4, 0.042], [64682.0, 0.103], [64685.2, 0.017], [64688.8, 0.066]], "asks": [[64689.0, 10.739], [64690.3, 0.001], [64691.1, 0.012], [64829.2, 2.15], [64831.7, 3.891], [64848.7, 6.576], [64887.5, 11.969], [65335.9, 6.758], [65400.0, 100.693], [65982.7, 0.023]]}
{"kind": "depth", "E": 1787080661761, "U": 11315371147828, "u": 11315371152449, "recv_ms": 1787080661706, "bids": [[14288.9, 2.842], [14388.9, 1.358], [51751.0, 0.0], [58220.0, 4.018], [62101.3, 2.788], [63826.3, 0.069], [64042.0, 2.169], [64365.5, 5.375], [64493.6, 11.084], [64532.4, 9.934], [64549.4, 5.212], [64595.1, 0.038], [64673.8, 0.009], [64684.6, 0.001]], "asks": [[64694.5, 0.013], [64708.4, 0.446], [64818.4, 0.216], [64831.7, 5.399], [64848.7, 10.414], [64887.5, 4.864], [65335.9, 6.758], [65465.3, 46.791]]}
{"kind": "depth", "E": 1787080661863, "U": 11315371152506, "u": 11315371157597, "recv_ms": 1787080661809, "bids": [[1000.0, 35.81], [14288.9, 3.206], [14388.9, 0.994], [58220.0, 4.018], [61454.4, 0.0], [62101.3, 2.785], [63395.2, 0.071], [63621.5, 7.616], [63688.9, 0.007], [63750.9, 35.411], [64042.0, 2.169], [64601.8, 0.015], [64608.5, 0.017], [64666.7, 0.008], [64666.9, 1.12], [64682.0, 0.171], [64684.6, 0.001], [64688.9, 4.59]], "asks": [[64689.0, 10.74], [64691.1, 0.012], [64722.0, 0.473], [64728.7, 0.322], [65335.9, 6.758], [65689.0, 10.015]]}
{"kind": "depth", "E": 1787080661965, "U": 11315371157791, "u": 11315371163828, "recv_ms": 1787080661912, "bids": [[1000.0, 35.81], [14288.9, 3.556], [14388.9, 0.644], [58220.0, 4.018], [61454.4, 0.0], [61454.5, 2.463], [62101.3, 2.788], [63841.1, 1.064], [63880.3, 25.761], [64042.0, 2.169], [64361.2, 0.108], [64365.4, 0.0], [64493.6, 11.084], [64532.4, 9.934], [64549.4, 5.212], [64615.2, 0.457], [64684.6, 0.251], [64688.9, 4.59]], "asks": [[64690.9, 0.017], [64691.0, 0.99], [64691.1, 0.012], [64692.1, 0.542], [64692.2, 0.095], [64695.5, 0.14], [64720.9, 0.251], [64728.7, 0.308], [64775.6, 0.126], [64831.7, 4.549], [64848.7, 10.414], [64887.5, 4.487], [65335.9, 6.758], [65409.7, 3.849]]}
{"kind": "depth", "E": 1787080662067, "U": 11315371163873, "u": 11315371172979, "recv_ms": 1787080662015, "bids": [[14188.9, 0.084], [14288.9, 3.752], [14388.9, 0.364], [58220.0, 4.018], [61454.4, 0.0], [61454.5, 2.465], [62101.3, 2.785], [63395.2, 0.068], [63688.9, 0.027], [63700.9, 0.019], [63811.8, 1.953], [64042.0, 2.17], [64365.5, 5.375], [64532.4, 6.541], [64549.4, 4.521], [64621.9, 0.333], [64624.2, 0.04], [64628.6, 0.018], [64643.6, 0.444], [64656.3, 0.986], [64658.2, 0.001], [64663.6, 0.604], [64665.0, 0.504], [64665.4, 0.077], [64667.2, 1.192], [64674.6, 0.428], [64677.3, 0.002], [64682.0, 0.103], [64684.6, 0.001], [64685.2, 0.267], [64685.5, 0.022], [64687.4, 0.001], [64687.6, 0.084], [64687.9, 0.315], [64688.0, 0.046], [64688.4, 0.111], [64688.9, 4.591]], "asks": [[64689.0, 11.23], [64689.1, 0.337], [64690.9, 0.001], [64691.1, 0.014], [64692.0, 0.005], [64692.1, 0.001], [64692.2, 0.652], [64692.3, 0.821], [64692.5, 0.08], [64692.7, 0.242], [64692.8, 1.004], [64692.9, 0.0], [64695.4, 0.464], [64695.5, 0.047], [64696.3, 0.003], [64735.6, 0.001], [64747.3, 0.001], [64850.8, 0.002], [64887.5, 4.375], [65012.5, 0.003], [65335.9, 6.758], [65493.8, 3.187], [65677.1, 0.057], [65689.0, 10.035], [65756.4, 5.497], [65982.7, 0.026]]}
{"kind": "depth", "E": 1787080662169, "U": 11315371173159, "u": 11315371178536, "recv_ms": 1787080662116, "bids": [[1000.0, 35.96], [14188.9, 0.308], [14288.9, 3.654], [14388.9, 0.238], [58220.0, 4.018], [61454.4, 0.0], [63688.9, 0.007], [63700.8, 1.72], [63700.9, 0.038], [63815.6, 16.351], [64042.0, 2.17], [64635.3, 0.424], [64650.2, 0.455], [64659.6, 0.002], [64684.6, 0.251], [64685.2, 0.017], [64687.9, 0.005], [64688.8, 0.217], [64688.9, 4.591]], "asks": [[64689.1, 0.163], [64690.9, 0.001], [64691.0, 0.09], [64691.1, 0.012], [64692.0, 0.546], [64692.1, 0.001], [64692.2, 0.088], [64692.7, 0.149], [64694.9, 0.002], [64695.4, 0.001], [64695.5, 0.147], [64696.3, 0.482], [65335.9, 6.758], [65602.7, 45.858], [65677.0, 0.012], [65689.0, 10.015], [66629.5, 0.0], [71157.9, 0.0]]}
{"kind": "depth", "E": 1787080662271, "U": 11315371178581, "u": 11315371184301, "recv_ms": 1787080662218, "bids": [[1000.0, 35.81], [14188.9, 0.546], [14288.9, 3.542], [14388.9, 0.112], [51751.0, 0.002], [58220.0, 4.018], [61454.4, 0.0], [62101.3, 2.788], [63920.4, 18.515], [64042.0, 2.17], [64532.4, 10.001], [64534.1, 1.423], [64549.4, 5.24], [64611.2, 0.0], [64642.0, 2.294], [64643.6, 0.444], [64648.7, 0.015], [64650.0, 2.932], [64664.6, 0.002], [64665.1, 0.559], [64666.1, 1.241], [64666.7, 0.124], [64667.6, 0.026], [64669.6, 0.043], [64670.1, 1.37], [64671.0, 0.007], [64675.4, 0.542], [64678.7, 0.003], [64684.6, 0.251], [64687.6, 0.0], [64687.8, 0.0], [64688.9, 4.591]], "asks": [[64689.0, 11.231], [64689.1, 0.225], [64690.1, 0.395], [64690.5, 0.133], [64692.0, 0.005], [64694.2, 0.001], [64694.9, 0.001], [64695.5, 0.688], [64702.8, 0.021], [64703.5, 0.957], [64705.8, 0.004], [64706.3, 0.726], [64707.2, 0.565], [64707.3, 1.266], [64708.5, 0.344], [64708.7, 5.003], [64709.7, 0.004], [64710.4, 0.124], [64734.3, 0.306], [64829.2, 1.531], [64831.7, 5.399], [64848.7, 10.414], [65335.9, 6.758], [65465.3, 46.182], [65497.6, 20.222], [65677.1, 0.076]]}
{"kind": "depth", "E": 1787080662373, "U": 11315371184544, "u": 11315371200610, "recv_ms": 1787080662321, "bids": [[14188.9, 0.784], [14288.9, 3.416], [14388.9, 0.0], [51751.0, 0.0], [58220.0, 4.018], [62101.3, 2.785], [63714.8, 4.27], [63880.3, 26.112], [64042.0, 2.17], [64143.9, 0.0], [64365.5, 5.375], [64405.0, 0.121], [64538.6, 0.003], [64607.7, 0.011], [64637.0, 0.018], [64640.0, 0.307], [64640.1, 3.505], [64655.4, 0.02], [64684.6, 0.251], [64687.1, 0.001]], "asks": [[64689.0, 11.231], [64692.1, 0.542], [64692.2, 0.111], [64692.3, 0.819], [64692.6, 0.074], [64692.7, 0.149], [64695.4, 0.001], [64695.5, 0.124], [64696.3, 0.482], [64709.1, 10.003], [64710.5, 3.21], [64725.9, 0.0], [64750.1, 0.022], [64837.2, 0.772], [64848.7, 6.811], [64887.5, 8.864], [64990.5, 0.0], [65246.1, 0.312], [65335.9, 6.758], [65756.4, 6.56]]}
{"kind": "depth", "E": 1787080662475, "U": 11315371200692, "u": 11315371207377, "recv_ms": 1787080662421, "bids": [[1000.0, 35.81], [14188.9, 1.148], [14288.9, 3.052], [51751.1, 0.0], [58220.0, 4.018], [62101.3, 2.788], [63479.2, 2.467], [63688.9, 0.027], [63912.6, 46.125], [63919.1, 8.438], [64042.0, 2.17], [64549.4, 0.0], [64656.2, 0.003], [64662.1, 0.172], [64663.6, 0.579], [64664.6, 0.027], [64668.8, 2.347], [64672.5, 0.008], [64684.6, 0.001]], "asks": [[64692.0, 0.005], [64692.1, 0.542], [64692.2, 0.111], [64692.7, 0.149], [64695.4, 0.001], [64695.5, 0.124], [64696.3, 0.482], [64705.0, 0.047], [64831.7, 0.0], [65335.9, 6.758], [65421.8, 0.0], [65465.3, 46.791], [65553.3, 2.677], [65689.0, 10.035]]}
{"kind": "depth", "E": 1787080662679, "U": 11315371212763, "u": 11315371217603, "recv_ms": 1787080662626, "bids": [[14188.9, 1.862], [14288.9, 2.338], [51751.0, 0.0], [58220.0, 4.018], [61454.4, 0.0], [63688.9, 0.007], [64042.0, 2.17], [64171.4, 9.8], [64365.5, 5.385], [64682.2, 0.186], [64684.6, 0.001], [64688.9, 4.591]], "asks": [[64689.0, 11.239], [64692.1, 0.001], [64692.2, 0.652], [64692.7, 0.242], [64695.4, 0.464], [64695.5, 0.047], [64696.3, 0.003], [65206.5, 9.334], [65335.9, 6.758], [65689.0, 10.015]]}
{"kind": "depth", "E": 1787080662781, "U": 11315371217712, "u": 11315371222391, "recv_ms": 1787080662730, "bids": [[1000.0, 35.81], [14188.9, 2.212], [14288.9, 1.988], [58220.0, 4.018], [61454.4, 0.0], [62101.3, 2.788], [63919.1, 9.375], [64042.0, 2.17], [64082.2, 0.941], [64493.6, 8.148], [64532.4, 6.233], [64549.4, 3.155], [64623.4, 3.182], [64656.3, 1.011], [64664.6, 0.002], [64684.6, 0.001], [64686.6, 0.085], [64686.9, 0.0], [64688.9, 4.667]], "asks": [[64691.9, 0.614], [64692.0, 0.905], [64692.1, 0.001], [64692.2, 0.088], [64692.7, 0.149], [64695.4, 0.001], [64695.5, 0.055], [64696.1, 0.009], [64696.3, 0.543], [64696.8, 0.414], [64755.1, 3.423], [64818.4, 0.216], [64831.7, 1.767], [64848.7, 2.907], [64887.5, 4.864], [65335.9, 6.758], [65562.3, 15.871], [65603.8, 0.761], [65618.0, 6.931], [65713.4, 0.076]]}
{"kind": "depth", "E": 1787080662985, "U": 11315371226724, "u": 11315371232108, "recv_ms": 1787080662931, "bids": [[14188.9, 2.926], [14288.9, 1.274], [58220.0, 4.018], [61454.4, 0.0], [62101.3, 2.788], [63395.2, 0.071], [64042.0, 2.17], [64365.5, 5.375], [64630.6, 0.004], [64656.3, 0.986], [64664.7, 1.731]], "asks": [[64689.0, 11.239], [64747.3, 0.004], [64850.8, 0.005], [65335.9, 6.758], [65409.7, 4.612], [65982.7, 0.026]]}
{"kind": "depth", "E": 1787080663087, "U": 11315371232180, "u": 11315371254996, "recv_ms": 1787080663034, "bids": [[1000.0, 35.81], [14188.9, 3.29], [14288.9, 0.91], [58220.0, 4.018], [61454.4, 0.0], [63071.7, 1.991], [63395.2, 0.068], [63688.9, 0.007], [64042.0, 2.169], [64365.4, 0.002], [64549.4, 4.521], [64588.5, 0.005], [64588.6, 0.016], [64672.9, 0.001], [64675.6, 0.548], [64677.3, 0.002], [64682.0, 0.103], [64684.4, 2.006], [64684.5, 0.027], [64684.6, 0.001], [64685.5, 0.0], [64685.6, 0.07], [64685.7, 0.106], [64688.4, 0.112], [64688.8, 0.066], [64688.9, 4.564]], "asks": [[64689.0, 10.982], [64689.1, 0.235], [64689.6, 0.112], [64691.8, 0.022], [64693.8, 0.005], [64695.5, 0.039], [64718.5, 0.4], [64727.1, 0.002], [64734.2, 0.497], [64831.7, 5.399], [64879.6, 0.118], [64879.7, 0.006], [64887.5, 4.374], [65012.5, 0.001], [65335.9, 6.758], [65392.5, 0.0], [65486.9, 0.797], [65493.8, 2.959], [65627.0, 37.332], [65689.0, 10.015], [71157.9, 0.0]]}
{"kind": "depth", "E": 1787080663189, "U": 11315371255554, "u": 11315371266845, "recv_ms": 1787080663137, "bids": [[14188.9, 3.64], [14288.9, 0.56], [58220.0, 4.018], [61454.4, 0.0], [62101.3, 2.785], [63524.5, 2.836], [63815.6, 16.507], [63912.6, 45.188], [63920.4, 16.952], [64042.0, 2.169], [64171.4, 9.179], [64365.5, 4.987], [64495.3, 0.007], [64541.8, 0.003], [64605.8, 0.028], [64652.4, 0.4], [64654.3, 0.002], [64655.7, 0.333], [64656.2, 0.003], [64664.6, 0.027], [64664.7, 1.706], [64665.5, 0.081], [64674.7, 0.078], [64675.2, 0.033], [64675.6, 0.541], [64681.0, 0.001], [64681.4, 0.004], [64682.0, 0.103], [64683.0, 0.044], [64685.3, 0.255], [64686.4, 0.004], [64686.6, 0.001], [64688.9, 4.339]], "asks": [[64689.0, 11.086], [64689.1, 0.703], [64690.5, 0.136], [64690.7, 0.565], [64690.8, 2.326], [64690.9, 0.001], [64691.0, 0.987], [64691.3, 0.005], [64691.8, 0.006], [64691.9, 0.05], [64692.0, 0.905], [64692.6, 0.072], [64693.0, 0.002], [64693.1, 0.111], [64694.8, 0.01], [64695.4, 0.472], [64695.5, 0.132], [64696.1, 0.001], [64696.3, 0.003], [64701.9, 0.279], [64702.0, 2.903], [64733.0, 0.0], [64734.2, 0.521], [65335.9, 6.758], [66148.3, 0.603]]}
{"kind": "depth", "E": 1787080663291, "U": 11315371266894, "u": 11315371273238, "recv_ms": 1787080663236, "bids": [[14188.9, 3.752], [14288.9, 0.322], [14588.9, 0.126], [51751.0, 0.0], [58220.0, 4.018], [62101.3, 2.788], [63688.9, 0.027], [64042.0, 2.169], [64365.5, 4.987], [64490.7, 0.02], [64518.8, 0.049], [64656.3, 1.011], [64658.9, 2.562], [64664.6, 0.002], [64675.6, 0.0], [64682.0, 0.103], [64683.0, 0.044], [64683.1, 0.626]], "asks": [[64689.0, 11.119], [64690.6, 0.103], [64690.9, 0.003], [64692.2, 0.122], [64693.9, 0.003], [64695.4, 0.001], [64695.5, 0.047], [64696.3, 0.559], [64708.4, 0.375], [64721.5, 0.0], [65335.9, 6.758], [65689.0, 10.035], [66144.5, 0.603]]}
{"kind": "depth", "E": 1787080663393, "U": 11315371273366, "u": 11315371278405, "recv_ms": 1787080663339, "bids": [[1000.0, 35.81], [14188.9, 3.626], [14288.9, 0.21], [14588.9, 0.364], [51751.0, 0.0], [58220.0, 4.018], [61454.4, 0.0], [62101.3, 2.785], [64042.0, 2.169], [64656.3, 0.986], [64658.9, 2.564], [64664.7, 1.731], [64666.7, 0.122], [64666.9, 1.118], [64675.6, 0.0], [64683.1, 0.085], [64683.2, 0.002], [64683.5, 0.111], [64683.8, 0.149], [64683.9, 0.542]], "asks": [[64689.0, 11.119], [64690.6, 0.002], [64692.2, 0.088], [64721.5, 0.002], [64848.7, 10.414], [64887.5, 9.447], [65335.9, 6.758], [65407.5, 0.46]]}
{"kind": "depth", "E": 1787080663495, "U": 11315371278864, "u": 11315371284181, "recv_ms": 1787080663443, "bids": [[14188.9, 3.514], [14288.9, 0.084], [14588.9, 0.602], [51751.1, 0.0], [58220.0, 4.018], [61454.4, 0.0], [62101.3, 2.788], [63395.2, 0.071], [63524.5, 3.213], [63688.9, 0.007], [63912.6, 47.688], [64042.0, 2.169], [64171.4, 9.801], [64365.5, 5.375], [64672.5, 0.008], [64675.6, 0.0], [64682.0, 0.228], [64683.0, 0.044], [64683.1, 0.626], [64683.9, 0.001], [64688.9, 4.339]], "asks": [[64689.0, 11.12], [64690.6, 0.002], [64692.3, 0.838], [64692.5, 0.102], [64705.0, 0.047], [65335.9, 6.758], [65501.4, 2.667], [65551.6, 0.0], [65561.7, 0.612], [65689.0, 10.015]]}
{"kind": "depth", "E": 1787080663597, "U": 11315371284271, "u": 11315371289464, "recv_ms": 1787080663545, "bids": [[1000.0, 35.81], [14188.9, 3.332], [14288.9, 0.0], [14588.9, 0.868], [58220.0, 4.018], [61454.4, 0.0], [61454.5, 2.463], [61454.6, 0.008], [64042.0, 2.169], [64365.4, 0.001], [64365.5, 5.375], [64549.4, 4.395], [64630.6, 0.004], [64643.6, 0.441], [64665.5, 0.699], [64666.3, 0.002], [64668.7, 2.233], [64672.9, 0.619], [64675.6, 0.548], [64682.0, 0.353], [64683.0, 0.037], [64683.1, 0.085], [64683.2, 0.002], [64688.8, 0.217], [64688.9, 4.564]], "asks": [[64689.0, 10.95], [64696.7, 2.937], [64704.1, 1.111], [64704.3, 0.126], [64711.3, 0.172], [64734.3, 0.306], [64829.2, 2.15], [64887.5, 5.08], [65335.9, 6.758], [65575.2, 4.258]]}
{"kind": "depth", "E": 1787080663699, "U": 11315371289524, "u": 11315371294488, "recv_ms": 1787080663647, "bids": [[1000.0, 35.81], [14188.9, 2.968], [14588.9, 1.232], [58220.0, 4.018], [61454.4, 0.0], [61454.5, 2.465], [62101.3, 2.785], [63688.9, 0.027], [63919.1, 8.437], [64042.0, 2.169], [64665.1, 0.002], [64665.2, 0.559], [64665.5, 0.081], [64666.2, 2.558], [64672.7, 0.736], [64672.9, 0.001], [64675.4, 0.001], [64675.6, 0.0], [64675.7, 0.172], [64678.7, 0.544], [64682.0, 0.103], [64683.0, 0.585], [64683.1, 0.335], [64688.9, 4.339]], "asks": [[64689.0, 11.331], [64689.2, 0.488], [64690.9, 0.001], [64691.1, 0.013], [64693.3, 0.499], [64693.4, 0.028], [64696.7, 2.319], [64697.3, 0.465], [64698.2, 0.768], [64699.0, 0.057], [64702.5, 1.017], [64703.9, 0.688], [64707.2, 0.024], [64708.5, 0.885], [64711.2, 0.001], [64719.7, 0.842], [64728.0, 1.239], [65012.5, 0.002], [65335.9, 6.758], [65689.0, 10.035]]}
{"kind": "depth", "E": 1787080663801, "U": 11315371294543, "u": 11315371298989, "recv_ms": 1787080663749, "bids": [[14188.9, 2.618], [14588.9, 1.582], [51751.0, 0.0], [58220.0, 4.018], [62101.3, 2.788], [63592.8, 11.458], [63819.2, 4.379], [64667.3, 0.371], [64674.0, 0.335], [64675.4, 0.542], [64675.6, 0.0], [64678.7, 0.003], [64682.0, 0.103], [64683.0, 0.585], [64683.1, 0.085], [64683.2, 0.002], [64683.5, 0.111]], "asks": [[64707.2, 0.565], [64708.4, 0.446], [64708.5, 0.344], [64784.2, 0.0], [64818.4, 0.216], [65335.9, 6.758], [65497.6, 20.633]]}
{"kind": "depth", "E": 1787080663903, "U": 11315371299276, "u": 11315371305460, "recv_ms": 1787080663850, "bids": [[1000.0, 35.81], [14188.9, 2.254], [14588.9, 1.946], [58220.0, 4.018], [61454.4, 0.0], [62101.3, 2.785], [63688.9, 0.007], [63779.5, 5.622], [63919.1, 9.375], [64042.0, 2.169], [64365.5, 5.375], [64656.2, 0.028], [64661.3, 0.042], [64664.7, 1.706], [64667.5, 0.044], [64675.6, 0.0], [64682.0, 0.353], [64683.0, 0.044], [64683.1, 0.085], [64683.2, 0.543]], "asks": [[64689.0, 11.502], [64690.6, 0.002], [64691.0, 0.087], [64691.9, 0.05], [64692.0, 0.005], [64751.8, 0.137], [65335.9, 6.758], [65520.5, 0.0], [65594.6, 47.687], [65689.0, 10.015]]}
{"kind": "depth", "E": 1787080664005, "U": 11315371305642, "u": 11315371312737, "recv_ms": 1787080663953, "bids": [[1000.0, 35.81], [14188.9, 1.904], [14588.9, 2.296], [58220.0, 4.018], [61454.4, 0.0], [62101.3, 2.788], [63395.2, 0.074], [63589.2, 18.188], [64042.0, 2.169], [64625.4, 0.033], [64656.0, 0.871], [64656.1, 0.002], [64656.2, 0.028], [64659.4, 0.008], [64659.5, 0.003], [64659.6, 0.002], [64675.6, 0.548], [64682.0, 0.353], [64683.0, 0.037], [64683.2, 0.002], [64683.5, 0.111], [64686.7, 0.086], [64688.9, 4.44]], "asks": [[64689.2, 0.404], [64689.6, 0.028], [64690.7, 0.565], [64693.0, 0.902], [64693.1, 0.091], [64693.3, 0.477], [64695.5, 0.047], [64696.1, 0.001], [64696.3, 0.559], [64704.1, 0.493], [64718.5, 0.34], [64727.1, 0.062], [64887.5, 7.821], [65335.9, 6.758], [65497.6, 20.633], [65691.7, 19.91], [65982.7, 0.023]]}
{"kind": "depth", "E": 1787080664107, "U": 11315371312881, "u": 11315371318979, "recv_ms": 1787080664052, "bids": [[14188.9, 1.54], [14588.9, 2.66], [51751.0, 0.0], [58220.0, 4.018], [61454.5, 2.467], [63688.9, 0.027], [63700.9, 0.029], [63815.6, 17.132], [64042.0, 2.169], [64365.4, 0.0], [64675.6, 0.541], [64675.7, 0.172], [64677.3, 0.002], [64682.0, 0.103], [64683.0, 0.044], [64684.5, 0.277]], "asks": [[64848.7, 6.821], [64887.5, 9.255], [65012.5, 0.003], [65335.9, 6.758], [65677.1, 0.067], [65689.0, 10.035], [65982.7, 0.02]]}
{"kind": "depth", "E": 1787080664209, "U": 11315371319213, "u": 11315371325620, "recv_ms": 1787080664156, "bids": [[1000.0, 35.81], [14188.9, 1.176], [14588.9, 3.024], [51751.0, 0.0], [58220.0, 4.018], [61454.4, 0.0], [62101.3, 2.785], [63700.9, 0.038], [64042.0, 2.169], [64365.5, 5.375], [64549.4, 5.064], [64643.6, 0.444], [64656.2, 0.003], [64664.3, 0.085], [64675.7, 0.172], [64683.0, 0.294], [64684.5, 0.027], [64688.9, 4.44]], "asks": [[64699.3, 0.381], [64766.7, 0.203], [64831.7, 4.729], [64887.5, 12.417], [65335.9, 6.758], [65402.1, 1.39], [65409.7, 5.376]]}
{"kind": "depth", "E": 1787080664311, "U": 11315371325687, "u": 11315371331587, "recv_ms": 1787080664257, "bids": [[1000.0, 35.81], [14188.9, 0.826], [14588.9, 3.374], [51751.0, 0.0], [58220.0, 4.018], [61454.4, 0.006], [62101.3, 2.788], [63688.9, 0.007], [64042.0, 2.171], [64675.7, 0.179], [64683.0, 0.287], [64687.2, 0.084]], "asks": [[64689.0, 11.502], [64848.7, 10.414], [64887.5, 7.641], [65335.9, 6.758], [65602.7, 43.574], [65677.1, 0.076], [65689.0, 10.015]]}
{"kind": "depth", "E": 1787080664515, "U": 11315371337094, "u": 11315371341698, "recv_ms": 1787080664461, "bids": [[1000.0, 35.81], [14188.9, 0.294], [14488.9, 0.182], [14588.9, 3.724], [51751.1, 0.0], [58220.0, 4.018], [61454.4, 0.006], [63688.9, 0.027], [64042.0, 2.169], [64570.3, 3.865], [64572.0, 0.038], [64582.5, 2.383], [64617.7, 2.381], [64672.5, 0.008], [64675.7, 0.179], [64682.0, 0.103], [64683.0, 0.287], [64685.3, 0.023], [64685.6, 0.047], [64686.1, 0.232], [64688.8, 0.066], [64688.9, 4.665]], "asks": [[64690.6, 0.002], [64705.0, 0.047], [64708.4, 0.375], [64751.2, 0.006], [64753.7, 0.106], [64760.1, 0.047], [64796.3, 1.237], [64796.4, 2.32], [64824.4, 3.865], [64831.7, 5.399], [64848.7, 10.414], [64887.5, 5.393], [65335.9, 6.758], [65394.1, 11.158], [65627.0, 38.092], [65689.0, 10.035], [65700.1, 0.651]]}
{"kind": "depth", "E": 1787080664617, "U": 11315371341834, "u": 11315371346069, "recv_ms": 1787080664564, "bids": [[1000.0, 35.81], [14188.9, 0.182], [14488.9, 0.42], [14588.9, 3.598], [58220.0, 4.018], [62101.3, 2.788], [63395.2, 0.016], [63467.1, 0.16], [63539.0, 0.019], [63610.8, 2.395], [63682.7, 0.0], [63754.6, 9.401], [63826.5, 0.783], [63898.4, 0.014], [63919.1, 9.375], [63970.2, 0.0], [64042.0, 2.169], [64042.1, 0.0], [64145.5, 0.228], [64683.0, 0.162], [64684.5, 0.152]], "asks": [[64690.6, 0.004], [64848.7, 6.821], [64887.5, 9.561], [65335.9, 6.7], [65407.8, 0.02], [65479.6, 0.017], [65551.5, 0.0], [65594.6, 49.971], [65604.9, 0.913], [65623.4, 0.155], [65627.0, 37.027], [65695.3, 0.002], [65767.1, 0.003], [65839.0, 0.012], [65910.9, 0.0], [65982.8, 2.31]]}
{"kind": "depth", "E": 1787080664821, "U": 11315371352034, "u": 11315371357107, "recv_ms": 1787080664767, "bids": [[1000.0, 35.81], [14188.9, 0.0], [14488.9, 0.952], [14588.9, 3.248], [58220.0, 4.018], [61454.4, 0.006], [62101.3, 2.788], [63395.2, 0.019], [64042.0, 2.169], [64365.4, 0.001], [64493.6, 7.529], [64532.4, 4.758], [64549.4, 2.452], [64588.3, 0.001], [64594.7, 0.004], [64601.2, 4.055], [64607.7, 0.008], [64611.2, 0.003], [64614.1, 0.01], [64620.6, 0.011], [64623.4, 3.184], [64627.1, 2.372], [64630.6, 0.001], [64633.5, 0.632], [64640.0, 0.304], [64643.6, 0.441], [64646.5, 0.383], [64652.9, 0.036], [64659.4, 0.005], [64665.5, 0.699], [64666.6, 0.046], [64672.9, 0.619], [64673.3, 0.014], [64674.4, 0.157], [64679.8, 0.004], [64683.0, 0.037], [64688.9, 4.665]], "asks": [[64689.0, 11.501], [64695.0, 0.204], [64695.1, 0.017], [64696.7, 2.937], [64699.3, 0.378], [64704.1, 1.111], [64705.8, 0.001], [64712.2, 2.327], [64718.7, 0.002], [64725.2, 0.001], [64731.6, 0.012], [64734.3, 0.306], [64736.1, 0.001], [64742.5, 0.014], [64749.0, 0.0], [64752.0, 7.108], [64755.1, 3.619], [64755.5, 0.0], [64762.6, 0.0], [64766.7, 0.2], [64779.2, 1.269], [64783.7, 0.0], [64786.2, 0.0], [64790.0, 0.005], [64818.4, 0.216], [64831.7, 1.947], [64848.7, 2.876], [64887.5, 4.795], [65335.9, 6.7], [65497.6, 20.861]]}
{"kind": "depth", "E": 1787080665127, "U": 11315371368205, "u": 11315371375668, "recv_ms": 1787080665075, "bids": [[1000.0, 35.81], [14488.9, 2.03], [14588.9, 2.17], [51751.0, 0.0], [58220.0, 4.018], [62101.3, 2.788], [63688.9, 0.007], [63880.3, 25.995], [64042.0, 2.169], [64677.3, 0.002], [64683.0, 0.037], [64683.5, 0.236]], "asks": [[64693.2, 0.285], [64695.1, 0.018], [64697.5, 0.228], [64697.6, 0.213], [64699.3, 0.377], [65012.5, 0.001], [65335.9, 6.7], [65497.6, 21.013], [65689.0, 10.015]]}
{"kind": "depth", "E": 1787080665229, "U": 11315371376054, "u": 11315371381698, "recv_ms": 1787080665179, "bids": [[1000.0, 35.81], [14488.9, 2.394], [14588.9, 1.806], [58220.0, 4.018], [61454.4, 0.006], [62101.3, 2.785], [63688.9, 0.027], [64042.0, 2.173], [64365.4, 0.002], [64582.5, 2.383], [64683.5, 0.111], [64683.6, 0.003], [64687.2, 0.0], [64688.9, 4.665]], "asks": [[64689.0, 11.492], [64692.2, 0.122], [64692.9, 0.034], [64693.1, 0.091], [64695.1, 0.017], [64751.2, 0.015], [64796.4, 2.32], [64848.7, 6.275], [64887.5, 12.572], [65335.9, 6.702], [65433.6, 10.996], [65689.0, 10.035]]}
{"kind": "depth", "E": 1787080665331, "U": 11315371381761, "u": 11315371388044, "recv_ms": 1787080665277, "bids": [[14488.9, 2.744], [14588.9, 1.456], [58220.0, 4.018], [61454.4, 0.012], [62101.3, 2.788], [63847.9, 19.547], [63939.8, 0.0], [64042.0, 2.169], [64106.7, 10.906], [64365.5, 5.385], [64664.3, 2.009], [64664.6, 0.002], [64665.2, 0.002], [64665.4, 0.634], [64666.2, 2.558], [64669.5, 0.005], [64670.1, 0.444], [64670.3, 0.984], [64671.1, 0.002], [64675.4, 0.542], [64675.6, 0.0], [64675.7, 0.172], [64678.7, 0.003], [64681.0, 0.0], [64681.4, 0.005], [64682.0, 0.237], [64682.7, 0.121], [64683.0, 0.653], [64684.5, 0.018], [64685.8, 0.02], [64686.2, 0.002], [64686.7, 0.002], [64688.9, 4.593]], "asks": [[64689.0, 11.436], [64689.1, 0.787], [64689.7, 0.084], [64690.6, 0.004], [64692.2, 0.088], [64692.5, 0.08], [64692.7, 0.149], [64692.9, 0.0], [64693.0, 1.212], [64693.1, 0.091], [64702.0, 2.903], [64702.8, 0.021], [64703.5, 0.032], [64703.6, 0.929], [64704.8, 0.006], [64705.8, 0.001], [64706.3, 0.17], [64706.4, 0.563], [64706.5, 0.002], [64707.2, 0.024], [64707.3, 1.864], [64708.4, 0.251], [64708.5, 0.344], [64848.7, 10.414], [64887.5, 7.358], [65271.2, 14.243], [65335.9, 6.7], [65402.1, 0.704], [65458.8, 8.241], [65530.0, 19.879], [65539.7, 9.146]]}
{"kind": "depth", "E": 1787080665433, "U": 11315371388210, "u": 11315371393103, "recv_ms": 1787080665379, "bids": [[1000.0, 35.81], [14488.9, 3.094], [14588.9, 1.106], [58220.0, 4.018], [62101.3, 2.785], [63333.5, 0.0], [63744.6, 0.049], [64042.0, 2.169], [64675.6, 0.541], [64675.7, 0.179], [64682.0, 0.103], [64683.0, 0.037], [64683.1, 0.085], [64684.5, 0.268], [64686.4, 0.088]], "asks": [[64689.1, 0.703], [64690.6, 0.002], [64887.5, 4.916], [65335.9, 6.7], [65493.8, 2.701], [71157.9, 0.0]]}
{"kind": "depth", "E": 1787080665535, "U": 11315371393198, "u": 11315371399943, "recv_ms": 1787080665482, "bids": [[1000.0, 35.81], [14488.9, 3.458], [14588.9, 0.742], [51751.1, 0.0], [58220.0, 4.018], [61454.4, 0.012], [63688.9, 0.007], [63783.3, 41.153], [63791.0, 31.325], [63938.7, 0.115], [64042.0, 2.169], [64656.0, 0.869], [64656.1, 0.0], [64656.2, 0.001], [64659.4, 0.003], [64659.5, 0.001], [64659.6, 0.0], [64665.5, 0.081], [64672.5, 0.006], [64672.9, 0.001], [64675.7, 0.172], [64682.0, 0.137], [64683.0, 0.044], [64684.5, 0.268]], "asks": [[64689.0, 11.447], [64690.6, 0.002], [64693.0, 0.902], [64696.7, 2.319], [64704.1, 0.493], [64705.0, 0.045], [64848.7, 6.821], [64887.5, 9.282], [65335.9, 6.7], [65458.8, 9.157], [65689.0, 10.015], [65982.7, 0.017]]}
{"kind": "depth", "E": 1787080665637, "U": 11315371400057, "u": 11315371406214, "recv_ms": 1787080665586, "bids": [[14388.9, 0.042], [14488.9, 3.738], [14588.9, 0.42], [51751.0, 0.0], [58220.0, 4.018], [62101.3, 2.788], [63324.4, 0.173], [63932.0, 6.257], [63991.6, 1.406], [64042.0, 2.169], [64365.5, 5.385], [64532.4, 0.212], [64534.1, 1.423], [64549.4, 0.0], [64672.5, 0.008], [64675.7, 0.172], [64682.0, 0.171], [64683.0, 0.044], [64684.5, 0.268]], "asks": [[64705.0, 0.047], [64829.2, 1.531], [64831.7, 0.0], [64848.7, 0.005], [65335.9, 6.7], [65394.1, 11.844], [65507.3, 1.542]]}
{"kind": "depth", "E": 1787080665841, "U": 11315371413691, "u": 11315371420326, "recv_ms": 1787080665788, "bids": [[1000.0, 35.81], [14388.9, 0.462], [14488.9, 3.584], [14588.9, 0.154], [58220.0, 4.018], [61454.4, 0.012], [61454.5, 2.465], [61454.6, 0.008], [62101.3, 2.788], [63395.2, 0.077], [63467.1, 0.218], [63539.0, 0.077], [63610.8, 2.453], [63682.7, 0.058], [63754.6, 9.459], [63779.5, 5.434], [63826.5, 0.841], [63898.4, 0.072], [63970.2, 0.058], [63983.8, 9.658], [64042.0, 2.169], [64042.1, 0.058], [64140.2, 0.007], [64365.4, 0.001], [64493.6, 11.002], [64532.4, 9.677], [64534.1, 2.654], [64549.4, 5.104], [64588.6, 0.013], [64588.7, 0.003], [64629.0, 0.009], [64629.4, 0.212], [64629.7, 0.031], [64630.0, 3.072], [64630.3, 1.398], [64642.0, 2.295], [64645.7, 0.161], [64645.8, 0.062], [64646.9, 0.374], [64647.2, 0.0], [64647.6, 0.002], [64647.9, 0.022], [64648.2, 0.0], [64648.4, 0.032], [64650.0, 2.838], [64650.3, 2.137], [64656.0, 0.871], [64656.1, 0.002], [64656.2, 0.003], [64657.0, 0.352], [64658.5, 2.373], [64658.6, 0.377], [64659.4, 0.005], [64659.5, 0.003], [64659.6, 0.002], [64660.0, 0.164], [64661.8, 0.009], [64661.9, 0.609], [64662.0, 0.137], [64662.1, 0.032], [64662.2, 0.0], [64662.3, 0.85], [64662.4, 2.363], [64662.5, 0.033], [64662.6, 0.111], [64662.8, 0.322], [64664.0, 1.384], [64664.4, 0.001], [64665.5, 0.699], [64672.9, 0.001], [64675.7, 0.179], [64679.6, 0.002], [64680.3, 0.007], [64681.4, 0.004], [64681.5, 1.057], [64681.6, 1.93], [64681.7, 0.07], [64681.8, 0.001], [64681.9, 0.005], [64682.0, 0.103], [64682.1, 0.102], [64682.2, 0.016], [64682.3, 0.2], [64682.4, 0.077], [64682.7, 0.089], [64683.0, 0.005], [64683.3, 0.002], [64683.7, 0.31], [64684.0, 0.001], [64684.2, 0.079], [64684.5, 0.018], [64686.9, 0.084], [64687.7, 0.001], [64688.1, 0.002], [64688.9, 4.592]], "asks": [[64689.0, 10.321], [64689.7, 0.0], [64690.1, 0.311], [64690.2, 0.091], [64691.1, 0.014], [64692.3, 0.819], [64692.4, 0.004], [64692.9, 0.0], [64693.1, 0.088], [64693.2, 0.305], [64693.4, 0.134], [64695.2, 0.044], [64695.3, 0.054], [64695.6, 1.479], [64695.9, 0.001], [64696.2, 0.244], [64696.4, 0.504], [64696.5, 0.464], [64696.8, 0.309], [64696.9, 0.155], [64697.0, 1.009], [64697.1, 0.37], [64697.2, 0.154], [64697.3, 0.325], [64697.4, 0.0], [64697.5, 0.06], [64697.6, 0.031], [64697.7, 0.557], [64697.8, 0.002], [64704.1, 0.493], [64713.1, 0.001], [64713.2, 1.375], [64713.4, 0.001], [64713.8, 0.004], [64714.1, 0.059], [64714.4, 0.443], [64714.5, 0.541], [64714.8, 3.539], [64715.2, 1.256], [64716.4, 0.001], [64716.6, 0.096], [64716.7, 0.131], [64716.8, 0.208], [64716.9, 0.182], [64717.0, 0.13], [64717.1, 0.0], [64717.2, 0.041], [64717.3, 1.342], [64717.4, 0.067], [64731.0, 0.066], [64731.1, 0.042], [64731.3, 0.17], [64731.7, 0.021], [64732.0, 0.023], [64732.3, 0.019], [64753.7, 0.115], [64791.2, 2.148], [64791.3, 0.0], [64799.5, 2.137], [64799.6, 0.0], [64807.8, 2.132], [64807.9, 0.0], [64818.4, 0.216], [64831.7, 4.534], [64848.7, 10.414], [64879.7, 0.003], [64879.8, 0.003], [64887.5, 4.916], [65012.5, 0.002], [65206.5, 8.721], [65335.9, 6.758], [65407.8, 0.078], [65479.6, 0.075], [65493.8, 2.442], [65497.6, 21.356], [65551.5, 0.058], [65623.4, 0.213], [65647.9, 2.432], [65695.3, 0.06], [65767.1, 0.061], [65839.0, 0.07], [65910.9, 0.058], [65982.8, 2.368]]}
{"kind": "depth", "E": 1787080666045, "U": 11315371426840, "u": 11315371433633, "recv_ms": 1787080665991, "bids": [[1000.0, 35.81], [14388.9, 1.036], [14488.9, 3.164], [14588.9, 0.0], [58220.0, 4.016], [62101.3, 2.785], [63987.5, 6.781], [64042.0, 2.169], [64625.4, 0.133], [64647.1, 0.343], [64647.7, 0.435], [64677.3, 0.007], [64681.9, 0.075], [64682.2, 0.186], [64682.9, 1.921], [64683.5, 0.143], [64684.5, 0.018], [64688.8, 0.066]], "asks": [[64695.9, 0.043], [64696.6, 0.064], [64697.2, 0.238], [64697.5, 0.257], [64713.8, 0.046], [64714.5, 0.583], [64716.8, 0.292], [64717.1, 0.197], [64731.7, 0.063], [64732.4, 0.043], [64887.5, 4.813], [65206.5, 9.64], [65335.9, 6.758], [65639.9, 13.079], [65982.7, 0.014]]}
{"kind": "depth", "E": 1787080666147, "U": 11315371433652, "u": 11315371440443, "recv_ms": 1787080666093, "bids": [[1000.0, 35.81], [14388.9, 1.4], [14488.9, 2.8], [58220.0, 4.018], [61454.6, 0.006], [62101.3, 2.788], [63688.9, 0.027], [63700.8, 1.71], [63700.9, 0.048], [63855.7, 4.534], [64042.0, 2.169], [64609.5, 0.054], [64611.2, 0.0], [64630.5, 0.046], [64643.6, 0.444], [64648.1, 0.055], [64675.7, 0.172], [64677.3, 0.002], [64681.6, 2.0], [64681.9, 0.145], [64683.0, 0.012], [64683.8, 0.181], [64684.5, 0.018]], "asks": [[64694.5, 0.014], [64695.6, 1.514], [64697.6, 0.22], [64697.8, 0.163], [64713.5, 0.346], [64717.2, 0.23], [64717.4, 0.228], [64731.4, 0.035], [64734.3, 0.306], [65335.9, 6.758], [65627.0, 39.157], [65677.0, 0.002], [65689.0, 10.035], [65840.5, 0.76]]}
{"kind": "depth", "E": 1787080666249, "U": 11315371440602, "u": 11315371448003, "recv_ms": 1787080666196, "bids": [[14388.9, 1.75], [14488.9, 2.45], [58220.0, 4.018], [61454.4, 0.018], [62101.3, 2.785], [63983.8, 10.671], [64042.0, 2.169], [64365.4, 0.0], [64365.5, 5.375], [64559.5, 0.023], [64629.5, 0.048], [64630.6, 0.004], [64637.0, 0.016], [64650.0, 2.852], [64662.1, 0.102], [64662.4, 2.463], [64662.5, 0.133], [64662.7, 0.201], [64662.8, 0.392], [64663.0, 0.092], [64675.6, 0.0], [64675.7, 0.172], [64682.1, 0.352], [64682.5, 0.102], [64683.0, 0.553], [64684.5, 0.018], [64686.9, 0.0], [64688.9, 4.367]], "asks": [[64689.0, 10.45], [64689.5, 0.084], [64691.1, 0.012], [64692.9, 0.003], [64697.0, 1.169], [64711.3, 0.168], [64714.8, 3.699], [64766.7, 0.203], [64887.5, 7.636], [65012.5, 0.003], [65335.9, 6.758], [65473.3, 24.804], [65497.6, 21.127], [65588.2, 13.393], [65677.1, 0.086]]}
{"kind": "depth", "E": 1787080666453, "U": 11315371454332, "u": 11315371459768, "recv_ms": 1787080666398, "bids": [[1000.0, 35.81], [14388.9, 2.464], [14488.9, 1.736], [51751.0, 0.0], [58220.0, 4.018], [61454.4, 0.018], [63395.2, 0.077], [63880.3, 26.229], [64042.0, 2.169], [64624.2, 0.039], [64656.3, 1.011], [64662.3, 0.92], [64662.6, 0.181], [64664.7, 1.706], [64666.8, 0.032], [64675.4, 0.542], [64678.7, 0.003], [64682.1, 0.102], [64685.8, 0.042], [64688.8, 0.219]], "asks": [[64689.0, 10.448], [64707.2, 0.565], [64707.3, 1.323], [64708.5, 0.344], [64753.7, 0.114], [64848.7, 10.414], [64887.5, 7.636], [65335.9, 6.758], [65601.1, 7.155], [65686.1, 0.0]]}
{"kind": "depth", "E": 1787080666555, "U": 11315371459973, "u": 11315371464473, "recv_ms": 1787080666507, "bids": [[14388.9, 2.828], [14488.9, 1.372], [51751.0, 0.0], [51751.1, 0.0], [58220.0, 4.018], [61454.4, 0.018], [62101.3, 2.785], [63686.2, 17.252], [63688.9, 0.027], [63750.9, 36.508], [64042.0, 2.169], [64365.5, 5.375], [64662.0, 0.207], [64662.2, 0.14], [64664.6, 0.102], [64665.5, 0.081], [64672.5, 0.006], [64675.6, 0.0], [64682.1, 0.102], [64683.0, 0.012], [64683.1, 0.085], [64683.2, 0.034], [64683.9, 0.542], [64684.5, 0.268], [64688.9, 4.361]], "asks": [[64689.0, 10.509], [64705.0, 0.045], [64708.7, 0.003], [65335.9, 6.758], [65465.3, 48.317], [65689.0, 10.035]]}
{"kind": "depth", "E": 1787080666657, "U": 11315371464553, "u": 11315371468937, "recv_ms": 1787080666603, "bids": [[1000.0, 35.81], [14388.9, 3.192], [14488.9, 1.008], [51751.0, 0.0], [58220.0, 4.018], [61454.4, 0.018], [62101.3, 2.788], [64042.0, 2.169], [64145.5, 0.256], [64672.5, 0.008], [64675.6, 0.541], [64683.0, 0.012], [64683.9, 0.001], [64684.5, 0.268]], "asks": [[64689.0, 10.433], [64705.0, 0.047], [64733.0, 0.042], [64752.0, 7.528], [65335.9, 6.758], [71157.9, 0.002]]}
{"kind": "depth", "E": 1787080666759, "U": 11315371468996, "u": 11315371474614, "recv_ms": 1787080666705, "bids": [[1000.0, 35.81], [14388.9, 3.542], [14488.9, 0.658], [58220.0, 4.018], [61454.6, 0.004], [62101.3, 2.785], [62955.2, 0.005], [63688.9, 0.007], [63819.2, 3.754], [64042.0, 2.169], [64656.3, 0.986], [64664.7, 1.731], [64675.7, 0.172], [64683.0, 0.012], [64684.5, 0.018], [64688.9, 4.371]], "asks": [[64689.0, 10.579], [64691.1, 0.012], [64694.5, 0.013], [64696.3, 0.744], [64701.1, 0.63], [64703.1, 0.404], [64709.0, 0.157], [64716.1, 0.073], [64818.4, 0.216], [65012.5, 0.002], [65101.7, 0.0], [65335.9, 6.758], [65501.4, 2.553], [65602.7, 41.29], [65689.0, 10.015], [71157.9, 0.0]]}
{"kind": "depth", "E": 1787080667065, "U": 11315371488755, "u": 11315371500462, "recv_ms": 1787080667012, "bids": [[1000.0, 35.81], [14288.9, 0.518], [14388.9, 3.57], [14488.9, 0.112], [58220.0, 4.018], [61454.4, 0.018], [62101.3, 2.785], [63688.9, 0.027], [63718.6, 9.741], [63779.5, 5.246], [63791.0, 28.976], [63815.6, 17.757], [64042.0, 2.169], [64365.4, 0.001], [64493.6, 10.401], [64532.4, 8.197], [64549.4, 4.395], [64591.7, 0.654], [64598.2, 0.029], [64604.6, 0.032], [64611.1, 2.251], [64617.6, 3.657], [64624.0, 0.204], [64630.5, 0.049], [64637.0, 0.019], [64643.4, 0.31], [64649.9, 0.026], [64656.4, 0.014], [64662.9, 1.184], [64665.5, 0.699], [64666.8, 0.028], [64669.3, 0.129], [64672.7, 0.736], [64672.9, 0.619], [64675.7, 0.179], [64675.8, 0.007], [64677.3, 0.002], [64682.3, 0.203], [64682.7, 0.005], [64683.0, 0.005], [64684.5, 0.268], [64686.9, 0.084], [64687.5, 0.086], [64687.7, 0.311], [64688.4, 0.121], [64688.9, 4.597]], "asks": [[64689.0, 10.377], [64689.5, 0.0], [64690.2, 0.007], [64691.1, 0.014], [64692.9, 0.0], [64694.7, 0.009], [64696.8, 0.414], [64701.1, 0.633], [64703.3, 0.32], [64704.2, 0.465], [64707.6, 0.664], [64714.1, 0.107], [64720.5, 0.053], [64727.0, 0.056], [64733.5, 0.094], [64739.9, 0.021], [64746.4, 0.004], [64752.9, 0.003], [64759.3, 0.003], [64765.8, 0.003], [64772.3, 1.281], [64778.8, 2.324], [64785.2, 0.025], [64791.7, 0.224], [64829.2, 2.15], [64831.7, 3.671], [64848.7, 5.01], [64887.5, 7.636], [65090.0, 0.161], [65335.9, 6.758], [65689.0, 10.035], [65691.7, 18.846], [65982.7, 0.008]]}
{"kind": "depth", "E": 1787080667167, "U": 11315371500501, "u": 11315371514216, "recv_ms": 1787080667114, "bids": [[14288.9, 0.77], [14388.9, 3.43], [14488.9, 0.0], [51751.0, 0.002], [58220.0, 4.018], [62101.3, 2.788], [63912.6, 50.031], [64042.0, 2.169], [64365.5, 5.375], [64602.3, 0.001], [64609.5, 0.052], [64609.9, 0.001], [64637.0, 0.018], [64637.8, 0.002], [64672.9, 0.001], [64684.5, 0.018], [64687.5, 0.002]], "asks": [[64689.0, 10.483], [64690.5, 0.133], [64690.7, 0.568], [64693.0, 0.922], [64694.2, 0.002], [64735.6, 0.001], [64831.7, 5.399], [64848.7, 10.414], [64887.5, 5.075], [65335.9, 6.759], [65497.6, 21.499], [66042.1, 0.0]]}
{"kind": "depth", "E": 1787080667269, "U": 11315371514339, "u": 11315371520855, "recv_ms": 1787080667215, "bids": [[1000.0, 35.81], [14288.9, 1.134], [14388.9, 3.066], [51751.0, 0.0], [58220.0, 4.018], [61454.4, 0.018], [62101.3, 2.785], [62728.2, 0.0], [63688.9, 0.007], [63783.3, 43.502], [64042.0, 2.169], [64365.4, 0.002], [64656.3, 0.986], [64664.7, 1.731], [64684.5, 0.018], [64688.9, 4.597]], "asks": [[64689.0, 10.453], [64693.2, 0.327], [64693.7, 0.377], [64701.3, 0.225], [64701.4, 0.352], [65012.5, 0.001], [65335.9, 6.759], [65689.0, 10.015], [65982.7, 0.011]]}
{"kind": "depth", "E": 1787080667575, "U": 11315371532818, "u": 11315371539854, "recv_ms": 1787080667523, "bids": [[1000.0, 35.96], [14288.9, 2.198], [14388.9, 2.002], [51751.1, 0.0], [58220.0, 4.018], [62101.3, 2.785], [64042.0, 2.169], [64650.0, 2.838], [64665.5, 0.081], [64672.7, 0.736], [64675.7, 0.179], [64683.0, 0.005], [64684.5, 0.143], [64687.7, 0.001], [64688.9, 4.592]], "asks": [[64689.0, 10.458], [64690.0, 0.491], [64693.2, 0.33], [64735.6, 0.001], [64848.7, 6.277], [64887.5, 12.246], [65307.3, 8.495], [65335.9, 6.759], [65497.6, 21.758], [65982.7, 0.014]]}
{"kind": "depth", "E": 1787080667677, "U": 11315371539979, "u": 11315371545212, "recv_ms": 1787080667623, "bids": [[1000.0, 35.81], [14288.9, 2.548], [14388.9, 1.652], [51751.0, 0.0], [58220.0, 4.018], [61454.4, 0.018], [61454.6, 0.006], [62101.3, 2.788], [63688.9, 0.007], [63694.0, 10.589], [63912.6, 49.812], [63977.3, 1.872], [64042.0, 2.169], [64106.7, 12.307], [64171.4, 9.801], [64652.8, 0.389], [64672.5, 0.008], [64675.7, 0.172], [64683.0, 0.255], [64683.1, 0.092], [64684.5, 0.018], [64686.9, 0.0], [64688.9, 4.592]], "asks": [[64689.0, 10.458], [64705.0, 0.047], [64711.2, 0.003], [64711.3, 0.17], [64848.7, 10.414], [64887.5, 4.813], [65335.9, 6.759], [65453.9, 0.003], [65689.0, 10.015], [65982.7, 0.011], [66074.4, 0.003]]}
{"kind": "depth", "E": 1787080667779, "U": 11315371545372, "u": 11315371553067, "recv_ms": 1787080667726, "bids": [[14288.9, 2.912], [14388.9, 1.288], [51751.0, 0.0], [58220.0, 4.018], [62101.3, 2.785], [63714.8, 3.879], [64042.0, 2.169], [64365.5, 5.375], [64549.4, 0.0], [64683.0, 0.005]], "asks": [[64692.6, 0.025], [64818.4, 0.216], [64831.7, 0.0], [65335.9, 6.759]]}
{"kind": "depth", "E": 1787080667881, "U": 11315371553497, "u": 11315371561629, "recv_ms": 1787080667827, "bids": [[1000.0, 35.81], [14288.9, 3.276], [14388.9, 0.924], [58220.0, 4.018], [63686.2, 19.448], [64042.0, 2.169], [64549.4, 5.129], [64683.0, 0.005]], "asks": [[64831.7, 4.729], [64848.7, 6.848], [64887.5, 8.961], [65303.5, 15.289], [65335.9, 6.759], [65445.9, 3.738], [65497.6, 21.416], [65653.1, 0.0]]}
{"kind": "depth", "E": 1787080668085, "U": 11315371568398, "u": 11315371575634, "recv_ms": 1787080668032, "bids": [[14188.9, 0.112], [14288.9, 3.766], [14388.9, 0.322], [58220.0, 4.018], [61454.4, 0.018], [62101.3, 2.785], [63700.9, 0.04], [63765.6, 0.022], [63767.4, 0.003], [64042.0, 2.169], [64365.4, 0.001], [64365.5, 4.764], [64570.3, 0.0], [64571.3, 4.446], [64582.5, 2.383], [64588.7, 0.0], [64588.8, 1.014], [64617.7, 2.381], [64650.0, 2.852], [64665.6, 0.625], [64673.0, 2.466], [64677.3, 0.002], [64683.0, 0.005], [64684.5, 0.143], [64688.9, 4.591]], "asks": [[64689.0, 10.458], [64689.4, 0.084], [64696.9, 0.773], [64703.3, 0.32], [64704.3, 0.744], [64731.0, 0.096], [64731.2, 1.221], [64733.0, 0.0], [64760.1, 0.047], [64796.4, 2.32], [64824.4, 3.865], [64879.8, 0.0], [64879.9, 1.186], [65335.9, 6.761], [65337.4, 0.001], [65465.3, 49.079], [65610.6, 0.635], [65612.4, 0.015], [65677.1, 0.078]]}
{"kind": "depth", "E": 1787080668187, "U": 11315371575653, "u": 11315371581902, "recv_ms": 1787080668135, "bids": [[1000.0, 35.81], [14188.9, 0.35], [14288.9, 3.64], [14388.9, 0.21], [51751.0, 0.0], [58220.0, 4.018], [62101.3, 2.788], [63688.9, 0.007], [63700.9, 0.048], [63765.6, 0.03], [63767.4, 0.011], [64042.0, 2.169], [64365.5, 5.385], [64602.7, 0.026], [64609.5, 0.051], [64609.9, 0.003], [64637.0, 0.016], [64637.7, 0.009], [64637.8, 0.001], [64655.7, 0.17], [64665.1, 0.559], [64665.4, 0.077], [64666.2, 2.558], [64666.7, 0.122], [64667.7, 0.009], [64675.4, 0.542], [64675.7, 0.172], [64678.7, 0.003], [64683.0, 0.005], [64683.1, 0.092], [64684.5, 0.018], [64688.9, 4.601]], "asks": [[64689.0, 10.446], [64696.2, 0.29], [64705.4, 0.563], [64705.5, 1.257], [64706.9, 0.001], [64707.2, 0.565], [64708.5, 0.344], [64709.6, 0.001], [64710.5, 3.325], [64848.7, 10.414], [64887.5, 5.075], [65012.5, 0.002], [65335.9, 6.758], [65458.8, 8.242], [65659.3, 18.592], [65666.3, 0.392], [65689.0, 10.015]]}
{"kind": "depth", "E": 1787080668289, "U": 11315371581982, "u": 11315371587129, "recv_ms": 1787080668241, "bids": [[14188.9, 0.588], [14288.9, 3.528], [14388.9, 0.084], [51751.0, 0.0], [58220.0, 4.018], [61454.4, 0.018], [62101.3, 2.785], [64042.0, 2.169], [64145.5, 0.256], [64365.4, 0.0], [64527.1, 0.003], [64611.2, 0.003], [64656.0, 0.869], [64656.1, 0.0], [64656.2, 0.026], [64659.4, 0.003], [64659.5, 0.001], [64659.6, 0.0], [64665.6, 0.007], [64673.0, 1.848], [64675.7, 0.179], [64683.0, 0.005], [64683.1, 0.085], [64684.5, 0.018], [64688.4, 0.112], [64688.9, 4.6]], "asks": [[64689.0, 10.45], [64691.1, 0.014], [64696.2, 0.289], [64696.9, 0.155], [64704.3, 0.126], [64709.6, 0.116], [64710.5, 3.21], [64731.0, 0.066], [64731.2, 1.251], [64799.0, 0.079], [64848.7, 10.414], [64887.5, 4.814], [65335.9, 6.758], [65610.6, 0.643], [65612.4, 0.023], [65677.1, 0.086], [65982.7, 0.014]]}
{"kind": "depth", "E": 1787080668391, "U": 11315371587205, "u": 11315371592105, "recv_ms": 1787080668338, "bids": [[14188.9, 0.854], [14288.9, 3.346], [14388.9, 0.0], [58220.0, 4.018], [61454.4, 0.019], [63688.9, 0.027], [64042.0, 2.169], [64145.5, 0.247], [64356.0, 5.15], [64365.5, 5.375], [64683.0, 0.005]], "asks": [[64689.0, 10.455], [65012.5, 0.003], [65335.9, 6.758], [65647.9, 1.216], [65689.0, 10.035]]}
{"kind": "depth", "E": 1787080668595, "U": 11315371597445, "u": 11315371601748, "recv_ms": 1787080668543, "bids": [[14188.9, 1.568], [14288.9, 2.632], [51751.0, 0.0], [51751.1, 0.0], [58220.0, 4.018], [61454.4, 0.018], [61454.5, 2.463], [62101.3, 2.785], [63395.2, 0.071], [63688.9, 0.007], [64042.0, 2.169], [64582.5, 2.383], [64611.2, 0.0], [64630.6, 0.004], [64643.6, 0.441], [64664.4, 0.001], [64665.1, 0.002], [64665.7, 0.718], [64666.1, 1.241], [64666.7, 0.006], [64667.2, 1.308], [64669.5, 0.931], [64670.3, 0.058], [64675.4, 0.001], [64675.7, 0.172], [64678.4, 2.449], [64682.1, 0.102], [64683.0, 0.012], [64683.1, 0.001], [64684.5, 0.268], [64685.1, 0.238], [64685.2, 0.017], [64686.1, 0.0], [64686.4, 0.088], [64686.7, 0.234], [64686.8, 0.085], [64687.6, 0.0], [64687.7, 0.085], [64687.9, 0.049], [64688.0, 0.003], [64688.3, 0.001], [64688.4, 0.0], [64688.9, 4.811]], "asks": [[64689.0, 9.615], [64689.4, 0.0], [64690.0, 0.407], [64690.5, 0.049], [64690.7, 0.017], [64690.9, 0.004], [64691.0, 0.087], [64691.2, 1.186], [64691.3, 0.003], [64691.9, 0.004], [64692.0, 0.007], [64692.7, 0.79], [64693.2, 0.285], [64693.4, 0.112], [64693.8, 0.089], [64694.2, 0.085], [64695.1, 0.058], [64695.2, 0.014], [64695.4, 0.464], [64695.5, 0.047], [64695.7, 0.038], [64696.1, 0.001], [64696.3, 0.188], [64701.9, 0.279], [64703.1, 1.329], [64703.3, 0.32], [64703.6, 0.004], [64705.4, 0.007], [64706.0, 0.561], [64706.9, 0.008], [64707.2, 0.024], [64708.5, 0.885], [64709.6, 0.001], [64710.0, 0.237], [64734.3, 0.306], [64735.6, 0.043], [64766.7, 0.2], [64796.4, 2.32], [64799.0, 0.076], [64848.7, 10.414], [64887.5, 7.102], [65335.9, 6.758], [65689.0, 10.015], [65982.7, 0.017]]}
{"kind": "depth", "E": 1787080668799, "U": 11315371612372, "u": 11315371624619, "recv_ms": 1787080668747, "bids": [[1000.0, 35.81], [14188.9, 2.282], [14288.9, 1.918], [58220.0, 4.018], [61454.4, 0.018], [63688.9, 0.027], [63783.3, 43.878], [64042.0, 2.169], [64666.9, 1.12], [64684.5, 0.018], [64685.3, 0.0], [64685.4, 0.001], [64685.8, 0.02], [64688.9, 4.812]], "asks": [[64690.2, 0.091], [64694.2, 0.001], [64711.3, 0.168], [64818.4, 0.216], [64887.5, 4.345], [65100.0, 56.48], [65335.9, 6.758], [65413.5, 0.012], [65689.0, 10.035]]}
{"kind": "depth", "E": 1787080668901, "U": 11315371624935, "u": 11315371631648, "recv_ms": 1787080668849, "bids": [[14188.9, 2.646], [14288.9, 1.554], [58220.0, 4.018], [62101.3, 3.474], [63783.3, 46.227], [64042.0, 2.169], [64145.5, 0.242], [64675.3, 0.671], [64675.6, 0.0], [64675.7, 0.188], [64681.7, 0.14], [64683.0, 0.012], [64684.5, 0.018], [64684.6, 0.542], [64685.8, 0.001], [64687.3, 0.024], [64688.2, 0.31], [64688.8, 0.066]], "asks": [[64690.9, 0.001], [64691.1, 0.017], [64692.7, 0.697], [64695.5, 0.132], [65323.7, 0.001], [65335.9, 6.758]]}
{"kind": "depth", "E": 1787080669105, "U": 11315371638158, "u": 11315371644975, "recv_ms": 1787080669060, "bids": [[1000.0, 35.81], [14188.9, 3.36], [14288.9, 0.84], [58220.0, 4.018], [61454.4, 0.018], [62101.3, 3.474], [64042.0, 2.169], [64634.5, 0.001], [64637.1, 0.224], [64650.0, 2.838], [64653.1, 0.005], [64660.4, 0.01], [64669.4, 5.01], [64670.9, 1.829], [64675.6, 0.0], [64677.3, 0.002], [64682.4, 0.077], [64683.0, 0.005], [64684.4, 2.006], [64684.6, 0.611], [64684.7, 0.22], [64685.2, 0.017], [64687.2, 0.084], [64687.3, 0.024], [64687.5, 0.022], [64688.9, 4.784]], "asks": [[64689.0, 10.289], [64691.9, 0.545], [64692.0, 0.623], [64692.2, 0.088], [64692.7, 0.156], [64695.5, 0.055], [64696.1, 0.086], [64699.3, 0.377], [64733.0, 0.042], [64735.6, 0.001], [64848.7, 6.717], [64887.5, 8.735], [65012.5, 0.002], [65335.9, 6.758], [65699.7, 3.192]]}
{"kind": "depth", "E": 1787080669207, "U": 11315371645067, "u": 11315371649310, "recv_ms": 1787080669154, "bids": [[14188.9, 3.682], [14288.9, 0.504], [14588.9, 0.014], [58220.0, 4.018], [61454.4, 0.018], [62101.3, 3.477], [63912.6, 50.031], [64042.0, 2.169], [64549.4, 0.0], [64634.5, 0.029], [64637.0, 0.015], [64637.7, 0.011], [64666.9, 1.118], [64669.4, 0.01], [64670.9, 1.025], [64685.2, 0.267], [64688.9, 4.779]], "asks": [[64691.8, 0.006], [64691.9, 0.004], [64692.7, 0.69], [64694.1, 2.632], [64695.4, 0.472], [64695.5, 0.062], [64696.1, 0.078], [64696.3, 0.188], [64829.2, 1.531], [64831.7, 0.0], [65335.9, 6.758], [65982.7, 0.02]]}
{"kind": "depth", "E": 1787080669309, "U": 11315371649370, "u": 11315371654378, "recv_ms": 1787080669259, "bids": [[1000.0, 35.81], [14188.9, 3.738], [14288.9, 0.294], [14588.9, 0.168], [51751.0, 0.0], [58220.0, 4.018], [63688.9, 0.027], [64042.0, 2.169], [64365.4, 0.001], [64365.5, 5.385], [64532.4, 9.933], [64534.1, 2.692], [64549.4, 5.211], [64664.6, 0.102], [64665.4, 0.634], [64685.2, 0.267], [64688.9, 4.779]], "asks": [[64691.9, 0.011], [64692.7, 0.69], [64695.4, 0.001], [64695.5, 0.039], [64696.1, 0.001], [64696.3, 0.752], [64711.1, 1.422], [64831.7, 5.076], [64848.7, 7.41], [64887.5, 7.716], [65335.9, 6.758], [65689.0, 10.035], [65691.7, 20.974]]}
{"kind": "depth", "E": 1787080669513, "U": 11315371659175, "u": 11315371663786, "recv_ms": 1787080669459, "bids": [[14188.9, 3.486], [14288.9, 0.07], [14588.9, 0.644], [51751.0, 0.0], [51751.1, 0.0], [58220.0, 4.018], [62101.3, 3.477], [63688.9, 0.007], [64042.0, 2.169], [64532.4, 6.712], [64549.4, 3.656], [64671.9, 0.25], [64683.0, 0.005], [64685.2, 0.017], [64686.3, 0.0], [64687.4, 0.094], [64688.0, 0.044]], "asks": [[64690.1, 0.001], [64691.1, 0.014], [64691.3, 0.006], [64848.7, 10.414], [64887.5, 10.599], [65335.9, 6.758], [65402.1, 0.094], [65689.0, 10.015]]}
{"kind": "depth", "E": 1787080669615, "U": 11315371663954, "u": 11315371667326, "recv_ms": 1787080669563, "bids": [[1000.0, 35.81], [14188.9, 3.262], [14288.9, 0.0], [14588.9, 0.938], [58220.0, 4.018], [61454.4, 0.018], [61454.5, 2.463], [61454.6, 0.008], [62101.3, 3.474], [64042.0, 2.169], [64365.5, 5.385], [64656.0, 0.871], [64656.1, 0.002], [64656.2, 0.028], [64659.4, 0.005], [64659.5, 0.003], [64659.6, 0.002], [64672.7, 0.737], [64682.4, 0.211], [64683.0, 0.005], [64684.7, 0.086], [64685.2, 0.267], [64688.9, 4.879]], "asks": [[64690.2, 0.007], [64691.8, 0.547], [64691.9, 0.011], [64695.4, 0.001], [64695.5, 0.039], [64696.1, 0.001], [64696.3, 0.752], [64848.7, 7.538], [65335.9, 6.758], [65497.6, 21.987]]}
{"kind": "depth", "E": 1787080669717, "U": 11315371667417, "u": 11315371672198, "recv_ms": 1787080669663, "bids": [[1000.0, 35.81], [14188.9, 2.898], [14588.9, 1.302], [58220.0, 4.018], [61454.4, 0.018], [63395.2, 0.068], [63688.9, 0.027], [63745.8, 0.0], [63770.3, 4.22], [64042.0, 2.169], [64672.5, 0.008], [64682.4, 0.145], [64684.7, 0.154], [64685.2, 0.267]], "asks": [[64689.0, 10.289], [64691.8, 0.006], [64691.9, 0.004], [64692.0, 0.005], [64695.5, 0.124], [64696.1, 0.549], [64696.3, 0.667], [64705.0, 0.047], [64708.8, 7.13], [65335.9, 6.758], [65394.1, 12.454], [65689.0, 10.035]]}
{"kind": "depth", "E": 1787080669819, "U": 11315371672239, "u": 11315371676993, "recv_ms": 1787080669764, "bids": [[14188.9, 2.562], [14588.9, 1.638], [51751.0, 0.0], [58220.0, 4.018], [62101.3, 3.477], [63991.6, 0.004], [64042.0, 2.169], [64621.6, 0.001], [64656.2, 0.003], [64664.4, 0.026], [64682.4, 0.077], [64684.7, 0.086], [64685.2, 0.017]], "asks": [[64818.4, 0.216], [65329.4, 1.71], [65335.9, 6.758], [71157.9, 0.0]]}
{"kind": "depth", "E": 1787080669921, "U": 11315371677202, "u": 11315371681195, "recv_ms": 1787080669867, "bids": [[1000.0, 35.81], [14188.9, 2.184], [14588.9, 2.016], [58220.0, 4.018], [61454.4, 0.018], [61454.5, 2.465], [62101.3, 3.474], [63688.9, 0.007], [63738.0, 10.338], [64042.0, 2.169], [64365.5, 5.385], [64549.4, 3.656], [64630.6, 0.001], [64643.6, 0.444], [64657.9, 0.028], [64664.4, 0.001], [64666.1, 1.241], [64667.0, 1.019], [64682.4, 0.077], [64684.7, 0.086], [64685.2, 0.017], [64688.9, 4.779]], "asks": [[64722.8, 0.028], [64730.2, 0.0], [64734.3, 0.306], [64831.7, 5.106], [65335.9, 6.758], [65486.5, 0.153], [65689.0, 10.015]]}
{"kind": "depth", "E": 1787080670023, "U": 11315371681236, "u": 11315371686779, "recv_ms": 1787080669969, "bids": [[1000.0, 35.81], [14188.9, 1.834], [14588.9, 2.366], [58220.0, 4.018], [61454.4, 0.018], [62101.3, 3.477], [62749.8, 0.004], [63811.9, 1.254], [63983.8, 12.073], [64042.0, 2.169], [64661.8, 0.171], [64681.6, 1.998], [64682.4, 0.077], [64682.8, 0.0], [64684.7, 0.086], [64685.2, 0.017], [64688.9, 4.794]], "asks": [[64691.1, 0.012], [64691.9, 0.002], [64692.2, 0.663], [64692.7, 0.25], [64692.8, 1.002], [64693.2, 0.353], [64693.5, 0.142], [64693.8, 0.087], [64696.1, 0.008], [64701.6, 0.039], [64848.7, 7.558], [65000.0, 117.611], [65335.9, 6.758], [65486.9, 0.034], [65601.1, 8.068]]}
{"kind": "depth", "E": 1787080670125, "U": 11315371686942, "u": 11315371692802, "recv_ms": 1787080670071, "bids": [[14188.9, 1.484], [14588.9, 2.716], [51751.0, 0.0], [58220.0, 4.018], [62101.3, 3.474], [63688.9, 0.027], [64359.5, 0.002], [64365.5, 5.375], [64609.5, 0.049], [64609.9, 0.004], [64620.0, 3.007], [64637.0, 0.014], [64639.9, 0.74], [64640.0, 0.303], [64645.8, 0.001], [64646.4, 0.01], [64646.5, 0.382], [64646.6, 0.081], [64677.3, 0.002], [64682.4, 0.077], [64684.7, 0.211]], "asks": [[64691.0, 0.084], [64692.1, 0.001], [64692.2, 0.088], [64692.6, 0.022], [64692.7, 0.149], [64693.2, 0.285], [64693.4, 0.115], [64693.5, 0.008], [64695.0, 0.207], [64695.4, 0.009], [64695.5, 0.587], [64696.1, 0.078], [64697.4, 0.141], [64697.5, 0.25], [64749.3, 1.807], [64750.3, 0.063], [64848.7, 10.414], [64887.5, 10.595], [65335.9, 6.758], [65689.0, 10.035]]}
{"kind": "depth", "E": 1787080670227, "U": 11315371692877, "u": 11315371698988, "recv_ms": 1787080670174, "bids": [[1000.0, 35.81], [14188.9, 1.12], [14588.9, 3.08], [51751.0, 0.0], [58220.0, 4.018], [61454.4, 0.018], [61454.6, 0.006], [64042.0, 2.169], [64365.4, 0.001], [64527.1, 0.006], [64571.3, 0.581], [64572.5, 3.953], [64582.5, 2.383], [64617.7, 2.381], [64619.0, 0.181], [64630.6, 0.004], [64637.0, 0.013], [64637.7, 0.012], [64650.0, 2.852], [64665.6, 0.625], [64673.0, 1.848], [64684.7, 0.086], [64685.2, 0.017], [64687.5, 0.106], [64688.9, 4.796]], "asks": [[64689.0, 10.286], [64693.2, 0.288], [64696.9, 0.155], [64704.3, 0.744], [64733.0, 0.0], [64760.1, 0.047], [64766.7, 0.203], [64796.4, 2.32], [64824.4, 3.865], [64848.7, 7.558], [65335.9, 6.758], [65982.7, 0.023]]}
{"kind": "depth", "E": 1787080670329, "U": 11315371699113, "u": 11315371707677, "recv_ms": 1787080670275, "bids": [[1000.0, 35.81], [14188.9, 0.756], [14588.9, 3.444], [51751.0, 0.0], [58220.0, 4.018], [61454.4, 0.018], [62101.3, 3.477], [63688.9, 0.007], [63815.6, 18.07], [64042.0, 2.171], [64665.1, 0.559], [64665.4, 0.077], [64666.3, 0.002], [64669.5, 0.005], [64670.2, 0.929], [64671.2, 0.003], [64675.4, 0.542], [64678.7, 0.003], [64684.7, 0.086], [64685.2, 0.017], [64686.5, 0.02], [64687.5, 0.022], [64687.8, 0.31], [64688.0, 0.003], [64688.2, 0.0], [64688.8, 0.066], [64688.9, 4.795]], "asks": [[64689.0, 10.286], [64689.9, 0.313], [64690.1, 0.085], [64692.2, 0.095], [64692.7, 0.69], [64695.4, 0.001], [64695.5, 0.039], [64696.1, 0.001], [64696.3, 0.752], [64705.8, 0.557], [64706.0, 0.005], [64706.8, 0.001], [64707.3, 1.864], [64707.5, 2.612], [64708.5, 0.344], [64709.6, 0.116], [64710.0, 0.122], [64710.6, 0.154], [64719.9, 0.0], [64848.7, 10.414], [65012.5, 0.002], [65335.9, 6.758], [65689.0, 10.015]]}
{"kind": "depth", "E": 1787080670431, "U": 11315371707725, "u": 11315371724842, "recv_ms": 1787080670378, "bids": [[14188.9, 0.448], [14488.9, 0.042], [14588.9, 3.71], [58220.0, 4.018], [61454.4, 0.018], [62101.3, 3.474], [64042.0, 2.169], [64145.5, 0.316], [64365.4, 0.0], [64365.5, 5.385], [64591.9, 0.026], [64625.4, 0.033], [64666.6, 0.162], [64667.0, 0.903], [64675.6, 0.007], [64684.6, 0.604], [64685.2, 0.017], [64686.9, 0.093], [64687.2, 0.0], [64687.4, 0.001], [64687.9, 0.048], [64688.9, 4.795]], "asks": [[64689.0, 10.278], [64692.1, 0.001], [64692.2, 0.088], [64692.7, 0.149], [64695.5, 0.587], [64696.1, 0.549], [64696.3, 0.204], [64848.7, 10.414], [65335.9, 6.758]]}
{"kind": "depth", "E": 1787080670533, "U": 11315371725271, "u": 11315371737410, "recv_ms": 1787080670480, "bids": [[1000.0, 35.81], [14188.9, 0.28], [14488.9, 0.224], [14588.9, 3.696], [51751.1, 0.0], [58220.0, 4.018], [61454.4, 0.018], [61454.5, 2.463], [61454.6, 0.008], [62101.3, 3.477], [63688.9, 0.027], [63880.3, 26.23], [64042.0, 2.169], [64145.5, 0.292], [64664.4, 0.558], [64665.1, 0.002], [64666.0, 3.217], [64666.6, 0.046], [64669.5, 0.931], [64670.2, 0.003], [64675.6, 0.007], [64676.1, 0.0], [64682.7, 0.089], [64683.1, 0.085], [64684.5, 1.837], [64684.6, 0.063], [64685.2, 0.017], [64686.4, 0.004], [64686.8, 0.001], [64687.8, 0.0], [64688.9, 4.795]], "asks": [[64689.0, 10.294], [64689.2, 0.488], [64689.6, 0.112], [64692.2, 0.156], [64692.7, 0.149], [64693.1, 0.122], [64693.4, 0.031], [64693.8, 0.003], [64695.4, 0.008], [64695.5, 0.588], [64696.1, 0.094], [64696.3, 0.651], [64703.3, 0.32], [64848.7, 7.538], [64880.2, 0.566], [65012.5, 0.003], [65335.9, 6.758], [65497.6, 21.759], [65689.0, 10.035], [65982.7, 0.023]]}
{"kind": "depth", "E": 1787080670635, "U": 11315371737668, "u": 11315371744039, "recv_ms": 1787080670583, "bids": [[1000.0, 35.81], [14188.9, 0.154], [14488.9, 0.462], [14588.9, 3.584], [58220.0, 4.018], [61454.6, 0.006], [62101.3, 3.474], [64042.0, 2.169], [64078.0, 13.36], [64675.6, 0.0], [64676.3, 0.001], [64676.6, 0.0], [64681.7, 0.14], [64684.5, 1.844], [64685.2, 0.017], [64687.9, 0.005], [64688.9, 4.813]], "asks": [[64689.0, 10.295], [64692.2, 0.155], [64692.7, 0.183], [64693.1, 0.088], [64693.2, 0.322], [64848.7, 10.414], [65316.5, 1.515], [65335.9, 6.758]]}
{"kind": "depth", "E": 1787080670839, "U": 11315371751052, "u": 11315371757261, "recv_ms": 1787080670786, "bids": [[1000.0, 35.81], [14188.9, 0.0], [14488.9, 1.022], [14588.9, 3.178], [58220.0, 4.018], [62101.3, 3.477], [64042.0, 2.169], [64681.7, 0.14], [64685.2, 0.017], [64688.8, 0.22]], "asks": [[64848.7, 7.464], [65335.9, 6.758], [65538.0, 7.038], [71157.9, 0.0]]}
{"kind": "depth", "E": 1787080671145, "U": 11315371768615, "u": 11315371775222, "recv_ms": 1787080671092, "bids": [[1000.0, 35.81], [14488.9, 2.1], [14588.9, 2.1], [58220.0, 4.018], [61454.4, 0.018], [63395.2, 0.071], [63688.9, 0.007], [63718.5, 0.008], [63797.5, 0.907], [64042.0, 2.169], [64106.7, 12.463], [64609.9, 0.006], [64630.6, 0.004], [64637.7, 0.013], [64640.0, 0.302], [64640.6, 0.004], [64643.6, 0.441], [64646.5, 0.38], [64647.0, 0.214], [64656.0, 0.869], [64656.1, 0.0], [64656.2, 0.001], [64659.4, 0.003], [64659.5, 0.001], [64659.6, 0.0], [64677.3, 0.002], [64681.7, 0.274], [64685.2, 0.267], [64688.9, 4.813]], "asks": [[64689.0, 10.295], [64698.1, 0.012], [64734.3, 0.306], [64766.7, 0.2], [64848.7, 10.414], [65335.9, 6.758], [65602.7, 36.723], [65689.0, 10.015]]}
{"kind": "depth", "E": 1787080671247, "U": 11315371775261, "u": 11315371783406, "recv_ms": 1787080671193, "bids": [[1000.0, 35.81], [14488.9, 2.45], [14588.9, 1.75], [58220.0, 4.018], [61454.5, 2.465], [62101.3, 3.474], [63749.1, 0.0], [63940.2, 0.172], [64042.0, 2.169], [64637.7, 0.014], [64647.0, 0.215], [64653.4, 0.104], [64675.4, 0.001], [64676.1, 0.0], [64676.4, 0.001], [64676.6, 0.0], [64678.4, 2.449], [64681.7, 0.14], [64685.2, 0.267], [64686.1, 0.084], [64688.9, 4.813]], "asks": [[64689.0, 9.455], [64689.2, 0.404], [64694.2, 0.021], [64694.3, 0.026], [64695.1, 0.017], [64704.3, 0.126], [64705.5, 1.351], [64707.2, 0.024], [64708.5, 0.885], [64709.4, 0.003], [64716.8, 0.908], [64848.7, 7.464], [65012.5, 0.002], [65335.9, 6.758]]}
{"kind": "depth", "E": 1787080671349, "U": 11315371783510, "u": 11315371790691, "recv_ms": 1787080671299, "bids": [[14488.9, 2.8], [14588.9, 1.4], [58220.0, 4.018], [61454.4, 0.018], [62101.3, 3.477], [63395.2, 0.065], [63688.9, 0.027], [63815.6, 17.68], [64042.0, 2.169], [64365.4, 0.001], [64365.5, 5.385], [64571.6, 3.865], [64572.5, 0.088], [64572.8, 1.416], [64588.8, 1.011], [64588.9, 0.559], [64617.7, 2.381], [64650.0, 2.838], [64664.4, 0.001], [64665.6, 0.007], [64665.7, 0.718], [64666.1, 1.241], [64667.2, 1.308], [64675.4, 0.542], [64675.6, 0.007], [64676.3, 0.155], [64678.4, 1.908], [64682.1, 0.203], [64682.4, 0.077], [64684.5, 1.837], [64684.6, 0.131], [64685.2, 0.142], [64685.3, 0.0], [64687.0, 0.084], [64688.9, 4.812]], "asks": [[64689.0, 10.201], [64689.6, 0.028], [64692.1, 0.542], [64692.2, 0.095], [64692.7, 0.149], [64695.4, 0.001], [64695.5, 0.039], [64696.1, 0.001], [64696.3, 0.752], [64705.8, 0.557], [64706.8, 0.001], [64733.0, 0.042], [64760.1, 0.047], [64824.4, 3.865], [64848.7, 10.414], [65335.9, 6.758], [65594.6, 54.539], [65689.0, 10.035]]}
{"kind": "depth", "E": 1787080671451, "U": 11315371790716, "u": 11315371803690, "recv_ms": 1787080671397, "bids": [[1000.0, 35.81], [14488.9, 3.164], [14588.9, 1.036], [58220.0, 4.018], [61454.4, 0.018], [62101.3, 3.474], [63395.2, 0.068], [63688.9, 0.007], [63770.3, 4.454], [63789.7, 17.298], [63815.6, 18.07], [64042.0, 2.169], [64532.4, 6.712], [64549.4, 3.656], [64675.6, 0.0], [64676.1, 0.154], [64676.3, 0.001], [64682.1, 0.102], [64684.6, 0.07], [64685.2, 0.017], [64688.9, 4.812]], "asks": [[64689.0, 10.223], [64690.1, 0.001], [64692.1, 0.001], [64692.2, 0.088], [64692.7, 0.697], [64693.2, 0.288], [64693.4, 0.115], [64695.4, 0.001], [64695.5, 0.039], [64696.1, 0.001], [64696.3, 0.752], [64707.4, 1.216], [64708.5, 0.344], [64708.6, 2.907], [64708.8, 7.132], [64848.7, 7.491], [65335.9, 6.76], [65689.0, 10.015]]}
{"kind": "depth", "E": 1787080671553, "U": 11315371803820, "u": 11315371811029, "recv_ms": 1787080671498, "bids": [[1000.0, 35.81], [14488.9, 3.514], [14588.9, 0.686], [51751.1, 0.0], [58220.0, 4.018], [61454.4, 0.018], [62101.3, 3.477], [63746.2, 0.225], [64042.0, 2.169], [64365.4, 0.002], [64624.2, 0.04], [64650.0, 2.852], [64682.1, 0.203], [64684.6, 0.138], [64685.2, 0.267], [64688.9, 4.812]], "asks": [[64689.0, 10.222], [64692.1, 0.001], [64692.2, 0.088], [64692.7, 0.172], [64695.4, 0.549], [64695.5, 0.58], [64696.1, 0.001], [64696.3, 0.188], [64753.7, 0.115], [64879.9, 1.183], [64880.0, 6.562], [65012.5, 0.001], [65335.9, 6.758], [67276.6, 1.921]]}
{"kind": "depth", "E": 1787080671655, "U": 11315371811259, "u": 11315371816905, "recv_ms": 1787080671607, "bids": [[14388.9, 0.07], [14488.9, 3.738], [14588.9, 0.392], [51751.0, 0.0], [58220.0, 4.018], [61454.4, 0.018], [64042.0, 2.169], [64365.5, 5.375], [64493.6, 6.111], [64532.4, 2.113], [64549.4, 1.15], [64623.4, 0.818], [64682.1, 0.17], [64685.2, 0.267], [64688.9, 4.812]], "asks": [[64689.0, 10.329], [64692.1, 0.542], [64692.2, 0.088], [64692.7, 0.156], [64695.4, 0.001], [64695.5, 0.039], [64696.1, 0.017], [64696.3, 0.736], [64752.0, 7.108], [64755.1, 0.002], [64829.2, 2.15], [64831.7, 5.399], [64848.7, 10.414], [65335.9, 6.758], [65473.3, 23.278], [65474.4, 4.58], [65475.0, 3.021]]}
{"kind": "depth", "E": 1787080671757, "U": 11315371817148, "u": 11315371831808, "recv_ms": 1787080671703, "bids": [[1000.0, 35.81], [14388.9, 0.28], [14488.9, 3.668], [14588.9, 0.252], [58220.0, 4.018], [61454.4, 0.018], [62101.3, 3.474], [62739.8, 0.683], [63688.9, 0.027], [64042.0, 2.169], [64493.6, 8.997], [64532.4, 5.431], [64534.1, 2.02], [64549.4, 3.034], [64566.0, 0.085], [64566.2, 0.284], [64619.7, 0.256], [64619.8, 0.173], [64623.5, 2.327], [64645.0, 0.446], [64651.9, 0.681], [64665.1, 0.559], [64665.7, 0.161], [64669.5, 0.005], [64670.3, 0.984], [64671.1, 0.002], [64672.5, 0.008], [64675.4, 0.001], [64675.5, 0.869], [64678.7, 0.003], [64685.2, 0.267], [64688.8, 0.066], [64688.9, 4.812]], "asks": [[64689.0, 10.33], [64690.2, 0.091], [64692.1, 0.001], [64692.2, 0.095], [64692.7, 0.706], [64694.2, 0.001], [64694.3, 0.003], [64695.3, 0.054], [64695.4, 0.001], [64695.5, 0.039], [64696.1, 0.001], [64696.3, 0.736], [64705.0, 0.047], [64705.5, 1.907], [64705.8, 0.001], [64706.8, 0.001], [64707.3, 1.864], [64707.4, 0.675], [64708.5, 0.344], [64716.8, 0.29], [64722.9, 0.074], [64723.2, 0.008], [64733.0, 0.0], [64751.2, 0.024], [64752.0, 7.508], [64753.7, 0.106], [64755.1, 3.485], [64760.2, 0.271], [64760.5, 0.241], [64818.4, 0.216], [64822.3, 0.326], [64822.7, 0.005], [65335.9, 6.758], [65689.0, 10.035]]}
{"kind": "depth", "E": 1787080672063, "U": 11315371844679, "u": 11315371849327, "recv_ms": 1787080672011, "bids": [[1000.0, 35.81], [14388.9, 1.106], [14488.9, 3.094], [14588.9, 0.0], [58220.0, 4.018], [61454.4, 0.018], [62101.3, 3.477], [63136.4, 0.395], [63797.5, 0.0], [64042.0, 2.169], [64145.5, 0.218], [64629.2, 0.005], [64629.5, 0.016], [64629.8, 0.022], [64630.2, 1.852], [64630.5, 0.017], [64647.1, 0.311], [64647.4, 0.007], [64647.7, 0.403], [64648.1, 0.023], [64648.3, 1.7], [64648.4, 0.0], [64662.0, 0.137], [64662.1, 0.032], [64662.2, 0.0], [64662.3, 0.85], [64662.4, 2.363], [64662.5, 0.033], [64662.6, 0.111], [64662.7, 0.001], [64662.8, 0.322], [64663.0, 0.022], [64664.1, 0.135], [64664.6, 0.002], [64677.3, 0.002], [64681.6, 1.928], [64681.7, 0.0], [64681.8, 0.001], [64681.9, 0.005], [64682.0, 0.003], [64682.1, 0.002], [64682.2, 0.016], [64682.3, 0.003], [64682.4, 0.077], [64682.5, 0.002], [64682.6, 0.003], [64682.9, 1.889], [64683.2, 0.002], [64683.5, 0.111], [64683.8, 0.087], [64684.0, 0.033], [64684.2, 0.047], [64684.6, 0.07], [64685.2, 0.142], [64688.9, 4.812]], "asks": [[64694.3, 0.023], [64694.4, 0.035], [64695.3, 0.016], [64695.6, 1.514], [64695.9, 0.001], [64696.2, 0.244], [64696.6, 0.022], [64696.8, 0.309], [64697.0, 0.918], [64697.1, 0.24], [64697.2, 0.088], [64697.3, 0.041], [64697.4, 0.0], [64697.5, 0.053], [64697.6, 0.031], [64697.7, 0.473], [64697.8, 0.002], [64713.2, 1.337], [64713.5, 0.346], [64713.8, 0.004], [64714.1, 0.062], [64714.5, 0.541], [64714.8, 3.539], [64715.3, 0.316], [64716.5, 3.33], [64716.6, 0.005], [64716.7, 0.001], [64716.8, 0.14], [64716.9, 0.182], [64717.0, 0.0], [64717.1, 0.0], [64717.2, 0.041], [64717.3, 1.258], [64717.4, 0.067], [64731.1, 0.004], [64731.4, 0.035], [64731.7, 0.021], [64732.0, 0.023], [64732.4, 0.001], [64848.7, 10.414], [65335.9, 6.758], [65647.9, 0.0]]}
{"kind": "depth", "E": 1787080672165, "U": 11315371849448, "u": 11315371854949, "recv_ms": 1787080672119, "bids": [[1000.0, 35.81], [14388.9, 1.456], [14488.9, 2.744], [58220.0, 4.018], [63688.9, 0.027], [63700.8, 1.718], [63700.9, 0.04], [63880.3, 25.996], [64042.0, 2.169], [64549.4, 3.656], [64637.7, 0.015], [64640.0, 0.301], [64640.6, 0.005], [64646.5, 0.379], [64646.9, 0.375], [64647.0, 0.213], [64648.6, 0.496], [64676.1, 0.154], [64681.7, 0.0], [64681.8, 0.071], [64682.0, 0.073], [64682.7, 0.105], [64684.4, 2.038], [64685.2, 0.017], [64687.4, 0.085], [64688.9, 4.805]], "asks": [[64689.0, 10.329], [64690.2, 0.007], [64695.3, 0.054], [64697.0, 1.078], [64697.6, 0.122], [64697.8, 0.079], [64713.2, 1.375], [64714.8, 3.699], [64717.2, 0.132], [64717.4, 0.144], [64731.1, 0.042], [64831.7, 5.399], [64887.5, 10.654], [65335.9, 6.758], [65497.6, 21.758], [65677.1, 0.078], [65689.0, 10.035]]}
{"kind": "depth", "E": 1787080672267, "U": 11315371855067, "u": 11315371860936, "recv_ms": 1787080672215, "bids": [[14388.9, 1.82], [14488.9, 2.38], [51751.0, 0.0], [58220.0, 4.018], [61454.4, 0.018], [62101.3, 3.474], [63605.8, 2.508], [63789.7, 18.205], [64042.0, 2.17], [64365.5, 5.375], [64549.4, 0.0], [64611.2, 0.003], [64625.4, 0.133], [64647.6, 0.034], [64663.9, 0.619], [64671.2, 0.621], [64681.7, 0.0], [64681.9, 0.075], [64682.2, 0.116], [64682.3, 0.103], [64682.5, 0.102], [64682.6, 0.173], [64682.8, 0.07], [64683.4, 0.435], [64684.6, 0.07], [64685.2, 0.017], [64688.8, 0.221], [64688.9, 4.798]], "asks": [[64695.1, 0.017], [64696.2, 0.289], [64696.8, 0.414], [64697.0, 1.169], [64697.1, 0.37], [64697.2, 0.238], [64697.3, 0.171], [64697.5, 0.173], [64697.7, 0.557], [64702.5, 1.017], [64714.1, 0.107], [64716.5, 3.435], [64716.6, 0.096], [64716.7, 0.131], [64716.8, 0.29], [64717.0, 0.13], [64717.1, 0.12], [64717.3, 1.342], [64732.0, 0.068], [64799.0, 0.079], [64831.7, 0.0], [65335.9, 6.758], [65639.9, 15.511], [65677.0, 0.01], [66629.5, 0.003]]}
{"kind": "depth", "E": 1787080672369, "U": 11315371861073, "u": 11315371866110, "recv_ms": 1787080672317, "bids": [[1000.0, 35.81], [14388.9, 2.184], [14488.9, 2.016], [51751.0, 0.0], [58220.0, 4.018], [61454.4, 0.018], [62101.3, 3.477], [63395.2, 0.074], [63688.9, 0.007], [63880.3, 26.347], [63975.1, 2.947], [64042.0, 2.17], [64365.4, 0.001], [64532.4, 0.212], [64534.1, 1.423], [64630.4, 2.376], [64647.3, 0.036], [64647.9, 0.054], [64681.9, 0.145], [64682.0, 0.143], [64682.2, 0.216], [64682.3, 0.103], [64682.4, 0.177], [64683.1, 0.117], [64683.7, 0.342], [64684.6, 0.07], [64685.2, 0.017], [64687.4, 0.001], [64688.9, 4.798]], "asks": [[64689.0, 10.328], [64690.1, 0.085], [64692.2, 0.088], [64692.7, 0.156], [64695.4, 0.001], [64695.5, 0.039], [64695.9, 0.043], [64696.1, 0.558], [64696.3, 0.736], [64696.6, 0.064], [64697.3, 0.291], [64697.4, 0.14], [64697.6, 0.22], [64697.8, 0.163], [64713.8, 0.046], [64714.5, 0.583], [64715.3, 0.456], [64716.9, 0.302], [64717.2, 0.23], [64717.4, 0.228], [64731.7, 0.063], [64732.4, 0.043], [64829.2, 1.531], [64848.7, 0.005], [65335.9, 6.758], [65689.0, 10.015]]}
{"kind": "depth", "E": 1787080672471, "U": 11315371866196, "u": 11315371870950, "recv_ms": 1787080672419, "bids": [[1000.0, 35.81], [14388.9, 2.52], [14488.9, 1.68], [58220.0, 4.018], [61454.4, 0.018], [62101.3, 3.474], [63602.1, 1.254], [64042.0, 2.17], [64493.6, 8.997], [64532.4, 5.431], [64549.4, 3.034], [64611.2, 0.0], [64630.6, 0.004], [64630.7, 0.072], [64643.6, 0.441], [64662.8, 0.392], [64682.1, 0.072], [64684.6, 0.104], [64685.2, 0.267], [64688.9, 4.798]], "asks": [[64689.0, 10.357], [64692.7, 0.149], [64695.5, 0.594], [64696.3, 0.188], [64697.5, 0.25], [64717.1, 0.197], [64734.3, 0.306], [64766.7, 0.2], [64799.0, 0.076], [64831.7, 5.399], [64848.7, 10.414], [64887.5, 13.027], [65012.5, 0.002], [65335.9, 6.758]]}
{"kind": "depth", "E": 1787080672573, "U": 11315371871122, "u": 11315371875779, "recv_ms": 1787080672528, "bids": [[14388.9, 2.884], [14488.9, 1.316], [51751.1, 0.0], [58220.0, 4.018], [61454.4, 0.024], [63688.9, 0.027], [64042.0, 2.17], [64330.4, 0.0], [64365.4, 0.0], [64365.5, 5.375], [64549.4, 3.656], [64629.7, 0.063], [64662.2, 0.07], [64662.4, 2.433], [64664.8, 0.153], [64671.2, 0.003], [64684.6, 0.104], [64685.2, 0.267], [64688.9, 4.797]], "asks": [[64689.0, 10.357], [64692.7, 0.165], [64695.4, 0.542], [64696.1, 0.001], [64831.7, 5.399], [64887.5, 10.654], [65012.5, 0.003], [65335.9, 6.758], [65594.6, 54.356], [65689.0, 10.035]]}
{"kind": "depth", "E": 1787080672675, "U": 11315371875923, "u": 11315371880707, "recv_ms": 1787080672622, "bids": [[1000.0, 35.81], [14388.9, 3.248], [14488.9, 0.952], [58220.0, 4.018], [61454.4, 0.024], [62101.3, 3.477], [63071.7, 1.912], [63718.6, 10.132], [63987.4, 0.468], [64042.0, 2.17], [64137.1, 0.028], [64171.4, 8.867], [64629.4, 0.244], [64630.1, 0.201], [64656.0, 0.871], [64656.1, 0.002], [64656.2, 0.003], [64659.4, 0.005], [64659.5, 0.003], [64659.6, 0.002], [64662.3, 0.92], [64662.6, 0.211], [64662.7, 0.101], [64662.9, 1.384], [64663.0, 0.092], [64663.2, 0.072], [64663.9, 0.001], [64664.6, 0.559], [64665.1, 0.002], [64675.6, 0.0], [64684.5, 1.844], [64684.6, 0.313], [64685.2, 0.017], [64686.5, 0.104], [64687.0, 0.0], [64688.9, 4.547]], "asks": [[64689.0, 10.357], [64689.7, 0.084], [64692.1, 0.542], [64692.2, 0.095], [64692.7, 0.149], [64695.3, 0.054], [64695.4, 0.001], [64695.5, 0.039], [64696.1, 0.017], [64696.3, 0.736], [64708.9, 0.215], [64709.8, 0.121], [64710.5, 3.21], [64731.0, 0.096], [64731.2, 1.221], [65335.9, 6.758], [65635.0, 3.957], [65982.7, 0.023], [67276.6, 1.908]]}
{"kind": "depth", "E": 1787080672777, "U": 11315371880817, "u": 11315371885506, "recv_ms": 1787080672726, "bids": [[1000.0, 35.81], [14388.9, 3.598], [14488.9, 0.602], [58220.0, 4.018], [62101.3, 3.474], [63688.9, 0.007], [64042.0, 2.17], [64320.2, 0.002], [64662.3, 0.99], [64662.4, 2.503], [64662.8, 0.492], [64664.4, 0.101], [64672.5, 0.008], [64675.6, 0.0], [64681.7, 0.134], [64684.5, 1.844], [64684.6, 0.063], [64685.2, 0.267]], "asks": [[64689.0, 10.441], [64692.1, 0.001], [64692.2, 0.095], [64692.7, 0.165], [64695.4, 0.001], [64695.5, 0.039], [64696.1, 0.542], [64696.3, 0.736], [64705.0, 0.047], [64818.4, 0.216], [65335.9, 6.758], [65594.6, 56.639], [65598.4, 22.988], [65689.0, 10.015]]}
{"kind": "depth", "E": 1787080672879, "U": 11315371885663, "u": 11315371892947, "recv_ms": 1787080672827, "bids": [[14288.9, 0.098], [14388.9, 3.766], [14488.9, 0.336], [58220.0, 4.018], [61454.4, 0.024], [62101.3, 3.477], [63983.8, 12.774], [64042.0, 2.17], [64134.4, 0.079], [64365.5, 5.385], [64549.4, 0.0], [64662.5, 0.103], [64681.7, 0.0], [64685.2, 0.017], [64686.5, 0.02], [64688.9, 4.547]], "asks": [[64689.0, 10.441], [64692.2, 0.088], [64692.7, 0.149], [64693.0, 1.212], [64693.4, 0.031], [64695.5, 0.07], [64696.3, 0.728], [64702.0, 2.9], [64717.9, 0.007], [64718.0, 0.003], [64718.1, 0.005], [64720.9, 0.253], [64721.0, 1.897], [64721.1, 0.504], [64721.7, 0.002], [64721.8, 0.275], [64721.9, 0.016], [64723.9, 0.002], [64724.0, 0.004], [64724.1, 0.003], [64831.7, 0.0], [65335.9, 6.758], [65594.6, 57.172], [65627.0, 40.07], [65982.7, 0.026]]}
{"kind": "depth", "E": 1787080673083, "U": 11315371899546, "u": 11315371905970, "recv_ms": 1787080673033, "bids": [[14288.9, 0.574], [14388.9, 3.528], [14488.9, 0.098], [51751.0, 0.0], [58220.0, 4.018], [58220.1, 0.0], [61454.4, 0.03], [61454.5, 2.463], [61454.6, 0.008], [63700.9, 0.02], [63880.3, 26.113], [63912.6, 49.329], [63913.2, 0.001], [64042.0, 2.17], [64495.8, 2.821], [64532.4, 5.431], [64549.4, 3.033], [64677.3, 0.002], [64684.6, 0.063], [64685.2, 0.267], [64688.4, 0.126], [64688.9, 4.427]], "asks": [[64689.0, 10.371], [64689.7, 0.0], [64693.0, 0.902], [65335.9, 6.758], [65677.1, 0.058], [65982.7, 0.023]]}
{"kind": "depth", "E": 1787080673185, "U": 11315371906061, "u": 11315371921496, "recv_ms": 1787080673132, "bids": [[14288.9, 0.84], [14388.9, 3.36], [14488.9, 0.0], [51751.0, 0.0], [58220.0, 4.018], [61454.4, 0.03], [62101.3, 3.477], [63388.6, 0.005], [63688.9, 0.007], [63700.8, 1.738], [64042.0, 2.17], [64365.5, 5.385], [64602.7, 0.024], [64609.8, 0.004], [64609.9, 0.0], [64637.7, 0.007], [64640.0, 0.3], [64640.5, 0.003], [64640.6, 0.003], [64646.9, 0.377], [64660.3, 0.002], [64675.6, 0.0], [64684.5, 1.837], [64684.6, 0.32], [64685.2, 0.017], [64688.4, 0.127]], "asks": [[64689.0, 10.278], [64695.7, 0.039], [64698.1, 0.011], [65335.9, 6.758], [65689.0, 10.015], [65885.0, 0.103]]}
{"kind": "depth", "E": 1787080673287, "U": 11315371921608, "u": 11315371943856, "recv_ms": 1787080673237, "bids": [[1000.0, 35.81], [14288.9, 1.19], [14388.9, 3.01], [58220.0, 4.018], [62101.3, 3.474], [63749.2, 0.0], [63754.6, 9.302], [63912.6, 50.031], [64042.0, 2.169], [64684.6, 0.07], [64685.2, 0.267], [64688.8, 0.066]], "asks": [[64848.7, 10.414], [65335.9, 6.758], [65677.0, 0.03], [65982.7, 0.026]]}
{"kind": "depth", "E": 1787080673389, "U": 11315371944199, "u": 11315371954143, "recv_ms": 1787080673337, "bids": [[14288.9, 1.554], [14388.9, 2.646], [58220.0, 4.018], [61454.4, 0.036], [61454.5, 2.465], [62101.3, 3.477], [63688.9, 0.027], [64042.0, 2.171], [64493.6, 6.642], [64532.4, 3.372], [64549.4, 1.763], [64623.5, 0.0], [64665.6, 0.625], [64672.9, 0.001], [64685.2, 0.142], [64688.9, 4.431]], "asks": [[64689.0, 10.282], [64689.7, 0.084], [64695.5, 0.61], [64695.7, 0.038], [64696.3, 0.188], [64696.8, 0.414], [64704.2, 1.083], [64752.0, 7.108], [64755.1, 0.002], [65335.9, 6.758], [65689.0, 10.035], [65898.7, 6.178], [65982.7, 0.023], [71157.9, 0.0]]}
{"kind": "depth", "E": 1787080673593, "U": 11315371962009, "u": 11315371969839, "recv_ms": 1787080673540, "bids": [[1000.0, 35.81], [14288.9, 2.268], [14388.9, 1.932], [51751.0, 0.0], [51751.1, 0.0], [58220.0, 4.018], [63688.9, 0.007], [63741.6, 7.908], [64042.0, 2.169], [64365.4, 0.002], [64664.3, 0.06], [64685.2, 0.017]], "asks": [[64689.0, 10.287], [64708.4, 0.375], [64848.7, 10.414], [65012.5, 0.001], [65335.9, 6.758], [65689.0, 10.015], [65982.7, 0.02]]}
{"kind": "depth", "E": 1787080673695, "U": 11315371969917, "u": 11315371983663, "recv_ms": 1787080673645, "bids": [[14288.9, 2.618], [14388.9, 1.582], [51751.0, 0.0], [58220.0, 4.02], [61454.5, 2.467], [61454.6, 0.006], [62101.3, 3.477], [62101.4, 0.004], [63127.4, 1.356], [63395.2, 0.077], [64042.0, 2.169], [64517.0, 0.003], [64534.1, 2.231], [64611.2, 0.003], [64630.6, 0.001], [64643.6, 0.441], [64685.2, 0.017], [64688.8, 0.221]], "asks": [[64689.0, 10.377], [64692.8, 1.312], [64727.1, 0.002], [64734.3, 0.306], [64736.4, 0.075], [64752.0, 7.509], [64766.7, 0.2], [64829.2, 2.15], [64848.7, 7.083], [65335.9, 6.758]]}
{"kind": "depth", "E": 1787080673797, "U": 11315371983971, "u": 11315371991582, "recv_ms": 1787080673745, "bids": [[14288.9, 2.982], [14388.9, 1.218], [51751.0, 0.0], [58220.0, 4.018], [61454.4, 0.036], [62101.3, 3.474], [63688.9, 0.027], [63738.0, 10.886], [64042.0, 2.169], [64078.0, 12.738], [64365.5, 5.385], [64672.5, 0.006], [64685.2, 0.017], [64686.8, 0.001], [64687.8, 0.0]], "asks": [[64692.2, 0.636], [64692.7, 0.149], [64695.4, 0.001], [64695.5, 0.039], [64696.1, 0.001], [64696.3, 0.752], [64705.0, 0.045], [64762.3, 0.662], [64762.4, 0.011], [64818.4, 0.216], [64848.7, 10.414], [65335.9, 6.758], [65689.0, 10.035]]}
{"kind": "depth", "E": 1787080674103, "U": 11315372004519, "u": 11315372011520, "recv_ms": 1787080674052, "bids": [[14188.9, 0.154], [14288.9, 3.738], [14388.9, 0.308], [58220.0, 4.018], [62101.3, 3.474], [63700.9, 0.01], [64042.0, 2.169], [64074.4, 16.455], [64365.5, 5.375], [64640.2, 0.08], [64677.3, 0.002], [64685.2, 0.017]], "asks": [[64689.0, 10.377], [64690.4, 0.0], [64692.0, 0.005], [64695.5, 0.587], [64848.7, 7.138], [65206.5, 9.335], [65335.9, 6.758], [65677.1, 0.048]]}
{"kind": "depth", "E": 1787080674205, "U": 11315372011698, "u": 11315372018267, "recv_ms": 1787080674167, "bids": [[1000.0, 35.81], [14188.9, 0.392], [14288.9, 3.612], [14388.9, 0.196], [58220.0, 4.018], [62101.3, 3.477], [63688.9, 0.027], [63700.8, 1.748], [63880.3, 25.996], [64042.0, 2.169], [64084.5, 0.0], [64549.4, 3.656], [64602.7, 0.026], [64609.9, 0.003], [64637.7, 0.009], [64640.6, 0.005], [64646.9, 0.379], [64685.2, 0.267], [64686.6, 0.085], [64687.9, 0.028]], "asks": [[64695.2, 0.015], [64831.7, 5.399], [64848.7, 10.414], [65335.9, 6.758], [65689.0, 10.035]]}
{"kind": "depth", "E": 1787080674307, "U": 11315372018370, "u": 11315372024267, "recv_ms": 1787080674255, "bids": [[14188.9, 0.63], [14288.9, 3.5], [14388.9, 0.07], [51751.0, 0.0], [58220.0, 4.018], [62101.3, 3.474], [63688.9, 0.007], [64042.0, 2.169], [64637.7, 0.01], [64685.2, 0.267], [64686.6, 0.001]], "asks": [[64689.2, 0.488], [65206.5, 9.64], [65335.9, 6.758], [65594.6, 57.355], [65677.0, 0.04], [65689.0, 10.015]]}
{"kind": "depth", "E": 1787080674409, "U": 11315372024440, "u": 11315372049221, "recv_ms": 1787080674357, "bids": [[1000.0, 35.81], [14188.9, 0.91], [14288.9, 3.29], [14388.9, 0.0], [58220.0, 4.018], [61454.4, 0.042], [62101.3, 3.477], [63758.7, 5.327], [64042.0, 2.169], [64080.8, 0.687], [64365.4, 0.001], [64365.5, 5.385], [64643.6, 0.444], [64656.0, 0.869], [64656.1, 0.0], [64656.2, 0.001], [64657.0, 0.016], [64657.5, 0.073], [64659.4, 0.003], [64659.5, 0.001], [64659.6, 0.0], [64661.6, 0.62], [64665.4, 0.007], [64665.6, 0.007], [64667.1, 0.061], [64669.0, 0.619], [64672.7, 0.272], [64674.9, 1.634], [64675.1, 1.912], [64682.7, 0.189], [64683.4, 0.125], [64684.6, 0.07], [64685.2, 0.142], [64686.1, 0.232], [64686.3, 0.022], [64686.7, 0.002], [64687.3, 0.001], [64687.5, 0.002], [64687.9, 0.005], [64688.9, 4.205]], "asks": [[64692.7, 0.783], [64692.9, 0.618], [64695.2, 0.014], [64695.3, 0.054], [64695.4, 0.001], [64695.5, 0.046], [64696.1, 0.001], [64696.3, 0.659], [64707.4, 5.708], [64707.5, 10.017], [64708.4, 0.446], [64711.3, 0.238], [64714.6, 0.0], [64719.0, 0.007], [64751.2, 0.006], [64766.7, 0.203], [65335.9, 6.76]]}
{"kind": "depth", "E": 1787080674511, "U": 11315372049237, "u": 11315372071395, "recv_ms": 1787080674459, "bids": [[1000.0, 35.81], [14188.9, 1.274], [14288.9, 2.926], [32344.4, 0.0], [58220.0, 4.018], [61454.4, 0.042], [63395.2, 0.08], [64042.0, 2.169], [64625.4, 0.033], [64651.6, 0.439], [64661.6, 0.002], [64669.0, 0.001], [64675.0, 3.237], [64675.6, 0.548], [64675.7, 0.312], [64682.3, 0.187], [64684.5, 1.28], [64684.6, 0.063], [64685.1, 0.467], [64685.2, 0.017], [64685.3, 0.016], [64685.7, 0.002], [64686.1, 0.0], [64686.4, 0.116], [64686.9, 0.0], [64688.9, 4.104]], "asks": [[64689.0, 11.678], [64690.7, 0.568], [64690.9, 0.003], [64691.3, 0.003], [64691.5, 0.016], [64692.2, 0.088], [64692.7, 0.149], [64692.9, 0.0], [64695.5, 0.039], [64696.1, 0.094], [64707.4, 0.724], [64709.1, 0.003], [64726.7, 4.021], [64726.8, 0.0], [64755.9, 2.049], [64756.9, 37.861], [64763.5, 0.0], [64848.7, 7.007], [65012.5, 0.002], [65335.9, 6.758], [66600.0, 24.736]]}
{"kind": "depth", "E": 1787080674613, "U": 11315372071636, "u": 11315372080735, "recv_ms": 1787080674560, "bids": [[14188.9, 1.624], [14288.9, 2.576], [51751.0, 0.0], [51751.1, 0.0], [58220.0, 4.018], [62101.3, 3.474], [63688.9, 0.027], [63744.4, 1.738], [63750.9, 37.448], [64042.0, 2.169], [64365.4, 0.0], [64663.6, 0.444], [64669.9, 0.258], [64675.6, 0.541], [64675.8, 0.007], [64683.0, 0.012], [64684.6, 0.079], [64685.2, 0.267], [64685.3, 0.0]], "asks": [[64689.0, 11.709], [64692.0, 0.905], [64693.7, 0.347], [65335.9, 6.758], [65689.0, 10.035]]}
{"kind": "depth", "E": 1787080674715, "U": 11315372080968, "u": 11315372086371, "recv_ms": 1787080674663, "bids": [[1000.0, 35.81], [14188.9, 1.974], [14288.9, 2.226], [58220.0, 4.018], [62101.3, 3.477], [63880.3, 26.229], [64042.0, 2.169], [64365.5, 5.385], [64532.4, 0.212], [64534.1, 1.423], [64549.4, 0.0], [64658.1, 0.164], [64664.0, 1.47], [64675.8, 0.007], [64683.0, 0.012], [64684.6, 0.079], [64685.2, 0.267], [64685.3, 0.0], [64688.8, 0.066]], "asks": [[64755.9, 7.277], [64831.7, 0.0], [64848.7, 0.005], [65012.5, 0.003], [65335.9, 6.758]]}
{"kind": "depth", "E": 1787080674817, "U": 11315372086488, "u": 11315372091802, "recv_ms": 1787080674763, "bids": [[1000.0, 35.81], [14188.9, 2.338], [14288.9, 1.862], [58220.0, 4.018], [61454.5, 2.465], [61454.6, 0.008], [62101.3, 3.474], [63688.9, 0.007], [63903.5, 2.344], [64042.0, 2.169], [64532.4, 6.608], [64534.1, 2.195], [64549.4, 3.61], [64672.5, 0.006], [64675.8, 0.007], [64676.1, 0.154], [64683.0, 0.012], [64684.6, 0.079], [64685.2, 0.017], [64685.3, 0.0]], "asks": [[64705.0, 0.045], [64818.4, 0.216], [64831.7, 4.777], [64848.7, 7.007], [65248.4, 0.003], [65335.9, 6.758], [65689.0, 10.015]]}
{"kind": "depth", "E": 1787080674919, "U": 11315372091925, "u": 11315372100329, "recv_ms": 1787080674867, "bids": [[14188.9, 2.702], [14288.9, 1.498], [58220.0, 4.018], [61454.4, 0.048], [63362.8, 2.998], [63750.9, 37.605], [64042.0, 2.169], [64171.4, 5.912], [64672.5, 0.008], [64675.8, 0.014], [64683.0, 0.005], [64684.6, 0.063], [64685.2, 0.017], [64685.3, 0.016], [64686.3, 0.0], [64686.4, 0.116], [64688.9, 4.1]], "asks": [[64689.0, 11.724], [64690.4, 0.002], [64705.0, 0.047], [64705.2, 0.023], [64708.5, 0.329], [64848.7, 10.414], [65335.9, 6.758]]}
{"kind": "depth", "E": 1787080675021, "U": 11315372101223, "u": 11315372110767, "recv_ms": 1787080674968, "bids": [[1000.0, 35.81], [14188.9, 3.052], [14288.9, 1.148], [58220.0, 4.018], [61454.4, 0.048], [62101.3, 3.477], [63688.9, 0.027], [64042.0, 2.169], [64365.5, 5.375], [64532.4, 6.608], [64549.4, 3.61], [64611.2, 0.0], [64630.2, 1.667], [64630.6, 0.004], [64643.6, 0.441], [64672.7, 0.435], [64675.6, 0.541], [64675.8, 0.007], [64681.7, 0.0], [64683.0, 0.012], [64684.6, 0.079], [64685.1, 0.235], [64685.3, 0.0], [64685.7, 0.234], [64688.7, 0.024], [64688.8, 0.06], [64688.9, 4.071]], "asks": [[64692.0, 0.005], [64695.5, 0.047], [64696.3, 0.651], [64711.3, 0.168], [64717.8, 0.072], [64734.3, 0.306], [64766.7, 0.2], [64829.2, 2.15], [64831.7, 5.399], [64887.5, 10.842], [65335.9, 6.758], [65689.0, 10.035]]}
{"kind": "depth", "E": 1787080675123, "U": 11315372110909, "u": 11315372118422, "recv_ms": 1787080675069, "bids": [[1000.0, 35.81], [14188.9, 3.416], [14288.9, 0.784], [58220.0, 4.018], [61454.4, 0.048], [62101.3, 3.474], [63653.9, 4.831], [63700.9, 0.002], [63765.6, 0.022], [63767.4, 0.003], [63874.0, 0.782], [64042.0, 2.169], [64171.4, 9.801], [64549.4, 0.0], [64609.9, 0.004], [64640.6, 0.007], [64643.6, 0.626], [64675.6, 0.541], [64677.3, 0.002], [64681.6, 2.178], [64683.0, 0.012], [64683.1, 0.117], [64683.2, 0.002], [64688.5, 0.029], [64688.9, 4.168]], "asks": [[64698.0, 0.125], [64829.2, 1.531], [64831.7, 0.0], [65243.9, 0.381], [65335.9, 6.758], [65610.6, 0.635], [65612.4, 0.015], [65627.0, 39.005], [65677.1, 0.04], [65982.7, 0.02]]}
{"kind": "depth", "E": 1787080675225, "U": 11315372118518, "u": 11315372123754, "recv_ms": 1787080675172, "bids": [[14188.9, 3.71], [14288.9, 0.462], [14588.9, 0.028], [51751.0, 0.002], [58220.0, 4.018], [62101.3, 3.477], [63688.9, 0.007], [63700.8, 1.756], [63765.5, 0.01], [63767.3, 0.008], [64042.0, 2.169], [64145.5, 0.218], [64532.4, 0.212], [64534.1, 1.423], [64637.7, 0.012], [64647.0, 0.214], [64675.6, 0.548], [64681.6, 1.928], [64683.0, 0.005], [64683.1, 0.117], [64685.6, 0.131], [64688.8, 0.215]], "asks": [[64689.0, 11.725], [64848.7, 0.005], [65335.9, 6.758], [65602.7, 34.439], [65610.5, 0.04], [65689.0, 10.015], [71157.9, 0.0]]}
{"kind": "depth", "E": 1787080675327, "U": 11315372123771, "u": 11315372131870, "recv_ms": 1787080675310, "bids": [[1000.0, 35.81], [14188.9, 3.71], [14288.9, 0.28], [14588.9, 0.21], [51751.0, 0.0], [58220.0, 4.018], [61454.4, 0.048], [62101.3, 3.474], [63653.9, 5.929], [64042.0, 2.169], [64365.5, 5.385], [64493.6, 9.485], [64532.4, 6.608], [64549.4, 3.61], [64672.6, 3.188], [64675.6, 0.541], [64675.8, 0.014], [64681.6, 1.928], [64683.0, 0.005], [64683.4, 0.435], [64684.6, 0.079], [64686.2, 0.086], [64688.9, 4.395]], "asks": [[64689.0, 10.43], [64689.2, 0.404], [64690.7, 0.568], [64690.9, 0.001], [64691.3, 0.005], [64692.7, 0.242], [64695.4, 0.001], [64695.5, 0.039], [64696.1, 0.001], [64696.3, 0.659], [64704.2, 0.465], [64831.7, 5.399], [64848.7, 10.414], [64887.5, 10.842], [65335.9, 6.758], [65497.6, 21.075], [65612.3, 0.016], [65627.0, 40.07], [65677.0, 0.048], [65788.0, 6.749]]}
{"kind": "depth", "E": 1787080675429, "U": 11315372132110, "u": 11315372138061, "recv_ms": 1787080675377, "bids": [[1000.0, 35.81], [14188.9, 3.598], [14288.9, 0.154], [14588.9, 0.448], [51751.0, 0.0], [58220.0, 4.018], [61454.4, 0.048], [63688.9, 0.027], [63847.9, 20.642], [64042.0, 2.169], [64065.1, 1.034], [64665.7, 0.161], [64673.1, 0.005], [64675.5, 0.331], [64675.6, 1.082], [64675.8, 0.014], [64678.4, 1.908], [64681.6, 1.928], [64681.7, 0.0], [64682.3, 0.237], [64683.0, 0.005], [64684.6, 0.147], [64685.2, 0.017], [64686.2, 0.108], [64686.3, 0.019], [64686.7, 0.086], [64688.9, 4.395]], "asks": [[64689.0, 10.448], [64690.7, 0.02], [64692.2, 0.095], [64692.7, 0.783], [64695.4, 0.001], [64695.5, 0.039], [64696.1, 0.001], [64696.3, 0.659], [64697.0, 1.169], [64704.4, 1.471], [64707.2, 0.565], [64707.3, 1.323], [64707.5, 0.017], [64708.4, 0.375], [64708.5, 0.329], [64710.3, 10.15], [64751.2, 0.024], [65335.9, 6.758], [65497.6, 20.847], [65689.0, 10.035]]}
{"kind": "depth", "E": 1787080675531, "U": 11315372138091, "u": 11315372143708, "recv_ms": 1787080675478, "bids": [[14188.9, 3.472], [14288.9, 0.042], [14588.9, 0.686], [58220.0, 4.018], [61454.4, 0.048], [62101.3, 3.477], [64042.0, 2.169], [64365.5, 5.375], [64675.4, 0.542], [64675.6, 0.541], [64675.8, 0.014], [64678.4, 1.908], [64681.7, 0.0], [64682.3, 0.103], [64683.0, 0.005], [64684.6, 0.079], [64685.8, 0.001]], "asks": [[64689.0, 10.418], [64690.7, 0.017], [64691.0, 0.087], [64691.1, 0.012], [64692.1, 0.001], [64692.2, 0.222], [64692.7, 0.242], [64692.9, 0.0], [64693.1, 0.088], [64693.2, 0.288], [64693.7, 0.377], [64695.4, 0.464], [64695.5, 0.595], [64696.1, 0.001], [64696.3, 0.188], [64707.2, 0.024], [64707.4, 0.675], [64708.5, 0.87], [64713.9, 0.053], [64848.7, 7.007], [65012.5, 0.002], [65326.7, 2.026], [65335.9, 6.758], [65501.4, 2.401], [65594.6, 59.639], [65801.7, 1.818]]}
{"kind": "depth", "E": 1787080675633, "U": 11315372143784, "u": 11315372148547, "recv_ms": 1787080675584, "bids": [[1000.0, 35.81], [14188.9, 3.206], [14288.9, 0.0], [14588.9, 0.994], [51751.1, 0.0], [58220.0, 4.018], [62101.3, 3.474], [63688.9, 0.007], [63750.9, 36.508], [64042.0, 2.169], [64651.6, 0.103], [64655.4, 0.356], [64684.6, 0.079]], "asks": [[64689.0, 10.419], [64692.0, 0.005], [64692.1, 0.001], [64692.2, 0.088], [64692.7, 0.242], [64695.4, 0.464], [64695.5, 0.595], [64696.1, 0.001], [64696.3, 0.188], [64848.7, 10.414], [65323.0, 1.717], [65335.9, 6.758], [65497.6, 21.075], [65689.0, 10.015]]}
{"kind": "depth", "E": 1787080675837, "U": 11315372154315, "u": 11315372162000, "recv_ms": 1787080675785, "bids": [[14188.9, 2.492], [14588.9, 1.708], [32344.5, 0.0], [51751.0, 0.0], [58220.0, 4.018], [62101.3, 3.474], [63395.2, 0.083], [63688.9, 0.027], [63750.9, 37.605], [63880.3, 25.878], [64042.0, 2.169], [64365.5, 5.385], [64684.6, 0.079]], "asks": [[64818.4, 0.216], [64848.7, 7.083], [65335.9, 6.758], [65594.6, 59.183], [65689.0, 10.035]]}
{"kind": "depth", "E": 1787080675939, "U": 11315372162165, "u": 11315372167667, "recv_ms": 1787080675888, "bids": [[1000.0, 35.81], [14188.9, 2.128], [14588.9, 2.072], [58220.0, 4.018], [61454.4, 0.054], [63880.3, 26.229], [64042.0, 2.169], [64672.5, 0.008], [64676.1, 0.0], [64684.6, 0.079]], "asks": [[64690.6, 0.187], [64692.2, 0.189], [64692.7, 0.149], [64693.1, 0.156], [64705.0, 0.047], [64848.7, 10.414], [65335.9, 6.758], [65465.3, 49.385], [65602.7, 32.155]]}
{"kind": "depth", "E": 1787080676041, "U": 11315372167764, "u": 11315372172019, "recv_ms": 1787080675990, "bids": [[1000.0, 35.81], [14188.9, 1.778], [14588.9, 2.422], [58220.0, 4.018], [61454.4, 0.054], [62101.3, 3.477], [63589.2, 18.815], [63688.9, 0.007], [64042.0, 2.169], [64549.4, 3.01], [64569.5, 3.865], [64571.6, 0.0], [64572.8, 0.963], [64582.5, 2.383], [64617.7, 2.381], [64653.5, 0.338], [64655.4, 0.02], [64676.1, 0.154], [64677.3, 0.007], [64681.7, 0.068], [64684.6, 0.329], [64685.7, 0.002], [64686.1, 0.232], [64688.9, 4.169]], "asks": [[64689.0, 10.455], [64690.6, 0.086], [64692.2, 0.088], [64693.1, 0.088], [64693.7, 0.347], [64707.3, 1.864], [64708.5, 3.444], [64760.1, 0.047], [64796.4, 2.32], [64824.4, 3.865], [64831.7, 5.399], [65335.9, 6.758], [65423.4, 0.0], [65465.3, 48.7], [65594.6, 59.639], [65689.0, 10.015]]}
{"kind": "depth", "E": 1787080676143, "U": 11315372172068, "u": 11315372177619, "recv_ms": 1787080676091, "bids": [[14188.9, 1.414], [14588.9, 2.786], [51751.0, 0.0], [58220.0, 4.018], [61454.5, 2.467], [62101.3, 3.474], [63395.2, 0.08], [63688.9, 0.027], [64042.0, 2.171], [64365.5, 5.23], [64549.4, 0.0], [64582.5, 2.383], [64640.7, 0.163], [64647.0, 0.215], [64677.3, 0.002], [64681.7, 0.0], [64682.3, 0.353], [64684.6, 0.079], [64688.8, 0.06], [64688.9, 4.167]], "asks": [[64690.6, 0.086], [64692.2, 0.088], [64692.7, 0.149], [64693.1, 0.088], [64696.1, 0.095], [64698.0, 0.124], [64708.4, 0.446], [64717.9, 0.005], [64718.0, 0.001], [64718.1, 0.003], [64720.9, 0.251], [64721.0, 1.895], [64721.1, 0.502], [64721.7, 0.0], [64723.9, 0.0], [64724.0, 0.002], [64724.1, 0.001], [64796.4, 2.32], [64831.7, 0.0], [65012.4, 2.307], [65335.9, 6.758], [65689.0, 10.035]]}
{"kind": "depth", "E": 1787080676245, "U": 11315372177630, "u": 11315372183286, "recv_ms": 1787080676194, "bids": [[1000.0, 35.81], [14188.9, 1.064], [14588.9, 3.136], [51751.0, 0.0], [58220.0, 4.018], [61454.4, 0.054], [61454.6, 0.006], [62101.3, 3.477], [64042.0, 2.169], [64365.5, 2.903], [64549.4, 0.0], [64630.6, 0.001], [64637.8, 0.002], [64643.6, 0.629], [64675.8, 0.007], [64683.0, 0.012], [64688.9, 4.167]], "asks": [[64696.1, 0.094], [64721.8, 0.273], [64721.9, 0.014], [64734.3, 0.306], [64831.7, 0.0], [64887.5, 11.069], [65011.4, 0.465], [65335.9, 6.758], [65465.3, 49.92]]}
{"kind": "depth", "E": 1787080676347, "U": 11315372183351, "u": 11315372188479, "recv_ms": 1787080676294, "bids": [[1000.0, 35.81], [14188.9, 0.7], [14588.9, 3.5], [51751.0, 0.0], [58220.0, 4.018], [61454.4, 0.054], [63744.4, 2.13], [64042.0, 2.169], [64365.5, 3.058], [64549.4, 3.554], [64675.0, 3.239], [64675.8, 0.014], [64682.3, 0.103], [64683.0, 0.005], [64685.2, 0.142], [64686.0, 0.085]], "asks": [[64689.0, 10.423], [64775.6, 0.026], [64831.7, 4.581], [64848.7, 10.414], [65012.4, 2.461], [65335.9, 6.758], [65465.3, 49.843], [65548.7, 0.0]]}
{"kind": "depth", "E": 1787080676449, "U": 11315372188602, "u": 11315372193628, "recv_ms": 1787080676395, "bids": [[14188.9, 0.406], [14488.9, 0.056], [14588.9, 3.738], [58220.0, 4.018], [61454.5, 2.465], [61454.6, 0.008], [62101.3, 3.474], [63395.2, 0.077], [63688.9, 0.007], [64042.0, 2.169], [64365.5, 5.385], [64675.6, 0.0], [64675.8, 0.007], [64684.6, 0.627], [64685.2, 0.017]], "asks": [[64689.8, 0.132], [64689.9, 0.324], [64690.0, 1.307], [64690.7, 0.001], [64691.1, 0.012], [64692.2, 0.629], [64692.7, 0.149], [64692.9, 0.0], [64693.1, 0.088], [64693.2, 0.288], [64695.3, 0.131], [64695.4, 0.464], [64695.5, 0.046], [64696.1, 0.017], [64696.3, 0.196], [65011.4, 0.903], [65012.4, 4.765], [65335.9, 6.605], [65458.8, 8.241], [65465.3, 45.267], [65562.3, 16.601], [65689.0, 10.015], [65982.7, 0.023]]}
{"kind": "depth", "E": 1787080676653, "U": 11315372199130, "u": 11315372205415, "recv_ms": 1787080676600, "bids": [[1000.0, 35.81], [14188.9, 0.126], [14488.9, 0.504], [14588.9, 3.57], [51751.1, 0.0], [58220.0, 4.018], [61454.4, 0.06], [61454.5, 2.463], [61454.6, 0.01], [62101.3, 3.474], [63688.9, 0.027], [63802.4, 3.679], [64042.0, 2.169], [64171.4, 9.491], [64365.4, 0.0], [64620.7, 6.93], [64624.2, 0.039], [64685.2, 0.267], [64688.8, 0.215]], "asks": [[64689.0, 10.315], [64689.8, 0.132], [64690.7, 0.001], [64696.9, 0.155], [64753.7, 0.105], [64770.6, 0.475], [64887.5, 10.842], [65335.9, 6.605], [65465.3, 50.605], [65689.0, 10.035]]}
{"kind": "depth", "E": 1787080676857, "U": 11315372209590, "u": 11315372214598, "recv_ms": 1787080676804, "bids": [[1000.0, 35.81], [14188.9, 0.0], [14488.9, 1.078], [14588.9, 3.122], [58220.0, 4.018], [61454.4, 0.06], [61454.5, 2.459], [61454.6, 0.014], [63688.9, 0.007], [63880.3, 25.995], [64042.0, 2.169], [64532.4, 5.38], [64549.4, 3.01], [64650.0, 2.838], [64685.2, 0.267], [64688.9, 4.167]], "asks": [[64707.3, 1.862], [64707.9, 0.008], [64829.2, 2.15], [64831.7, 5.399], [65335.9, 6.758], [65689.0, 10.015], [65982.7, 0.026]]}
{"kind": "depth", "E": 1787080677163, "U": 11315372227290, "u": 11315372233813, "recv_ms": 1787080677111, "bids": [[1000.0, 35.81], [14488.9, 2.156], [14588.9, 2.044], [51751.0, 0.0], [58220.0, 4.018], [62101.3, 3.474], [64042.0, 2.171], [64532.4, 3.761], [64549.4, 1.844], [64602.7, 0.024], [64637.7, 0.013], [64637.8, 0.001], [64640.6, 0.008], [64640.7, 0.162], [64646.9, 0.38], [64647.0, 0.213], [64672.7, 0.435], [64682.3, 0.103], [64684.7, 0.086], [64685.2, 0.142], [64688.9, 4.167]], "asks": [[64692.1, 0.001], [64692.2, 0.088], [64692.7, 0.149], [64695.4, 0.001], [64695.5, 0.054], [64696.1, 0.558], [64696.3, 0.728], [64697.6, 0.221], [64848.7, 7.007], [65335.9, 6.758], [65485.1, 0.0], [65497.6, 21.911]]}
{"kind": "depth", "E": 1787080677469, "U": 11315372252602, "u": 11315372260627, "recv_ms": 1787080677416, "bids": [[1000.0, 35.81], [14488.9, 3.234], [14588.9, 0.966], [58220.0, 4.018], [62101.3, 3.474], [63395.2, 0.071], [63579.9, 0.0], [64042.0, 2.169], [64685.2, 0.017]], "asks": [[64690.1, 0.09], [64848.7, 7.007], [65335.9, 6.759], [65982.7, 0.02]]}
{"kind": "depth", "E": 1787080677571, "U": 11315372260706, "u": 11315372268307, "recv_ms": 1787080677518, "bids": [[1000.0, 35.81], [14488.9, 3.584], [14588.9, 0.616], [58220.0, 4.018], [61454.4, 0.072], [62101.3, 3.477], [63425.1, 0.0], [63688.9, 0.027], [63880.3, 26.346], [64042.0, 2.169], [64532.4, 4.736], [64549.4, 2.428], [64623.5, 0.0], [64630.6, 0.001], [64643.6, 0.629], [64665.7, 0.161], [64672.7, 0.435], [64673.0, 1.848], [64685.2, 0.267], [64688.8, 0.06], [64688.9, 4.167]], "asks": [[64689.0, 11.077], [64696.9, 0.155], [64704.3, 0.126], [64734.3, 0.306], [64755.1, 0.002], [64766.7, 0.2], [64831.7, 4.777], [65335.9, 6.759], [65465.3, 52.131], [65689.0, 10.035]]}
{"kind": "depth", "E": 1787080677673, "U": 11315372268471, "u": 11315372275783, "recv_ms": 1787080677628, "bids": [[14388.9, 0.084], [14488.9, 3.78], [14588.9, 0.336], [51751.0, 0.0], [51751.1, 0.0], [58220.0, 4.018], [62101.3, 3.474], [63576.3, 2.511], [63802.4, 3.054], [64042.0, 2.169], [64078.0, 12.272], [64171.4, 9.805], [64365.5, 5.385], [64532.4, 6.671], [64549.4, 3.638], [64623.5, 2.354], [64671.9, 0.074], [64685.2, 0.267]], "asks": [[64752.0, 7.108], [64755.1, 3.519], [64831.7, 5.399], [64848.7, 7.007], [65335.9, 6.759], [65486.4, 0.0]]}
{"kind": "depth", "E": 1787080677775, "U": 11315372275851, "u": 11315372282363, "recv_ms": 1787080677722, "bids": [[1000.0, 35.81], [14388.9, 0.322], [14488.9, 3.654], [14588.9, 0.224], [58220.0, 4.018], [61454.4, 0.072], [63780.4, 2.224], [64042.0, 2.169], [64171.4, 9.801], [64532.4, 6.671], [64549.4, 3.638], [64617.5, 0.0], [64617.6, 2.764], [64640.1, 0.005], [64656.3, 0.034], [64685.2, 0.267], [64688.9, 4.167]], "asks": [[64713.2, 0.395], [64726.6, 1.731], [64729.4, 2.761], [64752.0, 1.108], [64818.4, 0.216], [64848.7, 10.414], [64887.5, 10.727], [65012.5, 0.001], [65335.9, 6.759], [65594.6, 61.923]]}
{"kind": "depth", "E": 1787080677979, "U": 11315372286959, "u": 11315372292578, "recv_ms": 1787080677926, "bids": [[14388.9, 0.812], [14488.9, 3.388], [14588.9, 0.0], [58220.0, 4.018], [62101.3, 3.474], [64042.0, 2.169], [64078.0, 11.572], [64365.5, 5.385], [64493.6, 8.971], [64532.4, 5.379], [64549.4, 3.01], [64578.4, 1.757], [64585.3, 1.271], [64617.3, 6.025], [64630.6, 0.004], [64639.9, 4.24], [64656.1, 1.002], [64672.5, 0.008], [64685.2, 0.267], [64686.5, 0.104], [64686.9, 0.019]], "asks": [[64694.3, 0.003], [64694.4, 0.054], [64705.0, 0.047], [64713.2, 1.399], [64714.9, 2.324], [64729.3, 4.13], [64752.0, 7.108], [64766.7, 0.203], [64831.7, 5.399], [64848.7, 10.414], [64887.5, 10.138], [65335.9, 6.759], [65602.7, 31.972]]}
{"kind": "depth", "E": 1787080678081, "U": 11315372292709, "u": 11315372297605, "recv_ms": 1787080678029, "bids": [[1000.0, 35.81], [14388.9, 1.162], [14488.9, 3.038], [58220.0, 4.018], [61454.4, 0.072], [61454.6, 0.012], [62101.3, 3.477], [63688.9, 0.027], [64042.0, 2.169], [64585.2, 10.002], [64602.6, 0.002], [64640.6, 0.009], [64664.6, 0.559], [64665.4, 0.007], [64666.1, 1.357], [64666.2, 2.558], [64667.7, 0.009], [64677.3, 0.002], [64685.2, 0.017], [64686.7, 0.024], [64688.8, 0.218]], "asks": [[64689.0, 11.062], [64689.3, 0.0], [64694.4, 0.032], [64704.8, 0.006], [64705.5, 1.351], [64705.8, 0.557], [64706.8, 0.001], [64709.8, 0.006], [64710.5, 3.325], [64784.4, 10.016], [65335.9, 6.759], [65517.4, 0.762], [65548.8, 0.0], [65689.0, 10.035], [65859.2, 8.189]]}
{"kind": "depth", "E": 1787080678285, "U": 11315372304681, "u": 11315372311804, "recv_ms": 1787080678232, "bids": [[14388.9, 1.876], [14488.9, 2.324], [51751.0, 0.0], [58220.0, 4.018], [60793.2, 0.0], [61454.4, 0.072], [63688.9, 0.007], [63742.1, 1.001], [64042.0, 2.169], [64365.5, 5.385], [64685.2, 0.017], [64686.5, 0.02], [64688.9, 4.168]], "asks": [[64689.1, 0.787], [64695.9, 0.043], [65335.9, 6.758], [65498.1, 6.804], [65594.6, 62.106], [65689.0, 10.015]]}
{"kind": "depth", "E": 1787080678387, "U": 11315372312024, "u": 11315372319058, "recv_ms": 1787080678334, "bids": [[1000.0, 35.81], [14388.9, 2.24], [14488.9, 1.96], [51751.0, 0.0], [58220.0, 4.018], [61439.9, 0.0], [61454.4, 0.073], [62086.7, 0.006], [62101.3, 3.477], [63815.6, 19.711], [64042.0, 2.169], [64493.6, 6.11], [64532.4, 2.113], [64534.1, 1.423], [64549.4, 1.15], [64620.7, 6.83], [64623.5, 0.0], [64658.9, 2.562], [64685.2, 0.017]], "asks": [[64689.0, 11.061], [64721.5, 0.0], [64755.1, 0.002], [64831.7, 4.631], [64848.7, 10.414], [65335.9, 6.758], [65498.3, 1.525], [65982.7, 0.014]]}
{"kind": "depth", "E": 1787080678489, "U": 11315372319154, "u": 11315372323543, "recv_ms": 1787080678438, "bids": [[14388.9, 2.604], [14488.9, 1.596], [58220.0, 4.018], [61454.4, 0.072], [62101.3, 3.474], [63380.1, 2.207], [63688.9, 0.027], [63744.4, 2.521], [63880.3, 26.58], [64042.0, 2.169], [64044.1, 0.052], [64204.7, 0.001], [64365.7, 0.002], [64493.6, 8.996], [64527.1, 0.004], [64532.4, 5.431], [64534.1, 2.02], [64549.4, 3.033], [64623.5, 2.327], [64658.9, 2.564], [64685.2, 0.267]], "asks": [[64689.0, 11.061], [64721.5, 0.002], [64755.1, 3.501], [64848.7, 6.471], [64856.5, 0.001], [65018.7, 0.043], [65181.3, 0.0], [65335.9, 6.758], [65344.3, 0.128], [65566.1, 2.131], [65689.0, 10.035]]}
{"kind": "depth", "E": 1787080678591, "U": 11315372323615, "u": 11315372327827, "recv_ms": 1787080678539, "bids": [[14388.9, 2.954], [14488.9, 1.246], [51751.0, 0.01], [58220.0, 4.018], [61454.4, 0.072], [62101.3, 3.477], [64042.0, 2.169], [64044.1, 0.06], [64204.7, 0.006], [64365.5, 5.375], [64365.7, 0.005], [64527.1, 0.006], [64532.4, 3.796], [64549.4, 1.859], [64611.2, 0.003], [64629.4, 0.212], [64629.7, 0.031], [64630.1, 0.169], [64630.4, 2.344], [64630.7, 0.04], [64637.1, 0.196], [64647.3, 0.004], [64647.6, 0.002], [64647.9, 0.022], [64648.3, 1.668], [64648.6, 0.464], [64662.2, 0.0], [64662.3, 0.85], [64662.4, 2.363], [64662.5, 0.033], [64662.6, 0.111], [64662.7, 0.001], [64662.8, 0.322], [64662.9, 1.184], [64663.0, 0.022], [64663.2, 0.002], [64664.4, 0.001], [64664.8, 0.053], [64665.6, 0.625], [64672.9, 0.619], [64681.8, 0.001], [64681.9, 0.005], [64682.0, 0.003], [64682.1, 0.002], [64682.2, 0.016], [64682.3, 0.003], [64682.4, 0.007], [64682.5, 0.002], [64682.6, 0.003], [64682.7, 0.189], [64682.8, 0.0], [64683.1, 0.085], [64683.4, 0.093], [64683.7, 0.31], [64684.0, 0.001], [64684.4, 2.006], [64685.2, 0.267], [64688.9, 4.163]], "asks": [[64694.5, 0.035], [64695.3, 0.016], [64695.6, 1.479], [64695.9, 0.001], [64696.2, 0.244], [64696.6, 0.022], [64696.8, 0.927], [64697.0, 0.918], [64697.1, 0.24], [64697.2, 0.154], [64697.3, 0.041], [64697.4, 0.0], [64697.5, 0.053], [64697.6, 0.031], [64697.7, 0.473], [64697.8, 0.002], [64704.2, 1.083], [64713.2, 1.361], [64713.5, 0.311], [64713.8, 0.004], [64714.1, 0.062], [64714.5, 0.541], [64714.8, 3.539], [64714.9, 2.327], [64715.3, 0.316], [64716.5, 3.33], [64716.6, 0.005], [64716.7, 0.001], [64716.8, 0.206], [64716.9, 0.182], [64717.0, 0.0], [64717.1, 0.0], [64717.2, 0.041], [64717.3, 1.258], [64717.4, 0.067], [64731.1, 0.004], [64731.4, 0.0], [64731.7, 0.021], [64732.0, 0.023], [64732.4, 0.001], [64799.0, 0.079], [64831.7, 5.399], [64848.7, 10.414], [64856.5, 0.003], [64887.5, 15.422], [65018.7, 0.046], [65181.3, 0.005], [65335.9, 6.758], [65344.3, 0.136]]}
{"kind": "depth", "E": 1787080678693, "U": 11315372327830, "u": 11315372332483, "recv_ms": 1787080678642, "bids": [[1000.0, 35.81], [14388.9, 3.304], [14488.9, 0.896], [51751.0, 0.0], [51751.1, 0.0], [58220.0, 4.018], [61454.6, 0.01], [62101.3, 3.474], [63395.2, 0.074], [63688.9, 0.007], [64042.0, 2.169], [64532.4, 5.431], [64549.4, 3.033], [64625.4, 0.133], [64647.5, 0.036], [64648.1, 0.055], [64648.4, 0.032], [64675.6, 0.541], [64676.1, 0.154], [64676.2, 0.003], [64682.1, 0.072], [64682.4, 0.207], [64682.5, 0.102], [64682.7, 0.289], [64682.8, 0.07], [64683.0, 0.075], [64683.3, 0.034], [64683.9, 0.033], [64684.2, 0.079], [64684.5, 1.287], [64684.6, 0.079], [64684.7, 0.086], [64685.2, 0.017], [64688.9, 4.163]], "asks": [[64695.6, 1.514], [64695.9, 0.043], [64696.6, 0.064], [64696.8, 1.032], [64697.0, 1.009], [64697.1, 0.37], [64697.3, 0.171], [64697.4, 0.14], [64697.5, 0.173], [64697.7, 0.557], [64713.5, 0.346], [64713.8, 0.046], [64714.5, 0.583], [64715.3, 0.456], [64716.5, 3.435], [64716.6, 0.096], [64716.7, 0.131], [64717.0, 0.13], [64717.1, 0.12], [64717.3, 1.342], [64731.4, 0.035], [64731.7, 0.063], [64732.4, 0.043], [65335.9, 6.758], [65602.7, 29.688], [65689.0, 10.015]]}
{"kind": "depth", "E": 1787080678795, "U": 11315372332508, "u": 11315372336337, "recv_ms": 1787080678742, "bids": [[14388.9, 3.668], [14488.9, 0.532], [58220.0, 4.018], [63395.2, 0.071], [64042.0, 2.169], [64611.2, 0.0], [64630.6, 0.001], [64643.6, 0.629], [64648.8, 0.244], [64675.6, 0.0], [64682.1, 0.142], [64682.2, 0.086], [64682.3, 0.073], [64682.5, 0.202], [64684.5, 1.853], [64684.6, 0.086], [64685.2, 0.267], [64686.6, 0.085]], "asks": [[64689.1, 0.703], [64692.2, 0.088], [64692.7, 0.149], [64693.2, 0.288], [64695.3, 0.054], [64697.3, 0.291], [64697.5, 0.25], [64697.6, 0.129], [64697.8, 0.086], [64704.8, 0.562], [64705.8, 0.001], [64708.9, 0.33], [64710.5, 3.21], [64713.2, 1.399], [64716.9, 0.302], [64717.1, 0.197], [64717.2, 0.139], [64717.4, 0.151], [64731.1, 0.042], [64734.3, 0.306], [64752.0, 7.509], [64766.7, 0.2], [64799.0, 0.076], [64818.4, 0.216], [64829.2, 2.15], [65335.9, 6.758], [65475.0, 3.784], [65562.3, 17.209], [65594.6, 64.39], [65643.7, 6.767], [65857.2, 5.934]]}
{"kind": "depth", "E": 1787080678897, "U": 11315372336396, "u": 11315372341592, "recv_ms": 1787080678845, "bids": [[14288.9, 0.14], [14388.9, 3.738], [14488.9, 0.322], [58220.0, 4.018], [62101.3, 3.477], [63395.2, 0.074], [63688.9, 0.027], [64042.0, 2.169], [64365.4, 0.0], [64365.5, 5.375], [64630.2, 1.699], [64647.8, 0.033], [64664.6, 0.002], [64665.6, 1.182], [64682.2, 0.156], [64682.6, 0.073], [64683.6, 0.035], [64685.2, 0.017]], "asks": [[64696.2, 0.289], [64697.2, 0.238], [64697.6, 0.22], [64704.8, 0.006], [64705.8, 0.557], [64707.3, 1.321], [64708.4, 0.916], [64708.9, 0.215], [64709.9, 0.131], [64714.1, 0.107], [64716.8, 0.29], [64717.2, 0.23], [64732.0, 0.068], [64751.2, 0.006], [64848.7, 6.501], [65206.5, 9.335], [65335.9, 6.758], [65594.6, 64.207], [65689.0, 10.035], [66148.3, 0.0]]}
{"kind": "depth", "E": 1787080678999, "U": 11315372341784, "u": 11315372346657, "recv_ms": 1787080678949, "bids": [[1000.0, 35.81], [14288.9, 0.378], [14388.9, 3.626], [14488.9, 0.196], [58220.0, 4.018], [62101.3, 3.474], [63920.4, 15.389], [64042.0, 2.169], [64629.6, 0.032], [64630.6, 0.033], [64663.1, 0.411], [64672.5, 0.008], [64675.6, 0.0], [64682.0, 0.073], [64682.9, 1.989], [64683.0, 0.075], [64684.5, 1.86], [64684.6, 0.079], [64685.2, 0.017], [64688.8, 0.063]], "asks": [[64697.0, 1.169], [64697.8, 0.163], [64705.0, 0.047], [64714.8, 3.699], [64717.4, 0.228], [64848.7, 10.414], [65011.3, 0.112], [65335.9, 6.76], [65473.3, 20.226]]}
{"kind": "depth", "E": 1787080679101, "U": 11315372346680, "u": 11315372350806, "recv_ms": 1787080679048, "bids": [[14288.9, 0.616], [14388.9, 3.5], [14488.9, 0.084], [51751.0, 0.0], [58220.0, 4.018], [61454.4, 0.072], [62101.3, 3.477], [63688.9, 0.007], [64042.0, 2.169], [64630.9, 0.033], [64662.5, 0.103], [64662.6, 0.181], [64662.8, 0.422], [64662.9, 1.284], [64663.1, 0.511], [64663.2, 0.072], [64663.4, 1.933], [64664.5, 0.269], [64677.3, 0.002], [64682.7, 0.205], [64683.7, 0.62], [64684.6, 0.079], [64685.2, 0.142], [64687.0, 0.0], [64688.4, 0.0]], "asks": [[64689.0, 10.929], [64689.6, 0.118], [64689.7, 0.0], [64696.8, 0.414], [64704.2, 0.465], [64751.2, 0.024], [64848.7, 7.051], [65012.5, 0.003], [65206.5, 9.64], [65335.9, 6.758], [65350.0, 152.578], [65465.3, 53.657], [65538.0, 6.581], [65639.9, 16.044], [65689.0, 10.015], [65853.4, 1.734], [66144.5, 1.206]]}
{"kind": "depth", "E": 1787080679203, "U": 11315372351002, "u": 11315372355970, "recv_ms": 1787080679151, "bids": [[14288.9, 0.896], [14388.9, 3.304], [14488.9, 0.0], [51751.0, 0.0], [58220.0, 4.018], [61454.4, 0.076], [63880.3, 26.229], [63912.6, 51.594], [64365.5, 5.385], [64629.9, 0.032], [64634.5, 0.015], [64637.8, 0.004], [64662.5, 0.173], [64662.7, 0.071], [64662.9, 1.384], [64664.6, 0.559], [64665.6, 0.625], [64685.2, 0.017]], "asks": [[64693.8, 0.004], [64707.2, 0.565], [64708.4, 0.375], [64848.7, 10.414], [65100.0, 56.526], [65335.9, 6.758], [65497.6, 21.91], [65630.7, 10.464]]}
{"kind": "depth", "E": 1787080679305, "U": 11315372356284, "u": 11315372361995, "recv_ms": 1787080679252, "bids": [[1000.0, 35.81], [14288.9, 1.246], [14388.9, 2.954], [58220.0, 4.018], [61454.4, 0.076], [62101.3, 3.474], [63418.5, 2.7], [63688.9, 0.027], [64042.0, 2.169], [64494.8, 0.026], [64575.9, 0.0], [64576.0, 0.007], [64623.5, 0.0], [64656.0, 0.871], [64656.1, 1.004], [64656.2, 0.003], [64659.4, 0.005], [64659.5, 0.003], [64659.6, 0.002], [64662.4, 2.433], [64662.6, 0.251], [64663.0, 0.092], [64665.6, 0.007], [64672.9, 0.001], [64675.4, 0.542], [64676.1, 0.154], [64676.2, 0.003], [64678.4, 1.908], [64685.2, 0.017], [64688.4, 0.135], [64688.9, 4.163]], "asks": [[64689.0, 10.905], [64692.7, 0.149], [64693.8, 0.003], [64694.4, 0.013], [64695.4, 1.005], [64695.5, 0.131], [64696.1, 0.017], [64696.3, 0.188], [64707.2, 0.024], [64708.4, 0.916], [64752.0, 7.108], [64755.1, 0.002], [64800.1, 1.564], [64802.7, 0.024], [65012.4, 4.611], [65335.9, 6.758], [65530.0, 21.25], [65689.0, 10.035]]}
{"kind": "depth", "E": 1787080679407, "U": 11315372362208, "u": 11315372368064, "recv_ms": 1787080679354, "bids": [[14288.9, 1.61], [14388.9, 2.59], [58220.0, 4.018], [61454.4, 0.076], [61454.5, 2.461], [62101.3, 3.477], [64042.0, 2.169], [64538.0, 2.687], [64540.7, 1.236], [64665.0, 0.604], [64685.2, 0.017], [64686.4, 0.2], [64686.6, 0.001]], "asks": [[64689.0, 10.904], [64690.3, 0.002], [64692.2, 0.629], [64692.6, 0.022], [64692.7, 0.149], [64694.5, 0.055], [64695.3, 0.054], [64695.4, 0.001], [64695.5, 0.046], [64696.1, 0.017], [64696.3, 0.736], [64839.0, 1.421], [64840.3, 0.0], [64848.7, 10.414], [65335.9, 6.758]]}
{"kind": "depth", "E": 1787080679509, "U": 11315372368220, "u": 11315372373345, "recv_ms": 1787080679456, "bids": [[1000.0, 35.96], [14288.9, 1.96], [14388.9, 2.24], [58220.0, 4.018], [61454.4, 0.08], [62101.3, 3.474], [63688.9, 0.007], [63758.7, 4.23], [63776.8, 6.105], [63791.0, 26.628], [64042.0, 2.169], [64365.5, 5.385], [64499.2, 0.006], [64671.9, 0.249], [64685.2, 0.267], [64688.8, 0.218], [64688.9, 4.164]], "asks": [[64689.0, 10.905], [64692.2, 0.088], [64695.5, 0.594], [64696.1, 0.558], [64696.3, 0.188], [64879.1, 0.0], [65335.9, 6.758], [65474.4, 5.343], [65689.0, 10.015]]}
{"kind": "depth", "E": 1787080679713, "U": 11315372387392, "u": 11315372395001, "recv_ms": 1787080679660, "bids": [[14288.9, 2.688], [14388.9, 1.512], [51751.0, 0.0], [51751.1, 0.0], [58220.0, 4.016], [63688.9, 0.027], [63750.9, 38.702], [63783.3, 48.575], [63819.2, 2.971], [64042.0, 2.169], [64540.7, 3.571], [64549.4, 3.033], [64578.4, 3.485], [64617.6, 3.506], [64672.7, 0.435], [64673.1, 0.005], [64685.2, 0.267], [64686.7, 0.002], [64686.8, 0.107], [64688.9, 4.091]], "asks": [[64689.0, 10.875], [64689.5, 0.084], [64693.7, 0.377], [64704.8, 0.006], [64705.8, 0.557], [64707.2, 0.565], [64708.4, 0.375], [64708.9, 0.215], [64709.8, 0.121], [64709.9, 0.016], [64752.0, 7.514], [64784.0, 2.193], [64831.7, 5.399], [64839.0, 3.815], [64848.7, 10.414], [65335.9, 6.758], [65689.0, 10.035], [66306.2, 1.132]]}
{"kind": "depth", "E": 1787080679815, "U": 11315372395023, "u": 11315372400956, "recv_ms": 1787080679762, "bids": [[1000.0, 35.81], [14288.9, 3.038], [14388.9, 1.162], [51751.0, 0.0], [58220.0, 4.018], [61454.4, 0.081], [62101.3, 3.474], [63688.9, 0.007], [63802.4, 2.429], [63880.3, 25.878], [64042.0, 2.169], [64317.3, 0.0], [64319.9, 0.374], [64365.5, 5.385], [64413.9, 0.002], [64415.1, 0.537], [64475.0, 0.329], [64484.8, 0.0], [64484.9, 0.0], [64485.5, 1.278], [64493.6, 6.653], [64532.4, 3.39], [64549.4, 1.771], [64675.6, 0.007], [64683.7, 0.31], [64684.5, 1.853], [64685.2, 0.017], [64686.8, 0.023], [64688.9, 4.091]], "asks": [[64689.0, 10.874], [64818.4, 0.216], [64831.7, 2.85], [64848.7, 4.487], [64880.9, 0.876], [64882.6, 0.0], [64887.5, 7.422], [64953.9, 1.346], [64954.0, 0.024], [65049.8, 2.924], [65051.4, 0.063], [65335.9, 6.758], [65506.7, 1.527], [65539.7, 9.908], [65689.0, 10.015], [65699.7, 2.128]]}
{"kind": "depth", "E": 1787080679917, "U": 11315372401098, "u": 11315372405179, "recv_ms": 1787080679863, "bids": [[1000.0, 35.81], [14288.9, 3.402], [14388.9, 0.798], [58220.0, 4.018], [61454.4, 0.08], [61454.6, 0.006], [62101.3, 3.477], [64042.0, 2.169], [64053.8, 0.005], [64200.8, 0.0], [64493.6, 9.58], [64532.4, 6.845], [64549.4, 3.714], [64623.5, 2.354], [64675.6, 0.0], [64684.5, 1.853], [64684.6, 0.086], [64685.2, 0.017]], "asks": [[64689.0, 10.904], [64693.7, 0.347], [64752.0, 7.108], [64755.0, 3.665], [64831.7, 5.399], [64848.7, 10.414], [64887.5, 10.777], [65168.5, 0.001], [65318.0, 2.69], [65335.9, 6.758], [65691.7, 22.038], [65982.7, 0.017]]}
{"kind": "depth", "E": 1787080680019, "U": 11315372405260, "u": 11315372416532, "recv_ms": 1787080679968, "bids": [[14188.9, 0.028], [14288.9, 3.696], [14388.9, 0.476], [58220.0, 4.018], [61454.4, 0.08], [61454.6, 0.004], [62101.3, 3.474], [63688.9, 0.027], [64042.0, 2.171], [64317.3, 41.952], [64319.9, 6.587], [64365.4, 0.001], [64413.9, 34.57], [64415.1, 5.634], [64484.8, 27.481], [64549.4, 0.0], [64628.8, 1.156], [64647.4, 0.011], [64648.0, 1.277], [64648.6, 0.8], [64653.5, 0.002], [64654.0, 0.006], [64654.1, 0.057], [64654.6, 0.0], [64657.6, 1.584], [64658.7, 0.052], [64664.0, 1.47], [64665.1, 0.002], [64665.4, 0.0], [64665.8, 1.17], [64667.1, 0.19], [64667.5, 0.046], [64668.4, 0.002], [64669.5, 0.005], [64669.8, 0.931], [64670.0, 1.353], [64670.2, 0.01], [64670.3, 0.058], [64670.5, 0.386], [64671.5, 0.208], [64671.6, 0.036], [64672.5, 0.008], [64673.9, 0.031], [64674.6, 0.379], [64674.7, 0.111], [64675.1, 1.832], [64675.3, 0.663], [64675.6, 0.548], [64675.7, 0.172], [64677.5, 0.321], [64678.5, 1.017], [64679.0, 0.001], [64679.2, 0.0], [64681.4, 0.005], [64681.5, 1.057], [64681.6, 0.093], [64682.0, 0.157], [64682.3, 0.157], [64682.7, 0.289], [64683.7, 0.0], [64684.5, 0.034], [64684.6, 0.063], [64684.7, 0.002], [64684.9, 0.002], [64685.1, 0.151], [64685.2, 0.017], [64685.6, 0.047], [64685.7, 0.024], [64685.8, 0.021], [64686.0, 0.001], [64686.1, 0.0], [64686.2, 0.002], [64686.3, 0.0], [64686.4, 0.116], [64686.8, 0.001], [64686.9, 0.0], [64688.9, 3.47]], "asks": [[64689.0, 11.015], [64689.8, 0.68], [64690.0, 1.31], [64690.2, 0.0], [64690.9, 0.003], [64691.0, 0.084], [64691.1, 0.012], [64691.3, 0.003], [64695.4, 0.001], [64695.5, 0.587], [64696.1, 0.017], [64697.0, 1.169], [64702.2, 1.006], [64702.8, 0.021], [64703.0, 0.158], [64703.1, 0.404], [64704.0, 0.269], [64705.0, 0.047], [64705.9, 0.207], [64706.0, 0.062], [64706.1, 0.282], [64706.2, 10.592], [64706.3, 0.172], [64706.5, 0.002], [64706.9, 0.001], [64707.1, 1.011], [64707.2, 0.024], [64707.3, 1.264], [64707.5, 0.017], [64707.9, 0.006], [64709.4, 0.157], [64710.3, 0.15], [64710.6, 0.0], [64713.9, 0.004], [64714.2, 0.751], [64714.5, 0.579], [64714.6, 0.004], [64722.5, 1.001], [64749.1, 0.402], [64751.2, 0.006], [64831.7, 0.0], [64882.5, 26.381], [64953.9, 33.835], [65012.5, 0.001], [65051.4, 40.264], [65335.9, 6.76], [65689.0, 10.035], [71157.9, 0.001]]}
{"kind": "depth", "E": 1787080680121, "U": 11315372416571, "u": 11315372428656, "recv_ms": 1787080680070, "bids": [[1000.0, 35.81], [14188.9, 0.196], [14288.9, 3.71], [14388.9, 0.294], [51751.0, 0.0], [58220.0, 4.018], [61454.4, 0.08], [62101.3, 3.477], [63770.3, 3.986], [63793.4, 9.577], [63815.6, 20.336], [64042.0, 2.169], [64201.5, 53.113], [64365.4, 0.002], [64365.5, 5.385], [64475.0, 0.113], [64484.9, 0.216], [64549.4, 3.656], [64611.0, 0.4], [64613.7, 1.286], [64623.2, 0.044], [64624.2, 0.037], [64626.0, 0.26], [64626.1, 0.047], [64628.8, 1.132], [64630.6, 0.036], [64634.1, 0.021], [64636.9, 0.825], [64640.4, 0.001], [64643.6, 0.626], [64646.6, 0.02], [64646.7, 3.023], [64653.9, 2.376], [64654.1, 0.0], [64667.8, 0.464], [64669.2, 1.375], [64669.4, 0.007], [64669.7, 0.052], [64669.8, 0.005], [64671.0, 0.001], [64671.6, 0.051], [64673.4, 0.312], [64673.7, 0.007], [64673.8, 0.003], [64674.4, 0.156], [64675.0, 3.369], [64675.2, 0.033], [64675.3, 0.123], [64675.4, 0.001], [64675.5, 0.331], [64675.6, 0.0], [64675.7, 0.172], [64675.8, 0.007], [64675.9, 0.009], [64676.0, 0.169], [64676.1, 0.695], [64677.3, 0.002], [64678.3, 1.0], [64678.4, 1.914], [64678.6, 1.064], [64678.7, 2.493], [64678.8, 0.542], [64680.7, 0.112], [64681.3, 0.084], [64681.4, 0.05], [64682.8, 0.116], [64683.0, 0.076], [64683.5, 0.003], [64683.6, 0.035], [64683.8, 0.086], [64684.2, 0.117], [64684.3, 0.388], [64684.4, 1.922], [64684.5, 0.05], [64684.6, 0.065], [64684.9, 0.001], [64685.3, 0.112], [64685.6, 0.001], [64685.7, 0.043], [64685.8, 0.001], [64686.4, 0.004], [64688.5, 0.033], [64688.7, 0.02], [64688.9, 3.98]], "asks": [[64689.0, 12.703], [64689.1, 0.739], [64689.7, 0.0], [64689.8, 0.052], [64690.1, 0.092], [64690.5, 0.003], [64690.7, 0.001], [64690.9, 0.001], [64691.1, 0.022], [64691.2, 1.14], [64692.1, 0.011], [64692.6, 0.047], [64692.7, 0.111], [64693.5, 0.067], [64694.1, 2.633], [64695.1, 0.016], [64695.5, 0.023], [64695.8, 0.008], [64696.1, 0.573], [64696.2, 0.297], [64696.3, 0.728], [64698.0, 0.125], [64699.0, 0.057], [64699.2, 0.122], [64700.5, 0.005], [64701.0, 1.685], [64701.8, 0.111], [64701.9, 1.109], [64702.1, 0.147], [64702.2, 0.101], [64702.6, 0.482], [64702.8, 0.036], [64703.7, 0.027], [64704.4, 1.471], [64705.0, 0.028], [64705.4, 0.002], [64705.5, 1.332], [64707.1, 0.47], [64707.2, 0.55], [64708.4, 0.446], [64708.5, 1.975], [64731.0, 0.096], [64731.2, 1.221], [64734.3, 0.306], [64737.1, 1.066], [64737.4, 0.0], [64828.2, 0.215], [64831.7, 5.399], [64848.7, 10.414], [64887.5, 11.016], [65049.8, 8.519], [65168.4, 49.956], [65335.9, 6.758], [65982.7, 0.014], [71157.9, 0.0]]}
{"kind": "depth", "E": 1787080680223, "U": 11315372428702, "u": 11315372464104, "recv_ms": 1787080680442, "bids": [[1000.0, 35.81], [14182.1, 0.07], [14184.3, 0.028], [14185.2, 0.056], [14185.7, 0.014], [14187.9, 0.014], [14188.9, 0.252], [14282.1, 0.042], [14284.3, 0.014], [14285.2, 0.014], [14285.7, 0.014], [14288.9, 3.514], [14388.9, 0.168], [51751.0, 0.0], [58213.8, 0.003], [58216.6, 6.787], [58217.1, 0.001], [58220.0, 4.067], [61451.4, 0.003], [61897.5, 0.0], [62060.0, 1.17], [63388.5, 0.003], [63390.7, 0.006], [63391.5, 0.006], [63395.2, 0.071], [63688.9, 0.007], [64035.3, 0.0], [64037.5, 0.029], [64038.2, 0.008], [64038.3, 0.001], [64038.8, 0.0], [64039.6, 0.0], [64041.0, 0.006], [64041.8, 1.638], [64042.0, 2.169], [64341.5, 0.015], [64342.2, 4.513], [64345.1, 0.001], [64348.4, 0.002], [64349.1, 0.004], [64351.6, 0.002], [64354.4, 0.029], [64417.6, 4.451], [64490.4, 13.308], [64493.6, 0.0], [64495.8, 1.393], [64499.7, 0.001], [64502.9, 0.016], [64522.7, 0.228], [64536.1, 0.028], [64541.9, 0.247], [64549.3, 0.028], [64554.9, 0.016], [64556.6, 0.209], [64556.8, 0.002], [64558.0, 0.608], [64558.1, 0.009], [64559.5, 0.027], [64560.0, 0.44], [64561.2, 0.002], [64563.1, 0.002], [64566.2, 0.283], [64576.7, 32.489], [64579.3, 0.834], [64587.0, 0.021], [64587.2, 1.446], [64589.2, 0.01], [64589.9, 0.001], [64591.0, 0.001], [64591.9, 0.027], [64597.1, 0.0], [64597.2, 0.004], [64600.9, 0.343], [64603.1, 0.009], [64603.2, 3.263], [64604.4, 4.328], [64604.5, 2.391], [64605.4, 0.003], [64606.3, 0.0], [64606.5, 0.002], [64606.9, 0.317], [64607.3, 2.401], [64607.5, 0.0], [64607.8, 0.144], [64609.1, 0.019], [64610.1, 0.01], [64611.0, 0.38], [64611.9, 0.314], [64612.1, 0.001], [64612.7, 0.041], [64613.3, 0.003], [64614.9, 0.088], [64615.3, 0.384], [64616.5, 0.285], [64617.3, 6.027], [64617.5, 0.0], [64617.6, 1.96], [64618.0, 0.014], [64618.4, 0.0], [64618.5, 0.005], [64618.8, 0.0], [64619.0, 0.172], [64619.3, 0.003], [64619.5, 0.379], [64620.1, 0.006], [64620.4, 0.009], [64620.7, 2.153], [64621.0, 0.182], [64621.7, 0.011], [64622.1, 0.052], [64622.2, 0.004], [64622.5, 0.003], [64623.0, 0.014], [64623.1, 0.312], [64623.2, 0.0], [64623.3, 2.338], [64623.5, 2.379], [64624.2, 0.006], [64624.3, 0.239], [64624.6, 0.0], [64625.0, 1.611], [64625.4, 0.033], [64625.8, 0.007], [64625.9, 0.003], [64626.0, 0.235], [64626.2, 0.008], [64627.2, 0.02], [64628.3, 0.55], [64629.0, 0.005], [64629.3, 0.005], [64629.5, 0.016], [64629.7, 0.031], [64630.4, 2.367], [64630.5, 0.038], [64630.6, 0.042], [64631.4, 0.015], [64633.0, 0.083], [64633.3, 0.048], [64633.9, 0.0], [64634.0, 0.003], [64634.1, 0.002], [64634.6, 0.042], [64634.9, 0.047], [64635.3, 0.423], [64635.8, 0.016], [64636.2, 0.004], [64636.3, 0.006], [64636.6, 0.001], [64636.7, 0.001], [64636.8, 1.714], [64636.9, 0.824], [64637.1, 0.127], [64637.5, 0.009], [64637.7, 0.013], [64638.0, 0.014], [64638.6, 0.455], [64638.8, 0.001], [64638.9, 0.004], [64639.0, 0.0], [64639.1, 0.533], [64639.8, 0.017], [64639.9, 4.242], [64640.1, 0.003], [64640.6, 0.007], [64640.8, 0.0], [64641.7, 2.135], [64641.9, 0.329], [64642.0, 0.219], [64642.1, 0.0], [64642.3, 0.002], [64642.6, 0.042], [64642.8, 0.034], [64643.0, 2.616], [64643.1, 4.222], [64643.2, 4.784], [64643.4, 0.41], [64643.5, 0.07], [64643.6, 0.441], [64643.7, 0.057], [64644.0, 1.473], [64644.1, 0.0], [64644.4, 0.001], [64644.8, 1.237], [64645.2, 0.201], [64645.3, 0.0], [64645.6, 0.0], [64645.7, 0.162], [64646.0, 0.043], [64646.1, 0.125], [64646.3, 0.504], [64646.6, 0.018], [64646.7, 3.283], [64646.8, 0.035], [64647.1, 0.411], [64647.2, 0.0], [64647.4, 0.007], [64648.6, 0.464], [64649.0, 0.249], [64650.0, 4.948], [64650.1, 0.075], [64650.2, 0.441], [64650.3, 0.155], [64651.0, 0.002], [64651.1, 0.318], [64651.2, 1.172], [64651.3, 0.319], [64651.6, 0.191], [64651.7, 0.003], [64651.9, 0.699], [64652.1, 0.136], [64652.4, 0.411], [64652.8, 0.389], [64653.3, 0.257], [64653.8, 0.007], [64653.9, 2.319], [64654.1, 0.557], [64654.4, 1.206], [64654.5, 0.322], [64654.6, 0.097], [64655.8, 0.028], [64656.1, 1.01], [64656.2, 0.012], [64656.3, 0.046], [64656.5, 0.005], [64656.6, 2.642], [64656.7, 0.306], [64657.0, 0.066], [64657.1, 0.003], [64657.2, 0.12], [64657.3, 0.002], [64657.4, 0.015], [64657.5, 0.003], [64657.6, 1.47], [64657.9, 1.741], [64658.0, 1.263], [64658.2, 0.001], [64658.3, 2.133], [64658.4, 0.0], [64658.5, 0.317], [64658.6, 0.377], [64658.7, 0.067], [64658.8, 0.461], [64658.9, 1.991], [64659.1, 0.313], [64659.2, 2.775], [64659.4, 0.005], [64659.8, 0.054], [64659.9, 0.003], [64660.3, 0.003], [64660.4, 0.01], [64660.6, 0.001], [64660.8, 1.184], [64661.0, 0.027], [64661.2, 0.02], [64661.3, 0.042], [64661.4, 0.0], [64661.6, 0.002], [64661.8, 0.0], [64661.9, 0.61], [64662.0, 0.139], [64662.1, 0.018], [64662.2, 0.926], [64662.3, 0.912], [64662.4, 0.115], [64662.5, 0.152], [64662.6, 0.251], [64662.7, 0.071], [64662.8, 0.419], [64662.9, 0.341], [64663.1, 0.511], [64663.2, 0.072], [64663.4, 1.933], [64663.5, 0.001], [64663.6, 0.003], [64663.8, 0.002], [64664.0, 1.316], [64664.1, 0.018], [64664.3, 1.06], [64664.4, 0.001], [64664.5, 0.384], [64664.6, 0.036], [64664.7, 0.622], [64664.8, 0.003], [64665.0, 0.012], [64665.1, 0.002], [64665.2, 0.156], [64665.3, 1.689], [64665.4, 0.0], [64665.5, 0.001], [64665.6, 0.088], [64665.7, 0.165], [64665.8, 1.163], [64665.9, 0.324], [64666.1, 0.003], [64666.2, 0.695], [64666.3, 0.004], [64666.4, 2.32], [64666.5, 0.044], [64666.6, 0.047], [64666.7, 0.006], [64666.8, 0.013], [64666.9, 0.655], [64667.0, 0.903], [64667.1, 0.061], [64667.2, 0.001], [64667.3, 0.912], [64667.4, 1.55], [64667.5, 0.047], [64667.6, 0.026], [64667.7, 0.006], [64667.8, 0.0], [64667.9, 0.084], [64668.0, 0.121], [64668.3, 0.315], [64668.4, 0.002], [64668.5, 0.003], [64668.6, 0.002], [64668.7, 2.196], [64668.8, 0.188], [64668.9, 0.623], [64669.0, 2.327], [64669.1, 0.453], [64669.2, 0.003], [64669.3, 0.005], [64669.5, 0.004], [64669.6, 0.023], [64669.8, 0.006], [64670.0, 1.364], [64670.1, 0.134], [64670.2, 0.003], [64670.3, 0.056], [64670.4, 0.046], [64670.5, 0.232], [64670.6, 0.679], [64670.7, 0.172], [64670.8, 0.002], [64670.9, 0.669], [64671.0, 0.002], [64671.1, 0.01], [64671.2, 0.168], [64671.3, 0.006], [64671.4, 0.31], [64671.5, 0.208], [64671.6, 0.003], [64671.7, 0.473], [64671.9, 0.19], [64672.0, 0.009], [64672.2, 0.008], [64672.3, 0.006], [64672.4, 0.0], [64672.5, 0.006], [64672.6, 2.111], [64672.7, 0.201], [64672.8, 0.001], [64672.9, 0.001], [64673.0, 0.468], [64673.1, 0.02], [64673.2, 0.0], [64673.3, 0.013], [64673.4, 0.001], [64673.5, 0.128], [64673.6, 0.002], [64673.7, 0.003], [64673.8, 1.075], [64673.9, 0.024], [64674.0, 0.215], [64674.1, 0.312], [64674.2, 0.0], [64674.3, 0.002], [64674.4, 0.001], [64674.5, 0.002], [64674.6, 0.001], [64674.7, 0.071], [64674.8, 0.25], [64674.9, 0.426], [64675.0, 0.102], [64675.1, 0.056], [64675.2, 0.033], [64675.3, 0.003], [64675.4, 0.085], [64675.5, 0.018], [64675.6, 0.541], [64675.7, 0.169], [64675.8, 0.192], [64675.9, 0.003], [64676.0, 0.001], [64676.1, 0.084], [64676.2, 0.006], [64676.3, 0.001], [64676.5, 0.084], [64676.7, 0.311], [64676.8, 0.004], [64676.9, 1.925], [64677.0, 0.084], [64677.1, 0.003], [64677.2, 0.001], [64677.4, 0.328], [64677.5, 0.001], [64677.6, 1.921], [64677.7, 0.001], [64677.8, 0.085], [64677.9, 0.105], [64678.0, 0.076], [64678.1, 0.104], [64678.2, 0.197], [64678.3, 0.0], [64678.4, 0.008], [64678.5, 0.001], [64678.6, 0.086], [64678.7, 0.002], [64678.8, 0.002], [64678.9, 0.045], [64679.0, 0.001], [64679.1, 0.001], [64679.2, 0.232], [64679.3, 0.001], [64679.4, 0.001], [64679.5, 0.032], [64679.6, 0.001], [64679.7, 0.007], [64679.8, 0.0], [64680.0, 0.005], [64680.2, 0.003], [64680.3, 0.002], [64680.4, 0.001], [64680.5, 0.001], [64680.6, 0.002], [64680.7, 0.003], [64680.9, 0.0], [64681.1, 0.003], [64681.2, 0.0], [64681.3, 0.0], [64681.4, 0.002], [64681.5, 0.0], [64681.6, 0.003], [64681.7, 0.001], [64681.8, 0.0], [64681.9, 0.001], [64682.0, 0.003], [64682.1, 6.72], [64682.2, 0.0], [64682.3, 0.0], [64682.4, 0.0], [64682.5, 0.0], [64682.6, 0.0], [64682.7, 0.0], [64682.8, 0.0], [64682.9, 0.0], [64683.0, 0.0], [64683.1, 0.0], [64683.2, 0.0], [64683.3, 0.0], [64683.4, 0.0], [64683.5, 0.0], [64683.6, 0.0], [64683.8, 0.0], [64683.9, 0.0], [64684.0, 0.0], [64684.1, 0.0], [64684.2, 0.0], [64684.3, 0.0], [64684.4, 0.0], [64684.5, 0.0], [64684.6, 0.0], [64684.7, 0.0], [64684.8, 0.0], [64684.9, 0.0], [64685.0, 0.0], [64685.1, 0.0], [64685.2, 0.0], [64685.3, 0.0], [64685.4, 0.0], [64685.6, 0.0], [64685.7, 0.0], [64685.8, 0.0], [64685.9, 0.0], [64686.0, 0.0], [64686.2, 0.0], [64686.4, 0.0], [64686.5, 0.0], [64686.6, 0.0], [64686.7, 0.0], [64686.8, 0.0], [64687.1, 0.0], [64687.3, 0.0], [64687.4, 0.0], [64687.5, 0.0], [64687.7, 0.0], [64687.9, 0.0], [64688.0, 0.0], [64688.1, 0.0], [64688.3, 0.0], [64688.4, 0.0], [64688.5, 0.0], [64688.6, 0.0], [64688.7, 0.0], [64688.8, 0.0], [64688.9, 0.0]], "asks": [[64682.2, 32.07], [64682.3, 0.498], [64682.4, 0.002], [64682.5, 0.032], [64682.6, 0.0], [64682.7, 2.443], [64682.8, 0.0], [64682.9, 0.002], [64683.0, 0.0], [64683.1, 0.0], [64683.2, 0.0], [64683.3, 0.001], [64683.4, 0.084], [64683.5, 0.001], [64683.6, 0.0], [64683.7, 0.739], [64683.8, 0.001], [64683.9, 0.0], [64684.0, 0.004], [64684.2, 0.016], [64684.3, 4.05], [64684.4, 1.153], [64684.5, 0.001], [64684.6, 0.0], [64684.7, 0.0], [64684.8, 0.001], [64684.9, 0.001], [64685.0, 0.002], [64685.1, 0.093], [64685.2, 5.962], [64685.3, 8.468], [64685.4, 0.003], [64685.5, 0.002], [64685.6, 0.075], [64685.7, 0.008], [64685.8, 1.963], [64685.9, 0.005], [64686.0, 0.003], [64686.1, 0.024], [64686.2, 0.002], [64686.3, 0.001], [64686.4, 0.085], [64686.5, 0.31], [64686.6, 0.001], [64686.7, 0.002], [64686.8, 0.001], [64686.9, 0.272], [64687.0, 0.085], [64687.1, 0.003], [64687.2, 0.011], [64687.3, 0.0], [64687.4, 0.004], [64687.5, 0.002], [64687.6, 0.002], [64687.7, 0.837], [64687.8, 0.0], [64687.9, 3.104], [64688.0, 1.391], [64688.1, 0.004], [64688.2, 2.528], [64688.3, 0.002], [64688.4, 0.0], [64688.5, 0.015], [64688.6, 0.003], [64688.7, 0.977], [64688.8, 0.452], [64688.9, 0.004], [64689.0, 1.025], [64689.1, 0.003], [64689.2, 0.404], [64689.3, 0.002], [64689.4, 0.001], [64689.5, 0.085], [64689.6, 0.035], [64689.7, 0.0], [64689.8, 0.014], [64689.9, 0.338], [64690.0, 1.307], [64690.1, 0.009], [64690.2, 0.0], [64690.3, 0.003], [64690.5, 0.003], [64690.6, 0.003], [64690.7, 0.002], [64690.8, 2.325], [64690.9, 0.186], [64691.0, 0.0], [64691.1, 0.313], [64691.2, 1.389], [64691.3, 0.004], [64691.4, 0.074], [64691.5, 0.015], [64691.6, 0.001], [64691.7, 0.023], [64691.8, 0.02], [64691.9, 0.003], [64692.0, 0.136], [64692.1, 0.001], [64692.2, 0.001], [64692.4, 0.003], [64692.6, 0.014], [64692.7, 0.108], [64692.8, 0.767], [64692.9, 0.58], [64693.0, 0.902], [64693.1, 0.01], [64693.2, 0.009], [64693.3, 0.002], [64693.4, 0.032], [64693.5, 0.194], [64693.6, 0.066], [64693.7, 0.347], [64693.8, 0.017], [64693.9, 0.003], [64694.0, 0.632], [64694.1, 2.63], [64694.2, 0.002], [64694.4, 0.012], [64694.5, 0.295], [64694.7, 0.929], [64694.8, 0.113], [64694.9, 0.038], [64695.0, 0.34], [64695.1, 0.532], [64695.2, 0.533], [64695.3, 0.039], [64695.4, 0.002], [64695.5, 0.008], [64695.6, 1.513], [64695.7, 0.192], [64695.8, 0.531], [64696.0, 0.025], [64696.1, 0.251], [64696.2, 0.046], [64696.3, 0.002], [64696.4, 0.466], [64696.5, 0.464], [64696.6, 0.062], [64696.7, 2.32], [64696.8, 0.105], [64696.9, 0.154], [64697.1, 1.144], [64697.2, 0.235], [64697.3, 0.277], [64697.4, 0.2], [64697.5, 0.199], [64697.6, 0.22], [64697.7, 0.773], [64697.8, 0.163], [64697.9, 0.116], [64698.0, 0.181], [64698.1, 0.0], [64698.2, 0.315], [64698.3, 0.003], [64698.4, 1.152], [64698.6, 0.873], [64698.7, 0.015], [64698.8, 1.015], [64698.9, 1.389], [64699.0, 0.124], [64699.1, 1.303], [64699.2, 0.024], [64699.7, 0.0], [64699.9, 0.113], [64700.0, 0.312], [64700.3, 0.338], [64700.4, 0.02], [64700.5, 0.0], [64700.6, 0.002], [64700.7, 0.001], [64700.9, 0.009], [64701.0, 1.684], [64701.2, 0.0], [64701.4, 0.353], [64701.5, 0.069], [64701.6, 0.394], [64701.7, 0.036], [64701.8, 0.03], [64701.9, 0.18], [64702.0, 2.903], [64702.1, 0.004], [64702.2, 10.197], [64702.5, 0.005], [64702.6, 0.463], [64702.8, 0.351], [64703.0, 0.004], [64703.1, 0.092], [64703.2, 0.399], [64703.3, 0.0], [64703.4, 0.316], [64703.6, 0.16], [64703.7, 0.035], [64703.8, 0.0], [64703.9, 0.678], [64704.0, 0.129], [64704.1, 0.116], [64704.5, 2.361], [64704.6, 2.972], [64704.7, 0.002], [64704.8, 0.006], [64705.0, 0.025], [64705.2, 0.0], [64705.3, 0.115], [64705.4, 0.001], [64705.5, 1.333], [64705.6, 1.561], [64705.8, 0.001], [64705.9, 0.064], [64706.0, 0.005], [64706.1, 0.275], [64706.2, 0.025], [64706.3, 0.17], [64706.5, 0.002], [64706.6, 0.003], [64707.1, 0.463], [64707.2, 0.008], [64707.4, 0.015], [64707.6, 0.633], [64707.7, 0.006], [64707.8, 0.001], [64708.2, 0.03], [64708.3, 0.01], [64708.4, 0.001], [64708.7, 0.003], [64708.8, 6.189], [64708.9, 0.23], [64709.0, 0.001], [64709.1, 0.001], [64709.4, 0.157], [64709.5, 0.001], [64709.6, 0.05], [64709.7, 0.004], [64709.8, 0.005], [64710.0, 0.122], [64710.2, 0.024], [64710.3, 0.134], [64710.4, 0.008], [64710.5, 1.816], [64710.7, 0.015], [64710.8, 0.099], [64710.9, 0.002], [64711.0, 0.367], [64711.1, 1.051], [64711.3, 0.172], [64711.8, 0.631], [64712.1, 1.247], [64712.2, 2.377], [64712.9, 0.036], [64713.0, 0.135], [64713.2, 0.268], [64713.5, 0.351], [64713.6, 0.007], [64714.2, 0.631], [64714.3, 3.085], [64714.6, 0.0], [64715.0, 0.001], [64715.3, 0.455], [64715.4, 0.013], [64715.5, 0.016], [64715.9, 0.001], [64716.5, 3.495], [64716.7, 0.221], [64716.8, 0.24], [64717.0, 0.13], [64717.2, 0.19], [64717.4, 0.223], [64717.7, 0.008], [64717.8, 0.004], [64717.9, 0.007], [64718.3, 0.021], [64719.1, 0.498], [64719.3, 0.317], [64719.5, 1.326], [64719.7, 0.026], [64720.0, 0.153], [64720.2, 0.001], [64720.3, 0.072], [64720.4, 0.015], [64720.6, 0.0], [64720.7, 0.066], [64720.8, 0.069], [64720.9, 0.239], [64721.0, 0.002], [64721.3, 0.16], [64721.5, 0.004], [64721.6, 1.361], [64721.7, 0.002], [64721.8, 0.248], [64721.9, 0.054], [64722.1, 0.029], [64722.2, 2.015], [64722.3, 0.045], [64722.4, 0.628], [64722.5, 0.001], [64722.6, 0.125], [64722.7, 2.761], [64722.8, 0.003], [64723.7, 0.002], [64723.8, 0.003], [64723.9, 0.002], [64724.2, 0.028], [64725.3, 0.0], [64725.5, 0.0], [64725.7, 0.006], [64725.9, 0.156], [64726.1, 0.286], [64727.1, 0.0], [64727.3, 0.377], [64727.6, 0.0], [64727.7, 0.025], [64727.8, 0.017], [64728.3, 0.001], [64728.6, 0.022], [64728.8, 0.355], [64728.9, 0.125], [64729.0, 0.009], [64729.3, 0.632], [64729.6, 0.01], [64730.2, 0.0], [64730.5, 0.002], [64732.2, 0.029], [64733.6, 4.251], [64733.8, 0.0], [64734.0, 0.001], [64734.3, 0.305], [64734.7, 0.278], [64735.2, 0.029], [64736.1, 0.003], [64736.4, 0.017], [64736.5, 0.0], [64736.8, 0.003], [64737.3, 0.004], [64738.0, 0.002], [64738.1, 0.016], [64738.9, 0.004], [64739.6, 0.0], [64740.0, 0.12], [64740.3, 0.093], [64740.6, 2.55], [64741.2, 2.718], [64741.3, 0.161], [64743.3, 0.224], [64744.4, 0.026], [64746.6, 0.003], [64746.7, 0.088], [64747.1, 0.0], [64749.3, 1.807], [64750.3, 0.002], [64751.6, 0.001], [64751.9, 0.223], [64752.0, 1.108], [64753.1, 0.002], [64755.0, 3.665], [64755.9, 2.049], [64756.9, 0.027], [64760.1, 0.046], [64760.8, 0.0], [64763.5, 0.0], [64764.0, 0.035], [64764.1, 0.0], [64764.9, 0.68], [64765.2, 0.0], [64765.7, 1.237], [64766.0, 0.016], [64766.7, 0.203], [64767.9, 0.009], [64769.4, 0.4], [64770.0, 0.122], [64770.1, 0.001], [64772.3, 1.281], [64774.4, 0.205], [64774.5, 38.129], [64775.7, 0.014], [64777.1, 0.002], [64780.7, 0.202], [64781.8, 0.022], [64782.2, 0.0], [64782.3, 2.893], [64784.0, 0.802], [64784.4, 0.016], [64785.2, 0.022], [64785.4, 0.03], [64787.4, 0.177], [64787.6, 0.0], [64791.1, 2.132], [64791.2, 0.018], [64791.7, 0.221], [64793.6, 0.046], [64793.9, 2.386], [64794.8, 0.003], [64799.4, 2.128], [64799.5, 0.006], [64803.0, 0.017], [64804.9, 0.004], [64807.7, 2.146], [64807.8, 0.001], [64813.8, 0.333], [64814.7, 0.332], [64814.9, 0.001], [64817.3, 0.029], [64819.9, 0.0], [64820.9, 0.001], [64823.0, 0.053], [64825.4, 0.001], [64838.6, 1.607], [64838.7, 0.013], [64845.5, 0.0], [64848.7, 0.005], [64849.8, 7.204], [64852.5, 1.465], [64852.6, 0.001], [64855.8, 0.0], [64858.6, 0.0], [64861.8, 25.956], [64867.4, 0.015], [64880.2, 0.004], [64884.3, 0.017], [64887.5, 0.011], [64888.6, 10.933], [65088.1, 0.003], [65329.0, 0.271], [65331.2, 0.058], [65332.1, 1.199], [65332.2, 0.006], [65334.9, 2.121], [65335.1, 0.004], [65335.9, 6.758], [65538.0, 4.296], [65677.3, 2.971], [65679.2, 1.067], [65682.2, 0.001], [65685.2, 0.002], [65685.3, 0.008], [65685.8, 0.072], [65689.0, 10.015], [65718.2, 0.018], [65721.2, 0.0]]}
{"kind": "depth", "E": 1787080680325, "U": 11315372464194, "u": 11315372479498, "recv_ms": 1787080680456, "bids": [[14182.1, 0.308], [14282.1, 0.154], [14288.9, 3.276], [14388.9, 0.056], [51746.0, 0.0], [51751.0, 0.0], [58213.8, 0.003], [61447.9, 0.0], [61750.0, 4.92], [62101.3, 3.474], [63207.2, 0.009], [64035.3, 0.0], [64499.7, 0.0], [64548.2, 0.219], [64556.1, 0.834], [64556.6, 0.092], [64558.0, 0.522], [64561.8, 0.472], [64568.6, 0.002], [64568.9, 0.016], [64575.7, 0.028], [64575.9, 0.013], [64576.7, 0.0], [64578.9, 2.886], [64582.7, 0.0], [64583.0, 0.016], [64589.8, 0.0], [64590.0, 0.41], [64596.8, 3.347], [64597.1, 0.013], [64598.7, 37.904], [64602.0, 0.291], [64603.9, 0.026], [64604.0, 0.379], [64604.1, 0.019], [64604.5, 2.32], [64606.0, 0.041], [64610.9, 0.0], [64611.2, 0.013], [64612.0, 0.406], [64613.0, 0.118], [64617.4, 0.032], [64618.0, 0.001], [64623.6, 0.005], [64627.2, 0.016], [64630.3, 1.769], [64630.4, 2.413], [64637.2, 1.886], [64639.9, 4.303], [64640.6, 0.011], [64641.6, 1.063], [64642.2, 0.004], [64642.8, 0.105], [64642.9, 0.071], [64643.0, 2.824], [64643.1, 4.322], [64643.3, 4.289], [64643.4, 0.411], [64643.5, 0.07], [64643.6, 0.441], [64643.7, 0.0], [64643.8, 0.092], [64644.0, 1.474], [64644.6, 0.003], [64646.6, 0.118], [64646.7, 3.222], [64647.5, 0.093], [64655.0, 0.93], [64655.6, 0.019], [64656.0, 0.895], [64656.2, 1.326], [64656.4, 0.038], [64656.6, 2.632], [64657.2, 0.157], [64660.7, 1.931], [64662.3, 1.558], [64662.4, 0.115], [64662.6, 0.405], [64662.7, 0.152], [64662.8, 0.326], [64663.1, 0.411], [64663.5, 0.125], [64664.1, 0.011], [64664.3, 0.06], [64664.5, 0.124], [64665.2, 0.002], [64665.6, 0.008], [64666.0, 3.103], [64667.2, 0.212], [64667.3, 0.371], [64668.6, 0.002], [64668.9, 0.546], [64669.0, 2.32], [64669.1, 0.998], [64669.2, 0.074], [64669.4, 0.007], [64670.1, 0.134], [64670.4, 0.006], [64670.9, 1.097], [64671.0, 0.902], [64671.1, 0.011], [64671.3, 0.003], [64672.5, 0.007], [64673.1, 1.939], [64673.2, 0.665], [64673.3, 0.013], [64673.5, 0.128], [64673.7, 0.002], [64673.8, 1.305], [64673.9, 0.044], [64674.0, 0.004], [64674.1, 0.002], [64674.8, 0.32], [64674.9, 0.566], [64675.0, 0.08], [64675.1, 0.156], [64675.2, 0.233], [64675.4, 0.001], [64675.5, 0.188], [64675.6, 0.0], [64675.7, 0.239], [64675.8, 0.108], [64676.0, 0.002], [64676.3, 0.033], [64676.9, 0.006], [64677.3, 0.034], [64677.9, 0.103], [64678.0, 0.078], [64678.1, 0.102], [64679.2, 0.0], [64679.4, 0.085], [64679.5, 0.264], [64679.6, 0.002], [64679.8, 0.084], [64680.2, 0.087], [64682.1, 4.167]], "asks": [[64682.2, 37.379], [64683.0, 0.0], [64683.3, 0.001], [64684.0, 0.001], [64684.3, 3.052], [64684.4, 1.139], [64685.1, 0.0], [64685.3, 3.946], [64685.6, 0.008], [64686.1, 0.002], [64687.7, 0.84], [64687.9, 3.105], [64688.0, 1.381], [64688.1, 0.003], [64688.5, 0.016], [64689.0, 0.985], [64690.0, 2.208], [64690.3, 0.008], [64690.7, 0.014], [64692.0, 0.138], [64692.7, 0.193], [64693.9, 0.011], [64694.1, 2.715], [64694.5, 0.375], [64694.7, 0.004], [64695.7, 0.212], [64695.8, 1.456], [64696.0, 0.023], [64696.8, 0.106], [64697.1, 1.354], [64697.7, 0.716], [64698.0, 0.177], [64698.8, 0.474], [64699.2, 0.012], [64699.3, 0.434], [64699.7, 0.0], [64700.0, 0.44], [64700.2, 0.003], [64700.9, 0.55], [64701.6, 0.396], [64702.0, 2.901], [64702.2, 10.119], [64702.4, 1.557], [64702.6, 0.483], [64703.1, 0.072], [64703.6, 1.861], [64703.7, 0.128], [64703.9, 0.468], [64704.6, 2.972], [64705.6, 2.006], [64708.1, 0.836], [64709.5, 0.091], [64710.0, 0.006], [64712.8, 0.022], [64716.7, 0.131], [64718.1, 0.007], [64724.3, 0.052], [64725.6, 0.157], [64725.9, 0.0], [64727.3, 0.373], [64727.5, 0.0], [64728.3, 0.0], [64728.9, 0.124], [64729.5, 0.0], [64730.1, 0.005], [64730.6, 0.696], [64730.7, 0.034], [64731.0, 0.066], [64731.3, 0.169], [64731.9, 0.002], [64739.9, 0.018], [64740.3, 0.097], [64740.6, 2.34], [64743.3, 0.22], [64749.4, 0.01], [64750.4, 1.458], [64756.9, 38.2], [64763.5, 0.0], [64769.7, 0.045], [64774.5, 0.054], [64780.3, 0.0], [64801.9, 0.122], [64841.9, 10.807], [64849.8, 0.0], [64849.9, 5.678], [64861.7, 4.583], [64873.9, 0.638], [64880.7, 7.345], [64888.6, 0.006], [65008.6, 0.154], [65329.0, 0.271]]}
{"kind": "depth", "E": 1787080680427, "U": 11315372479681, "u": 11315372489341, "recv_ms": 1787080680469, "bids": [[1000.0, 35.81], [14182.1, 0.616], [14282.1, 0.21], [14288.9, 2.968], [14388.9, 0.0], [58213.8, 0.003], [61447.9, 0.0], [61756.0, 0.042], [62094.8, 0.009], [63682.1, 0.02], [63783.0, 1.286], [63791.0, 24.279], [64034.6, 0.388], [64035.3, 0.0], [64041.4, 0.838], [64365.5, 5.375], [64538.7, 0.037], [64554.2, 2.322], [64586.1, 0.008], [64598.7, 5.415], [64611.9, 32.803], [64612.3, 0.036], [64616.4, 0.003], [64619.5, 0.381], [64621.1, 0.023], [64634.6, 0.157], [64637.4, 0.209], [64640.4, 0.002], [64641.0, 0.016], [64642.8, 0.035], [64643.0, 2.754], [64643.1, 4.392], [64643.3, 4.389], [64652.0, 1.744], [64654.1, 0.0], [64657.2, 0.041], [64657.7, 0.163], [64657.9, 1.626], [64659.2, 2.768], [64659.8, 0.611], [64659.9, 0.01], [64660.3, 0.01], [64660.9, 0.349], [64661.0, 0.025], [64661.4, 0.116], [64662.0, 1.039], [64662.2, 0.928], [64662.4, 0.239], [64662.5, 0.082], [64662.7, 0.082], [64662.9, 0.241], [64663.1, 0.311], [64663.2, 0.002], [64663.4, 1.863], [64663.5, 0.001], [64664.5, 0.009], [64666.5, 0.037], [64666.7, 0.004], [64668.8, 0.319], [64668.9, 0.083], [64670.1, 0.142], [64670.6, 0.37], [64671.7, 0.473], [64672.4, 0.309], [64673.2, 0.471], [64673.8, 0.631], [64673.9, 0.044], [64675.0, 1.797], [64675.1, 1.404], [64675.3, 0.181], [64675.4, 0.078], [64675.6, 0.001], [64676.6, 0.032], [64677.7, 0.565], [64677.8, 0.086], [64678.2, 0.085], [64680.3, 0.114], [64681.0, 0.002], [64682.1, 4.187]], "asks": [[64682.2, 37.521], [64682.3, 0.499], [64682.4, 0.003], [64682.8, 0.001], [64683.0, 0.9], [64683.8, 0.008], [64683.9, 0.0], [64684.2, 0.019], [64684.3, 2.504], [64684.9, 0.004], [64685.2, 5.435], [64685.3, 3.771], [64685.6, 0.0], [64686.4, 0.086], [64687.7, 0.003], [64688.8, 0.422], [64689.0, 0.813], [64689.1, 0.002], [64689.2, 0.403], [64690.4, 0.311], [64691.1, 0.004], [64692.6, 0.022], [64692.7, 0.108], [64693.4, 0.732], [64693.9, 0.095], [64695.1, 0.069], [64695.5, 0.008], [64695.8, 0.529], [64696.6, 0.533], [64696.9, 1.079], [64698.6, 0.317], [64699.3, 0.377], [64700.2, 0.566], [64700.3, 0.223], [64700.6, 0.0], [64700.9, 0.066], [64701.2, 0.002], [64701.6, 0.389], [64701.9, 0.721], [64702.2, 10.003], [64704.1, 0.001], [64704.2, 0.581], [64705.6, 1.117], [64707.7, 0.01], [64708.0, 1.097], [64711.3, 0.168], [64712.9, 0.106], [64718.7, 0.006], [64720.3, 0.002], [64721.6, 1.476], [64722.3, 0.041], [64723.7, 0.117], [64724.2, 3.528], [64725.4, 0.078], [64725.7, 0.005], [64726.3, 0.176], [64726.9, 0.0], [64743.5, 0.063], [64746.7, 0.027], [64746.8, 6.001], [64754.7, 38.173], [64756.9, 0.027], [64770.6, 0.375], [64779.1, 0.008], [64779.2, 11.269], [64782.3, 2.885], [64841.9, 10.807], [64850.6, 0.003], [64880.7, 7.519], [64882.4, 0.218], [64887.8, 0.525], [64889.4, 0.01], [65329.0, 0.271], [65530.0, 23.535], [65682.2, 0.021], [65975.8, 0.011]]}
{"kind": "depth", "E": 1787080680529, "U": 11315372489365, "u": 11315372505363, "recv_ms": 1787080680531, "bids": [[1000.0, 35.81], [14182.1, 0.966], [14288.9, 2.618], [58213.8, 0.003], [61447.9, 0.0], [62094.8, 0.006], [63880.3, 25.612], [64035.3, 0.002], [64556.7, 0.086], [64611.7, 2.378], [64612.7, 0.009], [64642.8, 0.105], [64643.0, 2.824], [64643.4, 0.481], [64646.7, 2.886], [64647.9, 0.358], [64654.6, 0.107], [64655.6, 0.009], [64657.6, 1.43], [64657.7, 0.166], [64659.8, 0.054], [64661.2, 0.577], [64662.2, 0.002], [64662.4, 0.169], [64662.5, 0.012], [64662.6, 0.335], [64662.9, 0.141], [64663.0, 0.086], [64665.1, 0.928], [64665.3, 1.383], [64665.5, 0.001], [64665.8, 1.203], [64668.6, 0.004], [64669.1, 0.457], [64669.9, 0.256], [64671.2, 0.166], [64671.7, 0.627], [64671.9, 0.19], [64672.5, 0.006], [64672.7, 0.742], [64673.2, 0.0], [64673.6, 0.312], [64673.8, 0.629], [64674.7, 0.141], [64674.9, 0.567], [64675.0, 1.867], [64675.1, 1.404], [64675.2, 0.696], [64675.3, 0.259], [64675.4, 0.078], [64675.8, 0.233], [64676.0, 0.034], [64676.1, 0.0], [64676.5, 0.0], [64677.7, 0.024], [64677.8, 0.627], [64678.8, 0.002], [64679.5, 0.264], [64680.8, 0.084], [64681.2, 0.084], [64681.5, 0.002], [64681.8, 0.001], [64681.9, 0.0], [64682.0, 0.021], [64682.1, 8.043]], "asks": [[64682.2, 37.513], [64682.3, 0.009], [64682.4, 0.001], [64682.5, 0.04], [64682.6, 1.001], [64682.7, 2.319], [64683.0, 0.851], [64683.1, 0.001], [64683.4, 0.0], [64683.8, 0.001], [64684.2, 0.009], [64684.3, 2.511], [64684.7, 0.0], [64684.9, 0.001], [64685.0, 0.097], [64685.1, 0.003], [64685.2, 5.34], [64685.3, 3.559], [64685.7, 0.008], [64685.8, 1.891], [64686.2, 0.002], [64686.4, 0.105], [64686.5, 0.333], [64687.6, 0.494], [64688.0, 1.06], [64688.1, 0.002], [64688.2, 2.404], [64688.7, 0.976], [64688.8, 0.421], [64689.0, 0.757], [64689.2, 0.003], [64692.6, 0.014], [64693.2, 0.017], [64693.4, 0.191], [64693.9, 0.01], [64694.7, 0.012], [64694.9, 0.656], [64695.2, 0.533], [64695.5, 0.0], [64696.0, 0.023], [64696.3, 0.008], [64696.9, 0.154], [64697.0, 1.167], [64697.2, 0.275], [64697.6, 0.218], [64698.1, 0.925], [64698.3, 0.001], [64698.9, 1.387], [64699.6, 0.001], [64700.2, 0.001], [64700.7, 0.001], [64700.9, 0.064], [64701.0, 1.691], [64701.4, 0.909], [64701.5, 0.067], [64701.9, 0.18], [64703.5, 0.573], [64704.2, 0.465], [64704.8, 0.122], [64704.9, 0.105], [64706.1, 0.235], [64712.2, 2.327], [64716.6, 0.094], [64717.9, 0.005], [64719.2, 0.003], [64720.5, 0.051], [64748.4, 0.027], [64749.4, 0.0], [64800.0, 10.974], [64841.9, 0.397], [64850.5, 7.618], [64873.9, 0.005], [64880.7, 0.093], [64889.3, 11.422], [65315.9, 0.002], [65329.0, 0.271], [65494.2, 0.761], [65498.3, 0.763], [66097.3, 0.648]]}
{"kind": "depth", "E": 1787080680631, "U": 11315372505398, "u": 11315372518040, "recv_ms": 1787080680580, "bids": [[14182.1, 1.33], [14288.9, 2.254], [58213.8, 0.003], [61447.9, 0.0], [63682.1, 0.0], [63718.5, 0.0], [63741.6, 7.36], [63770.3, 3.752], [63776.6, 3.132], [64035.3, 0.0], [64611.7, 2.346], [64612.0, 0.374], [64627.7, 0.039], [64643.2, 4.798], [64662.6, 0.265], [64662.7, 0.002], [64664.1, 0.073], [64665.2, 0.62], [64667.0, 1.803], [64670.8, 0.082], [64671.7, 0.473], [64671.9, 0.344], [64672.6, 2.111], [64673.1, 0.02], [64674.8, 0.318], [64675.3, 0.173], [64675.4, 0.642], [64675.5, 0.196], [64675.6, 0.017], [64675.8, 0.233], [64675.9, 0.006], [64676.8, 0.004], [64677.0, 0.0], [64677.7, 0.001], [64677.8, 0.086], [64679.5, 0.032], [64679.6, 0.002], [64680.1, 0.234], [64680.3, 0.002], [64681.2, 0.124], [64681.3, 0.112], [64681.7, 0.085], [64682.0, 0.023], [64682.1, 8.445]], "asks": [[64682.2, 37.768], [64682.5, 0.032], [64682.9, 0.837], [64683.0, 0.0], [64684.2, 0.009], [64684.4, 1.055], [64684.8, 0.002], [64685.0, 0.002], [64685.2, 5.435], [64686.4, 0.086], [64686.5, 0.31], [64686.9, 0.302], [64687.4, 0.088], [64688.5, 0.14], [64689.0, 0.537], [64690.0, 1.308], [64690.3, 0.004], [64691.8, 0.028], [64693.2, 0.009], [64693.5, 0.202], [64694.7, 0.004], [64694.8, 0.113], [64695.1, 0.077], [64695.2, 0.213], [64696.4, 0.001], [64696.5, 0.472], [64696.6, 0.525], [64698.0, 0.497], [64698.3, 0.001], [64698.4, 1.152], [64701.2, 0.0], [64701.7, 0.038], [64702.2, 0.003], [64704.8, 0.006], [64705.8, 0.735], [64706.0, 10.005], [64721.0, 0.014], [64724.3, 0.054], [64841.9, 0.397], [64850.4, 7.579], [64850.5, 0.028], [64880.7, 0.093], [64889.2, 8.827], [64889.3, 0.391], [64955.2, 2.845], [65329.0, 0.271], [65594.6, 64.39], [65682.2, 0.001], [71150.4, 0.002]]}
{"kind": "depth", "E": 1787080680733, "U": 11315372518308, "u": 11315372526870, "recv_ms": 1787080680681, "bids": [[1000.0, 35.81], [14182.1, 1.68], [14288.9, 1.904], [51745.7, 0.0], [58213.8, 0.003], [61447.9, 0.001], [62094.8, 0.009], [63203.7, 0.002], [63388.5, 0.006], [64035.3, 0.0], [64365.5, 5.385], [64491.9, 2.288], [64540.0, 0.251], [64585.3, 2.611], [64613.7, 5.974], [64617.4, 0.033], [64620.7, 2.253], [64624.2, 0.005], [64632.7, 0.002], [64654.0, 0.004], [64655.2, 0.07], [64655.3, 0.089], [64655.9, 0.64], [64663.0, 0.016], [64665.2, 0.002], [64667.2, 0.292], [64668.8, 0.195], [64669.2, 0.198], [64670.8, 0.002], [64671.6, 0.157], [64671.9, 0.19], [64675.8, 0.233], [64675.9, 0.006], [64680.7, 0.008], [64681.3, 0.117], [64682.1, 8.214]], "asks": [[64685.1, 0.0], [64685.6, 0.003], [64686.9, 0.03], [64687.1, 0.022], [64687.3, 0.023], [64688.1, 0.274], [64690.4, 0.309], [64691.0, 0.9], [64691.8, 0.02], [64692.0, 0.146], [64693.9, 0.003], [64694.5, 0.295], [64695.2, 0.22], [64695.7, 0.058], [64696.7, 2.4], [64698.3, 0.155], [64746.9, 0.002], [64752.0, 7.163], [64753.5, 0.048], [64753.7, 0.104], [64775.6, 0.126], [64777.8, 2.224], [64800.1, 3.054], [64811.6, 0.0], [64841.8, 2.674], [64841.9, 10.807], [64842.9, 0.0], [64850.4, 0.002], [64880.7, 5.546], [64880.9, 4.728], [64889.2, 0.0], [65329.0, 0.271], [65429.5, 1.241], [65433.4, 2.724], [71150.4, 0.0]]}
{"kind": "depth", "E": 1787080680835, "U": 11315372527185, "u": 11315372541047, "recv_ms": 1787080680784, "bids": [[1000.0, 35.81], [14182.1, 2.044], [14288.9, 1.54], [58213.8, 0.003], [61447.9, 0.0], [61752.5, 0.001], [62094.8, 0.006], [63395.2, 0.068], [63694.0, 9.492], [63731.3, 0.565], [63855.7, 3.596], [64035.3, 0.0], [64047.4, 66.081], [64488.1, 0.263], [64532.4, 0.212], [64534.1, 1.423], [64549.4, 0.0], [64556.0, 0.16], [64567.5, 0.003], [64574.1, 0.002], [64599.8, 1.185], [64606.5, 0.0], [64620.7, 2.153], [64632.2, 0.503], [64638.9, 0.002], [64653.0, 0.061], [64653.7, 0.025], [64654.6, 0.097], [64664.6, 0.038], [64665.9, 0.324], [64667.2, 0.294], [64669.8, 0.004], [64671.1, 0.009], [64671.6, 0.003], [64675.5, 0.321], [64675.8, 0.108], [64675.9, 0.006]], "asks": [[64682.9, 0.002], [64684.2, 0.017], [64684.9, 0.085], [64686.6, 0.001], [64686.8, 0.003], [64688.9, 0.006], [64692.0, 0.138], [64694.9, 0.706], [64701.7, 0.005], [64706.6, 0.001], [64716.5, 3.493], [64717.8, 0.002], [64732.1, 0.027], [64738.9, 0.002], [64746.8, 6.011], [64747.5, 0.001], [64748.4, 0.017], [64764.5, 0.014], [64771.3, 0.0], [64775.6, 0.026], [64796.9, 0.002], [64803.7, 0.008], [64829.2, 1.531], [64831.7, 0.0], [64841.8, 0.429], [64841.9, 0.397], [65312.2, 65.432], [65329.0, 0.271]]}
{"kind": "depth", "E": 1787080680937, "U": 11315372541109, "u": 11315372554350, "recv_ms": 1787080680884, "bids": [[14182.1, 2.394], [14288.9, 1.19], [58213.8, 0.003], [61447.9, 0.0], [62094.8, 0.009], [63682.1, 0.02], [63711.9, 2.076], [63873.6, 0.353], [64035.3, 0.0], [64319.7, 0.493], [64348.2, 0.0], [64358.7, 0.005], [64365.5, 5.375], [64486.8, 15.507], [64490.4, 0.555], [64525.6, 5.962], [64542.6, 3.758], [64612.3, 0.004], [64640.4, 1.255], [64652.4, 0.421], [64653.0, 0.051], [64656.0, 0.893], [64656.1, 1.008], [64656.2, 1.324], [64659.4, 0.003], [64659.5, 0.001], [64659.6, 0.0], [64669.2, 0.074], [64671.4, 0.464], [64675.5, 0.196], [64675.6, 0.017], [64679.5, 0.051], [64680.3, 0.004], [64682.0, 0.036], [64682.1, 8.228]], "asks": [[64682.2, 37.769], [64684.2, 0.009], [64687.1, 0.003], [64687.3, 0.0], [64688.0, 1.01], [64692.1, 0.009], [64693.7, 0.126], [64746.2, 0.743], [64746.8, 6.001], [64833.3, 4.917], [64850.3, 7.596], [64880.7, 0.093], [64889.1, 9.073], [65329.0, 0.271], [65429.5, 2.149], [65433.6, 10.081], [65497.6, 22.139], [65627.0, 40.222], [65659.3, 19.809], [65682.2, 0.021]]}
