{"kind": "depth", "E": 1787080703989, "U": 11315374323451, "u": 11315374339392, "recv_ms": 1787080703939, "bids": [[1000.0, 35.81], [14282.1, 3.64], [14382.1, 0.768], [51745.7, 0.0], [58213.8, 0.003], [61447.9, 0.03], [62094.8, 0.695], [63682.1, 0.0], [63880.3, 22.499], [63896.8, 3.761], [64035.3, 0.101], [64358.6, 0.01], [64431.4, 0.986], [64457.2, 0.298], [64483.1, 0.002], [64494.3, 0.002], [64509.0, 0.211], [64520.2, 0.003], [64534.9, 0.0], [64587.2, 1.446], [64596.7, 0.008], [64608.6, 0.013], [64617.6, 6.473], [64619.1, 0.338], [64634.0, 0.001], [64641.9, 0.571], [64652.0, 1.744], [64659.5, 0.121], [64663.9, 0.001], [64665.7, 0.163], [64666.6, 0.973], [64667.3, 0.373], [64667.8, 0.336], [64669.6, 0.023], [64672.0, 2.516], [64672.1, 0.541], [64672.2, 0.008], [64672.4, 0.0], [64672.5, 0.007], [64674.4, 0.047], [64675.7, 0.339], [64675.8, 0.466], [64675.9, 0.178], [64676.0, 0.217], [64677.5, 0.002], [64677.9, 0.003], [64680.0, 0.011], [64680.2, 0.004], [64682.1, 24.273]], "asks": [[64682.4, 0.137], [64683.0, 0.0], [64684.5, 0.819], [64686.4, 0.002], [64686.9, 0.062], [64687.3, 0.007], [64687.5, 0.018], [64687.6, 0.221], [64687.7, 2.003], [64687.8, 2.334], [64687.9, 2.988], [64688.2, 0.391], [64690.3, 0.241], [64690.5, 0.019], [64690.6, 0.544], [64690.7, 0.184], [64691.1, 0.747], [64691.8, 0.02], [64691.9, 0.003], [64692.8, 0.457], [64693.2, 0.339], [64694.0, 0.002], [64696.0, 1.193], [64697.0, 0.018], [64698.2, 0.315], [64701.1, 0.716], [64701.4, 0.353], [64707.7, 0.132], [64710.9, 0.025], [64713.8, 0.158], [64717.3, 1.259], [64723.7, 10.115], [64750.5, 0.0], [64761.1, 0.027], [64841.4, 0.0], [64843.6, 7.47], [64844.1, 0.003], [64858.8, 0.0], [64880.2, 0.004], [64882.4, 10.503], [64884.7, 0.593], [64910.6, 0.0], [64936.5, 0.006], [64962.3, 0.006], [65005.7, 0.0], [65329.0, 0.263], [65682.2, 0.001], [65975.8, 1.52]]}
{"kind": "depth", "E": 1787080704091, "U": 11315374339563, "u": 11315374353260, "recv_ms": 1787080704042, "bids": [[14182.1, 0.126], [14282.1, 3.752], [14382.1, 0.53], [58213.8, 0.003], [61447.9, 0.031], [62094.8, 0.698], [62748.2, 0.011], [63388.5, 0.056], [64035.3, 0.101], [64358.7, 1.866], [64416.7, 0.001], [64442.6, 0.001], [64468.4, 0.001], [64486.1, 9.24], [64610.5, 0.007], [64633.8, 0.0], [64639.9, 0.746], [64650.1, 0.005], [64651.3, 0.256], [64662.2, 0.0], [64663.9, 0.117], [64668.5, 0.158], [64670.5, 0.292], [64672.2, 0.116], [64672.5, 0.006], [64674.3, 0.135], [64674.4, 0.055], [64675.2, 0.644], [64675.9, 0.178], [64676.0, 0.11], [64676.4, 0.033], [64682.1, 24.273]], "asks": [[64682.2, 3.687], [64684.0, 0.001], [64685.0, 0.011], [64685.9, 0.001], [64686.5, 0.008], [64686.6, 0.123], [64687.3, 0.091], [64687.8, 2.319], [64689.2, 0.091], [64690.3, 0.087], [64690.5, 0.011], [64690.6, 0.003], [64690.7, 0.648], [64691.1, 0.276], [64691.9, 0.474], [64692.2, 0.004], [64692.7, 0.03], [64693.2, 0.319], [64693.8, 0.208], [64694.0, 0.002], [64694.9, 0.098], [64695.1, 1.794], [64703.0, 0.004], [64703.6, 1.918], [64704.3, 0.753], [64705.4, 0.001], [64706.1, 0.235], [64706.9, 0.117], [64713.8, 0.004], [64714.0, 0.17], [64841.4, 10.41], [64843.6, 0.0], [64870.0, 0.11], [64880.2, 12.951], [64882.4, 0.218], [64895.9, 0.029], [64921.7, 0.001], [64947.6, 0.011], [65329.0, 0.263], [65602.7, 11.417], [65693.2, 0.651]]}
{"kind": "depth", "E": 1787080704193, "U": 11315374353369, "u": 11315374365149, "recv_ms": 1787080704141, "bids": [[1000.0, 35.81], [14182.1, 0.364], [14282.1, 3.626], [14382.1, 0.418], [51746.0, 0.0], [58213.8, 0.003], [61447.9, 0.03], [62094.8, 0.695], [63682.1, 0.02], [64035.3, 0.101], [64486.1, 15.484], [64610.5, 0.009], [64623.8, 0.003], [64630.5, 0.015], [64630.8, 0.233], [64633.4, 0.616], [64636.8, 1.714], [64674.2, 0.0], [64674.4, 0.047], [64675.9, 0.178], [64676.0, 0.117], [64678.3, 0.085]], "asks": [[64682.2, 3.684], [64687.8, 2.867], [64690.7, 0.1], [64691.1, 0.284], [64691.3, 0.005], [64691.9, 0.466], [64696.0, 0.293], [64697.0, 0.918], [64701.0, 1.689], [64704.9, 0.105], [64713.9, 0.144], [64714.0, 0.016], [64727.5, 0.003], [64728.3, 0.001], [64732.2, 0.029], [64759.9, 0.752], [64811.6, 0.0], [64880.2, 7.13], [65206.5, 2.141], [65329.0, 0.263], [65490.7, 2.598], [65682.2, 0.021]]}
{"kind": "depth", "E": 1787080704295, "U": 11315374365300, "u": 11315374376115, "recv_ms": 1787080704244, "bids": [[1000.0, 35.81], [14182.1, 0.602], [14282.1, 3.514], [14382.1, 0.292], [51746.0, 0.0], [58213.8, 0.003], [61447.9, 0.03], [62741.6, 4.768], [63388.5, 0.053], [63763.6, 3.285], [64035.3, 0.101], [64486.1, 9.248], [64663.2, 0.125], [64663.9, 0.001], [64666.6, 0.047], [64667.6, 0.952], [64672.2, 0.116], [64674.2, 0.008], [64674.3, 0.135], [64675.2, 0.644], [64675.7, 0.375], [64675.9, 0.448], [64676.0, 0.109], [64678.3, 0.084], [64682.1, 24.274]], "asks": [[64682.2, 4.21], [64686.5, 0.008], [64686.8, 0.003], [64686.9, 0.146], [64690.3, 0.003], [64699.1, 0.129], [64700.0, 2.677], [64700.2, 0.001], [64704.3, 0.212], [64705.4, 0.542], [64713.9, 0.144], [64880.2, 12.914], [65329.0, 0.263], [65394.4, 1.71], [65459.1, 2.302], [65555.4, 3.729], [65587.8, 19.671]]}
{"kind": "depth", "E": 1787080704397, "U": 11315374376183, "u": 11315374383307, "recv_ms": 1787080704347, "bids": [[14182.1, 0.868], [14282.1, 3.332], [14382.1, 0.208], [58213.8, 0.003], [61454.4, 0.038], [62094.8, 0.698], [63682.1, 0.0], [63864.0, 0.783], [63919.1, 2.813], [64035.3, 0.101], [64358.6, 0.009], [64358.7, 1.876], [64622.7, 0.0], [64623.1, 0.312], [64623.4, 0.818], [64623.7, 0.024], [64624.0, 0.204], [64640.6, 0.005], [64640.9, 0.002], [64641.0, 0.048], [64641.3, 0.002], [64641.6, 1.063], [64641.9, 0.539], [64643.2, 2.781], [64655.5, 0.019], [64655.6, 0.009], [64655.7, 0.17], [64655.8, 0.028], [64655.9, 0.47], [64656.0, 1.407], [64656.1, 0.0], [64656.2, 1.713], [64656.3, 0.046], [64656.5, 0.002], [64657.7, 0.163], [64658.1, 0.164], [64662.4, 0.052], [64663.1, 0.311], [64663.2, 0.118], [64667.8, 0.0], [64674.2, 0.008], [64675.1, 1.228], [64675.2, 0.644], [64675.3, 0.011], [64675.4, 0.001], [64675.5, 0.698], [64675.6, 0.001], [64675.7, 0.277], [64675.8, 0.366], [64675.9, 0.0], [64676.0, 0.001], [64676.1, 0.0], [64676.4, 0.001], [64676.7, 0.033], [64677.0, 0.0], [64677.4, 0.398], [64677.7, 0.451], [64678.3, 0.085], [64682.1, 24.273]], "asks": [[64682.2, 4.209], [64688.0, 1.012], [64688.3, 0.002], [64691.0, 0.003], [64691.1, 0.276], [64691.9, 0.003], [64692.1, 0.001], [64693.9, 0.129], [64694.0, 0.473], [64694.2, 0.002], [64694.4, 0.082], [64694.6, 0.001], [64694.9, 0.053], [64695.1, 1.274], [64695.2, 1.059], [64695.5, 0.12], [64695.6, 0.369], [64695.7, 0.008], [64695.8, 0.529], [64695.9, 0.001], [64696.0, 0.107], [64696.1, 0.252], [64696.2, 0.001], [64696.3, 0.0], [64696.4, 0.156], [64699.5, 0.0], [64704.5, 2.908], [64705.4, 0.001], [64711.8, 0.631], [64712.1, 1.247], [64712.3, 0.166], [64712.4, 0.001], [64712.8, 0.022], [64713.1, 0.155], [64713.5, 0.31], [64713.9, 0.004], [64715.1, 0.12], [64715.3, 0.315], [64715.4, 0.013], [64715.5, 0.016], [64715.6, 0.578], [64715.7, 0.025], [64715.8, 0.001], [64715.9, 0.001], [64716.0, 0.005], [64716.1, 0.073], [64729.7, 0.014], [64730.0, 0.083], [64730.2, 0.045], [64730.3, 1.238], [64730.7, 0.034], [64731.0, 0.066], [65199.7, 7.806], [65329.0, 0.263], [65490.7, 2.826], [65497.6, 18.515], [65682.2, 0.001]]}
{"kind": "depth", "E": 1787080704499, "U": 11315374383423, "u": 11315374390175, "recv_ms": 1787080704447, "bids": [[1000.0, 35.81], [14182.1, 1.232], [14282.1, 2.968], [58213.8, 0.003], [61447.9, 0.03], [62094.8, 0.695], [64035.3, 0.101], [64541.9, 3.792], [64616.2, 0.001], [64618.5, 33.636], [64640.6, 0.037], [64641.3, 0.034], [64649.2, 0.015], [64649.3, 0.002], [64649.4, 0.083], [64652.7, 0.002], [64652.8, 0.391], [64666.6, 0.384], [64675.1, 1.228], [64675.5, 0.768], [64675.6, 0.271], [64675.8, 0.436], [64676.4, 0.033], [64677.1, 0.119], [64678.3, 0.084], [64681.5, 0.086], [64682.1, 24.659]], "asks": [[64682.2, 4.23], [64686.0, 0.087], [64689.0, 0.158], [64691.3, 0.004], [64691.9, 0.011], [64694.0, 0.465], [64694.1, 3.156], [64694.8, 0.155], [64695.4, 0.086], [64695.7, 0.085], [64703.2, 0.419], [64710.9, 0.005], [64711.9, 0.491], [64712.0, 1.287], [64712.6, 0.044], [64715.0, 0.085], [64715.3, 0.392], [64719.1, 0.498], [64719.9, 10.0], [64723.7, 0.115], [64729.9, 0.121], [64730.5, 0.044], [64824.4, 5.399], [64825.6, 1.564], [64826.7, 0.029], [65005.7, 0.001], [65329.0, 0.263], [65497.6, 18.173], [65554.1, 0.0], [65975.8, 1.523]]}
{"kind": "depth", "E": 1787080704703, "U": 11315374395727, "u": 11315374402098, "recv_ms": 1787080704654, "bids": [[14182.1, 1.946], [14282.1, 2.254], [58213.8, 0.003], [61448.1, 0.002], [62094.8, 0.695], [64035.3, 0.101], [64358.7, 1.876], [64486.1, 15.507], [64614.1, 33.663], [64618.5, 0.005], [64622.6, 0.135], [64623.1, 0.344], [64651.3, 0.199], [64651.7, 0.06], [64652.0, 1.751], [64652.6, 0.005], [64662.3, 0.513], [64664.2, 0.017], [64664.9, 0.0], [64669.6, 0.024], [64670.5, 0.308], [64670.9, 0.025], [64671.5, 0.039], [64671.8, 0.002], [64671.9, 0.015], [64672.0, 2.509], [64672.2, 0.1], [64674.2, 0.549], [64674.3, 0.002], [64675.2, 0.173], [64675.3, 0.073], [64675.5, 0.868], [64675.6, 0.101], [64675.8, 0.536], [64675.9, 0.108], [64676.0, 0.171], [64678.9, 0.018], [64682.1, 24.575]], "asks": [[64684.4, 0.012], [64684.7, 0.085], [64684.9, 0.002], [64685.4, 0.397], [64687.3, 0.094], [64687.6, 0.126], [64687.9, 2.984], [64688.5, 0.088], [64689.6, 0.016], [64690.0, 0.004], [64690.7, 0.571], [64693.9, 0.129], [64694.0, 0.002], [64694.4, 0.097], [64695.1, 1.434], [64695.2, 1.15], [64695.3, 0.365], [64695.5, 0.25], [64695.6, 0.489], [64695.9, 0.092], [64698.7, 0.11], [64698.8, 0.474], [64700.0, 1.752], [64700.7, 0.926], [64702.5, 0.005], [64703.1, 0.074], [64703.3, 0.0], [64703.5, 0.567], [64703.6, 1.861], [64704.3, 0.753], [64704.4, 1.528], [64704.5, 2.367], [64705.4, 0.001], [64706.9, 0.001], [64707.3, 0.017], [64707.6, 0.748], [64713.0, 0.175], [64714.1, 0.062], [64714.2, 0.785], [64714.8, 3.63], [64714.9, 2.607], [64715.1, 0.25], [64715.2, 1.376], [64715.5, 0.107], [64715.9, 0.015], [64718.5, 0.34], [64734.0, 0.018], [64736.6, 0.001], [64760.1, 0.0], [64880.2, 6.941], [65329.0, 0.263], [65555.4, 4.337], [65879.4, 0.002]]}
{"kind": "depth", "E": 1787080704805, "U": 11315374402229, "u": 11315374408462, "recv_ms": 1787080704756, "bids": [[1000.0, 35.81], [14182.1, 2.296], [14282.1, 1.904], [58213.8, 0.003], [61447.9, 0.03], [63682.1, 0.0], [64035.3, 0.101], [64614.1, 0.01], [64616.3, 36.461], [64622.8, 0.404], [64623.4, 0.85], [64655.6, 0.079], [64656.1, 0.1], [64662.3, 0.177], [64669.6, 0.023], [64670.5, 0.292], [64672.2, 0.008], [64674.2, 0.557], [64674.3, 0.11], [64674.9, 0.427], [64675.2, 0.173], [64675.4, 0.141], [64675.6, 0.201], [64675.9, 0.1], [64676.1, 0.07], [64681.3, 0.048], [64681.8, 0.335], [64682.1, 23.257]], "asks": [[64682.2, 5.107], [64693.3, 0.002], [64695.0, 1.345], [64695.6, 0.629], [64695.8, 0.725], [64697.0, 0.018], [64698.4, 1.247], [64698.5, 0.525], [64698.7, 0.015], [64703.2, 0.399], [64709.8, 0.025], [64713.5, 0.45], [64714.6, 0.108], [64715.4, 0.209], [65206.5, 1.836], [65329.0, 0.263], [65600.7, 1.136], [65682.2, 0.001]]}
{"kind": "depth", "E": 1787080704907, "U": 11315374408562, "u": 11315374415466, "recv_ms": 1787080704856, "bids": [[1000.0, 35.81], [14182.1, 2.66], [14282.1, 1.54], [58213.8, 0.003], [62094.8, 0.698], [63783.3, 47.823], [64035.3, 0.101], [64486.1, 15.486], [64541.9, 3.792], [64616.3, 2.808], [64617.4, 0.181], [64618.4, 33.653], [64620.0, 3.025], [64623.7, 0.056], [64624.1, 0.032], [64630.6, 0.009], [64651.0, 0.057], [64651.7, 0.003], [64655.9, 0.54], [64656.2, 1.783], [64657.8, 0.311], [64659.0, 0.118], [64661.3, 1.986], [64661.9, 0.617], [64662.4, 0.045], [64663.6, 0.003], [64664.2, 0.015], [64666.9, 1.588], [64667.5, 0.149], [64667.6, 0.489], [64667.7, 0.006], [64670.3, 0.064], [64671.1, 0.008], [64671.5, 0.032], [64672.1, 0.0], [64674.1, 0.443], [64674.2, 0.541], [64674.3, 0.009], [64674.7, 0.38], [64674.9, 0.426], [64675.6, 0.302], [64675.7, 0.277], [64675.8, 0.768], [64675.9, 0.37], [64681.8, 0.251], [64682.1, 23.109]], "asks": [[64682.2, 6.954], [64684.4, 0.013], [64685.1, 2.76], [64686.1, 0.009], [64687.3, 0.087], [64688.0, 1.013], [64688.2, 0.701], [64690.7, 0.57], [64697.6, 0.123], [64698.4, 1.152], [64699.7, 0.927], [64700.7, 0.001], [64702.2, 0.566], [64703.1, 0.131], [64703.2, 0.399], [64703.5, 0.004], [64704.4, 1.471], [64704.8, 0.026], [64705.8, 0.117], [64707.6, 0.633], [64709.8, 0.005], [64716.1, 10.073], [64719.9, 0.002], [64720.5, 3.976], [64731.4, 0.014], [64734.0, 0.004], [64824.4, 5.399], [64841.4, 10.41], [64843.5, 0.0], [64880.2, 7.126], [65199.7, 8.111], [65329.0, 0.263], [65515.6, 0.0], [65878.8, 1.968], [71150.5, 0.0]]}
{"kind": "depth", "E": 1787080705009, "U": 11315374415625, "u": 11315374421076, "recv_ms": 1787080704956, "bids": [[14182.1, 3.01], [14282.1, 1.19], [51745.7, 0.0], [58213.8, 0.003], [61454.4, 0.032], [62094.8, 0.695], [63682.1, 0.02], [63770.3, 1.879], [63791.0, 5.49], [64035.3, 0.101], [64358.6, 0.008], [64358.7, 1.876], [64620.7, 6.797], [64655.6, 0.149], [64655.8, 0.098], [64658.1, 0.264], [64661.2, 5.559], [64661.3, 1.985], [64661.8, 0.0], [64664.7, 0.63], [64665.7, 0.163], [64666.4, 3.246], [64666.9, 0.662], [64672.1, 0.633], [64674.3, 0.002], [64675.6, 0.201], [64675.7, 0.412], [64675.8, 0.243], [64675.9, 0.1], [64676.0, 0.171], [64677.0, 0.168]], "asks": [[64698.2, 0.315], [64698.7, 0.94], [64699.7, 0.002], [64714.4, 3.287], [64755.9, 7.638], [65005.7, 0.002], [65329.0, 0.263], [65490.7, 3.168], [65682.2, 0.021]]}
{"kind": "depth", "E": 1787080705111, "U": 11315374421112, "u": 11315374429529, "recv_ms": 1787080705059, "bids": [[1000.0, 35.81], [14182.1, 3.374], [14282.1, 0.826], [58213.8, 0.003], [61447.9, 0.03], [62094.8, 0.698], [63388.5, 0.05], [64035.3, 0.101], [64068.2, 0.0], [64596.1, 0.0], [64603.2, 3.263], [64603.4, 0.094], [64614.1, 0.01], [64614.8, 0.0], [64616.3, 2.808], [64617.4, 0.172], [64618.4, 34.39], [64620.7, 2.153], [64636.8, 1.717], [64639.9, 0.742], [64650.4, 0.686], [64651.0, 0.0], [64655.7, 0.24], [64655.9, 0.64], [64656.0, 1.507], [64656.2, 1.883], [64656.3, 0.146], [64656.4, 0.108], [64656.5, 0.072], [64667.5, 0.141], [64667.6, 0.026], [64670.3, 0.519], [64670.5, 0.292], [64672.1, 1.082], [64672.2, 0.008], [64674.0, 2.323], [64674.2, 0.108], [64674.3, 0.018], [64675.6, 0.201], [64675.7, 0.277], [64675.8, 0.227], [64682.1, 23.289]], "asks": [[64682.2, 6.239], [64684.7, 0.001], [64684.9, 0.086], [64685.4, 0.397], [64685.8, 0.085], [64685.9, 0.003], [64686.0, 0.003], [64686.2, 0.397], [64688.2, 0.391], [64689.2, 0.006], [64690.6, 0.006], [64759.9, 0.755], [64818.4, 0.213], [64841.4, 10.41], [64841.6, 1.797], [64843.4, 0.014], [64880.2, 6.861], [64882.2, 0.017], [65329.0, 0.263], [65587.8, 19.854], [65975.8, 1.526]]}
{"kind": "depth", "E": 1787080705213, "U": 11315374429610, "u": 11315374435958, "recv_ms": 1787080705166, "bids": [[14182.1, 3.71], [14282.1, 0.476], [14582.1, 0.014], [58213.8, 0.003], [61447.9, 0.03], [62094.8, 0.695], [63682.1, 0.0], [64035.3, 0.101], [64171.4, 2.18], [64307.5, 0.013], [64309.1, 0.838], [64563.4, 11.233], [64565.7, 4.12], [64578.8, 0.156], [64580.9, 6.17], [64581.0, 0.129], [64591.4, 3.568], [64599.1, 1.804], [64603.3, 1.483], [64603.4, 0.093], [64604.4, 4.331], [64610.3, 0.027], [64610.5, 0.003], [64614.1, 34.4], [64618.4, 0.0], [64620.7, 2.253], [64630.6, 0.012], [64633.5, 4.133], [64639.7, 0.002], [64655.8, 0.168], [64657.7, 0.263], [64664.7, 0.629], [64665.8, 0.926], [64666.4, 2.32], [64668.7, 2.197], [64670.3, 0.535], [64672.1, 0.541], [64672.2, 0.093], [64674.2, 0.007], [64674.3, 0.002], [64675.6, 0.758], [64675.9, 0.37], [64682.1, 23.205]], "asks": [[64682.2, 6.322], [64687.5, 0.01], [64689.0, 0.091], [64762.8, 0.269], [64767.6, 1.916], [64775.6, 0.126], [64775.9, 1.427], [64776.2, 3.777], [64787.6, 5.901], [64792.2, 0.01], [64806.4, 11.833], [64811.6, 0.003], [64841.4, 10.41], [64841.6, 0.773], [64843.4, 0.014], [64880.2, 7.026], [64882.2, 0.017], [65329.0, 0.263], [65594.6, 63.385], [65682.2, 0.001], [72350.0, 0.031]]}
{"kind": "depth", "E": 1787080705315, "U": 11315374436032, "u": 11315374441623, "recv_ms": 1787080705263, "bids": [[14182.1, 3.724], [14282.1, 0.294], [14582.1, 0.182], [51746.0, 0.0], [58213.8, 0.003], [61448.0, 0.013], [61448.1, 0.006], [63776.6, 22.485], [64035.3, 0.101], [64358.7, 1.876], [64610.9, 0.0], [64614.1, 0.01], [64616.3, 2.808], [64618.4, 34.39], [64633.5, 0.633], [64649.7, 0.002], [64654.8, 1.984], [64662.4, 0.161], [64663.2, 0.002], [64670.3, 0.535], [64672.2, 0.549], [64674.2, 0.077], [64674.3, 0.009], [64675.6, 0.225], [64675.9, 0.1]], "asks": [[64708.1, 0.85], [64723.3, 1.241], [64723.4, 0.096], [64736.6, 0.015], [64746.0, 0.629], [64746.1, 0.003], [64746.9, 0.367], [64813.8, 0.001], [64814.7, 0.0], [65329.0, 0.263]]}
{"kind": "depth", "E": 1787080705417, "U": 11315374441766, "u": 11315374450770, "recv_ms": 1787080705366, "bids": [[1000.0, 35.81], [14182.1, 3.598], [14282.1, 0.182], [14582.1, 0.42], [51746.0, 0.0], [58213.8, 0.003], [61447.9, 0.03], [62094.8, 0.698], [63682.1, 0.02], [63808.9, 1.643], [64067.6, 5.603], [64164.6, 8.244], [64486.1, 6.96], [64524.9, 3.153], [64525.0, 0.52], [64541.9, 2.037], [64572.1, 0.003], [64578.6, 0.0], [64578.7, 0.002], [64604.4, 4.328], [64612.9, 6.001], [64616.3, 0.0], [64623.8, 0.0], [64635.5, 7.06], [64636.8, 1.714], [64651.6, 1.061], [64665.0, 0.63], [64670.3, 0.056], [64670.4, 0.238], [64671.2, 0.402], [64671.3, 0.003], [64672.2, 0.008], [64672.3, 0.622], [64674.2, 1.113], [64674.3, 0.017], [64675.6, 0.201], [64675.7, 0.412], [64675.8, 0.227]], "asks": [[64682.2, 6.321], [64698.1, 0.637], [64705.5, 2.271], [64710.2, 0.985], [64727.5, 0.0], [64736.6, 0.001], [64749.1, 0.402], [64759.9, 0.752], [64779.2, 1.269], [64792.2, 0.007], [64824.4, 0.0], [64826.4, 3.338], [64841.4, 0.0], [64843.4, 3.3], [64880.2, 0.004], [64882.2, 4.815], [65005.7, 0.001], [65329.0, 0.263], [65682.2, 0.021]]}
{"kind": "depth", "E": 1787080705519, "U": 11315374451016, "u": 11315374457345, "recv_ms": 1787080705472, "bids": [[14182.1, 3.486], [14282.1, 0.056], [14582.1, 0.658], [58213.8, 0.003], [61447.9, 0.031], [62094.8, 0.695], [63873.6, 6.742], [63880.3, 22.148], [64035.3, 0.101], [64358.6, 0.009], [64486.1, 15.507], [64524.9, 6.156], [64541.9, 3.741], [64614.1, 0.01], [64614.8, 0.0], [64616.2, 2.889], [64616.3, 34.39], [64617.4, 0.19], [64618.4, 0.0], [64652.9, 0.038], [64670.3, 0.056], [64674.2, 0.0], [64674.3, 0.55], [64675.7, 0.277], [64675.8, 0.344], [64675.9, 0.1], [64676.0, 0.634], [64681.5, 0.002], [64682.1, 23.222]], "asks": [[64682.2, 6.322], [64684.3, 0.088], [64688.9, 0.008], [64727.5, 0.003], [64734.0, 0.018], [64748.8, 4.792], [64777.8, 0.778], [64779.1, 0.002], [64782.3, 2.893], [64824.4, 5.399], [64826.4, 1.207], [64841.4, 10.41], [64843.4, 0.014], [65329.0, 0.263], [65420.1, 0.769], [65579.0, 0.08], [65975.8, 1.523]]}
{"kind": "depth", "E": 1787080705621, "U": 11315374457422, "u": 11315374463498, "recv_ms": 1787080705572, "bids": [[14182.1, 3.248], [14282.1, 0.0], [14582.1, 0.952], [58213.8, 0.003], [61447.9, 0.03], [62094.8, 0.698], [63000.4, 0.006], [63682.1, 0.0], [63919.1, 1.876], [64035.3, 0.103], [64358.7, 1.876], [64541.9, 3.172], [64629.2, 0.009], [64632.7, 0.002], [64668.7, 2.196], [64670.3, 0.057], [64674.2, 0.007], [64674.3, 0.465], [64675.6, 0.774], [64675.8, 0.227], [64675.9, 0.1], [64676.0, 0.256], [64676.1, 0.07], [64681.4, 0.086], [64681.8, 0.335], [64682.1, 23.227]], "asks": [[64684.3, 0.004], [64704.8, 0.026], [64712.0, 1.287], [64726.4, 3.505], [64734.0, 0.004], [64749.0, 6.0], [64824.4, 5.399], [64880.2, 8.649], [64882.2, 0.017], [65329.0, 0.263], [65490.7, 3.397], [65682.2, 0.001], [66169.9, 2.313]]}
{"kind": "depth", "E": 1787080705723, "U": 11315374463536, "u": 11315374470392, "recv_ms": 1787080705673, "bids": [[1000.0, 35.81], [14182.1, 2.884], [14582.1, 1.316], [58213.8, 0.003], [61447.9, 0.036], [61448.0, 0.011], [61448.1, 0.008], [64035.3, 0.101], [64486.1, 8.26], [64524.9, 6.288], [64541.9, 3.797], [64616.3, 0.0], [64618.5, 34.395], [64649.4, 0.14], [64650.4, 0.629], [64660.1, 0.928], [64661.2, 5.002], [64661.6, 0.118], [64662.4, 0.045], [64665.1, 0.928], [64665.3, 1.757], [64665.8, 0.0], [64670.3, 0.056], [64674.2, 0.0], [64674.3, 0.002], [64674.4, 0.048], [64675.6, 0.225], [64675.7, 0.277], [64675.8, 0.227], [64675.9, 0.1], [64676.1, 0.07], [64676.2, 1.024], [64681.8, 0.251]], "asks": [[64682.2, 6.322], [64697.5, 0.002], [64698.4, 2.077], [64698.7, 0.015], [64700.3, 0.303], [64701.2, 0.576], [64701.3, 0.167], [64702.1, 0.004], [64702.2, 0.067], [64703.1, 0.074], [64703.5, 0.545], [64704.3, 0.212], [64880.2, 13.225], [65329.0, 0.263], [65568.3, 0.614]]}
{"kind": "depth", "E": 1787080705825, "U": 11315374470497, "u": 11315374476529, "recv_ms": 1787080705775, "bids": [[14182.1, 2.52], [14582.1, 1.68], [51746.0, 0.0], [58213.8, 0.003], [62094.8, 0.695], [63388.5, 0.053], [63653.9, 1.098], [63682.1, 0.02], [64035.3, 0.101], [64486.1, 15.507], [64617.4, 0.172], [64670.3, 0.519], [64670.6, 0.371], [64674.2, 0.641], [64674.3, 0.026], [64674.4, 0.047], [64675.6, 0.201], [64675.9, 0.1], [64676.0, 0.171], [64676.2, 0.005], [64682.0, 0.072]], "asks": [[64880.2, 7.044], [65329.0, 0.263], [65682.2, 0.021], [71150.5, 0.0]]}
{"kind": "depth", "E": 1787080705927, "U": 11315374476617, "u": 11315374482681, "recv_ms": 1787080705875, "bids": [[14182.1, 2.17], [14582.1, 2.03], [58213.8, 0.003], [61454.4, 0.026], [62094.8, 0.698], [63912.4, 7.542], [64035.3, 0.101], [64358.7, 1.876], [64670.3, 0.519], [64674.2, 0.0], [64674.3, 0.002], [64675.6, 0.225], [64675.9, 0.1], [64676.0, 0.179], [64676.1, 0.626], [64676.2, 0.082]], "asks": [[64684.5, 0.903], [64841.4, 0.0], [64843.3, 7.255], [64880.2, 0.004], [64882.1, 10.748], [65329.0, 0.263], [65571.4, 1.641], [66180.6, 1.751]]}
{"kind": "depth", "E": 1787080706029, "U": 11315374482790, "u": 11315374488001, "recv_ms": 1787080705977, "bids": [[1000.0, 35.81], [14182.1, 1.82], [14582.1, 2.38], [51745.7, 0.0], [58213.8, 0.003], [62094.8, 0.695], [63395.1, 2.551], [63467.0, 0.0], [63538.9, 0.005], [63610.8, 2.395], [63682.1, 0.0], [63682.6, 0.0], [63754.5, 0.0], [63826.4, 0.0], [63898.3, 0.001], [63970.1, 0.234], [64035.3, 0.101], [64042.0, 2.169], [64359.3, 0.11], [64486.1, 15.507], [64620.7, 7.007], [64665.7, 0.163], [64670.3, 0.056], [64674.2, 0.007], [64674.3, 0.465], [64675.6, 0.31], [64675.7, 0.826], [64675.9, 0.1], [64676.0, 0.306], [64676.1, 0.07], [64676.2, 0.005], [64678.6, 0.003], [64680.0, 0.009], [64681.6, 0.003], [64682.0, 0.052]], "asks": [[64695.0, 0.445], [64696.0, 1.084], [64697.5, 0.042], [64698.2, 0.315], [64705.9, 0.024], [64723.3, 1.652], [64747.1, 1.11], [64841.4, 10.41], [64843.3, 0.001], [64880.2, 7.044], [64882.1, 0.005], [65005.7, 0.0], [65329.0, 0.263], [65335.8, 0.336], [65407.7, 0.229], [65479.5, 0.0], [65490.7, 3.739], [65551.4, 0.0], [65602.7, 9.134], [65623.3, 0.914], [65682.2, 0.001], [65695.2, 0.0], [65767.0, 1.149], [65838.9, 0.228], [65910.8, 0.001], [65982.7, 0.002], [68228.8, 0.0]]}
{"kind": "depth", "E": 1787080706131, "U": 11315374488175, "u": 11315374496051, "recv_ms": 1787080706081, "bids": [[14182.1, 1.456], [14582.1, 2.744], [51746.0, 0.0], [58213.8, 0.003], [61447.9, 0.036], [62094.8, 0.698], [63647.2, 5.618], [63682.1, 0.02], [63694.1, 3.6], [63880.3, 21.797], [64035.3, 0.103], [64358.6, 0.01], [64541.9, 0.247], [64596.1, 0.002], [64596.7, 0.003], [64596.8, 3.352], [64603.2, 3.265], [64610.3, 0.029], [64633.5, 0.634], [64639.7, 0.003], [64649.2, 0.013], [64649.3, 0.0], [64649.4, 0.138], [64652.7, 0.0], [64652.8, 0.389], [64666.6, 0.047], [64670.3, 0.056], [64670.5, 0.292], [64674.2, 0.007], [64674.3, 1.123], [64675.6, 0.201], [64675.7, 0.277], [64675.8, 0.371], [64675.9, 0.172], [64676.0, 0.171], [64676.1, 0.34], [64676.2, 0.005], [64682.1, 23.35]], "asks": [[64682.2, 3.909], [64684.4, 0.005], [64684.5, 0.819], [64684.9, 0.002], [64687.5, 0.002], [64688.9, 0.092], [64689.2, 0.09], [64689.6, 0.1], [64690.5, 0.003], [64690.7, 0.554], [64693.5, 0.174], [64696.6, 0.02], [64698.1, 0.019], [64710.9, 0.0], [64711.1, 1.052], [64712.0, 1.307], [64714.1, 0.216], [64714.2, 0.631], [64716.1, 10.075], [64721.4, 10.061], [64824.4, 0.0], [65329.0, 0.263], [65562.3, 15.885], [65568.3, 1.222], [65670.1, 0.0], [65682.2, 0.021]]}
{"kind": "depth", "E": 1787080706233, "U": 11315374496075, "u": 11315374507521, "recv_ms": 1787080706182, "bids": [[14182.1, 1.106], [14582.1, 3.094], [51746.0, 0.0], [58213.8, 0.003], [61447.9, 0.036], [63000.4, 0.005], [63694.1, 3.621], [63811.9, 0.629], [63880.3, 21.563], [64035.3, 0.101], [64358.7, 1.866], [64541.8, 2.928], [64617.3, 0.025], [64618.5, 34.397], [64630.7, 0.041], [64635.2, 1.376], [64641.9, 0.361], [64649.4, 0.081], [64650.7, 0.223], [64660.1, 0.371], [64661.7, 1.057], [64665.0, 0.012], [64665.1, 0.002], [64666.4, 3.246], [64667.0, 1.239], [64670.3, 0.056], [64670.6, 0.37], [64672.1, 0.007], [64672.3, 0.004], [64674.1, 0.984], [64674.2, 0.109], [64674.3, 1.006], [64675.6, 0.201], [64675.8, 0.227], [64675.9, 0.378], [64676.1, 0.07], [64677.9, 0.004], [64678.6, 0.002], [64680.0, 0.011], [64682.1, 23.407]], "asks": [[64682.2, 4.43], [64684.4, 0.013], [64684.9, 0.013], [64685.4, 0.087], [64685.8, 0.311], [64686.2, 0.313], [64686.5, 0.092], [64687.3, 0.084], [64687.5, 0.005], [64687.6, 0.134], [64690.6, 0.03], [64698.4, 1.152], [64698.9, 2.188], [64700.9, 0.134], [64701.2, 0.02], [64701.8, 0.572], [64702.2, 0.01], [64702.8, 0.408], [64703.2, 0.419], [64703.5, 0.004], [64704.3, 0.753], [64704.8, 0.006], [64705.5, 1.653], [64710.7, 0.023], [64712.0, 1.287], [64714.1, 0.062], [64714.2, 0.785], [64717.3, 1.257], [64721.4, 0.061], [64734.0, 0.018], [64760.1, 0.0], [64811.6, 0.003], [64824.4, 5.399], [64880.2, 8.648], [65329.0, 0.263], [65490.7, 4.081], [65587.8, 22.137], [65670.1, 0.021], [68228.8, 0.076]]}
{"kind": "depth", "E": 1787080706335, "U": 11315374507652, "u": 11315374513096, "recv_ms": 1787080706284, "bids": [[1000.0, 35.81], [14182.1, 0.742], [14582.1, 3.458], [51746.0, 0.0], [58213.8, 0.003], [61447.9, 0.042], [62094.8, 0.695], [63517.8, 0.026], [63808.9, 2.268], [64035.3, 0.101], [64630.7, 0.042], [64661.6, 0.002], [64663.5, 2.436], [64670.3, 0.519], [64670.4, 0.254], [64672.1, 0.633], [64674.2, 0.0], [64674.3, 0.002], [64674.4, 0.048], [64675.6, 0.209], [64675.7, 0.547], [64675.9, 0.108], [64677.9, 0.003]], "asks": [[64682.2, 4.431], [64698.9, 1.263], [64699.5, 0.925], [64701.8, 0.016], [64702.5, 0.561], [64705.8, 0.001], [64706.7, 0.117], [65329.0, 0.263], [65635.0, 0.914]]}
{"kind": "depth", "E": 1787080706437, "U": 11315374513231, "u": 11315374518699, "recv_ms": 1787080706385, "bids": [[14182.1, 0.42], [14482.1, 0.042], [14582.1, 3.738], [58213.8, 0.003], [62094.8, 0.698], [63388.5, 0.056], [63682.1, 0.0], [63919.1, 0.938], [64035.3, 0.101], [64358.6, 0.009], [64403.3, 0.054], [64486.1, 15.507], [64581.0, 10.121], [64581.1, 2.328], [64614.1, 0.01], [64614.8, 0.0], [64616.3, 34.694], [64617.4, 0.19], [64618.5, 0.007], [64620.7, 2.253], [64650.7, 0.166], [64651.5, 0.058], [64652.3, 0.068], [64666.4, 2.32], [64667.1, 0.99], [64668.0, 0.125], [64670.3, 0.519], [64670.4, 0.238], [64672.1, 0.633], [64672.2, 0.024], [64674.1, 0.443], [64674.2, 0.0], [64674.3, 0.002], [64674.4, 0.589], [64675.6, 0.201], [64675.7, 0.277], [64675.8, 0.227], [64675.9, 0.116]], "asks": [[64699.5, 0.0], [64700.4, 1.006], [64702.5, 0.005], [64702.8, 0.351], [64703.3, 0.556], [64703.4, 0.311], [64704.2, 0.522], [64704.3, 0.753], [64705.4, 0.001], [64782.2, 1.608], [64782.3, 12.885], [64841.4, 0.0], [64843.2, 8.461], [64880.2, 12.848], [65329.0, 0.263], [65682.2, 0.001], [65889.5, 1.968]]}
{"kind": "depth", "E": 1787080706539, "U": 11315374518744, "u": 11315374523197, "recv_ms": 1787080706488, "bids": [[1000.0, 35.81], [14182.1, 0.266], [14482.1, 0.238], [14582.1, 3.696], [58213.8, 0.003], [61447.9, 0.042], [61454.4, 0.02], [62094.8, 0.695], [64035.3, 0.101], [64358.7, 1.866], [64365.5, 1.342], [64367.8, 1.298], [64486.1, 9.24], [64614.1, 34.704], [64616.3, 0.0], [64617.4, 0.172], [64618.4, 0.0], [64665.3, 2.375], [64667.0, 0.903], [64670.3, 0.056], [64671.8, 0.003], [64672.1, 0.0], [64672.2, 0.008], [64672.7, 0.618], [64674.4, 0.588], [64675.6, 1.313], [64682.1, 23.45]], "asks": [[64698.5, 1.143], [64705.9, 0.642], [64714.2, 0.631], [64714.3, 1.0], [64841.4, 10.41], [64843.2, 1.207], [65005.7, 0.001], [65011.4, 0.465], [65012.4, 1.076], [65329.0, 0.263], [65465.3, 46.64], [65499.7, 2.274], [65878.8, 2.952], [71150.5, 0.0]]}
{"kind": "depth", "E": 1787080706641, "U": 11315374523429, "u": 11315374528360, "recv_ms": 1787080706589, "bids": [[1000.0, 35.81], [14182.1, 0.154], [14482.1, 0.462], [14582.1, 3.584], [58213.8, 0.003], [61447.9, 0.043], [62094.8, 0.698], [63682.1, 0.02], [63776.6, 22.673], [63912.4, 8.48], [63912.6, 37.756], [63919.1, 0.0], [64035.3, 0.101], [64486.1, 11.3], [64524.9, 6.241], [64541.8, 3.554], [64614.8, 0.018], [64664.5, 0.345], [64682.1, 23.493]], "asks": [[64682.2, 4.323], [64698.5, 0.525], [64714.1, 0.062], [64714.3, 0.846], [64714.4, 3.441], [64839.1, 0.347], [64839.2, 0.011], [65000.0, 117.711], [65329.0, 0.263], [65620.1, 21.269], [65682.2, 0.021]]}
{"kind": "depth", "E": 1787080706743, "U": 11315374528395, "u": 11315374533026, "recv_ms": 1787080706692, "bids": [[14182.1, 0.028], [14482.1, 0.714], [14582.1, 3.458], [58213.8, 0.003], [61447.9, 0.042], [63763.6, 3.519], [64035.3, 0.101], [64358.7, 4.194], [64572.1, 0.0], [64614.1, 0.01], [64614.8, 0.0], [64616.3, 34.694], [64636.8, 1.717], [64671.8, 0.002], [64675.3, 0.074]], "asks": [[64727.5, 0.003], [65005.5, 1.268], [65005.6, 3.999], [65006.1, 0.0], [65329.0, 0.263], [65424.1, 0.0]]}
{"kind": "depth", "E": 1787080706845, "U": 11315374533209, "u": 11315374537532, "recv_ms": 1787080706793, "bids": [[1000.0, 35.81], [14182.1, 0.0], [14482.1, 1.036], [14582.1, 3.164], [58213.8, 0.003], [61447.9, 0.042], [62094.8, 0.695], [63589.2, 13.006], [63682.1, 0.0], [63718.6, 9.051], [64035.3, 0.101], [64171.4, 1.87], [64358.7, 4.194], [64365.5, 1.187], [64486.1, 15.507], [64541.8, 2.901], [64682.1, 23.493]], "asks": [[64682.2, 4.323], [64824.4, 5.399], [64880.2, 8.773], [65011.4, 0.124], [65012.4, 0.922], [65329.0, 0.265], [65458.4, 15.332], [65465.3, 41.379], [65473.3, 12.596], [65587.8, 22.32], [65682.2, 0.001]]}
{"kind": "depth", "E": 1787080706947, "U": 11315374537567, "u": 11315374542085, "recv_ms": 1787080706894, "bids": [[1000.0, 35.81], [14482.1, 1.4], [14582.1, 2.8], [58213.8, 0.003], [61448.0, 0.013], [62094.8, 0.698], [63912.4, 9.418], [64035.3, 0.101], [64486.0, 9.282], [64486.1, 0.0], [64617.4, 0.19], [64671.1, 0.162], [64671.2, 0.248], [64673.6, 0.237], [64675.3, 0.073]], "asks": [[64880.2, 12.893], [65329.0, 0.263], [65458.8, 1.834], [65465.3, 40.617], [65594.6, 63.202], [65602.7, 6.851]]}
{"kind": "depth", "E": 1787080707049, "U": 11315374542233, "u": 11315374547744, "recv_ms": 1787080706995, "bids": [[14482.1, 1.764], [14582.1, 2.436], [51745.7, 0.0], [58213.8, 0.003], [62094.8, 0.695], [63568.9, 0.005], [63582.5, 9.26], [63682.1, 0.02], [63711.9, 1.935], [63809.5, 0.001], [64035.3, 0.101], [64164.6, 8.554], [64292.8, 3.124], [64358.6, 0.008], [64358.7, 4.349], [64524.8, 6.944], [64524.9, 0.007], [64541.8, 3.564], [64578.4, 2.095], [64617.6, 6.666], [64665.7, 0.163], [64670.5, 0.297], [64673.6, 0.236], [64674.9, 0.427]], "asks": [[64698.2, 0.315], [64782.2, 6.254], [64782.3, 10.019], [64824.4, 5.399], [64841.3, 10.41], [64841.4, 0.0], [65005.6, 4.153], [65329.0, 0.263], [65393.7, 0.458], [65458.4, 16.017], [65682.2, 0.021]]}
{"kind": "depth", "E": 1787080707151, "U": 11315374547781, "u": 11315374553924, "recv_ms": 1787080707100, "bids": [[1000.0, 35.81], [14482.1, 2.114], [14582.1, 2.086], [58213.8, 0.003], [61447.9, 0.048], [64035.3, 0.101], [64358.7, 4.359], [64603.2, 3.268], [64610.3, 0.031], [64620.0, 3.007], [64623.8, 0.003], [64624.2, 0.002], [64630.7, 0.043], [64633.5, 0.636], [64639.7, 0.005], [64670.5, 0.292], [64682.1, 23.492]], "asks": [[64682.2, 4.197], [64685.4, 0.003], [64686.0, 0.087], [64691.2, 1.829], [64693.5, 0.173], [64703.2, 0.399], [64704.9, 0.125], [64759.9, 0.755], [64782.1, 0.008], [64782.2, 6.246], [64844.0, 0.037], [64879.7, 0.006], [64879.8, 0.0], [65005.7, 0.002], [65329.0, 0.263], [65458.4, 21.356], [65587.8, 24.604]]}
{"kind": "depth", "E": 1787080707253, "U": 11315374554005, "u": 11315374558805, "recv_ms": 1787080707199, "bids": [[1000.0, 35.81], [14482.1, 2.464], [14582.1, 1.736], [58213.8, 0.003], [62094.8, 0.698], [63395.2, 0.062], [63467.1, 0.218], [63539.0, 0.077], [63610.8, 2.453], [63682.1, 0.0], [63682.7, 0.058], [63754.6, 8.363], [63826.5, 0.841], [63898.4, 0.072], [63970.2, 0.058], [64042.1, 0.058], [64610.3, 0.032], [64617.4, 0.189], [64657.2, 0.004], [64665.8, 0.037], [64674.9, 0.426], [64675.8, 0.362], [64680.9, 0.001]], "asks": [[64746.9, 0.366], [64811.6, 0.003], [65329.0, 0.263], [65335.9, 6.758], [65402.7, 0.764], [65407.8, 0.078], [65451.9, 7.592], [65479.6, 0.075], [65551.5, 0.058], [65623.4, 0.213], [65682.2, 0.001], [65695.3, 0.06], [65767.1, 0.061]]}
{"kind": "depth", "E": 1787080707355, "U": 11315374558905, "u": 11315374564466, "recv_ms": 1787080707303, "bids": [[14482.1, 2.828], [14582.1, 1.372], [58213.8, 0.003], [61454.4, 0.014], [62094.8, 0.695], [63388.5, 0.059], [63568.3, 4.243], [63783.3, 47.354], [63873.6, 7.093], [64035.3, 0.101], [64486.0, 0.004], [64524.8, 0.689], [64541.8, 0.003], [64665.9, 0.349], [64667.1, 0.064], [64668.2, 1.467], [64670.3, 0.056], [64675.6, 0.85], [64675.7, 0.277], [64675.8, 0.227], [64675.9, 0.116], [64676.0, 0.171], [64676.1, 0.533], [64676.6, 0.001], [64680.9, 0.0]], "asks": [[64682.2, 4.197], [64685.6, 0.084], [64689.6, 0.016], [64706.7, 0.001], [64707.6, 0.748], [64824.4, 0.0], [64841.3, 0.0], [64880.2, 0.004], [65329.0, 0.263], [65839.0, 0.07], [65910.9, 0.058], [65982.8, 2.368]]}
{"kind": "depth", "E": 1787080707457, "U": 11315374564565, "u": 11315374569846, "recv_ms": 1787080707404, "bids": [[1000.0, 35.81], [14482.1, 3.192], [14582.1, 1.008], [58213.8, 0.003], [61447.9, 0.048], [62094.8, 0.698], [63682.1, 0.02], [64035.3, 0.101], [64358.7, 4.359], [64486.0, 8.795], [64524.8, 5.772], [64541.8, 2.99], [64566.9, 0.0], [64569.7, 3.989], [64611.1, 2.251], [64613.9, 0.083], [64667.3, 1.299], [64668.2, 0.541], [64670.3, 0.056], [64672.1, 0.0], [64674.1, 0.443], [64674.2, 0.015], [64674.4, 0.047], [64675.2, 0.714], [64675.6, 0.835], [64675.7, 0.277], [64675.8, 0.227], [64675.9, 0.108], [64676.0, 0.642], [64676.1, 0.07], [64677.7, 0.656]], "asks": [[64704.3, 0.753], [64705.4, 0.001], [64753.5, 0.048], [64756.3, 0.212], [64817.8, 1.888], [64820.8, 7.292], [64824.4, 5.399], [64841.3, 10.41], [64880.2, 15.041], [65329.0, 0.263], [65682.2, 0.021], [65966.0, 0.013], [66629.7, 2.174]]}
{"kind": "depth", "E": 1787080707559, "U": 11315374569896, "u": 11315374575869, "recv_ms": 1787080707506, "bids": [[1000.0, 35.81], [14482.1, 3.542], [14582.1, 0.658], [58213.8, 0.003], [61447.9, 0.048], [61454.4, 0.008], [62094.8, 0.695], [64035.3, 0.101], [64616.3, 0.0], [64618.4, 34.694], [64661.7, 0.5], [64662.5, 0.569], [64665.3, 1.757], [64665.9, 0.359], [64670.3, 0.519], [64670.4, 0.238], [64672.1, 0.633], [64672.2, 0.024], [64672.7, 0.0], [64674.2, 0.0], [64674.7, 0.381], [64675.6, 0.201], [64675.7, 0.277], [64675.9, 0.108], [64676.0, 0.171], [64676.1, 0.078], [64676.6, 0.0]], "asks": [[64682.2, 4.197], [64687.2, 0.005], [64687.5, 0.002], [64693.0, 1.211], [64694.1, 2.847], [64701.2, 0.02], [64705.9, 0.024], [64708.5, 0.944], [65005.7, 0.001], [65329.0, 0.263], [66169.9, 2.916]]}
{"kind": "depth", "E": 1787080707661, "U": 11315374575963, "u": 11315374581080, "recv_ms": 1787080707608, "bids": [[14382.1, 0.278], [14482.1, 3.752], [14582.1, 0.378], [51746.0, 0.0], [58213.8, 0.003], [61448.0, 0.011], [61448.1, 0.01], [63682.1, 0.0], [63776.6, 23.142], [64035.3, 0.101], [64358.6, 0.009], [64617.4, 0.171], [64617.6, 1.218], [64654.6, 0.251], [64671.1, 0.008], [64674.7, 0.38], [64676.9, 0.006]], "asks": [[65329.0, 0.263], [65607.6, 2.727], [65682.2, 0.001], [66623.5, 2.174]]}
{"kind": "depth", "E": 1787080707865, "U": 11315374587618, "u": 11315374593479, "recv_ms": 1787080707814, "bids": [[1000.0, 35.81], [14382.1, 0.74], [14482.1, 3.542], [14582.1, 0.126], [58213.8, 0.003], [61447.9, 0.048], [62094.8, 0.695], [63682.1, 0.02], [63873.6, 7.444], [64035.3, 0.101], [64649.2, 0.015], [64649.3, 0.002], [64649.4, 0.083], [64652.7, 0.002], [64652.8, 0.391], [64652.9, 0.04], [64665.9, 0.349], [64670.4, 0.238], [64671.5, 0.186], [64672.2, 0.024], [64675.7, 0.412]], "asks": [[64682.2, 4.197], [64841.3, 10.41], [64841.6, 0.773], [64843.1, 0.0], [65329.0, 0.263], [65329.1, 0.101], [65555.4, 4.718], [65682.2, 0.021]]}
{"kind": "depth", "E": 1787080707967, "U": 11315374593701, "u": 11315374599089, "recv_ms": 1787080707918, "bids": [[14382.1, 0.978], [14482.1, 3.43], [14582.1, 0.0], [58213.8, 0.003], [61447.9, 0.054], [61448.0, 0.011], [61448.1, 0.012], [62094.8, 0.698], [63564.6, 2.123], [63873.6, 7.678], [64035.3, 0.101], [64604.4, 4.331], [64623.8, 0.0], [64636.8, 1.714], [64675.7, 0.277], [64675.8, 0.362]], "asks": [[64702.7, 0.557], [64703.3, 0.0], [64706.9, 0.117], [64707.6, 0.633], [64727.5, 0.003], [64759.9, 0.752], [65329.0, 0.263], [65581.3, 4.2]]}
{"kind": "depth", "E": 1787080708069, "U": 11315374599220, "u": 11315374603904, "recv_ms": 1787080708023, "bids": [[1000.0, 35.81], [14382.1, 1.342], [14482.1, 3.066], [51745.7, 0.0], [58213.8, 0.003], [63682.1, 0.0], [63912.6, 37.537], [64035.3, 0.101], [64358.7, 4.359], [64486.0, 15.511], [64581.1, 2.32], [64582.2, 3.383], [64582.3, 0.008], [64620.7, 7.05], [64665.7, 0.163], [64670.4, 0.254], [64670.5, 0.292], [64671.5, 0.186], [64671.7, 0.473], [64672.2, 0.008], [64675.8, 0.497], [64680.5, 0.002], [64681.8, 0.251]], "asks": [[64682.2, 4.192], [64698.2, 0.315], [64880.1, 7.112], [64880.2, 0.004], [65011.9, 0.248], [65297.3, 0.027], [65682.2, 0.001]]}
{"kind": "depth", "E": 1787080708171, "U": 11315374604022, "u": 11315374609295, "recv_ms": 1787080708118, "bids": [[1000.0, 35.81], [14382.1, 1.692], [14482.1, 2.716], [58213.8, 0.003], [61447.9, 0.054], [62094.8, 0.695], [63388.5, 0.062], [64035.3, 0.101], [64603.2, 3.269], [64610.3, 0.033], [64633.4, 0.617], [64633.5, 0.632], [64639.7, 0.006], [64647.7, 0.403], [64665.9, 0.359], [64670.4, 0.238], [64672.2, 0.024], [64675.8, 0.227], [64675.9, 0.378], [64680.5, 0.001], [64682.0, 0.053], [64682.1, 23.492]], "asks": [[64682.2, 4.181], [65005.7, 0.0], [65329.0, 0.263]]}
{"kind": "depth", "E": 1787080708273, "U": 11315374609441, "u": 11315374615854, "recv_ms": 1787080708224, "bids": [[14382.1, 2.042], [14482.1, 2.366], [51746.0, 0.0], [58213.8, 0.003], [61447.9, 0.054], [62094.8, 0.698], [62515.2, 0.007], [63550.2, 5.008], [63682.1, 0.02], [64035.3, 0.101], [64358.6, 0.01], [64358.7, 4.359], [64486.0, 11.578], [64524.8, 4.128], [64541.8, 1.851], [64588.6, 0.016], [64588.7, 0.0], [64670.4, 0.238], [64671.5, 0.186], [64672.2, 0.024], [64675.9, 0.378], [64682.1, 23.492]], "asks": [[64682.2, 4.179], [64696.3, 0.157], [64704.9, 0.105], [64709.8, 0.025], [64811.6, 0.003], [64880.1, 15.068], [65296.7, 2.146], [65329.0, 0.263], [65682.2, 0.021]]}
{"kind": "depth", "E": 1787080708375, "U": 11315374615879, "u": 11315374623043, "recv_ms": 1787080708324, "bids": [[1000.0, 35.81], [14382.1, 2.392], [14482.1, 2.016], [51746.0, 0.0], [58213.8, 0.003], [61447.9, 0.054], [62094.8, 0.695], [63682.1, 0.0], [63905.9, 23.088], [64035.3, 0.101], [64486.0, 4.187], [64524.8, 2.67], [64541.8, 1.22], [64569.0, 0.556], [64569.4, 1.722], [64614.1, 35.043], [64616.2, 0.001], [64618.4, 0.0]], "asks": [[64682.2, 4.179], [64691.2, 1.828], [64747.1, 0.581], [64748.8, 1.243], [64796.8, 2.47], [64797.7, 0.023], [64824.3, 4.731], [64824.4, 0.0], [65329.0, 0.263], [65562.3, 15.596], [65682.2, 0.001]]}
{"kind": "depth", "E": 1787080708477, "U": 11315374623253, "u": 11315374630906, "recv_ms": 1787080708425, "bids": [[1000.0, 35.81], [14382.1, 2.756], [14482.1, 1.652], [58213.8, 0.003], [61448.1, 0.006], [62094.8, 0.698], [64035.3, 0.101], [64486.0, 15.511], [64524.8, 6.902], [64526.5, 1.112], [64541.8, 3.548], [64568.6, 13.492], [64614.1, 0.01], [64616.2, 2.506], [64616.3, 35.884], [64620.7, 2.253], [64671.5, 0.032], [64675.9, 0.108]], "asks": [[64685.6, 0.0], [64686.0, 0.003], [64748.7, 3.577], [64796.2, 12.858], [64880.1, 6.879], [65329.0, 0.263]]}
{"kind": "depth", "E": 1787080708579, "U": 11315374630955, "u": 11315374636644, "recv_ms": 1787080708530, "bids": [[14382.1, 3.12], [14482.1, 1.288], [58213.8, 0.003], [61447.9, 0.054], [63388.5, 0.053], [63486.1, 0.0], [63682.1, 0.02], [63783.3, 47.166], [64035.3, 0.101], [64358.7, 4.349], [64526.5, 1.963], [64617.4, 0.18], [64658.9, 1.989], [64665.3, 1.757], [64670.3, 0.535], [64670.4, 0.238], [64671.4, 0.464], [64672.1, 0.541], [64672.2, 0.008], [64672.7, 0.0], [64675.6, 0.216], [64675.9, 0.108], [64676.0, 0.248], [64679.1, 0.001], [64680.8, 0.203], [64681.7, 0.001], [64682.1, 23.164]], "asks": [[64685.1, 2.76], [64686.0, 0.087], [64687.7, 2.313], [64698.5, 0.525], [64702.6, 0.483], [64708.5, 0.326], [64709.8, 0.005], [64719.2, 0.003], [64760.1, 0.001], [64793.9, 4.024], [64841.3, 0.0], [64843.0, 9.618], [64880.1, 0.0], [64881.8, 10.844], [65329.0, 0.263], [65458.4, 22.882], [65659.3, 17.24], [65682.2, 0.021], [65975.8, 1.52]]}
{"kind": "depth", "E": 1787080708681, "U": 11315374636686, "u": 11315374643756, "recv_ms": 1787080708629, "bids": [[1000.0, 35.81], [14382.1, 3.47], [14482.1, 0.938], [58213.8, 0.003], [62094.8, 0.695], [64035.3, 0.101], [64358.6, 0.009], [64616.3, 0.0], [64617.4, 0.171], [64618.4, 35.884], [64658.9, 1.991], [64670.3, 0.519], [64670.4, 0.238], [64672.1, 0.0], [64672.2, 0.549], [64675.6, 0.563], [64675.7, 0.293], [64675.9, 0.109], [64676.0, 0.171], [64682.0, 0.052], [64682.1, 23.168]], "asks": [[64719.2, 0.005], [64841.3, 10.41], [64843.0, 2.368], [64880.1, 8.716], [64881.8, 0.0], [65329.0, 0.263], [65473.3, 10.309], [65587.8, 24.787], [71150.4, 0.01]]}
{"kind": "depth", "E": 1787080708783, "U": 11315374643814, "u": 11315374651643, "recv_ms": 1787080708730, "bids": [[1000.0, 35.81], [14382.1, 3.834], [14482.1, 0.574], [58213.8, 0.003], [61447.9, 0.054], [62094.8, 0.698], [63485.5, 1.023], [63808.9, 2.894], [64035.3, 0.101], [64614.1, 35.894], [64618.4, 0.0], [64670.4, 0.254], [64672.1, 0.084], [64675.6, 0.209], [64675.7, 0.277], [64675.8, 0.227], [64675.9, 0.243], [64678.7, 0.312], [64681.2, 0.001], [64682.1, 23.275]], "asks": [[64682.2, 4.176], [64686.0, 0.003], [64687.7, 2.003], [64702.6, 0.463], [64709.8, 0.025], [64760.1, 0.0], [65005.7, 0.001], [65329.0, 0.263], [65420.1, 0.006], [71150.4, 0.008]]}
{"kind": "depth", "E": 1787080708885, "U": 11315374651823, "u": 11315374658270, "recv_ms": 1787080708832, "bids": [[14282.1, 0.112], [14382.1, 3.974], [14482.1, 0.322], [58213.8, 0.003], [61447.9, 0.054], [62094.8, 0.695], [63682.1, 0.0], [63747.2, 1.099], [63912.6, 37.318], [64035.3, 0.101], [64358.7, 4.359], [64486.0, 9.284], [64612.9, 0.001], [64635.5, 3.56], [64651.6, 0.101], [64671.0, 1.057], [64671.4, 0.31], [64672.1, 0.077], [64675.6, 0.216], [64675.7, 0.278], [64675.9, 0.108], [64681.2, 0.0], [64682.1, 23.227]], "asks": [[64686.1, 0.093], [64686.5, 0.008], [64687.2, 0.002], [64687.4, 0.007], [64689.6, 0.101], [64702.6, 0.483], [64709.8, 0.005], [64710.2, 0.024], [64726.4, 0.005], [64749.0, 0.0], [64760.1, 0.0], [64880.1, 12.915], [65329.0, 0.263], [65329.1, 0.1], [65458.4, 25.17], [65682.2, 0.001]]}
{"kind": "depth", "E": 1787080708987, "U": 11315374658445, "u": 11315374665802, "recv_ms": 1787080708934, "bids": [[1000.0, 35.81], [14282.1, 0.35], [14382.1, 3.848], [14482.1, 0.21], [58213.8, 0.003], [62094.8, 0.698], [63880.3, 21.095], [64035.3, 0.101], [64614.1, 0.01], [64618.4, 35.884], [64649.4, 0.023], [64652.9, 0.1], [64659.5, 0.121], [64661.5, 0.003], [64662.5, 0.012], [64662.7, 0.562], [64663.5, 2.32], [64664.3, 0.176], [64666.7, 0.93], [64667.3, 0.373], [64670.3, 0.527], [64670.4, 0.238], [64672.1, 0.633], [64672.2, 0.016], [64673.3, 0.014], [64674.1, 0.443], [64674.2, 0.008], [64675.2, 0.714], [64675.6, 0.201], [64675.7, 0.277], [64675.9, 0.108], [64676.1, 0.07]], "asks": [[64699.1, 0.129], [64700.2, 0.926], [64700.4, 0.081], [64702.1, 0.004], [64702.6, 0.463], [64702.7, 0.001], [64703.0, 0.56], [64703.2, 0.395], [64703.4, 0.331], [64704.3, 0.212], [64705.4, 0.542], [64706.1, 0.235], [64706.9, 0.001], [64707.1, 0.579], [64717.5, 2.532], [64722.7, 2.821], [64723.3, 1.241], [64724.8, 1.285], [64730.0, 0.023], [64736.6, 0.015], [64754.7, 36.761], [64755.9, 2.047], [64756.9, 0.001], [64841.3, 10.41], [64842.9, 0.0], [65329.0, 0.263]]}
{"kind": "depth", "E": 1787080709089, "U": 11315374666019, "u": 11315374674267, "recv_ms": 1787080709037, "bids": [[1000.0, 35.81], [14282.1, 0.588], [14382.1, 3.736], [14482.1, 0.084], [51745.7, 0.0], [51746.0, 0.0], [58213.8, 0.003], [62094.8, 0.712], [63388.5, 0.056], [63682.1, 0.02], [63694.1, 3.612], [64035.3, 0.101], [64572.8, 1.416], [64581.0, 0.129], [64582.2, 1.609], [64582.3, 0.0], [64613.3, 6.003], [64614.1, 35.894], [64618.4, 0.0], [64620.7, 2.253], [64635.9, 3.612], [64652.1, 0.999], [64665.7, 0.163], [64670.5, 0.292], [64673.3, 0.013], [64675.5, 0.869], [64675.9, 0.108]], "asks": [[64698.2, 0.315], [64710.2, 0.989], [64723.3, 1.656], [64726.4, 3.505], [64736.6, 0.001], [64749.0, 6.0], [64754.7, 0.009], [64756.9, 36.753], [64782.1, 0.0], [64782.2, 1.6], [64782.3, 0.027], [65329.0, 0.263], [65387.8, 0.001], [65670.2, 0.017], [65682.2, 0.021]]}
{"kind": "depth", "E": 1787080709191, "U": 11315374674338, "u": 11315374680680, "recv_ms": 1787080709138, "bids": [[14282.1, 0.854], [14382.1, 3.554], [14482.1, 0.0], [51746.0, 0.0], [58213.8, 0.003], [61447.9, 0.054], [61454.4, 0.004], [62094.8, 0.695], [63694.1, 3.621], [63758.7, 2.194], [64035.3, 0.101], [64129.8, 0.004], [64358.7, 4.359], [64541.8, 3.58], [64610.4, 0.018], [64614.1, 0.01], [64616.3, 36.264], [64630.3, 1.401], [64633.5, 0.634], [64636.8, 1.717], [64639.7, 0.008], [64675.5, 0.868], [64675.9, 0.378], [64678.1, 0.003]], "asks": [[64682.2, 4.192], [64690.7, 0.555], [64700.3, 0.223], [64703.2, 0.399], [64708.3, 0.244], [64759.9, 0.755], [64811.6, 0.004], [64824.3, 5.58], [64850.8, 0.002], [65329.0, 0.263], [65497.6, 17.944], [65962.9, 0.607]]}
{"kind": "depth", "E": 1787080709293, "U": 11315374680857, "u": 11315374687739, "recv_ms": 1787080709240, "bids": [[1000.0, 35.81], [14282.1, 1.204], [14382.1, 3.204], [58213.8, 0.003], [61447.9, 0.054], [62094.8, 0.698], [63682.1, 0.0], [63744.2, 21.47], [63880.3, 20.862], [64035.3, 0.101], [64358.6, 0.008], [64524.8, 5.773], [64541.8, 2.992], [64581.0, 10.121], [64581.1, 2.328], [64604.4, 4.328], [64617.4, 0.18], [64636.8, 1.717], [64675.9, 0.378], [64678.1, 0.002], [64679.8, 0.001]], "asks": [[64682.2, 4.193], [64700.2, 1.006], [64708.3, 0.164], [64713.8, 0.158], [64714.4, 3.287], [64727.5, 0.003], [64759.9, 0.752], [64782.2, 1.608], [64782.3, 10.019], [64811.6, 0.003], [65326.7, 1.014], [65329.0, 0.263], [65387.2, 3.813], [65670.2, 0.026], [65682.2, 0.001]]}
{"kind": "depth", "E": 1787080709395, "U": 11315374687747, "u": 11315374694058, "recv_ms": 1787080709342, "bids": [[1000.0, 35.81], [14282.1, 1.568], [14382.1, 2.84], [58213.8, 0.003], [61447.9, 0.054], [62094.8, 0.695], [64035.3, 0.101], [64100.0, 74.283], [64486.0, 5.941], [64524.8, 2.545], [64526.5, 1.112], [64541.8, 1.158], [64588.5, 0.008], [64588.6, 0.013], [64616.3, 0.0], [64617.4, 0.171], [64618.4, 36.264], [64649.2, 0.013], [64649.3, 0.0], [64649.4, 0.021], [64652.7, 0.0], [64652.8, 0.389], [64652.9, 0.098], [64670.8, 0.002], [64674.1, 0.446], [64675.9, 0.108], [64676.8, 0.005], [64679.8, 0.0], [64682.1, 23.227]], "asks": [[64682.2, 4.172], [64686.1, 0.009], [64713.8, 0.004], [64713.9, 0.158], [64824.3, 0.181], [64825.9, 2.101], [64841.3, 0.0], [64841.6, 1.204], [64842.9, 3.536], [64879.5, 0.006], [64879.7, 0.003], [64880.1, 0.0], [64881.7, 6.711], [65005.7, 0.002], [65329.0, 0.263]]}
{"kind": "depth", "E": 1787080709497, "U": 11315374694611, "u": 11315374721031, "recv_ms": 1787080709473, "bids": [[14282.1, 1.876], [14282.2, 0.014], [14282.4, 0.014], [14382.1, 2.504], [51746.0, 0.0], [58213.8, 0.001], [61447.9, 0.054], [61541.6, 0.001], [63388.5, 0.053], [63682.1, 0.02], [63682.2, 0.005], [63684.6, 0.002], [63685.1, 0.001], [63721.6, 0.0], [63883.9, 3.931], [64035.3, 0.105], [64035.4, 0.006], [64358.7, 4.359], [64486.0, 8.784], [64524.8, 5.747], [64541.8, 2.98], [64594.3, 0.008], [64596.8, 3.347], [64600.9, 36.607], [64603.1, 0.009], [64607.8, 0.143], [64611.9, 0.314], [64614.1, 0.01], [64614.6, 0.026], [64618.4, 0.0], [64618.5, 0.005], [64618.9, 0.022], [64619.1, 0.312], [64620.7, 2.265], [64623.5, 0.004], [64623.6, 0.001], [64631.3, 0.058], [64632.2, 0.504], [64632.4, 0.011], [64633.1, 0.025], [64633.9, 0.012], [64634.2, 0.0], [64636.0, 0.051], [64636.2, 0.002], [64637.9, 0.025], [64639.8, 0.003], [64642.2, 0.004], [64644.1, 0.014], [64645.1, 0.094], [64648.4, 0.0], [64650.9, 0.013], [64651.5, 0.001], [64651.7, 0.017], [64652.5, 0.134], [64653.7, 0.082], [64653.8, 0.004], [64653.9, 2.319], [64659.5, 0.001], [64660.9, 0.349], [64661.8, 0.0], [64662.3, 0.203], [64662.4, 0.06], [64662.5, 0.001], [64662.7, 0.005], [64662.8, 0.45], [64662.9, 0.141], [64663.3, 0.353], [64663.6, 0.001], [64663.7, 1.003], [64664.3, 0.06], [64664.4, 0.558], [64664.5, 0.009], [64664.6, 0.005], [64664.9, 0.002], [64665.2, 0.088], [64665.4, 0.0], [64665.9, 0.155], [64666.2, 0.704], [64666.6, 0.047], [64666.7, 0.004], [64666.9, 0.655], [64667.9, 0.107], [64668.0, 0.125], [64668.8, 0.262], [64668.9, 0.01], [64669.1, 1.512], [64669.2, 0.08], [64669.4, 0.006], [64669.5, 0.006], [64669.6, 0.949], [64670.0, 1.353], [64670.1, 0.378], [64670.3, 0.056], [64670.5, 0.252], [64671.1, 0.009], [64671.2, 0.081], [64671.3, 0.004], [64671.8, 0.037], [64672.1, 0.015], [64672.2, 0.009], [64672.3, 0.552], [64672.6, 0.003], [64673.0, 0.468], [64673.3, 0.128], [64673.5, 0.008], [64673.7, 0.004], [64674.0, 2.478], [64674.1, 0.446], [64674.2, 0.672], [64674.6, 0.001], [64675.0, 0.034], [64675.2, 0.174], [64675.5, 1.348], [64675.6, 0.75], [64675.7, 0.421], [64675.8, 0.325], [64675.9, 0.173], [64676.2, 0.001], [64676.5, 0.054], [64676.8, 0.004], [64677.2, 0.055], [64677.4, 0.429], [64677.5, 0.074], [64677.7, 0.485], [64677.8, 0.318], [64677.9, 0.05], [64678.2, 0.001], [64678.6, 0.048], [64678.8, 0.596], [64679.1, 0.161], [64679.8, 0.036], [64680.0, 0.009], [64680.1, 0.122], [64680.2, 0.001], [64680.5, 0.004], [64680.8, 0.32], [64680.9, 0.27], [64681.0, 0.145], [64681.8, 0.019], [64681.9, 0.027], [64682.0, 0.031], [64682.1, 7.755], [64682.2, 32.543], [64682.3, 7.852], [64682.4, 41.64]], "asks": [[64682.2, 0.0], [64682.3, 0.0], [64682.4, 0.0], [64682.5, 0.048], [64683.1, 0.0], [64683.9, 0.0], [64684.1, 1.0], [64684.3, 0.002], [64684.4, 0.003], [64684.9, 0.002], [64685.0, 1.01], [64685.1, 0.0], [64685.2, 0.0], [64685.8, 0.001], [64686.1, 0.002], [64686.2, 0.312], [64686.5, 0.0], [64686.6, 0.003], [64686.7, 0.001], [64686.9, 0.063], [64687.1, 0.01], [64687.3, 0.0], [64687.4, 0.004], [64687.6, 0.097], [64687.7, 0.0], [64687.8, 2.328], [64687.9, 2.985], [64688.0, 0.012], [64688.1, 0.886], [64688.4, 0.054], [64688.5, 0.004], [64688.7, 0.0], [64688.8, 0.004], [64688.9, 0.008], [64689.0, 0.092], [64689.1, 0.048], [64689.2, 0.006], [64689.6, 0.016], [64689.9, 0.011], [64690.0, 0.004], [64690.3, 0.003], [64690.6, 0.547], [64690.7, 0.183], [64690.9, 0.465], [64691.1, 0.36], [64691.3, 0.004], [64691.4, 0.158], [64691.8, 0.112], [64691.9, 0.003], [64692.0, 0.908], [64692.2, 0.128], [64692.3, 0.441], [64692.4, 0.496], [64692.5, 0.164], [64692.9, 0.317], [64693.0, 0.902], [64693.2, 0.009], [64693.3, 0.086], [64693.4, 0.19], [64693.8, 0.089], [64693.9, 0.314], [64694.3, 0.005], [64695.0, 0.312], [64696.0, 0.184], [64696.4, 0.156], [64697.4, 0.035], [64697.6, 0.028], [64697.9, 0.116], [64698.0, 0.176], [64698.1, 0.0], [64698.3, 0.003], [64699.1, 0.129], [64699.7, 0.02], [64700.2, 0.019], [64700.7, 0.001], [64700.8, 0.039], [64701.2, 0.0], [64701.5, 0.228], [64702.0, 0.929], [64702.2, 0.009], [64702.7, 0.098], [64702.8, 0.351], [64702.9, 0.819], [64703.0, 0.004], [64703.1, 0.072], [64703.3, 0.006], [64703.8, 0.009], [64704.2, 0.465], [64704.3, 0.206], [64704.4, 1.479], [64704.5, 2.361], [64704.7, 0.558], [64704.9, 0.055], [64705.2, 0.04], [64705.4, 0.001], [64705.9, 0.039], [64706.1, 0.791], [64706.8, 0.001], [64707.1, 0.463], [64707.7, 0.128], [64707.8, 0.013], [64708.0, 0.643], [64708.3, 0.164], [64709.1, 0.001], [64710.1, 0.118], [64710.8, 0.099], [64711.9, 0.371], [64712.0, 1.299], [64712.7, 0.07], [64715.7, 0.115], [64716.1, 0.075], [64718.6, 0.12], [64719.4, 0.001], [64719.9, 0.0], [64720.5, 3.978], [64722.7, 2.761], [64726.7, 0.0], [64727.0, 10.056], [64729.6, 0.105], [64747.0, 0.166], [64756.5, 0.054], [64760.1, 0.001], [64760.8, 0.0], [64761.1, 0.001], [64793.9, 4.027], [64824.3, 5.58], [64825.9, 0.001], [64841.3, 0.0], [64841.6, 0.773], [64842.9, 7.232], [64880.1, 15.111], [64881.7, 0.0], [65329.0, 0.267], [65600.7, 1.592], [65682.2, 0.021]]}
