{"kind": "depth", "E": 1787088292469, "U": 11315915931112, "u": 11315915935111, "recv_ms": 1787088292412, "bids": [[14385.0, 2.52], [14485.0, 1.68], [58126.5, 0.053], [63585.0, 0.096], [63745.3, 7.127], [63874.6, 9.672], [63939.2, 4.556], [64068.3, 10.937], [64262.1, 5.532], [64449.4, 0.02], [64477.5, 0.0], [64495.3, 0.251], [64508.5, 35.143]], "asks": [[64588.1, 0.033], [64608.9, 0.567], [64609.8, 1.914], [64684.0, 5.751], [64719.1, 0.019], [64778.2, 3.123], [65231.0, 11.687], [65457.0, 21.799], [65585.1, 0.02], [65743.2, 0.686]]}
{"kind": "depth", "E": 1787088292673, "U": 11315915938699, "u": 11315915942895, "recv_ms": 1787088292610, "bids": [[1000.0, 35.76], [14385.0, 3.248], [14485.0, 0.952], [58126.5, 0.053], [61355.7, 2.453], [62001.6, 2.071], [63585.0, 0.076], [63738.4, 11.59], [63874.6, 9.907], [63932.1, 2.189], [63939.2, 4.556], [64558.5, 0.061], [64559.4, 0.018], [64559.7, 0.008], [64566.9, 0.116], [64567.0, 0.033], [64567.7, 0.0], [64567.9, 0.001], [64568.9, 0.557], [64569.1, 0.0], [64572.9, 0.927], [64573.8, 0.015], [64573.9, 0.011], [64575.1, 0.561], [64585.0, 58.29]], "asks": [[64588.5, 0.088], [64590.7, 0.054], [64591.7, 0.154], [64604.7, 0.004], [64609.7, 0.49], [64610.7, 0.274], [64611.5, 0.0], [65047.3, 0.004], [65231.0, 11.687], [65585.1, 0.0]]}
{"kind": "depth", "E": 1787088292775, "U": 11315915942947, "u": 11315915946748, "recv_ms": 1787088292712, "bids": [[14385.0, 3.598], [14485.0, 0.602], [51668.0, 0.0], [58126.5, 0.053], [62001.6, 2.074], [63609.5, 6.827], [63648.5, 49.087], [63738.4, 11.042], [63777.7, 32.523], [63932.1, 1.642], [63939.2, 4.556], [64262.1, 5.522], [64508.5, 0.007], [64510.7, 35.158], [64540.6, 0.002], [64550.8, 0.0], [64555.1, 1.172], [64566.9, 0.0], [64567.7, 0.116], [64568.7, 0.061], [64572.7, 0.001], [64572.9, 0.0], [64573.6, 0.949], [64573.7, 0.698], [64574.5, 0.025], [64574.6, 0.0], [64575.1, 0.645], [64575.3, 0.133], [64576.0, 0.038], [64576.1, 0.03], [64576.3, 0.003]], "asks": [[64585.1, 6.187], [64588.0, 0.087], [64604.2, 1.78], [64605.3, 0.016], [64608.9, 0.01], [64609.8, 2.471], [64610.7, 0.158], [64611.5, 0.116], [64620.1, 0.108], [65231.0, 11.687], [65457.0, 22.408], [71043.7, 0.0]]}
{"kind": "depth", "E": 1787088292877, "U": 11315915946842, "u": 11315915950546, "recv_ms": 1787088292814, "bids": [[1000.0, 35.76], [14285.0, 0.098], [14385.0, 3.766], [14485.0, 0.336], [58126.5, 0.053], [61355.7, 2.453], [62001.6, 2.071], [63487.1, 24.398], [63585.0, 0.096], [63693.5, 1.596], [63738.4, 10.494], [63939.1, 13.929], [63939.2, 4.556], [64262.0, 1.336], [64387.4, 8.352], [64426.1, 4.774], [64443.1, 2.681], [64531.7, 0.037], [64568.2, 0.003], [64575.1, 0.026], [64576.0, 0.657], [64583.7, 0.0], [64585.0, 58.297]], "asks": [[64585.1, 6.189], [64588.0, 0.003], [64600.6, 0.004], [64724.3, 4.376], [64741.2, 8.394], [64778.2, 0.936], [64780.0, 14.429], [64908.1, 0.001], [65231.0, 11.687], [65585.1, 0.02], [65676.1, 11.711], [65869.9, 6.065]]}
{"kind": "depth", "E": 1787088292979, "U": 11315915950566, "u": 11315915954247, "recv_ms": 1787088292915, "bids": [[1000.0, 35.76], [14285.0, 0.336], [14385.0, 3.64], [14485.0, 0.224], [58126.5, 0.053], [61355.7, 2.453], [63700.2, 8.142], [63738.4, 9.946], [63745.3, 8.223], [63939.1, 14.476], [63939.2, 4.556], [64530.4, 0.252], [64530.7, 0.004], [64531.0, 0.032], [64531.4, 0.0], [64531.7, 0.0], [64547.0, 0.032], [64547.4, 0.312], [64547.7, 1.274], [64548.0, 0.468], [64548.3, 0.033], [64550.8, 0.002], [64561.9, 0.001], [64562.0, 0.073], [64562.1, 0.001], [64562.2, 0.0], [64562.3, 0.0], [64562.4, 0.003], [64562.5, 0.002], [64562.6, 0.049], [64562.7, 0.266], [64562.9, 0.088], [64563.3, 0.003], [64573.7, 0.156], [64575.1, 0.568], [64579.1, 0.095], [64579.2, 0.034], [64579.3, 0.01], [64579.4, 0.754], [64579.5, 0.309], [64579.6, 0.126], [64579.7, 0.045], [64579.8, 0.0], [64579.9, 0.002], [64580.0, 0.318], [64580.4, 0.035], [64580.7, 0.032], [64581.0, 0.137], [64581.3, 0.443], [64581.7, 0.033], [64582.2, 0.01], [64583.7, 0.005]], "asks": [[64585.1, 5.994], [64588.1, 0.033], [64590.7, 0.054], [64591.0, 0.135], [64591.3, 0.071], [64591.7, 0.154], [64592.0, 0.064], [64592.1, 0.344], [64592.3, 0.134], [64592.4, 0.002], [64592.5, 0.042], [64592.6, 0.317], [64592.7, 0.006], [64592.8, 0.003], [64592.9, 0.46], [64593.0, 0.147], [64593.1, 0.006], [64593.2, 0.0], [64593.3, 0.135], [64595.4, 0.793], [64597.8, 0.025], [64597.9, 0.661], [64598.0, 1.729], [64598.7, 0.134], [64607.4, 0.669], [64607.7, 0.051], [64608.0, 0.267], [64608.3, 0.106], [64608.7, 0.054], [64609.0, 0.094], [64609.5, 0.677], [64609.6, 0.117], [64609.7, 0.0], [64609.8, 2.352], [64609.9, 1.129], [64610.1, 0.137], [64610.2, 0.015], [64610.3, 0.049], [64610.4, 0.203], [64620.1, 0.11], [64624.0, 0.262], [64624.3, 0.085], [64624.7, 0.0], [64625.0, 0.245], [64625.3, 0.028], [64647.2, 1.751], [65046.6, 0.119], [65101.8, 9.737], [65231.0, 11.687], [65676.1, 10.19], [65683.0, 16.361], [65869.9, 3.943]]}
{"kind": "depth", "E": 1787088293081, "U": 11315915954379, "u": 11315915959270, "recv_ms": 1787088293019, "bids": [[14285.0, 0.56], [14385.0, 3.542], [14485.0, 0.098], [51668.0, 0.004], [58126.5, 0.053], [62001.6, 2.074], [63487.1, 24.79], [63583.9, 30.0], [63585.0, 0.076], [63648.5, 50.185], [63932.1, 1.095], [63939.2, 4.556], [64262.1, 5.522], [64426.2, 0.97], [64510.8, 6.363], [64573.4, 0.216], [64579.2, 0.104], [64579.3, 0.08], [64579.5, 0.509], [64579.6, 0.226], [64579.8, 0.1], [64579.9, 0.072], [64580.0, 0.418], [64585.0, 58.297]], "asks": [[64592.1, 0.522], [64592.4, 0.222], [64592.5, 0.168], [64592.6, 0.558], [64592.8, 0.493], [64592.9, 0.72], [64593.0, 0.286], [64593.1, 0.132], [64595.8, 0.311], [64609.0, 0.314], [64609.5, 0.937], [64609.6, 0.243], [64609.7, 0.24], [64609.9, 1.359], [64610.1, 0.397], [64610.2, 0.155], [64610.3, 0.175], [64647.2, 1.737], [64724.2, 1.065], [65224.4, 2.148], [65231.0, 11.689], [65585.1, 0.0], [65586.2, 28.984], [65876.8, 3.832]]}
{"kind": "depth", "E": 1787088293183, "U": 11315915959281, "u": 11315915964428, "recv_ms": 1787088293121, "bids": [[1000.0, 35.76], [14285.0, 0.826], [14385.0, 3.374], [14485.0, 0.0], [51668.0, 0.0], [58126.5, 0.002], [61355.7, 2.453], [62001.6, 2.071], [63480.1, 7.87], [63616.2, 26.556], [63745.3, 8.771], [63816.4, 8.465], [63939.2, 4.556], [64469.8, 3.876], [64469.9, 0.999], [64510.7, 0.022], [64512.9, 35.138], [64514.0, 0.057], [64544.9, 0.014], [64552.7, 0.007], [64555.1, 1.168], [64573.7, 0.698], [64575.1, 0.026], [64579.1, 0.165], [64579.3, 0.15], [64579.8, 0.2], [64582.2, 0.01], [64585.0, 58.29]], "asks": [[64585.1, 6.801], [64588.2, 0.087], [64590.7, 0.364], [64592.2, 0.002], [64592.5, 0.418], [64592.6, 0.557], [64593.1, 0.286], [64593.2, 0.133], [64597.7, 0.034], [64598.6, 0.012], [64609.7, 0.49], [64610.2, 0.309], [64610.4, 0.336], [64656.2, 0.046], [64720.2, 1.064], [64720.3, 3.871], [64908.0, 4.924], [65101.8, 9.43], [65231.0, 11.687], [65488.9, 0.002], [65683.0, 17.881], [65876.8, 3.835]]}
{"kind": "depth", "E": 1787088293285, "U": 11315915964564, "u": 11315915969010, "recv_ms": 1787088293222, "bids": [[1000.0, 35.76], [14285.0, 1.176], [14385.0, 3.024], [58126.5, 0.002], [61355.7, 2.453], [62001.6, 2.074], [63583.9, 31.099], [63680.8, 76.249], [63713.1, 30.004], [63745.3, 9.319], [63810.0, 72.276], [63939.2, 4.556], [64469.9, 1.453], [64510.8, 1.311], [64522.3, 0.845], [64530.4, 0.284], [64530.7, 0.036], [64531.0, 0.064], [64531.4, 0.032], [64531.7, 0.032], [64568.2, 0.56], [64568.9, 0.0], [64573.7, 0.698], [64575.1, 0.645], [64576.0, 0.038], [64576.1, 0.03], [64579.6, 0.326], [64579.7, 0.115], [64580.0, 0.488], [64585.0, 58.291]], "asks": [[64585.1, 6.865], [64587.5, 0.084], [64591.6, 0.018], [64591.7, 0.07], [64591.8, 0.002], [64592.2, 0.001], [64592.3, 0.281], [64592.6, 0.676], [64592.7, 0.197], [64604.1, 0.542], [64604.2, 1.238], [64605.3, 0.016], [64609.5, 1.084], [64609.8, 2.471], [64609.9, 1.549], [64624.0, 0.31], [64624.3, 0.133], [64624.7, 0.067], [64625.0, 0.303], [64625.3, 0.082], [64647.5, 0.024], [65101.8, 10.351], [65231.0, 12.223], [65586.2, 30.05], [65805.3, 4.249], [65876.8, 5.957]]}
{"kind": "depth", "E": 1787088293387, "U": 11315915969056, "u": 11315915973642, "recv_ms": 1787088293324, "bids": [[14285.0, 1.54], [14385.0, 2.66], [51668.0, 0.0], [58126.5, 0.002], [61355.7, 2.453], [61355.8, 0.006], [61355.9, 0.009], [63293.3, 7.187], [63585.0, 0.096], [63932.1, 0.548], [63939.1, 15.023], [63939.2, 4.556], [64262.1, 5.522], [64436.5, 0.0], [64443.1, 2.652], [64473.9, 2.38], [64475.7, 0.459], [64500.8, 0.029], [64526.8, 0.006], [64539.7, 0.683], [64559.7, 0.627], [64561.9, 0.071], [64562.2, 0.07], [64566.2, 0.031], [64567.0, 0.033], [64567.8, 2.597], [64568.0, 0.006], [64573.2, 0.017], [64575.1, 0.103], [64576.0, 0.58], [64585.0, 58.303]], "asks": [[64585.1, 6.645], [64587.5, 0.0], [64597.3, 0.402], [64604.7, 0.004], [64617.4, 0.204], [64643.3, 0.003], [64669.3, 0.0], [64695.9, 0.16], [64724.2, 0.003], [64724.3, 4.376], [64733.3, 0.003], [64908.0, 5.078], [65101.8, 10.658], [65231.0, 12.223], [65585.1, 0.02]]}
{"kind": "depth", "E": 1787088293591, "U": 11315915977611, "u": 11315915981356, "recv_ms": 1787088293528, "bids": [[1000.0, 35.76], [14285.0, 2.254], [14385.0, 1.946], [51668.0, 0.0], [58126.5, 0.002], [61355.7, 2.453], [62001.6, 2.074], [63583.9, 29.999], [63585.0, 0.076], [63648.5, 49.086], [63680.8, 76.061], [63842.3, 13.579], [63874.3, 6.029], [63874.6, 9.673], [63939.2, 4.556], [64397.7, 0.003], [64397.8, 11.661], [64399.9, 0.371], [64436.6, 10.4], [64443.1, 2.652], [64473.9, 10.43], [64522.3, 2.959], [64559.7, 0.008], [64562.1, 0.071], [64562.7, 0.436], [64582.2, 0.01], [64585.0, 58.296]], "asks": [[64585.1, 6.583], [64647.5, 2.485], [64695.9, 8.554], [64724.3, 5.411], [64733.2, 10.828], [64741.1, 0.024], [64771.9, 0.0], [64772.0, 12.222], [65231.0, 12.224], [65392.4, 24.417], [65585.1, 0.0]]}
{"kind": "depth", "E": 1787088293693, "U": 11315915981470, "u": 11315915985775, "recv_ms": 1787088293630, "bids": [[14285.0, 2.604], [14385.0, 1.596], [51668.0, 0.0], [58126.5, 0.002], [61355.7, 2.453], [62001.6, 2.071], [63293.3, 7.187], [63293.4, 0.0], [63365.2, 0.0], [63415.5, 4.435], [63436.9, 0.0], [63508.7, 0.007], [63580.4, 0.0], [63652.2, 0.0], [63724.0, 0.15], [63795.7, 0.003], [63867.5, 3.128], [63939.1, 15.57], [63939.2, 4.497], [64262.1, 5.532], [64387.4, 2.393], [64399.9, 2.084], [64426.1, 2.442], [64426.2, 0.0], [64443.1, 1.481], [64469.8, 3.876], [64478.8, 2.379], [64514.0, 0.057], [64520.4, 0.456], [64540.5, 0.954], [64540.7, 0.494], [64552.2, 0.003], [64552.3, 0.063], [64552.4, 0.03], [64555.6, 1.742], [64555.7, 0.005], [64555.8, 0.325], [64560.6, 0.024], [64562.5, 0.172], [64562.9, 0.258], [64564.4, 0.013], [64575.1, 0.026], [64575.5, 0.037], [64576.0, 0.038], [64576.1, 0.649], [64577.6, 0.001], [64581.3, 0.133], [64585.0, 58.139]], "asks": [[64585.1, 7.189], [64587.3, 0.086], [64587.7, 0.027], [64590.4, 0.004], [64597.9, 0.663], [64598.1, 0.18], [64608.5, 0.573], [64609.8, 1.914], [64610.1, 0.513], [64611.5, 0.0], [64623.9, 4.061], [64656.2, 0.046], [64692.3, 2.323], [64720.3, 3.871], [64724.3, 2.733], [64733.1, 0.025], [64741.1, 0.0], [64741.2, 5.69], [64780.0, 8.63], [65224.4, 1.612], [65231.0, 12.165], [65302.7, 0.007], [65374.5, 0.0], [65446.2, 0.001], [65518.0, 0.843], [65589.8, 0.0], [65661.5, 0.045], [65676.1, 8.669], [65733.3, 0.023], [65805.0, 0.001], [65805.3, 2.124], [65876.8, 5.895]]}
{"kind": "depth", "E": 1787088293795, "U": 11315915985813, "u": 11315915989355, "recv_ms": 1787088293732, "bids": [[1000.0, 35.76], [14285.0, 2.968], [14385.0, 1.232], [51668.0, 0.0], [58126.5, 0.002], [62001.6, 2.074], [63422.4, 1.37], [63583.9, 31.099], [63585.0, 0.096], [63648.5, 50.185], [63842.3, 14.518], [63939.2, 4.497], [64387.4, 8.14], [64426.1, 4.717], [64443.1, 0.0], [64565.3, 0.005], [64575.1, 0.568], [64576.0, 0.115], [64576.1, 0.03], [64585.0, 57.941]], "asks": [[64724.3, 0.003], [64741.2, 8.394], [64780.0, 14.429], [65231.0, 12.165], [65418.1, 4.197], [65585.1, 0.02], [65792.8, 5.99]]}
{"kind": "depth", "E": 1787088293897, "U": 11315915989556, "u": 11315915993578, "recv_ms": 1787088293838, "bids": [[14285.0, 3.318], [14385.0, 0.882], [58126.5, 0.002], [61355.7, 2.453], [63585.0, 0.076], [63874.6, 9.907], [63881.0, 18.575], [63939.2, 4.497], [64262.0, 1.335], [64387.4, 8.14], [64426.1, 4.717], [64443.1, 2.652], [64565.5, 0.571], [64568.2, 0.56], [64585.0, 58.146]], "asks": [[64585.1, 7.471], [64600.6, 0.004], [64724.3, 5.411], [64741.2, 10.439], [64780.0, 14.918], [64908.1, 0.0], [65231.0, 12.701], [65333.9, 1.072], [65392.4, 24.645], [65418.1, 3.663], [65585.1, 0.0], [65683.0, 19.401], [65812.2, 6.379]]}
{"kind": "depth", "E": 1787088293999, "U": 11315915993596, "u": 11315915997258, "recv_ms": 1787088293936, "bids": [[14285.0, 3.682], [14385.0, 0.518], [58126.5, 0.002], [61355.7, 2.453], [62001.6, 2.071], [63179.2, 2.26], [63777.7, 32.288], [63939.2, 4.497], [64262.0, 1.336], [64262.1, 5.522], [64426.1, 0.302], [64443.1, 0.0], [64540.5, 0.893], [64540.6, 0.063]], "asks": [[64724.3, 0.003], [64741.2, 0.013], [64908.1, 0.001], [65176.5, 0.0], [65231.0, 12.701], [65424.8, 14.346]]}
{"kind": "depth", "E": 1787088294101, "U": 11315915997306, "u": 11315916001896, "recv_ms": 1787088294037, "bids": [[1000.0, 35.76], [14185.0, 0.154], [14285.0, 3.738], [14385.0, 0.308], [58126.5, 0.002], [61355.7, 2.453], [62001.6, 2.074], [63939.2, 4.497], [64003.7, 27.372], [64426.2, 4.471], [64438.1, 2.242], [64443.1, 2.68], [64494.1, 1.48], [64515.1, 6.418], [64542.7, 1.122], [64552.7, 0.003], [64573.4, 0.216], [64575.1, 0.026], [64576.0, 0.657], [64585.0, 58.139]], "asks": [[64585.1, 7.371], [64585.8, 0.014], [64601.9, 1.826], [64604.0, 0.625], [64604.6, 5.041], [64607.4, 0.05], [64614.0, 0.006], [64614.1, 0.068], [64614.2, 0.098], [64617.0, 0.384], [64617.1, 0.033], [64617.2, 0.017], [64617.9, 0.003], [64618.0, 2.738], [64618.1, 0.002], [64620.0, 0.049], [64620.1, 0.112], [64620.2, 0.446], [64644.6, 2.32], [64656.8, 1.839], [64657.9, 6.737], [64659.8, 5.635], [64660.1, 2.495], [64662.3, 30.441], [64667.0, 0.04], [64670.3, 0.0], [64672.3, 0.01], [64675.6, 0.0], [64724.2, 1.219], [64724.3, 5.411], [64741.2, 10.439], [64771.9, 3.255], [64950.0, 25.223], [65224.4, 1.076], [65231.0, 12.701], [65340.7, 8.04], [65392.4, 24.904], [65424.8, 14.88], [65708.4, 6.08], [65876.8, 5.898]]}
{"kind": "depth", "E": 1787088294305, "U": 11315916006277, "u": 11315916011297, "recv_ms": 1787088294241, "bids": [[14185.0, 0.63], [14285.0, 3.5], [14385.0, 0.07], [51668.0, 0.0], [58126.5, 0.002], [61355.7, 2.453], [62001.6, 2.074], [63293.3, 7.181], [63648.5, 50.185], [63939.2, 4.497], [64262.1, 5.532], [64426.2, 4.481], [64443.1, 2.685], [64567.1, 0.211], [64567.7, 0.0], [64572.9, 0.927], [64573.2, 0.559], [64573.6, 0.022], [64573.7, 0.156]], "asks": [[64585.1, 7.589], [64587.3, 0.002], [64601.9, 1.136], [64604.0, 0.006], [64604.6, 0.041], [64607.3, 0.625], [64644.6, 2.334], [64724.2, 0.003], [64724.3, 5.411], [64741.2, 10.439], [65224.4, 0.54], [65231.0, 12.701], [65581.8, 1.96]]}
{"kind": "depth", "E": 1787088294407, "U": 11315916011345, "u": 11315916015534, "recv_ms": 1787088294343, "bids": [[1000.0, 35.76], [14185.0, 0.91], [14285.0, 3.29], [14385.0, 0.0], [51668.0, 0.0], [58126.5, 0.002], [61355.7, 2.454], [63519.3, 7.863], [63585.0, 0.076], [63842.3, 13.58], [63939.2, 4.497], [64003.7, 27.606], [64443.1, 0.0], [64507.4, 0.012], [64544.9, 0.018], [64555.1, 1.168], [64559.1, 0.0], [64561.6, 0.624], [64569.0, 0.627], [64585.0, 58.14]], "asks": [[64585.1, 7.591], [64587.2, 0.011], [64587.6, 0.188], [64591.3, 0.071], [64595.4, 1.412], [64602.7, 0.62], [64630.4, 0.217], [64658.0, 30.075], [64659.8, 1.32], [64660.1, 2.495], [64724.3, 0.003], [65231.0, 13.237], [65392.4, 25.476], [65579.3, 7.388], [65585.1, 0.0], [65586.2, 31.116], [65715.3, 9.788]]}
{"kind": "depth", "E": 1787088294509, "U": 11315916015600, "u": 11315916019150, "recv_ms": 1787088294447, "bids": [[14185.0, 1.274], [14285.0, 2.926], [58126.5, 0.002], [61355.7, 2.453], [62001.6, 2.071], [63616.2, 29.695], [63777.7, 32.905], [63824.4, 0.0], [63939.2, 4.497], [64426.2, 0.0], [64499.7, 0.0], [64512.6, 0.001], [64512.9, 35.088], [64515.1, 1.242], [64559.1, 0.003], [64561.6, 0.005], [64567.8, 2.443], [64569.0, 0.008]], "asks": [[64585.1, 7.597], [64595.4, 0.793], [64602.7, 0.001], [64610.6, 0.222], [64610.7, 0.004], [64623.9, 4.058], [64741.2, 0.013], [65231.0, 13.236]]}
{"kind": "depth", "E": 1787088294611, "U": 11315916019217, "u": 11315916022646, "recv_ms": 1787088294550, "bids": [[14185.0, 1.624], [14285.0, 2.576], [51668.0, 0.0], [58126.5, 0.002], [61355.7, 2.453], [62001.6, 2.074], [63585.0, 0.096], [63842.3, 14.518], [63939.2, 4.497], [64262.1, 5.532], [64387.4, 0.216], [64507.4, 0.009], [64526.8, 0.003], [64539.7, 0.686], [64568.0, 0.006], [64568.3, 0.154], [64584.8, 0.36], [64585.0, 58.139]], "asks": [[64610.4, 0.336], [64610.6, 0.068], [64617.4, 0.204], [64658.0, 0.007], [64662.3, 30.446], [64780.0, 0.02], [65231.0, 13.236], [65585.1, 0.02], [65586.2, 32.03]]}
{"kind": "depth", "E": 1787088294713, "U": 11315916022786, "u": 11315916026296, "recv_ms": 1787088294687, "bids": [[1000.0, 35.76], [14185.0, 1.974], [14285.0, 2.226], [58126.5, 0.002], [61355.7, 2.453], [61355.8, 0.008], [62001.6, 2.071], [63680.6, 4.747], [63939.2, 4.497], [64387.4, 8.35], [64426.2, 4.471], [64443.1, 2.68], [64565.5, 0.005], [64565.6, 5.041], [64565.7, 1.395], [64568.1, 0.315], [64568.3, 0.0], [64573.2, 0.559], [64573.3, 0.013], [64573.7, 0.148], [64575.1, 0.568], [64576.0, 0.038], [64576.1, 0.107], [64585.0, 58.139]], "asks": [[64587.0, 0.001], [64587.1, 0.002], [64587.2, 0.011], [64591.4, 0.048], [64608.5, 0.016], [64609.2, 3.161], [64610.1, 0.397], [64610.4, 0.336], [64610.7, 0.12], [64610.8, 0.159], [64658.0, 30.075], [64660.1, 2.491], [64662.3, 0.378], [64724.3, 5.411], [64741.2, 10.439], [64780.0, 14.632], [65231.0, 13.772]]}
{"kind": "depth", "E": 1787088294815, "U": 11315916026377, "u": 11315916030095, "recv_ms": 1787088294752, "bids": [[14185.0, 2.338], [14285.0, 1.862], [58126.5, 0.002], [61355.7, 2.454], [63585.0, 0.076], [63939.2, 4.341], [64544.9, 0.014], [64573.2, 0.559], [64575.1, 0.026], [64575.2, 0.001], [64576.0, 0.038], [64576.1, 0.649], [64585.0, 58.14]], "asks": [[64586.1, 0.031], [64587.1, 0.086], [64587.2, 0.011], [64587.7, 0.025], [64590.3, 0.017], [64592.7, 0.196], [64592.9, 0.721], [64610.4, 0.49], [64610.8, 0.005], [64666.6, 0.045], [65231.0, 13.772], [65305.7, 0.413], [65489.3, 85.707], [65495.8, 4.268], [65579.3, 6.474], [65585.1, 0.0]]}
{"kind": "depth", "E": 1787088295019, "U": 11315916034212, "u": 11315916037358, "recv_ms": 1787088294956, "bids": [[1000.0, 35.76], [14185.0, 3.052], [14285.0, 1.148], [58126.5, 0.002], [61355.7, 2.453], [61355.9, 0.005], [62001.6, 2.071], [63738.7, 13.315], [63745.4, 25.022], [63939.2, 4.4], [64262.0, 1.335], [64387.4, 2.393], [64426.2, 2.14], [64443.1, 1.48], [64567.9, 0.155], [64575.1, 0.568], [64576.0, 0.123], [64585.0, 58.14]], "asks": [[64587.6, 0.104], [64587.7, 0.109], [64610.3, 0.175], [64610.4, 0.49], [64724.3, 5.411], [64908.1, 0.0], [65231.0, 13.831], [65676.1, 7.758]]}
{"kind": "depth", "E": 1787088295223, "U": 11315916041978, "u": 11315916047334, "recv_ms": 1787088295160, "bids": [[1000.0, 35.76], [14085.0, 0.028], [14185.0, 3.71], [14285.0, 0.462], [51668.0, 0.002], [58126.5, 0.002], [61355.7, 2.453], [62001.6, 2.071], [63293.3, 7.184], [63585.0, 0.076], [63939.2, 4.556], [64262.1, 5.532], [64443.1, 2.155], [64494.1, 0.0], [64495.3, 0.251], [64495.4, 0.014], [64508.5, 35.006], [64515.1, 1.242], [64526.8, 0.006], [64545.4, 0.023], [64555.1, 1.168], [64585.0, 58.14]], "asks": [[64587.3, 0.086], [64610.3, 0.175], [64610.4, 0.49], [64610.7, 0.12], [64611.7, 3.396], [64614.1, 10.068], [64623.9, 4.061], [64636.8, 0.012], [64643.3, 0.006], [64644.6, 2.32], [64656.8, 1.839], [64658.0, 0.007], [64662.3, 30.502], [64724.2, 0.003], [64724.3, 4.046], [64741.2, 7.815], [65231.0, 13.831], [65392.4, 25.629], [65585.1, 0.0], [65611.6, 10.983], [65876.8, 5.954]]}
{"kind": "depth", "E": 1787088295325, "U": 11315916047420, "u": 11315916051963, "recv_ms": 1787088295262, "bids": [[1000.0, 35.76], [14085.0, 0.21], [14185.0, 3.71], [14285.0, 0.28], [51668.0, 0.0], [58126.5, 0.002], [61355.7, 2.453], [63680.8, 76.249], [63900.1, 0.035], [63939.2, 4.556], [64508.5, 0.007], [64512.9, 35.001], [64585.0, 58.139]], "asks": [[64585.1, 7.595], [64587.3, 0.002], [64594.5, 0.043], [64601.2, 0.433], [64610.3, 0.329], [64610.4, 0.336], [64618.0, 1.421], [64618.3, 0.003], [64644.6, 2.334], [64658.0, 30.131], [64660.1, 2.491], [64662.3, 0.378], [65231.0, 13.833], [65357.0, 6.982]]}
{"kind": "depth", "E": 1787088295427, "U": 11315916051969, "u": 11315916056676, "recv_ms": 1787088295364, "bids": [[14085.0, 0.448], [14185.0, 3.584], [14285.0, 0.168], [51668.0, 0.0], [58126.5, 0.002], [61355.7, 2.453], [62001.6, 2.074], [63293.3, 7.187], [63585.0, 0.096], [63939.2, 4.556], [64443.1, 2.178], [64543.2, 0.04], [64545.4, 0.019], [64553.2, 0.043], [64563.1, 3.074], [64570.4, 1.713], [64585.0, 58.138]], "asks": [[64585.1, 7.597], [64586.1, 0.029], [64587.8, 0.014], [64596.8, 0.62], [64598.1, 0.208], [64604.2, 1.857], [64610.3, 0.175], [64610.7, 0.274], [64611.7, 2.155], [64614.1, 0.068], [64617.2, 10.017], [64647.2, 1.765], [64659.6, 0.004], [64666.6, 0.041], [64670.4, 0.012], [64724.3, 5.411], [65231.0, 13.831], [65324.8, 0.0], [65585.1, 0.02], [65618.5, 12.41]]}
{"kind": "depth", "E": 1787088295529, "U": 11315916056828, "u": 11315916063661, "recv_ms": 1787088295466, "bids": [[1000.0, 35.76], [14085.0, 0.672], [14185.0, 3.486], [14285.0, 0.042], [58126.5, 0.002], [61355.8, 0.006], [61355.9, 0.007], [62001.6, 2.071], [63874.6, 9.673], [63906.9, 4.058], [63939.2, 4.556], [64262.1, 5.532], [64495.3, 0.251], [64510.7, 35.021], [64512.9, 0.002], [64535.9, 0.022], [64550.0, 0.259], [64558.0, 0.109], [64560.6, 0.334], [64562.8, 0.0], [64563.1, 2.455], [64566.9, 0.002], [64568.5, 0.008], [64570.3, 0.04], [64570.4, 1.094], [64570.8, 0.475], [64571.9, 0.001], [64572.2, 0.009], [64572.4, 0.0], [64573.3, 0.005], [64573.6, 0.564], [64573.7, 0.24], [64573.9, 0.165], [64575.1, 0.019], [64575.5, 0.221], [64575.9, 1.418], [64576.0, 0.046], [64577.2, 1.391], [64577.3, 0.001], [64577.9, 0.309], [64578.5, 0.014], [64578.8, 0.444], [64578.9, 1.553], [64579.5, 0.2], [64580.4, 0.189], [64581.6, 0.0], [64582.1, 0.326], [64583.3, 0.003], [64584.8, 0.047], [64585.0, 58.139]], "asks": [[64586.5, 0.114], [64587.7, 0.109], [64595.1, 0.31], [64595.9, 0.004], [64596.1, 0.067], [64596.8, 0.001], [64597.3, 0.093], [64597.8, 0.017], [64599.0, 0.007], [64600.9, 0.015], [64602.7, 0.007], [64604.0, 0.625], [64604.2, 1.238], [64605.6, 0.005], [64605.7, 0.162], [64606.7, 0.114], [64607.3, 0.006], [64607.7, 0.049], [64619.1, 0.002], [64647.2, 1.765], [64670.4, 0.021], [65231.0, 13.831]]}
{"kind": "depth", "E": 1787088295631, "U": 11315916063769, "u": 11315916071107, "recv_ms": 1787088295570, "bids": [[1000.0, 35.76], [14085.0, 0.994], [14185.0, 3.206], [14285.0, 0.0], [58126.5, 0.002], [61355.7, 2.453], [62001.6, 2.074], [63189.8, 4.739], [63585.0, 0.076], [63705.8, 3.92], [63939.2, 4.556], [64469.8, 3.876], [64478.8, 2.379], [64510.7, 0.022], [64512.6, 0.001], [64512.9, 35.001], [64514.0, 0.057], [64530.7, 0.05], [64533.3, 0.087], [64543.2, 0.036], [64544.9, 0.039], [64551.4, 0.017], [64553.2, 0.018], [64553.9, 2.619], [64555.6, 1.746], [64556.5, 0.019], [64560.6, 0.315], [64562.9, 0.256], [64563.0, 1.254], [64565.3, 0.003], [64565.6, 0.044], [64565.7, 0.098], [64566.5, 0.003], [64566.7, 0.168], [64566.9, 0.0], [64567.1, 0.095], [64567.6, 0.559], [64567.9, 0.001], [64568.0, 0.16], [64568.2, 0.003], [64571.5, 0.0], [64572.2, 0.009], [64573.2, 0.559], [64573.4, 0.224], [64573.5, 0.0], [64573.6, 0.022], [64573.7, 0.774], [64575.1, 0.019], [64575.6, 0.0], [64576.0, 0.038], [64577.3, 0.001], [64577.4, 0.45], [64578.2, 0.179], [64578.8, 0.026], [64578.9, 0.005], [64579.0, 0.094], [64579.1, 1.713], [64579.2, 0.096], [64580.5, 0.001], [64580.7, 0.116], [64581.6, 0.006], [64583.0, 0.001], [64583.9, 0.005], [64584.5, 0.05], [64584.7, 0.001], [64584.8, 0.027], [64584.9, 0.138], [64585.0, 45.07]], "asks": [[64585.1, 8.822], [64585.2, 0.092], [64585.6, 0.003], [64585.7, 0.159], [64586.0, 0.218], [64586.2, 0.086], [64587.8, 0.012], [64588.4, 0.013], [64588.5, 0.089], [64588.9, 0.086], [64589.0, 0.006], [64590.1, 0.0], [64590.5, 0.001], [64591.0, 0.051], [64591.9, 0.009], [64592.0, 1.949], [64592.1, 0.754], [64592.6, 0.677], [64592.9, 0.72], [64593.1, 0.286], [64594.0, 0.002], [64595.4, 0.813], [64596.1, 0.059], [64596.7, 0.009], [64596.8, 1.886], [64597.8, 0.009], [64597.9, 0.02], [64598.0, 0.008], [64598.1, 0.18], [64598.6, 0.12], [64598.7, 0.669], [64599.5, 2.385], [64604.0, 0.006], [64605.0, 0.928], [64606.4, 0.002], [64608.4, 0.0], [64608.9, 0.567], [64609.2, 2.604], [64609.9, 1.606], [64610.4, 0.266], [64610.6, 0.184], [64610.7, 0.158], [64612.0, 0.106], [64612.4, 10.046], [64617.2, 0.019], [64618.1, 0.072], [64618.3, 0.001], [64621.3, 0.0], [64629.6, 0.025], [64642.0, 0.003], [64647.2, 1.737], [64656.2, 0.046], [64670.4, 0.003], [64692.3, 2.323], [64720.3, 3.871], [64724.3, 3.706], [64741.2, 7.219], [65231.0, 13.831], [65353.2, 38.81], [65585.1, 0.0], [65792.8, 6.901]]}
{"kind": "depth", "E": 1787088295733, "U": 11315916071164, "u": 11315916075393, "recv_ms": 1787088295671, "bids": [[14085.0, 1.344], [14185.0, 2.856], [58126.5, 0.002], [61355.7, 2.453], [62001.6, 2.071], [63777.7, 33.14], [63939.2, 4.556], [64504.1, 35.027], [64512.9, 0.002], [64515.1, 1.242], [64567.6, 0.713], [64567.8, 2.443], [64567.9, 0.001], [64568.0, 0.006], [64570.7, 1.28], [64571.5, 0.0], [64572.2, 0.009], [64572.7, 0.526], [64573.3, 0.082], [64573.7, 0.697], [64575.3, 0.573], [64576.0, 0.038], [64577.3, 0.001], [64577.5, 0.31], [64577.9, 0.0], [64578.8, 0.026], [64578.9, 1.553], [64579.1, 0.165], [64579.6, 0.48], [64580.4, 0.035], [64582.9, 0.011], [64583.3, 0.0], [64583.9, 0.089], [64585.0, 45.069]], "asks": [[64585.1, 8.824], [64585.2, 0.008], [64601.0, 1.803], [64602.0, 1.038], [64609.7, 0.606], [64610.6, 0.068], [64614.0, 0.004], [64614.1, 0.066], [64614.2, 0.096], [64617.0, 0.382], [64617.1, 0.031], [64617.2, 0.017], [64617.9, 0.001], [64618.0, 1.419], [64618.1, 0.07], [64620.0, 0.047], [64620.1, 0.11], [64620.2, 0.444], [64724.3, 5.411], [64741.2, 10.439], [64780.0, 14.584], [65231.0, 13.831], [65353.2, 37.282]]}
{"kind": "depth", "E": 1787088295835, "U": 11315916075504, "u": 11315916079749, "recv_ms": 1787088295772, "bids": [[1000.0, 35.76], [14085.0, 1.708], [14185.0, 2.492], [51668.0, 0.0], [58126.5, 0.002], [63585.0, 0.096], [63738.7, 12.375], [63874.6, 9.907], [63939.2, 4.556], [64262.1, 5.522], [64504.1, 0.028], [64510.0, 2.016], [64512.9, 35.001], [64573.6, 0.007], [64574.6, 0.015], [64576.0, 0.032], [64577.0, 2.436], [64577.3, 1.549], [64578.8, 0.026], [64578.9, 0.005], [64579.0, 0.094], [64579.1, 0.166], [64579.2, 0.096], [64580.5, 0.0], [64581.9, 0.861], [64585.0, 45.068]], "asks": [[64592.1, 0.76], [64593.1, 0.28], [64594.6, 0.015], [64595.5, 0.016], [65191.8, 8.509], [65231.0, 13.831], [65585.1, 0.02], [65754.2, 3.911], [71043.7, 0.0]]}
{"kind": "depth", "E": 1787088295937, "U": 11315916079869, "u": 11315916084660, "recv_ms": 1787088295874, "bids": [[1000.0, 35.76], [14085.0, 2.058], [14185.0, 2.142], [58126.5, 0.002], [62001.6, 2.074], [63713.1, 31.964], [63939.2, 4.556], [64526.8, 0.006], [64531.7, 0.037], [64539.7, 0.683], [64551.4, 0.003], [64568.2, 0.003], [64583.7, 0.0]], "asks": [[64600.6, 0.004], [64617.4, 0.204], [64643.3, 0.003], [65231.0, 13.831], [65360.1, 72.393]]}
{"kind": "depth", "E": 1787088296039, "U": 11315916084948, "u": 11315916089979, "recv_ms": 1787088295976, "bids": [[14085.0, 2.422], [14185.0, 1.778], [58126.5, 0.002], [61355.7, 2.453], [62001.6, 2.071], [63293.3, 7.19], [63585.0, 0.076], [63745.4, 25.649], [63939.2, 4.556], [64127.2, 0.001], [64128.3, 0.315], [64262.0, 1.335], [64387.4, 7.984], [64426.2, 4.371], [64443.1, 2.631], [64520.4, 0.455], [64573.3, 0.005], [64573.4, 0.229], [64573.5, 0.077], [64573.8, 0.015], [64578.3, 0.004], [64579.1, 0.165], [64580.7, 0.032], [64582.5, 0.085], [64584.4, 0.245], [64584.9, 0.222], [64585.0, 45.069]], "asks": [[64585.1, 8.373], [64585.7, 0.075], [64586.2, 0.002], [64586.5, 0.03], [64586.9, 0.184], [64587.3, 0.086], [64588.4, 0.003], [64590.1, 0.084], [64598.1, 0.194], [64601.0, 0.903], [64602.0, 1.938], [64605.5, 5.001], [64623.9, 4.089], [64642.0, 0.045], [64644.6, 2.32], [64649.7, 0.365], [64658.0, 0.007], [64660.1, 32.633], [64662.3, 0.378], [64900.0, 35.56], [64908.1, 0.0], [65231.0, 13.831], [65392.4, 25.4], [65585.1, 0.0], [65592.8, 3.26]]}
{"kind": "depth", "E": 1787088296141, "U": 11315916090126, "u": 11315916095025, "recv_ms": 1787088296080, "bids": [[1000.0, 35.76], [14085.0, 2.772], [14185.0, 1.428], [51668.0, 0.0], [58126.5, 0.002], [61355.7, 2.453], [62001.6, 2.074], [63293.3, 7.187], [63745.4, 25.962], [63939.2, 4.556], [64262.0, 1.336], [64262.1, 5.522], [64443.1, 0.0], [64515.1, 6.397], [64530.7, 0.036], [64533.3, 0.073], [64535.9, 0.008], [64564.2, 0.535], [64573.4, 0.224], [64578.3, 0.001], [64585.0, 45.069]], "asks": [[64585.1, 8.371], [64586.5, 0.114], [64588.4, 0.013], [64592.3, 0.282], [64607.4, 0.054], [64630.3, 0.464], [64630.4, 0.017], [64636.8, 0.212], [64636.9, 0.0], [64659.8, 5.649], [64724.2, 1.219], [64724.3, 0.003], [64908.1, 0.001], [64914.5, 0.201], [64914.6, 0.045], [65176.9, 0.001], [65198.7, 28.211], [65231.0, 13.831]]}
{"kind": "depth", "E": 1787088296243, "U": 11315916095273, "u": 11315916101357, "recv_ms": 1787088296180, "bids": [[1000.0, 35.76], [14085.0, 3.136], [14185.0, 1.064], [51668.0, 0.0], [58126.5, 0.002], [63293.3, 7.19], [63585.0, 0.096], [63939.2, 4.556], [64220.0, 1.137], [64263.5, 0.152], [64316.5, 0.0], [64387.3, 0.0], [64426.2, 0.0], [64426.3, 0.304], [64531.7, 0.032], [64575.9, 1.418], [64583.7, 0.005], [64584.9, 0.138], [64585.0, 45.066]], "asks": [[64585.1, 8.373], [64592.3, 0.281], [64605.5, 0.001], [64607.4, 0.05], [64644.6, 2.334], [64658.0, 30.149], [64660.1, 2.491], [64724.2, 0.003], [64741.2, 0.013], [64782.7, 0.0], [64854.0, 0.0], [64922.4, 0.277], [64951.3, 0.001], [65175.9, 0.46], [65231.0, 13.831], [65585.1, 0.02]]}
{"kind": "depth", "E": 1787088296345, "U": 11315916101537, "u": 11315916106107, "recv_ms": 1787088296289, "bids": [[14085.0, 3.5], [14185.0, 0.7], [51668.0, 0.0], [58126.5, 0.002], [61355.7, 2.453], [62001.6, 2.071], [63835.7, 0.782], [63867.8, 7.035], [63939.2, 4.556], [64220.3, 0.862], [64316.8, 2.125], [64382.7, 7.453], [64387.4, 0.0], [64387.5, 8.134], [64390.1, 0.0], [64391.2, 0.015], [64426.2, 3.488], [64443.2, 2.186], [64539.7, 0.686], [64545.4, 0.019], [64552.3, 0.067], [64555.6, 1.742], [64582.5, 0.084], [64584.1, 0.001], [64585.0, 45.066]], "asks": [[64585.1, 8.374], [64588.4, 0.003], [64636.8, 0.215], [64643.3, 0.006], [64659.8, 1.32], [64724.3, 5.411], [64741.2, 10.439], [64778.2, 0.936], [64780.0, 15.457], [64780.8, 0.175], [64782.6, 0.003], [64787.6, 7.423], [64851.3, 0.483], [64950.5, 0.43], [65231.0, 13.833], [65360.1, 72.179]]}
{"kind": "depth", "E": 1787088296447, "U": 11315916106129, "u": 11315916113524, "recv_ms": 1787088296383, "bids": [[1000.0, 35.76], [14085.0, 3.738], [14185.0, 0.406], [14485.0, 0.056], [51668.0, 0.0], [58126.5, 0.002], [62001.6, 2.074], [63583.9, 30.001], [63585.0, 0.076], [63777.7, 32.789], [63939.2, 4.556], [63957.2, 0.0], [64099.8, 0.007], [64262.1, 5.532], [64545.4, 0.019], [64552.3, 0.063], [64582.2, 0.011], [64584.1, 0.0], [64584.8, 0.111]], "asks": [[64585.1, 8.377], [64588.4, 0.013], [64591.9, 0.009], [64724.3, 4.046], [64741.2, 6.322], [64778.2, 3.123], [64780.0, 8.436], [65068.4, 0.0], [65217.8, 0.0], [65231.0, 13.831], [65521.6, 49.876], [65585.1, 0.0], [65876.8, 5.951]]}
{"kind": "depth", "E": 1787088296549, "U": 11315916113677, "u": 11315916120617, "recv_ms": 1787088296486, "bids": [[1000.0, 35.76], [14085.0, 3.696], [14185.0, 0.252], [14485.0, 0.252], [58126.5, 0.002], [61355.7, 2.453], [61355.9, 0.005], [62001.6, 2.071], [63017.8, 0.0], [63480.4, 2.202], [63648.5, 49.088], [63939.2, 4.556], [64219.7, 42.597], [64220.3, 7.11], [64316.1, 33.704], [64316.8, 6.884], [64387.0, 27.598], [64555.6, 1.746], [64561.6, 0.624], [64569.0, 0.627], [64577.8, 0.016], [64580.4, 0.036], [64581.1, 0.007], [64582.2, 0.01], [64585.0, 45.066]], "asks": [[64588.4, 0.003], [64595.4, 0.813], [64601.2, 0.433], [64602.7, 0.626], [64724.3, 5.411], [64741.2, 10.439], [64778.2, 0.936], [64780.0, 14.635], [64780.6, 27.283], [64851.3, 5.453], [64851.9, 33.752], [64949.0, 10.795], [64949.2, 43.103], [65231.0, 13.831], [65328.4, 4.256], [65521.6, 50.943]]}
{"kind": "depth", "E": 1787088296855, "U": 11315916129420, "u": 11315916134599, "recv_ms": 1787088296793, "bids": [[1000.0, 35.76], [14085.0, 3.122], [14185.0, 0.0], [14485.0, 1.078], [58126.5, 0.002], [61355.7, 2.453], [62001.6, 2.071], [63377.3, 6.257], [63422.5, 13.687], [63585.0, 0.076], [63674.4, 4.077], [63864.2, 0.235], [63939.2, 4.556], [64003.7, 28.541], [64426.2, 3.444], [64443.2, 2.163], [64495.3, 0.251], [64510.7, 34.727], [64512.9, 0.002], [64567.8, 2.597], [64568.1, 0.161], [64569.0, 0.008], [64585.0, 45.064]], "asks": [[64585.1, 8.005], [64724.3, 5.411], [64741.2, 10.439], [65231.0, 13.831], [65328.5, 11.918], [65585.1, 0.0]]}
{"kind": "depth", "E": 1787088296957, "U": 11315916134703, "u": 11315916139448, "recv_ms": 1787088296893, "bids": [[14085.0, 2.758], [14485.0, 1.442], [58126.5, 0.002], [62001.6, 2.074], [63726.8, 0.001], [63939.2, 4.556], [64068.3, 10.625], [64100.1, 0.022], [64104.2, 4.32], [64262.1, 5.377], [64541.4, 0.004], [64555.6, 1.742], [64561.6, 0.005], [64567.8, 2.443], [64568.2, 0.003], [64585.0, 45.064]], "asks": [[64585.1, 8.231], [64591.9, 0.009], [64600.6, 0.004], [64659.6, 0.0], [64666.1, 0.028], [65231.0, 13.831]]}
{"kind": "depth", "E": 1787088297059, "U": 11315916139481, "u": 11315916143764, "recv_ms": 1787088296996, "bids": [[1000.0, 35.76], [14085.0, 2.408], [14485.0, 1.792], [58126.5, 0.002], [61355.7, 2.453], [62001.6, 2.071], [63585.0, 0.096], [63865.0, 1.488], [63939.2, 4.556], [64510.7, 0.022], [64512.6, 0.001], [64512.9, 34.707], [64567.6, 0.559], [64567.8, 2.597], [64573.4, 0.224], [64584.5, 0.007], [64584.8, 0.027], [64585.0, 45.064]], "asks": [[64585.1, 10.272], [64586.0, 0.302], [64590.1, 0.0], [64591.9, 0.001], [64592.1, 0.761], [64592.6, 0.676], [64596.0, 0.014], [64658.0, 0.007], [64662.3, 30.543], [65231.0, 13.831], [65367.0, 3.913], [65417.8, 26.156], [65421.6, 0.763], [65579.3, 5.408], [65585.1, 0.02], [65876.8, 5.954]]}
{"kind": "depth", "E": 1787088297161, "U": 11315916143874, "u": 11315916148025, "recv_ms": 1787088297098, "bids": [[1000.0, 35.76], [14085.0, 2.044], [14485.0, 2.156], [51668.0, 0.0], [58126.5, 0.002], [61355.8, 0.008], [62001.6, 2.074], [63630.0, 1.341], [63939.2, 4.556], [64068.3, 10.937], [64262.0, 1.336], [64262.1, 5.532], [64469.8, 0.005], [64494.1, 1.48], [64514.0, 0.011], [64515.1, 6.353], [64526.8, 0.003], [64539.7, 0.686], [64541.4, 0.0], [64555.6, 1.746], [64564.2, 0.0], [64564.9, 1.289], [64567.5, 0.217], [64567.8, 2.443], [64573.3, 0.082], [64573.5, 0.0]], "asks": [[64588.4, 0.013], [64591.9, 0.001], [64593.9, 0.046], [64596.0, 0.006], [64596.1, 0.067], [64601.0, 0.903], [64602.0, 1.038], [64611.7, 3.387], [64617.4, 0.204], [64643.3, 0.003], [64656.2, 0.0], [64656.8, 6.11], [64658.0, 30.172], [64662.3, 0.378], [64720.3, 0.0], [64724.2, 1.219], [64908.1, 0.001], [65231.0, 13.831], [65334.8, 3.82], [65475.9, 3.596]]}
{"kind": "depth", "E": 1787088297263, "U": 11315916148068, "u": 11315916152121, "recv_ms": 1787088297200, "bids": [[14085.0, 1.694], [14485.0, 2.506], [58126.5, 0.002], [63585.0, 0.076], [63803.3, 43.352], [63939.2, 4.556], [64262.1, 5.532], [64391.2, 0.016], [64469.8, 3.876], [64469.9, 1.453], [64495.3, 0.251], [64510.0, 2.016], [64512.9, 34.707], [64514.0, 0.057], [64515.1, 1.242], [64561.0, 0.015], [64567.4, 0.156], [64567.5, 0.063], [64582.0, 0.989]], "asks": [[64602.0, 1.938], [64656.2, 0.046], [64659.6, 0.004], [64666.1, 0.024], [64720.3, 3.871], [65231.0, 13.831], [65424.7, 29.991], [65482.8, 25.298], [65585.1, 0.0], [65586.2, 34.009], [65876.8, 5.951]]}
{"kind": "depth", "E": 1787088297365, "U": 11315916152219, "u": 11315916155840, "recv_ms": 1787088297302, "bids": [[1000.0, 35.76], [14085.0, 1.344], [14485.0, 2.856], [58126.5, 0.002], [61355.7, 2.453], [62001.6, 2.071], [63609.5, 5.258], [63810.0, 74.53], [63939.2, 4.556], [63954.7, 64.745], [64443.2, 1.946], [64531.7, 0.037], [64563.0, 1.254], [64564.8, 0.002], [64564.9, 0.002], [64583.7, 0.0], [64584.2, 0.048], [64585.0, 45.041]], "asks": [[64585.1, 10.274], [64593.9, 0.045], [64724.2, 0.003], [64724.3, 5.411], [65215.7, 66.751], [65231.0, 13.831], [65514.7, 11.743], [65876.8, 5.954]]}
{"kind": "depth", "E": 1787088297467, "U": 11315916155947, "u": 11315916159194, "recv_ms": 1787088297403, "bids": [[1000.0, 35.76], [14085.0, 0.98], [14485.0, 3.22], [51668.0, 0.0], [58126.5, 0.002], [61355.7, 2.454], [62001.6, 2.074], [63551.6, 14.066], [63585.0, 0.096], [63803.3, 41.787], [63939.2, 4.556], [64387.5, 7.769], [64426.2, 4.37], [64443.2, 2.638], [64522.3, 2.959], [64581.8, 0.018], [64585.0, 45.045]], "asks": [[64585.1, 10.289], [64637.1, 0.0], [64647.5, 2.508], [65231.0, 13.831], [65585.1, 0.02]]}
{"kind": "depth", "E": 1787088297671, "U": 11315916162535, "u": 11315916166611, "recv_ms": 1787088297609, "bids": [[1000.0, 35.76], [14085.0, 0.35], [14385.0, 0.084], [14485.0, 3.766], [51668.0, 0.0], [58126.5, 0.002], [61355.7, 2.453], [63585.0, 0.076], [63616.2, 31.264], [63662.6, 0.0], [63810.0, 76.095], [63939.2, 4.556], [64443.2, 2.146], [64545.4, 0.023], [64552.3, 0.063], [64581.8, 0.017], [64585.0, 45.045]], "asks": [[64588.4, 0.003], [64724.3, 5.411], [65231.0, 13.831], [65417.8, 25.24], [65521.6, 51.057], [65585.1, 0.0], [65753.6, 0.0]]}
{"kind": "depth", "E": 1787088297773, "U": 11315916166687, "u": 11315916169865, "recv_ms": 1787088297711, "bids": [[1000.0, 35.76], [14085.0, 0.224], [14385.0, 0.308], [14485.0, 3.668], [58126.5, 0.002], [62001.6, 2.074], [63791.6, 0.793], [63803.3, 40.222], [63810.0, 74.217], [63939.2, 4.556], [64387.5, 7.769], [64545.4, 0.019], [64555.6, 1.746]], "asks": [[64591.9, 0.011], [64607.2, 0.005], [64780.0, 15.137], [65231.0, 13.831], [65353.2, 35.754], [65392.4, 25.286], [65420.9, 0.0], [65469.9, 6.729]]}
{"kind": "depth", "E": 1787088297875, "U": 11315916169995, "u": 11315916173051, "recv_ms": 1787088297813, "bids": [[14085.0, 0.112], [14385.0, 0.56], [14485.0, 3.528], [58126.5, 0.002], [61355.7, 2.454], [62001.6, 2.071], [63585.0, 0.096], [63674.1, 49.955], [63939.2, 4.556], [64262.1, 5.522], [64562.5, 0.172], [64569.9, 0.027], [64585.0, 45.038]], "asks": [[64591.9, 0.001], [64596.3, 0.0], [64603.6, 0.003], [64606.0, 5.005], [64607.2, 0.001], [64623.9, 4.061], [65231.0, 13.831], [65424.7, 30.907], [65585.1, 0.02]]}
{"kind": "depth", "E": 1787088297977, "U": 11315916173098, "u": 11315916176401, "recv_ms": 1787088297913, "bids": [[1000.0, 35.76], [14085.0, 0.0], [14385.0, 0.812], [14485.0, 3.388], [58126.5, 0.002], [61355.7, 2.453], [62001.6, 2.074], [63777.7, 32.438], [63810.0, 75.782], [63939.2, 4.556], [64568.2, 0.001], [64585.0, 45.038]], "asks": [[64586.0, 0.218], [64600.6, 0.002], [65231.0, 13.831], [65389.0, 0.135]]}
{"kind": "depth", "E": 1787088298079, "U": 11315916176450, "u": 11315916181111, "recv_ms": 1787088298017, "bids": [[1000.0, 35.76], [14385.0, 1.162], [14485.0, 3.038], [58126.5, 0.002], [61355.7, 2.453], [61355.8, 0.01], [62001.6, 2.071], [63293.3, 7.032], [63585.0, 0.076], [63680.8, 78.602], [63810.0, 77.66], [63874.6, 13.033], [63939.2, 4.556], [64545.4, 0.023], [64555.6, 1.742], [64568.2, 0.003], [64573.3, 0.005], [64573.4, 0.224], [64573.8, 0.092], [64582.2, 0.02], [64584.8, 0.027], [64585.0, 45.039]], "asks": [[64586.0, 0.302], [64600.6, 0.004], [64610.1, 0.551], [64610.5, 0.0], [64656.8, 1.839], [64658.0, 0.007], [64660.1, 32.732], [64662.3, 0.378], [65231.0, 13.831], [65360.1, 73.921], [65564.1, 0.267], [65585.1, 0.0]]}
{"kind": "depth", "E": 1787088298181, "U": 11315916181198, "u": 11315916185059, "recv_ms": 1787088298120, "bids": [[14385.0, 1.526], [14485.0, 2.674], [58126.5, 0.002], [61355.7, 2.453], [61947.7, 0.0], [63238.3, 1.941], [63484.2, 0.001], [63674.1, 47.603], [63777.7, 32.524], [63939.2, 4.556], [64262.0, 1.336], [64262.1, 5.522], [64387.1, 5.033], [64426.3, 0.917], [64469.8, 0.005], [64514.0, 0.011], [64515.1, 6.353], [64564.2, 0.535], [64585.0, 45.129]], "asks": [[64586.0, 0.218], [64598.0, 0.009], [64605.4, 1.503], [64656.2, 0.0], [64656.8, 6.121], [64658.0, 30.248], [64659.6, 0.0], [64660.1, 2.491], [64666.1, 0.028], [64720.3, 0.0], [64724.2, 1.219], [64778.2, 7.18], [64908.0, 4.924], [64908.1, 0.001], [65231.0, 13.831], [65353.7, 8.254], [65643.8, 0.305], [65740.7, 10.102], [66518.1, 0.0]]}
{"kind": "depth", "E": 1787088298283, "U": 11315916185095, "u": 11315916188340, "recv_ms": 1787088298222, "bids": [[1000.0, 35.76], [14385.0, 1.876], [14485.0, 2.324], [51668.0, 0.0], [58126.5, 0.002], [60657.2, 0.0], [61355.8, 0.012], [62001.6, 2.074], [62593.0, 0.002], [63028.4, 3.419], [63585.0, 0.096], [63939.2, 4.556], [64469.8, 3.876], [64514.0, 0.057], [64531.7, 0.032], [64545.4, 0.019], [64555.6, 1.746], [64583.7, 0.005]], "asks": [[64585.1, 10.112], [64586.5, 0.03], [64609.4, 0.018], [64637.1, 0.015], [64656.2, 0.046], [64720.3, 3.871], [64741.2, 6.986], [64780.0, 11.405], [65231.0, 13.831], [65585.1, 0.02], [65805.6, 0.0], [65870.1, 0.0]]}
{"kind": "depth", "E": 1787088298385, "U": 11315916188441, "u": 11315916192957, "recv_ms": 1787088298324, "bids": [[1000.0, 35.76], [14385.0, 2.24], [14485.0, 1.96], [51668.0, 0.0], [58126.5, 0.002], [61302.5, 0.001], [61355.7, 2.453], [61355.8, 0.014], [62001.6, 2.071], [63293.3, 7.035], [63487.1, 25.734], [63583.9, 29.999], [63648.5, 49.086], [63939.2, 4.556], [64003.7, 28.307], [64526.8, 0.003], [64539.7, 0.683], [64546.2, 0.002], [64573.5, 0.077], [64573.8, 0.015], [64582.2, 0.02], [64585.0, 45.129]], "asks": [[64585.1, 10.128], [64607.1, 0.072], [64607.2, 0.001], [64608.4, 0.014], [64617.4, 0.201], [64621.3, 0.014], [64637.1, 0.0], [64643.3, 0.003], [64649.7, 0.362], [64741.2, 6.383], [64780.0, 11.405], [65231.0, 13.831], [65392.4, 25.63], [65563.5, 0.299]]}
{"kind": "depth", "E": 1787088298487, "U": 11315916192982, "u": 11315916196929, "recv_ms": 1787088298425, "bids": [[14385.0, 2.59], [14485.0, 1.61], [51668.0, 0.0], [58126.5, 0.002], [61355.7, 2.453], [62001.6, 2.074], [63583.9, 31.099], [63585.0, 0.076], [63648.5, 50.185], [63680.8, 80.954], [63777.7, 32.173], [63803.0, 12.528], [63939.2, 4.556], [64262.1, 5.522], [64549.2, 0.0], [64549.3, 0.039], [64562.8, 0.619], [64570.2, 0.626]], "asks": [[64585.1, 10.113], [64596.6, 0.646], [64603.9, 0.619], [64623.9, 3.981], [64637.1, 0.015], [64741.2, 10.439], [65231.0, 13.831], [65353.7, 9.171], [65585.1, 0.0], [65650.8, 7.257], [65812.2, 6.683], [65876.8, 6.254]]}
{"kind": "depth", "E": 1787088298589, "U": 11315916197002, "u": 11315916201002, "recv_ms": 1787088298525, "bids": [[1000.0, 35.76], [14385.0, 2.954], [14485.0, 1.246], [51668.0, 0.0], [58126.5, 0.002], [61355.7, 2.453], [61355.8, 0.016], [63293.3, 7.038], [63377.3, 7.202], [63680.8, 80.484], [63738.4, 10.73], [63939.2, 4.556], [63941.4, 0.0], [64101.7, 0.0], [64262.4, 0.004], [64387.5, 7.847], [64423.5, 3.827], [64426.2, 3.427], [64443.2, 2.154], [64522.3, 2.959], [64531.7, 0.037], [64562.8, 0.0], [64570.2, 0.007], [64576.9, 0.001], [64577.3, 0.001], [64578.5, 0.249], [64578.8, 1.574], [64583.1, 0.002], [64583.7, 0.0], [64585.0, 45.134]], "asks": [[64585.1, 10.34], [64596.6, 0.027], [64603.9, 0.0], [64647.5, 2.454], [64752.3, 0.018], [64908.0, 4.308], [64914.2, 0.0], [65076.5, 0.0], [65231.0, 13.831], [65239.2, 0.0]]}
{"kind": "depth", "E": 1787088298793, "U": 11315916205953, "u": 11315916209978, "recv_ms": 1787088298731, "bids": [[14385.0, 3.654], [14485.0, 0.546], [51668.0, 0.0], [58126.5, 0.002], [61355.7, 2.453], [62001.6, 2.074], [63680.6, 3.838], [63939.2, 4.556], [63941.4, 0.008], [64101.7, 0.005], [64262.1, 5.532], [64262.4, 0.007], [64423.5, 3.829], [64531.7, 0.032], [64555.6, 1.746], [64583.7, 0.005], [64585.0, 45.438]], "asks": [[64585.1, 10.275], [64587.3, 0.086], [64610.0, 0.929], [64610.1, 0.551], [64637.1, 0.0], [64724.3, 5.411], [64741.2, 10.439], [64780.0, 15.03], [65076.5, 0.005], [65231.0, 13.831], [65239.2, 0.008], [65431.6, 2.289]]}
{"kind": "depth", "E": 1787088298895, "U": 11315916210170, "u": 11315916214917, "recv_ms": 1787088298832, "bids": [[1000.0, 35.76], [14285.0, 0.14], [14385.0, 3.738], [14485.0, 0.322], [58126.5, 0.002], [62001.6, 2.071], [63585.0, 0.076], [63745.3, 8.223], [63939.2, 4.556], [64262.1, 5.377], [64531.7, 0.037], [64562.9, 0.26], [64580.2, 0.001], [64583.1, 0.001], [64583.7, 0.0]], "asks": [[64609.9, 1.606], [64610.1, 0.551], [64908.0, 4.924], [65231.0, 13.831], [65585.1, 0.0]]}
{"kind": "depth", "E": 1787088298997, "U": 11315916215060, "u": 11315916219297, "recv_ms": 1787088298935, "bids": [[14285.0, 0.364], [14385.0, 3.64], [14485.0, 0.196], [58126.5, 0.002], [61355.7, 2.453], [62001.6, 2.074], [63687.3, 26.888], [63939.2, 4.558], [64541.4, 0.0], [64555.6, 1.742], [64568.2, 0.001], [64582.2, 0.02]], "asks": [[64585.1, 10.23], [64600.6, 0.002], [64609.8, 1.914], [64610.1, 0.551], [64741.2, 6.332], [64780.0, 11.274], [65231.0, 13.831], [65553.9, 30.306]]}
{"kind": "depth", "E": 1787088299099, "U": 11315916219331, "u": 11315916222738, "recv_ms": 1787088299037, "bids": [[14285.0, 0.616], [14385.0, 3.5], [14485.0, 0.084], [51668.0, 0.0], [58126.5, 0.002], [61355.7, 2.453], [63293.3, 7.038], [63585.0, 0.096], [63745.3, 9.319], [63791.6, 0.01], [63803.3, 38.656], [63939.2, 4.556], [63993.5, 0.473], [64262.1, 5.377], [64478.8, 2.379], [64531.7, 0.032], [64555.6, 1.746], [64568.2, 0.003], [64573.4, 0.224], [64576.4, 0.021], [64580.2, 0.0], [64582.2, 0.02], [64583.7, 0.005], [64585.0, 45.444]], "asks": [[64585.1, 10.004], [64600.6, 0.004], [64692.3, 2.323], [64741.2, 10.439], [64780.0, 15.457], [65231.0, 13.831], [65585.1, 0.02], [65744.3, 1.263]]}
{"kind": "depth", "E": 1787088299201, "U": 11315916222883, "u": 11315916226976, "recv_ms": 1787088299139, "bids": [[1000.0, 35.76], [14285.0, 0.896], [14385.0, 3.304], [14485.0, 0.0], [51668.0, 0.0], [58126.5, 0.002], [61355.7, 2.453], [61355.8, 0.014], [61355.9, 0.007], [62001.6, 2.071], [63939.2, 4.556], [64262.0, 1.335], [64390.1, 3.359], [64443.2, 2.93], [64508.1, 8.304], [64512.9, 0.002], [64515.1, 35.675], [64520.4, 0.446], [64530.4, 0.252], [64530.7, 0.004], [64531.0, 0.032], [64531.4, 0.0], [64531.7, 0.005], [64547.0, 0.0], [64547.4, 0.28], [64547.7, 1.242], [64548.0, 0.436], [64548.3, 0.001], [64561.9, 0.001], [64562.0, 0.073], [64562.1, 0.001], [64562.2, 0.0], [64562.3, 0.0], [64562.4, 0.003], [64562.5, 0.002], [64562.6, 0.049], [64562.7, 0.266], [64562.9, 0.09], [64563.0, 0.823], [64563.3, 0.003], [64576.4, 0.02], [64577.8, 0.017], [64578.6, 2.322], [64579.1, 0.025], [64579.2, 0.026], [64579.3, 0.08], [64579.4, 0.684], [64579.5, 0.0], [64579.6, 0.28], [64579.7, 0.045], [64579.8, 0.0], [64579.9, 0.002], [64580.0, 0.318], [64580.4, 0.003], [64580.7, 0.0], [64581.0, 0.105], [64581.3, 0.101], [64581.7, 0.001], [64581.9, 0.533], [64583.7, 0.0]], "asks": [[64585.1, 9.989], [64590.7, 0.316], [64591.0, 0.003], [64591.3, 0.004], [64591.7, 0.012], [64592.0, 1.895], [64592.1, 0.421], [64592.3, 0.134], [64592.4, 0.003], [64592.5, 0.042], [64592.6, 0.317], [64592.7, 0.006], [64592.8, 0.003], [64592.9, 0.46], [64593.0, 0.013], [64593.1, 0.154], [64593.2, 0.0], [64593.3, 0.002], [64607.4, 0.002], [64607.7, 0.001], [64608.0, 0.2], [64608.3, 0.048], [64608.7, 0.0], [64609.0, 0.094], [64609.5, 0.677], [64609.6, 0.117], [64609.7, 0.116], [64609.8, 1.795], [64609.9, 1.186], [64610.1, 0.158], [64610.2, 0.169], [64610.3, 0.049], [64610.4, 0.0], [64623.9, 3.995], [64624.0, 0.262], [64624.3, 0.085], [64624.7, 0.0], [64625.0, 0.245], [64625.3, 0.028], [64637.1, 0.015], [64644.6, 2.334], [64720.2, 1.554], [64724.3, 5.411], [64741.1, 0.0], [64741.2, 6.383], [64780.0, 11.405], [64908.1, 0.0], [65101.8, 10.351], [65166.7, 0.038], [65231.0, 13.831]]}
{"kind": "depth", "E": 1787088299303, "U": 11315916227018, "u": 11315916230508, "recv_ms": 1787088299240, "bids": [[14285.0, 1.246], [14385.0, 2.954], [58126.5, 0.002], [62001.6, 2.074], [63585.0, 0.076], [63673.9, 5.488], [63810.0, 76.957], [63939.2, 4.556], [63994.1, 0.234], [64262.0, 1.336], [64387.5, 10.872], [64520.4, 0.464], [64531.7, 0.0], [64541.4, 0.004], [64547.0, 0.032], [64547.4, 0.312], [64547.7, 1.274], [64548.0, 0.468], [64548.3, 0.033], [64555.6, 1.742], [64566.3, 0.001], [64566.7, 0.052], [64567.2, 0.557], [64567.3, 0.121], [64567.6, 0.002], [64572.3, 0.929], [64572.9, 0.0], [64575.8, 2.334], [64577.8, 0.016], [64579.6, 0.38], [64579.7, 0.115], [64580.0, 0.388], [64580.4, 0.035], [64580.7, 0.032], [64581.0, 0.137], [64581.3, 0.133], [64581.7, 0.033], [64583.7, 0.005], [64585.0, 45.137]], "asks": [[64585.1, 10.215], [64586.9, 0.184], [64590.7, 0.364], [64591.0, 0.051], [64591.3, 0.071], [64591.7, 0.07], [64592.0, 1.949], [64592.3, 0.281], [64592.6, 0.436], [64592.7, 0.196], [64607.4, 0.05], [64607.5, 0.006], [64607.7, 0.049], [64608.0, 0.267], [64608.3, 0.106], [64608.4, 0.571], [64608.7, 0.054], [64608.9, 0.01], [64609.5, 0.824], [64609.8, 1.914], [64609.9, 1.376], [64644.6, 2.32], [64741.2, 10.439], [64780.0, 10.295], [64908.1, 0.001], [65231.0, 13.831], [65392.4, 25.401], [65585.1, 0.0]]}
{"kind": "depth", "E": 1787088299405, "U": 11315916230703, "u": 11315916234309, "recv_ms": 1787088299342, "bids": [[14285.0, 1.61], [14385.0, 2.59], [51668.0, 0.002], [58126.5, 0.002], [62001.6, 2.071], [63628.9, 2.487], [63810.0, 78.522], [64262.1, 5.377], [64541.4, 0.0], [64555.6, 1.746], [64576.3, 0.002], [64579.1, 0.095], [64579.4, 0.754], [64584.8, 0.027], [64584.9, 0.21]], "asks": [[64586.9, 0.184], [64593.0, 0.146], [64593.3, 0.135], [64597.0, 0.221], [64610.1, 0.137], [64610.2, 0.323], [64610.4, 0.133], [65047.4, 0.0], [65166.4, 24.63], [65231.0, 13.831], [65431.3, 1.542], [65760.6, 0.759], [67500.0, 77.103]]}
{"kind": "depth", "E": 1787088299507, "U": 11315916234337, "u": 11315916238711, "recv_ms": 1787088299445, "bids": [[1000.0, 35.76], [14285.0, 1.96], [14385.0, 2.24], [51668.0, 0.0], [58126.5, 0.002], [61355.7, 2.453], [62001.6, 2.074], [63585.0, 0.096], [63810.0, 79.225], [63939.2, 4.556], [64196.4, 0.003], [64575.8, 2.333], [64577.7, 0.048], [64578.6, 2.319], [64579.1, 0.165], [64579.2, 0.096], [64579.3, 0.15], [64579.5, 0.2], [64579.6, 0.48], [64579.7, 0.215], [64579.8, 0.07], [64580.0, 0.488], [64581.9, 0.001], [64582.1, 1.127], [64584.8, 0.027]], "asks": [[64585.1, 9.989], [64586.6, 0.086], [64586.9, 0.1], [64592.1, 0.66], [64592.4, 0.223], [64592.5, 0.168], [64592.6, 0.676], [64592.8, 0.493], [64592.9, 0.72], [64593.0, 0.286], [64593.1, 0.28], [64593.2, 0.133], [64609.0, 0.314], [64609.5, 1.084], [64609.6, 0.243], [64609.7, 0.356], [64609.9, 1.606], [64610.1, 0.397], [64610.2, 0.463], [64610.3, 0.175], [64610.4, 0.266], [64623.9, 3.981], [64741.2, 6.919], [65101.8, 10.657], [65231.0, 13.831], [65292.4, 3.717], [65399.4, 4.591], [65585.1, 0.02]]}
{"kind": "depth", "E": 1787088299609, "U": 11315916238823, "u": 11315916242914, "recv_ms": 1787088299548, "bids": [[14285.0, 2.31], [14385.0, 1.89], [58126.5, 0.002], [61355.7, 2.453], [63293.3, 7.041], [63635.6, 26.822], [63803.1, 6.451], [63939.2, 4.556], [64219.7, 0.0], [64220.3, 0.862], [64316.1, 0.001], [64316.8, 2.125], [64387.0, 0.522], [64387.1, 1.442], [64443.2, 2.973], [64530.4, 0.284], [64530.7, 0.036], [64531.0, 0.064], [64531.4, 0.032], [64531.7, 0.032], [64561.6, 0.005], [64562.1, 0.071], [64569.0, 0.008], [64577.7, 0.047], [64579.8, 0.17], [64580.7, 0.033], [64585.0, 45.143]], "asks": [[64592.5, 0.418], [64595.4, 0.813], [64598.1, 0.18], [64602.8, 0.004], [64604.5, 1.517], [64605.4, 1.041], [64606.0, 0.005], [64609.7, 0.606], [64610.2, 0.309], [64610.3, 0.329], [64624.0, 0.31], [64624.3, 0.133], [64624.7, 0.067], [64625.0, 0.303], [64625.3, 0.082], [64644.6, 2.334], [64724.2, 0.003], [64724.3, 5.411], [64741.2, 6.332], [64780.6, 0.001], [65231.0, 13.831]]}
{"kind": "depth", "E": 1787088299711, "U": 11315916242936, "u": 11315916246547, "recv_ms": 1787088299648, "bids": [[14285.0, 2.674], [14385.0, 1.526], [51668.0, 0.0], [58126.5, 0.002], [61355.8, 0.016], [62001.6, 2.071], [63293.3, 7.199], [63585.0, 0.076], [63777.7, 32.524], [63939.1, 15.57], [63939.2, 4.556], [64068.3, 10.002], [64262.1, 4.745], [64387.5, 7.846], [64531.7, 0.037], [64562.5, 0.172], [64562.9, 0.16], [64566.3, 0.117], [64567.3, 0.005], [64582.0, 0.988], [64582.1, 1.128], [64583.7, 0.0], [64585.0, 45.143]], "asks": [[64585.1, 9.979], [64604.5, 1.393], [64605.0, 0.001], [64605.6, 0.932], [64623.9, 3.995], [64741.2, 10.439], [64778.2, 2.385], [64851.3, 0.483], [64851.9, 0.04], [64949.0, 4.862], [64949.2, 0.008], [65046.8, 0.23], [65231.0, 13.831], [65421.4, 0.763], [65457.0, 21.799], [65585.1, 0.0]]}
{"kind": "depth", "E": 1787088299813, "U": 11315916246659, "u": 11315916250705, "recv_ms": 1787088299750, "bids": [[1000.0, 35.76], [14285.0, 3.038], [14385.0, 1.162], [51668.0, 0.0], [58126.5, 0.002], [61355.7, 2.453], [62001.6, 2.075], [63487.1, 26.363], [63939.2, 4.558], [63954.7, 0.0], [64104.1, 0.004], [64382.7, 7.453], [64387.1, 1.226], [64504.1, 34.194], [64515.1, 1.242], [64531.7, 0.032], [64561.9, 0.071], [64562.2, 0.07], [64566.3, 0.001], [64567.2, 0.116], [64568.2, 0.56], [64583.7, 0.005]], "asks": [[64585.1, 9.978], [64604.5, 1.393], [64780.5, 0.001], [64787.6, 7.423], [65066.1, 0.0], [65215.7, 0.031], [65231.0, 13.831], [65693.0, 0.001], [66529.3, 4.501]]}
{"kind": "depth", "E": 1787088299915, "U": 11315916250719, "u": 11315916254102, "recv_ms": 1787088299902, "bids": [[14285.0, 3.388], [14385.0, 0.812], [58126.5, 0.002], [62001.6, 2.072], [63585.0, 0.096], [63777.7, 32.789], [63939.2, 4.556], [64003.6, 3.276], [64068.3, 10.937], [64215.1, 0.071], [64216.0, 42.707], [64216.1, 6.869], [64262.1, 5.367], [64312.5, 34.337], [64313.0, 6.514], [64383.3, 27.241], [64426.2, 0.0], [64443.2, 0.008], [64504.1, 0.028], [64512.9, 33.862], [64549.2, 0.039], [64549.3, 0.0], [64562.0, 0.213], [64562.2, 0.14], [64562.3, 0.1], [64562.4, 0.103], [64562.5, 0.272], [64562.6, 0.119], [64562.9, 0.26], [64563.3, 0.103], [64580.7, 0.032], [64584.6, 0.02], [64585.0, 45.052]], "asks": [[64585.1, 10.202], [64586.2, 0.086], [64590.4, 0.004], [64610.3, 0.175], [64724.3, 0.003], [64741.2, 0.013], [64780.6, 27.807], [64851.3, 5.465], [64851.9, 33.83], [64949.0, 10.729], [64949.2, 42.663], [65231.0, 13.831], [65392.4, 25.142], [65585.1, 0.02], [65876.8, 6.251]]}
{"kind": "depth", "E": 1787088300017, "U": 11315916254217, "u": 11315916259861, "recv_ms": 1787088299954, "bids": [[14185.0, 0.014], [14285.0, 3.71], [14385.0, 0.476], [58126.5, 0.002], [61355.7, 2.453], [61355.8, 0.014], [61355.9, 0.009], [63777.7, 32.554], [63939.2, 4.556], [63953.0, 67.141], [64100.4, 54.124], [64262.1, 5.377], [64426.3, 4.392], [64426.4, 0.958], [64443.2, 2.942], [64469.8, 3.876], [64469.9, 1.453], [64512.9, 0.002], [64514.0, 0.057], [64515.1, 35.102], [64558.5, 0.004], [64558.6, 0.057], [64562.7, 0.366], [64567.4, 0.002], [64567.9, 0.155], [64572.3, 0.002], [64572.9, 0.927], [64573.2, 0.017], [64573.3, 0.005], [64573.5, 0.154], [64573.6, 0.626], [64573.7, 0.155], [64573.8, 0.557], [64573.9, 0.011], [64576.7, 0.68], [64577.2, 1.237], [64579.6, 0.326], [64579.9, 0.156], [64580.4, 0.036], [64582.2, 0.01], [64582.9, 0.008], [64583.2, 0.088], [64584.4, 0.161], [64584.6, 0.103], [64585.0, 44.794]], "asks": [[64585.1, 10.209], [64585.8, 0.014], [64586.1, 0.029], [64586.2, 0.002], [64592.1, 0.661], [64592.4, 0.222], [64592.7, 0.198], [64596.5, 0.12], [64609.1, 0.154], [64609.9, 1.549], [64610.3, 0.329], [64610.5, 0.057], [64611.3, 0.208], [64612.1, 0.055], [64612.3, 0.001], [64615.6, 0.186], [64618.5, 0.0], [64622.0, 0.155], [64625.0, 0.149], [64633.5, 0.002], [64656.2, 0.046], [64720.2, 1.064], [64720.3, 3.871], [64724.3, 4.57], [64741.2, 5.098], [64780.0, 8.573], [65231.0, 13.831], [65457.0, 22.408], [65696.0, 3.879], [65747.6, 3.104]]}
{"kind": "depth", "E": 1787088300119, "U": 11315916259887, "u": 11315916296427, "recv_ms": 1787088300087, "bids": [[1000.0, 35.76], [14185.0, 0.196], [14285.0, 3.71], [14385.0, 0.294], [51668.0, 0.002], [58126.5, 0.002], [61355.7, 2.454], [62001.6, 2.075], [63293.3, 7.202], [63585.0, 0.076], [63777.7, 32.203], [63939.2, 4.556], [64100.5, 4.322], [64104.2, 0.0], [64382.7, 7.237], [64383.4, 1.177], [64387.5, 10.558], [64442.7, 0.01], [64451.0, 1.0], [64469.8, 3.876], [64469.9, 0.999], [64478.8, 2.379], [64484.4, 0.075], [64488.3, 0.01], [64489.6, 0.0], [64492.6, 0.002], [64493.8, 0.0], [64493.9, 0.005], [64495.3, 0.26], [64498.9, 0.009], [64499.4, 0.059], [64500.2, 0.041], [64504.1, 0.028], [64508.5, 33.867], [64509.3, 0.014], [64511.0, 0.026], [64511.7, 0.026], [64514.0, 0.057], [64514.1, 0.013], [64515.1, 1.242], [64515.7, 0.001], [64516.5, 0.0], [64516.6, 0.007], [64517.4, 0.001], [64520.1, 0.002], [64520.4, 0.446], [64521.0, 0.5], [64523.0, 0.0], [64524.2, 0.0], [64525.0, 0.431], [64526.9, 0.482], [64528.7, 2.414], [64530.7, 0.036], [64532.4, 3.88], [64534.0, 0.001], [64534.8, 2.164], [64536.6, 0.001], [64536.7, 0.095], [64536.8, 0.013], [64537.5, 1.946], [64537.6, 1.453], [64539.1, 0.014], [64540.1, 0.06], [64540.3, 0.065], [64540.6, 0.002], [64541.1, 0.006], [64541.3, 3.528], [64542.4, 2.168], [64542.5, 0.0], [64543.3, 0.029], [64544.5, 0.03], [64545.0, 0.297], [64545.3, 0.12], [64545.6, 0.003], [64545.9, 0.619], [64546.1, 0.0], [64546.7, 0.071], [64546.9, 0.117], [64547.1, 0.318], [64549.2, 0.0], [64549.3, 0.039], [64550.1, 2.293], [64552.2, 0.005], [64552.3, 0.065], [64552.4, 0.002], [64553.2, 0.018], [64553.7, 1.528], [64553.8, 0.019], [64554.3, 0.053], [64554.4, 2.321], [64554.8, 0.015], [64555.3, 0.0], [64555.6, 1.748], [64555.7, 0.056], [64555.8, 0.327], [64556.5, 0.0], [64556.8, 0.011], [64557.0, 1.713], [64557.3, 0.0], [64557.4, 2.419], [64557.5, 1.016], [64557.6, 0.071], [64557.7, 0.016], [64558.0, 0.039], [64558.6, 0.0], [64559.0, 0.001], [64559.8, 1.345], [64560.2, 0.002], [64560.6, 0.005], [64560.9, 0.311], [64561.1, 0.0], [64561.4, 0.004], [64561.8, 0.081], [64562.0, 0.163], [64562.6, 0.089], [64564.0, 0.004], [64564.5, 0.038], [64565.6, 0.159], [64566.1, 0.021], [64566.5, 0.558], [64567.0, 0.033], [64567.2, 0.0], [64567.6, 0.002], [64567.9, 0.001], [64568.1, 0.16], [64568.2, 0.003], [64570.3, 0.033], [64570.6, 0.159], [64570.8, 0.467], [64571.0, 0.328], [64571.1, 0.0], [64571.3, 0.0], [64571.4, 0.017], [64571.5, 0.002], [64571.8, 0.02], [64572.2, 0.001], [64572.3, 0.001], [64572.4, 0.927], [64572.5, 0.002], [64572.9, 0.0], [64573.1, 2.338], [64573.2, 0.017], [64573.3, 0.012], [64573.4, 0.216], [64573.5, 0.542], [64573.6, 0.004], [64573.7, 0.148], [64573.8, 0.015], [64574.3, 0.001], [64574.5, 0.032], [64574.6, 0.0], [64574.7, 0.003], [64575.3, 0.03], [64575.4, 0.001], [64575.5, 0.002], [64575.9, 0.956], [64576.0, 0.039], [64576.1, 0.022], [64576.4, 0.02], [64576.7, 0.526], [64577.0, 2.43], [64577.3, 0.001], [64577.5, 0.085], [64577.6, 0.001], [64578.2, 0.176], [64578.3, 0.155], [64578.8, 0.01], [64578.9, 0.039], [64579.1, 0.173], [64579.2, 0.095], [64579.3, 0.151], [64579.4, 0.754], [64579.5, 0.2], [64579.6, 1.1], [64579.7, 0.989], [64579.8, 0.944], [64579.9, 0.002], [64580.1, 1.657], [64580.2, 0.774], [64580.3, 0.003], [64580.4, 0.189], [64580.6, 0.109], [64580.7, 0.04], [64580.8, 0.312], [64580.9, 0.931], [64581.1, 0.007], [64581.4, 0.271], [64581.5, 0.78], [64581.6, 0.105], [64581.9, 0.001], [64582.1, 1.516], [64582.2, 0.014], [64582.4, 0.002], [64582.5, 0.395], [64582.6, 0.778], [64582.8, 0.084], [64583.0, 0.001], [64583.1, 0.002], [64583.2, 0.085], [64583.3, 0.154], [64583.9, 0.089], [64584.0, 0.096], [64584.2, 0.044], [64584.4, 0.198], [64584.5, 0.019], [64584.6, 0.103], [64584.7, 0.0], [64584.8, 0.026], [64584.9, 0.535], [64585.0, 60.214]], "asks": [[64585.1, 7.32], [64585.2, 0.006], [64585.5, 0.0], [64585.6, 0.002], [64585.7, 0.075], [64585.9, 0.015], [64586.0, 0.216], [64586.2, 0.0], [64586.5, 0.03], [64586.6, 0.002], [64587.3, 0.002], [64587.7, 0.025], [64588.2, 0.003], [64588.3, 0.002], [64588.4, 0.004], [64588.5, 0.004], [64588.6, 0.016], [64588.8, 0.004], [64588.9, 0.004], [64589.0, 0.003], [64589.3, 0.001], [64589.4, 0.002], [64589.7, 0.005], [64590.1, 0.0], [64590.2, 0.776], [64590.3, 0.017], [64590.4, 0.005], [64590.6, 0.0], [64590.7, 0.006], [64590.8, 0.007], [64590.9, 0.001], [64591.0, 0.002], [64591.2, 0.001], [64591.3, 0.004], [64591.4, 0.0], [64591.5, 0.859], [64591.6, 0.018], [64591.7, 0.012], [64591.8, 0.169], [64591.9, 0.001], [64592.0, 0.004], [64592.1, 0.084], [64592.2, 0.085], [64592.3, 0.014], [64592.4, 0.002], [64592.5, 0.135], [64592.6, 0.007], [64592.7, 0.003], [64592.8, 0.002], [64592.9, 0.328], [64593.0, 0.097], [64593.1, 0.0], [64593.2, 0.0], [64593.3, 0.002], [64593.5, 0.289], [64593.6, 0.035], [64593.9, 0.013], [64594.1, 0.001], [64594.2, 0.085], [64594.3, 0.251], [64594.4, 0.351], [64594.5, 0.003], [64594.6, 0.003], [64594.7, 0.089], [64595.0, 0.461], [64595.1, 0.001], [64595.2, 0.007], [64595.3, 0.033], [64595.4, 1.235], [64595.7, 0.002], [64595.8, 0.0], [64595.9, 0.0], [64596.0, 2.654], [64596.1, 0.501], [64596.2, 0.004], [64596.3, 0.0], [64596.4, 0.003], [64596.5, 0.04], [64596.6, 0.027], [64596.7, 0.001], [64596.8, 0.001], [64596.9, 0.312], [64597.1, 0.062], [64597.3, 0.031], [64597.4, 0.087], [64597.5, 0.095], [64597.6, 0.096], [64597.7, 0.033], [64598.0, 0.013], [64598.1, 0.02], [64598.2, 0.001], [64598.3, 0.376], [64598.4, 0.018], [64598.5, 0.004], [64598.6, 2.408], [64598.7, 0.159], [64598.8, 0.003], [64599.0, 0.0], [64599.1, 0.066], [64599.3, 0.24], [64599.4, 0.017], [64599.5, 1.766], [64599.6, 1.897], [64599.7, 0.003], [64599.8, 1.704], [64600.0, 3.915], [64600.1, 0.0], [64600.3, 0.0], [64600.6, 0.004], [64600.8, 0.002], [64600.9, 0.643], [64601.1, 0.312], [64601.2, 0.497], [64601.3, 0.0], [64601.5, 0.0], [64601.6, 0.196], [64601.7, 0.0], [64601.8, 0.0], [64601.9, 1.176], [64602.0, 1.027], [64602.2, 0.039], [64602.5, 0.054], [64602.6, 0.002], [64602.7, 0.0], [64602.8, 0.552], [64602.9, 0.818], [64603.0, 0.074], [64603.1, 0.018], [64603.2, 0.004], [64603.3, 0.015], [64603.4, 0.061], [64603.5, 0.002], [64603.7, 0.0], [64604.1, 0.309], [64604.3, 1.0], [64604.4, 0.795], [64604.6, 0.001], [64604.8, 0.174], [64605.1, 0.311], [64605.2, 0.01], [64605.3, 0.016], [64605.4, 1.121], [64605.5, 0.001], [64605.6, 0.005], [64605.7, 0.0], [64605.8, 3.248], [64606.1, 0.023], [64606.6, 0.057], [64606.8, 0.094], [64607.0, 0.03], [64607.1, 0.072], [64607.4, 0.051], [64607.6, 0.064], [64607.8, 0.0], [64607.9, 0.635], [64608.0, 0.271], [64608.4, 0.0], [64608.5, 0.023], [64608.7, 0.086], [64608.8, 0.679], [64609.1, 0.619], [64609.2, 1.642], [64609.4, 0.0], [64609.6, 0.439], [64609.7, 0.49], [64609.9, 1.359], [64610.0, 0.914], [64610.1, 0.454], [64610.3, 0.175], [64610.5, 0.0], [64610.7, 0.006], [64611.3, 0.201], [64611.4, 0.003], [64611.5, 0.009], [64611.6, 0.846], [64611.7, 2.31], [64612.0, 0.121], [64612.3, 0.001], [64612.4, 0.046], [64612.7, 0.007], [64612.9, 0.035], [64613.0, 0.168], [64613.5, 1.291], [64613.6, 3.732], [64613.7, 0.36], [64614.0, 0.121], [64614.4, 0.006], [64614.7, 0.031], [64614.9, 0.375], [64615.2, 0.001], [64615.6, 0.032], [64615.7, 0.155], [64615.8, 2.32], [64616.0, 0.038], [64616.1, 0.011], [64616.3, 0.101], [64616.5, 0.021], [64617.1, 0.071], [64617.2, 0.015], [64617.6, 1.007], [64618.6, 4.263], [64618.7, 0.339], [64618.8, 0.033], [64619.5, 10.003], [64620.7, 0.0], [64620.9, 2.88], [64621.0, 2.352], [64621.3, 0.0], [64621.8, 0.13], [64622.0, 0.001], [64622.1, 0.536], [64622.2, 0.019], [64622.5, 0.184], [64623.1, 0.06], [64623.8, 0.047], [64623.9, 3.979], [64624.6, 0.006], [64624.8, 2.694], [64626.6, 0.019], [64627.0, 0.31], [64627.3, 0.443], [64627.5, 2.572], [64628.2, 0.006], [64628.6, 0.154], [64628.7, 0.201], [64628.8, 0.002], [64629.2, 0.005], [64629.3, 1.494], [64629.6, 0.0], [64629.9, 1.62], [64630.0, 0.083], [64630.4, 0.009], [64630.5, 0.001], [64632.1, 0.04], [64634.2, 0.007], [64634.7, 0.002], [64635.0, 0.006], [64635.2, 0.213], [64635.3, 0.056], [64639.1, 0.449], [64639.3, 0.019], [64639.6, 0.008], [64642.0, 0.099], [64643.2, 0.01], [64643.6, 0.0], [64643.8, 0.321], [64644.0, 0.003], [64644.6, 2.32], [64646.9, 0.0], [64647.1, 0.409], [64651.9, 0.002], [64654.2, 0.334], [64655.1, 0.428], [64655.4, 0.028], [64655.8, 0.028], [64656.2, 0.046], [64656.3, 0.002], [64656.8, 1.839], [64657.5, 0.0], [64657.9, 6.711], [64658.0, 0.007], [64658.3, 0.0], [64658.5, 0.671], [64659.1, 0.404], [64659.6, 0.004], [64660.9, 0.03], [64661.3, 0.061], [64662.4, 0.0], [64662.6, 0.031], [64663.1, 0.377], [64666.1, 0.024], [64668.7, 0.104], [64668.8, 0.026], [64672.0, 2.156], [64672.1, 0.046], [64673.5, 0.237], [64675.5, 0.001], [64675.6, 0.0], [64679.6, 3.155], [64679.7, 0.0], [64682.1, 1.339], [64684.3, 30.548], [64687.3, 2.513], [64687.4, 0.02], [64690.4, 0.003], [64691.3, 0.798], [64691.6, 0.029], [64692.3, 2.323], [64696.0, 0.004], [64700.0, 1.73], [64703.3, 1.664], [64703.9, 0.002], [64710.0, 0.151], [64720.3, 3.871], [64724.3, 4.585], [64741.2, 7.499], [64748.9, 16.184], [64752.6, 0.212], [64761.8, 0.075], [64780.5, 0.217], [64787.6, 7.207], [64908.0, 5.078], [64912.9, 0.2], [64913.0, 0.001], [65231.0, 13.831], [65356.6, 0.0], [65585.1, 0.0], [65876.8, 6.248]]}
{"kind": "depth", "E": 1787088300221, "U": 11315916296586, "u": 11315916328746, "recv_ms": 1787088300237, "bids": [[14185.0, 0.364], [14186.8, 0.028], [14188.3, 0.014], [14188.5, 0.014], [14285.0, 3.57], [14285.6, 0.014], [14286.8, 0.014], [14288.5, 0.014], [14385.0, 0.168], [51668.0, 0.0], [58126.5, 0.0], [58128.1, 0.0], [58129.6, 0.002], [61355.7, 2.453], [61359.0, 0.256], [62001.6, 2.072], [63293.3, 7.205], [63578.2, 0.0], [63579.9, 0.0], [63580.1, 0.146], [63580.6, 0.012], [63580.7, 0.003], [63582.1, 0.066], [63582.3, 0.017], [63586.8, 2.619], [63588.3, 0.002], [63588.5, 0.031], [63680.8, 80.954], [63777.7, 32.554], [63810.0, 77.974], [63939.2, 4.556], [63940.9, 0.039], [63942.6, 0.0], [64003.6, 4.367], [64361.2, 0.084], [64362.8, 0.0], [64364.5, 2.738], [64365.3, 0.295], [64365.4, 0.0], [64377.8, 0.116], [64382.7, 0.0], [64383.1, 0.158], [64383.4, 12.52], [64384.7, 0.086], [64386.3, 0.0], [64387.1, 0.0], [64387.5, 7.767], [64401.2, 0.233], [64402.8, 0.215], [64412.9, 0.0], [64445.4, 0.0], [64448.6, 0.0], [64451.9, 0.04], [64460.1, 0.01], [64460.3, 0.0], [64461.9, 0.0], [64464.5, 0.769], [64464.8, 0.012], [64466.7, 0.921], [64474.3, 0.274], [64475.5, 0.025], [64487.7, 0.0], [64488.6, 0.105], [64490.6, 0.0], [64493.1, 0.0], [64493.8, 0.0], [64493.9, 0.0], [64496.5, 0.184], [64497.5, 0.0], [64497.9, 0.148], [64498.9, 0.014], [64500.6, 0.207], [64504.0, 0.046], [64508.1, 4.677], [64508.5, 0.007], [64508.6, 0.084], [64509.1, 0.002], [64511.0, 0.025], [64511.7, 0.0], [64512.1, 0.001], [64513.2, 2.324], [64515.8, 2.346], [64515.9, 1.567], [64516.0, 1.501], [64517.3, 0.003], [64519.1, 0.019], [64521.1, 0.264], [64521.9, 0.079], [64522.0, 0.636], [64522.5, 0.006], [64525.0, 0.221], [64526.5, 0.009], [64527.0, 0.025], [64528.9, 0.004], [64529.0, 0.35], [64529.7, 1.473], [64529.8, 0.002], [64530.8, 0.0], [64531.6, 0.001], [64532.9, 0.01], [64533.5, 0.209], [64533.7, 2.319], [64533.8, 1.478], [64534.3, 0.0], [64534.6, 1.638], [64534.7, 2.176], [64534.8, 0.012], [64534.9, 0.03], [64535.0, 0.032], [64535.1, 0.02], [64535.3, 0.449], [64535.4, 0.006], [64535.6, 0.0], [64536.1, 0.038], [64536.7, 0.095], [64536.9, 0.256], [64537.5, 0.058], [64538.4, 0.001], [64538.5, 0.033], [64539.0, 0.002], [64539.6, 0.0], [64539.7, 0.686], [64540.1, 0.0], [64540.2, 0.101], [64540.3, 0.061], [64541.0, 0.06], [64541.3, 3.503], [64541.9, 2.378], [64542.4, 2.165], [64542.9, 0.0], [64543.4, 0.656], [64543.5, 0.373], [64543.8, 0.014], [64544.0, 0.055], [64544.1, 0.0], [64545.3, 0.0], [64545.7, 0.459], [64545.8, 0.096], [64545.9, 0.549], [64546.2, 0.005], [64546.7, 0.283], [64547.0, 0.059], [64548.0, 0.45], [64548.1, 3.049], [64548.6, 0.0], [64549.6, 0.017], [64549.8, 0.0], [64550.0, 0.257], [64550.8, 0.0], [64551.4, 0.002], [64552.1, 0.031], [64552.3, 0.065], [64553.0, 0.0], [64553.8, 0.015], [64554.6, 0.163], [64555.6, 1.752], [64555.7, 0.007], [64555.8, 0.327], [64556.1, 0.449], [64556.2, 0.001], [64556.8, 0.013], [64557.0, 0.0], [64557.4, 2.329], [64557.5, 1.016], [64557.6, 0.007], [64557.7, 0.078], [64557.8, 0.019], [64558.0, 0.039], [64558.8, 0.0], [64559.2, 0.003], [64559.5, 0.009], [64559.7, 0.025], [64559.8, 1.343], [64559.9, 0.001], [64560.3, 0.017], [64561.3, 0.113], [64561.4, 0.058], [64561.6, 5.005], [64561.8, 0.059], [64562.0, 0.141], [64562.1, 0.072], [64562.6, 0.085], [64562.9, 0.309], [64563.2, 0.016], [64563.3, 0.103], [64563.5, 0.021], [64563.8, 0.685], [64564.2, 0.535], [64564.3, 0.001], [64565.6, 0.133], [64565.7, 0.097], [64566.0, 0.122], [64566.1, 0.329], [64566.2, 0.016], [64566.3, 0.001], [64566.5, 0.001], [64566.6, 0.002], [64566.7, 0.019], [64567.0, 0.0], [64567.1, 0.015], [64567.8, 2.328], [64568.0, 0.005], [64568.4, 0.313], [64568.6, 0.032], [64568.7, 0.061], [64568.9, 0.0], [64570.0, 0.201], [64570.1, 0.0], [64570.2, 0.007], [64570.4, 1.113], [64570.6, 0.005], [64570.7, 1.243], [64571.0, 0.362], [64571.4, 0.017], [64571.5, 0.0], [64571.9, 0.769], [64572.0, 1.567], [64572.2, 0.001], [64572.4, 0.002], [64572.5, 0.002], [64572.7, 0.001], [64573.1, 2.322], [64573.2, 0.013], [64573.3, 0.012], [64573.4, 0.216], [64573.5, 0.0], [64573.9, 0.011], [64574.0, 0.019], [64574.2, 0.031], [64574.4, 0.026], [64574.5, 0.025], [64574.6, 0.0], [64574.7, 0.003], [64574.8, 0.013], [64574.9, 0.002], [64575.0, 0.902], [64575.1, 0.021], [64575.2, 0.0], [64575.3, 0.033], [64575.8, 2.334], [64576.0, 0.032], [64576.2, 0.315], [64576.3, 0.079], [64576.4, 0.115], [64576.5, 0.0], [64576.7, 1.453], [64576.9, 0.0], [64577.1, 0.003], [64577.3, 0.015], [64577.5, 0.036], [64577.7, 0.041], [64577.8, 0.014], [64577.9, 0.0], [64578.2, 0.176], [64578.3, 0.155], [64578.5, 0.248], [64578.7, 1.57], [64578.8, 0.087], [64578.9, 0.005], [64579.0, 0.24], [64579.1, 0.147], [64579.2, 0.109], [64579.3, 0.141], [64579.5, 0.743], [64579.6, 0.326], [64579.7, 0.175], [64579.8, 0.17], [64579.9, 0.001], [64580.1, 0.803], [64580.2, 0.0], [64580.3, 0.003], [64580.6, 0.055], [64580.7, 0.032], [64580.9, 0.157], [64581.0, 1.601], [64581.1, 0.007], [64581.3, 0.033], [64581.4, 0.025], [64581.5, 0.001], [64581.6, 0.0], [64581.7, 0.067], [64581.8, 0.015], [64582.0, 0.904], [64582.1, 1.591], [64582.2, 0.004], [64582.4, 0.008], [64582.5, 0.31], [64582.6, 0.0], [64582.8, 0.31], [64582.9, 0.019], [64583.1, 0.002], [64583.2, 0.001], [64583.3, 0.0], [64583.4, 0.059], [64583.5, 0.001], [64583.6, 0.084], [64583.7, 0.008], [64583.8, 0.016], [64584.0, 0.101], [64584.1, 0.146], [64584.4, 0.2], [64584.5, 0.019], [64584.6, 0.094], [64584.7, 0.008], [64584.8, 0.133], [64584.9, 0.348], [64585.0, 39.406], [64585.1, 5.198], [64585.2, 2.311], [64585.3, 12.978], [64585.4, 0.001], [64585.5, 0.001], [64585.6, 1.612], [64585.7, 1.027], [64585.8, 0.0], [64585.9, 0.197], [64586.0, 9.641], [64586.1, 0.026], [64586.2, 0.001], [64586.3, 0.996], [64586.4, 0.374], [64586.5, 0.025], [64586.6, 0.193], [64586.7, 0.003], [64586.8, 11.938], [64586.9, 13.853], [64587.0, 0.033], [64587.1, 1.118], [64587.2, 0.194], [64587.3, 0.273], [64587.4, 0.0], [64587.5, 1.242], [64587.6, 1.203], [64587.7, 6.907], [64587.8, 0.387], [64587.9, 0.032], [64588.0, 1.211], [64588.1, 3.222], [64588.2, 0.399], [64588.3, 6.674], [64588.4, 0.734], [64588.5, 37.343]], "asks": [[64585.1, 0.0], [64585.2, 0.0], [64585.3, 0.0], [64585.6, 0.0], [64585.7, 0.0], [64585.8, 0.0], [64585.9, 0.0], [64586.0, 0.0], [64586.1, 0.0], [64586.4, 0.0], [64586.5, 0.0], [64586.6, 0.0], [64586.7, 0.0], [64586.8, 0.0], [64586.9, 0.0], [64587.0, 0.0], [64587.1, 0.0], [64587.2, 0.0], [64587.3, 0.0], [64587.4, 0.0], [64587.6, 0.0], [64587.7, 0.0], [64587.8, 0.0], [64587.9, 0.0], [64588.0, 0.0], [64588.1, 0.0], [64588.2, 0.0], [64588.3, 0.0], [64588.4, 0.0], [64588.5, 0.0], [64588.6, 0.05], [64588.7, 0.001], [64588.8, 0.003], [64588.9, 0.388], [64589.0, 0.776], [64589.1, 0.687], [64589.2, 0.061], [64589.3, 0.0], [64589.4, 0.0], [64589.8, 0.0], [64589.9, 0.0], [64590.0, 0.033], [64590.1, 0.0], [64590.2, 0.001], [64590.3, 0.016], [64590.4, 0.004], [64590.7, 0.005], [64590.8, 0.001], [64591.2, 0.002], [64591.3, 0.002], [64591.4, 0.0], [64591.5, 0.001], [64591.6, 0.007], [64591.8, 0.001], [64592.1, 0.0], [64592.2, 0.001], [64592.3, 0.015], [64592.4, 0.002], [64592.5, 0.388], [64592.6, 0.007], [64592.7, 0.001], [64592.8, 0.002], [64592.9, 0.018], [64593.0, 0.013], [64593.1, 0.0], [64593.2, 0.002], [64593.4, 0.002], [64593.5, 0.0], [64593.8, 0.084], [64593.9, 0.016], [64594.1, 0.001], [64594.2, 0.003], [64594.3, 0.25], [64594.4, 0.001], [64594.5, 0.001], [64594.6, 0.387], [64594.7, 0.315], [64594.9, 0.004], [64595.0, 0.002], [64595.2, 0.007], [64595.3, 0.001], [64595.4, 0.623], [64595.5, 0.016], [64595.6, 0.017], [64595.8, 0.0], [64595.9, 0.0], [64596.0, 0.122], [64596.1, 0.369], [64596.4, 1.886], [64596.5, 0.001], [64596.7, 0.001], [64596.9, 0.312], [64597.0, 0.221], [64597.2, 0.084], [64597.3, 1.886], [64597.4, 0.023], [64597.5, 0.002], [64597.6, 0.092], [64597.7, 0.056], [64598.0, 0.09], [64598.1, 0.018], [64598.2, 0.354], [64598.3, 0.46], [64598.4, 0.019], [64598.5, 0.063], [64598.6, 1.974], [64598.7, 0.087], [64598.8, 0.0], [64598.9, 0.0], [64599.1, 0.091], [64599.3, 0.0], [64599.4, 0.257], [64599.5, 1.746], [64599.7, 0.001], [64599.8, 0.001], [64599.9, 2.327], [64600.0, 3.892], [64600.1, 0.001], [64600.2, 0.001], [64600.3, 0.04], [64600.4, 0.108], [64600.5, 0.012], [64600.8, 0.002], [64600.9, 0.015], [64601.2, 0.417], [64601.6, 0.199], [64601.8, 0.092], [64601.9, 1.416], [64602.0, 1.027], [64602.1, 0.129], [64602.4, 0.05], [64602.7, 0.004], [64602.8, 0.068], [64603.0, 0.035], [64603.1, 0.075], [64603.7, 0.093], [64603.8, 0.004], [64603.9, 0.001], [64604.0, 0.005], [64604.1, 0.349], [64604.2, 0.001], [64604.4, 0.135], [64604.7, 0.137], [64604.8, 0.175], [64605.1, 0.885], [64605.2, 0.001], [64605.3, 0.0], [64605.4, 0.0], [64605.7, 0.001], [64605.8, 0.002], [64606.0, 0.04], [64606.1, 2.344], [64606.3, 0.003], [64606.4, 0.002], [64606.6, 0.002], [64606.7, 0.0], [64606.8, 0.003], [64606.9, 0.059], [64607.0, 0.033], [64607.1, 0.088], [64607.2, 0.001], [64607.3, 0.002], [64607.6, 0.001], [64607.8, 0.672], [64607.9, 0.63], [64608.0, 0.246], [64608.1, 0.066], [64608.5, 1.253], [64608.6, 0.018], [64608.7, 0.086], [64608.8, 0.002], [64609.1, 0.64], [64609.6, 0.404], [64609.7, 1.032], [64609.8, 1.795], [64610.0, 0.014], [64610.1, 0.397], [64610.3, 0.126], [64610.4, 0.133], [64610.5, 0.0], [64610.7, 0.0], [64610.9, 0.0], [64611.2, 0.01], [64611.3, 1.13], [64611.4, 0.003], [64611.5, 0.007], [64611.6, 0.69], [64611.9, 0.0], [64612.0, 0.106], [64612.3, 0.558], [64612.4, 0.0], [64612.5, 0.003], [64612.6, 0.0], [64612.8, 0.004], [64612.9, 0.05], [64613.0, 0.019], [64613.1, 0.015], [64613.4, 0.005], [64613.7, 0.2], [64613.8, 0.327], [64614.1, 0.076], [64614.2, 0.105], [64614.4, 0.007], [64614.5, 0.421], [64614.7, 0.0], [64614.8, 0.669], [64615.0, 0.841], [64615.1, 1.298], [64615.4, 0.0], [64615.5, 0.185], [64615.6, 0.016], [64615.8, 2.324], [64616.0, 0.032], [64616.2, 0.01], [64616.3, 0.108], [64616.5, 0.003], [64616.7, 0.0], [64616.8, 0.002], [64617.3, 0.078], [64617.4, 0.204], [64617.6, 1.056], [64617.7, 0.059], [64618.0, 1.425], [64618.1, 0.017], [64618.3, 0.013], [64618.7, 0.347], [64618.8, 0.001], [64619.0, 1.022], [64619.2, 0.001], [64619.3, 0.057], [64619.5, 0.005], [64619.8, 0.069], [64619.9, 0.0], [64620.1, 0.108], [64620.3, 0.025], [64620.8, 0.01], [64620.9, 1.489], [64621.8, 0.105], [64622.5, 0.094], [64622.6, 0.052], [64622.9, 0.327], [64623.4, 1.239], [64623.8, 0.005], [64624.2, 0.957], [64624.3, 0.135], [64625.1, 0.689], [64625.3, 0.054], [64625.5, 0.0], [64625.8, 0.075], [64626.1, 0.162], [64626.2, 0.001], [64626.4, 0.005], [64627.3, 0.461], [64627.4, 1.26], [64627.5, 2.362], [64627.6, 0.134], [64627.8, 0.0], [64628.2, 0.0], [64628.5, 0.012], [64629.0, 0.482], [64629.1, 0.095], [64629.2, 0.005], [64629.4, 0.065], [64629.6, 0.004], [64630.0, 0.023], [64630.1, 0.021], [64630.2, 0.201], [64630.3, 0.264], [64630.5, 10.001], [64630.8, 0.027], [64631.3, 0.065], [64631.8, 0.015], [64632.6, 0.0], [64632.7, 0.002], [64632.8, 0.0], [64632.9, 0.405], [64633.5, 0.002], [64633.6, 0.005], [64634.3, 0.82], [64634.7, 0.01], [64635.2, 0.242], [64635.4, 0.0], [64635.7, 4.591], [64635.9, 2.319], [64636.6, 0.089], [64637.3, 0.002], [64637.9, 0.0], [64639.4, 0.449], [64639.5, 0.002], [64639.9, 1.473], [64640.0, 0.03], [64640.7, 0.05], [64641.0, 0.127], [64641.3, 0.068], [64641.6, 0.06], [64642.0, 0.045], [64643.7, 0.002], [64644.0, 0.005], [64646.0, 0.003], [64647.2, 1.751], [64647.3, 0.37], [64648.2, 0.0], [64648.3, 0.216], [64648.7, 2.341], [64649.0, 0.032], [64649.7, 0.365], [64649.8, 0.449], [64649.9, 0.922], [64650.3, 0.003], [64652.1, 0.001], [64653.7, 2.236], [64653.8, 0.0], [64654.3, 0.072], [64655.4, 0.002], [64655.5, 0.031], [64655.8, 0.028], [64656.3, 0.005], [64657.6, 0.026], [64659.0, 0.234], [64659.5, 0.011], [64660.1, 2.513], [64662.6, 0.029], [64663.1, 0.337], [64664.0, 0.063], [64664.4, 0.465], [64664.8, 0.166], [64666.5, 0.1], [64666.8, 0.0], [64667.0, 0.032], [64667.6, 0.0], [64668.0, 0.024], [64668.9, 30.549], [64669.0, 0.0], [64669.8, 0.0], [64670.9, 0.013], [64672.0, 2.154], [64672.3, 0.002], [64673.6, 2.321], [64673.8, 0.006], [64674.3, 2.638], [64674.5, 0.003], [64675.6, 0.001], [64678.0, 0.173], [64678.5, 0.008], [64679.6, 3.153], [64680.6, 0.003], [64682.0, 0.775], [64683.8, 0.026], [64684.3, 0.0], [64685.0, 0.013], [64686.8, 0.035], [64686.9, 0.014], [64687.7, 0.001], [64692.1, 0.013], [64694.7, 2.648], [64699.2, 0.624], [64701.8, 0.0], [64703.0, 0.006], [64704.4, 0.014], [64706.2, 0.014], [64707.9, 0.0], [64708.6, 0.0], [64708.9, 0.001], [64709.9, 0.0], [64713.3, 0.015], [64716.6, 0.002], [64720.3, 3.884], [64721.5, 0.006], [64722.9, 0.241], [64724.0, 0.001], [64724.2, 1.096], [64745.1, 0.001], [64774.0, 0.011], [64990.9, 0.158], [65023.4, 0.0], [65066.7, 53.998], [65231.0, 13.831], [65232.8, 0.042], [65234.5, 0.0], [65328.4, 2.438], [65328.5, 0.0], [65330.1, 0.909], [65330.2, 10.593], [65331.5, 0.909], [65331.9, 9.105], [65389.5, 0.0], [65392.5, 0.0], [65393.0, 4.2], [65393.1, 2.292], [65394.8, 1.521], [65395.6, 0.76], [65396.5, 2.29], [65588.6, 0.031]]}
{"kind": "depth", "E": 1787088300323, "U": 11315916328758, "u": 11315916368993, "recv_ms": 1787088300355, "bids": [[1000.0, 35.76], [14188.5, 0.056], [14188.7, 0.014], [14188.9, 0.028], [14189.0, 0.168], [14285.0, 3.318], [14288.5, 0.028], [14288.9, 0.028], [14289.0, 0.07], [14385.0, 0.056], [51668.0, 0.0], [51671.0, 0.0], [58126.5, 0.051], [58129.6, 0.0], [58130.0, 0.002], [58130.1, 0.002], [61359.0, 0.255], [61359.5, 0.001], [62005.4, 0.003], [63297.3, 0.022], [63582.1, 0.062], [63582.3, 0.015], [63583.2, 0.002], [63585.0, 0.074], [63588.7, 0.637], [63588.9, 0.004], [63589.0, 0.043], [63648.5, 50.185], [63667.6, 0.822], [63816.4, 9.404], [63940.9, 0.033], [63942.6, 0.0], [63942.8, 0.005], [63943.0, 0.071], [63943.1, 0.0], [64262.0, 1.335], [64262.1, 5.377], [64266.0, 5.019], [64361.2, 0.007], [64364.4, 0.122], [64365.3, 0.218], [64365.6, 0.103], [64383.1, 0.004], [64383.5, 0.077], [64384.7, 0.009], [64395.4, 0.969], [64401.2, 0.387], [64401.3, 0.312], [64401.4, 0.154], [64401.6, 2.732], [64401.7, 0.077], [64402.8, 0.311], [64403.0, 0.505], [64403.2, 0.08], [64404.1, 0.001], [64404.4, 0.019], [64407.7, 0.002], [64435.4, 0.094], [64447.2, 0.823], [64450.6, 1.117], [64451.0, 1.0], [64460.1, 0.01], [64462.7, 0.0], [64466.4, 0.526], [64467.1, 0.0], [64467.7, 4.647], [64479.4, 0.0], [64493.1, 33.86], [64496.0, 0.025], [64498.9, 0.009], [64506.0, 3.604], [64507.2, 0.006], [64509.5, 0.184], [64510.5, 0.468], [64511.8, 0.001], [64513.0, 0.228], [64514.2, 0.155], [64515.8, 3.793], [64515.9, 0.094], [64521.9, 0.002], [64523.5, 0.0], [64523.9, 0.017], [64526.7, 0.0], [64527.0, 0.235], [64528.9, 0.0], [64529.6, 1.474], [64529.7, 0.001], [64530.0, 0.005], [64530.1, 0.003], [64530.2, 0.031], [64530.4, 0.033], [64531.6, 0.0], [64533.0, 0.186], [64533.8, 1.453], [64534.5, 0.103], [64534.6, 1.428], [64535.0, 0.017], [64535.2, 0.45], [64535.3, 0.016], [64536.0, 0.007], [64536.9, 0.251], [64538.5, 0.014], [64539.0, 0.005], [64539.1, 0.0], [64540.2, 0.015], [64540.3, 0.0], [64541.0, 0.0], [64541.2, 0.002], [64541.4, 0.329], [64542.1, 0.023], [64542.3, 2.159], [64542.4, 0.015], [64543.3, 0.684], [64543.4, 0.001], [64543.8, 0.075], [64544.0, 0.049], [64544.2, 0.008], [64544.5, 0.0], [64545.1, 0.015], [64545.6, 0.452], [64545.7, 0.01], [64546.4, 0.014], [64548.0, 0.48], [64548.2, 0.139], [64549.0, 0.018], [64549.6, 0.0], [64549.9, 2.158], [64550.0, 0.243], [64550.1, 0.141], [64550.4, 0.06], [64551.7, 0.001], [64552.0, 0.046], [64552.4, 0.004], [64552.8, 0.072], [64552.9, 0.0], [64553.6, 0.087], [64554.3, 0.001], [64554.6, 0.043], [64556.0, 0.451], [64556.1, 0.0], [64556.3, 0.013], [64557.1, 0.164], [64559.1, 0.017], [64559.5, 0.003], [64559.8, 1.349], [64561.2, 0.019], [64561.4, 1.762], [64561.5, 2.373], [64561.6, 5.007], [64562.4, 0.103], [64562.6, 0.07], [64562.7, 0.206], [64562.9, 0.26], [64563.2, 0.065], [64563.6, 0.015], [64563.8, 0.7], [64566.1, 0.02], [64566.5, 0.296], [64568.0, 0.007], [64569.2, 0.06], [64569.5, 0.309], [64569.7, 0.006], [64570.4, 1.129], [64571.2, 0.098], [64571.4, 0.015], [64571.9, 0.558], [64572.7, 0.0], [64572.8, 0.123], [64573.2, 0.003], [64573.6, 0.001], [64574.1, 0.246], [64574.2, 0.03], [64574.9, 0.001], [64575.0, 0.921], [64575.6, 0.0], [64575.7, 0.001], [64575.8, 2.333], [64576.0, 0.03], [64576.4, 0.093], [64576.5, 0.002], [64577.1, 0.002], [64577.4, 0.451], [64577.5, 0.0], [64577.7, 0.001], [64577.9, 0.0], [64578.0, 1.066], [64578.3, 0.156], [64578.8, 0.01], [64579.0, 0.26], [64579.2, 0.11], [64579.7, 0.176], [64579.8, 0.17], [64580.0, 0.49], [64580.2, 0.016], [64580.3, 0.005], [64580.6, 0.001], [64581.7, 0.033], [64582.1, 0.807], [64582.2, 0.003], [64582.5, 0.313], [64582.8, 0.001], [64582.9, 0.014], [64583.6, 0.034], [64584.0, 0.181], [64584.1, 0.0], [64584.2, 0.003], [64584.4, 0.017], [64584.5, 0.0], [64584.6, 0.094], [64584.7, 0.007], [64584.8, 0.113], [64584.9, 0.345], [64585.0, 37.464], [64585.1, 4.711], [64585.2, 0.012], [64585.3, 6.31], [64585.4, 0.659], [64585.5, 0.0], [64585.6, 0.206], [64585.7, 0.013], [64585.9, 0.002], [64586.0, 0.099], [64586.1, 0.0], [64586.2, 0.021], [64586.3, 0.006], [64586.4, 0.012], [64586.5, 0.309], [64586.6, 0.0], [64586.7, 0.0], [64586.8, 0.78], [64586.9, 0.297], [64587.0, 0.022], [64587.1, 0.0], [64587.2, 0.0], [64587.3, 0.095], [64587.4, 0.0], [64587.5, 0.31], [64587.6, 0.876], [64587.7, 0.476], [64587.8, 0.0], [64587.9, 0.0], [64588.0, 0.002], [64588.1, 2.319], [64588.2, 0.011], [64588.3, 0.157], [64588.4, 0.776], [64588.5, 1.646], [64588.6, 0.774], [64588.7, 1.091], [64588.8, 1.441], [64588.9, 4.261], [64589.0, 53.383]], "asks": [[64588.6, 0.0], [64588.7, 0.0], [64588.8, 0.0], [64588.9, 0.0], [64589.0, 0.0], [64589.1, 1.265], [64589.2, 0.061], [64589.5, 0.0], [64589.6, 0.002], [64590.0, 0.028], [64590.3, 0.0], [64590.9, 0.001], [64591.0, 0.0], [64591.3, 0.002], [64591.5, 0.002], [64591.6, 0.006], [64591.7, 0.002], [64591.8, 0.004], [64591.9, 0.003], [64592.0, 0.011], [64592.4, 0.002], [64592.5, 0.001], [64592.8, 0.0], [64592.9, 0.08], [64593.0, 1.89], [64593.1, 0.774], [64593.2, 0.146], [64593.3, 0.002], [64593.4, 0.002], [64593.6, 0.809], [64593.7, 1.885], [64593.8, 0.0], [64593.9, 0.068], [64594.0, 0.002], [64594.1, 0.004], [64594.2, 0.001], [64594.3, 0.238], [64594.5, 0.001], [64594.6, 0.0], [64594.7, 0.011], [64594.9, 0.005], [64595.0, 0.002], [64595.1, 0.1], [64595.2, 0.007], [64595.3, 0.003], [64595.4, 0.24], [64595.5, 0.108], [64595.6, 1.659], [64595.8, 0.0], [64595.9, 0.084], [64596.0, 0.022], [64596.1, 0.067], [64596.2, 0.088], [64596.3, 0.82], [64596.4, 0.001], [64596.6, 0.111], [64596.7, 0.001], [64596.9, 0.002], [64597.0, 0.221], [64597.1, 0.321], [64597.2, 0.085], [64597.3, 0.002], [64597.4, 0.023], [64597.7, 0.001], [64597.9, 0.023], [64598.0, 0.098], [64598.1, 0.018], [64598.2, 0.444], [64598.4, 0.009], [64598.5, 0.001], [64598.6, 0.012], [64598.7, 0.087], [64599.1, 0.007], [64599.3, 0.0], [64599.4, 0.017], [64599.6, 1.901], [64599.7, 0.0], [64599.8, 0.001], [64600.0, 3.874], [64600.1, 0.001], [64600.3, 0.06], [64600.4, 0.133], [64601.0, 0.901], [64601.1, 0.311], [64601.4, 0.001], [64601.6, 0.037], [64601.7, 0.08], [64601.8, 0.092], [64601.9, 1.436], [64602.0, 0.129], [64602.1, 0.052], [64602.2, 0.033], [64602.8, 0.068], [64603.0, 0.036], [64603.6, 0.006], [64603.8, 0.221], [64604.0, 0.582], [64604.1, 0.349], [64604.2, 0.231], [64604.3, 1.26], [64604.4, 2.237], [64604.7, 0.263], [64604.8, 0.308], [64605.0, 0.008], [64606.3, 0.01], [64607.1, 0.072], [64607.4, 0.002], [64607.7, 0.078], [64607.9, 0.65], [64608.0, 0.246], [64608.1, 0.017], [64608.2, 0.013], [64608.3, 0.078], [64608.4, 0.001], [64608.7, 0.032], [64608.9, 0.018], [64609.0, 0.47], [64609.1, 0.62], [64609.5, 0.831], [64609.6, 0.198], [64609.7, 0.792], [64610.0, 0.005], [64610.1, 0.27], [64610.2, 0.169], [64610.4, 0.182], [64610.8, 0.006], [64611.2, 0.011], [64611.3, 1.131], [64611.5, 0.007], [64612.3, 0.001], [64612.9, 0.035], [64613.0, 0.014], [64613.1, 0.001], [64613.2, 2.32], [64613.5, 1.307], [64613.6, 3.732], [64613.7, 0.04], [64613.8, 0.167], [64613.9, 0.557], [64614.0, 0.136], [64614.1, 0.076], [64614.4, 0.006], [64614.5, 0.429], [64614.6, 0.004], [64614.7, 0.008], [64615.2, 0.008], [64615.4, 0.001], [64615.5, 0.237], [64615.6, 0.014], [64616.2, 0.008], [64616.4, 0.004], [64616.7, 0.04], [64616.8, 0.002], [64616.9, 0.0], [64617.0, 0.702], [64617.1, 0.031], [64617.5, 0.017], [64617.6, 1.007], [64617.8, 0.085], [64618.0, 0.044], [64618.1, 0.098], [64618.2, 0.383], [64618.6, 0.007], [64618.9, 0.017], [64619.0, 0.902], [64619.7, 0.0], [64620.0, 0.048], [64620.3, 0.0], [64620.9, 1.498], [64621.6, 0.628], [64623.0, 0.095], [64623.4, 1.237], [64623.9, 3.981], [64624.2, 2.852], [64625.4, 3.503], [64625.7, 0.24], [64625.8, 0.005], [64626.0, 0.163], [64626.1, 0.0], [64626.2, 0.153], [64626.3, 0.28], [64626.4, 0.021], [64626.9, 0.241], [64627.3, 0.835], [64627.4, 1.4], [64627.7, 1.164], [64628.0, 10.005], [64628.1, 0.889], [64628.9, 0.449], [64629.0, 0.033], [64629.1, 0.093], [64629.3, 1.508], [64629.4, 0.097], [64629.6, 0.0], [64630.2, 0.016], [64630.5, 0.003], [64631.1, 2.492], [64631.4, 0.004], [64632.7, 0.028], [64632.9, 0.403], [64633.1, 1.892], [64633.7, 0.21], [64634.0, 0.026], [64634.3, 0.82], [64634.7, 0.002], [64635.1, 0.389], [64635.7, 4.593], [64635.9, 2.375], [64636.4, 1.277], [64636.8, 0.023], [64639.3, 0.468], [64639.4, 0.005], [64639.7, 0.016], [64639.8, 1.475], [64639.9, 0.001], [64640.9, 0.002], [64642.0, 0.05], [64642.2, 0.387], [64642.3, 0.015], [64642.4, 0.03], [64643.0, 0.005], [64643.2, 0.0], [64643.3, 0.003], [64643.8, 0.26], [64644.0, 0.015], [64647.1, 0.416], [64647.3, 0.431], [64647.9, 0.119], [64648.3, 0.006], [64648.7, 2.32], [64650.1, 0.0], [64651.2, 0.034], [64653.6, 1.471], [64653.7, 0.765], [64653.8, 0.002], [64654.8, 0.002], [64655.2, 0.042], [64656.0, 0.034], [64656.3, 0.008], [64657.6, 0.0], [64658.0, 0.217], [64660.9, 0.0], [64664.4, 0.495], [64666.1, 0.026], [64667.6, 0.0], [64668.8, 0.026], [64668.9, 30.549], [64671.9, 2.25], [64672.0, 0.008], [64675.0, 0.092], [64675.5, 0.001], [64675.6, 0.001], [64676.3, 0.14], [64678.0, 0.167], [64679.9, 0.006], [64680.0, 0.169], [64683.9, 0.442], [64686.6, 0.004], [64687.2, 2.146], [64687.3, 0.366], [64691.3, 0.806], [64701.4, 0.009], [64703.3, 0.0], [64706.4, 0.001], [64706.6, 0.003], [64706.9, 2.32], [64707.0, 0.118], [64708.6, 0.0], [64708.8, 0.086], [64716.2, 1.694], [64817.6, 0.378], [64817.9, 0.0], [64908.1, 0.0], [64912.1, 0.002], [65232.8, 0.042], [65234.5, 0.0], [65234.7, 0.011], [65234.9, 0.0], [65235.0, 0.612], [65328.4, 1.529], [65330.1, 0.0], [65330.2, 7.866], [65331.5, 0.0], [65331.9, 10.014], [65332.1, 2.76], [65332.2, 2.733], [65393.0, 2.686], [65393.1, 0.0], [65394.8, 0.007], [65395.6, 0.003], [65396.5, 6.075], [65396.7, 0.761], [65396.8, 0.757], [65396.9, 0.781], [65880.8, 0.003], [71048.1, 0.001]]}
{"kind": "depth", "E": 1787088300425, "U": 11315916369074, "u": 11315916380817, "recv_ms": 1787088300363, "bids": [[1000.0, 35.76], [14189.0, 0.462], [14285.0, 3.094], [14289.0, 0.056], [14385.0, 0.0], [58130.1, 0.002], [61359.5, 0.0], [62005.4, 0.0], [63874.6, 12.799], [63943.1, 0.0], [64243.6, 0.705], [64468.1, 0.087], [64493.1, 0.0], [64507.2, 0.005], [64508.5, 33.867], [64516.4, 0.008], [64536.9, 0.256], [64544.0, 0.048], [64548.7, 0.004], [64551.5, 0.327], [64552.4, 0.002], [64552.8, 0.07], [64553.6, 0.077], [64554.1, 0.0], [64554.2, 0.011], [64555.4, 0.001], [64563.2, 0.066], [64569.6, 0.185], [64573.0, 0.012], [64574.5, 0.061], [64574.8, 0.015], [64574.9, 0.003], [64576.1, 0.024], [64576.5, 0.0], [64582.6, 0.184], [64583.3, 0.04], [64584.0, 0.255], [64584.4, 0.018], [64585.0, 37.244], [64585.1, 4.715], [64585.2, 0.012], [64585.6, 0.207], [64586.0, 0.097], [64586.6, 0.0], [64586.9, 0.101], [64587.7, 0.863], [64587.8, 0.774], [64588.1, 2.321], [64588.2, 0.016], [64588.4, 0.002], [64588.5, 0.872], [64588.8, 1.442], [64588.9, 4.256], [64589.0, 53.351]], "asks": [[64591.7, 1.65], [64592.9, 0.854], [64593.1, 0.0], [64593.5, 0.0], [64593.6, 0.422], [64594.2, 0.001], [64594.6, 0.084], [64595.4, 0.24], [64595.5, 0.428], [64595.6, 0.017], [64596.3, 0.0], [64597.2, 0.084], [64597.5, 0.003], [64598.0, 0.09], [64598.4, 0.008], [64598.7, 0.003], [64599.1, 0.015], [64599.3, 0.542], [64599.4, 1.654], [64599.5, 1.744], [64599.7, 0.001], [64599.8, 0.094], [64600.8, 0.0], [64601.7, 0.0], [64602.0, 0.127], [64602.1, 0.054], [64603.3, 0.052], [64603.9, 0.148], [64604.1, 0.599], [64604.6, 0.155], [64605.0, 0.908], [64605.3, 0.08], [64607.7, 0.056], [64607.9, 0.688], [64608.2, 0.005], [64608.5, 1.413], [64608.9, 0.01], [64609.0, 0.25], [64609.2, 1.191], [64609.9, 1.129], [64610.1, 0.01], [64610.2, 0.015], [64610.4, 0.0], [64614.1, 0.077], [64616.4, 0.036], [64616.7, 0.0], [64617.6, 1.056], [64617.8, 0.015], [64618.3, 0.083], [64621.0, 2.358], [64625.5, 0.0], [64627.2, 0.155], [64627.4, 1.65], [64628.0, 10.159], [64628.1, 0.761], [64635.5, 0.039], [64635.6, 1.505], [64642.3, 0.069], [64644.0, 0.005], [64644.6, 2.33], [64650.5, 0.631], [64650.8, 0.21], [64651.9, 0.0], [64652.8, 0.021], [64653.6, 1.473], [64656.0, 0.035], [64658.0, 0.007], [64662.4, 30.548], [64666.8, 0.0], [64668.9, 0.001], [64707.0, 0.001], [64708.8, 0.0], [64714.6, 0.0], [64720.9, 0.008], [64725.4, 4.647], [64748.8, 3.407], [64780.5, 0.073], [64787.6, 7.423], [65034.7, 0.59], [65231.6, 0.003], [65235.0, 0.612], [65235.5, 0.38]]}
{"kind": "depth", "E": 1787088300527, "U": 11315916380947, "u": 11315916395961, "recv_ms": 1787088300472, "bids": [[14189.0, 0.826], [14285.0, 2.842], [14288.5, 0.0], [14288.9, 0.0], [14289.0, 0.0], [51671.0, 0.0], [58130.1, 0.002], [60922.8, 0.002], [61355.9, 0.007], [61359.5, 0.0], [63588.5, 0.011], [63616.3, 0.02], [63810.0, 79.225], [63943.1, 0.0], [64514.2, 0.129], [64515.9, 0.12], [64543.8, 0.014], [64544.3, 0.079], [64546.6, 0.004], [64548.0, 0.45], [64548.5, 0.032], [64554.2, 0.001], [64554.7, 1.357], [64567.5, 0.001], [64570.2, 0.007], [64570.7, 1.305], [64575.6, 0.002], [64576.1, 0.022], [64576.2, 0.314], [64577.8, 0.014], [64582.1, 0.806], [64583.3, 0.0], [64584.9, 0.345], [64585.0, 37.044], [64585.1, 4.711], [64585.6, 0.089], [64586.1, 0.0], [64586.8, 0.779], [64586.9, 0.101], [64587.0, 0.021], [64587.6, 0.102], [64587.9, 0.775], [64588.2, 0.016], [64588.8, 2.713], [64588.9, 1.961], [64589.0, 53.555]], "asks": [[64589.1, 2.49], [64589.2, 0.062], [64589.8, 0.027], [64591.2, 0.001], [64591.5, 0.001], [64591.6, 0.007], [64591.8, 0.005], [64592.0, 0.013], [64592.8, 0.0], [64592.9, 0.019], [64593.5, 0.0], [64593.6, 0.035], [64593.7, 0.0], [64594.3, 0.322], [64595.2, 0.008], [64595.3, 0.197], [64595.4, 0.627], [64595.5, 0.936], [64596.9, 1.887], [64598.0, 0.122], [64598.1, 1.903], [64598.3, 0.376], [64598.4, 0.009], [64598.5, 0.001], [64599.1, 0.007], [64599.4, 1.654], [64599.5, 1.752], [64599.8, 0.078], [64600.0, 3.875], [64600.6, 0.066], [64601.8, 1.329], [64604.3, 1.263], [64607.9, 0.688], [64609.0, 0.25], [64609.5, 0.733], [64609.7, 0.542], [64610.3, 0.0], [64611.7, 2.32], [64614.5, 0.431], [64614.9, 0.376], [64615.5, 0.235], [64615.8, 3.277], [64617.6, 1.007], [64618.1, 0.218], [64626.2, 0.033], [64644.6, 2.32], [64645.1, 0.011], [64647.3, 0.37], [64647.8, 0.503], [64653.7, 0.766], [64656.0, 0.009], [64657.7, 1.03], [64664.4, 0.465], [64664.9, 0.03], [64780.0, 0.02], [64784.0, 15.091], [65235.0, 0.614], [65588.6, 0.011]]}
{"kind": "depth", "E": 1787088300629, "U": 11315916395984, "u": 11315916415496, "recv_ms": 1787088300566, "bids": [[1000.0, 35.76], [14189.0, 1.176], [14285.0, 2.52], [14285.6, 0.0], [14286.8, 0.0], [51668.0, 0.0], [58130.1, 0.002], [61359.5, 0.0], [62005.4, 0.003], [63297.3, 0.025], [63943.1, 0.0], [63964.7, 8.391], [64262.1, 5.367], [64265.4, 0.01], [64470.3, 0.052], [64556.8, 0.011], [64560.6, 0.624], [64568.0, 0.626], [64573.1, 2.324], [64574.8, 0.004], [64576.0, 0.03], [64578.0, 1.077], [64582.4, 0.009], [64584.6, 0.094], [64585.0, 36.968], [64585.2, 0.4], [64585.4, 1.433], [64585.5, 0.774], [64586.6, 0.001], [64587.7, 0.089], [64587.8, 0.0], [64587.9, 0.001], [64588.5, 0.776], [64588.6, 0.0], [64588.7, 0.318], [64588.8, 0.845], [64588.9, 1.961], [64589.0, 53.679]], "asks": [[64589.1, 2.61], [64591.6, 0.007], [64592.9, 0.019], [64594.2, 0.001], [64595.2, 0.008], [64595.3, 0.003], [64595.4, 0.24], [64596.8, 0.017], [64598.3, 0.995], [64599.4, 0.025], [64599.9, 2.389], [64600.6, 0.004], [64605.6, 0.624], [64609.0, 0.094], [64620.8, 0.011], [64630.6, 4.256], [64635.5, 0.195], [65235.0, 0.612], [65308.5, 0.0]]}
{"kind": "depth", "E": 1787088300731, "U": 11315916415669, "u": 11315916425242, "recv_ms": 1787088300668, "bids": [[1000.0, 35.76], [14189.0, 1.54], [14285.0, 2.156], [58130.1, 0.002], [61359.5, 0.0], [62005.4, 0.0], [63589.0, 0.063], [63874.6, 13.033], [63943.1, 0.0], [64122.7, 0.126], [64543.6, 1.516], [64554.7, 1.347], [64555.0, 0.016], [64560.6, 0.005], [64568.0, 0.007], [64576.2, 0.352], [64584.5, 0.004], [64584.6, 0.094], [64585.0, 36.963], [64585.2, 0.012], [64585.4, 0.651], [64585.6, 0.863], [64585.7, 0.409], [64587.7, 0.086], [64588.7, 0.317], [64588.8, 0.846], [64589.0, 53.676]], "asks": [[64589.1, 2.891], [64589.8, 0.032], [64590.1, 0.015], [64593.8, 0.084], [64596.1, 0.065], [64598.0, 0.038], [64605.0, 0.91], [64606.6, 0.004], [64622.5, 0.22], [64623.8, 0.161], [64624.2, 12.852], [64628.0, 0.159], [64635.5, 0.039], [64642.0, 0.045], [64642.3, 0.054], [64643.4, 0.107], [64645.1, 0.001], [64645.5, 0.034], [64647.2, 1.737], [64738.6, 0.001], [64751.4, 0.317], [64784.0, 0.0], [64788.6, 11.088], [65224.2, 70.675], [65235.0, 0.612], [65392.4, 24.799], [65589.1, 0.021]]}
{"kind": "depth", "E": 1787088300833, "U": 11315916425427, "u": 11315916433374, "recv_ms": 1787088300773, "bids": [[14189.0, 1.89], [14285.0, 1.806], [58130.1, 0.002], [61359.5, 0.0], [62001.6, 2.071], [62005.4, 0.003], [62049.9, 0.01], [63293.3, 7.202], [63803.0, 13.311], [63943.1, 0.0], [63971.4, 28.472], [64262.1, 5.522], [64530.7, 0.032], [64534.8, 0.016], [64536.6, 2.509], [64555.6, 1.748], [64557.8, 0.023], [64568.5, 0.317], [64569.5, 0.0], [64570.0, 0.085], [64571.9, 0.001], [64572.6, 0.526], [64573.3, 0.005], [64573.5, 0.557], [64573.8, 0.017], [64575.5, 0.002], [64576.5, 0.007], [64581.0, 0.053], [64584.4, 0.018], [64584.5, 0.0], [64584.9, 0.346], [64585.0, 36.961], [64585.4, 0.651], [64585.5, 0.309], [64585.6, 0.089], [64585.7, 1.561], [64585.8, 0.008], [64586.5, 0.0], [64586.8, 0.763], [64587.6, 0.105], [64588.5, 0.762], [64588.7, 0.338], [64588.8, 0.846], [64588.9, 0.524], [64589.0, 53.707]], "asks": [[64589.1, 2.892], [64595.5, 0.938], [64596.2, 0.088], [64598.3, 0.376], [64599.4, 0.102], [64599.7, 0.003], [64599.8, 0.001], [64603.3, 0.361], [64604.6, 0.157], [64605.6, 0.005], [64606.3, 0.003], [64606.9, 0.066], [64609.1, 0.001], [64611.5, 0.626], [64616.3, 0.101], [64616.9, 0.007], [64617.3, 0.063], [64618.8, 0.003], [64621.3, 0.015], [64624.1, 1.924], [64624.2, 10.967], [64631.4, 0.0], [64631.7, 0.005], [64636.7, 0.001], [64640.7, 0.119], [64784.0, 14.985], [64788.6, 0.003], [65235.0, 0.612], [65436.1, 5.613]]}
{"kind": "depth", "E": 1787088300935, "U": 11315916433778, "u": 11315916440274, "recv_ms": 1787088300874, "bids": [[1000.0, 35.76], [14189.0, 2.254], [14285.0, 1.442], [58130.1, 0.002], [62049.9, 0.008], [63589.0, 0.043], [63674.1, 45.25], [63700.2, 7.516], [63943.1, 0.0], [64123.2, 0.117], [64265.4, 0.0], [64266.1, 0.094], [64508.5, 0.007], [64510.7, 33.885], [64517.5, 0.0], [64524.4, 0.04], [64530.1, 0.0], [64536.6, 5.017], [64539.7, 0.683], [64548.9, 0.003], [64555.0, 0.006], [64555.4, 0.011], [64573.6, 0.003], [64584.4, 0.022], [64585.4, 0.566], [64585.8, 0.008], [64585.9, 0.087], [64586.9, 0.107], [64587.9, 0.003], [64588.3, 0.134], [64588.5, 0.76], [64589.0, 53.691]], "asks": [[64596.5, 0.011], [64597.9, 0.035], [64617.4, 0.201], [64621.3, 0.018], [64630.4, 0.006], [64633.4, 2.493], [64645.5, 0.024], [64645.8, 0.01], [64659.3, 0.0], [64690.8, 0.019], [64707.1, 0.133], [64709.2, 11.8], [64784.0, 0.0], [64788.5, 11.103], [65235.0, 0.612], [65589.1, 0.001], [65758.6, 0.759]]}
{"kind": "depth", "E": 1787088301037, "U": 11315916440418, "u": 11315916447893, "recv_ms": 1787088300974, "bids": [[1000.0, 35.76], [14189.0, 2.604], [14285.0, 1.092], [58130.1, 0.002], [60760.3, 0.052], [61359.5, 0.0], [62005.4, 0.0], [63293.3, 7.199], [63700.2, 8.142], [63943.1, 0.0], [64557.5, 0.008], [64559.8, 0.328], [64561.4, 1.705], [64564.1, 2.376], [64576.0, 0.03], [64576.1, 0.022], [64576.7, 0.526], [64577.4, 0.456], [64578.6, 3.246], [64579.5, 0.201], [64580.2, 0.558], [64580.9, 0.003], [64584.4, 0.018], [64584.9, 0.5], [64585.4, 0.024], [64585.6, 0.089], [64585.8, 0.008], [64585.9, 0.629], [64586.6, 0.0], [64586.7, 0.002], [64587.4, 0.002], [64587.8, 0.154], [64588.4, 0.0], [64588.5, 0.741], [64588.8, 1.249], [64588.9, 0.549], [64589.0, 53.614]], "asks": [[64589.1, 4.392], [64589.2, 0.001], [64593.2, 0.207], [64593.8, 0.0], [64598.0, 0.587], [64599.1, 0.0], [64599.3, 0.0], [64609.4, 0.542], [64609.7, 0.0], [64611.3, 0.931], [64615.1, 1.241], [64615.3, 0.208], [64615.9, 0.057], [64618.0, 0.044], [64618.3, 0.083], [64618.4, 2.476], [64653.7, 0.765], [64784.0, 15.159], [64788.5, 0.0], [65235.0, 0.612], [65396.5, 6.304], [65396.7, 0.004], [65581.8, 1.307], [65629.8, 1.524]]}
{"kind": "depth", "E": 1787088301139, "U": 11315916448057, "u": 11315916457200, "recv_ms": 1787088301097, "bids": [[14189.0, 2.968], [14285.0, 0.728], [58130.1, 0.002], [61359.5, 0.0], [61904.7, 0.011], [62005.4, 0.003], [63589.0, 0.063], [63943.1, 0.0], [64464.7, 0.016], [64468.7, 0.047], [64471.8, 0.234], [64475.8, 0.084], [64478.8, 2.366], [64482.8, 0.015], [64485.9, 0.003], [64487.2, 11.223], [64489.9, 0.014], [64492.9, 1.504], [64496.9, 0.013], [64500.0, 22.396], [64504.0, 0.059], [64507.0, 0.001], [64511.0, 0.038], [64514.1, 0.0], [64518.1, 1.49], [64520.4, 0.447], [64548.1, 2.961], [64556.8, 0.009], [64561.0, 0.97], [64563.7, 0.063], [64564.1, 2.319], [64568.2, 0.001], [64569.4, 0.553], [64572.2, 0.003], [64575.7, 0.155], [64575.8, 2.333], [64576.3, 0.081], [64577.4, 0.451], [64578.1, 0.0], [64578.6, 2.319], [64578.8, 0.937], [64579.5, 0.201], [64580.2, 0.558], [64582.1, 0.804], [64582.6, 0.218], [64582.9, 0.008], [64583.6, 0.0], [64584.0, 0.265], [64584.1, 0.0], [64584.3, 0.001], [64585.0, 36.939], [64586.0, 0.098], [64587.5, 0.0], [64589.0, 53.652]], "asks": [[64589.1, 3.172], [64593.0, 1.892], [64593.7, 0.084], [64594.9, 0.003], [64595.9, 0.394], [64597.7, 0.001], [64598.2, 0.445], [64599.7, 0.002], [64600.6, 0.002], [64601.2, 0.404], [64601.8, 1.331], [64604.6, 0.159], [64607.5, 0.004], [64609.4, 0.0], [64609.7, 0.542], [64610.7, 0.0], [64610.9, 0.0], [64611.2, 0.938], [64611.3, 0.004], [64614.4, 0.008], [64618.3, 0.237], [64618.4, 2.322], [64649.7, 0.366], [64653.7, 0.766], [64776.6, 0.0], [64777.8, 0.003], [65235.0, 0.612], [65589.1, 0.021], [66522.5, 0.0]]}
{"kind": "depth", "E": 1787088301241, "U": 11315916457358, "u": 11315916466624, "recv_ms": 1787088301178, "bids": [[1000.0, 35.76], [14089.0, 0.042], [14189.0, 3.234], [14285.0, 0.42], [51671.0, 0.0], [58130.1, 0.002], [61355.8, 0.012], [61355.9, 0.009], [61904.7, 0.013], [62005.4, 0.0], [63684.5, 2.353], [63943.1, 0.0], [64266.1, 0.104], [64385.1, 0.727], [64469.9, 2.161], [64484.6, 0.003], [64510.8, 6.103], [64555.4, 0.001], [64555.6, 1.748], [64555.8, 0.337], [64562.2, 0.143], [64563.0, 1.972], [64584.2, 0.003], [64585.2, 0.001], [64586.0, 0.088], [64586.4, 0.001], [64586.9, 0.101], [64587.3, 0.084], [64587.4, 0.007], [64588.2, 0.006], [64588.5, 0.731], [64589.0, 53.652]], "asks": [[64618.3, 0.733], [64618.4, 2.322], [64618.5, 0.154], [64624.0, 2.195], [64624.1, 0.039], [64643.3, 0.213], [64645.8, 0.0], [64646.0, 0.003], [64646.3, 0.013], [64650.8, 0.0], [64678.4, 0.009], [64701.4, 0.307], [64733.1, 2.092], [64778.2, 4.795], [64784.0, 0.0], [64788.4, 11.179], [65235.0, 0.612], [65306.5, 0.765], [65397.1, 0.763], [65467.0, 0.869]]}
{"kind": "depth", "E": 1787088301343, "U": 11315916467085, "u": 11315916474932, "recv_ms": 1787088301280, "bids": [[1000.0, 35.76], [14089.0, 0.252], [14189.0, 3.178], [14285.0, 0.266], [58130.1, 0.002], [61359.5, 0.0], [62005.4, 0.003], [63589.0, 0.043], [63943.1, 0.0], [64266.0, 5.018], [64490.0, 1.087], [64543.0, 0.009], [64555.8, 0.327], [64556.0, 0.461], [64572.5, 0.004], [64578.0, 1.602], [64580.7, 0.306], [64583.3, 0.04], [64584.2, 0.003], [64585.0, 36.899], [64585.5, 0.324], [64587.6, 0.107], [64588.3, 0.125], [64588.5, 0.73], [64588.9, 0.526], [64589.0, 53.652]], "asks": [[64589.1, 3.171], [64593.7, 0.0], [64598.0, 0.038], [64598.2, 0.444], [64598.4, 0.009], [64599.3, 0.001], [64599.4, 0.566], [64599.5, 1.744], [64599.8, 0.094], [64606.9, 0.059], [64607.3, 0.009], [64611.4, 0.018], [64615.8, 2.324], [64634.4, 0.308], [64646.3, 0.003], [64646.4, 0.017], [64686.0, 0.008], [64717.7, 0.0], [64731.3, 0.297], [64784.0, 0.0], [64788.4, 11.083], [64912.1, 0.001], [65235.0, 0.612], [65589.1, 0.001], [65696.0, 3.272]]}
{"kind": "depth", "E": 1787088301445, "U": 11315916475088, "u": 11315916482643, "recv_ms": 1787088301384, "bids": [[14089.0, 0.476], [14189.0, 3.08], [14285.0, 0.14], [51671.0, 0.0], [58130.1, 0.002], [61359.5, 0.0], [63620.2, 0.008], [63745.4, 28.782], [63943.1, 0.0], [64468.1, 0.0], [64584.1, 0.0], [64585.4, 0.016], [64585.8, 0.016], [64589.0, 53.651]], "asks": [[64616.3, 1.082], [65235.0, 0.612], [65474.0, 0.688], [65527.6, 6.551], [65581.8, 0.654], [65700.0, 30.989], [65773.0, 1.972], [65880.8, 0.006]]}
{"kind": "depth", "E": 1787088301547, "U": 11315916482793, "u": 11315916490611, "recv_ms": 1787088301484, "bids": [[1000.0, 35.76], [14089.0, 0.728], [14189.0, 2.94], [14285.0, 0.028], [51671.2, 0.0], [58130.1, 0.002], [61355.8, 0.01], [61355.9, 0.011], [62005.4, 0.0], [63238.3, 2.241], [63293.3, 7.196], [63589.0, 0.063], [63943.1, 0.0], [64266.0, 5.019], [64266.1, 0.094], [64468.3, 0.085], [64469.5, 2.319], [64556.0, 0.451], [64556.2, 0.011], [64572.3, 0.003], [64579.0, 0.166], [64584.1, 0.0], [64587.0, 0.021], [64587.2, 0.002], [64589.0, 53.681]], "asks": [[64590.5, 0.005], [64593.4, 0.002], [64593.8, 0.084], [64594.1, 0.0], [64597.1, 0.31], [64601.2, 0.369], [64604.2, 0.242], [64612.0, 0.113], [64615.2, 0.001], [64618.9, 0.018], [64646.4, 0.007], [64646.6, 0.015], [64653.7, 0.765], [64709.2, 11.717], [64709.7, 0.177], [64784.0, 15.183], [64788.4, 0.0], [64912.1, 0.002], [65235.0, 0.612], [65435.7, 0.763], [65589.1, 0.021]]}
{"kind": "depth", "E": 1787088301649, "U": 11315916490776, "u": 11315916499568, "recv_ms": 1787088301588, "bids": [[1000.0, 35.76], [14089.0, 1.064], [14189.0, 2.632], [14285.0, 0.0], [58130.1, 0.002], [61359.5, 0.0], [62005.4, 0.003], [62593.0, 1.002], [63297.3, 0.028], [63745.4, 28.39], [63943.1, 0.0], [64262.2, 3.396], [64426.3, 0.001], [64426.4, 0.303], [64430.3, 3.25], [64443.2, 0.008], [64447.2, 3.036], [64541.4, 0.251], [64543.8, 0.092], [64556.2, 0.001], [64556.3, 0.023], [64578.7, 2.189], [64584.0, 0.265], [64584.1, 0.0], [64586.0, 0.088], [64586.9, 0.107], [64587.0, 0.016], [64588.9, 0.046], [64589.0, 54.167]], "asks": [[64589.1, 3.252], [64589.9, 0.002], [64590.5, 0.001], [64591.1, 0.004], [64618.2, 0.383], [64618.5, 0.0], [64618.6, 0.161], [64625.6, 0.028], [64646.6, 0.005], [64646.7, 0.011], [64653.7, 0.766], [64784.0, 15.187], [64788.3, 0.0], [65235.0, 0.614], [65333.9, 0.537], [65344.8, 0.593], [65396.5, 6.563], [65538.6, 1.218], [65784.0, 1.032], [65840.1, 1.3]]}
{"kind": "depth", "E": 1787088301751, "U": 11315916499595, "u": 11315916506221, "recv_ms": 1787088301690, "bids": [[14089.0, 1.414], [14189.0, 2.282], [58130.1, 0.002], [61359.5, 0.0], [61947.7, 2.0], [62005.4, 0.0], [63422.5, 13.679], [63589.0, 0.043], [63781.6, 0.235], [63943.1, 0.0], [64430.3, 4.536], [64447.2, 3.713], [64552.2, 0.003], [64552.3, 0.063], [64552.4, 0.0], [64555.6, 1.746], [64555.7, 0.005], [64555.8, 0.325], [64556.3, 0.013], [64556.4, 0.011], [64585.0, 36.642], [64587.0, 0.026]], "asks": [[64589.1, 3.253], [64592.3, 0.003], [64601.9, 1.443], [64605.0, 0.903], [64618.5, 0.0], [64618.6, 0.007], [64646.7, 0.001], [64646.8, 0.345], [64672.2, 0.049], [64754.2, 0.05], [64754.5, 0.009], [64784.0, 0.0], [64788.2, 11.044], [65235.0, 0.612], [65589.1, 0.001]]}
{"kind": "depth", "E": 1787088301853, "U": 11315916506369, "u": 11315916512733, "recv_ms": 1787088301791, "bids": [[1000.0, 35.76], [14089.0, 1.764], [14189.0, 1.932], [51671.0, 0.0], [58130.1, 0.002], [61302.5, 3.001], [61359.5, 0.0], [62005.4, 0.003], [63781.3, 0.436], [63943.1, 0.0], [64266.1, 0.094], [64387.5, 0.002], [64390.1, 0.0], [64391.5, 6.982], [64430.3, 4.573], [64447.2, 3.772], [64549.2, 0.039], [64549.3, 0.0], [64566.4, 0.009], [64570.4, 1.094], [64577.6, 0.036], [64584.0, 0.265], [64589.0, 54.195]], "asks": [[64598.0, 0.587], [64598.3, 0.377], [64599.3, 0.0], [64599.4, 0.017], [64724.3, 0.003], [64732.5, 5.407], [64741.2, 0.013], [64749.4, 7.888], [64788.2, 14.771], [65235.0, 0.612], [65371.1, 0.772], [65629.8, 0.003]]}
{"kind": "depth", "E": 1787088301955, "U": 11315916512870, "u": 11315916518975, "recv_ms": 1787088301891, "bids": [[1000.0, 35.76], [14089.0, 2.128], [14189.0, 1.568], [58130.1, 0.002], [63589.0, 0.063], [63678.2, 0.816], [63749.3, 0.708], [63943.1, 0.0], [64122.6, 0.001], [64122.7, 0.009], [64575.3, 0.003], [64579.3, 0.223]], "asks": [[64607.9, 0.648], [64610.3, 0.0], [64613.6, 3.772], [64617.9, 0.003], [64646.8, 0.335], [64646.9, 0.01], [64659.6, 0.0], [64662.7, 0.004], [64669.3, 0.0], [65396.5, 6.716], [65467.0, 0.26], [65589.1, 0.021]]}
{"kind": "depth", "E": 1787088302057, "U": 11315916519123, "u": 11315916526151, "recv_ms": 1787088301994, "bids": [[14089.0, 2.478], [14189.0, 1.218], [58130.1, 0.002], [60657.2, 4.0], [61359.5, 0.0], [62005.4, 0.0], [63597.9, 0.0], [63680.8, 80.766], [63943.1, 0.0], [64123.3, 0.122], [64266.1, 0.104], [64391.5, 6.977], [64430.3, 4.594], [64447.2, 3.783], [64495.3, 34.572], [64510.7, 0.025], [64510.8, 1.311], [64556.4, 0.001], [64556.5, 0.01], [64565.8, 0.024], [64577.4, 0.451], [64578.6, 3.246], [64578.8, 0.01], [64583.9, 0.093], [64585.0, 36.629], [64588.9, 0.202], [64589.0, 54.208]], "asks": [[64591.7, 1.652], [64593.4, 0.086], [64597.6, 0.008], [64618.3, 0.733], [64618.5, 0.0], [64618.7, 0.501], [64623.9, 5.866], [64624.0, 0.31], [64732.5, 5.407], [64745.2, 10.521], [64749.4, 0.0], [64788.2, 13.789], [65235.0, 0.612]]}
{"kind": "depth", "E": 1787088302159, "U": 11315916526189, "u": 11315916556505, "recv_ms": 1787088302105, "bids": [[1000.0, 35.76], [14089.0, 2.534], [14090.1, 0.014], [14091.6, 0.028], [14093.3, 0.014], [14093.8, 0.252], [14188.9, 0.014], [14189.0, 0.868], [32270.2, 0.007], [32294.8, 0.007], [32296.9, 0.007], [32332.9, 0.028], [32333.0, 1.333], [50000.0, 233.343], [51672.0, 0.0], [51675.0, 0.0], [58130.1, 0.0], [58131.0, 0.01], [58134.4, 0.002], [60597.9, 0.002], [61364.1, 0.0], [62010.0, 1.629], [63582.3, 0.013], [63583.2, 0.0], [63586.8, 2.605], [63588.3, 0.0], [63588.5, 0.009], [63588.7, 0.633], [63589.0, 0.043], [63590.3, 0.004], [63591.6, 0.008], [63592.9, 0.041], [63593.5, 0.002], [63593.8, 0.008], [63943.1, 0.0], [63947.9, 0.151], [64068.1, 0.157], [64074.9, 0.003], [64077.0, 0.049], [64132.7, 0.05], [64139.5, 0.003], [64176.0, 0.09], [64197.3, 0.0], [64204.1, 0.003], [64211.1, 0.467], [64261.9, 0.056], [64268.6, 0.002], [64326.5, 0.003], [64333.2, 2.515], [64358.1, 2.384], [64386.2, 0.002], [64391.0, 0.009], [64397.8, 11.662], [64398.5, 0.0], [64401.2, 0.156], [64401.3, 0.158], [64401.4, 0.0], [64401.6, 2.886], [64401.7, 0.0], [64402.8, 0.111], [64403.0, 0.351], [64403.2, 0.234], [64408.2, 0.001], [64412.8, 2.003], [64416.0, 0.034], [64430.2, 3.253], [64445.0, 2.021], [64445.1, 0.001], [64450.7, 0.015], [64451.0, 0.0], [64453.1, 0.0], [64453.2, 0.0], [64454.3, 0.001], [64455.4, 1.594], [64455.6, 0.0], [64460.7, 0.786], [64462.4, 0.003], [64463.5, 0.722], [64464.5, 0.769], [64465.4, 0.393], [64468.3, 0.0], [64470.4, 1.353], [64471.1, 0.035], [64473.2, 0.629], [64473.8, 0.245], [64476.0, 0.449], [64483.4, 0.068], [64487.5, 0.003], [64488.4, 0.0], [64492.0, 0.0], [64492.1, 0.936], [64492.8, 0.007], [64493.9, 0.063], [64494.2, 0.025], [64495.3, 0.26], [64495.4, 0.022], [64496.0, 0.02], [64497.1, 0.03], [64498.0, 0.597], [64499.7, 0.009], [64501.7, 0.063], [64501.8, 0.004], [64504.8, 0.003], [64504.9, 0.001], [64505.8, 11.499], [64506.6, 6.974], [64506.9, 0.03], [64508.0, 2.32], [64508.1, 4.655], [64508.6, 0.012], [64509.1, 0.002], [64509.4, 0.155], [64510.0, 2.015], [64512.0, 0.118], [64512.9, 34.753], [64514.0, 0.011], [64514.3, 0.026], [64515.5, 0.001], [64515.7, 1.473], [64515.8, 2.32], [64515.9, 0.094], [64516.5, 0.036], [64517.4, 0.063], [64518.1, 0.013], [64519.6, 1.433], [64520.2, 2.044], [64520.5, 0.383], [64520.6, 0.046], [64521.3, 0.171], [64522.7, 0.387], [64523.6, 0.01], [64524.4, 0.009], [64524.5, 2.321], [64525.0, 0.22], [64525.3, 0.003], [64525.5, 0.345], [64526.4, 0.031], [64527.0, 0.026], [64527.5, 0.0], [64527.6, 0.003], [64527.8, 0.002], [64528.8, 1.244], [64529.2, 0.082], [64529.5, 1.472], [64529.6, 0.002], [64530.0, 0.001], [64530.1, 0.003], [64530.4, 0.243], [64530.7, 0.032], [64531.0, 0.033], [64531.2, 1.443], [64532.8, 0.0], [64533.1, 0.0], [64533.3, 0.07], [64533.5, 0.221], [64533.8, 2.031], [64534.6, 3.576], [64534.7, 0.017], [64534.8, 0.004], [64535.1, 0.469], [64535.2, 0.001], [64535.3, 0.0], [64535.5, 0.621], [64535.8, 0.005], [64536.6, 5.019], [64536.7, 0.093], [64536.9, 0.251], [64537.2, 0.004], [64539.0, 0.001], [64539.5, 0.329], [64539.7, 0.682], [64540.4, 0.0], [64541.8, 0.002], [64542.0, 0.004], [64542.1, 0.024], [64542.2, 2.148], [64542.3, 0.0], [64542.6, 1.03], [64542.7, 0.0], [64542.8, 0.018], [64542.9, 0.0], [64543.1, 0.059], [64543.2, 0.656], [64543.3, 0.029], [64543.5, 0.31], [64543.7, 2.879], [64543.8, 0.013], [64543.9, 0.013], [64544.2, 0.018], [64544.7, 0.007], [64544.9, 0.014], [64545.1, 0.003], [64545.4, 0.052], [64545.5, 0.778], [64545.6, 0.011], [64546.2, 0.083], [64546.4, 0.0], [64546.6, 0.0], [64546.8, 0.007], [64547.1, 0.015], [64547.2, 0.039], [64547.7, 1.279], [64548.2, 0.079], [64548.3, 0.033], [64548.4, 0.211], [64548.5, 0.03], [64548.6, 0.031], [64548.8, 0.005], [64548.9, 0.002], [64549.0, 0.001], [64549.8, 2.148], [64549.9, 0.007], [64550.0, 0.259], [64550.3, 0.0], [64551.1, 0.002], [64551.4, 0.016], [64551.5, 0.407], [64552.3, 0.123], [64553.2, 1.202], [64553.7, 0.001], [64553.8, 0.0], [64554.0, 0.027], [64554.1, 0.005], [64554.5, 3.878], [64554.8, 0.002], [64554.9, 0.007], [64555.0, 0.005], [64555.6, 1.742], [64555.9, 0.45], [64556.0, 0.002], [64556.9, 0.018], [64557.0, 0.014], [64557.1, 0.014], [64557.2, 0.001], [64557.5, 0.002], [64557.6, 0.0], [64557.7, 0.008], [64557.8, 0.019], [64558.4, 0.138], [64558.7, 0.004], [64559.0, 0.696], [64559.1, 0.003], [64559.3, 0.011], [64559.4, 0.018], [64559.7, 0.008], [64559.8, 0.322], [64560.0, 0.083], [64560.1, 0.07], [64560.2, 1.614], [64560.3, 0.01], [64560.5, 0.107], [64560.8, 0.002], [64560.9, 0.318], [64561.2, 0.0], [64561.4, 0.001], [64561.5, 2.676], [64561.7, 1.682], [64562.1, 0.072], [64562.2, 0.147], [64562.5, 0.276], [64562.7, 0.198], [64562.9, 0.18], [64563.1, 2.451], [64563.2, 0.031], [64563.3, 0.101], [64563.5, 0.0], [64563.7, 0.006], [64563.8, 0.685], [64563.9, 0.334], [64564.1, 2.32], [64564.4, 0.034], [64564.5, 0.053], [64565.6, 0.015], [64565.7, 0.097], [64565.8, 0.023], [64565.9, 0.369], [64566.0, 0.122], [64566.2, 0.031], [64566.4, 0.022], [64566.6, 0.009], [64566.7, 0.018], [64566.9, 0.0], [64567.7, 0.002], [64568.1, 0.005], [64568.5, 1.008], [64568.6, 0.034], [64568.7, 0.061], [64568.9, 0.057], [64569.3, 0.049], [64569.4, 0.492], [64569.6, 0.008], [64569.7, 0.005], [64569.8, 0.011], [64569.9, 0.005], [64570.0, 0.004], [64570.3, 0.032], [64570.5, 2.343], [64570.7, 1.304], [64570.8, 0.471], [64570.9, 0.002], [64571.0, 0.327], [64571.4, 0.023], [64571.6, 0.001], [64572.0, 0.445], [64572.2, 0.001], [64572.4, 0.0], [64572.5, 0.003], [64572.6, 0.41], [64572.8, 0.122], [64573.1, 2.323], [64573.2, 0.093], [64573.4, 0.0], [64573.5, 0.0], [64573.6, 0.002], [64573.7, 0.147], [64573.9, 0.003], [64574.0, 0.019], [64574.1, 0.035], [64574.2, 0.026], [64574.3, 0.001], [64574.4, 0.025], [64574.5, 0.042], [64574.7, 0.0], [64575.0, 0.902], [64575.1, 0.022], [64575.4, 0.02], [64575.6, 0.0], [64575.9, 0.991], [64576.1, 0.014], [64576.2, 0.351], [64576.3, 0.081], [64576.5, 0.0], [64576.7, 0.31], [64576.9, 0.08], [64577.0, 2.548], [64577.1, 0.082], [64577.2, 1.237], [64577.3, 0.035], [64577.6, 0.002], [64577.7, 0.003], [64577.9, 0.0], [64578.0, 1.549], [64578.2, 0.139], [64578.4, 0.0], [64578.5, 0.013], [64578.6, 2.319], [64578.7, 1.57], [64578.8, 0.011], [64578.9, 0.216], [64579.0, 0.02], [64579.1, 0.14], [64579.2, 0.11], [64579.3, 0.78], [64579.4, 0.071], [64579.6, 0.224], [64579.7, 0.176], [64579.9, 0.001], [64580.0, 0.488], [64580.1, 0.802], [64580.2, 0.016], [64580.4, 0.035], [64580.5, 0.007], [64580.6, 0.001], [64580.9, 0.004], [64581.0, 0.052], [64581.2, 0.226], [64581.3, 0.034], [64581.4, 0.019], [64581.5, 0.0], [64581.7, 0.032], [64581.8, 0.022], [64581.9, 0.037], [64582.0, 0.916], [64582.1, 0.804], [64582.2, 0.003], [64582.3, 0.0], [64582.5, 0.332], [64582.6, 0.0], [64582.7, 0.0], [64582.8, 0.22], [64582.9, 0.011], [64583.1, 0.147], [64583.2, 0.0], [64583.3, 0.967], [64583.4, 0.602], [64583.8, 0.001], [64583.9, 0.005], [64584.0, 0.181], [64584.1, 0.014], [64584.4, 0.232], [64584.5, 0.683], [64584.6, 0.01], [64584.8, 0.008], [64584.9, 0.48], [64585.0, 35.815], [64585.1, 3.389], [64585.2, 0.249], [64585.3, 6.312], [64585.4, 1.254], [64585.5, 0.642], [64585.6, 0.005], [64585.7, 0.001], [64585.8, 0.0], [64585.9, 0.003], [64586.0, 1.406], [64586.1, 0.111], [64586.3, 0.005], [64586.4, 0.035], [64586.5, 0.013], [64586.6, 0.002], [64586.7, 0.0], [64586.8, 0.6], [64586.9, 0.084], [64587.0, 0.016], [64587.1, 0.001], [64587.3, 0.085], [64587.5, 0.309], [64587.6, 0.002], [64587.7, 0.397], [64587.9, 0.004], [64588.0, 0.044], [64588.1, 2.323], [64588.2, 0.732], [64588.3, 0.088], [64588.5, 0.706], [64588.6, 0.001], [64588.7, 0.085], [64588.8, 0.017], [64588.9, 0.157], [64589.0, 0.879], [64589.1, 0.621], [64589.2, 1.884], [64589.3, 0.075], [64589.4, 0.001], [64589.5, 0.001], [64589.6, 0.008], [64589.7, 0.0], [64589.8, 0.0], [64589.9, 0.0], [64590.0, 0.005], [64590.1, 1.476], [64590.2, 0.676], [64590.3, 0.001], [64590.4, 0.001], [64590.5, 0.005], [64590.6, 0.001], [64590.7, 0.001], [64590.8, 2.32], [64590.9, 0.008], [64591.0, 0.001], [64591.1, 0.001], [64591.2, 0.0], [64591.3, 0.001], [64591.4, 0.001], [64591.5, 0.004], [64591.6, 0.731], [64591.7, 0.629], [64591.8, 0.044], [64591.9, 0.006], [64592.0, 0.002], [64592.1, 0.001], [64592.2, 0.0], [64592.3, 0.0], [64592.4, 0.0], [64592.5, 0.2], [64592.6, 0.002], [64592.7, 0.001], [64592.8, 0.0], [64592.9, 0.001], [64593.0, 0.003], [64593.1, 0.084], [64593.2, 0.001], [64593.3, 0.038], [64593.4, 0.002], [64593.5, 3.081], [64593.6, 0.511], [64593.7, 0.059], [64593.8, 33.006]], "asks": [[64589.1, 0.0], [64589.2, 0.0], [64589.6, 0.0], [64589.7, 0.0], [64589.8, 0.0], [64589.9, 0.0], [64590.0, 0.0], [64590.1, 0.0], [64590.2, 0.0], [64590.4, 0.0], [64590.5, 0.0], [64590.7, 0.0], [64590.8, 0.0], [64590.9, 0.0], [64591.1, 0.0], [64591.2, 0.0], [64591.3, 0.0], [64591.5, 0.0], [64591.6, 0.0], [64591.7, 0.0], [64591.8, 0.0], [64591.9, 0.0], [64592.0, 0.0], [64592.2, 0.0], [64592.3, 0.0], [64592.4, 0.0], [64592.5, 0.0], [64592.6, 0.0], [64592.7, 0.0], [64592.9, 0.0], [64593.0, 0.0], [64593.2, 0.0], [64593.3, 0.0], [64593.4, 0.0], [64593.5, 0.0], [64593.6, 0.0], [64593.8, 0.0], [64593.9, 10.303], [64594.0, 0.003], [64594.1, 0.001], [64594.2, 0.001], [64594.3, 0.002], [64594.5, 0.0], [64594.6, 0.0], [64594.7, 0.0], [64594.8, 0.0], [64594.9, 0.002], [64595.0, 0.001], [64595.1, 0.0], [64595.2, 0.007], [64595.3, 0.001], [64595.4, 0.086], [64595.5, 0.015], [64595.6, 0.003], [64595.7, 0.001], [64595.8, 0.084], [64595.9, 0.0], [64596.0, 0.002], [64596.1, 0.0], [64596.2, 0.087], [64596.3, 0.001], [64596.4, 0.002], [64596.5, 0.013], [64596.6, 0.003], [64596.7, 0.085], [64596.8, 0.001], [64596.9, 0.312], [64597.0, 0.002], [64597.1, 0.0], [64597.2, 0.0], [64597.3, 0.001], [64597.4, 0.085], [64597.6, 0.004], [64597.7, 0.001], [64597.8, 0.013], [64597.9, 0.105], [64598.0, 0.006], [64598.1, 0.018], [64598.2, 0.001], [64598.3, 0.001], [64598.4, 0.093], [64598.5, 0.0], [64598.6, 0.013], [64598.7, 0.087], [64598.8, 0.2], [64598.9, 0.001], [64599.1, 0.084], [64599.2, 0.007], [64599.3, 0.0], [64599.4, 0.017], [64599.5, 0.001], [64599.6, 0.002], [64599.7, 0.0], [64599.8, 0.005], [64599.9, 0.669], [64600.0, 3.703], [64600.1, 0.004], [64600.2, 0.002], [64600.3, 0.0], [64600.4, 0.022], [64600.5, 0.001], [64600.7, 0.015], [64600.8, 0.001], [64600.9, 0.325], [64601.0, 0.001], [64601.1, 0.311], [64601.2, 0.059], [64601.3, 0.0], [64601.4, 0.001], [64601.6, 0.02], [64601.7, 0.0], [64601.8, 0.003], [64601.9, 1.176], [64602.0, 0.127], [64602.1, 0.052], [64602.2, 0.001], [64602.3, 0.003], [64602.5, 0.055], [64602.6, 0.016], [64602.7, 0.0], [64602.8, 0.111], [64602.9, 0.376], [64603.0, 0.035], [64603.1, 0.409], [64603.2, 0.005], [64603.3, 0.015], [64603.5, 0.003], [64603.7, 0.0], [64603.8, 0.756], [64603.9, 0.383], [64604.0, 0.371], [64604.1, 0.559], [64604.2, 0.295], [64604.3, 1.26], [64604.4, 0.782], [64604.5, 1.393], [64604.6, 0.154], [64604.7, 0.263], [64604.8, 0.149], [64605.0, 0.004], [64605.1, 0.779], [64605.2, 0.281], [64605.3, 0.0], [64605.5, 0.217], [64605.6, 0.005], [64605.7, 0.001], [64606.0, 0.005], [64606.1, 0.023], [64606.2, 0.75], [64606.3, 0.024], [64606.4, 0.002], [64606.6, 0.017], [64606.8, 0.074], [64606.9, 0.002], [64607.0, 0.002], [64607.1, 0.291], [64607.3, 0.002], [64607.5, 0.008], [64607.7, 0.001], [64607.8, 0.024], [64607.9, 1.616], [64608.0, 0.013], [64608.1, 0.003], [64608.4, 0.0], [64608.5, 0.078], [64608.6, 0.019], [64608.7, 0.258], [64608.8, 0.213], [64608.9, 0.311], [64609.0, 1.98], [64609.1, 3.137], [64609.2, 0.002], [64609.3, 0.0], [64609.4, 1.24], [64609.5, 0.012], [64609.6, 0.001], [64609.7, 0.0], [64609.9, 0.005], [64610.0, 0.006], [64610.1, 0.005], [64610.2, 0.055], [64610.6, 0.129], [64610.7, 0.038], [64610.8, 0.448], [64610.9, 0.004], [64611.0, 1.343], [64611.1, 0.015], [64611.2, 0.011], [64611.4, 0.164], [64611.5, 0.08], [64611.6, 0.702], [64611.7, 2.31], [64612.0, 0.346], [64612.1, 0.043], [64612.3, 0.001], [64612.4, 0.33], [64612.6, 0.337], [64612.9, 0.007], [64613.1, 2.352], [64613.2, 0.001], [64613.3, 0.127], [64613.4, 0.086], [64613.5, 0.014], [64613.6, 3.732], [64613.8, 0.007], [64613.9, 0.0], [64614.0, 0.127], [64614.2, 0.099], [64614.3, 0.002], [64614.4, 0.01], [64614.5, 0.456], [64614.6, 0.0], [64614.7, 0.0], [64614.8, 0.042], [64615.0, 0.002], [64615.1, 0.004], [64615.2, 0.002], [64615.3, 1.134], [64615.5, 0.07], [64615.6, 0.542], [64615.7, 2.99], [64615.8, 0.005], [64615.9, 0.049], [64616.1, 0.052], [64616.2, 0.03], [64616.3, 0.102], [64616.6, 0.017], [64616.7, 0.0], [64616.8, 0.002], [64616.9, 1.237], [64617.0, 0.318], [64617.3, 0.0], [64617.4, 0.105], [64617.5, 0.0], [64617.6, 1.008], [64617.8, 0.001], [64618.0, 0.014], [64618.1, 0.098], [64618.2, 1.156], [64618.3, 0.013], [64618.4, 0.003], [64618.6, 0.564], [64618.7, 0.311], [64618.8, 0.003], [64618.9, 0.027], [64619.0, 0.002], [64619.2, 1.184], [64619.4, 0.004], [64619.5, 0.006], [64619.7, 0.007], [64619.8, 0.083], [64620.0, 0.165], [64620.1, 0.108], [64620.2, 0.444], [64620.4, 0.022], [64620.5, 0.04], [64620.7, 0.001], [64620.8, 0.068], [64620.9, 1.49], [64621.0, 0.019], [64621.3, 0.003], [64621.6, 0.0], [64621.7, 0.007], [64621.9, 0.322], [64622.0, 0.001], [64622.1, 0.31], [64622.2, 0.181], [64622.4, 0.002], [64622.6, 0.045], [64622.7, 0.007], [64623.0, 0.03], [64623.2, 0.123], [64623.3, 2.332], [64623.4, 0.0], [64623.5, 0.003], [64623.8, 2.026], [64623.9, 3.981], [64624.0, 0.311], [64624.2, 0.957], [64624.3, 0.135], [64624.4, 0.64], [64624.5, 0.015], [64624.6, 0.0], [64624.7, 0.079], [64624.8, 0.375], [64625.0, 0.15], [64625.1, 0.689], [64625.2, 0.003], [64625.3, 0.072], [64625.6, 0.122], [64625.7, 0.222], [64625.9, 0.163], [64626.0, 0.001], [64626.1, 0.023], [64626.2, 0.324], [64626.4, 0.005], [64626.6, 0.001], [64627.1, 0.011], [64627.2, 0.183], [64627.3, 0.906], [64627.4, 10.393], [64627.5, 0.043], [64627.6, 0.197], [64627.7, 1.196], [64627.8, 0.2], [64628.0, 0.156], [64628.1, 0.133], [64628.2, 0.154], [64628.4, 0.13], [64628.7, 0.001], [64628.8, 0.451], [64628.9, 0.0], [64629.1, 0.003], [64629.3, 1.508], [64629.4, 0.009], [64629.9, 1.684], [64630.1, 0.0], [64630.2, 0.002], [64630.4, 0.036], [64630.5, 0.631], [64630.6, 0.016], [64630.7, 0.015], [64630.8, 0.042], [64631.2, 0.0], [64631.3, 0.059], [64631.7, 0.001], [64632.0, 0.005], [64632.4, 0.019], [64632.5, 0.09], [64632.6, 2.401], [64632.7, 0.002], [64632.9, 1.64], [64633.0, 4.86], [64633.2, 0.0], [64633.3, 0.003], [64633.7, 0.031], [64633.9, 0.001], [64634.0, 0.001], [64634.3, 1.042], [64634.6, 0.0], [64635.2, 0.013], [64635.5, 0.001], [64635.6, 0.0], [64635.7, 0.007], [64635.9, 0.006], [64636.0, 0.295], [64636.4, 0.04], [64636.7, 0.001], [64636.8, 0.015], [64636.9, 0.05], [64637.4, 0.109], [64637.6, 0.001], [64637.9, 0.028], [64638.1, 0.406], [64638.4, 0.0], [64638.5, 0.001], [64638.6, 0.009], [64639.0, 0.209], [64639.2, 0.452], [64639.3, 0.019], [64639.5, 0.002], [64639.6, 0.01], [64639.7, 1.488], [64639.8, 0.003], [64640.1, 0.035], [64640.2, 0.63], [64640.4, 2.319], [64640.7, 0.05], [64640.8, 0.01], [64641.1, 0.001], [64641.2, 0.447], [64641.4, 0.001], [64641.6, 0.06], [64641.7, 0.003], [64642.0, 1.803], [64642.1, 0.025], [64642.2, 0.392], [64643.0, 0.005], [64643.1, 0.701], [64643.3, 0.003], [64643.4, 0.108], [64644.0, 3.561], [64644.6, 0.001], [64645.0, 0.032], [64645.4, 0.014], [64645.5, 0.093], [64645.6, 0.001], [64645.7, 0.304], [64646.1, 0.015], [64647.0, 0.05], [64647.1, 2.731], [64648.6, 0.023], [64648.7, 0.001], [64649.6, 0.071], [64649.7, 0.815], [64649.8, 0.033], [64649.9, 0.0], [64650.5, 0.631], [64650.7, 0.211], [64652.4, 0.004], [64652.8, 1.451], [64653.5, 1.471], [64653.6, 0.002], [64653.7, 0.766], [64655.5, 0.063], [64656.0, 0.077], [64656.2, 0.0], [64656.3, 0.003], [64657.0, 0.0], [64657.7, 1.004], [64657.9, 6.713], [64658.6, 0.0], [64659.8, 1.325], [64660.0, 0.047], [64660.1, 2.495], [64660.6, 4.599], [64660.8, 0.001], [64662.0, 0.017], [64662.4, 0.0], [64662.7, 0.0], [64662.8, 0.229], [64663.1, 0.724], [64664.8, 0.31], [64667.4, 0.004], [64667.6, 0.001], [64667.8, 0.0], [64668.1, 0.31], [64668.9, 0.001], [64669.3, 0.05], [64670.0, 0.02], [64671.4, 0.1], [64671.5, 0.062], [64671.9, 0.103], [64672.0, 2.153], [64672.2, 0.007], [64674.0, 0.001], [64674.9, 0.017], [64675.2, 1.082], [64675.3, 0.001], [64676.3, 0.14], [64678.4, 0.186], [64679.2, 0.0], [64679.6, 3.151], [64684.5, 0.057], [64687.2, 0.0], [64687.3, 2.509], [64688.8, 0.003], [64690.9, 0.027], [64692.3, 0.0], [64692.4, 0.094], [64693.7, 0.0], [64694.1, 0.0], [64695.0, 0.116], [64699.3, 0.003], [64700.0, 1.851], [64704.1, 31.682], [64705.8, 0.098], [64706.0, 0.628], [64706.3, 0.001], [64707.1, 0.021], [64708.2, 0.0], [64709.7, 0.093], [64710.5, 0.0], [64711.1, 0.0], [64711.2, 0.0], [64711.4, 0.028], [64711.5, 0.12], [64711.8, 0.001], [64713.0, 2.395], [64713.8, 2.322], [64714.2, 0.003], [64715.6, 1.237], [64726.0, 1.239], [64726.3, 2.488], [64726.4, 0.242], [64729.8, 2.323], [64753.5, 0.004], [64761.3, 0.038], [64762.4, 0.212], [64773.0, 0.196], [64778.8, 0.078], [64785.5, 0.028], [64792.4, 0.004], [64843.3, 0.002], [64850.1, 0.014], [64907.9, 0.749], [64912.0, 0.209], [64912.9, 0.0], [64914.7, 0.001], [64958.4, 0.017], [64972.5, 0.0], [64979.3, 0.093], [65037.1, 0.001], [65043.8, 0.002], [65101.7, 0.337], [65108.4, 1.272], [65235.0, 0.612], [65239.8, 0.075], [65331.9, 0.015], [65332.1, 0.942], [65332.2, 0.006], [65333.4, 0.0], [65334.9, 2.292], [65337.1, 14.546], [65353.2, 34.226], [65396.5, 0.66], [65396.8, 0.0], [65396.9, 0.024], [65397.1, 0.0], [65399.5, 2.31], [65401.5, 4.089], [65401.7, 7.575], [65589.1, 0.001], [65744.3, 0.503], [65876.8, 6.245], [65885.7, 0.028], [70507.9, 0.0], [70670.3, 0.0], [70832.8, 0.0], [70995.2, 0.003]]}
{"kind": "depth", "E": 1787088302261, "U": 11315916556713, "u": 11315916567078, "recv_ms": 1787088302201, "bids": [[1000.0, 35.76], [14093.8, 0.602], [14185.0, 0.308], [14186.8, 0.014], [14188.3, 0.0], [14188.5, 0.028], [14189.0, 0.63], [32296.9, 0.028], [51671.0, 0.002], [51675.0, 0.004], [58134.4, 0.002], [61364.1, 0.001], [62010.0, 1.626], [63302.0, 0.003], [63551.6, 14.066], [63803.3, 37.091], [63947.9, 0.153], [64006.9, 0.0], [64010.9, 0.016], [64127.4, 0.117], [64167.0, 0.006], [64170.9, 0.008], [64327.4, 0.133], [64331.4, 0.004], [64383.4, 12.304], [64390.1, 2.188], [64400.1, 0.216], [64421.3, 0.0], [64421.8, 0.062], [64434.7, 0.136], [64447.2, 3.009], [64447.3, 1.377], [64450.1, 1.896], [64462.2, 2.343], [64488.2, 0.003], [64492.2, 0.002], [64493.8, 0.008], [64495.4, 0.014], [64508.1, 8.705], [64510.7, 34.773], [64512.9, 0.002], [64515.1, 1.242], [64521.7, 0.0], [64522.7, 0.464], [64527.0, 0.3], [64530.1, 0.0], [64534.7, 0.021], [64534.8, 0.0], [64537.6, 1.438], [64539.5, 0.311], [64543.0, 0.006], [64544.3, 0.018], [64546.2, 0.005], [64546.5, 0.004], [64546.7, 0.283], [64546.9, 0.195], [64548.5, 0.0], [64549.0, 0.019], [64549.1, 0.065], [64551.6, 0.004], [64552.0, 0.021], [64553.3, 0.738], [64556.5, 0.0], [64557.2, 0.011], [64558.4, 0.018], [64559.3, 0.029], [64561.5, 2.626], [64565.7, 0.217], [64566.0, 0.005], [64566.1, 0.017], [64566.7, 0.006], [64568.7, 0.111], [64569.1, 0.007], [64572.2, 0.004], [64572.7, 0.083], [64574.4, 0.185], [64574.5, 0.043], [64574.9, 0.006], [64575.4, 0.001], [64575.5, 0.082], [64575.9, 0.99], [64576.5, 0.012], [64576.9, 0.0], [64577.5, 0.557], [64577.9, 0.002], [64578.8, 0.009], [64579.1, 0.07], [64579.3, 0.153], [64579.7, 0.131], [64579.8, 0.1], [64580.4, 0.003], [64582.6, 0.927], [64583.3, 0.04], [64584.3, 0.038], [64585.5, 0.65], [64585.6, 0.01], [64586.4, 0.105], [64586.5, 0.021], [64586.7, 0.07], [64586.8, 0.7], [64586.9, 0.176], [64587.1, 0.101], [64587.2, 0.072], [64587.3, 0.186], [64587.7, 0.429], [64588.0, 0.045], [64588.1, 2.321], [64588.3, 0.088], [64588.6, 0.033], [64589.0, 0.836], [64589.1, 0.008], [64589.2, 1.549], [64589.3, 0.075], [64589.8, 0.382], [64590.0, 0.006], [64590.2, 0.002], [64590.7, 0.002], [64590.9, 0.016], [64591.0, 0.001], [64591.6, 1.031], [64591.8, 0.054], [64592.0, 0.003], [64592.6, 0.003], [64593.2, 0.0], [64593.5, 3.08], [64593.6, 0.512], [64593.8, 33.557]], "asks": [[64593.9, 4.548], [64594.0, 0.001], [64595.4, 0.002], [64595.5, 0.032], [64595.8, 0.0], [64596.2, 0.003], [64596.3, 0.0], [64596.5, 0.015], [64596.8, 0.002], [64596.9, 0.002], [64598.6, 0.001], [64599.0, 0.008], [64599.1, 1.817], [64599.2, 0.087], [64599.5, 0.085], [64599.6, 0.004], [64599.7, 0.008], [64599.8, 1.894], [64599.9, 0.751], [64600.1, 0.003], [64601.0, 0.003], [64602.0, 0.128], [64603.1, 0.409], [64603.2, 0.042], [64603.7, 2.319], [64603.9, 0.383], [64604.0, 0.403], [64604.4, 0.784], [64604.8, 0.142], [64606.8, 0.003], [64607.4, 0.014], [64607.8, 0.069], [64607.9, 1.671], [64608.5, 0.016], [64609.1, 3.129], [64610.1, 0.007], [64611.5, 0.0], [64611.8, 6.04], [64612.0, 1.246], [64613.2, 0.009], [64613.3, 0.166], [64613.4, 0.006], [64613.5, 0.014], [64614.8, 0.125], [64615.1, 0.546], [64615.2, 1.163], [64615.6, 0.0], [64615.7, 3.07], [64616.8, 0.004], [64617.0, 0.311], [64617.1, 0.0], [64617.6, 1.015], [64618.8, 0.001], [64620.5, 0.048], [64620.6, 0.078], [64620.9, 1.49], [64621.1, 0.155], [64621.3, 0.0], [64622.2, 0.162], [64624.2, 0.977], [64624.3, 0.055], [64625.4, 0.003], [64626.6, 2.32], [64626.7, 1.904], [64627.2, 0.198], [64627.4, 0.393], [64628.1, 0.165], [64628.4, 0.06], [64633.0, 4.84], [64633.7, 0.109], [64634.2, 0.356], [64636.0, 0.044], [64638.6, 0.001], [64640.1, 0.062], [64642.0, 0.903], [64642.5, 0.05], [64646.9, 0.0], [64647.0, 0.301], [64647.1, 2.728], [64647.6, 0.021], [64647.8, 0.45], [64652.7, 0.062], [64654.3, 0.0], [64656.7, 0.003], [64662.8, 0.208], [64664.9, 0.0], [64666.8, 30.588], [64667.4, 0.001], [64669.8, 1.427], [64681.9, 0.003], [64685.9, 0.002], [64704.1, 1.094], [64722.0, 0.019], [64729.7, 1.264], [64843.6, 0.0], [64847.6, 0.099], [65005.7, 0.0], [65009.7, 0.017], [65042.7, 0.623], [65168.2, 0.0], [65172.3, 0.016], [65239.8, 0.075], [65317.0, 0.323]]}
{"kind": "depth", "E": 1787088302363, "U": 11315916567102, "u": 11315916574861, "recv_ms": 1787088302302, "bids": [[14093.8, 0.966], [14185.0, 0.168], [14186.8, 0.0], [14188.5, 0.0], [14188.7, 0.0], [14188.9, 0.0], [14189.0, 0.476], [51671.0, 0.0], [51675.0, 0.0], [58134.4, 0.002], [61364.1, 0.0], [63593.8, 0.028], [63947.9, 0.151], [64266.1, 0.104], [64473.1, 0.091], [64474.8, 0.118], [64477.5, 0.008], [64508.5, 34.758], [64509.8, 1.382], [64510.7, 0.022], [64519.5, 0.011], [64521.7, 0.0], [64531.7, 0.0], [64533.5, 0.209], [64535.4, 0.019], [64536.5, 2.319], [64541.2, 4.265], [64542.6, 1.028], [64545.5, 0.772], [64545.6, 0.003], [64546.9, 0.119], [64547.0, 0.059], [64547.2, 0.047], [64548.2, 0.157], [64548.8, 0.004], [64549.1, 0.08], [64550.0, 0.243], [64557.0, 0.0], [64557.2, 0.001], [64558.0, 0.049], [64561.6, 5.047], [64562.0, 0.071], [64563.2, 0.025], [64563.7, 0.012], [64564.2, 0.549], [64565.9, 0.31], [64566.4, 0.007], [64567.0, 1.704], [64567.9, 0.016], [64568.1, 0.021], [64570.7, 1.242], [64572.3, 0.003], [64573.9, 0.003], [64574.6, 0.019], [64575.0, 0.002], [64575.5, 0.143], [64579.4, 0.001], [64579.5, 0.101], [64579.6, 0.124], [64579.9, 0.001], [64580.0, 0.388], [64580.7, 0.274], [64581.3, 0.002], [64582.1, 0.592], [64583.4, 0.603], [64585.0, 35.813], [64585.7, 0.078], [64586.1, 0.119], [64586.5, 0.153], [64586.8, 0.8], [64587.0, 0.916], [64587.2, 0.172], [64587.8, 0.158], [64588.0, 0.035], [64588.2, 1.012], [64588.3, 0.128], [64588.8, 0.018], [64589.0, 0.829], [64589.1, 0.01], [64589.3, 1.301], [64589.9, 0.0], [64590.2, 0.002], [64590.7, 0.001], [64590.9, 0.008], [64593.0, 0.313], [64593.8, 33.597]], "asks": [[64593.9, 4.086], [64594.2, 0.0], [64595.4, 0.001], [64596.7, 0.001], [64597.0, 0.086], [64597.8, 1.902], [64599.0, 0.016], [64599.2, 0.007], [64599.7, 0.0], [64599.8, 1.89], [64600.2, 0.086], [64600.6, 0.002], [64601.1, 0.001], [64603.3, 0.018], [64603.4, 0.688], [64603.5, 0.003], [64603.6, 0.021], [64604.7, 0.343], [64605.0, 0.001], [64608.8, 0.213], [64609.0, 1.338], [64609.7, 0.007], [64612.6, 0.33], [64613.3, 0.297], [64613.5, 0.556], [64615.1, 0.004], [64616.2, 0.027], [64616.6, 0.002], [64617.4, 0.106], [64617.6, 1.03], [64618.1, 0.113], [64620.9, 1.49], [64621.1, 0.001], [64621.7, 0.001], [64622.1, 0.316], [64624.7, 0.067], [64626.5, 0.023], [64627.3, 0.887], [64629.6, 0.018], [64630.2, 10.004], [64630.5, 0.629], [64632.4, 0.0], [64634.7, 0.018], [64639.6, 0.008], [64640.1, 0.054], [64640.2, 0.632], [64641.7, 0.011], [64642.3, 0.06], [64645.3, 0.015], [64647.6, 0.011], [64648.4, 0.013], [64648.6, 0.005], [64658.5, 0.742], [64660.8, 0.002], [64665.6, 0.457], [64665.9, 0.0], [64690.9, 0.021], [64714.0, 0.101], [64745.2, 0.096], [64750.0, 13.274], [64932.8, 1.695], [64956.9, 2.42], [64958.8, 4.234], [64996.3, 4.83], [64997.7, 10.92], [65235.5, 0.001], [65239.8, 0.079], [65240.5, 0.379], [65369.0, 1.752], [65593.9, 0.02]]}
{"kind": "depth", "E": 1787088302465, "U": 11315916574871, "u": 11315916583617, "recv_ms": 1787088302438, "bids": [[1000.0, 35.76], [14093.8, 1.162], [14185.0, 0.014], [14189.0, 0.35], [14493.8, 0.084], [51675.0, 0.002], [58134.4, 0.002], [61364.1, 0.0], [62010.0, 1.629], [63302.0, 0.006], [63555.6, 1.1], [63813.9, 1.565], [63947.9, 0.151], [64266.0, 5.018], [64508.5, 0.007], [64519.5, 34.762], [64520.4, 0.446], [64529.2, 0.083], [64531.0, 0.001], [64535.4, 0.006], [64537.1, 0.018], [64549.1, 0.065], [64550.8, 0.016], [64555.6, 1.74], [64556.9, 0.016], [64558.2, 0.0], [64559.5, 0.001], [64561.6, 5.007], [64563.7, 0.006], [64563.9, 0.34], [64567.6, 0.059], [64568.1, 0.005], [64568.9, 0.0], [64569.8, 0.031], [64569.9, 0.045], [64579.0, 0.022], [64579.1, 0.0], [64579.3, 0.083], [64579.5, 0.001], [64579.8, 0.0], [64580.3, 0.005], [64580.6, 0.008], [64581.0, 0.02], [64581.8, 0.015], [64581.9, 0.0], [64585.7, 0.009], [64586.0, 1.443], [64586.1, 0.111], [64586.6, 0.072], [64587.0, 0.986], [64587.4, 0.077], [64588.3, 0.128], [64589.0, 0.635], [64589.3, 0.075], [64589.4, 0.001], [64590.2, 0.002], [64590.9, 0.008], [64591.8, 0.055], [64593.0, 0.003]], "asks": [[64593.9, 4.651], [64594.1, 0.0], [64594.2, 0.001], [64594.6, 0.004], [64595.8, 0.084], [64596.3, 0.084], [64597.7, 0.009], [64599.0, 0.009], [64599.7, 0.001], [64600.1, 0.004], [64600.2, 0.002], [64601.0, 0.003], [64601.1, 0.311], [64602.0, 0.127], [64602.3, 0.001], [64603.4, 0.061], [64603.6, 0.004], [64603.8, 0.756], [64604.7, 0.263], [64604.9, 0.001], [64606.2, 0.748], [64606.6, 0.079], [64606.8, 0.083], [64607.0, 0.002], [64607.8, 0.007], [64608.7, 0.265], [64608.8, 0.848], [64612.0, 2.146], [64617.6, 1.015], [64619.0, 0.118], [64619.3, 0.073], [64621.2, 0.159], [64622.1, 0.31], [64622.4, 0.008], [64623.2, 0.007], [64625.8, 1.012], [64626.5, 0.01], [64628.2, 0.168], [64629.0, 0.007], [64629.6, 0.0], [64630.1, 0.028], [64631.3, 0.078], [64634.7, 0.002], [64636.4, 0.06], [64637.9, 0.0], [64642.0, 4.403], [64649.7, 0.814], [64658.5, 0.743], [64665.8, 0.007], [64674.9, 0.013], [64683.1, 0.064], [64912.1, 0.001], [65239.8, 0.075], [65353.7, 8.254], [65392.4, 24.456], [65876.8, 6.242], [68000.0, 89.78]]}
{"kind": "depth", "E": 1787088302567, "U": 11315916583734, "u": 11315916590425, "recv_ms": 1787088302504, "bids": [[1000.0, 35.76], [14093.8, 1.064], [14185.0, 0.0], [14189.0, 0.238], [14493.8, 0.308], [51675.0, 0.0], [58134.4, 0.002], [61364.1, 0.0], [61539.9, 0.003], [61548.2, 0.114], [62010.0, 1.626], [63593.8, 0.008], [63931.6, 0.0], [63947.9, 0.151], [64270.8, 0.024], [64487.2, 11.22], [64488.6, 0.108], [64528.0, 0.439], [64529.0, 0.0], [64539.1, 0.005], [64547.4, 0.512], [64548.4, 0.011], [64556.7, 0.001], [64558.0, 0.037], [64558.7, 0.014], [64559.3, 0.027], [64572.3, 1.204], [64575.9, 0.955], [64578.2, 0.137], [64579.2, 0.04], [64579.7, 0.061], [64580.0, 0.318], [64580.1, 0.804], [64581.7, 0.0], [64583.1, 0.182], [64585.7, 0.086], [64587.0, 0.988], [64587.2, 0.173], [64588.3, 0.12], [64589.0, 0.595], [64589.1, 0.008], [64589.3, 0.075], [64589.4, 0.009], [64591.9, 0.001], [64593.5, 3.08], [64593.8, 33.826]], "asks": [[64593.9, 4.604], [64595.8, 0.0], [64602.1, 0.05], [64603.4, 0.059], [64604.7, 0.261], [64606.0, 0.003], [64610.0, 0.906], [64612.0, 1.246], [64621.2, 0.159], [64622.7, 3.449], [64625.6, 0.123], [64626.6, 4.205], [64626.7, 0.019], [64627.8, 0.0], [64633.7, 0.309], [64634.3, 0.842], [64640.1, 0.254], [64648.4, 0.003], [64649.1, 0.02], [64777.8, 0.0], [64779.2, 0.003], [64912.0, 0.009], [64916.9, 0.001], [64917.8, 0.2], [65239.8, 0.075], [65401.3, 2.343], [65433.6, 3.058], [65457.0, 22.103], [65593.9, 0.0], [65669.7, 0.002], [67610.9, 0.101], [67620.1, 0.04]]}
{"kind": "depth", "E": 1787088302669, "U": 11315916590499, "u": 11315916596571, "recv_ms": 1787088302607, "bids": [[14093.8, 0.966], [14189.0, 0.112], [14493.8, 0.532], [58134.4, 0.002], [60435.4, 0.002], [61364.1, 0.0], [62010.0, 1.629], [63947.9, 0.151], [64266.1, 0.094], [64270.8, 0.024], [64470.5, 0.018], [64479.3, 0.003], [64502.8, 0.017], [64511.6, 0.004], [64530.4, 0.275], [64531.0, 0.033], [64535.1, 0.467], [64543.9, 0.015], [64546.3, 0.17], [64546.9, 0.117], [64561.0, 0.972], [64561.1, 0.002], [64561.2, 0.002], [64563.7, 0.004], [64564.4, 0.036], [64564.5, 0.055], [64564.6, 0.003], [64567.4, 0.0], [64568.5, 1.01], [64568.8, 0.634], [64576.2, 0.97], [64576.3, 0.079], [64577.1, 0.084], [64577.9, 0.0], [64578.0, 1.024], [64581.1, 0.009], [64581.5, 0.927], [64582.6, 0.0], [64585.0, 35.811], [64585.7, 0.009], [64588.3, 0.128], [64589.0, 0.593], [64589.2, 1.551], [64589.4, 0.001], [64592.4, 0.003], [64593.5, 3.065], [64593.7, 0.061], [64593.8, 33.842]], "asks": [[64593.9, 4.669], [64594.9, 0.0], [64595.8, 0.084], [64596.2, 0.001], [64601.8, 0.001], [64606.6, 0.081], [64609.6, 0.004], [64611.4, 0.166], [64611.8, 6.06], [64612.8, 0.004], [64613.4, 0.625], [64614.2, 0.139], [64614.4, 0.008], [64619.2, 1.186], [64620.4, 0.002], [64620.5, 0.008], [64620.8, 0.687], [64621.1, 0.155], [64621.2, 0.005], [64623.0, 0.015], [64634.5, 0.031], [64635.0, 0.004], [64643.8, 0.262], [64667.2, 0.037], [64676.2, 0.002], [64699.7, 0.017], [64708.6, 0.002], [65239.8, 0.075], [65514.7, 10.676], [65521.6, 50.943]]}
{"kind": "depth", "E": 1787088302771, "U": 11315916596600, "u": 11315916601791, "recv_ms": 1787088302709, "bids": [[1000.0, 35.76], [14089.0, 2.478], [14091.6, 0.014], [14093.8, 0.896], [14189.0, 0.0], [14493.8, 0.784], [58134.4, 0.002], [61364.1, 0.0], [62010.0, 1.626], [63593.8, 0.028], [63947.9, 0.151], [64519.5, 0.011], [64521.7, 34.751], [64558.7, 0.004], [64559.2, 0.013], [64568.1, 0.075], [64568.8, 0.015], [64571.7, 0.023], [64574.6, 0.0], [64576.2, 0.351], [64578.7, 1.57], [64582.2, 0.545], [64583.4, 0.061], [64584.7, 0.001], [64585.0, 35.748], [64586.9, 0.17], [64587.4, 0.072], [64589.0, 0.587], [64589.1, 0.018], [64590.4, 0.009], [64591.8, 0.067], [64592.0, 0.005], [64592.6, 0.003], [64593.2, 0.004], [64593.8, 32.621]], "asks": [[64593.9, 4.669], [64595.8, 0.0], [64597.7, 0.102], [64599.0, 0.015], [64599.4, 0.017], [64599.9, 0.759], [64600.9, 0.335], [64602.2, 0.013], [64608.7, 0.265], [64613.4, 0.006], [64620.8, 0.068], [64621.1, 0.001], [64621.4, 0.164], [64648.5, 0.078], [64649.1, 0.01], [64649.6, 0.081], [64678.7, 2.322], [64690.4, 0.0], [64727.8, 0.021], [65239.8, 0.077], [65362.6, 0.93], [65457.0, 21.341], [65465.9, 0.305], [65593.9, 0.02], [65601.7, 0.659], [65685.5, 0.607]]}
{"kind": "depth", "E": 1787088302873, "U": 11315916601866, "u": 11315916606921, "recv_ms": 1787088302811, "bids": [[1000.0, 35.76], [14089.0, 2.366], [14093.3, 0.0], [14093.8, 0.672], [14493.8, 1.134], [58134.4, 0.002], [61364.1, 0.0], [63302.0, 0.009], [63497.1, 0.0], [63628.9, 1.938], [63947.9, 0.151], [64537.2, 0.0], [64539.6, 0.004], [64559.2, 0.003], [64559.6, 0.011], [64575.9, 1.071], [64576.9, 0.557], [64577.0, 1.532], [64577.5, 0.0], [64582.0, 0.016], [64588.3, 1.676], [64589.2, 0.003], [64591.5, 0.003], [64592.0, 0.905], [64593.7, 0.062], [64593.8, 33.011]], "asks": [[64593.9, 5.31], [64595.9, 0.0], [64600.1, 0.002], [64602.0, 0.129], [64605.6, 0.067], [64605.7, 0.31], [64606.1, 0.023], [64606.6, 0.019], [64608.9, 0.002], [64611.5, 0.619], [64617.1, 0.557], [64618.2, 0.537], [64618.6, 0.007], [64620.8, 0.075], [64622.4, 0.317], [64622.7, 3.442], [64626.2, 0.015], [64626.3, 10.28], [64630.2, 0.004], [64634.3, 0.838], [64636.5, 0.004], [64649.6, 0.071], [64650.1, 0.01], [65239.8, 0.075], [65530.5, 1.074], [65627.4, 2.738]]}
{"kind": "depth", "E": 1787088302975, "U": 11315916607061, "u": 11315916611696, "recv_ms": 1787088302913, "bids": [[14089.0, 2.128], [14090.1, 0.0], [14093.8, 0.56], [14493.8, 1.498], [58134.4, 0.002], [61355.8, 0.008], [61355.9, 0.013], [62010.0, 1.629], [63593.8, 0.008], [63727.2, 0.807], [63745.3, 8.222], [63947.9, 0.151], [64270.8, 0.024], [64541.7, 0.002], [64559.6, 0.001], [64560.0, 0.093], [64570.3, 0.011], [64576.1, 0.002], [64577.7, 0.005], [64582.3, 0.0], [64587.7, 0.492], [64589.0, 0.542]], "asks": [[64597.9, 0.087], [64603.0, 0.01], [64611.0, 1.303], [64650.1, 0.0], [64650.4, 0.011], [64658.7, 0.027], [65239.8, 0.075], [65392.4, 24.228], [65457.0, 20.732], [65465.9, 1.067], [65530.5, 1.188], [65593.9, 0.0], [71053.3, 0.0]]}
{"kind": "depth", "E": 1787088303077, "U": 11315916611796, "u": 11315916619772, "recv_ms": 1787088303013, "bids": [[1000.0, 35.76], [14089.0, 1.904], [14093.8, 0.434], [14493.8, 1.848], [58134.4, 0.002], [62010.0, 1.626], [63508.6, 0.66], [63593.8, 0.028], [63639.5, 0.549], [63738.7, 11.435], [63759.2, 0.001], [63777.7, 32.203], [63947.9, 0.151], [64450.7, 0.018], [64521.7, 34.751], [64523.9, 0.017], [64567.1, 0.072], [64567.6, 0.002], [64575.7, 0.001], [64578.5, 0.167], [64582.2, 0.003], [64582.9, 0.614], [64583.0, 0.543], [64584.9, 0.326], [64589.6, 0.162], [64593.8, 33.012]], "asks": [[64593.9, 6.811], [64595.8, 0.084], [64598.0, 0.067], [64599.7, 0.55], [64608.7, 0.258], [64608.8, 0.306], [64614.2, 1.065], [64615.3, 0.208], [64619.1, 0.059], [64619.8, 0.189], [64620.8, 0.018], [64714.7, 0.0], [64728.7, 0.06], [65239.8, 0.075], [65593.9, 0.02]]}
{"kind": "depth", "E": 1787088303179, "U": 11315916619817, "u": 11315916628102, "recv_ms": 1787088303118, "bids": [[1000.0, 35.76], [14089.0, 1.666], [14093.8, 0.322], [14493.8, 2.198], [58134.4, 0.002], [61355.7, 2.447], [61364.1, 0.0], [62010.0, 1.629], [63616.2, 30.873], [63733.4, 1.097], [63947.9, 0.153], [63993.5, 0.239], [64392.6, 1.542], [64431.6, 2.363], [64468.7, 0.034], [64473.5, 0.026], [64475.8, 0.071], [64480.6, 0.589], [64482.8, 0.002], [64487.6, 0.015], [64489.9, 0.001], [64494.7, 0.072], [64496.9, 0.0], [64501.7, 0.076], [64504.0, 0.046], [64508.8, 0.017], [64511.0, 0.025], [64514.8, 0.106], [64515.8, 2.333], [64518.1, 0.0], [64522.9, 0.015], [64524.6, 6.858], [64530.4, 0.065], [64537.6, 1.648], [64541.9, 2.379], [64560.0, 0.083], [64560.3, 0.02], [64561.1, 0.044], [64569.4, 0.856], [64574.7, 0.034], [64576.3, 0.094], [64577.0, 1.532], [64577.3, 0.001], [64578.5, 0.013], [64578.6, 2.319], [64578.7, 1.57], [64578.8, 0.011], [64578.9, 0.216], [64579.2, 0.059], [64582.3, 0.0], [64584.1, 0.026], [64589.0, 0.539], [64589.2, 0.018], [64592.4, 0.005], [64593.1, 0.086], [64593.8, 33.014]], "asks": [[64595.2, 0.008], [64599.7, 0.001], [64599.8, 0.001], [64601.2, 0.059], [64602.1, 0.065], [64603.0, 0.01], [64605.2, 0.343], [64605.6, 0.005], [64606.8, 0.095], [64608.1, 0.002], [64608.9, 0.551], [64609.0, 2.238], [64609.4, 1.24], [64610.0, 0.006], [64611.6, 0.721], [64615.0, 0.017], [64618.9, 0.055], [64624.2, 2.741], [64625.3, 0.162], [64632.5, 0.0], [64649.9, 0.785], [64650.4, 0.001], [64650.7, 0.221], [64713.6, 1.873], [64740.8, 0.627], [65037.9, 0.232], [65239.8, 0.075], [65353.2, 32.698], [65528.0, 2.923], [65885.7, 0.031]]}
{"kind": "depth", "E": 1787088303281, "U": 11315916628151, "u": 11315916635313, "recv_ms": 1787088303218, "bids": [[14089.0, 1.428], [14093.8, 0.196], [14493.8, 2.562], [58134.4, 0.002], [60272.9, 0.003], [61364.1, 0.0], [62010.0, 1.626], [63745.3, 7.126], [63749.3, 1.648], [63932.4, 1.639], [63947.9, 0.151], [64270.8, 0.024], [64560.3, 0.01], [64560.5, 0.117], [64574.8, 0.002], [64576.0, 0.01], [64578.6, 2.473], [64579.5, 0.005], [64582.2, 0.003], [64583.0, 0.543], [64584.7, 0.066], [64589.0, 0.536], [64591.1, 0.007], [64591.7, 0.629], [64591.8, 0.061], [64593.0, 0.044], [64593.8, 33.017]], "asks": [[64593.9, 9.082], [64594.0, 0.003], [64597.7, 0.095], [64599.0, 0.007], [64599.1, 0.084], [64599.6, 0.002], [64599.7, 0.0], [64603.6, 0.02], [64617.6, 1.014], [64625.4, 0.001], [64626.3, 10.282], [64630.9, 0.015], [64632.7, 0.016], [64650.7, 0.211], [64650.9, 0.01], [64666.3, 0.126], [65217.6, 0.0], [65239.8, 0.075], [65369.0, 3.28], [65465.9, 1.676], [65601.7, 1.311], [65676.1, 6.847]]}
{"kind": "depth", "E": 1787088303383, "U": 11315916635386, "u": 11315916641882, "recv_ms": 1787088303321, "bids": [[1000.0, 35.76], [14089.0, 1.176], [14093.8, 0.084], [14493.8, 2.926], [58134.4, 0.002], [61355.9, 0.011], [61364.1, 0.0], [63593.8, 0.008], [63620.2, 0.399], [63866.7, 1.778], [63943.1, 0.069], [63947.9, 0.151], [64003.0, 5.003], [64447.2, 0.049], [64447.3, 0.005], [64450.2, 3.363], [64473.1, 0.004], [64578.4, 0.154], [64578.5, 0.013], [64578.6, 2.319], [64582.4, 0.009], [64591.3, 0.003], [64593.8, 33.018]], "asks": [[64593.9, 8.856], [64603.1, 0.409], [64611.8, 6.04], [64614.2, 1.025], [64615.7, 3.09], [64615.8, 0.045], [64629.5, 0.029], [64634.5, 0.016], [64729.7, 0.484], [64732.5, 0.0], [64733.1, 7.499], [65239.8, 0.075], [65502.2, 4.107], [65593.9, 0.0], [65860.1, 0.65]]}
{"kind": "depth", "E": 1787088303485, "U": 11315916642049, "u": 11315916649006, "recv_ms": 1787088303423, "bids": [[1000.0, 35.76], [14089.0, 0.924], [14091.6, 0.0], [14093.8, 0.0], [14493.8, 3.276], [51675.0, 0.0], [58134.4, 0.002], [61355.8, 0.006], [61355.9, 0.013], [62010.0, 1.629], [63431.1, 0.015], [63736.2, 1.096], [63947.9, 0.151], [64270.8, 0.023], [64533.4, 0.058], [64560.5, 0.107], [64560.7, 0.012], [64576.4, 0.095], [64578.4, 0.0], [64578.5, 0.167], [64579.8, 0.007], [64580.5, 0.0]], "asks": [[64610.6, 0.127], [64611.3, 0.005], [64615.2, 1.162], [64615.8, 0.005], [64617.1, 0.597], [64626.2, 0.018], [64650.9, 0.0], [64651.1, 0.405], [64916.9, 0.0], [65233.4, 0.701], [65239.8, 0.075], [65478.8, 0.637]]}
{"kind": "depth", "E": 1787088303587, "U": 11315916649472, "u": 11315916662832, "recv_ms": 1787088303524, "bids": [[14089.0, 0.56], [14493.8, 3.64], [51672.0, 0.0], [58134.4, 0.002], [61364.1, 0.0], [62010.0, 1.626], [63293.3, 7.193], [63593.8, 0.028], [63689.5, 0.193], [63938.5, 1.344], [63942.1, 0.4], [63947.9, 0.153], [64270.8, 0.034], [64552.6, 0.025], [64559.3, 0.002], [64560.7, 0.002], [64560.9, 0.328], [64567.5, 0.02], [64571.7, 0.004], [64578.2, 0.291], [64578.5, 0.013], [64582.4, 0.009], [64593.8, 33.018]], "asks": [[64593.9, 9.082], [64599.0, 0.01], [64651.1, 0.395], [64651.3, 0.396], [64916.9, 0.001], [65239.8, 0.075], [65528.0, 2.542], [65593.9, 0.02], [65627.4, 4.259], [65969.3, 0.226]]}
{"kind": "depth", "E": 1787088303689, "U": 11315916662942, "u": 11315916676377, "recv_ms": 1787088303626, "bids": [[1000.0, 35.76], [14089.0, 0.322], [14393.8, 0.112], [14493.8, 3.766], [58134.4, 0.004], [62010.0, 1.629], [63881.6, 0.88], [63947.9, 0.151], [64466.4, 0.41], [64577.5, 0.002]], "asks": [[64610.9, 0.007], [64614.2, 1.022], [64907.9, 0.464], [64908.0, 2.771], [65166.4, 23.558], [65239.8, 0.075], [66063.6, 0.0]]}
{"kind": "depth", "E": 1787088303791, "U": 11315916676394, "u": 11315916683020, "recv_ms": 1787088303728, "bids": [[1000.0, 35.76], [14089.0, 0.21], [14393.8, 0.364], [14493.8, 3.626], [58134.4, 0.002], [60110.5, 0.036], [61364.1, 0.0], [63302.0, 0.012], [63593.8, 0.008], [63609.1, 2.033], [63947.9, 0.151], [64430.3, 0.0], [64433.3, 3.467], [64450.2, 2.371], [64560.9, 0.318], [64561.0, 0.982], [64566.5, 0.353], [64567.1, 0.015], [64568.6, 0.653], [64575.0, 0.118], [64575.9, 1.574], [64576.1, 0.559], [64576.9, 0.0], [64580.9, 0.004], [64581.5, 0.927], [64581.9, 0.0], [64582.2, 0.003], [64582.4, 0.009], [64583.0, 0.543], [64589.8, 0.015], [64592.4, 0.007], [64593.8, 33.018]], "asks": [[64593.9, 9.083], [64597.9, 0.724], [64603.6, 0.012], [64605.0, 0.063], [64605.2, 0.281], [64607.8, 0.015], [64611.0, 2.203], [64611.9, 0.0], [64612.0, 0.346], [64613.0, 0.556], [64613.1, 2.971], [64613.3, 0.297], [64613.5, 0.014], [64614.2, 0.096], [64614.3, 0.928], [64620.5, 0.627], [64651.3, 0.386], [64651.4, 0.011], [64826.4, 0.018], [65239.8, 0.075], [65239.9, 0.001], [65593.9, 0.0], [65763.7, 0.759], [71053.3, 0.001]]}
{"kind": "depth", "E": 1787088303893, "U": 11315916683190, "u": 11315916689889, "recv_ms": 1787088303831, "bids": [[14089.0, 0.084], [14393.8, 0.588], [14493.8, 3.528], [58134.4, 0.002], [61364.1, 0.0], [62010.0, 1.626], [63947.9, 0.151], [64270.8, 0.024], [64474.1, 0.087], [64561.0, 0.972], [64561.1, 0.054], [64566.5, 0.353], [64567.2, 0.0], [64568.1, 0.075], [64568.6, 0.034], [64575.0, 0.002], [64575.6, 0.116], [64575.9, 0.955], [64576.7, 0.31], [64580.9, 0.931], [64581.5, 0.0], [64582.1, 0.36], [64582.2, 0.545], [64582.6, 0.0], [64583.0, 0.001], [64585.4, 1.246], [64585.5, 0.666], [64585.7, 0.001], [64588.6, 0.033], [64588.7, 0.085], [64593.8, 33.019]], "asks": [[64595.1, 0.002], [64597.7, 0.094], [64597.8, 0.013], [64599.0, 0.009], [64600.1, 0.001], [64600.5, 0.002], [64603.6, 0.02], [64607.8, 0.007], [64611.7, 2.31], [64613.0, 0.556], [64613.1, 2.352], [64613.3, 0.297], [64613.5, 0.014], [64614.2, 1.022], [64614.3, 0.002], [64614.8, 0.143], [64615.0, 0.017], [64616.3, 0.102], [64617.1, 0.597], [64617.9, 0.003], [64618.3, 0.013], [64619.1, 0.059], [64619.9, 0.0], [64620.5, 0.008], [64626.5, 1.895], [64626.6, 2.32], [64651.4, 0.001], [64651.5, 0.01], [64748.0, 0.009], [65239.8, 0.075], [66079.6, 0.605], [71053.3, 0.0]]}
{"kind": "depth", "E": 1787088303995, "U": 11315916689930, "u": 11315916695469, "recv_ms": 1787088303977, "bids": [[1000.0, 35.76], [14089.0, 0.0], [14393.8, 0.868], [14493.8, 3.332], [58134.4, 0.002], [61364.1, 0.001], [62010.0, 1.629], [63593.8, 0.028], [63634.7, 4.236], [63713.1, 31.808], [63803.3, 35.526], [63947.9, 0.151], [64582.4, 0.009], [64585.5, 0.666], [64588.2, 0.006], [64588.6, 1.554], [64588.7, 0.085], [64593.8, 33.018]], "asks": [[64608.8, 0.309], [64612.1, 0.04], [64915.5, 0.592], [64916.9, 2.308], [65177.0, 3.091], [65239.8, 0.075], [65593.9, 0.02], [66498.3, 0.0]]}
{"kind": "depth", "E": 1787088304097, "U": 11315916695629, "u": 11315916703766, "recv_ms": 1787088304062, "bids": [[1000.0, 35.76], [14393.8, 1.218], [14493.8, 2.982], [58134.4, 0.002], [61364.1, 0.0], [62010.0, 1.626], [63293.3, 7.19], [63947.9, 0.151], [64512.9, 34.87], [64521.7, 0.0], [64524.6, 2.038], [64559.2, 0.002], [64561.1, 0.044], [64561.2, 0.012], [64582.2, 0.003], [64583.0, 0.543], [64593.8, 33.017]], "asks": [[64595.8, 0.0], [64600.5, 0.001], [64601.0, 0.004], [64619.2, 1.188], [64651.5, 0.0], [64651.6, 0.014], [64845.0, 0.01], [65239.8, 0.075], [65360.1, 73.707], [65677.8, 0.0], [65683.0, 15.751]]}
{"kind": "depth", "E": 1787088304199, "U": 11315916704096, "u": 11315916713404, "recv_ms": 1787088304136, "bids": [[14393.8, 1.582], [14493.8, 2.618], [58134.4, 0.002], [61364.1, 0.0], [62010.0, 1.629], [63593.8, 0.008], [63818.7, 1.569], [63947.9, 0.151], [64270.8, 0.034], [64416.0, 0.982], [64447.2, 0.972], [64450.2, 0.093], [64450.3, 3.255], [64470.2, 0.126], [64488.1, 0.002], [64512.9, 0.002], [64516.2, 0.003], [64521.7, 35.043], [64524.6, 6.901], [64559.1, 0.679], [64577.0, 1.532], [64580.8, 0.315], [64582.4, 0.009], [64593.7, 0.057], [64593.8, 33.128]], "asks": [[64606.1, 0.024], [64609.4, 1.24], [64618.1, 0.62], [64640.3, 1.315], [64652.1, 0.004], [64666.3, 4.703], [64720.2, 1.594], [64733.1, 7.499], [64932.8, 0.0], [64956.9, 1.915], [64958.8, 0.0], [64996.3, 3.434], [64997.7, 0.342], [65239.8, 0.075], [65401.3, 2.686], [65593.9, 0.0], [65692.0, 0.762], [66506.3, 0.128]]}
{"kind": "depth", "E": 1787088304301, "U": 11315916713537, "u": 11315916723932, "recv_ms": 1787088304238, "bids": [[1000.0, 35.76], [14393.8, 1.932], [14493.8, 2.268], [51675.0, 0.0], [58134.4, 0.002], [61364.1, 0.0], [63645.4, 4.89], [63803.3, 33.961], [63947.9, 0.151], [64554.0, 0.031], [64561.2, 0.002], [64561.3, 0.123], [64562.5, 0.272], [64576.2, 0.353], [64589.0, 0.413], [64593.8, 33.128]], "asks": [[64593.9, 9.096], [64596.6, 0.017], [64640.3, 1.316], [64651.6, 0.004], [64651.7, 0.012], [64714.0, 0.015], [64957.0, 2.066], [65239.8, 0.075]]}
{"kind": "depth", "E": 1787088304403, "U": 11315916724025, "u": 11315916729805, "recv_ms": 1787088304340, "bids": [[14393.8, 2.296], [14493.8, 1.904], [51671.0, 0.0], [58134.4, 0.002], [59948.0, 0.003], [61364.1, 0.0], [62010.0, 1.626], [63293.3, 7.187], [63593.8, 0.028], [64512.9, 35.045], [64521.7, 0.0], [64524.6, 2.038], [64554.0, 0.027], [64561.5, 2.63], [64582.4, 0.009], [64585.5, 0.666], [64588.7, 1.311], [64588.8, 0.018], [64591.8, 0.063], [64593.8, 33.129]], "asks": [[64595.8, 0.002], [64651.7, 0.002], [64651.8, 0.01], [65239.8, 0.075], [65292.0, 0.001], [65292.1, 2.299], [65593.9, 0.02], [65692.0, 5.322], [71053.3, 0.0]]}
{"kind": "depth", "E": 1787088304505, "U": 11315916730052, "u": 11315916736333, "recv_ms": 1787088304441, "bids": [[14393.8, 2.66], [14493.8, 1.54], [51675.0, 0.0], [58134.4, 0.002], [61355.9, 0.011], [61364.1, 0.0], [62010.0, 1.629], [63818.7, 3.134], [63947.9, 0.151], [64270.8, 0.024], [64512.9, 0.002], [64521.7, 35.043], [64561.3, 0.113], [64561.4, 0.011], [64585.5, 0.666], [64588.7, 0.085], [64588.8, 0.018], [64593.8, 33.251]], "asks": [[64593.9, 9.097], [64808.3, 0.746], [64808.4, 0.0], [64808.7, 0.0], [64833.0, 0.976], [64834.3, 4.247], [64871.2, 3.278], [64873.2, 10.604], [65086.0, 0.157], [65239.8, 0.075]]}
{"kind": "depth", "E": 1787088304607, "U": 11315916736378, "u": 11315916743933, "recv_ms": 1787088304545, "bids": [[1000.0, 35.76], [14393.8, 3.01], [14493.8, 1.19], [58134.4, 0.002], [61355.9, 0.009], [61364.1, 0.0], [62010.0, 1.626], [63593.8, 0.008], [63740.1, 0.783], [63771.0, 7.049], [63947.9, 0.151], [64270.8, 0.024], [64576.8, 0.001], [64582.4, 0.009], [64583.8, 0.021], [64593.8, 33.249]], "asks": [[64595.9, 0.084], [64600.1, 0.002], [64601.0, 0.003], [64604.4, 0.786], [64620.5, 0.01], [64808.3, 0.015], [64833.0, 0.371], [64834.3, 0.005], [64871.2, 1.945], [64873.2, 0.006], [64916.9, 2.308], [65239.8, 0.075], [65392.4, 24.0], [65593.9, 0.0], [65885.7, 0.034]]}
{"kind": "depth", "E": 1787088304709, "U": 11315916744401, "u": 11315916753454, "recv_ms": 1787088304657, "bids": [[14393.8, 3.36], [14493.8, 0.84], [58134.4, 0.002], [63947.9, 0.151], [64106.1, 0.0], [64582.4, 0.009], [64593.8, 33.255]], "asks": [[65234.0, 0.082], [65239.8, 0.075], [65239.9, 0.0], [65324.3, 0.0], [65401.3, 2.914], [65417.8, 24.324]]}
{"kind": "depth", "E": 1787088304811, "U": 11315916753570, "u": 11315916761326, "recv_ms": 1787088304748, "bids": [[14293.8, 0.014], [14393.8, 3.696], [14493.8, 0.49], [51675.0, 0.0], [58134.4, 0.002], [61364.1, 0.0], [62010.0, 1.629], [63293.3, 7.184], [63302.0, 0.015], [63422.5, 13.301], [63593.8, 0.028], [63770.6, 2.349], [63786.4, 0.667], [63947.9, 0.151], [64262.1, 3.192], [64270.8, 0.024], [64480.0, 15.201], [64516.2, 0.0], [64533.4, 0.055], [64535.6, 0.003], [64564.5, 0.057], [64568.8, 0.015], [64572.0, 0.427], [64576.2, 0.353], [64585.0, 35.735], [64593.8, 33.268]], "asks": [[64593.9, 9.096], [64600.1, 0.002], [64601.0, 0.003], [64609.3, 0.008], [64613.4, 0.006], [64620.7, 0.001], [64634.4, 0.305], [64639.2, 0.455], [64651.8, 0.0], [64651.9, 0.01], [64710.7, 2.324], [64714.1, 0.087], [64736.6, 0.093], [64774.4, 2.826], [64775.4, 10.614], [65239.8, 0.075], [65421.2, 0.763], [65433.6, 3.974], [65482.4, 55.859], [65537.0, 0.459], [65593.9, 0.02]]}
{"kind": "depth", "E": 1787088304913, "U": 11315916761556, "u": 11315916769834, "recv_ms": 1787088304851, "bids": [[1000.0, 35.76], [14293.8, 0.168], [14393.8, 3.738], [14493.8, 0.294], [58134.4, 0.002], [61355.8, 0.004], [61355.9, 0.011], [61364.1, 0.0], [62010.0, 1.626], [63777.7, 31.734], [63867.7, 6.115], [63947.9, 0.151], [64326.4, 0.0], [64342.8, 0.942], [64561.4, 0.001], [64561.5, 2.64], [64585.5, 0.658], [64585.6, 0.018], [64588.7, 0.085], [64593.8, 33.269]], "asks": [[64593.9, 9.098], [64595.5, 0.113], [64596.2, 0.003], [64597.8, 0.014], [64599.8, 0.002], [64774.4, 1.424], [64775.4, 0.0], [65239.8, 0.075], [65353.7, 7.337], [65405.0, 0.182], [65514.7, 9.761], [65692.0, 6.233]]}
{"kind": "depth", "E": 1787088305015, "U": 11315916770009, "u": 11315916778159, "recv_ms": 1787088304952, "bids": [[14293.8, 0.42], [14393.8, 3.598], [14493.8, 0.182], [58134.4, 0.002], [59785.6, 0.002], [61355.9, 0.009], [62010.0, 1.629], [63593.8, 0.008], [63947.9, 0.151], [64270.8, 2.354], [64582.4, 0.009]], "asks": [[64596.4, 0.004], [64601.4, 0.004], [64603.3, 0.015], [65239.8, 0.075], [65282.2, 5.503], [65362.6, 1.847], [65498.2, 2.413], [65527.6, 5.333], [65593.9, 0.0]]}
{"kind": "depth", "E": 1787088305117, "U": 11315916778318, "u": 11315916791688, "recv_ms": 1787088305056, "bids": [[14293.8, 0.644], [14393.8, 3.5], [14493.8, 0.056], [51672.0, 0.0], [51675.0, 0.002], [58134.4, 0.002], [61364.1, 0.0], [62010.0, 1.626], [63431.1, 0.393], [63947.9, 0.151], [64270.8, 2.354], [64469.8, 0.005], [64476.6, 3.888], [64478.8, 0.043], [64487.7, 2.322], [64520.6, 0.0], [64520.8, 2.366], [64582.2, 0.003], [64584.5, 0.0], [64586.8, 0.798], [64587.7, 0.495], [64588.3, 1.673], [64589.0, 0.41], [64590.1, 0.57], [64593.0, 0.003], [64593.7, 0.066], [64593.8, 33.162]], "asks": [[64593.9, 9.098], [64595.8, 0.002], [64595.9, 0.0], [64600.1, 0.002], [64601.0, 0.003], [64603.2, 0.043], [64604.0, 0.405], [64606.1, 0.023], [64611.7, 4.013], [64621.8, 0.107], [64626.4, 1.89], [64626.5, 0.01], [64627.9, 0.0], [64637.6, 4.256], [64662.8, 0.162], [64663.0, 1.306], [64673.0, 0.013], [64676.3, 10.77], [64701.6, 2.322], [64713.8, 0.0], [64714.8, 0.017], [64720.3, 0.013], [64728.8, 4.313], [64728.9, 0.512], [65239.8, 0.075], [65530.5, 2.103], [65603.0, 0.031]]}
{"kind": "depth", "E": 1787088305219, "U": 11315916791978, "u": 11315916802030, "recv_ms": 1787088305155, "bids": [[1000.0, 35.76], [14293.8, 0.952], [14393.8, 3.248], [14493.8, 0.0], [51675.0, 0.0], [58134.4, 0.002], [61364.1, 0.0], [63593.8, 0.028], [63947.9, 0.151], [64435.1, 1.353], [64475.7, 0.009], [64476.7, 2.554], [64524.6, 6.901], [64541.9, 2.378], [64561.0, 0.97], [64561.1, 0.042], [64561.2, 0.0], [64564.4, 0.034], [64564.5, 0.055], [64564.6, 0.001], [64577.0, 1.532], [64582.4, 0.009], [64591.6, 0.775], [64593.8, 33.162]], "asks": [[64609.4, 1.24], [64616.9, 1.257], [64624.2, 2.721], [64637.5, 1.16], [64655.2, 0.045], [64659.8, 1.842], [64678.7, 2.319], [64701.4, 0.616], [64720.2, 1.064], [64727.6, 0.89], [65239.8, 0.075], [65421.3, 0.763], [65469.9, 6.12], [65511.1, 0.229], [65543.4, 1.219], [65593.9, 0.02]]}
{"kind": "depth", "E": 1787088305321, "U": 11315916802311, "u": 11315916810961, "recv_ms": 1787088305258, "bids": [[14293.8, 1.316], [14393.8, 2.884], [58134.4, 0.002], [61364.1, 0.0], [62010.0, 1.629], [63628.9, 1.389], [63821.0, 1.508], [63947.9, 0.151], [63993.5, 0.005], [64003.1, 2.281], [64450.3, 0.0], [64541.7, 0.003], [64561.5, 2.636], [64585.5, 0.55], [64585.6, 0.094], [64588.7, 0.117], [64593.8, 33.159]], "asks": [[64593.9, 9.318], [64601.2, 0.051], [64603.2, 0.042], [64617.7, 0.061], [64733.1, 2.092], [65211.2, 0.719], [65239.8, 0.075], [65298.0, 1.945], [65353.2, 31.17], [65392.4, 23.772], [65880.8, 0.003], [65989.3, 0.649]]}
{"kind": "depth", "E": 1787088305423, "U": 11315916810993, "u": 11315916817593, "recv_ms": 1787088305360, "bids": [[14293.8, 1.666], [14393.8, 2.534], [58134.4, 0.002], [61364.1, 0.0], [62010.0, 1.626], [63593.8, 0.008], [63947.9, 0.151], [64270.8, 2.354], [64450.4, 3.27], [64487.7, 2.322], [64554.0, 0.027], [64561.5, 2.64], [64566.5, 0.296], [64567.1, 0.072], [64568.0, 0.007], [64580.9, 0.004], [64581.5, 0.927], [64582.0, 0.005], [64582.5, 0.332], [64585.4, 1.257], [64585.6, 0.087], [64588.7, 0.124], [64593.8, 33.204]], "asks": [[64595.4, 0.085], [64601.8, 0.038], [64610.7, 0.001], [64613.0, 0.014], [64613.5, 0.556], [64614.0, 1.053], [64614.2, 0.096], [64614.9, 0.376], [64617.1, 0.04], [64617.9, 0.56], [64619.1, 0.002], [64619.9, 0.057], [64651.9, 0.0], [64652.0, 0.053], [64701.5, 3.701], [64701.6, 0.0], [64733.1, 7.499], [65239.8, 0.075], [65369.0, 4.808], [65457.0, 20.352], [65537.0, 0.84], [65593.9, 0.0], [65747.6, 2.739]]}
{"kind": "depth", "E": 1787088305525, "U": 11315916817670, "u": 11315916825562, "recv_ms": 1787088305462, "bids": [[1000.0, 35.76], [14293.8, 2.016], [14393.8, 2.184], [51675.0, 0.0], [58134.4, 0.002], [62010.0, 1.629], [63293.3, 7.178], [63297.3, 0.025], [63947.9, 0.151], [64512.9, 35.045], [64521.7, 0.0], [64523.9, 0.017], [64524.6, 2.038], [64581.5, 0.927], [64582.5, 0.332], [64585.0, 35.729], [64587.7, 0.492], [64593.5, 2.981]], "asks": [[64593.9, 9.098], [64595.2, 0.092], [64595.4, 0.001], [64595.7, 0.085], [64598.2, 0.003], [64599.9, 0.675], [64613.9, 0.926], [64614.0, 0.127], [64614.9, 0.376], [64865.7, 0.6], [64958.4, 0.019], [65226.9, 0.994], [65239.8, 0.075], [65478.8, 1.246]]}
{"kind": "depth", "E": 1787088305627, "U": 11315916825740, "u": 11315916832033, "recv_ms": 1787088305565, "bids": [[14293.8, 2.38], [14393.8, 1.82], [58134.4, 0.002], [61364.1, 0.0], [62010.0, 1.626], [63593.8, 0.028], [63644.3, 0.549], [63947.9, 0.151], [64270.8, 2.353], [64512.9, 0.002], [64521.7, 35.267], [64561.5, 2.64], [64593.5, 3.065], [64593.8, 33.21]], "asks": [[64593.9, 9.318], [64595.2, 0.008], [64597.1, 0.002], [64916.9, 2.307], [65239.8, 0.075], [65392.4, 23.513], [65465.9, 2.056], [65514.7, 8.694], [65593.9, 0.02], [65756.6, 0.365]]}
{"kind": "depth", "E": 1787088305729, "U": 11315916832262, "u": 11315916838416, "recv_ms": 1787088305667, "bids": [[1000.0, 35.76], [14293.8, 2.744], [14393.8, 1.456], [51675.0, 0.0], [58134.4, 0.002], [61364.1, 0.001], [63721.8, 0.156], [63947.9, 0.151], [64270.8, 2.354], [64433.3, 0.147], [64433.5, 4.738], [64450.4, 0.002], [64450.5, 3.266], [64587.2, 0.482], [64587.5, 0.0], [64588.3, 0.125], [64588.7, 1.64]], "asks": [[64593.9, 7.918], [64594.0, 0.001], [64595.7, 0.001], [64595.8, 0.004], [64599.8, 0.01], [64600.1, 0.001], [64602.0, 0.13], [64603.6, 0.088], [64608.8, 0.216], [64608.9, 0.544], [64609.0, 2.237], [64609.7, 0.0], [64610.9, 0.626], [64611.5, 0.0], [64613.9, 0.0], [64614.4, 0.934], [64617.0, 0.868], [64617.9, 0.003], [64620.1, 0.115], [64620.8, 0.011], [64623.1, 0.062], [64733.1, 7.499], [64750.0, 13.274], [64916.9, 2.308], [65239.8, 0.077], [65360.1, 72.944], [66199.7, 2.87]]}
{"kind": "depth", "E": 1787088305831, "U": 11315916838437, "u": 11315916845325, "recv_ms": 1787088305769, "bids": [[1000.0, 35.76], [14293.8, 3.094], [14393.8, 1.106], [58134.4, 0.002], [61364.1, 0.0], [62010.0, 1.629], [63593.8, 0.008], [63947.9, 0.151], [64512.9, 35.269], [64521.7, 0.0], [64523.9, 0.017], [64561.5, 2.63], [64561.6, 5.017], [64563.1, 1.3], [64568.6, 0.653], [64575.9, 1.574], [64585.6, 0.126], [64588.7, 1.633], [64590.1, 0.09], [64593.8, 33.21]], "asks": [[64595.9, 0.084], [64599.8, 0.56], [64601.2, 0.052], [64602.0, 0.129], [64603.6, 0.004], [64608.9, 0.11], [64613.1, 2.971], [64620.5, 0.629], [65239.8, 0.075], [65369.0, 5.022], [65593.9, 0.0]]}
{"kind": "depth", "E": 1787088305933, "U": 11315916845470, "u": 11315916851060, "recv_ms": 1787088305872, "bids": [[14293.8, 3.458], [14393.8, 0.742], [58134.4, 0.002], [62010.0, 1.626], [63642.1, 2.211], [63947.9, 0.151], [64512.9, 0.002], [64521.7, 35.394], [64554.0, 0.031], [64561.5, 2.626], [64562.2, 0.143], [64562.6, 0.074], [64575.6, 0.0], [64575.9, 1.69], [64576.1, 0.002], [64576.8, 0.558], [64579.8, 0.0], [64580.1, 0.811], [64589.0, 0.409], [64593.2, 0.001], [64593.3, 0.041]], "asks": [[64594.0, 0.003], [64595.8, 0.002], [64605.7, 0.001], [64605.8, 0.311], [64607.5, 0.004], [64607.9, 1.675], [64617.0, 0.311], [64617.1, 0.597], [64618.8, 0.117], [64619.0, 0.004], [64620.1, 0.108], [64620.4, 0.009], [65239.8, 0.075], [65530.5, 3.17], [65550.4, 1.301]]}
{"kind": "depth", "E": 1787088306035, "U": 11315916851114, "u": 11315916857205, "recv_ms": 1787088305974, "bids": [[1000.0, 35.76], [14193.8, 0.042], [14293.8, 3.724], [14393.8, 0.434], [58134.4, 0.002], [61355.9, 0.007], [62010.0, 1.629], [63302.0, 0.018], [63593.8, 0.028], [63810.0, 74.529], [63947.9, 0.151], [64106.3, 3.965], [64270.8, 2.364], [64516.2, 0.003], [64521.7, 0.0], [64523.9, 35.411], [64524.4, 0.163], [64530.4, 0.001], [64530.7, 0.0], [64531.0, 0.001], [64531.4, 0.0], [64535.6, 0.0], [64547.0, 0.027], [64547.4, 0.48], [64547.7, 1.247], [64548.0, 0.418], [64548.3, 0.001], [64561.9, 0.001], [64562.0, 0.001], [64562.1, 0.002], [64562.2, 0.003], [64562.3, 0.0], [64562.4, 0.003], [64562.5, 0.002], [64562.6, 0.004], [64562.7, 0.098], [64562.9, 0.01], [64563.3, 0.001], [64568.1, 0.005], [64585.0, 35.629], [64586.4, 0.035], [64586.5, 0.013], [64586.6, 0.072], [64586.7, 0.0], [64586.8, 0.598], [64586.9, 0.0], [64587.0, 0.918], [64587.1, 0.001], [64587.2, 0.312], [64587.3, 0.086], [64587.4, 0.072], [64587.7, 0.46], [64588.0, 0.003], [64588.3, 0.093], [64588.6, 1.11], [64588.7, 0.085], [64588.8, 0.018], [64588.9, 1.705], [64589.0, 0.377]], "asks": [[64598.8, 0.202], [64599.8, 0.002], [64601.2, 0.051], [64602.0, 0.128], [64602.1, 0.017], [64602.4, 0.002], [64602.8, 0.044], [64603.1, 0.351], [64603.4, 0.005], [64603.6, 0.012], [64603.8, 0.685], [64603.9, 0.236], [64604.0, 0.039], [64604.1, 0.0], [64604.2, 0.065], [64604.3, 1.0], [64604.4, 0.253], [64604.6, 0.154], [64604.7, 0.002], [64604.8, 0.009], [64605.0, 0.001], [64606.8, 0.168], [64607.8, 0.015], [64608.9, 0.714], [64611.4, 0.169], [64616.3, 0.099], [64622.3, 0.315], [64622.5, 0.094], [64623.1, 0.216], [64624.0, 0.263], [64624.3, 0.007], [64624.7, 0.0], [64625.0, 0.092], [64625.3, 0.108], [64625.7, 0.002], [64626.3, 10.022], [64626.9, 0.001], [64627.0, 0.001], [64627.2, 0.051], [64627.3, 0.398], [64627.4, 0.003], [64627.6, 0.064], [64627.7, 0.936], [64628.0, 0.002], [64628.1, 0.032], [64640.7, 0.002], [64641.0, 0.079], [64641.3, 0.001], [64641.6, 0.002], [64642.3, 0.006], [64652.1, 0.004], [64671.4, 0.027], [65239.8, 0.077], [65292.1, 1.534], [65360.1, 67.673], [65369.0, 5.785], [65392.4, 23.285], [65593.9, 0.02]]}
{"kind": "depth", "E": 1787088306239, "U": 11315916871066, "u": 11315916880663, "recv_ms": 1787088306180, "bids": [[14193.8, 0.476], [14293.8, 3.57], [14393.8, 0.154], [58134.4, 0.002], [61364.1, 0.0], [62010.0, 1.626], [63593.8, 0.008], [63650.7, 0.314], [63818.7, 7.828], [63824.1, 1.293], [63947.9, 0.151], [64520.4, 0.445], [64524.6, 6.977], [64529.2, 0.086], [64535.6, 0.003], [64553.4, 0.032], [64553.7, 0.033], [64554.1, 0.037], [64554.4, 2.353], [64568.6, 0.034], [64575.9, 1.071], [64577.0, 1.532], [64584.9, 0.312], [64585.0, 35.615], [64586.5, 0.083], [64587.1, 1.719], [64587.2, 0.312], [64587.3, 0.156], [64588.0, 0.035], [64588.4, 0.032], [64588.6, 1.11], [64588.7, 0.117], [64588.8, 0.026], [64589.0, 0.409], [64593.7, 0.057], [64593.8, 33.211]], "asks": [[64593.9, 7.465], [64594.0, 0.001], [64595.9, 0.0], [64596.3, 0.0], [64597.1, 0.004], [64599.8, 0.01], [64599.9, 0.759], [64602.2, 0.061], [64602.6, 0.064], [64602.9, 0.443], [64603.2, 0.1], [64603.6, 0.005], [64604.0, 0.165], [64604.1, 0.24], [64604.8, 0.142], [64608.8, 0.278], [64608.9, 0.652], [64609.4, 1.24], [64613.1, 2.352], [64619.6, 0.05], [64619.9, 0.105], [64620.2, 0.511], [64620.5, 0.068], [64620.9, 2.13], [64622.5, 0.22], [64622.6, 0.285], [64623.3, 2.465], [64636.9, 0.098], [64637.2, 0.048], [64637.5, 1.227], [64637.8, 0.06], [64649.7, 0.813], [64671.5, 0.065], [64675.2, 2.557], [64682.4, 0.377], [64693.6, 0.056], [64779.2, 0.0], [64779.3, 0.003], [64808.7, 0.477], [65239.8, 0.075], [65311.5, 1.53], [65369.0, 11.054], [65593.9, 0.0], [104929.0, 0.0]]}
{"kind": "depth", "E": 1787088306341, "U": 11315916880773, "u": 11315916891444, "recv_ms": 1787088306281, "bids": [[1000.0, 35.76], [14193.8, 0.714], [14293.8, 3.458], [14393.8, 0.028], [51675.0, 0.0], [58134.4, 0.002], [62010.0, 1.629], [63947.9, 0.151], [64270.8, 2.364], [64474.1, 0.001], [64586.5, 0.153], [64586.6, 0.142], [64586.7, 0.07], [64586.8, 0.768], [64586.9, 0.2], [64587.2, 0.412], [64587.3, 0.256], [64588.7, 0.125], [64588.8, 0.018], [64589.1, 0.018], [64593.8, 33.211]], "asks": [[64599.8, 0.567], [64603.6, 0.004], [64603.9, 0.456], [64604.0, 0.415], [64604.3, 1.49], [64604.4, 0.513], [64604.5, 1.666], [64604.7, 0.261], [64607.8, 0.069], [64608.6, 0.019], [64608.7, 0.258], [64608.8, 0.216], [64608.9, 0.103], [64621.2, 0.225], [64621.7, 0.261], [64622.5, 0.47], [64622.8, 0.306], [64622.9, 0.587], [64623.0, 0.288], [64623.1, 0.342], [64623.2, 0.14], [65239.8, 0.075], [65401.3, 3.143]]}
{"kind": "depth", "E": 1787088306443, "U": 11315916891587, "u": 11315916902080, "recv_ms": 1787088306383, "bids": [[1000.0, 35.76], [14193.8, 1.036], [14293.8, 3.164], [14393.8, 0.0], [58134.4, 0.002], [61364.1, 0.0], [62010.0, 1.626], [63404.4, 0.043], [63593.8, 0.028], [63713.1, 31.416], [63931.3, 0.157], [63947.9, 0.151], [64535.8, 0.037], [64536.7, 0.125], [64568.2, 0.071], [64568.9, 0.07], [64585.5, 0.008], [64585.6, 0.01], [64587.1, 0.171], [64588.7, 0.125], [64588.8, 0.676], [64588.9, 1.705], [64592.0, 0.946]], "asks": [[64593.9, 7.466], [65239.8, 0.075], [65343.8, 0.764], [65392.4, 23.056], [65593.9, 0.02], [65880.8, 0.0], [67177.7, 0.016]]}
{"kind": "depth", "E": 1787088306545, "U": 11315916902471, "u": 11315916911193, "recv_ms": 1787088306485, "bids": [[14193.8, 1.386], [14293.8, 2.814], [51675.0, 0.0], [58134.4, 0.002], [62010.0, 1.629], [63777.7, 31.5], [63786.4, 0.902], [63942.1, 0.013], [63947.2, 0.387], [63947.9, 0.151], [64450.5, 0.005], [64536.1, 0.07], [64536.4, 0.035], [64537.1, 0.05], [64545.0, 0.298], [64568.3, 0.07], [64568.5, 1.11], [64568.6, 0.104], [64585.5, 0.008], [64587.1, 1.719], [64588.6, 1.11], [64588.7, 0.783], [64588.8, 0.018], [64588.9, 0.157], [64589.1, 0.018], [64592.0, 0.905]], "asks": [[64596.2, 0.001], [64599.5, 0.087], [64620.3, 0.002], [64733.1, 2.092], [64850.0, 25.911], [65239.8, 0.075], [65435.0, 0.949], [65440.7, 0.768], [104929.0, 0.236]]}
{"kind": "depth", "E": 1787088306647, "U": 11315916911254, "u": 11315916919303, "recv_ms": 1787088306584, "bids": [[1000.0, 35.76], [14193.8, 1.75], [14293.8, 2.45], [58134.4, 0.002], [61364.1, 0.0], [63593.8, 0.008], [63867.7, 5.239], [63947.9, 0.151], [64003.6, 3.275], [64270.8, 2.363], [64383.9, 0.078], [64391.5, 0.102], [64392.6, 0.591], [64394.8, 7.236], [64433.5, 0.504], [64433.6, 3.353], [64435.1, 0.942], [64450.6, 3.901], [64506.9, 0.027], [64532.8, 0.003], [64563.0, 4.513], [64568.0, 0.077], [64568.2, 0.141], [64568.7, 0.211], [64568.8, 0.085], [64569.6, 0.108], [64585.5, 0.666], [64588.7, 0.125]], "asks": [[64593.9, 7.548], [64596.6, 0.101], [64601.2, 0.013], [64733.1, 7.499], [64750.0, 13.274], [64788.2, 0.0], [64788.8, 15.435], [64916.9, 2.307], [65239.8, 0.075], [65593.9, 0.0]]}
{"kind": "depth", "E": 1787088306851, "U": 11315916925965, "u": 11315916932334, "recv_ms": 1787088306789, "bids": [[14193.8, 2.464], [14293.8, 1.736], [58134.4, 0.002], [61364.1, 0.0], [62010.0, 1.629], [63293.3, 7.175], [63297.3, 0.016], [63593.8, 0.028], [63609.5, 3.924], [63671.6, 0.011], [63791.8, 0.026], [63947.9, 0.151], [64450.6, 3.901], [64475.6, 0.088], [64512.9, 0.002], [64521.7, 35.73], [64524.6, 2.038], [64561.0, 0.972], [64561.1, 0.044], [64561.2, 0.002], [64564.4, 0.036], [64564.5, 0.057], [64564.6, 0.003], [64575.2, 0.116], [64575.9, 0.955], [64576.1, 0.559], [64576.8, 0.001], [64578.6, 2.938], [64581.6, 0.0], [64582.1, 0.52], [64583.0, 0.543], [64586.0, 1.443], [64593.7, 0.067], [64593.8, 33.045]], "asks": [[64593.9, 7.129], [64596.2, 0.001], [64599.6, 1.024], [64599.7, 1.756], [64599.8, 0.018], [64599.9, 0.094], [64600.1, 0.002], [64602.0, 0.127], [64603.6, 0.004], [64606.1, 0.085], [64607.8, 0.007], [64608.9, 0.652], [64624.5, 0.015], [64631.9, 0.017], [64733.1, 7.499], [65101.8, 10.351], [65239.8, 0.075], [65593.9, 0.02], [65736.6, 2.259]]}
{"kind": "depth", "E": 1787088306953, "U": 11315916932405, "u": 11315916939135, "recv_ms": 1787088306891, "bids": [[1000.0, 35.76], [14193.8, 2.814], [14293.8, 1.386], [58134.4, 0.002], [62010.0, 1.626], [63385.9, 0.787], [63593.8, 0.008], [63818.7, 9.047], [63882.4, 2.065], [63947.9, 0.151], [64236.2, 0.002], [64250.7, 0.492], [64270.8, 2.364], [64575.2, 0.0], [64576.0, 0.126], [64576.1, 0.002], [64576.8, 0.558], [64579.8, 0.007], [64580.1, 0.804], [64587.1, 0.171], [64588.7, 1.673], [64593.2, 0.004], [64593.3, 0.038], [64593.8, 33.046]], "asks": [[64596.2, 0.085], [64597.1, 0.002], [64598.0, 0.069], [64617.1, 0.04], [64617.3, 0.557], [64626.3, 11.907], [64626.4, 0.005], [64653.4, 0.055], [64656.0, 0.035], [65110.7, 0.308], [65239.8, 0.075], [65353.4, 1.273], [65440.8, 0.765], [65593.9, 0.0]]}
{"kind": "depth", "E": 1787088307055, "U": 11315916939269, "u": 11315916951074, "recv_ms": 1787088306998, "bids": [[1000.0, 35.76], [14193.8, 3.178], [14293.8, 1.022], [58134.4, 0.004], [62010.0, 1.629], [63745.4, 28.272], [63947.9, 0.155], [64497.3, 0.005], [64498.0, 0.592], [64514.3, 0.0], [64516.7, 0.04], [64554.0, 0.027], [64561.5, 2.63], [64574.1, 0.054], [64576.4, 0.13], [64578.2, 0.243], [64582.2, 0.008], [64583.1, 0.147], [64587.7, 0.495], [64588.7, 2.217], [64588.8, 0.527], [64589.1, 1.036], [64590.0, 0.065], [64590.9, 1.026], [64592.0, 0.908], [64593.8, 33.133]], "asks": [[64593.9, 5.274], [64595.2, 0.007], [64596.2, 0.001], [64596.6, 0.017], [64597.0, 0.002], [64597.1, 0.002], [64597.3, 0.001], [64597.7, 0.001], [64597.9, 0.724], [64598.0, 0.067], [64598.3, 0.085], [64598.4, 0.092], [64598.7, 0.003], [64599.0, 0.006], [64599.1, 1.969], [64599.8, 0.001], [64600.2, 0.086], [64600.6, 0.086], [64600.9, 0.025], [64601.0, 0.087], [64601.3, 0.084], [64601.6, 0.019], [64601.7, 0.084], [64603.7, 0.0], [64603.8, 0.241], [64604.0, 0.383], [64604.2, 0.816], [64604.8, 0.141], [64605.8, 0.002], [64606.2, 0.689], [64608.0, 0.012], [64608.9, 0.086], [64609.4, 0.003], [64609.5, 0.01], [64611.2, 0.01], [64611.3, 0.01], [64612.0, 0.341], [64613.3, 0.173], [64614.8, 0.141], [64616.1, 0.002], [64617.1, 0.0], [64617.3, 0.0], [64617.9, 0.56], [64620.6, 0.008], [64621.6, 0.002], [64622.4, 0.008], [64622.7, 3.801], [64625.2, 0.001], [64625.6, 0.003], [64626.3, 1.907], [64627.9, 0.07], [64628.4, 0.0], [64632.1, 0.16], [64633.5, 10.002], [64635.5, 0.061], [64650.7, 0.001], [64657.2, 0.211], [65239.8, 0.075], [65369.9, 0.875], [65401.3, 3.371], [65756.6, 0.487], [65885.7, 0.037]]}
{"kind": "depth", "E": 1787088307157, "U": 11315916951167, "u": 11315916977431, "recv_ms": 1787088307098, "bids": [[14193.8, 3.528], [14293.8, 0.672], [58134.4, 0.002], [61364.1, 0.0], [63593.8, 0.028], [63856.5, 1.567], [63947.9, 0.151], [64077.0, 0.049], [64401.6, 2.809], [64403.2, 0.157], [64476.6, 0.018], [64476.7, 6.424], [64497.3, 0.0], [64497.5, 0.005], [64515.6, 1.028], [64516.7, 0.014], [64520.8, 2.32], [64520.9, 0.046], [64521.7, 0.0], [64523.9, 35.747], [64524.0, 0.128], [64530.8, 0.21], [64537.4, 0.0], [64537.6, 1.438], [64543.8, 0.013], [64546.0, 0.011], [64551.0, 0.038], [64551.1, 0.062], [64552.3, 0.063], [64552.6, 0.0], [64552.7, 0.0], [64553.2, 1.202], [64553.8, 0.0], [64555.3, 0.062], [64558.6, 0.12], [64558.9, 1.438], [64560.1, 0.0], [64560.3, 0.01], [64560.7, 0.002], [64561.0, 0.997], [64561.6, 0.017], [64561.9, 0.001], [64562.9, 0.006], [64563.0, 2.545], [64563.1, 2.865], [64563.7, 0.002], [64565.3, 0.003], [64565.7, 0.097], [64566.4, 0.064], [64567.1, 0.015], [64567.5, 0.001], [64568.9, 0.16], [64569.1, 0.075], [64569.3, 0.0], [64569.4, 0.856], [64571.8, 0.1], [64572.7, 0.116], [64573.2, 0.003], [64573.3, 0.085], [64574.1, 0.035], [64574.5, 0.159], [64574.7, 0.0], [64575.4, 0.001], [64575.5, 0.063], [64576.0, 0.567], [64576.1, 0.004], [64576.4, 0.095], [64576.7, 0.345], [64576.8, 0.001], [64577.1, 0.002], [64577.5, 0.002], [64578.8, 0.012], [64579.4, 0.008], [64579.6, 0.0], [64580.4, 0.93], [64580.5, 0.542], [64580.6, 0.001], [64581.0, 0.02], [64581.1, 0.009], [64581.3, 0.003], [64581.4, 0.019], [64581.5, 0.0], [64581.6, 0.0], [64581.8, 0.015], [64581.9, 0.0], [64582.2, 0.003], [64582.9, 0.626], [64583.0, 0.001], [64584.5, 0.184], [64584.9, 0.311], [64585.1, 4.277], [64585.2, 0.157], [64585.4, 0.462], [64585.5, 0.008], [64586.0, 1.175], [64586.3, 0.314], [64587.2, 0.103], [64587.6, 0.002], [64587.7, 0.182], [64587.8, 0.154], [64588.2, 0.13], [64588.3, 0.084], [64588.6, 1.11], [64588.7, 1.665], [64588.8, 0.566], [64589.0, 0.409], [64589.1, 0.562], [64589.2, 0.646], [64589.3, 0.107], [64589.4, 0.543], [64589.5, 1.019], [64589.6, 0.154], [64590.0, 0.006], [64590.7, 0.0], [64590.8, 0.001], [64590.9, 0.084], [64591.2, 0.002], [64591.5, 0.087], [64591.6, 0.476], [64591.7, 0.044], [64591.8, 0.019], [64591.9, 0.001], [64592.0, 0.905], [64592.1, 0.086], [64592.2, 0.003], [64592.3, 0.0], [64592.5, 0.284], [64593.1, 0.312], [64593.2, 0.001], [64593.4, 0.0], [64593.5, 0.352], [64593.6, 0.229], [64593.7, 0.067], [64593.8, 19.228]], "asks": [[64593.9, 10.443], [64594.0, 0.003], [64594.3, 0.09], [64594.4, 0.004], [64594.8, 0.084], [64595.0, 0.001], [64595.3, 0.001], [64595.5, 0.197], [64595.6, 0.003], [64596.0, 0.312], [64596.2, 0.085], [64596.5, 0.015], [64596.7, 0.085], [64596.8, 0.002], [64596.9, 0.002], [64597.1, 0.312], [64597.2, 0.0], [64597.3, 0.085], [64597.4, 0.001], [64597.7, 0.094], [64597.8, 0.01], [64597.9, 0.724], [64598.4, 0.008], [64598.5, 0.003], [64598.6, 0.001], [64599.0, 0.007], [64599.1, 0.084], [64599.2, 0.007], [64599.3, 0.004], [64599.6, 0.002], [64599.7, 0.0], [64599.8, 0.001], [64599.9, 0.672], [64600.1, 0.006], [64600.2, 0.002], [64600.3, 0.0], [64600.6, 0.002], [64601.0, 0.003], [64601.1, 0.621], [64601.3, 0.0], [64601.6, 0.02], [64601.7, 0.0], [64602.0, 0.127], [64603.5, 0.073], [64603.6, 2.355], [64604.0, 0.381], [64604.4, 0.582], [64604.8, 0.142], [64604.9, 0.31], [64605.2, 0.041], [64605.5, 0.276], [64606.0, 0.243], [64606.1, 0.023], [64607.8, 0.0], [64608.0, 0.013], [64608.1, 0.009], [64608.4, 0.077], [64608.5, 0.566], [64608.7, 0.274], [64608.8, 1.453], [64608.9, 0.628], [64609.0, 2.23], [64609.1, 3.131], [64609.3, 0.008], [64610.9, 0.007], [64611.2, 0.011], [64611.3, 0.005], [64611.5, 0.0], [64611.6, 0.726], [64613.0, 0.556], [64613.3, 0.297], [64613.4, 0.932], [64613.5, 0.014], [64613.7, 0.058], [64614.4, 0.008], [64614.5, 0.421], [64614.8, 0.125], [64615.1, 0.039], [64615.3, 0.208], [64615.4, 0.001], [64615.5, 0.12], [64615.9, 0.0], [64616.1, 0.051], [64616.2, 0.586], [64616.3, 0.101], [64616.9, 1.237], [64617.3, 0.116], [64617.9, 0.003], [64618.2, 0.594], [64618.8, 0.001], [64619.2, 1.188], [64619.9, 0.048], [64620.1, 0.108], [64620.2, 0.581], [64620.3, 0.042], [64620.4, 0.002], [64620.8, 0.072], [64621.3, 0.12], [64621.4, 0.184], [64621.6, 0.311], [64621.9, 10.322], [64622.0, 0.003], [64622.3, 0.315], [64622.6, 0.285], [64622.7, 3.751], [64623.3, 2.465], [64623.8, 1.87], [64624.2, 0.007], [64625.3, 0.018], [64626.7, 0.044], [64627.3, 0.373], [64627.4, 0.001], [64627.5, 0.043], [64627.6, 0.066], [64627.9, 0.0], [64629.2, 0.095], [64630.1, 0.0], [64630.8, 0.028], [64632.1, 0.04], [64632.7, 0.002], [64633.5, 0.002], [64633.9, 0.001], [64635.5, 0.001], [64636.5, 0.004], [64636.6, 0.149], [64637.6, 4.258], [64638.3, 0.0], [64638.4, 0.014], [64639.6, 0.164], [64642.0, 4.405], [64643.1, 0.699], [64643.9, 0.001], [64648.2, 0.0], [64649.0, 0.032], [64652.0, 0.263], [64653.4, 0.013], [64656.0, 0.051], [64657.2, 0.001], [64657.3, 0.026], [64658.5, 0.743], [64663.0, 1.26], [64663.1, 0.77], [64728.8, 0.443], [64728.9, 4.382], [65239.8, 0.075], [65353.2, 29.642], [65593.9, 0.02], [65885.7, 0.034]]}
{"kind": "depth", "E": 1787088307259, "U": 11315916978000, "u": 11315916986643, "recv_ms": 1787088307196, "bids": [[1000.0, 35.76], [14093.8, 0.07], [14193.8, 3.752], [14293.8, 0.378], [51675.0, 0.0], [58134.4, 0.002], [61364.1, 0.0], [62010.0, 1.626], [63605.7, 0.035], [63947.9, 0.151], [64263.5, 0.044], [64270.8, 2.354], [64272.5, 0.12], [64524.6, 7.029], [64575.9, 0.937], [64577.0, 1.532], [64578.1, 0.154], [64578.2, 0.089], [64578.8, 0.019], [64579.8, 0.0], [64580.4, 0.003], [64580.5, 0.0], [64581.1, 0.936], [64581.2, 0.768], [64581.3, 0.002], [64581.9, 0.0], [64582.0, 0.005], [64582.8, 0.238], [64583.0, 0.001], [64587.0, 1.142], [64588.2, 0.006], [64588.5, 0.706], [64588.7, 1.937], [64588.8, 1.132], [64589.0, 0.516], [64589.1, 1.036], [64589.2, 0.102], [64589.3, 0.083], [64589.4, 0.001], [64589.5, 0.001], [64591.6, 0.283], [64592.5, 0.2], [64593.8, 17.531]], "asks": [[64593.9, 10.613], [64594.4, 0.001], [64595.2, 0.008], [64595.5, 0.099], [64598.4, 0.009], [64604.5, 0.276], [64605.8, 0.094], [64607.9, 1.677], [64609.4, 0.003], [64610.6, 0.066], [64613.4, 0.006], [64614.3, 0.928], [64617.3, 0.0], [64618.2, 0.537], [64618.8, 0.117], [64619.2, 1.245], [64620.9, 3.836], [64632.4, 0.002], [64644.2, 6.972], [64648.6, 0.003], [64655.2, 0.042], [64922.4, 0.169], [64928.4, 0.11], [65239.8, 0.075], [65401.3, 3.63]]}
{"kind": "depth", "E": 1787088307361, "U": 11315916986763, "u": 11315916994023, "recv_ms": 1787088307298, "bids": [[1000.0, 35.76], [14093.8, 0.28], [14193.8, 3.682], [14293.8, 0.238], [45212.4, 0.002], [51675.0, 0.0], [58134.4, 0.002], [61364.1, 0.0], [62010.0, 1.629], [63302.0, 0.024], [63593.8, 0.008], [63947.9, 0.151], [64290.7, 0.161], [64310.5, 0.084], [64516.2, 0.0], [64526.0, 0.129], [64530.8, 0.0], [64535.6, 0.0], [64538.0, 0.212], [64548.5, 0.003], [64558.6, 0.0], [64565.8, 0.143], [64578.6, 2.319], [64581.2, 0.226], [64583.0, 0.543], [64587.0, 1.018], [64587.8, 0.278], [64588.7, 1.665], [64588.8, 0.58], [64589.1, 0.018], [64589.2, 0.11], [64591.6, 0.482], [64593.8, 17.534]], "asks": [[64593.9, 10.613], [64613.3, 5.297], [64652.1, 0.004], [64653.4, 0.027], [64656.0, 0.009], [64658.5, 0.672], [64671.5, 0.062], [65239.8, 0.075], [65593.9, 0.0]]}
{"kind": "depth", "E": 1787088307463, "U": 11315916994136, "u": 11315916999612, "recv_ms": 1787088307401, "bids": [[14093.8, 0.532], [14193.8, 3.542], [14293.8, 0.126], [34000.0, 1.146], [58134.4, 0.002], [61364.1, 0.0], [62010.0, 1.626], [63615.5, 2.629], [63667.9, 4.276], [63947.9, 0.151], [64179.7, 0.0], [64199.3, 0.004], [64270.8, 2.364], [64588.8, 0.572], [64589.1, 0.018], [64589.2, 0.118], [64591.3, 0.004], [64591.6, 0.483], [64592.6, 0.002], [64593.8, 17.533]], "asks": [[64610.0, 0.906], [64611.0, 1.303], [64626.8, 0.0], [65101.8, 6.517], [65239.8, 0.075], [65369.0, 12.582], [66208.7, 0.453]]}
{"kind": "depth", "E": 1787088307565, "U": 11315916999798, "u": 11315917006027, "recv_ms": 1787088307502, "bids": [[1000.0, 35.76], [14093.8, 0.77], [14193.8, 3.43], [14293.8, 0.0], [51675.0, 0.0], [58134.4, 0.002], [61355.9, 0.007], [63302.0, 0.021], [63947.9, 0.151], [64522.7, 0.387], [64589.1, 0.018], [64591.6, 0.483], [64593.8, 17.541]], "asks": [[64607.8, 0.016], [64608.0, 0.913], [64608.5, 0.558], [64608.7, 0.266], [64609.0, 1.33], [64622.9, 0.589], [64623.6, 1.886], [64625.8, 0.005], [64626.3, 0.022], [65239.8, 0.075], [65353.2, 28.114], [65369.0, 14.11], [65392.4, 22.941], [65400.0, 95.505], [65482.4, 53.572]]}
{"kind": "depth", "E": 1787088307667, "U": 11315917006120, "u": 11315917011333, "recv_ms": 1787088307603, "bids": [[1000.0, 35.76], [14093.8, 1.12], [14193.8, 3.08], [58134.4, 0.002], [61364.1, 0.002], [62010.0, 1.629], [63593.8, 0.028], [63947.9, 0.151], [64010.9, 0.0], [64015.7, 0.016], [64170.9, 0.0], [64175.7, 0.054], [64331.4, 0.0], [64336.2, 0.004], [64492.2, 0.0], [64497.0, 0.027], [64522.7, 0.31], [64589.0, 0.593], [64589.1, 0.018], [64591.3, 0.003], [64591.6, 0.494], [64593.2, 0.002]], "asks": [[64594.9, 0.002], [64599.0, 0.006], [64608.0, 1.03], [64617.8, 1.009], [64623.5, 1.888], [64623.6, 0.001], [64685.9, 0.0], [64690.7, 0.006], [64847.6, 0.095], [64852.4, 0.006], [65009.7, 0.009], [65014.6, 0.026], [65110.7, 4.141], [65172.3, 0.0], [65177.1, 0.017], [65239.8, 0.075], [65569.9, 0.763], [65593.9, 0.02]]}
{"kind": "depth", "E": 1787088307769, "U": 11315917011499, "u": 11315917016900, "recv_ms": 1787088307772, "bids": [[14093.8, 1.47], [14193.8, 2.73], [58134.4, 0.002], [61364.1, 0.004], [61991.2, 0.0], [62010.0, 1.626], [63593.8, 0.008], [63823.9, 0.0], [63947.9, 0.151], [64122.5, 0.0], [64270.8, 2.363], [64450.6, 4.352], [64581.1, 0.009], [64581.8, 0.016], [64582.1, 0.36], [64582.5, 1.259], [64589.1, 0.018], [64590.8, 0.007], [64591.1, 0.001], [64591.6, 0.494]], "asks": [[64613.0, 0.014], [64613.5, 0.556], [64614.3, 0.002], [64614.9, 1.302], [64616.2, 0.029], [64617.7, 0.618], [64733.1, 7.499], [64916.9, 2.307], [65239.8, 0.075], [65311.5, 2.295], [65401.3, 3.858], [65593.9, 0.0], [65844.5, 1.363]]}
{"kind": "depth", "E": 1787088307871, "U": 11315917017034, "u": 11315917022984, "recv_ms": 1787088307809, "bids": [[1000.0, 35.76], [14093.8, 1.834], [14193.8, 2.366], [51675.0, 0.0], [58134.4, 0.002], [61364.1, 0.004], [62010.0, 1.629], [63674.1, 42.897], [63843.9, 0.792], [63947.9, 0.153], [64270.8, 2.364], [64450.6, 1.117], [64554.5, 3.882], [64561.5, 2.626], [64564.7, 0.001], [64567.6, 0.621], [64574.9, 0.625], [64581.5, 0.927], [64582.5, 0.332], [64589.1, 0.018], [64590.7, 0.001], [64591.6, 0.494], [64593.2, 0.001], [64593.8, 17.541]], "asks": [[64612.2, 0.619], [64613.3, 0.297], [64616.2, 0.027], [64616.3, 0.099], [64619.5, 0.625], [64733.1, 2.092], [64916.9, 2.308], [65239.8, 0.075], [65401.3, 3.973]]}
{"kind": "depth", "E": 1787088307973, "U": 11315917023000, "u": 11315917028647, "recv_ms": 1787088307911, "bids": [[1000.0, 35.76], [14093.8, 2.184], [14193.8, 2.016], [58134.4, 0.002], [62010.0, 1.626], [63803.1, 5.575], [63947.9, 0.151], [64068.3, 7.042], [64250.7, 0.0], [64251.8, 0.494], [64554.5, 3.878], [64562.0, 0.005], [64574.5, 0.043], [64575.6, 0.116], [64576.0, 0.01], [64576.8, 0.558], [64585.7, 0.078], [64588.7, 0.117], [64589.1, 1.643], [64589.2, 1.059], [64589.5, 0.009], [64590.4, 0.001], [64590.7, 0.0], [64591.6, 0.725], [64592.2, 0.0], [64592.6, 0.005], [64593.8, 17.542]], "asks": [[64607.8, 0.093], [64608.4, 0.0], [64609.1, 3.151], [64612.2, 0.0], [64615.7, 3.07], [64616.9, 1.794], [64617.7, 0.061], [64619.8, 0.196], [64620.8, 0.065], [65239.8, 0.075], [65292.1, 0.769], [65424.7, 29.839], [65853.5, 0.757]]}
{"kind": "depth", "E": 1787088308279, "U": 11315917041674, "u": 11315917046996, "recv_ms": 1787088308217, "bids": [[1000.0, 35.76], [14093.8, 3.262], [14193.8, 0.938], [51675.0, 0.0], [58134.4, 0.002], [61364.1, 0.004], [62010.0, 1.626], [63302.0, 0.021], [63593.8, 0.008], [63817.8, 0.882], [63947.9, 0.151], [64450.7, 3.22], [64535.6, 0.003], [64571.8, 0.104], [64575.0, 0.118], [64575.6, 0.0], [64576.0, 0.567], [64576.8, 0.001], [64577.0, 1.53], [64578.8, 0.012], [64580.1, 0.811], [64580.9, 0.931], [64581.0, 0.02], [64581.5, 0.0], [64581.6, 0.0], [64582.1, 0.502], [64583.0, 0.543], [64585.4, 0.463], [64585.7, 0.078], [64587.3, 0.172], [64587.5, 0.31], [64587.8, 0.154], [64588.2, 0.13], [64588.7, 0.389], [64589.0, 0.516], [64589.1, 1.915], [64589.2, 1.059], [64593.3, 0.122], [64593.8, 17.494]], "asks": [[64593.9, 10.606], [64594.8, 0.0], [64596.0, 0.002], [64604.9, 0.001], [64605.1, 1.002], [64605.4, 0.309], [64607.6, 0.004], [64609.4, 0.001], [64610.9, 0.004], [64613.3, 0.297], [64614.2, 1.022], [64614.9, 0.376], [64617.8, 1.009], [64618.8, 0.117], [64619.8, 0.189], [64620.4, 0.009], [64622.8, 0.308], [64622.9, 0.591], [64623.0, 0.29], [64624.7, 0.578], [64625.7, 0.004], [64625.8, 0.007], [64625.9, 0.165], [64626.7, 0.046], [64626.8, 0.002], [64626.9, 0.003], [64628.8, 0.453], [64628.9, 0.002], [64629.0, 0.009], [64639.4, 0.161], [64639.6, 0.008], [64671.5, 0.065], [64733.1, 7.499], [65239.8, 0.075], [65593.9, 0.0]]}
{"kind": "depth", "E": 1787088308381, "U": 11315917047197, "u": 11315917053859, "recv_ms": 1787088308321, "bids": [[14093.8, 3.612], [14193.8, 0.588], [58134.4, 0.002], [61364.1, 0.004], [62010.0, 1.629], [63302.0, 0.024], [63578.5, 0.058], [63593.8, 0.028], [63786.4, 2.154], [63947.9, 0.151], [64270.8, 2.364], [64561.0, 0.995], [64561.1, 0.042], [64561.2, 0.0], [64564.4, 0.034], [64564.5, 0.055], [64564.6, 0.001], [64574.1, 5.035], [64575.9, 1.556], [64577.0, 1.532], [64588.7, 0.117], [64589.0, 0.516], [64589.1, 2.187], [64589.2, 1.059], [64593.8, 17.501]], "asks": [[64595.1, 0.002], [64609.4, 0.003], [64613.4, 1.461], [64613.6, 0.002], [64621.3, 0.0], [64628.7, 0.121], [65239.8, 0.075], [65482.4, 51.284], [65593.9, 0.02], [65679.5, 0.001]]}
{"kind": "depth", "E": 1787088308585, "U": 11315917058521, "u": 11315917062912, "recv_ms": 1787088308524, "bids": [[1000.0, 35.76], [14093.8, 3.654], [14193.8, 0.21], [14493.8, 0.336], [51675.0, 0.0], [58134.4, 0.002], [61355.7, 2.441], [61364.1, 0.004], [63774.8, 4.721], [63811.5, 0.783], [63947.9, 0.151], [63996.9, 0.156], [64433.6, 0.046], [64433.8, 3.251], [64435.1, 1.342], [64450.7, 2.75], [64516.2, 0.0], [64535.6, 0.0], [64548.5, 0.0], [64553.9, 0.002], [64567.6, 0.021], [64574.9, 0.006], [64589.2, 0.041], [64593.8, 17.588]], "asks": [[64593.9, 9.999], [64595.7, 0.001], [64600.1, 0.004], [64602.0, 0.129], [64602.5, 0.056], [64603.5, 0.073], [64607.4, 0.014], [64608.1, 0.002], [64608.6, 0.026], [64608.9, 0.009], [64611.5, 0.619], [64643.4, 0.094], [64652.1, 0.004], [64656.0, 0.037], [64671.5, 0.062], [64733.1, 7.499], [64750.0, 2.849], [64750.1, 10.428], [65239.8, 0.077], [65498.2, 4.7]]}
{"kind": "depth", "E": 1787088308687, "U": 11315917062944, "u": 11315917067962, "recv_ms": 1787088308623, "bids": [[14093.8, 3.514], [14193.8, 0.098], [14493.8, 0.588], [58134.4, 0.002], [61364.1, 0.004], [62010.0, 1.629], [63302.0, 0.021], [63593.8, 0.008], [63683.0, 0.977], [63874.3, 5.326], [63947.9, 0.151], [64270.8, 2.519], [64554.5, 3.882], [64562.0, 0.001], [64589.2, 1.059]], "asks": [[64593.9, 9.989], [64594.9, 0.0], [64595.9, 0.0], [64600.8, 0.003], [64605.8, 0.097], [64608.8, 1.45], [64625.5, 0.002], [65239.8, 0.075], [65593.9, 0.0], [65840.1, 0.65], [65885.7, 0.028]]}
{"kind": "depth", "E": 1787088308789, "U": 11315917068143, "u": 11315917072417, "recv_ms": 1787088308727, "bids": [[1000.0, 35.76], [14093.8, 3.36], [14193.8, 0.0], [14493.8, 0.84], [58134.4, 0.002], [61364.1, 0.006], [62010.0, 1.626], [63302.0, 0.018], [63754.1, 0.118], [63889.7, 0.82], [63947.9, 0.151], [64450.7, 2.75], [64573.0, 0.009], [64589.2, 1.059]], "asks": [[64593.9, 9.302], [64603.5, 0.065], [64607.5, 0.012], [64733.1, 7.499], [65239.8, 0.075], [65885.7, 0.031]]}
{"kind": "depth", "E": 1787088308891, "U": 11315917072635, "u": 11315917077874, "recv_ms": 1787088308831, "bids": [[1000.0, 35.76], [14093.8, 2.996], [14493.8, 1.204], [58134.4, 0.002], [61355.9, 0.005], [62010.0, 1.629], [63593.8, 0.028], [63759.5, 0.0], [63786.4, 2.271], [63876.2, 0.782], [63947.8, 0.012], [63947.9, 0.151], [64270.8, 2.518], [64569.7, 0.002], [64580.9, 0.004], [64581.5, 0.927], [64582.1, 0.36], [64582.6, 0.0], [64589.2, 1.059], [64593.8, 17.588]], "asks": [[64595.6, 0.087], [64603.5, 0.073], [64607.5, 0.004], [64613.0, 0.556], [64613.5, 0.014], [64614.1, 0.077], [64614.2, 0.096], [64615.0, 0.943], [64616.9, 1.237], [64617.9, 0.56], [64621.9, 0.322], [64625.1, 10.689], [64916.9, 2.461], [65239.8, 0.075], [65324.4, 2.011], [65593.9, 0.02], [65683.0, 15.372]]}
{"kind": "depth", "E": 1787088308993, "U": 11315917078012, "u": 11315917082725, "recv_ms": 1787088308930, "bids": [[14093.8, 2.632], [14493.8, 1.568], [58134.4, 0.002], [61364.1, 0.006], [63522.3, 0.0], [63771.0, 5.483], [63947.9, 0.151], [64251.8, 0.002], [64252.5, 0.493], [64270.8, 2.518], [64568.6, 0.723], [64575.9, 2.175], [64576.0, 0.01], [64576.8, 0.558], [64586.3, 0.005], [64586.9, 0.509], [64589.1, 1.643], [64589.2, 1.059], [64593.8, 17.588]], "asks": [[64593.9, 9.298], [64594.3, 0.002], [64595.2, 0.012], [64595.6, 0.003], [64597.0, 0.003], [64602.0, 0.171], [64613.2, 0.628], [64617.1, 0.557], [64617.9, 0.003], [64620.5, 0.687], [64621.6, 0.002], [64622.0, 0.312], [64656.0, 0.009], [64697.1, 3.011], [64716.6, 0.006], [65239.8, 0.075], [65527.6, 4.115], [66130.7, 0.001]]}
{"kind": "depth", "E": 1787088309095, "U": 11315917082791, "u": 11315917088252, "recv_ms": 1787088309032, "bids": [[1000.0, 35.76], [14093.8, 2.282], [14493.8, 1.918], [58134.4, 0.002], [61364.1, 0.006], [62010.0, 1.626], [63577.2, 11.314], [63593.8, 0.008], [63856.6, 0.0], [63947.9, 0.151], [64270.8, 2.519], [64433.8, 0.003], [64435.1, 0.942], [64450.7, 0.018], [64514.8, 0.105], [64554.5, 3.878], [64562.0, 0.005], [64582.2, 0.003], [64589.0, 0.503], [64589.2, 0.041], [64593.8, 17.601]], "asks": [[64733.1, 2.092], [64750.1, 0.003], [64916.9, 2.462], [65239.8, 0.075], [65593.9, 0.0], [65692.0, 6.612]]}
{"kind": "depth", "E": 1787088309197, "U": 11315917088345, "u": 11315917093063, "recv_ms": 1787088309135, "bids": [[1000.0, 35.76], [14093.8, 1.918], [14493.8, 2.282], [51675.0, 0.0], [58134.4, 0.002], [62010.0, 1.629], [63537.7, 4.249], [63786.4, 3.054], [64589.2, 0.041], [64593.8, 17.623]], "asks": [[65239.8, 0.075], [65543.4, 2.437]]}
{"kind": "depth", "E": 1787088309299, "U": 11315917093097, "u": 11315917100438, "recv_ms": 1787088309237, "bids": [[14093.8, 1.568], [14493.8, 2.632], [58134.4, 0.002], [61364.1, 0.008], [62010.0, 1.626], [63577.2, 10.215], [63593.8, 0.028], [63676.6, 0.235], [63947.9, 0.151], [64270.8, 2.519], [64394.8, 0.09], [64396.8, 0.668], [64403.2, 0.234], [64568.6, 0.104], [64575.9, 1.556], [64585.7, 0.001], [64587.7, 0.101], [64589.0, 0.426], [64589.2, 0.041], [64593.8, 17.622]], "asks": [[64594.1, 0.001], [64594.2, 0.016], [64595.3, 0.016], [64601.4, 0.006], [64602.8, 0.002], [64604.2, 0.816], [64613.2, 0.009], [64620.5, 0.068], [64624.7, 2.007], [64639.3, 0.175], [64639.4, 0.005], [64656.0, 0.009], [64788.8, 0.0], [65101.8, 6.21], [65239.8, 0.075], [65583.7, 0.0], [65593.9, 0.02]]}
{"kind": "depth", "E": 1787088309503, "U": 11315917105171, "u": 11315917111638, "recv_ms": 1787088309440, "bids": [[1000.0, 35.76], [14093.8, 0.854], [14493.8, 3.346], [45212.4, 0.0], [45212.5, 0.003], [58134.4, 0.002], [62010.0, 2.319], [63592.6, 2.197], [63593.8, 0.008], [63843.9, 1.574], [63947.9, 0.153], [64262.1, 2.882], [64395.1, 6.618], [64433.8, 4.109], [64450.8, 2.891], [64531.2, 3.724], [64552.2, 0.007], [64562.0, 0.001], [64589.2, 0.041], [64593.8, 17.622]], "asks": [[64656.7, 1.735], [64908.0, 2.463], [65239.8, 0.075], [65593.9, 0.0], [65679.6, 0.379]]}
{"kind": "depth", "E": 1787088309605, "U": 11315917111672, "u": 11315917116762, "recv_ms": 1787088309543, "bids": [[14093.8, 0.504], [14493.8, 3.696], [51675.0, 0.0], [58134.4, 0.002], [62010.0, 2.316], [63302.0, 0.021], [63689.5, 2.545], [63947.9, 0.151], [64270.8, 2.519], [64411.5, 0.001], [64419.5, 2.98], [64543.7, 0.001], [64552.6, 2.98], [64587.7, 0.098], [64589.2, 1.059]], "asks": [[64595.6, 0.087], [64608.9, 0.628], [64611.5, 0.0], [64623.9, 0.006], [64632.8, 3.939], [64691.4, 0.0], [64759.0, 0.001], [64764.6, 3.939], [65239.8, 0.075], [65357.0, 6.218], [65360.1, 66.451], [65553.9, 29.925], [65562.8, 2.243]]}
{"kind": "depth", "E": 1787088309707, "U": 11315917117084, "u": 11315917122155, "recv_ms": 1787088309645, "bids": [[1000.0, 35.76], [14093.8, 0.308], [14393.8, 0.168], [14493.8, 3.724], [58134.4, 0.002], [61364.1, 0.008], [62010.0, 2.319], [63593.8, 0.028], [63947.9, 0.151], [64270.8, 2.674], [64447.5, 0.013], [64450.8, 2.891], [64501.1, 0.0], [64516.3, 6.993], [64517.2, 2.302], [64553.3, 1.096], [64575.0, 0.002], [64575.6, 0.116], [64576.6, 0.016], [64579.5, 0.012], [64580.1, 0.804], [64589.2, 1.059], [64593.3, 0.182], [64593.8, 17.623]], "asks": [[64617.1, 0.0], [64617.9, 0.56], [64618.8, 0.001], [64619.3, 0.189], [64620.9, 0.004], [64663.7, 0.009], [64664.5, 29.86], [64666.3, 0.126], [64666.8, 0.0], [64685.0, 0.0], [64685.1, 0.014], [64691.3, 0.209], [64694.7, 2.656], [64733.1, 7.499], [64758.9, 0.006], [64762.8, 1.787], [64916.9, 2.616], [65239.8, 0.075], [65311.5, 3.06], [65369.0, 15.331], [65593.9, 0.02]]}
{"kind": "depth", "E": 1787088309809, "U": 11315917122235, "u": 11315917127677, "recv_ms": 1787088309748, "bids": [[14093.8, 0.182], [14393.8, 0.406], [14493.8, 3.612], [58134.4, 0.002], [61364.1, 0.008], [62010.0, 2.316], [63405.3, 0.003], [63947.8, 0.011], [63947.9, 0.151], [64450.8, 2.891], [64470.3, 0.031], [64548.5, 0.003], [64561.5, 2.628], [64589.2, 1.059], [64593.8, 17.539]], "asks": [[64595.3, 0.1], [64602.1, 0.019], [64622.8, 0.306], [64622.9, 0.589], [64623.0, 0.288], [64625.7, 0.002], [64625.8, 0.005], [64625.9, 0.163], [64626.7, 0.044], [64626.8, 0.0], [64626.9, 0.001], [64628.8, 0.451], [64628.9, 0.0], [64629.0, 0.007], [64652.1, 0.004], [64671.5, 0.071], [64733.1, 7.499], [65239.8, 0.075]]}
{"kind": "depth", "E": 1787088310013, "U": 11315917133227, "u": 11315917140583, "recv_ms": 1787088309951, "bids": [[1000.0, 35.76], [14093.8, 0.0], [14393.8, 0.924], [14493.8, 3.276], [58134.4, 0.002], [61364.1, 0.008], [63302.0, 0.018], [63593.8, 0.008], [63641.8, 13.18], [63816.4, 8.465], [63947.9, 0.151], [64401.6, 2.886], [64450.8, 0.004], [64476.7, 2.554], [64476.9, 6.189], [64520.9, 0.0], [64521.1, 0.31], [64566.4, 0.007], [64567.2, 0.057], [64567.6, 0.64], [64575.0, 0.621], [64578.3, 0.002], [64583.0, 0.697], [64587.8, 0.0], [64588.8, 0.022], [64589.2, 0.041], [64589.3, 0.633], [64589.4, 0.155], [64593.8, 17.539]], "asks": [[64607.8, 0.643], [64608.5, 0.016], [64612.2, 0.0], [64616.9, 1.794], [64617.9, 0.003], [64618.6, 0.161], [64619.5, 0.625], [64622.2, 0.008], [64628.6, 0.0], [64631.5, 0.196], [64663.1, 0.724], [64663.3, 0.048], [64664.5, 0.004], [64666.3, 4.594], [64666.7, 29.886], [64727.6, 0.89], [64728.9, 0.512], [64729.0, 3.885], [64733.1, 2.092], [65239.8, 0.075], [65392.4, 22.712], [65593.9, 0.0]]}
{"kind": "depth", "E": 1787088310217, "U": 11315917148363, "u": 11315917154590, "recv_ms": 1787088310157, "bids": [[14393.8, 1.638], [14493.8, 2.562], [58134.4, 0.002], [61364.1, 0.01], [62010.0, 2.319], [63593.8, 0.028], [63657.2, 1.099], [63825.1, 0.939], [63947.9, 0.151], [64270.8, 2.674], [64499.9, 0.158], [64520.3, 2.537], [64523.4, 0.013], [64564.6, 0.005], [64567.1, 0.072], [64567.2, 0.0], [64568.0, 0.147], [64575.6, 0.116], [64576.6, 0.016], [64581.5, 0.927], [64582.3, 0.002], [64585.4, 0.464], [64585.5, 0.008], [64585.6, 0.009], [64586.0, 1.174], [64586.2, 0.022], [64586.6, 0.451], [64586.8, 0.683], [64586.9, 0.2], [64587.7, 0.097], [64588.7, 0.116], [64588.8, 1.586], [64589.1, 0.637], [64589.2, 0.033], [64589.3, 0.083], [64589.4, 0.155], [64589.5, 0.009], [64589.6, 0.154], [64589.7, 0.0], [64590.5, 0.089], [64591.3, 0.003], [64591.6, 0.736], [64592.9, 0.085], [64593.8, 17.538]], "asks": [[64593.9, 9.872], [64594.4, 0.004], [64594.7, 0.084], [64599.5, 0.003], [64601.3, 0.0], [64612.0, 0.348], [64613.0, 0.014], [64613.3, 0.832], [64613.9, 0.926], [64614.1, 0.077], [64614.8, 0.125], [64616.9, 1.237], [64617.7, 0.618], [64618.8, 0.058], [64619.2, 1.188], [64619.7, 0.007], [64664.5, 0.004], [64666.7, 29.773], [65239.8, 0.075], [65489.3, 85.707], [65593.9, 0.02], [65699.2, 0.761]]}
{"kind": "depth", "E": 1787088310319, "U": 11315917154789, "u": 11315917160790, "recv_ms": 1787088310262, "bids": [[1000.0, 35.76], [14393.8, 2.002], [14493.8, 2.198], [51675.0, 0.0], [58134.4, 0.002], [62010.0, 2.316], [63302.0, 0.021], [63947.9, 0.151], [64068.3, 6.419], [64435.1, 1.47], [64455.8, 0.271], [64535.6, 0.003], [64581.1, 0.008], [64583.1, 0.148], [64586.2, 0.021], [64589.9, 0.001], [64593.8, 17.538]], "asks": [[64594.7, 0.0], [64594.8, 0.084], [64622.5, 2.29], [64671.5, 0.074], [65110.7, 4.448], [65239.8, 0.075], [65282.2, 4.815]]}
{"kind": "depth", "E": 1787088310421, "U": 11315917160974, "u": 11315917166323, "recv_ms": 1787088310360, "bids": [[14393.8, 2.352], [14493.8, 1.848], [51675.0, 0.0], [58134.4, 0.002], [63593.8, 0.008], [63947.9, 0.151], [64397.8, 0.001], [64399.9, 0.371], [64406.7, 4.043], [64577.0, 1.532], [64579.7, 0.006], [64581.4, 0.02], [64583.1, 0.147], [64588.8, 1.562], [64589.1, 0.637], [64589.2, 0.033], [64589.3, 0.107]], "asks": [[64594.9, 0.002], [64609.4, 0.003], [64610.1, 0.014], [64613.7, 0.051], [64771.9, 0.0], [64772.0, 0.093], [65239.8, 0.077], [65343.8, 1.528], [65593.9, 0.0], [65860.1, 1.3]]}
{"kind": "depth", "E": 1787088310523, "U": 11315917166365, "u": 11315917171999, "recv_ms": 1787088310460, "bids": [[14393.8, 2.716], [14493.8, 1.484], [58134.4, 0.002], [61364.1, 0.01], [62010.0, 2.319], [63680.8, 80.578], [63779.2, 0.787], [63947.9, 0.151], [64077.0, 4.255], [64270.8, 2.664], [64450.8, 0.004], [64574.2, 0.081], [64588.3, 0.0], [64588.7, 0.116], [64589.1, 0.637], [64589.2, 0.041], [64589.3, 0.099], [64593.3, 0.182], [64593.7, 0.141], [64593.8, 17.538]], "asks": [[64593.9, 9.862], [64594.8, 0.0], [64595.3, 0.016], [64733.1, 2.092], [65239.8, 0.075], [65298.0, 2.632], [65353.7, 6.42], [65475.9, 2.682], [65840.1, 0.0]]}
