{"kind": "depth", "E": 1787088310625, "U": 11315917172085, "u": 11315917178488, "recv_ms": 1787088310564, "bids": [[1000.0, 35.76], [14393.8, 3.08], [14493.8, 1.12], [51675.0, 0.0], [58134.4, 0.002], [62010.0, 2.316], [63593.8, 0.028], [63947.9, 0.151], [64077.0, 4.567], [64216.0, 0.03], [64216.1, 0.499], [64312.5, 0.048], [64313.0, 1.569], [64383.3, 0.003], [64383.4, 0.961], [64450.9, 2.949], [64564.6, 0.001], [64581.4, 0.019], [64581.5, 0.927], [64582.5, 0.332], [64583.6, 0.001], [64589.1, 0.909], [64589.2, 1.059]], "asks": [[64613.9, 0.0], [64614.9, 1.302], [64618.8, 0.001], [64619.8, 0.246], [64733.1, 7.499], [64778.2, 0.027], [64780.5, 0.001], [64780.6, 0.001], [64787.6, 7.495], [64851.3, 0.483], [64851.9, 0.04], [64949.0, 4.862], [64949.2, 0.008], [65239.8, 0.075], [65457.0, 19.743], [65469.9, 5.511], [65593.9, 0.02], [71053.3, 0.002]]}
{"kind": "depth", "E": 1787088310727, "U": 11315917178591, "u": 11315917184158, "recv_ms": 1787088310663, "bids": [[14393.8, 3.43], [14493.8, 0.77], [58134.4, 0.002], [61364.1, 0.008], [61364.2, 0.024], [62010.0, 2.319], [63727.0, 0.027], [63947.9, 0.151], [64450.9, 0.012], [64524.0, 0.11], [64554.5, 3.882], [64581.9, 0.001], [64583.6, 0.0], [64589.1, 0.909], [64589.2, 1.059], [64593.7, 0.141], [64593.8, 17.538]], "asks": [[64595.3, 0.016], [64616.5, 0.019], [64733.1, 2.092], [64787.6, 7.279], [64803.7, 7.994], [65239.8, 0.075], [65362.6, 2.764], [65491.8, 0.915], [65885.7, 0.034], [71053.3, 0.0]]}
{"kind": "depth", "E": 1787088310829, "U": 11315917184436, "u": 11315917190714, "recv_ms": 1787088310766, "bids": [[1000.0, 35.91], [14293.8, 0.028], [14393.8, 3.724], [14493.8, 0.448], [51675.0, 0.0], [58134.4, 0.002], [62010.0, 2.316], [63593.8, 0.008], [63876.5, 0.852], [63947.9, 0.151], [63953.0, 0.0], [64100.4, 0.067], [64270.8, 2.674], [64433.8, 0.003], [64433.9, 4.163], [64435.1, 0.942], [64450.9, 2.931], [64576.1, 0.561], [64576.8, 0.001], [64580.9, 0.931], [64581.0, 0.562], [64581.5, 0.0], [64581.6, 0.0], [64583.0, 0.155], [64589.1, 0.637], [64589.2, 1.059], [64593.7, 0.057]], "asks": [[64613.3, 1.758], [64614.9, 0.376], [64616.2, 0.584], [64617.7, 0.061], [64733.1, 7.499], [64750.1, 10.428], [65066.7, 0.0], [65224.2, 2.296], [65239.8, 0.075], [65465.9, 2.665], [65478.8, 1.855], [65593.9, 0.0], [65618.5, 11.345], [66150.8, 0.647]]}
{"kind": "depth", "E": 1787088310931, "U": 11315917190819, "u": 11315917195673, "recv_ms": 1787088310869, "bids": [[1000.0, 35.76], [14293.8, 0.224], [14393.8, 3.696], [14493.8, 0.28], [58134.4, 0.002], [61364.1, 0.006], [61364.2, 0.026], [62970.4, 8.015], [63816.4, 7.526], [63947.9, 0.151], [64227.6, 44.478], [64253.0, 0.001], [64253.4, 1.753], [64324.1, 33.949], [64325.2, 6.085], [64395.0, 27.988], [64519.2, 0.0], [64524.0, 0.128], [64524.1, 0.013], [64580.1, 0.805], [64581.0, 0.02], [64581.9, 0.0], [64583.0, 0.697], [64587.3, 0.173], [64589.2, 0.041], [64593.7, 0.057]], "asks": [[64593.9, 9.873], [64594.9, 0.0], [64602.7, 0.002], [64613.3, 0.832], [64614.2, 1.022], [64616.2, 0.027], [64617.1, 0.557], [64790.8, 5.261], [64791.0, 26.332], [64861.7, 5.339], [64862.2, 32.962], [64956.9, 7.968], [64959.5, 41.386], [65239.8, 0.075], [65421.5, 0.386]]}
{"kind": "depth", "E": 1787088311033, "U": 11315917195732, "u": 11315917201210, "recv_ms": 1787088310977, "bids": [[14293.8, 0.462], [14393.8, 3.584], [14493.8, 0.154], [58134.4, 0.002], [61364.1, 0.008], [62010.0, 2.319], [63302.0, 0.018], [63593.8, 0.028], [63620.2, 0.391], [63947.9, 0.151], [64100.1, 4.342], [64100.5, 0.002], [64433.9, 0.0], [64434.0, 4.163], [64450.9, 3.222], [64554.5, 3.878], [64562.0, 0.005], [64567.6, 0.64], [64574.9, 0.625], [64580.9, 0.004], [64581.5, 0.927], [64582.2, 0.008], [64593.8, 17.482]], "asks": [[64595.3, 0.016], [64600.1, 0.007], [64612.2, 0.0], [64615.3, 0.21], [64616.8, 0.002], [64619.5, 0.625], [64699.3, 0.0], [64733.1, 7.499], [64750.1, 10.428], [64790.9, 2.346], [64803.7, 7.778], [65076.5, 52.944], [65200.0, 143.919], [65239.8, 0.075], [65593.9, 0.02], [65627.4, 5.324]]}
{"kind": "depth", "E": 1787088311135, "U": 11315917201222, "u": 11315917206631, "recv_ms": 1787088311073, "bids": [[1000.0, 35.76], [14293.8, 0.7], [14393.8, 3.458], [14493.8, 0.042], [50000.0, 233.333], [51675.0, 0.0], [58134.4, 0.002], [62010.0, 2.316], [63803.1, 4.699], [63947.9, 0.151], [64270.8, 2.664], [64535.6, 0.0], [64548.5, 0.003], [64580.1, 0.804], [64582.2, 0.003], [64587.0, 1.019], [64587.3, 0.174], [64589.2, 0.041]], "asks": [[64604.6, 0.155], [64623.4, 1.885], [64623.5, 0.003], [64652.1, 0.004], [64671.5, 0.071], [64916.9, 2.616], [65511.1, 0.457], [65699.1, 0.76]]}
{"kind": "depth", "E": 1787088311237, "U": 11315917206754, "u": 11315917211830, "recv_ms": 1787088311178, "bids": [[1000.0, 35.76], [14293.8, 1.008], [14393.8, 3.192], [14493.8, 0.0], [51675.0, 0.0], [58134.4, 0.002], [62010.0, 2.319], [62979.0, 0.121], [63566.7, 0.0], [63593.8, 0.008], [63825.1, 1.878], [63947.9, 0.151], [64499.9, 0.157], [64509.0, 1.334], [64554.5, 3.882], [64562.0, 0.001], [64587.0, 1.018], [64589.2, 0.041], [64589.4, 0.156], [64593.8, 17.481]], "asks": [[65239.8, 0.075], [65360.1, 65.993], [65593.9, 0.0]]}
{"kind": "depth", "E": 1787088311339, "U": 11315917211878, "u": 11315917217537, "recv_ms": 1787088311277, "bids": [[14293.8, 1.372], [14393.8, 2.828], [58134.4, 0.002], [61364.1, 0.008], [63947.9, 0.151], [64382.7, 7.237], [64409.1, 1.541], [64434.0, 3.249], [64435.1, 1.342], [64450.9, 2.74], [64476.9, 2.319], [64477.0, 4.242], [64487.7, 2.322], [64521.1, 0.264], [64521.2, 0.046], [64529.2, 0.087], [64583.6, 0.001], [64587.3, 0.177], [64589.1, 0.637], [64589.2, 0.041], [64589.4, 0.155], [64593.3, 0.098], [64593.5, 0.436], [64593.7, 0.068], [64593.8, 17.481]], "asks": [[64594.8, 0.0], [64621.2, 3.939], [64621.3, 10.0], [64622.5, 0.47], [64632.7, 0.002], [64650.7, 0.062], [64650.8, 0.014], [64653.4, 0.013], [64656.0, 0.009], [64658.5, 0.673], [64663.3, 0.002], [64663.4, 0.067], [64701.1, 0.646], [64701.2, 2.322], [64701.4, 0.009], [64727.6, 0.89], [64729.0, 0.015], [64729.1, 3.894], [64733.1, 7.499], [64750.1, 10.428], [64758.5, 0.734], [64778.0, 1.281], [65239.8, 0.075], [65282.2, 4.127], [65562.8, 2.624], [65885.7, 0.031], [66531.6, 0.003]]}
{"kind": "depth", "E": 1787088311543, "U": 11315917223668, "u": 11315917229126, "recv_ms": 1787088311481, "bids": [[1000.0, 35.76], [14293.8, 2.086], [14393.8, 2.114], [45212.5, 0.0], [58134.4, 0.002], [61364.1, 0.014], [62010.0, 2.319], [63424.5, 0.675], [63624.8, 0.021], [63947.9, 0.151], [64566.5, 0.353], [64567.1, 0.015], [64575.1, 0.138], [64575.6, 0.0], [64581.0, 0.02], [64581.1, 0.008], [64581.5, 0.927], [64581.6, 0.0], [64581.9, 0.0], [64583.0, 0.697], [64583.6, 0.0], [64584.1, 0.026], [64585.2, 0.158], [64589.2, 0.041], [64593.5, 0.352], [64593.8, 17.481]], "asks": [[64595.1, 0.086], [64603.4, 0.007], [64613.4, 1.461], [64614.2, 0.096], [64614.3, 0.928], [64617.8, 1.009], [64618.3, 0.013], [64618.8, 0.117], [64619.2, 1.245], [64619.3, 0.073], [64619.8, 0.189], [64624.7, 0.578], [64625.1, 0.689], [64630.1, 0.028], [64632.7, 0.016], [64639.0, 0.024], [64639.2, 0.611], [64639.3, 0.019], [64656.0, 0.051], [64760.5, 0.003], [64775.5, 0.021], [65239.8, 0.075], [65521.6, 48.81]]}
{"kind": "depth", "E": 1787088311645, "U": 11315917229412, "u": 11315917234569, "recv_ms": 1787088311582, "bids": [[14293.8, 2.436], [14393.8, 1.764], [51675.0, 0.002], [58134.4, 0.002], [61364.1, 0.015], [62010.0, 2.316], [63192.8, 0.0], [63195.3, 0.002], [63593.8, 0.008], [63947.9, 0.151], [63963.5, 68.159], [64111.0, 57.766], [64320.1, 0.0], [64328.9, 0.001], [64346.0, 5.019], [64351.3, 0.0], [64354.7, 0.001], [64371.8, 0.0], [64380.6, 0.003], [64397.7, 0.002], [64406.4, 0.002], [64423.5, 3.828], [64432.3, 0.027], [64450.9, 0.012], [64585.2, 0.157], [64590.5, 0.09], [64593.3, 0.182]], "asks": [[64593.9, 9.791], [64595.1, 0.002], [64619.5, 0.006], [64733.1, 2.092], [64755.4, 0.002], [64781.3, 0.001], [64807.1, 0.38], [64833.0, 0.372], [64858.8, 0.001], [65229.0, 66.573], [65239.8, 0.075], [65298.0, 3.319], [65360.1, 65.382], [65521.6, 47.743], [65530.5, 5.303], [65593.9, 0.0], [65650.8, 6.192], [71053.3, 0.0]]}
{"kind": "depth", "E": 1787088311747, "U": 11315917234791, "u": 11315917239603, "recv_ms": 1787088311684, "bids": [[1000.0, 35.76], [14293.8, 2.8], [14393.8, 1.4], [51675.0, 0.0], [58134.4, 0.002], [61364.1, 0.014], [62010.0, 2.319], [63302.0, 0.021], [63495.7, 0.628], [63593.8, 0.028], [63947.9, 0.151], [64100.1, 0.022], [64111.1, 4.631], [64270.8, 2.664], [64395.1, 0.001], [64434.0, 0.0], [64435.1, 0.942], [64554.5, 3.878], [64562.0, 0.005], [64588.2, 0.125], [64593.8, 17.477]], "asks": [[64593.9, 9.791], [64639.0, 0.209], [64750.1, 0.003], [64779.3, 0.0], [64779.4, 0.007], [64788.8, 0.0], [65239.8, 0.075], [65401.3, 4.431], [65498.2, 7.17], [65593.9, 0.02]]}
{"kind": "depth", "E": 1787088311951, "U": 11315917245863, "u": 11315917250984, "recv_ms": 1787088311888, "bids": [[14293.8, 3.514], [14393.8, 0.686], [58134.4, 0.002], [61364.1, 0.014], [62010.0, 2.316], [63302.0, 0.024], [63864.1, 0.0], [63947.9, 0.151], [64253.4, 1.261], [64253.5, 0.492], [64526.1, 0.001], [64531.0, 0.009], [64580.7, 0.0], [64582.9, 0.023], [64590.5, 0.089], [64593.8, 17.478]], "asks": [[64612.4, 0.0], [64612.6, 0.0], [64661.7, 0.055], [65239.8, 0.075], [65369.0, 16.4], [65530.5, 6.37], [65659.7, 1.066]]}
{"kind": "depth", "E": 1787088312053, "U": 11315917251237, "u": 11315917256776, "recv_ms": 1787088311990, "bids": [[1000.0, 35.76], [14193.8, 0.056], [14293.8, 3.752], [14393.8, 0.392], [58134.4, 0.002], [61364.1, 0.014], [62010.0, 2.319], [63593.8, 0.008], [63947.9, 0.151], [64270.8, 2.674], [64487.7, 2.322], [64566.5, 0.296], [64567.4, 0.057], [64581.0, 0.947], [64581.1, 0.55], [64581.5, 0.0], [64581.6, 0.0], [64582.2, 0.003], [64583.0, 0.155], [64583.1, 0.147], [64583.2, 0.0], [64593.7, 0.152], [64593.8, 17.478]], "asks": [[64604.0, 0.383], [64612.2, 0.0], [64613.3, 1.492], [64613.4, 1.461], [64614.3, 0.928], [64619.5, 0.625], [64701.2, 2.322], [65239.8, 0.075], [65593.9, 0.0], [65708.4, 4.864], [65724.3, 1.217], [65885.7, 0.028]]}
{"kind": "depth", "E": 1787088312155, "U": 11315917256800, "u": 11315917262551, "recv_ms": 1787088312093, "bids": [[1000.0, 35.76], [14193.8, 0.28], [14293.8, 3.668], [14393.8, 0.252], [51675.0, 0.05], [58134.4, 0.002], [62010.0, 2.316], [63816.4, 6.587], [63874.0, 0.234], [63947.9, 0.151], [64077.0, 4.567], [64270.8, 2.673], [64423.5, 3.825], [64509.1, 0.003], [64526.5, 0.007], [64535.6, 0.003], [64566.6, 0.066], [64567.4, 0.0], [64576.1, 0.004], [64577.1, 0.559], [64581.0, 0.02], [64581.1, 0.008], [64581.9, 0.927], [64582.0, 0.547], [64588.5, 0.708], [64588.7, 0.388], [64589.1, 0.909], [64589.2, 1.059], [64593.0, 0.008], [64593.6, 0.313], [64593.7, 0.068], [64593.8, 17.456]], "asks": [[64594.4, 0.004], [64594.5, 0.0], [64595.8, 0.024], [64613.4, 1.461], [64614.3, 0.928], [64671.5, 0.074], [64916.9, 2.615], [65239.8, 0.075], [65683.0, 14.993]]}
{"kind": "depth", "E": 1787088312257, "U": 11315917262650, "u": 11315917267577, "recv_ms": 1787088312194, "bids": [[14193.8, 0.504], [14293.8, 3.57], [14393.8, 0.126], [51675.0, 0.006], [58134.4, 0.002], [61364.1, 0.02], [62010.0, 2.319], [63593.8, 0.028], [63947.9, 0.153], [64270.8, 2.674], [64477.0, 4.242], [64521.2, 0.046], [64581.5, 0.927], [64581.6, 0.0], [64581.9, 0.0], [64582.0, 0.005], [64582.1, 0.36], [64582.2, 0.545], [64588.7, 0.116], [64589.1, 0.637], [64589.2, 1.059], [64589.3, 1.117], [64592.0, 0.947], [64593.6, 0.229], [64593.8, 17.456]], "asks": [[64595.3, 0.1], [64663.4, 0.067], [64729.1, 0.024], [64729.2, 3.882], [64916.9, 2.616], [65239.8, 0.075], [65593.9, 0.02], [65860.1, 1.95]]}
{"kind": "depth", "E": 1787088312359, "U": 11315917267584, "u": 11315917276973, "recv_ms": 1787088312297, "bids": [[1000.0, 35.76], [14193.8, 0.756], [14293.8, 3.43], [14393.8, 0.014], [51675.0, 0.0], [58134.4, 0.002], [63302.0, 0.021], [63689.5, 2.733], [63738.7, 10.495], [63825.1, 2.817], [63867.7, 4.848], [63947.9, 0.151], [64230.1, 7.984], [64270.8, 2.674], [64396.8, 5.834], [64435.1, 1.342], [64496.9, 0.003], [64516.2, 0.0], [64535.6, 0.0], [64535.8, 0.005], [64536.1, 0.038], [64536.4, 0.003], [64536.7, 0.093], [64537.1, 0.018], [64548.4, 0.011], [64548.5, 0.0], [64553.1, 0.004], [64553.4, 0.0], [64553.7, 0.001], [64554.1, 0.005], [64554.4, 2.321], [64568.0, 0.007], [64568.1, 0.005], [64568.2, 0.001], [64568.3, 0.0], [64568.5, 1.01], [64568.6, 0.034], [64568.7, 0.111], [64568.8, 0.015], [64568.9, 0.09], [64569.6, 0.008], [64570.0, 0.004], [64578.5, 0.007], [64581.6, 0.542], [64582.2, 0.003], [64582.3, 0.002], [64582.4, 0.009], [64585.5, 0.008], [64586.5, 0.013], [64586.6, 0.311], [64586.7, 0.0], [64586.8, 0.513], [64586.9, 0.0], [64587.0, 0.918], [64587.1, 0.001], [64587.2, 0.003], [64587.3, 0.107], [64587.4, 0.002], [64587.7, 0.065], [64588.0, 0.003], [64588.4, 0.0], [64588.7, 0.084], [64588.8, 0.022], [64589.0, 0.394], [64589.1, 0.018], [64589.2, 0.025], [64589.3, 0.075], [64589.4, 0.155], [64589.5, 0.086], [64589.6, 0.17], [64589.7, 0.008], [64589.8, 2.113], [64591.6, 0.503], [64592.4, 0.008], [64593.8, 17.455]], "asks": [[64602.2, 0.013], [64602.6, 0.016], [64602.9, 0.376], [64603.2, 0.042], [64603.5, 0.019], [64603.8, 0.094], [64603.9, 0.486], [64604.0, 0.007], [64604.1, 0.0], [64604.2, 0.507], [64604.3, 1.0], [64604.4, 0.315], [64604.5, 0.003], [64604.6, 0.001], [64604.7, 0.002], [64604.8, 0.009], [64619.6, 0.002], [64619.9, 0.0], [64620.2, 0.444], [64620.5, 0.01], [64620.8, 0.011], [64621.2, 3.719], [64621.7, 0.001], [64622.3, 0.168], [64622.4, 0.258], [64622.5, 0.094], [64622.6, 0.045], [64622.7, 3.442], [64622.8, 0.078], [64622.9, 0.331], [64623.0, 0.017], [64623.1, 0.062], [64623.2, 0.007], [64623.3, 2.332], [64631.1, 3.435], [64636.9, 0.05], [64637.2, 0.0], [64637.5, 1.16], [64637.8, 0.002], [64638.2, 0.036], [64652.1, 0.001], [64671.5, 0.074], [64772.2, 1.43], [65239.8, 0.075], [65489.3, 85.524]]}
{"kind": "depth", "E": 1787088312461, "U": 11315917277863, "u": 11315917289496, "recv_ms": 1787088312400, "bids": [[1000.0, 35.76], [14193.8, 1.106], [14293.8, 3.094], [14393.8, 0.0], [58134.4, 0.002], [62010.0, 2.316], [63487.1, 21.016], [63593.8, 0.008], [63746.9, 0.783], [63947.9, 0.151], [64553.2, 1.234], [64554.1, 0.037], [64562.0, 0.005], [64577.0, 1.532], [64585.5, 0.008], [64586.2, 0.021], [64586.3, 0.005], [64586.5, 0.013], [64586.7, 0.07], [64587.0, 1.042], [64587.5, 0.38], [64587.8, 0.032], [64588.2, 0.001], [64588.6, 1.11], [64588.7, 0.115], [64588.8, 1.594], [64589.1, 0.653], [64589.2, 0.018], [64589.5, 0.009], [64589.6, 0.154], [64589.7, 0.0], [64589.8, 0.016], [64591.6, 0.481], [64592.4, 0.007]], "asks": [[64602.4, 0.05], [64603.3, 0.069], [64603.5, 0.011], [64603.6, 2.502], [64604.4, 0.407], [64607.0, 0.01], [64607.8, 0.705], [64607.9, 1.677], [64609.4, 0.003], [64619.7, 0.055], [64620.7, 0.055], [64622.1, 0.457], [64622.9, 0.485], [64637.0, 0.055], [64638.0, 0.068], [64662.9, 5.279], [64664.5, 29.727], [64666.3, 0.117], [64666.7, 0.03], [65239.8, 0.075], [65593.9, 0.0], [65692.0, 6.991]]}
{"kind": "depth", "E": 1787088312563, "U": 11315917289579, "u": 11315917308177, "recv_ms": 1787088312538, "bids": [[14193.8, 1.456], [14293.8, 2.744], [58134.4, 0.002], [61364.1, 0.018], [61364.2, 0.028], [62010.0, 2.319], [63302.0, 0.018], [63593.8, 0.028], [63754.1, 1.136], [63947.9, 0.153], [64068.3, 6.108], [64488.7, 0.0], [64488.8, 0.006], [64509.8, 1.376], [64517.4, 0.062], [64524.0, 0.11], [64533.4, 0.055], [64534.5, 0.08], [64535.5, 0.627], [64536.3, 0.025], [64537.1, 0.004], [64537.5, 0.002], [64540.7, 0.442], [64544.0, 0.016], [64544.3, 0.036], [64545.7, 0.0], [64547.2, 0.076], [64547.3, 0.005], [64550.4, 0.014], [64550.8, 0.0], [64551.1, 0.002], [64552.8, 0.069], [64553.5, 0.032], [64554.5, 0.035], [64554.7, 1.378], [64555.1, 1.224], [64555.6, 0.97], [64556.3, 0.022], [64556.9, 0.001], [64558.2, 0.018], [64558.3, 0.053], [64561.0, 4.872], [64561.6, 0.047], [64562.3, 0.009], [64562.4, 0.003], [64563.2, 0.017], [64563.9, 0.314], [64564.1, 2.38], [64564.3, 0.001], [64564.7, 0.007], [64564.8, 0.034], [64566.6, 0.009], [64566.7, 0.014], [64566.8, 0.058], [64567.6, 0.002], [64567.9, 0.001], [64568.0, 0.053], [64568.4, 0.313], [64568.9, 0.105], [64569.1, 0.007], [64569.8, 0.011], [64569.9, 0.005], [64570.1, 0.057], [64571.8, 0.104], [64572.0, 0.429], [64572.1, 1.169], [64572.7, 0.083], [64572.8, 0.008], [64573.1, 2.321], [64573.5, 0.0], [64573.7, 0.0], [64573.8, 0.007], [64573.9, 0.002], [64574.1, 5.037], [64574.9, 0.006], [64575.1, 0.022], [64575.7, 0.002], [64576.1, 0.002], [64576.5, 0.061], [64576.8, 0.02], [64577.0, 0.632], [64577.1, 0.002], [64577.2, 1.273], [64577.6, 0.115], [64578.2, 0.12], [64578.7, 1.292], [64579.3, 0.001], [64579.4, 0.001], [64579.5, 0.005], [64579.6, 0.557], [64580.1, 0.803], [64580.2, 0.0], [64580.3, 0.003], [64580.4, 0.005], [64581.5, 0.0], [64581.6, 0.0], [64581.8, 0.015], [64582.1, 0.357], [64582.2, 0.01], [64582.9, 0.024], [64583.0, 0.001], [64583.2, 0.007], [64583.8, 0.001], [64584.5, 0.0], [64584.7, 0.086], [64584.9, 1.238], [64585.2, 0.156], [64585.4, 1.016], [64585.5, 0.024], [64586.1, 0.16], [64586.2, 0.647], [64586.5, 0.021], [64586.6, 0.002], [64586.7, 0.07], [64586.8, 0.36], [64587.0, 0.918], [64587.1, 0.171], [64587.4, 0.107], [64587.5, 0.381], [64588.0, 0.903], [64588.1, 2.353], [64588.5, 0.108], [64588.7, 0.268], [64588.8, 0.048], [64588.9, 0.157], [64589.0, 0.361], [64589.1, 0.205], [64589.2, 1.606], [64589.3, 0.107], [64589.4, 0.158], [64589.5, 0.017], [64589.6, 0.154], [64589.7, 0.004], [64589.8, 0.015], [64589.9, 0.001], [64590.0, 0.01], [64590.1, 0.087], [64590.2, 0.061], [64590.4, 0.311], [64590.5, 0.089], [64591.1, 0.001], [64591.2, 0.0], [64591.6, 0.081], [64591.7, 1.915], [64591.8, 0.835], [64592.0, 0.905], [64592.1, 0.128], [64592.6, 0.156], [64592.7, 0.006], [64592.8, 0.31], [64593.6, 0.356], [64593.8, 32.408]], "asks": [[64593.9, 2.412], [64594.0, 0.001], [64594.4, 0.001], [64595.2, 0.007], [64595.3, 0.016], [64595.6, 0.003], [64595.8, 0.002], [64596.2, 0.001], [64596.7, 0.001], [64597.0, 0.002], [64597.1, 0.002], [64597.3, 0.001], [64597.5, 0.005], [64597.7, 0.001], [64597.8, 0.071], [64597.9, 0.64], [64598.3, 0.001], [64598.4, 0.008], [64598.5, 0.0], [64598.7, 0.003], [64599.3, 0.0], [64599.5, 0.087], [64599.7, 0.009], [64599.8, 1.795], [64599.9, 0.849], [64600.1, 0.008], [64600.2, 0.086], [64600.6, 0.086], [64601.0, 0.087], [64601.1, 0.311], [64601.3, 0.084], [64601.4, 0.003], [64601.6, 0.019], [64601.7, 0.084], [64601.9, 0.675], [64602.0, 0.047], [64602.1, 0.067], [64602.5, 0.055], [64602.7, 0.069], [64602.8, 0.043], [64603.0, 0.068], [64603.1, 0.0], [64603.2, 0.005], [64603.4, 0.007], [64603.5, 0.375], [64603.6, 0.152], [64603.8, 0.001], [64604.0, 0.126], [64604.1, 0.19], [64604.3, 1.133], [64604.5, 0.004], [64604.6, 0.0], [64604.8, 0.009], [64605.0, 0.033], [64605.1, 1.321], [64605.2, 0.001], [64605.4, 0.0], [64605.5, 0.297], [64605.8, 0.094], [64605.9, 0.112], [64606.0, 0.003], [64606.1, 2.342], [64606.3, 0.023], [64606.8, 0.086], [64607.0, 0.002], [64607.6, 0.001], [64607.7, 0.04], [64607.8, 0.62], [64607.9, 1.62], [64608.0, 0.913], [64608.6, 1.353], [64608.7, 2.577], [64608.8, 0.522], [64608.9, 0.002], [64609.0, 0.001], [64609.1, 0.185], [64609.2, 0.0], [64609.6, 0.001], [64610.0, 0.006], [64611.4, 0.01], [64611.5, 0.093], [64611.8, 6.043], [64611.9, 0.002], [64612.0, 0.341], [64612.4, 0.007], [64612.7, 0.002], [64613.3, 0.826], [64613.4, 1.541], [64613.8, 0.167], [64614.2, 0.003], [64614.3, 0.002], [64614.8, 0.042], [64615.1, 0.004], [64615.2, 1.163], [64615.3, 0.208], [64615.6, 0.0], [64615.7, 2.957], [64615.8, 0.025], [64616.2, 0.008], [64616.3, 0.019], [64616.4, 0.071], [64616.8, 0.544], [64616.9, 1.237], [64617.1, 0.0], [64617.4, 0.002], [64617.6, 1.057], [64617.7, 0.987], [64618.1, 0.605], [64618.2, 0.377], [64618.5, 0.619], [64618.6, 0.166], [64618.8, 0.001], [64619.1, 0.017], [64619.2, 1.188], [64619.3, 0.157], [64619.4, 0.052], [64619.5, 0.006], [64620.0, 0.232], [64620.3, 0.1], [64620.4, 0.002], [64620.6, 0.565], [64620.8, 0.011], [64620.9, 0.002], [64621.0, 0.019], [64621.2, 0.005], [64621.3, 0.0], [64621.4, 0.164], [64621.8, 0.261], [64622.0, 0.001], [64622.2, 0.116], [64622.4, 0.252], [64622.5, 0.403], [64622.7, 3.501], [64622.8, 0.211], [64623.0, 0.017], [64623.2, 0.013], [64623.3, 2.339], [64623.4, 0.08], [64623.9, 0.006], [64624.4, 0.66], [64625.7, 0.013], [64625.8, 0.316], [64626.7, 0.064], [64627.4, 0.104], [64627.5, 0.025], [64628.1, 0.038], [64628.2, 0.154], [64628.6, 0.002], [64629.2, 0.005], [64630.0, 0.025], [64630.5, 0.719], [64630.6, 0.001], [64631.0, 0.249], [64631.3, 0.064], [64631.5, 0.042], [64631.8, 0.015], [64632.2, 10.0], [64632.4, 0.0], [64634.4, 0.009], [64634.8, 0.154], [64635.0, 0.004], [64635.3, 0.03], [64635.4, 0.018], [64636.1, 0.01], [64636.4, 0.04], [64636.5, 0.022], [64636.7, 0.049], [64637.3, 0.069], [64637.7, 0.066], [64638.2, 0.006], [64638.6, 0.024], [64639.0, 0.209], [64639.1, 0.446], [64639.3, 0.0], [64639.6, 0.0], [64640.1, 0.254], [64641.5, 0.0], [64642.3, 0.0], [64643.8, 0.282], [64644.0, 3.563], [64649.3, 0.003], [64649.4, 0.021], [64649.6, 0.079], [64654.7, 0.028], [64657.6, 0.03], [64660.9, 0.031], [64662.9, 0.787], [64664.5, 0.004], [64666.7, 0.03], [64670.9, 0.0], [64671.0, 0.013], [64671.4, 0.1], [64684.8, 0.95], [64686.5, 29.798], [64688.7, 0.001], [64692.1, 0.0], [64692.2, 0.013], [64695.3, 0.0], [64706.2, 0.001], [64706.3, 0.014], [64711.5, 0.003], [64712.0, 0.121], [64714.1, 0.0], [64720.3, 0.0], [64720.4, 0.013], [64757.9, 0.0], [64771.9, 0.069], [65231.0, 13.678], [65239.8, 0.075], [65337.1, 13.637], [65337.4, 0.918], [65593.9, 0.02], [65618.5, 9.215]]}
{"kind": "depth", "E": 1787088312665, "U": 11315917308292, "u": 11315917319440, "recv_ms": 1787088312602, "bids": [[1000.0, 35.76], [14193.8, 1.806], [14293.8, 2.394], [51675.0, 0.0], [58134.4, 0.002], [61355.9, 0.003], [61364.1, 0.018], [62010.0, 2.316], [63495.7, 5.346], [63551.6, 12.966], [63648.5, 49.086], [63947.9, 0.151], [64077.0, 4.878], [64270.8, 2.674], [64452.0, 0.101], [64454.4, 0.007], [64463.3, 4.699], [64466.1, 0.038], [64478.4, 0.0], [64491.5, 0.589], [64539.1, 0.0], [64546.5, 0.001], [64549.7, 0.024], [64557.3, 0.003], [64561.5, 2.624], [64571.2, 0.102], [64573.3, 0.005], [64581.0, 0.1], [64582.9, 0.023], [64583.2, 0.007], [64583.3, 0.04], [64583.8, 0.021], [64584.7, 0.066], [64588.8, 0.118], [64589.1, 0.275], [64589.3, 0.307], [64589.5, 0.117], [64589.6, 0.224], [64589.7, 0.1], [64589.8, 0.019], [64591.6, 0.081], [64592.1, 0.133], [64593.8, 32.413]], "asks": [[64593.9, 2.412], [64598.4, 0.009], [64598.7, 0.087], [64599.1, 1.972], [64599.9, 0.187], [64601.6, 0.02], [64603.6, 0.151], [64603.7, 0.22], [64603.8, 0.127], [64603.9, 0.726], [64604.0, 0.126], [64604.1, 0.42], [64604.2, 0.768], [64604.4, 0.547], [64604.5, 0.003], [64604.6, 0.133], [64604.7, 0.002], [64605.2, 0.001], [64606.0, 0.006], [64607.8, 0.078], [64608.0, 0.013], [64608.5, 0.558], [64608.7, 2.614], [64609.3, 0.0], [64611.0, 2.203], [64613.8, 0.163], [64614.3, 0.057], [64621.0, 0.239], [64621.4, 0.01], [64621.5, 0.652], [64622.3, 0.294], [64622.4, 0.492], [64622.6, 0.358], [64622.8, 0.351], [64623.1, 0.195], [64626.1, 1.908], [64627.5, 0.013], [64632.8, 3.943], [64633.1, 0.017], [64646.2, 0.014], [64648.6, 1.878], [64654.0, 0.248], [64666.7, 29.828], [64686.5, 0.0], [64704.1, 1.094], [64706.3, 0.014], [64779.6, 0.0], [64796.8, 0.976], [65239.8, 0.075], [65521.6, 45.609], [65528.0, 2.162], [65586.2, 32.943]]}
{"kind": "depth", "E": 1787088312869, "U": 11315917329676, "u": 11315917341487, "recv_ms": 1787088312809, "bids": [[14193.8, 2.534], [14293.8, 1.666], [58134.4, 0.002], [61364.1, 0.018], [62010.0, 2.319], [63302.0, 0.021], [63586.0, 0.674], [63593.8, 0.008], [63947.9, 0.151], [64270.8, 2.664], [64463.7, 0.063], [64536.2, 0.033], [64537.2, 0.032], [64537.4, 0.032], [64561.0, 4.874], [64561.1, 0.044], [64561.2, 0.002], [64564.4, 0.027], [64564.5, 0.057], [64564.6, 0.003], [64565.8, 0.152], [64568.2, 0.071], [64568.7, 0.181], [64569.0, 0.078], [64569.2, 0.117], [64570.1, 0.0], [64577.9, 0.116], [64578.7, 1.733], [64579.3, 0.001], [64579.6, 0.0], [64579.8, 0.002], [64580.4, 0.003], [64581.8, 0.015], [64583.5, 0.928], [64584.9, 0.311], [64585.6, 0.017], [64586.5, 0.013], [64589.2, 1.71], [64589.5, 0.117], [64591.6, 0.08], [64591.9, 0.597], [64592.2, 0.005], [64592.6, 0.002], [64592.7, 0.001], [64593.8, 32.414]], "asks": [[64597.7, 0.063], [64597.8, 1.897], [64598.7, 0.003], [64599.0, 0.014], [64599.1, 1.888], [64599.5, 0.087], [64599.8, 1.879], [64599.9, 0.103], [64600.2, 0.086], [64600.3, 0.0], [64600.6, 0.086], [64601.0, 0.087], [64601.1, 0.311], [64601.9, 0.912], [64602.0, 0.017], [64602.1, 0.151], [64602.4, 0.134], [64602.5, 0.055], [64602.8, 0.156], [64603.0, 0.069], [64603.2, 0.005], [64603.4, 0.007], [64603.5, 0.375], [64603.9, 0.726], [64604.1, 0.862], [64604.2, 0.585], [64606.8, 0.015], [64608.5, 0.024], [64609.5, 0.019], [64610.8, 0.455], [64610.9, 0.654], [64612.4, 0.0], [64613.0, 0.914], [64614.8, 0.002], [64615.1, 0.546], [64615.9, 0.0], [64616.7, 0.926], [64616.8, 0.002], [64617.7, 0.061], [64618.8, 0.003], [64618.9, 0.046], [64619.3, 0.155], [64620.3, 0.109], [64621.5, 0.652], [64621.6, 0.002], [64632.7, 0.087], [64644.2, 6.969], [64676.1, 0.003], [64712.0, 0.005], [64714.5, 1.301], [65239.8, 0.228], [65530.5, 7.437], [65537.0, 1.22], [65586.2, 31.878], [65593.9, 0.0], [65595.1, 1.066], [65627.4, 7.454]]}
{"kind": "depth", "E": 1787088312971, "U": 11315917341627, "u": 11315917350838, "recv_ms": 1787088312909, "bids": [[1000.0, 35.76], [14193.8, 2.884], [14293.8, 1.316], [58134.4, 0.002], [61364.1, 0.018], [62010.0, 2.316], [63302.0, 0.024], [63560.3, 1.1], [63657.2, 2.197], [63947.9, 0.151], [64253.5, 0.0], [64253.6, 0.492], [64568.6, 0.134], [64570.6, 0.075], [64579.8, 0.0], [64580.5, 0.002], [64581.8, 0.016], [64585.3, 6.33], [64585.6, 0.009], [64586.5, 0.013], [64586.6, 0.01], [64589.2, 1.706], [64591.6, 0.081], [64591.7, 1.914]], "asks": [[64593.9, 3.0], [64598.7, 0.087], [64599.0, 0.009], [64599.1, 1.972], [64599.7, 0.009], [64602.0, 0.018], [64602.4, 0.05], [64602.5, 0.056], [64602.8, 0.072], [64603.0, 0.068], [64603.5, 0.378], [64606.0, 0.003], [64608.5, 0.016], [64610.7, 0.009], [64610.8, 0.448], [64611.5, 0.1], [64612.0, 1.241], [64613.0, 0.014], [64618.8, 0.001], [64619.4, 0.052], [64619.5, 0.008], [64621.5, 0.652], [65239.8, 0.23], [65530.5, 8.504], [65547.2, 0.076], [65627.4, 8.519], [65683.0, 14.614], [71053.3, 0.0]]}
{"kind": "depth", "E": 1787088313073, "U": 11315917350844, "u": 11315917357898, "recv_ms": 1787088313011, "bids": [[1000.0, 35.76], [14193.8, 3.234], [14293.8, 0.966], [58134.4, 0.002], [61364.1, 0.024], [62010.0, 2.319], [63302.0, 0.021], [63593.8, 0.028], [63947.9, 0.151], [64518.7, 0.963], [64541.3, 0.003], [64557.6, 0.031], [64561.0, 3.919], [64568.6, 0.753], [64570.3, 0.081], [64570.6, 0.145], [64570.8, 0.571], [64571.0, 0.427], [64571.1, 0.07], [64571.9, 0.101], [64572.4, 0.1], [64576.0, 0.629], [64576.9, 0.08], [64577.4, 0.482], [64578.1, 0.154], [64578.8, 0.011], [64579.3, 0.003], [64580.5, 0.0], [64581.0, 0.02], [64582.2, 0.017], [64583.2, 0.0], [64584.9, 0.312], [64585.2, 0.698], [64585.4, 0.474], [64585.5, 0.566], [64585.6, 0.094], [64586.2, 0.028], [64586.6, 0.002], [64587.5, 0.565], [64587.7, 0.068], [64588.2, 0.009], [64588.3, 0.154], [64588.7, 1.64], [64588.9, 0.227], [64589.1, 0.584], [64589.2, 0.15], [64589.4, 0.001], [64589.5, 0.109], [64589.7, 0.1], [64589.8, 0.015], [64589.9, 0.001], [64590.4, 0.002], [64591.6, 0.08], [64593.8, 32.414]], "asks": [[64593.9, 3.001], [64596.6, 0.101], [64597.0, 0.086], [64597.5, 0.007], [64599.0, 0.017], [64599.7, 0.001], [64601.7, 0.0], [64602.1, 0.067], [64606.8, 0.095], [64607.6, 0.31], [64607.8, 0.567], [64608.4, 0.092], [64608.5, 1.253], [64608.8, 0.213], [64610.7, 0.001], [64610.9, 0.004], [64611.5, 0.719], [64613.2, 0.009], [64613.4, 1.461], [64615.1, 0.546], [64615.9, 0.926], [64616.6, 0.002], [64616.7, 0.0], [64617.8, 0.001], [64618.3, 0.015], [64618.5, 0.0], [64619.1, 0.574], [64619.5, 0.006], [64620.6, 0.124], [64621.1, 0.058], [64621.5, 0.652], [64621.6, 0.002], [64622.2, 0.0], [64622.7, 3.704], [64640.3, 0.001], [64642.0, 0.905], [64647.0, 0.301], [64648.0, 0.012], [65239.8, 0.228], [65498.2, 8.085], [65521.6, 42.408], [65530.5, 10.638], [65593.9, 0.02], [65618.5, 7.083]]}
{"kind": "depth", "E": 1787088313277, "U": 11315917366570, "u": 11315917374718, "recv_ms": 1787088313212, "bids": [[1000.0, 35.76], [14093.8, 0.084], [14193.8, 3.78], [14293.8, 0.336], [51675.0, 0.0], [58134.4, 0.002], [63593.8, 0.008], [63616.2, 30.52], [63947.9, 0.151], [64270.8, 2.663], [64408.8, 0.029], [64528.6, 7.001], [64529.9, 1.779], [64551.2, 3.514], [64567.4, 0.972], [64568.9, 0.015], [64576.1, 0.092], [64588.6, 1.419], [64589.1, 0.275], [64589.7, 1.118]], "asks": [[64596.6, 0.017], [64597.0, 0.002], [64597.5, 0.091], [64599.7, 0.009], [64603.3, 0.069], [64603.4, 0.007], [64603.8, 0.127], [64607.8, 0.017], [64608.4, 0.634], [64621.6, 0.002], [64623.4, 1.057], [64626.0, 1.886], [64626.1, 0.023], [64639.6, 3.5], [64678.6, 2.394], [64680.3, 0.012], [64916.9, 2.615], [65239.8, 0.228], [65530.5, 11.705], [65593.9, 0.0], [65627.4, 9.584]]}
{"kind": "depth", "E": 1787088313379, "U": 11315917375224, "u": 11315917383512, "recv_ms": 1787088313318, "bids": [[1000.0, 35.76], [14093.8, 0.336], [14193.8, 3.64], [14293.8, 0.224], [51675.0, 0.0], [58134.4, 0.002], [61364.1, 0.024], [62010.0, 2.319], [63598.0, 0.001], [63947.9, 0.151], [64270.8, 2.664], [64421.1, 1.033], [64451.0, 0.0], [64451.1, 3.367], [64496.2, 10.001], [64561.3, 0.113], [64568.6, 0.191], [64569.2, 0.06], [64576.0, 0.01], [64577.3, 0.117], [64577.9, 0.0], [64581.5, 0.007], [64582.2, 0.01], [64583.1, 1.074], [64583.5, 0.001], [64583.6, 0.542], [64585.0, 35.769], [64585.2, 0.156], [64586.1, 0.006], [64588.8, 0.118], [64589.7, 0.1], [64593.8, 32.431]], "asks": [[64593.9, 3.002], [64603.7, 0.262], [64605.6, 0.005], [64621.7, 0.001], [64622.4, 2.182], [64622.8, 0.349], [64622.9, 0.483], [64623.0, 0.274], [64625.7, 0.011], [64625.8, 0.314], [64625.9, 0.163], [64626.7, 0.062], [64626.8, 0.0], [64626.9, 0.001], [64628.8, 0.451], [64628.9, 0.0], [64629.0, 0.007], [64640.3, 0.748], [64659.7, 6.001], [64692.0, 10.064], [64712.1, 0.123], [64733.1, 7.499], [64916.9, 2.616], [65239.8, 0.228], [65521.6, 41.341], [65586.2, 30.812]]}
{"kind": "depth", "E": 1787088313481, "U": 11315917383628, "u": 11315917392010, "recv_ms": 1787088313417, "bids": [[14093.8, 0.56], [14193.8, 3.542], [14293.8, 0.098], [58134.4, 0.002], [61364.1, 0.024], [62010.0, 2.316], [63302.0, 0.024], [63593.8, 0.028], [63705.8, 1.961], [63947.9, 0.151], [64270.8, 2.674], [64493.8, 0.0], [64496.3, 2.329], [64498.3, 2.135], [64561.0, 3.919], [64568.9, 0.015], [64577.0, 0.632], [64583.2, 0.542], [64583.6, 0.0], [64587.7, 0.065], [64588.8, 0.118], [64589.7, 0.1], [64591.6, 0.08], [64592.8, 0.0], [64593.8, 32.426]], "asks": [[64596.6, 0.101], [64597.0, 0.086], [64601.1, 0.621], [64601.3, 0.0], [64609.4, 0.003], [64621.7, 0.001], [64691.9, 0.008], [64694.7, 2.648], [65239.8, 0.228], [65581.8, 0.001], [65593.9, 0.02]]}
{"kind": "depth", "E": 1787088313583, "U": 11315917392159, "u": 11315917398441, "recv_ms": 1787088313519, "bids": [[1000.0, 35.76], [14093.8, 0.826], [14193.8, 3.374], [14293.8, 0.0], [58134.4, 0.002], [61364.1, 0.024], [62010.0, 2.319], [63624.9, 1.711], [63947.9, 0.151], [64561.1, 0.047], [64588.8, 0.118], [64591.6, 0.081], [64592.0, 0.906], [64593.8, 32.422]], "asks": [[64621.7, 0.001], [64621.8, 0.415], [64671.0, 0.0], [64671.9, 0.116], [64678.0, 0.154], [64678.9, 0.013], [64685.1, 0.001], [64686.0, 0.021], [64692.2, 0.0], [64693.0, 0.03], [64699.2, 0.611], [64700.1, 0.013], [64706.3, 0.001], [64707.1, 0.034], [64713.3, 0.002], [64714.2, 0.016], [64720.4, 0.0], [64721.2, 0.015], [65191.8, 7.897], [65239.8, 0.228], [65356.8, 0.005], [65521.6, 40.274], [65530.5, 12.772], [65595.1, 3.197]]}
{"kind": "depth", "E": 1787088313685, "U": 11315917398571, "u": 11315917405317, "recv_ms": 1787088313623, "bids": [[1000.0, 35.76], [14093.8, 1.19], [14193.8, 3.01], [51675.0, 0.0], [58134.4, 0.002], [62010.0, 2.316], [63302.0, 0.021], [63593.8, 0.008], [63720.9, 1.979], [63947.9, 0.151], [64451.1, 0.0], [64451.2, 5.762], [64548.5, 0.003], [64555.1, 1.228], [64562.0, 0.001], [64583.2, 0.0], [64585.2, 0.698]], "asks": [[64604.7, 0.004], [64621.8, 0.261], [64621.9, 0.476], [64652.1, 0.004], [64671.5, 0.071], [64733.1, 7.499], [65239.8, 0.228], [65530.5, 13.839], [65593.9, 0.0], [66886.1, 0.0]]}
{"kind": "depth", "E": 1787088313787, "U": 11315917405401, "u": 11315917411378, "recv_ms": 1787088313738, "bids": [[14093.8, 1.54], [14193.8, 2.66], [51675.0, 0.0], [58134.4, 0.002], [63674.1, 40.545], [63947.9, 0.151], [64270.8, 2.664], [64451.2, 2.395]], "asks": [[64596.6, 0.017], [64597.0, 0.002], [64621.9, 0.476], [64733.1, 2.092], [65101.8, 5.903], [65207.5, 0.612], [65239.8, 0.228], [65773.0, 0.986]]}
{"kind": "depth", "E": 1787088313889, "U": 11315917411538, "u": 11315917416837, "recv_ms": 1787088313826, "bids": [[1000.0, 35.76], [14093.8, 1.904], [14193.8, 2.296], [58134.4, 0.002], [61364.1, 0.024], [62010.0, 2.319], [63593.8, 0.028], [63947.9, 0.151], [64434.0, 0.0], [64434.2, 4.258], [64451.2, 5.762], [64501.5, 0.093], [64534.4, 0.0], [64570.9, 0.0], [64587.3, 0.108], [64588.7, 1.64], [64593.8, 32.422]], "asks": [[64621.9, 0.322], [64622.1, 0.611], [64733.1, 7.499], [64750.1, 10.428], [65239.8, 0.228], [65239.9, 0.001], [65593.9, 0.02], [65650.8, 5.127], [65788.9, 0.986]]}
{"kind": "depth", "E": 1787088313991, "U": 11315917416916, "u": 11315917425118, "recv_ms": 1787088313932, "bids": [[1000.0, 35.76], [14093.8, 2.254], [14193.8, 1.946], [58134.4, 0.002], [61364.1, 0.024], [61364.2, 0.026], [62010.0, 2.316], [63642.1, 1.866], [63947.9, 0.151], [64227.6, 0.0], [64230.1, 1.462], [64253.6, 0.0], [64253.7, 0.497], [64285.7, 0.682], [64324.1, 0.001], [64325.2, 1.168], [64395.0, 0.301], [64396.8, 1.825], [64451.2, 5.733], [64555.1, 1.224], [64564.7, 0.011], [64588.7, 1.64], [64593.8, 32.421]], "asks": [[64621.9, 0.322], [64622.0, 0.155], [64622.1, 0.457], [64733.1, 7.499], [64790.8, 1.473], [64791.0, 0.012], [64861.7, 0.475], [64862.2, 0.002], [64956.9, 1.915], [64959.5, 0.0], [65110.7, 4.755], [65239.8, 0.228], [65324.7, 0.0], [66893.4, 0.146]]}
{"kind": "depth", "E": 1787088314093, "U": 11315917425472, "u": 11315917437856, "recv_ms": 1787088314030, "bids": [[14093.8, 2.604], [14193.8, 1.596], [51675.0, 0.0], [58134.4, 0.002], [61364.1, 0.024], [62010.0, 2.319], [63593.8, 0.008], [63650.7, 0.659], [63689.5, 5.084], [63882.9, 0.496], [63947.9, 0.151], [64111.0, 2.947], [64270.8, 2.664], [64569.3, 0.619], [64576.7, 0.964], [64582.2, 0.01], [64588.7, 1.64], [64593.8, 32.424]], "asks": [[64603.3, 0.069], [64603.4, 0.007], [64607.8, 0.001], [64608.4, 0.65], [64613.9, 0.619], [64621.3, 0.619], [64621.9, 0.322], [64622.0, 0.001], [64691.9, 2.327], [65239.8, 0.228], [65593.9, 0.0], [65885.7, 0.025]]}
{"kind": "depth", "E": 1787088314195, "U": 11315917437973, "u": 11315917462647, "recv_ms": 1787088314158, "bids": [[1000.0, 35.76], [14093.8, 2.842], [14095.4, 0.042], [14097.6, 0.084], [14193.8, 1.232], [51675.0, 0.0], [51676.0, 0.0], [58134.4, 0.0], [58137.8, 0.002], [61364.1, 0.026], [61364.2, 0.024], [63305.7, 0.007], [63583.9, 30.0], [63588.5, 0.003], [63588.7, 0.621], [63588.9, 0.0], [63589.0, 0.037], [63591.6, 0.004], [63592.6, 3.296], [63592.9, 0.037], [63594.0, 0.002], [63595.4, 0.018], [63597.6, 0.022], [63648.5, 47.988], [63657.2, 3.295], [63803.3, 32.396], [63947.9, 0.151], [63949.4, 0.013], [63951.6, 0.0], [63963.5, 0.002], [64100.1, 4.342], [64111.1, 0.311], [64363.4, 0.077], [64364.5, 2.815], [64365.0, 0.223], [64382.8, 0.077], [64450.9, 0.0], [64452.9, 0.005], [64457.8, 0.005], [64461.3, 0.014], [64467.8, 0.121], [64468.4, 0.003], [64493.1, 34.435], [64495.3, 0.26], [64497.5, 0.0], [64497.9, 0.027], [64499.7, 0.009], [64505.9, 0.005], [64507.2, 0.131], [64509.0, 1.335], [64510.7, 0.022], [64512.0, 0.318], [64514.0, 0.01], [64514.6, 0.061], [64515.6, 1.0], [64516.0, 1.5], [64517.2, 2.29], [64521.6, 0.089], [64522.1, 2.619], [64522.7, 0.033], [64523.1, 0.015], [64523.9, 0.017], [64524.4, 0.009], [64524.6, 0.274], [64525.5, 0.327], [64526.0, 0.052], [64528.0, 0.089], [64528.6, 7.001], [64531.5, 0.022], [64535.5, 0.621], [64539.1, 0.005], [64539.4, 0.006], [64539.5, 0.325], [64539.6, 0.0], [64540.2, 0.0], [64540.5, 0.892], [64542.7, 0.0], [64542.9, 0.004], [64543.3, 0.011], [64543.4, 0.005], [64543.8, 0.01], [64544.2, 0.017], [64544.3, 0.018], [64544.9, 0.0], [64545.6, 0.002], [64547.2, 0.007], [64547.4, 0.28], [64548.2, 0.079], [64548.3, 0.001], [64548.8, 0.061], [64550.1, 0.139], [64550.5, 0.006], [64551.0, 0.046], [64551.2, 3.53], [64551.4, 0.094], [64552.0, 0.02], [64552.6, 2.982], [64552.7, 0.004], [64553.0, 0.018], [64553.1, 0.002], [64553.3, 1.066], [64554.0, 0.027], [64554.9, 0.037], [64555.3, 0.062], [64557.3, 0.003], [64557.7, 0.008], [64558.2, 0.0], [64558.7, 0.074], [64560.0, 0.081], [64560.2, 1.614], [64561.0, 3.894], [64561.2, 0.027], [64562.2, 0.015], [64562.3, 0.0], [64562.6, 0.0], [64562.7, 0.001], [64562.9, 0.005], [64564.1, 2.32], [64564.2, 0.539], [64564.5, 0.117], [64564.7, 0.005], [64564.9, 0.016], [64565.0, 0.002], [64565.1, 0.018], [64565.6, 0.015], [64565.8, 0.143], [64566.0, 0.005], [64566.1, 0.017], [64566.2, 0.016], [64566.6, 0.057], [64566.7, 0.012], [64567.9, 0.101], [64568.1, 0.005], [64568.6, 0.134], [64568.9, 0.0], [64569.1, 0.007], [64569.3, 0.0], [64569.6, 0.017], [64569.8, 0.01], [64570.2, 0.02], [64570.3, 0.082], [64570.5, 2.421], [64570.9, 0.015], [64571.2, 0.103], [64571.9, 0.158], [64572.1, 1.146], [64572.7, 0.083], [64572.8, 0.006], [64572.9, 0.015], [64573.1, 2.322], [64573.4, 0.001], [64574.3, 0.001], [64574.5, 0.042], [64575.3, 0.093], [64575.5, 0.062], [64576.1, 0.002], [64576.3, 0.079], [64576.5, 0.012], [64576.7, 0.345], [64576.8, 0.001], [64577.2, 1.237], [64577.3, 0.0], [64577.4, 0.451], [64577.7, 0.004], [64578.0, 1.023], [64578.7, 1.176], [64579.3, 0.02], [64579.5, 0.001], [64580.1, 0.803], [64580.6, 0.0], [64580.9, 0.005], [64581.1, 0.124], [64581.2, 0.257], [64581.3, 0.002], [64581.4, 0.016], [64581.5, 0.002], [64581.6, 0.557], [64581.8, 0.016], [64581.9, 0.0], [64582.2, 0.003], [64582.4, 0.01], [64582.5, 0.336], [64582.6, 0.0], [64582.7, 0.001], [64582.8, 0.237], [64582.9, 0.011], [64583.0, 0.001], [64583.1, 0.002], [64583.4, 0.061], [64583.8, 0.008], [64584.0, 0.179], [64584.1, 0.012], [64584.4, 0.231], [64584.5, 0.007], [64584.7, 0.067], [64584.9, 0.311], [64585.2, 0.001], [64585.4, 0.461], [64585.5, 0.0], [64585.6, 0.008], [64585.7, 0.001], [64585.8, 0.0], [64586.1, 0.0], [64586.2, 0.02], [64586.4, 0.001], [64586.5, 0.94], [64586.6, 0.148], [64586.8, 0.367], [64587.1, 0.191], [64587.4, 0.002], [64587.7, 0.065], [64587.8, 0.032], [64587.9, 0.005], [64588.2, 0.558], [64588.5, 0.108], [64588.6, 1.11], [64588.7, 0.0], [64588.8, 0.118], [64589.0, 0.5], [64589.1, 0.286], [64589.2, 0.306], [64589.3, 0.232], [64589.4, 0.001], [64589.5, 0.101], [64589.7, 0.101], [64589.8, 0.015], [64589.9, 0.007], [64590.0, 0.127], [64590.1, 0.003], [64590.3, 0.001], [64590.4, 0.001], [64590.5, 0.001], [64590.8, 0.001], [64591.1, 0.032], [64591.3, 0.005], [64591.5, 0.397], [64591.6, 0.013], [64591.7, 1.867], [64591.8, 0.826], [64591.9, 0.001], [64592.0, 0.91], [64592.1, 0.087], [64592.2, 0.0], [64592.4, 0.003], [64592.5, 0.084], [64592.6, 0.002], [64592.7, 0.001], [64592.8, 0.015], [64592.9, 0.084], [64593.0, 0.008], [64593.1, 0.391], [64593.2, 0.007], [64593.3, 0.145], [64593.5, 0.041], [64593.6, 0.002], [64593.7, 0.004], [64593.8, 0.967], [64593.9, 4.617], [64594.0, 0.422], [64594.1, 0.001], [64594.2, 0.427], [64594.3, 0.003], [64594.4, 0.284], [64594.5, 0.001], [64594.6, 0.201], [64594.9, 0.001], [64595.0, 0.004], [64595.1, 0.001], [64595.2, 0.002], [64595.3, 0.001], [64595.4, 2.705], [64595.5, 5.14], [64595.6, 0.008], [64595.7, 0.0], [64595.9, 0.622], [64596.0, 0.008], [64596.3, 0.0], [64596.4, 0.085], [64596.5, 2.32], [64596.6, 1.318], [64596.7, 0.0], [64597.0, 0.0], [64597.3, 0.001], [64597.4, 0.0], [64597.5, 0.009], [64597.6, 44.756]], "asks": [[64593.9, 0.0], [64594.0, 0.0], [64594.1, 0.0], [64594.2, 0.0], [64594.3, 0.0], [64594.4, 0.0], [64594.6, 0.0], [64595.0, 0.0], [64595.1, 0.0], [64595.2, 0.0], [64595.3, 0.0], [64595.4, 0.0], [64595.5, 0.0], [64595.6, 0.0], [64595.7, 0.0], [64595.8, 0.0], [64596.0, 0.0], [64596.2, 0.0], [64596.4, 0.0], [64596.5, 0.0], [64596.6, 0.0], [64596.7, 0.0], [64596.8, 0.0], [64596.9, 0.0], [64597.0, 0.0], [64597.1, 0.0], [64597.3, 0.0], [64597.4, 0.0], [64597.5, 0.0], [64597.6, 0.0], [64597.7, 4.809], [64597.8, 0.007], [64597.9, 0.639], [64598.0, 0.066], [64598.1, 0.018], [64598.2, 0.002], [64598.3, 0.0], [64598.4, 0.008], [64598.5, 0.0], [64598.7, 0.003], [64598.8, 0.002], [64598.9, 0.0], [64599.0, 0.0], [64599.1, 0.0], [64599.2, 0.0], [64599.3, 0.0], [64599.5, 0.003], [64599.6, 0.001], [64599.7, 0.0], [64599.8, 0.004], [64599.9, 0.003], [64600.0, 3.787], [64600.1, 0.003], [64600.2, 0.202], [64600.4, 0.007], [64600.5, 0.085], [64600.6, 0.001], [64600.8, 0.003], [64600.9, 0.098], [64601.0, 0.313], [64601.1, 0.001], [64601.2, 0.014], [64601.3, 0.084], [64601.6, 0.008], [64601.7, 0.084], [64602.0, 0.017], [64602.1, 0.136], [64602.2, 0.002], [64602.4, 0.134], [64602.5, 0.055], [64602.6, 0.002], [64602.7, 0.07], [64602.8, 0.156], [64602.9, 0.001], [64603.0, 0.065], [64603.1, 0.103], [64603.2, 0.034], [64603.4, 0.008], [64603.5, 0.109], [64603.7, 0.22], [64603.8, 0.571], [64603.9, 0.725], [64604.0, 0.126], [64604.1, 0.42], [64604.2, 0.536], [64604.3, 0.134], [64604.4, 0.295], [64604.8, 0.011], [64604.9, 0.002], [64605.0, 0.001], [64605.1, 1.002], [64605.2, 0.002], [64605.4, 0.001], [64605.6, 0.006], [64605.8, 0.014], [64605.9, 0.46], [64606.0, 0.003], [64606.1, 0.023], [64606.2, 0.689], [64606.3, 0.026], [64606.8, 0.015], [64606.9, 0.0], [64607.1, 0.229], [64607.2, 0.079], [64607.3, 0.002], [64607.4, 0.014], [64607.6, 0.001], [64607.7, 0.078], [64607.8, 0.55], [64607.9, 1.617], [64608.0, 0.296], [64608.2, 0.019], [64608.3, 0.048], [64608.4, 0.0], [64608.5, 0.016], [64608.7, 2.616], [64609.5, 0.019], [64609.8, 1.796], [64610.0, 0.006], [64610.1, 0.011], [64610.5, 0.077], [64610.6, 0.066], [64610.7, 0.003], [64611.0, 1.395], [64611.1, 0.324], [64611.4, 0.007], [64611.5, 0.155], [64611.6, 0.721], [64611.7, 4.018], [64612.1, 0.041], [64613.2, 0.008], [64613.3, 0.166], [64613.5, 0.0], [64613.7, 0.049], [64613.8, 0.003], [64613.9, 0.083], [64614.3, 0.064], [64614.7, 0.001], [64614.8, 0.001], [64614.9, 0.376], [64615.1, 0.004], [64615.4, 0.001], [64615.5, 0.066], [64615.7, 2.95], [64615.8, 0.001], [64615.9, 0.0], [64616.1, 0.054], [64616.7, 0.021], [64616.8, 0.002], [64616.9, 1.237], [64617.1, 0.784], [64617.3, 0.001], [64617.5, 0.542], [64617.6, 1.059], [64618.0, 0.021], [64618.2, 0.377], [64618.3, 0.013], [64618.8, 0.161], [64619.0, 0.004], [64619.1, 0.002], [64619.3, 1.063], [64619.4, 0.048], [64619.7, 0.688], [64619.9, 0.001], [64620.0, 0.232], [64620.1, 0.108], [64620.2, 0.444], [64620.3, 0.1], [64620.5, 0.01], [64620.6, 0.008], [64620.7, 0.054], [64620.8, 0.012], [64621.1, 0.016], [64621.2, 0.012], [64621.3, 0.0], [64621.9, 0.322], [64622.0, 0.155], [64622.5, 0.444], [64622.8, 0.349], [64623.2, 0.007], [64623.3, 2.332], [64623.4, 1.057], [64623.6, 0.015], [64623.7, 0.558], [64623.8, 1.87], [64623.9, 0.007], [64624.0, 0.264], [64624.1, 0.048], [64624.3, 0.018], [64624.6, 0.057], [64624.7, 0.694], [64625.1, 0.69], [64625.2, 0.007], [64625.7, 0.003], [64625.8, 0.005], [64625.9, 0.213], [64626.1, 0.015], [64626.7, 0.019], [64627.2, 0.008], [64627.7, 0.954], [64628.0, 0.311], [64628.1, 0.032], [64628.8, 0.452], [64629.4, 0.0], [64629.5, 0.037], [64629.8, 0.004], [64630.2, 0.002], [64630.5, 0.629], [64630.7, 0.029], [64631.1, 3.437], [64631.6, 0.023], [64632.2, 0.0], [64632.6, 2.391], [64632.7, 0.167], [64633.5, 0.0], [64633.7, 0.304], [64633.9, 0.001], [64635.3, 10.032], [64635.4, 0.0], [64635.7, 0.007], [64636.0, 0.056], [64636.1, 0.001], [64636.4, 0.0], [64636.5, 0.018], [64636.8, 0.028], [64636.9, 0.025], [64637.2, 0.069], [64637.5, 1.25], [64637.6, 4.256], [64638.0, 1.035], [64638.1, 0.406], [64638.6, 0.001], [64639.0, 0.185], [64639.6, 3.502], [64640.1, 0.227], [64640.2, 0.63], [64640.3, 0.752], [64640.7, 0.002], [64640.8, 0.01], [64641.7, 0.003], [64642.2, 0.432], [64642.9, 0.003], [64643.8, 0.246], [64644.5, 0.967], [64645.5, 0.101], [64646.1, 0.016], [64648.3, 0.021], [64650.7, 0.001], [64651.0, 1.867], [64652.0, 0.053], [64652.3, 0.061], [64654.2, 0.305], [64657.3, 0.0], [64657.4, 1.934], [64658.5, 0.6], [64661.3, 0.271], [64662.1, 1.352], [64663.4, 0.093], [64664.9, 0.0], [64666.2, 0.03], [64666.7, 0.03], [64667.0, 0.0], [64667.8, 0.001], [64669.8, 1.397], [64670.0, 0.094], [64671.1, 31.026], [64671.3, 0.031], [64673.2, 0.002], [64674.1, 0.001], [64675.3, 0.004], [64678.0, 0.155], [64681.9, 0.203], [64684.5, 0.063], [64687.3, 2.509], [64691.9, 2.319], [64694.7, 2.656], [64699.3, 0.003], [64705.5, 0.005], [64712.1, 0.008], [64714.3, 0.116], [64714.5, 1.215], [64715.9, 0.03], [64716.6, 0.005], [64717.0, 0.09], [64722.0, 0.016], [64723.2, 0.221], [64733.9, 0.072], [64734.0, 0.001], [64735.2, 1.0], [64745.2, 0.099], [64770.7, 2.319], [64770.8, 0.013], [64772.1, 0.204], [64774.0, 0.008], [64774.4, 0.86], [64774.5, 0.0], [64777.1, 0.005], [64777.2, 0.001], [64778.8, 0.001], [64778.9, 0.015], [64779.4, 0.004], [64779.5, 0.004], [64783.9, 0.007], [64786.6, 0.526], [64790.9, 2.13], [64794.6, 0.934], [64795.7, 3.251], [64803.7, 7.994], [64848.3, 0.0], [64849.8, 0.0], [64849.9, 3.969], [64860.9, 0.0], [64886.9, 0.0], [64887.0, 0.071], [64893.4, 0.0], [64925.9, 0.022], [64940.3, 0.383], [64958.4, 0.017], [65044.4, 0.195], [65076.5, 0.005], [65229.0, 0.498], [65239.8, 0.228], [65241.5, 0.0], [65243.7, 0.04], [65337.1, 0.911], [65337.4, 0.001], [65338.8, 9.091], [65341.0, 4.594], [65401.5, 3.332], [65401.7, 1.519], [65403.4, 3.03], [65405.6, 3.795], [65498.2, 8.268], [65521.6, 39.513], [65597.7, 0.037], [65659.7, 2.131], [68388.4, 0.0], [69858.0, 0.001], [70020.5, 0.0], [70182.9, 0.01], [70345.4, 0.002]]}
{"kind": "depth", "E": 1787088314297, "U": 11315917462683, "u": 11315917486861, "recv_ms": 1787088314237, "bids": [[1000.0, 35.76], [14097.6, 0.434], [14193.8, 0.882], [51675.0, 0.0], [51678.0, 0.004], [58137.8, 0.002], [61367.7, 0.0], [62010.0, 2.316], [63597.6, 0.036], [63951.6, 0.0], [64178.6, 0.002], [64231.2, 41.82], [64233.1, 6.658], [64270.8, 2.663], [64274.6, 0.1], [64327.7, 32.373], [64329.1, 5.531], [64398.5, 26.676], [64448.9, 0.006], [64493.1, 0.0], [64496.3, 2.321], [64500.1, 0.01], [64507.2, 0.126], [64508.9, 0.051], [64515.6, 2.473], [64515.7, 0.0], [64521.6, 0.063], [64521.7, 34.435], [64521.8, 5.173], [64523.3, 0.184], [64529.2, 0.056], [64529.4, 1.476], [64529.5, 0.0], [64533.0, 0.217], [64534.5, 2.226], [64534.6, 1.428], [64534.7, 0.017], [64535.0, 0.466], [64535.1, 0.018], [64536.9, 0.461], [64537.1, 0.016], [64538.0, 0.002], [64539.1, 0.0], [64539.3, 0.004], [64542.1, 2.165], [64542.2, 0.0], [64545.4, 0.501], [64545.5, 0.323], [64547.3, 0.005], [64547.6, 0.003], [64549.8, 2.146], [64553.3, 1.543], [64555.6, 0.97], [64555.8, 0.774], [64555.9, 0.001], [64558.7, 0.004], [64558.8, 0.014], [64559.7, 0.078], [64560.5, 0.093], [64561.6, 0.037], [64561.8, 0.069], [64561.9, 0.001], [64563.6, 0.135], [64565.8, 0.023], [64566.2, 0.016], [64566.6, 0.008], [64567.1, 0.064], [64568.7, 0.131], [64569.7, 0.059], [64570.0, 0.018], [64570.4, 1.214], [64570.9, 0.03], [64571.9, 0.101], [64572.9, 0.0], [64574.3, 0.001], [64575.0, 0.008], [64575.2, 0.0], [64576.0, 0.01], [64576.7, 0.31], [64578.1, 0.154], [64578.3, 0.119], [64578.9, 0.005], [64579.3, 0.001], [64579.7, 0.004], [64579.8, 0.0], [64580.0, 0.318], [64580.1, 0.834], [64580.2, 0.558], [64581.0, 0.022], [64581.1, 0.008], [64581.2, 0.226], [64581.6, 0.0], [64582.4, 0.008], [64582.7, 0.212], [64583.0, 0.008], [64583.8, 0.021], [64583.9, 0.04], [64584.1, 0.939], [64584.7, 0.067], [64585.0, 35.767], [64585.4, 0.995], [64585.5, 0.008], [64585.8, 0.0], [64586.1, 0.0], [64586.2, 0.028], [64586.3, 0.005], [64586.5, 0.013], [64586.8, 0.359], [64587.0, 0.929], [64587.1, 0.171], [64587.6, 0.002], [64588.2, 0.023], [64588.3, 0.238], [64589.1, 0.283], [64589.3, 0.232], [64589.9, 0.007], [64590.0, 0.13], [64590.6, 0.009], [64590.9, 0.0], [64591.0, 1.551], [64591.1, 0.032], [64591.3, 0.002], [64591.5, 0.004], [64592.0, 0.905], [64592.1, 0.008], [64592.6, 0.312], [64593.0, 0.008], [64593.6, 0.155], [64593.7, 0.003], [64593.8, 0.554], [64593.9, 3.071], [64594.0, 0.369], [64594.5, 0.007], [64594.6, 0.047], [64595.0, 0.088], [64595.1, 0.006], [64595.2, 0.007], [64595.4, 1.011], [64595.5, 0.005], [64595.6, 0.0], [64595.8, 0.084], [64595.9, 0.622], [64596.0, 0.002], [64596.1, 0.0], [64596.2, 0.084], [64596.3, 0.0], [64596.4, 0.001], [64596.5, 0.001], [64596.6, 0.0], [64596.7, 0.0], [64596.8, 0.105], [64596.9, 0.0], [64597.0, 0.084], [64597.1, 0.312], [64597.3, 0.0], [64597.4, 0.0], [64597.5, 0.009], [64597.6, 40.495]], "asks": [[64597.7, 4.408], [64597.8, 0.002], [64598.0, 0.064], [64598.4, 0.008], [64598.6, 0.001], [64598.8, 0.002], [64599.0, 0.0], [64599.2, 0.0], [64599.4, 0.017], [64599.5, 0.003], [64599.6, 0.001], [64599.7, 0.0], [64599.8, 0.004], [64599.9, 0.096], [64600.0, 3.703], [64600.1, 0.003], [64600.4, 0.012], [64600.5, 0.011], [64600.6, 0.001], [64600.9, 0.086], [64601.0, 0.001], [64601.1, 0.001], [64601.2, 0.014], [64601.6, 0.008], [64601.8, 0.001], [64601.9, 0.571], [64602.2, 0.002], [64602.4, 0.134], [64602.5, 0.055], [64602.8, 0.156], [64603.1, 0.103], [64603.4, 0.008], [64603.5, 0.108], [64603.6, 0.155], [64603.8, 0.569], [64604.0, 0.127], [64604.2, 0.536], [64604.6, 0.133], [64604.8, 0.008], [64605.0, 0.003], [64605.2, 0.001], [64605.6, 0.009], [64605.8, 0.014], [64606.1, 2.342], [64606.3, 0.006], [64606.8, 0.015], [64607.3, 0.022], [64607.7, 0.001], [64607.8, 0.085], [64607.9, 1.618], [64608.0, 0.298], [64608.5, 1.315], [64608.6, 1.353], [64608.7, 2.614], [64608.8, 0.002], [64610.5, 0.0], [64610.9, 0.004], [64611.1, 0.015], [64611.5, 0.093], [64611.6, 0.71], [64611.7, 2.879], [64611.8, 0.003], [64611.9, 0.0], [64612.0, 1.239], [64612.1, 0.044], [64612.5, 0.004], [64612.6, 0.211], [64612.9, 0.006], [64613.4, 1.541], [64613.5, 0.037], [64613.9, 0.003], [64614.0, 1.027], [64614.9, 0.376], [64615.1, 0.546], [64616.4, 0.071], [64616.5, 0.945], [64616.9, 1.267], [64617.0, 0.312], [64617.1, 0.785], [64617.5, 0.0], [64617.9, 0.003], [64618.0, 0.021], [64619.3, 0.137], [64619.5, 0.005], [64619.7, 0.681], [64620.0, 0.245], [64621.2, 0.005], [64621.3, 0.557], [64621.5, 0.709], [64622.0, 0.001], [64622.8, 0.349], [64622.9, 0.488], [64623.2, 0.011], [64623.4, 1.057], [64623.5, 0.009], [64623.7, 0.001], [64623.9, 0.162], [64624.0, 0.008], [64624.3, 0.022], [64624.6, 0.0], [64625.0, 0.083], [64625.8, 0.167], [64625.9, 0.051], [64626.6, 8.357], [64627.6, 0.918], [64628.0, 0.002], [64628.7, 0.57], [64628.8, 0.003], [64629.8, 2.413], [64629.9, 1.691], [64630.0, 0.025], [64630.4, 0.006], [64630.5, 0.629], [64631.9, 0.057], [64633.2, 0.008], [64634.7, 10.002], [64635.1, 0.417], [64635.3, 0.032], [64636.4, 0.009], [64636.9, 0.0], [64637.5, 1.16], [64638.4, 0.042], [64639.6, 4.974], [64639.7, 0.016], [64640.1, 0.2], [64641.6, 0.05], [64642.8, 0.024], [64643.8, 0.255], [64644.8, 1.052], [64647.1, 2.73], [64648.0, 0.015], [64649.6, 0.528], [64649.7, 0.364], [64651.0, 1.872], [64652.0, 0.043], [64652.2, 0.01], [64652.4, 0.0], [64652.8, 1.661], [64653.4, 1.484], [64653.5, 0.0], [64655.6, 0.005], [64657.2, 0.001], [64659.6, 2.907], [64659.8, 0.005], [64661.3, 0.061], [64663.4, 0.067], [64665.0, 0.128], [64667.5, 0.042], [64668.9, 0.001], [64671.1, 1.084], [64672.0, 2.151], [64672.7, 0.009], [64676.0, 0.026], [64677.7, 29.891], [64679.6, 3.149], [64687.3, 2.507], [64687.7, 0.033], [64691.3, 2.02], [64697.1, 0.012], [64704.0, 0.013], [64708.4, 2.998], [64786.6, 0.526], [64794.7, 27.014], [64865.8, 5.792], [64865.9, 32.852], [64916.9, 2.615], [64961.9, 8.379], [64963.2, 41.288], [65243.7, 0.04], [65337.1, 0.002], [65338.8, 0.001], [65341.0, 14.593], [65401.7, 0.005], [65403.4, 0.002], [65405.6, 8.337], [65889.6, 0.003]]}
{"kind": "depth", "E": 1787088314399, "U": 11315917486915, "u": 11315917501188, "recv_ms": 1787088314337, "bids": [[14097.6, 0.784], [14193.8, 0.532], [58137.8, 0.002], [59623.1, 0.002], [61367.7, 0.0], [62013.6, 0.003], [63179.2, 1.583], [63293.4, 0.0], [63305.7, 0.01], [63365.2, 0.0], [63436.9, 0.0], [63508.7, 0.007], [63580.4, 0.0], [63652.2, 0.0], [63724.0, 0.15], [63777.7, 31.265], [63795.7, 0.003], [63818.7, 10.611], [63867.5, 3.128], [63939.2, 4.497], [63951.6, 0.0], [64270.8, 2.663], [64454.0, 0.027], [64468.1, 0.104], [64548.8, 0.0], [64551.0, 0.107], [64553.6, 0.076], [64554.9, 0.007], [64556.8, 0.008], [64557.1, 0.044], [64559.7, 0.008], [64561.0, 3.892], [64561.1, 0.045], [64561.2, 0.025], [64561.8, 0.059], [64562.4, 0.013], [64564.4, 0.025], [64564.5, 0.115], [64564.6, 0.001], [64564.8, 0.036], [64564.9, 0.018], [64565.0, 0.004], [64567.1, 0.015], [64567.3, 0.075], [64568.2, 0.073], [64568.3, 0.002], [64568.4, 0.315], [64575.5, 0.05], [64577.1, 0.002], [64578.7, 1.238], [64579.0, 0.041], [64580.2, 0.557], [64581.1, 0.009], [64584.5, 0.007], [64584.7, 0.066], [64584.9, 0.312], [64585.7, 0.009], [64586.1, 0.0], [64586.2, 0.02], [64587.2, 0.629], [64587.7, 0.002], [64588.2, 0.015], [64588.3, 0.162], [64590.0, 0.13], [64590.6, 0.009], [64591.1, 0.341], [64592.0, 0.906], [64592.1, 0.008], [64593.6, 0.156], [64593.8, 0.359], [64594.2, 0.43], [64594.5, 0.008], [64595.2, 0.008], [64595.4, 1.158], [64595.5, 0.002], [64596.8, 0.003], [64597.1, 0.311], [64597.2, 0.179], [64597.4, 0.001], [64597.5, 0.012], [64597.6, 39.179]], "asks": [[64597.7, 5.882], [64598.4, 0.009], [64599.9, 0.096], [64600.0, 3.785], [64600.3, 0.0], [64600.4, 0.096], [64600.5, 0.011], [64601.6, 0.009], [64601.9, 0.001], [64604.0, 0.126], [64604.6, 0.134], [64604.8, 0.009], [64605.2, 0.001], [64605.4, 0.033], [64605.6, 0.006], [64605.7, 0.004], [64606.1, 2.332], [64607.8, 0.667], [64609.5, 0.319], [64610.1, 0.02], [64615.1, 0.004], [64616.4, 0.613], [64616.5, 0.019], [64616.7, 0.001], [64617.6, 1.079], [64618.0, 0.947], [64621.2, 0.015], [64621.5, 0.652], [64622.9, 0.545], [64623.7, 0.001], [64623.9, 0.008], [64626.5, 0.319], [64627.9, 0.12], [64628.7, 0.45], [64630.4, 0.007], [64635.5, 0.001], [64636.7, 0.173], [64642.1, 0.0], [64642.2, 0.429], [64650.3, 0.028], [64651.6, 0.007], [64652.2, 0.0], [64652.3, 0.0], [64652.8, 1.451], [64652.9, 0.01], [64654.5, 0.063], [64658.5, 0.455], [64659.8, 0.007], [64660.2, 0.03], [64660.6, 4.809], [64668.9, 29.874], [64670.0, 0.239], [64671.3, 0.001], [64673.5, 0.267], [64677.7, 0.018], [64720.9, 0.0], [64728.9, 0.52], [64920.7, 0.001], [65231.0, 13.619], [65240.5, 0.0], [65243.7, 0.036], [65244.2, 3.979], [65302.7, 0.007], [65374.5, 0.0], [65446.2, 0.001], [65457.0, 19.453], [65518.0, 0.843], [65589.8, 0.0], [65661.5, 0.045], [65733.3, 0.023], [65805.0, 0.001], [65876.8, 6.183]]}
{"kind": "depth", "E": 1787088314501, "U": 11315917501448, "u": 11315917509081, "recv_ms": 1787088314439, "bids": [[1000.0, 35.76], [14097.6, 0.868], [14193.8, 0.308], [14497.6, 0.14], [58137.8, 0.002], [62013.6, 0.0], [63597.6, 0.016], [63648.5, 46.89], [63816.4, 5.648], [63951.6, 0.0], [64100.1, 0.022], [64115.6, 53.915], [64115.7, 4.329], [64368.4, 0.008], [64473.5, 0.013], [64477.0, 0.372], [64477.3, 0.02], [64478.8, 3.913], [64480.6, 0.576], [64484.4, 0.088], [64487.6, 0.002], [64491.4, 0.033], [64494.7, 0.059], [64498.5, 0.017], [64501.7, 0.063], [64505.5, 2.425], [64508.8, 0.004], [64512.6, 0.014], [64515.8, 2.32], [64519.6, 1.446], [64521.2, 0.0], [64521.7, 0.0], [64522.9, 0.002], [64523.0, 0.046], [64523.9, 34.452], [64526.7, 0.013], [64538.5, 0.032], [64542.8, 0.003], [64560.6, 0.003], [64560.8, 0.0], [64570.4, 1.164], [64577.0, 0.63], [64577.6, 0.165], [64580.8, 0.317], [64582.7, 0.214], [64582.9, 0.013], [64583.8, 0.001], [64584.0, 0.175], [64589.0, 0.508], [64590.7, 0.063], [64593.8, 0.35], [64594.2, 0.837], [64594.4, 0.284], [64595.9, 0.637], [64597.2, 0.329], [64597.6, 39.181]], "asks": [[64597.7, 5.882], [64598.1, 0.003], [64599.5, 0.087], [64600.0, 3.778], [64600.2, 0.201], [64600.8, 0.004], [64603.2, 0.597], [64603.5, 0.024], [64604.6, 0.133], [64605.2, 0.002], [64607.3, 0.02], [64607.5, 0.002], [64608.6, 1.351], [64608.8, 0.0], [64609.4, 0.001], [64609.9, 0.003], [64610.1, 0.018], [64613.2, 0.01], [64618.9, 0.048], [64620.7, 0.055], [64624.1, 0.202], [64651.4, 0.016], [64663.4, 0.021], [64665.5, 0.488], [64727.6, 0.261], [64729.2, 0.012], [64729.7, 1.035], [64730.7, 3.87], [64794.6, 1.15], [64803.7, 7.778], [65243.7, 0.036], [65554.0, 0.373], [65597.7, 0.017], [65889.6, 0.006]]}
{"kind": "depth", "E": 1787088314603, "U": 11315917509115, "u": 11315917517137, "recv_ms": 1787088314540, "bids": [[1000.0, 35.76], [14097.6, 0.728], [14193.8, 0.196], [14497.6, 0.392], [58137.8, 0.002], [61355.9, 0.001], [61367.7, 0.0], [62013.6, 0.003], [63951.6, 0.0], [64521.8, 0.024], [64522.9, 0.0], [64524.1, 0.011], [64555.4, 0.003], [64556.6, 0.059], [64562.4, 0.003], [64563.0, 2.545], [64563.4, 0.041], [64580.3, 0.001], [64580.4, 0.005], [64580.9, 0.003], [64581.0, 0.02], [64582.9, 0.538], [64584.9, 0.312], [64585.6, 0.321], [64587.3, 0.11], [64589.8, 1.563], [64590.1, 0.011], [64590.6, 0.001], [64591.0, 0.003], [64591.1, 0.361], [64593.8, 0.25], [64593.9, 3.051], [64594.5, 0.007], [64595.4, 0.963], [64595.5, 0.007], [64596.5, 0.003], [64597.6, 39.238]], "asks": [[64597.7, 5.883], [64602.2, 0.008], [64603.0, 0.073], [64604.1, 0.43], [64605.3, 0.012], [64605.6, 0.006], [64607.1, 0.222], [64611.0, 2.295], [64612.0, 0.339], [64612.1, 0.051], [64614.0, 0.127], [64617.6, 1.072], [64622.8, 0.356], [64624.1, 0.048], [64652.9, 0.0], [64653.4, 1.484], [64653.9, 0.01], [64657.2, 0.015], [65243.7, 0.036], [65353.7, 5.503], [65357.0, 5.454]]}
{"kind": "depth", "E": 1787088314705, "U": 11315917517303, "u": 11315917547880, "recv_ms": 1787088314650, "bids": [[14093.8, 2.772], [14095.4, 0.028], [14097.6, 0.658], [14097.8, 0.014], [14099.9, 0.042], [14193.8, 0.07], [14497.6, 0.532], [14499.9, 0.084], [51676.3, 0.0], [58137.8, 0.0], [58139.9, 0.002], [60768.1, 0.0], [61367.7, 0.0], [63302.0, 0.018], [63308.0, 0.804], [63590.3, 0.002], [63591.6, 0.002], [63597.6, 0.04], [63713.1, 30.79], [63777.7, 31.0], [63887.2, 4.036], [63951.6, 0.0], [63951.8, 1.839], [63953.9, 0.014], [64074.9, 0.002], [64083.1, 0.001], [64139.5, 0.002], [64147.7, 0.001], [64204.1, 0.002], [64212.3, 0.127], [64268.6, 0.001], [64274.6, 0.11], [64276.9, 0.114], [64333.2, 2.514], [64341.5, 0.114], [64397.8, 0.0], [64399.9, 4.325], [64406.1, 2.894], [64435.5, 0.002], [64454.8, 2.816], [64461.3, 0.013], [64462.4, 0.002], [64463.5, 0.094], [64469.4, 0.121], [64470.4, 1.352], [64470.7, 0.005], [64477.4, 0.007], [64484.6, 0.0], [64487.4, 2.14], [64487.7, 0.0], [64488.8, 0.003], [64490.0, 1.09], [64490.9, 2.746], [64492.7, 0.0], [64493.5, 0.0], [64494.1, 0.0], [64495.3, 34.695], [64495.4, 6.835], [64495.5, 0.003], [64499.4, 0.018], [64500.2, 0.0], [64504.8, 0.048], [64507.3, 0.033], [64508.9, 0.046], [64510.4, 0.046], [64511.2, 0.042], [64512.0, 0.118], [64512.9, 0.002], [64513.9, 0.003], [64515.5, 1.474], [64515.6, 1.0], [64516.8, 0.184], [64517.0, 0.135], [64517.2, 0.077], [64517.3, 0.003], [64517.4, 2.215], [64517.5, 0.2], [64518.0, 0.25], [64519.3, 0.003], [64520.0, 9.399], [64520.2, 0.26], [64520.3, 1.905], [64520.5, 0.073], [64522.2, 1.237], [64523.2, 0.003], [64523.3, 0.158], [64523.9, 0.017], [64524.6, 1.501], [64524.7, 0.047], [64525.8, 0.075], [64527.0, 0.299], [64527.7, 0.048], [64529.3, 1.489], [64529.4, 0.004], [64531.1, 1.548], [64531.4, 0.0], [64533.4, 0.001], [64534.6, 0.077], [64534.9, 0.479], [64535.0, 0.017], [64535.3, 0.001], [64536.9, 2.004], [64538.5, 0.03], [64539.3, 0.004], [64539.5, 0.311], [64539.6, 0.0], [64539.7, 0.688], [64541.0, 0.025], [64541.7, 0.005], [64542.1, 2.164], [64543.1, 0.714], [64543.2, 0.001], [64545.0, 0.282], [64545.3, 0.449], [64545.4, 3.93], [64545.9, 1.047], [64546.3, 0.38], [64546.4, 0.017], [64546.8, 1.309], [64546.9, 0.016], [64547.2, 0.005], [64547.6, 0.0], [64548.3, 0.0], [64548.8, 0.0], [64549.7, 2.169], [64549.8, 0.0], [64550.0, 0.243], [64550.5, 0.0], [64551.0, 0.046], [64551.2, 3.516], [64551.4, 0.001], [64551.5, 0.485], [64553.1, 0.002], [64553.3, 1.604], [64553.6, 0.074], [64554.7, 1.27], [64555.7, 0.508], [64555.8, 0.325], [64557.1, 0.014], [64557.8, 0.112], [64557.9, 0.016], [64558.0, 0.035], [64558.6, 0.014], [64559.2, 0.0], [64559.4, 0.048], [64559.8, 0.323], [64560.2, 0.0], [64560.9, 0.311], [64561.2, 0.0], [64561.3, 0.113], [64562.2, 0.0], [64562.4, 0.001], [64563.2, 0.016], [64563.6, 0.015], [64564.5, 0.055], [64564.8, 0.061], [64565.1, 0.0], [64565.3, 0.003], [64566.7, 0.006], [64566.9, 0.0], [64567.0, 0.0], [64567.1, 0.015], [64567.3, 0.005], [64567.6, 0.004], [64567.7, 0.011], [64568.0, 0.051], [64568.1, 0.005], [64568.3, 0.003], [64568.7, 0.13], [64568.8, 1.729], [64569.2, 0.066], [64569.6, 0.008], [64569.7, 0.002], [64570.0, 0.004], [64570.2, 0.007], [64570.5, 2.421], [64570.9, 0.015], [64571.2, 0.12], [64571.4, 0.037], [64571.6, 0.121], [64571.7, 0.004], [64571.8, 0.124], [64571.9, 0.11], [64572.0, 0.309], [64572.1, 1.146], [64573.0, 0.012], [64573.4, 0.015], [64573.9, 0.0], [64574.0, 0.076], [64574.1, 5.047], [64574.4, 0.245], [64574.5, 0.112], [64574.6, 0.09], [64575.3, 0.003], [64575.5, 0.001], [64576.0, 0.009], [64576.2, 0.353], [64576.3, 0.004], [64576.6, 0.015], [64576.9, 0.102], [64577.6, 0.115], [64578.0, 1.021], [64578.1, 0.204], [64578.3, 0.002], [64579.0, 0.041], [64579.7, 0.002], [64579.8, 0.0], [64580.1, 0.803], [64580.4, 0.003], [64580.8, 0.32], [64580.9, 0.005], [64581.1, 0.125], [64581.2, 0.0], [64581.5, 0.002], [64582.0, 0.003], [64582.3, 0.033], [64582.7, 0.003], [64582.8, 0.018], [64582.9, 0.538], [64583.1, 0.002], [64583.2, 0.056], [64583.3, 0.0], [64583.6, 0.035], [64583.9, 0.025], [64584.0, 0.174], [64584.1, 0.012], [64584.2, 0.002], [64584.4, 0.016], [64584.5, 0.0], [64584.6, 0.008], [64584.7, 0.068], [64584.9, 0.311], [64585.0, 35.978], [64585.3, 6.31], [64585.4, 0.453], [64585.5, 0.0], [64585.6, 0.547], [64585.7, 0.001], [64586.0, 0.939], [64586.6, 0.004], [64586.7, 0.07], [64587.2, 0.299], [64587.3, 0.109], [64587.5, 0.566], [64587.9, 0.004], [64588.0, 0.902], [64588.1, 2.353], [64588.2, 0.942], [64588.3, 0.154], [64588.4, 0.146], [64588.6, 1.123], [64588.7, 0.542], [64588.8, 0.339], [64589.0, 0.508], [64589.1, 0.275], [64589.2, 0.305], [64589.4, 0.0], [64589.6, 0.224], [64589.8, 0.015], [64589.9, 0.001], [64590.0, 0.129], [64590.1, 0.004], [64590.2, 0.062], [64590.5, 0.236], [64590.7, 0.0], [64591.1, 0.032], [64591.4, 0.0], [64591.7, 1.867], [64591.9, 0.443], [64592.0, 0.907], [64592.1, 0.007], [64592.5, 0.0], [64592.7, 0.002], [64592.8, 0.016], [64592.9, 0.0], [64593.1, 0.312], [64593.3, 0.185], [64593.5, 0.003], [64593.8, 0.227], [64593.9, 2.897], [64594.0, 0.321], [64594.1, 0.001], [64594.4, 0.286], [64594.6, 0.001], [64595.1, 0.005], [64595.2, 0.009], [64595.4, 0.598], [64595.5, 0.005], [64595.6, 0.001], [64595.7, 0.043], [64595.8, 0.103], [64595.9, 0.015], [64596.0, 0.004], [64596.1, 0.023], [64596.2, 0.104], [64596.6, 0.001], [64596.7, 0.033], [64596.9, 0.001], [64597.1, 0.31], [64597.2, 0.002], [64597.3, 0.001], [64597.4, 0.0], [64597.5, 0.317], [64597.6, 0.401], [64597.7, 3.875], [64597.8, 8.991], [64597.9, 0.0], [64598.0, 0.001], [64598.1, 0.084], [64598.3, 0.988], [64598.4, 0.001], [64598.5, 0.0], [64598.6, 0.628], [64598.7, 0.0], [64598.8, 0.001], [64599.2, 0.001], [64599.3, 1.042], [64599.4, 0.64], [64599.5, 0.323], [64599.6, 0.004], [64599.7, 0.0], [64599.8, 0.005], [64599.9, 40.657]], "asks": [[64597.7, 0.0], [64597.8, 0.0], [64597.9, 0.0], [64598.0, 0.0], [64598.1, 0.0], [64598.2, 0.0], [64598.4, 0.0], [64598.6, 0.0], [64598.7, 0.0], [64598.8, 0.0], [64599.4, 0.0], [64599.5, 0.0], [64599.6, 0.0], [64599.8, 0.0], [64599.9, 0.0], [64600.0, 10.894], [64600.1, 0.003], [64600.2, 0.0], [64600.3, 0.001], [64600.4, 0.096], [64600.5, 0.01], [64600.6, 0.007], [64600.8, 0.087], [64600.9, 0.0], [64601.0, 0.0], [64601.2, 0.013], [64601.3, 0.084], [64601.4, 0.0], [64601.6, 0.007], [64601.7, 0.0], [64602.0, 0.089], [64602.1, 0.052], [64602.2, 0.002], [64602.4, 0.003], [64602.6, 0.084], [64602.7, 0.003], [64602.8, 0.07], [64603.0, 0.007], [64603.1, 0.085], [64603.2, 0.01], [64603.4, 0.047], [64603.5, 0.086], [64603.6, 0.001], [64603.7, 0.22], [64603.8, 0.128], [64603.9, 0.596], [64604.1, 0.42], [64604.2, 0.62], [64604.4, 0.297], [64604.6, 0.217], [64604.8, 0.008], [64605.0, 0.003], [64605.1, 0.311], [64605.2, 0.001], [64605.3, 0.0], [64605.4, 0.002], [64605.5, 0.084], [64605.6, 0.008], [64605.7, 0.001], [64605.8, 0.214], [64605.9, 0.021], [64606.0, 0.003], [64606.1, 0.323], [64606.2, 0.004], [64606.3, 0.002], [64606.6, 0.02], [64606.7, 0.0], [64607.1, 0.003], [64607.2, 0.506], [64607.3, 0.35], [64607.7, 0.001], [64607.8, 0.001], [64607.9, 0.006], [64608.0, 0.013], [64608.2, 0.005], [64608.4, 0.02], [64608.5, 0.019], [64608.6, 1.071], [64608.7, 0.038], [64609.1, 0.182], [64609.2, 0.152], [64609.3, 0.0], [64609.5, 0.376], [64609.6, 0.159], [64609.7, 0.032], [64610.1, 0.009], [64610.6, 0.347], [64610.7, 0.017], [64610.9, 0.097], [64611.3, 0.003], [64611.4, 0.004], [64611.5, 0.0], [64611.7, 0.761], [64611.8, 0.0], [64611.9, 0.0], [64612.1, 0.051], [64612.6, 0.0], [64612.7, 0.005], [64612.9, 0.628], [64613.0, 2.335], [64613.1, 0.033], [64613.3, 0.228], [64614.0, 0.127], [64614.1, 0.078], [64614.2, 0.01], [64614.3, 0.057], [64614.8, 0.0], [64614.9, 0.586], [64615.0, 0.017], [64615.1, 0.012], [64615.2, 1.323], [64615.3, 0.203], [64615.6, 0.0], [64615.7, 2.322], [64616.1, 0.002], [64616.2, 0.006], [64616.3, 0.02], [64616.4, 0.036], [64616.5, 0.003], [64616.7, 0.009], [64616.8, 0.633], [64617.0, 0.311], [64617.1, 0.001], [64617.6, 1.012], [64618.0, 0.021], [64618.1, 0.815], [64618.3, 0.001], [64618.4, 0.011], [64618.7, 0.311], [64618.8, 0.041], [64619.1, 0.002], [64619.3, 0.137], [64619.4, 0.832], [64619.6, 0.034], [64619.7, 0.667], [64619.8, 0.19], [64619.9, 0.161], [64620.0, 0.247], [64620.3, 0.06], [64620.5, 0.012], [64620.8, 0.013], [64621.0, 0.239], [64621.1, 0.001], [64621.2, 0.557], [64621.3, 0.0], [64621.4, 0.015], [64621.5, 0.652], [64621.7, 0.004], [64621.8, 0.262], [64621.9, 0.002], [64622.0, 0.927], [64622.9, 1.04], [64623.2, 0.0], [64623.3, 2.381], [64623.4, 0.08], [64623.6, 0.029], [64623.7, 0.321], [64624.0, 0.009], [64624.1, 0.193], [64624.3, 0.015], [64624.4, 0.64], [64624.5, 0.0], [64624.7, 1.863], [64624.8, 0.395], [64624.9, 0.037], [64625.2, 0.001], [64625.4, 0.001], [64625.7, 0.01], [64625.8, 0.163], [64626.1, 0.0], [64626.3, 0.02], [64626.4, 0.03], [64626.5, 0.319], [64626.6, 8.359], [64626.8, 0.097], [64627.0, 0.001], [64627.1, 0.011], [64627.5, 0.033], [64627.7, 0.942], [64627.9, 0.0], [64628.2, 0.166], [64628.7, 0.455], [64629.3, 0.033], [64629.5, 0.022], [64629.8, 2.323], [64630.0, 0.026], [64630.1, 0.046], [64630.4, 0.007], [64630.7, 0.015], [64631.3, 0.066], [64631.6, 0.005], [64631.7, 0.001], [64633.3, 10.003], [64633.5, 0.0], [64633.6, 0.013], [64633.7, 0.079], [64634.7, 0.072], [64634.8, 0.274], [64635.0, 0.021], [64635.7, 0.005], [64635.9, 0.0], [64636.0, 0.044], [64636.6, 0.089], [64636.8, 0.015], [64637.0, 3.804], [64637.1, 0.017], [64637.5, 0.2], [64638.3, 0.02], [64638.6, 0.001], [64638.7, 0.006], [64639.0, 0.0], [64639.1, 0.895], [64639.2, 0.006], [64639.3, 0.018], [64640.1, 0.0], [64640.2, 0.645], [64640.5, 0.09], [64640.6, 0.002], [64641.5, 0.009], [64642.5, 0.05], [64642.6, 0.013], [64642.7, 0.002], [64642.9, 0.001], [64643.5, 0.022], [64643.9, 0.201], [64644.9, 0.04], [64645.2, 0.0], [64645.5, 0.032], [64645.9, 0.006], [64647.0, 1.291], [64647.2, 0.001], [64647.7, 0.002], [64649.5, 0.453], [64649.6, 0.079], [64649.7, 0.338], [64650.9, 0.006], [64651.9, 0.0], [64653.3, 1.471], [64653.4, 0.013], [64653.9, 0.07], [64656.1, 0.0], [64656.3, 0.002], [64658.5, 0.455], [64659.4, 0.002], [64662.6, 0.0], [64663.7, 0.034], [64664.0, 0.064], [64665.0, 0.102], [64666.4, 0.124], [64667.8, 0.001], [64668.8, 5.923], [64669.8, 0.0], [64672.0, 2.15], [64673.1, 0.34], [64673.2, 0.002], [64673.5, 0.237], [64674.1, 0.001], [64675.8, 0.03], [64678.1, 0.0], [64679.6, 3.148], [64680.0, 0.128], [64684.5, 0.057], [64686.6, 0.0], [64686.8, 0.0], [64686.9, 0.0], [64687.9, 0.0], [64689.0, 0.001], [64690.6, 0.041], [64691.9, 2.319], [64693.8, 0.059], [64698.4, 0.054], [64701.1, 0.0], [64701.2, 0.0], [64701.4, 0.308], [64707.4, 2.335], [64707.5, 0.61], [64714.2, 0.015], [64714.3, 0.003], [64714.8, 0.017], [64717.0, 0.002], [64717.6, 2.527], [64722.5, 0.012], [64729.2, 0.019], [64735.2, 1.0], [64735.6, 0.001], [64736.3, 0.047], [64761.8, 0.006], [64775.3, 0.07], [64776.0, 0.005], [64779.5, 0.001], [64780.7, 0.004], [64784.9, 0.157], [64785.5, 0.027], [64786.6, 0.295], [64787.3, 0.526], [64793.2, 0.001], [64794.6, 5.099], [64850.1, 0.013], [64857.8, 0.006], [64914.7, 0.0], [64917.8, 0.0], [64921.6, 0.282], [64922.4, 0.17], [64923.0, 0.009], [64979.3, 0.092], [64987.0, 3.287], [65043.8, 0.001], [65046.9, 0.669], [65051.6, 0.001], [65108.4, 1.271], [65116.2, 0.001], [65243.7, 0.036], [65243.9, 1.518], [65246.0, 13.782], [65341.0, 1.867], [65343.3, 12.726], [65405.6, 0.01], [65407.9, 8.327], [65421.3, 0.0], [65482.4, 50.186], [65564.0, 0.629], [65597.7, 0.037], [65891.9, 0.006], [69370.6, 0.0], [69533.1, 0.0], [69695.6, 0.0]]}
{"kind": "depth", "E": 1787088314807, "U": 11315917547898, "u": 11315917563977, "recv_ms": 1787088314747, "bids": [[1000.0, 35.76], [14093.8, 2.618], [14095.4, 0.014], [14097.6, 0.574], [14099.9, 0.07], [14193.8, 0.0], [14499.9, 0.378], [58139.9, 0.002], [61369.9, 0.0], [62013.6, 0.0], [63308.0, 0.807], [63657.2, 4.393], [63725.5, 0.626], [63777.7, 30.765], [63825.1, 3.756], [63953.9, 0.008], [64146.1, 0.002], [64462.2, 2.319], [64470.2, 0.014], [64470.7, 0.029], [64487.2, 11.219], [64493.7, 5.569], [64495.3, 0.26], [64495.4, 1.689], [64500.1, 0.003], [64501.3, 0.008], [64505.0, 0.851], [64519.5, 0.011], [64520.3, 1.905], [64521.1, 0.098], [64521.7, 34.435], [64524.6, 6.477], [64532.5, 0.166], [64538.6, 0.214], [64539.3, 0.0], [64542.0, 0.008], [64546.3, 0.17], [64551.5, 0.407], [64552.7, 0.082], [64557.3, 0.028], [64563.4, 0.031], [64563.9, 0.324], [64564.8, 0.036], [64567.3, 0.075], [64567.7, 0.071], [64572.3, 1.261], [64574.0, 0.019], [64574.4, 0.025], [64574.5, 0.042], [64576.3, 0.053], [64578.0, 0.121], [64580.6, 0.001], [64581.1, 0.161], [64582.5, 0.333], [64583.2, 0.007], [64585.4, 0.461], [64586.7, 0.078], [64587.2, 1.226], [64588.2, 0.015], [64588.3, 0.162], [64588.8, 0.881], [64589.8, 0.015], [64589.9, 0.009], [64590.6, 0.071], [64591.0, 0.903], [64591.1, 0.132], [64592.1, 1.563], [64592.2, 0.309], [64593.2, 0.001], [64593.3, 0.061], [64593.8, 0.182], [64594.5, 0.001], [64594.8, 0.04], [64595.2, 0.003], [64595.7, 0.021], [64595.8, 0.084], [64596.0, 0.01], [64596.1, 0.0], [64596.2, 0.084], [64597.3, 0.006], [64597.5, 0.007], [64597.6, 0.338], [64597.7, 2.32], [64597.8, 8.982], [64597.9, 0.025], [64598.0, 0.001], [64598.3, 0.001], [64598.4, 0.012], [64598.5, 0.084], [64599.1, 0.0], [64599.3, 1.044], [64599.5, 0.323], [64599.6, 0.002], [64599.7, 0.002], [64599.9, 40.92]], "asks": [[64600.0, 10.491], [64600.4, 0.012], [64600.7, 0.099], [64600.8, 0.003], [64601.2, 0.097], [64601.3, 0.0], [64601.6, 0.091], [64602.1, 0.004], [64602.4, 0.002], [64602.8, 0.196], [64602.9, 0.002], [64603.3, 0.015], [64604.8, 0.009], [64605.0, 0.003], [64605.2, 0.001], [64605.6, 0.005], [64607.2, 0.015], [64607.3, 0.351], [64608.0, 0.014], [64608.4, 0.0], [64608.7, 0.037], [64609.1, 0.001], [64609.5, 0.067], [64609.7, 0.033], [64610.0, 0.026], [64610.2, 0.015], [64610.5, 0.0], [64610.7, 0.009], [64611.0, 1.395], [64611.4, 0.004], [64612.6, 0.0], [64612.8, 0.012], [64612.9, 0.636], [64613.3, 0.068], [64613.7, 0.033], [64615.1, 0.012], [64615.6, 0.18], [64616.7, 0.001], [64617.1, 0.0], [64617.5, 0.008], [64618.0, 0.563], [64618.1, 0.717], [64618.3, 0.004], [64618.9, 0.128], [64619.3, 0.138], [64619.4, 0.833], [64619.6, 0.034], [64620.0, 0.236], [64620.6, 0.934], [64621.0, 0.239], [64621.2, 0.015], [64622.0, 0.001], [64623.3, 2.332], [64623.7, 0.001], [64624.1, 0.039], [64625.4, 0.155], [64625.5, 0.006], [64625.6, 0.323], [64625.8, 0.167], [64626.0, 0.001], [64626.3, 0.0], [64626.5, 0.01], [64626.8, 0.057], [64627.3, 0.682], [64627.8, 0.011], [64628.0, 0.098], [64630.0, 0.075], [64631.1, 4.534], [64632.2, 0.015], [64633.0, 4.838], [64633.3, 10.095], [64636.2, 0.053], [64637.0, 2.286], [64640.5, 0.0], [64644.9, 0.038], [64645.1, 0.186], [64645.9, 0.008], [64646.5, 0.061], [64649.3, 0.028], [64651.6, 0.076], [64653.9, 0.0], [64654.3, 0.01], [64654.5, 0.002], [64655.6, 0.001], [64656.5, 0.001], [64656.8, 1.9], [64659.5, 0.029], [64663.7, 0.009], [64670.0, 0.265], [64676.4, 0.525], [64680.0, 0.129], [64682.1, 1.338], [64682.9, 0.029], [64686.7, 0.0], [64694.7, 2.648], [64696.2, 1.257], [64696.5, 1.844], [64709.0, 0.009], [64716.3, 0.0], [64716.8, 0.005], [64761.4, 0.005], [64803.0, 0.49], [64914.8, 4.506], [64955.3, 0.015], [65101.8, 4.983], [65246.0, 13.778], [65341.0, 0.049], [65343.3, 14.544], [65368.6, 0.939], [65482.4, 47.898], [65502.2, 3.651], [65569.7, 0.344]]}
{"kind": "depth", "E": 1787088314909, "U": 11315917564355, "u": 11315917573471, "recv_ms": 1787088314846, "bids": [[1000.0, 35.76], [14093.8, 2.394], [14097.6, 0.532], [14097.8, 0.0], [14099.9, 0.0], [14499.9, 0.728], [58139.9, 0.002], [61369.9, 0.001], [62015.9, 0.004], [63597.6, 0.02], [63856.5, 0.785], [63953.9, 0.008], [64240.0, 0.955], [64253.7, 0.005], [64438.1, 1.934], [64450.9, 0.307], [64461.0, 0.062], [64520.0, 9.396], [64539.4, 0.006], [64548.5, 0.0], [64552.7, 0.004], [64553.4, 0.078], [64554.0, 0.002], [64558.7, 0.064], [64563.1, 2.89], [64563.9, 0.314], [64564.6, 0.011], [64567.7, 0.011], [64572.9, 1.704], [64574.1, 5.048], [64578.7, 1.176], [64579.0, 0.022], [64580.3, 0.001], [64580.5, 0.16], [64581.9, 0.061], [64584.6, 0.009], [64586.7, 0.008], [64587.0, 0.029], [64587.3, 0.009], [64587.5, 0.496], [64587.8, 0.0], [64588.6, 1.126], [64590.9, 0.1], [64591.0, 0.973], [64591.4, 0.07], [64591.6, 0.045], [64592.0, 0.939], [64592.3, 0.001], [64592.6, 0.344], [64592.9, 0.032], [64594.1, 0.004], [64594.6, 0.004], [64595.9, 0.382], [64597.6, 0.332], [64597.8, 0.446], [64599.3, 0.371], [64599.9, 40.92]], "asks": [[64600.2, 0.001], [64600.3, 0.084], [64601.6, 0.092], [64604.6, 0.133], [64605.3, 0.048], [64605.4, 0.197], [64605.7, 0.049], [64606.3, 0.06], [64606.6, 0.074], [64606.9, 0.147], [64609.2, 0.153], [64609.5, 0.075], [64609.6, 0.802], [64609.7, 2.352], [64610.7, 0.001], [64612.1, 0.048], [64612.8, 0.004], [64612.9, 0.002], [64614.8, 0.008], [64614.9, 0.589], [64615.0, 0.917], [64615.2, 1.326], [64615.8, 1.704], [64616.7, 0.001], [64617.5, 0.0], [64618.1, 1.168], [64618.9, 0.088], [64619.1, 2.321], [64619.4, 0.993], [64620.7, 0.001], [64621.1, 0.004], [64622.1, 0.31], [64623.6, 0.996], [64624.0, 0.008], [64624.6, 0.04], [64625.4, 0.001], [64625.5, 0.006], [64627.5, 0.153], [64629.7, 1.888], [64633.8, 0.027], [64634.8, 0.154], [64639.2, 0.003], [64639.3, 0.078], [64641.5, 0.156], [64645.2, 0.003], [64646.5, 0.001], [64649.3, 0.003], [64651.0, 0.972], [64653.3, 1.681], [64654.3, 0.0], [64654.5, 0.05], [64654.8, 0.05], [64655.0, 0.011], [64655.4, 0.06], [64655.8, 0.082], [64656.0, 0.951], [64660.6, 4.599], [64662.9, 0.789], [64675.3, 0.001], [65239.9, 0.0], [65244.2, 3.6], [65246.0, 13.778], [65246.6, 0.379], [65504.4, 0.183], [65597.7, 0.017], [65891.9, 0.009]]}
{"kind": "depth", "E": 1787088315011, "U": 11315917573521, "u": 11315917581934, "recv_ms": 1787088314949, "bids": [[14093.8, 2.142], [14097.6, 0.42], [14499.9, 1.092], [58139.9, 0.002], [59460.6, 0.002], [61369.9, 0.0], [62015.9, 0.001], [63487.1, 20.23], [63551.6, 11.866], [63617.5, 0.791], [63842.3, 14.128], [63932.2, 0.547], [63953.9, 0.008], [63968.0, 63.742], [64274.6, 0.11], [64451.2, 2.395], [64454.2, 5.239], [64521.7, 0.0], [64523.9, 34.364], [64564.5, 0.053], [64565.8, 0.021], [64575.5, 0.081], [64576.4, 0.114], [64576.9, 0.022], [64581.1, 0.192], [64581.8, 0.017], [64582.3, 0.002], [64584.6, 0.008], [64585.3, 6.312], [64585.5, 0.002], [64587.1, 0.001], [64588.1, 2.321], [64588.2, 1.099], [64588.7, 0.0], [64588.8, 0.307], [64589.8, 0.015], [64592.3, 0.0], [64594.6, 0.088], [64597.0, 0.984], [64597.6, 0.329], [64598.0, 0.085], [64598.1, 0.0], [64598.5, 0.084], [64599.3, 0.002], [64599.5, 1.283], [64599.9, 40.693]], "asks": [[64600.2, 0.0], [64600.3, 0.001], [64603.1, 0.084], [64603.5, 0.085], [64603.7, 0.0], [64603.8, 0.129], [64604.0, 0.127], [64604.3, 0.14], [64605.0, 0.011], [64606.0, 0.08], [64606.1, 0.324], [64607.3, 0.362], [64609.3, 0.542], [64609.4, 0.001], [64609.5, 0.075], [64609.6, 0.168], [64610.5, 0.0], [64611.2, 0.009], [64611.4, 0.002], [64612.5, 0.002], [64612.7, 0.003], [64612.9, 0.094], [64616.7, 0.094], [64619.4, 1.064], [64619.7, 0.619], [64620.3, 0.002], [64622.3, 0.343], [64623.3, 2.334], [64624.0, 0.065], [64625.2, 0.155], [64625.8, 0.168], [64626.8, 0.0], [64630.0, 0.026], [64655.1, 0.495], [64662.3, 0.381], [64733.1, 2.092], [64739.2, 1.493], [64739.3, 5.434], [64740.8, 0.019], [64813.8, 0.0], [64834.0, 0.032], [65082.6, 51.863], [65232.2, 67.148], [65246.0, 13.778], [65360.1, 64.924], [65400.0, 110.315], [65504.4, 2.47]]}
{"kind": "depth", "E": 1787088315113, "U": 11315917582055, "u": 11315917591287, "recv_ms": 1787088315051, "bids": [[1000.0, 35.76], [14093.8, 1.918], [14097.6, 0.294], [14499.9, 1.442], [58139.9, 0.002], [61369.9, 0.0], [62015.9, 0.004], [63599.9, 0.028], [63953.9, 0.008], [64516.4, 0.01], [64543.4, 0.001], [64545.7, 0.004], [64550.1, 0.141], [64552.7, 0.0], [64553.4, 0.0], [64553.5, 0.11], [64555.1, 1.228], [64564.2, 0.535], [64564.6, 0.001], [64565.1, 0.629], [64568.5, 1.008], [64568.6, 0.138], [64572.5, 0.622], [64574.6, 0.092], [64575.5, 0.001], [64580.2, 0.0], [64581.1, 0.19], [64581.8, 0.016], [64581.9, 0.618], [64582.4, 0.088], [64584.9, 0.312], [64585.4, 0.462], [64586.0, 0.902], [64586.7, 0.935], [64587.2, 0.301], [64588.3, 0.162], [64589.2, 0.273], [64589.6, 0.07], [64591.2, 0.037], [64591.4, 0.379], [64592.2, 0.0], [64593.8, 0.158], [64596.8, 0.0], [64597.4, 0.003], [64597.6, 0.275], [64597.9, 0.025], [64598.4, 0.002], [64598.5, 0.0], [64598.9, 0.007], [64599.6, 0.003], [64599.7, 0.001], [64599.8, 0.008], [64599.9, 40.743]], "asks": [[64600.0, 10.493], [64600.1, 0.005], [64600.2, 0.001], [64600.3, 0.084], [64604.2, 0.774], [64606.6, 0.072], [64607.0, 0.222], [64608.7, 0.039], [64609.3, 0.0], [64609.5, 0.152], [64609.6, 0.725], [64610.1, 0.318], [64612.7, 0.005], [64612.9, 0.064], [64613.3, 0.006], [64614.8, 0.016], [64615.1, 0.004], [64615.9, 0.002], [64617.0, 0.311], [64618.5, 0.619], [64619.0, 0.623], [64619.1, 3.247], [64619.2, 1.186], [64619.4, 1.016], [64619.7, 0.0], [64620.0, 0.169], [64620.6, 0.008], [64625.1, 0.69], [64625.2, 0.001], [64625.3, 0.174], [64625.8, 0.787], [64629.9, 1.693], [64632.1, 0.1], [64638.8, 0.22], [64639.3, 0.018], [64640.3, 0.748], [64642.6, 0.017], [64655.0, 0.001], [64655.6, 0.011], [64659.5, 0.015], [64684.0, 5.732], [64712.9, 0.019], [65116.8, 0.955], [65246.0, 13.78], [65600.0, 70.131]]}
{"kind": "depth", "E": 1787088315215, "U": 11315917591369, "u": 11315917600121, "recv_ms": 1787088315154, "bids": [[14093.8, 1.666], [14097.6, 0.182], [14499.9, 1.806], [58139.9, 0.002], [61369.9, 0.0], [62058.3, 0.0], [62920.3, 0.001], [63178.7, 0.003], [63495.7, 6.132], [63727.3, 0.0], [63953.9, 0.008], [64565.1, 0.0], [64565.6, 0.025], [64572.5, 0.003], [64578.2, 0.09], [64584.2, 0.0], [64585.4, 0.461], [64586.1, 0.008], [64586.7, 0.927], [64589.3, 0.24], [64589.6, 0.07], [64589.9, 0.001], [64595.0, 0.151], [64597.6, 0.272], [64597.9, 0.035], [64598.5, 0.086], [64599.9, 40.746]], "asks": [[64600.0, 11.823], [64600.1, 0.005], [64600.2, 0.0], [64600.3, 0.001], [64602.9, 0.021], [64603.0, 0.03], [64604.6, 0.134], [64606.1, 0.323], [64609.5, 0.168], [64610.3, 0.0], [64611.0, 1.396], [64614.0, 1.027], [64614.8, 0.0], [64615.9, 0.022], [64618.5, 0.0], [64619.1, 3.249], [64619.4, 0.945], [64619.5, 0.003], [64621.0, 0.019], [64624.8, 0.375], [64625.8, 0.168], [64655.6, 0.001], [64656.0, 0.961], [64659.3, 0.002], [64700.9, 0.0], [64712.2, 0.033], [64719.2, 3.246], [64758.5, 0.643], [64759.2, 0.264], [64923.0, 0.008], [65246.0, 14.359], [65282.2, 3.439], [67096.9, 0.021]]}
{"kind": "depth", "E": 1787088315317, "U": 11315917600287, "u": 11315917607371, "recv_ms": 1787088315252, "bids": [[14093.8, 1.428], [14097.6, 0.056], [14499.9, 2.17], [58139.9, 0.002], [61369.9, 0.002], [62015.9, 0.001], [63560.3, 2.2], [63599.9, 0.008], [63953.9, 0.008], [64113.6, 0.003], [64274.6, 0.099], [64276.9, 0.114], [64474.6, 0.114], [64564.5, 0.055], [64578.1, 0.05], [64578.2, 0.089], [64580.0, 0.319], [64582.8, 0.172], [64582.9, 0.013], [64592.3, 0.002], [64597.9, 0.025], [64598.9, 0.009], [64599.9, 40.745]], "asks": [[64600.0, 13.43], [64604.2, 0.775], [64604.6, 0.133], [64605.8, 0.217], [64609.4, 0.001], [64609.5, 0.075], [64609.6, 0.276], [64611.6, 0.772], [64612.9, 0.544], [64614.8, 0.0], [64627.6, 2.65], [64629.4, 10.0], [64630.3, 0.266], [64631.1, 3.377], [64633.3, 0.095], [64716.9, 0.486], [64923.0, 0.009], [65246.0, 14.359], [65304.0, 0.723], [65375.2, 0.464], [65392.4, 22.484], [65424.7, 29.534], [65586.2, 29.746], [65600.0, 70.111], [65607.9, 0.693], [65740.7, 9.343]]}
{"kind": "depth", "E": 1787088315419, "U": 11315917607431, "u": 11315917613084, "recv_ms": 1787088315358, "bids": [[1000.0, 35.76], [14093.8, 1.148], [14095.4, 0.0], [14097.6, 0.0], [14499.9, 2.52], [58139.9, 0.002], [61369.9, 0.002], [62015.9, 0.004], [62920.3, 0.0], [63302.0, 0.015], [63583.9, 29.373], [63953.9, 0.008], [64475.6, 0.002], [64477.3, 0.007], [64478.6, 2.33], [64479.6, 0.013], [64480.0, 15.286], [64484.4, 0.075], [64486.7, 0.015], [64491.4, 0.02], [64493.7, 5.582], [64498.5, 0.004], [64500.8, 0.042], [64505.5, 2.412], [64507.8, 0.013], [64512.6, 0.001], [64514.9, 0.017], [64519.6, 1.433], [64521.9, 0.015], [64524.9, 0.025], [64526.7, 0.0], [64528.0, 0.116], [64529.0, 0.013], [64564.5, 0.175], [64565.6, 0.015], [64566.0, 0.015], [64571.4, 0.037], [64571.6, 0.001], [64571.7, 0.061], [64572.3, 1.204], [64574.1, 0.048], [64575.9, 0.937], [64576.0, 0.01], [64576.1, 0.003], [64579.0, 0.053], [64580.0, 0.318], [64580.2, 0.116], [64581.1, 0.043], [64586.1, 0.935], [64586.2, 0.562], [64586.7, 0.0], [64586.8, 0.359], [64587.2, 0.224], [64588.2, 0.557], [64588.7, 0.077], [64589.1, 0.151], [64591.9, 0.002], [64592.2, 0.442], [64593.8, 0.126], [64594.0, 0.445], [64594.3, 0.013], [64596.8, 0.003], [64597.4, 0.0], [64597.6, 0.271], [64597.7, 0.001], [64597.9, 0.02], [64598.0, 0.001], [64598.4, 0.001], [64598.5, 0.002], [64598.6, 0.0], [64599.5, 0.922], [64599.6, 0.002], [64599.9, 22.151]], "asks": [[64600.0, 13.515], [64603.8, 0.139], [64605.5, 0.088], [64605.7, 0.142], [64606.8, 0.015], [64609.5, 0.64], [64609.6, 0.881], [64612.6, 0.007], [64612.8, 0.004], [64612.9, 0.002], [64614.2, 0.003], [64614.8, 0.0], [64615.9, 0.002], [64617.2, 0.05], [64618.9, 0.108], [64624.1, 0.05], [64624.7, 2.934], [64624.9, 0.002], [64625.2, 0.155], [64625.3, 0.02], [64625.5, 10.006], [64627.8, 0.0], [64629.4, 0.002], [64630.1, 0.018], [64631.0, 0.093], [64631.1, 3.375], [64632.7, 0.153], [64636.2, 0.039], [64643.9, 0.357], [64653.3, 1.471], [64656.0, 0.951], [64656.4, 0.06], [64657.2, 0.001], [64660.0, 0.257], [64709.9, 0.02], [64719.2, 3.16], [64719.3, 0.088], [64920.7, 0.0], [65246.0, 14.359], [65382.4, 0.769]]}
{"kind": "depth", "E": 1787088315521, "U": 11315917613234, "u": 11315917619286, "recv_ms": 1787088315459, "bids": [[14093.8, 0.784], [14499.9, 2.884], [58139.9, 0.002], [59298.2, 0.002], [61364.1, 0.024], [61364.2, 0.026], [61369.9, 0.002], [62015.9, 0.001], [63599.9, 0.028], [63953.9, 0.008], [64276.9, 0.115], [64542.3, 0.015], [64553.5, 0.032], [64553.6, 0.152], [64576.1, 0.002], [64578.8, 0.091], [64580.6, 0.558], [64580.8, 0.318], [64581.9, 0.061], [64582.4, 0.008], [64582.6, 0.154], [64582.8, 0.018], [64583.1, 0.004], [64585.4, 0.471], [64585.7, 0.928], [64586.1, 0.008], [64586.2, 0.02], [64586.3, 0.547], [64588.1, 2.321], [64592.3, 0.003], [64594.2, 0.834], [64594.3, 0.097], [64595.9, 0.367], [64597.6, 0.187], [64599.9, 22.343]], "asks": [[64603.4, 0.005], [64603.8, 0.129], [64606.8, 0.015], [64611.4, 0.064], [64611.6, 0.71], [64613.0, 3.237], [64613.2, 0.008], [64613.6, 0.0], [64614.0, 0.127], [64615.5, 0.068], [64616.7, 0.636], [64618.0, 0.021], [64618.1, 2.094], [64619.1, 2.323], [64621.1, 0.561], [64622.5, 0.56], [64622.9, 0.483], [64624.7, 2.818], [64625.2, 0.001], [64625.4, 0.155], [64626.2, 0.088], [64627.6, 0.918], [64634.7, 0.002], [64656.9, 3.781], [65191.8, 7.132], [65246.0, 14.359], [65600.0, 70.131]]}
{"kind": "depth", "E": 1787088315725, "U": 11315917625539, "u": 11315917630796, "recv_ms": 1787088315663, "bids": [[1000.0, 35.76], [14093.8, 0.28], [14399.9, 0.196], [14499.9, 3.192], [51679.9, 0.0], [58139.9, 0.002], [61369.9, 0.002], [63594.2, 0.636], [63599.9, 0.008], [63803.3, 30.831], [63932.1, 0.001], [63953.9, 0.01], [64479.3, 0.001], [64485.4, 0.004], [64511.6, 0.002], [64517.7, 0.007], [64543.9, 0.013], [64550.0, 0.245], [64566.3, 0.001], [64566.5, 0.306], [64574.1, 0.04], [64585.9, 0.018], [64586.3, 0.005], [64586.6, 0.002], [64595.3, 0.003], [64597.8, 0.448], [64599.9, 22.313]], "asks": [[64600.0, 13.519], [64602.4, 0.022], [64602.5, 0.078], [64607.0, 0.222], [64611.4, 0.062], [64611.6, 0.691], [64611.7, 0.776], [64617.5, 0.544], [64618.1, 1.837], [64620.6, 0.019], [64624.1, 0.039], [64625.5, 1.361], [64637.4, 2.32], [64643.8, 0.253], [64649.9, 0.787], [64652.7, 0.211], [64656.7, 1.735], [64657.0, 0.01], [64660.0, 0.047], [64676.2, 0.0], [64682.3, 1.099], [64708.6, 0.0], [64714.7, 0.002], [65213.6, 0.765], [65244.1, 0.912], [65246.0, 14.359], [65302.7, 0.066], [65374.5, 0.059], [65446.2, 0.06], [65475.9, 1.768], [65518.0, 0.902], [65589.8, 0.059], [65600.0, 70.111], [65661.5, 0.104], [65733.3, 0.082], [65805.0, 0.06], [65876.8, 6.242], [65891.9, 0.012]]}
{"kind": "depth", "E": 1787088315827, "U": 11315917630846, "u": 11315917636585, "recv_ms": 1787088315764, "bids": [[14093.8, 0.168], [14399.9, 0.448], [14499.9, 3.052], [58139.9, 0.002], [61369.9, 0.002], [62015.9, 0.001], [63810.0, 73.529], [63953.9, 0.008], [64175.9, 0.003], [64566.5, 0.296], [64566.7, 0.016], [64592.0, 0.944], [64593.4, 0.0], [64594.0, 0.448], [64597.5, 0.091], [64597.6, 0.065]], "asks": [[64618.2, 0.395], [64657.0, 0.0], [64657.2, 0.011], [64661.2, 0.064], [65101.8, 4.676], [65246.0, 14.359], [65324.4, 1.246]]}
{"kind": "depth", "E": 1787088315929, "U": 11315917636694, "u": 11315917642583, "recv_ms": 1787088315866, "bids": [[14093.8, 0.042], [14399.9, 0.672], [14499.9, 2.954], [58139.9, 0.002], [61369.9, 0.002], [62015.9, 0.004], [62970.4, 7.618], [63178.7, 0.0], [63599.9, 0.028], [63674.4, 3.294], [63818.7, 11.392], [63824.7, 1.566], [63953.9, 0.008], [64240.0, 0.462], [64247.4, 0.493], [64272.4, 0.047], [64276.9, 0.125], [64490.0, 1.087], [64490.7, 0.004], [64583.0, 0.001], [64584.5, 0.007], [64594.0, 0.445], [64594.2, 0.837], [64595.4, 0.39], [64597.1, 0.394], [64597.5, 0.007], [64597.9, 0.02], [64599.9, 22.296]], "asks": [[64600.0, 14.766], [64601.0, 0.0], [64602.9, 0.022], [64604.2, 0.774], [64605.4, 0.304], [64606.6, 0.447], [64609.5, 0.082], [64610.9, 0.159], [64611.4, 0.0], [64612.6, 0.0], [64612.9, 0.544], [64613.1, 0.04], [64614.8, 0.016], [64617.3, 0.012], [64618.1, 1.168], [64619.3, 0.081], [64619.6, 0.034], [64620.6, 0.008], [64624.7, 0.064], [64625.7, 0.003], [64633.4, 2.508], [64637.5, 0.0], [64639.8, 0.203], [64640.2, 0.63], [64643.9, 0.157], [64646.2, 0.214], [64780.7, 0.001], [64781.4, 0.003], [64921.6, 0.082], [64923.9, 0.201], [65116.8, 1.262], [65246.0, 14.359], [65497.8, 0.914], [65536.6, 0.761], [65600.0, 70.131]]}
{"kind": "depth", "E": 1787088316031, "U": 11315917642731, "u": 11315917648151, "recv_ms": 1787088315967, "bids": [[1000.0, 35.76], [14093.8, 0.0], [14399.9, 0.994], [14499.9, 2.674], [58139.9, 0.002], [61369.9, 0.002], [62015.9, 0.001], [63599.9, 0.008], [63953.9, 0.008], [64175.9, 0.002], [64430.0, 0.676], [64532.2, 0.001], [64538.5, 0.048], [64538.6, 0.214], [64545.0, 0.285], [64553.9, 0.002], [64554.0, 0.08], [64564.8, 0.034], [64564.9, 0.016], [64565.0, 0.002], [64566.7, 0.006], [64566.9, 0.01], [64568.2, 0.071], [64568.3, 0.001], [64568.4, 0.313], [64580.8, 0.319], [64585.0, 35.977], [64586.3, 0.005], [64593.8, 0.119], [64597.4, 0.084], [64597.9, 0.03], [64599.9, 21.991]], "asks": [[64600.0, 14.905], [64604.8, 0.111], [64607.0, 0.222], [64608.6, 1.161], [64615.7, 2.478], [64618.7, 0.327], [64620.6, 0.101], [64622.8, 0.413], [64657.2, 0.001], [64657.3, 0.01], [64662.0, 0.033], [65246.0, 13.778], [65600.0, 70.111], [65885.7, 0.022], [67157.3, 0.035], [68411.3, 1.46]]}
{"kind": "depth", "E": 1787088316133, "U": 11315917648226, "u": 11315917654532, "recv_ms": 1787088316069, "bids": [[14399.9, 1.344], [14499.9, 2.324], [58139.9, 0.002], [59135.7, 0.011], [63200.0, 22.531], [63686.8, 0.785], [63792.4, 0.235], [63953.9, 0.008], [64241.5, 0.0], [64243.0, 0.205], [64554.0, 0.002], [64554.1, 0.115], [64565.0, 0.621], [64571.8, 0.12], [64572.4, 0.719], [64580.2, 0.0], [64580.6, 0.117], [64581.4, 0.018], [64581.6, 0.002], [64588.3, 0.704], [64593.8, 0.022], [64596.8, 0.0], [64597.3, 0.009], [64597.9, 0.03], [64598.2, 0.084], [64599.9, 22.487]], "asks": [[64600.0, 14.82], [64600.3, 0.085], [64604.3, 0.142], [64608.7, 0.037], [64609.4, 0.002], [64611.0, 1.395], [64618.4, 0.011], [64623.5, 0.009], [64623.7, 0.117], [64625.8, 0.787], [64629.6, 1.885], [64629.7, 0.003], [64636.2, 0.067], [65032.2, 0.001], [65246.0, 13.778], [65324.1, 0.77], [65472.1, 0.29]]}
{"kind": "depth", "E": 1787088316235, "U": 11315917654570, "u": 11315917663997, "recv_ms": 1787088316173, "bids": [[1000.0, 35.76], [14399.9, 1.708], [14499.9, 1.96], [58139.9, 0.002], [61369.9, 0.002], [62015.9, 0.004], [63953.9, 0.008], [64175.9, 0.001], [64276.9, 0.125], [64539.4, 0.003], [64552.3, 0.066], [64566.9, 0.0], [64567.0, 0.01], [64597.2, 0.004], [64599.9, 22.539]], "asks": [[64600.2, 0.001], [64600.3, 0.084], [64625.2, 0.155], [64625.4, 0.001], [64643.0, 0.008], [64645.2, 0.0], [64657.3, 0.0], [64657.5, 0.01], [65224.4, 0.004], [65246.0, 13.778], [65288.8, 0.376], [65421.2, 0.0]]}
{"kind": "depth", "E": 1787088316337, "U": 11315917664117, "u": 11315917670340, "recv_ms": 1787088316274, "bids": [[1000.0, 35.76], [14399.9, 2.072], [14499.9, 1.596], [51678.0, 0.004], [51680.0, 1.939], [58139.9, 0.002], [61369.9, 0.002], [62015.9, 0.001], [63469.0, 0.265], [63599.9, 0.028], [63953.9, 0.008], [64523.9, 0.017], [64524.6, 1.501], [64528.3, 34.349], [64528.6, 1.001], [64529.9, 5.959], [64551.2, 0.016], [64553.3, 1.2], [64567.0, 0.0], [64567.2, 0.01], [64567.4, 0.0], [64580.1, 5.803], [64582.1, 1.076], [64593.8, 0.02], [64597.0, 0.902], [64597.9, 0.03], [64599.9, 22.543]], "asks": [[64600.0, 14.815], [64617.5, 0.002], [64618.0, 0.563], [64623.6, 0.029], [64625.2, 0.001], [64625.4, 0.155], [64639.6, 1.474], [64657.5, 0.0], [64657.6, 0.04], [64659.6, 2.024], [64659.7, 0.001], [64778.8, 0.0], [64923.0, 0.008], [65246.0, 13.778], [65343.3, 13.635], [65360.1, 63.091], [65382.6, 0.78], [65600.0, 70.131]]}
{"kind": "depth", "E": 1787088316439, "U": 11315917670435, "u": 11315917677155, "recv_ms": 1787088316381, "bids": [[14399.9, 2.422], [14499.9, 1.246], [51675.0, 0.0], [58139.9, 0.002], [62015.9, 0.004], [63792.4, 0.735], [63953.9, 0.008], [64175.9, 0.0], [64276.9, 0.124], [64496.2, 0.001], [64498.3, 0.75], [64521.7, 33.888], [64524.6, 6.397], [64524.9, 0.007], [64528.3, 0.002], [64529.2, 0.055], [64529.9, 1.051], [64532.6, 6.021], [64533.6, 0.002], [64554.8, 6.039], [64555.2, 3.522], [64571.3, 0.965], [64594.3, 0.013], [64597.9, 0.02], [64598.7, 0.084]], "asks": [[64600.1, 0.005], [64600.2, 0.0], [64600.3, 0.001], [64600.7, 0.015], [64625.3, 0.174], [64625.4, 0.989], [64641.5, 3.656], [64657.6, 0.03], [64657.7, 1.014], [64658.5, 0.454], [64664.2, 6.015], [64664.6, 0.011], [64665.8, 0.003], [64666.3, 4.663], [64666.7, 30.401], [64668.8, 0.026], [64668.9, 0.001], [64673.1, 0.344], [64691.3, 0.44], [64692.0, 0.064], [65224.2, 0.0], [65246.0, 13.778]]}
{"kind": "depth", "E": 1787088316541, "U": 11315917677280, "u": 11315917683235, "recv_ms": 1787088316478, "bids": [[1000.0, 35.76], [14399.9, 2.786], [14497.6, 0.518], [14499.9, 0.896], [58139.9, 0.002], [60782.9, 1.973], [61369.9, 0.002], [62015.9, 0.001], [63598.1, 0.001], [63599.9, 0.008], [63908.7, 0.859], [63953.9, 0.008], [64276.9, 0.125], [64448.9, 0.005], [64490.7, 0.001], [64490.8, 1.241], [64521.7, 0.0], [64523.9, 33.905], [64542.3, 0.0], [64554.1, 0.037], [64555.6, 2.27], [64555.7, 0.586], [64559.3, 0.003], [64575.2, 0.001], [64577.7, 0.006], [64577.8, 0.016], [64583.1, 0.004], [64594.6, 0.004], [64595.9, 0.382], [64597.9, 0.03], [64599.2, 0.085], [64599.9, 22.544]], "asks": [[64600.0, 14.806], [64615.5, 0.068], [64625.3, 0.02], [64625.5, 1.515], [64640.3, 1.21], [64662.9, 1.742], [64666.3, 0.117], [64666.7, 0.03], [64669.8, 5.784], [64671.1, 31.455], [64923.0, 0.009], [65246.0, 13.778], [65312.1, 0.857], [65343.5, 0.917], [65375.2, 2.297], [65447.2, 0.763], [65489.3, 85.068], [65517.3, 0.228], [65600.0, 70.111]]}
{"kind": "depth", "E": 1787088316643, "U": 11315917683318, "u": 11315917688311, "recv_ms": 1787088316580, "bids": [[1000.0, 35.76], [14399.9, 3.136], [14497.6, 0.406], [14499.9, 0.658], [51679.9, 0.0], [58139.9, 0.002], [58973.3, 0.002], [61369.9, 0.002], [63876.4, 0.783], [63953.9, 0.008], [64500.3, 10.011], [64542.3, 0.015], [64565.0, 0.002], [64567.2, 0.0], [64567.3, 0.085], [64572.4, 0.1], [64575.2, 0.0], [64580.1, 5.919], [64580.6, 0.001], [64581.1, 0.6], [64581.5, 0.002], [64581.9, 0.062], [64586.0, 1.829], [64586.1, 0.008], [64586.5, 0.013], [64586.6, 0.002], [64588.3, 0.704], [64595.9, 0.367], [64599.9, 22.545]], "asks": [[64600.0, 14.888], [64601.2, 0.013], [64602.9, 0.002], [64603.0, 0.007], [64603.1, 0.085], [64604.6, 0.217], [64609.4, 0.001], [64611.8, 0.008], [64616.8, 0.633], [64617.5, 0.002], [64618.0, 0.563], [64618.5, 0.0], [64619.3, 1.007], [64619.8, 0.19], [64621.3, 0.0], [64622.0, 0.001], [64622.2, 0.557], [64623.3, 2.334], [64624.2, 0.066], [64624.7, 0.0], [64625.3, 0.027], [64625.8, 0.168], [64626.8, 0.002], [64657.7, 1.004], [64657.8, 0.01], [64694.7, 4.731], [64696.5, 11.844], [65246.0, 13.778], [65489.3, 84.611], [65891.9, 0.015]]}
{"kind": "depth", "E": 1787088316847, "U": 11315917693055, "u": 11315917697767, "recv_ms": 1787088316786, "bids": [[1000.0, 35.76], [14299.9, 0.056], [14399.9, 3.738], [14497.6, 0.028], [14499.9, 0.378], [51680.0, 1.939], [58139.9, 0.002], [61369.9, 0.002], [62015.9, 0.001], [62070.2, 1.455], [63599.9, 0.008], [63705.8, 0.001], [63706.4, 1.096], [63857.0, 0.393], [63864.2, 0.0], [63953.7, 0.547], [63953.9, 0.008], [64276.9, 0.125], [64557.5, 0.002], [64565.3, 0.007], [64567.0, 0.002], [64567.1, 0.017], [64567.2, 0.002], [64570.5, 2.423], [64570.6, 0.147], [64570.7, 1.344], [64571.3, 0.0], [64578.6, 2.32], [64585.6, 0.234], [64586.9, 0.0], [64598.3, 0.003]], "asks": [[64600.0, 14.315], [64601.0, 0.002], [64603.1, 0.084], [64604.0, 0.128], [64609.5, 0.624], [64612.9, 0.002], [64668.8, 6.001], [64668.9, 30.372], [64669.8, 0.0], [64671.1, 1.084], [64802.1, 0.6], [65246.0, 13.778], [65353.7, 4.586], [65600.0, 70.111], [65891.9, 0.018], [67119.4, 1.343]]}
{"kind": "depth", "E": 1787088316949, "U": 11315917697908, "u": 11315917703163, "recv_ms": 1787088316885, "bids": [[1000.0, 35.76], [14299.9, 0.266], [14399.9, 3.682], [14497.6, 0.0], [14499.9, 0.252], [58139.9, 0.002], [61369.9, 0.002], [62015.9, 0.004], [63746.8, 0.783], [63842.3, 13.189], [63953.9, 0.008], [64247.4, 0.001], [64252.1, 0.494], [64556.9, 0.005], [64565.3, 0.003], [64599.9, 22.557]], "asks": [[64657.8, 0.0], [64657.9, 6.723], [65246.0, 13.778], [65676.1, 5.326]]}
{"kind": "depth", "E": 1787088317051, "U": 11315917703196, "u": 11315917710112, "recv_ms": 1787088316987, "bids": [[14299.9, 0.504], [14399.9, 3.556], [14499.9, 0.14], [58139.9, 0.002], [61369.9, 0.004], [62015.9, 0.001], [63953.9, 0.008], [64454.1, 2.484], [64556.9, 0.001], [64578.6, 2.319], [64584.2, 0.003], [64586.1, 0.008], [64588.3, 0.709]], "asks": [[65246.0, 13.778], [65368.7, 0.917], [65407.5, 0.23], [65762.8, 0.759], [71060.0, 0.0]]}
{"kind": "depth", "E": 1787088317153, "U": 11315917710188, "u": 11315917715790, "recv_ms": 1787088317090, "bids": [[1000.0, 35.76], [14299.9, 0.728], [14399.9, 3.458], [14499.9, 0.014], [51675.0, 0.0], [51680.0, 1.939], [58139.9, 0.002], [58810.8, 0.002], [61369.9, 0.004], [63599.9, 0.028], [63726.3, 1.959], [63879.9, 0.236], [63953.9, 0.008], [64083.1, 0.001], [64276.9, 0.125], [64565.3, 0.007], [64565.8, 0.64], [64567.4, 0.0], [64567.5, 0.011], [64571.3, 0.995], [64573.2, 0.622], [64580.1, 5.803], [64581.0, 0.136], [64581.1, 0.043], [64582.0, 0.56], [64582.6, 0.0], [64582.7, 0.003], [64584.2, 0.002], [64587.1, 0.002], [64588.3, 0.704], [64599.9, 22.602]], "asks": [[64602.0, 0.108], [64602.2, 0.025], [64610.1, 0.319], [64619.2, 1.805], [64626.5, 0.629], [65246.0, 13.778], [65360.1, 62.328], [65600.0, 70.131], [65698.2, 1.53], [65805.3, 0.0]]}
{"kind": "depth", "E": 1787088317255, "U": 11315917715806, "u": 11315917721035, "recv_ms": 1787088317190, "bids": [[1000.0, 35.76], [14299.9, 1.078], [14399.9, 3.122], [14499.9, 0.0], [51676.0, 0.0], [58139.9, 0.002], [61364.1, 0.022], [61364.2, 0.026], [61369.9, 0.006], [62015.9, 0.004], [63857.0, 1.331], [63953.9, 0.008], [63964.7, 7.689], [64557.5, 0.006], [64565.3, 0.003], [64573.2, 0.003], [64579.4, 0.002], [64582.5, 0.329], [64582.6, 0.154], [64587.0, 0.033], [64587.1, 0.001], [64599.9, 22.605]], "asks": [[64625.7, 0.005], [64628.1, 0.034], [65246.0, 13.778], [65375.2, 3.06], [65392.4, 21.882], [65553.9, 29.582]]}
{"kind": "depth", "E": 1787088317357, "U": 11315917721288, "u": 11315917727563, "recv_ms": 1787088317294, "bids": [[14299.9, 1.428], [14399.9, 2.772], [58139.9, 0.002], [62015.9, 0.001], [63599.9, 0.008], [63777.7, 30.499], [63953.9, 0.008], [64454.2, 1.751], [64557.5, 0.002], [64565.3, 0.007], [64582.5, 0.483], [64582.6, 0.0], [64582.9, 0.013], [64585.0, 36.502], [64585.1, 4.312], [64587.7, 0.649]], "asks": [[64601.6, 0.094], [64657.9, 6.713], [64658.0, 0.017], [64739.2, 0.686], [64739.3, 0.028], [65246.0, 13.778], [65407.5, 0.489], [65600.0, 70.111], [65611.6, 9.461], [65827.4, 2.125]]}
{"kind": "depth", "E": 1787088317459, "U": 11315917727700, "u": 11315917734080, "recv_ms": 1787088317397, "bids": [[1000.0, 35.76], [14299.9, 1.792], [14399.9, 2.408], [58139.9, 0.002], [61369.9, 0.006], [62015.9, 0.004], [63856.5, 0.003], [63932.2, 0.0], [63953.9, 0.008], [63986.2, 0.701], [64262.1, 2.727], [64276.9, 0.125], [64434.2, 0.0], [64435.1, 0.942], [64437.9, 4.409], [64454.9, 5.689], [64539.4, 0.006], [64542.3, 0.0], [64552.3, 0.063], [64571.7, 0.004], [64573.2, 0.06], [64580.2, 0.0], [64581.0, 0.02], [64581.2, 0.557], [64581.7, 0.116], [64582.0, 0.003], [64584.7, 0.003], [64586.0, 0.902], [64586.1, 0.008], [64587.7, 1.576], [64587.8, 0.542], [64588.3, 0.162], [64590.8, 0.086], [64594.3, 0.003], [64595.0, 0.067], [64595.9, 0.382], [64596.3, 0.002], [64596.8, 0.006], [64599.7, 0.085]], "asks": [[64600.0, 14.303], [64601.6, 0.01], [64605.0, 0.095], [64605.8, 0.214], [64618.0, 0.021], [64618.9, 0.65], [64619.3, 0.081], [64620.1, 1.034], [64621.3, 0.0], [64622.2, 0.0], [64623.0, 0.831], [64623.7, 0.001], [64624.2, 0.009], [64624.7, 0.116], [64625.0, 0.14], [64633.3, 0.093], [64643.0, 0.008], [64739.2, 1.405], [64739.3, 5.434], [64750.1, 0.003], [64756.2, 2.1], [64756.3, 10.424], [64757.2, 0.0], [64793.7, 0.053], [64908.0, 2.309], [65246.0, 13.778], [65569.0, 2.832], [65611.6, 7.939], [65740.7, 7.216]]}
{"kind": "depth", "E": 1787088317663, "U": 11315917740267, "u": 11315917745366, "recv_ms": 1787088317600, "bids": [[14299.9, 2.506], [14399.9, 1.694], [51679.9, 0.0], [51680.0, 1.939], [58139.9, 0.004], [58648.3, 0.002], [62015.9, 0.001], [62984.9, 1.436], [63953.9, 0.008], [64276.9, 0.28], [64565.8, 0.021], [64571.5, 0.057], [64572.3, 1.204], [64580.1, 5.919], [64580.9, 0.005], [64581.7, 0.0], [64584.5, 0.0], [64585.4, 0.478], [64586.0, 1.829], [64586.2, 0.0], [64586.7, 0.0], [64586.8, 0.359], [64587.8, 0.542], [64590.0, 0.13], [64594.0, 0.465], [64597.9, 0.03], [64599.9, 22.606]], "asks": [[64600.0, 13.63], [64604.0, 0.127], [64604.2, 0.775], [64609.4, 0.017], [64614.8, 0.0], [64616.8, 0.633], [64617.5, 0.544], [64618.5, 0.926], [64618.9, 0.108], [64619.2, 1.186], [64620.1, 0.108], [64623.3, 2.391], [64625.0, 0.083], [64626.5, 0.01], [64923.0, 0.163], [65246.0, 13.778], [65633.6, 3.044], [65740.7, 2.962], [65762.8, 2.885], [65891.9, 0.021]]}
{"kind": "depth", "E": 1787088317765, "U": 11315917745505, "u": 11315917751637, "recv_ms": 1787088317701, "bids": [[1000.0, 35.76], [14299.9, 2.856], [14399.9, 1.344], [51680.0, 1.939], [58139.9, 0.002], [61369.9, 0.006], [62015.9, 0.004], [63577.2, 9.115], [63599.9, 0.008], [63867.7, 4.457], [63953.9, 0.008], [64276.9, 0.27], [64379.2, 0.0], [64409.4, 3.023], [64555.7, 0.586], [64565.3, 0.007], [64585.0, 36.509], [64585.4, 0.471], [64590.0, 0.129], [64594.2, 0.838], [64597.9, 0.03], [64599.7, 0.002], [64599.9, 22.606]], "asks": [[64601.5, 0.084], [64617.5, 0.002], [64618.0, 0.563], [64618.5, 0.0], [64619.3, 1.007], [64623.3, 2.334], [64624.3, 0.072], [64629.4, 0.004], [65246.0, 13.778], [65392.4, 21.654], [65600.0, 70.111], [65762.8, 5.011]]}
{"kind": "depth", "E": 1787088317867, "U": 11315917751824, "u": 11315917757918, "recv_ms": 1787088317803, "bids": [[1000.0, 35.76], [14299.9, 3.22], [14399.9, 0.98], [58139.9, 0.002], [62015.9, 0.001], [63947.2, 0.0], [63951.1, 0.387], [63953.9, 0.008], [64011.9, 3.48], [64582.3, 0.003], [64594.2, 0.837], [64599.7, 0.001]], "asks": [[64616.9, 1.268], [64625.3, 0.027], [64625.5, 1.515], [64627.0, 0.003], [64908.0, 2.155], [65246.0, 13.778], [65349.9, 0.902], [65521.6, 39.399], [65569.1, 0.723], [65762.8, 7.137], [67184.0, 0.641]]}
{"kind": "depth", "E": 1787088317969, "U": 11315917757989, "u": 11315917763243, "recv_ms": 1787088317907, "bids": [[14299.9, 3.584], [14399.9, 0.616], [58139.9, 0.002], [62015.9, 0.004], [63598.6, 1.122], [63599.9, 0.028], [63953.9, 0.008], [64252.1, 0.002], [64255.1, 0.492], [64542.3, 0.0], [64595.9, 0.382], [64597.9, 0.02]], "asks": [[64625.5, 1.361], [64625.6, 0.477], [65246.0, 13.778], [65246.2, 0.536], [65600.0, 70.131]]}
{"kind": "depth", "E": 1787088318173, "U": 11315917768300, "u": 11315917773453, "recv_ms": 1787088318110, "bids": [[1000.0, 35.76], [14199.9, 0.308], [14299.9, 3.668], [14399.9, 0.224], [58139.9, 0.002], [61369.9, 0.006], [62015.9, 0.001], [63377.3, 5.675], [63599.9, 0.008], [63727.2, 0.023], [63953.9, 0.008], [64565.0, 0.002], [64572.3, 1.204], [64580.1, 5.803], [64580.6, 0.117], [64580.9, 0.005], [64581.2, 0.0], [64581.9, 0.618], [64582.3, 0.002], [64585.7, 0.002], [64585.9, 0.003], [64592.4, 0.018], [64594.4, 0.296], [64595.5, 0.0], [64597.9, 0.02], [64598.5, 0.006], [64599.2, 0.001], [64599.9, 22.606]], "asks": [[64600.0, 14.32], [64601.1, 0.085], [64602.0, 0.089], [64602.2, 0.002], [64602.4, 0.002], [64602.5, 0.055], [64615.0, 0.902], [64618.3, 0.019], [64618.4, 0.011], [64622.2, 0.557], [64623.0, 0.274], [64623.7, 0.117], [64624.7, 0.0], [64625.7, 0.005], [64923.0, 0.317], [65246.0, 13.778], [65536.7, 0.114], [65600.0, 70.111]]}
{"kind": "depth", "E": 1787088318275, "U": 11315917773605, "u": 11315917782235, "recv_ms": 1787088318212, "bids": [[14199.9, 0.56], [14299.9, 3.528], [14399.9, 0.112], [51680.0, 1.939], [58139.9, 0.002], [61369.9, 0.006], [62015.9, 0.004], [63088.8, 0.282], [63617.7, 0.785], [63953.9, 0.008], [64272.5, 0.012], [64275.8, 0.109], [64276.9, 0.29], [64524.9, 0.025], [64582.8, 0.0], [64588.8, 0.325], [64597.9, 0.02], [64599.9, 22.413]], "asks": [[64600.0, 14.32], [64609.4, 0.001], [64614.8, 0.016], [64630.7, 0.017], [64658.0, 0.007], [64658.1, 0.33], [64781.4, 0.0], [64781.5, 0.003], [64928.4, 0.002], [64933.3, 0.139], [65246.0, 13.778], [65246.5, 2.302], [65633.6, 4.566], [65891.9, 0.024]]}
{"kind": "depth", "E": 1787088318377, "U": 11315917782280, "u": 11315917788503, "recv_ms": 1787088318313, "bids": [[1000.0, 35.76], [14199.9, 0.798], [14299.9, 3.402], [14399.9, 0.0], [58139.9, 0.002], [61548.2, 0.1], [61554.1, 0.039], [62015.9, 0.001], [63391.9, 0.741], [63599.9, 0.028], [63953.9, 0.008], [64276.9, 0.27], [64570.5, 2.425], [64580.5, 0.163], [64585.7, 0.001], [64589.6, 0.071], [64597.9, 0.02], [64598.9, 0.057], [64599.9, 22.393]], "asks": [[64625.4, 0.989], [64625.5, 1.515], [64625.6, 0.323], [64677.6, 0.005], [64714.3, 0.0], [64721.2, 0.002], [64721.3, 0.013], [65177.1, 0.001], [65183.2, 0.017], [65246.0, 13.778], [65600.0, 70.131], [65740.7, 0.836], [67620.1, 0.0], [67626.5, 0.04]]}
{"kind": "depth", "E": 1787088318479, "U": 11315917788676, "u": 11315917795459, "recv_ms": 1787088318417, "bids": [[1000.0, 35.76], [14199.9, 1.162], [14299.9, 3.038], [58139.9, 0.002], [61369.9, 0.006], [62015.9, 0.004], [63302.0, 0.003], [63577.2, 8.644], [63648.5, 45.791], [63953.9, 0.008], [64015.7, 0.0], [64021.7, 0.016], [64175.7, 0.046], [64181.8, 0.089], [64336.2, 0.0], [64342.2, 0.447], [64497.0, 0.025], [64503.1, 0.006], [64549.2, 0.0], [64549.3, 0.039], [64577.8, 0.014], [64584.4, 0.023], [64585.0, 36.502], [64585.7, 0.002], [64586.0, 0.902], [64586.5, 0.94], [64587.5, 0.496], [64589.6, 0.07], [64590.3, 0.002], [64591.9, 0.001], [64592.3, 0.003], [64594.6, 0.088], [64595.0, 0.151], [64597.9, 0.02], [64598.2, 0.084], [64598.7, 0.0], [64599.9, 20.942]], "asks": [[64600.2, 0.001], [64600.3, 0.084], [64605.0, 0.011], [64610.1, 0.318], [64617.5, 0.002], [64618.0, 0.021], [64618.9, 0.65], [64619.3, 0.081], [64619.9, 1.087], [64622.2, 0.0], [64622.8, 0.97], [64623.7, 0.001], [64624.3, 0.188], [64625.5, 1.515], [64636.2, 0.039], [64690.7, 0.004], [64696.8, 0.006], [64852.4, 0.002], [64858.5, 0.004], [65014.6, 0.018], [65020.7, 0.252], [65246.0, 13.782], [65553.9, 29.239], [65762.8, 9.262]]}
{"kind": "depth", "E": 1787088318581, "U": 11315917795504, "u": 11315917800656, "recv_ms": 1787088318517, "bids": [[14199.9, 1.512], [14299.9, 2.688], [51680.0, 1.943], [58139.9, 0.002], [63308.0, 0.81], [63599.9, 0.008], [63727.8, 0.788], [63777.7, 30.264], [63953.9, 0.008], [64276.9, 0.279], [64535.8, 0.005], [64536.2, 0.001], [64536.8, 0.013], [64537.2, 0.0], [64537.4, 0.0], [64553.2, 1.202], [64553.5, 0.0], [64554.1, 0.005], [64554.5, 0.003], [64554.7, 1.238], [64568.2, 0.001], [64568.6, 0.038], [64568.7, 0.06], [64568.8, 1.629], [64569.0, 0.008], [64570.3, 0.012], [64570.4, 1.094], [64570.5, 2.355], [64570.6, 0.077], [64570.7, 1.244], [64570.8, 0.471], [64571.0, 0.327], [64571.1, 0.0], [64571.9, 0.01], [64572.4, 0.0], [64579.2, 0.06], [64583.1, 0.004], [64585.7, 0.001], [64588.8, 0.255], [64588.9, 0.157], [64589.0, 0.438], [64589.1, 0.081], [64589.2, 0.173], [64589.3, 0.008], [64589.5, 0.001], [64589.6, 0.0], [64589.7, 0.001], [64590.6, 0.001], [64590.9, 0.0], [64591.0, 0.903], [64591.1, 0.032], [64591.4, 0.309], [64591.6, 0.013], [64592.0, 0.912], [64592.6, 0.312], [64592.9, 0.0], [64594.4, 0.298], [64597.9, 0.03], [64598.3, 0.001]], "asks": [[64603.8, 0.003], [64603.9, 0.106], [64604.0, 0.008], [64604.1, 0.0], [64604.2, 0.255], [64604.3, 0.009], [64604.4, 0.143], [64604.5, 0.003], [64604.6, 0.084], [64605.3, 0.0], [64605.7, 0.094], [64606.0, 0.013], [64606.3, 0.002], [64606.6, 0.393], [64606.9, 0.0], [64607.0, 0.002], [64615.5, 0.068], [64617.5, 0.544], [64618.9, 0.108], [64621.5, 0.392], [64622.3, 0.217], [64622.4, 1.692], [64622.5, 0.135], [64622.6, 0.128], [64622.7, 3.444], [64622.8, 0.837], [64622.9, 0.329], [64623.0, 0.015], [64623.1, 0.062], [64625.5, 1.361], [64625.7, 0.159], [64629.5, 1.907], [64629.6, 0.0], [64636.7, 0.125], [64637.0, 2.238], [64637.3, 0.002], [64637.7, 0.008], [64638.0, 0.981], [64638.8, 0.0], [64641.5, 3.509], [64654.5, 0.002], [64654.8, 0.002], [64655.1, 0.428], [64655.4, 0.002], [64655.8, 0.028], [64923.0, 0.316], [65246.0, 13.778], [65485.8, 0.763], [65600.0, 70.111]]}
{"kind": "depth", "E": 1787088318683, "U": 11315917800735, "u": 11315917807126, "recv_ms": 1787088318620, "bids": [[1000.0, 35.76], [14199.9, 1.876], [14299.9, 2.324], [51679.9, 0.0], [51680.0, 1.939], [58139.9, 0.002], [61369.9, 0.006], [62015.9, 0.001], [63953.9, 0.008], [64276.9, 0.28], [64523.9, 0.017], [64526.1, 33.766], [64570.6, 0.007], [64579.2, 0.059], [64583.8, 0.002], [64584.0, 0.126], [64586.0, 0.951], [64589.1, 0.011], [64590.5, 0.306], [64590.7, 0.07], [64590.9, 0.1], [64591.0, 1.003], [64591.2, 0.137], [64591.3, 0.072], [64591.4, 0.409], [64592.3, 0.002], [64599.9, 20.943]], "asks": [[64600.6, 0.027], [64600.9, 0.023], [64603.8, 0.002], [64604.0, 0.007], [64604.3, 0.007], [64604.4, 0.003], [64606.7, 0.002], [64607.1, 0.349], [64607.3, 0.602], [64607.4, 0.244], [64607.5, 0.262], [64607.7, 0.141], [64607.9, 0.139], [64609.4, 0.017], [64614.8, 0.0], [64622.8, 0.697], [64624.8, 0.595], [64625.3, 0.287], [64625.7, 0.159], [64625.9, 0.079], [64626.5, 0.136], [64626.7, 0.259], [64626.9, 0.231], [64627.1, 0.151], [64627.3, 0.815], [64637.0, 1.672], [64666.7, 30.916], [64668.9, 0.001], [64923.0, 0.317], [65246.0, 13.778], [65569.0, 3.175]]}
{"kind": "depth", "E": 1787088318785, "U": 11315917807344, "u": 11315917812844, "recv_ms": 1787088318722, "bids": [[1000.0, 35.76], [14199.9, 2.226], [14299.9, 1.974], [58139.9, 0.002], [61369.9, 0.006], [62015.9, 0.004], [62970.4, 7.142], [63599.9, 0.028], [63648.5, 44.692], [63663.2, 1.125], [63953.9, 0.008], [64454.9, 2.319], [64455.2, 3.451], [64486.9, 0.003], [64524.6, 1.501], [64524.9, 0.007], [64527.0, 5.311], [64527.5, 0.018], [64539.4, 0.003], [64554.6, 0.046], [64556.2, 0.033], [64557.2, 0.097], [64583.8, 0.001], [64586.9, 0.001], [64590.6, 0.141], [64590.9, 0.2], [64591.2, 0.237], [64591.8, 0.858], [64592.7, 0.034], [64593.8, 0.007], [64599.9, 20.956]], "asks": [[64600.1, 0.005], [64600.2, 0.0], [64600.3, 0.001], [64604.1, 0.001], [64605.0, 0.012], [64605.4, 0.461], [64605.7, 0.142], [64606.7, 0.056], [64607.2, 0.265], [64607.5, 0.522], [64607.8, 0.127], [64607.9, 0.272], [64623.5, 0.057], [64624.5, 0.054], [64626.6, 8.609], [64627.0, 0.263], [64627.2, 0.134], [64627.3, 0.948], [64641.3, 0.049], [64642.2, 0.483], [64643.0, 0.005], [64645.3, 0.018], [64666.3, 4.74], [64668.8, 0.026], [64677.6, 0.002], [64739.2, 0.686], [64739.3, 5.434], [65246.0, 13.778], [65600.0, 70.131]]}
{"kind": "depth", "E": 1787088318887, "U": 11315917813140, "u": 11315917819192, "recv_ms": 1787088318825, "bids": [[14199.9, 2.59], [14299.9, 1.61], [58139.9, 0.002], [61369.9, 0.008], [62015.9, 0.001], [63302.0, 0.0], [63953.9, 0.008], [64276.9, 0.27], [64455.2, 3.539], [64463.3, 3.118], [64469.4, 1.152], [64478.8, 3.998], [64480.0, 15.201], [64556.5, 0.032], [64556.8, 0.04], [64557.5, 0.034], [64577.4, 0.452], [64577.9, 0.0], [64579.7, 0.0], [64580.1, 5.805], [64584.4, 0.016], [64585.0, 36.49], [64585.4, 0.478], [64586.6, 0.002], [64586.9, 0.0], [64587.8, 0.542], [64590.7, 0.14], [64591.1, 0.102], [64591.5, 0.074], [64592.1, 1.595], [64592.4, 0.05], [64593.0, 0.04], [64597.9, 0.02], [64598.9, 0.141], [64599.9, 20.956]], "asks": [[64600.0, 14.941], [64600.4, 0.032], [64600.7, 0.038], [64602.7, 0.004], [64604.2, 0.254], [64605.4, 0.509], [64606.0, 0.08], [64606.3, 0.06], [64606.9, 0.147], [64607.3, 0.721], [64607.7, 0.295], [64609.4, 0.543], [64609.5, 0.075], [64609.6, 0.796], [64610.8, 0.51], [64610.9, 0.097], [64612.9, 0.094], [64614.8, 0.016], [64617.5, 0.002], [64618.0, 0.563], [64618.5, 0.926], [64619.9, 0.161], [64623.2, 0.048], [64623.8, 1.937], [64624.1, 0.097], [64626.3, 0.147], [64626.7, 0.378], [64627.1, 0.305], [64627.6, 2.643], [64628.9, 10.002], [64632.0, 0.007], [64632.1, 0.04], [64638.6, 0.061], [64640.9, 0.05], [64641.6, 0.117], [64641.9, 0.06], [64719.3, 0.002], [64719.5, 0.104], [64739.3, 0.028], [64739.4, 5.406], [65000.0, 118.178], [65246.0, 13.778], [65295.5, 14.098]]}
{"kind": "depth", "E": 1787088318989, "U": 11315917819286, "u": 11315917825136, "recv_ms": 1787088318926, "bids": [[1000.0, 35.76], [14199.9, 2.94], [14299.9, 1.26], [58139.9, 0.002], [63599.9, 0.008], [63680.8, 80.39], [63822.6, 5.294], [63844.1, 0.548], [63953.9, 0.009], [64255.1, 0.0], [64256.8, 0.519], [64577.4, 0.451], [64579.7, 0.001], [64590.8, 0.156], [64591.0, 1.103], [64597.9, 0.03], [64598.9, 0.057]], "asks": [[64605.4, 0.691], [64607.4, 0.434], [64607.6, 0.134], [64609.4, 0.001], [64609.5, 0.167], [64612.9, 0.544], [64618.5, 0.0], [64619.3, 1.007], [64626.8, 0.192], [64627.0, 0.396], [65246.0, 13.778], [65310.6, 0.805], [65407.5, 0.832], [65600.0, 70.111]]}
{"kind": "depth", "E": 1787088319091, "U": 11315917825281, "u": 11315917832552, "recv_ms": 1787088319028, "bids": [[1000.0, 35.76], [14199.9, 3.304], [14299.9, 0.896], [58139.9, 0.002], [62015.9, 0.004], [63519.3, 6.762], [63598.6, 1.593], [63662.8, 0.0], [63663.2, 2.223], [63953.9, 0.009], [64521.7, 33.765], [64522.3, 0.854], [64526.1, 0.001], [64527.0, 0.299], [64538.4, 0.033], [64539.4, 0.035], [64571.1, 0.07], [64571.3, 1.065], [64571.6, 0.101], [64571.8, 0.22], [64571.9, 0.08], [64573.1, 2.422], [64573.6, 0.102], [64582.5, 0.329], [64588.3, 0.162]], "asks": [[64625.7, 0.005], [64663.7, 0.0], [64664.4, 0.0], [64666.3, 0.117], [64666.7, 0.03], [64671.1, 31.97], [65246.0, 13.778]]}
{"kind": "depth", "E": 1787088319193, "U": 11315917832745, "u": 11315917838499, "recv_ms": 1787088319133, "bids": [[14199.9, 3.654], [14299.9, 0.546], [58139.9, 0.002], [61369.9, 0.008], [62015.9, 0.001], [63534.0, 1.102], [63599.9, 0.028], [63792.4, 1.001], [63810.0, 72.904], [63882.0, 0.8], [63953.9, 0.009], [64262.1, 2.572], [64276.9, 0.28], [64407.7, 0.0], [64432.0, 0.068], [64490.8, 1.238], [64490.9, 2.749], [64521.7, 0.0], [64522.3, 0.845], [64523.9, 33.748], [64524.9, 0.016], [64535.3, 0.003], [64538.7, 0.033], [64539.1, 0.032], [64539.7, 0.72], [64565.0, 0.002], [64571.2, 0.26], [64571.5, 0.157], [64571.8, 0.32], [64572.3, 1.204], [64579.7, 0.0], [64581.6, 0.003], [64584.9, 0.319], [64585.4, 0.471], [64585.5, 0.017], [64590.3, 0.032], [64591.1, 0.073], [64592.4, 0.035], [64595.4, 0.385], [64597.9, 0.03], [64599.9, 21.116]], "asks": [[64600.0, 14.942], [64600.4, 0.116], [64606.6, 0.393], [64610.7, 0.063], [64610.8, 0.448], [64618.4, 0.011], [64622.2, 0.557], [64622.8, 0.14], [64625.7, 0.005], [64668.9, 31.146], [64671.1, 1.084], [64696.8, 0.285], [64908.0, 2.001], [65101.8, 4.37], [65246.0, 13.778], [65318.0, 0.952], [65353.3, 1.707], [65424.8, 14.575], [65600.0, 70.131]]}
{"kind": "depth", "E": 1787088319295, "U": 11315917838733, "u": 11315917845592, "recv_ms": 1787088319244, "bids": [[1000.0, 35.76], [14099.9, 0.14], [14199.9, 3.738], [14299.9, 0.322], [51680.0, 1.939], [58139.9, 0.002], [61364.1, 0.02], [61364.2, 0.028], [61369.9, 0.008], [62015.9, 0.004], [63305.7, 0.007], [63551.6, 10.766], [63953.7, 1.641], [63953.9, 0.009], [64068.3, 5.797], [64402.6, 0.0], [64430.2, 7.565], [64438.5, 2.387], [64556.9, 0.001], [64565.3, 0.007], [64567.0, 0.0], [64567.1, 0.015], [64567.2, 0.0], [64570.5, 2.353], [64570.6, 0.005], [64570.7, 1.242], [64571.3, 1.135], [64571.7, 0.074], [64572.1, 1.216], [64581.5, 0.559], [64581.6, 0.002], [64581.9, 0.061], [64584.2, 0.003], [64591.1, 0.382], [64591.4, 0.1], [64592.3, 0.002], [64597.2, 0.007], [64597.3, 0.006], [64597.9, 0.02], [64599.9, 21.115]], "asks": [[64602.0, 0.098], [64602.1, 0.019], [64618.8, 0.361], [64623.5, 0.173], [64624.3, 0.072], [64625.6, 0.003], [64802.1, 0.0], [65246.0, 13.778], [65246.2, 1.072], [65439.9, 0.305], [65889.6, 0.003]]}
{"kind": "depth", "E": 1787088319397, "U": 11315917845780, "u": 11315917850725, "recv_ms": 1787088319333, "bids": [[1000.0, 35.76], [14099.9, 0.378], [14199.9, 3.626], [14299.9, 0.196], [51680.0, 1.939], [58139.9, 0.002], [61369.9, 0.009], [62015.9, 0.001], [63305.7, 0.004], [63599.9, 0.008], [63842.3, 12.25], [63953.9, 0.009], [64262.1, 2.417], [64571.4, 0.107], [64571.6, 0.201], [64577.8, 0.016], [64579.3, 0.001], [64580.2, 0.0], [64580.6, 0.001], [64580.9, 0.678], [64581.5, 0.002], [64585.8, 0.927], [64586.5, 0.013], [64586.6, 0.002], [64587.8, 0.0], [64588.3, 0.704], [64592.3, 0.003], [64597.9, 0.02], [64599.9, 21.121]], "asks": [[64616.7, 0.094], [64618.0, 0.563], [64621.3, 0.0], [64622.2, 0.557], [64628.5, 0.012], [64671.5, 0.062], [64739.2, 1.405], [65116.8, 1.568], [65246.0, 13.778], [65600.0, 70.111]]}
{"kind": "depth", "E": 1787088319499, "U": 11315917850755, "u": 11315917856194, "recv_ms": 1787088319436, "bids": [[14099.9, 0.616], [14199.9, 3.5], [14299.9, 0.084], [51680.0, 1.939], [58139.9, 0.002], [61369.9, 0.008], [63824.7, 2.411], [63882.9, 0.887], [63953.9, 0.009], [64083.1, 0.313], [64276.9, 0.425], [64567.6, 0.004], [64567.7, 0.021], [64580.2, 0.0], [64584.2, 0.002], [64588.9, 0.158], [64597.9, 0.03], [64598.6, 0.084], [64599.9, 21.134]], "asks": [[64600.4, 0.032], [64628.5, 0.166], [64922.4, 0.248], [64923.0, 0.471], [65246.0, 13.778], [65376.7, 0.856], [65407.5, 1.06], [65891.9, 0.027]]}
{"kind": "depth", "E": 1787088319601, "U": 11315917856264, "u": 11315917864086, "recv_ms": 1787088319537, "bids": [[1000.0, 35.76], [14099.9, 0.882], [14199.9, 3.318], [14299.9, 0.0], [58139.9, 0.002], [61364.1, 0.018], [61364.2, 0.03], [62015.9, 0.004], [63566.3, 1.101], [63599.9, 0.028], [63857.0, 2.27], [63953.9, 0.009], [64068.3, 5.485], [64353.9, 0.008], [64388.8, 1.059], [64583.1, 0.004], [64588.9, 0.157], [64591.3, 0.073], [64598.6, 0.0]], "asks": [[64600.2, 0.001], [64600.3, 0.084], [64608.3, 0.283], [64609.5, 0.725], [64609.9, 0.216], [64610.0, 0.088], [64610.2, 0.015], [64610.7, 0.001], [64611.5, 0.219], [64612.9, 0.002], [64613.1, 0.266], [64614.8, 0.0], [64615.5, 0.068], [64628.4, 0.0], [64628.5, 0.012], [64865.7, 0.0], [65246.0, 13.778], [65600.0, 70.131]]}
{"kind": "depth", "E": 1787088319703, "U": 11315917864206, "u": 11315917868889, "recv_ms": 1787088319640, "bids": [[1000.0, 35.76], [14099.9, 1.246], [14199.9, 2.954], [51679.9, 0.0], [58139.9, 0.002], [61369.9, 0.014], [62015.9, 0.001], [63953.9, 0.009], [64276.9, 0.579], [64395.2, 0.0], [64396.8, 0.813], [64399.6, 8.217], [64437.9, 0.0], [64438.4, 4.619], [64440.0, 2.173], [64455.2, 0.0], [64455.3, 4.051], [64531.2, 1.443], [64536.4, 2.294], [64541.7, 0.008], [64570.6, 0.007], [64579.9, 0.155], [64591.3, 0.072], [64596.1, 0.001], [64599.7, 0.02], [64599.9, 21.127]], "asks": [[64601.4, 0.002], [64656.7, 0.003], [64662.5, 1.87], [64677.6, 0.005], [64696.9, 0.022], [64739.2, 0.686], [64739.4, 5.406], [64756.2, 0.0], [64756.3, 10.424], [64788.8, 0.0], [64795.1, 15.433], [64923.0, 0.47], [65246.0, 13.778]]}
{"kind": "depth", "E": 1787088319805, "U": 11315917869010, "u": 11315917873867, "recv_ms": 1787088319741, "bids": [[14099.9, 1.596], [14199.9, 2.604], [51680.0, 1.939], [58139.9, 0.002], [61369.9, 0.014], [62015.9, 0.004], [63599.9, 0.008], [63953.9, 0.009], [64083.1, 0.625], [64276.9, 0.59], [64455.3, 3.538], [64586.4, 0.002], [64596.1, 0.0], [64599.7, 0.021], [64599.9, 21.126]], "asks": [[64600.0, 14.943], [64609.2, 0.154], [64739.4, 5.406], [64923.0, 0.471], [65246.0, 13.778], [65600.0, 70.111], [65891.9, 0.027]]}
{"kind": "depth", "E": 1787088319907, "U": 11315917873958, "u": 11315917879347, "recv_ms": 1787088319843, "bids": [[1000.0, 35.76], [14099.9, 1.96], [14199.9, 2.24], [58139.9, 0.002], [61369.9, 0.014], [62015.9, 0.001], [63402.9, 0.898], [63752.7, 0.784], [63953.9, 0.009], [64068.3, 4.55], [64455.3, 0.816], [64579.9, 0.001], [64583.6, 0.036], [64586.4, 0.001], [64599.9, 21.127]], "asks": [[64650.8, 0.0], [64739.4, 0.0], [65246.0, 13.778]]}
{"kind": "depth", "E": 1787088320111, "U": 11315917885447, "u": 11315917893529, "recv_ms": 1787088320048, "bids": [[14099.9, 2.674], [14199.9, 1.526], [51680.0, 1.939], [58139.9, 0.002], [61369.9, 0.018], [61370.0, 0.012], [62015.9, 0.004], [63953.9, 0.008], [64083.1, 1.56], [64276.9, 0.58], [64455.4, 4.828], [64500.3, 0.011], [64552.8, 0.13], [64553.3, 1.139], [64580.0, 0.318], [64585.8, 0.0], [64586.7, 0.927], [64587.8, 0.0], [64588.3, 0.704], [64592.4, 0.036], [64599.9, 21.071]], "asks": [[64628.7, 0.455], [64656.3, 0.063], [64656.8, 1.839], [64696.5, 1.844], [64739.4, 5.406], [65246.0, 13.778]]}
{"kind": "depth", "E": 1787088320315, "U": 11315917899976, "u": 11315917905253, "recv_ms": 1787088320252, "bids": [[1000.0, 35.76], [14099.9, 3.388], [14199.9, 0.812], [51680.0, 1.939], [58139.9, 0.002], [61369.9, 0.018], [62015.9, 0.004], [63777.7, 29.913], [63844.1, 1.096], [63953.9, 0.008], [64500.2, 10.0], [64521.7, 33.724], [64526.1, 0.001], [64532.5, 6.166], [64557.5, 0.034], [64565.3, 0.007], [64568.4, 0.313], [64571.5, 0.1], [64572.2, 0.061], [64573.1, 2.422], [64575.8, 2.333], [64581.2, 0.001], [64581.5, 0.559], [64581.9, 0.061], [64584.5, 0.007], [64584.9, 0.312], [64586.3, 0.006], [64597.9, 0.02], [64598.2, 0.084], [64599.9, 21.072]], "asks": [[64600.0, 14.944], [64600.4, 0.012], [64600.7, 0.015], [64609.4, 0.001], [64617.5, 0.544], [64618.0, 0.021], [64618.9, 0.108], [64619.0, 1.549], [64619.3, 0.081], [64619.9, 0.161], [64621.8, 0.262], [64622.2, 0.0], [64622.8, 0.697], [64623.5, 0.057], [64624.4, 0.758], [64629.1, 0.622], [64696.7, 10.0], [65246.0, 13.778], [65295.9, 0.0], [65353.7, 3.669], [65511.7, 0.762]]}
{"kind": "depth", "E": 1787088320417, "U": 11315917905402, "u": 11315917909432, "recv_ms": 1787088320355, "bids": [[14099.9, 3.71], [14199.9, 0.476], [14499.9, 0.014], [58139.9, 0.002], [61369.9, 0.022], [61370.0, 0.014], [63599.9, 0.028], [63648.5, 43.476], [63792.4, 1.236], [63953.9, 0.008], [64276.9, 0.59], [64455.4, 1.594], [64521.7, 0.0], [64522.3, 0.845], [64523.9, 33.741], [64524.9, 0.025], [64537.6, 2.111], [64541.7, 0.008], [64542.3, 0.0], [64593.0, 0.035], [64595.9, 0.382], [64597.9, 0.03], [64599.9, 21.095]], "asks": [[64600.1, 0.006], [64600.2, 0.0], [64600.3, 0.0], [64600.7, 0.099], [64640.3, 1.229], [64662.9, 1.671], [64677.6, 0.005], [64739.2, 0.686], [64739.4, 0.0], [65246.0, 13.778], [65375.2, 4.588], [65600.0, 70.131]]}
{"kind": "depth", "E": 1787088320519, "U": 11315917909465, "u": 11315917915760, "recv_ms": 1787088320456, "bids": [[1000.0, 35.76], [14099.9, 3.71], [14199.9, 0.294], [14499.9, 0.196], [58139.9, 0.002], [61369.9, 0.022], [62015.9, 0.001], [62984.9, 1.912], [63308.0, 0.807], [63410.0, 0.156], [63663.2, 2.341], [63953.9, 0.008], [64438.4, 0.007], [64438.5, 6.837], [64455.5, 3.489], [64490.9, 0.427], [64492.8, 2.329], [64542.3, 0.015], [64581.2, 0.0], [64585.2, 0.002], [64592.3, 0.002], [64595.9, 0.367], [64598.5, 0.09], [64599.9, 21.096]], "asks": [[64600.0, 14.945], [64600.1, 0.005], [64600.3, 0.001], [64611.8, 0.0], [64617.5, 0.002], [64618.0, 0.563], [64628.6, 0.002], [64706.4, 2.323], [64707.4, 0.013], [64739.4, 5.406], [64756.3, 0.0], [64756.4, 10.424], [65246.0, 13.778], [65368.7, 1.834]]}
{"kind": "depth", "E": 1787088320723, "U": 11315917921883, "u": 11315917926684, "recv_ms": 1787088320660, "bids": [[14099.9, 3.472], [14199.9, 0.056], [14499.9, 0.672], [51679.9, 0.0], [58139.9, 0.002], [62015.9, 0.001], [63630.9, 0.008], [63688.2, 0.786], [63953.9, 0.008], [63971.2, 0.0], [64276.9, 0.59], [64438.5, 2.387], [64440.0, 1.705], [64455.5, 0.04], [64505.5, 2.413], [64523.9, 0.017], [64524.9, 0.007], [64526.1, 33.725], [64542.3, 0.0], [64576.2, 0.315], [64579.9, 0.001], [64583.1, 0.004], [64586.9, 0.0], [64589.3, 0.009], [64595.9, 0.382], [64599.9, 20.823]], "asks": [[64615.5, 0.068], [64625.9, 0.051], [64629.1, 0.003], [64739.4, 0.0], [64756.4, 0.0], [65246.0, 13.778]]}
{"kind": "depth", "E": 1787088320825, "U": 11315917926816, "u": 11315917932282, "recv_ms": 1787088320761, "bids": [[1000.0, 35.76], [14099.9, 3.234], [14199.9, 0.0], [14499.9, 0.966], [58139.9, 0.002], [61369.9, 0.024], [62015.9, 0.004], [63431.3, 5.25], [63599.9, 0.028], [63695.5, 0.188], [63951.1, 0.0], [63953.3, 0.701], [63953.9, 0.008], [64276.9, 0.59], [64399.6, 0.051], [64399.8, 8.479], [64438.5, 5.97], [64455.5, 3.066], [64580.5, 0.164], [64589.3, 0.008], [64599.9, 20.823]], "asks": [[64628.9, 10.004], [64629.0, 0.009], [64629.1, 0.005], [64631.8, 0.017], [64631.9, 0.059], [64632.0, 0.009], [64632.8, 3.945], [64632.9, 1.642], [64633.0, 4.84], [64634.9, 0.006], [64635.0, 0.023], [64635.1, 0.419], [64739.4, 5.406], [64756.4, 10.424], [64795.1, 15.031], [64923.0, 0.47], [65246.0, 13.778], [65600.0, 70.131]]}
{"kind": "depth", "E": 1787088320927, "U": 11315917932354, "u": 11315917936579, "recv_ms": 1787088320863, "bids": [[14099.9, 2.87], [14499.9, 1.33], [58139.9, 0.002], [61364.2, 0.028], [63792.2, 0.062], [63844.1, 1.644], [63953.9, 0.008], [63992.7, 3.84], [64258.0, 0.194], [64258.7, 0.658], [64455.5, 3.273], [64505.5, 2.412], [64542.3, 0.015], [64580.5, 0.163], [64582.2, 0.004], [64594.3, 0.006], [64594.6, 0.004], [64595.9, 0.367], [64599.4, 0.724], [64599.9, 21.05]], "asks": [[64600.0, 14.889], [64600.7, 0.015], [64601.1, 0.001], [64628.7, 0.609], [64636.2, 0.067], [64923.0, 0.471], [65143.2, 0.0], [65246.0, 13.778]]}
{"kind": "depth", "E": 1787088321131, "U": 11315917941489, "u": 11315917948877, "recv_ms": 1787088321072, "bids": [[1000.0, 35.76], [14099.9, 2.156], [14499.9, 2.044], [51680.0, 1.939], [58139.9, 0.002], [61369.9, 0.024], [62015.9, 0.004], [63777.7, 29.648], [63953.9, 0.008], [64580.1, 5.959], [64584.2, 0.002], [64588.3, 0.704], [64589.1, 0.012], [64594.3, 0.003], [64599.9, 21.125]], "asks": [[64600.0, 14.887], [64609.7, 2.353], [64625.9, 0.065], [64628.5, 0.012], [64629.4, 1.889], [64629.5, 0.022], [64645.4, 0.017], [64676.1, 0.0], [64781.5, 0.0], [64781.6, 0.003], [64890.7, 0.341], [65246.0, 13.778], [65282.2, 2.828], [65295.6, 1.452], [65418.1, 3.129], [65543.2, 0.628], [65554.4, 0.771]]}
{"kind": "depth", "E": 1787088321233, "U": 11315917949032, "u": 11315917954353, "recv_ms": 1787088321170, "bids": [[14099.9, 1.806], [14499.9, 2.394], [58139.9, 0.002], [62015.9, 0.001], [63305.7, 0.001], [63308.0, 0.807], [63599.9, 0.028], [63953.9, 0.008], [64478.7, 0.084], [64478.8, 3.913], [64480.0, 15.201], [64541.7, 0.008], [64554.6, 0.043], [64580.0, 0.318], [64580.1, 5.805], [64586.2, 0.001], [64589.1, 0.011]], "asks": [[64606.1, 0.311], [64628.4, 0.0], [64628.6, 0.156], [64658.2, 0.023], [64677.6, 0.002], [65157.4, 0.088], [65246.0, 13.778], [65310.6, 1.034], [65421.6, 0.0], [65600.0, 70.131], [65889.6, 0.0], [65891.9, 0.021]]}
{"kind": "depth", "E": 1787088321335, "U": 11315917954426, "u": 11315917961082, "recv_ms": 1787088321272, "bids": [[14099.9, 1.442], [14499.9, 2.758], [58139.9, 0.002], [61369.9, 0.024], [62015.9, 0.004], [63599.9, 0.008], [63705.9, 0.002], [63953.9, 0.008], [64276.9, 0.59], [64455.5, 0.04], [64455.6, 3.151], [64542.3, 0.0], [64556.9, 0.001], [64564.1, 2.939], [64565.3, 0.007], [64571.4, 0.726], [64579.9, 0.001], [64593.8, 0.006], [64595.9, 0.382], [64599.8, 0.015], [64599.9, 21.127]], "asks": [[64617.5, 0.002], [64624.8, 1.214], [64628.4, 0.0], [64628.6, 0.002], [64814.7, 0.0], [64832.5, 0.352], [64832.6, 0.754], [64833.0, 0.156], [65246.0, 13.778], [65421.4, 0.0], [65440.0, 1.154], [65600.0, 70.111]]}
{"kind": "depth", "E": 1787088321641, "U": 11315917970065, "u": 11315917974239, "recv_ms": 1787088321577, "bids": [[1000.0, 35.76], [14099.9, 0.42], [14399.9, 0.042], [14499.9, 3.738], [51680.0, 1.939], [58139.9, 0.002], [61369.9, 0.03], [62015.9, 0.004], [63195.3, 0.0], [63198.8, 0.002], [63424.2, 0.789], [63599.9, 0.028], [63628.9, 0.135], [63810.0, 71.808], [63842.3, 10.372], [63953.9, 0.008], [64276.9, 0.59], [64438.5, 2.387], [64455.6, 0.0], [64521.7, 0.0], [64523.9, 33.746], [64580.1, 5.805], [64583.1, 0.002], [64586.2, 0.0], [64589.4, 0.001], [64599.9, 21.129]], "asks": [[64600.0, 14.807], [64601.5, 0.0], [64602.9, 0.002], [64603.2, 0.011], [64605.0, 0.096], [64615.5, 0.066], [64624.8, 0.595], [64628.5, 0.012], [64739.2, 0.686], [64739.4, 0.0], [64756.4, 0.0], [65246.0, 13.778], [65435.0, 0.682], [65527.6, 3.581], [65600.0, 70.131], [65891.9, 0.018]]}
{"kind": "depth", "E": 1787088321743, "U": 11315917974282, "u": 11315917979394, "recv_ms": 1787088321679, "bids": [[1000.0, 35.76], [14099.9, 0.266], [14399.9, 0.252], [14499.9, 3.682], [51679.9, 0.0], [58139.9, 0.002], [62015.9, 0.001], [63308.0, 0.81], [63857.0, 3.208], [63953.9, 0.008], [64524.9, 0.025], [64542.3, 0.0], [64553.6, 0.078], [64565.3, 0.003], [64583.1, 0.004], [64589.4, 0.0], [64595.5, 0.001], [64595.9, 0.382], [64597.9, 0.03], [64599.2, 0.007], [64599.9, 21.076]], "asks": [[64600.0, 14.808], [64600.9, 0.107], [64603.2, 0.01], [64603.3, 0.016], [64615.5, 0.068], [64628.6, 0.002], [65246.0, 13.778], [65293.0, 0.065], [65447.2, 1.526], [65536.7, 1.181], [66544.6, 0.65]]}
{"kind": "depth", "E": 1787088321845, "U": 11315917979754, "u": 11315917984842, "recv_ms": 1787088321781, "bids": [[14099.9, 0.14], [14399.9, 0.49], [14499.9, 3.57], [58139.9, 0.002], [61369.9, 0.036], [63599.9, 0.008], [63650.3, 1.282], [63680.8, 80.382], [63727.8, 1.414], [63953.9, 0.01], [64276.9, 0.589], [64399.8, 0.315], [64400.0, 46.185], [64438.7, 3.638], [64455.7, 2.655], [64523.9, 33.746], [64526.1, 0.001], [64589.5, 0.002], [64594.1, 0.007], [64595.5, 0.0], [64597.9, 0.03], [64599.9, 21.076]], "asks": [[64739.4, 5.406], [64756.4, 10.424], [64795.1, 15.433], [64923.0, 0.471], [65246.0, 13.778], [65449.4, 0.277], [65600.0, 70.111], [65670.1, 5.463], [65891.9, 0.015]]}
{"kind": "depth", "E": 1787088321947, "U": 11315917984848, "u": 11315917990293, "recv_ms": 1787088321885, "bids": [[1000.0, 35.76], [14099.9, 0.028], [14399.9, 0.728], [14499.9, 3.444], [58139.9, 0.002], [62015.9, 0.004], [63824.7, 3.506], [63857.0, 4.147], [63953.9, 0.008], [64258.7, 0.166], [64259.1, 0.492], [64276.9, 0.59], [64523.9, 0.017], [64524.9, 0.007], [64526.1, 33.757], [64542.3, 0.015], [64564.1, 2.32], [64571.4, 0.107], [64587.8, 0.001], [64589.5, 0.001], [64595.9, 0.367], [64599.9, 21.082]], "asks": [[64609.7, 2.352], [64611.9, 0.008], [64619.0, 0.623], [64619.5, 0.929], [65246.0, 13.778], [65265.8, 2.74], [65312.1, 1.713], [65549.6, 1.59], [71060.0, 0.0]]}
{"kind": "depth", "E": 1787088322049, "U": 11315917990373, "u": 11315917997953, "recv_ms": 1787088321984, "bids": [[1000.0, 35.76], [14099.9, 0.0], [14399.9, 1.05], [14499.9, 3.15], [58139.9, 0.002], [61369.9, 0.034], [61370.0, 0.016], [62015.9, 0.001], [63599.9, 0.028], [63792.4, 1.587], [63953.9, 0.008], [64579.9, 0.155], [64588.3, 0.709]], "asks": [[64600.0, 13.497], [64600.6, 0.007], [64600.9, 0.084], [64603.3, 0.015], [64605.5, 0.089], [64613.4, 1.461], [64618.8, 0.041], [64619.2, 1.266], [64621.2, 0.335], [64628.4, 0.154], [65246.0, 13.778], [65317.6, 0.765], [65547.0, 25.285], [65600.0, 70.131]]}
{"kind": "depth", "E": 1787088322151, "U": 11315917998235, "u": 11315918004110, "recv_ms": 1787088322087, "bids": [[14399.9, 1.414], [14499.9, 2.786], [58139.9, 0.002], [61369.9, 0.034], [62015.9, 0.004], [63713.1, 29.538], [63953.9, 0.008], [64083.1, 1.872], [64579.8, 0.154], [64579.9, 0.001], [64585.6, 0.242], [64586.1, 0.0], [64587.8, 0.0], [64588.3, 0.704], [64588.8, 0.263], [64589.3, 0.0], [64596.2, 0.085], [64599.9, 21.084]], "asks": [[64600.0, 13.5], [64606.6, 0.393], [64610.1, 0.398], [64619.2, 1.186], [65246.0, 13.778], [65683.0, 14.235], [65685.3, 0.607]]}
{"kind": "depth", "E": 1787088322253, "U": 11315918004224, "u": 11315918009875, "recv_ms": 1787088322188, "bids": [[1000.0, 35.76], [14399.9, 1.764], [14499.9, 2.436], [51680.0, 1.941], [58139.9, 0.002], [62015.9, 0.001], [63599.9, 0.008], [63953.9, 0.008], [64276.9, 0.59], [64579.7, 0.154], [64579.8, 0.0], [64599.9, 21.078]], "asks": [[65211.2, 0.107], [65246.0, 13.778], [65292.1, 0.004], [65600.0, 70.111]]}
{"kind": "depth", "E": 1787088322355, "U": 11315918009953, "u": 11315918015765, "recv_ms": 1787088322291, "bids": [[1000.0, 35.76], [14399.9, 2.128], [14499.9, 2.072], [51680.0, 1.941], [58139.9, 0.002], [61369.9, 0.034], [63599.9, 0.028], [63803.3, 29.266], [63830.0, 2.398], [63953.9, 0.008], [64455.7, 0.003], [64521.7, 33.756], [64522.3, 0.863], [64526.1, 0.001], [64554.6, 0.046], [64564.2, 1.154], [64571.5, 0.719], [64587.0, 0.022], [64590.6, 0.152], [64593.7, 0.004], [64596.2, 0.084], [64599.5, 1.006], [64599.9, 21.078]], "asks": [[64600.0, 13.483], [64600.9, 0.0], [64617.6, 1.012], [64624.9, 0.621], [64628.3, 0.002], [64628.4, 0.0], [64739.4, 0.0], [64907.9, 0.326], [64908.0, 1.847], [65101.8, 4.063], [65116.8, 1.875], [65246.0, 13.778], [65569.0, 4.698], [65600.0, 70.131], [65698.2, 1.909]]}
{"kind": "depth", "E": 1787088322457, "U": 11315918015798, "u": 11315918021283, "recv_ms": 1787088322394, "bids": [[14399.9, 2.492], [14499.9, 1.708], [51680.0, 1.939], [58139.9, 0.002], [62015.9, 0.004], [63727.8, 2.04], [63953.9, 0.008], [64455.8, 3.223], [64521.7, 0.0], [64522.3, 0.845], [64523.9, 33.773], [64524.6, 6.38], [64580.1, 5.921], [64580.9, 0.005], [64586.0, 0.951], [64586.7, 0.0], [64586.8, 0.359], [64586.9, 0.927], [64587.8, 0.542], [64588.3, 0.162], [64594.3, 1.019], [64598.9, 0.009], [64599.1, 0.124], [64599.5, 0.922]], "asks": [[64601.4, 0.0], [64601.6, 0.094], [64618.5, 0.0], [64619.3, 1.007], [64619.5, 0.003], [64621.3, 0.0], [64622.2, 0.557], [64622.8, 0.14], [64622.9, 0.329], [64623.8, 2.053], [64624.4, 0.642], [64628.5, 0.166], [64677.6, 0.005], [64739.2, 1.405], [64739.5, 5.407], [65246.0, 13.778], [65269.3, 0.002], [65360.1, 61.718], [65360.6, 3.858]]}
{"kind": "depth", "E": 1787088322661, "U": 11315918027298, "u": 11315918032367, "recv_ms": 1787088322597, "bids": [[1000.0, 35.76], [14399.9, 3.206], [14499.9, 0.994], [34000.0, 1.146], [51680.0, 1.939], [58139.9, 0.002], [62015.9, 0.004], [63404.3, 0.0], [63599.9, 0.008], [63953.9, 0.008], [64438.7, 0.126], [64455.8, 0.271], [64592.3, 0.01], [64593.7, 0.003], [64594.3, 1.019], [64594.5, 0.001], [64598.4, 0.002]], "asks": [[64628.2, 0.166], [64628.3, 0.156], [64628.5, 0.012], [64629.9, 1.721], [64644.8, 1.093], [64739.2, 0.686], [64739.5, 0.001], [64756.4, 0.0], [65375.2, 6.726], [65553.9, 28.896], [65600.0, 70.111], [65891.9, 0.021]]}
{"kind": "depth", "E": 1787088322763, "U": 11315918032395, "u": 11315918037883, "recv_ms": 1787088322737, "bids": [[14399.9, 3.556], [14499.9, 0.644], [51679.9, 0.0], [51680.0, 1.943], [58139.9, 0.002], [61369.9, 0.034], [62015.9, 0.001], [63953.9, 0.008], [64400.0, 38.406], [64523.9, 0.017], [64524.6, 1.501], [64526.1, 33.757], [64583.1, 0.004], [64592.3, 0.002], [64594.3, 0.003], [64594.5, 0.009], [64598.4, 0.001], [64599.9, 21.079]], "asks": [[64615.5, 0.068], [64628.3, 0.002], [64628.4, 0.0], [64628.9, 10.002], [64629.0, 0.007], [64629.1, 0.003], [64631.8, 0.015], [64631.9, 0.057], [64632.0, 0.007], [64632.8, 3.943], [64632.9, 1.64], [64633.0, 4.838], [64634.9, 0.004], [64635.0, 0.021], [64635.1, 0.417], [64795.1, 0.0], [65246.0, 13.778], [65439.8, 0.306]]}
{"kind": "depth", "E": 1787088322865, "U": 11315918037996, "u": 11315918043667, "recv_ms": 1787088322802, "bids": [[1000.0, 35.76], [14299.9, 0.084], [14399.9, 3.752], [14499.9, 0.364], [51680.0, 1.939], [58139.9, 0.002], [61369.9, 0.034], [63599.9, 0.028], [63792.4, 1.852], [63953.9, 0.008], [64068.3, 3.926], [64262.1, 2.262], [64276.9, 0.59], [64400.1, 7.774], [64438.9, 3.522], [64455.8, 3.192], [64521.7, 0.0], [64522.3, 0.845], [64523.9, 33.869], [64526.1, 0.001], [64592.3, 0.002], [64592.6, 0.313], [64594.3, 1.019], [64594.5, 0.009], [64599.9, 21.078]], "asks": [[64739.5, 5.407], [64756.4, 10.424], [64795.2, 15.434], [64923.0, 0.624], [65246.0, 13.778], [65447.1, 1.526], [65547.0, 22.238], [65569.0, 6.221], [65569.1, 1.066], [65600.0, 70.131]]}
{"kind": "depth", "E": 1787088322967, "U": 11315918043706, "u": 11315918048022, "recv_ms": 1787088322905, "bids": [[1000.0, 35.76], [14299.9, 0.308], [14399.9, 3.654], [14499.9, 0.238], [58139.9, 0.002], [61369.9, 0.032], [61370.0, 0.018], [62015.9, 0.004], [63599.9, 0.008], [63759.6, 0.783], [63953.9, 0.008], [64259.1, 0.0], [64259.2, 0.682], [64276.9, 0.59], [64336.2, 0.51], [64455.8, 0.271], [64490.9, 0.424], [64524.9, 0.025], [64579.7, 0.0], [64585.0, 36.402], [64592.3, 0.01], [64594.3, 0.003], [64594.5, 0.001], [64599.1, 0.04], [64599.9, 21.077]], "asks": [[64600.7, 0.099], [64739.5, 0.001], [64923.0, 0.625], [65246.0, 13.778], [65418.1, 2.595], [65447.2, 2.289], [65576.3, 0.766], [65600.0, 70.111]]}
{"kind": "depth", "E": 1787088323171, "U": 11315918054369, "u": 11315918059859, "recv_ms": 1787088323107, "bids": [[1000.0, 35.76], [14299.9, 0.784], [14399.9, 3.416], [14499.9, 0.0], [51680.0, 1.941], [58139.9, 0.002], [61370.0, 0.016], [62015.9, 0.004], [63377.3, 4.888], [63648.5, 42.378], [63953.9, 0.008], [64276.9, 0.745], [64526.1, 0.001], [64528.3, 33.854], [64532.5, 0.166], [64555.1, 1.228], [64571.3, 0.14], [64579.6, 0.154], [64590.1, 0.005], [64592.6, 0.312]], "asks": [[64612.0, 0.34], [64625.6, 0.003], [64628.1, 0.034], [64628.2, 0.166], [64628.3, 0.156], [64629.3, 1.918], [64629.4, 0.004], [64640.3, 0.748], [64641.7, 0.003], [64662.9, 0.789], [64664.4, 0.0], [65246.0, 13.778], [65392.4, 21.197], [65440.0, 1.688], [65472.1, 0.671]]}
{"kind": "depth", "E": 1787088323273, "U": 11315918059973, "u": 11315918064594, "recv_ms": 1787088323209, "bids": [[1000.0, 35.76], [14299.9, 1.134], [14399.9, 3.066], [51680.0, 1.939], [58139.9, 0.002], [61369.9, 0.04], [63409.2, 1.351], [63599.9, 0.028], [63953.9, 0.008], [64455.9, 2.92], [64478.7, 0.0], [64500.2, 0.0], [64530.1, 0.018], [64555.1, 4.728], [64571.2, 1.24], [64599.9, 21.081]], "asks": [[64628.3, 0.002], [64628.5, 0.166], [64666.5, 0.024], [64673.1, 0.34], [64696.7, 0.0], [64739.5, 5.407], [65246.0, 13.778], [65424.8, 13.965], [65439.8, 0.611], [65527.6, 3.047], [65600.0, 70.131], [65611.6, 4.896], [65694.4, 0.018], [65701.0, 0.116]]}
{"kind": "depth", "E": 1787088323375, "U": 11315918064612, "u": 11315918069665, "recv_ms": 1787088323312, "bids": [[14299.9, 1.498], [14399.9, 2.702], [58139.9, 0.002], [61369.9, 0.04], [62015.9, 0.001], [63391.9, 1.528], [63663.2, 4.537], [63953.9, 0.008], [64523.9, 0.017], [64524.9, 0.025], [64526.1, 33.853], [64527.5, 0.0], [64528.3, 0.002], [64532.5, 6.166], [64549.2, 0.039], [64549.3, 0.0], [64564.2, 1.154], [64571.5, 0.719], [64588.8, 0.255], [64589.3, 0.008], [64592.3, 0.01], [64599.9, 21.081]], "asks": [[64617.6, 1.012], [64624.9, 0.621], [64625.6, 0.968], [64628.9, 10.004], [64629.0, 0.009], [64629.1, 0.005], [64631.8, 0.017], [64631.9, 0.059], [64632.0, 0.009], [64632.8, 3.945], [64632.9, 1.642], [64633.0, 4.84], [64634.9, 0.006], [64635.0, 0.023], [64635.1, 0.419], [64640.3, 1.229], [64641.8, 3.501], [64662.9, 1.672], [64664.4, 6.0], [64675.9, 0.005], [64682.4, 0.452], [65246.0, 13.778], [65353.7, 2.752], [65360.1, 61.504], [65694.4, 0.014], [65701.0, 0.037]]}
{"kind": "depth", "E": 1787088323477, "U": 11315918069757, "u": 11315918074317, "recv_ms": 1787088323413, "bids": [[1000.0, 35.76], [14299.9, 1.862], [14399.9, 2.338], [58139.9, 0.002], [62015.9, 0.004], [63583.9, 28.274], [63599.9, 0.008], [63953.9, 0.008], [64276.9, 0.745], [64500.2, 10.0], [64524.9, 0.007], [64527.0, 5.324], [64527.5, 0.018], [64554.6, 0.046], [64564.2, 0.535], [64571.5, 0.1], [64586.4, 0.002], [64590.1, 0.004], [64599.1, 0.04], [64599.9, 21.076]], "asks": [[64600.0, 13.395], [64600.7, 0.015], [64600.8, 0.087], [64624.9, 0.002], [64672.7, 0.0], [64677.6, 0.005], [64696.7, 10.0], [64739.2, 1.405], [64908.0, 1.693], [65101.8, 2.835], [65191.8, 6.367], [65224.3, 1.796], [65246.0, 13.778], [65439.8, 0.916], [65549.6, 2.123], [65586.2, 28.68], [65600.0, 70.111]]}
{"kind": "depth", "E": 1787088323579, "U": 11315918074363, "u": 11315918078478, "recv_ms": 1787088323516, "bids": [[1000.0, 35.76], [14299.9, 2.212], [14399.9, 1.988], [58139.9, 0.002], [61369.9, 0.04], [62015.9, 0.001], [63308.0, 0.807], [63777.7, 29.296], [63953.9, 0.008], [64455.9, 0.0], [64456.0, 3.17], [64549.2, 0.0], [64549.3, 0.039], [64586.4, 0.001], [64589.1, 0.012], [64598.2, 0.104], [64598.9, 0.093], [64599.9, 21.077]], "asks": [[64600.8, 0.003], [64611.4, 1.613], [64644.4, 1.431], [64739.2, 0.686], [64739.5, 5.407], [64923.0, 0.779], [65116.8, 2.182], [65246.0, 13.778], [65368.7, 2.751], [65418.1, 2.061], [65469.9, 4.902], [65633.6, 6.087]]}
{"kind": "depth", "E": 1787088323681, "U": 11315918078537, "u": 11315918083089, "recv_ms": 1787088323616, "bids": [[14299.9, 2.562], [14399.9, 1.638], [51680.0, 1.939], [58139.9, 0.002], [61369.9, 0.046], [61370.0, 0.014], [62015.9, 0.004], [63308.0, 0.81], [63599.9, 0.028], [63695.5, 0.196], [63816.4, 4.709], [63953.9, 0.008], [64521.7, 0.0], [64522.3, 0.845], [64523.9, 33.869], [64526.1, 0.001], [64527.0, 0.299], [64553.6, 0.074], [64565.3, 0.007], [64599.9, 21.088]], "asks": [[64600.0, 13.396], [64610.6, 0.348], [64616.9, 1.267], [64628.2, 0.32], [64628.3, 0.002], [64628.5, 0.012], [65213.7, 0.766], [65246.0, 13.778], [65246.2, 1.608], [65392.4, 20.937], [65600.0, 70.131]]}
{"kind": "depth", "E": 1787088323783, "U": 11315918083140, "u": 11315918087485, "recv_ms": 1787088323721, "bids": [[1000.0, 35.76], [14299.9, 2.926], [14399.9, 1.274], [51679.9, 0.0], [51680.0, 1.939], [58139.9, 0.002], [63598.6, 2.692], [63616.2, 30.167], [63953.9, 0.008], [64276.9, 0.735], [64479.9, 0.088], [64522.3, 0.848], [64523.9, 0.017], [64526.1, 33.853], [64541.7, 0.005], [64554.6, 0.043], [64583.1, 0.004], [64589.1, 0.011], [64594.2, 0.835]], "asks": [[64615.5, 0.068], [64628.2, 0.166], [64628.4, 0.154], [64658.2, 0.023], [64677.6, 0.002], [65116.8, 3.102], [65246.0, 13.778], [65440.0, 2.222], [65601.3, 1.066]]}
{"kind": "depth", "E": 1787088323885, "U": 11315918087664, "u": 11315918092419, "recv_ms": 1787088323822, "bids": [[1000.0, 35.76], [14299.9, 3.29], [14399.9, 0.91], [58139.9, 0.002], [61369.9, 0.047], [62015.9, 0.001], [63599.9, 0.008], [63810.0, 71.338], [63816.4, 3.77], [63828.0, 0.803], [63953.9, 0.008], [64456.0, 3.668], [64567.0, 0.002], [64567.1, 0.017], [64567.2, 0.002], [64570.5, 2.355], [64570.6, 0.009], [64570.7, 1.244], [64584.0, 0.127], [64594.2, 0.834], [64599.9, 21.088]], "asks": [[64628.4, 0.0], [64628.5, 0.166], [64739.5, 5.407], [65246.0, 13.778], [65360.1, 61.29], [65485.0, 1.188], [65600.0, 70.111]]}
{"kind": "depth", "E": 1787088324191, "U": 11315918102442, "u": 11315918107276, "recv_ms": 1787088324127, "bids": [[1000.0, 35.76], [14199.9, 0.364], [14299.9, 3.626], [14399.9, 0.21], [51680.0, 1.939], [58139.9, 0.002], [62015.9, 0.004], [63771.0, 4.7], [63824.7, 5.54], [63831.2, 1.905], [63953.9, 0.008], [64529.6, 0.0], [64591.6, 0.015]], "asks": [[64609.5, 0.726], [64612.0, 0.339], [65246.0, 13.779], [65246.2, 2.144], [65291.2, 1.241], [65382.5, 0.767], [65439.8, 1.221], [71060.0, 0.0]]}
{"kind": "depth", "E": 1787088324293, "U": 11315918107344, "u": 11315918113253, "recv_ms": 1787088324229, "bids": [[14199.9, 0.602], [14299.9, 3.514], [14399.9, 0.084], [51680.0, 1.939], [58139.9, 0.002], [61364.2, 0.026], [61369.9, 0.046], [63599.9, 0.008], [63777.7, 29.061], [63953.9, 0.008], [64276.9, 0.735], [64533.3, 0.001], [64547.1, 0.0], [64565.3, 0.007], [64599.9, 21.087]], "asks": [[64600.2, 0.001], [64600.3, 0.007], [64600.7, 0.028], [65246.0, 13.779], [65504.4, 5.669], [65600.0, 70.111], [65891.9, 0.018]]}
{"kind": "depth", "E": 1787088324395, "U": 11315918113357, "u": 11315918119159, "recv_ms": 1787088324331, "bids": [[1000.0, 35.76], [14199.9, 0.868], [14299.9, 3.332], [14399.9, 0.0], [58139.9, 0.002], [61369.9, 0.046], [62015.9, 0.001], [63429.7, 0.787], [63792.4, 2.635], [63874.3, 4.311], [63953.9, 0.008], [64391.2, 0.013], [64527.0, 5.324], [64548.2, 0.148], [64553.6, 0.078], [64554.6, 0.046], [64555.8, 0.34], [64565.0, 0.621], [64565.3, 0.003], [64572.4, 0.619], [64599.9, 21.043]], "asks": [[64600.0, 13.417], [64609.5, 0.725], [64618.4, 0.63], [64625.7, 0.624], [64636.2, 0.039], [64667.2, 0.046], [64667.5, 0.033], [64677.6, 0.005], [64739.2, 1.405], [65246.0, 13.779], [65246.2, 2.68], [65469.9, 4.293], [65579.3, 4.342], [71060.0, 0.0]]}
{"kind": "depth", "E": 1787088324497, "U": 11315918119285, "u": 11315918123725, "recv_ms": 1787088324433, "bids": [[1000.0, 35.76], [14199.9, 1.218], [14299.9, 2.982], [58139.9, 0.002], [61369.9, 0.052], [62015.9, 0.004], [63404.7, 0.0], [63953.9, 0.008], [64438.4, 0.01], [64553.6, 0.074], [64565.3, 0.007], [64586.2, 0.0], [64589.9, 0.002], [64599.9, 21.09]], "asks": [[64606.8, 0.003], [65246.0, 13.779]]}
{"kind": "depth", "E": 1787088324599, "U": 11315918123795, "u": 11315918130361, "recv_ms": 1787088324534, "bids": [[14199.9, 1.582], [14299.9, 2.618], [51680.0, 1.939], [58139.9, 0.002], [61369.9, 0.052], [62015.9, 0.001], [63308.0, 0.813], [63519.3, 5.661], [63599.9, 0.028], [63648.5, 40.181], [63895.8, 1.019], [63953.9, 0.008], [64276.9, 0.745], [64456.0, 0.225], [64456.1, 2.966], [64565.0, 0.002], [64572.4, 0.0], [64589.9, 0.001], [64594.4, 0.299], [64599.9, 21.085]], "asks": [[64613.6, 0.012], [64618.4, 0.011], [64625.7, 0.005], [64625.9, 0.051], [64739.2, 0.686], [64739.5, 5.407], [65246.0, 13.779], [65485.0, 1.797], [65600.0, 70.131], [65601.3, 2.132], [66199.7, 2.795]]}
{"kind": "depth", "E": 1787088324803, "U": 11315918135344, "u": 11315918140714, "recv_ms": 1787088324740, "bids": [[1000.0, 35.76], [14199.9, 2.296], [14299.9, 1.904], [51679.9, 0.0], [58139.9, 0.002], [61369.9, 0.058], [62015.9, 0.004], [63599.9, 0.008], [63842.3, 8.495], [63953.9, 0.008], [64549.3, 0.0], [64555.7, 0.59], [64565.3, 0.003], [64568.9, 0.039], [64582.1, 1.077], [64583.1, 0.004], [64591.5, 0.074], [64594.5, 0.0], [64598.9, 0.009], [64599.5, 0.931], [64599.9, 21.084]], "asks": [[64600.0, 13.419], [64612.9, 0.002], [64613.0, 3.237], [64615.5, 0.068], [64628.4, 0.0], [64628.5, 0.012], [64781.6, 0.0], [64781.7, 0.021], [65246.0, 13.779], [65600.0, 70.111], [65891.9, 0.018], [71060.0, 0.0]]}
{"kind": "depth", "E": 1787088324905, "U": 11315918140910, "u": 11315918145939, "recv_ms": 1787088324841, "bids": [[14199.9, 2.646], [14299.9, 1.554], [58139.9, 0.002], [61369.9, 0.058], [62015.9, 0.001], [63534.0, 2.202], [63663.2, 6.733], [63951.8, 0.903], [63953.9, 0.008], [64276.9, 0.745], [64400.1, 0.216], [64400.5, 7.748], [64438.9, 0.059], [64439.2, 4.523], [64440.0, 2.16], [64456.1, 0.0], [64456.2, 3.227], [64536.4, 0.003], [64536.7, 2.444], [64599.9, 21.041]], "asks": [[64600.7, 0.112], [64605.0, 0.012], [64628.6, 0.156], [64662.5, 0.0], [64662.6, 1.89], [65246.0, 13.779], [65407.5, 1.517], [65569.0, 8.086], [66215.0, 0.075]]}
{"kind": "depth", "E": 1787088325007, "U": 11315918145962, "u": 11315918151142, "recv_ms": 1787088324944, "bids": [[1000.0, 35.76], [14199.9, 3.01], [14299.9, 1.19], [58139.9, 0.002], [61364.2, 0.024], [61369.9, 0.058], [62015.9, 0.004], [63049.5, 0.076], [63599.9, 0.028], [63648.5, 40.024], [63953.9, 0.008], [64259.4, 0.0], [64259.6, 0.493], [64276.9, 0.744], [64538.4, 0.001], [64538.7, 0.001], [64539.1, 0.0], [64539.4, 0.003], [64539.7, 0.688], [64556.2, 0.001], [64556.5, 0.0], [64556.8, 0.008], [64557.2, 0.065], [64557.5, 0.002], [64571.1, 0.0], [64571.2, 1.1], [64571.3, 0.0], [64571.4, 0.037], [64571.5, 0.0], [64571.6, 0.001], [64571.7, 0.004], [64571.8, 0.12], [64571.9, 0.01], [64572.1, 1.146], [64573.1, 2.322], [64573.6, 0.002], [64582.1, 1.076], [64584.4, 0.017], [64590.5, 0.236], [64590.6, 0.012], [64590.7, 0.0], [64590.8, 0.086], [64590.9, 0.0], [64591.0, 0.903], [64591.1, 0.312], [64591.2, 0.037], [64591.3, 0.002], [64591.4, 0.0], [64591.5, 0.004], [64591.8, 0.826], [64592.1, 1.555], [64592.4, 0.003], [64592.7, 0.002], [64593.0, 0.003], [64599.9, 21.088]], "asks": [[64605.4, 0.184], [64605.7, 0.094], [64606.0, 0.013], [64606.3, 0.002], [64606.7, 0.0], [64606.9, 0.0], [64607.1, 0.003], [64607.2, 0.015], [64607.3, 0.362], [64607.4, 0.014], [64607.5, 0.002], [64607.6, 0.001], [64607.7, 0.001], [64607.8, 0.001], [64607.9, 0.006], [64608.7, 0.039], [64623.2, 0.0], [64623.5, 0.009], [64623.8, 1.986], [64624.1, 0.039], [64624.5, 0.0], [64624.8, 0.375], [64625.3, 0.027], [64626.3, 0.0], [64626.5, 0.01], [64626.6, 8.359], [64626.7, 0.019], [64626.8, 0.002], [64626.9, 0.001], [64627.0, 0.003], [64627.1, 0.011], [64627.2, 0.008], [64627.3, 0.682], [64628.4, 0.154], [64628.6, 0.002], [64628.9, 10.002], [64629.0, 0.007], [64629.1, 0.003], [64631.8, 0.015], [64631.9, 0.057], [64632.0, 0.007], [64632.8, 3.943], [64632.9, 1.64], [64633.0, 4.838], [64634.9, 0.004], [64635.0, 0.021], [64635.1, 0.417], [64636.2, 0.053], [64640.9, 0.002], [64641.3, 0.001], [64641.6, 0.05], [64641.9, 0.002], [64642.2, 0.429], [64923.0, 0.778], [65246.0, 13.779], [65600.0, 70.131]]}
{"kind": "depth", "E": 1787088325109, "U": 11315918151292, "u": 11315918156501, "recv_ms": 1787088325046, "bids": [[1000.0, 35.76], [14199.9, 3.374], [14299.9, 0.826], [58139.9, 0.002], [61369.9, 0.058], [62015.9, 0.001], [63430.5, 0.676], [63857.0, 6.023], [63953.9, 0.008], [63964.7, 6.317], [63973.3, 0.941], [64276.9, 0.745], [64478.8, 0.043], [64478.9, 0.997], [64484.8, 3.871], [64522.3, 0.845], [64523.0, 0.0], [64529.0, 0.059], [64541.7, 0.005], [64554.6, 0.046], [64556.4, 0.033], [64557.3, 0.06], [64588.3, 0.162], [64590.7, 0.07], [64590.9, 0.07], [64591.1, 0.412], [64591.2, 0.137], [64591.3, 0.102], [64591.5, 0.174], [64591.9, 0.033], [64592.9, 0.032], [64599.9, 21.084]], "asks": [[64600.0, 13.42], [64605.4, 0.318], [64605.8, 0.265], [64606.7, 0.054], [64607.1, 0.223], [64607.2, 0.141], [64607.3, 0.602], [64607.5, 0.492], [64607.7, 0.141], [64608.0, 0.147], [64623.5, 0.057], [64624.5, 0.054], [64624.9, 0.222], [64625.3, 0.287], [64626.6, 8.485], [64626.7, 0.259], [64626.9, 0.231], [64627.2, 0.148], [64627.4, 0.237], [64628.4, 0.0], [64641.3, 0.049], [64642.3, 0.054], [64658.2, 0.023], [64665.5, 0.442], [64671.2, 0.046], [64677.6, 0.002], [64729.7, 0.484], [64730.7, 0.0], [64735.3, 3.87], [64923.0, 0.779], [65147.0, 1.052], [65246.0, 13.779], [65375.2, 6.94]]}
{"kind": "depth", "E": 1787088325211, "U": 11315918156545, "u": 11315918160483, "recv_ms": 1787088325148, "bids": [[14099.9, 0.014], [14199.9, 3.696], [14299.9, 0.49], [58139.9, 0.002], [61369.9, 0.058], [63599.9, 0.008], [63953.9, 0.008], [63964.7, 5.615], [64276.9, 0.745], [64456.2, 2.805], [64479.9, 0.0], [64556.7, 0.033], [64557.0, 0.032], [64557.7, 0.04], [64582.8, 0.001], [64584.4, 0.016], [64590.7, 0.14], [64590.8, 0.156], [64591.0, 1.003], [64591.4, 0.1], [64592.2, 0.474], [64592.6, 0.344], [64593.2, 0.033], [64599.9, 21.084]], "asks": [[64605.4, 0.528], [64606.1, 0.378], [64606.4, 0.06], [64607.3, 0.852], [64607.6, 0.261], [64607.9, 0.265], [64612.0, 0.34], [64620.2, 0.463], [64623.2, 0.048], [64623.9, 0.075], [64624.2, 0.067], [64626.7, 0.509], [64627.0, 0.263], [64627.3, 0.941], [64628.4, 0.0], [64630.1, 0.0], [64641.0, 0.127], [64641.6, 0.117], [64642.0, 0.963], [64739.5, 5.407], [65246.0, 13.778], [65600.0, 70.111]]}
{"kind": "depth", "E": 1787088325313, "U": 11315918160630, "u": 11315918169187, "recv_ms": 1787088325249, "bids": [[1000.0, 35.76], [14099.9, 0.168], [14199.9, 3.738], [14299.9, 0.294], [51680.0, 1.939], [58139.9, 0.002], [61369.9, 0.058], [61370.0, 0.012], [62015.9, 0.004], [63953.9, 0.008], [64555.7, 0.586], [64565.3, 0.007], [64582.8, 0.0], [64586.4, 0.002], [64590.9, 0.14], [64591.3, 0.172], [64591.6, 0.085], [64597.9, 0.03], [64599.9, 21.081]], "asks": [[64607.0, 0.15], [64607.4, 0.133], [64607.8, 0.155], [64626.4, 0.177], [64626.8, 0.121], [64627.2, 0.302], [64628.4, 0.0], [65162.0, 0.654], [65246.0, 13.78]]}
{"kind": "depth", "E": 1787088325517, "U": 11315918174825, "u": 11315918179602, "recv_ms": 1787088325454, "bids": [[14099.9, 0.658], [14199.9, 3.486], [14299.9, 0.056], [58139.9, 0.002], [61369.9, 0.058], [62015.9, 0.004], [63599.9, 0.008], [63759.6, 0.0], [63953.9, 0.008], [63964.7, 4.835], [63986.2, 2.103], [64276.9, 0.745], [64536.8, 0.001], [64538.9, 0.037], [64539.2, 1.897], [64539.9, 0.032], [64540.0, 0.085], [64543.3, 0.001], [64549.7, 2.16], [64557.6, 0.043], [64560.8, 0.011], [64564.1, 2.33], [64564.2, 0.535], [64567.0, 0.0], [64567.1, 0.015], [64567.2, 0.0], [64570.5, 2.362], [64570.6, 0.007], [64570.7, 1.242], [64571.4, 0.107], [64571.5, 0.07], [64571.7, 0.104], [64571.9, 0.11], [64572.1, 1.216], [64573.3, 0.105], [64573.8, 0.103], [64581.3, 0.002], [64582.8, 0.001], [64585.0, 36.4], [64597.8, 0.452], [64597.9, 0.021], [64599.0, 0.0], [64599.9, 20.849]], "asks": [[64600.0, 13.418], [64600.7, 0.028], [64600.8, 0.087], [64617.6, 1.012], [64624.9, 0.222], [64628.4, 0.154], [64656.9, 3.823], [64739.2, 1.405], [65246.0, 13.778], [65600.0, 70.111], [65891.9, 0.012]]}
{"kind": "depth", "E": 1787088325619, "U": 11315918179653, "u": 11315918184466, "recv_ms": 1787088325557, "bids": [[1000.0, 35.91], [14099.9, 0.952], [14199.9, 3.248], [14299.9, 0.0], [58139.9, 0.002], [63228.7, 2.37], [63656.7, 0.411], [63795.8, 2.35], [63849.6, 0.782], [63864.5, 0.001], [63953.9, 0.008], [64456.3, 4.149], [64571.3, 0.14], [64571.5, 0.14], [64571.6, 0.101], [64572.0, 0.409], [64582.8, 0.0], [64584.7, 0.004], [64586.5, 0.94], [64586.9, 0.0], [64597.9, 0.031]], "asks": [[64628.3, 0.156], [64628.4, 0.0], [64739.2, 0.686], [64739.5, 5.407], [65246.0, 13.778]]}
{"kind": "depth", "E": 1787088325823, "U": 11315918190615, "u": 11315918195408, "recv_ms": 1787088325760, "bids": [[14099.9, 1.652], [14199.9, 2.548], [51679.9, 0.0], [51680.0, 1.939], [58139.9, 0.002], [62015.9, 0.004], [63599.9, 0.028], [63860.7, 3.29], [63953.9, 0.008], [64276.9, 0.745], [64556.9, 0.005], [64565.3, 0.003], [64571.6, 0.171], [64571.8, 0.22], [64578.0, 0.122], [64583.1, 0.004], [64584.7, 0.003], [64599.9, 20.853]], "asks": [[64615.5, 0.068], [65246.0, 13.778], [65328.4, 0.764], [65424.7, 28.924], [65579.3, 3.276], [65600.0, 70.131], [65746.5, 4.102], [65891.9, 0.015]]}
{"kind": "depth", "E": 1787088325925, "U": 11315918195494, "u": 11315918200337, "recv_ms": 1787088325861, "bids": [[1000.0, 35.76], [14099.9, 2.016], [14199.9, 2.184], [58139.9, 0.002], [61369.9, 0.058], [62015.9, 0.001], [63049.5, 0.0], [63243.3, 0.329], [63682.6, 0.234], [63953.9, 0.008], [64491.0, 0.041], [64491.1, 0.031], [64527.5, 0.0], [64530.1, 0.0], [64587.8, 0.0], [64588.3, 0.704], [64588.7, 0.077], [64595.0, 0.067], [64599.0, 0.084], [64599.4, 0.724], [64599.9, 21.078]], "asks": [[64600.0, 13.334], [64600.8, 0.003], [64601.2, 0.013], [64628.6, 0.156], [64628.7, 0.455], [65246.0, 13.778], [65601.3, 3.198], [65768.6, 4.1]]}
{"kind": "depth", "E": 1787088326129, "U": 11315918206512, "u": 11315918213235, "recv_ms": 1787088326066, "bids": [[14099.9, 2.73], [14199.9, 1.47], [51680.0, 1.939], [58139.9, 0.002], [61369.9, 0.062], [63430.1, 0.787], [63674.1, 35.839], [63792.4, 3.221], [63822.6, 3.65], [63953.9, 0.008], [64276.9, 0.744], [64588.3, 0.704], [64599.9, 21.076]], "asks": [[64600.0, 13.332], [64601.1, 0.001], [64609.8, 1.797], [64612.0, 0.339], [64747.0, 0.0], [64761.7, 0.497], [64781.7, 0.018], [64781.8, 0.005], [65191.8, 5.709], [65246.0, 13.778]]}
{"kind": "depth", "E": 1787088326333, "U": 11315918219637, "u": 11315918225454, "recv_ms": 1787088326270, "bids": [[14099.9, 3.444], [14199.9, 0.756], [51680.0, 1.939], [58139.9, 0.002], [61369.9, 0.064], [62015.9, 0.004], [63391.9, 2.283], [63695.5, 2.548], [63887.2, 3.099], [63953.9, 0.008], [64255.3, 0.0], [64554.6, 0.046], [64581.2, 0.001], [64583.7, 0.12], [64599.5, 1.015]], "asks": [[64600.0, 13.333], [64628.5, 0.166], [64628.6, 0.002], [64658.2, 0.023], [65177.7, 2.385], [65246.0, 13.778], [65392.4, 20.594], [66531.6, 0.0]]}
{"kind": "depth", "E": 1787088326435, "U": 11315918225482, "u": 11315918230499, "recv_ms": 1787088326374, "bids": [[14099.9, 3.724], [14199.9, 0.434], [14499.9, 0.042], [58139.9, 0.002], [61369.9, 0.066], [62015.9, 0.001], [63599.9, 0.008], [63844.1, 2.192], [63953.9, 0.008], [64255.4, 0.514], [64276.9, 0.735], [64456.4, 3.066], [64486.2, 1.485], [64554.5, 0.001], [64554.8, 6.041], [64556.9, 0.005], [64565.2, 0.003], [64578.8, 0.092], [64581.2, 0.0]], "asks": [[64600.0, 13.328], [64628.5, 0.012], [64628.8, 0.157], [64629.4, 0.002], [64631.1, 3.377], [64739.2, 1.405], [64739.5, 0.001], [64739.6, 5.406], [64746.6, 0.001], [65246.0, 13.778], [65360.1, 60.526], [65600.0, 70.111]]}
{"kind": "depth", "E": 1787088326639, "U": 11315918235705, "u": 11315918240274, "recv_ms": 1787088326576, "bids": [[14099.9, 3.57], [14199.9, 0.154], [14499.9, 0.476], [58139.9, 0.002], [61369.9, 0.072], [63599.9, 0.028], [63663.2, 6.89], [63953.9, 0.008], [64456.4, 0.0], [64456.5, 3.088], [64521.7, 0.0], [64523.9, 0.017], [64526.1, 33.669], [64535.3, 0.003], [64564.3, 0.001], [64571.6, 0.171], [64580.2, 0.0], [64583.2, 0.008], [64599.9, 21.079]], "asks": [[64600.0, 13.41], [64601.6, 0.01], [64605.0, 0.096], [64625.0, 0.083], [64664.6, 0.002], [64739.6, 5.406], [65181.4, 1.152], [65246.0, 13.778], [65393.0, 1.158], [65521.6, 37.265], [65600.0, 70.131]]}
{"kind": "depth", "E": 1787088326741, "U": 11315918240509, "u": 11315918245030, "recv_ms": 1787088326678, "bids": [[14099.9, 3.458], [14199.9, 0.028], [14499.9, 0.714], [58139.9, 0.002], [62015.9, 0.001], [63308.0, 0.807], [63874.3, 3.608], [63953.9, 0.008], [64276.9, 0.745], [64524.6, 1.501], [64556.9, 0.005], [64565.2, 0.003], [64571.5, 0.197], [64572.2, 0.074], [64580.1, 5.921], [64581.0, 0.02], [64581.1, 0.6], [64582.0, 0.003], [64583.2, 0.007], [64585.3, 6.313], [64586.0, 1.878], [64586.1, 0.542], [64586.5, 0.013], [64586.6, 0.002], [64588.3, 0.162]], "asks": [[64602.0, 0.033], [64605.3, 0.086], [64616.8, 0.633], [64617.5, 0.544], [64618.0, 0.021], [64621.3, 0.557], [64622.2, 0.0], [64622.8, 0.14], [64623.8, 1.986], [65246.0, 13.778], [65536.7, 2.248], [66070.6, 3.93]]}
{"kind": "depth", "E": 1787088326843, "U": 11315918245068, "u": 11315918248773, "recv_ms": 1787088326780, "bids": [[1000.0, 35.76], [14099.9, 3.164], [14199.9, 0.0], [14499.9, 1.036], [51679.9, 0.0], [58139.9, 0.0], [61369.9, 0.072], [61995.1, 3.458], [62015.9, 0.004], [63599.9, 0.008], [63953.9, 0.008], [63986.2, 3.552], [64576.9, 0.023], [64583.1, 0.004], [64585.3, 6.312], [64586.1, 0.0], [64588.3, 0.704], [64599.9, 21.118]], "asks": [[64600.0, 13.398], [64602.2, 0.108], [64615.5, 0.068], [64617.5, 0.002], [64618.0, 0.563], [64621.3, 0.0], [64622.2, 0.557], [65246.0, 13.778], [65600.0, 70.111]]}
{"kind": "depth", "E": 1787088326945, "U": 11315918248775, "u": 11315918252551, "recv_ms": 1787088326882, "bids": [[14099.9, 2.814], [14499.9, 1.386], [58139.9, 0.002], [62015.9, 0.001], [63583.9, 26.076], [63648.5, 38.927], [63816.4, 2.831], [63895.8, 1.721], [63953.9, 0.008], [64209.2, 0.0], [64259.6, 0.001], [64259.7, 0.492]], "asks": [[65246.0, 13.778], [65553.9, 28.21], [65564.0, 0.362]]}
{"kind": "depth", "E": 1787088327149, "U": 11315918259005, "u": 11315918264379, "recv_ms": 1787088327140, "bids": [[1000.0, 35.76], [14099.9, 2.086], [14499.9, 2.114], [58139.9, 0.002], [62015.9, 0.004], [63598.6, 4.889], [63663.2, 7.987], [63831.2, 2.844], [63953.9, 0.008], [64083.1, 2.188], [64276.9, 0.744], [64456.5, 0.022], [64484.8, 0.001], [64529.0, 0.013], [64557.5, 0.006], [64565.2, 0.003], [64588.3, 0.704]], "asks": [[64671.2, 0.0], [64735.3, 0.0], [64739.6, 0.0], [64923.0, 0.778], [65246.0, 13.778], [65578.4, 0.266]]}
{"kind": "depth", "E": 1787088327251, "U": 11315918264430, "u": 11315918269186, "recv_ms": 1787088327189, "bids": [[14099.9, 1.736], [14499.9, 2.464], [58139.9, 0.002], [61369.9, 0.072], [62015.9, 0.001], [63448.1, 1.259], [63599.9, 0.008], [63810.0, 70.556], [63953.9, 0.008], [63986.2, 4.253], [64083.1, 2.184], [64234.7, 0.005], [64276.9, 0.745], [64439.2, 0.004], [64440.0, 1.705], [64484.7, 3.87], [64486.2, 1.045], [64528.9, 0.046], [64557.5, 0.002], [64565.2, 0.007], [64580.1, 5.805], [64580.6, 0.117], [64599.9, 21.118]], "asks": [[64671.2, 0.046], [64735.3, 3.87], [64739.2, 0.686], [64756.4, 0.0], [64923.0, 0.779], [65246.0, 13.778], [65528.0, 1.522], [65553.9, 27.867], [65569.0, 8.429], [65600.0, 70.111], [65747.3, 1.963]]}
{"kind": "depth", "E": 1787088327353, "U": 11315918269299, "u": 11315918274174, "recv_ms": 1787088327289, "bids": [[1000.0, 35.76], [14099.9, 1.386], [14499.9, 2.814], [58139.9, 0.002], [62015.9, 0.004], [63577.2, 7.544], [63599.9, 0.028], [63695.5, 2.736], [63785.1, 3.049], [63860.3, 0.0], [63874.3, 2.905], [63953.9, 0.008], [64276.9, 0.745], [64400.5, 0.0], [64555.7, 0.59], [64565.2, 0.003], [64576.9, 0.022], [64578.8, 0.092], [64599.5, 0.931]], "asks": [[64601.0, 0.086], [64605.3, 0.002], [64795.2, 0.001], [65246.0, 13.778], [65569.0, 8.772], [65600.0, 70.131]]}
{"kind": "depth", "E": 1787088327455, "U": 11315918274264, "u": 11315918279389, "recv_ms": 1787088327392, "bids": [[1000.0, 35.76], [14099.9, 1.022], [14499.9, 3.178], [58139.9, 0.002], [62015.9, 0.001], [63042.9, 0.679], [63469.4, 1.261], [63598.6, 5.988], [63810.0, 70.337], [63817.4, 0.787], [63882.3, 0.786], [63953.9, 0.008], [64486.2, 1.485], [64575.0, 0.009], [64578.8, 0.091], [64581.1, 0.043], [64581.5, 0.559], [64581.9, 0.061]], "asks": [[64601.0, 0.002], [64617.5, 0.002], [64618.0, 0.563], [64638.8, 0.0], [64757.2, 0.475], [65246.0, 13.778], [65360.7, 0.78], [65375.2, 7.918], [65414.8, 0.763], [65543.2, 0.963]]}
{"kind": "depth", "E": 1787088327557, "U": 11315918279493, "u": 11315918284504, "recv_ms": 1787088327494, "bids": [[14099.9, 0.672], [14499.9, 3.528], [58139.9, 0.002], [61369.9, 0.072], [63953.9, 0.008], [64564.2, 1.154], [64571.6, 0.79], [64575.0, 0.008], [64579.8, 0.001], [64597.9, 0.031], [64599.7, 0.105], [64599.9, 21.118]], "asks": [[64601.7, 0.0], [64617.6, 1.012], [64625.0, 0.702], [64636.2, 0.039], [64971.6, 0.0], [65246.0, 13.778], [65350.2, 0.764], [65891.9, 0.015]]}
{"kind": "depth", "E": 1787088327659, "U": 11315918284681, "u": 11315918290070, "recv_ms": 1787088327596, "bids": [[1000.0, 35.76], [14099.9, 0.378], [14399.9, 0.07], [14499.9, 3.752], [51680.0, 1.939], [58139.9, 0.002], [62015.9, 0.004], [63599.9, 0.008], [63810.0, 69.556], [63895.8, 2.423], [63953.9, 0.008], [64068.3, 3.614], [64262.1, 2.107], [64276.9, 0.735], [64536.7, 0.093], [64536.8, 2.344], [64554.6, 0.046], [64571.2, 0.12], [64579.8, 0.0], [64584.5, 0.008], [64585.0, 35.875], [64587.7, 0.002]], "asks": [[64658.2, 0.023], [64662.6, 1.876], [65246.0, 13.778], [65376.7, 1.711], [65600.0, 70.111], [65891.9, 0.012]]}
{"kind": "depth", "E": 1787088327761, "U": 11315918290105, "u": 11315918294967, "recv_ms": 1787088327698, "bids": [[1000.0, 35.76], [14099.9, 0.238], [14399.9, 0.28], [14499.9, 3.682], [58139.9, 0.002], [62015.9, 0.001], [63551.6, 9.666], [63953.9, 0.008], [64175.9, 0.001], [64400.8, 8.518], [64439.6, 4.744], [64440.0, 2.193], [64456.5, 3.638], [64521.7, 33.698], [64526.1, 0.001], [64571.2, 1.094], [64580.6, 0.117], [64581.6, 0.002], [64597.9, 0.021]], "asks": [[64617.5, 0.544], [64618.0, 0.021], [64618.9, 0.08], [64619.0, 0.623], [64619.9, 1.087], [64622.2, 0.0], [64622.8, 0.697], [64623.8, 1.87], [64624.4, 0.758], [64636.2, 0.053], [64739.6, 5.406], [64756.5, 10.424], [64795.3, 13.339], [65213.7, 1.423], [65246.0, 13.778]]}
{"kind": "depth", "E": 1787088327863, "U": 11315918295239, "u": 11315918299937, "recv_ms": 1787088327801, "bids": [[14099.9, 0.126], [14399.9, 0.532], [14499.9, 3.542], [51679.9, 0.0], [58139.9, 0.002], [61364.2, 0.022], [61369.9, 0.072], [62015.9, 0.004], [63512.7, 0.002], [63599.9, 0.028], [63616.2, 29.814], [63695.5, 5.088], [63824.7, 6.321], [63953.9, 0.008], [64083.1, 2.496], [64175.9, 0.002], [64276.9, 0.89], [64521.7, 0.0], [64523.9, 33.715], [64578.5, 0.008], [64583.1, 0.004], [64584.5, 0.007], [64586.3, 0.005], [64587.6, 0.003], [64597.9, 0.031], [64599.9, 21.118]], "asks": [[64607.0, 0.149], [64608.3, 0.284], [64611.9, 0.0], [64615.5, 0.068], [64997.5, 0.006], [65246.0, 13.778], [65248.3, 1.155], [65600.0, 70.131]]}
{"kind": "depth", "E": 1787088327965, "U": 11315918300078, "u": 11315918305499, "recv_ms": 1787088327901, "bids": [[1000.0, 35.76], [14099.9, 0.0], [14399.9, 0.756], [14499.9, 3.444], [58139.9, 0.002], [61369.9, 0.072], [62015.9, 0.001], [63566.3, 2.201], [63953.9, 0.008], [63964.7, 3.51], [64175.9, 0.003], [64259.7, 0.0], [64259.8, 0.625], [64276.9, 0.89], [64413.6, 0.6], [64592.3, 0.009], [64599.9, 21.119]], "asks": [[65246.0, 13.778], [65424.7, 28.619], [65517.3, 0.456]]}
{"kind": "depth", "E": 1787088328067, "U": 11315918305566, "u": 11315918309942, "recv_ms": 1787088328005, "bids": [[1000.0, 35.76], [14399.9, 1.12], [14499.9, 3.08], [58139.9, 0.002], [61369.9, 0.072], [63534.0, 3.302], [63599.9, 0.008], [63810.0, 67.678], [63953.9, 0.008], [64175.9, 0.004], [64439.6, 3.502], [64456.5, 0.022], [64456.6, 3.003], [64555.7, 0.586], [64568.6, 0.042], [64588.3, 0.704], [64588.7, 0.085], [64589.3, 0.0], [64592.3, 0.008], [64599.9, 21.213]], "asks": [[64600.0, 13.399], [64625.0, 0.083], [64739.6, 5.406], [64756.5, 0.0], [64756.6, 10.454], [65191.8, 5.051], [65246.0, 13.778], [65600.0, 70.111], [65891.9, 0.015]]}
{"kind": "depth", "E": 1787088328271, "U": 11315918314117, "u": 11315918318812, "recv_ms": 1787088328207, "bids": [[1000.0, 35.76], [14399.9, 1.82], [14499.9, 2.38], [51680.0, 1.939], [58139.9, 0.002], [61369.9, 0.072], [62015.9, 0.001], [63599.9, 0.028], [63731.3, 1.584], [63824.7, 7.103], [63953.9, 0.008], [64276.9, 0.889], [64456.6, 0.054], [64580.9, 0.006], [64582.3, 0.002], [64592.4, 0.004], [64599.9, 21.213]], "asks": [[64622.0, 0.558], [64622.8, 0.14], [64623.7, 0.117], [64624.4, 0.642], [64739.6, 0.0], [64923.0, 0.778], [65246.0, 13.778], [65407.5, 2.348], [65439.8, 1.831], [65482.4, 43.322], [65600.0, 70.131], [65746.5, 0.002]]}
{"kind": "depth", "E": 1787088328373, "U": 11315918318948, "u": 11315918323423, "recv_ms": 1787088328310, "bids": [[1000.0, 35.76], [14399.9, 2.198], [14499.9, 2.002], [51680.0, 1.939], [58139.9, 0.002], [61369.9, 0.072], [62015.9, 0.004], [63824.7, 8.98], [63953.9, 0.008], [64276.9, 0.89], [64439.6, 0.0], [64592.3, 0.009], [64592.4, 0.003], [64599.9, 21.213]], "asks": [[64617.5, 0.002], [64618.0, 0.563], [64628.7, 0.609], [64628.8, 0.003], [64756.6, 0.03], [64923.0, 0.779], [65246.0, 13.778], [65414.8, 1.526]]}
{"kind": "depth", "E": 1787088328475, "U": 11315918323505, "u": 11315918327763, "recv_ms": 1787088328413, "bids": [[14399.9, 2.548], [14499.9, 1.652], [58139.9, 0.002], [61369.9, 0.074], [63599.9, 0.008], [63860.4, 3.15], [63953.9, 0.008], [64439.7, 4.737], [64440.0, 1.705], [64456.6, 3.629], [64484.7, 3.87], [64524.6, 6.362], [64528.9, 0.046], [64541.7, 0.008], [64557.5, 0.006], [64568.6, 0.038], [64580.6, 0.117], [64581.5, 0.002], [64581.6, 0.002], [64581.7, 0.557], [64582.6, 0.0], [64592.3, 0.009], [64592.4, 0.003], [64594.3, 0.003], [64594.5, 0.0], [64599.9, 21.214]], "asks": [[64617.5, 0.544], [64618.0, 0.021], [64618.9, 0.08], [64622.0, 0.001], [64622.8, 0.697], [64623.7, 0.001], [64624.4, 0.758], [64628.6, 0.002], [64628.7, 0.455], [64629.1, 1.888], [64629.2, 0.005], [64671.2, 0.046], [64677.6, 0.005], [64729.2, 0.022], [64735.3, 3.87], [64739.2, 1.405], [64739.6, 5.406], [64756.6, 10.454], [65246.0, 13.778], [65504.4, 7.956], [65600.0, 70.111], [66085.8, 0.604]]}
{"kind": "depth", "E": 1787088328781, "U": 11315918338036, "u": 11315918342652, "recv_ms": 1787088328719, "bids": [[14399.9, 3.612], [14499.9, 0.588], [51679.9, 0.0], [51680.0, 1.939], [58139.9, 0.002], [61369.9, 0.074], [62015.9, 0.691], [63021.7, 1.358], [63583.9, 24.976], [63795.8, 1.567], [63953.9, 0.008], [64400.8, 0.002], [64400.9, 8.382], [64439.7, 4.759], [64456.6, 3.325], [64536.8, 2.367], [64555.7, 0.59], [64564.2, 0.535], [64565.2, 0.003], [64571.6, 0.171], [64582.9, 0.013], [64585.4, 0.464], [64585.5, 0.025], [64585.8, 0.525], [64586.1, 0.927], [64586.2, 0.0], [64586.3, 0.005], [64586.6, 0.002], [64586.7, 0.0], [64588.1, 2.863], [64588.3, 0.162], [64588.5, 0.748], [64599.9, 21.219]], "asks": [[64609.8, 1.796], [64618.7, 1.253], [64619.9, 0.161], [64624.8, 0.375], [64636.2, 0.053], [64662.6, 1.873], [65246.0, 13.778], [65353.2, 23.53], [65482.4, 41.035]]}
{"kind": "depth", "E": 1787088329087, "U": 11315918351890, "u": 11315918357175, "recv_ms": 1787088329024, "bids": [[14299.9, 0.588], [14399.9, 3.514], [14499.9, 0.098], [58139.9, 0.002], [61369.9, 0.072], [61370.0, 0.014], [62015.9, 0.691], [63599.9, 0.028], [63953.9, 0.008], [64491.1, 0.028], [64491.2, 0.003], [64585.8, 0.0], [64588.3, 0.162], [64588.5, 0.108], [64599.9, 21.219]], "asks": [[64600.0, 13.456], [64601.4, 0.09], [64602.0, 0.014], [64602.2, 0.086], [64617.5, 0.002], [64618.0, 0.563], [64618.7, 0.327], [64619.3, 1.007], [64907.9, 0.211], [64908.0, 1.077], [65191.8, 4.363], [65246.0, 13.778], [65600.0, 70.131], [65941.4, 2.284]]}
{"kind": "depth", "E": 1787088329189, "U": 11315918357368, "u": 11315918363567, "recv_ms": 1787088329125, "bids": [[1000.0, 35.76], [14299.9, 0.84], [14399.9, 3.36], [14499.9, 0.0], [51680.0, 1.939], [58139.9, 0.002], [61369.9, 0.072], [62015.9, 0.694], [62970.4, 7.14], [63308.0, 0.81], [63824.7, 9.199], [63831.2, 3.783], [63881.9, 0.782], [63953.9, 0.008], [64037.9, 1.17], [64276.9, 0.89], [64456.6, 0.054], [64456.7, 3.576], [64586.1, 0.0], [64587.1, 0.928], [64588.7, 0.077], [64589.0, 0.333], [64589.3, 0.008], [64590.1, 0.109], [64592.3, 0.009], [64599.0, 0.0], [64599.9, 21.215]], "asks": [[64601.0, 0.086], [64611.0, 1.396], [64628.6, 0.002], [64628.8, 0.003], [64739.6, 5.406], [65213.7, 2.111], [65246.0, 13.778], [65392.4, 20.138], [65748.1, 0.76]]}
{"kind": "depth", "E": 1787088329291, "U": 11315918363847, "u": 11315918369546, "recv_ms": 1787088329228, "bids": [[1000.0, 35.76], [14299.9, 1.204], [14399.9, 2.996], [58139.9, 0.002], [61369.9, 0.074], [62015.9, 0.691], [63599.9, 0.008], [63953.9, 0.009], [64275.8, 0.109], [64588.8, 0.255], [64599.1, 0.124], [64599.9, 21.225]], "asks": [[64601.0, 0.002], [64601.2, 0.025], [64622.2, 0.557], [64622.8, 0.14], [64628.9, 10.156], [64923.0, 1.394], [64933.3, 0.139], [65246.0, 13.778], [65600.0, 70.111], [65711.1, 1.142], [71060.0, 0.0]]}
{"kind": "depth", "E": 1787088329495, "U": 11315918377126, "u": 11315918382429, "recv_ms": 1787088329431, "bids": [[1000.0, 35.76], [14299.9, 1.918], [14399.9, 2.282], [58139.9, 0.002], [63599.9, 0.028], [63953.9, 0.009], [64276.9, 0.9], [64439.7, 0.058], [64456.7, 0.0], [64599.1, 0.04]], "asks": [[64600.8, 0.087], [64739.2, 0.686], [64739.6, 0.0], [64756.6, 0.03], [64923.0, 1.394], [65246.0, 13.778], [65417.8, 23.408], [65482.4, 38.747], [65600.0, 70.131]]}
{"kind": "depth", "E": 1787088329597, "U": 11315918382584, "u": 11315918387255, "recv_ms": 1787088329534, "bids": [[1000.0, 35.76], [14299.9, 2.268], [14399.9, 1.932], [51680.0, 1.939], [58139.9, 0.002], [61369.9, 0.072], [61370.0, 0.016], [62015.9, 0.691], [63308.0, 0.813], [63810.0, 66.975], [63953.9, 0.009], [64400.9, 0.0], [64401.0, 9.318], [64439.8, 3.657], [64456.7, 3.085], [64564.2, 1.154], [64565.2, 0.003], [64571.6, 0.79], [64577.2, 1.238], [64578.9, 0.005], [64599.0, 0.0], [64599.9, 21.225]], "asks": [[64600.8, 0.003], [64601.0, 0.086], [64603.7, 0.041], [64606.8, 0.006], [64608.5, 0.016], [64617.6, 1.012], [64625.0, 0.702], [64739.2, 1.405], [64739.6, 5.406], [64756.6, 10.454], [64795.3, 15.054], [65101.8, 2.529], [65246.0, 13.778], [65439.8, 2.747], [65457.0, 18.692]]}
{"kind": "depth", "E": 1787088329699, "U": 11315918387312, "u": 11315918391196, "recv_ms": 1787088329636, "bids": [[14299.9, 2.632], [14399.9, 1.568], [51680.0, 1.939], [58139.9, 0.002], [62015.9, 0.694], [63308.0, 0.81], [63599.9, 0.008], [63663.2, 10.026], [63953.9, 0.009], [64276.9, 0.89], [64456.7, 0.0], [64520.4, 0.442], [64541.7, 0.008], [64557.5, 0.006], [64572.7, 0.0], [64577.2, 1.237], [64580.2, 0.001], [64586.1, 0.927], [64587.1, 0.001], [64587.2, 0.766], [64588.1, 2.321], [64599.1, 0.124]], "asks": [[64601.0, 0.002], [64623.2, 0.164], [64624.4, 0.642], [64677.6, 0.005], [64739.6, 0.0], [65246.0, 13.778], [65600.0, 70.111]]}
{"kind": "depth", "E": 1787088329801, "U": 11315918391331, "u": 11315918399033, "recv_ms": 1787088329739, "bids": [[1000.0, 35.76], [14299.9, 2.982], [14399.9, 1.218], [51679.9, 0.0], [51680.0, 1.939], [58139.9, 0.002], [61369.9, 0.073], [62015.9, 0.691], [63745.4, 27.881], [63824.7, 9.902], [63953.9, 0.009], [64456.7, 3.69], [64556.9, 0.005], [64557.5, 0.002], [64562.0, 0.083], [64580.2, 0.0], [64586.2, 0.0], [64587.2, 0.224], [64588.1, 2.863], [64592.3, 0.009], [64594.3, 0.003], [64594.5, 0.0], [64599.9, 21.225]], "asks": [[64612.1, 0.056], [64739.6, 5.406], [65116.8, 3.408], [65213.7, 2.768], [65246.0, 13.778], [65472.1, 1.051], [65564.0, 0.095], [65891.9, 0.018]]}
{"kind": "depth", "E": 1787088329903, "U": 11315918399119, "u": 11315918406022, "recv_ms": 1787088329840, "bids": [[1000.0, 35.76], [14299.9, 3.346], [14399.9, 0.854], [58139.9, 0.002], [61369.9, 0.071], [61370.0, 0.018], [63599.9, 0.028], [63616.2, 29.5], [63816.4, 0.953], [63831.2, 4.722], [63953.9, 0.009], [64456.7, 0.0], [64523.9, 0.017], [64526.1, 33.746], [64583.1, 0.004], [64599.1, 0.04]], "asks": [[64600.0, 13.459], [64601.0, 0.086], [64615.5, 0.068], [64739.2, 0.686], [64739.6, 0.0], [65246.0, 13.778], [65600.0, 70.131]]}
{"kind": "depth", "E": 1787088330005, "U": 11315918406205, "u": 11315918412599, "recv_ms": 1787088329942, "bids": [[14299.9, 3.696], [14399.9, 0.504], [58139.9, 0.0], [61369.9, 0.07], [62015.9, 0.694], [63752.8, 0.784], [63760.1, 0.316], [63953.9, 0.009], [64276.9, 0.9], [64456.8, 2.562], [64521.7, 33.745], [64523.9, 0.017], [64526.1, 0.001], [64597.9, 0.021]], "asks": [[64600.0, 13.461], [64623.2, 0.048], [64623.7, 0.117], [64739.7, 5.416], [65246.0, 13.778], [65296.2, 1.53], [65392.4, 19.985], [65425.3, 0.763], [65578.4, 0.533], [65768.6, 8.199]]}
{"kind": "depth", "E": 1787088330107, "U": 11315918412605, "u": 11315918422291, "recv_ms": 1787088330044, "bids": [[1000.0, 35.76], [14199.9, 0.168], [14299.9, 3.724], [14399.9, 0.308], [58139.9, 0.002], [61369.9, 0.07], [62015.9, 0.691], [63953.9, 0.009], [64068.3, 2.679], [64262.1, 1.485], [64505.9, 0.004], [64521.7, 0.0], [64524.6, 1.501], [64526.1, 33.769], [64527.0, 5.311], [64527.5, 0.018], [64535.9, 0.007], [64552.6, 3.043], [64552.8, 0.069], [64564.2, 0.535], [64566.4, 0.026], [64571.6, 0.171], [64576.4, 0.095], [64588.3, 0.162], [64595.0, 0.151], [64597.9, 0.021], [64598.5, 0.006], [64599.9, 21.225]], "asks": [[64600.0, 14.795], [64600.6, 0.091], [64602.9, 0.003], [64604.9, 0.002], [64605.0, 0.012], [64605.5, 0.088], [64622.4, 2.602], [64623.3, 2.348], [64623.8, 11.87], [64625.0, 0.083], [64626.4, 0.641], [64628.9, 0.156], [64636.2, 0.039], [64654.3, 0.014], [64656.2, 0.061], [64656.3, 0.002], [64656.9, 3.767], [65246.0, 13.778], [65327.8, 0.018]]}
{"kind": "depth", "E": 1787088330413, "U": 11315918446629, "u": 11315918453319, "recv_ms": 1787088330350, "bids": [[1000.0, 35.76], [14199.9, 0.938], [14299.9, 3.262], [14399.9, 0.0], [58139.9, 0.002], [63308.0, 0.813], [63599.9, 0.028], [63630.9, 0.667], [63953.9, 0.008], [64083.1, 3.431], [64276.9, 1.511], [64456.8, 0.0], [64564.5, 0.175], [64592.1, 1.563], [64594.3, 0.003], [64594.5, 0.0], [64594.6, 0.004], [64597.9, 0.031]], "asks": [[64630.3, 0.266], [64739.7, 0.01], [64923.0, 1.393], [65246.0, 13.778], [65600.0, 70.131]]}
{"kind": "depth", "E": 1787088330821, "U": 11315918473627, "u": 11315918480114, "recv_ms": 1787088330758, "bids": [[1000.0, 35.76], [14199.9, 2.366], [14299.9, 1.834], [51679.9, 0.0], [58139.9, 0.002], [61369.9, 0.07], [63599.9, 0.028], [63803.3, 27.701], [63824.7, 11.153], [63953.9, 0.008], [64456.8, 3.259], [64565.0, 0.002], [64572.3, 1.204], [64599.1, 0.0], [64599.9, 20.571]], "asks": [[64618.4, 0.011], [64625.7, 0.005], [64628.9, 0.002], [64739.7, 5.416], [65246.0, 13.778], [65600.0, 70.131], [65770.1, 0.759], [65891.9, 0.012]]}
{"kind": "depth", "E": 1787088331025, "U": 11315918485990, "u": 11315918491619, "recv_ms": 1787088330962, "bids": [[1000.0, 35.76], [14199.9, 3.08], [14299.9, 1.12], [58139.9, 0.002], [61369.9, 0.07], [62015.9, 0.694], [63599.9, 0.008], [63666.7, 0.785], [63860.4, 2.368], [63953.9, 0.008], [64401.1, 6.333], [64401.2, 8.223], [64439.9, 4.685], [64456.8, 0.0], [64456.9, 2.736], [64536.8, 0.001], [64536.9, 4.311], [64567.0, 0.002], [64567.1, 0.017], [64567.2, 0.002], [64570.5, 2.364], [64570.6, 0.009], [64570.7, 1.244], [64597.9, 0.021], [64599.4, 0.656]], "asks": [[64600.0, 14.931], [64601.3, 0.001], [64602.2, 0.086], [64609.9, 0.278], [64610.0, 0.026], [64615.3, 0.003], [64626.2, 0.288], [64662.6, 1.88], [64739.7, 5.416], [65246.0, 13.778], [65600.0, 70.111]]}
{"kind": "depth", "E": 1787088331229, "U": 11315918499750, "u": 11315918506318, "recv_ms": 1787088331166, "bids": [[14099.9, 0.028], [14199.9, 3.724], [14299.9, 0.448], [51680.0, 1.941], [58139.9, 0.002], [62015.9, 0.694], [63599.9, 0.028], [63777.7, 28.592], [63867.7, 4.066], [63953.9, 0.008], [64276.9, 1.512], [64456.9, 2.742], [64585.0, 33.252], [64592.1, 1.563], [64594.3, 0.003], [64594.5, 0.0], [64594.6, 0.004], [64599.9, 20.346]], "asks": [[64629.0, 2.046], [64629.1, 0.003], [64739.7, 5.416], [65246.0, 13.778], [65504.4, 12.53], [65600.0, 70.131], [65891.9, 0.009]]}
{"kind": "depth", "E": 1787088331331, "U": 11315918506539, "u": 11315918513741, "recv_ms": 1787088331268, "bids": [[1000.0, 35.76], [14099.9, 0.224], [14199.9, 3.696], [14299.9, 0.28], [51680.0, 1.939], [58139.9, 0.002], [61369.9, 0.068], [61370.0, 0.018], [63599.9, 0.008], [63953.9, 0.008], [64528.2, 0.019], [64530.4, 33.742], [64532.7, 0.163], [64577.9, 0.004], [64579.7, 0.0], [64580.6, 0.001], [64581.0, 0.136], [64581.1, 0.043], [64581.7, 0.0], [64582.0, 0.56], [64586.2, 0.0], [64588.1, 2.321], [64588.3, 0.704], [64597.9, 0.021], [64598.7, 0.084], [64599.9, 20.146]], "asks": [[64600.6, 0.007], [64601.0, 0.002], [64601.1, 0.001], [64601.3, 0.0], [64602.9, 0.003], [64616.8, 0.633], [64617.5, 0.002], [64618.0, 0.563], [64618.3, 0.019], [64619.2, 2.112], [64619.3, 0.081], [64621.3, 0.0], [64622.2, 0.557], [65246.0, 13.78], [65482.4, 36.459], [65502.2, 3.195], [65527.6, 0.535], [65600.0, 70.111]]}
{"kind": "depth", "E": 1787088331433, "U": 11315918513744, "u": 11315918519665, "recv_ms": 1787088331378, "bids": [[14099.9, 0.462], [14199.9, 3.584], [14299.9, 0.154], [51680.0, 1.939], [58139.9, 0.002], [61369.9, 0.068], [62015.9, 0.691], [63953.9, 0.01], [64523.9, 0.017], [64524.6, 0.25], [64524.9, 0.007], [64527.0, 0.025], [64528.2, 33.76], [64529.9, 0.002], [64530.4, 0.001], [64533.8, 0.0], [64537.6, 0.005], [64538.6, 0.214], [64538.9, 0.005], [64539.2, 1.865], [64539.6, 0.0], [64539.9, 0.0], [64540.5, 0.314], [64541.7, 0.005], [64543.6, 0.004], [64545.9, 0.0], [64550.2, 0.002], [64553.3, 0.001], [64554.6, 0.046], [64555.6, 0.0], [64556.4, 0.001], [64556.5, 0.032], [64556.7, 0.001], [64557.0, 0.0], [64557.3, 0.028], [64557.5, 0.034], [64557.7, 0.008], [64559.1, 0.003], [64563.1, 1.325], [64564.2, 0.0], [64564.7, 0.072], [64569.4, 0.0], [64571.3, 0.0], [64571.4, 0.037], [64571.5, 0.057], [64571.6, 0.001], [64571.7, 0.004], [64571.8, 0.12], [64571.9, 0.01], [64572.0, 0.309], [64572.1, 0.003], [64572.2, 0.004], [64573.3, 0.005], [64573.8, 0.003], [64575.9, 0.005], [64578.7, 0.011], [64580.1, 0.803], [64580.3, 5.003], [64581.5, 0.559], [64582.0, 0.003], [64582.1, 0.0], [64585.3, 0.022], [64588.6, 0.017], [64590.7, 0.0], [64590.8, 0.156], [64590.9, 0.0], [64591.0, 0.903], [64591.1, 0.382], [64591.2, 0.037], [64591.3, 0.002], [64591.4, 0.0], [64591.5, 0.004], [64591.6, 0.015], [64591.8, 0.006], [64591.9, 0.001], [64592.1, 1.595], [64592.2, 0.442], [64592.4, 0.004], [64592.6, 0.312], [64592.9, 0.0], [64593.1, 0.344], [64593.2, 0.001], [64594.2, 0.0], [64597.9, 0.031], [64599.5, 0.332], [64599.9, 18.129]], "asks": [[64605.4, 0.002], [64605.8, 0.265], [64606.1, 0.311], [64606.4, 0.002], [64606.7, 0.0], [64606.8, 0.06], [64607.0, 0.002], [64607.1, 0.003], [64607.2, 0.015], [64607.3, 0.362], [64607.4, 0.014], [64607.5, 0.002], [64607.6, 0.001], [64607.7, 0.001], [64607.8, 0.134], [64607.9, 0.006], [64608.0, 0.014], [64608.1, 0.135], [64608.6, 0.107], [64611.7, 0.019], [64615.2, 0.165], [64618.1, 0.0], [64619.1, 2.321], [64620.6, 10.103], [64622.4, 0.002], [64623.2, 0.0], [64623.5, 0.009], [64623.6, 0.077], [64623.9, 0.008], [64624.2, 0.009], [64624.5, 0.0], [64624.6, 0.094], [64624.9, 0.002], [64625.3, 0.027], [64625.5, 0.006], [64626.4, 0.494], [64626.6, 8.359], [64626.7, 0.019], [64626.8, 0.002], [64626.9, 0.001], [64627.0, 0.003], [64627.1, 0.011], [64627.2, 0.141], [64627.3, 0.682], [64627.4, 0.104], [64627.5, 0.286], [64627.6, 0.064], [64641.0, 0.079], [64641.3, 0.001], [64641.4, 0.049], [64641.6, 0.05], [64642.0, 0.905], [64642.3, 0.0], [64642.4, 0.084], [64658.2, 0.023], [64677.6, 0.002], [65246.0, 13.778], [65504.4, 14.817]]}
{"kind": "depth", "E": 1787088331535, "U": 11315918519689, "u": 11315918531602, "recv_ms": 1787088331483, "bids": [[14099.9, 0.7], [14199.9, 3.458], [14299.9, 0.042], [58139.9, 0.002], [61369.9, 0.066], [61370.0, 0.02], [62015.9, 0.694], [63953.9, 0.008], [64132.9, 0.021], [64156.8, 0.003], [64158.6, 0.0], [64162.7, 0.0], [64165.7, 0.005], [64169.6, 0.002], [64170.8, 0.086], [64175.3, 0.0], [64178.2, 0.007], [64181.7, 0.0], [64185.1, 0.0], [64188.1, 0.26], [64190.3, 0.013], [64194.1, 0.001], [64198.1, 0.002], [64200.1, 0.0], [64204.3, 0.003], [64206.8, 0.008], [64211.1, 0.022], [64213.9, 0.001], [64216.1, 0.0], [64220.3, 0.001], [64222.1, 0.0], [64226.2, 0.003], [64230.1, 0.552], [64231.2, 0.0], [64233.1, 0.0], [64235.1, 0.004], [64239.8, 0.003], [64243.0, 0.011], [64245.2, 0.0], [64249.6, 0.0], [64250.1, 0.808], [64255.4, 0.024], [64258.8, 0.105], [64261.4, 0.0], [64265.1, 0.032], [64268.1, 0.0], [64271.1, 0.002], [64275.1, 0.0], [64276.9, 1.522], [64277.1, 0.01], [64281.1, 0.0], [64284.1, 0.0], [64287.1, 0.126], [64291.1, 0.034], [64294.1, 0.159], [64297.1, 0.0], [64300.1, 0.922], [64302.7, 0.0], [64306.0, 0.017], [64309.1, 0.0], [64313.0, 0.223], [64316.8, 0.005], [64319.7, 0.001], [64321.1, 0.0], [64325.2, 0.004], [64327.7, 0.002], [64329.1, 0.001], [64332.1, 0.21], [64335.3, 0.283], [64339.1, 0.062], [64342.1, 0.134], [64345.1, 0.0], [64348.1, 0.002], [64350.7, 0.007], [64355.1, 0.0], [64358.1, 0.0], [64360.1, 0.001], [64363.1, 0.0], [64367.0, 0.0], [64370.1, 0.005], [64373.3, 0.002], [64376.6, 0.002], [64380.4, 0.001], [64382.7, 0.0], [64385.1, 0.005], [64390.1, 0.0], [64392.6, 0.0], [64396.8, 0.003], [64398.5, 0.0], [64399.9, 0.159], [64401.1, 0.001], [64401.2, 5.735], [64406.1, 1.621], [64409.1, 0.002], [64412.8, 0.944], [64416.0, 0.034], [64418.9, 0.014], [64421.1, 0.0], [64423.5, 0.104], [64426.4, 0.0], [64431.6, 0.0], [64435.1, 0.12], [64438.1, 0.01], [64440.0, 0.682], [64444.1, 0.411], [64447.2, 0.049], [64450.1, 0.0], [64454.2, 0.015], [64455.4, 0.0], [64460.7, 0.062], [64462.3, 0.0], [64466.7, 0.0], [64469.9, 0.028], [64473.6, 0.012], [64476.7, 0.128], [64478.9, 0.0], [64481.0, 0.03], [64486.2, 0.0], [64487.4, 0.001], [64492.1, 0.0], [64495.4, 0.014], [64498.3, 0.014], [64501.2, 3.558], [64505.5, 0.002], [64508.1, 4.655], [64510.8, 0.003], [64515.1, 0.002], [64517.2, 0.095], [64517.4, 0.062], [64520.3, 0.067], [64523.9, 33.758], [64528.2, 0.019], [64530.5, 0.314], [64541.6, 0.006], [64556.9, 0.033], [64557.2, 0.097], [64557.8, 0.144], [64563.1, 1.339], [64571.4, 0.023], [64572.0, 0.307], [64579.5, 0.002], [64584.9, 0.311], [64585.1, 4.314], [64585.3, 0.02], [64588.0, 0.903], [64588.4, 0.223], [64588.7, 0.0], [64590.3, 0.031], [64591.0, 0.973], [64591.1, 0.452], [64591.2, 0.137], [64591.3, 0.202], [64591.5, 0.104], [64591.6, 0.085], [64591.7, 1.967], [64592.1, 1.719], [64592.3, 0.002], [64592.4, 0.036], [64592.7, 0.034], [64593.4, 0.032], [64594.0, 0.341], [64594.1, 0.004], [64594.6, 0.088], [64594.8, 0.06], [64595.1, 0.0], [64595.7, 0.003], [64597.8, 0.513], [64597.9, 0.031], [64598.2, 0.0], [64598.7, 0.0], [64599.9, 18.129]], "asks": [[64600.0, 14.953], [64600.1, 0.089], [64600.6, 0.317], [64600.9, 0.084], [64601.0, 0.003], [64601.3, 0.0], [64602.2, 0.086], [64602.9, 0.002], [64605.5, 0.136], [64606.2, 0.071], [64606.5, 0.059], [64607.2, 0.235], [64607.3, 0.488], [64607.4, 0.254], [64607.6, 0.491], [64607.7, 0.261], [64607.8, 0.274], [64607.9, 0.132], [64608.1, 0.135], [64609.4, 0.001], [64612.9, 0.002], [64619.4, 1.264], [64623.3, 2.394], [64623.9, 0.075], [64624.3, 0.13], [64625.0, 0.303], [64625.4, 0.261], [64626.7, 0.145], [64626.8, 0.242], [64627.0, 0.233], [64627.1, 0.271], [64627.2, 0.281], [64627.3, 0.808], [64631.1, 1.002], [64633.0, 4.84], [64633.3, 0.091], [64634.2, 0.007], [64637.0, 0.007], [64638.8, 0.014], [64640.3, 0.001], [64641.1, 0.049], [64641.7, 0.07], [64642.0, 0.963], [64644.1, 0.0], [64647.0, 0.301], [64649.9, 0.002], [64653.7, 0.002], [64656.8, 0.0], [64659.5, 0.025], [64659.6, 0.0], [64659.8, 0.011], [64662.1, 1.366], [64662.9, 0.002], [64666.3, 0.0], [64668.8, 0.026], [64673.3, 0.002], [64675.2, 0.002], [64678.6, 0.176], [64682.1, 0.002], [64684.8, 0.007], [64688.0, 0.365], [64691.3, 0.0], [64694.7, 0.0], [64698.6, 0.002], [64701.4, 0.009], [64704.1, 0.005], [64709.1, 0.0], [64710.6, 0.0], [64713.6, 0.039], [64717.5, 0.0], [64720.2, 0.378], [64724.2, 0.003], [64727.6, 0.001], [64729.7, 0.0], [64733.1, 0.025], [64738.5, 0.0], [64739.2, 0.0], [64743.7, 0.005], [64746.9, 0.001], [64748.8, 0.019], [64752.9, 0.374], [64757.2, 0.0], [64758.5, 0.441], [64762.8, 0.371], [64765.5, 0.026], [64768.4, 0.205], [64772.2, 0.0], [64774.4, 0.002], [64778.0, 0.006], [64780.8, 0.008], [64784.9, 0.004], [64785.7, 0.234], [64786.6, 0.218], [64787.3, 0.218], [64787.6, 0.072], [64790.8, 0.372], [64794.6, 0.216], [64794.7, 0.055], [64799.9, 0.0], [64800.2, 0.006], [64803.7, 0.011], [64808.7, 0.0], [64809.9, 0.0], [64815.0, 0.104], [64817.6, 0.001], [64819.9, 0.0], [64824.8, 0.376], [64826.3, 0.0], [64831.8, 0.411], [64832.5, 0.0], [64836.3, 0.023], [64839.9, 0.0], [64841.7, 0.0], [64845.2, 0.002], [64849.9, 0.004], [64851.3, 0.0], [64854.9, 0.032], [64858.9, 0.015], [64861.7, 0.039], [64865.8, 0.011], [64865.9, 0.0], [64868.5, 0.125], [64871.2, 0.0], [64874.5, 0.0], [64877.1, 0.001], [64880.9, 0.0], [64886.1, 0.0], [64887.5, 0.518], [64887.9, 0.864], [64889.9, 0.0], [64894.8, 0.0], [64897.9, 0.012], [64899.9, 0.059], [64904.9, 0.02], [64907.9, 0.0], [64909.7, 0.0], [64913.1, 0.014], [64915.5, 0.012], [64919.9, 0.008], [64922.4, 0.004], [64923.0, 1.394], [64926.6, 0.094], [64929.1, 0.0], [64932.1, 0.817], [64935.1, 0.0], [64938.5, 0.01], [64941.5, 0.034], [64944.9, 0.0], [64949.0, 1.005], [64950.5, 0.003], [64954.7, 0.0], [64956.9, 0.932], [64961.9, 0.912], [64963.2, 0.0], [64963.7, 0.0], [64967.9, 0.0], [64969.6, 2.633], [64973.0, 0.017], [64976.9, 0.0], [64979.9, 0.001], [64983.7, 0.0], [64988.4, 4.322], [64989.9, 0.0], [64993.6, 0.0], [64996.3, 2.004], [64999.9, 0.096], [65003.2, 0.0], [65005.9, 0.002], [65009.9, 0.183], [65011.9, 0.001], [65014.9, 0.002], [65018.5, 0.0], [65021.9, 0.0], [65024.9, 0.0], [65027.9, 0.067], [65031.9, 0.0], [65034.7, 0.0], [65037.9, 0.0], [65042.7, 0.042], [65044.4, 0.004], [65046.9, 0.252], [65246.0, 13.778], [65392.4, 19.725]]}
{"kind": "depth", "E": 1787088331637, "U": 11315918531884, "u": 11315918541262, "recv_ms": 1787088331574, "bids": [[1000.0, 35.76], [14099.9, 1.008], [14199.9, 3.192], [14299.9, 0.0], [58139.9, 0.004], [61369.9, 0.066], [62015.9, 0.691], [63198.8, 0.0], [63204.7, 0.02], [63599.9, 0.028], [63602.1, 0.0], [63860.4, 1.586], [63953.9, 0.008], [63968.0, 0.025], [64115.6, 0.014], [64524.9, 0.025], [64566.4, 0.645], [64573.8, 0.622], [64580.3, 0.003], [64590.9, 0.07], [64591.0, 1.043], [64591.6, 0.185], [64592.1, 0.039], [64592.2, 0.442], [64592.3, 0.126], [64594.1, 0.004], [64594.2, 0.008], [64594.3, 0.003], [64594.5, 1.548], [64597.6, 0.006], [64597.9, 0.021], [64599.9, 18.13]], "asks": [[64600.0, 14.871], [64600.1, 0.005], [64600.5, 0.094], [64601.0, 0.002], [64601.5, 0.001], [64607.3, 0.738], [64607.9, 0.286], [64608.0, 0.147], [64619.8, 0.809], [64626.7, 0.395], [64627.2, 0.9], [64627.3, 0.962], [64627.4, 0.237], [64629.0, 2.046], [64709.0, 0.001], [64709.1, 0.008], [64885.9, 0.309], [64887.5, 0.537], [65082.6, 0.0], [65232.2, 0.0], [65246.0, 13.778], [65549.6, 4.635], [65600.0, 70.131], [65670.1, 4.856]]}
{"kind": "depth", "E": 1787088331739, "U": 11315918541398, "u": 11315918553864, "recv_ms": 1787088331676, "bids": [[14099.9, 1.372], [14199.9, 2.828], [58139.9, 0.002], [61369.9, 0.064], [61370.0, 0.022], [63308.0, 0.819], [63874.3, 2.203], [63953.9, 0.008], [64439.9, 1.084], [64440.0, 3.661], [64456.9, 0.0], [64457.0, 2.312], [64535.3, 0.004], [64538.8, 0.117], [64539.1, 0.032], [64539.7, 0.72], [64540.1, 0.032], [64566.4, 0.026], [64573.8, 0.003], [64591.4, 0.1], [64591.5, 0.174], [64591.8, 0.076], [64592.1, 0.039], [64594.1, 0.004], [64594.2, 0.008], [64594.3, 2.567], [64594.5, 0.0], [64597.9, 0.021], [64598.5, 0.013], [64598.9, 0.002], [64599.9, 18.133]], "asks": [[64600.0, 14.872], [64607.1, 0.15], [64607.5, 0.311], [64619.8, 0.19], [64626.5, 0.157], [64626.9, 0.31], [64662.1, 1.352], [64664.6, 0.003], [64668.9, 0.001], [64671.1, 34.069], [64672.4, 0.009], [64673.3, 0.002], [64739.7, 5.416], [64756.6, 10.454], [65246.0, 13.778], [65392.4, 19.313], [65407.5, 2.729], [65447.1, 2.289]]}
{"kind": "depth", "E": 1787088331841, "U": 11315918554193, "u": 11315918565287, "recv_ms": 1787088331779, "bids": [[14099.9, 1.722], [14199.9, 2.478], [51679.9, 0.0], [51680.0, 1.939], [58139.9, 0.002], [61369.9, 0.065], [61523.7, 0.001], [62015.9, 0.694], [63599.9, 0.008], [63616.2, 28.794], [63795.8, 0.784], [63953.9, 0.008], [64100.1, 4.342], [64115.7, 0.009], [64233.4, 40.973], [64276.9, 1.522], [64329.9, 33.461], [64400.1, 0.0], [64400.7, 27.665], [64400.8, 0.218], [64535.3, 0.018], [64539.4, 0.035], [64571.4, 0.093], [64571.7, 0.074], [64573.3, 0.085], [64578.8, 0.011], [64592.1, 1.595], [64594.2, 0.0], [64594.3, 0.003], [64594.5, 0.0], [64594.6, 0.088], [64596.8, 0.009], [64597.0, 0.902], [64597.8, 0.429], [64597.9, 0.043], [64598.1, 0.0], [64599.9, 18.069]], "asks": [[64600.0, 14.957], [64601.0, 0.003], [64601.5, 0.0], [64604.6, 0.0], [64619.4, 1.193], [64623.3, 2.38], [64624.6, 0.096], [64627.2, 0.281], [64629.0, 2.046], [64629.2, 0.005], [64636.2, 0.039], [64669.8, 0.009], [64781.8, 0.002], [64781.9, 0.003], [64785.7, 0.542], [64794.6, 0.0], [64795.7, 3.467], [64795.8, 27.232], [64867.1, 34.454], [64964.4, 43.103], [65246.0, 13.778], [65342.9, 0.394], [65600.0, 70.111]]}
