{"kind": "depth", "E": 1787095525587, "U": 11316385353598, "u": 11316385366657, "recv_ms": 1787095525667, "bids": [[14207.0, 0.84], [14307.0, 1.33], [14307.4, 1.33], [14407.4, 0.0], [58236.3, 0.002], [61471.6, 0.001], [62118.7, 0.024], [62749.2, 0.003], [63529.0, 1.331], [63894.0, 0.0], [64026.8, 2.101], [64059.9, 0.0], [64385.1, 0.005], [64401.3, 0.196], [64407.7, 0.193], [64409.3, 0.0], [64440.3, 5.271], [64511.3, 4.599], [64516.1, 0.306], [64521.0, 0.431], [64538.8, 0.192], [64550.1, 3.46], [64610.5, 1.89], [64637.6, 0.0], [64639.1, 0.157], [64642.5, 0.018], [64643.9, 0.565], [64665.9, 2.334], [64666.3, 0.001], [64667.5, 0.498], [64674.8, 0.082], [64674.9, 0.031], [64684.7, 0.002], [64689.1, 0.002], [64690.7, 0.003], [64693.1, 0.559], [64694.3, 0.196], [64701.1, 0.004], [64702.5, 1.555], [64703.3, 1.48], [64703.4, 0.02], [64703.6, 0.001], [64703.8, 0.336], [64703.9, 0.014], [64705.7, 0.0], [64705.8, 1.39], [64706.0, 0.259], [64707.0, 0.152]], "asks": [[64707.1, 37.676], [64707.2, 2.655], [64710.7, 0.34], [64710.8, 0.009], [64711.8, 0.077], [64715.0, 0.311], [64719.7, 0.71], [64721.8, 0.732], [64729.9, 0.473], [64730.3, 0.312], [64733.0, 0.156], [64735.1, 0.0], [64758.8, 0.548], [64768.6, 8.826], [64847.6, 0.0], [64847.9, 4.371], [64864.0, 4.182], [64864.6, 0.007], [64864.8, 5.82], [64903.5, 1.353], [64903.7, 1.571], [65014.9, 0.196], [65017.0, 0.923], [65030.7, 0.001], [65354.2, 0.153], [65516.3, 1.285], [65710.1, 1.064], [66001.2, 0.009]]}
{"kind": "depth", "E": 1787095525689, "U": 11316385366839, "u": 11316385377867, "recv_ms": 1787095525756, "bids": [[1000.0, 35.91], [14207.0, 1.19], [14307.4, 0.98], [58236.3, 0.002], [61471.6, 0.0], [61472.0, 0.075], [61472.1, 0.006], [63707.0, 0.036], [64059.9, 0.0], [64383.5, 0.109], [64383.6, 0.024], [64516.1, 0.383], [64538.8, 0.269], [64550.1, 3.537], [64639.1, 0.26], [64643.9, 0.565], [64703.4, 0.02], [64703.6, 0.001], [64703.8, 0.079], [64703.9, 0.014], [64704.2, 0.003], [64705.7, 1.39], [64705.8, 0.0], [64706.1, 0.001], [64707.0, 0.153]], "asks": [[64707.1, 37.668], [64775.1, 0.011], [64817.8, 1.887], [64847.7, 5.398], [64847.9, 0.383], [64864.6, 10.413], [64864.8, 0.009], [64902.0, 0.029], [64903.5, 8.876], [64903.7, 0.013], [65354.2, 0.155], [65412.8, 0.992], [65613.0, 0.285], [65613.4, 9.02], [65707.1, 0.02], [66001.2, 0.015]]}
{"kind": "depth", "E": 1787095525791, "U": 11316385377977, "u": 11316385387379, "recv_ms": 1787095525851, "bids": [[1000.0, 35.91], [14207.0, 1.554], [14307.4, 0.616], [51766.0, 0.0], [58236.3, 0.002], [61471.6, 0.0], [62118.7, 0.027], [63412.9, 0.015], [63917.1, 7.626], [64059.9, 0.0], [64383.8, 0.001], [64671.0, 0.087], [64703.4, 0.02], [64703.6, 0.009], [64703.8, 0.002], [64703.9, 0.002], [64704.4, 0.014], [64705.6, 0.002], [64705.7, 1.39], [64705.8, 0.0], [64706.0, 0.265], [64707.0, 0.151]], "asks": [[64707.1, 37.674], [64710.3, 0.004], [64736.4, 0.388], [64736.6, 0.023], [64739.5, 0.001], [64740.3, 0.744], [64742.4, 0.092], [64742.5, 0.001], [64742.6, 0.016], [64847.7, 5.398], [64847.8, 0.001], [64864.6, 10.413], [64864.8, 0.009], [64903.5, 7.708], [64903.6, 2.46], [65030.5, 1.1], [65030.6, 2.303], [65030.7, 0.002], [65031.9, 0.076], [65211.0, 6.44], [65354.2, 0.153], [65482.0, 3.664], [66110.8, 0.647]]}
{"kind": "depth", "E": 1787095525893, "U": 11316385387462, "u": 11316385402528, "recv_ms": 1787095525954, "bids": [[14207.0, 1.89], [14307.4, 0.28], [58236.3, 0.002], [61471.6, 0.0], [62118.7, 0.024], [62765.7, 2.408], [63447.3, 0.0], [63480.2, 5.191], [64059.9, 0.0], [64684.7, 0.002], [64689.1, 0.002], [64690.6, 0.586], [64690.7, 0.001], [64694.3, 0.196], [64700.3, 0.224], [64701.0, 0.849], [64701.6, 0.001], [64702.2, 0.002], [64703.4, 0.02], [64703.6, 0.009], [64704.0, 0.008], [64704.4, 0.0], [64705.4, 0.0], [64705.5, 0.0], [64705.6, 1.392], [64705.7, 0.0], [64705.8, 0.0], [64705.9, 0.003], [64707.0, 0.15]], "asks": [[64707.1, 37.675], [64708.5, 0.0], [64710.7, 0.03], [64710.8, 0.319], [64715.0, 0.311], [64719.6, 0.177], [64719.7, 0.71], [64721.8, 0.732], [64723.1, 0.003], [64723.2, 1.249], [64729.9, 0.473], [64733.4, 0.64], [64736.5, 0.001], [64739.4, 0.019], [64739.6, 0.213], [64740.4, 0.394], [64740.5, 0.002], [64762.1, 0.484], [64762.2, 0.003], [64864.6, 10.413], [64864.8, 0.009], [64903.5, 8.721], [64903.6, 2.46], [65224.8, 0.32], [65354.2, 0.153], [66001.2, 0.018]]}
{"kind": "depth", "E": 1787095525995, "U": 11316385403014, "u": 11316385416177, "recv_ms": 1787095526057, "bids": [[1000.0, 35.91], [14207.0, 2.268], [14307.1, 0.602], [14307.4, 0.0], [58236.3, 0.002], [61471.6, 0.0], [62118.7, 0.027], [63707.0, 0.016], [64059.9, 0.0], [64365.6, 0.492], [64365.7, 0.002], [64383.5, 0.109], [64660.4, 2.415], [64684.7, 0.002], [64689.1, 0.002], [64692.5, 0.883], [64692.7, 0.073], [64693.1, 0.003], [64693.5, 0.278], [64694.0, 1.947], [64694.3, 0.196], [64694.5, 0.03], [64700.1, 1.468], [64700.2, 0.319], [64700.3, 0.224], [64700.4, 0.541], [64700.9, 0.034], [64701.1, 0.007], [64701.2, 0.007], [64701.8, 0.001], [64702.1, 0.543], [64702.2, 0.086], [64702.5, 1.787], [64703.4, 0.02], [64703.6, 0.001], [64704.2, 1.807], [64704.3, 0.01], [64704.4, 0.028], [64705.6, 0.002], [64705.7, 0.0], [64707.0, 0.92]], "asks": [[64707.1, 37.047], [64707.2, 2.654], [64709.0, 0.0], [64709.5, 0.016], [64710.7, 0.03], [64710.8, 0.319], [64715.0, 0.311], [64719.7, 0.71], [64721.6, 0.003], [64721.7, 0.322], [64721.8, 0.732], [64722.3, 1.008], [64725.5, 10.311], [64729.9, 0.473], [64847.7, 5.398], [64847.8, 0.001], [64864.6, 10.413], [64864.8, 0.009], [64903.5, 7.333], [64903.6, 2.46], [65354.2, 0.153], [65515.0, 0.001], [65515.9, 0.787], [65691.5, 0.806], [65707.1, 0.0]]}
{"kind": "depth", "E": 1787095526097, "U": 11316385416394, "u": 11316385425247, "recv_ms": 1787095526158, "bids": [[1000.0, 35.91], [14207.0, 2.618], [14307.1, 0.252], [51766.0, 0.0], [58236.3, 0.002], [61471.6, 0.0], [63186.0, 0.632], [63930.6, 2.187], [64059.9, 0.0], [64544.6, 0.039], [64545.3, 0.001], [64674.9, 0.649], [64682.2, 1.553], [64682.8, 0.016], [64684.7, 0.002], [64689.1, 0.002], [64694.3, 0.196], [64695.4, 0.261], [64701.1, 0.548], [64701.3, 0.543], [64701.7, 0.093], [64701.8, 0.001], [64702.1, 0.002], [64702.2, 0.002], [64702.9, 0.004], [64704.1, 0.002], [64707.0, 0.919]], "asks": [[64707.1, 37.161], [64710.8, 0.319], [64715.0, 0.311], [64719.7, 0.71], [64721.8, 0.732], [64723.2, 1.559], [64724.0, 0.001], [64725.5, 10.313], [64728.9, 0.803], [64729.9, 0.163], [64733.7, 0.463], [64734.7, 0.0], [64736.2, 0.627], [64847.7, 0.001], [64847.8, 3.973], [64864.6, 0.007], [64864.7, 5.812], [64903.5, 1.353], [64903.6, 3.991], [64909.9, 0.803], [64910.4, 2.648], [65290.3, 0.038], [65354.2, 0.153]]}
{"kind": "depth", "E": 1787095526199, "U": 11316385425338, "u": 11316385432717, "recv_ms": 1787095526260, "bids": [[14207.0, 2.982], [14307.0, 1.218], [14307.1, 0.0], [51766.0, 0.0], [58236.3, 0.002], [61471.6, 0.0], [61472.0, 0.073], [61472.1, 0.008], [62118.7, 0.024], [63658.3, 0.439], [63707.0, 0.036], [64059.9, 0.0], [64684.7, 0.002], [64689.1, 0.002], [64691.9, 1.023], [64692.5, 0.327], [64692.9, 0.123], [64693.5, 0.162], [64694.3, 0.196], [64700.9, 0.493], [64701.3, 0.084], [64702.9, 0.004], [64703.4, 0.02]], "asks": [[64707.1, 37.169], [64707.5, 1.429], [64708.1, 0.143], [64710.8, 0.319], [64712.1, 0.087], [64715.0, 0.311], [64719.6, 0.136], [64719.7, 0.71], [64720.0, 0.66], [64721.8, 0.732], [64723.2, 1.559], [64847.7, 5.398], [64847.8, 0.001], [64864.6, 10.413], [64864.7, 0.002], [64903.5, 7.549], [64903.6, 2.46], [65354.2, 0.153], [65707.1, 0.02], [65787.7, 0.009], [65805.4, 4.856], [65839.6, 1.215], [66636.2, 0.0]]}
{"kind": "depth", "E": 1787095526301, "U": 11316385433008, "u": 11316385440522, "recv_ms": 1787095526364, "bids": [[1000.0, 35.91], [14207.0, 3.332], [14307.0, 0.868], [51766.0, 0.0], [58236.3, 0.002], [62118.7, 0.027], [63121.3, 0.0], [63797.3, 0.001], [64189.3, 0.314], [64383.5, 0.109], [64544.6, 0.0], [64545.3, 0.04], [64642.5, 0.034], [64674.7, 0.21], [64674.8, 0.072], [64700.4, 0.0], [64701.1, 1.089]], "asks": [[65288.0, 22.394], [65354.2, 0.153], [66653.2, 2.173]]}
{"kind": "depth", "E": 1787095526403, "U": 11316385440892, "u": 11316385448098, "recv_ms": 1787095526464, "bids": [[1000.0, 35.91], [14207.0, 3.696], [14307.0, 0.504], [51765.6, 0.0], [58236.3, 0.002], [61472.1, 0.006], [62118.7, 0.024], [63413.3, 0.014], [63707.0, 0.016], [63723.1, 0.784], [63917.2, 0.781], [63922.3, 1.877], [64059.9, 0.0], [64189.3, 0.31], [64598.9, 0.0], [64599.3, 2.335], [64677.0, 0.157], [64677.9, 0.0], [64700.3, 0.215], [64700.4, 0.541], [64701.1, 0.548], [64703.5, 0.008], [64704.1, 0.002], [64704.3, 0.134], [64705.3, 0.174]], "asks": [[64715.0, 0.331], [64715.2, 0.033], [64812.9, 0.003], [64813.2, 2.318], [65354.2, 0.153], [65563.3, 8.683], [65707.1, 0.0]]}
{"kind": "depth", "E": 1787095526505, "U": 11316385448292, "u": 11316385455491, "recv_ms": 1787095526566, "bids": [[14207.0, 3.738], [14307.0, 0.308], [14607.0, 0.154], [58236.3, 0.002], [61471.6, 0.0], [62118.7, 0.027], [63671.8, 1.098], [63829.1, 1.956], [64059.9, 0.0], [64171.6, 3.392], [64383.5, 0.109], [64547.3, 0.015], [64548.3, 7.036], [64565.0, 0.001], [64565.1, 1.072], [64565.3, 5.242], [64568.2, 0.0], [64597.0, 2.778], [64597.3, 0.0], [64610.3, 0.003], [64626.2, 0.0], [64626.4, 1.997], [64634.4, 0.001], [64634.6, 2.022], [64639.7, 2.337], [64642.7, 0.165], [64642.9, 2.091], [64673.7, 0.326], [64674.9, 0.031], [64682.2, 0.935], [64697.7, 0.497], [64699.6, 0.002], [64700.4, 0.0], [64701.1, 1.091], [64702.4, 1.839], [64703.1, 0.055], [64703.5, 0.001], [64703.8, 0.002], [64704.3, 0.134], [64706.0, 0.391], [64707.0, 0.926]], "asks": [[64707.1, 36.17], [64708.9, 0.0], [64709.0, 0.216], [64709.6, 0.117], [64710.3, 0.003], [64710.7, 0.185], [64710.8, 0.164], [64715.0, 0.331], [64717.1, 0.016], [64717.3, 1.996], [64719.7, 0.71], [64721.8, 0.732], [64723.2, 1.559], [64725.4, 0.027], [64725.6, 1.997], [64728.9, 0.185], [64733.0, 0.152], [64736.2, 0.009], [64759.3, 2.324], [64765.8, 1.326], [64817.6, 0.001], [64847.7, 3.972], [64864.0, 3.374], [64864.6, 0.007], [64864.7, 5.812], [64903.5, 2.89], [65030.7, 0.001], [65034.3, 1.846], [65038.4, 0.0], [65321.8, 0.687], [65354.2, 0.153]]}
{"kind": "depth", "E": 1787095526607, "U": 11316385455505, "u": 11316385462924, "recv_ms": 1787095526667, "bids": [[1000.0, 35.91], [14207.0, 3.626], [14307.0, 0.182], [14607.0, 0.392], [58236.3, 0.002], [63707.0, 0.036], [63894.1, 0.0], [64059.9, 0.0], [64369.9, 1.766], [64383.5, 0.119], [64401.3, 0.158], [64407.7, 0.155], [64507.8, 2.75], [64516.1, 0.268], [64521.0, 0.354], [64532.8, 4.179], [64536.0, 1.357], [64538.8, 0.154], [64550.1, 3.46], [64565.1, 0.029], [64565.4, 1.901], [64639.1, 0.041], [64639.8, 6.492], [64643.9, 0.577], [64684.7, 0.002], [64689.1, 0.002], [64692.1, 3.22], [64694.3, 0.196], [64697.1, 0.162], [64700.3, 0.756], [64701.1, 0.55], [64702.9, 0.004], [64703.8, 0.259], [64704.2, 1.807], [64704.3, 0.134], [64704.4, 0.028], [64705.4, 0.0], [64707.0, 0.925]], "asks": [[64707.1, 36.173], [64710.7, 0.185], [64710.8, 0.164], [64713.5, 0.001], [64715.0, 0.331], [64719.7, 0.71], [64721.8, 0.732], [64723.2, 1.559], [64731.9, 0.89], [64732.6, 0.216], [64733.4, 0.084], [64750.9, 0.003], [64757.3, 0.001], [64763.8, 0.026], [64770.3, 0.0], [64847.7, 3.285], [64861.0, 0.802], [64864.6, 0.007], [64864.7, 4.326], [64903.5, 2.817], [65354.2, 0.153], [65580.6, 0.618], [65707.1, 0.02]]}
{"kind": "depth", "E": 1787095526709, "U": 11316385463107, "u": 11316385469810, "recv_ms": 1787095526769, "bids": [[1000.0, 35.91], [14207.0, 3.5], [14307.0, 0.07], [14607.0, 0.63], [58236.3, 0.002], [61471.6, 0.0], [61650.4, 0.004], [61656.1, 0.016], [62118.7, 0.024], [63801.1, 0.188], [63937.0, 0.97], [64059.9, 0.0], [64383.4, 0.234], [64548.3, 0.0], [64548.4, 6.962], [64643.9, 0.673], [64684.7, 0.002], [64689.1, 0.002], [64694.3, 0.196], [64697.1, 0.162], [64702.9, 0.004], [64703.4, 0.028], [64703.8, 0.182], [64704.3, 0.126], [64707.0, 0.923]], "asks": [[64707.1, 36.215], [64709.6, 0.116], [64710.2, 0.131], [64710.7, 0.185], [64710.8, 0.164], [64715.0, 0.331], [64719.7, 0.71], [64721.8, 0.732], [64723.2, 1.559], [64847.7, 5.398], [64864.7, 10.408], [64903.5, 7.981], [65354.2, 0.153], [67732.3, 0.0], [67738.6, 0.042]]}
{"kind": "depth", "E": 1787095526811, "U": 11316385470100, "u": 11316385476322, "recv_ms": 1787095526871, "bids": [[14207.0, 3.276], [14307.0, 0.0], [14607.0, 0.924], [58236.3, 0.002], [61471.6, 0.0], [62118.7, 0.027], [63412.9, 0.018], [63707.0, 0.016], [63832.7, 8.917], [63917.1, 7.157], [64059.9, 0.0], [64352.4, 0.001], [64383.4, 0.235], [64383.5, 2.445], [64384.0, 0.995], [64643.9, 0.661], [64669.7, 0.0], [64690.0, 0.866], [64703.4, 0.02], [64703.8, 0.336], [64704.1, 0.002], [64704.3, 0.134], [64707.0, 0.928]], "asks": [[65030.7, 0.0], [65211.0, 5.521], [65482.0, 3.511], [65707.1, 0.0], [71177.9, 0.0]]}
{"kind": "depth", "E": 1787095526913, "U": 11316385476497, "u": 11316385482157, "recv_ms": 1787095526974, "bids": [[1000.0, 35.91], [14207.0, 2.926], [14607.0, 1.274], [58236.3, 0.002], [62118.7, 0.024], [63922.3, 0.939], [64059.9, 0.0], [64365.6, 0.0], [64366.0, 1.569], [64383.5, 2.435], [64544.6, 0.039], [64545.3, 0.001], [64643.9, 0.654], [64669.3, 0.622], [64684.7, 0.002], [64689.1, 0.002], [64690.6, 0.586], [64694.3, 0.196], [64696.0, 0.482], [64697.1, 0.162], [64700.3, 0.215], [64701.1, 1.091], [64702.9, 0.004], [64703.8, 0.336], [64704.3, 0.126], [64704.4, 0.036]], "asks": [[64710.7, 0.185], [64710.8, 0.164], [64715.0, 0.331], [64719.7, 0.71], [64721.8, 0.732], [64723.1, 0.003], [64723.2, 1.559], [64762.0, 0.032], [64762.1, 0.474], [65228.6, 0.689], [65288.0, 21.63], [65354.2, 0.153], [65628.0, 9.733]]}
{"kind": "depth", "E": 1787095527015, "U": 11316385482443, "u": 11316385494241, "recv_ms": 1787095527080, "bids": [[1000.0, 35.91], [14207.0, 2.562], [14607.0, 1.638], [58236.3, 0.002], [61471.6, 0.0], [62118.7, 0.027], [63707.0, 0.036], [63898.2, 0.236], [63930.5, 0.871], [63937.0, 1.907], [64059.9, 0.0], [64391.8, 0.003], [64401.3, 0.004], [64407.7, 0.001], [64516.1, 0.114], [64538.8, 0.0], [64565.3, 0.091], [64565.4, 5.151], [64623.9, 0.0], [64630.3, 0.0], [64635.5, 0.009], [64639.1, 0.003], [64640.4, 0.312], [64640.7, 0.0], [64640.9, 0.014], [64641.0, 0.014], [64641.1, 0.0], [64641.3, 0.004], [64641.7, 0.03], [64642.2, 0.019], [64643.9, 0.462], [64650.0, 3.703], [64653.0, 0.0], [64655.6, 1.291], [64659.1, 0.038], [64659.4, 0.0], [64659.7, 0.001], [64660.1, 0.055], [64660.4, 2.383], [64666.4, 0.0], [64668.1, 0.409], [64668.7, 0.315], [64670.3, 0.0], [64673.3, 0.003], [64673.6, 2.518], [64674.0, 0.097], [64674.1, 0.073], [64674.2, 0.0], [64674.3, 0.312], [64674.4, 0.069], [64674.5, 0.013], [64674.6, 0.003], [64674.7, 0.01], [64674.8, 0.002], [64675.0, 0.035], [64675.2, 2.505], [64675.4, 0.016], [64675.7, 0.003], [64676.0, 2.009], [64677.0, 0.0], [64677.1, 0.061], [64677.3, 0.008], [64677.4, 0.002], [64680.5, 0.059], [64680.7, 0.207], [64680.8, 0.092], [64681.6, 1.186], [64684.7, 0.157], [64685.1, 0.0], [64687.1, 1.702], [64687.7, 0.005], [64687.9, 0.05], [64689.1, 0.157], [64690.5, 0.007], [64690.9, 0.005], [64691.2, 0.025], [64691.9, 0.467], [64692.9, 0.0], [64693.0, 0.912], [64694.2, 1.675], [64694.3, 0.335], [64694.5, 0.586], [64694.6, 1.005], [64694.7, 0.021], [64695.1, 0.117], [64695.3, 0.018], [64695.4, 0.121], [64695.5, 0.312], [64695.6, 0.004], [64695.7, 0.229], [64695.8, 0.351], [64695.9, 0.003], [64696.0, 0.282], [64696.1, 0.007], [64696.3, 0.003], [64696.5, 0.004], [64696.8, 0.063], [64696.9, 0.001], [64697.1, 0.67], [64697.2, 0.003], [64697.5, 0.007], [64697.8, 0.014], [64698.4, 0.178], [64698.7, 0.28], [64699.0, 0.274], [64699.1, 0.002], [64699.5, 0.0], [64699.9, 0.007], [64700.1, 0.969], [64700.2, 0.731], [64700.3, 0.285], [64700.6, 0.539], [64700.7, 0.254], [64700.9, 0.033], [64701.0, 0.85], [64701.1, 0.005], [64701.2, 0.162], [64701.5, 1.001], [64702.3, 2.321], [64702.4, 0.188], [64702.5, 1.237], [64702.6, 0.0], [64702.7, 0.002], [64702.8, 0.087], [64702.9, 0.156], [64703.0, 0.459], [64703.2, 0.008], [64703.4, 1.109], [64703.5, 0.632], [64703.6, 0.001], [64703.8, 0.528], [64704.0, 0.093], [64704.1, 0.003], [64704.2, 0.003], [64704.3, 1.547], [64704.4, 0.41], [64704.7, 0.001], [64705.1, 0.084], [64705.3, 0.173], [64705.4, 0.18], [64705.5, 0.084], [64705.9, 0.002], [64706.0, 0.622], [64706.9, 0.002], [64707.0, 7.173]], "asks": [[64707.1, 28.761], [64707.2, 0.02], [64707.3, 0.003], [64707.4, 0.002], [64707.5, 0.428], [64707.6, 0.018], [64707.7, 0.002], [64708.0, 0.046], [64708.1, 0.0], [64708.2, 0.0], [64708.4, 0.002], [64708.8, 0.085], [64709.2, 0.084], [64709.5, 0.009], [64709.6, 0.084], [64709.8, 0.0], [64709.9, 0.001], [64710.1, 0.005], [64710.2, 0.096], [64710.3, 0.0], [64710.4, 0.029], [64710.5, 0.001], [64710.7, 0.022], [64710.8, 0.012], [64710.9, 0.56], [64711.1, 0.088], [64711.3, 0.193], [64711.4, 0.096], [64711.5, 0.032], [64711.6, 0.0], [64711.7, 0.014], [64711.8, 0.091], [64711.9, 0.001], [64712.0, 0.506], [64712.1, 0.158], [64712.2, 0.395], [64712.3, 0.006], [64713.6, 0.012], [64713.7, 0.483], [64713.9, 0.16], [64714.5, 0.0], [64714.6, 0.166], [64715.0, 0.001], [64715.1, 0.015], [64715.2, 0.01], [64715.4, 0.015], [64715.5, 0.002], [64716.0, 0.123], [64716.2, 0.031], [64716.3, 0.04], [64716.5, 0.008], [64716.6, 0.003], [64716.7, 0.463], [64716.8, 1.198], [64716.9, 0.156], [64717.0, 0.001], [64717.2, 0.0], [64718.3, 0.439], [64718.6, 0.126], [64719.3, 0.006], [64719.5, 0.06], [64719.6, 0.741], [64719.7, 0.082], [64720.0, 0.659], [64720.2, 0.377], [64721.3, 0.118], [64721.7, 0.002], [64721.8, 0.011], [64721.9, 3.588], [64722.4, 0.43], [64723.0, 0.013], [64723.2, 1.248], [64723.7, 0.007], [64724.5, 0.003], [64725.0, 0.153], [64725.1, 0.0], [64725.3, 0.06], [64725.5, 0.313], [64725.8, 0.387], [64726.0, 0.006], [64726.2, 1.573], [64726.4, 2.327], [64726.5, 0.053], [64726.6, 0.004], [64726.8, 0.008], [64726.9, 0.687], [64727.6, 0.63], [64728.2, 0.327], [64728.3, 0.085], [64728.6, 0.002], [64728.9, 0.15], [64729.3, 0.0], [64729.6, 0.012], [64729.8, 0.225], [64729.9, 0.106], [64730.0, 2.683], [64730.3, 0.003], [64730.4, 0.0], [64730.7, 0.201], [64731.5, 0.001], [64731.9, 0.334], [64732.2, 11.385], [64732.4, 0.765], [64732.5, 0.064], [64732.6, 0.022], [64732.7, 0.016], [64732.8, 0.014], [64732.9, 0.024], [64733.0, 0.002], [64733.1, 0.033], [64733.2, 2.769], [64733.3, 3.181], [64733.4, 0.007], [64733.7, 0.004], [64734.5, 0.018], [64734.6, 0.005], [64734.7, 0.613], [64735.6, 0.0], [64735.9, 0.132], [64736.1, 2.302], [64738.8, 0.004], [64744.1, 0.043], [64744.3, 0.027], [64744.8, 0.007], [64745.4, 1.688], [64746.0, 1.508], [64747.0, 0.0], [64747.3, 0.001], [64747.7, 0.18], [64747.8, 0.059], [64748.0, 0.017], [64748.3, 0.012], [64751.0, 2.181], [64757.5, 0.287], [64758.9, 1.48], [64763.9, 0.27], [64768.6, 1.842], [64768.9, 0.278], [64770.2, 0.079], [64770.4, 0.563], [64770.5, 0.078], [64771.3, 7.513], [64781.2, 0.0], [64786.7, 0.006], [64797.7, 0.077], [64814.3, 0.868], [64815.2, 0.0], [64816.1, 2.924], [64816.9, 11.735], [64827.3, 0.013], [64847.1, 46.699], [64847.7, 2.985], [64852.2, 3.191], [64853.1, 0.0], [64854.7, 15.123], [64864.7, 3.904], [64893.6, 14.829], [64903.5, 2.893], [64910.4, 5.753], [65354.2, 0.157], [65515.9, 1.245], [65707.1, 0.02], [66001.6, 0.007]]}
{"kind": "depth", "E": 1787095527117, "U": 11316385494245, "u": 11316385505319, "recv_ms": 1787095527183, "bids": [[14207.0, 2.198], [14607.0, 2.002], [58236.3, 0.002], [61471.6, 0.0], [63865.8, 0.938], [64059.9, 0.0], [64507.7, 0.0], [64507.8, 0.001], [64509.6, 8.775], [64518.7, 1.075], [64531.0, 0.002], [64534.2, 1.422], [64548.4, 0.001], [64549.6, 6.804], [64550.0, 6.096], [64600.5, 2.319], [64630.3, 0.001], [64642.3, 2.397], [64643.9, 0.539], [64644.4, 0.339], [64659.1, 0.07], [64659.4, 0.032], [64659.7, 0.033], [64660.3, 0.134], [64669.1, 0.002], [64669.9, 3.876], [64670.3, 0.0], [64675.0, 0.035], [64676.3, 0.06], [64677.1, 0.001], [64682.3, 1.345], [64684.7, 0.002], [64685.4, 0.003], [64686.7, 0.009], [64687.1, 1.7], [64687.8, 0.007], [64687.9, 0.01], [64689.1, 0.002], [64689.3, 0.314], [64693.8, 0.557], [64694.3, 0.18], [64694.5, 0.132], [64694.7, 0.021], [64695.1, 0.001], [64695.3, 0.088], [64695.4, 0.121], [64695.5, 0.382], [64695.6, 0.104], [64696.0, 0.382], [64696.5, 0.036], [64696.8, 0.095], [64697.1, 0.547], [64697.2, 0.003], [64697.8, 0.046], [64698.1, 0.201], [64699.0, 0.314], [64700.3, 0.285], [64701.2, 0.007], [64702.2, 0.003], [64702.4, 0.186], [64702.5, 1.696], [64702.6, 1.089], [64702.9, 0.001], [64703.0, 0.232], [64703.2, 0.007], [64703.3, 0.987], [64703.4, 0.02], [64703.5, 0.632], [64703.6, 1.63], [64703.8, 0.374], [64703.9, 0.002], [64704.0, 0.109], [64704.3, 0.002], [64704.4, 0.394], [64704.5, 0.003], [64704.8, 0.016], [64704.9, 0.003], [64705.3, 0.128], [64705.4, 0.096], [64705.5, 0.001], [64705.6, 0.086], [64706.0, 0.184], [64706.6, 0.005], [64707.0, 7.177]], "asks": [[64707.1, 27.38], [64707.4, 0.002], [64707.6, 0.016], [64707.7, 0.168], [64708.0, 0.046], [64708.3, 0.0], [64709.8, 0.032], [64710.4, 0.067], [64710.8, 0.36], [64711.1, 0.123], [64711.6, 0.11], [64712.0, 0.656], [64712.1, 0.242], [64712.3, 0.097], [64713.1, 0.007], [64714.5, 0.001], [64715.2, 0.008], [64715.6, 0.33], [64716.0, 0.124], [64716.2, 0.341], [64716.3, 0.349], [64716.7, 0.504], [64716.8, 1.682], [64716.9, 0.154], [64717.2, 2.319], [64717.9, 0.01], [64719.5, 0.678], [64719.6, 0.2], [64719.7, 0.702], [64720.0, 1.63], [64720.6, 0.008], [64721.0, 0.025], [64721.8, 0.321], [64725.5, 0.324], [64726.5, 0.036], [64728.5, 0.035], [64729.0, 2.338], [64729.1, 0.608], [64729.2, 0.206], [64729.5, 0.042], [64729.8, 0.26], [64729.9, 0.416], [64730.0, 3.563], [64730.1, 1.717], [64732.2, 11.387], [64732.3, 0.0], [64732.9, 0.116], [64733.2, 2.917], [64733.4, 0.091], [64733.5, 0.121], [64735.1, 0.459], [64735.6, 0.154], [64736.1, 1.843], [64736.3, 0.01], [64742.1, 0.156], [64745.9, 2.358], [64747.2, 1.355], [64747.9, 1.542], [64748.2, 0.667], [64748.5, 0.036], [64748.6, 0.098], [64756.5, 2.32], [64759.0, 0.004], [64760.5, 0.0], [64767.8, 2.533], [64769.3, 0.009], [64770.2, 0.077], [64771.3, 7.515], [64771.9, 0.026], [64844.9, 48.994], [64847.1, 0.001], [64864.7, 0.002], [64866.6, 6.092], [64893.6, 0.006], [65224.8, 1.239], [65321.8, 1.45], [65354.2, 0.153], [66001.2, 0.021]]}
{"kind": "depth", "E": 1787095527219, "U": 11316385505435, "u": 11316385511958, "recv_ms": 1787095527279, "bids": [[1000.0, 35.91], [14207.0, 1.848], [14607.0, 2.352], [58236.3, 0.002], [62118.7, 0.024], [63707.0, 0.016], [64059.9, 2.338], [64383.5, 2.435], [64531.0, 0.001], [64605.1, 0.0], [64605.2, 0.004], [64638.3, 0.001], [64639.8, 1.761], [64640.4, 33.604], [64642.3, 2.32], [64643.9, 0.385], [64650.0, 3.731], [64660.0, 0.138], [64666.9, 0.443], [64684.7, 0.157], [64689.1, 0.157], [64694.3, 0.335], [64695.9, 0.073], [64697.2, 0.158], [64697.5, 0.039], [64700.3, 0.44], [64703.7, 0.156], [64703.8, 0.528], [64704.6, 0.002], [64705.6, 0.002], [64706.6, 0.003], [64706.7, 0.002], [64707.0, 7.168]], "asks": [[64707.1, 27.476], [64707.2, 0.023], [64707.3, 0.005], [64707.4, 0.242], [64708.1, 0.084], [64708.2, 0.31], [64710.1, 0.037], [64710.4, 0.065], [64710.8, 0.05], [64711.7, 0.084], [64713.6, 0.013], [64716.2, 0.031], [64716.8, 1.683], [64716.9, 0.156], [64719.0, 0.002], [64719.4, 0.549], [64719.7, 0.082], [64720.0, 1.631], [64721.8, 0.011], [64723.2, 1.249], [64723.5, 0.004], [64726.4, 2.328], [64726.5, 0.16], [64728.0, 2.853], [64728.8, 0.129], [64729.6, 0.013], [64729.9, 0.106], [64732.5, 0.015], [64732.8, 0.323], [64733.0, 0.072], [64739.0, 0.385], [64739.1, 0.05], [64741.6, 0.07], [64747.6, 0.033], [64748.9, 0.397], [64774.4, 8.316], [64774.6, 47.47], [64778.6, 0.473], [64844.9, 1.542], [64847.7, 5.398], [64864.7, 10.408], [64866.6, 0.044], [64870.5, 0.077], [64903.5, 8.538], [65354.2, 0.153], [65707.1, 0.0], [65902.4, 0.012]]}
{"kind": "depth", "E": 1787095527321, "U": 11316385512078, "u": 11316385518238, "recv_ms": 1787095527393, "bids": [[1000.0, 35.91], [14207.0, 1.498], [14607.0, 2.702], [58236.3, 0.002], [61471.6, 0.0], [62118.7, 0.027], [63922.3, 0.001], [64059.9, 2.338], [64175.9, 0.315], [64369.9, 1.611], [64371.2, 0.621], [64592.1, 0.441], [64643.9, 0.462], [64684.7, 0.002], [64684.9, 0.006], [64686.4, 0.779], [64688.9, 0.002], [64689.1, 0.002], [64689.2, 0.102], [64692.5, 0.883], [64692.9, 0.0], [64693.6, 0.117], [64693.8, 0.001], [64694.3, 0.18], [64694.5, 0.016], [64695.3, 0.158], [64695.4, 0.191], [64695.5, 0.452], [64695.6, 0.174], [64695.8, 0.451], [64696.2, 0.073], [64697.2, 0.003], [64698.7, 0.003], [64700.3, 0.285], [64701.6, 0.46], [64702.1, 0.543], [64702.3, 2.553], [64702.5, 1.237], [64702.6, 0.548], [64703.0, 0.0], [64703.2, 0.091], [64703.7, 0.001], [64703.8, 0.528], [64705.1, 0.0], [64706.0, 0.141], [64707.0, 7.005]], "asks": [[64707.1, 27.477], [64707.6, 0.1], [64710.3, 0.003], [64710.4, 0.065], [64710.5, 0.001], [64710.6, 0.394], [64710.8, 0.05], [64711.4, 0.18], [64711.7, 0.146], [64711.8, 0.221], [64711.9, 0.001], [64712.0, 0.726], [64712.1, 0.25], [64712.2, 0.381], [64712.3, 0.174], [64714.5, 0.0], [64715.1, 0.018], [64715.8, 0.003], [64716.2, 0.031], [64719.7, 0.082], [64721.8, 0.019], [64721.9, 3.599], [64725.5, 0.313], [64726.5, 0.284], [64729.9, 0.106], [64730.0, 3.561], [64732.6, 0.106], [64732.8, 0.879], [64733.1, 0.163], [64733.3, 3.251], [64733.4, 0.161], [64733.5, 0.191], [64733.6, 2.95], [64734.1, 0.0], [64734.7, 0.057], [64734.8, 0.855], [64735.1, 0.0], [64746.0, 1.452], [64756.7, 0.659], [64760.4, 0.597], [64767.8, 2.323], [64772.4, 47.452], [64774.4, 1.891], [64774.6, 0.018], [64829.5, 10.213], [65017.0, 0.155], [65354.2, 0.153], [66001.6, 0.004]]}
{"kind": "depth", "E": 1787095527423, "U": 11316385518600, "u": 11316385525855, "recv_ms": 1787095527483, "bids": [[14207.0, 1.134], [14607.0, 3.066], [51765.6, 0.0], [58236.3, 0.002], [62118.7, 0.024], [63707.0, 0.036], [63897.0, 0.032], [63930.5, 2.276], [64059.9, 2.338], [64640.3, 0.054], [64640.7, 0.032], [64641.0, 0.046], [64641.6, 2.064], [64643.9, 0.385], [64665.7, 0.008], [64674.4, 0.169], [64694.3, 0.196], [64694.7, 0.005], [64695.7, 0.429], [64695.9, 0.173], [64696.0, 0.452], [64696.1, 0.107], [64697.8, 0.046], [64703.3, 0.005], [64703.6, 1.63], [64703.7, 1.788], [64703.9, 0.002]], "asks": [[64708.3, 0.08], [64710.5, 0.001], [64711.5, 0.226], [64711.7, 0.266], [64711.9, 0.261], [64716.2, 0.031], [64719.7, 0.002], [64721.8, 0.019], [64726.0, 0.906], [64726.5, 0.355], [64729.9, 0.106], [64730.2, 0.116], [64730.6, 1.027], [64732.8, 0.963], [64732.9, 0.236], [64733.1, 0.283], [64756.9, 0.004], [64766.0, 1.2], [64786.7, 0.002], [64847.7, 0.001], [64849.0, 4.007], [64864.7, 0.002], [64866.0, 6.036], [64903.5, 1.353], [64904.8, 1.489], [65030.6, 2.917], [65354.2, 0.153], [65707.1, 0.02], [65936.5, 2.121], [66001.2, 0.024]]}
{"kind": "depth", "E": 1787095527525, "U": 11316385526115, "u": 11316385537143, "recv_ms": 1787095527585, "bids": [[1000.0, 35.91], [14207.0, 0.784], [14607.0, 3.416], [58236.3, 0.002], [64059.9, 2.338], [64383.5, 2.435], [64641.3, 0.036], [64674.1, 0.143], [64674.2, 0.07], [64674.7, 0.11], [64694.3, 0.172], [64697.8, 0.07], [64704.5, 0.003]], "asks": [[64708.3, 0.0], [64716.4, 0.476], [64718.5, 0.027], [64721.9, 3.588], [64722.0, 2.569], [64723.5, 0.039], [64730.7, 0.166], [64736.0, 0.007], [64847.7, 5.398], [64848.9, 0.0], [64849.0, 0.05], [64864.7, 10.408], [64865.9, 0.0], [64866.0, 0.104], [64903.5, 8.532], [64904.7, 0.009], [64904.8, 0.0], [65354.2, 0.153]]}
{"kind": "depth", "E": 1787095527627, "U": 11316385537344, "u": 11316385542724, "recv_ms": 1787095527687, "bids": [[1000.0, 35.91], [14207.0, 0.448], [14507.0, 0.028], [14607.0, 3.724], [51766.0, 0.0], [58236.3, 0.004], [62118.7, 0.027], [63707.0, 0.016], [63937.0, 2.844], [64059.9, 2.338], [64189.3, 0.62], [64383.5, 2.59], [64507.3, 0.663], [64565.5, 1.927], [64642.4, 6.629], [64674.6, 0.073], [64692.3, 0.009], [64693.0, 0.905], [64694.3, 0.196], [64697.8, 0.046]], "asks": [[64770.2, 47.529], [64772.4, 0.0], [64854.6, 2.832], [64854.9, 0.032], [64909.9, 1.164], [64982.2, 0.103], [65030.6, 3.071], [65354.2, 0.153], [65610.8, 2.273], [65707.1, 0.0]]}
{"kind": "depth", "E": 1787095527729, "U": 11316385542846, "u": 11316385547871, "recv_ms": 1787095527791, "bids": [[14207.0, 0.28], [14507.0, 0.21], [14607.0, 3.71], [58236.3, 0.002], [62118.7, 0.024], [63218.7, 0.793], [63929.0, 0.875], [64059.9, 2.338], [64127.8, 0.017], [64128.2, 0.004], [64383.4, 0.233], [64597.0, 2.775], [64597.3, 0.003], [64674.0, 0.167], [64674.1, 0.213], [64674.2, 0.14], [64674.3, 0.382], [64674.5, 0.113], [64675.0, 0.105], [64694.3, 0.172], [64697.8, 0.07], [64698.5, 0.05], [64702.3, 2.321], [64702.8, 0.319], [64704.5, 0.003]], "asks": [[64765.8, 1.326], [65030.7, 0.001], [65291.3, 0.016], [65291.7, 0.0], [65549.2, 0.08]]}
{"kind": "depth", "E": 1787095527831, "U": 11316385547882, "u": 11316385552687, "recv_ms": 1787095527892, "bids": [[1000.0, 35.91], [14207.0, 0.154], [14507.0, 0.448], [14607.0, 3.598], [58236.3, 0.002], [61471.6, 0.0], [62118.7, 0.027], [63398.4, 0.005], [63470.2, 0.0], [63542.1, 0.0], [63614.0, 1.412], [63685.9, 0.0], [63707.0, 0.036], [63757.8, 0.003], [63829.6, 0.001], [63901.5, 0.004], [63973.4, 0.001], [64045.3, 0.0], [64059.9, 2.338], [64288.2, 0.008], [64288.6, 0.513], [64383.5, 2.6], [64448.9, 0.004], [64449.3, 0.486], [64610.0, 0.202], [64610.4, 0.051], [64642.7, 0.164], [64674.5, 0.213], [64674.7, 0.21], [64674.8, 0.072], [64677.0, 0.1], [64677.4, 0.102], [64694.3, 0.196], [64697.8, 0.046], [64705.9, 0.046], [64707.0, 7.126]], "asks": [[64716.4, 0.396], [64716.7, 0.463], [64719.2, 0.397], [64719.3, 0.029], [64722.6, 1.535], [64736.0, 0.009], [64736.1, 1.845], [64736.2, 0.011], [64739.0, 0.387], [64739.1, 0.052], [64739.2, 0.564], [64739.9, 0.016], [64740.0, 0.054], [64740.1, 0.004], [64742.0, 0.003], [64742.1, 0.158], [64742.2, 0.029], [64772.2, 0.05], [64804.1, 0.002], [64804.5, 0.025], [64847.7, 0.001], [64848.6, 5.086], [64864.7, 0.002], [64865.6, 8.575], [64903.5, 1.353], [64904.4, 1.422], [64966.1, 0.004], [64966.5, 0.004], [65128.5, 0.015], [65128.9, 1.148], [65307.4, 0.0], [65339.1, 5.344], [65354.2, 0.153], [65411.0, 0.703], [65482.9, 0.001], [65554.8, 0.0], [65626.6, 0.025], [65698.5, 0.0], [65707.1, 0.02], [65770.4, 0.0], [65842.3, 0.0], [65914.2, 0.005], [65986.0, 0.833]]}
{"kind": "depth", "E": 1787095527933, "U": 11316385552817, "u": 11316385559282, "recv_ms": 1787095527999, "bids": [[1000.0, 35.91], [14207.0, 0.042], [14507.0, 0.686], [14607.0, 3.472], [58236.3, 0.002], [62118.7, 0.024], [64059.9, 2.338], [64365.7, 0.494], [64366.0, 1.077], [64661.1, 0.031], [64670.7, 0.164], [64676.0, 2.049], [64690.6, 0.586], [64700.6, 0.54], [64704.5, 0.003]], "asks": [[64714.6, 0.246], [64722.6, 1.455], [64723.1, 0.003], [64790.2, 0.483], [64798.4, 1.986], [64814.7, 0.0], [64814.8, 0.016], [64847.7, 0.001], [64848.5, 3.992], [64848.6, 1.811], [64864.7, 0.002], [64865.5, 6.072], [64865.6, 4.129], [64903.5, 1.353], [64904.3, 1.491], [64904.4, 0.004], [65030.7, 0.002], [65354.2, 0.153], [65807.1, 0.318]]}
{"kind": "depth", "E": 1787095528035, "U": 11316385559362, "u": 11316385563682, "recv_ms": 1787095528096, "bids": [[14207.0, 0.0], [14507.0, 1.008], [14607.0, 3.192], [58236.3, 0.002], [63690.7, 8.623], [63707.0, 0.016], [64059.9, 2.338], [64565.4, 0.0], [64565.5, 0.026], [64566.6, 5.155], [64674.1, 0.151], [64695.4, 0.196]], "asks": [[64720.0, 2.531], [64722.0, 1.669], [64756.7, 0.046], [64829.5, 0.029], [64847.7, 5.398], [64848.5, 0.003], [64864.7, 10.408], [64865.5, 0.072], [64903.5, 8.331], [64904.3, 0.0], [65354.2, 0.153], [65707.1, 0.0]]}
{"kind": "depth", "E": 1787095528137, "U": 11316385563716, "u": 11316385570123, "recv_ms": 1787095528201, "bids": [[1000.0, 35.91], [14507.0, 1.358], [14607.0, 2.842], [58236.3, 0.002], [61466.1, 0.004], [61471.6, 0.003], [61472.1, 0.004], [62118.7, 0.027], [63413.3, 0.011], [64059.9, 2.338], [64383.5, 2.6], [64643.9, 0.462], [64669.2, 0.472], [64669.3, 0.468], [64678.5, 0.123], [64684.4, 1.763], [64685.9, 0.42], [64693.6, 0.001], [64694.3, 0.288], [64695.0, 0.003], [64695.4, 0.191], [64696.9, 0.31], [64697.8, 0.07], [64702.8, 0.087], [64703.3, 0.237], [64703.6, 0.085], [64703.9, 1.547], [64704.5, 0.003], [64705.4, 0.18], [64707.0, 7.353]], "asks": [[64710.3, 0.0], [64714.6, 0.166], [64715.5, 0.003], [64716.3, 0.429], [64719.5, 0.06], [64719.9, 0.967], [64732.5, 0.633], [64732.8, 0.407], [64733.2, 3.473], [64739.9, 0.634], [65341.2, 1.014], [65354.2, 0.153], [65610.8, 2.046], [65843.5, 9.02], [66001.2, 0.027]]}
{"kind": "depth", "E": 1787095528239, "U": 11316385570335, "u": 11316385576393, "recv_ms": 1787095528301, "bids": [[14507.0, 1.722], [14607.0, 2.478], [58236.3, 0.002], [61471.6, 0.002], [62118.7, 0.024], [63413.3, 0.008], [63697.0, 0.006], [63707.0, 0.036], [63782.3, 9.967], [64059.9, 2.338], [64703.3, 0.005], [64703.7, 2.02], [64705.4, 0.218]], "asks": [[64735.6, 0.71], [64752.2, 1.708], [64752.3, 3.584], [64766.7, 0.248], [64769.3, 0.0], [64770.2, 0.077], [64772.4, 47.001], [64778.9, 0.006], [65354.2, 0.153], [65707.1, 0.02], [65837.7, 7.573]]}
{"kind": "depth", "E": 1787095528341, "U": 11316385576570, "u": 11316385582988, "recv_ms": 1787095528406, "bids": [[14507.0, 2.072], [14607.0, 2.128], [51766.0, 0.0], [58236.3, 0.002], [61471.6, 0.002], [62118.7, 0.027], [63704.0, 1.14], [63879.3, 0.899], [64059.9, 2.338], [64211.9, 0.001], [64276.5, 0.461], [64341.1, 0.698], [64405.7, 0.0], [64407.2, 0.471], [64471.9, 0.478], [64536.6, 0.471], [64566.6, 5.155], [64643.9, 0.616], [64669.2, 0.472], [64676.0, 0.049], [64694.3, 0.211], [64695.2, 0.238], [64695.7, 0.422], [64697.7, 0.511], [64697.8, 0.147], [64698.1, 0.187], [64700.6, 0.314], [64700.9, 0.117], [64703.0, 0.003], [64703.2, 0.323], [64703.4, 0.018], [64703.5, 0.629], [64703.7, 1.788], [64703.8, 0.451], [64704.0, 0.025], [64704.4, 0.0], [64704.5, 0.003], [64707.0, 6.753]], "asks": [[64707.1, 27.561], [64710.5, 0.004], [64711.8, 0.137], [64728.2, 4.327], [64731.9, 0.383], [64732.5, 0.015], [64739.1, 0.003], [64739.9, 0.016], [64847.7, 5.398], [64864.7, 0.002], [64865.4, 8.598], [64903.5, 1.353], [64904.3, 1.496], [65354.2, 0.153], [65760.1, 0.0]]}
{"kind": "depth", "E": 1787095528443, "U": 11316385583046, "u": 11316385588657, "recv_ms": 1787095528506, "bids": [[1000.0, 35.91], [14507.0, 2.436], [14607.0, 1.764], [51765.6, 0.0], [51766.0, 0.0], [58236.3, 0.002], [62118.7, 0.024], [63707.0, 0.016], [63736.4, 2.424], [63930.5, 3.057], [64059.9, 2.338], [64342.5, 0.941], [64383.5, 2.6], [64643.9, 0.693], [64650.0, 3.703], [64652.6, 2.361], [64670.7, 0.106], [64672.3, 8.002], [64684.9, 0.002], [64700.2, 0.815], [64703.6, 0.001], [64703.8, 0.374], [64704.0, 0.027], [64704.5, 0.001], [64705.4, 0.103], [64706.0, 0.077], [64707.0, 6.122]], "asks": [[64707.1, 28.56], [64711.2, 0.063], [64711.7, 0.204], [64713.1, 0.008], [64716.6, 0.096], [64730.0, 2.681], [64732.2, 1.387], [64758.9, 1.471], [64770.2, 47.078], [64772.4, 0.0], [64864.7, 10.408], [64865.4, 2.32], [64903.5, 8.486], [64904.2, 0.0], [64904.3, 0.0], [65354.2, 0.153], [65707.1, 0.0]]}
{"kind": "depth", "E": 1787095528545, "U": 11316385588790, "u": 11316385593509, "recv_ms": 1787095528614, "bids": [[14507.0, 2.786], [14607.0, 1.414], [58236.3, 0.002], [61471.6, 0.002], [63412.9, 0.021], [63797.4, 0.0], [64059.9, 2.339], [64370.1, 1.246], [64521.0, 0.431], [64565.0, 1.11], [64636.8, 2.458], [64643.9, 0.693], [64669.2, 0.318], [64675.2, 3.669], [64686.0, 0.443], [64689.5, 0.007], [64690.5, 0.0], [64694.8, 0.019], [64695.2, 0.231], [64696.0, 0.761], [64696.9, 0.001], [64702.4, 0.727], [64702.5, 1.24], [64702.6, 0.007], [64703.0, 0.0], [64703.8, 0.451], [64705.4, 0.096]], "asks": [[64707.1, 28.57], [64716.6, 0.729], [64718.0, 0.905], [64719.3, 0.109], [64719.4, 0.008], [64719.5, 0.052], [64719.6, 0.116], [64720.0, 1.631], [64726.2, 1.493], [64727.4, 2.008], [64729.3, 0.002], [64729.5, 0.044], [64768.6, 8.752], [64813.1, 1.454], [64814.3, 0.001], [64864.7, 0.002], [64865.4, 8.522], [64903.5, 1.353], [64904.2, 1.503], [65354.2, 0.153], [65385.0, 8.123], [65515.9, 1.397], [65643.7, 5.931], [65645.4, 0.761], [65794.2, 0.607], [65871.8, 2.122]]}
{"kind": "depth", "E": 1787095528647, "U": 11316385593653, "u": 11316385598235, "recv_ms": 1787095528707, "bids": [[14507.0, 3.15], [14607.0, 1.05], [58236.3, 0.002], [62118.7, 0.027], [63707.0, 0.036], [63773.5, 1.894], [63829.2, 1.956], [64059.9, 2.339], [64403.3, 0.026], [64521.0, 0.354], [64643.9, 0.462], [64669.5, 0.0], [64679.5, 0.175], [64680.5, 0.002], [64692.1, 3.22], [64692.5, 0.327], [64692.8, 0.558], [64693.4, 1.139], [64694.3, 0.211], [64701.1, 0.464], [64701.6, 0.001], [64702.1, 0.002], [64702.5, 1.781], [64703.8, 0.528], [64704.5, 0.001]], "asks": [[64711.1, 0.13], [64712.1, 0.243], [64715.5, 0.312], [64716.3, 0.12], [64732.3, 0.057], [64733.2, 3.473], [64733.6, 2.95], [64734.5, 0.477], [64734.7, 0.0], [64734.8, 0.396], [64864.0, 4.182], [64864.7, 10.408], [64865.4, 2.32], [64903.5, 8.204], [64904.2, 0.0], [65288.0, 20.943], [65354.2, 0.153], [65707.1, 0.02]]}
{"kind": "depth", "E": 1787095528749, "U": 11316385598727, "u": 11316385604770, "recv_ms": 1787095528813, "bids": [[1000.0, 35.91], [14507.0, 3.5], [14607.0, 0.7], [58236.3, 0.002], [62118.7, 0.024], [64059.9, 2.339], [64383.5, 2.6], [64484.4, 0.075], [64486.4, 0.993], [64636.1, 33.187], [64640.4, 0.312], [64642.4, 1.834], [64643.9, 0.616], [64645.2, 0.002], [64669.4, 0.155], [64669.5, 0.0], [64700.0, 0.245], [64703.8, 0.528]], "asks": [[64732.3, 0.0], [64733.3, 3.308], [65030.7, 0.001], [65354.2, 0.153], [65366.0, 2.371], [65434.4, 0.0], [65837.7, 5.45]]}
{"kind": "depth", "E": 1787095528851, "U": 11316385604971, "u": 11316385611337, "recv_ms": 1787095528910, "bids": [[14407.0, 0.056], [14507.0, 3.752], [14607.0, 0.392], [51766.0, 0.0], [58236.3, 0.002], [62118.7, 0.027], [63413.3, 0.005], [63707.0, 0.016], [63722.8, 3.211], [64059.9, 2.339], [64383.4, 0.234], [64636.1, 0.013], [64638.3, 33.078], [64643.9, 0.385], [64669.3, 0.622], [64669.4, 0.001], [64692.8, 0.558], [64693.6, 0.001], [64694.3, 0.095], [64695.1, 0.117], [64701.1, 0.005], [64702.7, 0.461], [64705.4, 0.173]], "asks": [[64733.2, 2.917], [64733.3, 3.315], [64734.1, 0.556], [64734.5, 0.011], [64735.2, 1.466], [64864.7, 10.408], [64865.4, 2.32], [64903.5, 9.255], [64904.2, 0.0], [65321.8, 2.137], [65354.2, 0.153], [65643.7, 2.889], [65707.1, 0.0], [65871.8, 4.244]]}
{"kind": "depth", "E": 1787095528953, "U": 11316385611431, "u": 11316385616456, "recv_ms": 1787095529014, "bids": [[14407.0, 0.266], [14507.0, 3.682], [14607.0, 0.252], [58236.3, 0.002], [64059.9, 2.339], [64365.7, 0.002], [64366.0, 1.569], [64383.4, 0.235], [64639.1, 0.08], [64690.6, 0.586], [64694.2, 1.791], [64695.1, 0.001], [64701.8, 0.46], [64702.1, 0.543], [64702.5, 1.24], [64702.7, 0.002]], "asks": [[64723.1, 0.003], [64733.3, 3.308], [64733.8, 0.01], [65030.7, 0.0], [65354.2, 0.153], [65572.6, 6.056], [65606.5, 1.523], [65710.4, 1.055]]}
{"kind": "depth", "E": 1787095529055, "U": 11316385616540, "u": 11316385623512, "recv_ms": 1787095529122, "bids": [[1000.0, 35.91], [14407.0, 0.504], [14507.0, 3.57], [14607.0, 0.126], [58236.3, 0.0], [61471.6, 0.002], [62118.7, 0.024], [63398.4, 0.063], [63470.2, 0.058], [63542.1, 0.058], [63614.0, 1.47], [63685.9, 0.058], [63707.0, 0.036], [63755.8, 0.548], [63757.8, 0.061], [63829.6, 0.059], [63901.5, 0.062], [63973.4, 0.059], [64026.8, 2.032], [64045.3, 0.058], [64059.9, 2.339], [64287.1, 3.294], [64383.5, 2.59], [64530.3, 0.0], [64562.7, 0.0], [64566.6, 5.155], [64588.8, 0.008], [64590.1, 3.866], [64590.9, 0.022], [64597.3, 0.003], [64599.3, 0.017], [64599.4, 2.331], [64626.4, 0.0], [64626.5, 2.419], [64634.6, 0.026], [64634.8, 2.0], [64634.9, 0.046], [64637.7, 0.758], [64639.1, 0.003], [64642.6, 0.217], [64642.9, 0.311], [64643.0, 1.806], [64652.6, 2.347], [64660.6, 0.046], [64669.2, 0.472], [64669.3, 0.468], [64670.7, 0.064], [64671.1, 0.002], [64672.1, 0.003], [64672.3, 0.004], [64672.8, 0.546], [64677.5, 2.002], [64678.5, 0.173], [64679.5, 0.118], [64680.4, 1.34], [64680.8, 0.002], [64681.8, 0.524], [64683.7, 1.298], [64685.7, 2.457], [64690.9, 0.04], [64692.6, 0.001], [64692.8, 0.002], [64694.4, 0.565], [64694.8, 0.012], [64695.4, 0.196], [64696.0, 0.452], [64696.6, 0.024], [64697.8, 0.054], [64697.9, 0.309], [64699.6, 0.001], [64699.8, 0.478], [64700.2, 0.731], [64701.7, 0.091], [64701.8, 0.001], [64702.1, 0.002], [64702.4, 0.186], [64702.5, 1.237], [64702.6, 0.634], [64702.9, 0.004], [64703.0, 0.459], [64703.2, 0.091], [64703.5, 0.629], [64703.6, 0.001], [64703.7, 2.02], [64703.9, 1.549], [64704.0, 3.61], [64704.1, 0.087], [64704.2, 1.808], [64704.3, 0.005], [64704.5, 0.001], [64704.7, 0.313], [64704.8, 0.016], [64704.9, 0.005], [64705.1, 0.084], [64705.4, 0.526], [64705.6, 1.807], [64707.0, 7.19]], "asks": [[64707.1, 9.483], [64707.2, 0.02], [64707.3, 0.002], [64707.5, 0.348], [64707.6, 0.016], [64708.1, 0.0], [64708.2, 0.0], [64708.8, 0.001], [64709.0, 0.0], [64709.1, 0.221], [64709.2, 0.0], [64709.5, 0.01], [64709.6, 0.0], [64710.2, 0.011], [64710.3, 0.084], [64710.4, 0.064], [64710.5, 0.001], [64710.6, 0.0], [64710.7, 0.106], [64711.1, 0.122], [64711.8, 0.221], [64712.0, 0.726], [64712.1, 0.244], [64712.2, 0.524], [64712.5, 0.087], [64712.9, 0.084], [64713.0, 0.01], [64713.2, 0.085], [64713.6, 0.097], [64713.8, 0.004], [64714.4, 0.012], [64714.6, 0.163], [64714.8, 0.008], [64715.5, 0.003], [64715.6, 0.02], [64715.9, 0.708], [64716.3, 0.032], [64716.5, 0.031], [64716.6, 0.08], [64716.7, 0.0], [64716.9, 0.154], [64717.1, 2.335], [64717.2, 0.0], [64717.3, 0.0], [64717.4, 2.173], [64717.7, 0.008], [64717.9, 0.002], [64718.0, 0.005], [64718.3, 0.02], [64718.5, 0.016], [64719.3, 0.029], [64719.5, 0.036], [64719.7, 2.772], [64719.8, 0.002], [64719.9, 0.349], [64720.0, 1.835], [64720.1, 1.312], [64720.2, 0.006], [64720.5, 2.09], [64722.2, 0.545], [64722.6, 1.535], [64723.0, 0.006], [64723.5, 0.002], [64724.0, 0.008], [64724.7, 0.463], [64725.6, 0.047], [64725.7, 2.0], [64726.0, 0.904], [64726.5, 0.284], [64727.1, 0.002], [64728.2, 4.329], [64728.5, 0.033], [64728.9, 0.1], [64729.1, 0.454], [64729.3, 0.0], [64729.5, 0.042], [64731.9, 0.334], [64732.6, 0.102], [64732.8, 0.098], [64733.0, 0.443], [64733.3, 3.251], [64733.8, 0.003], [64734.7, 0.064], [64735.2, 1.007], [64735.5, 0.13], [64735.6, 0.606], [64735.9, 0.471], [64736.1, 1.965], [64736.8, 0.114], [64740.2, 0.05], [64742.1, 0.004], [64744.0, 1.286], [64744.3, 0.027], [64748.6, 0.154], [64765.8, 1.326], [64768.9, 0.078], [64769.3, 0.009], [64770.2, 0.0], [64770.5, 0.001], [64771.9, 0.024], [64777.3, 0.047], [64778.4, 0.147], [64780.1, 0.001], [64783.4, 0.0], [64785.5, 0.027], [64787.8, 46.881], [64789.3, 0.027], [64797.7, 0.231], [64797.8, 0.075], [64813.2, 0.0], [64813.3, 2.358], [64841.6, 5.056], [64844.4, 0.0], [64847.7, 0.001], [64848.4, 4.158], [64864.7, 0.002], [64865.4, 8.671], [64893.1, 1.522], [64893.5, 5.627], [64896.3, 0.014], [64896.4, 0.003], [64903.5, 1.353], [64904.2, 1.505], [65036.0, 0.181], [65041.8, 0.115], [65339.1, 5.402], [65354.2, 0.153], [65411.0, 0.761], [65482.9, 0.059], [65554.8, 0.058], [65626.6, 0.083], [65698.5, 0.058], [65707.1, 0.02], [65770.4, 0.058], [65842.3, 0.058], [65914.2, 0.063], [65986.0, 0.891]]}
{"kind": "depth", "E": 1787095529157, "U": 11316385623517, "u": 11316385627978, "recv_ms": 1787095529225, "bids": [[14407.0, 0.742], [14507.0, 3.444], [14607.0, 0.014], [51766.0, 0.0], [58236.3, 0.002], [61471.6, 0.002], [62118.7, 0.027], [63915.8, 20.64], [64059.9, 2.339], [64626.5, 0.421], [64626.7, 2.627], [64634.8, 0.003], [64635.0, 2.003], [64638.3, 0.001], [64639.1, 0.311], [64640.4, 33.389], [64643.0, 0.029], [64643.2, 1.774], [64643.9, 0.693], [64659.5, 0.62], [64660.6, 0.032], [64662.5, 0.0], [64666.9, 0.443], [64667.8, 0.016], [64674.2, 8.14], [64675.2, 2.505], [64677.5, 0.002], [64678.5, 0.123], [64680.8, 0.059], [64681.8, 0.467], [64682.8, 0.001], [64683.2, 1.321], [64684.1, 0.464], [64685.7, 2.507], [64687.7, 0.02], [64688.8, 0.019], [64693.4, 1.695], [64694.4, 0.009], [64694.7, 0.106], [64695.3, 0.143], [64695.4, 0.191], [64695.7, 0.429], [64696.6, 0.017], [64697.1, 0.547], [64697.8, 0.046], [64699.2, 0.003], [64699.5, 0.003], [64699.7, 2.321], [64699.8, 0.478], [64700.2, 0.815], [64700.7, 0.269], [64701.6, 0.001], [64702.2, 0.002], [64702.4, 0.646], [64702.6, 0.541], [64702.7, 0.009], [64702.8, 1.548], [64702.9, 0.001], [64703.0, 0.002], [64703.2, 0.323], [64703.7, 1.317], [64703.8, 0.223], [64703.9, 0.004], [64704.0, 0.011], [64704.1, 0.003], [64704.2, 0.004], [64704.3, 1.555], [64704.4, 0.008], [64704.7, 0.001], [64704.8, 0.019], [64704.9, 0.003], [64705.1, 0.0], [64705.4, 0.141], [64705.5, 0.001], [64705.6, 0.002], [64705.7, 0.0], [64706.0, 0.518], [64706.2, 0.004], [64707.0, 6.484]], "asks": [[64707.1, 10.701], [64707.2, 0.023], [64708.4, 0.086], [64708.9, 0.003], [64709.1, 0.085], [64709.3, 0.228], [64709.5, 0.009], [64709.9, 0.085], [64710.0, 0.003], [64710.4, 0.065], [64710.9, 0.87], [64711.2, 0.001], [64712.1, 0.243], [64712.4, 0.005], [64712.5, 0.003], [64712.9, 0.0], [64713.2, 0.001], [64713.5, 0.001], [64713.6, 0.013], [64714.7, 0.181], [64715.0, 0.081], [64715.5, 0.002], [64715.6, 0.003], [64716.5, 0.024], [64716.6, 1.808], [64716.7, 0.649], [64717.0, 0.31], [64717.4, 0.176], [64717.5, 1.999], [64718.4, 0.215], [64719.6, 0.116], [64719.7, 2.748], [64719.9, 0.411], [64720.0, 2.736], [64720.1, 1.326], [64720.3, 0.619], [64720.4, 4.015], [64720.5, 3.946], [64720.9, 0.012], [64722.3, 1.019], [64722.4, 0.447], [64722.6, 1.455], [64725.6, 0.036], [64725.7, 0.003], [64725.8, 2.387], [64726.5, 0.355], [64727.4, 1.191], [64728.2, 0.329], [64728.4, 0.459], [64729.8, 0.414], [64730.1, 11.717], [64732.6, 0.106], [64732.9, 0.285], [64733.1, 0.592], [64734.8, 0.855], [64735.6, 0.556], [64735.9, 0.012], [64736.3, 0.164], [64740.2, 0.001], [64742.7, 0.218], [64759.0, 0.003], [64768.6, 1.842], [64783.4, 46.877], [64786.4, 0.077], [64787.4, 1.431], [64787.8, 0.004], [64797.8, 0.074], [64847.7, 5.398], [64848.4, 0.0], [64864.7, 10.408], [64865.4, 2.32], [64903.5, 8.115], [64904.2, 0.0], [65354.2, 0.153], [65710.1, 2.128], [66001.2, 0.03]]}
{"kind": "depth", "E": 1787095529259, "U": 11316385628040, "u": 11316385632306, "recv_ms": 1787095529320, "bids": [[1000.0, 35.91], [14407.0, 1.092], [14507.0, 3.108], [14607.0, 0.0], [51766.0, 0.0], [58236.3, 0.002], [61471.6, 0.002], [62118.7, 0.024], [63707.0, 0.016], [64059.9, 2.339], [64343.5, 0.079], [64345.1, 0.677], [64407.7, 0.078], [64425.3, 0.101], [64440.1, 0.0], [64440.3, 0.846], [64511.1, 0.01], [64511.3, 2.305], [64544.6, 0.0], [64545.3, 0.04], [64636.1, 33.09], [64637.1, 4.178], [64637.4, 0.308], [64638.3, 0.001], [64639.1, 0.234], [64640.4, 0.312], [64652.6, 2.347], [64655.2, 2.512], [64662.3, 0.004], [64686.4, 0.859], [64688.6, 0.098], [64688.8, 0.006], [64689.2, 0.022], [64700.7, 0.579], [64702.8, 0.628], [64703.1, 0.058], [64703.3, 0.003], [64703.6, 0.085], [64703.8, 0.528], [64703.9, 1.549], [64704.0, 0.947], [64704.1, 0.087], [64704.2, 0.004], [64704.3, 0.003], [64704.4, 0.0], [64704.5, 0.001], [64704.8, 0.018], [64705.4, 0.218], [64706.0, 0.084], [64707.0, 6.455]], "asks": [[64707.1, 11.016], [64709.8, 0.042], [64713.7, 0.721], [64717.0, 0.403], [64719.2, 0.378], [64719.3, 0.006], [64719.6, 0.178], [64719.9, 0.349], [64720.0, 2.936], [64728.0, 1.953], [64767.4, 0.002], [64770.1, 51.263], [64783.4, 0.0], [64825.6, 0.481], [64847.7, 5.398], [64848.4, 0.0], [64864.7, 10.408], [64865.4, 2.32], [64903.5, 8.117], [64904.2, 0.0], [64907.1, 0.122], [64907.2, 0.004], [64976.9, 2.988], [64978.6, 0.001], [65075.9, 1.021], [65076.0, 0.094], [65354.2, 0.153], [65707.1, 0.0]]}
{"kind": "depth", "E": 1787095529361, "U": 11316385632422, "u": 11316385637497, "recv_ms": 1787095529422, "bids": [[1000.0, 35.91], [14407.0, 1.442], [14507.0, 2.758], [58236.3, 0.002], [61472.0, 0.069], [61472.1, 0.008], [62118.7, 0.027], [64059.9, 2.408], [64078.6, 0.0], [64100.1, 4.342], [64224.1, 0.031], [64300.1, 13.335], [64343.6, 0.006], [64383.5, 2.6], [64407.7, 0.001], [64577.5, 0.038], [64594.6, 1.51], [64636.1, 0.013], [64637.4, 0.0], [64638.3, 33.078], [64639.1, 0.08], [64643.9, 0.462], [64652.6, 2.361], [64655.5, 0.012], [64674.2, 8.142], [64675.2, 2.503], [64686.4, 0.779], [64692.9, 0.08], [64694.7, 0.005], [64696.3, 0.312], [64697.8, 0.147], [64697.9, 0.0], [64699.4, 0.003], [64703.6, 0.001], [64703.8, 0.528], [64704.0, 0.027], [64704.1, 0.003], [64704.2, 0.002], [64706.0, 0.084], [64707.0, 6.349]], "asks": [[64711.1, 0.123], [64718.6, 0.137], [64720.1, 1.312], [64722.3, 1.008], [64725.1, 0.002], [64725.8, 2.405], [64727.1, 0.0], [64730.1, 11.719], [64730.6, 1.025], [64731.1, 0.315], [64847.7, 0.001], [64848.4, 4.006], [64864.7, 0.002], [64865.4, 8.369], [64903.5, 1.353], [64904.2, 1.499], [65193.2, 0.138], [65343.1, 0.0], [65354.2, 0.153], [65596.1, 0.0], [65625.9, 0.227], [65773.1, 2.277], [65837.7, 3.326]]}
{"kind": "depth", "E": 1787095529463, "U": 11316385637609, "u": 11316385641894, "recv_ms": 1787095529526, "bids": [[14407.0, 1.806], [14507.0, 2.394], [51765.6, 0.0], [58236.3, 0.002], [63707.0, 0.036], [63917.1, 6.533], [64059.9, 2.408], [64371.2, 0.0], [64373.1, 0.173], [64498.0, 0.97], [64638.3, 0.001], [64639.1, 0.003], [64640.4, 33.389], [64669.1, 0.156], [64669.2, 0.318], [64700.2, 0.861], [64701.9, 0.459], [64702.4, 0.187], [64704.5, 0.001]], "asks": [[64817.2, 0.018], [64821.6, 0.0], [64847.7, 5.398], [64848.4, 0.0], [64864.7, 10.408], [64865.4, 2.32], [64903.5, 7.971], [64904.2, 0.0], [65354.2, 0.153], [65707.1, 0.02], [66001.6, 0.001]]}
{"kind": "depth", "E": 1787095529565, "U": 11316385641983, "u": 11316385645731, "recv_ms": 1787095529627, "bids": [[1000.0, 35.91], [14407.0, 2.17], [14507.0, 2.03], [51766.0, 0.0], [58236.3, 0.002], [62118.7, 0.024], [63801.5, 36.698], [64059.9, 2.407], [64341.1, 0.0], [64342.1, 37.988], [64342.2, 6.454], [64383.5, 3.221], [64438.7, 29.504], [64440.3, 5.123], [64509.7, 23.6], [64642.4, 6.597], [64652.6, 2.347], [64675.2, 3.668], [64684.7, 0.004], [64694.3, 0.196], [64694.7, 0.012], [64695.7, 0.422], [64697.8, 0.046], [64702.2, 0.003], [64702.4, 0.727], [64702.8, 0.087], [64703.8, 0.612], [64704.0, 0.027], [64706.0, 0.225]], "asks": [[64715.0, 0.001], [64716.8, 1.763], [64717.1, 2.355], [64717.3, 0.023], [64718.0, 0.905], [64719.1, 0.081], [64719.6, 0.116], [64720.0, 2.036], [64729.2, 0.208], [64730.0, 3.62], [64768.6, 8.682], [64864.7, 10.408], [64865.4, 2.32], [64903.5, 9.074], [64904.2, 0.0], [64907.2, 23.806], [64976.9, 7.106], [64978.6, 30.152], [65076.1, 37.012], [65354.2, 0.153]]}
{"kind": "depth", "E": 1787095529667, "U": 11316385645753, "u": 11316385649723, "recv_ms": 1787095529728, "bids": [[1000.0, 35.91], [14407.0, 2.52], [14507.0, 1.68], [51766.0, 0.0], [58236.3, 0.002], [61471.6, 0.004], [62118.7, 0.027], [63707.0, 0.016], [63930.5, 3.681], [64059.9, 2.407], [64100.1, 0.022], [64226.3, 47.182], [64300.1, 16.791], [64342.2, 7.318], [64383.5, 3.221], [64545.9, 0.063], [64599.4, 0.013], [64599.5, 2.318], [64636.1, 33.09], [64640.4, 0.312], [64683.7, 0.0], [64692.8, 0.558], [64693.4, 1.139], [64694.1, 2.633], [64694.3, 0.095], [64697.8, 0.147], [64702.5, 1.24], [64703.1, 0.055], [64703.9, 1.549], [64704.0, 0.027], [64704.1, 0.003], [64704.5, 0.001], [64706.0, 0.225]], "asks": [[64711.1, 0.13], [64713.0, 0.003], [64715.5, 0.311], [64717.0, 0.094], [64719.6, 0.734], [64720.3, 0.001], [64731.6, 1.549], [64733.1, 0.839], [64734.1, 0.0], [64769.0, 0.227], [64813.3, 0.04], [64813.4, 2.318], [65193.2, 47.018], [65354.2, 0.153], [65707.1, 0.0], [65871.8, 6.367], [66001.2, 0.033]]}
{"kind": "depth", "E": 1787095529769, "U": 11316385649805, "u": 11316385669019, "recv_ms": 1787095529945, "bids": [[14406.0, 0.238], [14406.2, 0.014], [14406.7, 0.014], [14407.0, 2.604], [14507.0, 1.33], [51765.0, 0.0], [58235.4, 0.002], [58235.5, 0.0], [58236.3, 0.0], [61471.6, 0.004], [62118.7, 0.024], [63411.9, 0.003], [63412.9, 0.024], [63883.4, 12.921], [64058.9, 0.0], [64059.0, 0.007], [64059.1, 7.089], [64059.6, 0.002], [64059.9, 2.407], [64384.1, 0.544], [64400.3, 0.0], [64483.8, 0.001], [64515.2, 3.13], [64515.7, 0.0], [64519.1, 0.097], [64520.6, 0.0], [64520.7, 0.001], [64521.6, 0.079], [64539.4, 0.0], [64541.7, 0.023], [64541.8, 1.482], [64550.7, 0.115], [64550.9, 0.077], [64551.3, 0.078], [64555.4, 0.0], [64555.5, 1.48], [64560.3, 0.004], [64584.8, 4.639], [64585.3, 0.0], [64586.9, 0.001], [64589.9, 0.004], [64605.2, 0.001], [64605.8, 0.004], [64611.3, 0.044], [64614.8, 0.009], [64626.0, 0.001], [64626.7, 0.628], [64626.9, 2.0], [64633.3, 0.012], [64635.0, 0.005], [64635.1, 2.389], [64635.5, 0.003], [64636.1, 33.02], [64636.7, 6.215], [64637.1, 4.178], [64637.3, 0.015], [64637.4, 0.0], [64637.5, 0.94], [64638.1, 1.355], [64638.3, 0.097], [64638.7, 0.172], [64638.8, 0.078], [64639.8, 1.759], [64640.9, 0.001], [64641.0, 0.046], [64641.2, 0.002], [64641.5, 6.003], [64642.4, 1.834], [64642.5, 0.05], [64643.2, 0.0], [64643.4, 1.774], [64643.5, 1.375], [64643.6, 0.094], [64643.8, 0.0], [64643.9, 0.385], [64647.5, 0.004], [64648.3, 0.001], [64650.1, 0.104], [64650.8, 0.158], [64651.5, 0.0], [64652.6, 2.361], [64652.9, 0.078], [64656.6, 0.001], [64658.0, 0.063], [64658.2, 0.027], [64659.5, 0.002], [64663.5, 0.631], [64667.4, 2.001], [64667.8, 0.016], [64668.4, 0.17], [64669.1, 0.002], [64669.9, 3.876], [64670.0, 0.65], [64670.4, 1.277], [64670.7, 0.106], [64671.4, 0.015], [64672.1, 0.02], [64673.6, 2.522], [64674.2, 0.14], [64674.5, 0.213], [64674.6, 0.083], [64674.7, 0.2], [64675.0, 0.101], [64675.2, 2.505], [64675.4, 0.001], [64675.7, 0.06], [64676.9, 0.018], [64677.1, 0.007], [64677.3, 0.016], [64678.6, 0.002], [64678.9, 0.321], [64679.3, 2.319], [64679.9, 0.013], [64680.2, 0.109], [64680.8, 0.002], [64681.6, 1.187], [64681.7, 1.299], [64684.1, 0.466], [64684.7, 0.001], [64685.1, 0.0], [64685.7, 2.52], [64685.9, 0.42], [64686.0, 0.445], [64686.2, 0.005], [64686.4, 0.859], [64686.7, 0.007], [64687.2, 0.025], [64687.7, 0.005], [64688.0, 1.394], [64688.3, 0.002], [64688.5, 0.244], [64688.6, 0.085], [64689.1, 0.558], [64689.5, 0.0], [64690.1, 0.852], [64690.2, 0.009], [64690.5, 0.154], [64690.6, 0.626], [64691.4, 0.039], [64691.5, 0.0], [64691.8, 0.311], [64692.3, 0.002], [64692.4, 0.78], [64692.8, 0.002], [64692.9, 0.0], [64693.3, 0.068], [64693.6, 0.001], [64693.8, 0.155], [64693.9, 1.272], [64694.0, 1.947], [64694.1, 2.479], [64694.2, 1.984], [64694.3, 0.095], [64694.5, 0.016], [64694.7, 0.013], [64694.9, 0.025], [64695.3, 0.143], [64695.4, 0.171], [64695.5, 0.451], [64695.7, 0.423], [64696.3, 0.003], [64696.8, 0.036], [64696.9, 0.155], [64697.1, 0.04], [64697.3, 0.087], [64697.4, 0.463], [64697.5, 1.038], [64697.6, 1.353], [64697.7, 1.038], [64697.8, 0.139], [64698.0, 0.1], [64698.1, 0.188], [64698.2, 0.001], [64698.4, 0.263], [64698.5, 0.051], [64698.7, 0.087], [64698.9, 0.001], [64699.0, 0.275], [64699.1, 0.086], [64699.5, 0.084], [64699.7, 2.321], [64699.8, 0.569], [64699.9, 0.543], [64700.1, 1.283], [64700.2, 0.132], [64700.3, 0.132], [64700.4, 0.002], [64700.6, 0.231], [64700.7, 0.254], [64700.8, 0.019], [64700.9, 0.033], [64701.0, 0.848], [64701.1, 1.558], [64701.2, 0.24], [64701.3, 0.077], [64701.4, 0.002], [64701.5, 0.001], [64701.6, 0.001], [64701.7, 0.007], [64701.8, 0.008], [64701.9, 0.0], [64702.1, 0.134], [64702.2, 0.002], [64702.3, 0.002], [64702.4, 0.102], [64702.5, 0.001], [64702.6, 0.0], [64702.7, 0.002], [64702.8, 0.003], [64703.0, 0.0], [64703.2, 0.003], [64703.5, 0.001], [64703.6, 0.001], [64703.7, 0.628], [64703.8, 0.009], [64703.9, 0.003], [64704.0, 0.008], [64704.1, 0.001], [64704.2, 0.004], [64704.3, 0.002], [64704.5, 0.0], [64704.6, 0.005], [64704.7, 0.0], [64704.8, 0.016], [64705.0, 0.001], [64705.1, 0.0], [64705.2, 0.003], [64705.4, 1.869], [64705.5, 0.043], [64705.6, 0.309], [64705.9, 0.002], [64706.0, 0.038], [64706.1, 0.0], [64706.2, 0.0], [64706.5, 0.0], [64706.6, 0.0], [64706.7, 0.0], [64706.9, 0.0], [64707.0, 0.0]], "asks": [[64706.1, 39.368], [64706.2, 3.78], [64706.3, 1.822], [64706.4, 0.001], [64706.5, 0.0], [64706.6, 0.0], [64706.7, 3.51], [64706.8, 1.121], [64706.9, 0.0], [64707.0, 2.5], [64707.1, 2.249], [64707.2, 0.022], [64707.3, 0.0], [64707.4, 0.003], [64707.6, 0.017], [64708.0, 0.047], [64708.3, 0.001], [64708.8, 0.009], [64708.9, 0.007], [64709.0, 0.001], [64709.3, 0.004], [64709.4, 0.291], [64709.6, 0.0], [64710.0, 0.005], [64710.8, 0.047], [64710.9, 0.873], [64711.0, 0.505], [64711.1, 0.123], [64711.4, 0.181], [64711.5, 0.226], [64711.6, 0.114], [64711.8, 0.221], [64712.2, 0.44], [64712.4, 0.004], [64712.9, 0.008], [64713.1, 0.012], [64713.6, 0.191], [64714.1, 0.005], [64714.4, 0.02], [64714.5, 0.008], [64714.6, 0.163], [64714.7, 0.001], [64714.8, 0.007], [64715.0, 0.001], [64715.1, 0.018], [64715.2, 0.008], [64715.7, 0.009], [64715.8, 0.006], [64716.0, 0.139], [64716.1, 0.581], [64716.2, 0.116], [64716.3, 0.66], [64716.4, 0.397], [64716.5, 1.245], [64716.6, 0.003], [64716.7, 0.043], [64717.0, 0.994], [64717.1, 2.335], [64717.3, 0.0], [64717.5, 0.001], [64717.7, 2.004], [64718.0, 0.005], [64718.4, 0.015], [64718.7, 0.022], [64719.0, 0.421], [64719.1, 0.081], [64719.3, 0.486], [64719.5, 0.651], [64719.6, 0.116], [64719.7, 2.748], [64719.8, 0.002], [64719.9, 0.349], [64720.0, 1.226], [64720.1, 1.298], [64720.3, 0.001], [64720.4, 4.466], [64720.5, 15.413], [64721.0, 0.032], [64721.6, 1.003], [64721.8, 0.011], [64722.4, 0.43], [64722.6, 0.455], [64723.2, 1.249], [64723.4, 25.015], [64724.0, 0.002], [64724.1, 0.045], [64724.4, 0.407], [64725.1, 0.0], [64725.3, 0.04], [64725.6, 0.661], [64725.8, 0.405], [64726.0, 2.902], [64726.1, 0.314], [64726.9, 0.027], [64727.3, 0.05], [64727.6, 0.47], [64728.2, 0.009], [64729.1, 0.763], [64729.4, 0.559], [64729.6, 0.011], [64729.7, 0.059], [64730.0, 2.681], [64730.1, 1.702], [64730.6, 1.025], [64730.7, 0.126], [64731.2, 1.928], [64731.6, 1.24], [64731.8, 0.046], [64732.1, 0.001], [64732.2, 1.374], [64733.0, 0.45], [64733.1, 0.283], [64733.2, 2.469], [64733.3, 0.53], [64733.5, 0.199], [64733.7, 0.004], [64733.8, 0.015], [64734.4, 7.554], [64734.5, 0.003], [64734.7, 0.0], [64734.8, 0.396], [64735.6, 0.562], [64735.9, 0.006], [64736.0, 0.007], [64736.1, 1.963], [64736.2, 0.009], [64736.9, 0.001], [64737.1, 0.022], [64738.7, 0.059], [64739.0, 0.385], [64739.1, 0.001], [64739.2, 0.562], [64739.9, 0.014], [64740.0, 0.052], [64740.1, 0.002], [64741.0, 0.065], [64741.2, 0.019], [64741.3, 0.033], [64741.4, 2.463], [64741.6, 0.0], [64741.9, 0.002], [64742.0, 0.001], [64742.1, 0.002], [64742.2, 0.027], [64744.1, 0.028], [64744.8, 0.001], [64744.9, 0.358], [64745.2, 0.002], [64745.9, 2.372], [64746.9, 0.022], [64747.5, 0.005], [64747.9, 0.075], [64748.0, 1.484], [64748.6, 0.098], [64751.8, 0.0], [64752.4, 0.684], [64756.2, 0.003], [64757.7, 0.0], [64758.6, 0.044], [64760.4, 0.387], [64764.0, 0.003], [64764.3, 0.004], [64764.5, 0.015], [64765.1, 0.0], [64765.6, 0.005], [64766.7, 0.239], [64767.2, 0.003], [64768.6, 1.842], [64769.3, 0.0], [64769.6, 3.468], [64770.1, 4.386], [64770.8, 0.088], [64770.9, 0.204], [64771.0, 0.206], [64771.3, 7.515], [64775.3, 0.377], [64777.5, 0.201], [64778.9, 47.031], [64779.5, 0.158], [64788.0, 0.061], [64791.4, 0.0], [64802.9, 0.005], [64863.7, 10.454], [64864.0, 3.374], [64864.7, 0.002], [64865.4, 2.32], [64878.0, 0.072], [64885.8, 0.003], [64896.4, 0.0], [64896.9, 0.003], [64902.5, 6.792], [64903.4, 2.577], [64903.5, 1.353], [64904.2, 0.0], [65353.2, 0.0], [65353.4, 1.273], [65353.9, 0.0], [65354.2, 0.153], [65701.1, 0.027], [65702.1, 0.0], [65702.5, 0.0], [65702.7, 0.001], [65702.8, 0.0], [65706.3, 0.004], [65706.8, 1.214], [66000.2, 0.014], [68132.4, 0.003]]}
{"kind": "depth", "E": 1787095529871, "U": 11316385669156, "u": 11316385688827, "recv_ms": 1787095530203, "bids": [[1000.0, 35.91], [14405.5, 0.308], [14405.6, 0.014], [14406.0, 0.28], [14507.0, 0.966], [58234.9, 0.003], [58235.4, 0.0], [61470.7, 0.0], [62117.2, 0.013], [63413.0, 0.0], [63706.0, 0.02], [63883.4, 12.57], [64058.4, 0.007], [64058.5, 0.0], [64058.8, 0.101], [64058.9, 0.0], [64382.0, 0.079], [64383.4, 0.234], [64383.5, 3.221], [64384.1, 0.467], [64385.2, 0.077], [64401.4, 0.269], [64407.9, 0.269], [64515.7, 0.0], [64516.2, 0.077], [64519.1, 0.02], [64521.1, 0.083], [64521.6, 0.002], [64528.0, 1.496], [64528.1, 1.881], [64539.6, 0.0], [64544.6, 0.039], [64545.3, 0.001], [64550.2, 1.933], [64550.7, 0.0], [64550.9, 0.0], [64551.3, 0.001], [64555.5, 0.008], [64555.6, 1.472], [64563.5, 0.0], [64563.6, 0.452], [64569.4, 2.618], [64574.1, 0.0], [64574.2, 0.468], [64574.5, 2.309], [64577.5, 0.014], [64584.3, 0.027], [64584.6, 0.0], [64585.7, 0.04], [64586.7, 0.024], [64592.8, 0.013], [64593.8, 0.009], [64599.8, 0.013], [64600.8, 0.0], [64606.0, 0.009], [64606.9, 0.041], [64607.9, 0.0], [64609.7, 0.191], [64611.7, 0.077], [64613.9, 0.013], [64614.9, 0.0], [64621.0, 0.026], [64622.0, 0.283], [64628.0, 0.014], [64629.0, 6.301], [64630.8, 0.036], [64631.9, 0.001], [64633.9, 0.003], [64635.1, 2.402], [64636.1, 0.0], [64636.7, 6.215], [64637.5, 0.915], [64637.6, 0.103], [64637.7, 0.387], [64637.8, 0.448], [64638.1, 1.24], [64638.2, 33.429], [64638.3, 0.001], [64638.7, 0.095], [64638.8, 0.001], [64638.9, 0.03], [64639.9, 0.0], [64641.6, 2.076], [64642.4, 2.014], [64642.5, 0.127], [64642.9, 0.311], [64643.1, 0.0], [64643.5, 1.363], [64643.6, 0.017], [64647.2, 0.628], [64649.1, 0.035], [64650.1, 0.099], [64652.9, 0.078], [64662.9, 0.117], [64663.1, 2.322], [64663.2, 8.002], [64664.9, 0.003], [64665.5, 1.095], [64665.9, 2.335], [64667.4, 0.001], [64667.6, 0.062], [64668.3, 0.001], [64670.4, 1.392], [64671.0, 0.104], [64671.4, 0.009], [64672.1, 0.003], [64673.1, 0.153], [64673.8, 0.09], [64676.2, 0.018], [64676.3, 0.0], [64676.4, 0.006], [64676.8, 1.312], [64677.1, 0.001], [64677.3, 0.002], [64678.1, 0.009], [64678.3, 0.006], [64678.4, 1.534], [64678.9, 0.313], [64679.1, 0.015], [64680.2, 0.094], [64680.4, 1.25], [64680.7, 0.087], [64680.8, 0.017], [64681.5, 0.018], [64684.1, 0.546], [64684.4, 1.702], [64685.6, 0.005], [64686.2, 0.673], [64686.4, 0.779], [64687.2, 0.019], [64687.6, 0.464], [64687.7, 0.004], [64688.0, 1.393], [64688.8, 0.013], [64690.2, 0.002], [64690.6, 0.586], [64691.4, 0.046], [64692.3, 0.005], [64692.4, 0.773], [64692.6, 0.31], [64693.0, 0.005], [64693.1, 0.002], [64693.2, 0.053], [64693.7, 0.061], [64693.9, 1.272], [64694.0, 1.047], [64694.1, 2.479], [64694.2, 1.675], [64694.3, 0.405], [64694.7, 0.013], [64695.2, 0.231], [64695.5, 0.141], [64695.7, 0.422], [64696.5, 0.036], [64696.9, 0.399], [64697.1, 0.133], [64697.4, 0.004], [64697.5, 1.143], [64697.6, 1.812], [64697.7, 0.5], [64697.8, 0.594], [64697.9, 0.0], [64698.0, 0.22], [64698.3, 0.233], [64698.5, 0.021], [64698.6, 0.002], [64699.1, 0.089], [64699.2, 0.003], [64699.3, 0.002], [64699.7, 2.321], [64699.8, 1.019], [64699.9, 0.002], [64700.1, 0.008], [64700.2, 0.048], [64700.3, 1.677], [64700.4, 1.805], [64700.5, 1.525], [64700.6, 0.232], [64700.8, 0.027], [64701.1, 0.003], [64701.2, 0.008], [64701.3, 1.653], [64701.5, 0.001], [64701.7, 0.007], [64701.8, 0.001], [64702.1, 0.126], [64702.2, 0.01], [64702.3, 0.002], [64702.4, 0.102], [64702.5, 0.001], [64702.7, 0.002], [64702.8, 0.006], [64702.9, 0.002], [64703.2, 0.002], [64703.3, 0.002], [64703.4, 0.007], [64703.5, 0.001], [64703.7, 0.001], [64703.9, 0.002], [64704.1, 0.0], [64704.6, 0.002], [64704.7, 0.324], [64705.2, 0.002], [64705.3, 0.001], [64705.4, 0.0], [64705.5, 0.071], [64705.6, 0.0], [64705.9, 0.0], [64706.0, 0.0]], "asks": [[64705.6, 38.057], [64705.7, 2.134], [64705.8, 0.001], [64705.9, 2.5], [64706.0, 3.503], [64706.1, 1.006], [64706.2, 1.0], [64706.3, 0.091], [64706.4, 0.0], [64706.7, 0.002], [64706.8, 0.12], [64707.0, 0.0], [64707.1, 1.249], [64707.9, 0.001], [64708.7, 0.058], [64709.8, 0.043], [64710.3, 0.085], [64710.8, 0.047], [64711.3, 0.194], [64711.7, 0.246], [64711.8, 0.137], [64712.0, 0.278], [64712.1, 0.691], [64712.2, 0.482], [64712.5, 0.003], [64713.2, 0.428], [64713.7, 0.721], [64714.7, 0.0], [64714.8, 0.007], [64715.1, 0.018], [64715.2, 0.556], [64715.3, 0.591], [64715.6, 0.002], [64715.8, 0.156], [64715.9, 0.708], [64716.0, 0.143], [64716.1, 0.033], [64716.2, 0.116], [64716.4, 0.396], [64716.7, 0.051], [64716.9, 0.004], [64718.4, 0.022], [64718.5, 0.028], [64718.6, 0.126], [64718.7, 0.022], [64718.8, 0.023], [64719.0, 0.006], [64719.6, 0.116], [64720.1, 1.299], [64720.3, 0.001], [64720.4, 5.466], [64721.0, 0.025], [64721.6, 0.003], [64721.8, 0.003], [64722.6, 0.007], [64722.7, 0.48], [64722.8, 2.958], [64723.0, 0.008], [64723.2, 1.249], [64723.4, 25.013], [64724.8, 0.797], [64725.0, 0.284], [64725.1, 0.001], [64726.5, 0.335], [64726.6, 0.003], [64726.9, 0.026], [64729.2, 0.298], [64729.4, 0.559], [64730.5, 0.0], [64731.1, 0.328], [64731.2, 1.469], [64731.6, 1.699], [64731.8, 0.031], [64732.7, 0.025], [64732.9, 0.297], [64733.5, 0.191], [64733.8, 0.003], [64734.2, 0.006], [64734.3, 1.47], [64734.9, 0.472], [64735.4, 0.0], [64735.6, 0.616], [64736.0, 0.021], [64736.4, 0.503], [64736.8, 0.024], [64737.6, 1.282], [64738.7, 0.042], [64739.9, 0.015], [64740.9, 0.006], [64741.0, 0.065], [64741.1, 0.311], [64741.2, 0.013], [64742.8, 0.007], [64744.8, 0.015], [64745.8, 0.016], [64745.9, 2.358], [64746.9, 0.007], [64747.0, 0.0], [64747.3, 0.031], [64748.0, 0.003], [64748.1, 2.468], [64748.4, 0.393], [64750.2, 7.072], [64750.4, 1.234], [64751.0, 2.18], [64755.4, 0.039], [64760.8, 0.061], [64761.8, 0.009], [64763.4, 0.02], [64764.5, 0.01], [64770.3, 0.403], [64770.7, 0.242], [64772.4, 47.026], [64774.5, 0.0], [64778.9, 0.005], [64779.5, 0.133], [64780.9, 0.118], [64781.1, 0.0], [64781.2, 0.0], [64783.4, 0.0], [64785.5, 0.027], [64803.1, 0.011], [64804.9, 2.412], [64842.1, 0.003], [64863.2, 10.408], [64863.7, 0.048], [64865.6, 4.129], [64886.8, 0.11], [64897.6, 5.466], [64902.0, 6.536], [64902.5, 0.012], [64904.5, 0.009], [65029.2, 0.001], [65352.7, 1.527], [65352.8, 0.167], [65353.1, 0.0], [65353.2, 0.0], [65516.6, 2.268], [65516.9, 6.177], [65706.0, 0.028], [65706.1, 2.148], [65707.2, 0.0], [65707.4, 0.0], [65999.7, 1.544], [71176.2, 0.002]]}
{"kind": "depth", "E": 1787095529973, "U": 11316385688983, "u": 11316385702922, "recv_ms": 1787095530472, "bids": [[1000.0, 35.91], [14405.2, 0.224], [14405.5, 0.434], [14507.0, 0.616], [58234.6, 0.005], [58234.9, 0.001], [61470.2, 0.0], [63706.0, 0.0], [63799.3, 0.323], [63897.2, 0.233], [64057.5, 0.386], [64058.1, 1.654], [64058.3, 0.0], [64058.4, 0.007], [64059.7, 0.022], [64361.9, 0.502], [64366.0, 1.077], [64381.7, 0.077], [64382.0, 0.002], [64383.4, 0.233], [64385.2, 0.0], [64401.1, 0.27], [64401.4, 0.077], [64407.9, 0.077], [64515.9, 0.192], [64516.2, 0.077], [64520.8, 0.077], [64521.1, 0.006], [64550.2, 1.818], [64551.5, 0.11], [64553.1, 0.021], [64560.3, 0.004], [64576.0, 0.01], [64583.9, 0.07], [64609.8, 0.078], [64611.4, 0.726], [64611.7, 0.0], [64634.4, 0.001], [64637.5, 0.941], [64637.6, 0.0], [64637.7, 0.31], [64638.9, 0.185], [64639.2, 0.021], [64641.6, 2.064], [64641.9, 0.334], [64642.4, 1.834], [64642.5, 0.05], [64643.7, 0.009], [64646.2, 0.21], [64646.8, 0.01], [64647.2, 0.622], [64647.5, 0.0], [64650.1, 0.105], [64654.3, 0.0], [64656.3, 0.003], [64656.6, 0.062], [64658.0, 0.002], [64660.0, 0.138], [64660.1, 0.069], [64664.9, 0.002], [64665.7, 0.108], [64667.0, 0.118], [64667.2, 1.376], [64667.6, 0.002], [64667.8, 0.002], [64671.0, 0.174], [64673.9, 2.38], [64674.4, 0.179], [64674.6, 0.073], [64675.3, 0.002], [64676.1, 0.006], [64676.4, 0.0], [64678.7, 0.05], [64679.0, 0.139], [64682.1, 0.006], [64683.6, 0.052], [64684.3, 0.348], [64684.6, 1.64], [64685.7, 2.47], [64686.1, 0.002], [64686.2, 0.674], [64687.5, 0.007], [64689.6, 0.05], [64690.6, 0.835], [64690.9, 0.005], [64692.5, 0.116], [64693.0, 0.905], [64693.2, 0.013], [64695.0, 0.003], [64696.4, 0.0], [64696.9, 0.315], [64697.5, 0.142], [64697.6, 1.353], [64697.8, 0.594], [64697.9, 0.0], [64698.3, 0.001], [64698.5, 0.022], [64698.6, 1.002], [64698.7, 0.087], [64699.0, 0.275], [64699.1, 0.09], [64699.3, 0.004], [64699.8, 0.788], [64699.9, 0.086], [64700.1, 0.006], [64700.2, 0.507], [64700.3, 1.761], [64700.4, 0.0], [64700.8, 0.11], [64701.1, 0.544], [64701.6, 0.001], [64702.0, 0.903], [64702.1, 0.128], [64702.2, 0.01], [64702.4, 0.103], [64702.9, 0.001], [64703.2, 0.001], [64703.6, 0.003], [64703.7, 0.0], [64704.0, 0.006], [64704.2, 0.048], [64704.7, 0.531], [64704.8, 0.015], [64704.9, 0.001], [64705.0, 0.043], [64705.1, 0.003], [64705.2, 1.807], [64705.3, 0.0], [64705.4, 0.0], [64705.5, 0.0]], "asks": [[64705.3, 34.14], [64705.4, 0.005], [64705.5, 4.26], [64705.6, 3.557], [64705.7, 1.396], [64705.8, 0.0], [64706.0, 1.001], [64706.1, 0.005], [64706.2, 0.001], [64707.1, 1.245], [64707.2, 0.022], [64707.3, 0.0], [64707.4, 0.322], [64707.5, 0.345], [64707.9, 0.002], [64709.1, 0.127], [64710.2, 0.011], [64710.8, 0.047], [64711.4, 0.097], [64711.6, 0.11], [64711.7, 0.204], [64712.2, 0.44], [64713.2, 0.002], [64713.7, 1.14], [64713.8, 0.003], [64715.0, 0.016], [64715.1, 0.018], [64715.7, 0.009], [64715.8, 0.153], [64716.5, 0.008], [64716.6, 0.003], [64716.7, 1.253], [64716.8, 1.683], [64718.2, 0.018], [64718.3, 0.02], [64718.4, 0.022], [64718.5, 0.016], [64718.8, 0.031], [64719.0, 0.941], [64719.6, 0.116], [64719.7, 2.329], [64720.0, 0.326], [64720.3, 0.42], [64720.4, 5.469], [64720.5, 15.623], [64722.4, 0.22], [64722.7, 0.482], [64723.0, 0.006], [64723.1, 0.001], [64723.2, 1.249], [64723.6, 0.01], [64725.0, 0.285], [64725.2, 0.003], [64726.5, 0.335], [64727.1, 0.0], [64729.2, 0.208], [64729.4, 0.003], [64729.7, 0.002], [64731.0, 0.57], [64731.2, 1.526], [64731.6, 1.24], [64732.7, 0.484], [64732.9, 0.285], [64733.2, 2.481], [64734.4, 7.484], [64734.7, 0.006], [64734.9, 0.466], [64735.5, 0.19], [64735.6, 0.556], [64739.3, 0.091], [64740.9, 0.0], [64741.2, 0.019], [64742.5, 0.071], [64742.8, 0.007], [64749.8, 0.206], [64752.4, 0.474], [64753.6, 1.48], [64760.8, 0.061], [64761.8, 0.019], [64762.0, 0.022], [64770.0, 0.537], [64770.2, 47.026], [64770.3, 0.0], [64771.3, 7.515], [64772.4, 0.0], [64778.9, 0.005], [64779.5, 0.159], [64780.9, 0.093], [64781.1, 0.0], [64804.2, 0.003], [64825.6, 0.581], [64844.0, 0.034], [64844.7, 0.772], [64899.9, 6.199], [64908.7, 0.011], [64916.2, 0.0], [65028.9, 0.049], [65352.4, 0.477], [65352.7, 1.527], [65450.8, 0.912], [65451.9, 0.269], [65452.2, 10.896], [65515.5, 1.512], [65515.6, 0.756], [65516.6, 0.0], [65624.8, 0.246], [65705.3, 0.024], [65706.1, 2.128], [65706.8, 1.19], [65877.7, 4.094], [65999.4, 3.483], [66001.3, 0.004]]}
{"kind": "depth", "E": 1787095530075, "U": 11316385702942, "u": 11316385711790, "recv_ms": 1787095530476, "bids": [[14305.2, 0.084], [14405.2, 0.504], [14407.0, 2.52], [14507.0, 0.336], [58234.6, 0.005], [61469.9, 0.0], [62117.2, 0.01], [63060.8, 0.01], [63411.1, 0.004], [63412.9, 0.021], [64058.1, 1.654], [64528.1, 0.409], [64528.2, 1.473], [64541.8, 0.01], [64541.9, 1.474], [64563.6, 0.003], [64563.7, 0.812], [64574.2, 0.019], [64574.3, 1.007], [64630.0, 0.044], [64630.8, 0.006], [64637.8, 0.0], [64637.9, 0.448], [64665.7, 0.008], [64668.0, 0.103], [64671.0, 0.104], [64673.3, 0.005], [64674.1, 0.161], [64674.4, 0.169], [64675.7, 0.003], [64678.2, 0.07], [64678.6, 0.059], [64685.6, 0.008], [64686.1, 0.001], [64688.8, 0.015], [64692.7, 0.071], [64693.6, 0.003], [64696.8, 0.145], [64697.8, 0.046], [64698.5, 0.021], [64699.0, 0.223], [64699.6, 0.002], [64699.8, 1.336], [64699.9, 0.318], [64700.6, 0.234], [64700.8, 0.093], [64701.2, 0.936], [64701.4, 0.0], [64702.2, 0.013], [64702.8, 0.006], [64704.0, 0.004], [64704.7, 0.74], [64705.0, 0.044], [64705.2, 1.71]], "asks": [[64705.3, 31.921], [64705.4, 0.021], [64705.5, 4.229], [64705.7, 1.395], [64707.1, 1.199], [64707.4, 0.242], [64707.5, 0.341], [64707.6, 0.017], [64707.7, 0.168], [64709.1, 0.085], [64709.5, 0.163], [64710.2, 0.166], [64711.3, 0.04], [64712.1, 0.243], [64712.2, 0.888], [64714.6, 0.243], [64715.1, 0.018], [64715.2, 0.17], [64715.8, 0.694], [64718.0, 0.905], [64718.4, 0.015], [64718.8, 0.011], [64719.3, 0.493], [64719.6, 0.271], [64720.3, 0.73], [64720.5, 14.155], [64720.6, 1.476], [64721.3, 0.12], [64722.7, 0.034], [64722.8, 3.406], [64723.1, 0.156], [64726.5, 0.355], [64729.4, 0.005], [64732.1, 0.091], [64732.7, 0.025], [64733.3, 0.541], [64733.4, 0.609], [64734.3, 0.002], [64734.4, 8.952], [64735.3, 0.072], [64737.0, 0.003], [64739.3, 0.001], [64742.5, 0.001], [64746.5, 0.088], [64747.3, 0.001], [64747.4, 0.179], [64759.9, 0.061], [64760.8, 0.0], [64761.5, 0.025], [64761.8, 0.009], [64796.0, 0.008], [64863.2, 0.001], [64865.8, 6.228], [64886.5, 0.112], [64902.0, 0.029], [64904.6, 1.535], [64909.9, 0.803], [64910.4, 2.648], [65352.4, 0.475], [65450.8, 2.728], [65452.2, 9.08], [65515.5, 2.268], [65516.9, 5.421]]}
{"kind": "depth", "E": 1787095530177, "U": 11316385711965, "u": 11316385721260, "recv_ms": 1787095530481, "bids": [[1000.0, 35.91], [14305.2, 0.322], [14405.2, 0.616], [14407.0, 2.282], [14507.0, 0.224], [58234.6, 0.005], [61466.1, 0.002], [61469.9, 0.0], [62116.9, 0.003], [63412.9, 0.018], [63705.2, 0.055], [64058.1, 1.658], [64382.0, 0.002], [64383.5, 3.211], [64384.9, 0.462], [64655.4, 0.061], [64656.6, 0.001], [64663.2, 0.002], [64666.0, 0.348], [64667.0, 2.118], [64668.2, 0.003], [64673.3, 0.005], [64673.9, 2.39], [64674.1, 0.151], [64685.8, 0.049], [64689.4, 0.002], [64692.9, 0.011], [64694.4, 0.01], [64696.0, 0.172], [64697.3, 0.003], [64697.6, 1.269], [64699.9, 0.086], [64700.6, 0.466], [64701.1, 0.628], [64701.2, 0.016], [64701.4, 0.0], [64701.6, 0.085], [64702.1, 1.048], [64705.2, 1.751]], "asks": [[64705.3, 32.014], [64707.1, 1.197], [64707.7, 0.169], [64707.8, 0.14], [64709.3, 0.159], [64710.2, 0.011], [64712.7, 0.014], [64712.9, 0.0], [64714.3, 0.159], [64714.5, 0.0], [64714.6, 0.163], [64714.8, 0.026], [64715.0, 0.038], [64715.1, 0.019], [64715.2, 0.17], [64715.7, 0.017], [64715.8, 0.694], [64716.2, 0.468], [64716.6, 0.011], [64716.7, 1.245], [64718.8, 0.283], [64718.9, 0.072], [64719.6, 0.271], [64720.3, 0.73], [64723.1, 0.156], [64723.2, 1.249], [64761.2, 0.044], [64761.5, 0.015], [64862.9, 11.012], [64865.8, 0.011], [64901.7, 5.488], [64904.6, 0.001], [64910.4, 5.753], [65352.4, 0.477], [65430.3, 2.136], [65450.3, 1.816], [65450.8, 0.912], [65705.3, 0.044], [66001.2, 0.03], [66001.3, 0.001]]}
{"kind": "depth", "E": 1787095530279, "U": 11316385721270, "u": 11316385729444, "recv_ms": 1787095530484, "bids": [[1000.0, 35.91], [14305.2, 0.56], [14405.2, 0.742], [14407.0, 2.044], [14507.0, 0.098], [51764.0, 0.0], [51766.0, 0.0], [58234.6, 0.005], [61466.1, 0.0], [61469.9, 0.0], [62116.9, 0.0], [63073.6, 2.296], [63411.1, 0.007], [63412.9, 0.015], [63968.6, 6.79], [64058.1, 1.654], [64073.5, 59.888], [64407.6, 0.046], [64597.3, 0.0], [64668.0, 0.257], [64673.1, 0.156], [64673.6, 2.524], [64673.7, 0.336], [64673.9, 2.38], [64693.0, 0.903], [64702.1, 0.128], [64702.8, 0.006], [64705.2, 1.784]], "asks": [[64705.3, 32.022], [64705.5, 4.836], [64707.1, 0.863], [64707.8, 0.14], [64707.9, 0.002], [64713.5, 0.003], [64724.4, 0.39], [64724.7, 0.48], [64738.7, 0.003], [64738.9, 0.14], [64739.4, 0.017], [64759.0, 0.064], [64759.9, 0.0], [64761.1, 1.322], [64761.2, 0.034], [64765.4, 0.38], [64765.8, 1.323], [64817.2, 0.015], [64901.7, 5.583], [65338.1, 59.856], [65352.4, 0.477], [65418.9, 3.053], [65450.3, 2.724], [65452.2, 8.172], [65515.0, 1.513], [65516.9, 3.909], [65677.7, 3.061]]}
{"kind": "depth", "E": 1787095530381, "U": 11316385729533, "u": 11316385736498, "recv_ms": 1787095530489, "bids": [[14305.2, 0.826], [14405.2, 0.84], [14407.0, 1.778], [14507.0, 0.0], [58234.6, 0.005], [61469.9, 0.0], [63704.4, 11.343], [63705.2, 0.035], [63769.3, 0.315], [63786.3, 3.381], [63917.1, 6.064], [64058.1, 1.654], [64409.2, 0.496], [64638.9, 0.3], [64642.2, 0.02], [64643.7, 0.182], [64648.2, 1.786], [64663.2, 0.0], [64664.1, 3.503], [64664.7, 0.001], [64666.3, 0.015], [64683.3, 0.164], [64687.2, 0.019], [64690.1, 0.736], [64693.7, 0.177], [64694.3, 0.405], [64694.4, 0.009], [64694.7, 0.013], [64697.8, 0.046], [64698.0, 0.136], [64698.1, 0.191], [64699.3, 0.002], [64700.7, 0.256], [64701.4, 0.002], [64701.5, 0.001], [64702.1, 0.212], [64704.0, 0.048], [64704.2, 0.002], [64704.9, 0.0], [64705.2, 3.256]], "asks": [[64705.3, 31.639], [64707.7, 0.168], [64708.0, 0.047], [64708.4, 0.09], [64709.3, 0.159], [64713.9, 0.24], [64715.1, 0.018], [64715.2, 0.17], [64719.6, 0.271], [64720.3, 0.73], [64723.1, 0.001], [64723.2, 1.404], [64724.3, 0.002], [64724.7, 0.463], [64724.8, 0.814], [64731.0, 0.014], [64731.2, 1.469], [64732.6, 0.719], [64770.2, 47.028], [64771.3, 7.513], [64862.9, 6.848], [64901.7, 1.531], [65352.4, 0.477], [65450.3, 3.632], [65452.2, 7.264], [65515.0, 2.269], [65516.9, 3.153], [65705.3, 0.024], [66001.2, 0.027], [68293.9, 0.004]]}
{"kind": "depth", "E": 1787095530483, "U": 11316385736502, "u": 11316385743105, "recv_ms": 1787095530545, "bids": [[1000.0, 35.91], [14305.2, 1.176], [14407.0, 1.428], [51764.2, 0.0], [58234.6, 0.005], [61469.9, 0.0], [62116.9, 0.003], [63411.1, 0.01], [63412.9, 0.012], [63999.8, 4.037], [64058.1, 1.654], [64381.7, 0.077], [64551.5, 0.187], [64664.1, 3.502], [64673.5, 2.803], [64673.7, 0.326], [64683.3, 0.164], [64687.2, 0.019], [64694.3, 0.405], [64694.7, 0.013], [64697.1, 0.125], [64697.8, 0.054], [64698.1, 0.188], [64698.5, 0.021], [64700.6, 1.007], [64701.1, 0.087], [64701.4, 0.002], [64701.6, 0.001], [64702.1, 0.128], [64702.7, 0.002], [64703.0, 0.002], [64705.2, 1.884]], "asks": [[64705.3, 31.646], [64705.6, 3.553], [64706.1, 0.002], [64708.4, 0.086], [64709.3, 0.159], [64715.2, 0.17], [64719.6, 0.271], [64720.3, 0.73], [64723.1, 0.156], [64723.2, 1.249], [64752.7, 0.015], [64752.8, 0.005], [64755.5, 0.393], [64760.9, 0.01], [64761.1, 1.312], [64824.4, 0.008], [64862.9, 6.847], [64901.7, 1.528], [65352.4, 0.475], [65450.3, 4.54], [65452.2, 6.356], [65464.2, 0.906], [65464.6, 1.431]]}
{"kind": "depth", "E": 1787095530585, "U": 11316385743133, "u": 11316385751194, "recv_ms": 1787095530647, "bids": [[1000.0, 35.91], [14305.2, 1.526], [14407.0, 1.078], [58234.6, 0.005], [61469.9, 0.001], [62116.9, 0.0], [63702.2, 1.098], [63705.2, 0.055], [63928.6, 0.469], [64058.1, 1.656], [64511.3, 5.682], [64543.3, 1.485], [64605.8, 0.001], [64606.0, 0.012], [64639.8, 6.448], [64648.2, 1.772], [64650.8, 0.172], [64666.3, 0.001], [64668.9, 2.354], [64673.4, 0.018], [64673.5, 2.793], [64683.3, 0.164], [64687.2, 0.019], [64694.3, 0.405], [64694.7, 0.013], [64697.4, 0.004], [64697.8, 0.602], [64699.6, 0.001], [64699.8, 0.788], [64700.0, 0.245], [64700.2, 0.508], [64700.3, 1.763], [64700.6, 0.775], [64701.3, 1.885], [64701.4, 0.126], [64701.8, 0.001], [64702.1, 0.004], [64702.2, 0.005], [64702.4, 1.641], [64702.5, 2.328], [64702.6, 0.0], [64704.7, 1.084], [64705.2, 1.887]], "asks": [[64705.3, 33.524], [64705.6, 3.551], [64708.1, 0.0], [64708.2, 0.0], [64708.5, 0.0], [64709.3, 0.159], [64713.3, 0.006], [64715.2, 0.17], [64719.6, 0.271], [64720.3, 0.73], [64723.1, 0.156], [64724.8, 0.797], [64725.8, 0.422], [64733.3, 2.963], [64752.8, 0.005], [64760.8, 0.01], [64760.9, 0.0], [64768.6, 8.834], [64817.2, 0.018], [64836.6, 0.003], [64861.0, 1.649], [64896.9, 0.0], [64897.1, 0.232], [64907.1, 3.659], [65075.9, 6.414], [65352.4, 0.475], [65450.3, 6.356], [65452.2, 4.54], [65514.4, 1.371], [65677.7, 6.101], [65705.3, 0.044], [65837.7, 1.203], [66001.2, 0.024]]}
{"kind": "depth", "E": 1787095530687, "U": 11316385751213, "u": 11316385757090, "recv_ms": 1787095530749, "bids": [[14305.2, 1.89], [14407.0, 0.714], [58234.6, 0.005], [61469.9, 0.0], [62116.9, 0.003], [63589.5, 0.0], [64058.1, 1.654], [64222.6, 0.0], [64630.0, 0.014], [64630.1, 0.032], [64672.6, 0.004], [64673.3, 0.015], [64673.4, 0.008], [64673.6, 2.52], [64683.3, 0.164], [64687.2, 0.019], [64688.8, 0.008], [64689.1, 0.002], [64691.2, 0.032], [64692.0, 1.586], [64694.3, 0.405], [64694.4, 0.009], [64694.7, 0.013], [64697.1, 0.04], [64697.8, 0.139], [64698.0, 0.139], [64698.6, 0.002], [64699.1, 0.087], [64699.8, 1.788], [64699.9, 0.637], [64700.3, 0.218], [64700.6, 0.234], [64701.1, 0.087], [64701.2, 0.008], [64701.3, 0.232], [64701.4, 0.545], [64701.5, 1.546], [64701.6, 0.009], [64701.7, 0.091], [64702.7, 0.126], [64705.2, 3.355]], "asks": [[64705.3, 31.586], [64705.4, 0.023], [64705.5, 4.838], [64705.7, 1.085], [64707.2, 0.018], [64707.9, 0.003], [64708.2, 0.0], [64708.5, 0.004], [64709.0, 0.0], [64709.3, 0.159], [64713.1, 0.321], [64715.2, 0.17], [64715.5, 0.002], [64716.6, 0.019], [64718.9, 0.064], [64719.6, 0.271], [64720.3, 0.73], [64723.1, 0.156], [64746.5, 0.058], [64746.7, 0.03], [64752.7, 0.015], [64752.8, 0.005], [64760.7, 0.072], [64760.8, 0.0], [64862.9, 11.012], [64901.7, 5.304], [65352.4, 0.475], [65515.0, 3.025], [65516.9, 2.397], [65999.4, 3.486], [66001.2, 0.021]]}
{"kind": "depth", "E": 1787095530789, "U": 11316385757226, "u": 11316385762148, "recv_ms": 1787095530849, "bids": [[1000.0, 35.91], [14305.2, 2.24], [14407.0, 0.364], [58234.6, 0.005], [61469.9, 0.0], [64058.1, 1.654], [64073.3, 0.001], [64356.6, 0.001], [64358.3, 0.491], [64381.7, 0.087], [64584.9, 0.014], [64585.7, 0.027], [64592.0, 0.038], [64592.8, 0.0], [64599.0, 0.013], [64599.8, 0.0], [64606.1, 0.013], [64606.9, 0.028], [64613.1, 0.014], [64613.9, 0.0], [64620.2, 0.641], [64621.0, 0.013], [64627.2, 0.259], [64628.0, 0.001], [64634.3, 0.014], [64635.1, 2.389], [64648.2, 1.786], [64652.5, 0.001], [64668.0, 0.257], [64683.3, 0.164], [64687.2, 0.019], [64694.4, 0.009], [64694.7, 0.013], [64697.8, 0.139], [64700.5, 1.124], [64701.6, 0.009], [64702.0, 0.907], [64702.8, 0.006], [64705.2, 3.359]], "asks": [[64708.5, 0.0], [64708.6, 0.0], [64709.3, 0.159], [64710.2, 0.011], [64715.2, 0.17], [64716.6, 0.011], [64718.7, 0.024], [64718.9, 0.072], [64719.4, 0.008], [64719.6, 0.271], [64720.3, 0.73], [64723.1, 0.156], [64723.2, 1.249], [64752.5, 0.001], [64752.6, 0.204], [64752.7, 0.015], [65352.4, 0.475], [65450.3, 7.264], [65452.3, 7.927]]}
{"kind": "depth", "E": 1787095530891, "U": 11316385762392, "u": 11316385768415, "recv_ms": 1787095530953, "bids": [[1000.0, 35.91], [14305.2, 2.604], [14407.0, 0.0], [58234.6, 0.005], [61469.9, 0.0], [62116.9, 0.0], [63618.2, 0.643], [63705.2, 0.035], [64058.1, 1.654], [64071.2, 1.034], [64381.6, 0.008], [64563.5, 5.266], [64565.0, 1.755], [64566.6, 0.003], [64648.2, 1.772], [64673.2, 0.016], [64673.3, 0.005], [64683.3, 0.319], [64687.2, 0.174], [64693.3, 0.184], [64693.7, 0.061], [64694.3, 0.56], [64694.7, 0.168], [64697.8, 0.139], [64697.9, 0.0], [64698.0, 0.294], [64699.1, 0.086], [64699.8, 1.789], [64699.9, 0.637], [64700.2, 0.507], [64701.1, 0.087], [64701.5, 1.546], [64702.5, 2.32], [64702.6, 0.155], [64702.7, 0.126], [64702.8, 0.014], [64705.2, 3.073]], "asks": [[64708.6, 0.0], [64709.3, 0.004], [64715.2, 0.015], [64716.6, 0.011], [64718.9, 0.064], [64719.6, 0.116], [64720.3, 0.42], [64723.1, 0.001], [64746.5, 0.088], [64746.7, 0.0], [64752.6, 0.05], [64752.8, 0.159], [64760.6, 0.013], [64760.7, 0.062], [64845.9, 5.421], [64847.7, 0.001], [64862.9, 6.936], [64901.7, 1.527], [65029.2, 0.0], [65352.4, 0.477], [65610.8, 1.818], [65705.3, 0.024], [65871.8, 8.489], [66001.2, 0.018]]}
{"kind": "depth", "E": 1787095530993, "U": 11316385768453, "u": 11316385775833, "recv_ms": 1787095531054, "bids": [[14305.2, 2.954], [14405.5, 0.406], [14405.6, 0.0], [14406.0, 0.0], [14406.2, 0.0], [14406.7, 0.0], [58234.6, 0.005], [61469.9, 0.0], [62116.9, 0.003], [63411.1, 0.013], [63790.0, 0.153], [63928.8, 0.219], [64058.1, 1.654], [64360.2, 6.453], [64361.9, 0.01], [64648.2, 1.772], [64666.3, 0.001], [64668.0, 0.257], [64681.5, 0.033], [64683.3, 0.319], [64687.2, 0.174], [64688.0, 1.408], [64688.8, 0.006], [64690.7, 0.008], [64691.2, 0.581], [64692.0, 1.03], [64692.9, 0.011], [64693.3, 0.184], [64694.2, 1.675], [64694.3, 0.56], [64694.7, 0.168], [64697.2, 0.006], [64697.8, 0.294], [64698.0, 0.136], [64699.7, 2.324], [64699.9, 0.634], [64700.0, 0.245], [64700.2, 0.048], [64700.6, 0.233], [64700.8, 0.552], [64701.1, 1.64], [64701.2, 0.549], [64701.4, 0.002], [64701.5, 0.001], [64701.6, 0.001], [64701.7, 0.007], [64702.0, 0.907], [64702.3, 0.004], [64702.6, 0.165], [64702.7, 0.126], [64702.8, 0.006], [64705.2, 3.038]], "asks": [[64705.3, 31.595], [64705.7, 1.085], [64707.5, 0.333], [64708.3, 0.001], [64708.6, 0.0], [64708.7, 0.058], [64709.3, 0.004], [64715.2, 0.015], [64716.6, 0.011], [64718.9, 0.072], [64719.6, 0.116], [64720.2, 0.006], [64720.3, 4.42], [64720.4, 3.546], [64720.5, 4.155], [64721.3, 0.118], [64723.1, 0.001], [64731.5, 0.001], [64732.4, 1.321], [64732.6, 0.163], [64733.3, 2.504], [64734.1, 0.459], [64823.6, 0.068], [64862.9, 6.828], [64901.7, 1.529], [65028.9, 0.048], [65352.4, 0.475], [65999.4, 3.489], [66001.2, 0.015]]}
{"kind": "depth", "E": 1787095531095, "U": 11316385775907, "u": 11316385782738, "recv_ms": 1787095531163, "bids": [[1000.0, 35.91], [14305.2, 3.318], [14405.5, 0.042], [58234.6, 0.005], [61469.9, 0.0], [62116.9, 0.0], [63411.0, 0.003], [63705.2, 0.055], [64058.1, 1.66], [64381.6, 0.009], [64381.7, 0.077], [64583.9, 0.0], [64648.2, 1.786], [64655.3, 0.11], [64666.3, 0.015], [64667.0, 0.118], [64683.3, 0.164], [64687.2, 0.019], [64688.8, 0.008], [64693.6, 0.003], [64694.3, 0.405], [64694.7, 0.005], [64697.8, 0.123], [64701.1, 1.548], [64701.3, 0.0], [64701.4, 0.002], [64701.5, 0.001], [64702.4, 0.103], [64702.5, 0.001], [64702.6, 0.01], [64702.8, 0.006], [64705.0, 0.0], [64705.1, 0.0], [64705.2, 0.0]], "asks": [[64704.9, 13.322], [64705.1, 8.152], [64705.2, 10.772], [64705.3, 29.509], [64705.4, 0.021], [64705.9, 0.0], [64706.0, 0.001], [64707.1, 0.855], [64707.4, 0.24], [64708.2, 0.001], [64708.4, 0.086], [64708.6, 0.0], [64709.3, 0.159], [64714.3, 0.151], [64715.2, 0.17], [64715.7, 0.009], [64716.6, 0.003], [64718.9, 0.064], [64719.4, 0.016], [64719.6, 0.426], [64720.2, 0.161], [64721.3, 0.12], [64722.7, 0.032], [64723.1, 0.156], [64732.8, 0.557], [64734.1, 0.0], [64751.0, 1.91], [64757.5, 0.017], [64760.5, 0.01], [64760.6, 0.003], [64763.9, 0.0], [64770.4, 0.023], [64862.9, 11.012], [64901.7, 5.059], [64910.4, 2.648], [65352.3, 0.018], [65352.4, 0.475], [65450.1, 1.764], [65452.2, 3.632], [65514.8, 1.187], [65516.9, 1.641], [65705.3, 0.044], [65706.3, 0.002], [65706.8, 1.184], [65805.3, 0.91]]}
{"kind": "depth", "E": 1787095531197, "U": 11316385782739, "u": 11316385803656, "recv_ms": 1787095531262, "bids": [[1000.0, 35.91], [14304.7, 0.322], [14304.8, 0.028], [14405.2, 0.532], [14405.5, 0.0], [58234.2, 0.004], [58234.3, 0.0], [58234.6, 0.003], [61469.4, 0.001], [61471.6, 0.002], [61471.7, 0.002], [62116.5, 0.003], [63410.7, 0.01], [63412.9, 0.009], [63705.2, 0.035], [63799.1, 10.798], [63818.5, 0.625], [64057.7, 0.405], [64057.8, 0.0], [64058.1, 1.654], [64528.2, 0.001], [64528.3, 1.474], [64534.2, 1.421], [64541.9, 0.002], [64542.0, 1.472], [64555.6, 0.0], [64555.7, 1.488], [64560.3, 0.004], [64583.6, 0.069], [64585.2, 0.024], [64585.4, 0.0], [64585.5, 0.0], [64598.3, 2.318], [64599.5, 0.0], [64601.0, 0.629], [64626.9, 0.001], [64627.0, 2.162], [64629.5, 2.32], [64630.1, 0.002], [64635.1, 0.39], [64635.3, 2.045], [64635.9, 0.026], [64636.1, 32.364], [64637.3, 0.015], [64637.5, 0.915], [64638.2, 0.422], [64639.8, 1.759], [64643.4, 0.001], [64643.5, 3.135], [64643.6, 0.094], [64644.9, 0.005], [64646.8, 0.006], [64648.8, 0.004], [64649.1, 0.03], [64649.2, 0.074], [64650.1, 0.095], [64654.9, 0.076], [64655.4, 0.0], [64657.9, 0.311], [64658.6, 0.31], [64658.7, 0.0], [64660.1, 0.073], [64662.3, 0.0], [64662.4, 4.281], [64667.6, 0.156], [64667.7, 0.005], [64667.8, 0.002], [64668.0, 0.103], [64670.9, 0.293], [64671.0, 0.104], [64671.9, 0.073], [64676.2, 0.004], [64677.2, 0.178], [64677.3, 0.011], [64677.6, 0.682], [64678.1, 0.0], [64678.6, 0.002], [64680.1, 0.023], [64680.8, 0.002], [64681.7, 0.001], [64683.1, 0.63], [64683.3, 0.164], [64684.1, 0.544], [64684.4, 1.702], [64685.4, 0.01], [64685.8, 0.048], [64686.2, 0.667], [64686.4, 0.003], [64687.2, 0.019], [64688.0, 1.393], [64688.6, 0.087], [64688.8, 0.162], [64689.4, 0.009], [64689.7, 0.556], [64689.9, 0.002], [64690.4, 0.12], [64690.5, 0.0], [64690.6, 0.795], [64690.7, 0.001], [64690.8, 0.081], [64691.2, 0.023], [64691.4, 0.002], [64691.8, 0.433], [64691.9, 0.776], [64692.2, 0.165], [64692.6, 0.001], [64693.0, 0.905], [64693.3, 0.068], [64693.8, 0.001], [64693.9, 1.312], [64694.3, 0.095], [64694.4, 0.319], [64694.7, 0.106], [64695.2, 0.017], [64695.7, 0.202], [64695.9, 0.327], [64696.5, 0.12], [64696.8, 0.146], [64696.9, 0.245], [64697.0, 3.867], [64697.1, 1.04], [64697.2, 0.003], [64697.3, 0.087], [64697.5, 0.142], [64697.6, 1.353], [64697.7, 0.5], [64697.8, 0.594], [64697.9, 0.0], [64698.0, 0.22], [64698.1, 0.188], [64698.4, 0.722], [64698.5, 0.021], [64698.7, 0.092], [64699.0, 0.246], [64699.1, 0.086], [64699.2, 0.002], [64699.3, 0.002], [64699.4, 0.003], [64699.5, 0.086], [64699.6, 0.001], [64699.7, 2.321], [64699.8, 0.478], [64699.9, 1.639], [64700.0, 0.786], [64700.1, 0.006], [64700.3, 0.134], [64700.6, 0.002], [64700.7, 0.254], [64700.8, 0.009], [64700.9, 0.033], [64701.1, 0.127], [64701.2, 0.014], [64701.3, 0.0], [64701.4, 0.0], [64701.6, 0.005], [64701.8, 0.001], [64701.9, 0.0], [64702.0, 0.903], [64702.1, 0.004], [64702.2, 0.003], [64702.4, 0.102], [64702.5, 0.001], [64702.6, 0.309], [64702.7, 0.002], [64703.2, 0.48], [64703.6, 0.01], [64703.8, 0.002], [64703.9, 0.044], [64704.0, 0.004], [64704.1, 1.39], [64704.2, 0.001], [64704.6, 0.002], [64704.7, 0.072], [64704.8, 0.0]], "asks": [[64704.8, 43.997], [64704.9, 3.623], [64705.0, 1.004], [64705.1, 3.5], [64705.2, 3.893], [64705.3, 0.573], [64705.4, 0.017], [64705.5, 0.003], [64705.6, 0.359], [64705.7, 0.084], [64705.8, 0.0], [64706.0, 0.0], [64706.3, 0.092], [64707.1, 0.469], [64707.2, 0.004], [64707.5, 0.34], [64707.6, 0.018], [64707.7, 0.215], [64708.0, 0.047], [64708.3, 0.001], [64708.8, 0.002], [64709.3, 0.159], [64709.4, 0.065], [64709.6, 0.227], [64709.7, 0.124], [64709.8, 0.084], [64710.0, 0.007], [64710.1, 0.079], [64710.3, 0.085], [64710.5, 0.001], [64710.7, 0.107], [64711.1, 0.037], [64711.9, 0.279], [64712.0, 0.587], [64712.1, 0.251], [64712.4, 0.004], [64712.5, 0.181], [64712.7, 0.004], [64713.1, 0.012], [64713.3, 0.004], [64713.4, 0.406], [64713.5, 0.001], [64713.6, 0.021], [64713.7, 2.245], [64713.8, 0.422], [64713.9, 0.389], [64714.0, 0.001], [64714.2, 0.002], [64714.4, 0.02], [64714.5, 2.876], [64714.6, 10.002], [64714.7, 0.0], [64714.8, 0.007], [64715.0, 0.016], [64715.2, 0.015], [64715.5, 0.288], [64715.6, 0.01], [64715.8, 0.153], [64716.0, 0.126], [64716.2, 0.391], [64716.6, 0.003], [64717.1, 2.549], [64717.2, 0.002], [64717.7, 0.006], [64717.8, 0.006], [64717.9, 2.001], [64718.2, 0.014], [64718.4, 0.015], [64718.5, 0.015], [64718.8, 0.503], [64719.4, 0.008], [64719.6, 0.271], [64719.8, 0.022], [64720.2, 0.006], [64720.3, 0.42], [64720.5, 4.153], [64720.8, 0.188], [64721.8, 0.003], [64722.4, 0.0], [64723.0, 0.006], [64723.1, 0.003], [64724.3, 0.662], [64725.0, 0.284], [64725.6, 0.001], [64726.0, 0.904], [64726.1, 2.312], [64726.5, 0.335], [64729.7, 0.002], [64730.0, 3.237], [64730.4, 0.015], [64730.9, 0.012], [64731.0, 0.071], [64731.1, 0.313], [64731.4, 0.015], [64731.9, 0.802], [64732.4, 0.765], [64732.6, 0.106], [64732.7, 0.016], [64732.8, 0.098], [64733.0, 0.443], [64733.4, 0.161], [64733.5, 0.639], [64739.3, 0.001], [64739.6, 0.213], [64741.2, 0.013], [64744.8, 0.001], [64745.8, 0.03], [64746.0, 1.482], [64746.5, 0.058], [64746.7, 0.0], [64748.1, 1.001], [64748.2, 2.134], [64749.2, 0.001], [64756.0, 1.259], [64758.5, 0.061], [64759.0, 0.003], [64759.6, 0.006], [64763.0, 0.03], [64763.4, 0.015], [64763.6, 0.005], [64764.3, 0.0], [64768.6, 1.842], [64769.5, 0.027], [64770.1, 51.659], [64770.2, 0.002], [64772.3, 7.421], [64777.9, 0.027], [64778.9, 0.005], [64779.5, 0.133], [64781.2, 0.0], [64812.2, 2.323], [64813.4, 0.0], [64844.7, 0.772], [64862.4, 6.232], [64862.9, 0.605], [64901.2, 1.575], [64901.7, 0.002], [65351.8, 0.012], [65351.9, 0.073], [65352.3, 0.0], [65514.8, 1.943], [65516.9, 0.885], [65626.4, 1.432], [65658.3, 0.763], [65704.9, 0.038], [65705.2, 0.004], [65705.3, 0.024], [65706.0, 0.01], [65706.3, 0.0], [65706.8, 1.17], [65998.8, 3.953], [65998.9, 0.028]]}
{"kind": "depth", "E": 1787095531299, "U": 11316385803710, "u": 11316385823078, "recv_ms": 1787095531430, "bids": [[14203.1, 0.056], [14204.7, 0.084], [14303.1, 0.028], [14303.6, 0.014], [14304.2, 0.014], [14304.7, 0.49], [14305.2, 3.178], [14405.2, 0.308], [51764.0, 0.0], [58232.7, 0.002], [58234.2, 0.002], [61468.4, 0.051], [61469.5, 0.015], [63292.9, 0.043], [63294.8, 0.002], [63410.7, 0.013], [63826.5, 0.782], [63894.5, 0.234], [64056.1, 0.042], [64056.6, 0.007], [64057.0, 1.13], [64057.2, 0.0], [64057.7, 0.403], [64062.4, 0.865], [64185.5, 0.01], [64378.6, 12.368], [64380.1, 2.984], [64401.1, 0.193], [64401.4, 0.0], [64407.9, 0.0], [64510.5, 0.003], [64529.1, 0.021], [64532.3, 0.001], [64539.7, 0.095], [64542.0, 0.0], [64542.1, 1.472], [64550.2, 1.741], [64550.3, 0.077], [64551.5, 0.18], [64555.7, 0.016], [64555.8, 1.472], [64560.3, 0.005], [64561.4, 1.0], [64563.7, 0.363], [64563.8, 0.449], [64567.1, 0.015], [64574.3, 0.558], [64574.4, 14.196], [64582.5, 0.068], [64583.1, 0.0], [64583.6, 0.0], [64584.0, 3.008], [64584.5, 0.004], [64584.9, 0.014], [64585.0, 0.001], [64601.0, 0.628], [64609.8, 0.001], [64611.4, 0.719], [64635.6, 0.027], [64636.1, 0.0], [64637.9, 0.0], [64638.0, 0.483], [64638.1, 1.238], [64638.3, 32.367], [64638.4, 1.248], [64638.9, 0.216], [64641.9, 0.322], [64642.5, 0.134], [64642.7, 0.133], [64642.8, 0.027], [64643.6, 0.017], [64643.7, 0.175], [64644.1, 0.1], [64644.8, 1.054], [64647.2, 0.627], [64647.7, 0.0], [64648.3, 0.001], [64649.2, 0.069], [64653.3, 0.392], [64655.3, 0.11], [64658.0, 0.005], [64662.9, 0.002], [64663.8, 0.002], [64664.4, 0.002], [64665.1, 0.085], [64667.6, 0.002], [64667.9, 0.002], [64669.5, 0.0], [64670.0, 0.635], [64670.4, 1.277], [64670.9, 0.287], [64671.0, 0.087], [64671.2, 0.005], [64672.6, 0.0], [64673.1, 0.166], [64673.2, 0.006], [64674.2, 0.159], [64674.3, 0.388], [64675.0, 0.107], [64675.3, 0.002], [64675.6, 0.017], [64676.1, 0.0], [64676.3, 0.057], [64676.5, 0.003], [64677.2, 0.164], [64677.3, 0.002], [64677.6, 0.625], [64678.3, 0.006], [64678.4, 1.535], [64679.1, 0.001], [64679.4, 0.48], [64680.1, 0.008], [64680.8, 1.3], [64681.2, 2.71], [64681.6, 1.188], [64681.9, 0.008], [64682.3, 1.371], [64683.1, 0.628], [64683.3, 0.164], [64684.4, 0.001], [64684.6, 1.648], [64684.7, 0.001], [64684.8, 0.674], [64685.3, 0.01], [64685.4, 0.004], [64685.8, 0.048], [64686.2, 0.007], [64686.5, 0.025], [64686.6, 0.044], [64687.2, 0.019], [64689.7, 0.563], [64690.2, 0.126], [64690.4, 0.289], [64690.6, 0.795], [64690.7, 0.021], [64690.8, 0.228], [64691.8, 0.311], [64692.0, 1.03], [64692.2, 0.011], [64693.0, 0.906], [64693.3, 0.052], [64693.9, 1.272], [64694.2, 1.676], [64694.3, 0.119], [64694.4, 0.163], [64694.5, 0.325], [64694.6, 0.005], [64694.7, 0.082], [64694.8, 0.012], [64694.9, 0.006], [64695.4, 0.172], [64695.5, 0.142], [64695.9, 0.173], [64696.0, 0.173], [64696.1, 0.107], [64696.2, 0.157], [64696.6, 0.032], [64697.1, 0.039], [64697.2, 0.551], [64697.4, 1.004], [64697.5, 0.142], [64697.6, 1.356], [64697.7, 0.5], [64697.8, 0.046], [64697.9, 0.002], [64698.1, 0.194], [64698.2, 0.101], [64698.4, 0.263], [64698.5, 0.021], [64698.6, 1.549], [64698.7, 0.636], [64698.9, 0.055], [64699.0, 0.014], [64699.1, 0.002], [64699.2, 0.461], [64699.5, 0.002], [64699.6, 0.085], [64699.8, 0.385], [64699.9, 0.13], [64700.0, 0.329], [64700.1, 0.004], [64700.2, 0.048], [64700.3, 0.134], [64700.4, 0.0], [64700.5, 1.123], [64700.6, 0.002], [64700.8, 0.015], [64700.9, 0.019], [64701.0, 0.848], [64701.1, 0.004], [64701.2, 0.006], [64701.3, 0.0], [64701.4, 0.0], [64701.5, 0.001], [64701.6, 0.001], [64701.7, 0.0], [64701.8, 0.0], [64702.0, 0.903], [64702.1, 0.001], [64702.3, 0.003], [64702.4, 0.002], [64702.5, 0.0], [64702.6, 0.0], [64702.7, 0.002], [64702.8, 0.662], [64702.9, 0.001], [64703.0, 0.01], [64703.1, 1.973], [64703.2, 0.0], [64703.3, 0.0], [64703.4, 0.0], [64703.5, 0.0], [64703.6, 0.0], [64703.8, 0.0], [64703.9, 0.0], [64704.0, 0.0], [64704.1, 0.0], [64704.2, 0.0], [64704.3, 0.0], [64704.6, 0.0], [64704.7, 0.0]], "asks": [[64703.2, 35.899], [64703.3, 0.003], [64703.4, 0.002], [64703.5, 0.008], [64703.6, 2.5], [64703.7, 1.086], [64703.8, 0.0], [64703.9, 0.001], [64704.0, 0.002], [64704.1, 1.155], [64704.2, 2.501], [64704.3, 6.765], [64704.4, 0.001], [64704.5, 0.046], [64704.7, 2.501], [64704.8, 3.911], [64704.9, 0.094], [64705.0, 0.006], [64705.1, 0.002], [64705.2, 0.391], [64705.3, 0.555], [64705.4, 0.016], [64705.5, 0.001], [64705.9, 0.001], [64706.0, 0.001], [64706.1, 0.007], [64706.3, 0.093], [64706.5, 0.001], [64706.6, 0.001], [64706.7, 0.0], [64706.8, 0.121], [64706.9, 0.015], [64707.0, 0.001], [64707.2, 0.005], [64707.4, 0.241], [64707.5, 0.333], [64707.7, 0.208], [64707.9, 0.002], [64708.0, 0.055], [64708.7, 0.058], [64708.8, 0.003], [64709.0, 0.02], [64709.1, 0.109], [64709.2, 0.026], [64709.3, 0.004], [64709.4, 0.011], [64709.6, 0.228], [64709.7, 0.004], [64709.8, 0.043], [64709.9, 0.001], [64710.1, 0.059], [64710.3, 0.001], [64710.4, 0.05], [64710.7, 0.023], [64710.8, 0.046], [64710.9, 0.872], [64711.2, 0.179], [64711.5, 0.535], [64711.9, 0.261], [64712.0, 0.278], [64712.1, 0.261], [64712.2, 0.44], [64712.3, 0.621], [64712.5, 0.005], [64712.8, 0.004], [64713.0, 0.002], [64713.4, 0.947], [64713.6, 0.183], [64714.4, 0.951], [64714.5, 2.335], [64714.9, 0.003], [64715.2, 0.008], [64715.5, 0.288], [64715.6, 0.002], [64715.8, 0.003], [64716.1, 0.037], [64716.6, 0.003], [64716.7, 1.237], [64716.9, 0.006], [64717.0, 0.994], [64717.2, 0.0], [64717.3, 0.007], [64717.6, 0.464], [64717.7, 0.137], [64717.8, 0.002], [64717.9, 3.001], [64718.7, 0.004], [64719.0, 0.941], [64719.3, 0.486], [64719.4, 0.026], [64719.5, 0.033], [64719.6, 0.446], [64720.3, 0.422], [64720.4, 2.546], [64720.6, 0.008], [64720.7, 1.469], [64720.9, 0.014], [64721.8, 0.003], [64722.2, 0.563], [64722.6, 0.667], [64722.8, 2.958], [64722.9, 0.452], [64723.1, 0.156], [64723.6, 0.009], [64723.7, 0.005], [64724.2, 0.004], [64724.3, 0.002], [64724.4, 0.389], [64724.8, 0.797], [64725.8, 0.387], [64726.4, 2.329], [64727.8, 0.333], [64727.9, 0.68], [64729.1, 0.454], [64729.2, 0.21], [64729.7, 0.017], [64730.2, 0.125], [64730.3, 0.003], [64730.4, 0.0], [64730.6, 0.562], [64730.9, 0.012], [64731.1, 0.313], [64731.7, 0.764], [64731.9, 0.334], [64733.2, 2.469], [64733.6, 2.956], [64733.9, 0.073], [64734.2, 0.006], [64734.4, 7.484], [64734.5, 1.471], [64734.7, 0.0], [64735.0, 0.156], [64736.1, 1.977], [64736.4, 0.388], [64737.6, 1.265], [64739.5, 0.001], [64739.6, 0.213], [64739.7, 0.016], [64740.0, 0.058], [64740.8, 1.357], [64743.9, 0.043], [64744.9, 0.026], [64745.8, 0.002], [64747.0, 0.0], [64747.8, 0.058], [64747.9, 0.075], [64748.0, 0.002], [64748.1, 1.016], [64748.2, 2.14], [64748.6, 0.097], [64749.0, 6.637], [64750.2, 6.957], [64754.3, 0.001], [64755.4, 0.038], [64757.2, 0.005], [64759.6, 0.0], [64760.4, 0.397], [64760.5, 0.0], [64761.6, 0.012], [64762.1, 0.474], [64762.7, 0.0], [64763.6, 0.0], [64767.9, 0.017], [64768.6, 1.84], [64768.7, 0.667], [64769.6, 3.47], [64770.1, 4.386], [64772.2, 0.019], [64778.9, 0.005], [64781.1, 0.0], [64783.4, 0.0], [64785.5, 0.027], [64786.0, 0.045], [64787.4, 8.245], [64787.8, 47.277], [64793.8, 0.435], [64794.7, 0.0], [64795.4, 0.001], [64801.0, 25.036], [64807.5, 0.556], [64810.9, 0.0], [64822.7, 0.067], [64823.6, 0.0], [64842.1, 0.002], [64844.7, 0.771], [64845.4, 5.397], [64845.9, 0.024], [64854.0, 0.0], [64862.4, 10.407], [64871.5, 22.544], [64881.4, 0.002], [64901.2, 6.671], [65350.2, 0.0], [65350.7, 0.118], [65351.1, 0.409], [65351.3, 0.0], [65351.8, 0.008], [65450.1, 2.672], [65452.2, 2.724], [65597.9, 24.717], [65675.9, 0.379], [65703.7, 0.01], [65704.1, 1.1], [65704.3, 0.024], [65704.9, 0.024], [65705.2, 0.0], [65705.3, 0.006], [65706.0, 0.004], [65997.2, 0.014], [65998.8, 3.956]]}
{"kind": "depth", "E": 1787095531401, "U": 11316385823327, "u": 11316385833598, "recv_ms": 1787095531466, "bids": [[1000.0, 35.91], [14203.1, 0.294], [14303.1, 0.14], [14305.2, 2.94], [14405.2, 0.196], [51763.0, 0.0], [58232.7, 0.002], [61467.9, 0.0], [62116.5, 0.0], [63703.1, 0.805], [63847.0, 3.928], [64056.1, 0.048], [64381.7, 0.087], [64528.3, 0.002], [64528.4, 1.472], [64549.2, 0.024], [64555.8, 0.0], [64555.9, 1.473], [64560.3, 0.005], [64563.8, 0.0], [64563.9, 0.449], [64574.4, 13.747], [64574.5, 2.734], [64600.7, 0.116], [64622.0, 0.284], [64627.9, 0.037], [64629.5, 2.29], [64638.0, 0.035], [64638.1, 1.688], [64642.5, 0.057], [64643.9, 0.398], [64644.8, 1.04], [64653.3, 0.453], [64654.9, 0.015], [64661.7, 0.002], [64663.2, 0.001], [64663.9, 0.133], [64667.0, 0.272], [64667.1, 1.29], [64668.3, 0.116], [64668.8, 1.486], [64672.3, 0.006], [64678.5, 0.138], [64679.4, 0.465], [64680.8, 0.002], [64683.3, 0.244], [64684.1, 0.464], [64684.4, 0.041], [64684.5, 0.003], [64685.3, 0.009], [64685.8, 0.038], [64686.2, 0.006], [64686.6, 0.004], [64686.8, 0.464], [64688.0, 1.949], [64688.2, 0.304], [64688.5, 0.36], [64689.7, 0.007], [64690.4, 0.134], [64690.6, 0.584], [64691.7, 0.009], [64692.0, 1.026], [64692.8, 0.322], [64693.0, 0.006], [64693.2, 0.009], [64694.3, 0.026], [64695.7, 0.2], [64696.2, 0.073], [64696.9, 0.704], [64697.1, 0.58], [64697.2, 0.01], [64697.3, 0.087], [64697.6, 1.356], [64697.7, 0.178], [64697.8, 0.587], [64697.9, 0.002], [64698.2, 0.109], [64698.3, 0.001], [64698.5, 0.021], [64698.6, 0.004], [64698.7, 0.087], [64698.8, 0.004], [64699.2, 0.002], [64699.8, 1.93], [64699.9, 0.13], [64700.0, 0.245], [64700.4, 0.001], [64700.5, 1.123], [64700.8, 0.007], [64700.9, 0.018], [64701.1, 0.004], [64701.6, 0.002], [64702.0, 0.045], [64702.8, 0.14], [64702.9, 0.0], [64703.0, 0.009], [64703.1, 0.784]], "asks": [[64703.2, 37.142], [64703.3, 0.006], [64703.4, 0.084], [64703.5, 0.0], [64704.1, 1.002], [64704.3, 6.684], [64704.5, 0.1], [64704.8, 1.004], [64704.9, 0.088], [64705.1, 0.003], [64705.2, 0.446], [64705.3, 0.554], [64705.5, 0.0], [64705.6, 0.36], [64705.9, 0.002], [64706.1, 0.0], [64706.6, 0.001], [64707.0, 0.008], [64708.0, 0.001], [64708.7, 0.004], [64709.0, 0.0], [64709.1, 0.086], [64709.2, 0.006], [64709.5, 0.255], [64710.1, 0.036], [64710.3, 0.024], [64710.4, 0.05], [64711.3, 0.048], [64711.8, 0.145], [64713.3, 0.004], [64713.5, 0.0], [64713.6, 0.028], [64713.7, 1.368], [64714.3, 0.151], [64714.4, 0.178], [64714.5, 2.319], [64714.6, 0.082], [64715.8, 0.011], [64715.9, 0.712], [64716.0, 1.026], [64716.1, 0.203], [64716.3, 0.68], [64716.6, 0.011], [64718.1, 0.211], [64719.6, 0.754], [64719.8, 0.002], [64720.5, 3.941], [64720.7, 0.001], [64720.8, 1.656], [64720.9, 0.012], [64721.1, 10.496], [64721.8, 0.005], [64722.8, 2.978], [64722.9, 0.004], [64723.0, 0.454], [64723.1, 0.002], [64724.2, 0.003], [64725.1, 0.0], [64728.2, 0.066], [64728.9, 0.22], [64730.1, 2.161], [64731.0, 0.014], [64731.7, 0.305], [64732.8, 0.095], [64733.5, 0.191], [64733.6, 3.404], [64735.2, 1.02], [64736.1, 1.843], [64736.2, 0.034], [64737.3, 0.818], [64738.1, 0.057], [64743.4, 0.027], [64744.4, 0.417], [64746.0, 1.452], [64747.1, 0.021], [64747.4, 0.178], [64748.0, 0.117], [64748.1, 1.001], [64748.2, 0.673], [64748.3, 1.479], [64756.9, 0.065], [64758.5, 0.0], [64761.3, 0.006], [64763.0, 0.026], [64767.9, 47.323], [64769.6, 3.468], [64787.4, 1.431], [64787.8, 0.004], [64793.8, 0.269], [64800.8, 0.009], [64803.1, 0.003], [64804.9, 2.414], [64843.8, 0.001], [64845.4, 0.0], [64845.5, 3.589], [64860.8, 0.0], [64862.4, 0.0], [64862.5, 3.181], [64862.6, 0.92], [64899.6, 0.002], [64901.2, 0.051], [64901.3, 1.308], [64901.4, 0.001], [64906.7, 0.027], [65350.2, 0.008], [65450.0, 28.023], [65452.2, 0.908], [65452.3, 7.019], [65703.2, 0.02], [65997.2, 0.02]]}
{"kind": "depth", "E": 1787095531503, "U": 11316385833600, "u": 11316385850222, "recv_ms": 1787095531567, "bids": [[1000.0, 35.91], [14203.1, 0.532], [14303.1, 0.266], [14305.2, 2.702], [14405.2, 0.07], [51762.5, 0.0], [58232.7, 0.002], [61467.9, 0.0], [61472.1, 0.006], [62114.9, 0.008], [63898.6, 6.501], [64055.5, 0.389], [64056.1, 0.042], [64057.5, 0.0], [64183.5, 0.021], [64400.6, 0.081], [64529.1, 0.02], [64581.2, 0.473], [64581.7, 0.001], [64582.5, 0.0], [64583.7, 0.092], [64584.0, 2.915], [64642.0, 0.029], [64643.9, 0.385], [64654.2, 0.023], [64658.7, 0.003], [64662.1, 0.001], [64663.2, 0.0], [64666.7, 0.202], [64667.0, 0.118], [64667.5, 0.496], [64671.4, 0.027], [64672.7, 0.01], [64673.1, 0.156], [64674.2, 0.14], [64674.4, 0.226], [64674.6, 0.079], [64675.0, 0.101], [64676.3, 0.0], [64676.6, 3.014], [64678.3, 1.707], [64678.5, 0.123], [64678.7, 0.065], [64679.4, 0.45], [64679.5, 0.294], [64680.5, 1.3], [64682.3, 1.345], [64683.7, 0.001], [64686.0, 0.449], [64686.1, 0.557], [64686.2, 0.161], [64687.3, 0.007], [64688.0, 1.393], [64689.1, 0.157], [64689.4, 0.002], [64690.0, 0.903], [64690.2, 0.129], [64690.7, 0.001], [64691.0, 0.902], [64692.0, 0.911], [64692.4, 0.773], [64692.8, 0.322], [64693.6, 0.023], [64694.1, 2.319], [64694.2, 1.768], [64694.3, 0.165], [64694.6, 0.165], [64694.7, 0.005], [64694.9, 0.003], [64695.3, 0.223], [64695.4, 0.092], [64695.5, 0.142], [64695.6, 0.633], [64695.9, 1.173], [64696.0, 0.714], [64696.1, 0.202], [64696.3, 0.004], [64696.4, 0.105], [64696.5, 0.202], [64696.6, 0.032], [64696.9, 0.245], [64697.0, 3.866], [64697.1, 0.192], [64697.3, 0.319], [64697.4, 0.004], [64697.5, 0.037], [64697.9, 1.555], [64698.0, 0.295], [64698.2, 0.101], [64698.3, 0.002], [64698.6, 0.002], [64699.8, 0.385], [64700.6, 0.001], [64700.8, 0.007], [64701.1, 0.138], [64701.2, 0.012], [64702.5, 0.0], [64702.6, 0.0], [64702.7, 0.002], [64702.8, 0.002], [64703.0, 1.399], [64703.1, 0.089]], "asks": [[64703.2, 39.11], [64703.3, 1.006], [64703.4, 1.085], [64703.6, 3.5], [64704.0, 0.002], [64704.1, 0.74], [64704.3, 0.274], [64704.4, 0.0], [64704.7, 2.581], [64704.8, 0.007], [64704.9, 0.087], [64705.3, 0.55], [64705.9, 0.002], [64706.8, 0.281], [64709.7, 0.005], [64710.8, 0.046], [64711.7, 0.218], [64712.5, 0.003], [64712.7, 0.005], [64713.4, 0.406], [64713.5, 0.0], [64713.7, 1.376], [64713.9, 0.229], [64714.1, 0.546], [64714.6, 0.002], [64714.9, 0.002], [64715.8, 0.011], [64716.1, 0.44], [64716.5, 0.006], [64716.6, 0.01], [64716.8, 2.488], [64717.2, 4.002], [64717.3, 0.047], [64719.0, 0.041], [64719.5, 0.033], [64720.3, 0.422], [64721.1, 0.496], [64721.6, 0.779], [64722.0, 1.665], [64722.2, 0.545], [64722.6, 0.686], [64722.8, 2.958], [64723.1, 0.002], [64723.2, 1.249], [64724.1, 0.005], [64724.7, 0.553], [64726.5, 0.355], [64728.1, 0.002], [64729.0, 2.812], [64729.7, 0.002], [64730.1, 1.702], [64732.1, 0.001], [64733.1, 0.289], [64733.3, 2.516], [64733.6, 3.398], [64735.2, 1.007], [64738.1, 0.075], [64740.8, 1.338], [64745.3, 0.176], [64746.2, 0.022], [64747.1, 0.006], [64749.0, 6.611], [64760.1, 0.012], [64760.4, 0.387], [64763.6, 0.003], [64765.4, 0.377], [64765.8, 48.596], [64767.9, 0.05], [64770.0, 0.134], [64793.8, 0.103], [64817.2, 0.015], [64825.6, 0.481], [64841.6, 5.056], [64843.8, 5.399], [64844.9, 1.542], [64845.4, 0.0], [64845.5, 0.0], [64860.8, 10.407], [64861.0, 0.802], [64861.9, 0.0], [64862.4, 0.0], [64862.5, 0.002], [64899.6, 7.374], [64900.7, 0.387], [64901.3, 0.023], [65139.8, 0.0], [65350.2, 0.0], [65449.6, 0.909], [65452.3, 6.104], [65468.5, 15.238], [65997.2, 0.026], [66989.5, 0.0], [68455.3, 0.002]]}
{"kind": "depth", "E": 1787095531605, "U": 11316385850403, "u": 11316385863014, "recv_ms": 1787095531672, "bids": [[14203.1, 0.812], [14303.1, 0.336], [14305.2, 2.422], [14405.2, 0.0], [58232.7, 0.002], [61467.9, 0.0], [62114.9, 0.005], [63409.1, 0.01], [63703.1, 0.785], [64056.1, 0.046], [64604.7, 0.015], [64639.8, 6.36], [64640.0, 0.115], [64664.4, 0.004], [64672.0, 0.103], [64677.8, 2.579], [64679.5, 0.139], [64681.3, 0.037], [64682.1, 0.004], [64686.2, 0.006], [64689.1, 0.002], [64690.4, 0.136], [64691.4, 0.003], [64692.0, 0.91], [64694.3, 0.103], [64694.7, 0.003], [64695.4, 0.077], [64696.0, 0.173], [64696.1, 0.109], [64696.3, 0.003], [64696.5, 0.2], [64696.9, 0.247], [64697.1, 0.578], [64697.2, 0.01], [64697.3, 0.087], [64697.7, 0.178], [64697.8, 0.587], [64698.0, 0.14], [64700.5, 1.123], [64700.8, 0.009], [64701.1, 0.015], [64701.2, 0.004], [64701.7, 0.002], [64702.1, 0.001], [64702.2, 0.144], [64703.0, 0.009], [64703.1, 0.104]], "asks": [[64703.2, 39.192], [64703.5, 1.863], [64703.6, 3.501], [64704.1, 0.157], [64704.7, 2.501], [64705.3, 0.549], [64705.4, 0.053], [64706.0, 0.001], [64707.5, 0.331], [64709.5, 0.163], [64710.5, 0.156], [64710.8, 0.201], [64710.9, 0.873], [64711.3, 0.011], [64712.1, 0.262], [64712.7, 0.004], [64712.9, 0.08], [64715.0, 0.916], [64715.8, 0.166], [64715.9, 0.714], [64716.6, 0.165], [64718.4, 0.055], [64718.8, 0.523], [64719.5, 0.188], [64720.2, 0.004], [64721.9, 3.433], [64723.1, 0.157], [64725.3, 0.0], [64726.5, 0.335], [64728.5, 0.035], [64732.8, 0.093], [64765.7, 8.095], [64843.8, 0.001], [64844.7, 4.351], [64857.7, 3.146], [64860.8, 0.0], [64861.7, 3.255], [64899.6, 0.002], [64900.5, 1.335], [65350.2, 0.004], [65703.2, 0.0], [65997.2, 0.032], [67006.3, 0.142]]}
{"kind": "depth", "E": 1787095531707, "U": 11316385863034, "u": 11316385875170, "recv_ms": 1787095531770, "bids": [[1000.0, 35.91], [14203.1, 1.176], [14305.2, 2.058], [58232.7, 0.002], [61467.9, 0.0], [62114.9, 0.008], [63409.1, 0.013], [63762.8, 11.239], [63816.6, 12.119], [63862.1, 3.309], [63894.4, 0.351], [64056.1, 0.044], [64185.6, 0.935], [64381.2, 0.0], [64381.7, 0.077], [64403.3, 0.001], [64560.3, 0.005], [64582.8, 0.013], [64584.9, 0.001], [64589.9, 0.017], [64592.0, 0.025], [64596.9, 0.013], [64599.0, 0.0], [64604.0, 0.017], [64606.1, 0.0], [64611.0, 0.014], [64613.1, 0.001], [64618.1, 0.013], [64620.2, 0.628], [64625.1, 0.015], [64627.2, 0.246], [64632.2, 0.04], [64634.3, 0.001], [64641.6, 2.141], [64647.2, 0.631], [64648.8, 0.0], [64649.0, 0.392], [64654.7, 0.001], [64660.4, 2.475], [64668.0, 1.003], [64670.7, 0.11], [64671.2, 0.001], [64672.3, 0.016], [64672.7, 0.0], [64675.1, 0.004], [64681.1, 0.001], [64681.3, 0.037], [64685.8, 0.038], [64686.1, 0.001], [64686.2, 0.006], [64688.3, 0.558], [64688.5, 0.244], [64688.9, 0.003], [64689.0, 0.93], [64689.1, 0.002], [64690.1, 0.852], [64690.3, 0.035], [64692.0, 0.009], [64694.3, 0.103], [64695.8, 0.452], [64697.0, 2.966], [64697.2, 0.01], [64697.5, 0.036], [64697.6, 1.353], [64697.9, 0.002], [64698.0, 0.14], [64698.2, 0.104], [64699.8, 1.938], [64699.9, 0.13], [64702.2, 0.003], [64702.3, 0.482], [64702.4, 0.215], [64703.0, 1.399], [64703.1, 0.104]], "asks": [[64703.2, 39.205], [64703.7, 1.088], [64704.1, 0.0], [64704.5, 0.255], [64704.8, 0.005], [64706.3, 0.093], [64707.1, 0.429], [64710.8, 0.201], [64710.9, 0.872], [64711.0, 0.505], [64714.3, 0.228], [64715.5, 0.211], [64715.8, 0.166], [64716.1, 0.444], [64716.6, 0.628], [64718.0, 0.005], [64719.0, 0.037], [64719.5, 0.033], [64719.6, 0.446], [64723.1, 0.157], [64728.7, 0.559], [64729.0, 2.353], [64729.7, 0.009], [64729.9, 0.565], [64730.0, 2.681], [64730.9, 0.005], [64744.3, 0.031], [64748.6, 0.093], [64759.7, 0.012], [64760.1, 0.002], [64843.8, 5.399], [64844.7, 0.771], [64857.7, 1.838], [64860.8, 10.407], [64861.7, 0.012], [64899.6, 7.028], [64900.5, 0.003], [65168.1, 0.061], [65350.2, 0.006], [65449.5, 1.681], [65452.2, 0.0], [65997.2, 0.035]]}
{"kind": "depth", "E": 1787095531809, "U": 11316385875201, "u": 11316385885497, "recv_ms": 1787095531870, "bids": [[1000.0, 35.91], [14203.1, 1.526], [14305.2, 1.708], [51763.0, 0.0], [58232.7, 0.002], [63412.9, 0.006], [63703.1, 0.805], [63738.3, 2.332], [63894.4, 1.132], [64056.1, 0.044], [64563.5, 0.0], [64565.0, 1.11], [64680.6, 0.006], [64685.8, 0.038], [64689.1, 0.002], [64689.5, 0.116], [64690.1, 0.736], [64691.4, 0.001], [64692.1, 2.972], [64692.3, 0.007], [64693.4, 1.387], [64694.3, 0.103], [64695.8, 0.453], [64696.3, 0.003], [64696.9, 0.246], [64697.2, 0.01], [64697.7, 0.004], [64699.9, 0.13], [64700.1, 0.004], [64700.5, 1.123], [64702.3, 0.003], [64702.4, 0.143], [64703.0, 1.399], [64703.1, 0.106]], "asks": [[64703.2, 39.961], [64704.3, 0.257], [64704.5, 0.255], [64704.8, 0.004], [64706.3, 0.093], [64707.8, 0.142], [64710.8, 0.201], [64715.8, 0.166], [64717.1, 2.551], [64719.6, 0.446], [64723.1, 0.157], [64725.0, 0.282], [64843.8, 0.001], [65350.2, 0.004], [65703.2, 0.02], [65997.2, 0.038], [71173.6, 0.0]]}
{"kind": "depth", "E": 1787095531911, "U": 11316385885513, "u": 11316385896024, "recv_ms": 1787095531980, "bids": [[14203.1, 1.89], [14305.2, 1.344], [58232.7, 0.002], [61467.9, 0.0], [62114.9, 0.005], [63409.1, 0.016], [63829.7, 0.64], [64056.1, 0.044], [64353.0, 0.749], [64360.2, 5.961], [64381.6, 0.008], [64509.6, 0.003], [64549.6, 0.0], [64560.3, 0.005], [64654.2, 0.022], [64658.1, 0.004], [64660.7, 0.109], [64671.0, 0.089], [64672.1, 0.013], [64672.3, 0.006], [64691.4, 0.309], [64691.9, 0.467], [64692.0, 0.909], [64695.8, 0.452], [64696.8, 0.147], [64696.9, 0.246], [64700.8, 0.01], [64703.0, 1.399], [64703.1, 0.108]], "asks": [[64703.2, 39.236], [64705.3, 0.546], [64706.3, 0.093], [64706.4, 0.0], [64712.1, 0.261], [64759.4, 0.02], [64759.7, 0.002], [64820.4, 0.1], [64860.8, 0.0], [64899.6, 0.002], [65350.2, 0.004], [65514.2, 4.558], [65515.5, 0.756], [65515.6, 0.0], [65516.9, 0.129], [65597.9, 24.534], [65614.0, 0.911]]}
{"kind": "depth", "E": 1787095532013, "U": 11316385896127, "u": 11316385906275, "recv_ms": 1787095532081, "bids": [[1000.0, 35.91], [14203.1, 2.254], [14305.2, 0.98], [58232.7, 0.002], [61467.9, 0.0], [62114.9, 0.008], [63409.1, 0.019], [63703.1, 0.785], [63765.0, 1.276], [63931.1, 5.389], [64056.1, 0.042], [64379.6, 0.012], [64381.6, 0.007], [64678.4, 1.534], [64692.4, 0.774], [64695.8, 0.452], [64696.8, 0.147], [64697.1, 0.037], [64697.9, 0.543], [64700.5, 1.123], [64700.8, 0.009], [64703.0, 1.399], [64703.1, 0.108]], "asks": [[64703.2, 39.957], [64706.5, 0.001], [64707.4, 0.395], [64709.5, 0.009], [64712.9, 0.0], [64713.1, 0.013], [64713.7, 1.456], [64973.6, 0.277], [64974.4, 0.002], [65026.8, 0.001], [65350.2, 0.0], [65449.5, 2.589], [65450.8, 0.004], [65514.2, 5.314], [65515.5, 0.0], [65643.0, 0.494], [65703.2, 0.0], [65997.2, 0.044], [68616.8, 0.002]]}
{"kind": "depth", "E": 1787095532115, "U": 11316385906320, "u": 11316385916840, "recv_ms": 1787095532178, "bids": [[1000.0, 35.91], [14203.1, 2.604], [14305.2, 0.63], [58232.7, 0.002], [61467.9, 0.0], [62114.9, 0.005], [63409.1, 0.022], [63784.3, 0.236], [63924.7, 13.939], [64056.1, 0.044], [64507.0, 12.42], [64507.3, 2.428], [64545.8, 6.959], [64546.6, 2.002], [64562.8, 5.252], [64664.2, 1.347], [64671.8, 0.017], [64672.1, 0.003], [64686.7, 0.009], [64688.8, 0.16], [64691.5, 0.0], [64692.1, 2.892], [64695.6, 0.174], [64695.9, 1.173], [64696.8, 0.146], [64696.9, 0.247], [64697.0, 3.425], [64697.1, 0.578], [64697.6, 1.353], [64697.9, 0.002], [64698.3, 0.234], [64701.1, 0.017], [64702.0, 0.003], [64702.1, 0.041], [64702.4, 0.002], [64702.5, 0.479], [64702.6, 0.214], [64703.0, 1.399], [64703.1, 0.39]], "asks": [[64703.2, 37.022], [64704.3, 0.258], [64706.5, 0.001], [64710.3, 0.001], [64719.2, 0.38], [64721.3, 0.118], [64759.2, 0.226], [64759.4, 0.01], [64843.8, 5.399], [64860.8, 10.407], [64899.6, 7.018], [65026.8, 0.002], [65350.2, 0.004], [65449.5, 3.497], [65450.3, 5.448], [66001.2, 0.012]]}
{"kind": "depth", "E": 1787095532217, "U": 11316385916872, "u": 11316385927158, "recv_ms": 1787095532279, "bids": [[14203.1, 2.954], [14305.2, 0.28], [51763.0, 0.0], [58232.7, 0.004], [61467.9, 0.0], [62114.9, 0.008], [63409.1, 0.025], [63703.1, 0.805], [63933.2, 0.937], [64056.1, 0.042], [64560.3, 0.004], [64671.6, 0.036], [64671.8, 0.007], [64680.3, 0.005], [64687.3, 0.0], [64687.7, 0.004], [64688.7, 2.326], [64689.5, 0.0], [64690.7, 0.117], [64695.7, 0.2], [64695.9, 0.173], [64696.8, 1.147], [64696.9, 0.246], [64697.2, 0.011], [64700.7, 0.254], [64700.8, 0.01], [64702.5, 0.464], [64703.0, 0.009], [64703.1, 1.008]], "asks": [[64703.2, 36.301], [64704.3, 0.257], [64706.6, 0.001], [64708.7, 0.011], [64710.5, 0.158], [64710.9, 0.874], [64713.2, 0.024], [64716.6, 0.01], [64717.2, 0.002], [64718.8, 0.503], [64719.6, 1.064], [64720.4, 4.624], [64721.1, 10.496], [64726.2, 1.493], [64726.5, 0.355], [64728.2, 0.009], [64728.7, 0.003], [64729.3, 0.057], [64729.4, 0.561], [64729.9, 0.106], [64730.5, 0.459], [64733.6, 3.398], [64759.0, 0.013], [64759.2, 0.216], [64770.8, 0.017], [65350.2, 0.0], [65703.2, 0.02]]}
{"kind": "depth", "E": 1787095532319, "U": 11316385927159, "u": 11316385935865, "recv_ms": 1787095532380, "bids": [[1000.0, 35.91], [14203.1, 3.318], [14304.7, 0.434], [14304.8, 0.0], [14305.2, 0.0], [51763.0, 0.0], [51764.0, 0.0], [58232.7, 0.002], [61467.9, 0.0], [63814.6, 5.947], [63926.8, 1.251], [64056.1, 0.042], [64379.6, 0.012], [64560.3, 0.005], [64604.7, 0.0], [64685.9, 0.435], [64689.9, 0.118], [64690.7, 0.001], [64695.6, 0.189], [64695.8, 1.452], [64696.8, 0.146], [64700.1, 1.092], [64703.0, 1.399], [64703.1, 0.27]], "asks": [[64703.2, 36.664], [64705.3, 0.232], [64706.5, 0.001], [64706.6, 0.001], [64707.9, 0.002], [64710.9, 0.874], [64843.8, 5.399], [64844.7, 0.771], [64860.8, 10.407], [64861.7, 0.012], [64899.6, 6.218], [64900.5, 0.003], [65288.0, 20.286], [65350.2, 0.0], [65449.5, 5.32], [65450.3, 4.54], [65514.2, 7.582], [65515.0, 0.757], [65548.3, 2.285], [65997.2, 0.047]]}
{"kind": "depth", "E": 1787095532421, "U": 11316385936219, "u": 11316385946913, "recv_ms": 1787095532490, "bids": [[1000.0, 35.91], [14203.1, 3.64], [14204.7, 0.056], [14304.7, 0.112], [14603.1, 0.028], [58232.7, 0.002], [61467.9, 0.0], [62114.9, 0.005], [63703.1, 0.785], [63797.6, 0.009], [64056.1, 0.042], [64560.3, 0.005], [64604.7, 0.015], [64671.5, 0.01], [64671.6, 0.026], [64691.7, 0.011], [64695.6, 0.174], [64697.1, 0.037], [64697.2, 0.011], [64697.9, 0.543], [64700.1, 0.004], [64700.7, 0.254], [64702.1, 0.001], [64703.0, 0.009], [64703.1, 0.118]], "asks": [[64703.2, 36.995], [64705.2, 0.445], [64705.5, 0.001], [64706.6, 0.001], [64710.9, 0.874], [64717.4, 0.178], [64751.4, 4.473], [64751.5, 0.157], [64752.8, 0.005], [64758.8, 0.558], [64759.0, 0.003], [65350.2, 0.002], [65449.5, 6.228], [65450.3, 3.632], [65624.1, 0.227], [65703.2, 0.0], [66001.2, 0.009]]}
{"kind": "depth", "E": 1787095532523, "U": 11316385947084, "u": 11316385957174, "recv_ms": 1787095532587, "bids": [[14203.1, 3.724], [14204.7, 0.0], [14303.1, 0.28], [14303.6, 0.0], [14304.2, 0.0], [14304.7, 0.0], [14603.1, 0.196], [51762.5, 0.0], [58232.7, 0.002], [61467.9, 0.0], [62114.9, 0.008], [63825.9, 1.566], [64056.1, 0.042], [64232.3, 0.323], [64560.3, 0.004], [64671.3, 0.011], [64671.5, 0.0], [64691.1, 0.602], [64692.7, 0.285], [64694.1, 2.549], [64694.3, 0.312], [64695.8, 0.452], [64696.0, 0.402], [64696.3, 0.066], [64696.8, 0.146], [64696.9, 1.246], [64697.1, 0.037], [64697.3, 0.088], [64697.9, 0.002], [64698.0, 0.681], [64698.4, 0.089], [64700.6, 0.003], [64700.7, 0.12], [64700.8, 0.008], [64702.7, 0.009], [64703.0, 0.002], [64703.1, 0.432]], "asks": [[64703.2, 35.424], [64706.7, 0.0], [64707.9, 0.063], [64710.9, 0.874], [64758.7, 0.04], [64758.8, 0.548], [64765.8, 48.598], [64766.0, 1.198], [65350.2, 0.004], [65449.5, 8.952], [65450.3, 0.908], [65471.0, 4.663], [65474.8, 0.915]]}
{"kind": "depth", "E": 1787095532625, "U": 11316385957212, "u": 11316385968801, "recv_ms": 1787095532688, "bids": [[1000.0, 35.91], [14203.1, 3.584], [14303.1, 0.168], [14603.1, 0.448], [58232.7, 0.002], [61467.9, 0.0], [62114.9, 0.005], [63409.1, 0.028], [63703.1, 0.805], [63867.6, 4.812], [64056.1, 0.044], [64379.6, 0.002], [64560.3, 0.005], [64563.2, 1.909], [64625.7, 0.001], [64627.1, 1.285], [64657.9, 1.666], [64671.2, 0.011], [64671.3, 0.001], [64695.7, 1.2], [64696.2, 0.157], [64696.5, 0.201], [64696.9, 0.245], [64697.1, 0.579], [64697.2, 0.01], [64697.3, 0.088], [64698.0, 0.14], [64699.6, 0.001], [64700.7, 0.12], [64703.0, 0.002], [64703.1, 0.132]], "asks": [[64703.2, 38.567], [64706.8, 0.281], [64710.9, 0.873], [64718.8, 0.523], [64726.5, 0.335], [64758.6, 0.054], [64758.7, 0.03], [64841.6, 5.745], [65350.2, 0.0], [65703.2, 0.02], [65997.2, 0.05], [68778.2, 0.002]]}
{"kind": "depth", "E": 1787095532727, "U": 11316385968811, "u": 11316385979130, "recv_ms": 1787095532792, "bids": [[1000.0, 35.91], [14203.1, 3.472], [14303.1, 0.056], [14603.1, 0.672], [58232.7, 0.002], [61467.9, 0.0], [61471.6, 0.0], [61471.7, 0.004], [62114.9, 0.008], [63409.1, 0.031], [63769.1, 38.876], [63894.3, 0.117], [63930.9, 26.325], [64056.1, 0.042], [64562.8, 0.001], [64563.2, 1.045], [64697.1, 0.578], [64703.0, 1.392], [64703.1, 0.112]], "asks": [[64703.2, 36.21], [64705.6, 0.359], [64706.7, 0.0], [64706.8, 0.281], [64707.9, 0.002], [64710.9, 0.874], [64716.3, 0.66], [64716.9, 0.004], [64718.8, 0.503], [64720.4, 4.626], [64726.5, 0.355], [64751.5, 0.003], [64841.6, 5.056], [64843.8, 0.001], [65350.2, 0.002], [65514.2, 8.338], [65515.0, 0.001], [65801.0, 4.561]]}
{"kind": "depth", "E": 1787095532829, "U": 11316385979226, "u": 11316385989564, "recv_ms": 1787095532892, "bids": [[14203.1, 3.206], [14303.1, 0.0], [14603.1, 0.994], [58232.7, 0.002], [61467.9, 0.0], [63291.7, 0.002], [63292.9, 0.041], [63703.1, 0.785], [63765.0, 2.372], [64056.1, 0.046], [64342.1, 0.055], [64342.2, 1.657], [64438.7, 0.126], [64440.3, 0.846], [64509.7, 0.0], [64511.3, 0.0], [64545.8, 7.175], [64546.6, 1.095], [64562.8, 5.238], [64595.9, 2.334], [64598.3, 0.0], [64621.9, 0.152], [64622.9, 0.244], [64658.7, 0.003], [64666.7, 0.048], [64680.6, 0.161], [64685.8, 0.193], [64688.1, 0.007], [64688.7, 2.319], [64689.1, 0.157], [64693.6, 0.055], [64694.3, 0.467], [64694.6, 0.197], [64696.2, 0.087], [64696.5, 0.169], [64696.8, 0.114], [64697.1, 0.546], [64697.2, 0.165], [64697.5, 0.004], [64697.8, 0.555], [64699.9, 0.285], [64700.7, 0.12], [64703.0, 1.392], [64703.1, 0.113]], "asks": [[64703.2, 38.403], [64704.5, 0.1], [64706.6, 0.001], [64710.8, 0.046], [64710.9, 0.872], [64715.8, 0.011], [64718.8, 0.523], [64719.5, 0.033], [64719.6, 0.754], [64720.3, 0.422], [64723.1, 0.002], [64726.5, 0.335], [64763.6, 0.003], [64810.3, 2.318], [64812.2, 0.005], [64843.8, 5.399], [64860.8, 10.407], [64899.6, 6.255], [64907.1, 0.122], [64907.2, 0.004], [64976.9, 2.988], [64978.6, 0.001], [65075.9, 1.021], [65076.1, 0.002], [65350.2, 0.002], [65449.5, 9.86], [65450.3, 0.0], [65703.2, 0.0], [65997.2, 0.053]]}
{"kind": "depth", "E": 1787095532931, "U": 11316385989583, "u": 11316386001038, "recv_ms": 1787095532993, "bids": [[1000.0, 35.91], [14203.1, 2.856], [14603.1, 1.344], [58232.7, 0.002], [61467.9, 0.0], [62114.9, 0.005], [63409.1, 0.034], [63926.8, 2.813], [64056.1, 0.042], [64353.0, 0.257], [64356.6, 0.493], [64379.5, 0.001], [64379.6, 0.002], [64560.3, 0.005], [64562.8, 5.238], [64622.6, 0.409], [64638.4, 1.249], [64653.7, 0.49], [64671.1, 0.012], [64671.2, 0.001], [64680.6, 0.006], [64685.8, 0.038], [64689.1, 0.002], [64691.0, 0.904], [64693.1, 0.072], [64694.3, 0.344], [64696.2, 0.087], [64696.5, 0.168], [64696.9, 0.246], [64697.2, 0.011], [64699.9, 0.13], [64703.0, 1.392], [64703.1, 0.267]], "asks": [[64703.2, 38.408], [64704.5, 0.255], [64706.7, 0.0], [64709.7, 0.002], [64710.8, 0.201], [64710.9, 0.874], [64715.8, 0.166], [64719.5, 0.188], [64720.3, 0.577], [64723.1, 0.157], [64758.5, 0.01], [64758.6, 0.044], [64767.9, 0.051], [64809.0, 0.003], [64843.8, 0.001], [64844.6, 4.033], [64860.8, 0.0], [64861.0, 1.213], [64861.6, 3.318], [64899.6, 0.002], [64900.5, 1.31], [65026.8, 0.001], [65193.2, 0.138], [65338.1, 0.004], [65350.2, 0.002], [65804.7, 4.703], [65997.2, 0.056]]}
{"kind": "depth", "E": 1787095533033, "U": 11316386001045, "u": 11316386010182, "recv_ms": 1787095533099, "bids": [[1000.0, 35.91], [14203.1, 2.506], [14603.1, 1.694], [58232.7, 0.002], [61467.9, 0.0], [62114.9, 0.008], [63703.1, 0.805], [63814.6, 5.634], [63865.1, 1.565], [64056.1, 0.042], [64073.5, 0.0], [64100.1, 4.342], [64226.3, 0.005], [64300.1, 13.335], [64337.1, 37.247], [64342.2, 0.793], [64433.7, 30.261], [64504.7, 24.076], [64507.0, 12.444], [64507.3, 0.663], [64545.8, 6.961], [64560.3, 0.005], [64562.8, 5.04], [64622.9, 0.212], [64636.5, 0.001], [64640.0, 2.904], [64641.6, 2.148], [64691.5, 0.005], [64696.4, 0.106], [64696.9, 0.245], [64697.2, 0.01], [64700.7, 0.12], [64702.6, 0.0], [64703.0, 1.392], [64703.1, 0.123]], "asks": [[64703.2, 36.947], [64705.7, 0.291], [64706.7, 0.0], [64710.9, 0.872], [64726.5, 0.264], [64758.4, 0.056], [64758.5, 0.0], [64765.6, 3.439], [64773.0, 0.187], [64822.7, 0.0], [64843.8, 5.399], [64844.6, 0.396], [64860.8, 10.407], [64861.0, 0.802], [64861.6, 0.0], [64899.5, 24.943], [64899.6, 7.199], [64900.5, 0.003], [64970.9, 33.39], [65026.8, 0.0], [65068.4, 39.399], [65350.2, 0.0], [65703.2, 0.02]]}
{"kind": "depth", "E": 1787095533135, "U": 11316386010254, "u": 11316386020451, "recv_ms": 1787095533197, "bids": [[14203.1, 2.142], [14603.1, 2.058], [51763.0, 0.0], [58232.7, 0.002], [61467.9, 0.0], [62114.9, 0.005], [63409.1, 0.037], [63576.6, 0.785], [63848.6, 0.782], [64056.1, 0.042], [64124.0, 0.148], [64127.8, 0.001], [64284.3, 0.008], [64288.2, 0.0], [64379.5, 0.002], [64435.1, 6.947], [64445.0, 0.816], [64448.9, 0.0], [64621.6, 0.032], [64621.9, 0.12], [64622.3, 0.178], [64653.7, 0.42], [64671.0, 0.099], [64671.1, 0.002], [64686.7, 0.009], [64691.5, 0.0], [64693.3, 0.084], [64694.0, 1.079], [64696.1, 0.109], [64696.4, 0.105], [64696.9, 0.246], [64697.8, 0.787], [64698.3, 0.002], [64699.2, 0.086], [64703.0, 1.392], [64703.1, 0.122]], "asks": [[64703.2, 37.677], [64704.3, 0.258], [64706.8, 0.281], [64710.0, 0.123], [64719.2, 0.38], [64899.4, 10.226], [64899.9, 0.276], [65124.6, 0.008], [65128.5, 0.007], [65287.4, 0.05], [65291.3, 0.0], [65350.2, 0.0], [65514.2, 9.094], [65514.8, 1.187], [65997.2, 0.062], [66001.2, 0.006], [71173.6, 0.0]]}
{"kind": "depth", "E": 1787095533237, "U": 11316386020545, "u": 11316386030660, "recv_ms": 1787095533327, "bids": [[1000.0, 36.06], [14203.1, 1.792], [14603.1, 2.408], [58232.7, 0.002], [61467.9, 0.0], [62114.9, 0.008], [63703.1, 0.785], [63714.8, 0.011], [63773.5, 1.66], [63829.6, 0.372], [63924.6, 8.952], [64056.1, 0.044], [64379.6, 0.002], [64606.1, 0.002], [64610.0, 0.2], [64622.6, 0.377], [64638.4, 1.242], [64640.0, 2.897], [64641.6, 2.148], [64642.5, 0.05], [64666.0, 0.348], [64673.3, 0.005], [64680.6, 0.006], [64685.8, 0.038], [64689.1, 0.002], [64694.3, 0.344], [64696.4, 0.106], [64696.9, 0.245], [64697.1, 0.546], [64697.2, 0.01], [64697.8, 0.555], [64698.5, 0.253], [64699.6, 0.085], [64699.9, 0.13], [64700.7, 0.12], [64702.6, 0.22], [64703.0, 1.392], [64703.1, 0.12]], "asks": [[64703.2, 36.972], [64704.5, 0.255], [64706.9, 0.015], [64707.1, 0.421], [64710.8, 0.201], [64712.7, 0.004], [64712.9, 0.019], [64715.8, 0.166], [64719.5, 0.188], [64720.1, 1.299], [64720.3, 0.577], [64723.1, 0.157], [64800.2, 0.108], [64804.1, 0.0], [64860.8, 0.0], [64861.6, 6.395], [64899.6, 0.002], [64900.4, 1.592], [64962.2, 0.011], [64966.1, 0.0], [65350.2, 0.0], [65449.5, 11.676], [65450.1, 0.856], [65477.5, 8.432], [65481.3, 0.213], [65514.2, 9.85], [65514.8, 0.431], [65610.6, 1.091], [65691.6, 0.011], [65703.2, 0.0]]}
{"kind": "depth", "E": 1787095533339, "U": 11316386030709, "u": 11316386039320, "recv_ms": 1787095533404, "bids": [[1000.0, 35.91], [14203.1, 1.428], [14603.1, 2.772], [58232.7, 0.002], [61467.9, 0.0], [63409.1, 0.04], [63717.6, 0.861], [64056.1, 0.042], [64100.1, 0.022], [64221.2, 47.78], [64272.2, 0.007], [64300.1, 16.791], [64337.2, 0.866], [64560.3, 0.004], [64621.6, 0.0], [64690.0, 0.902], [64695.7, 0.2], [64696.6, 0.033], [64696.7, 1.069], [64697.2, 0.01], [64697.3, 0.089], [64699.9, 0.137], [64700.5, 1.123], [64703.0, 1.392], [64703.1, 0.641]], "asks": [[64703.2, 35.497], [64704.3, 0.257], [64706.8, 0.281], [64710.9, 0.874], [64758.3, 0.011], [64758.4, 0.046], [64860.8, 10.407], [64861.6, 0.0], [64899.6, 6.463], [64900.4, 0.025], [65350.2, 0.0], [65997.2, 0.065], [71173.6, 0.0]]}
{"kind": "depth", "E": 1787095533441, "U": 11316386039492, "u": 11316386046655, "recv_ms": 1787095533503, "bids": [[14203.1, 1.078], [14603.1, 3.122], [58232.7, 0.002], [61467.9, 0.0], [62114.9, 0.005], [63703.1, 0.805], [63926.7, 0.781], [64056.1, 0.042], [64604.7, 0.0], [64622.3, 0.146], [64640.3, 0.022], [64640.7, 0.0], [64641.0, 0.014], [64641.3, 0.004], [64641.6, 2.109], [64656.2, 0.032], [64656.5, 0.034], [64657.2, 0.384], [64659.1, 0.038], [64659.4, 0.0], [64659.7, 0.001], [64660.0, 0.106], [64660.3, 0.102], [64666.7, 0.048], [64666.8, 0.154], [64670.9, 0.297], [64671.0, 0.089], [64674.0, 0.097], [64674.1, 0.011], [64674.2, 0.0], [64674.3, 0.318], [64674.4, 0.126], [64674.5, 0.013], [64674.6, 0.009], [64674.7, 0.0], [64674.8, 0.002], [64675.0, 0.031], [64677.0, 0.0], [64677.4, 0.002], [64690.4, 0.138], [64692.4, 0.874], [64692.9, 0.111], [64693.1, 0.002], [64693.3, 0.052], [64693.6, 0.055], [64694.0, 1.079], [64694.3, 0.312], [64694.6, 0.197], [64694.7, 0.112], [64695.3, 0.083], [64695.4, 0.007], [64695.5, 0.002], [64695.6, 0.019], [64695.7, 0.0], [64695.8, 0.352], [64695.9, 0.003], [64696.0, 0.232], [64696.1, 0.009], [64696.8, 0.005], [64697.3, 0.089], [64700.7, 0.12], [64703.0, 1.392], [64703.1, 0.662]], "asks": [[64707.0, 0.008], [64709.6, 0.26], [64709.8, 0.011], [64710.1, 0.004], [64710.3, 0.036], [64710.4, 0.015], [64710.6, 0.038], [64710.8, 0.163], [64711.1, 0.002], [64711.3, 0.121], [64711.4, 0.013], [64711.5, 0.341], [64711.6, 0.0], [64711.7, 0.028], [64711.8, 0.165], [64711.9, 0.001], [64712.0, 0.058], [64712.1, 0.107], [64712.2, 0.37], [64712.3, 0.453], [64718.8, 0.503], [64726.5, 0.284], [64728.3, 0.117], [64728.5, 0.003], [64728.8, 0.097], [64729.0, 2.388], [64729.2, 0.175], [64729.3, 0.095], [64729.5, 0.004], [64729.8, 0.379], [64730.0, 2.791], [64730.2, 0.015], [64730.6, 0.422], [64732.6, 0.022], [64732.8, 0.009], [64732.9, 0.055], [64733.0, 0.523], [64733.1, 0.039], [64733.2, 2.319], [64733.3, 2.446], [64733.4, 0.007], [64733.5, 0.03], [64733.6, 3.321], [64742.1, 0.082], [64747.0, 0.032], [64747.2, 1.323], [64747.6, 0.001], [64747.7, 0.215], [64747.9, 0.04], [64748.0, 0.155], [64748.2, 0.635], [64748.5, 0.001], [64751.3, 0.001], [65350.2, 0.0], [65449.5, 14.4], [65450.0, 25.299], [65481.2, 6.099], [65703.2, 0.02]]}
{"kind": "depth", "E": 1787095533543, "U": 11316386046738, "u": 11316386053882, "recv_ms": 1787095533602, "bids": [[1000.0, 35.91], [14203.1, 0.714], [14603.1, 3.486], [51762.5, 0.0], [58232.7, 0.002], [61467.9, 0.0], [62114.9, 0.008], [64056.1, 0.042], [64379.6, 0.002], [64562.8, 5.04], [64641.6, 2.116], [64656.8, 0.051], [64666.7, 0.202], [64666.8, 0.0], [64692.1, 2.962], [64692.3, 0.077], [64692.8, 0.422], [64694.3, 0.344], [64697.3, 0.089], [64699.9, 0.13], [64703.0, 1.392], [64703.1, 0.654]], "asks": [[64703.2, 35.497], [64707.0, 0.008], [64709.9, 0.033], [64710.9, 0.874], [64711.4, 0.123], [64711.9, 0.085], [64712.1, 0.198], [64728.6, 0.034], [64732.7, 0.126], [64733.2, 2.403], [64733.3, 2.537], [64747.4, 0.21], [64751.4, 4.473], [64821.7, 0.069], [64843.8, 5.399], [64899.6, 6.021], [65350.2, 0.0], [65446.3, 0.0], [65449.5, 15.308], [65449.6, 0.001]]}
{"kind": "depth", "E": 1787095533645, "U": 11316386054155, "u": 11316386061148, "recv_ms": 1787095533707, "bids": [[14203.1, 0.42], [14503.1, 0.056], [14603.1, 3.724], [51763.0, 0.0], [58232.7, 0.002], [61467.9, 0.001], [61472.1, 0.004], [62114.9, 0.005], [63703.1, 0.785], [64056.1, 0.044], [64504.7, 23.713], [64504.8, 3.904], [64546.6, 2.003], [64562.8, 4.71], [64641.6, 2.109], [64666.7, 0.202], [64692.7, 0.355], [64699.9, 0.137], [64700.7, 0.12], [64703.0, 1.392], [64703.1, 0.657]], "asks": [[64703.2, 35.497], [64706.9, 0.015], [64710.9, 0.874], [64711.5, 0.411], [64718.8, 0.523], [64726.5, 0.264], [64732.8, 0.079], [64751.3, 0.001], [64758.2, 0.05], [64758.3, 0.001], [64843.8, 5.399], [64857.7, 3.146], [64899.6, 7.383], [64970.8, 5.079], [65350.2, 0.0], [65350.3, 0.001], [65430.3, 1.602], [65610.6, 1.274], [65703.2, 0.0], [104929.0, 0.0]]}
{"kind": "depth", "E": 1787095533747, "U": 11316386061156, "u": 11316386068046, "recv_ms": 1787095533808, "bids": [[14203.1, 0.252], [14503.1, 0.252], [14603.1, 3.696], [58232.7, 0.002], [61467.9, 0.001], [64056.1, 0.042], [64562.8, 0.001], [64637.5, 0.947], [64637.8, 0.032], [64638.4, 1.274], [64641.6, 2.109], [64655.9, 0.036], [64662.4, 2.281], [64667.4, 8.001], [64692.1, 3.032], [64692.2, 0.081], [64692.3, 0.147], [64692.4, 0.944], [64692.6, 0.101], [64692.7, 0.455], [64693.1, 0.072], [64693.3, 0.084], [64696.2, 0.003], [64697.3, 0.089], [64699.9, 0.137], [64700.0, 0.329], [64703.0, 0.002], [64703.1, 1.027]], "asks": [[64704.5, 0.1], [64704.8, 0.001], [64707.1, 0.421], [64710.8, 0.008], [64710.9, 0.909], [64711.2, 0.263], [64711.5, 0.531], [64711.6, 0.13], [64711.8, 0.235], [64711.9, 0.155], [64712.0, 0.128], [64712.1, 0.275], [64715.8, 0.011], [64718.8, 0.503], [64719.5, 0.033], [64720.3, 0.422], [64723.1, 0.002], [64726.5, 0.284], [64729.6, 0.046], [64732.4, 0.849], [64732.7, 0.246], [64732.9, 0.185], [64733.1, 0.109], [64733.2, 2.473], [64733.3, 2.607], [64733.4, 0.084], [64745.4, 1.45], [64748.3, 1.514], [64751.4, 4.473], [64843.8, 0.001], [65350.2, 0.0]]}
{"kind": "depth", "E": 1787095533849, "U": 11316386068172, "u": 11316386073947, "recv_ms": 1787095533908, "bids": [[1000.0, 35.91], [14203.1, 0.14], [14503.1, 0.49], [14603.1, 3.57], [58232.7, 0.002], [61467.9, 0.0], [62114.9, 0.008], [64056.1, 0.042], [64071.0, 61.911], [64379.6, 0.002], [64562.8, 4.942], [64638.1, 1.72], [64641.6, 2.116], [64643.2, 0.007], [64664.2, 1.333], [64668.8, 2.585], [64671.2, 0.101], [64674.2, 0.1], [64692.5, 0.316], [64692.9, 0.181], [64699.9, 0.13], [64700.7, 0.12]], "asks": [[64703.2, 35.499], [64704.5, 0.255], [64707.0, 0.012], [64710.8, 0.163], [64710.9, 0.907], [64711.3, 0.205], [64711.7, 0.288], [64715.8, 0.166], [64719.5, 0.188], [64720.3, 0.577], [64723.1, 0.157], [64730.4, 0.14], [64732.6, 0.106], [64732.9, 0.305], [64751.3, 0.001], [64843.8, 5.399], [64899.6, 6.748], [65185.5, 45.926], [65335.4, 57.372], [65350.2, 0.0], [65482.5, 1.601], [65483.9, 19.306]]}
{"kind": "depth", "E": 1787095533951, "U": 11316386074186, "u": 11316386082244, "recv_ms": 1787095534011, "bids": [[14203.1, 0.014], [14503.1, 0.728], [14603.1, 3.458], [58232.7, 0.002], [61467.9, 0.0], [62114.9, 0.005], [63409.1, 0.043], [63703.1, 0.805], [63816.6, 11.494], [63829.6, 1.154], [64056.1, 0.042], [64356.6, 0.001], [64358.9, 0.493], [64379.5, 0.001], [64560.3, 0.005], [64604.7, 0.015], [64637.1, 4.21], [64663.3, 2.0], [64664.2, 1.347], [64667.4, 0.001], [64668.8, 1.486], [64670.9, 0.367], [64671.0, 0.159], [64671.5, 0.1], [64695.4, 0.167], [64695.6, 1.004], [64696.7, 0.069], [64696.9, 0.085], [64697.3, 0.089], [64697.9, 0.002], [64698.2, 0.111], [64699.6, 0.001], [64699.8, 1.938], [64699.9, 0.13], [64700.0, 0.245], [64703.0, 1.392], [64703.1, 0.579]], "asks": [[64703.2, 35.436], [64704.5, 0.1], [64707.0, 0.008], [64708.0, 0.062], [64710.8, 0.008], [64710.9, 0.908], [64715.8, 0.011], [64718.8, 0.503], [64719.5, 0.033], [64720.3, 0.422], [64723.1, 0.002], [64726.5, 0.284], [65288.0, 19.629], [65350.2, 0.0], [65461.8, 0.534], [65639.3, 9.889], [65703.2, 0.02], [104929.0, 0.236]]}
{"kind": "depth", "E": 1787095534053, "U": 11316386082481, "u": 11316386089558, "recv_ms": 1787095534114, "bids": [[14203.1, 0.0], [14503.1, 1.064], [14603.1, 3.136], [58232.7, 0.002], [61467.9, 0.0], [62114.9, 0.008], [64056.1, 0.042], [64086.2, 1.032], [64379.5, 0.0], [64560.3, 0.004], [64658.7, 0.003], [64666.7, 0.048], [64670.8, 0.051], [64670.9, 0.357], [64671.4, 0.097], [64691.5, 0.0], [64695.6, 0.004], [64696.7, 1.07], [64697.0, 3.425], [64697.3, 0.088], [64698.2, 0.104], [64699.9, 0.13], [64700.7, 0.12], [64703.0, 0.002], [64703.1, 0.583]], "asks": [[64703.2, 35.497], [64703.8, 0.002], [64706.9, 0.015], [64708.0, 0.001], [64710.9, 0.909], [64763.6, 0.003], [65026.8, 0.002], [65350.2, 0.0], [65481.2, 7.624]]}
{"kind": "depth", "E": 1787095534155, "U": 11316386089589, "u": 11316386095793, "recv_ms": 1787095534216, "bids": [[1000.0, 35.91], [14503.1, 1.428], [14603.1, 2.772], [58232.7, 0.002], [61467.9, 0.0], [62114.9, 0.005], [63412.9, 0.003], [63703.1, 0.785], [63829.6, 1.779], [64056.1, 0.042], [64379.6, 0.012], [64381.7, 0.0], [64384.9, 0.385], [64401.1, 0.155], [64407.6, 0.008], [64409.2, 0.419], [64515.9, 0.154], [64520.3, 0.22], [64520.8, 0.0], [64551.5, 0.103], [64587.0, 14.258], [64590.1, 0.002], [64591.0, 0.849], [64595.9, 2.334], [64604.7, 0.0], [64611.4, 0.642], [64631.7, 0.046], [64634.9, 0.0], [64638.4, 1.197], [64638.9, 0.101], [64640.0, 2.82], [64641.6, 2.116], [64643.2, 0.115], [64643.7, 0.021], [64670.8, 0.121], [64670.9, 0.427], [64671.0, 0.229], [64671.1, 0.072], [64671.3, 0.101], [64671.5, 0.2], [64671.8, 0.077], [64681.2, 2.712], [64686.7, 0.009], [64695.6, 0.019], [64696.8, 0.006], [64697.1, 0.005], [64697.9, 0.002], [64698.0, 0.681], [64699.6, 0.085], [64699.9, 0.13], [64700.5, 1.123], [64700.6, 1.72], [64701.5, 0.001], [64703.0, 0.002], [64703.1, 1.127]], "asks": [[64703.2, 34.681], [64705.8, 0.001], [64706.6, 0.0], [64707.1, 0.421], [64708.2, 0.062], [64709.7, 0.003], [64719.2, 0.38], [64774.1, 0.046], [64777.3, 0.001], [64810.3, 2.318], [64835.9, 0.779], [64838.4, 3.979], [64841.6, 1.192], [64857.7, 1.838], [64860.8, 10.407], [64861.6, 0.0], [64897.1, 0.229], [64897.2, 1.684], [64899.6, 6.373], [64900.4, 0.025], [65319.4, 0.656], [65350.2, 0.0], [65500.9, 13.384], [65703.2, 0.0], [66309.5, 0.0]]}
{"kind": "depth", "E": 1787095534257, "U": 11316386095967, "u": 11316386103062, "recv_ms": 1787095534318, "bids": [[14503.1, 1.778], [14603.1, 2.422], [51763.0, 0.004], [58232.7, 0.002], [61467.9, 0.0], [64056.1, 0.042], [64384.4, 0.0], [64507.4, 0.039], [64604.7, 0.015], [64641.6, 2.154], [64666.3, 0.001], [64668.9, 2.34], [64670.7, 0.068], [64671.3, 0.201], [64671.6, 0.096], [64673.8, 0.19], [64678.9, 0.313], [64686.3, 0.0], [64689.9, 0.002], [64691.2, 0.139], [64695.6, 0.004], [64696.8, 0.006], [64697.0, 2.966], [64698.2, 0.104], [64698.3, 0.461], [64699.8, 1.938], [64700.7, 0.12], [64703.0, 0.002], [64703.1, 0.752]], "asks": [[64703.2, 34.681], [64707.1, 0.421], [64709.7, 0.002], [64713.7, 1.448], [64715.8, 0.019], [64718.8, 0.523], [64724.8, 0.797], [64726.5, 0.264], [64732.2, 1.374], [64860.8, 10.407], [64861.5, 0.001], [64899.6, 6.744], [64900.4, 0.025], [65350.2, 0.0], [65447.9, 14.541], [65449.5, 0.773], [65512.6, 8.317], [65514.2, 1.534], [65642.9, 1.801], [65997.2, 0.068], [66001.2, 0.003]]}
{"kind": "depth", "E": 1787095534359, "U": 11316386103123, "u": 11316386112938, "recv_ms": 1787095534421, "bids": [[14503.1, 2.142], [14603.1, 2.058], [51763.0, 0.0], [58232.7, 0.002], [61471.7, 0.002], [62114.9, 0.008], [63401.1, 0.68], [63409.1, 0.046], [63703.1, 0.805], [64056.1, 0.042], [64082.0, 0.726], [64174.6, 2.085], [64368.6, 0.782], [64560.3, 0.005], [64643.2, 0.192], [64689.5, 0.116], [64690.1, 0.736], [64691.2, 0.023], [64696.4, 0.105], [64696.8, 0.005], [64697.1, 0.547], [64697.2, 0.469], [64697.6, 0.974], [64697.9, 0.005], [64698.0, 0.14], [64698.2, 0.101], [64698.3, 0.002], [64698.6, 0.002], [64698.7, 0.087], [64698.8, 0.012], [64698.9, 1.6], [64699.8, 0.385], [64699.9, 0.13], [64701.5, 0.008], [64703.0, 0.0], [64703.1, 0.434]], "asks": [[64703.2, 34.681], [64704.9, 0.09], [64707.0, 0.008], [64707.1, 0.425], [64722.6, 0.757], [64729.2, 0.175], [64729.8, 0.838], [64730.5, 0.0], [64860.8, 10.407], [64861.5, 0.001], [64899.6, 6.376], [64900.4, 0.025], [65209.7, 2.338], [65350.2, 0.0], [65703.2, 0.02], [66648.6, 0.0]]}
{"kind": "depth", "E": 1787095534461, "U": 11316386112975, "u": 11316386121773, "recv_ms": 1787095534539, "bids": [[1000.0, 35.91], [14503.1, 2.492], [14603.1, 1.708], [51762.5, 0.002], [58232.7, 0.002], [61467.9, 0.001], [61469.5, 0.013], [61469.6, 0.004], [62114.9, 0.005], [63409.1, 0.049], [64056.1, 0.042], [64185.5, 0.631], [64379.6, 0.477], [64587.0, 10.394], [64587.1, 4.259], [64610.9, 0.077], [64631.7, 0.046], [64666.3, 0.155], [64672.0, 0.105], [64697.9, 1.55], [64698.0, 0.148], [64698.8, 0.004], [64698.9, 0.055], [64699.0, 0.014], [64699.8, 0.385], [64699.9, 0.006], [64700.1, 0.004], [64700.5, 1.123], [64700.7, 0.244], [64700.8, 0.016], [64701.1, 0.009], [64701.5, 0.001], [64703.0, 1.39], [64703.1, 0.128]], "asks": [[64703.2, 35.981], [64707.1, 0.421], [64710.9, 0.907], [64751.0, 1.91], [64751.3, 0.001], [64774.1, 0.046], [64815.3, 0.012], [64828.6, 0.002], [64838.4, 3.979], [64867.1, 0.005], [65220.8, 6.894], [65350.2, 0.0], [65352.5, 0.385], [65355.2, 1.0], [66320.8, 0.075]]}
{"kind": "depth", "E": 1787095534563, "U": 11316386122019, "u": 11316386133331, "recv_ms": 1787095534629, "bids": [[14503.1, 2.856], [14603.1, 1.344], [51762.5, 0.0], [58232.7, 0.002], [61467.9, 0.001], [62114.9, 0.008], [63409.1, 0.052], [63703.1, 0.785], [63805.7, 0.0], [64056.1, 0.042], [64585.9, 0.003], [64686.0, 0.912], [64689.5, 0.0], [64689.8, 0.136], [64690.6, 0.604], [64691.0, 0.904], [64691.9, 0.004], [64693.2, 0.006], [64693.6, 0.035], [64696.2, 0.087], [64697.1, 0.238], [64697.3, 0.629], [64697.4, 0.545], [64697.6, 0.977], [64697.8, 0.014], [64697.9, 1.547], [64698.0, 0.148], [64698.1, 0.194], [64698.5, 0.021], [64699.2, 0.002], [64699.6, 0.001], [64699.8, 0.385], [64700.5, 1.123], [64700.7, 0.252], [64700.8, 0.008], [64703.0, 1.39], [64703.1, 0.127]], "asks": [[64703.2, 38.426], [64704.5, 0.102], [64706.9, 0.015], [64708.2, 0.001], [64710.9, 1.023], [64713.6, 0.036], [64713.7, 2.141], [64713.8, 0.769], [64715.8, 0.629], [64716.6, 4.01], [64719.6, 0.021], [64720.4, 2.548], [64721.1, 0.496], [64729.8, 0.379], [64730.6, 0.881], [64734.8, 0.049], [64751.3, 0.155], [65350.2, 0.0], [65500.9, 13.155], [65703.2, 0.0], [65997.2, 0.074]]}
{"kind": "depth", "E": 1787095534665, "U": 11316386133401, "u": 11316386146101, "recv_ms": 1787095534728, "bids": [[1000.0, 35.91], [14503.1, 3.206], [14603.1, 0.994], [51763.0, 0.0], [58232.7, 0.002], [61467.9, 0.001], [61472.1, 0.002], [62114.9, 0.005], [63704.4, 10.255], [63717.6, 0.47], [64056.1, 0.044], [64339.1, 6.464], [64435.7, 0.0], [64461.6, 0.0], [64487.5, 0.002], [64507.3, 2.431], [64513.4, 0.013], [64539.3, 0.031], [64551.0, 0.081], [64563.2, 1.863], [64641.6, 2.231], [64687.5, 0.563], [64688.3, 0.002], [64692.9, 0.184], [64696.5, 0.627], [64696.8, 0.005], [64697.2, 0.01], [64699.2, 0.086], [64700.5, 0.839], [64700.7, 0.244], [64700.8, 0.016], [64703.0, 0.0], [64703.1, 0.41]], "asks": [[64703.2, 35.848], [64707.1, 0.421], [64710.9, 1.023], [64717.0, 1.014], [64718.8, 0.503], [64726.5, 0.264], [64727.7, 0.014], [64728.9, 0.776], [64729.3, 0.095], [64729.4, 0.005], [64730.2, 0.474], [64730.6, 0.422], [64751.3, 0.001], [64751.5, 0.157], [64758.1, 0.012], [64758.2, 0.04], [64841.6, 1.881], [65350.2, 0.0], [65350.3, 0.0], [71173.5, 0.002]]}
{"kind": "depth", "E": 1787095534767, "U": 11316386146172, "u": 11316386155474, "recv_ms": 1787095534828, "bids": [[1000.0, 35.91], [14503.1, 3.57], [14603.1, 0.63], [51763.0, 0.004], [58232.7, 0.002], [61467.9, 0.0], [63411.9, 0.0], [63412.9, 0.0], [63703.1, 0.805], [63894.3, 0.273], [64056.1, 0.042], [64379.6, 0.467], [64507.4, 0.193], [64551.0, 0.088], [64604.7, 0.0], [64610.9, 0.084], [64638.4, 1.12], [64638.9, 0.024], [64643.2, 0.115], [64695.6, 0.019], [64696.8, 0.006], [64697.1, 0.005], [64697.8, 0.246], [64700.7, 0.244], [64700.8, 0.016], [64703.0, 1.39], [64703.1, 0.406]], "asks": [[64703.2, 35.849], [64707.0, 0.008], [64710.9, 1.022], [64751.5, 0.157], [65350.2, 0.0], [65446.4, 0.0], [65703.2, 0.02], [66000.2, 0.011], [66001.2, 0.0], [71173.5, 0.0]]}
{"kind": "depth", "E": 1787095534869, "U": 11316386155547, "u": 11316386165061, "recv_ms": 1787095534939, "bids": [[14403.1, 0.084], [14503.1, 3.766], [14603.1, 0.35], [51763.0, 0.0], [58232.7, 0.002], [61467.9, 0.0], [62114.9, 0.008], [63603.1, 2.515], [63700.2, 1.108], [63732.6, 0.395], [63761.8, 0.001], [63829.6, 2.404], [63930.9, 24.776], [64056.1, 0.042], [64688.3, 0.022], [64690.6, 0.584], [64696.7, 1.071], [64700.5, 0.839], [64700.7, 0.244], [64700.8, 0.016], [64703.0, 1.39], [64703.1, 0.41]], "asks": [[64703.2, 35.848], [64707.1, 0.421], [64707.2, 0.009], [64710.9, 1.023], [65350.2, 0.0], [65563.3, 7.922], [65999.7, 1.541]]}
{"kind": "depth", "E": 1787095534971, "U": 11316386165071, "u": 11316386173216, "recv_ms": 1787095535042, "bids": [[1000.0, 35.91], [14403.1, 0.308], [14503.1, 3.668], [14603.1, 0.224], [58232.7, 0.002], [61467.9, 0.0], [62114.9, 0.005], [63703.1, 0.785], [63784.3, 0.47], [63926.7, 2.344], [64056.1, 0.044], [64088.4, 0.622], [64092.7, 10.697], [64358.9, 0.001], [64360.3, 0.495], [64529.1, 0.0], [64545.8, 6.317], [64562.8, 4.806], [64563.2, 1.045], [64609.3, 0.078], [64641.6, 2.193], [64643.2, 0.077], [64700.5, 0.839], [64700.7, 0.244], [64700.8, 0.016], [64703.0, 1.39], [64703.1, 0.412]], "asks": [[64703.2, 36.505], [64710.9, 1.022], [64821.7, 0.001], [64825.1, 0.089], [64841.6, 1.192], [64843.8, 5.399], [64860.8, 10.407], [64899.6, 7.729], [65350.2, 0.0], [65576.7, 0.761], [65703.2, 0.0], [65870.1, 0.984], [65999.4, 3.486], [65999.7, 1.538]]}
{"kind": "depth", "E": 1787095535073, "U": 11316386173291, "u": 11316386183059, "recv_ms": 1787095535135, "bids": [[1000.0, 35.91], [14403.1, 0.56], [14503.1, 3.528], [14603.1, 0.112], [51763.0, 0.0], [58232.7, 0.002], [61467.9, 0.0], [62114.9, 0.008], [63732.5, 0.392], [64056.1, 0.042], [64086.2, 0.0], [64379.6, 0.467], [64560.3, 0.005], [64684.7, 0.001], [64690.7, 0.31], [64691.4, 0.0], [64691.5, 0.0], [64694.3, 0.344], [64696.9, 0.096], [64699.0, 0.002], [64699.9, 0.006], [64700.1, 0.01], [64700.5, 0.84], [64700.7, 0.252], [64700.8, 0.008], [64702.2, 0.0], [64703.0, 1.39], [64703.1, 0.412]], "asks": [[64703.2, 34.73], [64705.3, 0.188], [64705.9, 0.009], [64707.0, 0.001], [64708.1, 0.061], [64710.9, 1.023], [64717.0, 0.994], [64726.2, 1.956], [64726.5, 0.284], [64860.8, 0.0], [64861.0, 1.74], [64861.5, 6.851], [64899.6, 0.002], [64900.3, 1.604], [65026.8, 0.0], [65350.2, 0.0], [65500.9, 12.926], [65997.2, 0.077]]}
{"kind": "depth", "E": 1787095535175, "U": 11316386183171, "u": 11316386191922, "recv_ms": 1787095535248, "bids": [[14403.1, 0.798], [14503.1, 3.402], [14603.1, 0.0], [51763.0, 0.0], [58232.7, 0.002], [61467.9, 0.0], [62114.9, 0.005], [63411.1, 0.01], [63703.1, 0.805], [63714.8, 0.019], [63779.5, 0.008], [63781.3, 0.108], [64056.1, 0.042], [64379.5, 0.002], [64560.3, 0.005], [64666.3, 0.001], [64678.2, 0.688], [64678.4, 1.535], [64685.6, 0.008], [64686.7, 0.009], [64687.5, 0.007], [64689.3, 0.87], [64689.8, 0.02], [64691.4, 0.116], [64696.2, 0.003], [64696.5, 0.168], [64696.9, 0.096], [64697.8, 0.014], [64698.3, 0.461], [64698.6, 0.234], [64700.1, 0.01], [64700.3, 0.218], [64700.5, 0.002], [64700.7, 1.533], [64700.8, 0.008], [64701.1, 0.009], [64701.2, 0.962], [64701.8, 0.0], [64703.0, 1.39], [64703.1, 0.405]], "asks": [[64703.2, 33.1], [64703.4, 1.085], [64703.7, 1.004], [64703.8, 0.086], [64704.2, 2.585], [64704.3, 0.173], [64704.9, 0.087], [64705.1, 0.005], [64705.5, 0.0], [64705.6, 0.049], [64707.2, 0.005], [64710.9, 1.024], [64711.7, 0.29], [64713.7, 2.061], [64714.6, 0.082], [64715.8, 0.011], [64716.6, 0.01], [64718.8, 0.523], [64719.2, 0.38], [64719.6, 0.639], [64720.2, 4.542], [64720.3, 10.422], [64720.4, 0.464], [64722.6, 0.686], [64724.1, 0.005], [64726.5, 0.264], [64728.9, 0.22], [64729.6, 0.602], [64730.2, 0.015], [64730.8, 1.104], [64731.5, 0.001], [64732.6, 0.102], [64755.0, 0.434], [65350.2, 0.0], [65703.2, 0.02], [65999.7, 1.535]]}
{"kind": "depth", "E": 1787095535277, "U": 11316386192121, "u": 11316386200669, "recv_ms": 1787095535351, "bids": [[1000.0, 35.91], [14403.1, 1.148], [14503.1, 3.052], [58232.7, 0.002], [61467.9, 0.001], [63409.1, 0.055], [63411.1, 0.007], [63497.8, 3.144], [63703.1, 0.785], [64056.1, 0.046], [64082.0, 1.759], [64379.6, 0.477], [64627.0, 0.163], [64627.2, 2.245], [64635.3, 0.046], [64635.5, 2.002], [64643.5, 1.363], [64643.7, 1.793], [64678.2, 0.07], [64678.4, 1.534], [64688.4, 0.558], [64689.3, 0.314], [64690.1, 0.002], [64690.4, 0.139], [64690.7, 0.426], [64690.8, 1.343], [64691.4, 0.0], [64692.5, 0.316], [64694.4, 0.163], [64694.6, 0.197], [64697.1, 0.553], [64697.2, 0.003], [64697.3, 0.088], [64697.5, 0.004], [64697.7, 0.463], [64697.9, 1.779], [64698.3, 0.002], [64698.6, 0.002], [64699.8, 0.509], [64700.1, 0.01], [64700.4, 0.001], [64700.6, 1.718], [64700.7, 1.401], [64700.8, 0.016], [64701.1, 0.009], [64701.2, 0.004], [64702.6, 0.22], [64703.0, 1.39], [64703.1, 0.401]], "asks": [[64703.2, 34.497], [64704.9, 0.09], [64705.6, 0.05], [64705.9, 0.002], [64706.4, 0.007], [64707.1, 0.421], [64709.6, 0.033], [64709.8, 0.238], [64710.9, 1.024], [64717.9, 1.002], [64718.0, 2.003], [64726.1, 0.314], [64726.3, 2.0], [64728.7, 0.007], [64860.8, 10.407], [64861.0, 0.802], [64861.5, 0.001], [64899.6, 6.186], [64900.3, 0.002], [65350.2, 0.0], [65385.4, 0.855], [65625.1, 0.011], [65626.9, 2.29], [65691.6, 0.019], [65703.2, 0.0], [65900.2, 1.04], [65997.2, 0.08]]}
{"kind": "depth", "E": 1787095535379, "U": 11316386200677, "u": 11316386208078, "recv_ms": 1787095535440, "bids": [[1000.0, 35.91], [14403.1, 1.512], [14503.1, 2.688], [58232.7, 0.0], [61467.9, 0.001], [62114.9, 0.008], [64056.1, 0.042], [64560.3, 0.005], [64562.8, 0.001], [64657.8, 2.326], [64658.7, 0.0], [64694.4, 0.704], [64697.1, 0.012], [64697.5, 0.004], [64698.0, 0.148], [64700.4, 0.001], [64700.5, 0.002], [64703.0, 1.39], [64703.1, 0.399]], "asks": [[64703.2, 33.851], [64705.8, 0.311], [64707.1, 0.421], [64710.9, 1.022], [64711.0, 0.507], [64722.6, 0.668], [64723.4, 25.032], [64761.5, 0.018], [64763.6, 0.0], [64815.3, 0.009], [64843.8, 0.001], [65350.2, 0.0]]}
{"kind": "depth", "E": 1787095535481, "U": 11316386208085, "u": 11316386215965, "recv_ms": 1787095535540, "bids": [[14403.1, 1.862], [14503.1, 2.338], [51762.5, 0.0], [58232.7, 0.002], [61467.9, 0.0], [62114.9, 0.005], [64056.1, 0.042], [64381.2, 0.077], [64507.0, 12.984], [64507.3, 0.663], [64545.8, 6.986], [64562.8, 4.93], [64666.7, 0.048], [64694.4, 0.163], [64697.1, 0.553], [64697.5, 0.004], [64698.0, 1.106], [64703.0, 0.0]], "asks": [[64703.2, 33.27], [64707.2, 0.005], [64708.1, 0.0], [64741.0, 0.3], [64820.1, 0.07], [64843.8, 5.399], [64860.8, 10.407], [64899.6, 6.756], [65350.2, 0.0], [65416.5, 0.859]]}
{"kind": "depth", "E": 1787095535583, "U": 11316386215974, "u": 11316386224085, "recv_ms": 1787095535646, "bids": [[1000.0, 35.91], [14403.1, 2.226], [14503.1, 1.974], [58232.7, 0.002], [61467.9, 0.0], [62114.9, 0.008], [63703.1, 0.805], [64056.1, 0.044], [64379.6, 0.477], [64666.5, 0.155], [64694.4, 0.711], [64697.1, 0.005], [64697.5, 0.004], [64698.0, 0.148], [64699.7, 2.405], [64700.3, 0.134], [64700.6, 1.718], [64700.8, 0.018], [64703.0, 1.39], [64703.1, 0.401]], "asks": [[64703.2, 33.924], [64707.2, 0.009], [64710.9, 1.024], [64711.0, 0.505], [64860.8, 0.0], [64861.5, 6.969], [64899.6, 0.002], [64900.3, 1.597], [65350.2, 0.002], [65703.2, 0.02], [65997.2, 0.083]]}
{"kind": "depth", "E": 1787095535685, "U": 11316386224138, "u": 11316386232110, "recv_ms": 1787095535746, "bids": [[1000.0, 35.91], [14403.1, 2.576], [14503.1, 1.624], [51762.0, 0.0], [58232.7, 0.002], [61467.9, 0.006], [63477.0, 2.05], [64056.1, 0.042], [64507.3, 2.512], [64560.3, 0.004], [64563.2, 1.861], [64689.1, 0.009], [64689.7, 0.0], [64690.0, 1.018], [64690.7, 0.31], [64693.8, 0.21], [64694.3, 0.328], [64694.4, 0.179], [64694.6, 0.197], [64696.6, 0.073], [64696.9, 0.558], [64697.1, 0.546], [64697.5, 0.011], [64697.6, 0.974], [64697.7, 0.004], [64697.9, 1.547], [64698.0, 0.108], [64698.1, 0.009], [64700.2, 0.086], [64700.5, 0.001], [64700.6, 0.001], [64700.7, 0.994], [64700.8, 0.018], [64702.6, 0.015], [64703.0, 0.0]], "asks": [[64703.2, 33.272], [64705.8, 0.313], [64707.2, 0.005], [64709.9, 0.033], [64710.7, 0.332], [64710.8, 0.008], [64710.9, 1.022], [64711.5, 0.222], [64712.1, 0.283], [64712.9, 0.019], [64713.6, 0.105], [64714.3, 0.151], [64717.0, 1.014], [64718.8, 0.503], [64726.5, 0.264], [64729.4, 0.005], [64730.0, 3.25], [64730.8, 0.645], [64841.6, 1.881], [65317.9, 0.656], [65350.2, 0.0], [65512.0, 0.419]]}
{"kind": "depth", "E": 1787095535787, "U": 11316386232149, "u": 11316386239407, "recv_ms": 1787095535849, "bids": [[14403.1, 2.94], [14503.1, 1.26], [51762.0, 0.0], [58232.7, 0.002], [62114.9, 0.005], [63703.1, 0.785], [63924.6, 4.266], [63931.1, 4.452], [63968.6, 6.088], [64056.1, 0.042], [64560.3, 0.004], [64609.3, 0.085], [64666.5, 0.155], [64666.7, 0.048], [64684.7, 0.001], [64694.3, 0.328], [64696.3, 0.066], [64697.0, 2.966], [64697.5, 0.243], [64697.6, 1.331], [64698.0, 1.917], [64699.9, 0.002], [64700.6, 0.001], [64700.8, 0.018], [64701.0, 0.849], [64701.1, 1.658], [64701.2, 0.383], [64703.0, 1.39], [64703.1, 0.397]], "asks": [[64703.2, 34.556], [64706.4, 0.007], [64707.1, 0.421], [64707.2, 0.009], [64711.1, 0.004], [64860.8, 10.407], [64861.5, 0.001], [64899.6, 7.032], [64900.3, 0.002], [65350.2, 0.01], [65462.0, 1.616], [65703.2, 0.0]]}
