{"kind": "depth", "E": 1787089605725, "U": 11315997125637, "u": 11315997132535, "recv_ms": 1787089605682, "bids": [[1000.0, 35.76], [14072.9, 0.28], [14372.9, 0.196], [14472.9, 3.724], [58115.6, 0.004], [61344.2, 0.005], [61989.9, 0.026], [63281.5, 0.022], [63507.4, 2.22], [63572.9, 0.0], [63636.6, 9.42], [63675.3, 0.941], [63882.0, 1.814], [63927.2, 0.007], [64551.5, 0.001], [64564.0, 0.003], [64564.9, 0.0], [64565.4, 0.001], [64565.7, 0.0], [64565.9, 0.002], [64566.8, 6.917], [64566.9, 0.681], [64567.0, 0.226], [64567.2, 0.442], [64567.3, 0.185], [64567.6, 0.235], [64567.9, 0.398], [64568.6, 0.085], [64569.6, 1.682], [64570.1, 1.743], [64570.2, 0.078], [64570.5, 0.626], [64571.2, 0.001], [64572.3, 0.003], [64572.9, 25.018]], "asks": [[64573.0, 0.651], [64575.7, 0.002], [64576.0, 0.04], [64578.1, 0.991], [64578.2, 1.834], [64579.4, 0.02], [64579.7, 0.086], [64579.9, 0.032], [64580.2, 0.002], [64580.3, 0.001], [64580.4, 0.01], [64583.9, 0.0], [64586.6, 2.549], [64586.8, 0.004], [64590.4, 0.007], [64591.8, 0.025], [64598.4, 0.037], [64600.0, 0.94], [64601.0, 0.221], [64601.6, 0.237], [64602.8, 0.001], [64602.9, 2.889], [64603.4, 0.007], [64612.0, 0.04], [64612.6, 0.817], [64619.5, 0.042], [64621.4, 10.011], [64625.7, 0.024], [64644.8, 1.432], [64646.9, 38.054], [64759.5, 0.023], [64759.6, 0.003], [65218.7, 0.004], [65573.0, 0.0]]}
{"kind": "depth", "E": 1787089605827, "U": 11315997132555, "u": 11315997136538, "recv_ms": 1787089605785, "bids": [[14072.9, 0.168], [14372.9, 0.448], [14472.9, 3.584], [58115.6, 0.002], [61344.2, 0.005], [61989.9, 0.029], [63927.2, 0.005], [64495.4, 1.98], [64514.7, 0.018], [64544.6, 0.14], [64548.5, 0.109], [64548.8, 0.546], [64551.5, 0.0], [64551.8, 0.09], [64556.5, 0.083], [64563.0, 0.97], [64572.3, 0.001], [64572.9, 25.021]], "asks": [[64573.0, 0.807], [64578.1, 0.0], [64594.7, 0.044], [64597.0, 0.111], [64597.6, 0.565], [64600.9, 0.01], [64601.9, 0.065], [64631.2, 0.003], [64644.8, 39.486], [64646.9, 0.0], [64650.5, 0.636], [64939.3, 0.0], [65218.7, 0.002], [65459.2, 0.769], [67800.8, 0.035]]}
{"kind": "depth", "E": 1787089605929, "U": 11315997136640, "u": 11315997140665, "recv_ms": 1787089605888, "bids": [[1000.0, 35.76], [14072.9, 0.042], [14372.9, 0.672], [14472.9, 3.486], [58115.6, 0.002], [61344.2, 0.005], [63572.9, 0.02], [63927.2, 0.005], [64250.0, 12.307], [64499.7, 0.015], [64501.9, 32.6], [64548.5, 0.108], [64567.9, 0.166], [64569.5, 0.425], [64570.1, 1.666], [64570.6, 0.079], [64572.3, 0.003], [64572.9, 25.023]], "asks": [[64573.0, 0.808], [64575.5, 0.004], [64589.3, 0.0], [64589.9, 0.31], [64605.8, 0.347], [64768.9, 9.511], [64895.9, 0.645], [65444.7, 1.371], [65573.0, 0.02]]}
{"kind": "depth", "E": 1787089606031, "U": 11315997140686, "u": 11315997144100, "recv_ms": 1787089605997, "bids": [[1000.0, 35.76], [14072.9, 0.0], [14372.9, 0.994], [14472.9, 3.206], [58115.6, 0.002], [61989.9, 0.026], [63225.8, 0.0], [63281.5, 0.019], [63661.0, 0.786], [63927.2, 0.005], [63936.8, 0.036], [64250.0, 12.308], [64549.3, 0.006], [64554.8, 0.465], [64556.2, 0.117]], "asks": [[64573.0, 0.815], [64592.2, 0.31], [64592.8, 0.8], [64599.2, 0.0], [64599.6, 0.177], [64599.7, 2.114], [64601.6, 0.083], [64652.5, 1.33], [64655.5, 0.026], [64659.6, 0.0], [64662.5, 0.773], [64666.6, 0.04], [64669.6, 0.014], [64673.7, 0.0], [64676.6, 0.013], [64680.7, 0.0], [64683.7, 0.013], [64690.1, 0.113], [64768.9, 9.508], [65088.8, 7.701], [65218.7, 0.002], [65380.6, 5.379], [65420.3, 0.763]]}
{"kind": "depth", "E": 1787089606133, "U": 11315997144201, "u": 11315997151246, "recv_ms": 1787089606091, "bids": [[14372.9, 1.358], [14472.9, 2.842], [58115.6, 0.002], [61989.9, 0.029], [63225.8, 0.052], [63560.0, 1.65], [63572.9, 0.0], [63757.2, 2.896], [63927.2, 0.005], [63959.5, 4.179], [64549.3, 0.005], [64553.7, 0.071], [64555.6, 0.116], [64556.1, 0.005], [64556.2, 0.001], [64561.3, 0.001], [64572.9, 24.99]], "asks": [[64582.8, 0.245], [64585.6, 0.057], [64588.5, 0.009], [64601.4, 4.595], [64602.8, 1.886], [64602.9, 1.004], [64616.2, 5.255], [64687.8, 0.0], [64690.7, 0.014], [64694.8, 7.396], [64697.8, 0.808], [64701.9, 0.001], [64704.9, 0.454], [65089.6, 2.155], [65218.7, 0.002], [65380.8, 1.559], [65528.7, 3.05], [65573.0, 0.0], [69000.0, 75.817]]}
{"kind": "depth", "E": 1787089606235, "U": 11315997151314, "u": 11315997156507, "recv_ms": 1787089606193, "bids": [[1000.0, 35.76], [14372.9, 1.708], [14472.9, 2.492], [58115.6, 0.002], [61344.2, 0.005], [61989.9, 0.026], [62932.1, 0.0], [63927.2, 0.005], [64250.0, 12.299], [64562.0, 0.001], [64562.1, 0.0], [64563.3, 0.939], [64564.0, 0.545], [64572.9, 25.021]], "asks": [[64592.8, 0.258], [64593.5, 0.574], [64597.6, 0.008], [64598.6, 0.558], [64599.6, 0.061], [64600.6, 0.183], [64601.6, 0.237], [64621.4, 0.011], [64644.8, 39.635], [64646.9, 0.0], [64895.9, 0.644], [65163.1, 1.958], [65218.7, 0.002], [65459.2, 0.006], [65477.0, 1.64], [65657.8, 1.524], [65864.4, 0.018], [67800.8, 0.03]]}
{"kind": "depth", "E": 1787089606337, "U": 11315997156722, "u": 11315997161305, "recv_ms": 1787089606295, "bids": [[1000.0, 35.76], [14372.9, 2.058], [14472.9, 2.142], [51658.0, 0.0], [58115.6, 0.002], [61344.2, 0.005], [61989.9, 0.029], [63572.9, 0.02], [63635.8, 13.775], [63927.2, 0.005], [64502.0, 8.507], [64548.7, 0.006], [64553.7, 0.07], [64562.4, 0.947], [64563.1, 0.542], [64563.3, 0.012], [64564.0, 0.003], [64572.9, 25.01]], "asks": [[64573.0, 0.831], [65218.7, 0.002], [65573.0, 0.02]]}
{"kind": "depth", "E": 1787089606439, "U": 11315997161440, "u": 11315997165548, "recv_ms": 1787089606395, "bids": [[14372.9, 2.422], [14472.9, 1.778], [51658.0, 0.0], [51658.3, 0.0], [58115.6, 0.002], [61344.3, 0.008], [63572.0, 3.142], [63927.2, 0.007], [64548.7, 0.005], [64569.5, 0.193], [64570.4, 0.861], [64572.9, 25.403]], "asks": [[64573.0, 0.832], [64601.5, 1.24], [64601.6, 0.237], [65218.7, 0.002], [65388.1, 1.529], [65605.4, 3.198]]}
{"kind": "depth", "E": 1787089606541, "U": 11315997165579, "u": 11315997169844, "recv_ms": 1787089606507, "bids": [[1000.0, 35.76], [14372.9, 2.772], [14472.9, 1.428], [51658.0, 0.0], [58115.6, 0.002], [61344.2, 0.005], [61989.9, 0.026], [63448.9, 1.425], [63572.9, 0.0], [63652.7, 0.796], [63675.3, 1.881], [63927.2, 0.005], [64250.0, 12.309], [64435.7, 0.1], [64495.4, 1.983], [64549.8, 0.017], [64572.9, 25.406]], "asks": [[64573.0, 0.857], [64574.9, 0.024], [64579.0, 0.104], [64583.6, 0.304], [64601.6, 0.083], [64650.5, 0.639], [64761.6, 0.437], [64763.8, 0.002], [65218.7, 0.002], [65426.5, 2.625], [65573.0, 0.0], [66188.6, 0.006]]}
{"kind": "depth", "E": 1787089606643, "U": 11315997169999, "u": 11315997174000, "recv_ms": 1787089606601, "bids": [[1000.0, 35.76], [14372.9, 3.136], [14472.9, 1.064], [51658.0, 0.0], [58115.6, 0.002], [61989.9, 0.029], [63624.6, 3.303], [63636.6, 10.518], [63790.3, 4.215], [63927.2, 0.005], [64549.8, 0.016], [64552.6, 0.025], [64555.6, 0.0], [64556.4, 0.116]], "asks": [[64597.7, 1.222], [64598.6, 0.001], [64599.7, 2.23], [64600.6, 0.067], [64601.5, 1.24], [64601.7, 1.121], [64768.9, 9.414], [65218.7, 0.002], [65426.5, 2.335], [66187.3, 1.587], [67800.8, 0.025]]}
{"kind": "depth", "E": 1787089606847, "U": 11315997178634, "u": 11315997182503, "recv_ms": 1787089606805, "bids": [[1000.0, 35.76], [14272.9, 0.056], [14372.9, 3.738], [14472.9, 0.406], [51658.0, 0.0], [58115.6, 0.002], [61344.4, 0.004], [61989.9, 0.029], [63475.2, 0.392], [63668.9, 4.594], [63927.2, 0.005], [64250.0, 12.299]], "asks": [[65218.7, 0.002], [67134.8, 1.274]]}
{"kind": "depth", "E": 1787089606949, "U": 11315997182646, "u": 11315997186212, "recv_ms": 1787089606907, "bids": [[1000.0, 35.76], [14272.9, 0.252], [14372.9, 3.696], [14472.9, 0.252], [58115.6, 0.002], [61344.2, 0.005], [63571.2, 9.751], [63572.9, 0.0], [63636.6, 11.617], [63660.4, 8.631], [63765.7, 1.235], [63798.0, 8.349], [63927.2, 0.005], [64250.0, 12.298], [64572.9, 25.386]], "asks": [[64579.5, 2.864], [64585.2, 1.048], [65218.7, 0.002], [65371.5, 1.023], [65573.0, 0.0]]}
{"kind": "depth", "E": 1787089607051, "U": 11315997186227, "u": 11315997190381, "recv_ms": 1787089607011, "bids": [[14272.9, 0.504], [14372.9, 3.556], [14472.9, 0.14], [58115.6, 0.002], [61344.2, 0.005], [61989.9, 0.026], [63318.9, 0.0], [63448.4, 0.017], [63572.0, 4.241], [63927.2, 0.005], [64415.8, 7.864], [64416.0, 2.238], [64432.7, 4.295], [64435.1, 1.524], [64463.1, 0.004], [64475.2, 1.325], [64495.4, 1.98], [64513.7, 1.869], [64514.7, 0.015], [64520.4, 0.251], [64561.3, 0.006], [64570.1, 1.668], [64572.9, 25.374]], "asks": [[64573.0, 0.846], [64575.5, 0.005], [64601.7, 0.967], [64631.2, 0.003], [64650.5, 0.636], [64656.0, 0.775], [64657.8, 0.0], [64711.9, 0.672], [64712.9, 0.0], [64713.2, 5.456], [64729.6, 2.756], [64730.2, 10.428], [64768.9, 0.0], [64771.2, 12.602], [64895.9, 0.645], [65088.8, 6.78], [65218.7, 0.002], [65748.2, 0.765]]}
{"kind": "depth", "E": 1787089607153, "U": 11315997190563, "u": 11315997196911, "recv_ms": 1787089607114, "bids": [[1000.0, 35.76], [14272.9, 0.742], [14372.9, 3.444], [14472.9, 0.014], [51658.0, 0.0], [58115.6, 0.002], [61344.3, 0.008], [61989.9, 0.029], [63281.5, 0.022], [63572.9, 0.02], [63757.2, 2.662], [63854.6, 2.586], [63927.2, 0.005], [64250.0, 12.308], [64553.1, 0.062], [64556.1, 0.005], [64560.0, 7.269], [64560.4, 0.444], [64561.3, 0.001], [64561.8, 2.845], [64563.0, 2.149], [64563.8, 0.009], [64564.5, 0.353], [64565.4, 0.009], [64566.8, 0.002], [64567.0, 0.86], [64569.6, 0.93], [64570.1, 1.653], [64570.2, 0.062], [64570.5, 0.084], [64570.6, 0.002], [64572.3, 0.001], [64572.9, 25.374]], "asks": [[64573.0, 0.844], [64579.0, 0.02], [64585.5, 0.003], [64588.5, 0.009], [64589.6, 0.017], [64596.5, 0.147], [64601.5, 1.394], [64602.7, 2.155], [64602.8, 0.001], [64607.5, 0.025], [64768.9, 9.366], [64771.2, 0.0], [65089.6, 3.076], [65218.7, 0.002], [65573.0, 0.02], [65864.4, 0.015], [66516.8, 1.287]]}
{"kind": "depth", "E": 1787089607255, "U": 11315997196961, "u": 11315997201871, "recv_ms": 1787089607213, "bids": [[1000.0, 35.76], [14272.9, 1.078], [14372.9, 3.122], [14472.9, 0.0], [51658.0, 0.0], [58115.6, 0.002], [61989.9, 0.026], [63927.2, 0.005], [64250.0, 12.307], [64567.0, 0.226], [64570.5, 0.718], [64570.6, 0.002], [64572.1, 0.107], [64572.3, 0.003]], "asks": [[64601.5, 1.24], [64601.6, 0.237], [65218.7, 0.002], [65864.4, 0.018]]}
{"kind": "depth", "E": 1787089607357, "U": 11315997202047, "u": 11315997205946, "recv_ms": 1787089607315, "bids": [[14272.9, 1.428], [14372.9, 2.772], [58115.6, 0.002], [63475.2, 1.178], [63572.9, 0.0], [63739.4, 0.956], [63927.2, 0.005], [64508.6, 1.496], [64550.2, 1.046], [64566.8, 0.636], [64567.0, 0.226], [64570.5, 0.084], [64570.6, 0.002], [64572.3, 0.001]], "asks": [[64614.4, 1.932], [64643.9, 8.347], [65218.7, 0.002], [65573.0, 0.0]]}
{"kind": "depth", "E": 1787089607459, "U": 11315997206153, "u": 11315997211098, "recv_ms": 1787089607417, "bids": [[1000.0, 35.76], [14272.9, 1.792], [14372.9, 2.408], [51658.3, 0.0], [58115.6, 0.002], [61344.2, 0.005], [61989.9, 0.029], [63281.5, 0.019], [63927.2, 0.005], [64250.0, 12.297], [64548.6, 2.32], [64550.2, 1.045], [64571.7, 0.365], [64572.9, 25.368]], "asks": [[64573.0, 0.835], [64639.4, 4.462], [64730.1, 10.432], [64730.2, 0.0], [64768.9, 9.243], [64771.2, 0.0], [64895.9, 0.646], [65218.7, 0.002]]}
{"kind": "depth", "E": 1787089607663, "U": 11315997216524, "u": 11315997221483, "recv_ms": 1787089607622, "bids": [[14272.9, 2.506], [14372.9, 1.694], [51658.0, 0.0], [58115.6, 0.002], [61344.2, 0.005], [61989.9, 0.029], [63572.9, 0.02], [63927.2, 0.005], [64432.7, 0.0], [64435.1, 0.986], [64469.0, 0.092], [64469.1, 0.081], [64540.1, 0.314], [64540.2, 0.11], [64540.3, 0.002], [64543.6, 0.041], [64543.7, 0.066], [64543.8, 1.088], [64553.2, 0.001], [64557.2, 0.001], [64572.9, 25.369]], "asks": [[64573.0, 0.829], [64658.1, 0.09], [64713.2, 0.048], [64883.0, 0.068], [65218.7, 0.002], [65573.0, 0.02], [65864.4, 0.015]]}
{"kind": "depth", "E": 1787089607765, "U": 11315997221603, "u": 11315997226162, "recv_ms": 1787089607723, "bids": [[1000.0, 35.76], [14272.9, 2.856], [14372.9, 1.344], [51658.0, 0.0], [58115.6, 0.002], [61989.9, 0.026], [63869.1, 1.052], [63927.2, 0.005], [64250.0, 12.307], [64415.8, 0.0], [64416.0, 1.263], [64552.3, 2.332], [64557.2, 0.0]], "asks": [[64643.6, 0.049], [64670.8, 0.0], [64729.6, 1.378], [64730.1, 0.004], [65218.7, 0.002]]}
{"kind": "depth", "E": 1787089607867, "U": 11315997226303, "u": 11315997230971, "recv_ms": 1787089607824, "bids": [[1000.0, 35.76], [14272.9, 3.22], [14372.9, 0.98], [58115.6, 0.002], [61344.2, 0.005], [61344.3, 0.006], [61344.4, 0.004], [63498.9, 0.0], [63572.9, 0.0], [63757.2, 2.311], [63765.7, 1.469], [63927.1, 0.001], [63927.2, 0.005], [64415.7, 7.98], [64432.7, 4.287], [64552.5, 1.062], [64559.9, 0.623], [64572.9, 25.37]], "asks": [[64595.9, 0.922], [64619.5, 0.0], [64713.2, 5.456], [64730.1, 10.432], [64763.9, 0.479], [64768.9, 9.423], [65218.7, 0.002], [65549.5, 0.762], [65573.0, 0.0]]}
{"kind": "depth", "E": 1787089607969, "U": 11315997231218, "u": 11315997235770, "recv_ms": 1787089607927, "bids": [[14272.9, 3.57], [14372.9, 0.63], [58115.6, 0.002], [61989.9, 0.029], [62958.6, 1.268], [63757.2, 2.077], [63818.3, 0.0], [63927.2, 0.005], [64432.7, 0.0], [64467.1, 2.328], [64467.2, 0.015], [64470.2, 1.092]], "asks": [[64681.1, 0.0], [64681.2, 2.323], [64713.2, 0.048], [64895.9, 0.645], [65218.7, 0.002], [65335.1, 1.53], [65483.5, 1.676], [65678.6, 1.52]]}
{"kind": "depth", "E": 1787089608071, "U": 11315997235936, "u": 11315997241444, "recv_ms": 1787089608029, "bids": [[1000.0, 35.76], [14172.9, 0.084], [14272.9, 3.766], [14372.9, 0.35], [58115.6, 0.002], [61344.3, 0.004], [61344.4, 0.006], [61989.9, 0.026], [63507.4, 3.321], [63589.1, 1.028], [63590.1, 0.008], [64250.0, 12.298], [64432.7, 4.278], [64552.3, 2.331], [64555.8, 0.001], [64561.3, 0.001]], "asks": [[64713.2, 5.456], [64763.9, 0.0], [64768.9, 9.48], [64895.1, 4.003], [65186.4, 2.15], [65218.7, 0.002], [65555.8, 0.008], [65556.9, 0.763], [65864.4, 0.012]]}
{"kind": "depth", "E": 1787089608173, "U": 11315997241594, "u": 11315997246924, "recv_ms": 1787089608131, "bids": [[1000.0, 35.76], [14172.9, 0.308], [14272.9, 3.668], [14372.9, 0.224], [51658.0, 0.0], [58115.6, 0.002], [61344.2, 0.005], [61989.9, 0.029], [63572.9, 0.02], [63589.1, 1.037], [63590.1, 0.018], [63648.9, 1.885], [63830.3, 5.633], [63927.2, 0.005], [64456.6, 0.055], [64553.8, 0.004], [64555.8, 0.0], [64556.1, 0.005], [64559.5, 0.311], [64572.1, 0.024], [64572.9, 25.305]], "asks": [[64587.1, 0.0], [64588.5, 0.009], [64614.4, 1.932], [64622.7, 0.028], [64628.4, 0.001], [64650.5, 0.628], [64651.5, 0.008], [64651.7, 0.001], [64652.7, 0.008], [64655.1, 0.083], [64655.5, 0.013], [64662.2, 0.013], [64662.5, 0.76], [64669.3, 0.013], [64669.6, 0.001], [64676.3, 0.213], [64676.6, 0.0], [64683.4, 0.014], [64683.7, 0.0], [64895.9, 0.799], [65218.7, 0.002], [65573.0, 0.02], [65717.6, 1.411]]}
{"kind": "depth", "E": 1787089608275, "U": 11315997246977, "u": 11315997250984, "recv_ms": 1787089608233, "bids": [[14172.9, 0.56], [14272.9, 3.528], [14372.9, 0.112], [51658.0, 0.0], [58115.6, 0.002], [61989.9, 0.026], [63927.2, 0.005], [64553.0, 0.06], [64559.5, 0.31], [64559.7, 0.025], [64572.9, 25.37]], "asks": [[64576.9, 0.038], [64584.2, 0.0], [64601.6, 0.083], [64617.0, 0.073], [64690.4, 0.046], [64690.7, 0.001], [64697.5, 0.105], [64697.8, 0.795], [64704.5, 0.106], [64704.9, 0.441], [65218.7, 0.002], [65555.8, 0.018], [65556.9, 0.772], [65597.3, 0.003]]}
{"kind": "depth", "E": 1787089608377, "U": 11315997251057, "u": 11315997254941, "recv_ms": 1787089608337, "bids": [[1000.0, 35.76], [14172.9, 0.798], [14272.9, 3.402], [14372.9, 0.0], [58115.6, 0.002], [61344.3, 0.006], [63572.9, 0.0], [63927.2, 0.007], [64250.0, 12.308], [64415.7, 0.134], [64432.7, 0.0], [64463.1, 0.001], [64514.7, 0.018], [64553.0, 0.059], [64554.4, 0.001]], "asks": [[64601.5, 1.24], [64601.7, 1.121], [64602.6, 1.886], [64602.7, 0.27], [64631.2, 0.003], [64637.3, 1.701], [64713.2, 0.048], [64730.1, 0.004], [64895.9, 0.798], [65218.7, 0.002], [65261.0, 0.001], [65444.7, 2.423], [65573.0, 0.0]]}
{"kind": "depth", "E": 1787089608479, "U": 11315997254973, "u": 11315997267717, "recv_ms": 1787089608441, "bids": [[1000.0, 35.76], [14172.9, 1.162], [14272.9, 3.038], [51658.3, 0.0], [58115.6, 0.002], [61344.2, 0.005], [61989.9, 0.029], [63281.5, 0.025], [63668.9, 6.946], [63927.2, 0.005], [64234.3, 0.004], [64241.5, 0.116], [64250.0, 12.309], [64415.7, 7.982], [64416.0, 2.235], [64432.7, 4.288], [64435.1, 1.523], [64441.8, 0.001], [64457.3, 0.374], [64457.5, 3.903], [64474.5, 0.02], [64474.7, 4.266], [64486.3, 0.046], [64495.3, 0.01], [64495.4, 1.98], [64499.5, 0.037], [64501.5, 0.0], [64501.7, 0.11], [64501.9, 32.62], [64502.0, 4.84], [64504.2, 4.402], [64504.3, 0.077], [64508.8, 0.254], [64512.0, 0.12], [64512.2, 3.672], [64513.4, 0.06], [64514.0, 0.011], [64516.3, 0.0], [64516.6, 0.036], [64520.1, 1.889], [64524.4, 0.017], [64525.5, 0.036], [64526.3, 0.041], [64526.4, 0.429], [64528.4, 0.021], [64529.0, 0.004], [64531.0, 0.001], [64533.3, 0.003], [64533.9, 0.025], [64536.2, 0.469], [64537.7, 0.149], [64538.1, 0.446], [64539.5, 0.001], [64540.7, 0.033], [64541.0, 2.607], [64541.5, 0.037], [64543.6, 0.033], [64544.0, 0.027], [64544.7, 0.23], [64545.6, 2.955], [64545.8, 0.008], [64546.1, 0.007], [64546.7, 0.0], [64546.9, 0.006], [64547.2, 0.006], [64548.2, 0.0], [64548.8, 0.603], [64549.1, 0.476], [64549.3, 0.017], [64550.0, 0.029], [64550.1, 0.004], [64551.3, 0.18], [64551.4, 0.001], [64551.6, 0.002], [64551.8, 0.0], [64552.1, 0.0], [64552.5, 0.443], [64554.4, 0.0], [64555.1, 0.001], [64555.9, 0.501], [64556.3, 0.119], [64556.4, 0.0], [64556.8, 1.03], [64558.1, 0.116], [64558.6, 0.56], [64559.0, 0.001], [64559.7, 0.025], [64559.8, 0.0], [64559.9, 0.004], [64560.0, 0.354], [64560.1, 0.001], [64560.6, 0.017], [64560.7, 0.003], [64561.0, 0.079], [64561.4, 0.087], [64561.9, 0.01], [64562.4, 0.02], [64563.0, 0.97], [64563.1, 0.0], [64563.7, 0.927], [64563.8, 0.002], [64564.0, 0.545], [64564.1, 0.01], [64564.4, 0.014], [64565.1, 0.053], [64565.2, 0.001], [64565.4, 0.001], [64566.2, 0.001], [64566.4, 0.711], [64566.5, 0.002], [64566.6, 0.465], [64566.7, 0.004], [64566.8, 0.002], [64567.0, 0.226], [64567.2, 0.442], [64567.3, 2.185], [64567.4, 0.301], [64567.6, 0.173], [64567.7, 0.117], [64567.8, 0.237], [64569.4, 0.013], [64569.7, 0.004], [64570.0, 1.523], [64570.1, 0.089], [64570.2, 0.154], [64570.4, 0.629], [64570.5, 0.316], [64570.6, 0.002], [64570.8, 0.0], [64571.0, 1.377], [64571.1, 1.557], [64571.2, 0.017], [64571.3, 0.646], [64571.4, 0.004], [64571.6, 0.059], [64571.7, 0.32], [64571.8, 0.005], [64572.2, 0.0], [64572.3, 0.002], [64572.4, 0.0], [64572.9, 27.151]], "asks": [[64573.0, 0.365], [64573.1, 0.003], [64575.5, 0.005], [64575.6, 1.802], [64575.7, 0.001], [64575.9, 0.014], [64576.0, 0.039], [64576.1, 0.005], [64576.7, 0.001], [64576.8, 0.58], [64576.9, 1.761], [64577.0, 0.002], [64578.0, 0.078], [64578.2, 1.834], [64578.3, 0.094], [64579.2, 0.023], [64579.4, 1.82], [64579.5, 1.063], [64579.6, 0.001], [64579.9, 0.0], [64580.3, 0.009], [64580.4, 0.002], [64580.5, 6.859], [64580.9, 0.114], [64581.1, 0.004], [64581.2, 0.0], [64581.3, 0.467], [64581.5, 0.0], [64581.6, 0.009], [64581.9, 0.002], [64582.0, 0.153], [64582.3, 0.001], [64582.4, 0.007], [64582.6, 0.014], [64582.7, 0.058], [64582.8, 0.084], [64583.0, 0.116], [64583.1, 0.0], [64583.2, 0.091], [64583.3, 0.001], [64583.4, 1.248], [64583.5, 0.001], [64583.6, 0.003], [64583.7, 2.581], [64583.8, 0.002], [64584.0, 0.008], [64584.2, 0.007], [64584.3, 0.001], [64584.4, 0.006], [64584.6, 0.08], [64584.8, 0.016], [64585.4, 0.493], [64585.5, 0.002], [64585.6, 0.013], [64585.8, 1.087], [64585.9, 0.0], [64586.0, 0.154], [64586.1, 0.0], [64586.2, 0.001], [64586.4, 0.021], [64586.5, 1.447], [64586.6, 0.23], [64586.8, 0.001], [64587.0, 0.036], [64587.4, 0.0], [64587.5, 0.008], [64587.7, 0.005], [64587.8, 0.001], [64587.9, 0.229], [64588.0, 0.008], [64588.1, 0.004], [64588.2, 0.767], [64588.3, 0.253], [64588.8, 0.009], [64589.0, 0.148], [64589.2, 0.813], [64589.6, 0.009], [64589.7, 0.044], [64589.8, 0.443], [64590.0, 1.253], [64590.1, 0.483], [64590.4, 0.01], [64590.7, 0.312], [64590.8, 0.0], [64590.9, 0.0], [64591.0, 0.012], [64591.1, 0.739], [64591.2, 0.776], [64591.3, 4.46], [64591.4, 0.074], [64591.6, 0.157], [64591.8, 0.005], [64591.9, 0.0], [64592.0, 0.027], [64592.6, 0.002], [64592.9, 0.001], [64593.1, 0.094], [64593.5, 0.032], [64593.6, 0.786], [64594.0, 2.32], [64594.1, 0.003], [64594.2, 0.035], [64594.7, 0.044], [64594.8, 0.001], [64594.9, 0.039], [64595.0, 1.482], [64595.2, 0.177], [64595.3, 0.543], [64595.4, 0.009], [64595.6, 0.015], [64595.8, 0.165], [64595.9, 0.303], [64596.0, 0.139], [64596.2, 0.949], [64596.3, 0.039], [64596.5, 0.158], [64596.6, 0.018], [64597.0, 0.111], [64597.1, 0.574], [64597.5, 0.642], [64597.7, 0.621], [64598.0, 0.006], [64598.4, 0.017], [64598.5, 0.004], [64599.2, 2.044], [64599.3, 0.001], [64599.5, 0.001], [64599.7, 1.794], [64599.8, 0.0], [64599.9, 0.001], [64600.0, 0.939], [64600.2, 0.183], [64600.3, 0.048], [64600.4, 0.0], [64600.5, 0.058], [64600.6, 0.624], [64600.9, 0.003], [64601.2, 2.344], [64601.3, 0.085], [64601.4, 4.711], [64601.5, 0.003], [64601.7, 0.967], [64601.8, 0.0], [64601.9, 0.065], [64602.1, 0.173], [64602.4, 0.005], [64602.5, 0.003], [64602.6, 0.001], [64603.0, 0.008], [64603.2, 0.436], [64603.5, 0.353], [64603.6, 0.025], [64603.9, 0.162], [64604.2, 0.012], [64604.4, 0.058], [64604.5, 0.006], [64604.7, 0.009], [64605.1, 0.313], [64605.3, 1.344], [64605.4, 1.402], [64605.7, 0.253], [64605.9, 0.444], [64606.3, 0.367], [64607.0, 0.002], [64607.6, 0.014], [64607.7, 0.48], [64607.9, 0.005], [64608.0, 0.01], [64608.3, 1.633], [64608.4, 0.004], [64608.5, 0.002], [64608.7, 0.024], [64609.0, 2.319], [64609.5, 0.011], [64609.7, 0.007], [64610.2, 0.209], [64610.3, 0.004], [64610.8, 0.456], [64612.5, 0.02], [64613.1, 0.478], [64613.2, 0.002], [64613.7, 0.009], [64613.8, 0.022], [64614.1, 0.026], [64614.3, 0.027], [64614.4, 1.345], [64615.6, 0.006], [64616.2, 0.17], [64616.9, 1.244], [64617.0, 0.042], [64617.3, 0.312], [64618.3, 0.021], [64619.6, 0.024], [64619.9, 0.018], [64620.0, 0.074], [64620.8, 0.09], [64621.6, 0.389], [64622.8, 0.025], [64623.1, 0.071], [64623.2, 10.005], [64623.6, 0.02], [64628.0, 2.62], [64628.1, 7.119], [64628.2, 0.25], [64628.9, 0.14], [64631.4, 0.008], [64633.2, 0.079], [64636.4, 0.036], [64643.6, 0.003], [64643.9, 3.021], [64644.8, 1.432], [64645.2, 0.215], [64646.9, 0.0], [64649.7, 0.0], [64659.1, 0.093], [64660.1, 0.013], [64662.3, 0.008], [64664.5, 0.004], [64665.9, 0.0], [64666.4, 0.006], [64668.9, 38.145], [64671.7, 0.001], [64672.3, 1.237], [64673.2, 0.0], [64673.3, 0.002], [64673.5, 0.173], [64676.9, 0.643], [64679.9, 1.243], [64680.0, 3.101], [64690.1, 0.0], [64690.2, 0.0], [64690.9, 0.021], [64691.1, 0.117], [64698.1, 0.557], [64699.4, 0.001], [64711.9, 1.393], [64713.2, 5.456], [64714.2, 0.002], [64715.8, 3.874], [64729.6, 2.756], [64730.1, 10.432], [64740.7, 0.0], [64742.8, 0.216], [64754.1, 0.068], [64768.9, 9.318], [64883.0, 0.069], [64907.0, 0.0], [64914.4, 0.116], [65218.7, 0.002], [65380.2, 2.349], [65606.2, 2.558], [65864.4, 0.015]]}
{"kind": "depth", "E": 1787089608581, "U": 11315997267946, "u": 11315997273437, "recv_ms": 1787089608539, "bids": [[14172.9, 1.526], [14272.9, 2.674], [51658.0, 0.0], [58115.6, 0.002], [61344.2, 0.005], [61989.9, 0.026], [63572.9, 0.02], [63668.9, 7.416], [63927.2, 0.005], [64450.7, 3.131], [64451.4, 0.004], [64474.0, 2.43], [64474.8, 0.047], [64501.9, 0.001], [64504.1, 32.662], [64551.6, 0.001], [64553.4, 0.735], [64556.3, 0.039], [64563.1, 0.003], [64565.2, 0.002], [64565.3, 0.001], [64565.8, 0.082], [64566.4, 0.711], [64567.4, 0.927], [64567.5, 0.116], [64567.8, 0.175], [64568.1, 0.063], [64570.2, 0.07], [64570.5, 0.085], [64570.9, 0.626], [64571.2, 0.003], [64571.3, 0.104], [64571.4, 0.004], [64571.8, 0.003], [64572.1, 0.026], [64572.9, 28.435]], "asks": [[64573.0, 0.419], [64575.5, 0.283], [64575.7, 0.002], [64578.2, 1.806], [64580.0, 0.045], [64580.3, 0.001], [64580.4, 0.01], [64585.4, 0.473], [64585.9, 0.001], [64586.0, 0.176], [64586.4, 0.108], [64586.8, 0.068], [64587.0, 0.119], [64587.1, 0.0], [64587.4, 0.074], [64587.7, 0.069], [64588.1, 0.264], [64588.5, 0.529], [64588.6, 1.889], [64588.7, 0.217], [64588.8, 0.142], [64588.9, 0.147], [64589.7, 0.159], [64591.0, 0.012], [64591.2, 0.234], [64591.6, 0.002], [64591.8, 0.045], [64592.9, 0.001], [64593.0, 0.545], [64594.9, 0.031], [64596.1, 0.011], [64596.6, 0.058], [64600.3, 0.008], [64601.7, 0.005], [64601.9, 0.001], [64602.3, 0.034], [64604.0, 0.016], [64605.7, 2.138], [64605.9, 0.194], [64606.0, 0.141], [64621.6, 0.649], [64622.1, 0.27], [64624.7, 0.014], [64628.2, 0.0], [64628.4, 0.251], [64628.5, 4.554], [64628.6, 0.147], [64628.7, 0.134], [64628.8, 0.579], [64639.3, 0.067], [64639.6, 0.067], [64639.9, 0.229], [64640.2, 5.079], [64640.6, 0.003], [64649.1, 38.144], [64664.5, 0.004], [64668.9, 0.001], [64691.3, 0.124], [64763.9, 0.479], [64821.9, 0.0], [65218.7, 0.002], [65508.5, 19.012], [65573.0, 0.02], [67155.9, 1.274]]}
{"kind": "depth", "E": 1787089608683, "U": 11315997273517, "u": 11315997280859, "recv_ms": 1787089608643, "bids": [[1000.0, 35.76], [14172.9, 1.876], [14272.9, 2.324], [58115.6, 0.002], [61344.2, 0.005], [61989.9, 0.029], [63927.2, 0.005], [64250.0, 12.299], [64469.1, 0.078], [64469.3, 0.021], [64557.6, 0.117], [64558.1, 0.0], [64562.0, 0.001], [64564.1, 0.002], [64566.6, 7.38], [64566.7, 0.012], [64567.3, 0.185], [64568.1, 0.001], [64568.4, 0.162], [64569.6, 1.866], [64570.0, 1.425], [64570.5, 0.084], [64571.2, 0.003], [64571.8, 0.003], [64572.1, 0.024], [64572.2, 0.002], [64572.9, 28.395]], "asks": [[64573.0, 0.504], [64575.4, 0.002], [64578.2, 1.82], [64578.3, 0.094], [64578.4, 0.006], [64578.8, 0.001], [64579.2, 0.024], [64579.5, 1.065], [64580.0, 0.355], [64580.5, 6.859], [64580.6, 41.648], [64582.3, 0.004], [64582.4, 0.008], [64583.2, 0.007], [64585.6, 0.014], [64585.8, 1.529], [64587.0, 0.154], [64587.9, 0.39], [64588.2, 1.047], [64588.5, 2.848], [64588.7, 0.371], [64588.8, 0.143], [64591.0, 0.64], [64594.7, 0.009], [64599.1, 0.557], [64599.5, 0.019], [64600.6, 0.0], [64601.3, 0.002], [64601.9, 0.008], [64602.7, 0.0], [64604.0, 0.002], [64604.2, 0.005], [64604.6, 0.183], [64605.4, 1.241], [64605.6, 0.0], [64605.7, 1.888], [64606.1, 0.465], [64606.2, 0.002], [64606.3, 0.08], [64608.0, 0.983], [64613.1, 0.388], [64618.9, 0.001], [64619.9, 0.0], [64622.1, 0.284], [64623.0, 10.077], [64623.2, 0.005], [64624.7, 0.0], [64627.9, 0.161], [64628.1, 7.399], [64628.6, 0.301], [64628.8, 0.432], [64759.6, 0.0], [64759.9, 0.003], [65218.7, 0.002], [65380.2, 2.578], [65864.4, 0.018]]}
{"kind": "depth", "E": 1787089608785, "U": 11315997280938, "u": 11315997285325, "recv_ms": 1787089608743, "bids": [[1000.0, 35.76], [14172.9, 2.24], [14272.9, 1.96], [58115.6, 0.002], [61989.9, 0.026], [63344.3, 0.152], [63572.9, 0.0], [63927.2, 0.005], [64521.2, 0.546], [64528.9, 0.21], [64539.1, 0.059], [64540.4, 2.319], [64564.1, 0.003], [64566.7, 0.004], [64567.4, 0.301], [64567.5, 0.1], [64569.6, 1.928], [64570.0, 1.363], [64571.2, 0.653], [64572.9, 28.394]], "asks": [[64580.4, 0.01], [64587.9, 0.545], [64588.4, 0.142], [64588.6, 2.029], [64589.7, 0.004], [64601.0, 0.154], [64601.6, 0.009], [64628.3, 0.126], [64628.6, 0.441], [65218.7, 0.002], [65573.0, 0.0], [65864.4, 0.021]]}
{"kind": "depth", "E": 1787089608887, "U": 11315997285362, "u": 11315997290575, "recv_ms": 1787089608847, "bids": [[14172.9, 2.59], [14272.9, 1.61], [58115.6, 0.002], [61344.2, 0.005], [63281.5, 0.022], [63927.1, 0.0], [63927.2, 0.005], [64522.0, 0.373], [64528.9, 0.0], [64532.8, 0.476], [64539.1, 0.019], [64564.1, 0.002], [64565.7, 0.001], [64571.6, 0.016], [64571.7, 0.363], [64572.2, 0.0], [64572.9, 28.392]], "asks": [[64575.3, 0.28], [64575.4, 0.002], [64575.5, 0.005], [64586.8, 0.071], [64588.4, 0.362], [64605.8, 0.221], [64606.1, 0.311], [64610.8, 0.706], [64628.3, 0.126], [64640.6, 0.067], [65218.7, 0.002], [65509.3, 8.722], [65690.6, 0.001]]}
{"kind": "depth", "E": 1787089608989, "U": 11315997290764, "u": 11315997296606, "recv_ms": 1787089608948, "bids": [[1000.0, 35.76], [14172.9, 2.94], [14272.9, 1.26], [58115.6, 0.002], [61989.9, 0.029], [63572.9, 0.02], [63628.0, 1.884], [63765.7, 1.937], [63821.7, 0.013], [63927.2, 0.005], [64250.0, 12.299], [64432.7, 4.119], [64435.1, 0.986], [64464.5, 0.212], [64466.8, 1.99], [64555.0, 0.097], [64561.9, 0.09], [64565.7, 0.0], [64565.8, 0.002], [64566.7, 0.02], [64570.9, 0.394], [64571.2, 0.637], [64571.3, 0.104], [64571.5, 0.0], [64572.1, 0.024], [64572.6, 0.232]], "asks": [[64575.2, 0.002], [64588.4, 0.521], [64603.9, 0.003], [64605.8, 0.001], [64606.0, 0.001], [64611.4, 0.171], [64711.9, 0.672], [64713.2, 5.456], [64768.9, 10.559], [65218.7, 0.002], [65573.0, 0.02]]}
{"kind": "depth", "E": 1787089609091, "U": 11315997296810, "u": 11315997304249, "recv_ms": 1787089609049, "bids": [[1000.0, 35.76], [14172.9, 3.304], [14272.9, 0.896], [58115.6, 0.002], [61344.2, 0.005], [61989.9, 0.026], [63770.3, 3.138], [63927.2, 0.005], [64250.0, 12.298], [64442.9, 0.0], [64469.3, 0.018], [64469.4, 0.003], [64495.3, 32.629], [64495.4, 1.983], [64500.9, 0.424], [64504.1, 0.043], [64551.9, 0.62], [64555.0, 0.096], [64559.3, 0.621], [64561.3, 0.001], [64564.4, 0.015], [64572.1, 0.026], [64572.9, 28.433]], "asks": [[64575.2, 0.993], [64595.4, 0.628], [64600.0, 0.945], [64602.7, 0.619], [64650.5, 0.631], [65218.7, 0.002]]}
{"kind": "depth", "E": 1787089609193, "U": 11315997304364, "u": 11315997310481, "recv_ms": 1787089609151, "bids": [[14172.9, 3.668], [14272.9, 0.532], [58115.6, 0.002], [61344.2, 0.005], [61989.9, 0.029], [63572.9, 0.0], [63636.6, 12.715], [63830.3, 6.572], [63854.7, 0.782], [63927.2, 0.005], [64249.2, 4.429], [64495.3, 0.01], [64501.9, 0.001], [64504.1, 32.648], [64556.1, 0.005], [64559.3, 0.002], [64564.4, 0.014], [64569.6, 1.866], [64569.7, 0.066], [64572.9, 28.434]], "asks": [[64573.0, 0.418], [64575.2, 0.002], [64580.6, 41.645], [64583.6, 0.035], [64583.9, 0.001], [64585.3, 0.0], [64588.5, 2.848], [64595.4, 0.009], [64602.7, 0.0], [64610.9, 0.582], [64895.9, 0.799], [65218.7, 0.002], [65367.3, 0.77], [65573.0, 0.0], [65703.0, 1.248], [65864.4, 0.018]]}
{"kind": "depth", "E": 1787089609295, "U": 11315997310586, "u": 11315997315149, "recv_ms": 1787089609253, "bids": [[1000.0, 35.76], [14072.9, 0.14], [14172.9, 3.738], [14272.9, 0.322], [51658.0, 0.0], [58115.6, 0.002], [61344.2, 0.005], [63854.7, 1.564], [63927.2, 0.005], [63971.4, 0.004], [64250.0, 12.308], [64540.1, 0.312], [64540.2, 0.108], [64540.3, 0.0], [64543.6, 0.031], [64543.7, 0.064], [64543.8, 1.086], [64557.6, 0.117], [64558.6, 0.56], [64558.7, 0.005], [64559.5, 0.31], [64572.9, 28.444]], "asks": [[64573.0, 0.421], [64596.2, 0.022], [64597.2, 1.02], [64599.1, 0.0], [64600.0, 1.502], [64600.5, 0.001], [64601.4, 4.595], [64601.9, 0.065], [64602.0, 0.136], [65218.7, 0.002], [65864.4, 0.021]]}
{"kind": "depth", "E": 1787089609397, "U": 11315997315217, "u": 11315997319564, "recv_ms": 1787089609358, "bids": [[1000.0, 35.76], [14072.9, 0.378], [14172.9, 3.626], [14272.9, 0.196], [51658.0, 0.0], [58115.6, 0.002], [61344.2, 0.005], [61989.9, 0.026], [63495.2, 0.009], [63572.9, 0.02], [63927.2, 0.007], [64250.0, 12.462], [64466.8, 1.084], [64467.2, 1.58], [64510.2, 2.322], [64510.5, 0.752], [64510.9, 0.0], [64511.2, 0.001], [64511.5, 0.329], [64529.6, 0.438], [64529.9, 0.001], [64530.2, 0.0], [64530.5, 0.009], [64530.8, 2.384], [64544.5, 0.018], [64544.6, 0.07], [64544.7, 0.09], [64544.8, 0.002], [64544.9, 0.057], [64545.0, 0.015], [64545.1, 0.07], [64545.2, 0.466], [64545.4, 0.003], [64548.1, 0.002], [64548.5, 0.008], [64551.9, 0.001], [64561.8, 2.32], [64562.8, 0.003], [64564.5, 0.022], [64567.0, 0.156], [64567.1, 0.001], [64567.2, 0.302], [64567.3, 0.649], [64567.4, 0.101], [64567.5, 0.0], [64567.6, 0.003], [64567.7, 0.017], [64567.8, 0.005], [64567.9, 0.096], [64568.2, 0.085], [64568.5, 0.001], [64568.7, 0.063], [64568.8, 0.001], [64569.2, 0.002], [64569.4, 0.083], [64569.5, 0.161], [64569.7, 0.004], [64571.2, 0.003], [64572.9, 28.443]], "asks": [[64573.0, 0.632], [64586.4, 0.041], [64586.8, 0.004], [64587.0, 0.071], [64587.4, 0.0], [64587.7, 0.005], [64587.9, 0.384], [64588.1, 0.004], [64588.2, 0.62], [64588.3, 0.003], [64588.4, 0.175], [64588.5, 2.328], [64588.6, 1.619], [64588.7, 0.07], [64588.8, 0.157], [64588.9, 0.0], [64589.0, 0.008], [64594.9, 0.039], [64595.9, 1.23], [64596.1, 0.003], [64597.2, 0.093], [64605.3, 0.468], [64605.7, 0.003], [64610.8, 0.456], [64610.9, 0.362], [64611.3, 0.149], [64611.4, 0.024], [64617.1, 5.5], [64620.0, 0.007], [64620.3, 0.0], [64620.6, 5.021], [64620.9, 0.0], [64621.2, 1.583], [64621.3, 0.971], [64621.6, 0.389], [64622.1, 0.014], [64623.0, 0.077], [64627.9, 0.0], [64628.1, 6.972], [64628.3, 0.0], [64628.4, 0.001], [64628.5, 4.284], [64628.6, 0.0], [64628.7, 0.001], [64628.9, 0.0], [64639.3, 0.0], [64639.6, 0.0], [64639.9, 0.146], [64640.2, 5.005], [64640.6, 0.003], [64646.8, 6.473], [64646.9, 37.917], [64649.1, 0.0], [64895.9, 0.8], [65218.7, 0.002], [65573.0, 0.02]]}
{"kind": "depth", "E": 1787089609499, "U": 11315997319574, "u": 11315997323878, "recv_ms": 1787089609457, "bids": [[14072.9, 0.616], [14172.9, 3.5], [14272.9, 0.084], [51658.3, 0.0], [58115.6, 0.002], [61344.2, 0.005], [61989.9, 0.029], [63281.5, 0.025], [63572.9, 0.0], [63765.7, 2.288], [63927.2, 0.005], [64531.9, 0.158], [64532.3, 0.033], [64532.6, 0.259], [64532.9, 0.48], [64533.2, 0.109], [64558.3, 2.228], [64561.4, 0.05], [64565.4, 0.038], [64568.7, 0.001], [64569.4, 0.145], [64569.5, 0.231], [64570.1, 0.189], [64570.3, 0.08], [64570.6, 0.034], [64570.9, 0.426], [64571.2, 0.035], [64571.6, 0.048], [64571.7, 0.32], [64571.9, 0.032], [64572.9, 28.433]], "asks": [[64580.5, 6.952], [64586.4, 0.108], [64586.7, 0.069], [64587.0, 0.154], [64587.3, 0.54], [64587.7, 0.069], [64587.8, 0.162], [64588.2, 0.9], [64588.7, 0.224], [64605.7, 0.07], [64605.8, 1.886], [64606.0, 0.068], [64606.3, 0.163], [64606.7, 0.092], [64607.0, 0.066], [64610.3, 0.165], [64610.7, 0.298], [64611.2, 0.159], [64618.8, 0.005], [64619.4, 0.074], [65218.7, 0.002], [65339.2, 5.839], [65573.0, 0.0]]}
{"kind": "depth", "E": 1787089609601, "U": 11315997323971, "u": 11315997330352, "recv_ms": 1787089609560, "bids": [[1000.0, 35.76], [14072.9, 0.896], [14172.9, 3.304], [14272.9, 0.0], [58115.6, 0.002], [61989.9, 0.026], [63765.7, 2.522], [63927.2, 0.005], [64250.0, 12.462], [64495.4, 1.98], [64514.7, 0.018], [64526.5, 0.023], [64528.4, 0.0], [64542.0, 0.024], [64544.0, 0.007], [64545.8, 0.014], [64546.1, 0.001], [64554.3, 0.025], [64556.3, 0.014], [64558.3, 0.228], [64559.4, 0.065], [64561.4, 0.002], [64564.9, 0.001], [64569.4, 0.083], [64569.5, 0.293], [64569.7, 0.074], [64569.9, 2.49], [64571.8, 0.042], [64572.9, 28.431]], "asks": [[64573.0, 0.659], [64578.2, 1.834], [64579.2, 0.108], [64585.3, 0.02], [64585.5, 0.024], [64586.0, 0.157], [64588.3, 0.129], [64588.4, 0.395], [64588.6, 1.759], [64590.0, 1.257], [64604.2, 0.011], [64604.5, 0.0], [64610.5, 0.022], [64610.8, 0.582], [64610.9, 0.582], [64611.1, 0.14], [64612.5, 0.0], [64617.6, 1.022], [64619.6, 0.003], [64620.8, 0.114], [64622.8, 0.0], [64626.0, 0.36], [64628.0, 2.572], [64630.2, 0.005], [64631.2, 0.003], [64643.6, 0.0], [64650.5, 0.628], [64759.9, 0.0], [64760.0, 0.181], [64895.1, 3.387], [65218.7, 0.002], [65864.4, 0.018]]}
{"kind": "depth", "E": 1787089609703, "U": 11315997330458, "u": 11315997335667, "recv_ms": 1787089609662, "bids": [[1000.0, 35.76], [14072.9, 1.246], [14172.9, 2.954], [58115.6, 0.002], [61344.2, 0.005], [61989.9, 0.029], [63560.0, 0.551], [63797.2, 25.198], [63927.2, 0.005], [64415.7, 0.134], [64432.7, 0.0], [64554.2, 0.006], [64564.9, 0.0], [64567.3, 0.015], [64567.4, 0.101], [64569.4, 0.153], [64569.5, 0.231], [64569.6, 1.866], [64569.7, 0.136], [64569.8, 0.203], [64570.0, 1.463], [64570.1, 0.259], [64570.2, 0.17], [64571.2, 0.669], [64572.9, 28.432]], "asks": [[64573.0, 0.704], [64580.4, 0.103], [64580.5, 6.879], [64582.0, 0.133], [64588.0, 0.268], [64588.1, 0.151], [64588.2, 1.15], [64588.4, 0.915], [64588.9, 0.14], [64598.8, 0.591], [64600.0, 0.945], [64600.8, 0.426], [64602.0, 0.02], [64607.4, 0.417], [64607.8, 0.34], [64610.6, 0.242], [64610.7, 0.548], [64610.9, 0.832], [64611.4, 0.164], [64713.2, 0.048], [64730.1, 0.004], [65218.7, 0.002], [65355.8, 3.48], [65485.1, 1.982]]}
{"kind": "depth", "E": 1787089609805, "U": 11315997335856, "u": 11315997340122, "recv_ms": 1787089609764, "bids": [[14072.9, 1.596], [14172.9, 2.604], [51658.0, 0.0], [58115.6, 0.002], [63572.9, 0.02], [63927.2, 0.005], [64415.7, 7.542], [64416.0, 1.263], [64432.6, 4.089], [64512.6, 0.033], [64512.9, 0.034], [64513.2, 0.037], [64513.6, 0.463], [64513.9, 0.079], [64546.9, 0.076], [64554.2, 0.005], [64555.7, 0.177], [64569.5, 0.301], [64569.6, 1.936], [64569.7, 0.236], [64572.9, 28.555]], "asks": [[64588.5, 2.598], [64588.6, 1.906], [64588.7, 0.357], [64611.0, 4.087], [64611.2, 0.306], [64611.3, 0.282], [64625.0, 0.082], [64625.3, 0.067], [64625.6, 0.523], [64626.0, 0.434], [64626.3, 0.064], [64713.2, 5.456], [64729.6, 1.378], [64730.1, 10.432], [64768.9, 10.807], [65218.7, 0.002], [65573.0, 0.02], [67134.8, 0.637]]}
{"kind": "depth", "E": 1787089610009, "U": 11315997344771, "u": 11315997348704, "recv_ms": 1787089609967, "bids": [[14072.9, 2.31], [14172.9, 1.89], [58115.6, 0.002], [61344.2, 0.005], [61989.9, 0.029], [63572.9, 0.0], [63834.8, 4.696], [63927.2, 0.005], [64415.7, 7.542], [64432.6, 4.089], [64547.1, 1.283], [64547.4, 0.257], [64551.8, 0.0], [64556.8, 1.03], [64557.6, 0.117], [64557.7, 0.0], [64558.2, 0.336], [64558.4, 0.908], [64558.6, 0.002], [64559.3, 0.002], [64561.1, 0.01], [64561.9, 0.083], [64562.9, 1.246], [64563.7, 0.927], [64564.5, 0.022], [64572.9, 28.554]], "asks": [[64578.7, 0.088], [64584.6, 0.0], [64585.4, 0.553], [64593.5, 0.032], [64594.9, 0.573], [64595.3, 0.001], [64595.9, 0.303], [64596.2, 0.03], [64596.9, 0.927], [64598.8, 0.034], [64599.9, 0.558], [64600.8, 0.31], [64601.8, 0.116], [64601.9, 0.058], [64602.8, 0.008], [64713.2, 5.456], [64730.1, 10.432], [65218.7, 0.002], [65371.5, 0.764], [65509.3, 8.836], [65573.0, 0.0]]}
{"kind": "depth", "E": 1787089610111, "U": 11315997348932, "u": 11315997354745, "recv_ms": 1787089610070, "bids": [[14072.9, 2.674], [14172.9, 1.526], [51658.0, 0.0], [58115.6, 0.002], [61344.2, 0.005], [61989.9, 0.026], [63572.9, 0.02], [63590.1, 0.01], [63798.0, 11.792], [63927.2, 0.005], [64527.1, 0.073], [64531.5, 0.061], [64546.9, 0.146], [64547.3, 0.1], [64547.5, 0.201], [64547.6, 0.071], [64550.4, 0.114], [64550.9, 0.728], [64552.3, 2.95], [64554.6, 0.005], [64558.2, 0.335], [64559.6, 1.865], [64559.7, 0.644], [64560.4, 0.442], [64561.3, 0.001], [64566.7, 0.647], [64566.8, 0.009], [64568.4, 0.169], [64568.9, 0.001], [64570.1, 0.256], [64571.2, 0.035], [64572.9, 28.545]], "asks": [[64577.8, 0.098], [64579.3, 0.101], [64580.4, 0.098], [64582.8, 0.0], [64585.5, 0.002], [64588.1, 0.159], [64590.9, 0.619], [64591.0, 0.632], [64593.0, 0.003], [64593.1, 0.017], [64594.8, 0.009], [64595.7, 0.94], [64596.2, 0.022], [64603.1, 0.62], [64612.3, 10.079], [64617.1, 0.415], [64622.1, 0.0], [64630.5, 0.628], [64646.8, 0.859], [64646.9, 37.625], [64653.5, 0.041], [65218.7, 0.004], [65528.7, 2.288], [65555.8, 0.01], [65573.0, 0.02]]}
{"kind": "depth", "E": 1787089610213, "U": 11315997354794, "u": 11315997359115, "recv_ms": 1787089610171, "bids": [[1000.0, 35.76], [14072.9, 3.038], [14172.9, 1.162], [51658.0, 0.0], [58115.6, 0.002], [61989.9, 0.029], [63281.5, 0.028], [63590.1, 0.018], [63604.4, 0.001], [63927.2, 0.005], [64055.5, 7.326], [64250.0, 12.462], [64547.0, 0.165], [64547.1, 1.353], [64547.2, 0.106], [64554.6, 0.004], [64556.1, 0.005], [64558.2, 0.336]], "asks": [[64588.5, 2.598], [64646.9, 0.0], [64651.3, 37.632], [64895.9, 1.415], [65218.7, 0.002], [65497.5, 11.066], [65755.3, 0.0]]}
{"kind": "depth", "E": 1787089610315, "U": 11315997359163, "u": 11315997364767, "recv_ms": 1787089610274, "bids": [[14072.9, 3.388], [14172.9, 0.812], [51658.0, 0.0], [58115.6, 0.002], [61344.2, 0.005], [63927.2, 0.005], [64056.3, 2.51], [64250.0, 12.463], [64432.6, 0.009], [64505.7, 0.019], [64563.2, 0.396], [64564.8, 0.01], [64566.6, 0.465], [64566.7, 0.631], [64569.6, 1.0], [64572.9, 28.545]], "asks": [[64575.6, 1.816], [64588.1, 0.793], [64588.4, 2.152], [64590.9, 0.0], [64591.8, 0.005], [64593.1, 0.002], [64597.5, 0.682], [64646.9, 37.625], [64649.1, 0.0], [64651.3, 0.007], [64713.2, 0.048], [65218.7, 0.002], [65464.1, 1.535], [65555.7, 0.008], [65780.5, 0.607]]}
{"kind": "depth", "E": 1787089610417, "U": 11315997364926, "u": 11315997370859, "recv_ms": 1787089610383, "bids": [[14072.9, 3.71], [14172.9, 0.476], [14472.9, 0.014], [58115.6, 0.002], [61344.2, 0.005], [61989.9, 0.026], [63538.9, 6.134], [63572.9, 0.0], [63927.2, 0.007], [64415.7, 6.663], [64416.0, 1.263], [64432.6, 3.633], [64435.1, 1.424], [64505.2, 6.765], [64551.3, 0.181], [64552.3, 2.331], [64556.2, 6.916], [64556.8, 1.822], [64558.2, 0.335], [64559.7, 0.025], [64569.1, 0.005], [64572.9, 28.547]], "asks": [[64573.0, 0.643], [64575.9, 0.031], [64595.7, 0.321], [64603.1, 0.001], [64605.3, 1.514], [64646.8, 6.396], [64672.2, 1.029], [64711.9, 1.393], [64713.2, 5.456], [64729.6, 1.378], [64730.1, 10.432], [64895.9, 1.414], [65218.7, 0.002], [65330.1, 1.528], [65515.8, 0.305], [65573.0, 0.0]]}
{"kind": "depth", "E": 1787089610519, "U": 11315997370928, "u": 11315997376385, "recv_ms": 1787089610476, "bids": [[1000.0, 35.76], [14072.9, 3.71], [14172.9, 0.294], [14472.9, 0.196], [51658.3, 0.0], [58115.6, 0.002], [61989.9, 0.029], [63604.3, 0.022], [63927.2, 0.005], [64250.0, 12.464], [64533.3, 0.004], [64551.3, 0.18], [64565.4, 0.039], [64572.3, 0.001]], "asks": [[65163.1, 1.3], [65218.7, 0.002], [65548.0, 3.002]]}
{"kind": "depth", "E": 1787089610621, "U": 11315997376534, "u": 11315997380751, "recv_ms": 1787089610579, "bids": [[14072.9, 3.598], [14172.9, 0.168], [14472.9, 0.434], [58115.6, 0.002], [61344.2, 0.005], [61989.9, 0.026], [63179.4, 0.0], [63180.1, 0.002], [63281.5, 0.025], [63539.7, 3.3], [63572.9, 0.02], [63927.2, 0.005], [64565.4, 0.038], [64567.4, 0.008], [64568.4, 0.17], [64572.1, 0.023], [64572.9, 28.55]], "asks": [[64573.0, 0.653], [64586.0, 0.135], [65218.7, 0.002], [65341.4, 4.586], [65573.0, 0.02], [65643.6, 0.002], [67134.8, 0.0]]}
{"kind": "depth", "E": 1787089610723, "U": 11315997380801, "u": 11315997384978, "recv_ms": 1787089610681, "bids": [[14072.9, 3.472], [14172.9, 0.056], [14472.9, 0.672], [58115.6, 0.002], [61344.2, 0.005], [63797.2, 24.416], [63846.2, 5.0], [63927.2, 0.005], [64415.7, 7.544], [64432.6, 4.09], [64499.5, 0.031], [64504.1, 32.654], [64562.9, 1.247], [64568.4, 0.169], [64572.9, 28.549]], "asks": [[64583.9, 0.024], [64585.3, 0.0], [64599.1, 0.557], [64599.9, 0.001], [64612.5, 0.006], [64615.6, 0.0], [64713.2, 5.456], [64730.1, 10.432], [64768.9, 10.801], [65218.7, 0.002], [65670.7, 1.217]]}
{"kind": "depth", "E": 1787089610825, "U": 11315997385134, "u": 11315997389540, "recv_ms": 1787089610783, "bids": [[1000.0, 35.76], [14072.9, 3.22], [14172.9, 0.0], [14472.9, 0.98], [58115.6, 0.002], [61989.9, 0.029], [63572.9, 0.0], [63790.1, 0.783], [63869.1, 1.676], [63927.2, 0.005], [64250.0, 12.464], [64432.6, 0.009], [64435.1, 0.986], [64562.9, 1.246], [64567.1, 0.002]], "asks": [[64575.3, 0.001], [64575.5, 0.287], [64577.8, 0.014], [64711.9, 0.672], [64713.2, 0.048], [65218.7, 0.002], [65285.5, 0.862], [65388.0, 9.22], [65541.6, 2.621], [65573.0, 0.0], [65864.4, 0.021]]}
{"kind": "depth", "E": 1787089611029, "U": 11315997400013, "u": 11315997408965, "recv_ms": 1787089610987, "bids": [[14072.9, 2.506], [14472.9, 1.694], [58115.6, 0.002], [61344.2, 0.006], [61344.3, 0.01], [61989.9, 0.029], [63572.9, 0.02], [63798.0, 12.574], [63927.2, 0.005], [63991.1, 0.34], [64432.6, 4.114], [64467.1, 0.005], [64468.6, 2.357], [64540.1, 0.314], [64540.2, 0.11], [64540.3, 0.002], [64543.6, 0.033], [64543.7, 0.066], [64543.8, 1.088]], "asks": [[64573.0, 0.653], [64654.7, 0.014], [64655.1, 0.07], [64661.8, 0.068], [64662.2, 0.0], [64668.9, 0.014], [64669.3, 0.0], [64675.9, 0.013], [64676.3, 0.2], [64681.2, 0.0], [64683.0, 0.013], [64683.4, 0.001], [64685.4, 8.269], [64713.2, 5.456], [64768.9, 10.652], [65218.7, 0.002], [65561.5, 0.013], [65573.0, 0.02], [71030.3, 0.0]]}
{"kind": "depth", "E": 1787089611131, "U": 11315997409022, "u": 11315997416093, "recv_ms": 1787089611090, "bids": [[1000.0, 35.76], [14072.9, 2.156], [14472.9, 2.044], [34000.0, 1.146], [58115.6, 0.002], [61344.2, 0.005], [61989.9, 0.026], [63571.2, 8.651], [63635.8, 12.676], [63927.2, 0.005], [64250.0, 12.454], [64450.7, 3.047], [64469.4, 0.0], [64469.5, 0.005], [64495.4, 1.983], [64521.2, 0.549], [64552.5, 1.062], [64559.9, 0.623], [64561.3, 0.001], [64572.9, 28.551]], "asks": [[64573.0, 0.646], [64575.6, 1.802], [64583.7, 2.6], [64585.3, 0.001], [64589.8, 0.463], [64590.8, 0.008], [64595.9, 0.922], [64597.1, 0.554], [64603.3, 0.658], [64650.5, 0.631], [64690.0, 0.058], [64690.4, 0.033], [64697.1, 0.025], [64697.5, 0.092], [64704.1, 1.063], [64704.5, 0.093], [65218.7, 0.002]]}
{"kind": "depth", "E": 1787089611233, "U": 11315997416164, "u": 11315997421263, "recv_ms": 1787089611193, "bids": [[14072.9, 1.82], [14472.9, 2.38], [58115.6, 0.002], [61344.2, 0.005], [61344.3, 0.012], [62435.8, 1.439], [63281.5, 0.019], [63572.0, 6.44], [63572.9, 0.0], [63636.6, 13.814], [63927.2, 0.005], [64250.0, 12.453], [64432.6, 4.114], [64499.5, 0.013], [64501.6, 0.004], [64544.7, 0.0], [64551.9, 0.091], [64552.5, 0.443], [64556.1, 0.005], [64559.9, 0.004], [64563.4, 0.68], [64566.0, 0.398], [64572.9, 28.551]], "asks": [[64573.0, 0.571], [64588.5, 2.598], [64595.9, 0.303], [64603.3, 0.039], [64606.9, 0.014], [64713.2, 5.456], [65218.7, 0.004], [65347.9, 9.845], [65357.5, 4.25], [65467.2, 1.37], [65573.0, 0.0], [65573.9, 5.181], [65864.4, 0.018]]}
{"kind": "depth", "E": 1787089611437, "U": 11315997425921, "u": 11315997432783, "recv_ms": 1787089611398, "bids": [[1000.0, 35.76], [14072.9, 1.092], [14472.9, 3.108], [51658.3, 0.0], [58115.6, 0.002], [61344.2, 0.005], [61344.3, 0.01], [61344.4, 0.008], [61989.9, 0.026], [63341.0, 0.0], [63572.9, 0.02], [63624.6, 1.106], [63927.2, 0.005], [64205.0, 0.013], [64206.8, 1.417], [64301.5, 0.0], [64302.5, 1.087], [64372.3, 0.003], [64373.5, 0.802], [64415.6, 6.576], [64415.7, 0.134], [64416.0, 2.17], [64432.6, 3.655], [64495.4, 6.608], [64505.7, 0.001], [64516.6, 0.221], [64556.2, 6.918], [64557.5, 2.32], [64572.9, 28.55]], "asks": [[64573.0, 0.568], [64602.8, 0.575], [64611.0, 4.085], [64612.3, 10.081], [64713.2, 5.456], [64729.6, 2.756], [64730.1, 10.432], [64772.2, 1.397], [64774.0, 0.008], [64845.1, 0.189], [64845.2, 0.002], [64941.5, 0.112], [64942.5, 0.0], [65218.7, 0.002], [65573.0, 0.02]]}
{"kind": "depth", "E": 1787089611539, "U": 11315997432795, "u": 11315997439625, "recv_ms": 1787089611500, "bids": [[14072.9, 0.728], [14472.9, 3.472], [58115.6, 0.002], [61989.9, 0.029], [62946.7, 0.0], [63636.6, 14.912], [63675.1, 0.0], [63770.2, 0.015], [63854.7, 2.346], [63927.2, 0.005], [63942.0, 2.478], [64250.0, 12.462], [64363.0, 5.331], [64372.4, 0.005], [64451.8, 1.676], [64463.1, 0.004], [64476.0, 0.073], [64495.3, 0.01], [64495.4, 1.983], [64504.1, 32.824], [64572.9, 28.561]], "asks": [[64682.8, 0.003], [64773.9, 0.003], [64803.7, 7.934], [65210.2, 1.22], [65218.7, 0.002], [65270.4, 0.765], [65350.7, 4.685], [67155.9, 1.911]]}
{"kind": "depth", "E": 1787089611641, "U": 11315997439648, "u": 11315997448684, "recv_ms": 1787089611601, "bids": [[1000.0, 35.76], [14072.9, 0.42], [14372.9, 0.042], [14472.9, 3.738], [58115.6, 0.002], [61344.2, 0.005], [61344.3, 0.008], [61344.4, 0.01], [61989.9, 0.026], [63572.9, 0.0], [63636.6, 16.011], [63642.8, 0.01], [63927.2, 0.005], [63936.6, 2.886], [64089.4, 0.0], [64207.5, 41.555], [64250.0, 12.462], [64303.9, 34.143], [64374.7, 26.607], [64538.1, 0.443], [64572.9, 28.565]], "asks": [[64590.2, 0.334], [64778.9, 26.979], [64850.2, 34.185], [64895.9, 1.416], [64947.5, 40.909], [65059.4, 0.0], [65218.7, 0.002], [65573.0, 0.0], [65711.8, 0.884], [65916.6, 0.153]]}
{"kind": "depth", "E": 1787089611743, "U": 11315997448857, "u": 11315997456795, "recv_ms": 1787089611703, "bids": [[1000.0, 35.76], [14072.9, 0.266], [14372.9, 0.252], [14472.9, 3.682], [58115.6, 0.002], [63636.6, 16.796], [63927.2, 0.007], [63944.5, 66.941], [64206.8, 0.008], [64207.6, 7.562], [64249.2, 3.807], [64302.5, 0.007], [64304.0, 6.397], [64377.2, 5.283], [64478.4, 0.436], [64481.0, 0.031], [64501.4, 0.027], [64505.0, 0.442], [64522.0, 0.163], [64530.0, 0.242], [64561.1, 2.01], [64570.1, 1.804], [64571.1, 0.009], [64572.9, 31.519]], "asks": [[64576.9, 1.724], [64578.7, 0.004], [64579.3, 0.093], [64580.4, 0.095], [64588.1, 0.777], [64592.4, 0.671], [64594.7, 0.001], [64594.8, 0.001], [64595.0, 1.477], [64617.8, 5.086], [64643.1, 0.028], [64646.7, 0.021], [64713.2, 0.048], [64947.4, 11.305], [64947.9, 0.0], [65214.0, 66.906], [65218.7, 0.002], [65340.6, 4.433], [65380.2, 2.837]]}
{"kind": "depth", "E": 1787089611845, "U": 11315997456864, "u": 11315997491480, "recv_ms": 1787089611809, "bids": [[14072.9, 0.14], [14372.9, 0.476], [14472.9, 3.584], [58115.6, 0.002], [61344.2, 0.005], [61989.9, 0.029], [63281.5, 0.019], [63386.2, 4.411], [63572.9, 0.02], [63656.9, 0.001], [63927.2, 0.005], [63959.5, 4.802], [64363.0, 5.115], [64367.3, 1.377], [64374.8, 0.217], [64393.8, 0.07], [64415.6, 5.716], [64432.6, 3.209], [64477.4, 0.004], [64478.4, 0.431], [64479.2, 0.001], [64479.4, 0.008], [64483.9, 2.532], [64485.8, 2.667], [64487.2, 0.0], [64490.3, 2.319], [64492.3, 0.036], [64493.6, 0.475], [64494.7, 0.062], [64495.3, 0.01], [64495.5, 0.337], [64498.7, 0.028], [64500.1, 0.003], [64501.4, 0.001], [64501.9, 32.885], [64502.0, 4.866], [64503.3, 0.345], [64503.6, 0.0], [64504.0, 0.45], [64504.1, 0.049], [64505.0, 0.442], [64505.2, 2.209], [64506.1, 0.029], [64506.5, 0.0], [64508.3, 0.122], [64508.4, 0.031], [64511.7, 0.039], [64513.0, 0.228], [64514.9, 0.027], [64521.3, 0.044], [64522.7, 0.226], [64530.0, 0.032], [64533.0, 0.028], [64535.4, 0.002], [64539.9, 0.004], [64540.0, 0.149], [64542.0, 0.02], [64542.6, 0.001], [64544.8, 0.002], [64545.1, 0.0], [64546.6, 0.001], [64546.9, 0.146], [64548.0, 1.243], [64548.8, 0.603], [64549.9, 1.68], [64550.4, 0.119], [64551.7, 0.002], [64551.9, 0.001], [64553.5, 0.314], [64553.6, 0.099], [64553.9, 0.05], [64554.1, 0.856], [64554.7, 0.054], [64556.2, 0.003], [64556.5, 0.003], [64556.7, 0.098], [64556.8, 1.03], [64557.6, 0.001], [64558.1, 0.116], [64558.4, 0.35], [64559.0, 0.559], [64559.8, 0.0], [64560.1, 0.006], [64561.1, 0.01], [64563.2, 0.388], [64563.7, 0.0], [64564.3, 0.927], [64565.1, 0.053], [64565.2, 6.917], [64565.3, 0.001], [64565.4, 0.131], [64566.4, 1.929], [64566.5, 0.01], [64568.4, 0.009], [64569.6, 0.782], [64569.7, 0.174], [64570.0, 1.405], [64570.2, 0.178], [64571.1, 0.001], [64572.9, 31.061]], "asks": [[64573.0, 0.564], [64575.5, 0.005], [64576.1, 0.002], [64576.3, 0.01], [64576.8, 0.002], [64579.0, 0.016], [64579.2, 0.024], [64579.3, 0.101], [64579.6, 0.311], [64579.7, 0.002], [64580.0, 0.045], [64580.1, 0.001], [64580.4, 0.095], [64580.5, 6.795], [64582.8, 0.084], [64583.2, 0.091], [64583.6, 0.087], [64583.7, 2.581], [64583.9, 0.084], [64585.3, 0.0], [64585.4, 0.393], [64585.7, 0.002], [64586.0, 0.172], [64586.1, 0.093], [64586.8, 0.001], [64587.0, 0.087], [64587.3, 0.7], [64588.1, 0.159], [64588.4, 0.756], [64589.8, 0.443], [64589.9, 0.342], [64590.0, 1.253], [64591.0, 0.012], [64591.2, 0.86], [64592.2, 0.569], [64592.4, 0.666], [64593.2, 0.001], [64593.4, 0.006], [64593.7, 0.018], [64594.8, 0.009], [64596.9, 0.0], [64597.5, 1.569], [64597.6, 0.028], [64599.1, 0.0], [64599.5, 0.019], [64599.6, 0.22], [64599.7, 1.744], [64599.9, 0.033], [64600.1, 0.008], [64600.4, 0.557], [64600.5, 0.036], [64600.6, 0.04], [64602.1, 0.019], [64604.6, 0.093], [64606.3, 0.093], [64607.7, 0.53], [64607.9, 0.005], [64608.7, 0.024], [64610.4, 0.403], [64611.4, 0.254], [64611.5, 0.016], [64612.3, 0.081], [64614.9, 0.0], [64615.5, 0.311], [64615.6, 0.0], [64616.1, 0.072], [64617.7, 1.34], [64617.8, 0.001], [64619.0, 0.001], [64621.0, 4.596], [64621.1, 10.389], [64621.2, 0.001], [64622.7, 0.003], [64623.5, 0.081], [64625.9, 0.668], [64629.7, 0.027], [64637.6, 2.622], [64638.6, 0.0], [64639.9, 0.356], [64643.1, 0.002], [64645.3, 0.028], [64645.7, 0.0], [64646.7, 0.021], [64646.8, 0.859], [64646.9, 0.0], [64647.2, 0.001], [64647.8, 0.494], [64649.1, 37.23], [64651.3, 0.007], [64653.4, 6.31], [64653.5, 0.041], [64713.2, 5.456], [64730.1, 10.432], [64778.8, 0.216], [64803.7, 7.718], [65218.7, 0.002], [65573.0, 0.02], [65864.4, 0.03]]}
{"kind": "depth", "E": 1787089611947, "U": 11315997491522, "u": 11315997503239, "recv_ms": 1787089611905, "bids": [[1000.0, 35.76], [14072.9, 0.028], [14372.9, 0.728], [14472.9, 3.444], [58115.6, 0.002], [61344.2, 0.005], [61989.9, 0.026], [63281.5, 0.025], [63410.6, 1.419], [63927.2, 0.005], [64091.5, 53.125], [64250.0, 13.084], [64564.6, 0.002], [64564.8, 0.002], [64565.2, 6.919], [64566.8, 0.017], [64569.5, 0.301], [64570.0, 1.405], [64570.1, 0.256], [64571.1, 0.001], [64571.2, 0.035], [64571.3, 1.652], [64572.9, 28.872]], "asks": [[64579.6, 0.001], [64580.0, 0.355], [64585.4, 0.313], [64586.6, 0.31], [64589.0, 0.011], [64592.2, 0.609], [64593.3, 0.13], [64600.5, 0.001], [64600.6, 0.0], [64602.2, 0.0], [64605.7, 1.955], [64605.8, 0.001], [64608.3, 1.682], [64611.0, 4.087], [64612.3, 0.079], [64615.5, 0.262], [64624.6, 0.023], [64626.8, 0.0], [64632.7, 0.21], [64639.9, 0.146], [64653.4, 0.83], [65063.2, 53.201], [65218.7, 0.002], [65253.5, 4.143], [65341.4, 5.503], [65454.3, 5.859], [65549.5, 1.524]]}
{"kind": "depth", "E": 1787089612049, "U": 11315997503487, "u": 11315997515052, "recv_ms": 1787089612011, "bids": [[1000.0, 35.76], [14072.9, 0.0], [14372.9, 1.05], [14472.9, 3.15], [58115.6, 0.002], [61344.2, 0.005], [61989.9, 0.029], [63572.9, 0.0], [63927.2, 0.007], [64533.0, 0.003], [64540.2, 0.135], [64561.3, 0.006], [64561.9, 0.702], [64568.1, 0.001], [64569.3, 0.393], [64569.5, 0.301], [64569.6, 0.844], [64570.0, 1.343], [64570.1, 0.256], [64570.2, 0.17], [64571.2, 0.035], [64571.3, 0.104], [64571.4, 1.552], [64571.5, 0.008], [64572.8, 0.415], [64572.9, 30.692], [64573.8, 3.894]], "asks": [[64573.0, 0.0], [64573.1, 0.0], [64573.3, 0.0], [64573.4, 0.0], [64579.3, 0.093], [64579.7, 0.002], [64580.0, 0.045], [64580.4, 0.103], [64584.4, 0.005], [64586.4, 0.14], [64588.1, 0.151], [64589.0, 0.008], [64590.7, 0.32], [64602.2, 0.0], [64609.0, 2.319], [64616.3, 0.0], [64622.5, 0.118], [64629.7, 0.002], [64691.1, 0.0], [64691.6, 0.193], [65218.7, 0.002], [65222.0, 8.285], [65276.8, 0.842], [65484.9, 0.763], [65573.0, 0.0], [66988.0, 0.575], [67088.0, 1.777], [67155.0, 0.182]]}
