{"kind": "depth", "E": 1787089560641, "U": 11315993543697, "u": 11315993558856, "recv_ms": 1787089560609, "bids": [[1000.0, 35.76], [14172.1, 1.722], [14272.1, 2.478], [51658.0, 0.0], [58114.8, 0.067], [61343.4, 0.0], [61989.2, 0.003], [63280.7, 0.017], [63926.4, 0.003], [64249.2, 2.342], [64432.1, 3.536], [64495.3, 0.011], [64501.9, 31.336], [64532.7, 0.0], [64544.5, 0.088], [64545.6, 3.166], [64551.9, 0.001], [64559.7, 0.009], [64560.1, 0.474], [64560.2, 0.011], [64561.9, 0.666], [64565.9, 0.156], [64566.2, 0.031], [64566.9, 0.238], [64568.1, 0.001], [64571.4, 0.003], [64572.1, 24.78]], "asks": [[64572.2, 0.281], [64572.8, 1.395], [64572.9, 0.003], [64575.9, 0.015], [64576.0, 1.102], [64577.3, 0.084], [64579.9, 0.807], [64587.9, 0.38], [64595.2, 0.174], [64601.7, 1.56], [64712.9, 6.624], [64827.9, 0.11], [64895.1, 2.465], [65217.9, 0.0], [65443.9, 1.069], [65605.4, 1.066], [66500.2, 0.039], [67800.8, 0.035], [71933.4, 0.117]]}
{"kind": "depth", "E": 1787089560743, "U": 11315993558989, "u": 11315993566994, "recv_ms": 1787089560702, "bids": [[1000.0, 35.76], [14172.1, 2.086], [14272.1, 2.114], [58114.8, 0.067], [61343.5, 0.012], [61343.6, 0.003], [61989.2, 0.0], [63065.0, 0.022], [63572.1, 0.018], [63603.6, 0.021], [63678.6, 0.004], [63789.4, 9.68], [63926.4, 0.003], [64249.2, 2.497], [64555.3, 0.007], [64559.7, 0.009], [64560.1, 1.016], [64560.2, 0.011], [64561.9, 0.124]], "asks": [[64572.7, 0.0], [64572.8, 1.395], [64574.5, 0.004], [64574.6, 0.472], [64575.8, 0.008], [64575.9, 1.711], [64577.3, 0.084], [64580.0, 0.124], [64580.6, 41.802], [64587.7, 2.326], [64895.1, 2.464], [65217.9, 0.0], [65572.2, 0.002]]}
{"kind": "depth", "E": 1787089560845, "U": 11315993567205, "u": 11315993574943, "recv_ms": 1787089560804, "bids": [[14172.1, 2.436], [14272.1, 1.764], [51657.7, 0.0], [58114.8, 0.067], [61343.4, 0.0], [61989.2, 0.003], [63641.2, 3.14], [63730.0, 3.414], [63782.3, 1.981], [63926.4, 0.003], [63958.1, 0.0], [64249.2, 2.498], [64432.1, 0.022], [64507.5, 0.326], [64510.6, 1.12], [64523.8, 3.766], [64566.9, 0.238], [64572.1, 24.776]], "asks": [[64572.7, 0.0], [64572.8, 0.002], [64572.9, 1.396], [64608.1, 4.93], [64616.2, 0.17], [64620.6, 5.019], [64634.2, 0.696], [64636.8, 0.003], [64659.8, 7.614], [64660.1, 0.013], [64668.9, 37.141], [64712.9, 1.215], [64768.4, 3.562], [65132.9, 0.001], [65217.9, 0.0], [65484.1, 4.883], [65486.6, 5.604]]}
{"kind": "depth", "E": 1787089560947, "U": 11315993574987, "u": 11315993583759, "recv_ms": 1787089560906, "bids": [[1000.0, 35.76], [14172.1, 2.8], [14272.1, 1.4], [58114.8, 0.067], [63280.7, 0.02], [63572.1, 0.038], [63907.1, 0.382], [63926.4, 0.003], [64231.3, 0.06], [64231.5, 0.498], [64249.2, 2.498], [64495.3, 0.011], [64499.7, 30.897], [64501.9, 0.077], [64523.8, 5.02], [64548.0, 1.368], [64548.5, 0.154], [64565.8, 0.002], [64566.2, 1.579], [64569.7, 0.311], [64570.9, 0.0], [64571.2, 0.16]], "asks": [[64572.8, 1.395], [64572.9, 0.003], [64580.0, 0.123], [64580.4, 0.035], [64596.1, 0.56], [64596.9, 0.0], [64597.5, 0.15], [64598.4, 2.571], [64659.8, 2.299], [64662.3, 37.186], [64668.9, 0.001], [65217.9, 0.0], [65264.5, 1.223], [65295.4, 0.194], [65572.2, 0.022]]}
{"kind": "depth", "E": 1787089561049, "U": 11315993583873, "u": 11315993592512, "recv_ms": 1787089561007, "bids": [[1000.0, 35.76], [14172.1, 3.15], [14272.1, 1.05], [58114.8, 0.067], [61343.4, 0.0], [61989.2, 0.0], [63226.0, 0.056], [63705.7, 12.545], [63728.6, 1.097], [63764.9, 1.085], [63926.4, 0.003], [63983.8, 0.468], [64034.1, 0.0], [64055.5, 3.899], [64376.4, 6.482], [64415.2, 7.127], [64416.0, 1.263], [64432.1, 4.058], [64526.7, 0.032], [64538.6, 0.011], [64539.1, 0.012], [64539.3, 0.007], [64539.4, 0.007], [64539.5, 0.006], [64542.8, 0.008], [64542.9, 0.392], [64543.0, 0.022], [64548.3, 0.154], [64548.5, 0.0], [64560.0, 0.354], [64560.1, 1.016], [64560.2, 0.011], [64560.4, 0.941], [64560.5, 0.007], [64566.8, 0.001], [64572.1, 24.779]], "asks": [[64572.2, 0.281], [64572.7, 1.393], [64572.8, 0.002], [64577.4, 1.819], [64580.0, 0.123], [64580.4, 0.035], [64592.5, 0.001], [64592.8, 1.185], [64594.9, 1.283], [64597.0, 0.111], [64597.1, 0.314], [64597.3, 0.067], [64598.1, 0.582], [64607.5, 0.021], [64613.6, 0.033], [64712.9, 6.624], [64729.6, 1.378], [64729.9, 10.456], [64755.6, 4.691], [64768.4, 2.272], [64768.6, 10.859], [65153.9, 1.072], [65217.9, 0.0], [65325.2, 9.143], [65486.6, 4.537]]}
{"kind": "depth", "E": 1787089561151, "U": 11315993592542, "u": 11315993599651, "recv_ms": 1787089561110, "bids": [[14172.1, 3.514], [14272.1, 0.686], [58114.8, 0.067], [61343.4, 0.001], [61989.2, 0.003], [63572.1, 0.018], [63782.3, 1.042], [63803.7, 3.208], [63926.4, 1.408], [64545.4, 0.003], [64545.5, 0.078], [64545.7, 0.0], [64559.7, 0.017], [64560.1, 1.401], [64560.2, 0.545], [64560.4, 0.014], [64560.5, 0.002], [64560.6, 0.021], [64560.7, 0.017], [64561.9, 0.124], [64566.8, 0.001], [64571.4, 0.003], [64572.1, 24.78]], "asks": [[64572.7, 1.393], [64572.8, 0.002], [64580.0, 0.124], [64580.4, 0.034], [64585.5, 0.01], [64597.3, 0.01], [64597.5, 0.207], [65217.9, 0.0], [65347.1, 11.041], [65508.5, 9.602], [65551.1, 4.115], [65572.2, 0.002]]}
{"kind": "depth", "E": 1787089561253, "U": 11315993599950, "u": 11315993607839, "recv_ms": 1787089561210, "bids": [[1000.0, 35.76], [14072.1, 0.056], [14172.1, 3.752], [14272.1, 0.392], [51658.0, 0.0], [58114.8, 0.067], [61343.4, 0.0], [61989.2, 0.0], [62596.7, 1.0], [63242.0, 0.921], [63926.4, 1.408], [64240.6, 0.0], [64249.2, 2.498], [64250.9, 0.108], [64432.1, 0.022], [64544.2, 0.001], [64551.4, 0.05], [64559.7, 0.009], [64560.4, 0.022], [64566.8, 0.001], [64572.1, 24.78]], "asks": [[64572.7, 1.393], [64572.8, 0.002], [64712.9, 1.215], [64893.4, 0.0], [64908.3, 0.113], [65217.9, 0.0], [65276.0, 1.541], [67800.8, 0.04]]}
{"kind": "depth", "E": 1787089561355, "U": 11315993607843, "u": 11315993616486, "recv_ms": 1787089561314, "bids": [[1000.0, 35.76], [14072.1, 0.28], [14172.1, 3.668], [14272.1, 0.252], [51658.0, 0.002], [58114.8, 0.067], [61343.4, 0.0], [61951.4, 2.002], [63387.0, 0.0], [63572.1, 0.038], [63723.7, 0.345], [63780.2, 7.187], [63803.7, 4.147], [63926.4, 1.408], [64038.5, 0.311], [64055.5, 4.21], [64232.1, 0.001], [64415.2, 0.002], [64530.6, 0.005], [64539.1, 0.008], [64548.2, 0.154], [64548.3, 0.0], [64559.7, 0.009], [64560.2, 0.003], [64560.4, 0.022], [64561.9, 0.666], [64566.8, 0.001], [64571.4, 0.008], [64572.1, 24.782]], "asks": [[64572.7, 0.0], [64572.8, 1.395], [64580.0, 0.123], [64580.4, 0.035], [64729.9, 0.028], [64906.4, 0.084], [65217.9, 0.0], [65329.7, 3.272], [65508.5, 10.669], [65572.2, 0.022], [65573.1, 5.33], [65863.6, 0.024]]}
{"kind": "depth", "E": 1787089561457, "U": 11315993616681, "u": 11315993626046, "recv_ms": 1787089561417, "bids": [[14072.1, 0.518], [14172.1, 3.556], [14272.1, 0.126], [51658.0, 0.0], [58114.8, 0.067], [60660.7, 4.0], [61306.1, 3.017], [61343.4, 0.0], [61989.2, 0.003], [63926.4, 1.408], [64249.2, 3.944], [64249.6, 0.7], [64376.4, 6.454], [64415.2, 7.103], [64432.1, 4.047], [64530.6, 0.001], [64548.2, 0.0], [64548.4, 0.469], [64559.7, 0.009], [64560.2, 0.003], [64560.4, 0.014], [64561.9, 0.666], [64566.8, 0.005], [64571.4, 0.003], [64572.1, 24.785]], "asks": [[64572.7, 0.0], [64572.8, 0.002], [64577.3, 0.084], [64577.8, 0.069], [64580.0, 0.123], [64580.4, 0.035], [64580.5, 6.779], [64587.5, 0.092], [64589.9, 0.009], [64712.9, 6.624], [64729.8, 10.431], [64768.6, 10.921], [64873.4, 0.0], [65217.9, 0.002]]}
{"kind": "depth", "E": 1787089561559, "U": 11315993626070, "u": 11315993634371, "recv_ms": 1787089561517, "bids": [[1000.0, 35.76], [14072.1, 0.756], [14172.1, 3.43], [14272.1, 0.014], [58114.8, 0.067], [61343.4, 0.0], [61989.2, 0.0], [63572.1, 0.018], [63926.4, 1.408], [64055.5, 4.833], [64249.2, 4.333], [64432.1, 4.058], [64513.9, 0.05], [64520.4, 0.003], [64539.4, 0.011], [64548.4, 0.469], [64559.7, 0.009], [64560.2, 0.545], [64560.4, 0.022], [64561.9, 0.124], [64566.8, 0.001], [64572.1, 24.786]], "asks": [[64572.2, 0.312], [64572.7, 1.393], [64572.8, 0.002], [64580.0, 0.124], [64580.4, 0.034], [64580.5, 6.872], [64587.5, 0.007], [64589.9, 0.001], [64630.4, 1.237], [64712.9, 6.624], [64768.6, 10.859], [65217.9, 0.0], [65335.1, 4.586], [65347.1, 11.499], [65532.7, 0.0], [65572.2, 0.002], [65863.6, 0.027]]}
{"kind": "depth", "E": 1787089561661, "U": 11315993634475, "u": 11315993659546, "recv_ms": 1787089561619, "bids": [[1000.0, 35.76], [14072.1, 1.092], [14172.1, 3.108], [14272.1, 0.0], [58114.8, 0.067], [61343.4, 0.0], [61989.2, 0.003], [63280.7, 0.017], [63548.0, 0.005], [63661.6, 0.943], [63705.7, 11.761], [63797.2, 8.782], [63926.4, 1.408], [64249.2, 4.332], [64363.3, 0.077], [64363.4, 0.077], [64364.4, 0.238], [64364.5, 0.161], [64364.6, 0.0], [64481.2, 0.008], [64481.9, 0.001], [64490.4, 0.003], [64496.9, 0.001], [64497.5, 0.088], [64498.1, 0.049], [64498.8, 0.28], [64499.3, 0.0], [64499.7, 30.897], [64501.7, 0.063], [64502.3, 0.029], [64504.1, 0.043], [64511.5, 0.329], [64524.2, 0.422], [64527.6, 0.005], [64528.1, 0.097], [64528.4, 0.12], [64528.5, 0.014], [64530.1, 0.052], [64531.9, 3.018], [64532.0, 2.109], [64534.5, 0.001], [64536.7, 0.0], [64537.1, 0.216], [64538.3, 0.005], [64540.2, 0.11], [64541.4, 0.012], [64543.0, 0.021], [64544.0, 0.007], [64544.5, 0.018], [64545.0, 0.072], [64545.5, 0.021], [64545.6, 3.046], [64546.3, 0.151], [64546.9, 0.006], [64548.0, 1.522], [64548.3, 0.0], [64548.4, 0.315], [64548.5, 0.008], [64550.0, 0.029], [64550.7, 0.001], [64550.8, 0.0], [64551.4, 0.001], [64551.9, 0.009], [64552.1, 0.08], [64552.8, 0.003], [64553.9, 0.0], [64554.3, 0.117], [64554.7, 0.005], [64555.0, 0.099], [64555.1, 0.002], [64555.2, 0.006], [64555.5, 0.04], [64556.0, 0.003], [64556.2, 0.001], [64557.3, 0.002], [64557.6, 0.008], [64558.3, 0.231], [64558.6, 0.007], [64559.1, 0.011], [64559.3, 0.007], [64559.4, 0.022], [64559.8, 0.927], [64560.1, 0.474], [64560.2, 0.003], [64560.3, 1.009], [64560.4, 0.456], [64560.5, 0.018], [64561.8, 2.32], [64561.9, 0.124], [64562.0, 0.078], [64562.1, 0.015], [64562.5, 0.466], [64562.7, 0.001], [64562.9, 0.0], [64563.0, 0.0], [64563.1, 0.001], [64563.4, 0.071], [64563.5, 0.311], [64563.8, 0.008], [64564.4, 0.083], [64564.5, 0.203], [64565.1, 0.071], [64565.2, 0.001], [64565.3, 0.119], [64565.4, 1.872], [64565.6, 0.342], [64565.7, 0.032], [64565.8, 0.025], [64565.9, 0.904], [64566.0, 0.241], [64566.1, 0.019], [64566.2, 0.001], [64566.3, 0.117], [64566.4, 0.007], [64566.5, 0.002], [64566.7, 0.72], [64567.3, 0.021], [64567.4, 0.002], [64568.0, 0.087], [64568.1, 0.154], [64568.5, 0.085], [64568.6, 0.001], [64569.0, 0.001], [64569.3, 0.0], [64569.6, 0.001], [64569.7, 0.001], [64569.8, 0.002], [64570.3, 0.0], [64570.5, 0.0], [64570.6, 0.002], [64570.7, 0.131], [64571.1, 0.0], [64571.2, 0.03], [64571.5, 0.054], [64571.6, 0.003], [64571.8, 0.001], [64571.9, 0.007], [64572.0, 0.011], [64572.1, 10.76]], "asks": [[64572.2, 0.377], [64572.3, 1.395], [64572.7, 0.0], [64572.8, 0.003], [64573.4, 0.916], [64573.5, 1.801], [64573.6, 0.001], [64573.9, 0.085], [64574.1, 0.093], [64574.4, 0.088], [64574.5, 0.003], [64574.6, 0.503], [64574.8, 0.002], [64574.9, 0.086], [64575.7, 0.086], [64575.8, 0.018], [64576.0, 1.412], [64576.1, 0.085], [64576.5, 0.086], [64576.8, 0.005], [64576.9, 0.085], [64577.2, 0.008], [64577.3, 2.395], [64577.4, 0.089], [64577.9, 0.005], [64578.0, 2.588], [64578.1, 0.025], [64579.1, 0.0], [64579.5, 0.001], [64579.8, 0.47], [64579.9, 0.723], [64580.0, 0.123], [64580.1, 0.313], [64580.2, 0.002], [64580.3, 2.403], [64580.4, 0.034], [64580.5, 8.016], [64580.6, 41.718], [64581.0, 0.134], [64581.3, 0.467], [64584.0, 2.332], [64584.7, 10.0], [64585.2, 2.258], [64585.5, 0.009], [64586.2, 0.06], [64589.3, 1.105], [64590.8, 0.008], [64591.1, 0.0], [64591.3, 0.145], [64592.2, 1.237], [64592.8, 0.258], [64593.3, 0.095], [64594.3, 0.052], [64594.6, 0.0], [64594.9, 1.281], [64595.2, 0.178], [64595.8, 0.48], [64595.9, 0.296], [64596.5, 0.147], [64599.0, 4.124], [64599.2, 0.0], [64600.7, 0.28], [64602.0, 0.02], [64603.0, 0.036], [64605.3, 0.956], [64607.8, 0.16], [64608.1, 0.084], [64608.3, 0.98], [64610.5, 0.003], [64613.1, 0.598], [64614.9, 0.0], [64615.0, 0.002], [64619.1, 2.319], [64620.3, 0.024], [64624.9, 0.025], [64626.4, 0.014], [64627.6, 0.006], [64628.4, 0.001], [64635.8, 0.0], [64638.4, 0.652], [64638.6, 0.0], [64639.4, 0.216], [64639.8, 0.004], [64640.5, 0.126], [64641.0, 0.066], [64643.4, 3.293], [64895.1, 2.465], [65217.9, 0.0], [65682.4, 2.433], [67800.8, 0.045]]}
{"kind": "depth", "E": 1787089561763, "U": 11315993659632, "u": 11315993675469, "recv_ms": 1787089561722, "bids": [[14072.1, 1.456], [14172.1, 2.744], [58114.8, 0.067], [61343.4, 0.001], [61989.2, 0.0], [63572.1, 0.038], [63926.4, 1.408], [64249.2, 4.322], [64524.2, 0.352], [64528.5, 0.052], [64530.1, 0.003], [64531.6, 0.822], [64531.9, 2.968], [64535.8, 6.916], [64537.1, 0.126], [64537.4, 0.377], [64537.7, 0.001], [64539.5, 0.056], [64544.3, 0.099], [64546.3, 0.116], [64554.8, 0.466], [64555.1, 0.037], [64555.3, 0.007], [64560.0, 0.353], [64560.2, 0.096], [64560.5, 0.002], [64562.0, 0.001], [64562.1, 0.0], [64562.9, 1.245], [64563.2, 0.253], [64563.6, 0.005], [64564.7, 0.381], [64565.5, 2.319], [64565.6, 0.38], [64566.0, 0.249], [64566.1, 0.669], [64566.2, 0.005], [64567.3, 0.144], [64570.8, 0.046], [64572.0, 0.012], [64572.1, 10.757]], "asks": [[64572.2, 0.361], [64572.3, 1.395], [64573.3, 0.0], [64573.4, 0.095], [64574.1, 0.0], [64574.6, 0.012], [64574.8, 0.196], [64575.2, 0.002], [64575.8, 0.018], [64577.1, 0.054], [64577.2, 0.0], [64577.3, 2.323], [64578.0, 2.587], [64578.1, 0.006], [64578.2, 0.005], [64579.4, 0.038], [64579.7, 0.681], [64579.8, 0.454], [64579.9, 0.833], [64580.0, 0.132], [64580.2, 0.018], [64580.5, 6.779], [64587.7, 2.326], [64590.1, 0.367], [64590.8, 0.0], [64591.2, 0.242], [64597.5, 0.187], [64598.5, 2.473], [64598.7, 0.026], [64598.9, 0.036], [64600.2, 0.238], [64607.7, 0.016], [64608.4, 0.004], [64613.1, 0.388], [64613.5, 0.025], [64624.9, 0.21], [64627.0, 0.061], [64638.4, 0.592], [64827.9, 0.0], [64830.5, 0.001], [64895.1, 2.619], [65217.9, 0.0], [65479.9, 6.863], [65572.2, 0.022], [65634.3, 1.318]]}
{"kind": "depth", "E": 1787089561865, "U": 11315993675564, "u": 11315993697636, "recv_ms": 1787089561823, "bids": [[1000.0, 35.76], [14072.1, 1.806], [14172.1, 2.394], [51657.7, 0.0], [51658.0, 0.0], [58114.8, 0.065], [61343.4, 0.0], [63700.4, 0.325], [63926.4, 1.408], [64249.2, 4.321], [64416.0, 2.128], [64457.7, 3.872], [64457.8, 0.004], [64466.0, 2.563], [64466.9, 0.776], [64467.0, 0.017], [64480.8, 0.021], [64481.2, 0.003], [64495.0, 0.408], [64495.3, 30.893], [64496.1, 0.0], [64498.8, 0.044], [64499.3, 0.21], [64499.7, 0.015], [64501.9, 0.077], [64502.0, 8.231], [64506.0, 0.031], [64512.6, 0.029], [64524.8, 1.496], [64528.4, 0.0], [64532.0, 0.109], [64535.7, 0.121], [64535.8, 0.001], [64536.9, 0.003], [64537.5, 1.75], [64541.4, 0.001], [64544.5, 0.058], [64544.8, 0.014], [64558.2, 0.346], [64560.0, 0.354], [64560.2, 0.003], [64560.7, 0.006], [64563.2, 0.254], [64563.5, 0.312], [64564.3, 0.21], [64564.5, 0.287], [64564.9, 0.154], [64566.1, 0.629], [64566.4, 0.008], [64567.6, 0.003], [64568.0, 0.003], [64568.5, 0.001], [64569.6, 0.002], [64572.0, 0.012], [64572.1, 10.846]], "asks": [[64572.2, 0.378], [64572.3, 1.395], [64572.8, 0.086], [64572.9, 0.008], [64573.3, 0.084], [64573.4, 1.006], [64574.8, 0.196], [64575.8, 0.008], [64576.2, 0.002], [64577.1, 0.046], [64577.2, 0.943], [64577.4, 0.005], [64577.7, 0.003], [64578.1, 0.005], [64578.3, 0.465], [64578.4, 0.006], [64578.9, 0.062], [64579.2, 0.098], [64579.3, 0.126], [64579.4, 0.038], [64579.7, 0.609], [64579.8, 0.395], [64579.9, 0.819], [64580.0, 0.118], [64584.0, 0.839], [64584.7, 0.0], [64589.3, 2.46], [64591.1, 10.0], [64594.8, 0.625], [64595.2, 0.174], [64596.0, 0.138], [64598.5, 2.319], [64598.6, 0.001], [64598.7, 0.014], [64608.1, 3.42], [64616.6, 0.31], [64617.6, 1.002], [64624.9, 0.0], [64625.4, 0.001], [64629.6, 0.21], [64636.7, 0.026], [64637.8, 0.023], [64640.5, 0.1], [64644.1, 6.046], [64659.8, 7.621], [64683.8, 2.323], [64683.9, 1.02], [64713.3, 3.903], [64729.6, 2.756], [64768.4, 3.602], [64895.1, 2.62], [65217.9, 0.0], [65486.6, 3.47], [65742.4, 0.76], [65863.6, 0.024]]}
{"kind": "depth", "E": 1787089561967, "U": 11315993697806, "u": 11315993717966, "recv_ms": 1787089561927, "bids": [[14072.1, 2.156], [14172.1, 2.044], [58114.8, 0.067], [61343.4, 0.0], [61989.2, 0.017], [63572.1, 0.018], [63660.1, 0.784], [63709.0, 4.739], [63926.4, 1.408], [64231.5, 0.005], [64231.8, 0.493], [64480.3, 0.005], [64480.8, 0.016], [64494.7, 0.184], [64495.3, 0.011], [64499.7, 30.991], [64502.0, 4.828], [64514.1, 0.0], [64528.1, 0.126], [64528.5, 0.129], [64528.6, 0.004], [64531.8, 6.921], [64533.4, 0.115], [64535.7, 0.001], [64535.8, 0.121], [64537.1, 0.216], [64537.5, 0.928], [64538.3, 0.045], [64539.9, 1.315], [64544.3, 0.009], [64544.5, 0.018], [64545.3, 0.003], [64545.6, 3.048], [64548.6, 2.354], [64548.9, 0.311], [64549.5, 0.972], [64549.6, 0.005], [64553.7, 0.071], [64553.9, 0.116], [64554.3, 0.001], [64555.1, 0.56], [64555.8, 0.211], [64558.5, 1.126], [64559.2, 0.007], [64559.3, 0.006], [64559.4, 0.949], [64559.7, 0.551], [64559.8, 0.0], [64560.3, 0.467], [64561.2, 0.161], [64561.5, 0.041], [64561.8, 2.474], [64562.5, 0.473], [64562.6, 0.064], [64562.9, 1.555], [64563.0, 0.232], [64563.4, 0.155], [64563.5, 0.002], [64563.8, 0.092], [64564.2, 0.158], [64564.4, 0.086], [64564.6, 0.204], [64564.7, 0.071], [64564.8, 0.583], [64565.4, 0.324], [64565.5, 0.041], [64565.6, 0.086], [64565.8, 0.002], [64565.9, 0.002], [64566.0, 0.132], [64566.1, 0.003], [64566.2, 0.005], [64566.3, 3.008], [64566.4, 0.07], [64566.5, 0.002], [64566.6, 0.344], [64566.7, 0.006], [64566.8, 0.0], [64567.0, 1.802], [64567.1, 0.001], [64567.3, 0.029], [64567.7, 0.014], [64568.2, 1.705], [64568.3, 2.957], [64568.4, 0.033], [64568.9, 0.036], [64570.7, 0.124], [64572.0, 0.008], [64572.1, 5.121]], "asks": [[64572.2, 0.388], [64572.3, 0.004], [64572.4, 0.085], [64572.7, 0.003], [64572.8, 0.087], [64573.3, 0.084], [64573.9, 0.127], [64574.2, 0.043], [64574.6, 0.322], [64574.8, 0.199], [64575.8, 0.018], [64577.1, 0.046], [64577.2, 0.008], [64577.4, 0.113], [64577.9, 0.077], [64578.1, 0.005], [64578.3, 0.625], [64578.6, 0.018], [64579.2, 0.026], [64579.3, 0.125], [64579.8, 0.411], [64580.2, 0.002], [64580.3, 2.603], [64584.0, 0.839], [64584.3, 0.001], [64584.8, 0.027], [64585.8, 2.914], [64587.1, 0.022], [64587.2, 10.004], [64587.3, 0.501], [64589.3, 1.105], [64589.4, 0.009], [64590.8, 0.0], [64591.0, 0.016], [64591.1, 0.002], [64591.2, 0.234], [64591.6, 0.136], [64594.0, 0.004], [64594.1, 0.622], [64594.3, 0.05], [64594.4, 0.455], [64594.8, 0.001], [64595.2, 0.173], [64595.8, 0.445], [64600.6, 0.09], [64607.8, 0.07], [64610.6, 0.095], [64613.6, 0.005], [64616.5, 0.037], [64629.6, 0.0], [64630.0, 0.23], [64646.8, 0.859], [64649.4, 0.003], [64666.8, 1.032], [64668.8, 0.777], [64679.3, 0.001], [64846.6, 0.015], [65217.9, 0.0], [65230.5, 0.817], [65572.2, 0.002], [65657.0, 0.613], [65702.2, 1.216]]}
{"kind": "depth", "E": 1787089562069, "U": 11315993718117, "u": 11315993731470, "recv_ms": 1787089562026, "bids": [[14072.1, 2.52], [14172.1, 1.68], [58114.8, 0.067], [61343.4, 0.0], [61343.5, 0.014], [61989.2, 0.014], [63022.4, 0.637], [63280.7, 0.023], [63926.4, 1.408], [64249.2, 4.321], [64475.2, 1.328], [64494.6, 0.05], [64499.3, 0.0], [64506.5, 0.212], [64513.8, 1.264], [64521.1, 0.006], [64531.8, 0.006], [64536.4, 2.005], [64559.4, 0.022], [64559.8, 0.927], [64560.2, 0.096], [64560.5, 0.002], [64564.5, 0.287], [64565.3, 0.117], [64566.2, 0.007], [64566.7, 0.09], [64567.3, 0.113], [64568.4, 0.034], [64568.9, 0.036], [64572.1, 5.126]], "asks": [[64572.2, 0.374], [64572.3, 1.397], [64572.7, 0.0], [64573.2, 0.011], [64573.3, 0.084], [64574.6, 0.322], [64574.8, 0.197], [64575.8, 0.0], [64575.9, 0.007], [64576.1, 0.087], [64577.2, 0.016], [64577.9, 0.005], [64578.1, 0.005], [64578.4, 0.007], [64578.6, 0.017], [64579.8, 0.483], [64580.0, 0.132], [64583.4, 0.242], [64585.0, 0.864], [64585.8, 1.606], [64586.2, 0.049], [64587.1, 0.014], [64587.2, 0.004], [64589.4, 0.007], [64590.6, 0.09], [64590.8, 0.542], [64591.4, 0.071], [64591.6, 0.005], [64592.2, 11.237], [64597.0, 0.168], [64597.5, 0.13], [64598.7, 0.014], [64599.0, 4.004], [64605.6, 0.12], [64610.8, 0.442], [64617.5, 0.031], [64626.4, 0.0], [64649.7, 0.004], [64660.1, 37.242], [64662.3, 0.001], [64846.6, 0.215], [65217.9, 0.0], [65508.5, 11.736]]}
{"kind": "depth", "E": 1787089562171, "U": 11315993731544, "u": 11315993741159, "recv_ms": 1787089562130, "bids": [[1000.0, 35.76], [14072.1, 2.884], [14172.1, 1.316], [51658.0, 0.002], [58114.8, 0.067], [61343.4, 0.0], [61989.2, 0.017], [63572.1, 0.038], [63614.5, 8.909], [63926.4, 1.408], [63998.0, 0.926], [64513.8, 1.25], [64521.0, 0.384], [64531.6, 0.752], [64537.1, 0.126], [64537.4, 0.328], [64538.8, 0.186], [64544.6, 0.139], [64545.0, 0.015], [64545.4, 0.06], [64548.6, 2.319], [64555.9, 0.502], [64559.8, 0.0], [64560.1, 1.401], [64563.0, 0.0], [64563.4, 0.071], [64564.1, 0.304], [64564.7, 0.074], [64565.0, 0.906], [64567.7, 0.098], [64572.1, 5.233]], "asks": [[64572.3, 1.397], [64572.4, 0.001], [64573.2, 0.001], [64574.6, 0.312], [64575.9, 0.015], [64577.1, 0.054], [64577.2, 0.0], [64578.4, 0.006], [64578.5, 0.101], [64579.6, 0.076], [64579.8, 0.412], [64582.6, 0.014], [64590.6, 0.09], [64590.8, 0.0], [64591.0, 0.016], [64591.4, 0.613], [64592.2, 10.31], [64592.4, 0.93], [64597.0, 0.111], [64597.2, 0.148], [64598.7, 0.014], [65217.9, 0.0], [65403.8, 2.12], [65572.2, 0.022], [71029.5, 0.0]]}
{"kind": "depth", "E": 1787089562273, "U": 11315993741288, "u": 11315993751848, "recv_ms": 1787089562232, "bids": [[14072.1, 3.234], [14172.1, 0.966], [51658.0, 0.0], [58114.8, 0.067], [61343.4, 0.0], [61989.2, 0.0], [63926.4, 1.408], [64539.5, 0.006], [64544.8, 0.003], [64546.7, 0.05], [64548.0, 1.368], [64548.3, 0.011], [64559.7, 0.009], [64560.2, 0.638], [64564.1, 0.072], [64564.7, 0.303], [64565.1, 0.071], [64566.3, 2.352], [64566.4, 1.146], [64572.1, 5.229]], "asks": [[64572.2, 0.373], [64572.3, 0.004], [64572.9, 0.003], [64573.1, 0.015], [64573.3, 0.084], [64574.8, 0.197], [64575.9, 0.007], [64576.1, 0.085], [64577.1, 0.046], [64577.2, 0.016], [64577.4, 0.115], [64578.4, 0.007], [64579.8, 0.411], [64580.0, 0.132], [64580.3, 2.403], [64587.4, 0.155], [64588.3, 0.003], [64590.6, 0.082], [64591.0, 0.024], [64729.8, 0.003], [64730.4, 6.513], [65217.9, 0.0], [65218.0, 2.653], [65250.2, 2.534], [65322.8, 9.477], [66501.1, 0.0], [71933.4, 0.155]]}
{"kind": "depth", "E": 1787089562375, "U": 11315993752283, "u": 11315993762796, "recv_ms": 1787089562333, "bids": [[14072.1, 3.598], [14172.1, 0.602], [58114.8, 0.067], [61343.4, 0.0], [63572.1, 0.018], [63635.8, 3.297], [63660.2, 0.785], [63705.7, 10.977], [63926.4, 1.408], [64249.2, 4.321], [64432.1, 0.022], [64539.3, 0.005], [64548.1, 0.176], [64564.7, 0.306], [64568.9, 0.151], [64572.1, 5.229]], "asks": [[64572.2, 0.373], [64572.3, 1.397], [64572.8, 0.003], [64573.2, 0.011], [64573.3, 1.019], [64573.8, 0.019], [64573.9, 0.108], [64574.6, 0.312], [64574.8, 0.196], [64575.9, 0.015], [64577.2, 0.008], [64578.4, 0.006], [64580.0, 0.133], [64580.3, 2.603], [64598.5, 2.473], [64712.9, 1.215], [65217.9, 0.0], [65572.2, 0.002], [65863.6, 0.021]]}
{"kind": "depth", "E": 1787089562477, "U": 11315993763022, "u": 11315993771628, "recv_ms": 1787089562441, "bids": [[1000.0, 35.76], [14072.1, 3.78], [14172.1, 0.336], [14472.1, 0.084], [58114.8, 0.067], [61343.4, 0.0], [61989.2, 0.003], [63280.7, 0.026], [63870.0, 0.188], [63926.4, 1.408], [64432.1, 4.309], [64568.9, 0.036], [64572.1, 5.228]], "asks": [[64572.2, 0.373], [64572.3, 0.004], [64573.2, 0.001], [64573.3, 0.084], [64573.8, 0.0], [64573.9, 0.085], [64575.9, 0.007], [64577.2, 0.016], [64578.4, 0.006], [64579.8, 0.412], [64580.0, 0.132], [64598.5, 2.319], [64712.9, 6.624], [64768.6, 10.838], [65217.9, 0.0], [65356.8, 0.922], [65583.4, 7.157], [66516.0, 0.643]]}
{"kind": "depth", "E": 1787089562579, "U": 11315993771686, "u": 11315993780183, "recv_ms": 1787089562536, "bids": [[14072.1, 3.626], [14172.1, 0.238], [14472.1, 0.336], [58114.8, 0.067], [61343.4, 0.0], [61989.2, 0.0], [63552.0, 5.01], [63572.1, 0.038], [63778.0, 17.865], [63926.4, 1.408], [64227.7, 0.025], [64415.2, 5.855], [64432.1, 3.704], [64564.7, 0.074], [64565.4, 0.556], [64568.9, 0.074]], "asks": [[64572.2, 0.374], [64572.3, 0.004], [64573.2, 0.011], [64574.0, 0.045], [64574.6, 0.312], [64575.9, 0.007], [64577.2, 0.016], [64579.8, 0.411], [64580.0, 0.133], [64598.4, 2.571], [64598.5, 2.473], [64657.9, 37.261], [64659.8, 2.299], [64660.1, 0.013], [64712.9, 6.624], [64729.8, 10.431], [64730.4, 0.001], [65217.9, 0.0], [65551.1, 3.05], [65572.2, 0.022], [65605.4, 2.132]]}
{"kind": "depth", "E": 1787089562681, "U": 11315993780265, "u": 11315993789272, "recv_ms": 1787089562639, "bids": [[14072.1, 3.542], [14172.1, 0.098], [14472.1, 0.56], [58114.8, 0.067], [61989.2, 0.003], [63926.4, 1.41], [64249.2, 4.321], [64462.3, 0.004], [64494.6, 0.047], [64513.9, 0.047], [64547.2, 0.625], [64552.9, 0.364], [64554.5, 1.939], [64563.8, 0.008], [64564.2, 0.074], [64568.2, 1.789], [64568.9, 0.021], [64569.1, 0.085], [64570.6, 0.312], [64571.2, 0.071], [64571.6, 0.0], [64571.9, 0.01], [64572.1, 5.237]], "asks": [[64572.2, 0.374], [64572.3, 0.004], [64573.3, 0.007], [64573.4, 0.744], [64573.9, 0.044], [64574.0, 0.002], [64574.6, 0.002], [64574.8, 0.002], [64575.9, 0.007], [64577.2, 0.092], [64577.6, 0.087], [64578.7, 0.017], [64579.8, 0.318], [64580.2, 0.095], [64590.5, 0.641], [64592.2, 0.31], [64594.0, 0.002], [64594.8, 0.003], [64595.6, 2.334], [64597.9, 0.633], [64630.4, 1.237], [64649.7, 0.001], [64657.9, 0.032], [64662.3, 37.23], [64895.1, 2.619], [65217.9, 0.0], [65327.3, 18.693]]}
{"kind": "depth", "E": 1787089562783, "U": 11315993789318, "u": 11315993797934, "recv_ms": 1787089562741, "bids": [[1000.0, 35.76], [14072.1, 3.374], [14172.1, 0.0], [14472.1, 0.826], [58114.8, 0.067], [61343.4, 0.0], [62996.7, 2.037], [63571.2, 2.208], [63572.1, 0.018], [63926.4, 1.408], [64249.2, 4.477], [64432.1, 3.849], [64528.1, 0.097], [64555.3, 0.007], [64570.6, 0.002], [64571.2, 0.03], [64571.9, 0.011], [64572.1, 5.24]], "asks": [[64572.3, 0.004], [64574.8, 0.001], [64575.9, 0.015], [64576.3, 0.008], [64577.2, 0.092], [64578.2, 0.012], [64580.0, 0.132], [64580.3, 2.604], [64587.7, 2.326], [64594.3, 0.05], [64595.2, 10.173], [64598.5, 2.319], [64598.6, 0.001], [64598.7, 0.168], [64660.1, 37.242], [64662.3, 0.001], [64712.9, 6.624], [64830.5, 0.196], [65217.9, 0.0], [65572.2, 0.002], [65573.1, 6.395]]}
{"kind": "depth", "E": 1787089562885, "U": 11315993798021, "u": 11315993806912, "recv_ms": 1787089562843, "bids": [[14072.1, 3.024], [14472.1, 1.176], [51657.7, 0.0], [58114.8, 0.067], [61343.4, 0.0], [61666.0, 13.749], [61989.2, 0.0], [63280.7, 0.023], [63572.1, 0.038], [63724.8, 1.881], [63756.0, 0.258], [63797.2, 10.347], [63926.4, 1.408], [64495.3, 30.931], [64499.7, 0.015], [64502.0, 8.245], [64536.4, 0.005], [64542.0, 7.016], [64543.5, 3.185], [64545.4, 0.003], [64546.1, 0.058], [64547.2, 0.006], [64547.9, 0.505], [64548.1, 0.022], [64548.3, 0.0], [64551.8, 0.011], [64554.5, 1.32], [64555.1, 0.002], [64556.4, 0.558], [64557.6, 0.07], [64558.2, 0.335], [64560.1, 0.474], [64560.2, 0.096], [64560.7, 0.933], [64560.8, 0.288], [64561.9, 0.666], [64566.2, 0.005], [64566.4, 1.084], [64566.9, 0.24], [64567.0, 0.001], [64567.1, 0.443], [64567.3, 0.115], [64568.2, 0.085], [64568.3, 2.331], [64568.4, 0.002], [64569.5, 1.802], [64569.6, 0.66], [64570.6, 0.312], [64571.9, 0.008], [64572.1, 6.377]], "asks": [[64572.2, 0.222], [64572.3, 1.395], [64574.8, 0.002], [64576.8, 0.002], [64577.3, 2.328], [64577.4, 0.005], [64578.2, 0.005], [64580.2, 0.079], [64580.3, 2.604], [64580.4, 0.05], [64580.6, 41.719], [64590.5, 0.022], [64591.4, 0.613], [64592.0, 0.026], [64592.1, 2.836], [64592.4, 0.003], [64592.8, 0.258], [64593.1, 0.929], [64596.1, 0.003], [64596.6, 0.615], [64597.2, 0.091], [64597.6, 0.065], [64597.9, 0.014], [64600.0, 1.014], [64617.7, 1.34], [64645.9, 0.2], [64647.1, 2.325], [64656.0, 1.201], [64657.9, 0.032], [64660.1, 0.013], [64662.3, 0.001], [64664.5, 37.182], [64675.4, 2.169], [64757.5, 0.017], [64757.6, 0.003], [64830.5, 0.306], [64846.6, 0.215], [64895.1, 2.618], [64904.1, 0.35], [64905.3, 0.005], [65217.9, 0.0], [65326.5, 0.063], [65494.4, 1.068], [65560.2, 0.0], [65572.2, 0.022], [65591.2, 0.037], [65615.7, 0.0]]}
{"kind": "depth", "E": 1787089562987, "U": 11315993806948, "u": 11315993816390, "recv_ms": 1787089562945, "bids": [[1000.0, 35.91], [14072.1, 2.66], [14472.1, 1.54], [58114.8, 0.067], [61343.4, 0.0], [61989.2, 0.003], [63773.5, 15.365], [63926.4, 1.408], [64231.8, 0.0], [64232.0, 0.5], [64249.2, 4.478], [64495.3, 0.011], [64499.7, 30.935], [64502.0, 4.828], [64504.3, 2.043], [64504.5, 0.006], [64512.2, 3.67], [64512.4, 1.987], [64520.1, 1.965], [64520.3, 0.067], [64528.1, 0.069], [64545.7, 0.057], [64546.1, 0.001], [64546.3, 0.135], [64553.9, 0.0], [64555.0, 0.215], [64555.2, 0.004], [64556.0, 0.005], [64557.6, 0.008], [64560.4, 1.383], [64560.7, 0.006], [64563.5, 0.001], [64563.6, 0.005], [64565.3, 0.117], [64565.5, 0.041], [64566.2, 0.005], [64566.4, 1.086], [64566.5, 0.002], [64566.6, 0.405], [64566.7, 0.09], [64566.9, 0.238], [64567.3, 1.825], [64568.1, 0.155], [64568.2, 1.886], [64568.3, 2.215], [64568.4, 0.001], [64568.9, 0.021], [64569.5, 0.001], [64569.6, 1.381], [64569.7, 0.002], [64569.8, 0.002], [64570.5, 0.019], [64570.6, 0.002], [64571.2, 0.031], [64571.9, 0.007], [64572.1, 6.392]], "asks": [[64572.2, 0.221], [64572.3, 1.395], [64573.1, 0.01], [64573.2, 0.001], [64574.2, 0.048], [64574.8, 0.001], [64576.3, 0.012], [64578.9, 0.062], [64580.2, 0.002], [64580.3, 2.404], [64580.4, 0.119], [64580.5, 6.787], [64583.5, 0.657], [64583.6, 0.003], [64591.4, 2.656], [64591.5, 0.631], [64592.1, 1.389], [64594.1, 0.003], [64594.8, 0.622], [64595.2, 0.173], [64597.3, 0.01], [64599.3, 2.11], [64599.4, 0.018], [64600.2, 0.168], [64607.0, 2.423], [64618.7, 0.068], [64660.1, 37.191], [64662.3, 0.001], [64664.5, 0.004], [64675.5, 0.2], [65217.9, 0.0], [65347.1, 13.027]]}
{"kind": "depth", "E": 1787089563089, "U": 11315993816512, "u": 11315993827203, "recv_ms": 1787089563047, "bids": [[1000.0, 35.76], [14072.1, 2.31], [14472.1, 1.89], [58114.8, 0.067], [61343.4, 0.0], [61989.2, 0.0], [63280.7, 0.026], [63586.6, 4.742], [63586.8, 3.39], [63651.6, 0.002], [63654.0, 0.065], [63732.7, 0.431], [63926.4, 1.408], [64031.0, 0.001], [64536.5, 0.0], [64540.4, 9.234], [64542.0, 0.101], [64543.5, 0.332], [64543.9, 0.0], [64544.9, 0.048], [64545.1, 0.057], [64545.7, 0.0], [64553.1, 0.117], [64554.3, 0.001], [64554.4, 0.558], [64555.0, 0.099], [64555.4, 0.001], [64555.6, 0.005], [64555.9, 0.502], [64556.0, 0.003], [64556.4, 0.0], [64558.6, 0.007], [64559.6, 1.37], [64559.7, 1.478], [64560.2, 0.096], [64560.4, 0.456], [64560.5, 0.002], [64561.9, 0.124], [64563.8, 0.009], [64569.1, 0.001], [64569.7, 0.002], [64571.8, 0.002], [64571.9, 0.01], [64572.1, 5.236]], "asks": [[64572.2, 0.53], [64572.3, 0.002], [64573.7, 0.084], [64574.6, 0.002], [64574.8, 0.001], [64576.3, 0.015], [64577.3, 2.326], [64578.6, 0.024], [64580.2, 0.01], [64580.5, 6.779], [64589.9, 0.001], [64590.6, 0.624], [64591.0, 0.024], [64591.1, 0.002], [64591.3, 0.145], [64591.4, 2.114], [64591.9, 0.007], [64592.1, 2.316], [64592.7, 0.0], [64593.1, 0.002], [64594.4, 1.074], [64594.8, 0.003], [64595.4, 0.566], [64595.5, 1.176], [64595.8, 0.445], [64596.0, 0.138], [64596.6, 0.058], [64596.7, 0.015], [64596.9, 0.057], [64597.0, 0.227], [64597.5, 0.014], [64597.6, 0.008], [64599.3, 2.11], [64618.7, 0.068], [64657.9, 0.032], [64660.1, 37.191], [65174.1, 1.53], [65217.9, 0.0], [65340.6, 4.433], [65460.1, 0.917], [65490.4, 0.007], [65492.8, 0.456], [65508.5, 12.803], [65557.4, 0.0], [65557.6, 0.003], [65605.4, 3.198], [67155.0, 0.294], [67800.8, 0.049], [71933.4, 0.221]]}
{"kind": "depth", "E": 1787089563191, "U": 11315993827237, "u": 11315993837070, "recv_ms": 1787089563149, "bids": [[14072.1, 1.946], [14472.1, 2.254], [58114.8, 0.067], [61343.4, 0.0], [61343.5, 0.016], [61989.2, 0.003], [63517.7, 0.0], [63572.1, 0.018], [63587.3, 0.02], [63652.1, 0.008], [63654.5, 0.014], [63926.4, 1.408], [64540.4, 2.319], [64540.6, 2.001], [64546.3, 0.116], [64568.9, 0.182], [64569.7, 0.002], [64570.8, 0.091], [64571.2, 0.001], [64571.6, 0.046], [64571.9, 0.008], [64572.1, 5.221]], "asks": [[64572.2, 0.52], [64572.3, 1.395], [64573.2, 0.011], [64573.7, 0.0], [64576.3, 0.012], [64577.4, 0.01], [64578.6, 0.017], [64580.2, 0.002], [64580.4, 0.127], [64583.4, 0.243], [64594.2, 10.671], [64655.7, 2.321], [64660.1, 0.013], [64662.3, 37.179], [65076.9, 2.047], [65217.9, 0.0], [65496.5, 0.0], [65571.8, 5.461], [65572.2, 0.002], [65637.6, 3.378], [65863.6, 0.024]]}
{"kind": "depth", "E": 1787089563293, "U": 11315993837170, "u": 11315993846863, "recv_ms": 1787089563250, "bids": [[1000.0, 35.76], [14072.1, 1.596], [14472.1, 2.604], [58114.8, 0.067], [61343.4, 0.0], [61343.5, 0.018], [63572.1, 0.038], [63611.7, 0.022], [63653.5, 0.468], [63724.7, 0.784], [63795.6, 6.01], [63926.4, 1.41], [64249.2, 4.488], [64467.0, 0.014], [64467.2, 0.018], [64547.9, 0.505], [64548.0, 1.368], [64554.4, 0.0], [64555.8, 0.769], [64563.7, 0.013], [64563.8, 0.008], [64568.9, 0.105], [64569.7, 0.008], [64571.9, 0.007], [64572.1, 5.223]], "asks": [[64572.2, 0.482], [64572.3, 1.41], [64573.2, 0.001], [64574.8, 0.001], [64583.4, 0.242], [64590.6, 0.082], [64591.3, 0.687], [64592.1, 1.389], [64592.5, 0.928], [64593.9, 0.229], [64594.2, 0.671], [64595.4, 0.009], [64596.1, 0.56], [64596.9, 0.0], [64597.2, 10.091], [64597.4, 0.062], [64618.7, 0.068], [64660.1, 37.191], [64662.3, 0.001], [64757.6, 0.0], [64757.7, 6.606], [65088.8, 5.554], [65217.9, 0.0], [65218.0, 2.652], [65482.7, 2.057], [65489.9, 0.008], [65492.3, 0.011], [65548.5, 0.769], [65557.1, 0.025], [65572.2, 0.022]]}
{"kind": "depth", "E": 1787089563395, "U": 11315993846881, "u": 11315993854693, "recv_ms": 1787089563354, "bids": [[1000.0, 35.76], [14072.1, 1.232], [14472.1, 2.968], [58114.8, 0.067], [61343.4, 0.0], [61989.2, 0.0], [63538.9, 2.205], [63622.9, 1.883], [63778.0, 16.299], [63926.4, 1.408], [64528.1, 0.097], [64547.9, 0.505], [64549.5, 0.974], [64563.7, 0.013], [64569.7, 0.002], [64572.1, 5.213]], "asks": [[64572.2, 0.533], [64572.3, 0.118], [64573.4, 1.125], [64573.9, 0.105], [64574.8, 0.001], [64575.9, 0.007], [64577.2, 0.1], [64579.8, 0.318], [64580.1, 0.314], [64580.3, 2.403], [64590.5, 0.025], [64596.0, 0.135], [65185.6, 0.536], [65217.9, 0.0], [65355.0, 3.953], [65508.5, 13.87], [65509.8, 1.297], [65863.6, 0.027]]}
{"kind": "depth", "E": 1787089563497, "U": 11315993854810, "u": 11315993862884, "recv_ms": 1787089563457, "bids": [[14072.1, 0.882], [14472.1, 3.318], [58114.8, 0.067], [61339.9, 0.0], [61343.4, 0.0], [61989.2, 0.003], [63572.1, 0.018], [63926.4, 1.408], [63965.3, 1.718], [64192.0, 0.011], [64547.9, 0.505], [64563.6, 0.051], [64568.9, 0.021], [64570.8, 0.046], [64571.2, 0.045], [64572.1, 5.211]], "asks": [[64572.2, 0.535], [64572.3, 0.118], [64573.3, 0.007], [64574.8, 0.001], [64575.9, 0.015], [64576.2, 0.374], [64576.8, 0.005], [64577.2, 0.092], [64579.5, 0.002], [64580.0, 0.132], [64580.1, 0.313], [65217.9, 0.0], [65489.1, 0.685], [65572.2, 0.002]]}
{"kind": "depth", "E": 1787089563599, "U": 11315993863014, "u": 11315993870449, "recv_ms": 1787089563557, "bids": [[1000.0, 35.76], [14072.1, 0.518], [14472.1, 3.682], [51658.0, 0.0], [58114.8, 0.067], [61343.5, 0.016], [61343.6, 0.005], [61989.2, 0.0], [63648.9, 26.362], [63926.4, 1.408], [64094.4, 0.016], [64096.3, 0.0], [64249.2, 4.488], [64547.8, 1.197], [64547.9, 0.351], [64568.6, 0.085]], "asks": [[64572.2, 0.49], [64572.3, 1.511], [64573.3, 0.007], [64573.9, 0.085], [64579.5, 0.001], [64579.7, 0.609], [64580.0, 0.133], [64768.6, 10.638], [65217.9, 0.0], [65335.2, 0.015], [65377.6, 5.246], [65521.4, 2.301], [65722.1, 0.76]]}
{"kind": "depth", "E": 1787089563701, "U": 11315993870656, "u": 11315993878798, "recv_ms": 1787089563659, "bids": [[1000.0, 35.76], [14072.1, 0.308], [14372.1, 0.154], [14472.1, 3.738], [58114.8, 0.067], [58114.9, 0.002], [61343.4, 0.0], [61989.2, 0.003], [63550.0, 7.179], [63572.1, 0.038], [63614.5, 7.81], [63668.1, 4.706], [63797.2, 11.913], [63926.4, 1.408]], "asks": [[64572.2, 0.488], [64572.3, 1.511], [65500.5, 6.552], [65565.0, 4.342], [65572.2, 0.022], [65597.3, 0.429], [65721.3, 2.604], [67800.8, 0.053]]}
{"kind": "depth", "E": 1787089563803, "U": 11315993878808, "u": 11315993886695, "recv_ms": 1787089563761, "bids": [[14072.1, 0.196], [14372.1, 0.392], [14472.1, 3.612], [58114.8, 0.067], [58114.9, 0.0], [63926.4, 1.408], [63971.6, 7.641], [63984.6, 0.238], [64249.2, 4.487], [64555.3, 0.007], [64565.4, 0.324], [64566.1, 0.235]], "asks": [[64572.3, 0.118], [64573.9, 0.127], [64587.7, 2.326], [64589.0, 0.005], [64590.0, 1.297], [64895.1, 2.619], [65217.9, 0.0], [65347.1, 13.486]]}
{"kind": "depth", "E": 1787089563905, "U": 11315993886785, "u": 11315993894155, "recv_ms": 1787089563864, "bids": [[1000.0, 35.76], [14072.1, 0.07], [14372.1, 0.63], [14472.1, 3.5], [51657.7, 0.0], [58114.8, 0.067], [61343.4, 0.0], [61989.2, 0.0], [63572.1, 0.018], [63926.4, 1.408], [63991.0, 1.457], [64249.2, 4.487], [64353.0, 5.454], [64462.3, 0.001], [64502.0, 8.237], [64513.9, 0.05], [64547.2, 0.625], [64554.6, 0.739], [64557.6, 0.001], [64557.7, 0.007], [64558.5, 1.126], [64559.7, 0.936], [64561.9, 0.666], [64563.7, 0.012], [64572.1, 5.213]], "asks": [[64572.2, 0.49], [64572.3, 0.118], [64574.8, 0.002], [64590.5, 0.025], [64590.6, 0.701], [64591.3, 0.687], [64595.5, 2.577], [64597.9, 0.633], [64621.2, 1.566], [64622.3, 0.001], [64630.4, 1.237], [64659.8, 7.62], [65217.9, 0.0], [65377.6, 5.018], [65500.5, 5.485], [65572.2, 0.002]]}
{"kind": "depth", "E": 1787089564007, "U": 11315993894181, "u": 11315993903346, "recv_ms": 1787089563966, "bids": [[1000.0, 35.76], [14072.1, 0.0], [14372.1, 0.91], [14472.1, 3.29], [58114.8, 0.067], [61343.4, 0.0], [61989.2, 0.003], [63453.1, 0.72], [63571.2, 3.308], [63635.8, 4.396], [63926.4, 1.408], [63991.0, 1.925], [64232.0, 0.007], [64232.1, 0.494], [64249.2, 4.486], [64553.1, 0.001], [64554.9, 2.438], [64559.8, 0.542], [64561.9, 0.124], [64563.7, 0.013], [64572.1, 5.214]], "asks": [[64572.2, 0.49], [64572.3, 1.511], [64574.8, 0.001], [64597.0, 0.111], [64597.6, 0.124], [65217.9, 0.0], [65419.5, 0.764], [65508.5, 14.937], [65573.1, 7.461], [65605.4, 4.264], [65863.6, 0.03]]}
{"kind": "depth", "E": 1787089564109, "U": 11315993903628, "u": 11315993910900, "recv_ms": 1787089564067, "bids": [[14372.1, 1.26], [14472.1, 2.94], [58114.8, 0.067], [61343.4, 0.0], [61343.5, 0.014], [61343.6, 0.007], [61989.2, 0.0], [63926.4, 1.408], [64044.0, 0.051], [64442.9, 0.03], [64494.6, 0.05], [64559.7, 0.009], [64560.2, 1.023], [64560.5, 0.002], [64563.7, 0.012], [64570.6, 0.312], [64572.1, 5.223]], "asks": [[64572.3, 1.511], [64573.9, 0.085], [64574.2, 0.007], [64574.8, 0.002], [64586.6, 0.224], [64592.1, 1.386], [64649.7, 0.004], [64653.1, 0.207], [64895.1, 2.62], [65217.9, 0.0], [65458.2, 0.3], [65508.5, 16.004], [65645.5, 1.674], [65863.6, 0.027]]}
{"kind": "depth", "E": 1787089564211, "U": 11315993911347, "u": 11315993922804, "recv_ms": 1787089564173, "bids": [[1000.0, 35.76], [14372.1, 1.624], [14472.1, 2.576], [58114.8, 0.067], [61343.4, 0.0], [61989.2, 0.003], [63356.6, 0.003], [63474.4, 5.02], [63572.1, 0.038], [63724.8, 2.665], [63926.4, 1.408], [64055.5, 5.144], [64249.2, 4.486], [64369.9, 0.013], [64432.1, 4.037], [64454.2, 2.4], [64466.0, 0.24], [64469.8, 5.923], [64503.4, 0.003], [64512.6, 0.001], [64514.0, 0.017], [64528.1, 0.069], [64529.4, 0.002], [64540.6, 0.001], [64545.1, 0.0], [64545.7, 6.915], [64546.8, 0.057], [64547.2, 0.006], [64547.6, 0.001], [64551.7, 2.002], [64551.9, 0.001], [64554.2, 0.005], [64554.6, 0.12], [64554.9, 2.322], [64555.6, 0.0], [64555.7, 0.292], [64555.8, 0.211], [64556.4, 0.558], [64557.0, 0.003], [64557.1, 0.016], [64557.2, 0.0], [64557.6, 0.001], [64557.7, 0.0], [64557.9, 0.156], [64558.0, 0.003], [64558.3, 0.228], [64559.7, 0.016], [64559.8, 0.0], [64560.0, 0.358], [64560.2, 0.096], [64560.5, 0.929], [64561.0, 0.005], [64561.8, 2.477], [64561.9, 0.666], [64562.5, 0.318], [64563.4, 0.074], [64563.7, 0.012], [64563.8, 0.001], [64564.0, 0.003], [64564.5, 0.203], [64564.9, 0.07], [64565.3, 0.033], [64565.5, 0.048], [64565.6, 0.002], [64566.0, 0.187], [64566.1, 0.003], [64566.4, 1.084], [64567.2, 0.281], [64567.3, 0.115], [64567.7, 0.098], [64568.1, 0.0], [64568.2, 0.085], [64568.3, 2.168], [64568.4, 0.002], [64569.5, 0.006], [64569.7, 3.566], [64569.8, 0.049], [64569.9, 0.239], [64570.6, 0.396], [64570.7, 0.001], [64570.8, 0.046], [64571.5, 0.138], [64571.6, 0.086], [64572.0, 0.009], [64572.1, 10.001]], "asks": [[64572.2, 0.47], [64572.3, 0.118], [64572.4, 0.001], [64573.1, 0.01], [64573.4, 0.476], [64573.5, 0.0], [64573.9, 0.001], [64574.2, 0.002], [64574.4, 0.004], [64574.7, 0.001], [64574.8, 0.002], [64574.9, 0.002], [64575.0, 0.006], [64575.7, 0.312], [64575.9, 0.007], [64576.0, 1.102], [64576.1, 0.001], [64576.5, 0.002], [64576.8, 0.086], [64576.9, 0.001], [64577.2, 0.0], [64577.3, 0.007], [64577.4, 0.008], [64577.9, 1.632], [64578.0, 2.671], [64578.1, 0.002], [64578.3, 0.549], [64578.7, 0.101], [64579.1, 0.084], [64579.4, 0.122], [64579.6, 0.244], [64579.8, 0.4], [64579.9, 0.0], [64580.0, 0.125], [64580.1, 0.312], [64580.2, 0.086], [64580.3, 0.084], [64580.4, 0.041], [64580.5, 7.221], [64580.6, 41.72], [64580.8, 0.014], [64581.0, 0.064], [64581.4, 0.407], [64582.0, 0.374], [64582.4, 0.048], [64582.5, 0.024], [64583.3, 0.001], [64584.0, 0.836], [64585.0, 0.236], [64587.5, 0.084], [64587.6, 0.493], [64587.7, 0.007], [64588.2, 0.852], [64589.1, 0.024], [64589.2, 2.32], [64589.5, 0.002], [64590.0, 1.257], [64590.2, 0.345], [64590.4, 0.007], [64590.6, 0.002], [64590.9, 0.66], [64591.0, 0.016], [64591.1, 0.01], [64591.3, 0.687], [64591.5, 0.003], [64592.0, 0.026], [64592.4, 0.011], [64592.5, 0.001], [64592.7, 0.12], [64592.9, 1.556], [64593.5, 0.032], [64593.9, 0.211], [64594.1, 0.003], [64594.2, 0.671], [64594.4, 0.455], [64594.8, 1.238], [64594.9, 0.044], [64595.0, 0.702], [64595.4, 0.628], [64595.6, 2.494], [64595.7, 0.321], [64595.8, 0.447], [64595.9, 0.296], [64596.1, 0.003], [64597.1, 0.473], [64597.2, 0.091], [64597.4, 0.005], [64597.6, 0.008], [64597.7, 0.618], [64597.9, 0.014], [64598.4, 2.564], [64598.6, 0.058], [64598.9, 0.016], [64599.4, 0.018], [64599.9, 0.636], [64600.0, 1.13], [64600.7, 0.3], [64602.2, 0.0], [64606.3, 0.049], [64607.6, 10.019], [64616.2, 0.212], [64619.3, 0.077], [64651.9, 0.03], [64656.8, 0.166], [64660.1, 0.013], [64666.7, 0.0], [64668.9, 37.179], [64669.9, 5.933], [64679.3, 0.004], [64683.8, 0.0], [64685.9, 2.323], [64700.2, 0.102], [64700.4, 0.002], [64700.8, 1.178], [64701.1, 0.112], [64712.9, 1.215], [64717.8, 4.907], [64753.0, 1.349], [64757.7, 6.603], [64757.8, 41.387], [64827.9, 0.305], [65217.9, 0.0], [65407.7, 0.002], [65572.2, 0.022], [65863.6, 0.024]]}
{"kind": "depth", "E": 1787089564313, "U": 11315993922819, "u": 11315993933063, "recv_ms": 1787089564273, "bids": [[1000.0, 35.76], [14372.1, 1.988], [14472.1, 2.212], [51658.0, 0.0], [58114.8, 0.067], [61343.4, 0.0], [63280.7, 0.032], [63926.4, 1.408], [64370.6, 0.812], [64380.1, 2.047], [64390.9, 0.53], [64495.3, 0.011], [64499.7, 0.015], [64501.9, 30.955], [64502.0, 4.828], [64545.7, 0.0], [64546.8, 0.0], [64548.2, 0.057], [64557.9, 0.001], [64558.6, 0.069], [64560.5, 0.157], [64561.9, 0.124], [64562.0, 0.928], [64562.7, 0.0], [64562.9, 2.097], [64563.0, 0.016], [64563.1, 0.0], [64563.5, 0.001], [64566.0, 0.191], [64566.4, 1.168], [64566.6, 0.343], [64566.7, 0.09], [64568.3, 0.001], [64568.6, 0.085], [64568.9, 0.002], [64569.6, 0.298], [64569.8, 0.102], [64569.9, 0.24], [64570.0, 0.006], [64570.1, 0.0], [64570.2, 2.098], [64570.6, 0.312], [64570.7, 0.007], [64571.2, 0.001], [64571.3, 0.047], [64571.5, 0.054], [64571.6, 0.986], [64571.7, 0.0], [64572.0, 0.016], [64572.1, 9.742]], "asks": [[64572.2, 0.478], [64572.8, 0.002], [64573.2, 0.001], [64573.3, 0.007], [64573.4, 0.383], [64573.6, 0.0], [64573.9, 0.0], [64574.6, 0.001], [64574.8, 0.001], [64575.0, 0.001], [64575.6, 1.272], [64575.7, 0.396], [64575.9, 1.808], [64576.1, 0.085], [64576.3, 0.017], [64576.4, 0.084], [64577.3, 0.087], [64577.4, 1.823], [64577.9, 1.624], [64579.1, 0.091], [64579.6, 0.004], [64579.7, 0.067], [64579.8, 0.316], [64580.0, 0.111], [64580.1, 0.311], [64580.2, 0.01], [64580.3, 0.084], [64580.4, 0.583], [64580.5, 9.541], [64583.3, 0.161], [64584.0, 3.155], [64585.8, 1.482], [64586.6, 2.543], [64587.3, 0.466], [64587.5, 0.007], [64587.9, 1.617], [64589.1, 0.101], [64591.3, 0.145], [64592.0, 0.026], [64592.5, 0.543], [64592.9, 0.629], [64593.2, 0.001], [64593.6, 0.435], [64594.4, 1.382], [64595.0, 0.737], [64595.2, 0.174], [64595.5, 0.004], [64598.1, 0.502], [64598.6, 0.001], [64599.0, 4.004], [64599.5, 0.01], [64600.2, 0.225], [64600.6, 0.0], [64600.7, 0.28], [64602.1, 0.019], [64603.2, 0.516], [64606.7, 0.038], [64608.3, 1.07], [64612.3, 0.079], [64613.3, 0.0], [64623.0, 0.078], [64655.7, 39.599], [64656.0, 0.003], [64659.8, 2.299], [64660.1, 0.013], [64667.4, 0.211], [64668.9, 0.001], [64669.8, 0.008], [64673.5, 0.885], [64675.5, 0.0], [64678.7, 2.519], [64681.8, 0.022], [64707.4, 0.897], [64707.5, 1.478], [64707.6, 0.0], [64729.6, 1.378], [64729.8, 0.003], [64732.9, 1.633], [64734.8, 10.427], [64846.6, 0.015], [64870.0, 0.032], [64930.0, 0.437], [65217.9, 0.0], [65379.4, 2.542], [65469.8, 1.525]]}
{"kind": "depth", "E": 1787089564415, "U": 11315993933183, "u": 11315993942065, "recv_ms": 1787089564375, "bids": [[14372.1, 2.338], [14472.1, 1.862], [51658.0, 0.0], [58114.8, 0.067], [61343.4, 0.0], [61989.2, 0.0], [63015.8, 0.68], [63572.1, 0.018], [63764.9, 1.319], [63926.4, 1.408], [64547.8, 1.043], [64548.0, 1.522], [64558.6, 0.007], [64559.6, 1.432], [64563.0, 0.0], [64563.5, 0.001], [64564.8, 0.522], [64566.0, 0.308], [64566.5, 0.002], [64566.7, 1.646], [64566.8, 0.634], [64567.3, 0.139], [64569.5, 0.003], [64569.6, 0.483], [64569.8, 0.002], [64569.9, 0.239], [64570.2, 0.0], [64570.3, 0.0], [64570.4, 0.628], [64571.6, 0.736], [64571.7, 0.005], [64572.1, 10.348]], "asks": [[64572.2, 0.478], [64572.8, 0.003], [64573.3, 0.007], [64574.0, 0.003], [64575.5, 0.939], [64575.6, 0.337], [64577.4, 1.809], [64580.0, 0.125], [64584.3, 0.004], [64586.5, 0.158], [64590.2, 0.334], [64595.2, 0.173], [64610.6, 0.096], [64611.0, 0.08], [64611.6, 0.311], [64619.1, 2.32], [64623.0, 0.077], [64649.1, 37.278], [64653.5, 0.041], [64655.7, 2.321], [65217.9, 0.0], [65377.6, 4.79], [65572.2, 0.002]]}
{"kind": "depth", "E": 1787089564517, "U": 11315993942280, "u": 11315993950541, "recv_ms": 1787089564476, "bids": [[1000.0, 35.76], [14372.1, 2.688], [14472.1, 1.512], [58114.8, 0.067], [61343.4, 0.0], [61989.2, 0.003], [63926.4, 1.408], [64249.2, 4.486], [64495.3, 30.889], [64501.9, 0.077], [64528.5, 0.148], [64530.8, 2.361], [64538.3, 0.005], [64545.6, 9.963], [64545.7, 0.057], [64547.5, 0.016], [64548.0, 1.522], [64548.2, 0.0], [64551.7, 0.002], [64558.6, 0.014], [64559.7, 0.009], [64561.2, 1.088], [64562.0, 0.001], [64562.1, 0.542], [64562.9, 1.555], [64563.5, 0.002], [64565.0, 0.413], [64566.6, 0.345], [64569.5, 0.001], [64569.7, 3.558], [64570.5, 0.02], [64571.4, 0.003], [64571.7, 0.0], [64572.0, 0.011], [64572.1, 6.862]], "asks": [[64572.2, 0.507], [64573.1, 0.01], [64573.2, 0.001], [64573.3, 1.4], [64574.0, 0.003], [64574.8, 1.802], [64575.1, 0.09], [64575.5, 0.004], [64576.1, 0.087], [64577.8, 0.077], [64577.9, 1.624], [64578.4, 0.007], [64579.4, 0.038], [64579.8, 0.314], [64580.2, 0.002], [64580.3, 0.284], [64580.6, 41.719], [64586.4, 0.634], [64591.8, 0.025], [64593.1, 0.929], [64594.4, 0.455], [64595.7, 0.32], [64597.7, 0.675], [64600.2, 0.168], [64601.1, 0.677], [64603.1, 5.089], [64606.3, 0.034], [64611.0, 0.079], [64616.2, 0.17], [64667.4, 0.011], [64678.7, 2.319], [65217.9, 0.002], [65270.5, 4.59], [65372.9, 0.0], [65417.9, 0.3]]}
{"kind": "depth", "E": 1787089564619, "U": 11315993950592, "u": 11315993957946, "recv_ms": 1787089564577, "bids": [[1000.0, 35.96], [14372.1, 3.052], [14472.1, 1.148], [58114.8, 0.067], [61989.2, 0.0], [63572.1, 0.038], [63614.5, 6.711], [63646.2, 0.0], [63782.3, 0.103], [63926.4, 1.408], [64495.3, 0.011], [64499.7, 0.015], [64501.9, 30.955], [64530.8, 2.321], [64545.2, 0.604], [64557.5, 2.322], [64559.6, 1.925], [64560.1, 0.002], [64560.5, 0.002], [64560.6, 0.948], [64561.2, 0.161], [64562.9, 1.71], [64571.3, 0.001], [64572.1, 6.861]], "asks": [[64573.1, 0.01], [64573.2, 0.001], [64573.3, 1.4], [64577.8, 0.069], [64580.2, 0.01], [64607.6, 0.019], [64610.6, 0.095], [64616.2, 0.212], [64646.9, 37.278], [64649.1, 0.0], [64846.6, 0.215], [65217.9, 0.0], [65572.2, 0.022]]}
{"kind": "depth", "E": 1787089564721, "U": 11315993958254, "u": 11315993966437, "recv_ms": 1787089564680, "bids": [[14372.1, 3.416], [14472.1, 0.784], [58114.8, 0.067], [63653.5, 0.234], [63926.4, 1.408], [64507.4, 0.006], [64507.7, 0.0], [64508.0, 0.002], [64508.3, 4.863], [64508.7, 0.134], [64526.7, 0.0], [64527.0, 0.003], [64527.3, 0.0], [64527.6, 0.037], [64527.7, 0.058], [64527.9, 2.63], [64528.0, 0.095], [64528.3, 0.034], [64528.6, 0.036], [64541.6, 1.668], [64541.7, 0.034], [64541.8, 0.002], [64541.9, 0.001], [64542.0, 0.001], [64542.1, 0.001], [64542.2, 0.018], [64542.3, 0.979], [64542.4, 0.433], [64542.6, 0.002], [64545.2, 0.504], [64545.6, 9.863], [64563.0, 0.016], [64563.4, 0.708], [64564.1, 0.002], [64564.2, 0.004], [64564.3, 0.0], [64564.4, 0.016], [64564.5, 0.003], [64564.6, 0.004], [64564.7, 0.004], [64564.8, 0.322], [64564.9, 0.0], [64565.0, 0.313], [64565.1, 0.071], [64565.3, 0.071], [64565.6, 0.086], [64565.7, 0.0], [64566.0, 0.276], [64566.3, 2.352], [64566.4, 0.808], [64566.6, 0.345], [64566.7, 0.09], [64566.8, 0.0], [64567.0, 0.033], [64567.3, 0.147], [64569.6, 0.298], [64569.8, 1.566], [64569.9, 0.155]], "asks": [[64572.9, 1.396], [64573.0, 0.0], [64573.1, 0.01], [64573.2, 0.001], [64573.3, 0.007], [64574.7, 0.085], [64577.3, 0.015], [64577.9, 0.005], [64578.4, 0.006], [64579.1, 0.007], [64579.7, 0.0], [64580.0, 0.058], [64580.2, 0.075], [64580.3, 0.209], [64580.6, 41.645], [64581.0, 0.0], [64581.2, 0.003], [64581.4, 0.0], [64581.5, 0.0], [64581.6, 0.009], [64581.7, 0.02], [64581.8, 0.002], [64581.9, 0.002], [64582.0, 0.073], [64582.1, 0.083], [64582.2, 0.002], [64582.9, 0.081], [64583.2, 0.074], [64583.5, 0.74], [64583.8, 0.076], [64584.8, 0.153], [64585.1, 0.142], [64586.5, 0.147], [64599.0, 3.937], [64599.3, 2.043], [64599.6, 0.061], [64600.0, 1.056], [64600.3, 0.008], [64600.7, 0.02], [64601.1, 0.407], [64602.2, 0.067], [64602.5, 0.078], [64602.8, 0.084], [64603.1, 5.163], [64603.7, 0.0], [64603.9, 0.003], [64604.0, 0.002], [64604.1, 0.002], [64604.2, 2.321], [64604.3, 1.133], [64604.4, 0.003], [64604.5, 0.0], [64604.6, 0.093], [64604.7, 0.175], [64607.3, 0.142], [64607.6, 0.159], [64618.3, 0.0], [64618.7, 0.001], [64618.9, 0.001], [64619.3, 0.003], [64619.6, 0.003], [64621.5, 3.567], [64621.8, 0.071], [64622.1, 0.083], [64622.5, 0.35], [64649.5, 0.0], [64650.2, 2.335], [64656.5, 0.001], [64657.3, 0.013], [64663.6, 0.0], [64664.3, 0.013], [64670.6, 0.001], [64671.4, 0.04], [64677.7, 0.0], [64678.4, 0.019], [64684.8, 1.898], [64685.5, 0.019], [64691.8, 0.661], [64692.6, 0.014], [64698.9, 0.048], [64699.6, 0.013], [65217.9, 0.0], [65500.5, 4.418], [65629.6, 0.001]]}
{"kind": "depth", "E": 1787089564823, "U": 11315993966485, "u": 11315993974487, "recv_ms": 1787089564807, "bids": [[1000.0, 35.96], [14272.1, 0.028], [14372.1, 3.71], [14472.1, 0.462], [51658.0, 0.0], [58114.8, 0.067], [61343.4, 0.0], [61989.2, 0.003], [63572.1, 0.018], [63635.8, 5.495], [63659.1, 4.712], [63797.2, 12.132], [63803.7, 5.086], [63926.4, 1.408], [64249.2, 4.486], [64495.3, 0.011], [64499.7, 30.801], [64501.9, 0.077], [64502.0, 8.217], [64547.1, 2.087], [64555.3, 0.005], [64564.8, 0.392], [64565.3, 0.171], [64565.4, 0.424], [64565.5, 0.118], [64566.7, 0.09], [64569.0, 0.085], [64569.8, 0.002], [64569.9, 0.155], [64570.0, 0.006], [64570.7, 0.015], [64570.8, 1.594], [64570.9, 0.008], [64572.1, 6.86]], "asks": [[64572.2, 0.508], [64572.9, 0.003], [64573.0, 0.0], [64573.1, 1.403], [64573.2, 0.001], [64583.9, 1.29], [64584.0, 2.327], [64584.6, 0.147], [64584.7, 0.25], [64584.9, 0.22], [64585.4, 0.453], [64587.7, 0.005], [64595.5, 1.252], [64607.1, 0.263], [64607.2, 0.316], [64607.4, 0.223], [64607.9, 0.163], [64646.8, 6.367], [64646.9, 37.434], [64660.1, 0.013], [64668.8, 1.12], [64895.1, 2.619], [65217.9, 0.0], [65264.5, 0.535], [65572.2, 0.002]]}
{"kind": "depth", "E": 1787089564925, "U": 11315993974509, "u": 11315993982768, "recv_ms": 1787089564882, "bids": [[1000.0, 35.96], [14272.1, 0.196], [14372.1, 3.724], [14472.1, 0.28], [51657.7, 0.0], [58114.8, 0.067], [61989.2, 0.0], [63616.6, 4.406], [63666.4, 11.457], [63926.4, 1.408], [64232.1, 0.001], [64232.2, 0.493], [64249.2, 4.487], [64432.1, 0.022], [64527.3, 0.032], [64546.3, 0.135], [64549.5, 1.089], [64555.3, 0.007], [64564.8, 0.462], [64564.9, 0.07], [64565.0, 0.383], [64565.1, 0.171], [64565.2, 0.201], [64565.6, 0.192], [64566.0, 0.308], [64566.5, 0.01], [64566.7, 0.09], [64570.5, 0.001], [64570.7, 0.007], [64570.8, 0.046], [64570.9, 0.008], [64571.0, 0.0], [64571.1, 0.0], [64571.7, 1.548], [64572.0, 0.013]], "asks": [[64573.1, 0.01], [64573.2, 1.394], [64584.2, 0.064], [64584.5, 0.264], [64584.9, 0.74], [64585.0, 0.506], [64585.2, 2.405], [64585.3, 0.28], [64587.7, 0.007], [64603.5, 0.097], [64603.9, 0.263], [64604.3, 1.403], [64607.4, 0.473], [64607.5, 0.291], [64607.7, 0.163], [64607.8, 0.35], [64622.8, 0.064], [64717.8, 0.001], [65187.0, 0.018], [65217.9, 0.0]]}
{"kind": "depth", "E": 1787089565027, "U": 11315993982821, "u": 11315993991697, "recv_ms": 1787089564985, "bids": [[14272.1, 0.448], [14372.1, 3.584], [14472.1, 0.168], [58114.8, 0.067], [61989.2, 0.003], [63572.1, 0.038], [63635.8, 6.594], [63655.2, 0.716], [63926.4, 1.408], [64432.1, 4.212], [64508.3, 4.895], [64508.6, 0.882], [64509.0, 1.249], [64509.3, 0.046], [64549.5, 1.108], [64563.0, 0.008], [64563.4, 0.074], [64564.9, 0.14], [64565.5, 0.218], [64565.7, 0.07], [64566.5, 0.002], [64566.7, 0.09], [64566.8, 0.0], [64569.6, 0.298], [64569.8, 2.208], [64570.9, 0.0], [64571.7, 0.0]], "asks": [[64573.0, 0.0], [64573.1, 1.403], [64573.2, 0.001], [64574.7, 0.705], [64575.6, 0.002], [64576.1, 0.085], [64577.5, 0.002], [64580.2, 0.074], [64580.6, 41.646], [64584.4, 0.515], [64584.7, 0.53], [64585.2, 2.559], [64598.0, 0.131], [64600.0, 0.94], [64606.9, 0.161], [64607.2, 0.596], [64607.7, 0.317], [64712.9, 6.624], [64768.6, 11.277], [64895.1, 2.618], [65217.9, 0.0], [65276.0, 2.229], [65508.5, 17.071], [65572.2, 0.022], [65637.6, 4.443]]}
{"kind": "depth", "E": 1787089565129, "U": 11315993992057, "u": 11315994001087, "recv_ms": 1787089565093, "bids": [[1000.0, 35.96], [14272.1, 0.686], [14372.1, 3.472], [14472.1, 0.042], [51658.0, 0.0], [58114.8, 0.067], [61343.4, 0.001], [61989.2, 0.0], [63280.7, 0.029], [63552.0, 3.91], [63663.3, 0.94], [63926.4, 1.408], [64055.5, 5.144], [64249.2, 4.488], [64461.0, 0.063], [64467.9, 0.001], [64469.0, 0.092], [64475.0, 0.115], [64494.6, 0.047], [64498.2, 0.149], [64501.9, 0.062], [64503.5, 0.006], [64513.9, 0.05], [64526.2, 3.533], [64528.5, 0.129], [64529.5, 0.002], [64542.5, 0.071], [64542.8, 0.178], [64548.0, 2.141], [64555.4, 0.62], [64560.5, 0.929], [64560.6, 0.021], [64561.4, 0.002], [64561.9, 0.666], [64562.1, 0.0], [64563.0, 0.008], [64566.6, 0.343], [64567.5, 0.232], [64567.6, 0.005], [64568.1, 0.0], [64570.5, 0.02], [64572.1, 6.855]], "asks": [[64572.2, 0.508], [64573.0, 0.0], [64573.1, 0.01], [64573.2, 1.394], [64573.3, 0.007], [64574.5, 0.446], [64574.6, 0.001], [64578.1, 0.0], [64578.4, 0.006], [64578.8, 0.001], [64580.5, 9.542], [64580.6, 41.645], [64584.4, 0.516], [64589.1, 0.086], [64591.3, 0.687], [64591.4, 2.733], [64592.5, 0.001], [64592.9, 1.571], [64593.1, 0.002], [64593.8, 0.0], [64597.7, 0.618], [64598.0, 0.015], [64598.4, 2.571], [64598.5, 2.376], [64598.8, 0.769], [64599.9, 0.629], [64630.4, 1.237], [64649.7, 0.001], [65174.1, 0.765], [65217.9, 0.0]]}
{"kind": "depth", "E": 1787089565231, "U": 11315994001202, "u": 11315994008590, "recv_ms": 1787089565189, "bids": [[1000.0, 36.16], [14272.1, 0.994], [14372.1, 3.206], [14472.1, 0.0], [51658.0, 0.0], [58114.8, 0.067], [61343.4, 0.001], [63572.1, 0.018], [63926.4, 1.408], [63934.8, 0.044], [64467.2, 0.015], [64467.3, 0.025], [64468.7, 0.035], [64495.2, 0.252], [64495.3, 0.011], [64499.7, 30.801], [64502.0, 4.828], [64508.0, 0.034], [64539.3, 0.003], [64539.4, 0.009], [64539.5, 0.004], [64542.3, 1.049], [64542.8, 0.176], [64542.9, 0.49], [64543.0, 0.089], [64545.8, 0.1], [64546.3, 0.235], [64564.9, 0.147], [64565.5, 0.189], [64567.3, 0.128], [64571.8, 0.006], [64572.0, 0.013], [64572.1, 6.857]], "asks": [[64573.1, 0.01], [64573.2, 1.394], [64574.2, 0.002], [64574.3, 0.001], [64574.4, 0.004], [64574.5, 0.003], [64574.8, 1.816], [64577.9, 0.005], [64579.6, 0.076], [64579.9, 0.001], [64580.2, 0.002], [64580.3, 0.209], [64580.5, 9.541], [64587.8, 0.0], [64589.0, 0.082], [64589.1, 0.009], [64595.2, 0.174], [64846.6, 0.015], [65217.9, 0.0], [65270.4, 3.06], [65572.2, 0.002], [65863.6, 0.027]]}
{"kind": "depth", "E": 1787089565333, "U": 11315994008678, "u": 11315994017440, "recv_ms": 1787089565292, "bids": [[14272.1, 1.358], [14372.1, 2.842], [58114.8, 0.067], [61343.4, 0.0], [61343.5, 0.012], [61343.6, 0.009], [61989.2, 0.003], [63926.4, 1.408], [63989.2, 1.095], [64469.6, 2.323], [64469.8, 3.6], [64542.3, 1.119], [64542.4, 0.503], [64542.5, 0.141], [64542.6, 0.102], [64542.7, 0.1], [64556.0, 0.561], [64556.4, 0.0], [64562.5, 0.311], [64562.9, 1.4], [64564.3, 0.31], [64565.5, 0.17], [64566.6, 0.385], [64567.5, 0.0], [64567.6, 0.237], [64568.2, 0.085], [64569.5, 0.008], [64571.8, 0.002], [64572.0, 0.01], [64572.1, 6.869]], "asks": [[64573.1, 0.01], [64573.2, 0.001], [64577.3, 0.015], [64579.9, 0.0], [64580.2, 0.003], [64580.3, 0.209], [64589.1, 0.009], [64590.6, 0.01], [64591.1, 0.002], [64592.0, 0.034], [64592.4, 0.003], [64595.2, 0.173], [64596.4, 0.599], [64597.7, 0.061], [64598.4, 2.564], [64598.8, 0.776], [64684.0, 6.966], [64685.9, 0.0], [65185.6, 1.301], [65217.9, 0.0], [65370.1, 0.855], [65379.4, 2.77]]}
{"kind": "depth", "E": 1787089565435, "U": 11315994017535, "u": 11315994026684, "recv_ms": 1787089565392, "bids": [[1000.0, 36.16], [14272.1, 1.708], [14372.1, 2.492], [58114.8, 0.067], [61343.4, 0.0], [61989.2, 0.0], [63571.2, 4.408], [63572.1, 0.038], [63573.1, 0.002], [63674.5, 2.491], [63926.4, 1.41], [63939.2, 0.004], [64249.2, 4.488], [64432.1, 0.022], [64477.9, 1.708], [64495.3, 0.011], [64499.7, 30.801], [64542.4, 0.573], [64543.0, 0.189], [64543.2, 0.173], [64566.8, 0.02], [64571.8, 0.002], [64572.0, 0.01], [64572.1, 6.872]], "asks": [[64573.0, 1.393], [64573.1, 0.01], [64573.3, 0.0], [64577.9, 0.005], [64580.2, 0.002], [64580.3, 0.209], [64580.6, 41.646], [64582.4, 0.028], [64598.7, 0.168], [64644.7, 37.435], [64646.8, 0.859], [64646.9, 0.0], [64712.9, 1.215], [65217.9, 0.0], [65572.2, 0.022], [65742.2, 0.781], [65917.6, 0.0]]}
{"kind": "depth", "E": 1787089565537, "U": 11315994026688, "u": 11315994036001, "recv_ms": 1787089565495, "bids": [[1000.0, 36.16], [14272.1, 2.058], [14372.1, 2.142], [51658.0, 0.0], [58114.8, 0.067], [61333.7, 0.0], [61343.4, 0.0], [61989.2, 0.003], [63280.7, 0.032], [63926.4, 1.408], [63947.4, 1.453], [64432.1, 3.74], [64495.3, 30.797], [64499.7, 0.015], [64559.9, 0.021], [64560.1, 0.329], [64562.7, 0.114], [64566.6, 0.366], [64567.6, 0.005], [64568.1, 0.232]], "asks": [[64573.0, 1.393], [64573.1, 0.01], [64573.2, 0.001], [64580.6, 41.645], [64582.5, 0.043], [64591.3, 0.145], [64592.0, 0.576], [64596.2, 0.03], [64598.7, 0.014], [64598.8, 0.93], [64601.1, 0.392], [64712.8, 5.436], [65217.9, 0.0], [65332.6, 1.838], [65379.4, 2.998], [65741.1, 0.653], [65863.6, 0.024]]}
{"kind": "depth", "E": 1787089565639, "U": 11315994036125, "u": 11315994044180, "recv_ms": 1787089565597, "bids": [[14272.1, 2.422], [14372.1, 1.778], [58114.8, 0.067], [61343.4, 0.0], [63531.2, 1.249], [63572.1, 0.018], [63648.9, 24.008], [63926.4, 1.408], [63958.7, 1.484], [64571.2, 0.042], [64572.1, 6.871]], "asks": [[64572.2, 0.508], [64573.0, 1.393], [64573.1, 0.01], [64592.9, 0.644], [64593.3, 1.022], [64596.4, 0.042], [64596.9, 0.557], [64598.8, 0.776], [64598.9, 0.17], [65217.9, 0.0], [65572.2, 0.002]]}
{"kind": "depth", "E": 1787089565741, "U": 11315994044364, "u": 11315994052188, "recv_ms": 1787089565699, "bids": [[1000.0, 36.16], [14272.1, 2.772], [14372.1, 1.428], [34000.0, 1.146], [51658.0, 0.0], [58114.8, 0.067], [61989.2, 0.0], [63538.9, 3.305], [63597.2, 0.667], [63926.4, 1.408], [64249.2, 4.478], [64495.3, 0.011], [64499.7, 30.801], [64548.0, 1.987], [64548.2, 0.154], [64566.8, 0.0], [64568.0, 0.022], [64572.1, 6.869]], "asks": [[64573.0, 0.0], [64573.1, 0.01], [65217.9, 0.0], [65340.6, 5.35], [65933.0, 0.159]]}
{"kind": "depth", "E": 1787089565843, "U": 11315994052199, "u": 11315994060408, "recv_ms": 1787089565800, "bids": [[1000.0, 36.16], [14272.1, 3.136], [14372.1, 1.064], [58114.8, 0.067], [61989.2, 0.003], [63572.1, 0.038], [63926.4, 1.408], [64502.0, 8.214], [64543.2, 2.15], [64555.3, 0.005], [64560.1, 0.002], [64562.7, 0.0], [64572.0, 0.013]], "asks": [[64573.0, 0.0], [64573.1, 1.403], [64587.7, 0.005], [64605.1, 1.342], [64643.4, 8.796], [65217.9, 0.0], [65347.1, 14.25], [65572.2, 0.022], [65583.4, 6.091], [65669.9, 7.145]]}
{"kind": "depth", "E": 1787089565945, "U": 11315994060536, "u": 11315994068637, "recv_ms": 1787089565904, "bids": [[14272.1, 3.486], [14372.1, 0.714], [51657.7, 0.0], [58114.8, 0.067], [61989.2, 0.0], [63926.4, 1.408], [64231.9, 0.493], [64232.2, 0.0], [64249.2, 4.477], [64432.1, 0.022], [64495.3, 30.797], [64499.7, 0.015], [64502.0, 4.828], [64507.5, 0.327], [64555.3, 0.007], [64572.0, 0.01]], "asks": [[64573.0, 1.393], [64573.1, 0.01], [64587.7, 0.007], [64636.8, 0.004], [64712.8, 0.027], [65217.9, 0.0], [65456.4, 21.518], [65474.5, 5.215], [65660.2, 1.214]]}
{"kind": "depth", "E": 1787089566047, "U": 11315994068695, "u": 11315994077482, "recv_ms": 1787089566007, "bids": [[1000.0, 36.16], [14172.1, 0.056], [14272.1, 3.738], [14372.1, 0.406], [58114.8, 0.067], [61343.4, 0.0], [61989.2, 0.003], [63572.1, 0.018], [63926.4, 1.408], [64249.2, 4.476], [64415.1, 6.033], [64415.2, 0.002], [64416.0, 1.969], [64432.1, 3.74], [64555.5, 0.156], [64555.7, 0.176], [64556.0, 0.003], [64556.4, 0.558], [64556.8, 1.028], [64560.5, 0.934], [64566.6, 0.343], [64567.6, 0.237], [64568.1, 0.0], [64569.8, 0.584], [64569.9, 1.78], [64572.1, 6.872]], "asks": [[64572.2, 0.508], [64573.0, 0.0], [64573.1, 0.01], [64573.3, 1.393], [64574.6, 0.001], [64578.8, 0.001], [64580.2, 0.003], [64580.6, 41.644], [64589.0, 0.005], [64589.1, 0.086], [64598.3, 0.27], [64598.8, 0.653], [64599.2, 0.007], [64616.2, 0.17], [64642.0, 0.005], [64651.9, 0.027], [64712.8, 5.436], [64729.8, 10.431], [64732.9, 0.087], [64734.8, 0.0], [64895.1, 2.619], [65217.9, 0.0], [65476.2, 13.026], [65572.2, 0.002], [65605.4, 5.33]]}
{"kind": "depth", "E": 1787089566149, "U": 11315994077747, "u": 11315994085733, "recv_ms": 1787089566107, "bids": [[1000.0, 36.16], [14172.1, 0.252], [14272.1, 3.696], [14372.1, 0.252], [58114.8, 0.067], [61343.6, 0.007], [63666.9, 2.507], [63821.7, 5.646], [63926.4, 1.408], [64461.0, 0.062], [64467.9, 0.0], [64475.0, 0.114], [64493.7, 0.004], [64495.0, 0.409], [64495.3, 0.011], [64498.2, 0.148], [64499.7, 30.748], [64501.0, 0.407], [64503.5, 0.005], [64524.2, 0.353], [64529.4, 0.003], [64529.5, 0.001], [64560.5, 0.002], [64561.3, 0.928], [64561.9, 0.124], [64562.9, 1.942], [64569.6, 0.382]], "asks": [[64573.3, 0.0], [64580.2, 0.002], [64580.6, 41.645], [64581.3, 0.468], [64584.4, 0.515], [64593.3, 0.095], [64593.8, 0.927], [64598.9, 0.016], [65217.9, 0.0], [65379.4, 3.485], [65476.2, 15.314], [65682.8, 0.761]]}
{"kind": "depth", "E": 1787089566251, "U": 11315994085743, "u": 11315994093787, "recv_ms": 1787089566209, "bids": [[14172.1, 0.504], [14272.1, 3.556], [14372.1, 0.14], [58114.8, 0.067], [61343.4, 0.0], [61343.5, 0.01], [61343.6, 0.009], [61989.2, 0.0], [63572.1, 0.038], [63926.4, 1.408], [63988.2, 0.0], [64486.9, 0.001], [64494.6, 0.05], [64495.3, 30.744], [64499.7, 0.015], [64504.9, 0.103], [64521.2, 0.476], [64561.9, 0.124], [64562.5, 0.312], [64562.9, 1.942], [64563.5, 0.001], [64563.7, 0.013], [64572.0, 0.013], [64572.1, 6.869]], "asks": [[64573.3, 1.393], [64574.6, 0.001], [64574.7, 0.621], [64574.8, 1.816], [64577.9, 0.013], [64579.0, 0.02], [64580.3, 0.201], [64580.6, 41.645], [64581.3, 0.467], [64583.2, 0.075], [64592.0, 0.034], [64592.5, 0.543], [64598.3, 0.154], [64598.7, 0.13], [64598.9, 0.17], [64649.7, 0.004], [64895.1, 2.62], [65167.2, 0.001], [65217.9, 0.0], [65405.7, 0.4], [65572.2, 0.022]]}
{"kind": "depth", "E": 1787089566353, "U": 11315994093883, "u": 11315994102107, "recv_ms": 1787089566311, "bids": [[1000.0, 36.16], [14172.1, 0.742], [14272.1, 3.444], [14372.1, 0.014], [51658.0, 0.0], [58114.8, 0.067], [61343.4, 0.0], [61989.2, 0.003], [63655.2, 0.95], [63674.5, 3.4], [63829.5, 0.939], [63926.4, 1.408], [64010.3, 2.357], [64089.6, 0.0], [64249.2, 4.486], [64457.6, 3.872], [64457.7, 0.0], [64469.5, 2.325], [64469.6, 0.0], [64501.8, 0.05], [64501.9, 0.016], [64548.0, 1.368], [64555.4, 0.001], [64561.9, 0.666], [64562.9, 1.4], [64565.6, 0.108], [64570.2, 0.084], [64572.0, 0.01], [64572.1, 6.87]], "asks": [[64572.2, 0.486], [64573.1, 1.403], [64573.2, 0.001], [64573.3, 0.0], [64574.8, 1.802], [64575.0, 0.002], [64575.1, 0.006], [64577.9, 0.005], [64578.5, 0.108], [64579.1, 0.0], [64580.3, 0.009], [64591.4, 2.114], [64594.0, 0.002], [64596.9, 0.0], [64597.4, 0.562], [64598.8, 0.034], [64601.4, 1.96], [64644.0, 3.605], [64644.1, 6.0], [64683.3, 2.323], [64684.0, 4.643], [64713.2, 3.92], [64713.3, 0.031], [64846.6, 0.215], [65217.9, 0.0], [65290.5, 1.691], [65863.6, 0.027]]}
{"kind": "depth", "E": 1787089566455, "U": 11315994102172, "u": 11315994109448, "recv_ms": 1787089566413, "bids": [[1000.0, 36.16], [14172.1, 1.078], [14272.1, 3.122], [14372.1, 0.0], [58114.8, 0.067], [61343.4, 0.0], [61989.2, 0.0], [63572.1, 0.018], [63926.4, 1.408], [64494.6, 0.05], [64495.3, 0.011], [64499.7, 30.748], [64513.9, 0.047], [64560.9, 0.928], [64561.3, 0.001], [64572.0, 0.013]], "asks": [[64572.2, 0.484], [64573.1, 1.403], [64573.2, 0.001], [64598.9, 0.016], [64630.4, 1.237], [64649.7, 0.001], [64768.5, 13.738], [64768.6, 0.002], [65187.8, 1.302], [65217.9, 0.0], [65411.7, 1.072], [65572.2, 0.002]]}
{"kind": "depth", "E": 1787089566557, "U": 11315994109591, "u": 11315994117139, "recv_ms": 1787089566516, "bids": [[14172.1, 1.442], [14272.1, 2.758], [51658.0, 0.0], [58114.8, 0.067], [61989.2, 0.003], [63158.1, 2.034], [63655.2, 1.184], [63668.1, 5.176], [63797.2, 12.915], [63926.4, 1.408], [64562.5, 0.311], [64562.8, 1.171], [64567.8, 0.046], [64567.9, 0.001], [64568.0, 0.003], [64572.0, 0.01], [64572.1, 6.873]], "asks": [[64572.2, 0.484], [64572.9, 0.003], [64573.0, 0.0], [64573.1, 0.01], [64583.2, 0.074], [64583.5, 0.74], [64587.8, 0.0], [64589.0, 0.013], [64589.1, 0.078], [64598.8, 0.034], [64599.0, 4.091], [64741.0, 0.065], [65217.9, 0.0], [65863.6, 0.024]]}
{"kind": "depth", "E": 1787089566659, "U": 11315994117283, "u": 11315994126061, "recv_ms": 1787089566618, "bids": [[1000.0, 36.16], [14172.1, 1.792], [14272.1, 2.408], [58114.8, 0.067], [63572.1, 0.038], [63668.1, 5.364], [63926.4, 1.408], [64112.9, 0.475], [64249.2, 4.476], [64457.6, 3.872], [64501.8, 0.05], [64563.0, 0.0], [64569.8, 0.552]], "asks": [[64573.0, 0.0], [64573.1, 0.01], [64573.2, 0.001], [64575.6, 0.001], [64575.7, 0.086], [64577.9, 0.005], [64579.5, 0.012], [64580.3, 0.009], [64582.9, 0.07], [64593.0, 0.93], [64593.8, 0.0], [64599.0, 4.091], [64643.9, 0.124], [64644.0, 3.559], [64713.2, 3.92], [65217.9, 0.002], [65339.1, 3.643], [65367.3, 2.298], [65572.2, 0.022]]}
{"kind": "depth", "E": 1787089566761, "U": 11315994126376, "u": 11315994133830, "recv_ms": 1787089566719, "bids": [[1000.0, 36.16], [14172.1, 2.142], [14272.1, 2.058], [58114.8, 0.067], [61343.5, 0.008], [61343.6, 0.011], [61989.2, 0.0], [63926.4, 1.408], [64545.1, 0.0], [64545.7, 0.0], [64547.1, 2.144], [64554.3, 0.117], [64555.5, 0.04], [64555.6, 0.558], [64556.4, 0.0], [64559.8, 0.0], [64560.1, 0.002], [64560.9, 0.001], [64561.0, 0.932], [64561.9, 0.666], [64563.0, 0.008], [64563.7, 0.013], [64570.0, 0.038], [64572.0, 0.013]], "asks": [[64573.0, 0.0], [64573.1, 0.01], [64573.2, 0.001], [64573.3, 1.393], [64574.6, 0.937], [64576.0, 1.412], [64577.9, 0.005], [64579.4, 0.038], [64580.3, 0.009], [64580.5, 9.542], [64580.6, 41.644], [64590.6, 0.01], [64592.0, 0.576], [64592.5, 0.001], [64593.0, 0.003], [64593.4, 0.001], [64594.2, 1.598], [64595.8, 0.447], [64596.9, 0.557], [64597.4, 0.005], [64597.9, 0.014], [64598.5, 2.319], [64598.9, 0.073], [64599.0, 4.091], [65080.8, 2.148], [65198.6, 0.847], [65217.9, 0.0], [65339.1, 1.809], [65456.4, 19.23], [65863.6, 0.027]]}
{"kind": "depth", "E": 1787089566863, "U": 11315994133838, "u": 11315994142596, "recv_ms": 1787089566820, "bids": [[14172.1, 2.506], [14272.1, 1.694], [51657.7, 0.002], [58114.8, 0.067], [61989.2, 0.003], [63572.1, 0.018], [63770.3, 6.27], [63926.4, 1.408], [64502.0, 8.207], [64546.0, 0.502], [64547.1, 2.087], [64560.1, 0.358], [64561.9, 0.666], [64562.7, 0.138], [64563.0, 0.008], [64572.0, 0.01]], "asks": [[64573.1, 0.01], [64573.2, 0.001], [64573.3, 0.0], [64574.6, 0.002], [64579.4, 0.038], [64580.3, 0.209], [64580.5, 9.542], [64592.0, 0.034], [64592.8, 0.8], [64593.2, 0.928], [64594.2, 0.671], [64598.9, 0.227], [64599.0, 3.937], [64599.1, 0.001], [64656.0, 0.775], [65217.9, 0.0], [65339.2, 6.053], [65572.2, 0.002], [65818.1, 2.35]]}
{"kind": "depth", "E": 1787089566965, "U": 11315994142637, "u": 11315994150894, "recv_ms": 1787089566924, "bids": [[1000.0, 36.16], [14172.1, 2.856], [14272.1, 1.344], [51657.7, 0.0], [58114.8, 0.067], [61343.4, 0.001], [61343.6, 0.009], [61989.2, 0.0], [63552.0, 2.81], [63926.4, 1.408], [64231.9, 0.0], [64232.0, 0.5], [64249.2, 4.476], [64495.3, 0.011], [64499.7, 30.709], [64502.0, 4.828], [64539.3, 0.005], [64539.4, 0.011], [64539.5, 0.006], [64542.8, 0.178], [64542.9, 0.492], [64543.0, 0.191], [64546.3, 0.216], [64548.9, 0.001], [64550.4, 0.324], [64554.3, 0.001], [64555.3, 0.007], [64555.6, 0.0], [64555.7, 0.292], [64556.9, 0.559], [64563.7, 0.013], [64564.3, 0.0], [64564.6, 0.314], [64569.9, 1.703], [64570.0, 0.115], [64572.0, 0.01], [64572.1, 6.871]], "asks": [[64573.0, 1.393], [64573.1, 0.01], [64577.9, 0.005], [64580.3, 0.209], [64587.7, 0.007], [64587.9, 1.926], [64588.2, 0.543], [64595.2, 0.174], [64596.9, 0.0], [64597.1, 1.03], [64598.4, 2.68], [64598.7, 0.014], [65217.9, 0.0], [65290.4, 0.765], [65347.1, 16.543], [65476.2, 17.601]]}
{"kind": "depth", "E": 1787089567067, "U": 11315994150944, "u": 11315994159389, "recv_ms": 1787089567025, "bids": [[1000.0, 36.16], [14172.1, 3.22], [14272.1, 0.98], [58114.8, 0.067], [61343.4, 0.0], [63280.7, 0.029], [63572.1, 0.038], [63926.4, 1.408], [64557.6, 0.002], [64560.5, 0.002], [64569.8, 0.002], [64569.9, 0.155], [64570.0, 0.022], [64570.7, 2.12], [64570.8, 0.123], [64571.8, 0.002], [64572.0, 0.013]], "asks": [[64572.2, 0.484], [64573.0, 0.0], [64573.1, 0.01], [64593.2, 0.001], [64593.6, 1.362], [64599.2, 0.0], [64599.3, 2.05], [64895.1, 2.619], [65088.8, 6.474], [65217.9, 0.0], [65379.4, 3.713], [65572.2, 0.022]]}
{"kind": "depth", "E": 1787089567169, "U": 11315994159564, "u": 11315994167397, "recv_ms": 1787089567127, "bids": [[14172.1, 3.57], [14272.1, 0.63], [58114.8, 0.067], [61989.2, 0.003], [63571.2, 5.508], [63789.4, 8.898], [63926.4, 1.408], [64249.2, 4.476], [64468.0, 0.288], [64468.8, 1.496], [64475.1, 0.001], [64487.0, 0.001], [64493.8, 0.003], [64495.3, 0.01], [64498.4, 1.523], [64501.1, 3.562], [64503.5, 0.004], [64524.2, 0.354], [64529.4, 0.005], [64561.9, 0.124], [64562.9, 1.942], [64563.7, 0.013], [64567.6, 0.003], [64568.5, 0.003], [64568.9, 0.234], [64572.0, 0.01]], "asks": [[64572.9, 0.003], [64573.0, 1.393], [64573.1, 0.01], [64574.6, 0.002], [64577.9, 0.005], [64578.5, 0.101], [64578.6, 0.024], [64579.4, 0.038], [64580.3, 0.209], [64580.4, 0.584], [64580.5, 9.541], [64582.3, 0.002], [64680.6, 0.001], [64895.1, 2.618], [65217.9, 0.0], [71029.5, 0.001]]}
{"kind": "depth", "E": 1787089567271, "U": 11315994167405, "u": 11315994175193, "recv_ms": 1787089567229, "bids": [[1000.0, 36.16], [14072.1, 0.084], [14172.1, 3.766], [14272.1, 0.35], [51658.0, 0.0], [58114.8, 0.067], [61343.4, 0.0], [61989.2, 0.0], [63280.7, 0.023], [63572.1, 0.018], [63648.9, 21.654], [63705.6, 0.784], [63926.4, 1.408], [64249.2, 4.478], [64415.1, 6.033], [64432.1, 3.748], [64521.2, 0.477], [64546.0, 0.445], [64547.8, 1.1], [64552.9, 0.349], [64554.1, 0.546], [64558.1, 0.0], [64560.6, 0.036], [64561.0, 0.005], [64562.3, 0.928], [64562.9, 1.4], [64563.7, 0.012], [64564.0, 0.545], [64565.4, 0.409], [64567.1, 0.458], [64572.0, 0.013], [64572.1, 6.873]], "asks": [[64572.9, 0.003], [64573.0, 1.393], [64574.5, 0.446], [64574.6, 0.002], [64577.9, 0.005], [64578.7, 0.086], [64580.0, 0.073], [64580.2, 0.01], [64580.3, 0.201], [64580.4, 0.583], [64580.6, 41.645], [64582.3, 0.001], [64583.9, 1.275], [64586.4, 0.649], [64592.8, 0.258], [64592.9, 0.644], [64593.5, 0.574], [64593.6, 0.435], [64594.6, 0.927], [64597.1, 0.473], [64598.2, 0.557], [64598.4, 2.564], [64598.8, 0.034], [64599.6, 0.177], [64712.8, 5.436], [64729.8, 10.431], [64846.6, 0.015], [65217.9, 0.0], [65572.2, 0.002], [65657.8, 5.329], [71029.5, 0.0]]}
{"kind": "depth", "E": 1787089567373, "U": 11315994175487, "u": 11315994185735, "recv_ms": 1787089567332, "bids": [[14072.1, 0.308], [14172.1, 3.668], [14272.1, 0.224], [51658.0, 0.0], [58114.8, 0.067], [61343.4, 0.0], [61989.2, 0.003], [63280.7, 0.02], [63705.7, 10.193], [63926.3, 0.031], [63926.4, 1.408], [64502.3, 0.002], [64528.1, 0.042], [64545.6, 2.948], [64546.8, 0.057], [64547.1, 1.213], [64547.8, 1.043], [64548.0, 1.987], [64549.0, 6.917], [64551.6, 0.001], [64555.3, 0.626], [64561.7, 1.21], [64562.3, 0.001], [64563.0, 0.55], [64563.7, 0.013], [64564.0, 0.003], [64569.4, 0.002], [64572.0, 0.01], [64572.1, 6.873]], "asks": [[64572.2, 0.288], [64572.8, 0.002], [64573.0, 1.393], [64573.1, 0.01], [64574.5, 0.003], [64574.6, 0.002], [64576.0, 1.412], [64576.3, 0.013], [64579.9, 0.0], [64580.0, 0.064], [64580.2, 0.01], [64580.3, 0.001], [64580.5, 9.542], [64580.6, 41.644], [64591.3, 0.764], [64592.0, 0.026], [64592.5, 0.551], [64593.5, 0.032], [64594.0, 0.001], [64594.1, 0.003], [64598.9, 0.073], [64599.3, 2.043], [64599.7, 0.048], [64601.7, 0.967], [64603.1, 0.078], [64607.3, 10.142], [64616.2, 0.17], [64846.6, 0.215], [65217.9, 0.0]]}
{"kind": "depth", "E": 1787089567475, "U": 11315994185817, "u": 11315994195984, "recv_ms": 1787089567432, "bids": [[14072.1, 0.56], [14172.1, 3.528], [14272.1, 0.112], [58114.8, 0.067], [61343.4, 0.0], [61989.2, 0.0], [63572.1, 0.038], [63668.1, 7.717], [63797.2, 13.697], [63926.4, 1.408], [64249.2, 4.488], [64527.4, 0.0], [64531.5, 0.06], [64539.6, 0.002], [64561.9, 0.666], [64563.0, 0.008], [64563.7, 0.013], [64572.1, 6.876]], "asks": [[64572.9, 1.396], [64573.0, 0.0], [64574.6, 0.002], [64579.7, 0.0], [64580.5, 9.542], [64586.2, 0.045], [64598.7, 0.168], [65217.9, 0.0], [65565.0, 3.276], [65572.2, 0.022]]}
{"kind": "depth", "E": 1787089567577, "U": 11315994196195, "u": 11315994205861, "recv_ms": 1787089567538, "bids": [[1000.0, 36.16], [14072.1, 0.798], [14172.1, 3.402], [14272.1, 0.0], [58114.8, 0.067], [61343.4, 0.0], [63668.1, 10.07], [63926.4, 1.408], [64502.3, 0.029], [64561.2, 1.088], [64561.7, 0.283], [64572.1, 6.875]], "asks": [[64572.2, 0.318], [64572.5, 0.017], [64572.9, 0.003], [64573.0, 0.0], [64574.6, 0.002], [64574.9, 0.001], [64575.3, 0.085], [64579.4, 0.038], [64580.0, 0.073], [64580.5, 9.542], [64582.1, 0.124], [64593.6, 1.362], [64594.6, 0.0], [64598.7, 0.014], [64598.9, 0.073], [64602.5, 5.163], [64607.3, 0.142], [64619.8, 0.245], [64627.0, 0.001], [64630.1, 0.003], [64642.0, 0.002], [65217.9, 0.0], [65573.1, 8.527], [66459.8, 0.0]]}
{"kind": "depth", "E": 1787089567679, "U": 11315994205982, "u": 11315994215728, "recv_ms": 1787089567637, "bids": [[14072.1, 1.162], [14172.1, 3.038], [58114.8, 0.067], [61989.2, 0.003], [63280.7, 0.023], [63422.7, 0.125], [63572.1, 0.018], [63713.4, 3.293], [63860.5, 2.733], [63926.4, 1.408], [63971.6, 5.3], [64494.6, 0.047], [64513.9, 0.05], [64568.1, 0.002], [64568.5, 0.001], [64570.2, 0.0], [64572.0, 0.01], [64572.1, 6.879]], "asks": [[64572.2, 0.32], [64572.9, 1.396], [64573.0, 0.0], [64574.9, 0.086], [64577.9, 0.005], [64580.2, 0.002], [64580.3, 0.009], [64598.9, 0.227], [64630.4, 1.237], [65080.8, 1.841], [65217.9, 0.0], [65453.1, 0.005], [65572.2, 0.002]]}
{"kind": "depth", "E": 1787089567781, "U": 11315994215857, "u": 11315994226566, "recv_ms": 1787089567738, "bids": [[14072.1, 1.512], [14172.1, 2.688], [51658.0, 0.002], [58114.8, 0.067], [61342.3, 0.015], [61343.4, 0.0], [61989.2, 0.0], [63905.4, 2.385], [63926.4, 1.408], [64249.2, 4.488], [64432.1, 0.022], [64503.9, 0.029], [64572.0, 0.017]], "asks": [[64572.9, 0.003], [64573.0, 1.393], [64573.1, 0.01], [64574.6, 0.937], [64574.8, 1.816], [64577.9, 0.013], [64580.3, 0.001], [64712.8, 0.027], [65217.9, 0.0]]}
{"kind": "depth", "E": 1787089567883, "U": 11315994226600, "u": 11315994236321, "recv_ms": 1787089567841, "bids": [[1000.0, 36.16], [14072.1, 1.876], [14172.1, 2.324], [51658.0, 0.0], [58114.8, 0.067], [61989.2, 0.003], [63280.7, 0.02], [63572.1, 0.038], [63926.4, 1.408], [64432.1, 4.151], [64502.0, 8.201], [64526.9, 0.235], [64534.8, 0.004], [64539.4, 0.007], [64563.7, 0.013], [64572.0, 0.017], [64572.1, 6.876]], "asks": [[64572.9, 0.003], [64573.0, 1.393], [64574.6, 0.002], [64574.8, 1.802], [64577.9, 0.005], [64579.4, 0.038], [64580.3, 0.009], [64580.5, 9.542], [64627.0, 0.005], [64627.8, 0.168], [64712.8, 5.436], [64729.6, 2.756], [64950.0, 25.152], [65217.9, 0.0], [65339.1, 1.046], [65355.0, 4.183], [65486.6, 2.403], [65572.2, 0.022], [66483.0, 0.128]]}
{"kind": "depth", "E": 1787089567985, "U": 11315994236341, "u": 11315994244968, "recv_ms": 1787089567943, "bids": [[14072.1, 2.226], [14172.1, 1.974], [51657.7, 0.0], [58114.8, 0.067], [61343.4, 0.0], [61989.2, 0.0], [63498.9, 2.202], [63628.0, 9.576], [63641.5, 0.0], [63868.3, 1.406], [63926.4, 1.408], [64231.9, 0.493], [64232.0, 0.007], [64376.4, 1.247], [64415.1, 3.565], [64432.1, 2.226], [64550.0, 0.339], [64550.4, 0.014], [64555.3, 0.626], [64563.7, 0.012], [64563.8, 0.002], [64570.7, 0.572], [64570.8, 1.671], [64572.0, 0.01], [64572.1, 6.882]], "asks": [[64572.9, 1.396], [64573.0, 0.0], [64574.8, 1.816], [64577.9, 0.005], [64580.3, 0.009], [64587.7, 0.007], [64597.0, 0.668], [64598.2, 0.0], [64598.3, 0.27], [64598.9, 0.073], [64599.1, 0.155], [64599.6, 0.061], [65088.8, 6.781], [65217.9, 0.0], [65377.6, 4.562], [65464.1, 3.061]]}
{"kind": "depth", "E": 1787089568087, "U": 11315994245034, "u": 11315994253283, "recv_ms": 1787089568045, "bids": [[14072.1, 2.59], [14172.1, 1.61], [58114.8, 0.067], [61343.4, 0.0], [63447.8, 0.0], [63572.1, 0.018], [63587.8, 0.024], [63628.0, 8.477], [63731.0, 3.935], [63926.4, 1.408], [64249.2, 4.488], [64376.4, 6.291], [64415.1, 6.129], [64432.1, 3.554], [64558.6, 0.007], [64559.5, 0.317], [64560.1, 0.002], [64560.5, 0.002], [64562.7, 0.0], [64570.7, 0.573], [64572.1, 6.914]], "asks": [[64572.2, 0.32], [64572.9, 0.003], [64573.0, 1.393], [64573.1, 0.01], [64574.8, 1.802], [65196.3, 0.0], [65217.9, 0.0], [65347.1, 17.306], [65556.4, 0.022], [65572.2, 0.002]]}
{"kind": "depth", "E": 1787089568189, "U": 11315994253457, "u": 11315994263070, "recv_ms": 1787089568147, "bids": [[1000.0, 36.16], [14072.1, 2.94], [14172.1, 1.26], [51658.0, 0.0], [58114.8, 0.067], [61343.4, 0.0], [61989.2, 0.003], [63177.2, 1.468], [63588.3, 0.01], [63926.4, 1.408], [64249.2, 4.486], [64493.9, 0.001], [64494.6, 0.05], [64495.1, 0.003], [64501.2, 0.04], [64524.4, 0.011], [64526.5, 0.003], [64529.5, 0.002], [64561.9, 0.124], [64562.9, 1.942], [64563.8, 0.001], [64572.0, 0.017], [64572.1, 6.886]], "asks": [[64573.0, 0.0], [64574.6, 0.002], [64574.8, 1.802], [64577.9, 0.005], [64579.4, 0.039], [64580.3, 0.009], [64580.5, 9.541], [64584.9, 0.741], [64597.0, 0.111], [64597.4, 0.562], [64598.3, 0.154], [64598.7, 0.13], [64649.7, 0.004], [65217.9, 0.0], [65508.5, 18.138], [65634.3, 0.71], [66108.6, 1.316]]}
{"kind": "depth", "E": 1787089568291, "U": 11315994263178, "u": 11315994271694, "recv_ms": 1787089568250, "bids": [[14072.1, 3.29], [14172.1, 0.91], [51658.0, 0.0], [58114.8, 0.067], [61343.4, 0.0], [61989.2, 0.0], [63280.7, 0.017], [63506.7, 2.202], [63572.1, 0.038], [63635.8, 7.693], [63926.3, 0.03], [63926.4, 1.408], [64437.4, 0.0], [64560.6, 0.018], [64563.8, 0.002], [64564.5, 0.021], [64572.1, 6.885]], "asks": [[64572.2, 0.334], [64572.8, 0.003], [64573.0, 1.393], [64573.1, 0.01], [64574.8, 1.816], [64577.9, 0.005], [64579.4, 0.038], [64580.3, 0.009], [64580.6, 41.645], [64595.2, 0.173], [64599.1, 0.001], [64768.5, 13.481], [65217.9, 0.0], [65387.2, 1.53], [65555.9, 0.012], [65572.2, 0.022]]}
{"kind": "depth", "E": 1787089568393, "U": 11315994271747, "u": 11315994279039, "recv_ms": 1787089568350, "bids": [[1000.0, 36.31], [14072.1, 3.654], [14172.1, 0.546], [58114.8, 0.067], [61989.2, 0.003], [63635.8, 8.792], [63926.4, 1.408], [64249.2, 4.486], [64538.8, 0.116], [64546.0, 0.515], [64563.8, 0.002], [64572.0, 0.01], [64572.1, 6.875]], "asks": [[64572.2, 0.335], [64573.0, 0.0], [64573.1, 1.403], [64577.9, 0.005], [64580.3, 0.009], [64598.9, 0.073], [64599.0, 3.937], [64627.0, 0.001], [64633.7, 0.006], [64639.4, 0.207], [64895.1, 2.62], [65217.9, 0.0], [65657.0, 1.22], [65863.6, 0.027], [66034.6, 0.001]]}
{"kind": "depth", "E": 1787089568495, "U": 11315994279213, "u": 11315994287062, "recv_ms": 1787089568457, "bids": [[1000.0, 36.16], [14072.1, 3.738], [14172.1, 0.322], [14472.1, 0.14], [58114.8, 0.067], [61343.4, 0.001], [61343.6, 0.007], [62369.0, 0.087], [63745.7, 1.571], [63901.7, 1.328], [63926.4, 1.408], [64432.1, 0.022], [64462.3, 0.004], [64532.4, 0.357], [64537.3, 0.015], [64539.3, 0.003], [64539.4, 0.005], [64539.5, 0.004], [64542.8, 0.176], [64542.9, 0.49], [64543.0, 0.189], [64561.9, 0.666], [64562.9, 1.4], [64563.8, 0.001], [64572.0, 0.017], [64572.1, 6.876]], "asks": [[64573.0, 1.393], [64573.1, 0.01], [64574.6, 0.002], [64577.9, 0.005], [64579.3, 0.126], [64580.3, 0.009], [64580.6, 41.644], [64599.0, 4.091], [64712.8, 0.027], [65217.9, 0.0]]}
{"kind": "depth", "E": 1787089568597, "U": 11315994287586, "u": 11315994295365, "recv_ms": 1787089568554, "bids": [[14072.1, 3.64], [14172.1, 0.196], [14472.1, 0.364], [58114.8, 0.067], [61343.4, 0.0], [61989.2, 0.0], [63572.1, 0.018], [63926.4, 1.408], [64432.1, 3.943], [64544.6, 0.09], [64551.8, 0.06], [64563.8, 0.001], [64572.0, 0.017], [64572.1, 6.875]], "asks": [[64572.2, 0.335], [64573.0, 0.0], [64573.1, 1.403], [64577.9, 0.013], [64579.3, 0.125], [64580.2, 0.002], [64580.3, 0.001], [64580.6, 41.645], [64712.8, 5.436], [64768.5, 13.928], [65217.9, 0.0], [65354.9, 0.766], [65572.2, 0.002], [65838.0, 1.1]]}
{"kind": "depth", "E": 1787089568699, "U": 11315994295543, "u": 11315994303154, "recv_ms": 1787089568657, "bids": [[1000.0, 36.16], [14072.1, 3.5], [14172.1, 0.084], [14472.1, 0.616], [58114.8, 0.067], [61343.4, 0.0], [61989.2, 0.003], [63713.4, 2.352], [63789.4, 9.681], [63903.3, 1.239], [63926.4, 1.408], [64249.2, 4.476], [64432.1, 3.943], [64563.8, 0.001], [64572.0, 0.01], [64572.1, 6.891]], "asks": [[64573.0, 1.393], [64573.1, 0.01], [64574.6, 0.002], [64574.8, 1.802], [64577.9, 0.005], [64580.3, 0.009], [64595.2, 0.174], [64599.0, 3.937], [64599.1, 0.155], [64639.4, 0.216], [64712.8, 5.436], [65217.9, 0.0], [67155.0, 0.281]]}
{"kind": "depth", "E": 1787089568801, "U": 11315994303477, "u": 11315994311042, "recv_ms": 1787089568759, "bids": [[1000.0, 36.16], [14072.1, 3.318], [14172.1, 0.0], [14472.1, 0.882], [58114.8, 0.067], [61343.4, 0.0], [61989.2, 0.0], [63001.2, 0.001], [63572.1, 0.038], [63764.9, 2.102], [63916.5, 0.003], [63926.4, 1.408], [64241.4, 0.62], [64432.1, 0.022], [64438.2, 0.088], [64563.8, 0.001], [64572.1, 6.89]], "asks": [[64573.0, 0.0], [64573.1, 1.403], [64574.6, 0.002], [64574.8, 1.802], [64577.9, 0.005], [64579.3, 0.126], [64580.3, 0.009], [64580.6, 41.644], [64599.1, 0.001], [64599.2, 0.154], [64712.8, 0.027], [64887.1, 0.819], [65217.9, 0.0], [65572.2, 0.022]]}
{"kind": "depth", "E": 1787089568903, "U": 11315994311440, "u": 11315994319315, "recv_ms": 1787089568862, "bids": [[14072.1, 2.954], [14472.1, 1.246], [51657.7, 0.002], [58114.8, 0.067], [61343.4, 0.0], [61989.2, 0.003], [63926.4, 1.408], [64249.2, 4.631], [64415.1, 6.958], [64432.1, 3.943], [64508.6, 1.331], [64549.5, 2.079], [64563.8, 0.001], [64572.1, 6.889]], "asks": [[64573.0, 1.393], [64573.1, 0.01], [64574.8, 1.816], [64577.9, 0.013], [64579.3, 0.125], [64580.2, 0.002], [64580.3, 0.001], [64580.6, 41.645], [64601.7, 1.603], [64712.8, 5.436], [64729.8, 10.431], [64895.1, 2.928], [65217.9, 0.0], [65335.5, 0.047]]}
{"kind": "depth", "E": 1787089569005, "U": 11315994319441, "u": 11315994326382, "recv_ms": 1787089568963, "bids": [[1000.0, 36.16], [14072.1, 2.604], [14472.1, 1.596], [51657.7, 0.0], [58114.8, 0.067], [63280.7, 0.02], [63572.1, 0.018], [63724.7, 1.568], [63732.7, 1.371], [63763.3, 3.668], [63926.4, 1.408], [64249.2, 4.641], [64462.3, 0.001], [64494.6, 0.047], [64513.9, 0.05], [64555.3, 0.626], [64555.4, 0.117], [64555.7, 0.176], [64558.6, 0.014], [64559.5, 0.31], [64561.9, 0.666], [64563.0, 0.008], [64568.9, 0.002], [64569.9, 0.387], [64572.1, 6.888]], "asks": [[64573.0, 1.393], [64573.1, 0.01], [64574.6, 0.002], [64574.8, 1.802], [64577.9, 0.005], [64579.3, 0.126], [64580.3, 0.009], [64580.6, 41.644], [64587.7, 0.007], [64593.6, 0.435], [64594.2, 1.598], [64630.4, 1.237], [64649.7, 0.001], [65217.9, 0.0], [65572.2, 0.002], [65677.8, 1.977], [65863.6, 0.024]]}
{"kind": "depth", "E": 1787089569107, "U": 11315994326444, "u": 11315994333980, "recv_ms": 1787089569064, "bids": [[1000.0, 36.16], [14072.1, 2.24], [14472.1, 1.96], [51658.0, 0.038], [58114.8, 0.067], [61343.4, 0.0], [61989.2, 0.0], [63572.1, 0.038], [63587.8, 0.013], [63724.8, 3.449], [63821.7, 4.707], [63926.4, 1.408], [64501.2, 0.041], [64555.4, 0.117], [64556.2, 0.001], [64556.4, 0.558], [64556.9, 0.001], [64560.5, 0.002], [64561.9, 0.666], [64563.0, 0.008], [64563.8, 0.001], [64572.0, 0.017], [64572.1, 6.898]], "asks": [[64572.2, 0.335], [64573.0, 0.0], [64573.1, 0.01], [64574.6, 0.937], [64579.3, 0.125], [64579.4, 0.038], [64580.2, 0.003], [64597.4, 0.005], [64597.7, 0.618], [64597.8, 6.597], [64598.7, 0.014], [64599.1, 0.117], [64608.1, 0.084], [64608.2, 0.712], [65217.9, 0.0], [65347.1, 21.431], [65377.6, 4.334], [65556.4, 0.011], [65572.2, 0.022]]}
{"kind": "depth", "E": 1787089569209, "U": 11315994334005, "u": 11315994343730, "recv_ms": 1787089569168, "bids": [[14072.1, 1.89], [14472.1, 2.31], [51658.0, 0.0], [58114.8, 0.067], [61343.4, 0.0], [61989.2, 0.003], [63587.8, 0.024], [63613.8, 3.991], [63926.4, 1.408], [64493.9, 0.002], [64572.0, 0.01], [64572.1, 6.902]], "asks": [[64572.8, 0.002], [64573.0, 1.393], [64573.1, 0.01], [64574.6, 0.002], [64574.8, 1.816], [64577.9, 0.005], [64579.3, 0.125], [64580.2, 0.002], [64580.3, 0.009], [64580.5, 9.541], [64580.6, 41.645], [64582.6, 0.014], [64584.9, 0.74], [64685.6, 0.102], [65217.9, 0.0], [65434.2, 0.009], [65476.2, 18.363]]}
{"kind": "depth", "E": 1787089569311, "U": 11315994344136, "u": 11315994353065, "recv_ms": 1787089569270, "bids": [[1000.0, 35.76], [14072.1, 1.526], [14472.1, 2.674], [58114.8, 0.067], [61343.4, 0.0], [61989.2, 0.0], [63022.4, 0.561], [63338.6, 0.74], [63829.5, 1.878], [63926.4, 1.408], [64249.2, 4.641], [64376.4, 6.067], [64415.1, 6.958], [64432.1, 3.943], [64572.1, 6.891]], "asks": [[64572.2, 0.337], [64573.0, 1.393], [64573.1, 0.01], [64577.9, 0.005], [64580.3, 0.009], [64599.2, 0.154], [64625.5, 0.005], [64633.7, 0.002], [64712.8, 5.436], [64729.8, 10.431], [64768.5, 13.928], [64895.1, 2.926], [65217.9, 0.0], [65556.4, 0.022]]}
{"kind": "depth", "E": 1787089569413, "U": 11315994353238, "u": 11315994360403, "recv_ms": 1787089569371, "bids": [[1000.0, 35.76], [14072.1, 1.176], [14472.1, 3.024], [58114.8, 0.067], [61343.4, 0.001], [61343.6, 0.005], [61989.2, 0.003], [63447.5, 3.148], [63572.1, 0.018], [63732.7, 3.721], [63926.4, 1.408], [63991.0, 4.265], [64047.7, 1.247], [64560.4, 0.887], [64563.0, 0.222], [64563.8, 0.001], [64572.1, 6.891]], "asks": [[64572.2, 0.34], [64573.0, 0.0], [64573.1, 1.403], [64574.8, 1.858], [64577.9, 0.005], [64580.0, 0.073], [64580.3, 0.009], [65217.9, 0.0], [65456.8, 1.218], [65572.2, 0.002]]}
{"kind": "depth", "E": 1787089569515, "U": 11315994360635, "u": 11315994368543, "recv_ms": 1787089569473, "bids": [[14072.1, 0.812], [14472.1, 3.388], [58114.8, 0.067], [61343.4, 0.0], [63280.7, 0.023], [63364.6, 2.489], [63830.8, 0.011], [63860.5, 2.03], [63926.4, 1.408], [63947.4, 0.783], [64249.2, 4.643], [64432.1, 0.022], [64524.5, 2.383], [64531.5, 0.0], [64560.7, 0.003], [64563.8, 0.001], [64565.6, 0.111], [64569.8, 0.008], [64570.7, 0.567], [64572.1, 6.89]], "asks": [[64572.2, 0.34], [64572.3, 0.002], [64572.9, 1.396], [64573.0, 0.132], [64573.1, 0.01], [64573.4, 0.362], [64574.6, 0.002], [64574.7, 0.626], [64574.9, 0.085], [64576.3, 0.016], [64577.9, 0.005], [64579.0, 0.02], [64580.2, 0.003], [64580.3, 0.009], [64580.6, 41.644], [64712.8, 0.027], [65217.9, 0.0]]}
{"kind": "depth", "E": 1787089569617, "U": 11315994368791, "u": 11315994377960, "recv_ms": 1787089569576, "bids": [[1000.0, 35.76], [14072.1, 0.476], [14372.1, 0.014], [14472.1, 3.71], [58114.8, 0.067], [61343.4, 0.0], [61343.6, 0.003], [61989.2, 0.0], [63338.6, 0.0], [63572.1, 0.038], [63732.7, 3.799], [63855.6, 1.803], [63868.3, 2.109], [63922.3, 1.196], [63926.4, 1.408], [64055.5, 6.079], [64249.2, 4.643], [64376.4, 0.0], [64415.1, 0.0], [64416.0, 1.263], [64467.3, 0.022], [64467.4, 0.07], [64512.6, 0.029], [64572.1, 6.887]], "asks": [[64572.2, 0.339], [64572.5, 0.021], [64572.9, 0.003], [64573.0, 0.132], [64573.1, 1.403], [64574.9, 0.085], [64577.9, 0.005], [64580.2, 0.002], [64580.3, 0.209], [64580.6, 41.645], [64599.1, 0.117], [64599.2, 0.0], [64729.6, 1.378], [64729.8, 0.003], [64757.8, 41.384], [64758.0, 0.009], [64768.5, 2.391], [64846.6, 0.015], [65217.9, 0.0], [65572.2, 0.022]]}
{"kind": "depth", "E": 1787089569719, "U": 11315994378182, "u": 11315994384795, "recv_ms": 1787089569680, "bids": [[1000.0, 35.76], [14072.1, 0.294], [14372.1, 0.196], [14472.1, 3.71], [58114.8, 0.067], [61343.4, 0.0], [61989.2, 0.003], [63466.7, 2.202], [63660.4, 8.693], [63926.4, 1.408], [64375.6, 0.023], [64376.4, 6.067], [64395.2, 3.351], [64396.8, 1.25], [64415.1, 6.959], [64416.0, 2.107], [64432.1, 3.943], [64563.8, 0.002], [64572.1, 6.886]], "asks": [[64572.9, 1.396], [64573.0, 0.132], [64573.1, 0.01], [64573.4, 0.002], [64574.6, 0.002], [64574.7, 0.986], [64574.9, 0.086], [64577.9, 0.005], [64578.3, 0.556], [64578.6, 0.017], [64579.0, 0.02], [64580.2, 0.003], [64580.3, 0.209], [64580.6, 41.644], [64599.0, 4.091], [64620.0, 0.018], [64630.1, 0.0], [64712.8, 5.436], [64729.6, 2.756], [64729.7, 10.428], [64768.4, 3.704], [64768.5, 13.927], [65217.9, 0.0], [65377.6, 4.106], [65379.4, 3.941], [65722.4, 0.764], [71933.4, 0.155]]}
{"kind": "depth", "E": 1787089569821, "U": 11315994384953, "u": 11315994391742, "recv_ms": 1787089569780, "bids": [[14072.1, 0.168], [14372.1, 0.434], [14472.1, 3.598], [58114.8, 0.067], [61989.2, 0.0], [63364.6, 3.229], [63572.1, 0.018], [63613.8, 3.834], [63926.4, 1.408], [64495.3, 0.01], [64499.7, 30.7], [64502.0, 4.828], [64544.1, 0.437], [64563.0, 0.23], [64563.1, 0.634], [64563.8, 0.002], [64566.5, 0.018], [64567.1, 0.46], [64567.3, 0.147], [64568.1, 0.0], [64569.6, 0.298], [64570.0, 0.006], [64570.6, 0.002], [64570.7, 0.001], [64570.8, 0.046], [64570.9, 0.0], [64571.0, 0.0], [64571.1, 0.0], [64571.7, 1.548], [64572.1, 6.89]], "asks": [[64572.2, 0.34], [64572.9, 1.396], [64573.0, 0.132], [64573.1, 0.01], [64574.5, 0.087], [64574.6, 0.937], [64574.9, 0.085], [64576.1, 0.088], [64578.3, 0.549], [64578.7, 0.002], [64579.0, 0.02], [64580.2, 0.003], [64587.8, 0.077], [64589.1, 0.001], [64599.0, 3.937], [64599.1, 0.271], [64887.1, 0.665], [65080.8, 1.535], [65217.9, 0.0], [65484.1, 5.646], [65572.2, 0.002], [71029.5, 0.0]]}
{"kind": "depth", "E": 1787089569923, "U": 11315994391908, "u": 11315994398078, "recv_ms": 1787089569881, "bids": [[1000.0, 35.76], [14072.1, 0.056], [14372.1, 0.672], [14472.1, 3.472], [51657.7, 0.0], [58114.8, 0.067], [63519.8, 0.014], [63926.4, 1.408], [64249.2, 4.643], [64442.9, 0.003], [64502.0, 8.2], [64545.3, 0.06], [64546.8, 0.0], [64554.3, 0.117], [64555.4, 0.001], [64555.6, 0.558], [64556.4, 0.0], [64558.6, 0.007], [64559.5, 0.317], [64560.7, 0.93], [64560.8, 0.83], [64561.2, 0.161], [64561.9, 0.124], [64563.0, 0.222], [64563.1, 0.0], [64566.4, 0.808], [64566.5, 0.002], [64566.7, 0.09], [64567.1, 0.458], [64567.6, 0.005], [64569.6, 0.298], [64570.0, 1.585], [64570.5, 0.647], [64571.7, 0.0]], "asks": [[64572.7, 0.0], [64572.8, 1.395], [64572.9, 0.003], [64574.6, 0.002], [64578.3, 0.556], [64579.0, 0.02], [64580.2, 0.003], [64580.3, 0.009], [64590.8, 0.542], [64592.5, 0.009], [64593.1, 0.929], [64594.2, 0.671], [64595.5, 1.987], [64595.8, 1.004], [64597.7, 0.061], [64768.5, 13.956], [64846.6, 0.215], [65217.9, 0.0]]}
{"kind": "depth", "E": 1787089570025, "U": 11315994398189, "u": 11315994407153, "recv_ms": 1787089569983, "bids": [[1000.0, 35.76], [14072.1, 0.0], [14372.1, 0.966], [14472.1, 3.234], [58114.8, 0.067], [61343.4, 0.0], [61343.5, 0.01], [61989.2, 0.003], [63572.1, 0.038], [63926.4, 1.408], [64545.3, 0.003], [64546.2, 0.057], [64554.3, 0.001], [64555.3, 0.626], [64555.4, 0.117], [64558.6, 0.007], [64559.5, 0.31], [64559.8, 0.007], [64559.9, 0.029], [64560.7, 0.003], [64560.8, 1.215], [64561.8, 2.323], [64561.9, 0.666], [64563.0, 0.368], [64563.8, 0.001], [64565.4, 0.255], [64566.3, 2.506], [64567.1, 0.46], [64567.6, 0.003], [64569.5, 0.162], [64569.8, 0.002], [64569.9, 0.234], [64570.0, 0.037], [64570.6, 1.556], [64572.0, 0.013], [64572.1, 6.895]], "asks": [[64572.7, 0.0], [64572.8, 0.002], [64572.9, 0.003], [64574.9, 0.086], [64577.9, 0.005], [64579.6, 0.076], [64579.7, 0.0], [64579.8, 0.314], [64580.2, 0.003], [64580.3, 0.751], [64580.4, 0.041], [64587.7, 0.007], [64590.8, 0.0], [64592.0, 0.568], [64595.8, 0.447], [64596.7, 0.572], [64598.0, 0.072], [64598.2, 0.116], [64598.9, 0.016], [64599.0, 3.937], [64599.1, 0.001], [64895.1, 3.08], [65088.8, 7.087], [65217.9, 0.0], [65572.2, 0.022], [66128.5, 0.654]]}
{"kind": "depth", "E": 1787089570127, "U": 11315994407202, "u": 11315994417849, "recv_ms": 1787089570085, "bids": [[14372.1, 1.33], [14472.1, 2.87], [58114.8, 0.067], [61343.4, 0.0], [61989.2, 0.0], [63280.7, 0.017], [63587.3, 0.012], [63587.8, 0.016], [63652.1, 0.0], [63654.5, 0.006], [63763.3, 3.317], [63926.4, 1.408], [64055.5, 6.079], [64524.6, 0.25], [64525.7, 0.068], [64537.4, 0.326], [64548.0, 1.368], [64555.3, 0.007], [64555.6, 0.0], [64556.8, 1.586], [64559.9, 0.021], [64560.5, 0.002], [64563.1, 0.65], [64563.8, 0.002], [64566.5, 0.018], [64569.8, 0.004], [64569.9, 0.233], [64570.0, 0.006], [64570.5, 0.02], [64570.6, 0.002], [64570.7, 0.001], [64570.8, 0.356], [64570.9, 0.0], [64571.0, 0.0], [64571.1, 0.0], [64571.7, 1.548], [64572.0, 0.01], [64572.1, 6.894]], "asks": [[64572.2, 0.34], [64573.0, 0.132], [64573.1, 0.01], [64573.5, 1.761], [64574.9, 0.086], [64577.9, 0.005], [64580.2, 0.003], [64580.3, 0.209], [64580.4, 0.583], [64580.6, 41.644], [64584.4, 0.516], [64591.3, 0.145], [64593.1, 0.002], [64593.3, 1.022], [64594.0, 0.001], [64599.0, 3.937], [64608.4, 0.002], [64628.0, 2.572], [64629.2, 0.09], [64846.6, 0.015], [65217.9, 0.0], [65489.9, 0.0], [65492.3, 0.003], [65556.4, 0.014], [65557.1, 0.017], [65863.6, 0.021], [66057.4, 0.604]]}
{"kind": "depth", "E": 1787089570229, "U": 11315994417934, "u": 11315994428068, "recv_ms": 1787089570189, "bids": [[1000.0, 35.76], [14372.1, 1.68], [14472.1, 2.52], [58114.8, 0.067], [61343.4, 0.0], [61989.2, 0.003], [63531.2, 0.148], [63572.1, 0.018], [63588.1, 0.795], [63589.3, 0.015], [63653.0, 0.843], [63655.3, 0.008], [63926.4, 1.41], [64249.2, 4.643], [64494.6, 0.047], [64513.9, 0.047], [64525.5, 0.044], [64539.4, 0.03], [64541.2, 0.006], [64556.4, 0.558], [64556.8, 1.028], [64563.1, 0.008], [64566.4, 0.808], [64566.5, 0.002], [64566.7, 0.09], [64567.1, 0.458], [64568.9, 0.004], [64569.6, 0.298], [64569.8, 2.21], [64571.7, 0.0], [64571.8, 0.002], [64572.1, 6.895]], "asks": [[64572.2, 0.367], [64573.0, 0.132], [64573.1, 1.403], [64573.6, 0.001], [64574.8, 1.802], [64574.9, 0.085], [64576.0, 0.965], [64577.3, 0.007], [64577.4, 0.008], [64578.3, 0.549], [64579.9, 0.0], [64580.2, 0.002], [64580.3, 0.217], [64580.5, 9.542], [64593.3, 0.095], [64593.5, 0.959], [64599.0, 4.091], [64599.1, 0.001], [64608.5, 0.005], [64630.4, 1.234], [64649.7, 0.001], [65217.9, 0.0], [65488.9, 0.01], [65491.2, 0.021], [65554.9, 0.01], [65556.0, 0.481], [65572.2, 0.002], [65758.8, 0.986]]}
{"kind": "depth", "E": 1787089570331, "U": 11315994428180, "u": 11315994438027, "recv_ms": 1787089570291, "bids": [[1000.0, 35.76], [14372.1, 2.044], [14472.1, 2.156], [51658.0, 0.0], [58114.8, 0.067], [61989.2, 0.0], [63926.4, 1.408], [64175.1, 0.005], [64433.5, 0.505], [64567.7, 0.1], [64568.9, 0.002], [64572.1, 6.888]], "asks": [[64572.2, 0.368], [64573.1, 0.01], [64573.2, 1.394], [64577.3, 0.004], [64577.4, 0.005], [64577.9, 0.021], [64578.3, 0.551], [64580.3, 0.201], [64593.1, 0.929], [64593.5, 0.032], [64599.0, 3.937], [64599.1, 0.155], [65217.9, 0.0]]}
{"kind": "depth", "E": 1787089570433, "U": 11315994438337, "u": 11315994447294, "recv_ms": 1787089570391, "bids": [[14372.1, 2.394], [14472.1, 1.806], [51658.0, 0.0], [58114.8, 0.067], [61343.4, 0.0], [61988.1, 0.126], [63169.0, 1.042], [63179.2, 1.585], [63280.7, 0.014], [63538.9, 4.405], [63572.1, 0.038], [63615.2, 5.025], [63926.4, 1.408], [64506.0, 0.058], [64545.7, 0.057], [64546.2, 0.0], [64560.5, 0.929], [64560.8, 0.288], [64563.8, 0.002], [64567.7, 0.098], [64568.1, 0.002], [64569.5, 0.246], [64569.8, 2.202], [64570.0, 0.014], [64572.1, 6.897]], "asks": [[64573.0, 0.132], [64573.1, 1.403], [64573.2, 0.001], [64574.5, 0.003], [64577.9, 0.005], [64580.3, 0.217], [64587.8, 0.0], [64588.0, 3.29], [64589.0, 0.09], [64591.3, 0.687], [64592.0, 0.034], [64592.5, 0.001], [64599.1, 0.155], [64662.3, 0.008], [65572.2, 0.022]]}
{"kind": "depth", "E": 1787089570535, "U": 11315994447595, "u": 11315994457073, "recv_ms": 1787089570494, "bids": [[1000.0, 35.76], [14372.1, 2.758], [14472.1, 1.442], [58114.8, 0.067], [61343.4, 0.0], [61989.2, 0.003], [62932.0, 1.29], [63280.7, 0.017], [63926.4, 1.408], [64249.2, 4.641], [64495.3, 30.695], [64499.7, 0.015], [64501.9, 0.016], [64528.1, 0.07], [64545.2, 7.419], [64547.1, 2.094], [64549.0, 0.002], [64549.5, 1.108], [64572.1, 6.894]], "asks": [[64572.2, 0.397], [64573.1, 1.403], [64577.9, 0.005], [64580.3, 0.217], [64587.8, 0.085], [64589.0, 0.005], [64599.1, 0.001], [64599.2, 0.154], [64768.5, 13.481], [65217.9, 0.0], [65766.8, 0.991], [71933.4, 0.142]]}
{"kind": "depth", "E": 1787089570637, "U": 11315994457198, "u": 11315994466411, "recv_ms": 1787089570596, "bids": [[1000.0, 35.76], [14372.1, 3.108], [14472.1, 1.092], [51658.0, 0.0], [58114.8, 0.067], [61989.2, 0.0], [63572.1, 0.018], [63603.6, 0.013], [63622.9, 2.432], [63764.9, 2.336], [63926.4, 1.408], [64495.3, 0.01], [64499.7, 30.7], [64502.0, 4.828], [64531.1, 0.025], [64539.4, 0.005], [64560.4, 0.456], [64563.0, 0.154]], "asks": [[64573.1, 1.403], [64577.9, 0.005], [64580.3, 0.217], [64599.2, 0.0], [64723.0, 0.001], [64743.2, 3.518], [65217.9, 0.0], [65572.2, 0.002], [65721.3, 1.953], [71029.4, 0.002]]}
{"kind": "depth", "E": 1787089570739, "U": 11315994466419, "u": 11315994474718, "recv_ms": 1787089570696, "bids": [[14372.1, 3.472], [14472.1, 0.728], [58114.8, 0.067], [61343.4, 0.0], [61989.2, 0.003], [63926.4, 1.408], [64376.4, 6.343], [64415.1, 7.081], [64432.1, 4.003], [64499.7, 0.015], [64501.9, 30.701], [64508.2, 4.247], [64508.3, 0.136], [64508.6, 0.882], [64572.0, 0.012], [64572.1, 6.897]], "asks": [[64572.2, 0.398], [64573.1, 1.403], [64573.2, 0.001], [64587.8, 0.077], [64589.0, 0.013], [64599.1, 0.001], [64599.2, 0.154], [64634.2, 0.422], [64635.4, 0.001], [64638.3, 2.103], [64712.8, 5.436], [64720.9, 0.0], [64895.1, 3.082], [65217.9, 0.0], [71029.4, 0.0], [71029.5, 0.0]]}
{"kind": "depth", "E": 1787089570841, "U": 11315994474755, "u": 11315994483455, "recv_ms": 1787089570799, "bids": [[1000.0, 35.76], [14272.1, 0.042], [14372.1, 3.738], [14472.1, 0.42], [51658.0, 0.0], [58114.8, 0.067], [61989.2, 0.0], [63572.1, 0.038], [63603.5, 0.008], [63842.5, 0.001], [63926.4, 1.408], [64241.4, 0.465], [64249.2, 4.631], [64495.3, 0.01], [64499.7, 30.709], [64501.9, 0.016], [64531.1, 0.0], [64539.4, 0.03], [64561.1, 0.004], [64572.0, 0.01]], "asks": [[64572.5, 0.028], [64573.1, 0.01], [64573.2, 0.001], [64581.8, 0.003], [64599.2, 0.0], [64599.3, 2.197], [64768.5, 13.7], [65217.9, 0.0], [65379.4, 4.169], [65572.2, 0.022], [65863.6, 0.018]]}
{"kind": "depth", "E": 1787089570943, "U": 11315994483500, "u": 11315994492438, "recv_ms": 1787089570899, "bids": [[1000.0, 35.76], [14272.1, 0.252], [14372.1, 3.682], [14472.1, 0.266], [51657.7, 0.0], [58114.8, 0.067], [61343.4, 0.0], [63635.8, 8.949], [63926.4, 1.408], [64249.2, 4.786], [64432.1, 3.975], [64502.0, 8.201], [64546.3, 0.235], [64559.8, 0.007], [64560.4, 1.383], [64560.5, 0.01], [64561.5, 0.041], [64561.9, 0.666], [64563.0, 0.154], [64563.1, 0.0], [64563.8, 0.002], [64567.3, 0.128], [64572.0, 0.012], [64572.1, 6.894]], "asks": [[64573.1, 0.01], [64573.2, 1.394], [64577.9, 0.005], [64580.3, 0.217], [64587.8, 0.085], [64589.0, 0.005], [64591.3, 0.687], [64592.5, 0.001], [64592.8, 1.185], [64593.1, 0.002], [64593.9, 0.211], [64598.0, 0.015], [64598.2, 0.0], [64598.6, 0.058], [64598.8, 0.15], [64599.2, 0.007], [64599.7, 0.041], [64608.6, 1.641], [64712.8, 5.436], [64720.9, 0.879], [65217.9, 0.0], [65863.6, 0.021]]}
{"kind": "depth", "E": 1787089571045, "U": 11315994492573, "u": 11315994501083, "recv_ms": 1787089571002, "bids": [[14272.1, 0.476], [14372.1, 3.584], [14472.1, 0.14], [58114.8, 0.067], [61989.2, 0.003], [63572.1, 0.018], [63926.4, 1.408], [64434.9, 0.139], [64442.6, 2.999], [64507.5, 0.326], [64555.3, 0.007], [64556.7, 0.02], [64557.0, 0.001], [64559.7, 0.009], [64560.4, 0.456], [64560.5, 0.015], [64560.7, 0.93], [64569.8, 0.035], [64570.0, 0.556], [64570.1, 1.625], [64570.5, 0.02], [64572.0, 0.01], [64572.1, 6.904]], "asks": [[64572.2, 0.399], [64572.9, 0.003], [64573.0, 1.525], [64573.1, 0.01], [64573.2, 0.001], [64574.5, 0.087], [64587.7, 0.007], [64591.3, 0.145], [64592.0, 0.576], [64592.1, 1.386], [64592.8, 0.258], [64593.1, 0.929], [64597.6, 0.065], [64598.6, 0.001], [64636.8, 0.003], [65217.9, 0.0], [65572.2, 0.002]]}
{"kind": "depth", "E": 1787089571147, "U": 11315994501350, "u": 11315994511502, "recv_ms": 1787089571105, "bids": [[1000.0, 35.76], [14272.1, 0.728], [14372.1, 3.444], [14472.1, 0.028], [51658.0, 0.0], [58114.8, 0.067], [61343.4, 0.0], [61343.5, 0.012], [61989.2, 0.0], [63466.5, 0.787], [63926.4, 1.408], [64249.2, 4.796], [64548.0, 1.987], [64555.4, 0.736], [64559.8, 0.015], [64560.5, 0.002], [64563.0, 0.162], [64563.1, 0.008], [64563.3, 0.001], [64566.5, 0.002], [64569.8, 0.004], [64570.0, 0.006], [64570.1, 0.0], [64570.5, 0.001], [64570.6, 0.009], [64570.9, 0.085], [64571.0, 0.0], [64571.1, 2.098]], "asks": [[64572.2, 0.399], [64572.9, 1.396], [64573.0, 0.132], [64577.9, 0.005], [64580.3, 0.217], [64591.3, 0.687], [64591.4, 2.733], [64592.0, 0.034], [64597.8, 6.713], [64598.8, 0.034], [65217.9, 0.0], [65356.8, 0.769]]}
{"kind": "depth", "E": 1787089571249, "U": 11315994511591, "u": 11315994520224, "recv_ms": 1787089571208, "bids": [[1000.0, 35.76], [14272.1, 1.05], [14372.1, 3.15], [14472.1, 0.0], [51658.0, 0.0], [58114.8, 0.067], [61343.4, 0.0], [61989.2, 0.003], [63572.1, 0.038], [63926.4, 1.408], [63958.7, 2.154], [64432.1, 3.337], [64435.1, 0.986], [64495.3, 30.704], [64499.7, 0.015], [64508.0, 0.002], [64508.3, 0.104], [64508.6, 0.85], [64509.0, 1.217], [64509.3, 0.014], [64527.3, 0.0], [64527.6, 0.005], [64527.9, 2.598], [64528.3, 0.002], [64528.5, 0.148], [64528.6, 0.004], [64537.1, 0.14], [64542.3, 0.979], [64542.4, 0.433], [64542.5, 0.001], [64542.6, 0.002], [64542.7, 0.0], [64542.8, 0.006], [64542.9, 0.39], [64543.0, 0.019], [64543.2, 2.08], [64545.8, 0.0], [64546.3, 0.135], [64559.8, 0.007], [64563.0, 0.154], [64563.1, 0.0], [64563.2, 0.254], [64563.3, 0.001], [64563.8, 0.002], [64564.8, 0.322], [64564.9, 0.007], [64565.0, 0.313], [64565.1, 0.001], [64565.2, 0.001], [64565.3, 0.101], [64565.4, 0.155], [64565.5, 0.0], [64565.6, 0.011], [64565.7, 0.0], [64566.0, 0.276], [64566.3, 2.474], [64566.4, 0.808], [64566.5, 0.002], [64566.6, 0.311], [64566.7, 0.098], [64566.8, 0.002], [64567.0, 0.001], [64567.3, 0.096], [64568.1, 0.0], [64569.6, 0.547], [64569.8, 0.654], [64570.0, 1.562], [64570.6, 0.002], [64570.9, 0.0], [64571.1, 0.0], [64571.2, 0.001], [64571.3, 0.049], [64571.7, 0.0], [64571.8, 0.002], [64572.1, 6.9]], "asks": [[64572.8, 0.002], [64572.9, 1.396], [64577.9, 0.005], [64580.3, 0.217], [64582.9, 0.003], [64583.2, 0.007], [64583.5, 0.657], [64583.8, 0.002], [64584.2, 0.0], [64584.4, 0.355], [64584.5, 0.004], [64584.6, 0.0], [64584.7, 0.25], [64584.8, 0.027], [64584.9, 0.0], [64585.0, 0.236], [64585.1, 0.002], [64585.2, 2.258], [64585.3, 0.0], [64585.4, 0.313], [64591.3, 0.145], [64592.0, 0.576], [64602.2, 0.0], [64602.5, 5.096], [64602.8, 0.001], [64603.1, 0.004], [64603.5, 0.033], [64603.9, 0.003], [64604.3, 1.133], [64606.9, 0.0], [64607.1, 0.116], [64607.2, 0.316], [64607.3, 0.016], [64607.4, 0.003], [64607.5, 0.021], [64607.6, 0.019], [64607.7, 0.016], [64607.8, 0.07], [64607.9, 0.023], [64621.5, 3.5], [64621.8, 0.004], [64622.1, 0.0], [64622.5, 0.276], [64622.8, 0.0], [64712.8, 5.436], [65217.9, 0.0], [65572.2, 0.022]]}
{"kind": "depth", "E": 1787089571351, "U": 11315994520278, "u": 11315994528668, "recv_ms": 1787089571316, "bids": [[14272.1, 1.414], [14372.1, 2.786], [58114.8, 0.067], [61343.4, 0.0], [63022.4, 0.517], [63465.4, 1.258], [63926.4, 1.408], [64435.1, 1.414], [64495.3, 0.01], [64499.7, 30.709], [64502.0, 4.828], [64527.7, 0.09], [64528.0, 0.127], [64528.4, 0.032], [64528.7, 0.045], [64563.0, 0.162], [64563.3, 0.627], [64563.4, 0.09], [64563.8, 0.002], [64564.9, 0.077], [64565.0, 0.453], [64565.2, 0.101], [64566.4, 0.84], [64566.5, 1.55], [64566.7, 0.122], [64566.8, 0.0], [64567.0, 0.035], [64567.3, 0.128], [64567.7, 0.098], [64569.4, 0.002], [64569.6, 0.298], [64569.8, 0.004], [64570.0, 0.006], [64570.1, 0.008], [64570.5, 0.009], [64572.1, 6.91]], "asks": [[64572.9, 0.003], [64573.0, 1.525], [64577.9, 0.005], [64580.3, 0.217], [64582.7, 0.071], [64583.0, 0.183], [64583.3, 0.244], [64583.6, 0.077], [64584.8, 0.297], [64585.0, 0.383], [64585.1, 0.282], [64599.3, 2.197], [64602.0, 0.087], [64602.3, 0.104], [64602.6, 0.084], [64602.9, 1.076], [64607.3, 0.286], [64607.5, 0.168], [64607.6, 0.299], [64621.3, 1.038], [64621.6, 0.464], [64621.9, 0.098], [64622.3, 0.075], [65217.9, 0.0], [65377.6, 3.763]]}
{"kind": "depth", "E": 1787089571453, "U": 11315994528714, "u": 11315994537405, "recv_ms": 1787089571412, "bids": [[1000.0, 35.76], [14272.1, 1.764], [14372.1, 2.436], [58114.8, 0.067], [61343.4, 0.0], [61517.7, 0.0], [61527.6, 0.017], [61988.1, 0.125], [61989.2, 0.0], [63572.1, 0.018], [63926.4, 1.408], [64249.2, 4.796], [64432.1, 3.415], [64563.0, 0.17], [64563.3, 0.627], [64563.4, 0.074], [64565.0, 0.523], [64565.5, 0.1], [64565.8, 0.072], [64566.4, 0.84], [64566.5, 0.002], [64566.7, 0.122], [64567.0, 0.035], [64567.3, 0.128], [64568.1, 0.0], [64569.8, 0.004], [64570.1, 0.0], [64570.5, 0.001], [64570.6, 0.002], [64570.8, 0.357], [64570.9, 0.016], [64571.0, 1.548], [64572.1, 6.907]], "asks": [[64572.9, 0.003], [64573.0, 1.525], [64573.1, 0.01], [64584.2, 0.161], [64584.5, 0.284], [64585.0, 0.537], [64599.3, 2.197], [64606.7, 0.199], [64607.0, 2.703], [64607.5, 0.322], [64712.8, 5.436], [65217.9, 0.002], [65379.4, 4.397], [65572.2, 0.002], [65742.5, 0.762], [67586.5, 0.0], [67597.4, 0.04]]}
{"kind": "depth", "E": 1787089571555, "U": 11315994537504, "u": 11315994556629, "recv_ms": 1787089571513, "bids": [[1000.0, 35.76], [14272.1, 2.128], [14372.1, 2.072], [58114.8, 0.067], [61343.4, 0.0], [61343.5, 0.012], [61343.6, 0.005], [61989.2, 0.003], [63280.7, 0.02], [63487.3, 1.093], [63628.0, 7.378], [63635.8, 9.106], [63648.9, 19.3], [63821.7, 3.768], [63926.4, 1.408], [64457.5, 3.903], [64457.6, 0.0], [64467.4, 0.067], [64467.5, 1.507], [64468.9, 2.345], [64469.5, 0.002], [64480.0, 15.222], [64480.3, 0.0], [64501.7, 0.109], [64501.8, 0.004], [64512.6, 0.001], [64513.9, 0.05], [64525.7, 0.007], [64525.8, 0.064], [64527.4, 0.032], [64528.1, 0.042], [64537.5, 0.998], [64546.0, 0.445], [64548.0, 1.368], [64555.4, 0.117], [64556.8, 1.029], [64559.6, 1.863], [64563.0, 0.154], [64563.3, 0.001], [64563.4, 0.074], [64564.4, 0.013], [64564.5, 0.024], [64564.7, 0.001], [64565.1, 0.071], [64565.3, 0.285], [64565.4, 0.225], [64565.6, 0.095], [64566.1, 0.035], [64566.3, 2.476], [64566.5, 1.628], [64566.7, 0.748], [64567.0, 0.033], [64567.3, 0.171], [64568.6, 0.001], [64568.7, 0.085], [64569.0, 0.001], [64569.5, 0.162], [64569.6, 0.523], [64569.7, 2.321], [64570.8, 0.046], [64570.9, 0.0], [64571.0, 0.0], [64571.1, 0.0], [64571.3, 0.001], [64571.6, 0.493], [64572.1, 6.907]], "asks": [[64572.2, 0.314], [64572.8, 0.002], [64572.9, 1.396], [64573.0, 0.132], [64573.4, 0.095], [64573.6, 0.001], [64574.0, 0.087], [64578.0, 2.587], [64578.3, 0.465], [64580.3, 0.017], [64582.5, 0.001], [64584.0, 2.391], [64584.4, 0.354], [64584.6, 0.126], [64584.7, 0.47], [64584.9, 0.14], [64587.8, 0.008], [64589.0, 0.082], [64589.4, 0.004], [64591.3, 0.145], [64591.4, 2.114], [64592.0, 0.576], [64594.0, 0.006], [64594.3, 0.001], [64594.4, 0.45], [64597.0, 0.231], [64599.3, 2.043], [64599.4, 0.172], [64600.1, 1.893], [64601.2, 0.074], [64601.4, 1.341], [64603.3, 0.103], [64605.6, 0.0], [64607.1, 0.242], [64607.2, 0.536], [64607.4, 0.143], [64622.4, 0.436], [64622.6, 0.067], [64630.0, 0.02], [64630.4, 1.237], [64631.8, 0.224], [64638.9, 0.028], [64643.8, 0.046], [64643.9, 0.078], [64645.3, 0.028], [64651.8, 0.026], [64658.3, 0.027], [64664.7, 0.03], [64682.4, 2.323], [64683.3, 0.0], [64713.2, 3.92], [64846.6, 0.215], [65217.9, 0.0], [65500.5, 3.351], [65531.5, 0.0]]}
{"kind": "depth", "E": 1787089571657, "U": 11315994557015, "u": 11315994567257, "recv_ms": 1787089571615, "bids": [[14272.1, 2.492], [14372.1, 1.708], [51658.0, 0.0], [58114.8, 0.067], [61343.5, 0.014], [61989.2, 0.0], [63538.9, 8.334], [63572.1, 0.038], [63668.1, 12.423], [63725.0, 0.913], [63745.7, 0.788], [63926.4, 1.408], [64508.4, 0.035], [64508.7, 0.166], [64509.0, 1.249], [64509.4, 0.038], [64542.8, 0.106], [64545.7, 0.0], [64546.8, 0.057], [64560.7, 0.003], [64561.6, 1.196], [64561.9, 0.124], [64563.0, 0.696], [64564.8, 0.392], [64565.2, 0.201], [64565.5, 0.2], [64565.6, 0.165], [64565.7, 0.1]], "asks": [[64572.9, 1.396], [64573.0, 0.132], [64584.3, 0.264], [64584.4, 0.501], [64584.5, 0.534], [64584.7, 0.74], [64585.2, 2.398], [64592.0, 0.034], [64592.5, 0.543], [64593.1, 0.002], [64593.9, 1.138], [64596.7, 0.015], [64597.4, 0.562], [64597.6, 0.008], [64597.8, 6.597], [64598.7, 0.071], [64598.9, 0.132], [64603.7, 0.26], [64604.1, 0.272], [64606.9, 0.147], [64607.0, 2.953], [64607.7, 0.156], [65217.9, 0.0], [65572.2, 0.022]]}
{"kind": "depth", "E": 1787089571759, "U": 11315994567364, "u": 11315994578090, "recv_ms": 1787089571716, "bids": [[1000.0, 35.76], [14272.1, 2.842], [14372.1, 1.358], [51658.0, 0.0], [58114.8, 0.067], [61343.4, 0.0], [61989.2, 0.003], [63465.4, 0.629], [63635.8, 10.205], [63829.5, 2.817], [63926.4, 1.408], [64249.2, 4.798], [64542.4, 0.503], [64542.5, 0.141], [64542.7, 0.1], [64543.0, 0.119], [64545.7, 0.057], [64546.8, 0.0], [64555.2, 0.002], [64560.4, 1.383], [64561.6, 0.269], [64561.9, 0.666], [64563.0, 0.154], [64572.1, 6.911]], "asks": [[64572.2, 0.314], [64572.9, 0.003], [64573.0, 0.132], [64591.3, 0.687], [64592.5, 0.001], [64592.8, 1.185], [64593.9, 0.211], [64596.3, 0.565], [64597.4, 0.005], [64597.6, 0.065], [64598.7, 10.014], [64599.4, 0.018], [64599.5, 0.01], [64601.7, 0.967], [64602.5, 0.011], [64895.1, 3.08], [65217.9, 0.0], [65508.5, 19.205], [65863.6, 0.018]]}
{"kind": "depth", "E": 1787089571861, "U": 11315994578362, "u": 11315994589542, "recv_ms": 1787089571819, "bids": [[1000.0, 35.76], [14272.1, 3.192], [14372.1, 1.008], [58114.8, 0.067], [61343.4, 0.0], [63280.7, 0.023], [63384.0, 2.027], [63572.1, 0.018], [63764.9, 3.119], [63789.4, 9.056], [63918.7, 0.01], [63926.4, 1.408], [64047.7, 0.936], [64376.4, 0.973], [64415.1, 4.269], [64432.1, 2.453], [64508.1, 0.072], [64542.5, 0.211], [64543.3, 0.07], [64569.1, 0.085], [64570.7, 0.311], [64572.1, 6.912]], "asks": [[64572.9, 0.003], [64573.0, 1.525], [64573.1, 0.01], [64574.0, 0.003], [64599.4, 0.018], [64599.5, 0.164], [65327.3, 17.164], [65572.2, 0.002]]}
{"kind": "depth", "E": 1787089571963, "U": 11315994589758, "u": 11315994600056, "recv_ms": 1787089571920, "bids": [[14272.1, 3.556], [14372.1, 0.644], [51657.7, 0.0], [58114.8, 0.067], [61343.4, 0.0], [61989.2, 0.0], [63280.7, 0.023], [63487.3, 1.721], [63572.1, 0.038], [63579.9, 9.486], [63732.7, 4.112], [63764.9, 3.47], [63926.4, 1.564], [64301.5, 0.0], [64376.4, 5.864], [64415.1, 7.041], [64432.1, 4.017], [64468.9, 2.345], [64502.0, 8.201], [64539.3, 0.005], [64539.4, 0.032], [64539.5, 0.006], [64542.6, 0.072], [64542.8, 0.208], [64542.9, 0.462], [64543.0, 0.121], [64572.0, 0.006], [64572.1, 6.909]], "asks": [[64572.8, 0.003], [64572.9, 0.003], [64573.0, 0.132], [64598.4, 0.016], [64598.7, 0.014], [64599.4, 0.018], [64599.5, 0.164], [64601.0, 10.0], [64682.4, 2.323], [65217.9, 0.0], [65367.0, 0.857], [65513.5, 2.973], [65572.2, 0.022], [65863.6, 0.015]]}
{"kind": "depth", "E": 1787089572065, "U": 11315994600225, "u": 11315994612408, "recv_ms": 1787089572023, "bids": [[1000.0, 35.76], [14172.1, 0.07], [14272.1, 3.766], [14372.1, 0.364], [58114.8, 0.067], [61989.2, 0.003], [63926.4, 1.564], [64249.2, 4.798], [64530.8, 2.346], [64539.4, 0.007], [64541.2, 0.004], [64542.3, 1.049], [64543.0, 0.221], [64543.1, 2.392], [64545.9, 2.42], [64546.3, 0.235], [64555.3, 0.007], [64560.5, 0.002], [64566.5, 0.01], [64566.6, 0.373], [64566.7, 0.129], [64567.3, 0.713], [64567.4, 1.627], [64567.5, 0.008], [64572.0, 0.008], [64572.1, 6.909]], "asks": [[64572.2, 0.328], [64572.9, 1.396], [64573.0, 0.132], [64580.3, 0.017], [64581.5, 0.02], [64581.6, 0.032], [64587.7, 0.007], [64587.8, 0.085], [64589.0, 0.005], [64597.8, 6.713], [64598.9, 0.016], [64599.5, 0.01], [64599.7, 0.195], [64608.5, 0.003], [65217.9, 0.0], [65347.1, 22.96], [67398.9, 0.0]]}
{"kind": "depth", "E": 1787089572167, "U": 11315994612451, "u": 11315994623364, "recv_ms": 1787089572126, "bids": [[1000.0, 35.76], [14172.1, 0.308], [14272.1, 3.654], [14372.1, 0.238], [51658.0, 0.0], [58114.8, 0.067], [61343.4, 0.0], [61989.2, 0.0], [63572.1, 0.018], [63587.3, 0.003], [63588.3, 0.019], [63603.5, 0.361], [63628.0, 6.279], [63797.2, 14.322], [63926.4, 1.566], [64055.5, 6.39], [64350.8, 10.782], [64541.2, 0.006], [64547.4, 0.621], [64554.7, 0.624], [64561.2, 0.686], [64563.8, 0.2], [64572.1, 6.908]], "asks": [[64572.9, 0.003], [64573.0, 0.132], [64583.5, 0.658], [64590.7, 1.373], [64598.1, 1.121], [64599.5, 0.164], [64599.7, 0.041], [64608.4, 0.004], [65217.9, 0.0], [65521.4, 3.519], [65557.1, 0.008], [65572.2, 0.002], [71029.5, 0.001]]}
{"kind": "depth", "E": 1787089572269, "U": 11315994623382, "u": 11315994633735, "recv_ms": 1787089572225, "bids": [[14172.1, 0.532], [14272.1, 3.556], [14372.1, 0.112], [51658.0, 0.0], [58114.8, 0.067], [61343.4, 0.0], [62957.8, 0.873], [63926.4, 1.564], [64250.9, 0.108], [64494.6, 0.05], [64495.3, 0.01], [64499.7, 30.594], [64502.0, 4.828], [64528.5, 0.129], [64530.8, 2.321], [64539.4, 0.032], [64570.5, 0.02], [64572.1, 6.898]], "asks": [[64572.2, 0.328], [64572.9, 1.396], [64573.0, 0.132], [64585.2, 2.401], [64599.5, 0.01], [64599.6, 0.061], [64599.7, 0.041], [64649.7, 0.004], [64908.3, 0.113], [65217.9, 0.0], [65556.1, 0.014], [71029.5, 0.0], [71933.4, 0.104]]}
{"kind": "depth", "E": 1787089572371, "U": 11315994633764, "u": 11315994643124, "recv_ms": 1787089572329, "bids": [[1000.0, 35.91], [14172.1, 0.784], [14272.1, 3.416], [14372.1, 0.0], [58114.8, 0.067], [61343.4, 0.0], [61989.2, 0.003], [63635.8, 11.304], [63926.4, 1.564], [64249.2, 4.788], [64432.1, 3.781], [64435.1, 0.986], [64531.0, 0.021], [64539.4, 0.032], [64545.2, 7.421], [64545.6, 2.946], [64572.1, 6.897]], "asks": [[64572.9, 1.396], [64578.2, 0.007], [64597.8, 6.715], [64599.0, 3.935], [64599.7, 0.195], [64712.8, 5.436], [65217.9, 0.0], [65218.0, 2.653], [65485.9, 6.955], [65488.7, 6.417], [65741.1, 1.304], [66506.5, 0.003]]}
{"kind": "depth", "E": 1787089572473, "U": 11315994643302, "u": 11315994652634, "recv_ms": 1787089572437, "bids": [[1000.0, 35.76], [14172.1, 1.134], [14272.1, 3.066], [58114.8, 0.067], [61989.2, 0.0], [63572.1, 0.038], [63628.0, 5.18], [63770.3, 5.487], [63821.7, 2.829], [63926.4, 1.564], [64557.6, 0.064], [64563.8, 0.199], [64566.6, 0.311], [64572.0, 0.24], [64572.1, 6.902]], "asks": [[64572.9, 0.003], [64573.0, 1.525], [64578.2, 0.005], [64578.3, 0.467], [64599.7, 0.195], [65217.9, 0.0], [65572.2, 0.022], [65707.4, 0.0]]}
{"kind": "depth", "E": 1787089572575, "U": 11315994652704, "u": 11315994660738, "recv_ms": 1787089572533, "bids": [[14172.1, 1.498], [14272.1, 2.702], [51658.0, 0.004], [58114.8, 0.067], [61343.4, 0.0], [61343.5, 0.016], [61989.2, 0.003], [63620.4, 0.0], [63789.4, 8.43], [63861.8, 3.362], [63926.4, 1.564], [64047.7, 0.624], [64241.4, 0.31], [64495.3, 30.589], [64499.7, 0.015], [64542.3, 0.071], [64561.2, 0.161], [64563.8, 0.002], [64572.1, 6.902]], "asks": [[64572.6, 0.001], [64572.7, 1.393], [64572.9, 0.003], [64573.0, 0.132], [64578.3, 0.465], [64581.5, 0.0], [64599.7, 0.195], [65217.9, 0.0], [65508.5, 19.318], [65734.5, 0.607]]}
{"kind": "depth", "E": 1787089572677, "U": 11315994660910, "u": 11315994669187, "recv_ms": 1787089572636, "bids": [[1000.0, 35.76], [14172.1, 1.848], [14272.1, 2.352], [51658.0, 0.0], [58114.8, 0.067], [61343.4, 0.0], [61989.2, 0.0], [63158.1, 1.356], [63280.7, 0.02], [63447.5, 2.361], [63572.1, 0.018], [63613.8, 3.716], [63666.4, 11.449], [63821.7, 1.89], [63926.4, 1.564], [64249.2, 4.788], [64432.1, 3.781], [64495.3, 0.01], [64499.7, 30.594], [64571.2, 0.001], [64572.1, 6.899]], "asks": [[64572.2, 0.327], [64572.7, 0.0], [64572.8, 0.002], [64572.9, 0.003], [64573.0, 1.525], [64578.3, 0.467], [64712.8, 5.436], [65217.9, 0.0], [65387.3, 2.839], [65508.5, 20.385], [65516.4, 4.826], [65572.2, 0.002], [65722.4, 0.004]]}
{"kind": "depth", "E": 1787089572779, "U": 11315994669400, "u": 11315994677349, "recv_ms": 1787089572736, "bids": [[14172.1, 2.198], [14272.1, 2.002], [58114.8, 0.067], [61343.4, 0.0], [63629.3, 0.316], [63635.8, 12.403], [63797.2, 14.948], [63829.5, 3.756], [63926.4, 1.564], [64055.5, 6.702], [64249.2, 4.941], [64432.1, 3.781], [64462.3, 0.004], [64477.9, 0.001], [64494.6, 0.047], [64513.9, 0.047], [64541.9, 0.952], [64563.8, 0.002]], "asks": [[64572.2, 0.327], [64572.9, 1.396], [64573.0, 0.132], [64599.7, 0.041], [64630.4, 1.237], [64649.7, 0.001], [64712.8, 5.436], [65217.9, 0.0]]}
{"kind": "depth", "E": 1787089572881, "U": 11315994677421, "u": 11315994685816, "recv_ms": 1787089572841, "bids": [[14172.1, 2.576], [14272.1, 1.624], [58114.8, 0.067], [61343.4, 0.0], [61989.2, 0.003], [63572.1, 0.038], [63623.0, 0.118], [63635.8, 12.521], [63829.5, 4.695], [63926.4, 1.564], [64047.7, 0.312], [64249.2, 4.951], [64432.1, 3.57], [64485.9, 1.709], [64563.8, 0.001], [64563.9, 0.632], [64565.3, 0.201], [64569.5, 0.246], [64572.1, 6.923]], "asks": [[64572.9, 0.003], [64573.0, 1.525], [64573.2, 0.001], [64578.3, 0.465], [64599.7, 0.041], [64599.8, 0.17], [64895.1, 3.082], [65217.9, 0.0], [65411.6, 0.61], [65461.8, 3.322], [65540.8, 1.868], [65572.2, 0.022]]}
{"kind": "depth", "E": 1787089572983, "U": 11315994685845, "u": 11315994692330, "recv_ms": 1787089572940, "bids": [[1000.0, 35.76], [14172.1, 2.926], [14272.1, 1.274], [51657.7, 0.0], [58114.8, 0.067], [61989.2, 0.0], [63926.4, 1.564], [64175.9, 0.817], [64435.1, 1.449], [64495.3, 30.589], [64499.7, 0.015], [64502.0, 4.828], [64563.8, 0.002], [64563.9, 0.631], [64572.1, 6.922]], "asks": [[64572.9, 1.396], [64573.0, 0.132], [64573.1, 0.01], [64578.2, 0.005], [64580.3, 0.217], [64581.4, 0.02], [64583.5, 0.657], [64590.7, 0.754], [64598.9, 3.912], [64846.6, 0.015], [65217.9, 0.0], [65379.4, 4.55], [65481.5, 2.145]]}
{"kind": "depth", "E": 1787089573085, "U": 11315994692471, "u": 11315994700588, "recv_ms": 1787089573044, "bids": [[14172.1, 3.276], [14272.1, 0.924], [58114.8, 0.067], [61343.4, 0.0], [61989.2, 0.003], [63563.5, 4.87], [63572.1, 0.018], [63629.3, 0.707], [63926.4, 1.564], [64055.5, 7.014], [64495.3, 0.01], [64499.7, 30.717], [64555.3, 0.007], [64560.5, 0.002], [64561.2, 0.508], [64563.8, 0.127], [64563.9, 0.632], [64566.3, 2.474], [64567.0, 0.035], [64572.1, 6.92]], "asks": [[64572.9, 0.003], [64573.0, 0.132], [64573.1, 1.403], [64577.9, 0.005], [64578.3, 0.465], [64580.3, 0.217], [64587.7, 0.007], [65217.9, 0.0], [65379.4, 4.893], [65469.8, 2.409], [65572.2, 0.002], [65863.6, 0.018], [71933.4, 0.038]]}
{"kind": "depth", "E": 1787089573187, "U": 11315994700916, "u": 11315994709662, "recv_ms": 1787089573147, "bids": [[14172.1, 3.64], [14272.1, 0.56], [58114.8, 0.067], [61989.2, 0.0], [63382.9, 0.789], [63674.2, 3.331], [63926.4, 1.564], [64175.9, 0.816], [64249.2, 4.951], [64563.9, 0.631], [64568.0, 0.703], [64572.1, 6.921]], "asks": [[64572.9, 1.396], [64573.0, 0.132], [64573.1, 0.01], [64574.5, 0.003], [64576.1, 0.085], [64577.2, 0.084], [64577.9, 0.005], [64578.3, 0.465], [64580.3, 0.217], [64583.2, 0.008], [65217.9, 0.0]]}
{"kind": "depth", "E": 1787089573289, "U": 11315994709758, "u": 11315994718104, "recv_ms": 1787089573248, "bids": [[1000.0, 35.76], [14072.1, 0.126], [14172.1, 3.752], [14272.1, 0.322], [51658.0, 0.0], [58114.8, 0.067], [61343.5, 0.014], [61343.6, 0.007], [63571.2, 6.608], [63572.1, 0.038], [63926.4, 1.564], [64468.8, 3.819], [64468.9, 0.022], [64504.9, 0.113], [64545.7, 0.057], [64546.8, 0.0], [64557.7, 0.007], [64558.6, 0.0], [64560.4, 1.383], [64561.5, 0.041], [64561.9, 0.666], [64563.0, 0.154], [64563.1, 0.008], [64566.5, 0.002], [64566.7, 0.122], [64567.0, 0.033], [64567.3, 0.147], [64567.4, 0.002], [64567.5, 0.0], [64567.9, 0.003], [64569.8, 0.004], [64570.0, 0.006], [64570.1, 0.0], [64570.4, 0.629], [64570.5, 0.121], [64570.6, 0.001], [64570.8, 2.151], [64571.6, 0.808]], "asks": [[64572.2, 0.327], [64572.9, 0.003], [64573.0, 1.525], [64573.1, 0.01], [64578.1, 0.002], [64591.3, 0.687], [64591.4, 2.733], [64592.5, 0.001], [64592.8, 1.185], [64593.9, 0.211], [64596.3, 0.008], [64597.2, 0.648], [64597.5, 0.071], [64597.6, 0.008], [64597.8, 6.599], [64598.6, 0.001], [64598.8, 0.15], [64682.2, 2.323], [64682.4, 0.0], [65217.9, 0.0], [65540.8, 2.157], [65572.2, 0.022]]}
{"kind": "depth", "E": 1787089573391, "U": 11315994718264, "u": 11315994727549, "recv_ms": 1787089573347, "bids": [[14072.1, 0.364], [14172.1, 3.626], [14272.1, 0.21], [51658.0, 0.0], [58114.8, 0.067], [61343.4, 0.0], [61989.2, 0.003], [63572.1, 0.018], [63700.4, 0.951], [63789.4, 7.96], [63926.4, 1.564], [64376.4, 0.868], [64415.1, 4.48], [64432.1, 2.665], [64554.7, 0.005], [64560.5, 0.002], [64561.2, 0.161], [64563.0, 0.154], [64563.1, 0.0], [64563.2, 0.803], [64563.3, 0.001], [64563.8, 0.001], [64565.6, 0.081], [64566.4, 0.842], [64566.5, 1.566], [64566.7, 0.223], [64567.0, 0.033], [64567.3, 0.147], [64567.9, 0.001], [64570.0, 0.09], [64570.5, 0.001], [64570.8, 0.046], [64570.9, 0.0], [64571.0, 0.0], [64571.1, 0.0], [64571.6, 0.493], [64572.1, 6.925]], "asks": [[64572.2, 0.327], [64572.9, 0.003], [64573.0, 1.525], [64574.9, 0.001], [64577.9, 0.021], [64578.0, 2.671], [64578.1, 0.0], [64580.3, 0.201], [64591.4, 2.114], [64598.1, 0.502], [65217.9, 0.0], [65218.0, 2.652], [65500.5, 2.284], [65572.2, 0.002]]}
{"kind": "depth", "E": 1787089573493, "U": 11315994727705, "u": 11315994735927, "recv_ms": 1787089573449, "bids": [[14072.1, 0.602], [14172.1, 3.514], [14272.1, 0.084], [58114.8, 0.067], [61343.4, 0.0], [61989.2, 0.0], [63763.3, 2.966], [63926.4, 1.564], [64175.9, 0.815], [64241.4, 0.155], [64249.2, 4.941], [64376.4, 5.887], [64415.1, 7.065], [64432.1, 3.996], [64548.2, 0.0], [64549.1, 0.154], [64560.5, 0.01], [64563.2, 0.254], [64566.4, 0.84], [64566.5, 0.002], [64566.7, 0.122], [64566.8, 0.0], [64567.2, 0.283], [64567.3, 0.147], [64569.6, 0.465], [64569.8, 2.21], [64569.9, 0.001], [64570.3, 0.232], [64570.5, 0.02], [64571.6, 0.786]], "asks": [[64572.9, 0.003], [64573.0, 0.132], [64577.9, 0.005], [64578.2, 0.007], [64580.3, 0.217], [64582.1, 0.105], [64887.1, 0.511], [65080.8, 1.228], [65217.9, 0.002], [65508.5, 21.452]]}
{"kind": "depth", "E": 1787089573595, "U": 11315994735971, "u": 11315994744733, "recv_ms": 1787089573552, "bids": [[1000.0, 35.76], [14072.1, 0.868], [14172.1, 3.332], [14272.1, 0.0], [58114.8, 0.067], [61343.4, 0.0], [61989.2, 0.003], [63280.7, 0.023], [63403.2, 0.675], [63465.4, 0.0], [63926.4, 1.564], [64249.2, 5.096], [64534.8, 0.0], [64541.4, 0.005], [64543.0, 7.136], [64543.2, 2.857], [64545.2, 0.506], [64547.1, 1.213], [64549.0, 0.156], [64549.1, 0.0], [64560.5, 0.002], [64563.1, 0.0], [64563.2, 0.254], [64566.4, 0.842], [64566.5, 1.55], [64566.7, 0.671], [64566.8, 0.008], [64567.1, 0.458], [64567.2, 0.281], [64567.3, 0.147], [64567.9, 0.001], [64569.6, 0.735], [64569.8, 0.113], [64569.9, 0.001], [64570.5, 0.02], [64570.8, 0.046], [64571.6, 0.493], [64572.1, 6.922]], "asks": [[64572.2, 0.362], [64572.9, 0.003], [64573.0, 0.132], [64577.9, 0.021], [64578.2, 0.005], [64578.3, 0.467], [64580.3, 0.201], [64895.1, 3.236], [65088.8, 7.394], [65217.9, 0.0]]}
{"kind": "depth", "E": 1787089573697, "U": 11315994744796, "u": 11315994753107, "recv_ms": 1787089573655, "bids": [[14072.1, 1.218], [14172.1, 2.982], [58114.8, 0.067], [63487.3, 2.349], [63572.1, 0.038], [63666.9, 1.567], [63797.2, 15.418], [63926.4, 1.564], [64175.9, 0.814], [64549.0, 0.156], [64560.5, 0.01], [64563.0, 0.162], [64563.3, 0.001], [64566.4, 0.84], [64566.5, 0.002], [64566.7, 0.122], [64566.8, 0.0], [64567.1, 0.458], [64567.3, 0.128], [64567.9, 0.003], [64569.6, 0.465], [64569.8, 0.004], [64569.9, 0.001], [64570.3, 0.0], [64570.5, 0.001], [64570.8, 0.062], [64570.9, 0.239], [64571.0, 2.175], [64571.6, 0.74], [64572.0, 0.26]], "asks": [[64572.9, 0.003], [64573.0, 0.132], [64573.1, 0.01], [64577.9, 0.005], [64580.3, 0.217], [65217.9, 0.0], [65377.6, 3.535], [65387.1, 0.764], [65572.2, 0.022], [65863.6, 0.015]]}
{"kind": "depth", "E": 1787089573799, "U": 11315994753236, "u": 11315994762087, "recv_ms": 1787089573756, "bids": [[1000.0, 35.76], [14072.1, 1.582], [14172.1, 2.618], [51658.0, 0.0], [58114.8, 0.067], [61343.4, 0.0], [61989.2, 0.0], [63678.4, 0.627], [63926.4, 1.564], [64249.2, 5.096], [64376.4, 0.901], [64415.1, 3.375], [64432.1, 1.992], [64435.1, 0.986], [64508.2, 0.001], [64548.8, 0.7], [64549.0, 0.002], [64560.5, 0.002], [64563.0, 0.154], [64563.3, 0.001], [64566.4, 0.842], [64566.5, 0.002], [64566.7, 1.67], [64566.8, 0.0], [64567.3, 0.155], [64567.9, 0.001], [64569.6, 0.732], [64569.8, 0.12], [64569.9, 0.543], [64570.5, 0.02], [64570.8, 0.046], [64570.9, 0.232], [64571.0, 0.0], [64571.1, 0.0], [64571.6, 0.493], [64572.0, 0.262]], "asks": [[64572.2, 0.362], [64572.9, 0.003], [64573.0, 1.525], [64577.9, 0.005], [64580.3, 0.217], [64638.3, 0.002], [64712.7, 5.41], [64712.8, 0.027], [65217.9, 0.0], [67405.1, 0.0]]}
{"kind": "depth", "E": 1787089573901, "U": 11315994762349, "u": 11315994769601, "recv_ms": 1787089573859, "bids": [[1000.0, 35.76], [14072.1, 1.932], [14172.1, 2.268], [58114.8, 0.067], [61343.5, 0.016], [61989.2, 0.003], [63280.7, 0.026], [63572.1, 0.018], [63674.5, 4.34], [63821.7, 0.952], [63926.4, 1.564], [64376.4, 5.912], [64415.1, 6.182], [64432.1, 3.545], [64508.1, 4.517], [64560.5, 0.01], [64563.0, 0.162], [64563.3, 0.627], [64563.4, 0.082], [64566.4, 0.84], [64566.5, 0.002], [64566.7, 0.122], [64566.8, 0.0], [64567.1, 0.46], [64567.3, 0.128], [64567.9, 0.001], [64569.6, 0.465], [64569.8, 0.004], [64569.9, 0.001], [64570.0, 0.09], [64570.1, 0.0], [64570.5, 0.001], [64570.6, 0.001], [64570.8, 1.61], [64571.6, 0.821], [64572.1, 6.925]], "asks": [[64572.9, 0.003], [64573.0, 1.525], [64573.1, 0.01], [64583.8, 0.087], [64586.5, 1.447], [64587.8, 0.0], [64596.8, 0.434], [64625.5, 0.001], [64632.5, 0.004], [64637.7, 2.234], [64895.1, 3.234], [65217.9, 0.0], [65572.2, 0.002]]}
{"kind": "depth", "E": 1787089574003, "U": 11315994769811, "u": 11315994777770, "recv_ms": 1787089573962, "bids": [[14072.1, 2.296], [14172.1, 1.904], [51657.7, 0.0], [58114.8, 0.067], [61343.4, 0.0], [61989.2, 0.0], [63003.3, 0.008], [63280.7, 0.023], [63435.3, 0.0], [63563.5, 3.77], [63829.5, 5.633], [63834.8, 8.606], [63926.4, 1.564], [64047.7, 0.0], [64249.2, 5.098], [64432.1, 3.524], [64435.1, 0.986], [64495.3, 30.712], [64499.7, 0.015], [64502.0, 4.828], [64520.5, 0.345], [64532.8, 0.44], [64541.4, 0.001], [64560.5, 0.002], [64563.0, 0.154], [64563.3, 0.001], [64563.4, 0.074], [64566.4, 0.842], [64566.5, 1.55], [64566.7, 0.122], [64566.8, 0.008], [64567.1, 0.458], [64567.3, 0.147], [64569.6, 0.735], [64569.8, 0.662], [64570.8, 0.046], [64571.0, 0.0], [64571.6, 0.493], [64572.1, 6.924]], "asks": [[64572.9, 0.003], [64573.0, 0.132], [64573.1, 1.403], [64575.8, 0.003], [64583.2, 0.007], [64596.7, 5.1], [64598.9, 2.419], [64601.0, 0.0], [64712.7, 5.41], [65217.9, 0.0], [65565.0, 2.21]]}
{"kind": "depth", "E": 1787089574105, "U": 11315994777938, "u": 11315994786881, "recv_ms": 1787089574063, "bids": [[1000.0, 35.76], [14072.1, 2.646], [14172.1, 1.554], [51658.0, 0.0], [58114.8, 0.067], [61989.2, 0.003], [63572.1, 0.038], [63795.9, 6.105], [63926.4, 1.566], [64249.2, 5.108], [64462.3, 0.001], [64495.3, 0.01], [64499.7, 30.843], [64513.9, 0.05], [64545.1, 0.0], [64545.7, 0.0], [64546.0, 0.502], [64554.3, 0.117], [64555.3, 0.007], [64555.4, 0.001], [64555.5, 0.598], [64556.4, 0.0], [64559.7, 0.009], [64559.8, 0.007], [64559.9, 0.021], [64560.4, 0.456], [64560.5, 0.002], [64560.7, 0.93], [64561.9, 0.666], [64562.8, 0.872], [64566.0, 0.192], [64566.7, 0.788], [64566.8, 0.0], [64569.8, 0.004], [64569.9, 0.001], [64570.0, 0.09], [64570.1, 0.0], [64570.5, 0.001], [64570.7, 0.395], [64572.1, 6.954]], "asks": [[64572.2, 0.347], [64572.9, 1.396], [64573.0, 0.132], [64573.1, 0.01], [64575.3, 0.001], [64575.8, 0.0], [64578.3, 0.549], [64587.7, 0.007], [64590.6, 0.01], [64590.8, 0.0], [64591.3, 0.145], [64592.0, 0.576], [64592.1, 1.386], [64592.8, 0.258], [64593.0, 0.93], [64595.6, 2.494], [64596.5, 0.704], [64596.7, 0.015], [64597.2, 0.091], [64600.6, 10.0], [64630.4, 1.237], [65217.9, 0.0], [65461.8, 2.408], [65572.2, 0.022]]}
{"kind": "depth", "E": 1787089574207, "U": 11315994786973, "u": 11315994794679, "recv_ms": 1787089574164, "bids": [[1000.0, 35.76], [14072.1, 3.01], [14172.1, 1.19], [51658.0, 0.0], [58114.8, 0.067], [63461.5, 0.635], [63789.4, 8.743], [63803.7, 6.025], [63926.4, 1.564], [64532.8, 0.436], [64540.7, 0.006], [64562.0, 0.017], [64563.3, 0.001], [64566.4, 0.84], [64566.5, 0.002], [64566.7, 0.122], [64567.1, 0.458], [64567.9, 0.003], [64569.6, 0.465], [64569.8, 0.004], [64569.9, 0.109], [64570.0, 0.09], [64570.1, 2.09], [64570.5, 0.02], [64571.6, 0.732], [64572.1, 6.955]], "asks": [[64572.9, 0.003], [64573.0, 1.525], [64577.9, 0.021], [64578.2, 0.007], [64580.3, 0.201], [64582.7, 0.072], [64625.1, 0.391], [64632.5, 0.0], [65217.9, 0.0], [65469.8, 3.323]]}
{"kind": "depth", "E": 1787089574309, "U": 11315994794966, "u": 11315994803890, "recv_ms": 1787089574290, "bids": [[14072.1, 3.36], [14172.1, 0.84], [51658.0, 0.0], [58114.8, 0.067], [61343.4, 0.0], [61989.2, 0.0], [63571.2, 7.708], [63572.1, 0.018], [63926.4, 1.564], [64055.5, 7.326], [64432.1, 3.976], [64458.9, 0.091], [64470.8, 0.02], [64494.6, 0.05], [64511.7, 0.015], [64519.9, 0.001], [64530.8, 2.384], [64545.1, 0.057], [64546.0, 0.445], [64554.7, 0.624], [64559.8, 0.934], [64560.7, 0.003], [64561.2, 0.686], [64561.3, 0.543], [64561.9, 0.124], [64562.0, 0.001], [64563.8, 0.126], [64566.5, 1.55], [64566.6, 0.313], [64566.7, 0.788], [64567.9, 0.001], [64569.6, 0.735], [64569.9, 0.001], [64570.1, 0.0], [64570.5, 0.02], [64572.1, 6.953]], "asks": [[64572.2, 0.347], [64572.9, 0.003], [64573.0, 0.132], [64573.1, 0.01], [64577.9, 0.021], [64578.2, 0.005], [64580.3, 0.201], [64582.7, 0.071], [64590.6, 0.552], [64590.7, 1.373], [64592.0, 0.034], [64592.2, 1.237], [64593.0, 0.003], [64593.9, 0.23], [64597.1, 0.589], [64598.1, 1.121], [64598.8, 0.034], [64607.6, 0.28], [64649.7, 0.004], [64712.7, 5.41], [65217.9, 0.0], [65513.2, 1.096], [65572.2, 0.002], [65573.1, 9.593], [65863.6, 0.018]]}
{"kind": "depth", "E": 1787089574411, "U": 11315994803913, "u": 11315994814982, "recv_ms": 1787089574369, "bids": [[1000.0, 35.76], [14072.1, 3.696], [14172.1, 0.49], [14472.1, 0.014], [58114.8, 0.067], [61343.4, 0.0], [61989.2, 0.003], [63158.1, 0.678], [63447.5, 1.574], [63466.5, 1.574], [63926.4, 1.564], [64249.2, 5.108], [64457.4, 3.872], [64457.5, 0.031], [64468.7, 2.358], [64468.8, 1.496], [64495.3, 30.838], [64499.7, 0.015], [64501.6, 0.233], [64501.7, 0.063], [64532.8, 0.44], [64540.7, 0.002], [64548.8, 0.546], [64549.1, 0.0], [64554.7, 0.005], [64559.8, 0.007], [64559.9, 0.948], [64560.7, 0.003], [64566.4, 0.756], [64571.2, 0.001], [64572.1, 6.95]], "asks": [[64572.9, 0.003], [64573.0, 1.525], [64573.1, 0.015], [64575.7, 0.002], [64575.9, 1.892], [64576.1, 0.001], [64576.3, 0.011], [64577.9, 0.021], [64578.2, 0.007], [64578.7, 0.086], [64579.1, 0.084], [64580.3, 0.201], [64590.6, 0.01], [64590.7, 0.754], [64590.8, 0.0], [64592.0, 0.576], [64592.2, 0.31], [64593.1, 0.929], [64597.1, 0.473], [64598.0, 0.131], [64598.1, 0.502], [64643.8, 0.046], [64682.1, 2.325], [64682.2, 0.0], [64713.1, 3.872], [64713.2, 0.048], [65217.9, 0.0]]}
{"kind": "depth", "E": 1787089574513, "U": 11315994815123, "u": 11315994826230, "recv_ms": 1787089574476, "bids": [[1000.0, 35.76], [14072.1, 3.724], [14172.1, 0.294], [14472.1, 0.182], [58114.8, 0.067], [61989.2, 0.0], [63177.2, 2.145], [63572.1, 0.038], [63621.0, 2.058], [63668.1, 12.431], [63926.4, 1.564], [64495.3, 0.01], [64499.7, 30.843], [64532.8, 0.436], [64539.9, 1.319], [64548.8, 0.7], [64549.0, 0.002]], "asks": [[64573.0, 1.525], [64578.2, 0.005], [64580.0, 0.115], [64639.4, 0.207], [65217.9, 0.0], [65322.8, 7.644], [65339.1, 0.436], [65572.2, 0.022], [65742.5, 1.522]]}
{"kind": "depth", "E": 1787089574615, "U": 11315994826327, "u": 11315994839864, "recv_ms": 1787089574572, "bids": [[14072.1, 3.598], [14172.1, 0.182], [14472.1, 0.42], [58114.8, 0.067], [61343.4, 0.0], [61989.2, 0.003], [63384.0, 1.352], [63926.4, 1.564], [64376.4, 5.912], [64415.1, 7.082], [64432.1, 4.036], [64539.3, 0.003], [64539.4, 0.03], [64539.5, 0.004], [64542.8, 0.206], [64542.9, 0.46], [64543.0, 7.134], [64572.1, 6.951]], "asks": [[64573.0, 0.132], [64573.1, 0.015], [64593.3, 0.144], [64601.2, 0.025], [65040.8, 2.74], [65217.9, 0.0]]}
{"kind": "depth", "E": 1787089574717, "U": 11315994840052, "u": 11315994854061, "recv_ms": 1787089574674, "bids": [[1000.0, 35.76], [14072.1, 3.5], [14172.1, 0.056], [14472.1, 0.644], [58114.8, 0.067], [61343.4, 0.0], [63572.1, 0.018], [63666.9, 0.0], [64249.2, 5.108]], "asks": [[64572.2, 0.347], [64573.0, 1.525], [64573.1, 0.015], [64578.4, 0.008], [65217.9, 0.0], [65347.1, 25.403], [65572.2, 0.002]]}
{"kind": "depth", "E": 1787089574819, "U": 11315994854270, "u": 11315994868289, "recv_ms": 1787089574777, "bids": [[1000.0, 35.76], [14072.1, 3.248], [14172.1, 0.0], [14472.1, 0.952], [58114.8, 0.067], [61343.5, 0.014], [61343.6, 0.009], [61989.2, 0.0], [63401.8, 0.804], [63628.7, 4.236], [63885.9, 0.001], [63926.4, 1.564], [64529.5, 0.006], [64539.9, 1.315], [64566.4, 0.84], [64566.5, 0.002], [64566.7, 0.13], [64569.8, 2.208], [64569.9, 0.003], [64570.0, 0.006], [64570.7, 0.311], [64571.6, 0.493], [64572.1, 6.948]], "asks": [[64573.0, 0.132], [64574.9, 0.085], [64575.5, 0.088], [64579.1, 0.0], [64625.1, 0.387], [64633.4, 0.004], [65217.9, 0.0], [65508.5, 22.213]]}
{"kind": "depth", "E": 1787089574921, "U": 11315994868467, "u": 11315994879990, "recv_ms": 1787089574877, "bids": [[14072.1, 2.898], [14472.1, 1.302], [58114.8, 0.067], [61343.5, 0.016], [61989.2, 0.003], [63498.9, 1.101], [63572.1, 0.038], [63628.0, 4.081], [63639.6, 0.0], [64432.1, 4.007], [64474.4, 0.0], [64498.3, 0.014], [64544.7, 0.05], [64551.8, 0.011], [64561.9, 0.14], [64563.3, 0.543], [64566.5, 1.55], [64566.6, 0.311], [64566.7, 0.122], [64567.1, 0.46], [64567.3, 0.128], [64567.7, 0.098], [64569.6, 0.465], [64569.8, 0.086], [64569.9, 0.003], [64570.0, 0.03], [64570.5, 0.001], [64570.7, 0.001], [64571.0, 0.0], [64571.4, 0.313], [64571.6, 0.755]], "asks": [[64573.0, 1.525], [64573.1, 0.015], [64573.3, 0.0], [64574.7, 0.366], [64576.4, 0.087], [64578.3, 0.551], [64578.4, 0.006], [64624.6, 0.21], [64631.8, 0.014], [64633.4, 0.0], [64712.7, 5.41], [65217.9, 0.0], [65334.7, 1.567], [65572.2, 0.022]]}
{"kind": "depth", "E": 1787089575023, "U": 11315994880357, "u": 11315994891120, "recv_ms": 1787089574981, "bids": [[1000.0, 35.76], [14072.1, 2.534], [14472.1, 1.666], [51657.7, 0.0], [58114.8, 0.067], [61343.4, 0.0], [61989.2, 0.0], [63661.6, 1.726], [63674.5, 5.907], [63858.9, 0.876], [63926.4, 1.564], [64249.2, 5.096], [64415.1, 7.024], [64432.1, 4.007], [64435.1, 1.514], [64495.3, 30.838], [64499.7, 0.015], [64502.0, 4.828], [64508.1, 4.555], [64516.4, 0.008], [64527.5, 0.416], [64530.5, 0.024], [64539.4, 0.03], [64548.6, 2.473], [64548.8, 0.546], [64559.9, 0.021], [64560.1, 0.01], [64560.7, 0.93], [64561.3, 0.001], [64561.9, 0.666], [64563.3, 0.001], [64566.4, 0.84], [64566.5, 1.55], [64566.7, 0.122], [64567.1, 0.458], [64567.3, 0.128], [64567.7, 0.1], [64569.6, 0.465], [64569.8, 0.66], [64570.0, 0.006], [64570.1, 0.0], [64571.6, 0.806]], "asks": [[64572.2, 0.346], [64573.0, 1.525], [64573.1, 0.015], [64578.3, 0.549], [64626.0, 0.261], [64637.5, 2.186], [64637.7, 0.007], [64712.7, 5.41], [64729.7, 10.428], [64895.1, 3.236], [65217.9, 0.0], [65513.2, 0.716]]}
{"kind": "depth", "E": 1787089575125, "U": 11315994891304, "u": 11315994900327, "recv_ms": 1787089575082, "bids": [[1000.0, 35.76], [14072.1, 2.184], [14472.1, 2.016], [58114.8, 0.067], [61343.6, 0.007], [63572.1, 0.018], [63926.4, 1.564], [64055.5, 7.33], [64412.5, 0.0], [64471.6, 0.15], [64495.3, 0.01], [64499.7, 30.902], [64507.5, 0.416], [64528.2, 0.061], [64529.5, 0.002], [64545.1, 0.0], [64546.1, 0.058], [64555.3, 0.005], [64560.1, 0.002], [64560.5, 0.002], [64566.5, 1.552], [64566.7, 0.788], [64567.7, 0.098], [64569.6, 0.645], [64569.8, 0.002], [64569.9, 0.003], [64571.6, 0.493]], "asks": [[64572.2, 0.347], [64573.0, 1.525], [64578.4, 0.006], [64581.5, 0.001], [64587.7, 0.005], [64597.5, 0.014], [64597.9, 0.071], [64626.0, 0.257], [64633.4, 0.004], [65217.9, 0.0], [65302.8, 0.003], [65572.2, 0.002], [65676.2, 0.003], [104929.0, 0.0]]}
{"kind": "depth", "E": 1787089575227, "U": 11315994900658, "u": 11315994908728, "recv_ms": 1787089575185, "bids": [[14072.1, 1.82], [14472.1, 2.38], [58114.8, 0.067], [61989.2, 0.003], [63506.7, 3.303], [63635.8, 13.62], [63764.9, 3.821], [63926.4, 1.564], [64055.5, 7.326], [64503.6, 0.0], [64526.2, 0.033], [64540.8, 0.011], [64541.9, 0.001], [64555.3, 0.007], [64567.3, 0.147]], "asks": [[64573.0, 1.525], [64573.1, 0.015], [64587.7, 0.007], [64605.3, 0.002], [64621.2, 1.097], [64621.5, 0.0], [64625.1, 0.391], [64633.4, 0.0], [64644.1, 0.0], [65217.9, 0.0], [65515.0, 0.381], [65668.2, 2.206]]}
{"kind": "depth", "E": 1787089575329, "U": 11315994909016, "u": 11315994917804, "recv_ms": 1787089575285, "bids": [[1000.0, 35.76], [14072.1, 1.47], [14472.1, 2.73], [58114.8, 0.067], [61343.4, 0.0], [61989.2, 0.0], [62369.0, 0.036], [63572.1, 0.038], [63926.4, 1.564], [64249.2, 5.106], [64471.3, 0.003], [64473.4, 1.922], [64494.6, 0.05], [64512.6, 0.029], [64513.9, 0.047], [64545.1, 0.057], [64546.1, 0.001], [64559.8, 0.007], [64560.5, 0.929], [64560.7, 0.003], [64561.3, 0.001], [64561.9, 0.666], [64567.3, 0.128]], "asks": [[64572.2, 0.472], [64573.0, 1.525], [64573.1, 0.015], [64578.4, 0.008], [64580.9, 0.052], [64582.1, 0.083], [64590.6, 0.01], [64591.3, 0.687], [64592.0, 0.034], [64592.2, 0.31], [64592.9, 1.571], [64593.1, 0.002], [64596.9, 0.0], [64597.6, 0.065], [64597.9, 0.014], [64630.4, 1.237], [64649.7, 0.001], [64675.4, 0.769], [64676.5, 0.011], [65217.9, 0.0], [65474.5, 4.758], [65572.2, 0.022], [65684.1, 4.106]]}
{"kind": "depth", "E": 1787089575431, "U": 11315994918157, "u": 11315994926265, "recv_ms": 1787089575388, "bids": [[1000.0, 35.76], [14072.1, 1.106], [14472.1, 3.094], [58114.8, 0.067], [61343.5, 0.018], [61989.2, 0.003], [63698.7, 5.4], [63926.4, 1.564], [64503.1, 6.004], [64525.7, 3.507], [64541.9, 0.963], [64567.3, 0.147], [64569.9, 0.001], [64570.5, 0.003], [64570.8, 0.356], [64571.4, 0.003], [64571.9, 0.009]], "asks": [[64572.9, 0.003], [64573.0, 0.132], [64605.6, 0.967], [64621.7, 3.5], [64644.4, 7.878], [65064.6, 0.0], [65217.9, 0.0], [65456.4, 16.941], [65461.8, 1.524], [65516.4, 4.483], [65863.6, 0.021], [67800.8, 0.058], [71909.4, 0.0], [104929.0, 0.236]]}
{"kind": "depth", "E": 1787089575533, "U": 11315994926381, "u": 11315994935874, "recv_ms": 1787089575490, "bids": [[14072.1, 0.742], [14472.1, 3.458], [58114.8, 0.067], [61343.4, 0.0], [61989.2, 0.0], [63572.1, 0.018], [63594.6, 0.353], [63700.4, 1.578], [63770.2, 1.581], [63926.4, 1.564], [64436.1, 4.27], [64495.3, 30.897], [64499.7, 0.015], [64538.0, 2.002], [64545.1, 0.0], [64545.7, 0.057], [64546.8, 0.0], [64547.4, 0.002], [64554.3, 0.001], [64554.8, 0.466], [64555.0, 0.215], [64555.5, 0.04], [64556.1, 0.003], [64556.2, 0.559], [64557.2, 0.0], [64560.4, 1.383], [64560.5, 0.01], [64561.2, 0.161], [64561.3, 0.543], [64561.5, 0.041], [64561.9, 0.124], [64563.0, 0.154], [64563.1, 0.0], [64563.8, 0.001], [64564.5, 0.021], [64565.6, 0.165], [64566.0, 0.276], [64566.5, 0.004], [64566.7, 0.122], [64566.8, 0.0], [64567.3, 0.128], [64569.1, 0.001], [64569.5, 0.162], [64569.6, 0.465], [64569.8, 2.099], [64569.9, 0.11], [64571.6, 0.789], [64571.9, 0.007], [64572.1, 6.556]], "asks": [[64572.2, 0.473], [64572.8, 1.395], [64572.9, 0.003], [64573.0, 0.132], [64573.1, 0.015], [64573.3, 0.966], [64573.7, 0.084], [64574.1, 0.084], [64574.6, 0.002], [64576.0, 0.967], [64577.5, 0.0], [64577.9, 0.005], [64578.0, 2.674], [64578.3, 0.465], [64578.7, 0.002], [64579.0, 0.021], [64579.8, 0.311], [64580.3, 0.217], [64580.5, 9.541], [64581.5, 0.0], [64590.8, 0.0], [64591.3, 0.687], [64592.4, 0.003], [64592.5, 0.001], [64592.8, 0.258], [64592.9, 0.644], [64593.8, 0.927], [64593.9, 0.23], [64595.9, 5.381], [64596.5, 0.147], [64597.4, 0.562], [64597.5, 0.014], [64597.6, 0.008], [64598.0, 0.015], [64598.2, 0.619], [64598.5, 2.376], [64598.6, 0.001], [64598.7, 0.021], [64598.8, 0.15], [64599.2, 0.0], [64600.6, 0.0], [65080.8, 0.921], [65083.5, 0.0], [65217.9, 0.0], [65379.4, 5.121], [65572.2, 0.002], [65669.9, 7.524]]}
{"kind": "depth", "E": 1787089575635, "U": 11315994935962, "u": 11315994943736, "recv_ms": 1787089575594, "bids": [[1000.0, 35.76], [14072.1, 0.434], [14372.1, 0.042], [14472.1, 3.724], [51658.0, 0.0], [58114.8, 0.067], [61343.4, 0.0], [63763.3, 2.701], [63926.4, 1.564], [64249.2, 5.096], [64468.6, 2.357], [64468.7, 0.035], [64470.9, 10.0], [64473.4, 3.32], [64495.3, 0.01], [64499.7, 30.902], [64538.0, 0.002], [64560.5, 0.552], [64561.3, 0.001], [64561.9, 0.132], [64563.1, 0.0], [64563.3, 0.001], [64563.9, 0.631], [64566.5, 0.004], [64569.4, 0.234], [64569.8, 0.012], [64569.9, 0.017], [64570.0, 0.006], [64570.1, 0.0], [64570.5, 0.086], [64570.6, 2.091], [64570.9, 0.0], [64572.1, 6.556]], "asks": [[64572.8, 0.002], [64572.9, 0.003], [64579.0, 0.02], [64580.2, 0.003], [64580.9, 0.033], [64581.4, 0.0], [64581.6, 0.009], [64595.8, 0.127], [64597.3, 0.33], [64599.8, 0.19], [64606.7, 0.179], [64675.4, 2.169], [64676.7, 10.0], [64682.0, 3.097], [64682.1, 0.002], [65088.8, 8.62], [65177.8, 0.029], [65217.9, 0.0], [65469.8, 4.207], [65476.2, 18.819]]}
{"kind": "depth", "E": 1787089575737, "U": 11315994943833, "u": 11315994951645, "recv_ms": 1787089575694, "bids": [[1000.0, 35.76], [14072.1, 0.266], [14372.1, 0.224], [14472.1, 3.71], [58114.8, 0.067], [61343.4, 0.0], [61989.2, 0.003], [63447.5, 0.787], [63572.1, 0.038], [63853.9, 0.782], [63926.4, 1.564], [64432.1, 4.226], [64435.1, 0.986], [64530.9, 0.801], [64539.4, 0.005], [64560.5, 0.01], [64561.9, 0.674], [64563.3, 0.635], [64566.5, 0.004], [64569.1, 0.085], [64569.5, 0.246], [64569.8, 0.002], [64569.9, 0.001], [64570.5, 0.003], [64570.6, 0.001], [64570.9, 0.001], [64571.0, 0.0], [64571.1, 0.0], [64571.7, 1.564], [64571.9, 0.009], [64572.1, 6.552]], "asks": [[64572.2, 0.467], [64572.7, 0.0], [64572.8, 1.395], [64573.3, 0.0], [64573.7, 0.0], [64574.1, 0.0], [64577.9, 0.021], [64580.2, 0.002], [64580.3, 0.201], [64580.6, 41.645], [64598.2, 0.0], [64712.7, 5.41], [64758.0, 0.006], [64758.1, 0.005], [65217.9, 0.0], [65516.4, 4.14], [65540.8, 2.5], [65572.2, 0.022]]}
{"kind": "depth", "E": 1787089575839, "U": 11315994951967, "u": 11315994960076, "recv_ms": 1787089575796, "bids": [[14072.1, 0.154], [14372.1, 0.476], [14472.1, 3.57], [58114.8, 0.067], [61343.5, 0.016], [61343.6, 0.009], [61989.2, 0.0], [63603.5, 0.675], [63926.4, 1.564], [64530.9, 0.776], [64539.2, 0.462], [64560.5, 0.01], [64561.9, 0.666], [64563.3, 0.001], [64565.6, 0.081], [64566.5, 0.004], [64566.7, 0.122], [64567.3, 0.147], [64569.6, 0.465], [64569.8, 2.208], [64569.9, 0.003], [64570.0, 0.09], [64570.5, 0.02], [64571.6, 0.784], [64571.7, 0.0], [64571.9, 0.007]], "asks": [[64572.7, 0.0], [64572.8, 1.395], [64573.0, 0.224], [64573.3, 0.954], [64574.9, 0.001], [64577.9, 0.005], [64578.3, 0.549], [64580.3, 0.217], [64640.2, 3.533], [64642.5, 0.015], [64643.4, 0.093], [64644.7, 0.001], [64649.1, 38.01], [65087.0, 0.056], [65088.8, 8.927], [65185.6, 2.296], [65217.9, 0.0], [67800.8, 0.063]]}
{"kind": "depth", "E": 1787089575941, "U": 11315994960199, "u": 11315994968178, "recv_ms": 1787089575898, "bids": [[1000.0, 35.76], [14072.1, 0.028], [14372.1, 0.7], [14472.1, 3.472], [58114.8, 0.067], [61989.2, 0.003], [63413.7, 0.042], [63572.1, 0.018], [63926.4, 1.564], [64249.2, 5.096], [64545.0, 0.072], [64545.7, 0.0], [64550.0, 0.325], [64555.4, 0.559], [64556.2, 0.001], [64559.7, 0.936], [64560.4, 0.456], [64560.5, 0.552], [64561.9, 0.124], [64566.5, 0.002], [64567.2, 0.283]], "asks": [[64572.6, 0.001], [64572.7, 0.0], [64572.8, 0.002], [64592.0, 0.034], [64592.9, 1.571], [64593.8, 0.0], [64595.6, 3.051], [64597.4, 0.005], [64644.7, 38.011], [64649.1, 0.0], [65217.9, 0.0], [65541.3, 0.349], [65572.2, 0.002]]}
{"kind": "depth", "E": 1787089576043, "U": 11315994968194, "u": 11315994974916, "recv_ms": 1787089576047, "bids": [[1000.0, 35.76], [14072.1, 0.0], [14372.1, 1.036], [14472.1, 3.164], [51657.7, 0.0], [58114.8, 0.067], [61343.4, 0.0], [62956.1, 0.476], [63280.7, 0.023], [63628.0, 2.983], [63763.3, 2.435], [63926.4, 1.564], [64435.1, 1.547], [64495.3, 30.925], [64499.7, 0.015], [64502.0, 4.828], [64542.0, 0.001], [64548.6, 2.319], [64549.0, 0.156], [64560.5, 0.015], [64561.9, 0.666], [64570.9, 0.0], [64571.6, 0.799], [64572.1, 6.556]], "asks": [[64572.7, 0.0], [64572.8, 1.395], [64572.9, 0.003], [64577.9, 0.005], [64580.3, 0.217], [64597.5, 0.071], [64598.5, 2.319], [64599.8, 0.036], [64642.5, 0.015], [64644.7, 38.011], [64649.1, 0.0], [64895.1, 3.234], [65217.9, 0.0], [65515.0, 0.671]]}
{"kind": "depth", "E": 1787089576145, "U": 11315994974991, "u": 11315994983858, "recv_ms": 1787089576103, "bids": [[14372.1, 1.386], [14472.1, 2.814], [58114.8, 0.067], [61989.2, 0.0], [63177.2, 2.822], [63466.5, 2.361], [63572.1, 0.038], [63588.3, 0.009], [63635.8, 14.718], [63789.4, 8.273], [63835.1, 0.786], [63926.4, 1.564], [64249.2, 5.098], [64478.8, 0.044], [64494.2, 0.041], [64495.3, 0.01], [64499.7, 30.93], [64507.2, 0.439], [64507.5, 0.417], [64530.9, 0.801], [64539.2, 0.437], [64555.3, 0.005], [64555.4, 0.001], [64556.0, 0.561], [64557.7, 0.0], [64558.5, 1.133], [64559.7, 0.009], [64560.5, 0.937]], "asks": [[64572.7, 0.0], [64572.8, 1.395], [64577.9, 0.005], [64580.3, 0.217], [64581.8, 0.022], [64582.0, 0.095], [64584.5, 0.535], [64587.1, 0.323], [64587.7, 0.005], [64587.9, 1.617], [64595.6, 2.494], [64596.4, 0.599], [64597.8, 6.715], [64598.8, 0.034], [64599.3, 2.197], [64636.8, 0.004], [65217.9, 0.0], [65555.9, 0.002], [65572.2, 0.022]]}
{"kind": "depth", "E": 1787089576247, "U": 11315994984008, "u": 11315995003984, "recv_ms": 1787089576205, "bids": [[1000.0, 35.76], [14372.1, 1.75], [14472.1, 2.45], [58114.8, 0.067], [61343.4, 0.0], [61989.2, 0.003], [62957.8, 0.875], [63280.7, 0.026], [63435.6, 3.705], [63589.4, 0.285], [63648.9, 16.947], [63926.4, 1.564], [64249.2, 5.108], [64432.1, 0.022], [64475.4, 0.03], [64479.7, 0.008], [64480.0, 15.217], [64481.8, 0.075], [64488.3, 0.039], [64494.7, 0.157], [64495.0, 0.383], [64498.9, 0.035], [64501.2, 0.04], [64507.6, 2.325], [64520.5, 0.32], [64538.9, 6.915], [64539.3, 0.005], [64539.4, 0.007], [64539.5, 0.006], [64539.9, 1.319], [64540.5, 2.156], [64542.8, 0.208], [64542.9, 0.462], [64543.0, 0.221], [64543.2, 2.08], [64549.0, 0.002], [64549.1, 0.154], [64555.3, 0.007], [64559.3, 0.002], [64560.5, 0.929], [64560.6, 0.018], [64563.0, 0.154], [64563.1, 0.0], [64566.3, 2.476], [64566.5, 1.566], [64566.7, 0.772], [64567.2, 0.281], [64569.5, 0.162], [64569.6, 0.744], [64569.7, 0.002], [64569.8, 0.003], [64569.9, 2.322], [64570.0, 0.006], [64570.6, 0.311], [64570.8, 0.046], [64571.6, 0.508], [64572.1, 6.94]], "asks": [[64572.6, 0.001], [64572.7, 0.0], [64572.8, 1.395], [64573.3, 0.0], [64574.3, 0.001], [64574.6, 0.086], [64575.1, 0.09], [64578.3, 0.465], [64578.4, 0.006], [64587.7, 0.007], [64593.7, 0.008], [64594.0, 0.001], [64599.2, 0.0], [64599.3, 2.043], [64599.4, 0.172], [64617.0, 0.031], [64624.6, 0.0], [64624.8, 0.993], [64636.7, 0.0], [64640.6, 0.029], [64642.5, 38.025], [64644.7, 0.001], [64712.7, 0.001], [65217.9, 0.0], [65335.1, 3.822], [65555.0, 76.254], [67800.8, 0.068]]}
{"kind": "depth", "E": 1787089576349, "U": 11315995004185, "u": 11315995027691, "recv_ms": 1787089576307, "bids": [[1000.0, 35.76], [14372.1, 2.1], [14472.1, 2.1], [51658.0, 0.0], [58114.8, 0.067], [61343.4, 0.0], [61989.2, 0.0], [63572.1, 0.018], [63797.2, 15.888], [63926.4, 1.564], [64432.1, 4.234], [64435.1, 0.986], [64479.6, 0.005], [64479.7, 0.003], [64479.8, 0.004], [64485.0, 0.157], [64487.2, 0.028], [64491.5, 0.073], [64493.6, 0.267], [64495.5, 0.336], [64497.4, 0.003], [64497.9, 0.0], [64498.9, 0.009], [64500.1, 0.031], [64504.4, 0.004], [64506.5, 0.24], [64507.5, 0.42], [64510.8, 0.451], [64513.0, 0.252], [64513.9, 0.05], [64530.9, 0.776], [64539.3, 0.03], [64545.0, 0.015], [64546.1, 0.058], [64549.0, 0.156], [64549.1, 0.0], [64549.6, 0.0], [64551.7, 0.007], [64556.8, 1.069], [64558.5, 1.133], [64561.5, 0.001], [64563.9, 0.632], [64565.3, 0.285], [64565.6, 0.165], [64566.5, 0.002], [64566.7, 0.671], [64566.8, 0.0], [64567.3, 0.224], [64567.4, 1.55], [64567.5, 0.04], [64568.7, 0.001], [64569.1, 0.001], [64569.6, 0.66], [64570.6, 0.001], [64572.1, 6.948]], "asks": [[64572.2, 0.469], [64572.7, 0.0], [64572.8, 1.395], [64573.0, 0.224], [64573.3, 1.05], [64573.6, 0.085], [64574.0, 0.087], [64574.7, 0.676], [64578.0, 2.59], [64578.3, 0.465], [64579.9, 0.0], [64580.5, 9.542], [64580.6, 41.644], [64589.3, 2.331], [64591.9, 0.626], [64592.0, 10.034], [64593.6, 0.44], [64593.7, 0.003], [64593.8, 0.0], [64595.4, 0.009], [64595.9, 0.296], [64596.4, 0.042], [64596.7, 0.572], [64597.8, 6.599], [64598.2, 0.116], [64599.4, 0.018], [64599.6, 0.215], [64599.8, 0.106], [64600.1, 1.893], [64602.3, 0.101], [64607.0, 2.883], [64612.0, 0.039], [64612.1, 0.0], [64617.4, 0.003], [64619.3, 0.003], [64624.8, 0.783], [64625.3, 0.0], [64625.4, 0.211], [64637.2, 0.026], [64638.9, 0.028], [64639.1, 0.102], [64640.6, 0.003], [64642.5, 0.015], [64644.7, 38.011], [64645.3, 0.028], [64646.9, 0.0], [64649.7, 0.004], [64651.8, 0.026], [64658.3, 0.027], [64664.7, 0.03], [64712.7, 5.41], [65217.9, 0.0], [65345.3, 1.553], [65572.2, 0.002]]}
{"kind": "depth", "E": 1787089576451, "U": 11315995027932, "u": 11315995040866, "recv_ms": 1787089576408, "bids": [[14372.1, 2.464], [14472.1, 1.736], [51658.0, 0.0], [58114.8, 0.067], [61989.2, 0.003], [63403.2, 1.35], [63545.4, 1.464], [63698.7, 5.244], [63926.4, 1.564], [64506.5, 0.03], [64513.7, 0.373], [64548.4, 0.469], [64549.0, 0.002], [64569.4, 0.002], [64570.3, 0.232]], "asks": [[64572.7, 0.0], [64572.8, 0.002], [64573.1, 0.01], [64573.6, 0.09], [64578.3, 0.465], [64579.9, 0.001], [64580.5, 9.541], [64625.4, 0.001], [64632.0, 0.647], [65217.9, 0.002], [65258.2, 0.23], [71933.4, 0.0]]}
{"kind": "depth", "E": 1787089576553, "U": 11315995041005, "u": 11315995051214, "recv_ms": 1787089576510, "bids": [[1000.0, 35.76], [14372.1, 2.814], [14472.1, 1.386], [58114.8, 0.067], [61343.4, 0.0], [61343.6, 0.007], [63280.7, 0.023], [63563.5, 2.671], [63572.1, 0.038], [63668.1, 14.783], [63830.6, 0.469], [63926.4, 1.564], [64249.2, 5.098], [64462.3, 0.001], [64494.6, 0.047], [64513.9, 0.047], [64547.4, 0.621], [64554.8, 1.085], [64572.1, 6.942]], "asks": [[64572.2, 0.497], [64572.7, 1.393], [64572.8, 0.002], [64572.9, 0.003], [64578.2, 0.007], [64579.9, 0.0], [64580.0, 0.122], [64580.5, 9.542], [64580.8, 0.007], [64590.8, 0.619], [64595.9, 0.296], [64598.1, 0.505], [64598.2, 0.735], [64630.4, 1.234], [64649.7, 0.004], [65080.8, 0.0], [65217.9, 0.0], [65270.5, 3.825], [65377.6, 3.307], [65572.2, 0.022], [65657.8, 4.568]]}
{"kind": "depth", "E": 1787089576655, "U": 11315995051455, "u": 11315995061850, "recv_ms": 1787089576611, "bids": [[1000.0, 35.76], [14372.1, 3.178], [14472.1, 1.022], [58114.8, 0.067], [61343.4, 0.0], [61343.5, 0.014], [61343.6, 0.009], [61989.2, 0.0], [63280.7, 0.026], [63926.4, 1.564], [64519.4, 0.014], [64545.6, 3.003], [64546.1, 0.001], [64554.8, 0.466], [64572.1, 6.941]], "asks": [[64572.2, 0.498], [64572.6, 0.001], [64572.7, 0.0], [64572.8, 1.395], [64578.2, 0.007], [64590.8, 0.0], [64598.2, 0.116], [64599.6, 0.215], [65217.9, 0.0], [67800.8, 0.073]]}
{"kind": "depth", "E": 1787089576757, "U": 11315995061932, "u": 11315995071306, "recv_ms": 1787089576714, "bids": [[14372.1, 3.542], [14472.1, 0.658], [58114.8, 0.067], [61343.4, 0.0], [61989.2, 0.003], [63280.7, 0.023], [63572.1, 0.018], [63926.4, 1.564], [64563.9, 0.632], [64564.8, 0.392], [64568.6, 0.085], [64570.7, 0.311], [64571.9, 0.007], [64572.1, 6.942]], "asks": [[64572.2, 0.449], [64572.6, 1.394], [64572.7, 0.0], [64572.8, 0.002], [64573.3, 0.705], [64573.6, 0.006], [64574.8, 0.001], [64575.9, 1.892], [64576.0, 1.451], [64577.3, 0.014], [64577.4, 1.806], [64577.9, 0.013], [64578.1, 0.001], [64578.2, 0.005], [64578.5, 0.103], [64580.1, 0.312], [64580.3, 0.001], [64580.5, 9.541], [64619.1, 2.319], [64639.4, 0.216], [64846.6, 0.215], [65088.8, 9.848], [65217.9, 0.0], [65282.5, 0.995], [65327.3, 15.635], [65354.8, 0.764], [65572.2, 0.002], [65863.6, 0.018]]}
{"kind": "depth", "E": 1787089576859, "U": 11315995071391, "u": 11315995080598, "recv_ms": 1787089576816, "bids": [[1000.0, 35.76], [14272.1, 0.07], [14372.1, 3.752], [14472.1, 0.378], [51658.0, 0.0], [58114.8, 0.067], [61989.2, 0.0], [63280.7, 0.02], [63447.4, 0.0], [63571.2, 8.807], [63763.3, 2.201], [63828.2, 0.786], [63834.9, 3.513], [63854.6, 0.24], [63926.4, 1.564], [64249.2, 5.108], [64547.4, 0.002], [64560.6, 0.56], [64561.9, 0.124], [64572.1, 6.555]], "asks": [[64572.2, 0.449], [64572.6, 0.001], [64572.7, 0.0], [64573.6, 0.001], [64573.9, 0.005], [64577.9, 0.005], [64578.1, 0.0], [64579.9, 0.001], [64580.3, 0.009], [64599.6, 0.061], [65217.9, 0.0], [65322.8, 8.408], [65347.1, 26.931]]}
{"kind": "depth", "E": 1787089576961, "U": 11315995080700, "u": 11315995090108, "recv_ms": 1787089576917, "bids": [[1000.0, 35.76], [14272.1, 0.28], [14372.1, 3.682], [14472.1, 0.238], [58114.8, 0.067], [61343.4, 0.0], [61989.2, 0.003], [63572.1, 0.038], [63700.4, 1.97], [63926.4, 1.566], [64435.1, 1.548], [64502.0, 8.238], [64529.5, 0.006], [64540.8, 0.007], [64560.6, 0.018], [64561.9, 0.666], [64563.9, 0.631], [64572.1, 6.553]], "asks": [[64572.5, 0.028], [64572.6, 1.394], [64572.7, 0.0], [64572.9, 0.003], [64573.9, 0.0], [64574.2, 0.007], [64576.0, 0.965], [64577.3, 0.006], [64577.4, 0.005], [64578.3, 0.467], [64578.4, 0.006], [64578.5, 0.101], [64579.9, 0.0], [64580.3, 0.017], [64580.6, 41.645], [64599.3, 2.197], [64644.3, 8.085], [65217.9, 0.0], [65528.7, 4.574], [65572.2, 0.022]]}
{"kind": "depth", "E": 1787089577063, "U": 11315995090171, "u": 11315995098751, "recv_ms": 1787089577020, "bids": [[14272.1, 0.532], [14372.1, 3.542], [14472.1, 0.126], [32286.4, 0.053], [51657.7, 0.0], [58114.8, 0.067], [61343.4, 0.0], [63280.7, 0.023], [63641.2, 2.355], [63926.4, 1.564], [64529.5, 0.002], [64539.8, 0.009], [64544.7, 0.107], [64545.6, 2.946], [64553.9, 0.116], [64555.0, 0.099], [64555.1, 0.56], [64556.0, 0.003], [64559.3, 0.929], [64560.5, 0.002], [64560.6, 0.018], [64560.7, 0.545], [64561.9, 0.124], [64570.7, 0.001]], "asks": [[64572.2, 0.463], [64572.6, 1.014], [64572.7, 0.0], [64572.8, 1.395], [64573.3, 0.0], [64577.9, 1.818], [64578.3, 0.465], [64580.3, 0.001], [64583.8, 0.087], [64590.4, 0.015], [64590.6, 0.544], [64591.3, 0.145], [64591.7, 0.927], [64592.9, 0.644], [64596.4, 0.099], [64597.5, 0.014], [65217.9, 0.0]]}
{"kind": "depth", "E": 1787089577165, "U": 11315995099088, "u": 11315995108585, "recv_ms": 1787089577124, "bids": [[1000.0, 35.76], [14272.1, 0.756], [14372.1, 3.444], [14472.1, 0.0], [51658.0, 0.0], [58114.8, 0.067], [61343.4, 0.0], [61989.2, 0.0], [63572.1, 0.018], [63588.1, 0.787], [63588.3, 0.017], [63653.0, 0.835], [63653.1, 0.058], [63655.3, 0.0], [63655.4, 0.009], [63773.5, 13.486], [63778.0, 14.733], [63926.4, 1.566], [64031.7, 0.002], [64225.4, 0.0], [64226.8, 0.232], [64249.2, 5.096], [64478.8, 0.043], [64478.9, 0.005], [64502.0, 8.237], [64502.1, 0.189], [64507.2, 0.438], [64529.8, 0.703], [64553.9, 0.0], [64554.9, 2.438], [64555.1, 0.002], [64555.3, 0.005], [64556.0, 0.561], [64559.3, 0.002], [64559.7, 0.009], [64559.9, 0.021], [64560.2, 1.023], [64560.7, 0.003], [64561.9, 0.666], [64563.9, 0.632], [64566.7, 0.122], [64567.3, 0.147], [64567.5, 0.085], [64570.5, 0.601], [64572.1, 6.554]], "asks": [[64572.2, 0.464], [64572.6, 0.001], [64572.7, 1.393], [64572.8, 0.002], [64573.4, 0.85], [64576.0, 1.321], [64577.8, 0.069], [64578.2, 0.007], [64578.6, 0.017], [64579.9, 0.001], [64580.6, 41.644], [64582.3, 0.001], [64584.5, 0.534], [64587.7, 0.005], [64590.6, 0.002], [64591.3, 0.687], [64591.7, 0.0], [64592.6, 3.248], [64596.3, 0.565], [64596.4, 0.042], [64596.7, 0.015], [64597.3, 0.387], [64597.6, 0.124], [64598.2, 0.0], [64870.8, 0.243], [64870.9, 0.0], [64895.1, 3.235], [65217.9, 0.0], [65302.5, 1.062], [65476.2, 21.107], [65488.9, 0.002], [65491.2, 0.013], [65556.0, 0.473], [65572.2, 0.002]]}
{"kind": "depth", "E": 1787089577267, "U": 11315995108875, "u": 11315995118693, "recv_ms": 1787089577224, "bids": [[1000.0, 35.76], [14272.1, 1.12], [14372.1, 3.08], [51658.0, 0.0], [58114.8, 0.067], [61343.4, 0.0], [61989.2, 0.003], [63778.0, 13.167], [63789.3, 1.579], [63926.4, 1.564], [64467.5, 1.504], [64467.6, 0.006], [64499.0, 0.148], [64499.1, 0.002], [64501.6, 0.234], [64555.3, 0.007], [64560.5, 0.01], [64561.1, 0.003], [64562.0, 0.009], [64562.4, 0.001], [64563.1, 0.634], [64563.9, 0.632], [64566.5, 1.566], [64567.4, 0.002], [64567.5, 0.0], [64569.6, 0.465], [64570.5, 0.02], [64570.6, 0.001], [64570.7, 0.001], [64570.8, 0.046], [64570.9, 0.0], [64571.6, 0.777], [64572.1, 6.554]], "asks": [[64572.2, 0.459], [64572.6, 1.394], [64572.7, 0.0], [64572.8, 0.002], [64574.2, 0.002], [64574.4, 0.009], [64574.7, 0.366], [64577.8, 0.069], [64578.2, 0.005], [64578.6, 0.017], [64579.9, 0.0], [64580.2, 0.003], [64581.8, 0.021], [64583.1, 0.001], [64587.7, 0.007], [64588.6, 0.015], [64599.3, 2.197], [64636.8, 0.01], [64895.1, 3.236], [65217.9, 0.0], [65485.9, 6.802], [65489.0, 0.858], [65491.3, 0.01], [65556.1, 0.022], [66846.1, 0.0]]}
{"kind": "depth", "E": 1787089577369, "U": 11315995118957, "u": 11315995128562, "recv_ms": 1787089577327, "bids": [[14272.1, 1.47], [14372.1, 2.73], [58114.8, 0.067], [61343.4, 0.0], [61989.2, 0.0], [63280.7, 0.02], [63572.1, 0.038], [63764.9, 4.086], [63797.2, 19.331], [63926.3, 0.031], [63926.4, 1.564], [64055.5, 8.572], [64249.2, 5.873], [64499.7, 0.015], [64501.6, 0.235], [64501.9, 30.931], [64512.6, 0.001], [64538.9, 0.0], [64540.5, 1.261], [64542.9, 2.462], [64560.5, 0.002], [64562.0, 0.001], [64563.1, 0.0], [64564.2, 0.004], [64566.7, 0.772], [64569.1, 0.085], [64569.6, 0.722], [64569.9, 2.32], [64570.0, 0.008], [64571.3, 0.311], [64571.6, 0.508], [64571.9, 0.009], [64572.1, 6.561]], "asks": [[64572.2, 0.461], [64572.6, 0.001], [64572.7, 1.393], [64573.4, 0.095], [64574.0, 0.003], [64577.9, 2.753], [64578.6, 0.019], [64589.3, 1.105], [64591.9, 0.007], [64592.0, 0.034], [64595.3, 0.62], [64596.6, 10.058], [64599.3, 2.043], [64599.5, 0.164], [64600.4, 0.0], [64895.1, 4.005], [65217.9, 0.0], [65377.6, 2.963], [65572.2, 0.022], [66870.2, 0.146]]}
{"kind": "depth", "E": 1787089577471, "U": 11315995128891, "u": 11315995140096, "recv_ms": 1787089577428, "bids": [[1000.0, 35.76], [14272.1, 1.834], [14372.1, 2.366], [58114.8, 0.067], [61343.4, 0.0], [63422.7, 0.081], [63466.5, 3.148], [63648.9, 14.593], [63745.7, 0.005], [63926.4, 1.564], [64249.2, 5.883], [64495.5, 0.31], [64497.6, 0.459], [64563.8, 0.002], [64563.9, 0.631], [64571.3, 0.001], [64571.9, 0.007], [64572.1, 6.561]], "asks": [[64572.6, 0.001], [64572.7, 1.393], [64572.9, 0.003], [64573.4, 0.791], [64577.9, 1.818], [64578.6, 0.017], [64579.0, 0.021], [64580.2, 0.002], [64580.6, 41.644], [64587.8, 0.035], [64595.0, 0.702], [64622.2, 0.028], [64630.9, 0.211], [64632.0, 0.437], [64637.2, 0.0], [64639.3, 0.026], [65217.9, 0.0], [65660.2, 0.607], [65682.8, 1.368]]}
{"kind": "depth", "E": 1787089577573, "U": 11315995140294, "u": 11315995148047, "recv_ms": 1787089577537, "bids": [[1000.0, 35.76], [14272.1, 2.198], [14372.1, 2.002], [51658.0, 0.0], [58114.8, 0.067], [61343.4, 0.001], [61989.2, 0.003], [63572.1, 0.018], [63797.2, 20.897], [63926.4, 1.564], [64502.3, 0.029], [64510.1, 0.052], [64544.7, 0.05], [64546.8, 0.057], [64547.4, 0.621], [64554.2, 0.121], [64554.8, 1.085], [64554.9, 2.322], [64555.1, 0.002], [64556.0, 0.003], [64556.9, 0.559], [64557.7, 0.007], [64558.5, 1.126], [64559.6, 1.863], [64559.7, 0.009], [64560.2, 0.096], [64560.3, 0.467], [64560.5, 0.002], [64561.4, 0.929], [64561.9, 0.124], [64563.0, 0.696], [64563.8, 0.001], [64572.1, 6.564]], "asks": [[64572.6, 0.001], [64572.7, 1.393], [64577.8, 1.004], [64578.2, 0.007], [64579.0, 0.02], [64580.0, 0.122], [64580.2, 0.002], [64580.6, 41.645], [64590.8, 0.619], [64591.3, 0.145], [64592.5, 0.543], [64592.6, 2.321], [64593.8, 0.927], [64596.3, 0.008], [64597.1, 1.03], [64597.3, 0.33], [64597.6, 0.008], [64598.0, 0.022], [64598.2, 0.619], [64598.5, 2.376], [64598.7, 0.13], [65217.9, 0.0], [65377.6, 2.704], [65572.2, 0.002]]}
{"kind": "depth", "E": 1787089577675, "U": 11315995148060, "u": 11315995154344, "recv_ms": 1787089577631, "bids": [[14272.1, 2.548], [14372.1, 1.652], [51658.0, 0.0], [58114.8, 0.067], [58114.9, 0.002], [61343.4, 0.0], [61989.2, 0.0], [63022.4, 0.473], [63678.4, 0.001], [63926.4, 1.564], [64508.1, 4.523], [64508.4, 0.003], [64508.7, 0.134], [64509.0, 1.217], [64509.4, 0.006], [64527.4, 0.0], [64527.7, 0.058], [64528.0, 0.095], [64528.4, 0.0], [64528.7, 0.013], [64542.3, 0.001], [64542.4, 0.433], [64542.5, 0.001], [64542.6, 0.002], [64542.7, 0.0], [64542.8, 0.008], [64542.9, 2.392], [64543.0, 0.021], [64543.1, 2.322], [64543.3, 0.0], [64545.7, 0.057], [64545.9, 2.32], [64546.3, 0.135], [64546.8, 0.0], [64556.0, 0.561], [64556.9, 0.001], [64560.4, 1.383], [64561.4, 0.002], [64561.9, 0.666], [64563.0, 0.154], [64563.8, 0.002], [64564.8, 0.322], [64564.9, 0.007], [64565.0, 0.313], [64565.1, 0.001], [64565.2, 0.001], [64565.3, 0.085], [64565.4, 0.155], [64565.5, 0.0], [64565.6, 0.095], [64565.7, 0.0], [64565.8, 0.002], [64566.1, 0.003], [64566.4, 0.808], [64566.7, 0.74], [64567.0, 0.001], [64567.3, 0.115], [64572.1, 6.564]], "asks": [[64572.6, 0.001], [64572.7, 1.393], [64572.8, 0.002], [64577.8, 0.069], [64578.2, 0.005], [64579.0, 0.02], [64580.2, 0.003], [64580.6, 41.644], [64582.7, 0.004], [64583.0, 0.116], [64583.3, 0.161], [64583.6, 0.003], [64584.0, 2.327], [64584.2, 0.0], [64584.3, 0.004], [64584.4, 0.354], [64584.5, 0.004], [64584.6, 0.0], [64584.7, 0.0], [64584.8, 0.027], [64584.9, 0.0], [64585.0, 0.236], [64585.1, 0.002], [64585.2, 2.261], [64591.3, 0.687], [64592.5, 0.001], [64592.7, 1.047], [64593.8, 0.0], [64602.0, 0.02], [64602.3, 0.034], [64602.6, 0.001], [64602.9, 1.002], [64603.3, 0.039], [64603.7, 0.0], [64604.1, 0.002], [64606.7, 0.018], [64606.9, 0.0], [64607.0, 2.353], [64607.1, 0.116], [64607.2, 0.066], [64607.3, 0.016], [64607.4, 0.003], [64607.5, 0.021], [64607.6, 0.0], [64607.7, 0.016], [64621.3, 0.971], [64621.6, 0.397], [64621.9, 0.015], [64622.3, 0.001], [64622.6, 0.003], [64887.1, 0.357], [65217.9, 0.0], [68000.0, 89.785]]}
{"kind": "depth", "E": 1787089577777, "U": 11315995154451, "u": 11315995160571, "recv_ms": 1787089577734, "bids": [[1000.0, 35.91], [14272.1, 2.898], [14372.1, 1.302], [51658.0, 0.0], [58114.8, 0.067], [58114.9, 0.0], [61989.2, 0.003], [63572.1, 0.038], [63665.5, 0.0], [63668.1, 17.136], [63738.0, 3.138], [63764.9, 5.135], [63926.4, 1.564], [64249.2, 5.873], [64544.9, 0.105], [64545.7, 0.0], [64555.1, 0.56], [64556.0, 0.003], [64559.6, 2.79], [64559.7, 0.551], [64559.9, 0.029], [64560.4, 0.456], [64560.5, 0.002], [64561.9, 0.124], [64563.1, 0.0], [64563.2, 0.796], [64563.3, 0.001], [64565.0, 0.383], [64565.1, 0.071], [64565.3, 0.185], [64565.6, 0.195], [64566.7, 0.19], [64566.8, 0.0], [64571.3, 0.311], [64572.1, 6.56]], "asks": [[64572.2, 0.458], [64572.6, 0.001], [64572.7, 1.393], [64572.8, 0.002], [64573.4, 0.095], [64577.9, 2.753], [64578.4, 0.008], [64583.8, 0.002], [64584.3, 0.284], [64584.6, 0.27], [64584.8, 0.174], [64584.9, 0.147], [64587.8, 0.12], [64596.7, 0.072], [64598.0, 0.015], [64598.5, 2.319], [64598.9, 2.426], [64605.1, 0.944], [64606.8, 0.281], [64607.1, 0.386], [64607.3, 0.163], [64607.4, 0.15], [65217.9, 0.0], [65516.4, 3.797], [65572.2, 0.022]]}
{"kind": "depth", "E": 1787089577879, "U": 11315995160603, "u": 11315995167580, "recv_ms": 1787089577836, "bids": [[1000.0, 35.76], [14272.1, 3.262], [14372.1, 0.938], [58114.8, 0.067], [61343.4, 0.0], [61989.2, 0.0], [63280.7, 0.023], [63545.4, 0.791], [63666.4, 10.979], [63705.7, 9.409], [63854.1, 0.789], [63926.4, 1.564], [64508.7, 0.116], [64513.9, 0.05], [64518.8, 0.043], [64525.3, 0.171], [64526.0, 0.363], [64527.5, 0.448], [64559.7, 0.009], [64559.9, 0.021], [64561.2, 0.686], [64561.9, 0.666], [64563.2, 0.254], [64563.8, 0.174], [64564.5, 0.024], [64565.1, 0.141], [64565.9, 0.072], [64566.1, 0.035], [64566.7, 0.74], [64569.8, 0.235], [64570.3, 0.0], [64571.9, 0.007]], "asks": [[64572.2, 0.461], [64572.7, 0.0], [64572.8, 0.002], [64572.9, 1.396], [64573.4, 0.791], [64574.6, 0.086], [64577.8, 0.512], [64577.9, 1.818], [64578.4, 0.006], [64579.0, 0.021], [64580.2, 0.002], [64580.3, 0.001], [64580.6, 41.644], [64581.8, 0.044], [64583.8, 0.066], [64584.0, 2.488], [64584.8, 0.328], [64587.8, 0.043], [64588.0, 0.008], [64588.8, 0.087], [64589.7, 0.004], [64596.2, 0.027], [64596.7, 0.015], [64597.6, 0.065], [64599.5, 0.254], [64603.1, 0.068], [64606.5, 0.177], [64607.3, 0.317], [64608.3, 0.98], [64622.4, 0.5], [64630.4, 1.237], [64649.7, 0.001], [64894.8, 0.807], [64895.1, 4.159], [65217.9, 0.002], [65268.2, 5.148], [65355.0, 4.947], [65488.7, 5.502]]}
{"kind": "depth", "E": 1787089577981, "U": 11315995167587, "u": 11315995174868, "recv_ms": 1787089577942, "bids": [[14272.1, 3.626], [14372.1, 0.574], [58114.8, 0.067], [61343.4, 0.0], [63572.1, 0.018], [63687.5, 1.412], [63700.4, 2.596], [63926.4, 1.564], [64508.6, 1.234], [64527.8, 5.441], [64528.1, 0.074], [64528.5, 0.161], [64528.8, 0.068], [64559.7, 0.009], [64559.8, 0.015], [64561.9, 0.666], [64563.8, 0.173], [64565.2, 0.071], [64565.4, 0.255], [64565.5, 0.07], [64566.5, 1.598], [64566.7, 0.732], [64566.8, 0.032], [64567.1, 0.49], [64567.4, 0.034], [64572.1, 6.56]], "asks": [[64572.2, 0.471], [64572.9, 0.003], [64577.4, 0.033], [64577.8, 0.069], [64578.3, 0.467], [64579.0, 0.02], [64580.0, 0.108], [64580.2, 0.003], [64580.3, 0.201], [64582.5, 0.068], [64582.8, 0.067], [64583.1, 0.084], [64583.4, 0.316], [64584.4, 0.48], [64584.5, 0.224], [64584.7, 0.14], [64595.5, 3.311], [64601.8, 0.073], [64602.1, 0.086], [64602.4, 0.088], [64602.8, 0.075], [64606.9, 0.126], [64607.0, 2.573], [64607.2, 0.206], [64621.1, 0.456], [64621.4, 0.078], [64621.7, 3.583], [64622.1, 0.074], [64640.2, 9.161], [64642.5, 0.015], [64644.3, 0.0], [64644.7, 0.001], [64649.1, 37.991], [64846.6, 0.015], [65217.9, 0.002], [65334.7, 0.803], [65387.3, 2.534], [65540.8, 2.843], [65572.2, 0.002]]}
{"kind": "depth", "E": 1787089578083, "U": 11315995174897, "u": 11315995182654, "recv_ms": 1787089578042, "bids": [[1000.0, 35.76], [14172.1, 0.112], [14272.1, 3.752], [14372.1, 0.336], [51657.7, 0.0], [58114.8, 0.067], [61343.4, 0.0], [61343.6, 0.007], [61989.2, 0.003], [63564.6, 0.673], [63641.2, 1.57], [63668.1, 17.606], [63705.7, 8.625], [63742.9, 0.839], [63926.4, 1.564], [64249.2, 5.883], [64523.8, 5.024], [64530.9, 0.776], [64539.3, 0.028], [64539.4, 0.005], [64539.5, 0.004], [64539.8, 0.005], [64542.6, 0.072], [64542.8, 0.006], [64542.9, 2.39], [64543.0, 0.019], [64559.6, 1.863], [64559.8, 0.007], [64560.5, 0.002], [64560.6, 0.945], [64563.9, 0.631], [64564.9, 0.077], [64565.1, 0.211], [64565.3, 0.285], [64565.4, 0.355], [64565.6, 0.295], [64565.7, 0.07], [64565.8, 0.102], [64567.3, 0.123], [64572.1, 6.562]], "asks": [[64572.2, 0.47], [64572.9, 0.003], [64580.0, 0.122], [64580.2, 0.002], [64580.6, 41.645], [64581.5, 0.019], [64584.1, 2.233], [64584.2, 0.147], [64584.3, 0.534], [64584.5, 0.474], [64584.6, 0.54], [64584.9, 0.28], [64585.0, 0.376], [64591.3, 0.145], [64592.0, 0.576], [64603.5, 0.293], [64603.9, 0.273], [64606.7, 0.165], [64606.9, 0.376], [64607.0, 2.823], [64607.4, 0.283], [64607.5, 0.161], [64640.2, 3.533], [65217.9, 0.0], [65276.0, 2.917], [65347.1, 27.145]]}
{"kind": "depth", "E": 1787089578185, "U": 11315995182760, "u": 11315995189495, "recv_ms": 1787089578144, "bids": [[14172.1, 0.336], [14272.1, 3.654], [14372.1, 0.21], [58114.8, 0.067], [61343.4, 0.0], [61989.2, 0.0], [63572.1, 0.038], [63700.4, 2.752], [63926.4, 1.564], [64249.2, 5.885], [64479.0, 0.028], [64495.3, 0.01], [64499.7, 30.782], [64501.6, 0.236], [64501.9, 0.016], [64502.0, 4.827], [64502.2, 0.004], [64507.4, 0.005], [64508.2, 0.033], [64521.5, 0.017], [64523.8, 5.02], [64524.5, 2.385], [64529.7, 0.072], [64529.8, 0.702], [64539.8, 0.009], [64542.5, 0.071], [64542.8, 0.106], [64543.1, 2.422], [64544.9, 0.048], [64546.2, 0.057], [64554.2, 0.005], [64555.1, 0.002], [64555.3, 0.123], [64556.4, 0.558], [64557.7, 0.0], [64558.5, 1.133], [64563.9, 0.631], [64566.5, 0.034], [64566.7, 0.09], [64567.3, 0.123], [64569.9, 2.321], [64570.0, 2.214], [64571.9, 0.009], [64572.1, 6.565]], "asks": [[64572.9, 0.003], [64583.8, 0.067], [64592.7, 0.12], [64593.2, 0.928], [64598.1, 0.621], [64598.7, 0.014], [64599.3, 2.043], [64599.4, 0.172], [64599.5, 0.1], [64600.8, 0.31], [64644.7, 37.992], [64646.9, 0.0], [64649.1, 0.0], [64895.1, 4.157], [65217.9, 0.0], [65290.5, 2.456], [65412.2, 0.31], [65508.5, 23.128], [65572.2, 0.022]]}
{"kind": "depth", "E": 1787089578287, "U": 11315995189505, "u": 11315995195456, "recv_ms": 1787089578245, "bids": [[14172.1, 0.588], [14272.1, 3.514], [14372.1, 0.098], [51658.0, 0.0], [58114.8, 0.067], [61989.2, 0.003], [63926.4, 1.564], [64249.2, 5.885], [64432.1, 0.022], [64442.6, 2.319], [64442.9, 0.723], [64494.6, 0.05], [64508.5, 0.055], [64508.8, 0.321], [64509.1, 0.15], [64509.5, 0.033], [64521.5, 0.018], [64542.6, 0.142], [64543.4, 0.077], [64555.3, 0.123], [64562.0, 0.017], [64563.1, 0.542], [64566.5, 0.034], [64567.3, 0.115], [64569.6, 0.465], [64569.9, 2.32], [64570.0, 0.039], [64570.5, 0.02], [64570.6, 0.002], [64570.7, 0.001], [64570.8, 1.671], [64571.6, 0.824], [64571.9, 0.007], [64572.1, 6.562]], "asks": [[64572.2, 0.471], [64572.9, 0.003], [64587.7, 0.007], [64588.9, 0.014], [64599.2, 0.0], [64599.3, 2.197], [64599.4, 0.018], [64615.3, 0.033], [64649.7, 0.004], [64712.7, 0.001], [65217.9, 0.0], [65379.4, 5.349], [65668.2, 1.827], [65677.8, 2.737]]}
{"kind": "depth", "E": 1787089578389, "U": 11315995195506, "u": 11315995201148, "recv_ms": 1787089578345, "bids": [[1000.0, 35.76], [14172.1, 0.84], [14272.1, 3.36], [14372.1, 0.0], [58114.8, 0.067], [61343.4, 0.0], [63280.7, 0.026], [63597.2, 0.275], [63926.3, 0.03], [63926.4, 1.564], [64432.1, 4.225], [64435.1, 1.547], [64542.7, 0.07], [64542.9, 2.49], [64543.0, 0.089], [64562.0, 0.001], [64563.1, 0.0], [64563.2, 0.254], [64566.5, 1.598], [64566.7, 0.74], [64569.6, 0.722], [64570.0, 0.008], [64570.5, 0.001], [64570.8, 0.046], [64571.6, 0.015], [64571.7, 0.0], [64571.8, 0.545], [64572.1, 6.552]], "asks": [[64572.9, 0.003], [64712.7, 5.41], [65217.9, 0.0], [65681.5, 0.379], [67803.9, 0.002]]}
{"kind": "depth", "E": 1787089578491, "U": 11315995201392, "u": 11315995207833, "recv_ms": 1787089578448, "bids": [[14172.1, 1.204], [14272.1, 2.996], [58114.8, 0.067], [61989.2, 0.0], [63572.1, 0.018], [63886.4, 1.367], [63926.4, 1.564], [64542.4, 0.503], [64542.6, 0.212], [64542.9, 2.59], [64543.1, 2.522], [64543.2, 2.15], [64546.0, 0.545], [64546.4, 0.217], [64564.5, 0.021], [64570.5, 0.02]], "asks": [[64572.9, 0.003], [64600.1, 0.008], [65217.9, 0.0], [65572.2, 0.002], [65634.3, 0.102]]}
{"kind": "depth", "E": 1787089578593, "U": 11315995207935, "u": 11315995213982, "recv_ms": 1787089578552, "bids": [[14172.1, 1.568], [14272.1, 2.632], [51658.0, 0.0], [58114.8, 0.067], [61343.4, 0.0], [61989.2, 0.003], [61989.3, 0.001], [63382.9, 0.001], [63466.4, 0.79], [63572.1, 0.038], [63764.9, 5.369], [63926.4, 1.564], [64249.2, 5.875], [64545.3, 0.06], [64546.2, 0.0], [64554.3, 0.117], [64555.3, 0.007], [64555.8, 0.769], [64556.4, 0.0], [64560.0, 1.285], [64560.6, 0.018], [64561.3, 0.543], [64561.9, 0.124], [64570.6, 0.001], [64572.1, 6.523]], "asks": [[64572.9, 0.003], [64573.0, 0.225], [64573.2, 0.0], [64577.4, 0.047], [64577.8, 1.004], [64578.7, 0.002], [64580.6, 41.645], [64590.7, 0.754], [64592.0, 0.576], [64595.9, 0.296], [64596.9, 0.557], [64597.1, 0.473], [64599.2, 0.154], [64599.3, 2.043], [64816.4, 0.298], [64817.9, 1.885], [65217.9, 0.0], [65572.2, 0.022], [65863.6, 0.021]]}
{"kind": "depth", "E": 1787089578695, "U": 11315995214029, "u": 11315995222862, "recv_ms": 1787089578653, "bids": [[1000.0, 35.76], [14172.1, 1.918], [14272.1, 2.282], [51658.0, 0.0], [58114.8, 0.067], [61989.2, 0.0], [63603.5, 1.066], [63660.2, 1.569], [63853.9, 1.564], [63926.4, 1.564], [64243.2, 0.0], [64452.3, 0.011], [64462.3, 0.43], [64572.1, 6.555]], "asks": [[64572.9, 0.938], [64577.8, 0.069], [64599.2, 0.0], [64599.4, 0.018], [64599.5, 0.254], [65217.9, 0.0], [65335.0, 7.086], [65488.7, 4.434], [65548.7, 5.286]]}
{"kind": "depth", "E": 1787089578797, "U": 11315995223105, "u": 11315995229738, "recv_ms": 1787089578754, "bids": [[14172.1, 2.282], [14272.1, 1.918], [58114.8, 0.067], [61343.4, 0.0], [61989.2, 0.003], [63926.4, 1.564], [64415.1, 6.982], [64416.0, 1.263], [64432.1, 4.225], [64435.1, 0.986], [64572.1, 6.566]], "asks": [[64572.9, 0.938], [64625.1, 0.387], [64633.4, 0.004], [64712.7, 5.41], [64729.6, 11.806], [64729.7, 0.0], [65217.9, 0.0], [65657.0, 1.827], [65823.6, 0.049]]}
{"kind": "depth", "E": 1787089578899, "U": 11315995229848, "u": 11315995237406, "recv_ms": 1787089578856, "bids": [[14172.1, 2.632], [14272.1, 1.568], [58114.8, 0.067], [63269.5, 0.0], [63341.2, 0.0], [63413.0, 0.0], [63484.7, 0.19], [63556.4, 0.0], [63572.1, 0.018], [63628.2, 0.0], [63699.9, 0.024], [63771.6, 0.0], [63843.4, 0.0], [63915.1, 0.003], [63926.4, 1.566], [64249.2, 6.04], [64249.6, 0.987], [64416.0, 2.111], [64532.8, 0.44], [64539.8, 0.005]], "asks": [[64572.2, 0.471], [64572.9, 0.003], [64625.1, 0.391], [64633.4, 0.0], [65206.3, 0.0], [65217.9, 0.0], [65258.2, 0.0], [65278.0, 6.157], [65322.5, 0.764], [65349.8, 0.0], [65421.5, 6.597], [65493.2, 0.001], [65508.5, 23.28], [65565.0, 2.151], [65572.2, 0.002], [65636.7, 0.001], [65708.4, 0.0], [65780.2, 0.006], [65851.9, 0.0]]}
{"kind": "depth", "E": 1787089579001, "U": 11315995237458, "u": 11315995243330, "recv_ms": 1787089578957, "bids": [[1000.0, 35.76], [14172.1, 2.982], [14272.1, 1.218], [58114.8, 0.067], [61989.2, 0.0], [63926.4, 1.564], [64502.0, 8.216], [64532.8, 0.436], [64539.8, 0.009]], "asks": [[64572.9, 0.003], [64605.1, 1.31], [64644.3, 8.082], [65217.9, 0.0], [65508.5, 24.347]]}
{"kind": "depth", "E": 1787089579103, "U": 11315995243540, "u": 11315995251096, "recv_ms": 1787089579061, "bids": [[14172.1, 3.346], [14272.1, 0.854], [51657.7, 0.0], [58114.8, 0.067], [61343.4, 0.0], [61343.6, 0.005], [61989.2, 0.003], [63572.1, 0.038], [63834.8, 7.824], [63926.4, 1.564], [64494.6, 0.05], [64513.9, 0.047], [64560.5, 0.002], [64561.2, 0.161], [64563.8, 0.001], [64572.1, 6.563]], "asks": [[64572.9, 0.003], [64591.3, 0.095], [64593.3, 0.095], [64597.0, 0.111], [64597.8, 6.649], [64599.8, 0.036], [64600.4, 0.049], [64605.7, 0.123], [64608.4, 0.074], [64630.4, 1.237], [64630.9, 0.001], [64637.5, 2.396], [64649.7, 0.001], [64898.0, 0.1], [65217.9, 0.0], [65283.0, 0.649], [65379.4, 5.692], [65572.2, 0.022]]}
{"kind": "depth", "E": 1787089579205, "U": 11315995251336, "u": 11315995257750, "recv_ms": 1787089579162, "bids": [[1000.0, 35.76], [14072.1, 0.014], [14172.1, 3.682], [14272.1, 0.504], [58114.8, 0.067], [61989.2, 0.0], [63388.6, 1.58], [63763.3, 1.849], [63926.4, 1.564], [64249.2, 6.028], [64501.7, 0.064], [64507.4, 0.004], [64521.6, 0.01], [64524.6, 0.251], [64529.8, 0.704], [64554.3, 0.001], [64555.3, 0.123], [64566.5, 0.05], [64566.7, 0.663], [64567.3, 0.192], [64570.0, 1.556]], "asks": [[64572.9, 0.003], [65217.9, 0.0], [67789.8, 0.005]]}
{"kind": "depth", "E": 1787089579307, "U": 11315995257796, "u": 11315995263421, "recv_ms": 1787089579266, "bids": [[1000.0, 35.76], [14072.1, 0.168], [14172.1, 3.724], [14272.1, 0.308], [51658.0, 0.0], [58114.8, 0.067], [61343.4, 0.0], [61343.5, 0.012], [61343.6, 0.007], [61989.2, 0.003], [63280.7, 0.023], [63409.8, 0.386], [63572.1, 0.018], [63926.4, 1.564], [64421.1, 0.123], [64548.4, 0.315], [64548.9, 0.155], [64555.3, 0.123], [64556.4, 0.002], [64556.7, 0.018], [64560.1, 0.01], [64561.9, 0.132], [64563.0, 0.788], [64564.5, 0.021], [64566.5, 0.034], [64566.7, 0.09], [64567.3, 0.115], [64569.6, 0.465], [64569.8, 0.003], [64570.0, 0.008], [64570.5, 0.017], [64570.6, 0.233], [64570.7, 0.001], [64570.8, 0.046], [64570.9, 1.548], [64571.8, 0.806], [64572.1, 6.562]], "asks": [[64572.9, 0.003], [64587.7, 0.007], [64895.1, 4.159], [65217.9, 0.0], [65379.4, 5.951], [65387.3, 2.229], [65572.2, 0.002], [65863.6, 0.015]]}
{"kind": "depth", "E": 1787089579409, "U": 11315995263479, "u": 11315995271470, "recv_ms": 1787089579367, "bids": [[14072.1, 0.392], [14172.1, 3.626], [14272.1, 0.182], [51658.0, 0.002], [58114.8, 0.067], [61343.4, 0.0], [63724.8, 4.233], [63795.6, 5.791], [63926.4, 1.564], [64528.5, 0.18], [64548.6, 2.473], [64548.9, 0.001], [64554.3, 0.117], [64555.3, 0.007], [64560.1, 0.002], [64561.3, 0.001], [64561.4, 0.544], [64561.9, 0.124], [64563.0, 0.154], [64563.9, 0.631], [64566.5, 1.598], [64566.7, 0.663], [64567.3, 0.192], [64569.6, 0.722], [64570.5, 0.001], [64570.9, 0.0], [64571.8, 0.545], [64572.1, 6.562]], "asks": [[64572.2, 0.471], [64572.9, 0.003], [64590.7, 0.754], [64592.0, 0.576], [64595.9, 0.296], [64596.7, 0.572], [64596.9, 0.0], [64597.2, 0.091], [64598.1, 0.621], [64598.9, 2.419], [64599.3, 2.05], [64630.1, 0.21], [64637.5, 2.186], [64895.1, 4.775], [65217.9, 0.0], [65395.0, 2.804]]}
{"kind": "depth", "E": 1787089579511, "U": 11315995271644, "u": 11315995277359, "recv_ms": 1787089579468, "bids": [[1000.0, 35.76], [14072.1, 0.644], [14172.1, 3.486], [14272.1, 0.07], [51658.0, 0.0], [58114.8, 0.067], [61343.4, 0.0], [61989.2, 0.0], [63564.6, 1.346], [63572.1, 0.038], [63926.4, 1.564], [64249.2, 6.038], [64531.0, 0.021], [64537.7, 0.088], [64539.3, 0.003], [64539.4, 0.03], [64560.1, 0.002], [64561.4, 0.002], [64561.5, 0.543], [64572.1, 6.564]], "asks": [[64572.2, 0.502], [64572.9, 0.938], [64590.7, 0.754], [64592.0, 0.576], [64596.6, 0.058], [64642.5, 0.015], [64644.3, 0.0], [64644.7, 37.975], [64651.3, 0.007], [65217.9, 0.0], [65411.6, 0.915], [65572.2, 0.022]]}
{"kind": "depth", "E": 1787089579613, "U": 11315995277417, "u": 11315995283533, "recv_ms": 1787089579570, "bids": [[1000.0, 35.76], [14072.1, 0.938], [14172.1, 3.262], [14272.1, 0.0], [58114.8, 0.067], [61343.4, 0.0], [61343.6, 0.005], [61989.2, 0.003], [63572.1, 0.018], [63757.1, 4.549], [63787.0, 0.784], [63797.2, 22.775], [63926.4, 1.564], [63938.2, 0.01], [63956.7, 1.619], [64457.3, 4.246], [64457.4, 0.0], [64468.6, 0.034], [64501.5, 0.046], [64501.6, 0.19], [64563.9, 0.631], [64572.1, 6.554]], "asks": [[64572.2, 0.5], [64572.9, 0.938], [64580.3, 0.001], [64582.0, 0.073], [64585.0, 0.365], [64585.4, 0.323], [64595.5, 0.004], [64597.2, 10.091], [64642.5, 37.989], [64643.7, 0.047], [64643.8, 0.0], [64644.7, 0.001], [64682.0, 0.774], [64712.9, 5.087], [64713.1, 0.0], [64846.6, 0.215], [65217.9, 0.0], [65418.7, 0.267], [65421.3, 0.0], [65572.2, 0.002], [65756.5, 0.004], [65779.7, 0.758], [71029.5, 0.0]]}
{"kind": "depth", "E": 1787089579715, "U": 11315995283603, "u": 11315995288738, "recv_ms": 1787089579674, "bids": [[14072.1, 1.288], [14172.1, 2.912], [58114.8, 0.067], [61343.5, 0.014], [61989.2, 0.0], [63280.7, 0.02], [63926.4, 1.564], [64045.2, 0.001], [64468.2, 2.325], [64565.3, 0.201], [64569.5, 0.246]], "asks": [[64572.9, 0.938], [64574.4, 0.004], [64574.5, 0.007], [64681.7, 2.325], [64712.6, 1.798], [64712.9, 3.872], [65040.8, 0.0], [65203.6, 0.015], [65217.9, 0.0], [65354.8, 1.528]]}
{"kind": "depth", "E": 1787089579817, "U": 11315995288864, "u": 11315995294189, "recv_ms": 1787089579774, "bids": [[1000.0, 35.76], [14072.1, 1.638], [14172.1, 2.562], [51658.0, 0.0], [58114.8, 0.067], [61343.4, 0.0], [61989.3, 0.0], [63763.3, 1.615], [63764.9, 5.526], [63926.4, 1.564], [64249.2, 6.028], [64530.9, 0.801], [64539.4, 0.005], [64560.1, 0.002], [64561.5, 0.001], [64561.9, 0.666]], "asks": [[64572.2, 0.501], [64572.9, 0.938], [64590.6, 0.002], [64592.0, 0.576], [64592.1, 2.313], [64593.2, 0.001], [64599.4, 0.172], [64599.5, 0.1], [64681.0, 0.001], [64726.1, 0.0], [64751.9, 0.0], [64777.7, 0.1], [64803.6, 0.0], [64829.4, 0.003], [65211.5, 0.688], [65217.9, 0.0], [65492.8, 0.228], [65712.5, 8.526]]}
{"kind": "depth", "E": 1787089579919, "U": 11315995294204, "u": 11315995299602, "recv_ms": 1787089579876, "bids": [[1000.0, 35.76], [14072.1, 2.002], [14172.1, 2.198], [58114.8, 0.067], [61989.2, 0.003], [63508.7, 0.007], [63528.7, 0.001], [63572.1, 0.038], [63660.2, 2.353], [63724.8, 5.017], [63926.4, 1.564], [64055.5, 8.884], [64421.1, 0.002], [64557.7, 0.007], [64558.5, 1.126], [64560.0, 0.358], [64560.6, 0.945], [64561.4, 0.002], [64561.9, 0.666], [64562.9, 1.4]], "asks": [[64572.9, 0.003], [64591.3, 0.637], [64592.0, 0.034], [64592.1, 1.386], [64592.5, 0.001], [64593.1, 0.002], [64593.8, 0.927], [64597.6, 0.008], [64598.3, 0.161], [64598.5, 2.376], [64599.3, 2.043], [64599.4, 0.018], [65217.9, 0.0], [65443.9, 1.831], [65463.8, 0.763], [65572.2, 0.022], [65668.2, 1.448]]}
{"kind": "depth", "E": 1787089580021, "U": 11315995299692, "u": 11315995306549, "recv_ms": 1787089579980, "bids": [[14072.1, 2.366], [14172.1, 1.834], [58114.8, 0.067], [61343.4, 0.0], [61989.2, 0.0], [63338.5, 0.646], [63926.4, 1.564], [64435.1, 1.547], [64532.8, 0.44], [64539.8, 0.005], [64559.6, 1.863], [64559.7, 0.009], [64560.6, 0.018], [64560.7, 0.93], [64561.2, 0.686], [64561.9, 0.666], [64563.8, 0.102], [64564.6, 0.317], [64572.1, 6.555]], "asks": [[64572.2, 0.502], [64572.9, 0.003], [64589.1, 0.161], [64591.3, 0.095], [64592.0, 0.576], [64593.0, 0.93], [64593.8, 0.0], [64595.6, 2.334], [64596.6, 0.058], [64596.7, 3.509], [64597.6, 0.065], [64598.5, 2.319], [64640.2, 9.152], [64642.5, 0.015], [64649.1, 37.974], [65217.9, 0.0], [65319.8, 1.07], [65516.4, 3.454], [65657.8, 3.807], [65734.5, 0.972], [71029.5, 0.0]]}
{"kind": "depth", "E": 1787089580123, "U": 11315995306649, "u": 11315995315599, "recv_ms": 1787089580082, "bids": [[1000.0, 35.76], [14072.1, 2.702], [14172.1, 1.498], [51657.7, 0.0], [51658.0, 0.002], [58114.8, 0.067], [61343.4, 0.0], [61343.5, 0.012], [61343.6, 0.007], [61989.2, 0.003], [63273.0, 0.059], [63344.8, 0.848], [63416.5, 0.059], [63516.3, 4.244], [63538.9, 9.434], [63572.1, 0.018], [63587.8, 0.005], [63589.3, 0.007], [63926.4, 1.564], [64055.5, 8.884], [64249.2, 6.028], [64495.3, 30.541], [64499.7, 0.015], [64510.1, 0.024], [64512.6, 0.029], [64519.4, 0.011], [64524.5, 2.383], [64525.0, 7.184], [64525.8, 0.006], [64526.1, 0.134], [64527.1, 0.104], [64529.8, 0.705], [64530.7, 0.0], [64530.8, 2.409], [64530.9, 0.776], [64534.5, 0.001], [64535.6, 6.931], [64537.5, 1.811], [64539.0, 0.003], [64539.2, 0.437], [64542.9, 0.59], [64547.4, 0.002], [64548.9, 0.311], [64550.0, 0.015], [64554.8, 0.466], [64556.1, 0.005], [64556.4, 0.0], [64559.2, 0.014], [64559.8, 0.0], [64560.0, 1.285], [64560.5, 0.002], [64560.7, 0.003], [64561.1, 0.003], [64561.3, 0.543], [64561.9, 0.124], [64562.4, 0.155], [64563.0, 0.0], [64563.9, 0.632], [64564.3, 0.007], [64564.6, 0.314], [64564.9, 0.07], [64565.6, 0.449], [64566.3, 2.322], [64566.7, 0.121], [64567.1, 0.551], [64567.3, 0.734], [64568.7, 0.155], [64569.5, 0.092], [64570.0, 0.006], [64572.1, 6.493]], "asks": [[64572.2, 1.683], [64572.3, 0.003], [64572.9, 0.002], [64574.6, 1.021], [64575.8, 0.008], [64576.3, 0.013], [64577.9, 2.336], [64578.3, 0.465], [64579.5, 0.013], [64580.1, 0.312], [64580.3, 0.094], [64580.9, 0.055], [64581.8, 0.025], [64583.8, 0.066], [64587.5, 0.007], [64587.8, 0.035], [64588.8, 0.01], [64589.1, 0.001], [64590.4, 0.007], [64590.7, 0.754], [64590.8, 0.542], [64591.3, 0.095], [64592.0, 5.119], [64592.3, 0.178], [64592.4, 0.93], [64593.0, 0.003], [64593.5, 0.032], [64595.0, 0.704], [64595.8, 0.125], [64596.4, 0.04], [64596.7, 0.572], [64597.2, 0.093], [64597.6, 0.008], [64598.2, 0.057], [64610.9, 0.362], [64611.5, 0.001], [64629.2, 0.029], [64629.5, 0.073], [64640.2, 3.533], [64644.7, 37.981], [64649.1, 0.0], [64657.8, 4.254], [65217.9, 0.0], [65554.9, 0.002], [65556.4, 0.003], [65572.2, 0.002], [67789.8, 0.0]]}
{"kind": "depth", "E": 1787089580225, "U": 11315995315755, "u": 11315995322052, "recv_ms": 1787089580183, "bids": [[1000.0, 35.76], [14072.1, 3.066], [14172.1, 1.134], [51658.0, 0.0], [58114.8, 0.067], [61343.4, 0.0], [61989.2, 0.0], [63488.2, 0.795], [63560.0, 2.652], [63587.9, 0.796], [63589.4, 0.293], [63631.7, 0.059], [63703.4, 0.063], [63775.2, 10.498], [63787.0, 0.002], [63846.9, 3.652], [63918.7, 0.069], [63926.4, 1.564], [64495.3, 0.01], [64495.4, 1.835], [64499.7, 30.546], [64502.0, 4.827], [64532.8, 0.436], [64539.3, 0.005], [64539.4, 0.007], [64539.5, 0.006], [64539.8, 0.009], [64542.7, 0.072], [64542.8, 0.108], [64542.9, 0.592], [64549.5, 1.106], [64566.3, 2.32], [64566.5, 0.05], [64566.7, 0.113], [64567.1, 0.553], [64567.4, 1.582], [64567.5, 0.008], [64569.5, 0.008], [64572.1, 6.496]], "asks": [[64572.2, 1.684], [64574.1, 0.084], [64574.5, 0.942], [64574.6, 0.396], [64577.9, 2.074], [64578.4, 0.006], [64579.5, 0.012], [64580.1, 0.313], [64580.3, 0.001], [64580.6, 41.644], [64588.5, 0.092], [64589.9, 0.009], [64590.8, 0.0], [64591.3, 0.637], [64599.5, 0.254], [64642.5, 37.995], [64644.7, 0.001], [65209.9, 1.59], [65217.9, 0.0], [65281.7, 0.059], [65327.7, 1.078], [65353.4, 1.332], [65425.2, 0.059], [65496.9, 0.066], [65555.0, 76.262], [65556.5, 0.011], [65568.6, 1.556], [65640.4, 0.095], [65669.9, 7.903], [65712.1, 0.059], [65783.8, 1.067], [65855.6, 0.061]]}
{"kind": "depth", "E": 1787089580327, "U": 11315995322309, "u": 11315995328782, "recv_ms": 1787089580284, "bids": [[14072.1, 3.43], [14172.1, 0.77], [51658.0, 0.0], [58114.8, 0.067], [63401.8, 1.592], [63466.7, 1.415], [63572.1, 0.038], [63894.1, 4.748], [63926.4, 1.564], [64249.2, 6.029], [64555.3, 0.007], [64567.3, 0.715], [64572.1, 6.495]], "asks": [[64572.2, 1.682], [64574.5, 0.942], [64575.8, 0.0], [64577.8, 0.077], [64577.9, 2.074], [64578.4, 0.006], [64580.1, 0.313], [64587.7, 0.007], [64595.0, 0.702], [64595.3, 0.622], [64599.5, 0.1], [64599.8, 0.19], [64895.1, 4.773], [65217.9, 0.0], [65354.9, 1.53], [65540.9, 0.343], [65572.2, 0.022], [65850.7, 0.616], [65863.6, 0.018]]}
{"kind": "depth", "E": 1787089580429, "U": 11315995328981, "u": 11315995336082, "recv_ms": 1787089580388, "bids": [[1000.0, 35.76], [14072.1, 3.724], [14172.1, 0.448], [14472.1, 0.028], [58114.8, 0.067], [61343.4, 0.0], [61989.2, 0.003], [63561.0, 2.191], [63625.6, 2.335], [63648.9, 12.239], [63653.5, 0.0], [63797.2, 23.557], [63926.4, 1.564], [64249.2, 6.03], [64494.6, 0.047], [64510.1, 0.052], [64513.9, 0.05], [64535.6, 0.016], [64537.5, 0.998], [64539.7, 2.0], [64544.6, 0.147], [64545.3, 0.003], [64546.3, 0.058], [64549.5, 0.991], [64551.8, 0.0], [64555.0, 0.099], [64555.2, 0.013], [64555.8, 0.211], [64556.0, 0.561], [64559.3, 0.002], [64559.7, 0.009], [64560.0, 0.358], [64560.1, 0.002], [64560.4, 1.383], [64561.3, 0.543], [64564.5, 0.024], [64566.2, 0.005], [64566.7, 0.105], [64567.5, 0.016], [64572.1, 6.397]], "asks": [[64572.2, 1.422], [64572.3, 0.001], [64574.1, 0.0], [64574.5, 0.007], [64574.6, 0.086], [64575.8, 0.935], [64577.9, 1.81], [64578.4, 0.006], [64580.1, 0.312], [64580.5, 9.542], [64588.5, 0.015], [64588.8, 0.087], [64589.9, 0.001], [64590.4, 0.015], [64592.0, 0.034], [64594.7, 5.086], [64595.2, 0.174], [64596.1, 0.56], [64596.4, 0.04], [64596.6, 0.058], [64596.7, 0.015], [64597.3, 0.387], [64597.5, 0.13], [64598.1, 0.505], [64598.2, 0.0], [64602.3, 0.034], [64611.0, 0.082], [64630.4, 1.237], [65217.9, 0.0], [65387.3, 1.923], [65863.6, 0.021], [71029.5, 0.001]]}
{"kind": "depth", "E": 1787089580531, "U": 11315995336102, "u": 11315995342526, "recv_ms": 1787089580488, "bids": [[1000.0, 35.76], [14072.1, 3.696], [14172.1, 0.28], [14472.1, 0.224], [58114.8, 0.067], [61989.2, 0.0], [63572.1, 0.018], [63615.2, 3.692], [63763.3, 1.381], [63926.4, 1.564], [64499.7, 0.015], [64501.9, 30.547], [64530.8, 2.384], [64539.4, 0.032], [64550.1, 0.002]], "asks": [[64575.8, 0.935], [64579.9, 0.0], [64580.5, 9.542], [65217.9, 0.0], [65377.6, 2.361], [65411.7, 1.377], [65513.2, 0.335], [65572.2, 0.002], [71029.5, 0.0]]}
{"kind": "depth", "E": 1787089580633, "U": 11315995342690, "u": 11315995350300, "recv_ms": 1787089580591, "bids": [[14072.1, 3.598], [14172.1, 0.154], [14472.1, 0.448], [58114.8, 0.067], [61343.4, 0.0], [61989.2, 0.003], [63622.9, 3.765], [63926.4, 1.564], [64432.1, 4.051], [64467.6, 0.003], [64467.9, 0.003], [64485.9, 0.003], [64532.8, 0.44], [64539.8, 0.005], [64572.1, 6.502]], "asks": [[64572.2, 1.416], [64575.8, 0.935], [64579.9, 0.001], [64580.5, 9.56], [64581.8, 0.002], [64594.7, 0.001], [64597.3, 10.387], [64712.7, 5.41], [64758.1, 0.002], [64758.4, 0.007], [65217.9, 0.0], [65488.7, 3.367]]}
{"kind": "depth", "E": 1787089580735, "U": 11315995350335, "u": 11315995356624, "recv_ms": 1787089580692, "bids": [[1000.0, 35.76], [14072.1, 3.458], [14172.1, 0.042], [14472.1, 0.7], [58114.8, 0.067], [61343.4, 0.0], [61989.2, 0.0], [63571.2, 9.907], [63572.1, 0.038], [63616.6, 3.307], [63635.8, 15.817], [63668.1, 19.959], [63926.4, 1.564], [63950.9, 5.139], [64249.2, 6.04], [64493.4, 1.709], [64532.8, 0.436], [64539.6, 0.006], [64555.1, 0.56], [64556.0, 0.003], [64559.3, 0.929], [64559.7, 0.009], [64560.4, 0.456], [64560.5, 0.002], [64561.3, 0.543], [64572.1, 6.506]], "asks": [[64575.8, 0.935], [64577.8, 0.077], [64579.9, 0.0], [64580.5, 9.561], [64598.3, 0.154], [64598.8, 0.041], [64617.2, 0.015], [64619.5, 0.04], [65217.9, 0.0], [65572.2, 0.022]]}
{"kind": "depth", "E": 1787089580837, "U": 11315995356817, "u": 11315995363147, "recv_ms": 1787089580793, "bids": [[1000.0, 35.76], [14072.1, 3.192], [14172.1, 0.0], [14472.1, 1.008], [34000.0, 1.146], [58114.8, 0.067], [63603.5, 1.058], [63635.8, 16.915], [63641.4, 0.0], [63764.9, 5.877], [63853.8, 0.786], [63926.4, 1.564]], "asks": [[64574.6, 0.086], [64575.8, 0.0], [64579.9, 0.0], [64580.5, 9.561], [65217.9, 0.002], [65508.5, 25.414]]}
{"kind": "depth", "E": 1787089580939, "U": 11315995363220, "u": 11315995368596, "recv_ms": 1787089580897, "bids": [[14072.1, 2.842], [14472.1, 1.358], [58114.8, 0.067], [61343.4, 0.0], [61989.2, 0.003], [63020.7, 0.078], [63572.1, 0.018], [63763.3, 1.03], [63926.4, 1.564], [63958.7, 2.856], [64432.1, 0.022], [64435.1, 0.986]], "asks": [[64572.2, 1.461], [64712.6, 0.0], [64712.7, 0.001], [65197.1, 0.076], [65217.9, 0.0], [65387.3, 1.617], [65572.2, 0.002]]}
{"kind": "depth", "E": 1787089581041, "U": 11315995369078, "u": 11315995375048, "recv_ms": 1787089580998, "bids": [[1000.0, 35.76], [14072.1, 2.478], [14472.1, 1.722], [58114.8, 0.067], [61343.4, 0.0], [61989.2, 0.0], [63280.7, 0.023], [63926.4, 1.564], [64249.2, 6.04], [64432.1, 4.114], [64435.1, 1.53], [64559.3, 0.002], [64560.2, 1.023], [64560.5, 0.007]], "asks": [[64572.2, 1.461], [64596.7, 2.859], [64640.2, 9.153], [64642.5, 0.015], [64651.3, 37.987], [64711.9, 1.25], [64712.7, 5.41], [65217.9, 0.0]]}
{"kind": "depth", "E": 1787089581143, "U": 11315995375353, "u": 11315995382906, "recv_ms": 1787089581100, "bids": [[1000.0, 35.76], [14072.1, 2.114], [14472.1, 2.086], [51657.7, 0.0], [51658.0, 0.0], [58114.8, 0.067], [61989.2, 0.003], [63572.1, 0.038], [63588.3, 0.017], [63603.6, 0.021], [63797.2, 23.776], [63926.4, 1.564], [64495.3, 30.411], [64501.9, 0.016], [64547.9, 0.97], [64555.2, 0.632], [64560.5, 0.002]], "asks": [[64572.2, 1.462], [64577.8, 0.077], [64577.9, 1.81], [64579.9, 0.001], [64580.4, 0.605], [64580.5, 9.561], [64581.5, 0.0], [64591.2, 0.853], [64598.6, 0.62], [64617.5, 0.017], [64624.2, 0.04], [64640.2, 3.533], [64642.5, 0.015], [64644.7, 0.001], [64649.1, 37.864], [64651.3, 0.007], [65205.0, 1.064], [65217.9, 0.0], [65387.3, 1.312], [65411.7, 1.682], [65461.8, 0.0], [65469.8, 5.731], [65556.1, 0.013], [65572.2, 0.022]]}
{"kind": "depth", "E": 1787089581245, "U": 11315995383097, "u": 11315995389373, "recv_ms": 1787089581201, "bids": [[14072.1, 1.75], [14472.1, 2.45], [58114.8, 0.067], [61343.4, 0.0], [62609.4, 1.452], [63926.4, 1.564], [64238.9, 0.0], [64432.1, 3.641], [64495.3, 0.01], [64499.7, 0.015], [64501.9, 30.417], [64507.5, 0.419], [64508.0, 4.348], [64508.1, 0.04], [64572.1, 6.503]], "asks": [[64572.2, 1.464], [64579.9, 0.0], [64580.5, 9.561], [64636.6, 2.34], [64636.8, 0.009], [64637.5, 0.0], [64642.5, 37.879], [64649.1, 0.0], [64712.7, 5.41], [65217.9, 0.002], [65330.1, 2.445], [65556.1, 0.022], [65863.6, 0.024]]}
{"kind": "depth", "E": 1787089581347, "U": 11315995389408, "u": 11315995395896, "recv_ms": 1787089581305, "bids": [[1000.0, 35.76], [14072.1, 1.414], [14472.1, 2.786], [58114.8, 0.067], [61343.5, 0.014], [61989.2, 0.0], [63572.1, 0.018], [63753.8, 0.006], [63926.4, 1.564], [64249.2, 6.039], [64555.3, 0.007], [64559.4, 0.022], [64559.7, 0.009], [64560.2, 0.096], [64560.3, 1.394], [64561.3, 0.001], [64561.9, 0.666], [64569.5, 0.092]], "asks": [[64577.8, 1.012], [64587.7, 0.007], [64625.1, 0.387], [64633.4, 0.004], [64895.1, 4.774], [65217.9, 0.0], [65572.2, 0.002], [66163.7, 0.004]]}
{"kind": "depth", "E": 1787089581449, "U": 11315995396349, "u": 11315995403656, "recv_ms": 1787089581409, "bids": [[1000.0, 35.76], [14072.1, 1.05], [14472.1, 3.15], [58114.8, 0.067], [61343.4, 0.0], [61989.2, 0.003], [63572.1, 0.038], [63926.4, 1.566], [64249.2, 6.66], [64432.1, 0.022], [64495.3, 30.411], [64501.9, 0.016], [64504.3, 2.12], [64510.1, 0.024], [64535.8, 7.036], [64539.3, 0.003], [64539.7, 0.0], [64547.9, 0.351], [64549.5, 0.972], [64550.1, 0.0], [64555.2, 0.013], [64561.3, 0.543], [64561.9, 0.124], [64566.5, 0.034], [64566.7, 0.097], [64567.5, 0.008], [64570.0, 0.038], [64572.1, 6.507]], "asks": [[64572.2, 1.714], [64572.3, 0.003], [64575.8, 0.943], [64577.8, 0.069], [64579.4, 0.038], [64579.9, 0.0], [64580.2, 0.003], [64580.5, 9.56], [64591.2, 0.234], [64591.9, 5.092], [64596.7, 0.015], [64597.3, 0.387], [64604.4, 0.018], [64633.4, 0.0], [64642.5, 0.015], [64651.3, 37.871], [64712.7, 0.001], [64895.1, 4.775], [65217.9, 0.0], [65340.6, 6.267], [65411.7, 1.987], [65572.2, 0.022]]}
{"kind": "depth", "E": 1787089581551, "U": 11315995403713, "u": 11315995410516, "recv_ms": 1787089581509, "bids": [[14072.1, 0.686], [14472.1, 3.514], [58114.8, 0.067], [61343.4, 0.001], [61989.2, 0.0], [63280.7, 0.02], [63778.0, 11.602], [63926.4, 1.564], [64415.1, 0.0], [64416.0, 1.263], [64435.1, 0.986], [64494.6, 0.05], [64495.3, 0.01], [64499.7, 30.416], [64539.7, 2.0], [64561.9, 0.14], [64563.0, 0.008], [64563.9, 0.631], [64566.7, 0.09], [64567.3, 0.096], [64567.4, 0.034], [64567.5, 0.0], [64569.6, 0.465], [64570.0, 0.021], [64570.5, 1.626], [64570.7, 0.543], [64570.8, 0.054], [64571.8, 0.803], [64572.1, 6.499]], "asks": [[64572.2, 1.711], [64575.8, 0.0], [64577.8, 1.012], [64579.4, 0.038], [64580.2, 0.003], [64591.9, 0.007], [64594.2, 0.673], [64594.3, 0.003], [64626.0, 0.261], [64642.5, 37.879], [64649.7, 0.004], [64651.3, 0.007], [64729.6, 1.378], [64799.8, 2.66], [65217.9, 0.0], [65489.1, 0.913]]}
{"kind": "depth", "E": 1787089581653, "U": 11315995410537, "u": 11315995418610, "recv_ms": 1787089581611, "bids": [[1000.0, 35.76], [14072.1, 0.392], [14372.1, 0.07], [14472.1, 3.738], [51658.0, 0.0], [58114.8, 0.067], [61343.4, 0.0], [61343.5, 0.012], [61343.6, 0.009], [61989.2, 0.003], [63280.7, 0.017], [63364.6, 4.175], [63458.9, 0.0], [63764.9, 6.111], [63926.4, 1.564], [64249.2, 6.65], [64376.4, 5.737], [64415.1, 5.877], [64416.0, 1.946], [64432.1, 3.662], [64494.6, 0.047], [64499.7, 0.015], [64501.9, 30.417], [64513.9, 0.05], [64535.8, 0.121], [64546.3, 0.001], [64561.9, 0.124], [64562.8, 0.003], [64563.0, 1.315], [64563.1, 0.0], [64563.9, 0.632], [64566.4, 0.81], [64566.5, 0.05], [64566.7, 0.19], [64567.1, 0.551], [64567.3, 2.194], [64569.6, 0.741], [64570.0, 0.006], [64570.5, 0.001], [64570.7, 0.002], [64570.8, 0.046], [64570.9, 0.0], [64571.8, 0.545], [64572.1, 6.498]], "asks": [[64572.2, 1.714], [64575.8, 0.0], [64577.8, 0.077], [64579.4, 0.038], [64580.1, 0.331], [64580.2, 0.003], [64580.3, 0.02], [64595.0, 10.702], [64630.4, 1.237], [64649.7, 0.001], [64712.7, 5.41], [64729.6, 11.806], [64768.3, 4.342], [64768.4, 13.899], [64768.5, 2.391], [64885.6, 0.469], [64886.3, 1.372], [64886.4, 0.322], [64887.2, 0.469], [65217.9, 0.0], [65483.9, 2.769]]}
{"kind": "depth", "E": 1787089581755, "U": 11315995418620, "u": 11315995427461, "recv_ms": 1787089581712, "bids": [[1000.0, 35.76], [14072.1, 0.252], [14372.1, 0.28], [14472.1, 3.668], [58114.8, 0.067], [61343.4, 0.0], [63097.4, 0.0], [63572.1, 0.018], [63797.2, 25.34], [63926.4, 1.564], [64566.7, 0.182], [64567.4, 0.042], [64570.7, 0.001], [64572.1, 6.495]], "asks": [[64577.8, 1.012], [64579.4, 0.038], [64580.2, 0.003], [64580.3, 0.001], [64594.2, 0.671], [64887.0, 0.52], [65217.9, 0.0], [65377.6, 2.101], [65572.2, 0.002], [65677.8, 3.497], [65818.1, 1.7]]}
{"kind": "depth", "E": 1787089581857, "U": 11315995427668, "u": 11315995435152, "recv_ms": 1787089581815, "bids": [[14072.1, 0.126], [14372.1, 0.504], [14472.1, 3.57], [58114.8, 0.067], [61989.2, 0.0], [63480.8, 0.628], [63926.4, 1.564]], "asks": [[64575.8, 0.0], [64577.8, 0.077], [64577.9, 2.745], [64579.4, 0.038], [64580.2, 0.003], [65217.9, 0.0], [65660.2, 0.0]]}
