{"kind": "depth", "E": 1787089581959, "U": 11315995435387, "u": 11315995441969, "recv_ms": 1787089581923, "bids": [[1000.0, 35.76], [14072.1, 0.014], [14372.1, 0.756], [14472.1, 3.43], [58114.8, 0.067], [61343.4, 0.0], [61989.2, 0.003], [63119.2, 0.64], [63552.0, 1.71], [63572.1, 0.038], [63709.9, 1.899], [63926.4, 1.564], [64249.2, 6.66], [64376.4, 5.964], [64415.1, 6.88], [64432.1, 3.903], [64507.9, 4.529], [64508.0, 0.002], [64508.6, 0.85], [64532.8, 0.44], [64539.6, 0.002], [64548.6, 2.319], [64549.1, 0.154], [64549.2, 0.001], [64572.1, 6.498]], "asks": [[64577.9, 1.81], [64579.4, 0.038], [64580.2, 0.003], [64636.5, 2.031], [64636.6, 0.31], [65217.9, 0.0], [65572.2, 0.022]]}
{"kind": "depth", "E": 1787089582061, "U": 11315995442126, "u": 11315995448796, "recv_ms": 1787089582019, "bids": [[1000.0, 35.76], [14072.1, 0.0], [14372.1, 1.092], [14472.1, 3.108], [58114.8, 0.067], [61343.4, 0.0], [61989.2, 0.0], [63280.7, 0.014], [63474.4, 5.807], [63926.4, 1.564], [64435.1, 1.499], [64502.0, 8.161], [64550.1, 0.002], [64560.5, 0.002], [64572.1, 6.508]], "asks": [[64572.2, 1.714], [64595.5, 1.962], [64634.2, 0.704], [64656.0, 1.311], [64711.9, 1.898], [65217.9, 0.002], [65474.5, 4.575], [65863.6, 0.021]]}
{"kind": "depth", "E": 1787089582163, "U": 11315995448826, "u": 11315995456237, "recv_ms": 1787089582120, "bids": [[14372.1, 1.456], [14472.1, 2.744], [51657.7, 0.0], [58114.8, 0.067], [61343.6, 0.007], [61497.2, 0.002], [61989.2, 0.003], [63571.2, 11.007], [63572.1, 0.018], [63579.8, 0.356], [63655.2, 1.418], [63764.9, 6.345], [63926.4, 1.564], [64572.1, 6.505]], "asks": [[64577.8, 0.077], [64579.4, 0.039], [64580.2, 0.002], [64580.5, 9.541], [64580.9, 0.033], [64583.2, 0.008], [64594.3, 0.001], [64599.7, 0.195], [64599.8, 0.036], [64642.5, 0.015], [64651.3, 37.871], [65217.9, 0.0], [65572.2, 0.002], [65682.8, 1.975]]}
{"kind": "depth", "E": 1787089582265, "U": 11315995456486, "u": 11315995464540, "recv_ms": 1787089582222, "bids": [[1000.0, 35.76], [14372.1, 1.82], [14472.1, 2.38], [51658.0, 0.002], [58114.8, 0.067], [61343.4, 0.0], [61343.5, 0.014], [63732.7, 4.817], [63926.4, 1.564], [64249.2, 6.65], [64547.9, 0.97], [64555.2, 0.632], [64566.7, 0.105], [64567.4, 0.119], [64572.1, 6.496]], "asks": [[64577.8, 0.077], [64579.4, 0.039], [64580.2, 0.002], [64591.2, 0.853], [64599.7, 0.195], [64642.5, 0.015], [64651.3, 37.862], [65217.9, 0.0], [65315.1, 13.701], [65379.4, 6.295], [65383.0, 1.168], [65387.3, 1.006], [65515.0, 1.052]]}
{"kind": "depth", "E": 1787089582367, "U": 11315995464621, "u": 11315995472028, "recv_ms": 1787089582325, "bids": [[1000.0, 35.76], [14372.1, 2.17], [14472.1, 2.03], [51658.0, 0.0], [58114.8, 0.067], [61989.2, 0.0], [63572.1, 0.038], [63926.4, 1.564], [64523.8, 5.022], [64523.9, 0.466], [64532.8, 0.436], [64539.9, 1.323], [64555.3, 0.007]], "asks": [[64577.8, 0.077], [64579.4, 0.038], [64580.2, 0.003], [64587.7, 0.007], [64594.2, 0.669], [64595.0, 10.704], [64599.5, 0.1], [64599.7, 0.041], [64599.8, 0.19], [64644.7, 37.856], [64651.3, 0.007], [64895.1, 4.774], [65217.9, 0.0], [65572.2, 0.022]]}
{"kind": "depth", "E": 1787089582469, "U": 11315995472110, "u": 11315995480839, "recv_ms": 1787089582428, "bids": [[14372.1, 2.534], [14472.1, 1.666], [58114.8, 0.067], [61343.4, 0.0], [61989.2, 0.003], [63280.7, 0.011], [63603.5, 1.411], [63833.1, 6.206], [63926.4, 1.566], [64249.2, 6.651], [64468.0, 2.611], [64468.2, 0.002], [64494.6, 0.05], [64495.3, 30.383], [64501.9, 0.016], [64502.0, 4.827], [64504.3, 2.121], [64512.2, 3.671], [64512.6, 0.001], [64520.1, 1.968], [64541.9, 7.878], [64542.6, 0.211], [64542.7, 0.07], [64543.0, 0.091], [64543.2, 2.918], [64544.6, 0.09], [64545.8, 0.0], [64546.1, 0.058], [64546.3, 0.02], [64547.9, 0.351], [64555.1, 0.002], [64555.2, 0.013], [64556.1, 0.003], [64556.4, 0.558], [64557.0, 0.003], [64562.4, 0.154], [64564.3, 0.0], [64565.3, 0.208], [64565.6, 0.365], [64566.9, 0.239], [64567.8, 0.004], [64568.7, 0.001], [64568.9, 0.005], [64569.5, 0.092], [64569.7, 0.156], [64569.9, 2.404], [64571.0, 0.0], [64571.7, 0.041], [64572.1, 6.478]], "asks": [[64572.2, 0.697], [64572.3, 0.001], [64573.4, 0.698], [64574.6, 0.002], [64575.0, 0.086], [64575.1, 0.006], [64575.5, 0.004], [64575.8, 0.0], [64576.4, 0.084], [64577.4, 0.019], [64577.8, 0.085], [64577.9, 1.802], [64578.0, 2.674], [64578.2, 0.025], [64578.3, 0.549], [64578.4, 0.029], [64578.7, 0.086], [64579.7, 0.0], [64580.0, 0.115], [64580.1, 0.312], [64580.2, 0.002], [64580.3, 0.001], [64580.4, 0.59], [64580.6, 41.645], [64583.1, 0.083], [64583.4, 0.506], [64583.5, 0.465], [64588.5, 0.007], [64589.1, 0.009], [64590.4, 0.007], [64590.8, 0.008], [64591.2, 0.234], [64591.3, 0.095], [64591.4, 2.115], [64592.0, 0.576], [64592.4, 0.003], [64593.2, 0.928], [64595.0, 0.704], [64595.3, 0.62], [64595.8, 0.127], [64596.0, 10.135], [64596.1, 0.003], [64596.7, 0.572], [64597.3, 0.33], [64597.5, 0.014], [64597.7, 0.061], [64597.9, 0.071], [64598.2, 0.116], [64598.6, 0.001], [64599.3, 2.044], [64611.1, 0.0], [64611.2, 4.343], [64616.5, 0.237], [64616.8, 0.637], [64623.0, 0.277], [64623.3, 2.332], [64628.9, 0.0], [64649.7, 0.004], [64681.5, 4.656], [64681.7, 0.002], [64692.5, 0.014], [64692.6, 0.001], [64729.6, 2.335], [64729.7, 7.268], [64895.1, 4.773], [64900.6, 0.201], [64900.9, 0.076], [65217.9, 0.0], [65218.0, 2.653], [65315.1, 12.792], [65315.4, 0.918], [65319.8, 0.535], [65411.6, 1.22]]}
{"kind": "depth", "E": 1787089582571, "U": 11315995480878, "u": 11315995489356, "recv_ms": 1787089582527, "bids": [[1000.0, 35.76], [14372.1, 2.884], [14472.1, 1.316], [58114.8, 0.067], [61343.4, 0.0], [61989.2, 0.0], [63572.1, 0.018], [63615.2, 3.142], [63639.2, 0.001], [63926.4, 1.564], [64249.2, 6.652], [64495.3, 0.01], [64499.7, 30.388], [64539.7, 0.0], [64545.1, 0.057], [64546.1, 0.001], [64550.0, 0.017], [64555.4, 0.559], [64556.4, 0.0], [64556.7, 0.02], [64557.0, 0.001], [64559.7, 0.936], [64560.3, 0.467], [64562.3, 0.002], [64568.9, 0.002], [64572.1, 6.479]], "asks": [[64572.2, 0.724], [64575.8, 0.0], [64577.8, 0.085], [64580.3, 0.001], [64583.0, 0.117], [64590.6, 0.002], [64591.3, 0.637], [64592.0, 0.034], [64592.1, 1.386], [64592.9, 1.571], [64593.2, 0.001], [64608.6, 1.644], [64620.0, 0.015], [64642.5, 37.87], [64644.7, 0.001], [64729.6, 11.806], [64729.7, 0.0], [65217.9, 0.0], [65268.2, 4.46], [65315.1, 11.883], [65318.4, 1.274], [65456.4, 14.652], [65553.3, 1.708], [65572.2, 0.002], [65863.6, 0.024], [66102.0, 0.647]]}
{"kind": "depth", "E": 1787089582673, "U": 11315995489630, "u": 11315995497591, "recv_ms": 1787089582630, "bids": [[1000.0, 35.76], [14372.1, 3.22], [14472.1, 0.98], [51658.0, 0.0], [58114.8, 0.067], [61343.4, 0.0], [63660.4, 9.477], [63764.9, 6.697], [63926.4, 1.564], [63950.9, 4.515], [64432.1, 0.022], [64435.1, 0.986], [64569.3, 0.154], [64569.7, 0.002], [64572.1, 6.481]], "asks": [[64711.9, 1.25], [64712.7, 0.001], [65217.9, 0.0], [65315.1, 10.065], [65315.4, 2.754], [65460.1, 0.002], [65476.2, 23.395], [65573.1, 10.659]]}
{"kind": "depth", "E": 1787089582775, "U": 11315995497866, "u": 11315995504982, "recv_ms": 1787089582733, "bids": [[14372.1, 3.598], [14472.1, 0.602], [51658.0, 0.0], [58114.8, 0.067], [61343.5, 0.012], [61343.6, 0.009], [61989.2, 0.003], [61989.3, 0.001], [63572.1, 0.038], [63622.9, 4.314], [63763.3, 0.796], [63795.9, 4.853], [63830.6, 0.234], [63926.4, 1.564], [64499.7, 0.015], [64501.9, 30.389], [64563.9, 0.631]], "asks": [[65217.9, 0.0], [65315.1, 9.156], [65315.4, 3.672], [65327.7, 1.613], [65572.2, 0.022]]}
{"kind": "depth", "E": 1787089582877, "U": 11315995505126, "u": 11315995513121, "recv_ms": 1787089582833, "bids": [[1000.0, 35.76], [14272.1, 0.084], [14372.1, 3.78], [14472.1, 0.336], [58114.8, 0.067], [61343.4, 0.0], [61989.2, 0.0], [63926.4, 1.564], [64249.2, 6.652], [64376.4, 5.75], [64415.1, 6.958], [64432.1, 4.213], [64483.1, 0.002], [64495.4, 1.98], [64556.4, 0.002], [64556.7, 0.018], [64572.1, 6.482]], "asks": [[64619.5, 0.0], [64626.7, 0.102], [64712.6, 5.409], [64729.6, 11.806], [64768.3, 12.292], [64768.4, 0.005], [65217.9, 0.002], [65276.0, 3.605]]}
{"kind": "depth", "E": 1787089582979, "U": 11315995513188, "u": 11315995520265, "recv_ms": 1787089582936, "bids": [[1000.0, 35.76], [14272.1, 0.336], [14372.1, 3.64], [14472.1, 0.224], [58114.8, 0.067], [61343.5, 0.014], [61989.2, 0.003], [62628.3, 0.683], [63576.5, 1.57], [63764.9, 6.931], [63797.2, 26.591], [63855.3, 0.244], [63926.4, 1.564], [63958.7, 3.479], [64396.6, 0.001], [64494.6, 0.047], [64513.9, 0.05], [64529.5, 0.006], [64539.9, 1.319], [64549.1, 0.0], [64565.6, 0.368]], "asks": [[64630.4, 1.237], [64649.7, 0.001], [65217.9, 0.0], [65315.4, 5.506]]}
{"kind": "depth", "E": 1787089583081, "U": 11315995520399, "u": 11315995528273, "recv_ms": 1787089583040, "bids": [[14272.1, 0.574], [14372.1, 3.528], [14472.1, 0.098], [51658.0, 0.004], [58114.8, 0.067], [61343.4, 0.0], [61989.2, 0.0], [63572.1, 0.018], [63926.4, 1.564], [64147.8, 0.014], [64154.2, 0.0], [64376.4, 6.075], [64415.1, 6.21], [64432.1, 3.558], [64435.1, 1.545], [64467.9, 0.0], [64468.1, 0.003], [64502.0, 8.157], [64504.9, 0.037], [64507.9, 4.581], [64529.5, 0.002], [64533.3, 0.077], [64539.7, 0.004], [64549.0, 0.156], [64560.5, 0.002], [64572.1, 6.492]], "asks": [[64572.2, 0.723], [64577.8, 1.02], [64595.5, 3.205], [64636.4, 2.008], [64636.5, 0.001], [64640.2, 9.134], [64711.9, 1.898], [64758.4, 0.004], [64758.6, 0.052], [64768.2, 4.102], [65217.9, 0.002], [65572.2, 0.002], [65863.6, 0.027], [66186.5, 0.603]]}
{"kind": "depth", "E": 1787089583183, "U": 11315995528310, "u": 11315995535485, "recv_ms": 1787089583143, "bids": [[1000.0, 35.76], [14272.1, 0.826], [14372.1, 3.374], [14472.1, 0.0], [51657.7, 0.0], [51658.0, 0.0], [58114.8, 0.067], [63926.4, 1.564], [64249.2, 6.662], [64495.3, 30.359], [64501.9, 0.016], [64502.0, 4.827], [64502.3, 0.028], [64504.9, 0.0]], "asks": [[64577.8, 0.085], [64580.9, 0.034], [64583.2, 0.007], [64640.2, 3.533], [64642.5, 37.846], [64644.7, 0.001], [64651.3, 0.007], [65217.9, 0.0], [65268.2, 3.772], [65270.5, 3.06]]}
{"kind": "depth", "E": 1787089583285, "U": 11315995535606, "u": 11315995543212, "recv_ms": 1787089583242, "bids": [[14272.1, 1.19], [14372.1, 3.01], [58114.8, 0.067], [61343.4, 0.0], [61989.2, 0.003], [63572.1, 0.038], [63926.4, 1.564], [64250.9, 0.108], [64432.1, 3.523], [64464.7, 0.022], [64495.3, 0.01], [64499.7, 30.364], [64547.8, 1.662], [64555.1, 0.621], [64564.9, 0.077], [64565.3, 0.201], [64568.5, 0.001], [64572.1, 6.482]], "asks": [[64572.2, 0.711], [64577.8, 1.02], [64580.9, 0.033], [64591.1, 0.621], [64598.5, 2.938], [64642.5, 0.015], [64649.1, 37.831], [64712.6, 5.409], [64908.3, 0.113], [65217.9, 0.0], [65377.6, 1.758], [65572.2, 0.022]]}
{"kind": "depth", "E": 1787089583387, "U": 11315995543284, "u": 11315995550587, "recv_ms": 1787089583346, "bids": [[14272.1, 1.54], [14372.1, 2.66], [58114.8, 0.067], [61343.4, 0.0], [61989.2, 0.0], [63886.4, 0.508], [63926.4, 1.564], [64133.8, 3.471], [64249.2, 6.661], [64376.4, 0.901], [64415.1, 4.601], [64432.1, 2.722], [64532.8, 0.44], [64539.7, 0.0], [64543.8, 0.098], [64555.3, 0.005], [64572.1, 6.485]], "asks": [[64572.2, 0.712], [64577.8, 0.085], [64587.7, 0.005], [64644.7, 37.832], [64649.1, 0.0], [65217.9, 0.0], [65218.0, 2.652], [65276.0, 4.293]]}
{"kind": "depth", "E": 1787089583489, "U": 11315995550898, "u": 11315995557931, "recv_ms": 1787089583446, "bids": [[1000.0, 35.76], [14272.1, 1.904], [14372.1, 2.296], [58114.8, 0.067], [61989.2, 0.003], [63564.8, 2.783], [63572.1, 0.018], [63926.4, 1.564], [64249.2, 6.65], [64376.4, 6.075], [64415.1, 7.115], [64432.1, 4.019], [64438.2, 0.005], [64515.9, 0.018], [64555.3, 0.007], [64570.6, 0.001], [64571.0, 0.232], [64572.1, 6.496]], "asks": [[64577.8, 0.085], [64587.7, 0.007], [64700.8, 1.091], [64723.9, 0.008], [64733.6, 0.464], [64895.1, 4.774], [65217.9, 0.0], [65379.4, 6.555], [65572.2, 0.002]]}
{"kind": "depth", "E": 1787089583591, "U": 11315995558008, "u": 11315995565824, "recv_ms": 1787089583548, "bids": [[14272.1, 2.254], [14372.1, 1.946], [58114.8, 0.067], [61343.4, 0.0], [61989.2, 0.0], [63894.1, 5.607], [63926.4, 1.564], [64290.0, 5.633], [64432.1, 3.495], [64435.1, 0.986], [64494.6, 0.05], [64549.0, 0.002], [64549.5, 1.126]], "asks": [[64572.2, 0.712], [64583.7, 0.0], [64626.0, 0.257], [64633.4, 0.004], [64711.9, 1.25], [64712.6, 5.409], [64895.1, 4.775], [65217.9, 0.0], [65270.4, 2.295], [65838.0, 1.75]]}
{"kind": "depth", "E": 1787089583693, "U": 11315995565916, "u": 11315995572902, "recv_ms": 1787089583650, "bids": [[14272.1, 2.618], [14372.1, 1.582], [51658.0, 0.0], [58114.8, 0.067], [61343.5, 0.012], [61343.6, 0.011], [61989.3, 0.0], [63338.5, 0.016], [63572.5, 4.24], [63926.4, 1.566], [64249.2, 6.66], [64549.2, 0.155], [64549.3, 0.005], [64549.5, 0.972]], "asks": [[65476.2, 23.578], [65863.6, 0.024]]}
{"kind": "depth", "E": 1787089583795, "U": 11315995572923, "u": 11315995579255, "recv_ms": 1787089583752, "bids": [[1000.0, 35.76], [14272.1, 2.968], [14372.1, 1.232], [51658.0, 0.0], [58114.8, 0.067], [61343.4, 0.0], [61989.2, 0.003], [63020.7, 0.002], [63572.1, 0.038], [63796.0, 0.783], [63926.4, 1.564], [64420.0, 0.918], [64432.1, 3.523], [64572.1, 6.413]], "asks": [[64599.7, 0.195], [64599.8, 0.036], [64712.6, 5.409], [65088.8, 9.542], [65217.9, 0.0], [65572.2, 0.022], [65666.1, 0.002], [65863.6, 0.027]]}
{"kind": "depth", "E": 1787089583897, "U": 11315995579339, "u": 11315995587348, "recv_ms": 1787089583854, "bids": [[14272.1, 3.304], [14372.1, 0.896], [58114.8, 0.067], [61989.2, 0.0], [62936.7, 0.0], [63926.4, 1.564], [64450.3, 1.322], [64504.9, 0.027], [64537.5, 0.998], [64559.7, 0.009], [64559.8, 0.927], [64560.9, 0.001], [64563.1, 0.55], [64566.5, 0.034], [64566.7, 0.09], [64567.3, 0.096], [64567.4, 0.034], [64569.6, 0.465], [64569.9, 2.405], [64570.0, 0.013], [64570.5, 0.11], [64570.6, 0.001], [64570.7, 1.549], [64571.8, 0.822], [64572.1, 5.948]], "asks": [[64576.2, 0.377], [64577.8, 0.085], [64590.6, 0.544], [64591.3, 0.095], [64591.9, 0.007], [64592.0, 5.119], [64592.2, 1.237], [64592.9, 0.644], [64593.3, 0.095], [64595.5, 1.962], [64596.0, 0.135], [64599.7, 0.195], [64599.8, 0.036], [64688.7, 0.581], [65217.9, 0.0]]}
{"kind": "depth", "E": 1787089583999, "U": 11315995587564, "u": 11315995595626, "recv_ms": 1787089583957, "bids": [[14272.1, 3.682], [14372.1, 0.518], [58114.8, 0.067], [61343.4, 0.0], [61989.2, 0.003], [63280.7, 0.005], [63364.6, 4.805], [63572.1, 0.018], [63926.4, 1.564], [64249.2, 6.66], [64508.2, 0.001], [64508.5, 0.023], [64508.8, 0.289], [64509.1, 0.118], [64509.5, 0.001], [64514.1, 0.078], [64520.5, 0.32], [64527.5, 0.416], [64527.8, 5.409], [64528.1, 0.042], [64528.5, 0.148], [64528.8, 0.036], [64532.8, 0.436], [64533.3, 0.001], [64537.0, 0.121], [64539.5, 6.921], [64541.9, 0.963], [64542.4, 0.433], [64542.5, 0.001], [64542.6, 0.001], [64542.7, 0.0], [64542.8, 0.008], [64542.9, 0.392], [64543.0, 0.021], [64543.1, 2.322], [64543.2, 2.08], [64543.4, 0.007], [64546.0, 0.445], [64546.4, 0.117], [64555.1, 0.002], [64563.1, 0.65], [64563.2, 0.254], [64564.9, 0.007], [64565.0, 0.313], [64565.1, 0.001], [64565.2, 0.001], [64565.3, 0.001], [64565.4, 0.155], [64565.5, 0.0], [64565.6, 0.168], [64565.7, 0.0], [64565.8, 0.002], [64565.9, 0.002], [64566.1, 0.003], [64566.5, 0.002], [64566.7, 1.654], [64566.8, 0.0], [64567.1, 0.519], [64567.3, 0.115], [64567.4, 0.002], [64569.6, 0.735], [64569.9, 2.404], [64570.0, 0.006], [64570.5, 0.001], [64570.7, 0.001], [64570.8, 0.046], [64571.8, 0.545], [64572.1, 6.4]], "asks": [[64576.2, 0.374], [64577.8, 0.085], [64582.5, 0.001], [64582.8, 0.0], [64583.1, 0.0], [64583.4, 0.432], [64583.8, 0.002], [64584.0, 2.327], [64584.1, 1.973], [64584.2, 0.0], [64584.3, 0.004], [64584.4, 0.354], [64584.5, 0.004], [64584.6, 0.0], [64584.7, 0.0], [64584.8, 0.027], [64584.9, 0.0], [64585.0, 0.225], [64591.1, 0.002], [64595.9, 0.296], [64599.7, 0.041], [64599.8, 0.19], [64601.8, 0.006], [64602.1, 0.019], [64602.4, 0.005], [64602.8, 0.001], [64603.1, 0.004], [64603.5, 0.033], [64603.9, 0.003], [64605.1, 0.944], [64606.5, 0.016], [64606.7, 0.018], [64606.8, 0.001], [64606.9, 0.0], [64607.0, 2.353], [64607.1, 0.116], [64607.2, 0.066], [64607.3, 0.016], [64607.4, 0.003], [64607.5, 0.021], [64621.1, 0.389], [64621.4, 0.011], [64621.7, 3.5], [64622.1, 0.0], [64622.4, 0.436], [64625.1, 0.391], [64633.4, 0.0], [64642.5, 0.015], [64644.7, 37.789], [64651.3, 0.007], [65088.8, 9.848], [65217.9, 0.0], [65572.2, 0.002], [65689.3, 0.759]]}
{"kind": "depth", "E": 1787089584101, "U": 11315995595722, "u": 11315995604994, "recv_ms": 1787089584060, "bids": [[1000.0, 35.76], [14172.1, 0.154], [14272.1, 3.738], [14372.1, 0.308], [51657.7, 0.0], [51658.0, 0.05], [58114.8, 0.067], [62874.2, 0.0], [62957.8, 0.954], [63588.3, 0.009], [63589.4, 0.283], [63653.1, 0.05], [63655.4, 0.001], [63797.2, 27.294], [63829.5, 6.023], [63926.4, 1.564], [64435.1, 1.442], [64435.8, 0.002], [64457.3, 4.246], [64495.3, 30.341], [64499.7, 0.015], [64501.5, 0.046], [64501.9, 0.016], [64502.0, 4.827], [64502.3, 0.027], [64540.5, 2.173], [64546.3, 0.058], [64560.5, 0.002], [64563.1, 0.0], [64564.9, 0.077], [64565.0, 0.383], [64565.1, 0.071], [64565.3, 0.201], [64565.5, 0.1], [64565.6, 0.238], [64565.7, 0.1], [64567.3, 0.223], [64567.4, 0.544]], "asks": [[64583.8, 0.262], [64583.9, 1.422], [64584.0, 2.577], [64584.2, 0.52], [64584.4, 0.501], [64584.5, 0.137], [64584.6, 0.14], [64589.3, 1.59], [64590.6, 0.002], [64591.3, 0.637], [64599.8, 0.036], [64599.9, 0.783], [64603.1, 0.264], [64603.5, 0.303], [64606.4, 0.581], [64606.5, 0.266], [64606.7, 0.268], [64606.9, 0.147], [64607.0, 2.486], [64607.1, 0.256], [64640.2, 9.124], [64642.5, 37.803], [64643.6, 0.046], [64643.7, 0.001], [64644.7, 0.001], [64701.1, 0.0], [64711.9, 1.898], [64712.0, 5.6], [64712.9, 0.0], [64732.9, 0.145], [65314.8, 1.158], [65379.4, 6.783], [65489.0, 0.85], [65491.3, 0.002], [65555.0, 76.252], [65556.1, 0.014], [65758.8, 0.0]]}
{"kind": "depth", "E": 1787089584203, "U": 11315995605136, "u": 11315995614658, "recv_ms": 1787089584160, "bids": [[14172.1, 0.392], [14272.1, 3.612], [14372.1, 0.196], [51658.0, 0.0], [58114.8, 0.067], [61343.4, 0.0], [61989.2, 0.0], [63572.1, 0.038], [63588.3, 0.017], [63589.4, 0.293], [63653.1, 0.058], [63655.4, 0.009], [63926.4, 1.564], [64494.6, 0.05], [64495.3, 0.01], [64499.2, 0.006], [64499.7, 30.346], [64502.3, 0.0], [64513.9, 0.047], [64524.7, 0.091], [64527.5, 0.448], [64527.8, 5.441], [64528.7, 0.003], [64563.1, 0.549], [64564.9, 0.147], [64565.2, 0.101], [64565.6, 0.338], [64566.1, 0.035], [64566.4, 0.842], [64566.5, 1.566], [64566.7, 0.191], [64567.3, 0.115], [64567.4, 0.002], [64569.6, 0.465], [64570.0, 0.006], [64570.5, 0.001], [64570.6, 0.001], [64570.7, 0.001], [64571.8, 0.545], [64572.1, 6.492]], "asks": [[64572.2, 0.712], [64577.4, 0.005], [64580.0, 0.106], [64582.7, 0.005], [64583.1, 0.074], [64583.4, 0.496], [64583.9, 1.702], [64584.3, 0.274], [64584.6, 0.287], [64602.4, 0.079], [64602.7, 0.064], [64606.4, 0.861], [64606.8, 0.271], [64607.1, 0.403], [64621.7, 3.574], [64622.1, 0.064], [64630.4, 1.237], [65217.9, 0.0], [65572.2, 0.022]]}
{"kind": "depth", "E": 1787089584305, "U": 11315995614775, "u": 11315995622883, "recv_ms": 1787089584262, "bids": [[14172.1, 0.616], [14272.1, 3.514], [14372.1, 0.07], [51658.0, 0.0], [58114.8, 0.067], [61989.2, 0.003], [63661.6, 2.667], [63926.4, 1.564], [64054.2, 0.0], [64249.2, 6.65], [64528.1, 0.074], [64528.4, 0.032], [64528.7, 0.035], [64549.2, 0.001], [64549.4, 0.156], [64549.6, 0.0], [64563.1, 0.0], [64565.1, 0.141], [64565.8, 0.072], [64566.7, 0.764], [64567.1, 0.551], [64567.3, 0.123], [64567.4, 0.034], [64569.6, 0.738]], "asks": [[64582.1, 0.15], [64582.4, 0.095], [64582.7, 0.088], [64583.6, 0.164], [64584.4, 0.655], [64601.4, 1.408], [64601.8, 0.073], [64602.1, 0.102], [64606.1, 0.472], [64606.9, 0.301], [64620.8, 0.149], [64621.1, 0.456], [64621.4, 0.094], [65482.7, 2.972], [65489.0, 0.858], [65491.3, 0.01], [65516.4, 3.111], [65555.0, 76.262], [65556.1, 0.022], [65668.2, 1.069], [65766.8, 1.977]]}
{"kind": "depth", "E": 1787089584407, "U": 11315995623175, "u": 11315995630816, "recv_ms": 1787089584364, "bids": [[1000.0, 35.76], [14172.1, 0.91], [14272.1, 3.29], [14372.1, 0.0], [58114.8, 0.067], [61343.4, 0.0], [61989.2, 0.0], [63280.7, 0.008], [63572.1, 0.018], [63770.2, 0.798], [63926.4, 1.564], [64147.8, 0.014], [64154.3, 0.009], [64513.9, 0.05], [64514.1, 0.0], [64522.5, 0.081], [64528.9, 0.004], [64537.0, 0.117], [64543.3, 2.0], [64554.8, 1.085], [64565.2, 0.171], [64565.4, 0.255], [64565.5, 0.17], [64568.5, 0.004], [64572.1, 6.495]], "asks": [[64572.2, 0.643], [64578.0, 2.694], [64578.2, 0.048], [64580.0, 0.05], [64584.1, 2.319], [64584.3, 0.414], [64590.8, 0.008], [64592.0, 0.034], [64592.2, 0.31], [64592.6, 3.248], [64606.6, 0.347], [64606.8, 0.411], [64618.7, 0.057], [64649.7, 0.004], [64661.2, 0.043], [64758.6, 0.049], [64758.7, 0.005], [65217.9, 0.0], [65572.2, 0.002], [66121.9, 1.208]]}
{"kind": "depth", "E": 1787089584509, "U": 11315995630959, "u": 11315995638964, "recv_ms": 1787089584467, "bids": [[14172.1, 1.26], [14272.1, 2.94], [58114.8, 0.067], [61989.2, 0.003], [63764.9, 7.165], [63926.4, 1.564], [64055.5, 9.82], [64499.7, 0.015], [64501.9, 30.347], [64502.3, 0.037], [64508.1, 0.072], [64508.4, 0.035], [64528.9, 0.0], [64539.5, 0.006], [64539.7, 0.004], [64540.5, 1.261], [64542.4, 0.503], [64542.5, 0.071], [64542.6, 0.071], [64542.8, 0.108], [64543.0, 0.121], [64543.1, 2.392], [64545.9, 2.42], [64546.3, 0.135], [64546.4, 0.217], [64549.4, 0.002], [64549.5, 0.972], [64555.3, 0.007]], "asks": [[64572.2, 0.644], [64577.8, 1.02], [64580.0, 0.106], [64587.7, 0.007], [64589.3, 1.105], [64599.2, 10.0], [64618.7, 0.001], [64623.9, 0.004], [64640.2, 3.533], [64642.5, 0.015], [64651.3, 37.795], [64895.1, 4.774], [65217.9, 0.0], [65540.9, 0.686]]}
{"kind": "depth", "E": 1787089584611, "U": 11315995639068, "u": 11315995647712, "recv_ms": 1787089584569, "bids": [[1000.0, 35.76], [14172.1, 1.624], [14272.1, 2.576], [51658.0, 0.0], [58114.8, 0.067], [61343.4, 0.0], [61343.5, 0.01], [61343.6, 0.013], [63322.1, 0.008], [63572.1, 0.038], [63926.4, 1.564], [64249.2, 6.662], [64432.1, 0.022], [64435.1, 0.986], [64449.2, 0.118], [64495.2, 0.033], [64508.7, 0.148], [64509.1, 0.15], [64509.4, 0.038], [64514.2, 0.26], [64542.4, 0.573], [64542.7, 0.1], [64543.1, 2.492], [64549.4, 0.156], [64571.3, 0.351], [64572.1, 6.474]], "asks": [[64577.8, 0.085], [64642.5, 37.803], [64644.7, 0.001], [64651.3, 0.007], [64689.0, 2.153], [64711.9, 1.25], [64712.6, 0.0], [64768.2, 2.518], [64769.9, 0.001], [64895.1, 4.773], [65102.3, 0.022], [65217.9, 0.002], [65572.2, 0.022], [65669.9, 8.282]]}
{"kind": "depth", "E": 1787089584713, "U": 11315995647862, "u": 11315995656314, "recv_ms": 1787089584670, "bids": [[1000.0, 35.76], [14172.1, 1.974], [14272.1, 2.226], [58114.8, 0.067], [61343.4, 0.0], [61989.2, 0.0], [63595.5, 1.553], [63926.4, 1.564], [64415.1, 6.981], [64432.1, 4.225], [64542.6, 0.141], [64543.3, 2.07], [64549.4, 0.002], [64568.5, 0.001], [64572.1, 6.469]], "asks": [[64572.2, 0.645], [64574.6, 0.086], [64712.6, 5.409], [64729.6, 11.806], [64885.4, 0.057], [65217.9, 0.0], [65513.2, 0.0], [65526.5, 0.339], [71029.4, 0.002]]}
{"kind": "depth", "E": 1787089584815, "U": 11315995656617, "u": 11315995664849, "recv_ms": 1787089584771, "bids": [[14172.1, 2.338], [14272.1, 1.862], [58114.8, 0.067], [61989.2, 0.003], [62893.2, 1.27], [63572.1, 0.018], [63926.4, 1.564], [64541.9, 0.001], [64542.7, 0.17], [64542.9, 0.492], [64543.0, 0.191], [64548.9, 0.465], [64549.4, 0.002], [64559.9, 0.021], [64561.2, 0.161], [64561.3, 0.001], [64561.4, 0.002], [64561.5, 0.543], [64563.8, 0.001]], "asks": [[64577.8, 1.02], [65217.9, 0.0], [65290.4, 1.53], [65516.4, 2.768], [65572.2, 0.002], [71029.4, 0.0]]}
{"kind": "depth", "E": 1787089584917, "U": 11315995664992, "u": 11315995671425, "recv_ms": 1787089584875, "bids": [[1000.0, 35.76], [14172.1, 2.688], [14272.1, 1.512], [58114.8, 0.067], [61989.2, 0.0], [63342.4, 0.315], [63926.4, 1.564], [64249.2, 6.652], [64559.9, 0.563], [64561.5, 0.001], [64561.6, 0.269], [64561.7, 0.283], [64561.8, 2.323]], "asks": [[64577.8, 0.085], [64726.1, 10.622], [65129.1, 0.537], [65217.9, 0.0]]}
{"kind": "depth", "E": 1787089585019, "U": 11315995671578, "u": 11315995679347, "recv_ms": 1787089584977, "bids": [[1000.0, 35.76], [14172.1, 3.052], [14272.1, 1.148], [58114.8, 0.067], [61343.4, 0.0], [63287.2, 2.029], [63572.1, 0.038], [63926.4, 1.564], [64540.9, 2.21], [64572.1, 6.472]], "asks": [[65196.1, 0.658], [65217.9, 0.0], [65262.8, 0.773], [65379.4, 7.126], [65540.8, 3.186], [65572.2, 0.022]]}
{"kind": "depth", "E": 1787089585121, "U": 11315995679539, "u": 11315995690723, "recv_ms": 1787089585080, "bids": [[14172.1, 3.402], [14272.1, 0.798], [51657.7, 0.0], [58114.8, 0.067], [61989.2, 0.003], [63665.1, 0.001], [63926.4, 1.564], [64055.5, 9.824], [64175.9, 0.815], [64435.1, 1.547], [64502.0, 8.15], [64521.9, 0.004], [64524.8, 1.497], [64530.7, 0.025], [64539.4, 0.007], [64560.5, 0.002], [64567.1, 0.49], [64570.5, 0.02], [64572.1, 6.532]], "asks": [[64598.9, 3.349], [64610.5, 0.063], [64619.8, 0.185], [64640.2, 3.533], [64642.5, 0.015], [64649.1, 37.788], [64711.9, 1.898], [65217.9, 0.0], [65523.9, 0.0]]}
{"kind": "depth", "E": 1787089585223, "U": 11315995690739, "u": 11315995700589, "recv_ms": 1787089585181, "bids": [[1000.0, 35.76], [14072.1, 0.028], [14172.1, 3.71], [14272.1, 0.462], [51658.0, 0.002], [58114.8, 0.067], [61343.4, 0.0], [61343.6, 0.011], [61989.2, 0.0], [63067.9, 0.0], [63572.1, 0.018], [63926.4, 1.564], [64055.5, 9.82], [64163.7, 2.824], [64164.5, 0.592], [64175.9, 0.816], [64249.2, 6.652], [64521.9, 0.005], [64572.1, 6.52]], "asks": [[64572.2, 0.645], [64599.4, 0.172], [64599.9, 0.629], [64642.5, 37.749], [64649.1, 0.0], [65217.9, 0.153], [65282.5, 4.054], [65290.4, 2.295], [65572.2, 0.002]]}
{"kind": "depth", "E": 1787089585325, "U": 11315995700862, "u": 11315995708769, "recv_ms": 1787089585283, "bids": [[1000.0, 35.76], [14072.1, 0.196], [14172.1, 3.724], [14272.1, 0.28], [51658.0, 0.0], [58114.8, 0.067], [61343.4, 0.001], [61989.2, 0.003], [63926.4, 1.564], [64175.9, 0.817], [64495.3, 0.01], [64501.9, 0.016], [64502.0, 4.827], [64504.1, 30.264], [64539.3, 0.003], [64539.4, 0.007], [64539.5, 6.921], [64542.8, 0.108], [64542.9, 0.492], [64543.3, 0.07], [64572.1, 6.188]], "asks": [[64576.4, 0.087], [64580.0, 0.115], [64582.7, 0.087], [64593.9, 0.229], [64595.1, 6.305], [64599.2, 0.0], [64599.4, 0.018], [64599.5, 0.1], [64599.8, 0.19], [64613.0, 2.36], [64639.4, 0.207], [65217.9, 0.153], [65863.6, 0.024]]}
{"kind": "depth", "E": 1787089585427, "U": 11315995709024, "u": 11315995716380, "recv_ms": 1787089585386, "bids": [[14072.1, 0.448], [14172.1, 3.584], [14272.1, 0.168], [51658.0, 0.0], [58114.8, 0.067], [61343.4, 0.0], [61989.2, 0.0], [63572.1, 0.038], [63687.5, 2.038], [63926.4, 1.564], [64175.9, 0.818], [64495.3, 0.01], [64501.9, 30.237], [64504.1, 0.043], [64540.5, 2.17], [64572.1, 6.058]], "asks": [[64598.9, 2.419], [65217.9, 0.153], [65547.5, 0.27], [65572.2, 0.022]]}
{"kind": "depth", "E": 1787089585529, "U": 11315995716608, "u": 11315995724065, "recv_ms": 1787089585488, "bids": [[1000.0, 35.76], [14072.1, 0.672], [14172.1, 3.486], [14272.1, 0.042], [58114.8, 0.067], [61343.4, 0.0], [61343.5, 0.008], [61343.6, 0.013], [63086.9, 0.633], [63926.4, 1.564], [64249.2, 6.652], [64494.6, 0.047], [64513.9, 0.05], [64548.9, 0.311], [64549.3, 0.159], [64555.3, 0.007], [64567.4, 0.095], [64572.1, 6.477]], "asks": [[64572.2, 0.674], [64587.7, 0.007], [64591.3, 0.637], [64599.8, 0.19], [64630.4, 1.237], [64649.7, 0.001], [65217.9, 0.153], [65270.5, 2.295], [65327.3, 14.107], [65347.1, 22.561], [65863.6, 0.027]]}
{"kind": "depth", "E": 1787089585631, "U": 11315995724288, "u": 11315995732177, "recv_ms": 1787089585591, "bids": [[1000.0, 35.76], [14072.1, 0.994], [14172.1, 3.206], [14272.1, 0.0], [58114.8, 0.067], [61343.4, 0.0], [61989.2, 0.003], [63572.1, 0.018], [63748.1, 0.784], [63926.4, 1.566], [64249.2, 6.65], [64555.4, 0.001], [64555.8, 0.769], [64559.8, 0.0], [64559.9, 0.021], [64560.0, 1.285], [64560.1, 0.002], [64561.0, 0.005], [64561.1, 0.003], [64561.2, 0.703], [64561.9, 0.124], [64566.5, 0.018], [64566.7, 0.679], [64567.3, 1.748], [64569.9, 2.32], [64570.1, 0.232], [64571.0, 0.0], [64572.1, 6.478]], "asks": [[64574.6, 0.086], [64586.4, 0.958], [64587.1, 0.014], [64590.8, 0.55], [64591.3, 0.095], [64592.0, 0.034], [64592.4, 0.93], [64592.6, 2.321], [64593.3, 0.095], [64595.9, 0.853], [64596.7, 0.015], [64597.4, 0.121], [64598.2, 0.0], [65217.9, 0.153], [65456.4, 12.364], [65572.2, 0.002]]}
{"kind": "depth", "E": 1787089585733, "U": 11315995732210, "u": 11315995739406, "recv_ms": 1787089585693, "bids": [[14072.1, 1.358], [14172.1, 2.842], [58114.8, 0.067], [61343.4, 0.0], [61989.2, 0.0], [63767.1, 0.8], [63926.4, 1.564], [64432.1, 0.022], [64435.1, 0.986], [64474.0, 2.438], [64485.6, 0.193], [64504.5, 0.001], [64523.8, 5.027], [64526.1, 0.062], [64536.7, 0.072], [64560.1, 0.01], [64561.2, 0.161], [64561.3, 0.001], [64561.4, 0.002], [64561.5, 0.001], [64561.6, 0.811], [64563.1, 0.642], [64566.5, 0.002], [64566.7, 0.122], [64567.3, 0.115], [64567.4, 0.095], [64569.6, 0.465], [64570.5, 0.036], [64570.6, 0.001], [64570.7, 0.001], [64570.8, 1.594], [64571.8, 0.818], [64572.1, 6.49]], "asks": [[64572.2, 0.674], [64577.8, 0.085], [64590.8, 0.008], [64591.3, 0.637], [64605.8, 1.704], [64711.9, 1.25], [64712.6, 0.0], [64895.1, 2.467], [65217.9, 0.153], [65347.1, 27.145], [65442.2, 4.73]]}
{"kind": "depth", "E": 1787089585835, "U": 11315995739499, "u": 11315995747447, "recv_ms": 1787089585795, "bids": [[1000.0, 35.76], [14072.1, 1.708], [14172.1, 2.492], [51658.0, 0.0], [58114.8, 0.067], [61989.2, 0.003], [63572.1, 0.038], [63926.4, 1.564], [64249.2, 6.66], [64432.1, 4.225], [64526.8, 0.032], [64528.0, 0.173], [64554.3, 0.001], [64554.6, 0.236], [64555.4, 0.001], [64560.0, 1.285], [64560.1, 0.544], [64560.9, 0.001], [64561.0, 0.005], [64561.3, 0.526], [64561.6, 0.269], [64561.7, 0.283], [64563.1, 0.0], [64563.2, 0.254], [64564.0, 0.133], [64566.5, 1.566], [64566.7, 0.764], [64567.3, 0.123], [64569.6, 0.641], [64570.5, 0.02], [64570.8, 0.046], [64570.9, 0.0], [64571.8, 0.545]], "asks": [[64575.8, 0.0], [64578.0, 2.674], [64578.2, 0.005], [64578.4, 0.006], [64591.3, 0.095], [64592.0, 0.576], [64592.4, 0.93], [64593.3, 0.095], [64595.9, 0.853], [64596.9, 0.0], [64597.4, 0.005], [64597.9, 0.071], [64598.2, 0.116], [64598.3, 0.161], [64598.8, 0.034], [64599.7, 0.195], [64599.8, 0.036], [64712.6, 5.409], [65217.9, 0.153], [65327.3, 12.578], [65347.1, 28.673], [65572.2, 0.022]]}
{"kind": "depth", "E": 1787089585937, "U": 11315995747628, "u": 11315995754601, "recv_ms": 1787089585900, "bids": [[1000.0, 35.76], [14072.1, 2.072], [14172.1, 2.128], [58114.8, 0.067], [61989.2, 0.0], [63616.6, 2.209], [63768.5, 0.0], [63926.4, 1.564], [64432.1, 0.022], [64528.5, 0.129], [64572.1, 6.407]], "asks": [[64575.8, 0.943], [64577.8, 0.077], [64599.7, 0.041], [64599.8, 0.19], [64712.6, 0.0], [65217.9, 0.153]]}
{"kind": "depth", "E": 1787089586039, "U": 11315995754608, "u": 11315995762527, "recv_ms": 1787089585995, "bids": [[14072.1, 2.422], [14172.1, 1.778], [58114.8, 0.067], [61343.4, 0.0], [61343.6, 0.011], [63572.1, 0.018], [63926.4, 1.564], [64432.1, 4.225], [64523.8, 5.027], [64539.6, 0.006], [64539.7, 0.0], [64560.5, 0.007], [64564.0, 0.134], [64564.2, 0.011], [64564.5, 0.021], [64564.9, 0.14], [64565.6, 0.422], [64568.7, 0.155], [64569.1, 0.001], [64569.3, 0.0], [64569.5, 0.008], [64571.3, 0.041], [64572.1, 6.486]], "asks": [[64572.2, 0.673], [64572.9, 0.937], [64573.6, 0.085], [64575.7, 0.002], [64575.8, 0.008], [64578.7, 0.002], [64579.2, 0.033], [64580.3, 0.094], [64580.4, 0.583], [64588.8, 0.01], [64589.1, 0.001], [64590.8, 0.0], [64591.1, 0.01], [64592.0, 0.568], [64599.8, 0.036], [64600.1, 0.162], [64712.6, 5.409], [64895.1, 4.775], [65217.9, 0.153], [65443.9, 2.211], [65464.2, 0.834], [65572.2, 0.002], [65863.6, 0.03]]}
{"kind": "depth", "E": 1787089586141, "U": 11315995763004, "u": 11315995772825, "recv_ms": 1787089586098, "bids": [[1000.0, 35.76], [14072.1, 2.786], [14172.1, 1.414], [51657.7, 0.0], [51658.0, 0.0], [58114.8, 0.067], [61343.4, 0.0], [61989.2, 0.003], [63257.6, 0.031], [63635.8, 18.013], [63698.7, 4.853], [63789.3, 2.362], [63926.4, 1.564], [64249.2, 6.65], [64435.1, 1.547], [64499.5, 0.031], [64502.0, 8.134], [64560.5, 0.002], [64564.0, 0.133], [64572.1, 6.487]], "asks": [[64572.9, 0.002], [64574.6, 1.021], [64583.4, 0.497], [64590.8, 0.0], [64591.3, 0.637], [64592.0, 0.026], [64592.1, 2.134], [64640.2, 3.533], [64642.5, 0.015], [64649.1, 37.734], [64711.9, 1.898], [65217.9, 0.153]]}
{"kind": "depth", "E": 1787089586243, "U": 11315995772923, "u": 11315995782235, "recv_ms": 1787089586200, "bids": [[1000.0, 35.76], [14072.1, 3.136], [14172.1, 1.064], [51658.0, 0.0], [58114.8, 0.067], [61989.2, 0.0], [63572.1, 0.038], [63926.4, 1.564], [64572.1, 6.486]], "asks": [[64572.2, 0.673], [64642.5, 37.667], [64649.1, 0.0], [65217.9, 0.153], [65340.6, 5.35], [65572.2, 0.022], [65863.6, 0.03]]}
{"kind": "depth", "E": 1787089586345, "U": 11315995782461, "u": 11315995790535, "recv_ms": 1787089586302, "bids": [[14072.1, 3.5], [14172.1, 0.7], [51658.0, 0.0], [58114.8, 0.067], [61343.4, 0.0], [61989.2, 0.003], [63277.8, 0.316], [63926.4, 1.564], [64507.5, 0.42], [64566.5, 0.018], [64566.7, 0.137], [64567.3, 1.748], [64567.4, 0.645], [64571.9, 0.01], [64572.1, 6.482]], "asks": [[64574.6, 0.086], [64577.8, 0.077], [64578.7, 0.021], [64578.8, 0.023], [64585.7, 0.614], [64586.4, 0.649], [64594.4, 1.069], [64595.3, 0.001], [64595.9, 0.296], [64596.1, 0.56], [64597.5, 0.13], [64598.2, 0.0], [64636.8, 0.01], [65217.9, 0.153]]}
{"kind": "depth", "E": 1787089586447, "U": 11315995790640, "u": 11315995799165, "recv_ms": 1787089586405, "bids": [[1000.0, 35.76], [14072.1, 3.738], [14172.1, 0.406], [14472.1, 0.056], [58114.8, 0.067], [61095.5, 0.0], [63572.1, 0.018], [63700.4, 3.143], [63926.4, 1.564], [64249.2, 6.66], [64432.1, 3.829], [64571.9, 0.011], [64572.1, 6.481]], "asks": [[64600.0, 1.094], [64600.1, 0.008], [64626.1, 0.001], [64712.6, 5.409], [65088.8, 6.014], [65217.9, 0.153], [65340.6, 6.267], [65572.2, 0.002], [67800.8, 0.068]]}
{"kind": "depth", "E": 1787089586549, "U": 11315995799339, "u": 11315995806730, "recv_ms": 1787089586506, "bids": [[1000.0, 35.76], [14072.1, 3.696], [14172.1, 0.252], [14472.1, 0.252], [58114.8, 0.067], [61343.4, 0.0], [61989.2, 0.0], [63458.1, 0.0], [63926.4, 1.564], [64376.4, 6.529], [64415.1, 7.324], [64432.1, 4.123], [64494.6, 0.05], [64551.2, 0.003], [64555.3, 0.007]], "asks": [[64572.2, 0.674], [64577.8, 0.077], [64587.7, 0.007], [64591.3, 1.256], [64599.9, 0.629], [64600.0, 0.94], [64623.8, 1.911], [64649.7, 0.004], [64725.8, 0.002], [64768.3, 11.291], [65217.9, 0.153]]}
{"kind": "depth", "E": 1787089586651, "U": 11315995806991, "u": 11315995814801, "recv_ms": 1787089586608, "bids": [[14072.1, 3.556], [14172.1, 0.14], [14472.1, 0.504], [58114.8, 0.067], [61343.4, 0.0], [61989.2, 0.003], [63572.1, 0.038], [63926.4, 1.564], [64432.1, 3.557], [64435.1, 0.986], [64512.6, 0.029], [64564.0, 0.134], [64565.3, 0.285], [64568.6, 0.001], [64572.1, 6.483]], "asks": [[64572.2, 0.674], [64573.2, 0.084], [64578.3, 0.465], [64600.0, 1.094], [64711.9, 1.25], [64712.6, 5.409], [65217.9, 0.153], [65513.5, 1.754], [65521.4, 4.738], [65572.2, 0.022]]}
{"kind": "depth", "E": 1787089586753, "U": 11315995814997, "u": 11315995821849, "recv_ms": 1787089586710, "bids": [[1000.0, 35.76], [14072.1, 3.458], [14172.1, 0.014], [14472.1, 0.728], [58114.8, 0.067], [61343.4, 0.0], [61989.2, 0.0], [63306.3, 0.682], [63480.8, 1.256], [63683.4, 6.144], [63926.4, 1.564], [64249.2, 6.652], [64494.6, 0.05], [64513.9, 0.047], [64553.9, 0.116], [64554.6, 0.12], [64555.0, 0.657], [64555.8, 0.211], [64557.7, 0.0], [64558.5, 1.133], [64559.3, 0.929], [64560.0, 0.358], [64572.1, 6.487]], "asks": [[64596.4, 0.097], [64596.6, 0.174], [64597.5, 0.014], [64597.9, 0.014], [64598.3, 0.154], [64598.7, 0.021], [64630.4, 1.237], [64649.7, 0.001], [64895.1, 4.773], [65088.8, 9.848], [65217.9, 0.153]]}
{"kind": "depth", "E": 1787089586855, "U": 11315995821881, "u": 11315995829533, "recv_ms": 1787089586813, "bids": [[1000.0, 35.76], [14072.1, 3.122], [14172.1, 0.0], [14472.1, 1.078], [58114.8, 0.067], [61989.2, 0.003], [63572.1, 0.018], [63926.4, 1.564], [64557.7, 0.007], [64558.5, 1.126], [64559.3, 0.002], [64560.2, 1.023], [64568.7, 0.239], [64572.1, 6.484]], "asks": [[64573.2, 0.0], [64577.8, 0.077], [64596.4, 0.04], [64596.6, 0.058], [64597.3, 0.387], [64597.5, 0.13], [64599.8, 0.19], [64600.0, 0.94], [65528.7, 3.812], [65572.2, 0.002], [65669.9, 3.72]]}
{"kind": "depth", "E": 1787089586957, "U": 11315995829637, "u": 11315995837455, "recv_ms": 1787089586913, "bids": [[14072.1, 2.772], [14472.1, 1.428], [58114.8, 0.067], [61343.4, 0.0], [63926.4, 1.564], [64549.3, 0.159], [64569.1, 0.085]], "asks": [[64573.6, 0.001], [65217.9, 0.153], [65492.8, 0.0], [65863.6, 0.033]]}
{"kind": "depth", "E": 1787089587059, "U": 11315995837501, "u": 11315995846833, "recv_ms": 1787089587019, "bids": [[1000.0, 35.76], [14072.1, 2.408], [14472.1, 1.792], [58114.8, 0.067], [61343.4, 0.0], [61989.2, 0.0], [63448.3, 0.0], [63465.0, 0.616], [63572.1, 0.038], [63926.4, 1.564], [64182.0, 3.137], [64249.2, 6.652], [64468.1, 0.0], [64468.2, 0.005], [64488.3, 0.038], [64549.2, 0.155], [64549.3, 0.005], [64555.5, 0.042], [64556.4, 0.0], [64560.5, 0.002], [64564.0, 0.133], [64572.0, 0.262], [64572.1, 6.485]], "asks": [[64572.2, 0.67], [64575.8, 0.943], [64577.8, 0.077], [64594.3, 0.003], [64595.8, 0.125], [64611.5, 0.016], [64620.4, 0.072], [65217.9, 0.153], [65572.2, 0.022], [65669.9, 8.282], [67800.8, 0.063]]}
{"kind": "depth", "E": 1787089587161, "U": 11315995847007, "u": 11315995855780, "recv_ms": 1787089587119, "bids": [[1000.0, 35.76], [14072.1, 2.058], [14472.1, 2.142], [51657.7, 0.0], [58114.8, 0.067], [61343.4, 0.0], [61989.2, 0.003], [63764.9, 7.43], [63926.4, 1.564], [64180.6, 0.01], [64182.1, 1.226], [64435.1, 1.447], [64508.6, 1.234], [64564.0, 0.133], [64572.1, 6.486]], "asks": [[64575.8, 0.008], [64577.8, 0.077], [64599.7, 0.041], [64599.8, 0.036], [64605.1, 1.582], [64640.2, 9.104], [64711.9, 1.898], [65217.9, 0.153], [65350.7, 5.372]]}
{"kind": "depth", "E": 1787089587263, "U": 11315995855939, "u": 11315995863819, "recv_ms": 1787089587223, "bids": [[14072.1, 1.694], [14472.1, 2.506], [58114.8, 0.067], [61989.2, 0.0], [63474.4, 6.435], [63487.3, 2.977], [63572.1, 0.018], [63579.8, 0.003], [63656.9, 2.354], [63709.0, 4.425], [63926.4, 1.566], [64432.1, 4.016], [64435.1, 0.986], [64522.0, 0.164], [64541.2, 0.004], [64572.1, 6.484]], "asks": [[64577.8, 0.077], [64599.7, 0.195], [64608.4, 0.072], [64711.9, 1.25], [64712.6, 5.409], [65217.9, 0.153], [65290.5, 3.221], [65525.2, 0.128], [65572.2, 0.002]]}
{"kind": "depth", "E": 1787089587365, "U": 11315995864013, "u": 11315995871397, "recv_ms": 1787089587323, "bids": [[1000.0, 35.76], [14072.1, 1.33], [14472.1, 2.87], [58114.8, 0.067], [61343.4, 0.0], [61343.6, 0.009], [61989.2, 0.003], [63627.7, 0.736], [63926.4, 1.564], [64249.2, 6.662], [64541.2, 0.006], [64553.9, 0.0], [64554.7, 0.121], [64555.0, 0.099], [64555.9, 1.06], [64571.8, 0.548], [64571.9, 0.008], [64572.1, 6.483]], "asks": [[64572.2, 0.669], [64574.3, 0.085], [64599.7, 0.041], [64599.8, 0.19], [64608.4, 0.074], [65217.9, 0.153], [65270.2, 1.532], [65315.1, 8.247]]}
{"kind": "depth", "E": 1787089587467, "U": 11315995871491, "u": 11315995879086, "recv_ms": 1787089587426, "bids": [[1000.0, 35.76], [14072.1, 0.98], [14472.1, 3.22], [58114.8, 0.067], [61343.4, 0.0], [63572.1, 0.038], [63732.7, 5.13], [63770.3, 4.704], [63926.3, 0.031], [63926.4, 1.564], [64162.0, 0.049], [64205.6, 0.0], [64206.8, 1.417], [64302.0, 0.192], [64302.5, 1.087], [64372.8, 1.735], [64373.5, 0.802], [64547.8, 1.043], [64554.8, 0.466], [64564.3, 0.003], [64571.9, 0.007], [64572.1, 6.482]], "asks": [[64572.2, 0.632], [64591.3, 0.637], [64598.5, 2.319], [64599.8, 0.19], [64774.5, 0.365], [64776.8, 0.001], [64848.0, 4.416], [64848.1, 0.032], [64944.9, 0.455], [64945.3, 0.004], [65217.9, 0.155], [65315.4, 6.423], [65347.1, 27.91], [65476.2, 25.865], [65572.2, 0.022], [66506.5, 0.0], [67800.8, 0.058]]}
{"kind": "depth", "E": 1787089587569, "U": 11315995879252, "u": 11315995886101, "recv_ms": 1787089587526, "bids": [[14072.1, 0.644], [14472.1, 3.556], [58114.8, 0.067], [61343.4, 0.0], [61343.5, 0.012], [61989.2, 0.0], [63603.5, 1.764], [63764.9, 7.664], [63926.4, 1.564], [64090.0, 0.076], [64363.0, 5.331], [64372.9, 0.0], [64432.1, 3.557], [64543.0, 0.191], [64548.0, 1.987], [64555.3, 0.007], [64555.4, 0.62], [64572.1, 6.484]], "asks": [[64572.2, 0.635], [64587.7, 0.007], [64591.4, 2.734], [64598.7, 0.64], [64599.8, 0.036], [64599.9, 0.629], [64712.6, 5.409], [64776.7, 0.024], [64803.7, 7.934], [65217.9, 0.153], [65347.1, 29.439], [65456.4, 10.075], [65540.8, 3.529]]}
{"kind": "depth", "E": 1787089587671, "U": 11315995886540, "u": 11315995893759, "recv_ms": 1787089587627, "bids": [[1000.0, 35.76], [14072.1, 0.35], [14372.1, 0.084], [14472.1, 3.766], [51658.0, 0.0], [58114.8, 0.067], [61989.2, 0.003], [63572.1, 0.018], [63629.3, 1.098], [63764.9, 7.898], [63778.0, 10.036], [63926.4, 1.564], [63942.2, 0.004], [64249.2, 6.652], [64553.9, 0.116], [64554.7, 0.005], [64555.1, 0.56], [64555.9, 0.502], [64559.4, 0.022], [64559.5, 1.237], [64559.7, 0.551], [64560.1, 0.002], [64560.2, 0.096], [64560.3, 0.467], [64560.4, 0.456], [64561.9, 0.124], [64564.3, 0.0], [64572.1, 6.488]], "asks": [[64577.8, 0.077], [64596.7, 0.015], [64597.5, 0.014], [64597.6, 0.124], [65062.2, 0.0], [65211.9, 0.001], [65217.9, 0.153], [65270.2, 0.767], [65347.1, 30.202], [65572.2, 0.002], [65863.6, 0.036]]}
{"kind": "depth", "E": 1787089587773, "U": 11315995893991, "u": 11315995902372, "recv_ms": 1787089587731, "bids": [[1000.0, 35.76], [14072.1, 0.224], [14372.1, 0.308], [14472.1, 3.668], [58114.8, 0.067], [61989.2, 0.0], [63383.0, 2.392], [63717.2, 1.572], [63926.4, 1.564], [64205.0, 41.853], [64206.8, 7.408], [64249.2, 4.319], [64301.4, 34.588], [64372.3, 26.643], [64373.5, 4.676], [64432.1, 0.022], [64482.8, 0.002], [64482.9, 0.001], [64495.1, 0.098], [64528.1, 0.088], [64539.3, 0.001], [64539.4, 0.005], [64539.5, 6.919], [64542.8, 0.106], [64542.9, 0.49], [64548.0, 1.368], [64555.4, 0.001], [64559.5, 0.31], [64559.7, 0.009], [64560.4, 1.383], [64560.5, 0.002], [64561.9, 0.666], [64563.1, 0.101], [64566.5, 0.002], [64566.7, 0.122], [64567.3, 0.115], [64567.4, 0.095], [64567.5, 0.0], [64569.1, 0.001], [64569.6, 0.465], [64570.5, 0.02], [64570.6, 0.024], [64570.7, 0.001], [64570.8, 2.136], [64571.8, 0.761], [64572.1, 6.349]], "asks": [[64572.2, 0.636], [64572.9, 0.937], [64573.5, 1.845], [64573.9, 0.084], [64578.0, 2.59], [64580.0, 0.101], [64580.5, 9.541], [64584.1, 2.321], [64592.4, 0.003], [64592.8, 1.185], [64712.6, 0.0], [64744.3, 0.001], [64758.7, 0.002], [64758.8, 0.175], [64771.5, 5.811], [64774.3, 27.033], [64845.5, 33.323], [64895.1, 4.775], [65217.9, 0.153], [65476.2, 28.153], [65484.2, 0.763]]}
{"kind": "depth", "E": 1787089587875, "U": 11315995902530, "u": 11315995910112, "recv_ms": 1787089587833, "bids": [[14072.1, 0.112], [14372.1, 0.56], [14472.1, 3.528], [58114.8, 0.067], [61343.4, 0.0], [61343.6, 0.007], [63280.7, 0.011], [63572.1, 0.038], [63615.2, 2.592], [63648.9, 9.885], [63797.2, 28.86], [63926.4, 1.564], [64089.4, 52.512], [64363.0, 5.115], [64372.4, 0.221], [64376.4, 6.529], [64415.1, 7.324], [64432.1, 4.123], [64453.0, 0.238], [64560.5, 0.544], [64561.9, 0.124], [64563.1, 0.0], [64563.7, 0.017], [64564.0, 0.134], [64566.5, 1.566], [64566.7, 0.687], [64567.3, 0.2], [64568.7, 0.155], [64569.6, 0.7], [64570.5, 0.001], [64570.6, 0.001], [64570.8, 0.046], [64570.9, 0.0], [64571.0, 0.0], [64571.8, 0.548], [64572.1, 6.345]], "asks": [[64572.9, 0.937], [64599.9, 0.783], [64712.6, 5.409], [64762.8, 0.543], [64768.3, 10.41], [64774.2, 1.258], [64803.7, 7.718], [64827.9, 0.195], [64830.5, 0.196], [65217.9, 0.153], [65572.2, 0.022]]}
{"kind": "depth", "E": 1787089587977, "U": 11315995910333, "u": 11315995918121, "recv_ms": 1787089587941, "bids": [[1000.0, 35.76], [14072.1, 0.0], [14372.1, 0.798], [14472.1, 3.402], [58114.8, 0.065], [61343.4, 0.0], [61989.2, 0.003], [63926.4, 1.564], [64249.2, 4.319], [64494.6, 0.047], [64513.9, 0.05], [64564.0, 0.133], [64566.7, 0.679], [64567.4, 0.103], [64570.5, 0.02], [64572.1, 6.345]], "asks": [[64572.2, 0.636], [64572.9, 0.002], [64577.4, 0.033], [64577.8, 1.012], [64579.9, 0.11], [64599.8, 0.036], [64599.9, 0.629], [64630.4, 1.234], [65217.9, 0.153]]}
{"kind": "depth", "E": 1787089588079, "U": 11315995918133, "u": 11315995926274, "recv_ms": 1787089588036, "bids": [[1000.0, 35.76], [14372.1, 1.162], [14472.1, 3.038], [58114.8, 0.067], [61989.2, 0.0], [63572.1, 0.018], [63668.1, 22.312], [64249.2, 6.65], [64560.5, 0.544], [64564.0, 0.134]], "asks": [[64572.9, 0.937], [64577.4, 0.143], [64577.8, 0.077], [64600.0, 0.94], [64630.4, 1.237], [64762.8, 0.0], [65217.9, 0.155], [65402.3, 0.007], [65477.6, 0.0], [65572.2, 0.002], [67800.8, 0.063]]}
{"kind": "depth", "E": 1787089588181, "U": 11315995926363, "u": 11315995934404, "recv_ms": 1787089588138, "bids": [[14372.1, 1.512], [14472.1, 2.688], [51657.7, 0.0], [58114.8, 0.067], [61343.4, 0.0], [61989.2, 0.003], [63280.7, 0.008], [63622.9, 4.863], [63797.2, 24.164], [63834.9, 2.731], [63926.4, 1.564], [64435.1, 1.532], [64567.4, 0.042], [64572.1, 6.41]], "asks": [[64572.9, 0.002], [64577.8, 0.077], [64600.0, 0.94], [64601.1, 0.394], [64601.2, 0.027], [64601.3, 2.323], [64604.1, 0.004], [64604.2, 2.323], [64604.3, 1.135], [64605.0, 0.003], [64605.1, 1.584], [64605.2, 0.166], [64607.1, 0.405], [64607.2, 0.068], [64607.3, 0.018], [64643.9, 3.021], [64711.9, 1.898], [65217.9, 0.153], [65863.6, 0.03]]}
{"kind": "depth", "E": 1787089588283, "U": 11315995934705, "u": 11315995942921, "recv_ms": 1787089588240, "bids": [[1000.0, 35.76], [14372.1, 1.876], [14472.1, 2.324], [51658.0, 0.0], [58114.8, 0.067], [61095.5, 0.002], [61343.4, 0.0], [61989.2, 0.0], [63280.7, 0.011], [63572.1, 0.038], [63627.7, 0.391], [63926.4, 1.564], [64249.2, 6.66], [64432.1, 0.022], [64435.1, 0.986], [64564.0, 0.133], [64572.1, 6.411]], "asks": [[64572.8, 0.003], [64600.0, 0.94], [64600.1, 0.008], [64711.9, 1.25], [64712.6, 0.0], [65217.9, 0.153], [65411.6, 1.525], [65572.2, 0.022]]}
{"kind": "depth", "E": 1787089588385, "U": 11315995943066, "u": 11315995951878, "recv_ms": 1787089588343, "bids": [[1000.0, 35.76], [14372.1, 2.226], [14472.1, 1.974], [51658.0, 0.0], [58114.8, 0.067], [61343.4, 0.0], [63797.2, 28.86], [63926.4, 1.564], [64415.1, 7.24], [64416.0, 2.149], [64432.1, 4.048], [64553.9, 0.0], [64554.8, 0.582], [64555.1, 0.002], [64556.0, 0.561], [64563.1, 0.024], [64566.5, 0.002], [64566.7, 0.122], [64567.3, 0.115], [64567.4, 0.034], [64567.5, 0.542], [64567.6, 0.08], [64569.6, 0.465], [64570.5, 1.591], [64572.1, 6.408]], "asks": [[64572.2, 0.636], [64580.0, 0.115], [64600.2, 0.322], [64712.6, 5.409], [64729.5, 10.454], [64729.6, 1.378], [64768.3, 10.793], [65166.0, 2.409], [65217.9, 0.153], [65329.7, 3.058], [65421.0, 1.145], [67800.8, 0.058]]}
{"kind": "depth", "E": 1787089588487, "U": 11315995951952, "u": 11315995959869, "recv_ms": 1787089588444, "bids": [[14372.1, 2.59], [14472.1, 1.61], [58114.8, 0.067], [61989.2, 0.003], [63572.1, 0.018], [63617.8, 0.345], [63700.4, 3.377], [63713.4, 0.001], [63926.3, 0.03], [63926.4, 1.564], [63940.8, 65.199], [64549.2, 0.001], [64549.3, 0.159], [64563.1, 0.65], [64566.5, 0.002], [64567.3, 0.096], [64567.5, 0.0], [64567.6, 0.003], [64570.5, 0.017], [64570.6, 0.001], [64570.7, 0.001], [64570.8, 0.046], [64570.9, 1.548], [64571.8, 0.758]], "asks": [[64572.8, 0.002], [64941.5, 6.353], [64943.6, 41.893], [65060.5, 50.637], [65210.2, 67.076], [65217.9, 0.153], [65542.1, 0.001], [65572.2, 0.002], [65682.4, 1.217]]}
{"kind": "depth", "E": 1787089588589, "U": 11315995960064, "u": 11315995968911, "recv_ms": 1787089588546, "bids": [[1000.0, 35.76], [14372.1, 2.94], [14472.1, 1.26], [58114.8, 0.067], [61343.4, 0.0], [61989.2, 0.0], [63648.9, 7.532], [63926.4, 1.564], [64249.2, 6.65], [64376.4, 6.756], [64415.1, 7.465], [64428.2, 0.024], [64432.1, 4.154], [64436.9, 0.0], [64437.0, 0.033], [64438.0, 0.408], [64453.0, 0.243], [64459.4, 11.124], [64460.1, 2.757], [64494.6, 0.05], [64507.8, 4.631], [64507.9, 0.161], [64546.2, 0.003], [64546.9, 0.625], [64554.2, 0.624], [64555.3, 0.007], [64563.1, 0.0], [64563.7, 0.012], [64564.0, 0.134], [64566.5, 1.566], [64566.7, 0.679], [64567.3, 0.2], [64567.4, 0.103], [64569.6, 0.7], [64570.5, 0.001], [64570.9, 0.0], [64571.8, 0.548], [64572.1, 6.219]], "asks": [[64572.2, 0.668], [64573.1, 0.094], [64574.8, 0.311], [64577.6, 0.003], [64584.1, 0.658], [64587.7, 0.007], [64600.0, 0.94], [64600.1, 0.008], [64600.2, 0.168], [64600.4, 0.203], [64636.0, 2.018], [64636.4, 0.005], [64649.7, 0.004], [64659.8, 0.0], [64662.2, 0.0], [64681.9, 2.805], [64684.4, 12.177], [64712.6, 5.409], [64733.7, 0.006], [64768.3, 10.023], [65217.9, 0.153], [65682.4, 0.0], [65702.2, 2.432], [65863.6, 0.027]]}
{"kind": "depth", "E": 1787089588691, "U": 11315995969037, "u": 11315995976482, "recv_ms": 1787089588648, "bids": [[14372.1, 3.304], [14472.1, 0.896], [58114.8, 0.067], [61343.4, 0.0], [61343.6, 0.005], [61989.2, 0.003], [63572.1, 0.038], [63753.7, 0.157], [63926.4, 1.564], [64535.6, 0.016], [64563.1, 0.024], [64564.9, 0.224], [64566.5, 0.002], [64566.7, 0.122], [64567.3, 0.192], [64567.4, 1.643], [64567.5, 0.0], [64568.2, 0.001], [64570.5, 0.043], [64570.6, 0.543], [64571.7, 0.044], [64571.8, 0.545], [64572.1, 6.242]], "asks": [[64572.6, 0.085], [64577.2, 0.0], [64583.4, 0.496], [64586.5, 1.451], [64589.1, 0.009], [64589.3, 2.323], [64589.9, 0.001], [64590.1, 10.367], [64591.1, 0.002], [64591.4, 2.115], [64592.1, 1.386], [64594.4, 1.069], [64595.1, 1.22], [65217.9, 0.153], [65327.3, 11.049], [65443.9, 2.927], [65464.1, 2.298], [65489.1, 1.141], [65548.7, 6.048], [65572.2, 0.022]]}
{"kind": "depth", "E": 1787089588793, "U": 11315995976593, "u": 11315995985056, "recv_ms": 1787089588750, "bids": [[14372.1, 3.654], [14472.1, 0.546], [51658.0, 0.0], [58114.8, 0.067], [61343.4, 0.0], [61989.2, 0.0], [63572.1, 0.018], [63668.1, 24.664], [63732.7, 7.48], [63926.4, 1.564], [64539.3, 6.916], [64539.5, 0.004], [64553.9, 0.116], [64554.8, 0.466], [64555.1, 0.56], [64556.0, 0.003], [64559.4, 0.949], [64559.7, 0.017], [64560.4, 0.456], [64560.5, 0.002], [64561.9, 0.666], [64563.1, 0.642], [64564.0, 0.133], [64564.4, 0.016], [64566.5, 1.566], [64567.3, 0.096], [64567.4, 0.095], [64567.5, 0.0], [64568.2, 0.085], [64569.6, 0.465], [64570.5, 0.001], [64570.6, 0.001], [64570.7, 0.002], [64570.8, 0.046], [64570.9, 0.0], [64571.0, 0.0], [64571.8, 0.759], [64572.1, 6.335]], "asks": [[64572.6, 0.001], [64573.1, 0.01], [64591.8, 0.025], [64592.7, 1.047], [64592.8, 0.258], [64594.7, 0.001], [64596.7, 0.015], [64597.6, 0.124], [64895.1, 4.773], [65217.9, 0.153], [65347.1, 30.416], [65547.5, 0.537], [65572.2, 0.002], [65702.2, 3.648], [65863.6, 0.024], [67800.8, 0.053]]}
{"kind": "depth", "E": 1787089588895, "U": 11315995985125, "u": 11315995992605, "recv_ms": 1787089588853, "bids": [[1000.0, 35.76], [14272.1, 0.14], [14372.1, 3.738], [14472.1, 0.322], [58114.8, 0.067], [61343.4, 0.0], [63926.4, 1.564], [64249.2, 6.652], [64457.2, 4.17], [64457.3, 0.374], [64467.6, 2.326], [64468.0, 0.288], [64493.4, 0.003], [64501.4, 0.047], [64501.5, 0.0], [64503.1, 0.004], [64525.3, 0.209], [64525.7, 0.007], [64528.1, 0.074], [64540.9, 1.245], [64553.9, 0.0], [64555.1, 0.002], [64555.6, 0.116], [64555.9, 1.06], [64556.8, 1.069], [64559.4, 0.022], [64559.7, 0.009], [64560.1, 0.929], [64560.2, 0.096], [64561.0, 0.005], [64561.1, 0.003], [64561.2, 0.703], [64561.9, 0.124], [64562.0, 0.001], [64563.1, 0.0], [64564.4, 0.013], [64564.9, 0.227], [64566.7, 0.764], [64567.3, 0.123], [64568.6, 0.085], [64569.6, 0.697], [64570.7, 0.001], [64571.8, 0.545], [64572.1, 6.332]], "asks": [[64572.2, 0.644], [64574.8, 0.001], [64577.4, 0.157], [64577.8, 0.077], [64590.8, 0.0], [64591.3, 0.637], [64592.0, 0.026], [64592.7, 0.12], [64593.4, 0.928], [64596.1, 0.003], [64596.9, 0.557], [64597.3, 0.33], [64597.6, 0.008], [64598.2, 0.057], [64598.3, 0.27], [64600.3, 0.162], [64600.4, 0.049], [64605.6, 0.0], [64621.7, 0.074], [64643.6, 0.046], [64643.9, 0.078], [64644.4, 1.878], [64681.1, 2.323], [64681.5, 2.333], [64711.7, 3.885], [64712.0, 1.728], [65217.9, 0.153], [65347.1, 31.944], [65863.6, 0.027]]}
{"kind": "depth", "E": 1787089588997, "U": 11315995992774, "u": 11315995999768, "recv_ms": 1787089588954, "bids": [[14272.1, 0.364], [14372.1, 3.64], [14472.1, 0.196], [58114.8, 0.067], [61343.4, 0.0], [61989.2, 0.003], [63651.2, 0.785], [63668.1, 24.852], [63926.4, 1.564], [64432.1, 0.022], [64470.9, 0.0], [64473.4, 1.922], [64500.5, 2.12], [64502.3, 6.037], [64512.6, 0.001], [64524.9, 3.507], [64541.0, 0.98], [64549.0, 0.156], [64549.3, 0.005], [64560.2, 0.096], [64560.3, 1.009], [64561.2, 0.161], [64561.3, 0.526], [64561.4, 0.002], [64564.0, 0.134], [64564.9, 0.224], [64572.1, 6.335]], "asks": [[64572.9, 0.002], [64575.8, 0.008], [64588.6, 1.619], [64598.7, 0.64], [64603.0, 0.998], [64619.2, 3.934], [64641.8, 6.0], [64675.4, 0.769], [64676.7, 0.0], [64711.9, 0.0], [64712.6, 0.0], [65217.9, 0.153]]}
{"kind": "depth", "E": 1787089589099, "U": 11315995999789, "u": 11315996008916, "recv_ms": 1787089589057, "bids": [[14272.1, 0.616], [14372.1, 3.5], [14472.1, 0.084], [58114.8, 0.067], [61343.4, 0.0], [61989.2, 0.0], [63572.1, 0.038], [63616.6, 1.11], [63668.1, 25.321], [63926.4, 1.564], [64249.2, 6.652], [64432.1, 4.056], [64543.0, 0.189], [64549.0, 0.156], [64560.5, 0.002], [64564.0, 0.133], [64572.1, 6.336]], "asks": [[64572.9, 0.002], [64640.2, 3.533], [64642.5, 37.34], [64644.7, 0.001], [64649.1, 0.0], [64712.6, 5.409], [64768.3, 10.74], [65217.9, 0.153], [65290.2, 0.766], [65572.2, 0.022]]}
{"kind": "depth", "E": 1787089589201, "U": 11315996009099, "u": 11315996018653, "recv_ms": 1787089589157, "bids": [[1000.0, 35.76], [14272.1, 0.882], [14372.1, 3.318], [14472.1, 0.0], [51657.7, 0.0], [51658.0, 0.0], [58114.8, 0.067], [61343.5, 0.014], [61497.2, 0.001], [61989.2, 0.003], [63789.4, 9.056], [63926.4, 1.564], [64302.5, 5.945], [64438.0, 2.078], [64468.2, 0.002], [64468.3, 0.003], [64470.5, 10.018], [64507.8, 0.249], [64508.6, 0.85], [64512.6, 0.029], [64564.0, 0.133], [64564.3, 0.003], [64564.9, 0.14], [64567.4, 0.034], [64569.1, 0.085], [64572.1, 6.38]], "asks": [[64572.9, 0.937], [64573.5, 1.761], [64575.4, 0.088], [64577.8, 0.341], [64580.5, 9.541], [64583.0, 0.118], [64634.2, 0.422], [64636.0, 0.062], [64640.2, 3.533], [64642.5, 0.015], [64649.1, 37.325], [64659.8, 1.169], [64676.1, 10.122], [64711.6, 2.156], [64845.2, 5.136], [65217.9, 0.153]]}
{"kind": "depth", "E": 1787089589303, "U": 11315996018908, "u": 11315996025703, "recv_ms": 1787089589261, "bids": [[14272.1, 1.246], [14372.1, 2.954], [58114.8, 0.067], [61343.4, 0.0], [63572.1, 0.018], [63592.0, 0.639], [63926.4, 1.564], [64459.4, 0.003], [64494.6, 0.05], [64513.9, 0.047], [64564.0, 0.134], [64568.8, 0.233], [64570.1, 0.0], [64572.1, 6.377]], "asks": [[64572.2, 0.645], [64572.9, 0.002], [64577.4, 0.352], [64577.8, 0.077], [64579.9, 0.11], [64580.5, 9.542], [64580.6, 41.644], [64630.4, 1.237], [64642.5, 37.34], [64644.7, 0.001], [64649.1, 0.0], [64649.7, 0.001], [64684.4, 0.064], [64768.3, 10.738], [64827.9, 0.0], [64830.5, 0.001], [65217.9, 0.153], [65572.2, 0.002]]}
{"kind": "depth", "E": 1787089589405, "U": 11315996025802, "u": 11315996033076, "recv_ms": 1787089589362, "bids": [[14272.1, 1.596], [14372.1, 2.604], [58114.8, 0.067], [61343.4, 0.0], [61989.2, 0.0], [62376.6, 0.076], [63022.4, 0.511], [63280.7, 0.014], [63635.8, 19.112], [63638.2, 0.007], [63926.4, 1.564], [64249.2, 6.662], [64432.1, 3.582], [64460.1, 1.551], [64543.4, 2.007], [64554.2, 0.005], [64554.7, 0.121], [64555.6, 0.0], [64560.3, 0.467], [64560.5, 0.01], [64561.9, 0.666], [64564.0, 0.133], [64566.5, 0.002], [64566.7, 0.122], [64567.3, 0.096], [64569.6, 0.465], [64570.0, 0.122], [64570.5, 2.091], [64572.1, 6.377]], "asks": [[64572.2, 0.419], [64572.9, 0.002], [64573.2, 0.0], [64574.8, 0.196], [64576.3, 0.011], [64578.4, 0.007], [64580.3, 0.294], [64580.5, 9.541], [64596.1, 0.003], [64596.4, 0.597], [64596.9, 0.0], [64598.7, 0.021], [64681.9, 1.048], [64711.6, 0.096], [64712.6, 5.409], [64846.6, 0.015], [65217.9, 0.153], [65290.2, 1.531]]}
{"kind": "depth", "E": 1787089589507, "U": 11315996033327, "u": 11315996042619, "recv_ms": 1787089589464, "bids": [[1000.0, 35.76], [14272.1, 1.96], [14372.1, 2.24], [58114.8, 0.067], [61343.4, 0.0], [61989.2, 0.003], [63401.9, 0.792], [63572.1, 0.038], [63603.5, 2.117], [63709.3, 0.0], [63732.7, 8.185], [63926.4, 1.564], [64399.6, 0.051], [64399.7, 0.0], [64501.9, 0.016], [64502.0, 4.827], [64504.1, 30.387], [64505.5, 6.067], [64525.3, 0.228], [64528.5, 0.148], [64539.3, 0.001], [64540.5, 1.261], [64560.5, 0.002], [64563.1, 0.65], [64566.5, 0.002], [64567.3, 0.115], [64569.1, 0.001], [64570.0, 0.006], [64570.5, 0.001], [64570.6, 0.001], [64570.7, 0.001], [64570.8, 0.054], [64570.9, 0.0], [64571.0, 1.556], [64572.1, 6.381]], "asks": [[64573.2, 0.0], [64573.3, 0.0], [64578.4, 0.006], [64580.5, 9.542], [64583.1, 0.077], [64584.7, 0.003], [64586.6, 2.54], [64588.2, 0.54], [64610.5, 0.003], [64618.5, 0.06], [64727.6, 2.146], [64728.6, 0.0], [65217.9, 0.153], [65572.2, 0.022]]}
{"kind": "depth", "E": 1787089589609, "U": 11315996042728, "u": 11315996051404, "recv_ms": 1787089589574, "bids": [[14272.1, 2.31], [14372.1, 1.89], [51658.0, 0.0], [58114.8, 0.067], [61343.4, 0.0], [61989.2, 0.0], [63926.4, 1.564], [63971.6, 2.958], [64375.9, 0.001], [64376.4, 6.756], [64377.2, 0.001], [64383.3, 16.181], [64415.1, 6.529], [64422.1, 14.062], [64432.1, 3.68], [64459.4, 11.051], [64507.8, 4.6], [64510.1, 0.052], [64555.3, 0.626], [64560.2, 0.638], [64561.9, 0.124], [64563.1, 0.0], [64564.0, 0.133], [64566.5, 1.566], [64566.7, 0.764], [64567.3, 0.123], [64569.6, 0.641], [64570.8, 0.046], [64570.9, 0.0], [64571.0, 0.0], [64572.1, 6.361]], "asks": [[64572.2, 0.42], [64573.2, 0.0], [64573.3, 1.393], [64577.2, 0.008], [64577.3, 0.006], [64577.8, 0.069], [64578.4, 0.007], [64580.3, 0.294], [64580.5, 9.541], [64587.7, 0.007], [64589.1, 0.009], [64591.3, 1.256], [64594.4, 1.069], [64598.7, 0.64], [64600.1, 0.162], [64600.3, 0.008], [64620.3, 0.0], [64635.9, 1.984], [64684.3, 12.177], [64721.6, 15.688], [64755.6, 0.072], [64759.3, 2.99], [64760.4, 20.056], [64768.3, 11.396], [64799.8, 2.46], [64885.4, 0.057], [64895.1, 4.619], [65217.9, 0.153], [65347.1, 31.257], [65489.1, 1.369], [65647.1, 0.0]]}
{"kind": "depth", "E": 1787089589711, "U": 11315996051432, "u": 11315996058806, "recv_ms": 1787089589668, "bids": [[1000.0, 35.91], [14272.1, 2.674], [14372.1, 1.526], [51658.0, 0.0], [58114.8, 0.067], [61989.2, 0.003], [63572.1, 0.018], [63614.5, 5.612], [63926.4, 1.564], [64249.2, 6.662], [64447.4, 0.0], [64467.6, 2.326], [64495.3, 0.01], [64501.9, 0.016], [64504.1, 30.387], [64505.5, 2.142], [64539.1, 0.019], [64549.0, 0.002], [64549.6, 0.0], [64564.0, 0.134]], "asks": [[64573.2, 0.0], [64573.3, 1.393], [64577.2, 0.0], [64577.3, 0.941], [64577.8, 0.077], [64578.4, 0.006], [64579.9, 0.11], [64580.5, 9.542], [64589.1, 0.628], [64594.4, 0.45], [64675.5, 0.2], [64681.0, 2.324], [64681.1, 0.0], [65217.9, 0.153], [65572.2, 0.002]]}
{"kind": "depth", "E": 1787089589813, "U": 11315996058973, "u": 11315996066004, "recv_ms": 1787089589770, "bids": [[1000.0, 35.76], [14272.1, 3.024], [14372.1, 1.176], [51658.0, 0.0], [58114.8, 0.067], [63635.8, 20.211], [63676.8, 0.002], [63926.4, 1.564], [63991.0, 6.606], [64495.3, 0.01], [64501.9, 30.294], [64504.1, 0.043], [64525.3, 0.209], [64528.5, 0.129], [64549.4, 0.156], [64564.0, 0.134]], "asks": [[64573.2, 0.0], [64573.3, 0.0], [64576.0, 0.965], [64577.2, 0.0], [64577.3, 0.006], [64577.8, 0.069], [64577.9, 0.013], [64578.4, 0.006], [64580.3, 0.294], [64580.5, 9.541], [64580.6, 41.645], [64589.1, 0.628], [64594.4, 0.45], [64895.1, 4.773], [65217.9, 0.155], [65347.1, 31.944]]}
{"kind": "depth", "E": 1787089589915, "U": 11315996066072, "u": 11315996073638, "recv_ms": 1787089589872, "bids": [[14272.1, 3.388], [14372.1, 0.812], [58114.8, 0.067], [61343.4, 0.0], [61989.2, 0.0], [63280.7, 0.011], [63572.1, 0.038], [63853.9, 2.346], [63926.4, 1.564], [64249.2, 6.66], [64376.4, 6.888], [64415.1, 7.543], [64432.1, 4.189], [64507.8, 4.616], [64529.5, 0.006], [64530.7, 0.0], [64539.5, 0.029], [64539.6, 0.002], [64564.0, 0.134], [64570.5, 0.02], [64572.1, 6.362]], "asks": [[64572.2, 0.42], [64573.3, 1.393], [64600.1, 0.008], [64600.2, 0.168], [64617.3, 0.026], [64635.9, 1.984], [64712.6, 4.324], [64768.3, 9.784], [64895.1, 4.774], [65217.9, 0.153], [65572.2, 0.022], [65669.9, 8.889], [67800.8, 0.058]]}
{"kind": "depth", "E": 1787089590017, "U": 11315996073728, "u": 11315996081033, "recv_ms": 1787089589974, "bids": [[1000.0, 35.76], [14172.1, 0.028], [14272.1, 3.696], [14372.1, 0.476], [58114.8, 0.067], [61343.4, 0.0], [61989.2, 0.003], [63384.0, 0.677], [63926.4, 1.564], [64205.0, 0.013], [64206.8, 1.417], [64249.2, 6.65], [64301.4, 1.11], [64302.5, 1.087], [64372.3, 0.003], [64373.5, 0.802], [64501.9, 0.016], [64504.1, 30.321], [64555.3, 0.007], [64560.2, 0.638], [64561.9, 0.124], [64564.0, 0.133], [64572.1, 6.361]], "asks": [[64572.2, 0.419], [64573.2, 1.393], [64573.3, 0.0], [64577.4, 0.324], [64580.3, 0.294], [64589.1, 0.009], [64590.8, 0.542], [64591.3, 0.095], [64592.0, 0.026], [64594.4, 1.069], [64596.4, 0.04], [64596.9, 0.557], [64598.7, 0.021], [64600.1, 0.008], [64600.2, 0.322], [64771.5, 0.6], [64774.3, 0.0], [64845.2, 0.145], [64845.5, 0.091], [64895.1, 4.775], [64941.5, 0.112], [64943.6, 0.005], [65217.9, 0.153], [65347.1, 32.158], [67800.8, 0.053]]}
{"kind": "depth", "E": 1787089590119, "U": 11315996081131, "u": 11315996093932, "recv_ms": 1787089590078, "bids": [[1000.0, 35.76], [14172.1, 0.196], [14272.1, 3.71], [14372.1, 0.294], [58114.8, 0.067], [61343.6, 0.003], [61989.2, 0.0], [63550.0, 6.079], [63572.1, 0.018], [63588.3, 0.008], [63589.4, 0.285], [63614.5, 4.513], [63627.7, 0.0], [63700.4, 4.003], [63926.4, 1.564], [64363.0, 5.331], [64372.4, 0.005], [64513.4, 0.03], [64516.8, 0.618], [64520.8, 3.652], [64522.0, 0.163], [64522.1, 0.246], [64522.5, 0.106], [64524.5, 2.323], [64526.1, 0.001], [64526.6, 0.329], [64529.0, 0.0], [64529.5, 0.002], [64529.9, 0.001], [64530.9, 0.836], [64539.5, 0.004], [64539.6, 0.006], [64549.3, 0.159], [64549.4, 0.002], [64560.5, 0.002]], "asks": [[64573.2, 0.0], [64573.3, 0.0], [64577.8, 0.088], [64578.0, 2.612], [64606.0, 0.001], [64611.3, 0.062], [64613.5, 0.0], [64618.5, 0.0], [64619.3, 0.028], [64629.5, 0.012], [64630.0, 0.081], [64729.5, 0.026], [64729.6, 8.774], [64762.8, 1.965], [64774.2, 1.042], [64803.7, 7.934], [64922.0, 0.378], [65088.8, 9.542], [65185.6, 5.36], [65217.9, 0.153], [65340.6, 5.35], [65367.8, 0.764], [65549.9, 1.224], [65555.0, 76.254], [65556.1, 0.013], [65572.2, 0.002], [65863.6, 0.03]]}
{"kind": "depth", "E": 1787089590221, "U": 11315996094034, "u": 11315996102459, "recv_ms": 1787089590178, "bids": [[14172.1, 0.434], [14272.1, 3.598], [14372.1, 0.168], [51657.7, 0.0], [58114.8, 0.067], [61343.4, 0.0], [61989.2, 0.003], [63571.2, 12.107], [63588.3, 0.017], [63589.4, 0.293], [63635.8, 21.31], [63748.0, 2.332], [63926.4, 1.564], [63940.8, 0.001], [64055.5, 9.82], [64089.4, 0.0], [64399.1, 0.426], [64435.1, 1.541], [64473.4, 3.32], [64481.3, 0.012], [64493.6, 0.503], [64508.3, 0.122], [64509.7, 0.002], [64519.6, 0.008], [64522.5, 0.081], [64529.7, 0.097], [64572.1, 6.362]], "asks": [[64573.2, 0.0], [64573.3, 0.0], [64590.8, 0.0], [64591.3, 0.637], [64600.2, 0.322], [64600.3, 0.008], [64611.3, 0.002], [64617.8, 0.061], [64634.2, 0.697], [64675.5, 0.0], [64681.9, 2.814], [64711.6, 1.994], [65060.5, 0.0], [65088.8, 9.848], [65210.2, 1.22], [65217.9, 0.153], [65261.2, 0.144], [65318.8, 0.067], [65327.3, 9.52], [65555.0, 76.262], [65556.1, 0.022], [65573.1, 11.267]]}
{"kind": "depth", "E": 1787089590323, "U": 11315996102485, "u": 11315996109769, "recv_ms": 1787089590280, "bids": [[1000.0, 35.76], [14172.1, 0.672], [14272.1, 3.472], [14372.1, 0.056], [51658.0, 0.0], [58114.8, 0.067], [63280.7, 0.014], [63572.1, 0.038], [63594.6, 0.0], [63629.3, 1.489], [63748.0, 1.98], [63926.4, 1.564], [64205.0, 42.129], [64206.8, 7.449], [64249.2, 6.66], [64301.5, 34.378], [64302.5, 6.08], [64372.3, 27.411], [64564.5, 0.021], [64572.1, 6.36]], "asks": [[64573.2, 0.0], [64573.3, 1.393], [64600.2, 0.168], [64600.3, 0.162], [64774.0, 26.239], [64845.1, 5.055], [64845.2, 32.601], [64941.5, 6.377], [64942.5, 42.044], [65217.9, 0.153], [65340.6, 6.267], [65572.2, 0.022]]}
{"kind": "depth", "E": 1787089590425, "U": 11315996109855, "u": 11315996116998, "recv_ms": 1787089590384, "bids": [[1000.0, 35.76], [14172.1, 0.98], [14272.1, 3.22], [14372.1, 0.0], [58114.8, 0.067], [61343.4, 0.0], [61343.5, 0.016], [61989.2, 0.0], [63572.1, 0.018], [63748.0, 1.746], [63926.4, 1.564], [64089.4, 52.231], [64108.9, 0.0], [64363.0, 5.115], [64372.4, 0.221], [64508.1, 0.04], [64508.4, 0.003], [64508.7, 0.116], [64509.1, 0.118], [64509.4, 0.006], [64527.5, 0.416], [64527.8, 5.409], [64528.1, 0.042], [64528.4, 0.0], [64528.7, 0.003], [64542.4, 0.433], [64542.5, 0.001], [64542.6, 0.001], [64542.7, 0.0], [64542.8, 0.006], [64542.9, 0.39], [64543.0, 0.019], [64543.1, 2.322], [64543.3, 0.0], [64545.9, 2.32], [64546.4, 0.117], [64563.1, 0.0], [64564.0, 0.134], [64564.9, 0.0], [64565.0, 0.383], [64565.1, 0.001], [64565.2, 0.001], [64565.3, 0.155], [64565.4, 0.155], [64565.5, 0.1], [64565.6, 0.252], [64565.7, 0.0], [64565.8, 0.002], [64566.1, 0.003], [64566.4, 0.81], [64566.5, 0.002], [64566.7, 0.09], [64567.1, 0.458], [64567.3, 0.123], [64567.4, 0.002], [64570.0, 2.212], [64572.1, 6.358]], "asks": [[64572.2, 0.42], [64573.1, 0.01], [64573.2, 0.0], [64573.3, 1.393], [64582.1, 0.083], [64582.4, 0.028], [64582.7, 0.004], [64583.1, 0.003], [64583.4, 0.432], [64583.6, 0.003], [64583.8, 0.002], [64583.9, 1.095], [64584.0, 2.327], [64584.1, 0.452], [64584.2, 0.0], [64584.3, 0.004], [64584.4, 0.494], [64584.5, 0.004], [64584.6, 0.0], [64589.1, 0.628], [64594.4, 0.45], [64596.1, 0.56], [64596.9, 0.0], [64601.4, 1.341], [64601.8, 0.006], [64602.1, 0.019], [64602.4, 0.005], [64602.7, 0.0], [64603.1, 0.004], [64603.5, 0.033], [64605.1, 0.946], [64606.1, 0.311], [64606.4, 0.654], [64606.5, 0.016], [64606.6, 0.141], [64606.7, 0.018], [64606.8, 0.001], [64606.9, 0.14], [64607.0, 2.353], [64607.1, 0.118], [64620.8, 0.082], [64621.1, 0.389], [64621.4, 0.011], [64621.7, 0.0], [64622.1, 0.0], [64729.5, 10.454], [64729.6, 1.378], [64773.9, 0.219], [64803.7, 7.718], [65059.4, 52.085], [65217.9, 0.153], [65276.0, 4.904], [65340.6, 7.184], [65347.1, 30.935], [65572.2, 0.002]]}
{"kind": "depth", "E": 1787089590527, "U": 11315996117081, "u": 11315996124077, "recv_ms": 1787089590485, "bids": [[14172.1, 1.33], [14272.1, 2.87], [58114.8, 0.067], [61343.4, 0.0], [61989.2, 0.003], [63614.5, 3.414], [63764.9, 8.132], [63802.5, 0.783], [63803.7, 5.086], [63926.4, 1.564], [64494.6, 0.047], [64513.9, 0.05], [64527.6, 0.037], [64527.9, 2.63], [64528.5, 0.161], [64528.9, 0.032], [64555.3, 0.626], [64563.1, 0.65], [64564.0, 0.133], [64565.1, 0.071], [64565.2, 0.071], [64565.4, 0.255], [64565.5, 0.2], [64565.6, 0.352], [64565.8, 0.172], [64566.2, 0.037], [64566.5, 0.034], [64567.2, 0.313], [64567.3, 0.115], [64567.5, 0.032], [64569.6, 0.465], [64569.9, 2.32], [64570.0, 0.014], [64570.1, 0.0], [64570.5, 0.02], [64570.6, 0.001], [64570.7, 0.001], [64570.8, 1.602], [64572.1, 6.358]], "asks": [[64573.2, 0.0], [64573.3, 1.393], [64580.3, 0.094], [64581.8, 0.069], [64582.2, 0.069], [64582.8, 0.074], [64583.1, 0.067], [64583.5, 0.725], [64583.6, 0.15], [64583.7, 0.25], [64583.9, 1.345], [64584.0, 2.597], [64584.2, 0.147], [64584.3, 0.137], [64589.0, 0.624], [64589.1, 0.009], [64591.3, 1.256], [64594.4, 0.45], [64598.7, 0.64], [64601.2, 0.094], [64601.5, 1.771], [64602.1, 0.093], [64602.5, 0.075], [64602.9, 1.262], [64603.3, 0.309], [64605.1, 1.192], [64606.1, 0.458], [64606.3, 0.284], [64606.4, 0.904], [64606.7, 0.165], [64606.8, 0.134], [64620.5, 0.093], [64620.8, 0.149], [64621.5, 0.074], [64621.8, 0.068], [64630.4, 1.234], [64649.7, 0.004], [64675.5, 0.2], [64712.6, 5.409], [64729.5, 10.454], [64729.6, 1.378], [64766.0, 0.093], [65217.9, 0.153], [65347.1, 32.464], [65484.1, 6.409], [65508.5, 24.348], [67800.8, 0.058]]}
{"kind": "depth", "E": 1787089590629, "U": 11315996124401, "u": 11315996130640, "recv_ms": 1787089590586, "bids": [[1000.0, 35.76], [14172.1, 1.68], [14272.1, 2.52], [58114.8, 0.067], [61343.4, 0.0], [61343.5, 0.014], [61343.6, 0.005], [61989.2, 0.0], [63603.5, 2.47], [63926.4, 1.564], [64249.2, 6.65], [64432.1, 0.022], [64435.1, 0.986], [64528.2, 0.093], [64555.3, 0.626], [64563.1, 0.0], [64564.1, 0.003], [64565.1, 0.141], [64565.3, 0.255], [64565.7, 0.1], [64566.5, 1.598], [64566.7, 0.732], [64566.8, 0.032], [64567.3, 0.123], [64569.6, 0.641], [64570.0, 0.006], [64570.8, 0.046], [64570.9, 0.0], [64572.1, 6.357]], "asks": [[64572.2, 0.423], [64573.2, 0.0], [64573.3, 1.393], [64578.7, 0.002], [64578.8, 0.001], [64580.3, 0.294], [64582.5, 0.084], [64583.6, 0.43], [64584.0, 2.867], [64584.3, 0.284], [64587.7, 0.007], [64601.8, 0.089], [64606.2, 0.282], [64606.5, 0.286], [64606.8, 0.281], [64621.1, 0.472], [64711.6, 0.096], [64712.6, 0.0], [65217.9, 0.153], [67800.8, 0.053]]}
{"kind": "depth", "E": 1787089590731, "U": 11315996130869, "u": 11315996137050, "recv_ms": 1787089590688, "bids": [[1000.0, 35.76], [14172.1, 2.044], [14272.1, 2.156], [58114.8, 0.067], [61343.4, 0.0], [63572.1, 0.038], [63635.8, 22.409], [63803.7, 6.025], [63804.2, 0.0], [63926.4, 1.564], [64415.1, 6.487], [64416.0, 1.263], [64432.1, 3.94], [64436.1, 0.002], [64540.2, 7.025], [64543.4, 0.007], [64564.1, 0.002], [64564.3, 0.0], [64565.2, 0.141], [64565.6, 0.422], [64566.0, 0.346], [64572.1, 6.322]], "asks": [[64572.2, 0.424], [64573.2, 0.0], [64573.3, 0.0], [64583.4, 0.593], [64583.8, 0.128], [64584.2, 0.301], [64605.9, 0.162], [64606.3, 0.41], [64606.7, 0.319], [64675.5, 0.0], [64712.6, 5.409], [64727.6, 0.001], [64729.5, 10.454], [64758.8, 0.172], [64758.9, 0.019], [64768.2, 11.297], [64768.3, 0.001], [65217.9, 0.153], [65347.1, 33.687], [65572.2, 0.022], [71029.5, 0.0]]}
{"kind": "depth", "E": 1787089590833, "U": 11315996137110, "u": 11315996144954, "recv_ms": 1787089590791, "bids": [[14172.1, 2.394], [14272.1, 1.806], [58114.8, 0.067], [61989.2, 0.003], [63926.4, 1.564], [64438.0, 0.408], [64457.2, 4.17], [64495.3, 0.01], [64501.4, 0.047], [64501.9, 30.263], [64504.1, 0.043], [64508.2, 0.033], [64508.6, 0.882], [64509.2, 0.032], [64509.5, 0.033], [64510.1, 0.024], [64540.5, 2.171], [64542.5, 0.071], [64542.8, 0.076], [64543.0, 0.119], [64555.3, 0.007], [64571.8, 0.546], [64572.1, 6.359]], "asks": [[64572.2, 0.44], [64573.2, 0.0], [64573.3, 0.0], [64580.3, 0.294], [64583.0, 0.117], [64589.0, 0.005], [64591.3, 0.637], [64594.4, 1.069], [64598.7, 0.021], [64643.6, 0.046], [64675.5, 0.2], [64711.7, 0.013], [64712.0, 5.6], [65217.9, 0.153], [65508.5, 25.414], [65863.6, 0.033], [71029.5, 0.0]]}
{"kind": "depth", "E": 1787089590935, "U": 11315996145037, "u": 11315996151445, "recv_ms": 1787089590892, "bids": [[1000.0, 35.76], [14172.1, 2.758], [14272.1, 1.442], [58114.8, 0.067], [61343.4, 0.0], [61343.5, 0.016], [61989.2, 0.0], [63572.1, 0.018], [63926.4, 1.564], [64249.2, 6.66], [64456.6, 4.322], [64508.9, 0.311], [64512.6, 0.001], [64542.6, 0.071], [64542.7, 0.07], [64542.8, 0.176], [64542.9, 0.49], [64543.1, 2.422], [64543.3, 0.07], [64546.1, 0.101], [64546.5, 0.104], [64549.1, 0.154], [64549.3, 0.005], [64564.9, 0.003], [64572.1, 6.359]], "asks": [[64572.2, 0.397], [64573.2, 1.393], [64573.3, 0.0], [64580.3, 0.094], [64601.1, 0.392], [64601.2, 0.092], [64601.3, 2.321], [64604.1, 0.002], [64604.2, 2.321], [64604.3, 1.133], [64605.0, 0.001], [64605.1, 1.19], [64605.2, 0.164], [64607.1, 0.116], [64607.2, 0.066], [64607.3, 0.016], [64895.1, 4.774], [65217.9, 0.153], [65572.2, 0.002], [65863.6, 0.03], [71029.5, 0.0]]}
{"kind": "depth", "E": 1787089591037, "U": 11315996151639, "u": 11315996159138, "recv_ms": 1787089590994, "bids": [[1000.0, 35.76], [14172.1, 3.122], [14272.1, 1.078], [58114.8, 0.067], [61343.4, 0.0], [61989.2, 0.003], [63603.6, 0.013], [63926.4, 1.564], [63942.0, 68.356], [64249.2, 6.662], [64540.2, 0.11], [64540.5, 1.261], [64542.5, 0.141], [64542.7, 0.14], [64543.2, 2.18], [64544.2, 2.001], [64560.5, 0.007], [64572.1, 6.356]], "asks": [[64572.2, 0.395], [64573.2, 0.0], [64573.3, 1.393], [64599.8, 0.19], [64600.3, 0.008], [64895.1, 4.773], [65210.2, 65.578], [65217.9, 0.153], [65335.1, 3.058], [65605.4, 4.264], [65863.6, 0.027]]}
{"kind": "depth", "E": 1787089591139, "U": 11315996159234, "u": 11315996167070, "recv_ms": 1787089591096, "bids": [[14172.1, 3.472], [14272.1, 0.728], [58114.8, 0.067], [61989.2, 0.0], [63572.1, 0.038], [63587.9, 0.785], [63588.1, 0.795], [63588.3, 0.009], [63653.1, 0.05], [63655.2, 1.652], [63655.4, 0.001], [63926.4, 1.564], [64501.9, 0.016], [64504.1, 30.29], [64521.9, 0.003], [64524.8, 1.496], [64543.1, 2.492], [64543.4, 0.077], [64560.5, 0.002]], "asks": [[64573.3, 1.393], [64584.7, 0.004], [64599.7, 0.041], [64599.8, 0.19], [65166.0, 1.797], [65217.9, 0.153], [65361.9, 0.641], [65489.0, 0.85], [65491.3, 0.002], [65556.1, 0.014], [65556.5, 0.0], [65572.2, 0.022]]}
{"kind": "depth", "E": 1787089591241, "U": 11315996167119, "u": 11315996173993, "recv_ms": 1787089591199, "bids": [[1000.0, 35.76], [14072.1, 0.056], [14172.1, 3.724], [14272.1, 0.42], [51657.7, 0.0], [51658.0, 0.0], [58114.8, 0.067], [61343.4, 0.0], [63587.2, 0.015], [63587.8, 0.016], [63603.6, 0.021], [63641.2, 0.785], [63653.0, 0.843], [63655.3, 0.008], [63926.4, 1.564], [64249.2, 6.507], [64383.8, 2.643], [64416.0, 2.037], [64438.0, 1.441], [64460.1, 2.746], [64505.5, 6.052], [64507.9, 0.16], [64508.9, 0.059], [64520.4, 0.254], [64521.8, 0.226], [64529.7, 0.072], [64539.4, 0.03], [64546.3, 0.116], [64572.1, 6.357]], "asks": [[64573.2, 0.0], [64573.3, 1.393], [64599.1, 0.0], [64599.8, 0.036], [64599.9, 0.783], [64640.2, 3.533], [64642.5, 0.015], [64644.7, 37.353], [64649.1, 0.0], [64675.4, 2.199], [64711.9, 2.057], [64761.6, 0.685], [65217.9, 0.153], [65488.9, 0.01], [65491.2, 0.021], [65556.0, 0.481], [65556.4, 0.014], [65863.6, 0.024], [67800.8, 0.053]]}
{"kind": "depth", "E": 1787089591343, "U": 11315996174043, "u": 11315996180748, "recv_ms": 1787089591301, "bids": [[1000.0, 35.76], [14072.1, 0.252], [14172.1, 3.682], [14272.1, 0.266], [58114.8, 0.067], [61343.4, 0.0], [61989.2, 0.003], [63572.1, 0.018], [63576.5, 0.785], [63706.0, 0.0], [63803.7, 5.086], [63926.4, 1.564], [64055.5, 5.924], [64572.1, 6.357]], "asks": [[64572.2, 0.394], [64573.2, 1.393], [64573.3, 0.0], [64642.5, 37.367], [64644.7, 0.001], [65185.6, 5.972], [65217.9, 0.153], [65393.2, 0.001], [65508.5, 24.347], [65572.2, 0.002], [65605.4, 5.33], [71029.5, 0.0]]}
{"kind": "depth", "E": 1787089591445, "U": 11315996180840, "u": 11315996188752, "recv_ms": 1787089591403, "bids": [[14072.1, 0.49], [14172.1, 3.57], [14272.1, 0.14], [51658.0, 0.0], [58114.8, 0.067], [61343.4, 0.0], [61343.6, 0.003], [61989.2, 0.0], [63464.6, 0.054], [63572.1, 0.038], [63926.4, 1.564], [64249.2, 6.662], [64432.1, 3.867], [64507.5, 0.419], [64510.1, 0.052], [64564.9, 0.0], [64566.7, 0.647], [64567.3, 0.2], [64567.4, 0.01], [64572.1, 6.323]], "asks": [[64572.2, 0.438], [64573.2, 0.0], [64573.3, 0.0], [64580.3, 0.294], [64636.8, 0.009], [64712.5, 5.41], [64712.6, 0.0], [65198.2, 0.031], [65217.9, 0.153], [65347.1, 33.076], [65521.0, 0.172], [65572.2, 0.022], [65863.6, 0.027], [66162.8, 0.235]]}
{"kind": "depth", "E": 1787089591547, "U": 11315996188790, "u": 11315996194105, "recv_ms": 1787089591504, "bids": [[1000.0, 35.76], [14072.1, 0.728], [14172.1, 3.444], [14272.1, 0.028], [58114.8, 0.067], [61343.4, 0.0], [61989.2, 0.003], [63022.4, 0.526], [63597.0, 0.275], [63926.4, 1.564], [64055.5, 9.82], [64249.2, 6.662], [64494.6, 0.05], [64572.1, 6.357]], "asks": [[64572.2, 0.465], [64594.3, 0.001], [64594.7, 0.003], [64630.4, 1.237], [65217.9, 0.153], [65657.8, 3.046]]}
{"kind": "depth", "E": 1787089591649, "U": 11315996194264, "u": 11315996199545, "recv_ms": 1787089591606, "bids": [[1000.0, 35.76], [14072.1, 1.064], [14172.1, 3.136], [14272.1, 0.0], [58114.8, 0.067], [58114.9, 0.002], [63705.7, 7.841], [63803.7, 5.086], [63926.4, 1.564], [64555.3, 0.005]], "asks": [[64587.7, 0.005], [64599.9, 0.629], [64600.0, 1.094], [65217.9, 1.53], [65347.1, 33.687], [65399.7, 1.528], [65413.6, 1.527], [65508.5, 24.347], [65540.8, 4.9], [65573.1, 10.201], [67800.8, 0.048]]}
{"kind": "depth", "E": 1787089591751, "U": 11315996199599, "u": 11315996205578, "recv_ms": 1787089591709, "bids": [[14072.1, 1.414], [14172.1, 2.786], [58114.8, 0.067], [58114.9, 0.0], [61343.4, 0.0], [61989.2, 0.0], [63403.2, 2.025], [63572.1, 0.018], [63926.4, 1.564], [64415.1, 0.0], [64416.0, 1.263], [64432.1, 0.022], [64495.3, 30.257], [64501.9, 0.001], [64504.1, 0.043], [64505.5, 2.142], [64510.1, 0.024], [64512.6, 0.015], [64537.5, 0.928], [64540.3, 6.915], [64544.6, 0.16], [64544.7, 0.12], [64548.9, 0.465], [64549.1, 0.0], [64554.7, 0.74], [64555.3, 0.007], [64567.3, 0.261], [64572.1, 6.297]], "asks": [[64572.2, 0.468], [64587.7, 0.007], [64589.1, 0.001], [64589.3, 1.105], [64590.1, 0.367], [64590.7, 1.373], [64591.2, 0.242], [64598.1, 1.124], [64711.9, 0.0], [64712.5, 0.001], [64729.5, 0.026], [65217.9, 1.53], [65572.2, 0.002], [66186.5, 1.131]]}
{"kind": "depth", "E": 1787089591853, "U": 11315996205786, "u": 11315996212146, "recv_ms": 1787089591811, "bids": [[1000.0, 35.76], [14072.1, 1.764], [14172.1, 2.436], [51658.0, 0.0], [58114.8, 0.067], [61343.5, 0.018], [61989.2, 0.003], [63572.1, 0.038], [63803.7, 6.025], [63926.4, 1.564], [64249.2, 6.652], [64376.4, 0.0], [64462.3, 0.433], [64494.6, 0.047], [64495.3, 0.01], [64501.9, 30.248], [64513.9, 0.047], [64540.3, 0.0]], "asks": [[64572.2, 0.468], [64597.2, 10.093], [64601.2, 0.094], [64604.1, 0.004], [64604.2, 2.323], [64604.3, 1.135], [64605.0, 0.003], [64605.1, 1.192], [64605.2, 0.166], [64607.1, 0.118], [64607.2, 0.068], [64607.3, 0.018], [64630.4, 1.237], [64640.3, 38.846], [64642.5, 0.015], [64649.7, 0.001], [64768.2, 0.0], [65217.9, 1.53], [65379.4, 7.469], [65508.5, 25.414], [65572.2, 0.022], [65573.1, 11.267]]}
{"kind": "depth", "E": 1787089591955, "U": 11315996212172, "u": 11315996217997, "recv_ms": 1787089591913, "bids": [[1000.0, 35.76], [14072.1, 2.128], [14172.1, 2.072], [58114.8, 0.067], [61343.4, 0.0], [61989.2, 0.0], [63748.0, 1.512], [63764.9, 8.483], [63926.4, 1.564], [64376.4, 6.518], [64415.1, 7.381], [64432.1, 4.392], [64501.9, 0.001], [64504.1, 30.23], [64510.1, 0.038], [64521.3, 0.019], [64572.1, 6.294]], "asks": [[64601.1, 0.394], [64601.3, 2.323], [64640.3, 1.473], [64642.5, 37.388], [64646.9, 0.0], [64712.5, 5.41], [64729.5, 10.454], [64768.2, 10.094], [65217.9, 1.532], [65863.6, 0.024]]}
{"kind": "depth", "E": 1787089592057, "U": 11315996218064, "u": 11315996224636, "recv_ms": 1787089592014, "bids": [[14072.1, 2.478], [14172.1, 1.722], [58114.8, 0.067], [61343.4, 0.0], [61989.2, 0.003], [63764.9, 8.717], [63926.4, 1.564], [64249.2, 6.65], [64432.1, 3.753], [64548.9, 0.311], [64549.0, 0.002], [64560.5, 0.002]], "asks": [[64572.2, 0.469], [64712.5, 5.41], [64762.8, 0.0], [65217.9, 1.53]]}
{"kind": "depth", "E": 1787089592159, "U": 11315996224861, "u": 11315996231422, "recv_ms": 1787089592116, "bids": [[1000.0, 35.76], [14072.1, 2.842], [14172.1, 1.358], [51658.0, 0.0], [58114.8, 0.067], [61343.4, 0.0], [63572.1, 0.018], [63926.4, 1.564], [64120.1, 0.084], [64249.2, 6.66], [64521.9, 0.004], [64524.8, 1.497], [64525.6, 0.014], [64548.9, 0.465], [64572.1, 6.295]], "asks": [[64573.4, 0.782], [64577.4, 0.344], [64577.6, 0.026], [64761.6, 0.437], [64895.1, 4.621], [65166.0, 1.032], [65217.9, 1.53], [65456.4, 7.786], [65572.2, 0.002], [65863.6, 0.027]]}
{"kind": "depth", "E": 1787089592261, "U": 11315996231525, "u": 11315996238478, "recv_ms": 1787089592218, "bids": [[1000.0, 35.76], [14072.1, 3.206], [14172.1, 0.994], [51657.7, 0.0], [51658.0, 0.0], [58114.8, 0.067], [61989.2, 0.0], [63589.4, 0.283], [63738.0, 2.354], [63764.9, 8.951], [63821.5, 0.782], [63926.4, 1.564], [64055.5, 9.509], [64256.3, 0.007], [64267.9, 0.053], [64373.5, 4.822], [64416.0, 2.17], [64435.1, 1.476], [64442.9, 0.003], [64443.1, 0.707], [64505.5, 6.043]], "asks": [[64595.5, 3.297], [64640.2, 3.533], [64642.5, 0.015], [64649.1, 37.373], [64711.9, 2.057], [64762.8, 1.799], [64772.2, 5.312], [65217.9, 1.53], [65459.5, 0.001], [65549.6, 2.134], [65555.0, 76.252], [67800.8, 0.053], [71029.5, 0.0]]}
{"kind": "depth", "E": 1787089592363, "U": 11315996238558, "u": 11315996246014, "recv_ms": 1787089592321, "bids": [[14072.1, 3.542], [14172.1, 0.658], [58114.8, 0.067], [61343.4, 0.0], [61343.5, 0.016], [61343.6, 0.005], [61989.2, 0.003], [63572.1, 0.038], [63926.4, 1.564], [64350.8, 0.098], [64432.1, 4.252], [64467.4, 2.39], [64467.6, 0.003], [64468.3, 0.0], [64468.4, 0.003], [64505.5, 6.045], [64506.5, 0.028], [64510.1, 0.024], [64525.6, 0.0], [64528.1, 0.069], [64544.2, 0.001], [64545.1, 0.0], [64546.9, 0.006], [64547.3, 0.057], [64554.7, 0.005], [64555.9, 0.502], [64556.0, 0.119], [64556.9, 0.559], [64557.6, 0.002], [64558.7, 0.066], [64560.1, 0.002], [64560.2, 0.096], [64561.4, 0.929], [64561.9, 0.666], [64566.0, 0.349], [64567.4, 1.811], [64568.8, 0.001], [64569.4, 0.234], [64569.6, 0.994], [64572.1, 7.73]], "asks": [[64572.2, 0.388], [64573.2, 0.0], [64573.4, 0.086], [64573.5, 0.0], [64573.6, 0.0], [64576.4, 0.084], [64577.4, 0.322], [64577.6, 0.003], [64577.8, 0.069], [64578.0, 2.59], [64578.7, 0.004], [64580.3, 0.094], [64580.5, 7.222], [64590.7, 0.754], [64591.3, 0.095], [64592.0, 0.568], [64596.1, 0.003], [64597.2, 10.65], [64598.1, 0.505], [64598.2, 0.0], [64598.7, 0.014], [64599.2, 0.064], [64629.4, 4.631], [64630.4, 1.235], [64642.5, 37.388], [64649.1, 0.0], [64680.9, 2.323], [64681.0, 0.001], [64712.5, 0.001], [64712.6, 5.409], [64895.1, 4.775], [65217.9, 1.53], [65361.9, 0.413], [65572.2, 0.022]]}
{"kind": "depth", "E": 1787089592465, "U": 11315996246133, "u": 11315996252945, "recv_ms": 1787089592423, "bids": [[1000.0, 35.76], [14072.1, 3.766], [14172.1, 0.364], [14472.1, 0.07], [58114.8, 0.067], [61989.2, 0.0], [63280.7, 0.017], [63589.3, 0.017], [63797.2, 30.049], [63926.4, 1.564], [64249.2, 6.65], [64486.0, 0.031], [64493.0, 0.043], [64495.3, 0.01], [64501.9, 30.188], [64504.1, 0.043], [64504.8, 0.219], [64505.5, 2.144], [64527.1, 0.073], [64534.1, 0.0], [64545.5, 6.936], [64547.1, 2.103], [64547.4, 0.087], [64548.9, 0.311], [64549.4, 0.156], [64557.7, 0.0], [64558.8, 0.007], [64558.9, 0.001], [64559.0, 0.001], [64563.1, 0.008], [64566.5, 0.034], [64566.7, 0.09], [64567.3, 0.115], [64567.4, 0.002], [64569.0, 0.233], [64569.4, 0.002], [64569.6, 0.467], [64569.9, 2.321], [64570.0, 0.648], [64570.1, 0.016], [64570.5, 1.568], [64572.1, 6.639]], "asks": [[64572.2, 0.388], [64573.2, 0.0], [64573.3, 0.0], [64574.5, 0.737], [64574.6, 1.887], [64576.0, 1.442], [64576.2, 0.377], [64577.2, 0.008], [64577.3, 1.717], [64577.4, 0.198], [64577.9, 0.005], [64579.9, 0.111], [64580.3, 0.294], [64580.6, 41.644], [64592.0, 0.026], [64592.5, 0.543], [64595.5, 1.962], [64597.2, 0.65], [64599.9, 10.629], [64642.5, 0.015], [64649.1, 37.373], [64830.5, 0.111], [65185.6, 6.737], [65217.9, 1.53], [65476.2, 30.441]]}
{"kind": "depth", "E": 1787089592567, "U": 11315996253227, "u": 11315996259670, "recv_ms": 1787089592526, "bids": [[1000.0, 35.76], [14072.1, 3.654], [14172.1, 0.238], [14472.1, 0.308], [58114.8, 0.067], [61343.4, 0.0], [61989.2, 0.003], [63572.1, 0.018], [63635.8, 21.31], [63723.7, 0.032], [63926.4, 1.564], [64055.5, 9.82], [64391.1, 10.679], [64393.6, 2.835], [64501.9, 0.001], [64504.1, 30.23], [64513.9, 0.05], [64515.2, 0.335], [64545.3, 0.143], [64549.2, 0.155], [64549.4, 0.002], [64563.1, 0.0], [64566.5, 1.582], [64566.7, 0.671], [64567.3, 0.2], [64569.6, 0.738], [64569.9, 2.32], [64570.0, 0.006], [64570.1, 0.0], [64570.5, 0.02], [64570.6, 0.001], [64572.1, 6.637]], "asks": [[64573.4, 0.002], [64573.6, 0.0], [64573.7, 1.393], [64574.4, 0.004], [64579.9, 0.111], [64580.5, 7.222], [64639.4, 0.216], [64642.5, 37.388], [64649.1, 0.0], [64649.7, 0.004], [64675.5, 0.0], [65160.5, 5.093], [65217.9, 1.53], [65218.0, 2.653], [65363.4, 0.994], [65365.2, 0.0], [65554.9, 0.012], [65572.2, 0.002], [65573.1, 11.875], [65818.1, 1.05]]}
{"kind": "depth", "E": 1787089592669, "U": 11315996259849, "u": 11315996268159, "recv_ms": 1787089592626, "bids": [[14072.1, 3.556], [14172.1, 0.112], [14472.1, 0.532], [58114.8, 0.067], [61343.5, 0.014], [61343.6, 0.007], [63926.4, 1.564], [64432.1, 4.343], [64435.1, 0.986], [64495.3, 0.01], [64501.9, 30.188], [64504.1, 0.043], [64535.8, 0.001], [64544.9, 0.168], [64545.9, 2.322], [64546.6, 0.058], [64547.3, 0.0], [64549.5, 2.972], [64555.3, 0.005], [64555.4, 0.117], [64556.0, 0.003], [64556.4, 0.558], [64556.9, 0.001], [64560.9, 0.928], [64561.4, 0.002], [64563.1, 0.008], [64565.3, 0.171], [64566.5, 0.034], [64566.7, 0.632], [64567.3, 0.115], [64569.3, 0.084], [64569.6, 0.822], [64570.0, 1.593], [64570.1, 0.077], [64570.9, 0.31], [64572.1, 6.64]], "asks": [[64572.2, 0.345], [64573.7, 0.0], [64573.8, 1.393], [64573.9, 0.0], [64574.3, 0.001], [64574.4, 0.004], [64576.2, 0.374], [64577.2, 0.092], [64577.5, 0.084], [64580.0, 0.106], [64587.7, 0.005], [64599.9, 0.629], [64606.4, 5.989], [64675.5, 0.2], [64711.9, 0.0], [64712.5, 5.41], [64712.6, 0.0], [64768.2, 10.602], [65217.9, 1.53], [65508.5, 24.347]]}
{"kind": "depth", "E": 1787089592771, "U": 11315996268349, "u": 11315996274575, "recv_ms": 1787089592730, "bids": [[1000.0, 35.76], [14072.1, 3.416], [14172.1, 0.0], [14472.1, 0.784], [58114.8, 0.067], [61989.2, 0.0], [63572.1, 0.038], [63635.8, 22.409], [63732.7, 8.498], [63926.4, 1.564], [64249.2, 6.66], [64555.3, 0.007], [64563.1, 0.65], [64566.5, 1.598], [64566.7, 0.09], [64567.3, 0.115], [64569.6, 0.551], [64570.0, 0.006], [64570.1, 0.0], [64570.5, 0.02], [64570.6, 0.001], [64570.7, 0.001], [64571.0, 0.0], [64571.1, 0.0], [64571.8, 0.785]], "asks": [[64573.7, 1.393], [64573.8, 0.0], [64579.9, 0.111], [64580.5, 7.222], [64587.7, 0.007], [65217.9, 1.53], [65334.7, 0.039], [65355.0, 5.711], [65572.2, 0.022]]}
{"kind": "depth", "E": 1787089592873, "U": 11315996274749, "u": 11315996280872, "recv_ms": 1787089592834, "bids": [[1000.0, 35.76], [14072.1, 3.052], [14472.1, 1.148], [58114.8, 0.067], [61343.4, 0.0], [61989.2, 0.003], [63280.7, 0.014], [63926.4, 1.564], [64539.3, 0.003], [64539.4, 0.032], [64539.5, 0.006], [64542.8, 0.178], [64542.9, 0.492], [64543.0, 0.121], [64545.5, 0.021], [64547.1, 1.213], [64547.9, 0.97], [64548.8, 0.7], [64549.2, 0.001], [64555.3, 0.626], [64563.1, 0.0], [64566.7, 0.732], [64567.3, 0.123], [64569.6, 0.835], [64571.8, 0.546], [64572.1, 6.638]], "asks": [[64573.7, 0.0], [64573.8, 0.0], [64580.0, 0.149], [64591.3, 0.714], [64598.6, 0.62], [65508.5, 25.414], [65513.5, 0.535], [65605.4, 4.264], [68500.0, 33.664]]}
{"kind": "depth", "E": 1787089592975, "U": 11315996280882, "u": 11315996286804, "recv_ms": 1787089592933, "bids": [[14072.1, 2.702], [14472.1, 1.498], [58114.8, 0.067], [61989.2, 0.0], [63572.1, 0.018], [63595.5, 2.338], [63660.2, 3.137], [63926.4, 1.564], [64384.7, 2.321], [64432.1, 0.022], [64438.5, 2.388], [64501.9, 0.001], [64504.1, 30.23], [64532.4, 0.316], [64572.1, 6.637]], "asks": [[64572.2, 0.345], [64573.7, 1.393], [64573.8, 0.0], [64579.9, 0.111], [64580.0, 0.158], [64580.5, 7.222], [64712.5, 0.001], [65217.9, 1.53], [65379.4, 7.697], [65572.2, 0.002]]}
{"kind": "depth", "E": 1787089593077, "U": 11315996286939, "u": 11315996293288, "recv_ms": 1787089593034, "bids": [[1000.0, 35.76], [14072.1, 2.352], [14472.1, 1.848], [58114.8, 0.067], [61989.2, 0.003], [63572.1, 0.038], [63926.4, 1.566], [64249.2, 6.66], [64432.1, 4.343], [64444.4, 0.424], [64450.6, 3.764], [64453.1, 0.008], [64462.3, 0.43], [64491.0, 1.403], [64494.6, 0.05], [64513.9, 0.047], [64535.9, 0.336], [64541.0, 3.584], [64547.8, 0.001], [64547.9, 1.007], [64550.2, 1.045], [64560.5, 0.002], [64572.1, 6.636]], "asks": [[64572.2, 0.323], [64573.7, 0.0], [64573.8, 0.0], [64579.9, 0.111], [64580.3, 0.094], [64580.5, 7.222], [64630.4, 1.235], [64649.7, 0.001], [64712.5, 5.41], [65217.9, 1.532], [65521.4, 5.957], [65572.2, 0.022], [65863.6, 0.03], [67800.8, 0.049]]}
{"kind": "depth", "E": 1787089593179, "U": 11315996293294, "u": 11315996298476, "recv_ms": 1787089593140, "bids": [[1000.0, 35.76], [14072.1, 2.002], [14472.1, 2.198], [51658.0, 0.0], [58114.8, 0.067], [61343.4, 0.0], [63487.3, 3.605], [63552.0, 0.767], [63725.0, 1.697], [63926.4, 1.564], [64249.2, 6.505], [64376.5, 1.26], [64435.1, 1.564], [64505.5, 6.07], [64521.8, 0.227], [64521.9, 0.003], [64524.8, 1.496], [64547.9, 0.388], [64555.3, 0.007], [64561.9, 0.124], [64563.0, 1.857], [64572.1, 6.636]], "asks": [[64573.7, 1.393], [64573.8, 0.0], [64579.9, 0.11], [64580.0, 0.159], [64580.6, 41.644], [64582.7, 0.004], [64584.7, 0.003], [64591.3, 0.095], [64593.4, 0.001], [64593.9, 1.156], [64598.3, 0.154], [64598.6, 0.001], [64598.8, 0.15], [64605.1, 2.168], [64611.0, 3.815], [64611.2, 0.161], [64640.2, 9.958], [64711.9, 2.057], [64761.6, 0.66], [64895.1, 4.773], [65217.9, 1.53], [65340.6, 6.267], [65508.5, 24.347], [65605.4, 4.264]]}
{"kind": "depth", "E": 1787089593281, "U": 11315996298564, "u": 11315996305162, "recv_ms": 1787089593246, "bids": [[14072.1, 1.638], [14472.1, 2.562], [51657.7, 0.0], [58114.8, 0.067], [61989.2, 0.0], [63280.7, 0.011], [63571.2, 13.05], [63926.4, 1.564], [64502.3, 6.0]], "asks": [[64573.7, 0.0], [64574.4, 0.004], [64578.4, 0.007], [64580.0, 0.158], [64580.6, 41.644], [64642.5, 0.015], [64649.1, 37.345], [64761.6, 0.437], [64762.8, 0.0], [65217.9, 1.53], [65573.1, 10.81], [67155.0, 0.294]]}
{"kind": "depth", "E": 1787089593383, "U": 11315996305195, "u": 11315996311341, "recv_ms": 1787089593340, "bids": [[1000.0, 35.76], [14072.1, 1.274], [14472.1, 2.926], [58114.8, 0.067], [61343.4, 0.0], [61989.2, 0.003], [63572.1, 0.018], [63645.4, 0.655], [63724.8, 5.801], [63926.4, 1.564], [64249.2, 6.507], [64510.1, 0.052], [64531.9, 0.127], [64532.6, 0.227], [64572.1, 6.637]], "asks": [[64573.6, 1.393], [64573.7, 0.0], [64578.4, 0.006], [64580.0, 0.159], [64580.3, 0.294], [64580.6, 41.644], [64640.2, 3.533], [64642.5, 37.36], [64649.1, 0.0], [65088.8, 9.541], [65217.9, 1.53], [65419.6, 1.983], [65572.2, 0.002], [65677.8, 4.257], [66495.9, 0.644]]}
{"kind": "depth", "E": 1787089593485, "U": 11315996311538, "u": 11315996317932, "recv_ms": 1787089593443, "bids": [[1000.0, 35.76], [14072.1, 0.924], [14472.1, 3.276], [58114.8, 0.067], [61343.4, 0.0], [61989.2, 0.0], [63280.7, 0.014], [63926.4, 1.564], [64249.2, 6.662], [64510.1, 0.024], [64545.2, 7.421], [64549.5, 0.972], [64563.1, 0.101], [64566.5, 1.582], [64566.7, 0.09], [64567.3, 0.115], [64569.6, 0.551], [64570.0, 0.006], [64570.1, 0.0], [64570.5, 0.585], [64570.6, 0.001], [64571.8, 0.798], [64572.1, 6.165]], "asks": [[64572.2, 0.323], [64573.6, 0.0], [64573.7, 1.393], [64573.8, 0.0], [64580.0, 0.158], [64580.5, 7.223], [64600.0, 0.94], [64601.1, 0.392], [64601.2, 0.092], [64601.3, 2.321], [64602.0, 10.02], [64604.1, 0.002], [64604.2, 2.321], [64604.3, 1.133], [64605.0, 0.001], [64605.1, 2.166], [64605.2, 0.164], [64607.1, 0.116], [64607.2, 0.066], [64607.3, 0.016], [64642.5, 0.015], [64651.3, 37.352], [64675.5, 0.0], [64762.8, 1.799], [65088.8, 9.848], [65217.9, 1.53], [65340.6, 7.184], [65508.5, 25.414], [65573.1, 11.875], [65605.4, 5.33]]}
{"kind": "depth", "E": 1787089593587, "U": 11315996317998, "u": 11315996324455, "recv_ms": 1787089593543, "bids": [[14072.1, 0.56], [14472.1, 3.64], [51658.0, 0.0], [58114.8, 0.067], [61343.4, 0.0], [63538.9, 8.334], [63572.1, 0.038], [63764.9, 9.185], [63926.4, 1.564], [64415.1, 4.812], [64432.1, 2.908], [64548.8, 0.546], [64549.2, 0.155], [64561.9, 0.666], [64563.0, 1.315], [64563.1, 0.008], [64566.5, 0.034], [64566.7, 0.09], [64567.3, 0.115], [64569.6, 0.551], [64569.9, 2.321], [64570.0, 0.664], [64570.1, 1.548], [64570.5, 0.02], [64571.8, 0.798], [64572.1, 6.628]], "asks": [[64573.6, 0.0], [64573.7, 1.393], [64573.8, 0.0], [64576.2, 0.377], [64599.9, 0.783], [64605.1, 0.311], [64606.4, 0.904], [64644.7, 37.346], [64651.3, 0.007], [64768.2, 11.403], [65217.9, 1.53], [65218.0, 2.652], [65508.5, 24.347], [65572.2, 0.022], [65863.6, 0.027], [67800.8, 0.045]]}
{"kind": "depth", "E": 1787089593689, "U": 11315996324512, "u": 11315996329733, "recv_ms": 1787089593646, "bids": [[1000.0, 35.76], [14072.1, 0.322], [14372.1, 0.112], [14472.1, 3.766], [58114.8, 0.067], [61989.2, 0.003], [63926.4, 1.564], [64249.2, 6.662], [64462.5, 4.082], [64464.4, 0.027], [64495.3, 30.182], [64502.3, 6.018], [64504.1, 0.043], [64504.9, 0.0], [64505.5, 2.144], [64530.9, 3.677], [64549.2, 0.155], [64563.1, 0.65], [64566.5, 1.582], [64570.0, 0.006], [64570.1, 0.0], [64570.5, 0.02], [64570.6, 0.001], [64570.7, 0.001], [64571.0, 0.016]], "asks": [[64573.7, 1.393], [64573.8, 0.0], [64599.6, 0.061], [64599.7, 0.041], [64599.9, 0.629], [64642.5, 37.36], [64644.7, 0.001], [65217.9, 1.53], [65637.6, 4.443]]}
{"kind": "depth", "E": 1787089593791, "U": 11315996329787, "u": 11315996334621, "recv_ms": 1787089593748, "bids": [[1000.0, 35.76], [14072.1, 0.21], [14372.1, 0.364], [14472.1, 3.626], [58114.8, 0.067], [61343.4, 0.0], [61989.2, 0.0], [63572.1, 0.018], [63716.4, 0.001], [63926.4, 1.564], [64432.1, 3.843], [64495.3, 0.01], [64501.9, 30.173], [64549.2, 2.155], [64555.3, 0.007], [64563.1, 0.0], [64566.7, 0.748], [64567.3, 0.123], [64569.6, 0.835], [64569.9, 2.32], [64571.0, 0.0], [64571.8, 0.546], [64572.1, 6.627]], "asks": [[64573.6, 0.0], [64573.7, 1.393], [64587.7, 0.007], [64599.8, 0.19], [64712.5, 5.41], [65217.9, 1.53], [65508.5, 25.414], [65572.2, 0.002], [67155.0, 0.281]]}
{"kind": "depth", "E": 1787089593893, "U": 11315996334685, "u": 11315996340147, "recv_ms": 1787089593850, "bids": [[14072.1, 0.084], [14372.1, 0.588], [14472.1, 3.528], [58114.8, 0.067], [61989.2, 0.003], [63538.9, 9.434], [63926.4, 1.564], [64513.7, 0.163], [64520.9, 3.159], [64545.2, 0.506], [64548.0, 1.987], [64555.4, 0.736]], "asks": [[64572.2, 0.323], [64573.6, 0.0], [64573.7, 0.0], [64591.4, 2.734], [64598.7, 0.633], [64602.0, 0.02], [65217.9, 1.53], [65456.4, 5.498]]}
{"kind": "depth", "E": 1787089593995, "U": 11315996340191, "u": 11315996344762, "recv_ms": 1787089593953, "bids": [[1000.0, 35.76], [14072.1, 0.0], [14372.1, 0.868], [14472.1, 3.332], [58114.8, 0.067], [61343.4, 0.0], [61989.2, 0.0], [63572.1, 0.038], [63716.5, 0.034], [63726.1, 0.276], [63926.4, 1.564], [64249.2, 6.662], [64529.5, 0.006], [64539.6, 0.002], [64549.1, 0.154], [64549.2, 2.001], [64555.4, 0.117], [64563.1, 0.101], [64564.7, 0.004], [64566.0, 0.346], [64566.5, 0.034], [64566.7, 0.09], [64567.3, 0.115], [64569.6, 0.551], [64570.0, 0.006], [64570.1, 0.0], [64570.5, 0.585], [64570.6, 1.549], [64571.8, 0.798], [64572.1, 6.46]], "asks": [[64573.6, 0.0], [64573.7, 1.393], [64591.4, 2.115], [64605.8, 11.704], [65217.9, 1.53], [65572.2, 0.022]]}
{"kind": "depth", "E": 1787089594097, "U": 11315996344898, "u": 11315996352689, "recv_ms": 1787089594061, "bids": [[14372.1, 1.022], [14372.9, 0.21], [14472.1, 2.968], [58114.8, 0.065], [58115.6, 0.002], [61343.4, 0.0], [63281.5, 0.004], [63572.1, 0.018], [63757.1, 5.332], [63926.4, 1.564], [63927.2, 0.005], [64413.4, 0.523], [64432.1, 3.865], [64435.0, 1.541], [64436.4, 0.031], [64461.4, 0.58], [64473.2, 0.639], [64473.4, 3.319], [64477.5, 0.0], [64479.6, 0.0], [64479.8, 0.009], [64487.9, 0.004], [64495.3, 30.086], [64501.9, 0.001], [64504.1, 0.043], [64504.9, 0.018], [64510.2, 2.322], [64510.9, 0.0], [64512.6, 0.001], [64514.0, 0.03], [64515.4, 0.01], [64516.3, 0.464], [64519.4, 0.005], [64526.6, 0.332], [64527.5, 0.413], [64529.0, 0.015], [64529.5, 0.002], [64529.6, 0.438], [64530.5, 0.009], [64533.3, 0.004], [64537.0, 0.121], [64537.4, 0.332], [64538.3, 0.002], [64539.8, 0.008], [64541.5, 0.055], [64543.0, 0.102], [64543.4, 0.071], [64543.5, 0.001], [64543.9, 0.006], [64544.9, 0.177], [64546.7, 0.065], [64547.5, 0.031], [64547.9, 0.387], [64548.0, 1.368], [64548.1, 0.002], [64549.1, 0.476], [64549.2, 0.001], [64550.1, 0.004], [64550.6, 0.001], [64552.8, 0.002], [64553.0, 0.059], [64553.2, 0.001], [64553.9, 2.0], [64554.8, 0.465], [64555.5, 0.04], [64555.8, 0.0], [64555.9, 0.504], [64556.4, 0.0], [64556.8, 1.068], [64557.6, 0.56], [64558.0, 0.214], [64558.6, 0.0], [64558.7, 0.004], [64559.7, 0.017], [64560.4, 0.596], [64560.8, 0.012], [64560.9, 0.001], [64561.3, 0.588], [64561.8, 2.324], [64561.9, 1.051], [64562.0, 0.627], [64562.3, 0.278], [64562.4, 0.0], [64563.1, 0.008], [64563.2, 0.798], [64563.5, 0.002], [64563.6, 0.065], [64563.7, 0.165], [64563.8, 0.008], [64564.1, 0.002], [64564.2, 0.003], [64564.5, 0.022], [64564.7, 0.003], [64564.8, 0.322], [64565.6, 0.184], [64566.0, 0.262], [64566.2, 0.033], [64566.4, 1.116], [64566.5, 1.59], [64566.6, 0.372], [64566.7, 0.098], [64566.9, 0.239], [64567.1, 0.001], [64567.2, 0.313], [64567.3, 0.114], [64567.4, 0.008], [64568.1, 0.019], [64568.5, 0.155], [64568.7, 0.001], [64568.9, 0.001], [64569.1, 0.004], [64569.5, 0.007], [64569.6, 0.558], [64569.7, 0.004], [64569.9, 2.322], [64570.1, 0.084], [64570.2, 0.001], [64570.3, 0.002], [64570.4, 0.63], [64570.5, 0.019], [64570.6, 0.002], [64570.7, 0.001], [64571.0, 0.085], [64571.1, 0.0], [64571.3, 0.02], [64571.4, 0.047], [64571.6, 0.016], [64571.7, 0.041], [64571.8, 0.006], [64571.9, 0.0], [64572.0, 0.258], [64572.1, 1.284], [64572.2, 0.919], [64572.3, 0.0], [64572.4, 0.0], [64572.5, 0.0], [64572.7, 0.007], [64572.8, 0.007], [64572.9, 22.852]], "asks": [[64572.2, 0.0], [64572.3, 0.0], [64572.4, 0.0], [64572.5, 0.0], [64572.6, 0.0], [64572.8, 0.0], [64572.9, 0.0], [64573.0, 4.754], [64573.1, 0.012], [64573.3, 0.001], [64573.6, 0.0], [64573.7, 0.0], [64574.3, 0.0], [64574.5, 0.114], [64574.6, 0.001], [64574.7, 0.366], [64574.8, 0.001], [64575.0, 0.002], [64575.1, 0.004], [64575.4, 0.002], [64575.6, 0.196], [64575.7, 0.002], [64575.8, 0.001], [64575.9, 0.092], [64576.0, 0.655], [64576.1, 0.001], [64576.2, 0.391], [64576.3, 0.011], [64576.5, 0.002], [64576.9, 0.003], [64577.2, 0.084], [64577.3, 0.002], [64577.4, 0.197], [64577.5, 0.088], [64577.9, 0.105], [64578.0, 2.587], [64578.1, 0.002], [64578.2, 0.037], [64578.3, 0.55], [64578.6, 0.101], [64578.7, 0.004], [64578.8, 0.001], [64579.2, 0.034], [64579.6, 0.004], [64579.9, 0.0], [64580.0, 0.088], [64580.2, 0.002], [64580.3, 0.078], [64580.4, 0.655], [64580.5, 7.219], [64580.6, 41.645], [64585.2, 2.262], [64585.7, 0.403], [64585.9, 0.0], [64586.0, 0.015], [64586.2, 0.041], [64586.7, 0.005], [64587.0, 0.047], [64587.8, 0.0], [64587.9, 1.828], [64588.1, 0.06], [64588.5, 0.015], [64589.3, 0.0], [64589.4, 0.005], [64590.4, 0.015], [64590.5, 0.022], [64590.9, 0.0], [64591.2, 0.234], [64591.3, 0.095], [64591.5, 0.002], [64592.0, 0.027], [64592.1, 1.392], [64592.4, 0.663], [64592.9, 0.629], [64593.6, 0.435], [64593.8, 0.005], [64594.6, 0.035], [64594.7, 0.001], [64594.8, 1.238], [64595.2, 0.175], [64595.3, 0.003], [64595.8, 0.445], [64596.3, 0.022], [64597.2, 0.093], [64597.3, 0.01], [64597.5, 0.029], [64597.8, 7.206], [64598.0, 0.006], [64598.7, 0.014], [64599.0, 3.92], [64599.2, 0.057], [64599.4, 0.027], [64599.5, 0.01], [64599.8, 0.036], [64600.1, 0.169], [64601.6, 0.009], [64601.8, 0.083], [64602.3, 0.04], [64604.0, 0.008], [64604.1, 0.0], [64605.1, 0.326], [64605.8, 1.704], [64606.4, 0.905], [64606.5, 0.362], [64608.0, 0.028], [64609.5, 0.037], [64610.5, 5.09], [64611.2, 0.159], [64613.2, 0.017], [64614.4, 0.047], [64614.7, 0.0], [64617.0, 0.045], [64625.1, 0.387], [64627.3, 0.033], [64628.0, 2.576], [64630.3, 0.011], [64631.0, 0.097], [64639.8, 0.001], [64640.2, 3.542], [64640.8, 0.011], [64642.5, 0.015], [64649.1, 37.217], [64649.9, 0.003], [64668.0, 0.018], [64671.2, 0.0], [64675.5, 0.2], [64681.6, 2.472], [64688.7, 0.495], [64689.0, 2.036], [64712.5, 5.41], [64758.9, 0.016], [64759.0, 0.004], [64831.3, 0.115], [64844.2, 0.2], [64887.8, 0.429], [65217.9, 1.53], [65218.7, 0.002], [65315.1, 0.066], [65316.0, 8.525], [65335.0, 6.322], [65379.4, 7.925], [65379.7, 0.816], [65380.6, 6.136], [65482.7, 3.886], [65572.2, 0.002], [65863.6, 0.024]]}
{"kind": "depth", "E": 1787089594199, "U": 11315996352697, "u": 11315996359364, "recv_ms": 1787089594158, "bids": [[14372.9, 0.56], [14472.1, 2.618], [58115.6, 0.002], [61343.5, 0.012], [61343.6, 0.009], [61344.2, 0.001], [61989.9, 0.029], [63674.2, 2.579], [63927.2, 0.005], [64422.0, 0.011], [64422.2, 2.421], [64461.8, 0.0], [64473.6, 0.044], [64495.3, 0.01], [64501.9, 30.077], [64502.0, 8.365], [64502.3, 7.491], [64502.4, 0.047], [64505.5, 0.315], [64510.7, 0.45], [64510.8, 0.001], [64516.1, 1.475], [64516.2, 2.323], [64521.8, 0.228], [64524.7, 0.092], [64526.6, 0.271], [64527.4, 0.061], [64528.1, 0.042], [64531.9, 0.126], [64532.3, 0.001], [64532.9, 0.448], [64537.5, 0.898], [64538.3, 0.032], [64539.9, 1.309], [64540.0, 0.159], [64540.2, 0.108], [64550.0, 0.006], [64552.6, 0.035], [64553.6, 0.009], [64553.9, 0.0], [64556.8, 1.07], [64557.8, 6.92], [64558.8, 0.0], [64559.1, 0.009], [64559.6, 2.871], [64560.0, 0.365], [64560.8, 0.001], [64561.3, 0.526], [64562.0, 0.085], [64562.1, 0.008], [64563.1, 0.55], [64563.2, 0.79], [64563.3, 0.012], [64563.7, 0.011], [64563.8, 0.001], [64564.9, 0.007], [64566.0, 0.416], [64566.4, 1.178], [64570.3, 0.31], [64571.4, 0.045], [64572.1, 0.542], [64572.8, 0.009], [64572.9, 26.171]], "asks": [[64573.0, 4.868], [64574.5, 0.084], [64575.5, 0.004], [64575.6, 0.001], [64577.4, 0.002], [64577.5, 0.086], [64578.2, 0.214], [64579.2, 0.027], [64579.6, 0.006], [64579.8, 0.001], [64579.9, 0.007], [64580.3, 1.698], [64580.4, 0.965], [64580.7, 0.483], [64580.8, 0.01], [64584.0, 2.868], [64584.1, 0.453], [64585.7, 0.094], [64586.2, 0.35], [64588.5, 0.092], [64589.1, 1.14], [64590.2, 0.333], [64590.5, 0.024], [64592.0, 0.035], [64592.3, 0.18], [64600.1, 0.015], [64600.2, 0.168], [64600.3, 0.162], [64600.9, 1.887], [64604.8, 0.46], [64604.9, 0.018], [64605.7, 1.299], [64610.5, 0.003], [64611.0, 3.817], [64612.6, 10.817], [64612.7, 0.156], [64615.3, 0.482], [64615.4, 0.0], [64617.3, 0.024], [64618.2, 0.003], [64626.4, 1.472], [64626.5, 0.006], [64630.0, 0.02], [64630.3, 0.001], [64630.4, 1.245], [64630.8, 0.064], [64637.6, 2.622], [64640.2, 11.195], [64640.3, 0.001], [64642.5, 37.232], [64649.1, 0.0], [64653.8, 0.008], [64654.8, 0.033], [64727.7, 2.855], [64761.6, 0.66], [64816.4, 0.019], [64817.9, 0.0], [65218.7, 0.002], [65315.4, 0.002], [65316.1, 6.363], [65332.6, 0.921], [65347.1, 33.228], [65347.8, 0.461], [65380.0, 27.765], [65380.1, 0.238], [65380.7, 2.274], [65605.4, 4.264]]}
{"kind": "depth", "E": 1787089594301, "U": 11315996359580, "u": 11315996366227, "recv_ms": 1787089594300, "bids": [[1000.0, 35.76], [14372.9, 0.91], [14472.1, 2.268], [51657.7, 0.0], [51658.0, 0.0], [58115.6, 0.004], [61344.2, 0.001], [61989.9, 0.026], [63281.5, 0.007], [63571.2, 11.95], [63635.8, 21.31], [63726.0, 0.297], [63927.2, 0.005], [64055.5, 9.509], [64249.2, 6.652], [64250.9, 0.0], [64251.7, 0.108], [64432.1, 0.022], [64435.1, 0.986], [64546.8, 0.079], [64549.9, 0.31], [64553.1, 0.062], [64566.6, 0.311], [64569.0, 0.001], [64569.5, 0.239], [64572.1, 0.496], [64572.9, 26.484]], "asks": [[64576.0, 0.941], [64577.9, 1.894], [64580.3, 1.77], [64580.4, 0.893], [64584.1, 0.452], [64596.3, 0.008], [64612.6, 0.817], [64615.9, 10.0], [64630.1, 0.0], [64637.9, 0.228], [64640.2, 5.014], [64642.5, 0.015], [64646.9, 37.217], [64711.9, 0.0], [64712.5, 0.001], [64761.6, 0.437], [64762.8, 0.0], [64906.3, 0.108], [64908.3, 0.005], [65218.4, 1.295], [65218.7, 0.002], [65219.3, 0.379], [65340.6, 6.267], [65380.1, 0.466], [65508.5, 23.28], [65838.7, 0.671]]}
{"kind": "depth", "E": 1787089594403, "U": 11315996366253, "u": 11315996371787, "recv_ms": 1787089594360, "bids": [[14372.9, 1.274], [14472.1, 1.904], [51658.0, 0.0], [58115.6, 0.002], [61989.9, 0.029], [63572.9, 0.02], [63613.0, 4.083], [63651.1, 0.191], [63802.5, 0.0], [63927.2, 0.007], [64055.5, 9.82], [64249.2, 6.65], [64376.4, 0.0], [64415.1, 0.0], [64494.6, 0.047], [64513.9, 0.05], [64540.0, 0.149], [64540.1, 0.322], [64571.4, 0.002], [64571.6, 0.062], [64572.2, 0.918], [64572.9, 27.147]], "asks": [[64575.8, 0.011], [64578.2, 0.2], [64598.9, 2.433], [64600.9, 0.002], [64617.5, 0.014], [64618.3, 0.003], [64630.4, 1.235], [64630.5, 0.638], [64644.7, 37.218], [64646.9, 0.0], [64649.9, 0.0], [64729.5, 0.026], [64768.2, 0.0], [64831.3, 0.31], [64895.9, 0.03], [65154.2, 1.997], [65218.7, 0.002], [65341.4, 0.918], [65573.0, 0.02], [65573.1, 10.809], [65606.2, 1.066]]}
{"kind": "depth", "E": 1787089594607, "U": 11315996376403, "u": 11315996380640, "recv_ms": 1787089594607, "bids": [[1000.0, 35.76], [14372.9, 1.988], [14472.1, 1.19], [51658.0, 0.002], [58115.6, 0.002], [61344.2, 0.001], [63474.4, 1.715], [63572.9, 0.0], [63668.1, 25.79], [63927.2, 0.005], [64249.2, 6.65], [64540.1, 0.312], [64540.2, 0.118], [64572.9, 25.307]], "asks": [[64573.0, 4.945], [64620.3, 0.04], [64626.7, 0.062], [64630.5, 0.628], [64630.6, 0.01], [64689.3, 0.087], [64689.5, 0.117], [65185.3, 0.001], [65218.7, 0.002], [65509.3, 2.472], [65573.0, 0.0], [65573.9, 1.07]]}
{"kind": "depth", "E": 1787089594709, "U": 11315996380742, "u": 11315996385376, "recv_ms": 1787089594666, "bids": [[14372.9, 2.352], [14472.1, 0.826], [51658.0, 0.0], [58115.6, 0.002], [61989.9, 0.029], [63280.7, 0.011], [63474.4, 6.435], [63648.9, 5.178], [63917.4, 1.282], [63927.2, 0.005], [64451.8, 1.592], [64452.6, 0.013], [64458.9, 0.078], [64459.7, 0.015], [64465.9, 0.001], [64466.7, 0.013], [64473.0, 0.018], [64473.8, 0.014], [64480.0, 15.204], [64480.8, 0.029], [64487.1, 0.007], [64487.9, 0.017], [64494.1, 0.0], [64494.9, 0.021], [64501.2, 0.027], [64502.0, 4.84], [64544.7, 0.071], [64551.9, 0.05]], "asks": [[65205.8, 0.612], [65218.7, 0.002], [65354.3, 3.254]]}
{"kind": "depth", "E": 1787089594811, "U": 11315996385404, "u": 11315996390947, "recv_ms": 1787089594809, "bids": [[14272.9, 0.014], [14372.9, 2.674], [14472.1, 0.49], [51658.0, 0.0], [58115.6, 0.002], [61989.9, 0.026], [63281.5, 0.013], [63572.9, 0.02], [63627.6, 0.0], [63927.2, 0.005], [64250.0, 11.687], [64540.2, 0.108], [64540.3, 0.01], [64549.1, 0.322], [64549.5, 1.126], [64551.2, 0.069], [64555.3, 0.005], [64556.1, 0.005]], "asks": [[64577.8, 0.069], [64587.7, 0.005], [64588.5, 0.094], [64617.8, 0.001], [64619.6, 0.003], [64628.0, 2.576], [64628.7, 0.061], [64630.6, 0.0], [64630.7, 0.023], [65218.7, 0.002], [65367.3, 1.534], [65432.4, 1.543], [65573.0, 0.02]]}
{"kind": "depth", "E": 1787089595015, "U": 11315996401494, "u": 11315996410510, "recv_ms": 1787089595016, "bids": [[14272.9, 0.42], [14372.9, 2.576], [14472.1, 0.182], [58115.6, 0.002], [61344.2, 0.002], [63572.9, 0.0], [63668.1, 25.978], [63927.2, 0.005], [64415.0, 7.189], [64416.0, 1.263], [64431.9, 3.747], [64508.8, 0.284], [64509.9, 0.0], [64513.7, 0.186], [64529.5, 0.006], [64537.0, 0.117], [64540.3, 0.002], [64540.4, 2.329], [64549.5, 1.126], [64565.4, 0.101], [64566.6, 0.465], [64572.1, 0.242], [64572.9, 25.309]], "asks": [[64573.0, 5.047], [64577.8, 0.069], [64578.2, 0.005], [64578.9, 0.001], [64579.3, 0.186], [64580.5, 7.235], [64588.5, 0.086], [64590.4, 0.007], [64596.9, 0.0], [64630.7, 0.013], [64630.8, 0.074], [64713.3, 5.439], [64730.3, 10.428], [64886.2, 0.962], [65166.0, 0.343], [65218.7, 0.002], [65335.0, 5.558], [65501.6, 0.534], [65573.0, 0.0], [66516.8, 0.644], [68228.8, 0.0]]}
{"kind": "depth", "E": 1787089595219, "U": 11315996417518, "u": 11315996423402, "recv_ms": 1787089595322, "bids": [[1000.0, 35.76], [14272.9, 0.952], [14372.9, 2.226], [14472.1, 0.0], [51658.0, 0.0], [58115.6, 0.002], [61344.2, 0.001], [61989.9, 0.029], [63572.9, 0.02], [63635.8, 21.31], [63674.2, 1.953], [63700.4, 5.381], [63803.7, 5.086], [63927.2, 0.005], [64056.3, 0.016], [64416.0, 1.962], [64431.9, 0.005], [64502.0, 8.376], [64549.2, 0.155]], "asks": [[64573.0, 5.287], [64612.0, 5.124], [64614.6, 2.629], [64617.0, 0.031], [64644.7, 0.001], [64650.1, 6.534], [64651.3, 37.265], [64711.9, 1.25], [64713.3, 0.031], [64729.6, 2.756], [64768.9, 1.999], [65218.7, 0.002], [65508.5, 22.213], [65573.0, 0.02], [65637.6, 3.378], [68228.8, 0.076]]}
{"kind": "depth", "E": 1787089595321, "U": 11315996423540, "u": 11315996429668, "recv_ms": 1787089595323, "bids": [[14272.9, 1.302], [14372.9, 1.876], [51658.3, 0.0], [58115.6, 0.002], [61344.2, 0.001], [61970.5, 1.382], [61989.9, 0.026], [63280.7, 0.008], [63795.9, 3.914], [63927.2, 0.005], [64432.0, 4.275], [64435.1, 1.547], [64571.7, 0.041], [64572.9, 25.331]], "asks": [[64573.0, 5.288], [64580.9, 0.033], [64614.6, 1.35], [64615.9, 0.0], [64617.0, 0.045], [64642.5, 37.273], [64651.3, 0.007], [64713.3, 5.439], [64763.7, 0.15], [64769.0, 11.438], [65186.4, 0.727], [65218.7, 0.002], [65424.2, 0.006], [65522.2, 1.303]]}
{"kind": "depth", "E": 1787089595423, "U": 11315996429863, "u": 11315996437132, "recv_ms": 1787089595379, "bids": [[1000.0, 35.76], [14272.9, 1.666], [14372.9, 1.512], [58115.6, 0.002], [61344.2, 0.002], [61989.9, 0.029], [63572.9, 0.0], [63803.8, 0.939], [63927.2, 0.005], [64250.0, 11.689], [64457.2, 4.17], [64467.3, 2.345], [64467.4, 0.067], [64468.4, 0.0], [64468.9, 0.025], [64501.4, 0.047], [64540.4, 2.319], [64540.5, 1.271], [64552.3, 2.331], [64552.6, 0.024], [64571.7, 0.0], [64572.9, 25.361]], "asks": [[64576.1, 0.002], [64578.2, 0.019], [64601.8, 1.968], [64601.9, 0.001], [64630.8, 0.064], [64630.9, 0.011], [64643.5, 3.823], [64643.6, 0.0], [64650.1, 1.108], [64680.9, 0.0], [64681.4, 2.323], [64712.0, 1.728], [64713.8, 3.872], [64759.0, 0.001], [64759.4, 0.028], [64895.9, 0.028], [65218.7, 0.002], [65509.3, 3.539], [65573.0, 0.0], [65638.5, 1.065], [65864.4, 0.003]]}
{"kind": "depth", "E": 1787089595525, "U": 11315996437300, "u": 11315996443177, "recv_ms": 1787089595527, "bids": [[1000.0, 35.76], [14272.9, 2.016], [14372.9, 1.162], [58115.6, 0.002], [61343.5, 0.008], [61343.6, 0.011], [61344.2, 0.001], [63023.2, 0.085], [63635.8, 22.409], [63803.7, 6.025], [63927.2, 0.005], [64502.3, 7.473], [64540.5, 1.261], [64540.6, 0.011], [64556.9, 0.559], [64557.6, 0.002], [64561.4, 0.929], [64561.9, 0.666], [64563.1, 0.008], [64570.5, 0.103], [64571.0, 0.001]], "asks": [[64573.0, 5.283], [64575.8, 0.0], [64578.2, 0.005], [64630.9, 0.001], [64631.0, 0.107], [65218.7, 0.002], [65471.7, 0.228], [65863.6, 0.021]]}
{"kind": "depth", "E": 1787089595627, "U": 11315996443204, "u": 11315996448599, "recv_ms": 1787089595585, "bids": [[14272.9, 2.38], [14372.1, 0.938], [14372.9, 0.882], [58115.6, 0.002], [61343.5, 0.008], [61343.6, 0.013], [61989.9, 0.026], [63384.8, 0.315], [63572.9, 0.02], [63927.2, 0.005], [64412.4, 0.0], [64513.9, 0.05], [64572.9, 25.331]], "asks": [[64575.7, 0.012], [64577.7, 0.013], [64630.4, 1.232], [64631.2, 0.003], [65218.7, 0.002], [65363.4, 0.766], [65444.6, 1.067], [65573.0, 0.02]]}
{"kind": "depth", "E": 1787089595729, "U": 11315996448686, "u": 11315996454351, "recv_ms": 1787089595734, "bids": [[1000.0, 35.76], [14272.9, 2.73], [14372.1, 0.812], [14372.9, 0.658], [51658.0, 0.0], [58115.6, 0.002], [61344.2, 0.001], [61989.9, 0.029], [63538.9, 8.334], [63572.9, 0.0], [63723.8, 0.28], [63927.2, 0.005], [64249.2, 6.65], [64250.0, 11.679], [64457.2, 4.17], [64501.4, 0.047], [64566.4, 1.094], [64570.4, 0.629], [64570.9, 0.394], [64572.7, 0.008]], "asks": [[64574.5, 0.006], [64643.5, 3.823], [64713.6, 3.885], [64713.8, 0.0], [65218.7, 0.002], [65380.7, 1.517], [65477.4, 2.288], [65573.0, 0.0], [65903.2, 0.002]]}
{"kind": "depth", "E": 1787089596137, "U": 11315996471219, "u": 11315996478133, "recv_ms": 1787089596094, "bids": [[1000.0, 35.76], [14172.9, 0.238], [14272.9, 3.696], [14372.1, 0.084], [14372.9, 0.182], [51658.0, 0.0], [58115.6, 0.002], [61344.2, 0.001], [61989.9, 0.026], [63635.8, 22.566], [63927.2, 0.005], [64528.0, 0.095], [64528.1, 0.12], [64531.5, 0.0], [64532.8, 0.44], [64534.8, 0.139], [64539.4, 0.03], [64539.6, 0.042], [64545.2, 0.466], [64547.3, 0.619], [64554.6, 0.739], [64561.3, 0.526], [64570.3, 0.0], [64572.9, 25.296]], "asks": [[64584.1, 0.453], [64590.7, 1.373], [64598.0, 0.625], [64599.9, 0.629], [64600.0, 1.094], [64619.7, 0.06], [64628.7, 0.001], [64763.7, 0.725], [65218.7, 0.002], [65316.2, 0.917], [66649.0, 0.013]]}
{"kind": "depth", "E": 1787089596239, "U": 11315996478182, "u": 11315996483892, "recv_ms": 1787089596198, "bids": [[14172.9, 0.476], [14272.9, 3.57], [14372.9, 0.07], [51658.0, 0.0], [58115.6, 0.002], [61989.9, 0.029], [63613.0, 3.926], [63774.5, 0.0], [63780.2, 6.968], [63821.5, 1.564], [63927.2, 0.005], [64482.2, 3.858], [64488.7, 0.793], [64504.8, 1.373], [64518.1, 0.024], [64522.5, 0.002], [64532.8, 0.436], [64533.2, 0.077], [64539.6, 0.046], [64561.9, 0.124], [64563.0, 1.857]], "asks": [[64611.9, 1.321], [64628.0, 2.572], [64629.4, 4.635], [64634.3, 0.443], [64635.9, 2.06], [64640.2, 11.201], [64673.3, 0.002], [64679.8, 0.0], [64711.9, 1.897], [65218.7, 0.002], [65341.4, 2.752]]}
{"kind": "depth", "E": 1787089596341, "U": 11315996484069, "u": 11315996489513, "recv_ms": 1787089596302, "bids": [[1000.0, 35.76], [14172.9, 0.7], [14272.9, 3.472], [14372.1, 0.028], [14372.9, 0.0], [51658.0, 0.0], [51658.3, 0.0], [58115.6, 0.002], [61989.9, 0.026], [63572.9, 0.0], [63635.8, 21.467], [63803.7, 5.086], [63927.2, 0.005], [64249.2, 6.65], [64532.8, 0.476], [64539.6, 0.006], [64555.4, 0.001], [64555.8, 0.116], [64556.9, 0.001], [64557.0, 0.559], [64558.1, 0.0], [64559.2, 0.021], [64560.0, 0.358], [64561.9, 0.666], [64563.0, 1.315], [64563.2, 0.809], [64571.3, 0.001]], "asks": [[64580.5, 7.219], [64588.5, 0.094], [64589.9, 0.009], [64592.0, 0.577], [64592.5, 0.001], [64593.8, 0.02], [64593.9, 0.229], [64594.7, 0.928], [64597.0, 0.111], [64598.2, 0.557], [64598.8, 0.034], [64599.6, 0.177], [64600.0, 0.94], [64600.1, 0.169], [64640.2, 5.014], [64642.5, 37.34], [64644.7, 0.001], [64649.1, 0.0], [65218.7, 0.002], [65573.0, 0.0], [66677.0, 0.135], [67155.8, 0.005]]}
{"kind": "depth", "E": 1787089596443, "U": 11315996489525, "u": 11315996495230, "recv_ms": 1787089596401, "bids": [[1000.0, 35.76], [14172.9, 1.036], [14272.9, 3.164], [14372.1, 0.0], [58115.6, 0.002], [61344.2, 0.001], [63584.9, 3.125], [63601.1, 0.001], [63668.9, 2.353], [63927.2, 0.005], [64250.0, 11.677], [64540.6, 0.001], [64540.7, 0.012], [64572.9, 25.339]], "asks": [[64593.6, 1.362], [64594.7, 0.001], [64631.0, 0.097], [64631.1, 1.01], [65218.7, 0.002], [65347.9, 1.168], [65717.8, 0.0]]}
{"kind": "depth", "E": 1787089596545, "U": 11315996495317, "u": 11315996500119, "recv_ms": 1787089596503, "bids": [[14172.9, 1.4], [14272.9, 2.8], [58115.6, 0.002], [61989.9, 0.029], [63572.9, 0.02], [63636.6, 1.57], [63804.5, 2.821], [63927.2, 0.005], [64410.6, 0.022], [64415.0, 1.17], [64432.0, 0.065], [64507.5, 0.42], [64521.5, 0.015], [64537.3, 0.0], [64542.8, 0.191], [64555.2, 0.002], [64558.9, 0.012]], "asks": [[64597.2, 0.65], [64598.2, 0.0], [64598.6, 0.117], [64599.6, 0.061], [64600.1, 0.169], [64636.8, 0.01], [64650.5, 0.639], [64713.3, 0.031], [64730.3, 0.0], [64895.9, 0.03], [65218.7, 0.002], [65270.5, 1.53], [65388.1, 0.765], [65458.8, 5.524], [65573.0, 0.02]]}
{"kind": "depth", "E": 1787089596647, "U": 11315996500177, "u": 11315996514602, "recv_ms": 1787089596608, "bids": [[1000.0, 35.76], [14172.9, 1.75], [14272.9, 2.45], [51658.0, 0.0], [58115.6, 0.002], [61344.2, 0.001], [61989.9, 0.026], [63281.5, 0.019], [63572.9, 0.0], [63927.2, 0.005], [64250.0, 11.677], [64379.1, 0.006], [64415.1, 6.937], [64432.0, 4.307], [64434.5, 0.014], [64448.1, 0.247], [64504.9, 0.0], [64508.2, 0.001], [64508.6, 0.85], [64508.9, 0.027], [64509.2, 0.0], [64509.5, 0.001], [64526.1, 0.02], [64527.6, 0.008], [64527.9, 2.598], [64528.2, 0.061], [64528.5, 0.129], [64528.9, 0.0], [64542.5, 0.001], [64542.6, 0.001], [64542.7, 0.0], [64542.8, 0.021], [64542.9, 0.39], [64543.0, 0.0], [64543.1, 2.322], [64543.2, 2.08], [64543.3, 0.0], [64543.4, 0.001], [64545.3, 0.192], [64546.1, 0.001], [64546.5, 0.004], [64547.3, 0.0], [64550.9, 0.629], [64551.9, 0.001], [64554.6, 0.12], [64555.0, 0.096], [64555.8, 0.0], [64555.9, 0.502], [64556.7, 0.134], [64556.9, 0.003], [64557.0, 0.001], [64557.8, 0.005], [64557.9, 0.559], [64559.2, 0.014], [64559.6, 1.863], [64559.7, 0.009], [64559.9, 0.021], [64560.4, 0.449], [64561.3, 0.001], [64561.6, 0.217], [64561.9, 0.124], [64562.0, 0.001], [64562.1, 0.0], [64562.8, 0.055], [64562.9, 1.245], [64563.1, 0.0], [64563.2, 0.267], [64563.3, 0.554], [64563.4, 0.225], [64564.0, 0.003], [64564.1, 0.002], [64564.5, 0.03], [64564.6, 0.004], [64564.8, 7.237], [64565.0, 0.313], [64565.1, 0.071], [64565.2, 0.001], [64565.3, 0.001], [64565.4, 0.001], [64565.5, 0.0], [64565.6, 0.421], [64565.7, 0.155], [64565.8, 0.002], [64566.0, 0.346], [64566.2, 0.001], [64566.4, 1.921], [64566.5, 1.558], [64566.7, 0.656], [64566.8, 0.0], [64567.2, 0.281], [64567.3, 0.03], [64567.5, 0.0], [64567.8, 0.007], [64569.4, 0.005], [64569.5, 0.007], [64570.4, 0.629], [64570.5, 0.084], [64571.0, 0.311], [64571.3, 0.085], [64572.0, 0.342], [64572.3, 0.0], [64572.9, 27.562]], "asks": [[64573.0, 0.544], [64573.1, 0.01], [64573.5, 0.0], [64573.9, 1.393], [64574.2, 0.0], [64574.3, 0.0], [64574.5, 0.012], [64574.6, 0.001], [64574.7, 0.371], [64575.0, 0.002], [64575.1, 0.002], [64575.6, 0.005], [64575.7, 0.012], [64575.9, 0.008], [64576.3, 0.008], [64576.4, 0.0], [64576.8, 0.01], [64576.9, 1.695], [64577.7, 0.003], [64577.8, 0.069], [64577.9, 1.886], [64578.7, 0.007], [64579.0, 0.104], [64579.4, 0.102], [64579.7, 0.084], [64579.8, 0.021], [64579.9, 0.0], [64580.2, 0.444], [64580.4, 0.59], [64580.5, 6.777], [64581.8, 0.002], [64582.2, 0.002], [64582.5, 0.001], [64582.8, 0.0], [64583.1, 0.003], [64583.2, 0.287], [64583.4, 0.432], [64583.5, 0.465], [64583.6, 0.003], [64583.7, 0.154], [64583.8, 0.002], [64583.9, 0.875], [64584.0, 2.328], [64584.1, 0.313], [64584.2, 0.0], [64584.3, 0.001], [64584.4, 0.354], [64588.5, 0.017], [64589.0, 0.082], [64589.9, 0.001], [64590.6, 0.01], [64590.7, 0.754], [64592.0, 0.035], [64593.5, 0.032], [64593.6, 0.435], [64594.1, 0.545], [64594.4, 0.45], [64594.6, 0.962], [64595.3, 0.001], [64595.4, 0.628], [64595.8, 0.127], [64597.1, 0.793], [64597.2, 0.093], [64598.0, 0.006], [64598.2, 0.557], [64598.6, 0.001], [64599.4, 0.143], [64600.1, 0.008], [64600.2, 0.322], [64600.6, 0.007], [64601.2, 0.025], [64601.5, 1.704], [64601.8, 1.885], [64602.1, 0.019], [64602.5, 0.011], [64602.9, 1.002], [64603.3, 0.039], [64605.7, 0.403], [64605.9, 0.001], [64606.1, 0.311], [64606.2, 0.156], [64606.3, 0.034], [64606.4, 0.435], [64606.5, 0.092], [64606.6, 0.001], [64606.7, 0.018], [64606.8, 0.001], [64606.9, 0.0], [64611.9, 0.795], [64612.0, 0.039], [64616.9, 1.238], [64619.3, 0.003], [64620.5, 0.026], [64620.8, 10.082], [64621.1, 0.389], [64621.5, 0.0], [64621.8, 0.004], [64628.4, 0.026], [64682.8, 0.003], [64711.9, 1.25], [64713.3, 5.439], [64729.6, 2.756], [64730.2, 6.984], [64769.0, 11.408], [65218.7, 0.002], [65458.8, 5.341], [65573.0, 0.0], [65580.5, 0.654], [65741.1, 5.405], [65863.6, 0.015]]}
{"kind": "depth", "E": 1787089596749, "U": 11315996515513, "u": 11315996523907, "recv_ms": 1787089596707, "bids": [[1000.0, 35.76], [14172.9, 2.1], [14272.9, 2.1], [58115.6, 0.002], [61344.2, 0.002], [61989.9, 0.029], [63623.7, 1.256], [63829.5, 5.084], [63927.2, 0.005], [64532.8, 0.436], [64542.3, 0.041], [64542.9, 0.31], [64543.5, 0.001], [64543.8, 0.1], [64550.9, 0.628], [64552.8, 0.082], [64555.6, 0.116], [64556.7, 0.018], [64556.9, 0.561], [64557.9, 0.001], [64558.1, 0.003], [64561.9, 0.124], [64563.1, 0.542], [64563.3, 0.012], [64564.5, 0.022], [64565.5, 0.07], [64565.9, 0.072], [64566.8, 0.008], [64568.0, 0.703], [64572.3, 0.003], [64572.9, 25.339]], "asks": [[64573.7, 0.0], [64573.9, 0.0], [64574.0, 0.003], [64574.1, 1.393], [64574.5, 0.002], [64575.6, 1.806], [64576.8, 0.02], [64579.6, 0.008], [64580.3, 0.073], [64582.9, 0.164], [64583.4, 0.558], [64584.1, 0.312], [64592.0, 0.035], [64592.8, 0.8], [64593.5, 0.032], [64594.1, 0.003], [64594.4, 1.377], [64594.6, 0.035], [64605.5, 0.177], [64605.9, 0.127], [65218.7, 0.002], [65355.8, 1.952], [65450.0, 29.019], [65864.4, 0.009]]}
{"kind": "depth", "E": 1787089596851, "U": 11315996524135, "u": 11315996532290, "recv_ms": 1787089596808, "bids": [[14172.9, 2.464], [14272.9, 1.736], [58115.6, 0.002], [61344.2, 0.001], [61989.9, 0.026], [63538.9, 8.334], [63927.2, 0.007], [64527.5, 0.445], [64527.8, 5.441], [64528.1, 0.152], [64528.5, 0.161], [64528.8, 0.068], [64549.3, 0.085], [64552.8, 0.002], [64556.1, 0.005], [64564.9, 0.077], [64565.2, 0.071], [64565.5, 0.17], [64565.6, 0.521], [64565.7, 0.225], [64566.2, 0.033], [64566.5, 1.59], [64566.8, 0.04], [64567.1, 0.033], [64567.4, 0.04], [64567.7, 0.098], [64572.9, 25.307]], "asks": [[64573.0, 0.43], [64573.9, 0.234], [64574.1, 0.0], [64574.2, 1.393], [64574.7, 0.124], [64575.5, 0.283], [64575.7, 0.013], [64578.3, 0.563], [64579.8, 0.001], [64581.4, 0.067], [64581.7, 0.087], [64581.9, 0.022], [64582.0, 0.156], [64582.4, 0.102], [64582.7, 0.068], [64583.1, 0.15], [64583.3, 0.411], [64583.4, 0.778], [64583.6, 0.143], [64583.8, 0.005], [64583.9, 1.015], [64588.5, 0.017], [64600.2, 0.322], [64600.7, 0.087], [64601.0, 0.067], [64601.3, 2.404], [64601.7, 1.041], [64602.0, 0.084], [64605.7, 0.55], [64605.8, 1.954], [64605.9, 0.347], [64606.1, 0.451], [64606.4, 0.575], [65218.7, 0.002], [65947.2, 1.298]]}
{"kind": "depth", "E": 1787089596953, "U": 11315996532375, "u": 11315996541340, "recv_ms": 1787089596912, "bids": [[1000.0, 35.76], [14172.9, 2.814], [14272.9, 1.386], [58115.6, 0.002], [61344.2, 0.001], [63539.7, 1.1], [63572.9, 0.02], [63927.2, 0.009], [64250.0, 11.687], [64432.0, 0.065], [64500.5, 0.414], [64513.9, 0.047], [64514.7, 0.018], [64537.9, 0.071], [64544.7, 0.001], [64554.6, 0.004], [64556.4, 0.002], [64556.9, 0.559], [64560.0, 0.354], [64563.2, 0.383], [64564.8, 0.322], [64565.1, 0.141], [64565.2, 0.141], [64565.3, 0.201], [64565.4, 0.101], [64565.8, 0.102], [64567.5, 0.0], [64567.6, 0.003], [64567.7, 0.014], [64571.2, 2.001], [64572.8, 0.093], [64572.9, 28.293]], "asks": [[64573.0, 0.429], [64573.4, 0.001], [64574.0, 0.003], [64574.2, 0.0], [64574.3, 1.393], [64575.7, 0.003], [64575.9, 0.008], [64576.0, 0.94], [64576.8, 0.002], [64577.2, 0.0], [64577.5, 0.002], [64577.9, 1.878], [64578.0, 0.006], [64578.1, 0.0], [64579.2, 0.026], [64579.5, 0.001], [64580.1, 0.396], [64580.2, 0.002], [64580.4, 0.016], [64580.5, 6.775], [64580.7, 0.481], [64580.8, 0.007], [64583.1, 0.41], [64583.5, 0.985], [64583.6, 0.413], [64583.7, 0.301], [64583.8, 0.138], [64586.2, 0.041], [64588.5, 0.009], [64589.3, 0.011], [64590.3, 0.002], [64590.6, 0.002], [64592.0, 0.027], [64592.8, 0.258], [64594.1, 0.545], [64597.8, 6.599], [64602.4, 0.265], [64602.8, 0.271], [64605.7, 0.43], [64606.0, 0.251], [64606.1, 0.721], [64606.2, 0.303], [64606.3, 0.167], [64607.7, 0.066], [64613.4, 0.121], [64620.8, 0.082], [64628.5, 9.369], [64631.2, 0.003], [64637.9, 0.018], [64648.1, 0.299], [64650.5, 0.636], [64682.8, 0.0], [64713.3, 0.031], [65218.7, 0.01], [65347.1, 32.769], [65573.0, 0.02]]}
{"kind": "depth", "E": 1787089597055, "U": 11315996541416, "u": 11315996563418, "recv_ms": 1787089597021, "bids": [[1000.0, 35.76], [14172.9, 3.178], [14272.9, 1.022], [58115.6, 0.002], [61344.2, 0.001], [61989.9, 0.029], [63281.5, 0.025], [63572.9, 0.0], [63829.5, 6.023], [63927.2, 0.005], [64432.0, 4.283], [64435.1, 0.986], [64462.7, 0.0], [64474.5, 0.061], [64479.8, 0.004], [64480.7, 0.198], [64497.6, 0.433], [64501.3, 0.031], [64520.9, 2.949], [64530.0, 0.242], [64536.3, 0.001], [64537.9, 0.001], [64538.3, 0.032], [64542.6, 0.071], [64543.1, 2.422], [64544.9, 0.057], [64545.1, 0.07], [64545.3, 0.143], [64545.5, 0.141], [64545.6, 2.953], [64546.7, 0.015], [64551.4, 0.002], [64552.7, 0.055], [64554.1, 0.596], [64556.8, 1.03], [64559.8, 0.008], [64561.3, 0.001], [64561.9, 0.132], [64562.3, 0.277], [64563.3, 0.646], [64563.9, 0.671], [64565.0, 0.383], [64566.4, 0.973], [64566.6, 0.527], [64566.7, 0.006], [64567.4, 0.044], [64567.5, 0.0], [64570.8, 0.0], [64571.1, 0.001], [64571.4, 0.001], [64571.5, 0.0], [64572.1, 0.235], [64572.2, 0.818], [64572.8, 0.1], [64572.9, 28.822]], "asks": [[64574.0, 0.013], [64574.2, 0.0], [64574.3, 1.393], [64574.5, 0.002], [64574.6, 0.001], [64574.7, 0.045], [64575.4, 0.012], [64575.5, 0.005], [64575.9, 0.007], [64576.0, 0.039], [64576.8, 0.676], [64577.1, 0.0], [64577.8, 0.015], [64577.9, 1.794], [64578.0, 0.008], [64578.3, 0.558], [64578.5, 0.001], [64579.2, 0.072], [64579.6, 0.006], [64579.9, 0.154], [64580.4, 0.65], [64580.5, 7.217], [64580.6, 41.645], [64580.7, 0.483], [64580.8, 0.093], [64581.2, 0.087], [64582.4, 0.082], [64583.0, 0.116], [64583.7, 2.882], [64583.8, 0.285], [64584.3, 0.021], [64585.4, 0.343], [64586.0, 0.324], [64588.5, 0.017], [64590.3, 0.01], [64590.8, 0.002], [64591.8, 0.005], [64592.0, 0.035], [64592.3, 1.305], [64592.8, 0.258], [64593.8, 0.015], [64594.1, 0.545], [64594.7, 0.006], [64595.6, 2.334], [64597.1, 0.633], [64598.9, 2.753], [64599.0, 0.121], [64600.4, 0.0], [64601.4, 4.553], [64606.4, 0.722], [64607.3, 0.065], [64608.4, 0.004], [64611.9, 0.865], [64613.1, 0.508], [64613.4, 0.001], [64615.3, 0.482], [64619.7, 0.0], [64620.4, 0.072], [64622.3, 0.001], [64624.7, 10.0], [64626.4, 1.532], [64628.5, 4.284], [64639.3, 0.0], [64640.1, 0.21], [64643.1, 0.028], [64648.1, 0.089], [64713.3, 5.439], [64769.0, 11.392], [65218.7, 0.002], [65270.5, 0.765], [65417.1, 0.611], [65470.6, 0.916], [65573.0, 0.0], [65864.4, 0.012]]}
{"kind": "depth", "E": 1787089597157, "U": 11315996563770, "u": 11315996574691, "recv_ms": 1787089597117, "bids": [[14172.9, 3.528], [14272.9, 0.672], [58115.6, 0.002], [61344.2, 0.001], [61989.2, 0.69], [61989.9, 0.026], [63281.5, 0.028], [63927.2, 0.005], [64508.2, 0.033], [64508.5, 0.055], [64508.8, 0.316], [64509.1, 0.15], [64509.5, 0.033], [64542.3, 0.041], [64543.0, 0.07], [64543.4, 0.071], [64546.6, 0.001], [64547.6, 0.058], [64548.5, 0.008], [64549.1, 0.476], [64549.2, 0.001], [64549.6, 0.001], [64549.7, 0.108], [64551.4, 0.001], [64561.4, 0.002], [64561.9, 0.132], [64562.1, 0.927], [64563.0, 0.967], [64563.4, 0.225], [64563.5, 0.001], [64567.4, 0.04], [64569.4, 0.006], [64571.1, 0.233], [64572.9, 26.229]], "asks": [[64573.9, 0.244], [64574.0, 0.003], [64574.2, 0.0], [64574.3, 0.0], [64574.5, 0.002], [64574.6, 1.394], [64575.4, 0.002], [64575.5, 0.015], [64576.0, 0.04], [64576.7, 0.001], [64579.2, 0.073], [64579.4, 0.104], [64579.5, 0.001], [64579.6, 0.004], [64580.3, 0.105], [64583.4, 2.361], [64583.6, 0.445], [64583.9, 0.14], [64585.7, 0.094], [64588.2, 0.541], [64593.1, 0.002], [64594.4, 0.45], [64595.4, 1.555], [64599.2, 0.0], [64599.4, 0.027], [64599.8, 0.036], [64600.1, 0.162], [64600.2, 0.225], [64600.4, 0.05], [64600.5, 0.117], [64601.7, 2.926], [64601.8, 0.0], [64605.7, 0.55], [64607.7, 0.016], [64613.1, 0.388], [64620.1, 0.072], [64620.3, 0.0], [64620.4, 0.139], [64620.7, 0.083], [64621.0, 1.573], [64621.3, 1.035], [64627.3, 0.073], [64642.5, 0.015], [64646.9, 37.383], [64651.3, 0.007], [65218.7, 0.002], [65347.9, 1.627], [65370.1, 0.0], [65489.9, 0.228], [65863.6, 0.012], [65864.4, 0.015]]}
{"kind": "depth", "E": 1787089597259, "U": 11315996574799, "u": 11315996583189, "recv_ms": 1787089597217, "bids": [[1000.0, 35.76], [14072.9, 0.07], [14172.9, 3.752], [14272.9, 0.378], [51658.0, 0.0], [51658.3, 0.0], [58115.6, 0.002], [61343.6, 0.011], [61344.2, 0.001], [61989.9, 0.029], [63927.2, 0.005], [64250.0, 11.687], [64432.0, 0.065], [64507.2, 2.144], [64508.6, 1.228], [64522.4, 0.215], [64530.0, 0.032], [64542.4, 0.503], [64542.7, 0.07], [64542.9, 0.41], [64543.1, 2.522], [64543.2, 2.15], [64548.1, 0.003], [64549.6, 0.0], [64561.9, 0.124], [64562.9, 1.245], [64563.4, 0.233], [64567.2, 7.196], [64567.4, 0.04], [64571.2, 0.001], [64572.9, 25.497]], "asks": [[64573.9, 0.234], [64574.3, 1.393], [64574.4, 0.004], [64574.5, 0.012], [64574.6, 0.001], [64575.5, 0.015], [64579.4, 0.106], [64583.6, 0.445], [64584.8, 0.022], [64585.4, 0.333], [64585.6, 0.025], [64586.4, 0.658], [64589.3, 0.0], [64600.1, 0.008], [64600.2, 0.379], [64605.7, 1.645], [64619.2, 3.994], [64624.6, 2.291], [64624.8, 0.003], [64626.4, 1.472], [64646.8, 6.36], [64713.3, 0.031], [64720.9, 3.108], [65218.7, 0.002], [65501.6, 0.0], [65864.4, 0.018]]}
{"kind": "depth", "E": 1787089597361, "U": 11315996583386, "u": 11315996591081, "recv_ms": 1787089597319, "bids": [[1000.0, 35.76], [14072.9, 0.294], [14172.9, 3.668], [14272.9, 0.238], [51658.0, 0.0], [58115.6, 0.002], [61989.9, 0.026], [63572.9, 0.02], [63770.3, 3.921], [63927.2, 0.005], [64500.0, 22.56], [64516.7, 0.042], [64524.7, 0.003], [64542.6, 0.141], [64542.7, 0.14], [64542.8, 0.121], [64542.9, 0.51], [64546.0, 0.545], [64546.4, 0.217], [64563.3, 0.012], [64563.4, 0.225], [64566.5, 0.042], [64566.6, 0.465], [64567.3, 2.282], [64567.4, 0.482], [64569.6, 1.758]], "asks": [[64574.3, 0.0], [64574.4, 0.004], [64574.5, 0.002], [64575.5, 0.005], [64592.8, 0.258], [64594.1, 0.545], [64644.7, 37.384], [64646.8, 0.859], [64646.9, 0.0], [65088.8, 8.928], [65218.7, 0.002], [65347.1, 30.935], [65350.4, 0.857], [65419.1, 0.267], [65471.7, 0.0], [65573.0, 0.02]]}
{"kind": "depth", "E": 1787089597463, "U": 11315996591249, "u": 11315996601311, "recv_ms": 1787089597422, "bids": [[14072.9, 0.532], [14172.9, 3.542], [14272.9, 0.126], [58115.6, 0.002], [61344.2, 0.001], [63280.7, 0.005], [63281.5, 0.031], [63306.3, 1.358], [63629.6, 0.0], [63927.2, 0.005], [64432.1, 4.264], [64435.1, 1.516], [64495.3, 30.804], [64501.9, 0.001], [64502.0, 4.84], [64542.5, 0.071], [64546.5, 0.061], [64547.6, 0.001], [64548.1, 0.002], [64561.2, 1.088], [64562.1, 0.0], [64562.2, 0.544], [64562.8, 0.056], [64563.1, 0.0], [64567.4, 0.482], [64572.9, 26.235]], "asks": [[64574.2, 1.393], [64574.3, 0.0], [64574.4, 0.004], [64575.5, 0.015], [64576.7, 0.011], [64577.8, 0.015], [64579.4, 0.104], [64580.3, 0.113], [64580.4, 0.642], [64583.5, 0.986], [64592.0, 0.035], [64592.8, 0.258], [64593.4, 0.001], [64593.5, 0.032], [64594.1, 0.545], [64594.5, 0.945], [64595.4, 0.628], [64598.3, 0.154], [64599.3, 2.101], [64600.2, 0.322], [64644.7, 0.001], [64651.3, 37.39], [64713.3, 5.439], [64769.0, 11.41], [65218.7, 0.002], [65320.9, 0.0], [65380.2, 0.23]]}
{"kind": "depth", "E": 1787089597565, "U": 11315996601427, "u": 11315996607490, "recv_ms": 1787089597524, "bids": [[1000.0, 35.76], [14072.9, 0.756], [14172.9, 3.444], [14272.9, 0.0], [58115.6, 0.002], [61989.9, 0.029], [62626.2, 0.604], [63572.9, 0.0], [63927.2, 0.005], [64250.0, 11.687], [64495.3, 0.01], [64501.9, 30.795], [64551.8, 0.001], [64555.5, 0.003], [64555.6, 0.0], [64556.7, 0.134], [64556.9, 0.001], [64557.6, 0.559], [64561.4, 0.039], [64561.8, 2.323], [64562.8, 0.055], [64567.1, 0.034], [64567.4, 0.482], [64572.9, 25.497]], "asks": [[64573.0, 0.461], [64574.0, 0.003], [64574.2, 0.0], [64574.3, 0.0], [64575.5, 0.292], [64576.7, 0.001], [64577.8, 0.015], [64579.9, 0.1], [64580.0, 0.096], [64580.3, 0.105], [64580.6, 41.699], [64583.5, 0.985], [64588.5, 0.094], [64589.0, 0.005], [64592.8, 0.258], [64594.1, 0.545], [64599.4, 0.143], [64600.2, 0.168], [64600.3, 0.162], [64600.5, 0.001], [64646.9, 37.383], [64651.3, 0.007], [64895.9, 0.028], [65089.6, 0.928], [65218.7, 0.002], [65347.9, 3.461], [65355.8, 2.716], [65356.1, 0.614], [65380.2, 0.573], [65420.5, 0.007], [65522.2, 1.837], [65573.0, 0.0], [66510.0, 0.018]]}
{"kind": "depth", "E": 1787089597667, "U": 11315996607587, "u": 11315996614243, "recv_ms": 1787089597627, "bids": [[1000.0, 35.76], [14072.9, 1.12], [14172.9, 3.08], [58115.6, 0.002], [61989.9, 0.026], [63927.1, 0.001], [63927.2, 0.005], [64250.0, 11.689], [64415.1, 0.0], [64416.0, 1.263], [64432.1, 0.022], [64435.1, 0.986], [64551.8, 0.0], [64553.4, 0.667], [64566.7, 0.004], [64567.2, 7.198]], "asks": [[64577.8, 0.015], [64580.0, 0.096], [64582.2, 0.013], [64585.6, 0.014], [64599.8, 0.034], [64600.1, 0.057], [64601.4, 4.555], [64607.3, 0.016], [64713.3, 0.031], [64729.6, 1.378], [64730.2, 0.0], [65088.0, 3.958], [65218.7, 0.002], [65444.7, 1.143]]}
{"kind": "depth", "E": 1787089597769, "U": 11315996614423, "u": 11315996620388, "recv_ms": 1787089597726, "bids": [[14072.9, 1.47], [14172.9, 2.73], [58115.6, 0.002], [61344.2, 0.001], [61989.9, 0.029], [63572.9, 0.02], [63927.2, 0.005], [64457.2, 4.17], [64501.4, 0.047], [64531.9, 0.13], [64539.6, 0.002], [64567.3, 2.286], [64572.9, 25.532]], "asks": [[64577.8, 0.015], [64579.5, 0.003], [64580.0, 0.096], [64643.5, 3.777], [64643.6, 0.046], [64711.9, 0.0], [64713.6, 0.013], [64713.8, 3.872], [65218.7, 0.002], [65573.0, 0.02]]}
{"kind": "depth", "E": 1787089597871, "U": 11315996620442, "u": 11315996625920, "recv_ms": 1787089597829, "bids": [[1000.0, 35.76], [14072.9, 1.834], [14172.9, 2.366], [51658.0, 0.0], [58115.6, 0.002], [61989.9, 0.026], [62629.3, 2.347], [63281.5, 0.034], [63795.9, 2.975], [63797.2, 29.267], [63927.2, 0.005], [64250.0, 11.679], [64376.2, 0.001], [64376.4, 6.139], [64376.5, 0.091], [64377.2, 0.479], [64415.1, 6.986], [64416.0, 2.107], [64432.1, 4.256], [64553.4, 0.666], [64554.7, 0.006], [64556.1, 0.005], [64563.1, 0.001]], "asks": [[64575.5, 0.282], [64577.8, 0.023], [64580.0, 0.088], [64583.8, 0.286], [64588.5, 0.094], [64713.3, 5.439], [64730.2, 10.428], [64768.4, 0.687], [64768.9, 0.0], [64769.0, 11.292], [65391.9, 0.786], [65523.3, 1.523], [66064.6, 0.0], [66178.4, 0.454]]}
{"kind": "depth", "E": 1787089597973, "U": 11315996626013, "u": 11315996632191, "recv_ms": 1787089597931, "bids": [[1000.0, 35.76], [14072.9, 2.198], [14172.9, 2.002], [58115.6, 0.002], [61343.6, 0.009], [61344.2, 0.001], [63572.9, 0.0], [63636.6, 1.727], [63641.1, 0.0], [63742.1, 0.962], [63765.7, 0.237], [63798.0, 0.241], [63804.5, 3.76], [63927.2, 0.005], [63994.1, 3.172], [63994.9, 0.016], [64154.1, 0.0], [64154.9, 0.008], [64314.5, 0.0], [64315.3, 4.511], [64475.3, 0.007], [64476.1, 0.006], [64551.0, 0.001], [64554.7, 0.005], [64572.9, 25.5]], "asks": [[64575.4, 0.012], [64577.8, 0.023], [64579.2, 0.092], [64579.3, 0.208], [64580.0, 0.088], [64644.7, 0.001], [64646.9, 0.0], [64649.1, 37.383], [64669.0, 0.0], [64669.8, 0.01], [64830.7, 0.0], [64831.5, 0.007], [64992.7, 0.247], [64993.6, 0.765], [65155.2, 0.469], [65156.0, 0.512], [65218.7, 0.002], [65392.0, 0.07], [65573.0, 0.0]]}
{"kind": "depth", "E": 1787089598075, "U": 11315996632250, "u": 11315996640223, "recv_ms": 1787089598037, "bids": [[14072.9, 2.548], [14172.9, 1.652], [51658.0, 0.004], [58115.6, 0.002], [61527.6, 0.003], [61528.3, 0.014], [61989.9, 0.029], [61990.0, 0.485], [63572.9, 0.02], [63655.3, 0.0], [63798.0, 0.46], [63927.2, 0.005], [64502.3, 1.473], [64524.9, 0.007], [64531.9, 0.126], [64540.7, 0.016], [64541.0, 2.609], [64547.9, 1.006], [64555.3, 0.624], [64561.3, 0.001], [64561.8, 2.32], [64566.7, 0.007], [64572.9, 25.498]], "asks": [[64573.0, 0.462], [64591.3, 0.714], [64600.3, 0.008], [64600.4, 0.204], [64603.0, 0.036], [64619.2, 0.494], [64620.9, 5.085], [64624.7, 0.0], [64641.8, 0.0], [64646.9, 37.493], [64649.1, 0.0], [65218.7, 0.002], [65256.3, 0.0], [65412.4, 0.936], [65488.9, 0.002], [65573.0, 0.02], [65573.1, 9.743], [67597.4, 0.0], [67598.2, 0.043]]}
{"kind": "depth", "E": 1787089598177, "U": 11315996640234, "u": 11315996646870, "recv_ms": 1787089598135, "bids": [[1000.0, 35.76], [14072.9, 2.898], [14172.9, 1.302], [51658.0, 0.002], [58115.6, 0.002], [61344.2, 0.001], [61989.9, 0.026], [63576.5, 0.0], [63588.1, 0.787], [63589.1, 1.028], [63653.0, 0.835], [63653.9, 0.008], [63656.1, 0.008], [63798.0, 1.242], [63927.2, 0.005], [63939.6, 0.0], [63965.9, 0.623], [64250.0, 11.679], [64470.5, 0.018], [64514.7, 0.018], [64551.0, 0.0], [64553.5, 0.312], [64561.2, 0.161], [64562.3, 1.204]], "asks": [[64583.4, 2.362], [64588.2, 0.54], [64598.7, 0.633], [64603.1, 0.001], [64624.6, 0.0], [64631.2, 0.0], [65218.7, 0.002], [65291.3, 0.765], [65491.2, 0.013], [65556.0, 0.473], [66033.7, 0.605], [66187.3, 0.075]]}
{"kind": "depth", "E": 1787089598279, "U": 11315996646964, "u": 11315996653055, "recv_ms": 1787089598238, "bids": [[1000.0, 35.76], [14072.9, 3.262], [14172.9, 0.938], [51658.0, 0.0], [51658.3, 0.0], [58115.6, 0.002], [61343.6, 0.007], [61989.9, 0.029], [63927.2, 0.005], [64473.4, 1.921], [64502.0, 8.228], [64505.1, 6.001], [64527.7, 3.558], [64541.3, 5.003], [64543.9, 0.997], [64550.0, 0.014], [64553.5, 0.311], [64555.9, 0.503], [64561.1, 0.373], [64563.7, 0.295]], "asks": [[64605.9, 1.335], [64620.8, 2.716], [64621.2, 0.001], [64622.0, 3.664], [64644.6, 6.0], [64646.8, 6.376], [64675.4, 0.769], [64676.1, 0.122], [64713.7, 1.353], [64714.4, 0.131], [64769.0, 11.442], [65218.7, 0.002], [65276.9, 0.978], [65477.0, 0.503], [65489.9, 0.236], [65492.1, 0.01], [65556.9, 0.763]]}
{"kind": "depth", "E": 1787089598381, "U": 11315996653153, "u": 11315996660952, "recv_ms": 1787089598339, "bids": [[14072.9, 3.612], [14172.9, 0.588], [58115.6, 0.002], [61344.2, 0.001], [63023.2, 0.009], [63506.7, 2.202], [63572.9, 0.0], [63635.8, 19.269], [63723.8, 0.006], [63794.8, 1.111], [63927.2, 0.005], [64338.0, 7.015], [64370.5, 0.794], [64377.2, 0.478], [64495.3, 0.01], [64499.7, 31.047], [64501.9, 0.001], [64502.0, 4.84], [64531.9, 0.13], [64540.7, 0.012], [64547.9, 0.387], [64555.3, 0.005], [64555.9, 0.502], [64558.2, 0.336], [64562.2, 0.002], [64563.1, 0.543], [64564.0, 0.003], [64572.8, 0.093], [64572.9, 25.504]], "asks": [[64573.0, 0.448], [64579.5, 0.001], [64579.6, 0.006], [64583.4, 2.361], [64591.3, 0.095], [64598.7, 0.014], [64644.7, 37.494], [64646.8, 0.859], [64646.9, 0.0], [64725.4, 0.001], [64764.6, 0.0], [64769.0, 11.394], [65218.7, 0.002], [65347.1, 30.172], [65477.0, 0.686], [65559.9, 0.655], [65573.0, 0.0], [65573.9, 2.136]]}
{"kind": "depth", "E": 1787089598483, "U": 11315996661125, "u": 11315996666691, "recv_ms": 1787089598440, "bids": [[1000.0, 35.76], [14072.9, 3.752], [14172.9, 0.336], [14472.9, 0.112], [58115.6, 0.002], [61344.3, 0.002], [61989.9, 0.026], [63280.7, 0.002], [63606.2, 0.004], [63651.1, 0.003], [63927.2, 0.005], [64250.0, 11.689], [64472.7, 10.087], [64473.4, 3.319], [64547.9, 0.388], [64558.2, 0.335]], "asks": [[64577.8, 0.015], [64579.2, 0.073], [64580.0, 0.053], [64642.5, 37.508], [64644.7, 0.001], [64675.4, 2.199], [64677.0, 12.62], [65218.7, 0.002], [65270.5, 0.0], [65818.1, 0.4]]}
{"kind": "depth", "E": 1787089598687, "U": 11315996673106, "u": 11315996679355, "recv_ms": 1787089598644, "bids": [[14072.9, 3.514], [14172.9, 0.098], [14472.9, 0.588], [51658.0, 0.0], [58115.6, 0.002], [61344.2, 0.005], [61344.3, 0.004], [61989.9, 0.026], [62376.6, 0.0], [63507.4, 1.119], [63636.6, 3.925], [63927.1, 0.0], [63927.2, 0.005], [64250.0, 11.687], [64432.1, 4.256], [64529.3, 0.027], [64552.7, 0.052], [64563.2, 0.364]], "asks": [[64573.0, 0.449], [64631.2, 0.003], [64713.3, 5.439], [64769.0, 11.293], [65218.7, 0.002], [66962.1, 0.006], [71030.3, 0.002]]}
{"kind": "depth", "E": 1787089598789, "U": 11315996679426, "u": 11315996686966, "recv_ms": 1787089598745, "bids": [[1000.0, 35.76], [14072.9, 3.346], [14172.9, 0.0], [14472.9, 0.854], [58115.6, 0.002], [61343.6, 0.005], [61344.2, 0.005], [61989.9, 0.029], [63281.5, 0.037], [63572.9, 0.0], [63846.5, 2.752], [63923.9, 0.002], [63925.7, 0.0], [63926.5, 0.387], [63927.2, 0.005], [63943.2, 0.0], [64250.0, 11.677], [64432.1, 0.022], [64551.3, 0.171], [64569.4, 0.005], [64571.4, 0.003]], "asks": [[64573.0, 0.45], [64576.6, 0.001], [64576.7, 0.009], [64576.8, 0.668], [64577.8, 0.023], [64583.6, 0.482], [64588.5, 0.094], [64590.3, 0.01], [64591.9, 0.015], [64592.0, 0.027], [64713.3, 0.031], [64895.9, 0.03], [65218.7, 0.002], [65291.2, 1.166], [65573.0, 0.0], [71030.3, 0.0]]}
{"kind": "depth", "E": 1787089598891, "U": 11315996687172, "u": 11315996695234, "recv_ms": 1787089598847, "bids": [[1000.0, 35.76], [14072.9, 2.996], [14472.9, 1.204], [58115.6, 0.002], [63022.4, 0.488], [63179.2, 1.583], [63797.3, 0.001], [63927.2, 0.005], [64415.1, 0.0], [64415.2, 7.09], [64432.1, 4.307], [64556.1, 0.005], [64572.9, 25.506]], "asks": [[64578.1, 0.019], [64578.3, 0.58], [64588.5, 0.094], [64601.6, 1.894], [64601.7, 1.041], [64713.3, 5.439], [64730.2, 10.428], [64769.0, 10.981], [64895.1, 4.619], [65088.8, 8.621], [65218.7, 0.002]]}
{"kind": "depth", "E": 1787089598993, "U": 11315996695564, "u": 11315996703073, "recv_ms": 1787089598950, "bids": [[14072.9, 2.646], [14472.9, 1.554], [58115.6, 0.002], [61344.2, 0.005], [61989.9, 0.026], [61990.0, 0.479], [63572.9, 0.02], [63869.0, 0.717], [63927.2, 0.005], [63965.9, 1.312]], "asks": [[64576.7, 0.009], [64577.8, 0.023], [64588.5, 0.094], [64590.3, 0.01], [64591.9, 0.015], [64605.3, 0.004], [64618.2, 0.002], [64619.4, 0.072], [64632.3, 0.004], [64642.5, 37.503], [64649.1, 0.0], [64657.7, 1.003], [64671.1, 0.001], [65218.7, 0.002], [65573.0, 0.02]]}
{"kind": "depth", "E": 1787089599095, "U": 11315996703343, "u": 11315996710974, "recv_ms": 1787089599053, "bids": [[1000.0, 35.91], [14072.9, 2.282], [14472.9, 1.918], [58115.6, 0.002], [61989.9, 0.029], [63588.3, 0.0], [63927.2, 0.005], [63946.5, 2.182], [64250.0, 11.687], [64522.4, 0.005], [64529.6, 0.648], [64549.6, 0.001], [64561.3, 0.001]], "asks": [[64575.4, 0.002], [64578.2, 0.019], [64598.9, 2.739], [64642.5, 37.503], [64649.1, 0.0], [64895.1, 4.465], [65218.7, 0.002], [65288.1, 0.03], [65356.1, 0.271], [65380.2, 0.916], [65489.9, 0.464], [65556.1, 0.005]]}
{"kind": "depth", "E": 1787089599197, "U": 11315996711088, "u": 11315996718552, "recv_ms": 1787089599154, "bids": [[1000.0, 35.76], [14072.9, 1.932], [14472.9, 2.268], [58115.6, 0.002], [61344.2, 0.005], [61989.9, 0.026], [63281.5, 0.034], [63572.9, 0.0], [63589.1, 1.037], [63789.4, 9.839], [63817.4, 1.1], [63927.2, 0.005], [64432.1, 4.307], [64549.6, 0.0], [64551.9, 0.002], [64557.4, 0.628], [64564.7, 0.003], [64568.1, 0.019], [64572.9, 26.253]], "asks": [[64579.5, 0.003], [64579.6, 0.004], [64584.6, 0.0], [64599.4, 0.027], [64599.7, 0.157], [64604.3, 1.133], [64611.6, 0.311], [64713.3, 5.439], [64895.9, 0.184], [65089.6, 1.235], [65218.7, 0.002], [65302.5, 0.297], [65573.0, 0.0], [65863.6, 0.009], [65864.4, 0.021]]}
{"kind": "depth", "E": 1787089599299, "U": 11315996718645, "u": 11315996728413, "recv_ms": 1787089599262, "bids": [[14072.9, 1.568], [14472.9, 2.632], [51658.3, 0.0], [58115.6, 0.002], [61344.2, 0.005], [61989.9, 0.029], [63022.4, 0.473], [63281.5, 0.031], [63572.9, 0.02], [63656.0, 0.264], [63927.2, 0.011], [64377.2, 1.333], [64435.1, 1.522], [64502.0, 8.264], [64537.4, 0.326], [64540.5, 1.276], [64541.4, 0.016], [64542.1, 0.007], [64543.9, 0.991], [64545.5, 0.147], [64547.5, 0.001], [64548.2, 0.015], [64548.9, 0.001], [64551.4, 0.311], [64551.9, 0.001], [64553.7, 0.07], [64554.5, 1.24], [64554.9, 2.322], [64555.4, 0.117], [64556.4, 0.558], [64556.7, 0.018], [64557.6, 0.001], [64557.9, 0.001], [64558.2, 0.336], [64558.4, 0.352], [64559.2, 0.007], [64559.8, 0.0], [64560.8, 0.928], [64561.2, 0.168], [64561.7, 0.323], [64561.9, 0.132], [64562.3, 0.277], [64562.4, 0.542], [64562.5, 0.314], [64563.1, 0.008], [64563.2, 0.388], [64563.9, 0.631], [64564.5, 0.107], [64564.9, 0.07], [64566.1, 0.01], [64567.2, 0.283], [64567.3, 2.131], [64567.5, 0.0], [64567.9, 0.096], [64568.1, 0.081], [64568.5, 0.001], [64569.6, 0.783], [64570.0, 1.243], [64570.5, 0.238], [64571.2, 2.001], [64572.2, 1.132], [64572.3, 0.0], [64572.8, 0.094], [64572.9, 26.203]], "asks": [[64574.5, 0.0], [64575.4, 0.012], [64576.7, 0.003], [64576.8, 0.131], [64576.9, 0.001], [64577.8, 0.015], [64577.9, 0.005], [64578.0, 0.006], [64578.2, 0.005], [64578.6, 0.017], [64579.0, 0.02], [64579.4, 0.02], [64579.5, 1.804], [64579.6, 0.995], [64579.7, 0.31], [64580.0, 0.045], [64580.1, 0.002], [64580.4, 1.819], [64580.6, 41.647], [64580.8, 0.093], [64581.0, 0.0], [64581.2, 0.087], [64581.5, 0.091], [64581.9, 0.106], [64582.0, 0.086], [64582.1, 0.003], [64582.3, 0.085], [64582.6, 0.098], [64583.0, 0.2], [64583.1, 0.44], [64583.4, 2.445], [64583.6, 0.602], [64583.7, 2.966], [64583.8, 0.285], [64584.1, 0.396], [64585.4, 0.313], [64588.5, 0.009], [64589.8, 0.086], [64589.9, 0.556], [64590.3, 0.002], [64591.3, 0.103], [64591.8, 0.025], [64591.9, 0.008], [64592.0, 0.027], [64592.1, 1.386], [64592.7, 0.12], [64592.8, 0.8], [64593.2, 0.001], [64593.4, 0.001], [64593.6, 0.442], [64594.1, 0.003], [64594.2, 1.596], [64594.5, 0.018], [64595.4, 0.009], [64595.8, 0.125], [64596.4, 0.659], [64596.7, 0.015], [64596.9, 0.0], [64597.2, 0.095], [64597.6, 0.565], [64597.7, 0.046], [64598.1, 0.505], [64598.2, 0.0], [64598.4, 0.031], [64598.9, 2.753], [64599.2, 0.116], [64599.7, 0.041], [64600.6, 0.0], [64601.0, 0.067], [64601.2, 0.032], [64601.3, 2.41], [64602.3, 0.034], [64604.6, 0.163], [64608.6, 1.641], [64611.9, 0.795], [64620.8, 0.082], [64620.9, 0.0], [64625.7, 0.024], [64625.9, 0.668], [64629.6, 10.0], [64637.1, 0.387], [64643.9, 3.021], [64663.8, 0.004], [64689.3, 0.0], [64689.5, 0.0], [64689.6, 0.098], [64712.9, 1.215], [64729.6, 2.756], [64768.4, 2.193], [65218.7, 0.002], [65262.9, 1.531], [65289.9, 0.236], [65327.3, 7.991], [65347.9, 4.438], [65556.9, 0.772], [65573.0, 0.02], [65864.4, 0.024]]}
{"kind": "depth", "E": 1787089599401, "U": 11315996728446, "u": 11315996748633, "recv_ms": 1787089599362, "bids": [[1000.0, 35.76], [14072.9, 1.218], [14472.9, 2.982], [58115.6, 0.002], [61344.2, 0.005], [63281.5, 0.04], [63648.7, 0.0], [63927.2, 0.005], [64250.0, 11.677], [64406.3, 0.0], [64425.2, 0.001], [64438.6, 0.0], [64439.9, 1.115], [64452.4, 0.277], [64475.4, 0.003], [64477.4, 0.031], [64480.7, 0.193], [64480.8, 0.029], [64480.9, 0.0], [64481.0, 0.036], [64481.8, 0.049], [64483.9, 2.558], [64488.3, 0.01], [64490.3, 2.347], [64491.1, 0.0], [64499.7, 31.264], [64501.2, 0.002], [64501.3, 0.005], [64501.9, 0.001], [64502.4, 0.047], [64503.0, 0.145], [64503.3, 0.37], [64503.6, 0.0], [64505.0, 0.468], [64518.2, 0.001], [64521.2, 0.687], [64528.1, 0.17], [64529.6, 0.438], [64531.9, 0.126], [64532.8, 0.436], [64539.4, 0.005], [64539.9, 0.005], [64540.0, 0.174], [64541.7, 0.038], [64542.0, 0.005], [64546.0, 0.545], [64549.3, 0.005], [64550.3, 0.484], [64550.4, 0.324], [64551.4, 0.001], [64552.7, 0.003], [64553.5, 0.36], [64554.7, 0.004], [64556.4, 0.0], [64556.5, 0.083], [64556.8, 1.588], [64557.6, 0.003], [64558.2, 0.335], [64558.4, 0.35], [64558.5, 1.126], [64560.3, 0.475], [64560.6, 0.025], [64560.8, 0.001], [64561.1, 0.373], [64561.2, 0.161], [64561.9, 0.125], [64562.0, 0.001], [64562.1, 0.008], [64562.4, 0.927], [64562.9, 1.246], [64563.1, 0.0], [64563.7, 0.837], [64563.8, 0.543], [64564.0, 0.088], [64564.5, 0.029], [64566.9, 1.787], [64567.0, 0.063], [64567.3, 0.034], [64568.1, 0.0], [64568.2, 0.085], [64570.0, 1.243], [64570.7, 0.233], [64571.0, 0.311], [64571.1, 0.001], [64571.6, 0.058], [64572.3, 0.001], [64572.9, 25.572]], "asks": [[64575.4, 0.012], [64575.5, 0.005], [64575.7, 0.002], [64576.3, 0.007], [64576.7, 0.011], [64576.8, 0.612], [64576.9, 1.625], [64577.6, 0.002], [64578.1, 0.072], [64578.2, 1.862], [64578.3, 0.558], [64579.2, 0.08], [64579.3, 0.093], [64579.4, 0.028], [64579.5, 1.804], [64579.6, 0.004], [64579.7, 0.0], [64580.0, 0.355], [64580.1, 0.001], [64580.3, 0.55], [64580.4, 1.803], [64580.5, 7.394], [64580.8, 0.009], [64580.9, 0.117], [64581.2, 0.003], [64581.3, 0.551], [64581.5, 0.007], [64581.7, 0.171], [64581.9, 0.022], [64582.3, 0.001], [64583.3, 0.283], [64583.6, 0.57], [64584.1, 0.396], [64584.5, 0.088], [64584.7, 0.163], [64584.8, 0.019], [64585.0, 0.221], [64585.2, 2.262], [64585.5, 0.002], [64585.7, 0.095], [64586.4, 0.021], [64587.9, 0.591], [64588.1, 0.063], [64588.9, 0.009], [64589.0, 0.09], [64589.8, 0.001], [64589.9, 0.007], [64590.3, 0.002], [64591.0, 0.012], [64591.3, 0.095], [64591.8, 0.005], [64591.9, 0.0], [64592.0, 0.035], [64592.8, 0.258], [64593.5, 0.032], [64593.7, 0.01], [64594.0, 0.543], [64594.1, 0.003], [64594.2, 0.676], [64594.7, 0.928], [64594.8, 1.238], [64594.9, 0.044], [64595.0, 0.709], [64596.4, 0.661], [64597.0, 0.131], [64597.2, 0.093], [64597.6, 0.008], [64598.6, 0.558], [64599.8, 0.014], [64600.1, 0.008], [64600.4, 0.0], [64600.8, 0.464], [64601.5, 1.24], [64601.6, 0.009], [64602.4, 0.285], [64604.6, 0.093], [64605.3, 0.468], [64605.7, 1.525], [64606.5, 0.002], [64606.9, 0.05], [64607.3, 0.065], [64611.5, 0.136], [64612.3, 0.079], [64613.5, 0.07], [64613.9, 0.09], [64614.4, 0.005], [64617.0, 0.031], [64618.8, 0.005], [64619.1, 2.32], [64619.2, 0.434], [64626.0, 0.317], [64627.9, 5.085], [64629.6, 0.0], [64633.4, 0.0], [64638.6, 0.21], [64640.1, 0.0], [64642.5, 0.015], [64643.1, 0.002], [64644.7, 37.489], [64645.1, 0.0], [64646.7, 0.047], [64648.9, 0.0], [64649.1, 0.0], [64650.2, 2.322], [64652.1, 0.014], [64657.3, 0.0], [64659.1, 0.107], [64664.3, 0.0], [64666.2, 0.015], [64671.4, 0.027], [64673.2, 0.013], [64678.4, 0.006], [64680.3, 4.371], [64683.3, 0.003], [64685.5, 0.006], [64687.3, 0.013], [64692.5, 0.001], [64694.4, 0.016], [64699.6, 0.0], [64701.5, 0.013], [64895.9, 0.338], [65218.7, 0.004], [65488.7, 2.452], [65580.3, 0.002], [65864.4, 0.027]]}
{"kind": "depth", "E": 1787089599503, "U": 11315996748699, "u": 11315996755396, "recv_ms": 1787089599460, "bids": [[14072.9, 0.854], [14472.9, 3.346], [51658.0, 0.0], [58115.6, 0.002], [61344.2, 0.005], [61989.9, 0.026], [62935.3, 0.239], [63795.9, 2.036], [63927.2, 0.005], [64249.2, 6.495], [64495.3, 31.259], [64495.4, 1.98], [64499.7, 0.015], [64501.9, 0.001], [64514.7, 0.015], [64553.5, 0.363], [64559.1, 0.006], [64560.3, 0.474], [64561.1, 0.003], [64563.5, 0.002], [64563.7, 0.011], [64564.0, 0.003], [64564.5, 0.022], [64565.0, 0.384], [64566.5, 0.034], [64566.8, 0.032], [64566.9, 0.239], [64567.0, 0.001], [64567.3, 0.015], [64569.7, 0.066], [64570.1, 0.316], [64570.3, 6.915], [64570.5, 2.436], [64570.7, 0.001], [64571.2, 0.001], [64572.1, 0.232], [64572.2, 1.811], [64572.9, 25.542]], "asks": [[64575.4, 0.002], [64576.7, 0.003], [64579.2, 0.07], [64579.3, 0.093], [64579.4, 0.02], [64579.5, 1.802], [64580.1, 0.085], [64584.2, 0.001], [64584.5, 0.004], [64588.5, 0.029], [64589.0, 0.082], [64591.0, 0.004], [64591.6, 0.002], [64592.0, 0.027], [64597.0, 0.111], [64600.6, 0.0], [64600.7, 0.087], [64600.8, 0.31], [64600.9, 0.156], [64603.3, 1.924], [64631.2, 0.0], [65218.7, 0.002], [65509.3, 4.454], [65541.6, 0.381], [67155.8, 0.0]]}
{"kind": "depth", "E": 1787089599605, "U": 11315996755485, "u": 11315996761926, "recv_ms": 1787089599562, "bids": [[14072.9, 0.504], [14472.9, 3.696], [51658.0, 0.0], [58115.6, 0.002], [61989.9, 0.029], [63572.9, 0.0], [63804.5, 4.699], [63829.5, 5.084], [63927.2, 0.005], [64495.3, 0.01], [64499.7, 31.264], [64502.0, 4.84], [64540.4, 2.359], [64542.3, 0.001], [64555.4, 0.001], [64556.8, 1.03], [64556.9, 0.117], [64558.3, 0.786], [64565.6, 0.528], [64566.1, 0.003], [64569.6, 0.497], [64569.7, 0.004], [64570.1, 0.378]], "asks": [[64576.7, 0.011], [64579.4, 0.028], [64579.8, 0.085], [64579.9, 0.186], [64580.5, 7.401], [64581.5, 0.0], [64584.1, 0.312], [64586.0, 0.015], [64586.6, 2.858], [64589.0, 0.09], [64591.0, 0.012], [64592.0, 0.035], [64599.2, 0.0], [64599.8, 0.13], [64600.9, 0.002], [64669.1, 0.0], [65218.7, 0.002], [65573.0, 0.0], [66058.2, 2.271], [67134.8, 1.911]]}
{"kind": "depth", "E": 1787089599707, "U": 11315996761973, "u": 11315996772184, "recv_ms": 1787089599668, "bids": [[1000.0, 35.76], [14072.9, 0.308], [14372.9, 0.168], [14472.9, 3.724], [58115.6, 0.002], [61344.2, 0.005], [61989.9, 0.026], [63273.0, 0.0], [63281.5, 0.043], [63344.8, 0.789], [63416.5, 0.0], [63488.2, 0.736], [63560.0, 2.593], [63572.9, 0.02], [63631.7, 0.0], [63660.9, 0.807], [63703.4, 0.004], [63775.2, 10.439], [63846.9, 3.593], [63918.7, 0.01], [63927.2, 0.007], [64250.0, 11.832], [64432.1, 0.022], [64432.9, 5.791], [64537.7, 0.087], [64545.5, 0.141], [64545.8, 0.006], [64549.8, 0.017], [64556.2, 0.117], [64556.9, 0.003], [64557.0, 0.002], [64557.2, 0.558], [64557.6, 0.001], [64558.3, 0.228], [64559.9, 0.001], [64560.5, 0.01], [64560.6, 0.017], [64561.6, 1.144], [64561.9, 0.125], [64562.4, 0.0], [64562.8, 0.003], [64563.1, 0.543], [64563.5, 0.001], [64563.6, 0.073], [64563.7, 0.63], [64563.8, 0.001], [64564.0, 0.062], [64565.0, 0.383], [64567.2, 0.303], [64569.9, 2.32], [64570.1, 0.146], [64570.2, 0.002], [64570.3, 6.917], [64570.5, 1.802], [64570.6, 0.002], [64570.8, 0.0], [64571.3, 0.104], [64572.9, 27.042]], "asks": [[64573.0, 0.493], [64574.6, 0.011], [64575.5, 0.292], [64575.8, 0.001], [64576.7, 0.011], [64576.8, 0.612], [64578.1, 0.072], [64578.2, 1.82], [64578.7, 0.004], [64579.4, 0.02], [64579.5, 0.001], [64579.8, 0.001], [64580.0, 0.053], [64580.1, 0.311], [64580.2, 0.544], [64580.3, 0.008], [64580.4, 0.002], [64580.5, 7.313], [64580.6, 41.731], [64580.9, 0.117], [64581.0, 0.007], [64582.1, 0.087], [64583.1, 0.41], [64583.6, 0.45], [64583.8, 0.286], [64584.1, 0.446], [64584.2, 0.02], [64586.4, 0.649], [64586.6, 2.549], [64587.8, 0.309], [64588.2, 0.62], [64589.0, 0.082], [64589.7, 0.004], [64590.5, 0.032], [64591.0, 0.004], [64592.0, 0.043], [64592.1, 1.346], [64592.5, 0.543], [64593.7, 0.01], [64593.9, 0.211], [64594.0, 0.001], [64594.1, 0.003], [64595.8, 0.127], [64596.4, 0.659], [64596.6, 0.076], [64597.3, 0.01], [64597.5, 0.029], [64598.6, 0.558], [64598.9, 2.739], [64599.7, 0.091], [64600.8, 0.31], [64601.2, 0.038], [64601.3, 2.558], [64606.9, 0.0], [64609.4, 0.0], [64612.7, 0.196], [64617.3, 0.286], [64618.2, 0.0], [64618.8, 0.007], [64619.2, 0.432], [64619.5, 0.056], [64620.6, 5.021], [64627.4, 5.09], [64627.9, 0.0], [64633.3, 0.001], [64689.8, 0.113], [64713.3, 5.439], [65209.9, 1.531], [65218.7, 0.002], [65281.7, 0.0], [65353.4, 1.273], [65413.3, 0.076], [65425.2, 0.0], [65496.9, 0.007], [65568.6, 1.497], [65573.0, 0.02], [65640.4, 0.036], [65712.1, 0.0], [65783.8, 1.008], [65855.6, 0.002], [65864.4, 0.03]]}
{"kind": "depth", "E": 1787089599809, "U": 11315996772280, "u": 11315996777737, "recv_ms": 1787089599767, "bids": [[14072.9, 0.182], [14372.9, 0.392], [14472.9, 3.626], [58115.6, 0.002], [61344.2, 0.005], [61344.3, 0.006], [63281.5, 0.04], [63927.2, 0.005], [64250.0, 11.834], [64553.7, 0.071], [64554.7, 0.084], [64556.5, 0.003], [64557.0, 0.001], [64563.6, 0.065], [64563.7, 0.011], [64564.0, 0.055], [64564.1, 0.002], [64570.0, 1.243], [64570.1, 0.146], [64570.6, 0.628], [64570.7, 0.009], [64571.3, 0.085], [64572.9, 25.575]], "asks": [[64574.6, 0.001], [64575.5, 0.282], [64576.7, 0.003], [64576.8, 0.612], [64578.1, 0.08], [64580.0, 1.854], [64580.2, 0.628], [64584.1, 0.362], [64592.5, 0.001], [64592.8, 0.258], [64594.0, 0.543], [64594.1, 0.003], [64594.7, 0.62], [64595.2, 1.102], [64595.8, 0.125], [64596.3, 0.01], [64596.4, 0.04], [64600.1, 0.057], [64601.3, 2.404], [64603.2, 2.401], [64603.3, 0.039], [64606.7, 0.108], [64607.3, 0.016], [64613.9, 0.0], [64895.9, 0.336], [65218.7, 0.002]]}
{"kind": "depth", "E": 1787089600013, "U": 11315996783852, "u": 11315996788549, "recv_ms": 1787089599971, "bids": [[1000.0, 35.76], [14072.9, 0.0], [14372.9, 0.938], [14472.9, 3.262], [58115.6, 0.002], [61989.9, 0.026], [63572.9, 0.0], [63795.9, 1.097], [63927.2, 0.005], [63934.6, 0.004], [63936.9, 0.002], [64055.5, 8.885], [64056.3, 0.951], [64250.0, 11.844], [64387.3, 0.0], [64550.3, 0.484], [64556.3, 0.015], [64560.5, 0.002], [64561.9, 0.133]], "asks": [[64601.0, 0.067], [64601.1, 0.392], [64601.3, 2.404], [65218.7, 0.002], [65327.3, 6.463], [65356.1, 0.012], [65573.0, 0.0], [65657.5, 0.761], [65710.1, 0.0]]}
{"kind": "depth", "E": 1787089600115, "U": 11315996788603, "u": 11315996796005, "recv_ms": 1787089600075, "bids": [[14372.9, 1.288], [14472.9, 2.912], [58115.6, 0.002], [61344.2, 0.005], [61989.9, 0.029], [63208.4, 2.37], [63281.5, 0.043], [63572.9, 0.02], [63589.3, 0.007], [63589.4, 0.275], [63603.6, 0.013], [63804.5, 5.638], [63927.2, 0.007], [64500.3, 0.126], [64527.1, 0.134], [64527.4, 0.0], [64540.1, 0.314], [64540.2, 0.11], [64540.3, 0.002], [64543.6, 0.041], [64543.7, 0.066], [64546.3, 0.001], [64554.8, 0.466], [64556.3, 0.014], [64561.3, 0.001], [64562.1, 0.0], [64563.1, 0.542], [64563.8, 0.002], [64564.3, 0.0], [64568.3, 0.001], [64569.6, 0.747], [64569.8, 0.235], [64570.7, 0.094], [64571.1, 0.003], [64572.6, 0.0], [64572.7, 0.01], [64572.9, 25.595]], "asks": [[64573.8, 0.0], [64578.1, 0.08], [64579.8, 0.009], [64580.0, 1.846], [64583.8, 0.285], [64584.5, 0.005], [64584.9, 0.001], [64585.0, 0.221], [64589.9, 0.015], [64590.5, 0.024], [64591.3, 0.103], [64592.0, 0.035], [64622.0, 3.666], [64622.5, 0.274], [64630.5, 0.689], [64630.8, 0.003], [64690.1, 0.0], [64704.3, 0.001], [65218.7, 0.002], [65452.9, 1.386], [65554.9, 0.002], [65555.0, 76.244], [65573.0, 0.02], [65580.5, 1.307], [65657.8, 2.285], [65838.8, 0.65], [65870.9, 0.0]]}
{"kind": "depth", "E": 1787089600319, "U": 11315996802465, "u": 11315996809544, "recv_ms": 1787089600276, "bids": [[1000.0, 35.76], [14372.9, 2.002], [14472.9, 2.198], [51658.0, 0.0], [51658.3, 0.0], [58115.6, 0.002], [61344.2, 0.005], [61344.3, 0.008], [63216.9, 0.316], [63604.4, 0.009], [63927.2, 0.005], [64502.0, 8.306], [64548.8, 0.626], [64552.0, 0.622], [64554.7, 0.004], [64558.1, 0.004], [64559.4, 0.641], [64562.5, 0.314], [64564.1, 0.002], [64569.4, 0.005], [64569.8, 0.003], [64571.1, 0.001], [64571.4, 0.005], [64572.8, 0.096], [64572.9, 25.585]], "asks": [[64579.6, 0.006], [64584.8, 0.019], [64594.7, 0.62], [64595.4, 0.628], [64596.4, 0.04], [64601.0, 0.067], [64601.1, 0.392], [64602.8, 0.89], [64621.9, 2.871], [64622.9, 10.019], [64627.4, 0.005], [64643.9, 8.24], [64723.2, 2.046], [65218.7, 0.002], [65291.3, 1.53], [65555.8, 0.018], [65735.3, 0.607]]}
{"kind": "depth", "E": 1787089600421, "U": 11315996809747, "u": 11315996816035, "recv_ms": 1787089600378, "bids": [[14372.9, 2.366], [14472.9, 1.834], [51658.0, 0.0], [58115.6, 0.002], [61989.9, 0.029], [63572.9, 0.0], [63927.2, 0.005], [64554.5, 1.241], [64558.1, 0.003], [64563.1, 0.0], [64565.6, 0.218]], "asks": [[64575.4, 0.002], [64575.8, 0.004], [64579.6, 0.004], [64579.8, 0.093], [64583.7, 2.882], [64601.1, 0.392], [64652.1, 0.001], [64652.5, 1.343], [64659.1, 0.094], [64659.6, 0.013], [64666.2, 0.002], [64666.6, 0.053], [64673.2, 0.0], [64673.7, 0.013], [64680.3, 4.358], [64680.7, 0.013], [64687.3, 0.0], [64687.8, 0.013], [64694.4, 0.003], [64694.8, 7.409], [64701.5, 0.0], [64701.9, 0.014], [65163.3, 0.0], [65218.7, 0.002], [65573.0, 0.0]]}
{"kind": "depth", "E": 1787089600523, "U": 11315996816060, "u": 11315996821692, "recv_ms": 1787089600480, "bids": [[1000.0, 35.76], [14372.9, 2.716], [14472.9, 1.484], [58115.6, 0.002], [61344.2, 0.005], [61989.9, 0.026], [63927.2, 0.005], [64250.0, 11.834], [64508.6, 1.246], [64554.5, 1.24], [64555.8, 0.001], [64559.4, 0.022], [64565.2, 0.142], [64572.9, 25.582]], "asks": [[64573.0, 0.522], [64579.6, 0.006], [64585.9, 0.001], [64592.3, 1.305], [64593.8, 0.557], [64593.9, 0.211], [64594.0, 0.001], [64594.7, 0.001], [64594.9, 0.971], [64595.2, 0.175], [64596.4, 0.659], [64601.0, 0.221], [64606.3, 0.237], [64613.5, 0.0], [64895.1, 4.311], [65088.8, 8.315], [65218.7, 0.002]]}
{"kind": "depth", "E": 1787089600625, "U": 11315996821811, "u": 11315996827057, "recv_ms": 1787089600583, "bids": [[1000.0, 35.76], [14372.9, 3.066], [14472.9, 1.134], [58115.6, 0.002], [61989.9, 0.029], [63179.4, 0.002], [63572.9, 0.02], [63738.0, 1.571], [63927.2, 0.005], [64432.9, 1.455], [64435.1, 0.986], [64550.3, 0.465], [64555.8, 0.0], [64557.2, 0.0], [64557.7, 0.001], [64558.1, 0.561], [64560.9, 0.009], [64561.9, 0.125]], "asks": [[64579.4, 0.104], [64579.9, 0.132], [64580.6, 41.785], [64583.4, 2.361], [64589.0, 0.005], [64589.9, 0.092], [64594.7, 0.62], [64596.4, 0.04], [64601.0, 0.067], [64601.1, 0.546], [64649.4, 0.006], [64663.8, 0.001], [64712.9, 0.0], [64713.3, 0.031], [65218.7, 0.002], [65573.0, 0.02], [65864.4, 0.027]]}
{"kind": "depth", "E": 1787089600727, "U": 11315996827069, "u": 11315996833174, "recv_ms": 1787089600686, "bids": [[14372.9, 3.43], [14472.9, 0.77], [58115.6, 0.002], [61344.2, 0.005], [63927.2, 0.005], [64432.8, 4.361], [64435.1, 1.523], [64457.2, 0.298], [64457.3, 4.246], [64467.2, 2.338], [64467.3, 0.022], [64495.3, 31.546], [64499.7, 0.015], [64501.4, 0.001], [64501.5, 0.046], [64502.0, 4.84], [64514.7, 0.015], [64545.9, 2.323], [64546.5, 0.004], [64547.2, 0.063], [64548.6, 2.319], [64549.8, 0.016], [64552.0, 0.003], [64556.2, 0.001], [64556.6, 0.118], [64557.6, 0.559], [64557.7, 0.0], [64558.1, 0.003], [64559.8, 0.007], [64559.9, 0.004], [64560.4, 0.442], [64560.7, 0.003], [64560.9, 0.001], [64561.1, 0.528], [64561.6, 0.217], [64561.7, 7.238], [64561.9, 0.133], [64562.0, 0.928], [64562.4, 0.008], [64563.0, 1.958], [64563.1, 0.542], [64563.2, 0.388], [64563.7, 0.368], [64564.0, 0.689], [64565.4, 0.163], [64566.2, 0.034], [64566.5, 0.042], [64566.7, 0.316], [64566.9, 0.239], [64567.0, 1.549], [64567.1, 0.041], [64567.4, 0.272], [64569.1, 0.001], [64570.0, 0.006], [64570.1, 0.084], [64570.3, 0.002], [64570.5, 0.238], [64570.6, 0.002], [64570.7, 0.001], [64572.2, 0.814], [64572.7, 0.009], [64572.8, 0.096], [64572.9, 24.87]], "asks": [[64573.0, 0.57], [64573.1, 0.01], [64573.4, 1.394], [64573.6, 0.591], [64573.7, 0.0], [64574.3, 1.801], [64575.4, 0.002], [64575.5, 0.005], [64576.8, 0.612], [64578.1, 0.008], [64578.2, 1.834], [64578.3, 0.642], [64578.4, 0.008], [64578.9, 0.085], [64579.5, 1.634], [64579.6, 0.004], [64579.7, 0.002], [64580.0, 0.048], [64580.3, 0.08], [64580.4, 2.321], [64580.6, 41.783], [64582.6, 0.014], [64583.0, 0.116], [64584.9, 0.0], [64587.8, 1.546], [64589.0, 0.005], [64589.7, 0.241], [64589.9, 0.015], [64592.4, 0.666], [64594.4, 1.377], [64594.7, 0.001], [64594.9, 0.044], [64595.4, 0.628], [64595.8, 0.125], [64597.1, 0.473], [64597.9, 0.571], [64598.6, 0.001], [64599.3, 2.044], [64599.8, 0.014], [64600.4, 0.057], [64600.6, 0.116], [64601.1, 0.392], [64602.8, 0.271], [64616.6, 5.395], [64619.5, 0.0], [64639.4, 0.207], [64640.2, 5.005], [64643.6, 0.046], [64643.9, 3.021], [64644.7, 0.001], [64653.5, 37.448], [64669.9, 5.936], [64681.3, 2.324], [64681.4, 0.0], [64689.6, 0.014], [64713.3, 5.439], [64713.8, 0.0], [64714.1, 3.872], [64759.4, 0.025], [64759.5, 0.026], [64768.9, 9.924], [64769.0, 0.311], [64895.9, 0.49], [65089.6, 1.541], [65186.4, 1.492], [65218.7, 0.002]]}
{"kind": "depth", "E": 1787089600829, "U": 11315996833310, "u": 11315996838924, "recv_ms": 1787089600787, "bids": [[1000.0, 35.76], [14272.9, 0.028], [14372.9, 3.71], [14472.9, 0.462], [51658.0, 0.0], [58115.6, 0.002], [61344.2, 0.005], [61989.9, 0.026], [63281.5, 0.046], [63572.9, 0.0], [63927.2, 0.005], [64250.0, 11.842], [64495.3, 31.884], [64499.7, 0.015], [64543.8, 0.098], [64555.8, 0.116], [64556.4, 0.558], [64556.6, 0.002], [64557.6, 0.001], [64561.7, 7.24], [64561.9, 0.123], [64562.1, 0.542], [64563.1, 0.0], [64563.2, 0.388], [64563.3, 0.02], [64563.5, 0.085], [64564.0, 0.605], [64565.4, 0.101], [64565.7, 0.287], [64567.1, 0.483], [64568.1, 0.0], [64569.6, 0.696], [64571.4, 0.003], [64572.7, 0.008], [64572.9, 24.86]], "asks": [[64573.2, 0.001], [64573.3, 0.0], [64573.4, 1.394], [64574.4, 0.005], [64576.7, 0.011], [64578.1, 0.008], [64579.8, 0.085], [64592.2, 0.852], [64593.8, 0.015], [64601.1, 0.546], [64616.6, 5.397], [64617.4, 0.001], [64621.9, 0.015], [64622.9, 0.019], [64642.5, 37.577], [64644.7, 0.001], [64653.5, 0.041], [64895.9, 0.491], [65218.7, 0.002], [65380.2, 1.259], [65573.0, 0.0]]}
{"kind": "depth", "E": 1787089600931, "U": 11315996839162, "u": 11315996845802, "recv_ms": 1787089600890, "bids": [[1000.0, 35.76], [14272.9, 0.224], [14372.9, 3.696], [14472.9, 0.28], [58115.6, 0.002], [61343.6, 0.003], [61989.9, 0.043], [63272.9, 0.061], [63344.7, 0.126], [63416.4, 0.059], [63488.1, 0.06], [63538.9, 7.234], [63559.9, 0.451], [63631.6, 0.059], [63703.3, 0.85], [63775.1, 0.073], [63846.8, 0.841], [63918.6, 0.059], [63927.2, 0.005], [64249.2, 5.049], [64495.3, 0.01], [64499.7, 31.889], [64556.1, 0.003], [64561.1, 0.003], [64563.7, 0.011], [64572.9, 24.861]], "asks": [[64573.1, 0.01], [64573.2, 0.0], [64573.3, 0.001], [64573.4, 0.001], [64573.5, 0.0], [64573.6, 0.0], [64588.5, 0.027], [64601.1, 0.392], [64601.2, 0.192], [64895.9, 0.492], [65209.8, 0.129], [65218.7, 0.002], [65281.6, 0.071], [65284.1, 0.736], [65323.3, 0.764], [65335.1, 2.294], [65353.3, 0.086], [65425.1, 0.059], [65485.1, 2.096], [65496.8, 0.059], [65568.5, 0.06], [65640.3, 0.066], [65712.0, 9.993], [65783.7, 0.061], [65855.5, 0.059]]}
{"kind": "depth", "E": 1787089601033, "U": 11315996845842, "u": 11315996850729, "recv_ms": 1787089600990, "bids": [[14272.9, 0.448], [14372.9, 3.598], [14472.9, 0.154], [58115.6, 0.002], [61344.2, 0.005], [61989.9, 0.04], [63539.7, 2.2], [63572.9, 0.02], [63927.2, 0.005], [64249.2, 4.894], [64432.8, 3.947], [64435.1, 0.986], [64556.1, 0.005], [64557.6, 0.003], [64572.9, 24.858]], "asks": [[64573.1, 0.011], [64573.2, 0.0], [64573.3, 1.393], [64573.4, 0.001], [64576.7, 0.009], [64587.7, 0.006], [64588.5, 0.029], [64713.3, 5.439], [64768.9, 10.762], [65218.7, 0.002], [65356.0, 0.022], [65573.0, 0.02]]}
{"kind": "depth", "E": 1787089601135, "U": 11315996850910, "u": 11315996856447, "recv_ms": 1787089601092, "bids": [[1000.0, 35.76], [14272.9, 0.7], [14372.9, 3.458], [14472.9, 0.042], [51658.0, 0.0], [58115.6, 0.002], [61344.2, 0.005], [61989.9, 0.043], [63667.4, 0.44], [63927.2, 0.005], [64250.0, 11.842], [64528.1, 0.092], [64528.2, 0.139], [64561.3, 0.001], [64565.7, 0.225], [64565.8, 0.164], [64568.1, 0.019], [64572.9, 24.857]], "asks": [[64573.1, 0.01], [64573.2, 0.001], [64573.3, 0.0], [64573.5, 1.393], [64584.5, 0.005], [64603.1, 1.886], [64603.2, 0.516], [64689.7, 0.088], [65218.7, 0.002], [65347.9, 5.966], [65650.1, 0.0]]}
{"kind": "depth", "E": 1787089601237, "U": 11315996856673, "u": 11315996862106, "recv_ms": 1787089601195, "bids": [[1000.0, 35.76], [14272.9, 1.022], [14372.9, 3.178], [14472.9, 0.0], [51658.0, 0.0], [58115.6, 0.002], [61344.2, 0.005], [61989.9, 0.029], [62958.6, 0.634], [63572.9, 0.0], [63705.6, 0.0], [63927.2, 0.005], [64250.0, 11.997], [64572.8, 0.099], [64572.9, 24.855]], "asks": [[64573.1, 0.01], [64573.2, 0.0], [64573.3, 0.001], [64573.5, 0.0], [64573.6, 1.393], [64592.2, 0.852], [64594.1, 0.003], [64594.4, 0.45], [64595.3, 0.928], [64599.9, 0.636], [64601.2, 0.185], [64768.9, 9.55], [65218.7, 0.002], [65380.2, 1.374], [65573.0, 0.0], [65573.9, 3.05], [67155.9, 0.637], [71030.3, 0.001]]}
{"kind": "depth", "E": 1787089601339, "U": 11315996862137, "u": 11315996867474, "recv_ms": 1787089601298, "bids": [[14272.9, 1.372], [14372.9, 2.828], [51658.3, 0.0], [58115.6, 0.002], [61989.9, 0.026], [63390.6, 0.0], [63660.4, 9.289], [63927.2, 0.005], [64502.0, 8.399], [64550.3, 1.084], [64557.6, 0.622], [64563.4, 0.767], [64564.0, 0.063], [64564.5, 0.022], [64569.7, 0.158], [64570.5, 0.084], [64572.9, 24.856]], "asks": [[64573.6, 1.393], [64573.7, 0.0], [64593.7, 0.629], [64600.9, 0.156], [64601.1, 1.011], [64601.2, 0.031], [64621.2, 1.583], [64640.2, 5.005], [64642.5, 0.015], [64649.1, 37.562], [64712.9, 1.215], [65218.7, 0.002], [65361.9, 0.153], [71030.3, 0.0]]}
{"kind": "depth", "E": 1787089601441, "U": 11315996867658, "u": 11315996873579, "recv_ms": 1787089601398, "bids": [[1000.0, 35.76], [14272.9, 1.736], [14372.9, 2.464], [58115.6, 0.002], [61344.2, 0.005], [61344.3, 0.01], [61989.9, 0.029], [63281.5, 0.049], [63572.9, 0.02], [63677.6, 0.784], [63701.2, 1.02], [63927.2, 0.005], [64250.0, 11.987], [64467.2, 2.338], [64503.1, 0.022], [64550.3, 0.465], [64557.6, 0.003], [64559.2, 6.922], [64559.6, 2.782], [64560.1, 0.01], [64561.7, 0.325], [64563.0, 0.967], [64563.3, 0.012], [64572.9, 24.765]], "asks": [[64573.0, 0.68], [64573.6, 1.395], [64573.7, 0.0], [64573.8, 0.0], [64575.7, 0.001], [64578.1, 0.008], [64579.3, 0.1], [64579.4, 0.646], [64579.5, 0.001], [64580.2, 0.086], [64580.3, 0.073], [64580.5, 7.315], [64593.7, 0.01], [64600.9, 0.002], [64601.0, 0.221], [64601.1, 0.392], [64636.4, 0.008], [64649.4, 0.003], [64681.2, 2.323], [64681.3, 0.001], [65218.7, 0.002], [65573.0, 0.02], [65640.0, 0.123], [65864.4, 0.024]]}
{"kind": "depth", "E": 1787089601543, "U": 11315996873642, "u": 11315996879724, "recv_ms": 1787089601501, "bids": [[1000.0, 35.76], [14272.9, 2.086], [14372.9, 2.114], [51658.0, 0.0], [58115.6, 0.002], [61344.2, 0.005], [61989.9, 0.026], [63927.2, 0.005], [64514.7, 0.018], [64566.0, 0.655], [64566.5, 1.59], [64566.7, 0.007], [64567.0, 0.001], [64572.9, 24.795]], "asks": [[64573.6, 1.395], [64573.7, 0.0], [64575.7, 0.001], [64578.1, 0.0], [64579.3, 0.093], [64579.4, 0.104], [64580.0, 0.056], [64580.3, 0.622], [64580.5, 7.313], [64586.1, 0.34], [64587.8, 1.237], [64588.9, 0.086], [64589.7, 0.164], [64600.7, 0.087], [64601.0, 0.067], [64631.2, 0.003], [64642.5, 37.577], [64649.1, 0.0], [64701.4, 0.009], [65218.7, 0.002], [71030.3, 0.0]]}
{"kind": "depth", "E": 1787089601645, "U": 11315996879913, "u": 11315996885817, "recv_ms": 1787089601601, "bids": [[14272.9, 2.45], [14372.9, 1.75], [51658.0, 0.002], [58115.6, 0.002], [61989.9, 0.029], [63011.2, 0.0], [63281.5, 0.046], [63572.9, 0.0], [63927.2, 0.005], [64449.8, 0.093], [64450.3, 1.238], [64507.5, 0.419]], "asks": [[64573.6, 0.002], [64573.7, 0.0], [64573.8, 1.393], [64601.1, 0.546], [64636.8, 0.009], [64689.7, 0.001], [64690.0, 0.132], [65218.7, 0.002], [65347.9, 7.493], [65573.0, 0.0], [65664.3, 0.613]]}
{"kind": "depth", "E": 1787089601747, "U": 11315996885839, "u": 11315996892425, "recv_ms": 1787089601706, "bids": [[1000.0, 35.76], [14272.9, 2.8], [14372.9, 1.4], [51658.0, 0.0], [58115.6, 0.002], [61344.2, 0.005], [63572.9, 0.02], [63927.2, 0.005], [64250.0, 11.987], [64540.1, 0.312], [64540.2, 0.108], [64540.3, 0.0], [64543.6, 0.039], [64543.7, 0.064], [64549.2, 0.001], [64550.4, 0.014], [64551.3, 0.481], [64554.8, 0.465], [64558.5, 1.106], [64558.6, 6.915], [64559.2, 0.007], [64560.1, 0.002], [64560.8, 0.001], [64561.5, 0.928], [64562.0, 0.001], [64562.2, 0.01], [64562.4, 0.0], [64563.1, 0.008], [64563.4, 0.225], [64563.5, 0.001], [64564.0, 0.063], [64564.2, 0.003], [64565.2, 0.452], [64566.0, 0.346], [64566.5, 1.582], [64566.7, 0.641], [64567.1, 0.503], [64570.1, 0.087], [64572.2, 0.814], [64572.9, 24.806]], "asks": [[64573.0, 0.68], [64573.6, 0.0], [64573.8, 0.0], [64575.5, 0.005], [64575.7, 0.001], [64576.0, 0.039], [64576.7, 0.001], [64578.1, 0.0], [64578.3, 0.558], [64579.2, 0.069], [64580.0, 0.061], [64580.2, 0.086], [64586.1, 0.031], [64587.3, 0.775], [64588.5, 0.009], [64588.9, 0.009], [64589.7, 0.044], [64589.9, 0.092], [64591.3, 0.095], [64591.7, 0.008], [64591.8, 0.025], [64592.7, 0.0], [64593.9, 1.138], [64595.2, 0.415], [64595.3, 0.001], [64598.9, 2.419], [64599.7, 0.411], [64611.3, 10.002], [64616.6, 0.312], [65218.7, 0.002], [65380.2, 1.633], [65478.1, 0.0], [65573.0, 0.02], [65864.4, 0.021]]}
{"kind": "depth", "E": 1787089601849, "U": 11315996892472, "u": 11315996898932, "recv_ms": 1787089601807, "bids": [[1000.0, 35.76], [14272.9, 3.15], [14372.9, 1.05], [58115.6, 0.002], [61989.9, 0.026], [63927.2, 0.005], [64250.0, 11.988], [64548.8, 0.546], [64556.5, 0.083], [64564.2, 0.003], [64565.8, 0.102], [64565.9, 0.134], [64566.7, 0.641], [64566.8, 0.032]], "asks": [[64573.5, 0.0], [64573.6, 0.0], [64573.7, 1.393], [64575.7, 0.002], [64578.1, 0.0], [64580.0, 0.061], [64593.9, 0.211], [64594.5, 0.945], [64595.4, 0.009], [64596.3, 0.629], [64642.5, 0.015], [64649.1, 37.614], [64895.9, 0.49], [65218.7, 0.002], [65477.0, 0.869], [65678.4, 0.76], [65864.4, 0.024]]}
{"kind": "depth", "E": 1787089601951, "U": 11315996899235, "u": 11315996904994, "recv_ms": 1787089601909, "bids": [[14272.9, 3.514], [14372.9, 0.686], [58115.6, 0.002], [61344.2, 0.005], [61344.3, 0.008], [61344.4, 0.002], [61989.9, 0.029], [63572.9, 0.0], [63927.2, 0.005], [64250.0, 11.989], [64514.7, 0.015], [64556.1, 0.003], [64561.1, 0.417], [64563.7, 0.265], [64564.2, 0.003], [64566.7, 0.099], [64566.8, 0.574], [64572.9, 24.775]], "asks": [[64573.7, 0.0], [64573.8, 1.393], [64576.0, 0.04], [64578.1, 0.0], [64579.2, 0.07], [64580.0, 0.061], [64588.5, 0.007], [64611.3, 0.002], [64614.5, 10.005], [64631.2, 0.0], [65218.7, 0.002], [65573.0, 0.0], [65678.6, 0.76], [65864.5, 2.274]]}
{"kind": "depth", "E": 1787089602053, "U": 11315996905062, "u": 11315996911372, "recv_ms": 1787089602011, "bids": [[1000.0, 35.76], [14172.9, 0.056], [14272.9, 3.752], [14372.9, 0.392], [58115.6, 0.002], [61989.9, 0.026], [63861.9, 0.027], [63927.2, 0.005], [64250.0, 11.989], [64495.4, 1.983], [64556.1, 0.005], [64557.6, 0.001], [64558.7, 0.005], [64561.3, 0.006], [64561.5, 0.001], [64562.0, 0.928], [64562.2, 0.01], [64562.9, 1.246], [64563.1, 0.008], [64567.4, 0.04], [64567.8, 0.239], [64572.9, 24.807]], "asks": [[64573.7, 1.393], [64573.8, 0.0], [64588.5, 0.009], [64592.1, 1.888], [64592.2, 0.31], [64594.1, 0.003], [64594.5, 0.018], [64595.3, 0.928], [64631.2, 0.003], [64640.2, 5.014], [65218.7, 0.002], [65864.4, 0.021]]}
{"kind": "depth", "E": 1787089602155, "U": 11315996911697, "u": 11315996918477, "recv_ms": 1787089602113, "bids": [[1000.0, 35.76], [14172.9, 0.28], [14272.9, 3.668], [14372.9, 0.252], [58115.6, 0.002], [63281.5, 0.037], [63587.8, 0.005], [63588.6, 0.011], [63739.4, 1.72], [63927.2, 0.005], [64561.3, 0.001]], "asks": [[64573.7, 1.393], [64573.8, 0.0], [64578.1, 0.008], [64579.5, 0.201], [64580.0, 0.053], [64603.0, 1.921], [64603.1, 0.001], [64675.5, 0.0], [64844.2, 0.0], [65218.7, 0.002], [65353.1, 0.879], [65556.4, 0.003], [71030.3, 0.0]]}
{"kind": "depth", "E": 1787089602257, "U": 11315996918740, "u": 11315996924876, "recv_ms": 1787089602215, "bids": [[14172.9, 0.518], [14272.9, 3.556], [14372.9, 0.126], [51658.0, 0.006], [58115.6, 0.002], [61344.2, 0.005], [61989.9, 0.029], [63281.5, 0.034], [63572.9, 0.02], [63648.9, 4.237], [63882.0, 0.955], [63927.2, 0.005], [64560.2, 0.104], [64562.2, 0.01], [64563.1, 0.0], [64563.4, 0.859], [64564.0, 0.055], [64565.9, 0.072], [64566.1, 0.065], [64566.7, 0.007], [64566.8, 0.032], [64566.9, 0.247], [64571.3, 0.104], [64572.0, 0.34], [64572.1, 0.23], [64572.8, 0.1], [64572.9, 24.806]], "asks": [[64573.0, 0.679], [64573.6, 0.0], [64573.7, 1.393], [64573.8, 0.0], [64575.5, 0.005], [64575.7, 0.002], [64576.7, 0.001], [64576.9, 0.001], [64578.1, 0.016], [64578.2, 1.918], [64579.4, 0.104], [64579.5, 0.001], [64580.0, 0.045], [64580.4, 2.324], [64584.5, 0.004], [64644.7, 37.615], [64649.1, 0.0], [64676.3, 0.2], [65218.7, 0.002], [65557.2, 0.011], [65573.0, 0.02], [65864.4, 0.018]]}
{"kind": "depth", "E": 1787089602359, "U": 11315996924952, "u": 11315996929752, "recv_ms": 1787089602317, "bids": [[1000.0, 35.76], [14172.9, 0.756], [14272.9, 3.43], [14372.9, 0.014], [51658.0, 0.0], [51658.3, 0.0], [58115.6, 0.002], [61344.2, 0.005], [61989.9, 0.026], [63635.8, 18.17], [63660.4, 9.101], [63757.9, 0.784], [63829.5, 4.145], [63927.2, 0.005], [64250.0, 11.989], [64435.1, 1.461], [64504.8, 0.219], [64505.2, 2.181], [64541.2, 0.004], [64550.2, 1.664], [64550.3, 0.775], [64551.3, 0.171], [64557.6, 0.62], [64562.4, 0.02], [64567.1, 0.483], [64572.9, 24.809]], "asks": [[64573.7, 0.0], [64573.8, 0.0], [64575.5, 0.005], [64576.8, 0.423], [64579.5, 0.201], [64580.0, 1.846], [64580.2, 0.086], [64593.6, 1.061], [64601.0, 0.686], [64601.1, 0.392], [64608.4, 0.002], [64614.4, 2.82], [64614.6, 0.027], [64643.9, 8.259], [64727.7, 1.299], [65218.7, 0.002], [65508.5, 21.146]]}
{"kind": "depth", "E": 1787089602461, "U": 11315996929883, "u": 11315996935366, "recv_ms": 1787089602424, "bids": [[1000.0, 35.76], [14172.9, 1.092], [14272.9, 3.108], [14372.9, 0.0], [58115.6, 0.002], [61344.2, 0.005], [61989.9, 0.029], [63281.5, 0.031], [63572.9, 0.0], [63834.8, 7.042], [63927.2, 0.005], [64541.2, 0.006], [64550.2, 1.045], [64557.6, 0.001], [64572.9, 24.777]], "asks": [[64573.0, 0.669], [64579.5, 0.001], [64593.6, 0.442], [64601.0, 0.221], [64608.4, 0.004], [65218.7, 0.002], [65573.0, 0.0]]}
{"kind": "depth", "E": 1787089602665, "U": 11315996940342, "u": 11315996947227, "recv_ms": 1787089602624, "bids": [[1000.0, 35.76], [14172.9, 1.806], [14272.9, 2.394], [51658.0, 0.0], [58115.6, 0.002], [61344.2, 0.005], [63778.0, 8.47], [63798.0, 1.867], [63927.2, 0.005], [63936.8, 0.816], [63959.5, 1.404], [64056.3, 1.262], [64250.0, 11.999], [64457.3, 4.246], [64480.7, 0.093], [64501.5, 0.046], [64547.8, 0.001], [64550.0, 0.015], [64552.8, 0.082], [64556.5, 0.003], [64567.3, 0.247], [64567.8, 0.007], [64572.9, 24.809]], "asks": [[64579.5, 1.817], [64643.6, 0.046], [64714.1, 0.0], [64714.2, 3.874], [65218.7, 0.002], [65327.3, 4.934], [65355.9, 0.765], [65509.3, 5.673], [65546.3, 0.0]]}
{"kind": "depth", "E": 1787089602767, "U": 11315996947464, "u": 11315996953086, "recv_ms": 1787089602725, "bids": [[1000.0, 35.76], [14172.9, 2.17], [14272.9, 2.03], [58115.6, 0.004], [61989.9, 0.029], [62609.4, 0.768], [63572.9, 0.0], [63645.3, 0.784], [63927.2, 0.005], [64249.2, 4.739], [64432.8, 0.071], [64435.1, 0.986], [64550.0, 0.014]], "asks": [[64573.8, 1.393], [64712.9, 0.0], [64713.3, 0.031], [65218.7, 0.002], [65218.8, 0.016], [65488.7, 1.537], [65573.0, 0.0], [65670.7, 0.913]]}
{"kind": "depth", "E": 1787089602869, "U": 11315996953146, "u": 11315996961353, "recv_ms": 1787089602827, "bids": [[14172.9, 2.534], [14272.9, 1.666], [58115.6, 0.002], [61344.2, 0.005], [61989.9, 0.026], [63636.6, 6.123], [63742.1, 0.844], [63834.8, 6.26], [63927.2, 0.005], [64250.0, 11.998], [64432.8, 4.355], [64468.9, 0.022], [64469.0, 0.095], [64514.7, 0.018]], "asks": [[64573.0, 0.666], [64573.7, 0.0], [64573.8, 1.393], [64575.7, 0.001], [64580.4, 2.321], [64615.5, 0.262], [64616.5, 0.037], [64622.0, 3.866], [64623.0, 0.077], [64644.9, 0.201], [64645.9, 0.0], [64650.5, 0.639], [64702.2, 0.003], [64716.2, 4.555], [64844.2, 0.2], [64895.9, 0.491], [64899.6, 0.201], [64900.6, 0.001], [64903.1, 0.352], [64904.1, 0.0], [65864.4, 0.021]]}
{"kind": "depth", "E": 1787089602971, "U": 11315996961507, "u": 11315996970001, "recv_ms": 1787089602930, "bids": [[1000.0, 35.76], [14172.9, 2.884], [14272.9, 1.316], [58115.6, 0.002], [61344.3, 0.01], [61989.9, 0.029], [63572.9, 0.02], [63668.9, 4.03], [63725.5, 0.784], [63765.7, 0.354], [63778.0, 6.904], [63927.2, 0.005], [64250.0, 11.987], [64508.2, 0.001], [64508.5, 0.023], [64508.8, 0.284], [64509.1, 0.118], [64509.5, 0.001], [64527.5, 0.413], [64527.8, 5.409], [64528.1, 0.06], [64528.5, 0.129], [64528.8, 0.036], [64542.4, 0.433], [64542.5, 0.001], [64542.6, 0.001], [64542.7, 0.0], [64542.8, 0.021], [64542.9, 0.31], [64543.0, 0.0], [64543.1, 2.322], [64543.2, 2.08], [64543.4, 0.001], [64546.0, 0.445], [64546.4, 0.117], [64556.1, 0.003], [64564.9, 0.0], [64565.0, 0.313], [64565.1, 0.001], [64565.2, 0.312], [64565.3, 0.001], [64565.4, 0.001], [64565.5, 0.0], [64565.6, 0.018], [64565.7, 0.155], [64565.8, 0.002], [64565.9, 0.002], [64566.2, 0.002], [64566.5, 1.55], [64566.8, 0.0], [64567.1, 0.451], [64567.4, 0.008], [64572.9, 24.811]], "asks": [[64573.7, 0.0], [64573.8, 1.393], [64575.7, 0.002], [64576.6, 0.038], [64581.4, 0.0], [64581.7, 0.104], [64582.0, 0.003], [64582.4, 0.008], [64582.7, 0.004], [64582.9, 0.003], [64583.1, 0.003], [64583.2, 0.007], [64583.3, 0.033], [64583.4, 2.015], [64583.5, 0.465], [64583.6, 0.003], [64583.7, 2.581], [64583.8, 0.005], [64583.9, 0.0], [64588.5, 0.007], [64600.7, 0.02], [64601.0, 0.154], [64601.3, 2.321], [64601.7, 0.967], [64602.0, 0.02], [64602.4, 0.025], [64602.8, 0.001], [64605.5, 0.016], [64605.7, 1.098], [64605.8, 1.704], [64605.9, 0.989], [64606.0, 0.001], [64606.1, 0.311], [64606.2, 0.002], [64606.3, 0.104], [64606.4, 0.435], [64620.1, 0.005], [64620.4, 0.072], [64620.7, 0.0], [64621.0, 1.499], [64621.3, 0.971], [64895.9, 0.492], [65218.7, 0.002], [65347.9, 9.021], [65509.3, 6.588], [65548.3, 0.267], [65573.0, 0.02], [71030.3, 0.0]]}
{"kind": "depth", "E": 1787089603073, "U": 11315996970203, "u": 11315996979090, "recv_ms": 1787089603032, "bids": [[1000.0, 35.76], [14172.9, 3.234], [14272.9, 0.966], [58115.6, 0.002], [61344.2, 0.005], [61989.9, 0.026], [63410.6, 0.79], [63668.9, 4.218], [63739.4, 1.455], [63794.8, 0.563], [63829.5, 3.206], [63830.3, 2.817], [63927.2, 0.005], [64250.0, 12.142], [64556.1, 0.005], [64561.3, 0.001], [64566.7, 0.239], [64567.1, 0.521], [64567.2, 0.373], [64567.3, 0.015], [64567.7, 0.114], [64567.9, 0.166], [64572.9, 24.813]], "asks": [[64573.6, 0.0], [64573.7, 1.393], [64573.8, 0.0], [64580.7, 0.486], [64582.8, 0.161], [64583.1, 0.283], [64583.6, 0.157], [64583.8, 0.152], [64585.3, 0.002], [64587.7, 0.005], [64588.5, 0.009], [64594.1, 0.93], [64595.3, 0.001], [64605.4, 0.165], [64605.6, 0.28], [64606.1, 0.465], [64606.3, 0.251], [65218.7, 0.002], [65380.2, 1.893]]}
{"kind": "depth", "E": 1787089603175, "U": 11315996979469, "u": 11315996987061, "recv_ms": 1787089603134, "bids": [[14172.9, 3.598], [14272.9, 0.602], [58115.6, 0.002], [61344.2, 0.005], [63281.5, 0.028], [63635.8, 15.972], [63798.0, 3.433], [63829.5, 2.267], [63927.2, 0.005], [64055.5, 8.262], [64499.7, 32.16], [64501.9, 0.001], [64529.6, 0.47], [64529.9, 0.033], [64530.2, 0.032], [64530.5, 0.041], [64530.8, 2.416], [64557.8, 0.003], [64558.6, 6.917], [64561.1, 0.003], [64563.7, 0.011], [64567.3, 0.085], [64567.6, 0.073], [64568.2, 0.117], [64568.5, 0.033], [64568.8, 0.033], [64569.2, 0.034], [64569.5, 0.039], [64572.9, 24.802]], "asks": [[64573.7, 0.0], [64573.8, 0.0], [64581.3, 0.618], [64581.6, 0.076], [64581.9, 0.105], [64582.3, 0.075], [64582.6, 0.078], [64583.3, 0.159], [64583.5, 0.605], [64584.6, 0.001], [64600.6, 0.183], [64601.0, 0.221], [64601.3, 2.404], [64601.6, 0.083], [64601.9, 0.065], [64605.8, 1.83], [64606.0, 0.141], [64614.5, 10.007], [64615.0, 0.0], [65218.7, 0.002]]}
{"kind": "depth", "E": 1787089603277, "U": 11315996987188, "u": 11315996992827, "recv_ms": 1787089603236, "bids": [[1000.0, 35.76], [14072.9, 0.084], [14172.9, 3.78], [14272.9, 0.336], [51658.0, 0.0], [58115.6, 0.002], [61989.9, 0.029], [63572.9, 0.0], [63797.2, 28.016], [63817.4, 1.648], [63927.2, 0.005], [64055.5, 7.95], [64250.0, 12.142], [64495.4, 1.98], [64499.7, 0.015], [64501.9, 32.357], [64514.7, 0.018], [64567.0, 0.071], [64567.5, 0.1], [64567.6, 0.173], [64567.8, 0.077]], "asks": [[64583.1, 0.43], [64583.2, 0.257], [64583.3, 0.379], [64583.8, 0.292], [64605.6, 0.427], [64605.7, 1.348], [64605.8, 2.05], [64606.3, 0.391], [64631.2, 0.003], [64650.5, 0.636], [65218.7, 0.002], [65573.0, 0.0]]}
{"kind": "depth", "E": 1787089603379, "U": 11315996992996, "u": 11315996998899, "recv_ms": 1787089603337, "bids": [[1000.0, 35.76], [14072.9, 0.336], [14172.9, 3.64], [14272.9, 0.224], [51658.0, 0.0], [51658.3, 0.0], [58115.6, 0.002], [61344.2, 0.005], [61989.9, 0.026], [63636.6, 7.222], [63830.3, 3.756], [63927.2, 0.005], [64056.3, 1.574], [64432.8, 4.363], [64435.1, 0.986], [64495.3, 32.366], [64495.4, 6.563], [64501.9, 0.001], [64502.0, 4.84], [64520.0, 9.781], [64529.0, 0.019], [64544.5, 0.088], [64549.7, 0.727], [64557.1, 0.635], [64562.1, 0.0], [64563.5, 0.543], [64566.1, 0.003], [64566.4, 1.035], [64567.1, 0.591], [64567.2, 0.443], [64567.3, 0.185], [64567.4, 0.208], [64567.8, 0.177], [64572.9, 24.803]], "asks": [[64578.1, 1.007], [64583.0, 0.376], [64583.4, 2.535], [64583.5, 0.875], [64583.6, 0.304], [64583.7, 2.714], [64592.1, 1.346], [64593.0, 0.545], [64593.1, 0.621], [64594.1, 0.003], [64595.2, 1.342], [64600.5, 0.62], [64602.3, 0.294], [64602.7, 0.27], [64602.9, 2.887], [64603.0, 0.036], [64605.9, 1.239], [64606.0, 0.411], [64606.1, 0.612], [64606.2, 0.135], [64713.2, 5.456], [64713.7, 0.011], [64714.1, 0.0], [64716.2, 0.03], [65218.7, 0.002], [65920.2, 0.005]]}
{"kind": "depth", "E": 1787089603481, "U": 11315996999020, "u": 11315997003759, "recv_ms": 1787089603438, "bids": [[14072.9, 0.56], [14172.9, 3.542], [14272.9, 0.098], [58115.6, 0.002], [61989.9, 0.029], [63572.9, 0.02], [63927.2, 0.005], [64495.3, 0.01], [64495.4, 1.98], [64499.7, 32.371], [64503.1, 0.004], [64510.2, 2.354], [64510.5, 0.784], [64510.9, 0.032], [64511.2, 0.033], [64511.5, 0.361], [64544.7, 0.071], [64545.2, 0.566], [64545.4, 0.073], [64562.1, 0.0], [64563.5, 0.543], [64566.7, 0.007], [64567.1, 0.823], [64572.9, 24.802]], "asks": [[64578.1, 0.016], [64620.0, 0.082], [64620.3, 0.067], [64620.6, 5.104], [64620.9, 0.074], [64621.3, 1.035], [65218.7, 0.002], [65270.4, 1.53], [65573.0, 0.02]]}
{"kind": "depth", "E": 1787089603583, "U": 11315997004024, "u": 11315997010375, "recv_ms": 1787089603542, "bids": [[1000.0, 35.76], [14072.9, 0.826], [14172.9, 3.374], [14272.9, 0.0], [58115.6, 0.002], [61344.2, 0.005], [63571.2, 11.95], [63798.0, 4.059], [63927.2, 0.005], [64056.3, 1.886], [64250.0, 12.152], [64494.7, 0.088], [64521.2, 0.756], [64544.8, 0.073], [64545.1, 0.14], [64561.2, 0.001], [64562.1, 0.542], [64563.5, 0.001], [64567.7, 0.274], [64569.6, 0.93], [64572.9, 24.801]], "asks": [[64573.0, 0.642], [64593.1, 0.002], [64625.0, 0.018], [64636.4, 0.005], [65218.7, 0.002], [65477.0, 0.877], [66079.7, 0.003]]}
{"kind": "depth", "E": 1787089603685, "U": 11315997010492, "u": 11315997014981, "recv_ms": 1787089603643, "bids": [[1000.0, 35.76], [14072.9, 1.19], [14172.9, 3.01], [58115.6, 0.002], [61343.6, 0.001], [61344.2, 0.005], [61344.3, 0.008], [61344.4, 0.004], [61989.9, 0.026], [63572.9, 0.0], [63797.2, 27.546], [63927.2, 0.005], [64432.8, 3.419], [64544.5, 0.158], [64544.9, 0.157], [64545.0, 0.115], [64545.1, 0.24], [64545.2, 0.636], [64548.1, 0.102], [64548.5, 0.108], [64572.9, 24.671]], "asks": [[64713.2, 5.456], [64768.9, 10.002], [65218.7, 0.002], [65573.0, 0.0], [65929.0, 0.403], [67035.3, 0.0]]}
{"kind": "depth", "E": 1787089603787, "U": 11315997015045, "u": 11315997020150, "recv_ms": 1787089603745, "bids": [[14072.9, 1.54], [14172.9, 2.66], [51658.0, 0.006], [58115.6, 0.002], [61344.2, 0.005], [61989.9, 0.029], [63572.0, 1.1], [63927.2, 0.005], [64432.8, 4.107], [64544.6, 0.23], [64544.7, 0.141], [64544.8, 0.173], [64572.9, 24.802]], "asks": [[64584.6, 0.0], [64713.2, 5.456], [64768.9, 10.239], [65218.7, 0.002], [65218.8, 0.015], [66174.8, 0.003]]}
{"kind": "depth", "E": 1787089603889, "U": 11315997020266, "u": 11315997028102, "recv_ms": 1787089603848, "bids": [[1000.0, 35.76], [14072.9, 1.89], [14172.9, 2.31], [51658.0, 0.0], [58115.6, 0.002], [61343.5, 0.006], [61343.6, 0.003], [61989.9, 0.026], [63281.5, 0.031], [63422.9, 1.261], [63572.9, 0.02], [63765.7, 0.705], [63778.0, 5.338], [63927.2, 0.005], [64250.0, 12.153], [64562.1, 0.542], [64563.5, 0.001]], "asks": [[64578.1, 1.007], [64592.2, 0.852], [64593.0, 0.003], [64594.1, 0.003], [64763.7, 0.15], [64895.9, 0.491], [65218.7, 0.002], [65508.5, 20.079], [65573.0, 0.02]]}
{"kind": "depth", "E": 1787089603991, "U": 11315997028109, "u": 11315997033706, "recv_ms": 1787089603950, "bids": [[1000.0, 35.76], [14072.9, 2.254], [14172.9, 1.946], [58115.6, 0.002], [61344.2, 0.005], [61989.9, 0.029], [63281.5, 0.028], [63442.9, 1.263], [63668.9, 4.406], [63798.0, 4.529], [63859.3, 0.626], [63927.2, 0.005], [64549.7, 0.108], [64557.1, 0.016], [64566.4, 0.973], [64566.6, 0.527], [64572.6, 0.0], [64572.7, 0.008], [64572.9, 24.807]], "asks": [[64573.0, 0.62], [64578.1, 0.016], [64580.7, 0.483], [64600.5, 0.001], [64895.9, 0.49], [65218.7, 0.002], [65380.2, 2.121], [65864.4, 0.024], [67065.5, 0.149]]}
{"kind": "depth", "E": 1787089604093, "U": 11315997033816, "u": 11315997038785, "recv_ms": 1787089604050, "bids": [[14072.9, 2.618], [14172.9, 1.582], [51658.0, 0.0], [58115.6, 0.002], [61344.2, 0.005], [63341.0, 0.787], [63572.9, 0.0], [63794.8, 0.015], [63798.0, 6.094], [63927.2, 0.007], [63936.6, 4.212], [64249.2, 4.584], [64556.1, 0.005], [64561.1, 0.44], [64561.3, 0.001], [64563.7, 0.287], [64572.9, 24.805]], "asks": [[64588.5, 0.009], [64895.1, 4.157], [65088.8, 8.008], [65218.7, 0.002], [65573.0, 0.0]]}
{"kind": "depth", "E": 1787089604195, "U": 11315997038826, "u": 11315997044435, "recv_ms": 1787089604154, "bids": [[1000.0, 35.76], [14072.9, 2.968], [14172.9, 1.232], [51658.0, 0.0], [58115.6, 0.002], [61989.9, 0.026], [63365.4, 0.787], [63829.5, 1.329], [63854.6, 1.022], [63927.2, 0.005], [64250.0, 12.144], [64449.8, 0.007], [64548.0, 1.36], [64572.9, 24.813]], "asks": [[64585.7, 0.096], [65166.0, 0.684], [65218.7, 0.002], [65399.6, 3.824], [65436.0, 0.034], [65509.3, 7.655], [65864.4, 0.021], [67155.9, 0.65], [67223.0, 0.002], [67322.0, 0.018], [67408.0, 0.0]]}
{"kind": "depth", "E": 1787089604297, "U": 11315997044578, "u": 11315997049352, "recv_ms": 1787089604258, "bids": [[1000.0, 35.76], [14072.9, 3.332], [14172.9, 0.868], [51658.0, 0.0], [58115.6, 0.002], [61344.2, 0.005], [61989.9, 0.029], [63571.2, 10.85], [63572.9, 0.02], [63616.6, 0.011], [63641.2, 0.0], [63798.0, 7.66], [63817.4, 2.196], [63927.2, 0.005], [63959.5, 2.027], [64376.4, 0.0], [64377.1, 8.449], [64377.2, 1.434], [64415.2, 0.002], [64415.8, 7.349], [64432.8, 4.103], [64507.8, 0.249], [64508.2, 4.352], [64508.6, 0.868], [64572.9, 24.815]], "asks": [[64573.0, 0.636], [64580.9, 0.12], [64634.2, 0.693], [64635.8, 1.96], [64635.9, 0.076], [64713.2, 5.145], [64768.9, 10.272], [64895.9, 0.644], [65089.6, 1.848], [65218.7, 0.002], [65573.0, 0.02]]}
{"kind": "depth", "E": 1787089604399, "U": 11315997049469, "u": 11315997054891, "recv_ms": 1787089604357, "bids": [[14072.9, 3.682], [14172.9, 0.518], [51658.3, 0.0], [58115.6, 0.002], [61989.9, 0.026], [63281.5, 0.025], [63854.6, 1.804], [63927.2, 0.005], [63959.5, 2.697], [64250.0, 12.299], [64435.1, 1.485], [64500.7, 0.115]], "asks": [[64714.1, 1.34], [65218.7, 0.002], [65573.1, 8.677]]}
{"kind": "depth", "E": 1787089604501, "U": 11315997054981, "u": 11315997060235, "recv_ms": 1787089604459, "bids": [[1000.0, 35.91], [14072.9, 3.738], [14172.9, 0.308], [14472.9, 0.154], [58115.6, 0.002], [61344.3, 0.006], [61344.4, 0.006], [61989.9, 0.029], [62629.1, 0.683], [63572.9, 0.0], [63636.6, 8.321], [63803.7, 4.147], [63830.3, 4.694], [63927.2, 0.005], [64250.0, 12.299], [64514.7, 0.018]], "asks": [[64631.2, 0.003], [65218.7, 0.002], [65573.0, 0.0]]}
{"kind": "depth", "E": 1787089604705, "U": 11315997065442, "u": 11315997070082, "recv_ms": 1787089604664, "bids": [[14072.9, 3.514], [14172.9, 0.07], [14472.9, 0.616], [58115.6, 0.002], [61989.9, 0.026], [63281.5, 0.022], [63572.9, 0.02], [63804.5, 6.577], [63927.2, 0.005], [64443.1, 0.001], [64443.5, 0.897], [64450.7, 3.134], [64500.7, 0.015]], "asks": [[64761.6, 0.686], [64763.8, 1.972], [65218.7, 0.002], [65367.4, 0.0], [65499.0, 1.599], [65573.0, 0.02], [65864.4, 0.018]]}
{"kind": "depth", "E": 1787089604807, "U": 11315997070218, "u": 11315997075133, "recv_ms": 1787089604765, "bids": [[1000.0, 35.76], [14072.9, 3.29], [14172.9, 0.0], [14472.9, 0.91], [58115.6, 0.002], [61344.2, 0.005], [61989.9, 0.029], [63770.6, 1.566], [63927.2, 0.007], [63936.6, 3.51], [64250.0, 12.299], [64415.8, 6.894], [64432.8, 3.869], [64572.9, 24.806]], "asks": [[64593.4, 0.001], [64713.2, 5.456], [64715.9, 0.057], [64730.2, 10.428], [65218.7, 0.002]]}
{"kind": "depth", "E": 1787089604909, "U": 11315997075164, "u": 11315997080628, "recv_ms": 1787089604867, "bids": [[14072.9, 2.94], [14472.9, 1.26], [58115.6, 0.002], [61989.9, 0.026], [63572.9, 0.0], [63765.7, 0.97], [63927.2, 0.005], [64056.3, 2.198], [64090.9, 0.031], [64250.0, 12.298]], "asks": [[64573.8, 0.0], [64895.9, 0.645], [65218.7, 0.002], [65341.4, 3.669], [65573.0, 0.0]]}
{"kind": "depth", "E": 1787089605113, "U": 11315997086158, "u": 11315997091495, "recv_ms": 1787089605070, "bids": [[1000.0, 35.76], [14072.9, 2.226], [14472.9, 1.974], [51658.0, 0.028], [58115.6, 0.002], [61989.9, 0.029], [63281.5, 0.019], [63572.9, 0.02], [63589.1, 1.029], [63642.6, 2.354], [63653.9, 0.0], [63656.1, 0.0], [63927.2, 0.005], [64250.0, 12.308], [64556.1, 0.005], [64561.3, 0.001], [64572.9, 24.811]], "asks": [[64588.5, 0.009], [65218.7, 0.002], [65291.2, 1.931], [65347.1, 29.562], [65489.9, 0.456], [65492.1, 0.002], [65556.9, 0.764], [65573.0, 0.02], [65864.4, 0.015], [67155.9, 0.637]]}
{"kind": "depth", "E": 1787089605215, "U": 11315997091504, "u": 11315997097539, "recv_ms": 1787089605174, "bids": [[14072.9, 1.862], [14472.9, 2.338], [51658.0, 0.0], [58115.6, 0.002], [61344.2, 0.005], [61344.4, 0.004], [61989.9, 0.026], [63589.1, 1.037], [63653.9, 0.008], [63656.1, 0.008], [63739.4, 1.19], [63789.5, 4.7], [63927.2, 0.005], [64056.3, 2.202], [64250.0, 12.307], [64499.7, 0.015], [64501.9, 32.635], [64530.0, 0.036], [64541.7, 0.034], [64558.6, 0.002], [64559.6, 1.863]], "asks": [[64573.0, 0.653], [64895.9, 0.646], [65218.7, 0.002]]}
{"kind": "depth", "E": 1787089605317, "U": 11315997097709, "u": 11315997101996, "recv_ms": 1787089605280, "bids": [[14072.9, 1.512], [14472.9, 2.688], [58115.6, 0.002], [61344.2, 0.005], [61989.9, 0.029], [63572.9, 0.0], [63834.8, 5.478], [63927.2, 0.005], [64056.3, 2.198], [64251.7, 0.108], [64435.1, 1.451], [64467.2, 2.338], [64502.0, 8.513], [64555.3, 6.92], [64556.8, 1.864], [64561.1, 0.003], [64562.1, 0.542], [64563.5, 0.001], [64563.7, 0.011], [64572.9, 24.721]], "asks": [[64577.7, 0.087], [64582.1, 0.003], [64592.2, 0.852], [64594.1, 0.003], [64622.5, 0.093], [64681.1, 2.323], [64681.2, 0.0], [64712.9, 1.215], [64906.3, 0.0], [64908.2, 0.108], [65218.7, 0.004], [65489.9, 0.464], [65492.1, 0.01], [65556.9, 0.772], [65573.0, 0.0], [65724.9, 0.03], [66058.2, 3.632]]}
{"kind": "depth", "E": 1787089605419, "U": 11315997102028, "u": 11315997107055, "recv_ms": 1787089605379, "bids": [[1000.0, 35.76], [14072.9, 1.148], [14472.9, 3.052], [51658.3, 0.0], [58115.6, 0.002], [61344.2, 0.005], [61989.9, 0.026], [63506.7, 1.101], [63635.8, 14.873], [63927.2, 0.005], [64250.0, 12.307], [64495.3, 0.01], [64499.7, 32.619], [64501.9, 0.001], [64502.0, 4.84], [64530.0, 0.032], [64539.4, 0.009], [64548.8, 0.626], [64552.8, 0.002], [64572.9, 24.82]], "asks": [[64573.0, 0.652], [64605.9, 1.432], [65218.7, 0.002], [65347.9, 9.631], [67800.8, 0.04]]}
{"kind": "depth", "E": 1787089605521, "U": 11315997107254, "u": 11315997113848, "recv_ms": 1787089605480, "bids": [[14072.9, 0.798], [14472.9, 3.402], [58115.6, 0.002], [63572.9, 0.02], [63652.7, 1.736], [63927.2, 0.007], [64450.7, 3.047], [64451.4, 0.091], [64540.5, 1.261], [64541.4, 0.001], [64542.1, 0.001], [64543.9, 0.0], [64545.8, 0.0], [64546.9, 0.012], [64548.8, 0.546], [64549.1, 0.482], [64549.9, 1.61], [64554.8, 0.581], [64555.4, 0.559], [64555.8, 0.0], [64556.4, 0.0], [64556.5, 0.083], [64556.9, 0.001], [64559.9, 0.004], [64560.2, 0.096], [64561.0, 0.002], [64562.2, 0.002], [64562.5, 0.311], [64563.4, 0.232], [64563.5, 0.001], [64564.2, 0.003], [64565.2, 0.002], [64565.6, 0.011], [64566.7, 0.634], [64566.9, 0.239], [64567.1, 0.583], [64567.7, 0.284], [64567.8, 0.174], [64568.1, 0.019], [64568.3, 2.001], [64568.6, 0.317], [64569.3, 0.393], [64569.4, 0.002], [64570.0, 1.251], [64570.1, 0.087], [64571.4, 0.006], [64571.6, 0.016], [64572.0, 0.343], [64572.4, 0.002], [64572.6, 0.0], [64572.7, 0.01], [64572.9, 27.819]], "asks": [[64574.3, 0.0], [64574.4, 0.004], [64575.5, 0.005], [64575.6, 0.005], [64575.7, 0.001], [64576.0, 0.039], [64577.7, 0.003], [64578.1, 0.0], [64578.2, 0.019], [64578.9, 0.001], [64579.2, 0.023], [64579.3, 0.093], [64579.4, 0.02], [64579.5, 0.016], [64579.8, 0.001], [64579.9, 0.078], [64580.0, 0.045], [64580.1, 0.001], [64580.2, 0.002], [64580.3, 0.08], [64580.6, 41.799], [64580.9, 0.033], [64581.0, 0.0], [64581.1, 0.124], [64581.3, 0.534], [64582.1, 0.087], [64582.5, 0.092], [64582.8, 0.245], [64583.1, 0.427], [64583.2, 0.341], [64583.6, 0.388], [64583.9, 0.084], [64584.1, 0.312], [64584.2, 0.0], [64584.3, 0.108], [64584.7, 0.16], [64585.0, 0.218], [64585.1, 0.072], [64585.7, 0.095], [64585.9, 0.004], [64586.7, 0.002], [64587.3, 0.466], [64587.7, 0.011], [64588.1, 0.066], [64589.0, 0.005], [64589.3, 0.309], [64589.9, 0.001], [64590.5, 0.024], [64591.3, 0.714], [64591.7, 0.0], [64592.0, 0.035], [64593.4, 0.001], [64593.6, 0.435], [64593.7, 0.01], [64594.7, 0.001], [64594.8, 1.245], [64595.2, 1.182], [64596.2, 0.584], [64596.3, 0.627], [64597.1, 0.633], [64597.9, 0.014], [64598.0, 0.018], [64598.2, 0.116], [64598.3, 0.0], [64600.6, 0.067], [64601.0, 0.375], [64601.2, 0.025], [64604.0, 0.002], [64604.7, 0.021], [64607.4, 0.157], [64614.4, 2.862], [64614.5, 0.007], [64625.0, 0.015], [64626.3, 5.085], [64670.8, 0.003], [64689.8, 0.0], [64768.9, 10.002], [65218.7, 0.002], [65573.0, 0.02], [66187.3, 1.584]]}
{"kind": "depth", "E": 1787089605623, "U": 11315997113920, "u": 11315997125595, "recv_ms": 1787089605583, "bids": [[14072.9, 0.462], [14372.9, 0.028], [14472.9, 3.71], [51658.0, 0.0], [58115.6, 0.004], [61344.2, 0.005], [61989.9, 0.029], [63281.5, 0.016], [63927.2, 0.005], [64250.0, 12.297], [64465.3, 0.613], [64469.8, 0.006], [64478.3, 0.002], [64487.8, 0.001], [64490.5, 3.676], [64507.1, 1.754], [64513.7, 0.163], [64516.7, 0.065], [64520.1, 1.888], [64530.3, 0.26], [64538.2, 0.0], [64541.8, 0.017], [64542.8, 0.036], [64543.8, 1.086], [64544.7, 0.14], [64544.8, 0.172], [64550.3, 0.484], [64554.1, 0.906], [64554.7, 0.005], [64555.3, 0.005], [64555.4, 0.001], [64556.8, 1.588], [64557.8, 0.003], [64559.2, 0.007], [64559.6, 1.863], [64559.8, 0.007], [64560.1, 0.001], [64560.3, 0.467], [64560.4, 0.444], [64560.5, 0.002], [64560.9, 0.001], [64561.9, 0.003], [64562.2, 0.002], [64562.4, 0.02], [64563.0, 0.97], [64563.1, 0.0], [64563.4, 0.155], [64563.5, 0.008], [64564.0, 0.011], [64564.3, 0.0], [64564.8, 0.002], [64564.9, 0.001], [64565.1, 0.053], [64565.2, 0.001], [64565.3, 0.001], [64565.4, 0.009], [64565.7, 0.155], [64566.0, 0.192], [64566.2, 0.001], [64566.4, 0.711], [64566.5, 0.002], [64566.6, 0.465], [64566.7, 0.007], [64566.8, 6.915], [64567.1, 0.141], [64567.2, 0.444], [64567.3, 0.247], [64567.7, 0.277], [64567.8, 0.175], [64568.1, 0.001], [64568.2, 0.117], [64568.3, 0.001], [64568.4, 0.002], [64568.6, 0.317], [64568.9, 0.008], [64569.1, 0.002], [64569.2, 0.034], [64569.3, 0.393], [64569.4, 0.122], [64569.5, 0.193], [64569.7, 0.004], [64570.0, 1.243], [64570.1, 2.285], [64570.2, 0.062], [64570.3, 0.01], [64570.5, 0.084], [64570.7, 0.011], [64571.2, 0.06], [64571.5, 0.043], [64571.7, 0.32], [64572.2, 1.292], [64572.3, 0.001], [64572.4, 0.0], [64572.5, 0.0], [64572.7, 0.011], [64572.8, 0.105], [64572.9, 25.019]], "asks": [[64574.8, 0.0], [64575.5, 0.262], [64575.6, 1.677], [64575.7, 0.001], [64576.1, 0.588], [64576.7, 1.803], [64576.8, 0.002], [64577.8, 0.014], [64578.0, 0.078], [64578.1, 0.0], [64578.2, 1.834], [64578.4, 0.006], [64579.2, 0.024], [64579.3, 0.093], [64579.4, 1.011], [64579.5, 1.817], [64579.6, 0.002], [64579.9, 0.0], [64580.0, 0.355], [64580.1, 0.085], [64580.2, 0.01], [64580.3, 1.802], [64580.4, 0.002], [64580.5, 7.394], [64580.6, 41.647], [64580.9, 0.117], [64581.1, 0.044], [64581.4, 0.084], [64581.7, 0.02], [64582.0, 0.133], [64582.1, 0.003], [64582.4, 0.011], [64582.5, 0.085], [64582.7, 0.138], [64583.4, 2.635], [64583.7, 2.721], [64583.8, 0.289], [64584.0, 2.327], [64584.3, 0.004], [64584.7, 0.003], [64585.0, 0.218], [64585.1, 0.002], [64585.2, 2.093], [64585.4, 0.333], [64585.9, 0.003], [64586.0, 0.175], [64586.4, 0.649], [64586.8, 0.001], [64587.9, 0.229], [64588.7, 0.07], [64588.9, 0.0], [64589.0, 0.005], [64589.3, 0.309], [64589.7, 0.004], [64589.8, 0.001], [64589.9, 0.001], [64590.4, 0.027], [64590.5, 0.027], [64590.6, 0.002], [64590.9, 0.0], [64591.1, 0.741], [64591.3, 0.103], [64591.8, 0.005], [64591.9, 0.008], [64592.0, 0.653], [64593.4, 0.001], [64593.6, 0.555], [64593.9, 0.211], [64594.0, 0.001], [64594.1, 0.003], [64594.3, 0.001], [64594.4, 0.458], [64594.6, 0.0], [64594.7, 0.009], [64594.8, 1.238], [64594.9, 0.045], [64595.2, 1.102], [64595.7, 0.321], [64595.9, 0.303], [64596.2, 0.027], [64596.3, 0.008], [64596.4, 0.0], [64596.6, 0.058], [64597.0, 0.668], [64597.2, 0.093], [64597.7, 0.665], [64598.0, 0.012], [64598.2, 0.0], [64598.3, 0.0], [64598.4, 0.038], [64598.6, 0.001], [64598.9, 2.419], [64599.2, 0.116], [64599.3, 2.044], [64599.4, 0.029], [64599.5, 0.028], [64599.7, 0.411], [64599.9, 0.629], [64600.0, 0.939], [64600.9, 0.009], [64601.2, 0.025], [64601.4, 4.595], [64601.9, 0.1], [64602.8, 1.886], [64602.9, 1.002], [64606.7, 0.018], [64611.2, 0.005], [64613.4, 0.091], [64614.4, 1.345], [64614.8, 0.985], [64615.0, 0.154], [64625.7, 5.109], [64626.3, 0.0], [64632.3, 0.004], [64640.2, 5.005], [64643.9, 3.021], [64644.7, 0.001], [64646.9, 38.054], [64651.3, 0.007], [64653.4, 0.83], [64653.5, 0.041], [64690.0, 0.045], [64690.2, 0.085], [64768.9, 9.823], [65218.7, 0.002], [66495.9, 0.0]]}
