{"receive_ns":1788563035018195000,"stream":"btcusdt@depth@100ms","event_type":"depthUpdate","event_time_ms":1788563035055,"raw_json":"{\"stream\":\"btcusdt@depth@100ms\",\"data\":{\"e\":\"depthUpdate\",\"E\":1788563035055,\"T\":1788563035053,\"s\":\"BTCUSDT\",\"ps\":\"BTCUSDT\",\"U\":11478212197673,\"u\":11478212202432,\"pu\":11478212197587,\"b\":[[\"29298.10\",\"0.938\"],[\"29398.10\",\"1.162\"],[\"71638.20\",\"0.002\"],[\"76414.10\",\"0.000\"],[\"78494.30\",\"0.533\"],[\"78538.80\",\"8.139\"],[\"78609.00\",\"0.014\"],[\"78611.30\",\"0.016\"],[\"78802.10\",\"0.002\"],[\"79200.10\",\"0.152\"],[\"79383.50\",\"3.981\"],[\"79384.00\",\"2.537\"],[\"79401.10\",\"0.000\"],[\"79431.30\",\"2.674\"],[\"79439.80\",\"0.001\"],[\"79440.90\",\"1.005\"],[\"79470.70\",\"0.565\"],[\"79496.60\",\"0.502\"],[\"79504.60\",\"0.000\"],[\"79506.60\",\"0.070\"],[\"79563.30\",\"0.001\"],[\"79564.80\",\"0.499\"],[\"79569.50\",\"0.002\"],[\"79572.10\",\"0.518\"],[\"79583.80\",\"0.000\"],[\"79598.10\",\"10.642\"]],\"a\":[[\"79599.40\",\"0.000\"],[\"79599.50\",\"0.000\"],[\"79600.00\",\"0.057\"],[\"79600.10\",\"0.002\"],[\"79601.00\",\"0.035\"],[\"79601.40\",\"0.026\"],[\"79601.50\",\"0.027\"],[\"79603.10\",\"0.000\"],[\"79720.20\",\"0.401\"],[\"79735.50\",\"0.275\"],[\"79736.70\",\"0.125\"],[\"79759.60\",\"2.566\"],[\"79807.40\",\"6.733\"],[\"79958.30\",\"0.001\"],[\"79958.40\",\"0.439\"],[\"79976.30\",\"0.001\"],[\"79976.80\",\"0.000\"],[\"79996.20\",\"0.653\"],[\"80356.60\",\"2.357\"],[\"80394.20\",\"0.499\"]],\"st\":1}}"}
{"receive_ns":1788563035090389000,"stream":"btcusdt@depth@100ms","event_type":"depthUpdate","event_time_ms":1788563035157,"raw_json":"{\"stream\":\"btcusdt@depth@100ms\",\"data\":{\"e\":\"depthUpdate\",\"E\":1788563035157,\"T\":1788563035153,\"s\":\"BTCUSDT\",\"ps\":\"BTCUSDT\",\"U\":11478212202467,\"u\":11478212208190,\"pu\":11478212202432,\"b\":[[\"1000.00\",\"24.604\"],[\"29298.10\",\"1.113\"],[\"29398.10\",\"0.987\"],[\"71638.20\",\"0.002\"],[\"75618.10\",\"0.018\"],[\"76414.10\",\"0.002\"],[\"78376.10\",\"0.007\"],[\"78380.60\",\"0.009\"],[\"78424.70\",\"1.171\"],[\"78663.40\",\"0.889\"],[\"78678.10\",\"0.000\"],[\"78681.90\",\"6.141\"],[\"78802.10\",\"0.002\"],[\"78942.20\",\"1.424\"],[\"79200.10\",\"0.152\"],[\"79401.10\",\"0.232\"],[\"79440.90\",\"2.110\"],[\"79441.80\",\"0.202\"],[\"79496.60\",\"0.828\"],[\"79595.60\",\"0.230\"]],\"a\":[[\"79600.30\",\"0.020\"],[\"79600.40\",\"0.294\"],[\"79601.60\",\"0.026\"],[\"79601.80\",\"0.027\"],[\"79603.10\",\"0.200\"],[\"79629.80\",\"0.011\"],[\"79653.50\",\"0.005\"],[\"79675.40\",\"0.652\"],[\"79684.90\",\"0.032\"],[\"79733.90\",\"0.186\"],[\"79735.50\",\"0.526\"],[\"79736.70\",\"0.000\"],[\"79736.80\",\"0.125\"],[\"79736.90\",\"0.000\"],[\"79996.20\",\"1.707\"],[\"80376.10\",\"0.003\"],[\"80394.20\",\"0.497\"],[\"80533.60\",\"8.864\"],[\"80811.20\",\"0.007\"]],\"st\":1}}"}
{"receive_ns":1788563035094382000,"stream":"btcusdt@bookTicker","event_type":"bookTicker","event_time_ms":1788563035160,"raw_json":"{\"stream\":\"btcusdt@bookTicker\",\"data\":{\"e\":\"bookTicker\",\"u\":11478212208431,\"s\":\"BTCUSDT\",\"ps\":\"BTCUSDT\",\"b\":\"79598.10\",\"B\":\"10.642\",\"a\":\"79598.20\",\"A\":\"2.445\",\"T\":1788563035159,\"E\":1788563035160,\"st\":1}}"}
{"receive_ns":1788563035094800000,"stream":"btcusdt@trade","event_type":"trade","event_time_ms":1788563035160,"raw_json":"{\"stream\":\"btcusdt@trade\",\"data\":{\"e\":\"trade\",\"E\":1788563035160,\"T\":1788563035159,\"s\":\"BTCUSDT\",\"t\":8054081699,\"p\":\"79598.20\",\"q\":\"0.058\",\"X\":\"MARKET\",\"m\":false,\"st\":1}}"}
{"receive_ns":1788563035094995000,"stream":"btcusdt@bookTicker","event_type":"bookTicker","event_time_ms":1788563035161,"raw_json":"{\"stream\":\"btcusdt@bookTicker\",\"data\":{\"e\":\"bookTicker\",\"u\":11478212208587,\"s\":\"BTCUSDT\",\"ps\":\"BTCUSDT\",\"b\":\"79598.10\",\"B\":\"10.650\",\"a\":\"79598.20\",\"A\":\"2.445\",\"T\":1788563035161,\"E\":1788563035161,\"st\":1}}"}
{"receive_ns":1788563035095150000,"stream":"btcusdt@bookTicker","event_type":"bookTicker","event_time_ms":1788563035161,"raw_json":"{\"stream\":\"btcusdt@bookTicker\",\"data\":{\"e\":\"bookTicker\",\"u\":11478212208607,\"s\":\"BTCUSDT\",\"ps\":\"BTCUSDT\",\"b\":\"79598.10\",\"B\":\"10.650\",\"a\":\"79598.20\",\"A\":\"2.365\",\"T\":1788563035161,\"E\":1788563035161,\"st\":1}}"}
{"receive_ns":1788563035095328000,"stream":"btcusdt@bookTicker","event_type":"bookTicker","event_time_ms":1788563035162,"raw_json":"{\"stream\":\"btcusdt@bookTicker\",\"data\":{\"e\":\"bookTicker\",\"u\":11478212208715,\"s\":\"BTCUSDT\",\"ps\":\"BTCUSDT\",\"b\":\"79598.10\",\"B\":\"10.642\",\"a\":\"79598.20\",\"A\":\"2.365\",\"T\":1788563035162,\"E\":1788563035162,\"st\":1}}"}
{"receive_ns":1788563035099803000,"stream":"btcusdt@bookTicker","event_type":"bookTicker","event_time_ms":1788563035164,"raw_json":"{\"stream\":\"btcusdt@bookTicker\",\"data\":{\"e\":\"bookTicker\",\"u\":11478212208868,\"s\":\"BTCUSDT\",\"ps\":\"BTCUSDT\",\"b\":\"79598.10\",\"B\":\"10.642\",\"a\":\"79598.20\",\"A\":\"2.364\",\"T\":1788563035164,\"E\":1788563035164,\"st\":1}}"}
{"receive_ns":1788563035114194000,"stream":"btcusdt@bookTicker","event_type":"bookTicker","event_time_ms":1788563035181,"raw_json":"{\"stream\":\"btcusdt@bookTicker\",\"data\":{\"e\":\"bookTicker\",\"u\":11478212209785,\"s\":\"BTCUSDT\",\"ps\":\"BTCUSDT\",\"b\":\"79598.10\",\"B\":\"10.644\",\"a\":\"79598.20\",\"A\":\"2.364\",\"T\":1788563035180,\"E\":1788563035181,\"st\":1}}"}
{"receive_ns":1788563035165842000,"stream":"btcusdt@bookTicker","event_type":"bookTicker","event_time_ms":1788563035232,"raw_json":"{\"stream\":\"btcusdt@bookTicker\",\"data\":{\"e\":\"bookTicker\",\"u\":11478212212639,\"s\":\"BTCUSDT\",\"ps\":\"BTCUSDT\",\"b\":\"79598.10\",\"B\":\"10.630\",\"a\":\"79598.20\",\"A\":\"2.364\",\"T\":1788563035232,\"E\":1788563035232,\"st\":1}}"}
{"receive_ns":1788563035170293000,"stream":"btcusdt@bookTicker","event_type":"bookTicker","event_time_ms":1788563035235,"raw_json":"{\"stream\":\"btcusdt@bookTicker\",\"data\":{\"e\":\"bookTicker\",\"u\":11478212212786,\"s\":\"BTCUSDT\",\"ps\":\"BTCUSDT\",\"b\":\"79598.10\",\"B\":\"10.646\",\"a\":\"79598.20\",\"A\":\"2.364\",\"T\":1788563035235,\"E\":1788563035235,\"st\":1}}"}
{"receive_ns":1788563035245155000,"stream":"btcusdt@bookTicker","event_type":"bookTicker","event_time_ms":1788563035236,"raw_json":"{\"stream\":\"btcusdt@bookTicker\",\"data\":{\"e\":\"bookTicker\",\"u\":11478212212831,\"s\":\"BTCUSDT\",\"ps\":\"BTCUSDT\",\"b\":\"79598.10\",\"B\":\"10.649\",\"a\":\"79598.20\",\"A\":\"2.364\",\"T\":1788563035236,\"E\":1788563035236,\"st\":1}}"}
{"receive_ns":1788563035245754000,"stream":"btcusdt@depth@100ms","event_type":"depthUpdate","event_time_ms":1788563035259,"raw_json":"{\"stream\":\"btcusdt@depth@100ms\",\"data\":{\"e\":\"depthUpdate\",\"E\":1788563035259,\"T\":1788563035257,\"s\":\"BTCUSDT\",\"ps\":\"BTCUSDT\",\"U\":11478212208346,\"u\":11478212214063,\"pu\":11478212208190,\"b\":[[\"1000.00\",\"24.604\"],[\"29298.10\",\"1.295\"],[\"29398.10\",\"0.805\"],[\"63679.00\",\"0.000\"],[\"71638.20\",\"0.002\"],[\"76414.10\",\"0.000\"],[\"78443.90\",\"0.892\"],[\"78682.70\",\"0.762\"],[\"78802.10\",\"0.002\"],[\"79200.10\",\"0.152\"],[\"79440.90\",\"2.110\"],[\"79462.50\",\"0.007\"],[\"79462.60\",\"0.016\"],[\"79470.70\",\"0.604\"],[\"79562.70\",\"0.002\"],[\"79563.30\",\"0.001\"],[\"79564.80\",\"0.499\"],[\"79569.50\",\"0.002\"],[\"79572.10\",\"0.518\"],[\"79573.50\",\"0.040\"],[\"79581.80\",\"0.080\"],[\"79589.40\",\"0.002\"],[\"79592.20\",\"0.000\"],[\"79592.30\",\"0.252\"],[\"79593.50\",\"0.000\"],[\"79598.10\",\"10.649\"]],\"a\":[[\"79598.20\",\"2.364\"],[\"79600.70\",\"0.002\"],[\"79600.90\",\"0.080\"],[\"79601.00\",\"0.009\"],[\"79601.10\",\"0.004\"],[\"79601.30\",\"0.000\"],[\"79601.90\",\"0.026\"],[\"79602.00\",\"0.103\"],[\"79602.10\",\"0.028\"],[\"79602.20\",\"0.280\"],[\"79603.30\",\"0.000\"],[\"79684.80\",\"0.003\"],[\"79698.90\",\"0.002\"],[\"79699.00\",\"0.110\"],[\"79720.20\",\"0.432\"],[\"79735.50\",\"0.275\"],[\"79736.80\",\"0.125\"],[\"79820.60\",\"0.000\"],[\"79820.70\",\"0.003\"],[\"79996.20\",\"1.707\"],[\"80354.40\",\"3.106\"],[\"80394.20\",\"3.103\"],[\"80815.70\",\"0.007\"]],\"st\":1}}"}
{"receive_ns":1788563035294388000,"stream":"btcusdt@bookTicker","event_type":"bookTicker","event_time_ms":1788563035315,"raw_json":"{\"stream\":\"btcusdt@bookTicker\",\"data\":{\"e\":\"bookTicker\",\"u\":11478212216910,\"s\":\"BTCUSDT\",\"ps\":\"BTCUSDT\",\"b\":\"79598.10\",\"B\":\"10.646\",\"a\":\"79598.20\",\"A\":\"2.364\",\"T\":1788563035314,\"E\":1788563035315,\"st\":1}}"}
{"receive_ns":1788563035294742000,"stream":"btcusdt@bookTicker","event_type":"bookTicker","event_time_ms":1788563035317,"raw_json":"{\"stream\":\"btcusdt@bookTicker\",\"data\":{\"e\":\"bookTicker\",\"u\":11478212217046,\"s\":\"BTCUSDT\",\"ps\":\"BTCUSDT\",\"b\":\"79598.10\",\"B\":\"10.652\",\"a\":\"79598.20\",\"A\":\"2.364\",\"T\":1788563035317,\"E\":1788563035317,\"st\":1}}"}
{"receive_ns":1788563035295010000,"stream":"btcusdt@bookTicker","event_type":"bookTicker","event_time_ms":1788563035322,"raw_json":"{\"stream\":\"btcusdt@bookTicker\",\"data\":{\"e\":\"bookTicker\",\"u\":11478212217291,\"s\":\"BTCUSDT\",\"ps\":\"BTCUSDT\",\"b\":\"79598.10\",\"B\":\"10.660\",\"a\":\"79598.20\",\"A\":\"2.364\",\"T\":1788563035322,\"E\":1788563035322,\"st\":1}}"}
{"receive_ns":1788563035295264000,"stream":"btcusdt@bookTicker","event_type":"bookTicker","event_time_ms":1788563035323,"raw_json":"{\"stream\":\"btcusdt@bookTicker\",\"data\":{\"e\":\"bookTicker\",\"u\":11478212217348,\"s\":\"BTCUSDT\",\"ps\":\"BTCUSDT\",\"b\":\"79598.10\",\"B\":\"10.652\",\"a\":\"79598.20\",\"A\":\"2.364\",\"T\":1788563035323,\"E\":1788563035323,\"st\":1}}"}
{"receive_ns":1788563035295558000,"stream":"btcusdt@bookTicker","event_type":"bookTicker","event_time_ms":1788563035325,"raw_json":"{\"stream\":\"btcusdt@bookTicker\",\"data\":{\"e\":\"bookTicker\",\"u\":11478212217512,\"s\":\"BTCUSDT\",\"ps\":\"BTCUSDT\",\"b\":\"79598.10\",\"B\":\"10.619\",\"a\":\"79598.20\",\"A\":\"2.364\",\"T\":1788563035325,\"E\":1788563035325,\"st\":1}}"}
{"receive_ns":1788563035295979000,"stream":"btcusdt@bookTicker","event_type":"bookTicker","event_time_ms":1788563035328,"raw_json":"{\"stream\":\"btcusdt@bookTicker\",\"data\":{\"e\":\"bookTicker\",\"u\":11478212217666,\"s\":\"BTCUSDT\",\"ps\":\"BTCUSDT\",\"b\":\"79598.10\",\"B\":\"10.653\",\"a\":\"79598.20\",\"A\":\"2.364\",\"T\":1788563035328,\"E\":1788563035328,\"st\":1}}"}
{"receive_ns":1788563035296273000,"stream":"btcusdt@bookTicker","event_type":"bookTicker","event_time_ms":1788563035342,"raw_json":"{\"stream\":\"btcusdt@bookTicker\",\"data\":{\"e\":\"bookTicker\",\"u\":11478212218496,\"s\":\"BTCUSDT\",\"ps\":\"BTCUSDT\",\"b\":\"79598.10\",\"B\":\"10.653\",\"a\":\"79598.20\",\"A\":\"2.365\",\"T\":1788563035342,\"E\":1788563035342,\"st\":1}}"}
{"receive_ns":1788563035296804000,"stream":"btcusdt@depth@100ms","event_type":"depthUpdate","event_time_ms":1788563035361,"raw_json":"{\"stream\":\"btcusdt@depth@100ms\",\"data\":{\"e\":\"depthUpdate\",\"E\":1788563035361,\"T\":1788563035358,\"s\":\"BTCUSDT\",\"ps\":\"BTCUSDT\",\"U\":11478212214279,\"u\":11478212220157,\"pu\":11478212214063,\"b\":[[\"29298.10\",\"1.470\"],[\"29398.10\",\"0.630\"],[\"63675.00\",\"0.006\"],[\"71638.20\",\"0.002\"],[\"76414.10\",\"0.002\"],[\"78231.70\",\"0.638\"],[\"78464.50\",\"8.171\"],[\"78623.70\",\"8.190\"],[\"78732.70\",\"1.904\"],[\"78802.10\",\"0.002\"],[\"78961.30\",\"0.253\"],[\"79401.10\",\"0.232\"],[\"79416.80\",\"0.002\"],[\"79419.40\",\"0.516\"],[\"79419.90\",\"1.517\"],[\"79440.90\",\"2.185\"],[\"79441.80\",\"0.202\"],[\"79448.50\",\"1.512\"],[\"79452.80\",\"0.502\"],[\"79496.60\",\"0.251\"],[\"79553.70\",\"0.436\"],[\"79556.10\",\"0.006\"],[\"79598.10\",\"10.653\"]],\"a\":[[\"79598.20\",\"2.365\"],[\"79599.50\",\"0.252\"],[\"79600.50\",\"0.486\"],[\"79600.70\",\"0.002\"],[\"79600.80\",\"0.001\"],[\"79601.20\",\"0.027\"],[\"79602.10\",\"0.028\"],[\"79602.20\",\"0.003\"],[\"79603.10\",\"0.200\"],[\"79661.00\",\"1.755\"],[\"79733.90\",\"0.127\"],[\"79735.50\",\"0.275\"],[\"79736.40\",\"0.011\"],[\"79736.70\",\"0.000\"],[\"79736.80\",\"0.000\"],[\"79737.10\",\"2.066\"],[\"79737.20\",\"0.001\"],[\"79798.00\",\"1.465\"],[\"79957.20\",\"0.321\"],[\"79958.40\",\"0.439\"],[\"79996.20\",\"1.707\"],[\"80175.70\",\"0.000\"],[\"80394.20\",\"3.103\"],[\"80553.40\",\"1.728\"],[\"80734.20\",\"0.866\"]],\"st\":1}}"}
{"receive_ns":1788563035297117000,"stream":"btcusdt@bookTicker","event_type":"bookTicker","event_time_ms":1788563035363,"raw_json":"{\"stream\":\"btcusdt@bookTicker\",\"data\":{\"e\":\"bookTicker\",\"u\":11478212220452,\"s\":\"BTCUSDT\",\"ps\":\"BTCUSDT\",\"b\":\"79598.10\",\"B\":\"10.653\",\"a\":\"79598.20\",\"A\":\"2.364\",\"T\":1788563035362,\"E\":1788563035363,\"st\":1}}"}
{"receive_ns":1788563035359050000,"stream":"btcusdt@bookTicker","event_type":"bookTicker","event_time_ms":1788563035424,"raw_json":"{\"stream\":\"btcusdt@bookTicker\",\"data\":{\"e\":\"bookTicker\",\"u\":11478212223502,\"s\":\"BTCUSDT\",\"ps\":\"BTCUSDT\",\"b\":\"79598.10\",\"B\":\"10.653\",\"a\":\"79598.20\",\"A\":\"2.368\",\"T\":1788563035423,\"E\":1788563035424,\"st\":1}}"}
{"receive_ns":1788563035362424000,"stream":"btcusdt@bookTicker","event_type":"bookTicker","event_time_ms":1788563035426,"raw_json":"{\"stream\":\"btcusdt@bookTicker\",\"data\":{\"e\":\"bookTicker\",\"u\":11478212223691,\"s\":\"BTCUSDT\",\"ps\":\"BTCUSDT\",\"b\":\"79598.10\",\"B\":\"10.653\",\"a\":\"79598.20\",\"A\":\"2.372\",\"T\":1788563035425,\"E\":1788563035426,\"st\":1}}"}
{"receive_ns":1788563035399208000,"stream":"btcusdt@depth@100ms","event_type":"depthUpdate","event_time_ms":1788563035463,"raw_json":"{\"stream\":\"btcusdt@depth@100ms\",\"data\":{\"e\":\"depthUpdate\",\"E\":1788563035463,\"T\":1788563035461,\"s\":\"BTCUSDT\",\"ps\":\"BTCUSDT\",\"U\":11478212220385,\"u\":11478212225384,\"pu\":11478212220157,\"b\":[[\"1000.00\",\"24.604\"],[\"29298.10\",\"1.652\"],[\"29398.10\",\"0.448\"],[\"71638.20\",\"0.002\"],[\"77974.00\",\"0.257\"],[\"78371.80\",\"0.006\"],[\"78546.90\",\"0.006\"],[\"78578.60\",\"10.003\"],[\"78769.60\",\"1.131\"],[\"78802.10\",\"0.002\"],[\"79200.10\",\"0.011\"],[\"79440.90\",\"1.180\"],[\"79571.90\",\"0.634\"],[\"79573.60\",\"0.000\"],[\"79574.40\",\"0.050\"]],\"a\":[[\"79598.20\",\"2.372\"],[\"79600.40\",\"0.294\"],[\"79600.70\",\"0.028\"],[\"79614.30\",\"0.361\"],[\"79629.40\",\"0.780\"],[\"79736.60\",\"0.000\"],[\"79736.70\",\"0.000\"],[\"79737.10\",\"1.941\"],[\"79996.20\",\"1.181\"],[\"80363.90\",\"0.006\"],[\"80394.20\",\"3.103\"],[\"80586.60\",\"0.006\"],[\"80761.70\",\"0.051\"],[\"81159.50\",\"0.075\"],[\"87558.10\",\"0.000\"]],\"st\":1}}"}
{"receive_ns":1788563035424909000,"stream":"btcusdt@bookTicker","event_type":"bookTicker","event_time_ms":1788563035482,"raw_json":"{\"stream\":\"btcusdt@bookTicker\",\"data\":{\"e\":\"bookTicker\",\"u\":11478212226233,\"s\":\"BTCUSDT\",\"ps\":\"BTCUSDT\",\"b\":\"79598.10\",\"B\":\"10.653\",\"a\":\"79598.20\",\"A\":\"2.402\",\"T\":1788563035482,\"E\":1788563035482,\"st\":1}}"}
{"receive_ns":1788563035425354000,"stream":"btcusdt@bookTicker","event_type":"bookTicker","event_time_ms":1788563035484,"raw_json":"{\"stream\":\"btcusdt@bookTicker\",\"data\":{\"e\":\"bookTicker\",\"u\":11478212226308,\"s\":\"BTCUSDT\",\"ps\":\"BTCUSDT\",\"b\":\"79598.10\",\"B\":\"10.653\",\"a\":\"79598.20\",\"A\":\"2.401\",\"T\":1788563035484,\"E\":1788563035484,\"st\":1}}"}
{"receive_ns":1788563035500237000,"stream":"btcusdt@depth@100ms","event_type":"depthUpdate","event_time_ms":1788563035565,"raw_json":"{\"stream\":\"btcusdt@depth@100ms\",\"data\":{\"e\":\"depthUpdate\",\"E\":1788563035565,\"T\":1788563035564,\"s\":\"BTCUSDT\",\"ps\":\"BTCUSDT\",\"U\":11478212225472,\"u\":11478212229708,\"pu\":11478212225384,\"b\":[[\"1000.00\",\"24.604\"],[\"29198.10\",\"0.028\"],[\"29298.10\",\"1.771\"],[\"29398.10\",\"0.301\"],[\"63678.50\",\"0.000\"],[\"71638.20\",\"0.002\"],[\"76414.10\",\"0.000\"],[\"78006.20\",\"0.018\"],[\"78371.80\",\"0.000\"],[\"78546.90\",\"0.000\"],[\"78802.10\",\"0.004\"],[\"79200.10\",\"0.152\"],[\"79401.10\",\"0.000\"],[\"79440.70\",\"0.000\"],[\"79440.90\",\"1.507\"],[\"79441.80\",\"0.202\"],[\"79452.80\",\"0.000\"],[\"79470.70\",\"0.000\"],[\"79496.60\",\"0.000\"],[\"79524.50\",\"0.001\"],[\"79533.80\",\"0.007\"],[\"79573.30\",\"0.013\"]],\"a\":[[\"79598.20\",\"2.401\"],[\"79600.40\",\"0.293\"],[\"79600.60\",\"0.018\"],[\"79603.10\",\"0.200\"],[\"79605.60\",\"1.012\"],[\"79612.30\",\"0.030\"],[\"79618.90\",\"0.043\"],[\"79624.40\",\"0.021\"],[\"79720.20\",\"0.022\"],[\"79735.50\",\"0.024\"],[\"79736.80\",\"0.000\"],[\"79737.20\",\"0.001\"],[\"79958.40\",\"0.439\"],[\"79996.20\",\"0.653\"],[\"80363.90\",\"0.000\"],[\"80394.20\",\"2.981\"],[\"80533.60\",\"7.624\"],[\"80533.80\",\"9.919\"],[\"80586.60\",\"0.000\"],[\"80693.00\",\"13.740\"],[\"80752.40\",\"0.866\"]],\"st\":1}}"}
{"receive_ns":1788563035594444000,"stream":"btcusdt@bookTicker","event_type":"bookTicker","event_time_ms":1788563035660,"raw_json":"{\"stream\":\"btcusdt@bookTicker\",\"data\":{\"e\":\"bookTicker\",\"u\":11478212233907,\"s\":\"BTCUSDT\",\"ps\":\"BTCUSDT\",\"b\":\"79598.10\",\"B\":\"10.654\",\"a\":\"79598.20\",\"A\":\"2.401\",\"T\":1788563035660,\"E\":1788563035660,\"st\":1}}"}
{"receive_ns":1788563035595200000,"stream":"btcusdt@bookTicker","event_type":"bookTicker","event_time_ms":1788563035661,"raw_json":"{\"stream\":\"btcusdt@bookTicker\",\"data\":{\"e\":\"bookTicker\",\"u\":11478212234060,\"s\":\"BTCUSDT\",\"ps\":\"BTCUSDT\",\"b\":\"79598.10\",\"B\":\"10.710\",\"a\":\"79598.20\",\"A\":\"2.401\",\"T\":1788563035661,\"E\":1788563035661,\"st\":1}}"}
{"receive_ns":1788563035595571000,"stream":"btcusdt@bookTicker","event_type":"bookTicker","event_time_ms":1788563035661,"raw_json":"{\"stream\":\"btcusdt@bookTicker\",\"data\":{\"e\":\"bookTicker\",\"u\":11478212234080,\"s\":\"BTCUSDT\",\"ps\":\"BTCUSDT\",\"b\":\"79598.10\",\"B\":\"10.710\",\"a\":\"79598.20\",\"A\":\"2.400\",\"T\":1788563035661,\"E\":1788563035661,\"st\":1}}"}
{"receive_ns":1788563035596011000,"stream":"btcusdt@trade","event_type":"trade","event_time_ms":1788563035661,"raw_json":"{\"stream\":\"btcusdt@trade\",\"data\":{\"e\":\"trade\",\"E\":1788563035661,\"T\":1788563035661,\"s\":\"BTCUSDT\",\"t\":8054081700,\"p\":\"79598.20\",\"q\":\"0.001\",\"X\":\"MARKET\",\"m\":false,\"st\":1}}"}
{"receive_ns":1788563035598722000,"stream":"btcusdt@bookTicker","event_type":"bookTicker","event_time_ms":1788563035663,"raw_json":"{\"stream\":\"btcusdt@bookTicker\",\"data\":{\"e\":\"bookTicker\",\"u\":11478212234318,\"s\":\"BTCUSDT\",\"ps\":\"BTCUSDT\",\"b\":\"79598.10\",\"B\":\"10.710\",\"a\":\"79598.20\",\"A\":\"2.401\",\"T\":1788563035662,\"E\":1788563035663,\"st\":1}}"}
{"receive_ns":1788563035599341000,"stream":"btcusdt@bookTicker","event_type":"bookTicker","event_time_ms":1788563035663,"raw_json":"{\"stream\":\"btcusdt@bookTicker\",\"data\":{\"e\":\"bookTicker\",\"u\":11478212234375,\"s\":\"BTCUSDT\",\"ps\":\"BTCUSDT\",\"b\":\"79598.10\",\"B\":\"10.708\",\"a\":\"79598.20\",\"A\":\"2.401\",\"T\":1788563035663,\"E\":1788563035663,\"st\":1}}"}
{"receive_ns":1788563035599883000,"stream":"btcusdt@bookTicker","event_type":"bookTicker","event_time_ms":1788563035663,"raw_json":"{\"stream\":\"btcusdt@bookTicker\",\"data\":{\"e\":\"bookTicker\",\"u\":11478212234407,\"s\":\"BTCUSDT\",\"ps\":\"BTCUSDT\",\"b\":\"79598.10\",\"B\":\"10.716\",\"a\":\"79598.20\",\"A\":\"2.401\",\"T\":1788563035663,\"E\":1788563035663,\"st\":1}}"}
{"receive_ns":1788563035600279000,"stream":"btcusdt@bookTicker","event_type":"bookTicker","event_time_ms":1788563035664,"raw_json":"{\"stream\":\"btcusdt@bookTicker\",\"data\":{\"e\":\"bookTicker\",\"u\":11478212234623,\"s\":\"BTCUSDT\",\"ps\":\"BTCUSDT\",\"b\":\"79598.10\",\"B\":\"10.708\",\"a\":\"79598.20\",\"A\":\"2.401\",\"T\":1788563035663,\"E\":1788563035664,\"st\":1}}"}
{"receive_ns":1788563035600738000,"stream":"btcusdt@bookTicker","event_type":"bookTicker","event_time_ms":1788563035665,"raw_json":"{\"stream\":\"btcusdt@bookTicker\",\"data\":{\"e\":\"bookTicker\",\"u\":11478212234790,\"s\":\"BTCUSDT\",\"ps\":\"BTCUSDT\",\"b\":\"79598.10\",\"B\":\"10.708\",\"a\":\"79598.20\",\"A\":\"2.389\",\"T\":1788563035664,\"E\":1788563035665,\"st\":1}}"}
{"receive_ns":1788563035603107000,"stream":"btcusdt@depth@100ms","event_type":"depthUpdate","event_time_ms":1788563035667,"raw_json":"{\"stream\":\"btcusdt@depth@100ms\",\"data\":{\"e\":\"depthUpdate\",\"E\":1788563035667,\"T\":1788563035666,\"s\":\"BTCUSDT\",\"ps\":\"BTCUSDT\",\"U\":11478212229740,\"u\":11478212234971,\"pu\":11478212229708,\"b\":[[\"29198.10\",\"0.084\"],[\"29298.10\",\"1.841\"],[\"29398.10\",\"0.175\"],[\"63679.00\",\"0.000\"],[\"71638.20\",\"0.002\"],[\"71638.30\",\"0.002\"],[\"76414.10\",\"0.002\"],[\"77995.60\",\"0.000\"],[\"77997.90\",\"0.000\"],[\"78001.80\",\"0.002\"],[\"78265.60\",\"0.002\"],[\"78483.70\",\"3.818\"],[\"78642.90\",\"2.540\"],[\"78784.10\",\"1.332\"],[\"78802.10\",\"0.004\"],[\"79077.70\",\"0.154\"],[\"79120.50\",\"0.313\"],[\"79226.00\",\"0.256\"],[\"79429.40\",\"0.017\"],[\"79431.30\",\"0.000\"],[\"79440.90\",\"2.938\"],[\"79466.70\",\"3.908\"],[\"79472.70\",\"1.572\"],[\"79564.80\",\"0.047\"],[\"79566.90\",\"0.452\"],[\"79569.50\",\"0.630\"],[\"79571.70\",\"0.003\"],[\"79571.90\",\"0.006\"],[\"79573.50\",\"0.040\"],[\"79574.90\",\"0.373\"],[\"79575.90\",\"0.000\"],[\"79577.40\",\"0.076\"],[\"79577.60\",\"0.801\"],[\"79578.70\",\"0.000\"],[\"79579.40\",\"0.000\"],[\"79579.70\",\"0.006\"],[\"79580.80\",\"0.000\"],[\"79581.00\",\"0.000\"],[\"79581.40\",\"0.007\"],[\"79581.60\",\"0.648\"],[\"79581.80\",\"0.076\"],[\"79582.00\",\"0.457\"],[\"79582.40\",\"0.117\"],[\"79582.90\",\"0.564\"],[\"79583.00\",\"0.081\"],[\"79583.40\",\"0.006\"],[\"79583.50\",\"0.032\"],[\"79583.60\",\"0.064\"],[\"79584.10\",\"0.112\"],[\"79584.80\",\"0.004\"],[\"79585.20\",\"0.002\"],[\"79586.80\",\"0.002\"],[\"79586.90\",\"0.002\"],[\"79587.50\",\"0.000\"],[\"79587.60\",\"0.005\"],[\"79589.40\",\"0.006\"],[\"79589.80\",\"0.503\"],[\"79591.60\",\"0.794\"],[\"79592.20\",\"0.000\"],[\"79598.10\",\"10.708\"]],\"a\":[[\"79598.20\",\"2.389\"],[\"79600.70\",\"0.002\"],[\"79600.80\",\"0.001\"],[\"79601.20\",\"0.001\"],[\"79601.40\",\"0.000\"],[\"79601.50\",\"0.001\"],[\"79601.60\",\"0.000\"],[\"79601.80\",\"0.001\"],[\"79601.90\",\"0.000\"],[\"79602.00\",\"0.077\"],[\"79602.10\",\"0.253\"],[\"79602.20\",\"0.003\"],[\"79603.80\",\"0.000\"],[\"79603.90\",\"0.050\"],[\"79604.10\",\"0.329\"],[\"79604.30\",\"0.029\"],[\"79604.50\",\"0.033\"],[\"79604.70\",\"0.026\"],[\"79605.40\",\"0.006\"],[\"79605.50\",\"0.004\"],[\"79605.90\",\"0.026\"],[\"79606.00\",\"0.692\"],[\"79606.10\",\"0.001\"],[\"79606.20\",\"0.094\"],[\"79606.30\",\"0.340\"],[\"79606.40\",\"0.107\"],[\"79606.50\",\"0.027\"],[\"79606.60\",\"1.369\"],[\"79606.70\",\"0.026\"],[\"79606.80\",\"0.027\"],[\"79607.00\",\"0.026\"],[\"79607.10\",\"0.000\"],[\"79607.20\",\"0.002\"],[\"79607.70\",\"1.264\"],[\"79608.30\",\"0.001\"],[\"79609.50\",\"0.071\"],[\"79610.20\",\"0.315\"],[\"79610.60\",\"0.001\"],[\"79611.10\",\"0.281\"],[\"79613.20\",\"0.060\"],[\"79613.70\",\"0.251\"],[\"79613.90\",\"0.000\"],[\"79614.70\",\"0.001\"],[\"79614.90\",\"0.372\"],[\"79615.30\",\"0.001\"],[\"79617.00\",\"0.457\"],[\"79618.90\",\"0.036\"],[\"79619.30\",\"0.026\"],[\"79619.50\",\"0.162\"],[\"79619.70\",\"0.255\"],[\"79619.90\",\"0.150\"],[\"79621.60\",\"0.627\"],[\"79622.30\",\"0.001\"],[\"79622.70\",\"0.000\"],[\"79623.90\",\"1.298\"],[\"79625.40\",\"0.000\"],[\"79625.50\",\"0.649\"],[\"79627.10\",\"0.046\"],[\"79631.40\",\"0.228\"],[\"79637.90\",\"0.060\"],[\"79654.30\",\"0.037\"],[\"79736.70\",\"0.000\"],[\"79736.90\",\"0.000\"],[\"79737.10\",\"1.941\"],[\"79737.20\",\"0.001\"],[\"79759.60\",\"0.013\"],[\"79996.20\",\"1.617\"],[\"80394.20\",\"2.981\"],[\"80533.80\",\"8.679\"],[\"81179.10\",\"0.003\"],[\"81185.50\",\"0.000\"],[\"87558.10\",\"0.000\"]],\"st\":1}}"}
{"receive_ns":1788563035608288000,"stream":"btcusdt@bookTicker","event_type":"bookTicker","event_time_ms":1788563035672,"raw_json":"{\"stream\":\"btcusdt@bookTicker\",\"data\":{\"e\":\"bookTicker\",\"u\":11478212235495,\"s\":\"BTCUSDT\",\"ps\":\"BTCUSDT\",\"b\":\"79598.10\",\"B\":\"10.716\",\"a\":\"79598.20\",\"A\":\"2.389\",\"T\":1788563035672,\"E\":1788563035672,\"st\":1}}"}
{"receive_ns":1788563035608793000,"stream":"btcusdt@bookTicker","event_type":"bookTicker","event_time_ms":1788563035673,"raw_json":"{\"stream\":\"btcusdt@bookTicker\",\"data\":{\"e\":\"bookTicker\",\"u\":11478212235533,\"s\":\"BTCUSDT\",\"ps\":\"BTCUSDT\",\"b\":\"79598.10\",\"B\":\"10.708\",\"a\":\"79598.20\",\"A\":\"2.389\",\"T\":1788563035672,\"E\":1788563035673,\"st\":1}}"}
{"receive_ns":1788563035642597000,"stream":"btcusdt@bookTicker","event_type":"bookTicker","event_time_ms":1788563035707,"raw_json":"{\"stream\":\"btcusdt@bookTicker\",\"data\":{\"e\":\"bookTicker\",\"u\":11478212236753,\"s\":\"BTCUSDT\",\"ps\":\"BTCUSDT\",\"b\":\"79598.10\",\"B\":\"10.708\",\"a\":\"79598.20\",\"A\":\"3.553\",\"T\":1788563035707,\"E\":1788563035707,\"st\":1}}"}
{"receive_ns":1788563035643108000,"stream":"btcusdt@bookTicker","event_type":"bookTicker","event_time_ms":1788563035708,"raw_json":"{\"stream\":\"btcusdt@bookTicker\",\"data\":{\"e\":\"bookTicker\",\"u\":11478212236797,\"s\":\"BTCUSDT\",\"ps\":\"BTCUSDT\",\"b\":\"79598.10\",\"B\":\"10.708\",\"a\":\"79598.20\",\"A\":\"3.552\",\"T\":1788563035707,\"E\":1788563035708,\"st\":1}}"}
{"receive_ns":1788563035643542000,"stream":"btcusdt@bookTicker","event_type":"bookTicker","event_time_ms":1788563035708,"raw_json":"{\"stream\":\"btcusdt@bookTicker\",\"data\":{\"e\":\"bookTicker\",\"u\":11478212236823,\"s\":\"BTCUSDT\",\"ps\":\"BTCUSDT\",\"b\":\"79598.10\",\"B\":\"10.710\",\"a\":\"79598.20\",\"A\":\"3.552\",\"T\":1788563035708,\"E\":1788563035708,\"st\":1}}"}
{"receive_ns":1788563035643973000,"stream":"btcusdt@bookTicker","event_type":"bookTicker","event_time_ms":1788563035708,"raw_json":"{\"stream\":\"btcusdt@bookTicker\",\"data\":{\"e\":\"bookTicker\",\"u\":11478212236865,\"s\":\"BTCUSDT\",\"ps\":\"BTCUSDT\",\"b\":\"79598.10\",\"B\":\"10.718\",\"a\":\"79598.20\",\"A\":\"3.552\",\"T\":1788563035708,\"E\":1788563035708,\"st\":1}}"}
{"receive_ns":1788563035644435000,"stream":"btcusdt@bookTicker","event_type":"bookTicker","event_time_ms":1788563035708,"raw_json":"{\"stream\":\"btcusdt@bookTicker\",\"data\":{\"e\":\"bookTicker\",\"u\":11478212236876,\"s\":\"BTCUSDT\",\"ps\":\"BTCUSDT\",\"b\":\"79598.10\",\"B\":\"10.718\",\"a\":\"79598.20\",\"A\":\"3.553\",\"T\":1788563035708,\"E\":1788563035708,\"st\":1}}"}
{"receive_ns":1788563035644958000,"stream":"btcusdt@bookTicker","event_type":"bookTicker","event_time_ms":1788563035708,"raw_json":"{\"stream\":\"btcusdt@bookTicker\",\"data\":{\"e\":\"bookTicker\",\"u\":11478212236912,\"s\":\"BTCUSDT\",\"ps\":\"BTCUSDT\",\"b\":\"79598.10\",\"B\":\"10.710\",\"a\":\"79598.20\",\"A\":\"3.553\",\"T\":1788563035708,\"E\":1788563035708,\"st\":1}}"}
{"receive_ns":1788563035651714000,"stream":"btcusdt@bookTicker","event_type":"bookTicker","event_time_ms":1788563035717,"raw_json":"{\"stream\":\"btcusdt@bookTicker\",\"data\":{\"e\":\"bookTicker\",\"u\":11478212237232,\"s\":\"BTCUSDT\",\"ps\":\"BTCUSDT\",\"b\":\"79598.10\",\"B\":\"10.718\",\"a\":\"79598.20\",\"A\":\"3.553\",\"T\":1788563035717,\"E\":1788563035717,\"st\":1}}"}
{"receive_ns":1788563035690856000,"stream":"btcusdt@bookTicker","event_type":"bookTicker","event_time_ms":1788563035755,"raw_json":"{\"stream\":\"btcusdt@bookTicker\",\"data\":{\"e\":\"bookTicker\",\"u\":11478212240307,\"s\":\"BTCUSDT\",\"ps\":\"BTCUSDT\",\"b\":\"79598.10\",\"B\":\"10.718\",\"a\":\"79598.20\",\"A\":\"3.554\",\"T\":1788563035755,\"E\":1788563035755,\"st\":1}}"}
{"receive_ns":1788563035702406000,"stream":"btcusdt@bookTicker","event_type":"bookTicker","event_time_ms":1788563035768,"raw_json":"{\"stream\":\"btcusdt@bookTicker\",\"data\":{\"e\":\"bookTicker\",\"u\":11478212240938,\"s\":\"BTCUSDT\",\"ps\":\"BTCUSDT\",\"b\":\"79598.10\",\"B\":\"10.718\",\"a\":\"79598.20\",\"A\":\"3.555\",\"T\":1788563035768,\"E\":1788563035768,\"st\":1}}"}
{"receive_ns":1788563035711312000,"stream":"btcusdt@depth@100ms","event_type":"depthUpdate","event_time_ms":1788563035769,"raw_json":"{\"stream\":\"btcusdt@depth@100ms\",\"data\":{\"e\":\"depthUpdate\",\"E\":1788563035769,\"T\":1788563035768,\"s\":\"BTCUSDT\",\"ps\":\"BTCUSDT\",\"U\":11478212235051,\"u\":11478212240938,\"pu\":11478212234971,\"b\":[[\"1000.00\",\"24.604\"],[\"29198.10\",\"0.147\"],[\"29298.10\",\"1.890\"],[\"29398.10\",\"0.063\"],[\"63679.00\",\"0.000\"],[\"71638.20\",\"0.002\"],[\"71638.30\",\"0.000\"],[\"71670.00\",\"0.003\"],[\"76414.10\",\"0.000\"],[\"78252.90\",\"0.638\"],[\"78802.10\",\"0.002\"],[\"79200.10\",\"0.143\"],[\"79431.40\",\"2.893\"],[\"79440.90\",\"2.436\"],[\"79441.80\",\"0.001\"],[\"79467.30\",\"3.280\"],[\"79470.80\",\"0.729\"],[\"79488.50\",\"0.000\"],[\"79493.00\",\"0.022\"],[\"79496.30\",\"0.000\"],[\"79497.70\",\"0.001\"],[\"79499.30\",\"0.197\"],[\"79500.00\",\"1.789\"],[\"79502.10\",\"0.058\"],[\"79504.40\",\"0.000\"],[\"79506.60\",\"0.000\"],[\"79507.10\",\"4.949\"],[\"79508.70\",\"0.000\"],[\"79511.30\",\"0.040\"],[\"79513.40\",\"0.038\"],[\"79523.90\",\"1.192\"],[\"79529.30\",\"0.001\"],[\"79536.70\",\"0.001\"],[\"79537.10\",\"3.009\"],[\"79539.40\",\"21.497\"],[\"79563.30\",\"0.453\"],[\"79566.90\",\"0.000\"],[\"79569.50\",\"0.002\"],[\"79569.60\",\"0.003\"],[\"79570.10\",\"0.373\"],[\"79572.10\",\"0.518\"],[\"79572.40\",\"0.254\"],[\"79573.20\",\"0.001\"],[\"79574.30\",\"0.630\"],[\"79574.90\",\"0.000\"],[\"79575.10\",\"0.083\"],[\"79575.30\",\"0.001\"],[\"79576.90\",\"4.299\"],[\"79579.70\",\"0.000\"],[\"79581.00\",\"0.000\"],[\"79581.40\",\"0.003\"],[\"79581.60\",\"0.630\"],[\"79581.90\",\"0.000\"],[\"79582.00\",\"0.160\"],[\"79582.20\",\"0.139\"],[\"79583.00\",\"0.071\"],[\"79583.40\",\"0.002\"],[\"79583.50\",\"0.053\"],[\"79583.60\",\"0.320\"],[\"79584.10\",\"0.112\"],[\"79585.50\",\"0.000\"],[\"79585.60\",\"0.069\"],[\"79586.80\",\"0.002\"],[\"79587.60\",\"0.001\"],[\"79587.70\",\"0.010\"],[\"79587.80\",\"0.071\"],[\"79588.30\",\"0.082\"],[\"79588.40\",\"0.100\"],[\"79588.60\",\"0.164\"],[\"79588.90\",\"0.321\"],[\"79589.40\",\"0.002\"],[\"79589.50\",\"0.001\"],[\"79589.60\",\"0.108\"],[\"79589.80\",\"0.252\"],[\"79590.70\",\"0.001\"],[\"79591.40\",\"0.166\"],[\"79591.80\",\"0.134\"],[\"79592.00\",\"0.255\"],[\"79592.30\",\"0.000\"],[\"79593.30\",\"0.002\"],[\"79594.50\",\"0.000\"],[\"79596.40\",\"0.073\"],[\"79598.10\",\"10.718\"]],\"a\":[[\"79598.20\",\"3.555\"],[\"79599.50\",\"0.000\"],[\"79600.10\",\"0.002\"],[\"79600.30\",\"0.005\"],[\"79600.60\",\"0.000\"],[\"79601.10\",\"0.003\"],[\"79602.20\",\"0.254\"],[\"79602.30\",\"0.000\"],[\"79602.50\",\"0.000\"],[\"79603.10\",\"0.000\"],[\"79603.20\",\"0.004\"],[\"79603.30\",\"0.000\"],[\"79603.40\",\"0.002\"],[\"79603.60\",\"0.001\"],[\"79603.70\",\"0.255\"],[\"79603.80\",\"0.000\"],[\"79604.00\",\"2.874\"],[\"79604.20\",\"0.999\"],[\"79604.30\",\"0.003\"],[\"79604.50\",\"0.007\"],[\"79604.60\",\"0.002\"],[\"79604.70\",\"0.000\"],[\"79605.40\",\"0.026\"],[\"79605.50\",\"0.026\"],[\"79605.60\",\"1.038\"],[\"79605.80\",\"0.026\"],[\"79605.90\",\"0.026\"],[\"79606.00\",\"0.718\"],[\"79606.10\",\"0.001\"],[\"79606.20\",\"1.284\"],[\"79606.30\",\"0.366\"],[\"79606.40\",\"0.082\"],[\"79606.50\",\"0.001\"],[\"79606.60\",\"1.369\"],[\"79606.70\",\"0.026\"],[\"79606.80\",\"0.001\"],[\"79606.90\",\"0.003\"],[\"79607.00\",\"0.000\"],[\"79607.20\",\"0.002\"],[\"79607.30\",\"0.000\"],[\"79607.40\",\"0.001\"],[\"79607.60\",\"0.007\"],[\"79607.70\",\"0.000\"],[\"79608.20\",\"0.078\"],[\"79608.30\",\"1.257\"],[\"79609.50\",\"0.017\"],[\"79609.60\",\"0.697\"],[\"79609.70\",\"3.385\"],[\"79609.80\",\"0.001\"],[\"79610.00\",\"0.140\"],[\"79610.20\",\"0.002\"],[\"79610.60\",\"0.001\"],[\"79611.10\",\"0.660\"],[\"79611.70\",\"0.006\"],[\"79611.80\",\"1.788\"],[\"79612.60\",\"0.060\"],[\"79613.00\",\"0.002\"],[\"79613.50\",\"1.245\"],[\"79613.70\",\"0.000\"],[\"79614.20\",\"0.900\"],[\"79614.70\",\"0.453\"],[\"79614.90\",\"0.011\"],[\"79615.30\",\"0.252\"],[\"79615.60\",\"0.063\"],[\"79617.00\",\"0.005\"],[\"79619.50\",\"0.002\"],[\"79620.30\",\"0.020\"],[\"79620.40\",\"0.125\"],[\"79621.40\",\"0.082\"],[\"79622.20\",\"4.524\"],[\"79623.10\",\"0.163\"],[\"79623.40\",\"0.064\"],[\"79623.60\",\"0.755\"],[\"79624.20\",\"0.834\"],[\"79625.40\",\"0.000\"],[\"79626.90\",\"0.056\"],[\"79627.10\",\"0.000\"],[\"79627.90\",\"0.000\"],[\"79628.20\",\"0.202\"],[\"79629.10\",\"0.193\"],[\"79630.10\",\"0.628\"],[\"79632.50\",\"1.420\"],[\"79635.30\",\"0.001\"],[\"79635.90\",\"0.613\"],[\"79636.10\",\"0.127\"],[\"79637.90\",\"0.015\"],[\"79638.00\",\"0.068\"],[\"79641.60\",\"0.003\"],[\"79642.30\",\"0.078\"],[\"79643.50\",\"0.403\"],[\"79644.20\",\"10.003\"],[\"79644.40\",\"0.015\"],[\"79644.90\",\"0.073\"],[\"79646.30\",\"0.191\"],[\"79648.80\",\"0.401\"],[\"79648.90\",\"0.577\"],[\"79726.80\",\"0.394\"],[\"79736.40\",\"0.011\"],[\"79737.00\",\"0.040\"],[\"79764.20\",\"0.922\"],[\"79766.20\",\"2.936\"],[\"79772.60\",\"0.000\"],[\"79790.50\",\"0.095\"],[\"79821.00\",\"0.088\"],[\"79958.40\",\"0.020\"],[\"79996.20\",\"1.616\"],[\"80394.20\",\"2.981\"],[\"80687.40\",\"11.761\"],[\"81826.90\",\"0.244\"]],\"st\":1}}"}
{"receive_ns":1788563035770109000,"stream":"btcusdt@bookTicker","event_type":"bookTicker","event_time_ms":1788563035834,"raw_json":"{\"stream\":\"btcusdt@bookTicker\",\"data\":{\"e\":\"bookTicker\",\"u\":11478212244050,\"s\":\"BTCUSDT\",\"ps\":\"BTCUSDT\",\"b\":\"79598.10\",\"B\":\"10.718\",\"a\":\"79598.20\",\"A\":\"3.556\",\"T\":1788563035834,\"E\":1788563035834,\"st\":1}}"}
{"receive_ns":1788563035783954000,"stream":"btcusdt@bookTicker","event_type":"bookTicker","event_time_ms":1788563035848,"raw_json":"{\"stream\":\"btcusdt@bookTicker\",\"data\":{\"e\":\"bookTicker\",\"u\":11478212244680,\"s\":\"BTCUSDT\",\"ps\":\"BTCUSDT\",\"b\":\"79598.10\",\"B\":\"10.718\",\"a\":\"79598.20\",\"A\":\"3.567\",\"T\":1788563035848,\"E\":1788563035848,\"st\":1}}"}
{"receive_ns":1788563035785077000,"stream":"btcusdt@bookTicker","event_type":"bookTicker","event_time_ms":1788563035849,"raw_json":"{\"stream\":\"btcusdt@bookTicker\",\"data\":{\"e\":\"bookTicker\",\"u\":11478212244721,\"s\":\"BTCUSDT\",\"ps\":\"BTCUSDT\",\"b\":\"79598.10\",\"B\":\"10.718\",\"a\":\"79598.20\",\"A\":\"3.568\",\"T\":1788563035849,\"E\":1788563035849,\"st\":1}}"}
{"receive_ns":1788563035805154000,"stream":"btcusdt@depth@100ms","event_type":"depthUpdate","event_time_ms":1788563035871,"raw_json":"{\"stream\":\"btcusdt@depth@100ms\",\"data\":{\"e\":\"depthUpdate\",\"E\":1788563035871,\"T\":1788563035869,\"s\":\"BTCUSDT\",\"ps\":\"BTCUSDT\",\"U\":11478212241011,\"u\":11478212245297,\"pu\":11478212240938,\"b\":[[\"1000.00\",\"24.604\"],[\"29198.10\",\"0.266\"],[\"29298.10\",\"1.834\"],[\"29398.10\",\"0.000\"],[\"71638.20\",\"0.002\"],[\"71670.00\",\"0.000\"],[\"78072.80\",\"0.449\"],[\"78782.80\",\"0.003\"],[\"78802.10\",\"0.002\"],[\"79226.00\",\"0.256\"],[\"79439.80\",\"0.202\"],[\"79440.90\",\"2.938\"],[\"79522.00\",\"0.008\"],[\"79537.60\",\"1.339\"],[\"79539.40\",\"21.498\"],[\"79541.70\",\"3.910\"],[\"79554.30\",\"0.070\"],[\"79582.00\",\"0.090\"],[\"79582.40\",\"0.017\"],[\"79582.60\",\"0.000\"],[\"79587.80\",\"0.141\"],[\"79588.10\",\"0.351\"],[\"79588.20\",\"0.100\"],[\"79588.30\",\"0.182\"],[\"79588.50\",\"0.120\"],[\"79588.60\",\"0.264\"],[\"79592.20\",\"0.000\"]],\"a\":[[\"79598.20\",\"3.568\"],[\"79601.50\",\"0.003\"],[\"79602.10\",\"0.253\"],[\"79602.20\",\"0.254\"],[\"79603.10\",\"0.200\"],[\"79603.30\",\"0.026\"],[\"79603.40\",\"0.028\"],[\"79603.70\",\"0.281\"],[\"79604.20\",\"1.025\"],[\"79604.90\",\"0.460\"],[\"79605.00\",\"0.055\"],[\"79605.20\",\"0.103\"],[\"79605.30\",\"0.026\"],[\"79605.60\",\"1.012\"],[\"79605.80\",\"0.000\"],[\"79605.90\",\"0.000\"],[\"79606.00\",\"0.692\"],[\"79606.20\",\"1.258\"],[\"79606.30\",\"0.340\"],[\"79606.60\",\"1.343\"],[\"79606.70\",\"0.000\"],[\"79608.30\",\"0.001\"],[\"79608.50\",\"1.861\"],[\"79609.50\",\"1.273\"],[\"79616.00\",\"0.062\"],[\"79656.60\",\"1.383\"],[\"79958.40\",\"0.439\"],[\"79996.20\",\"1.616\"],[\"80394.20\",\"2.981\"],[\"80553.40\",\"5.448\"],[\"80712.60\",\"3.714\"]],\"st\":1}}"}
{"receive_ns":1788563035815306000,"stream":"btcusdt@bookTicker","event_type":"bookTicker","event_time_ms":1788563035880,"raw_json":"{\"stream\":\"btcusdt@bookTicker\",\"data\":{\"e\":\"bookTicker\",\"u\":11478212245783,\"s\":\"BTCUSDT\",\"ps\":\"BTCUSDT\",\"b\":\"79598.10\",\"B\":\"10.697\",\"a\":\"79598.20\",\"A\":\"3.568\",\"T\":1788563035880,\"E\":1788563035880,\"st\":1}}"}
{"receive_ns":1788563035821087000,"stream":"btcusdt@bookTicker","event_type":"bookTicker","event_time_ms":1788563035886,"raw_json":"{\"stream\":\"btcusdt@bookTicker\",\"data\":{\"e\":\"bookTicker\",\"u\":11478212246055,\"s\":\"BTCUSDT\",\"ps\":\"BTCUSDT\",\"b\":\"79598.10\",\"B\":\"10.717\",\"a\":\"79598.20\",\"A\":\"3.568\",\"T\":1788563035886,\"E\":1788563035886,\"st\":1}}"}
{"receive_ns":1788563035908023000,"stream":"btcusdt@depth@100ms","event_type":"depthUpdate","event_time_ms":1788563035973,"raw_json":"{\"stream\":\"btcusdt@depth@100ms\",\"data\":{\"e\":\"depthUpdate\",\"E\":1788563035973,\"T\":1788563035971,\"s\":\"BTCUSDT\",\"ps\":\"BTCUSDT\",\"U\":11478212245436,\"u\":11478212248960,\"pu\":11478212245297,\"b\":[[\"29198.10\",\"0.441\"],[\"29298.10\",\"1.659\"],[\"71638.20\",\"0.002\"],[\"75618.10\",\"0.023\"],[\"76414.10\",\"0.002\"],[\"78238.10\",\"0.000\"],[\"78284.70\",\"0.893\"],[\"78669.40\",\"0.002\"],[\"78802.10\",\"0.002\"],[\"79200.10\",\"0.143\"],[\"79440.90\",\"2.938\"],[\"79444.80\",\"0.270\"],[\"79447.10\",\"0.046\"],[\"79542.80\",\"0.052\"],[\"79554.30\",\"0.000\"],[\"79568.30\",\"0.204\"],[\"79570.10\",\"0.000\"],[\"79571.90\",\"0.000\"],[\"79573.10\",\"2.437\"],[\"79582.00\",\"0.020\"],[\"79582.30\",\"0.076\"],[\"79582.50\",\"0.095\"],[\"79582.70\",\"0.002\"],[\"79582.80\",\"0.003\"],[\"79582.90\",\"0.428\"],[\"79583.10\",\"0.102\"],[\"79585.10\",\"0.000\"],[\"79588.00\",\"0.206\"],[\"79588.30\",\"0.282\"],[\"79588.70\",\"0.100\"],[\"79588.80\",\"0.009\"],[\"79589.30\",\"0.033\"],[\"79589.60\",\"0.136\"],[\"79590.10\",\"0.033\"],[\"79590.90\",\"0.032\"],[\"79598.10\",\"10.717\"]],\"a\":[[\"79602.20\",\"0.254\"],[\"79603.20\",\"0.030\"],[\"79605.50\",\"0.000\"],[\"79611.80\",\"1.416\"],[\"79613.00\",\"0.374\"],[\"79632.50\",\"1.474\"],[\"79633.40\",\"0.075\"],[\"79665.20\",\"0.001\"],[\"79680.60\",\"0.000\"],[\"79996.20\",\"1.615\"],[\"80394.20\",\"2.981\"]],\"st\":1}}"}
{"receive_ns":1788563035917937000,"stream":"btcusdt@bookTicker","event_type":"bookTicker","event_time_ms":1788563035982,"raw_json":"{\"stream\":\"btcusdt@bookTicker\",\"data\":{\"e\":\"bookTicker\",\"u\":11478212249282,\"s\":\"BTCUSDT\",\"ps\":\"BTCUSDT\",\"b\":\"79598.10\",\"B\":\"10.717\",\"a\":\"79598.20\",\"A\":\"3.567\",\"T\":1788563035981,\"E\":1788563035982,\"st\":1}}"}
{"receive_ns":1788563035923757000,"stream":"btcusdt@bookTicker","event_type":"bookTicker","event_time_ms":1788563035989,"raw_json":"{\"stream\":\"btcusdt@bookTicker\",\"data\":{\"e\":\"bookTicker\",\"u\":11478212249555,\"s\":\"BTCUSDT\",\"ps\":\"BTCUSDT\",\"b\":\"79598.10\",\"B\":\"10.717\",\"a\":\"79598.20\",\"A\":\"3.569\",\"T\":1788563035989,\"E\":1788563035989,\"st\":1}}"}
{"receive_ns":1788563035975835000,"stream":"btcusdt@bookTicker","event_type":"bookTicker","event_time_ms":1788563036042,"raw_json":"{\"stream\":\"btcusdt@bookTicker\",\"data\":{\"e\":\"bookTicker\",\"u\":11478212251467,\"s\":\"BTCUSDT\",\"ps\":\"BTCUSDT\",\"b\":\"79598.10\",\"B\":\"10.717\",\"a\":\"79598.20\",\"A\":\"3.568\",\"T\":1788563036042,\"E\":1788563036042,\"st\":1}}"}
{"receive_ns":1788563036010181000,"stream":"btcusdt@depth@100ms","event_type":"depthUpdate","event_time_ms":1788563036075,"raw_json":"{\"stream\":\"btcusdt@depth@100ms\",\"data\":{\"e\":\"depthUpdate\",\"E\":1788563036075,\"T\":1788563036073,\"s\":\"BTCUSDT\",\"ps\":\"BTCUSDT\",\"U\":11478212249007,\"u\":11478212252443,\"pu\":11478212248960,\"b\":[[\"1000.00\",\"24.604\"],[\"29198.10\",\"0.623\"],[\"29298.10\",\"1.477\"],[\"63679.00\",\"0.000\"],[\"71638.20\",\"0.002\"],[\"76414.10\",\"0.000\"],[\"78006.20\",\"0.021\"],[\"78455.80\",\"0.001\"],[\"78464.50\",\"6.262\"],[\"78623.70\",\"6.920\"],[\"78802.10\",\"0.002\"],[\"79200.10\",\"0.154\"],[\"79226.00\",\"0.256\"],[\"79400.00\",\"4.755\"],[\"79401.10\",\"0.100\"],[\"79431.40\",\"0.000\"],[\"79434.40\",\"2.899\"],[\"79439.80\",\"0.001\"],[\"79440.90\",\"2.838\"],[\"79470.80\",\"0.125\"],[\"79473.80\",\"0.653\"],[\"79521.70\",\"0.045\"],[\"79578.80\",\"0.289\"],[\"79579.10\",\"0.066\"],[\"79582.10\",\"0.010\"],[\"79582.40\",\"0.016\"],[\"79583.10\",\"0.002\"],[\"79583.50\",\"0.021\"],[\"79583.80\",\"0.000\"],[\"79583.90\",\"0.001\"],[\"79584.30\",\"0.002\"],[\"79587.90\",\"0.073\"],[\"79588.90\",\"0.421\"],[\"79590.60\",\"0.460\"],[\"79592.20\",\"0.000\"]],\"a\":[[\"79598.20\",\"3.568\"],[\"79602.10\",\"0.253\"],[\"79602.20\",\"0.344\"],[\"79603.00\",\"0.026\"],[\"79603.10\",\"0.200\"],[\"79605.40\",\"0.000\"],[\"79606.00\",\"0.001\"],[\"79610.60\",\"0.005\"],[\"79611.10\",\"0.656\"],[\"79721.90\",\"0.398\"],[\"79726.80\",\"0.001\"],[\"79737.90\",\"0.015\"],[\"79738.10\",\"0.000\"],[\"79738.40\",\"0.002\"],[\"79738.60\",\"0.705\"],[\"79761.30\",\"2.407\"],[\"79764.20\",\"0.550\"],[\"79766.20\",\"0.000\"],[\"79958.40\",\"0.439\"],[\"79996.20\",\"1.615\"],[\"80394.20\",\"2.981\"],[\"80490.60\",\"0.000\"],[\"80731.60\",\"0.000\"],[\"80734.20\",\"0.000\"],[\"81179.10\",\"0.000\"]],\"st\":1}}"}
{"receive_ns":1788563036049200000,"stream":"btcusdt@bookTicker","event_type":"bookTicker","event_time_ms":1788563036116,"raw_json":"{\"stream\":\"btcusdt@bookTicker\",\"data\":{\"e\":\"bookTicker\",\"u\":11478212254305,\"s\":\"BTCUSDT\",\"ps\":\"BTCUSDT\",\"b\":\"79598.10\",\"B\":\"10.717\",\"a\":\"79598.20\",\"A\":\"3.566\",\"T\":1788563036116,\"E\":1788563036116,\"st\":1}}"}
{"receive_ns":1788563036056833000,"stream":"btcusdt@bookTicker","event_type":"bookTicker","event_time_ms":1788563036123,"raw_json":"{\"stream\":\"btcusdt@bookTicker\",\"data\":{\"e\":\"bookTicker\",\"u\":11478212254700,\"s\":\"BTCUSDT\",\"ps\":\"BTCUSDT\",\"b\":\"79598.10\",\"B\":\"10.717\",\"a\":\"79598.20\",\"A\":\"3.569\",\"T\":1788563036123,\"E\":1788563036123,\"st\":1}}"}
{"receive_ns":1788563036111653000,"stream":"btcusdt@depth@100ms","event_type":"depthUpdate","event_time_ms":1788563036177,"raw_json":"{\"stream\":\"btcusdt@depth@100ms\",\"data\":{\"e\":\"depthUpdate\",\"E\":1788563036177,\"T\":1788563036173,\"s\":\"BTCUSDT\",\"ps\":\"BTCUSDT\",\"U\":11478212252486,\"u\":11478212257126,\"pu\":11478212252443,\"b\":[[\"1000.00\",\"24.604\"],[\"29198.10\",\"0.798\"],[\"29298.10\",\"1.302\"],[\"63679.00\",\"0.000\"],[\"71638.20\",\"0.002\"],[\"76414.10\",\"0.002\"],[\"78376.10\",\"0.000\"],[\"78380.60\",\"0.016\"],[\"78460.30\",\"0.007\"],[\"78682.70\",\"0.864\"],[\"78802.10\",\"0.002\"],[\"79541.60\",\"0.349\"],[\"79560.60\",\"0.077\"],[\"79582.30\",\"0.006\"],[\"79583.00\",\"0.001\"],[\"79584.90\",\"0.273\"],[\"79588.10\",\"0.421\"],[\"79588.80\",\"0.079\"]],\"a\":[[\"79598.20\",\"3.569\"],[\"79600.10\",\"0.001\"],[\"79602.20\",\"0.370\"],[\"79602.30\",\"0.026\"],[\"79602.90\",\"0.027\"],[\"79605.00\",\"0.029\"],[\"79605.20\",\"0.077\"],[\"79605.30\",\"0.000\"],[\"79610.60\",\"0.001\"],[\"79610.90\",\"0.744\"],[\"79614.90\",\"0.051\"],[\"79615.60\",\"0.023\"],[\"79633.00\",\"0.202\"],[\"79653.40\",\"0.083\"],[\"79675.30\",\"0.005\"],[\"79684.80\",\"0.004\"],[\"79698.90\",\"0.003\"],[\"79700.80\",\"0.044\"],[\"79705.20\",\"0.031\"],[\"79717.90\",\"0.033\"],[\"79996.20\",\"1.740\"],[\"80260.40\",\"0.001\"],[\"80394.20\",\"2.981\"],[\"80672.80\",\"0.494\"],[\"80692.80\",\"11.756\"],[\"80694.10\",\"0.000\"],[\"80811.20\",\"0.000\"]],\"st\":1}}"}
{"receive_ns":1788563036206115000,"stream":"btcusdt@bookTicker","event_type":"bookTicker","event_time_ms":1788563036271,"raw_json":"{\"stream\":\"btcusdt@bookTicker\",\"data\":{\"e\":\"bookTicker\",\"u\":11478212261434,\"s\":\"BTCUSDT\",\"ps\":\"BTCUSDT\",\"b\":\"79598.10\",\"B\":\"10.717\",\"a\":\"79598.20\",\"A\":\"3.570\",\"T\":1788563036271,\"E\":1788563036271,\"st\":1}}"}
{"receive_ns":1788563036214262000,"stream":"btcusdt@depth@100ms","event_type":"depthUpdate","event_time_ms":1788563036279,"raw_json":"{\"stream\":\"btcusdt@depth@100ms\",\"data\":{\"e\":\"depthUpdate\",\"E\":1788563036279,\"T\":1788563036278,\"s\":\"BTCUSDT\",\"ps\":\"BTCUSDT\",\"U\":11478212257247,\"u\":11478212262025,\"pu\":11478212257126,\"b\":[[\"29198.10\",\"0.980\"],[\"29298.10\",\"1.120\"],[\"71638.20\",\"0.002\"],[\"76414.10\",\"0.000\"],[\"77701.50\",\"0.023\"],[\"78358.60\",\"0.478\"],[\"78545.30\",\"3.435\"],[\"78802.10\",\"0.002\"],[\"79200.10\",\"0.154\"],[\"79226.00\",\"0.024\"],[\"79400.00\",\"4.554\"],[\"79401.10\",\"0.502\"],[\"79440.90\",\"1.005\"],[\"79485.30\",\"0.136\"],[\"79493.00\",\"0.043\"],[\"79538.60\",\"0.003\"],[\"79539.50\",\"4.647\"],[\"79545.90\",\"0.000\"],[\"79559.90\",\"2.672\"],[\"79560.00\",\"0.105\"],[\"79560.10\",\"0.072\"],[\"79560.30\",\"0.173\"],[\"79563.30\",\"0.001\"],[\"79564.00\",\"0.139\"],[\"79565.40\",\"10.884\"],[\"79565.50\",\"0.792\"],[\"79565.90\",\"0.484\"],[\"79566.90\",\"0.032\"],[\"79574.10\",\"0.003\"],[\"79575.80\",\"0.856\"],[\"79577.00\",\"0.001\"],[\"79582.40\",\"0.001\"],[\"79583.00\",\"0.019\"],[\"79584.80\",\"0.066\"],[\"79585.30\",\"0.077\"],[\"79585.60\",\"0.007\"],[\"79592.20\",\"0.000\"],[\"79593.30\",\"0.000\"]],\"a\":[[\"79598.20\",\"3.570\"],[\"79600.70\",\"0.017\"],[\"79601.30\",\"0.018\"],[\"79602.00\",\"0.103\"],[\"79602.10\",\"0.002\"],[\"79602.20\",\"0.280\"],[\"79602.70\",\"0.003\"],[\"79603.10\",\"0.000\"],[\"79604.90\",\"0.434\"],[\"79608.10\",\"0.681\"],[\"79614.70\",\"0.001\"],[\"79615.70\",\"0.454\"],[\"79638.00\",\"0.004\"],[\"79644.80\",\"0.471\"],[\"79674.40\",\"1.467\"],[\"79689.10\",\"0.076\"],[\"79738.10\",\"0.125\"],[\"79738.20\",\"0.801\"],[\"79738.30\",\"0.030\"],[\"79738.60\",\"0.580\"],[\"79804.00\",\"1.821\"],[\"79958.40\",\"0.020\"],[\"79976.30\",\"0.250\"],[\"79996.20\",\"0.776\"],[\"80394.20\",\"2.981\"],[\"80574.70\",\"0.000\"],[\"80691.90\",\"3.415\"],[\"80736.10\",\"0.007\"],[\"80752.40\",\"1.732\"],[\"80815.70\",\"0.014\"],[\"81190.10\",\"0.029\"]],\"st\":1}}"}
{"receive_ns":1788563036257111000,"stream":"btcusdt@bookTicker","event_type":"bookTicker","event_time_ms":1788563036324,"raw_json":"{\"stream\":\"btcusdt@bookTicker\",\"data\":{\"e\":\"bookTicker\",\"u\":11478212264234,\"s\":\"BTCUSDT\",\"ps\":\"BTCUSDT\",\"b\":\"79598.10\",\"B\":\"10.717\",\"a\":\"79598.20\",\"A\":\"3.568\",\"T\":1788563036323,\"E\":1788563036324,\"st\":1}}"}
{"receive_ns":1788563036261370000,"stream":"btcusdt@bookTicker","event_type":"bookTicker","event_time_ms":1788563036326,"raw_json":"{\"stream\":\"btcusdt@bookTicker\",\"data\":{\"e\":\"bookTicker\",\"u\":11478212264391,\"s\":\"BTCUSDT\",\"ps\":\"BTCUSDT\",\"b\":\"79598.10\",\"B\":\"10.715\",\"a\":\"79598.20\",\"A\":\"3.568\",\"T\":1788563036326,\"E\":1788563036326,\"st\":1}}"}
{"receive_ns":1788563036262130000,"stream":"btcusdt@trade","event_type":"trade","event_time_ms":1788563036326,"raw_json":"{\"stream\":\"btcusdt@trade\",\"data\":{\"e\":\"trade\",\"E\":1788563036326,\"T\":1788563036326,\"s\":\"BTCUSDT\",\"t\":8054081701,\"p\":\"79598.10\",\"q\":\"0.002\",\"X\":\"MARKET\",\"m\":true,\"st\":1}}"}
{"receive_ns":1788563036262902000,"stream":"btcusdt@bookTicker","event_type":"bookTicker","event_time_ms":1788563036328,"raw_json":"{\"stream\":\"btcusdt@bookTicker\",\"data\":{\"e\":\"bookTicker\",\"u\":11478212264457,\"s\":\"BTCUSDT\",\"ps\":\"BTCUSDT\",\"b\":\"79598.10\",\"B\":\"10.707\",\"a\":\"79598.20\",\"A\":\"3.568\",\"T\":1788563036328,\"E\":1788563036328,\"st\":1}}"}
{"receive_ns":1788563036264133000,"stream":"btcusdt@bookTicker","event_type":"bookTicker","event_time_ms":1788563036328,"raw_json":"{\"stream\":\"btcusdt@bookTicker\",\"data\":{\"e\":\"bookTicker\",\"u\":11478212264509,\"s\":\"BTCUSDT\",\"ps\":\"BTCUSDT\",\"b\":\"79598.10\",\"B\":\"10.715\",\"a\":\"79598.20\",\"A\":\"3.568\",\"T\":1788563036328,\"E\":1788563036328,\"st\":1}}"}
{"receive_ns":1788563036264980000,"stream":"btcusdt@bookTicker","event_type":"bookTicker","event_time_ms":1788563036329,"raw_json":"{\"stream\":\"btcusdt@bookTicker\",\"data\":{\"e\":\"bookTicker\",\"u\":11478212264548,\"s\":\"BTCUSDT\",\"ps\":\"BTCUSDT\",\"b\":\"79598.10\",\"B\":\"10.707\",\"a\":\"79598.20\",\"A\":\"3.568\",\"T\":1788563036329,\"E\":1788563036329,\"st\":1}}"}
{"receive_ns":1788563036300286000,"stream":"btcusdt@bookTicker","event_type":"bookTicker","event_time_ms":1788563036365,"raw_json":"{\"stream\":\"btcusdt@bookTicker\",\"data\":{\"e\":\"bookTicker\",\"u\":11478212266030,\"s\":\"BTCUSDT\",\"ps\":\"BTCUSDT\",\"b\":\"79598.10\",\"B\":\"10.701\",\"a\":\"79598.20\",\"A\":\"3.568\",\"T\":1788563036365,\"E\":1788563036365,\"st\":1}}"}
{"receive_ns":1788563036303467000,"stream":"btcusdt@bookTicker","event_type":"bookTicker","event_time_ms":1788563036368,"raw_json":"{\"stream\":\"btcusdt@bookTicker\",\"data\":{\"e\":\"bookTicker\",\"u\":11478212266138,\"s\":\"BTCUSDT\",\"ps\":\"BTCUSDT\",\"b\":\"79598.10\",\"B\":\"10.711\",\"a\":\"79598.20\",\"A\":\"3.568\",\"T\":1788563036368,\"E\":1788563036368,\"st\":1}}"}
{"receive_ns":1788563036315744000,"stream":"btcusdt@depth@100ms","event_type":"depthUpdate","event_time_ms":1788563036381,"raw_json":"{\"stream\":\"btcusdt@depth@100ms\",\"data\":{\"e\":\"depthUpdate\",\"E\":1788563036381,\"T\":1788563036379,\"s\":\"BTCUSDT\",\"ps\":\"BTCUSDT\",\"U\":11478212262055,\"u\":11478212266672,\"pu\":11478212262025,\"b\":[[\"1000.00\",\"24.604\"],[\"29198.10\",\"1.155\"],[\"29298.10\",\"0.945\"],[\"34000.00\",\"0.975\"],[\"63679.00\",\"0.000\"],[\"71638.20\",\"0.002\"],[\"78483.70\",\"5.727\"],[\"78493.90\",\"4.287\"],[\"78642.90\",\"3.810\"],[\"78802.10\",\"0.002\"],[\"79200.10\",\"0.144\"],[\"79226.00\",\"0.256\"],[\"79400.00\",\"4.755\"],[\"79401.10\",\"0.602\"],[\"79440.90\",\"2.336\"],[\"79500.00\",\"1.791\"],[\"79539.40\",\"21.499\"],[\"79559.60\",\"0.078\"],[\"79564.10\",\"0.108\"],[\"79566.90\",\"0.064\"],[\"79598.10\",\"10.711\"]],\"a\":[[\"79598.20\",\"3.568\"],[\"79601.90\",\"0.026\"],[\"79602.10\",\"0.253\"],[\"79602.20\",\"0.370\"],[\"79603.10\",\"0.200\"],[\"79604.20\",\"0.999\"],[\"79639.30\",\"0.029\"],[\"79641.60\",\"0.002\"],[\"79654.00\",\"0.002\"],[\"79674.30\",\"0.003\"],[\"79674.40\",\"1.464\"],[\"79737.90\",\"0.015\"],[\"79738.10\",\"0.000\"],[\"79738.20\",\"0.801\"],[\"79738.50\",\"0.001\"],[\"79738.60\",\"0.580\"],[\"79996.20\",\"1.740\"],[\"80394.20\",\"2.981\"],[\"80712.60\",\"5.569\"],[\"81186.10\",\"0.015\"]],\"st\":1}}"}
{"receive_ns":1788563036383774000,"stream":"btcusdt@bookTicker","event_type":"bookTicker","event_time_ms":1788563036450,"raw_json":"{\"stream\":\"btcusdt@bookTicker\",\"data\":{\"e\":\"bookTicker\",\"u\":11478212269782,\"s\":\"BTCUSDT\",\"ps\":\"BTCUSDT\",\"b\":\"79598.10\",\"B\":\"10.677\",\"a\":\"79598.20\",\"A\":\"3.568\",\"T\":1788563036450,\"E\":1788563036450,\"st\":1}}"}
{"receive_ns":1788563036396804000,"stream":"btcusdt@bookTicker","event_type":"bookTicker","event_time_ms":1788563036453,"raw_json":"{\"stream\":\"btcusdt@bookTicker\",\"data\":{\"e\":\"bookTicker\",\"u\":11478212269949,\"s\":\"BTCUSDT\",\"ps\":\"BTCUSDT\",\"b\":\"79598.10\",\"B\":\"10.714\",\"a\":\"79598.20\",\"A\":\"3.568\",\"T\":1788563036453,\"E\":1788563036453,\"st\":1}}"}
{"receive_ns":1788563036417510000,"stream":"btcusdt@depth@100ms","event_type":"depthUpdate","event_time_ms":1788563036483,"raw_json":"{\"stream\":\"btcusdt@depth@100ms\",\"data\":{\"e\":\"depthUpdate\",\"E\":1788563036483,\"T\":1788563036482,\"s\":\"BTCUSDT\",\"ps\":\"BTCUSDT\",\"U\":11478212266745,\"u\":11478212271170,\"pu\":11478212266672,\"b\":[[\"1000.00\",\"24.604\"],[\"29198.10\",\"1.337\"],[\"29298.10\",\"0.763\"],[\"71638.20\",\"0.002\"],[\"76414.10\",\"0.002\"],[\"78244.90\",\"1.021\"],[\"78802.10\",\"0.002\"],[\"78961.30\",\"1.012\"],[\"79200.10\",\"0.003\"],[\"79440.90\",\"1.331\"],[\"79459.40\",\"0.000\"],[\"79475.70\",\"0.002\"],[\"79484.80\",\"0.000\"],[\"79494.80\",\"0.001\"],[\"79503.40\",\"0.000\"],[\"79506.80\",\"0.000\"],[\"79519.70\",\"0.018\"],[\"79559.70\",\"0.086\"],[\"79565.20\",\"0.102\"],[\"79574.40\",\"0.050\"],[\"79598.10\",\"10.714\"]],\"a\":[[\"79601.70\",\"0.027\"],[\"79602.20\",\"0.119\"],[\"79603.70\",\"0.255\"],[\"79614.30\",\"0.361\"],[\"79706.10\",\"0.000\"],[\"79717.60\",\"0.251\"],[\"79738.40\",\"0.002\"],[\"79738.60\",\"0.580\"],[\"79996.20\",\"1.214\"],[\"80394.20\",\"2.983\"]],\"st\":1}}"}
{"receive_ns":1788563036424836000,"stream":"btcusdt@bookTicker","event_type":"bookTicker","event_time_ms":1788563036489,"raw_json":"{\"stream\":\"btcusdt@bookTicker\",\"data\":{\"e\":\"bookTicker\",\"u\":11478212271637,\"s\":\"BTCUSDT\",\"ps\":\"BTCUSDT\",\"b\":\"79598.10\",\"B\":\"10.714\",\"a\":\"79598.20\",\"A\":\"3.567\",\"T\":1788563036489,\"E\":1788563036489,\"st\":1}}"}
{"receive_ns":1788563036433516000,"stream":"btcusdt@bookTicker","event_type":"bookTicker","event_time_ms":1788563036498,"raw_json":"{\"stream\":\"btcusdt@bookTicker\",\"data\":{\"e\":\"bookTicker\",\"u\":11478212272049,\"s\":\"BTCUSDT\",\"ps\":\"BTCUSDT\",\"b\":\"79598.10\",\"B\":\"10.714\",\"a\":\"79598.20\",\"A\":\"3.564\",\"T\":1788563036498,\"E\":1788563036498,\"st\":1}}"}
{"receive_ns":1788563036436868000,"stream":"btcusdt@bookTicker","event_type":"bookTicker","event_time_ms":1788563036502,"raw_json":"{\"stream\":\"btcusdt@bookTicker\",\"data\":{\"e\":\"bookTicker\",\"u\":11478212272254,\"s\":\"BTCUSDT\",\"ps\":\"BTCUSDT\",\"b\":\"79598.10\",\"B\":\"10.715\",\"a\":\"79598.20\",\"A\":\"3.564\",\"T\":1788563036502,\"E\":1788563036502,\"st\":1}}"}
{"receive_ns":1788563036444315000,"stream":"btcusdt@bookTicker","event_type":"bookTicker","event_time_ms":1788563036509,"raw_json":"{\"stream\":\"btcusdt@bookTicker\",\"data\":{\"e\":\"bookTicker\",\"u\":11478212272482,\"s\":\"BTCUSDT\",\"ps\":\"BTCUSDT\",\"b\":\"79598.10\",\"B\":\"10.715\",\"a\":\"79598.20\",\"A\":\"3.565\",\"T\":1788563036509,\"E\":1788563036509,\"st\":1}}"}
{"receive_ns":1788563036519644000,"stream":"btcusdt@depth@100ms","event_type":"depthUpdate","event_time_ms":1788563036585,"raw_json":"{\"stream\":\"btcusdt@depth@100ms\",\"data\":{\"e\":\"depthUpdate\",\"E\":1788563036585,\"T\":1788563036582,\"s\":\"BTCUSDT\",\"ps\":\"BTCUSDT\",\"U\":11478212271209,\"u\":11478212275592,\"pu\":11478212271170,\"b\":[[\"29198.10\",\"1.512\"],[\"29298.10\",\"0.588\"],[\"63678.00\",\"0.002\"],[\"63678.50\",\"0.000\"],[\"71638.20\",\"0.002\"],[\"76414.10\",\"0.000\"],[\"77981.80\",\"0.013\"],[\"78070.20\",\"0.000\"],[\"78158.70\",\"0.004\"],[\"78247.10\",\"2.552\"],[\"78335.50\",\"0.015\"],[\"78423.90\",\"0.000\"],[\"78512.30\",\"0.000\"],[\"78600.70\",\"0.019\"],[\"78642.90\",\"4.102\"],[\"78689.20\",\"0.000\"],[\"78777.60\",\"0.000\"],[\"78784.10\",\"0.888\"],[\"78802.10\",\"0.002\"],[\"79200.10\",\"0.144\"],[\"79226.00\",\"0.256\"],[\"79400.00\",\"4.755\"],[\"79401.10\",\"0.100\"],[\"79440.90\",\"2.838\"],[\"79473.80\",\"0.622\"],[\"79485.80\",\"0.652\"],[\"79501.10\",\"0.006\"],[\"79533.80\",\"0.001\"],[\"79542.40\",\"0.006\"],[\"79575.20\",\"0.737\"],[\"79587.10\",\"0.076\"],[\"79598.10\",\"10.715\"]],\"a\":[[\"79598.20\",\"3.565\"],[\"79602.10\",\"0.253\"],[\"79602.20\",\"0.370\"],[\"79603.10\",\"0.200\"],[\"79608.10\",\"0.262\"],[\"79721.60\",\"0.392\"],[\"79721.90\",\"0.000\"],[\"79958.40\",\"0.439\"],[\"79996.20\",\"1.740\"],[\"80369.00\",\"0.079\"],[\"80394.20\",\"2.981\"],[\"80457.40\",\"0.000\"],[\"80545.90\",\"0.001\"],[\"80634.30\",\"0.000\"],[\"80634.80\",\"2.961\"],[\"80692.80\",\"9.900\"],[\"80722.70\",\"0.005\"],[\"80732.80\",\"1.114\"],[\"80747.30\",\"0.000\"],[\"80811.10\",\"0.000\"],[\"80812.40\",\"2.224\"],[\"80899.50\",\"0.000\"],[\"80987.90\",\"0.000\"],[\"81076.40\",\"0.000\"],[\"81164.80\",\"0.000\"],[\"81186.10\",\"0.012\"],[\"81826.90\",\"0.488\"],[\"87558.10\",\"0.000\"]],\"st\":1}}"}
{"receive_ns":1788563036628467000,"stream":"btcusdt@depth@100ms","event_type":"depthUpdate","event_time_ms":1788563036687,"raw_json":"{\"stream\":\"btcusdt@depth@100ms\",\"data\":{\"e\":\"depthUpdate\",\"E\":1788563036687,\"T\":1788563036686,\"s\":\"BTCUSDT\",\"ps\":\"BTCUSDT\",\"U\":11478212275783,\"u\":11478212280002,\"pu\":11478212275592,\"b\":[[\"1000.00\",\"24.604\"],[\"29198.10\",\"1.694\"],[\"29298.10\",\"0.406\"],[\"63678.00\",\"0.000\"],[\"63679.00\",\"0.000\"],[\"71638.20\",\"0.002\"],[\"76414.10\",\"0.002\"],[\"77608.10\",\"0.554\"],[\"78386.50\",\"0.000\"],[\"78464.70\",\"5.348\"],[\"78491.70\",\"0.925\"],[\"78623.90\",\"4.634\"],[\"78784.40\",\"0.000\"],[\"78802.10\",\"0.002\"],[\"78982.00\",\"0.632\"],[\"79200.10\",\"0.153\"],[\"79514.80\",\"1.378\"]],\"a\":[[\"79601.50\",\"0.029\"],[\"79603.40\",\"0.002\"],[\"79738.50\",\"0.001\"],[\"79738.80\",\"0.125\"],[\"79738.90\",\"0.000\"],[\"79996.20\",\"1.865\"],[\"80394.20\",\"2.981\"],[\"80493.80\",\"0.290\"],[\"80533.80\",\"7.439\"],[\"80693.00\",\"10.027\"],[\"80728.50\",\"0.159\"],[\"80732.60\",\"3.774\"],[\"80752.40\",\"2.598\"],[\"80832.00\",\"0.867\"],[\"80891.70\",\"0.000\"],[\"80951.40\",\"0.549\"]],\"st\":1}}"}
{"receive_ns":1788563036650289000,"stream":"btcusdt@bookTicker","event_type":"bookTicker","event_time_ms":1788563036714,"raw_json":"{\"stream\":\"btcusdt@bookTicker\",\"data\":{\"e\":\"bookTicker\",\"u\":11478212281098,\"s\":\"BTCUSDT\",\"ps\":\"BTCUSDT\",\"b\":\"79598.10\",\"B\":\"10.715\",\"a\":\"79598.20\",\"A\":\"3.566\",\"T\":1788563036714,\"E\":1788563036714,\"st\":1}}"}
{"receive_ns":1788563036653755000,"stream":"btcusdt@bookTicker","event_type":"bookTicker","event_time_ms":1788563036718,"raw_json":"{\"stream\":\"btcusdt@bookTicker\",\"data\":{\"e\":\"bookTicker\",\"u\":11478212281240,\"s\":\"BTCUSDT\",\"ps\":\"BTCUSDT\",\"b\":\"79598.10\",\"B\":\"10.715\",\"a\":\"79598.20\",\"A\":\"3.565\",\"T\":1788563036717,\"E\":1788563036718,\"st\":1}}"}
{"receive_ns":1788563036654650000,"stream":"btcusdt@trade","event_type":"trade","event_time_ms":1788563036718,"raw_json":"{\"stream\":\"btcusdt@trade\",\"data\":{\"e\":\"trade\",\"E\":1788563036718,\"T\":1788563036717,\"s\":\"BTCUSDT\",\"t\":8054081702,\"p\":\"79598.20\",\"q\":\"0.001\",\"X\":\"MARKET\",\"m\":false,\"st\":1}}"}
{"receive_ns":1788563036655917000,"stream":"btcusdt@bookTicker","event_type":"bookTicker","event_time_ms":1788563036719,"raw_json":"{\"stream\":\"btcusdt@bookTicker\",\"data\":{\"e\":\"bookTicker\",\"u\":11478212281316,\"s\":\"BTCUSDT\",\"ps\":\"BTCUSDT\",\"b\":\"79598.10\",\"B\":\"10.723\",\"a\":\"79598.20\",\"A\":\"3.565\",\"T\":1788563036719,\"E\":1788563036719,\"st\":1}}"}
{"receive_ns":1788563036657009000,"stream":"btcusdt@bookTicker","event_type":"bookTicker","event_time_ms":1788563036720,"raw_json":"{\"stream\":\"btcusdt@bookTicker\",\"data\":{\"e\":\"bookTicker\",\"u\":11478212281404,\"s\":\"BTCUSDT\",\"ps\":\"BTCUSDT\",\"b\":\"79598.10\",\"B\":\"10.715\",\"a\":\"79598.20\",\"A\":\"3.565\",\"T\":1788563036719,\"E\":1788563036720,\"st\":1}}"}
{"receive_ns":1788563036659435000,"stream":"btcusdt@bookTicker","event_type":"bookTicker","event_time_ms":1788563036725,"raw_json":"{\"stream\":\"btcusdt@bookTicker\",\"data\":{\"e\":\"bookTicker\",\"u\":11478212281553,\"s\":\"BTCUSDT\",\"ps\":\"BTCUSDT\",\"b\":\"79598.10\",\"B\":\"10.715\",\"a\":\"79598.20\",\"A\":\"3.564\",\"T\":1788563036725,\"E\":1788563036725,\"st\":1}}"}
{"receive_ns":1788563036665971000,"stream":"btcusdt@bookTicker","event_type":"bookTicker","event_time_ms":1788563036732,"raw_json":"{\"stream\":\"btcusdt@bookTicker\",\"data\":{\"e\":\"bookTicker\",\"u\":11478212281788,\"s\":\"BTCUSDT\",\"ps\":\"BTCUSDT\",\"b\":\"79598.10\",\"B\":\"10.715\",\"a\":\"79598.20\",\"A\":\"3.567\",\"T\":1788563036732,\"E\":1788563036732,\"st\":1}}"}
{"receive_ns":1788563036677015000,"stream":"btcusdt@bookTicker","event_type":"bookTicker","event_time_ms":1788563036743,"raw_json":"{\"stream\":\"btcusdt@bookTicker\",\"data\":{\"e\":\"bookTicker\",\"u\":11478212282109,\"s\":\"BTCUSDT\",\"ps\":\"BTCUSDT\",\"b\":\"79598.10\",\"B\":\"10.687\",\"a\":\"79598.20\",\"A\":\"3.567\",\"T\":1788563036743,\"E\":1788563036743,\"st\":1}}"}
{"receive_ns":1788563036677983000,"stream":"btcusdt@trade","event_type":"trade","event_time_ms":1788563036743,"raw_json":"{\"stream\":\"btcusdt@trade\",\"data\":{\"e\":\"trade\",\"E\":1788563036743,\"T\":1788563036743,\"s\":\"BTCUSDT\",\"t\":8054081703,\"p\":\"79598.10\",\"q\":\"0.028\",\"X\":\"MARKET\",\"m\":true,\"st\":1}}"}
{"receive_ns":1788563036678928000,"stream":"btcusdt@bookTicker","event_type":"bookTicker","event_time_ms":1788563036744,"raw_json":"{\"stream\":\"btcusdt@bookTicker\",\"data\":{\"e\":\"bookTicker\",\"u\":11478212282197,\"s\":\"BTCUSDT\",\"ps\":\"BTCUSDT\",\"b\":\"79598.10\",\"B\":\"10.695\",\"a\":\"79598.20\",\"A\":\"3.567\",\"T\":1788563036744,\"E\":1788563036744,\"st\":1}}"}
{"receive_ns":1788563036679874000,"stream":"btcusdt@bookTicker","event_type":"bookTicker","event_time_ms":1788563036745,"raw_json":"{\"stream\":\"btcusdt@bookTicker\",\"data\":{\"e\":\"bookTicker\",\"u\":11478212282234,\"s\":\"BTCUSDT\",\"ps\":\"BTCUSDT\",\"b\":\"79598.10\",\"B\":\"10.687\",\"a\":\"79598.20\",\"A\":\"3.567\",\"T\":1788563036745,\"E\":1788563036745,\"st\":1}}"}
{"receive_ns":1788563036724281000,"stream":"btcusdt@depth@100ms","event_type":"depthUpdate","event_time_ms":1788563036789,"raw_json":"{\"stream\":\"btcusdt@depth@100ms\",\"data\":{\"e\":\"depthUpdate\",\"E\":1788563036789,\"T\":1788563036787,\"s\":\"BTCUSDT\",\"ps\":\"BTCUSDT\",\"U\":11478212280030,\"u\":11478212283400,\"pu\":11478212280002,\"b\":[[\"29098.10\",\"0.042\"],[\"29198.10\",\"1.785\"],[\"29298.10\",\"0.273\"],[\"71638.20\",\"0.002\"],[\"76414.10\",\"0.000\"],[\"77767.70\",\"0.001\"],[\"78430.60\",\"0.000\"],[\"78507.60\",\"0.508\"],[\"78563.30\",\"0.095\"],[\"78784.10\",\"0.444\"],[\"78802.10\",\"0.002\"],[\"78982.00\",\"0.000\"],[\"79200.10\",\"0.153\"],[\"79226.00\",\"0.024\"],[\"79400.00\",\"4.554\"],[\"79401.10\",\"0.502\"],[\"79440.90\",\"1.005\"],[\"79496.20\",\"0.020\"],[\"79504.50\",\"0.000\"],[\"79506.50\",\"0.001\"],[\"79519.00\",\"0.862\"],[\"79533.00\",\"0.247\"],[\"79534.60\",\"0.000\"],[\"79534.90\",\"0.735\"],[\"79553.60\",\"0.000\"],[\"79576.30\",\"0.000\"],[\"79582.00\",\"0.003\"],[\"79589.00\",\"0.088\"],[\"79592.20\",\"0.000\"],[\"79598.10\",\"10.687\"]],\"a\":[[\"79598.20\",\"3.567\"],[\"79601.20\",\"0.027\"],[\"79601.50\",\"0.003\"],[\"79601.70\",\"0.027\"],[\"79601.90\",\"0.002\"],[\"79602.00\",\"0.077\"],[\"79602.10\",\"0.002\"],[\"79602.20\",\"0.699\"],[\"79603.10\",\"0.000\"],[\"79603.30\",\"0.028\"],[\"79603.40\",\"0.028\"],[\"79603.50\",\"0.026\"],[\"79611.10\",\"1.347\"],[\"79623.10\",\"0.163\"],[\"79626.60\",\"0.010\"],[\"79634.50\",\"0.121\"],[\"79647.10\",\"0.001\"],[\"79647.20\",\"0.001\"],[\"79674.30\",\"0.000\"],[\"79674.40\",\"0.630\"],[\"79675.60\",\"0.001\"],[\"79738.60\",\"0.580\"],[\"79738.80\",\"0.000\"],[\"79834.40\",\"0.018\"],[\"79836.20\",\"0.004\"],[\"79958.40\",\"0.020\"],[\"79996.20\",\"0.902\"],[\"80394.20\",\"2.981\"],[\"81190.10\",\"0.032\"]],\"st\":1}}"}
{"receive_ns":1788563036851387000,"stream":"btcusdt@depth@100ms","event_type":"depthUpdate","event_time_ms":1788563036891,"raw_json":"{\"stream\":\"btcusdt@depth@100ms\",\"data\":{\"e\":\"depthUpdate\",\"E\":1788563036891,\"T\":1788563036889,\"s\":\"BTCUSDT\",\"ps\":\"BTCUSDT\",\"U\":11478212283479,\"u\":11478212286595,\"pu\":11478212283400,\"b\":[[\"29098.10\",\"0.098\"],[\"29198.10\",\"1.855\"],[\"29298.10\",\"0.147\"],[\"71638.20\",\"0.002\"],[\"71675.00\",\"0.005\"],[\"78802.10\",\"0.002\"],[\"79226.00\",\"0.256\"],[\"79400.00\",\"4.755\"],[\"79401.10\",\"1.682\"],[\"79440.90\",\"1.256\"],[\"79464.10\",\"0.002\"],[\"79467.30\",\"2.246\"],[\"79536.30\",\"0.008\"]],\"a\":[[\"79601.20\",\"0.001\"],[\"79602.10\",\"0.253\"],[\"79602.20\",\"0.789\"],[\"79603.10\",\"0.200\"],[\"79626.50\",\"0.002\"],[\"79627.20\",\"0.124\"],[\"79660.70\",\"0.271\"],[\"79716.20\",\"0.600\"],[\"79716.50\",\"0.002\"],[\"79996.20\",\"1.866\"],[\"80389.30\",\"0.001\"],[\"80394.20\",\"2.983\"],[\"80423.00\",\"0.232\"],[\"80468.00\",\"3.405\"],[\"80712.60\",\"7.424\"],[\"81186.10\",\"0.006\"]],\"st\":1}}"}
{"receive_ns":1788563036914033000,"stream":"btcusdt@bookTicker","event_type":"bookTicker","event_time_ms":1788563036978,"raw_json":"{\"stream\":\"btcusdt@bookTicker\",\"data\":{\"e\":\"bookTicker\",\"u\":11478212289298,\"s\":\"BTCUSDT\",\"ps\":\"BTCUSDT\",\"b\":\"79598.10\",\"B\":\"10.687\",\"a\":\"79598.20\",\"A\":\"3.565\",\"T\":1788563036978,\"E\":1788563036978,\"st\":1}}"}
{"receive_ns":1788563036915520000,"stream":"btcusdt@bookTicker","event_type":"bookTicker","event_time_ms":1788563036980,"raw_json":"{\"stream\":\"btcusdt@bookTicker\",\"data\":{\"e\":\"bookTicker\",\"u\":11478212289399,\"s\":\"BTCUSDT\",\"ps\":\"BTCUSDT\",\"b\":\"79598.10\",\"B\":\"10.687\",\"a\":\"79598.20\",\"A\":\"3.568\",\"T\":1788563036980,\"E\":1788563036980,\"st\":1}}"}
{"receive_ns":1788563036926582000,"stream":"btcusdt@depth@100ms","event_type":"depthUpdate","event_time_ms":1788563036993,"raw_json":"{\"stream\":\"btcusdt@depth@100ms\",\"data\":{\"e\":\"depthUpdate\",\"E\":1788563036993,\"T\":1788563036990,\"s\":\"BTCUSDT\",\"ps\":\"BTCUSDT\",\"U\":11478212286635,\"u\":11478212289699,\"pu\":11478212286595,\"b\":[[\"1000.00\",\"24.604\"],[\"29098.10\",\"0.161\"],[\"29198.10\",\"1.904\"],[\"29298.10\",\"0.035\"],[\"63678.00\",\"0.000\"],[\"63679.00\",\"0.000\"],[\"71638.20\",\"0.002\"],[\"71675.00\",\"0.002\"],[\"76414.10\",\"0.002\"],[\"78443.90\",\"1.019\"],[\"78730.50\",\"0.633\"],[\"78802.10\",\"0.002\"],[\"79200.10\",\"0.143\"],[\"79440.90\",\"1.256\"],[\"79458.00\",\"0.018\"],[\"79508.20\",\"6.169\"],[\"79511.20\",\"2.909\"],[\"79536.80\",\"3.585\"],[\"79557.50\",\"1.835\"],[\"79568.30\",\"0.198\"],[\"79570.70\",\"0.008\"],[\"79576.00\",\"0.007\"],[\"79592.20\",\"0.000\"]],\"a\":[[\"79598.20\",\"3.568\"],[\"79602.20\",\"0.789\"],[\"79634.50\",\"0.549\"],[\"79655.20\",\"3.587\"],[\"79683.90\",\"6.157\"],[\"79996.20\",\"1.866\"],[\"80394.20\",\"2.981\"],[\"80586.20\",\"2.250\"],[\"80712.60\",\"9.280\"],[\"80752.40\",\"3.464\"],[\"80911.60\",\"1.012\"],[\"87558.10\",\"0.000\"]],\"st\":1}}"}
{"receive_ns":1788563036949014000,"stream":"btcusdt@bookTicker","event_type":"bookTicker","event_time_ms":1788563037014,"raw_json":"{\"stream\":\"btcusdt@bookTicker\",\"data\":{\"e\":\"bookTicker\",\"u\":11478212290486,\"s\":\"BTCUSDT\",\"ps\":\"BTCUSDT\",\"b\":\"79598.10\",\"B\":\"10.687\",\"a\":\"79598.20\",\"A\":\"3.565\",\"T\":1788563037014,\"E\":1788563037014,\"st\":1}}"}
{"receive_ns":1788563036953858000,"stream":"btcusdt@bookTicker","event_type":"bookTicker","event_time_ms":1788563037018,"raw_json":"{\"stream\":\"btcusdt@bookTicker\",\"data\":{\"e\":\"bookTicker\",\"u\":11478212290623,\"s\":\"BTCUSDT\",\"ps\":\"BTCUSDT\",\"b\":\"79598.10\",\"B\":\"10.687\",\"a\":\"79598.20\",\"A\":\"3.566\",\"T\":1788563037018,\"E\":1788563037018,\"st\":1}}"}
{"receive_ns":1788563036974978000,"stream":"btcusdt@bookTicker","event_type":"bookTicker","event_time_ms":1788563037040,"raw_json":"{\"stream\":\"btcusdt@bookTicker\",\"data\":{\"e\":\"bookTicker\",\"u\":11478212291442,\"s\":\"BTCUSDT\",\"ps\":\"BTCUSDT\",\"b\":\"79598.10\",\"B\":\"10.687\",\"a\":\"79598.20\",\"A\":\"3.567\",\"T\":1788563037040,\"E\":1788563037040,\"st\":1}}"}
{"receive_ns":1788563037019566000,"stream":"btcusdt@bookTicker","event_type":"bookTicker","event_time_ms":1788563037084,"raw_json":"{\"stream\":\"btcusdt@bookTicker\",\"data\":{\"e\":\"bookTicker\",\"u\":11478212292843,\"s\":\"BTCUSDT\",\"ps\":\"BTCUSDT\",\"b\":\"79598.10\",\"B\":\"10.687\",\"a\":\"79598.20\",\"A\":\"3.169\",\"T\":1788563037084,\"E\":1788563037084,\"st\":1}}"}
{"receive_ns":1788563037026606000,"stream":"btcusdt@bookTicker","event_type":"bookTicker","event_time_ms":1788563037086,"raw_json":"{\"stream\":\"btcusdt@bookTicker\",\"data\":{\"e\":\"bookTicker\",\"u\":11478212293257,\"s\":\"BTCUSDT\",\"ps\":\"BTCUSDT\",\"b\":\"79598.10\",\"B\":\"10.695\",\"a\":\"79598.20\",\"A\":\"3.169\",\"T\":1788563037086,\"E\":1788563037086,\"st\":1}}"}
{"receive_ns":1788563037026857000,"stream":"btcusdt@bookTicker","event_type":"bookTicker","event_time_ms":1788563037086,"raw_json":"{\"stream\":\"btcusdt@bookTicker\",\"data\":{\"e\":\"bookTicker\",\"u\":11478212293388,\"s\":\"BTCUSDT\",\"ps\":\"BTCUSDT\",\"b\":\"79598.10\",\"B\":\"10.687\",\"a\":\"79598.20\",\"A\":\"3.169\",\"T\":1788563037086,\"E\":1788563037086,\"st\":1}}"}
{"receive_ns":1788563037033284000,"stream":"btcusdt@depth@100ms","event_type":"depthUpdate","event_time_ms":1788563037095,"raw_json":"{\"stream\":\"btcusdt@depth@100ms\",\"data\":{\"e\":\"depthUpdate\",\"E\":1788563037095,\"T\":1788563037094,\"s\":\"BTCUSDT\",\"ps\":\"BTCUSDT\",\"U\":11478212289800,\"u\":11478212294034,\"pu\":11478212289699,\"b\":[[\"29098.10\",\"0.308\"],[\"29198.10\",\"1.792\"],[\"29298.10\",\"0.000\"],[\"63678.00\",\"0.000\"],[\"71638.20\",\"0.002\"],[\"76414.10\",\"0.000\"],[\"78244.90\",\"1.532\"],[\"78260.00\",\"0.092\"],[\"78802.10\",\"0.002\"],[\"79200.10\",\"0.142\"],[\"79226.00\",\"0.256\"],[\"79400.00\",\"4.755\"],[\"79401.10\",\"0.602\"],[\"79440.90\",\"2.336\"],[\"79467.60\",\"10.255\"],[\"79500.00\",\"1.789\"],[\"79523.90\",\"1.190\"],[\"79533.20\",\"0.679\"],[\"79535.80\",\"0.208\"],[\"79549.80\",\"0.001\"],[\"79563.60\",\"0.001\"],[\"79571.70\",\"0.001\"],[\"79572.40\",\"0.882\"],[\"79574.30\",\"0.002\"],[\"79577.40\",\"0.000\"],[\"79577.60\",\"0.628\"],[\"79578.50\",\"1.893\"],[\"79580.30\",\"0.630\"],[\"79581.60\",\"0.002\"],[\"79582.20\",\"0.214\"],[\"79583.00\",\"0.020\"],[\"79583.60\",\"0.316\"],[\"79583.70\",\"0.005\"],[\"79583.80\",\"0.000\"],[\"79584.80\",\"0.004\"],[\"79585.60\",\"0.003\"],[\"79585.70\",\"0.085\"],[\"79585.80\",\"0.069\"],[\"79586.50\",\"0.005\"],[\"79587.10\",\"0.206\"],[\"79587.70\",\"0.006\"],[\"79588.10\",\"0.142\"],[\"79588.80\",\"0.075\"],[\"79588.90\",\"0.170\"],[\"79589.00\",\"0.092\"],[\"79589.60\",\"0.140\"],[\"79590.70\",\"0.000\"],[\"79591.30\",\"0.251\"],[\"79591.60\",\"0.795\"],[\"79591.80\",\"0.130\"],[\"79592.00\",\"0.543\"],[\"79592.20\",\"0.004\"],[\"79592.60\",\"0.076\"],[\"79593.50\",\"0.002\"],[\"79594.10\",\"0.078\"],[\"79598.10\",\"10.687\"]],\"a\":[[\"79598.20\",\"3.169\"],[\"79600.10\",\"0.002\"],[\"79601.60\",\"0.000\"],[\"79601.70\",\"0.001\"],[\"79602.10\",\"0.253\"],[\"79602.20\",\"0.254\"],[\"79602.30\",\"0.000\"],[\"79602.90\",\"0.001\"],[\"79603.00\",\"0.000\"],[\"79603.10\",\"0.200\"],[\"79603.20\",\"0.004\"],[\"79603.30\",\"0.000\"],[\"79603.40\",\"0.002\"],[\"79603.50\",\"0.000\"],[\"79603.60\",\"0.190\"],[\"79603.70\",\"0.003\"],[\"79603.90\",\"0.428\"],[\"79604.00\",\"3.252\"],[\"79604.40\",\"0.002\"],[\"79604.50\",\"0.007\"],[\"79604.60\",\"0.002\"],[\"79604.80\",\"0.003\"],[\"79604.90\",\"0.434\"],[\"79605.00\",\"0.029\"],[\"79605.10\",\"0.000\"],[\"79605.20\",\"0.077\"],[\"79605.70\",\"0.036\"],[\"79605.80\",\"0.026\"],[\"79606.00\",\"0.027\"],[\"79606.10\",\"0.027\"],[\"79606.20\",\"1.284\"],[\"79606.30\",\"0.366\"],[\"79606.40\",\"0.107\"],[\"79606.60\",\"1.369\"],[\"79606.70\",\"0.026\"],[\"79606.80\",\"0.027\"],[\"79607.20\",\"0.003\"],[\"79608.40\",\"0.644\"],[\"79609.50\",\"1.265\"],[\"79610.20\",\"0.010\"],[\"79610.90\",\"0.740\"],[\"79611.10\",\"0.972\"],[\"79614.90\",\"0.000\"],[\"79615.60\",\"0.003\"],[\"79615.80\",\"0.881\"],[\"79616.40\",\"1.402\"],[\"79618.40\",\"0.070\"],[\"79620.40\",\"0.504\"],[\"79621.60\",\"0.000\"],[\"79623.10\",\"0.003\"],[\"79623.20\",\"0.627\"],[\"79624.00\",\"0.187\"],[\"79625.50\",\"0.022\"],[\"79627.20\",\"0.751\"],[\"79628.10\",\"0.016\"],[\"79638.00\",\"0.002\"],[\"79643.90\",\"0.002\"],[\"79644.40\",\"0.055\"],[\"79649.20\",\"2.010\"],[\"79654.00\",\"0.000\"],[\"79663.90\",\"1.568\"],[\"79667.70\",\"1.630\"],[\"79724.50\",\"10.714\"],[\"79738.70\",\"0.000\"],[\"79738.90\",\"0.000\"],[\"79958.40\",\"0.439\"],[\"79996.20\",\"1.867\"],[\"80195.20\",\"0.623\"],[\"80394.20\",\"2.981\"],[\"80465.80\",\"0.942\"]],\"st\":1}}"}
{"receive_ns":1788563037033652000,"stream":"btcusdt@bookTicker","event_type":"bookTicker","event_time_ms":1788563037096,"raw_json":"{\"stream\":\"btcusdt@bookTicker\",\"data\":{\"e\":\"bookTicker\",\"u\":11478212294101,\"s\":\"BTCUSDT\",\"ps\":\"BTCUSDT\",\"b\":\"79598.10\",\"B\":\"10.787\",\"a\":\"79598.20\",\"A\":\"3.169\",\"T\":1788563037095,\"E\":1788563037096,\"st\":1}}"}
{"receive_ns":1788563037033847000,"stream":"btcusdt@bookTicker","event_type":"bookTicker","event_time_ms":1788563037097,"raw_json":"{\"stream\":\"btcusdt@bookTicker\",\"data\":{\"e\":\"bookTicker\",\"u\":11478212294156,\"s\":\"BTCUSDT\",\"ps\":\"BTCUSDT\",\"b\":\"79598.10\",\"B\":\"10.785\",\"a\":\"79598.20\",\"A\":\"3.169\",\"T\":1788563037097,\"E\":1788563037097,\"st\":1}}"}
{"receive_ns":1788563037064476000,"stream":"btcusdt@bookTicker","event_type":"bookTicker","event_time_ms":1788563037129,"raw_json":"{\"stream\":\"btcusdt@bookTicker\",\"data\":{\"e\":\"bookTicker\",\"u\":11478212295761,\"s\":\"BTCUSDT\",\"ps\":\"BTCUSDT\",\"b\":\"79598.10\",\"B\":\"10.765\",\"a\":\"79598.20\",\"A\":\"3.169\",\"T\":1788563037129,\"E\":1788563037129,\"st\":1}}"}
{"receive_ns":1788563037066543000,"stream":"btcusdt@bookTicker","event_type":"bookTicker","event_time_ms":1788563037132,"raw_json":"{\"stream\":\"btcusdt@bookTicker\",\"data\":{\"e\":\"bookTicker\",\"u\":11478212295912,\"s\":\"BTCUSDT\",\"ps\":\"BTCUSDT\",\"b\":\"79598.10\",\"B\":\"10.790\",\"a\":\"79598.20\",\"A\":\"3.169\",\"T\":1788563037132,\"E\":1788563037132,\"st\":1}}"}
{"receive_ns":1788563037067679000,"stream":"btcusdt@bookTicker","event_type":"bookTicker","event_time_ms":1788563037133,"raw_json":"{\"stream\":\"btcusdt@bookTicker\",\"data\":{\"e\":\"bookTicker\",\"u\":11478212295984,\"s\":\"BTCUSDT\",\"ps\":\"BTCUSDT\",\"b\":\"79598.10\",\"B\":\"10.792\",\"a\":\"79598.20\",\"A\":\"3.169\",\"T\":1788563037133,\"E\":1788563037133,\"st\":1}}"}
{"receive_ns":1788563037131788000,"stream":"btcusdt@depth@100ms","event_type":"depthUpdate","event_time_ms":1788563037197,"raw_json":"{\"stream\":\"btcusdt@depth@100ms\",\"data\":{\"e\":\"depthUpdate\",\"E\":1788563037197,\"T\":1788563037193,\"s\":\"BTCUSDT\",\"ps\":\"BTCUSDT\",\"U\":11478212294101,\"u\":11478212298235,\"pu\":11478212294034,\"b\":[[\"29098.10\",\"0.483\"],[\"29198.10\",\"1.617\"],[\"63679.00\",\"0.000\"],[\"71638.20\",\"0.002\"],[\"75610.50\",\"0.033\"],[\"75610.60\",\"0.002\"],[\"75618.20\",\"0.006\"],[\"76414.10\",\"0.002\"],[\"78603.10\",\"0.849\"],[\"78802.10\",\"0.002\"],[\"78864.00\",\"20.025\"],[\"79200.10\",\"0.001\"],[\"79440.90\",\"1.331\"],[\"79453.50\",\"0.000\"],[\"79507.10\",\"3.386\"],[\"79507.90\",\"1.416\"],[\"79570.80\",\"0.000\"],[\"79581.40\",\"0.004\"],[\"79584.00\",\"0.012\"],[\"79587.80\",\"0.145\"],[\"79589.00\",\"0.088\"],[\"79589.60\",\"0.136\"],[\"79591.60\",\"0.796\"],[\"79591.80\",\"0.029\"],[\"79592.20\",\"0.008\"],[\"79593.70\",\"0.127\"],[\"79598.10\",\"10.792\"]],\"a\":[[\"79600.10\",\"0.001\"],[\"79602.20\",\"0.003\"],[\"79603.50\",\"0.026\"],[\"79603.60\",\"0.027\"],[\"79603.90\",\"0.076\"],[\"79604.00\",\"2.900\"],[\"79604.40\",\"0.028\"],[\"79604.50\",\"0.033\"],[\"79604.70\",\"0.026\"],[\"79604.80\",\"0.029\"],[\"79604.90\",\"0.460\"],[\"79605.10\",\"0.026\"],[\"79605.20\",\"0.077\"],[\"79605.30\",\"0.000\"],[\"79605.50\",\"0.000\"],[\"79605.60\",\"1.012\"],[\"79605.70\",\"0.010\"],[\"79605.80\",\"0.000\"],[\"79606.00\",\"0.001\"],[\"79606.10\",\"0.001\"],[\"79606.20\",\"1.258\"],[\"79606.30\",\"0.340\"],[\"79606.40\",\"0.081\"],[\"79606.60\",\"1.343\"],[\"79606.70\",\"0.000\"],[\"79606.80\",\"0.001\"],[\"79608.50\",\"1.863\"],[\"79609.60\",\"0.258\"],[\"79610.60\",\"0.440\"],[\"79611.70\",\"0.003\"],[\"79614.80\",\"0.014\"],[\"79619.90\",\"0.070\"],[\"79621.10\",\"3.298\"],[\"79623.80\",\"0.007\"],[\"79624.00\",\"0.027\"],[\"79625.90\",\"0.161\"],[\"79626.00\",\"0.008\"],[\"79626.10\",\"0.047\"],[\"79626.90\",\"0.010\"],[\"79628.70\",\"0.810\"],[\"79649.20\",\"0.010\"],[\"79651.10\",\"0.037\"],[\"79663.60\",\"0.653\"],[\"79698.80\",\"0.001\"],[\"79724.40\",\"2.070\"],[\"79724.50\",\"10.244\"],[\"79737.40\",\"0.000\"],[\"79738.70\",\"0.000\"],[\"79996.20\",\"1.341\"],[\"80394.20\",\"2.981\"]],\"st\":1}}"}
{"receive_ns":1788563037233302000,"stream":"btcusdt@depth@100ms","event_type":"depthUpdate","event_time_ms":1788563037299,"raw_json":"{\"stream\":\"btcusdt@depth@100ms\",\"data\":{\"e\":\"depthUpdate\",\"E\":1788563037299,\"T\":1788563037298,\"s\":\"BTCUSDT\",\"ps\":\"BTCUSDT\",\"U\":11478212298502,\"u\":11478212303546,\"pu\":11478212298235,\"b\":[[\"1000.00\",\"24.604\"],[\"29098.10\",\"0.665\"],[\"29198.10\",\"1.435\"],[\"71638.20\",\"0.002\"],[\"75618.20\",\"0.008\"],[\"78002.40\",\"0.006\"],[\"78006.10\",\"0.006\"],[\"78346.70\",\"1.213\"],[\"78404.10\",\"0.012\"],[\"78545.70\",\"0.007\"],[\"78579.20\",\"0.015\"],[\"78784.10\",\"0.000\"],[\"78802.10\",\"0.014\"],[\"79200.10\",\"0.152\"],[\"79226.00\",\"0.256\"],[\"79400.00\",\"4.554\"],[\"79401.10\",\"0.000\"],[\"79439.80\",\"0.202\"],[\"79440.90\",\"2.436\"],[\"79442.90\",\"0.502\"],[\"79467.30\",\"0.000\"],[\"79467.70\",\"3.655\"],[\"79534.60\",\"1.382\"],[\"79543.50\",\"0.000\"],[\"79561.90\",\"0.949\"],[\"79589.40\",\"0.006\"],[\"79592.20\",\"0.004\"],[\"79593.50\",\"0.000\"]],\"a\":[[\"79602.10\",\"0.253\"],[\"79602.20\",\"0.254\"],[\"79602.70\",\"0.029\"],[\"79603.10\",\"0.200\"],[\"79603.30\",\"0.026\"],[\"79603.50\",\"0.030\"],[\"79604.90\",\"0.434\"],[\"79605.10\",\"0.000\"],[\"79608.10\",\"0.352\"],[\"79609.50\",\"1.269\"],[\"79610.20\",\"0.006\"],[\"79636.10\",\"0.129\"],[\"79654.60\",\"1.171\"],[\"79680.10\",\"2.734\"],[\"79698.80\",\"0.002\"],[\"79739.20\",\"0.000\"],[\"79739.40\",\"0.000\"],[\"79739.80\",\"0.125\"],[\"79812.20\",\"1.506\"],[\"79958.40\",\"0.439\"],[\"79996.20\",\"1.867\"],[\"80394.20\",\"2.993\"],[\"80617.10\",\"0.012\"],[\"80768.50\",\"0.006\"],[\"80792.20\",\"0.007\"],[\"81190.20\",\"0.006\"]],\"st\":1}}"}
{"receive_ns":1788563037335492000,"stream":"btcusdt@depth@100ms","event_type":"depthUpdate","event_time_ms":1788563037401,"raw_json":"{\"stream\":\"btcusdt@depth@100ms\",\"data\":{\"e\":\"depthUpdate\",\"E\":1788563037401,\"T\":1788563037399,\"s\":\"BTCUSDT\",\"ps\":\"BTCUSDT\",\"U\":11478212303672,\"u\":11478212307625,\"pu\":11478212303546,\"b\":[[\"29098.10\",\"0.840\"],[\"29198.10\",\"1.260\"],[\"71638.20\",\"0.002\"],[\"75618.20\",\"0.010\"],[\"76414.10\",\"0.000\"],[\"78641.00\",\"7.400\"],[\"78801.50\",\"0.453\"],[\"78802.10\",\"0.014\"],[\"79543.40\",\"1.091\"],[\"79578.90\",\"0.031\"],[\"79579.60\",\"0.707\"],[\"79589.40\",\"0.002\"],[\"79592.20\",\"0.008\"]],\"a\":[[\"79602.50\",\"0.026\"],[\"79604.80\",\"0.003\"],[\"79609.50\",\"0.013\"],[\"79611.30\",\"0.748\"],[\"79611.70\",\"0.069\"],[\"79620.30\",\"0.647\"],[\"79620.40\",\"0.125\"],[\"79621.10\",\"3.298\"],[\"80394.20\",\"2.995\"],[\"80712.60\",\"9.651\"]],\"st\":1}}"}
{"receive_ns":1788563037341809000,"stream":"btcusdt@bookTicker","event_type":"bookTicker","event_time_ms":1788563037407,"raw_json":"{\"stream\":\"btcusdt@bookTicker\",\"data\":{\"e\":\"bookTicker\",\"u\":11478212307872,\"s\":\"BTCUSDT\",\"ps\":\"BTCUSDT\",\"b\":\"79598.10\",\"B\":\"10.792\",\"a\":\"79598.20\",\"A\":\"3.168\",\"T\":1788563037407,\"E\":1788563037407,\"st\":1}}"}
{"receive_ns":1788563037342059000,"stream":"btcusdt@bookTicker","event_type":"bookTicker","event_time_ms":1788563037408,"raw_json":"{\"stream\":\"btcusdt@bookTicker\",\"data\":{\"e\":\"bookTicker\",\"u\":11478212307941,\"s\":\"BTCUSDT\",\"ps\":\"BTCUSDT\",\"b\":\"79598.10\",\"B\":\"10.798\",\"a\":\"79598.20\",\"A\":\"3.168\",\"T\":1788563037408,\"E\":1788563037408,\"st\":1}}"}
{"receive_ns":1788563037348395000,"stream":"btcusdt@bookTicker","event_type":"bookTicker","event_time_ms":1788563037413,"raw_json":"{\"stream\":\"btcusdt@bookTicker\",\"data\":{\"e\":\"bookTicker\",\"u\":11478212308146,\"s\":\"BTCUSDT\",\"ps\":\"BTCUSDT\",\"b\":\"79598.10\",\"B\":\"10.798\",\"a\":\"79598.20\",\"A\":\"3.170\",\"T\":1788563037413,\"E\":1788563037413,\"st\":1}}"}
{"receive_ns":1788563037437079000,"stream":"btcusdt@depth@100ms","event_type":"depthUpdate","event_time_ms":1788563037503,"raw_json":"{\"stream\":\"btcusdt@depth@100ms\",\"data\":{\"e\":\"depthUpdate\",\"E\":1788563037503,\"T\":1788563037502,\"s\":\"BTCUSDT\",\"ps\":\"BTCUSDT\",\"U\":11478212307702,\"u\":11478212311150,\"pu\":11478212307625,\"b\":[[\"29098.10\",\"1.022\"],[\"29198.10\",\"1.078\"],[\"71638.20\",\"0.002\"],[\"76414.10\",\"0.002\"],[\"78558.30\",\"0.592\"],[\"78783.00\",\"0.233\"],[\"78797.10\",\"0.470\"],[\"78802.10\",\"0.014\"],[\"79200.10\",\"0.152\"],[\"79439.80\",\"0.001\"],[\"79440.90\",\"2.436\"],[\"79442.90\",\"0.000\"],[\"79528.00\",\"0.036\"],[\"79572.10\",\"0.079\"],[\"79574.40\",\"0.050\"],[\"79575.30\",\"0.440\"],[\"79592.20\",\"0.008\"],[\"79598.10\",\"10.798\"]],\"a\":[[\"79598.20\",\"3.170\"],[\"79599.90\",\"0.010\"],[\"79602.20\",\"0.254\"],[\"79602.40\",\"0.027\"],[\"79603.10\",\"0.000\"],[\"79604.70\",\"0.000\"],[\"79613.00\",\"0.002\"],[\"79614.30\",\"0.361\"],[\"79614.60\",\"0.373\"],[\"79615.70\",\"0.002\"],[\"79616.90\",\"0.456\"],[\"79644.10\",\"0.003\"],[\"79644.20\",\"0.003\"],[\"79644.30\",\"0.165\"],[\"79739.40\",\"0.000\"],[\"79739.70\",\"0.002\"],[\"79739.80\",\"0.000\"],[\"79958.40\",\"0.020\"],[\"79996.20\",\"1.867\"],[\"80394.20\",\"2.993\"],[\"80533.60\",\"6.384\"],[\"80692.80\",\"8.043\"],[\"80920.80\",\"0.987\"]],\"st\":1}}"}
{"receive_ns":1788563037444251000,"stream":"btcusdt@bookTicker","event_type":"bookTicker","event_time_ms":1788563037508,"raw_json":"{\"stream\":\"btcusdt@bookTicker\",\"data\":{\"e\":\"bookTicker\",\"u\":11478212311423,\"s\":\"BTCUSDT\",\"ps\":\"BTCUSDT\",\"b\":\"79598.10\",\"B\":\"10.796\",\"a\":\"79598.20\",\"A\":\"3.170\",\"T\":1788563037508,\"E\":1788563037508,\"st\":1}}"}
{"receive_ns":1788563037444491000,"stream":"btcusdt@trade","event_type":"trade","event_time_ms":1788563037508,"raw_json":"{\"stream\":\"btcusdt@trade\",\"data\":{\"e\":\"trade\",\"E\":1788563037508,\"T\":1788563037508,\"s\":\"BTCUSDT\",\"t\":8054081704,\"p\":\"79598.10\",\"q\":\"0.002\",\"X\":\"MARKET\",\"m\":true,\"st\":1}}"}
{"receive_ns":1788563037444708000,"stream":"btcusdt@bookTicker","event_type":"bookTicker","event_time_ms":1788563037510,"raw_json":"{\"stream\":\"btcusdt@bookTicker\",\"data\":{\"e\":\"bookTicker\",\"u\":11478212311469,\"s\":\"BTCUSDT\",\"ps\":\"BTCUSDT\",\"b\":\"79598.10\",\"B\":\"10.804\",\"a\":\"79598.20\",\"A\":\"3.170\",\"T\":1788563037509,\"E\":1788563037510,\"st\":1}}"}
{"receive_ns":1788563037445754000,"stream":"btcusdt@bookTicker","event_type":"bookTicker","event_time_ms":1788563037510,"raw_json":"{\"stream\":\"btcusdt@bookTicker\",\"data\":{\"e\":\"bookTicker\",\"u\":11478212311539,\"s\":\"BTCUSDT\",\"ps\":\"BTCUSDT\",\"b\":\"79598.10\",\"B\":\"10.796\",\"a\":\"79598.20\",\"A\":\"3.170\",\"T\":1788563037510,\"E\":1788563037510,\"st\":1}}"}
{"receive_ns":1788563037540422000,"stream":"btcusdt@depth@100ms","event_type":"depthUpdate","event_time_ms":1788563037605,"raw_json":"{\"stream\":\"btcusdt@depth@100ms\",\"data\":{\"e\":\"depthUpdate\",\"E\":1788563037605,\"T\":1788563037603,\"s\":\"BTCUSDT\",\"ps\":\"BTCUSDT\",\"U\":11478212311232,\"u\":11478212315186,\"pu\":11478212311150,\"b\":[[\"1000.00\",\"24.604\"],[\"29098.10\",\"1.197\"],[\"29198.10\",\"0.903\"],[\"63678.50\",\"0.000\"],[\"71638.20\",\"0.002\"],[\"76414.10\",\"0.000\"],[\"78109.60\",\"0.766\"],[\"78364.30\",\"0.901\"],[\"78802.10\",\"0.141\"],[\"79200.10\",\"0.142\"],[\"79226.00\",\"0.256\"],[\"79400.00\",\"4.755\"],[\"79440.90\",\"2.938\"],[\"79462.60\",\"0.013\"],[\"79462.70\",\"0.013\"],[\"79568.60\",\"0.002\"],[\"79573.20\",\"0.440\"],[\"79575.30\",\"0.001\"],[\"79580.30\",\"0.645\"],[\"79585.70\",\"0.024\"],[\"79589.40\",\"0.006\"],[\"79592.20\",\"0.004\"],[\"79598.10\",\"10.796\"]],\"a\":[[\"79602.10\",\"0.253\"],[\"79603.10\",\"0.200\"],[\"79608.10\",\"0.262\"],[\"79622.70\",\"0.007\"],[\"79645.20\",\"10.080\"],[\"79645.30\",\"0.001\"],[\"79685.10\",\"0.097\"],[\"79685.80\",\"0.001\"],[\"79737.00\",\"0.034\"],[\"79739.30\",\"0.000\"],[\"79739.50\",\"0.000\"],[\"79739.70\",\"0.002\"],[\"79739.90\",\"0.125\"],[\"79820.70\",\"0.000\"],[\"79820.80\",\"0.005\"],[\"79958.40\",\"0.439\"],[\"79996.20\",\"1.867\"],[\"80394.20\",\"2.993\"],[\"81279.70\",\"0.001\"]],\"st\":1}}"}
{"receive_ns":1788563037576362000,"stream":"btcusdt@bookTicker","event_type":"bookTicker","event_time_ms":1788563037640,"raw_json":"{\"stream\":\"btcusdt@bookTicker\",\"data\":{\"e\":\"bookTicker\",\"u\":11478212317198,\"s\":\"BTCUSDT\",\"ps\":\"BTCUSDT\",\"b\":\"79598.10\",\"B\":\"10.804\",\"a\":\"79598.20\",\"A\":\"3.170\",\"T\":1788563037640,\"E\":1788563037640,\"st\":1}}"}
{"receive_ns":1788563037576692000,"stream":"btcusdt@bookTicker","event_type":"bookTicker","event_time_ms":1788563037641,"raw_json":"{\"stream\":\"btcusdt@bookTicker\",\"data\":{\"e\":\"bookTicker\",\"u\":11478212317276,\"s\":\"BTCUSDT\",\"ps\":\"BTCUSDT\",\"b\":\"79598.10\",\"B\":\"10.796\",\"a\":\"79598.20\",\"A\":\"3.170\",\"T\":1788563037641,\"E\":1788563037641,\"st\":1}}"}
{"receive_ns":1788563037581747000,"stream":"btcusdt@bookTicker","event_type":"bookTicker","event_time_ms":1788563037647,"raw_json":"{\"stream\":\"btcusdt@bookTicker\",\"data\":{\"e\":\"bookTicker\",\"u\":11478212317550,\"s\":\"BTCUSDT\",\"ps\":\"BTCUSDT\",\"b\":\"79598.10\",\"B\":\"10.796\",\"a\":\"79598.20\",\"A\":\"3.168\",\"T\":1788563037647,\"E\":1788563037647,\"st\":1}}"}
{"receive_ns":1788563037591400000,"stream":"btcusdt@bookTicker","event_type":"bookTicker","event_time_ms":1788563037656,"raw_json":"{\"stream\":\"btcusdt@bookTicker\",\"data\":{\"e\":\"bookTicker\",\"u\":11478212317890,\"s\":\"BTCUSDT\",\"ps\":\"BTCUSDT\",\"b\":\"79598.10\",\"B\":\"10.796\",\"a\":\"79598.20\",\"A\":\"3.172\",\"T\":1788563037656,\"E\":1788563037656,\"st\":1}}"}
{"receive_ns":1788563037598979000,"stream":"btcusdt@bookTicker","event_type":"bookTicker","event_time_ms":1788563037664,"raw_json":"{\"stream\":\"btcusdt@bookTicker\",\"data\":{\"e\":\"bookTicker\",\"u\":11478212318256,\"s\":\"BTCUSDT\",\"ps\":\"BTCUSDT\",\"b\":\"79598.10\",\"B\":\"10.796\",\"a\":\"79598.20\",\"A\":\"3.169\",\"T\":1788563037664,\"E\":1788563037664,\"st\":1}}"}
{"receive_ns":1788563037641627000,"stream":"btcusdt@depth@100ms","event_type":"depthUpdate","event_time_ms":1788563037707,"raw_json":"{\"stream\":\"btcusdt@depth@100ms\",\"data\":{\"e\":\"depthUpdate\",\"E\":1788563037707,\"T\":1788563037705,\"s\":\"BTCUSDT\",\"ps\":\"BTCUSDT\",\"U\":11478212315324,\"u\":11478212319525,\"pu\":11478212315186,\"b\":[[\"29098.10\",\"1.379\"],[\"29198.10\",\"0.721\"],[\"71638.20\",\"0.002\"],[\"75618.20\",\"0.008\"],[\"75618.30\",\"0.002\"],[\"76414.10\",\"0.002\"],[\"78230.00\",\"0.789\"],[\"78306.90\",\"0.000\"],[\"78704.80\",\"0.002\"],[\"78797.10\",\"0.026\"],[\"78802.10\",\"0.141\"],[\"79200.10\",\"0.001\"],[\"79440.90\",\"1.933\"],[\"79552.00\",\"1.629\"],[\"79589.40\",\"0.006\"],[\"79592.20\",\"0.004\"],[\"79598.10\",\"10.796\"]],\"a\":[[\"79598.20\",\"3.169\"],[\"79598.30\",\"0.004\"],[\"79599.20\",\"0.252\"],[\"79601.70\",\"0.001\"],[\"79601.80\",\"0.027\"],[\"79601.90\",\"0.028\"],[\"79602.00\",\"0.103\"],[\"79602.10\",\"0.279\"],[\"79602.20\",\"0.029\"],[\"79602.40\",\"0.001\"],[\"79602.50\",\"0.000\"],[\"79603.70\",\"0.029\"],[\"79603.80\",\"0.252\"],[\"79603.90\",\"0.050\"],[\"79604.00\",\"2.874\"],[\"79604.10\",\"0.329\"],[\"79604.40\",\"0.002\"],[\"79604.50\",\"0.007\"],[\"79614.90\",\"0.000\"],[\"79616.10\",\"0.454\"],[\"79616.90\",\"0.004\"],[\"79643.30\",\"0.001\"],[\"79739.70\",\"0.002\"],[\"79739.80\",\"0.125\"],[\"79739.90\",\"0.000\"],[\"79996.20\",\"1.341\"],[\"80394.20\",\"2.993\"],[\"80533.80\",\"7.067\"]],\"st\":1}}"}
{"receive_ns":1788563037743946000,"stream":"btcusdt@depth@100ms","event_type":"depthUpdate","event_time_ms":1788563037809,"raw_json":"{\"stream\":\"btcusdt@depth@100ms\",\"data\":{\"e\":\"depthUpdate\",\"E\":1788563037809,\"T\":1788563037808,\"s\":\"BTCUSDT\",\"ps\":\"BTCUSDT\",\"U\":11478212319577,\"u\":11478212323584,\"pu\":11478212319525,\"b\":[[\"1000.00\",\"24.604\"],[\"29098.10\",\"1.554\"],[\"29198.10\",\"0.546\"],[\"71638.20\",\"0.002\"],[\"75618.10\",\"0.028\"],[\"77987.00\",\"0.028\"],[\"78075.40\",\"0.028\"],[\"78163.90\",\"0.028\"],[\"78167.50\",\"0.660\"],[\"78252.30\",\"0.028\"],[\"78340.70\",\"0.028\"],[\"78429.10\",\"1.020\"],[\"78517.60\",\"0.919\"],[\"78606.00\",\"1.005\"],[\"78694.40\",\"0.220\"],[\"78782.80\",\"0.031\"],[\"78797.50\",\"0.000\"],[\"78801.30\",\"0.510\"],[\"78802.10\",\"0.141\"],[\"79200.10\",\"0.143\"],[\"79226.00\",\"0.024\"],[\"79400.00\",\"4.554\"],[\"79440.90\",\"1.005\"],[\"79442.90\",\"0.502\"]],\"a\":[[\"79599.50\",\"0.002\"],[\"79601.40\",\"0.026\"],[\"79601.60\",\"0.026\"],[\"79602.10\",\"0.028\"],[\"79603.10\",\"0.200\"],[\"79603.60\",\"0.001\"],[\"79603.70\",\"0.003\"],[\"79608.10\",\"0.513\"],[\"79634.30\",\"0.088\"],[\"79637.70\",\"0.006\"],[\"79691.80\",\"0.087\"],[\"79739.30\",\"0.000\"],[\"79739.80\",\"0.000\"],[\"79958.40\",\"0.439\"],[\"79996.20\",\"0.902\"],[\"80374.40\",\"0.030\"],[\"80394.20\",\"2.993\"],[\"80462.80\",\"0.028\"],[\"80484.90\",\"0.621\"],[\"80551.20\",\"0.028\"],[\"80553.40\",\"6.688\"],[\"80639.60\",\"0.033\"],[\"80712.60\",\"11.507\"],[\"80728.10\",\"0.028\"],[\"80816.50\",\"0.028\"],[\"80904.90\",\"0.028\"],[\"80993.30\",\"0.028\"],[\"81081.80\",\"0.030\"],[\"81170.20\",\"0.170\"],[\"87558.10\",\"0.000\"]],\"st\":1}}"}
{"receive_ns":1788563037744480000,"stream":"btcusdt@bookTicker","event_type":"bookTicker","event_time_ms":1788563037810,"raw_json":"{\"stream\":\"btcusdt@bookTicker\",\"data\":{\"e\":\"bookTicker\",\"u\":11478212323663,\"s\":\"BTCUSDT\",\"ps\":\"BTCUSDT\",\"b\":\"79598.10\",\"B\":\"10.804\",\"a\":\"79598.20\",\"A\":\"3.169\",\"T\":1788563037810,\"E\":1788563037810,\"st\":1}}"}
{"receive_ns":1788563037744741000,"stream":"btcusdt@bookTicker","event_type":"bookTicker","event_time_ms":1788563037811,"raw_json":"{\"stream\":\"btcusdt@bookTicker\",\"data\":{\"e\":\"bookTicker\",\"u\":11478212323698,\"s\":\"BTCUSDT\",\"ps\":\"BTCUSDT\",\"b\":\"79598.10\",\"B\":\"10.796\",\"a\":\"79598.20\",\"A\":\"3.169\",\"T\":1788563037811,\"E\":1788563037811,\"st\":1}}"}
{"receive_ns":1788563037806888000,"stream":"btcusdt@bookTicker","event_type":"bookTicker","event_time_ms":1788563037872,"raw_json":"{\"stream\":\"btcusdt@bookTicker\",\"data\":{\"e\":\"bookTicker\",\"u\":11478212325701,\"s\":\"BTCUSDT\",\"ps\":\"BTCUSDT\",\"b\":\"79598.10\",\"B\":\"10.796\",\"a\":\"79598.20\",\"A\":\"3.172\",\"T\":1788563037871,\"E\":1788563037872,\"st\":1}}"}
{"receive_ns":1788563037845960000,"stream":"btcusdt@depth@100ms","event_type":"depthUpdate","event_time_ms":1788563037911,"raw_json":"{\"stream\":\"btcusdt@depth@100ms\",\"data\":{\"e\":\"depthUpdate\",\"E\":1788563037911,\"T\":1788563037909,\"s\":\"BTCUSDT\",\"ps\":\"BTCUSDT\",\"U\":11478212323658,\"u\":11478212326845,\"pu\":11478212323584,\"b\":[[\"1000.00\",\"24.604\"],[\"29098.10\",\"1.736\"],[\"29198.10\",\"0.364\"],[\"71638.20\",\"0.002\"],[\"75610.10\",\"0.000\"],[\"75610.20\",\"0.004\"],[\"76414.10\",\"0.000\"],[\"77487.10\",\"0.000\"],[\"78006.20\",\"0.024\"],[\"78802.10\",\"0.143\"],[\"79200.10\",\"0.143\"],[\"79226.00\",\"0.256\"],[\"79440.90\",\"2.436\"],[\"79441.80\",\"0.202\"],[\"79589.40\",\"0.006\"],[\"79592.20\",\"0.004\"],[\"79598.10\",\"10.796\"]],\"a\":[[\"79598.20\",\"3.172\"],[\"79606.10\",\"0.252\"],[\"79996.20\",\"1.956\"],[\"80394.20\",\"2.993\"],[\"80533.80\",\"3.347\"],[\"80937.60\",\"0.000\"]],\"st\":1}}"}
{"receive_ns":1788563037926009000,"stream":"btcusdt@bookTicker","event_type":"bookTicker","event_time_ms":1788563037992,"raw_json":"{\"stream\":\"btcusdt@bookTicker\",\"data\":{\"e\":\"bookTicker\",\"u\":11478212329137,\"s\":\"BTCUSDT\",\"ps\":\"BTCUSDT\",\"b\":\"79598.10\",\"B\":\"10.796\",\"a\":\"79598.20\",\"A\":\"3.171\",\"T\":1788563037992,\"E\":1788563037992,\"st\":1}}"}
{"receive_ns":1788563037945579000,"stream":"btcusdt@bookTicker","event_type":"bookTicker","event_time_ms":1788563038010,"raw_json":"{\"stream\":\"btcusdt@bookTicker\",\"data\":{\"e\":\"bookTicker\",\"u\":11478212329945,\"s\":\"BTCUSDT\",\"ps\":\"BTCUSDT\",\"b\":\"79598.10\",\"B\":\"10.802\",\"a\":\"79598.20\",\"A\":\"3.171\",\"T\":1788563038010,\"E\":1788563038010,\"st\":1}}"}
{"receive_ns":1788563037946861000,"stream":"btcusdt@depth@100ms","event_type":"depthUpdate","event_time_ms":1788563038013,"raw_json":"{\"stream\":\"btcusdt@depth@100ms\",\"data\":{\"e\":\"depthUpdate\",\"E\":1788563038013,\"T\":1788563038012,\"s\":\"BTCUSDT\",\"ps\":\"BTCUSDT\",\"U\":11478212326891,\"u\":11478212330076,\"pu\":11478212326845,\"b\":[[\"29098.10\",\"1.799\"],[\"29198.10\",\"0.245\"],[\"29498.10\",\"0.056\"],[\"71638.20\",\"0.002\"],[\"76414.10\",\"0.002\"],[\"78404.10\",\"0.299\"],[\"78562.70\",\"0.445\"],[\"78611.30\",\"0.012\"],[\"78616.10\",\"0.196\"],[\"78802.10\",\"0.143\"],[\"79200.10\",\"0.143\"],[\"79226.00\",\"0.024\"],[\"79440.90\",\"1.005\"],[\"79441.80\",\"0.001\"],[\"79442.90\",\"0.000\"],[\"79581.40\",\"0.001\"],[\"79585.30\",\"0.080\"],[\"79593.80\",\"0.065\"],[\"79598.10\",\"10.802\"]],\"a\":[[\"79598.20\",\"3.171\"],[\"79602.20\",\"0.280\"],[\"79603.10\",\"0.000\"],[\"79606.10\",\"0.001\"],[\"79606.40\",\"0.078\"],[\"79608.10\",\"0.262\"],[\"79610.30\",\"0.826\"],[\"79622.70\",\"0.000\"],[\"79644.10\",\"0.001\"],[\"79691.80\",\"0.001\"],[\"79958.40\",\"0.020\"],[\"79996.20\",\"0.902\"],[\"80394.20\",\"2.993\"]],\"st\":1}}"}
{"receive_ns":1788563037972767000,"stream":"btcusdt@bookTicker","event_type":"bookTicker","event_time_ms":1788563038026,"raw_json":"{\"stream\":\"btcusdt@bookTicker\",\"data\":{\"e\":\"bookTicker\",\"u\":11478212330623,\"s\":\"BTCUSDT\",\"ps\":\"BTCUSDT\",\"b\":\"79598.10\",\"B\":\"10.864\",\"a\":\"79598.20\",\"A\":\"3.171\",\"T\":1788563038026,\"E\":1788563038026,\"st\":1}}"}
{"receive_ns":1788563037990746000,"stream":"btcusdt@bookTicker","event_type":"bookTicker","event_time_ms":1788563038056,"raw_json":"{\"stream\":\"btcusdt@bookTicker\",\"data\":{\"e\":\"bookTicker\",\"u\":11478212332220,\"s\":\"BTCUSDT\",\"ps\":\"BTCUSDT\",\"b\":\"79598.10\",\"B\":\"10.865\",\"a\":\"79598.20\",\"A\":\"3.171\",\"T\":1788563038056,\"E\":1788563038056,\"st\":1}}"}
{"receive_ns":1788563038034440000,"stream":"btcusdt@bookTicker","event_type":"bookTicker","event_time_ms":1788563038099,"raw_json":"{\"stream\":\"btcusdt@bookTicker\",\"data\":{\"e\":\"bookTicker\",\"u\":11478212333543,\"s\":\"BTCUSDT\",\"ps\":\"BTCUSDT\",\"b\":\"79598.10\",\"B\":\"10.865\",\"a\":\"79598.20\",\"A\":\"3.168\",\"T\":1788563038098,\"E\":1788563038099,\"st\":1}}"}
{"receive_ns":1788563038044280000,"stream":"btcusdt@bookTicker","event_type":"bookTicker","event_time_ms":1788563038108,"raw_json":"{\"stream\":\"btcusdt@bookTicker\",\"data\":{\"e\":\"bookTicker\",\"u\":11478212334142,\"s\":\"BTCUSDT\",\"ps\":\"BTCUSDT\",\"b\":\"79598.10\",\"B\":\"10.865\",\"a\":\"79598.20\",\"A\":\"3.169\",\"T\":1788563038108,\"E\":1788563038108,\"st\":1}}"}
{"receive_ns":1788563038049939000,"stream":"btcusdt@depth@100ms","event_type":"depthUpdate","event_time_ms":1788563038115,"raw_json":"{\"stream\":\"btcusdt@depth@100ms\",\"data\":{\"e\":\"depthUpdate\",\"E\":1788563038115,\"T\":1788563038113,\"s\":\"BTCUSDT\",\"ps\":\"BTCUSDT\",\"U\":11478212330115,\"u\":11478212334405,\"pu\":11478212330076,\"b\":[[\"1000.00\",\"24.604\"],[\"29098.10\",\"1.869\"],[\"29198.10\",\"0.119\"],[\"29498.10\",\"0.112\"],[\"71638.20\",\"0.002\"],[\"71675.00\",\"0.002\"],[\"76414.10\",\"0.000\"],[\"77687.70\",\"0.365\"],[\"78005.10\",\"0.002\"],[\"78152.10\",\"0.002\"],[\"78802.10\",\"0.141\"],[\"79200.10\",\"0.144\"],[\"79401.10\",\"0.232\"],[\"79439.80\",\"0.202\"],[\"79440.90\",\"1.933\"],[\"79492.60\",\"1.006\"],[\"79583.80\",\"0.000\"],[\"79592.20\",\"0.004\"],[\"79598.10\",\"10.865\"]],\"a\":[[\"79598.20\",\"3.169\"],[\"79602.20\",\"0.029\"],[\"79603.10\",\"0.200\"],[\"79611.20\",\"0.230\"],[\"79611.70\",\"0.065\"],[\"79621.10\",\"3.220\"],[\"79633.70\",\"0.099\"],[\"79726.60\",\"0.001\"],[\"79735.50\",\"0.024\"],[\"79739.60\",\"0.001\"],[\"79739.70\",\"0.002\"],[\"79742.30\",\"0.471\"],[\"79958.40\",\"0.439\"],[\"79996.20\",\"1.955\"],[\"80309.80\",\"0.000\"],[\"80394.20\",\"2.993\"],[\"80533.60\",\"5.144\"],[\"80563.80\",\"0.621\"],[\"80746.40\",\"0.000\"]],\"st\":1}}"}
{"receive_ns":1788563038149924000,"stream":"btcusdt@depth@100ms","event_type":"depthUpdate","event_time_ms":1788563038217,"raw_json":"{\"stream\":\"btcusdt@depth@100ms\",\"data\":{\"e\":\"depthUpdate\",\"E\":1788563038217,\"T\":1788563038214,\"s\":\"BTCUSDT\",\"ps\":\"BTCUSDT\",\"U\":11478212334486,\"u\":11478212338025,\"pu\":11478212334405,\"b\":[[\"1000.00\",\"24.604\"],[\"29098.10\",\"1.904\"],[\"29198.10\",\"0.014\"],[\"29498.10\",\"0.182\"],[\"71638.20\",\"0.002\"],[\"77157.70\",\"0.000\"],[\"77953.10\",\"0.000\"],[\"78576.00\",\"0.051\"],[\"78585.80\",\"0.005\"],[\"78592.50\",\"0.000\"],[\"78602.10\",\"0.004\"],[\"78616.10\",\"0.193\"],[\"78618.40\",\"16.625\"],[\"78802.10\",\"0.141\"],[\"79200.10\",\"0.013\"],[\"79440.90\",\"0.928\"],[\"79578.60\",\"0.297\"],[\"79580.30\",\"0.646\"],[\"79581.80\",\"0.345\"]],\"a\":[[\"79739.60\",\"0.001\"],[\"79739.90\",\"0.000\"],[\"79996.20\",\"1.429\"],[\"80394.20\",\"2.993\"],[\"80470.80\",\"0.000\"],[\"80484.30\",\"0.620\"],[\"80553.40\",\"10.407\"],[\"80703.30\",\"0.000\"]],\"st\":1}}"}
{"receive_ns":1788563038190281000,"stream":"btcusdt@bookTicker","event_type":"bookTicker","event_time_ms":1788563038254,"raw_json":"{\"stream\":\"btcusdt@bookTicker\",\"data\":{\"e\":\"bookTicker\",\"u\":11478212339522,\"s\":\"BTCUSDT\",\"ps\":\"BTCUSDT\",\"b\":\"79598.10\",\"B\":\"10.865\",\"a\":\"79598.20\",\"A\":\"3.170\",\"T\":1788563038254,\"E\":1788563038254,\"st\":1}}"}
{"receive_ns":1788563038254498000,"stream":"btcusdt@depth@100ms","event_type":"depthUpdate","event_time_ms":1788563038319,"raw_json":"{\"stream\":\"btcusdt@depth@100ms\",\"data\":{\"e\":\"depthUpdate\",\"E\":1788563038319,\"T\":1788563038317,\"s\":\"BTCUSDT\",\"ps\":\"BTCUSDT\",\"U\":11478212338157,\"u\":11478212341667,\"pu\":11478212338025,\"b\":[[\"29098.10\",\"1.750\"],[\"29198.10\",\"0.000\"],[\"29498.10\",\"0.350\"],[\"63678.00\",\"0.002\"],[\"71638.20\",\"0.002\"],[\"74771.40\",\"0.000\"],[\"76414.10\",\"0.002\"],[\"78558.30\",\"0.147\"],[\"78801.60\",\"0.444\"],[\"78802.10\",\"0.141\"],[\"79200.10\",\"0.154\"],[\"79226.00\",\"0.256\"],[\"79401.10\",\"0.100\"],[\"79439.80\",\"0.202\"],[\"79440.90\",\"2.838\"],[\"79492.60\",\"0.001\"],[\"79522.40\",\"0.002\"],[\"79558.30\",\"0.078\"],[\"79574.20\",\"0.003\"],[\"79585.30\",\"0.142\"],[\"79585.80\",\"0.007\"],[\"79592.20\",\"0.004\"]],\"a\":[[\"79598.20\",\"3.170\"],[\"79602.10\",\"0.279\"],[\"79602.20\",\"0.370\"],[\"79603.10\",\"0.200\"],[\"79622.10\",\"1.888\"],[\"79638.00\",\"0.004\"],[\"79645.10\",\"3.097\"],[\"79673.90\",\"0.003\"],[\"79740.00\",\"0.500\"],[\"79860.90\",\"0.005\"],[\"79958.40\",\"0.439\"],[\"79996.20\",\"1.865\"],[\"80314.60\",\"1.864\"],[\"80394.20\",\"2.994\"],[\"80672.80\",\"1.112\"],[\"80792.70\",\"0.278\"],[\"81190.10\",\"0.029\"]],\"st\":1}}"}
{"receive_ns":1788563038304927000,"stream":"btcusdt@bookTicker","event_type":"bookTicker","event_time_ms":1788563038340,"raw_json":"{\"stream\":\"btcusdt@bookTicker\",\"data\":{\"e\":\"bookTicker\",\"u\":11478212342747,\"s\":\"BTCUSDT\",\"ps\":\"BTCUSDT\",\"b\":\"79598.10\",\"B\":\"10.865\",\"a\":\"79598.20\",\"A\":\"3.169\",\"T\":1788563038340,\"E\":1788563038340,\"st\":1}}"}
{"receive_ns":1788563038305201000,"stream":"btcusdt@bookTicker","event_type":"bookTicker","event_time_ms":1788563038346,"raw_json":"{\"stream\":\"btcusdt@bookTicker\",\"data\":{\"e\":\"bookTicker\",\"u\":11478212342941,\"s\":\"BTCUSDT\",\"ps\":\"BTCUSDT\",\"b\":\"79598.10\",\"B\":\"10.865\",\"a\":\"79598.20\",\"A\":\"3.172\",\"T\":1788563038345,\"E\":1788563038346,\"st\":1}}"}
{"receive_ns":1788563038306484000,"stream":"btcusdt@bookTicker","event_type":"bookTicker","event_time_ms":1788563038371,"raw_json":"{\"stream\":\"btcusdt@bookTicker\",\"data\":{\"e\":\"bookTicker\",\"u\":11478212343889,\"s\":\"BTCUSDT\",\"ps\":\"BTCUSDT\",\"b\":\"79598.10\",\"B\":\"10.855\",\"a\":\"79598.20\",\"A\":\"3.172\",\"T\":1788563038371,\"E\":1788563038371,\"st\":1}}"}
{"receive_ns":1788563038307559000,"stream":"btcusdt@bookTicker","event_type":"bookTicker","event_time_ms":1788563038374,"raw_json":"{\"stream\":\"btcusdt@bookTicker\",\"data\":{\"e\":\"bookTicker\",\"u\":11478212343974,\"s\":\"BTCUSDT\",\"ps\":\"BTCUSDT\",\"b\":\"79598.10\",\"B\":\"10.872\",\"a\":\"79598.20\",\"A\":\"3.172\",\"T\":1788563038373,\"E\":1788563038374,\"st\":1}}"}
{"receive_ns":1788563038337267000,"stream":"btcusdt@bookTicker","event_type":"bookTicker","event_time_ms":1788563038404,"raw_json":"{\"stream\":\"btcusdt@bookTicker\",\"data\":{\"e\":\"bookTicker\",\"u\":11478212344888,\"s\":\"BTCUSDT\",\"ps\":\"BTCUSDT\",\"b\":\"79598.10\",\"B\":\"10.872\",\"a\":\"79598.20\",\"A\":\"3.173\",\"T\":1788563038403,\"E\":1788563038404,\"st\":1}}"}
{"receive_ns":1788563038355944000,"stream":"btcusdt@depth@100ms","event_type":"depthUpdate","event_time_ms":1788563038421,"raw_json":"{\"stream\":\"btcusdt@depth@100ms\",\"data\":{\"e\":\"depthUpdate\",\"E\":1788563038421,\"T\":1788563038417,\"s\":\"BTCUSDT\",\"ps\":\"BTCUSDT\",\"U\":11478212341749,\"u\":11478212345362,\"pu\":11478212341667,\"b\":[[\"1000.00\",\"24.604\"],[\"29098.10\",\"1.575\"],[\"29498.10\",\"0.525\"],[\"71638.20\",\"0.002\"],[\"75566.80\",\"0.000\"],[\"76362.20\",\"0.000\"],[\"76414.10\",\"0.000\"],[\"78404.10\",\"2.847\"],[\"78505.90\",\"0.636\"],[\"78623.90\",\"3.364\"],[\"78802.10\",\"2.042\"],[\"79001.10\",\"0.698\"],[\"79589.40\",\"0.002\"],[\"79592.20\",\"0.008\"],[\"79598.10\",\"10.872\"]],\"a\":[[\"79598.20\",\"3.173\"],[\"79601.40\",\"0.000\"],[\"79601.60\",\"0.000\"],[\"79604.30\",\"0.005\"],[\"79611.20\",\"0.226\"],[\"79611.70\",\"0.069\"],[\"79645.20\",\"10.081\"],[\"79660.70\",\"0.257\"],[\"79740.20\",\"0.127\"],[\"80394.20\",\"4.236\"],[\"80553.40\",\"11.647\"],[\"81190.10\",\"0.026\"]],\"st\":1}}"}
{"receive_ns":1788563038394575000,"stream":"btcusdt@bookTicker","event_type":"bookTicker","event_time_ms":1788563038457,"raw_json":"{\"stream\":\"btcusdt@bookTicker\",\"data\":{\"e\":\"bookTicker\",\"u\":11478212346671,\"s\":\"BTCUSDT\",\"ps\":\"BTCUSDT\",\"b\":\"79598.10\",\"B\":\"10.835\",\"a\":\"79598.20\",\"A\":\"3.173\",\"T\":1788563038457,\"E\":1788563038457,\"st\":1}}"}
{"receive_ns":1788563038394884000,"stream":"btcusdt@bookTicker","event_type":"bookTicker","event_time_ms":1788563038460,"raw_json":"{\"stream\":\"btcusdt@bookTicker\",\"data\":{\"e\":\"bookTicker\",\"u\":11478212346815,\"s\":\"BTCUSDT\",\"ps\":\"BTCUSDT\",\"b\":\"79598.10\",\"B\":\"10.876\",\"a\":\"79598.20\",\"A\":\"3.173\",\"T\":1788563038460,\"E\":1788563038460,\"st\":1}}"}
{"receive_ns":1788563038414630000,"stream":"btcusdt@bookTicker","event_type":"bookTicker","event_time_ms":1788563038478,"raw_json":"{\"stream\":\"btcusdt@bookTicker\",\"data\":{\"e\":\"bookTicker\",\"u\":11478212347370,\"s\":\"BTCUSDT\",\"ps\":\"BTCUSDT\",\"b\":\"79598.10\",\"B\":\"10.884\",\"a\":\"79598.20\",\"A\":\"3.173\",\"T\":1788563038477,\"E\":1788563038478,\"st\":1}}"}
{"receive_ns":1788563038414942000,"stream":"btcusdt@bookTicker","event_type":"bookTicker","event_time_ms":1788563038478,"raw_json":"{\"stream\":\"btcusdt@bookTicker\",\"data\":{\"e\":\"bookTicker\",\"u\":11478212347412,\"s\":\"BTCUSDT\",\"ps\":\"BTCUSDT\",\"b\":\"79598.10\",\"B\":\"10.876\",\"a\":\"79598.20\",\"A\":\"3.173\",\"T\":1788563038478,\"E\":1788563038478,\"st\":1}}"}
{"receive_ns":1788563038426179000,"stream":"btcusdt@bookTicker","event_type":"bookTicker","event_time_ms":1788563038492,"raw_json":"{\"stream\":\"btcusdt@bookTicker\",\"data\":{\"e\":\"bookTicker\",\"u\":11478212347871,\"s\":\"BTCUSDT\",\"ps\":\"BTCUSDT\",\"b\":\"79598.10\",\"B\":\"10.860\",\"a\":\"79598.20\",\"A\":\"3.173\",\"T\":1788563038492,\"E\":1788563038492,\"st\":1}}"}
{"receive_ns":1788563038429276000,"stream":"btcusdt@bookTicker","event_type":"bookTicker","event_time_ms":1788563038494,"raw_json":"{\"stream\":\"btcusdt@bookTicker\",\"data\":{\"e\":\"bookTicker\",\"u\":11478212347951,\"s\":\"BTCUSDT\",\"ps\":\"BTCUSDT\",\"b\":\"79598.10\",\"B\":\"10.881\",\"a\":\"79598.20\",\"A\":\"3.173\",\"T\":1788563038494,\"E\":1788563038494,\"st\":1}}"}
{"receive_ns":1788563038459175000,"stream":"btcusdt@depth@100ms","event_type":"depthUpdate","event_time_ms":1788563038523,"raw_json":"{\"stream\":\"btcusdt@depth@100ms\",\"data\":{\"e\":\"depthUpdate\",\"E\":1788563038523,\"T\":1788563038522,\"s\":\"BTCUSDT\",\"ps\":\"BTCUSDT\",\"U\":11478212345469,\"u\":11478212349290,\"pu\":11478212345362,\"b\":[[\"1000.00\",\"24.604\"],[\"29098.10\",\"1.393\"],[\"29498.10\",\"0.707\"],[\"71638.20\",\"0.002\"],[\"76414.10\",\"0.002\"],[\"77345.20\",\"0.258\"],[\"78006.20\",\"0.027\"],[\"78483.70\",\"7.636\"],[\"78642.90\",\"5.372\"],[\"78681.90\",\"5.386\"],[\"78784.50\",\"5.289\"],[\"78801.60\",\"0.888\"],[\"78802.10\",\"2.042\"],[\"79001.10\",\"1.330\"],[\"79200.10\",\"0.154\"],[\"79439.80\",\"0.001\"],[\"79440.90\",\"2.336\"],[\"79441.80\",\"0.202\"],[\"79442.90\",\"0.502\"],[\"79568.00\",\"0.026\"],[\"79570.70\",\"0.002\"],[\"79573.30\",\"0.007\"],[\"79574.40\",\"0.048\"],[\"79598.10\",\"10.881\"]],\"a\":[[\"79599.20\",\"0.000\"],[\"79599.90\",\"0.262\"],[\"79601.40\",\"0.026\"],[\"79602.20\",\"0.280\"],[\"79603.10\",\"0.200\"],[\"79614.30\",\"0.359\"],[\"79698.70\",\"0.001\"],[\"79740.00\",\"0.625\"],[\"79740.20\",\"0.002\"],[\"79958.40\",\"0.439\"],[\"79996.20\",\"1.865\"],[\"80394.20\",\"4.236\"],[\"80553.40\",\"12.887\"],[\"80568.10\",\"4.298\"],[\"80659.10\",\"0.000\"],[\"80712.60\",\"13.363\"],[\"81490.60\",\"0.020\"]],\"st\":1}}"}
{"receive_ns":1788563038489858000,"stream":"btcusdt@bookTicker","event_type":"bookTicker","event_time_ms":1788563038547,"raw_json":"{\"stream\":\"btcusdt@bookTicker\",\"data\":{\"e\":\"bookTicker\",\"u\":11478212350278,\"s\":\"BTCUSDT\",\"ps\":\"BTCUSDT\",\"b\":\"79598.10\",\"B\":\"10.881\",\"a\":\"79598.20\",\"A\":\"3.170\",\"T\":1788563038547,\"E\":1788563038547,\"st\":1}}"}
{"receive_ns":1788563038490152000,"stream":"btcusdt@trade","event_type":"trade","event_time_ms":1788563038547,"raw_json":"{\"stream\":\"btcusdt@trade\",\"data\":{\"e\":\"trade\",\"E\":1788563038547,\"T\":1788563038547,\"s\":\"BTCUSDT\",\"t\":8054081705,\"p\":\"79598.20\",\"q\":\"0.003\",\"X\":\"MARKET\",\"m\":false,\"st\":1}}"}
{"receive_ns":1788563038490362000,"stream":"btcusdt@bookTicker","event_type":"bookTicker","event_time_ms":1788563038548,"raw_json":"{\"stream\":\"btcusdt@bookTicker\",\"data\":{\"e\":\"bookTicker\",\"u\":11478212350370,\"s\":\"BTCUSDT\",\"ps\":\"BTCUSDT\",\"b\":\"79598.10\",\"B\":\"10.889\",\"a\":\"79598.20\",\"A\":\"3.170\",\"T\":1788563038548,\"E\":1788563038548,\"st\":1}}"}
{"receive_ns":1788563038490679000,"stream":"btcusdt@bookTicker","event_type":"bookTicker","event_time_ms":1788563038549,"raw_json":"{\"stream\":\"btcusdt@bookTicker\",\"data\":{\"e\":\"bookTicker\",\"u\":11478212350451,\"s\":\"BTCUSDT\",\"ps\":\"BTCUSDT\",\"b\":\"79598.10\",\"B\":\"10.889\",\"a\":\"79598.20\",\"A\":\"3.163\",\"T\":1788563038549,\"E\":1788563038549,\"st\":1}}"}
{"receive_ns":1788563038490873000,"stream":"btcusdt@bookTicker","event_type":"bookTicker","event_time_ms":1788563038549,"raw_json":"{\"stream\":\"btcusdt@bookTicker\",\"data\":{\"e\":\"bookTicker\",\"u\":11478212350454,\"s\":\"BTCUSDT\",\"ps\":\"BTCUSDT\",\"b\":\"79598.10\",\"B\":\"10.881\",\"a\":\"79598.20\",\"A\":\"3.163\",\"T\":1788563038549,\"E\":1788563038549,\"st\":1}}"}
{"receive_ns":1788563038525318000,"stream":"btcusdt@bookTicker","event_type":"bookTicker","event_time_ms":1788563038589,"raw_json":"{\"stream\":\"btcusdt@bookTicker\",\"data\":{\"e\":\"bookTicker\",\"u\":11478212351657,\"s\":\"BTCUSDT\",\"ps\":\"BTCUSDT\",\"b\":\"79598.10\",\"B\":\"10.881\",\"a\":\"79598.20\",\"A\":\"3.160\",\"T\":1788563038589,\"E\":1788563038589,\"st\":1}}"}
{"receive_ns":1788563038543171000,"stream":"btcusdt@bookTicker","event_type":"bookTicker","event_time_ms":1788563038598,"raw_json":"{\"stream\":\"btcusdt@bookTicker\",\"data\":{\"e\":\"bookTicker\",\"u\":11478212351969,\"s\":\"BTCUSDT\",\"ps\":\"BTCUSDT\",\"b\":\"79598.10\",\"B\":\"10.881\",\"a\":\"79598.20\",\"A\":\"3.161\",\"T\":1788563038598,\"E\":1788563038598,\"st\":1}}"}
{"receive_ns":1788563038546757000,"stream":"btcusdt@bookTicker","event_type":"bookTicker","event_time_ms":1788563038611,"raw_json":"{\"stream\":\"btcusdt@bookTicker\",\"data\":{\"e\":\"bookTicker\",\"u\":11478212352461,\"s\":\"BTCUSDT\",\"ps\":\"BTCUSDT\",\"b\":\"79598.10\",\"B\":\"10.881\",\"a\":\"79598.20\",\"A\":\"3.160\",\"T\":1788563038611,\"E\":1788563038611,\"st\":1}}"}
{"receive_ns":1788563038560340000,"stream":"btcusdt@depth@100ms","event_type":"depthUpdate","event_time_ms":1788563038625,"raw_json":"{\"stream\":\"btcusdt@depth@100ms\",\"data\":{\"e\":\"depthUpdate\",\"E\":1788563038625,\"T\":1788563038623,\"s\":\"BTCUSDT\",\"ps\":\"BTCUSDT\",\"U\":11478212349361,\"u\":11478212352892,\"pu\":11478212349290,\"b\":[[\"29098.10\",\"1.218\"],[\"29498.10\",\"0.882\"],[\"63678.50\",\"0.000\"],[\"63679.00\",\"0.003\"],[\"71638.20\",\"0.002\"],[\"76414.10\",\"0.000\"],[\"78802.10\",\"2.042\"],[\"79226.00\",\"0.256\"],[\"79401.10\",\"0.000\"],[\"79418.70\",\"4.056\"],[\"79419.80\",\"0.003\"],[\"79440.90\",\"2.436\"],[\"79447.50\",\"0.000\"],[\"79454.20\",\"2.512\"],[\"79496.20\",\"0.039\"],[\"79512.00\",\"0.085\"],[\"79512.20\",\"0.006\"],[\"79574.40\",\"0.050\"],[\"79598.10\",\"10.881\"]],\"a\":[[\"79598.20\",\"3.160\"],[\"79601.30\",\"0.044\"],[\"79602.10\",\"0.279\"],[\"79608.10\",\"0.352\"],[\"79614.30\",\"0.361\"],[\"79632.40\",\"0.200\"],[\"79687.20\",\"1.549\"],[\"79687.60\",\"2.907\"],[\"79715.90\",\"0.000\"],[\"79723.00\",\"2.070\"],[\"79740.00\",\"0.500\"],[\"79740.10\",\"0.001\"],[\"79740.30\",\"0.290\"],[\"79744.90\",\"17.556\"],[\"79745.40\",\"3.145\"],[\"79996.20\",\"1.865\"],[\"80394.20\",\"4.236\"]],\"st\":1}}"}
{"receive_ns":1788563038652860000,"stream":"btcusdt@bookTicker","event_type":"bookTicker","event_time_ms":1788563038718,"raw_json":"{\"stream\":\"btcusdt@bookTicker\",\"data\":{\"e\":\"bookTicker\",\"u\":11478212356066,\"s\":\"BTCUSDT\",\"ps\":\"BTCUSDT\",\"b\":\"79598.10\",\"B\":\"10.889\",\"a\":\"79598.20\",\"A\":\"3.160\",\"T\":1788563038718,\"E\":1788563038718,\"st\":1}}"}
{"receive_ns":1788563038653128000,"stream":"btcusdt@bookTicker","event_type":"bookTicker","event_time_ms":1788563038718,"raw_json":"{\"stream\":\"btcusdt@bookTicker\",\"data\":{\"e\":\"bookTicker\",\"u\":11478212356135,\"s\":\"BTCUSDT\",\"ps\":\"BTCUSDT\",\"b\":\"79598.10\",\"B\":\"10.881\",\"a\":\"79598.20\",\"A\":\"3.160\",\"T\":1788563038718,\"E\":1788563038718,\"st\":1}}"}
{"receive_ns":1788563038662829000,"stream":"btcusdt@depth@100ms","event_type":"depthUpdate","event_time_ms":1788563038727,"raw_json":"{\"stream\":\"btcusdt@depth@100ms\",\"data\":{\"e\":\"depthUpdate\",\"E\":1788563038727,\"T\":1788563038726,\"s\":\"BTCUSDT\",\"ps\":\"BTCUSDT\",\"U\":11478212352952,\"u\":11478212356675,\"pu\":11478212352892,\"b\":[[\"1000.00\",\"24.604\"],[\"29098.10\",\"1.036\"],[\"29498.10\",\"1.064\"],[\"63679.00\",\"0.000\"],[\"71638.20\",\"0.002\"],[\"78300.00\",\"140.593\"],[\"78802.10\",\"2.042\"],[\"79200.10\",\"0.154\"],[\"79440.90\",\"2.436\"],[\"79441.80\",\"0.001\"],[\"79442.90\",\"0.000\"],[\"79592.20\",\"0.008\"],[\"79598.10\",\"10.881\"]],\"a\":[[\"79598.60\",\"0.000\"],[\"79601.30\",\"0.018\"],[\"79601.40\",\"0.000\"],[\"79602.20\",\"0.280\"],[\"79603.10\",\"0.000\"],[\"79604.10\",\"0.329\"],[\"79735.20\",\"0.008\"],[\"79740.00\",\"0.500\"],[\"79740.10\",\"0.001\"],[\"79740.30\",\"0.165\"],[\"79740.50\",\"0.000\"],[\"79740.60\",\"0.361\"],[\"79740.70\",\"0.142\"],[\"79748.90\",\"0.002\"],[\"79958.40\",\"0.020\"],[\"79996.20\",\"1.865\"],[\"80394.20\",\"4.236\"],[\"80633.00\",\"0.326\"],[\"80692.80\",\"6.187\"]],\"st\":1}}"}
{"receive_ns":1788563038695680000,"stream":"btcusdt@bookTicker","event_type":"bookTicker","event_time_ms":1788563038760,"raw_json":"{\"stream\":\"btcusdt@bookTicker\",\"data\":{\"e\":\"bookTicker\",\"u\":11478212359198,\"s\":\"BTCUSDT\",\"ps\":\"BTCUSDT\",\"b\":\"79598.10\",\"B\":\"10.881\",\"a\":\"79598.20\",\"A\":\"3.167\",\"T\":1788563038760,\"E\":1788563038760,\"st\":1}}"}
{"receive_ns":1788563038754899000,"stream":"btcusdt@bookTicker","event_type":"bookTicker","event_time_ms":1788563038819,"raw_json":"{\"stream\":\"btcusdt@bookTicker\",\"data\":{\"e\":\"bookTicker\",\"u\":11478212361368,\"s\":\"BTCUSDT\",\"ps\":\"BTCUSDT\",\"b\":\"79598.10\",\"B\":\"10.881\",\"a\":\"79598.20\",\"A\":\"3.166\",\"T\":1788563038819,\"E\":1788563038819,\"st\":1}}"}
{"receive_ns":1788563038761553000,"stream":"btcusdt@bookTicker","event_type":"bookTicker","event_time_ms":1788563038825,"raw_json":"{\"stream\":\"btcusdt@bookTicker\",\"data\":{\"e\":\"bookTicker\",\"u\":11478212361624,\"s\":\"BTCUSDT\",\"ps\":\"BTCUSDT\",\"b\":\"79598.10\",\"B\":\"10.881\",\"a\":\"79598.20\",\"A\":\"3.169\",\"T\":1788563038825,\"E\":1788563038825,\"st\":1}}"}
{"receive_ns":1788563038764573000,"stream":"btcusdt@depth@100ms","event_type":"depthUpdate","event_time_ms":1788563038829,"raw_json":"{\"stream\":\"btcusdt@depth@100ms\",\"data\":{\"e\":\"depthUpdate\",\"E\":1788563038829,\"T\":1788563038827,\"s\":\"BTCUSDT\",\"ps\":\"BTCUSDT\",\"U\":11478212356733,\"u\":11478212361695,\"pu\":11478212356675,\"b\":[[\"1000.00\",\"24.604\"],[\"29098.10\",\"0.861\"],[\"29498.10\",\"1.239\"],[\"71638.20\",\"0.002\"],[\"76414.10\",\"0.002\"],[\"77584.00\",\"0.386\"],[\"77976.60\",\"0.565\"],[\"78578.60\",\"9.527\"],[\"78681.90\",\"6.147\"],[\"78802.10\",\"2.042\"],[\"79200.10\",\"0.153\"],[\"79226.00\",\"0.256\"],[\"79440.90\",\"2.436\"],[\"79441.80\",\"0.202\"],[\"79442.90\",\"0.502\"],[\"79592.20\",\"0.008\"]],\"a\":[[\"79598.20\",\"3.169\"],[\"79602.10\",\"0.279\"],[\"79602.20\",\"0.370\"],[\"79603.10\",\"0.200\"],[\"79604.10\",\"0.329\"],[\"79608.10\",\"0.262\"],[\"79704.40\",\"0.024\"],[\"79740.30\",\"0.290\"],[\"79740.60\",\"0.361\"],[\"79740.70\",\"0.017\"],[\"79749.80\",\"11.420\"],[\"79958.40\",\"0.439\"],[\"79996.20\",\"1.866\"],[\"80215.50\",\"0.249\"],[\"80394.20\",\"4.236\"],[\"80593.50\",\"0.000\"]],\"st\":1}}"}
{"receive_ns":1788563038769238000,"stream":"btcusdt@bookTicker","event_type":"bookTicker","event_time_ms":1788563038835,"raw_json":"{\"stream\":\"btcusdt@bookTicker\",\"data\":{\"e\":\"bookTicker\",\"u\":11478212362243,\"s\":\"BTCUSDT\",\"ps\":\"BTCUSDT\",\"b\":\"79598.10\",\"B\":\"10.881\",\"a\":\"79598.20\",\"A\":\"3.170\",\"T\":1788563038835,\"E\":1788563038835,\"st\":1}}"}
{"receive_ns":1788563038842501000,"stream":"btcusdt@bookTicker","event_type":"bookTicker","event_time_ms":1788563038904,"raw_json":"{\"stream\":\"btcusdt@bookTicker\",\"data\":{\"e\":\"bookTicker\",\"u\":11478212364422,\"s\":\"BTCUSDT\",\"ps\":\"BTCUSDT\",\"b\":\"79598.10\",\"B\":\"10.889\",\"a\":\"79598.20\",\"A\":\"3.170\",\"T\":1788563038904,\"E\":1788563038904,\"st\":1}}"}
{"receive_ns":1788563038842843000,"stream":"btcusdt@bookTicker","event_type":"bookTicker","event_time_ms":1788563038905,"raw_json":"{\"stream\":\"btcusdt@bookTicker\",\"data\":{\"e\":\"bookTicker\",\"u\":11478212364461,\"s\":\"BTCUSDT\",\"ps\":\"BTCUSDT\",\"b\":\"79598.10\",\"B\":\"10.881\",\"a\":\"79598.20\",\"A\":\"3.170\",\"T\":1788563038905,\"E\":1788563038905,\"st\":1}}"}
{"receive_ns":1788563038865846000,"stream":"btcusdt@depth@100ms","event_type":"depthUpdate","event_time_ms":1788563038931,"raw_json":"{\"stream\":\"btcusdt@depth@100ms\",\"data\":{\"e\":\"depthUpdate\",\"E\":1788563038931,\"T\":1788563038929,\"s\":\"BTCUSDT\",\"ps\":\"BTCUSDT\",\"U\":11478212361783,\"u\":11478212365320,\"pu\":11478212361695,\"b\":[[\"29098.10\",\"0.679\"],[\"29498.10\",\"1.421\"],[\"63679.00\",\"0.000\"],[\"71638.20\",\"0.002\"],[\"76414.10\",\"0.000\"],[\"78802.10\",\"2.042\"],[\"79517.20\",\"0.000\"],[\"79583.40\",\"0.020\"],[\"79584.10\",\"0.127\"],[\"79589.40\",\"0.006\"],[\"79592.20\",\"0.004\"],[\"79598.10\",\"10.881\"]],\"a\":[[\"79598.20\",\"3.170\"],[\"79599.50\",\"0.000\"],[\"79601.20\",\"0.027\"],[\"79605.10\",\"0.002\"],[\"79611.20\",\"0.230\"],[\"79611.70\",\"0.065\"],[\"79740.30\",\"0.165\"],[\"79740.40\",\"0.000\"],[\"79756.20\",\"0.002\"],[\"80394.20\",\"4.236\"],[\"80533.80\",\"2.852\"],[\"80712.60\",\"15.219\"],[\"80714.80\",\"8.091\"]],\"st\":1}}"}
{"receive_ns":1788563038967053000,"stream":"btcusdt@depth@100ms","event_type":"depthUpdate","event_time_ms":1788563039033,"raw_json":"{\"stream\":\"btcusdt@depth@100ms\",\"data\":{\"e\":\"depthUpdate\",\"E\":1788563039033,\"T\":1788563039032,\"s\":\"BTCUSDT\",\"ps\":\"BTCUSDT\",\"U\":11478212365384,\"u\":11478212368618,\"pu\":11478212365320,\"b\":[[\"1000.00\",\"24.604\"],[\"29098.10\",\"0.504\"],[\"29498.10\",\"1.596\"],[\"63679.00\",\"0.000\"],[\"71638.20\",\"0.002\"],[\"76414.10\",\"0.002\"],[\"78563.30\",\"2.002\"],[\"78585.80\",\"0.000\"],[\"78588.20\",\"0.006\"],[\"78602.10\",\"0.000\"],[\"78604.50\",\"0.010\"],[\"78802.10\",\"2.042\"],[\"78881.70\",\"1.900\"],[\"79200.10\",\"0.153\"],[\"79226.00\",\"0.024\"],[\"79440.90\",\"1.005\"],[\"79441.80\",\"0.202\"],[\"79442.90\",\"0.502\"],[\"79583.80\",\"0.004\"]],\"a\":[[\"79602.10\",\"0.028\"],[\"79602.20\",\"0.280\"],[\"79603.10\",\"0.200\"],[\"79958.40\",\"0.439\"],[\"79996.20\",\"0.902\"],[\"80394.20\",\"4.236\"],[\"81190.10\",\"0.023\"],[\"83333.00\",\"6.547\"]],\"st\":1}}"}
{"receive_ns":1788563039069595000,"stream":"btcusdt@depth@100ms","event_type":"depthUpdate","event_time_ms":1788563039135,"raw_json":"{\"stream\":\"btcusdt@depth@100ms\",\"data\":{\"e\":\"depthUpdate\",\"E\":1788563039135,\"T\":1788563039134,\"s\":\"BTCUSDT\",\"ps\":\"BTCUSDT\",\"U\":11478212368697,\"u\":11478212372105,\"pu\":11478212368618,\"b\":[[\"1000.00\",\"24.604\"],[\"29098.10\",\"0.329\"],[\"29398.10\",\"0.007\"],[\"29498.10\",\"1.764\"],[\"63679.00\",\"0.000\"],[\"71638.20\",\"0.002\"],[\"76414.10\",\"0.000\"],[\"78469.10\",\"0.001\"],[\"78631.80\",\"0.635\"],[\"78801.50\",\"0.897\"],[\"78802.10\",\"2.042\"],[\"79200.10\",\"0.152\"],[\"79226.00\",\"0.256\"],[\"79440.90\",\"2.436\"],[\"79558.30\",\"0.080\"],[\"79583.80\",\"0.000\"]],\"a\":[[\"79601.20\",\"0.001\"],[\"79602.10\",\"0.279\"],[\"79608.10\",\"0.352\"],[\"79611.10\",\"1.034\"],[\"79611.70\",\"0.003\"],[\"79638.00\",\"0.006\"],[\"79705.20\",\"0.006\"],[\"79740.10\",\"0.001\"],[\"79740.30\",\"0.290\"],[\"79996.20\",\"1.866\"],[\"80394.20\",\"4.236\"]],\"st\":1}}"}
{"receive_ns":1788563039069888000,"stream":"btcusdt@bookTicker","event_type":"bookTicker","event_time_ms":1788563039135,"raw_json":"{\"stream\":\"btcusdt@bookTicker\",\"data\":{\"e\":\"bookTicker\",\"u\":11478212372137,\"s\":\"BTCUSDT\",\"ps\":\"BTCUSDT\",\"b\":\"79598.10\",\"B\":\"10.881\",\"a\":\"79598.20\",\"A\":\"3.167\",\"T\":1788563039135,\"E\":1788563039135,\"st\":1}}"}
{"receive_ns":1788563039072971000,"stream":"btcusdt@bookTicker","event_type":"bookTicker","event_time_ms":1788563039137,"raw_json":"{\"stream\":\"btcusdt@bookTicker\",\"data\":{\"e\":\"bookTicker\",\"u\":11478212372238,\"s\":\"BTCUSDT\",\"ps\":\"BTCUSDT\",\"b\":\"79598.10\",\"B\":\"10.881\",\"a\":\"79598.20\",\"A\":\"3.168\",\"T\":1788563039137,\"E\":1788563039137,\"st\":1}}"}
{"receive_ns":1788563039117361000,"stream":"btcusdt@bookTicker","event_type":"bookTicker","event_time_ms":1788563039181,"raw_json":"{\"stream\":\"btcusdt@bookTicker\",\"data\":{\"e\":\"bookTicker\",\"u\":11478212373894,\"s\":\"BTCUSDT\",\"ps\":\"BTCUSDT\",\"b\":\"79598.10\",\"B\":\"10.856\",\"a\":\"79598.20\",\"A\":\"3.168\",\"T\":1788563039181,\"E\":1788563039181,\"st\":1}}"}
{"receive_ns":1788563039119667000,"stream":"btcusdt@bookTicker","event_type":"bookTicker","event_time_ms":1788563039184,"raw_json":"{\"stream\":\"btcusdt@bookTicker\",\"data\":{\"e\":\"bookTicker\",\"u\":11478212374079,\"s\":\"BTCUSDT\",\"ps\":\"BTCUSDT\",\"b\":\"79598.10\",\"B\":\"10.880\",\"a\":\"79598.20\",\"A\":\"3.168\",\"T\":1788563039183,\"E\":1788563039184,\"st\":1}}"}
{"receive_ns":1788563039125282000,"stream":"btcusdt@bookTicker","event_type":"bookTicker","event_time_ms":1788563039190,"raw_json":"{\"stream\":\"btcusdt@bookTicker\",\"data\":{\"e\":\"bookTicker\",\"u\":11478212374560,\"s\":\"BTCUSDT\",\"ps\":\"BTCUSDT\",\"b\":\"79598.10\",\"B\":\"10.881\",\"a\":\"79598.20\",\"A\":\"3.168\",\"T\":1788563039190,\"E\":1788563039190,\"st\":1}}"}
{"receive_ns":1788563039181161000,"stream":"btcusdt@depth@100ms","event_type":"depthUpdate","event_time_ms":1788563039237,"raw_json":"{\"stream\":\"btcusdt@depth@100ms\",\"data\":{\"e\":\"depthUpdate\",\"E\":1788563039237,\"T\":1788563039234,\"s\":\"BTCUSDT\",\"ps\":\"BTCUSDT\",\"U\":11478212372137,\"u\":11478212375865,\"pu\":11478212372105,\"b\":[[\"29098.10\",\"0.217\"],[\"29398.10\",\"0.070\"],[\"29498.10\",\"1.813\"],[\"71638.20\",\"0.002\"],[\"71675.00\",\"0.002\"],[\"78562.70\",\"0.890\"],[\"78801.60\",\"1.332\"],[\"78802.10\",\"2.042\"],[\"78834.80\",\"3.240\"],[\"78888.10\",\"0.648\"],[\"79000.10\",\"0.212\"],[\"79048.30\",\"0.000\"],[\"79048.40\",\"0.004\"],[\"79200.10\",\"0.654\"],[\"79222.80\",\"0.001\"],[\"79222.90\",\"0.000\"],[\"79223.80\",\"0.783\"],[\"79342.00\",\"0.004\"],[\"79343.30\",\"0.456\"],[\"79383.30\",\"0.001\"],[\"79440.90\",\"2.436\"],[\"79441.80\",\"0.001\"],[\"79442.90\",\"0.000\"],[\"79578.90\",\"0.003\"],[\"79579.60\",\"0.631\"],[\"79587.30\",\"0.530\"],[\"79592.20\",\"0.004\"],[\"79595.20\",\"0.077\"],[\"79598.10\",\"10.881\"]],\"a\":[[\"79598.20\",\"3.168\"],[\"79600.70\",\"0.017\"],[\"79600.90\",\"0.106\"],[\"79601.20\",\"0.027\"],[\"79601.30\",\"0.044\"],[\"79602.20\",\"0.280\"],[\"79603.10\",\"0.000\"],[\"79603.30\",\"0.000\"],[\"79603.50\",\"0.004\"],[\"79604.10\",\"0.329\"],[\"79653.40\",\"0.079\"],[\"79653.50\",\"0.000\"],[\"79698.70\",\"0.000\"],[\"79740.30\",\"0.290\"],[\"79840.80\",\"1.055\"],[\"79840.90\",\"0.001\"],[\"79958.40\",\"0.020\"],[\"79960.00\",\"0.269\"],[\"79960.80\",\"0.000\"],[\"79960.90\",\"0.006\"],[\"79986.20\",\"0.421\"],[\"79996.20\",\"1.867\"],[\"79999.90\",\"10.724\"],[\"80099.90\",\"10.442\"],[\"80137.00\",\"0.000\"],[\"80394.20\",\"4.236\"],[\"80951.40\",\"1.042\"],[\"81186.10\",\"0.003\"],[\"81190.10\",\"0.017\"]],\"st\":1}}"}
{"receive_ns":1788563039263857000,"stream":"btcusdt@bookTicker","event_type":"bookTicker","event_time_ms":1788563039326,"raw_json":"{\"stream\":\"btcusdt@bookTicker\",\"data\":{\"e\":\"bookTicker\",\"u\":11478212378803,\"s\":\"BTCUSDT\",\"ps\":\"BTCUSDT\",\"b\":\"79598.10\",\"B\":\"10.875\",\"a\":\"79598.20\",\"A\":\"3.168\",\"T\":1788563039326,\"E\":1788563039326,\"st\":1}}"}
{"receive_ns":1788563039270856000,"stream":"btcusdt@bookTicker","event_type":"bookTicker","event_time_ms":1788563039336,"raw_json":"{\"stream\":\"btcusdt@bookTicker\",\"data\":{\"e\":\"bookTicker\",\"u\":11478212379089,\"s\":\"BTCUSDT\",\"ps\":\"BTCUSDT\",\"b\":\"79598.10\",\"B\":\"10.883\",\"a\":\"79598.20\",\"A\":\"3.168\",\"T\":1788563039335,\"E\":1788563039336,\"st\":1}}"}
{"receive_ns":1788563039279067000,"stream":"btcusdt@bookTicker","event_type":"bookTicker","event_time_ms":1788563039336,"raw_json":"{\"stream\":\"btcusdt@bookTicker\",\"data\":{\"e\":\"bookTicker\",\"u\":11478212379124,\"s\":\"BTCUSDT\",\"ps\":\"BTCUSDT\",\"b\":\"79598.10\",\"B\":\"10.875\",\"a\":\"79598.20\",\"A\":\"3.168\",\"T\":1788563039336,\"E\":1788563039336,\"st\":1}}"}
{"receive_ns":1788563039279588000,"stream":"btcusdt@depth@100ms","event_type":"depthUpdate","event_time_ms":1788563039339,"raw_json":"{\"stream\":\"btcusdt@depth@100ms\",\"data\":{\"e\":\"depthUpdate\",\"E\":1788563039339,\"T\":1788563039338,\"s\":\"BTCUSDT\",\"ps\":\"BTCUSDT\",\"U\":11478212375979,\"u\":11478212379182,\"pu\":11478212375865,\"b\":[[\"1000.00\",\"24.604\"],[\"29098.10\",\"0.091\"],[\"29398.10\",\"0.126\"],[\"29498.10\",\"1.883\"],[\"71638.20\",\"0.002\"],[\"76414.10\",\"0.002\"],[\"78517.70\",\"2.099\"],[\"78574.30\",\"0.000\"],[\"78802.10\",\"2.676\"],[\"78820.20\",\"0.090\"],[\"78834.70\",\"0.000\"],[\"79200.10\",\"0.986\"],[\"79201.00\",\"0.465\"],[\"79226.00\",\"0.024\"],[\"79440.90\",\"2.336\"],[\"79564.80\",\"0.002\"],[\"79577.80\",\"0.055\"],[\"79580.70\",\"0.000\"],[\"79592.20\",\"0.004\"],[\"79596.30\",\"0.076\"],[\"79598.10\",\"10.875\"]],\"a\":[[\"79599.70\",\"0.000\"],[\"79600.90\",\"0.080\"],[\"79601.20\",\"0.001\"],[\"79601.30\",\"0.018\"],[\"79601.80\",\"0.001\"],[\"79601.90\",\"0.002\"],[\"79602.00\",\"0.077\"],[\"79602.10\",\"0.253\"],[\"79602.20\",\"0.370\"],[\"79602.40\",\"0.027\"],[\"79602.50\",\"0.026\"],[\"79602.80\",\"0.026\"],[\"79602.90\",\"0.027\"],[\"79603.00\",\"0.026\"],[\"79603.10\",\"0.226\"],[\"79604.10\",\"0.329\"],[\"79608.10\",\"0.262\"],[\"79611.10\",\"0.972\"],[\"79611.20\",\"0.226\"],[\"79611.70\",\"0.069\"],[\"79960.00\",\"0.053\"],[\"79996.20\",\"1.867\"],[\"80353.60\",\"0.194\"],[\"80394.20\",\"4.237\"],[\"80618.90\",\"0.001\"],[\"80746.80\",\"2.636\"]],\"st\":1}}"}
{"receive_ns":1788563039368916000,"stream":"btcusdt@bookTicker","event_type":"bookTicker","event_time_ms":1788563039433,"raw_json":"{\"stream\":\"btcusdt@bookTicker\",\"data\":{\"e\":\"bookTicker\",\"u\":11478212381775,\"s\":\"BTCUSDT\",\"ps\":\"BTCUSDT\",\"b\":\"79598.10\",\"B\":\"10.875\",\"a\":\"79598.20\",\"A\":\"3.170\",\"T\":1788563039433,\"E\":1788563039433,\"st\":1}}"}
{"receive_ns":1788563039376113000,"stream":"btcusdt@depth@100ms","event_type":"depthUpdate","event_time_ms":1788563039441,"raw_json":"{\"stream\":\"btcusdt@depth@100ms\",\"data\":{\"e\":\"depthUpdate\",\"E\":1788563039441,\"T\":1788563039438,\"s\":\"BTCUSDT\",\"ps\":\"BTCUSDT\",\"U\":11478212379192,\"u\":11478212381993,\"pu\":11478212379182,\"b\":[[\"1000.00\",\"24.604\"],[\"29098.10\",\"0.000\"],[\"29398.10\",\"0.210\"],[\"29498.10\",\"1.890\"],[\"71638.20\",\"0.002\"],[\"75608.60\",\"0.071\"],[\"75608.70\",\"0.002\"],[\"76414.10\",\"0.000\"],[\"78324.50\",\"3.187\"],[\"78722.50\",\"2.537\"],[\"78802.10\",\"2.676\"],[\"79051.30\",\"57.280\"],[\"79200.10\",\"0.343\"],[\"79226.10\",\"44.710\"],[\"79345.50\",\"37.159\"],[\"79440.90\",\"1.331\"],[\"79542.30\",\"0.002\"],[\"79553.10\",\"0.085\"],[\"79568.00\",\"0.020\"]],\"a\":[[\"79598.20\",\"3.170\"],[\"79601.00\",\"0.008\"],[\"79602.20\",\"0.119\"],[\"79603.10\",\"0.026\"],[\"79605.90\",\"0.002\"],[\"79654.00\",\"0.002\"],[\"79847.10\",\"35.321\"],[\"79967.30\",\"45.103\"],[\"79986.20\",\"0.002\"],[\"79996.20\",\"1.341\"],[\"80143.70\",\"53.864\"],[\"80394.20\",\"4.235\"],[\"80979.10\",\"0.003\"]],\"st\":1}}"}
{"receive_ns":1788563039418704000,"stream":"btcusdt@bookTicker","event_type":"bookTicker","event_time_ms":1788563039480,"raw_json":"{\"stream\":\"btcusdt@bookTicker\",\"data\":{\"e\":\"bookTicker\",\"u\":11478212383527,\"s\":\"BTCUSDT\",\"ps\":\"BTCUSDT\",\"b\":\"79598.10\",\"B\":\"10.858\",\"a\":\"79598.20\",\"A\":\"3.170\",\"T\":1788563039480,\"E\":1788563039480,\"st\":1}}"}
{"receive_ns":1788563039418966000,"stream":"btcusdt@bookTicker","event_type":"bookTicker","event_time_ms":1788563039483,"raw_json":"{\"stream\":\"btcusdt@bookTicker\",\"data\":{\"e\":\"bookTicker\",\"u\":11478212383687,\"s\":\"BTCUSDT\",\"ps\":\"BTCUSDT\",\"b\":\"79598.10\",\"B\":\"10.884\",\"a\":\"79598.20\",\"A\":\"3.170\",\"T\":1788563039483,\"E\":1788563039483,\"st\":1}}"}
{"receive_ns":1788563039477730000,"stream":"btcusdt@depth@100ms","event_type":"depthUpdate","event_time_ms":1788563039543,"raw_json":"{\"stream\":\"btcusdt@depth@100ms\",\"data\":{\"e\":\"depthUpdate\",\"E\":1788563039543,\"T\":1788563039541,\"s\":\"BTCUSDT\",\"ps\":\"BTCUSDT\",\"U\":11478212382094,\"u\":11478212385800,\"pu\":11478212381993,\"b\":[[\"29398.10\",\"0.392\"],[\"29498.10\",\"1.708\"],[\"71638.20\",\"0.002\"],[\"76414.10\",\"0.002\"],[\"78006.20\",\"0.030\"],[\"78165.30\",\"1.716\"],[\"78801.60\",\"1.776\"],[\"78802.10\",\"2.676\"],[\"78818.00\",\"0.868\"],[\"79200.10\",\"0.152\"],[\"79201.00\",\"0.264\"],[\"79227.80\",\"7.613\"],[\"79345.60\",\"9.002\"],[\"79400.00\",\"4.755\"],[\"79401.10\",\"0.502\"],[\"79440.90\",\"2.336\"],[\"79473.80\",\"0.626\"],[\"79574.40\",\"0.048\"],[\"79598.10\",\"10.884\"]],\"a\":[[\"79602.10\",\"0.028\"],[\"79602.20\",\"0.280\"],[\"79603.10\",\"0.226\"],[\"79608.10\",\"0.681\"],[\"79614.30\",\"0.359\"],[\"79721.60\",\"0.001\"],[\"79723.10\",\"0.385\"],[\"79964.40\",\"0.765\"],[\"79996.20\",\"1.103\"],[\"80360.50\",\"67.626\"],[\"80394.20\",\"4.235\"],[\"80553.40\",\"13.259\"],[\"80626.10\",\"85.622\"],[\"80752.40\",\"4.330\"]],\"st\":1}}"}
{"receive_ns":1788563039484940000,"stream":"btcusdt@bookTicker","event_type":"bookTicker","event_time_ms":1788563039549,"raw_json":"{\"stream\":\"btcusdt@bookTicker\",\"data\":{\"e\":\"bookTicker\",\"u\":11478212386037,\"s\":\"BTCUSDT\",\"ps\":\"BTCUSDT\",\"b\":\"79598.10\",\"B\":\"10.863\",\"a\":\"79598.20\",\"A\":\"3.170\",\"T\":1788563039549,\"E\":1788563039549,\"st\":1}}"}
{"receive_ns":1788563039488683000,"stream":"btcusdt@bookTicker","event_type":"bookTicker","event_time_ms":1788563039552,"raw_json":"{\"stream\":\"btcusdt@bookTicker\",\"data\":{\"e\":\"bookTicker\",\"u\":11478212386177,\"s\":\"BTCUSDT\",\"ps\":\"BTCUSDT\",\"b\":\"79598.10\",\"B\":\"10.886\",\"a\":\"79598.20\",\"A\":\"3.170\",\"T\":1788563039552,\"E\":1788563039552,\"st\":1}}"}
{"receive_ns":1788563039501295000,"stream":"btcusdt@bookTicker","event_type":"bookTicker","event_time_ms":1788563039565,"raw_json":"{\"stream\":\"btcusdt@bookTicker\",\"data\":{\"e\":\"bookTicker\",\"u\":11478212386630,\"s\":\"BTCUSDT\",\"ps\":\"BTCUSDT\",\"b\":\"79598.10\",\"B\":\"10.886\",\"a\":\"79598.20\",\"A\":\"3.177\",\"T\":1788563039565,\"E\":1788563039565,\"st\":1}}"}
{"receive_ns":1788563039513481000,"stream":"btcusdt@bookTicker","event_type":"bookTicker","event_time_ms":1788563039576,"raw_json":"{\"stream\":\"btcusdt@bookTicker\",\"data\":{\"e\":\"bookTicker\",\"u\":11478212386950,\"s\":\"BTCUSDT\",\"ps\":\"BTCUSDT\",\"b\":\"79598.10\",\"B\":\"10.886\",\"a\":\"79598.20\",\"A\":\"3.176\",\"T\":1788563039576,\"E\":1788563039576,\"st\":1}}"}
{"receive_ns":1788563039515868000,"stream":"btcusdt@bookTicker","event_type":"bookTicker","event_time_ms":1788563039580,"raw_json":"{\"stream\":\"btcusdt@bookTicker\",\"data\":{\"e\":\"bookTicker\",\"u\":11478212387135,\"s\":\"BTCUSDT\",\"ps\":\"BTCUSDT\",\"b\":\"79598.10\",\"B\":\"10.886\",\"a\":\"79598.20\",\"A\":\"3.179\",\"T\":1788563039580,\"E\":1788563039580,\"st\":1}}"}
{"receive_ns":1788563039580833000,"stream":"btcusdt@depth@100ms","event_type":"depthUpdate","event_time_ms":1788563039645,"raw_json":"{\"stream\":\"btcusdt@depth@100ms\",\"data\":{\"e\":\"depthUpdate\",\"E\":1788563039645,\"T\":1788563039644,\"s\":\"BTCUSDT\",\"ps\":\"BTCUSDT\",\"U\":11478212385860,\"u\":11478212390658,\"pu\":11478212385800,\"b\":[[\"1000.00\",\"24.604\"],[\"29398.10\",\"0.567\"],[\"29498.10\",\"1.533\"],[\"63678.50\",\"0.000\"],[\"63679.00\",\"0.000\"],[\"71638.20\",\"0.002\"],[\"78006.20\",\"0.027\"],[\"78459.30\",\"25.834\"],[\"78663.60\",\"0.229\"],[\"78802.10\",\"2.676\"],[\"78812.30\",\"0.000\"],[\"78834.80\",\"0.000\"],[\"78888.10\",\"3.240\"],[\"79000.10\",\"0.050\"],[\"79051.40\",\"0.648\"],[\"79200.10\",\"0.142\"],[\"79226.20\",\"0.162\"],[\"79228.00\",\"0.245\"],[\"79400.60\",\"0.022\"],[\"79401.10\",\"0.602\"],[\"79406.20\",\"0.001\"],[\"79542.30\",\"0.000\"],[\"79558.30\",\"0.080\"],[\"79574.40\",\"0.050\"],[\"79598.10\",\"10.886\"]],\"a\":[[\"79598.20\",\"3.179\"],[\"79601.90\",\"0.028\"],[\"79602.10\",\"0.279\"],[\"79602.20\",\"0.370\"],[\"79611.70\",\"0.007\"],[\"79614.30\",\"0.361\"],[\"79620.20\",\"0.067\"],[\"79638.00\",\"0.006\"],[\"79673.90\",\"0.001\"],[\"79740.10\",\"0.126\"],[\"79740.30\",\"0.165\"],[\"79967.20\",\"0.648\"],[\"79999.90\",\"13.316\"],[\"80099.90\",\"7.202\"],[\"80394.20\",\"4.235\"],[\"80951.40\",\"1.536\"]],\"st\":1}}"}
{"receive_ns":1788563039623471000,"stream":"btcusdt@bookTicker","event_type":"bookTicker","event_time_ms":1788563039685,"raw_json":"{\"stream\":\"btcusdt@bookTicker\",\"data\":{\"e\":\"bookTicker\",\"u\":11478212392427,\"s\":\"BTCUSDT\",\"ps\":\"BTCUSDT\",\"b\":\"79598.10\",\"B\":\"10.886\",\"a\":\"79598.20\",\"A\":\"3.186\",\"T\":1788563039685,\"E\":1788563039685,\"st\":1}}"}
{"receive_ns":1788563039682799000,"stream":"btcusdt@depth@100ms","event_type":"depthUpdate","event_time_ms":1788563039747,"raw_json":"{\"stream\":\"btcusdt@depth@100ms\",\"data\":{\"e\":\"depthUpdate\",\"E\":1788563039747,\"T\":1788563039745,\"s\":\"BTCUSDT\",\"ps\":\"BTCUSDT\",\"U\":11478212390696,\"u\":11478212395031,\"pu\":11478212390658,\"b\":[[\"1000.00\",\"24.604\"],[\"29398.10\",\"0.749\"],[\"29498.10\",\"1.351\"],[\"71638.20\",\"0.002\"],[\"75618.20\",\"0.006\"],[\"75618.30\",\"0.004\"],[\"76414.10\",\"0.000\"],[\"78598.70\",\"5.900\"],[\"78603.10\",\"1.484\"],[\"78802.10\",\"2.676\"],[\"78837.40\",\"67.905\"],[\"78961.30\",\"1.012\"],[\"79200.10\",\"0.142\"],[\"79400.00\",\"4.755\"],[\"79401.10\",\"0.100\"],[\"79440.90\",\"1.507\"],[\"79473.80\",\"0.546\"],[\"79514.60\",\"0.029\"],[\"79553.20\",\"0.281\"],[\"79592.20\",\"0.053\"]],\"a\":[[\"79598.20\",\"3.186\"],[\"79602.20\",\"0.370\"],[\"79603.10\",\"0.026\"],[\"79604.10\",\"0.329\"],[\"79608.10\",\"0.262\"],[\"79611.70\",\"0.069\"],[\"79620.20\",\"0.005\"],[\"79723.10\",\"0.324\"],[\"79740.00\",\"0.500\"],[\"79740.10\",\"0.001\"],[\"79740.20\",\"0.002\"],[\"79740.30\",\"0.165\"],[\"79964.40\",\"0.420\"],[\"79996.20\",\"0.903\"],[\"80394.20\",\"4.235\"],[\"80587.30\",\"0.496\"],[\"80792.70\",\"0.556\"]],\"st\":1}}"}
{"receive_ns":1788563039738907000,"stream":"btcusdt@bookTicker","event_type":"bookTicker","event_time_ms":1788563039803,"raw_json":"{\"stream\":\"btcusdt@bookTicker\",\"data\":{\"e\":\"bookTicker\",\"u\":11478212397471,\"s\":\"BTCUSDT\",\"ps\":\"BTCUSDT\",\"b\":\"79598.10\",\"B\":\"10.886\",\"a\":\"79598.20\",\"A\":\"3.187\",\"T\":1788563039803,\"E\":1788563039803,\"st\":1}}"}
{"receive_ns":1788563039745861000,"stream":"btcusdt@bookTicker","event_type":"bookTicker","event_time_ms":1788563039809,"raw_json":"{\"stream\":\"btcusdt@bookTicker\",\"data\":{\"e\":\"bookTicker\",\"u\":11478212397725,\"s\":\"BTCUSDT\",\"ps\":\"BTCUSDT\",\"b\":\"79598.10\",\"B\":\"10.886\",\"a\":\"79598.20\",\"A\":\"3.184\",\"T\":1788563039809,\"E\":1788563039809,\"st\":1}}"}
{"receive_ns":1788563039783736000,"stream":"btcusdt@depth@100ms","event_type":"depthUpdate","event_time_ms":1788563039849,"raw_json":"{\"stream\":\"btcusdt@depth@100ms\",\"data\":{\"e\":\"depthUpdate\",\"E\":1788563039849,\"T\":1788563039848,\"s\":\"BTCUSDT\",\"ps\":\"BTCUSDT\",\"U\":11478212395086,\"u\":11478212399517,\"pu\":11478212395031,\"b\":[[\"29398.10\",\"0.924\"],[\"29498.10\",\"1.176\"],[\"71638.20\",\"0.002\"],[\"76414.10\",\"0.002\"],[\"78165.30\",\"2.354\"],[\"78802.10\",\"2.678\"],[\"79228.00\",\"0.245\"],[\"79258.20\",\"0.003\"],[\"79290.00\",\"0.065\"],[\"79303.50\",\"0.001\"],[\"79321.90\",\"0.222\"],[\"79335.40\",\"0.415\"],[\"79353.70\",\"0.000\"],[\"79367.20\",\"0.003\"],[\"79385.50\",\"0.000\"],[\"79399.00\",\"0.001\"],[\"79401.10\",\"0.100\"],[\"79440.90\",\"2.838\"],[\"79550.30\",\"0.055\"]],\"a\":[[\"79598.20\",\"3.184\"],[\"79601.90\",\"0.002\"],[\"79602.10\",\"0.253\"],[\"79602.20\",\"0.370\"],[\"79603.10\",\"0.226\"],[\"79699.30\",\"0.003\"],[\"79713.90\",\"0.000\"],[\"79739.70\",\"0.127\"],[\"79739.90\",\"0.000\"],[\"79740.00\",\"0.500\"],[\"79740.20\",\"0.002\"],[\"79740.30\",\"0.165\"],[\"79797.30\",\"0.001\"],[\"79812.20\",\"0.646\"],[\"79816.00\",\"0.501\"],[\"79822.10\",\"8.110\"],[\"79829.10\",\"0.004\"],[\"79860.90\",\"0.006\"],[\"79964.40\",\"1.184\"],[\"79996.20\",\"1.102\"],[\"80394.20\",\"4.235\"],[\"80587.30\",\"0.248\"]],\"st\":1}}"}
{"receive_ns":1788563039842728000,"stream":"btcusdt@bookTicker","event_type":"bookTicker","event_time_ms":1788563039907,"raw_json":"{\"stream\":\"btcusdt@bookTicker\",\"data\":{\"e\":\"bookTicker\",\"u\":11478212401658,\"s\":\"BTCUSDT\",\"ps\":\"BTCUSDT\",\"b\":\"79598.10\",\"B\":\"10.886\",\"a\":\"79598.20\",\"A\":\"3.183\",\"T\":1788563039907,\"E\":1788563039907,\"st\":1}}"}
{"receive_ns":1788563039842925000,"stream":"btcusdt@trade","event_type":"trade","event_time_ms":1788563039907,"raw_json":"{\"stream\":\"btcusdt@trade\",\"data\":{\"e\":\"trade\",\"E\":1788563039907,\"T\":1788563039907,\"s\":\"BTCUSDT\",\"t\":8054081706,\"p\":\"79598.20\",\"q\":\"0.001\",\"X\":\"MARKET\",\"m\":false,\"st\":1}}"}
{"receive_ns":1788563039843142000,"stream":"btcusdt@bookTicker","event_type":"bookTicker","event_time_ms":1788563039908,"raw_json":"{\"stream\":\"btcusdt@bookTicker\",\"data\":{\"e\":\"bookTicker\",\"u\":11478212401743,\"s\":\"BTCUSDT\",\"ps\":\"BTCUSDT\",\"b\":\"79598.10\",\"B\":\"10.894\",\"a\":\"79598.20\",\"A\":\"3.183\",\"T\":1788563039908,\"E\":1788563039908,\"st\":1}}"}
{"receive_ns":1788563039843423000,"stream":"btcusdt@bookTicker","event_type":"bookTicker","event_time_ms":1788563039909,"raw_json":"{\"stream\":\"btcusdt@bookTicker\",\"data\":{\"e\":\"bookTicker\",\"u\":11478212401826,\"s\":\"BTCUSDT\",\"ps\":\"BTCUSDT\",\"b\":\"79598.10\",\"B\":\"10.886\",\"a\":\"79598.20\",\"A\":\"3.183\",\"T\":1788563039909,\"E\":1788563039909,\"st\":1}}"}
{"receive_ns":1788563039886345000,"stream":"btcusdt@depth@100ms","event_type":"depthUpdate","event_time_ms":1788563039951,"raw_json":"{\"stream\":\"btcusdt@depth@100ms\",\"data\":{\"e\":\"depthUpdate\",\"E\":1788563039951,\"T\":1788563039949,\"s\":\"BTCUSDT\",\"ps\":\"BTCUSDT\",\"U\":11478212399574,\"u\":11478212403074,\"pu\":11478212399517,\"b\":[[\"1000.00\",\"24.604\"],[\"29398.10\",\"1.106\"],[\"29498.10\",\"0.994\"],[\"71638.20\",\"0.002\"],[\"76414.10\",\"0.000\"],[\"78464.70\",\"3.438\"],[\"78802.10\",\"2.676\"],[\"78810.10\",\"0.569\"],[\"79200.10\",\"0.002\"],[\"79271.70\",\"0.001\"],[\"79440.90\",\"1.833\"],[\"79473.80\",\"0.032\"],[\"79569.60\",\"0.009\"],[\"79587.30\",\"0.529\"],[\"79592.20\",\"0.053\"],[\"79598.10\",\"10.886\"]],\"a\":[[\"79598.20\",\"3.183\"],[\"79602.20\",\"0.119\"],[\"79604.10\",\"0.329\"],[\"79667.60\",\"0.000\"],[\"79723.10\",\"0.000\"],[\"79739.70\",\"0.002\"],[\"79740.20\",\"0.002\"],[\"79740.30\",\"0.165\"],[\"79740.40\",\"0.000\"],[\"79832.00\",\"0.035\"],[\"79834.40\",\"0.000\"],[\"79892.80\",\"0.198\"],[\"79924.60\",\"0.016\"],[\"79996.20\",\"0.576\"],[\"80394.20\",\"4.235\"],[\"80728.50\",\"0.307\"],[\"80826.40\",\"0.000\"]],\"st\":1}}"}
{"receive_ns":1788563039937256000,"stream":"btcusdt@bookTicker","event_type":"bookTicker","event_time_ms":1788563040002,"raw_json":"{\"stream\":\"btcusdt@bookTicker\",\"data\":{\"e\":\"bookTicker\",\"u\":11478212404817,\"s\":\"BTCUSDT\",\"ps\":\"BTCUSDT\",\"b\":\"79598.10\",\"B\":\"10.886\",\"a\":\"79598.20\",\"A\":\"3.185\",\"T\":1788563040001,\"E\":1788563040002,\"st\":1}}"}
{"receive_ns":1788563039941811000,"stream":"btcusdt@bookTicker","event_type":"bookTicker","event_time_ms":1788563040006,"raw_json":"{\"stream\":\"btcusdt@bookTicker\",\"data\":{\"e\":\"bookTicker\",\"u\":11478212405761,\"s\":\"BTCUSDT\",\"ps\":\"BTCUSDT\",\"b\":\"79598.10\",\"B\":\"10.889\",\"a\":\"79598.20\",\"A\":\"3.185\",\"T\":1788563040006,\"E\":1788563040006,\"st\":1}}"}
{"receive_ns":1788563039979722000,"stream":"btcusdt@bookTicker","event_type":"bookTicker","event_time_ms":1788563040044,"raw_json":"{\"stream\":\"btcusdt@bookTicker\",\"data\":{\"e\":\"bookTicker\",\"u\":11478212408878,\"s\":\"BTCUSDT\",\"ps\":\"BTCUSDT\",\"b\":\"79598.10\",\"B\":\"10.889\",\"a\":\"79598.20\",\"A\":\"3.184\",\"T\":1788563040044,\"E\":1788563040044,\"st\":1}}"}
{"receive_ns":1788563039980050000,"stream":"btcusdt@bookTicker","event_type":"bookTicker","event_time_ms":1788563040046,"raw_json":"{\"stream\":\"btcusdt@bookTicker\",\"data\":{\"e\":\"bookTicker\",\"u\":11478212409019,\"s\":\"BTCUSDT\",\"ps\":\"BTCUSDT\",\"b\":\"79598.10\",\"B\":\"10.894\",\"a\":\"79598.20\",\"A\":\"3.184\",\"T\":1788563040045,\"E\":1788563040046,\"st\":1}}"}
{"receive_ns":1788563039990628000,"stream":"btcusdt@bookTicker","event_type":"bookTicker","event_time_ms":1788563040051,"raw_json":"{\"stream\":\"btcusdt@bookTicker\",\"data\":{\"e\":\"bookTicker\",\"u\":11478212409653,\"s\":\"BTCUSDT\",\"ps\":\"BTCUSDT\",\"b\":\"79598.10\",\"B\":\"10.894\",\"a\":\"79598.20\",\"A\":\"3.187\",\"T\":1788563040050,\"E\":1788563040051,\"st\":1}}"}
{"receive_ns":1788563039991366000,"stream":"btcusdt@depth@100ms","event_type":"depthUpdate","event_time_ms":1788563040053,"raw_json":"{\"stream\":\"btcusdt@depth@100ms\",\"data\":{\"e\":\"depthUpdate\",\"E\":1788563040053,\"T\":1788563040052,\"s\":\"BTCUSDT\",\"ps\":\"BTCUSDT\",\"U\":11478212403151,\"u\":11478212409806,\"pu\":11478212403074,\"b\":[[\"1000.00\",\"24.604\"],[\"29398.10\",\"1.281\"],[\"29498.10\",\"0.819\"],[\"63679.00\",\"0.000\"],[\"71638.20\",\"0.002\"],[\"76414.10\",\"0.002\"],[\"78562.80\",\"0.445\"],[\"78588.20\",\"0.002\"],[\"78590.60\",\"0.017\"],[\"78604.50\",\"0.005\"],[\"78606.90\",\"0.004\"],[\"78642.90\",\"6.642\"],[\"78802.10\",\"2.678\"],[\"78837.50\",\"9.559\"],[\"79200.10\",\"0.143\"],[\"79228.00\",\"0.245\"],[\"79400.00\",\"4.755\"],[\"79401.10\",\"0.100\"],[\"79434.40\",\"2.558\"],[\"79440.90\",\"2.838\"],[\"79473.80\",\"0.608\"],[\"79562.50\",\"0.002\"],[\"79564.40\",\"0.047\"],[\"79565.50\",\"0.832\"],[\"79566.70\",\"0.013\"],[\"79570.50\",\"0.253\"],[\"79572.40\",\"0.254\"],[\"79573.10\",\"2.064\"],[\"79573.50\",\"0.020\"],[\"79573.60\",\"0.373\"],[\"79575.40\",\"0.629\"],[\"79577.60\",\"0.000\"],[\"79579.40\",\"0.628\"],[\"79580.30\",\"0.018\"],[\"79583.00\",\"0.002\"],[\"79583.40\",\"0.648\"],[\"79583.50\",\"0.320\"],[\"79583.60\",\"0.002\"],[\"79583.80\",\"0.004\"],[\"79585.70\",\"0.004\"],[\"79589.40\",\"0.002\"],[\"79589.50\",\"0.005\"],[\"79592.20\",\"0.053\"],[\"79594.10\",\"0.077\"],[\"79594.20\",\"0.377\"],[\"79598.10\",\"10.894\"]],\"a\":[[\"79598.20\",\"3.187\"],[\"79600.80\",\"0.001\"],[\"79602.00\",\"0.103\"],[\"79602.10\",\"0.253\"],[\"79602.20\",\"0.370\"],[\"79603.10\",\"0.226\"],[\"79604.10\",\"0.329\"],[\"79606.30\",\"0.342\"],[\"79606.70\",\"0.002\"],[\"79607.90\",\"0.000\"],[\"79610.20\",\"0.445\"],[\"79610.60\",\"0.001\"],[\"79611.10\",\"1.351\"],[\"79611.30\",\"0.435\"],[\"79611.70\",\"0.003\"],[\"79613.70\",\"0.372\"],[\"79614.60\",\"0.001\"],[\"79616.10\",\"0.460\"],[\"79617.90\",\"0.000\"],[\"79623.20\",\"0.000\"],[\"79623.30\",\"0.630\"],[\"79627.20\",\"0.124\"],[\"79627.30\",\"1.055\"],[\"79628.30\",\"0.046\"],[\"79628.70\",\"0.764\"],[\"79630.10\",\"0.001\"],[\"79631.30\",\"0.627\"],[\"79723.00\",\"2.437\"],[\"79740.40\",\"0.000\"],[\"79740.60\",\"0.361\"],[\"79761.30\",\"0.025\"],[\"79762.40\",\"4.342\"],[\"79964.40\",\"1.184\"],[\"79996.20\",\"1.102\"],[\"80394.20\",\"4.235\"]],\"st\":1}}"}
{"receive_ns":1788563040090001000,"stream":"btcusdt@bookTicker","event_type":"bookTicker","event_time_ms":1788563040146,"raw_json":"{\"stream\":\"btcusdt@bookTicker\",\"data\":{\"e\":\"bookTicker\",\"u\":11478212417159,\"s\":\"BTCUSDT\",\"ps\":\"BTCUSDT\",\"b\":\"79598.10\",\"B\":\"10.894\",\"a\":\"79598.20\",\"A\":\"3.157\",\"T\":1788563040146,\"E\":1788563040146,\"st\":1}}"}
{"receive_ns":1788563040090783000,"stream":"btcusdt@depth@100ms","event_type":"depthUpdate","event_time_ms":1788563040155,"raw_json":"{\"stream\":\"btcusdt@depth@100ms\",\"data\":{\"e\":\"depthUpdate\",\"E\":1788563040155,\"T\":1788563040154,\"s\":\"BTCUSDT\",\"ps\":\"BTCUSDT\",\"U\":11478212409901,\"u\":11478212417853,\"pu\":11478212409806,\"b\":[[\"29398.10\",\"1.463\"],[\"29498.10\",\"0.637\"],[\"63679.00\",\"0.000\"],[\"71638.20\",\"0.002\"],[\"78523.50\",\"1.275\"],[\"78802.10\",\"2.676\"],[\"78837.50\",\"8.931\"],[\"78850.50\",\"1.271\"],[\"78861.10\",\"0.005\"],[\"79405.60\",\"0.060\"],[\"79447.10\",\"0.014\"],[\"79448.50\",\"1.544\"],[\"79521.20\",\"0.076\"],[\"79521.60\",\"0.839\"],[\"79583.80\",\"0.000\"]],\"a\":[[\"79598.20\",\"3.157\"],[\"79598.30\",\"0.104\"],[\"79601.70\",\"0.001\"],[\"79602.00\",\"0.077\"],[\"79602.20\",\"0.344\"],[\"79602.40\",\"0.001\"],[\"79602.50\",\"0.000\"],[\"79602.70\",\"0.003\"],[\"79603.20\",\"0.030\"],[\"79603.40\",\"0.028\"],[\"79603.50\",\"0.030\"],[\"79603.60\",\"0.027\"],[\"79604.00\",\"3.064\"],[\"79605.60\",\"0.976\"],[\"79611.10\",\"1.038\"],[\"79611.30\",\"0.748\"],[\"79612.30\",\"0.001\"],[\"79618.90\",\"0.000\"],[\"79624.40\",\"0.000\"],[\"79648.80\",\"0.351\"],[\"79649.00\",\"0.134\"],[\"79698.70\",\"0.001\"],[\"80324.30\",\"0.002\"],[\"80394.20\",\"4.235\"],[\"80568.10\",\"4.020\"],[\"80586.20\",\"2.002\"]],\"st\":1}}"}
{"receive_ns":1788563040117845000,"stream":"btcusdt@bookTicker","event_type":"bookTicker","event_time_ms":1788563040182,"raw_json":"{\"stream\":\"btcusdt@bookTicker\",\"data\":{\"e\":\"bookTicker\",\"u\":11478212419685,\"s\":\"BTCUSDT\",\"ps\":\"BTCUSDT\",\"b\":\"79598.10\",\"B\":\"10.894\",\"a\":\"79598.20\",\"A\":\"3.361\",\"T\":1788563040182,\"E\":1788563040182,\"st\":1}}"}
{"receive_ns":1788563040119092000,"stream":"btcusdt@bookTicker","event_type":"bookTicker","event_time_ms":1788563040184,"raw_json":"{\"stream\":\"btcusdt@bookTicker\",\"data\":{\"e\":\"bookTicker\",\"u\":11478212419790,\"s\":\"BTCUSDT\",\"ps\":\"BTCUSDT\",\"b\":\"79598.10\",\"B\":\"10.894\",\"a\":\"79598.20\",\"A\":\"3.360\",\"T\":1788563040184,\"E\":1788563040184,\"st\":1}}"}
{"receive_ns":1788563040122785000,"stream":"btcusdt@bookTicker","event_type":"bookTicker","event_time_ms":1788563040187,"raw_json":"{\"stream\":\"btcusdt@bookTicker\",\"data\":{\"e\":\"bookTicker\",\"u\":11478212419948,\"s\":\"BTCUSDT\",\"ps\":\"BTCUSDT\",\"b\":\"79598.10\",\"B\":\"10.870\",\"a\":\"79598.20\",\"A\":\"3.360\",\"T\":1788563040186,\"E\":1788563040187,\"st\":1}}"}
{"receive_ns":1788563040125747000,"stream":"btcusdt@bookTicker","event_type":"bookTicker","event_time_ms":1788563040189,"raw_json":"{\"stream\":\"btcusdt@bookTicker\",\"data\":{\"e\":\"bookTicker\",\"u\":11478212420093,\"s\":\"BTCUSDT\",\"ps\":\"BTCUSDT\",\"b\":\"79598.10\",\"B\":\"10.896\",\"a\":\"79598.20\",\"A\":\"3.360\",\"T\":1788563040189,\"E\":1788563040189,\"st\":1}}"}
{"receive_ns":1788563040127188000,"stream":"btcusdt@bookTicker","event_type":"bookTicker","event_time_ms":1788563040191,"raw_json":"{\"stream\":\"btcusdt@bookTicker\",\"data\":{\"e\":\"bookTicker\",\"u\":11478212420154,\"s\":\"BTCUSDT\",\"ps\":\"BTCUSDT\",\"b\":\"79598.10\",\"B\":\"10.896\",\"a\":\"79598.20\",\"A\":\"3.361\",\"T\":1788563040190,\"E\":1788563040191,\"st\":1}}"}
{"receive_ns":1788563040191789000,"stream":"btcusdt@depth@100ms","event_type":"depthUpdate","event_time_ms":1788563040257,"raw_json":"{\"stream\":\"btcusdt@depth@100ms\",\"data\":{\"e\":\"depthUpdate\",\"E\":1788563040257,\"T\":1788563040256,\"s\":\"BTCUSDT\",\"ps\":\"BTCUSDT\",\"U\":11478212417903,\"u\":11478212423200,\"pu\":11478212417853,\"b\":[[\"1000.00\",\"24.604\"],[\"29398.10\",\"1.638\"],[\"29498.10\",\"0.462\"],[\"71638.20\",\"0.002\"],[\"71638.30\",\"0.041\"],[\"75610.20\",\"0.002\"],[\"76414.10\",\"0.000\"],[\"77369.40\",\"0.258\"],[\"78006.20\",\"0.030\"],[\"78345.30\",\"6.266\"],[\"78424.90\",\"3.184\"],[\"78576.80\",\"90.402\"],[\"78802.10\",\"2.676\"],[\"79200.10\",\"0.153\"],[\"79228.00\",\"0.013\"],[\"79293.40\",\"0.000\"],[\"79358.00\",\"0.150\"],[\"79374.80\",\"0.000\"],[\"79400.00\",\"4.755\"],[\"79401.10\",\"0.000\"],[\"79440.90\",\"1.005\"],[\"79442.90\",\"0.502\"],[\"79531.10\",\"0.710\"],[\"79534.90\",\"0.044\"],[\"79587.30\",\"0.453\"],[\"79598.10\",\"10.896\"]],\"a\":[[\"79598.20\",\"3.361\"],[\"79601.40\",\"0.026\"],[\"79602.10\",\"0.002\"],[\"79602.20\",\"0.254\"],[\"79602.70\",\"0.029\"],[\"79603.10\",\"0.226\"],[\"79604.00\",\"3.064\"],[\"79606.20\",\"1.463\"],[\"79653.60\",\"0.060\"],[\"79654.80\",\"0.339\"],[\"79740.80\",\"0.002\"],[\"79964.40\",\"0.420\"],[\"79996.20\",\"0.901\"],[\"80335.20\",\"2.735\"],[\"80394.20\",\"4.235\"],[\"80593.20\",\"0.770\"],[\"80672.80\",\"1.606\"],[\"80832.00\",\"1.732\"]],\"st\":1}}"}
{"receive_ns":1788563040212586000,"stream":"btcusdt@bookTicker","event_type":"bookTicker","event_time_ms":1788563040270,"raw_json":"{\"stream\":\"btcusdt@bookTicker\",\"data\":{\"e\":\"bookTicker\",\"u\":11478212423810,\"s\":\"BTCUSDT\",\"ps\":\"BTCUSDT\",\"b\":\"79598.10\",\"B\":\"10.896\",\"a\":\"79598.20\",\"A\":\"3.358\",\"T\":1788563040269,\"E\":1788563040270,\"st\":1}}"}
{"receive_ns":1788563040213254000,"stream":"btcusdt@bookTicker","event_type":"bookTicker","event_time_ms":1788563040272,"raw_json":"{\"stream\":\"btcusdt@bookTicker\",\"data\":{\"e\":\"bookTicker\",\"u\":11478212423929,\"s\":\"BTCUSDT\",\"ps\":\"BTCUSDT\",\"b\":\"79598.10\",\"B\":\"10.896\",\"a\":\"79598.20\",\"A\":\"3.359\",\"T\":1788563040272,\"E\":1788563040272,\"st\":1}}"}
{"receive_ns":1788563040266374000,"stream":"btcusdt@bookTicker","event_type":"bookTicker","event_time_ms":1788563040331,"raw_json":"{\"stream\":\"btcusdt@bookTicker\",\"data\":{\"e\":\"bookTicker\",\"u\":11478212427157,\"s\":\"BTCUSDT\",\"ps\":\"BTCUSDT\",\"b\":\"79598.10\",\"B\":\"10.896\",\"a\":\"79598.20\",\"A\":\"3.360\",\"T\":1788563040331,\"E\":1788563040331,\"st\":1}}"}
{"receive_ns":1788563040266680000,"stream":"btcusdt@bookTicker","event_type":"bookTicker","event_time_ms":1788563040332,"raw_json":"{\"stream\":\"btcusdt@bookTicker\",\"data\":{\"e\":\"bookTicker\",\"u\":11478212427251,\"s\":\"BTCUSDT\",\"ps\":\"BTCUSDT\",\"b\":\"79598.10\",\"B\":\"10.902\",\"a\":\"79598.20\",\"A\":\"3.360\",\"T\":1788563040332,\"E\":1788563040332,\"st\":1}}"}
{"receive_ns":1788563040278085000,"stream":"btcusdt@bookTicker","event_type":"bookTicker","event_time_ms":1788563040342,"raw_json":"{\"stream\":\"btcusdt@bookTicker\",\"data\":{\"e\":\"bookTicker\",\"u\":11478212427813,\"s\":\"BTCUSDT\",\"ps\":\"BTCUSDT\",\"b\":\"79598.10\",\"B\":\"10.902\",\"a\":\"79598.20\",\"A\":\"3.362\",\"T\":1788563040342,\"E\":1788563040342,\"st\":1}}"}
{"receive_ns":1788563040291618000,"stream":"btcusdt@bookTicker","event_type":"bookTicker","event_time_ms":1788563040356,"raw_json":"{\"stream\":\"btcusdt@bookTicker\",\"data\":{\"e\":\"bookTicker\",\"u\":11478212429135,\"s\":\"BTCUSDT\",\"ps\":\"BTCUSDT\",\"b\":\"79598.10\",\"B\":\"10.901\",\"a\":\"79598.20\",\"A\":\"3.362\",\"T\":1788563040356,\"E\":1788563040356,\"st\":1}}"}
{"receive_ns":1788563040292003000,"stream":"btcusdt@trade","event_type":"trade","event_time_ms":1788563040356,"raw_json":"{\"stream\":\"btcusdt@trade\",\"data\":{\"e\":\"trade\",\"E\":1788563040356,\"T\":1788563040356,\"s\":\"BTCUSDT\",\"t\":8054081707,\"p\":\"79598.10\",\"q\":\"0.001\",\"X\":\"MARKET\",\"m\":true,\"st\":1}}"}
{"receive_ns":1788563040292314000,"stream":"btcusdt@bookTicker","event_type":"bookTicker","event_time_ms":1788563040357,"raw_json":"{\"stream\":\"btcusdt@bookTicker\",\"data\":{\"e\":\"bookTicker\",\"u\":11478212429244,\"s\":\"BTCUSDT\",\"ps\":\"BTCUSDT\",\"b\":\"79598.10\",\"B\":\"10.909\",\"a\":\"79598.20\",\"A\":\"3.362\",\"T\":1788563040357,\"E\":1788563040357,\"st\":1}}"}
{"receive_ns":1788563040293127000,"stream":"btcusdt@bookTicker","event_type":"bookTicker","event_time_ms":1788563040358,"raw_json":"{\"stream\":\"btcusdt@bookTicker\",\"data\":{\"e\":\"bookTicker\",\"u\":11478212429313,\"s\":\"BTCUSDT\",\"ps\":\"BTCUSDT\",\"b\":\"79598.10\",\"B\":\"10.901\",\"a\":\"79598.20\",\"A\":\"3.362\",\"T\":1788563040358,\"E\":1788563040358,\"st\":1}}"}
{"receive_ns":1788563040293801000,"stream":"btcusdt@depth@100ms","event_type":"depthUpdate","event_time_ms":1788563040359,"raw_json":"{\"stream\":\"btcusdt@depth@100ms\",\"data\":{\"e\":\"depthUpdate\",\"E\":1788563040359,\"T\":1788563040358,\"s\":\"BTCUSDT\",\"ps\":\"BTCUSDT\",\"U\":11478212423257,\"u\":11478212429313,\"pu\":11478212423200,\"b\":[[\"1000.00\",\"24.604\"],[\"29298.10\",\"0.021\"],[\"29398.10\",\"1.778\"],[\"29498.10\",\"0.301\"],[\"71638.20\",\"0.002\"],[\"71675.00\",\"0.002\"],[\"76414.10\",\"0.002\"],[\"78231.70\",\"0.000\"],[\"78802.10\",\"2.680\"],[\"78841.90\",\"1.306\"],[\"79200.10\",\"0.154\"],[\"79228.00\",\"0.245\"],[\"79384.60\",\"0.002\"],[\"79401.10\",\"0.100\"],[\"79440.90\",\"2.336\"],[\"79473.80\",\"0.032\"],[\"79537.70\",\"0.005\"],[\"79541.60\",\"0.352\"],[\"79571.50\",\"0.024\"],[\"79573.50\",\"0.000\"],[\"79583.80\",\"0.017\"],[\"79584.50\",\"0.032\"],[\"79592.20\",\"0.053\"],[\"79598.10\",\"10.901\"]],\"a\":[[\"79598.20\",\"3.362\"],[\"79600.70\",\"0.002\"],[\"79600.80\",\"0.027\"],[\"79601.20\",\"0.027\"],[\"79601.30\",\"0.000\"],[\"79602.10\",\"0.253\"],[\"79602.20\",\"0.344\"],[\"79603.50\",\"0.004\"],[\"79603.60\",\"0.001\"],[\"79604.00\",\"2.875\"],[\"79660.00\",\"0.000\"],[\"79661.60\",\"0.003\"],[\"79723.00\",\"2.070\"],[\"79740.90\",\"0.000\"],[\"79820.00\",\"1.298\"],[\"79845.50\",\"6.044\"],[\"79964.30\",\"7.727\"],[\"79964.40\",\"1.184\"],[\"79996.20\",\"1.101\"],[\"80310.10\",\"0.000\"],[\"80394.20\",\"4.237\"],[\"80464.60\",\"0.627\"],[\"80489.70\",\"0.033\"],[\"80628.50\",\"0.868\"]],\"st\":1}}"}
{"receive_ns":1788563040305623000,"stream":"btcusdt@bookTicker","event_type":"bookTicker","event_time_ms":1788563040370,"raw_json":"{\"stream\":\"btcusdt@bookTicker\",\"data\":{\"e\":\"bookTicker\",\"u\":11478212430184,\"s\":\"BTCUSDT\",\"ps\":\"BTCUSDT\",\"b\":\"79598.10\",\"B\":\"10.885\",\"a\":\"79598.20\",\"A\":\"3.362\",\"T\":1788563040370,\"E\":1788563040370,\"st\":1}}"}
{"receive_ns":1788563040316411000,"stream":"btcusdt@bookTicker","event_type":"bookTicker","event_time_ms":1788563040382,"raw_json":"{\"stream\":\"btcusdt@bookTicker\",\"data\":{\"e\":\"bookTicker\",\"u\":11478212430709,\"s\":\"BTCUSDT\",\"ps\":\"BTCUSDT\",\"b\":\"79598.10\",\"B\":\"10.879\",\"a\":\"79598.20\",\"A\":\"3.362\",\"T\":1788563040382,\"E\":1788563040382,\"st\":1}}"}
{"receive_ns":1788563040317458000,"stream":"btcusdt@bookTicker","event_type":"bookTicker","event_time_ms":1788563040384,"raw_json":"{\"stream\":\"btcusdt@bookTicker\",\"data\":{\"e\":\"bookTicker\",\"u\":11478212430773,\"s\":\"BTCUSDT\",\"ps\":\"BTCUSDT\",\"b\":\"79598.10\",\"B\":\"10.887\",\"a\":\"79598.20\",\"A\":\"3.362\",\"T\":1788563040383,\"E\":1788563040384,\"st\":1}}"}
{"receive_ns":1788563040320023000,"stream":"btcusdt@bookTicker","event_type":"bookTicker","event_time_ms":1788563040384,"raw_json":"{\"stream\":\"btcusdt@bookTicker\",\"data\":{\"e\":\"bookTicker\",\"u\":11478212430839,\"s\":\"BTCUSDT\",\"ps\":\"BTCUSDT\",\"b\":\"79598.10\",\"B\":\"10.879\",\"a\":\"79598.20\",\"A\":\"3.362\",\"T\":1788563040384,\"E\":1788563040384,\"st\":1}}"}
{"receive_ns":1788563040356020000,"stream":"btcusdt@bookTicker","event_type":"bookTicker","event_time_ms":1788563040420,"raw_json":"{\"stream\":\"btcusdt@bookTicker\",\"data\":{\"e\":\"bookTicker\",\"u\":11478212432823,\"s\":\"BTCUSDT\",\"ps\":\"BTCUSDT\",\"b\":\"79598.10\",\"B\":\"10.879\",\"a\":\"79598.20\",\"A\":\"3.364\",\"T\":1788563040420,\"E\":1788563040420,\"st\":1}}"}
{"receive_ns":1788563040387899000,"stream":"btcusdt@bookTicker","event_type":"bookTicker","event_time_ms":1788563040452,"raw_json":"{\"stream\":\"btcusdt@bookTicker\",\"data\":{\"e\":\"bookTicker\",\"u\":11478212434226,\"s\":\"BTCUSDT\",\"ps\":\"BTCUSDT\",\"b\":\"79598.10\",\"B\":\"10.895\",\"a\":\"79598.20\",\"A\":\"3.364\",\"T\":1788563040452,\"E\":1788563040452,\"st\":1}}"}
{"receive_ns":1788563040396843000,"stream":"btcusdt@depth@100ms","event_type":"depthUpdate","event_time_ms":1788563040461,"raw_json":"{\"stream\":\"btcusdt@depth@100ms\",\"data\":{\"e\":\"depthUpdate\",\"E\":1788563040461,\"T\":1788563040457,\"s\":\"BTCUSDT\",\"ps\":\"BTCUSDT\",\"U\":11478212429354,\"u\":11478212434512,\"pu\":11478212429313,\"b\":[[\"29298.10\",\"0.084\"],[\"29398.10\",\"1.827\"],[\"29498.10\",\"0.189\"],[\"63678.00\",\"0.002\"],[\"71638.20\",\"0.002\"],[\"75618.20\",\"0.004\"],[\"75618.30\",\"0.006\"],[\"76414.10\",\"0.000\"],[\"78802.10\",\"3.943\"],[\"79171.60\",\"0.000\"],[\"79200.10\",\"0.154\"],[\"79303.30\",\"0.016\"],[\"79367.90\",\"0.065\"],[\"79400.00\",\"4.554\"],[\"79440.90\",\"2.336\"],[\"79442.90\",\"0.000\"],[\"79448.50\",\"1.512\"],[\"79451.40\",\"1.542\"],[\"79462.70\",\"0.010\"],[\"79462.80\",\"0.003\"],[\"79467.40\",\"0.487\"],[\"79473.80\",\"0.626\"],[\"79561.30\",\"0.243\"],[\"79565.50\",\"0.792\"],[\"79583.40\",\"0.630\"],[\"79583.60\",\"0.006\"],[\"79583.70\",\"0.001\"],[\"79585.30\",\"0.146\"],[\"79585.70\",\"0.000\"],[\"79587.50\",\"0.004\"],[\"79587.80\",\"0.141\"],[\"79598.10\",\"10.895\"]],\"a\":[[\"79598.20\",\"3.364\"],[\"79599.40\",\"0.014\"],[\"79599.70\",\"0.017\"],[\"79600.70\",\"0.028\"],[\"79602.20\",\"0.344\"],[\"79603.10\",\"0.026\"],[\"79603.40\",\"0.002\"],[\"79609.50\",\"0.017\"],[\"79610.20\",\"0.441\"],[\"79611.10\",\"1.034\"],[\"79611.20\",\"0.230\"],[\"79723.00\",\"2.437\"],[\"79820.80\",\"0.002\"],[\"79820.90\",\"0.003\"],[\"79964.40\",\"0.765\"],[\"79996.20\",\"1.101\"],[\"80235.00\",\"1.004\"],[\"80394.20\",\"4.235\"]],\"st\":1}}"}
{"receive_ns":1788563040436280000,"stream":"btcusdt@bookTicker","event_type":"bookTicker","event_time_ms":1788563040501,"raw_json":"{\"stream\":\"btcusdt@bookTicker\",\"data\":{\"e\":\"bookTicker\",\"u\":11478212442955,\"s\":\"BTCUSDT\",\"ps\":\"BTCUSDT\",\"b\":\"79598.10\",\"B\":\"10.895\",\"a\":\"79598.20\",\"A\":\"3.363\",\"T\":1788563040500,\"E\":1788563040501,\"st\":1}}"}
{"receive_ns":1788563040457014000,"stream":"btcusdt@bookTicker","event_type":"bookTicker","event_time_ms":1788563040507,"raw_json":"{\"stream\":\"btcusdt@bookTicker\",\"data\":{\"e\":\"bookTicker\",\"u\":11478212443954,\"s\":\"BTCUSDT\",\"ps\":\"BTCUSDT\",\"b\":\"79598.10\",\"B\":\"10.895\",\"a\":\"79598.20\",\"A\":\"3.366\",\"T\":1788563040507,\"E\":1788563040507,\"st\":1}}"}
{"receive_ns":1788563040499380000,"stream":"btcusdt@depth@100ms","event_type":"depthUpdate","event_time_ms":1788563040563,"raw_json":"{\"stream\":\"btcusdt@depth@100ms\",\"data\":{\"e\":\"depthUpdate\",\"E\":1788563040563,\"T\":1788563040561,\"s\":\"BTCUSDT\",\"ps\":\"BTCUSDT\",\"U\":11478212434624,\"u\":11478212450991,\"pu\":11478212434512,\"b\":[[\"1000.00\",\"24.604\"],[\"29298.10\",\"0.140\"],[\"29398.10\",\"1.897\"],[\"29498.10\",\"0.063\"],[\"63678.00\",\"0.002\"],[\"63678.50\",\"0.002\"],[\"71638.20\",\"0.002\"],[\"75618.20\",\"0.002\"],[\"75618.30\",\"0.008\"],[\"76414.10\",\"0.002\"],[\"77608.10\",\"0.876\"],[\"78171.50\",\"0.000\"],[\"78603.10\",\"1.960\"],[\"78802.10\",\"3.943\"],[\"79200.10\",\"0.154\"],[\"79228.00\",\"0.245\"],[\"79400.00\",\"4.755\"],[\"79401.10\",\"0.000\"],[\"79440.90\",\"2.436\"],[\"79442.90\",\"0.502\"],[\"79574.40\",\"0.048\"]],\"a\":[[\"79598.20\",\"3.366\"],[\"79602.10\",\"0.253\"],[\"79602.20\",\"0.254\"],[\"79603.10\",\"0.226\"],[\"79608.10\",\"0.352\"],[\"79614.30\",\"0.359\"],[\"79711.90\",\"0.015\"],[\"79728.60\",\"0.000\"],[\"79962.40\",\"1.183\"],[\"79964.40\",\"0.001\"],[\"79996.20\",\"1.101\"],[\"80394.20\",\"4.235\"],[\"80644.50\",\"0.217\"]],\"st\":1}}"}
{"receive_ns":1788563040551015000,"stream":"btcusdt@bookTicker","event_type":"bookTicker","event_time_ms":1788563040616,"raw_json":"{\"stream\":\"btcusdt@bookTicker\",\"data\":{\"e\":\"bookTicker\",\"u\":11478212455862,\"s\":\"BTCUSDT\",\"ps\":\"BTCUSDT\",\"b\":\"79598.10\",\"B\":\"10.854\",\"a\":\"79598.20\",\"A\":\"3.366\",\"T\":1788563040615,\"E\":1788563040616,\"st\":1}}"}
{"receive_ns":1788563040557984000,"stream":"btcusdt@bookTicker","event_type":"bookTicker","event_time_ms":1788563040623,"raw_json":"{\"stream\":\"btcusdt@bookTicker\",\"data\":{\"e\":\"bookTicker\",\"u\":11478212456625,\"s\":\"BTCUSDT\",\"ps\":\"BTCUSDT\",\"b\":\"79598.10\",\"B\":\"10.894\",\"a\":\"79598.20\",\"A\":\"3.366\",\"T\":1788563040623,\"E\":1788563040623,\"st\":1}}"}
{"receive_ns":1788563040588011000,"stream":"btcusdt@bookTicker","event_type":"bookTicker","event_time_ms":1788563040651,"raw_json":"{\"stream\":\"btcusdt@bookTicker\",\"data\":{\"e\":\"bookTicker\",\"u\":11478212458430,\"s\":\"BTCUSDT\",\"ps\":\"BTCUSDT\",\"b\":\"79598.10\",\"B\":\"10.892\",\"a\":\"79598.20\",\"A\":\"3.366\",\"T\":1788563040651,\"E\":1788563040651,\"st\":1}}"}
{"receive_ns":1788563040600191000,"stream":"btcusdt@depth@100ms","event_type":"depthUpdate","event_time_ms":1788563040665,"raw_json":"{\"stream\":\"btcusdt@depth@100ms\",\"data\":{\"e\":\"depthUpdate\",\"E\":1788563040665,\"T\":1788563040662,\"s\":\"BTCUSDT\",\"ps\":\"BTCUSDT\",\"U\":11478212451161,\"u\":11478212459165,\"pu\":11478212450991,\"b\":[[\"1000.00\",\"24.604\"],[\"29298.10\",\"0.252\"],[\"29398.10\",\"1.848\"],[\"29498.10\",\"0.000\"],[\"63678.50\",\"0.000\"],[\"71638.20\",\"0.002\"],[\"78802.10\",\"3.943\"],[\"79200.10\",\"0.013\"],[\"79235.60\",\"0.000\"],[\"79440.90\",\"1.431\"],[\"79473.80\",\"0.032\"],[\"79574.40\",\"0.050\"],[\"79584.00\",\"0.030\"],[\"79592.20\",\"0.053\"],[\"79597.00\",\"0.138\"],[\"79598.10\",\"10.892\"]],\"a\":[[\"79602.20\",\"0.003\"],[\"79611.10\",\"1.038\"],[\"79611.20\",\"0.226\"],[\"79614.30\",\"0.361\"],[\"79623.80\",\"0.014\"],[\"79723.00\",\"2.070\"],[\"79740.30\",\"0.165\"],[\"79996.20\",\"0.575\"],[\"80394.20\",\"4.235\"],[\"80553.40\",\"13.754\"],[\"80593.90\",\"5.526\"],[\"80712.60\",\"15.838\"]],\"st\":1}}"}
{"receive_ns":1788563040674960000,"stream":"btcusdt@bookTicker","event_type":"bookTicker","event_time_ms":1788563040727,"raw_json":"{\"stream\":\"btcusdt@bookTicker\",\"data\":{\"e\":\"bookTicker\",\"u\":11478212463200,\"s\":\"BTCUSDT\",\"ps\":\"BTCUSDT\",\"b\":\"79598.10\",\"B\":\"10.892\",\"a\":\"79598.20\",\"A\":\"3.363\",\"T\":1788563040727,\"E\":1788563040727,\"st\":1}}"}
{"receive_ns":1788563040675511000,"stream":"btcusdt@bookTicker","event_type":"bookTicker","event_time_ms":1788563040732,"raw_json":"{\"stream\":\"btcusdt@bookTicker\",\"data\":{\"e\":\"bookTicker\",\"u\":11478212463481,\"s\":\"BTCUSDT\",\"ps\":\"BTCUSDT\",\"b\":\"79598.10\",\"B\":\"10.892\",\"a\":\"79598.20\",\"A\":\"3.364\",\"T\":1788563040732,\"E\":1788563040732,\"st\":1}}"}
{"receive_ns":1788563040759942000,"stream":"btcusdt@depth@100ms","event_type":"depthUpdate","event_time_ms":1788563040767,"raw_json":"{\"stream\":\"btcusdt@depth@100ms\",\"data\":{\"e\":\"depthUpdate\",\"E\":1788563040767,\"T\":1788563040766,\"s\":\"BTCUSDT\",\"ps\":\"BTCUSDT\",\"U\":11478212459458,\"u\":11478212465113,\"pu\":11478212459165,\"b\":[[\"29298.10\",\"0.434\"],[\"29398.10\",\"1.666\"],[\"71638.20\",\"0.002\"],[\"75618.30\",\"0.006\"],[\"76414.10\",\"0.000\"],[\"78006.20\",\"0.027\"],[\"78421.90\",\"0.005\"],[\"78423.20\",\"0.006\"],[\"78802.10\",\"3.943\"],[\"79200.10\",\"0.154\"],[\"79228.00\",\"0.013\"],[\"79400.00\",\"4.554\"],[\"79434.40\",\"2.572\"],[\"79439.80\",\"0.202\"],[\"79440.90\",\"1.507\"],[\"79442.90\",\"0.000\"],[\"79473.80\",\"0.608\"],[\"79545.70\",\"2.041\"],[\"79546.40\",\"0.763\"]],\"a\":[[\"79598.20\",\"3.364\"],[\"79602.10\",\"0.002\"],[\"79602.20\",\"0.254\"],[\"79603.10\",\"0.226\"],[\"79608.10\",\"0.262\"],[\"79722.90\",\"0.369\"],[\"79740.20\",\"0.002\"],[\"79740.30\",\"0.165\"],[\"79740.40\",\"0.000\"],[\"79762.30\",\"3.330\"],[\"79762.40\",\"1.566\"],[\"79962.40\",\"0.419\"],[\"79996.20\",\"0.901\"],[\"80394.20\",\"4.235\"],[\"80884.00\",\"0.006\"],[\"80885.30\",\"0.002\"]],\"st\":1}}"}
{"receive_ns":1788563040805537000,"stream":"btcusdt@depth@100ms","event_type":"depthUpdate","event_time_ms":1788563040869,"raw_json":"{\"stream\":\"btcusdt@depth@100ms\",\"data\":{\"e\":\"depthUpdate\",\"E\":1788563040869,\"T\":1788563040865,\"s\":\"BTCUSDT\",\"ps\":\"BTCUSDT\",\"U\":11478212465194,\"u\":11478212470124,\"pu\":11478212465113,\"b\":[[\"1000.00\",\"24.604\"],[\"29298.10\",\"0.609\"],[\"29398.10\",\"1.491\"],[\"71638.20\",\"0.002\"],[\"76414.10\",\"0.002\"],[\"78165.30\",\"2.520\"],[\"78802.10\",\"3.943\"],[\"79200.10\",\"0.154\"],[\"79228.00\",\"0.245\"],[\"79440.90\",\"2.938\"],[\"79558.30\",\"0.080\"],[\"79584.10\",\"0.112\"],[\"79584.70\",\"0.016\"],[\"79589.20\",\"0.004\"],[\"79589.50\",\"0.001\"]],\"a\":[[\"79602.10\",\"0.253\"],[\"79611.10\",\"1.038\"],[\"79611.20\",\"0.226\"],[\"79638.00\",\"0.006\"],[\"79740.20\",\"0.127\"],[\"79962.40\",\"1.273\"],[\"79996.20\",\"1.101\"],[\"80316.50\",\"6.497\"],[\"80394.20\",\"4.235\"],[\"80587.30\",\"0.000\"]],\"st\":1}}"}
{"receive_ns":1788563040895626000,"stream":"btcusdt@bookTicker","event_type":"bookTicker","event_time_ms":1788563040960,"raw_json":"{\"stream\":\"btcusdt@bookTicker\",\"data\":{\"e\":\"bookTicker\",\"u\":11478212474080,\"s\":\"BTCUSDT\",\"ps\":\"BTCUSDT\",\"b\":\"79598.10\",\"B\":\"10.892\",\"a\":\"79598.20\",\"A\":\"3.363\",\"T\":1788563040960,\"E\":1788563040960,\"st\":1}}"}
{"receive_ns":1788563040906246000,"stream":"btcusdt@bookTicker","event_type":"bookTicker","event_time_ms":1788563040969,"raw_json":"{\"stream\":\"btcusdt@bookTicker\",\"data\":{\"e\":\"bookTicker\",\"u\":11478212474557,\"s\":\"BTCUSDT\",\"ps\":\"BTCUSDT\",\"b\":\"79598.10\",\"B\":\"10.892\",\"a\":\"79598.20\",\"A\":\"3.366\",\"T\":1788563040969,\"E\":1788563040969,\"st\":1}}"}
{"receive_ns":1788563040906663000,"stream":"btcusdt@depth@100ms","event_type":"depthUpdate","event_time_ms":1788563040971,"raw_json":"{\"stream\":\"btcusdt@depth@100ms\",\"data\":{\"e\":\"depthUpdate\",\"E\":1788563040971,\"T\":1788563040969,\"s\":\"BTCUSDT\",\"ps\":\"BTCUSDT\",\"U\":11478212470263,\"u\":11478212474570,\"pu\":11478212470124,\"b\":[[\"1000.00\",\"24.604\"],[\"29298.10\",\"0.791\"],[\"29398.10\",\"1.309\"],[\"71638.20\",\"0.002\"],[\"76414.10\",\"0.000\"],[\"78493.90\",\"3.525\"],[\"78802.10\",\"3.943\"],[\"79200.10\",\"0.153\"],[\"79439.80\",\"0.001\"],[\"79440.90\",\"2.436\"],[\"79493.00\",\"0.055\"],[\"79569.60\",\"0.003\"],[\"79571.20\",\"0.006\"],[\"79592.20\",\"0.053\"]],\"a\":[[\"79598.20\",\"3.366\"],[\"79600.70\",\"0.002\"],[\"79600.80\",\"0.001\"],[\"79602.20\",\"0.254\"],[\"79603.10\",\"0.026\"],[\"79740.20\",\"0.002\"],[\"79740.50\",\"0.000\"],[\"79962.40\",\"0.854\"],[\"79996.20\",\"1.101\"],[\"80229.40\",\"0.001\"],[\"80354.40\",\"3.727\"],[\"80394.20\",\"4.235\"],[\"80469.40\",\"0.000\"],[\"80594.00\",\"0.627\"],[\"80867.40\",\"0.002\"]],\"st\":1}}"}
{"receive_ns":1788563040965506000,"stream":"btcusdt@bookTicker","event_type":"bookTicker","event_time_ms":1788563041028,"raw_json":"{\"stream\":\"btcusdt@bookTicker\",\"data\":{\"e\":\"bookTicker\",\"u\":11478212477204,\"s\":\"BTCUSDT\",\"ps\":\"BTCUSDT\",\"b\":\"79598.10\",\"B\":\"10.876\",\"a\":\"79598.20\",\"A\":\"3.366\",\"T\":1788563041028,\"E\":1788563041028,\"st\":1}}"}
{"receive_ns":1788563040999723000,"stream":"btcusdt@bookTicker","event_type":"bookTicker","event_time_ms":1788563041064,"raw_json":"{\"stream\":\"btcusdt@bookTicker\",\"data\":{\"e\":\"bookTicker\",\"u\":11478212479330,\"s\":\"BTCUSDT\",\"ps\":\"BTCUSDT\",\"b\":\"79598.10\",\"B\":\"10.867\",\"a\":\"79598.20\",\"A\":\"3.366\",\"T\":1788563041064,\"E\":1788563041064,\"st\":1}}"}
{"receive_ns":1788563040999949000,"stream":"btcusdt@trade","event_type":"trade","event_time_ms":1788563041064,"raw_json":"{\"stream\":\"btcusdt@trade\",\"data\":{\"e\":\"trade\",\"E\":1788563041064,\"T\":1788563041064,\"s\":\"BTCUSDT\",\"t\":8054081708,\"p\":\"79598.10\",\"q\":\"0.003\",\"X\":\"MARKET\",\"m\":true,\"st\":1}}"}
{"receive_ns":1788563041000092000,"stream":"btcusdt@trade","event_type":"trade","event_time_ms":1788563041064,"raw_json":"{\"stream\":\"btcusdt@trade\",\"data\":{\"e\":\"trade\",\"E\":1788563041064,\"T\":1788563041064,\"s\":\"BTCUSDT\",\"t\":8054081709,\"p\":\"79598.10\",\"q\":\"0.006\",\"X\":\"MARKET\",\"m\":true,\"st\":1}}"}
{"receive_ns":1788563041000293000,"stream":"btcusdt@bookTicker","event_type":"bookTicker","event_time_ms":1788563041065,"raw_json":"{\"stream\":\"btcusdt@bookTicker\",\"data\":{\"e\":\"bookTicker\",\"u\":11478212479464,\"s\":\"BTCUSDT\",\"ps\":\"BTCUSDT\",\"b\":\"79598.10\",\"B\":\"10.875\",\"a\":\"79598.20\",\"A\":\"3.366\",\"T\":1788563041065,\"E\":1788563041065,\"st\":1}}"}
{"receive_ns":1788563041000565000,"stream":"btcusdt@bookTicker","event_type":"bookTicker","event_time_ms":1788563041066,"raw_json":"{\"stream\":\"btcusdt@bookTicker\",\"data\":{\"e\":\"bookTicker\",\"u\":11478212479515,\"s\":\"BTCUSDT\",\"ps\":\"BTCUSDT\",\"b\":\"79598.10\",\"B\":\"10.867\",\"a\":\"79598.20\",\"A\":\"3.366\",\"T\":1788563041066,\"E\":1788563041066,\"st\":1}}"}
{"receive_ns":1788563041009901000,"stream":"btcusdt@depth@100ms","event_type":"depthUpdate","event_time_ms":1788563041073,"raw_json":"{\"stream\":\"btcusdt@depth@100ms\",\"data\":{\"e\":\"depthUpdate\",\"E\":1788563041073,\"T\":1788563041069,\"s\":\"BTCUSDT\",\"ps\":\"BTCUSDT\",\"U\":11478212474632,\"u\":11478212479719,\"pu\":11478212474570,\"b\":[[\"29298.10\",\"0.966\"],[\"29398.10\",\"1.134\"],[\"71638.20\",\"0.002\"],[\"78006.20\",\"0.024\"],[\"78369.80\",\"0.000\"],[\"78491.70\",\"1.687\"],[\"78802.10\",\"3.943\"],[\"79228.00\",\"0.013\"],[\"79401.10\",\"0.232\"],[\"79440.90\",\"1.005\"],[\"79441.80\",\"0.202\"],[\"79442.90\",\"1.607\"],[\"79492.60\",\"0.327\"],[\"79564.20\",\"0.733\"],[\"79564.40\",\"0.001\"],[\"79565.20\",\"0.102\"],[\"79566.00\",\"0.007\"],[\"79566.80\",\"0.000\"],[\"79573.20\",\"0.440\"],[\"79573.40\",\"0.374\"],[\"79573.60\",\"0.000\"],[\"79574.50\",\"0.003\"],[\"79574.60\",\"0.099\"],[\"79574.90\",\"0.000\"],[\"79575.20\",\"1.365\"],[\"79575.40\",\"0.001\"],[\"79579.20\",\"1.856\"],[\"79579.30\",\"0.321\"],[\"79579.40\",\"0.000\"],[\"79583.20\",\"0.630\"],[\"79583.40\",\"0.320\"],[\"79583.50\",\"0.006\"],[\"79583.60\",\"0.002\"],[\"79583.80\",\"0.017\"],[\"79592.00\",\"0.291\"],[\"79592.20\",\"0.053\"],[\"79596.30\",\"0.000\"],[\"79598.10\",\"10.867\"]],\"a\":[[\"79599.40\",\"0.090\"],[\"79600.40\",\"0.319\"],[\"79600.70\",\"0.028\"],[\"79602.10\",\"0.002\"],[\"79602.20\",\"0.003\"],[\"79603.10\",\"0.226\"],[\"79606.10\",\"0.252\"],[\"79610.20\",\"0.441\"],[\"79610.90\",\"0.740\"],[\"79611.00\",\"0.691\"],[\"79611.10\",\"1.034\"],[\"79611.20\",\"0.543\"],[\"79611.30\",\"0.435\"],[\"79612.30\",\"0.002\"],[\"79613.30\",\"0.919\"],[\"79613.70\",\"0.000\"],[\"79614.40\",\"0.000\"],[\"79614.50\",\"0.252\"],[\"79614.80\",\"0.013\"],[\"79616.10\",\"0.008\"],[\"79616.90\",\"0.456\"],[\"79628.00\",\"2.050\"],[\"79628.30\",\"0.000\"],[\"79629.10\",\"0.193\"],[\"79631.00\",\"0.704\"],[\"79631.30\",\"0.000\"],[\"79740.30\",\"0.165\"],[\"79740.50\",\"0.125\"],[\"79962.40\",\"1.273\"],[\"79996.20\",\"1.102\"],[\"80389.80\",\"0.000\"],[\"80394.20\",\"4.235\"],[\"80787.80\",\"0.000\"],[\"80804.70\",\"0.000\"],[\"80929.10\",\"0.616\"]],\"st\":1}}"}
{"receive_ns":1788563041111156000,"stream":"btcusdt@depth@100ms","event_type":"depthUpdate","event_time_ms":1788563041175,"raw_json":"{\"stream\":\"btcusdt@depth@100ms\",\"data\":{\"e\":\"depthUpdate\",\"E\":1788563041175,\"T\":1788563041174,\"s\":\"BTCUSDT\",\"ps\":\"BTCUSDT\",\"U\":11478212479874,\"u\":11478212485132,\"pu\":11478212479719,\"b\":[[\"1000.00\",\"24.604\"],[\"29298.10\",\"1.148\"],[\"29398.10\",\"0.952\"],[\"71638.20\",\"0.002\"],[\"76414.10\",\"0.002\"],[\"77953.10\",\"0.300\"],[\"78376.60\",\"0.000\"],[\"78380.60\",\"0.030\"],[\"78563.30\",\"2.256\"],[\"78802.10\",\"3.943\"],[\"79200.10\",\"0.012\"],[\"79440.90\",\"0.000\"],[\"79473.80\",\"0.576\"],[\"79486.10\",\"0.001\"],[\"79508.20\",\"0.023\"],[\"79511.20\",\"2.204\"],[\"79534.50\",\"0.006\"],[\"79536.80\",\"0.000\"],[\"79557.50\",\"1.404\"],[\"79591.80\",\"0.033\"],[\"79592.20\",\"0.049\"]],\"a\":[[\"79603.10\",\"0.026\"],[\"79609.70\",\"0.638\"],[\"79609.80\",\"0.000\"],[\"79610.80\",\"0.195\"],[\"79611.10\",\"1.038\"],[\"79611.20\",\"0.539\"],[\"79634.50\",\"0.121\"],[\"79653.60\",\"0.056\"],[\"79653.80\",\"0.040\"],[\"79654.60\",\"0.708\"],[\"79655.20\",\"0.002\"],[\"79680.10\",\"1.430\"],[\"79683.90\",\"0.011\"],[\"79698.70\",\"0.000\"],[\"79698.80\",\"0.001\"],[\"79740.50\",\"0.000\"],[\"79996.20\",\"0.576\"],[\"80394.20\",\"4.235\"],[\"80593.90\",\"4.912\"],[\"80745.30\",\"0.556\"],[\"80811.70\",\"0.000\"]],\"st\":1}}"}
{"receive_ns":1788563041137424000,"stream":"btcusdt@bookTicker","event_type":"bookTicker","event_time_ms":1788563041203,"raw_json":"{\"stream\":\"btcusdt@bookTicker\",\"data\":{\"e\":\"bookTicker\",\"u\":11478212487077,\"s\":\"BTCUSDT\",\"ps\":\"BTCUSDT\",\"b\":\"79598.10\",\"B\":\"10.876\",\"a\":\"79598.20\",\"A\":\"3.366\",\"T\":1788563041203,\"E\":1788563041203,\"st\":1}}"}
{"receive_ns":1788563041163129000,"stream":"btcusdt@bookTicker","event_type":"bookTicker","event_time_ms":1788563041226,"raw_json":"{\"stream\":\"btcusdt@bookTicker\",\"data\":{\"e\":\"bookTicker\",\"u\":11478212488273,\"s\":\"BTCUSDT\",\"ps\":\"BTCUSDT\",\"b\":\"79598.10\",\"B\":\"10.876\",\"a\":\"79598.20\",\"A\":\"3.363\",\"T\":1788563041226,\"E\":1788563041226,\"st\":1}}"}
{"receive_ns":1788563041163475000,"stream":"btcusdt@bookTicker","event_type":"bookTicker","event_time_ms":1788563041227,"raw_json":"{\"stream\":\"btcusdt@bookTicker\",\"data\":{\"e\":\"bookTicker\",\"u\":11478212488342,\"s\":\"BTCUSDT\",\"ps\":\"BTCUSDT\",\"b\":\"79598.10\",\"B\":\"10.876\",\"a\":\"79598.20\",\"A\":\"3.364\",\"T\":1788563041227,\"E\":1788563041227,\"st\":1}}"}
{"receive_ns":1788563041168506000,"stream":"btcusdt@bookTicker","event_type":"bookTicker","event_time_ms":1788563041232,"raw_json":"{\"stream\":\"btcusdt@bookTicker\",\"data\":{\"e\":\"bookTicker\",\"u\":11478212488754,\"s\":\"BTCUSDT\",\"ps\":\"BTCUSDT\",\"b\":\"79598.10\",\"B\":\"10.876\",\"a\":\"79598.20\",\"A\":\"3.367\",\"T\":1788563041232,\"E\":1788563041232,\"st\":1}}"}
{"receive_ns":1788563041212290000,"stream":"btcusdt@depth@100ms","event_type":"depthUpdate","event_time_ms":1788563041277,"raw_json":"{\"stream\":\"btcusdt@depth@100ms\",\"data\":{\"e\":\"depthUpdate\",\"E\":1788563041277,\"T\":1788563041274,\"s\":\"BTCUSDT\",\"ps\":\"BTCUSDT\",\"U\":11478212485212,\"u\":11478212491325,\"pu\":11478212485132,\"b\":[[\"1000.00\",\"24.604\"],[\"29298.10\",\"1.323\"],[\"29398.10\",\"0.777\"],[\"71620.80\",\"0.000\"],[\"71638.20\",\"0.002\"],[\"71785.50\",\"0.000\"],[\"76362.20\",\"2.000\"],[\"76414.10\",\"0.000\"],[\"77157.70\",\"1.000\"],[\"78002.40\",\"0.000\"],[\"78006.20\",\"0.015\"],[\"78220.50\",\"0.767\"],[\"78491.70\",\"2.959\"],[\"78493.90\",\"2.254\"],[\"78802.10\",\"3.943\"],[\"79200.10\",\"0.153\"],[\"79401.10\",\"0.000\"],[\"79439.80\",\"0.202\"],[\"79441.80\",\"0.001\"],[\"79442.90\",\"0.000\"],[\"79451.40\",\"1.510\"],[\"79451.90\",\"2.409\"],[\"79467.60\",\"0.011\"],[\"79467.70\",\"2.122\"],[\"79472.80\",\"0.032\"],[\"79473.80\",\"0.594\"],[\"79485.90\",\"0.361\"],[\"79492.60\",\"0.001\"],[\"79494.60\",\"1.507\"],[\"79563.20\",\"0.010\"],[\"79564.20\",\"0.687\"],[\"79564.30\",\"0.298\"],[\"79564.80\",\"0.454\"],[\"79565.90\",\"0.032\"],[\"79572.10\",\"0.079\"],[\"79572.60\",\"0.373\"],[\"79573.20\",\"0.440\"],[\"79573.40\",\"0.001\"],[\"79592.20\",\"0.049\"],[\"79598.10\",\"10.876\"]],\"a\":[[\"79598.20\",\"3.367\"],[\"79600.40\",\"0.293\"],[\"79600.70\",\"0.002\"],[\"79601.10\",\"0.029\"],[\"79606.10\",\"0.001\"],[\"79612.50\",\"0.263\"],[\"79613.30\",\"0.547\"],[\"79613.70\",\"0.372\"],[\"79614.70\",\"0.001\"],[\"79615.90\",\"0.562\"],[\"79616.10\",\"0.002\"],[\"79616.80\",\"0.007\"],[\"79616.90\",\"0.004\"],[\"79626.90\",\"0.010\"],[\"79628.00\",\"2.004\"],[\"79628.10\",\"0.062\"],[\"79653.70\",\"0.005\"],[\"79698.80\",\"0.000\"],[\"79722.80\",\"0.998\"],[\"79722.90\",\"0.002\"],[\"79724.40\",\"0.470\"],[\"79724.50\",\"0.000\"],[\"79735.50\",\"0.275\"],[\"79736.40\",\"0.011\"],[\"79740.40\",\"0.125\"],[\"79962.40\",\"0.419\"],[\"79996.20\",\"0.902\"],[\"80394.20\",\"4.235\"],[\"80815.60\",\"0.017\"],[\"81186.10\",\"0.000\"],[\"81190.10\",\"0.011\"]],\"st\":1}}"}
{"receive_ns":1788563041268553000,"stream":"btcusdt@bookTicker","event_type":"bookTicker","event_time_ms":1788563041332,"raw_json":"{\"stream\":\"btcusdt@bookTicker\",\"data\":{\"e\":\"bookTicker\",\"u\":11478212494274,\"s\":\"BTCUSDT\",\"ps\":\"BTCUSDT\",\"b\":\"79598.10\",\"B\":\"10.884\",\"a\":\"79598.20\",\"A\":\"3.367\",\"T\":1788563041331,\"E\":1788563041332,\"st\":1}}"}
{"receive_ns":1788563041268832000,"stream":"btcusdt@bookTicker","event_type":"bookTicker","event_time_ms":1788563041332,"raw_json":"{\"stream\":\"btcusdt@bookTicker\",\"data\":{\"e\":\"bookTicker\",\"u\":11478212494328,\"s\":\"BTCUSDT\",\"ps\":\"BTCUSDT\",\"b\":\"79598.10\",\"B\":\"10.876\",\"a\":\"79598.20\",\"A\":\"3.367\",\"T\":1788563041332,\"E\":1788563041332,\"st\":1}}"}
{"receive_ns":1788563041287638000,"stream":"btcusdt@bookTicker","event_type":"bookTicker","event_time_ms":1788563041351,"raw_json":"{\"stream\":\"btcusdt@bookTicker\",\"data\":{\"e\":\"bookTicker\",\"u\":11478212495234,\"s\":\"BTCUSDT\",\"ps\":\"BTCUSDT\",\"b\":\"79598.10\",\"B\":\"10.892\",\"a\":\"79598.20\",\"A\":\"3.367\",\"T\":1788563041351,\"E\":1788563041351,\"st\":1}}"}
{"receive_ns":1788563041315643000,"stream":"btcusdt@depth@100ms","event_type":"depthUpdate","event_time_ms":1788563041379,"raw_json":"{\"stream\":\"btcusdt@depth@100ms\",\"data\":{\"e\":\"depthUpdate\",\"E\":1788563041379,\"T\":1788563041377,\"s\":\"BTCUSDT\",\"ps\":\"BTCUSDT\",\"U\":11478212491412,\"u\":11478212497841,\"pu\":11478212491325,\"b\":[[\"29298.10\",\"1.505\"],[\"29398.10\",\"0.595\"],[\"63678.00\",\"0.002\"],[\"71638.20\",\"0.002\"],[\"71950.10\",\"0.000\"],[\"74771.40\",\"4.000\"],[\"75566.80\",\"3.000\"],[\"75614.50\",\"0.000\"],[\"75614.60\",\"0.002\"],[\"76414.10\",\"0.002\"],[\"78462.50\",\"0.000\"],[\"78464.50\",\"4.354\"],[\"78483.70\",\"7.890\"],[\"78494.30\",\"0.025\"],[\"78623.70\",\"5.650\"],[\"78632.60\",\"5.036\"],[\"78802.10\",\"3.943\"],[\"78837.50\",\"6.398\"],[\"79200.10\",\"0.152\"],[\"79401.10\",\"0.232\"],[\"79440.90\",\"1.431\"],[\"79454.80\",\"0.021\"],[\"79508.20\",\"6.169\"],[\"79511.20\",\"2.909\"],[\"79536.80\",\"3.585\"],[\"79542.30\",\"0.002\"],[\"79557.50\",\"1.848\"],[\"79564.80\",\"0.002\"],[\"79566.10\",\"0.454\"],[\"79567.00\",\"0.002\"],[\"79572.60\",\"0.000\"],[\"79573.20\",\"0.440\"],[\"79573.50\",\"0.373\"],[\"79574.70\",\"0.001\"],[\"79575.30\",\"0.001\"],[\"79598.10\",\"10.892\"]],\"a\":[[\"79599.20\",\"0.017\"],[\"79600.30\",\"0.031\"],[\"79606.10\",\"0.252\"],[\"79609.50\",\"0.009\"],[\"79610.20\",\"0.010\"],[\"79611.10\",\"1.038\"],[\"79611.40\",\"0.859\"],[\"79613.70\",\"0.000\"],[\"79614.60\",\"0.373\"],[\"79615.90\",\"0.110\"],[\"79616.90\",\"0.456\"],[\"79628.10\",\"0.016\"],[\"79629.30\",\"0.068\"],[\"79632.20\",\"0.427\"],[\"79652.80\",\"1.697\"],[\"79652.90\",\"3.595\"],[\"79654.60\",\"0.000\"],[\"79669.90\",\"0.002\"],[\"79680.10\",\"2.734\"],[\"79681.60\",\"6.147\"],[\"79724.40\",\"0.464\"],[\"79737.40\",\"0.006\"],[\"79740.20\",\"0.002\"],[\"79740.40\",\"0.000\"],[\"79961.60\",\"0.183\"],[\"79966.30\",\"0.855\"],[\"79996.20\",\"1.103\"],[\"80190.60\",\"0.000\"],[\"80394.20\",\"4.235\"],[\"80594.00\",\"1.247\"],[\"80647.60\",\"4.331\"]],\"st\":1}}"}
{"receive_ns":1788563041364343000,"stream":"btcusdt@bookTicker","event_type":"bookTicker","event_time_ms":1788563041426,"raw_json":"{\"stream\":\"btcusdt@bookTicker\",\"data\":{\"e\":\"bookTicker\",\"u\":11478212501824,\"s\":\"BTCUSDT\",\"ps\":\"BTCUSDT\",\"b\":\"79598.10\",\"B\":\"10.898\",\"a\":\"79598.20\",\"A\":\"3.367\",\"T\":1788563041426,\"E\":1788563041426,\"st\":1}}"}
{"receive_ns":1788563041406780000,"stream":"btcusdt@bookTicker","event_type":"bookTicker","event_time_ms":1788563041471,"raw_json":"{\"stream\":\"btcusdt@bookTicker\",\"data\":{\"e\":\"bookTicker\",\"u\":11478212504276,\"s\":\"BTCUSDT\",\"ps\":\"BTCUSDT\",\"b\":\"79598.10\",\"B\":\"10.898\",\"a\":\"79598.20\",\"A\":\"3.370\",\"T\":1788563041470,\"E\":1788563041471,\"st\":1}}"}
{"receive_ns":1788563041407232000,"stream":"btcusdt@trade","event_type":"trade","event_time_ms":1788563041471,"raw_json":"{\"stream\":\"btcusdt@trade\",\"data\":{\"e\":\"trade\",\"E\":1788563041471,\"T\":1788563041471,\"s\":\"BTCUSDT\",\"t\":8054081710,\"p\":\"0\",\"q\":\"0\",\"X\":\"NA\",\"m\":false,\"st\":1}}"}
{"receive_ns":1788563041409460000,"stream":"btcusdt@bookTicker","event_type":"bookTicker","event_time_ms":1788563041474,"raw_json":"{\"stream\":\"btcusdt@bookTicker\",\"data\":{\"e\":\"bookTicker\",\"u\":11478212504509,\"s\":\"BTCUSDT\",\"ps\":\"BTCUSDT\",\"b\":\"79598.10\",\"B\":\"10.898\",\"a\":\"79598.20\",\"A\":\"3.369\",\"T\":1788563041474,\"E\":1788563041474,\"st\":1}}"}
{"receive_ns":1788563041417988000,"stream":"btcusdt@depth@100ms","event_type":"depthUpdate","event_time_ms":1788563041481,"raw_json":"{\"stream\":\"btcusdt@depth@100ms\",\"data\":{\"e\":\"depthUpdate\",\"E\":1788563041481,\"T\":1788563041479,\"s\":\"BTCUSDT\",\"ps\":\"BTCUSDT\",\"U\":11478212498096,\"u\":11478212504692,\"pu\":11478212497841,\"b\":[[\"1000.00\",\"24.604\"],[\"29298.10\",\"1.680\"],[\"29398.10\",\"0.420\"],[\"71638.20\",\"0.002\"],[\"71675.00\",\"0.002\"],[\"72114.80\",\"0.000\"],[\"72279.40\",\"0.000\"],[\"76414.10\",\"0.000\"],[\"78682.70\",\"1.626\"],[\"78784.50\",\"4.021\"],[\"78802.10\",\"3.943\"],[\"79200.10\",\"0.152\"],[\"79439.80\",\"0.202\"],[\"79440.90\",\"2.436\"],[\"79442.90\",\"0.502\"],[\"79473.80\",\"0.533\"],[\"79494.60\",\"0.000\"],[\"79526.40\",\"0.003\"],[\"79598.10\",\"10.898\"]],\"a\":[[\"79598.20\",\"3.369\"],[\"79600.30\",\"0.005\"],[\"79693.80\",\"0.002\"],[\"79722.80\",\"0.937\"],[\"79735.50\",\"0.275\"],[\"79961.60\",\"0.002\"],[\"79962.40\",\"0.419\"],[\"79996.20\",\"1.103\"],[\"80394.20\",\"4.235\"],[\"80465.80\",\"1.499\"],[\"80468.00\",\"2.848\"],[\"80635.00\",\"0.269\"]],\"st\":1}}"}
{"receive_ns":1788563041447723000,"stream":"btcusdt@bookTicker","event_type":"bookTicker","event_time_ms":1788563041512,"raw_json":"{\"stream\":\"btcusdt@bookTicker\",\"data\":{\"e\":\"bookTicker\",\"u\":11478212507625,\"s\":\"BTCUSDT\",\"ps\":\"BTCUSDT\",\"b\":\"79598.10\",\"B\":\"10.858\",\"a\":\"79598.20\",\"A\":\"3.369\",\"T\":1788563041512,\"E\":1788563041512,\"st\":1}}"}
{"receive_ns":1788563041450687000,"stream":"btcusdt@bookTicker","event_type":"bookTicker","event_time_ms":1788563041515,"raw_json":"{\"stream\":\"btcusdt@bookTicker\",\"data\":{\"e\":\"bookTicker\",\"u\":11478212507878,\"s\":\"BTCUSDT\",\"ps\":\"BTCUSDT\",\"b\":\"79598.10\",\"B\":\"10.899\",\"a\":\"79598.20\",\"A\":\"3.369\",\"T\":1788563041515,\"E\":1788563041515,\"st\":1}}"}
{"receive_ns":1788563041451621000,"stream":"btcusdt@bookTicker","event_type":"bookTicker","event_time_ms":1788563041516,"raw_json":"{\"stream\":\"btcusdt@bookTicker\",\"data\":{\"e\":\"bookTicker\",\"u\":11478212507952,\"s\":\"BTCUSDT\",\"ps\":\"BTCUSDT\",\"b\":\"79598.10\",\"B\":\"10.897\",\"a\":\"79598.20\",\"A\":\"3.369\",\"T\":1788563041516,\"E\":1788563041516,\"st\":1}}"}
{"receive_ns":1788563041505045000,"stream":"btcusdt@bookTicker","event_type":"bookTicker","event_time_ms":1788563041569,"raw_json":"{\"stream\":\"btcusdt@bookTicker\",\"data\":{\"e\":\"bookTicker\",\"u\":11478212510752,\"s\":\"BTCUSDT\",\"ps\":\"BTCUSDT\",\"b\":\"79598.10\",\"B\":\"10.881\",\"a\":\"79598.20\",\"A\":\"3.369\",\"T\":1788563041568,\"E\":1788563041569,\"st\":1}}"}
{"receive_ns":1788563041518330000,"stream":"btcusdt@depth@100ms","event_type":"depthUpdate","event_time_ms":1788563041583,"raw_json":"{\"stream\":\"btcusdt@depth@100ms\",\"data\":{\"e\":\"depthUpdate\",\"E\":1788563041583,\"T\":1788563041581,\"s\":\"BTCUSDT\",\"ps\":\"BTCUSDT\",\"U\":11478212504814,\"u\":11478212511967,\"pu\":11478212504692,\"b\":[[\"1000.00\",\"24.604\"],[\"29198.10\",\"0.035\"],[\"29298.10\",\"1.792\"],[\"29398.10\",\"0.273\"],[\"71638.20\",\"0.002\"],[\"72444.10\",\"0.000\"],[\"72608.70\",\"0.000\"],[\"78642.90\",\"7.657\"],[\"78802.10\",\"3.943\"],[\"79401.10\",\"0.232\"],[\"79440.90\",\"1.105\"],[\"79467.60\",\"10.255\"],[\"79494.60\",\"1.331\"],[\"79507.10\",\"3.408\"],[\"79507.90\",\"0.011\"],[\"79563.30\",\"0.047\"],[\"79564.30\",\"0.252\"],[\"79565.30\",\"0.648\"],[\"79566.10\",\"0.002\"],[\"79572.60\",\"0.373\"],[\"79573.30\",\"0.000\"],[\"79573.50\",\"0.000\"],[\"79598.10\",\"10.881\"]],\"a\":[[\"79600.50\",\"0.486\"],[\"79600.90\",\"0.080\"],[\"79603.20\",\"0.004\"],[\"79606.10\",\"0.001\"],[\"79609.50\",\"0.017\"],[\"79609.60\",\"0.697\"],[\"79610.20\",\"0.002\"],[\"79611.40\",\"0.420\"],[\"79612.50\",\"0.635\"],[\"79614.60\",\"0.001\"],[\"79614.70\",\"0.001\"],[\"79615.90\",\"0.562\"],[\"79616.90\",\"0.004\"],[\"79627.10\",\"0.046\"],[\"79629.30\",\"0.022\"],[\"79678.40\",\"0.044\"],[\"79684.10\",\"0.001\"],[\"79685.30\",\"0.212\"],[\"79691.10\",\"7.707\"],[\"79696.80\",\"0.100\"],[\"79703.10\",\"0.015\"],[\"79711.90\",\"0.000\"],[\"79724.40\",\"0.470\"],[\"79724.50\",\"10.244\"],[\"79735.50\",\"0.526\"],[\"79736.40\",\"0.011\"],[\"79737.40\",\"0.000\"],[\"79821.90\",\"8.192\"],[\"79822.10\",\"0.000\"],[\"79962.40\",\"1.273\"],[\"79966.30\",\"0.001\"],[\"79996.20\",\"1.103\"],[\"80394.20\",\"4.235\"],[\"80806.50\",\"13.898\"],[\"81190.10\",\"0.011\"]],\"st\":1}}"}
{"receive_ns":1788563041620578000,"stream":"btcusdt@depth@100ms","event_type":"depthUpdate","event_time_ms":1788563041685,"raw_json":"{\"stream\":\"btcusdt@depth@100ms\",\"data\":{\"e\":\"depthUpdate\",\"E\":1788563041685,\"T\":1788563041683,\"s\":\"BTCUSDT\",\"ps\":\"BTCUSDT\",\"U\":11478212512159,\"u\":11478212518965,\"pu\":11478212511967,\"b\":[[\"29198.10\",\"0.098\"],[\"29298.10\",\"1.841\"],[\"29398.10\",\"0.161\"],[\"63678.00\",\"0.002\"],[\"63678.50\",\"0.000\"],[\"71638.20\",\"0.002\"],[\"72773.30\",\"0.000\"],[\"72938.00\",\"0.000\"],[\"76414.10\",\"0.002\"],[\"78006.20\",\"0.018\"],[\"78228.40\",\"0.000\"],[\"78423.70\",\"0.000\"],[\"78483.70\",\"9.798\"],[\"78642.90\",\"8.927\"],[\"78802.10\",\"3.943\"],[\"79200.10\",\"0.152\"],[\"79439.80\",\"0.001\"],[\"79440.90\",\"0.100\"],[\"79442.90\",\"0.000\"],[\"79492.60\",\"1.006\"],[\"79563.30\",\"0.001\"],[\"79564.20\",\"0.733\"],[\"79565.60\",\"0.002\"],[\"79572.60\",\"0.000\"],[\"79573.20\",\"0.001\"],[\"79573.30\",\"0.439\"],[\"79573.50\",\"0.373\"],[\"79574.40\",\"0.050\"],[\"79574.70\",\"0.001\"],[\"79575.30\",\"0.001\"]],\"a\":[[\"79600.90\",\"0.106\"],[\"79609.50\",\"0.009\"],[\"79609.60\",\"0.258\"],[\"79610.20\",\"0.010\"],[\"79611.40\",\"0.859\"],[\"79612.50\",\"0.263\"],[\"79613.70\",\"0.000\"],[\"79614.30\",\"0.361\"],[\"79614.60\",\"0.373\"],[\"79627.10\",\"0.000\"],[\"79628.30\",\"0.000\"],[\"79629.40\",\"0.826\"],[\"79702.60\",\"0.018\"],[\"79735.50\",\"0.526\"],[\"79962.40\",\"0.854\"],[\"79996.20\",\"1.103\"],[\"80230.50\",\"1.796\"],[\"80394.20\",\"4.235\"],[\"80635.00\",\"0.517\"],[\"80745.30\",\"0.278\"]],\"st\":1}}"}
{"receive_ns":1788563041664077000,"stream":"btcusdt@bookTicker","event_type":"bookTicker","event_time_ms":1788563041728,"raw_json":"{\"stream\":\"btcusdt@bookTicker\",\"data\":{\"e\":\"bookTicker\",\"u\":11478212521476,\"s\":\"BTCUSDT\",\"ps\":\"BTCUSDT\",\"b\":\"79598.10\",\"B\":\"10.881\",\"a\":\"79598.20\",\"A\":\"3.371\",\"T\":1788563041728,\"E\":1788563041728,\"st\":1}}"}
{"receive_ns":1788563041691711000,"stream":"btcusdt@bookTicker","event_type":"bookTicker","event_time_ms":1788563041748,"raw_json":"{\"stream\":\"btcusdt@bookTicker\",\"data\":{\"e\":\"bookTicker\",\"u\":11478212522485,\"s\":\"BTCUSDT\",\"ps\":\"BTCUSDT\",\"b\":\"79598.10\",\"B\":\"10.881\",\"a\":\"79598.20\",\"A\":\"3.368\",\"T\":1788563041748,\"E\":1788563041748,\"st\":1}}"}
{"receive_ns":1788563041691979000,"stream":"btcusdt@bookTicker","event_type":"bookTicker","event_time_ms":1788563041753,"raw_json":"{\"stream\":\"btcusdt@bookTicker\",\"data\":{\"e\":\"bookTicker\",\"u\":11478212522683,\"s\":\"BTCUSDT\",\"ps\":\"BTCUSDT\",\"b\":\"79598.10\",\"B\":\"10.881\",\"a\":\"79598.20\",\"A\":\"3.369\",\"T\":1788563041753,\"E\":1788563041753,\"st\":1}}"}
{"receive_ns":1788563041721831000,"stream":"btcusdt@depth@100ms","event_type":"depthUpdate","event_time_ms":1788563041787,"raw_json":"{\"stream\":\"btcusdt@depth@100ms\",\"data\":{\"e\":\"depthUpdate\",\"E\":1788563041787,\"T\":1788563041786,\"s\":\"BTCUSDT\",\"ps\":\"BTCUSDT\",\"U\":11478212519101,\"u\":11478212524766,\"pu\":11478212518965,\"b\":[[\"1000.00\",\"24.754\"],[\"29198.10\",\"0.154\"],[\"29298.10\",\"1.911\"],[\"29398.10\",\"0.035\"],[\"63678.00\",\"0.002\"],[\"71638.20\",\"0.002\"],[\"73102.60\",\"0.000\"],[\"73267.30\",\"0.000\"],[\"76414.10\",\"0.000\"],[\"78483.70\",\"11.707\"],[\"78802.10\",\"3.943\"],[\"79200.10\",\"0.152\"],[\"79239.90\",\"0.828\"],[\"79401.10\",\"0.232\"],[\"79439.80\",\"0.202\"],[\"79440.90\",\"0.602\"],[\"79473.20\",\"0.078\"],[\"79473.80\",\"0.576\"],[\"79494.60\",\"1.331\"],[\"79592.20\",\"0.049\"]],\"a\":[[\"79598.20\",\"3.369\"],[\"79600.50\",\"0.512\"],[\"79722.70\",\"0.378\"],[\"79722.80\",\"0.613\"],[\"79735.50\",\"0.526\"],[\"79736.40\",\"0.211\"],[\"79739.70\",\"0.002\"],[\"79739.90\",\"0.000\"],[\"79740.10\",\"0.001\"],[\"79962.40\",\"1.273\"],[\"79996.20\",\"1.103\"],[\"80394.20\",\"4.235\"],[\"80568.10\",\"3.871\"],[\"81190.10\",\"0.008\"]],\"st\":1}}"}
{"receive_ns":1788563041745081000,"stream":"btcusdt@bookTicker","event_type":"bookTicker","event_time_ms":1788563041809,"raw_json":"{\"stream\":\"btcusdt@bookTicker\",\"data\":{\"e\":\"bookTicker\",\"u\":11478212526358,\"s\":\"BTCUSDT\",\"ps\":\"BTCUSDT\",\"b\":\"79598.10\",\"B\":\"10.882\",\"a\":\"79598.20\",\"A\":\"3.369\",\"T\":1788563041809,\"E\":1788563041809,\"st\":1}}"}
{"receive_ns":1788563041824027000,"stream":"btcusdt@bookTicker","event_type":"bookTicker","event_time_ms":1788563041883,"raw_json":"{\"stream\":\"btcusdt@bookTicker\",\"data\":{\"e\":\"bookTicker\",\"u\":11478212530462,\"s\":\"BTCUSDT\",\"ps\":\"BTCUSDT\",\"b\":\"79598.10\",\"B\":\"10.882\",\"a\":\"79598.20\",\"A\":\"3.368\",\"T\":1788563041882,\"E\":1788563041883,\"st\":1}}"}
{"receive_ns":1788563041824861000,"stream":"btcusdt@depth@100ms","event_type":"depthUpdate","event_time_ms":1788563041889,"raw_json":"{\"stream\":\"btcusdt@depth@100ms\",\"data\":{\"e\":\"depthUpdate\",\"E\":1788563041889,\"T\":1788563041888,\"s\":\"BTCUSDT\",\"ps\":\"BTCUSDT\",\"U\":11478212524837,\"u\":11478212530737,\"pu\":11478212524766,\"b\":[[\"1000.00\",\"24.604\"],[\"29198.10\",\"0.294\"],[\"29298.10\",\"1.806\"],[\"29398.10\",\"0.000\"],[\"63678.00\",\"0.002\"],[\"71638.20\",\"0.002\"],[\"73431.90\",\"0.003\"],[\"73596.60\",\"0.001\"],[\"76414.10\",\"0.002\"],[\"78443.90\",\"1.121\"],[\"78802.10\",\"3.943\"],[\"79200.10\",\"0.011\"],[\"79492.60\",\"0.001\"],[\"79561.30\",\"0.203\"],[\"79571.50\",\"0.004\"],[\"79572.10\",\"0.518\"],[\"79573.30\",\"0.000\"],[\"79573.50\",\"0.413\"],[\"79589.20\",\"0.024\"],[\"79592.20\",\"0.049\"],[\"79598.10\",\"10.882\"]],\"a\":[[\"79598.20\",\"3.368\"],[\"79600.50\",\"0.486\"],[\"79735.50\",\"0.275\"],[\"79739.60\",\"0.001\"],[\"79739.70\",\"0.002\"],[\"79740.00\",\"0.500\"],[\"79740.20\",\"0.127\"],[\"79996.20\",\"0.577\"],[\"80394.20\",\"4.235\"],[\"80593.20\",\"1.048\"],[\"80633.00\",\"0.574\"]],\"st\":1}}"}
{"receive_ns":1788563041830929000,"stream":"btcusdt@bookTicker","event_type":"bookTicker","event_time_ms":1788563041895,"raw_json":"{\"stream\":\"btcusdt@bookTicker\",\"data\":{\"e\":\"bookTicker\",\"u\":11478212531058,\"s\":\"BTCUSDT\",\"ps\":\"BTCUSDT\",\"b\":\"79598.10\",\"B\":\"10.882\",\"a\":\"79598.20\",\"A\":\"3.268\",\"T\":1788563041895,\"E\":1788563041895,\"st\":1}}"}
{"receive_ns":1788563041831190000,"stream":"btcusdt@trade","event_type":"trade","event_time_ms":1788563041895,"raw_json":"{\"stream\":\"btcusdt@trade\",\"data\":{\"e\":\"trade\",\"E\":1788563041895,\"T\":1788563041895,\"s\":\"BTCUSDT\",\"t\":8054081711,\"p\":\"79598.20\",\"q\":\"0.100\",\"X\":\"MARKET\",\"m\":false,\"st\":1}}"}
{"receive_ns":1788563041832433000,"stream":"btcusdt@bookTicker","event_type":"bookTicker","event_time_ms":1788563041897,"raw_json":"{\"stream\":\"btcusdt@bookTicker\",\"data\":{\"e\":\"bookTicker\",\"u\":11478212531178,\"s\":\"BTCUSDT\",\"ps\":\"BTCUSDT\",\"b\":\"79598.10\",\"B\":\"10.890\",\"a\":\"79598.20\",\"A\":\"3.268\",\"T\":1788563041896,\"E\":1788563041897,\"st\":1}}"}
{"receive_ns":1788563041832606000,"stream":"btcusdt@bookTicker","event_type":"bookTicker","event_time_ms":1788563041897,"raw_json":"{\"stream\":\"btcusdt@bookTicker\",\"data\":{\"e\":\"bookTicker\",\"u\":11478212531195,\"s\":\"BTCUSDT\",\"ps\":\"BTCUSDT\",\"b\":\"79598.10\",\"B\":\"10.890\",\"a\":\"79598.20\",\"A\":\"3.267\",\"T\":1788563041897,\"E\":1788563041897,\"st\":1}}"}
{"receive_ns":1788563041832834000,"stream":"btcusdt@bookTicker","event_type":"bookTicker","event_time_ms":1788563041897,"raw_json":"{\"stream\":\"btcusdt@bookTicker\",\"data\":{\"e\":\"bookTicker\",\"u\":11478212531334,\"s\":\"BTCUSDT\",\"ps\":\"BTCUSDT\",\"b\":\"79598.10\",\"B\":\"10.882\",\"a\":\"79598.20\",\"A\":\"3.267\",\"T\":1788563041897,\"E\":1788563041897,\"st\":1}}"}
{"receive_ns":1788563041833763000,"stream":"btcusdt@bookTicker","event_type":"bookTicker","event_time_ms":1788563041898,"raw_json":"{\"stream\":\"btcusdt@bookTicker\",\"data\":{\"e\":\"bookTicker\",\"u\":11478212531386,\"s\":\"BTCUSDT\",\"ps\":\"BTCUSDT\",\"b\":\"79598.10\",\"B\":\"10.882\",\"a\":\"79598.20\",\"A\":\"3.268\",\"T\":1788563041898,\"E\":1788563041898,\"st\":1}}"}
{"receive_ns":1788563041928078000,"stream":"btcusdt@depth@100ms","event_type":"depthUpdate","event_time_ms":1788563041991,"raw_json":"{\"stream\":\"btcusdt@depth@100ms\",\"data\":{\"e\":\"depthUpdate\",\"E\":1788563041991,\"T\":1788563041990,\"s\":\"BTCUSDT\",\"ps\":\"BTCUSDT\",\"U\":11478212530821,\"u\":11478212536420,\"pu\":11478212530737,\"b\":[[\"29198.10\",\"0.476\"],[\"29298.10\",\"1.624\"],[\"63679.00\",\"0.002\"],[\"71638.20\",\"0.002\"],[\"73761.20\",\"0.000\"],[\"76414.10\",\"0.000\"],[\"78244.90\",\"2.170\"],[\"78364.30\",\"1.793\"],[\"78443.90\",\"2.012\"],[\"78802.10\",\"3.943\"],[\"79200.10\",\"0.152\"],[\"79401.10\",\"0.000\"],[\"79439.80\",\"0.202\"],[\"79440.90\",\"1.507\"],[\"79494.60\",\"0.000\"],[\"79561.30\",\"0.203\"],[\"79571.20\",\"0.000\"],[\"79572.10\",\"0.079\"],[\"79572.40\",\"0.274\"],[\"79572.50\",\"0.382\"],[\"79573.20\",\"0.440\"],[\"79573.50\",\"0.373\"],[\"79575.30\",\"0.001\"],[\"79575.50\",\"0.009\"],[\"79578.20\",\"0.417\"],[\"79589.20\",\"0.004\"],[\"79592.70\",\"0.253\"],[\"79596.40\",\"0.149\"],[\"79598.10\",\"10.882\"]],\"a\":[[\"79598.20\",\"3.268\"],[\"79599.40\",\"0.014\"],[\"79600.90\",\"0.080\"],[\"79601.10\",\"0.003\"],[\"79601.20\",\"0.001\"],[\"79601.40\",\"0.026\"],[\"79602.00\",\"0.077\"],[\"79602.10\",\"0.028\"],[\"79602.30\",\"0.026\"],[\"79603.10\",\"0.226\"],[\"79603.20\",\"0.030\"],[\"79612.30\",\"0.001\"],[\"79613.40\",\"0.003\"],[\"79735.50\",\"0.024\"],[\"79736.40\",\"0.011\"],[\"79739.70\",\"0.002\"],[\"79740.20\",\"0.127\"],[\"79820.90\",\"0.000\"],[\"79821.00\",\"0.091\"],[\"79962.40\",\"0.419\"],[\"79996.20\",\"0.902\"],[\"80235.00\",\"1.253\"],[\"80394.20\",\"4.235\"],[\"80548.80\",\"9.915\"]],\"st\":1}}"}
{"receive_ns":1788563041943856000,"stream":"btcusdt@bookTicker","event_type":"bookTicker","event_time_ms":1788563042009,"raw_json":"{\"stream\":\"btcusdt@bookTicker\",\"data\":{\"e\":\"bookTicker\",\"u\":11478212537441,\"s\":\"BTCUSDT\",\"ps\":\"BTCUSDT\",\"b\":\"79598.10\",\"B\":\"10.905\",\"a\":\"79598.20\",\"A\":\"3.268\",\"T\":1788563042009,\"E\":1788563042009,\"st\":1}}"}
{"receive_ns":1788563041946365000,"stream":"btcusdt@bookTicker","event_type":"bookTicker","event_time_ms":1788563042010,"raw_json":"{\"stream\":\"btcusdt@bookTicker\",\"data\":{\"e\":\"bookTicker\",\"u\":11478212537512,\"s\":\"BTCUSDT\",\"ps\":\"BTCUSDT\",\"b\":\"79598.10\",\"B\":\"10.907\",\"a\":\"79598.20\",\"A\":\"3.268\",\"T\":1788563042010,\"E\":1788563042010,\"st\":1}}"}
{"receive_ns":1788563041971383000,"stream":"btcusdt@bookTicker","event_type":"bookTicker","event_time_ms":1788563042034,"raw_json":"{\"stream\":\"btcusdt@bookTicker\",\"data\":{\"e\":\"bookTicker\",\"u\":11478212538770,\"s\":\"BTCUSDT\",\"ps\":\"BTCUSDT\",\"b\":\"79598.10\",\"B\":\"10.915\",\"a\":\"79598.20\",\"A\":\"3.268\",\"T\":1788563042033,\"E\":1788563042034,\"st\":1}}"}
{"receive_ns":1788563041971888000,"stream":"btcusdt@bookTicker","event_type":"bookTicker","event_time_ms":1788563042034,"raw_json":"{\"stream\":\"btcusdt@bookTicker\",\"data\":{\"e\":\"bookTicker\",\"u\":11478212538898,\"s\":\"BTCUSDT\",\"ps\":\"BTCUSDT\",\"b\":\"79598.10\",\"B\":\"10.907\",\"a\":\"79598.20\",\"A\":\"3.268\",\"T\":1788563042034,\"E\":1788563042034,\"st\":1}}"}
{"receive_ns":1788563042012531000,"stream":"btcusdt@bookTicker","event_type":"bookTicker","event_time_ms":1788563042075,"raw_json":"{\"stream\":\"btcusdt@bookTicker\",\"data\":{\"e\":\"bookTicker\",\"u\":11478212541713,\"s\":\"BTCUSDT\",\"ps\":\"BTCUSDT\",\"b\":\"79598.10\",\"B\":\"10.881\",\"a\":\"79598.20\",\"A\":\"3.268\",\"T\":1788563042075,\"E\":1788563042075,\"st\":1}}"}
{"receive_ns":1788563042015878000,"stream":"btcusdt@bookTicker","event_type":"bookTicker","event_time_ms":1788563042079,"raw_json":"{\"stream\":\"btcusdt@bookTicker\",\"data\":{\"e\":\"bookTicker\",\"u\":11478212541894,\"s\":\"BTCUSDT\",\"ps\":\"BTCUSDT\",\"b\":\"79598.10\",\"B\":\"10.914\",\"a\":\"79598.20\",\"A\":\"3.268\",\"T\":1788563042079,\"E\":1788563042079,\"st\":1}}"}
{"receive_ns":1788563042028322000,"stream":"btcusdt@depth@100ms","event_type":"depthUpdate","event_time_ms":1788563042093,"raw_json":"{\"stream\":\"btcusdt@depth@100ms\",\"data\":{\"e\":\"depthUpdate\",\"E\":1788563042093,\"T\":1788563042091,\"s\":\"BTCUSDT\",\"ps\":\"BTCUSDT\",\"U\":11478212536448,\"u\":11478212542521,\"pu\":11478212536420,\"b\":[[\"1000.00\",\"24.604\"],[\"29198.10\",\"0.651\"],[\"29298.10\",\"1.449\"],[\"63679.00\",\"0.000\"],[\"71638.20\",\"0.002\"],[\"73925.90\",\"0.002\"],[\"74090.50\",\"0.000\"],[\"75599.80\",\"0.010\"],[\"78361.80\",\"0.000\"],[\"78802.10\",\"3.943\"],[\"79200.10\",\"0.153\"],[\"79401.10\",\"0.232\"],[\"79426.30\",\"5.320\"],[\"79428.00\",\"1.282\"],[\"79439.10\",\"0.000\"],[\"79440.90\",\"2.938\"],[\"79457.60\",\"6.961\"],[\"79556.10\",\"0.004\"],[\"79564.50\",\"0.344\"],[\"79569.00\",\"0.040\"],[\"79572.40\",\"0.254\"],[\"79572.50\",\"0.342\"],[\"79576.20\",\"0.001\"],[\"79583.60\",\"0.035\"],[\"79583.80\",\"0.000\"],[\"79584.00\",\"0.012\"],[\"79584.10\",\"0.132\"],[\"79584.50\",\"0.017\"],[\"79584.70\",\"0.001\"],[\"79589.10\",\"0.001\"],[\"79589.60\",\"0.136\"],[\"79592.20\",\"0.049\"],[\"79598.10\",\"10.914\"]],\"a\":[[\"79598.80\",\"0.015\"],[\"79600.60\",\"0.026\"],[\"79600.70\",\"0.028\"],[\"79600.90\",\"0.106\"],[\"79601.10\",\"0.029\"],[\"79601.30\",\"0.026\"],[\"79601.40\",\"0.000\"],[\"79601.50\",\"0.029\"],[\"79601.60\",\"0.026\"],[\"79602.80\",\"0.000\"],[\"79602.90\",\"0.001\"],[\"79603.00\",\"0.000\"],[\"79603.10\",\"0.200\"],[\"79603.20\",\"0.004\"],[\"79606.10\",\"0.252\"],[\"79609.50\",\"0.017\"],[\"79610.20\",\"0.441\"],[\"79611.40\",\"0.420\"],[\"79613.40\",\"0.375\"],[\"79614.60\",\"0.001\"],[\"79628.00\",\"2.050\"],[\"79629.40\",\"0.780\"],[\"79739.40\",\"0.000\"],[\"79740.00\",\"0.500\"],[\"79740.10\",\"0.001\"],[\"79740.20\",\"0.002\"],[\"79962.40\",\"1.273\"],[\"79996.20\",\"1.102\"],[\"80394.20\",\"4.235\"],[\"80745.30\",\"0.000\"],[\"80812.80\",\"0.000\"]],\"st\":1}}"}
{"receive_ns":1788563042035590000,"stream":"btcusdt@bookTicker","event_type":"bookTicker","event_time_ms":1788563042099,"raw_json":"{\"stream\":\"btcusdt@bookTicker\",\"data\":{\"e\":\"bookTicker\",\"u\":11478212542923,\"s\":\"BTCUSDT\",\"ps\":\"BTCUSDT\",\"b\":\"79598.10\",\"B\":\"10.891\",\"a\":\"79598.20\",\"A\":\"3.268\",\"T\":1788563042099,\"E\":1788563042099,\"st\":1}}"}
{"receive_ns":1788563042037343000,"stream":"btcusdt@bookTicker","event_type":"bookTicker","event_time_ms":1788563042102,"raw_json":"{\"stream\":\"btcusdt@bookTicker\",\"data\":{\"e\":\"bookTicker\",\"u\":11478212543164,\"s\":\"BTCUSDT\",\"ps\":\"BTCUSDT\",\"b\":\"79598.10\",\"B\":\"10.915\",\"a\":\"79598.20\",\"A\":\"3.268\",\"T\":1788563042102,\"E\":1788563042102,\"st\":1}}"}
{"receive_ns":1788563042120650000,"stream":"btcusdt@bookTicker","event_type":"bookTicker","event_time_ms":1788563042186,"raw_json":"{\"stream\":\"btcusdt@bookTicker\",\"data\":{\"e\":\"bookTicker\",\"u\":11478212548164,\"s\":\"BTCUSDT\",\"ps\":\"BTCUSDT\",\"b\":\"79598.10\",\"B\":\"10.915\",\"a\":\"79598.20\",\"A\":\"3.267\",\"T\":1788563042185,\"E\":1788563042186,\"st\":1}}"}
{"receive_ns":1788563042121014000,"stream":"btcusdt@trade","event_type":"trade","event_time_ms":1788563042186,"raw_json":"{\"stream\":\"btcusdt@trade\",\"data\":{\"e\":\"trade\",\"E\":1788563042186,\"T\":1788563042185,\"s\":\"BTCUSDT\",\"t\":8054081712,\"p\":\"79598.20\",\"q\":\"0.001\",\"X\":\"MARKET\",\"m\":false,\"st\":1}}"}
