{"receive_ns":1788563042121324000,"stream":"btcusdt@bookTicker","event_type":"bookTicker","event_time_ms":1788563042187,"raw_json":"{\"stream\":\"btcusdt@bookTicker\",\"data\":{\"e\":\"bookTicker\",\"u\":11478212548278,\"s\":\"BTCUSDT\",\"ps\":\"BTCUSDT\",\"b\":\"79598.10\",\"B\":\"10.923\",\"a\":\"79598.20\",\"A\":\"3.267\",\"T\":1788563042187,\"E\":1788563042187,\"st\":1}}"}
{"receive_ns":1788563042125211000,"stream":"btcusdt@bookTicker","event_type":"bookTicker","event_time_ms":1788563042188,"raw_json":"{\"stream\":\"btcusdt@bookTicker\",\"data\":{\"e\":\"bookTicker\",\"u\":11478212548393,\"s\":\"BTCUSDT\",\"ps\":\"BTCUSDT\",\"b\":\"79598.10\",\"B\":\"10.915\",\"a\":\"79598.20\",\"A\":\"3.267\",\"T\":1788563042188,\"E\":1788563042188,\"st\":1}}"}
{"receive_ns":1788563042126795000,"stream":"btcusdt@bookTicker","event_type":"bookTicker","event_time_ms":1788563042191,"raw_json":"{\"stream\":\"btcusdt@bookTicker\",\"data\":{\"e\":\"bookTicker\",\"u\":11478212548586,\"s\":\"BTCUSDT\",\"ps\":\"BTCUSDT\",\"b\":\"79598.10\",\"B\":\"10.915\",\"a\":\"79598.20\",\"A\":\"3.266\",\"T\":1788563042191,\"E\":1788563042191,\"st\":1}}"}
{"receive_ns":1788563042127638000,"stream":"btcusdt@bookTicker","event_type":"bookTicker","event_time_ms":1788563042192,"raw_json":"{\"stream\":\"btcusdt@bookTicker\",\"data\":{\"e\":\"bookTicker\",\"u\":11478212548680,\"s\":\"BTCUSDT\",\"ps\":\"BTCUSDT\",\"b\":\"79598.10\",\"B\":\"10.915\",\"a\":\"79598.20\",\"A\":\"3.269\",\"T\":1788563042192,\"E\":1788563042192,\"st\":1}}"}
{"receive_ns":1788563042132412000,"stream":"btcusdt@depth@100ms","event_type":"depthUpdate","event_time_ms":1788563042195,"raw_json":"{\"stream\":\"btcusdt@depth@100ms\",\"data\":{\"e\":\"depthUpdate\",\"E\":1788563042195,\"T\":1788563042194,\"s\":\"BTCUSDT\",\"ps\":\"BTCUSDT\",\"U\":11478212542654,\"u\":11478212548754,\"pu\":11478212542521,\"b\":[[\"29198.10\",\"0.833\"],[\"29298.10\",\"1.267\"],[\"63679.00\",\"0.000\"],[\"71638.20\",\"0.002\"],[\"74255.20\",\"0.000\"],[\"74419.80\",\"0.000\"],[\"76414.10\",\"0.002\"],[\"78372.50\",\"0.021\"],[\"78411.50\",\"0.001\"],[\"78802.10\",\"3.943\"],[\"79200.10\",\"0.278\"],[\"79401.10\",\"0.734\"],[\"79439.80\",\"0.001\"],[\"79440.90\",\"1.431\"],[\"79442.00\",\"0.117\"],[\"79457.20\",\"5.531\"],[\"79462.80\",\"0.000\"],[\"79462.90\",\"0.003\"],[\"79492.60\",\"1.006\"],[\"79502.50\",\"0.003\"],[\"79526.40\",\"0.001\"],[\"79542.30\",\"0.000\"],[\"79558.30\",\"0.078\"],[\"79598.10\",\"10.915\"]],\"a\":[[\"79598.20\",\"3.269\"],[\"79600.60\",\"0.000\"],[\"79600.70\",\"0.002\"],[\"79600.80\",\"0.027\"],[\"79600.90\",\"0.080\"],[\"79601.70\",\"0.027\"],[\"79602.20\",\"0.254\"],[\"79603.10\",\"0.000\"],[\"79638.00\",\"0.006\"],[\"79653.70\",\"0.003\"],[\"79653.80\",\"0.038\"],[\"79669.90\",\"0.000\"],[\"79675.30\",\"0.004\"],[\"79680.40\",\"0.002\"],[\"79684.80\",\"0.001\"],[\"79684.90\",\"0.030\"],[\"79693.80\",\"0.000\"],[\"79698.90\",\"0.001\"],[\"79699.00\",\"0.109\"],[\"79699.10\",\"2.493\"],[\"79699.20\",\"0.000\"],[\"79699.30\",\"0.002\"],[\"79739.30\",\"0.000\"],[\"79739.70\",\"0.002\"],[\"79962.40\",\"1.273\"],[\"79996.20\",\"1.102\"],[\"80314.60\",\"3.729\"],[\"80389.60\",\"11.836\"],[\"80394.20\",\"4.237\"],[\"80633.00\",\"2.432\"],[\"80805.80\",\"0.000\"],[\"80926.00\",\"0.349\"]],\"st\":1}}"}
{"receive_ns":1788563042140976000,"stream":"btcusdt@bookTicker","event_type":"bookTicker","event_time_ms":1788563042204,"raw_json":"{\"stream\":\"btcusdt@bookTicker\",\"data\":{\"e\":\"bookTicker\",\"u\":11478212549583,\"s\":\"BTCUSDT\",\"ps\":\"BTCUSDT\",\"b\":\"79598.10\",\"B\":\"10.915\",\"a\":\"79598.20\",\"A\":\"3.268\",\"T\":1788563042204,\"E\":1788563042204,\"st\":1}}"}
{"receive_ns":1788563042191406000,"stream":"btcusdt@bookTicker","event_type":"bookTicker","event_time_ms":1788563042255,"raw_json":"{\"stream\":\"btcusdt@bookTicker\",\"data\":{\"e\":\"bookTicker\",\"u\":11478212552032,\"s\":\"BTCUSDT\",\"ps\":\"BTCUSDT\",\"b\":\"79598.10\",\"B\":\"10.931\",\"a\":\"79598.20\",\"A\":\"3.268\",\"T\":1788563042255,\"E\":1788563042255,\"st\":1}}"}
{"receive_ns":1788563042194623000,"stream":"btcusdt@bookTicker","event_type":"bookTicker","event_time_ms":1788563042258,"raw_json":"{\"stream\":\"btcusdt@bookTicker\",\"data\":{\"e\":\"bookTicker\",\"u\":11478212552201,\"s\":\"BTCUSDT\",\"ps\":\"BTCUSDT\",\"b\":\"79598.10\",\"B\":\"10.890\",\"a\":\"79598.20\",\"A\":\"3.268\",\"T\":1788563042258,\"E\":1788563042258,\"st\":1}}"}
{"receive_ns":1788563042199138000,"stream":"btcusdt@bookTicker","event_type":"bookTicker","event_time_ms":1788563042262,"raw_json":"{\"stream\":\"btcusdt@bookTicker\",\"data\":{\"e\":\"bookTicker\",\"u\":11478212552301,\"s\":\"BTCUSDT\",\"ps\":\"BTCUSDT\",\"b\":\"79598.10\",\"B\":\"10.933\",\"a\":\"79598.20\",\"A\":\"3.268\",\"T\":1788563042261,\"E\":1788563042262,\"st\":1}}"}
{"receive_ns":1788563042205877000,"stream":"btcusdt@bookTicker","event_type":"bookTicker","event_time_ms":1788563042269,"raw_json":"{\"stream\":\"btcusdt@bookTicker\",\"data\":{\"e\":\"bookTicker\",\"u\":11478212552615,\"s\":\"BTCUSDT\",\"ps\":\"BTCUSDT\",\"b\":\"79598.10\",\"B\":\"10.933\",\"a\":\"79598.20\",\"A\":\"3.266\",\"T\":1788563042269,\"E\":1788563042269,\"st\":1}}"}
{"receive_ns":1788563042227611000,"stream":"btcusdt@bookTicker","event_type":"bookTicker","event_time_ms":1788563042291,"raw_json":"{\"stream\":\"btcusdt@bookTicker\",\"data\":{\"e\":\"bookTicker\",\"u\":11478212553892,\"s\":\"BTCUSDT\",\"ps\":\"BTCUSDT\",\"b\":\"79598.10\",\"B\":\"10.932\",\"a\":\"79598.20\",\"A\":\"3.266\",\"T\":1788563042291,\"E\":1788563042291,\"st\":1}}"}
{"receive_ns":1788563042227891000,"stream":"btcusdt@bookTicker","event_type":"bookTicker","event_time_ms":1788563042292,"raw_json":"{\"stream\":\"btcusdt@bookTicker\",\"data\":{\"e\":\"bookTicker\",\"u\":11478212553926,\"s\":\"BTCUSDT\",\"ps\":\"BTCUSDT\",\"b\":\"79598.10\",\"B\":\"10.915\",\"a\":\"79598.20\",\"A\":\"3.266\",\"T\":1788563042292,\"E\":1788563042292,\"st\":1}}"}
{"receive_ns":1788563042233231000,"stream":"btcusdt@depth@100ms","event_type":"depthUpdate","event_time_ms":1788563042297,"raw_json":"{\"stream\":\"btcusdt@depth@100ms\",\"data\":{\"e\":\"depthUpdate\",\"E\":1788563042297,\"T\":1788563042295,\"s\":\"BTCUSDT\",\"ps\":\"BTCUSDT\",\"U\":11478212548812,\"u\":11478212554088,\"pu\":11478212548754,\"b\":[[\"29198.10\",\"1.008\"],[\"29298.10\",\"1.092\"],[\"71638.20\",\"0.002\"],[\"74584.50\",\"0.005\"],[\"74749.10\",\"0.000\"],[\"76414.10\",\"0.000\"],[\"78578.60\",\"9.375\"],[\"78802.10\",\"3.943\"],[\"79228.00\",\"0.245\"],[\"79401.10\",\"1.607\"],[\"79404.00\",\"1.215\"],[\"79440.90\",\"0.000\"],[\"79494.60\",\"0.326\"],[\"79561.40\",\"3.888\"],[\"79563.30\",\"0.001\"],[\"79564.20\",\"0.733\"],[\"79564.50\",\"0.344\"],[\"79565.60\",\"0.002\"],[\"79572.50\",\"0.342\"],[\"79573.20\",\"0.440\"],[\"79573.50\",\"0.373\"],[\"79574.70\",\"0.001\"],[\"79575.30\",\"0.001\"],[\"79592.20\",\"0.049\"],[\"79598.10\",\"10.915\"]],\"a\":[[\"79598.20\",\"3.266\"],[\"79600.30\",\"0.031\"],[\"79600.80\",\"0.001\"],[\"79600.90\",\"0.106\"],[\"79601.00\",\"0.034\"],[\"79602.10\",\"0.279\"],[\"79602.20\",\"0.003\"],[\"79602.70\",\"0.003\"],[\"79603.10\",\"0.000\"],[\"79603.50\",\"0.002\"],[\"79606.10\",\"0.001\"],[\"79609.50\",\"0.009\"],[\"79609.60\",\"0.258\"],[\"79610.20\",\"0.449\"],[\"79611.00\",\"1.004\"],[\"79611.20\",\"0.226\"],[\"79611.40\",\"0.420\"],[\"79612.40\",\"0.000\"],[\"79613.40\",\"0.375\"],[\"79613.70\",\"0.000\"],[\"79614.60\",\"0.001\"],[\"79627.10\",\"0.000\"],[\"79628.00\",\"2.050\"],[\"79628.30\",\"0.000\"],[\"79629.40\",\"0.780\"],[\"79654.20\",\"0.003\"],[\"79740.00\",\"0.625\"],[\"79962.40\",\"1.273\"],[\"79996.20\",\"1.102\"],[\"80394.20\",\"4.235\"],[\"80823.70\",\"0.008\"],[\"81243.60\",\"1.106\"]],\"st\":1}}"}
{"receive_ns":1788563042233535000,"stream":"btcusdt@bookTicker","event_type":"bookTicker","event_time_ms":1788563042297,"raw_json":"{\"stream\":\"btcusdt@bookTicker\",\"data\":{\"e\":\"bookTicker\",\"u\":11478212554140,\"s\":\"BTCUSDT\",\"ps\":\"BTCUSDT\",\"b\":\"79598.10\",\"B\":\"10.889\",\"a\":\"79598.20\",\"A\":\"3.266\",\"T\":1788563042297,\"E\":1788563042297,\"st\":1}}"}
{"receive_ns":1788563042237742000,"stream":"btcusdt@bookTicker","event_type":"bookTicker","event_time_ms":1788563042300,"raw_json":"{\"stream\":\"btcusdt@bookTicker\",\"data\":{\"e\":\"bookTicker\",\"u\":11478212554292,\"s\":\"BTCUSDT\",\"ps\":\"BTCUSDT\",\"b\":\"79598.10\",\"B\":\"10.921\",\"a\":\"79598.20\",\"A\":\"3.266\",\"T\":1788563042300,\"E\":1788563042300,\"st\":1}}"}
{"receive_ns":1788563042335892000,"stream":"btcusdt@depth@100ms","event_type":"depthUpdate","event_time_ms":1788563042399,"raw_json":"{\"stream\":\"btcusdt@depth@100ms\",\"data\":{\"e\":\"depthUpdate\",\"E\":1788563042399,\"T\":1788563042398,\"s\":\"BTCUSDT\",\"ps\":\"BTCUSDT\",\"U\":11478212554140,\"u\":11478212558751,\"pu\":11478212554088,\"b\":[[\"1000.00\",\"24.604\"],[\"29198.10\",\"1.190\"],[\"29298.10\",\"0.910\"],[\"63679.00\",\"0.000\"],[\"71638.20\",\"0.002\"],[\"75572.30\",\"0.000\"],[\"75737.00\",\"0.000\"],[\"76414.10\",\"0.002\"],[\"78643.50\",\"0.000\"],[\"78802.10\",\"3.943\"],[\"79200.10\",\"0.138\"],[\"79467.70\",\"3.379\"],[\"79492.60\",\"0.001\"],[\"79505.70\",\"0.001\"],[\"79507.20\",\"1.485\"],[\"79598.10\",\"10.921\"]],\"a\":[[\"79609.50\",\"0.017\"],[\"79610.20\",\"0.441\"],[\"79688.40\",\"1.842\"],[\"79724.40\",\"1.939\"],[\"79740.00\",\"0.500\"],[\"79962.30\",\"0.270\"],[\"79996.20\",\"0.575\"],[\"80394.20\",\"4.235\"],[\"80687.40\",\"11.390\"],[\"80953.60\",\"4.934\"],[\"81801.50\",\"0.245\"],[\"83578.10\",\"0.004\"]],\"st\":1}}"}
{"receive_ns":1788563042336166000,"stream":"btcusdt@bookTicker","event_type":"bookTicker","event_time_ms":1788563042399,"raw_json":"{\"stream\":\"btcusdt@bookTicker\",\"data\":{\"e\":\"bookTicker\",\"u\":11478212558801,\"s\":\"BTCUSDT\",\"ps\":\"BTCUSDT\",\"b\":\"79598.10\",\"B\":\"10.921\",\"a\":\"79598.20\",\"A\":\"3.267\",\"T\":1788563042399,\"E\":1788563042399,\"st\":1}}"}
{"receive_ns":1788563042336453000,"stream":"btcusdt@bookTicker","event_type":"bookTicker","event_time_ms":1788563042401,"raw_json":"{\"stream\":\"btcusdt@bookTicker\",\"data\":{\"e\":\"bookTicker\",\"u\":11478212558886,\"s\":\"BTCUSDT\",\"ps\":\"BTCUSDT\",\"b\":\"79598.10\",\"B\":\"10.921\",\"a\":\"79598.20\",\"A\":\"3.264\",\"T\":1788563042400,\"E\":1788563042401,\"st\":1}}"}
{"receive_ns":1788563042358590000,"stream":"btcusdt@bookTicker","event_type":"bookTicker","event_time_ms":1788563042422,"raw_json":"{\"stream\":\"btcusdt@bookTicker\",\"data\":{\"e\":\"bookTicker\",\"u\":11478212559772,\"s\":\"BTCUSDT\",\"ps\":\"BTCUSDT\",\"b\":\"79598.10\",\"B\":\"10.919\",\"a\":\"79598.20\",\"A\":\"3.264\",\"T\":1788563042422,\"E\":1788563042422,\"st\":1}}"}
{"receive_ns":1788563042358826000,"stream":"btcusdt@trade","event_type":"trade","event_time_ms":1788563042422,"raw_json":"{\"stream\":\"btcusdt@trade\",\"data\":{\"e\":\"trade\",\"E\":1788563042422,\"T\":1788563042422,\"s\":\"BTCUSDT\",\"t\":8054081713,\"p\":\"79598.10\",\"q\":\"0.002\",\"X\":\"MARKET\",\"m\":true,\"st\":1}}"}
{"receive_ns":1788563042359043000,"stream":"btcusdt@bookTicker","event_type":"bookTicker","event_time_ms":1788563042423,"raw_json":"{\"stream\":\"btcusdt@bookTicker\",\"data\":{\"e\":\"bookTicker\",\"u\":11478212559915,\"s\":\"BTCUSDT\",\"ps\":\"BTCUSDT\",\"b\":\"79598.10\",\"B\":\"10.927\",\"a\":\"79598.20\",\"A\":\"3.264\",\"T\":1788563042423,\"E\":1788563042423,\"st\":1}}"}
{"receive_ns":1788563042360052000,"stream":"btcusdt@bookTicker","event_type":"bookTicker","event_time_ms":1788563042424,"raw_json":"{\"stream\":\"btcusdt@bookTicker\",\"data\":{\"e\":\"bookTicker\",\"u\":11478212559963,\"s\":\"BTCUSDT\",\"ps\":\"BTCUSDT\",\"b\":\"79598.10\",\"B\":\"10.919\",\"a\":\"79598.20\",\"A\":\"3.264\",\"T\":1788563042424,\"E\":1788563042424,\"st\":1}}"}
{"receive_ns":1788563042371957000,"stream":"btcusdt@bookTicker","event_type":"bookTicker","event_time_ms":1788563042428,"raw_json":"{\"stream\":\"btcusdt@bookTicker\",\"data\":{\"e\":\"bookTicker\",\"u\":11478212560099,\"s\":\"BTCUSDT\",\"ps\":\"BTCUSDT\",\"b\":\"79598.10\",\"B\":\"10.919\",\"a\":\"79598.20\",\"A\":\"3.265\",\"T\":1788563042428,\"E\":1788563042428,\"st\":1}}"}
{"receive_ns":1788563042437080000,"stream":"btcusdt@depth@100ms","event_type":"depthUpdate","event_time_ms":1788563042501,"raw_json":"{\"stream\":\"btcusdt@depth@100ms\",\"data\":{\"e\":\"depthUpdate\",\"E\":1788563042501,\"T\":1788563042497,\"s\":\"BTCUSDT\",\"ps\":\"BTCUSDT\",\"U\":11478212558801,\"u\":11478212563503,\"pu\":11478212558751,\"b\":[[\"29198.10\",\"1.365\"],[\"29298.10\",\"0.735\"],[\"71638.20\",\"0.002\"],[\"71675.00\",\"0.002\"],[\"75901.60\",\"0.000\"],[\"78802.10\",\"3.943\"],[\"79200.10\",\"0.279\"],[\"79228.00\",\"0.013\"],[\"79401.10\",\"0.502\"],[\"79404.00\",\"1.215\"],[\"79472.70\",\"2.577\"],[\"79494.60\",\"0.000\"],[\"79554.10\",\"0.168\"],[\"79572.30\",\"0.027\"],[\"79575.50\",\"0.003\"],[\"79596.40\",\"0.073\"],[\"79598.10\",\"10.919\"]],\"a\":[[\"79598.20\",\"3.265\"],[\"79599.10\",\"0.002\"],[\"79599.80\",\"0.076\"],[\"79602.10\",\"0.028\"],[\"79602.20\",\"0.254\"],[\"79603.10\",\"0.200\"],[\"79740.00\",\"0.500\"],[\"79962.40\",\"0.419\"],[\"79996.20\",\"0.901\"],[\"80394.20\",\"4.235\"],[\"81073.00\",\"0.803\"]],\"st\":1}}"}
{"receive_ns":1788563042522412000,"stream":"btcusdt@bookTicker","event_type":"bookTicker","event_time_ms":1788563042587,"raw_json":"{\"stream\":\"btcusdt@bookTicker\",\"data\":{\"e\":\"bookTicker\",\"u\":11478212567665,\"s\":\"BTCUSDT\",\"ps\":\"BTCUSDT\",\"b\":\"79598.10\",\"B\":\"10.919\",\"a\":\"79598.20\",\"A\":\"3.266\",\"T\":1788563042587,\"E\":1788563042587,\"st\":1}}"}
{"receive_ns":1788563042537814000,"stream":"btcusdt@bookTicker","event_type":"bookTicker","event_time_ms":1788563042601,"raw_json":"{\"stream\":\"btcusdt@bookTicker\",\"data\":{\"e\":\"bookTicker\",\"u\":11478212568742,\"s\":\"BTCUSDT\",\"ps\":\"BTCUSDT\",\"b\":\"79598.10\",\"B\":\"10.903\",\"a\":\"79598.20\",\"A\":\"3.266\",\"T\":1788563042601,\"E\":1788563042601,\"st\":1}}"}
{"receive_ns":1788563042538449000,"stream":"btcusdt@depth@100ms","event_type":"depthUpdate","event_time_ms":1788563042603,"raw_json":"{\"stream\":\"btcusdt@depth@100ms\",\"data\":{\"e\":\"depthUpdate\",\"E\":1788563042603,\"T\":1788563042602,\"s\":\"BTCUSDT\",\"ps\":\"BTCUSDT\",\"U\":11478212563813,\"u\":11478212568776,\"pu\":11478212563503,\"b\":[[\"29198.10\",\"1.547\"],[\"29298.10\",\"0.553\"],[\"63678.00\",\"0.002\"],[\"71638.20\",\"0.002\"],[\"76066.30\",\"0.140\"],[\"76230.90\",\"0.000\"],[\"76414.10\",\"0.000\"],[\"78006.20\",\"0.021\"],[\"78802.10\",\"3.943\"],[\"79228.00\",\"0.245\"],[\"79401.10\",\"0.602\"],[\"79492.60\",\"1.332\"],[\"79563.30\",\"0.001\"],[\"79564.20\",\"0.687\"],[\"79564.30\",\"0.298\"],[\"79565.50\",\"0.792\"],[\"79572.10\",\"0.079\"],[\"79572.50\",\"0.342\"],[\"79573.20\",\"0.440\"],[\"79573.50\",\"0.373\"],[\"79574.70\",\"0.001\"],[\"79575.30\",\"0.001\"],[\"79579.00\",\"0.630\"],[\"79579.20\",\"1.228\"],[\"79583.00\",\"0.630\"],[\"79583.20\",\"0.316\"],[\"79583.40\",\"0.006\"],[\"79585.00\",\"0.146\"],[\"79585.30\",\"0.080\"],[\"79586.90\",\"0.012\"],[\"79587.50\",\"0.000\"],[\"79587.70\",\"0.000\"],[\"79588.90\",\"0.174\"],[\"79589.20\",\"0.000\"],[\"79590.50\",\"0.278\"],[\"79591.30\",\"0.000\"],[\"79594.10\",\"0.078\"],[\"79594.20\",\"0.376\"],[\"79595.20\",\"0.001\"],[\"79598.10\",\"10.903\"]],\"a\":[[\"79598.20\",\"3.266\"],[\"79598.30\",\"0.180\"],[\"79599.80\",\"0.102\"],[\"79600.30\",\"0.005\"],[\"79600.50\",\"0.512\"],[\"79600.70\",\"0.028\"],[\"79602.10\",\"0.253\"],[\"79602.30\",\"0.000\"],[\"79610.20\",\"0.002\"],[\"79610.80\",\"0.199\"],[\"79611.00\",\"0.691\"],[\"79611.10\",\"1.347\"],[\"79611.40\",\"0.859\"],[\"79613.40\",\"0.003\"],[\"79614.60\",\"0.373\"],[\"79615.90\",\"0.110\"],[\"79616.70\",\"0.453\"],[\"79622.90\",\"0.628\"],[\"79623.30\",\"0.003\"],[\"79628.00\",\"2.004\"],[\"79629.30\",\"0.068\"],[\"79669.40\",\"0.086\"],[\"79678.40\",\"0.038\"],[\"79694.10\",\"0.016\"],[\"79703.10\",\"0.000\"],[\"79739.90\",\"0.000\"],[\"79962.40\",\"1.273\"],[\"79996.20\",\"1.101\"],[\"80394.20\",\"4.235\"],[\"80635.10\",\"0.249\"],[\"81230.00\",\"2.020\"]],\"st\":1}}"}
{"receive_ns":1788563042573482000,"stream":"btcusdt@bookTicker","event_type":"bookTicker","event_time_ms":1788563042637,"raw_json":"{\"stream\":\"btcusdt@bookTicker\",\"data\":{\"e\":\"bookTicker\",\"u\":11478212570321,\"s\":\"BTCUSDT\",\"ps\":\"BTCUSDT\",\"b\":\"79598.10\",\"B\":\"10.903\",\"a\":\"79598.20\",\"A\":\"3.269\",\"T\":1788563042637,\"E\":1788563042637,\"st\":1}}"}
{"receive_ns":1788563042573693000,"stream":"btcusdt@bookTicker","event_type":"bookTicker","event_time_ms":1788563042637,"raw_json":"{\"stream\":\"btcusdt@bookTicker\",\"data\":{\"e\":\"bookTicker\",\"u\":11478212570327,\"s\":\"BTCUSDT\",\"ps\":\"BTCUSDT\",\"b\":\"79598.10\",\"B\":\"10.903\",\"a\":\"79598.20\",\"A\":\"3.268\",\"T\":1788563042637,\"E\":1788563042637,\"st\":1}}"}
{"receive_ns":1788563042641900000,"stream":"btcusdt@depth@100ms","event_type":"depthUpdate","event_time_ms":1788563042705,"raw_json":"{\"stream\":\"btcusdt@depth@100ms\",\"data\":{\"e\":\"depthUpdate\",\"E\":1788563042705,\"T\":1788563042702,\"s\":\"BTCUSDT\",\"ps\":\"BTCUSDT\",\"U\":11478212568883,\"u\":11478212573091,\"pu\":11478212568776,\"b\":[[\"1000.00\",\"24.604\"],[\"29198.10\",\"1.722\"],[\"29298.10\",\"0.378\"],[\"63678.50\",\"0.000\"],[\"63679.00\",\"0.000\"],[\"71638.20\",\"0.002\"],[\"76395.60\",\"0.019\"],[\"76414.10\",\"0.002\"],[\"78220.50\",\"0.001\"],[\"78802.10\",\"3.943\"],[\"79200.10\",\"0.279\"],[\"79401.10\",\"0.100\"],[\"79404.00\",\"1.215\"],[\"79472.70\",\"1.572\"],[\"79494.60\",\"1.507\"],[\"79574.40\",\"0.050\"],[\"79592.20\",\"0.049\"]],\"a\":[[\"79598.20\",\"3.268\"],[\"79599.80\",\"0.076\"],[\"79602.20\",\"0.003\"],[\"79603.10\",\"0.000\"],[\"79609.50\",\"0.009\"],[\"79610.20\",\"0.010\"],[\"79610.80\",\"0.195\"],[\"79611.10\",\"1.351\"],[\"79614.30\",\"0.361\"],[\"79735.50\",\"0.275\"],[\"79736.40\",\"0.211\"],[\"79962.40\",\"1.273\"],[\"79996.20\",\"1.101\"],[\"80235.00\",\"1.501\"],[\"80394.20\",\"4.235\"],[\"80747.80\",\"8.716\"],[\"80827.40\",\"6.056\"],[\"81070.80\",\"1.658\"],[\"87558.00\",\"0.002\"]],\"st\":1}}"}
{"receive_ns":1788563042709647000,"stream":"btcusdt@bookTicker","event_type":"bookTicker","event_time_ms":1788563042774,"raw_json":"{\"stream\":\"btcusdt@bookTicker\",\"data\":{\"e\":\"bookTicker\",\"u\":11478212576241,\"s\":\"BTCUSDT\",\"ps\":\"BTCUSDT\",\"b\":\"79598.10\",\"B\":\"10.920\",\"a\":\"79598.20\",\"A\":\"3.268\",\"T\":1788563042774,\"E\":1788563042774,\"st\":1}}"}
{"receive_ns":1788563042741432000,"stream":"btcusdt@depth@100ms","event_type":"depthUpdate","event_time_ms":1788563042807,"raw_json":"{\"stream\":\"btcusdt@depth@100ms\",\"data\":{\"e\":\"depthUpdate\",\"E\":1788563042807,\"T\":1788563042805,\"s\":\"BTCUSDT\",\"ps\":\"BTCUSDT\",\"U\":11478212573342,\"u\":11478212577836,\"pu\":11478212573091,\"b\":[[\"29098.10\",\"0.049\"],[\"29198.10\",\"1.806\"],[\"29298.10\",\"0.245\"],[\"71638.20\",\"0.002\"],[\"76414.10\",\"0.000\"],[\"78802.10\",\"3.943\"],[\"79228.00\",\"0.013\"],[\"79401.10\",\"0.232\"],[\"79492.60\",\"1.432\"],[\"79558.30\",\"0.080\"],[\"79598.10\",\"10.920\"]],\"a\":[[\"79599.50\",\"0.002\"],[\"79600.50\",\"0.486\"],[\"79600.70\",\"0.002\"],[\"79600.90\",\"0.080\"],[\"79601.00\",\"0.008\"],[\"79601.10\",\"0.003\"],[\"79601.30\",\"0.000\"],[\"79601.50\",\"0.003\"],[\"79601.60\",\"0.000\"],[\"79601.80\",\"0.027\"],[\"79602.10\",\"0.002\"],[\"79669.90\",\"0.002\"],[\"79735.50\",\"0.526\"],[\"79739.60\",\"0.001\"],[\"79739.90\",\"0.000\"],[\"79740.00\",\"0.625\"],[\"79962.30\",\"0.001\"],[\"79962.40\",\"1.273\"],[\"79996.20\",\"1.101\"],[\"80394.20\",\"6.098\"],[\"80468.00\",\"2.291\"],[\"80473.80\",\"2.490\"],[\"80792.20\",\"2.479\"],[\"80871.80\",\"3.086\"],[\"80967.30\",\"0.493\"],[\"81073.00\",\"0.003\"],[\"81152.60\",\"0.000\"],[\"87558.00\",\"0.000\"]],\"st\":1}}"}
{"receive_ns":1788563042773713000,"stream":"btcusdt@bookTicker","event_type":"bookTicker","event_time_ms":1788563042836,"raw_json":"{\"stream\":\"btcusdt@bookTicker\",\"data\":{\"e\":\"bookTicker\",\"u\":11478212579416,\"s\":\"BTCUSDT\",\"ps\":\"BTCUSDT\",\"b\":\"79598.10\",\"B\":\"10.936\",\"a\":\"79598.20\",\"A\":\"3.268\",\"T\":1788563042836,\"E\":1788563042836,\"st\":1}}"}
{"receive_ns":1788563042807612000,"stream":"btcusdt@bookTicker","event_type":"bookTicker","event_time_ms":1788563042871,"raw_json":"{\"stream\":\"btcusdt@bookTicker\",\"data\":{\"e\":\"bookTicker\",\"u\":11478212580992,\"s\":\"BTCUSDT\",\"ps\":\"BTCUSDT\",\"b\":\"79598.10\",\"B\":\"10.936\",\"a\":\"79598.20\",\"A\":\"3.265\",\"T\":1788563042871,\"E\":1788563042871,\"st\":1}}"}
{"receive_ns":1788563042828196000,"stream":"btcusdt@bookTicker","event_type":"bookTicker","event_time_ms":1788563042891,"raw_json":"{\"stream\":\"btcusdt@bookTicker\",\"data\":{\"e\":\"bookTicker\",\"u\":11478212581925,\"s\":\"BTCUSDT\",\"ps\":\"BTCUSDT\",\"b\":\"79598.10\",\"B\":\"10.936\",\"a\":\"79598.20\",\"A\":\"3.266\",\"T\":1788563042891,\"E\":1788563042891,\"st\":1}}"}
{"receive_ns":1788563042846162000,"stream":"btcusdt@depth@100ms","event_type":"depthUpdate","event_time_ms":1788563042909,"raw_json":"{\"stream\":\"btcusdt@depth@100ms\",\"data\":{\"e\":\"depthUpdate\",\"E\":1788563042909,\"T\":1788563042905,\"s\":\"BTCUSDT\",\"ps\":\"BTCUSDT\",\"U\":11478212577969,\"u\":11478212582598,\"pu\":11478212577836,\"b\":[[\"29098.10\",\"0.112\"],[\"29198.10\",\"1.855\"],[\"29298.10\",\"0.133\"],[\"63678.00\",\"0.002\"],[\"71638.20\",\"0.002\"],[\"71638.30\",\"0.054\"],[\"76414.10\",\"0.002\"],[\"78578.60\",\"9.184\"],[\"78579.30\",\"0.005\"],[\"78590.60\",\"0.012\"],[\"78595.50\",\"0.006\"],[\"78606.90\",\"0.000\"],[\"78611.70\",\"0.004\"],[\"78618.40\",\"16.623\"],[\"78802.10\",\"3.943\"],[\"79200.10\",\"0.138\"],[\"79404.00\",\"1.014\"],[\"79473.80\",\"0.594\"],[\"79494.60\",\"0.000\"],[\"79563.30\",\"0.047\"],[\"79564.30\",\"0.252\"],[\"79572.10\",\"0.079\"],[\"79572.50\",\"0.715\"],[\"79573.20\",\"0.001\"],[\"79573.50\",\"0.000\"],[\"79575.30\",\"0.440\"],[\"79592.20\",\"0.049\"],[\"79594.10\",\"0.077\"],[\"79594.20\",\"0.377\"],[\"79595.30\",\"0.079\"],[\"79598.10\",\"10.936\"]],\"a\":[[\"79598.20\",\"3.266\"],[\"79598.30\",\"0.104\"],[\"79601.50\",\"0.029\"],[\"79601.70\",\"0.001\"],[\"79601.80\",\"0.001\"],[\"79602.20\",\"0.029\"],[\"79602.60\",\"0.026\"],[\"79602.70\",\"0.029\"],[\"79602.80\",\"0.026\"],[\"79602.90\",\"0.027\"],[\"79603.00\",\"0.026\"],[\"79603.20\",\"0.030\"],[\"79603.30\",\"0.026\"],[\"79603.40\",\"0.028\"],[\"79609.50\",\"0.009\"],[\"79609.60\",\"0.258\"],[\"79610.20\",\"0.010\"],[\"79611.40\",\"0.859\"],[\"79612.40\",\"0.000\"],[\"79613.70\",\"0.372\"],[\"79614.60\",\"0.001\"],[\"79614.70\",\"0.001\"],[\"79615.90\",\"0.562\"],[\"79616.70\",\"0.001\"],[\"79646.00\",\"0.032\"],[\"79722.50\",\"0.385\"],[\"79722.70\",\"0.011\"],[\"79735.50\",\"0.024\"],[\"79736.40\",\"0.011\"],[\"79740.00\",\"0.500\"],[\"79740.20\",\"0.002\"],[\"79740.30\",\"0.165\"],[\"79962.40\",\"0.854\"],[\"79996.20\",\"0.575\"],[\"80394.20\",\"6.098\"],[\"80465.80\",\"2.056\"],[\"80672.80\",\"1.730\"],[\"80792.20\",\"2.757\"],[\"81190.10\",\"0.011\"]],\"st\":1}}"}
{"receive_ns":1788563042946810000,"stream":"btcusdt@depth@100ms","event_type":"depthUpdate","event_time_ms":1788563043011,"raw_json":"{\"stream\":\"btcusdt@depth@100ms\",\"data\":{\"e\":\"depthUpdate\",\"E\":1788563043011,\"T\":1788563043009,\"s\":\"BTCUSDT\",\"ps\":\"BTCUSDT\",\"U\":11478212582813,\"u\":11478212587756,\"pu\":11478212582598,\"b\":[[\"1000.00\",\"24.604\"],[\"29098.10\",\"0.175\"],[\"29198.10\",\"1.911\"],[\"29298.10\",\"0.014\"],[\"63679.00\",\"0.000\"],[\"71638.20\",\"0.002\"],[\"78802.10\",\"3.943\"],[\"78841.90\",\"3.840\"],[\"79200.10\",\"0.279\"],[\"79401.10\",\"0.332\"],[\"79404.00\",\"1.215\"],[\"79472.70\",\"1.547\"],[\"79472.80\",\"0.000\"],[\"79486.60\",\"0.015\"],[\"79492.60\",\"1.332\"],[\"79494.60\",\"1.507\"],[\"79563.30\",\"0.001\"],[\"79564.30\",\"0.298\"],[\"79572.50\",\"0.342\"],[\"79573.20\",\"0.440\"],[\"79573.50\",\"0.373\"],[\"79575.30\",\"0.001\"]],\"a\":[[\"79603.10\",\"0.200\"],[\"79606.10\",\"0.252\"],[\"79610.20\",\"0.449\"],[\"79611.40\",\"0.420\"],[\"79628.10\",\"0.062\"],[\"79629.30\",\"0.022\"],[\"79735.50\",\"0.275\"],[\"79739.70\",\"0.002\"],[\"79739.80\",\"0.000\"],[\"79740.00\",\"0.500\"],[\"79740.40\",\"0.000\"],[\"79962.40\",\"1.273\"],[\"79991.70\",\"3.974\"],[\"79996.20\",\"1.101\"],[\"80394.20\",\"6.098\"],[\"80708.00\",\"7.672\"]],\"st\":1}}"}
{"receive_ns":1788563042955786000,"stream":"btcusdt@bookTicker","event_type":"bookTicker","event_time_ms":1788563043022,"raw_json":"{\"stream\":\"btcusdt@bookTicker\",\"data\":{\"e\":\"bookTicker\",\"u\":11478212588831,\"s\":\"BTCUSDT\",\"ps\":\"BTCUSDT\",\"b\":\"79598.10\",\"B\":\"10.944\",\"a\":\"79598.20\",\"A\":\"3.266\",\"T\":1788563043021,\"E\":1788563043022,\"st\":1}}"}
{"receive_ns":1788563042957167000,"stream":"btcusdt@bookTicker","event_type":"bookTicker","event_time_ms":1788563043023,"raw_json":"{\"stream\":\"btcusdt@bookTicker\",\"data\":{\"e\":\"bookTicker\",\"u\":11478212588894,\"s\":\"BTCUSDT\",\"ps\":\"BTCUSDT\",\"b\":\"79598.10\",\"B\":\"10.936\",\"a\":\"79598.20\",\"A\":\"3.266\",\"T\":1788563043022,\"E\":1788563043023,\"st\":1}}"}
{"receive_ns":1788563043039728000,"stream":"btcusdt@bookTicker","event_type":"bookTicker","event_time_ms":1788563043103,"raw_json":"{\"stream\":\"btcusdt@bookTicker\",\"data\":{\"e\":\"bookTicker\",\"u\":11478212593048,\"s\":\"BTCUSDT\",\"ps\":\"BTCUSDT\",\"b\":\"79598.10\",\"B\":\"10.936\",\"a\":\"79598.20\",\"A\":\"3.265\",\"T\":1788563043103,\"E\":1788563043103,\"st\":1}}"}
{"receive_ns":1788563043047959000,"stream":"btcusdt@depth@100ms","event_type":"depthUpdate","event_time_ms":1788563043113,"raw_json":"{\"stream\":\"btcusdt@depth@100ms\",\"data\":{\"e\":\"depthUpdate\",\"E\":1788563043113,\"T\":1788563043110,\"s\":\"BTCUSDT\",\"ps\":\"BTCUSDT\",\"U\":11478212587833,\"u\":11478212593570,\"pu\":11478212587756,\"b\":[[\"29098.10\",\"0.336\"],[\"29198.10\",\"1.764\"],[\"29298.10\",\"0.000\"],[\"63678.00\",\"0.002\"],[\"63679.00\",\"0.000\"],[\"71638.20\",\"0.002\"],[\"71803.00\",\"0.013\"],[\"76414.10\",\"0.000\"],[\"78244.90\",\"2.617\"],[\"78380.60\",\"0.023\"],[\"78460.30\",\"0.000\"],[\"78466.10\",\"0.000\"],[\"78475.80\",\"0.762\"],[\"78478.60\",\"0.001\"],[\"78802.10\",\"3.943\"],[\"79200.10\",\"0.278\"],[\"79583.80\",\"0.000\"],[\"79592.20\",\"0.049\"],[\"79598.10\",\"10.936\"]],\"a\":[[\"79598.20\",\"3.265\"],[\"79599.40\",\"0.000\"],[\"79599.70\",\"0.000\"],[\"79601.40\",\"0.026\"],[\"79603.40\",\"0.002\"],[\"79609.50\",\"0.017\"],[\"79610.20\",\"0.441\"],[\"79740.30\",\"0.165\"],[\"79996.20\",\"1.102\"],[\"80195.20\",\"1.246\"],[\"80394.20\",\"6.098\"],[\"80710.80\",\"2.514\"],[\"80736.10\",\"0.000\"],[\"80815.70\",\"0.007\"],[\"81070.80\",\"2.458\"]],\"st\":1}}"}
{"receive_ns":1788563043048288000,"stream":"btcusdt@bookTicker","event_type":"bookTicker","event_time_ms":1788563043113,"raw_json":"{\"stream\":\"btcusdt@bookTicker\",\"data\":{\"e\":\"bookTicker\",\"u\":11478212593856,\"s\":\"BTCUSDT\",\"ps\":\"BTCUSDT\",\"b\":\"79598.10\",\"B\":\"10.936\",\"a\":\"79598.20\",\"A\":\"3.268\",\"T\":1788563043113,\"E\":1788563043113,\"st\":1}}"}
{"receive_ns":1788563043145375000,"stream":"btcusdt@bookTicker","event_type":"bookTicker","event_time_ms":1788563043209,"raw_json":"{\"stream\":\"btcusdt@bookTicker\",\"data\":{\"e\":\"bookTicker\",\"u\":11478212598601,\"s\":\"BTCUSDT\",\"ps\":\"BTCUSDT\",\"b\":\"79598.10\",\"B\":\"10.912\",\"a\":\"79598.20\",\"A\":\"3.268\",\"T\":1788563043209,\"E\":1788563043209,\"st\":1}}"}
{"receive_ns":1788563043146210000,"stream":"btcusdt@bookTicker","event_type":"bookTicker","event_time_ms":1788563043212,"raw_json":"{\"stream\":\"btcusdt@bookTicker\",\"data\":{\"e\":\"bookTicker\",\"u\":11478212598779,\"s\":\"BTCUSDT\",\"ps\":\"BTCUSDT\",\"b\":\"79598.10\",\"B\":\"10.937\",\"a\":\"79598.20\",\"A\":\"3.268\",\"T\":1788563043212,\"E\":1788563043212,\"st\":1}}"}
{"receive_ns":1788563043151564000,"stream":"btcusdt@depth@100ms","event_type":"depthUpdate","event_time_ms":1788563043215,"raw_json":"{\"stream\":\"btcusdt@depth@100ms\",\"data\":{\"e\":\"depthUpdate\",\"E\":1788563043215,\"T\":1788563043214,\"s\":\"BTCUSDT\",\"ps\":\"BTCUSDT\",\"U\":11478212593814,\"u\":11478212598914,\"pu\":11478212593570,\"b\":[[\"1000.00\",\"24.604\"],[\"29098.10\",\"0.518\"],[\"29198.10\",\"1.582\"],[\"71638.20\",\"0.002\"],[\"76414.10\",\"0.002\"],[\"78380.60\",\"0.030\"],[\"78439.50\",\"20.272\"],[\"78460.10\",\"0.010\"],[\"78507.60\",\"1.016\"],[\"78517.60\",\"0.028\"],[\"78579.30\",\"0.000\"],[\"78581.80\",\"0.004\"],[\"78595.50\",\"0.002\"],[\"78597.90\",\"0.033\"],[\"78611.70\",\"0.000\"],[\"78614.10\",\"0.003\"],[\"78802.10\",\"5.211\"],[\"79200.10\",\"0.278\"],[\"79401.10\",\"0.000\"],[\"79404.00\",\"1.014\"],[\"79485.60\",\"0.201\"],[\"79492.60\",\"0.001\"],[\"79494.60\",\"1.507\"],[\"79500.70\",\"0.002\"],[\"79503.80\",\"0.038\"],[\"79522.20\",\"1.752\"],[\"79563.30\",\"0.001\"],[\"79564.30\",\"0.252\"],[\"79564.50\",\"0.390\"],[\"79572.10\",\"0.079\"],[\"79572.30\",\"0.027\"],[\"79573.20\",\"0.001\"],[\"79573.30\",\"0.812\"],[\"79573.50\",\"0.000\"],[\"79573.60\",\"0.000\"],[\"79574.70\",\"0.001\"],[\"79575.30\",\"0.001\"],[\"79598.10\",\"10.937\"]],\"a\":[[\"79598.20\",\"3.268\"],[\"79600.60\",\"0.026\"],[\"79600.80\",\"0.027\"],[\"79601.30\",\"0.000\"],[\"79601.40\",\"0.000\"],[\"79601.50\",\"0.003\"],[\"79601.70\",\"0.027\"],[\"79601.80\",\"0.027\"],[\"79602.00\",\"0.103\"],[\"79602.10\",\"0.028\"],[\"79602.40\",\"0.027\"],[\"79602.80\",\"0.000\"],[\"79602.90\",\"0.001\"],[\"79603.00\",\"0.000\"],[\"79603.10\",\"0.000\"],[\"79603.20\",\"0.004\"],[\"79603.30\",\"0.000\"],[\"79606.10\",\"0.001\"],[\"79609.50\",\"0.009\"],[\"79609.60\",\"0.258\"],[\"79610.10\",\"0.440\"],[\"79610.20\",\"0.010\"],[\"79611.40\",\"0.420\"],[\"79612.20\",\"0.004\"],[\"79613.20\",\"0.432\"],[\"79613.50\",\"1.245\"],[\"79613.70\",\"0.000\"],[\"79614.60\",\"0.001\"],[\"79627.10\",\"0.000\"],[\"79628.10\",\"0.016\"],[\"79628.30\",\"0.000\"],[\"79629.40\",\"0.826\"],[\"79675.30\",\"0.005\"],[\"79685.00\",\"0.001\"],[\"79703.30\",\"1.182\"],[\"79735.50\",\"0.275\"],[\"79736.40\",\"0.211\"],[\"79739.70\",\"0.002\"],[\"79740.00\",\"0.500\"],[\"79962.40\",\"0.419\"],[\"79996.20\",\"0.902\"],[\"80190.70\",\"2.492\"],[\"80394.20\",\"6.098\"],[\"80792.20\",\"2.942\"],[\"80815.60\",\"0.024\"]],\"st\":1}}"}
{"receive_ns":1788563043161998000,"stream":"btcusdt@bookTicker","event_type":"bookTicker","event_time_ms":1788563043227,"raw_json":"{\"stream\":\"btcusdt@bookTicker\",\"data\":{\"e\":\"bookTicker\",\"u\":11478212599493,\"s\":\"BTCUSDT\",\"ps\":\"BTCUSDT\",\"b\":\"79598.10\",\"B\":\"10.921\",\"a\":\"79598.20\",\"A\":\"3.268\",\"T\":1788563043227,\"E\":1788563043227,\"st\":1}}"}
{"receive_ns":1788563043196692000,"stream":"btcusdt@bookTicker","event_type":"bookTicker","event_time_ms":1788563043260,"raw_json":"{\"stream\":\"btcusdt@bookTicker\",\"data\":{\"e\":\"bookTicker\",\"u\":11478212601250,\"s\":\"BTCUSDT\",\"ps\":\"BTCUSDT\",\"b\":\"79598.10\",\"B\":\"10.937\",\"a\":\"79598.20\",\"A\":\"3.268\",\"T\":1788563043260,\"E\":1788563043260,\"st\":1}}"}
{"receive_ns":1788563043197875000,"stream":"btcusdt@bookTicker","event_type":"bookTicker","event_time_ms":1788563043262,"raw_json":"{\"stream\":\"btcusdt@bookTicker\",\"data\":{\"e\":\"bookTicker\",\"u\":11478212601445,\"s\":\"BTCUSDT\",\"ps\":\"BTCUSDT\",\"b\":\"79598.10\",\"B\":\"10.937\",\"a\":\"79598.20\",\"A\":\"3.267\",\"T\":1788563043262,\"E\":1788563043262,\"st\":1}}"}
{"receive_ns":1788563043202298000,"stream":"btcusdt@bookTicker","event_type":"bookTicker","event_time_ms":1788563043266,"raw_json":"{\"stream\":\"btcusdt@bookTicker\",\"data\":{\"e\":\"bookTicker\",\"u\":11478212601621,\"s\":\"BTCUSDT\",\"ps\":\"BTCUSDT\",\"b\":\"79598.10\",\"B\":\"10.894\",\"a\":\"79598.20\",\"A\":\"3.267\",\"T\":1788563043266,\"E\":1788563043266,\"st\":1}}"}
{"receive_ns":1788563043207381000,"stream":"btcusdt@bookTicker","event_type":"bookTicker","event_time_ms":1788563043269,"raw_json":"{\"stream\":\"btcusdt@bookTicker\",\"data\":{\"e\":\"bookTicker\",\"u\":11478212601729,\"s\":\"BTCUSDT\",\"ps\":\"BTCUSDT\",\"b\":\"79598.10\",\"B\":\"10.939\",\"a\":\"79598.20\",\"A\":\"3.267\",\"T\":1788563043269,\"E\":1788563043269,\"st\":1}}"}
{"receive_ns":1788563043207622000,"stream":"btcusdt@bookTicker","event_type":"bookTicker","event_time_ms":1788563043270,"raw_json":"{\"stream\":\"btcusdt@bookTicker\",\"data\":{\"e\":\"bookTicker\",\"u\":11478212601749,\"s\":\"BTCUSDT\",\"ps\":\"BTCUSDT\",\"b\":\"79598.10\",\"B\":\"10.939\",\"a\":\"79598.20\",\"A\":\"3.269\",\"T\":1788563043269,\"E\":1788563043270,\"st\":1}}"}
{"receive_ns":1788563043259218000,"stream":"btcusdt@depth@100ms","event_type":"depthUpdate","event_time_ms":1788563043317,"raw_json":"{\"stream\":\"btcusdt@depth@100ms\",\"data\":{\"e\":\"depthUpdate\",\"E\":1788563043317,\"T\":1788563043316,\"s\":\"BTCUSDT\",\"ps\":\"BTCUSDT\",\"U\":11478212598982,\"u\":11478212604757,\"pu\":11478212598914,\"b\":[[\"1000.00\",\"24.604\"],[\"29098.10\",\"0.693\"],[\"29198.10\",\"1.407\"],[\"71638.20\",\"0.002\"],[\"71967.70\",\"0.013\"],[\"76414.10\",\"0.000\"],[\"78483.70\",\"13.616\"],[\"78802.10\",\"5.211\"],[\"79187.00\",\"0.085\"],[\"79193.20\",\"0.087\"],[\"79200.10\",\"0.268\"],[\"79401.10\",\"0.232\"],[\"79492.60\",\"1.432\"],[\"79563.30\",\"0.047\"],[\"79564.50\",\"0.344\"],[\"79572.10\",\"0.518\"],[\"79572.40\",\"0.627\"],[\"79573.30\",\"0.000\"],[\"79592.20\",\"0.049\"],[\"79598.10\",\"10.939\"]],\"a\":[[\"79598.20\",\"3.269\"],[\"79600.60\",\"0.000\"],[\"79600.80\",\"0.001\"],[\"79601.20\",\"0.027\"],[\"79601.30\",\"0.026\"],[\"79601.50\",\"0.029\"],[\"79602.70\",\"0.003\"],[\"79604.60\",\"0.003\"],[\"79609.50\",\"0.017\"],[\"79610.20\",\"0.002\"],[\"79627.10\",\"0.046\"],[\"79629.40\",\"0.780\"],[\"79653.80\",\"0.039\"],[\"79653.90\",\"0.002\"],[\"79699.00\",\"0.111\"],[\"79735.50\",\"0.526\"],[\"79736.40\",\"0.011\"],[\"79740.00\",\"0.625\"],[\"79962.40\",\"1.273\"],[\"79996.20\",\"1.476\"],[\"80394.20\",\"6.098\"],[\"80736.00\",\"0.007\"],[\"80759.00\",\"0.135\"]],\"st\":1}}"}
{"receive_ns":1788563043282834000,"stream":"btcusdt@bookTicker","event_type":"bookTicker","event_time_ms":1788563043347,"raw_json":"{\"stream\":\"btcusdt@bookTicker\",\"data\":{\"e\":\"bookTicker\",\"u\":11478212606550,\"s\":\"BTCUSDT\",\"ps\":\"BTCUSDT\",\"b\":\"79598.10\",\"B\":\"10.939\",\"a\":\"79598.20\",\"A\":\"3.266\",\"T\":1788563043347,\"E\":1788563043347,\"st\":1}}"}
{"receive_ns":1788563043283128000,"stream":"btcusdt@bookTicker","event_type":"bookTicker","event_time_ms":1788563043348,"raw_json":"{\"stream\":\"btcusdt@bookTicker\",\"data\":{\"e\":\"bookTicker\",\"u\":11478212606641,\"s\":\"BTCUSDT\",\"ps\":\"BTCUSDT\",\"b\":\"79598.10\",\"B\":\"10.939\",\"a\":\"79598.20\",\"A\":\"3.267\",\"T\":1788563043348,\"E\":1788563043348,\"st\":1}}"}
{"receive_ns":1788563043355272000,"stream":"btcusdt@depth@100ms","event_type":"depthUpdate","event_time_ms":1788563043419,"raw_json":"{\"stream\":\"btcusdt@depth@100ms\",\"data\":{\"e\":\"depthUpdate\",\"E\":1788563043419,\"T\":1788563043418,\"s\":\"BTCUSDT\",\"ps\":\"BTCUSDT\",\"U\":11478212604811,\"u\":11478212609531,\"pu\":11478212604757,\"b\":[[\"29098.10\",\"0.875\"],[\"29198.10\",\"1.225\"],[\"71638.20\",\"0.002\"],[\"76414.10\",\"0.002\"],[\"77000.00\",\"118.180\"],[\"78252.90\",\"1.021\"],[\"78459.30\",\"25.452\"],[\"78802.10\",\"5.211\"],[\"79200.10\",\"0.267\"],[\"79459.10\",\"2.305\"],[\"79485.60\",\"0.000\"],[\"79494.60\",\"1.005\"],[\"79502.50\",\"0.001\"],[\"79503.00\",\"1.990\"],[\"79542.30\",\"0.002\"],[\"79558.30\",\"0.078\"],[\"79583.10\",\"0.006\"],[\"79583.40\",\"0.002\"],[\"79594.10\",\"0.274\"]],\"a\":[[\"79598.20\",\"3.267\"],[\"79601.00\",\"0.034\"],[\"79602.60\",\"0.000\"],[\"79608.10\",\"0.513\"],[\"79627.10\",\"0.000\"],[\"79628.30\",\"0.046\"],[\"79638.00\",\"0.006\"],[\"79669.90\",\"0.000\"],[\"79686.30\",\"1.340\"],[\"79735.50\",\"0.024\"],[\"79740.00\",\"0.500\"],[\"79962.30\",\"0.270\"],[\"79962.40\",\"0.854\"],[\"79996.20\",\"1.476\"],[\"80394.20\",\"6.098\"],[\"80792.20\",\"3.220\"]],\"st\":1}}"}
{"receive_ns":1788563043450050000,"stream":"btcusdt@bookTicker","event_type":"bookTicker","event_time_ms":1788563043514,"raw_json":"{\"stream\":\"btcusdt@bookTicker\",\"data\":{\"e\":\"bookTicker\",\"u\":11478212613330,\"s\":\"BTCUSDT\",\"ps\":\"BTCUSDT\",\"b\":\"79598.10\",\"B\":\"10.939\",\"a\":\"79598.20\",\"A\":\"3.284\",\"T\":1788563043513,\"E\":1788563043514,\"st\":1}}"}
{"receive_ns":1788563043450256000,"stream":"btcusdt@bookTicker","event_type":"bookTicker","event_time_ms":1788563043514,"raw_json":"{\"stream\":\"btcusdt@bookTicker\",\"data\":{\"e\":\"bookTicker\",\"u\":11478212613334,\"s\":\"BTCUSDT\",\"ps\":\"BTCUSDT\",\"b\":\"79598.10\",\"B\":\"10.939\",\"a\":\"79598.20\",\"A\":\"3.298\",\"T\":1788563043513,\"E\":1788563043514,\"st\":1}}"}
{"receive_ns":1788563043450460000,"stream":"btcusdt@bookTicker","event_type":"bookTicker","event_time_ms":1788563043515,"raw_json":"{\"stream\":\"btcusdt@bookTicker\",\"data\":{\"e\":\"bookTicker\",\"u\":11478212613381,\"s\":\"BTCUSDT\",\"ps\":\"BTCUSDT\",\"b\":\"79598.10\",\"B\":\"10.939\",\"a\":\"79598.20\",\"A\":\"3.297\",\"T\":1788563043514,\"E\":1788563043515,\"st\":1}}"}
{"receive_ns":1788563043455090000,"stream":"btcusdt@depth@100ms","event_type":"depthUpdate","event_time_ms":1788563043521,"raw_json":"{\"stream\":\"btcusdt@depth@100ms\",\"data\":{\"e\":\"depthUpdate\",\"E\":1788563043521,\"T\":1788563043520,\"s\":\"BTCUSDT\",\"ps\":\"BTCUSDT\",\"U\":11478212609582,\"u\":11478212613672,\"pu\":11478212609531,\"b\":[[\"1000.00\",\"24.604\"],[\"29098.10\",\"1.050\"],[\"29198.10\",\"1.050\"],[\"71638.20\",\"0.002\"],[\"71675.00\",\"0.005\"],[\"72132.30\",\"0.012\"],[\"78006.20\",\"0.015\"],[\"78358.60\",\"0.191\"],[\"78443.90\",\"2.903\"],[\"78459.30\",\"25.197\"],[\"78802.10\",\"5.212\"],[\"79012.40\",\"0.640\"],[\"79354.00\",\"0.000\"],[\"79401.10\",\"0.734\"],[\"79404.00\",\"1.215\"],[\"79492.60\",\"1.432\"],[\"79558.30\",\"0.080\"],[\"79563.30\",\"0.001\"],[\"79564.30\",\"0.298\"],[\"79565.70\",\"0.001\"],[\"79572.10\",\"0.079\"],[\"79572.40\",\"0.254\"],[\"79573.20\",\"0.440\"],[\"79573.50\",\"0.373\"],[\"79574.90\",\"0.000\"],[\"79575.30\",\"0.001\"]],\"a\":[[\"79598.20\",\"3.297\"],[\"79600.00\",\"0.052\"],[\"79600.40\",\"0.319\"],[\"79602.40\",\"0.001\"],[\"79603.10\",\"0.200\"],[\"79608.10\",\"0.262\"],[\"79609.50\",\"0.009\"],[\"79610.10\",\"0.001\"],[\"79610.20\",\"0.010\"],[\"79611.40\",\"0.859\"],[\"79613.20\",\"0.060\"],[\"79614.90\",\"0.372\"],[\"79615.90\",\"0.110\"],[\"79616.90\",\"0.456\"],[\"79628.30\",\"0.000\"],[\"79629.50\",\"0.079\"],[\"79669.90\",\"0.002\"],[\"79735.50\",\"0.275\"],[\"79962.30\",\"0.001\"],[\"79962.40\",\"1.273\"],[\"79996.20\",\"1.477\"],[\"80394.20\",\"6.098\"],[\"80514.30\",\"17.010\"],[\"80553.40\",\"14.994\"],[\"80593.20\",\"1.197\"]],\"st\":1}}"}
{"receive_ns":1788563043463151000,"stream":"btcusdt@bookTicker","event_type":"bookTicker","event_time_ms":1788563043529,"raw_json":"{\"stream\":\"btcusdt@bookTicker\",\"data\":{\"e\":\"bookTicker\",\"u\":11478212613905,\"s\":\"BTCUSDT\",\"ps\":\"BTCUSDT\",\"b\":\"79598.10\",\"B\":\"10.939\",\"a\":\"79598.20\",\"A\":\"3.295\",\"T\":1788563043529,\"E\":1788563043529,\"st\":1}}"}
{"receive_ns":1788563043463971000,"stream":"btcusdt@bookTicker","event_type":"bookTicker","event_time_ms":1788563043531,"raw_json":"{\"stream\":\"btcusdt@bookTicker\",\"data\":{\"e\":\"bookTicker\",\"u\":11478212614001,\"s\":\"BTCUSDT\",\"ps\":\"BTCUSDT\",\"b\":\"79598.10\",\"B\":\"10.939\",\"a\":\"79598.20\",\"A\":\"3.296\",\"T\":1788563043531,\"E\":1788563043531,\"st\":1}}"}
{"receive_ns":1788563043520602000,"stream":"btcusdt@bookTicker","event_type":"bookTicker","event_time_ms":1788563043585,"raw_json":"{\"stream\":\"btcusdt@bookTicker\",\"data\":{\"e\":\"bookTicker\",\"u\":11478212616303,\"s\":\"BTCUSDT\",\"ps\":\"BTCUSDT\",\"b\":\"79598.10\",\"B\":\"10.939\",\"a\":\"79598.20\",\"A\":\"3.298\",\"T\":1788563043585,\"E\":1788563043585,\"st\":1}}"}
{"receive_ns":1788563043521080000,"stream":"btcusdt@bookTicker","event_type":"bookTicker","event_time_ms":1788563043586,"raw_json":"{\"stream\":\"btcusdt@bookTicker\",\"data\":{\"e\":\"bookTicker\",\"u\":11478212616313,\"s\":\"BTCUSDT\",\"ps\":\"BTCUSDT\",\"b\":\"79598.10\",\"B\":\"10.939\",\"a\":\"79598.20\",\"A\":\"3.297\",\"T\":1788563043585,\"E\":1788563043586,\"st\":1}}"}
{"receive_ns":1788563043544441000,"stream":"btcusdt@bookTicker","event_type":"bookTicker","event_time_ms":1788563043607,"raw_json":"{\"stream\":\"btcusdt@bookTicker\",\"data\":{\"e\":\"bookTicker\",\"u\":11478212617111,\"s\":\"BTCUSDT\",\"ps\":\"BTCUSDT\",\"b\":\"79598.10\",\"B\":\"10.923\",\"a\":\"79598.20\",\"A\":\"3.297\",\"T\":1788563043607,\"E\":1788563043607,\"st\":1}}"}
{"receive_ns":1788563043558231000,"stream":"btcusdt@depth@100ms","event_type":"depthUpdate","event_time_ms":1788563043623,"raw_json":"{\"stream\":\"btcusdt@depth@100ms\",\"data\":{\"e\":\"depthUpdate\",\"E\":1788563043623,\"T\":1788563043621,\"s\":\"BTCUSDT\",\"ps\":\"BTCUSDT\",\"U\":11478212613705,\"u\":11478212617730,\"pu\":11478212613672,\"b\":[[\"1000.00\",\"24.604\"],[\"29098.10\",\"1.232\"],[\"29198.10\",\"0.868\"],[\"71638.20\",\"0.002\"],[\"71675.00\",\"0.002\"],[\"75618.30\",\"0.004\"],[\"76414.10\",\"0.000\"],[\"78006.20\",\"0.018\"],[\"78797.00\",\"0.002\"],[\"78802.10\",\"5.212\"],[\"79021.50\",\"0.266\"],[\"79200.10\",\"0.136\"],[\"79494.60\",\"0.000\"],[\"79598.10\",\"10.923\"]],\"a\":[[\"79598.20\",\"3.297\"],[\"79996.20\",\"0.951\"],[\"80394.20\",\"6.098\"],[\"80670.20\",\"0.230\"]],\"st\":1}}"}
{"receive_ns":1788563043661370000,"stream":"btcusdt@depth@100ms","event_type":"depthUpdate","event_time_ms":1788563043725,"raw_json":"{\"stream\":\"btcusdt@depth@100ms\",\"data\":{\"e\":\"depthUpdate\",\"E\":1788563043725,\"T\":1788563043722,\"s\":\"BTCUSDT\",\"ps\":\"BTCUSDT\",\"U\":11478212617824,\"u\":11478212624515,\"pu\":11478212617730,\"b\":[[\"29098.10\",\"1.407\"],[\"29198.10\",\"0.693\"],[\"63678.50\",\"0.000\"],[\"71638.20\",\"0.002\"],[\"72297.00\",\"0.012\"],[\"75618.30\",\"0.002\"],[\"76414.10\",\"0.002\"],[\"78802.10\",\"5.212\"],[\"79200.10\",\"0.277\"],[\"79401.10\",\"1.507\"],[\"79404.00\",\"1.215\"],[\"79492.60\",\"0.001\"],[\"79572.10\",\"0.518\"],[\"79572.50\",\"0.715\"],[\"79573.20\",\"0.001\"],[\"79573.50\",\"0.000\"],[\"79574.40\",\"0.050\"],[\"79578.60\",\"0.249\"]],\"a\":[[\"79600.40\",\"0.293\"],[\"79602.20\",\"0.280\"],[\"79603.10\",\"0.200\"],[\"79609.50\",\"0.017\"],[\"79609.60\",\"0.697\"],[\"79610.20\",\"0.002\"],[\"79611.40\",\"0.420\"],[\"79612.40\",\"0.000\"],[\"79613.70\",\"0.372\"],[\"79614.30\",\"0.361\"],[\"79614.70\",\"0.001\"],[\"79614.90\",\"0.000\"],[\"79615.80\",\"1.333\"],[\"79616.90\",\"0.004\"],[\"79735.50\",\"0.024\"],[\"79962.40\",\"0.419\"],[\"79996.20\",\"1.277\"],[\"80392.40\",\"0.000\"],[\"80394.20\",\"6.098\"],[\"80690.00\",\"0.007\"]],\"st\":1}}"}
{"receive_ns":1788563043661656000,"stream":"btcusdt@bookTicker","event_type":"bookTicker","event_time_ms":1788563043725,"raw_json":"{\"stream\":\"btcusdt@bookTicker\",\"data\":{\"e\":\"bookTicker\",\"u\":11478212624624,\"s\":\"BTCUSDT\",\"ps\":\"BTCUSDT\",\"b\":\"79598.10\",\"B\":\"10.923\",\"a\":\"79598.20\",\"A\":\"3.206\",\"T\":1788563043724,\"E\":1788563043725,\"st\":1}}"}
{"receive_ns":1788563043661821000,"stream":"btcusdt@trade","event_type":"trade","event_time_ms":1788563043725,"raw_json":"{\"stream\":\"btcusdt@trade\",\"data\":{\"e\":\"trade\",\"E\":1788563043725,\"T\":1788563043724,\"s\":\"BTCUSDT\",\"t\":8054081714,\"p\":\"79598.20\",\"q\":\"0.091\",\"X\":\"MARKET\",\"m\":false,\"st\":1}}"}
{"receive_ns":1788563043661991000,"stream":"btcusdt@bookTicker","event_type":"bookTicker","event_time_ms":1788563043726,"raw_json":"{\"stream\":\"btcusdt@bookTicker\",\"data\":{\"e\":\"bookTicker\",\"u\":11478212624820,\"s\":\"BTCUSDT\",\"ps\":\"BTCUSDT\",\"b\":\"79598.10\",\"B\":\"10.931\",\"a\":\"79598.20\",\"A\":\"3.206\",\"T\":1788563043726,\"E\":1788563043726,\"st\":1}}"}
{"receive_ns":1788563043662198000,"stream":"btcusdt@bookTicker","event_type":"bookTicker","event_time_ms":1788563043727,"raw_json":"{\"stream\":\"btcusdt@bookTicker\",\"data\":{\"e\":\"bookTicker\",\"u\":11478212624972,\"s\":\"BTCUSDT\",\"ps\":\"BTCUSDT\",\"b\":\"79598.10\",\"B\":\"10.931\",\"a\":\"79598.20\",\"A\":\"3.199\",\"T\":1788563043726,\"E\":1788563043727,\"st\":1}}"}
{"receive_ns":1788563043662397000,"stream":"btcusdt@bookTicker","event_type":"bookTicker","event_time_ms":1788563043727,"raw_json":"{\"stream\":\"btcusdt@bookTicker\",\"data\":{\"e\":\"bookTicker\",\"u\":11478212624985,\"s\":\"BTCUSDT\",\"ps\":\"BTCUSDT\",\"b\":\"79598.10\",\"B\":\"10.923\",\"a\":\"79598.20\",\"A\":\"3.199\",\"T\":1788563043726,\"E\":1788563043727,\"st\":1}}"}
{"receive_ns":1788563043667390000,"stream":"btcusdt@bookTicker","event_type":"bookTicker","event_time_ms":1788563043732,"raw_json":"{\"stream\":\"btcusdt@bookTicker\",\"data\":{\"e\":\"bookTicker\",\"u\":11478212625405,\"s\":\"BTCUSDT\",\"ps\":\"BTCUSDT\",\"b\":\"79598.10\",\"B\":\"10.931\",\"a\":\"79598.20\",\"A\":\"3.199\",\"T\":1788563043732,\"E\":1788563043732,\"st\":1}}"}
{"receive_ns":1788563043669672000,"stream":"btcusdt@bookTicker","event_type":"bookTicker","event_time_ms":1788563043733,"raw_json":"{\"stream\":\"btcusdt@bookTicker\",\"data\":{\"e\":\"bookTicker\",\"u\":11478212625508,\"s\":\"BTCUSDT\",\"ps\":\"BTCUSDT\",\"b\":\"79598.10\",\"B\":\"10.923\",\"a\":\"79598.20\",\"A\":\"3.199\",\"T\":1788563043733,\"E\":1788563043733,\"st\":1}}"}
{"receive_ns":1788563043696545000,"stream":"btcusdt@bookTicker","event_type":"bookTicker","event_time_ms":1788563043761,"raw_json":"{\"stream\":\"btcusdt@bookTicker\",\"data\":{\"e\":\"bookTicker\",\"u\":11478212627691,\"s\":\"BTCUSDT\",\"ps\":\"BTCUSDT\",\"b\":\"79598.10\",\"B\":\"10.923\",\"a\":\"79598.20\",\"A\":\"3.206\",\"T\":1788563043761,\"E\":1788563043761,\"st\":1}}"}
{"receive_ns":1788563043706345000,"stream":"btcusdt@bookTicker","event_type":"bookTicker","event_time_ms":1788563043770,"raw_json":"{\"stream\":\"btcusdt@bookTicker\",\"data\":{\"e\":\"bookTicker\",\"u\":11478212628132,\"s\":\"BTCUSDT\",\"ps\":\"BTCUSDT\",\"b\":\"79598.10\",\"B\":\"10.939\",\"a\":\"79598.20\",\"A\":\"3.206\",\"T\":1788563043770,\"E\":1788563043770,\"st\":1}}"}
{"receive_ns":1788563043706613000,"stream":"btcusdt@bookTicker","event_type":"bookTicker","event_time_ms":1788563043771,"raw_json":"{\"stream\":\"btcusdt@bookTicker\",\"data\":{\"e\":\"bookTicker\",\"u\":11478212628185,\"s\":\"BTCUSDT\",\"ps\":\"BTCUSDT\",\"b\":\"79598.10\",\"B\":\"10.939\",\"a\":\"79598.20\",\"A\":\"3.207\",\"T\":1788563043771,\"E\":1788563043771,\"st\":1}}"}
{"receive_ns":1788563043728541000,"stream":"btcusdt@bookTicker","event_type":"bookTicker","event_time_ms":1788563043792,"raw_json":"{\"stream\":\"btcusdt@bookTicker\",\"data\":{\"e\":\"bookTicker\",\"u\":11478212629776,\"s\":\"BTCUSDT\",\"ps\":\"BTCUSDT\",\"b\":\"79598.10\",\"B\":\"10.939\",\"a\":\"79598.20\",\"A\":\"3.206\",\"T\":1788563043792,\"E\":1788563043792,\"st\":1}}"}
{"receive_ns":1788563043762097000,"stream":"btcusdt@depth@100ms","event_type":"depthUpdate","event_time_ms":1788563043827,"raw_json":"{\"stream\":\"btcusdt@depth@100ms\",\"data\":{\"e\":\"depthUpdate\",\"E\":1788563043827,\"T\":1788563043825,\"s\":\"BTCUSDT\",\"ps\":\"BTCUSDT\",\"U\":11478212624624,\"u\":11478212631313,\"pu\":11478212624515,\"b\":[[\"1000.00\",\"24.604\"],[\"29098.10\",\"1.589\"],[\"29198.10\",\"0.511\"],[\"55705.10\",\"0.002\"],[\"71638.20\",\"0.002\"],[\"72461.70\",\"0.012\"],[\"76414.10\",\"0.000\"],[\"78151.60\",\"0.007\"],[\"78802.10\",\"5.212\"],[\"79401.10\",\"1.739\"],[\"79418.70\",\"4.056\"],[\"79419.90\",\"1.048\"],[\"79454.00\",\"1.886\"],[\"79454.20\",\"0.628\"],[\"79472.70\",\"1.647\"],[\"79492.60\",\"1.332\"],[\"79511.80\",\"0.053\"],[\"79512.00\",\"0.047\"],[\"79576.60\",\"0.001\"],[\"79588.90\",\"0.170\"],[\"79589.10\",\"0.005\"],[\"79589.40\",\"0.002\"],[\"79592.20\",\"0.049\"],[\"79596.50\",\"0.077\"],[\"79598.10\",\"10.939\"]],\"a\":[[\"79598.20\",\"3.206\"],[\"79599.80\",\"0.000\"],[\"79601.00\",\"0.008\"],[\"79601.20\",\"0.001\"],[\"79601.30\",\"0.000\"],[\"79601.50\",\"0.003\"],[\"79601.60\",\"0.026\"],[\"79601.70\",\"0.027\"],[\"79601.80\",\"0.027\"],[\"79602.00\",\"0.103\"],[\"79602.10\",\"0.028\"],[\"79602.20\",\"0.029\"],[\"79602.40\",\"0.027\"],[\"79602.50\",\"0.026\"],[\"79602.60\",\"0.026\"],[\"79602.70\",\"0.029\"],[\"79602.80\",\"0.000\"],[\"79602.90\",\"0.001\"],[\"79603.00\",\"0.000\"],[\"79603.10\",\"0.000\"],[\"79606.10\",\"0.252\"],[\"79609.60\",\"0.258\"],[\"79610.60\",\"0.440\"],[\"79611.00\",\"0.695\"],[\"79611.10\",\"1.034\"],[\"79611.20\",\"0.539\"],[\"79611.80\",\"1.336\"],[\"79612.60\",\"0.140\"],[\"79622.90\",\"0.001\"],[\"79623.20\",\"0.627\"],[\"79687.00\",\"0.214\"],[\"79687.20\",\"1.511\"],[\"79722.30\",\"1.885\"],[\"79723.00\",\"0.186\"],[\"79739.60\",\"0.001\"],[\"79739.80\",\"0.000\"],[\"79745.10\",\"3.141\"],[\"79745.40\",\"0.004\"],[\"79962.40\",\"1.273\"],[\"79996.20\",\"1.477\"],[\"80394.20\",\"6.098\"],[\"80792.20\",\"3.498\"]],\"st\":1}}"}
{"receive_ns":1788563043777726000,"stream":"btcusdt@bookTicker","event_type":"bookTicker","event_time_ms":1788563043841,"raw_json":"{\"stream\":\"btcusdt@bookTicker\",\"data\":{\"e\":\"bookTicker\",\"u\":11478212632007,\"s\":\"BTCUSDT\",\"ps\":\"BTCUSDT\",\"b\":\"79598.10\",\"B\":\"10.939\",\"a\":\"79598.20\",\"A\":\"3.208\",\"T\":1788563043841,\"E\":1788563043841,\"st\":1}}"}
{"receive_ns":1788563043827903000,"stream":"btcusdt@bookTicker","event_type":"bookTicker","event_time_ms":1788563043891,"raw_json":"{\"stream\":\"btcusdt@bookTicker\",\"data\":{\"e\":\"bookTicker\",\"u\":11478212634215,\"s\":\"BTCUSDT\",\"ps\":\"BTCUSDT\",\"b\":\"79598.10\",\"B\":\"10.907\",\"a\":\"79598.20\",\"A\":\"3.208\",\"T\":1788563043891,\"E\":1788563043891,\"st\":1}}"}
{"receive_ns":1788563043828181000,"stream":"btcusdt@bookTicker","event_type":"bookTicker","event_time_ms":1788563043894,"raw_json":"{\"stream\":\"btcusdt@bookTicker\",\"data\":{\"e\":\"bookTicker\",\"u\":11478212634363,\"s\":\"BTCUSDT\",\"ps\":\"BTCUSDT\",\"b\":\"79598.10\",\"B\":\"10.941\",\"a\":\"79598.20\",\"A\":\"3.208\",\"T\":1788563043894,\"E\":1788563043894,\"st\":1}}"}
{"receive_ns":1788563043864407000,"stream":"btcusdt@depth@100ms","event_type":"depthUpdate","event_time_ms":1788563043929,"raw_json":"{\"stream\":\"btcusdt@depth@100ms\",\"data\":{\"e\":\"depthUpdate\",\"E\":1788563043929,\"T\":1788563043925,\"s\":\"BTCUSDT\",\"ps\":\"BTCUSDT\",\"U\":11478212631396,\"u\":11478212635539,\"pu\":11478212631313,\"b\":[[\"1000.00\",\"24.604\"],[\"29098.10\",\"1.750\"],[\"29198.10\",\"0.343\"],[\"29498.10\",\"0.007\"],[\"71638.20\",\"0.002\"],[\"75618.20\",\"0.004\"],[\"78006.20\",\"0.021\"],[\"78436.00\",\"0.258\"],[\"78603.10\",\"2.112\"],[\"78802.10\",\"5.212\"],[\"78809.50\",\"0.259\"],[\"79200.10\",\"0.277\"],[\"79401.10\",\"0.232\"],[\"79404.00\",\"1.014\"],[\"79473.70\",\"0.594\"],[\"79473.80\",\"0.000\"],[\"79494.60\",\"1.507\"],[\"79495.50\",\"0.215\"],[\"79572.10\",\"0.079\"],[\"79575.30\",\"0.440\"],[\"79592.20\",\"0.049\"],[\"79598.10\",\"10.941\"]],\"a\":[[\"79598.20\",\"3.208\"],[\"79600.10\",\"0.027\"],[\"79600.90\",\"0.106\"],[\"79601.00\",\"0.034\"],[\"79601.30\",\"0.026\"],[\"79601.50\",\"0.029\"],[\"79602.20\",\"0.003\"],[\"79602.40\",\"0.001\"],[\"79602.50\",\"0.000\"],[\"79602.60\",\"0.000\"],[\"79602.70\",\"0.003\"],[\"79609.50\",\"0.009\"],[\"79610.20\",\"0.010\"],[\"79610.60\",\"0.001\"],[\"79611.00\",\"0.695\"],[\"79611.20\",\"0.539\"],[\"79611.40\",\"0.859\"],[\"79613.70\",\"0.000\"],[\"79614.90\",\"0.372\"],[\"79615.80\",\"0.881\"],[\"79617.00\",\"0.457\"],[\"79722.30\",\"2.270\"],[\"79722.50\",\"0.000\"],[\"79735.50\",\"0.275\"],[\"79739.50\",\"0.000\"],[\"79739.80\",\"0.000\"],[\"79962.40\",\"1.273\"],[\"79996.20\",\"1.477\"],[\"80394.20\",\"6.098\"],[\"80663.50\",\"0.000\"],[\"80792.20\",\"4.240\"],[\"80951.40\",\"2.028\"]],\"st\":1}}"}
{"receive_ns":1788563043954049000,"stream":"btcusdt@bookTicker","event_type":"bookTicker","event_time_ms":1788563044018,"raw_json":"{\"stream\":\"btcusdt@bookTicker\",\"data\":{\"e\":\"bookTicker\",\"u\":11478212639943,\"s\":\"BTCUSDT\",\"ps\":\"BTCUSDT\",\"b\":\"79598.10\",\"B\":\"10.941\",\"a\":\"79598.20\",\"A\":\"3.206\",\"T\":1788563044018,\"E\":1788563044018,\"st\":1}}"}
{"receive_ns":1788563043961298000,"stream":"btcusdt@bookTicker","event_type":"bookTicker","event_time_ms":1788563044025,"raw_json":"{\"stream\":\"btcusdt@bookTicker\",\"data\":{\"e\":\"bookTicker\",\"u\":11478212641511,\"s\":\"BTCUSDT\",\"ps\":\"BTCUSDT\",\"b\":\"79598.10\",\"B\":\"10.941\",\"a\":\"79598.20\",\"A\":\"3.207\",\"T\":1788563044025,\"E\":1788563044025,\"st\":1}}"}
{"receive_ns":1788563043961533000,"stream":"btcusdt@bookTicker","event_type":"bookTicker","event_time_ms":1788563044026,"raw_json":"{\"stream\":\"btcusdt@bookTicker\",\"data\":{\"e\":\"bookTicker\",\"u\":11478212641631,\"s\":\"BTCUSDT\",\"ps\":\"BTCUSDT\",\"b\":\"79598.10\",\"B\":\"10.949\",\"a\":\"79598.20\",\"A\":\"3.207\",\"T\":1788563044026,\"E\":1788563044026,\"st\":1}}"}
{"receive_ns":1788563043961751000,"stream":"btcusdt@bookTicker","event_type":"bookTicker","event_time_ms":1788563044027,"raw_json":"{\"stream\":\"btcusdt@bookTicker\",\"data\":{\"e\":\"bookTicker\",\"u\":11478212641826,\"s\":\"BTCUSDT\",\"ps\":\"BTCUSDT\",\"b\":\"79598.10\",\"B\":\"10.941\",\"a\":\"79598.20\",\"A\":\"3.207\",\"T\":1788563044027,\"E\":1788563044027,\"st\":1}}"}
{"receive_ns":1788563043966151000,"stream":"btcusdt@depth@100ms","event_type":"depthUpdate","event_time_ms":1788563044031,"raw_json":"{\"stream\":\"btcusdt@depth@100ms\",\"data\":{\"e\":\"depthUpdate\",\"E\":1788563044031,\"T\":1788563044029,\"s\":\"BTCUSDT\",\"ps\":\"BTCUSDT\",\"U\":11478212635632,\"u\":11478212642063,\"pu\":11478212635539,\"b\":[[\"29098.10\",\"1.820\"],[\"29198.10\",\"0.217\"],[\"29498.10\",\"0.063\"],[\"71638.20\",\"0.002\"],[\"72626.40\",\"0.012\"],[\"76414.10\",\"0.002\"],[\"78597.90\",\"0.028\"],[\"78600.30\",\"0.004\"],[\"78802.10\",\"5.212\"],[\"79195.60\",\"3.654\"],[\"79401.10\",\"0.232\"],[\"79472.70\",\"1.547\"],[\"79492.60\",\"1.432\"],[\"79572.50\",\"0.342\"],[\"79573.20\",\"0.440\"],[\"79573.50\",\"0.373\"],[\"79575.30\",\"0.001\"],[\"79592.20\",\"0.049\"],[\"79598.10\",\"10.941\"]],\"a\":[[\"79598.20\",\"3.207\"],[\"79599.20\",\"0.000\"],[\"79600.10\",\"0.001\"],[\"79600.90\",\"0.080\"],[\"79601.00\",\"0.008\"],[\"79601.30\",\"0.000\"],[\"79602.20\",\"0.029\"],[\"79602.30\",\"0.026\"],[\"79606.10\",\"0.001\"],[\"79609.50\",\"0.017\"],[\"79610.20\",\"0.441\"],[\"79610.90\",\"1.053\"],[\"79611.20\",\"0.226\"],[\"79611.40\",\"0.420\"],[\"79613.50\",\"1.617\"],[\"79614.90\",\"0.000\"],[\"79627.90\",\"0.046\"],[\"79629.50\",\"0.033\"],[\"79733.90\",\"0.187\"],[\"79735.50\",\"0.526\"],[\"79739.30\",\"0.125\"],[\"79739.50\",\"0.000\"],[\"79962.40\",\"1.273\"],[\"79963.20\",\"0.211\"],[\"79996.20\",\"1.477\"],[\"80394.20\",\"6.719\"],[\"80568.10\",\"3.685\"],[\"80767.90\",\"0.000\"]],\"st\":1}}"}
{"receive_ns":1788563043997120000,"stream":"btcusdt@bookTicker","event_type":"bookTicker","event_time_ms":1788563044061,"raw_json":"{\"stream\":\"btcusdt@bookTicker\",\"data\":{\"e\":\"bookTicker\",\"u\":11478212644946,\"s\":\"BTCUSDT\",\"ps\":\"BTCUSDT\",\"b\":\"79598.10\",\"B\":\"10.949\",\"a\":\"79598.20\",\"A\":\"3.207\",\"T\":1788563044061,\"E\":1788563044061,\"st\":1}}"}
{"receive_ns":1788563043997389000,"stream":"btcusdt@bookTicker","event_type":"bookTicker","event_time_ms":1788563044061,"raw_json":"{\"stream\":\"btcusdt@bookTicker\",\"data\":{\"e\":\"bookTicker\",\"u\":11478212645052,\"s\":\"BTCUSDT\",\"ps\":\"BTCUSDT\",\"b\":\"79598.10\",\"B\":\"10.941\",\"a\":\"79598.20\",\"A\":\"3.207\",\"T\":1788563044061,\"E\":1788563044061,\"st\":1}}"}
{"receive_ns":1788563044071299000,"stream":"btcusdt@depth@100ms","event_type":"depthUpdate","event_time_ms":1788563044133,"raw_json":"{\"stream\":\"btcusdt@depth@100ms\",\"data\":{\"e\":\"depthUpdate\",\"E\":1788563044133,\"T\":1788563044130,\"s\":\"BTCUSDT\",\"ps\":\"BTCUSDT\",\"U\":11478212642230,\"u\":11478212650933,\"pu\":11478212642063,\"b\":[[\"1000.00\",\"24.604\"],[\"29098.10\",\"1.869\"],[\"29198.10\",\"0.105\"],[\"29498.10\",\"0.126\"],[\"71638.20\",\"0.002\"],[\"76414.10\",\"0.000\"],[\"78380.60\",\"0.023\"],[\"78802.10\",\"5.212\"],[\"79195.60\",\"3.276\"],[\"79200.10\",\"0.137\"],[\"79494.60\",\"0.502\"],[\"79563.20\",\"0.056\"],[\"79564.30\",\"0.252\"],[\"79572.10\",\"0.079\"],[\"79572.60\",\"0.373\"],[\"79573.20\",\"0.440\"],[\"79573.50\",\"0.000\"],[\"79578.60\",\"0.039\"],[\"79581.80\",\"0.000\"],[\"79582.90\",\"0.076\"],[\"79583.30\",\"0.562\"],[\"79583.80\",\"0.000\"],[\"79597.80\",\"0.077\"],[\"79598.10\",\"10.941\"]],\"a\":[[\"79599.90\",\"0.010\"],[\"79600.90\",\"0.004\"],[\"79601.50\",\"0.003\"],[\"79601.60\",\"0.000\"],[\"79601.70\",\"0.001\"],[\"79601.80\",\"0.001\"],[\"79602.00\",\"0.077\"],[\"79602.10\",\"0.002\"],[\"79602.20\",\"0.029\"],[\"79602.30\",\"0.026\"],[\"79602.40\",\"0.027\"],[\"79602.50\",\"0.026\"],[\"79602.60\",\"0.000\"],[\"79602.70\",\"0.029\"],[\"79602.80\",\"0.026\"],[\"79602.90\",\"0.027\"],[\"79603.00\",\"0.026\"],[\"79603.10\",\"0.026\"],[\"79603.30\",\"0.026\"],[\"79603.40\",\"0.002\"],[\"79603.50\",\"0.002\"],[\"79606.30\",\"0.340\"],[\"79606.40\",\"0.080\"],[\"79612.20\",\"0.080\"],[\"79612.40\",\"0.000\"],[\"79613.50\",\"1.617\"],[\"79630.10\",\"0.032\"],[\"79648.50\",\"1.062\"],[\"79651.00\",\"2.000\"],[\"79684.90\",\"0.031\"],[\"79735.50\",\"0.275\"],[\"79739.30\",\"0.000\"],[\"79739.50\",\"0.000\"],[\"79963.20\",\"0.011\"],[\"79996.20\",\"0.950\"],[\"80394.20\",\"6.719\"],[\"80548.80\",\"9.296\"],[\"80712.60\",\"16.209\"],[\"80815.70\",\"0.000\"],[\"80967.30\",\"0.986\"],[\"81826.90\",\"0.732\"]],\"st\":1}}"}
{"receive_ns":1788563044141821000,"stream":"btcusdt@bookTicker","event_type":"bookTicker","event_time_ms":1788563044205,"raw_json":"{\"stream\":\"btcusdt@bookTicker\",\"data\":{\"e\":\"bookTicker\",\"u\":11478212656670,\"s\":\"BTCUSDT\",\"ps\":\"BTCUSDT\",\"b\":\"79598.10\",\"B\":\"10.908\",\"a\":\"79598.20\",\"A\":\"3.207\",\"T\":1788563044205,\"E\":1788563044205,\"st\":1}}"}
{"receive_ns":1788563044145073000,"stream":"btcusdt@bookTicker","event_type":"bookTicker","event_time_ms":1788563044208,"raw_json":"{\"stream\":\"btcusdt@bookTicker\",\"data\":{\"e\":\"bookTicker\",\"u\":11478212656837,\"s\":\"BTCUSDT\",\"ps\":\"BTCUSDT\",\"b\":\"79598.10\",\"B\":\"10.940\",\"a\":\"79598.20\",\"A\":\"3.207\",\"T\":1788563044208,\"E\":1788563044208,\"st\":1}}"}
{"receive_ns":1788563044152926000,"stream":"btcusdt@bookTicker","event_type":"bookTicker","event_time_ms":1788563044216,"raw_json":"{\"stream\":\"btcusdt@bookTicker\",\"data\":{\"e\":\"bookTicker\",\"u\":11478212657261,\"s\":\"BTCUSDT\",\"ps\":\"BTCUSDT\",\"b\":\"79598.10\",\"B\":\"10.915\",\"a\":\"79598.20\",\"A\":\"3.207\",\"T\":1788563044216,\"E\":1788563044216,\"st\":1}}"}
{"receive_ns":1788563044154060000,"stream":"btcusdt@bookTicker","event_type":"bookTicker","event_time_ms":1788563044219,"raw_json":"{\"stream\":\"btcusdt@bookTicker\",\"data\":{\"e\":\"bookTicker\",\"u\":11478212657509,\"s\":\"BTCUSDT\",\"ps\":\"BTCUSDT\",\"b\":\"79598.10\",\"B\":\"10.947\",\"a\":\"79598.20\",\"A\":\"3.207\",\"T\":1788563044219,\"E\":1788563044219,\"st\":1}}"}
{"receive_ns":1788563044170536000,"stream":"btcusdt@depth@100ms","event_type":"depthUpdate","event_time_ms":1788563044235,"raw_json":"{\"stream\":\"btcusdt@depth@100ms\",\"data\":{\"e\":\"depthUpdate\",\"E\":1788563044235,\"T\":1788563044233,\"s\":\"BTCUSDT\",\"ps\":\"BTCUSDT\",\"U\":11478212651095,\"u\":11478212658441,\"pu\":11478212650933,\"b\":[[\"1000.00\",\"24.604\"],[\"29098.10\",\"1.897\"],[\"29198.10\",\"0.000\"],[\"29498.10\",\"0.203\"],[\"71638.20\",\"0.002\"],[\"72791.10\",\"0.011\"],[\"76414.10\",\"0.002\"],[\"78380.60\",\"0.030\"],[\"78669.00\",\"0.048\"],[\"78674.20\",\"0.057\"],[\"78802.10\",\"5.212\"],[\"79200.10\",\"0.268\"],[\"79401.10\",\"0.232\"],[\"79485.60\",\"0.201\"],[\"79492.60\",\"1.181\"],[\"79494.60\",\"1.507\"],[\"79495.50\",\"0.014\"],[\"79496.60\",\"0.251\"],[\"79525.00\",\"0.428\"],[\"79534.10\",\"0.357\"],[\"79563.20\",\"0.010\"],[\"79565.60\",\"0.048\"],[\"79566.00\",\"0.001\"],[\"79566.40\",\"0.009\"],[\"79572.10\",\"0.079\"],[\"79572.60\",\"0.000\"],[\"79573.20\",\"0.001\"],[\"79574.90\",\"0.373\"],[\"79575.30\",\"0.440\"],[\"79578.90\",\"0.031\"],[\"79583.00\",\"0.636\"],[\"79583.50\",\"0.000\"],[\"79584.80\",\"0.066\"],[\"79585.00\",\"0.080\"],[\"79585.40\",\"0.004\"],[\"79589.00\",\"0.088\"],[\"79589.10\",\"0.001\"],[\"79589.40\",\"0.006\"],[\"79592.20\",\"0.049\"],[\"79598.10\",\"10.947\"]],\"a\":[[\"79602.20\",\"0.003\"],[\"79602.30\",\"0.000\"],[\"79602.40\",\"0.001\"],[\"79602.50\",\"0.000\"],[\"79602.70\",\"0.003\"],[\"79602.80\",\"0.000\"],[\"79602.90\",\"0.001\"],[\"79603.00\",\"0.000\"],[\"79603.10\",\"0.000\"],[\"79603.30\",\"0.000\"],[\"79603.90\",\"0.076\"],[\"79604.10\",\"0.355\"],[\"79604.50\",\"0.007\"],[\"79604.60\",\"0.003\"],[\"79604.70\",\"0.000\"],[\"79604.90\",\"0.460\"],[\"79605.00\",\"0.029\"],[\"79605.10\",\"0.028\"],[\"79605.20\",\"0.103\"],[\"79605.30\",\"0.026\"],[\"79605.40\",\"0.026\"],[\"79605.60\",\"1.002\"],[\"79605.70\",\"0.036\"],[\"79605.80\",\"0.026\"],[\"79605.90\",\"0.002\"],[\"79606.00\",\"0.001\"],[\"79606.40\",\"0.078\"],[\"79606.70\",\"0.004\"],[\"79609.50\",\"0.009\"],[\"79610.20\",\"0.010\"],[\"79610.70\",\"0.643\"],[\"79610.90\",\"0.740\"],[\"79611.00\",\"0.691\"],[\"79611.10\",\"0.972\"],[\"79611.30\",\"0.752\"],[\"79611.40\",\"0.859\"],[\"79611.70\",\"0.065\"],[\"79613.50\",\"1.245\"],[\"79614.90\",\"0.372\"],[\"79616.10\",\"0.008\"],[\"79616.80\",\"0.001\"],[\"79627.90\",\"0.000\"],[\"79629.40\",\"0.826\"],[\"79645.10\",\"0.229\"],[\"79645.20\",\"0.081\"],[\"79653.80\",\"0.040\"],[\"79698.90\",\"0.003\"],[\"79735.50\",\"0.275\"],[\"79736.40\",\"0.211\"],[\"79739.40\",\"0.000\"],[\"79739.60\",\"0.001\"],[\"79739.80\",\"0.125\"],[\"79962.30\",\"0.252\"],[\"79962.40\",\"1.273\"],[\"79996.20\",\"1.476\"],[\"80394.20\",\"6.719\"],[\"80815.70\",\"0.007\"]],\"st\":1}}"}
{"receive_ns":1788563044193345000,"stream":"btcusdt@bookTicker","event_type":"bookTicker","event_time_ms":1788563044257,"raw_json":"{\"stream\":\"btcusdt@bookTicker\",\"data\":{\"e\":\"bookTicker\",\"u\":11478212659839,\"s\":\"BTCUSDT\",\"ps\":\"BTCUSDT\",\"b\":\"79598.10\",\"B\":\"10.946\",\"a\":\"79598.20\",\"A\":\"3.207\",\"T\":1788563044257,\"E\":1788563044257,\"st\":1}}"}
{"receive_ns":1788563044286041000,"stream":"btcusdt@depth@100ms","event_type":"depthUpdate","event_time_ms":1788563044337,"raw_json":"{\"stream\":\"btcusdt@depth@100ms\",\"data\":{\"e\":\"depthUpdate\",\"E\":1788563044337,\"T\":1788563044336,\"s\":\"BTCUSDT\",\"ps\":\"BTCUSDT\",\"U\":11478212658532,\"u\":11478212665387,\"pu\":11478212658441,\"b\":[[\"29098.10\",\"1.722\"],[\"29498.10\",\"0.378\"],[\"63679.00\",\"0.002\"],[\"71638.20\",\"0.002\"],[\"76414.10\",\"0.000\"],[\"78802.10\",\"5.212\"],[\"79200.10\",\"0.772\"],[\"79564.20\",\"0.733\"],[\"79565.60\",\"0.002\"],[\"79573.20\",\"0.440\"],[\"79573.50\",\"0.373\"],[\"79574.90\",\"0.000\"],[\"79575.30\",\"0.001\"],[\"79598.10\",\"10.946\"]],\"a\":[[\"79609.50\",\"0.017\"],[\"79610.20\",\"0.441\"],[\"79611.40\",\"0.420\"],[\"79613.30\",\"0.919\"],[\"79614.90\",\"0.000\"],[\"79627.90\",\"0.046\"],[\"79629.40\",\"0.780\"],[\"79645.20\",\"0.080\"],[\"79645.30\",\"0.000\"],[\"79739.00\",\"0.217\"],[\"79739.80\",\"0.000\"],[\"80012.90\",\"0.001\"],[\"80013.80\",\"0.090\"],[\"80394.20\",\"6.719\"],[\"80553.40\",\"15.613\"],[\"80613.40\",\"6.443\"]],\"st\":1}}"}
{"receive_ns":1788563044334083000,"stream":"btcusdt@bookTicker","event_type":"bookTicker","event_time_ms":1788563044397,"raw_json":"{\"stream\":\"btcusdt@bookTicker\",\"data\":{\"e\":\"bookTicker\",\"u\":11478212670202,\"s\":\"BTCUSDT\",\"ps\":\"BTCUSDT\",\"b\":\"79598.10\",\"B\":\"10.912\",\"a\":\"79598.20\",\"A\":\"3.207\",\"T\":1788563044397,\"E\":1788563044397,\"st\":1}}"}
{"receive_ns":1788563044334972000,"stream":"btcusdt@bookTicker","event_type":"bookTicker","event_time_ms":1788563044400,"raw_json":"{\"stream\":\"btcusdt@bookTicker\",\"data\":{\"e\":\"bookTicker\",\"u\":11478212670519,\"s\":\"BTCUSDT\",\"ps\":\"BTCUSDT\",\"b\":\"79598.10\",\"B\":\"10.949\",\"a\":\"79598.20\",\"A\":\"3.207\",\"T\":1788563044400,\"E\":1788563044400,\"st\":1}}"}
{"receive_ns":1788563044382019000,"stream":"btcusdt@depth@100ms","event_type":"depthUpdate","event_time_ms":1788563044439,"raw_json":"{\"stream\":\"btcusdt@depth@100ms\",\"data\":{\"e\":\"depthUpdate\",\"E\":1788563044439,\"T\":1788563044438,\"s\":\"BTCUSDT\",\"ps\":\"BTCUSDT\",\"U\":11478212665471,\"u\":11478212673255,\"pu\":11478212665387,\"b\":[[\"1000.00\",\"24.604\"],[\"29098.10\",\"1.540\"],[\"29498.10\",\"0.560\"],[\"63678.00\",\"0.002\"],[\"71638.20\",\"0.002\"],[\"72955.80\",\"0.011\"],[\"78244.90\",\"3.383\"],[\"78583.70\",\"3.487\"],[\"78666.80\",\"0.443\"],[\"78802.10\",\"5.211\"],[\"79200.10\",\"0.772\"],[\"79401.10\",\"0.000\"],[\"79485.60\",\"0.201\"],[\"79492.60\",\"0.001\"],[\"79494.60\",\"1.507\"],[\"79496.60\",\"0.000\"],[\"79565.30\",\"0.196\"],[\"79566.00\",\"0.453\"],[\"79572.30\",\"0.021\"],[\"79574.40\",\"0.056\"],[\"79579.40\",\"0.628\"],[\"79579.60\",\"0.003\"],[\"79584.80\",\"0.004\"],[\"79585.40\",\"0.066\"],[\"79590.50\",\"0.027\"],[\"79591.30\",\"0.251\"],[\"79598.10\",\"10.949\"]],\"a\":[[\"79603.50\",\"0.028\"],[\"79603.60\",\"0.027\"],[\"79605.70\",\"0.010\"],[\"79605.80\",\"0.000\"],[\"79611.20\",\"0.226\"],[\"79611.30\",\"0.814\"],[\"79611.70\",\"0.003\"],[\"79615.70\",\"0.454\"],[\"79617.00\",\"0.005\"],[\"79620.30\",\"0.020\"],[\"79620.40\",\"0.752\"],[\"79645.50\",\"10.000\"],[\"79651.00\",\"0.000\"],[\"79733.90\",\"0.127\"],[\"79735.50\",\"0.275\"],[\"79736.40\",\"0.211\"],[\"79739.00\",\"0.092\"],[\"79739.60\",\"0.001\"],[\"79962.20\",\"0.306\"],[\"79962.30\",\"0.001\"],[\"79962.40\",\"0.419\"],[\"79996.20\",\"1.276\"],[\"80394.20\",\"6.719\"],[\"80752.40\",\"5.196\"],[\"80832.00\",\"2.597\"]],\"st\":1}}"}
{"receive_ns":1788563044485853000,"stream":"btcusdt@depth@100ms","event_type":"depthUpdate","event_time_ms":1788563044541,"raw_json":"{\"stream\":\"btcusdt@depth@100ms\",\"data\":{\"e\":\"depthUpdate\",\"E\":1788563044541,\"T\":1788563044540,\"s\":\"BTCUSDT\",\"ps\":\"BTCUSDT\",\"U\":11478212673374,\"u\":11478212682638,\"pu\":11478212673255,\"b\":[[\"1000.00\",\"24.604\"],[\"29098.10\",\"1.365\"],[\"29498.10\",\"0.735\"],[\"71638.20\",\"0.002\"],[\"76414.10\",\"0.002\"],[\"78006.20\",\"0.018\"],[\"78603.10\",\"2.303\"],[\"78802.10\",\"5.211\"],[\"78881.50\",\"0.000\"],[\"79200.10\",\"0.782\"],[\"79401.10\",\"0.232\"],[\"79472.70\",\"1.647\"],[\"79492.60\",\"1.332\"],[\"79563.20\",\"0.010\"],[\"79564.20\",\"0.687\"],[\"79564.80\",\"0.002\"],[\"79565.50\",\"0.838\"],[\"79565.90\",\"0.038\"],[\"79566.00\",\"0.001\"],[\"79566.40\",\"0.003\"],[\"79567.00\",\"0.002\"],[\"79567.10\",\"0.452\"],[\"79572.10\",\"0.079\"],[\"79572.50\",\"0.342\"],[\"79573.20\",\"0.001\"],[\"79573.50\",\"0.000\"],[\"79574.80\",\"0.828\"],[\"79575.30\",\"0.440\"],[\"79578.40\",\"0.416\"],[\"79589.10\",\"0.005\"],[\"79589.40\",\"0.002\"],[\"79597.80\",\"0.001\"]],\"a\":[[\"79600.80\",\"0.077\"],[\"79601.90\",\"0.000\"],[\"79602.20\",\"0.029\"],[\"79602.80\",\"0.026\"],[\"79603.50\",\"0.002\"],[\"79605.60\",\"0.976\"],[\"79610.20\",\"0.002\"],[\"79611.00\",\"1.008\"],[\"79611.30\",\"0.497\"],[\"79611.40\",\"0.859\"],[\"79613.30\",\"0.547\"],[\"79614.70\",\"0.373\"],[\"79615.70\",\"0.002\"],[\"79615.80\",\"0.881\"],[\"79616.10\",\"0.002\"],[\"79616.50\",\"0.061\"],[\"79616.90\",\"0.456\"],[\"79627.90\",\"0.000\"],[\"79629.30\",\"0.068\"],[\"79645.60\",\"0.128\"],[\"79735.50\",\"0.275\"],[\"79736.40\",\"0.011\"],[\"79739.60\",\"0.001\"],[\"79962.20\",\"0.000\"],[\"79962.40\",\"1.273\"],[\"79996.20\",\"1.475\"],[\"80394.20\",\"6.719\"],[\"80548.80\",\"8.305\"]],\"st\":1}}"}
{"receive_ns":1788563044578000000,"stream":"btcusdt@depth@100ms","event_type":"depthUpdate","event_time_ms":1788563044643,"raw_json":"{\"stream\":\"btcusdt@depth@100ms\",\"data\":{\"e\":\"depthUpdate\",\"E\":1788563044643,\"T\":1788563044642,\"s\":\"BTCUSDT\",\"ps\":\"BTCUSDT\",\"U\":11478212682732,\"u\":11478212691093,\"pu\":11478212682638,\"b\":[[\"29098.10\",\"1.183\"],[\"29498.10\",\"0.917\"],[\"63678.00\",\"0.002\"],[\"71638.20\",\"0.002\"],[\"71675.00\",\"0.002\"],[\"76414.10\",\"0.000\"],[\"78525.70\",\"0.000\"],[\"78802.10\",\"5.211\"],[\"78956.90\",\"4.933\"],[\"79200.10\",\"0.782\"],[\"79485.60\",\"0.000\"],[\"79494.60\",\"1.005\"],[\"79542.30\",\"0.002\"],[\"79558.30\",\"0.078\"],[\"79564.40\",\"0.047\"],[\"79565.50\",\"0.792\"],[\"79573.20\",\"0.440\"],[\"79573.50\",\"0.373\"],[\"79574.80\",\"0.455\"],[\"79575.30\",\"0.001\"]],\"a\":[[\"79601.80\",\"0.027\"],[\"79605.40\",\"0.000\"],[\"79609.50\",\"0.009\"],[\"79610.20\",\"0.010\"],[\"79638.00\",\"0.006\"],[\"79657.10\",\"0.007\"],[\"79669.40\",\"0.080\"],[\"79669.90\",\"0.000\"],[\"79685.40\",\"0.015\"],[\"79694.10\",\"0.001\"],[\"79735.50\",\"0.526\"],[\"79962.40\",\"0.854\"],[\"79996.20\",\"1.475\"],[\"80394.20\",\"6.719\"],[\"80687.40\",\"11.142\"],[\"81150.40\",\"0.492\"]],\"st\":1}}"}
{"receive_ns":1788563044665930000,"stream":"btcusdt@bookTicker","event_type":"bookTicker","event_time_ms":1788563044728,"raw_json":"{\"stream\":\"btcusdt@bookTicker\",\"data\":{\"e\":\"bookTicker\",\"u\":11478212699718,\"s\":\"BTCUSDT\",\"ps\":\"BTCUSDT\",\"b\":\"79598.10\",\"B\":\"10.950\",\"a\":\"79598.20\",\"A\":\"3.207\",\"T\":1788563044728,\"E\":1788563044728,\"st\":1}}"}
{"receive_ns":1788563044680300000,"stream":"btcusdt@depth@100ms","event_type":"depthUpdate","event_time_ms":1788563044745,"raw_json":"{\"stream\":\"btcusdt@depth@100ms\",\"data\":{\"e\":\"depthUpdate\",\"E\":1788563044745,\"T\":1788563044741,\"s\":\"BTCUSDT\",\"ps\":\"BTCUSDT\",\"U\":11478212691211,\"u\":11478212700612,\"pu\":11478212691093,\"b\":[[\"1000.00\",\"24.604\"],[\"29098.10\",\"1.008\"],[\"29498.10\",\"1.092\"],[\"63678.00\",\"0.002\"],[\"63678.50\",\"0.000\"],[\"71638.20\",\"0.002\"],[\"73120.50\",\"0.011\"],[\"75618.30\",\"0.000\"],[\"76414.10\",\"0.002\"],[\"78802.10\",\"5.211\"],[\"78961.30\",\"1.012\"],[\"79200.10\",\"0.773\"],[\"79401.10\",\"0.232\"],[\"79404.00\",\"1.215\"],[\"79472.70\",\"1.547\"],[\"79488.20\",\"0.126\"],[\"79492.60\",\"1.432\"],[\"79494.60\",\"1.507\"],[\"79499.90\",\"0.046\"],[\"79507.10\",\"3.443\"],[\"79507.20\",\"0.972\"],[\"79522.60\",\"0.028\"],[\"79565.00\",\"0.008\"],[\"79574.40\",\"0.056\"],[\"79578.20\",\"0.405\"],[\"79592.20\",\"0.050\"],[\"79598.10\",\"10.950\"]],\"a\":[[\"79603.10\",\"0.200\"],[\"79614.30\",\"0.361\"],[\"79690.80\",\"4.291\"],[\"79691.10\",\"3.669\"],[\"79735.50\",\"0.526\"],[\"79821.50\",\"8.119\"],[\"79821.90\",\"0.000\"],[\"79962.40\",\"1.273\"],[\"79996.20\",\"1.475\"],[\"80394.20\",\"6.719\"],[\"80712.60\",\"18.065\"],[\"81190.10\",\"0.008\"]],\"st\":1}}"}
{"receive_ns":1788563044732339000,"stream":"btcusdt@bookTicker","event_type":"bookTicker","event_time_ms":1788563044788,"raw_json":"{\"stream\":\"btcusdt@bookTicker\",\"data\":{\"e\":\"bookTicker\",\"u\":11478212703414,\"s\":\"BTCUSDT\",\"ps\":\"BTCUSDT\",\"b\":\"79598.10\",\"B\":\"10.950\",\"a\":\"79598.20\",\"A\":\"3.208\",\"T\":1788563044788,\"E\":1788563044788,\"st\":1}}"}
{"receive_ns":1788563044783374000,"stream":"btcusdt@depth@100ms","event_type":"depthUpdate","event_time_ms":1788563044847,"raw_json":"{\"stream\":\"btcusdt@depth@100ms\",\"data\":{\"e\":\"depthUpdate\",\"E\":1788563044847,\"T\":1788563044846,\"s\":\"BTCUSDT\",\"ps\":\"BTCUSDT\",\"U\":11478212700820,\"u\":11478212706532,\"pu\":11478212700612,\"b\":[[\"1000.00\",\"24.604\"],[\"29098.10\",\"0.826\"],[\"29498.10\",\"1.274\"],[\"71638.20\",\"0.002\"],[\"73285.10\",\"0.011\"],[\"78483.10\",\"3.439\"],[\"78802.10\",\"5.211\"],[\"78996.60\",\"2.528\"],[\"79200.10\",\"0.632\"],[\"79494.60\",\"0.502\"],[\"79578.20\",\"0.417\"]],\"a\":[[\"79598.20\",\"3.208\"],[\"79735.20\",\"0.012\"],[\"79735.50\",\"0.275\"],[\"79739.30\",\"0.000\"],[\"79739.40\",\"0.000\"],[\"79996.20\",\"0.949\"],[\"80324.50\",\"0.000\"],[\"80394.20\",\"6.719\"],[\"80553.40\",\"16.604\"]],\"st\":1}}"}
{"receive_ns":1788563044783670000,"stream":"btcusdt@bookTicker","event_type":"bookTicker","event_time_ms":1788563044847,"raw_json":"{\"stream\":\"btcusdt@bookTicker\",\"data\":{\"e\":\"bookTicker\",\"u\":11478212706553,\"s\":\"BTCUSDT\",\"ps\":\"BTCUSDT\",\"b\":\"79598.10\",\"B\":\"10.950\",\"a\":\"79598.20\",\"A\":\"3.207\",\"T\":1788563044847,\"E\":1788563044847,\"st\":1}}"}
{"receive_ns":1788563044806665000,"stream":"btcusdt@bookTicker","event_type":"bookTicker","event_time_ms":1788563044854,"raw_json":"{\"stream\":\"btcusdt@bookTicker\",\"data\":{\"e\":\"bookTicker\",\"u\":11478212706989,\"s\":\"BTCUSDT\",\"ps\":\"BTCUSDT\",\"b\":\"79598.10\",\"B\":\"10.950\",\"a\":\"79598.20\",\"A\":\"3.209\",\"T\":1788563044854,\"E\":1788563044854,\"st\":1}}"}
{"receive_ns":1788563044891973000,"stream":"btcusdt@depth@100ms","event_type":"depthUpdate","event_time_ms":1788563044949,"raw_json":"{\"stream\":\"btcusdt@depth@100ms\",\"data\":{\"e\":\"depthUpdate\",\"E\":1788563044949,\"T\":1788563044947,\"s\":\"BTCUSDT\",\"ps\":\"BTCUSDT\",\"U\":11478212706553,\"u\":11478212712048,\"pu\":11478212706532,\"b\":[[\"29098.10\",\"0.651\"],[\"29498.10\",\"1.449\"],[\"63679.00\",\"0.002\"],[\"71638.20\",\"0.002\"],[\"76414.10\",\"0.000\"],[\"78240.50\",\"5.743\"],[\"78561.90\",\"0.890\"],[\"78802.10\",\"5.211\"],[\"79200.10\",\"0.773\"],[\"79401.10\",\"0.734\"],[\"79404.00\",\"1.215\"],[\"79494.60\",\"1.005\"],[\"79563.10\",\"0.050\"],[\"79564.40\",\"0.001\"],[\"79565.10\",\"0.453\"],[\"79567.10\",\"0.000\"],[\"79572.10\",\"0.079\"],[\"79572.40\",\"0.627\"],[\"79573.20\",\"0.001\"],[\"79573.50\",\"0.000\"],[\"79575.30\",\"0.440\"]],\"a\":[[\"79598.20\",\"3.209\"],[\"79601.30\",\"0.026\"],[\"79601.80\",\"0.001\"],[\"79602.10\",\"0.028\"],[\"79602.20\",\"0.029\"],[\"79602.40\",\"0.027\"],[\"79603.10\",\"0.200\"],[\"79605.20\",\"0.077\"],[\"79605.30\",\"0.000\"],[\"79609.50\",\"0.017\"],[\"79609.60\",\"0.258\"],[\"79610.20\",\"0.002\"],[\"79611.00\",\"1.008\"],[\"79611.20\",\"0.665\"],[\"79611.40\",\"0.420\"],[\"79612.40\",\"0.000\"],[\"79613.50\",\"1.245\"],[\"79614.60\",\"0.373\"],[\"79614.70\",\"0.001\"],[\"79626.90\",\"0.010\"],[\"79627.00\",\"0.002\"],[\"79628.10\",\"0.016\"],[\"79629.20\",\"0.066\"],[\"79629.30\",\"0.022\"],[\"79735.50\",\"0.024\"],[\"79739.40\",\"0.125\"],[\"79739.60\",\"0.001\"],[\"79962.40\",\"1.273\"],[\"79996.20\",\"1.475\"],[\"80195.20\",\"1.869\"],[\"80394.20\",\"6.719\"],[\"80713.20\",\"1.856\"]],\"st\":1}}"}
{"receive_ns":1788563044892942000,"stream":"btcusdt@bookTicker","event_type":"bookTicker","event_time_ms":1788563044951,"raw_json":"{\"stream\":\"btcusdt@bookTicker\",\"data\":{\"e\":\"bookTicker\",\"u\":11478212712293,\"s\":\"BTCUSDT\",\"ps\":\"BTCUSDT\",\"b\":\"79598.10\",\"B\":\"10.950\",\"a\":\"79598.20\",\"A\":\"3.207\",\"T\":1788563044951,\"E\":1788563044951,\"st\":1}}"}
{"receive_ns":1788563044897451000,"stream":"btcusdt@bookTicker","event_type":"bookTicker","event_time_ms":1788563044960,"raw_json":"{\"stream\":\"btcusdt@bookTicker\",\"data\":{\"e\":\"bookTicker\",\"u\":11478212712998,\"s\":\"BTCUSDT\",\"ps\":\"BTCUSDT\",\"b\":\"79598.10\",\"B\":\"10.950\",\"a\":\"79598.20\",\"A\":\"3.208\",\"T\":1788563044960,\"E\":1788563044960,\"st\":1}}"}
{"receive_ns":1788563044988335000,"stream":"btcusdt@depth@100ms","event_type":"depthUpdate","event_time_ms":1788563045051,"raw_json":"{\"stream\":\"btcusdt@depth@100ms\",\"data\":{\"e\":\"depthUpdate\",\"E\":1788563045051,\"T\":1788563045049,\"s\":\"BTCUSDT\",\"ps\":\"BTCUSDT\",\"U\":11478212712147,\"u\":11478212718877,\"pu\":11478212712048,\"b\":[[\"1000.00\",\"24.604\"],[\"29098.10\",\"0.469\"],[\"29498.10\",\"1.631\"],[\"55705.10\",\"0.000\"],[\"63679.00\",\"0.002\"],[\"71638.20\",\"0.002\"],[\"73449.80\",\"0.011\"],[\"75618.20\",\"0.002\"],[\"75618.30\",\"0.002\"],[\"76414.10\",\"0.002\"],[\"78581.80\",\"0.000\"],[\"78586.70\",\"0.005\"],[\"78614.10\",\"0.000\"],[\"78618.80\",\"0.002\"],[\"78802.10\",\"5.211\"],[\"78844.10\",\"2.150\"],[\"79200.10\",\"0.783\"],[\"79401.10\",\"0.734\"],[\"79492.60\",\"0.101\"],[\"79494.60\",\"2.336\"],[\"79496.20\",\"0.060\"],[\"79573.20\",\"0.440\"],[\"79575.30\",\"0.001\"],[\"79583.80\",\"0.004\"]],\"a\":[[\"79598.20\",\"3.208\"],[\"79601.30\",\"0.000\"],[\"79601.60\",\"0.026\"],[\"79601.80\",\"0.027\"],[\"79602.00\",\"0.103\"],[\"79603.10\",\"0.000\"],[\"79604.90\",\"0.434\"],[\"79605.10\",\"0.002\"],[\"79609.50\",\"0.009\"],[\"79610.20\",\"0.010\"],[\"79735.50\",\"0.275\"],[\"79739.40\",\"0.000\"],[\"79739.90\",\"0.125\"],[\"79962.40\",\"1.273\"],[\"79996.20\",\"1.475\"],[\"80362.30\",\"1.905\"],[\"80394.20\",\"6.719\"],[\"80792.20\",\"4.518\"],[\"81190.10\",\"0.011\"]],\"st\":1}}"}
{"receive_ns":1788563045024725000,"stream":"btcusdt@bookTicker","event_type":"bookTicker","event_time_ms":1788563045088,"raw_json":"{\"stream\":\"btcusdt@bookTicker\",\"data\":{\"e\":\"bookTicker\",\"u\":11478212721324,\"s\":\"BTCUSDT\",\"ps\":\"BTCUSDT\",\"b\":\"79598.10\",\"B\":\"10.958\",\"a\":\"79598.20\",\"A\":\"3.208\",\"T\":1788563045087,\"E\":1788563045088,\"st\":1}}"}
{"receive_ns":1788563045024996000,"stream":"btcusdt@bookTicker","event_type":"bookTicker","event_time_ms":1788563045088,"raw_json":"{\"stream\":\"btcusdt@bookTicker\",\"data\":{\"e\":\"bookTicker\",\"u\":11478212721384,\"s\":\"BTCUSDT\",\"ps\":\"BTCUSDT\",\"b\":\"79598.10\",\"B\":\"10.950\",\"a\":\"79598.20\",\"A\":\"3.208\",\"T\":1788563045088,\"E\":1788563045088,\"st\":1}}"}
{"receive_ns":1788563045089188000,"stream":"btcusdt@depth@100ms","event_type":"depthUpdate","event_time_ms":1788563045153,"raw_json":"{\"stream\":\"btcusdt@depth@100ms\",\"data\":{\"e\":\"depthUpdate\",\"E\":1788563045153,\"T\":1788563045152,\"s\":\"BTCUSDT\",\"ps\":\"BTCUSDT\",\"U\":11478212719022,\"u\":11478212725291,\"pu\":11478212718877,\"b\":[[\"1000.00\",\"24.604\"],[\"29098.10\",\"0.315\"],[\"29398.10\",\"0.021\"],[\"29498.10\",\"1.764\"],[\"63679.00\",\"0.002\"],[\"71638.20\",\"0.002\"],[\"75610.60\",\"0.000\"],[\"76414.10\",\"0.000\"],[\"78244.90\",\"7.212\"],[\"78404.10\",\"3.134\"],[\"78483.70\",\"13.998\"],[\"78558.90\",\"15.572\"],[\"78802.10\",\"5.211\"],[\"79200.10\",\"0.782\"],[\"79401.10\",\"0.232\"],[\"79404.00\",\"1.014\"],[\"79485.60\",\"0.201\"],[\"79492.60\",\"1.106\"],[\"79494.60\",\"1.833\"],[\"79578.70\",\"0.210\"],[\"79581.90\",\"0.270\"],[\"79583.80\",\"0.000\"],[\"79598.10\",\"10.950\"]],\"a\":[[\"79601.60\",\"0.026\"],[\"79601.90\",\"0.002\"],[\"79613.20\",\"0.432\"],[\"79614.60\",\"0.001\"],[\"79675.30\",\"0.004\"],[\"79684.90\",\"0.030\"],[\"79685.00\",\"0.003\"],[\"79735.50\",\"0.526\"],[\"79962.40\",\"1.273\"],[\"79996.20\",\"1.475\"],[\"80394.20\",\"6.719\"]],\"st\":1}}"}
{"receive_ns":1788563045157742000,"stream":"btcusdt@bookTicker","event_type":"bookTicker","event_time_ms":1788563045222,"raw_json":"{\"stream\":\"btcusdt@bookTicker\",\"data\":{\"e\":\"bookTicker\",\"u\":11478212729522,\"s\":\"BTCUSDT\",\"ps\":\"BTCUSDT\",\"b\":\"79598.10\",\"B\":\"10.918\",\"a\":\"79598.20\",\"A\":\"3.208\",\"T\":1788563045222,\"E\":1788563045222,\"st\":1}}"}
{"receive_ns":1788563045161552000,"stream":"btcusdt@bookTicker","event_type":"bookTicker","event_time_ms":1788563045225,"raw_json":"{\"stream\":\"btcusdt@bookTicker\",\"data\":{\"e\":\"bookTicker\",\"u\":11478212729706,\"s\":\"BTCUSDT\",\"ps\":\"BTCUSDT\",\"b\":\"79598.10\",\"B\":\"10.962\",\"a\":\"79598.20\",\"A\":\"3.208\",\"T\":1788563045225,\"E\":1788563045225,\"st\":1}}"}
{"receive_ns":1788563045167351000,"stream":"btcusdt@bookTicker","event_type":"bookTicker","event_time_ms":1788563045231,"raw_json":"{\"stream\":\"btcusdt@bookTicker\",\"data\":{\"e\":\"bookTicker\",\"u\":11478212730006,\"s\":\"BTCUSDT\",\"ps\":\"BTCUSDT\",\"b\":\"79598.10\",\"B\":\"10.962\",\"a\":\"79598.20\",\"A\":\"3.203\",\"T\":1788563045231,\"E\":1788563045231,\"st\":1}}"}
{"receive_ns":1788563045167543000,"stream":"btcusdt@trade","event_type":"trade","event_time_ms":1788563045231,"raw_json":"{\"stream\":\"btcusdt@trade\",\"data\":{\"e\":\"trade\",\"E\":1788563045231,\"T\":1788563045231,\"s\":\"BTCUSDT\",\"t\":8054081715,\"p\":\"79598.20\",\"q\":\"0.005\",\"X\":\"MARKET\",\"m\":false,\"st\":1}}"}
{"receive_ns":1788563045167731000,"stream":"btcusdt@bookTicker","event_type":"bookTicker","event_time_ms":1788563045232,"raw_json":"{\"stream\":\"btcusdt@bookTicker\",\"data\":{\"e\":\"bookTicker\",\"u\":11478212730073,\"s\":\"BTCUSDT\",\"ps\":\"BTCUSDT\",\"b\":\"79598.10\",\"B\":\"10.962\",\"a\":\"79598.20\",\"A\":\"3.201\",\"T\":1788563045232,\"E\":1788563045232,\"st\":1}}"}
{"receive_ns":1788563045167983000,"stream":"btcusdt@bookTicker","event_type":"bookTicker","event_time_ms":1788563045232,"raw_json":"{\"stream\":\"btcusdt@bookTicker\",\"data\":{\"e\":\"bookTicker\",\"u\":11478212730137,\"s\":\"BTCUSDT\",\"ps\":\"BTCUSDT\",\"b\":\"79598.10\",\"B\":\"10.970\",\"a\":\"79598.20\",\"A\":\"3.201\",\"T\":1788563045232,\"E\":1788563045232,\"st\":1}}"}
{"receive_ns":1788563045168494000,"stream":"btcusdt@bookTicker","event_type":"bookTicker","event_time_ms":1788563045233,"raw_json":"{\"stream\":\"btcusdt@bookTicker\",\"data\":{\"e\":\"bookTicker\",\"u\":11478212730271,\"s\":\"BTCUSDT\",\"ps\":\"BTCUSDT\",\"b\":\"79598.10\",\"B\":\"10.962\",\"a\":\"79598.20\",\"A\":\"3.201\",\"T\":1788563045233,\"E\":1788563045233,\"st\":1}}"}
{"receive_ns":1788563045177097000,"stream":"btcusdt@bookTicker","event_type":"bookTicker","event_time_ms":1788563045240,"raw_json":"{\"stream\":\"btcusdt@bookTicker\",\"data\":{\"e\":\"bookTicker\",\"u\":11478212730795,\"s\":\"BTCUSDT\",\"ps\":\"BTCUSDT\",\"b\":\"79598.10\",\"B\":\"10.962\",\"a\":\"79598.20\",\"A\":\"3.202\",\"T\":1788563045240,\"E\":1788563045240,\"st\":1}}"}
{"receive_ns":1788563045189377000,"stream":"btcusdt@bookTicker","event_type":"bookTicker","event_time_ms":1788563045252,"raw_json":"{\"stream\":\"btcusdt@bookTicker\",\"data\":{\"e\":\"bookTicker\",\"u\":11478212731503,\"s\":\"BTCUSDT\",\"ps\":\"BTCUSDT\",\"b\":\"79598.10\",\"B\":\"10.962\",\"a\":\"79598.20\",\"A\":\"3.201\",\"T\":1788563045251,\"E\":1788563045252,\"st\":1}}"}
{"receive_ns":1788563045189932000,"stream":"btcusdt@depth@100ms","event_type":"depthUpdate","event_time_ms":1788563045255,"raw_json":"{\"stream\":\"btcusdt@depth@100ms\",\"data\":{\"e\":\"depthUpdate\",\"E\":1788563045255,\"T\":1788563045253,\"s\":\"BTCUSDT\",\"ps\":\"BTCUSDT\",\"U\":11478212725402,\"u\":11478212731652,\"pu\":11478212725291,\"b\":[[\"29098.10\",\"0.189\"],[\"29398.10\",\"0.077\"],[\"29498.10\",\"1.834\"],[\"71638.20\",\"0.002\"],[\"73614.50\",\"0.010\"],[\"76414.10\",\"0.002\"],[\"78006.20\",\"0.015\"],[\"78802.10\",\"5.213\"],[\"78841.90\",\"4.346\"],[\"79195.60\",\"3.150\"],[\"79401.10\",\"0.232\"],[\"79492.60\",\"1.006\"],[\"79494.60\",\"0.502\"],[\"79496.60\",\"1.431\"],[\"79563.10\",\"0.004\"],[\"79565.40\",\"10.930\"],[\"79572.40\",\"0.254\"],[\"79572.50\",\"0.342\"],[\"79573.20\",\"0.001\"],[\"79573.80\",\"0.383\"],[\"79574.90\",\"0.439\"],[\"79598.10\",\"10.962\"]],\"a\":[[\"79598.20\",\"3.201\"],[\"79601.00\",\"0.034\"],[\"79601.60\",\"0.000\"],[\"79601.80\",\"0.027\"],[\"79602.00\",\"0.103\"],[\"79602.90\",\"0.027\"],[\"79604.10\",\"0.329\"],[\"79606.40\",\"0.080\"],[\"79606.70\",\"0.002\"],[\"79609.50\",\"0.017\"],[\"79609.60\",\"0.258\"],[\"79610.20\",\"0.002\"],[\"79611.20\",\"0.665\"],[\"79613.20\",\"0.060\"],[\"79614.60\",\"0.373\"],[\"79624.60\",\"0.030\"],[\"79627.10\",\"0.000\"],[\"79628.30\",\"0.000\"],[\"79629.20\",\"0.066\"],[\"79653.70\",\"0.005\"],[\"79698.90\",\"0.005\"],[\"79735.50\",\"0.526\"],[\"79736.40\",\"0.211\"],[\"79821.00\",\"0.088\"],[\"79821.10\",\"0.003\"],[\"79962.40\",\"1.273\"],[\"79996.20\",\"1.476\"],[\"80394.20\",\"6.719\"],[\"80514.40\",\"0.744\"]],\"st\":1}}"}
{"receive_ns":1788563045195598000,"stream":"btcusdt@bookTicker","event_type":"bookTicker","event_time_ms":1788563045261,"raw_json":"{\"stream\":\"btcusdt@bookTicker\",\"data\":{\"e\":\"bookTicker\",\"u\":11478212732063,\"s\":\"BTCUSDT\",\"ps\":\"BTCUSDT\",\"b\":\"79598.10\",\"B\":\"10.962\",\"a\":\"79598.20\",\"A\":\"3.203\",\"T\":1788563045260,\"E\":1788563045261,\"st\":1}}"}
{"receive_ns":1788563045208879000,"stream":"btcusdt@bookTicker","event_type":"bookTicker","event_time_ms":1788563045273,"raw_json":"{\"stream\":\"btcusdt@bookTicker\",\"data\":{\"e\":\"bookTicker\",\"u\":11478212732792,\"s\":\"BTCUSDT\",\"ps\":\"BTCUSDT\",\"b\":\"79598.10\",\"B\":\"10.962\",\"a\":\"79598.20\",\"A\":\"3.201\",\"T\":1788563045273,\"E\":1788563045273,\"st\":1}}"}
{"receive_ns":1788563045209082000,"stream":"btcusdt@trade","event_type":"trade","event_time_ms":1788563045273,"raw_json":"{\"stream\":\"btcusdt@trade\",\"data\":{\"e\":\"trade\",\"E\":1788563045273,\"T\":1788563045273,\"s\":\"BTCUSDT\",\"t\":8054081716,\"p\":\"79598.20\",\"q\":\"0.002\",\"X\":\"MARKET\",\"m\":false,\"st\":1}}"}
{"receive_ns":1788563045209562000,"stream":"btcusdt@bookTicker","event_type":"bookTicker","event_time_ms":1788563045274,"raw_json":"{\"stream\":\"btcusdt@bookTicker\",\"data\":{\"e\":\"bookTicker\",\"u\":11478212732927,\"s\":\"BTCUSDT\",\"ps\":\"BTCUSDT\",\"b\":\"79598.10\",\"B\":\"10.970\",\"a\":\"79598.20\",\"A\":\"3.201\",\"T\":1788563045274,\"E\":1788563045274,\"st\":1}}"}
{"receive_ns":1788563045209795000,"stream":"btcusdt@bookTicker","event_type":"bookTicker","event_time_ms":1788563045275,"raw_json":"{\"stream\":\"btcusdt@bookTicker\",\"data\":{\"e\":\"bookTicker\",\"u\":11478212733031,\"s\":\"BTCUSDT\",\"ps\":\"BTCUSDT\",\"b\":\"79598.10\",\"B\":\"10.962\",\"a\":\"79598.20\",\"A\":\"3.201\",\"T\":1788563045275,\"E\":1788563045275,\"st\":1}}"}
{"receive_ns":1788563045255955000,"stream":"btcusdt@bookTicker","event_type":"bookTicker","event_time_ms":1788563045317,"raw_json":"{\"stream\":\"btcusdt@bookTicker\",\"data\":{\"e\":\"bookTicker\",\"u\":11478212735143,\"s\":\"BTCUSDT\",\"ps\":\"BTCUSDT\",\"b\":\"79598.10\",\"B\":\"10.917\",\"a\":\"79598.20\",\"A\":\"3.201\",\"T\":1788563045316,\"E\":1788563045317,\"st\":1}}"}
{"receive_ns":1788563045257113000,"stream":"btcusdt@bookTicker","event_type":"bookTicker","event_time_ms":1788563045321,"raw_json":"{\"stream\":\"btcusdt@bookTicker\",\"data\":{\"e\":\"bookTicker\",\"u\":11478212735405,\"s\":\"BTCUSDT\",\"ps\":\"BTCUSDT\",\"b\":\"79598.10\",\"B\":\"10.959\",\"a\":\"79598.20\",\"A\":\"3.201\",\"T\":1788563045321,\"E\":1788563045321,\"st\":1}}"}
{"receive_ns":1788563045293258000,"stream":"btcusdt@depth@100ms","event_type":"depthUpdate","event_time_ms":1788563045357,"raw_json":"{\"stream\":\"btcusdt@depth@100ms\",\"data\":{\"e\":\"depthUpdate\",\"E\":1788563045357,\"T\":1788563045354,\"s\":\"BTCUSDT\",\"ps\":\"BTCUSDT\",\"U\":11478212731736,\"u\":11478212738085,\"pu\":11478212731652,\"b\":[[\"1000.00\",\"24.804\"],[\"29098.10\",\"0.077\"],[\"29398.10\",\"0.140\"],[\"29498.10\",\"1.883\"],[\"71638.20\",\"0.002\"],[\"75618.20\",\"0.004\"],[\"78483.70\",\"14.252\"],[\"78499.00\",\"0.502\"],[\"78732.70\",\"1.334\"],[\"78797.70\",\"14.872\"],[\"78802.10\",\"5.211\"],[\"79200.10\",\"0.631\"],[\"79405.60\",\"0.001\"],[\"79440.40\",\"0.000\"],[\"79492.60\",\"0.001\"],[\"79564.30\",\"0.298\"],[\"79565.40\",\"10.884\"],[\"79573.20\",\"0.440\"],[\"79574.90\",\"0.000\"],[\"79598.10\",\"10.959\"]],\"a\":[[\"79598.20\",\"3.201\"],[\"79601.00\",\"0.008\"],[\"79601.70\",\"0.001\"],[\"79601.80\",\"0.001\"],[\"79602.00\",\"0.077\"],[\"79602.10\",\"0.002\"],[\"79602.20\",\"0.003\"],[\"79603.10\",\"0.026\"],[\"79603.20\",\"0.030\"],[\"79603.30\",\"0.026\"],[\"79603.80\",\"0.000\"],[\"79604.10\",\"0.330\"],[\"79609.50\",\"0.009\"],[\"79610.20\",\"0.010\"],[\"79613.20\",\"0.432\"],[\"79614.60\",\"0.001\"],[\"79735.50\",\"0.275\"],[\"79996.20\",\"0.950\"],[\"80389.60\",\"10.594\"],[\"80394.20\",\"6.719\"]],\"st\":1}}"}
{"receive_ns":1788563045328565000,"stream":"btcusdt@bookTicker","event_type":"bookTicker","event_time_ms":1788563045392,"raw_json":"{\"stream\":\"btcusdt@bookTicker\",\"data\":{\"e\":\"bookTicker\",\"u\":11478212743186,\"s\":\"BTCUSDT\",\"ps\":\"BTCUSDT\",\"b\":\"79598.10\",\"B\":\"10.967\",\"a\":\"79598.20\",\"A\":\"3.201\",\"T\":1788563045392,\"E\":1788563045392,\"st\":1}}"}
{"receive_ns":1788563045328825000,"stream":"btcusdt@bookTicker","event_type":"bookTicker","event_time_ms":1788563045393,"raw_json":"{\"stream\":\"btcusdt@bookTicker\",\"data\":{\"e\":\"bookTicker\",\"u\":11478212743382,\"s\":\"BTCUSDT\",\"ps\":\"BTCUSDT\",\"b\":\"79598.10\",\"B\":\"10.959\",\"a\":\"79598.20\",\"A\":\"3.201\",\"T\":1788563045393,\"E\":1788563045393,\"st\":1}}"}
{"receive_ns":1788563045387371000,"stream":"btcusdt@bookTicker","event_type":"bookTicker","event_time_ms":1788563045451,"raw_json":"{\"stream\":\"btcusdt@bookTicker\",\"data\":{\"e\":\"bookTicker\",\"u\":11478212748278,\"s\":\"BTCUSDT\",\"ps\":\"BTCUSDT\",\"b\":\"79598.10\",\"B\":\"10.959\",\"a\":\"79598.20\",\"A\":\"3.200\",\"T\":1788563045451,\"E\":1788563045451,\"st\":1}}"}
{"receive_ns":1788563045395955000,"stream":"btcusdt@bookTicker","event_type":"bookTicker","event_time_ms":1788563045458,"raw_json":"{\"stream\":\"btcusdt@bookTicker\",\"data\":{\"e\":\"bookTicker\",\"u\":11478212748855,\"s\":\"BTCUSDT\",\"ps\":\"BTCUSDT\",\"b\":\"79598.10\",\"B\":\"10.959\",\"a\":\"79598.20\",\"A\":\"3.203\",\"T\":1788563045458,\"E\":1788563045458,\"st\":1}}"}
{"receive_ns":1788563045396578000,"stream":"btcusdt@depth@100ms","event_type":"depthUpdate","event_time_ms":1788563045459,"raw_json":"{\"stream\":\"btcusdt@depth@100ms\",\"data\":{\"e\":\"depthUpdate\",\"E\":1788563045459,\"T\":1788563045458,\"s\":\"BTCUSDT\",\"ps\":\"BTCUSDT\",\"U\":11478212738710,\"u\":11478212748855,\"pu\":11478212738085,\"b\":[[\"1000.00\",\"24.804\"],[\"29098.10\",\"0.000\"],[\"29398.10\",\"0.245\"],[\"29498.10\",\"1.855\"],[\"71638.20\",\"0.002\"],[\"73779.20\",\"0.010\"],[\"76414.10\",\"0.000\"],[\"78801.50\",\"2.798\"],[\"78802.10\",\"5.211\"],[\"79200.10\",\"0.772\"],[\"79401.10\",\"0.000\"],[\"79485.60\",\"0.201\"],[\"79492.60\",\"1.006\"],[\"79494.60\",\"0.502\"],[\"79496.60\",\"0.000\"],[\"79534.30\",\"0.210\"],[\"79538.20\",\"0.002\"],[\"79548.10\",\"0.001\"],[\"79565.10\",\"0.001\"],[\"79566.00\",\"0.453\"],[\"79578.70\",\"0.000\"],[\"79581.90\",\"0.000\"],[\"79585.10\",\"0.062\"],[\"79585.40\",\"0.004\"],[\"79597.70\",\"0.076\"],[\"79598.10\",\"10.959\"]],\"a\":[[\"79598.20\",\"3.203\"],[\"79600.80\",\"0.001\"],[\"79602.40\",\"0.001\"],[\"79602.80\",\"0.000\"],[\"79602.90\",\"0.001\"],[\"79603.10\",\"0.000\"],[\"79603.20\",\"0.004\"],[\"79603.30\",\"0.000\"],[\"79603.40\",\"0.002\"],[\"79603.60\",\"0.001\"],[\"79603.70\",\"0.003\"],[\"79603.90\",\"0.050\"],[\"79604.00\",\"2.874\"],[\"79604.10\",\"0.330\"],[\"79604.20\",\"1.025\"],[\"79604.30\",\"0.031\"],[\"79604.50\",\"0.033\"],[\"79604.60\",\"0.029\"],[\"79604.70\",\"0.026\"],[\"79604.80\",\"0.029\"],[\"79604.90\",\"0.460\"],[\"79605.00\",\"0.055\"],[\"79606.40\",\"0.078\"],[\"79606.70\",\"0.004\"],[\"79609.50\",\"0.009\"],[\"79610.20\",\"0.002\"],[\"79610.90\",\"0.740\"],[\"79611.00\",\"0.691\"],[\"79611.20\",\"1.044\"],[\"79611.30\",\"0.435\"],[\"79615.70\",\"0.454\"],[\"79616.90\",\"0.004\"],[\"79645.40\",\"2.867\"],[\"79645.50\",\"10.001\"],[\"79653.70\",\"0.007\"],[\"79668.60\",\"0.603\"],[\"79676.70\",\"0.077\"],[\"79733.90\",\"0.188\"],[\"79735.50\",\"0.275\"],[\"79736.40\",\"0.011\"],[\"79961.60\",\"0.248\"],[\"79962.40\",\"0.419\"],[\"79963.20\",\"0.211\"],[\"79996.20\",\"1.276\"],[\"80394.20\",\"6.719\"],[\"80672.80\",\"2.968\"],[\"80720.50\",\"0.647\"],[\"87558.10\",\"0.000\"]],\"st\":1}}"}
{"receive_ns":1788563045425158000,"stream":"btcusdt@bookTicker","event_type":"bookTicker","event_time_ms":1788563045488,"raw_json":"{\"stream\":\"btcusdt@bookTicker\",\"data\":{\"e\":\"bookTicker\",\"u\":11478212750725,\"s\":\"BTCUSDT\",\"ps\":\"BTCUSDT\",\"b\":\"79598.10\",\"B\":\"10.959\",\"a\":\"79598.20\",\"A\":\"3.205\",\"T\":1788563045488,\"E\":1788563045488,\"st\":1}}"}
{"receive_ns":1788563045451399000,"stream":"btcusdt@bookTicker","event_type":"bookTicker","event_time_ms":1788563045515,"raw_json":"{\"stream\":\"btcusdt@bookTicker\",\"data\":{\"e\":\"bookTicker\",\"u\":11478212752732,\"s\":\"BTCUSDT\",\"ps\":\"BTCUSDT\",\"b\":\"79598.10\",\"B\":\"10.959\",\"a\":\"79598.20\",\"A\":\"3.180\",\"T\":1788563045515,\"E\":1788563045515,\"st\":1}}"}
{"receive_ns":1788563045451626000,"stream":"btcusdt@trade","event_type":"trade","event_time_ms":1788563045515,"raw_json":"{\"stream\":\"btcusdt@trade\",\"data\":{\"e\":\"trade\",\"E\":1788563045515,\"T\":1788563045515,\"s\":\"BTCUSDT\",\"t\":8054081717,\"p\":\"79598.20\",\"q\":\"0.025\",\"X\":\"MARKET\",\"m\":false,\"st\":1}}"}
{"receive_ns":1788563045451853000,"stream":"btcusdt@bookTicker","event_type":"bookTicker","event_time_ms":1788563045516,"raw_json":"{\"stream\":\"btcusdt@bookTicker\",\"data\":{\"e\":\"bookTicker\",\"u\":11478212752904,\"s\":\"BTCUSDT\",\"ps\":\"BTCUSDT\",\"b\":\"79598.10\",\"B\":\"10.967\",\"a\":\"79598.20\",\"A\":\"3.180\",\"T\":1788563045516,\"E\":1788563045516,\"st\":1}}"}
{"receive_ns":1788563045452727000,"stream":"btcusdt@bookTicker","event_type":"bookTicker","event_time_ms":1788563045517,"raw_json":"{\"stream\":\"btcusdt@bookTicker\",\"data\":{\"e\":\"bookTicker\",\"u\":11478212753064,\"s\":\"BTCUSDT\",\"ps\":\"BTCUSDT\",\"b\":\"79598.10\",\"B\":\"10.959\",\"a\":\"79598.20\",\"A\":\"3.180\",\"T\":1788563045517,\"E\":1788563045517,\"st\":1}}"}
{"receive_ns":1788563045455754000,"stream":"btcusdt@bookTicker","event_type":"bookTicker","event_time_ms":1788563045520,"raw_json":"{\"stream\":\"btcusdt@bookTicker\",\"data\":{\"e\":\"bookTicker\",\"u\":11478212753552,\"s\":\"BTCUSDT\",\"ps\":\"BTCUSDT\",\"b\":\"79598.10\",\"B\":\"10.963\",\"a\":\"79598.20\",\"A\":\"3.180\",\"T\":1788563045520,\"E\":1788563045520,\"st\":1}}"}
{"receive_ns":1788563045456114000,"stream":"btcusdt@bookTicker","event_type":"bookTicker","event_time_ms":1788563045522,"raw_json":"{\"stream\":\"btcusdt@bookTicker\",\"data\":{\"e\":\"bookTicker\",\"u\":11478212753734,\"s\":\"BTCUSDT\",\"ps\":\"BTCUSDT\",\"b\":\"79598.10\",\"B\":\"10.926\",\"a\":\"79598.20\",\"A\":\"3.180\",\"T\":1788563045521,\"E\":1788563045522,\"st\":1}}"}
{"receive_ns":1788563045460433000,"stream":"btcusdt@bookTicker","event_type":"bookTicker","event_time_ms":1788563045524,"raw_json":"{\"stream\":\"btcusdt@bookTicker\",\"data\":{\"e\":\"bookTicker\",\"u\":11478212754125,\"s\":\"BTCUSDT\",\"ps\":\"BTCUSDT\",\"b\":\"79598.10\",\"B\":\"10.964\",\"a\":\"79598.20\",\"A\":\"3.180\",\"T\":1788563045524,\"E\":1788563045524,\"st\":1}}"}
{"receive_ns":1788563045498172000,"stream":"btcusdt@depth@100ms","event_type":"depthUpdate","event_time_ms":1788563045561,"raw_json":"{\"stream\":\"btcusdt@depth@100ms\",\"data\":{\"e\":\"depthUpdate\",\"E\":1788563045561,\"T\":1788563045560,\"s\":\"BTCUSDT\",\"ps\":\"BTCUSDT\",\"U\":11478212748917,\"u\":11478212757318,\"pu\":11478212748855,\"b\":[[\"29398.10\",\"0.420\"],[\"29498.10\",\"1.680\"],[\"71638.20\",\"0.002\"],[\"76414.10\",\"0.002\"],[\"77345.20\",\"0.000\"],[\"78149.40\",\"0.639\"],[\"78730.50\",\"1.203\"],[\"78802.10\",\"5.211\"],[\"79200.10\",\"0.898\"],[\"79401.10\",\"0.232\"],[\"79462.90\",\"0.000\"],[\"79463.00\",\"0.004\"],[\"79493.00\",\"0.034\"],[\"79494.60\",\"1.933\"],[\"79558.30\",\"0.080\"],[\"79563.20\",\"0.010\"],[\"79564.30\",\"0.252\"],[\"79565.10\",\"0.001\"],[\"79565.60\",\"0.048\"],[\"79565.90\",\"0.032\"],[\"79566.00\",\"0.001\"],[\"79566.40\",\"0.009\"],[\"79567.00\",\"0.454\"],[\"79572.10\",\"0.079\"],[\"79572.50\",\"0.342\"],[\"79573.20\",\"0.001\"],[\"79573.80\",\"0.010\"],[\"79574.80\",\"0.828\"],[\"79575.30\",\"0.440\"],[\"79598.10\",\"10.964\"]],\"a\":[[\"79598.20\",\"3.180\"],[\"79603.10\",\"0.026\"],[\"79603.90\",\"0.076\"],[\"79604.10\",\"0.356\"],[\"79604.20\",\"1.025\"],[\"79604.30\",\"0.031\"],[\"79604.50\",\"0.007\"],[\"79605.20\",\"0.077\"],[\"79605.30\",\"0.000\"],[\"79609.50\",\"0.017\"],[\"79609.60\",\"0.258\"],[\"79610.20\",\"0.002\"],[\"79611.20\",\"0.605\"],[\"79611.40\",\"0.859\"],[\"79613.20\",\"0.060\"],[\"79614.70\",\"0.373\"],[\"79615.70\",\"0.002\"],[\"79617.00\",\"0.457\"],[\"79627.10\",\"0.000\"],[\"79628.30\",\"0.000\"],[\"79629.20\",\"0.020\"],[\"79629.30\",\"0.068\"],[\"79645.40\",\"0.008\"],[\"79645.50\",\"0.000\"],[\"79645.60\",\"0.127\"],[\"79650.00\",\"10.195\"],[\"79650.10\",\"0.003\"],[\"79669.90\",\"0.002\"],[\"79735.50\",\"0.526\"],[\"79962.40\",\"1.273\"],[\"79996.20\",\"1.476\"],[\"80394.20\",\"6.719\"],[\"80394.80\",\"1.864\"],[\"80573.10\",\"0.005\"],[\"80603.90\",\"0.396\"]],\"st\":1}}"}
{"receive_ns":1788563045597270000,"stream":"btcusdt@depth@100ms","event_type":"depthUpdate","event_time_ms":1788563045663,"raw_json":"{\"stream\":\"btcusdt@depth@100ms\",\"data\":{\"e\":\"depthUpdate\",\"E\":1788563045663,\"T\":1788563045662,\"s\":\"BTCUSDT\",\"ps\":\"BTCUSDT\",\"U\":11478212757385,\"u\":11478212764059,\"pu\":11478212757318,\"b\":[[\"1000.00\",\"24.804\"],[\"29398.10\",\"0.602\"],[\"29498.10\",\"1.498\"],[\"63679.00\",\"0.002\"],[\"71638.20\",\"0.002\"],[\"71675.00\",\"0.002\"],[\"73943.90\",\"0.011\"],[\"75610.20\",\"0.000\"],[\"76414.10\",\"0.000\"],[\"78802.10\",\"5.211\"],[\"78880.60\",\"0.886\"],[\"79200.10\",\"0.908\"],[\"79485.60\",\"0.000\"],[\"79492.60\",\"1.006\"],[\"79493.00\",\"0.022\"],[\"79494.60\",\"1.933\"],[\"79495.50\",\"0.215\"],[\"79541.60\",\"0.456\"],[\"79564.20\",\"0.733\"],[\"79565.60\",\"0.002\"],[\"79573.20\",\"0.440\"],[\"79573.30\",\"0.373\"],[\"79574.80\",\"0.455\"],[\"79575.30\",\"0.001\"]],\"a\":[[\"79601.90\",\"0.000\"],[\"79602.90\",\"0.001\"],[\"79603.10\",\"0.000\"],[\"79603.60\",\"0.027\"],[\"79605.00\",\"0.029\"],[\"79609.50\",\"0.009\"],[\"79610.20\",\"0.006\"],[\"79610.90\",\"0.744\"],[\"79611.20\",\"0.601\"],[\"79735.50\",\"0.526\"],[\"79736.40\",\"0.211\"],[\"79962.40\",\"1.273\"],[\"79963.20\",\"0.011\"],[\"79996.20\",\"1.476\"],[\"80394.20\",\"6.719\"],[\"80647.50\",\"0.000\"],[\"80688.70\",\"0.494\"]],\"st\":1}}"}
{"receive_ns":1788563045612041000,"stream":"btcusdt@bookTicker","event_type":"bookTicker","event_time_ms":1788563045675,"raw_json":"{\"stream\":\"btcusdt@bookTicker\",\"data\":{\"e\":\"bookTicker\",\"u\":11478212764813,\"s\":\"BTCUSDT\",\"ps\":\"BTCUSDT\",\"b\":\"79598.10\",\"B\":\"10.964\",\"a\":\"79598.20\",\"A\":\"3.177\",\"T\":1788563045675,\"E\":1788563045675,\"st\":1}}"}
{"receive_ns":1788563045621377000,"stream":"btcusdt@bookTicker","event_type":"bookTicker","event_time_ms":1788563045684,"raw_json":"{\"stream\":\"btcusdt@bookTicker\",\"data\":{\"e\":\"bookTicker\",\"u\":11478212765364,\"s\":\"BTCUSDT\",\"ps\":\"BTCUSDT\",\"b\":\"79598.10\",\"B\":\"10.964\",\"a\":\"79598.20\",\"A\":\"3.178\",\"T\":1788563045684,\"E\":1788563045684,\"st\":1}}"}
{"receive_ns":1788563045686067000,"stream":"btcusdt@bookTicker","event_type":"bookTicker","event_time_ms":1788563045750,"raw_json":"{\"stream\":\"btcusdt@bookTicker\",\"data\":{\"e\":\"bookTicker\",\"u\":11478212768842,\"s\":\"BTCUSDT\",\"ps\":\"BTCUSDT\",\"b\":\"79598.10\",\"B\":\"10.964\",\"a\":\"79598.20\",\"A\":\"3.176\",\"T\":1788563045750,\"E\":1788563045750,\"st\":1}}"}
{"receive_ns":1788563045701034000,"stream":"btcusdt@depth@100ms","event_type":"depthUpdate","event_time_ms":1788563045765,"raw_json":"{\"stream\":\"btcusdt@depth@100ms\",\"data\":{\"e\":\"depthUpdate\",\"E\":1788563045765,\"T\":1788563045762,\"s\":\"BTCUSDT\",\"ps\":\"BTCUSDT\",\"U\":11478212764079,\"u\":11478212769418,\"pu\":11478212764059,\"b\":[[\"1000.00\",\"24.804\"],[\"29398.10\",\"0.777\"],[\"29498.10\",\"1.323\"],[\"63678.50\",\"0.000\"],[\"71638.20\",\"0.002\"],[\"76414.10\",\"0.002\"],[\"78006.20\",\"0.018\"],[\"78638.50\",\"29.719\"],[\"78802.10\",\"5.211\"],[\"79200.10\",\"0.907\"],[\"79401.10\",\"0.232\"],[\"79458.00\",\"0.006\"],[\"79494.60\",\"1.933\"],[\"79574.40\",\"0.056\"]],\"a\":[[\"79598.20\",\"3.176\"],[\"79609.50\",\"0.009\"],[\"79610.20\",\"0.010\"],[\"79614.30\",\"0.361\"],[\"79735.50\",\"0.526\"],[\"79739.90\",\"0.000\"],[\"79961.60\",\"0.002\"],[\"79962.40\",\"1.273\"],[\"79996.20\",\"1.477\"],[\"80394.20\",\"6.719\"],[\"80794.30\",\"1.491\"]],\"st\":1}}"}
{"receive_ns":1788563045744713000,"stream":"btcusdt@bookTicker","event_type":"bookTicker","event_time_ms":1788563045809,"raw_json":"{\"stream\":\"btcusdt@bookTicker\",\"data\":{\"e\":\"bookTicker\",\"u\":11478212771517,\"s\":\"BTCUSDT\",\"ps\":\"BTCUSDT\",\"b\":\"79598.10\",\"B\":\"10.964\",\"a\":\"79598.20\",\"A\":\"3.177\",\"T\":1788563045808,\"E\":1788563045809,\"st\":1}}"}
{"receive_ns":1788563045744966000,"stream":"btcusdt@bookTicker","event_type":"bookTicker","event_time_ms":1788563045809,"raw_json":"{\"stream\":\"btcusdt@bookTicker\",\"data\":{\"e\":\"bookTicker\",\"u\":11478212771560,\"s\":\"BTCUSDT\",\"ps\":\"BTCUSDT\",\"b\":\"79598.10\",\"B\":\"10.932\",\"a\":\"79598.20\",\"A\":\"3.177\",\"T\":1788563045809,\"E\":1788563045809,\"st\":1}}"}
{"receive_ns":1788563045748124000,"stream":"btcusdt@bookTicker","event_type":"bookTicker","event_time_ms":1788563045813,"raw_json":"{\"stream\":\"btcusdt@bookTicker\",\"data\":{\"e\":\"bookTicker\",\"u\":11478212771947,\"s\":\"BTCUSDT\",\"ps\":\"BTCUSDT\",\"b\":\"79598.10\",\"B\":\"10.965\",\"a\":\"79598.20\",\"A\":\"3.177\",\"T\":1788563045812,\"E\":1788563045813,\"st\":1}}"}
{"receive_ns":1788563045803044000,"stream":"btcusdt@depth@100ms","event_type":"depthUpdate","event_time_ms":1788563045867,"raw_json":"{\"stream\":\"btcusdt@depth@100ms\",\"data\":{\"e\":\"depthUpdate\",\"E\":1788563045867,\"T\":1788563045866,\"s\":\"BTCUSDT\",\"ps\":\"BTCUSDT\",\"U\":11478212769570,\"u\":11478212775040,\"pu\":11478212769418,\"b\":[[\"1000.00\",\"25.004\"],[\"29398.10\",\"0.959\"],[\"29498.10\",\"1.141\"],[\"63679.00\",\"0.002\"],[\"71638.20\",\"0.002\"],[\"74108.60\",\"0.010\"],[\"78802.10\",\"5.211\"],[\"78996.60\",\"1.896\"],[\"79200.10\",\"0.907\"],[\"79423.50\",\"11.695\"],[\"79466.80\",\"0.000\"],[\"79492.60\",\"0.001\"],[\"79494.60\",\"1.431\"],[\"79495.50\",\"0.014\"],[\"79496.60\",\"1.005\"],[\"79500.50\",\"0.021\"],[\"79563.30\",\"0.047\"],[\"79564.20\",\"0.687\"],[\"79565.10\",\"0.453\"],[\"79567.00\",\"0.002\"],[\"79572.10\",\"0.518\"],[\"79572.50\",\"0.715\"],[\"79573.20\",\"0.001\"],[\"79573.30\",\"0.000\"],[\"79584.30\",\"0.019\"],[\"79584.50\",\"0.032\"],[\"79598.10\",\"10.965\"]],\"a\":[[\"79598.20\",\"3.177\"],[\"79602.20\",\"0.029\"],[\"79603.10\",\"0.026\"],[\"79603.50\",\"0.028\"],[\"79603.60\",\"0.001\"],[\"79603.70\",\"0.029\"],[\"79603.90\",\"0.050\"],[\"79604.90\",\"0.434\"],[\"79605.00\",\"0.029\"],[\"79609.50\",\"0.017\"],[\"79609.60\",\"0.258\"],[\"79610.20\",\"0.441\"],[\"79610.90\",\"0.744\"],[\"79611.20\",\"0.601\"],[\"79611.40\",\"0.420\"],[\"79612.40\",\"0.000\"],[\"79613.50\",\"1.617\"],[\"79614.70\",\"0.001\"],[\"79627.10\",\"0.000\"],[\"79628.30\",\"0.046\"],[\"79629.30\",\"0.022\"],[\"79735.50\",\"0.526\"],[\"79736.40\",\"0.011\"],[\"79739.40\",\"0.125\"],[\"79962.40\",\"0.854\"],[\"79996.20\",\"1.477\"],[\"80190.70\",\"1.869\"],[\"80394.20\",\"6.719\"],[\"80593.20\",\"1.383\"],[\"80603.90\",\"0.148\"],[\"83557.80\",\"0.004\"]],\"st\":1}}"}
{"receive_ns":1788563045832450000,"stream":"btcusdt@bookTicker","event_type":"bookTicker","event_time_ms":1788563045889,"raw_json":"{\"stream\":\"btcusdt@bookTicker\",\"data\":{\"e\":\"bookTicker\",\"u\":11478212776331,\"s\":\"BTCUSDT\",\"ps\":\"BTCUSDT\",\"b\":\"79598.10\",\"B\":\"10.965\",\"a\":\"79598.20\",\"A\":\"3.176\",\"T\":1788563045888,\"E\":1788563045889,\"st\":1}}"}
{"receive_ns":1788563045832680000,"stream":"btcusdt@bookTicker","event_type":"bookTicker","event_time_ms":1788563045896,"raw_json":"{\"stream\":\"btcusdt@bookTicker\",\"data\":{\"e\":\"bookTicker\",\"u\":11478212776732,\"s\":\"BTCUSDT\",\"ps\":\"BTCUSDT\",\"b\":\"79598.10\",\"B\":\"10.965\",\"a\":\"79598.20\",\"A\":\"3.179\",\"T\":1788563045896,\"E\":1788563045896,\"st\":1}}"}
{"receive_ns":1788563045905536000,"stream":"btcusdt@depth@100ms","event_type":"depthUpdate","event_time_ms":1788563045969,"raw_json":"{\"stream\":\"btcusdt@depth@100ms\",\"data\":{\"e\":\"depthUpdate\",\"E\":1788563045969,\"T\":1788563045965,\"s\":\"BTCUSDT\",\"ps\":\"BTCUSDT\",\"U\":11478212775076,\"u\":11478212780626,\"pu\":11478212775040,\"b\":[[\"1000.00\",\"25.004\"],[\"29398.10\",\"1.134\"],[\"29498.10\",\"0.966\"],[\"71638.20\",\"0.002\"],[\"76414.10\",\"0.000\"],[\"78598.90\",\"0.002\"],[\"78797.70\",\"13.605\"],[\"78802.10\",\"5.211\"],[\"79051.30\",\"0.001\"],[\"79200.10\",\"0.897\"],[\"79226.10\",\"0.005\"],[\"79227.80\",\"0.974\"],[\"79345.50\",\"0.503\"],[\"79345.60\",\"4.032\"],[\"79401.10\",\"0.000\"],[\"79485.60\",\"0.201\"],[\"79492.60\",\"0.503\"],[\"79493.00\",\"0.075\"],[\"79494.60\",\"0.000\"],[\"79526.40\",\"0.003\"],[\"79542.30\",\"0.000\"],[\"79558.30\",\"0.078\"],[\"79563.30\",\"0.001\"],[\"79564.30\",\"0.298\"],[\"79565.60\",\"0.002\"],[\"79572.10\",\"0.079\"],[\"79572.50\",\"0.342\"],[\"79573.20\",\"0.440\"],[\"79573.50\",\"0.373\"],[\"79574.40\",\"0.050\"],[\"79574.80\",\"0.455\"],[\"79575.30\",\"0.001\"],[\"79576.10\",\"0.009\"]],\"a\":[[\"79598.20\",\"3.179\"],[\"79600.50\",\"0.562\"],[\"79609.50\",\"0.017\"],[\"79610.20\",\"0.002\"],[\"79611.40\",\"0.859\"],[\"79613.50\",\"1.245\"],[\"79614.70\",\"0.373\"],[\"79628.30\",\"0.000\"],[\"79629.40\",\"0.826\"],[\"79638.00\",\"0.006\"],[\"79669.90\",\"0.000\"],[\"79696.80\",\"0.000\"],[\"79735.50\",\"0.275\"],[\"79739.10\",\"0.002\"],[\"79739.40\",\"0.000\"],[\"79739.60\",\"0.001\"],[\"79845.50\",\"0.877\"],[\"79847.10\",\"0.000\"],[\"79962.40\",\"0.000\"],[\"79964.30\",\"0.828\"],[\"79967.20\",\"0.000\"],[\"79967.30\",\"0.000\"],[\"79986.20\",\"0.421\"],[\"79995.10\",\"0.200\"],[\"79996.20\",\"1.277\"],[\"79999.90\",\"10.724\"],[\"80099.90\",\"10.442\"],[\"80143.70\",\"0.000\"],[\"80394.20\",\"6.719\"],[\"80727.10\",\"0.866\"],[\"81190.10\",\"0.014\"]],\"st\":1}}"}
{"receive_ns":1788563045978730000,"stream":"btcusdt@bookTicker","event_type":"bookTicker","event_time_ms":1788563046043,"raw_json":"{\"stream\":\"btcusdt@bookTicker\",\"data\":{\"e\":\"bookTicker\",\"u\":11478212786964,\"s\":\"BTCUSDT\",\"ps\":\"BTCUSDT\",\"b\":\"79598.10\",\"B\":\"11.001\",\"a\":\"79598.20\",\"A\":\"3.179\",\"T\":1788563046043,\"E\":1788563046043,\"st\":1}}"}
{"receive_ns":1788563045979205000,"stream":"btcusdt@bookTicker","event_type":"bookTicker","event_time_ms":1788563046044,"raw_json":"{\"stream\":\"btcusdt@bookTicker\",\"data\":{\"e\":\"bookTicker\",\"u\":11478212787024,\"s\":\"BTCUSDT\",\"ps\":\"BTCUSDT\",\"b\":\"79598.10\",\"B\":\"10.999\",\"a\":\"79598.20\",\"A\":\"3.179\",\"T\":1788563046044,\"E\":1788563046044,\"st\":1}}"}
{"receive_ns":1788563046029091000,"stream":"btcusdt@depth@100ms","event_type":"depthUpdate","event_time_ms":1788563046071,"raw_json":"{\"stream\":\"btcusdt@depth@100ms\",\"data\":{\"e\":\"depthUpdate\",\"E\":1788563046071,\"T\":1788563046069,\"s\":\"BTCUSDT\",\"ps\":\"BTCUSDT\",\"U\":11478212780840,\"u\":11478212789381,\"pu\":11478212780626,\"b\":[[\"1000.00\",\"25.004\"],[\"29398.10\",\"1.316\"],[\"29498.10\",\"0.784\"],[\"63679.00\",\"0.002\"],[\"71638.20\",\"0.002\"],[\"74273.30\",\"0.009\"],[\"76414.10\",\"0.002\"],[\"78576.80\",\"0.000\"],[\"78642.90\",\"12.736\"],[\"78802.10\",\"5.211\"],[\"78837.40\",\"0.000\"],[\"79200.10\",\"0.988\"],[\"79494.60\",\"1.431\"],[\"79496.60\",\"0.000\"],[\"79524.80\",\"0.014\"],[\"79534.10\",\"0.343\"],[\"79583.80\",\"0.000\"],[\"79593.70\",\"0.026\"],[\"79593.80\",\"0.166\"],[\"79598.10\",\"10.999\"]],\"a\":[[\"79601.70\",\"0.027\"],[\"79604.80\",\"0.003\"],[\"79609.50\",\"0.017\"],[\"79610.20\",\"0.002\"],[\"79735.50\",\"0.024\"],[\"79739.40\",\"0.125\"],[\"79986.20\",\"0.672\"],[\"79995.10\",\"0.000\"],[\"79996.20\",\"1.805\"],[\"80360.50\",\"0.000\"],[\"80394.20\",\"6.719\"],[\"80626.10\",\"0.001\"],[\"80633.00\",\"2.605\"]],\"st\":1}}"}
{"receive_ns":1788563046046754000,"stream":"btcusdt@bookTicker","event_type":"bookTicker","event_time_ms":1788563046112,"raw_json":"{\"stream\":\"btcusdt@bookTicker\",\"data\":{\"e\":\"bookTicker\",\"u\":11478212792323,\"s\":\"BTCUSDT\",\"ps\":\"BTCUSDT\",\"b\":\"79598.10\",\"B\":\"10.999\",\"a\":\"79598.20\",\"A\":\"3.176\",\"T\":1788563046112,\"E\":1788563046112,\"st\":1}}"}
{"receive_ns":1788563046055501000,"stream":"btcusdt@bookTicker","event_type":"bookTicker","event_time_ms":1788563046121,"raw_json":"{\"stream\":\"btcusdt@bookTicker\",\"data\":{\"e\":\"bookTicker\",\"u\":11478212793138,\"s\":\"BTCUSDT\",\"ps\":\"BTCUSDT\",\"b\":\"79598.10\",\"B\":\"10.999\",\"a\":\"79598.20\",\"A\":\"3.177\",\"T\":1788563046120,\"E\":1788563046121,\"st\":1}}"}
{"receive_ns":1788563046096721000,"stream":"btcusdt@bookTicker","event_type":"bookTicker","event_time_ms":1788563046161,"raw_json":"{\"stream\":\"btcusdt@bookTicker\",\"data\":{\"e\":\"bookTicker\",\"u\":11478212796690,\"s\":\"BTCUSDT\",\"ps\":\"BTCUSDT\",\"b\":\"79598.10\",\"B\":\"10.999\",\"a\":\"79598.20\",\"A\":\"3.545\",\"T\":1788563046161,\"E\":1788563046161,\"st\":1}}"}
{"receive_ns":1788563046096990000,"stream":"btcusdt@bookTicker","event_type":"bookTicker","event_time_ms":1788563046162,"raw_json":"{\"stream\":\"btcusdt@bookTicker\",\"data\":{\"e\":\"bookTicker\",\"u\":11478212796994,\"s\":\"BTCUSDT\",\"ps\":\"BTCUSDT\",\"b\":\"79598.10\",\"B\":\"11.007\",\"a\":\"79598.20\",\"A\":\"3.545\",\"T\":1788563046162,\"E\":1788563046162,\"st\":1}}"}
{"receive_ns":1788563046105290000,"stream":"btcusdt@bookTicker","event_type":"bookTicker","event_time_ms":1788563046162,"raw_json":"{\"stream\":\"btcusdt@bookTicker\",\"data\":{\"e\":\"bookTicker\",\"u\":11478212797095,\"s\":\"BTCUSDT\",\"ps\":\"BTCUSDT\",\"b\":\"79598.10\",\"B\":\"11.009\",\"a\":\"79598.20\",\"A\":\"3.545\",\"T\":1788563046162,\"E\":1788563046162,\"st\":1}}"}
{"receive_ns":1788563046105485000,"stream":"btcusdt@bookTicker","event_type":"bookTicker","event_time_ms":1788563046162,"raw_json":"{\"stream\":\"btcusdt@bookTicker\",\"data\":{\"e\":\"bookTicker\",\"u\":11478212797121,\"s\":\"BTCUSDT\",\"ps\":\"BTCUSDT\",\"b\":\"79598.10\",\"B\":\"10.987\",\"a\":\"79598.20\",\"A\":\"3.545\",\"T\":1788563046162,\"E\":1788563046162,\"st\":1}}"}
{"receive_ns":1788563046105636000,"stream":"btcusdt@bookTicker","event_type":"bookTicker","event_time_ms":1788563046162,"raw_json":"{\"stream\":\"btcusdt@bookTicker\",\"data\":{\"e\":\"bookTicker\",\"u\":11478212797137,\"s\":\"BTCUSDT\",\"ps\":\"BTCUSDT\",\"b\":\"79598.10\",\"B\":\"10.987\",\"a\":\"79598.20\",\"A\":\"3.544\",\"T\":1788563046162,\"E\":1788563046162,\"st\":1}}"}
{"receive_ns":1788563046105778000,"stream":"btcusdt@bookTicker","event_type":"bookTicker","event_time_ms":1788563046162,"raw_json":"{\"stream\":\"btcusdt@bookTicker\",\"data\":{\"e\":\"bookTicker\",\"u\":11478212797199,\"s\":\"BTCUSDT\",\"ps\":\"BTCUSDT\",\"b\":\"79598.10\",\"B\":\"10.995\",\"a\":\"79598.20\",\"A\":\"3.544\",\"T\":1788563046162,\"E\":1788563046162,\"st\":1}}"}
{"receive_ns":1788563046106020000,"stream":"btcusdt@bookTicker","event_type":"bookTicker","event_time_ms":1788563046163,"raw_json":"{\"stream\":\"btcusdt@bookTicker\",\"data\":{\"e\":\"bookTicker\",\"u\":11478212797537,\"s\":\"BTCUSDT\",\"ps\":\"BTCUSDT\",\"b\":\"79598.10\",\"B\":\"10.987\",\"a\":\"79598.20\",\"A\":\"3.544\",\"T\":1788563046163,\"E\":1788563046163,\"st\":1}}"}
{"receive_ns":1788563046106209000,"stream":"btcusdt@bookTicker","event_type":"bookTicker","event_time_ms":1788563046163,"raw_json":"{\"stream\":\"btcusdt@bookTicker\",\"data\":{\"e\":\"bookTicker\",\"u\":11478212797577,\"s\":\"BTCUSDT\",\"ps\":\"BTCUSDT\",\"b\":\"79598.10\",\"B\":\"10.979\",\"a\":\"79598.20\",\"A\":\"3.544\",\"T\":1788563046163,\"E\":1788563046163,\"st\":1}}"}
{"receive_ns":1788563046109161000,"stream":"btcusdt@depth@100ms","event_type":"depthUpdate","event_time_ms":1788563046173,"raw_json":"{\"stream\":\"btcusdt@depth@100ms\",\"data\":{\"e\":\"depthUpdate\",\"E\":1788563046173,\"T\":1788563046171,\"s\":\"BTCUSDT\",\"ps\":\"BTCUSDT\",\"U\":11478212789484,\"u\":11478212798922,\"pu\":11478212789381,\"b\":[[\"29398.10\",\"1.491\"],[\"29498.10\",\"0.609\"],[\"63679.00\",\"0.002\"],[\"71638.20\",\"0.002\"],[\"76414.10\",\"0.000\"],[\"78000.00\",\"75.390\"],[\"78603.10\",\"2.519\"],[\"78802.10\",\"5.211\"],[\"78912.40\",\"0.057\"],[\"79051.60\",\"57.470\"],[\"79195.60\",\"2.646\"],[\"79200.10\",\"1.129\"],[\"79226.30\",\"43.739\"],[\"79345.80\",\"35.921\"],[\"79401.10\",\"0.502\"],[\"79404.00\",\"1.215\"],[\"79469.80\",\"0.014\"],[\"79482.70\",\"0.017\"],[\"79485.60\",\"0.000\"],[\"79492.60\",\"0.001\"],[\"79494.60\",\"2.436\"],[\"79496.80\",\"0.000\"],[\"79510.50\",\"0.001\"],[\"79511.60\",\"0.829\"],[\"79519.00\",\"0.033\"],[\"79524.80\",\"0.000\"],[\"79527.50\",\"2.050\"],[\"79531.10\",\"0.019\"],[\"79563.30\",\"0.047\"],[\"79564.30\",\"0.252\"],[\"79572.10\",\"0.518\"],[\"79572.50\",\"0.715\"],[\"79573.20\",\"0.001\"],[\"79573.50\",\"0.000\"],[\"79597.70\",\"0.000\"],[\"79598.10\",\"10.979\"]],\"a\":[[\"79598.20\",\"3.544\"],[\"79601.20\",\"0.027\"],[\"79601.60\",\"0.026\"],[\"79601.70\",\"0.001\"],[\"79602.10\",\"0.002\"],[\"79602.20\",\"0.003\"],[\"79602.30\",\"0.026\"],[\"79603.10\",\"0.226\"],[\"79603.40\",\"0.028\"],[\"79603.50\",\"0.282\"],[\"79604.40\",\"0.002\"],[\"79604.60\",\"0.003\"],[\"79604.70\",\"0.000\"],[\"79609.50\",\"0.017\"],[\"79609.60\",\"0.258\"],[\"79610.20\",\"0.441\"],[\"79610.90\",\"0.740\"],[\"79611.10\",\"0.976\"],[\"79611.40\",\"0.420\"],[\"79612.40\",\"0.000\"],[\"79613.70\",\"0.372\"],[\"79614.70\",\"0.001\"],[\"79627.10\",\"0.000\"],[\"79628.30\",\"0.046\"],[\"79629.40\",\"0.780\"],[\"79641.40\",\"0.211\"],[\"79645.20\",\"2.080\"],[\"79650.50\",\"0.020\"],[\"79651.90\",\"0.002\"],[\"79669.60\",\"0.000\"],[\"79675.30\",\"0.005\"],[\"79684.90\",\"0.031\"],[\"79733.90\",\"0.127\"],[\"79739.00\",\"0.092\"],[\"79739.20\",\"0.000\"],[\"79739.30\",\"0.000\"],[\"79739.40\",\"0.000\"],[\"79846.90\",\"35.357\"],[\"79967.20\",\"44.686\"],[\"79986.20\",\"0.421\"],[\"79991.70\",\"3.475\"],[\"79996.20\",\"2.331\"],[\"80143.50\",\"54.301\"],[\"80394.20\",\"6.719\"],[\"80712.60\",\"18.312\"],[\"80752.40\",\"5.320\"]],\"st\":1}}"}
{"receive_ns":1788563046109600000,"stream":"btcusdt@bookTicker","event_type":"bookTicker","event_time_ms":1788563046174,"raw_json":"{\"stream\":\"btcusdt@bookTicker\",\"data\":{\"e\":\"bookTicker\",\"u\":11478212799158,\"s\":\"BTCUSDT\",\"ps\":\"BTCUSDT\",\"b\":\"79598.10\",\"B\":\"10.987\",\"a\":\"79598.20\",\"A\":\"3.544\",\"T\":1788563046174,\"E\":1788563046174,\"st\":1}}"}
{"receive_ns":1788563046109851000,"stream":"btcusdt@bookTicker","event_type":"bookTicker","event_time_ms":1788563046174,"raw_json":"{\"stream\":\"btcusdt@bookTicker\",\"data\":{\"e\":\"bookTicker\",\"u\":11478212799262,\"s\":\"BTCUSDT\",\"ps\":\"BTCUSDT\",\"b\":\"79598.10\",\"B\":\"10.979\",\"a\":\"79598.20\",\"A\":\"3.544\",\"T\":1788563046174,\"E\":1788563046174,\"st\":1}}"}
{"receive_ns":1788563046136213000,"stream":"btcusdt@bookTicker","event_type":"bookTicker","event_time_ms":1788563046200,"raw_json":"{\"stream\":\"btcusdt@bookTicker\",\"data\":{\"e\":\"bookTicker\",\"u\":11478212801850,\"s\":\"BTCUSDT\",\"ps\":\"BTCUSDT\",\"b\":\"79598.10\",\"B\":\"10.987\",\"a\":\"79598.20\",\"A\":\"3.544\",\"T\":1788563046200,\"E\":1788563046200,\"st\":1}}"}
{"receive_ns":1788563046138045000,"stream":"btcusdt@bookTicker","event_type":"bookTicker","event_time_ms":1788563046201,"raw_json":"{\"stream\":\"btcusdt@bookTicker\",\"data\":{\"e\":\"bookTicker\",\"u\":11478212802008,\"s\":\"BTCUSDT\",\"ps\":\"BTCUSDT\",\"b\":\"79598.10\",\"B\":\"10.979\",\"a\":\"79598.20\",\"A\":\"3.544\",\"T\":1788563046200,\"E\":1788563046201,\"st\":1}}"}
{"receive_ns":1788563046211316000,"stream":"btcusdt@depth@100ms","event_type":"depthUpdate","event_time_ms":1788563046275,"raw_json":"{\"stream\":\"btcusdt@depth@100ms\",\"data\":{\"e\":\"depthUpdate\",\"E\":1788563046275,\"T\":1788563046274,\"s\":\"BTCUSDT\",\"ps\":\"BTCUSDT\",\"U\":11478212799034,\"u\":11478212808693,\"pu\":11478212798922,\"b\":[[\"1000.00\",\"25.004\"],[\"29398.10\",\"1.673\"],[\"29498.10\",\"0.427\"],[\"71638.20\",\"0.002\"],[\"74437.90\",\"0.009\"],[\"78577.10\",\"86.918\"],[\"78603.10\",\"3.154\"],[\"78802.10\",\"5.211\"],[\"78831.40\",\"0.001\"],[\"78837.70\",\"71.411\"],[\"79051.40\",\"0.000\"],[\"79051.70\",\"1.554\"],[\"79200.10\",\"0.907\"],[\"79226.20\",\"0.000\"],[\"79226.40\",\"0.395\"],[\"79227.80\",\"7.493\"],[\"79469.80\",\"0.000\"],[\"79483.40\",\"0.014\"],[\"79492.30\",\"0.031\"],[\"79492.60\",\"0.233\"],[\"79494.60\",\"2.436\"],[\"79503.90\",\"0.002\"],[\"79507.80\",\"0.000\"],[\"79516.40\",\"0.001\"],[\"79517.00\",\"0.354\"],[\"79555.00\",\"0.032\"],[\"79563.30\",\"0.001\"],[\"79564.30\",\"0.298\"],[\"79565.50\",\"0.792\"],[\"79572.10\",\"0.079\"],[\"79572.50\",\"0.342\"],[\"79573.20\",\"0.440\"],[\"79573.50\",\"0.373\"],[\"79574.50\",\"0.631\"],[\"79574.70\",\"0.001\"],[\"79575.20\",\"0.737\"],[\"79575.30\",\"0.001\"],[\"79578.40\",\"1.044\"],[\"79579.00\",\"0.002\"],[\"79582.10\",\"0.016\"],[\"79582.30\",\"0.324\"],[\"79582.40\",\"0.629\"],[\"79582.60\",\"0.000\"],[\"79583.00\",\"0.002\"],[\"79583.10\",\"0.002\"],[\"79583.20\",\"0.002\"],[\"79583.60\",\"0.020\"],[\"79584.20\",\"0.070\"],[\"79585.10\",\"0.000\"],[\"79585.30\",\"0.077\"],[\"79585.40\",\"0.000\"],[\"79586.30\",\"0.006\"],[\"79586.90\",\"0.006\"],[\"79588.40\",\"0.104\"],[\"79589.10\",\"0.001\"],[\"79590.40\",\"0.457\"],[\"79591.30\",\"0.000\"],[\"79592.70\",\"0.001\"],[\"79596.50\",\"0.001\"],[\"79598.10\",\"10.979\"]],\"a\":[[\"79599.40\",\"0.328\"],[\"79600.00\",\"0.078\"],[\"79600.20\",\"0.027\"],[\"79600.60\",\"0.026\"],[\"79603.10\",\"0.026\"],[\"79603.90\",\"0.050\"],[\"79604.10\",\"0.330\"],[\"79604.20\",\"0.999\"],[\"79604.30\",\"0.005\"],[\"79606.10\",\"0.007\"],[\"79607.60\",\"0.001\"],[\"79608.30\",\"0.005\"],[\"79609.50\",\"0.009\"],[\"79610.20\",\"0.319\"],[\"79610.60\",\"0.063\"],[\"79610.80\",\"0.199\"],[\"79611.10\",\"0.972\"],[\"79611.20\",\"0.226\"],[\"79611.40\",\"0.859\"],[\"79613.70\",\"0.000\"],[\"79614.60\",\"0.373\"],[\"79622.00\",\"0.063\"],[\"79622.30\",\"0.628\"],[\"79623.20\",\"0.000\"],[\"79623.40\",\"0.002\"],[\"79626.40\",\"0.627\"],[\"79627.30\",\"0.428\"],[\"79628.30\",\"0.000\"],[\"79629.30\",\"0.068\"],[\"79645.30\",\"0.001\"],[\"79650.00\",\"0.195\"],[\"79650.10\",\"0.002\"],[\"79650.50\",\"0.006\"],[\"79665.80\",\"0.041\"],[\"79674.80\",\"0.014\"],[\"79698.70\",\"0.001\"],[\"79739.00\",\"0.092\"],[\"79966.30\",\"1.106\"],[\"79967.10\",\"0.686\"],[\"79996.20\",\"1.476\"],[\"79999.90\",\"13.316\"],[\"80099.90\",\"7.202\"],[\"80394.20\",\"6.719\"]],\"st\":1}}"}
{"receive_ns":1788563046258734000,"stream":"btcusdt@bookTicker","event_type":"bookTicker","event_time_ms":1788563046324,"raw_json":"{\"stream\":\"btcusdt@bookTicker\",\"data\":{\"e\":\"bookTicker\",\"u\":11478212813346,\"s\":\"BTCUSDT\",\"ps\":\"BTCUSDT\",\"b\":\"79598.10\",\"B\":\"10.937\",\"a\":\"79598.20\",\"A\":\"3.544\",\"T\":1788563046324,\"E\":1788563046324,\"st\":1}}"}
{"receive_ns":1788563046262031000,"stream":"btcusdt@bookTicker","event_type":"bookTicker","event_time_ms":1788563046327,"raw_json":"{\"stream\":\"btcusdt@bookTicker\",\"data\":{\"e\":\"bookTicker\",\"u\":11478212813603,\"s\":\"BTCUSDT\",\"ps\":\"BTCUSDT\",\"b\":\"79598.10\",\"B\":\"10.990\",\"a\":\"79598.20\",\"A\":\"3.544\",\"T\":1788563046327,\"E\":1788563046327,\"st\":1}}"}
{"receive_ns":1788563046262287000,"stream":"btcusdt@bookTicker","event_type":"bookTicker","event_time_ms":1788563046328,"raw_json":"{\"stream\":\"btcusdt@bookTicker\",\"data\":{\"e\":\"bookTicker\",\"u\":11478212813698,\"s\":\"BTCUSDT\",\"ps\":\"BTCUSDT\",\"b\":\"79598.10\",\"B\":\"10.990\",\"a\":\"79598.20\",\"A\":\"3.545\",\"T\":1788563046328,\"E\":1788563046328,\"st\":1}}"}
{"receive_ns":1788563046311567000,"stream":"btcusdt@depth@100ms","event_type":"depthUpdate","event_time_ms":1788563046377,"raw_json":"{\"stream\":\"btcusdt@depth@100ms\",\"data\":{\"e\":\"depthUpdate\",\"E\":1788563046377,\"T\":1788563046374,\"s\":\"BTCUSDT\",\"ps\":\"BTCUSDT\",\"U\":11478212808966,\"u\":11478212816621,\"pu\":11478212808693,\"b\":[[\"1000.00\",\"25.004\"],[\"29298.10\",\"0.035\"],[\"29398.10\",\"1.778\"],[\"29498.10\",\"0.287\"],[\"71638.20\",\"0.002\"],[\"76414.10\",\"0.002\"],[\"78523.50\",\"1.911\"],[\"78802.10\",\"5.211\"],[\"78841.90\",\"4.852\"],[\"78961.30\",\"1.264\"],[\"79200.10\",\"0.908\"],[\"79401.10\",\"0.000\"],[\"79404.00\",\"1.014\"],[\"79494.60\",\"2.436\"],[\"79517.00\",\"0.340\"],[\"79526.00\",\"0.036\"],[\"79555.10\",\"0.028\"],[\"79558.30\",\"0.080\"],[\"79592.00\",\"0.543\"],[\"79598.10\",\"10.990\"]],\"a\":[[\"79598.20\",\"3.545\"],[\"79600.00\",\"0.052\"],[\"79600.20\",\"0.001\"],[\"79608.30\",\"0.009\"],[\"79610.10\",\"0.005\"],[\"79610.20\",\"0.315\"],[\"79610.80\",\"0.193\"],[\"79623.30\",\"0.047\"],[\"79643.50\",\"0.358\"],[\"79666.00\",\"0.052\"],[\"79669.90\",\"0.002\"],[\"79674.80\",\"0.000\"],[\"79735.50\",\"0.275\"],[\"79739.20\",\"0.000\"],[\"79739.40\",\"0.000\"],[\"79986.20\",\"0.002\"],[\"79996.20\",\"1.476\"],[\"80230.40\",\"4.604\"],[\"80394.20\",\"6.719\"]],\"st\":1}}"}
{"receive_ns":1788563046415539000,"stream":"btcusdt@depth@100ms","event_type":"depthUpdate","event_time_ms":1788563046479,"raw_json":"{\"stream\":\"btcusdt@depth@100ms\",\"data\":{\"e\":\"depthUpdate\",\"E\":1788563046479,\"T\":1788563046477,\"s\":\"BTCUSDT\",\"ps\":\"BTCUSDT\",\"U\":11478212816949,\"u\":11478212823652,\"pu\":11478212816621,\"b\":[[\"29298.10\",\"0.091\"],[\"29398.10\",\"1.848\"],[\"29498.10\",\"0.161\"],[\"71638.20\",\"0.002\"],[\"74602.60\",\"0.009\"],[\"76414.10\",\"0.000\"],[\"78704.10\",\"0.001\"],[\"78802.10\",\"5.211\"],[\"79200.10\",\"1.411\"],[\"79401.10\",\"0.232\"],[\"79423.50\",\"11.635\"],[\"79492.60\",\"1.432\"],[\"79494.60\",\"1.005\"],[\"79495.50\",\"0.215\"],[\"79496.60\",\"0.502\"],[\"79500.50\",\"0.001\"],[\"79507.20\",\"1.362\"],[\"79565.10\",\"0.001\"],[\"79566.00\",\"0.453\"],[\"79569.80\",\"0.251\"],[\"79570.50\",\"0.002\"],[\"79584.20\",\"0.070\"],[\"79584.70\",\"0.001\"],[\"79591.80\",\"0.029\"],[\"79592.20\",\"0.054\"]],\"a\":[[\"79606.10\",\"0.007\"],[\"79607.70\",\"0.000\"],[\"79610.10\",\"0.005\"],[\"79610.20\",\"0.377\"],[\"79610.60\",\"0.001\"],[\"79614.40\",\"0.251\"],[\"79615.30\",\"0.001\"],[\"79615.70\",\"0.454\"],[\"79617.00\",\"0.005\"],[\"79645.10\",\"1.907\"],[\"79735.50\",\"0.526\"],[\"79736.40\",\"0.211\"],[\"79739.90\",\"0.000\"],[\"79821.30\",\"8.284\"],[\"79821.50\",\"0.001\"],[\"79962.40\",\"0.854\"],[\"79964.30\",\"7.716\"],[\"79964.40\",\"0.420\"],[\"79966.30\",\"0.001\"],[\"79996.20\",\"1.974\"],[\"80362.60\",\"72.473\"]],\"st\":1}}"}
{"receive_ns":1788563046478002000,"stream":"btcusdt@bookTicker","event_type":"bookTicker","event_time_ms":1788563046542,"raw_json":"{\"stream\":\"btcusdt@bookTicker\",\"data\":{\"e\":\"bookTicker\",\"u\":11478212828220,\"s\":\"BTCUSDT\",\"ps\":\"BTCUSDT\",\"b\":\"79598.10\",\"B\":\"10.952\",\"a\":\"79598.20\",\"A\":\"3.545\",\"T\":1788563046542,\"E\":1788563046542,\"st\":1}}"}
{"receive_ns":1788563046481217000,"stream":"btcusdt@bookTicker","event_type":"bookTicker","event_time_ms":1788563046545,"raw_json":"{\"stream\":\"btcusdt@bookTicker\",\"data\":{\"e\":\"bookTicker\",\"u\":11478212828403,\"s\":\"BTCUSDT\",\"ps\":\"BTCUSDT\",\"b\":\"79598.10\",\"B\":\"10.991\",\"a\":\"79598.20\",\"A\":\"3.545\",\"T\":1788563046545,\"E\":1788563046545,\"st\":1}}"}
{"receive_ns":1788563046488138000,"stream":"btcusdt@bookTicker","event_type":"bookTicker","event_time_ms":1788563046552,"raw_json":"{\"stream\":\"btcusdt@bookTicker\",\"data\":{\"e\":\"bookTicker\",\"u\":11478212828970,\"s\":\"BTCUSDT\",\"ps\":\"BTCUSDT\",\"b\":\"79598.10\",\"B\":\"10.991\",\"a\":\"79598.20\",\"A\":\"3.177\",\"T\":1788563046552,\"E\":1788563046552,\"st\":1}}"}
{"receive_ns":1788563046488411000,"stream":"btcusdt@bookTicker","event_type":"bookTicker","event_time_ms":1788563046553,"raw_json":"{\"stream\":\"btcusdt@bookTicker\",\"data\":{\"e\":\"bookTicker\",\"u\":11478212829162,\"s\":\"BTCUSDT\",\"ps\":\"BTCUSDT\",\"b\":\"79598.10\",\"B\":\"10.999\",\"a\":\"79598.20\",\"A\":\"3.177\",\"T\":1788563046553,\"E\":1788563046553,\"st\":1}}"}
{"receive_ns":1788563046489827000,"stream":"btcusdt@bookTicker","event_type":"bookTicker","event_time_ms":1788563046554,"raw_json":"{\"stream\":\"btcusdt@bookTicker\",\"data\":{\"e\":\"bookTicker\",\"u\":11478212829307,\"s\":\"BTCUSDT\",\"ps\":\"BTCUSDT\",\"b\":\"79598.10\",\"B\":\"10.991\",\"a\":\"79598.20\",\"A\":\"3.177\",\"T\":1788563046554,\"E\":1788563046554,\"st\":1}}"}
{"receive_ns":1788563046517200000,"stream":"btcusdt@depth@100ms","event_type":"depthUpdate","event_time_ms":1788563046581,"raw_json":"{\"stream\":\"btcusdt@depth@100ms\",\"data\":{\"e\":\"depthUpdate\",\"E\":1788563046581,\"T\":1788563046580,\"s\":\"BTCUSDT\",\"ps\":\"BTCUSDT\",\"U\":11478212823837,\"u\":11478212830986,\"pu\":11478212823652,\"b\":[[\"1000.00\",\"25.004\"],[\"29298.10\",\"0.154\"],[\"29398.10\",\"1.897\"],[\"29498.10\",\"0.049\"],[\"63679.00\",\"0.002\"],[\"71638.20\",\"0.002\"],[\"76414.10\",\"0.002\"],[\"78802.10\",\"5.211\"],[\"79001.10\",\"1.962\"],[\"79200.10\",\"1.270\"],[\"79494.60\",\"0.000\"],[\"79527.50\",\"1.359\"],[\"79563.30\",\"0.047\"],[\"79564.30\",\"0.252\"],[\"79565.10\",\"0.453\"],[\"79566.00\",\"0.001\"],[\"79572.10\",\"0.518\"],[\"79572.50\",\"0.715\"],[\"79573.20\",\"0.001\"],[\"79573.50\",\"0.000\"],[\"79598.10\",\"10.991\"]],\"a\":[[\"79598.20\",\"3.177\"],[\"79600.60\",\"0.000\"],[\"79601.20\",\"0.001\"],[\"79601.60\",\"0.000\"],[\"79601.70\",\"0.001\"],[\"79601.80\",\"0.001\"],[\"79602.30\",\"0.000\"],[\"79602.80\",\"0.026\"],[\"79602.90\",\"0.027\"],[\"79603.20\",\"0.030\"],[\"79603.50\",\"0.030\"],[\"79603.80\",\"0.026\"],[\"79603.90\",\"0.076\"],[\"79606.10\",\"0.001\"],[\"79607.70\",\"0.006\"],[\"79609.60\",\"0.258\"],[\"79610.20\",\"0.816\"],[\"79611.40\",\"0.420\"],[\"79612.40\",\"0.000\"],[\"79613.70\",\"0.372\"],[\"79614.60\",\"0.001\"],[\"79614.70\",\"0.001\"],[\"79615.70\",\"0.002\"],[\"79615.90\",\"0.562\"],[\"79627.10\",\"0.000\"],[\"79628.30\",\"0.046\"],[\"79629.30\",\"0.022\"],[\"79733.90\",\"0.188\"],[\"79735.50\",\"0.275\"],[\"79739.60\",\"0.001\"],[\"79739.90\",\"0.125\"],[\"79996.20\",\"1.448\"],[\"80394.20\",\"6.719\"],[\"80531.70\",\"0.433\"],[\"81190.10\",\"0.017\"]],\"st\":1}}"}
{"receive_ns":1788563046619382000,"stream":"btcusdt@depth@100ms","event_type":"depthUpdate","event_time_ms":1788563046683,"raw_json":"{\"stream\":\"btcusdt@depth@100ms\",\"data\":{\"e\":\"depthUpdate\",\"E\":1788563046683,\"T\":1788563046681,\"s\":\"BTCUSDT\",\"ps\":\"BTCUSDT\",\"U\":11478212831018,\"u\":11478212836756,\"pu\":11478212830986,\"b\":[[\"1000.00\",\"25.004\"],[\"29298.10\",\"0.287\"],[\"29398.10\",\"1.813\"],[\"29498.10\",\"0.000\"],[\"71638.20\",\"0.002\"],[\"74767.30\",\"0.012\"],[\"76414.10\",\"0.000\"],[\"78802.10\",\"5.211\"],[\"79200.10\",\"1.411\"],[\"79461.80\",\"0.100\"],[\"79485.60\",\"0.201\"],[\"79494.60\",\"1.507\"],[\"79495.50\",\"0.014\"],[\"79496.60\",\"0.000\"],[\"79536.70\",\"0.000\"],[\"79536.80\",\"3.586\"],[\"79563.30\",\"0.001\"],[\"79564.30\",\"0.298\"],[\"79565.40\",\"10.884\"],[\"79572.10\",\"0.079\"],[\"79572.50\",\"0.342\"],[\"79573.20\",\"0.440\"],[\"79573.50\",\"0.373\"],[\"79574.70\",\"0.001\"],[\"79574.90\",\"0.000\"]],\"a\":[[\"79601.90\",\"0.026\"],[\"79610.20\",\"0.377\"],[\"79611.40\",\"0.859\"],[\"79613.70\",\"0.000\"],[\"79614.60\",\"0.373\"],[\"79615.90\",\"0.110\"],[\"79616.90\",\"0.456\"],[\"79628.30\",\"0.000\"],[\"79629.20\",\"0.066\"],[\"79674.50\",\"2.899\"],[\"79675.60\",\"0.000\"],[\"79685.10\",\"0.065\"],[\"79685.80\",\"0.033\"],[\"79691.80\",\"0.101\"],[\"79735.50\",\"0.526\"],[\"79736.40\",\"0.011\"],[\"79739.90\",\"0.000\"],[\"79962.40\",\"1.273\"],[\"79964.40\",\"0.001\"],[\"79996.20\",\"1.973\"],[\"80394.20\",\"6.719\"],[\"81190.10\",\"0.014\"]],\"st\":1}}"}
{"receive_ns":1788563046719748000,"stream":"btcusdt@depth@100ms","event_type":"depthUpdate","event_time_ms":1788563046785,"raw_json":"{\"stream\":\"btcusdt@depth@100ms\",\"data\":{\"e\":\"depthUpdate\",\"E\":1788563046785,\"T\":1788563046781,\"s\":\"BTCUSDT\",\"ps\":\"BTCUSDT\",\"U\":11478212836832,\"u\":11478212840866,\"pu\":11478212836756,\"b\":[[\"29298.10\",\"0.455\"],[\"29398.10\",\"1.645\"],[\"63678.50\",\"0.000\"],[\"71638.20\",\"0.002\"],[\"71675.00\",\"0.002\"],[\"75618.20\",\"0.006\"],[\"78802.10\",\"5.211\"],[\"79200.10\",\"1.412\"],[\"79401.10\",\"0.232\"],[\"79492.60\",\"1.106\"],[\"79494.60\",\"1.833\"],[\"79496.20\",\"0.073\"],[\"79574.40\",\"0.050\"]],\"a\":[[\"79601.80\",\"0.027\"],[\"79601.90\",\"0.000\"],[\"79602.50\",\"0.026\"],[\"79603.90\",\"0.050\"],[\"79606.10\",\"0.007\"],[\"79607.70\",\"0.000\"],[\"79614.30\",\"0.361\"],[\"79735.50\",\"0.526\"],[\"79962.40\",\"1.273\"],[\"79971.30\",\"0.012\"],[\"79996.20\",\"1.973\"],[\"80394.20\",\"6.719\"],[\"80548.80\",\"7.810\"],[\"80607.80\",\"0.186\"]],\"st\":1}}"}
{"receive_ns":1788563046823943000,"stream":"btcusdt@depth@100ms","event_type":"depthUpdate","event_time_ms":1788563046887,"raw_json":"{\"stream\":\"btcusdt@depth@100ms\",\"data\":{\"e\":\"depthUpdate\",\"E\":1788563046887,\"T\":1788563046885,\"s\":\"BTCUSDT\",\"ps\":\"BTCUSDT\",\"U\":11478212841038,\"u\":11478212845508,\"pu\":11478212840866,\"b\":[[\"1000.00\",\"25.004\"],[\"29298.10\",\"0.644\"],[\"29398.10\",\"1.456\"],[\"71638.20\",\"0.002\"],[\"75618.20\",\"0.008\"],[\"76414.10\",\"0.002\"],[\"78802.10\",\"5.211\"],[\"79200.10\",\"1.402\"],[\"79485.60\",\"0.000\"],[\"79494.60\",\"1.833\"],[\"79550.30\",\"0.024\"],[\"79563.30\",\"0.047\"],[\"79564.30\",\"0.252\"],[\"79572.10\",\"0.518\"],[\"79572.50\",\"0.715\"],[\"79573.20\",\"0.001\"],[\"79573.50\",\"0.000\"],[\"79578.60\",\"0.249\"],[\"79581.80\",\"0.270\"]],\"a\":[[\"79601.50\",\"0.003\"],[\"79602.20\",\"0.003\"],[\"79603.10\",\"0.226\"],[\"79603.80\",\"0.000\"],[\"79609.60\",\"0.697\"],[\"79611.40\",\"0.420\"],[\"79612.40\",\"0.000\"],[\"79613.70\",\"0.372\"],[\"79614.60\",\"0.001\"],[\"79627.10\",\"0.000\"],[\"79628.30\",\"0.046\"],[\"79629.20\",\"0.020\"],[\"79645.10\",\"0.229\"],[\"79647.30\",\"0.018\"],[\"79665.30\",\"5.650\"],[\"79733.90\",\"0.127\"],[\"79735.50\",\"0.024\"],[\"79804.00\",\"0.935\"],[\"79807.40\",\"0.008\"],[\"79808.40\",\"2.263\"],[\"79809.90\",\"7.435\"],[\"79821.30\",\"8.333\"],[\"79962.40\",\"1.273\"],[\"79996.20\",\"1.973\"],[\"80190.70\",\"1.246\"],[\"80394.20\",\"6.719\"],[\"80529.50\",\"0.433\"]],\"st\":1}}"}
{"receive_ns":1788563046933261000,"stream":"btcusdt@depth@100ms","event_type":"depthUpdate","event_time_ms":1788563046989,"raw_json":"{\"stream\":\"btcusdt@depth@100ms\",\"data\":{\"e\":\"depthUpdate\",\"E\":1788563046989,\"T\":1788563046986,\"s\":\"BTCUSDT\",\"ps\":\"BTCUSDT\",\"U\":11478212845565,\"u\":11478212850458,\"pu\":11478212845508,\"b\":[[\"1000.00\",\"25.004\"],[\"29298.10\",\"0.819\"],[\"29398.10\",\"1.281\"],[\"71638.20\",\"0.002\"],[\"76414.10\",\"0.000\"],[\"78563.30\",\"2.447\"],[\"78802.10\",\"5.211\"],[\"79401.10\",\"0.232\"],[\"79404.00\",\"1.215\"],[\"79423.40\",\"0.070\"],[\"79492.60\",\"1.432\"],[\"79494.60\",\"1.507\"],[\"79500.40\",\"0.339\"],[\"79563.30\",\"0.001\"],[\"79564.20\",\"0.733\"],[\"79565.40\",\"10.884\"],[\"79572.10\",\"0.079\"],[\"79572.50\",\"0.342\"],[\"79573.20\",\"0.440\"],[\"79573.30\",\"0.373\"],[\"79574.60\",\"0.099\"],[\"79574.90\",\"0.000\"],[\"79576.10\",\"0.003\"],[\"79578.10\",\"0.010\"],[\"79595.40\",\"0.002\"]],\"a\":[[\"79601.10\",\"0.029\"],[\"79603.10\",\"0.026\"],[\"79609.60\",\"0.258\"],[\"79611.40\",\"0.859\"],[\"79647.40\",\"0.090\"],[\"79735.50\",\"0.275\"],[\"79739.80\",\"0.000\"],[\"79740.00\",\"0.500\"],[\"79962.40\",\"1.273\"],[\"79996.20\",\"1.973\"],[\"80394.20\",\"6.719\"],[\"80553.40\",\"17.099\"],[\"80626.00\",\"89.682\"]],\"st\":1}}"}
{"receive_ns":1788563047009551000,"stream":"btcusdt@bookTicker","event_type":"bookTicker","event_time_ms":1788563047072,"raw_json":"{\"stream\":\"btcusdt@bookTicker\",\"data\":{\"e\":\"bookTicker\",\"u\":11478212855170,\"s\":\"BTCUSDT\",\"ps\":\"BTCUSDT\",\"b\":\"79598.10\",\"B\":\"10.992\",\"a\":\"79598.20\",\"A\":\"3.177\",\"T\":1788563047072,\"E\":1788563047072,\"st\":1}}"}
{"receive_ns":1788563047027672000,"stream":"btcusdt@depth@100ms","event_type":"depthUpdate","event_time_ms":1788563047091,"raw_json":"{\"stream\":\"btcusdt@depth@100ms\",\"data\":{\"e\":\"depthUpdate\",\"E\":1788563047091,\"T\":1788563047090,\"s\":\"BTCUSDT\",\"ps\":\"BTCUSDT\",\"U\":11478212850689,\"u\":11478212855989,\"pu\":11478212850458,\"b\":[[\"29298.10\",\"1.001\"],[\"29398.10\",\"1.099\"],[\"71638.20\",\"0.002\"],[\"75618.20\",\"0.006\"],[\"75618.30\",\"0.004\"],[\"76414.10\",\"0.002\"],[\"78523.50\",\"2.419\"],[\"78802.10\",\"5.211\"],[\"79200.10\",\"1.261\"],[\"79494.60\",\"0.000\"],[\"79583.80\",\"0.000\"],[\"79598.10\",\"10.992\"]],\"a\":[[\"79601.10\",\"0.003\"],[\"79739.30\",\"0.000\"],[\"79739.60\",\"0.001\"],[\"79739.80\",\"0.000\"],[\"79739.90\",\"0.000\"],[\"79962.40\",\"0.854\"],[\"79996.20\",\"1.447\"],[\"80394.20\",\"6.719\"]],\"st\":1}}"}
{"receive_ns":1788563047131943000,"stream":"btcusdt@depth@100ms","event_type":"depthUpdate","event_time_ms":1788563047193,"raw_json":"{\"stream\":\"btcusdt@depth@100ms\",\"data\":{\"e\":\"depthUpdate\",\"E\":1788563047193,\"T\":1788563047192,\"s\":\"BTCUSDT\",\"ps\":\"BTCUSDT\",\"U\":11478212856054,\"u\":11478212862361,\"pu\":11478212855989,\"b\":[[\"1000.00\",\"25.154\"],[\"29298.10\",\"1.176\"],[\"29398.10\",\"0.924\"],[\"63679.00\",\"0.002\"],[\"71638.20\",\"0.002\"],[\"76414.10\",\"0.000\"],[\"78006.20\",\"0.015\"],[\"78578.60\",\"8.968\"],[\"78802.10\",\"6.478\"],[\"79200.10\",\"1.412\"],[\"79401.10\",\"0.000\"],[\"79404.00\",\"1.215\"],[\"79492.60\",\"0.001\"],[\"79494.60\",\"1.507\"],[\"79526.40\",\"0.001\"],[\"79558.30\",\"0.080\"],[\"79563.20\",\"0.056\"],[\"79564.20\",\"0.687\"],[\"79572.10\",\"0.518\"],[\"79572.40\",\"0.627\"],[\"79573.20\",\"0.001\"],[\"79573.30\",\"0.000\"]],\"a\":[[\"79601.20\",\"0.027\"],[\"79609.60\",\"0.697\"],[\"79611.40\",\"0.420\"],[\"79638.00\",\"0.006\"],[\"79660.80\",\"0.316\"],[\"79669.90\",\"0.000\"],[\"79684.90\",\"0.032\"],[\"79698.70\",\"0.000\"],[\"79735.50\",\"0.024\"],[\"79740.00\",\"0.625\"],[\"79962.40\",\"0.419\"],[\"79991.70\",\"3.350\"],[\"79996.20\",\"1.773\"],[\"80394.20\",\"7.961\"],[\"80548.80\",\"7.190\"],[\"80593.20\",\"1.661\"]],\"st\":1}}"}
{"receive_ns":1788563047230450000,"stream":"btcusdt@depth@100ms","event_type":"depthUpdate","event_time_ms":1788563047295,"raw_json":"{\"stream\":\"btcusdt@depth@100ms\",\"data\":{\"e\":\"depthUpdate\",\"E\":1788563047295,\"T\":1788563047293,\"s\":\"BTCUSDT\",\"ps\":\"BTCUSDT\",\"U\":11478212862407,\"u\":11478212868053,\"pu\":11478212862361,\"b\":[[\"1000.00\",\"25.004\"],[\"29298.10\",\"1.358\"],[\"29398.10\",\"0.742\"],[\"71638.20\",\"0.002\"],[\"77369.40\",\"0.516\"],[\"78802.10\",\"6.478\"],[\"79228.00\",\"0.245\"],[\"79401.10\",\"0.100\"],[\"79472.70\",\"2.552\"],[\"79492.60\",\"0.327\"],[\"79563.20\",\"0.010\"],[\"79564.10\",\"0.154\"],[\"79565.30\",\"0.196\"],[\"79572.10\",\"0.079\"],[\"79572.40\",\"0.254\"],[\"79573.20\",\"0.440\"],[\"79573.30\",\"0.373\"],[\"79574.60\",\"0.099\"],[\"79574.90\",\"0.000\"]],\"a\":[[\"79601.20\",\"0.001\"],[\"79606.10\",\"0.258\"],[\"79609.60\",\"0.258\"],[\"79611.40\",\"0.859\"],[\"79613.70\",\"0.000\"],[\"79614.50\",\"0.624\"],[\"79962.40\",\"1.273\"],[\"79996.20\",\"1.973\"],[\"80394.20\",\"7.961\"]],\"st\":1}}"}
{"receive_ns":1788563047240548000,"stream":"btcusdt@bookTicker","event_type":"bookTicker","event_time_ms":1788563047304,"raw_json":"{\"stream\":\"btcusdt@bookTicker\",\"data\":{\"e\":\"bookTicker\",\"u\":11478212868629,\"s\":\"BTCUSDT\",\"ps\":\"BTCUSDT\",\"b\":\"79598.10\",\"B\":\"10.948\",\"a\":\"79598.20\",\"A\":\"3.177\",\"T\":1788563047304,\"E\":1788563047304,\"st\":1}}"}
{"receive_ns":1788563047259850000,"stream":"btcusdt@bookTicker","event_type":"bookTicker","event_time_ms":1788563047307,"raw_json":"{\"stream\":\"btcusdt@bookTicker\",\"data\":{\"e\":\"bookTicker\",\"u\":11478212868832,\"s\":\"BTCUSDT\",\"ps\":\"BTCUSDT\",\"b\":\"79598.10\",\"B\":\"10.993\",\"a\":\"79598.20\",\"A\":\"3.177\",\"T\":1788563047307,\"E\":1788563047307,\"st\":1}}"}
{"receive_ns":1788563047271286000,"stream":"btcusdt@bookTicker","event_type":"bookTicker","event_time_ms":1788563047335,"raw_json":"{\"stream\":\"btcusdt@bookTicker\",\"data\":{\"e\":\"bookTicker\",\"u\":11478212870464,\"s\":\"BTCUSDT\",\"ps\":\"BTCUSDT\",\"b\":\"79598.10\",\"B\":\"10.977\",\"a\":\"79598.20\",\"A\":\"3.177\",\"T\":1788563047335,\"E\":1788563047335,\"st\":1}}"}
{"receive_ns":1788563047332849000,"stream":"btcusdt@depth@100ms","event_type":"depthUpdate","event_time_ms":1788563047397,"raw_json":"{\"stream\":\"btcusdt@depth@100ms\",\"data\":{\"e\":\"depthUpdate\",\"E\":1788563047397,\"T\":1788563047393,\"s\":\"BTCUSDT\",\"ps\":\"BTCUSDT\",\"U\":11478212868132,\"u\":11478212873746,\"pu\":11478212868053,\"b\":[[\"29298.10\",\"1.533\"],[\"29398.10\",\"0.567\"],[\"63679.00\",\"0.002\"],[\"71638.20\",\"0.002\"],[\"76414.10\",\"0.002\"],[\"78006.20\",\"0.018\"],[\"78802.10\",\"6.478\"],[\"79200.10\",\"1.411\"],[\"79404.00\",\"1.215\"],[\"79492.60\",\"0.829\"],[\"79494.60\",\"1.005\"],[\"79535.20\",\"0.764\"],[\"79598.10\",\"10.977\"]],\"a\":[[\"79601.30\",\"0.026\"],[\"79601.60\",\"0.026\"],[\"79603.10\",\"0.226\"],[\"79603.70\",\"0.003\"],[\"79659.90\",\"0.251\"],[\"79809.80\",\"5.174\"],[\"79809.90\",\"0.000\"],[\"79962.40\",\"1.273\"],[\"79996.20\",\"2.098\"],[\"80389.60\",\"9.352\"],[\"80394.20\",\"7.961\"],[\"80593.20\",\"1.847\"],[\"80633.00\",\"2.853\"],[\"81243.60\",\"0.000\"]],\"st\":1}}"}
{"receive_ns":1788563047371887000,"stream":"btcusdt@bookTicker","event_type":"bookTicker","event_time_ms":1788563047434,"raw_json":"{\"stream\":\"btcusdt@bookTicker\",\"data\":{\"e\":\"bookTicker\",\"u\":11478212876208,\"s\":\"BTCUSDT\",\"ps\":\"BTCUSDT\",\"b\":\"79598.10\",\"B\":\"10.924\",\"a\":\"79598.20\",\"A\":\"3.177\",\"T\":1788563047434,\"E\":1788563047434,\"st\":1}}"}
{"receive_ns":1788563047372086000,"stream":"btcusdt@bookTicker","event_type":"bookTicker","event_time_ms":1788563047435,"raw_json":"{\"stream\":\"btcusdt@bookTicker\",\"data\":{\"e\":\"bookTicker\",\"u\":11478212876219,\"s\":\"BTCUSDT\",\"ps\":\"BTCUSDT\",\"b\":\"79598.10\",\"B\":\"10.891\",\"a\":\"79598.20\",\"A\":\"3.177\",\"T\":1788563047434,\"E\":1788563047435,\"st\":1}}"}
{"receive_ns":1788563047380730000,"stream":"btcusdt@bookTicker","event_type":"bookTicker","event_time_ms":1788563047437,"raw_json":"{\"stream\":\"btcusdt@bookTicker\",\"data\":{\"e\":\"bookTicker\",\"u\":11478212876378,\"s\":\"BTCUSDT\",\"ps\":\"BTCUSDT\",\"b\":\"79598.10\",\"B\":\"10.945\",\"a\":\"79598.20\",\"A\":\"3.177\",\"T\":1788563047437,\"E\":1788563047437,\"st\":1}}"}
{"receive_ns":1788563047380984000,"stream":"btcusdt@bookTicker","event_type":"bookTicker","event_time_ms":1788563047438,"raw_json":"{\"stream\":\"btcusdt@bookTicker\",\"data\":{\"e\":\"bookTicker\",\"u\":11478212876440,\"s\":\"BTCUSDT\",\"ps\":\"BTCUSDT\",\"b\":\"79598.10\",\"B\":\"10.976\",\"a\":\"79598.20\",\"A\":\"3.177\",\"T\":1788563047438,\"E\":1788563047438,\"st\":1}}"}
{"receive_ns":1788563047396877000,"stream":"btcusdt@bookTicker","event_type":"bookTicker","event_time_ms":1788563047462,"raw_json":"{\"stream\":\"btcusdt@bookTicker\",\"data\":{\"e\":\"bookTicker\",\"u\":11478212877762,\"s\":\"BTCUSDT\",\"ps\":\"BTCUSDT\",\"b\":\"79598.10\",\"B\":\"10.976\",\"a\":\"79598.20\",\"A\":\"3.176\",\"T\":1788563047462,\"E\":1788563047462,\"st\":1}}"}
{"receive_ns":1788563047406726000,"stream":"btcusdt@bookTicker","event_type":"bookTicker","event_time_ms":1788563047469,"raw_json":"{\"stream\":\"btcusdt@bookTicker\",\"data\":{\"e\":\"bookTicker\",\"u\":11478212878203,\"s\":\"BTCUSDT\",\"ps\":\"BTCUSDT\",\"b\":\"79598.10\",\"B\":\"10.976\",\"a\":\"79598.20\",\"A\":\"3.179\",\"T\":1788563047469,\"E\":1788563047469,\"st\":1}}"}
{"receive_ns":1788563047434181000,"stream":"btcusdt@depth@100ms","event_type":"depthUpdate","event_time_ms":1788563047499,"raw_json":"{\"stream\":\"btcusdt@depth@100ms\",\"data\":{\"e\":\"depthUpdate\",\"E\":1788563047499,\"T\":1788563047498,\"s\":\"BTCUSDT\",\"ps\":\"BTCUSDT\",\"U\":11478212873906,\"u\":11478212879674,\"pu\":11478212873746,\"b\":[[\"1000.00\",\"25.004\"],[\"29298.10\",\"1.715\"],[\"29398.10\",\"0.385\"],[\"71638.20\",\"0.002\"],[\"76414.10\",\"0.000\"],[\"78802.10\",\"6.478\"],[\"79175.40\",\"0.027\"],[\"79200.10\",\"1.411\"],[\"79228.00\",\"0.013\"],[\"79345.60\",\"0.008\"],[\"79345.90\",\"9.583\"],[\"79401.10\",\"0.232\"],[\"79472.70\",\"1.547\"],[\"79491.40\",\"0.014\"],[\"79492.60\",\"0.503\"],[\"79494.60\",\"2.436\"],[\"79499.00\",\"0.003\"],[\"79502.00\",\"0.003\"],[\"79509.60\",\"0.003\"],[\"79563.20\",\"0.056\"],[\"79564.10\",\"0.108\"],[\"79565.10\",\"0.001\"],[\"79565.90\",\"0.038\"],[\"79566.40\",\"0.003\"],[\"79567.00\",\"0.454\"],[\"79572.10\",\"0.079\"],[\"79572.40\",\"0.254\"],[\"79573.20\",\"0.001\"],[\"79573.30\",\"0.000\"],[\"79574.60\",\"0.472\"],[\"79574.90\",\"0.439\"],[\"79576.20\",\"0.007\"],[\"79578.10\",\"0.004\"],[\"79596.70\",\"0.076\"],[\"79598.00\",\"0.111\"],[\"79598.10\",\"10.976\"]],\"a\":[[\"79598.20\",\"3.179\"],[\"79599.40\",\"0.252\"],[\"79600.50\",\"0.486\"],[\"79600.90\",\"0.030\"],[\"79601.00\",\"0.008\"],[\"79601.10\",\"0.003\"],[\"79601.30\",\"0.000\"],[\"79601.60\",\"0.000\"],[\"79601.70\",\"0.027\"],[\"79602.70\",\"0.029\"],[\"79603.10\",\"0.026\"],[\"79603.30\",\"0.026\"],[\"79603.40\",\"0.002\"],[\"79603.50\",\"0.004\"],[\"79606.10\",\"0.007\"],[\"79609.60\",\"0.258\"],[\"79611.00\",\"1.130\"],[\"79611.40\",\"0.420\"],[\"79612.40\",\"0.000\"],[\"79613.50\",\"1.245\"],[\"79614.50\",\"0.624\"],[\"79614.70\",\"0.001\"],[\"79615.70\",\"0.002\"],[\"79616.90\",\"0.456\"],[\"79645.10\",\"1.064\"],[\"79659.90\",\"0.000\"],[\"79735.50\",\"0.024\"],[\"79845.50\",\"6.042\"],[\"79961.60\",\"0.183\"],[\"79962.40\",\"1.273\"],[\"79996.20\",\"2.099\"],[\"80195.20\",\"2.492\"],[\"80394.20\",\"7.963\"],[\"80553.40\",\"17.719\"],[\"80672.80\",\"3.315\"],[\"80692.60\",\"9.779\"]],\"st\":1}}"}
{"receive_ns":1788563047556683000,"stream":"btcusdt@bookTicker","event_type":"bookTicker","event_time_ms":1788563047580,"raw_json":"{\"stream\":\"btcusdt@bookTicker\",\"data\":{\"e\":\"bookTicker\",\"u\":11478212886148,\"s\":\"BTCUSDT\",\"ps\":\"BTCUSDT\",\"b\":\"79598.10\",\"B\":\"10.984\",\"a\":\"79598.20\",\"A\":\"3.179\",\"T\":1788563047580,\"E\":1788563047580,\"st\":1}}"}
{"receive_ns":1788563047556921000,"stream":"btcusdt@bookTicker","event_type":"bookTicker","event_time_ms":1788563047581,"raw_json":"{\"stream\":\"btcusdt@bookTicker\",\"data\":{\"e\":\"bookTicker\",\"u\":11478212886189,\"s\":\"BTCUSDT\",\"ps\":\"BTCUSDT\",\"b\":\"79598.10\",\"B\":\"10.976\",\"a\":\"79598.20\",\"A\":\"3.179\",\"T\":1788563047580,\"E\":1788563047581,\"st\":1}}"}
{"receive_ns":1788563047557107000,"stream":"btcusdt@bookTicker","event_type":"bookTicker","event_time_ms":1788563047593,"raw_json":"{\"stream\":\"btcusdt@bookTicker\",\"data\":{\"e\":\"bookTicker\",\"u\":11478212886917,\"s\":\"BTCUSDT\",\"ps\":\"BTCUSDT\",\"b\":\"79598.10\",\"B\":\"10.992\",\"a\":\"79598.20\",\"A\":\"3.179\",\"T\":1788563047593,\"E\":1788563047593,\"st\":1}}"}
{"receive_ns":1788563047557496000,"stream":"btcusdt@depth@100ms","event_type":"depthUpdate","event_time_ms":1788563047601,"raw_json":"{\"stream\":\"btcusdt@depth@100ms\",\"data\":{\"e\":\"depthUpdate\",\"E\":1788563047601,\"T\":1788563047599,\"s\":\"BTCUSDT\",\"ps\":\"BTCUSDT\",\"U\":11478212879755,\"u\":11478212887276,\"pu\":11478212879674,\"b\":[[\"29198.10\",\"0.049\"],[\"29298.10\",\"1.792\"],[\"29398.10\",\"0.259\"],[\"63679.00\",\"0.002\"],[\"71638.20\",\"0.002\"],[\"75608.70\",\"0.000\"],[\"76414.10\",\"0.002\"],[\"78802.10\",\"7.745\"],[\"78956.90\",\"4.427\"],[\"79001.10\",\"2.594\"],[\"79200.10\",\"1.411\"],[\"79404.00\",\"1.014\"],[\"79492.60\",\"1.006\"],[\"79494.60\",\"1.431\"],[\"79542.30\",\"0.002\"],[\"79566.00\",\"0.453\"],[\"79567.00\",\"0.002\"],[\"79573.20\",\"0.440\"],[\"79573.30\",\"0.373\"],[\"79574.60\",\"0.099\"],[\"79574.90\",\"0.000\"],[\"79578.40\",\"1.042\"],[\"79598.10\",\"10.992\"]],\"a\":[[\"79600.70\",\"0.002\"],[\"79603.30\",\"0.000\"],[\"79614.20\",\"0.902\"],[\"79649.10\",\"0.006\"],[\"79657.10\",\"0.001\"],[\"79669.90\",\"0.002\"],[\"79676.80\",\"0.091\"],[\"79685.40\",\"0.000\"],[\"79735.50\",\"0.275\"],[\"79740.00\",\"0.500\"],[\"79962.40\",\"0.854\"],[\"79996.20\",\"2.099\"],[\"80230.40\",\"4.355\"],[\"80380.50\",\"0.932\"],[\"80394.20\",\"7.961\"],[\"80548.80\",\"6.818\"],[\"80634.30\",\"0.248\"],[\"87558.10\",\"0.000\"]],\"st\":1}}"}
{"receive_ns":1788563047567905000,"stream":"btcusdt@bookTicker","event_type":"bookTicker","event_time_ms":1788563047632,"raw_json":"{\"stream\":\"btcusdt@bookTicker\",\"data\":{\"e\":\"bookTicker\",\"u\":11478212889074,\"s\":\"BTCUSDT\",\"ps\":\"BTCUSDT\",\"b\":\"79598.10\",\"B\":\"11.000\",\"a\":\"79598.20\",\"A\":\"3.179\",\"T\":1788563047632,\"E\":1788563047632,\"st\":1}}"}
{"receive_ns":1788563047568515000,"stream":"btcusdt@bookTicker","event_type":"bookTicker","event_time_ms":1788563047633,"raw_json":"{\"stream\":\"btcusdt@bookTicker\",\"data\":{\"e\":\"bookTicker\",\"u\":11478212889138,\"s\":\"BTCUSDT\",\"ps\":\"BTCUSDT\",\"b\":\"79598.10\",\"B\":\"10.992\",\"a\":\"79598.20\",\"A\":\"3.179\",\"T\":1788563047632,\"E\":1788563047633,\"st\":1}}"}
{"receive_ns":1788563047582368000,"stream":"btcusdt@bookTicker","event_type":"bookTicker","event_time_ms":1788563047647,"raw_json":"{\"stream\":\"btcusdt@bookTicker\",\"data\":{\"e\":\"bookTicker\",\"u\":11478212890076,\"s\":\"BTCUSDT\",\"ps\":\"BTCUSDT\",\"b\":\"79598.10\",\"B\":\"11.003\",\"a\":\"79598.20\",\"A\":\"3.179\",\"T\":1788563047647,\"E\":1788563047647,\"st\":1}}"}
{"receive_ns":1788563047637831000,"stream":"btcusdt@depth@100ms","event_type":"depthUpdate","event_time_ms":1788563047703,"raw_json":"{\"stream\":\"btcusdt@depth@100ms\",\"data\":{\"e\":\"depthUpdate\",\"E\":1788563047703,\"T\":1788563047701,\"s\":\"BTCUSDT\",\"ps\":\"BTCUSDT\",\"U\":11478212887405,\"u\":11478212893274,\"pu\":11478212887276,\"b\":[[\"29198.10\",\"0.105\"],[\"29298.10\",\"1.862\"],[\"29398.10\",\"0.133\"],[\"63678.50\",\"0.002\"],[\"63679.00\",\"0.004\"],[\"71638.20\",\"0.002\"],[\"78638.50\",\"28.079\"],[\"78802.10\",\"7.745\"],[\"79401.10\",\"0.232\"],[\"79473.70\",\"0.000\"],[\"79485.60\",\"0.201\"],[\"79494.60\",\"1.933\"],[\"79598.10\",\"11.003\"]],\"a\":[[\"79598.50\",\"0.004\"],[\"79685.80\",\"0.001\"],[\"79685.90\",\"0.032\"],[\"79722.30\",\"1.885\"],[\"79735.50\",\"0.526\"],[\"79736.40\",\"0.211\"],[\"79739.80\",\"0.125\"],[\"79962.40\",\"1.273\"],[\"79996.20\",\"2.099\"],[\"80394.20\",\"7.961\"],[\"80712.60\",\"18.324\"],[\"81230.00\",\"3.126\"],[\"83047.20\",\"0.026\"],[\"83056.80\",\"0.100\"]],\"st\":1}}"}
{"receive_ns":1788563047719371000,"stream":"btcusdt@bookTicker","event_type":"bookTicker","event_time_ms":1788563047783,"raw_json":"{\"stream\":\"btcusdt@bookTicker\",\"data\":{\"e\":\"bookTicker\",\"u\":11478212897524,\"s\":\"BTCUSDT\",\"ps\":\"BTCUSDT\",\"b\":\"79598.10\",\"B\":\"11.003\",\"a\":\"79598.20\",\"A\":\"3.176\",\"T\":1788563047783,\"E\":1788563047783,\"st\":1}}"}
{"receive_ns":1788563047727491000,"stream":"btcusdt@bookTicker","event_type":"bookTicker","event_time_ms":1788563047792,"raw_json":"{\"stream\":\"btcusdt@bookTicker\",\"data\":{\"e\":\"bookTicker\",\"u\":11478212897893,\"s\":\"BTCUSDT\",\"ps\":\"BTCUSDT\",\"b\":\"79598.10\",\"B\":\"11.003\",\"a\":\"79598.20\",\"A\":\"3.177\",\"T\":1788563047792,\"E\":1788563047792,\"st\":1}}"}
{"receive_ns":1788563047739479000,"stream":"btcusdt@depth@100ms","event_type":"depthUpdate","event_time_ms":1788563047805,"raw_json":"{\"stream\":\"btcusdt@depth@100ms\",\"data\":{\"e\":\"depthUpdate\",\"E\":1788563047805,\"T\":1788563047802,\"s\":\"BTCUSDT\",\"ps\":\"BTCUSDT\",\"U\":11478212893396,\"u\":11478212898780,\"pu\":11478212893274,\"b\":[[\"1000.00\",\"25.004\"],[\"29198.10\",\"0.168\"],[\"29298.10\",\"1.911\"],[\"29398.10\",\"0.021\"],[\"63678.50\",\"0.000\"],[\"63679.00\",\"0.002\"],[\"71638.20\",\"0.002\"],[\"71675.00\",\"0.005\"],[\"76414.10\",\"0.000\"],[\"78797.70\",\"12.337\"],[\"78802.10\",\"7.745\"],[\"79200.10\",\"1.259\"],[\"79473.70\",\"0.576\"],[\"79492.60\",\"0.001\"],[\"79572.40\",\"0.627\"],[\"79572.50\",\"0.781\"],[\"79573.20\",\"0.001\"],[\"79573.30\",\"0.000\"],[\"79574.40\",\"0.048\"]],\"a\":[[\"79598.20\",\"3.177\"],[\"79600.50\",\"0.512\"],[\"79600.60\",\"0.000\"],[\"79600.80\",\"0.001\"],[\"79600.90\",\"0.004\"],[\"79601.40\",\"0.026\"],[\"79601.60\",\"0.026\"],[\"79603.20\",\"0.004\"],[\"79612.40\",\"0.000\"],[\"79613.50\",\"1.617\"],[\"79614.30\",\"0.359\"],[\"79614.50\",\"0.252\"],[\"79722.60\",\"0.368\"],[\"79735.50\",\"0.024\"],[\"79736.40\",\"0.011\"],[\"79739.80\",\"0.000\"],[\"79996.20\",\"1.573\"],[\"80378.30\",\"0.502\"],[\"80394.20\",\"7.961\"]],\"st\":1}}"}
{"receive_ns":1788563047843480000,"stream":"btcusdt@depth@100ms","event_type":"depthUpdate","event_time_ms":1788563047907,"raw_json":"{\"stream\":\"btcusdt@depth@100ms\",\"data\":{\"e\":\"depthUpdate\",\"E\":1788563047907,\"T\":1788563047906,\"s\":\"BTCUSDT\",\"ps\":\"BTCUSDT\",\"U\":11478212899099,\"u\":11478212904909,\"pu\":11478212898780,\"b\":[[\"29198.10\",\"0.329\"],[\"29298.10\",\"1.771\"],[\"29398.10\",\"0.000\"],[\"71638.20\",\"0.002\"],[\"71675.00\",\"0.002\"],[\"76414.10\",\"0.002\"],[\"78586.70\",\"0.000\"],[\"78591.50\",\"0.017\"],[\"78802.10\",\"7.745\"],[\"79200.10\",\"1.400\"],[\"79401.10\",\"0.000\"],[\"79404.00\",\"1.215\"],[\"79451.90\",\"2.377\"],[\"79453.30\",\"0.033\"],[\"79485.60\",\"0.000\"],[\"79492.60\",\"1.006\"],[\"79494.60\",\"0.828\"],[\"79572.40\",\"0.254\"],[\"79573.50\",\"0.373\"],[\"79574.40\",\"0.050\"],[\"79574.60\",\"0.099\"]],\"a\":[[\"79600.50\",\"0.486\"],[\"79613.50\",\"1.245\"],[\"79614.30\",\"0.361\"],[\"79614.50\",\"0.624\"],[\"79660.80\",\"0.516\"],[\"79735.50\",\"0.275\"],[\"79962.40\",\"0.419\"],[\"79996.20\",\"2.100\"],[\"80394.20\",\"7.963\"],[\"80965.70\",\"0.010\"]],\"st\":1}}"}
{"receive_ns":1788563047940744000,"stream":"btcusdt@bookTicker","event_type":"bookTicker","event_time_ms":1788563048005,"raw_json":"{\"stream\":\"btcusdt@bookTicker\",\"data\":{\"e\":\"bookTicker\",\"u\":11478212910499,\"s\":\"BTCUSDT\",\"ps\":\"BTCUSDT\",\"b\":\"79598.10\",\"B\":\"11.003\",\"a\":\"79598.20\",\"A\":\"3.176\",\"T\":1788563048005,\"E\":1788563048005,\"st\":1}}"}
{"receive_ns":1788563047941880000,"stream":"btcusdt@bookTicker","event_type":"bookTicker","event_time_ms":1788563048008,"raw_json":"{\"stream\":\"btcusdt@bookTicker\",\"data\":{\"e\":\"bookTicker\",\"u\":11478212910648,\"s\":\"BTCUSDT\",\"ps\":\"BTCUSDT\",\"b\":\"79598.10\",\"B\":\"11.003\",\"a\":\"79598.20\",\"A\":\"3.179\",\"T\":1788563048008,\"E\":1788563048008,\"st\":1}}"}
{"receive_ns":1788563047951580000,"stream":"btcusdt@depth@100ms","event_type":"depthUpdate","event_time_ms":1788563048009,"raw_json":"{\"stream\":\"btcusdt@depth@100ms\",\"data\":{\"e\":\"depthUpdate\",\"E\":1788563048009,\"T\":1788563048008,\"s\":\"BTCUSDT\",\"ps\":\"BTCUSDT\",\"U\":11478212904930,\"u\":11478212910676,\"pu\":11478212904909,\"b\":[[\"29198.10\",\"0.504\"],[\"29298.10\",\"1.596\"],[\"63679.00\",\"0.002\"],[\"71638.20\",\"0.002\"],[\"76414.10\",\"0.000\"],[\"78802.10\",\"7.745\"],[\"79297.00\",\"0.000\"],[\"79344.70\",\"0.001\"],[\"79401.10\",\"0.232\"],[\"79494.60\",\"1.933\"],[\"79507.10\",\"0.000\"],[\"79585.30\",\"0.080\"]],\"a\":[[\"79598.20\",\"3.179\"],[\"79601.10\",\"0.029\"],[\"79690.80\",\"0.211\"],[\"79735.50\",\"0.526\"],[\"79739.00\",\"0.092\"],[\"79962.40\",\"1.273\"],[\"79996.20\",\"2.100\"],[\"80394.20\",\"7.961\"],[\"80468.00\",\"1.733\"],[\"80687.30\",\"1.857\"],[\"87558.10\",\"0.000\"]],\"st\":1}}"}
{"receive_ns":1788563047994247000,"stream":"btcusdt@bookTicker","event_type":"bookTicker","event_time_ms":1788563048057,"raw_json":"{\"stream\":\"btcusdt@bookTicker\",\"data\":{\"e\":\"bookTicker\",\"u\":11478212913216,\"s\":\"BTCUSDT\",\"ps\":\"BTCUSDT\",\"b\":\"79598.10\",\"B\":\"10.964\",\"a\":\"79598.20\",\"A\":\"3.179\",\"T\":1788563048057,\"E\":1788563048057,\"st\":1}}"}
{"receive_ns":1788563047998483000,"stream":"btcusdt@bookTicker","event_type":"bookTicker","event_time_ms":1788563048063,"raw_json":"{\"stream\":\"btcusdt@bookTicker\",\"data\":{\"e\":\"bookTicker\",\"u\":11478212913593,\"s\":\"BTCUSDT\",\"ps\":\"BTCUSDT\",\"b\":\"79598.10\",\"B\":\"11.005\",\"a\":\"79598.20\",\"A\":\"3.179\",\"T\":1788563048062,\"E\":1788563048063,\"st\":1}}"}
{"receive_ns":1788563048047073000,"stream":"btcusdt@depth@100ms","event_type":"depthUpdate","event_time_ms":1788563048111,"raw_json":"{\"stream\":\"btcusdt@depth@100ms\",\"data\":{\"e\":\"depthUpdate\",\"E\":1788563048111,\"T\":1788563048110,\"s\":\"BTCUSDT\",\"ps\":\"BTCUSDT\",\"U\":11478212910709,\"u\":11478212916841,\"pu\":11478212910676,\"b\":[[\"1000.00\",\"25.004\"],[\"29198.10\",\"0.686\"],[\"29298.10\",\"1.414\"],[\"63679.00\",\"0.002\"],[\"71638.20\",\"0.002\"],[\"76414.10\",\"0.002\"],[\"78578.00\",\"0.004\"],[\"78591.50\",\"0.013\"],[\"78594.00\",\"0.007\"],[\"78600.30\",\"0.000\"],[\"78609.90\",\"0.004\"],[\"78618.80\",\"0.000\"],[\"78802.10\",\"7.745\"],[\"79200.10\",\"1.410\"],[\"79401.10\",\"0.734\"],[\"79404.00\",\"1.215\"],[\"79480.10\",\"1.544\"],[\"79492.60\",\"1.006\"],[\"79494.60\",\"1.431\"],[\"79507.10\",\"3.429\"],[\"79507.20\",\"1.360\"],[\"79572.50\",\"0.715\"],[\"79573.50\",\"0.000\"],[\"79574.90\",\"0.439\"],[\"79583.80\",\"0.000\"],[\"79598.10\",\"11.005\"]],\"a\":[[\"79601.00\",\"0.008\"],[\"79601.10\",\"0.003\"],[\"79601.30\",\"0.026\"],[\"79601.40\",\"0.000\"],[\"79601.60\",\"0.000\"],[\"79601.70\",\"0.001\"],[\"79601.80\",\"0.001\"],[\"79602.20\",\"0.029\"],[\"79602.30\",\"0.026\"],[\"79602.40\",\"0.027\"],[\"79603.20\",\"0.004\"],[\"79603.30\",\"0.000\"],[\"79603.40\",\"0.002\"],[\"79612.40\",\"0.000\"],[\"79613.70\",\"0.372\"],[\"79614.50\",\"0.252\"],[\"79660.80\",\"0.516\"],[\"79690.50\",\"3.999\"],[\"79735.50\",\"0.275\"],[\"79738.70\",\"0.000\"],[\"79739.00\",\"0.092\"],[\"79821.20\",\"8.212\"],[\"79821.30\",\"0.000\"],[\"79962.40\",\"1.273\"],[\"79996.20\",\"2.100\"],[\"80235.00\",\"1.749\"],[\"80394.20\",\"7.961\"],[\"81403.50\",\"0.000\"]],\"st\":1}}"}
{"receive_ns":1788563048071024000,"stream":"btcusdt@bookTicker","event_type":"bookTicker","event_time_ms":1788563048135,"raw_json":"{\"stream\":\"btcusdt@bookTicker\",\"data\":{\"e\":\"bookTicker\",\"u\":11478212918437,\"s\":\"BTCUSDT\",\"ps\":\"BTCUSDT\",\"b\":\"79598.10\",\"B\":\"10.969\",\"a\":\"79598.20\",\"A\":\"3.179\",\"T\":1788563048135,\"E\":1788563048135,\"st\":1}}"}
{"receive_ns":1788563048071219000,"stream":"btcusdt@trade","event_type":"trade","event_time_ms":1788563048135,"raw_json":"{\"stream\":\"btcusdt@trade\",\"data\":{\"e\":\"trade\",\"E\":1788563048135,\"T\":1788563048135,\"s\":\"BTCUSDT\",\"t\":8054081718,\"p\":\"79598.10\",\"q\":\"0.001\",\"X\":\"MARKET\",\"m\":true,\"st\":1}}"}
{"receive_ns":1788563048071358000,"stream":"btcusdt@trade","event_type":"trade","event_time_ms":1788563048135,"raw_json":"{\"stream\":\"btcusdt@trade\",\"data\":{\"e\":\"trade\",\"E\":1788563048135,\"T\":1788563048135,\"s\":\"BTCUSDT\",\"t\":8054081719,\"p\":\"79598.10\",\"q\":\"0.035\",\"X\":\"MARKET\",\"m\":true,\"st\":1}}"}
{"receive_ns":1788563048071569000,"stream":"btcusdt@bookTicker","event_type":"bookTicker","event_time_ms":1788563048137,"raw_json":"{\"stream\":\"btcusdt@bookTicker\",\"data\":{\"e\":\"bookTicker\",\"u\":11478212918637,\"s\":\"BTCUSDT\",\"ps\":\"BTCUSDT\",\"b\":\"79598.10\",\"B\":\"10.977\",\"a\":\"79598.20\",\"A\":\"3.179\",\"T\":1788563048137,\"E\":1788563048137,\"st\":1}}"}
{"receive_ns":1788563048071882000,"stream":"btcusdt@bookTicker","event_type":"bookTicker","event_time_ms":1788563048137,"raw_json":"{\"stream\":\"btcusdt@bookTicker\",\"data\":{\"e\":\"bookTicker\",\"u\":11478212918687,\"s\":\"BTCUSDT\",\"ps\":\"BTCUSDT\",\"b\":\"79598.10\",\"B\":\"10.977\",\"a\":\"79598.20\",\"A\":\"3.172\",\"T\":1788563048137,\"E\":1788563048137,\"st\":1}}"}
{"receive_ns":1788563048072154000,"stream":"btcusdt@bookTicker","event_type":"bookTicker","event_time_ms":1788563048138,"raw_json":"{\"stream\":\"btcusdt@bookTicker\",\"data\":{\"e\":\"bookTicker\",\"u\":11478212918715,\"s\":\"BTCUSDT\",\"ps\":\"BTCUSDT\",\"b\":\"79598.10\",\"B\":\"10.969\",\"a\":\"79598.20\",\"A\":\"3.172\",\"T\":1788563048137,\"E\":1788563048138,\"st\":1}}"}
{"receive_ns":1788563048148650000,"stream":"btcusdt@depth@100ms","event_type":"depthUpdate","event_time_ms":1788563048213,"raw_json":"{\"stream\":\"btcusdt@depth@100ms\",\"data\":{\"e\":\"depthUpdate\",\"E\":1788563048213,\"T\":1788563048211,\"s\":\"BTCUSDT\",\"ps\":\"BTCUSDT\",\"U\":11478212916979,\"u\":11478212923843,\"pu\":11478212916841,\"b\":[[\"29198.10\",\"0.861\"],[\"29298.10\",\"1.239\"],[\"71638.20\",\"0.002\"],[\"78446.10\",\"3.307\"],[\"78802.10\",\"7.745\"],[\"79401.10\",\"0.734\"],[\"79418.40\",\"3.141\"],[\"79418.70\",\"0.915\"],[\"79451.90\",\"2.409\"],[\"79453.30\",\"0.001\"],[\"79453.80\",\"1.895\"],[\"79454.00\",\"0.002\"],[\"79472.70\",\"1.647\"],[\"79494.60\",\"1.331\"],[\"79511.60\",\"0.867\"],[\"79511.80\",\"0.015\"],[\"79522.70\",\"0.009\"],[\"79573.20\",\"0.440\"],[\"79574.90\",\"0.000\"],[\"79598.00\",\"0.035\"],[\"79598.10\",\"10.969\"]],\"a\":[[\"79598.20\",\"3.172\"],[\"79600.40\",\"0.293\"],[\"79600.60\",\"0.076\"],[\"79601.00\",\"0.034\"],[\"79659.90\",\"0.251\"],[\"79675.30\",\"0.004\"],[\"79675.40\",\"0.650\"],[\"79684.90\",\"0.030\"],[\"79686.80\",\"0.038\"],[\"79687.00\",\"0.176\"],[\"79698.90\",\"0.002\"],[\"79699.00\",\"0.109\"],[\"79722.20\",\"1.885\"],[\"79722.30\",\"0.001\"],[\"79735.50\",\"0.024\"],[\"79739.20\",\"0.000\"],[\"79745.00\",\"3.217\"],[\"79745.10\",\"0.000\"],[\"79962.40\",\"1.273\"],[\"79996.20\",\"2.100\"],[\"80394.20\",\"7.961\"],[\"80465.80\",\"2.614\"],[\"80468.00\",\"1.175\"],[\"81190.10\",\"0.014\"]],\"st\":1}}"}
{"receive_ns":1788563048168250000,"stream":"btcusdt@bookTicker","event_type":"bookTicker","event_time_ms":1788563048231,"raw_json":"{\"stream\":\"btcusdt@bookTicker\",\"data\":{\"e\":\"bookTicker\",\"u\":11478212925353,\"s\":\"BTCUSDT\",\"ps\":\"BTCUSDT\",\"b\":\"79598.10\",\"B\":\"10.969\",\"a\":\"79598.20\",\"A\":\"3.169\",\"T\":1788563048231,\"E\":1788563048231,\"st\":1}}"}
{"receive_ns":1788563048247640000,"stream":"btcusdt@bookTicker","event_type":"bookTicker","event_time_ms":1788563048311,"raw_json":"{\"stream\":\"btcusdt@bookTicker\",\"data\":{\"e\":\"bookTicker\",\"u\":11478212931465,\"s\":\"BTCUSDT\",\"ps\":\"BTCUSDT\",\"b\":\"79598.10\",\"B\":\"10.924\",\"a\":\"79598.20\",\"A\":\"3.169\",\"T\":1788563048311,\"E\":1788563048311,\"st\":1}}"}
{"receive_ns":1788563048250188000,"stream":"btcusdt@bookTicker","event_type":"bookTicker","event_time_ms":1788563048314,"raw_json":"{\"stream\":\"btcusdt@bookTicker\",\"data\":{\"e\":\"bookTicker\",\"u\":11478212931716,\"s\":\"BTCUSDT\",\"ps\":\"BTCUSDT\",\"b\":\"79598.10\",\"B\":\"10.971\",\"a\":\"79598.20\",\"A\":\"3.169\",\"T\":1788563048314,\"E\":1788563048314,\"st\":1}}"}
{"receive_ns":1788563048250655000,"stream":"btcusdt@depth@100ms","event_type":"depthUpdate","event_time_ms":1788563048315,"raw_json":"{\"stream\":\"btcusdt@depth@100ms\",\"data\":{\"e\":\"depthUpdate\",\"E\":1788563048315,\"T\":1788563048314,\"s\":\"BTCUSDT\",\"ps\":\"BTCUSDT\",\"U\":11478212924094,\"u\":11478212931716,\"pu\":11478212923843,\"b\":[[\"29198.10\",\"1.043\"],[\"29298.10\",\"1.057\"],[\"71638.20\",\"0.002\"],[\"76414.10\",\"0.000\"],[\"78721.90\",\"1.077\"],[\"78802.10\",\"7.745\"],[\"79200.10\",\"1.410\"],[\"79401.10\",\"0.232\"],[\"79492.60\",\"0.001\"],[\"79578.90\",\"0.003\"],[\"79598.10\",\"10.971\"]],\"a\":[[\"79598.20\",\"3.169\"],[\"79601.00\",\"0.008\"],[\"79601.30\",\"0.000\"],[\"79601.60\",\"0.000\"],[\"79659.90\",\"0.502\"],[\"79698.90\",\"0.001\"],[\"79699.10\",\"2.494\"],[\"79739.10\",\"0.002\"],[\"79739.20\",\"0.000\"],[\"79962.40\",\"0.854\"],[\"79996.20\",\"1.699\"],[\"80389.60\",\"8.110\"],[\"80394.20\",\"7.961\"]],\"st\":1}}"}
{"receive_ns":1788563048352883000,"stream":"btcusdt@depth@100ms","event_type":"depthUpdate","event_time_ms":1788563048417,"raw_json":"{\"stream\":\"btcusdt@depth@100ms\",\"data\":{\"e\":\"depthUpdate\",\"E\":1788563048417,\"T\":1788563048413,\"s\":\"BTCUSDT\",\"ps\":\"BTCUSDT\",\"U\":11478212931822,\"u\":11478212939505,\"pu\":11478212931716,\"b\":[[\"1000.00\",\"25.004\"],[\"29198.10\",\"1.218\"],[\"29298.10\",\"0.882\"],[\"63678.00\",\"0.002\"],[\"71638.20\",\"0.002\"],[\"76414.10\",\"0.002\"],[\"78802.10\",\"7.745\"],[\"79180.90\",\"0.000\"],[\"79195.60\",\"0.756\"],[\"79200.10\",\"1.400\"],[\"79401.10\",\"0.000\"],[\"79404.00\",\"1.215\"],[\"79472.70\",\"2.049\"],[\"79492.60\",\"1.006\"],[\"79494.60\",\"0.000\"],[\"79573.20\",\"0.001\"],[\"79574.90\",\"0.439\"],[\"79584.20\",\"0.008\"],[\"79584.70\",\"0.063\"],[\"79586.30\",\"0.010\"],[\"79586.90\",\"0.002\"],[\"79588.40\",\"0.104\"]],\"a\":[[\"79602.00\",\"0.077\"],[\"79602.10\",\"0.028\"],[\"79602.20\",\"0.003\"],[\"79602.30\",\"0.000\"],[\"79602.40\",\"0.001\"],[\"79602.50\",\"0.000\"],[\"79602.70\",\"0.003\"],[\"79602.80\",\"0.000\"],[\"79602.90\",\"0.001\"],[\"79603.10\",\"0.000\"],[\"79603.30\",\"0.026\"],[\"79603.50\",\"0.002\"],[\"79604.00\",\"2.900\"],[\"79604.20\",\"1.025\"],[\"79604.30\",\"0.031\"],[\"79604.40\",\"0.028\"],[\"79604.50\",\"0.033\"],[\"79604.60\",\"0.029\"],[\"79604.70\",\"0.026\"],[\"79604.90\",\"0.460\"],[\"79605.00\",\"0.029\"],[\"79605.10\",\"0.002\"],[\"79606.10\",\"0.001\"],[\"79607.70\",\"0.006\"],[\"79608.30\",\"0.005\"],[\"79608.40\",\"0.648\"],[\"79609.50\",\"0.009\"],[\"79610.10\",\"0.001\"],[\"79610.20\",\"0.002\"],[\"79610.60\",\"0.380\"],[\"79638.00\",\"0.070\"],[\"79659.90\",\"0.251\"],[\"79660.80\",\"0.516\"],[\"79739.20\",\"0.000\"],[\"79739.50\",\"0.000\"],[\"79962.40\",\"0.419\"],[\"79996.20\",\"2.025\"],[\"80394.20\",\"7.961\"],[\"80465.80\",\"3.172\"]],\"st\":1}}"}
{"receive_ns":1788563048381194000,"stream":"btcusdt@bookTicker","event_type":"bookTicker","event_time_ms":1788563048444,"raw_json":"{\"stream\":\"btcusdt@bookTicker\",\"data\":{\"e\":\"bookTicker\",\"u\":11478212943179,\"s\":\"BTCUSDT\",\"ps\":\"BTCUSDT\",\"b\":\"79598.10\",\"B\":\"10.917\",\"a\":\"79598.20\",\"A\":\"3.169\",\"T\":1788563048444,\"E\":1788563048444,\"st\":1}}"}
{"receive_ns":1788563048382899000,"stream":"btcusdt@bookTicker","event_type":"bookTicker","event_time_ms":1788563048447,"raw_json":"{\"stream\":\"btcusdt@bookTicker\",\"data\":{\"e\":\"bookTicker\",\"u\":11478212943333,\"s\":\"BTCUSDT\",\"ps\":\"BTCUSDT\",\"b\":\"79598.10\",\"B\":\"10.980\",\"a\":\"79598.20\",\"A\":\"3.169\",\"T\":1788563048447,\"E\":1788563048447,\"st\":1}}"}
{"receive_ns":1788563048449946000,"stream":"btcusdt@bookTicker","event_type":"bookTicker","event_time_ms":1788563048513,"raw_json":"{\"stream\":\"btcusdt@bookTicker\",\"data\":{\"e\":\"bookTicker\",\"u\":11478212947940,\"s\":\"BTCUSDT\",\"ps\":\"BTCUSDT\",\"b\":\"79598.10\",\"B\":\"10.980\",\"a\":\"79598.20\",\"A\":\"3.170\",\"T\":1788563048513,\"E\":1788563048513,\"st\":1}}"}
{"receive_ns":1788563048455503000,"stream":"btcusdt@depth@100ms","event_type":"depthUpdate","event_time_ms":1788563048519,"raw_json":"{\"stream\":\"btcusdt@depth@100ms\",\"data\":{\"e\":\"depthUpdate\",\"E\":1788563048519,\"T\":1788563048518,\"s\":\"BTCUSDT\",\"ps\":\"BTCUSDT\",\"U\":11478212940462,\"u\":11478212948309,\"pu\":11478212939505,\"b\":[[\"29198.10\",\"1.400\"],[\"29298.10\",\"0.700\"],[\"71638.20\",\"0.002\"],[\"76414.10\",\"0.000\"],[\"78802.10\",\"7.745\"],[\"79181.80\",\"0.008\"],[\"79195.90\",\"0.301\"],[\"79200.10\",\"1.260\"],[\"79401.10\",\"0.332\"],[\"79494.60\",\"1.331\"],[\"79542.30\",\"0.002\"],[\"79558.30\",\"0.078\"],[\"79573.20\",\"0.440\"],[\"79574.90\",\"0.000\"],[\"79598.10\",\"10.980\"]],\"a\":[[\"79598.20\",\"3.170\"],[\"79603.60\",\"0.253\"],[\"79638.00\",\"0.070\"],[\"79659.90\",\"0.251\"],[\"79660.80\",\"0.316\"],[\"79664.20\",\"1.486\"],[\"79669.90\",\"0.000\"],[\"79739.50\",\"0.000\"],[\"79739.80\",\"0.000\"],[\"79740.00\",\"0.625\"],[\"79740.10\",\"0.001\"],[\"79961.60\",\"0.287\"],[\"79962.40\",\"1.273\"],[\"79996.20\",\"2.224\"],[\"80394.20\",\"7.961\"],[\"80568.10\",\"3.407\"],[\"80633.00\",\"3.101\"]],\"st\":1}}"}
{"receive_ns":1788563048550378000,"stream":"btcusdt@bookTicker","event_type":"bookTicker","event_time_ms":1788563048612,"raw_json":"{\"stream\":\"btcusdt@bookTicker\",\"data\":{\"e\":\"bookTicker\",\"u\":11478212955193,\"s\":\"BTCUSDT\",\"ps\":\"BTCUSDT\",\"b\":\"79598.10\",\"B\":\"10.969\",\"a\":\"79598.20\",\"A\":\"3.170\",\"T\":1788563048612,\"E\":1788563048612,\"st\":1}}"}
{"receive_ns":1788563048555551000,"stream":"btcusdt@depth@100ms","event_type":"depthUpdate","event_time_ms":1788563048621,"raw_json":"{\"stream\":\"btcusdt@depth@100ms\",\"data\":{\"e\":\"depthUpdate\",\"E\":1788563048621,\"T\":1788563048618,\"s\":\"BTCUSDT\",\"ps\":\"BTCUSDT\",\"U\":11478212948416,\"u\":11478212955747,\"pu\":11478212948309,\"b\":[[\"1000.00\",\"25.004\"],[\"29198.10\",\"1.575\"],[\"29298.10\",\"0.525\"],[\"63678.00\",\"0.002\"],[\"63679.00\",\"0.002\"],[\"71638.20\",\"0.002\"],[\"76414.10\",\"0.002\"],[\"78006.20\",\"0.015\"],[\"78583.70\",\"3.202\"],[\"78802.10\",\"7.745\"],[\"79200.10\",\"3.291\"],[\"79401.10\",\"0.834\"],[\"79404.00\",\"1.215\"],[\"79472.70\",\"2.552\"],[\"79492.60\",\"0.001\"],[\"79496.20\",\"0.086\"],[\"79573.20\",\"0.001\"],[\"79574.90\",\"0.439\"],[\"79598.10\",\"10.969\"]],\"a\":[[\"79602.00\",\"0.077\"],[\"79602.10\",\"0.002\"],[\"79602.20\",\"0.254\"],[\"79603.10\",\"0.226\"],[\"79604.90\",\"0.434\"],[\"79739.90\",\"0.000\"],[\"79740.00\",\"0.500\"],[\"79740.10\",\"0.001\"],[\"79962.40\",\"1.273\"],[\"79996.20\",\"2.224\"],[\"80195.20\",\"3.115\"],[\"80394.20\",\"7.962\"]],\"st\":1}}"}
{"receive_ns":1788563048656798000,"stream":"btcusdt@bookTicker","event_type":"bookTicker","event_time_ms":1788563048720,"raw_json":"{\"stream\":\"btcusdt@bookTicker\",\"data\":{\"e\":\"bookTicker\",\"u\":11478212963669,\"s\":\"BTCUSDT\",\"ps\":\"BTCUSDT\",\"b\":\"79598.10\",\"B\":\"10.969\",\"a\":\"79598.20\",\"A\":\"3.162\",\"T\":1788563048720,\"E\":1788563048720,\"st\":1}}"}
{"receive_ns":1788563048657017000,"stream":"btcusdt@trade","event_type":"trade","event_time_ms":1788563048720,"raw_json":"{\"stream\":\"btcusdt@trade\",\"data\":{\"e\":\"trade\",\"E\":1788563048720,\"T\":1788563048720,\"s\":\"BTCUSDT\",\"t\":8054081720,\"p\":\"79598.20\",\"q\":\"0.008\",\"X\":\"MARKET\",\"m\":false,\"st\":1}}"}
{"receive_ns":1788563048657186000,"stream":"btcusdt@bookTicker","event_type":"bookTicker","event_time_ms":1788563048722,"raw_json":"{\"stream\":\"btcusdt@bookTicker\",\"data\":{\"e\":\"bookTicker\",\"u\":11478212963812,\"s\":\"BTCUSDT\",\"ps\":\"BTCUSDT\",\"b\":\"79598.10\",\"B\":\"10.977\",\"a\":\"79598.20\",\"A\":\"3.162\",\"T\":1788563048721,\"E\":1788563048722,\"st\":1}}"}
{"receive_ns":1788563048657562000,"stream":"btcusdt@depth@100ms","event_type":"depthUpdate","event_time_ms":1788563048723,"raw_json":"{\"stream\":\"btcusdt@depth@100ms\",\"data\":{\"e\":\"depthUpdate\",\"E\":1788563048723,\"T\":1788563048722,\"s\":\"BTCUSDT\",\"ps\":\"BTCUSDT\",\"U\":11478212955953,\"u\":11478212963957,\"pu\":11478212955747,\"b\":[[\"1000.00\",\"25.004\"],[\"29198.10\",\"1.757\"],[\"29298.10\",\"0.343\"],[\"63678.50\",\"0.000\"],[\"71638.20\",\"0.002\"],[\"78802.10\",\"7.745\"],[\"79200.10\",\"3.616\"],[\"79401.10\",\"0.834\"],[\"79492.60\",\"1.332\"],[\"79494.60\",\"0.000\"],[\"79564.80\",\"0.002\"],[\"79565.90\",\"0.032\"],[\"79566.00\",\"0.001\"],[\"79566.40\",\"0.009\"],[\"79567.00\",\"0.454\"],[\"79573.20\",\"0.440\"],[\"79574.90\",\"0.000\"],[\"79598.00\",\"0.111\"],[\"79598.10\",\"10.969\"]],\"a\":[[\"79598.20\",\"3.162\"],[\"79600.60\",\"0.000\"],[\"79602.20\",\"0.003\"],[\"79602.90\",\"0.001\"],[\"79603.10\",\"0.200\"],[\"79603.30\",\"0.000\"],[\"79603.60\",\"0.279\"],[\"79603.70\",\"0.029\"],[\"79603.90\",\"0.076\"],[\"79604.90\",\"0.434\"],[\"79614.70\",\"0.001\"],[\"79615.70\",\"0.002\"],[\"79616.90\",\"0.456\"],[\"79659.90\",\"0.251\"],[\"79961.60\",\"0.183\"],[\"79962.40\",\"1.273\"],[\"79996.20\",\"2.224\"],[\"80394.20\",\"7.964\"]],\"st\":1}}"}
{"receive_ns":1788563048657753000,"stream":"btcusdt@bookTicker","event_type":"bookTicker","event_time_ms":1788563048722,"raw_json":"{\"stream\":\"btcusdt@bookTicker\",\"data\":{\"e\":\"bookTicker\",\"u\":11478212963945,\"s\":\"BTCUSDT\",\"ps\":\"BTCUSDT\",\"b\":\"79598.10\",\"B\":\"10.969\",\"a\":\"79598.20\",\"A\":\"3.162\",\"T\":1788563048722,\"E\":1788563048722,\"st\":1}}"}
{"receive_ns":1788563048704882000,"stream":"btcusdt@bookTicker","event_type":"bookTicker","event_time_ms":1788563048760,"raw_json":"{\"stream\":\"btcusdt@bookTicker\",\"data\":{\"e\":\"bookTicker\",\"u\":11478212966876,\"s\":\"BTCUSDT\",\"ps\":\"BTCUSDT\",\"b\":\"79598.10\",\"B\":\"10.969\",\"a\":\"79598.20\",\"A\":\"3.169\",\"T\":1788563048760,\"E\":1788563048760,\"st\":1}}"}
{"receive_ns":1788563048762596000,"stream":"btcusdt@depth@100ms","event_type":"depthUpdate","event_time_ms":1788563048825,"raw_json":"{\"stream\":\"btcusdt@depth@100ms\",\"data\":{\"e\":\"depthUpdate\",\"E\":1788563048825,\"T\":1788563048824,\"s\":\"BTCUSDT\",\"ps\":\"BTCUSDT\",\"U\":11478212963964,\"u\":11478212972831,\"pu\":11478212963957,\"b\":[[\"29098.10\",\"0.063\"],[\"29198.10\",\"1.806\"],[\"29298.10\",\"0.231\"],[\"71638.20\",\"0.002\"],[\"76414.10\",\"0.000\"],[\"78493.90\",\"1.492\"],[\"78802.10\",\"7.747\"],[\"79200.10\",\"3.475\"],[\"79463.00\",\"0.001\"],[\"79463.10\",\"0.003\"],[\"79574.40\",\"0.048\"]],\"a\":[[\"79598.20\",\"3.169\"],[\"79598.50\",\"0.006\"],[\"79602.70\",\"0.003\"],[\"79603.10\",\"0.000\"],[\"79604.70\",\"0.000\"],[\"79614.30\",\"0.359\"],[\"79637.90\",\"0.019\"],[\"79735.20\",\"0.012\"],[\"79740.10\",\"0.001\"],[\"79821.10\",\"0.000\"],[\"79821.20\",\"8.215\"],[\"80190.70\",\"0.623\"],[\"80394.20\",\"7.962\"]],\"st\":1}}"}
{"receive_ns":1788563048779798000,"stream":"btcusdt@bookTicker","event_type":"bookTicker","event_time_ms":1788563048844,"raw_json":"{\"stream\":\"btcusdt@bookTicker\",\"data\":{\"e\":\"bookTicker\",\"u\":11478212974510,\"s\":\"BTCUSDT\",\"ps\":\"BTCUSDT\",\"b\":\"79598.10\",\"B\":\"10.969\",\"a\":\"79598.20\",\"A\":\"3.168\",\"T\":1788563048843,\"E\":1788563048844,\"st\":1}}"}
{"receive_ns":1788563048794165000,"stream":"btcusdt@bookTicker","event_type":"bookTicker","event_time_ms":1788563048857,"raw_json":"{\"stream\":\"btcusdt@bookTicker\",\"data\":{\"e\":\"bookTicker\",\"u\":11478212975570,\"s\":\"BTCUSDT\",\"ps\":\"BTCUSDT\",\"b\":\"79598.10\",\"B\":\"10.971\",\"a\":\"79598.20\",\"A\":\"3.168\",\"T\":1788563048857,\"E\":1788563048857,\"st\":1}}"}
{"receive_ns":1788563048862021000,"stream":"btcusdt@depth@100ms","event_type":"depthUpdate","event_time_ms":1788563048927,"raw_json":"{\"stream\":\"btcusdt@depth@100ms\",\"data\":{\"e\":\"depthUpdate\",\"E\":1788563048927,\"T\":1788563048925,\"s\":\"BTCUSDT\",\"ps\":\"BTCUSDT\",\"U\":11478212972973,\"u\":11478212980478,\"pu\":11478212972831,\"b\":[[\"1000.00\",\"25.004\"],[\"29098.10\",\"0.119\"],[\"29198.10\",\"1.876\"],[\"29298.10\",\"0.105\"],[\"63679.00\",\"0.002\"],[\"71638.20\",\"0.002\"],[\"71675.00\",\"0.002\"],[\"76414.10\",\"0.002\"],[\"78006.20\",\"0.012\"],[\"78603.10\",\"3.370\"],[\"78802.10\",\"7.745\"],[\"79200.10\",\"3.616\"],[\"79401.10\",\"0.232\"],[\"79404.00\",\"1.014\"],[\"79472.70\",\"1.547\"],[\"79473.60\",\"0.602\"],[\"79473.70\",\"0.000\"],[\"79485.60\",\"0.201\"],[\"79492.60\",\"1.432\"],[\"79494.60\",\"1.507\"],[\"79574.40\",\"0.050\"],[\"79598.10\",\"10.971\"]],\"a\":[[\"79598.20\",\"3.168\"],[\"79614.30\",\"0.361\"],[\"79659.90\",\"0.000\"],[\"79722.30\",\"0.386\"],[\"79722.60\",\"0.001\"],[\"79735.50\",\"0.526\"],[\"79736.40\",\"0.211\"],[\"79962.40\",\"1.273\"],[\"79996.20\",\"2.223\"],[\"80235.00\",\"1.998\"],[\"80394.20\",\"7.962\"],[\"80553.40\",\"18.091\"]],\"st\":1}}"}
{"receive_ns":1788563048876402000,"stream":"btcusdt@bookTicker","event_type":"bookTicker","event_time_ms":1788563048932,"raw_json":"{\"stream\":\"btcusdt@bookTicker\",\"data\":{\"e\":\"bookTicker\",\"u\":11478212980999,\"s\":\"BTCUSDT\",\"ps\":\"BTCUSDT\",\"b\":\"79598.10\",\"B\":\"10.971\",\"a\":\"79598.20\",\"A\":\"3.139\",\"T\":1788563048932,\"E\":1788563048932,\"st\":1}}"}
{"receive_ns":1788563048876617000,"stream":"btcusdt@trade","event_type":"trade","event_time_ms":1788563048932,"raw_json":"{\"stream\":\"btcusdt@trade\",\"data\":{\"e\":\"trade\",\"E\":1788563048932,\"T\":1788563048932,\"s\":\"BTCUSDT\",\"t\":8054081721,\"p\":\"79598.20\",\"q\":\"0.029\",\"X\":\"MARKET\",\"m\":false,\"st\":1}}"}
{"receive_ns":1788563048876813000,"stream":"btcusdt@bookTicker","event_type":"bookTicker","event_time_ms":1788563048934,"raw_json":"{\"stream\":\"btcusdt@bookTicker\",\"data\":{\"e\":\"bookTicker\",\"u\":11478212981158,\"s\":\"BTCUSDT\",\"ps\":\"BTCUSDT\",\"b\":\"79598.10\",\"B\":\"10.979\",\"a\":\"79598.20\",\"A\":\"3.139\",\"T\":1788563048934,\"E\":1788563048934,\"st\":1}}"}
{"receive_ns":1788563048877043000,"stream":"btcusdt@bookTicker","event_type":"bookTicker","event_time_ms":1788563048935,"raw_json":"{\"stream\":\"btcusdt@bookTicker\",\"data\":{\"e\":\"bookTicker\",\"u\":11478212981265,\"s\":\"BTCUSDT\",\"ps\":\"BTCUSDT\",\"b\":\"79598.10\",\"B\":\"10.971\",\"a\":\"79598.20\",\"A\":\"3.139\",\"T\":1788563048934,\"E\":1788563048935,\"st\":1}}"}
{"receive_ns":1788563048895461000,"stream":"btcusdt@bookTicker","event_type":"bookTicker","event_time_ms":1788563048960,"raw_json":"{\"stream\":\"btcusdt@bookTicker\",\"data\":{\"e\":\"bookTicker\",\"u\":11478212984045,\"s\":\"BTCUSDT\",\"ps\":\"BTCUSDT\",\"b\":\"79598.10\",\"B\":\"10.979\",\"a\":\"79598.20\",\"A\":\"3.139\",\"T\":1788563048959,\"E\":1788563048960,\"st\":1}}"}
{"receive_ns":1788563048895775000,"stream":"btcusdt@bookTicker","event_type":"bookTicker","event_time_ms":1788563048960,"raw_json":"{\"stream\":\"btcusdt@bookTicker\",\"data\":{\"e\":\"bookTicker\",\"u\":11478212984105,\"s\":\"BTCUSDT\",\"ps\":\"BTCUSDT\",\"b\":\"79598.10\",\"B\":\"10.971\",\"a\":\"79598.20\",\"A\":\"3.139\",\"T\":1788563048960,\"E\":1788563048960,\"st\":1}}"}
{"receive_ns":1788563048966329000,"stream":"btcusdt@depth@100ms","event_type":"depthUpdate","event_time_ms":1788563049029,"raw_json":"{\"stream\":\"btcusdt@depth@100ms\",\"data\":{\"e\":\"depthUpdate\",\"E\":1788563049029,\"T\":1788563049025,\"s\":\"BTCUSDT\",\"ps\":\"BTCUSDT\",\"U\":11478212980643,\"u\":11478212988620,\"pu\":11478212980478,\"b\":[[\"1000.00\",\"25.004\"],[\"29098.10\",\"0.196\"],[\"29198.10\",\"1.897\"],[\"29298.10\",\"0.007\"],[\"63679.00\",\"0.002\"],[\"71638.20\",\"0.002\"],[\"76414.10\",\"0.000\"],[\"78578.60\",\"8.816\"],[\"78583.70\",\"2.986\"],[\"78594.00\",\"0.002\"],[\"78596.40\",\"0.004\"],[\"78802.10\",\"7.745\"],[\"79200.10\",\"3.743\"],[\"79565.10\",\"0.453\"],[\"79567.00\",\"0.002\"],[\"79578.90\",\"0.031\"],[\"79598.10\",\"10.971\"]],\"a\":[[\"79598.20\",\"3.139\"],[\"79599.40\",\"0.000\"],[\"79600.10\",\"0.253\"],[\"79603.60\",\"0.001\"],[\"79603.70\",\"0.029\"],[\"79603.90\",\"0.050\"],[\"79604.00\",\"2.874\"],[\"79604.20\",\"0.999\"],[\"79604.30\",\"0.005\"],[\"79604.40\",\"0.002\"],[\"79604.70\",\"0.026\"],[\"79604.90\",\"0.460\"],[\"79605.00\",\"0.055\"],[\"79605.10\",\"0.028\"],[\"79605.20\",\"0.103\"],[\"79605.30\",\"0.026\"],[\"79608.20\",\"0.080\"],[\"79650.00\",\"10.195\"],[\"79650.10\",\"0.003\"],[\"79733.90\",\"0.188\"],[\"79736.40\",\"0.011\"],[\"79740.10\",\"0.001\"],[\"79740.50\",\"0.000\"],[\"80372.50\",\"0.030\"],[\"80394.20\",\"9.204\"],[\"80514.30\",\"16.272\"],[\"81190.10\",\"0.017\"]],\"st\":1}}"}
{"receive_ns":1788563049052682000,"stream":"btcusdt@bookTicker","event_type":"bookTicker","event_time_ms":1788563049116,"raw_json":"{\"stream\":\"btcusdt@bookTicker\",\"data\":{\"e\":\"bookTicker\",\"u\":11478212996261,\"s\":\"BTCUSDT\",\"ps\":\"BTCUSDT\",\"b\":\"79598.10\",\"B\":\"10.982\",\"a\":\"79598.20\",\"A\":\"3.139\",\"T\":1788563049116,\"E\":1788563049116,\"st\":1}}"}
{"receive_ns":1788563049066306000,"stream":"btcusdt@depth@100ms","event_type":"depthUpdate","event_time_ms":1788563049131,"raw_json":"{\"stream\":\"btcusdt@depth@100ms\",\"data\":{\"e\":\"depthUpdate\",\"E\":1788563049131,\"T\":1788563049130,\"s\":\"BTCUSDT\",\"ps\":\"BTCUSDT\",\"U\":11478212988803,\"u\":11478212997422,\"pu\":11478212988620,\"b\":[[\"29098.10\",\"0.371\"],[\"29198.10\",\"1.729\"],[\"29298.10\",\"0.000\"],[\"63679.00\",\"0.002\"],[\"71638.20\",\"0.002\"],[\"78380.60\",\"0.022\"],[\"78491.70\",\"3.721\"],[\"78802.10\",\"7.745\"],[\"79200.10\",\"3.743\"],[\"79401.10\",\"0.000\"],[\"79404.00\",\"1.215\"],[\"79485.60\",\"0.000\"],[\"79492.60\",\"0.001\"],[\"79494.60\",\"1.507\"],[\"79583.80\",\"0.000\"],[\"79598.10\",\"10.982\"]],\"a\":[[\"79603.10\",\"0.200\"],[\"79649.90\",\"0.039\"],[\"79650.00\",\"0.195\"],[\"79675.30\",\"0.006\"],[\"79733.90\",\"0.127\"],[\"79735.50\",\"0.024\"],[\"79740.30\",\"0.290\"],[\"79740.50\",\"0.000\"],[\"79740.60\",\"0.361\"],[\"79962.40\",\"0.419\"],[\"79996.20\",\"2.023\"],[\"80394.20\",\"9.204\"],[\"80815.60\",\"0.016\"],[\"81801.50\",\"0.001\"]],\"st\":1}}"}
{"receive_ns":1788563049071591000,"stream":"btcusdt@bookTicker","event_type":"bookTicker","event_time_ms":1788563049137,"raw_json":"{\"stream\":\"btcusdt@bookTicker\",\"data\":{\"e\":\"bookTicker\",\"u\":11478212997978,\"s\":\"BTCUSDT\",\"ps\":\"BTCUSDT\",\"b\":\"79598.10\",\"B\":\"10.941\",\"a\":\"79598.20\",\"A\":\"3.139\",\"T\":1788563049137,\"E\":1788563049137,\"st\":1}}"}
{"receive_ns":1788563049073936000,"stream":"btcusdt@bookTicker","event_type":"bookTicker","event_time_ms":1788563049139,"raw_json":"{\"stream\":\"btcusdt@bookTicker\",\"data\":{\"e\":\"bookTicker\",\"u\":11478212998240,\"s\":\"BTCUSDT\",\"ps\":\"BTCUSDT\",\"b\":\"79598.10\",\"B\":\"10.986\",\"a\":\"79598.20\",\"A\":\"3.139\",\"T\":1788563049139,\"E\":1788563049139,\"st\":1}}"}
{"receive_ns":1788563049104954000,"stream":"btcusdt@bookTicker","event_type":"bookTicker","event_time_ms":1788563049169,"raw_json":"{\"stream\":\"btcusdt@bookTicker\",\"data\":{\"e\":\"bookTicker\",\"u\":11478213000563,\"s\":\"BTCUSDT\",\"ps\":\"BTCUSDT\",\"b\":\"79598.10\",\"B\":\"10.986\",\"a\":\"79598.20\",\"A\":\"3.130\",\"T\":1788563049168,\"E\":1788563049169,\"st\":1}}"}
{"receive_ns":1788563049105210000,"stream":"btcusdt@trade","event_type":"trade","event_time_ms":1788563049169,"raw_json":"{\"stream\":\"btcusdt@trade\",\"data\":{\"e\":\"trade\",\"E\":1788563049169,\"T\":1788563049168,\"s\":\"BTCUSDT\",\"t\":8054081722,\"p\":\"79598.20\",\"q\":\"0.009\",\"X\":\"MARKET\",\"m\":false,\"st\":1}}"}
{"receive_ns":1788563049106004000,"stream":"btcusdt@bookTicker","event_type":"bookTicker","event_time_ms":1788563049170,"raw_json":"{\"stream\":\"btcusdt@bookTicker\",\"data\":{\"e\":\"bookTicker\",\"u\":11478213000745,\"s\":\"BTCUSDT\",\"ps\":\"BTCUSDT\",\"b\":\"79598.10\",\"B\":\"10.994\",\"a\":\"79598.20\",\"A\":\"3.130\",\"T\":1788563049170,\"E\":1788563049170,\"st\":1}}"}
{"receive_ns":1788563049106154000,"stream":"btcusdt@bookTicker","event_type":"bookTicker","event_time_ms":1788563049170,"raw_json":"{\"stream\":\"btcusdt@bookTicker\",\"data\":{\"e\":\"bookTicker\",\"u\":11478213000821,\"s\":\"BTCUSDT\",\"ps\":\"BTCUSDT\",\"b\":\"79598.10\",\"B\":\"10.967\",\"a\":\"79598.20\",\"A\":\"3.130\",\"T\":1788563049170,\"E\":1788563049170,\"st\":1}}"}
{"receive_ns":1788563049106305000,"stream":"btcusdt@trade","event_type":"trade","event_time_ms":1788563049170,"raw_json":"{\"stream\":\"btcusdt@trade\",\"data\":{\"e\":\"trade\",\"E\":1788563049170,\"T\":1788563049170,\"s\":\"BTCUSDT\",\"t\":8054081723,\"p\":\"79598.10\",\"q\":\"0.027\",\"X\":\"MARKET\",\"m\":true,\"st\":1}}"}
{"receive_ns":1788563049106462000,"stream":"btcusdt@bookTicker","event_type":"bookTicker","event_time_ms":1788563049171,"raw_json":"{\"stream\":\"btcusdt@bookTicker\",\"data\":{\"e\":\"bookTicker\",\"u\":11478213000886,\"s\":\"BTCUSDT\",\"ps\":\"BTCUSDT\",\"b\":\"79598.10\",\"B\":\"10.959\",\"a\":\"79598.20\",\"A\":\"3.130\",\"T\":1788563049170,\"E\":1788563049171,\"st\":1}}"}
{"receive_ns":1788563049106654000,"stream":"btcusdt@bookTicker","event_type":"bookTicker","event_time_ms":1788563049171,"raw_json":"{\"stream\":\"btcusdt@bookTicker\",\"data\":{\"e\":\"bookTicker\",\"u\":11478213000984,\"s\":\"BTCUSDT\",\"ps\":\"BTCUSDT\",\"b\":\"79598.10\",\"B\":\"10.967\",\"a\":\"79598.20\",\"A\":\"3.130\",\"T\":1788563049171,\"E\":1788563049171,\"st\":1}}"}
{"receive_ns":1788563049115699000,"stream":"btcusdt@bookTicker","event_type":"bookTicker","event_time_ms":1788563049172,"raw_json":"{\"stream\":\"btcusdt@bookTicker\",\"data\":{\"e\":\"bookTicker\",\"u\":11478213001073,\"s\":\"BTCUSDT\",\"ps\":\"BTCUSDT\",\"b\":\"79598.10\",\"B\":\"10.959\",\"a\":\"79598.20\",\"A\":\"3.130\",\"T\":1788563049172,\"E\":1788563049172,\"st\":1}}"}
{"receive_ns":1788563049168125000,"stream":"btcusdt@depth@100ms","event_type":"depthUpdate","event_time_ms":1788563049233,"raw_json":"{\"stream\":\"btcusdt@depth@100ms\",\"data\":{\"e\":\"depthUpdate\",\"E\":1788563049233,\"T\":1788563049230,\"s\":\"BTCUSDT\",\"ps\":\"BTCUSDT\",\"U\":11478212997476,\"u\":11478213006201,\"pu\":11478212997422,\"b\":[[\"1000.00\",\"25.004\"],[\"29098.10\",\"0.546\"],[\"29198.10\",\"1.554\"],[\"71638.20\",\"0.002\"],[\"76414.10\",\"0.002\"],[\"78006.20\",\"0.009\"],[\"78380.60\",\"0.030\"],[\"78802.10\",\"7.745\"],[\"79401.10\",\"0.232\"],[\"79472.70\",\"1.647\"],[\"79492.60\",\"1.332\"],[\"79507.10\",\"0.000\"],[\"79598.00\",\"0.035\"],[\"79598.10\",\"10.959\"]],\"a\":[[\"79598.20\",\"3.130\"],[\"79600.70\",\"0.078\"],[\"79602.10\",\"0.002\"],[\"79602.60\",\"0.026\"],[\"79603.10\",\"0.000\"],[\"79605.30\",\"0.000\"],[\"79650.10\",\"0.002\"],[\"79651.90\",\"0.001\"],[\"79684.80\",\"0.002\"],[\"79690.50\",\"0.002\"],[\"79699.00\",\"0.110\"],[\"79735.50\",\"0.275\"],[\"79740.30\",\"0.165\"],[\"79740.50\",\"0.000\"],[\"79740.60\",\"0.486\"],[\"79962.40\",\"1.273\"],[\"79996.20\",\"2.223\"],[\"80230.50\",\"1.548\"],[\"80370.30\",\"0.602\"],[\"80394.20\",\"9.204\"],[\"80815.70\",\"0.015\"],[\"80926.00\",\"0.003\"]],\"st\":1}}"}
{"receive_ns":1788563049257451000,"stream":"btcusdt@bookTicker","event_type":"bookTicker","event_time_ms":1788563049319,"raw_json":"{\"stream\":\"btcusdt@bookTicker\",\"data\":{\"e\":\"bookTicker\",\"u\":11478213012626,\"s\":\"BTCUSDT\",\"ps\":\"BTCUSDT\",\"b\":\"79598.10\",\"B\":\"10.912\",\"a\":\"79598.20\",\"A\":\"3.130\",\"T\":1788563049319,\"E\":1788563049319,\"st\":1}}"}
{"receive_ns":1788563049259436000,"stream":"btcusdt@bookTicker","event_type":"bookTicker","event_time_ms":1788563049322,"raw_json":"{\"stream\":\"btcusdt@bookTicker\",\"data\":{\"e\":\"bookTicker\",\"u\":11478213012832,\"s\":\"BTCUSDT\",\"ps\":\"BTCUSDT\",\"b\":\"79598.10\",\"B\":\"10.968\",\"a\":\"79598.20\",\"A\":\"3.130\",\"T\":1788563049322,\"E\":1788563049322,\"st\":1}}"}
{"receive_ns":1788563049270844000,"stream":"btcusdt@depth@100ms","event_type":"depthUpdate","event_time_ms":1788563049335,"raw_json":"{\"stream\":\"btcusdt@depth@100ms\",\"data\":{\"e\":\"depthUpdate\",\"E\":1788563049335,\"T\":1788563049334,\"s\":\"BTCUSDT\",\"ps\":\"BTCUSDT\",\"U\":11478213006399,\"u\":11478213013819,\"pu\":11478213006201,\"b\":[[\"1000.00\",\"24.604\"],[\"29098.10\",\"0.728\"],[\"29198.10\",\"1.372\"],[\"71638.20\",\"0.002\"],[\"76414.10\",\"0.000\"],[\"78359.90\",\"10.707\"],[\"78802.10\",\"7.745\"],[\"79200.10\",\"3.743\"],[\"79404.00\",\"1.014\"],[\"79494.60\",\"0.000\"],[\"79507.10\",\"3.405\"],[\"79507.20\",\"0.972\"],[\"79583.60\",\"0.002\"],[\"79585.20\",\"0.016\"],[\"79598.10\",\"10.968\"]],\"a\":[[\"79602.00\",\"0.103\"],[\"79602.60\",\"0.000\"],[\"79602.80\",\"0.026\"],[\"79603.00\",\"0.026\"],[\"79603.10\",\"0.026\"],[\"79603.20\",\"0.030\"],[\"79603.90\",\"0.239\"],[\"79605.00\",\"0.029\"],[\"79605.10\",\"0.002\"],[\"79605.20\",\"0.077\"],[\"79659.90\",\"0.251\"],[\"79690.40\",\"3.987\"],[\"79735.50\",\"0.024\"],[\"79740.20\",\"0.002\"],[\"79740.60\",\"0.361\"],[\"79821.10\",\"8.246\"],[\"79821.20\",\"0.003\"],[\"79962.40\",\"0.854\"],[\"79996.20\",\"1.697\"],[\"80394.20\",\"9.204\"],[\"80514.40\",\"1.488\"]],\"st\":1}}"}
{"receive_ns":1788563049341178000,"stream":"btcusdt@bookTicker","event_type":"bookTicker","event_time_ms":1788563049406,"raw_json":"{\"stream\":\"btcusdt@bookTicker\",\"data\":{\"e\":\"bookTicker\",\"u\":11478213019880,\"s\":\"BTCUSDT\",\"ps\":\"BTCUSDT\",\"b\":\"79598.10\",\"B\":\"10.968\",\"a\":\"79598.20\",\"A\":\"3.131\",\"T\":1788563049406,\"E\":1788563049406,\"st\":1}}"}
{"receive_ns":1788563049372399000,"stream":"btcusdt@depth@100ms","event_type":"depthUpdate","event_time_ms":1788563049437,"raw_json":"{\"stream\":\"btcusdt@depth@100ms\",\"data\":{\"e\":\"depthUpdate\",\"E\":1788563049437,\"T\":1788563049434,\"s\":\"BTCUSDT\",\"ps\":\"BTCUSDT\",\"U\":11478213013942,\"u\":11478213022016,\"pu\":11478213013819,\"b\":[[\"29098.10\",\"0.903\"],[\"29198.10\",\"1.197\"],[\"71638.20\",\"0.002\"],[\"76414.10\",\"0.002\"],[\"78561.00\",\"0.191\"],[\"78638.50\",\"27.572\"],[\"78642.90\",\"14.006\"],[\"78802.10\",\"7.745\"],[\"78956.90\",\"4.174\"],[\"78961.30\",\"1.517\"],[\"79181.80\",\"0.122\"],[\"79401.10\",\"0.332\"],[\"79404.00\",\"1.215\"],[\"79472.70\",\"1.547\"],[\"79492.60\",\"1.332\"],[\"79494.60\",\"1.507\"],[\"79507.20\",\"1.356\"]],\"a\":[[\"79598.20\",\"3.131\"],[\"79602.00\",\"0.077\"],[\"79602.40\",\"0.027\"],[\"79602.50\",\"0.026\"],[\"79603.10\",\"0.226\"],[\"79604.90\",\"0.434\"],[\"79659.90\",\"0.251\"],[\"79740.30\",\"0.165\"],[\"79740.60\",\"0.361\"],[\"79962.40\",\"1.273\"],[\"79996.20\",\"2.223\"],[\"80394.20\",\"9.204\"],[\"83557.80\",\"0.000\"]],\"st\":1}}"}
{"receive_ns":1788563049394537000,"stream":"btcusdt@bookTicker","event_type":"bookTicker","event_time_ms":1788563049459,"raw_json":"{\"stream\":\"btcusdt@bookTicker\",\"data\":{\"e\":\"bookTicker\",\"u\":11478213023908,\"s\":\"BTCUSDT\",\"ps\":\"BTCUSDT\",\"b\":\"79598.10\",\"B\":\"10.937\",\"a\":\"79598.20\",\"A\":\"3.131\",\"T\":1788563049459,\"E\":1788563049459,\"st\":1}}"}
{"receive_ns":1788563049396514000,"stream":"btcusdt@bookTicker","event_type":"bookTicker","event_time_ms":1788563049462,"raw_json":"{\"stream\":\"btcusdt@bookTicker\",\"data\":{\"e\":\"bookTicker\",\"u\":11478213024161,\"s\":\"BTCUSDT\",\"ps\":\"BTCUSDT\",\"b\":\"79598.10\",\"B\":\"10.972\",\"a\":\"79598.20\",\"A\":\"3.131\",\"T\":1788563049462,\"E\":1788563049462,\"st\":1}}"}
{"receive_ns":1788563049425832000,"stream":"btcusdt@bookTicker","event_type":"bookTicker","event_time_ms":1788563049491,"raw_json":"{\"stream\":\"btcusdt@bookTicker\",\"data\":{\"e\":\"bookTicker\",\"u\":11478213026235,\"s\":\"BTCUSDT\",\"ps\":\"BTCUSDT\",\"b\":\"79598.10\",\"B\":\"10.972\",\"a\":\"79598.20\",\"A\":\"3.133\",\"T\":1788563049491,\"E\":1788563049491,\"st\":1}}"}
{"receive_ns":1788563049457513000,"stream":"btcusdt@bookTicker","event_type":"bookTicker","event_time_ms":1788563049521,"raw_json":"{\"stream\":\"btcusdt@bookTicker\",\"data\":{\"e\":\"bookTicker\",\"u\":11478213028621,\"s\":\"BTCUSDT\",\"ps\":\"BTCUSDT\",\"b\":\"79598.10\",\"B\":\"10.972\",\"a\":\"79598.20\",\"A\":\"3.135\",\"T\":1788563049521,\"E\":1788563049521,\"st\":1}}"}
{"receive_ns":1788563049464693000,"stream":"btcusdt@bookTicker","event_type":"bookTicker","event_time_ms":1788563049530,"raw_json":"{\"stream\":\"btcusdt@bookTicker\",\"data\":{\"e\":\"bookTicker\",\"u\":11478213029324,\"s\":\"BTCUSDT\",\"ps\":\"BTCUSDT\",\"b\":\"79598.10\",\"B\":\"10.968\",\"a\":\"79598.20\",\"A\":\"3.135\",\"T\":1788563049530,\"E\":1788563049530,\"st\":1}}"}
{"receive_ns":1788563049474900000,"stream":"btcusdt@bookTicker","event_type":"bookTicker","event_time_ms":1788563049533,"raw_json":"{\"stream\":\"btcusdt@bookTicker\",\"data\":{\"e\":\"bookTicker\",\"u\":11478213029547,\"s\":\"BTCUSDT\",\"ps\":\"BTCUSDT\",\"b\":\"79598.10\",\"B\":\"10.973\",\"a\":\"79598.20\",\"A\":\"3.135\",\"T\":1788563049532,\"E\":1788563049533,\"st\":1}}"}
{"receive_ns":1788563049475360000,"stream":"btcusdt@bookTicker","event_type":"bookTicker","event_time_ms":1788563049534,"raw_json":"{\"stream\":\"btcusdt@bookTicker\",\"data\":{\"e\":\"bookTicker\",\"u\":11478213029682,\"s\":\"BTCUSDT\",\"ps\":\"BTCUSDT\",\"b\":\"79598.10\",\"B\":\"10.910\",\"a\":\"79598.20\",\"A\":\"3.135\",\"T\":1788563049533,\"E\":1788563049534,\"st\":1}}"}
{"receive_ns":1788563049475585000,"stream":"btcusdt@bookTicker","event_type":"bookTicker","event_time_ms":1788563049536,"raw_json":"{\"stream\":\"btcusdt@bookTicker\",\"data\":{\"e\":\"bookTicker\",\"u\":11478213029873,\"s\":\"BTCUSDT\",\"ps\":\"BTCUSDT\",\"b\":\"79598.10\",\"B\":\"10.983\",\"a\":\"79598.20\",\"A\":\"3.135\",\"T\":1788563049536,\"E\":1788563049536,\"st\":1}}"}
{"receive_ns":1788563049475989000,"stream":"btcusdt@depth@100ms","event_type":"depthUpdate","event_time_ms":1788563049539,"raw_json":"{\"stream\":\"btcusdt@depth@100ms\",\"data\":{\"e\":\"depthUpdate\",\"E\":1788563049539,\"T\":1788563049538,\"s\":\"BTCUSDT\",\"ps\":\"BTCUSDT\",\"U\":11478213022294,\"u\":11478213030044,\"pu\":11478213022016,\"b\":[[\"1000.00\",\"24.604\"],[\"29098.10\",\"1.085\"],[\"29198.10\",\"1.015\"],[\"71638.20\",\"0.002\"],[\"75614.60\",\"0.000\"],[\"76414.10\",\"0.000\"],[\"78364.30\",\"2.685\"],[\"78802.10\",\"7.747\"],[\"79200.10\",\"3.601\"],[\"79439.30\",\"0.000\"],[\"79574.00\",\"0.007\"],[\"79576.20\",\"0.001\"],[\"79598.10\",\"10.983\"]],\"a\":[[\"79598.20\",\"3.135\"],[\"79602.20\",\"0.003\"],[\"79602.40\",\"0.001\"],[\"79603.90\",\"0.050\"],[\"79604.60\",\"0.034\"],[\"79604.70\",\"0.000\"],[\"79645.10\",\"2.151\"],[\"79645.20\",\"0.080\"],[\"79646.90\",\"12.116\"],[\"79740.30\",\"0.165\"],[\"79740.60\",\"0.361\"],[\"79996.20\",\"2.224\"],[\"80394.20\",\"9.204\"],[\"80533.80\",\"2.480\"]],\"st\":1}}"}
{"receive_ns":1788563049531679000,"stream":"btcusdt@bookTicker","event_type":"bookTicker","event_time_ms":1788563049596,"raw_json":"{\"stream\":\"btcusdt@bookTicker\",\"data\":{\"e\":\"bookTicker\",\"u\":11478213034635,\"s\":\"BTCUSDT\",\"ps\":\"BTCUSDT\",\"b\":\"79598.10\",\"B\":\"10.983\",\"a\":\"79598.20\",\"A\":\"3.137\",\"T\":1788563049596,\"E\":1788563049596,\"st\":1}}"}
{"receive_ns":1788563049576547000,"stream":"btcusdt@depth@100ms","event_type":"depthUpdate","event_time_ms":1788563049641,"raw_json":"{\"stream\":\"btcusdt@depth@100ms\",\"data\":{\"e\":\"depthUpdate\",\"E\":1788563049641,\"T\":1788563049639,\"s\":\"BTCUSDT\",\"ps\":\"BTCUSDT\",\"U\":11478213030108,\"u\":11478213039185,\"pu\":11478213030044,\"b\":[[\"1000.00\",\"24.604\"],[\"29098.10\",\"1.260\"],[\"29198.10\",\"0.840\"],[\"71638.20\",\"0.002\"],[\"71638.30\",\"0.056\"],[\"78642.90\",\"14.387\"],[\"78802.10\",\"9.012\"],[\"78961.30\",\"1.770\"],[\"79200.10\",\"3.732\"],[\"79401.10\",\"0.000\"],[\"79404.00\",\"1.215\"],[\"79492.60\",\"0.001\"],[\"79494.60\",\"1.507\"],[\"79526.40\",\"0.003\"]],\"a\":[[\"79598.20\",\"3.137\"],[\"79599.50\",\"0.078\"],[\"79601.60\",\"0.000\"],[\"79601.80\",\"0.027\"],[\"79602.20\",\"0.029\"],[\"79603.10\",\"0.226\"],[\"79604.60\",\"0.008\"],[\"79614.70\",\"0.001\"],[\"79615.70\",\"0.002\"],[\"79616.90\",\"0.456\"],[\"79659.90\",\"0.000\"],[\"79669.90\",\"0.002\"],[\"79740.50\",\"0.000\"],[\"79740.80\",\"0.002\"],[\"79962.40\",\"0.419\"],[\"79996.20\",\"2.024\"],[\"80215.50\",\"0.000\"],[\"80394.20\",\"9.203\"]],\"st\":1}}"}
{"receive_ns":1788563049634272000,"stream":"btcusdt@bookTicker","event_type":"bookTicker","event_time_ms":1788563049697,"raw_json":"{\"stream\":\"btcusdt@bookTicker\",\"data\":{\"e\":\"bookTicker\",\"u\":11478213043783,\"s\":\"BTCUSDT\",\"ps\":\"BTCUSDT\",\"b\":\"79598.10\",\"B\":\"10.983\",\"a\":\"79598.20\",\"A\":\"3.135\",\"T\":1788563049697,\"E\":1788563049697,\"st\":1}}"}
{"receive_ns":1788563049642103000,"stream":"btcusdt@bookTicker","event_type":"bookTicker","event_time_ms":1788563049706,"raw_json":"{\"stream\":\"btcusdt@bookTicker\",\"data\":{\"e\":\"bookTicker\",\"u\":11478213045208,\"s\":\"BTCUSDT\",\"ps\":\"BTCUSDT\",\"b\":\"79598.10\",\"B\":\"10.983\",\"a\":\"79598.20\",\"A\":\"3.138\",\"T\":1788563049706,\"E\":1788563049706,\"st\":1}}"}
{"receive_ns":1788563049678951000,"stream":"btcusdt@depth@100ms","event_type":"depthUpdate","event_time_ms":1788563049743,"raw_json":"{\"stream\":\"btcusdt@depth@100ms\",\"data\":{\"e\":\"depthUpdate\",\"E\":1788563049743,\"T\":1788563049742,\"s\":\"BTCUSDT\",\"ps\":\"BTCUSDT\",\"U\":11478213039345,\"u\":11478213049018,\"pu\":11478213039185,\"b\":[[\"29098.10\",\"1.442\"],[\"29198.10\",\"0.658\"],[\"63678.50\",\"0.000\"],[\"71638.20\",\"0.002\"],[\"71638.30\",\"0.054\"],[\"76414.10\",\"0.002\"],[\"78642.90\",\"14.894\"],[\"78802.10\",\"9.012\"],[\"78961.30\",\"2.023\"],[\"79401.10\",\"0.232\"],[\"79472.70\",\"1.647\"],[\"79492.60\",\"1.332\"],[\"79522.40\",\"0.000\"],[\"79526.40\",\"0.003\"]],\"a\":[[\"79598.20\",\"3.138\"],[\"79601.40\",\"0.000\"],[\"79601.50\",\"0.003\"],[\"79601.80\",\"0.001\"],[\"79601.90\",\"0.026\"],[\"79604.60\",\"0.012\"],[\"79638.00\",\"0.070\"],[\"79669.90\",\"0.000\"],[\"79735.50\",\"0.275\"],[\"79740.80\",\"0.002\"],[\"79962.40\",\"1.273\"],[\"79991.70\",\"3.225\"],[\"79996.20\",\"2.224\"],[\"80230.50\",\"1.050\"],[\"80394.20\",\"9.203\"],[\"80706.80\",\"0.717\"],[\"80951.40\",\"2.275\"]],\"st\":1}}"}
{"receive_ns":1788563049743248000,"stream":"btcusdt@bookTicker","event_type":"bookTicker","event_time_ms":1788563049807,"raw_json":"{\"stream\":\"btcusdt@bookTicker\",\"data\":{\"e\":\"bookTicker\",\"u\":11478213053239,\"s\":\"BTCUSDT\",\"ps\":\"BTCUSDT\",\"b\":\"79598.10\",\"B\":\"10.983\",\"a\":\"79598.20\",\"A\":\"3.139\",\"T\":1788563049807,\"E\":1788563049807,\"st\":1}}"}
{"receive_ns":1788563049782340000,"stream":"btcusdt@depth@100ms","event_type":"depthUpdate","event_time_ms":1788563049845,"raw_json":"{\"stream\":\"btcusdt@depth@100ms\",\"data\":{\"e\":\"depthUpdate\",\"E\":1788563049845,\"T\":1788563049842,\"s\":\"BTCUSDT\",\"ps\":\"BTCUSDT\",\"U\":11478213049126,\"u\":11478213055912,\"pu\":11478213049018,\"b\":[[\"1000.00\",\"24.604\"],[\"29098.10\",\"1.617\"],[\"29198.10\",\"0.483\"],[\"71638.20\",\"0.002\"],[\"76414.10\",\"0.000\"],[\"78359.90\",\"9.815\"],[\"78678.30\",\"5.472\"],[\"78802.10\",\"9.012\"],[\"79200.10\",\"3.732\"],[\"79401.10\",\"0.734\"],[\"79404.00\",\"1.215\"],[\"79434.20\",\"2.534\"],[\"79434.40\",\"0.001\"],[\"79473.60\",\"0.585\"],[\"79494.60\",\"1.005\"],[\"79574.40\",\"0.048\"],[\"79584.90\",\"0.290\"]],\"a\":[[\"79598.20\",\"3.139\"],[\"79601.90\",\"0.000\"],[\"79602.00\",\"0.077\"],[\"79602.10\",\"0.002\"],[\"79602.20\",\"0.003\"],[\"79602.50\",\"0.000\"],[\"79603.10\",\"0.226\"],[\"79603.30\",\"0.026\"],[\"79603.40\",\"0.028\"],[\"79604.60\",\"0.015\"],[\"79614.30\",\"0.359\"],[\"79722.20\",\"2.252\"],[\"79722.30\",\"0.001\"],[\"79735.50\",\"0.526\"],[\"79740.80\",\"0.002\"],[\"79761.60\",\"2.264\"],[\"79762.30\",\"0.584\"],[\"79962.40\",\"1.273\"],[\"79996.20\",\"2.224\"],[\"80235.00\",\"2.247\"],[\"80394.20\",\"9.203\"],[\"80553.40\",\"18.463\"],[\"80712.60\",\"18.757\"],[\"81429.00\",\"0.734\"]],\"st\":1}}"}
{"receive_ns":1788563049863729000,"stream":"btcusdt@bookTicker","event_type":"bookTicker","event_time_ms":1788563049925,"raw_json":"{\"stream\":\"btcusdt@bookTicker\",\"data\":{\"e\":\"bookTicker\",\"u\":11478213062036,\"s\":\"BTCUSDT\",\"ps\":\"BTCUSDT\",\"b\":\"79598.10\",\"B\":\"10.983\",\"a\":\"79598.20\",\"A\":\"3.136\",\"T\":1788563049925,\"E\":1788563049925,\"st\":1}}"}
{"receive_ns":1788563049863978000,"stream":"btcusdt@bookTicker","event_type":"bookTicker","event_time_ms":1788563049928,"raw_json":"{\"stream\":\"btcusdt@bookTicker\",\"data\":{\"e\":\"bookTicker\",\"u\":11478213062252,\"s\":\"BTCUSDT\",\"ps\":\"BTCUSDT\",\"b\":\"79598.10\",\"B\":\"10.967\",\"a\":\"79598.20\",\"A\":\"3.136\",\"T\":1788563049928,\"E\":1788563049928,\"st\":1}}"}
{"receive_ns":1788563049864210000,"stream":"btcusdt@bookTicker","event_type":"bookTicker","event_time_ms":1788563049930,"raw_json":"{\"stream\":\"btcusdt@bookTicker\",\"data\":{\"e\":\"bookTicker\",\"u\":11478213062415,\"s\":\"BTCUSDT\",\"ps\":\"BTCUSDT\",\"b\":\"79598.10\",\"B\":\"10.967\",\"a\":\"79598.20\",\"A\":\"3.137\",\"T\":1788563049930,\"E\":1788563049930,\"st\":1}}"}
{"receive_ns":1788563049884586000,"stream":"btcusdt@depth@100ms","event_type":"depthUpdate","event_time_ms":1788563049947,"raw_json":"{\"stream\":\"btcusdt@depth@100ms\",\"data\":{\"e\":\"depthUpdate\",\"E\":1788563049947,\"T\":1788563049945,\"s\":\"BTCUSDT\",\"ps\":\"BTCUSDT\",\"U\":11478213056066,\"u\":11478213063667,\"pu\":11478213055912,\"b\":[[\"1000.00\",\"24.604\"],[\"29098.10\",\"1.764\"],[\"29198.10\",\"0.322\"],[\"29498.10\",\"0.014\"],[\"71638.20\",\"0.002\"],[\"75618.20\",\"0.004\"],[\"75618.30\",\"0.006\"],[\"76414.10\",\"0.002\"],[\"78475.80\",\"1.398\"],[\"78802.10\",\"9.012\"],[\"79200.10\",\"3.742\"],[\"79401.10\",\"0.734\"],[\"79472.70\",\"1.647\"],[\"79492.60\",\"1.332\"],[\"79574.40\",\"0.050\"],[\"79596.70\",\"0.000\"],[\"79598.10\",\"10.967\"]],\"a\":[[\"79598.20\",\"3.137\"],[\"79601.20\",\"0.001\"],[\"79601.50\",\"0.003\"],[\"79601.60\",\"0.026\"],[\"79601.80\",\"0.027\"],[\"79601.90\",\"0.026\"],[\"79602.40\",\"0.027\"],[\"79603.10\",\"0.026\"],[\"79603.40\",\"0.002\"],[\"79603.70\",\"0.003\"],[\"79603.80\",\"0.252\"],[\"79604.50\",\"0.007\"],[\"79614.30\",\"0.361\"],[\"79735.50\",\"0.526\"],[\"79962.40\",\"1.273\"],[\"79996.20\",\"2.349\"],[\"80394.20\",\"10.445\"],[\"80704.60\",\"0.732\"]],\"st\":1}}"}
{"receive_ns":1788563049976050000,"stream":"btcusdt@bookTicker","event_type":"bookTicker","event_time_ms":1788563050039,"raw_json":"{\"stream\":\"btcusdt@bookTicker\",\"data\":{\"e\":\"bookTicker\",\"u\":11478213071952,\"s\":\"BTCUSDT\",\"ps\":\"BTCUSDT\",\"b\":\"79598.10\",\"B\":\"10.894\",\"a\":\"79598.20\",\"A\":\"3.137\",\"T\":1788563050039,\"E\":1788563050039,\"st\":1}}"}
{"receive_ns":1788563049976393000,"stream":"btcusdt@bookTicker","event_type":"bookTicker","event_time_ms":1788563050041,"raw_json":"{\"stream\":\"btcusdt@bookTicker\",\"data\":{\"e\":\"bookTicker\",\"u\":11478213072077,\"s\":\"BTCUSDT\",\"ps\":\"BTCUSDT\",\"b\":\"79598.10\",\"B\":\"10.896\",\"a\":\"79598.20\",\"A\":\"3.137\",\"T\":1788563050041,\"E\":1788563050041,\"st\":1}}"}
{"receive_ns":1788563049978547000,"stream":"btcusdt@bookTicker","event_type":"bookTicker","event_time_ms":1788563050043,"raw_json":"{\"stream\":\"btcusdt@bookTicker\",\"data\":{\"e\":\"bookTicker\",\"u\":11478213072316,\"s\":\"BTCUSDT\",\"ps\":\"BTCUSDT\",\"b\":\"79598.10\",\"B\":\"10.970\",\"a\":\"79598.20\",\"A\":\"3.137\",\"T\":1788563050043,\"E\":1788563050043,\"st\":1}}"}
{"receive_ns":1788563049986519000,"stream":"btcusdt@depth@100ms","event_type":"depthUpdate","event_time_ms":1788563050049,"raw_json":"{\"stream\":\"btcusdt@depth@100ms\",\"data\":{\"e\":\"depthUpdate\",\"E\":1788563050049,\"T\":1788563050047,\"s\":\"BTCUSDT\",\"ps\":\"BTCUSDT\",\"U\":11478213063724,\"u\":11478213072780,\"pu\":11478213063667,\"b\":[[\"29098.10\",\"1.820\"],[\"29198.10\",\"0.203\"],[\"29498.10\",\"0.077\"],[\"71638.20\",\"0.002\"],[\"71675.00\",\"0.002\"],[\"75618.20\",\"0.004\"],[\"75618.30\",\"0.008\"],[\"76414.10\",\"0.000\"],[\"78364.30\",\"3.577\"],[\"78578.00\",\"0.000\"],[\"78582.90\",\"0.005\"],[\"78609.90\",\"0.000\"],[\"78614.70\",\"0.003\"],[\"78682.70\",\"2.388\"],[\"78802.10\",\"9.012\"],[\"79200.10\",\"3.741\"],[\"79401.10\",\"0.232\"],[\"79404.00\",\"1.014\"],[\"79494.60\",\"0.000\"],[\"79563.20\",\"0.010\"],[\"79564.20\",\"0.733\"],[\"79572.50\",\"0.342\"],[\"79573.30\",\"0.373\"],[\"79583.80\",\"0.004\"],[\"79598.10\",\"10.970\"]],\"a\":[[\"79601.40\",\"0.000\"],[\"79601.50\",\"0.003\"],[\"79601.60\",\"0.026\"],[\"79601.80\",\"0.001\"],[\"79601.90\",\"0.000\"],[\"79602.00\",\"0.103\"],[\"79602.20\",\"0.029\"],[\"79606.30\",\"0.342\"],[\"79606.70\",\"0.002\"],[\"79610.20\",\"0.441\"],[\"79611.00\",\"0.691\"],[\"79615.00\",\"0.058\"],[\"79735.50\",\"0.526\"],[\"79740.40\",\"0.000\"],[\"79740.70\",\"0.017\"],[\"79962.40\",\"0.854\"],[\"79996.20\",\"1.824\"],[\"80235.00\",\"2.745\"],[\"80394.20\",\"10.445\"],[\"80706.80\",\"0.000\"],[\"80905.70\",\"0.000\"],[\"81190.10\",\"0.014\"]],\"st\":1}}"}
