{"receive_ns":1788563050026752000,"stream":"btcusdt@bookTicker","event_type":"bookTicker","event_time_ms":1788563050083,"raw_json":"{\"stream\":\"btcusdt@bookTicker\",\"data\":{\"e\":\"bookTicker\",\"u\":11478213075978,\"s\":\"BTCUSDT\",\"ps\":\"BTCUSDT\",\"b\":\"79598.10\",\"B\":\"10.959\",\"a\":\"79598.20\",\"A\":\"3.137\",\"T\":1788563050083,\"E\":1788563050083,\"st\":1}}"}
{"receive_ns":1788563050027819000,"stream":"btcusdt@bookTicker","event_type":"bookTicker","event_time_ms":1788563050093,"raw_json":"{\"stream\":\"btcusdt@bookTicker\",\"data\":{\"e\":\"bookTicker\",\"u\":11478213077054,\"s\":\"BTCUSDT\",\"ps\":\"BTCUSDT\",\"b\":\"79598.10\",\"B\":\"10.967\",\"a\":\"79598.20\",\"A\":\"3.137\",\"T\":1788563050093,\"E\":1788563050093,\"st\":1}}"}
{"receive_ns":1788563050028040000,"stream":"btcusdt@bookTicker","event_type":"bookTicker","event_time_ms":1788563050093,"raw_json":"{\"stream\":\"btcusdt@bookTicker\",\"data\":{\"e\":\"bookTicker\",\"u\":11478213077349,\"s\":\"BTCUSDT\",\"ps\":\"BTCUSDT\",\"b\":\"79598.10\",\"B\":\"10.959\",\"a\":\"79598.20\",\"A\":\"3.137\",\"T\":1788563050093,\"E\":1788563050093,\"st\":1}}"}
{"receive_ns":1788563050077560000,"stream":"btcusdt@bookTicker","event_type":"bookTicker","event_time_ms":1788563050142,"raw_json":"{\"stream\":\"btcusdt@bookTicker\",\"data\":{\"e\":\"bookTicker\",\"u\":11478213082962,\"s\":\"BTCUSDT\",\"ps\":\"BTCUSDT\",\"b\":\"79598.10\",\"B\":\"10.914\",\"a\":\"79598.20\",\"A\":\"3.137\",\"T\":1788563050142,\"E\":1788563050142,\"st\":1}}"}
{"receive_ns":1788563050077841000,"stream":"btcusdt@bookTicker","event_type":"bookTicker","event_time_ms":1788563050143,"raw_json":"{\"stream\":\"btcusdt@bookTicker\",\"data\":{\"e\":\"bookTicker\",\"u\":11478213083036,\"s\":\"BTCUSDT\",\"ps\":\"BTCUSDT\",\"b\":\"79598.10\",\"B\":\"10.914\",\"a\":\"79598.20\",\"A\":\"3.136\",\"T\":1788563050142,\"E\":1788563050143,\"st\":1}}"}
{"receive_ns":1788563050078284000,"stream":"btcusdt@bookTicker","event_type":"bookTicker","event_time_ms":1788563050144,"raw_json":"{\"stream\":\"btcusdt@bookTicker\",\"data\":{\"e\":\"bookTicker\",\"u\":11478213083227,\"s\":\"BTCUSDT\",\"ps\":\"BTCUSDT\",\"b\":\"79598.10\",\"B\":\"10.968\",\"a\":\"79598.20\",\"A\":\"3.136\",\"T\":1788563050144,\"E\":1788563050144,\"st\":1}}"}
{"receive_ns":1788563050082690000,"stream":"btcusdt@bookTicker","event_type":"bookTicker","event_time_ms":1788563050147,"raw_json":"{\"stream\":\"btcusdt@bookTicker\",\"data\":{\"e\":\"bookTicker\",\"u\":11478213083422,\"s\":\"BTCUSDT\",\"ps\":\"BTCUSDT\",\"b\":\"79598.10\",\"B\":\"10.968\",\"a\":\"79598.20\",\"A\":\"3.140\",\"T\":1788563050146,\"E\":1788563050147,\"st\":1}}"}
{"receive_ns":1788563050088859000,"stream":"btcusdt@depth@100ms","event_type":"depthUpdate","event_time_ms":1788563050151,"raw_json":"{\"stream\":\"btcusdt@depth@100ms\",\"data\":{\"e\":\"depthUpdate\",\"E\":1788563050151,\"T\":1788563050150,\"s\":\"BTCUSDT\",\"ps\":\"BTCUSDT\",\"U\":11478213073035,\"u\":11478213083793,\"pu\":11478213072780,\"b\":[[\"1000.00\",\"24.604\"],[\"29098.10\",\"1.890\"],[\"29198.10\",\"0.077\"],[\"29498.10\",\"0.133\"],[\"71638.20\",\"0.002\"],[\"75618.30\",\"0.006\"],[\"78380.60\",\"0.023\"],[\"78460.10\",\"0.010\"],[\"78623.90\",\"2.603\"],[\"78802.10\",\"9.012\"],[\"78861.10\",\"0.000\"],[\"78942.20\",\"0.919\"],[\"78961.30\",\"2.528\"],[\"79200.10\",\"3.731\"],[\"79401.10\",\"0.232\"],[\"79404.00\",\"1.215\"],[\"79472.70\",\"1.547\"],[\"79473.60\",\"0.008\"],[\"79492.60\",\"1.432\"],[\"79494.60\",\"1.507\"],[\"79521.40\",\"0.050\"],[\"79521.60\",\"0.789\"],[\"79563.20\",\"0.056\"],[\"79564.20\",\"0.687\"],[\"79572.10\",\"0.518\"],[\"79572.40\",\"0.627\"],[\"79573.20\",\"0.001\"],[\"79573.30\",\"0.000\"],[\"79583.80\",\"0.000\"],[\"79596.70\",\"0.076\"],[\"79598.10\",\"10.968\"]],\"a\":[[\"79598.20\",\"3.140\"],[\"79601.60\",\"0.000\"],[\"79602.00\",\"0.077\"],[\"79602.10\",\"0.002\"],[\"79602.20\",\"0.003\"],[\"79602.30\",\"0.026\"],[\"79602.40\",\"0.001\"],[\"79602.70\",\"0.029\"],[\"79603.40\",\"0.028\"],[\"79603.60\",\"0.027\"],[\"79603.70\",\"0.029\"],[\"79612.40\",\"0.372\"],[\"79613.70\",\"0.000\"],[\"79627.10\",\"0.046\"],[\"79628.30\",\"0.000\"],[\"79648.80\",\"0.401\"],[\"79649.00\",\"0.084\"],[\"79672.10\",\"0.002\"],[\"79675.30\",\"0.004\"],[\"79675.40\",\"0.651\"],[\"79684.80\",\"0.001\"],[\"79699.00\",\"0.109\"],[\"79722.20\",\"1.885\"],[\"79735.50\",\"0.526\"],[\"79736.40\",\"0.211\"],[\"79740.60\",\"0.486\"],[\"79775.50\",\"0.340\"],[\"79824.60\",\"0.011\"],[\"79962.40\",\"1.273\"],[\"79996.20\",\"2.350\"],[\"80335.20\",\"2.730\"],[\"80394.20\",\"10.445\"],[\"80736.00\",\"0.000\"],[\"80815.60\",\"0.009\"],[\"81190.10\",\"0.017\"]],\"st\":1}}"}
{"receive_ns":1788563050195644000,"stream":"btcusdt@depth@100ms","event_type":"depthUpdate","event_time_ms":1788563050253,"raw_json":"{\"stream\":\"btcusdt@depth@100ms\",\"data\":{\"e\":\"depthUpdate\",\"E\":1788563050253,\"T\":1788563050252,\"s\":\"BTCUSDT\",\"ps\":\"BTCUSDT\",\"U\":11478213083826,\"u\":11478213092237,\"pu\":11478213083793,\"b\":[[\"1000.00\",\"24.604\"],[\"29098.10\",\"1.869\"],[\"29198.10\",\"0.000\"],[\"29498.10\",\"0.231\"],[\"71638.20\",\"0.002\"],[\"76414.10\",\"0.002\"],[\"78380.60\",\"0.030\"],[\"78642.90\",\"15.655\"],[\"78802.10\",\"9.012\"],[\"78861.10\",\"0.005\"],[\"79454.80\",\"0.009\"],[\"79473.60\",\"0.585\"],[\"79563.20\",\"0.056\"],[\"79564.40\",\"0.001\"],[\"79572.10\",\"0.518\"],[\"79572.40\",\"0.627\"],[\"79573.20\",\"0.001\"],[\"79573.30\",\"0.000\"],[\"79573.50\",\"0.000\"],[\"79574.60\",\"0.099\"],[\"79574.90\",\"0.000\"]],\"a\":[[\"79601.30\",\"0.000\"],[\"79601.90\",\"0.000\"],[\"79602.10\",\"0.028\"],[\"79603.60\",\"0.001\"],[\"79603.70\",\"0.003\"],[\"79610.20\",\"0.441\"],[\"79611.40\",\"0.420\"],[\"79612.40\",\"0.000\"],[\"79613.30\",\"0.919\"],[\"79613.50\",\"1.245\"],[\"79614.50\",\"0.252\"],[\"79627.10\",\"0.046\"],[\"79628.10\",\"0.016\"],[\"79629.10\",\"0.193\"],[\"79699.10\",\"2.496\"],[\"79722.10\",\"0.367\"],[\"79740.00\",\"0.500\"],[\"79740.10\",\"0.001\"],[\"79740.30\",\"0.165\"],[\"79740.60\",\"0.361\"],[\"80335.10\",\"0.033\"],[\"80394.20\",\"10.445\"],[\"80593.20\",\"2.125\"],[\"80704.60\",\"1.449\"],[\"80736.00\",\"0.007\"],[\"80815.60\",\"0.016\"]],\"st\":1}}"}
{"receive_ns":1788563050227456000,"stream":"btcusdt@bookTicker","event_type":"bookTicker","event_time_ms":1788563050292,"raw_json":"{\"stream\":\"btcusdt@bookTicker\",\"data\":{\"e\":\"bookTicker\",\"u\":11478213095229,\"s\":\"BTCUSDT\",\"ps\":\"BTCUSDT\",\"b\":\"79598.10\",\"B\":\"11.006\",\"a\":\"79598.20\",\"A\":\"3.140\",\"T\":1788563050292,\"E\":1788563050292,\"st\":1}}"}
{"receive_ns":1788563050235591000,"stream":"btcusdt@bookTicker","event_type":"bookTicker","event_time_ms":1788563050292,"raw_json":"{\"stream\":\"btcusdt@bookTicker\",\"data\":{\"e\":\"bookTicker\",\"u\":11478213095249,\"s\":\"BTCUSDT\",\"ps\":\"BTCUSDT\",\"b\":\"79598.10\",\"B\":\"11.044\",\"a\":\"79598.20\",\"A\":\"3.140\",\"T\":1788563050292,\"E\":1788563050292,\"st\":1}}"}
{"receive_ns":1788563050235870000,"stream":"btcusdt@bookTicker","event_type":"bookTicker","event_time_ms":1788563050293,"raw_json":"{\"stream\":\"btcusdt@bookTicker\",\"data\":{\"e\":\"bookTicker\",\"u\":11478213095294,\"s\":\"BTCUSDT\",\"ps\":\"BTCUSDT\",\"b\":\"79598.10\",\"B\":\"11.042\",\"a\":\"79598.20\",\"A\":\"3.140\",\"T\":1788563050293,\"E\":1788563050293,\"st\":1}}"}
{"receive_ns":1788563050247847000,"stream":"btcusdt@bookTicker","event_type":"bookTicker","event_time_ms":1788563050313,"raw_json":"{\"stream\":\"btcusdt@bookTicker\",\"data\":{\"e\":\"bookTicker\",\"u\":11478213097037,\"s\":\"BTCUSDT\",\"ps\":\"BTCUSDT\",\"b\":\"79598.10\",\"B\":\"11.058\",\"a\":\"79598.20\",\"A\":\"3.140\",\"T\":1788563050312,\"E\":1788563050313,\"st\":1}}"}
{"receive_ns":1788563050254995000,"stream":"btcusdt@bookTicker","event_type":"bookTicker","event_time_ms":1788563050314,"raw_json":"{\"stream\":\"btcusdt@bookTicker\",\"data\":{\"e\":\"bookTicker\",\"u\":11478213097171,\"s\":\"BTCUSDT\",\"ps\":\"BTCUSDT\",\"b\":\"79598.10\",\"B\":\"11.060\",\"a\":\"79598.20\",\"A\":\"3.140\",\"T\":1788563050314,\"E\":1788563050314,\"st\":1}}"}
{"receive_ns":1788563050290341000,"stream":"btcusdt@depth@100ms","event_type":"depthUpdate","event_time_ms":1788563050355,"raw_json":"{\"stream\":\"btcusdt@depth@100ms\",\"data\":{\"e\":\"depthUpdate\",\"E\":1788563050355,\"T\":1788563050353,\"s\":\"BTCUSDT\",\"ps\":\"BTCUSDT\",\"U\":11478213092292,\"u\":11478213100068,\"pu\":11478213092237,\"b\":[[\"29098.10\",\"1.687\"],[\"29498.10\",\"0.413\"],[\"63678.00\",\"0.007\"],[\"71638.20\",\"0.002\"],[\"76000.00\",\"99.881\"],[\"76414.10\",\"0.000\"],[\"78439.50\",\"19.381\"],[\"78603.10\",\"3.655\"],[\"78802.10\",\"9.012\"],[\"79200.10\",\"3.731\"],[\"79401.10\",\"0.000\"],[\"79404.00\",\"1.014\"],[\"79485.60\",\"0.201\"],[\"79492.60\",\"0.001\"],[\"79494.60\",\"1.507\"],[\"79572.10\",\"0.079\"],[\"79573.20\",\"0.440\"],[\"79577.10\",\"0.500\"],[\"79577.80\",\"0.010\"],[\"79592.20\",\"0.155\"],[\"79593.80\",\"0.065\"],[\"79594.20\",\"0.376\"],[\"79594.30\",\"0.350\"],[\"79595.20\",\"0.002\"],[\"79597.60\",\"0.174\"],[\"79598.10\",\"11.060\"]],\"a\":[[\"79601.90\",\"0.026\"],[\"79602.00\",\"0.103\"],[\"79603.40\",\"0.002\"],[\"79606.20\",\"1.282\"],[\"79627.10\",\"0.000\"],[\"79628.30\",\"0.046\"],[\"79735.50\",\"0.275\"],[\"79736.40\",\"0.211\"],[\"79740.10\",\"0.001\"],[\"79740.30\",\"0.290\"],[\"79962.40\",\"0.419\"],[\"79996.20\",\"2.150\"],[\"80394.20\",\"10.445\"],[\"80468.00\",\"0.617\"],[\"80911.60\",\"1.876\"]],\"st\":1}}"}
{"receive_ns":1788563050305632000,"stream":"btcusdt@bookTicker","event_type":"bookTicker","event_time_ms":1788563050369,"raw_json":"{\"stream\":\"btcusdt@bookTicker\",\"data\":{\"e\":\"bookTicker\",\"u\":11478213101083,\"s\":\"BTCUSDT\",\"ps\":\"BTCUSDT\",\"b\":\"79598.10\",\"B\":\"11.060\",\"a\":\"79598.20\",\"A\":\"3.136\",\"T\":1788563050369,\"E\":1788563050369,\"st\":1}}"}
{"receive_ns":1788563050313827000,"stream":"btcusdt@bookTicker","event_type":"bookTicker","event_time_ms":1788563050377,"raw_json":"{\"stream\":\"btcusdt@bookTicker\",\"data\":{\"e\":\"bookTicker\",\"u\":11478213101749,\"s\":\"BTCUSDT\",\"ps\":\"BTCUSDT\",\"b\":\"79598.10\",\"B\":\"11.060\",\"a\":\"79598.20\",\"A\":\"3.137\",\"T\":1788563050376,\"E\":1788563050377,\"st\":1}}"}
{"receive_ns":1788563050318141000,"stream":"btcusdt@bookTicker","event_type":"bookTicker","event_time_ms":1788563050382,"raw_json":"{\"stream\":\"btcusdt@bookTicker\",\"data\":{\"e\":\"bookTicker\",\"u\":11478213102431,\"s\":\"BTCUSDT\",\"ps\":\"BTCUSDT\",\"b\":\"79598.10\",\"B\":\"11.004\",\"a\":\"79598.20\",\"A\":\"3.137\",\"T\":1788563050382,\"E\":1788563050382,\"st\":1}}"}
{"receive_ns":1788563050321753000,"stream":"btcusdt@bookTicker","event_type":"bookTicker","event_time_ms":1788563050385,"raw_json":"{\"stream\":\"btcusdt@bookTicker\",\"data\":{\"e\":\"bookTicker\",\"u\":11478213102782,\"s\":\"BTCUSDT\",\"ps\":\"BTCUSDT\",\"b\":\"79598.10\",\"B\":\"11.061\",\"a\":\"79598.20\",\"A\":\"3.137\",\"T\":1788563050385,\"E\":1788563050385,\"st\":1}}"}
{"receive_ns":1788563050358794000,"stream":"btcusdt@bookTicker","event_type":"bookTicker","event_time_ms":1788563050422,"raw_json":"{\"stream\":\"btcusdt@bookTicker\",\"data\":{\"e\":\"bookTicker\",\"u\":11478213105560,\"s\":\"BTCUSDT\",\"ps\":\"BTCUSDT\",\"b\":\"79598.10\",\"B\":\"11.061\",\"a\":\"79598.20\",\"A\":\"2.956\",\"T\":1788563050422,\"E\":1788563050422,\"st\":1}}"}
{"receive_ns":1788563050393858000,"stream":"btcusdt@depth@100ms","event_type":"depthUpdate","event_time_ms":1788563050457,"raw_json":"{\"stream\":\"btcusdt@depth@100ms\",\"data\":{\"e\":\"depthUpdate\",\"E\":1788563050457,\"T\":1788563050454,\"s\":\"BTCUSDT\",\"ps\":\"BTCUSDT\",\"U\":11478213100193,\"u\":11478213107961,\"pu\":11478213100068,\"b\":[[\"1000.00\",\"24.604\"],[\"29098.10\",\"1.512\"],[\"29498.10\",\"0.588\"],[\"63678.00\",\"0.004\"],[\"71638.20\",\"0.002\"],[\"76414.10\",\"0.002\"],[\"78443.90\",\"3.794\"],[\"78448.40\",\"0.504\"],[\"78802.10\",\"9.012\"],[\"78996.60\",\"1.264\"],[\"79200.10\",\"3.731\"],[\"79401.10\",\"0.232\"],[\"79492.60\",\"1.432\"],[\"79572.50\",\"0.781\"],[\"79573.20\",\"0.001\"],[\"79594.20\",\"0.376\"],[\"79595.20\",\"0.002\"],[\"79598.10\",\"11.061\"]],\"a\":[[\"79598.20\",\"2.956\"],[\"79601.30\",\"0.000\"],[\"79601.90\",\"0.000\"],[\"79602.00\",\"0.077\"],[\"79602.10\",\"0.002\"],[\"79602.30\",\"0.000\"],[\"79602.70\",\"0.003\"],[\"79602.80\",\"0.000\"],[\"79603.00\",\"0.000\"],[\"79603.40\",\"0.028\"],[\"79603.60\",\"0.027\"],[\"79603.70\",\"0.029\"],[\"79603.80\",\"0.026\"],[\"79603.90\",\"0.076\"],[\"79733.90\",\"0.188\"],[\"79735.50\",\"0.526\"],[\"79740.00\",\"0.625\"],[\"79740.30\",\"0.165\"],[\"79961.60\",\"0.287\"],[\"79962.40\",\"1.273\"],[\"79996.20\",\"2.350\"],[\"80394.20\",\"10.445\"]],\"st\":1}}"}
{"receive_ns":1788563050448414000,"stream":"btcusdt@bookTicker","event_type":"bookTicker","event_time_ms":1788563050511,"raw_json":"{\"stream\":\"btcusdt@bookTicker\",\"data\":{\"e\":\"bookTicker\",\"u\":11478213112492,\"s\":\"BTCUSDT\",\"ps\":\"BTCUSDT\",\"b\":\"79598.10\",\"B\":\"11.061\",\"a\":\"79598.20\",\"A\":\"2.957\",\"T\":1788563050511,\"E\":1788563050511,\"st\":1}}"}
{"receive_ns":1788563050495667000,"stream":"btcusdt@depth@100ms","event_type":"depthUpdate","event_time_ms":1788563050559,"raw_json":"{\"stream\":\"btcusdt@depth@100ms\",\"data\":{\"e\":\"depthUpdate\",\"E\":1788563050559,\"T\":1788563050558,\"s\":\"BTCUSDT\",\"ps\":\"BTCUSDT\",\"U\":11478213108110,\"u\":11478213116418,\"pu\":11478213107961,\"b\":[[\"1000.00\",\"24.604\"],[\"29098.10\",\"1.330\"],[\"29498.10\",\"0.770\"],[\"71638.20\",\"0.002\"],[\"78638.50\",\"26.302\"],[\"78797.70\",\"11.070\"],[\"78802.10\",\"9.012\"],[\"79200.10\",\"3.731\"],[\"79485.60\",\"0.000\"],[\"79494.60\",\"0.000\"],[\"79563.20\",\"0.010\"],[\"79564.20\",\"0.733\"],[\"79565.40\",\"10.884\"],[\"79572.40\",\"0.254\"],[\"79572.50\",\"0.342\"],[\"79573.20\",\"0.440\"],[\"79573.50\",\"0.373\"],[\"79574.70\",\"0.001\"],[\"79574.90\",\"0.000\"],[\"79578.40\",\"1.040\"]],\"a\":[[\"79598.20\",\"2.957\"],[\"79600.10\",\"0.001\"],[\"79601.90\",\"0.000\"],[\"79602.20\",\"0.003\"],[\"79602.60\",\"0.026\"],[\"79602.80\",\"0.000\"],[\"79602.90\",\"0.027\"],[\"79603.90\",\"0.050\"],[\"79606.20\",\"1.284\"],[\"79610.20\",\"0.002\"],[\"79611.40\",\"0.859\"],[\"79613.30\",\"0.547\"],[\"79614.50\",\"0.624\"],[\"79628.30\",\"0.000\"],[\"79629.20\",\"0.066\"],[\"79735.50\",\"0.526\"],[\"79736.40\",\"0.011\"],[\"79739.70\",\"0.002\"],[\"79740.00\",\"0.500\"],[\"79962.40\",\"0.854\"],[\"79996.20\",\"1.823\"],[\"80394.20\",\"10.445\"],[\"80465.80\",\"3.730\"]],\"st\":1}}"}
{"receive_ns":1788563050502352000,"stream":"btcusdt@bookTicker","event_type":"bookTicker","event_time_ms":1788563050566,"raw_json":"{\"stream\":\"btcusdt@bookTicker\",\"data\":{\"e\":\"bookTicker\",\"u\":11478213117087,\"s\":\"BTCUSDT\",\"ps\":\"BTCUSDT\",\"b\":\"79598.10\",\"B\":\"11.072\",\"a\":\"79598.20\",\"A\":\"2.957\",\"T\":1788563050566,\"E\":1788563050566,\"st\":1}}"}
{"receive_ns":1788563050567163000,"stream":"btcusdt@bookTicker","event_type":"bookTicker","event_time_ms":1788563050631,"raw_json":"{\"stream\":\"btcusdt@bookTicker\",\"data\":{\"e\":\"bookTicker\",\"u\":11478213121483,\"s\":\"BTCUSDT\",\"ps\":\"BTCUSDT\",\"b\":\"79598.10\",\"B\":\"11.072\",\"a\":\"79598.20\",\"A\":\"2.956\",\"T\":1788563050631,\"E\":1788563050631,\"st\":1}}"}
{"receive_ns":1788563050575097000,"stream":"btcusdt@bookTicker","event_type":"bookTicker","event_time_ms":1788563050639,"raw_json":"{\"stream\":\"btcusdt@bookTicker\",\"data\":{\"e\":\"bookTicker\",\"u\":11478213121911,\"s\":\"BTCUSDT\",\"ps\":\"BTCUSDT\",\"b\":\"79598.10\",\"B\":\"11.072\",\"a\":\"79598.20\",\"A\":\"2.959\",\"T\":1788563050638,\"E\":1788563050639,\"st\":1}}"}
{"receive_ns":1788563050587199000,"stream":"btcusdt@bookTicker","event_type":"bookTicker","event_time_ms":1788563050651,"raw_json":"{\"stream\":\"btcusdt@bookTicker\",\"data\":{\"e\":\"bookTicker\",\"u\":11478213122779,\"s\":\"BTCUSDT\",\"ps\":\"BTCUSDT\",\"b\":\"79598.10\",\"B\":\"10.998\",\"a\":\"79598.20\",\"A\":\"2.959\",\"T\":1788563050651,\"E\":1788563050651,\"st\":1}}"}
{"receive_ns":1788563050589735000,"stream":"btcusdt@bookTicker","event_type":"bookTicker","event_time_ms":1788563050654,"raw_json":"{\"stream\":\"btcusdt@bookTicker\",\"data\":{\"e\":\"bookTicker\",\"u\":11478213123041,\"s\":\"BTCUSDT\",\"ps\":\"BTCUSDT\",\"b\":\"79598.10\",\"B\":\"11.077\",\"a\":\"79598.20\",\"A\":\"2.959\",\"T\":1788563050653,\"E\":1788563050654,\"st\":1}}"}
{"receive_ns":1788563050597250000,"stream":"btcusdt@depth@100ms","event_type":"depthUpdate","event_time_ms":1788563050661,"raw_json":"{\"stream\":\"btcusdt@depth@100ms\",\"data\":{\"e\":\"depthUpdate\",\"E\":1788563050661,\"T\":1788563050659,\"s\":\"BTCUSDT\",\"ps\":\"BTCUSDT\",\"U\":11478213116533,\"u\":11478213123525,\"pu\":11478213116418,\"b\":[[\"29098.10\",\"1.155\"],[\"29498.10\",\"0.945\"],[\"63679.00\",\"0.002\"],[\"71638.20\",\"0.002\"],[\"76414.10\",\"0.000\"],[\"78479.30\",\"30.172\"],[\"78493.90\",\"0.754\"],[\"78603.10\",\"3.871\"],[\"78638.50\",\"25.032\"],[\"78802.10\",\"9.012\"],[\"79200.10\",\"3.732\"],[\"79401.10\",\"0.232\"],[\"79485.60\",\"0.201\"],[\"79492.60\",\"1.432\"],[\"79494.60\",\"1.507\"],[\"79581.60\",\"0.316\"],[\"79581.70\",\"0.007\"],[\"79582.30\",\"0.006\"],[\"79583.50\",\"0.000\"],[\"79583.70\",\"0.067\"],[\"79584.20\",\"0.004\"],[\"79584.70\",\"0.001\"],[\"79584.90\",\"0.270\"],[\"79585.70\",\"0.004\"],[\"79586.30\",\"0.006\"],[\"79587.70\",\"0.004\"],[\"79588.40\",\"0.100\"],[\"79594.20\",\"0.376\"],[\"79595.20\",\"0.002\"],[\"79595.70\",\"0.159\"],[\"79598.10\",\"11.077\"]],\"a\":[[\"79598.20\",\"2.959\"],[\"79602.20\",\"0.029\"],[\"79602.40\",\"0.027\"],[\"79603.80\",\"0.000\"],[\"79606.10\",\"0.007\"],[\"79607.70\",\"0.000\"],[\"79609.50\",\"0.322\"],[\"79610.20\",\"0.064\"],[\"79610.60\",\"0.005\"],[\"79611.70\",\"0.003\"],[\"79735.50\",\"0.526\"],[\"79736.40\",\"0.211\"],[\"79739.70\",\"0.002\"],[\"79739.80\",\"0.000\"],[\"79739.90\",\"0.000\"],[\"79740.10\",\"0.126\"],[\"79961.60\",\"0.183\"],[\"79962.40\",\"1.273\"],[\"79996.20\",\"2.349\"],[\"80195.20\",\"3.738\"],[\"80394.20\",\"10.445\"],[\"80468.00\",\"0.060\"],[\"80528.30\",\"13.763\"]],\"st\":1}}"}
{"receive_ns":1788563050603450000,"stream":"btcusdt@bookTicker","event_type":"bookTicker","event_time_ms":1788563050667,"raw_json":"{\"stream\":\"btcusdt@bookTicker\",\"data\":{\"e\":\"bookTicker\",\"u\":11478213124013,\"s\":\"BTCUSDT\",\"ps\":\"BTCUSDT\",\"b\":\"79598.10\",\"B\":\"11.077\",\"a\":\"79598.20\",\"A\":\"2.961\",\"T\":1788563050666,\"E\":1788563050667,\"st\":1}}"}
{"receive_ns":1788563050699304000,"stream":"btcusdt@depth@100ms","event_type":"depthUpdate","event_time_ms":1788563050763,"raw_json":"{\"stream\":\"btcusdt@depth@100ms\",\"data\":{\"e\":\"depthUpdate\",\"E\":1788563050763,\"T\":1788563050761,\"s\":\"BTCUSDT\",\"ps\":\"BTCUSDT\",\"U\":11478213123691,\"u\":11478213130430,\"pu\":11478213123525,\"b\":[[\"1000.00\",\"24.604\"],[\"29098.10\",\"0.973\"],[\"29498.10\",\"1.127\"],[\"63678.50\",\"0.000\"],[\"63679.00\",\"0.002\"],[\"71638.20\",\"0.002\"],[\"75618.20\",\"0.002\"],[\"75618.30\",\"0.008\"],[\"76414.10\",\"0.002\"],[\"78006.20\",\"0.012\"],[\"78483.70\",\"16.161\"],[\"78491.70\",\"4.459\"],[\"78603.10\",\"4.023\"],[\"78642.90\",\"16.925\"],[\"78802.10\",\"9.012\"],[\"78888.80\",\"1.048\"],[\"79200.10\",\"3.591\"],[\"79493.00\",\"0.063\"],[\"79508.20\",\"0.023\"],[\"79511.20\",\"2.204\"],[\"79536.80\",\"0.001\"],[\"79557.50\",\"1.404\"],[\"79563.20\",\"0.056\"],[\"79564.20\",\"0.687\"],[\"79572.10\",\"0.518\"],[\"79572.50\",\"0.715\"],[\"79573.20\",\"0.001\"],[\"79573.50\",\"0.000\"],[\"79581.70\",\"0.003\"],[\"79582.50\",\"0.099\"],[\"79587.70\",\"0.000\"],[\"79588.10\",\"0.146\"],[\"79590.70\",\"0.049\"],[\"79592.20\",\"0.106\"]],\"a\":[[\"79598.20\",\"2.961\"],[\"79609.50\",\"0.009\"],[\"79609.60\",\"0.697\"],[\"79610.10\",\"0.005\"],[\"79610.20\",\"0.377\"],[\"79610.60\",\"0.001\"],[\"79611.40\",\"0.420\"],[\"79612.40\",\"0.372\"],[\"79614.50\",\"0.252\"],[\"79614.70\",\"0.453\"],[\"79616.90\",\"0.004\"],[\"79627.10\",\"0.046\"],[\"79629.20\",\"0.020\"],[\"79632.20\",\"0.001\"],[\"79652.80\",\"0.356\"],[\"79652.90\",\"0.010\"],[\"79680.10\",\"1.430\"],[\"79681.60\",\"0.001\"],[\"79735.50\",\"0.275\"],[\"79740.10\",\"0.001\"],[\"80394.20\",\"10.445\"]],\"st\":1}}"}
{"receive_ns":1788563050785431000,"stream":"btcusdt@bookTicker","event_type":"bookTicker","event_time_ms":1788563050843,"raw_json":"{\"stream\":\"btcusdt@bookTicker\",\"data\":{\"e\":\"bookTicker\",\"u\":11478213135942,\"s\":\"BTCUSDT\",\"ps\":\"BTCUSDT\",\"b\":\"79598.10\",\"B\":\"11.077\",\"a\":\"79598.20\",\"A\":\"2.959\",\"T\":1788563050843,\"E\":1788563050843,\"st\":1}}"}
{"receive_ns":1788563050790122000,"stream":"btcusdt@bookTicker","event_type":"bookTicker","event_time_ms":1788563050855,"raw_json":"{\"stream\":\"btcusdt@bookTicker\",\"data\":{\"e\":\"bookTicker\",\"u\":11478213136761,\"s\":\"BTCUSDT\",\"ps\":\"BTCUSDT\",\"b\":\"79598.10\",\"B\":\"11.077\",\"a\":\"79598.20\",\"A\":\"2.956\",\"T\":1788563050855,\"E\":1788563050855,\"st\":1}}"}
{"receive_ns":1788563050793288000,"stream":"btcusdt@bookTicker","event_type":"bookTicker","event_time_ms":1788563050858,"raw_json":"{\"stream\":\"btcusdt@bookTicker\",\"data\":{\"e\":\"bookTicker\",\"u\":11478213136936,\"s\":\"BTCUSDT\",\"ps\":\"BTCUSDT\",\"b\":\"79598.10\",\"B\":\"11.077\",\"a\":\"79598.20\",\"A\":\"2.957\",\"T\":1788563050858,\"E\":1788563050858,\"st\":1}}"}
{"receive_ns":1788563050807922000,"stream":"btcusdt@depth@100ms","event_type":"depthUpdate","event_time_ms":1788563050865,"raw_json":"{\"stream\":\"btcusdt@depth@100ms\",\"data\":{\"e\":\"depthUpdate\",\"E\":1788563050865,\"T\":1788563050862,\"s\":\"BTCUSDT\",\"ps\":\"BTCUSDT\",\"U\":11478213130557,\"u\":11478213137164,\"pu\":11478213130430,\"b\":[[\"1000.00\",\"24.604\"],[\"29098.10\",\"0.798\"],[\"29498.10\",\"1.302\"],[\"71638.20\",\"0.002\"],[\"76414.10\",\"0.000\"],[\"78477.90\",\"4.451\"],[\"78483.70\",\"18.069\"],[\"78638.50\",\"24.461\"],[\"78642.90\",\"18.195\"],[\"78802.10\",\"9.012\"],[\"79200.10\",\"3.732\"],[\"79401.10\",\"0.232\"],[\"79467.60\",\"0.011\"],[\"79467.70\",\"2.122\"],[\"79485.60\",\"0.000\"],[\"79492.60\",\"0.001\"],[\"79494.60\",\"1.507\"],[\"79495.50\",\"0.215\"],[\"79496.60\",\"1.331\"],[\"79572.10\",\"0.079\"],[\"79573.20\",\"0.440\"],[\"79574.90\",\"0.000\"],[\"79583.70\",\"0.063\"],[\"79584.70\",\"0.005\"]],\"a\":[[\"79598.20\",\"2.957\"],[\"79601.70\",\"0.027\"],[\"79603.70\",\"0.003\"],[\"79606.10\",\"0.001\"],[\"79607.70\",\"0.006\"],[\"79609.60\",\"0.258\"],[\"79611.00\",\"1.130\"],[\"79612.40\",\"0.000\"],[\"79613.50\",\"1.245\"],[\"79614.50\",\"0.624\"],[\"79614.70\",\"0.001\"],[\"79615.80\",\"0.881\"],[\"79616.90\",\"0.456\"],[\"79627.10\",\"0.000\"],[\"79628.10\",\"0.062\"],[\"79724.40\",\"0.464\"],[\"79724.50\",\"0.000\"],[\"79735.50\",\"0.526\"],[\"79736.40\",\"0.211\"],[\"79737.40\",\"0.006\"],[\"79739.80\",\"0.000\"],[\"79962.40\",\"0.419\"],[\"79966.30\",\"0.765\"],[\"79996.20\",\"2.349\"],[\"80230.50\",\"0.304\"],[\"80394.20\",\"10.445\"],[\"80465.80\",\"4.287\"],[\"81826.90\",\"0.976\"]],\"st\":1}}"}
{"receive_ns":1788563050903919000,"stream":"btcusdt@depth@100ms","event_type":"depthUpdate","event_time_ms":1788563050967,"raw_json":"{\"stream\":\"btcusdt@depth@100ms\",\"data\":{\"e\":\"depthUpdate\",\"E\":1788563050967,\"T\":1788563050965,\"s\":\"BTCUSDT\",\"ps\":\"BTCUSDT\",\"U\":11478213137383,\"u\":11478213143618,\"pu\":11478213137164,\"b\":[[\"29098.10\",\"0.616\"],[\"29498.10\",\"1.484\"],[\"63678.00\",\"0.004\"],[\"71638.20\",\"0.002\"],[\"76414.10\",\"0.002\"],[\"78583.50\",\"0.636\"],[\"78802.10\",\"9.012\"],[\"79440.90\",\"0.100\"],[\"79458.00\",\"0.038\"],[\"79499.30\",\"0.385\"],[\"79511.80\",\"6.015\"],[\"79539.50\",\"4.648\"],[\"79539.60\",\"3.500\"],[\"79542.80\",\"0.051\"],[\"79559.50\",\"0.419\"],[\"79574.00\",\"0.001\"],[\"79574.40\",\"0.050\"],[\"79577.60\",\"0.006\"]],\"a\":[[\"79601.70\",\"0.001\"],[\"79610.10\",\"0.001\"],[\"79610.20\",\"0.381\"],[\"79614.30\",\"0.361\"],[\"79633.40\",\"0.507\"],[\"79653.30\",\"3.500\"],[\"79665.20\",\"0.000\"],[\"79680.10\",\"2.712\"],[\"79681.10\",\"6.002\"],[\"79685.90\",\"0.000\"],[\"79687.80\",\"0.105\"],[\"79962.40\",\"0.509\"],[\"80210.00\",\"0.004\"],[\"80235.00\",\"2.993\"],[\"80394.20\",\"10.445\"],[\"80548.80\",\"6.199\"],[\"80714.80\",\"7.472\"],[\"80951.40\",\"2.620\"]],\"st\":1}}"}
{"receive_ns":1788563050975507000,"stream":"btcusdt@bookTicker","event_type":"bookTicker","event_time_ms":1788563051037,"raw_json":"{\"stream\":\"btcusdt@bookTicker\",\"data\":{\"e\":\"bookTicker\",\"u\":11478213149150,\"s\":\"BTCUSDT\",\"ps\":\"BTCUSDT\",\"b\":\"79598.10\",\"B\":\"11.042\",\"a\":\"79598.20\",\"A\":\"2.957\",\"T\":1788563051037,\"E\":1788563051037,\"st\":1}}"}
{"receive_ns":1788563050982739000,"stream":"btcusdt@bookTicker","event_type":"bookTicker","event_time_ms":1788563051045,"raw_json":"{\"stream\":\"btcusdt@bookTicker\",\"data\":{\"e\":\"bookTicker\",\"u\":11478213150044,\"s\":\"BTCUSDT\",\"ps\":\"BTCUSDT\",\"b\":\"79598.10\",\"B\":\"11.080\",\"a\":\"79598.20\",\"A\":\"2.957\",\"T\":1788563051045,\"E\":1788563051045,\"st\":1}}"}
{"receive_ns":1788563050988971000,"stream":"btcusdt@bookTicker","event_type":"bookTicker","event_time_ms":1788563051052,"raw_json":"{\"stream\":\"btcusdt@bookTicker\",\"data\":{\"e\":\"bookTicker\",\"u\":11478213150574,\"s\":\"BTCUSDT\",\"ps\":\"BTCUSDT\",\"b\":\"79598.10\",\"B\":\"11.075\",\"a\":\"79598.20\",\"A\":\"2.957\",\"T\":1788563051051,\"E\":1788563051052,\"st\":1}}"}
{"receive_ns":1788563051006268000,"stream":"btcusdt@depth@100ms","event_type":"depthUpdate","event_time_ms":1788563051069,"raw_json":"{\"stream\":\"btcusdt@depth@100ms\",\"data\":{\"e\":\"depthUpdate\",\"E\":1788563051069,\"T\":1788563051066,\"s\":\"BTCUSDT\",\"ps\":\"BTCUSDT\",\"U\":11478213143706,\"u\":11478213151749,\"pu\":11478213143618,\"b\":[[\"1000.00\",\"24.604\"],[\"29098.10\",\"0.441\"],[\"29498.10\",\"1.659\"],[\"63679.00\",\"0.002\"],[\"71638.20\",\"0.002\"],[\"78802.10\",\"9.012\"],[\"78956.90\",\"3.921\"],[\"79200.10\",\"3.742\"],[\"79358.00\",\"0.175\"],[\"79401.10\",\"0.734\"],[\"79440.90\",\"1.105\"],[\"79457.70\",\"0.204\"],[\"79471.10\",\"10.001\"],[\"79472.00\",\"3.024\"],[\"79494.60\",\"0.000\"],[\"79495.50\",\"0.014\"],[\"79526.40\",\"0.003\"],[\"79547.30\",\"0.001\"],[\"79551.90\",\"0.077\"],[\"79563.20\",\"0.056\"],[\"79564.20\",\"0.687\"],[\"79572.10\",\"0.079\"],[\"79572.40\",\"0.627\"],[\"79572.50\",\"0.342\"],[\"79573.20\",\"0.440\"],[\"79573.30\",\"0.000\"],[\"79581.60\",\"0.002\"],[\"79582.50\",\"0.413\"],[\"79583.80\",\"0.000\"],[\"79598.10\",\"11.075\"]],\"a\":[[\"79602.20\",\"0.003\"],[\"79602.40\",\"0.001\"],[\"79603.70\",\"0.029\"],[\"79606.30\",\"0.340\"],[\"79606.70\",\"0.004\"],[\"79610.20\",\"0.820\"],[\"79611.00\",\"0.691\"],[\"79612.40\",\"0.372\"],[\"79613.30\",\"0.547\"],[\"79614.50\",\"0.252\"],[\"79627.10\",\"0.046\"],[\"79628.10\",\"0.016\"],[\"79638.00\",\"0.070\"],[\"79665.50\",\"0.054\"],[\"79718.90\",\"10.003\"],[\"79735.50\",\"0.526\"],[\"79736.40\",\"0.211\"],[\"79740.10\",\"0.126\"],[\"79821.00\",\"8.323\"],[\"79821.10\",\"0.000\"],[\"79962.40\",\"0.509\"],[\"79996.20\",\"2.348\"],[\"80235.00\",\"3.739\"],[\"80394.20\",\"10.445\"],[\"80983.90\",\"0.000\"],[\"81190.10\",\"0.014\"]],\"st\":1}}"}
{"receive_ns":1788563051048647000,"stream":"btcusdt@bookTicker","event_type":"bookTicker","event_time_ms":1788563051112,"raw_json":"{\"stream\":\"btcusdt@bookTicker\",\"data\":{\"e\":\"bookTicker\",\"u\":11478213156515,\"s\":\"BTCUSDT\",\"ps\":\"BTCUSDT\",\"b\":\"79598.10\",\"B\":\"11.083\",\"a\":\"79598.20\",\"A\":\"2.957\",\"T\":1788563051111,\"E\":1788563051112,\"st\":1}}"}
{"receive_ns":1788563051048921000,"stream":"btcusdt@bookTicker","event_type":"bookTicker","event_time_ms":1788563051112,"raw_json":"{\"stream\":\"btcusdt@bookTicker\",\"data\":{\"e\":\"bookTicker\",\"u\":11478213156578,\"s\":\"BTCUSDT\",\"ps\":\"BTCUSDT\",\"b\":\"79598.10\",\"B\":\"11.075\",\"a\":\"79598.20\",\"A\":\"2.957\",\"T\":1788563051112,\"E\":1788563051112,\"st\":1}}"}
{"receive_ns":1788563051087551000,"stream":"btcusdt@bookTicker","event_type":"bookTicker","event_time_ms":1788563051151,"raw_json":"{\"stream\":\"btcusdt@bookTicker\",\"data\":{\"e\":\"bookTicker\",\"u\":11478213161324,\"s\":\"BTCUSDT\",\"ps\":\"BTCUSDT\",\"b\":\"79598.10\",\"B\":\"11.021\",\"a\":\"79598.20\",\"A\":\"2.957\",\"T\":1788563051151,\"E\":1788563051151,\"st\":1}}"}
{"receive_ns":1788563051092721000,"stream":"btcusdt@bookTicker","event_type":"bookTicker","event_time_ms":1788563051154,"raw_json":"{\"stream\":\"btcusdt@bookTicker\",\"data\":{\"e\":\"bookTicker\",\"u\":11478213161631,\"s\":\"BTCUSDT\",\"ps\":\"BTCUSDT\",\"b\":\"79598.10\",\"B\":\"11.078\",\"a\":\"79598.20\",\"A\":\"2.957\",\"T\":1788563051154,\"E\":1788563051154,\"st\":1}}"}
{"receive_ns":1788563051107322000,"stream":"btcusdt@depth@100ms","event_type":"depthUpdate","event_time_ms":1788563051171,"raw_json":"{\"stream\":\"btcusdt@depth@100ms\",\"data\":{\"e\":\"depthUpdate\",\"E\":1788563051171,\"T\":1788563051170,\"s\":\"BTCUSDT\",\"ps\":\"BTCUSDT\",\"U\":11478213152030,\"u\":11478213162757,\"pu\":11478213151749,\"b\":[[\"1000.00\",\"24.604\"],[\"29098.10\",\"0.287\"],[\"29398.10\",\"0.028\"],[\"29498.10\",\"1.785\"],[\"63678.00\",\"0.004\"],[\"71638.20\",\"0.002\"],[\"71675.00\",\"0.002\"],[\"76414.10\",\"0.000\"],[\"78380.60\",\"0.030\"],[\"78439.50\",\"18.490\"],[\"78477.90\",\"3.942\"],[\"78563.30\",\"2.638\"],[\"78678.30\",\"4.710\"],[\"78802.10\",\"9.012\"],[\"79401.10\",\"0.734\"],[\"79440.90\",\"1.005\"],[\"79470.80\",\"0.000\"],[\"79492.60\",\"1.332\"],[\"79493.00\",\"0.085\"],[\"79494.60\",\"0.100\"],[\"79496.60\",\"0.000\"],[\"79499.30\",\"0.197\"],[\"79548.30\",\"0.000\"],[\"79563.20\",\"0.010\"],[\"79564.10\",\"0.154\"],[\"79564.30\",\"0.252\"],[\"79565.30\",\"0.196\"],[\"79572.40\",\"0.254\"],[\"79573.20\",\"0.440\"],[\"79573.30\",\"0.373\"],[\"79573.50\",\"0.000\"],[\"79574.60\",\"0.099\"],[\"79574.90\",\"0.000\"],[\"79594.30\",\"0.350\"],[\"79595.20\",\"0.002\"],[\"79598.10\",\"11.078\"]],\"a\":[[\"79601.90\",\"0.000\"],[\"79602.00\",\"0.077\"],[\"79610.20\",\"0.820\"],[\"79611.00\",\"0.691\"],[\"79612.40\",\"0.000\"],[\"79613.30\",\"0.919\"],[\"79613.50\",\"1.245\"],[\"79614.50\",\"0.252\"],[\"79627.10\",\"0.000\"],[\"79627.90\",\"0.046\"],[\"79628.10\",\"0.016\"],[\"79629.10\",\"0.193\"],[\"79675.30\",\"0.006\"],[\"79684.80\",\"0.002\"],[\"79718.80\",\"0.007\"],[\"79735.50\",\"0.526\"],[\"79736.40\",\"0.011\"],[\"79737.40\",\"0.000\"],[\"79740.10\",\"0.001\"],[\"79962.40\",\"1.273\"],[\"79966.30\",\"0.001\"],[\"79996.20\",\"2.348\"],[\"80394.20\",\"10.445\"],[\"80747.80\",\"7.850\"],[\"80815.60\",\"0.010\"]],\"st\":1}}"}
{"receive_ns":1788563051107613000,"stream":"btcusdt@bookTicker","event_type":"bookTicker","event_time_ms":1788563051171,"raw_json":"{\"stream\":\"btcusdt@bookTicker\",\"data\":{\"e\":\"bookTicker\",\"u\":11478213162898,\"s\":\"BTCUSDT\",\"ps\":\"BTCUSDT\",\"b\":\"79598.10\",\"B\":\"10.999\",\"a\":\"79598.20\",\"A\":\"2.957\",\"T\":1788563051171,\"E\":1788563051171,\"st\":1}}"}
{"receive_ns":1788563051109542000,"stream":"btcusdt@bookTicker","event_type":"bookTicker","event_time_ms":1788563051174,"raw_json":"{\"stream\":\"btcusdt@bookTicker\",\"data\":{\"e\":\"bookTicker\",\"u\":11478213163447,\"s\":\"BTCUSDT\",\"ps\":\"BTCUSDT\",\"b\":\"79598.10\",\"B\":\"11.080\",\"a\":\"79598.20\",\"A\":\"2.957\",\"T\":1788563051173,\"E\":1788563051174,\"st\":1}}"}
{"receive_ns":1788563051134887000,"stream":"btcusdt@bookTicker","event_type":"bookTicker","event_time_ms":1788563051200,"raw_json":"{\"stream\":\"btcusdt@bookTicker\",\"data\":{\"e\":\"bookTicker\",\"u\":11478213166662,\"s\":\"BTCUSDT\",\"ps\":\"BTCUSDT\",\"b\":\"79598.10\",\"B\":\"11.080\",\"a\":\"79598.20\",\"A\":\"2.956\",\"T\":1788563051200,\"E\":1788563051200,\"st\":1}}"}
{"receive_ns":1788563051143646000,"stream":"btcusdt@bookTicker","event_type":"bookTicker","event_time_ms":1788563051207,"raw_json":"{\"stream\":\"btcusdt@bookTicker\",\"data\":{\"e\":\"bookTicker\",\"u\":11478213167423,\"s\":\"BTCUSDT\",\"ps\":\"BTCUSDT\",\"b\":\"79598.10\",\"B\":\"11.080\",\"a\":\"79598.20\",\"A\":\"2.958\",\"T\":1788563051207,\"E\":1788563051207,\"st\":1}}"}
{"receive_ns":1788563051216660000,"stream":"btcusdt@depth@100ms","event_type":"depthUpdate","event_time_ms":1788563051273,"raw_json":"{\"stream\":\"btcusdt@depth@100ms\",\"data\":{\"e\":\"depthUpdate\",\"E\":1788563051273,\"T\":1788563051270,\"s\":\"BTCUSDT\",\"ps\":\"BTCUSDT\",\"U\":11478213162898,\"u\":11478213171766,\"pu\":11478213162757,\"b\":[[\"29098.10\",\"0.175\"],[\"29398.10\",\"0.091\"],[\"29498.10\",\"1.834\"],[\"71638.20\",\"0.002\"],[\"76414.10\",\"0.002\"],[\"78006.20\",\"0.012\"],[\"78802.10\",\"9.012\"],[\"79200.10\",\"3.602\"],[\"79594.20\",\"0.376\"],[\"79595.20\",\"0.002\"],[\"79598.10\",\"11.080\"]],\"a\":[[\"79598.20\",\"2.958\"],[\"79602.10\",\"0.028\"],[\"79602.60\",\"0.000\"],[\"79602.70\",\"0.029\"],[\"79698.90\",\"0.003\"],[\"79735.50\",\"0.275\"],[\"80394.20\",\"10.445\"],[\"80815.60\",\"0.016\"],[\"81040.40\",\"0.000\"]],\"st\":1}}"}
{"receive_ns":1788563051238002000,"stream":"btcusdt@bookTicker","event_type":"bookTicker","event_time_ms":1788563051302,"raw_json":"{\"stream\":\"btcusdt@bookTicker\",\"data\":{\"e\":\"bookTicker\",\"u\":11478213173646,\"s\":\"BTCUSDT\",\"ps\":\"BTCUSDT\",\"b\":\"79598.10\",\"B\":\"11.080\",\"a\":\"79598.20\",\"A\":\"2.956\",\"T\":1788563051301,\"E\":1788563051302,\"st\":1}}"}
{"receive_ns":1788563051311440000,"stream":"btcusdt@depth@100ms","event_type":"depthUpdate","event_time_ms":1788563051375,"raw_json":"{\"stream\":\"btcusdt@depth@100ms\",\"data\":{\"e\":\"depthUpdate\",\"E\":1788563051375,\"T\":1788563051373,\"s\":\"BTCUSDT\",\"ps\":\"BTCUSDT\",\"U\":11478213171938,\"u\":11478213178358,\"pu\":11478213171766,\"b\":[[\"1000.00\",\"24.604\"],[\"29098.10\",\"0.049\"],[\"29398.10\",\"0.147\"],[\"29498.10\",\"1.904\"],[\"71638.20\",\"0.002\"],[\"76414.10\",\"0.000\"],[\"78439.50\",\"17.599\"],[\"78561.00\",\"0.000\"],[\"78638.50\",\"23.191\"],[\"78678.30\",\"3.948\"],[\"78802.10\",\"9.012\"],[\"78995.00\",\"0.298\"],[\"79200.10\",\"3.743\"],[\"79401.10\",\"0.232\"],[\"79404.00\",\"1.215\"],[\"79440.90\",\"0.000\"],[\"79457.70\",\"0.003\"],[\"79472.70\",\"2.878\"],[\"79473.60\",\"0.585\"],[\"79492.60\",\"0.001\"],[\"79494.60\",\"1.507\"],[\"79502.50\",\"0.003\"],[\"79563.20\",\"0.056\"],[\"79564.10\",\"0.108\"],[\"79572.10\",\"0.079\"],[\"79572.40\",\"0.627\"],[\"79573.20\",\"0.440\"],[\"79573.30\",\"0.000\"]],\"a\":[[\"79598.20\",\"2.956\"],[\"79602.10\",\"0.002\"],[\"79606.10\",\"0.252\"],[\"79610.20\",\"0.507\"],[\"79610.60\",\"0.314\"],[\"79630.10\",\"0.659\"],[\"79631.00\",\"0.077\"],[\"79669.90\",\"0.002\"],[\"79722.00\",\"0.563\"],[\"79722.10\",\"0.000\"],[\"79735.50\",\"0.024\"],[\"79736.40\",\"0.011\"],[\"79962.40\",\"1.183\"],[\"79996.20\",\"2.348\"],[\"80394.20\",\"10.445\"]],\"st\":1}}"}
{"receive_ns":1788563051357733000,"stream":"btcusdt@bookTicker","event_type":"bookTicker","event_time_ms":1788563051422,"raw_json":"{\"stream\":\"btcusdt@bookTicker\",\"data\":{\"e\":\"bookTicker\",\"u\":11478213183240,\"s\":\"BTCUSDT\",\"ps\":\"BTCUSDT\",\"b\":\"79598.10\",\"B\":\"11.023\",\"a\":\"79598.20\",\"A\":\"2.956\",\"T\":1788563051422,\"E\":1788563051422,\"st\":1}}"}
{"receive_ns":1788563051368366000,"stream":"btcusdt@bookTicker","event_type":"bookTicker","event_time_ms":1788563051424,"raw_json":"{\"stream\":\"btcusdt@bookTicker\",\"data\":{\"e\":\"bookTicker\",\"u\":11478213183507,\"s\":\"BTCUSDT\",\"ps\":\"BTCUSDT\",\"b\":\"79598.10\",\"B\":\"11.085\",\"a\":\"79598.20\",\"A\":\"2.956\",\"T\":1788563051424,\"E\":1788563051424,\"st\":1}}"}
{"receive_ns":1788563051412841000,"stream":"btcusdt@depth@100ms","event_type":"depthUpdate","event_time_ms":1788563051477,"raw_json":"{\"stream\":\"btcusdt@depth@100ms\",\"data\":{\"e\":\"depthUpdate\",\"E\":1788563051477,\"T\":1788563051476,\"s\":\"BTCUSDT\",\"ps\":\"BTCUSDT\",\"U\":11478213178454,\"u\":11478213187560,\"pu\":11478213178358,\"b\":[[\"1000.00\",\"24.604\"],[\"29098.10\",\"0.000\"],[\"29398.10\",\"0.273\"],[\"29498.10\",\"1.827\"],[\"71638.20\",\"0.002\"],[\"78443.90\",\"4.685\"],[\"78638.50\",\"21.921\"],[\"78682.70\",\"3.150\"],[\"78802.10\",\"9.012\"],[\"78844.10\",\"1.518\"],[\"79401.10\",\"0.332\"],[\"79572.30\",\"0.027\"],[\"79577.60\",\"0.000\"],[\"79598.10\",\"11.085\"]],\"a\":[[\"79610.20\",\"0.820\"],[\"79610.60\",\"0.001\"],[\"79653.20\",\"1.327\"],[\"79716.20\",\"2.303\"],[\"79733.90\",\"0.127\"],[\"79961.60\",\"0.287\"],[\"79962.40\",\"1.273\"],[\"79988.40\",\"0.842\"],[\"79991.70\",\"1.354\"],[\"80394.20\",\"10.445\"],[\"80752.40\",\"6.186\"],[\"81038.10\",\"3.326\"]],\"st\":1}}"}
{"receive_ns":1788563051475549000,"stream":"btcusdt@bookTicker","event_type":"bookTicker","event_time_ms":1788563051539,"raw_json":"{\"stream\":\"btcusdt@bookTicker\",\"data\":{\"e\":\"bookTicker\",\"u\":11478213193285,\"s\":\"BTCUSDT\",\"ps\":\"BTCUSDT\",\"b\":\"79598.10\",\"B\":\"11.085\",\"a\":\"79598.20\",\"A\":\"2.954\",\"T\":1788563051539,\"E\":1788563051539,\"st\":1}}"}
{"receive_ns":1788563051482328000,"stream":"btcusdt@bookTicker","event_type":"bookTicker","event_time_ms":1788563051546,"raw_json":"{\"stream\":\"btcusdt@bookTicker\",\"data\":{\"e\":\"bookTicker\",\"u\":11478213194001,\"s\":\"BTCUSDT\",\"ps\":\"BTCUSDT\",\"b\":\"79598.10\",\"B\":\"11.085\",\"a\":\"79598.20\",\"A\":\"2.955\",\"T\":1788563051546,\"E\":1788563051546,\"st\":1}}"}
{"receive_ns":1788563051483120000,"stream":"btcusdt@bookTicker","event_type":"bookTicker","event_time_ms":1788563051548,"raw_json":"{\"stream\":\"btcusdt@bookTicker\",\"data\":{\"e\":\"bookTicker\",\"u\":11478213194124,\"s\":\"BTCUSDT\",\"ps\":\"BTCUSDT\",\"b\":\"79598.10\",\"B\":\"11.047\",\"a\":\"79598.20\",\"A\":\"2.955\",\"T\":1788563051547,\"E\":1788563051548,\"st\":1}}"}
{"receive_ns":1788563051487679000,"stream":"btcusdt@bookTicker","event_type":"bookTicker","event_time_ms":1788563051550,"raw_json":"{\"stream\":\"btcusdt@bookTicker\",\"data\":{\"e\":\"bookTicker\",\"u\":11478213194421,\"s\":\"BTCUSDT\",\"ps\":\"BTCUSDT\",\"b\":\"79598.10\",\"B\":\"11.084\",\"a\":\"79598.20\",\"A\":\"2.955\",\"T\":1788563051550,\"E\":1788563051550,\"st\":1}}"}
{"receive_ns":1788563051498101000,"stream":"btcusdt@bookTicker","event_type":"bookTicker","event_time_ms":1788563051553,"raw_json":"{\"stream\":\"btcusdt@bookTicker\",\"data\":{\"e\":\"bookTicker\",\"u\":11478213194652,\"s\":\"BTCUSDT\",\"ps\":\"BTCUSDT\",\"b\":\"79598.10\",\"B\":\"11.073\",\"a\":\"79598.20\",\"A\":\"2.955\",\"T\":1788563051553,\"E\":1788563051553,\"st\":1}}"}
{"receive_ns":1788563051516199000,"stream":"btcusdt@depth@100ms","event_type":"depthUpdate","event_time_ms":1788563051579,"raw_json":"{\"stream\":\"btcusdt@depth@100ms\",\"data\":{\"e\":\"depthUpdate\",\"E\":1788563051579,\"T\":1788563051578,\"s\":\"BTCUSDT\",\"ps\":\"BTCUSDT\",\"U\":11478213187629,\"u\":11478213196818,\"pu\":11478213187560,\"b\":[[\"29398.10\",\"0.455\"],[\"29498.10\",\"1.645\"],[\"34000.00\",\"0.975\"],[\"71638.20\",\"0.002\"],[\"76414.10\",\"0.002\"],[\"78642.90\",\"19.465\"],[\"78802.10\",\"9.012\"],[\"79018.50\",\"0.260\"],[\"79200.10\",\"3.743\"],[\"79401.10\",\"0.100\"],[\"79404.00\",\"1.215\"],[\"79461.10\",\"0.125\"],[\"79472.70\",\"1.547\"],[\"79492.60\",\"1.508\"],[\"79494.60\",\"0.000\"],[\"79531.60\",\"0.002\"],[\"79563.20\",\"0.010\"],[\"79564.10\",\"0.154\"],[\"79565.30\",\"0.196\"],[\"79572.40\",\"0.254\"],[\"79573.20\",\"0.440\"],[\"79573.30\",\"0.373\"],[\"79574.50\",\"0.631\"],[\"79574.80\",\"0.456\"],[\"79574.90\",\"0.000\"],[\"79583.70\",\"0.001\"],[\"79584.70\",\"0.067\"],[\"79598.10\",\"11.073\"]],\"a\":[[\"79598.20\",\"2.955\"],[\"79602.20\",\"0.003\"],[\"79602.70\",\"0.003\"],[\"79603.10\",\"0.026\"],[\"79603.80\",\"0.026\"],[\"79606.10\",\"0.001\"],[\"79610.20\",\"0.068\"],[\"79610.60\",\"0.314\"],[\"79611.00\",\"1.130\"],[\"79613.30\",\"0.547\"],[\"79614.40\",\"0.623\"],[\"79627.90\",\"0.000\"],[\"79629.10\",\"0.239\"],[\"79757.10\",\"0.000\"],[\"79961.60\",\"0.183\"],[\"79962.40\",\"0.509\"],[\"79996.20\",\"2.148\"],[\"80394.20\",\"10.445\"],[\"80708.00\",\"5.816\"]],\"st\":1}}"}
{"receive_ns":1788563051615952000,"stream":"btcusdt@depth@100ms","event_type":"depthUpdate","event_time_ms":1788563051681,"raw_json":"{\"stream\":\"btcusdt@depth@100ms\",\"data\":{\"e\":\"depthUpdate\",\"E\":1788563051681,\"T\":1788563051678,\"s\":\"BTCUSDT\",\"ps\":\"BTCUSDT\",\"U\":11478213197028,\"u\":11478213206178,\"pu\":11478213196818,\"b\":[[\"1000.00\",\"24.604\"],[\"29398.10\",\"0.630\"],[\"29498.10\",\"1.470\"],[\"63678.00\",\"0.004\"],[\"71638.20\",\"0.002\"],[\"76414.10\",\"0.000\"],[\"78443.90\",\"5.576\"],[\"78479.30\",\"28.280\"],[\"78538.80\",\"7.885\"],[\"78618.40\",\"15.988\"],[\"78682.70\",\"3.912\"],[\"78802.10\",\"9.012\"],[\"79200.10\",\"3.732\"],[\"79265.30\",\"0.010\"],[\"79267.30\",\"0.931\"],[\"79283.10\",\"10.441\"],[\"79283.90\",\"2.477\"],[\"79401.10\",\"0.232\"],[\"79494.60\",\"1.431\"],[\"79563.20\",\"0.056\"],[\"79564.10\",\"0.108\"],[\"79572.10\",\"0.518\"],[\"79572.40\",\"0.627\"],[\"79573.20\",\"0.001\"],[\"79573.30\",\"0.000\"],[\"79574.30\",\"0.001\"]],\"a\":[[\"79602.20\",\"0.003\"],[\"79602.40\",\"0.001\"],[\"79602.60\",\"0.000\"],[\"79602.70\",\"0.029\"],[\"79606.10\",\"0.252\"],[\"79609.60\",\"0.258\"],[\"79610.20\",\"0.507\"],[\"79611.00\",\"0.691\"],[\"79627.10\",\"0.000\"],[\"79628.10\",\"0.062\"],[\"79629.10\",\"0.193\"],[\"79757.20\",\"0.001\"],[\"79757.40\",\"0.000\"],[\"79962.40\",\"1.273\"],[\"79996.20\",\"4.220\"],[\"80394.20\",\"10.445\"],[\"81190.10\",\"0.011\"]],\"st\":1}}"}
{"receive_ns":1788563051637399000,"stream":"btcusdt@bookTicker","event_type":"bookTicker","event_time_ms":1788563051701,"raw_json":"{\"stream\":\"btcusdt@bookTicker\",\"data\":{\"e\":\"bookTicker\",\"u\":11478213207554,\"s\":\"BTCUSDT\",\"ps\":\"BTCUSDT\",\"b\":\"79598.10\",\"B\":\"11.079\",\"a\":\"79598.20\",\"A\":\"2.955\",\"T\":1788563051701,\"E\":1788563051701,\"st\":1}}"}
{"receive_ns":1788563051719325000,"stream":"btcusdt@depth@100ms","event_type":"depthUpdate","event_time_ms":1788563051783,"raw_json":"{\"stream\":\"btcusdt@depth@100ms\",\"data\":{\"e\":\"depthUpdate\",\"E\":1788563051783,\"T\":1788563051782,\"s\":\"BTCUSDT\",\"ps\":\"BTCUSDT\",\"U\":11478213206385,\"u\":11478213214410,\"pu\":11478213206178,\"b\":[[\"1000.00\",\"24.604\"],[\"29398.10\",\"0.812\"],[\"29498.10\",\"1.288\"],[\"63678.50\",\"0.000\"],[\"71638.20\",\"0.002\"],[\"76414.10\",\"0.002\"],[\"78280.30\",\"0.893\"],[\"78430.20\",\"0.954\"],[\"78642.90\",\"20.735\"],[\"78802.10\",\"9.012\"],[\"79200.10\",\"3.732\"],[\"79380.10\",\"0.000\"],[\"79404.00\",\"1.014\"],[\"79462.70\",\"0.012\"],[\"79492.60\",\"0.001\"],[\"79598.10\",\"11.079\"]],\"a\":[[\"79602.40\",\"0.027\"],[\"79602.60\",\"0.026\"],[\"79603.80\",\"0.000\"],[\"79693.80\",\"0.002\"],[\"79735.50\",\"0.275\"],[\"79757.30\",\"0.000\"],[\"79962.40\",\"0.854\"],[\"79996.20\",\"3.694\"],[\"80394.20\",\"10.445\"],[\"80712.60\",\"20.613\"],[\"80907.00\",\"0.864\"]],\"st\":1}}"}
{"receive_ns":1788563051779977000,"stream":"btcusdt@bookTicker","event_type":"bookTicker","event_time_ms":1788563051843,"raw_json":"{\"stream\":\"btcusdt@bookTicker\",\"data\":{\"e\":\"bookTicker\",\"u\":11478213220369,\"s\":\"BTCUSDT\",\"ps\":\"BTCUSDT\",\"b\":\"79598.10\",\"B\":\"11.079\",\"a\":\"79598.20\",\"A\":\"2.954\",\"T\":1788563051843,\"E\":1788563051843,\"st\":1}}"}
{"receive_ns":1788563051821098000,"stream":"btcusdt@depth@100ms","event_type":"depthUpdate","event_time_ms":1788563051885,"raw_json":"{\"stream\":\"btcusdt@depth@100ms\",\"data\":{\"e\":\"depthUpdate\",\"E\":1788563051885,\"T\":1788563051884,\"s\":\"BTCUSDT\",\"ps\":\"BTCUSDT\",\"U\":11478213214481,\"u\":11478213224095,\"pu\":11478213214410,\"b\":[[\"29398.10\",\"0.987\"],[\"29498.10\",\"1.113\"],[\"63678.00\",\"0.004\"],[\"71638.20\",\"0.002\"],[\"76414.10\",\"0.000\"],[\"78284.70\",\"1.786\"],[\"78483.70\",\"19.978\"],[\"78802.10\",\"9.012\"],[\"78936.70\",\"0.314\"],[\"78956.90\",\"3.415\"],[\"79401.10\",\"0.232\"],[\"79404.00\",\"1.215\"],[\"79472.70\",\"2.049\"],[\"79492.60\",\"1.006\"],[\"79494.60\",\"1.431\"],[\"79572.10\",\"0.079\"],[\"79572.40\",\"0.254\"],[\"79573.20\",\"0.440\"],[\"79573.30\",\"0.373\"],[\"79574.60\",\"0.099\"],[\"79574.90\",\"0.000\"]],\"a\":[[\"79598.20\",\"2.954\"],[\"79601.80\",\"0.001\"],[\"79602.10\",\"0.028\"],[\"79602.40\",\"0.001\"],[\"79602.60\",\"0.000\"],[\"79602.70\",\"0.029\"],[\"79603.10\",\"0.026\"],[\"79603.70\",\"0.029\"],[\"79603.80\",\"0.252\"],[\"79606.10\",\"0.001\"],[\"79610.20\",\"0.068\"],[\"79611.40\",\"0.859\"],[\"79628.10\",\"0.016\"],[\"79629.10\",\"0.239\"],[\"79681.20\",\"0.000\"],[\"79684.70\",\"0.020\"],[\"79735.50\",\"0.526\"],[\"79757.20\",\"0.001\"],[\"79962.40\",\"1.273\"],[\"79996.20\",\"4.220\"],[\"80394.20\",\"10.445\"],[\"80911.60\",\"2.740\"]],\"st\":1}}"}
{"receive_ns":1788563051922161000,"stream":"btcusdt@depth@100ms","event_type":"depthUpdate","event_time_ms":1788563051987,"raw_json":"{\"stream\":\"btcusdt@depth@100ms\",\"data\":{\"e\":\"depthUpdate\",\"E\":1788563051987,\"T\":1788563051986,\"s\":\"BTCUSDT\",\"ps\":\"BTCUSDT\",\"U\":11478213224478,\"u\":11478213233458,\"pu\":11478213224095,\"b\":[[\"1000.00\",\"24.604\"],[\"29398.10\",\"1.169\"],[\"29498.10\",\"0.931\"],[\"63678.00\",\"0.004\"],[\"71638.20\",\"0.002\"],[\"78006.20\",\"0.015\"],[\"78135.80\",\"0.639\"],[\"78802.10\",\"9.012\"],[\"78841.90\",\"5.231\"],[\"78844.10\",\"1.139\"],[\"79200.10\",\"3.601\"],[\"79572.30\",\"0.021\"],[\"79574.40\",\"0.050\"],[\"79576.70\",\"2.649\"]],\"a\":[[\"79601.50\",\"0.029\"],[\"79614.30\",\"0.361\"],[\"79735.50\",\"0.275\"],[\"79757.30\",\"0.000\"],[\"79991.70\",\"1.229\"],[\"80394.20\",\"10.445\"]],\"st\":1}}"}
{"receive_ns":1788563051972266000,"stream":"btcusdt@bookTicker","event_type":"bookTicker","event_time_ms":1788563052035,"raw_json":"{\"stream\":\"btcusdt@bookTicker\",\"data\":{\"e\":\"bookTicker\",\"u\":11478213236902,\"s\":\"BTCUSDT\",\"ps\":\"BTCUSDT\",\"b\":\"79598.10\",\"B\":\"11.090\",\"a\":\"79598.20\",\"A\":\"2.954\",\"T\":1788563052035,\"E\":1788563052035,\"st\":1}}"}
{"receive_ns":1788563052016089000,"stream":"btcusdt@bookTicker","event_type":"bookTicker","event_time_ms":1788563052079,"raw_json":"{\"stream\":\"btcusdt@bookTicker\",\"data\":{\"e\":\"bookTicker\",\"u\":11478213240188,\"s\":\"BTCUSDT\",\"ps\":\"BTCUSDT\",\"b\":\"79598.10\",\"B\":\"11.090\",\"a\":\"79598.20\",\"A\":\"2.948\",\"T\":1788563052079,\"E\":1788563052079,\"st\":1}}"}
{"receive_ns":1788563052016395000,"stream":"btcusdt@trade","event_type":"trade","event_time_ms":1788563052079,"raw_json":"{\"stream\":\"btcusdt@trade\",\"data\":{\"e\":\"trade\",\"E\":1788563052079,\"T\":1788563052079,\"s\":\"BTCUSDT\",\"t\":8054081724,\"p\":\"79598.20\",\"q\":\"0.006\",\"X\":\"MARKET\",\"m\":false,\"st\":1}}"}
{"receive_ns":1788563052016795000,"stream":"btcusdt@bookTicker","event_type":"bookTicker","event_time_ms":1788563052080,"raw_json":"{\"stream\":\"btcusdt@bookTicker\",\"data\":{\"e\":\"bookTicker\",\"u\":11478213240377,\"s\":\"BTCUSDT\",\"ps\":\"BTCUSDT\",\"b\":\"79598.10\",\"B\":\"11.098\",\"a\":\"79598.20\",\"A\":\"2.948\",\"T\":1788563052080,\"E\":1788563052080,\"st\":1}}"}
{"receive_ns":1788563052017179000,"stream":"btcusdt@bookTicker","event_type":"bookTicker","event_time_ms":1788563052081,"raw_json":"{\"stream\":\"btcusdt@bookTicker\",\"data\":{\"e\":\"bookTicker\",\"u\":11478213240550,\"s\":\"BTCUSDT\",\"ps\":\"BTCUSDT\",\"b\":\"79598.10\",\"B\":\"11.090\",\"a\":\"79598.20\",\"A\":\"2.948\",\"T\":1788563052081,\"E\":1788563052081,\"st\":1}}"}
{"receive_ns":1788563052026373000,"stream":"btcusdt@depth@100ms","event_type":"depthUpdate","event_time_ms":1788563052089,"raw_json":"{\"stream\":\"btcusdt@depth@100ms\",\"data\":{\"e\":\"depthUpdate\",\"E\":1788563052089,\"T\":1788563052087,\"s\":\"BTCUSDT\",\"ps\":\"BTCUSDT\",\"U\":11478213233518,\"u\":11478213241223,\"pu\":11478213233458,\"b\":[[\"1000.00\",\"24.604\"],[\"29398.10\",\"1.344\"],[\"29498.10\",\"0.756\"],[\"63678.00\",\"0.004\"],[\"71638.20\",\"0.002\"],[\"76414.10\",\"0.002\"],[\"78479.30\",\"26.371\"],[\"78802.10\",\"9.012\"],[\"79001.10\",\"3.226\"],[\"79200.10\",\"3.742\"],[\"79401.10\",\"0.000\"],[\"79404.00\",\"1.014\"],[\"79418.40\",\"0.000\"],[\"79418.50\",\"4.322\"],[\"79453.70\",\"1.957\"],[\"79453.80\",\"0.011\"],[\"79463.10\",\"0.000\"],[\"79463.20\",\"0.003\"],[\"79472.70\",\"1.547\"],[\"79485.60\",\"0.201\"],[\"79486.60\",\"0.001\"],[\"79492.60\",\"1.508\"],[\"79494.60\",\"0.000\"],[\"79511.50\",\"0.061\"],[\"79511.60\",\"0.829\"],[\"79563.20\",\"0.056\"],[\"79564.20\",\"0.687\"],[\"79572.10\",\"0.518\"],[\"79572.40\",\"0.627\"],[\"79573.20\",\"0.001\"],[\"79573.30\",\"0.000\"],[\"79583.80\",\"0.000\"],[\"79598.00\",\"0.111\"],[\"79598.10\",\"11.090\"]],\"a\":[[\"79598.20\",\"2.948\"],[\"79599.50\",\"0.002\"],[\"79601.50\",\"0.003\"],[\"79601.90\",\"0.000\"],[\"79602.10\",\"0.002\"],[\"79602.70\",\"0.003\"],[\"79602.90\",\"0.001\"],[\"79603.70\",\"0.218\"],[\"79603.80\",\"0.278\"],[\"79603.90\",\"0.076\"],[\"79610.20\",\"0.820\"],[\"79610.60\",\"0.001\"],[\"79611.40\",\"0.420\"],[\"79612.40\",\"0.372\"],[\"79613.30\",\"0.547\"],[\"79614.40\",\"0.251\"],[\"79628.00\",\"2.050\"],[\"79629.10\",\"0.193\"],[\"79684.50\",\"0.064\"],[\"79684.70\",\"0.015\"],[\"79686.70\",\"0.077\"],[\"79686.80\",\"0.000\"],[\"79722.10\",\"1.884\"],[\"79722.20\",\"0.001\"],[\"79735.50\",\"0.275\"],[\"79736.40\",\"0.011\"],[\"79744.80\",\"3.141\"],[\"79745.00\",\"0.076\"],[\"79820.90\",\"8.263\"],[\"79821.00\",\"0.088\"],[\"79821.20\",\"0.000\"],[\"79821.30\",\"0.003\"],[\"79962.40\",\"0.419\"],[\"79996.20\",\"4.145\"],[\"80394.20\",\"10.445\"],[\"80548.80\",\"4.959\"]],\"st\":1}}"}
{"receive_ns":1788563052128069000,"stream":"btcusdt@depth@100ms","event_type":"depthUpdate","event_time_ms":1788563052191,"raw_json":"{\"stream\":\"btcusdt@depth@100ms\",\"data\":{\"e\":\"depthUpdate\",\"E\":1788563052191,\"T\":1788563052189,\"s\":\"BTCUSDT\",\"ps\":\"BTCUSDT\",\"U\":11478213241374,\"u\":11478213250293,\"pu\":11478213241223,\"b\":[[\"29398.10\",\"1.526\"],[\"29498.10\",\"0.574\"],[\"63679.00\",\"0.002\"],[\"71638.20\",\"0.002\"],[\"76414.10\",\"0.000\"],[\"78006.20\",\"0.018\"],[\"78677.00\",\"1.073\"],[\"78802.10\",\"9.012\"],[\"78961.30\",\"3.034\"],[\"79200.10\",\"3.741\"],[\"79401.10\",\"0.232\"],[\"79460.70\",\"0.135\"],[\"79461.10\",\"0.000\"],[\"79494.60\",\"1.431\"],[\"79563.20\",\"0.010\"],[\"79564.40\",\"0.047\"],[\"79572.10\",\"0.079\"],[\"79572.40\",\"0.254\"],[\"79573.20\",\"0.440\"],[\"79573.30\",\"0.373\"],[\"79573.50\",\"0.000\"],[\"79574.60\",\"0.099\"],[\"79574.90\",\"0.000\"],[\"79592.20\",\"0.005\"],[\"79592.70\",\"0.102\"],[\"79595.20\",\"0.001\"],[\"79595.50\",\"0.002\"]],\"a\":[[\"79600.70\",\"0.078\"],[\"79601.90\",\"0.000\"],[\"79602.30\",\"0.000\"],[\"79602.40\",\"0.027\"],[\"79602.50\",\"0.000\"],[\"79602.60\",\"0.026\"],[\"79602.70\",\"0.029\"],[\"79603.10\",\"0.000\"],[\"79603.20\",\"0.004\"],[\"79603.30\",\"0.000\"],[\"79603.40\",\"0.028\"],[\"79603.70\",\"0.029\"],[\"79604.00\",\"2.900\"],[\"79604.10\",\"0.356\"],[\"79604.30\",\"0.005\"],[\"79604.40\",\"0.002\"],[\"79610.20\",\"0.820\"],[\"79611.00\",\"0.691\"],[\"79612.40\",\"0.000\"],[\"79613.30\",\"0.919\"],[\"79613.50\",\"1.245\"],[\"79614.50\",\"0.252\"],[\"79627.90\",\"0.046\"],[\"79628.00\",\"2.004\"],[\"79629.10\",\"0.193\"],[\"79684.50\",\"0.059\"],[\"79684.80\",\"0.003\"],[\"79698.90\",\"0.004\"],[\"79735.50\",\"0.526\"],[\"79757.20\",\"0.001\"],[\"79757.50\",\"1.831\"],[\"79962.40\",\"1.273\"],[\"79996.20\",\"4.345\"],[\"80394.20\",\"10.445\"]],\"st\":1}}"}
{"receive_ns":1788563052128569000,"stream":"btcusdt@bookTicker","event_type":"bookTicker","event_time_ms":1788563052191,"raw_json":"{\"stream\":\"btcusdt@bookTicker\",\"data\":{\"e\":\"bookTicker\",\"u\":11478213250372,\"s\":\"BTCUSDT\",\"ps\":\"BTCUSDT\",\"b\":\"79598.10\",\"B\":\"11.009\",\"a\":\"79598.20\",\"A\":\"2.948\",\"T\":1788563052191,\"E\":1788563052191,\"st\":1}}"}
{"receive_ns":1788563052138367000,"stream":"btcusdt@bookTicker","event_type":"bookTicker","event_time_ms":1788563052194,"raw_json":"{\"stream\":\"btcusdt@bookTicker\",\"data\":{\"e\":\"bookTicker\",\"u\":11478213250572,\"s\":\"BTCUSDT\",\"ps\":\"BTCUSDT\",\"b\":\"79598.10\",\"B\":\"11.104\",\"a\":\"79598.20\",\"A\":\"2.948\",\"T\":1788563052193,\"E\":1788563052194,\"st\":1}}"}
{"receive_ns":1788563052231656000,"stream":"btcusdt@depth@100ms","event_type":"depthUpdate","event_time_ms":1788563052293,"raw_json":"{\"stream\":\"btcusdt@depth@100ms\",\"data\":{\"e\":\"depthUpdate\",\"E\":1788563052293,\"T\":1788563052292,\"s\":\"BTCUSDT\",\"ps\":\"BTCUSDT\",\"U\":11478213250372,\"u\":11478213259296,\"pu\":11478213250293,\"b\":[[\"1000.00\",\"24.604\"],[\"29398.10\",\"1.701\"],[\"29498.10\",\"0.399\"],[\"71638.20\",\"0.002\"],[\"71675.00\",\"0.002\"],[\"76414.10\",\"0.002\"],[\"78467.80\",\"0.153\"],[\"78802.10\",\"9.012\"],[\"79200.10\",\"3.731\"],[\"79462.70\",\"0.010\"],[\"79485.60\",\"0.201\"],[\"79486.60\",\"0.022\"],[\"79492.60\",\"0.001\"],[\"79494.60\",\"2.938\"],[\"79502.50\",\"0.001\"],[\"79526.40\",\"0.003\"],[\"79534.00\",\"0.001\"],[\"79534.60\",\"1.382\"],[\"79539.40\",\"22.611\"],[\"79539.50\",\"0.190\"],[\"79595.20\",\"0.002\"],[\"79595.50\",\"0.001\"],[\"79598.00\",\"0.035\"],[\"79598.10\",\"11.104\"]],\"a\":[[\"79601.60\",\"0.000\"],[\"79601.70\",\"0.001\"],[\"79601.80\",\"0.001\"],[\"79601.90\",\"0.000\"],[\"79602.00\",\"0.077\"],[\"79602.80\",\"0.026\"],[\"79603.90\",\"0.050\"],[\"79604.00\",\"2.874\"],[\"79604.10\",\"0.330\"],[\"79638.00\",\"0.070\"],[\"79669.90\",\"0.000\"],[\"79693.80\",\"0.000\"],[\"79698.90\",\"0.005\"],[\"79735.50\",\"0.526\"],[\"79736.40\",\"0.211\"],[\"79962.40\",\"1.273\"],[\"79996.20\",\"4.346\"],[\"80394.20\",\"10.445\"],[\"80548.80\",\"3.719\"],[\"80708.00\",\"3.960\"]],\"st\":1}}"}
{"receive_ns":1788563052330730000,"stream":"btcusdt@depth@100ms","event_type":"depthUpdate","event_time_ms":1788563052395,"raw_json":"{\"stream\":\"btcusdt@depth@100ms\",\"data\":{\"e\":\"depthUpdate\",\"E\":1788563052395,\"T\":1788563052393,\"s\":\"BTCUSDT\",\"ps\":\"BTCUSDT\",\"U\":11478213259410,\"u\":11478213266303,\"pu\":11478213259296,\"b\":[[\"1000.00\",\"24.604\"],[\"29298.10\",\"0.042\"],[\"29398.10\",\"1.799\"],[\"29498.10\",\"0.259\"],[\"71638.20\",\"0.002\"],[\"76414.10\",\"0.000\"],[\"78478.70\",\"0.003\"],[\"78479.30\",\"24.462\"],[\"78483.70\",\"21.887\"],[\"78730.50\",\"1.773\"],[\"78788.30\",\"0.000\"],[\"78802.10\",\"10.279\"],[\"79401.10\",\"0.232\"],[\"79473.60\",\"0.602\"],[\"79492.60\",\"0.101\"],[\"79494.60\",\"1.582\"],[\"79496.60\",\"1.256\"],[\"79563.20\",\"0.056\"],[\"79564.40\",\"0.001\"],[\"79572.10\",\"0.518\"],[\"79572.40\",\"0.627\"],[\"79573.20\",\"0.001\"],[\"79573.30\",\"0.000\"],[\"79595.20\",\"0.001\"],[\"79595.50\",\"0.002\"],[\"79598.00\",\"0.111\"]],\"a\":[[\"79601.80\",\"0.001\"],[\"79602.40\",\"0.001\"],[\"79602.60\",\"0.000\"],[\"79602.70\",\"0.003\"],[\"79602.80\",\"0.000\"],[\"79602.90\",\"0.027\"],[\"79603.00\",\"0.026\"],[\"79603.10\",\"0.026\"],[\"79603.90\",\"0.076\"],[\"79684.50\",\"0.064\"],[\"79721.80\",\"3.061\"],[\"79722.00\",\"0.196\"],[\"79735.50\",\"0.526\"],[\"79962.40\",\"1.273\"],[\"79996.20\",\"4.346\"],[\"80394.20\",\"10.445\"],[\"80553.40\",\"19.703\"],[\"80747.80\",\"6.984\"],[\"80827.40\",\"5.191\"]],\"st\":1}}"}
{"receive_ns":1788563052336388000,"stream":"btcusdt@bookTicker","event_type":"bookTicker","event_time_ms":1788563052402,"raw_json":"{\"stream\":\"btcusdt@bookTicker\",\"data\":{\"e\":\"bookTicker\",\"u\":11478213266894,\"s\":\"BTCUSDT\",\"ps\":\"BTCUSDT\",\"b\":\"79598.10\",\"B\":\"11.104\",\"a\":\"79598.20\",\"A\":\"2.715\",\"T\":1788563052401,\"E\":1788563052402,\"st\":1}}"}
{"receive_ns":1788563052336787000,"stream":"btcusdt@trade","event_type":"trade","event_time_ms":1788563052402,"raw_json":"{\"stream\":\"btcusdt@trade\",\"data\":{\"e\":\"trade\",\"E\":1788563052402,\"T\":1788563052401,\"s\":\"BTCUSDT\",\"t\":8054081725,\"p\":\"79598.20\",\"q\":\"0.233\",\"X\":\"MARKET\",\"m\":false,\"st\":1}}"}
{"receive_ns":1788563052337112000,"stream":"btcusdt@bookTicker","event_type":"bookTicker","event_time_ms":1788563052403,"raw_json":"{\"stream\":\"btcusdt@bookTicker\",\"data\":{\"e\":\"bookTicker\",\"u\":11478213266957,\"s\":\"BTCUSDT\",\"ps\":\"BTCUSDT\",\"b\":\"79598.10\",\"B\":\"11.105\",\"a\":\"79598.20\",\"A\":\"2.715\",\"T\":1788563052403,\"E\":1788563052403,\"st\":1}}"}
{"receive_ns":1788563052338419000,"stream":"btcusdt@bookTicker","event_type":"bookTicker","event_time_ms":1788563052403,"raw_json":"{\"stream\":\"btcusdt@bookTicker\",\"data\":{\"e\":\"bookTicker\",\"u\":11478213267056,\"s\":\"BTCUSDT\",\"ps\":\"BTCUSDT\",\"b\":\"79598.10\",\"B\":\"11.099\",\"a\":\"79598.20\",\"A\":\"2.715\",\"T\":1788563052403,\"E\":1788563052403,\"st\":1}}"}
{"receive_ns":1788563052338608000,"stream":"btcusdt@bookTicker","event_type":"bookTicker","event_time_ms":1788563052403,"raw_json":"{\"stream\":\"btcusdt@bookTicker\",\"data\":{\"e\":\"bookTicker\",\"u\":11478213267069,\"s\":\"BTCUSDT\",\"ps\":\"BTCUSDT\",\"b\":\"79598.10\",\"B\":\"11.099\",\"a\":\"79598.20\",\"A\":\"2.716\",\"T\":1788563052403,\"E\":1788563052403,\"st\":1}}"}
{"receive_ns":1788563052338759000,"stream":"btcusdt@bookTicker","event_type":"bookTicker","event_time_ms":1788563052403,"raw_json":"{\"stream\":\"btcusdt@bookTicker\",\"data\":{\"e\":\"bookTicker\",\"u\":11478213267085,\"s\":\"BTCUSDT\",\"ps\":\"BTCUSDT\",\"b\":\"79598.10\",\"B\":\"11.107\",\"a\":\"79598.20\",\"A\":\"2.716\",\"T\":1788563052403,\"E\":1788563052403,\"st\":1}}"}
{"receive_ns":1788563052338969000,"stream":"btcusdt@bookTicker","event_type":"bookTicker","event_time_ms":1788563052404,"raw_json":"{\"stream\":\"btcusdt@bookTicker\",\"data\":{\"e\":\"bookTicker\",\"u\":11478213267224,\"s\":\"BTCUSDT\",\"ps\":\"BTCUSDT\",\"b\":\"79598.10\",\"B\":\"11.099\",\"a\":\"79598.20\",\"A\":\"2.716\",\"T\":1788563052404,\"E\":1788563052404,\"st\":1}}"}
{"receive_ns":1788563052436793000,"stream":"btcusdt@depth@100ms","event_type":"depthUpdate","event_time_ms":1788563052497,"raw_json":"{\"stream\":\"btcusdt@depth@100ms\",\"data\":{\"e\":\"depthUpdate\",\"E\":1788563052497,\"T\":1788563052496,\"s\":\"BTCUSDT\",\"ps\":\"BTCUSDT\",\"U\":11478213266470,\"u\":11478213273866,\"pu\":11478213266303,\"b\":[[\"29298.10\",\"0.105\"],[\"29398.10\",\"1.848\"],[\"29498.10\",\"0.147\"],[\"71638.20\",\"0.002\"],[\"78006.20\",\"0.015\"],[\"78483.70\",\"23.796\"],[\"78802.10\",\"10.279\"],[\"79200.10\",\"3.590\"],[\"79511.20\",\"1.256\"],[\"79511.90\",\"2.082\"],[\"79563.20\",\"0.010\"],[\"79564.40\",\"0.047\"],[\"79572.10\",\"0.079\"],[\"79572.40\",\"0.254\"],[\"79573.10\",\"2.070\"],[\"79573.20\",\"0.440\"],[\"79573.30\",\"0.373\"],[\"79574.60\",\"0.099\"],[\"79574.90\",\"0.000\"],[\"79576.70\",\"2.643\"],[\"79585.70\",\"0.000\"],[\"79586.30\",\"0.010\"],[\"79588.10\",\"0.142\"],[\"79588.40\",\"0.104\"],[\"79588.70\",\"0.100\"],[\"79598.10\",\"11.099\"]],\"a\":[[\"79598.20\",\"2.716\"],[\"79600.70\",\"0.002\"],[\"79602.30\",\"0.000\"],[\"79602.40\",\"0.027\"],[\"79602.90\",\"0.027\"],[\"79603.00\",\"0.026\"],[\"79603.10\",\"0.026\"],[\"79603.30\",\"0.026\"],[\"79603.40\",\"0.028\"],[\"79603.60\",\"0.027\"],[\"79603.70\",\"0.003\"],[\"79603.80\",\"0.000\"],[\"79603.90\",\"0.050\"],[\"79604.30\",\"0.031\"],[\"79604.60\",\"0.041\"],[\"79604.80\",\"0.029\"],[\"79604.90\",\"0.434\"],[\"79605.00\",\"0.029\"],[\"79605.10\",\"0.002\"],[\"79605.20\",\"0.077\"],[\"79605.30\",\"0.000\"],[\"79605.50\",\"0.000\"],[\"79605.60\",\"0.976\"],[\"79608.40\",\"0.648\"],[\"79610.20\",\"0.758\"],[\"79610.60\",\"0.063\"],[\"79611.40\",\"0.420\"],[\"79613.30\",\"0.547\"],[\"79614.50\",\"0.624\"],[\"79627.90\",\"0.046\"],[\"79629.10\",\"0.193\"],[\"79645.10\",\"0.760\"],[\"79645.30\",\"0.000\"],[\"79646.00\",\"0.000\"],[\"79646.90\",\"2.116\"],[\"79652.70\",\"2.000\"],[\"79652.80\",\"0.357\"],[\"79733.90\",\"0.188\"],[\"79735.50\",\"0.275\"],[\"79961.60\",\"0.287\"],[\"80394.20\",\"10.445\"],[\"80553.40\",\"20.943\"],[\"80712.60\",\"22.469\"]],\"st\":1}}"}
{"receive_ns":1788563052491042000,"stream":"btcusdt@bookTicker","event_type":"bookTicker","event_time_ms":1788563052553,"raw_json":"{\"stream\":\"btcusdt@bookTicker\",\"data\":{\"e\":\"bookTicker\",\"u\":11478213279041,\"s\":\"BTCUSDT\",\"ps\":\"BTCUSDT\",\"b\":\"79598.10\",\"B\":\"11.062\",\"a\":\"79598.20\",\"A\":\"2.716\",\"T\":1788563052553,\"E\":1788563052553,\"st\":1}}"}
{"receive_ns":1788563052492438000,"stream":"btcusdt@bookTicker","event_type":"bookTicker","event_time_ms":1788563052556,"raw_json":"{\"stream\":\"btcusdt@bookTicker\",\"data\":{\"e\":\"bookTicker\",\"u\":11478213279280,\"s\":\"BTCUSDT\",\"ps\":\"BTCUSDT\",\"b\":\"79598.10\",\"B\":\"11.100\",\"a\":\"79598.20\",\"A\":\"2.716\",\"T\":1788563052556,\"E\":1788563052556,\"st\":1}}"}
{"receive_ns":1788563052492833000,"stream":"btcusdt@bookTicker","event_type":"bookTicker","event_time_ms":1788563052557,"raw_json":"{\"stream\":\"btcusdt@bookTicker\",\"data\":{\"e\":\"bookTicker\",\"u\":11478213279362,\"s\":\"BTCUSDT\",\"ps\":\"BTCUSDT\",\"b\":\"79598.10\",\"B\":\"11.099\",\"a\":\"79598.20\",\"A\":\"2.716\",\"T\":1788563052557,\"E\":1788563052557,\"st\":1}}"}
{"receive_ns":1788563052493045000,"stream":"btcusdt@bookTicker","event_type":"bookTicker","event_time_ms":1788563052557,"raw_json":"{\"stream\":\"btcusdt@bookTicker\",\"data\":{\"e\":\"bookTicker\",\"u\":11478213279366,\"s\":\"BTCUSDT\",\"ps\":\"BTCUSDT\",\"b\":\"79598.10\",\"B\":\"11.099\",\"a\":\"79598.20\",\"A\":\"2.715\",\"T\":1788563052557,\"E\":1788563052557,\"st\":1}}"}
{"receive_ns":1788563052505523000,"stream":"btcusdt@bookTicker","event_type":"bookTicker","event_time_ms":1788563052570,"raw_json":"{\"stream\":\"btcusdt@bookTicker\",\"data\":{\"e\":\"bookTicker\",\"u\":11478213280346,\"s\":\"BTCUSDT\",\"ps\":\"BTCUSDT\",\"b\":\"79598.10\",\"B\":\"11.037\",\"a\":\"79598.20\",\"A\":\"2.715\",\"T\":1788563052569,\"E\":1788563052570,\"st\":1}}"}
{"receive_ns":1788563052508314000,"stream":"btcusdt@bookTicker","event_type":"bookTicker","event_time_ms":1788563052572,"raw_json":"{\"stream\":\"btcusdt@bookTicker\",\"data\":{\"e\":\"bookTicker\",\"u\":11478213280591,\"s\":\"BTCUSDT\",\"ps\":\"BTCUSDT\",\"b\":\"79598.10\",\"B\":\"11.098\",\"a\":\"79598.20\",\"A\":\"2.715\",\"T\":1788563052572,\"E\":1788563052572,\"st\":1}}"}
{"receive_ns":1788563052518437000,"stream":"btcusdt@bookTicker","event_type":"bookTicker","event_time_ms":1788563052581,"raw_json":"{\"stream\":\"btcusdt@bookTicker\",\"data\":{\"e\":\"bookTicker\",\"u\":11478213281422,\"s\":\"BTCUSDT\",\"ps\":\"BTCUSDT\",\"b\":\"79598.10\",\"B\":\"11.068\",\"a\":\"79598.20\",\"A\":\"2.715\",\"T\":1788563052580,\"E\":1788563052581,\"st\":1}}"}
{"receive_ns":1788563052518672000,"stream":"btcusdt@trade","event_type":"trade","event_time_ms":1788563052581,"raw_json":"{\"stream\":\"btcusdt@trade\",\"data\":{\"e\":\"trade\",\"E\":1788563052581,\"T\":1788563052580,\"s\":\"BTCUSDT\",\"t\":8054081726,\"p\":\"79598.10\",\"q\":\"0.030\",\"X\":\"MARKET\",\"m\":true,\"st\":1}}"}
{"receive_ns":1788563052518856000,"stream":"btcusdt@bookTicker","event_type":"bookTicker","event_time_ms":1788563052582,"raw_json":"{\"stream\":\"btcusdt@bookTicker\",\"data\":{\"e\":\"bookTicker\",\"u\":11478213281559,\"s\":\"BTCUSDT\",\"ps\":\"BTCUSDT\",\"b\":\"79598.10\",\"B\":\"11.076\",\"a\":\"79598.20\",\"A\":\"2.715\",\"T\":1788563052582,\"E\":1788563052582,\"st\":1}}"}
{"receive_ns":1788563052519111000,"stream":"btcusdt@bookTicker","event_type":"bookTicker","event_time_ms":1788563052582,"raw_json":"{\"stream\":\"btcusdt@bookTicker\",\"data\":{\"e\":\"bookTicker\",\"u\":11478213281621,\"s\":\"BTCUSDT\",\"ps\":\"BTCUSDT\",\"b\":\"79598.10\",\"B\":\"11.076\",\"a\":\"79598.20\",\"A\":\"3.079\",\"T\":1788563052582,\"E\":1788563052582,\"st\":1}}"}
{"receive_ns":1788563052519381000,"stream":"btcusdt@bookTicker","event_type":"bookTicker","event_time_ms":1788563052583,"raw_json":"{\"stream\":\"btcusdt@bookTicker\",\"data\":{\"e\":\"bookTicker\",\"u\":11478213281716,\"s\":\"BTCUSDT\",\"ps\":\"BTCUSDT\",\"b\":\"79598.10\",\"B\":\"11.068\",\"a\":\"79598.20\",\"A\":\"3.079\",\"T\":1788563052583,\"E\":1788563052583,\"st\":1}}"}
{"receive_ns":1788563052519768000,"stream":"btcusdt@bookTicker","event_type":"bookTicker","event_time_ms":1788563052583,"raw_json":"{\"stream\":\"btcusdt@bookTicker\",\"data\":{\"e\":\"bookTicker\",\"u\":11478213281819,\"s\":\"BTCUSDT\",\"ps\":\"BTCUSDT\",\"b\":\"79598.10\",\"B\":\"11.068\",\"a\":\"79598.20\",\"A\":\"3.078\",\"T\":1788563052583,\"E\":1788563052583,\"st\":1}}"}
{"receive_ns":1788563052535988000,"stream":"btcusdt@depth@100ms","event_type":"depthUpdate","event_time_ms":1788563052599,"raw_json":"{\"stream\":\"btcusdt@depth@100ms\",\"data\":{\"e\":\"depthUpdate\",\"E\":1788563052599,\"T\":1788563052598,\"s\":\"BTCUSDT\",\"ps\":\"BTCUSDT\",\"U\":11478213273914,\"u\":11478213283180,\"pu\":11478213273866,\"b\":[[\"1000.00\",\"24.604\"],[\"29298.10\",\"0.161\"],[\"29398.10\",\"1.918\"],[\"29498.10\",\"0.021\"],[\"63679.00\",\"0.002\"],[\"71638.20\",\"0.002\"],[\"76414.10\",\"0.002\"],[\"78439.50\",\"16.708\"],[\"78642.90\",\"21.305\"],[\"78678.30\",\"3.186\"],[\"78802.10\",\"10.279\"],[\"79200.10\",\"3.741\"],[\"79401.10\",\"0.232\"],[\"79460.70\",\"0.010\"],[\"79485.60\",\"0.201\"],[\"79492.60\",\"0.001\"],[\"79494.60\",\"2.838\"],[\"79496.60\",\"0.000\"],[\"79528.40\",\"0.719\"],[\"79535.20\",\"0.073\"],[\"79574.20\",\"0.631\"],[\"79574.50\",\"0.003\"],[\"79598.00\",\"0.035\"],[\"79598.10\",\"11.068\"]],\"a\":[[\"79598.20\",\"3.078\"],[\"79600.00\",\"0.128\"],[\"79601.10\",\"0.003\"],[\"79601.30\",\"0.026\"],[\"79602.00\",\"0.103\"],[\"79602.20\",\"0.029\"],[\"79602.40\",\"0.001\"],[\"79602.80\",\"0.026\"],[\"79603.40\",\"0.280\"],[\"79603.60\",\"0.001\"],[\"79604.30\",\"0.005\"],[\"79604.60\",\"0.015\"],[\"79604.80\",\"0.003\"],[\"79646.40\",\"10.334\"],[\"79735.50\",\"0.526\"],[\"79736.40\",\"0.211\"],[\"79961.60\",\"0.183\"],[\"79962.40\",\"1.183\"],[\"79996.20\",\"4.346\"],[\"80394.20\",\"10.445\"],[\"80573.20\",\"2.894\"],[\"80712.60\",\"23.088\"],[\"80747.80\",\"6.118\"],[\"80752.40\",\"7.052\"],[\"80832.00\",\"3.462\"]],\"st\":1}}"}
{"receive_ns":1788563052549255000,"stream":"btcusdt@bookTicker","event_type":"bookTicker","event_time_ms":1788563052610,"raw_json":"{\"stream\":\"btcusdt@bookTicker\",\"data\":{\"e\":\"bookTicker\",\"u\":11478213284185,\"s\":\"BTCUSDT\",\"ps\":\"BTCUSDT\",\"b\":\"79598.10\",\"B\":\"11.068\",\"a\":\"79598.20\",\"A\":\"3.117\",\"T\":1788563052610,\"E\":1788563052610,\"st\":1}}"}
{"receive_ns":1788563052549593000,"stream":"btcusdt@bookTicker","event_type":"bookTicker","event_time_ms":1788563052611,"raw_json":"{\"stream\":\"btcusdt@bookTicker\",\"data\":{\"e\":\"bookTicker\",\"u\":11478213284310,\"s\":\"BTCUSDT\",\"ps\":\"BTCUSDT\",\"b\":\"79598.10\",\"B\":\"11.068\",\"a\":\"79598.20\",\"A\":\"3.118\",\"T\":1788563052611,\"E\":1788563052611,\"st\":1}}"}
{"receive_ns":1788563052637053000,"stream":"btcusdt@depth@100ms","event_type":"depthUpdate","event_time_ms":1788563052701,"raw_json":"{\"stream\":\"btcusdt@depth@100ms\",\"data\":{\"e\":\"depthUpdate\",\"E\":1788563052701,\"T\":1788563052698,\"s\":\"BTCUSDT\",\"ps\":\"BTCUSDT\",\"U\":11478213283312,\"u\":11478213290874,\"pu\":11478213283180,\"b\":[[\"29298.10\",\"0.315\"],[\"29398.10\",\"1.785\"],[\"29498.10\",\"0.000\"],[\"71638.20\",\"0.002\"],[\"75618.30\",\"0.006\"],[\"76414.10\",\"0.000\"],[\"78479.30\",\"22.570\"],[\"78507.60\",\"1.525\"],[\"78603.10\",\"4.239\"],[\"78802.10\",\"10.279\"],[\"78841.90\",\"5.800\"],[\"79200.10\",\"3.742\"],[\"79496.60\",\"0.100\"],[\"79534.00\",\"0.001\"],[\"79536.70\",\"22.405\"],[\"79539.40\",\"0.221\"],[\"79548.40\",\"0.001\"],[\"79563.30\",\"0.047\"],[\"79564.40\",\"0.001\"],[\"79565.60\",\"0.065\"],[\"79572.10\",\"0.518\"],[\"79572.20\",\"0.377\"],[\"79573.20\",\"0.001\"],[\"79573.30\",\"0.000\"],[\"79573.50\",\"0.628\"],[\"79574.20\",\"0.003\"],[\"79577.60\",\"0.628\"],[\"79578.00\",\"0.002\"],[\"79578.40\",\"0.412\"],[\"79578.90\",\"0.003\"],[\"79581.50\",\"0.005\"],[\"79581.60\",\"0.944\"],[\"79581.90\",\"0.000\"],[\"79582.40\",\"0.001\"],[\"79582.50\",\"0.095\"],[\"79583.50\",\"0.062\"],[\"79583.60\",\"0.006\"],[\"79584.00\",\"0.012\"],[\"79584.30\",\"0.002\"],[\"79584.50\",\"0.017\"],[\"79584.70\",\"0.001\"],[\"79584.90\",\"0.253\"],[\"79585.20\",\"0.002\"],[\"79585.70\",\"0.004\"],[\"79586.30\",\"0.006\"],[\"79587.70\",\"0.004\"],[\"79588.10\",\"0.142\"],[\"79588.40\",\"0.100\"],[\"79589.50\",\"0.001\"],[\"79589.90\",\"0.251\"],[\"79590.40\",\"0.206\"],[\"79592.20\",\"0.005\"],[\"79595.20\",\"0.002\"],[\"79595.50\",\"0.001\"]],\"a\":[[\"79598.20\",\"3.118\"],[\"79599.80\",\"0.252\"],[\"79600.20\",\"0.001\"],[\"79600.40\",\"0.293\"],[\"79600.60\",\"0.026\"],[\"79601.10\",\"0.029\"],[\"79603.40\",\"0.254\"],[\"79606.10\",\"0.007\"],[\"79607.70\",\"0.008\"],[\"79608.30\",\"0.001\"],[\"79608.40\",\"0.644\"],[\"79609.50\",\"0.388\"],[\"79609.60\",\"0.697\"],[\"79610.10\",\"0.001\"],[\"79610.20\",\"0.002\"],[\"79610.60\",\"0.001\"],[\"79612.10\",\"2.913\"],[\"79613.30\",\"0.798\"],[\"79614.00\",\"0.457\"],[\"79614.40\",\"0.000\"],[\"79614.50\",\"0.252\"],[\"79616.90\",\"0.004\"],[\"79621.60\",\"0.627\"],[\"79622.30\",\"0.001\"],[\"79625.50\",\"0.649\"],[\"79626.40\",\"0.000\"],[\"79646.50\",\"0.003\"],[\"79652.70\",\"0.000\"],[\"79652.80\",\"0.356\"],[\"79736.40\",\"0.011\"],[\"79756.60\",\"0.137\"],[\"79962.40\",\"1.273\"],[\"79996.20\",\"4.345\"],[\"80235.00\",\"3.988\"],[\"80394.20\",\"10.445\"]],\"st\":1}}"}
{"receive_ns":1788563052683930000,"stream":"btcusdt@bookTicker","event_type":"bookTicker","event_time_ms":1788563052748,"raw_json":"{\"stream\":\"btcusdt@bookTicker\",\"data\":{\"e\":\"bookTicker\",\"u\":11478213295040,\"s\":\"BTCUSDT\",\"ps\":\"BTCUSDT\",\"b\":\"79598.10\",\"B\":\"11.068\",\"a\":\"79598.20\",\"A\":\"3.113\",\"T\":1788563052748,\"E\":1788563052748,\"st\":1}}"}
{"receive_ns":1788563052684221000,"stream":"btcusdt@trade","event_type":"trade","event_time_ms":1788563052748,"raw_json":"{\"stream\":\"btcusdt@trade\",\"data\":{\"e\":\"trade\",\"E\":1788563052748,\"T\":1788563052748,\"s\":\"BTCUSDT\",\"t\":8054081727,\"p\":\"79598.20\",\"q\":\"0.005\",\"X\":\"MARKET\",\"m\":false,\"st\":1}}"}
{"receive_ns":1788563052685126000,"stream":"btcusdt@bookTicker","event_type":"bookTicker","event_time_ms":1788563052750,"raw_json":"{\"stream\":\"btcusdt@bookTicker\",\"data\":{\"e\":\"bookTicker\",\"u\":11478213295219,\"s\":\"BTCUSDT\",\"ps\":\"BTCUSDT\",\"b\":\"79598.10\",\"B\":\"11.076\",\"a\":\"79598.20\",\"A\":\"3.113\",\"T\":1788563052750,\"E\":1788563052750,\"st\":1}}"}
{"receive_ns":1788563052686608000,"stream":"btcusdt@bookTicker","event_type":"bookTicker","event_time_ms":1788563052750,"raw_json":"{\"stream\":\"btcusdt@bookTicker\",\"data\":{\"e\":\"bookTicker\",\"u\":11478213295339,\"s\":\"BTCUSDT\",\"ps\":\"BTCUSDT\",\"b\":\"79598.10\",\"B\":\"11.068\",\"a\":\"79598.20\",\"A\":\"3.113\",\"T\":1788563052750,\"E\":1788563052750,\"st\":1}}"}
{"receive_ns":1788563052711253000,"stream":"btcusdt@bookTicker","event_type":"bookTicker","event_time_ms":1788563052776,"raw_json":"{\"stream\":\"btcusdt@bookTicker\",\"data\":{\"e\":\"bookTicker\",\"u\":11478213298055,\"s\":\"BTCUSDT\",\"ps\":\"BTCUSDT\",\"b\":\"79598.10\",\"B\":\"11.068\",\"a\":\"79598.20\",\"A\":\"3.482\",\"T\":1788563052776,\"E\":1788563052776,\"st\":1}}"}
{"receive_ns":1788563052711470000,"stream":"btcusdt@bookTicker","event_type":"bookTicker","event_time_ms":1788563052776,"raw_json":"{\"stream\":\"btcusdt@bookTicker\",\"data\":{\"e\":\"bookTicker\",\"u\":11478213298203,\"s\":\"BTCUSDT\",\"ps\":\"BTCUSDT\",\"b\":\"79598.10\",\"B\":\"11.068\",\"a\":\"79598.20\",\"A\":\"3.855\",\"T\":1788563052776,\"E\":1788563052776,\"st\":1}}"}
{"receive_ns":1788563052712213000,"stream":"btcusdt@bookTicker","event_type":"bookTicker","event_time_ms":1788563052777,"raw_json":"{\"stream\":\"btcusdt@bookTicker\",\"data\":{\"e\":\"bookTicker\",\"u\":11478213298616,\"s\":\"BTCUSDT\",\"ps\":\"BTCUSDT\",\"b\":\"79598.10\",\"B\":\"11.076\",\"a\":\"79598.20\",\"A\":\"3.855\",\"T\":1788563052777,\"E\":1788563052777,\"st\":1}}"}
{"receive_ns":1788563052712446000,"stream":"btcusdt@bookTicker","event_type":"bookTicker","event_time_ms":1788563052778,"raw_json":"{\"stream\":\"btcusdt@bookTicker\",\"data\":{\"e\":\"bookTicker\",\"u\":11478213298690,\"s\":\"BTCUSDT\",\"ps\":\"BTCUSDT\",\"b\":\"79598.10\",\"B\":\"11.076\",\"a\":\"79598.20\",\"A\":\"3.854\",\"T\":1788563052777,\"E\":1788563052778,\"st\":1}}"}
{"receive_ns":1788563052712657000,"stream":"btcusdt@bookTicker","event_type":"bookTicker","event_time_ms":1788563052778,"raw_json":"{\"stream\":\"btcusdt@bookTicker\",\"data\":{\"e\":\"bookTicker\",\"u\":11478213299357,\"s\":\"BTCUSDT\",\"ps\":\"BTCUSDT\",\"b\":\"79598.10\",\"B\":\"11.068\",\"a\":\"79598.20\",\"A\":\"3.854\",\"T\":1788563052778,\"E\":1788563052778,\"st\":1}}"}
{"receive_ns":1788563052712814000,"stream":"btcusdt@bookTicker","event_type":"bookTicker","event_time_ms":1788563052778,"raw_json":"{\"stream\":\"btcusdt@bookTicker\",\"data\":{\"e\":\"bookTicker\",\"u\":11478213299394,\"s\":\"BTCUSDT\",\"ps\":\"BTCUSDT\",\"b\":\"79598.10\",\"B\":\"11.051\",\"a\":\"79598.20\",\"A\":\"3.854\",\"T\":1788563052778,\"E\":1788563052778,\"st\":1}}"}
{"receive_ns":1788563052712963000,"stream":"btcusdt@bookTicker","event_type":"bookTicker","event_time_ms":1788563052778,"raw_json":"{\"stream\":\"btcusdt@bookTicker\",\"data\":{\"e\":\"bookTicker\",\"u\":11478213299483,\"s\":\"BTCUSDT\",\"ps\":\"BTCUSDT\",\"b\":\"79598.10\",\"B\":\"11.043\",\"a\":\"79598.20\",\"A\":\"3.854\",\"T\":1788563052778,\"E\":1788563052778,\"st\":1}}"}
{"receive_ns":1788563052713138000,"stream":"btcusdt@bookTicker","event_type":"bookTicker","event_time_ms":1788563052779,"raw_json":"{\"stream\":\"btcusdt@bookTicker\",\"data\":{\"e\":\"bookTicker\",\"u\":11478213299494,\"s\":\"BTCUSDT\",\"ps\":\"BTCUSDT\",\"b\":\"79598.10\",\"B\":\"11.012\",\"a\":\"79598.20\",\"A\":\"3.854\",\"T\":1788563052778,\"E\":1788563052779,\"st\":1}}"}
{"receive_ns":1788563052713311000,"stream":"btcusdt@bookTicker","event_type":"bookTicker","event_time_ms":1788563052779,"raw_json":"{\"stream\":\"btcusdt@bookTicker\",\"data\":{\"e\":\"bookTicker\",\"u\":11478213299531,\"s\":\"BTCUSDT\",\"ps\":\"BTCUSDT\",\"b\":\"79598.10\",\"B\":\"11.020\",\"a\":\"79598.20\",\"A\":\"3.854\",\"T\":1788563052778,\"E\":1788563052779,\"st\":1}}"}
{"receive_ns":1788563052713474000,"stream":"btcusdt@bookTicker","event_type":"bookTicker","event_time_ms":1788563052780,"raw_json":"{\"stream\":\"btcusdt@bookTicker\",\"data\":{\"e\":\"bookTicker\",\"u\":11478213300168,\"s\":\"BTCUSDT\",\"ps\":\"BTCUSDT\",\"b\":\"79598.10\",\"B\":\"10.920\",\"a\":\"79598.20\",\"A\":\"3.854\",\"T\":1788563052779,\"E\":1788563052780,\"st\":1}}"}
{"receive_ns":1788563052714762000,"stream":"btcusdt@bookTicker","event_type":"bookTicker","event_time_ms":1788563052780,"raw_json":"{\"stream\":\"btcusdt@bookTicker\",\"data\":{\"e\":\"bookTicker\",\"u\":11478213300252,\"s\":\"BTCUSDT\",\"ps\":\"BTCUSDT\",\"b\":\"79598.10\",\"B\":\"10.912\",\"a\":\"79598.20\",\"A\":\"3.854\",\"T\":1788563052780,\"E\":1788563052780,\"st\":1}}"}
{"receive_ns":1788563052725189000,"stream":"btcusdt@bookTicker","event_type":"bookTicker","event_time_ms":1788563052788,"raw_json":"{\"stream\":\"btcusdt@bookTicker\",\"data\":{\"e\":\"bookTicker\",\"u\":11478213304550,\"s\":\"BTCUSDT\",\"ps\":\"BTCUSDT\",\"b\":\"79598.10\",\"B\":\"10.872\",\"a\":\"79598.20\",\"A\":\"3.854\",\"T\":1788563052788,\"E\":1788563052788,\"st\":1}}"}
{"receive_ns":1788563052725564000,"stream":"btcusdt@bookTicker","event_type":"bookTicker","event_time_ms":1788563052790,"raw_json":"{\"stream\":\"btcusdt@bookTicker\",\"data\":{\"e\":\"bookTicker\",\"u\":11478213304860,\"s\":\"BTCUSDT\",\"ps\":\"BTCUSDT\",\"b\":\"79598.10\",\"B\":\"10.432\",\"a\":\"79598.20\",\"A\":\"3.854\",\"T\":1788563052790,\"E\":1788563052790,\"st\":1}}"}
{"receive_ns":1788563052727545000,"stream":"btcusdt@bookTicker","event_type":"bookTicker","event_time_ms":1788563052791,"raw_json":"{\"stream\":\"btcusdt@bookTicker\",\"data\":{\"e\":\"bookTicker\",\"u\":11478213305010,\"s\":\"BTCUSDT\",\"ps\":\"BTCUSDT\",\"b\":\"79598.10\",\"B\":\"10.432\",\"a\":\"79598.20\",\"A\":\"3.855\",\"T\":1788563052791,\"E\":1788563052791,\"st\":1}}"}
{"receive_ns":1788563052727792000,"stream":"btcusdt@bookTicker","event_type":"bookTicker","event_time_ms":1788563052792,"raw_json":"{\"stream\":\"btcusdt@bookTicker\",\"data\":{\"e\":\"bookTicker\",\"u\":11478213305157,\"s\":\"BTCUSDT\",\"ps\":\"BTCUSDT\",\"b\":\"79598.10\",\"B\":\"10.432\",\"a\":\"79598.20\",\"A\":\"4.225\",\"T\":1788563052792,\"E\":1788563052792,\"st\":1}}"}
{"receive_ns":1788563052731448000,"stream":"btcusdt@bookTicker","event_type":"bookTicker","event_time_ms":1788563052794,"raw_json":"{\"stream\":\"btcusdt@bookTicker\",\"data\":{\"e\":\"bookTicker\",\"u\":11478213305360,\"s\":\"BTCUSDT\",\"ps\":\"BTCUSDT\",\"b\":\"79598.10\",\"B\":\"10.432\",\"a\":\"79598.20\",\"A\":\"4.226\",\"T\":1788563052793,\"E\":1788563052794,\"st\":1}}"}
{"receive_ns":1788563052740089000,"stream":"btcusdt@depth@100ms","event_type":"depthUpdate","event_time_ms":1788563052803,"raw_json":"{\"stream\":\"btcusdt@depth@100ms\",\"data\":{\"e\":\"depthUpdate\",\"E\":1788563052803,\"T\":1788563052802,\"s\":\"BTCUSDT\",\"ps\":\"BTCUSDT\",\"U\":11478213291447,\"u\":11478213306481,\"pu\":11478213290874,\"b\":[[\"29298.10\",\"0.497\"],[\"29398.10\",\"1.603\"],[\"63678.50\",\"0.000\"],[\"71638.20\",\"0.002\"],[\"76414.10\",\"0.002\"],[\"78430.20\",\"0.509\"],[\"78523.50\",\"2.928\"],[\"78532.20\",\"0.223\"],[\"78582.90\",\"0.000\"],[\"78587.80\",\"0.012\"],[\"78614.70\",\"0.000\"],[\"78619.50\",\"0.002\"],[\"78638.50\",\"21.540\"],[\"78802.10\",\"10.279\"],[\"78961.30\",\"3.286\"],[\"79200.10\",\"3.742\"],[\"79401.10\",\"0.000\"],[\"79428.40\",\"0.317\"],[\"79460.70\",\"0.010\"],[\"79473.60\",\"0.803\"],[\"79485.60\",\"0.000\"],[\"79492.60\",\"1.508\"],[\"79494.60\",\"0.000\"],[\"79519.60\",\"0.060\"],[\"79531.30\",\"22.416\"],[\"79535.30\",\"0.291\"],[\"79536.70\",\"0.000\"],[\"79563.30\",\"0.047\"],[\"79563.50\",\"10.003\"],[\"79564.40\",\"0.001\"],[\"79565.70\",\"0.001\"],[\"79568.20\",\"0.001\"],[\"79572.00\",\"2.445\"],[\"79572.10\",\"0.518\"],[\"79572.20\",\"0.004\"],[\"79573.10\",\"0.070\"],[\"79573.30\",\"0.373\"],[\"79573.60\",\"0.000\"],[\"79574.60\",\"0.099\"],[\"79575.30\",\"0.001\"],[\"79576.90\",\"4.927\"],[\"79577.60\",\"0.000\"],[\"79579.00\",\"0.000\"],[\"79581.00\",\"0.634\"],[\"79581.10\",\"0.318\"],[\"79581.50\",\"0.001\"],[\"79581.60\",\"0.002\"],[\"79581.90\",\"0.000\"],[\"79582.10\",\"0.010\"],[\"79582.90\",\"0.080\"],[\"79583.60\",\"0.002\"],[\"79583.70\",\"0.001\"],[\"79585.30\",\"0.090\"],[\"79585.70\",\"0.000\"],[\"79586.30\",\"0.000\"],[\"79587.70\",\"0.000\"],[\"79587.80\",\"0.145\"],[\"79588.60\",\"0.104\"],[\"79589.20\",\"0.160\"],[\"79592.00\",\"0.291\"],[\"79592.20\",\"0.005\"],[\"79594.00\",\"0.030\"],[\"79594.20\",\"0.124\"],[\"79595.20\",\"0.001\"],[\"79596.60\",\"0.076\"],[\"79596.70\",\"0.000\"],[\"79598.10\",\"10.432\"]],\"a\":[[\"79598.20\",\"4.226\"],[\"79598.90\",\"0.000\"],[\"79599.30\",\"0.028\"],[\"79599.60\",\"0.026\"],[\"79599.70\",\"0.026\"],[\"79599.90\",\"0.036\"],[\"79600.20\",\"0.027\"],[\"79600.60\",\"0.000\"],[\"79600.80\",\"0.027\"],[\"79601.00\",\"0.034\"],[\"79601.10\",\"0.029\"],[\"79602.20\",\"0.003\"],[\"79602.30\",\"0.000\"],[\"79602.80\",\"0.000\"],[\"79602.90\",\"0.001\"],[\"79603.00\",\"0.000\"],[\"79603.10\",\"0.000\"],[\"79603.30\",\"0.000\"],[\"79609.50\",\"0.322\"],[\"79609.60\",\"0.258\"],[\"79610.10\",\"0.005\"],[\"79610.20\",\"0.064\"],[\"79610.60\",\"0.001\"],[\"79611.40\",\"0.859\"],[\"79612.10\",\"2.541\"],[\"79613.30\",\"0.798\"],[\"79614.00\",\"0.005\"],[\"79614.50\",\"0.624\"],[\"79615.30\",\"0.001\"],[\"79617.00\",\"0.457\"],[\"79627.10\",\"0.046\"],[\"79627.90\",\"0.000\"],[\"79629.40\",\"0.780\"],[\"79634.20\",\"10.002\"],[\"79640.90\",\"0.191\"],[\"79641.00\",\"0.002\"],[\"79646.40\",\"0.334\"],[\"79653.00\",\"0.060\"],[\"79667.80\",\"0.000\"],[\"79676.70\",\"0.017\"],[\"79735.50\",\"0.024\"],[\"79736.40\",\"0.011\"],[\"79756.60\",\"0.137\"],[\"79842.70\",\"0.004\"],[\"79962.40\",\"0.509\"],[\"79996.20\",\"4.145\"],[\"80394.20\",\"10.445\"],[\"80483.10\",\"0.152\"],[\"80514.30\",\"15.534\"],[\"80553.40\",\"21.562\"],[\"81031.00\",\"0.616\"],[\"81190.10\",\"0.014\"]],\"st\":1}}"}
{"receive_ns":1788563052779332000,"stream":"btcusdt@bookTicker","event_type":"bookTicker","event_time_ms":1788563052843,"raw_json":"{\"stream\":\"btcusdt@bookTicker\",\"data\":{\"e\":\"bookTicker\",\"u\":11478213310281,\"s\":\"BTCUSDT\",\"ps\":\"BTCUSDT\",\"b\":\"79598.10\",\"B\":\"10.424\",\"a\":\"79598.20\",\"A\":\"4.226\",\"T\":1788563052843,\"E\":1788563052843,\"st\":1}}"}
{"receive_ns":1788563052780514000,"stream":"btcusdt@bookTicker","event_type":"bookTicker","event_time_ms":1788563052845,"raw_json":"{\"stream\":\"btcusdt@bookTicker\",\"data\":{\"e\":\"bookTicker\",\"u\":11478213310393,\"s\":\"BTCUSDT\",\"ps\":\"BTCUSDT\",\"b\":\"79598.10\",\"B\":\"10.424\",\"a\":\"79598.20\",\"A\":\"4.274\",\"T\":1788563052844,\"E\":1788563052845,\"st\":1}}"}
{"receive_ns":1788563052781638000,"stream":"btcusdt@bookTicker","event_type":"bookTicker","event_time_ms":1788563052846,"raw_json":"{\"stream\":\"btcusdt@bookTicker\",\"data\":{\"e\":\"bookTicker\",\"u\":11478213310530,\"s\":\"BTCUSDT\",\"ps\":\"BTCUSDT\",\"b\":\"79598.10\",\"B\":\"10.424\",\"a\":\"79598.20\",\"A\":\"4.273\",\"T\":1788563052846,\"E\":1788563052846,\"st\":1}}"}
{"receive_ns":1788563052821118000,"stream":"btcusdt@bookTicker","event_type":"bookTicker","event_time_ms":1788563052884,"raw_json":"{\"stream\":\"btcusdt@bookTicker\",\"data\":{\"e\":\"bookTicker\",\"u\":11478213314040,\"s\":\"BTCUSDT\",\"ps\":\"BTCUSDT\",\"b\":\"79598.10\",\"B\":\"10.408\",\"a\":\"79598.20\",\"A\":\"4.273\",\"T\":1788563052883,\"E\":1788563052884,\"st\":1}}"}
{"receive_ns":1788563052847826000,"stream":"btcusdt@depth@100ms","event_type":"depthUpdate","event_time_ms":1788563052905,"raw_json":"{\"stream\":\"btcusdt@depth@100ms\",\"data\":{\"e\":\"depthUpdate\",\"E\":1788563052905,\"T\":1788563052902,\"s\":\"BTCUSDT\",\"ps\":\"BTCUSDT\",\"U\":11478213306694,\"u\":11478213315186,\"pu\":11478213306481,\"b\":[[\"1000.00\",\"24.604\"],[\"29298.10\",\"0.672\"],[\"29398.10\",\"1.428\"],[\"71638.20\",\"0.002\"],[\"78282.40\",\"0.002\"],[\"78443.90\",\"6.467\"],[\"78678.30\",\"2.424\"],[\"78682.70\",\"4.674\"],[\"78802.10\",\"10.279\"],[\"78844.10\",\"0.570\"],[\"79200.10\",\"3.732\"],[\"79401.10\",\"1.412\"],[\"79494.60\",\"0.251\"],[\"79496.60\",\"0.000\"],[\"79519.60\",\"0.000\"],[\"79529.00\",\"0.060\"],[\"79531.30\",\"0.011\"],[\"79534.00\",\"22.406\"],[\"79571.90\",\"0.373\"],[\"79572.00\",\"1.081\"],[\"79573.30\",\"0.000\"],[\"79575.80\",\"0.586\"],[\"79581.10\",\"0.319\"],[\"79581.20\",\"1.293\"],[\"79583.30\",\"0.762\"],[\"79586.90\",\"0.002\"],[\"79587.50\",\"0.004\"],[\"79587.80\",\"0.141\"],[\"79588.90\",\"0.174\"],[\"79592.20\",\"0.001\"],[\"79598.10\",\"10.408\"]],\"a\":[[\"79598.20\",\"4.273\"],[\"79598.90\",\"0.076\"],[\"79599.00\",\"0.027\"],[\"79599.10\",\"0.028\"],[\"79601.30\",\"0.000\"],[\"79602.00\",\"0.077\"],[\"79608.30\",\"0.001\"],[\"79609.40\",\"0.315\"],[\"79609.50\",\"0.013\"],[\"79609.60\",\"0.697\"],[\"79610.10\",\"0.001\"],[\"79610.20\",\"0.064\"],[\"79611.40\",\"0.420\"],[\"79613.90\",\"0.000\"],[\"79615.30\",\"0.453\"],[\"79617.00\",\"0.005\"],[\"79634.30\",\"0.089\"],[\"79636.10\",\"0.002\"],[\"79641.00\",\"0.001\"],[\"79646.50\",\"0.130\"],[\"79646.60\",\"0.002\"],[\"79653.00\",\"0.000\"],[\"79661.80\",\"0.081\"],[\"79733.90\",\"0.127\"],[\"79735.50\",\"0.275\"],[\"79962.40\",\"1.273\"],[\"79996.20\",\"4.345\"],[\"80394.20\",\"10.445\"],[\"80752.40\",\"7.918\"]],\"st\":1}}"}
{"receive_ns":1788563052912324000,"stream":"btcusdt@bookTicker","event_type":"bookTicker","event_time_ms":1788563052975,"raw_json":"{\"stream\":\"btcusdt@bookTicker\",\"data\":{\"e\":\"bookTicker\",\"u\":11478213319331,\"s\":\"BTCUSDT\",\"ps\":\"BTCUSDT\",\"b\":\"79598.10\",\"B\":\"10.408\",\"a\":\"79598.20\",\"A\":\"4.225\",\"T\":1788563052975,\"E\":1788563052975,\"st\":1}}"}
{"receive_ns":1788563052938207000,"stream":"btcusdt@bookTicker","event_type":"bookTicker","event_time_ms":1788563053002,"raw_json":"{\"stream\":\"btcusdt@bookTicker\",\"data\":{\"e\":\"bookTicker\",\"u\":11478213320785,\"s\":\"BTCUSDT\",\"ps\":\"BTCUSDT\",\"b\":\"79598.10\",\"B\":\"10.397\",\"a\":\"79598.20\",\"A\":\"4.225\",\"T\":1788563053002,\"E\":1788563053002,\"st\":1}}"}
{"receive_ns":1788563052943137000,"stream":"btcusdt@depth@100ms","event_type":"depthUpdate","event_time_ms":1788563053007,"raw_json":"{\"stream\":\"btcusdt@depth@100ms\",\"data\":{\"e\":\"depthUpdate\",\"E\":1788563053007,\"T\":1788563053006,\"s\":\"BTCUSDT\",\"ps\":\"BTCUSDT\",\"U\":11478213315397,\"u\":11478213321033,\"pu\":11478213315186,\"b\":[[\"29298.10\",\"0.854\"],[\"29398.10\",\"1.246\"],[\"71638.20\",\"0.002\"],[\"76414.10\",\"0.000\"],[\"78284.70\",\"1.939\"],[\"78802.10\",\"10.281\"],[\"79200.10\",\"3.732\"],[\"79473.60\",\"0.602\"],[\"79492.60\",\"0.001\"],[\"79529.00\",\"0.000\"],[\"79537.90\",\"0.261\"],[\"79572.90\",\"0.628\"],[\"79573.10\",\"0.064\"],[\"79573.50\",\"0.000\"],[\"79574.40\",\"0.050\"],[\"79578.40\",\"0.418\"],[\"79580.70\",\"0.628\"],[\"79581.00\",\"0.006\"],[\"79598.10\",\"10.397\"]],\"a\":[[\"79598.20\",\"4.225\"],[\"79598.90\",\"0.076\"],[\"79599.00\",\"0.001\"],[\"79599.10\",\"0.002\"],[\"79600.00\",\"0.154\"],[\"79601.10\",\"0.003\"],[\"79608.10\",\"0.513\"],[\"79612.40\",\"0.372\"],[\"79614.30\",\"0.361\"],[\"79614.50\",\"0.252\"],[\"79620.80\",\"1.005\"],[\"79621.60\",\"0.000\"],[\"79628.90\",\"0.627\"],[\"79630.10\",\"0.032\"],[\"79646.40\",\"0.461\"],[\"79646.50\",\"0.003\"],[\"79665.80\",\"0.043\"],[\"79680.40\",\"0.000\"],[\"79962.40\",\"0.854\"],[\"79996.20\",\"3.819\"],[\"80513.60\",\"0.125\"]],\"st\":1}}"}
{"receive_ns":1788563053004506000,"stream":"btcusdt@bookTicker","event_type":"bookTicker","event_time_ms":1788563053062,"raw_json":"{\"stream\":\"btcusdt@bookTicker\",\"data\":{\"e\":\"bookTicker\",\"u\":11478213324152,\"s\":\"BTCUSDT\",\"ps\":\"BTCUSDT\",\"b\":\"79598.10\",\"B\":\"10.359\",\"a\":\"79598.20\",\"A\":\"4.225\",\"T\":1788563053061,\"E\":1788563053062,\"st\":1}}"}
{"receive_ns":1788563053005380000,"stream":"btcusdt@bookTicker","event_type":"bookTicker","event_time_ms":1788563053065,"raw_json":"{\"stream\":\"btcusdt@bookTicker\",\"data\":{\"e\":\"bookTicker\",\"u\":11478213324325,\"s\":\"BTCUSDT\",\"ps\":\"BTCUSDT\",\"b\":\"79598.10\",\"B\":\"10.400\",\"a\":\"79598.20\",\"A\":\"4.225\",\"T\":1788563053065,\"E\":1788563053065,\"st\":1}}"}
{"receive_ns":1788563053005699000,"stream":"btcusdt@bookTicker","event_type":"bookTicker","event_time_ms":1788563053066,"raw_json":"{\"stream\":\"btcusdt@bookTicker\",\"data\":{\"e\":\"bookTicker\",\"u\":11478213324376,\"s\":\"BTCUSDT\",\"ps\":\"BTCUSDT\",\"b\":\"79598.10\",\"B\":\"10.400\",\"a\":\"79598.20\",\"A\":\"4.226\",\"T\":1788563053066,\"E\":1788563053066,\"st\":1}}"}
{"receive_ns":1788563053117268000,"stream":"btcusdt@depth@100ms","event_type":"depthUpdate","event_time_ms":1788563053109,"raw_json":"{\"stream\":\"btcusdt@depth@100ms\",\"data\":{\"e\":\"depthUpdate\",\"E\":1788563053109,\"T\":1788563053105,\"s\":\"BTCUSDT\",\"ps\":\"BTCUSDT\",\"U\":11478213321087,\"u\":11478213326211,\"pu\":11478213321033,\"b\":[[\"29298.10\",\"1.029\"],[\"29398.10\",\"1.071\"],[\"71638.20\",\"0.002\"],[\"75618.30\",\"0.004\"],[\"76414.10\",\"0.002\"],[\"78372.50\",\"0.012\"],[\"78380.60\",\"0.023\"],[\"78428.00\",\"1.527\"],[\"78587.80\",\"0.008\"],[\"78590.30\",\"0.005\"],[\"78596.40\",\"0.000\"],[\"78606.10\",\"0.004\"],[\"78682.70\",\"5.436\"],[\"78802.10\",\"10.279\"],[\"78841.90\",\"6.432\"],[\"79401.10\",\"0.834\"],[\"79404.00\",\"1.215\"],[\"79472.70\",\"2.552\"],[\"79473.90\",\"0.368\"],[\"79492.60\",\"1.332\"],[\"79494.60\",\"0.000\"],[\"79563.30\",\"0.001\"],[\"79564.00\",\"0.185\"],[\"79565.20\",\"0.102\"],[\"79571.90\",\"0.000\"],[\"79572.10\",\"0.079\"],[\"79573.00\",\"0.001\"],[\"79573.10\",\"0.503\"],[\"79573.50\",\"0.373\"],[\"79574.90\",\"0.000\"],[\"79578.60\",\"0.039\"],[\"79581.80\",\"0.000\"],[\"79583.80\",\"0.000\"],[\"79590.30\",\"0.110\"],[\"79590.50\",\"0.001\"],[\"79596.60\",\"0.000\"],[\"79597.50\",\"0.026\"],[\"79597.60\",\"0.200\"],[\"79597.70\",\"0.026\"],[\"79598.00\",\"0.009\"],[\"79598.10\",\"10.400\"]],\"a\":[[\"79598.20\",\"4.226\"],[\"79598.60\",\"0.026\"],[\"79603.10\",\"0.000\"],[\"79608.10\",\"0.262\"],[\"79609.50\",\"0.013\"],[\"79609.60\",\"0.258\"],[\"79610.20\",\"0.064\"],[\"79610.90\",\"1.179\"],[\"79612.40\",\"0.000\"],[\"79613.20\",\"0.432\"],[\"79613.40\",\"0.003\"],[\"79614.40\",\"0.000\"],[\"79627.10\",\"0.000\"],[\"79628.00\",\"2.004\"],[\"79628.90\",\"0.673\"],[\"79735.50\",\"0.275\"],[\"79962.40\",\"1.273\"],[\"79996.20\",\"4.345\"],[\"80356.60\",\"1.303\"],[\"80394.20\",\"10.445\"],[\"80815.70\",\"0.008\"],[\"80823.70\",\"0.000\"]],\"st\":1}}"}
{"receive_ns":1788563053117544000,"stream":"btcusdt@bookTicker","event_type":"bookTicker","event_time_ms":1788563053122,"raw_json":"{\"stream\":\"btcusdt@bookTicker\",\"data\":{\"e\":\"bookTicker\",\"u\":11478213326995,\"s\":\"BTCUSDT\",\"ps\":\"BTCUSDT\",\"b\":\"79598.10\",\"B\":\"10.339\",\"a\":\"79598.20\",\"A\":\"4.226\",\"T\":1788563053122,\"E\":1788563053122,\"st\":1}}"}
{"receive_ns":1788563053117716000,"stream":"btcusdt@bookTicker","event_type":"bookTicker","event_time_ms":1788563053125,"raw_json":"{\"stream\":\"btcusdt@bookTicker\",\"data\":{\"e\":\"bookTicker\",\"u\":11478213327145,\"s\":\"BTCUSDT\",\"ps\":\"BTCUSDT\",\"b\":\"79598.10\",\"B\":\"10.402\",\"a\":\"79598.20\",\"A\":\"4.226\",\"T\":1788563053125,\"E\":1788563053125,\"st\":1}}"}
{"receive_ns":1788563053117879000,"stream":"btcusdt@bookTicker","event_type":"bookTicker","event_time_ms":1788563053126,"raw_json":"{\"stream\":\"btcusdt@bookTicker\",\"data\":{\"e\":\"bookTicker\",\"u\":11478213327221,\"s\":\"BTCUSDT\",\"ps\":\"BTCUSDT\",\"b\":\"79598.10\",\"B\":\"10.401\",\"a\":\"79598.20\",\"A\":\"4.226\",\"T\":1788563053126,\"E\":1788563053126,\"st\":1}}"}
{"receive_ns":1788563053118099000,"stream":"btcusdt@bookTicker","event_type":"bookTicker","event_time_ms":1788563053127,"raw_json":"{\"stream\":\"btcusdt@bookTicker\",\"data\":{\"e\":\"bookTicker\",\"u\":11478213327264,\"s\":\"BTCUSDT\",\"ps\":\"BTCUSDT\",\"b\":\"79598.10\",\"B\":\"10.402\",\"a\":\"79598.20\",\"A\":\"4.226\",\"T\":1788563053127,\"E\":1788563053127,\"st\":1}}"}
{"receive_ns":1788563053140496000,"stream":"btcusdt@bookTicker","event_type":"bookTicker","event_time_ms":1788563053201,"raw_json":"{\"stream\":\"btcusdt@bookTicker\",\"data\":{\"e\":\"bookTicker\",\"u\":11478213330899,\"s\":\"BTCUSDT\",\"ps\":\"BTCUSDT\",\"b\":\"79598.10\",\"B\":\"10.307\",\"a\":\"79598.20\",\"A\":\"4.226\",\"T\":1788563053201,\"E\":1788563053201,\"st\":1}}"}
{"receive_ns":1788563053152946000,"stream":"btcusdt@bookTicker","event_type":"bookTicker","event_time_ms":1788563053204,"raw_json":"{\"stream\":\"btcusdt@bookTicker\",\"data\":{\"e\":\"bookTicker\",\"u\":11478213331062,\"s\":\"BTCUSDT\",\"ps\":\"BTCUSDT\",\"b\":\"79598.10\",\"B\":\"10.408\",\"a\":\"79598.20\",\"A\":\"4.226\",\"T\":1788563053204,\"E\":1788563053204,\"st\":1}}"}
{"receive_ns":1788563053153350000,"stream":"btcusdt@depth@100ms","event_type":"depthUpdate","event_time_ms":1788563053211,"raw_json":"{\"stream\":\"btcusdt@depth@100ms\",\"data\":{\"e\":\"depthUpdate\",\"E\":1788563053211,\"T\":1788563053209,\"s\":\"BTCUSDT\",\"ps\":\"BTCUSDT\",\"U\":11478213326445,\"u\":11478213331355,\"pu\":11478213326211,\"b\":[[\"1000.00\",\"24.604\"],[\"29298.10\",\"1.211\"],[\"29398.10\",\"0.889\"],[\"71638.20\",\"0.002\"],[\"75618.30\",\"0.002\"],[\"76414.10\",\"0.000\"],[\"78359.90\",\"8.039\"],[\"78364.30\",\"4.469\"],[\"78372.60\",\"0.010\"],[\"78380.60\",\"0.030\"],[\"78563.30\",\"2.829\"],[\"78583.70\",\"2.833\"],[\"78802.10\",\"10.279\"],[\"78841.90\",\"7.001\"],[\"79200.10\",\"3.602\"],[\"79461.40\",\"0.125\"],[\"79591.70\",\"0.822\"],[\"79591.80\",\"0.003\"],[\"79596.90\",\"0.271\"],[\"79597.80\",\"0.027\"],[\"79598.00\",\"0.035\"],[\"79598.10\",\"10.408\"]],\"a\":[[\"79598.60\",\"0.000\"],[\"79675.30\",\"0.004\"],[\"79675.40\",\"0.650\"],[\"79684.80\",\"0.001\"],[\"79685.00\",\"0.000\"],[\"79698.90\",\"0.001\"],[\"79699.10\",\"2.493\"],[\"79699.30\",\"0.001\"],[\"79703.30\",\"1.182\"],[\"79757.00\",\"0.000\"],[\"79757.20\",\"0.126\"],[\"79996.20\",\"4.344\"],[\"80394.20\",\"10.445\"],[\"80823.80\",\"0.008\"],[\"81190.10\",\"0.011\"]],\"st\":1}}"}
{"receive_ns":1788563053247578000,"stream":"btcusdt@depth@100ms","event_type":"depthUpdate","event_time_ms":1788563053313,"raw_json":"{\"stream\":\"btcusdt@depth@100ms\",\"data\":{\"e\":\"depthUpdate\",\"E\":1788563053313,\"T\":1788563053312,\"s\":\"BTCUSDT\",\"ps\":\"BTCUSDT\",\"U\":11478213331446,\"u\":11478213337766,\"pu\":11478213331355,\"b\":[[\"29298.10\",\"1.386\"],[\"29398.10\",\"0.714\"],[\"71638.20\",\"0.002\"],[\"76414.10\",\"0.002\"],[\"78642.90\",\"21.940\"],[\"78802.10\",\"10.279\"],[\"79200.10\",\"3.743\"],[\"79401.10\",\"0.000\"],[\"79404.00\",\"1.014\"],[\"79439.80\",\"0.202\"],[\"79461.40\",\"0.000\"],[\"79472.70\",\"1.547\"],[\"79492.60\",\"0.001\"],[\"79494.60\",\"1.507\"],[\"79563.10\",\"0.050\"],[\"79564.00\",\"0.139\"],[\"79572.10\",\"0.079\"],[\"79572.30\",\"0.021\"],[\"79573.00\",\"0.440\"],[\"79573.10\",\"0.064\"],[\"79573.50\",\"0.373\"],[\"79578.00\",\"0.004\"],[\"79581.10\",\"0.315\"],[\"79581.40\",\"0.005\"],[\"79583.40\",\"0.033\"],[\"79588.90\",\"0.170\"],[\"79589.30\",\"0.037\"],[\"79594.10\",\"0.526\"]],\"a\":[[\"79599.00\",\"0.001\"],[\"79599.30\",\"0.002\"],[\"79599.60\",\"0.000\"],[\"79599.70\",\"0.000\"],[\"79599.90\",\"0.010\"],[\"79600.00\",\"0.128\"],[\"79600.30\",\"0.031\"],[\"79600.40\",\"0.319\"],[\"79600.50\",\"0.512\"],[\"79601.10\",\"0.029\"],[\"79601.20\",\"0.027\"],[\"79609.60\",\"0.258\"],[\"79610.20\",\"0.503\"],[\"79610.90\",\"0.740\"],[\"79626.90\",\"0.056\"],[\"79627.60\",\"0.071\"],[\"79628.90\",\"0.627\"],[\"79636.40\",\"1.175\"],[\"79646.00\",\"0.032\"],[\"79735.50\",\"0.275\"],[\"79736.40\",\"0.211\"],[\"79757.20\",\"0.001\"],[\"79962.40\",\"0.419\"],[\"79996.20\",\"4.144\"],[\"80354.40\",\"4.285\"],[\"80394.20\",\"10.445\"],[\"80553.40\",\"22.182\"],[\"80815.70\",\"0.015\"],[\"80901.90\",\"0.001\"]],\"st\":1}}"}
{"receive_ns":1788563053351753000,"stream":"btcusdt@depth@100ms","event_type":"depthUpdate","event_time_ms":1788563053415,"raw_json":"{\"stream\":\"btcusdt@depth@100ms\",\"data\":{\"e\":\"depthUpdate\",\"E\":1788563053415,\"T\":1788563053414,\"s\":\"BTCUSDT\",\"ps\":\"BTCUSDT\",\"U\":11478213337863,\"u\":11478213344918,\"pu\":11478213337766,\"b\":[[\"29298.10\",\"1.568\"],[\"29398.10\",\"0.532\"],[\"63678.00\",\"0.004\"],[\"71638.20\",\"0.002\"],[\"71675.00\",\"0.005\"],[\"75618.20\",\"0.004\"],[\"78364.30\",\"5.361\"],[\"78563.30\",\"3.083\"],[\"78583.70\",\"2.642\"],[\"78802.10\",\"10.279\"],[\"79401.10\",\"0.332\"],[\"79423.40\",\"0.010\"],[\"79472.70\",\"2.552\"],[\"79492.60\",\"0.327\"],[\"79500.40\",\"0.319\"],[\"79563.10\",\"0.004\"],[\"79564.30\",\"0.298\"],[\"79573.00\",\"0.440\"],[\"79574.90\",\"0.000\"]],\"a\":[[\"79599.70\",\"0.026\"],[\"79610.20\",\"0.064\"],[\"79611.00\",\"1.130\"],[\"79613.20\",\"0.060\"],[\"79614.40\",\"0.372\"],[\"79615.30\",\"0.001\"],[\"79616.90\",\"0.456\"],[\"79620.80\",\"0.378\"],[\"79621.10\",\"3.847\"],[\"79626.90\",\"0.010\"],[\"79628.10\",\"0.016\"],[\"79629.00\",\"0.047\"],[\"79685.80\",\"0.033\"],[\"79687.80\",\"0.073\"],[\"79735.50\",\"0.526\"],[\"79962.40\",\"1.273\"],[\"79996.20\",\"4.344\"],[\"80354.40\",\"4.781\"],[\"80394.20\",\"10.445\"],[\"80899.60\",\"3.332\"]],\"st\":1}}"}
{"receive_ns":1788563053359574000,"stream":"btcusdt@bookTicker","event_type":"bookTicker","event_time_ms":1788563053424,"raw_json":"{\"stream\":\"btcusdt@bookTicker\",\"data\":{\"e\":\"bookTicker\",\"u\":11478213345460,\"s\":\"BTCUSDT\",\"ps\":\"BTCUSDT\",\"b\":\"79598.10\",\"B\":\"10.408\",\"a\":\"79598.20\",\"A\":\"4.228\",\"T\":1788563053424,\"E\":1788563053424,\"st\":1}}"}
{"receive_ns":1788563053420384000,"stream":"btcusdt@bookTicker","event_type":"bookTicker","event_time_ms":1788563053484,"raw_json":"{\"stream\":\"btcusdt@bookTicker\",\"data\":{\"e\":\"bookTicker\",\"u\":11478213349837,\"s\":\"BTCUSDT\",\"ps\":\"BTCUSDT\",\"b\":\"79598.10\",\"B\":\"10.419\",\"a\":\"79598.20\",\"A\":\"4.228\",\"T\":1788563053484,\"E\":1788563053484,\"st\":1}}"}
{"receive_ns":1788563053442345000,"stream":"btcusdt@bookTicker","event_type":"bookTicker","event_time_ms":1788563053506,"raw_json":"{\"stream\":\"btcusdt@bookTicker\",\"data\":{\"e\":\"bookTicker\",\"u\":11478213351598,\"s\":\"BTCUSDT\",\"ps\":\"BTCUSDT\",\"b\":\"79598.10\",\"B\":\"10.419\",\"a\":\"79598.20\",\"A\":\"3.041\",\"T\":1788563053506,\"E\":1788563053506,\"st\":1}}"}
{"receive_ns":1788563053443357000,"stream":"btcusdt@bookTicker","event_type":"bookTicker","event_time_ms":1788563053508,"raw_json":"{\"stream\":\"btcusdt@bookTicker\",\"data\":{\"e\":\"bookTicker\",\"u\":11478213351717,\"s\":\"BTCUSDT\",\"ps\":\"BTCUSDT\",\"b\":\"79598.10\",\"B\":\"10.419\",\"a\":\"79598.20\",\"A\":\"3.040\",\"T\":1788563053507,\"E\":1788563053508,\"st\":1}}"}
{"receive_ns":1788563053443541000,"stream":"btcusdt@bookTicker","event_type":"bookTicker","event_time_ms":1788563053508,"raw_json":"{\"stream\":\"btcusdt@bookTicker\",\"data\":{\"e\":\"bookTicker\",\"u\":11478213351757,\"s\":\"BTCUSDT\",\"ps\":\"BTCUSDT\",\"b\":\"79598.10\",\"B\":\"10.427\",\"a\":\"79598.20\",\"A\":\"3.040\",\"T\":1788563053507,\"E\":1788563053508,\"st\":1}}"}
{"receive_ns":1788563053451962000,"stream":"btcusdt@bookTicker","event_type":"bookTicker","event_time_ms":1788563053508,"raw_json":"{\"stream\":\"btcusdt@bookTicker\",\"data\":{\"e\":\"bookTicker\",\"u\":11478213351890,\"s\":\"BTCUSDT\",\"ps\":\"BTCUSDT\",\"b\":\"79598.10\",\"B\":\"10.419\",\"a\":\"79598.20\",\"A\":\"3.040\",\"T\":1788563053508,\"E\":1788563053508,\"st\":1}}"}
{"receive_ns":1788563053452212000,"stream":"btcusdt@bookTicker","event_type":"bookTicker","event_time_ms":1788563053509,"raw_json":"{\"stream\":\"btcusdt@bookTicker\",\"data\":{\"e\":\"bookTicker\",\"u\":11478213351942,\"s\":\"BTCUSDT\",\"ps\":\"BTCUSDT\",\"b\":\"79598.10\",\"B\":\"10.419\",\"a\":\"79598.20\",\"A\":\"3.041\",\"T\":1788563053509,\"E\":1788563053509,\"st\":1}}"}
{"receive_ns":1788563053453410000,"stream":"btcusdt@depth@100ms","event_type":"depthUpdate","event_time_ms":1788563053517,"raw_json":"{\"stream\":\"btcusdt@depth@100ms\",\"data\":{\"e\":\"depthUpdate\",\"E\":1788563053517,\"T\":1788563053513,\"s\":\"BTCUSDT\",\"ps\":\"BTCUSDT\",\"U\":11478213345065,\"u\":11478213352285,\"pu\":11478213344918,\"b\":[[\"1000.00\",\"24.604\"],[\"29298.10\",\"1.743\"],[\"29398.10\",\"0.357\"],[\"71638.20\",\"0.002\"],[\"71675.00\",\"0.002\"],[\"75618.20\",\"0.006\"],[\"76414.10\",\"0.000\"],[\"78475.80\",\"2.161\"],[\"78802.10\",\"10.279\"],[\"79200.10\",\"3.733\"],[\"79439.80\",\"0.001\"],[\"79494.60\",\"0.000\"],[\"79511.60\",\"0.000\"],[\"79528.40\",\"0.028\"],[\"79534.60\",\"4.263\"],[\"79563.50\",\"0.003\"],[\"79570.70\",\"2.002\"],[\"79578.40\",\"0.413\"],[\"79592.00\",\"0.543\"],[\"79596.40\",\"0.149\"],[\"79598.10\",\"10.419\"]],\"a\":[[\"79598.20\",\"3.041\"],[\"79599.70\",\"0.000\"],[\"79600.20\",\"0.001\"],[\"79600.30\",\"0.005\"],[\"79601.30\",\"0.026\"],[\"79601.40\",\"0.026\"],[\"79606.20\",\"0.096\"],[\"79621.90\",\"0.000\"],[\"79632.60\",\"2.182\"],[\"79634.20\",\"0.002\"],[\"79638.90\",\"2.001\"],[\"79733.90\",\"0.188\"],[\"79735.50\",\"0.526\"],[\"79736.40\",\"0.011\"],[\"79961.60\",\"0.287\"],[\"79962.40\",\"0.854\"],[\"79996.20\",\"3.818\"],[\"80394.20\",\"10.445\"],[\"80745.80\",\"0.858\"]],\"st\":1}}"}
{"receive_ns":1788563053518041000,"stream":"btcusdt@bookTicker","event_type":"bookTicker","event_time_ms":1788563053580,"raw_json":"{\"stream\":\"btcusdt@bookTicker\",\"data\":{\"e\":\"bookTicker\",\"u\":11478213355391,\"s\":\"BTCUSDT\",\"ps\":\"BTCUSDT\",\"b\":\"79598.10\",\"B\":\"10.427\",\"a\":\"79598.20\",\"A\":\"3.041\",\"T\":1788563053580,\"E\":1788563053580,\"st\":1}}"}
{"receive_ns":1788563053518995000,"stream":"btcusdt@bookTicker","event_type":"bookTicker","event_time_ms":1788563053581,"raw_json":"{\"stream\":\"btcusdt@bookTicker\",\"data\":{\"e\":\"bookTicker\",\"u\":11478213355494,\"s\":\"BTCUSDT\",\"ps\":\"BTCUSDT\",\"b\":\"79598.10\",\"B\":\"10.419\",\"a\":\"79598.20\",\"A\":\"3.041\",\"T\":1788563053581,\"E\":1788563053581,\"st\":1}}"}
{"receive_ns":1788563053554129000,"stream":"btcusdt@depth@100ms","event_type":"depthUpdate","event_time_ms":1788563053619,"raw_json":"{\"stream\":\"btcusdt@depth@100ms\",\"data\":{\"e\":\"depthUpdate\",\"E\":1788563053619,\"T\":1788563053617,\"s\":\"BTCUSDT\",\"ps\":\"BTCUSDT\",\"U\":11478213352550,\"u\":11478213357039,\"pu\":11478213352285,\"b\":[[\"29198.10\",\"0.056\"],[\"29298.10\",\"1.813\"],[\"29398.10\",\"0.231\"],[\"63679.00\",\"0.002\"],[\"71638.20\",\"0.002\"],[\"76414.10\",\"0.002\"],[\"78532.20\",\"0.000\"],[\"78802.10\",\"10.279\"],[\"78961.30\",\"3.539\"],[\"79401.10\",\"0.332\"],[\"79472.70\",\"1.547\"],[\"79485.60\",\"0.201\"],[\"79492.60\",\"1.332\"],[\"79494.60\",\"1.507\"],[\"79526.40\",\"0.003\"],[\"79534.00\",\"0.001\"],[\"79534.60\",\"1.382\"],[\"79536.70\",\"22.405\"],[\"79563.30\",\"0.047\"],[\"79564.30\",\"0.252\"],[\"79572.50\",\"0.715\"],[\"79573.50\",\"0.000\"],[\"79598.10\",\"10.419\"]],\"a\":[[\"79598.90\",\"0.000\"],[\"79600.40\",\"0.293\"],[\"79600.50\",\"0.486\"],[\"79601.60\",\"0.026\"],[\"79601.70\",\"0.027\"],[\"79604.20\",\"0.645\"],[\"79606.10\",\"0.001\"],[\"79606.70\",\"0.002\"],[\"79607.70\",\"0.014\"],[\"79607.90\",\"0.002\"],[\"79609.30\",\"0.004\"],[\"79609.50\",\"0.071\"],[\"79609.60\",\"0.258\"],[\"79610.20\",\"0.441\"],[\"79611.00\",\"0.691\"],[\"79612.40\",\"0.000\"],[\"79613.70\",\"0.372\"],[\"79614.40\",\"0.000\"],[\"79627.10\",\"0.000\"],[\"79628.30\",\"0.046\"],[\"79629.00\",\"0.001\"],[\"79632.60\",\"0.844\"],[\"79634.30\",\"0.088\"],[\"79638.00\",\"0.070\"],[\"79659.90\",\"0.251\"],[\"79660.80\",\"0.516\"],[\"79664.20\",\"4.951\"],[\"79666.10\",\"23.864\"],[\"79668.70\",\"1.758\"],[\"79668.80\",\"0.001\"],[\"79735.50\",\"0.275\"],[\"79961.60\",\"0.183\"],[\"79962.40\",\"1.273\"],[\"79994.20\",\"0.044\"],[\"79996.20\",\"4.300\"],[\"80394.20\",\"10.445\"],[\"81190.10\",\"0.014\"]],\"st\":1}}"}
{"receive_ns":1788563053657518000,"stream":"btcusdt@depth@100ms","event_type":"depthUpdate","event_time_ms":1788563053721,"raw_json":"{\"stream\":\"btcusdt@depth@100ms\",\"data\":{\"e\":\"depthUpdate\",\"E\":1788563053721,\"T\":1788563053720,\"s\":\"BTCUSDT\",\"ps\":\"BTCUSDT\",\"U\":11478213357140,\"u\":11478213362464,\"pu\":11478213357039,\"b\":[[\"29198.10\",\"0.119\"],[\"29298.10\",\"1.862\"],[\"29398.10\",\"0.119\"],[\"63679.00\",\"0.002\"],[\"71638.20\",\"0.002\"],[\"76414.10\",\"0.000\"],[\"78464.30\",\"1.909\"],[\"78802.10\",\"10.279\"],[\"79200.10\",\"3.591\"],[\"79563.30\",\"0.001\"],[\"79564.20\",\"0.733\"],[\"79565.40\",\"10.884\"],[\"79572.50\",\"0.342\"],[\"79573.00\",\"0.440\"],[\"79573.30\",\"0.373\"],[\"79574.60\",\"0.099\"],[\"79574.90\",\"0.000\"]],\"a\":[[\"79600.20\",\"0.001\"],[\"79610.20\",\"0.002\"],[\"79611.40\",\"0.859\"],[\"79613.70\",\"0.000\"],[\"79614.50\",\"0.624\"],[\"79628.30\",\"0.000\"],[\"79629.10\",\"0.239\"],[\"79646.30\",\"0.318\"],[\"79646.40\",\"0.334\"],[\"79733.90\",\"0.127\"],[\"79735.50\",\"0.024\"],[\"79757.00\",\"0.125\"],[\"80394.20\",\"10.445\"],[\"80752.40\",\"8.784\"],[\"80827.40\",\"4.326\"]],\"st\":1}}"}
{"receive_ns":1788563053672600000,"stream":"btcusdt@bookTicker","event_type":"bookTicker","event_time_ms":1788563053736,"raw_json":"{\"stream\":\"btcusdt@bookTicker\",\"data\":{\"e\":\"bookTicker\",\"u\":11478213363402,\"s\":\"BTCUSDT\",\"ps\":\"BTCUSDT\",\"b\":\"79598.10\",\"B\":\"10.435\",\"a\":\"79598.20\",\"A\":\"3.041\",\"T\":1788563053736,\"E\":1788563053736,\"st\":1}}"}
{"receive_ns":1788563053688751000,"stream":"btcusdt@bookTicker","event_type":"bookTicker","event_time_ms":1788563053752,"raw_json":"{\"stream\":\"btcusdt@bookTicker\",\"data\":{\"e\":\"bookTicker\",\"u\":11478213364709,\"s\":\"BTCUSDT\",\"ps\":\"BTCUSDT\",\"b\":\"79598.10\",\"B\":\"10.430\",\"a\":\"79598.20\",\"A\":\"3.041\",\"T\":1788563053752,\"E\":1788563053752,\"st\":1}}"}
{"receive_ns":1788563053691638000,"stream":"btcusdt@bookTicker","event_type":"bookTicker","event_time_ms":1788563053755,"raw_json":"{\"stream\":\"btcusdt@bookTicker\",\"data\":{\"e\":\"bookTicker\",\"u\":11478213364841,\"s\":\"BTCUSDT\",\"ps\":\"BTCUSDT\",\"b\":\"79598.10\",\"B\":\"10.434\",\"a\":\"79598.20\",\"A\":\"3.041\",\"T\":1788563053755,\"E\":1788563053755,\"st\":1}}"}
{"receive_ns":1788563053696240000,"stream":"btcusdt@bookTicker","event_type":"bookTicker","event_time_ms":1788563053760,"raw_json":"{\"stream\":\"btcusdt@bookTicker\",\"data\":{\"e\":\"bookTicker\",\"u\":11478213365054,\"s\":\"BTCUSDT\",\"ps\":\"BTCUSDT\",\"b\":\"79598.10\",\"B\":\"10.434\",\"a\":\"79598.20\",\"A\":\"3.034\",\"T\":1788563053760,\"E\":1788563053760,\"st\":1}}"}
{"receive_ns":1788563053700977000,"stream":"btcusdt@bookTicker","event_type":"bookTicker","event_time_ms":1788563053765,"raw_json":"{\"stream\":\"btcusdt@bookTicker\",\"data\":{\"e\":\"bookTicker\",\"u\":11478213365283,\"s\":\"BTCUSDT\",\"ps\":\"BTCUSDT\",\"b\":\"79598.10\",\"B\":\"10.434\",\"a\":\"79598.20\",\"A\":\"4.221\",\"T\":1788563053765,\"E\":1788563053765,\"st\":1}}"}
{"receive_ns":1788563053702190000,"stream":"btcusdt@bookTicker","event_type":"bookTicker","event_time_ms":1788563053766,"raw_json":"{\"stream\":\"btcusdt@bookTicker\",\"data\":{\"e\":\"bookTicker\",\"u\":11478213365320,\"s\":\"BTCUSDT\",\"ps\":\"BTCUSDT\",\"b\":\"79598.10\",\"B\":\"10.434\",\"a\":\"79598.20\",\"A\":\"4.219\",\"T\":1788563053766,\"E\":1788563053766,\"st\":1}}"}
{"receive_ns":1788563053702544000,"stream":"btcusdt@bookTicker","event_type":"bookTicker","event_time_ms":1788563053766,"raw_json":"{\"stream\":\"btcusdt@bookTicker\",\"data\":{\"e\":\"bookTicker\",\"u\":11478213365335,\"s\":\"BTCUSDT\",\"ps\":\"BTCUSDT\",\"b\":\"79598.10\",\"B\":\"10.434\",\"a\":\"79598.20\",\"A\":\"4.218\",\"T\":1788563053766,\"E\":1788563053766,\"st\":1}}"}
{"receive_ns":1788563053702841000,"stream":"btcusdt@bookTicker","event_type":"bookTicker","event_time_ms":1788563053766,"raw_json":"{\"stream\":\"btcusdt@bookTicker\",\"data\":{\"e\":\"bookTicker\",\"u\":11478213365345,\"s\":\"BTCUSDT\",\"ps\":\"BTCUSDT\",\"b\":\"79598.10\",\"B\":\"10.434\",\"a\":\"79598.20\",\"A\":\"4.217\",\"T\":1788563053766,\"E\":1788563053766,\"st\":1}}"}
{"receive_ns":1788563053703168000,"stream":"btcusdt@bookTicker","event_type":"bookTicker","event_time_ms":1788563053767,"raw_json":"{\"stream\":\"btcusdt@bookTicker\",\"data\":{\"e\":\"bookTicker\",\"u\":11478213365379,\"s\":\"BTCUSDT\",\"ps\":\"BTCUSDT\",\"b\":\"79598.10\",\"B\":\"10.442\",\"a\":\"79598.20\",\"A\":\"4.217\",\"T\":1788563053766,\"E\":1788563053767,\"st\":1}}"}
{"receive_ns":1788563053703544000,"stream":"btcusdt@bookTicker","event_type":"bookTicker","event_time_ms":1788563053767,"raw_json":"{\"stream\":\"btcusdt@bookTicker\",\"data\":{\"e\":\"bookTicker\",\"u\":11478213365437,\"s\":\"BTCUSDT\",\"ps\":\"BTCUSDT\",\"b\":\"79598.10\",\"B\":\"10.434\",\"a\":\"79598.20\",\"A\":\"4.217\",\"T\":1788563053767,\"E\":1788563053767,\"st\":1}}"}
{"receive_ns":1788563053729214000,"stream":"btcusdt@bookTicker","event_type":"bookTicker","event_time_ms":1788563053793,"raw_json":"{\"stream\":\"btcusdt@bookTicker\",\"data\":{\"e\":\"bookTicker\",\"u\":11478213366547,\"s\":\"BTCUSDT\",\"ps\":\"BTCUSDT\",\"b\":\"79598.10\",\"B\":\"10.434\",\"a\":\"79598.20\",\"A\":\"4.216\",\"T\":1788563053792,\"E\":1788563053793,\"st\":1}}"}
{"receive_ns":1788563053736176000,"stream":"btcusdt@bookTicker","event_type":"bookTicker","event_time_ms":1788563053800,"raw_json":"{\"stream\":\"btcusdt@bookTicker\",\"data\":{\"e\":\"bookTicker\",\"u\":11478213366972,\"s\":\"BTCUSDT\",\"ps\":\"BTCUSDT\",\"b\":\"79598.10\",\"B\":\"10.434\",\"a\":\"79598.20\",\"A\":\"4.219\",\"T\":1788563053800,\"E\":1788563053800,\"st\":1}}"}
{"receive_ns":1788563053759008000,"stream":"btcusdt@depth@100ms","event_type":"depthUpdate","event_time_ms":1788563053823,"raw_json":"{\"stream\":\"btcusdt@depth@100ms\",\"data\":{\"e\":\"depthUpdate\",\"E\":1788563053823,\"T\":1788563053822,\"s\":\"BTCUSDT\",\"ps\":\"BTCUSDT\",\"U\":11478213362504,\"u\":11478213368051,\"pu\":11478213362464,\"b\":[[\"1000.00\",\"24.604\"],[\"29198.10\",\"0.189\"],[\"29298.10\",\"1.904\"],[\"29398.10\",\"0.007\"],[\"63678.50\",\"0.000\"],[\"71638.20\",\"0.002\"],[\"76414.10\",\"0.002\"],[\"78165.30\",\"3.031\"],[\"78677.00\",\"0.507\"],[\"78802.10\",\"10.280\"],[\"79200.10\",\"3.732\"],[\"79401.10\",\"0.000\"],[\"79460.70\",\"0.135\"],[\"79473.60\",\"0.803\"],[\"79485.60\",\"0.000\"],[\"79492.60\",\"0.001\"],[\"79494.60\",\"1.507\"],[\"79502.50\",\"0.003\"],[\"79520.70\",\"0.010\"],[\"79536.70\",\"22.405\"],[\"79573.00\",\"0.440\"],[\"79574.90\",\"0.000\"],[\"79589.10\",\"0.005\"],[\"79589.30\",\"0.033\"],[\"79598.10\",\"10.434\"]],\"a\":[[\"79598.20\",\"4.219\"],[\"79598.80\",\"0.091\"],[\"79599.90\",\"0.036\"],[\"79600.10\",\"0.027\"],[\"79600.20\",\"0.027\"],[\"79600.60\",\"0.026\"],[\"79601.60\",\"0.000\"],[\"79601.70\",\"0.001\"],[\"79605.50\",\"0.006\"],[\"79606.20\",\"1.284\"],[\"79606.30\",\"0.342\"],[\"79607.70\",\"0.008\"],[\"79607.90\",\"0.000\"],[\"79609.30\",\"0.000\"],[\"79609.50\",\"0.013\"],[\"79610.20\",\"0.064\"],[\"79627.90\",\"0.829\"],[\"79659.90\",\"0.251\"],[\"79660.80\",\"0.516\"],[\"79669.90\",\"0.002\"],[\"79756.90\",\"0.000\"],[\"79757.00\",\"0.000\"],[\"79962.40\",\"0.419\"],[\"79994.20\",\"0.000\"],[\"79996.20\",\"4.145\"],[\"80230.40\",\"4.106\"],[\"80394.20\",\"10.445\"]],\"st\":1}}"}
{"receive_ns":1788563053768917000,"stream":"btcusdt@bookTicker","event_type":"bookTicker","event_time_ms":1788563053832,"raw_json":"{\"stream\":\"btcusdt@bookTicker\",\"data\":{\"e\":\"bookTicker\",\"u\":11478213368465,\"s\":\"BTCUSDT\",\"ps\":\"BTCUSDT\",\"b\":\"79598.10\",\"B\":\"10.418\",\"a\":\"79598.20\",\"A\":\"4.219\",\"T\":1788563053832,\"E\":1788563053832,\"st\":1}}"}
{"receive_ns":1788563053832421000,"stream":"btcusdt@bookTicker","event_type":"bookTicker","event_time_ms":1788563053897,"raw_json":"{\"stream\":\"btcusdt@bookTicker\",\"data\":{\"e\":\"bookTicker\",\"u\":11478213371088,\"s\":\"BTCUSDT\",\"ps\":\"BTCUSDT\",\"b\":\"79598.10\",\"B\":\"10.418\",\"a\":\"79598.20\",\"A\":\"4.221\",\"T\":1788563053897,\"E\":1788563053897,\"st\":1}}"}
{"receive_ns":1788563053861118000,"stream":"btcusdt@depth@100ms","event_type":"depthUpdate","event_time_ms":1788563053925,"raw_json":"{\"stream\":\"btcusdt@depth@100ms\",\"data\":{\"e\":\"depthUpdate\",\"E\":1788563053925,\"T\":1788563053921,\"s\":\"BTCUSDT\",\"ps\":\"BTCUSDT\",\"U\":11478213368153,\"u\":11478213372274,\"pu\":11478213368051,\"b\":[[\"29198.10\",\"0.357\"],[\"29298.10\",\"1.743\"],[\"29398.10\",\"0.000\"],[\"63679.00\",\"0.002\"],[\"71638.20\",\"0.002\"],[\"75618.20\",\"0.008\"],[\"78280.30\",\"0.000\"],[\"78802.10\",\"10.280\"],[\"79401.10\",\"0.232\"],[\"79423.30\",\"0.062\"],[\"79472.70\",\"1.647\"],[\"79492.60\",\"1.081\"],[\"79494.60\",\"1.758\"],[\"79500.30\",\"0.020\"],[\"79531.30\",\"22.454\"],[\"79536.70\",\"0.000\"],[\"79563.00\",\"0.053\"],[\"79564.20\",\"0.687\"],[\"79567.60\",\"12.039\"],[\"79570.70\",\"0.002\"],[\"79572.10\",\"0.518\"],[\"79572.20\",\"0.377\"],[\"79573.00\",\"0.001\"],[\"79573.30\",\"0.000\"],[\"79583.00\",\"0.064\"],[\"79583.50\",\"0.000\"],[\"79598.10\",\"10.418\"]],\"a\":[[\"79598.20\",\"4.221\"],[\"79599.90\",\"0.010\"],[\"79612.10\",\"2.913\"],[\"79614.50\",\"0.252\"],[\"79626.80\",\"0.051\"],[\"79629.10\",\"0.193\"],[\"79659.90\",\"0.000\"],[\"79660.80\",\"0.316\"],[\"79735.50\",\"0.275\"],[\"79756.90\",\"0.000\"],[\"79962.40\",\"1.273\"],[\"79996.20\",\"4.345\"],[\"80394.20\",\"10.445\"],[\"80747.80\",\"5.252\"],[\"80832.00\",\"4.327\"],[\"80907.00\",\"0.000\"],[\"81190.10\",\"0.017\"]],\"st\":1}}"}
{"receive_ns":1788563053961766000,"stream":"btcusdt@depth@100ms","event_type":"depthUpdate","event_time_ms":1788563054027,"raw_json":"{\"stream\":\"btcusdt@depth@100ms\",\"data\":{\"e\":\"depthUpdate\",\"E\":1788563054027,\"T\":1788563054026,\"s\":\"BTCUSDT\",\"ps\":\"BTCUSDT\",\"U\":11478213372458,\"u\":11478213378765,\"pu\":11478213372274,\"b\":[[\"1000.00\",\"24.604\"],[\"29198.10\",\"0.539\"],[\"29298.10\",\"1.561\"],[\"63679.00\",\"0.002\"],[\"71638.20\",\"0.002\"],[\"76414.10\",\"0.000\"],[\"78576.90\",\"0.012\"],[\"78590.30\",\"0.000\"],[\"78592.70\",\"2.523\"],[\"78606.10\",\"0.000\"],[\"78608.50\",\"0.005\"],[\"78619.50\",\"0.000\"],[\"78730.50\",\"2.343\"],[\"78732.70\",\"0.510\"],[\"78802.10\",\"10.280\"],[\"79200.10\",\"3.732\"],[\"79401.10\",\"0.734\"],[\"79460.70\",\"0.010\"],[\"79473.60\",\"0.602\"],[\"79494.60\",\"0.251\"],[\"79531.30\",\"0.011\"],[\"79534.00\",\"22.444\"],[\"79563.00\",\"0.007\"],[\"79564.10\",\"0.154\"],[\"79565.30\",\"0.196\"],[\"79572.10\",\"0.079\"],[\"79573.00\",\"0.440\"],[\"79574.40\",\"0.050\"],[\"79574.90\",\"0.000\"]],\"a\":[[\"79600.10\",\"0.001\"],[\"79600.20\",\"0.001\"],[\"79600.50\",\"0.512\"],[\"79600.60\",\"0.000\"],[\"79600.80\",\"0.001\"],[\"79601.60\",\"0.026\"],[\"79601.70\",\"0.027\"],[\"79601.80\",\"0.027\"],[\"79608.10\",\"0.262\"],[\"79610.20\",\"0.503\"],[\"79611.40\",\"0.420\"],[\"79612.10\",\"2.541\"],[\"79613.40\",\"0.003\"],[\"79614.30\",\"0.361\"],[\"79614.40\",\"0.372\"],[\"79626.80\",\"0.005\"],[\"79628.10\",\"0.062\"],[\"79962.40\",\"1.273\"],[\"79996.20\",\"3.819\"],[\"80394.20\",\"10.445\"]],\"st\":1}}"}
{"receive_ns":1788563053964696000,"stream":"btcusdt@bookTicker","event_type":"bookTicker","event_time_ms":1788563054029,"raw_json":"{\"stream\":\"btcusdt@bookTicker\",\"data\":{\"e\":\"bookTicker\",\"u\":11478213379111,\"s\":\"BTCUSDT\",\"ps\":\"BTCUSDT\",\"b\":\"79598.10\",\"B\":\"10.418\",\"a\":\"79598.20\",\"A\":\"4.219\",\"T\":1788563054029,\"E\":1788563054029,\"st\":1}}"}
{"receive_ns":1788563053965938000,"stream":"btcusdt@bookTicker","event_type":"bookTicker","event_time_ms":1788563054031,"raw_json":"{\"stream\":\"btcusdt@bookTicker\",\"data\":{\"e\":\"bookTicker\",\"u\":11478213379388,\"s\":\"BTCUSDT\",\"ps\":\"BTCUSDT\",\"b\":\"79598.10\",\"B\":\"10.417\",\"a\":\"79598.20\",\"A\":\"4.219\",\"T\":1788563054031,\"E\":1788563054031,\"st\":1}}"}
{"receive_ns":1788563053966118000,"stream":"btcusdt@trade","event_type":"trade","event_time_ms":1788563054031,"raw_json":"{\"stream\":\"btcusdt@trade\",\"data\":{\"e\":\"trade\",\"E\":1788563054031,\"T\":1788563054031,\"s\":\"BTCUSDT\",\"t\":8054081728,\"p\":\"79598.10\",\"q\":\"0.001\",\"X\":\"MARKET\",\"m\":true,\"st\":1}}"}
{"receive_ns":1788563053968521000,"stream":"btcusdt@bookTicker","event_type":"bookTicker","event_time_ms":1788563054033,"raw_json":"{\"stream\":\"btcusdt@bookTicker\",\"data\":{\"e\":\"bookTicker\",\"u\":11478213379598,\"s\":\"BTCUSDT\",\"ps\":\"BTCUSDT\",\"b\":\"79598.10\",\"B\":\"10.425\",\"a\":\"79598.20\",\"A\":\"4.219\",\"T\":1788563054033,\"E\":1788563054033,\"st\":1}}"}
{"receive_ns":1788563053968777000,"stream":"btcusdt@bookTicker","event_type":"bookTicker","event_time_ms":1788563054034,"raw_json":"{\"stream\":\"btcusdt@bookTicker\",\"data\":{\"e\":\"bookTicker\",\"u\":11478213379686,\"s\":\"BTCUSDT\",\"ps\":\"BTCUSDT\",\"b\":\"79598.10\",\"B\":\"10.417\",\"a\":\"79598.20\",\"A\":\"4.219\",\"T\":1788563054033,\"E\":1788563054034,\"st\":1}}"}
{"receive_ns":1788563054020121000,"stream":"btcusdt@bookTicker","event_type":"bookTicker","event_time_ms":1788563054085,"raw_json":"{\"stream\":\"btcusdt@bookTicker\",\"data\":{\"e\":\"bookTicker\",\"u\":11478213382598,\"s\":\"BTCUSDT\",\"ps\":\"BTCUSDT\",\"b\":\"79598.10\",\"B\":\"10.417\",\"a\":\"79598.20\",\"A\":\"4.179\",\"T\":1788563054085,\"E\":1788563054085,\"st\":1}}"}
{"receive_ns":1788563054020394000,"stream":"btcusdt@trade","event_type":"trade","event_time_ms":1788563054085,"raw_json":"{\"stream\":\"btcusdt@trade\",\"data\":{\"e\":\"trade\",\"E\":1788563054085,\"T\":1788563054085,\"s\":\"BTCUSDT\",\"t\":8054081729,\"p\":\"79598.20\",\"q\":\"0.040\",\"X\":\"MARKET\",\"m\":false,\"st\":1}}"}
{"receive_ns":1788563054021297000,"stream":"btcusdt@bookTicker","event_type":"bookTicker","event_time_ms":1788563054086,"raw_json":"{\"stream\":\"btcusdt@bookTicker\",\"data\":{\"e\":\"bookTicker\",\"u\":11478213382677,\"s\":\"BTCUSDT\",\"ps\":\"BTCUSDT\",\"b\":\"79598.10\",\"B\":\"10.425\",\"a\":\"79598.20\",\"A\":\"4.179\",\"T\":1788563054086,\"E\":1788563054086,\"st\":1}}"}
{"receive_ns":1788563054022758000,"stream":"btcusdt@bookTicker","event_type":"bookTicker","event_time_ms":1788563054087,"raw_json":"{\"stream\":\"btcusdt@bookTicker\",\"data\":{\"e\":\"bookTicker\",\"u\":11478213382843,\"s\":\"BTCUSDT\",\"ps\":\"BTCUSDT\",\"b\":\"79598.10\",\"B\":\"10.417\",\"a\":\"79598.20\",\"A\":\"4.179\",\"T\":1788563054087,\"E\":1788563054087,\"st\":1}}"}
{"receive_ns":1788563054022986000,"stream":"btcusdt@bookTicker","event_type":"bookTicker","event_time_ms":1788563054088,"raw_json":"{\"stream\":\"btcusdt@bookTicker\",\"data\":{\"e\":\"bookTicker\",\"u\":11478213382958,\"s\":\"BTCUSDT\",\"ps\":\"BTCUSDT\",\"b\":\"79598.10\",\"B\":\"10.417\",\"a\":\"79598.20\",\"A\":\"3.810\",\"T\":1788563054088,\"E\":1788563054088,\"st\":1}}"}
{"receive_ns":1788563054025946000,"stream":"btcusdt@bookTicker","event_type":"bookTicker","event_time_ms":1788563054089,"raw_json":"{\"stream\":\"btcusdt@bookTicker\",\"data\":{\"e\":\"bookTicker\",\"u\":11478213383056,\"s\":\"BTCUSDT\",\"ps\":\"BTCUSDT\",\"b\":\"79598.10\",\"B\":\"10.417\",\"a\":\"79598.20\",\"A\":\"3.811\",\"T\":1788563054089,\"E\":1788563054089,\"st\":1}}"}
{"receive_ns":1788563054072139000,"stream":"btcusdt@depth@100ms","event_type":"depthUpdate","event_time_ms":1788563054129,"raw_json":"{\"stream\":\"btcusdt@depth@100ms\",\"data\":{\"e\":\"depthUpdate\",\"E\":1788563054129,\"T\":1788563054125,\"s\":\"BTCUSDT\",\"ps\":\"BTCUSDT\",\"U\":11478213378929,\"u\":11478213385490,\"pu\":11478213378765,\"b\":[[\"1000.00\",\"24.604\"],[\"29198.10\",\"0.714\"],[\"29298.10\",\"1.386\"],[\"63678.00\",\"0.004\"],[\"71638.20\",\"0.002\"],[\"76414.10\",\"0.002\"],[\"78507.60\",\"2.033\"],[\"78802.10\",\"10.280\"],[\"79200.10\",\"3.732\"],[\"79401.10\",\"0.734\"],[\"79418.20\",\"3.141\"],[\"79418.50\",\"1.181\"],[\"79453.60\",\"1.885\"],[\"79453.70\",\"0.073\"],[\"79462.70\",\"0.012\"],[\"79463.20\",\"0.000\"],[\"79463.30\",\"0.004\"],[\"79472.70\",\"1.547\"],[\"79485.60\",\"0.201\"],[\"79492.60\",\"1.432\"],[\"79494.60\",\"1.005\"],[\"79511.40\",\"0.038\"],[\"79511.50\",\"0.023\"],[\"79583.80\",\"0.000\"],[\"79598.10\",\"10.417\"]],\"a\":[[\"79598.20\",\"3.811\"],[\"79598.80\",\"0.015\"],[\"79600.50\",\"0.486\"],[\"79601.00\",\"0.008\"],[\"79601.10\",\"0.003\"],[\"79601.90\",\"0.026\"],[\"79602.00\",\"0.103\"],[\"79609.30\",\"0.004\"],[\"79609.50\",\"0.071\"],[\"79610.20\",\"0.441\"],[\"79646.20\",\"0.128\"],[\"79646.30\",\"0.191\"],[\"79685.30\",\"0.213\"],[\"79686.60\",\"1.295\"],[\"79686.70\",\"0.039\"],[\"79693.80\",\"0.002\"],[\"79722.00\",\"2.080\"],[\"79722.10\",\"0.000\"],[\"79735.50\",\"0.275\"],[\"79736.40\",\"0.211\"],[\"79743.70\",\"3.142\"],[\"79744.80\",\"0.000\"],[\"79821.30\",\"0.000\"],[\"79821.40\",\"0.003\"],[\"79962.40\",\"1.273\"],[\"79996.20\",\"4.345\"],[\"80235.00\",\"4.237\"],[\"80394.20\",\"10.445\"]],\"st\":1}}"}
{"receive_ns":1788563054073821000,"stream":"btcusdt@bookTicker","event_type":"bookTicker","event_time_ms":1788563054139,"raw_json":"{\"stream\":\"btcusdt@bookTicker\",\"data\":{\"e\":\"bookTicker\",\"u\":11478213387129,\"s\":\"BTCUSDT\",\"ps\":\"BTCUSDT\",\"b\":\"79598.10\",\"B\":\"10.354\",\"a\":\"79598.20\",\"A\":\"3.811\",\"T\":1788563054138,\"E\":1788563054139,\"st\":1}}"}
{"receive_ns":1788563054082046000,"stream":"btcusdt@bookTicker","event_type":"bookTicker","event_time_ms":1788563054146,"raw_json":"{\"stream\":\"btcusdt@bookTicker\",\"data\":{\"e\":\"bookTicker\",\"u\":11478213387834,\"s\":\"BTCUSDT\",\"ps\":\"BTCUSDT\",\"b\":\"79598.10\",\"B\":\"10.419\",\"a\":\"79598.20\",\"A\":\"3.811\",\"T\":1788563054146,\"E\":1788563054146,\"st\":1}}"}
{"receive_ns":1788563054113489000,"stream":"btcusdt@bookTicker","event_type":"bookTicker","event_time_ms":1788563054177,"raw_json":"{\"stream\":\"btcusdt@bookTicker\",\"data\":{\"e\":\"bookTicker\",\"u\":11478213389810,\"s\":\"BTCUSDT\",\"ps\":\"BTCUSDT\",\"b\":\"79598.10\",\"B\":\"10.419\",\"a\":\"79598.20\",\"A\":\"3.808\",\"T\":1788563054177,\"E\":1788563054177,\"st\":1}}"}
{"receive_ns":1788563054122756000,"stream":"btcusdt@bookTicker","event_type":"bookTicker","event_time_ms":1788563054186,"raw_json":"{\"stream\":\"btcusdt@bookTicker\",\"data\":{\"e\":\"bookTicker\",\"u\":11478213390311,\"s\":\"BTCUSDT\",\"ps\":\"BTCUSDT\",\"b\":\"79598.10\",\"B\":\"10.419\",\"a\":\"79598.20\",\"A\":\"3.809\",\"T\":1788563054186,\"E\":1788563054186,\"st\":1}}"}
{"receive_ns":1788563054149164000,"stream":"btcusdt@bookTicker","event_type":"bookTicker","event_time_ms":1788563054214,"raw_json":"{\"stream\":\"btcusdt@bookTicker\",\"data\":{\"e\":\"bookTicker\",\"u\":11478213392003,\"s\":\"BTCUSDT\",\"ps\":\"BTCUSDT\",\"b\":\"79598.10\",\"B\":\"10.435\",\"a\":\"79598.20\",\"A\":\"3.809\",\"T\":1788563054214,\"E\":1788563054214,\"st\":1}}"}
{"receive_ns":1788563054166843000,"stream":"btcusdt@depth@100ms","event_type":"depthUpdate","event_time_ms":1788563054231,"raw_json":"{\"stream\":\"btcusdt@depth@100ms\",\"data\":{\"e\":\"depthUpdate\",\"E\":1788563054231,\"T\":1788563054230,\"s\":\"BTCUSDT\",\"ps\":\"BTCUSDT\",\"U\":11478213385737,\"u\":11478213392861,\"pu\":11478213385490,\"b\":[[\"29198.10\",\"0.896\"],[\"29298.10\",\"1.204\"],[\"71638.20\",\"0.002\"],[\"76414.10\",\"0.000\"],[\"78284.70\",\"2.832\"],[\"78730.50\",\"3.167\"],[\"78802.10\",\"10.280\"],[\"79200.10\",\"3.590\"],[\"79401.10\",\"0.232\"],[\"79461.10\",\"0.125\"],[\"79541.60\",\"0.560\"],[\"79563.20\",\"0.056\"],[\"79564.10\",\"0.108\"],[\"79572.20\",\"0.004\"],[\"79573.50\",\"0.373\"],[\"79594.00\",\"0.029\"],[\"79594.10\",\"0.527\"],[\"79597.70\",\"0.102\"],[\"79598.10\",\"10.435\"]],\"a\":[[\"79598.20\",\"3.809\"],[\"79601.00\",\"0.034\"],[\"79601.20\",\"0.001\"],[\"79601.30\",\"0.000\"],[\"79601.40\",\"0.000\"],[\"79601.60\",\"0.000\"],[\"79601.70\",\"0.001\"],[\"79602.10\",\"0.028\"],[\"79602.20\",\"0.029\"],[\"79602.40\",\"0.027\"],[\"79602.50\",\"0.026\"],[\"79602.60\",\"0.026\"],[\"79612.40\",\"0.000\"],[\"79613.70\",\"0.372\"],[\"79614.40\",\"0.000\"],[\"79675.80\",\"0.003\"],[\"79699.40\",\"0.166\"],[\"79757.40\",\"0.125\"],[\"79962.40\",\"0.854\"],[\"79996.20\",\"4.346\"],[\"80394.20\",\"10.445\"],[\"80573.20\",\"2.745\"],[\"80752.40\",\"9.650\"],[\"80911.60\",\"3.604\"]],\"st\":1}}"}
{"receive_ns":1788563054212920000,"stream":"btcusdt@bookTicker","event_type":"bookTicker","event_time_ms":1788563054278,"raw_json":"{\"stream\":\"btcusdt@bookTicker\",\"data\":{\"e\":\"bookTicker\",\"u\":11478213395549,\"s\":\"BTCUSDT\",\"ps\":\"BTCUSDT\",\"b\":\"79598.10\",\"B\":\"10.334\",\"a\":\"79598.20\",\"A\":\"3.809\",\"T\":1788563054278,\"E\":1788563054278,\"st\":1}}"}
{"receive_ns":1788563054216865000,"stream":"btcusdt@bookTicker","event_type":"bookTicker","event_time_ms":1788563054281,"raw_json":"{\"stream\":\"btcusdt@bookTicker\",\"data\":{\"e\":\"bookTicker\",\"u\":11478213395791,\"s\":\"BTCUSDT\",\"ps\":\"BTCUSDT\",\"b\":\"79598.10\",\"B\":\"10.450\",\"a\":\"79598.20\",\"A\":\"3.809\",\"T\":1788563054281,\"E\":1788563054281,\"st\":1}}"}
{"receive_ns":1788563054218982000,"stream":"btcusdt@bookTicker","event_type":"bookTicker","event_time_ms":1788563054283,"raw_json":"{\"stream\":\"btcusdt@bookTicker\",\"data\":{\"e\":\"bookTicker\",\"u\":11478213395902,\"s\":\"BTCUSDT\",\"ps\":\"BTCUSDT\",\"b\":\"79598.10\",\"B\":\"10.448\",\"a\":\"79598.20\",\"A\":\"3.809\",\"T\":1788563054283,\"E\":1788563054283,\"st\":1}}"}
{"receive_ns":1788563054230042000,"stream":"btcusdt@bookTicker","event_type":"bookTicker","event_time_ms":1788563054295,"raw_json":"{\"stream\":\"btcusdt@bookTicker\",\"data\":{\"e\":\"bookTicker\",\"u\":11478213396721,\"s\":\"BTCUSDT\",\"ps\":\"BTCUSDT\",\"b\":\"79598.10\",\"B\":\"10.448\",\"a\":\"79598.20\",\"A\":\"3.770\",\"T\":1788563054295,\"E\":1788563054295,\"st\":1}}"}
{"receive_ns":1788563054231226000,"stream":"btcusdt@bookTicker","event_type":"bookTicker","event_time_ms":1788563054297,"raw_json":"{\"stream\":\"btcusdt@bookTicker\",\"data\":{\"e\":\"bookTicker\",\"u\":11478213396801,\"s\":\"BTCUSDT\",\"ps\":\"BTCUSDT\",\"b\":\"79598.10\",\"B\":\"10.456\",\"a\":\"79598.20\",\"A\":\"3.770\",\"T\":1788563054296,\"E\":1788563054297,\"st\":1}}"}
{"receive_ns":1788563054232433000,"stream":"btcusdt@bookTicker","event_type":"bookTicker","event_time_ms":1788563054297,"raw_json":"{\"stream\":\"btcusdt@bookTicker\",\"data\":{\"e\":\"bookTicker\",\"u\":11478213396847,\"s\":\"BTCUSDT\",\"ps\":\"BTCUSDT\",\"b\":\"79598.10\",\"B\":\"10.448\",\"a\":\"79598.20\",\"A\":\"3.770\",\"T\":1788563054297,\"E\":1788563054297,\"st\":1}}"}
{"receive_ns":1788563054269188000,"stream":"btcusdt@depth@100ms","event_type":"depthUpdate","event_time_ms":1788563054333,"raw_json":"{\"stream\":\"btcusdt@depth@100ms\",\"data\":{\"e\":\"depthUpdate\",\"E\":1788563054333,\"T\":1788563054331,\"s\":\"BTCUSDT\",\"ps\":\"BTCUSDT\",\"U\":11478213392924,\"u\":11478213399036,\"pu\":11478213392861,\"b\":[[\"1000.00\",\"24.604\"],[\"29198.10\",\"1.071\"],[\"29298.10\",\"1.029\"],[\"63679.00\",\"0.002\"],[\"71638.20\",\"0.002\"],[\"78448.60\",\"1.096\"],[\"78802.10\",\"10.280\"],[\"79193.20\",\"0.000\"],[\"79193.50\",\"0.087\"],[\"79200.10\",\"3.731\"],[\"79401.10\",\"0.834\"],[\"79404.00\",\"1.215\"],[\"79472.70\",\"2.627\"],[\"79485.60\",\"0.000\"],[\"79492.60\",\"0.252\"],[\"79494.60\",\"1.005\"],[\"79563.20\",\"0.010\"],[\"79564.20\",\"0.733\"],[\"79565.10\",\"0.001\"],[\"79565.40\",\"10.884\"],[\"79566.00\",\"0.453\"],[\"79573.00\",\"0.440\"],[\"79574.90\",\"0.000\"],[\"79594.00\",\"0.029\"],[\"79594.10\",\"0.527\"],[\"79597.70\",\"0.026\"],[\"79598.10\",\"10.448\"]],\"a\":[[\"79598.20\",\"3.770\"],[\"79600.30\",\"0.031\"],[\"79609.30\",\"0.062\"],[\"79609.40\",\"0.002\"],[\"79609.50\",\"0.326\"],[\"79610.20\",\"0.441\"],[\"79611.40\",\"0.420\"],[\"79613.30\",\"1.170\"],[\"79613.70\",\"0.000\"],[\"79614.60\",\"0.001\"],[\"79615.70\",\"0.454\"],[\"79615.90\",\"0.116\"],[\"79616.50\",\"0.055\"],[\"79616.90\",\"0.004\"],[\"79628.10\",\"0.016\"],[\"79629.20\",\"0.066\"],[\"79659.90\",\"0.502\"],[\"79660.80\",\"0.516\"],[\"79735.50\",\"0.024\"],[\"79736.40\",\"0.011\"],[\"79757.10\",\"0.000\"],[\"79757.40\",\"0.000\"],[\"79757.60\",\"0.126\"],[\"79962.40\",\"1.273\"],[\"79996.20\",\"4.346\"],[\"80394.20\",\"10.445\"]],\"st\":1}}"}
{"receive_ns":1788563054327759000,"stream":"btcusdt@bookTicker","event_type":"bookTicker","event_time_ms":1788563054391,"raw_json":"{\"stream\":\"btcusdt@bookTicker\",\"data\":{\"e\":\"bookTicker\",\"u\":11478213402757,\"s\":\"BTCUSDT\",\"ps\":\"BTCUSDT\",\"b\":\"79598.10\",\"B\":\"10.391\",\"a\":\"79598.20\",\"A\":\"3.770\",\"T\":1788563054390,\"E\":1788563054391,\"st\":1}}"}
{"receive_ns":1788563054328157000,"stream":"btcusdt@bookTicker","event_type":"bookTicker","event_time_ms":1788563054393,"raw_json":"{\"stream\":\"btcusdt@bookTicker\",\"data\":{\"e\":\"bookTicker\",\"u\":11478213402925,\"s\":\"BTCUSDT\",\"ps\":\"BTCUSDT\",\"b\":\"79598.10\",\"B\":\"10.450\",\"a\":\"79598.20\",\"A\":\"3.770\",\"T\":1788563054393,\"E\":1788563054393,\"st\":1}}"}
{"receive_ns":1788563054328876000,"stream":"btcusdt@bookTicker","event_type":"bookTicker","event_time_ms":1788563054394,"raw_json":"{\"stream\":\"btcusdt@bookTicker\",\"data\":{\"e\":\"bookTicker\",\"u\":11478213402982,\"s\":\"BTCUSDT\",\"ps\":\"BTCUSDT\",\"b\":\"79598.10\",\"B\":\"10.452\",\"a\":\"79598.20\",\"A\":\"3.770\",\"T\":1788563054394,\"E\":1788563054394,\"st\":1}}"}
{"receive_ns":1788563054358520000,"stream":"btcusdt@bookTicker","event_type":"bookTicker","event_time_ms":1788563054422,"raw_json":"{\"stream\":\"btcusdt@bookTicker\",\"data\":{\"e\":\"bookTicker\",\"u\":11478213404505,\"s\":\"BTCUSDT\",\"ps\":\"BTCUSDT\",\"b\":\"79598.10\",\"B\":\"10.452\",\"a\":\"79598.20\",\"A\":\"3.768\",\"T\":1788563054422,\"E\":1788563054422,\"st\":1}}"}
{"receive_ns":1788563054370940000,"stream":"btcusdt@depth@100ms","event_type":"depthUpdate","event_time_ms":1788563054435,"raw_json":"{\"stream\":\"btcusdt@depth@100ms\",\"data\":{\"e\":\"depthUpdate\",\"E\":1788563054435,\"T\":1788563054433,\"s\":\"BTCUSDT\",\"ps\":\"BTCUSDT\",\"U\":11478213399147,\"u\":11478213405311,\"pu\":11478213399036,\"b\":[[\"1000.00\",\"24.604\"],[\"29198.10\",\"1.253\"],[\"29298.10\",\"0.847\"],[\"71638.20\",\"0.002\"],[\"76414.10\",\"0.002\"],[\"78439.50\",\"15.817\"],[\"78483.70\",\"25.705\"],[\"78552.00\",\"0.222\"],[\"78802.10\",\"10.280\"],[\"79195.60\",\"0.630\"],[\"79200.10\",\"3.741\"],[\"79461.10\",\"0.000\"],[\"79594.00\",\"0.029\"],[\"79594.10\",\"0.527\"],[\"79598.10\",\"10.452\"]],\"a\":[[\"79598.20\",\"3.768\"],[\"79600.30\",\"0.005\"],[\"79600.90\",\"0.004\"],[\"79601.00\",\"0.008\"],[\"79601.70\",\"0.027\"],[\"79757.60\",\"0.001\"],[\"80394.20\",\"10.445\"],[\"80514.40\",\"2.232\"],[\"80573.20\",\"2.467\"],[\"80593.20\",\"2.336\"]],\"st\":1}}"}
{"receive_ns":1788563054415745000,"stream":"btcusdt@bookTicker","event_type":"bookTicker","event_time_ms":1788563054464,"raw_json":"{\"stream\":\"btcusdt@bookTicker\",\"data\":{\"e\":\"bookTicker\",\"u\":11478213407396,\"s\":\"BTCUSDT\",\"ps\":\"BTCUSDT\",\"b\":\"79598.10\",\"B\":\"10.458\",\"a\":\"79598.20\",\"A\":\"3.768\",\"T\":1788563054464,\"E\":1788563054464,\"st\":1}}"}
{"receive_ns":1788563054416037000,"stream":"btcusdt@bookTicker","event_type":"bookTicker","event_time_ms":1788563054466,"raw_json":"{\"stream\":\"btcusdt@bookTicker\",\"data\":{\"e\":\"bookTicker\",\"u\":11478213407820,\"s\":\"BTCUSDT\",\"ps\":\"BTCUSDT\",\"b\":\"79598.10\",\"B\":\"10.458\",\"a\":\"79598.20\",\"A\":\"3.767\",\"T\":1788563054466,\"E\":1788563054466,\"st\":1}}"}
{"receive_ns":1788563054426271000,"stream":"btcusdt@bookTicker","event_type":"bookTicker","event_time_ms":1788563054471,"raw_json":"{\"stream\":\"btcusdt@bookTicker\",\"data\":{\"e\":\"bookTicker\",\"u\":11478213408233,\"s\":\"BTCUSDT\",\"ps\":\"BTCUSDT\",\"b\":\"79598.10\",\"B\":\"10.447\",\"a\":\"79598.20\",\"A\":\"3.767\",\"T\":1788563054471,\"E\":1788563054471,\"st\":1}}"}
{"receive_ns":1788563054457311000,"stream":"btcusdt@bookTicker","event_type":"bookTicker","event_time_ms":1788563054520,"raw_json":"{\"stream\":\"btcusdt@bookTicker\",\"data\":{\"e\":\"bookTicker\",\"u\":11478213413067,\"s\":\"BTCUSDT\",\"ps\":\"BTCUSDT\",\"b\":\"79598.10\",\"B\":\"10.447\",\"a\":\"79598.20\",\"A\":\"3.765\",\"T\":1788563054520,\"E\":1788563054520,\"st\":1}}"}
{"receive_ns":1788563054481577000,"stream":"btcusdt@depth@100ms","event_type":"depthUpdate","event_time_ms":1788563054537,"raw_json":"{\"stream\":\"btcusdt@depth@100ms\",\"data\":{\"e\":\"depthUpdate\",\"E\":1788563054537,\"T\":1788563054535,\"s\":\"BTCUSDT\",\"ps\":\"BTCUSDT\",\"U\":11478213405519,\"u\":11478213414485,\"pu\":11478213405311,\"b\":[[\"29198.10\",\"1.428\"],[\"29298.10\",\"0.672\"],[\"71638.20\",\"0.002\"],[\"76414.10\",\"0.000\"],[\"78642.90\",\"22.321\"],[\"78802.10\",\"10.280\"],[\"79200.10\",\"3.741\"],[\"79401.10\",\"1.839\"],[\"79404.00\",\"1.014\"],[\"79453.70\",\"0.000\"],[\"79494.60\",\"0.000\"],[\"79532.90\",\"0.001\"],[\"79534.60\",\"4.268\"],[\"79563.20\",\"0.056\"],[\"79564.20\",\"0.687\"],[\"79565.10\",\"0.001\"],[\"79565.90\",\"0.038\"],[\"79566.00\",\"0.001\"],[\"79566.40\",\"0.003\"],[\"79567.00\",\"0.454\"],[\"79567.60\",\"10.002\"],[\"79567.70\",\"3.775\"],[\"79569.40\",\"3.902\"],[\"79572.40\",\"0.254\"],[\"79573.50\",\"0.000\"],[\"79574.30\",\"2.001\"],[\"79574.60\",\"0.472\"],[\"79580.10\",\"0.216\"],[\"79582.20\",\"0.287\"],[\"79583.00\",\"0.002\"],[\"79583.20\",\"0.216\"],[\"79583.40\",\"0.095\"],[\"79589.40\",\"0.253\"],[\"79589.90\",\"0.000\"],[\"79597.60\",\"0.276\"],[\"79598.10\",\"10.447\"]],\"a\":[[\"79598.20\",\"3.765\"],[\"79600.70\",\"0.002\"],[\"79601.00\",\"0.034\"],[\"79601.10\",\"0.029\"],[\"79602.60\",\"0.000\"],[\"79603.10\",\"0.200\"],[\"79609.30\",\"0.000\"],[\"79609.40\",\"0.064\"],[\"79613.30\",\"0.798\"],[\"79614.40\",\"0.372\"],[\"79615.60\",\"0.009\"],[\"79615.70\",\"0.002\"],[\"79615.90\",\"0.110\"],[\"79616.40\",\"1.402\"],[\"79616.90\",\"0.456\"],[\"79636.40\",\"1.780\"],[\"79638.90\",\"0.001\"],[\"79659.90\",\"0.251\"],[\"79660.80\",\"0.316\"],[\"79740.00\",\"0.975\"],[\"79961.60\",\"0.287\"],[\"79962.40\",\"1.273\"],[\"79996.20\",\"4.346\"],[\"80356.60\",\"0.745\"],[\"80394.20\",\"10.445\"],[\"81190.10\",\"0.020\"]],\"st\":1}}"}
{"receive_ns":1788563054558069000,"stream":"btcusdt@bookTicker","event_type":"bookTicker","event_time_ms":1788563054622,"raw_json":"{\"stream\":\"btcusdt@bookTicker\",\"data\":{\"e\":\"bookTicker\",\"u\":11478213420426,\"s\":\"BTCUSDT\",\"ps\":\"BTCUSDT\",\"b\":\"79598.10\",\"B\":\"10.447\",\"a\":\"79598.20\",\"A\":\"3.764\",\"T\":1788563054622,\"E\":1788563054622,\"st\":1}}"}
{"receive_ns":1788563054558295000,"stream":"btcusdt@trade","event_type":"trade","event_time_ms":1788563054622,"raw_json":"{\"stream\":\"btcusdt@trade\",\"data\":{\"e\":\"trade\",\"E\":1788563054622,\"T\":1788563054622,\"s\":\"BTCUSDT\",\"t\":8054081730,\"p\":\"79598.20\",\"q\":\"0.001\",\"X\":\"MARKET\",\"m\":false,\"st\":1}}"}
{"receive_ns":1788563054558521000,"stream":"btcusdt@bookTicker","event_type":"bookTicker","event_time_ms":1788563054623,"raw_json":"{\"stream\":\"btcusdt@bookTicker\",\"data\":{\"e\":\"bookTicker\",\"u\":11478213420581,\"s\":\"BTCUSDT\",\"ps\":\"BTCUSDT\",\"b\":\"79598.10\",\"B\":\"10.455\",\"a\":\"79598.20\",\"A\":\"3.764\",\"T\":1788563054623,\"E\":1788563054623,\"st\":1}}"}
{"receive_ns":1788563054559093000,"stream":"btcusdt@bookTicker","event_type":"bookTicker","event_time_ms":1788563054624,"raw_json":"{\"stream\":\"btcusdt@bookTicker\",\"data\":{\"e\":\"bookTicker\",\"u\":11478213420668,\"s\":\"BTCUSDT\",\"ps\":\"BTCUSDT\",\"b\":\"79598.10\",\"B\":\"10.447\",\"a\":\"79598.20\",\"A\":\"3.764\",\"T\":1788563054624,\"E\":1788563054624,\"st\":1}}"}
{"receive_ns":1788563054575199000,"stream":"btcusdt@depth@100ms","event_type":"depthUpdate","event_time_ms":1788563054639,"raw_json":"{\"stream\":\"btcusdt@depth@100ms\",\"data\":{\"e\":\"depthUpdate\",\"E\":1788563054639,\"T\":1788563054638,\"s\":\"BTCUSDT\",\"ps\":\"BTCUSDT\",\"U\":11478213414694,\"u\":11478213421260,\"pu\":11478213414485,\"b\":[[\"1000.00\",\"24.604\"],[\"29198.10\",\"1.610\"],[\"29298.10\",\"0.490\"],[\"63678.00\",\"0.004\"],[\"63679.00\",\"0.002\"],[\"71638.20\",\"0.002\"],[\"71675.00\",\"0.005\"],[\"76414.10\",\"0.002\"],[\"78443.90\",\"7.358\"],[\"78583.70\",\"2.490\"],[\"78802.10\",\"10.280\"],[\"79200.10\",\"3.867\"],[\"79228.00\",\"0.245\"],[\"79400.00\",\"4.755\"],[\"79401.10\",\"2.938\"],[\"79472.70\",\"1.547\"],[\"79492.60\",\"0.001\"],[\"79533.40\",\"0.001\"],[\"79565.10\",\"0.453\"],[\"79566.00\",\"0.001\"],[\"79567.00\",\"0.002\"],[\"79567.60\",\"0.002\"],[\"79567.70\",\"0.003\"],[\"79572.40\",\"0.627\"],[\"79573.00\",\"0.440\"],[\"79573.30\",\"0.000\"],[\"79574.20\",\"0.004\"],[\"79574.60\",\"0.099\"],[\"79574.90\",\"0.000\"],[\"79598.10\",\"10.447\"]],\"a\":[[\"79598.20\",\"3.764\"],[\"79601.00\",\"0.008\"],[\"79602.10\",\"0.279\"],[\"79603.20\",\"0.002\"],[\"79604.10\",\"0.332\"],[\"79608.10\",\"0.262\"],[\"79609.40\",\"0.377\"],[\"79609.50\",\"0.013\"],[\"79609.60\",\"0.258\"],[\"79610.20\",\"0.441\"],[\"79611.00\",\"0.691\"],[\"79612.40\",\"0.000\"],[\"79613.40\",\"0.375\"],[\"79614.40\",\"0.000\"],[\"79615.50\",\"0.452\"],[\"79616.90\",\"0.004\"],[\"79642.30\",\"10.078\"],[\"79659.90\",\"0.000\"],[\"79666.10\",\"0.002\"],[\"79668.80\",\"23.854\"],[\"79961.60\",\"0.183\"],[\"79962.40\",\"1.183\"],[\"79994.20\",\"0.044\"],[\"79996.20\",\"4.302\"],[\"80394.20\",\"10.445\"],[\"80529.50\",\"0.866\"],[\"80531.70\",\"0.000\"],[\"80920.80\",\"0.493\"]],\"st\":1}}"}
{"receive_ns":1788563054599645000,"stream":"btcusdt@bookTicker","event_type":"bookTicker","event_time_ms":1788563054664,"raw_json":"{\"stream\":\"btcusdt@bookTicker\",\"data\":{\"e\":\"bookTicker\",\"u\":11478213422699,\"s\":\"BTCUSDT\",\"ps\":\"BTCUSDT\",\"b\":\"79598.10\",\"B\":\"10.421\",\"a\":\"79598.20\",\"A\":\"3.764\",\"T\":1788563054664,\"E\":1788563054664,\"st\":1}}"}
{"receive_ns":1788563054599891000,"stream":"btcusdt@trade","event_type":"trade","event_time_ms":1788563054664,"raw_json":"{\"stream\":\"btcusdt@trade\",\"data\":{\"e\":\"trade\",\"E\":1788563054664,\"T\":1788563054664,\"s\":\"BTCUSDT\",\"t\":8054081731,\"p\":\"79598.10\",\"q\":\"0.026\",\"X\":\"MARKET\",\"m\":true,\"st\":1}}"}
{"receive_ns":1788563054601013000,"stream":"btcusdt@bookTicker","event_type":"bookTicker","event_time_ms":1788563054666,"raw_json":"{\"stream\":\"btcusdt@bookTicker\",\"data\":{\"e\":\"bookTicker\",\"u\":11478213422833,\"s\":\"BTCUSDT\",\"ps\":\"BTCUSDT\",\"b\":\"79598.10\",\"B\":\"10.429\",\"a\":\"79598.20\",\"A\":\"3.764\",\"T\":1788563054666,\"E\":1788563054666,\"st\":1}}"}
{"receive_ns":1788563054601305000,"stream":"btcusdt@bookTicker","event_type":"bookTicker","event_time_ms":1788563054666,"raw_json":"{\"stream\":\"btcusdt@bookTicker\",\"data\":{\"e\":\"bookTicker\",\"u\":11478213422921,\"s\":\"BTCUSDT\",\"ps\":\"BTCUSDT\",\"b\":\"79598.10\",\"B\":\"10.421\",\"a\":\"79598.20\",\"A\":\"3.764\",\"T\":1788563054666,\"E\":1788563054666,\"st\":1}}"}
{"receive_ns":1788563054664950000,"stream":"btcusdt@bookTicker","event_type":"bookTicker","event_time_ms":1788563054729,"raw_json":"{\"stream\":\"btcusdt@bookTicker\",\"data\":{\"e\":\"bookTicker\",\"u\":11478213426231,\"s\":\"BTCUSDT\",\"ps\":\"BTCUSDT\",\"b\":\"79598.10\",\"B\":\"10.421\",\"a\":\"79598.20\",\"A\":\"3.766\",\"T\":1788563054729,\"E\":1788563054729,\"st\":1}}"}
{"receive_ns":1788563054678201000,"stream":"btcusdt@depth@100ms","event_type":"depthUpdate","event_time_ms":1788563054741,"raw_json":"{\"stream\":\"btcusdt@depth@100ms\",\"data\":{\"e\":\"depthUpdate\",\"E\":1788563054741,\"T\":1788563054739,\"s\":\"BTCUSDT\",\"ps\":\"BTCUSDT\",\"U\":11478213421341,\"u\":11478213426702,\"pu\":11478213421260,\"b\":[[\"1000.00\",\"24.604\"],[\"29098.10\",\"0.014\"],[\"29198.10\",\"1.757\"],[\"29298.10\",\"0.329\"],[\"71638.20\",\"0.002\"],[\"71675.00\",\"0.002\"],[\"76414.10\",\"0.000\"],[\"78802.10\",\"10.280\"],[\"78956.90\",\"0.254\"],[\"78961.30\",\"3.539\"],[\"79200.10\",\"3.858\"],[\"79400.00\",\"4.554\"],[\"79401.10\",\"1.431\"],[\"79473.60\",\"0.008\"],[\"79534.00\",\"0.001\"],[\"79534.60\",\"1.382\"],[\"79536.70\",\"22.483\"],[\"79566.40\",\"0.002\"],[\"79567.60\",\"0.001\"],[\"79594.00\",\"0.030\"],[\"79594.10\",\"0.526\"],[\"79596.40\",\"0.073\"],[\"79597.60\",\"0.200\"],[\"79598.10\",\"10.421\"]],\"a\":[[\"79598.20\",\"3.766\"],[\"79598.40\",\"0.334\"],[\"79600.30\",\"0.031\"],[\"79602.20\",\"0.280\"],[\"79603.10\",\"0.000\"],[\"79642.40\",\"2.948\"],[\"79664.20\",\"0.002\"],[\"79721.80\",\"2.676\"],[\"79962.40\",\"0.764\"],[\"79996.20\",\"3.775\"],[\"80230.40\",\"0.995\"],[\"80354.40\",\"5.339\"],[\"80394.20\",\"10.445\"],[\"80573.20\",\"2.256\"]],\"st\":1}}"}
{"receive_ns":1788563054686473000,"stream":"btcusdt@bookTicker","event_type":"bookTicker","event_time_ms":1788563054751,"raw_json":"{\"stream\":\"btcusdt@bookTicker\",\"data\":{\"e\":\"bookTicker\",\"u\":11478213427342,\"s\":\"BTCUSDT\",\"ps\":\"BTCUSDT\",\"b\":\"79598.10\",\"B\":\"10.405\",\"a\":\"79598.20\",\"A\":\"3.766\",\"T\":1788563054751,\"E\":1788563054751,\"st\":1}}"}
{"receive_ns":1788563054696950000,"stream":"btcusdt@bookTicker","event_type":"bookTicker","event_time_ms":1788563054760,"raw_json":"{\"stream\":\"btcusdt@bookTicker\",\"data\":{\"e\":\"bookTicker\",\"u\":11478213427887,\"s\":\"BTCUSDT\",\"ps\":\"BTCUSDT\",\"b\":\"79598.10\",\"B\":\"10.405\",\"a\":\"79598.20\",\"A\":\"3.773\",\"T\":1788563054760,\"E\":1788563054760,\"st\":1}}"}
{"receive_ns":1788563054703637000,"stream":"btcusdt@bookTicker","event_type":"bookTicker","event_time_ms":1788563054766,"raw_json":"{\"stream\":\"btcusdt@bookTicker\",\"data\":{\"e\":\"bookTicker\",\"u\":11478213428464,\"s\":\"BTCUSDT\",\"ps\":\"BTCUSDT\",\"b\":\"79598.10\",\"B\":\"10.405\",\"a\":\"79598.20\",\"A\":\"3.775\",\"T\":1788563054766,\"E\":1788563054766,\"st\":1}}"}
{"receive_ns":1788563054779606000,"stream":"btcusdt@depth@100ms","event_type":"depthUpdate","event_time_ms":1788563054843,"raw_json":"{\"stream\":\"btcusdt@depth@100ms\",\"data\":{\"e\":\"depthUpdate\",\"E\":1788563054843,\"T\":1788563054842,\"s\":\"BTCUSDT\",\"ps\":\"BTCUSDT\",\"U\":11478213426837,\"u\":11478213433475,\"pu\":11478213426702,\"b\":[[\"29098.10\",\"0.070\"],[\"29198.10\",\"1.827\"],[\"29298.10\",\"0.203\"],[\"63678.50\",\"0.000\"],[\"71638.20\",\"0.002\"],[\"78802.10\",\"10.279\"],[\"79228.00\",\"0.245\"],[\"79401.10\",\"1.933\"],[\"79402.00\",\"0.201\"],[\"79462.70\",\"0.010\"],[\"79472.70\",\"2.552\"],[\"79473.50\",\"0.606\"],[\"79496.20\",\"0.065\"],[\"79502.50\",\"0.001\"],[\"79520.00\",\"1.699\"],[\"79526.40\",\"0.003\"],[\"79536.00\",\"0.711\"],[\"79557.20\",\"0.001\"],[\"79569.40\",\"3.881\"],[\"79572.40\",\"0.254\"],[\"79573.00\",\"0.001\"],[\"79574.60\",\"0.472\"],[\"79574.90\",\"0.439\"],[\"79598.10\",\"10.405\"]],\"a\":[[\"79598.20\",\"3.775\"],[\"79600.10\",\"0.027\"],[\"79600.30\",\"0.005\"],[\"79600.90\",\"0.030\"],[\"79601.00\",\"0.034\"],[\"79602.10\",\"0.279\"],[\"79602.40\",\"0.001\"],[\"79602.50\",\"0.000\"],[\"79603.10\",\"0.200\"],[\"79604.00\",\"2.875\"],[\"79608.10\",\"0.352\"],[\"79610.20\",\"0.002\"],[\"79611.40\",\"0.859\"],[\"79613.40\",\"0.003\"],[\"79614.50\",\"0.624\"],[\"79615.50\",\"0.000\"],[\"79616.90\",\"0.456\"],[\"79638.00\",\"0.070\"],[\"79669.90\",\"0.000\"],[\"79693.80\",\"0.000\"],[\"79721.00\",\"0.367\"],[\"79757.00\",\"0.000\"],[\"79962.40\",\"1.183\"],[\"79994.20\",\"0.000\"],[\"79996.20\",\"4.345\"],[\"80394.20\",\"10.445\"],[\"80692.60\",\"9.531\"]],\"st\":1}}"}
{"receive_ns":1788563054779979000,"stream":"btcusdt@bookTicker","event_type":"bookTicker","event_time_ms":1788563054843,"raw_json":"{\"stream\":\"btcusdt@bookTicker\",\"data\":{\"e\":\"bookTicker\",\"u\":11478213433539,\"s\":\"BTCUSDT\",\"ps\":\"BTCUSDT\",\"b\":\"79598.10\",\"B\":\"10.405\",\"a\":\"79598.20\",\"A\":\"3.774\",\"T\":1788563054843,\"E\":1788563054843,\"st\":1}}"}
{"receive_ns":1788563054881973000,"stream":"btcusdt@depth@100ms","event_type":"depthUpdate","event_time_ms":1788563054945,"raw_json":"{\"stream\":\"btcusdt@depth@100ms\",\"data\":{\"e\":\"depthUpdate\",\"E\":1788563054945,\"T\":1788563054943,\"s\":\"BTCUSDT\",\"ps\":\"BTCUSDT\",\"U\":11478213433539,\"u\":11478213440273,\"pu\":11478213433475,\"b\":[[\"1000.00\",\"24.604\"],[\"29098.10\",\"0.133\"],[\"29198.10\",\"1.876\"],[\"29298.10\",\"0.091\"],[\"63678.00\",\"0.004\"],[\"71638.20\",\"0.002\"],[\"76414.10\",\"0.002\"],[\"78802.10\",\"10.279\"],[\"78995.00\",\"0.045\"],[\"79531.30\",\"0.011\"],[\"79534.00\",\"22.484\"],[\"79536.70\",\"0.000\"],[\"79554.60\",\"0.001\"],[\"79554.70\",\"2.511\"],[\"79556.90\",\"0.637\"],[\"79565.40\",\"10.885\"],[\"79565.90\",\"1.042\"],[\"79573.00\",\"0.440\"],[\"79573.30\",\"0.373\"],[\"79574.60\",\"0.099\"],[\"79574.90\",\"0.000\"],[\"79578.20\",\"0.405\"],[\"79580.10\",\"0.006\"],[\"79583.20\",\"0.002\"]],\"a\":[[\"79598.20\",\"3.774\"],[\"79599.10\",\"0.028\"],[\"79599.50\",\"0.028\"],[\"79600.10\",\"0.001\"],[\"79600.70\",\"0.028\"],[\"79602.10\",\"0.253\"],[\"79602.20\",\"0.254\"],[\"79608.10\",\"0.262\"],[\"79609.40\",\"0.377\"],[\"79609.50\",\"0.013\"],[\"79610.20\",\"0.002\"],[\"79618.20\",\"0.627\"],[\"79621.10\",\"0.736\"],[\"79621.20\",\"0.000\"],[\"79735.20\",\"0.018\"],[\"80692.60\",\"9.283\"]],\"st\":1}}"}
{"receive_ns":1788563054892464000,"stream":"btcusdt@bookTicker","event_type":"bookTicker","event_time_ms":1788563054954,"raw_json":"{\"stream\":\"btcusdt@bookTicker\",\"data\":{\"e\":\"bookTicker\",\"u\":11478213440962,\"s\":\"BTCUSDT\",\"ps\":\"BTCUSDT\",\"b\":\"79598.10\",\"B\":\"10.416\",\"a\":\"79598.20\",\"A\":\"3.774\",\"T\":1788563054954,\"E\":1788563054954,\"st\":1}}"}
{"receive_ns":1788563054967889000,"stream":"btcusdt@bookTicker","event_type":"bookTicker","event_time_ms":1788563055024,"raw_json":"{\"stream\":\"btcusdt@bookTicker\",\"data\":{\"e\":\"bookTicker\",\"u\":11478213444699,\"s\":\"BTCUSDT\",\"ps\":\"BTCUSDT\",\"b\":\"79598.10\",\"B\":\"10.416\",\"a\":\"79598.20\",\"A\":\"3.775\",\"T\":1788563055024,\"E\":1788563055024,\"st\":1}}"}
{"receive_ns":1788563054971057000,"stream":"btcusdt@bookTicker","event_type":"bookTicker","event_time_ms":1788563055036,"raw_json":"{\"stream\":\"btcusdt@bookTicker\",\"data\":{\"e\":\"bookTicker\",\"u\":11478213445730,\"s\":\"BTCUSDT\",\"ps\":\"BTCUSDT\",\"b\":\"79598.10\",\"B\":\"10.416\",\"a\":\"79598.20\",\"A\":\"4.118\",\"T\":1788563055036,\"E\":1788563055036,\"st\":1}}"}
{"receive_ns":1788563054972279000,"stream":"btcusdt@bookTicker","event_type":"bookTicker","event_time_ms":1788563055037,"raw_json":"{\"stream\":\"btcusdt@bookTicker\",\"data\":{\"e\":\"bookTicker\",\"u\":11478213445929,\"s\":\"BTCUSDT\",\"ps\":\"BTCUSDT\",\"b\":\"79598.10\",\"B\":\"10.416\",\"a\":\"79598.20\",\"A\":\"4.117\",\"T\":1788563055037,\"E\":1788563055037,\"st\":1}}"}
{"receive_ns":1788563054984315000,"stream":"btcusdt@depth@100ms","event_type":"depthUpdate","event_time_ms":1788563055047,"raw_json":"{\"stream\":\"btcusdt@depth@100ms\",\"data\":{\"e\":\"depthUpdate\",\"E\":1788563055047,\"T\":1788563055046,\"s\":\"BTCUSDT\",\"ps\":\"BTCUSDT\",\"U\":11478213440355,\"u\":11478213446835,\"pu\":11478213440273,\"b\":[[\"1000.00\",\"24.604\"],[\"29098.10\",\"0.224\"],[\"29198.10\",\"1.876\"],[\"29298.10\",\"0.000\"],[\"63678.00\",\"0.004\"],[\"71638.20\",\"0.002\"],[\"76414.10\",\"0.000\"],[\"78576.90\",\"0.008\"],[\"78579.40\",\"0.005\"],[\"78603.10\",\"4.391\"],[\"78608.50\",\"0.000\"],[\"78610.80\",\"0.004\"],[\"78802.10\",\"10.279\"],[\"78961.30\",\"6.700\"],[\"79200.10\",\"3.868\"],[\"79228.00\",\"0.013\"],[\"79401.10\",\"0.502\"],[\"79402.00\",\"0.201\"],[\"79461.20\",\"0.125\"],[\"79472.70\",\"2.552\"],[\"79473.50\",\"0.606\"],[\"79520.00\",\"0.870\"],[\"79536.00\",\"0.020\"],[\"79571.00\",\"10.001\"],[\"79574.20\",\"0.003\"],[\"79574.30\",\"0.001\"],[\"79574.40\",\"0.050\"],[\"79578.20\",\"0.417\"],[\"79583.80\",\"0.004\"],[\"79592.00\",\"0.291\"],[\"79598.10\",\"10.416\"]],\"a\":[[\"79598.20\",\"4.117\"],[\"79602.10\",\"0.002\"],[\"79602.20\",\"0.254\"],[\"79603.10\",\"0.200\"],[\"79609.40\",\"0.006\"],[\"79609.50\",\"0.322\"],[\"79609.60\",\"0.258\"],[\"79610.20\",\"0.503\"],[\"79611.40\",\"0.420\"],[\"79614.30\",\"0.361\"],[\"79636.60\",\"2.003\"],[\"79720.90\",\"0.367\"],[\"79721.00\",\"0.000\"],[\"79962.40\",\"0.419\"],[\"79996.20\",\"4.145\"],[\"80235.00\",\"7.347\"],[\"80394.20\",\"10.445\"],[\"81190.10\",\"0.017\"]],\"st\":1}}"}
{"receive_ns":1788563054995639000,"stream":"btcusdt@bookTicker","event_type":"bookTicker","event_time_ms":1788563055058,"raw_json":"{\"stream\":\"btcusdt@bookTicker\",\"data\":{\"e\":\"bookTicker\",\"u\":11478213448062,\"s\":\"BTCUSDT\",\"ps\":\"BTCUSDT\",\"b\":\"79598.10\",\"B\":\"10.410\",\"a\":\"79598.20\",\"A\":\"4.117\",\"T\":1788563055058,\"E\":1788563055058,\"st\":1}}"}
{"receive_ns":1788563055086604000,"stream":"btcusdt@depth@100ms","event_type":"depthUpdate","event_time_ms":1788563055149,"raw_json":"{\"stream\":\"btcusdt@depth@100ms\",\"data\":{\"e\":\"depthUpdate\",\"E\":1788563055149,\"T\":1788563055145,\"s\":\"BTCUSDT\",\"ps\":\"BTCUSDT\",\"U\":11478213447105,\"u\":11478213452974,\"pu\":11478213446835,\"b\":[[\"29098.10\",\"0.399\"],[\"29198.10\",\"1.701\"],[\"63678.00\",\"0.004\"],[\"63679.00\",\"0.002\"],[\"71638.20\",\"0.002\"],[\"76414.10\",\"0.002\"],[\"78439.50\",\"14.934\"],[\"78603.10\",\"4.582\"],[\"78802.10\",\"10.279\"],[\"79016.20\",\"0.253\"],[\"79228.00\",\"0.245\"],[\"79401.10\",\"1.933\"],[\"79461.20\",\"0.000\"],[\"79563.20\",\"0.010\"],[\"79565.30\",\"0.242\"],[\"79572.40\",\"0.254\"],[\"79573.00\",\"0.001\"],[\"79573.30\",\"0.000\"],[\"79574.50\",\"0.376\"],[\"79574.90\",\"0.439\"],[\"79583.80\",\"0.000\"],[\"79598.10\",\"10.410\"]],\"a\":[[\"79598.80\",\"0.041\"],[\"79599.10\",\"0.002\"],[\"79602.10\",\"0.253\"],[\"79602.20\",\"0.003\"],[\"79610.20\",\"0.064\"],[\"79611.00\",\"1.130\"],[\"79612.40\",\"0.000\"],[\"79613.50\",\"1.245\"],[\"79614.40\",\"0.372\"],[\"79614.50\",\"0.252\"],[\"79627.10\",\"0.000\"],[\"79628.10\",\"0.016\"],[\"79629.10\",\"0.239\"],[\"79629.20\",\"0.020\"],[\"79642.30\",\"0.078\"],[\"79666.10\",\"23.724\"],[\"79668.80\",\"0.001\"],[\"79675.80\",\"0.004\"],[\"79685.20\",\"0.001\"],[\"79757.10\",\"0.000\"],[\"79962.40\",\"1.273\"],[\"79996.20\",\"4.345\"],[\"80394.20\",\"10.445\"]],\"st\":1}}"}
{"receive_ns":1788563055101304000,"stream":"btcusdt@bookTicker","event_type":"bookTicker","event_time_ms":1788563055166,"raw_json":"{\"stream\":\"btcusdt@bookTicker\",\"data\":{\"e\":\"bookTicker\",\"u\":11478213454153,\"s\":\"BTCUSDT\",\"ps\":\"BTCUSDT\",\"b\":\"79598.10\",\"B\":\"10.418\",\"a\":\"79598.20\",\"A\":\"4.117\",\"T\":1788563055166,\"E\":1788563055166,\"st\":1}}"}
{"receive_ns":1788563055101591000,"stream":"btcusdt@bookTicker","event_type":"bookTicker","event_time_ms":1788563055166,"raw_json":"{\"stream\":\"btcusdt@bookTicker\",\"data\":{\"e\":\"bookTicker\",\"u\":11478213454189,\"s\":\"BTCUSDT\",\"ps\":\"BTCUSDT\",\"b\":\"79598.10\",\"B\":\"10.353\",\"a\":\"79598.20\",\"A\":\"4.117\",\"T\":1788563055166,\"E\":1788563055166,\"st\":1}}"}
{"receive_ns":1788563055101756000,"stream":"btcusdt@bookTicker","event_type":"bookTicker","event_time_ms":1788563055167,"raw_json":"{\"stream\":\"btcusdt@bookTicker\",\"data\":{\"e\":\"bookTicker\",\"u\":11478213454205,\"s\":\"BTCUSDT\",\"ps\":\"BTCUSDT\",\"b\":\"79598.10\",\"B\":\"10.345\",\"a\":\"79598.20\",\"A\":\"4.117\",\"T\":1788563055166,\"E\":1788563055167,\"st\":1}}"}
{"receive_ns":1788563055106079000,"stream":"btcusdt@bookTicker","event_type":"bookTicker","event_time_ms":1788563055170,"raw_json":"{\"stream\":\"btcusdt@bookTicker\",\"data\":{\"e\":\"bookTicker\",\"u\":11478213454403,\"s\":\"BTCUSDT\",\"ps\":\"BTCUSDT\",\"b\":\"79598.10\",\"B\":\"10.418\",\"a\":\"79598.20\",\"A\":\"4.117\",\"T\":1788563055169,\"E\":1788563055170,\"st\":1}}"}
{"receive_ns":1788563055106376000,"stream":"btcusdt@bookTicker","event_type":"bookTicker","event_time_ms":1788563055171,"raw_json":"{\"stream\":\"btcusdt@bookTicker\",\"data\":{\"e\":\"bookTicker\",\"u\":11478213454450,\"s\":\"BTCUSDT\",\"ps\":\"BTCUSDT\",\"b\":\"79598.10\",\"B\":\"10.418\",\"a\":\"79598.20\",\"A\":\"4.118\",\"T\":1788563055171,\"E\":1788563055171,\"st\":1}}"}
{"receive_ns":1788563055170397000,"stream":"btcusdt@bookTicker","event_type":"bookTicker","event_time_ms":1788563055235,"raw_json":"{\"stream\":\"btcusdt@bookTicker\",\"data\":{\"e\":\"bookTicker\",\"u\":11478213457825,\"s\":\"BTCUSDT\",\"ps\":\"BTCUSDT\",\"b\":\"79598.10\",\"B\":\"10.418\",\"a\":\"79598.20\",\"A\":\"4.117\",\"T\":1788563055235,\"E\":1788563055235,\"st\":1}}"}
{"receive_ns":1788563055189003000,"stream":"btcusdt@depth@100ms","event_type":"depthUpdate","event_time_ms":1788563055251,"raw_json":"{\"stream\":\"btcusdt@depth@100ms\",\"data\":{\"e\":\"depthUpdate\",\"E\":1788563055251,\"T\":1788563055249,\"s\":\"BTCUSDT\",\"ps\":\"BTCUSDT\",\"U\":11478213453174,\"u\":11478213458673,\"pu\":11478213452974,\"b\":[[\"1000.00\",\"24.604\"],[\"29098.10\",\"0.581\"],[\"29198.10\",\"1.519\"],[\"71638.20\",\"0.002\"],[\"75618.20\",\"0.006\"],[\"75618.30\",\"0.004\"],[\"76414.10\",\"0.000\"],[\"78006.20\",\"0.018\"],[\"78802.10\",\"10.279\"],[\"79200.10\",\"3.869\"],[\"79401.10\",\"2.938\"],[\"79402.00\",\"0.000\"],[\"79472.70\",\"1.547\"],[\"79564.10\",\"0.154\"],[\"79565.30\",\"0.196\"],[\"79567.70\",\"0.004\"],[\"79567.80\",\"10.004\"],[\"79571.00\",\"0.001\"],[\"79573.00\",\"0.440\"],[\"79573.30\",\"0.373\"],[\"79574.50\",\"0.003\"],[\"79574.90\",\"0.000\"],[\"79585.70\",\"0.002\"],[\"79598.10\",\"10.418\"]],\"a\":[[\"79598.20\",\"4.117\"],[\"79598.80\",\"0.015\"],[\"79599.00\",\"0.027\"],[\"79599.10\",\"0.028\"],[\"79599.30\",\"0.028\"],[\"79599.40\",\"0.026\"],[\"79601.80\",\"0.001\"],[\"79601.90\",\"0.000\"],[\"79602.00\",\"0.077\"],[\"79602.20\",\"0.254\"],[\"79603.10\",\"0.000\"],[\"79685.20\",\"0.002\"],[\"79699.40\",\"0.168\"],[\"79757.30\",\"0.125\"],[\"79962.40\",\"1.273\"],[\"79996.20\",\"4.344\"],[\"80394.20\",\"10.445\"]],\"st\":1}}"}
{"receive_ns":1788563055285054000,"stream":"btcusdt@bookTicker","event_type":"bookTicker","event_time_ms":1788563055349,"raw_json":"{\"stream\":\"btcusdt@bookTicker\",\"data\":{\"e\":\"bookTicker\",\"u\":11478213465275,\"s\":\"BTCUSDT\",\"ps\":\"BTCUSDT\",\"b\":\"79598.10\",\"B\":\"10.418\",\"a\":\"79598.20\",\"A\":\"4.116\",\"T\":1788563055349,\"E\":1788563055349,\"st\":1}}"}
{"receive_ns":1788563055291292000,"stream":"btcusdt@depth@100ms","event_type":"depthUpdate","event_time_ms":1788563055353,"raw_json":"{\"stream\":\"btcusdt@depth@100ms\",\"data\":{\"e\":\"depthUpdate\",\"E\":1788563055353,\"T\":1788563055352,\"s\":\"BTCUSDT\",\"ps\":\"BTCUSDT\",\"U\":11478213458758,\"u\":11478213465460,\"pu\":11478213458673,\"b\":[[\"1000.00\",\"24.604\"],[\"29098.10\",\"0.756\"],[\"29198.10\",\"1.344\"],[\"71638.20\",\"0.002\"],[\"78443.90\",\"8.249\"],[\"78552.00\",\"0.444\"],[\"78802.10\",\"10.281\"],[\"79200.10\",\"3.869\"],[\"79228.00\",\"0.245\"],[\"79401.10\",\"2.938\"],[\"79404.00\",\"1.215\"],[\"79460.90\",\"0.427\"]],\"a\":[[\"79598.20\",\"4.116\"],[\"79602.10\",\"0.253\"],[\"79603.10\",\"0.200\"],[\"79757.10\",\"0.125\"],[\"79757.20\",\"0.001\"],[\"79757.30\",\"0.000\"],[\"79757.50\",\"1.831\"],[\"79962.40\",\"1.183\"],[\"79966.30\",\"0.091\"],[\"79994.20\",\"0.044\"],[\"79996.20\",\"4.300\"],[\"80013.80\",\"0.003\"],[\"80016.90\",\"0.087\"],[\"80394.20\",\"10.445\"],[\"80746.80\",\"1.778\"]],\"st\":1}}"}
{"receive_ns":1788563055368700000,"stream":"btcusdt@bookTicker","event_type":"bookTicker","event_time_ms":1788563055432,"raw_json":"{\"stream\":\"btcusdt@bookTicker\",\"data\":{\"e\":\"bookTicker\",\"u\":11478213469012,\"s\":\"BTCUSDT\",\"ps\":\"BTCUSDT\",\"b\":\"79598.10\",\"B\":\"10.426\",\"a\":\"79598.20\",\"A\":\"4.116\",\"T\":1788563055432,\"E\":1788563055432,\"st\":1}}"}
{"receive_ns":1788563055368982000,"stream":"btcusdt@bookTicker","event_type":"bookTicker","event_time_ms":1788563055433,"raw_json":"{\"stream\":\"btcusdt@bookTicker\",\"data\":{\"e\":\"bookTicker\",\"u\":11478213469080,\"s\":\"BTCUSDT\",\"ps\":\"BTCUSDT\",\"b\":\"79598.10\",\"B\":\"10.418\",\"a\":\"79598.20\",\"A\":\"4.116\",\"T\":1788563055432,\"E\":1788563055433,\"st\":1}}"}
{"receive_ns":1788563055378485000,"stream":"btcusdt@bookTicker","event_type":"bookTicker","event_time_ms":1788563055443,"raw_json":"{\"stream\":\"btcusdt@bookTicker\",\"data\":{\"e\":\"bookTicker\",\"u\":11478213469644,\"s\":\"BTCUSDT\",\"ps\":\"BTCUSDT\",\"b\":\"79598.10\",\"B\":\"10.359\",\"a\":\"79598.20\",\"A\":\"4.116\",\"T\":1788563055443,\"E\":1788563055443,\"st\":1}}"}
{"receive_ns":1788563055385167000,"stream":"btcusdt@bookTicker","event_type":"bookTicker","event_time_ms":1788563055448,"raw_json":"{\"stream\":\"btcusdt@bookTicker\",\"data\":{\"e\":\"bookTicker\",\"u\":11478213469911,\"s\":\"BTCUSDT\",\"ps\":\"BTCUSDT\",\"b\":\"79598.10\",\"B\":\"10.420\",\"a\":\"79598.20\",\"A\":\"4.116\",\"T\":1788563055448,\"E\":1788563055448,\"st\":1}}"}
{"receive_ns":1788563055393789000,"stream":"btcusdt@depth@100ms","event_type":"depthUpdate","event_time_ms":1788563055455,"raw_json":"{\"stream\":\"btcusdt@depth@100ms\",\"data\":{\"e\":\"depthUpdate\",\"E\":1788563055455,\"T\":1788563055454,\"s\":\"BTCUSDT\",\"ps\":\"BTCUSDT\",\"U\":11478213465486,\"u\":11478213470197,\"pu\":11478213465460,\"b\":[[\"29098.10\",\"0.938\"],[\"29198.10\",\"1.162\"],[\"71638.20\",\"0.002\"],[\"76414.10\",\"0.002\"],[\"78006.20\",\"0.021\"],[\"78638.50\",\"20.906\"],[\"78802.10\",\"10.279\"],[\"79200.10\",\"3.728\"],[\"79401.10\",\"1.431\"],[\"79404.00\",\"1.014\"],[\"79563.10\",\"0.004\"],[\"79564.10\",\"0.154\"],[\"79565.20\",\"0.102\"],[\"79572.40\",\"0.254\"],[\"79573.00\",\"0.001\"],[\"79573.30\",\"0.000\"],[\"79574.50\",\"0.376\"],[\"79574.90\",\"0.439\"],[\"79591.50\",\"0.197\"],[\"79595.30\",\"0.003\"],[\"79598.00\",\"0.035\"],[\"79598.10\",\"10.420\"]],\"a\":[[\"79598.60\",\"0.000\"],[\"79599.00\",\"0.001\"],[\"79602.20\",\"0.003\"],[\"79603.10\",\"0.000\"],[\"79609.60\",\"0.258\"],[\"79610.20\",\"0.064\"],[\"79611.00\",\"1.130\"],[\"79612.40\",\"0.000\"],[\"79613.40\",\"0.003\"],[\"79614.40\",\"0.372\"],[\"79626.90\",\"0.010\"],[\"79628.00\",\"2.004\"],[\"79629.00\",\"0.047\"],[\"79629.10\",\"0.193\"],[\"79757.00\",\"0.000\"],[\"79757.10\",\"0.000\"],[\"79757.20\",\"0.001\"],[\"79757.30\",\"0.125\"],[\"79962.40\",\"0.764\"],[\"79996.20\",\"3.774\"],[\"80394.20\",\"10.445\"]],\"st\":1}}"}
{"receive_ns":1788563055394089000,"stream":"btcusdt@bookTicker","event_type":"bookTicker","event_time_ms":1788563055456,"raw_json":"{\"stream\":\"btcusdt@bookTicker\",\"data\":{\"e\":\"bookTicker\",\"u\":11478213470287,\"s\":\"BTCUSDT\",\"ps\":\"BTCUSDT\",\"b\":\"79598.10\",\"B\":\"10.428\",\"a\":\"79598.20\",\"A\":\"4.116\",\"T\":1788563055456,\"E\":1788563055456,\"st\":1}}"}
{"receive_ns":1788563055394298000,"stream":"btcusdt@bookTicker","event_type":"bookTicker","event_time_ms":1788563055457,"raw_json":"{\"stream\":\"btcusdt@bookTicker\",\"data\":{\"e\":\"bookTicker\",\"u\":11478213470350,\"s\":\"BTCUSDT\",\"ps\":\"BTCUSDT\",\"b\":\"79598.10\",\"B\":\"10.420\",\"a\":\"79598.20\",\"A\":\"4.116\",\"T\":1788563055456,\"E\":1788563055457,\"st\":1}}"}
{"receive_ns":1788563055417275000,"stream":"btcusdt@bookTicker","event_type":"bookTicker","event_time_ms":1788563055481,"raw_json":"{\"stream\":\"btcusdt@bookTicker\",\"data\":{\"e\":\"bookTicker\",\"u\":11478213471483,\"s\":\"BTCUSDT\",\"ps\":\"BTCUSDT\",\"b\":\"79598.10\",\"B\":\"10.420\",\"a\":\"79598.20\",\"A\":\"4.118\",\"T\":1788563055481,\"E\":1788563055481,\"st\":1}}"}
{"receive_ns":1788563055430052000,"stream":"btcusdt@bookTicker","event_type":"bookTicker","event_time_ms":1788563055494,"raw_json":"{\"stream\":\"btcusdt@bookTicker\",\"data\":{\"e\":\"bookTicker\",\"u\":11478213472136,\"s\":\"BTCUSDT\",\"ps\":\"BTCUSDT\",\"b\":\"79598.10\",\"B\":\"10.420\",\"a\":\"79598.20\",\"A\":\"4.126\",\"T\":1788563055494,\"E\":1788563055494,\"st\":1}}"}
{"receive_ns":1788563055464919000,"stream":"btcusdt@bookTicker","event_type":"bookTicker","event_time_ms":1788563055528,"raw_json":"{\"stream\":\"btcusdt@bookTicker\",\"data\":{\"e\":\"bookTicker\",\"u\":11478213473747,\"s\":\"BTCUSDT\",\"ps\":\"BTCUSDT\",\"b\":\"79598.10\",\"B\":\"10.420\",\"a\":\"79598.20\",\"A\":\"4.124\",\"T\":1788563055528,\"E\":1788563055528,\"st\":1}}"}
{"receive_ns":1788563055496083000,"stream":"btcusdt@depth@100ms","event_type":"depthUpdate","event_time_ms":1788563055557,"raw_json":"{\"stream\":\"btcusdt@depth@100ms\",\"data\":{\"e\":\"depthUpdate\",\"E\":1788563055557,\"T\":1788563055554,\"s\":\"BTCUSDT\",\"ps\":\"BTCUSDT\",\"U\":11478213470249,\"u\":11478213474965,\"pu\":11478213470197,\"b\":[[\"1000.00\",\"24.604\"],[\"29098.10\",\"1.113\"],[\"29198.10\",\"0.987\"],[\"71638.20\",\"0.002\"],[\"75618.20\",\"0.008\"],[\"76414.10\",\"0.000\"],[\"78483.70\",\"25.959\"],[\"78802.10\",\"10.279\"],[\"79200.10\",\"3.869\"],[\"79228.00\",\"0.013\"],[\"79401.10\",\"1.507\"],[\"79404.00\",\"1.215\"],[\"79460.90\",\"0.302\"],[\"79473.90\",\"0.400\"],[\"79534.60\",\"4.274\"],[\"79563.10\",\"0.050\"],[\"79564.10\",\"0.108\"],[\"79565.10\",\"0.001\"],[\"79566.00\",\"0.453\"],[\"79567.80\",\"10.005\"],[\"79567.90\",\"3.923\"],[\"79572.10\",\"0.518\"],[\"79572.30\",\"0.394\"],[\"79573.30\",\"0.000\"],[\"79574.50\",\"0.003\"],[\"79574.90\",\"0.000\"],[\"79595.30\",\"0.079\"],[\"79598.10\",\"10.420\"]],\"a\":[[\"79598.20\",\"4.124\"],[\"79599.10\",\"0.002\"],[\"79599.30\",\"0.002\"],[\"79601.30\",\"0.026\"],[\"79602.10\",\"0.002\"],[\"79602.20\",\"0.254\"],[\"79603.10\",\"0.200\"],[\"79609.40\",\"0.068\"],[\"79609.60\",\"0.258\"],[\"79610.20\",\"0.441\"],[\"79611.00\",\"0.691\"],[\"79612.20\",\"0.080\"],[\"79612.80\",\"0.255\"],[\"79613.30\",\"0.547\"],[\"79613.40\",\"0.375\"],[\"79614.40\",\"0.000\"],[\"79615.70\",\"0.454\"],[\"79616.90\",\"0.004\"],[\"79626.90\",\"0.010\"],[\"79628.00\",\"2.050\"],[\"79629.00\",\"0.001\"],[\"79665.20\",\"4.824\"],[\"79757.30\",\"0.000\"],[\"79961.60\",\"0.183\"],[\"79962.40\",\"0.419\"],[\"79966.30\",\"0.001\"],[\"79994.20\",\"0.000\"],[\"79996.20\",\"4.144\"],[\"80394.20\",\"10.445\"],[\"80752.40\",\"10.516\"],[\"87558.10\",\"0.000\"]],\"st\":1}}"}
{"receive_ns":1788563055502497000,"stream":"btcusdt@bookTicker","event_type":"bookTicker","event_time_ms":1788563055566,"raw_json":"{\"stream\":\"btcusdt@bookTicker\",\"data\":{\"e\":\"bookTicker\",\"u\":11478213475721,\"s\":\"BTCUSDT\",\"ps\":\"BTCUSDT\",\"b\":\"79598.10\",\"B\":\"10.428\",\"a\":\"79598.20\",\"A\":\"4.124\",\"T\":1788563055565,\"E\":1788563055566,\"st\":1}}"}
{"receive_ns":1788563055502944000,"stream":"btcusdt@bookTicker","event_type":"bookTicker","event_time_ms":1788563055566,"raw_json":"{\"stream\":\"btcusdt@bookTicker\",\"data\":{\"e\":\"bookTicker\",\"u\":11478213475790,\"s\":\"BTCUSDT\",\"ps\":\"BTCUSDT\",\"b\":\"79598.10\",\"B\":\"10.420\",\"a\":\"79598.20\",\"A\":\"4.124\",\"T\":1788563055566,\"E\":1788563055566,\"st\":1}}"}
{"receive_ns":1788563055595260000,"stream":"btcusdt@depth@100ms","event_type":"depthUpdate","event_time_ms":1788563055659,"raw_json":"{\"stream\":\"btcusdt@depth@100ms\",\"data\":{\"e\":\"depthUpdate\",\"E\":1788563055659,\"T\":1788563055657,\"s\":\"BTCUSDT\",\"ps\":\"BTCUSDT\",\"U\":11478213475180,\"u\":11478213482028,\"pu\":11478213474965,\"b\":[[\"1000.00\",\"24.604\"],[\"29098.10\",\"1.295\"],[\"29198.10\",\"0.805\"],[\"71638.20\",\"0.002\"],[\"76414.10\",\"0.002\"],[\"78642.90\",\"22.955\"],[\"78802.10\",\"10.279\"],[\"79228.00\",\"0.245\"],[\"79401.10\",\"2.938\"],[\"79598.10\",\"10.420\"]],\"a\":[[\"79599.20\",\"0.026\"],[\"79606.10\",\"0.252\"],[\"79820.70\",\"8.594\"],[\"79820.90\",\"0.000\"],[\"79962.40\",\"1.273\"],[\"79996.20\",\"4.344\"],[\"80394.20\",\"10.445\"],[\"87558.10\",\"0.000\"]],\"st\":1}}"}
{"receive_ns":1788563055632573000,"stream":"btcusdt@bookTicker","event_type":"bookTicker","event_time_ms":1788563055698,"raw_json":"{\"stream\":\"btcusdt@bookTicker\",\"data\":{\"e\":\"bookTicker\",\"u\":11478213484594,\"s\":\"BTCUSDT\",\"ps\":\"BTCUSDT\",\"b\":\"79598.10\",\"B\":\"10.428\",\"a\":\"79598.20\",\"A\":\"4.124\",\"T\":1788563055697,\"E\":1788563055698,\"st\":1}}"}
{"receive_ns":1788563055633464000,"stream":"btcusdt@bookTicker","event_type":"bookTicker","event_time_ms":1788563055698,"raw_json":"{\"stream\":\"btcusdt@bookTicker\",\"data\":{\"e\":\"bookTicker\",\"u\":11478213484681,\"s\":\"BTCUSDT\",\"ps\":\"BTCUSDT\",\"b\":\"79598.10\",\"B\":\"10.420\",\"a\":\"79598.20\",\"A\":\"4.124\",\"T\":1788563055698,\"E\":1788563055698,\"st\":1}}"}
{"receive_ns":1788563055635425000,"stream":"btcusdt@bookTicker","event_type":"bookTicker","event_time_ms":1788563055699,"raw_json":"{\"stream\":\"btcusdt@bookTicker\",\"data\":{\"e\":\"bookTicker\",\"u\":11478213484915,\"s\":\"BTCUSDT\",\"ps\":\"BTCUSDT\",\"b\":\"79598.10\",\"B\":\"10.420\",\"a\":\"79598.20\",\"A\":\"3.781\",\"T\":1788563055699,\"E\":1788563055699,\"st\":1}}"}
{"receive_ns":1788563055637970000,"stream":"btcusdt@bookTicker","event_type":"bookTicker","event_time_ms":1788563055702,"raw_json":"{\"stream\":\"btcusdt@bookTicker\",\"data\":{\"e\":\"bookTicker\",\"u\":11478213485523,\"s\":\"BTCUSDT\",\"ps\":\"BTCUSDT\",\"b\":\"79598.10\",\"B\":\"10.420\",\"a\":\"79598.20\",\"A\":\"3.408\",\"T\":1788563055701,\"E\":1788563055702,\"st\":1}}"}
{"receive_ns":1788563055638246000,"stream":"btcusdt@bookTicker","event_type":"bookTicker","event_time_ms":1788563055703,"raw_json":"{\"stream\":\"btcusdt@bookTicker\",\"data\":{\"e\":\"bookTicker\",\"u\":11478213485792,\"s\":\"BTCUSDT\",\"ps\":\"BTCUSDT\",\"b\":\"79598.10\",\"B\":\"10.428\",\"a\":\"79598.20\",\"A\":\"3.408\",\"T\":1788563055703,\"E\":1788563055703,\"st\":1}}"}
{"receive_ns":1788563055638527000,"stream":"btcusdt@bookTicker","event_type":"bookTicker","event_time_ms":1788563055704,"raw_json":"{\"stream\":\"btcusdt@bookTicker\",\"data\":{\"e\":\"bookTicker\",\"u\":11478213485915,\"s\":\"BTCUSDT\",\"ps\":\"BTCUSDT\",\"b\":\"79598.10\",\"B\":\"10.420\",\"a\":\"79598.20\",\"A\":\"3.408\",\"T\":1788563055704,\"E\":1788563055704,\"st\":1}}"}
{"receive_ns":1788563055652206000,"stream":"btcusdt@bookTicker","event_type":"bookTicker","event_time_ms":1788563055707,"raw_json":"{\"stream\":\"btcusdt@bookTicker\",\"data\":{\"e\":\"bookTicker\",\"u\":11478213486202,\"s\":\"BTCUSDT\",\"ps\":\"BTCUSDT\",\"b\":\"79598.10\",\"B\":\"10.420\",\"a\":\"79598.20\",\"A\":\"3.447\",\"T\":1788563055707,\"E\":1788563055707,\"st\":1}}"}
{"receive_ns":1788563055661553000,"stream":"btcusdt@bookTicker","event_type":"bookTicker","event_time_ms":1788563055726,"raw_json":"{\"stream\":\"btcusdt@bookTicker\",\"data\":{\"e\":\"bookTicker\",\"u\":11478213487467,\"s\":\"BTCUSDT\",\"ps\":\"BTCUSDT\",\"b\":\"79598.10\",\"B\":\"10.428\",\"a\":\"79598.20\",\"A\":\"3.447\",\"T\":1788563055725,\"E\":1788563055726,\"st\":1}}"}
{"receive_ns":1788563055661862000,"stream":"btcusdt@bookTicker","event_type":"bookTicker","event_time_ms":1788563055727,"raw_json":"{\"stream\":\"btcusdt@bookTicker\",\"data\":{\"e\":\"bookTicker\",\"u\":11478213487511,\"s\":\"BTCUSDT\",\"ps\":\"BTCUSDT\",\"b\":\"79598.10\",\"B\":\"10.420\",\"a\":\"79598.20\",\"A\":\"3.447\",\"T\":1788563055726,\"E\":1788563055727,\"st\":1}}"}
{"receive_ns":1788563055686227000,"stream":"btcusdt@bookTicker","event_type":"bookTicker","event_time_ms":1788563055750,"raw_json":"{\"stream\":\"btcusdt@bookTicker\",\"data\":{\"e\":\"bookTicker\",\"u\":11478213488568,\"s\":\"BTCUSDT\",\"ps\":\"BTCUSDT\",\"b\":\"79598.10\",\"B\":\"10.420\",\"a\":\"79598.20\",\"A\":\"3.445\",\"T\":1788563055749,\"E\":1788563055750,\"st\":1}}"}
{"receive_ns":1788563055695922000,"stream":"btcusdt@depth@100ms","event_type":"depthUpdate","event_time_ms":1788563055761,"raw_json":"{\"stream\":\"btcusdt@depth@100ms\",\"data\":{\"e\":\"depthUpdate\",\"E\":1788563055761,\"T\":1788563055759,\"s\":\"BTCUSDT\",\"ps\":\"BTCUSDT\",\"U\":11478213482149,\"u\":11478213489058,\"pu\":11478213482028,\"b\":[[\"29098.10\",\"1.470\"],[\"29198.10\",\"0.630\"],[\"71638.20\",\"0.002\"],[\"71675.00\",\"0.002\"],[\"78802.10\",\"10.279\"],[\"79200.10\",\"3.868\"],[\"79401.10\",\"1.933\"],[\"79404.00\",\"1.014\"],[\"79492.60\",\"1.006\"],[\"79502.50\",\"0.003\"],[\"79563.10\",\"0.004\"],[\"79564.20\",\"0.733\"],[\"79565.10\",\"0.453\"],[\"79565.40\",\"10.885\"],[\"79565.90\",\"1.036\"],[\"79566.00\",\"0.001\"],[\"79566.80\",\"0.006\"],[\"79567.70\",\"0.003\"],[\"79567.80\",\"0.005\"],[\"79567.90\",\"0.000\"],[\"79571.50\",\"0.002\"],[\"79572.10\",\"0.079\"],[\"79572.30\",\"0.021\"],[\"79572.80\",\"2.004\"],[\"79573.00\",\"0.440\"],[\"79573.50\",\"0.373\"],[\"79574.70\",\"0.001\"],[\"79574.90\",\"0.000\"],[\"79591.70\",\"1.074\"],[\"79598.10\",\"10.420\"]],\"a\":[[\"79598.20\",\"3.445\"],[\"79599.10\",\"0.028\"],[\"79599.20\",\"0.000\"],[\"79599.40\",\"0.000\"],[\"79601.40\",\"0.026\"],[\"79602.20\",\"0.254\"],[\"79603.10\",\"0.200\"],[\"79609.40\",\"0.381\"],[\"79609.50\",\"0.009\"],[\"79610.20\",\"0.002\"],[\"79611.40\",\"0.859\"],[\"79613.40\",\"0.003\"],[\"79614.60\",\"0.373\"],[\"79614.70\",\"0.001\"],[\"79615.60\",\"0.003\"],[\"79615.70\",\"0.002\"],[\"79615.80\",\"0.881\"],[\"79616.30\",\"1.138\"],[\"79616.90\",\"0.456\"],[\"79628.00\",\"2.004\"],[\"79629.20\",\"0.066\"],[\"79636.60\",\"0.003\"],[\"79640.10\",\"3.026\"],[\"79642.40\",\"12.948\"],[\"79667.90\",\"0.000\"],[\"79669.90\",\"0.002\"],[\"79962.40\",\"1.273\"],[\"79996.20\",\"4.345\"],[\"80394.20\",\"10.445\"]],\"st\":1}}"}
{"receive_ns":1788563055782026000,"stream":"btcusdt@bookTicker","event_type":"bookTicker","event_time_ms":1788563055843,"raw_json":"{\"stream\":\"btcusdt@bookTicker\",\"data\":{\"e\":\"bookTicker\",\"u\":11478213493136,\"s\":\"BTCUSDT\",\"ps\":\"BTCUSDT\",\"b\":\"79598.10\",\"B\":\"10.420\",\"a\":\"79598.20\",\"A\":\"3.444\",\"T\":1788563055843,\"E\":1788563055843,\"st\":1}}"}
{"receive_ns":1788563055803259000,"stream":"btcusdt@depth@100ms","event_type":"depthUpdate","event_time_ms":1788563055863,"raw_json":"{\"stream\":\"btcusdt@depth@100ms\",\"data\":{\"e\":\"depthUpdate\",\"E\":1788563055863,\"T\":1788563055861,\"s\":\"BTCUSDT\",\"ps\":\"BTCUSDT\",\"U\":11478213489199,\"u\":11478213494561,\"pu\":11478213489058,\"b\":[[\"1000.00\",\"24.604\"],[\"29098.10\",\"1.652\"],[\"29198.10\",\"0.448\"],[\"63678.50\",\"0.000\"],[\"71638.20\",\"0.002\"],[\"76414.10\",\"0.000\"],[\"78802.10\",\"10.279\"],[\"78996.60\",\"0.632\"],[\"79200.10\",\"3.858\"],[\"79228.00\",\"0.245\"],[\"79401.10\",\"0.602\"],[\"79404.00\",\"1.215\"],[\"79472.70\",\"2.552\"],[\"79494.60\",\"0.326\"],[\"79520.40\",\"0.832\"],[\"79536.30\",\"0.699\"],[\"79567.80\",\"0.004\"]],\"a\":[[\"79598.20\",\"3.444\"],[\"79606.10\",\"0.252\"],[\"79609.40\",\"0.002\"],[\"79609.50\",\"0.075\"],[\"79610.20\",\"0.315\"],[\"79962.40\",\"1.273\"],[\"79994.20\",\"0.156\"],[\"79996.20\",\"4.189\"],[\"80394.20\",\"10.445\"],[\"80573.20\",\"2.070\"],[\"80593.20\",\"2.485\"]],\"st\":1}}"}
{"receive_ns":1788563055856853000,"stream":"btcusdt@bookTicker","event_type":"bookTicker","event_time_ms":1788563055921,"raw_json":"{\"stream\":\"btcusdt@bookTicker\",\"data\":{\"e\":\"bookTicker\",\"u\":11478213497924,\"s\":\"BTCUSDT\",\"ps\":\"BTCUSDT\",\"b\":\"79598.10\",\"B\":\"10.409\",\"a\":\"79598.20\",\"A\":\"3.444\",\"T\":1788563055921,\"E\":1788563055921,\"st\":1}}"}
{"receive_ns":1788563055895351000,"stream":"btcusdt@bookTicker","event_type":"bookTicker","event_time_ms":1788563055958,"raw_json":"{\"stream\":\"btcusdt@bookTicker\",\"data\":{\"e\":\"bookTicker\",\"u\":11478213499802,\"s\":\"BTCUSDT\",\"ps\":\"BTCUSDT\",\"b\":\"79598.10\",\"B\":\"10.417\",\"a\":\"79598.20\",\"A\":\"3.444\",\"T\":1788563055958,\"E\":1788563055958,\"st\":1}}"}
{"receive_ns":1788563055895666000,"stream":"btcusdt@bookTicker","event_type":"bookTicker","event_time_ms":1788563055959,"raw_json":"{\"stream\":\"btcusdt@bookTicker\",\"data\":{\"e\":\"bookTicker\",\"u\":11478213499871,\"s\":\"BTCUSDT\",\"ps\":\"BTCUSDT\",\"b\":\"79598.10\",\"B\":\"10.409\",\"a\":\"79598.20\",\"A\":\"3.444\",\"T\":1788563055959,\"E\":1788563055959,\"st\":1}}"}
{"receive_ns":1788563055906790000,"stream":"btcusdt@depth@100ms","event_type":"depthUpdate","event_time_ms":1788563055965,"raw_json":"{\"stream\":\"btcusdt@depth@100ms\",\"data\":{\"e\":\"depthUpdate\",\"E\":1788563055965,\"T\":1788563055964,\"s\":\"BTCUSDT\",\"ps\":\"BTCUSDT\",\"U\":11478213494750,\"u\":11478213501247,\"pu\":11478213494561,\"b\":[[\"1000.00\",\"24.604\"],[\"29098.10\",\"1.771\"],[\"29198.10\",\"0.301\"],[\"29498.10\",\"0.028\"],[\"71638.20\",\"0.002\"],[\"76414.10\",\"0.002\"],[\"78802.10\",\"10.279\"],[\"79200.10\",\"3.717\"],[\"79401.10\",\"0.100\"],[\"79404.00\",\"1.014\"],[\"79492.60\",\"0.001\"],[\"79493.00\",\"0.032\"],[\"79576.20\",\"0.007\"],[\"79578.40\",\"0.407\"],[\"79598.10\",\"10.409\"]],\"a\":[[\"79602.20\",\"0.003\"],[\"79603.10\",\"0.000\"],[\"79757.30\",\"0.000\"],[\"79962.40\",\"0.854\"],[\"79996.20\",\"3.663\"],[\"80338.30\",\"0.663\"],[\"80394.20\",\"10.445\"],[\"80593.20\",\"2.763\"]],\"st\":1}}"}
{"receive_ns":1788563055989859000,"stream":"btcusdt@bookTicker","event_type":"bookTicker","event_time_ms":1788563056052,"raw_json":"{\"stream\":\"btcusdt@bookTicker\",\"data\":{\"e\":\"bookTicker\",\"u\":11478213507429,\"s\":\"BTCUSDT\",\"ps\":\"BTCUSDT\",\"b\":\"79598.10\",\"B\":\"10.417\",\"a\":\"79598.20\",\"A\":\"3.444\",\"T\":1788563056052,\"E\":1788563056052,\"st\":1}}"}
{"receive_ns":1788563055990255000,"stream":"btcusdt@bookTicker","event_type":"bookTicker","event_time_ms":1788563056053,"raw_json":"{\"stream\":\"btcusdt@bookTicker\",\"data\":{\"e\":\"bookTicker\",\"u\":11478213507529,\"s\":\"BTCUSDT\",\"ps\":\"BTCUSDT\",\"b\":\"79598.10\",\"B\":\"10.409\",\"a\":\"79598.20\",\"A\":\"3.444\",\"T\":1788563056053,\"E\":1788563056053,\"st\":1}}"}
{"receive_ns":1788563056003315000,"stream":"btcusdt@depth@100ms","event_type":"depthUpdate","event_time_ms":1788563056067,"raw_json":"{\"stream\":\"btcusdt@depth@100ms\",\"data\":{\"e\":\"depthUpdate\",\"E\":1788563056067,\"T\":1788563056066,\"s\":\"BTCUSDT\",\"ps\":\"BTCUSDT\",\"U\":11478213501466,\"u\":11478213508221,\"pu\":11478213501247,\"b\":[[\"29098.10\",\"1.841\"],[\"29198.10\",\"0.175\"],[\"29498.10\",\"0.084\"],[\"71638.20\",\"0.002\"],[\"76414.10\",\"0.000\"],[\"78006.20\",\"0.024\"],[\"78802.10\",\"10.279\"],[\"79200.10\",\"3.858\"],[\"79228.00\",\"0.245\"],[\"79401.10\",\"1.682\"],[\"79404.00\",\"1.215\"],[\"79418.10\",\"3.141\"],[\"79418.20\",\"0.000\"],[\"79462.70\",\"0.012\"],[\"79472.70\",\"1.547\"],[\"79492.60\",\"1.006\"],[\"79493.00\",\"0.078\"],[\"79494.60\",\"0.251\"],[\"79502.50\",\"0.001\"],[\"79511.40\",\"0.038\"],[\"79526.40\",\"0.001\"],[\"79572.40\",\"0.254\"],[\"79573.00\",\"0.440\"],[\"79573.30\",\"0.373\"],[\"79573.50\",\"0.000\"],[\"79574.40\",\"0.050\"],[\"79574.50\",\"0.003\"],[\"79574.90\",\"0.000\"],[\"79583.80\",\"0.000\"],[\"79598.10\",\"10.409\"]],\"a\":[[\"79598.90\",\"0.026\"],[\"79599.10\",\"0.002\"],[\"79603.10\",\"0.200\"],[\"79606.10\",\"0.252\"],[\"79608.10\",\"0.513\"],[\"79609.40\",\"0.315\"],[\"79609.50\",\"0.075\"],[\"79609.60\",\"0.258\"],[\"79610.20\",\"0.002\"],[\"79611.00\",\"1.130\"],[\"79611.40\",\"0.420\"],[\"79614.30\",\"0.361\"],[\"79638.00\",\"0.070\"],[\"79669.90\",\"0.000\"],[\"79686.60\",\"1.295\"],[\"79743.30\",\"3.152\"],[\"79743.70\",\"0.001\"],[\"79962.40\",\"1.273\"],[\"79994.20\",\"0.156\"],[\"79996.20\",\"4.189\"],[\"80394.20\",\"10.445\"]],\"st\":1}}"}
{"receive_ns":1788563056060830000,"stream":"btcusdt@bookTicker","event_type":"bookTicker","event_time_ms":1788563056125,"raw_json":"{\"stream\":\"btcusdt@bookTicker\",\"data\":{\"e\":\"bookTicker\",\"u\":11478213512905,\"s\":\"BTCUSDT\",\"ps\":\"BTCUSDT\",\"b\":\"79598.10\",\"B\":\"10.362\",\"a\":\"79598.20\",\"A\":\"3.444\",\"T\":1788563056125,\"E\":1788563056125,\"st\":1}}"}
{"receive_ns":1788563056061090000,"stream":"btcusdt@trade","event_type":"trade","event_time_ms":1788563056125,"raw_json":"{\"stream\":\"btcusdt@trade\",\"data\":{\"e\":\"trade\",\"E\":1788563056125,\"T\":1788563056125,\"s\":\"BTCUSDT\",\"t\":8054081732,\"p\":\"79598.10\",\"q\":\"0.047\",\"X\":\"MARKET\",\"m\":true,\"st\":1}}"}
{"receive_ns":1788563056061344000,"stream":"btcusdt@bookTicker","event_type":"bookTicker","event_time_ms":1788563056127,"raw_json":"{\"stream\":\"btcusdt@bookTicker\",\"data\":{\"e\":\"bookTicker\",\"u\":11478213513067,\"s\":\"BTCUSDT\",\"ps\":\"BTCUSDT\",\"b\":\"79598.10\",\"B\":\"10.370\",\"a\":\"79598.20\",\"A\":\"3.444\",\"T\":1788563056127,\"E\":1788563056127,\"st\":1}}"}
{"receive_ns":1788563056061668000,"stream":"btcusdt@bookTicker","event_type":"bookTicker","event_time_ms":1788563056127,"raw_json":"{\"stream\":\"btcusdt@bookTicker\",\"data\":{\"e\":\"bookTicker\",\"u\":11478213513124,\"s\":\"BTCUSDT\",\"ps\":\"BTCUSDT\",\"b\":\"79598.10\",\"B\":\"10.362\",\"a\":\"79598.20\",\"A\":\"3.444\",\"T\":1788563056127,\"E\":1788563056127,\"st\":1}}"}
{"receive_ns":1788563056069448000,"stream":"btcusdt@bookTicker","event_type":"bookTicker","event_time_ms":1788563056134,"raw_json":"{\"stream\":\"btcusdt@bookTicker\",\"data\":{\"e\":\"bookTicker\",\"u\":11478213513828,\"s\":\"BTCUSDT\",\"ps\":\"BTCUSDT\",\"b\":\"79598.10\",\"B\":\"10.370\",\"a\":\"79598.20\",\"A\":\"3.444\",\"T\":1788563056134,\"E\":1788563056134,\"st\":1}}"}
{"receive_ns":1788563056070356000,"stream":"btcusdt@bookTicker","event_type":"bookTicker","event_time_ms":1788563056134,"raw_json":"{\"stream\":\"btcusdt@bookTicker\",\"data\":{\"e\":\"bookTicker\",\"u\":11478213513876,\"s\":\"BTCUSDT\",\"ps\":\"BTCUSDT\",\"b\":\"79598.10\",\"B\":\"10.362\",\"a\":\"79598.20\",\"A\":\"3.444\",\"T\":1788563056134,\"E\":1788563056134,\"st\":1}}"}
{"receive_ns":1788563056096567000,"stream":"btcusdt@bookTicker","event_type":"bookTicker","event_time_ms":1788563056160,"raw_json":"{\"stream\":\"btcusdt@bookTicker\",\"data\":{\"e\":\"bookTicker\",\"u\":11478213515687,\"s\":\"BTCUSDT\",\"ps\":\"BTCUSDT\",\"b\":\"79598.10\",\"B\":\"10.370\",\"a\":\"79598.20\",\"A\":\"3.444\",\"T\":1788563056160,\"E\":1788563056160,\"st\":1}}"}
{"receive_ns":1788563056096816000,"stream":"btcusdt@bookTicker","event_type":"bookTicker","event_time_ms":1788563056161,"raw_json":"{\"stream\":\"btcusdt@bookTicker\",\"data\":{\"e\":\"bookTicker\",\"u\":11478213515751,\"s\":\"BTCUSDT\",\"ps\":\"BTCUSDT\",\"b\":\"79598.10\",\"B\":\"10.362\",\"a\":\"79598.20\",\"A\":\"3.444\",\"T\":1788563056160,\"E\":1788563056161,\"st\":1}}"}
{"receive_ns":1788563056097045000,"stream":"btcusdt@bookTicker","event_type":"bookTicker","event_time_ms":1788563056161,"raw_json":"{\"stream\":\"btcusdt@bookTicker\",\"data\":{\"e\":\"bookTicker\",\"u\":11478213515843,\"s\":\"BTCUSDT\",\"ps\":\"BTCUSDT\",\"b\":\"79598.10\",\"B\":\"10.367\",\"a\":\"79598.20\",\"A\":\"3.444\",\"T\":1788563056161,\"E\":1788563056161,\"st\":1}}"}
{"receive_ns":1788563056104903000,"stream":"btcusdt@depth@100ms","event_type":"depthUpdate","event_time_ms":1788563056169,"raw_json":"{\"stream\":\"btcusdt@depth@100ms\",\"data\":{\"e\":\"depthUpdate\",\"E\":1788563056169,\"T\":1788563056166,\"s\":\"BTCUSDT\",\"ps\":\"BTCUSDT\",\"U\":11478213508279,\"u\":11478213516124,\"pu\":11478213508221,\"b\":[[\"1000.00\",\"24.604\"],[\"29098.10\",\"1.890\"],[\"29198.10\",\"0.063\"],[\"29498.10\",\"0.147\"],[\"71638.20\",\"0.002\"],[\"75618.30\",\"0.002\"],[\"76414.10\",\"0.002\"],[\"78467.80\",\"0.306\"],[\"78477.90\",\"3.433\"],[\"78638.50\",\"20.271\"],[\"78802.10\",\"10.279\"],[\"79200.10\",\"3.858\"],[\"79460.70\",\"0.135\"],[\"79463.30\",\"0.001\"],[\"79463.40\",\"0.003\"],[\"79566.30\",\"0.015\"],[\"79570.10\",\"10.000\"],[\"79572.80\",\"0.004\"],[\"79578.80\",\"0.288\"],[\"79582.20\",\"0.287\"],[\"79597.20\",\"0.028\"],[\"79597.70\",\"0.000\"],[\"79597.80\",\"0.001\"],[\"79598.00\",\"0.035\"],[\"79598.10\",\"10.367\"]],\"a\":[[\"79598.30\",\"0.105\"],[\"79598.90\",\"0.000\"],[\"79599.50\",\"0.002\"],[\"79600.20\",\"0.027\"],[\"79603.10\",\"0.000\"],[\"79608.10\",\"0.262\"],[\"79609.40\",\"0.006\"],[\"79609.50\",\"0.322\"],[\"79610.20\",\"0.064\"],[\"79637.70\",\"2.006\"],[\"79640.10\",\"2.013\"],[\"79642.40\",\"2.948\"],[\"79757.20\",\"0.001\"],[\"79821.40\",\"0.000\"],[\"79821.50\",\"0.004\"],[\"80354.40\",\"5.897\"],[\"80394.20\",\"10.445\"]],\"st\":1}}"}
{"receive_ns":1788563056110094000,"stream":"btcusdt@bookTicker","event_type":"bookTicker","event_time_ms":1788563056173,"raw_json":"{\"stream\":\"btcusdt@bookTicker\",\"data\":{\"e\":\"bookTicker\",\"u\":11478213516655,\"s\":\"BTCUSDT\",\"ps\":\"BTCUSDT\",\"b\":\"79598.10\",\"B\":\"10.375\",\"a\":\"79598.20\",\"A\":\"3.444\",\"T\":1788563056173,\"E\":1788563056173,\"st\":1}}"}
{"receive_ns":1788563056110314000,"stream":"btcusdt@bookTicker","event_type":"bookTicker","event_time_ms":1788563056174,"raw_json":"{\"stream\":\"btcusdt@bookTicker\",\"data\":{\"e\":\"bookTicker\",\"u\":11478213516845,\"s\":\"BTCUSDT\",\"ps\":\"BTCUSDT\",\"b\":\"79598.10\",\"B\":\"10.383\",\"a\":\"79598.20\",\"A\":\"3.444\",\"T\":1788563056174,\"E\":1788563056174,\"st\":1}}"}
{"receive_ns":1788563056110488000,"stream":"btcusdt@bookTicker","event_type":"bookTicker","event_time_ms":1788563056174,"raw_json":"{\"stream\":\"btcusdt@bookTicker\",\"data\":{\"e\":\"bookTicker\",\"u\":11478213516958,\"s\":\"BTCUSDT\",\"ps\":\"BTCUSDT\",\"b\":\"79598.10\",\"B\":\"10.375\",\"a\":\"79598.20\",\"A\":\"3.444\",\"T\":1788563056174,\"E\":1788563056174,\"st\":1}}"}
{"receive_ns":1788563056110654000,"stream":"btcusdt@bookTicker","event_type":"bookTicker","event_time_ms":1788563056175,"raw_json":"{\"stream\":\"btcusdt@bookTicker\",\"data\":{\"e\":\"bookTicker\",\"u\":11478213517078,\"s\":\"BTCUSDT\",\"ps\":\"BTCUSDT\",\"b\":\"79598.10\",\"B\":\"10.367\",\"a\":\"79598.20\",\"A\":\"3.444\",\"T\":1788563056175,\"E\":1788563056175,\"st\":1}}"}
{"receive_ns":1788563056110798000,"stream":"btcusdt@bookTicker","event_type":"bookTicker","event_time_ms":1788563056175,"raw_json":"{\"stream\":\"btcusdt@bookTicker\",\"data\":{\"e\":\"bookTicker\",\"u\":11478213517079,\"s\":\"BTCUSDT\",\"ps\":\"BTCUSDT\",\"b\":\"79598.10\",\"B\":\"10.375\",\"a\":\"79598.20\",\"A\":\"3.444\",\"T\":1788563056175,\"E\":1788563056175,\"st\":1}}"}
{"receive_ns":1788563056110962000,"stream":"btcusdt@bookTicker","event_type":"bookTicker","event_time_ms":1788563056176,"raw_json":"{\"stream\":\"btcusdt@bookTicker\",\"data\":{\"e\":\"bookTicker\",\"u\":11478213517459,\"s\":\"BTCUSDT\",\"ps\":\"BTCUSDT\",\"b\":\"79598.10\",\"B\":\"10.367\",\"a\":\"79598.20\",\"A\":\"3.444\",\"T\":1788563056175,\"E\":1788563056176,\"st\":1}}"}
{"receive_ns":1788563056111176000,"stream":"btcusdt@bookTicker","event_type":"bookTicker","event_time_ms":1788563056177,"raw_json":"{\"stream\":\"btcusdt@bookTicker\",\"data\":{\"e\":\"bookTicker\",\"u\":11478213518271,\"s\":\"BTCUSDT\",\"ps\":\"BTCUSDT\",\"b\":\"79598.10\",\"B\":\"10.375\",\"a\":\"79598.20\",\"A\":\"3.444\",\"T\":1788563056177,\"E\":1788563056177,\"st\":1}}"}
{"receive_ns":1788563056114582000,"stream":"btcusdt@bookTicker","event_type":"bookTicker","event_time_ms":1788563056178,"raw_json":"{\"stream\":\"btcusdt@bookTicker\",\"data\":{\"e\":\"bookTicker\",\"u\":11478213519241,\"s\":\"BTCUSDT\",\"ps\":\"BTCUSDT\",\"b\":\"79598.10\",\"B\":\"10.367\",\"a\":\"79598.20\",\"A\":\"3.444\",\"T\":1788563056178,\"E\":1788563056178,\"st\":1}}"}
{"receive_ns":1788563056114749000,"stream":"btcusdt@bookTicker","event_type":"bookTicker","event_time_ms":1788563056178,"raw_json":"{\"stream\":\"btcusdt@bookTicker\",\"data\":{\"e\":\"bookTicker\",\"u\":11478213519379,\"s\":\"BTCUSDT\",\"ps\":\"BTCUSDT\",\"b\":\"79598.10\",\"B\":\"10.375\",\"a\":\"79598.20\",\"A\":\"3.444\",\"T\":1788563056178,\"E\":1788563056178,\"st\":1}}"}
{"receive_ns":1788563056122139000,"stream":"btcusdt@bookTicker","event_type":"bookTicker","event_time_ms":1788563056179,"raw_json":"{\"stream\":\"btcusdt@bookTicker\",\"data\":{\"e\":\"bookTicker\",\"u\":11478213520056,\"s\":\"BTCUSDT\",\"ps\":\"BTCUSDT\",\"b\":\"79598.10\",\"B\":\"10.383\",\"a\":\"79598.20\",\"A\":\"3.444\",\"T\":1788563056179,\"E\":1788563056179,\"st\":1}}"}
{"receive_ns":1788563056122374000,"stream":"btcusdt@bookTicker","event_type":"bookTicker","event_time_ms":1788563056180,"raw_json":"{\"stream\":\"btcusdt@bookTicker\",\"data\":{\"e\":\"bookTicker\",\"u\":11478213520577,\"s\":\"BTCUSDT\",\"ps\":\"BTCUSDT\",\"b\":\"79598.10\",\"B\":\"10.383\",\"a\":\"79598.20\",\"A\":\"3.080\",\"T\":1788563056179,\"E\":1788563056180,\"st\":1}}"}
{"receive_ns":1788563056122584000,"stream":"btcusdt@bookTicker","event_type":"bookTicker","event_time_ms":1788563056180,"raw_json":"{\"stream\":\"btcusdt@bookTicker\",\"data\":{\"e\":\"bookTicker\",\"u\":11478213520874,\"s\":\"BTCUSDT\",\"ps\":\"BTCUSDT\",\"b\":\"79598.10\",\"B\":\"10.375\",\"a\":\"79598.20\",\"A\":\"3.080\",\"T\":1788563056180,\"E\":1788563056180,\"st\":1}}"}
{"receive_ns":1788563056124852000,"stream":"btcusdt@bookTicker","event_type":"bookTicker","event_time_ms":1788563056181,"raw_json":"{\"stream\":\"btcusdt@bookTicker\",\"data\":{\"e\":\"bookTicker\",\"u\":11478213521573,\"s\":\"BTCUSDT\",\"ps\":\"BTCUSDT\",\"b\":\"79598.10\",\"B\":\"10.367\",\"a\":\"79598.20\",\"A\":\"3.080\",\"T\":1788563056181,\"E\":1788563056181,\"st\":1}}"}
{"receive_ns":1788563056125039000,"stream":"btcusdt@bookTicker","event_type":"bookTicker","event_time_ms":1788563056181,"raw_json":"{\"stream\":\"btcusdt@bookTicker\",\"data\":{\"e\":\"bookTicker\",\"u\":11478213521778,\"s\":\"BTCUSDT\",\"ps\":\"BTCUSDT\",\"b\":\"79598.10\",\"B\":\"10.375\",\"a\":\"79598.20\",\"A\":\"3.080\",\"T\":1788563056181,\"E\":1788563056181,\"st\":1}}"}
{"receive_ns":1788563056125213000,"stream":"btcusdt@bookTicker","event_type":"bookTicker","event_time_ms":1788563056182,"raw_json":"{\"stream\":\"btcusdt@bookTicker\",\"data\":{\"e\":\"bookTicker\",\"u\":11478213522395,\"s\":\"BTCUSDT\",\"ps\":\"BTCUSDT\",\"b\":\"79598.10\",\"B\":\"10.383\",\"a\":\"79598.20\",\"A\":\"3.080\",\"T\":1788563056181,\"E\":1788563056182,\"st\":1}}"}
{"receive_ns":1788563056125389000,"stream":"btcusdt@bookTicker","event_type":"bookTicker","event_time_ms":1788563056182,"raw_json":"{\"stream\":\"btcusdt@bookTicker\",\"data\":{\"e\":\"bookTicker\",\"u\":11478213523159,\"s\":\"BTCUSDT\",\"ps\":\"BTCUSDT\",\"b\":\"79598.10\",\"B\":\"10.383\",\"a\":\"79598.20\",\"A\":\"3.041\",\"T\":1788563056182,\"E\":1788563056182,\"st\":1}}"}
{"receive_ns":1788563056125589000,"stream":"btcusdt@bookTicker","event_type":"bookTicker","event_time_ms":1788563056183,"raw_json":"{\"stream\":\"btcusdt@bookTicker\",\"data\":{\"e\":\"bookTicker\",\"u\":11478213523343,\"s\":\"BTCUSDT\",\"ps\":\"BTCUSDT\",\"b\":\"79598.10\",\"B\":\"10.391\",\"a\":\"79598.20\",\"A\":\"3.041\",\"T\":1788563056182,\"E\":1788563056183,\"st\":1}}"}
{"receive_ns":1788563056126008000,"stream":"btcusdt@bookTicker","event_type":"bookTicker","event_time_ms":1788563056183,"raw_json":"{\"stream\":\"btcusdt@bookTicker\",\"data\":{\"e\":\"bookTicker\",\"u\":11478213523500,\"s\":\"BTCUSDT\",\"ps\":\"BTCUSDT\",\"b\":\"79598.10\",\"B\":\"10.391\",\"a\":\"79598.20\",\"A\":\"3.040\",\"T\":1788563056183,\"E\":1788563056183,\"st\":1}}"}
{"receive_ns":1788563056126185000,"stream":"btcusdt@bookTicker","event_type":"bookTicker","event_time_ms":1788563056183,"raw_json":"{\"stream\":\"btcusdt@bookTicker\",\"data\":{\"e\":\"bookTicker\",\"u\":11478213523519,\"s\":\"BTCUSDT\",\"ps\":\"BTCUSDT\",\"b\":\"79598.10\",\"B\":\"10.383\",\"a\":\"79598.20\",\"A\":\"3.040\",\"T\":1788563056183,\"E\":1788563056183,\"st\":1}}"}
{"receive_ns":1788563056126386000,"stream":"btcusdt@bookTicker","event_type":"bookTicker","event_time_ms":1788563056184,"raw_json":"{\"stream\":\"btcusdt@bookTicker\",\"data\":{\"e\":\"bookTicker\",\"u\":11478213524521,\"s\":\"BTCUSDT\",\"ps\":\"BTCUSDT\",\"b\":\"79598.10\",\"B\":\"10.383\",\"a\":\"79598.20\",\"A\":\"2.670\",\"T\":1788563056184,\"E\":1788563056184,\"st\":1}}"}
{"receive_ns":1788563056130125000,"stream":"btcusdt@bookTicker","event_type":"bookTicker","event_time_ms":1788563056184,"raw_json":"{\"stream\":\"btcusdt@bookTicker\",\"data\":{\"e\":\"bookTicker\",\"u\":11478213524862,\"s\":\"BTCUSDT\",\"ps\":\"BTCUSDT\",\"b\":\"79598.10\",\"B\":\"10.310\",\"a\":\"79598.20\",\"A\":\"2.670\",\"T\":1788563056184,\"E\":1788563056184,\"st\":1}}"}
{"receive_ns":1788563056130323000,"stream":"btcusdt@bookTicker","event_type":"bookTicker","event_time_ms":1788563056184,"raw_json":"{\"stream\":\"btcusdt@bookTicker\",\"data\":{\"e\":\"bookTicker\",\"u\":11478213525002,\"s\":\"BTCUSDT\",\"ps\":\"BTCUSDT\",\"b\":\"79598.10\",\"B\":\"10.302\",\"a\":\"79598.20\",\"A\":\"2.670\",\"T\":1788563056184,\"E\":1788563056184,\"st\":1}}"}
{"receive_ns":1788563056130475000,"stream":"btcusdt@bookTicker","event_type":"bookTicker","event_time_ms":1788563056184,"raw_json":"{\"stream\":\"btcusdt@bookTicker\",\"data\":{\"e\":\"bookTicker\",\"u\":11478213525005,\"s\":\"BTCUSDT\",\"ps\":\"BTCUSDT\",\"b\":\"79598.10\",\"B\":\"10.294\",\"a\":\"79598.20\",\"A\":\"2.670\",\"T\":1788563056184,\"E\":1788563056184,\"st\":1}}"}
{"receive_ns":1788563056130645000,"stream":"btcusdt@bookTicker","event_type":"bookTicker","event_time_ms":1788563056185,"raw_json":"{\"stream\":\"btcusdt@bookTicker\",\"data\":{\"e\":\"bookTicker\",\"u\":11478213525695,\"s\":\"BTCUSDT\",\"ps\":\"BTCUSDT\",\"b\":\"79598.10\",\"B\":\"10.302\",\"a\":\"79598.20\",\"A\":\"2.670\",\"T\":1788563056185,\"E\":1788563056185,\"st\":1}}"}
{"receive_ns":1788563056130821000,"stream":"btcusdt@bookTicker","event_type":"bookTicker","event_time_ms":1788563056186,"raw_json":"{\"stream\":\"btcusdt@bookTicker\",\"data\":{\"e\":\"bookTicker\",\"u\":11478213526232,\"s\":\"BTCUSDT\",\"ps\":\"BTCUSDT\",\"b\":\"79598.10\",\"B\":\"10.310\",\"a\":\"79598.20\",\"A\":\"2.670\",\"T\":1788563056185,\"E\":1788563056186,\"st\":1}}"}
{"receive_ns":1788563056130983000,"stream":"btcusdt@bookTicker","event_type":"bookTicker","event_time_ms":1788563056186,"raw_json":"{\"stream\":\"btcusdt@bookTicker\",\"data\":{\"e\":\"bookTicker\",\"u\":11478213526678,\"s\":\"BTCUSDT\",\"ps\":\"BTCUSDT\",\"b\":\"79598.10\",\"B\":\"10.302\",\"a\":\"79598.20\",\"A\":\"2.670\",\"T\":1788563056186,\"E\":1788563056186,\"st\":1}}"}
{"receive_ns":1788563056131189000,"stream":"btcusdt@bookTicker","event_type":"bookTicker","event_time_ms":1788563056187,"raw_json":"{\"stream\":\"btcusdt@bookTicker\",\"data\":{\"e\":\"bookTicker\",\"u\":11478213527528,\"s\":\"BTCUSDT\",\"ps\":\"BTCUSDT\",\"b\":\"79598.10\",\"B\":\"10.310\",\"a\":\"79598.20\",\"A\":\"2.670\",\"T\":1788563056187,\"E\":1788563056187,\"st\":1}}"}
{"receive_ns":1788563056131375000,"stream":"btcusdt@bookTicker","event_type":"bookTicker","event_time_ms":1788563056188,"raw_json":"{\"stream\":\"btcusdt@bookTicker\",\"data\":{\"e\":\"bookTicker\",\"u\":11478213527656,\"s\":\"BTCUSDT\",\"ps\":\"BTCUSDT\",\"b\":\"79598.10\",\"B\":\"10.302\",\"a\":\"79598.20\",\"A\":\"2.670\",\"T\":1788563056187,\"E\":1788563056188,\"st\":1}}"}
{"receive_ns":1788563056131555000,"stream":"btcusdt@bookTicker","event_type":"bookTicker","event_time_ms":1788563056188,"raw_json":"{\"stream\":\"btcusdt@bookTicker\",\"data\":{\"e\":\"bookTicker\",\"u\":11478213527738,\"s\":\"BTCUSDT\",\"ps\":\"BTCUSDT\",\"b\":\"79598.10\",\"B\":\"10.310\",\"a\":\"79598.20\",\"A\":\"2.670\",\"T\":1788563056188,\"E\":1788563056188,\"st\":1}}"}
{"receive_ns":1788563056131727000,"stream":"btcusdt@bookTicker","event_type":"bookTicker","event_time_ms":1788563056188,"raw_json":"{\"stream\":\"btcusdt@bookTicker\",\"data\":{\"e\":\"bookTicker\",\"u\":11478213527906,\"s\":\"BTCUSDT\",\"ps\":\"BTCUSDT\",\"b\":\"79598.10\",\"B\":\"10.302\",\"a\":\"79598.20\",\"A\":\"2.670\",\"T\":1788563056188,\"E\":1788563056188,\"st\":1}}"}
{"receive_ns":1788563056131894000,"stream":"btcusdt@bookTicker","event_type":"bookTicker","event_time_ms":1788563056189,"raw_json":"{\"stream\":\"btcusdt@bookTicker\",\"data\":{\"e\":\"bookTicker\",\"u\":11478213528229,\"s\":\"BTCUSDT\",\"ps\":\"BTCUSDT\",\"b\":\"79598.10\",\"B\":\"10.294\",\"a\":\"79598.20\",\"A\":\"2.670\",\"T\":1788563056188,\"E\":1788563056189,\"st\":1}}"}
{"receive_ns":1788563056132099000,"stream":"btcusdt@bookTicker","event_type":"bookTicker","event_time_ms":1788563056190,"raw_json":"{\"stream\":\"btcusdt@bookTicker\",\"data\":{\"e\":\"bookTicker\",\"u\":11478213528568,\"s\":\"BTCUSDT\",\"ps\":\"BTCUSDT\",\"b\":\"79598.10\",\"B\":\"10.368\",\"a\":\"79598.20\",\"A\":\"2.670\",\"T\":1788563056189,\"E\":1788563056190,\"st\":1}}"}
{"receive_ns":1788563056190116000,"stream":"btcusdt@bookTicker","event_type":"bookTicker","event_time_ms":1788563056254,"raw_json":"{\"stream\":\"btcusdt@bookTicker\",\"data\":{\"e\":\"bookTicker\",\"u\":11478213541526,\"s\":\"BTCUSDT\",\"ps\":\"BTCUSDT\",\"b\":\"79598.10\",\"B\":\"10.368\",\"a\":\"79598.20\",\"A\":\"2.671\",\"T\":1788563056254,\"E\":1788563056254,\"st\":1}}"}
{"receive_ns":1788563056209564000,"stream":"btcusdt@depth@100ms","event_type":"depthUpdate","event_time_ms":1788563056271,"raw_json":"{\"stream\":\"btcusdt@depth@100ms\",\"data\":{\"e\":\"depthUpdate\",\"E\":1788563056271,\"T\":1788563056270,\"s\":\"BTCUSDT\",\"ps\":\"BTCUSDT\",\"U\":11478213516344,\"u\":11478213543633,\"pu\":11478213516124,\"b\":[[\"1000.00\",\"24.604\"],[\"29098.10\",\"1.834\"],[\"29198.10\",\"0.000\"],[\"29498.10\",\"0.266\"],[\"63678.00\",\"0.008\"],[\"71638.20\",\"0.002\"],[\"75599.80\",\"0.005\"],[\"78006.20\",\"0.021\"],[\"78802.10\",\"10.279\"],[\"79200.10\",\"3.857\"],[\"79228.00\",\"0.013\"],[\"79308.70\",\"0.005\"],[\"79401.10\",\"0.000\"],[\"79404.00\",\"1.014\"],[\"79472.70\",\"3.054\"],[\"79473.60\",\"0.209\"],[\"79478.80\",\"0.252\"],[\"79479.50\",\"0.618\"],[\"79492.60\",\"0.001\"],[\"79494.60\",\"0.000\"],[\"79496.20\",\"0.096\"],[\"79501.90\",\"3.736\"],[\"79515.30\",\"0.001\"],[\"79523.30\",\"0.001\"],[\"79531.80\",\"0.776\"],[\"79534.30\",\"0.000\"],[\"79539.00\",\"0.005\"],[\"79545.30\",\"0.288\"],[\"79551.80\",\"0.516\"],[\"79560.30\",\"0.103\"],[\"79563.60\",\"0.071\"],[\"79564.20\",\"0.684\"],[\"79570.00\",\"0.004\"],[\"79573.60\",\"0.049\"],[\"79573.70\",\"0.024\"],[\"79576.10\",\"0.038\"],[\"79576.80\",\"2.393\"],[\"79576.90\",\"4.300\"],[\"79577.80\",\"0.638\"],[\"79580.30\",\"0.017\"],[\"79580.70\",\"0.000\"],[\"79581.10\",\"0.001\"],[\"79581.40\",\"0.001\"],[\"79581.70\",\"0.631\"],[\"79582.10\",\"0.324\"],[\"79582.30\",\"0.010\"],[\"79582.80\",\"0.003\"],[\"79582.90\",\"0.000\"],[\"79584.10\",\"0.081\"],[\"79585.30\",\"0.086\"],[\"79586.10\",\"0.004\"],[\"79586.80\",\"0.002\"],[\"79587.50\",\"0.000\"],[\"79588.10\",\"0.146\"],[\"79588.50\",\"0.120\"],[\"79589.10\",\"0.001\"],[\"79591.80\",\"0.007\"],[\"79594.10\",\"0.528\"],[\"79596.40\",\"0.149\"],[\"79596.70\",\"0.000\"],[\"79596.90\",\"0.269\"],[\"79597.60\",\"0.202\"],[\"79597.70\",\"0.076\"],[\"79598.10\",\"10.368\"]],\"a\":[[\"79598.20\",\"2.671\"],[\"79598.40\",\"0.100\"],[\"79599.80\",\"0.000\"],[\"79600.00\",\"0.051\"],[\"79600.20\",\"0.001\"],[\"79600.40\",\"0.292\"],[\"79600.50\",\"0.000\"],[\"79600.70\",\"0.002\"],[\"79600.90\",\"0.004\"],[\"79601.00\",\"0.008\"],[\"79601.10\",\"0.003\"],[\"79601.30\",\"0.000\"],[\"79601.40\",\"0.000\"],[\"79601.50\",\"0.003\"],[\"79601.70\",\"0.001\"],[\"79601.80\",\"0.001\"],[\"79601.90\",\"0.000\"],[\"79602.00\",\"0.001\"],[\"79602.10\",\"0.002\"],[\"79602.20\",\"0.003\"],[\"79602.40\",\"0.001\"],[\"79602.50\",\"0.000\"],[\"79602.60\",\"0.000\"],[\"79602.70\",\"0.003\"],[\"79602.80\",\"0.000\"],[\"79602.90\",\"0.001\"],[\"79603.10\",\"0.000\"],[\"79603.20\",\"0.002\"],[\"79603.30\",\"0.000\"],[\"79603.40\",\"0.002\"],[\"79603.50\",\"0.000\"],[\"79603.60\",\"0.001\"],[\"79603.70\",\"0.003\"],[\"79603.90\",\"0.050\"],[\"79604.00\",\"1.072\"],[\"79604.10\",\"2.402\"],[\"79604.20\",\"0.002\"],[\"79604.30\",\"0.005\"],[\"79604.40\",\"0.002\"],[\"79604.70\",\"0.026\"],[\"79604.80\",\"0.003\"],[\"79604.90\",\"0.460\"],[\"79605.00\",\"0.029\"],[\"79605.10\",\"0.002\"],[\"79605.20\",\"0.077\"],[\"79605.30\",\"0.000\"],[\"79605.40\",\"0.000\"],[\"79605.50\",\"0.026\"],[\"79605.60\",\"0.027\"],[\"79605.70\",\"0.036\"],[\"79605.80\",\"0.026\"],[\"79606.00\",\"0.001\"],[\"79606.10\",\"0.001\"],[\"79606.20\",\"1.310\"],[\"79606.30\",\"0.368\"],[\"79606.50\",\"0.007\"],[\"79606.70\",\"0.028\"],[\"79606.80\",\"0.001\"],[\"79606.90\",\"0.003\"],[\"79607.00\",\"0.000\"],[\"79607.10\",\"0.000\"],[\"79607.20\",\"0.003\"],[\"79607.30\",\"0.000\"],[\"79607.50\",\"0.003\"],[\"79607.70\",\"0.000\"],[\"79608.30\",\"0.009\"],[\"79608.40\",\"0.536\"],[\"79609.50\",\"0.009\"],[\"79609.60\",\"0.697\"],[\"79609.80\",\"0.002\"],[\"79610.20\",\"0.064\"],[\"79610.60\",\"0.654\"],[\"79611.00\",\"0.691\"],[\"79611.60\",\"0.001\"],[\"79612.60\",\"0.512\"],[\"79613.30\",\"0.623\"],[\"79614.60\",\"0.001\"],[\"79615.40\",\"0.004\"],[\"79615.70\",\"0.630\"],[\"79615.90\",\"0.112\"],[\"79619.40\",\"2.842\"],[\"79620.30\",\"0.001\"],[\"79620.40\",\"0.125\"],[\"79621.10\",\"0.109\"],[\"79621.60\",\"0.627\"],[\"79624.00\",\"0.025\"],[\"79625.50\",\"0.022\"],[\"79625.90\",\"0.788\"],[\"79627.30\",\"0.378\"],[\"79627.60\",\"0.001\"],[\"79628.60\",\"0.002\"],[\"79628.80\",\"0.335\"],[\"79628.90\",\"0.000\"],[\"79629.30\",\"0.021\"],[\"79629.60\",\"0.628\"],[\"79629.70\",\"0.006\"],[\"79629.90\",\"3.044\"],[\"79630.10\",\"0.001\"],[\"79631.40\",\"0.227\"],[\"79635.40\",\"0.052\"],[\"79635.90\",\"0.613\"],[\"79636.40\",\"1.660\"],[\"79637.00\",\"0.248\"],[\"79637.70\",\"0.006\"],[\"79638.00\",\"0.070\"],[\"79644.50\",\"0.002\"],[\"79644.90\",\"0.073\"],[\"79645.90\",\"0.070\"],[\"79646.00\",\"0.032\"],[\"79646.40\",\"0.454\"],[\"79648.40\",\"10.002\"],[\"79648.50\",\"1.063\"],[\"79661.20\",\"0.060\"],[\"79661.80\",\"0.021\"],[\"79662.70\",\"0.021\"],[\"79665.20\",\"0.000\"],[\"79666.00\",\"0.038\"],[\"79666.10\",\"0.002\"],[\"79668.80\",\"23.577\"],[\"79670.00\",\"0.001\"],[\"79675.80\",\"0.001\"],[\"79676.00\",\"0.016\"],[\"79678.50\",\"0.210\"],[\"79685.20\",\"0.000\"],[\"79685.30\",\"0.214\"],[\"79699.40\",\"0.165\"],[\"79699.50\",\"0.022\"],[\"79735.50\",\"0.275\"],[\"79736.40\",\"0.211\"],[\"79757.20\",\"0.001\"],[\"79962.40\",\"0.419\"],[\"79994.20\",\"0.000\"],[\"79996.20\",\"4.146\"],[\"80394.20\",\"10.445\"],[\"81190.10\",\"0.014\"]],\"st\":1}}"}
{"receive_ns":1788563056221042000,"stream":"btcusdt@bookTicker","event_type":"bookTicker","event_time_ms":1788563056285,"raw_json":"{\"stream\":\"btcusdt@bookTicker\",\"data\":{\"e\":\"bookTicker\",\"u\":11478213546016,\"s\":\"BTCUSDT\",\"ps\":\"BTCUSDT\",\"b\":\"79598.10\",\"B\":\"10.384\",\"a\":\"79598.20\",\"A\":\"2.671\",\"T\":1788563056285,\"E\":1788563056285,\"st\":1}}"}
{"receive_ns":1788563056224147000,"stream":"btcusdt@bookTicker","event_type":"bookTicker","event_time_ms":1788563056286,"raw_json":"{\"stream\":\"btcusdt@bookTicker\",\"data\":{\"e\":\"bookTicker\",\"u\":11478213546110,\"s\":\"BTCUSDT\",\"ps\":\"BTCUSDT\",\"b\":\"79598.10\",\"B\":\"10.268\",\"a\":\"79598.20\",\"A\":\"2.671\",\"T\":1788563056285,\"E\":1788563056286,\"st\":1}}"}
{"receive_ns":1788563056256041000,"stream":"btcusdt@bookTicker","event_type":"bookTicker","event_time_ms":1788563056288,"raw_json":"{\"stream\":\"btcusdt@bookTicker\",\"data\":{\"e\":\"bookTicker\",\"u\":11478213546523,\"s\":\"BTCUSDT\",\"ps\":\"BTCUSDT\",\"b\":\"79598.10\",\"B\":\"10.392\",\"a\":\"79598.20\",\"A\":\"2.671\",\"T\":1788563056288,\"E\":1788563056288,\"st\":1}}"}
{"receive_ns":1788563056256674000,"stream":"btcusdt@bookTicker","event_type":"bookTicker","event_time_ms":1788563056293,"raw_json":"{\"stream\":\"btcusdt@bookTicker\",\"data\":{\"e\":\"bookTicker\",\"u\":11478213546923,\"s\":\"BTCUSDT\",\"ps\":\"BTCUSDT\",\"b\":\"79598.10\",\"B\":\"10.388\",\"a\":\"79598.20\",\"A\":\"2.671\",\"T\":1788563056293,\"E\":1788563056293,\"st\":1}}"}
{"receive_ns":1788563056257425000,"stream":"btcusdt@bookTicker","event_type":"bookTicker","event_time_ms":1788563056296,"raw_json":"{\"stream\":\"btcusdt@bookTicker\",\"data\":{\"e\":\"bookTicker\",\"u\":11478213547329,\"s\":\"BTCUSDT\",\"ps\":\"BTCUSDT\",\"b\":\"79598.10\",\"B\":\"10.393\",\"a\":\"79598.20\",\"A\":\"2.671\",\"T\":1788563056295,\"E\":1788563056296,\"st\":1}}"}
{"receive_ns":1788563056257767000,"stream":"btcusdt@bookTicker","event_type":"bookTicker","event_time_ms":1788563056300,"raw_json":"{\"stream\":\"btcusdt@bookTicker\",\"data\":{\"e\":\"bookTicker\",\"u\":11478213547876,\"s\":\"BTCUSDT\",\"ps\":\"BTCUSDT\",\"b\":\"79598.10\",\"B\":\"10.401\",\"a\":\"79598.20\",\"A\":\"2.671\",\"T\":1788563056300,\"E\":1788563056300,\"st\":1}}"}
{"receive_ns":1788563056258153000,"stream":"btcusdt@bookTicker","event_type":"bookTicker","event_time_ms":1788563056301,"raw_json":"{\"stream\":\"btcusdt@bookTicker\",\"data\":{\"e\":\"bookTicker\",\"u\":11478213548027,\"s\":\"BTCUSDT\",\"ps\":\"BTCUSDT\",\"b\":\"79598.10\",\"B\":\"10.393\",\"a\":\"79598.20\",\"A\":\"2.671\",\"T\":1788563056301,\"E\":1788563056301,\"st\":1}}"}
{"receive_ns":1788563056258435000,"stream":"btcusdt@bookTicker","event_type":"bookTicker","event_time_ms":1788563056312,"raw_json":"{\"stream\":\"btcusdt@bookTicker\",\"data\":{\"e\":\"bookTicker\",\"u\":11478213550013,\"s\":\"BTCUSDT\",\"ps\":\"BTCUSDT\",\"b\":\"79598.10\",\"B\":\"10.393\",\"a\":\"79598.20\",\"A\":\"2.673\",\"T\":1788563056312,\"E\":1788563056312,\"st\":1}}"}
