{"receive_ns":1788563197725391000,"stream":"btcusdt@bookTicker","event_type":"bookTicker","event_time_ms":1788563197760,"raw_json":"{\"stream\":\"btcusdt@bookTicker\",\"data\":{\"e\":\"bookTicker\",\"u\":11478222768818,\"s\":\"BTCUSDT\",\"ps\":\"BTCUSDT\",\"b\":\"79607.10\",\"B\":\"10.396\",\"a\":\"79607.20\",\"A\":\"1.062\",\"T\":1788563197759,\"E\":1788563197760,\"st\":1}}"}
{"receive_ns":1788563197725648000,"stream":"btcusdt@bookTicker","event_type":"bookTicker","event_time_ms":1788563197760,"raw_json":"{\"stream\":\"btcusdt@bookTicker\",\"data\":{\"e\":\"bookTicker\",\"u\":11478222768870,\"s\":\"BTCUSDT\",\"ps\":\"BTCUSDT\",\"b\":\"79607.10\",\"B\":\"10.388\",\"a\":\"79607.20\",\"A\":\"1.062\",\"T\":1788563197760,\"E\":1788563197760,\"st\":1}}"}
{"receive_ns":1788563197725847000,"stream":"btcusdt@bookTicker","event_type":"bookTicker","event_time_ms":1788563197760,"raw_json":"{\"stream\":\"btcusdt@bookTicker\",\"data\":{\"e\":\"bookTicker\",\"u\":11478222768873,\"s\":\"BTCUSDT\",\"ps\":\"BTCUSDT\",\"b\":\"79607.10\",\"B\":\"10.369\",\"a\":\"79607.20\",\"A\":\"1.062\",\"T\":1788563197760,\"E\":1788563197760,\"st\":1}}"}
{"receive_ns":1788563197726035000,"stream":"btcusdt@bookTicker","event_type":"bookTicker","event_time_ms":1788563197761,"raw_json":"{\"stream\":\"btcusdt@bookTicker\",\"data\":{\"e\":\"bookTicker\",\"u\":11478222768896,\"s\":\"BTCUSDT\",\"ps\":\"BTCUSDT\",\"b\":\"79607.10\",\"B\":\"10.367\",\"a\":\"79607.20\",\"A\":\"1.062\",\"T\":1788563197760,\"E\":1788563197761,\"st\":1}}"}
{"receive_ns":1788563197801583000,"stream":"btcusdt@bookTicker","event_type":"bookTicker","event_time_ms":1788563197835,"raw_json":"{\"stream\":\"btcusdt@bookTicker\",\"data\":{\"e\":\"bookTicker\",\"u\":11478222772447,\"s\":\"BTCUSDT\",\"ps\":\"BTCUSDT\",\"b\":\"79607.10\",\"B\":\"10.369\",\"a\":\"79607.20\",\"A\":\"1.062\",\"T\":1788563197835,\"E\":1788563197835,\"st\":1}}"}
{"receive_ns":1788563197813463000,"stream":"btcusdt@depth@100ms","event_type":"depthUpdate","event_time_ms":1788563197849,"raw_json":"{\"stream\":\"btcusdt@depth@100ms\",\"data\":{\"e\":\"depthUpdate\",\"E\":1788563197849,\"T\":1788563197845,\"s\":\"BTCUSDT\",\"ps\":\"BTCUSDT\",\"U\":11478222767986,\"u\":11478222772918,\"pu\":11478222767836,\"b\":[[\"29207.10\",\"0.224\"],[\"29307.10\",\"1.876\"],[\"29407.10\",\"0.000\"],[\"63686.00\",\"0.002\"],[\"71646.30\",\"0.002\"],[\"76422.80\",\"0.000\"],[\"78811.00\",\"3.492\"],[\"79209.00\",\"0.001\"],[\"79209.10\",\"1.133\"],[\"79236.90\",\"0.015\"],[\"79434.00\",\"0.076\"],[\"79453.90\",\"0.204\"],[\"79487.70\",\"1.005\"],[\"79491.70\",\"1.506\"],[\"79493.70\",\"0.631\"],[\"79607.10\",\"10.369\"]],\"a\":[[\"79608.30\",\"0.103\"],[\"79608.70\",\"0.026\"],[\"79609.20\",\"0.000\"],[\"79610.20\",\"0.051\"],[\"79610.30\",\"0.613\"],[\"79611.20\",\"0.000\"],[\"79619.30\",\"0.340\"],[\"79620.50\",\"2.497\"],[\"79973.40\",\"1.713\"],[\"80403.30\",\"7.987\"],[\"81040.10\",\"1.183\"],[\"81199.30\",\"0.033\"]],\"st\":1}}"}
{"receive_ns":1788563197894221000,"stream":"btcusdt@bookTicker","event_type":"bookTicker","event_time_ms":1788563197929,"raw_json":"{\"stream\":\"btcusdt@bookTicker\",\"data\":{\"e\":\"bookTicker\",\"u\":11478222776544,\"s\":\"BTCUSDT\",\"ps\":\"BTCUSDT\",\"b\":\"79607.10\",\"B\":\"10.369\",\"a\":\"79607.20\",\"A\":\"1.060\",\"T\":1788563197929,\"E\":1788563197929,\"st\":1}}"}
{"receive_ns":1788563197916337000,"stream":"btcusdt@depth@100ms","event_type":"depthUpdate","event_time_ms":1788563197951,"raw_json":"{\"stream\":\"btcusdt@depth@100ms\",\"data\":{\"e\":\"depthUpdate\",\"E\":1788563197951,\"T\":1788563197949,\"s\":\"BTCUSDT\",\"ps\":\"BTCUSDT\",\"U\":11478222773130,\"u\":11478222777514,\"pu\":11478222772918,\"b\":[[\"1000.00\",\"24.604\"],[\"29207.10\",\"0.406\"],[\"29307.10\",\"1.694\"],[\"71646.30\",\"0.002\"],[\"76422.80\",\"0.002\"],[\"78413.00\",\"1.148\"],[\"78467.20\",\"0.003\"],[\"78467.80\",\"0.459\"],[\"78811.00\",\"3.493\"],[\"79209.10\",\"1.274\"],[\"79236.90\",\"0.247\"],[\"79438.00\",\"1.767\"],[\"79487.70\",\"1.305\"],[\"79493.70\",\"0.957\"],[\"79516.10\",\"0.001\"],[\"79535.40\",\"0.002\"],[\"79583.40\",\"1.875\"],[\"79592.00\",\"0.072\"],[\"79592.30\",\"0.077\"],[\"79596.80\",\"0.038\"],[\"79599.00\",\"0.050\"]],\"a\":[[\"79607.20\",\"1.060\"],[\"79611.20\",\"0.251\"],[\"79623.30\",\"0.045\"],[\"79625.00\",\"0.007\"],[\"79645.70\",\"0.265\"],[\"79676.90\",\"24.626\"],[\"79678.90\",\"0.018\"],[\"79693.10\",\"0.000\"],[\"79721.30\",\"0.002\"],[\"79733.30\",\"0.015\"],[\"79788.30\",\"0.414\"],[\"79973.40\",\"1.913\"],[\"80403.30\",\"7.987\"],[\"81199.30\",\"0.030\"],[\"87568.00\",\"0.000\"]],\"st\":1}}"}
{"receive_ns":1788563198026774000,"stream":"btcusdt@depth@100ms","event_type":"depthUpdate","event_time_ms":1788563198053,"raw_json":"{\"stream\":\"btcusdt@depth@100ms\",\"data\":{\"e\":\"depthUpdate\",\"E\":1788563198053,\"T\":1788563198050,\"s\":\"BTCUSDT\",\"ps\":\"BTCUSDT\",\"U\":11478222777579,\"u\":11478222783037,\"pu\":11478222777514,\"b\":[[\"29207.10\",\"0.581\"],[\"29307.10\",\"1.519\"],[\"63685.70\",\"0.001\"],[\"63686.00\",\"0.002\"],[\"71646.30\",\"0.002\"],[\"76422.80\",\"0.000\"],[\"78612.60\",\"1.270\"],[\"78617.40\",\"0.002\"],[\"78647.10\",\"19.047\"],[\"78811.00\",\"3.493\"],[\"79010.00\",\"2.416\"],[\"79491.70\",\"1.506\"],[\"79516.10\",\"3.015\"],[\"79519.40\",\"0.966\"],[\"79534.00\",\"0.001\"],[\"79536.70\",\"23.511\"],[\"79592.80\",\"0.007\"]],\"a\":[[\"79692.00\",\"1.397\"],[\"79698.00\",\"4.213\"],[\"79828.80\",\"8.611\"],[\"79829.00\",\"0.001\"],[\"79973.40\",\"1.913\"],[\"80403.30\",\"7.987\"],[\"80745.80\",\"0.000\"]],\"st\":1}}"}
{"receive_ns":1788563198032957000,"stream":"btcusdt@bookTicker","event_type":"bookTicker","event_time_ms":1788563198067,"raw_json":"{\"stream\":\"btcusdt@bookTicker\",\"data\":{\"e\":\"bookTicker\",\"u\":11478222783883,\"s\":\"BTCUSDT\",\"ps\":\"BTCUSDT\",\"b\":\"79607.10\",\"B\":\"10.377\",\"a\":\"79607.20\",\"A\":\"1.060\",\"T\":1788563198067,\"E\":1788563198067,\"st\":1}}"}
{"receive_ns":1788563198033185000,"stream":"btcusdt@bookTicker","event_type":"bookTicker","event_time_ms":1788563198068,"raw_json":"{\"stream\":\"btcusdt@bookTicker\",\"data\":{\"e\":\"bookTicker\",\"u\":11478222783884,\"s\":\"BTCUSDT\",\"ps\":\"BTCUSDT\",\"b\":\"79607.10\",\"B\":\"10.396\",\"a\":\"79607.20\",\"A\":\"1.060\",\"T\":1788563198067,\"E\":1788563198068,\"st\":1}}"}
{"receive_ns":1788563198033403000,"stream":"btcusdt@bookTicker","event_type":"bookTicker","event_time_ms":1788563198068,"raw_json":"{\"stream\":\"btcusdt@bookTicker\",\"data\":{\"e\":\"bookTicker\",\"u\":11478222783944,\"s\":\"BTCUSDT\",\"ps\":\"BTCUSDT\",\"b\":\"79607.10\",\"B\":\"10.388\",\"a\":\"79607.20\",\"A\":\"1.060\",\"T\":1788563198068,\"E\":1788563198068,\"st\":1}}"}
{"receive_ns":1788563198033669000,"stream":"btcusdt@bookTicker","event_type":"bookTicker","event_time_ms":1788563198068,"raw_json":"{\"stream\":\"btcusdt@bookTicker\",\"data\":{\"e\":\"bookTicker\",\"u\":11478222783945,\"s\":\"BTCUSDT\",\"ps\":\"BTCUSDT\",\"b\":\"79607.10\",\"B\":\"10.369\",\"a\":\"79607.20\",\"A\":\"1.060\",\"T\":1788563198068,\"E\":1788563198068,\"st\":1}}"}
{"receive_ns":1788563198033860000,"stream":"btcusdt@bookTicker","event_type":"bookTicker","event_time_ms":1788563198069,"raw_json":"{\"stream\":\"btcusdt@bookTicker\",\"data\":{\"e\":\"bookTicker\",\"u\":11478222783974,\"s\":\"BTCUSDT\",\"ps\":\"BTCUSDT\",\"b\":\"79607.10\",\"B\":\"10.371\",\"a\":\"79607.20\",\"A\":\"1.060\",\"T\":1788563198068,\"E\":1788563198069,\"st\":1}}"}
{"receive_ns":1788563198118962000,"stream":"btcusdt@depth@100ms","event_type":"depthUpdate","event_time_ms":1788563198155,"raw_json":"{\"stream\":\"btcusdt@depth@100ms\",\"data\":{\"e\":\"depthUpdate\",\"E\":1788563198155,\"T\":1788563198153,\"s\":\"BTCUSDT\",\"ps\":\"BTCUSDT\",\"U\":11478222783131,\"u\":11478222788205,\"pu\":11478222783037,\"b\":[[\"29207.10\",\"0.763\"],[\"29307.10\",\"1.337\"],[\"63686.00\",\"0.002\"],[\"71646.30\",\"0.002\"],[\"78500.60\",\"0.749\"],[\"78691.60\",\"1.523\"],[\"78706.00\",\"1.342\"],[\"78811.00\",\"3.493\"],[\"79209.10\",\"1.274\"],[\"79236.90\",\"0.247\"],[\"79434.00\",\"0.176\"],[\"79447.80\",\"0.002\"],[\"79471.70\",\"0.042\"],[\"79487.70\",\"1.456\"],[\"79493.70\",\"0.706\"],[\"79516.10\",\"5.033\"],[\"79538.40\",\"4.160\"],[\"79591.60\",\"0.073\"],[\"79592.00\",\"0.010\"],[\"79592.80\",\"0.003\"],[\"79594.30\",\"0.165\"],[\"79607.10\",\"10.371\"]],\"a\":[[\"79608.30\",\"0.077\"],[\"79608.70\",\"0.000\"],[\"79611.20\",\"0.592\"],[\"79615.70\",\"0.002\"],[\"79616.00\",\"0.095\"],[\"79616.20\",\"0.858\"],[\"79617.50\",\"0.641\"],[\"79618.80\",\"0.063\"],[\"79618.90\",\"0.317\"],[\"79682.50\",\"0.019\"],[\"79686.90\",\"0.002\"],[\"79688.30\",\"0.022\"],[\"79702.80\",\"0.010\"],[\"79788.30\",\"0.414\"],[\"79973.40\",\"1.913\"],[\"80403.30\",\"7.987\"]],\"st\":1}}"}
{"receive_ns":1788563198126991000,"stream":"btcusdt@bookTicker","event_type":"bookTicker","event_time_ms":1788563198162,"raw_json":"{\"stream\":\"btcusdt@bookTicker\",\"data\":{\"e\":\"bookTicker\",\"u\":11478222788756,\"s\":\"BTCUSDT\",\"ps\":\"BTCUSDT\",\"b\":\"79607.10\",\"B\":\"10.368\",\"a\":\"79607.20\",\"A\":\"1.060\",\"T\":1788563198162,\"E\":1788563198162,\"st\":1}}"}
{"receive_ns":1788563198127241000,"stream":"btcusdt@trade","event_type":"trade","event_time_ms":1788563198162,"raw_json":"{\"stream\":\"btcusdt@trade\",\"data\":{\"e\":\"trade\",\"E\":1788563198162,\"T\":1788563198162,\"s\":\"BTCUSDT\",\"t\":8054082681,\"p\":\"79607.10\",\"q\":\"0.003\",\"X\":\"MARKET\",\"m\":true,\"st\":1}}"}
{"receive_ns":1788563198127495000,"stream":"btcusdt@bookTicker","event_type":"bookTicker","event_time_ms":1788563198163,"raw_json":"{\"stream\":\"btcusdt@bookTicker\",\"data\":{\"e\":\"bookTicker\",\"u\":11478222788860,\"s\":\"BTCUSDT\",\"ps\":\"BTCUSDT\",\"b\":\"79607.10\",\"B\":\"10.387\",\"a\":\"79607.20\",\"A\":\"1.060\",\"T\":1788563198163,\"E\":1788563198163,\"st\":1}}"}
{"receive_ns":1788563198127818000,"stream":"btcusdt@bookTicker","event_type":"bookTicker","event_time_ms":1788563198164,"raw_json":"{\"stream\":\"btcusdt@bookTicker\",\"data\":{\"e\":\"bookTicker\",\"u\":11478222788917,\"s\":\"BTCUSDT\",\"ps\":\"BTCUSDT\",\"b\":\"79607.10\",\"B\":\"10.395\",\"a\":\"79607.20\",\"A\":\"1.060\",\"T\":1788563198164,\"E\":1788563198164,\"st\":1}}"}
{"receive_ns":1788563198128072000,"stream":"btcusdt@bookTicker","event_type":"bookTicker","event_time_ms":1788563198164,"raw_json":"{\"stream\":\"btcusdt@bookTicker\",\"data\":{\"e\":\"bookTicker\",\"u\":11478222788984,\"s\":\"BTCUSDT\",\"ps\":\"BTCUSDT\",\"b\":\"79607.10\",\"B\":\"10.376\",\"a\":\"79607.20\",\"A\":\"1.060\",\"T\":1788563198164,\"E\":1788563198164,\"st\":1}}"}
{"receive_ns":1788563198128259000,"stream":"btcusdt@bookTicker","event_type":"bookTicker","event_time_ms":1788563198164,"raw_json":"{\"stream\":\"btcusdt@bookTicker\",\"data\":{\"e\":\"bookTicker\",\"u\":11478222788989,\"s\":\"BTCUSDT\",\"ps\":\"BTCUSDT\",\"b\":\"79607.10\",\"B\":\"10.368\",\"a\":\"79607.20\",\"A\":\"1.060\",\"T\":1788563198164,\"E\":1788563198164,\"st\":1}}"}
{"receive_ns":1788563198155501000,"stream":"btcusdt@bookTicker","event_type":"bookTicker","event_time_ms":1788563198190,"raw_json":"{\"stream\":\"btcusdt@bookTicker\",\"data\":{\"e\":\"bookTicker\",\"u\":11478222791018,\"s\":\"BTCUSDT\",\"ps\":\"BTCUSDT\",\"b\":\"79607.10\",\"B\":\"10.057\",\"a\":\"79607.20\",\"A\":\"1.060\",\"T\":1788563198190,\"E\":1788563198190,\"st\":1}}"}
{"receive_ns":1788563198157686000,"stream":"btcusdt@bookTicker","event_type":"bookTicker","event_time_ms":1788563198193,"raw_json":"{\"stream\":\"btcusdt@bookTicker\",\"data\":{\"e\":\"bookTicker\",\"u\":11478222791362,\"s\":\"BTCUSDT\",\"ps\":\"BTCUSDT\",\"b\":\"79607.10\",\"B\":\"10.372\",\"a\":\"79607.20\",\"A\":\"1.060\",\"T\":1788563198193,\"E\":1788563198193,\"st\":1}}"}
{"receive_ns":1788563198159894000,"stream":"btcusdt@bookTicker","event_type":"bookTicker","event_time_ms":1788563198195,"raw_json":"{\"stream\":\"btcusdt@bookTicker\",\"data\":{\"e\":\"bookTicker\",\"u\":11478222791596,\"s\":\"BTCUSDT\",\"ps\":\"BTCUSDT\",\"b\":\"79607.10\",\"B\":\"10.375\",\"a\":\"79607.20\",\"A\":\"1.060\",\"T\":1788563198195,\"E\":1788563198195,\"st\":1}}"}
{"receive_ns":1788563198195490000,"stream":"btcusdt@bookTicker","event_type":"bookTicker","event_time_ms":1788563198230,"raw_json":"{\"stream\":\"btcusdt@bookTicker\",\"data\":{\"e\":\"bookTicker\",\"u\":11478222793957,\"s\":\"BTCUSDT\",\"ps\":\"BTCUSDT\",\"b\":\"79607.10\",\"B\":\"10.394\",\"a\":\"79607.20\",\"A\":\"1.060\",\"T\":1788563198230,\"E\":1788563198230,\"st\":1}}"}
{"receive_ns":1788563198195795000,"stream":"btcusdt@bookTicker","event_type":"bookTicker","event_time_ms":1788563198230,"raw_json":"{\"stream\":\"btcusdt@bookTicker\",\"data\":{\"e\":\"bookTicker\",\"u\":11478222793999,\"s\":\"BTCUSDT\",\"ps\":\"BTCUSDT\",\"b\":\"79607.10\",\"B\":\"10.375\",\"a\":\"79607.20\",\"A\":\"1.060\",\"T\":1788563198230,\"E\":1788563198230,\"st\":1}}"}
{"receive_ns":1788563198221539000,"stream":"btcusdt@depth@100ms","event_type":"depthUpdate","event_time_ms":1788563198257,"raw_json":"{\"stream\":\"btcusdt@depth@100ms\",\"data\":{\"e\":\"depthUpdate\",\"E\":1788563198257,\"T\":1788563198253,\"s\":\"BTCUSDT\",\"ps\":\"BTCUSDT\",\"U\":11478222788347,\"u\":11478222795259,\"pu\":11478222788205,\"b\":[[\"1000.00\",\"24.604\"],[\"29207.10\",\"0.938\"],[\"29307.10\",\"1.162\"],[\"71646.30\",\"0.002\"],[\"76422.80\",\"0.002\"],[\"78603.10\",\"6.993\"],[\"78651.80\",\"9.711\"],[\"78811.00\",\"3.493\"],[\"79209.10\",\"1.284\"],[\"79471.70\",\"0.042\"],[\"79478.20\",\"0.010\"],[\"79478.30\",\"0.003\"],[\"79491.70\",\"0.502\"],[\"79511.50\",\"0.022\"],[\"79516.10\",\"3.018\"],[\"79535.40\",\"0.000\"],[\"79607.10\",\"10.375\"]],\"a\":[[\"79608.30\",\"0.001\"],[\"79608.80\",\"0.001\"],[\"79609.00\",\"0.003\"],[\"79610.20\",\"0.077\"],[\"79624.70\",\"0.745\"],[\"79625.70\",\"0.453\"],[\"79626.50\",\"0.000\"],[\"79652.10\",\"0.026\"],[\"79663.00\",\"0.002\"],[\"79678.90\",\"0.016\"],[\"79702.80\",\"0.008\"],[\"79788.30\",\"0.215\"],[\"79809.80\",\"0.002\"],[\"79833.90\",\"0.017\"],[\"79836.40\",\"0.001\"],[\"79836.50\",\"0.003\"],[\"79973.40\",\"1.388\"],[\"80403.30\",\"7.987\"]],\"st\":1}}"}
{"receive_ns":1788563198245892000,"stream":"btcusdt@bookTicker","event_type":"bookTicker","event_time_ms":1788563198279,"raw_json":"{\"stream\":\"btcusdt@bookTicker\",\"data\":{\"e\":\"bookTicker\",\"u\":11478222796401,\"s\":\"BTCUSDT\",\"ps\":\"BTCUSDT\",\"b\":\"79607.10\",\"B\":\"10.115\",\"a\":\"79607.20\",\"A\":\"1.060\",\"T\":1788563198279,\"E\":1788563198279,\"st\":1}}"}
{"receive_ns":1788563198246189000,"stream":"btcusdt@bookTicker","event_type":"bookTicker","event_time_ms":1788563198281,"raw_json":"{\"stream\":\"btcusdt@bookTicker\",\"data\":{\"e\":\"bookTicker\",\"u\":11478222796473,\"s\":\"BTCUSDT\",\"ps\":\"BTCUSDT\",\"b\":\"79607.10\",\"B\":\"10.134\",\"a\":\"79607.20\",\"A\":\"1.060\",\"T\":1788563198281,\"E\":1788563198281,\"st\":1}}"}
{"receive_ns":1788563198247286000,"stream":"btcusdt@bookTicker","event_type":"bookTicker","event_time_ms":1788563198281,"raw_json":"{\"stream\":\"btcusdt@bookTicker\",\"data\":{\"e\":\"bookTicker\",\"u\":11478222796576,\"s\":\"BTCUSDT\",\"ps\":\"BTCUSDT\",\"b\":\"79607.10\",\"B\":\"10.115\",\"a\":\"79607.20\",\"A\":\"1.060\",\"T\":1788563198281,\"E\":1788563198281,\"st\":1}}"}
{"receive_ns":1788563198247581000,"stream":"btcusdt@bookTicker","event_type":"bookTicker","event_time_ms":1788563198283,"raw_json":"{\"stream\":\"btcusdt@bookTicker\",\"data\":{\"e\":\"bookTicker\",\"u\":11478222796685,\"s\":\"BTCUSDT\",\"ps\":\"BTCUSDT\",\"b\":\"79607.10\",\"B\":\"10.378\",\"a\":\"79607.20\",\"A\":\"1.060\",\"T\":1788563198283,\"E\":1788563198283,\"st\":1}}"}
{"receive_ns":1788563198248290000,"stream":"btcusdt@bookTicker","event_type":"bookTicker","event_time_ms":1788563198284,"raw_json":"{\"stream\":\"btcusdt@bookTicker\",\"data\":{\"e\":\"bookTicker\",\"u\":11478222796763,\"s\":\"BTCUSDT\",\"ps\":\"BTCUSDT\",\"b\":\"79607.10\",\"B\":\"10.376\",\"a\":\"79607.20\",\"A\":\"1.060\",\"T\":1788563198284,\"E\":1788563198284,\"st\":1}}"}
{"receive_ns":1788563198251390000,"stream":"btcusdt@bookTicker","event_type":"bookTicker","event_time_ms":1788563198286,"raw_json":"{\"stream\":\"btcusdt@bookTicker\",\"data\":{\"e\":\"bookTicker\",\"u\":11478222796856,\"s\":\"BTCUSDT\",\"ps\":\"BTCUSDT\",\"b\":\"79607.10\",\"B\":\"10.395\",\"a\":\"79607.20\",\"A\":\"1.060\",\"T\":1788563198285,\"E\":1788563198286,\"st\":1}}"}
{"receive_ns":1788563198251614000,"stream":"btcusdt@bookTicker","event_type":"bookTicker","event_time_ms":1788563198286,"raw_json":"{\"stream\":\"btcusdt@bookTicker\",\"data\":{\"e\":\"bookTicker\",\"u\":11478222796879,\"s\":\"BTCUSDT\",\"ps\":\"BTCUSDT\",\"b\":\"79607.10\",\"B\":\"10.403\",\"a\":\"79607.20\",\"A\":\"1.060\",\"T\":1788563198285,\"E\":1788563198286,\"st\":1}}"}
{"receive_ns":1788563198260934000,"stream":"btcusdt@bookTicker","event_type":"bookTicker","event_time_ms":1788563198286,"raw_json":"{\"stream\":\"btcusdt@bookTicker\",\"data\":{\"e\":\"bookTicker\",\"u\":11478222796943,\"s\":\"BTCUSDT\",\"ps\":\"BTCUSDT\",\"b\":\"79607.10\",\"B\":\"10.384\",\"a\":\"79607.20\",\"A\":\"1.060\",\"T\":1788563198286,\"E\":1788563198286,\"st\":1}}"}
{"receive_ns":1788563198261161000,"stream":"btcusdt@bookTicker","event_type":"bookTicker","event_time_ms":1788563198286,"raw_json":"{\"stream\":\"btcusdt@bookTicker\",\"data\":{\"e\":\"bookTicker\",\"u\":11478222796957,\"s\":\"BTCUSDT\",\"ps\":\"BTCUSDT\",\"b\":\"79607.10\",\"B\":\"10.376\",\"a\":\"79607.20\",\"A\":\"1.060\",\"T\":1788563198286,\"E\":1788563198286,\"st\":1}}"}
{"receive_ns":1788563198261542000,"stream":"btcusdt@bookTicker","event_type":"bookTicker","event_time_ms":1788563198287,"raw_json":"{\"stream\":\"btcusdt@bookTicker\",\"data\":{\"e\":\"bookTicker\",\"u\":11478222796997,\"s\":\"BTCUSDT\",\"ps\":\"BTCUSDT\",\"b\":\"79607.10\",\"B\":\"10.378\",\"a\":\"79607.20\",\"A\":\"1.060\",\"T\":1788563198287,\"E\":1788563198287,\"st\":1}}"}
{"receive_ns":1788563198325513000,"stream":"btcusdt@depth@100ms","event_type":"depthUpdate","event_time_ms":1788563198359,"raw_json":"{\"stream\":\"btcusdt@depth@100ms\",\"data\":{\"e\":\"depthUpdate\",\"E\":1788563198359,\"T\":1788563198357,\"s\":\"BTCUSDT\",\"ps\":\"BTCUSDT\",\"U\":11478222795405,\"u\":11478222800896,\"pu\":11478222795259,\"b\":[[\"29207.10\",\"1.120\"],[\"29307.10\",\"0.980\"],[\"63686.00\",\"0.002\"],[\"71646.30\",\"0.002\"],[\"76422.80\",\"0.000\"],[\"78492.60\",\"12.343\"],[\"78739.40\",\"1.711\"],[\"78801.40\",\"0.000\"],[\"78811.00\",\"3.493\"],[\"79204.30\",\"2.332\"],[\"79209.10\",\"1.143\"],[\"79236.90\",\"0.015\"],[\"79434.00\",\"0.076\"],[\"79487.70\",\"1.205\"],[\"79491.70\",\"1.506\"],[\"79493.70\",\"0.631\"],[\"79513.90\",\"1.026\"],[\"79529.80\",\"0.000\"],[\"79534.00\",\"23.462\"],[\"79536.70\",\"0.000\"],[\"79538.40\",\"0.795\"],[\"79575.30\",\"0.001\"],[\"79576.50\",\"0.454\"],[\"79606.40\",\"0.108\"],[\"79607.10\",\"10.378\"]],\"a\":[[\"79607.90\",\"0.076\"],[\"79608.80\",\"0.027\"],[\"79611.20\",\"0.000\"],[\"79625.70\",\"0.001\"],[\"79626.50\",\"0.452\"],[\"79674.10\",\"0.017\"],[\"79973.40\",\"1.713\"],[\"80000.40\",\"2.246\"],[\"80005.30\",\"0.001\"],[\"80019.70\",\"0.087\"],[\"80403.30\",\"7.987\"],[\"80562.50\",\"15.869\"],[\"80757.40\",\"3.678\"],[\"80761.50\",\"1.855\"]],\"st\":1}}"}
{"receive_ns":1788563198375024000,"stream":"btcusdt@bookTicker","event_type":"bookTicker","event_time_ms":1788563198410,"raw_json":"{\"stream\":\"btcusdt@bookTicker\",\"data\":{\"e\":\"bookTicker\",\"u\":11478222803920,\"s\":\"BTCUSDT\",\"ps\":\"BTCUSDT\",\"b\":\"79607.10\",\"B\":\"10.166\",\"a\":\"79607.20\",\"A\":\"1.060\",\"T\":1788563198410,\"E\":1788563198410,\"st\":1}}"}
{"receive_ns":1788563198379101000,"stream":"btcusdt@bookTicker","event_type":"bookTicker","event_time_ms":1788563198414,"raw_json":"{\"stream\":\"btcusdt@bookTicker\",\"data\":{\"e\":\"bookTicker\",\"u\":11478222804245,\"s\":\"BTCUSDT\",\"ps\":\"BTCUSDT\",\"b\":\"79607.10\",\"B\":\"10.382\",\"a\":\"79607.20\",\"A\":\"1.060\",\"T\":1788563198414,\"E\":1788563198414,\"st\":1}}"}
{"receive_ns":1788563198434955000,"stream":"btcusdt@depth@100ms","event_type":"depthUpdate","event_time_ms":1788563198461,"raw_json":"{\"stream\":\"btcusdt@depth@100ms\",\"data\":{\"e\":\"depthUpdate\",\"E\":1788563198461,\"T\":1788563198460,\"s\":\"BTCUSDT\",\"ps\":\"BTCUSDT\",\"U\":11478222801005,\"u\":11478222806494,\"pu\":11478222800896,\"b\":[[\"1000.00\",\"24.604\"],[\"29207.10\",\"1.295\"],[\"29307.10\",\"0.805\"],[\"71646.30\",\"0.002\"],[\"75626.80\",\"0.002\"],[\"76422.80\",\"0.002\"],[\"78811.00\",\"3.493\"],[\"78834.90\",\"0.544\"],[\"79010.00\",\"3.048\"],[\"79209.00\",\"0.002\"],[\"79209.10\",\"1.284\"],[\"79236.90\",\"0.247\"],[\"79453.90\",\"0.304\"],[\"79491.70\",\"1.757\"],[\"79493.70\",\"0.706\"],[\"79534.00\",\"0.001\"],[\"79536.70\",\"23.461\"],[\"79607.10\",\"10.382\"]],\"a\":[[\"79611.20\",\"0.592\"],[\"79674.10\",\"0.024\"],[\"79788.30\",\"0.414\"],[\"79973.40\",\"1.913\"],[\"80403.30\",\"7.987\"],[\"80681.90\",\"3.400\"],[\"80743.10\",\"0.001\"]],\"st\":1}}"}
{"receive_ns":1788563198495761000,"stream":"btcusdt@bookTicker","event_type":"bookTicker","event_time_ms":1788563198531,"raw_json":"{\"stream\":\"btcusdt@bookTicker\",\"data\":{\"e\":\"bookTicker\",\"u\":11478222809933,\"s\":\"BTCUSDT\",\"ps\":\"BTCUSDT\",\"b\":\"79607.10\",\"B\":\"10.385\",\"a\":\"79607.20\",\"A\":\"1.060\",\"T\":1788563198530,\"E\":1788563198531,\"st\":1}}"}
{"receive_ns":1788563198528821000,"stream":"btcusdt@depth@100ms","event_type":"depthUpdate","event_time_ms":1788563198563,"raw_json":"{\"stream\":\"btcusdt@depth@100ms\",\"data\":{\"e\":\"depthUpdate\",\"E\":1788563198563,\"T\":1788563198562,\"s\":\"BTCUSDT\",\"ps\":\"BTCUSDT\",\"U\":11478222806586,\"u\":11478222811378,\"pu\":11478222806494,\"b\":[[\"1000.00\",\"24.604\"],[\"29207.10\",\"1.477\"],[\"29307.10\",\"0.623\"],[\"63686.00\",\"0.036\"],[\"71646.30\",\"0.002\"],[\"75626.70\",\"0.015\"],[\"75626.80\",\"0.004\"],[\"76422.80\",\"0.000\"],[\"78811.00\",\"3.493\"],[\"79209.10\",\"1.284\"],[\"79440.40\",\"0.000\"],[\"79442.10\",\"2.282\"],[\"79481.50\",\"0.663\"],[\"79481.60\",\"0.004\"],[\"79487.70\",\"0.001\"],[\"79491.70\",\"1.757\"],[\"79516.10\",\"3.003\"],[\"79607.10\",\"10.385\"]],\"a\":[[\"79608.80\",\"0.001\"],[\"79698.00\",\"4.228\"],[\"79730.80\",\"0.353\"],[\"79731.00\",\"0.341\"],[\"79768.00\",\"0.064\"],[\"79770.20\",\"2.561\"],[\"79788.30\",\"0.215\"],[\"79828.80\",\"8.608\"],[\"79973.40\",\"1.150\"],[\"80403.30\",\"7.987\"],[\"80593.20\",\"2.500\"],[\"80701.00\",\"0.496\"]],\"st\":1}}"}
{"receive_ns":1788563198581270000,"stream":"btcusdt@bookTicker","event_type":"bookTicker","event_time_ms":1788563198616,"raw_json":"{\"stream\":\"btcusdt@bookTicker\",\"data\":{\"e\":\"bookTicker\",\"u\":11478222814175,\"s\":\"BTCUSDT\",\"ps\":\"BTCUSDT\",\"b\":\"79607.10\",\"B\":\"9.722\",\"a\":\"79607.20\",\"A\":\"1.060\",\"T\":1788563198616,\"E\":1788563198616,\"st\":1}}"}
{"receive_ns":1788563198581581000,"stream":"btcusdt@trade","event_type":"trade","event_time_ms":1788563198616,"raw_json":"{\"stream\":\"btcusdt@trade\",\"data\":{\"e\":\"trade\",\"E\":1788563198616,\"T\":1788563198616,\"s\":\"BTCUSDT\",\"t\":8054082682,\"p\":\"79607.10\",\"q\":\"0.663\",\"X\":\"MARKET\",\"m\":true,\"st\":1}}"}
{"receive_ns":1788563198584085000,"stream":"btcusdt@bookTicker","event_type":"bookTicker","event_time_ms":1788563198618,"raw_json":"{\"stream\":\"btcusdt@bookTicker\",\"data\":{\"e\":\"bookTicker\",\"u\":11478222814269,\"s\":\"BTCUSDT\",\"ps\":\"BTCUSDT\",\"b\":\"79607.10\",\"B\":\"9.741\",\"a\":\"79607.20\",\"A\":\"1.060\",\"T\":1788563198617,\"E\":1788563198618,\"st\":1}}"}
{"receive_ns":1788563198584311000,"stream":"btcusdt@bookTicker","event_type":"bookTicker","event_time_ms":1788563198618,"raw_json":"{\"stream\":\"btcusdt@bookTicker\",\"data\":{\"e\":\"bookTicker\",\"u\":11478222814319,\"s\":\"BTCUSDT\",\"ps\":\"BTCUSDT\",\"b\":\"79607.10\",\"B\":\"9.741\",\"a\":\"79607.20\",\"A\":\"1.210\",\"T\":1788563198618,\"E\":1788563198618,\"st\":1}}"}
{"receive_ns":1788563198584499000,"stream":"btcusdt@bookTicker","event_type":"bookTicker","event_time_ms":1788563198618,"raw_json":"{\"stream\":\"btcusdt@bookTicker\",\"data\":{\"e\":\"bookTicker\",\"u\":11478222814322,\"s\":\"BTCUSDT\",\"ps\":\"BTCUSDT\",\"b\":\"79607.10\",\"B\":\"9.749\",\"a\":\"79607.20\",\"A\":\"1.210\",\"T\":1788563198618,\"E\":1788563198618,\"st\":1}}"}
{"receive_ns":1788563198584680000,"stream":"btcusdt@bookTicker","event_type":"bookTicker","event_time_ms":1788563198618,"raw_json":"{\"stream\":\"btcusdt@bookTicker\",\"data\":{\"e\":\"bookTicker\",\"u\":11478222814349,\"s\":\"BTCUSDT\",\"ps\":\"BTCUSDT\",\"b\":\"79607.10\",\"B\":\"9.749\",\"a\":\"79607.20\",\"A\":\"1.236\",\"T\":1788563198618,\"E\":1788563198618,\"st\":1}}"}
{"receive_ns":1788563198584894000,"stream":"btcusdt@bookTicker","event_type":"bookTicker","event_time_ms":1788563198618,"raw_json":"{\"stream\":\"btcusdt@bookTicker\",\"data\":{\"e\":\"bookTicker\",\"u\":11478222814447,\"s\":\"BTCUSDT\",\"ps\":\"BTCUSDT\",\"b\":\"79607.10\",\"B\":\"9.749\",\"a\":\"79607.20\",\"A\":\"1.676\",\"T\":1788563198618,\"E\":1788563198618,\"st\":1}}"}
{"receive_ns":1788563198585079000,"stream":"btcusdt@bookTicker","event_type":"bookTicker","event_time_ms":1788563198618,"raw_json":"{\"stream\":\"btcusdt@bookTicker\",\"data\":{\"e\":\"bookTicker\",\"u\":11478222814450,\"s\":\"BTCUSDT\",\"ps\":\"BTCUSDT\",\"b\":\"79607.10\",\"B\":\"9.741\",\"a\":\"79607.20\",\"A\":\"1.676\",\"T\":1788563198618,\"E\":1788563198618,\"st\":1}}"}
{"receive_ns":1788563198585282000,"stream":"btcusdt@bookTicker","event_type":"bookTicker","event_time_ms":1788563198619,"raw_json":"{\"stream\":\"btcusdt@bookTicker\",\"data\":{\"e\":\"bookTicker\",\"u\":11478222814506,\"s\":\"BTCUSDT\",\"ps\":\"BTCUSDT\",\"b\":\"79607.10\",\"B\":\"9.741\",\"a\":\"79607.20\",\"A\":\"1.675\",\"T\":1788563198619,\"E\":1788563198619,\"st\":1}}"}
{"receive_ns":1788563198585458000,"stream":"btcusdt@bookTicker","event_type":"bookTicker","event_time_ms":1788563198619,"raw_json":"{\"stream\":\"btcusdt@bookTicker\",\"data\":{\"e\":\"bookTicker\",\"u\":11478222814512,\"s\":\"BTCUSDT\",\"ps\":\"BTCUSDT\",\"b\":\"79607.10\",\"B\":\"9.722\",\"a\":\"79607.20\",\"A\":\"1.675\",\"T\":1788563198619,\"E\":1788563198619,\"st\":1}}"}
{"receive_ns":1788563198585630000,"stream":"btcusdt@bookTicker","event_type":"bookTicker","event_time_ms":1788563198619,"raw_json":"{\"stream\":\"btcusdt@bookTicker\",\"data\":{\"e\":\"bookTicker\",\"u\":11478222814513,\"s\":\"BTCUSDT\",\"ps\":\"BTCUSDT\",\"b\":\"79607.10\",\"B\":\"9.741\",\"a\":\"79607.20\",\"A\":\"1.675\",\"T\":1788563198619,\"E\":1788563198619,\"st\":1}}"}
{"receive_ns":1788563198585836000,"stream":"btcusdt@bookTicker","event_type":"bookTicker","event_time_ms":1788563198619,"raw_json":"{\"stream\":\"btcusdt@bookTicker\",\"data\":{\"e\":\"bookTicker\",\"u\":11478222814554,\"s\":\"BTCUSDT\",\"ps\":\"BTCUSDT\",\"b\":\"79607.10\",\"B\":\"9.749\",\"a\":\"79607.20\",\"A\":\"1.675\",\"T\":1788563198619,\"E\":1788563198619,\"st\":1}}"}
{"receive_ns":1788563198586013000,"stream":"btcusdt@bookTicker","event_type":"bookTicker","event_time_ms":1788563198620,"raw_json":"{\"stream\":\"btcusdt@bookTicker\",\"data\":{\"e\":\"bookTicker\",\"u\":11478222814607,\"s\":\"BTCUSDT\",\"ps\":\"BTCUSDT\",\"b\":\"79607.10\",\"B\":\"9.749\",\"a\":\"79607.20\",\"A\":\"1.674\",\"T\":1788563198619,\"E\":1788563198620,\"st\":1}}"}
{"receive_ns":1788563198586215000,"stream":"btcusdt@bookTicker","event_type":"bookTicker","event_time_ms":1788563198620,"raw_json":"{\"stream\":\"btcusdt@bookTicker\",\"data\":{\"e\":\"bookTicker\",\"u\":11478222814629,\"s\":\"BTCUSDT\",\"ps\":\"BTCUSDT\",\"b\":\"79607.10\",\"B\":\"9.749\",\"a\":\"79607.20\",\"A\":\"1.675\",\"T\":1788563198620,\"E\":1788563198620,\"st\":1}}"}
{"receive_ns":1788563198586360000,"stream":"btcusdt@bookTicker","event_type":"bookTicker","event_time_ms":1788563198620,"raw_json":"{\"stream\":\"btcusdt@bookTicker\",\"data\":{\"e\":\"bookTicker\",\"u\":11478222814656,\"s\":\"BTCUSDT\",\"ps\":\"BTCUSDT\",\"b\":\"79607.10\",\"B\":\"9.730\",\"a\":\"79607.20\",\"A\":\"1.675\",\"T\":1788563198620,\"E\":1788563198620,\"st\":1}}"}
{"receive_ns":1788563198586497000,"stream":"btcusdt@bookTicker","event_type":"bookTicker","event_time_ms":1788563198620,"raw_json":"{\"stream\":\"btcusdt@bookTicker\",\"data\":{\"e\":\"bookTicker\",\"u\":11478222814657,\"s\":\"BTCUSDT\",\"ps\":\"BTCUSDT\",\"b\":\"79607.10\",\"B\":\"9.738\",\"a\":\"79607.20\",\"A\":\"1.675\",\"T\":1788563198620,\"E\":1788563198620,\"st\":1}}"}
{"receive_ns":1788563198586636000,"stream":"btcusdt@bookTicker","event_type":"bookTicker","event_time_ms":1788563198620,"raw_json":"{\"stream\":\"btcusdt@bookTicker\",\"data\":{\"e\":\"bookTicker\",\"u\":11478222814658,\"s\":\"BTCUSDT\",\"ps\":\"BTCUSDT\",\"b\":\"79607.10\",\"B\":\"9.730\",\"a\":\"79607.20\",\"A\":\"1.675\",\"T\":1788563198620,\"E\":1788563198620,\"st\":1}}"}
{"receive_ns":1788563198586836000,"stream":"btcusdt@bookTicker","event_type":"bookTicker","event_time_ms":1788563198621,"raw_json":"{\"stream\":\"btcusdt@bookTicker\",\"data\":{\"e\":\"bookTicker\",\"u\":11478222814759,\"s\":\"BTCUSDT\",\"ps\":\"BTCUSDT\",\"b\":\"79607.10\",\"B\":\"9.722\",\"a\":\"79607.20\",\"A\":\"1.675\",\"T\":1788563198621,\"E\":1788563198621,\"st\":1}}"}
{"receive_ns":1788563198604708000,"stream":"btcusdt@bookTicker","event_type":"bookTicker","event_time_ms":1788563198638,"raw_json":"{\"stream\":\"btcusdt@bookTicker\",\"data\":{\"e\":\"bookTicker\",\"u\":11478222815802,\"s\":\"BTCUSDT\",\"ps\":\"BTCUSDT\",\"b\":\"79607.10\",\"B\":\"9.730\",\"a\":\"79607.20\",\"A\":\"1.675\",\"T\":1788563198637,\"E\":1788563198638,\"st\":1}}"}
{"receive_ns":1788563198604911000,"stream":"btcusdt@bookTicker","event_type":"bookTicker","event_time_ms":1788563198638,"raw_json":"{\"stream\":\"btcusdt@bookTicker\",\"data\":{\"e\":\"bookTicker\",\"u\":11478222815832,\"s\":\"BTCUSDT\",\"ps\":\"BTCUSDT\",\"b\":\"79607.10\",\"B\":\"9.749\",\"a\":\"79607.20\",\"A\":\"1.675\",\"T\":1788563198638,\"E\":1788563198638,\"st\":1}}"}
{"receive_ns":1788563198605120000,"stream":"btcusdt@bookTicker","event_type":"bookTicker","event_time_ms":1788563198638,"raw_json":"{\"stream\":\"btcusdt@bookTicker\",\"data\":{\"e\":\"bookTicker\",\"u\":11478222815858,\"s\":\"BTCUSDT\",\"ps\":\"BTCUSDT\",\"b\":\"79607.10\",\"B\":\"9.741\",\"a\":\"79607.20\",\"A\":\"1.675\",\"T\":1788563198638,\"E\":1788563198638,\"st\":1}}"}
{"receive_ns":1788563198605280000,"stream":"btcusdt@bookTicker","event_type":"bookTicker","event_time_ms":1788563198638,"raw_json":"{\"stream\":\"btcusdt@bookTicker\",\"data\":{\"e\":\"bookTicker\",\"u\":11478222815867,\"s\":\"BTCUSDT\",\"ps\":\"BTCUSDT\",\"b\":\"79607.10\",\"B\":\"9.722\",\"a\":\"79607.20\",\"A\":\"1.675\",\"T\":1788563198638,\"E\":1788563198638,\"st\":1}}"}
{"receive_ns":1788563198605481000,"stream":"btcusdt@bookTicker","event_type":"bookTicker","event_time_ms":1788563198639,"raw_json":"{\"stream\":\"btcusdt@bookTicker\",\"data\":{\"e\":\"bookTicker\",\"u\":11478222815898,\"s\":\"BTCUSDT\",\"ps\":\"BTCUSDT\",\"b\":\"79607.10\",\"B\":\"9.722\",\"a\":\"79607.20\",\"A\":\"1.676\",\"T\":1788563198639,\"E\":1788563198639,\"st\":1}}"}
{"receive_ns":1788563198631395000,"stream":"btcusdt@depth@100ms","event_type":"depthUpdate","event_time_ms":1788563198665,"raw_json":"{\"stream\":\"btcusdt@depth@100ms\",\"data\":{\"e\":\"depthUpdate\",\"E\":1788563198665,\"T\":1788563198662,\"s\":\"BTCUSDT\",\"ps\":\"BTCUSDT\",\"U\":11478222811493,\"u\":11478222817079,\"pu\":11478222811378,\"b\":[[\"29207.10\",\"1.652\"],[\"29307.10\",\"0.448\"],[\"63686.00\",\"0.002\"],[\"71646.30\",\"0.002\"],[\"71681.00\",\"0.000\"],[\"75617.30\",\"0.000\"],[\"78015.00\",\"0.128\"],[\"78572.10\",\"0.842\"],[\"78811.00\",\"3.493\"],[\"79209.10\",\"1.787\"],[\"79210.10\",\"0.258\"],[\"79236.90\",\"0.247\"],[\"79434.00\",\"0.176\"],[\"79453.90\",\"0.455\"],[\"79487.70\",\"1.205\"],[\"79491.70\",\"1.506\"],[\"79493.70\",\"0.706\"],[\"79513.90\",\"0.197\"],[\"79534.00\",\"23.456\"],[\"79536.40\",\"0.210\"],[\"79536.70\",\"0.000\"],[\"79543.30\",\"0.000\"],[\"79544.50\",\"0.002\"],[\"79551.00\",\"0.000\"],[\"79551.60\",\"3.503\"],[\"79572.30\",\"0.121\"],[\"79573.10\",\"0.156\"],[\"79574.30\",\"0.001\"],[\"79575.30\",\"0.453\"],[\"79576.50\",\"0.002\"],[\"79577.10\",\"0.397\"],[\"79580.60\",\"0.000\"],[\"79584.80\",\"0.256\"],[\"79590.10\",\"0.294\"],[\"79592.70\",\"0.077\"],[\"79593.40\",\"0.002\"],[\"79594.10\",\"0.299\"],[\"79594.20\",\"0.001\"],[\"79600.20\",\"0.000\"],[\"79600.50\",\"0.000\"],[\"79601.20\",\"0.105\"],[\"79601.60\",\"0.001\"],[\"79602.30\",\"0.200\"],[\"79602.40\",\"0.058\"],[\"79603.00\",\"0.000\"],[\"79603.60\",\"0.000\"],[\"79604.00\",\"0.029\"],[\"79604.10\",\"0.026\"],[\"79604.20\",\"0.026\"],[\"79604.40\",\"0.028\"],[\"79604.50\",\"0.027\"],[\"79604.90\",\"0.000\"],[\"79605.00\",\"0.028\"],[\"79605.50\",\"0.002\"],[\"79605.70\",\"0.180\"],[\"79605.80\",\"0.000\"],[\"79605.90\",\"0.000\"],[\"79606.00\",\"0.003\"],[\"79606.10\",\"0.000\"],[\"79606.40\",\"0.082\"],[\"79606.50\",\"0.000\"],[\"79606.90\",\"0.006\"],[\"79607.00\",\"0.007\"],[\"79607.10\",\"9.722\"]],\"a\":[[\"79607.20\",\"1.676\"],[\"79607.30\",\"0.003\"],[\"79607.60\",\"0.000\"],[\"79608.20\",\"0.253\"],[\"79608.40\",\"0.251\"],[\"79609.00\",\"0.029\"],[\"79609.10\",\"0.026\"],[\"79609.20\",\"0.502\"],[\"79609.30\",\"0.279\"],[\"79610.20\",\"0.051\"],[\"79611.20\",\"0.090\"],[\"79615.70\",\"0.006\"],[\"79616.10\",\"0.548\"],[\"79617.50\",\"0.958\"],[\"79617.70\",\"0.803\"],[\"79618.80\",\"0.001\"],[\"79618.90\",\"0.000\"],[\"79622.00\",\"0.373\"],[\"79624.80\",\"0.573\"],[\"79636.90\",\"0.047\"],[\"79639.40\",\"0.002\"],[\"79644.20\",\"3.961\"],[\"79647.60\",\"9.796\"],[\"79654.00\",\"0.000\"],[\"79663.10\",\"0.001\"],[\"79663.40\",\"3.502\"],[\"79674.10\",\"0.036\"],[\"79788.80\",\"0.000\"],[\"79894.30\",\"0.000\"],[\"79942.30\",\"0.806\"],[\"79973.40\",\"1.913\"],[\"80004.30\",\"0.784\"],[\"80005.20\",\"2.007\"],[\"80403.30\",\"7.987\"],[\"80557.60\",\"14.047\"],[\"80562.50\",\"16.489\"],[\"80777.40\",\"0.432\"],[\"81199.30\",\"0.030\"]],\"st\":1}}"}
{"receive_ns":1788563198671333000,"stream":"btcusdt@bookTicker","event_type":"bookTicker","event_time_ms":1788563198706,"raw_json":"{\"stream\":\"btcusdt@bookTicker\",\"data\":{\"e\":\"bookTicker\",\"u\":11478222819382,\"s\":\"BTCUSDT\",\"ps\":\"BTCUSDT\",\"b\":\"79607.10\",\"B\":\"9.741\",\"a\":\"79607.20\",\"A\":\"1.676\",\"T\":1788563198705,\"E\":1788563198706,\"st\":1}}"}
{"receive_ns":1788563198671635000,"stream":"btcusdt@bookTicker","event_type":"bookTicker","event_time_ms":1788563198706,"raw_json":"{\"stream\":\"btcusdt@bookTicker\",\"data\":{\"e\":\"bookTicker\",\"u\":11478222819403,\"s\":\"BTCUSDT\",\"ps\":\"BTCUSDT\",\"b\":\"79607.10\",\"B\":\"9.722\",\"a\":\"79607.20\",\"A\":\"1.676\",\"T\":1788563198706,\"E\":1788563198706,\"st\":1}}"}
{"receive_ns":1788563198724604000,"stream":"btcusdt@bookTicker","event_type":"bookTicker","event_time_ms":1788563198759,"raw_json":"{\"stream\":\"btcusdt@bookTicker\",\"data\":{\"e\":\"bookTicker\",\"u\":11478222822650,\"s\":\"BTCUSDT\",\"ps\":\"BTCUSDT\",\"b\":\"79607.10\",\"B\":\"9.387\",\"a\":\"79607.20\",\"A\":\"1.676\",\"T\":1788563198758,\"E\":1788563198759,\"st\":1}}"}
{"receive_ns":1788563198727049000,"stream":"btcusdt@bookTicker","event_type":"bookTicker","event_time_ms":1788563198761,"raw_json":"{\"stream\":\"btcusdt@bookTicker\",\"data\":{\"e\":\"bookTicker\",\"u\":11478222822785,\"s\":\"BTCUSDT\",\"ps\":\"BTCUSDT\",\"b\":\"79607.10\",\"B\":\"9.723\",\"a\":\"79607.20\",\"A\":\"1.676\",\"T\":1788563198761,\"E\":1788563198761,\"st\":1}}"}
{"receive_ns":1788563198740917000,"stream":"btcusdt@depth@100ms","event_type":"depthUpdate","event_time_ms":1788563198767,"raw_json":"{\"stream\":\"btcusdt@depth@100ms\",\"data\":{\"e\":\"depthUpdate\",\"E\":1788563198767,\"T\":1788563198765,\"s\":\"BTCUSDT\",\"ps\":\"BTCUSDT\",\"U\":11478222817209,\"u\":11478222822976,\"pu\":11478222817079,\"b\":[[\"1000.00\",\"24.604\"],[\"29107.10\",\"0.028\"],[\"29207.10\",\"1.778\"],[\"29307.10\",\"0.294\"],[\"71646.30\",\"0.002\"],[\"76422.80\",\"0.002\"],[\"78261.70\",\"1.027\"],[\"78647.10\",\"17.777\"],[\"78811.00\",\"3.493\"],[\"79487.70\",\"2.209\"],[\"79491.70\",\"0.000\"],[\"79542.40\",\"0.038\"],[\"79548.10\",\"0.003\"],[\"79575.20\",\"0.868\"],[\"79591.10\",\"0.268\"],[\"79593.90\",\"0.000\"],[\"79594.00\",\"0.005\"],[\"79599.00\",\"0.151\"],[\"79601.20\",\"0.004\"],[\"79601.60\",\"0.000\"],[\"79602.00\",\"0.005\"],[\"79605.20\",\"0.028\"],[\"79607.10\",\"9.723\"]],\"a\":[[\"79608.40\",\"0.249\"],[\"79613.60\",\"0.007\"],[\"79614.10\",\"0.032\"],[\"79621.60\",\"0.001\"],[\"79622.00\",\"0.001\"],[\"79622.40\",\"0.641\"],[\"79623.00\",\"0.392\"],[\"79624.50\",\"0.478\"],[\"79645.60\",\"0.003\"],[\"79647.70\",\"0.205\"],[\"79973.40\",\"1.494\"],[\"80239.20\",\"1.990\"],[\"80403.30\",\"7.987\"],[\"80562.50\",\"17.729\"]],\"st\":1}}"}
{"receive_ns":1788563198763386000,"stream":"btcusdt@bookTicker","event_type":"bookTicker","event_time_ms":1788563198797,"raw_json":"{\"stream\":\"btcusdt@bookTicker\",\"data\":{\"e\":\"bookTicker\",\"u\":11478222824153,\"s\":\"BTCUSDT\",\"ps\":\"BTCUSDT\",\"b\":\"79607.10\",\"B\":\"9.742\",\"a\":\"79607.20\",\"A\":\"1.676\",\"T\":1788563198797,\"E\":1788563198797,\"st\":1}}"}
{"receive_ns":1788563198763677000,"stream":"btcusdt@bookTicker","event_type":"bookTicker","event_time_ms":1788563198797,"raw_json":"{\"stream\":\"btcusdt@bookTicker\",\"data\":{\"e\":\"bookTicker\",\"u\":11478222824181,\"s\":\"BTCUSDT\",\"ps\":\"BTCUSDT\",\"b\":\"79607.10\",\"B\":\"9.723\",\"a\":\"79607.20\",\"A\":\"1.676\",\"T\":1788563198797,\"E\":1788563198797,\"st\":1}}"}
{"receive_ns":1788563198799416000,"stream":"btcusdt@bookTicker","event_type":"bookTicker","event_time_ms":1788563198834,"raw_json":"{\"stream\":\"btcusdt@bookTicker\",\"data\":{\"e\":\"bookTicker\",\"u\":11478222826125,\"s\":\"BTCUSDT\",\"ps\":\"BTCUSDT\",\"b\":\"79607.10\",\"B\":\"9.742\",\"a\":\"79607.20\",\"A\":\"1.676\",\"T\":1788563198834,\"E\":1788563198834,\"st\":1}}"}
{"receive_ns":1788563198799723000,"stream":"btcusdt@bookTicker","event_type":"bookTicker","event_time_ms":1788563198834,"raw_json":"{\"stream\":\"btcusdt@bookTicker\",\"data\":{\"e\":\"bookTicker\",\"u\":11478222826169,\"s\":\"BTCUSDT\",\"ps\":\"BTCUSDT\",\"b\":\"79607.10\",\"B\":\"9.723\",\"a\":\"79607.20\",\"A\":\"1.676\",\"T\":1788563198834,\"E\":1788563198834,\"st\":1}}"}
{"receive_ns":1788563198823192000,"stream":"btcusdt@bookTicker","event_type":"bookTicker","event_time_ms":1788563198858,"raw_json":"{\"stream\":\"btcusdt@bookTicker\",\"data\":{\"e\":\"bookTicker\",\"u\":11478222827389,\"s\":\"BTCUSDT\",\"ps\":\"BTCUSDT\",\"b\":\"79607.10\",\"B\":\"9.731\",\"a\":\"79607.20\",\"A\":\"1.676\",\"T\":1788563198857,\"E\":1788563198858,\"st\":1}}"}
{"receive_ns":1788563198823444000,"stream":"btcusdt@bookTicker","event_type":"bookTicker","event_time_ms":1788563198858,"raw_json":"{\"stream\":\"btcusdt@bookTicker\",\"data\":{\"e\":\"bookTicker\",\"u\":11478222827390,\"s\":\"BTCUSDT\",\"ps\":\"BTCUSDT\",\"b\":\"79607.10\",\"B\":\"9.750\",\"a\":\"79607.20\",\"A\":\"1.676\",\"T\":1788563198857,\"E\":1788563198858,\"st\":1}}"}
{"receive_ns":1788563198823707000,"stream":"btcusdt@bookTicker","event_type":"bookTicker","event_time_ms":1788563198858,"raw_json":"{\"stream\":\"btcusdt@bookTicker\",\"data\":{\"e\":\"bookTicker\",\"u\":11478222827459,\"s\":\"BTCUSDT\",\"ps\":\"BTCUSDT\",\"b\":\"79607.10\",\"B\":\"9.742\",\"a\":\"79607.20\",\"A\":\"1.676\",\"T\":1788563198858,\"E\":1788563198858,\"st\":1}}"}
{"receive_ns":1788563198823898000,"stream":"btcusdt@bookTicker","event_type":"bookTicker","event_time_ms":1788563198859,"raw_json":"{\"stream\":\"btcusdt@bookTicker\",\"data\":{\"e\":\"bookTicker\",\"u\":11478222827466,\"s\":\"BTCUSDT\",\"ps\":\"BTCUSDT\",\"b\":\"79607.10\",\"B\":\"9.723\",\"a\":\"79607.20\",\"A\":\"1.676\",\"T\":1788563198858,\"E\":1788563198859,\"st\":1}}"}
{"receive_ns":1788563198834979000,"stream":"btcusdt@depth@100ms","event_type":"depthUpdate","event_time_ms":1788563198869,"raw_json":"{\"stream\":\"btcusdt@depth@100ms\",\"data\":{\"e\":\"depthUpdate\",\"E\":1788563198869,\"T\":1788563198865,\"s\":\"BTCUSDT\",\"ps\":\"BTCUSDT\",\"U\":11478222823054,\"u\":11478222828233,\"pu\":11478222822976,\"b\":[[\"1000.00\",\"24.604\"],[\"29107.10\",\"0.084\"],[\"29207.10\",\"1.841\"],[\"29307.10\",\"0.175\"],[\"63686.00\",\"0.002\"],[\"71646.30\",\"0.002\"],[\"76422.80\",\"0.000\"],[\"78158.30\",\"0.511\"],[\"78811.00\",\"3.493\"],[\"79209.00\",\"0.001\"],[\"79209.10\",\"1.777\"],[\"79236.90\",\"0.247\"],[\"79434.00\",\"0.678\"],[\"79453.90\",\"0.204\"],[\"79487.70\",\"2.209\"],[\"79491.70\",\"0.326\"],[\"79493.70\",\"0.631\"],[\"79553.30\",\"0.550\"],[\"79576.50\",\"0.004\"],[\"79584.70\",\"0.003\"],[\"79599.00\",\"0.050\"],[\"79599.90\",\"0.001\"],[\"79600.30\",\"0.253\"],[\"79600.40\",\"0.144\"],[\"79602.00\",\"0.004\"],[\"79602.10\",\"0.077\"],[\"79602.20\",\"0.046\"],[\"79603.30\",\"0.003\"],[\"79603.80\",\"0.076\"],[\"79605.90\",\"0.026\"],[\"79607.10\",\"9.723\"]],\"a\":[[\"79609.20\",\"0.701\"],[\"79611.20\",\"0.090\"],[\"79636.90\",\"0.001\"],[\"79638.00\",\"0.065\"],[\"79707.80\",\"0.005\"],[\"79721.30\",\"0.000\"],[\"79973.40\",\"1.913\"],[\"80005.30\",\"0.002\"],[\"80403.30\",\"7.987\"],[\"80482.90\",\"3.723\"]],\"st\":1}}"}
{"receive_ns":1788563198904967000,"stream":"btcusdt@bookTicker","event_type":"bookTicker","event_time_ms":1788563198940,"raw_json":"{\"stream\":\"btcusdt@bookTicker\",\"data\":{\"e\":\"bookTicker\",\"u\":11478222832416,\"s\":\"BTCUSDT\",\"ps\":\"BTCUSDT\",\"b\":\"79607.10\",\"B\":\"9.731\",\"a\":\"79607.20\",\"A\":\"1.676\",\"T\":1788563198939,\"E\":1788563198940,\"st\":1}}"}
{"receive_ns":1788563198905197000,"stream":"btcusdt@bookTicker","event_type":"bookTicker","event_time_ms":1788563198940,"raw_json":"{\"stream\":\"btcusdt@bookTicker\",\"data\":{\"e\":\"bookTicker\",\"u\":11478222832440,\"s\":\"BTCUSDT\",\"ps\":\"BTCUSDT\",\"b\":\"79607.10\",\"B\":\"9.750\",\"a\":\"79607.20\",\"A\":\"1.676\",\"T\":1788563198939,\"E\":1788563198940,\"st\":1}}"}
{"receive_ns":1788563198905404000,"stream":"btcusdt@bookTicker","event_type":"bookTicker","event_time_ms":1788563198940,"raw_json":"{\"stream\":\"btcusdt@bookTicker\",\"data\":{\"e\":\"bookTicker\",\"u\":11478222832586,\"s\":\"BTCUSDT\",\"ps\":\"BTCUSDT\",\"b\":\"79607.10\",\"B\":\"9.742\",\"a\":\"79607.20\",\"A\":\"1.676\",\"T\":1788563198940,\"E\":1788563198940,\"st\":1}}"}
{"receive_ns":1788563198905559000,"stream":"btcusdt@bookTicker","event_type":"bookTicker","event_time_ms":1788563198941,"raw_json":"{\"stream\":\"btcusdt@bookTicker\",\"data\":{\"e\":\"bookTicker\",\"u\":11478222832602,\"s\":\"BTCUSDT\",\"ps\":\"BTCUSDT\",\"b\":\"79607.10\",\"B\":\"9.723\",\"a\":\"79607.20\",\"A\":\"1.676\",\"T\":1788563198940,\"E\":1788563198941,\"st\":1}}"}
{"receive_ns":1788563198910348000,"stream":"btcusdt@bookTicker","event_type":"bookTicker","event_time_ms":1788563198945,"raw_json":"{\"stream\":\"btcusdt@bookTicker\",\"data\":{\"e\":\"bookTicker\",\"u\":11478222833759,\"s\":\"BTCUSDT\",\"ps\":\"BTCUSDT\",\"b\":\"79607.10\",\"B\":\"9.742\",\"a\":\"79607.20\",\"A\":\"1.676\",\"T\":1788563198945,\"E\":1788563198945,\"st\":1}}"}
{"receive_ns":1788563198910607000,"stream":"btcusdt@bookTicker","event_type":"bookTicker","event_time_ms":1788563198946,"raw_json":"{\"stream\":\"btcusdt@bookTicker\",\"data\":{\"e\":\"bookTicker\",\"u\":11478222833844,\"s\":\"BTCUSDT\",\"ps\":\"BTCUSDT\",\"b\":\"79607.10\",\"B\":\"9.723\",\"a\":\"79607.20\",\"A\":\"1.676\",\"T\":1788563198946,\"E\":1788563198946,\"st\":1}}"}
{"receive_ns":1788563198931786000,"stream":"btcusdt@bookTicker","event_type":"bookTicker","event_time_ms":1788563198966,"raw_json":"{\"stream\":\"btcusdt@bookTicker\",\"data\":{\"e\":\"bookTicker\",\"u\":11478222835509,\"s\":\"BTCUSDT\",\"ps\":\"BTCUSDT\",\"b\":\"79607.10\",\"B\":\"9.742\",\"a\":\"79607.20\",\"A\":\"1.676\",\"T\":1788563198966,\"E\":1788563198966,\"st\":1}}"}
{"receive_ns":1788563198932010000,"stream":"btcusdt@bookTicker","event_type":"bookTicker","event_time_ms":1788563198966,"raw_json":"{\"stream\":\"btcusdt@bookTicker\",\"data\":{\"e\":\"bookTicker\",\"u\":11478222835521,\"s\":\"BTCUSDT\",\"ps\":\"BTCUSDT\",\"b\":\"79607.10\",\"B\":\"9.750\",\"a\":\"79607.20\",\"A\":\"1.676\",\"T\":1788563198966,\"E\":1788563198966,\"st\":1}}"}
{"receive_ns":1788563198932267000,"stream":"btcusdt@bookTicker","event_type":"bookTicker","event_time_ms":1788563198966,"raw_json":"{\"stream\":\"btcusdt@bookTicker\",\"data\":{\"e\":\"bookTicker\",\"u\":11478222835548,\"s\":\"BTCUSDT\",\"ps\":\"BTCUSDT\",\"b\":\"79607.10\",\"B\":\"9.731\",\"a\":\"79607.20\",\"A\":\"1.676\",\"T\":1788563198966,\"E\":1788563198966,\"st\":1}}"}
{"receive_ns":1788563198932467000,"stream":"btcusdt@bookTicker","event_type":"bookTicker","event_time_ms":1788563198967,"raw_json":"{\"stream\":\"btcusdt@bookTicker\",\"data\":{\"e\":\"bookTicker\",\"u\":11478222835554,\"s\":\"BTCUSDT\",\"ps\":\"BTCUSDT\",\"b\":\"79607.10\",\"B\":\"9.723\",\"a\":\"79607.20\",\"A\":\"1.676\",\"T\":1788563198966,\"E\":1788563198967,\"st\":1}}"}
{"receive_ns":1788563198937292000,"stream":"btcusdt@depth@100ms","event_type":"depthUpdate","event_time_ms":1788563198971,"raw_json":"{\"stream\":\"btcusdt@depth@100ms\",\"data\":{\"e\":\"depthUpdate\",\"E\":1788563198971,\"T\":1788563198970,\"s\":\"BTCUSDT\",\"ps\":\"BTCUSDT\",\"U\":11478222828467,\"u\":11478222835828,\"pu\":11478222828233,\"b\":[[\"29107.10\",\"0.147\"],[\"29207.10\",\"1.897\"],[\"29307.10\",\"0.056\"],[\"63686.00\",\"0.002\"],[\"71646.30\",\"0.002\"],[\"75626.70\",\"0.017\"],[\"76422.80\",\"0.002\"],[\"78015.00\",\"0.125\"],[\"78483.70\",\"11.783\"],[\"78811.00\",\"3.492\"],[\"79487.70\",\"1.205\"],[\"79534.00\",\"0.001\"],[\"79536.70\",\"23.455\"],[\"79575.30\",\"0.453\"],[\"79576.50\",\"0.004\"],[\"79583.40\",\"1.875\"],[\"79593.00\",\"0.006\"],[\"79596.80\",\"0.032\"],[\"79602.00\",\"0.005\"],[\"79602.10\",\"0.076\"],[\"79603.80\",\"0.000\"],[\"79604.00\",\"0.003\"],[\"79605.40\",\"0.035\"],[\"79605.90\",\"0.026\"],[\"79607.10\",\"9.723\"]],\"a\":[[\"79623.30\",\"0.045\"],[\"79624.90\",\"0.002\"],[\"79625.70\",\"0.453\"],[\"79626.50\",\"0.000\"],[\"79973.40\",\"1.388\"],[\"80403.30\",\"7.987\"],[\"80557.60\",\"13.552\"]],\"st\":1}}"}
{"receive_ns":1788563198948431000,"stream":"btcusdt@bookTicker","event_type":"bookTicker","event_time_ms":1788563198982,"raw_json":"{\"stream\":\"btcusdt@bookTicker\",\"data\":{\"e\":\"bookTicker\",\"u\":11478222836481,\"s\":\"BTCUSDT\",\"ps\":\"BTCUSDT\",\"b\":\"79607.10\",\"B\":\"9.722\",\"a\":\"79607.20\",\"A\":\"1.676\",\"T\":1788563198982,\"E\":1788563198982,\"st\":1}}"}
{"receive_ns":1788563198963808000,"stream":"btcusdt@bookTicker","event_type":"bookTicker","event_time_ms":1788563198998,"raw_json":"{\"stream\":\"btcusdt@bookTicker\",\"data\":{\"e\":\"bookTicker\",\"u\":11478222837501,\"s\":\"BTCUSDT\",\"ps\":\"BTCUSDT\",\"b\":\"79607.10\",\"B\":\"9.741\",\"a\":\"79607.20\",\"A\":\"1.676\",\"T\":1788563198998,\"E\":1788563198998,\"st\":1}}"}
{"receive_ns":1788563198964341000,"stream":"btcusdt@bookTicker","event_type":"bookTicker","event_time_ms":1788563198999,"raw_json":"{\"stream\":\"btcusdt@bookTicker\",\"data\":{\"e\":\"bookTicker\",\"u\":11478222837563,\"s\":\"BTCUSDT\",\"ps\":\"BTCUSDT\",\"b\":\"79607.10\",\"B\":\"9.722\",\"a\":\"79607.20\",\"A\":\"1.676\",\"T\":1788563198998,\"E\":1788563198999,\"st\":1}}"}
{"receive_ns":1788563198988558000,"stream":"btcusdt@bookTicker","event_type":"bookTicker","event_time_ms":1788563199022,"raw_json":"{\"stream\":\"btcusdt@bookTicker\",\"data\":{\"e\":\"bookTicker\",\"u\":11478222840893,\"s\":\"BTCUSDT\",\"ps\":\"BTCUSDT\",\"b\":\"79607.10\",\"B\":\"9.741\",\"a\":\"79607.20\",\"A\":\"1.676\",\"T\":1788563199021,\"E\":1788563199022,\"st\":1}}"}
{"receive_ns":1788563198988749000,"stream":"btcusdt@bookTicker","event_type":"bookTicker","event_time_ms":1788563199022,"raw_json":"{\"stream\":\"btcusdt@bookTicker\",\"data\":{\"e\":\"bookTicker\",\"u\":11478222840927,\"s\":\"BTCUSDT\",\"ps\":\"BTCUSDT\",\"b\":\"79607.10\",\"B\":\"9.749\",\"a\":\"79607.20\",\"A\":\"1.676\",\"T\":1788563199022,\"E\":1788563199022,\"st\":1}}"}
{"receive_ns":1788563198988956000,"stream":"btcusdt@bookTicker","event_type":"bookTicker","event_time_ms":1788563199022,"raw_json":"{\"stream\":\"btcusdt@bookTicker\",\"data\":{\"e\":\"bookTicker\",\"u\":11478222840975,\"s\":\"BTCUSDT\",\"ps\":\"BTCUSDT\",\"b\":\"79607.10\",\"B\":\"9.730\",\"a\":\"79607.20\",\"A\":\"1.676\",\"T\":1788563199022,\"E\":1788563199022,\"st\":1}}"}
{"receive_ns":1788563198989110000,"stream":"btcusdt@bookTicker","event_type":"bookTicker","event_time_ms":1788563199022,"raw_json":"{\"stream\":\"btcusdt@bookTicker\",\"data\":{\"e\":\"bookTicker\",\"u\":11478222840977,\"s\":\"BTCUSDT\",\"ps\":\"BTCUSDT\",\"b\":\"79607.10\",\"B\":\"9.722\",\"a\":\"79607.20\",\"A\":\"1.676\",\"T\":1788563199022,\"E\":1788563199022,\"st\":1}}"}
{"receive_ns":1788563199017464000,"stream":"btcusdt@bookTicker","event_type":"bookTicker","event_time_ms":1788563199052,"raw_json":"{\"stream\":\"btcusdt@bookTicker\",\"data\":{\"e\":\"bookTicker\",\"u\":11478222842580,\"s\":\"BTCUSDT\",\"ps\":\"BTCUSDT\",\"b\":\"79607.10\",\"B\":\"9.727\",\"a\":\"79607.20\",\"A\":\"1.676\",\"T\":1788563199052,\"E\":1788563199052,\"st\":1}}"}
{"receive_ns":1788563199039358000,"stream":"btcusdt@depth@100ms","event_type":"depthUpdate","event_time_ms":1788563199073,"raw_json":"{\"stream\":\"btcusdt@depth@100ms\",\"data\":{\"e\":\"depthUpdate\",\"E\":1788563199073,\"T\":1788563199072,\"s\":\"BTCUSDT\",\"ps\":\"BTCUSDT\",\"U\":11478222835960,\"u\":11478222843879,\"pu\":11478222835828,\"b\":[[\"1000.00\",\"24.604\"],[\"29107.10\",\"0.266\"],[\"29207.10\",\"1.834\"],[\"29307.10\",\"0.000\"],[\"63685.70\",\"0.001\"],[\"63686.00\",\"0.002\"],[\"71646.30\",\"0.002\"],[\"75626.70\",\"0.019\"],[\"76422.80\",\"0.000\"],[\"78394.60\",\"0.021\"],[\"78811.00\",\"3.492\"],[\"79434.00\",\"0.678\"],[\"79487.70\",\"1.005\"],[\"79575.30\",\"0.001\"],[\"79576.20\",\"0.453\"],[\"79577.40\",\"0.000\"],[\"79591.60\",\"0.149\"],[\"79592.80\",\"0.003\"],[\"79601.60\",\"0.001\"],[\"79602.00\",\"0.004\"],[\"79602.10\",\"0.000\"],[\"79604.00\",\"0.029\"],[\"79605.20\",\"0.002\"],[\"79605.40\",\"0.009\"],[\"79605.90\",\"0.000\"],[\"79607.10\",\"9.727\"]],\"a\":[[\"79609.20\",\"0.502\"],[\"79623.00\",\"0.020\"],[\"79624.80\",\"0.945\"],[\"79625.70\",\"0.001\"],[\"79626.50\",\"0.452\"],[\"79638.00\",\"0.019\"],[\"79639.40\",\"0.048\"],[\"79973.40\",\"1.150\"],[\"80393.30\",\"0.933\"],[\"80403.30\",\"7.987\"],[\"80819.60\",\"0.013\"]],\"st\":1}}"}
{"receive_ns":1788563199061046000,"stream":"btcusdt@bookTicker","event_type":"bookTicker","event_time_ms":1788563199094,"raw_json":"{\"stream\":\"btcusdt@bookTicker\",\"data\":{\"e\":\"bookTicker\",\"u\":11478222845030,\"s\":\"BTCUSDT\",\"ps\":\"BTCUSDT\",\"b\":\"79607.10\",\"B\":\"9.724\",\"a\":\"79607.20\",\"A\":\"1.676\",\"T\":1788563199093,\"E\":1788563199094,\"st\":1}}"}
{"receive_ns":1788563199061247000,"stream":"btcusdt@trade","event_type":"trade","event_time_ms":1788563199094,"raw_json":"{\"stream\":\"btcusdt@trade\",\"data\":{\"e\":\"trade\",\"E\":1788563199094,\"T\":1788563199093,\"s\":\"BTCUSDT\",\"t\":8054082683,\"p\":\"79607.10\",\"q\":\"0.003\",\"X\":\"MARKET\",\"m\":true,\"st\":1}}"}
{"receive_ns":1788563199061489000,"stream":"btcusdt@bookTicker","event_type":"bookTicker","event_time_ms":1788563199095,"raw_json":"{\"stream\":\"btcusdt@bookTicker\",\"data\":{\"e\":\"bookTicker\",\"u\":11478222845089,\"s\":\"BTCUSDT\",\"ps\":\"BTCUSDT\",\"b\":\"79607.10\",\"B\":\"9.743\",\"a\":\"79607.20\",\"A\":\"1.676\",\"T\":1788563199094,\"E\":1788563199095,\"st\":1}}"}
{"receive_ns":1788563199061648000,"stream":"btcusdt@bookTicker","event_type":"bookTicker","event_time_ms":1788563199095,"raw_json":"{\"stream\":\"btcusdt@bookTicker\",\"data\":{\"e\":\"bookTicker\",\"u\":11478222845146,\"s\":\"BTCUSDT\",\"ps\":\"BTCUSDT\",\"b\":\"79607.10\",\"B\":\"9.751\",\"a\":\"79607.20\",\"A\":\"1.676\",\"T\":1788563199095,\"E\":1788563199095,\"st\":1}}"}
{"receive_ns":1788563199061844000,"stream":"btcusdt@bookTicker","event_type":"bookTicker","event_time_ms":1788563199096,"raw_json":"{\"stream\":\"btcusdt@bookTicker\",\"data\":{\"e\":\"bookTicker\",\"u\":11478222845236,\"s\":\"BTCUSDT\",\"ps\":\"BTCUSDT\",\"b\":\"79607.10\",\"B\":\"9.732\",\"a\":\"79607.20\",\"A\":\"1.676\",\"T\":1788563199095,\"E\":1788563199096,\"st\":1}}"}
{"receive_ns":1788563199061996000,"stream":"btcusdt@bookTicker","event_type":"bookTicker","event_time_ms":1788563199096,"raw_json":"{\"stream\":\"btcusdt@bookTicker\",\"data\":{\"e\":\"bookTicker\",\"u\":11478222845239,\"s\":\"BTCUSDT\",\"ps\":\"BTCUSDT\",\"b\":\"79607.10\",\"B\":\"9.724\",\"a\":\"79607.20\",\"A\":\"1.676\",\"T\":1788563199095,\"E\":1788563199096,\"st\":1}}"}
{"receive_ns":1788563199128245000,"stream":"btcusdt@bookTicker","event_type":"bookTicker","event_time_ms":1788563199162,"raw_json":"{\"stream\":\"btcusdt@bookTicker\",\"data\":{\"e\":\"bookTicker\",\"u\":11478222849800,\"s\":\"BTCUSDT\",\"ps\":\"BTCUSDT\",\"b\":\"79607.10\",\"B\":\"9.721\",\"a\":\"79607.20\",\"A\":\"1.676\",\"T\":1788563199162,\"E\":1788563199162,\"st\":1}}"}
{"receive_ns":1788563199140198000,"stream":"btcusdt@depth@100ms","event_type":"depthUpdate","event_time_ms":1788563199175,"raw_json":"{\"stream\":\"btcusdt@depth@100ms\",\"data\":{\"e\":\"depthUpdate\",\"E\":1788563199175,\"T\":1788563199173,\"s\":\"BTCUSDT\",\"ps\":\"BTCUSDT\",\"U\":11478222843946,\"u\":11478222850434,\"pu\":11478222843879,\"b\":[[\"1000.00\",\"24.604\"],[\"29107.10\",\"0.448\"],[\"29207.10\",\"1.652\"],[\"63686.00\",\"0.002\"],[\"71646.30\",\"0.002\"],[\"75626.70\",\"0.021\"],[\"78015.00\",\"0.122\"],[\"78394.60\",\"0.028\"],[\"78474.10\",\"0.007\"],[\"78479.30\",\"14.099\"],[\"78811.00\",\"4.126\"],[\"79209.10\",\"1.777\"],[\"79236.90\",\"0.247\"],[\"79434.00\",\"1.129\"],[\"79481.50\",\"0.000\"],[\"79487.70\",\"2.009\"],[\"79491.70\",\"0.075\"],[\"79538.40\",\"4.183\"],[\"79579.80\",\"0.254\"],[\"79582.20\",\"0.440\"],[\"79600.40\",\"0.043\"],[\"79600.60\",\"0.179\"],[\"79601.60\",\"0.000\"],[\"79602.20\",\"0.047\"],[\"79602.30\",\"0.276\"],[\"79604.00\",\"0.003\"],[\"79604.10\",\"0.000\"],[\"79604.30\",\"0.279\"],[\"79605.20\",\"0.028\"],[\"79605.40\",\"0.035\"],[\"79605.60\",\"0.108\"],[\"79606.20\",\"0.027\"],[\"79607.10\",\"9.721\"]],\"a\":[[\"79609.20\",\"0.701\"],[\"79611.20\",\"0.090\"],[\"79696.40\",\"1.949\"],[\"79730.80\",\"0.001\"],[\"79973.40\",\"1.913\"],[\"80000.40\",\"2.121\"],[\"80403.30\",\"7.987\"],[\"80593.20\",\"2.314\"],[\"80740.00\",\"5.063\"]],\"st\":1}}"}
{"receive_ns":1788563199158069000,"stream":"btcusdt@bookTicker","event_type":"bookTicker","event_time_ms":1788563199192,"raw_json":"{\"stream\":\"btcusdt@bookTicker\",\"data\":{\"e\":\"bookTicker\",\"u\":11478222851560,\"s\":\"BTCUSDT\",\"ps\":\"BTCUSDT\",\"b\":\"79607.10\",\"B\":\"9.505\",\"a\":\"79607.20\",\"A\":\"1.676\",\"T\":1788563199192,\"E\":1788563199192,\"st\":1}}"}
{"receive_ns":1788563199160025000,"stream":"btcusdt@bookTicker","event_type":"bookTicker","event_time_ms":1788563199195,"raw_json":"{\"stream\":\"btcusdt@bookTicker\",\"data\":{\"e\":\"bookTicker\",\"u\":11478222851757,\"s\":\"BTCUSDT\",\"ps\":\"BTCUSDT\",\"b\":\"79607.10\",\"B\":\"9.733\",\"a\":\"79607.20\",\"A\":\"1.676\",\"T\":1788563199195,\"E\":1788563199195,\"st\":1}}"}
{"receive_ns":1788563199230600000,"stream":"btcusdt@bookTicker","event_type":"bookTicker","event_time_ms":1788563199266,"raw_json":"{\"stream\":\"btcusdt@bookTicker\",\"data\":{\"e\":\"bookTicker\",\"u\":11478222856086,\"s\":\"BTCUSDT\",\"ps\":\"BTCUSDT\",\"b\":\"79607.10\",\"B\":\"9.397\",\"a\":\"79607.20\",\"A\":\"1.676\",\"T\":1788563199266,\"E\":1788563199266,\"st\":1}}"}
{"receive_ns":1788563199231843000,"stream":"btcusdt@bookTicker","event_type":"bookTicker","event_time_ms":1788563199268,"raw_json":"{\"stream\":\"btcusdt@bookTicker\",\"data\":{\"e\":\"bookTicker\",\"u\":11478222856249,\"s\":\"BTCUSDT\",\"ps\":\"BTCUSDT\",\"b\":\"79607.10\",\"B\":\"9.735\",\"a\":\"79607.20\",\"A\":\"1.676\",\"T\":1788563199268,\"E\":1788563199268,\"st\":1}}"}
{"receive_ns":1788563199239850000,"stream":"btcusdt@depth@100ms","event_type":"depthUpdate","event_time_ms":1788563199277,"raw_json":"{\"stream\":\"btcusdt@depth@100ms\",\"data\":{\"e\":\"depthUpdate\",\"E\":1788563199277,\"T\":1788563199273,\"s\":\"BTCUSDT\",\"ps\":\"BTCUSDT\",\"U\":11478222850528,\"u\":11478222856541,\"pu\":11478222850434,\"b\":[[\"29107.10\",\"0.623\"],[\"29207.10\",\"1.477\"],[\"71646.30\",\"0.002\"],[\"76422.80\",\"0.002\"],[\"78811.00\",\"4.126\"],[\"79209.10\",\"1.777\"],[\"79434.00\",\"1.129\"],[\"79442.10\",\"2.289\"],[\"79443.60\",\"0.860\"],[\"79481.50\",\"0.663\"],[\"79487.70\",\"2.009\"],[\"79593.50\",\"0.033\"],[\"79602.30\",\"0.200\"],[\"79604.20\",\"0.000\"],[\"79606.20\",\"0.001\"],[\"79606.40\",\"0.082\"],[\"79607.10\",\"9.735\"]],\"a\":[[\"79730.70\",\"0.953\"],[\"79770.10\",\"1.955\"],[\"79770.20\",\"0.600\"],[\"79973.40\",\"1.913\"],[\"80403.30\",\"7.987\"],[\"80740.00\",\"5.070\"],[\"80819.60\",\"0.020\"]],\"st\":1}}"}
{"receive_ns":1788563199342763000,"stream":"btcusdt@depth@100ms","event_type":"depthUpdate","event_time_ms":1788563199379,"raw_json":"{\"stream\":\"btcusdt@depth@100ms\",\"data\":{\"e\":\"depthUpdate\",\"E\":1788563199379,\"T\":1788563199377,\"s\":\"BTCUSDT\",\"ps\":\"BTCUSDT\",\"U\":11478222856782,\"u\":11478222863557,\"pu\":11478222856541,\"b\":[[\"1000.00\",\"24.604\"],[\"29107.10\",\"0.805\"],[\"29207.10\",\"1.295\"],[\"71646.30\",\"0.002\"],[\"76422.80\",\"0.000\"],[\"78811.00\",\"4.126\"],[\"79209.10\",\"1.777\"],[\"79236.90\",\"0.247\"],[\"79434.00\",\"0.678\"],[\"79487.70\",\"2.209\"],[\"79491.70\",\"0.326\"],[\"79492.40\",\"0.074\"]],\"a\":[[\"79609.20\",\"0.502\"],[\"79611.20\",\"0.289\"],[\"79630.00\",\"3.512\"],[\"79973.40\",\"1.913\"],[\"80005.20\",\"2.132\"],[\"80403.30\",\"7.987\"],[\"80562.50\",\"18.101\"],[\"80602.30\",\"4.025\"],[\"81199.30\",\"0.033\"]],\"st\":1}}"}
{"receive_ns":1788563199364361000,"stream":"btcusdt@bookTicker","event_type":"bookTicker","event_time_ms":1788563199399,"raw_json":"{\"stream\":\"btcusdt@bookTicker\",\"data\":{\"e\":\"bookTicker\",\"u\":11478222865282,\"s\":\"BTCUSDT\",\"ps\":\"BTCUSDT\",\"b\":\"79607.10\",\"B\":\"9.539\",\"a\":\"79607.20\",\"A\":\"1.676\",\"T\":1788563199399,\"E\":1788563199399,\"st\":1}}"}
{"receive_ns":1788563199366928000,"stream":"btcusdt@bookTicker","event_type":"bookTicker","event_time_ms":1788563199402,"raw_json":"{\"stream\":\"btcusdt@bookTicker\",\"data\":{\"e\":\"bookTicker\",\"u\":11478222865528,\"s\":\"BTCUSDT\",\"ps\":\"BTCUSDT\",\"b\":\"79607.10\",\"B\":\"9.738\",\"a\":\"79607.20\",\"A\":\"1.676\",\"T\":1788563199402,\"E\":1788563199402,\"st\":1}}"}
{"receive_ns":1788563199433638000,"stream":"btcusdt@bookTicker","event_type":"bookTicker","event_time_ms":1788563199460,"raw_json":"{\"stream\":\"btcusdt@bookTicker\",\"data\":{\"e\":\"bookTicker\",\"u\":11478222869565,\"s\":\"BTCUSDT\",\"ps\":\"BTCUSDT\",\"b\":\"79607.10\",\"B\":\"9.738\",\"a\":\"79607.20\",\"A\":\"1.678\",\"T\":1788563199460,\"E\":1788563199460,\"st\":1}}"}
{"receive_ns":1788563199447077000,"stream":"btcusdt@depth@100ms","event_type":"depthUpdate","event_time_ms":1788563199481,"raw_json":"{\"stream\":\"btcusdt@depth@100ms\",\"data\":{\"e\":\"depthUpdate\",\"E\":1788563199481,\"T\":1788563199477,\"s\":\"BTCUSDT\",\"ps\":\"BTCUSDT\",\"U\":11478222863753,\"u\":11478222870539,\"pu\":11478222863557,\"b\":[[\"1000.00\",\"24.604\"],[\"29107.10\",\"0.980\"],[\"29207.10\",\"1.120\"],[\"71646.30\",\"0.002\"],[\"76422.80\",\"0.002\"],[\"78226.00\",\"0.003\"],[\"78603.10\",\"6.841\"],[\"78811.00\",\"4.126\"],[\"79209.00\",\"0.000\"],[\"79209.10\",\"1.787\"],[\"79481.50\",\"0.601\"],[\"79487.70\",\"1.205\"],[\"79492.40\",\"0.106\"],[\"79515.30\",\"0.830\"],[\"79516.10\",\"2.992\"],[\"79531.20\",\"0.692\"],[\"79593.00\",\"0.000\"],[\"79594.70\",\"0.013\"],[\"79607.10\",\"9.738\"]],\"a\":[[\"79607.20\",\"1.678\"],[\"79698.00\",\"4.202\"],[\"79730.70\",\"0.891\"],[\"79741.00\",\"0.012\"],[\"79828.70\",\"9.619\"],[\"79828.80\",\"0.000\"],[\"79973.40\",\"1.388\"],[\"80403.30\",\"7.987\"]],\"st\":1}}"}
{"receive_ns":1788563199465595000,"stream":"btcusdt@bookTicker","event_type":"bookTicker","event_time_ms":1788563199499,"raw_json":"{\"stream\":\"btcusdt@bookTicker\",\"data\":{\"e\":\"bookTicker\",\"u\":11478222871916,\"s\":\"BTCUSDT\",\"ps\":\"BTCUSDT\",\"b\":\"79607.10\",\"B\":\"9.423\",\"a\":\"79607.20\",\"A\":\"1.678\",\"T\":1788563199499,\"E\":1788563199499,\"st\":1}}"}
{"receive_ns":1788563199466892000,"stream":"btcusdt@bookTicker","event_type":"bookTicker","event_time_ms":1788563199502,"raw_json":"{\"stream\":\"btcusdt@bookTicker\",\"data\":{\"e\":\"bookTicker\",\"u\":11478222872183,\"s\":\"BTCUSDT\",\"ps\":\"BTCUSDT\",\"b\":\"79607.10\",\"B\":\"9.773\",\"a\":\"79607.20\",\"A\":\"1.678\",\"T\":1788563199502,\"E\":1788563199502,\"st\":1}}"}
{"receive_ns":1788563199472397000,"stream":"btcusdt@bookTicker","event_type":"bookTicker","event_time_ms":1788563199508,"raw_json":"{\"stream\":\"btcusdt@bookTicker\",\"data\":{\"e\":\"bookTicker\",\"u\":11478222872609,\"s\":\"BTCUSDT\",\"ps\":\"BTCUSDT\",\"b\":\"79607.10\",\"B\":\"9.773\",\"a\":\"79607.20\",\"A\":\"1.652\",\"T\":1788563199508,\"E\":1788563199508,\"st\":1}}"}
{"receive_ns":1788563199473635000,"stream":"btcusdt@bookTicker","event_type":"bookTicker","event_time_ms":1788563199510,"raw_json":"{\"stream\":\"btcusdt@bookTicker\",\"data\":{\"e\":\"bookTicker\",\"u\":11478222872710,\"s\":\"BTCUSDT\",\"ps\":\"BTCUSDT\",\"b\":\"79607.10\",\"B\":\"9.792\",\"a\":\"79607.20\",\"A\":\"1.652\",\"T\":1788563199509,\"E\":1788563199510,\"st\":1}}"}
{"receive_ns":1788563199473804000,"stream":"btcusdt@bookTicker","event_type":"bookTicker","event_time_ms":1788563199510,"raw_json":"{\"stream\":\"btcusdt@bookTicker\",\"data\":{\"e\":\"bookTicker\",\"u\":11478222872715,\"s\":\"BTCUSDT\",\"ps\":\"BTCUSDT\",\"b\":\"79607.10\",\"B\":\"9.800\",\"a\":\"79607.20\",\"A\":\"1.652\",\"T\":1788563199509,\"E\":1788563199510,\"st\":1}}"}
{"receive_ns":1788563199474007000,"stream":"btcusdt@bookTicker","event_type":"bookTicker","event_time_ms":1788563199510,"raw_json":"{\"stream\":\"btcusdt@bookTicker\",\"data\":{\"e\":\"bookTicker\",\"u\":11478222872780,\"s\":\"BTCUSDT\",\"ps\":\"BTCUSDT\",\"b\":\"79607.10\",\"B\":\"9.781\",\"a\":\"79607.20\",\"A\":\"1.652\",\"T\":1788563199510,\"E\":1788563199510,\"st\":1}}"}
{"receive_ns":1788563199474153000,"stream":"btcusdt@bookTicker","event_type":"bookTicker","event_time_ms":1788563199510,"raw_json":"{\"stream\":\"btcusdt@bookTicker\",\"data\":{\"e\":\"bookTicker\",\"u\":11478222872783,\"s\":\"BTCUSDT\",\"ps\":\"BTCUSDT\",\"b\":\"79607.10\",\"B\":\"9.773\",\"a\":\"79607.20\",\"A\":\"1.652\",\"T\":1788563199510,\"E\":1788563199510,\"st\":1}}"}
{"receive_ns":1788563199474299000,"stream":"btcusdt@bookTicker","event_type":"bookTicker","event_time_ms":1788563199511,"raw_json":"{\"stream\":\"btcusdt@bookTicker\",\"data\":{\"e\":\"bookTicker\",\"u\":11478222872801,\"s\":\"BTCUSDT\",\"ps\":\"BTCUSDT\",\"b\":\"79607.10\",\"B\":\"9.771\",\"a\":\"79607.20\",\"A\":\"1.652\",\"T\":1788563199510,\"E\":1788563199511,\"st\":1}}"}
{"receive_ns":1788563199510238000,"stream":"btcusdt@bookTicker","event_type":"bookTicker","event_time_ms":1788563199545,"raw_json":"{\"stream\":\"btcusdt@bookTicker\",\"data\":{\"e\":\"bookTicker\",\"u\":11478222874469,\"s\":\"BTCUSDT\",\"ps\":\"BTCUSDT\",\"b\":\"79607.10\",\"B\":\"9.790\",\"a\":\"79607.20\",\"A\":\"1.652\",\"T\":1788563199545,\"E\":1788563199545,\"st\":1}}"}
{"receive_ns":1788563199510487000,"stream":"btcusdt@bookTicker","event_type":"bookTicker","event_time_ms":1788563199545,"raw_json":"{\"stream\":\"btcusdt@bookTicker\",\"data\":{\"e\":\"bookTicker\",\"u\":11478222874500,\"s\":\"BTCUSDT\",\"ps\":\"BTCUSDT\",\"b\":\"79607.10\",\"B\":\"9.771\",\"a\":\"79607.20\",\"A\":\"1.652\",\"T\":1788563199545,\"E\":1788563199545,\"st\":1}}"}
{"receive_ns":1788563199510639000,"stream":"btcusdt@bookTicker","event_type":"bookTicker","event_time_ms":1788563199546,"raw_json":"{\"stream\":\"btcusdt@bookTicker\",\"data\":{\"e\":\"bookTicker\",\"u\":11478222874518,\"s\":\"BTCUSDT\",\"ps\":\"BTCUSDT\",\"b\":\"79607.10\",\"B\":\"9.773\",\"a\":\"79607.20\",\"A\":\"1.652\",\"T\":1788563199546,\"E\":1788563199546,\"st\":1}}"}
{"receive_ns":1788563199592392000,"stream":"btcusdt@depth@100ms","event_type":"depthUpdate","event_time_ms":1788563199583,"raw_json":"{\"stream\":\"btcusdt@depth@100ms\",\"data\":{\"e\":\"depthUpdate\",\"E\":1788563199583,\"T\":1788563199582,\"s\":\"BTCUSDT\",\"ps\":\"BTCUSDT\",\"U\":11478222870727,\"u\":11478222876449,\"pu\":11478222870539,\"b\":[[\"29107.10\",\"1.162\"],[\"29207.10\",\"0.938\"],[\"71646.30\",\"0.002\"],[\"75626.70\",\"0.023\"],[\"76422.80\",\"0.000\"],[\"78174.20\",\"0.524\"],[\"78589.80\",\"0.000\"],[\"78599.60\",\"0.003\"],[\"78686.90\",\"3.936\"],[\"78811.00\",\"4.126\"],[\"79209.10\",\"1.646\"],[\"79236.90\",\"0.015\"],[\"79434.00\",\"0.076\"],[\"79453.90\",\"0.706\"],[\"79457.20\",\"0.000\"],[\"79471.70\",\"0.040\"],[\"79487.70\",\"0.001\"],[\"79491.70\",\"1.004\"],[\"79531.20\",\"0.001\"],[\"79535.40\",\"0.002\"],[\"79599.80\",\"0.002\"],[\"79600.60\",\"0.078\"],[\"79600.70\",\"0.003\"],[\"79601.00\",\"0.349\"],[\"79601.60\",\"0.000\"],[\"79601.70\",\"0.404\"],[\"79602.20\",\"0.046\"],[\"79602.40\",\"0.059\"],[\"79603.10\",\"1.407\"],[\"79604.30\",\"0.253\"],[\"79605.90\",\"0.026\"],[\"79606.40\",\"0.108\"],[\"79607.00\",\"0.033\"],[\"79607.10\",\"9.773\"]],\"a\":[[\"79607.20\",\"1.652\"],[\"79607.90\",\"0.076\"],[\"79608.00\",\"0.003\"],[\"79608.20\",\"0.253\"],[\"79608.60\",\"0.026\"],[\"79608.80\",\"0.027\"],[\"79609.20\",\"0.000\"],[\"79609.30\",\"0.027\"],[\"79610.00\",\"0.004\"],[\"79610.10\",\"0.001\"],[\"79611.20\",\"0.000\"],[\"79617.50\",\"0.954\"],[\"79617.70\",\"0.807\"],[\"79663.00\",\"0.002\"],[\"79973.40\",\"0.950\"],[\"80005.30\",\"0.003\"],[\"80403.30\",\"7.987\"],[\"81199.30\",\"0.030\"]],\"st\":1}}"}
{"receive_ns":1788563199592678000,"stream":"btcusdt@bookTicker","event_type":"bookTicker","event_time_ms":1788563199596,"raw_json":"{\"stream\":\"btcusdt@bookTicker\",\"data\":{\"e\":\"bookTicker\",\"u\":11478222877150,\"s\":\"BTCUSDT\",\"ps\":\"BTCUSDT\",\"b\":\"79607.10\",\"B\":\"9.792\",\"a\":\"79607.20\",\"A\":\"1.652\",\"T\":1788563199596,\"E\":1788563199596,\"st\":1}}"}
{"receive_ns":1788563199592851000,"stream":"btcusdt@bookTicker","event_type":"bookTicker","event_time_ms":1788563199596,"raw_json":"{\"stream\":\"btcusdt@bookTicker\",\"data\":{\"e\":\"bookTicker\",\"u\":11478222877184,\"s\":\"BTCUSDT\",\"ps\":\"BTCUSDT\",\"b\":\"79607.10\",\"B\":\"9.773\",\"a\":\"79607.20\",\"A\":\"1.652\",\"T\":1788563199596,\"E\":1788563199596,\"st\":1}}"}
{"receive_ns":1788563199593019000,"stream":"btcusdt@bookTicker","event_type":"bookTicker","event_time_ms":1788563199616,"raw_json":"{\"stream\":\"btcusdt@bookTicker\",\"data\":{\"e\":\"bookTicker\",\"u\":11478222878180,\"s\":\"BTCUSDT\",\"ps\":\"BTCUSDT\",\"b\":\"79607.10\",\"B\":\"9.792\",\"a\":\"79607.20\",\"A\":\"1.652\",\"T\":1788563199615,\"E\":1788563199616,\"st\":1}}"}
{"receive_ns":1788563199593189000,"stream":"btcusdt@bookTicker","event_type":"bookTicker","event_time_ms":1788563199616,"raw_json":"{\"stream\":\"btcusdt@bookTicker\",\"data\":{\"e\":\"bookTicker\",\"u\":11478222878214,\"s\":\"BTCUSDT\",\"ps\":\"BTCUSDT\",\"b\":\"79607.10\",\"B\":\"9.800\",\"a\":\"79607.20\",\"A\":\"1.652\",\"T\":1788563199616,\"E\":1788563199616,\"st\":1}}"}
{"receive_ns":1788563199593355000,"stream":"btcusdt@bookTicker","event_type":"bookTicker","event_time_ms":1788563199616,"raw_json":"{\"stream\":\"btcusdt@bookTicker\",\"data\":{\"e\":\"bookTicker\",\"u\":11478222878238,\"s\":\"BTCUSDT\",\"ps\":\"BTCUSDT\",\"b\":\"79607.10\",\"B\":\"9.781\",\"a\":\"79607.20\",\"A\":\"1.652\",\"T\":1788563199616,\"E\":1788563199616,\"st\":1}}"}
{"receive_ns":1788563199593550000,"stream":"btcusdt@bookTicker","event_type":"bookTicker","event_time_ms":1788563199617,"raw_json":"{\"stream\":\"btcusdt@bookTicker\",\"data\":{\"e\":\"bookTicker\",\"u\":11478222878283,\"s\":\"BTCUSDT\",\"ps\":\"BTCUSDT\",\"b\":\"79607.10\",\"B\":\"9.773\",\"a\":\"79607.20\",\"A\":\"1.652\",\"T\":1788563199617,\"E\":1788563199617,\"st\":1}}"}
{"receive_ns":1788563199611367000,"stream":"btcusdt@bookTicker","event_type":"bookTicker","event_time_ms":1788563199645,"raw_json":"{\"stream\":\"btcusdt@bookTicker\",\"data\":{\"e\":\"bookTicker\",\"u\":11478222879519,\"s\":\"BTCUSDT\",\"ps\":\"BTCUSDT\",\"b\":\"79607.10\",\"B\":\"9.776\",\"a\":\"79607.20\",\"A\":\"1.652\",\"T\":1788563199645,\"E\":1788563199645,\"st\":1}}"}
{"receive_ns":1788563199651003000,"stream":"btcusdt@depth@100ms","event_type":"depthUpdate","event_time_ms":1788563199685,"raw_json":"{\"stream\":\"btcusdt@depth@100ms\",\"data\":{\"e\":\"depthUpdate\",\"E\":1788563199685,\"T\":1788563199684,\"s\":\"BTCUSDT\",\"ps\":\"BTCUSDT\",\"U\":11478222876522,\"u\":11478222881962,\"pu\":11478222876449,\"b\":[[\"1000.00\",\"24.604\"],[\"29107.10\",\"1.337\"],[\"29207.10\",\"0.763\"],[\"71646.30\",\"0.002\"],[\"71681.00\",\"0.000\"],[\"78811.00\",\"4.126\"],[\"79209.10\",\"1.787\"],[\"79236.90\",\"0.247\"],[\"79434.00\",\"1.431\"],[\"79453.90\",\"0.906\"],[\"79487.70\",\"0.076\"],[\"79524.70\",\"1.302\"],[\"79602.20\",\"0.047\"],[\"79602.40\",\"0.058\"],[\"79603.10\",\"1.331\"],[\"79606.90\",\"0.032\"],[\"79607.00\",\"0.007\"],[\"79607.10\",\"9.776\"]],\"a\":[[\"79607.40\",\"0.102\"],[\"79607.50\",\"0.026\"],[\"79608.40\",\"0.275\"],[\"79608.50\",\"0.026\"],[\"79609.20\",\"0.251\"],[\"79609.50\",\"0.005\"],[\"79609.60\",\"0.000\"],[\"79609.80\",\"0.000\"],[\"79611.20\",\"0.341\"],[\"79619.00\",\"0.194\"],[\"79620.40\",\"0.439\"],[\"79620.50\",\"2.058\"],[\"79621.40\",\"0.260\"],[\"79973.40\",\"1.913\"],[\"80403.30\",\"7.987\"]],\"st\":1}}"}
{"receive_ns":1788563199752242000,"stream":"btcusdt@depth@100ms","event_type":"depthUpdate","event_time_ms":1788563199787,"raw_json":"{\"stream\":\"btcusdt@depth@100ms\",\"data\":{\"e\":\"depthUpdate\",\"E\":1788563199787,\"T\":1788563199786,\"s\":\"BTCUSDT\",\"ps\":\"BTCUSDT\",\"U\":11478222882054,\"u\":11478222887707,\"pu\":11478222881962,\"b\":[[\"1000.00\",\"24.604\"],[\"29107.10\",\"1.519\"],[\"29207.10\",\"0.581\"],[\"71646.30\",\"0.002\"],[\"76422.80\",\"0.002\"],[\"78476.70\",\"0.460\"],[\"78811.00\",\"4.126\"],[\"79209.10\",\"1.777\"],[\"79453.90\",\"0.906\"],[\"79487.70\",\"1.080\"],[\"79491.70\",\"0.000\"]],\"a\":[[\"79973.40\",\"1.913\"],[\"80403.30\",\"7.987\"],[\"81199.30\",\"0.027\"]],\"st\":1}}"}
{"receive_ns":1788563199809967000,"stream":"btcusdt@bookTicker","event_type":"bookTicker","event_time_ms":1788563199843,"raw_json":"{\"stream\":\"btcusdt@bookTicker\",\"data\":{\"e\":\"bookTicker\",\"u\":11478222890530,\"s\":\"BTCUSDT\",\"ps\":\"BTCUSDT\",\"b\":\"79607.10\",\"B\":\"9.776\",\"a\":\"79607.20\",\"A\":\"1.651\",\"T\":1788563199842,\"E\":1788563199843,\"st\":1}}"}
{"receive_ns":1788563199854543000,"stream":"btcusdt@depth@100ms","event_type":"depthUpdate","event_time_ms":1788563199889,"raw_json":"{\"stream\":\"btcusdt@depth@100ms\",\"data\":{\"e\":\"depthUpdate\",\"E\":1788563199889,\"T\":1788563199888,\"s\":\"BTCUSDT\",\"ps\":\"BTCUSDT\",\"U\":11478222887822,\"u\":11478222892629,\"pu\":11478222887707,\"b\":[[\"29107.10\",\"1.694\"],[\"29207.10\",\"0.406\"],[\"71646.30\",\"0.002\"],[\"76422.80\",\"0.000\"],[\"78101.20\",\"0.019\"],[\"78811.00\",\"4.126\"],[\"79209.00\",\"0.001\"],[\"79209.10\",\"1.777\"],[\"79236.90\",\"0.247\"],[\"79434.00\",\"0.427\"],[\"79453.90\",\"0.706\"],[\"79481.50\",\"0.537\"],[\"79487.70\",\"2.284\"],[\"79516.10\",\"2.973\"]],\"a\":[[\"79607.20\",\"1.651\"],[\"79609.20\",\"0.251\"],[\"79611.20\",\"0.540\"],[\"79621.70\",\"0.005\"],[\"79698.00\",\"4.193\"],[\"79730.60\",\"0.290\"],[\"79730.70\",\"0.601\"],[\"79828.70\",\"9.647\"],[\"79973.40\",\"1.913\"],[\"80005.30\",\"0.002\"],[\"80403.30\",\"7.989\"],[\"80761.50\",\"2.782\"]],\"st\":1}}"}
{"receive_ns":1788563199927996000,"stream":"btcusdt@bookTicker","event_type":"bookTicker","event_time_ms":1788563199963,"raw_json":"{\"stream\":\"btcusdt@bookTicker\",\"data\":{\"e\":\"bookTicker\",\"u\":11478222896889,\"s\":\"BTCUSDT\",\"ps\":\"BTCUSDT\",\"b\":\"79607.10\",\"B\":\"9.776\",\"a\":\"79607.20\",\"A\":\"1.650\",\"T\":1788563199963,\"E\":1788563199963,\"st\":1}}"}
{"receive_ns":1788563199955328000,"stream":"btcusdt@depth@100ms","event_type":"depthUpdate","event_time_ms":1788563199991,"raw_json":"{\"stream\":\"btcusdt@depth@100ms\",\"data\":{\"e\":\"depthUpdate\",\"E\":1788563199991,\"T\":1788563199990,\"s\":\"BTCUSDT\",\"ps\":\"BTCUSDT\",\"U\":11478222892688,\"u\":11478222898091,\"pu\":11478222892629,\"b\":[[\"1000.00\",\"24.604\"],[\"29107.10\",\"1.792\"],[\"29207.10\",\"0.266\"],[\"29507.10\",\"0.042\"],[\"71646.30\",\"0.002\"],[\"76422.80\",\"0.002\"],[\"76790.00\",\"0.370\"],[\"78015.00\",\"0.125\"],[\"78612.00\",\"2.046\"],[\"78811.00\",\"4.126\"],[\"79453.90\",\"0.204\"],[\"79487.70\",\"1.280\"],[\"79491.70\",\"1.004\"],[\"79583.40\",\"1.875\"],[\"79592.20\",\"0.007\"],[\"79594.70\",\"0.007\"],[\"79606.90\",\"0.006\"]],\"a\":[[\"79607.20\",\"1.650\"],[\"79611.20\",\"0.341\"],[\"79623.30\",\"0.045\"],[\"79973.40\",\"1.494\"],[\"80403.30\",\"7.987\"],[\"80557.60\",\"13.057\"]],\"st\":1}}"}
{"receive_ns":1788563200058325000,"stream":"btcusdt@depth@100ms","event_type":"depthUpdate","event_time_ms":1788563200093,"raw_json":"{\"stream\":\"btcusdt@depth@100ms\",\"data\":{\"e\":\"depthUpdate\",\"E\":1788563200093,\"T\":1788563200092,\"s\":\"BTCUSDT\",\"ps\":\"BTCUSDT\",\"U\":11478222898162,\"u\":11478222903565,\"pu\":11478222898091,\"b\":[[\"1000.00\",\"24.604\"],[\"29107.10\",\"1.855\"],[\"29207.10\",\"0.147\"],[\"29507.10\",\"0.098\"],[\"63685.70\",\"0.001\"],[\"71646.30\",\"0.002\"],[\"78134.40\",\"1.660\"],[\"78439.50\",\"9.508\"],[\"78603.10\",\"6.556\"],[\"78638.50\",\"16.612\"],[\"78811.00\",\"4.126\"],[\"78970.20\",\"2.275\"],[\"79209.10\",\"1.636\"],[\"79236.90\",\"0.015\"],[\"79434.00\",\"0.076\"],[\"79453.90\",\"0.706\"],[\"79487.70\",\"1.205\"],[\"79532.70\",\"0.001\"],[\"79533.10\",\"0.050\"],[\"79592.80\",\"0.003\"]],\"a\":[[\"79607.30\",\"0.029\"],[\"79607.40\",\"0.128\"],[\"79609.20\",\"0.000\"],[\"79609.40\",\"0.080\"],[\"79609.50\",\"0.007\"],[\"79611.20\",\"0.199\"],[\"79660.10\",\"0.002\"],[\"79660.50\",\"0.497\"],[\"79973.40\",\"1.713\"],[\"80403.30\",\"7.987\"],[\"80729.70\",\"1.977\"]],\"st\":1}}"}
{"receive_ns":1788563200061889000,"stream":"btcusdt@bookTicker","event_type":"bookTicker","event_time_ms":1788563200096,"raw_json":"{\"stream\":\"btcusdt@bookTicker\",\"data\":{\"e\":\"bookTicker\",\"u\":11478222903925,\"s\":\"BTCUSDT\",\"ps\":\"BTCUSDT\",\"b\":\"79607.10\",\"B\":\"9.773\",\"a\":\"79607.20\",\"A\":\"1.650\",\"T\":1788563200095,\"E\":1788563200096,\"st\":1}}"}
{"receive_ns":1788563200062207000,"stream":"btcusdt@trade","event_type":"trade","event_time_ms":1788563200096,"raw_json":"{\"stream\":\"btcusdt@trade\",\"data\":{\"e\":\"trade\",\"E\":1788563200096,\"T\":1788563200095,\"s\":\"BTCUSDT\",\"t\":8054082684,\"p\":\"79607.10\",\"q\":\"0.003\",\"X\":\"MARKET\",\"m\":true,\"st\":1}}"}
{"receive_ns":1788563200062496000,"stream":"btcusdt@bookTicker","event_type":"bookTicker","event_time_ms":1788563200097,"raw_json":"{\"stream\":\"btcusdt@bookTicker\",\"data\":{\"e\":\"bookTicker\",\"u\":11478222904095,\"s\":\"BTCUSDT\",\"ps\":\"BTCUSDT\",\"b\":\"79607.10\",\"B\":\"9.781\",\"a\":\"79607.20\",\"A\":\"1.650\",\"T\":1788563200097,\"E\":1788563200097,\"st\":1}}"}
{"receive_ns":1788563200062659000,"stream":"btcusdt@bookTicker","event_type":"bookTicker","event_time_ms":1788563200097,"raw_json":"{\"stream\":\"btcusdt@bookTicker\",\"data\":{\"e\":\"bookTicker\",\"u\":11478222904096,\"s\":\"BTCUSDT\",\"ps\":\"BTCUSDT\",\"b\":\"79607.10\",\"B\":\"9.800\",\"a\":\"79607.20\",\"A\":\"1.650\",\"T\":1788563200097,\"E\":1788563200097,\"st\":1}}"}
{"receive_ns":1788563200063217000,"stream":"btcusdt@bookTicker","event_type":"bookTicker","event_time_ms":1788563200098,"raw_json":"{\"stream\":\"btcusdt@bookTicker\",\"data\":{\"e\":\"bookTicker\",\"u\":11478222904193,\"s\":\"BTCUSDT\",\"ps\":\"BTCUSDT\",\"b\":\"79607.10\",\"B\":\"9.753\",\"a\":\"79607.20\",\"A\":\"1.650\",\"T\":1788563200098,\"E\":1788563200098,\"st\":1}}"}
{"receive_ns":1788563200063380000,"stream":"btcusdt@bookTicker","event_type":"bookTicker","event_time_ms":1788563200098,"raw_json":"{\"stream\":\"btcusdt@bookTicker\",\"data\":{\"e\":\"bookTicker\",\"u\":11478222904196,\"s\":\"BTCUSDT\",\"ps\":\"BTCUSDT\",\"b\":\"79607.10\",\"B\":\"9.753\",\"a\":\"79607.20\",\"A\":\"1.627\",\"T\":1788563200098,\"E\":1788563200098,\"st\":1}}"}
{"receive_ns":1788563200064286000,"stream":"btcusdt@bookTicker","event_type":"bookTicker","event_time_ms":1788563200098,"raw_json":"{\"stream\":\"btcusdt@bookTicker\",\"data\":{\"e\":\"bookTicker\",\"u\":11478222904212,\"s\":\"BTCUSDT\",\"ps\":\"BTCUSDT\",\"b\":\"79607.10\",\"B\":\"9.745\",\"a\":\"79607.20\",\"A\":\"1.627\",\"T\":1788563200098,\"E\":1788563200098,\"st\":1}}"}
{"receive_ns":1788563200064456000,"stream":"btcusdt@bookTicker","event_type":"bookTicker","event_time_ms":1788563200098,"raw_json":"{\"stream\":\"btcusdt@bookTicker\",\"data\":{\"e\":\"bookTicker\",\"u\":11478222904215,\"s\":\"BTCUSDT\",\"ps\":\"BTCUSDT\",\"b\":\"79607.10\",\"B\":\"9.726\",\"a\":\"79607.20\",\"A\":\"1.627\",\"T\":1788563200098,\"E\":1788563200098,\"st\":1}}"}
{"receive_ns":1788563200098809000,"stream":"btcusdt@bookTicker","event_type":"bookTicker","event_time_ms":1788563200134,"raw_json":"{\"stream\":\"btcusdt@bookTicker\",\"data\":{\"e\":\"bookTicker\",\"u\":11478222906461,\"s\":\"BTCUSDT\",\"ps\":\"BTCUSDT\",\"b\":\"79607.10\",\"B\":\"9.745\",\"a\":\"79607.20\",\"A\":\"1.627\",\"T\":1788563200133,\"E\":1788563200134,\"st\":1}}"}
{"receive_ns":1788563200099001000,"stream":"btcusdt@bookTicker","event_type":"bookTicker","event_time_ms":1788563200134,"raw_json":"{\"stream\":\"btcusdt@bookTicker\",\"data\":{\"e\":\"bookTicker\",\"u\":11478222906474,\"s\":\"BTCUSDT\",\"ps\":\"BTCUSDT\",\"b\":\"79607.10\",\"B\":\"9.753\",\"a\":\"79607.20\",\"A\":\"1.627\",\"T\":1788563200133,\"E\":1788563200134,\"st\":1}}"}
{"receive_ns":1788563200099193000,"stream":"btcusdt@bookTicker","event_type":"bookTicker","event_time_ms":1788563200134,"raw_json":"{\"stream\":\"btcusdt@bookTicker\",\"data\":{\"e\":\"bookTicker\",\"u\":11478222906511,\"s\":\"BTCUSDT\",\"ps\":\"BTCUSDT\",\"b\":\"79607.10\",\"B\":\"9.745\",\"a\":\"79607.20\",\"A\":\"1.627\",\"T\":1788563200134,\"E\":1788563200134,\"st\":1}}"}
{"receive_ns":1788563200099334000,"stream":"btcusdt@bookTicker","event_type":"bookTicker","event_time_ms":1788563200134,"raw_json":"{\"stream\":\"btcusdt@bookTicker\",\"data\":{\"e\":\"bookTicker\",\"u\":11478222906517,\"s\":\"BTCUSDT\",\"ps\":\"BTCUSDT\",\"b\":\"79607.10\",\"B\":\"9.726\",\"a\":\"79607.20\",\"A\":\"1.627\",\"T\":1788563200134,\"E\":1788563200134,\"st\":1}}"}
{"receive_ns":1788563200104120000,"stream":"btcusdt@bookTicker","event_type":"bookTicker","event_time_ms":1788563200139,"raw_json":"{\"stream\":\"btcusdt@bookTicker\",\"data\":{\"e\":\"bookTicker\",\"u\":11478222906810,\"s\":\"BTCUSDT\",\"ps\":\"BTCUSDT\",\"b\":\"79607.10\",\"B\":\"9.745\",\"a\":\"79607.20\",\"A\":\"1.627\",\"T\":1788563200139,\"E\":1788563200139,\"st\":1}}"}
{"receive_ns":1788563200104359000,"stream":"btcusdt@bookTicker","event_type":"bookTicker","event_time_ms":1788563200139,"raw_json":"{\"stream\":\"btcusdt@bookTicker\",\"data\":{\"e\":\"bookTicker\",\"u\":11478222906867,\"s\":\"BTCUSDT\",\"ps\":\"BTCUSDT\",\"b\":\"79607.10\",\"B\":\"9.726\",\"a\":\"79607.20\",\"A\":\"1.627\",\"T\":1788563200139,\"E\":1788563200139,\"st\":1}}"}
{"receive_ns":1788563200130143000,"stream":"btcusdt@bookTicker","event_type":"bookTicker","event_time_ms":1788563200165,"raw_json":"{\"stream\":\"btcusdt@bookTicker\",\"data\":{\"e\":\"bookTicker\",\"u\":11478222909764,\"s\":\"BTCUSDT\",\"ps\":\"BTCUSDT\",\"b\":\"79607.10\",\"B\":\"9.745\",\"a\":\"79607.20\",\"A\":\"1.627\",\"T\":1788563200165,\"E\":1788563200165,\"st\":1}}"}
{"receive_ns":1788563200130383000,"stream":"btcusdt@bookTicker","event_type":"bookTicker","event_time_ms":1788563200166,"raw_json":"{\"stream\":\"btcusdt@bookTicker\",\"data\":{\"e\":\"bookTicker\",\"u\":11478222909836,\"s\":\"BTCUSDT\",\"ps\":\"BTCUSDT\",\"b\":\"79607.10\",\"B\":\"9.726\",\"a\":\"79607.20\",\"A\":\"1.627\",\"T\":1788563200166,\"E\":1788563200166,\"st\":1}}"}
{"receive_ns":1788563200156839000,"stream":"btcusdt@bookTicker","event_type":"bookTicker","event_time_ms":1788563200190,"raw_json":"{\"stream\":\"btcusdt@bookTicker\",\"data\":{\"e\":\"bookTicker\",\"u\":11478222912005,\"s\":\"BTCUSDT\",\"ps\":\"BTCUSDT\",\"b\":\"79607.10\",\"B\":\"9.745\",\"a\":\"79607.20\",\"A\":\"1.627\",\"T\":1788563200190,\"E\":1788563200190,\"st\":1}}"}
{"receive_ns":1788563200157093000,"stream":"btcusdt@bookTicker","event_type":"bookTicker","event_time_ms":1788563200191,"raw_json":"{\"stream\":\"btcusdt@bookTicker\",\"data\":{\"e\":\"bookTicker\",\"u\":11478222912029,\"s\":\"BTCUSDT\",\"ps\":\"BTCUSDT\",\"b\":\"79607.10\",\"B\":\"9.726\",\"a\":\"79607.20\",\"A\":\"1.627\",\"T\":1788563200191,\"E\":1788563200191,\"st\":1}}"}
{"receive_ns":1788563200160571000,"stream":"btcusdt@depth@100ms","event_type":"depthUpdate","event_time_ms":1788563200195,"raw_json":"{\"stream\":\"btcusdt@depth@100ms\",\"data\":{\"e\":\"depthUpdate\",\"E\":1788563200195,\"T\":1788563200193,\"s\":\"BTCUSDT\",\"ps\":\"BTCUSDT\",\"U\":11478222903664,\"u\":11478222912229,\"pu\":11478222903565,\"b\":[[\"29107.10\",\"1.904\"],[\"29207.10\",\"0.035\"],[\"29507.10\",\"0.161\"],[\"71646.30\",\"0.002\"],[\"76418.40\",\"0.001\"],[\"76422.80\",\"0.000\"],[\"78015.00\",\"0.128\"],[\"78368.50\",\"3.568\"],[\"78448.10\",\"7.384\"],[\"78811.00\",\"4.126\"],[\"79209.10\",\"1.777\"],[\"79236.90\",\"0.247\"],[\"79411.70\",\"0.031\"],[\"79427.90\",\"0.002\"],[\"79434.00\",\"0.427\"],[\"79478.50\",\"0.000\"],[\"79481.50\",\"0.599\"],[\"79491.70\",\"0.075\"],[\"79511.50\",\"0.024\"],[\"79531.30\",\"23.466\"],[\"79531.80\",\"4.182\"],[\"79536.70\",\"0.000\"],[\"79538.40\",\"0.795\"],[\"79575.30\",\"0.001\"],[\"79576.20\",\"0.001\"],[\"79577.40\",\"0.452\"],[\"79591.60\",\"0.073\"],[\"79598.90\",\"0.169\"],[\"79600.20\",\"0.252\"],[\"79601.00\",\"0.248\"],[\"79601.20\",\"0.105\"],[\"79602.20\",\"0.046\"],[\"79602.40\",\"0.059\"],[\"79603.00\",\"0.076\"],[\"79604.20\",\"0.000\"],[\"79606.40\",\"0.082\"],[\"79606.50\",\"0.026\"],[\"79607.00\",\"0.033\"],[\"79607.10\",\"9.726\"]],\"a\":[[\"79607.20\",\"1.627\"],[\"79607.30\",\"0.003\"],[\"79607.40\",\"0.102\"],[\"79607.50\",\"0.000\"],[\"79608.20\",\"0.001\"],[\"79608.40\",\"0.249\"],[\"79608.50\",\"0.000\"],[\"79608.60\",\"0.000\"],[\"79608.80\",\"0.001\"],[\"79609.00\",\"0.003\"],[\"79609.10\",\"0.026\"],[\"79609.20\",\"0.502\"],[\"79609.30\",\"0.001\"],[\"79609.40\",\"0.080\"],[\"79609.50\",\"0.007\"],[\"79609.60\",\"0.000\"],[\"79609.70\",\"0.000\"],[\"79609.90\",\"0.028\"],[\"79610.00\",\"0.030\"],[\"79610.10\",\"0.027\"],[\"79610.20\",\"0.077\"],[\"79610.30\",\"0.639\"],[\"79610.40\",\"1.179\"],[\"79610.50\",\"0.028\"],[\"79610.70\",\"0.029\"],[\"79611.20\",\"0.090\"],[\"79613.60\",\"0.005\"],[\"79613.90\",\"0.003\"],[\"79615.70\",\"0.002\"],[\"79616.00\",\"0.099\"],[\"79617.50\",\"0.641\"],[\"79617.70\",\"0.741\"],[\"79619.00\",\"0.573\"],[\"79620.40\",\"0.000\"],[\"79620.50\",\"2.059\"],[\"79621.40\",\"0.699\"],[\"79622.70\",\"0.000\"],[\"79626.50\",\"0.000\"],[\"79627.10\",\"0.453\"],[\"79669.90\",\"0.007\"],[\"79678.90\",\"0.018\"],[\"79730.10\",\"0.000\"],[\"79730.60\",\"0.352\"],[\"79746.30\",\"0.252\"],[\"79973.40\",\"1.388\"],[\"80403.30\",\"7.987\"],[\"80562.50\",\"18.596\"]],\"st\":1}}"}
{"receive_ns":1788563200162426000,"stream":"btcusdt@bookTicker","event_type":"bookTicker","event_time_ms":1788563200199,"raw_json":"{\"stream\":\"btcusdt@bookTicker\",\"data\":{\"e\":\"bookTicker\",\"u\":11478222912565,\"s\":\"BTCUSDT\",\"ps\":\"BTCUSDT\",\"b\":\"79607.10\",\"B\":\"9.498\",\"a\":\"79607.20\",\"A\":\"1.627\",\"T\":1788563200198,\"E\":1788563200199,\"st\":1}}"}
{"receive_ns":1788563200167136000,"stream":"btcusdt@bookTicker","event_type":"bookTicker","event_time_ms":1788563200201,"raw_json":"{\"stream\":\"btcusdt@bookTicker\",\"data\":{\"e\":\"bookTicker\",\"u\":11478222912797,\"s\":\"BTCUSDT\",\"ps\":\"BTCUSDT\",\"b\":\"79607.10\",\"B\":\"9.729\",\"a\":\"79607.20\",\"A\":\"1.627\",\"T\":1788563200201,\"E\":1788563200201,\"st\":1}}"}
{"receive_ns":1788563200181018000,"stream":"btcusdt@bookTicker","event_type":"bookTicker","event_time_ms":1788563200215,"raw_json":"{\"stream\":\"btcusdt@bookTicker\",\"data\":{\"e\":\"bookTicker\",\"u\":11478222913953,\"s\":\"BTCUSDT\",\"ps\":\"BTCUSDT\",\"b\":\"79607.10\",\"B\":\"9.748\",\"a\":\"79607.20\",\"A\":\"1.627\",\"T\":1788563200215,\"E\":1788563200215,\"st\":1}}"}
{"receive_ns":1788563200181248000,"stream":"btcusdt@bookTicker","event_type":"bookTicker","event_time_ms":1788563200216,"raw_json":"{\"stream\":\"btcusdt@bookTicker\",\"data\":{\"e\":\"bookTicker\",\"u\":11478222914017,\"s\":\"BTCUSDT\",\"ps\":\"BTCUSDT\",\"b\":\"79607.10\",\"B\":\"9.729\",\"a\":\"79607.20\",\"A\":\"1.627\",\"T\":1788563200215,\"E\":1788563200216,\"st\":1}}"}
{"receive_ns":1788563200182401000,"stream":"btcusdt@bookTicker","event_type":"bookTicker","event_time_ms":1788563200216,"raw_json":"{\"stream\":\"btcusdt@bookTicker\",\"data\":{\"e\":\"bookTicker\",\"u\":11478222914079,\"s\":\"BTCUSDT\",\"ps\":\"BTCUSDT\",\"b\":\"79607.10\",\"B\":\"9.729\",\"a\":\"79607.20\",\"A\":\"1.187\",\"T\":1788563200216,\"E\":1788563200216,\"st\":1}}"}
{"receive_ns":1788563200182623000,"stream":"btcusdt@bookTicker","event_type":"bookTicker","event_time_ms":1788563200218,"raw_json":"{\"stream\":\"btcusdt@bookTicker\",\"data\":{\"e\":\"bookTicker\",\"u\":11478222914197,\"s\":\"BTCUSDT\",\"ps\":\"BTCUSDT\",\"b\":\"79607.10\",\"B\":\"9.737\",\"a\":\"79607.20\",\"A\":\"1.187\",\"T\":1788563200218,\"E\":1788563200218,\"st\":1}}"}
{"receive_ns":1788563200184022000,"stream":"btcusdt@bookTicker","event_type":"bookTicker","event_time_ms":1788563200218,"raw_json":"{\"stream\":\"btcusdt@bookTicker\",\"data\":{\"e\":\"bookTicker\",\"u\":11478222914234,\"s\":\"BTCUSDT\",\"ps\":\"BTCUSDT\",\"b\":\"79607.10\",\"B\":\"9.737\",\"a\":\"79607.20\",\"A\":\"1.037\",\"T\":1788563200218,\"E\":1788563200218,\"st\":1}}"}
{"receive_ns":1788563200184196000,"stream":"btcusdt@bookTicker","event_type":"bookTicker","event_time_ms":1788563200218,"raw_json":"{\"stream\":\"btcusdt@bookTicker\",\"data\":{\"e\":\"bookTicker\",\"u\":11478222914237,\"s\":\"BTCUSDT\",\"ps\":\"BTCUSDT\",\"b\":\"79607.10\",\"B\":\"9.756\",\"a\":\"79607.20\",\"A\":\"1.037\",\"T\":1788563200218,\"E\":1788563200218,\"st\":1}}"}
{"receive_ns":1788563200184359000,"stream":"btcusdt@bookTicker","event_type":"bookTicker","event_time_ms":1788563200219,"raw_json":"{\"stream\":\"btcusdt@bookTicker\",\"data\":{\"e\":\"bookTicker\",\"u\":11478222914278,\"s\":\"BTCUSDT\",\"ps\":\"BTCUSDT\",\"b\":\"79607.10\",\"B\":\"9.737\",\"a\":\"79607.20\",\"A\":\"1.037\",\"T\":1788563200218,\"E\":1788563200219,\"st\":1}}"}
{"receive_ns":1788563200184499000,"stream":"btcusdt@bookTicker","event_type":"bookTicker","event_time_ms":1788563200219,"raw_json":"{\"stream\":\"btcusdt@bookTicker\",\"data\":{\"e\":\"bookTicker\",\"u\":11478222914280,\"s\":\"BTCUSDT\",\"ps\":\"BTCUSDT\",\"b\":\"79607.10\",\"B\":\"9.729\",\"a\":\"79607.20\",\"A\":\"1.037\",\"T\":1788563200218,\"E\":1788563200219,\"st\":1}}"}
{"receive_ns":1788563200184649000,"stream":"btcusdt@bookTicker","event_type":"bookTicker","event_time_ms":1788563200219,"raw_json":"{\"stream\":\"btcusdt@bookTicker\",\"data\":{\"e\":\"bookTicker\",\"u\":11478222914355,\"s\":\"BTCUSDT\",\"ps\":\"BTCUSDT\",\"b\":\"79607.10\",\"B\":\"9.748\",\"a\":\"79607.20\",\"A\":\"1.037\",\"T\":1788563200219,\"E\":1788563200219,\"st\":1}}"}
{"receive_ns":1788563200184785000,"stream":"btcusdt@bookTicker","event_type":"bookTicker","event_time_ms":1788563200219,"raw_json":"{\"stream\":\"btcusdt@bookTicker\",\"data\":{\"e\":\"bookTicker\",\"u\":11478222914368,\"s\":\"BTCUSDT\",\"ps\":\"BTCUSDT\",\"b\":\"79607.10\",\"B\":\"9.756\",\"a\":\"79607.20\",\"A\":\"1.037\",\"T\":1788563200219,\"E\":1788563200219,\"st\":1}}"}
{"receive_ns":1788563200184932000,"stream":"btcusdt@bookTicker","event_type":"bookTicker","event_time_ms":1788563200219,"raw_json":"{\"stream\":\"btcusdt@bookTicker\",\"data\":{\"e\":\"bookTicker\",\"u\":11478222914386,\"s\":\"BTCUSDT\",\"ps\":\"BTCUSDT\",\"b\":\"79607.10\",\"B\":\"9.751\",\"a\":\"79607.20\",\"A\":\"1.037\",\"T\":1788563200219,\"E\":1788563200219,\"st\":1}}"}
{"receive_ns":1788563200185081000,"stream":"btcusdt@bookTicker","event_type":"bookTicker","event_time_ms":1788563200220,"raw_json":"{\"stream\":\"btcusdt@bookTicker\",\"data\":{\"e\":\"bookTicker\",\"u\":11478222914424,\"s\":\"BTCUSDT\",\"ps\":\"BTCUSDT\",\"b\":\"79607.10\",\"B\":\"9.743\",\"a\":\"79607.20\",\"A\":\"1.037\",\"T\":1788563200220,\"E\":1788563200220,\"st\":1}}"}
{"receive_ns":1788563200185229000,"stream":"btcusdt@bookTicker","event_type":"bookTicker","event_time_ms":1788563200220,"raw_json":"{\"stream\":\"btcusdt@bookTicker\",\"data\":{\"e\":\"bookTicker\",\"u\":11478222914449,\"s\":\"BTCUSDT\",\"ps\":\"BTCUSDT\",\"b\":\"79607.10\",\"B\":\"9.724\",\"a\":\"79607.20\",\"A\":\"1.037\",\"T\":1788563200220,\"E\":1788563200220,\"st\":1}}"}
{"receive_ns":1788563200237466000,"stream":"btcusdt@bookTicker","event_type":"bookTicker","event_time_ms":1788563200271,"raw_json":"{\"stream\":\"btcusdt@bookTicker\",\"data\":{\"e\":\"bookTicker\",\"u\":11478222916912,\"s\":\"BTCUSDT\",\"ps\":\"BTCUSDT\",\"b\":\"79607.10\",\"B\":\"9.386\",\"a\":\"79607.20\",\"A\":\"1.037\",\"T\":1788563200271,\"E\":1788563200271,\"st\":1}}"}
{"receive_ns":1788563200238072000,"stream":"btcusdt@bookTicker","event_type":"bookTicker","event_time_ms":1788563200274,"raw_json":"{\"stream\":\"btcusdt@bookTicker\",\"data\":{\"e\":\"bookTicker\",\"u\":11478222917086,\"s\":\"BTCUSDT\",\"ps\":\"BTCUSDT\",\"b\":\"79607.10\",\"B\":\"9.734\",\"a\":\"79607.20\",\"A\":\"1.037\",\"T\":1788563200274,\"E\":1788563200274,\"st\":1}}"}
{"receive_ns":1788563200239473000,"stream":"btcusdt@bookTicker","event_type":"bookTicker","event_time_ms":1788563200275,"raw_json":"{\"stream\":\"btcusdt@bookTicker\",\"data\":{\"e\":\"bookTicker\",\"u\":11478222917148,\"s\":\"BTCUSDT\",\"ps\":\"BTCUSDT\",\"b\":\"79607.10\",\"B\":\"9.733\",\"a\":\"79607.20\",\"A\":\"1.037\",\"T\":1788563200275,\"E\":1788563200275,\"st\":1}}"}
{"receive_ns":1788563200240641000,"stream":"btcusdt@bookTicker","event_type":"bookTicker","event_time_ms":1788563200276,"raw_json":"{\"stream\":\"btcusdt@bookTicker\",\"data\":{\"e\":\"bookTicker\",\"u\":11478222917217,\"s\":\"BTCUSDT\",\"ps\":\"BTCUSDT\",\"b\":\"79607.10\",\"B\":\"9.734\",\"a\":\"79607.20\",\"A\":\"1.037\",\"T\":1788563200276,\"E\":1788563200276,\"st\":1}}"}
{"receive_ns":1788563200256153000,"stream":"btcusdt@bookTicker","event_type":"bookTicker","event_time_ms":1788563200291,"raw_json":"{\"stream\":\"btcusdt@bookTicker\",\"data\":{\"e\":\"bookTicker\",\"u\":11478222918413,\"s\":\"BTCUSDT\",\"ps\":\"BTCUSDT\",\"b\":\"79607.10\",\"B\":\"9.471\",\"a\":\"79607.20\",\"A\":\"1.037\",\"T\":1788563200291,\"E\":1788563200291,\"st\":1}}"}
{"receive_ns":1788563200260061000,"stream":"btcusdt@bookTicker","event_type":"bookTicker","event_time_ms":1788563200294,"raw_json":"{\"stream\":\"btcusdt@bookTicker\",\"data\":{\"e\":\"bookTicker\",\"u\":11478222918668,\"s\":\"BTCUSDT\",\"ps\":\"BTCUSDT\",\"b\":\"79607.10\",\"B\":\"9.722\",\"a\":\"79607.20\",\"A\":\"1.037\",\"T\":1788563200294,\"E\":1788563200294,\"st\":1}}"}
{"receive_ns":1788563200263642000,"stream":"btcusdt@depth@100ms","event_type":"depthUpdate","event_time_ms":1788563200297,"raw_json":"{\"stream\":\"btcusdt@depth@100ms\",\"data\":{\"e\":\"depthUpdate\",\"E\":1788563200297,\"T\":1788563200296,\"s\":\"BTCUSDT\",\"ps\":\"BTCUSDT\",\"U\":11478222912371,\"u\":11478222918905,\"pu\":11478222912229,\"b\":[[\"1000.00\",\"24.604\"],[\"29107.10\",\"1.792\"],[\"29207.10\",\"0.000\"],[\"29507.10\",\"0.308\"],[\"71646.30\",\"0.002\"],[\"76422.80\",\"0.002\"],[\"78487.90\",\"19.087\"],[\"78811.00\",\"4.126\"],[\"79209.10\",\"1.636\"],[\"79236.90\",\"0.015\"],[\"79434.00\",\"0.076\"],[\"79453.90\",\"0.204\"],[\"79487.70\",\"0.001\"],[\"79491.70\",\"1.506\"],[\"79531.30\",\"0.011\"],[\"79531.80\",\"0.757\"],[\"79534.00\",\"0.001\"],[\"79536.70\",\"23.439\"],[\"79573.10\",\"0.110\"],[\"79575.40\",\"0.048\"],[\"79576.50\",\"0.004\"],[\"79581.70\",\"0.632\"],[\"79581.80\",\"2.070\"],[\"79582.00\",\"0.004\"],[\"79582.10\",\"0.003\"],[\"79582.80\",\"0.001\"],[\"79583.60\",\"1.023\"],[\"79584.30\",\"0.373\"],[\"79584.80\",\"0.277\"],[\"79585.40\",\"0.004\"],[\"79598.20\",\"0.254\"],[\"79598.80\",\"0.001\"],[\"79607.10\",\"9.722\"]],\"a\":[[\"79607.20\",\"1.037\"],[\"79607.30\",\"0.002\"],[\"79609.10\",\"0.000\"],[\"79609.20\",\"0.000\"],[\"79609.90\",\"0.002\"],[\"79610.00\",\"0.004\"],[\"79610.10\",\"0.001\"],[\"79610.20\",\"0.051\"],[\"79610.30\",\"0.613\"],[\"79610.40\",\"1.153\"],[\"79610.50\",\"0.002\"],[\"79610.80\",\"0.028\"],[\"79610.90\",\"0.027\"],[\"79611.00\",\"0.029\"],[\"79611.10\",\"0.103\"],[\"79611.20\",\"0.026\"],[\"79611.40\",\"1.322\"],[\"79611.50\",\"0.596\"],[\"79617.60\",\"0.194\"],[\"79617.70\",\"0.741\"],[\"79618.80\",\"0.005\"],[\"79618.90\",\"0.375\"],[\"79619.00\",\"0.194\"],[\"79644.20\",\"2.538\"],[\"79647.60\",\"0.002\"],[\"79647.70\",\"0.204\"],[\"79650.80\",\"9.779\"],[\"79677.30\",\"0.088\"],[\"79695.40\",\"0.602\"],[\"79707.80\",\"0.003\"],[\"79788.80\",\"0.006\"],[\"79973.40\",\"0.950\"],[\"80403.30\",\"7.989\"],[\"80602.30\",\"4.211\"],[\"81199.30\",\"0.024\"]],\"st\":1}}"}
{"receive_ns":1788563200340051000,"stream":"btcusdt@bookTicker","event_type":"bookTicker","event_time_ms":1788563200367,"raw_json":"{\"stream\":\"btcusdt@bookTicker\",\"data\":{\"e\":\"bookTicker\",\"u\":11478222923583,\"s\":\"BTCUSDT\",\"ps\":\"BTCUSDT\",\"b\":\"79607.10\",\"B\":\"9.769\",\"a\":\"79607.20\",\"A\":\"1.037\",\"T\":1788563200367,\"E\":1788563200367,\"st\":1}}"}
{"receive_ns":1788563200340302000,"stream":"btcusdt@bookTicker","event_type":"bookTicker","event_time_ms":1788563200368,"raw_json":"{\"stream\":\"btcusdt@bookTicker\",\"data\":{\"e\":\"bookTicker\",\"u\":11478222923653,\"s\":\"BTCUSDT\",\"ps\":\"BTCUSDT\",\"b\":\"79607.10\",\"B\":\"9.767\",\"a\":\"79607.20\",\"A\":\"1.037\",\"T\":1788563200368,\"E\":1788563200368,\"st\":1}}"}
{"receive_ns":1788563200364871000,"stream":"btcusdt@depth@100ms","event_type":"depthUpdate","event_time_ms":1788563200399,"raw_json":"{\"stream\":\"btcusdt@depth@100ms\",\"data\":{\"e\":\"depthUpdate\",\"E\":1788563200399,\"T\":1788563200398,\"s\":\"BTCUSDT\",\"ps\":\"BTCUSDT\",\"U\":11478222918972,\"u\":11478222924852,\"pu\":11478222918905,\"b\":[[\"1000.00\",\"24.604\"],[\"29107.10\",\"1.610\"],[\"29507.10\",\"0.490\"],[\"63686.00\",\"0.002\"],[\"71646.30\",\"0.002\"],[\"76422.80\",\"0.000\"],[\"78504.50\",\"0.638\"],[\"78603.10\",\"6.271\"],[\"78651.80\",\"10.981\"],[\"78811.00\",\"4.126\"],[\"79209.10\",\"1.787\"],[\"79236.90\",\"0.247\"],[\"79434.00\",\"0.176\"],[\"79485.70\",\"0.252\"],[\"79493.70\",\"1.910\"],[\"79607.10\",\"9.767\"]],\"a\":[[\"79609.20\",\"0.251\"],[\"79611.20\",\"0.566\"],[\"79648.30\",\"2.195\"],[\"79650.90\",\"0.003\"],[\"79788.80\",\"0.000\"],[\"79973.40\",\"1.913\"],[\"80403.30\",\"7.987\"],[\"81199.30\",\"0.021\"]],\"st\":1}}"}
{"receive_ns":1788563200371646000,"stream":"btcusdt@bookTicker","event_type":"bookTicker","event_time_ms":1788563200406,"raw_json":"{\"stream\":\"btcusdt@bookTicker\",\"data\":{\"e\":\"bookTicker\",\"u\":11478222925160,\"s\":\"BTCUSDT\",\"ps\":\"BTCUSDT\",\"b\":\"79607.10\",\"B\":\"9.568\",\"a\":\"79607.20\",\"A\":\"1.037\",\"T\":1788563200406,\"E\":1788563200406,\"st\":1}}"}
{"receive_ns":1788563200374501000,"stream":"btcusdt@bookTicker","event_type":"bookTicker","event_time_ms":1788563200409,"raw_json":"{\"stream\":\"btcusdt@bookTicker\",\"data\":{\"e\":\"bookTicker\",\"u\":11478222925446,\"s\":\"BTCUSDT\",\"ps\":\"BTCUSDT\",\"b\":\"79607.10\",\"B\":\"9.773\",\"a\":\"79607.20\",\"A\":\"1.037\",\"T\":1788563200409,\"E\":1788563200409,\"st\":1}}"}
{"receive_ns":1788563200374719000,"stream":"btcusdt@bookTicker","event_type":"bookTicker","event_time_ms":1788563200410,"raw_json":"{\"stream\":\"btcusdt@bookTicker\",\"data\":{\"e\":\"bookTicker\",\"u\":11478222925503,\"s\":\"BTCUSDT\",\"ps\":\"BTCUSDT\",\"b\":\"79607.10\",\"B\":\"9.775\",\"a\":\"79607.20\",\"A\":\"1.037\",\"T\":1788563200410,\"E\":1788563200410,\"st\":1}}"}
{"receive_ns":1788563200387136000,"stream":"btcusdt@bookTicker","event_type":"bookTicker","event_time_ms":1788563200422,"raw_json":"{\"stream\":\"btcusdt@bookTicker\",\"data\":{\"e\":\"bookTicker\",\"u\":11478222926101,\"s\":\"BTCUSDT\",\"ps\":\"BTCUSDT\",\"b\":\"79607.10\",\"B\":\"9.794\",\"a\":\"79607.20\",\"A\":\"1.037\",\"T\":1788563200422,\"E\":1788563200422,\"st\":1}}"}
{"receive_ns":1788563200387371000,"stream":"btcusdt@bookTicker","event_type":"bookTicker","event_time_ms":1788563200423,"raw_json":"{\"stream\":\"btcusdt@bookTicker\",\"data\":{\"e\":\"bookTicker\",\"u\":11478222926166,\"s\":\"BTCUSDT\",\"ps\":\"BTCUSDT\",\"b\":\"79607.10\",\"B\":\"9.775\",\"a\":\"79607.20\",\"A\":\"1.037\",\"T\":1788563200423,\"E\":1788563200423,\"st\":1}}"}
{"receive_ns":1788563200392183000,"stream":"btcusdt@bookTicker","event_type":"bookTicker","event_time_ms":1788563200428,"raw_json":"{\"stream\":\"btcusdt@bookTicker\",\"data\":{\"e\":\"bookTicker\",\"u\":11478222926605,\"s\":\"BTCUSDT\",\"ps\":\"BTCUSDT\",\"b\":\"79607.10\",\"B\":\"9.293\",\"a\":\"79607.20\",\"A\":\"1.037\",\"T\":1788563200428,\"E\":1788563200428,\"st\":1}}"}
{"receive_ns":1788563200413616000,"stream":"btcusdt@bookTicker","event_type":"bookTicker","event_time_ms":1788563200441,"raw_json":"{\"stream\":\"btcusdt@bookTicker\",\"data\":{\"e\":\"bookTicker\",\"u\":11478222927303,\"s\":\"BTCUSDT\",\"ps\":\"BTCUSDT\",\"b\":\"79607.10\",\"B\":\"9.776\",\"a\":\"79607.20\",\"A\":\"1.037\",\"T\":1788563200441,\"E\":1788563200441,\"st\":1}}"}
{"receive_ns":1788563200465954000,"stream":"btcusdt@depth@100ms","event_type":"depthUpdate","event_time_ms":1788563200501,"raw_json":"{\"stream\":\"btcusdt@depth@100ms\",\"data\":{\"e\":\"depthUpdate\",\"E\":1788563200501,\"T\":1788563200497,\"s\":\"BTCUSDT\",\"ps\":\"BTCUSDT\",\"U\":11478222924916,\"u\":11478222930592,\"pu\":11478222924852,\"b\":[[\"29107.10\",\"1.435\"],[\"29507.10\",\"0.665\"],[\"63686.00\",\"0.002\"],[\"71646.30\",\"0.002\"],[\"76422.80\",\"0.002\"],[\"78000.00\",\"75.415\"],[\"78015.00\",\"0.131\"],[\"78811.00\",\"4.126\"],[\"79453.90\",\"0.706\"],[\"79478.40\",\"0.125\"],[\"79491.70\",\"1.004\"],[\"79531.10\",\"0.000\"],[\"79576.20\",\"0.453\"],[\"79577.40\",\"0.000\"],[\"79592.20\",\"0.001\"],[\"79594.20\",\"0.007\"],[\"79601.60\",\"0.000\"],[\"79602.20\",\"0.046\"],[\"79602.40\",\"0.059\"],[\"79607.10\",\"9.776\"]],\"a\":[[\"79609.60\",\"0.000\"],[\"79609.90\",\"0.028\"],[\"79610.10\",\"0.027\"],[\"79973.40\",\"1.913\"],[\"80244.10\",\"1.245\"],[\"80403.30\",\"7.987\"],[\"80547.80\",\"7.374\"]],\"st\":1}}"}
{"receive_ns":1788563200468308000,"stream":"btcusdt@bookTicker","event_type":"bookTicker","event_time_ms":1788563200503,"raw_json":"{\"stream\":\"btcusdt@bookTicker\",\"data\":{\"e\":\"bookTicker\",\"u\":11478222930968,\"s\":\"BTCUSDT\",\"ps\":\"BTCUSDT\",\"b\":\"79607.10\",\"B\":\"9.776\",\"a\":\"79607.20\",\"A\":\"1.052\",\"T\":1788563200503,\"E\":1788563200503,\"st\":1}}"}
{"receive_ns":1788563200468536000,"stream":"btcusdt@bookTicker","event_type":"bookTicker","event_time_ms":1788563200504,"raw_json":"{\"stream\":\"btcusdt@bookTicker\",\"data\":{\"e\":\"bookTicker\",\"u\":11478222931048,\"s\":\"BTCUSDT\",\"ps\":\"BTCUSDT\",\"b\":\"79607.10\",\"B\":\"9.776\",\"a\":\"79607.20\",\"A\":\"1.051\",\"T\":1788563200504,\"E\":1788563200504,\"st\":1}}"}
{"receive_ns":1788563200469594000,"stream":"btcusdt@bookTicker","event_type":"bookTicker","event_time_ms":1788563200505,"raw_json":"{\"stream\":\"btcusdt@bookTicker\",\"data\":{\"e\":\"bookTicker\",\"u\":11478222931213,\"s\":\"BTCUSDT\",\"ps\":\"BTCUSDT\",\"b\":\"79607.10\",\"B\":\"9.426\",\"a\":\"79607.20\",\"A\":\"1.051\",\"T\":1788563200505,\"E\":1788563200505,\"st\":1}}"}
{"receive_ns":1788563200473357000,"stream":"btcusdt@bookTicker","event_type":"bookTicker","event_time_ms":1788563200508,"raw_json":"{\"stream\":\"btcusdt@bookTicker\",\"data\":{\"e\":\"bookTicker\",\"u\":11478222931417,\"s\":\"BTCUSDT\",\"ps\":\"BTCUSDT\",\"b\":\"79607.10\",\"B\":\"9.788\",\"a\":\"79607.20\",\"A\":\"1.051\",\"T\":1788563200508,\"E\":1788563200508,\"st\":1}}"}
{"receive_ns":1788563200473678000,"stream":"btcusdt@bookTicker","event_type":"bookTicker","event_time_ms":1788563200509,"raw_json":"{\"stream\":\"btcusdt@bookTicker\",\"data\":{\"e\":\"bookTicker\",\"u\":11478222931465,\"s\":\"BTCUSDT\",\"ps\":\"BTCUSDT\",\"b\":\"79607.10\",\"B\":\"9.788\",\"a\":\"79607.20\",\"A\":\"1.052\",\"T\":1788563200509,\"E\":1788563200509,\"st\":1}}"}
{"receive_ns":1788563200509325000,"stream":"btcusdt@bookTicker","event_type":"bookTicker","event_time_ms":1788563200544,"raw_json":"{\"stream\":\"btcusdt@bookTicker\",\"data\":{\"e\":\"bookTicker\",\"u\":11478222933478,\"s\":\"BTCUSDT\",\"ps\":\"BTCUSDT\",\"b\":\"79607.10\",\"B\":\"9.807\",\"a\":\"79607.20\",\"A\":\"1.052\",\"T\":1788563200544,\"E\":1788563200544,\"st\":1}}"}
{"receive_ns":1788563200509569000,"stream":"btcusdt@bookTicker","event_type":"bookTicker","event_time_ms":1788563200545,"raw_json":"{\"stream\":\"btcusdt@bookTicker\",\"data\":{\"e\":\"bookTicker\",\"u\":11478222933524,\"s\":\"BTCUSDT\",\"ps\":\"BTCUSDT\",\"b\":\"79607.10\",\"B\":\"9.788\",\"a\":\"79607.20\",\"A\":\"1.052\",\"T\":1788563200545,\"E\":1788563200545,\"st\":1}}"}
{"receive_ns":1788563200510604000,"stream":"btcusdt@bookTicker","event_type":"bookTicker","event_time_ms":1788563200546,"raw_json":"{\"stream\":\"btcusdt@bookTicker\",\"data\":{\"e\":\"bookTicker\",\"u\":11478222933626,\"s\":\"BTCUSDT\",\"ps\":\"BTCUSDT\",\"b\":\"79607.10\",\"B\":\"9.788\",\"a\":\"79607.20\",\"A\":\"1.492\",\"T\":1788563200546,\"E\":1788563200546,\"st\":1}}"}
{"receive_ns":1788563200513441000,"stream":"btcusdt@bookTicker","event_type":"bookTicker","event_time_ms":1788563200548,"raw_json":"{\"stream\":\"btcusdt@bookTicker\",\"data\":{\"e\":\"bookTicker\",\"u\":11478222933749,\"s\":\"BTCUSDT\",\"ps\":\"BTCUSDT\",\"b\":\"79607.10\",\"B\":\"9.788\",\"a\":\"79607.20\",\"A\":\"1.491\",\"T\":1788563200547,\"E\":1788563200548,\"st\":1}}"}
{"receive_ns":1788563200513610000,"stream":"btcusdt@bookTicker","event_type":"bookTicker","event_time_ms":1788563200548,"raw_json":"{\"stream\":\"btcusdt@bookTicker\",\"data\":{\"e\":\"bookTicker\",\"u\":11478222933758,\"s\":\"BTCUSDT\",\"ps\":\"BTCUSDT\",\"b\":\"79607.10\",\"B\":\"9.796\",\"a\":\"79607.20\",\"A\":\"1.491\",\"T\":1788563200548,\"E\":1788563200548,\"st\":1}}"}
{"receive_ns":1788563200513747000,"stream":"btcusdt@bookTicker","event_type":"bookTicker","event_time_ms":1788563200548,"raw_json":"{\"stream\":\"btcusdt@bookTicker\",\"data\":{\"e\":\"bookTicker\",\"u\":11478222933760,\"s\":\"BTCUSDT\",\"ps\":\"BTCUSDT\",\"b\":\"79607.10\",\"B\":\"9.815\",\"a\":\"79607.20\",\"A\":\"1.491\",\"T\":1788563200548,\"E\":1788563200548,\"st\":1}}"}
{"receive_ns":1788563200513877000,"stream":"btcusdt@bookTicker","event_type":"bookTicker","event_time_ms":1788563200548,"raw_json":"{\"stream\":\"btcusdt@bookTicker\",\"data\":{\"e\":\"bookTicker\",\"u\":11478222933761,\"s\":\"BTCUSDT\",\"ps\":\"BTCUSDT\",\"b\":\"79607.10\",\"B\":\"9.815\",\"a\":\"79607.20\",\"A\":\"1.641\",\"T\":1788563200548,\"E\":1788563200548,\"st\":1}}"}
{"receive_ns":1788563200514029000,"stream":"btcusdt@bookTicker","event_type":"bookTicker","event_time_ms":1788563200548,"raw_json":"{\"stream\":\"btcusdt@bookTicker\",\"data\":{\"e\":\"bookTicker\",\"u\":11478222933819,\"s\":\"BTCUSDT\",\"ps\":\"BTCUSDT\",\"b\":\"79607.10\",\"B\":\"9.807\",\"a\":\"79607.20\",\"A\":\"1.641\",\"T\":1788563200548,\"E\":1788563200548,\"st\":1}}"}
{"receive_ns":1788563200514164000,"stream":"btcusdt@bookTicker","event_type":"bookTicker","event_time_ms":1788563200548,"raw_json":"{\"stream\":\"btcusdt@bookTicker\",\"data\":{\"e\":\"bookTicker\",\"u\":11478222933821,\"s\":\"BTCUSDT\",\"ps\":\"BTCUSDT\",\"b\":\"79607.10\",\"B\":\"9.788\",\"a\":\"79607.20\",\"A\":\"1.641\",\"T\":1788563200548,\"E\":1788563200548,\"st\":1}}"}
{"receive_ns":1788563200514369000,"stream":"btcusdt@bookTicker","event_type":"bookTicker","event_time_ms":1788563200549,"raw_json":"{\"stream\":\"btcusdt@bookTicker\",\"data\":{\"e\":\"bookTicker\",\"u\":11478222933917,\"s\":\"BTCUSDT\",\"ps\":\"BTCUSDT\",\"b\":\"79607.10\",\"B\":\"9.788\",\"a\":\"79607.20\",\"A\":\"1.642\",\"T\":1788563200549,\"E\":1788563200549,\"st\":1}}"}
{"receive_ns":1788563200523123000,"stream":"btcusdt@bookTicker","event_type":"bookTicker","event_time_ms":1788563200550,"raw_json":"{\"stream\":\"btcusdt@bookTicker\",\"data\":{\"e\":\"bookTicker\",\"u\":11478222933973,\"s\":\"BTCUSDT\",\"ps\":\"BTCUSDT\",\"b\":\"79607.10\",\"B\":\"9.796\",\"a\":\"79607.20\",\"A\":\"1.642\",\"T\":1788563200550,\"E\":1788563200550,\"st\":1}}"}
{"receive_ns":1788563200523330000,"stream":"btcusdt@bookTicker","event_type":"bookTicker","event_time_ms":1788563200550,"raw_json":"{\"stream\":\"btcusdt@bookTicker\",\"data\":{\"e\":\"bookTicker\",\"u\":11478222933979,\"s\":\"BTCUSDT\",\"ps\":\"BTCUSDT\",\"b\":\"79607.10\",\"B\":\"9.815\",\"a\":\"79607.20\",\"A\":\"1.642\",\"T\":1788563200550,\"E\":1788563200550,\"st\":1}}"}
{"receive_ns":1788563200523682000,"stream":"btcusdt@bookTicker","event_type":"bookTicker","event_time_ms":1788563200551,"raw_json":"{\"stream\":\"btcusdt@bookTicker\",\"data\":{\"e\":\"bookTicker\",\"u\":11478222934021,\"s\":\"BTCUSDT\",\"ps\":\"BTCUSDT\",\"b\":\"79607.10\",\"B\":\"9.807\",\"a\":\"79607.20\",\"A\":\"1.642\",\"T\":1788563200551,\"E\":1788563200551,\"st\":1}}"}
{"receive_ns":1788563200523906000,"stream":"btcusdt@bookTicker","event_type":"bookTicker","event_time_ms":1788563200551,"raw_json":"{\"stream\":\"btcusdt@bookTicker\",\"data\":{\"e\":\"bookTicker\",\"u\":11478222934029,\"s\":\"BTCUSDT\",\"ps\":\"BTCUSDT\",\"b\":\"79607.10\",\"B\":\"9.788\",\"a\":\"79607.20\",\"A\":\"1.642\",\"T\":1788563200551,\"E\":1788563200551,\"st\":1}}"}
{"receive_ns":1788563200575641000,"stream":"btcusdt@depth@100ms","event_type":"depthUpdate","event_time_ms":1788563200603,"raw_json":"{\"stream\":\"btcusdt@depth@100ms\",\"data\":{\"e\":\"depthUpdate\",\"E\":1788563200603,\"T\":1788563200602,\"s\":\"BTCUSDT\",\"ps\":\"BTCUSDT\",\"U\":11478222930869,\"u\":11478222936827,\"pu\":11478222930592,\"b\":[[\"1000.00\",\"24.604\"],[\"29107.10\",\"1.253\"],[\"29507.10\",\"0.847\"],[\"63686.00\",\"0.004\"],[\"71646.30\",\"0.002\"],[\"78590.80\",\"0.004\"],[\"78599.60\",\"0.000\"],[\"78613.30\",\"5.006\"],[\"78617.40\",\"0.000\"],[\"78811.00\",\"4.126\"],[\"79209.10\",\"1.787\"],[\"79236.90\",\"0.247\"],[\"79434.00\",\"1.631\"],[\"79485.70\",\"0.001\"],[\"79487.70\",\"0.076\"],[\"79493.70\",\"0.631\"],[\"79573.40\",\"3.335\"],[\"79575.40\",\"0.002\"],[\"79578.10\",\"9.776\"],[\"79579.70\",\"2.794\"],[\"79581.70\",\"0.631\"],[\"79581.80\",\"0.002\"],[\"79582.60\",\"0.373\"],[\"79584.30\",\"0.000\"],[\"79607.10\",\"9.788\"]],\"a\":[[\"79607.20\",\"1.642\"],[\"79607.30\",\"0.003\"],[\"79608.70\",\"0.000\"],[\"79609.00\",\"0.002\"],[\"79609.20\",\"0.618\"],[\"79609.30\",\"0.027\"],[\"79609.50\",\"0.033\"],[\"79611.20\",\"0.199\"],[\"79611.40\",\"1.296\"],[\"79611.50\",\"0.570\"],[\"79619.30\",\"0.340\"],[\"79620.40\",\"0.439\"],[\"79621.40\",\"0.260\"],[\"79973.40\",\"1.913\"],[\"80005.30\",\"0.001\"],[\"80403.30\",\"7.987\"]],\"st\":1}}"}
{"receive_ns":1788563200597024000,"stream":"btcusdt@bookTicker","event_type":"bookTicker","event_time_ms":1788563200631,"raw_json":"{\"stream\":\"btcusdt@bookTicker\",\"data\":{\"e\":\"bookTicker\",\"u\":11478222938570,\"s\":\"BTCUSDT\",\"ps\":\"BTCUSDT\",\"b\":\"79607.10\",\"B\":\"9.785\",\"a\":\"79607.20\",\"A\":\"1.642\",\"T\":1788563200631,\"E\":1788563200631,\"st\":1}}"}
{"receive_ns":1788563200600960000,"stream":"btcusdt@bookTicker","event_type":"bookTicker","event_time_ms":1788563200636,"raw_json":"{\"stream\":\"btcusdt@bookTicker\",\"data\":{\"e\":\"bookTicker\",\"u\":11478222938858,\"s\":\"BTCUSDT\",\"ps\":\"BTCUSDT\",\"b\":\"79607.10\",\"B\":\"9.804\",\"a\":\"79607.20\",\"A\":\"1.642\",\"T\":1788563200636,\"E\":1788563200636,\"st\":1}}"}
{"receive_ns":1788563200601190000,"stream":"btcusdt@bookTicker","event_type":"bookTicker","event_time_ms":1788563200637,"raw_json":"{\"stream\":\"btcusdt@bookTicker\",\"data\":{\"e\":\"bookTicker\",\"u\":11478222938915,\"s\":\"BTCUSDT\",\"ps\":\"BTCUSDT\",\"b\":\"79607.10\",\"B\":\"9.785\",\"a\":\"79607.20\",\"A\":\"1.642\",\"T\":1788563200636,\"E\":1788563200637,\"st\":1}}"}
{"receive_ns":1788563200645564000,"stream":"btcusdt@bookTicker","event_type":"bookTicker","event_time_ms":1788563200679,"raw_json":"{\"stream\":\"btcusdt@bookTicker\",\"data\":{\"e\":\"bookTicker\",\"u\":11478222941169,\"s\":\"BTCUSDT\",\"ps\":\"BTCUSDT\",\"b\":\"79607.10\",\"B\":\"9.804\",\"a\":\"79607.20\",\"A\":\"1.642\",\"T\":1788563200679,\"E\":1788563200679,\"st\":1}}"}
{"receive_ns":1788563200645816000,"stream":"btcusdt@bookTicker","event_type":"bookTicker","event_time_ms":1788563200680,"raw_json":"{\"stream\":\"btcusdt@bookTicker\",\"data\":{\"e\":\"bookTicker\",\"u\":11478222941219,\"s\":\"BTCUSDT\",\"ps\":\"BTCUSDT\",\"b\":\"79607.10\",\"B\":\"9.785\",\"a\":\"79607.20\",\"A\":\"1.642\",\"T\":1788563200680,\"E\":1788563200680,\"st\":1}}"}
{"receive_ns":1788563200672387000,"stream":"btcusdt@depth@100ms","event_type":"depthUpdate","event_time_ms":1788563200705,"raw_json":"{\"stream\":\"btcusdt@depth@100ms\",\"data\":{\"e\":\"depthUpdate\",\"E\":1788563200705,\"T\":1788563200702,\"s\":\"BTCUSDT\",\"ps\":\"BTCUSDT\",\"U\":11478222937058,\"u\":11478222942202,\"pu\":11478222936827,\"b\":[[\"1000.00\",\"24.604\"],[\"29107.10\",\"1.078\"],[\"29507.10\",\"1.022\"],[\"63686.00\",\"0.002\"],[\"71646.30\",\"0.002\"],[\"76422.80\",\"0.000\"],[\"78210.00\",\"0.767\"],[\"78492.60\",\"12.725\"],[\"78811.00\",\"4.126\"],[\"79209.00\",\"0.002\"],[\"79209.10\",\"1.777\"],[\"79491.70\",\"0.000\"],[\"79560.20\",\"0.259\"],[\"79581.40\",\"2.324\"],[\"79582.10\",\"0.002\"],[\"79607.10\",\"9.785\"]],\"a\":[[\"79609.00\",\"0.003\"],[\"79617.70\",\"1.120\"],[\"79618.40\",\"0.059\"],[\"79618.80\",\"0.001\"],[\"79618.90\",\"0.000\"],[\"79649.90\",\"0.270\"],[\"79650.80\",\"9.780\"],[\"79653.70\",\"0.008\"],[\"79973.40\",\"1.388\"],[\"80403.30\",\"7.987\"],[\"80562.50\",\"19.091\"]],\"st\":1}}"}
{"receive_ns":1788563200703523000,"stream":"btcusdt@bookTicker","event_type":"bookTicker","event_time_ms":1788563200736,"raw_json":"{\"stream\":\"btcusdt@bookTicker\",\"data\":{\"e\":\"bookTicker\",\"u\":11478222943656,\"s\":\"BTCUSDT\",\"ps\":\"BTCUSDT\",\"b\":\"79607.10\",\"B\":\"9.804\",\"a\":\"79607.20\",\"A\":\"1.642\",\"T\":1788563200736,\"E\":1788563200736,\"st\":1}}"}
{"receive_ns":1788563200703783000,"stream":"btcusdt@bookTicker","event_type":"bookTicker","event_time_ms":1788563200737,"raw_json":"{\"stream\":\"btcusdt@bookTicker\",\"data\":{\"e\":\"bookTicker\",\"u\":11478222943689,\"s\":\"BTCUSDT\",\"ps\":\"BTCUSDT\",\"b\":\"79607.10\",\"B\":\"9.785\",\"a\":\"79607.20\",\"A\":\"1.642\",\"T\":1788563200737,\"E\":1788563200737,\"st\":1}}"}
{"receive_ns":1788563200726480000,"stream":"btcusdt@bookTicker","event_type":"bookTicker","event_time_ms":1788563200761,"raw_json":"{\"stream\":\"btcusdt@bookTicker\",\"data\":{\"e\":\"bookTicker\",\"u\":11478222944759,\"s\":\"BTCUSDT\",\"ps\":\"BTCUSDT\",\"b\":\"79607.10\",\"B\":\"9.785\",\"a\":\"79607.20\",\"A\":\"1.665\",\"T\":1788563200761,\"E\":1788563200761,\"st\":1}}"}
{"receive_ns":1788563200726720000,"stream":"btcusdt@bookTicker","event_type":"bookTicker","event_time_ms":1788563200762,"raw_json":"{\"stream\":\"btcusdt@bookTicker\",\"data\":{\"e\":\"bookTicker\",\"u\":11478222944817,\"s\":\"BTCUSDT\",\"ps\":\"BTCUSDT\",\"b\":\"79607.10\",\"B\":\"9.785\",\"a\":\"79607.20\",\"A\":\"1.664\",\"T\":1788563200762,\"E\":1788563200762,\"st\":1}}"}
{"receive_ns":1788563200751188000,"stream":"btcusdt@bookTicker","event_type":"bookTicker","event_time_ms":1788563200786,"raw_json":"{\"stream\":\"btcusdt@bookTicker\",\"data\":{\"e\":\"bookTicker\",\"u\":11478222946001,\"s\":\"BTCUSDT\",\"ps\":\"BTCUSDT\",\"b\":\"79607.10\",\"B\":\"9.804\",\"a\":\"79607.20\",\"A\":\"1.664\",\"T\":1788563200786,\"E\":1788563200786,\"st\":1}}"}
{"receive_ns":1788563200752671000,"stream":"btcusdt@bookTicker","event_type":"bookTicker","event_time_ms":1788563200787,"raw_json":"{\"stream\":\"btcusdt@bookTicker\",\"data\":{\"e\":\"bookTicker\",\"u\":11478222946032,\"s\":\"BTCUSDT\",\"ps\":\"BTCUSDT\",\"b\":\"79607.10\",\"B\":\"9.785\",\"a\":\"79607.20\",\"A\":\"1.664\",\"T\":1788563200787,\"E\":1788563200787,\"st\":1}}"}
{"receive_ns":1788563200752834000,"stream":"btcusdt@bookTicker","event_type":"bookTicker","event_time_ms":1788563200787,"raw_json":"{\"stream\":\"btcusdt@bookTicker\",\"data\":{\"e\":\"bookTicker\",\"u\":11478222946048,\"s\":\"BTCUSDT\",\"ps\":\"BTCUSDT\",\"b\":\"79607.10\",\"B\":\"9.783\",\"a\":\"79607.20\",\"A\":\"1.664\",\"T\":1788563200787,\"E\":1788563200787,\"st\":1}}"}
{"receive_ns":1788563200752978000,"stream":"btcusdt@bookTicker","event_type":"bookTicker","event_time_ms":1788563200787,"raw_json":"{\"stream\":\"btcusdt@bookTicker\",\"data\":{\"e\":\"bookTicker\",\"u\":11478222946052,\"s\":\"BTCUSDT\",\"ps\":\"BTCUSDT\",\"b\":\"79607.10\",\"B\":\"9.783\",\"a\":\"79607.20\",\"A\":\"1.665\",\"T\":1788563200787,\"E\":1788563200787,\"st\":1}}"}
{"receive_ns":1788563200772426000,"stream":"btcusdt@depth@100ms","event_type":"depthUpdate","event_time_ms":1788563200807,"raw_json":"{\"stream\":\"btcusdt@depth@100ms\",\"data\":{\"e\":\"depthUpdate\",\"E\":1788563200807,\"T\":1788563200806,\"s\":\"BTCUSDT\",\"ps\":\"BTCUSDT\",\"U\":11478222942289,\"u\":11478222947047,\"pu\":11478222942202,\"b\":[[\"29107.10\",\"0.896\"],[\"29507.10\",\"1.204\"],[\"71646.30\",\"0.002\"],[\"76422.80\",\"0.002\"],[\"78638.50\",\"15.353\"],[\"78811.00\",\"4.126\"],[\"79434.00\",\"0.427\"],[\"79453.90\",\"0.706\"],[\"79478.40\",\"0.000\"],[\"79481.50\",\"0.617\"],[\"79487.70\",\"1.080\"],[\"79511.50\",\"0.022\"],[\"79535.40\",\"0.002\"],[\"79603.00\",\"0.000\"],[\"79607.10\",\"9.783\"]],\"a\":[[\"79607.20\",\"1.665\"],[\"79608.80\",\"0.027\"],[\"79609.20\",\"0.592\"],[\"79609.30\",\"0.001\"],[\"79611.20\",\"0.000\"],[\"79622.30\",\"0.061\"],[\"79623.50\",\"0.376\"],[\"79624.80\",\"0.573\"],[\"79627.00\",\"0.627\"],[\"79630.00\",\"0.346\"],[\"79638.40\",\"2.675\"],[\"79645.80\",\"2.223\"],[\"79663.00\",\"0.002\"],[\"79678.90\",\"0.016\"],[\"79730.50\",\"0.352\"],[\"79730.60\",\"0.000\"],[\"79973.40\",\"1.150\"],[\"80403.30\",\"7.987\"],[\"80939.70\",\"0.493\"]],\"st\":1}}"}
{"receive_ns":1788563200811106000,"stream":"btcusdt@bookTicker","event_type":"bookTicker","event_time_ms":1788563200844,"raw_json":"{\"stream\":\"btcusdt@bookTicker\",\"data\":{\"e\":\"bookTicker\",\"u\":11478222949033,\"s\":\"BTCUSDT\",\"ps\":\"BTCUSDT\",\"b\":\"79607.10\",\"B\":\"9.791\",\"a\":\"79607.20\",\"A\":\"1.665\",\"T\":1788563200844,\"E\":1788563200844,\"st\":1}}"}
{"receive_ns":1788563200811299000,"stream":"btcusdt@bookTicker","event_type":"bookTicker","event_time_ms":1788563200844,"raw_json":"{\"stream\":\"btcusdt@bookTicker\",\"data\":{\"e\":\"bookTicker\",\"u\":11478222949036,\"s\":\"BTCUSDT\",\"ps\":\"BTCUSDT\",\"b\":\"79607.10\",\"B\":\"9.810\",\"a\":\"79607.20\",\"A\":\"1.665\",\"T\":1788563200844,\"E\":1788563200844,\"st\":1}}"}
{"receive_ns":1788563200811464000,"stream":"btcusdt@bookTicker","event_type":"bookTicker","event_time_ms":1788563200844,"raw_json":"{\"stream\":\"btcusdt@bookTicker\",\"data\":{\"e\":\"bookTicker\",\"u\":11478222949086,\"s\":\"BTCUSDT\",\"ps\":\"BTCUSDT\",\"b\":\"79607.10\",\"B\":\"9.802\",\"a\":\"79607.20\",\"A\":\"1.665\",\"T\":1788563200844,\"E\":1788563200844,\"st\":1}}"}
{"receive_ns":1788563200811602000,"stream":"btcusdt@bookTicker","event_type":"bookTicker","event_time_ms":1788563200845,"raw_json":"{\"stream\":\"btcusdt@bookTicker\",\"data\":{\"e\":\"bookTicker\",\"u\":11478222949092,\"s\":\"BTCUSDT\",\"ps\":\"BTCUSDT\",\"b\":\"79607.10\",\"B\":\"9.783\",\"a\":\"79607.20\",\"A\":\"1.665\",\"T\":1788563200844,\"E\":1788563200845,\"st\":1}}"}
{"receive_ns":1788563200811789000,"stream":"btcusdt@bookTicker","event_type":"bookTicker","event_time_ms":1788563200845,"raw_json":"{\"stream\":\"btcusdt@bookTicker\",\"data\":{\"e\":\"bookTicker\",\"u\":11478222949160,\"s\":\"BTCUSDT\",\"ps\":\"BTCUSDT\",\"b\":\"79607.10\",\"B\":\"9.785\",\"a\":\"79607.20\",\"A\":\"1.665\",\"T\":1788563200845,\"E\":1788563200845,\"st\":1}}"}
{"receive_ns":1788563200873631000,"stream":"btcusdt@depth@100ms","event_type":"depthUpdate","event_time_ms":1788563200909,"raw_json":"{\"stream\":\"btcusdt@depth@100ms\",\"data\":{\"e\":\"depthUpdate\",\"E\":1788563200909,\"T\":1788563200908,\"s\":\"BTCUSDT\",\"ps\":\"BTCUSDT\",\"U\":11478222947118,\"u\":11478222952417,\"pu\":11478222947047,\"b\":[[\"1000.00\",\"24.604\"],[\"29107.10\",\"0.721\"],[\"29507.10\",\"1.379\"],[\"63686.00\",\"0.006\"],[\"71646.30\",\"0.002\"],[\"71681.00\",\"0.000\"],[\"76422.80\",\"0.000\"],[\"78492.60\",\"14.633\"],[\"78811.00\",\"4.126\"],[\"79189.50\",\"0.000\"],[\"79209.00\",\"0.001\"],[\"79209.10\",\"1.777\"],[\"79236.90\",\"0.247\"],[\"79309.00\",\"0.017\"],[\"79434.00\",\"0.176\"],[\"79487.70\",\"2.209\"],[\"79491.70\",\"0.326\"],[\"79591.60\",\"0.149\"],[\"79601.70\",\"0.328\"],[\"79602.30\",\"0.201\"],[\"79602.40\",\"0.058\"],[\"79604.40\",\"0.002\"],[\"79606.60\",\"0.028\"],[\"79606.80\",\"0.030\"],[\"79607.00\",\"0.007\"],[\"79607.10\",\"9.785\"]],\"a\":[[\"79607.50\",\"0.026\"],[\"79608.10\",\"0.027\"],[\"79609.20\",\"0.251\"],[\"79610.40\",\"1.212\"],[\"79611.10\",\"0.077\"],[\"79611.20\",\"0.251\"],[\"79618.40\",\"0.000\"],[\"79630.10\",\"0.014\"],[\"79638.50\",\"0.001\"],[\"79645.90\",\"3.130\"],[\"79648.30\",\"0.860\"],[\"79650.80\",\"0.003\"],[\"79788.80\",\"0.006\"],[\"79973.40\",\"1.913\"],[\"80239.20\",\"1.742\"],[\"80403.30\",\"8.062\"],[\"80602.30\",\"4.397\"]],\"st\":1}}"}
{"receive_ns":1788563200876727000,"stream":"btcusdt@bookTicker","event_type":"bookTicker","event_time_ms":1788563200912,"raw_json":"{\"stream\":\"btcusdt@bookTicker\",\"data\":{\"e\":\"bookTicker\",\"u\":11478222952694,\"s\":\"BTCUSDT\",\"ps\":\"BTCUSDT\",\"b\":\"79607.10\",\"B\":\"9.780\",\"a\":\"79607.20\",\"A\":\"1.665\",\"T\":1788563200912,\"E\":1788563200912,\"st\":1}}"}
{"receive_ns":1788563200895615000,"stream":"btcusdt@bookTicker","event_type":"bookTicker","event_time_ms":1788563200926,"raw_json":"{\"stream\":\"btcusdt@bookTicker\",\"data\":{\"e\":\"bookTicker\",\"u\":11478222953546,\"s\":\"BTCUSDT\",\"ps\":\"BTCUSDT\",\"b\":\"79607.10\",\"B\":\"9.799\",\"a\":\"79607.20\",\"A\":\"1.665\",\"T\":1788563200926,\"E\":1788563200926,\"st\":1}}"}
{"receive_ns":1788563200895814000,"stream":"btcusdt@bookTicker","event_type":"bookTicker","event_time_ms":1788563200926,"raw_json":"{\"stream\":\"btcusdt@bookTicker\",\"data\":{\"e\":\"bookTicker\",\"u\":11478222953550,\"s\":\"BTCUSDT\",\"ps\":\"BTCUSDT\",\"b\":\"79607.10\",\"B\":\"9.807\",\"a\":\"79607.20\",\"A\":\"1.665\",\"T\":1788563200926,\"E\":1788563200926,\"st\":1}}"}
{"receive_ns":1788563200896013000,"stream":"btcusdt@bookTicker","event_type":"bookTicker","event_time_ms":1788563200926,"raw_json":"{\"stream\":\"btcusdt@bookTicker\",\"data\":{\"e\":\"bookTicker\",\"u\":11478222953604,\"s\":\"BTCUSDT\",\"ps\":\"BTCUSDT\",\"b\":\"79607.10\",\"B\":\"9.788\",\"a\":\"79607.20\",\"A\":\"1.665\",\"T\":1788563200926,\"E\":1788563200926,\"st\":1}}"}
{"receive_ns":1788563200896155000,"stream":"btcusdt@bookTicker","event_type":"bookTicker","event_time_ms":1788563200927,"raw_json":"{\"stream\":\"btcusdt@bookTicker\",\"data\":{\"e\":\"bookTicker\",\"u\":11478222953611,\"s\":\"BTCUSDT\",\"ps\":\"BTCUSDT\",\"b\":\"79607.10\",\"B\":\"9.780\",\"a\":\"79607.20\",\"A\":\"1.665\",\"T\":1788563200926,\"E\":1788563200927,\"st\":1}}"}
{"receive_ns":1788563200977174000,"stream":"btcusdt@depth@100ms","event_type":"depthUpdate","event_time_ms":1788563201011,"raw_json":"{\"stream\":\"btcusdt@depth@100ms\",\"data\":{\"e\":\"depthUpdate\",\"E\":1788563201011,\"T\":1788563201009,\"s\":\"BTCUSDT\",\"ps\":\"BTCUSDT\",\"U\":11478222952531,\"u\":11478222957762,\"pu\":11478222952417,\"b\":[[\"1000.00\",\"24.604\"],[\"29107.10\",\"0.539\"],[\"29507.10\",\"1.561\"],[\"63686.00\",\"0.002\"],[\"71646.30\",\"0.002\"],[\"76422.80\",\"0.002\"],[\"78439.50\",\"8.561\"],[\"78811.00\",\"4.126\"],[\"79209.10\",\"1.787\"],[\"79453.90\",\"0.204\"],[\"79478.50\",\"0.125\"],[\"79479.20\",\"0.000\"],[\"79481.50\",\"0.000\"],[\"79487.70\",\"1.707\"],[\"79491.70\",\"1.330\"],[\"79555.60\",\"0.002\"],[\"79583.40\",\"1.875\"],[\"79601.70\",\"0.404\"],[\"79604.50\",\"0.001\"],[\"79606.90\",\"0.032\"],[\"79607.00\",\"0.007\"],[\"79607.10\",\"9.780\"]],\"a\":[[\"79607.50\",\"0.000\"],[\"79608.00\",\"0.029\"],[\"79611.00\",\"0.003\"],[\"79621.70\",\"0.003\"],[\"79623.30\",\"0.045\"],[\"79625.90\",\"0.453\"],[\"79627.10\",\"0.001\"],[\"79670.60\",\"0.001\"],[\"79730.50\",\"0.000\"],[\"79973.40\",\"1.913\"],[\"80005.30\",\"0.002\"],[\"80403.30\",\"8.062\"],[\"80707.00\",\"11.045\"],[\"81199.30\",\"0.018\"]],\"st\":1}}"}
{"receive_ns":1788563201077954000,"stream":"btcusdt@depth@100ms","event_type":"depthUpdate","event_time_ms":1788563201113,"raw_json":"{\"stream\":\"btcusdt@depth@100ms\",\"data\":{\"e\":\"depthUpdate\",\"E\":1788563201113,\"T\":1788563201109,\"s\":\"BTCUSDT\",\"ps\":\"BTCUSDT\",\"U\":11478222957865,\"u\":11478222963460,\"pu\":11478222957762,\"b\":[[\"29107.10\",\"0.364\"],[\"29507.10\",\"1.736\"],[\"63685.70\",\"0.001\"],[\"63686.00\",\"0.002\"],[\"71646.30\",\"0.002\"],[\"78389.30\",\"0.008\"],[\"78394.60\",\"0.021\"],[\"78706.00\",\"0.835\"],[\"78811.00\",\"4.126\"],[\"79209.10\",\"1.787\"],[\"79236.90\",\"0.247\"],[\"79434.00\",\"0.176\"],[\"79442.10\",\"2.398\"],[\"79478.50\",\"0.000\"],[\"79481.50\",\"0.617\"],[\"79487.70\",\"1.707\"],[\"79491.70\",\"1.330\"],[\"79531.30\",\"23.450\"],[\"79536.70\",\"0.000\"],[\"79557.70\",\"0.001\"],[\"79592.80\",\"0.003\"]],\"a\":[[\"79607.80\",\"0.027\"],[\"79609.20\",\"0.000\"],[\"79611.20\",\"0.592\"],[\"79670.90\",\"0.001\"],[\"79730.40\",\"0.353\"],[\"79769.80\",\"1.953\"],[\"79770.10\",\"0.001\"],[\"79973.40\",\"1.913\"],[\"80403.30\",\"8.062\"],[\"80819.60\",\"0.013\"],[\"80824.80\",\"0.000\"]],\"st\":1}}"}
{"receive_ns":1788563201080291000,"stream":"btcusdt@bookTicker","event_type":"bookTicker","event_time_ms":1788563201114,"raw_json":"{\"stream\":\"btcusdt@bookTicker\",\"data\":{\"e\":\"bookTicker\",\"u\":11478222963687,\"s\":\"BTCUSDT\",\"ps\":\"BTCUSDT\",\"b\":\"79607.10\",\"B\":\"9.783\",\"a\":\"79607.20\",\"A\":\"1.665\",\"T\":1788563201114,\"E\":1788563201114,\"st\":1}}"}
{"receive_ns":1788563201086864000,"stream":"btcusdt@bookTicker","event_type":"bookTicker","event_time_ms":1788563201122,"raw_json":"{\"stream\":\"btcusdt@bookTicker\",\"data\":{\"e\":\"bookTicker\",\"u\":11478222964080,\"s\":\"BTCUSDT\",\"ps\":\"BTCUSDT\",\"b\":\"79607.10\",\"B\":\"9.802\",\"a\":\"79607.20\",\"A\":\"1.665\",\"T\":1788563201122,\"E\":1788563201122,\"st\":1}}"}
{"receive_ns":1788563201087125000,"stream":"btcusdt@bookTicker","event_type":"bookTicker","event_time_ms":1788563201122,"raw_json":"{\"stream\":\"btcusdt@bookTicker\",\"data\":{\"e\":\"bookTicker\",\"u\":11478222964112,\"s\":\"BTCUSDT\",\"ps\":\"BTCUSDT\",\"b\":\"79607.10\",\"B\":\"9.783\",\"a\":\"79607.20\",\"A\":\"1.665\",\"T\":1788563201122,\"E\":1788563201122,\"st\":1}}"}
{"receive_ns":1788563201119440000,"stream":"btcusdt@bookTicker","event_type":"bookTicker","event_time_ms":1788563201154,"raw_json":"{\"stream\":\"btcusdt@bookTicker\",\"data\":{\"e\":\"bookTicker\",\"u\":11478222965519,\"s\":\"BTCUSDT\",\"ps\":\"BTCUSDT\",\"b\":\"79607.10\",\"B\":\"9.780\",\"a\":\"79607.20\",\"A\":\"1.665\",\"T\":1788563201154,\"E\":1788563201154,\"st\":1}}"}
{"receive_ns":1788563201119650000,"stream":"btcusdt@trade","event_type":"trade","event_time_ms":1788563201154,"raw_json":"{\"stream\":\"btcusdt@trade\",\"data\":{\"e\":\"trade\",\"E\":1788563201154,\"T\":1788563201154,\"s\":\"BTCUSDT\",\"t\":8054082685,\"p\":\"79607.10\",\"q\":\"0.003\",\"X\":\"MARKET\",\"m\":true,\"st\":1}}"}
{"receive_ns":1788563201119846000,"stream":"btcusdt@bookTicker","event_type":"bookTicker","event_time_ms":1788563201155,"raw_json":"{\"stream\":\"btcusdt@bookTicker\",\"data\":{\"e\":\"bookTicker\",\"u\":11478222965608,\"s\":\"BTCUSDT\",\"ps\":\"BTCUSDT\",\"b\":\"79607.10\",\"B\":\"9.799\",\"a\":\"79607.20\",\"A\":\"1.665\",\"T\":1788563201155,\"E\":1788563201155,\"st\":1}}"}
{"receive_ns":1788563201119989000,"stream":"btcusdt@bookTicker","event_type":"bookTicker","event_time_ms":1788563201155,"raw_json":"{\"stream\":\"btcusdt@bookTicker\",\"data\":{\"e\":\"bookTicker\",\"u\":11478222965626,\"s\":\"BTCUSDT\",\"ps\":\"BTCUSDT\",\"b\":\"79607.10\",\"B\":\"9.807\",\"a\":\"79607.20\",\"A\":\"1.665\",\"T\":1788563201155,\"E\":1788563201155,\"st\":1}}"}
{"receive_ns":1788563201120548000,"stream":"btcusdt@bookTicker","event_type":"bookTicker","event_time_ms":1788563201156,"raw_json":"{\"stream\":\"btcusdt@bookTicker\",\"data\":{\"e\":\"bookTicker\",\"u\":11478222965747,\"s\":\"BTCUSDT\",\"ps\":\"BTCUSDT\",\"b\":\"79607.10\",\"B\":\"9.788\",\"a\":\"79607.20\",\"A\":\"1.665\",\"T\":1788563201156,\"E\":1788563201156,\"st\":1}}"}
{"receive_ns":1788563201120711000,"stream":"btcusdt@bookTicker","event_type":"bookTicker","event_time_ms":1788563201156,"raw_json":"{\"stream\":\"btcusdt@bookTicker\",\"data\":{\"e\":\"bookTicker\",\"u\":11478222965752,\"s\":\"BTCUSDT\",\"ps\":\"BTCUSDT\",\"b\":\"79607.10\",\"B\":\"9.780\",\"a\":\"79607.20\",\"A\":\"1.665\",\"T\":1788563201156,\"E\":1788563201156,\"st\":1}}"}
{"receive_ns":1788563201146920000,"stream":"btcusdt@bookTicker","event_type":"bookTicker","event_time_ms":1788563201182,"raw_json":"{\"stream\":\"btcusdt@bookTicker\",\"data\":{\"e\":\"bookTicker\",\"u\":11478222967149,\"s\":\"BTCUSDT\",\"ps\":\"BTCUSDT\",\"b\":\"79607.10\",\"B\":\"9.575\",\"a\":\"79607.20\",\"A\":\"1.665\",\"T\":1788563201182,\"E\":1788563201182,\"st\":1}}"}
{"receive_ns":1788563201151700000,"stream":"btcusdt@bookTicker","event_type":"bookTicker","event_time_ms":1788563201185,"raw_json":"{\"stream\":\"btcusdt@bookTicker\",\"data\":{\"e\":\"bookTicker\",\"u\":11478222967345,\"s\":\"BTCUSDT\",\"ps\":\"BTCUSDT\",\"b\":\"79607.10\",\"B\":\"9.781\",\"a\":\"79607.20\",\"A\":\"1.665\",\"T\":1788563201184,\"E\":1788563201185,\"st\":1}}"}
{"receive_ns":1788563201180190000,"stream":"btcusdt@depth@100ms","event_type":"depthUpdate","event_time_ms":1788563201215,"raw_json":"{\"stream\":\"btcusdt@depth@100ms\",\"data\":{\"e\":\"depthUpdate\",\"E\":1788563201215,\"T\":1788563201214,\"s\":\"BTCUSDT\",\"ps\":\"BTCUSDT\",\"U\":11478222963640,\"u\":11478222968572,\"pu\":11478222963460,\"b\":[[\"1000.00\",\"24.604\"],[\"29107.10\",\"0.238\"],[\"29407.10\",\"0.056\"],[\"29507.10\",\"1.806\"],[\"71646.30\",\"0.002\"],[\"76418.40\",\"0.000\"],[\"76422.80\",\"0.000\"],[\"78253.80\",\"5.867\"],[\"78389.30\",\"0.017\"],[\"78394.60\",\"0.028\"],[\"78558.90\",\"13.601\"],[\"78691.60\",\"2.285\"],[\"78811.00\",\"4.126\"],[\"79478.40\",\"0.125\"],[\"79487.70\",\"2.209\"],[\"79491.70\",\"0.326\"],[\"79531.30\",\"0.011\"],[\"79534.00\",\"23.452\"],[\"79575.30\",\"0.001\"],[\"79576.20\",\"0.001\"],[\"79576.50\",\"0.456\"],[\"79599.80\",\"0.000\"],[\"79607.10\",\"9.781\"]],\"a\":[[\"79610.40\",\"1.271\"],[\"79679.00\",\"5.671\"],[\"79973.40\",\"1.494\"],[\"80403.30\",\"8.062\"],[\"80522.90\",\"0.000\"],[\"80557.60\",\"11.817\"],[\"80819.60\",\"0.020\"]],\"st\":1}}"}
{"receive_ns":1788563201194763000,"stream":"btcusdt@bookTicker","event_type":"bookTicker","event_time_ms":1788563201228,"raw_json":"{\"stream\":\"btcusdt@bookTicker\",\"data\":{\"e\":\"bookTicker\",\"u\":11478222969174,\"s\":\"BTCUSDT\",\"ps\":\"BTCUSDT\",\"b\":\"79607.10\",\"B\":\"9.800\",\"a\":\"79607.20\",\"A\":\"1.665\",\"T\":1788563201228,\"E\":1788563201228,\"st\":1}}"}
{"receive_ns":1788563201195007000,"stream":"btcusdt@bookTicker","event_type":"bookTicker","event_time_ms":1788563201228,"raw_json":"{\"stream\":\"btcusdt@bookTicker\",\"data\":{\"e\":\"bookTicker\",\"u\":11478222969196,\"s\":\"BTCUSDT\",\"ps\":\"BTCUSDT\",\"b\":\"79607.10\",\"B\":\"9.808\",\"a\":\"79607.20\",\"A\":\"1.665\",\"T\":1788563201228,\"E\":1788563201228,\"st\":1}}"}
{"receive_ns":1788563201195175000,"stream":"btcusdt@bookTicker","event_type":"bookTicker","event_time_ms":1788563201228,"raw_json":"{\"stream\":\"btcusdt@bookTicker\",\"data\":{\"e\":\"bookTicker\",\"u\":11478222969220,\"s\":\"BTCUSDT\",\"ps\":\"BTCUSDT\",\"b\":\"79607.10\",\"B\":\"9.812\",\"a\":\"79607.20\",\"A\":\"1.665\",\"T\":1788563201228,\"E\":1788563201228,\"st\":1}}"}
{"receive_ns":1788563201196241000,"stream":"btcusdt@bookTicker","event_type":"bookTicker","event_time_ms":1788563201228,"raw_json":"{\"stream\":\"btcusdt@bookTicker\",\"data\":{\"e\":\"bookTicker\",\"u\":11478222969234,\"s\":\"BTCUSDT\",\"ps\":\"BTCUSDT\",\"b\":\"79607.10\",\"B\":\"9.793\",\"a\":\"79607.20\",\"A\":\"1.665\",\"T\":1788563201228,\"E\":1788563201228,\"st\":1}}"}
{"receive_ns":1788563201196403000,"stream":"btcusdt@bookTicker","event_type":"bookTicker","event_time_ms":1788563201229,"raw_json":"{\"stream\":\"btcusdt@bookTicker\",\"data\":{\"e\":\"bookTicker\",\"u\":11478222969257,\"s\":\"BTCUSDT\",\"ps\":\"BTCUSDT\",\"b\":\"79607.10\",\"B\":\"9.785\",\"a\":\"79607.20\",\"A\":\"1.665\",\"T\":1788563201228,\"E\":1788563201229,\"st\":1}}"}
{"receive_ns":1788563201203500000,"stream":"btcusdt@bookTicker","event_type":"bookTicker","event_time_ms":1788563201237,"raw_json":"{\"stream\":\"btcusdt@bookTicker\",\"data\":{\"e\":\"bookTicker\",\"u\":11478222969578,\"s\":\"BTCUSDT\",\"ps\":\"BTCUSDT\",\"b\":\"79607.10\",\"B\":\"9.554\",\"a\":\"79607.20\",\"A\":\"1.665\",\"T\":1788563201237,\"E\":1788563201237,\"st\":1}}"}
{"receive_ns":1788563201207976000,"stream":"btcusdt@bookTicker","event_type":"bookTicker","event_time_ms":1788563201241,"raw_json":"{\"stream\":\"btcusdt@bookTicker\",\"data\":{\"e\":\"bookTicker\",\"u\":11478222969783,\"s\":\"BTCUSDT\",\"ps\":\"BTCUSDT\",\"b\":\"79607.10\",\"B\":\"9.784\",\"a\":\"79607.20\",\"A\":\"1.665\",\"T\":1788563201240,\"E\":1788563201241,\"st\":1}}"}
{"receive_ns":1788563201250948000,"stream":"btcusdt@bookTicker","event_type":"bookTicker","event_time_ms":1788563201285,"raw_json":"{\"stream\":\"btcusdt@bookTicker\",\"data\":{\"e\":\"bookTicker\",\"u\":11478222972786,\"s\":\"BTCUSDT\",\"ps\":\"BTCUSDT\",\"b\":\"79607.10\",\"B\":\"9.436\",\"a\":\"79607.20\",\"A\":\"1.665\",\"T\":1788563201285,\"E\":1788563201285,\"st\":1}}"}
{"receive_ns":1788563201254553000,"stream":"btcusdt@bookTicker","event_type":"bookTicker","event_time_ms":1788563201288,"raw_json":"{\"stream\":\"btcusdt@bookTicker\",\"data\":{\"e\":\"bookTicker\",\"u\":11478222973182,\"s\":\"BTCUSDT\",\"ps\":\"BTCUSDT\",\"b\":\"79607.10\",\"B\":\"9.795\",\"a\":\"79607.20\",\"A\":\"1.665\",\"T\":1788563201287,\"E\":1788563201288,\"st\":1}}"}
{"receive_ns":1788563201282762000,"stream":"btcusdt@depth@100ms","event_type":"depthUpdate","event_time_ms":1788563201317,"raw_json":"{\"stream\":\"btcusdt@depth@100ms\",\"data\":{\"e\":\"depthUpdate\",\"E\":1788563201317,\"T\":1788563201314,\"s\":\"BTCUSDT\",\"ps\":\"BTCUSDT\",\"U\":11478222968620,\"u\":11478222975116,\"pu\":11478222968572,\"b\":[[\"1000.00\",\"24.604\"],[\"29107.10\",\"0.119\"],[\"29407.10\",\"0.112\"],[\"29507.10\",\"1.869\"],[\"71646.30\",\"0.002\"],[\"76422.80\",\"0.002\"],[\"78612.00\",\"2.198\"],[\"78739.40\",\"2.217\"],[\"78811.00\",\"4.126\"],[\"79204.30\",\"0.442\"],[\"79207.70\",\"0.246\"],[\"79209.10\",\"1.646\"],[\"79236.90\",\"0.015\"],[\"79434.00\",\"0.076\"],[\"79481.50\",\"0.000\"],[\"79487.70\",\"2.209\"],[\"79491.70\",\"0.502\"],[\"79602.10\",\"0.001\"],[\"79602.30\",\"0.200\"],[\"79607.10\",\"9.795\"]],\"a\":[[\"79607.70\",\"0.026\"],[\"79610.90\",\"0.001\"],[\"79611.20\",\"0.000\"],[\"79730.40\",\"0.001\"],[\"79973.40\",\"1.713\"],[\"80403.30\",\"8.062\"],[\"80467.90\",\"2.460\"],[\"80824.80\",\"0.008\"],[\"81199.30\",\"0.021\"],[\"83587.50\",\"0.007\"]],\"st\":1}}"}
{"receive_ns":1788563201307141000,"stream":"btcusdt@bookTicker","event_type":"bookTicker","event_time_ms":1788563201333,"raw_json":"{\"stream\":\"btcusdt@bookTicker\",\"data\":{\"e\":\"bookTicker\",\"u\":11478222976220,\"s\":\"BTCUSDT\",\"ps\":\"BTCUSDT\",\"b\":\"79607.10\",\"B\":\"9.814\",\"a\":\"79607.20\",\"A\":\"1.665\",\"T\":1788563201333,\"E\":1788563201333,\"st\":1}}"}
{"receive_ns":1788563201307371000,"stream":"btcusdt@bookTicker","event_type":"bookTicker","event_time_ms":1788563201334,"raw_json":"{\"stream\":\"btcusdt@bookTicker\",\"data\":{\"e\":\"bookTicker\",\"u\":11478222976263,\"s\":\"BTCUSDT\",\"ps\":\"BTCUSDT\",\"b\":\"79607.10\",\"B\":\"9.795\",\"a\":\"79607.20\",\"A\":\"1.665\",\"T\":1788563201334,\"E\":1788563201334,\"st\":1}}"}
{"receive_ns":1788563201307542000,"stream":"btcusdt@bookTicker","event_type":"bookTicker","event_time_ms":1788563201336,"raw_json":"{\"stream\":\"btcusdt@bookTicker\",\"data\":{\"e\":\"bookTicker\",\"u\":11478222976406,\"s\":\"BTCUSDT\",\"ps\":\"BTCUSDT\",\"b\":\"79607.10\",\"B\":\"9.814\",\"a\":\"79607.20\",\"A\":\"1.665\",\"T\":1788563201335,\"E\":1788563201336,\"st\":1}}"}
{"receive_ns":1788563201307687000,"stream":"btcusdt@bookTicker","event_type":"bookTicker","event_time_ms":1788563201336,"raw_json":"{\"stream\":\"btcusdt@bookTicker\",\"data\":{\"e\":\"bookTicker\",\"u\":11478222976428,\"s\":\"BTCUSDT\",\"ps\":\"BTCUSDT\",\"b\":\"79607.10\",\"B\":\"9.822\",\"a\":\"79607.20\",\"A\":\"1.665\",\"T\":1788563201335,\"E\":1788563201336,\"st\":1}}"}
{"receive_ns":1788563201307849000,"stream":"btcusdt@bookTicker","event_type":"bookTicker","event_time_ms":1788563201336,"raw_json":"{\"stream\":\"btcusdt@bookTicker\",\"data\":{\"e\":\"bookTicker\",\"u\":11478222976467,\"s\":\"BTCUSDT\",\"ps\":\"BTCUSDT\",\"b\":\"79607.10\",\"B\":\"9.803\",\"a\":\"79607.20\",\"A\":\"1.665\",\"T\":1788563201336,\"E\":1788563201336,\"st\":1}}"}
{"receive_ns":1788563201307982000,"stream":"btcusdt@bookTicker","event_type":"bookTicker","event_time_ms":1788563201336,"raw_json":"{\"stream\":\"btcusdt@bookTicker\",\"data\":{\"e\":\"bookTicker\",\"u\":11478222976469,\"s\":\"BTCUSDT\",\"ps\":\"BTCUSDT\",\"b\":\"79607.10\",\"B\":\"9.795\",\"a\":\"79607.20\",\"A\":\"1.665\",\"T\":1788563201336,\"E\":1788563201336,\"st\":1}}"}
{"receive_ns":1788563201353860000,"stream":"btcusdt@bookTicker","event_type":"bookTicker","event_time_ms":1788563201386,"raw_json":"{\"stream\":\"btcusdt@bookTicker\",\"data\":{\"e\":\"bookTicker\",\"u\":11478222978703,\"s\":\"BTCUSDT\",\"ps\":\"BTCUSDT\",\"b\":\"79607.10\",\"B\":\"9.814\",\"a\":\"79607.20\",\"A\":\"1.665\",\"T\":1788563201386,\"E\":1788563201386,\"st\":1}}"}
{"receive_ns":1788563201354055000,"stream":"btcusdt@bookTicker","event_type":"bookTicker","event_time_ms":1788563201386,"raw_json":"{\"stream\":\"btcusdt@bookTicker\",\"data\":{\"e\":\"bookTicker\",\"u\":11478222978710,\"s\":\"BTCUSDT\",\"ps\":\"BTCUSDT\",\"b\":\"79607.10\",\"B\":\"9.814\",\"a\":\"79607.20\",\"A\":\"1.691\",\"T\":1788563201386,\"E\":1788563201386,\"st\":1}}"}
{"receive_ns":1788563201357076000,"stream":"btcusdt@bookTicker","event_type":"bookTicker","event_time_ms":1788563201386,"raw_json":"{\"stream\":\"btcusdt@bookTicker\",\"data\":{\"e\":\"bookTicker\",\"u\":11478222978758,\"s\":\"BTCUSDT\",\"ps\":\"BTCUSDT\",\"b\":\"79607.10\",\"B\":\"9.795\",\"a\":\"79607.20\",\"A\":\"1.691\",\"T\":1788563201386,\"E\":1788563201386,\"st\":1}}"}
{"receive_ns":1788563201357269000,"stream":"btcusdt@bookTicker","event_type":"bookTicker","event_time_ms":1788563201387,"raw_json":"{\"stream\":\"btcusdt@bookTicker\",\"data\":{\"e\":\"bookTicker\",\"u\":11478222978818,\"s\":\"BTCUSDT\",\"ps\":\"BTCUSDT\",\"b\":\"79607.10\",\"B\":\"9.795\",\"a\":\"79607.20\",\"A\":\"1.690\",\"T\":1788563201387,\"E\":1788563201387,\"st\":1}}"}
{"receive_ns":1788563201357429000,"stream":"btcusdt@bookTicker","event_type":"bookTicker","event_time_ms":1788563201390,"raw_json":"{\"stream\":\"btcusdt@bookTicker\",\"data\":{\"e\":\"bookTicker\",\"u\":11478222978967,\"s\":\"BTCUSDT\",\"ps\":\"BTCUSDT\",\"b\":\"79607.10\",\"B\":\"9.803\",\"a\":\"79607.20\",\"A\":\"1.690\",\"T\":1788563201389,\"E\":1788563201390,\"st\":1}}"}
{"receive_ns":1788563201357562000,"stream":"btcusdt@bookTicker","event_type":"bookTicker","event_time_ms":1788563201390,"raw_json":"{\"stream\":\"btcusdt@bookTicker\",\"data\":{\"e\":\"bookTicker\",\"u\":11478222979008,\"s\":\"BTCUSDT\",\"ps\":\"BTCUSDT\",\"b\":\"79607.10\",\"B\":\"9.822\",\"a\":\"79607.20\",\"A\":\"1.690\",\"T\":1788563201390,\"E\":1788563201390,\"st\":1}}"}
{"receive_ns":1788563201357717000,"stream":"btcusdt@bookTicker","event_type":"bookTicker","event_time_ms":1788563201390,"raw_json":"{\"stream\":\"btcusdt@bookTicker\",\"data\":{\"e\":\"bookTicker\",\"u\":11478222979035,\"s\":\"BTCUSDT\",\"ps\":\"BTCUSDT\",\"b\":\"79607.10\",\"B\":\"9.814\",\"a\":\"79607.20\",\"A\":\"1.690\",\"T\":1788563201390,\"E\":1788563201390,\"st\":1}}"}
{"receive_ns":1788563201357873000,"stream":"btcusdt@bookTicker","event_type":"bookTicker","event_time_ms":1788563201391,"raw_json":"{\"stream\":\"btcusdt@bookTicker\",\"data\":{\"e\":\"bookTicker\",\"u\":11478222979040,\"s\":\"BTCUSDT\",\"ps\":\"BTCUSDT\",\"b\":\"79607.10\",\"B\":\"9.795\",\"a\":\"79607.20\",\"A\":\"1.690\",\"T\":1788563201390,\"E\":1788563201391,\"st\":1}}"}
{"receive_ns":1788563201358025000,"stream":"btcusdt@bookTicker","event_type":"bookTicker","event_time_ms":1788563201391,"raw_json":"{\"stream\":\"btcusdt@bookTicker\",\"data\":{\"e\":\"bookTicker\",\"u\":11478222979052,\"s\":\"BTCUSDT\",\"ps\":\"BTCUSDT\",\"b\":\"79607.10\",\"B\":\"9.795\",\"a\":\"79607.20\",\"A\":\"1.691\",\"T\":1788563201391,\"E\":1788563201391,\"st\":1}}"}
{"receive_ns":1788563201381721000,"stream":"btcusdt@bookTicker","event_type":"bookTicker","event_time_ms":1788563201416,"raw_json":"{\"stream\":\"btcusdt@bookTicker\",\"data\":{\"e\":\"bookTicker\",\"u\":11478222980266,\"s\":\"BTCUSDT\",\"ps\":\"BTCUSDT\",\"b\":\"79607.10\",\"B\":\"9.803\",\"a\":\"79607.20\",\"A\":\"1.691\",\"T\":1788563201416,\"E\":1788563201416,\"st\":1}}"}
{"receive_ns":1788563201381922000,"stream":"btcusdt@bookTicker","event_type":"bookTicker","event_time_ms":1788563201416,"raw_json":"{\"stream\":\"btcusdt@bookTicker\",\"data\":{\"e\":\"bookTicker\",\"u\":11478222980273,\"s\":\"BTCUSDT\",\"ps\":\"BTCUSDT\",\"b\":\"79607.10\",\"B\":\"9.822\",\"a\":\"79607.20\",\"A\":\"1.691\",\"T\":1788563201416,\"E\":1788563201416,\"st\":1}}"}
{"receive_ns":1788563201382121000,"stream":"btcusdt@bookTicker","event_type":"bookTicker","event_time_ms":1788563201417,"raw_json":"{\"stream\":\"btcusdt@bookTicker\",\"data\":{\"e\":\"bookTicker\",\"u\":11478222980328,\"s\":\"BTCUSDT\",\"ps\":\"BTCUSDT\",\"b\":\"79607.10\",\"B\":\"9.814\",\"a\":\"79607.20\",\"A\":\"1.691\",\"T\":1788563201416,\"E\":1788563201417,\"st\":1}}"}
{"receive_ns":1788563201382265000,"stream":"btcusdt@bookTicker","event_type":"bookTicker","event_time_ms":1788563201417,"raw_json":"{\"stream\":\"btcusdt@bookTicker\",\"data\":{\"e\":\"bookTicker\",\"u\":11478222980329,\"s\":\"BTCUSDT\",\"ps\":\"BTCUSDT\",\"b\":\"79607.10\",\"B\":\"9.795\",\"a\":\"79607.20\",\"A\":\"1.691\",\"T\":1788563201416,\"E\":1788563201417,\"st\":1}}"}
{"receive_ns":1788563201383037000,"stream":"btcusdt@depth@100ms","event_type":"depthUpdate","event_time_ms":1788563201419,"raw_json":"{\"stream\":\"btcusdt@depth@100ms\",\"data\":{\"e\":\"depthUpdate\",\"E\":1788563201419,\"T\":1788563201418,\"s\":\"BTCUSDT\",\"ps\":\"BTCUSDT\",\"U\":11478222975347,\"u\":11478222980420,\"pu\":11478222975116,\"b\":[[\"29107.10\",\"0.014\"],[\"29407.10\",\"0.189\"],[\"29507.10\",\"1.897\"],[\"71646.30\",\"0.002\"],[\"76422.80\",\"0.000\"],[\"78811.00\",\"4.126\"],[\"79209.10\",\"1.787\"],[\"79236.90\",\"0.247\"],[\"79442.10\",\"2.415\"],[\"79481.50\",\"0.617\"],[\"79487.70\",\"1.205\"],[\"79491.70\",\"0.928\"],[\"79575.30\",\"0.001\"],[\"79576.50\",\"0.004\"],[\"79577.40\",\"0.452\"],[\"79600.20\",\"0.000\"],[\"79602.10\",\"0.000\"],[\"79602.30\",\"0.201\"],[\"79604.90\",\"0.026\"],[\"79605.50\",\"0.028\"],[\"79605.80\",\"0.026\"],[\"79605.90\",\"0.000\"],[\"79606.00\",\"0.003\"],[\"79606.30\",\"0.026\"],[\"79606.50\",\"0.000\"],[\"79606.60\",\"0.002\"],[\"79606.80\",\"0.004\"],[\"79606.90\",\"0.006\"],[\"79607.10\",\"9.795\"]],\"a\":[[\"79607.20\",\"1.691\"],[\"79607.70\",\"0.000\"],[\"79608.30\",\"0.253\"],[\"79609.70\",\"0.252\"],[\"79611.20\",\"0.502\"],[\"79620.40\",\"0.000\"],[\"79621.40\",\"0.699\"],[\"79623.50\",\"0.004\"],[\"79624.80\",\"0.945\"],[\"79625.90\",\"0.001\"],[\"79627.10\",\"0.453\"],[\"79674.90\",\"0.211\"],[\"79730.40\",\"0.353\"],[\"79769.80\",\"1.916\"],[\"79973.40\",\"1.388\"],[\"80361.20\",\"0.000\"],[\"80403.30\",\"8.066\"],[\"87568.00\",\"0.000\"]],\"st\":1}}"}
{"receive_ns":1788563201385880000,"stream":"btcusdt@bookTicker","event_type":"bookTicker","event_time_ms":1788563201420,"raw_json":"{\"stream\":\"btcusdt@bookTicker\",\"data\":{\"e\":\"bookTicker\",\"u\":11478222980484,\"s\":\"BTCUSDT\",\"ps\":\"BTCUSDT\",\"b\":\"79607.10\",\"B\":\"9.803\",\"a\":\"79607.20\",\"A\":\"1.691\",\"T\":1788563201419,\"E\":1788563201420,\"st\":1}}"}
{"receive_ns":1788563201386059000,"stream":"btcusdt@bookTicker","event_type":"bookTicker","event_time_ms":1788563201420,"raw_json":"{\"stream\":\"btcusdt@bookTicker\",\"data\":{\"e\":\"bookTicker\",\"u\":11478222980499,\"s\":\"BTCUSDT\",\"ps\":\"BTCUSDT\",\"b\":\"79607.10\",\"B\":\"9.822\",\"a\":\"79607.20\",\"A\":\"1.691\",\"T\":1788563201419,\"E\":1788563201420,\"st\":1}}"}
{"receive_ns":1788563201394256000,"stream":"btcusdt@bookTicker","event_type":"bookTicker","event_time_ms":1788563201420,"raw_json":"{\"stream\":\"btcusdt@bookTicker\",\"data\":{\"e\":\"bookTicker\",\"u\":11478222980537,\"s\":\"BTCUSDT\",\"ps\":\"BTCUSDT\",\"b\":\"79607.10\",\"B\":\"9.814\",\"a\":\"79607.20\",\"A\":\"1.691\",\"T\":1788563201420,\"E\":1788563201420,\"st\":1}}"}
{"receive_ns":1788563201394505000,"stream":"btcusdt@bookTicker","event_type":"bookTicker","event_time_ms":1788563201421,"raw_json":"{\"stream\":\"btcusdt@bookTicker\",\"data\":{\"e\":\"bookTicker\",\"u\":11478222980543,\"s\":\"BTCUSDT\",\"ps\":\"BTCUSDT\",\"b\":\"79607.10\",\"B\":\"9.795\",\"a\":\"79607.20\",\"A\":\"1.691\",\"T\":1788563201420,\"E\":1788563201421,\"st\":1}}"}
{"receive_ns":1788563201414669000,"stream":"btcusdt@bookTicker","event_type":"bookTicker","event_time_ms":1788563201447,"raw_json":"{\"stream\":\"btcusdt@bookTicker\",\"data\":{\"e\":\"bookTicker\",\"u\":11478222982110,\"s\":\"BTCUSDT\",\"ps\":\"BTCUSDT\",\"b\":\"79607.10\",\"B\":\"9.312\",\"a\":\"79607.20\",\"A\":\"1.691\",\"T\":1788563201447,\"E\":1788563201447,\"st\":1}}"}
{"receive_ns":1788563201421364000,"stream":"btcusdt@bookTicker","event_type":"bookTicker","event_time_ms":1788563201456,"raw_json":"{\"stream\":\"btcusdt@bookTicker\",\"data\":{\"e\":\"bookTicker\",\"u\":11478222982539,\"s\":\"BTCUSDT\",\"ps\":\"BTCUSDT\",\"b\":\"79607.10\",\"B\":\"9.796\",\"a\":\"79607.20\",\"A\":\"1.691\",\"T\":1788563201455,\"E\":1788563201456,\"st\":1}}"}
{"receive_ns":1788563201421649000,"stream":"btcusdt@bookTicker","event_type":"bookTicker","event_time_ms":1788563201457,"raw_json":"{\"stream\":\"btcusdt@bookTicker\",\"data\":{\"e\":\"bookTicker\",\"u\":11478222982605,\"s\":\"BTCUSDT\",\"ps\":\"BTCUSDT\",\"b\":\"79607.10\",\"B\":\"9.794\",\"a\":\"79607.20\",\"A\":\"1.691\",\"T\":1788563201457,\"E\":1788563201457,\"st\":1}}"}
{"receive_ns":1788563201432500000,"stream":"btcusdt@bookTicker","event_type":"bookTicker","event_time_ms":1788563201468,"raw_json":"{\"stream\":\"btcusdt@bookTicker\",\"data\":{\"e\":\"bookTicker\",\"u\":11478222983186,\"s\":\"BTCUSDT\",\"ps\":\"BTCUSDT\",\"b\":\"79607.10\",\"B\":\"9.802\",\"a\":\"79607.20\",\"A\":\"1.691\",\"T\":1788563201468,\"E\":1788563201468,\"st\":1}}"}
{"receive_ns":1788563201432683000,"stream":"btcusdt@bookTicker","event_type":"bookTicker","event_time_ms":1788563201468,"raw_json":"{\"stream\":\"btcusdt@bookTicker\",\"data\":{\"e\":\"bookTicker\",\"u\":11478222983198,\"s\":\"BTCUSDT\",\"ps\":\"BTCUSDT\",\"b\":\"79607.10\",\"B\":\"9.821\",\"a\":\"79607.20\",\"A\":\"1.691\",\"T\":1788563201468,\"E\":1788563201468,\"st\":1}}"}
{"receive_ns":1788563201433806000,"stream":"btcusdt@bookTicker","event_type":"bookTicker","event_time_ms":1788563201468,"raw_json":"{\"stream\":\"btcusdt@bookTicker\",\"data\":{\"e\":\"bookTicker\",\"u\":11478222983287,\"s\":\"BTCUSDT\",\"ps\":\"BTCUSDT\",\"b\":\"79607.10\",\"B\":\"9.813\",\"a\":\"79607.20\",\"A\":\"1.691\",\"T\":1788563201468,\"E\":1788563201468,\"st\":1}}"}
{"receive_ns":1788563201433972000,"stream":"btcusdt@bookTicker","event_type":"bookTicker","event_time_ms":1788563201469,"raw_json":"{\"stream\":\"btcusdt@bookTicker\",\"data\":{\"e\":\"bookTicker\",\"u\":11478222983299,\"s\":\"BTCUSDT\",\"ps\":\"BTCUSDT\",\"b\":\"79607.10\",\"B\":\"9.794\",\"a\":\"79607.20\",\"A\":\"1.691\",\"T\":1788563201468,\"E\":1788563201469,\"st\":1}}"}
{"receive_ns":1788563201434110000,"stream":"btcusdt@bookTicker","event_type":"bookTicker","event_time_ms":1788563201469,"raw_json":"{\"stream\":\"btcusdt@bookTicker\",\"data\":{\"e\":\"bookTicker\",\"u\":11478222983309,\"s\":\"BTCUSDT\",\"ps\":\"BTCUSDT\",\"b\":\"79607.10\",\"B\":\"9.796\",\"a\":\"79607.20\",\"A\":\"1.691\",\"T\":1788563201468,\"E\":1788563201469,\"st\":1}}"}
{"receive_ns":1788563201447669000,"stream":"btcusdt@bookTicker","event_type":"bookTicker","event_time_ms":1788563201483,"raw_json":"{\"stream\":\"btcusdt@bookTicker\",\"data\":{\"e\":\"bookTicker\",\"u\":11478222984073,\"s\":\"BTCUSDT\",\"ps\":\"BTCUSDT\",\"b\":\"79607.10\",\"B\":\"9.800\",\"a\":\"79607.20\",\"A\":\"1.691\",\"T\":1788563201483,\"E\":1788563201483,\"st\":1}}"}
{"receive_ns":1788563201459012000,"stream":"btcusdt@bookTicker","event_type":"bookTicker","event_time_ms":1788563201493,"raw_json":"{\"stream\":\"btcusdt@bookTicker\",\"data\":{\"e\":\"bookTicker\",\"u\":11478222984659,\"s\":\"BTCUSDT\",\"ps\":\"BTCUSDT\",\"b\":\"79607.10\",\"B\":\"9.800\",\"a\":\"79607.20\",\"A\":\"1.665\",\"T\":1788563201493,\"E\":1788563201493,\"st\":1}}"}
{"receive_ns":1788563201495818000,"stream":"btcusdt@depth@100ms","event_type":"depthUpdate","event_time_ms":1788563201521,"raw_json":"{\"stream\":\"btcusdt@depth@100ms\",\"data\":{\"e\":\"depthUpdate\",\"E\":1788563201521,\"T\":1788563201520,\"s\":\"BTCUSDT\",\"ps\":\"BTCUSDT\",\"U\":11478222980434,\"u\":11478222986103,\"pu\":11478222980420,\"b\":[[\"1000.00\",\"24.604\"],[\"29107.10\",\"0.000\"],[\"29407.10\",\"0.350\"],[\"29507.10\",\"1.750\"],[\"71646.30\",\"0.002\"],[\"75626.70\",\"0.025\"],[\"78015.00\",\"0.134\"],[\"78439.50\",\"7.678\"],[\"78603.10\",\"6.080\"],[\"78811.00\",\"4.128\"],[\"79209.10\",\"3.677\"],[\"79210.10\",\"0.526\"],[\"79478.40\",\"0.000\"],[\"79487.70\",\"0.703\"],[\"79491.70\",\"1.430\"],[\"79534.00\",\"0.001\"],[\"79535.60\",\"0.013\"],[\"79536.70\",\"23.451\"],[\"79576.20\",\"0.453\"],[\"79577.40\",\"0.000\"],[\"79599.10\",\"0.001\"],[\"79600.70\",\"0.104\"],[\"79601.20\",\"0.004\"],[\"79601.60\",\"0.000\"],[\"79602.30\",\"0.201\"],[\"79604.70\",\"0.000\"],[\"79606.50\",\"0.026\"],[\"79606.60\",\"0.028\"],[\"79607.10\",\"9.800\"]],\"a\":[[\"79607.20\",\"1.665\"],[\"79609.70\",\"0.000\"],[\"79973.40\",\"1.150\"],[\"80403.30\",\"8.062\"],[\"80523.50\",\"0.744\"],[\"80707.00\",\"9.205\"],[\"81199.30\",\"0.018\"]],\"st\":1}}"}
{"receive_ns":1788563201496375000,"stream":"btcusdt@bookTicker","event_type":"bookTicker","event_time_ms":1788563201530,"raw_json":"{\"stream\":\"btcusdt@bookTicker\",\"data\":{\"e\":\"bookTicker\",\"u\":11478222986569,\"s\":\"BTCUSDT\",\"ps\":\"BTCUSDT\",\"b\":\"79607.10\",\"B\":\"9.438\",\"a\":\"79607.20\",\"A\":\"1.665\",\"T\":1788563201530,\"E\":1788563201530,\"st\":1}}"}
{"receive_ns":1788563201501353000,"stream":"btcusdt@bookTicker","event_type":"bookTicker","event_time_ms":1788563201537,"raw_json":"{\"stream\":\"btcusdt@bookTicker\",\"data\":{\"e\":\"bookTicker\",\"u\":11478222987044,\"s\":\"BTCUSDT\",\"ps\":\"BTCUSDT\",\"b\":\"79607.10\",\"B\":\"9.813\",\"a\":\"79607.20\",\"A\":\"1.665\",\"T\":1788563201537,\"E\":1788563201537,\"st\":1}}"}
{"receive_ns":1788563201513514000,"stream":"btcusdt@bookTicker","event_type":"bookTicker","event_time_ms":1788563201547,"raw_json":"{\"stream\":\"btcusdt@bookTicker\",\"data\":{\"e\":\"bookTicker\",\"u\":11478222987633,\"s\":\"BTCUSDT\",\"ps\":\"BTCUSDT\",\"b\":\"79607.10\",\"B\":\"9.813\",\"a\":\"79607.20\",\"A\":\"1.691\",\"T\":1788563201547,\"E\":1788563201547,\"st\":1}}"}
{"receive_ns":1788563201513745000,"stream":"btcusdt@bookTicker","event_type":"bookTicker","event_time_ms":1788563201549,"raw_json":"{\"stream\":\"btcusdt@bookTicker\",\"data\":{\"e\":\"bookTicker\",\"u\":11478222987728,\"s\":\"BTCUSDT\",\"ps\":\"BTCUSDT\",\"b\":\"79607.10\",\"B\":\"9.813\",\"a\":\"79607.20\",\"A\":\"1.690\",\"T\":1788563201549,\"E\":1788563201549,\"st\":1}}"}
{"receive_ns":1788563201515692000,"stream":"btcusdt@bookTicker","event_type":"bookTicker","event_time_ms":1788563201550,"raw_json":"{\"stream\":\"btcusdt@bookTicker\",\"data\":{\"e\":\"bookTicker\",\"u\":11478222987840,\"s\":\"BTCUSDT\",\"ps\":\"BTCUSDT\",\"b\":\"79607.10\",\"B\":\"9.813\",\"a\":\"79607.20\",\"A\":\"1.664\",\"T\":1788563201550,\"E\":1788563201550,\"st\":1}}"}
{"receive_ns":1788563201520149000,"stream":"btcusdt@bookTicker","event_type":"bookTicker","event_time_ms":1788563201555,"raw_json":"{\"stream\":\"btcusdt@bookTicker\",\"data\":{\"e\":\"bookTicker\",\"u\":11478222988157,\"s\":\"BTCUSDT\",\"ps\":\"BTCUSDT\",\"b\":\"79607.10\",\"B\":\"9.813\",\"a\":\"79607.20\",\"A\":\"1.690\",\"T\":1788563201555,\"E\":1788563201555,\"st\":1}}"}
{"receive_ns":1788563201520381000,"stream":"btcusdt@bookTicker","event_type":"bookTicker","event_time_ms":1788563201556,"raw_json":"{\"stream\":\"btcusdt@bookTicker\",\"data\":{\"e\":\"bookTicker\",\"u\":11478222988219,\"s\":\"BTCUSDT\",\"ps\":\"BTCUSDT\",\"b\":\"79607.10\",\"B\":\"9.813\",\"a\":\"79607.20\",\"A\":\"1.691\",\"T\":1788563201556,\"E\":1788563201556,\"st\":1}}"}
{"receive_ns":1788563201530239000,"stream":"btcusdt@bookTicker","event_type":"bookTicker","event_time_ms":1788563201564,"raw_json":"{\"stream\":\"btcusdt@bookTicker\",\"data\":{\"e\":\"bookTicker\",\"u\":11478222988922,\"s\":\"BTCUSDT\",\"ps\":\"BTCUSDT\",\"b\":\"79607.10\",\"B\":\"9.813\",\"a\":\"79607.20\",\"A\":\"1.665\",\"T\":1788563201564,\"E\":1788563201564,\"st\":1}}"}
{"receive_ns":1788563201532980000,"stream":"btcusdt@bookTicker","event_type":"bookTicker","event_time_ms":1788563201568,"raw_json":"{\"stream\":\"btcusdt@bookTicker\",\"data\":{\"e\":\"bookTicker\",\"u\":11478222989171,\"s\":\"BTCUSDT\",\"ps\":\"BTCUSDT\",\"b\":\"79607.10\",\"B\":\"9.813\",\"a\":\"79607.20\",\"A\":\"1.691\",\"T\":1788563201567,\"E\":1788563201568,\"st\":1}}"}
{"receive_ns":1788563201535433000,"stream":"btcusdt@bookTicker","event_type":"bookTicker","event_time_ms":1788563201571,"raw_json":"{\"stream\":\"btcusdt@bookTicker\",\"data\":{\"e\":\"bookTicker\",\"u\":11478222989451,\"s\":\"BTCUSDT\",\"ps\":\"BTCUSDT\",\"b\":\"79607.10\",\"B\":\"9.813\",\"a\":\"79607.20\",\"A\":\"1.665\",\"T\":1788563201571,\"E\":1788563201571,\"st\":1}}"}
{"receive_ns":1788563201539834000,"stream":"btcusdt@bookTicker","event_type":"bookTicker","event_time_ms":1788563201574,"raw_json":"{\"stream\":\"btcusdt@bookTicker\",\"data\":{\"e\":\"bookTicker\",\"u\":11478222989631,\"s\":\"BTCUSDT\",\"ps\":\"BTCUSDT\",\"b\":\"79607.10\",\"B\":\"9.821\",\"a\":\"79607.20\",\"A\":\"1.665\",\"T\":1788563201573,\"E\":1788563201574,\"st\":1}}"}
{"receive_ns":1788563201540103000,"stream":"btcusdt@bookTicker","event_type":"bookTicker","event_time_ms":1788563201574,"raw_json":"{\"stream\":\"btcusdt@bookTicker\",\"data\":{\"e\":\"bookTicker\",\"u\":11478222989668,\"s\":\"BTCUSDT\",\"ps\":\"BTCUSDT\",\"b\":\"79607.10\",\"B\":\"9.840\",\"a\":\"79607.20\",\"A\":\"1.665\",\"T\":1788563201574,\"E\":1788563201574,\"st\":1}}"}
{"receive_ns":1788563201540325000,"stream":"btcusdt@bookTicker","event_type":"bookTicker","event_time_ms":1788563201574,"raw_json":"{\"stream\":\"btcusdt@bookTicker\",\"data\":{\"e\":\"bookTicker\",\"u\":11478222989692,\"s\":\"BTCUSDT\",\"ps\":\"BTCUSDT\",\"b\":\"79607.10\",\"B\":\"9.832\",\"a\":\"79607.20\",\"A\":\"1.665\",\"T\":1788563201574,\"E\":1788563201574,\"st\":1}}"}
{"receive_ns":1788563201540475000,"stream":"btcusdt@bookTicker","event_type":"bookTicker","event_time_ms":1788563201574,"raw_json":"{\"stream\":\"btcusdt@bookTicker\",\"data\":{\"e\":\"bookTicker\",\"u\":11478222989699,\"s\":\"BTCUSDT\",\"ps\":\"BTCUSDT\",\"b\":\"79607.10\",\"B\":\"9.813\",\"a\":\"79607.20\",\"A\":\"1.665\",\"T\":1788563201574,\"E\":1788563201574,\"st\":1}}"}
{"receive_ns":1788563201548237000,"stream":"btcusdt@bookTicker","event_type":"bookTicker","event_time_ms":1788563201584,"raw_json":"{\"stream\":\"btcusdt@bookTicker\",\"data\":{\"e\":\"bookTicker\",\"u\":11478222990156,\"s\":\"BTCUSDT\",\"ps\":\"BTCUSDT\",\"b\":\"79607.10\",\"B\":\"9.813\",\"a\":\"79607.20\",\"A\":\"1.667\",\"T\":1788563201584,\"E\":1788563201584,\"st\":1}}"}
{"receive_ns":1788563201587146000,"stream":"btcusdt@depth@100ms","event_type":"depthUpdate","event_time_ms":1788563201623,"raw_json":"{\"stream\":\"btcusdt@depth@100ms\",\"data\":{\"e\":\"depthUpdate\",\"E\":1788563201623,\"T\":1788563201621,\"s\":\"BTCUSDT\",\"ps\":\"BTCUSDT\",\"U\":11478222986159,\"u\":11478222992232,\"pu\":11478222986103,\"b\":[[\"1000.00\",\"24.604\"],[\"29407.10\",\"0.532\"],[\"29507.10\",\"1.568\"],[\"63686.00\",\"0.002\"],[\"71646.30\",\"0.002\"],[\"76422.80\",\"0.002\"],[\"78811.00\",\"4.126\"],[\"79209.10\",\"3.677\"],[\"79236.90\",\"0.247\"],[\"79434.00\",\"0.427\"],[\"79478.20\",\"0.135\"],[\"79481.50\",\"0.000\"],[\"79487.70\",\"1.707\"],[\"79491.70\",\"1.079\"],[\"79516.10\",\"5.024\"],[\"79556.60\",\"0.311\"],[\"79601.60\",\"0.000\"],[\"79602.30\",\"0.201\"],[\"79604.80\",\"0.028\"],[\"79605.90\",\"0.026\"],[\"79606.30\",\"0.000\"],[\"79606.50\",\"0.000\"],[\"79606.60\",\"0.002\"],[\"79606.90\",\"0.006\"],[\"79607.00\",\"0.033\"],[\"79607.10\",\"9.813\"]],\"a\":[[\"79607.20\",\"1.667\"],[\"79607.30\",\"0.005\"],[\"79609.20\",\"0.502\"],[\"79610.40\",\"1.212\"],[\"79611.20\",\"0.289\"],[\"79730.40\",\"0.001\"],[\"79973.40\",\"1.913\"],[\"80199.40\",\"1.246\"],[\"80395.30\",\"1.017\"],[\"80403.30\",\"8.062\"],[\"81454.00\",\"0.001\"]],\"st\":1}}"}
{"receive_ns":1788563201650508000,"stream":"btcusdt@bookTicker","event_type":"bookTicker","event_time_ms":1788563201684,"raw_json":"{\"stream\":\"btcusdt@bookTicker\",\"data\":{\"e\":\"bookTicker\",\"u\":11478222995467,\"s\":\"BTCUSDT\",\"ps\":\"BTCUSDT\",\"b\":\"79607.10\",\"B\":\"9.813\",\"a\":\"79607.20\",\"A\":\"1.997\",\"T\":1788563201683,\"E\":1788563201684,\"st\":1}}"}
{"receive_ns":1788563201651926000,"stream":"btcusdt@bookTicker","event_type":"bookTicker","event_time_ms":1788563201685,"raw_json":"{\"stream\":\"btcusdt@bookTicker\",\"data\":{\"e\":\"bookTicker\",\"u\":11478222995709,\"s\":\"BTCUSDT\",\"ps\":\"BTCUSDT\",\"b\":\"79607.10\",\"B\":\"9.813\",\"a\":\"79607.20\",\"A\":\"1.996\",\"T\":1788563201685,\"E\":1788563201685,\"st\":1}}"}
{"receive_ns":1788563201652140000,"stream":"btcusdt@bookTicker","event_type":"bookTicker","event_time_ms":1788563201685,"raw_json":"{\"stream\":\"btcusdt@bookTicker\",\"data\":{\"e\":\"bookTicker\",\"u\":11478222995716,\"s\":\"BTCUSDT\",\"ps\":\"BTCUSDT\",\"b\":\"79607.10\",\"B\":\"9.832\",\"a\":\"79607.20\",\"A\":\"1.996\",\"T\":1788563201685,\"E\":1788563201685,\"st\":1}}"}
{"receive_ns":1788563201652283000,"stream":"btcusdt@bookTicker","event_type":"bookTicker","event_time_ms":1788563201685,"raw_json":"{\"stream\":\"btcusdt@bookTicker\",\"data\":{\"e\":\"bookTicker\",\"u\":11478222995727,\"s\":\"BTCUSDT\",\"ps\":\"BTCUSDT\",\"b\":\"79607.10\",\"B\":\"9.832\",\"a\":\"79607.20\",\"A\":\"1.995\",\"T\":1788563201685,\"E\":1788563201685,\"st\":1}}"}
{"receive_ns":1788563201652416000,"stream":"btcusdt@bookTicker","event_type":"bookTicker","event_time_ms":1788563201685,"raw_json":"{\"stream\":\"btcusdt@bookTicker\",\"data\":{\"e\":\"bookTicker\",\"u\":11478222995750,\"s\":\"BTCUSDT\",\"ps\":\"BTCUSDT\",\"b\":\"79607.10\",\"B\":\"9.840\",\"a\":\"79607.20\",\"A\":\"1.995\",\"T\":1788563201685,\"E\":1788563201685,\"st\":1}}"}
{"receive_ns":1788563201652571000,"stream":"btcusdt@bookTicker","event_type":"bookTicker","event_time_ms":1788563201686,"raw_json":"{\"stream\":\"btcusdt@bookTicker\",\"data\":{\"e\":\"bookTicker\",\"u\":11478222995815,\"s\":\"BTCUSDT\",\"ps\":\"BTCUSDT\",\"b\":\"79607.10\",\"B\":\"9.821\",\"a\":\"79607.20\",\"A\":\"1.995\",\"T\":1788563201686,\"E\":1788563201686,\"st\":1}}"}
{"receive_ns":1788563201652704000,"stream":"btcusdt@bookTicker","event_type":"bookTicker","event_time_ms":1788563201686,"raw_json":"{\"stream\":\"btcusdt@bookTicker\",\"data\":{\"e\":\"bookTicker\",\"u\":11478222995824,\"s\":\"BTCUSDT\",\"ps\":\"BTCUSDT\",\"b\":\"79607.10\",\"B\":\"9.813\",\"a\":\"79607.20\",\"A\":\"1.995\",\"T\":1788563201686,\"E\":1788563201686,\"st\":1}}"}
{"receive_ns":1788563201652897000,"stream":"btcusdt@bookTicker","event_type":"bookTicker","event_time_ms":1788563201687,"raw_json":"{\"stream\":\"btcusdt@bookTicker\",\"data\":{\"e\":\"bookTicker\",\"u\":11478222995880,\"s\":\"BTCUSDT\",\"ps\":\"BTCUSDT\",\"b\":\"79607.10\",\"B\":\"9.813\",\"a\":\"79607.20\",\"A\":\"1.996\",\"T\":1788563201686,\"E\":1788563201687,\"st\":1}}"}
{"receive_ns":1788563201653032000,"stream":"btcusdt@bookTicker","event_type":"bookTicker","event_time_ms":1788563201687,"raw_json":"{\"stream\":\"btcusdt@bookTicker\",\"data\":{\"e\":\"bookTicker\",\"u\":11478222995884,\"s\":\"BTCUSDT\",\"ps\":\"BTCUSDT\",\"b\":\"79607.10\",\"B\":\"9.813\",\"a\":\"79607.20\",\"A\":\"1.997\",\"T\":1788563201686,\"E\":1788563201687,\"st\":1}}"}
{"receive_ns":1788563201689781000,"stream":"btcusdt@depth@100ms","event_type":"depthUpdate","event_time_ms":1788563201725,"raw_json":"{\"stream\":\"btcusdt@depth@100ms\",\"data\":{\"e\":\"depthUpdate\",\"E\":1788563201725,\"T\":1788563201723,\"s\":\"BTCUSDT\",\"ps\":\"BTCUSDT\",\"U\":11478222992315,\"u\":11478222997834,\"pu\":11478222992232,\"b\":[[\"29407.10\",\"0.707\"],[\"29507.10\",\"1.393\"],[\"71646.30\",\"0.002\"],[\"75626.80\",\"0.002\"],[\"76422.80\",\"0.000\"],[\"78811.00\",\"4.126\"],[\"79209.00\",\"0.000\"],[\"79434.00\",\"0.929\"],[\"79442.10\",\"2.398\"],[\"79453.90\",\"1.208\"],[\"79481.50\",\"0.617\"],[\"79487.70\",\"1.205\"],[\"79491.70\",\"0.075\"],[\"79605.70\",\"0.000\"],[\"79607.10\",\"9.813\"]],\"a\":[[\"79607.20\",\"1.997\"],[\"79607.40\",\"0.104\"],[\"79607.80\",\"0.001\"],[\"79619.30\",\"0.779\"],[\"79621.40\",\"0.260\"],[\"79730.30\",\"0.352\"],[\"79769.80\",\"1.916\"],[\"79973.40\",\"1.913\"],[\"80005.30\",\"0.003\"],[\"80239.20\",\"1.244\"],[\"80271.60\",\"0.000\"],[\"80403.30\",\"8.062\"],[\"81199.30\",\"0.015\"]],\"st\":1}}"}
{"receive_ns":1788563201790870000,"stream":"btcusdt@depth@100ms","event_type":"depthUpdate","event_time_ms":1788563201827,"raw_json":"{\"stream\":\"btcusdt@depth@100ms\",\"data\":{\"e\":\"depthUpdate\",\"E\":1788563201827,\"T\":1788563201826,\"s\":\"BTCUSDT\",\"ps\":\"BTCUSDT\",\"U\":11478222997968,\"u\":11478223002560,\"pu\":11478222997834,\"b\":[[\"1000.00\",\"24.604\"],[\"29407.10\",\"0.889\"],[\"29507.10\",\"1.211\"],[\"63678.00\",\"0.000\"],[\"63679.00\",\"0.000\"],[\"63686.00\",\"0.000\"],[\"71646.30\",\"0.002\"],[\"76422.80\",\"0.002\"],[\"78368.50\",\"2.676\"],[\"78452.80\",\"3.653\"],[\"78651.80\",\"12.251\"],[\"78686.90\",\"3.174\"],[\"78811.00\",\"4.126\"],[\"79209.10\",\"3.677\"],[\"79236.90\",\"0.247\"],[\"79434.00\",\"1.882\"],[\"79455.80\",\"0.251\"],[\"79487.70\",\"0.076\"],[\"79491.70\",\"0.000\"],[\"79516.10\",\"3.034\"],[\"79602.30\",\"0.176\"],[\"79603.10\",\"1.356\"]],\"a\":[[\"79609.20\",\"0.701\"],[\"79611.20\",\"0.090\"],[\"79619.30\",\"0.340\"],[\"79620.40\",\"0.439\"],[\"79973.40\",\"1.913\"],[\"80403.30\",\"8.062\"]],\"st\":1}}"}
{"receive_ns":1788563201804419000,"stream":"btcusdt@bookTicker","event_type":"bookTicker","event_time_ms":1788563201838,"raw_json":"{\"stream\":\"btcusdt@bookTicker\",\"data\":{\"e\":\"bookTicker\",\"u\":11478223003372,\"s\":\"BTCUSDT\",\"ps\":\"BTCUSDT\",\"b\":\"79607.10\",\"B\":\"9.813\",\"a\":\"79607.20\",\"A\":\"2.361\",\"T\":1788563201838,\"E\":1788563201838,\"st\":1}}"}
{"receive_ns":1788563201804707000,"stream":"btcusdt@bookTicker","event_type":"bookTicker","event_time_ms":1788563201839,"raw_json":"{\"stream\":\"btcusdt@bookTicker\",\"data\":{\"e\":\"bookTicker\",\"u\":11478223003614,\"s\":\"BTCUSDT\",\"ps\":\"BTCUSDT\",\"b\":\"79607.10\",\"B\":\"9.813\",\"a\":\"79607.20\",\"A\":\"2.360\",\"T\":1788563201839,\"E\":1788563201839,\"st\":1}}"}
{"receive_ns":1788563201804868000,"stream":"btcusdt@bookTicker","event_type":"bookTicker","event_time_ms":1788563201839,"raw_json":"{\"stream\":\"btcusdt@bookTicker\",\"data\":{\"e\":\"bookTicker\",\"u\":11478223003662,\"s\":\"BTCUSDT\",\"ps\":\"BTCUSDT\",\"b\":\"79607.10\",\"B\":\"9.821\",\"a\":\"79607.20\",\"A\":\"2.360\",\"T\":1788563201839,\"E\":1788563201839,\"st\":1}}"}
{"receive_ns":1788563201805009000,"stream":"btcusdt@bookTicker","event_type":"bookTicker","event_time_ms":1788563201839,"raw_json":"{\"stream\":\"btcusdt@bookTicker\",\"data\":{\"e\":\"bookTicker\",\"u\":11478223003666,\"s\":\"BTCUSDT\",\"ps\":\"BTCUSDT\",\"b\":\"79607.10\",\"B\":\"9.821\",\"a\":\"79607.20\",\"A\":\"2.386\",\"T\":1788563201839,\"E\":1788563201839,\"st\":1}}"}
{"receive_ns":1788563201805140000,"stream":"btcusdt@bookTicker","event_type":"bookTicker","event_time_ms":1788563201839,"raw_json":"{\"stream\":\"btcusdt@bookTicker\",\"data\":{\"e\":\"bookTicker\",\"u\":11478223003679,\"s\":\"BTCUSDT\",\"ps\":\"BTCUSDT\",\"b\":\"79607.10\",\"B\":\"9.840\",\"a\":\"79607.20\",\"A\":\"2.386\",\"T\":1788563201839,\"E\":1788563201839,\"st\":1}}"}
{"receive_ns":1788563201805269000,"stream":"btcusdt@bookTicker","event_type":"bookTicker","event_time_ms":1788563201839,"raw_json":"{\"stream\":\"btcusdt@bookTicker\",\"data\":{\"e\":\"bookTicker\",\"u\":11478223003681,\"s\":\"BTCUSDT\",\"ps\":\"BTCUSDT\",\"b\":\"79607.10\",\"B\":\"9.840\",\"a\":\"79607.20\",\"A\":\"2.791\",\"T\":1788563201839,\"E\":1788563201839,\"st\":1}}"}
{"receive_ns":1788563201805422000,"stream":"btcusdt@bookTicker","event_type":"bookTicker","event_time_ms":1788563201840,"raw_json":"{\"stream\":\"btcusdt@bookTicker\",\"data\":{\"e\":\"bookTicker\",\"u\":11478223003985,\"s\":\"BTCUSDT\",\"ps\":\"BTCUSDT\",\"b\":\"79607.10\",\"B\":\"9.832\",\"a\":\"79607.20\",\"A\":\"2.791\",\"T\":1788563201840,\"E\":1788563201840,\"st\":1}}"}
{"receive_ns":1788563201805561000,"stream":"btcusdt@bookTicker","event_type":"bookTicker","event_time_ms":1788563201840,"raw_json":"{\"stream\":\"btcusdt@bookTicker\",\"data\":{\"e\":\"bookTicker\",\"u\":11478223004020,\"s\":\"BTCUSDT\",\"ps\":\"BTCUSDT\",\"b\":\"79607.10\",\"B\":\"9.813\",\"a\":\"79607.20\",\"A\":\"2.791\",\"T\":1788563201840,\"E\":1788563201840,\"st\":1}}"}
{"receive_ns":1788563201805689000,"stream":"btcusdt@bookTicker","event_type":"bookTicker","event_time_ms":1788563201840,"raw_json":"{\"stream\":\"btcusdt@bookTicker\",\"data\":{\"e\":\"bookTicker\",\"u\":11478223004070,\"s\":\"BTCUSDT\",\"ps\":\"BTCUSDT\",\"b\":\"79607.10\",\"B\":\"9.821\",\"a\":\"79607.20\",\"A\":\"2.791\",\"T\":1788563201840,\"E\":1788563201840,\"st\":1}}"}
{"receive_ns":1788563201805941000,"stream":"btcusdt@bookTicker","event_type":"bookTicker","event_time_ms":1788563201840,"raw_json":"{\"stream\":\"btcusdt@bookTicker\",\"data\":{\"e\":\"bookTicker\",\"u\":11478223004075,\"s\":\"BTCUSDT\",\"ps\":\"BTCUSDT\",\"b\":\"79607.10\",\"B\":\"9.821\",\"a\":\"79607.20\",\"A\":\"2.792\",\"T\":1788563201840,\"E\":1788563201840,\"st\":1}}"}
{"receive_ns":1788563201806247000,"stream":"btcusdt@bookTicker","event_type":"bookTicker","event_time_ms":1788563201841,"raw_json":"{\"stream\":\"btcusdt@bookTicker\",\"data\":{\"e\":\"bookTicker\",\"u\":11478223004314,\"s\":\"BTCUSDT\",\"ps\":\"BTCUSDT\",\"b\":\"79607.10\",\"B\":\"9.813\",\"a\":\"79607.20\",\"A\":\"2.792\",\"T\":1788563201841,\"E\":1788563201841,\"st\":1}}"}
{"receive_ns":1788563201810960000,"stream":"btcusdt@bookTicker","event_type":"bookTicker","event_time_ms":1788563201846,"raw_json":"{\"stream\":\"btcusdt@bookTicker\",\"data\":{\"e\":\"bookTicker\",\"u\":11478223005087,\"s\":\"BTCUSDT\",\"ps\":\"BTCUSDT\",\"b\":\"79607.10\",\"B\":\"9.821\",\"a\":\"79607.20\",\"A\":\"2.792\",\"T\":1788563201845,\"E\":1788563201846,\"st\":1}}"}
{"receive_ns":1788563201811206000,"stream":"btcusdt@bookTicker","event_type":"bookTicker","event_time_ms":1788563201846,"raw_json":"{\"stream\":\"btcusdt@bookTicker\",\"data\":{\"e\":\"bookTicker\",\"u\":11478223005228,\"s\":\"BTCUSDT\",\"ps\":\"BTCUSDT\",\"b\":\"79607.10\",\"B\":\"9.813\",\"a\":\"79607.20\",\"A\":\"2.792\",\"T\":1788563201846,\"E\":1788563201846,\"st\":1}}"}
{"receive_ns":1788563201828472000,"stream":"btcusdt@bookTicker","event_type":"bookTicker","event_time_ms":1788563201862,"raw_json":"{\"stream\":\"btcusdt@bookTicker\",\"data\":{\"e\":\"bookTicker\",\"u\":11478223006519,\"s\":\"BTCUSDT\",\"ps\":\"BTCUSDT\",\"b\":\"79607.10\",\"B\":\"9.813\",\"a\":\"79607.20\",\"A\":\"2.794\",\"T\":1788563201862,\"E\":1788563201862,\"st\":1}}"}
{"receive_ns":1788563201893727000,"stream":"btcusdt@depth@100ms","event_type":"depthUpdate","event_time_ms":1788563201929,"raw_json":"{\"stream\":\"btcusdt@depth@100ms\",\"data\":{\"e\":\"depthUpdate\",\"E\":1788563201929,\"T\":1788563201928,\"s\":\"BTCUSDT\",\"ps\":\"BTCUSDT\",\"U\":11478223002624,\"u\":11478223010715,\"pu\":11478223002560,\"b\":[[\"1000.00\",\"24.604\"],[\"29407.10\",\"1.064\"],[\"29507.10\",\"1.036\"],[\"63686.00\",\"0.000\"],[\"71646.30\",\"0.002\"],[\"71681.00\",\"0.003\"],[\"76422.80\",\"0.000\"],[\"78373.20\",\"1.784\"],[\"78452.80\",\"4.544\"],[\"78516.40\",\"0.276\"],[\"78612.00\",\"2.483\"],[\"78811.00\",\"4.126\"],[\"78965.50\",\"1.265\"],[\"79209.10\",\"3.667\"],[\"79392.80\",\"0.004\"],[\"79394.40\",\"5.983\"],[\"79453.90\",\"0.204\"],[\"79545.10\",\"4.717\"],[\"79556.30\",\"0.014\"],[\"79557.10\",\"0.003\"],[\"79571.70\",\"0.090\"],[\"79573.10\",\"0.111\"],[\"79573.20\",\"2.228\"],[\"79575.30\",\"0.074\"],[\"79575.80\",\"1.727\"],[\"79578.10\",\"0.004\"],[\"79579.50\",\"0.053\"],[\"79579.60\",\"0.547\"],[\"79579.70\",\"0.000\"],[\"79584.80\",\"0.256\"],[\"79585.70\",\"0.000\"],[\"79588.10\",\"0.001\"],[\"79589.10\",\"0.000\"],[\"79589.20\",\"0.195\"],[\"79589.30\",\"0.629\"],[\"79590.30\",\"0.132\"],[\"79591.20\",\"1.281\"],[\"79594.30\",\"0.002\"],[\"79598.30\",\"0.161\"],[\"79599.00\",\"0.050\"],[\"79599.10\",\"0.102\"],[\"79600.70\",\"0.003\"],[\"79601.60\",\"0.001\"],[\"79601.70\",\"0.328\"],[\"79602.20\",\"0.046\"],[\"79602.30\",\"0.175\"],[\"79604.10\",\"0.026\"],[\"79604.20\",\"0.026\"],[\"79604.30\",\"0.001\"],[\"79604.40\",\"0.028\"],[\"79604.50\",\"0.027\"],[\"79604.60\",\"0.027\"],[\"79604.70\",\"0.026\"],[\"79605.00\",\"0.002\"],[\"79605.10\",\"0.026\"],[\"79605.20\",\"0.002\"],[\"79605.40\",\"0.009\"],[\"79605.50\",\"0.002\"],[\"79605.60\",\"0.082\"],[\"79605.80\",\"0.000\"],[\"79605.90\",\"0.000\"],[\"79607.00\",\"0.007\"],[\"79607.10\",\"9.813\"]],\"a\":[[\"79607.20\",\"2.794\"],[\"79607.30\",\"0.006\"],[\"79607.90\",\"0.102\"],[\"79609.20\",\"0.502\"],[\"79609.70\",\"0.252\"],[\"79612.50\",\"0.003\"],[\"79615.30\",\"0.692\"],[\"79619.30\",\"0.343\"],[\"79621.00\",\"0.000\"],[\"79624.00\",\"0.007\"],[\"79635.00\",\"0.015\"],[\"79637.70\",\"0.025\"],[\"79649.80\",\"0.019\"],[\"79674.30\",\"0.060\"],[\"79674.50\",\"2.936\"],[\"79676.90\",\"24.627\"],[\"79685.30\",\"0.001\"],[\"79973.40\",\"1.388\"],[\"80244.10\",\"1.743\"],[\"80403.30\",\"8.064\"],[\"81199.30\",\"0.021\"]],\"st\":1}}"}
{"receive_ns":1788563201894956000,"stream":"btcusdt@bookTicker","event_type":"bookTicker","event_time_ms":1788563201931,"raw_json":"{\"stream\":\"btcusdt@bookTicker\",\"data\":{\"e\":\"bookTicker\",\"u\":11478223010896,\"s\":\"BTCUSDT\",\"ps\":\"BTCUSDT\",\"b\":\"79607.10\",\"B\":\"9.813\",\"a\":\"79607.20\",\"A\":\"2.800\",\"T\":1788563201930,\"E\":1788563201931,\"st\":1}}"}
{"receive_ns":1788563201992396000,"stream":"btcusdt@bookTicker","event_type":"bookTicker","event_time_ms":1788563202028,"raw_json":"{\"stream\":\"btcusdt@bookTicker\",\"data\":{\"e\":\"bookTicker\",\"u\":11478223015953,\"s\":\"BTCUSDT\",\"ps\":\"BTCUSDT\",\"b\":\"79607.10\",\"B\":\"9.813\",\"a\":\"79607.20\",\"A\":\"2.804\",\"T\":1788563202028,\"E\":1788563202028,\"st\":1}}"}
{"receive_ns":1788563201995738000,"stream":"btcusdt@depth@100ms","event_type":"depthUpdate","event_time_ms":1788563202031,"raw_json":"{\"stream\":\"btcusdt@depth@100ms\",\"data\":{\"e\":\"depthUpdate\",\"E\":1788563202031,\"T\":1788563202030,\"s\":\"BTCUSDT\",\"ps\":\"BTCUSDT\",\"U\":11478223010786,\"u\":11478223016140,\"pu\":11478223010715,\"b\":[[\"29407.10\",\"1.246\"],[\"29507.10\",\"0.854\"],[\"63686.00\",\"0.000\"],[\"71646.30\",\"0.002\"],[\"71681.00\",\"0.000\"],[\"78492.60\",\"16.542\"],[\"78647.10\",\"17.270\"],[\"78811.00\",\"4.126\"],[\"79236.90\",\"0.015\"],[\"79434.00\",\"0.076\"],[\"79455.80\",\"0.000\"],[\"79478.20\",\"0.010\"],[\"79487.70\",\"0.001\"],[\"79491.70\",\"1.506\"],[\"79535.40\",\"0.002\"],[\"79576.20\",\"0.453\"],[\"79577.40\",\"0.000\"],[\"79583.40\",\"1.875\"],[\"79585.70\",\"0.628\"],[\"79587.10\",\"0.000\"],[\"79589.30\",\"0.001\"],[\"79590.50\",\"0.076\"],[\"79592.00\",\"0.016\"],[\"79594.20\",\"0.001\"],[\"79600.60\",\"0.002\"],[\"79603.80\",\"0.026\"],[\"79603.90\",\"0.026\"],[\"79604.00\",\"0.029\"],[\"79604.70\",\"0.000\"],[\"79604.80\",\"0.002\"],[\"79604.90\",\"0.000\"],[\"79605.10\",\"0.000\"],[\"79605.30\",\"0.001\"]],\"a\":[[\"79607.20\",\"2.804\"],[\"79609.20\",\"0.000\"],[\"79611.20\",\"0.000\"],[\"79623.30\",\"0.045\"],[\"79625.70\",\"0.453\"],[\"79627.10\",\"0.001\"],[\"79640.80\",\"10.075\"],[\"79663.00\",\"0.000\"],[\"79973.40\",\"0.950\"],[\"80005.30\",\"0.002\"],[\"80398.40\",\"2.796\"],[\"80403.30\",\"8.064\"]],\"st\":1}}"}
{"receive_ns":1788563202001281000,"stream":"btcusdt@bookTicker","event_type":"bookTicker","event_time_ms":1788563202036,"raw_json":"{\"stream\":\"btcusdt@bookTicker\",\"data\":{\"e\":\"bookTicker\",\"u\":11478223016650,\"s\":\"BTCUSDT\",\"ps\":\"BTCUSDT\",\"b\":\"79607.10\",\"B\":\"9.813\",\"a\":\"79607.20\",\"A\":\"2.807\",\"T\":1788563202036,\"E\":1788563202036,\"st\":1}}"}
{"receive_ns":1788563202015642000,"stream":"btcusdt@bookTicker","event_type":"bookTicker","event_time_ms":1788563202051,"raw_json":"{\"stream\":\"btcusdt@bookTicker\",\"data\":{\"e\":\"bookTicker\",\"u\":11478223017575,\"s\":\"BTCUSDT\",\"ps\":\"BTCUSDT\",\"b\":\"79607.10\",\"B\":\"9.813\",\"a\":\"79607.20\",\"A\":\"2.798\",\"T\":1788563202051,\"E\":1788563202051,\"st\":1}}"}
{"receive_ns":1788563202015888000,"stream":"btcusdt@bookTicker","event_type":"bookTicker","event_time_ms":1788563202051,"raw_json":"{\"stream\":\"btcusdt@bookTicker\",\"data\":{\"e\":\"bookTicker\",\"u\":11478223017579,\"s\":\"BTCUSDT\",\"ps\":\"BTCUSDT\",\"b\":\"79607.10\",\"B\":\"9.813\",\"a\":\"79607.20\",\"A\":\"2.797\",\"T\":1788563202051,\"E\":1788563202051,\"st\":1}}"}
{"receive_ns":1788563202040963000,"stream":"btcusdt@bookTicker","event_type":"bookTicker","event_time_ms":1788563202076,"raw_json":"{\"stream\":\"btcusdt@bookTicker\",\"data\":{\"e\":\"bookTicker\",\"u\":11478223018952,\"s\":\"BTCUSDT\",\"ps\":\"BTCUSDT\",\"b\":\"79607.10\",\"B\":\"9.810\",\"a\":\"79607.20\",\"A\":\"2.797\",\"T\":1788563202076,\"E\":1788563202076,\"st\":1}}"}
{"receive_ns":1788563202041266000,"stream":"btcusdt@trade","event_type":"trade","event_time_ms":1788563202076,"raw_json":"{\"stream\":\"btcusdt@trade\",\"data\":{\"e\":\"trade\",\"E\":1788563202076,\"T\":1788563202076,\"s\":\"BTCUSDT\",\"t\":8054082686,\"p\":\"79607.10\",\"q\":\"0.003\",\"X\":\"MARKET\",\"m\":true,\"st\":1}}"}
{"receive_ns":1788563202049719000,"stream":"btcusdt@bookTicker","event_type":"bookTicker","event_time_ms":1788563202077,"raw_json":"{\"stream\":\"btcusdt@bookTicker\",\"data\":{\"e\":\"bookTicker\",\"u\":11478223019080,\"s\":\"BTCUSDT\",\"ps\":\"BTCUSDT\",\"b\":\"79607.10\",\"B\":\"9.818\",\"a\":\"79607.20\",\"A\":\"2.797\",\"T\":1788563202077,\"E\":1788563202077,\"st\":1}}"}
{"receive_ns":1788563202049931000,"stream":"btcusdt@bookTicker","event_type":"bookTicker","event_time_ms":1788563202078,"raw_json":"{\"stream\":\"btcusdt@bookTicker\",\"data\":{\"e\":\"bookTicker\",\"u\":11478223019198,\"s\":\"BTCUSDT\",\"ps\":\"BTCUSDT\",\"b\":\"79607.10\",\"B\":\"9.810\",\"a\":\"79607.20\",\"A\":\"2.797\",\"T\":1788563202078,\"E\":1788563202078,\"st\":1}}"}
{"receive_ns":1788563202050145000,"stream":"btcusdt@bookTicker","event_type":"bookTicker","event_time_ms":1788563202080,"raw_json":"{\"stream\":\"btcusdt@bookTicker\",\"data\":{\"e\":\"bookTicker\",\"u\":11478223019459,\"s\":\"BTCUSDT\",\"ps\":\"BTCUSDT\",\"b\":\"79607.10\",\"B\":\"9.807\",\"a\":\"79607.20\",\"A\":\"2.797\",\"T\":1788563202080,\"E\":1788563202080,\"st\":1}}"}
{"receive_ns":1788563202097130000,"stream":"btcusdt@depth@100ms","event_type":"depthUpdate","event_time_ms":1788563202133,"raw_json":"{\"stream\":\"btcusdt@depth@100ms\",\"data\":{\"e\":\"depthUpdate\",\"E\":1788563202133,\"T\":1788563202132,\"s\":\"BTCUSDT\",\"ps\":\"BTCUSDT\",\"U\":11478223016152,\"u\":11478223022174,\"pu\":11478223016140,\"b\":[[\"1000.00\",\"24.604\"],[\"29407.10\",\"1.421\"],[\"29507.10\",\"0.679\"],[\"63685.70\",\"0.001\"],[\"63686.00\",\"0.000\"],[\"71646.30\",\"0.002\"],[\"75626.70\",\"0.023\"],[\"75626.80\",\"0.004\"],[\"76422.80\",\"0.002\"],[\"78373.20\",\"2.676\"],[\"78532.40\",\"1.018\"],[\"78612.00\",\"2.768\"],[\"78691.60\",\"3.047\"],[\"78811.00\",\"4.126\"],[\"79209.00\",\"0.001\"],[\"79209.10\",\"3.667\"],[\"79236.90\",\"0.247\"],[\"79434.00\",\"0.176\"],[\"79493.70\",\"2.161\"],[\"79556.30\",\"0.000\"],[\"79567.50\",\"2.275\"],[\"79585.70\",\"0.000\"],[\"79588.10\",\"0.629\"],[\"79592.80\",\"0.003\"],[\"79600.50\",\"0.076\"],[\"79605.20\",\"0.002\"],[\"79605.30\",\"0.027\"],[\"79605.50\",\"0.028\"],[\"79607.10\",\"9.807\"]],\"a\":[[\"79607.20\",\"2.797\"],[\"79609.20\",\"0.502\"],[\"79609.30\",\"0.000\"],[\"79611.20\",\"0.090\"],[\"79612.50\",\"0.001\"],[\"79613.50\",\"0.002\"],[\"79640.90\",\"0.005\"],[\"79645.80\",\"0.000\"],[\"79645.90\",\"3.129\"],[\"79663.00\",\"0.002\"],[\"79688.30\",\"0.021\"],[\"79788.80\",\"0.000\"],[\"79973.40\",\"1.913\"],[\"80403.30\",\"8.062\"],[\"80562.50\",\"20.331\"]],\"st\":1}}"}
{"receive_ns":1788563202117367000,"stream":"btcusdt@trade","event_type":"trade","event_time_ms":1788563202152,"raw_json":"{\"stream\":\"btcusdt@trade\",\"data\":{\"e\":\"trade\",\"E\":1788563202152,\"T\":1788563202152,\"s\":\"BTCUSDT\",\"t\":8054082687,\"p\":\"79607.10\",\"q\":\"0.005\",\"X\":\"MARKET\",\"m\":true,\"st\":1}}"}
{"receive_ns":1788563202117682000,"stream":"btcusdt@bookTicker","event_type":"bookTicker","event_time_ms":1788563202152,"raw_json":"{\"stream\":\"btcusdt@bookTicker\",\"data\":{\"e\":\"bookTicker\",\"u\":11478223023134,\"s\":\"BTCUSDT\",\"ps\":\"BTCUSDT\",\"b\":\"79607.10\",\"B\":\"9.802\",\"a\":\"79607.20\",\"A\":\"2.797\",\"T\":1788563202152,\"E\":1788563202152,\"st\":1}}"}
{"receive_ns":1788563202118414000,"stream":"btcusdt@bookTicker","event_type":"bookTicker","event_time_ms":1788563202153,"raw_json":"{\"stream\":\"btcusdt@bookTicker\",\"data\":{\"e\":\"bookTicker\",\"u\":11478223023227,\"s\":\"BTCUSDT\",\"ps\":\"BTCUSDT\",\"b\":\"79607.10\",\"B\":\"9.810\",\"a\":\"79607.20\",\"A\":\"2.797\",\"T\":1788563202153,\"E\":1788563202153,\"st\":1}}"}
{"receive_ns":1788563202118707000,"stream":"btcusdt@bookTicker","event_type":"bookTicker","event_time_ms":1788563202154,"raw_json":"{\"stream\":\"btcusdt@bookTicker\",\"data\":{\"e\":\"bookTicker\",\"u\":11478223023322,\"s\":\"BTCUSDT\",\"ps\":\"BTCUSDT\",\"b\":\"79607.10\",\"B\":\"9.802\",\"a\":\"79607.20\",\"A\":\"2.797\",\"T\":1788563202154,\"E\":1788563202154,\"st\":1}}"}
{"receive_ns":1788563202168332000,"stream":"btcusdt@bookTicker","event_type":"bookTicker","event_time_ms":1788563202203,"raw_json":"{\"stream\":\"btcusdt@bookTicker\",\"data\":{\"e\":\"bookTicker\",\"u\":11478223025769,\"s\":\"BTCUSDT\",\"ps\":\"BTCUSDT\",\"b\":\"79607.10\",\"B\":\"9.803\",\"a\":\"79607.20\",\"A\":\"2.797\",\"T\":1788563202203,\"E\":1788563202203,\"st\":1}}"}
{"receive_ns":1788563202196150000,"stream":"btcusdt@bookTicker","event_type":"bookTicker","event_time_ms":1788563202229,"raw_json":"{\"stream\":\"btcusdt@bookTicker\",\"data\":{\"e\":\"bookTicker\",\"u\":11478223027117,\"s\":\"BTCUSDT\",\"ps\":\"BTCUSDT\",\"b\":\"79607.10\",\"B\":\"9.802\",\"a\":\"79607.20\",\"A\":\"2.797\",\"T\":1788563202229,\"E\":1788563202229,\"st\":1}}"}
{"receive_ns":1788563202199021000,"stream":"btcusdt@depth@100ms","event_type":"depthUpdate","event_time_ms":1788563202235,"raw_json":"{\"stream\":\"btcusdt@depth@100ms\",\"data\":{\"e\":\"depthUpdate\",\"E\":1788563202235,\"T\":1788563202234,\"s\":\"BTCUSDT\",\"ps\":\"BTCUSDT\",\"U\":11478223022240,\"u\":11478223027416,\"pu\":11478223022174,\"b\":[[\"1000.00\",\"24.604\"],[\"29407.10\",\"1.603\"],[\"29507.10\",\"0.497\"],[\"71646.30\",\"0.002\"],[\"75626.80\",\"0.002\"],[\"76422.80\",\"0.000\"],[\"78651.80\",\"12.758\"],[\"78811.00\",\"4.126\"],[\"78970.20\",\"2.528\"],[\"79209.10\",\"3.677\"],[\"79478.90\",\"0.002\"],[\"79487.70\",\"0.503\"],[\"79491.70\",\"1.004\"],[\"79511.50\",\"0.024\"],[\"79538.40\",\"4.182\"],[\"79578.80\",\"1.889\"],[\"79578.90\",\"1.429\"],[\"79599.10\",\"0.001\"],[\"79599.30\",\"0.102\"],[\"79603.80\",\"0.000\"],[\"79605.60\",\"0.108\"],[\"79607.10\",\"9.802\"]],\"a\":[[\"79640.70\",\"2.954\"],[\"79640.80\",\"10.076\"],[\"79642.30\",\"0.079\"],[\"79642.40\",\"3.020\"],[\"79678.90\",\"0.018\"],[\"79682.50\",\"0.018\"],[\"79682.90\",\"0.000\"],[\"79683.00\",\"0.019\"],[\"79688.60\",\"0.006\"],[\"79973.40\",\"1.913\"],[\"80403.30\",\"8.062\"],[\"81199.30\",\"0.018\"]],\"st\":1}}"}
{"receive_ns":1788563202212421000,"stream":"btcusdt@bookTicker","event_type":"bookTicker","event_time_ms":1788563202247,"raw_json":"{\"stream\":\"btcusdt@bookTicker\",\"data\":{\"e\":\"bookTicker\",\"u\":11478223028210,\"s\":\"BTCUSDT\",\"ps\":\"BTCUSDT\",\"b\":\"79607.10\",\"B\":\"9.802\",\"a\":\"79607.20\",\"A\":\"2.796\",\"T\":1788563202247,\"E\":1788563202247,\"st\":1}}"}
{"receive_ns":1788563202212646000,"stream":"btcusdt@trade","event_type":"trade","event_time_ms":1788563202247,"raw_json":"{\"stream\":\"btcusdt@trade\",\"data\":{\"e\":\"trade\",\"E\":1788563202247,\"T\":1788563202247,\"s\":\"BTCUSDT\",\"t\":8054082688,\"p\":\"79607.20\",\"q\":\"0.001\",\"X\":\"MARKET\",\"m\":false,\"st\":1}}"}
{"receive_ns":1788563202212859000,"stream":"btcusdt@bookTicker","event_type":"bookTicker","event_time_ms":1788563202248,"raw_json":"{\"stream\":\"btcusdt@bookTicker\",\"data\":{\"e\":\"bookTicker\",\"u\":11478223028357,\"s\":\"BTCUSDT\",\"ps\":\"BTCUSDT\",\"b\":\"79607.10\",\"B\":\"9.810\",\"a\":\"79607.20\",\"A\":\"2.796\",\"T\":1788563202248,\"E\":1788563202248,\"st\":1}}"}
{"receive_ns":1788563202213502000,"stream":"btcusdt@bookTicker","event_type":"bookTicker","event_time_ms":1788563202249,"raw_json":"{\"stream\":\"btcusdt@bookTicker\",\"data\":{\"e\":\"bookTicker\",\"u\":11478223028520,\"s\":\"BTCUSDT\",\"ps\":\"BTCUSDT\",\"b\":\"79607.10\",\"B\":\"9.802\",\"a\":\"79607.20\",\"A\":\"2.796\",\"T\":1788563202249,\"E\":1788563202249,\"st\":1}}"}
{"receive_ns":1788563202221299000,"stream":"btcusdt@bookTicker","event_type":"bookTicker","event_time_ms":1788563202256,"raw_json":"{\"stream\":\"btcusdt@bookTicker\",\"data\":{\"e\":\"bookTicker\",\"u\":11478223028975,\"s\":\"BTCUSDT\",\"ps\":\"BTCUSDT\",\"b\":\"79607.10\",\"B\":\"9.810\",\"a\":\"79607.20\",\"A\":\"2.796\",\"T\":1788563202255,\"E\":1788563202256,\"st\":1}}"}
{"receive_ns":1788563202221600000,"stream":"btcusdt@bookTicker","event_type":"bookTicker","event_time_ms":1788563202256,"raw_json":"{\"stream\":\"btcusdt@bookTicker\",\"data\":{\"e\":\"bookTicker\",\"u\":11478223029038,\"s\":\"BTCUSDT\",\"ps\":\"BTCUSDT\",\"b\":\"79607.10\",\"B\":\"9.802\",\"a\":\"79607.20\",\"A\":\"2.796\",\"T\":1788563202256,\"E\":1788563202256,\"st\":1}}"}
{"receive_ns":1788563202284105000,"stream":"btcusdt@bookTicker","event_type":"bookTicker","event_time_ms":1788563202290,"raw_json":"{\"stream\":\"btcusdt@bookTicker\",\"data\":{\"e\":\"bookTicker\",\"u\":11478223030963,\"s\":\"BTCUSDT\",\"ps\":\"BTCUSDT\",\"b\":\"79607.10\",\"B\":\"9.443\",\"a\":\"79607.20\",\"A\":\"2.796\",\"T\":1788563202290,\"E\":1788563202290,\"st\":1}}"}
{"receive_ns":1788563202284486000,"stream":"btcusdt@bookTicker","event_type":"bookTicker","event_time_ms":1788563202294,"raw_json":"{\"stream\":\"btcusdt@bookTicker\",\"data\":{\"e\":\"bookTicker\",\"u\":11478223031158,\"s\":\"BTCUSDT\",\"ps\":\"BTCUSDT\",\"b\":\"79607.10\",\"B\":\"9.814\",\"a\":\"79607.20\",\"A\":\"2.796\",\"T\":1788563202293,\"E\":1788563202294,\"st\":1}}"}
{"receive_ns":1788563202301366000,"stream":"btcusdt@depth@100ms","event_type":"depthUpdate","event_time_ms":1788563202337,"raw_json":"{\"stream\":\"btcusdt@depth@100ms\",\"data\":{\"e\":\"depthUpdate\",\"E\":1788563202337,\"T\":1788563202333,\"s\":\"BTCUSDT\",\"ps\":\"BTCUSDT\",\"U\":11478223027510,\"u\":11478223032947,\"pu\":11478223027416,\"b\":[[\"29307.10\",\"0.007\"],[\"29407.10\",\"1.764\"],[\"29507.10\",\"0.329\"],[\"71646.30\",\"0.002\"],[\"75626.70\",\"0.025\"],[\"76422.80\",\"0.002\"],[\"78006.10\",\"3.590\"],[\"78094.60\",\"0.000\"],[\"78183.00\",\"0.000\"],[\"78271.50\",\"0.000\"],[\"78359.90\",\"4.503\"],[\"78368.50\",\"1.784\"],[\"78448.30\",\"0.002\"],[\"78536.80\",\"0.000\"],[\"78603.10\",\"5.795\"],[\"78625.20\",\"5.941\"],[\"78651.80\",\"14.028\"],[\"78713.70\",\"0.000\"],[\"78802.10\",\"4.531\"],[\"78811.00\",\"4.126\"],[\"79209.10\",\"3.677\"],[\"79236.90\",\"0.247\"],[\"79434.00\",\"0.176\"],[\"79481.50\",\"0.000\"],[\"79491.70\",\"2.208\"],[\"79493.70\",\"0.957\"],[\"79576.50\",\"0.002\"],[\"79584.50\",\"0.060\"],[\"79585.50\",\"0.000\"],[\"79585.70\",\"0.000\"],[\"79588.10\",\"0.001\"],[\"79589.10\",\"0.000\"],[\"79589.20\",\"0.823\"],[\"79600.90\",\"0.000\"],[\"79601.60\",\"0.001\"],[\"79602.30\",\"0.251\"],[\"79603.90\",\"0.000\"],[\"79604.00\",\"0.003\"],[\"79605.80\",\"0.026\"],[\"79606.00\",\"0.029\"],[\"79607.10\",\"9.814\"]],\"a\":[[\"79607.20\",\"2.796\"],[\"79609.20\",\"0.502\"],[\"79611.20\",\"0.289\"],[\"79651.80\",\"0.327\"],[\"79730.30\",\"0.000\"],[\"79973.40\",\"1.913\"],[\"80394.10\",\"0.111\"],[\"80403.30\",\"8.062\"],[\"80482.50\",\"0.001\"],[\"80571.00\",\"0.013\"],[\"80659.40\",\"0.000\"],[\"80747.90\",\"0.001\"],[\"80792.20\",\"25.894\"],[\"80836.30\",\"0.002\"],[\"80924.70\",\"0.000\"],[\"81013.20\",\"0.978\"],[\"81101.60\",\"0.001\"],[\"81190.10\",\"0.002\"],[\"81199.30\",\"0.021\"]],\"st\":1}}"}
{"receive_ns":1788563202403167000,"stream":"btcusdt@depth@100ms","event_type":"depthUpdate","event_time_ms":1788563202439,"raw_json":"{\"stream\":\"btcusdt@depth@100ms\",\"data\":{\"e\":\"depthUpdate\",\"E\":1788563202439,\"T\":1788563202438,\"s\":\"BTCUSDT\",\"ps\":\"BTCUSDT\",\"U\":11478223033182,\"u\":11478223038010,\"pu\":11478223032947,\"b\":[[\"1000.00\",\"24.754\"],[\"29307.10\",\"0.070\"],[\"29407.10\",\"1.820\"],[\"29507.10\",\"0.210\"],[\"71646.30\",\"0.002\"],[\"76422.80\",\"0.000\"],[\"78237.90\",\"1.020\"],[\"78811.00\",\"4.126\"],[\"79487.70\",\"0.001\"],[\"79491.70\",\"2.208\"],[\"79585.70\",\"0.628\"],[\"79589.20\",\"0.195\"],[\"79589.30\",\"0.001\"],[\"79606.00\",\"0.003\"]],\"a\":[[\"79973.40\",\"1.494\"],[\"80000.40\",\"1.996\"],[\"80403.30\",\"8.062\"],[\"81000.00\",\"51.309\"]],\"st\":1}}"}
{"receive_ns":1788563202434238000,"stream":"btcusdt@bookTicker","event_type":"bookTicker","event_time_ms":1788563202463,"raw_json":"{\"stream\":\"btcusdt@bookTicker\",\"data\":{\"e\":\"bookTicker\",\"u\":11478223039159,\"s\":\"BTCUSDT\",\"ps\":\"BTCUSDT\",\"b\":\"79607.10\",\"B\":\"9.330\",\"a\":\"79607.20\",\"A\":\"2.796\",\"T\":1788563202462,\"E\":1788563202463,\"st\":1}}"}
{"receive_ns":1788563202434765000,"stream":"btcusdt@bookTicker","event_type":"bookTicker","event_time_ms":1788563202466,"raw_json":"{\"stream\":\"btcusdt@bookTicker\",\"data\":{\"e\":\"bookTicker\",\"u\":11478223039373,\"s\":\"BTCUSDT\",\"ps\":\"BTCUSDT\",\"b\":\"79607.10\",\"B\":\"9.329\",\"a\":\"79607.20\",\"A\":\"2.796\",\"T\":1788563202466,\"E\":1788563202466,\"st\":1}}"}
{"receive_ns":1788563202435159000,"stream":"btcusdt@bookTicker","event_type":"bookTicker","event_time_ms":1788563202466,"raw_json":"{\"stream\":\"btcusdt@bookTicker\",\"data\":{\"e\":\"bookTicker\",\"u\":11478223039374,\"s\":\"BTCUSDT\",\"ps\":\"BTCUSDT\",\"b\":\"79607.10\",\"B\":\"9.328\",\"a\":\"79607.20\",\"A\":\"2.796\",\"T\":1788563202466,\"E\":1788563202466,\"st\":1}}"}
{"receive_ns":1788563202435353000,"stream":"btcusdt@bookTicker","event_type":"bookTicker","event_time_ms":1788563202466,"raw_json":"{\"stream\":\"btcusdt@bookTicker\",\"data\":{\"e\":\"bookTicker\",\"u\":11478223039383,\"s\":\"BTCUSDT\",\"ps\":\"BTCUSDT\",\"b\":\"79607.10\",\"B\":\"9.327\",\"a\":\"79607.20\",\"A\":\"2.796\",\"T\":1788563202466,\"E\":1788563202466,\"st\":1}}"}
{"receive_ns":1788563202436429000,"stream":"btcusdt@bookTicker","event_type":"bookTicker","event_time_ms":1788563202471,"raw_json":"{\"stream\":\"btcusdt@bookTicker\",\"data\":{\"e\":\"bookTicker\",\"u\":11478223039599,\"s\":\"BTCUSDT\",\"ps\":\"BTCUSDT\",\"b\":\"79607.10\",\"B\":\"9.812\",\"a\":\"79607.20\",\"A\":\"2.796\",\"T\":1788563202471,\"E\":1788563202471,\"st\":1}}"}
{"receive_ns":1788563202440998000,"stream":"btcusdt@bookTicker","event_type":"bookTicker","event_time_ms":1788563202475,"raw_json":"{\"stream\":\"btcusdt@bookTicker\",\"data\":{\"e\":\"bookTicker\",\"u\":11478223039750,\"s\":\"BTCUSDT\",\"ps\":\"BTCUSDT\",\"b\":\"79607.10\",\"B\":\"9.860\",\"a\":\"79607.20\",\"A\":\"2.796\",\"T\":1788563202475,\"E\":1788563202475,\"st\":1}}"}
{"receive_ns":1788563202441223000,"stream":"btcusdt@bookTicker","event_type":"bookTicker","event_time_ms":1788563202475,"raw_json":"{\"stream\":\"btcusdt@bookTicker\",\"data\":{\"e\":\"bookTicker\",\"u\":11478223039752,\"s\":\"BTCUSDT\",\"ps\":\"BTCUSDT\",\"b\":\"79607.10\",\"B\":\"9.908\",\"a\":\"79607.20\",\"A\":\"2.796\",\"T\":1788563202475,\"E\":1788563202475,\"st\":1}}"}
{"receive_ns":1788563202441416000,"stream":"btcusdt@bookTicker","event_type":"bookTicker","event_time_ms":1788563202475,"raw_json":"{\"stream\":\"btcusdt@bookTicker\",\"data\":{\"e\":\"bookTicker\",\"u\":11478223039754,\"s\":\"BTCUSDT\",\"ps\":\"BTCUSDT\",\"b\":\"79607.10\",\"B\":\"9.956\",\"a\":\"79607.20\",\"A\":\"2.796\",\"T\":1788563202475,\"E\":1788563202475,\"st\":1}}"}
{"receive_ns":1788563202441686000,"stream":"btcusdt@bookTicker","event_type":"bookTicker","event_time_ms":1788563202476,"raw_json":"{\"stream\":\"btcusdt@bookTicker\",\"data\":{\"e\":\"bookTicker\",\"u\":11478223039811,\"s\":\"BTCUSDT\",\"ps\":\"BTCUSDT\",\"b\":\"79607.10\",\"B\":\"9.954\",\"a\":\"79607.20\",\"A\":\"2.796\",\"T\":1788563202476,\"E\":1788563202476,\"st\":1}}"}
{"receive_ns":1788563202467883000,"stream":"btcusdt@bookTicker","event_type":"bookTicker","event_time_ms":1788563202503,"raw_json":"{\"stream\":\"btcusdt@bookTicker\",\"data\":{\"e\":\"bookTicker\",\"u\":11478223041379,\"s\":\"BTCUSDT\",\"ps\":\"BTCUSDT\",\"b\":\"79607.10\",\"B\":\"9.962\",\"a\":\"79607.20\",\"A\":\"2.796\",\"T\":1788563202503,\"E\":1788563202503,\"st\":1}}"}
{"receive_ns":1788563202468699000,"stream":"btcusdt@bookTicker","event_type":"bookTicker","event_time_ms":1788563202504,"raw_json":"{\"stream\":\"btcusdt@bookTicker\",\"data\":{\"e\":\"bookTicker\",\"u\":11478223041434,\"s\":\"BTCUSDT\",\"ps\":\"BTCUSDT\",\"b\":\"79607.10\",\"B\":\"9.954\",\"a\":\"79607.20\",\"A\":\"2.796\",\"T\":1788563202504,\"E\":1788563202504,\"st\":1}}"}
{"receive_ns":1788563202502051000,"stream":"btcusdt@bookTicker","event_type":"bookTicker","event_time_ms":1788563202530,"raw_json":"{\"stream\":\"btcusdt@bookTicker\",\"data\":{\"e\":\"bookTicker\",\"u\":11478223042587,\"s\":\"BTCUSDT\",\"ps\":\"BTCUSDT\",\"b\":\"79607.10\",\"B\":\"9.954\",\"a\":\"79607.20\",\"A\":\"2.793\",\"T\":1788563202530,\"E\":1788563202530,\"st\":1}}"}
{"receive_ns":1788563202502315000,"stream":"btcusdt@bookTicker","event_type":"bookTicker","event_time_ms":1788563202531,"raw_json":"{\"stream\":\"btcusdt@bookTicker\",\"data\":{\"e\":\"bookTicker\",\"u\":11478223042662,\"s\":\"BTCUSDT\",\"ps\":\"BTCUSDT\",\"b\":\"79607.10\",\"B\":\"9.954\",\"a\":\"79607.20\",\"A\":\"2.767\",\"T\":1788563202530,\"E\":1788563202531,\"st\":1}}"}
{"receive_ns":1788563202505550000,"stream":"btcusdt@depth@100ms","event_type":"depthUpdate","event_time_ms":1788563202541,"raw_json":"{\"stream\":\"btcusdt@depth@100ms\",\"data\":{\"e\":\"depthUpdate\",\"E\":1788563202541,\"T\":1788563202537,\"s\":\"BTCUSDT\",\"ps\":\"BTCUSDT\",\"U\":11478223038120,\"u\":11478223043083,\"pu\":11478223038010,\"b\":[[\"1000.00\",\"24.604\"],[\"29307.10\",\"0.126\"],[\"29407.10\",\"1.883\"],[\"29507.10\",\"0.091\"],[\"71646.30\",\"0.002\"],[\"78373.20\",\"3.568\"],[\"78811.00\",\"4.126\"],[\"79209.10\",\"3.536\"],[\"79236.90\",\"0.015\"],[\"79394.30\",\"5.881\"],[\"79394.40\",\"0.000\"],[\"79434.00\",\"0.076\"],[\"79442.10\",\"2.819\"],[\"79453.90\",\"0.706\"],[\"79479.00\",\"1.013\"],[\"79479.10\",\"0.125\"],[\"79481.50\",\"0.477\"],[\"79487.70\",\"1.205\"],[\"79491.70\",\"1.004\"],[\"79493.70\",\"0.631\"],[\"79516.10\",\"2.938\"],[\"79524.90\",\"0.013\"],[\"79575.40\",\"0.454\"],[\"79576.20\",\"0.001\"],[\"79590.50\",\"0.000\"],[\"79599.30\",\"0.001\"],[\"79600.30\",\"0.505\"],[\"79600.40\",\"0.144\"],[\"79600.90\",\"0.000\"],[\"79601.60\",\"0.000\"],[\"79602.20\",\"0.047\"],[\"79603.50\",\"0.076\"],[\"79604.10\",\"0.000\"],[\"79604.20\",\"0.000\"],[\"79606.10\",\"0.026\"],[\"79606.60\",\"0.028\"],[\"79607.00\",\"0.033\"],[\"79607.10\",\"9.954\"]],\"a\":[[\"79607.20\",\"2.767\"],[\"79609.20\",\"0.000\"],[\"79609.70\",\"0.000\"],[\"79611.20\",\"0.000\"],[\"79674.30\",\"0.000\"],[\"79682.50\",\"0.078\"],[\"79697.90\",\"3.995\"],[\"79698.00\",\"0.211\"],[\"79730.30\",\"0.231\"],[\"79769.70\",\"1.220\"],[\"79769.80\",\"0.000\"],[\"79812.00\",\"0.607\"],[\"79815.80\",\"0.000\"],[\"79817.30\",\"1.409\"],[\"79817.40\",\"2.173\"],[\"79818.80\",\"0.001\"],[\"79828.70\",\"9.673\"],[\"79973.40\",\"1.713\"],[\"80403.30\",\"8.062\"],[\"80968.50\",\"0.619\"]],\"st\":1}}"}
{"receive_ns":1788563202505839000,"stream":"btcusdt@bookTicker","event_type":"bookTicker","event_time_ms":1788563202541,"raw_json":"{\"stream\":\"btcusdt@bookTicker\",\"data\":{\"e\":\"bookTicker\",\"u\":11478223043260,\"s\":\"BTCUSDT\",\"ps\":\"BTCUSDT\",\"b\":\"79607.10\",\"B\":\"9.579\",\"a\":\"79607.20\",\"A\":\"2.767\",\"T\":1788563202541,\"E\":1788563202541,\"st\":1}}"}
{"receive_ns":1788563202510088000,"stream":"btcusdt@bookTicker","event_type":"bookTicker","event_time_ms":1788563202544,"raw_json":"{\"stream\":\"btcusdt@bookTicker\",\"data\":{\"e\":\"bookTicker\",\"u\":11478223043379,\"s\":\"BTCUSDT\",\"ps\":\"BTCUSDT\",\"b\":\"79607.10\",\"B\":\"9.956\",\"a\":\"79607.20\",\"A\":\"2.767\",\"T\":1788563202544,\"E\":1788563202544,\"st\":1}}"}
{"receive_ns":1788563202510310000,"stream":"btcusdt@bookTicker","event_type":"bookTicker","event_time_ms":1788563202546,"raw_json":"{\"stream\":\"btcusdt@bookTicker\",\"data\":{\"e\":\"bookTicker\",\"u\":11478223043472,\"s\":\"BTCUSDT\",\"ps\":\"BTCUSDT\",\"b\":\"79607.10\",\"B\":\"9.958\",\"a\":\"79607.20\",\"A\":\"2.767\",\"T\":1788563202545,\"E\":1788563202546,\"st\":1}}"}
{"receive_ns":1788563202510456000,"stream":"btcusdt@bookTicker","event_type":"bookTicker","event_time_ms":1788563202546,"raw_json":"{\"stream\":\"btcusdt@bookTicker\",\"data\":{\"e\":\"bookTicker\",\"u\":11478223043493,\"s\":\"BTCUSDT\",\"ps\":\"BTCUSDT\",\"b\":\"79607.10\",\"B\":\"9.957\",\"a\":\"79607.20\",\"A\":\"2.767\",\"T\":1788563202546,\"E\":1788563202546,\"st\":1}}"}
{"receive_ns":1788563202512528000,"stream":"btcusdt@bookTicker","event_type":"bookTicker","event_time_ms":1788563202547,"raw_json":"{\"stream\":\"btcusdt@bookTicker\",\"data\":{\"e\":\"bookTicker\",\"u\":11478223043555,\"s\":\"BTCUSDT\",\"ps\":\"BTCUSDT\",\"b\":\"79607.10\",\"B\":\"9.958\",\"a\":\"79607.20\",\"A\":\"2.767\",\"T\":1788563202547,\"E\":1788563202547,\"st\":1}}"}
{"receive_ns":1788563202536634000,"stream":"btcusdt@bookTicker","event_type":"bookTicker","event_time_ms":1788563202570,"raw_json":"{\"stream\":\"btcusdt@bookTicker\",\"data\":{\"e\":\"bookTicker\",\"u\":11478223044843,\"s\":\"BTCUSDT\",\"ps\":\"BTCUSDT\",\"b\":\"79607.10\",\"B\":\"9.958\",\"a\":\"79607.20\",\"A\":\"2.793\",\"T\":1788563202570,\"E\":1788563202570,\"st\":1}}"}
{"receive_ns":1788563202536910000,"stream":"btcusdt@bookTicker","event_type":"bookTicker","event_time_ms":1788563202572,"raw_json":"{\"stream\":\"btcusdt@bookTicker\",\"data\":{\"e\":\"bookTicker\",\"u\":11478223044907,\"s\":\"BTCUSDT\",\"ps\":\"BTCUSDT\",\"b\":\"79607.10\",\"B\":\"9.958\",\"a\":\"79607.20\",\"A\":\"2.792\",\"T\":1788563202572,\"E\":1788563202572,\"st\":1}}"}
{"receive_ns":1788563202545842000,"stream":"btcusdt@bookTicker","event_type":"bookTicker","event_time_ms":1788563202579,"raw_json":"{\"stream\":\"btcusdt@bookTicker\",\"data\":{\"e\":\"bookTicker\",\"u\":11478223045333,\"s\":\"BTCUSDT\",\"ps\":\"BTCUSDT\",\"b\":\"79607.10\",\"B\":\"9.958\",\"a\":\"79607.20\",\"A\":\"2.766\",\"T\":1788563202579,\"E\":1788563202579,\"st\":1}}"}
{"receive_ns":1788563202546062000,"stream":"btcusdt@bookTicker","event_type":"bookTicker","event_time_ms":1788563202580,"raw_json":"{\"stream\":\"btcusdt@bookTicker\",\"data\":{\"e\":\"bookTicker\",\"u\":11478223045469,\"s\":\"BTCUSDT\",\"ps\":\"BTCUSDT\",\"b\":\"79607.10\",\"B\":\"9.958\",\"a\":\"79607.20\",\"A\":\"2.792\",\"T\":1788563202580,\"E\":1788563202580,\"st\":1}}"}
{"receive_ns":1788563202546259000,"stream":"btcusdt@bookTicker","event_type":"bookTicker","event_time_ms":1788563202582,"raw_json":"{\"stream\":\"btcusdt@bookTicker\",\"data\":{\"e\":\"bookTicker\",\"u\":11478223045582,\"s\":\"BTCUSDT\",\"ps\":\"BTCUSDT\",\"b\":\"79607.10\",\"B\":\"9.958\",\"a\":\"79607.20\",\"A\":\"2.793\",\"T\":1788563202581,\"E\":1788563202582,\"st\":1}}"}
{"receive_ns":1788563202549703000,"stream":"btcusdt@bookTicker","event_type":"bookTicker","event_time_ms":1788563202584,"raw_json":"{\"stream\":\"btcusdt@bookTicker\",\"data\":{\"e\":\"bookTicker\",\"u\":11478223045812,\"s\":\"BTCUSDT\",\"ps\":\"BTCUSDT\",\"b\":\"79607.10\",\"B\":\"9.961\",\"a\":\"79607.20\",\"A\":\"2.793\",\"T\":1788563202584,\"E\":1788563202584,\"st\":1}}"}
{"receive_ns":1788563202608024000,"stream":"btcusdt@depth@100ms","event_type":"depthUpdate","event_time_ms":1788563202643,"raw_json":"{\"stream\":\"btcusdt@depth@100ms\",\"data\":{\"e\":\"depthUpdate\",\"E\":1788563202643,\"T\":1788563202642,\"s\":\"BTCUSDT\",\"ps\":\"BTCUSDT\",\"U\":11478223043260,\"u\":11478223048453,\"pu\":11478223043083,\"b\":[[\"29307.10\",\"0.217\"],[\"29407.10\",\"1.883\"],[\"29507.10\",\"0.000\"],[\"63686.00\",\"0.000\"],[\"71646.30\",\"0.002\"],[\"75626.70\",\"0.023\"],[\"75626.80\",\"0.004\"],[\"76422.80\",\"0.002\"],[\"78452.80\",\"5.499\"],[\"78811.00\",\"4.126\"],[\"79209.10\",\"3.677\"],[\"79236.90\",\"0.247\"],[\"79434.00\",\"0.176\"],[\"79479.10\",\"0.000\"],[\"79479.60\",\"0.149\"],[\"79491.70\",\"0.326\"],[\"79575.40\",\"0.002\"],[\"79576.20\",\"0.453\"],[\"79577.40\",\"0.000\"],[\"79598.30\",\"0.161\"],[\"79600.30\",\"0.253\"],[\"79603.50\",\"0.000\"],[\"79606.20\",\"0.027\"],[\"79606.60\",\"0.002\"],[\"79606.80\",\"0.004\"],[\"79607.00\",\"0.007\"],[\"79607.10\",\"9.961\"]],\"a\":[[\"79607.20\",\"2.793\"],[\"79609.20\",\"0.502\"],[\"79611.20\",\"0.289\"],[\"79612.40\",\"0.255\"],[\"79613.50\",\"0.000\"],[\"79614.70\",\"0.252\"],[\"79625.70\",\"0.001\"],[\"79627.10\",\"0.453\"],[\"79973.40\",\"1.388\"],[\"80005.20\",\"2.257\"],[\"80244.10\",\"1.991\"],[\"80403.30\",\"8.062\"],[\"80764.10\",\"0.001\"]],\"st\":1}}"}
{"receive_ns":1788563202656519000,"stream":"btcusdt@bookTicker","event_type":"bookTicker","event_time_ms":1788563202690,"raw_json":"{\"stream\":\"btcusdt@bookTicker\",\"data\":{\"e\":\"bookTicker\",\"u\":11478223052304,\"s\":\"BTCUSDT\",\"ps\":\"BTCUSDT\",\"b\":\"79607.10\",\"B\":\"9.969\",\"a\":\"79607.20\",\"A\":\"2.793\",\"T\":1788563202689,\"E\":1788563202690,\"st\":1}}"}
{"receive_ns":1788563202656900000,"stream":"btcusdt@bookTicker","event_type":"bookTicker","event_time_ms":1788563202690,"raw_json":"{\"stream\":\"btcusdt@bookTicker\",\"data\":{\"e\":\"bookTicker\",\"u\":11478223052360,\"s\":\"BTCUSDT\",\"ps\":\"BTCUSDT\",\"b\":\"79607.10\",\"B\":\"9.961\",\"a\":\"79607.20\",\"A\":\"2.793\",\"T\":1788563202690,\"E\":1788563202690,\"st\":1}}"}
{"receive_ns":1788563202684544000,"stream":"btcusdt@bookTicker","event_type":"bookTicker","event_time_ms":1788563202718,"raw_json":"{\"stream\":\"btcusdt@bookTicker\",\"data\":{\"e\":\"bookTicker\",\"u\":11478223053540,\"s\":\"BTCUSDT\",\"ps\":\"BTCUSDT\",\"b\":\"79607.10\",\"B\":\"9.969\",\"a\":\"79607.20\",\"A\":\"2.793\",\"T\":1788563202718,\"E\":1788563202718,\"st\":1}}"}
{"receive_ns":1788563202684843000,"stream":"btcusdt@bookTicker","event_type":"bookTicker","event_time_ms":1788563202719,"raw_json":"{\"stream\":\"btcusdt@bookTicker\",\"data\":{\"e\":\"bookTicker\",\"u\":11478223053577,\"s\":\"BTCUSDT\",\"ps\":\"BTCUSDT\",\"b\":\"79607.10\",\"B\":\"9.961\",\"a\":\"79607.20\",\"A\":\"2.793\",\"T\":1788563202719,\"E\":1788563202719,\"st\":1}}"}
{"receive_ns":1788563202710817000,"stream":"btcusdt@depth@100ms","event_type":"depthUpdate","event_time_ms":1788563202745,"raw_json":"{\"stream\":\"btcusdt@depth@100ms\",\"data\":{\"e\":\"depthUpdate\",\"E\":1788563202745,\"T\":1788563202741,\"s\":\"BTCUSDT\",\"ps\":\"BTCUSDT\",\"U\":11478223048482,\"u\":11478223054423,\"pu\":11478223048453,\"b\":[[\"1000.00\",\"24.604\"],[\"29307.10\",\"0.392\"],[\"29407.10\",\"1.708\"],[\"71646.30\",\"0.002\"],[\"76422.80\",\"0.000\"],[\"78456.70\",\"1.402\"],[\"78811.00\",\"4.126\"],[\"79209.00\",\"0.002\"],[\"79453.90\",\"0.204\"],[\"79478.40\",\"0.125\"],[\"79478.90\",\"0.002\"],[\"79479.90\",\"0.079\"],[\"79491.70\",\"1.832\"],[\"79604.10\",\"0.026\"],[\"79604.20\",\"0.026\"],[\"79605.80\",\"0.000\"],[\"79606.10\",\"0.000\"],[\"79606.20\",\"0.001\"],[\"79606.30\",\"0.000\"],[\"79606.40\",\"0.108\"],[\"79607.10\",\"9.961\"]],\"a\":[[\"79973.40\",\"1.913\"],[\"80005.30\",\"0.001\"],[\"80403.30\",\"8.062\"],[\"80546.80\",\"1.229\"],[\"80721.70\",\"17.815\"],[\"80756.60\",\"5.320\"],[\"80836.20\",\"2.380\"],[\"81199.30\",\"0.024\"]],\"st\":1}}"}
{"receive_ns":1788563202811900000,"stream":"btcusdt@depth@100ms","event_type":"depthUpdate","event_time_ms":1788563202847,"raw_json":"{\"stream\":\"btcusdt@depth@100ms\",\"data\":{\"e\":\"depthUpdate\",\"E\":1788563202847,\"T\":1788563202845,\"s\":\"BTCUSDT\",\"ps\":\"BTCUSDT\",\"U\":11478223054534,\"u\":11478223059547,\"pu\":11478223054423,\"b\":[[\"29307.10\",\"0.574\"],[\"29407.10\",\"1.526\"],[\"71646.30\",\"0.002\"],[\"76422.80\",\"0.002\"],[\"78448.10\",\"6.493\"],[\"78811.00\",\"4.126\"],[\"79209.10\",\"3.667\"],[\"79236.90\",\"0.247\"],[\"79282.90\",\"0.326\"],[\"79434.00\",\"0.076\"],[\"79453.90\",\"0.304\"],[\"79487.70\",\"0.452\"],[\"79491.70\",\"1.506\"],[\"79493.70\",\"1.710\"]],\"a\":[[\"79609.20\",\"0.000\"],[\"79611.20\",\"0.701\"],[\"79612.40\",\"0.255\"],[\"79613.80\",\"0.000\"],[\"79615.20\",\"0.155\"],[\"79973.40\",\"1.913\"],[\"80403.30\",\"8.062\"],[\"80562.50\",\"21.570\"],[\"80923.80\",\"0.000\"]],\"st\":1}}"}
