{"receive_ns":1788563193297784000,"stream":"btcusdt@bookTicker","event_type":"bookTicker","event_time_ms":1788563193333,"raw_json":"{\"stream\":\"btcusdt@bookTicker\",\"data\":{\"e\":\"bookTicker\",\"u\":11478222497192,\"s\":\"BTCUSDT\",\"ps\":\"BTCUSDT\",\"b\":\"79607.10\",\"B\":\"10.494\",\"a\":\"79607.20\",\"A\":\"1.161\",\"T\":1788563193332,\"E\":1788563193333,\"st\":1}}"}
{"receive_ns":1788563193323974000,"stream":"btcusdt@bookTicker","event_type":"bookTicker","event_time_ms":1788563193358,"raw_json":"{\"stream\":\"btcusdt@bookTicker\",\"data\":{\"e\":\"bookTicker\",\"u\":11478222498791,\"s\":\"BTCUSDT\",\"ps\":\"BTCUSDT\",\"b\":\"79607.10\",\"B\":\"10.173\",\"a\":\"79607.20\",\"A\":\"1.161\",\"T\":1788563193358,\"E\":1788563193358,\"st\":1}}"}
{"receive_ns":1788563193325807000,"stream":"btcusdt@depth@100ms","event_type":"depthUpdate","event_time_ms":1788563193361,"raw_json":"{\"stream\":\"btcusdt@depth@100ms\",\"data\":{\"e\":\"depthUpdate\",\"E\":1788563193361,\"T\":1788563193360,\"s\":\"BTCUSDT\",\"ps\":\"BTCUSDT\",\"U\":11478222492046,\"u\":11478222498939,\"pu\":11478222491841,\"b\":[[\"1000.00\",\"24.604\"],[\"29107.10\",\"0.770\"],[\"29207.10\",\"1.330\"],[\"71646.30\",\"0.002\"],[\"76422.80\",\"0.000\"],[\"78811.00\",\"2.225\"],[\"79392.40\",\"0.083\"],[\"79392.50\",\"5.438\"],[\"79434.00\",\"0.427\"],[\"79440.20\",\"2.661\"],[\"79443.60\",\"0.915\"],[\"79478.80\",\"0.250\"],[\"79478.90\",\"0.127\"],[\"79479.60\",\"0.747\"],[\"79479.70\",\"0.558\"],[\"79530.00\",\"0.231\"],[\"79584.80\",\"0.309\"],[\"79601.10\",\"0.252\"],[\"79604.20\",\"0.076\"],[\"79607.10\",\"10.497\"]],\"a\":[[\"79607.20\",\"1.161\"],[\"79607.30\",\"0.002\"],[\"79609.30\",\"0.000\"],[\"79609.50\",\"0.005\"],[\"79609.60\",\"0.032\"],[\"79609.80\",\"0.000\"],[\"79609.90\",\"0.002\"],[\"79610.10\",\"0.001\"],[\"79610.30\",\"0.716\"],[\"79610.50\",\"0.028\"],[\"79610.60\",\"0.371\"],[\"79611.20\",\"0.116\"],[\"79611.30\",\"0.367\"],[\"79611.40\",\"1.322\"],[\"79611.50\",\"0.596\"],[\"79615.30\",\"0.694\"],[\"79615.70\",\"0.010\"],[\"79619.00\",\"0.194\"],[\"79620.40\",\"0.439\"],[\"79622.50\",\"0.000\"],[\"79623.50\",\"0.376\"],[\"79625.70\",\"0.001\"],[\"79626.80\",\"0.455\"],[\"79655.50\",\"0.002\"],[\"79658.20\",\"9.845\"],[\"79728.60\",\"0.340\"],[\"79768.00\",\"1.948\"],[\"79812.00\",\"1.007\"],[\"79815.80\",\"3.199\"],[\"79973.40\",\"0.969\"],[\"80403.30\",\"7.058\"],[\"80593.20\",\"3.453\"],[\"80602.30\",\"2.675\"],[\"80706.00\",\"5.736\"]],\"st\":1}}"}
{"receive_ns":1788563193326194000,"stream":"btcusdt@bookTicker","event_type":"bookTicker","event_time_ms":1788563193360,"raw_json":"{\"stream\":\"btcusdt@bookTicker\",\"data\":{\"e\":\"bookTicker\",\"u\":11478222498939,\"s\":\"BTCUSDT\",\"ps\":\"BTCUSDT\",\"b\":\"79607.10\",\"B\":\"10.497\",\"a\":\"79607.20\",\"A\":\"1.161\",\"T\":1788563193360,\"E\":1788563193360,\"st\":1}}"}
{"receive_ns":1788563193327112000,"stream":"btcusdt@bookTicker","event_type":"bookTicker","event_time_ms":1788563193362,"raw_json":"{\"stream\":\"btcusdt@bookTicker\",\"data\":{\"e\":\"bookTicker\",\"u\":11478222499019,\"s\":\"BTCUSDT\",\"ps\":\"BTCUSDT\",\"b\":\"79607.10\",\"B\":\"10.062\",\"a\":\"79607.20\",\"A\":\"1.161\",\"T\":1788563193362,\"E\":1788563193362,\"st\":1}}"}
{"receive_ns":1788563193336235000,"stream":"btcusdt@bookTicker","event_type":"bookTicker","event_time_ms":1788563193371,"raw_json":"{\"stream\":\"btcusdt@bookTicker\",\"data\":{\"e\":\"bookTicker\",\"u\":11478222499468,\"s\":\"BTCUSDT\",\"ps\":\"BTCUSDT\",\"b\":\"79607.10\",\"B\":\"10.523\",\"a\":\"79607.20\",\"A\":\"1.161\",\"T\":1788563193370,\"E\":1788563193371,\"st\":1}}"}
{"receive_ns":1788563193345121000,"stream":"btcusdt@bookTicker","event_type":"bookTicker","event_time_ms":1788563193379,"raw_json":"{\"stream\":\"btcusdt@bookTicker\",\"data\":{\"e\":\"bookTicker\",\"u\":11478222499897,\"s\":\"BTCUSDT\",\"ps\":\"BTCUSDT\",\"b\":\"79607.10\",\"B\":\"10.542\",\"a\":\"79607.20\",\"A\":\"1.161\",\"T\":1788563193379,\"E\":1788563193379,\"st\":1}}"}
{"receive_ns":1788563193345474000,"stream":"btcusdt@bookTicker","event_type":"bookTicker","event_time_ms":1788563193380,"raw_json":"{\"stream\":\"btcusdt@bookTicker\",\"data\":{\"e\":\"bookTicker\",\"u\":11478222499917,\"s\":\"BTCUSDT\",\"ps\":\"BTCUSDT\",\"b\":\"79607.10\",\"B\":\"10.523\",\"a\":\"79607.20\",\"A\":\"1.161\",\"T\":1788563193380,\"E\":1788563193380,\"st\":1}}"}
{"receive_ns":1788563193345766000,"stream":"btcusdt@bookTicker","event_type":"bookTicker","event_time_ms":1788563193380,"raw_json":"{\"stream\":\"btcusdt@bookTicker\",\"data\":{\"e\":\"bookTicker\",\"u\":11478222499942,\"s\":\"BTCUSDT\",\"ps\":\"BTCUSDT\",\"b\":\"79607.10\",\"B\":\"10.521\",\"a\":\"79607.20\",\"A\":\"1.161\",\"T\":1788563193380,\"E\":1788563193380,\"st\":1}}"}
{"receive_ns":1788563193465074000,"stream":"btcusdt@depth@100ms","event_type":"depthUpdate","event_time_ms":1788563193463,"raw_json":"{\"stream\":\"btcusdt@depth@100ms\",\"data\":{\"e\":\"depthUpdate\",\"E\":1788563193463,\"T\":1788563193462,\"s\":\"BTCUSDT\",\"ps\":\"BTCUSDT\",\"U\":11478222498966,\"u\":11478222504104,\"pu\":11478222498939,\"b\":[[\"1000.00\",\"24.604\"],[\"29107.10\",\"0.952\"],[\"29207.10\",\"1.148\"],[\"71646.30\",\"0.002\"],[\"78651.80\",\"4.379\"],[\"78811.00\",\"2.225\"],[\"79209.10\",\"0.388\"],[\"79236.90\",\"0.015\"],[\"79434.00\",\"0.578\"],[\"79453.90\",\"0.204\"],[\"79478.90\",\"0.002\"],[\"79479.80\",\"0.340\"],[\"79487.70\",\"1.005\"],[\"79491.70\",\"1.204\"],[\"79582.20\",\"0.001\"],[\"79582.80\",\"0.001\"],[\"79583.70\",\"0.779\"],[\"79584.30\",\"0.373\"],[\"79585.30\",\"0.002\"],[\"79585.60\",\"0.255\"],[\"79602.40\",\"0.058\"],[\"79602.90\",\"0.001\"],[\"79603.00\",\"0.077\"],[\"79607.10\",\"10.521\"]],\"a\":[[\"79609.20\",\"0.032\"],[\"79609.60\",\"0.058\"],[\"79611.20\",\"0.225\"],[\"79620.40\",\"0.000\"],[\"79621.40\",\"0.699\"],[\"79623.50\",\"0.004\"],[\"79624.60\",\"0.426\"],[\"79973.40\",\"1.713\"],[\"80403.30\",\"7.056\"],[\"80546.80\",\"2.458\"],[\"80602.30\",\"2.886\"],[\"80681.90\",\"1.545\"],[\"80712.60\",\"10.879\"],[\"81011.30\",\"0.001\"]],\"st\":1}}"}
{"receive_ns":1788563193465355000,"stream":"btcusdt@bookTicker","event_type":"bookTicker","event_time_ms":1788563193470,"raw_json":"{\"stream\":\"btcusdt@bookTicker\",\"data\":{\"e\":\"bookTicker\",\"u\":11478222504685,\"s\":\"BTCUSDT\",\"ps\":\"BTCUSDT\",\"b\":\"79607.10\",\"B\":\"10.540\",\"a\":\"79607.20\",\"A\":\"1.161\",\"T\":1788563193470,\"E\":1788563193470,\"st\":1}}"}
{"receive_ns":1788563193465540000,"stream":"btcusdt@bookTicker","event_type":"bookTicker","event_time_ms":1788563193471,"raw_json":"{\"stream\":\"btcusdt@bookTicker\",\"data\":{\"e\":\"bookTicker\",\"u\":11478222504727,\"s\":\"BTCUSDT\",\"ps\":\"BTCUSDT\",\"b\":\"79607.10\",\"B\":\"10.521\",\"a\":\"79607.20\",\"A\":\"1.161\",\"T\":1788563193470,\"E\":1788563193471,\"st\":1}}"}
{"receive_ns":1788563193465694000,"stream":"btcusdt@bookTicker","event_type":"bookTicker","event_time_ms":1788563193471,"raw_json":"{\"stream\":\"btcusdt@bookTicker\",\"data\":{\"e\":\"bookTicker\",\"u\":11478222504777,\"s\":\"BTCUSDT\",\"ps\":\"BTCUSDT\",\"b\":\"79607.10\",\"B\":\"10.523\",\"a\":\"79607.20\",\"A\":\"1.161\",\"T\":1788563193471,\"E\":1788563193471,\"st\":1}}"}
{"receive_ns":1788563193465862000,"stream":"btcusdt@bookTicker","event_type":"bookTicker","event_time_ms":1788563193471,"raw_json":"{\"stream\":\"btcusdt@bookTicker\",\"data\":{\"e\":\"bookTicker\",\"u\":11478222504789,\"s\":\"BTCUSDT\",\"ps\":\"BTCUSDT\",\"b\":\"79607.10\",\"B\":\"10.523\",\"a\":\"79607.20\",\"A\":\"1.601\",\"T\":1788563193471,\"E\":1788563193471,\"st\":1}}"}
{"receive_ns":1788563193466031000,"stream":"btcusdt@bookTicker","event_type":"bookTicker","event_time_ms":1788563193472,"raw_json":"{\"stream\":\"btcusdt@bookTicker\",\"data\":{\"e\":\"bookTicker\",\"u\":11478222504915,\"s\":\"BTCUSDT\",\"ps\":\"BTCUSDT\",\"b\":\"79607.10\",\"B\":\"10.523\",\"a\":\"79607.20\",\"A\":\"1.600\",\"T\":1788563193472,\"E\":1788563193472,\"st\":1}}"}
{"receive_ns":1788563193466200000,"stream":"btcusdt@bookTicker","event_type":"bookTicker","event_time_ms":1788563193473,"raw_json":"{\"stream\":\"btcusdt@bookTicker\",\"data\":{\"e\":\"bookTicker\",\"u\":11478222504963,\"s\":\"BTCUSDT\",\"ps\":\"BTCUSDT\",\"b\":\"79607.10\",\"B\":\"10.542\",\"a\":\"79607.20\",\"A\":\"1.600\",\"T\":1788563193472,\"E\":1788563193473,\"st\":1}}"}
{"receive_ns":1788563193466347000,"stream":"btcusdt@bookTicker","event_type":"bookTicker","event_time_ms":1788563193473,"raw_json":"{\"stream\":\"btcusdt@bookTicker\",\"data\":{\"e\":\"bookTicker\",\"u\":11478222504967,\"s\":\"BTCUSDT\",\"ps\":\"BTCUSDT\",\"b\":\"79607.10\",\"B\":\"10.550\",\"a\":\"79607.20\",\"A\":\"1.600\",\"T\":1788563193472,\"E\":1788563193473,\"st\":1}}"}
{"receive_ns":1788563193466514000,"stream":"btcusdt@bookTicker","event_type":"bookTicker","event_time_ms":1788563193473,"raw_json":"{\"stream\":\"btcusdt@bookTicker\",\"data\":{\"e\":\"bookTicker\",\"u\":11478222505030,\"s\":\"BTCUSDT\",\"ps\":\"BTCUSDT\",\"b\":\"79607.10\",\"B\":\"10.531\",\"a\":\"79607.20\",\"A\":\"1.600\",\"T\":1788563193473,\"E\":1788563193473,\"st\":1}}"}
{"receive_ns":1788563193466663000,"stream":"btcusdt@bookTicker","event_type":"bookTicker","event_time_ms":1788563193473,"raw_json":"{\"stream\":\"btcusdt@bookTicker\",\"data\":{\"e\":\"bookTicker\",\"u\":11478222505039,\"s\":\"BTCUSDT\",\"ps\":\"BTCUSDT\",\"b\":\"79607.10\",\"B\":\"10.523\",\"a\":\"79607.20\",\"A\":\"1.600\",\"T\":1788563193473,\"E\":1788563193473,\"st\":1}}"}
{"receive_ns":1788563193466826000,"stream":"btcusdt@bookTicker","event_type":"bookTicker","event_time_ms":1788563193474,"raw_json":"{\"stream\":\"btcusdt@bookTicker\",\"data\":{\"e\":\"bookTicker\",\"u\":11478222505078,\"s\":\"BTCUSDT\",\"ps\":\"BTCUSDT\",\"b\":\"79607.10\",\"B\":\"10.523\",\"a\":\"79607.20\",\"A\":\"1.601\",\"T\":1788563193474,\"E\":1788563193474,\"st\":1}}"}
{"receive_ns":1788563193466991000,"stream":"btcusdt@bookTicker","event_type":"bookTicker","event_time_ms":1788563193489,"raw_json":"{\"stream\":\"btcusdt@bookTicker\",\"data\":{\"e\":\"bookTicker\",\"u\":11478222505796,\"s\":\"BTCUSDT\",\"ps\":\"BTCUSDT\",\"b\":\"79607.10\",\"B\":\"10.238\",\"a\":\"79607.20\",\"A\":\"1.601\",\"T\":1788563193488,\"E\":1788563193489,\"st\":1}}"}
{"receive_ns":1788563193467156000,"stream":"btcusdt@bookTicker","event_type":"bookTicker","event_time_ms":1788563193490,"raw_json":"{\"stream\":\"btcusdt@bookTicker\",\"data\":{\"e\":\"bookTicker\",\"u\":11478222505900,\"s\":\"BTCUSDT\",\"ps\":\"BTCUSDT\",\"b\":\"79607.10\",\"B\":\"10.238\",\"a\":\"79607.20\",\"A\":\"1.161\",\"T\":1788563193490,\"E\":1788563193490,\"st\":1}}"}
{"receive_ns":1788563193467319000,"stream":"btcusdt@bookTicker","event_type":"bookTicker","event_time_ms":1788563193491,"raw_json":"{\"stream\":\"btcusdt@bookTicker\",\"data\":{\"e\":\"bookTicker\",\"u\":11478222505946,\"s\":\"BTCUSDT\",\"ps\":\"BTCUSDT\",\"b\":\"79607.10\",\"B\":\"10.531\",\"a\":\"79607.20\",\"A\":\"1.161\",\"T\":1788563193491,\"E\":1788563193491,\"st\":1}}"}
{"receive_ns":1788563193467462000,"stream":"btcusdt@bookTicker","event_type":"bookTicker","event_time_ms":1788563193491,"raw_json":"{\"stream\":\"btcusdt@bookTicker\",\"data\":{\"e\":\"bookTicker\",\"u\":11478222505962,\"s\":\"BTCUSDT\",\"ps\":\"BTCUSDT\",\"b\":\"79607.10\",\"B\":\"10.550\",\"a\":\"79607.20\",\"A\":\"1.161\",\"T\":1788563193491,\"E\":1788563193491,\"st\":1}}"}
{"receive_ns":1788563193467602000,"stream":"btcusdt@bookTicker","event_type":"bookTicker","event_time_ms":1788563193491,"raw_json":"{\"stream\":\"btcusdt@bookTicker\",\"data\":{\"e\":\"bookTicker\",\"u\":11478222505963,\"s\":\"BTCUSDT\",\"ps\":\"BTCUSDT\",\"b\":\"79607.10\",\"B\":\"10.558\",\"a\":\"79607.20\",\"A\":\"1.161\",\"T\":1788563193491,\"E\":1788563193491,\"st\":1}}"}
{"receive_ns":1788563193467762000,"stream":"btcusdt@bookTicker","event_type":"bookTicker","event_time_ms":1788563193492,"raw_json":"{\"stream\":\"btcusdt@bookTicker\",\"data\":{\"e\":\"bookTicker\",\"u\":11478222505998,\"s\":\"BTCUSDT\",\"ps\":\"BTCUSDT\",\"b\":\"79607.10\",\"B\":\"10.558\",\"a\":\"79607.20\",\"A\":\"1.160\",\"T\":1788563193491,\"E\":1788563193492,\"st\":1}}"}
{"receive_ns":1788563193467923000,"stream":"btcusdt@bookTicker","event_type":"bookTicker","event_time_ms":1788563193492,"raw_json":"{\"stream\":\"btcusdt@bookTicker\",\"data\":{\"e\":\"bookTicker\",\"u\":11478222506128,\"s\":\"BTCUSDT\",\"ps\":\"BTCUSDT\",\"b\":\"79607.10\",\"B\":\"10.550\",\"a\":\"79607.20\",\"A\":\"1.160\",\"T\":1788563193492,\"E\":1788563193492,\"st\":1}}"}
{"receive_ns":1788563193468066000,"stream":"btcusdt@bookTicker","event_type":"bookTicker","event_time_ms":1788563193492,"raw_json":"{\"stream\":\"btcusdt@bookTicker\",\"data\":{\"e\":\"bookTicker\",\"u\":11478222506131,\"s\":\"BTCUSDT\",\"ps\":\"BTCUSDT\",\"b\":\"79607.10\",\"B\":\"10.531\",\"a\":\"79607.20\",\"A\":\"1.160\",\"T\":1788563193492,\"E\":1788563193492,\"st\":1}}"}
{"receive_ns":1788563193468205000,"stream":"btcusdt@bookTicker","event_type":"bookTicker","event_time_ms":1788563193492,"raw_json":"{\"stream\":\"btcusdt@bookTicker\",\"data\":{\"e\":\"bookTicker\",\"u\":11478222506145,\"s\":\"BTCUSDT\",\"ps\":\"BTCUSDT\",\"b\":\"79607.10\",\"B\":\"10.531\",\"a\":\"79607.20\",\"A\":\"1.161\",\"T\":1788563193492,\"E\":1788563193492,\"st\":1}}"}
{"receive_ns":1788563193468368000,"stream":"btcusdt@bookTicker","event_type":"bookTicker","event_time_ms":1788563193493,"raw_json":"{\"stream\":\"btcusdt@bookTicker\",\"data\":{\"e\":\"bookTicker\",\"u\":11478222506150,\"s\":\"BTCUSDT\",\"ps\":\"BTCUSDT\",\"b\":\"79607.10\",\"B\":\"10.529\",\"a\":\"79607.20\",\"A\":\"1.161\",\"T\":1788563193492,\"E\":1788563193493,\"st\":1}}"}
{"receive_ns":1788563193468579000,"stream":"btcusdt@bookTicker","event_type":"bookTicker","event_time_ms":1788563193499,"raw_json":"{\"stream\":\"btcusdt@bookTicker\",\"data\":{\"e\":\"bookTicker\",\"u\":11478222506597,\"s\":\"BTCUSDT\",\"ps\":\"BTCUSDT\",\"b\":\"79607.10\",\"B\":\"10.304\",\"a\":\"79607.20\",\"A\":\"1.161\",\"T\":1788563193499,\"E\":1788563193499,\"st\":1}}"}
{"receive_ns":1788563193472855000,"stream":"btcusdt@bookTicker","event_type":"bookTicker","event_time_ms":1788563193501,"raw_json":"{\"stream\":\"btcusdt@bookTicker\",\"data\":{\"e\":\"bookTicker\",\"u\":11478222506780,\"s\":\"BTCUSDT\",\"ps\":\"BTCUSDT\",\"b\":\"79607.10\",\"B\":\"10.304\",\"a\":\"79607.20\",\"A\":\"1.601\",\"T\":1788563193501,\"E\":1788563193501,\"st\":1}}"}
{"receive_ns":1788563193473186000,"stream":"btcusdt@bookTicker","event_type":"bookTicker","event_time_ms":1788563193503,"raw_json":"{\"stream\":\"btcusdt@bookTicker\",\"data\":{\"e\":\"bookTicker\",\"u\":11478222506888,\"s\":\"BTCUSDT\",\"ps\":\"BTCUSDT\",\"b\":\"79607.10\",\"B\":\"10.323\",\"a\":\"79607.20\",\"A\":\"1.601\",\"T\":1788563193502,\"E\":1788563193503,\"st\":1}}"}
{"receive_ns":1788563193473370000,"stream":"btcusdt@bookTicker","event_type":"bookTicker","event_time_ms":1788563193503,"raw_json":"{\"stream\":\"btcusdt@bookTicker\",\"data\":{\"e\":\"bookTicker\",\"u\":11478222506893,\"s\":\"BTCUSDT\",\"ps\":\"BTCUSDT\",\"b\":\"79607.10\",\"B\":\"10.325\",\"a\":\"79607.20\",\"A\":\"1.601\",\"T\":1788563193502,\"E\":1788563193503,\"st\":1}}"}
{"receive_ns":1788563193473521000,"stream":"btcusdt@bookTicker","event_type":"bookTicker","event_time_ms":1788563193503,"raw_json":"{\"stream\":\"btcusdt@bookTicker\",\"data\":{\"e\":\"bookTicker\",\"u\":11478222506896,\"s\":\"BTCUSDT\",\"ps\":\"BTCUSDT\",\"b\":\"79607.10\",\"B\":\"10.325\",\"a\":\"79607.20\",\"A\":\"1.600\",\"T\":1788563193502,\"E\":1788563193503,\"st\":1}}"}
{"receive_ns":1788563193473666000,"stream":"btcusdt@bookTicker","event_type":"bookTicker","event_time_ms":1788563193503,"raw_json":"{\"stream\":\"btcusdt@bookTicker\",\"data\":{\"e\":\"bookTicker\",\"u\":11478222506901,\"s\":\"BTCUSDT\",\"ps\":\"BTCUSDT\",\"b\":\"79607.10\",\"B\":\"10.333\",\"a\":\"79607.20\",\"A\":\"1.600\",\"T\":1788563193502,\"E\":1788563193503,\"st\":1}}"}
{"receive_ns":1788563193473811000,"stream":"btcusdt@bookTicker","event_type":"bookTicker","event_time_ms":1788563193503,"raw_json":"{\"stream\":\"btcusdt@bookTicker\",\"data\":{\"e\":\"bookTicker\",\"u\":11478222506930,\"s\":\"BTCUSDT\",\"ps\":\"BTCUSDT\",\"b\":\"79607.10\",\"B\":\"10.333\",\"a\":\"79607.20\",\"A\":\"1.750\",\"T\":1788563193503,\"E\":1788563193503,\"st\":1}}"}
{"receive_ns":1788563193473988000,"stream":"btcusdt@bookTicker","event_type":"bookTicker","event_time_ms":1788563193503,"raw_json":"{\"stream\":\"btcusdt@bookTicker\",\"data\":{\"e\":\"bookTicker\",\"u\":11478222506957,\"s\":\"BTCUSDT\",\"ps\":\"BTCUSDT\",\"b\":\"79607.10\",\"B\":\"10.325\",\"a\":\"79607.20\",\"A\":\"1.750\",\"T\":1788563193503,\"E\":1788563193503,\"st\":1}}"}
{"receive_ns":1788563193474135000,"stream":"btcusdt@bookTicker","event_type":"bookTicker","event_time_ms":1788563193503,"raw_json":"{\"stream\":\"btcusdt@bookTicker\",\"data\":{\"e\":\"bookTicker\",\"u\":11478222506958,\"s\":\"BTCUSDT\",\"ps\":\"BTCUSDT\",\"b\":\"79607.10\",\"B\":\"10.306\",\"a\":\"79607.20\",\"A\":\"1.750\",\"T\":1788563193503,\"E\":1788563193503,\"st\":1}}"}
{"receive_ns":1788563193474301000,"stream":"btcusdt@bookTicker","event_type":"bookTicker","event_time_ms":1788563193504,"raw_json":"{\"stream\":\"btcusdt@bookTicker\",\"data\":{\"e\":\"bookTicker\",\"u\":11478222507034,\"s\":\"BTCUSDT\",\"ps\":\"BTCUSDT\",\"b\":\"79607.10\",\"B\":\"10.306\",\"a\":\"79607.20\",\"A\":\"1.751\",\"T\":1788563193504,\"E\":1788563193504,\"st\":1}}"}
{"receive_ns":1788563193509681000,"stream":"btcusdt@bookTicker","event_type":"bookTicker","event_time_ms":1788563193543,"raw_json":"{\"stream\":\"btcusdt@bookTicker\",\"data\":{\"e\":\"bookTicker\",\"u\":11478222510168,\"s\":\"BTCUSDT\",\"ps\":\"BTCUSDT\",\"b\":\"79607.10\",\"B\":\"10.121\",\"a\":\"79607.20\",\"A\":\"1.751\",\"T\":1788563193543,\"E\":1788563193543,\"st\":1}}"}
{"receive_ns":1788563193509948000,"stream":"btcusdt@bookTicker","event_type":"bookTicker","event_time_ms":1788563193546,"raw_json":"{\"stream\":\"btcusdt@bookTicker\",\"data\":{\"e\":\"bookTicker\",\"u\":11478222510401,\"s\":\"BTCUSDT\",\"ps\":\"BTCUSDT\",\"b\":\"79607.10\",\"B\":\"10.308\",\"a\":\"79607.20\",\"A\":\"1.751\",\"T\":1788563193546,\"E\":1788563193546,\"st\":1}}"}
{"receive_ns":1788563193530961000,"stream":"btcusdt@depth@100ms","event_type":"depthUpdate","event_time_ms":1788563193565,"raw_json":"{\"stream\":\"btcusdt@depth@100ms\",\"data\":{\"e\":\"depthUpdate\",\"E\":1788563193565,\"T\":1788563193562,\"s\":\"BTCUSDT\",\"ps\":\"BTCUSDT\",\"U\":11478222504342,\"u\":11478222511251,\"pu\":11478222504104,\"b\":[[\"29107.10\",\"1.127\"],[\"29207.10\",\"0.973\"],[\"71646.30\",\"0.002\"],[\"75622.40\",\"0.004\"],[\"76422.80\",\"0.002\"],[\"78493.80\",\"2.401\"],[\"78603.10\",\"7.278\"],[\"78605.30\",\"0.000\"],[\"78607.70\",\"1.273\"],[\"78811.00\",\"2.225\"],[\"79209.00\",\"0.001\"],[\"79209.10\",\"0.529\"],[\"79236.90\",\"0.247\"],[\"79434.00\",\"0.678\"],[\"79453.90\",\"0.455\"],[\"79478.40\",\"0.125\"],[\"79491.70\",\"1.279\"],[\"79575.40\",\"0.008\"],[\"79576.10\",\"0.533\"],[\"79582.20\",\"0.440\"],[\"79582.90\",\"0.373\"],[\"79583.70\",\"0.340\"],[\"79584.30\",\"0.000\"],[\"79599.70\",\"0.000\"],[\"79599.80\",\"0.000\"],[\"79601.10\",\"0.000\"],[\"79602.40\",\"0.058\"],[\"79603.00\",\"0.077\"],[\"79604.20\",\"0.000\"],[\"79607.10\",\"10.308\"]],\"a\":[[\"79607.20\",\"1.751\"],[\"79607.30\",\"0.003\"],[\"79608.60\",\"0.026\"],[\"79608.70\",\"0.000\"],[\"79608.80\",\"0.027\"],[\"79608.90\",\"0.026\"],[\"79609.00\",\"0.079\"],[\"79609.20\",\"0.534\"],[\"79609.30\",\"0.001\"],[\"79609.40\",\"0.032\"],[\"79609.70\",\"0.000\"],[\"79610.30\",\"0.716\"],[\"79611.20\",\"0.090\"],[\"79611.30\",\"0.341\"],[\"79611.40\",\"1.296\"],[\"79611.50\",\"0.570\"],[\"79612.40\",\"0.001\"],[\"79614.70\",\"0.254\"],[\"79615.20\",\"0.073\"],[\"79615.30\",\"0.692\"],[\"79615.70\",\"0.002\"],[\"79619.00\",\"0.633\"],[\"79621.40\",\"0.260\"],[\"79652.70\",\"2.158\"],[\"79653.70\",\"0.008\"],[\"79658.20\",\"0.003\"],[\"79973.40\",\"1.494\"],[\"80005.30\",\"0.002\"],[\"80403.30\",\"7.056\"],[\"80681.90\",\"2.288\"]],\"st\":1}}"}
{"receive_ns":1788563193628827000,"stream":"btcusdt@bookTicker","event_type":"bookTicker","event_time_ms":1788563193665,"raw_json":"{\"stream\":\"btcusdt@bookTicker\",\"data\":{\"e\":\"bookTicker\",\"u\":11478222516548,\"s\":\"BTCUSDT\",\"ps\":\"BTCUSDT\",\"b\":\"79607.10\",\"B\":\"10.327\",\"a\":\"79607.20\",\"A\":\"1.751\",\"T\":1788563193665,\"E\":1788563193665,\"st\":1}}"}
{"receive_ns":1788563193630131000,"stream":"btcusdt@bookTicker","event_type":"bookTicker","event_time_ms":1788563193666,"raw_json":"{\"stream\":\"btcusdt@bookTicker\",\"data\":{\"e\":\"bookTicker\",\"u\":11478222516581,\"s\":\"BTCUSDT\",\"ps\":\"BTCUSDT\",\"b\":\"79607.10\",\"B\":\"10.308\",\"a\":\"79607.20\",\"A\":\"1.751\",\"T\":1788563193666,\"E\":1788563193666,\"st\":1}}"}
{"receive_ns":1788563193630603000,"stream":"btcusdt@depth@100ms","event_type":"depthUpdate","event_time_ms":1788563193667,"raw_json":"{\"stream\":\"btcusdt@depth@100ms\",\"data\":{\"e\":\"depthUpdate\",\"E\":1788563193667,\"T\":1788563193666,\"s\":\"BTCUSDT\",\"ps\":\"BTCUSDT\",\"U\":11478222511529,\"u\":11478222516581,\"pu\":11478222511251,\"b\":[[\"1000.00\",\"24.604\"],[\"29107.10\",\"1.309\"],[\"29207.10\",\"0.791\"],[\"71646.30\",\"0.002\"],[\"76422.80\",\"0.000\"],[\"78109.60\",\"1.278\"],[\"78811.00\",\"2.225\"],[\"79434.00\",\"0.678\"],[\"79481.40\",\"0.007\"],[\"79487.70\",\"1.005\"],[\"79491.70\",\"0.075\"],[\"79520.30\",\"0.118\"],[\"79523.90\",\"1.190\"],[\"79548.10\",\"0.000\"],[\"79551.10\",\"0.631\"],[\"79568.00\",\"0.008\"],[\"79607.10\",\"10.308\"]],\"a\":[[\"79608.50\",\"0.026\"],[\"79610.40\",\"1.346\"],[\"79611.00\",\"0.003\"],[\"79639.90\",\"0.011\"],[\"79659.80\",\"0.206\"],[\"79669.40\",\"0.000\"],[\"79686.30\",\"0.742\"],[\"79687.70\",\"0.000\"],[\"79768.40\",\"0.993\"],[\"79973.40\",\"1.150\"],[\"80403.30\",\"7.056\"],[\"81409.20\",\"0.000\"]],\"st\":1}}"}
{"receive_ns":1788563193731822000,"stream":"btcusdt@depth@100ms","event_type":"depthUpdate","event_time_ms":1788563193769,"raw_json":"{\"stream\":\"btcusdt@depth@100ms\",\"data\":{\"e\":\"depthUpdate\",\"E\":1788563193769,\"T\":1788563193765,\"s\":\"BTCUSDT\",\"ps\":\"BTCUSDT\",\"U\":11478222516644,\"u\":11478222521501,\"pu\":11478222516581,\"b\":[[\"1000.00\",\"24.604\"],[\"29107.10\",\"1.484\"],[\"29207.10\",\"0.616\"],[\"71646.30\",\"0.002\"],[\"76422.80\",\"0.002\"],[\"78811.00\",\"3.492\"],[\"79209.10\",\"0.519\"],[\"79236.90\",\"0.247\"],[\"79434.00\",\"1.004\"],[\"79440.20\",\"0.003\"],[\"79443.60\",\"0.613\"],[\"79453.90\",\"0.204\"],[\"79479.60\",\"0.149\"],[\"79483.60\",\"2.164\"],[\"79491.70\",\"1.204\"],[\"79534.00\",\"0.001\"],[\"79534.10\",\"1.183\"],[\"79536.70\",\"23.405\"],[\"79547.60\",\"0.000\"],[\"79583.40\",\"1.875\"],[\"79592.90\",\"0.511\"]],\"a\":[[\"79609.20\",\"0.718\"],[\"79609.60\",\"0.043\"],[\"79611.20\",\"0.090\"],[\"79613.30\",\"0.003\"],[\"79619.00\",\"0.194\"],[\"79620.40\",\"0.439\"],[\"79623.30\",\"0.045\"],[\"79668.00\",\"0.084\"],[\"79674.20\",\"0.007\"],[\"79676.90\",\"0.207\"],[\"79682.30\",\"24.421\"],[\"79721.90\",\"0.002\"],[\"79728.60\",\"0.000\"],[\"79729.40\",\"0.697\"],[\"79729.50\",\"0.000\"],[\"79763.30\",\"0.008\"],[\"79768.00\",\"0.064\"],[\"79973.40\",\"1.913\"],[\"80244.10\",\"0.747\"],[\"80403.30\",\"7.055\"],[\"80593.20\",\"3.175\"]],\"st\":1}}"}
{"receive_ns":1788563193797991000,"stream":"btcusdt@bookTicker","event_type":"bookTicker","event_time_ms":1788563193833,"raw_json":"{\"stream\":\"btcusdt@bookTicker\",\"data\":{\"e\":\"bookTicker\",\"u\":11478222524324,\"s\":\"BTCUSDT\",\"ps\":\"BTCUSDT\",\"b\":\"79607.10\",\"B\":\"10.327\",\"a\":\"79607.20\",\"A\":\"1.751\",\"T\":1788563193833,\"E\":1788563193833,\"st\":1}}"}
{"receive_ns":1788563193798620000,"stream":"btcusdt@bookTicker","event_type":"bookTicker","event_time_ms":1788563193834,"raw_json":"{\"stream\":\"btcusdt@bookTicker\",\"data\":{\"e\":\"bookTicker\",\"u\":11478222524374,\"s\":\"BTCUSDT\",\"ps\":\"BTCUSDT\",\"b\":\"79607.10\",\"B\":\"10.308\",\"a\":\"79607.20\",\"A\":\"1.751\",\"T\":1788563193833,\"E\":1788563193834,\"st\":1}}"}
{"receive_ns":1788563193837757000,"stream":"btcusdt@depth@100ms","event_type":"depthUpdate","event_time_ms":1788563193871,"raw_json":"{\"stream\":\"btcusdt@depth@100ms\",\"data\":{\"e\":\"depthUpdate\",\"E\":1788563193871,\"T\":1788563193869,\"s\":\"BTCUSDT\",\"ps\":\"BTCUSDT\",\"U\":11478222521701,\"u\":11478222525781,\"pu\":11478222521501,\"b\":[[\"29107.10\",\"1.666\"],[\"29207.10\",\"0.434\"],[\"71646.30\",\"0.002\"],[\"75622.40\",\"0.002\"],[\"76422.80\",\"0.000\"],[\"78015.00\",\"0.134\"],[\"78811.00\",\"3.492\"],[\"79392.50\",\"5.448\"],[\"79434.00\",\"1.004\"],[\"79440.30\",\"2.683\"],[\"79479.70\",\"1.156\"],[\"79484.00\",\"10.001\"],[\"79487.70\",\"1.005\"],[\"79523.80\",\"6.300\"],[\"79534.00\",\"23.532\"],[\"79536.70\",\"0.000\"],[\"79551.60\",\"3.572\"],[\"79571.50\",\"0.605\"],[\"79607.10\",\"10.308\"]],\"a\":[[\"79608.10\",\"0.027\"],[\"79610.90\",\"0.001\"],[\"79643.50\",\"0.417\"],[\"79663.40\",\"3.501\"],[\"79676.90\",\"24.628\"],[\"79682.30\",\"0.000\"],[\"79691.30\",\"6.136\"],[\"79728.60\",\"0.340\"],[\"79729.40\",\"0.691\"],[\"79742.40\",\"0.006\"],[\"79763.30\",\"0.002\"],[\"79768.00\",\"1.921\"],[\"79812.00\",\"0.607\"],[\"79815.80\",\"3.128\"],[\"79973.40\",\"1.913\"],[\"80403.30\",\"7.055\"],[\"83577.10\",\"0.023\"]],\"st\":1}}"}
{"receive_ns":1788563193890175000,"stream":"btcusdt@bookTicker","event_type":"bookTicker","event_time_ms":1788563193925,"raw_json":"{\"stream\":\"btcusdt@bookTicker\",\"data\":{\"e\":\"bookTicker\",\"u\":11478222528654,\"s\":\"BTCUSDT\",\"ps\":\"BTCUSDT\",\"b\":\"79607.10\",\"B\":\"10.327\",\"a\":\"79607.20\",\"A\":\"1.751\",\"T\":1788563193925,\"E\":1788563193925,\"st\":1}}"}
{"receive_ns":1788563193890481000,"stream":"btcusdt@bookTicker","event_type":"bookTicker","event_time_ms":1788563193925,"raw_json":"{\"stream\":\"btcusdt@bookTicker\",\"data\":{\"e\":\"bookTicker\",\"u\":11478222528689,\"s\":\"BTCUSDT\",\"ps\":\"BTCUSDT\",\"b\":\"79607.10\",\"B\":\"10.308\",\"a\":\"79607.20\",\"A\":\"1.751\",\"T\":1788563193925,\"E\":1788563193925,\"st\":1}}"}
{"receive_ns":1788563193933919000,"stream":"btcusdt@bookTicker","event_type":"bookTicker","event_time_ms":1788563193968,"raw_json":"{\"stream\":\"btcusdt@bookTicker\",\"data\":{\"e\":\"bookTicker\",\"u\":11478222531109,\"s\":\"BTCUSDT\",\"ps\":\"BTCUSDT\",\"b\":\"79607.10\",\"B\":\"10.305\",\"a\":\"79607.20\",\"A\":\"1.751\",\"T\":1788563193968,\"E\":1788563193968,\"st\":1}}"}
{"receive_ns":1788563193934189000,"stream":"btcusdt@trade","event_type":"trade","event_time_ms":1788563193968,"raw_json":"{\"stream\":\"btcusdt@trade\",\"data\":{\"e\":\"trade\",\"E\":1788563193968,\"T\":1788563193968,\"s\":\"BTCUSDT\",\"t\":8054082670,\"p\":\"79607.10\",\"q\":\"0.003\",\"X\":\"MARKET\",\"m\":true,\"st\":1}}"}
{"receive_ns":1788563193934451000,"stream":"btcusdt@bookTicker","event_type":"bookTicker","event_time_ms":1788563193969,"raw_json":"{\"stream\":\"btcusdt@bookTicker\",\"data\":{\"e\":\"bookTicker\",\"u\":11478222531207,\"s\":\"BTCUSDT\",\"ps\":\"BTCUSDT\",\"b\":\"79607.10\",\"B\":\"10.324\",\"a\":\"79607.20\",\"A\":\"1.751\",\"T\":1788563193969,\"E\":1788563193969,\"st\":1}}"}
{"receive_ns":1788563193934666000,"stream":"btcusdt@bookTicker","event_type":"bookTicker","event_time_ms":1788563193969,"raw_json":"{\"stream\":\"btcusdt@bookTicker\",\"data\":{\"e\":\"bookTicker\",\"u\":11478222531224,\"s\":\"BTCUSDT\",\"ps\":\"BTCUSDT\",\"b\":\"79607.10\",\"B\":\"10.332\",\"a\":\"79607.20\",\"A\":\"1.751\",\"T\":1788563193969,\"E\":1788563193969,\"st\":1}}"}
{"receive_ns":1788563193934885000,"stream":"btcusdt@bookTicker","event_type":"bookTicker","event_time_ms":1788563193970,"raw_json":"{\"stream\":\"btcusdt@bookTicker\",\"data\":{\"e\":\"bookTicker\",\"u\":11478222531313,\"s\":\"BTCUSDT\",\"ps\":\"BTCUSDT\",\"b\":\"79607.10\",\"B\":\"10.313\",\"a\":\"79607.20\",\"A\":\"1.751\",\"T\":1788563193970,\"E\":1788563193970,\"st\":1}}"}
{"receive_ns":1788563193935043000,"stream":"btcusdt@bookTicker","event_type":"bookTicker","event_time_ms":1788563193970,"raw_json":"{\"stream\":\"btcusdt@bookTicker\",\"data\":{\"e\":\"bookTicker\",\"u\":11478222531318,\"s\":\"BTCUSDT\",\"ps\":\"BTCUSDT\",\"b\":\"79607.10\",\"B\":\"10.305\",\"a\":\"79607.20\",\"A\":\"1.751\",\"T\":1788563193970,\"E\":1788563193970,\"st\":1}}"}
{"receive_ns":1788563193938467000,"stream":"btcusdt@depth@100ms","event_type":"depthUpdate","event_time_ms":1788563193973,"raw_json":"{\"stream\":\"btcusdt@depth@100ms\",\"data\":{\"e\":\"depthUpdate\",\"E\":1788563193973,\"T\":1788563193972,\"s\":\"BTCUSDT\",\"ps\":\"BTCUSDT\",\"U\":11478222525853,\"u\":11478222531540,\"pu\":11478222525781,\"b\":[[\"1000.00\",\"24.604\"],[\"29107.10\",\"1.785\"],[\"29207.10\",\"0.287\"],[\"29507.10\",\"0.028\"],[\"63685.70\",\"0.001\"],[\"71646.30\",\"0.002\"],[\"78404.10\",\"8.197\"],[\"78557.70\",\"0.667\"],[\"78811.00\",\"3.492\"],[\"79209.10\",\"0.519\"],[\"79236.90\",\"0.247\"],[\"79434.00\",\"0.929\"],[\"79487.70\",\"2.209\"],[\"79491.70\",\"0.075\"],[\"79534.00\",\"0.001\"],[\"79535.40\",\"0.002\"],[\"79536.70\",\"23.531\"],[\"79549.40\",\"0.000\"],[\"79563.30\",\"0.071\"],[\"79579.20\",\"0.003\"],[\"79581.20\",\"0.000\"],[\"79592.70\",\"0.077\"],[\"79603.00\",\"0.001\"],[\"79604.90\",\"0.002\"],[\"79605.10\",\"0.000\"],[\"79606.80\",\"0.004\"],[\"79607.00\",\"0.007\"],[\"79607.10\",\"10.305\"]],\"a\":[[\"79607.40\",\"0.128\"],[\"79607.80\",\"0.027\"],[\"79609.20\",\"0.609\"],[\"79610.60\",\"0.345\"],[\"79610.80\",\"0.002\"],[\"79611.20\",\"0.199\"],[\"79614.70\",\"0.252\"],[\"79615.30\",\"0.694\"],[\"79617.00\",\"0.068\"],[\"79617.50\",\"0.732\"],[\"79620.50\",\"2.063\"],[\"79622.60\",\"0.000\"],[\"79624.90\",\"0.002\"],[\"79625.70\",\"0.453\"],[\"79626.80\",\"0.003\"],[\"79663.00\",\"0.002\"],[\"79729.50\",\"10.000\"],[\"79792.60\",\"0.000\"],[\"79792.70\",\"0.000\"],[\"79803.80\",\"7.532\"],[\"79973.40\",\"1.913\"],[\"80403.30\",\"7.055\"]],\"st\":1}}"}
{"receive_ns":1788563193943216000,"stream":"btcusdt@bookTicker","event_type":"bookTicker","event_time_ms":1788563193978,"raw_json":"{\"stream\":\"btcusdt@bookTicker\",\"data\":{\"e\":\"bookTicker\",\"u\":11478222531764,\"s\":\"BTCUSDT\",\"ps\":\"BTCUSDT\",\"b\":\"79607.10\",\"B\":\"10.324\",\"a\":\"79607.20\",\"A\":\"1.751\",\"T\":1788563193978,\"E\":1788563193978,\"st\":1}}"}
{"receive_ns":1788563193943410000,"stream":"btcusdt@bookTicker","event_type":"bookTicker","event_time_ms":1788563193978,"raw_json":"{\"stream\":\"btcusdt@bookTicker\",\"data\":{\"e\":\"bookTicker\",\"u\":11478222531765,\"s\":\"BTCUSDT\",\"ps\":\"BTCUSDT\",\"b\":\"79607.10\",\"B\":\"10.324\",\"a\":\"79607.20\",\"A\":\"1.777\",\"T\":1788563193978,\"E\":1788563193978,\"st\":1}}"}
{"receive_ns":1788563193943590000,"stream":"btcusdt@bookTicker","event_type":"bookTicker","event_time_ms":1788563193978,"raw_json":"{\"stream\":\"btcusdt@bookTicker\",\"data\":{\"e\":\"bookTicker\",\"u\":11478222531795,\"s\":\"BTCUSDT\",\"ps\":\"BTCUSDT\",\"b\":\"79607.10\",\"B\":\"10.305\",\"a\":\"79607.20\",\"A\":\"1.777\",\"T\":1788563193978,\"E\":1788563193978,\"st\":1}}"}
{"receive_ns":1788563193943763000,"stream":"btcusdt@bookTicker","event_type":"bookTicker","event_time_ms":1788563193979,"raw_json":"{\"stream\":\"btcusdt@bookTicker\",\"data\":{\"e\":\"bookTicker\",\"u\":11478222531817,\"s\":\"BTCUSDT\",\"ps\":\"BTCUSDT\",\"b\":\"79607.10\",\"B\":\"10.305\",\"a\":\"79607.20\",\"A\":\"1.776\",\"T\":1788563193979,\"E\":1788563193979,\"st\":1}}"}
{"receive_ns":1788563193943912000,"stream":"btcusdt@bookTicker","event_type":"bookTicker","event_time_ms":1788563193979,"raw_json":"{\"stream\":\"btcusdt@bookTicker\",\"data\":{\"e\":\"bookTicker\",\"u\":11478222531861,\"s\":\"BTCUSDT\",\"ps\":\"BTCUSDT\",\"b\":\"79607.10\",\"B\":\"10.313\",\"a\":\"79607.20\",\"A\":\"1.776\",\"T\":1788563193979,\"E\":1788563193979,\"st\":1}}"}
{"receive_ns":1788563193944112000,"stream":"btcusdt@bookTicker","event_type":"bookTicker","event_time_ms":1788563193979,"raw_json":"{\"stream\":\"btcusdt@bookTicker\",\"data\":{\"e\":\"bookTicker\",\"u\":11478222531866,\"s\":\"BTCUSDT\",\"ps\":\"BTCUSDT\",\"b\":\"79607.10\",\"B\":\"10.332\",\"a\":\"79607.20\",\"A\":\"1.776\",\"T\":1788563193979,\"E\":1788563193979,\"st\":1}}"}
{"receive_ns":1788563193944325000,"stream":"btcusdt@bookTicker","event_type":"bookTicker","event_time_ms":1788563193980,"raw_json":"{\"stream\":\"btcusdt@bookTicker\",\"data\":{\"e\":\"bookTicker\",\"u\":11478222531892,\"s\":\"BTCUSDT\",\"ps\":\"BTCUSDT\",\"b\":\"79607.10\",\"B\":\"10.324\",\"a\":\"79607.20\",\"A\":\"1.776\",\"T\":1788563193980,\"E\":1788563193980,\"st\":1}}"}
{"receive_ns":1788563193944478000,"stream":"btcusdt@bookTicker","event_type":"bookTicker","event_time_ms":1788563193980,"raw_json":"{\"stream\":\"btcusdt@bookTicker\",\"data\":{\"e\":\"bookTicker\",\"u\":11478222531895,\"s\":\"BTCUSDT\",\"ps\":\"BTCUSDT\",\"b\":\"79607.10\",\"B\":\"10.305\",\"a\":\"79607.20\",\"A\":\"1.776\",\"T\":1788563193980,\"E\":1788563193980,\"st\":1}}"}
{"receive_ns":1788563193944670000,"stream":"btcusdt@bookTicker","event_type":"bookTicker","event_time_ms":1788563193980,"raw_json":"{\"stream\":\"btcusdt@bookTicker\",\"data\":{\"e\":\"bookTicker\",\"u\":11478222531933,\"s\":\"BTCUSDT\",\"ps\":\"BTCUSDT\",\"b\":\"79607.10\",\"B\":\"10.305\",\"a\":\"79607.20\",\"A\":\"1.777\",\"T\":1788563193980,\"E\":1788563193980,\"st\":1}}"}
{"receive_ns":1788563193961766000,"stream":"btcusdt@bookTicker","event_type":"bookTicker","event_time_ms":1788563193996,"raw_json":"{\"stream\":\"btcusdt@bookTicker\",\"data\":{\"e\":\"bookTicker\",\"u\":11478222532769,\"s\":\"BTCUSDT\",\"ps\":\"BTCUSDT\",\"b\":\"79607.10\",\"B\":\"10.324\",\"a\":\"79607.20\",\"A\":\"1.777\",\"T\":1788563193996,\"E\":1788563193996,\"st\":1}}"}
{"receive_ns":1788563193962038000,"stream":"btcusdt@bookTicker","event_type":"bookTicker","event_time_ms":1788563193996,"raw_json":"{\"stream\":\"btcusdt@bookTicker\",\"data\":{\"e\":\"bookTicker\",\"u\":11478222532779,\"s\":\"BTCUSDT\",\"ps\":\"BTCUSDT\",\"b\":\"79607.10\",\"B\":\"10.332\",\"a\":\"79607.20\",\"A\":\"1.777\",\"T\":1788563193996,\"E\":1788563193996,\"st\":1}}"}
{"receive_ns":1788563193962233000,"stream":"btcusdt@bookTicker","event_type":"bookTicker","event_time_ms":1788563193997,"raw_json":"{\"stream\":\"btcusdt@bookTicker\",\"data\":{\"e\":\"bookTicker\",\"u\":11478222532840,\"s\":\"BTCUSDT\",\"ps\":\"BTCUSDT\",\"b\":\"79607.10\",\"B\":\"10.313\",\"a\":\"79607.20\",\"A\":\"1.777\",\"T\":1788563193996,\"E\":1788563193997,\"st\":1}}"}
{"receive_ns":1788563193962450000,"stream":"btcusdt@bookTicker","event_type":"bookTicker","event_time_ms":1788563193997,"raw_json":"{\"stream\":\"btcusdt@bookTicker\",\"data\":{\"e\":\"bookTicker\",\"u\":11478222532849,\"s\":\"BTCUSDT\",\"ps\":\"BTCUSDT\",\"b\":\"79607.10\",\"B\":\"10.305\",\"a\":\"79607.20\",\"A\":\"1.777\",\"T\":1788563193997,\"E\":1788563193997,\"st\":1}}"}
{"receive_ns":1788563194015083000,"stream":"btcusdt@bookTicker","event_type":"bookTicker","event_time_ms":1788563194049,"raw_json":"{\"stream\":\"btcusdt@bookTicker\",\"data\":{\"e\":\"bookTicker\",\"u\":11478222536328,\"s\":\"BTCUSDT\",\"ps\":\"BTCUSDT\",\"b\":\"79607.10\",\"B\":\"10.324\",\"a\":\"79607.20\",\"A\":\"1.777\",\"T\":1788563194049,\"E\":1788563194049,\"st\":1}}"}
{"receive_ns":1788563194015327000,"stream":"btcusdt@bookTicker","event_type":"bookTicker","event_time_ms":1788563194050,"raw_json":"{\"stream\":\"btcusdt@bookTicker\",\"data\":{\"e\":\"bookTicker\",\"u\":11478222536353,\"s\":\"BTCUSDT\",\"ps\":\"BTCUSDT\",\"b\":\"79607.10\",\"B\":\"10.332\",\"a\":\"79607.20\",\"A\":\"1.777\",\"T\":1788563194049,\"E\":1788563194050,\"st\":1}}"}
{"receive_ns":1788563194015553000,"stream":"btcusdt@bookTicker","event_type":"bookTicker","event_time_ms":1788563194050,"raw_json":"{\"stream\":\"btcusdt@bookTicker\",\"data\":{\"e\":\"bookTicker\",\"u\":11478222536426,\"s\":\"BTCUSDT\",\"ps\":\"BTCUSDT\",\"b\":\"79607.10\",\"B\":\"10.313\",\"a\":\"79607.20\",\"A\":\"1.777\",\"T\":1788563194050,\"E\":1788563194050,\"st\":1}}"}
{"receive_ns":1788563194015714000,"stream":"btcusdt@bookTicker","event_type":"bookTicker","event_time_ms":1788563194050,"raw_json":"{\"stream\":\"btcusdt@bookTicker\",\"data\":{\"e\":\"bookTicker\",\"u\":11478222536429,\"s\":\"BTCUSDT\",\"ps\":\"BTCUSDT\",\"b\":\"79607.10\",\"B\":\"10.305\",\"a\":\"79607.20\",\"A\":\"1.777\",\"T\":1788563194050,\"E\":1788563194050,\"st\":1}}"}
{"receive_ns":1788563194041344000,"stream":"btcusdt@depth@100ms","event_type":"depthUpdate","event_time_ms":1788563194075,"raw_json":"{\"stream\":\"btcusdt@depth@100ms\",\"data\":{\"e\":\"depthUpdate\",\"E\":1788563194075,\"T\":1788563194074,\"s\":\"BTCUSDT\",\"ps\":\"BTCUSDT\",\"U\":11478222531576,\"u\":11478222537951,\"pu\":11478222531540,\"b\":[[\"1000.00\",\"24.604\"],[\"29107.10\",\"1.841\"],[\"29207.10\",\"0.168\"],[\"29507.10\",\"0.091\"],[\"71646.30\",\"0.002\"],[\"76422.80\",\"0.002\"],[\"78015.00\",\"0.137\"],[\"78811.00\",\"3.492\"],[\"79209.10\",\"0.519\"],[\"79534.00\",\"23.532\"],[\"79536.70\",\"0.000\"],[\"79562.30\",\"0.806\"],[\"79575.30\",\"0.001\"],[\"79576.20\",\"0.453\"],[\"79577.40\",\"0.000\"],[\"79591.60\",\"0.145\"],[\"79592.80\",\"0.003\"],[\"79601.90\",\"0.106\"],[\"79604.30\",\"0.027\"],[\"79604.40\",\"0.280\"],[\"79606.30\",\"0.000\"],[\"79606.40\",\"0.108\"],[\"79606.50\",\"0.026\"],[\"79607.10\",\"10.305\"]],\"a\":[[\"79607.20\",\"1.777\"],[\"79610.50\",\"0.002\"],[\"79625.70\",\"0.001\"],[\"79627.10\",\"0.453\"],[\"79729.40\",\"0.697\"],[\"79742.40\",\"0.000\"],[\"80199.40\",\"1.869\"],[\"80403.30\",\"7.055\"],[\"80967.30\",\"2.094\"],[\"81199.30\",\"0.015\"]],\"st\":1}}"}
{"receive_ns":1788563194053187000,"stream":"btcusdt@bookTicker","event_type":"bookTicker","event_time_ms":1788563194087,"raw_json":"{\"stream\":\"btcusdt@bookTicker\",\"data\":{\"e\":\"bookTicker\",\"u\":11478222538841,\"s\":\"BTCUSDT\",\"ps\":\"BTCUSDT\",\"b\":\"79607.10\",\"B\":\"10.305\",\"a\":\"79607.20\",\"A\":\"1.751\",\"T\":1788563194087,\"E\":1788563194087,\"st\":1}}"}
{"receive_ns":1788563194095089000,"stream":"btcusdt@bookTicker","event_type":"bookTicker","event_time_ms":1788563194129,"raw_json":"{\"stream\":\"btcusdt@bookTicker\",\"data\":{\"e\":\"bookTicker\",\"u\":11478222541436,\"s\":\"BTCUSDT\",\"ps\":\"BTCUSDT\",\"b\":\"79607.10\",\"B\":\"10.306\",\"a\":\"79607.20\",\"A\":\"1.751\",\"T\":1788563194129,\"E\":1788563194129,\"st\":1}}"}
{"receive_ns":1788563194142199000,"stream":"btcusdt@depth@100ms","event_type":"depthUpdate","event_time_ms":1788563194177,"raw_json":"{\"stream\":\"btcusdt@depth@100ms\",\"data\":{\"e\":\"depthUpdate\",\"E\":1788563194177,\"T\":1788563194175,\"s\":\"BTCUSDT\",\"ps\":\"BTCUSDT\",\"U\":11478222538039,\"u\":11478222543887,\"pu\":11478222537951,\"b\":[[\"29107.10\",\"1.904\"],[\"29207.10\",\"0.049\"],[\"29507.10\",\"0.147\"],[\"71646.30\",\"0.002\"],[\"76422.80\",\"0.000\"],[\"78811.00\",\"3.492\"],[\"78870.10\",\"0.005\"],[\"79434.00\",\"0.929\"],[\"79487.70\",\"1.005\"],[\"79491.70\",\"1.279\"],[\"79523.90\",\"2.090\"],[\"79534.00\",\"0.001\"],[\"79535.00\",\"0.694\"],[\"79536.70\",\"23.531\"],[\"79551.10\",\"0.042\"],[\"79551.70\",\"1.123\"],[\"79601.20\",\"0.004\"],[\"79602.10\",\"0.076\"],[\"79607.00\",\"0.033\"],[\"79607.10\",\"10.306\"]],\"a\":[[\"79607.20\",\"1.751\"],[\"79607.40\",\"0.102\"],[\"79607.80\",\"0.001\"],[\"79608.10\",\"0.001\"],[\"79608.20\",\"0.029\"],[\"79609.10\",\"0.026\"],[\"79609.20\",\"0.635\"],[\"79611.20\",\"0.000\"],[\"79652.60\",\"1.281\"],[\"79654.60\",\"0.000\"],[\"79674.90\",\"0.410\"],[\"79676.80\",\"5.560\"],[\"79682.90\",\"0.001\"],[\"79688.50\",\"1.939\"],[\"79702.80\",\"0.001\"],[\"79973.40\",\"1.913\"],[\"80005.30\",\"0.001\"],[\"80239.20\",\"2.239\"],[\"80344.30\",\"0.000\"],[\"80403.30\",\"7.055\"],[\"80715.20\",\"0.002\"]],\"st\":1}}"}
{"receive_ns":1788563194148214000,"stream":"btcusdt@bookTicker","event_type":"bookTicker","event_time_ms":1788563194183,"raw_json":"{\"stream\":\"btcusdt@bookTicker\",\"data\":{\"e\":\"bookTicker\",\"u\":11478222544335,\"s\":\"BTCUSDT\",\"ps\":\"BTCUSDT\",\"b\":\"79607.10\",\"B\":\"10.307\",\"a\":\"79607.20\",\"A\":\"1.751\",\"T\":1788563194183,\"E\":1788563194183,\"st\":1}}"}
{"receive_ns":1788563194188521000,"stream":"btcusdt@bookTicker","event_type":"bookTicker","event_time_ms":1788563194213,"raw_json":"{\"stream\":\"btcusdt@bookTicker\",\"data\":{\"e\":\"bookTicker\",\"u\":11478222545709,\"s\":\"BTCUSDT\",\"ps\":\"BTCUSDT\",\"b\":\"79607.10\",\"B\":\"10.305\",\"a\":\"79607.20\",\"A\":\"1.751\",\"T\":1788563194213,\"E\":1788563194213,\"st\":1}}"}
{"receive_ns":1788563194199457000,"stream":"btcusdt@bookTicker","event_type":"bookTicker","event_time_ms":1788563194234,"raw_json":"{\"stream\":\"btcusdt@bookTicker\",\"data\":{\"e\":\"bookTicker\",\"u\":11478222546671,\"s\":\"BTCUSDT\",\"ps\":\"BTCUSDT\",\"b\":\"79607.10\",\"B\":\"10.305\",\"a\":\"79607.20\",\"A\":\"1.765\",\"T\":1788563194234,\"E\":1788563194234,\"st\":1}}"}
{"receive_ns":1788563194228315000,"stream":"btcusdt@bookTicker","event_type":"bookTicker","event_time_ms":1788563194263,"raw_json":"{\"stream\":\"btcusdt@bookTicker\",\"data\":{\"e\":\"bookTicker\",\"u\":11478222548175,\"s\":\"BTCUSDT\",\"ps\":\"BTCUSDT\",\"b\":\"79607.10\",\"B\":\"10.020\",\"a\":\"79607.20\",\"A\":\"1.765\",\"T\":1788563194262,\"E\":1788563194263,\"st\":1}}"}
{"receive_ns":1788563194230922000,"stream":"btcusdt@bookTicker","event_type":"bookTicker","event_time_ms":1788563194266,"raw_json":"{\"stream\":\"btcusdt@bookTicker\",\"data\":{\"e\":\"bookTicker\",\"u\":11478222548346,\"s\":\"BTCUSDT\",\"ps\":\"BTCUSDT\",\"b\":\"79607.10\",\"B\":\"10.281\",\"a\":\"79607.20\",\"A\":\"1.765\",\"T\":1788563194265,\"E\":1788563194266,\"st\":1}}"}
{"receive_ns":1788563194243846000,"stream":"btcusdt@depth@100ms","event_type":"depthUpdate","event_time_ms":1788563194279,"raw_json":"{\"stream\":\"btcusdt@depth@100ms\",\"data\":{\"e\":\"depthUpdate\",\"E\":1788563194279,\"T\":1788563194278,\"s\":\"BTCUSDT\",\"ps\":\"BTCUSDT\",\"U\":11478222543941,\"u\":11478222548768,\"pu\":11478222543887,\"b\":[[\"1000.00\",\"24.604\"],[\"29107.10\",\"1.820\"],[\"29207.10\",\"0.000\"],[\"29507.10\",\"0.280\"],[\"71646.30\",\"0.002\"],[\"71680.00\",\"0.127\"],[\"76422.80\",\"0.002\"],[\"78563.30\",\"7.248\"],[\"78811.00\",\"3.492\"],[\"79209.00\",\"0.002\"],[\"79209.10\",\"0.519\"],[\"79236.90\",\"0.247\"],[\"79434.00\",\"0.929\"],[\"79479.70\",\"1.095\"],[\"79491.70\",\"1.279\"],[\"79535.00\",\"0.003\"],[\"79592.90\",\"0.494\"],[\"79594.00\",\"0.020\"],[\"79606.70\",\"0.026\"],[\"79607.00\",\"0.007\"],[\"79607.10\",\"10.281\"]],\"a\":[[\"79607.20\",\"1.765\"],[\"79607.70\",\"0.026\"],[\"79607.80\",\"0.027\"],[\"79609.20\",\"0.277\"],[\"79609.60\",\"0.000\"],[\"79611.20\",\"0.341\"],[\"79674.90\",\"0.211\"],[\"79682.90\",\"0.002\"],[\"79707.70\",\"0.011\"],[\"79728.60\",\"0.280\"],[\"79973.40\",\"1.913\"],[\"80344.30\",\"0.005\"],[\"80403.30\",\"7.055\"]],\"st\":1}}"}
{"receive_ns":1788563194246031000,"stream":"btcusdt@bookTicker","event_type":"bookTicker","event_time_ms":1788563194280,"raw_json":"{\"stream\":\"btcusdt@bookTicker\",\"data\":{\"e\":\"bookTicker\",\"u\":11478222548841,\"s\":\"BTCUSDT\",\"ps\":\"BTCUSDT\",\"b\":\"79607.10\",\"B\":\"10.289\",\"a\":\"79607.20\",\"A\":\"1.765\",\"T\":1788563194279,\"E\":1788563194280,\"st\":1}}"}
{"receive_ns":1788563194246215000,"stream":"btcusdt@bookTicker","event_type":"bookTicker","event_time_ms":1788563194280,"raw_json":"{\"stream\":\"btcusdt@bookTicker\",\"data\":{\"e\":\"bookTicker\",\"u\":11478222548848,\"s\":\"BTCUSDT\",\"ps\":\"BTCUSDT\",\"b\":\"79607.10\",\"B\":\"10.308\",\"a\":\"79607.20\",\"A\":\"1.765\",\"T\":1788563194279,\"E\":1788563194280,\"st\":1}}"}
{"receive_ns":1788563194247955000,"stream":"btcusdt@bookTicker","event_type":"bookTicker","event_time_ms":1788563194280,"raw_json":"{\"stream\":\"btcusdt@bookTicker\",\"data\":{\"e\":\"bookTicker\",\"u\":11478222548898,\"s\":\"BTCUSDT\",\"ps\":\"BTCUSDT\",\"b\":\"79607.10\",\"B\":\"10.289\",\"a\":\"79607.20\",\"A\":\"1.765\",\"T\":1788563194280,\"E\":1788563194280,\"st\":1}}"}
{"receive_ns":1788563194248204000,"stream":"btcusdt@bookTicker","event_type":"bookTicker","event_time_ms":1788563194280,"raw_json":"{\"stream\":\"btcusdt@bookTicker\",\"data\":{\"e\":\"bookTicker\",\"u\":11478222548902,\"s\":\"BTCUSDT\",\"ps\":\"BTCUSDT\",\"b\":\"79607.10\",\"B\":\"10.281\",\"a\":\"79607.20\",\"A\":\"1.765\",\"T\":1788563194280,\"E\":1788563194280,\"st\":1}}"}
{"receive_ns":1788563194272992000,"stream":"btcusdt@bookTicker","event_type":"bookTicker","event_time_ms":1788563194309,"raw_json":"{\"stream\":\"btcusdt@bookTicker\",\"data\":{\"e\":\"bookTicker\",\"u\":11478222550212,\"s\":\"BTCUSDT\",\"ps\":\"BTCUSDT\",\"b\":\"79607.10\",\"B\":\"10.315\",\"a\":\"79607.20\",\"A\":\"1.765\",\"T\":1788563194309,\"E\":1788563194309,\"st\":1}}"}
{"receive_ns":1788563194331493000,"stream":"btcusdt@bookTicker","event_type":"bookTicker","event_time_ms":1788563194364,"raw_json":"{\"stream\":\"btcusdt@bookTicker\",\"data\":{\"e\":\"bookTicker\",\"u\":11478222552609,\"s\":\"BTCUSDT\",\"ps\":\"BTCUSDT\",\"b\":\"79607.10\",\"B\":\"9.991\",\"a\":\"79607.20\",\"A\":\"1.765\",\"T\":1788563194364,\"E\":1788563194364,\"st\":1}}"}
{"receive_ns":1788563194332894000,"stream":"btcusdt@bookTicker","event_type":"bookTicker","event_time_ms":1788563194367,"raw_json":"{\"stream\":\"btcusdt@bookTicker\",\"data\":{\"e\":\"bookTicker\",\"u\":11478222552801,\"s\":\"BTCUSDT\",\"ps\":\"BTCUSDT\",\"b\":\"79607.10\",\"B\":\"9.944\",\"a\":\"79607.20\",\"A\":\"1.765\",\"T\":1788563194367,\"E\":1788563194367,\"st\":1}}"}
{"receive_ns":1788563194333139000,"stream":"btcusdt@bookTicker","event_type":"bookTicker","event_time_ms":1788563194367,"raw_json":"{\"stream\":\"btcusdt@bookTicker\",\"data\":{\"e\":\"bookTicker\",\"u\":11478222552815,\"s\":\"BTCUSDT\",\"ps\":\"BTCUSDT\",\"b\":\"79607.10\",\"B\":\"10.272\",\"a\":\"79607.20\",\"A\":\"1.765\",\"T\":1788563194367,\"E\":1788563194367,\"st\":1}}"}
{"receive_ns":1788563194341667000,"stream":"btcusdt@bookTicker","event_type":"bookTicker","event_time_ms":1788563194376,"raw_json":"{\"stream\":\"btcusdt@bookTicker\",\"data\":{\"e\":\"bookTicker\",\"u\":11478222553312,\"s\":\"BTCUSDT\",\"ps\":\"BTCUSDT\",\"b\":\"79607.10\",\"B\":\"10.066\",\"a\":\"79607.20\",\"A\":\"1.765\",\"T\":1788563194376,\"E\":1788563194376,\"st\":1}}"}
{"receive_ns":1788563194342987000,"stream":"btcusdt@bookTicker","event_type":"bookTicker","event_time_ms":1788563194378,"raw_json":"{\"stream\":\"btcusdt@bookTicker\",\"data\":{\"e\":\"bookTicker\",\"u\":11478222553449,\"s\":\"BTCUSDT\",\"ps\":\"BTCUSDT\",\"b\":\"79607.10\",\"B\":\"10.273\",\"a\":\"79607.20\",\"A\":\"1.765\",\"T\":1788563194378,\"E\":1788563194378,\"st\":1}}"}
{"receive_ns":1788563194343178000,"stream":"btcusdt@bookTicker","event_type":"bookTicker","event_time_ms":1788563194378,"raw_json":"{\"stream\":\"btcusdt@bookTicker\",\"data\":{\"e\":\"bookTicker\",\"u\":11478222553450,\"s\":\"BTCUSDT\",\"ps\":\"BTCUSDT\",\"b\":\"79607.10\",\"B\":\"9.812\",\"a\":\"79607.20\",\"A\":\"1.765\",\"T\":1788563194378,\"E\":1788563194378,\"st\":1}}"}
{"receive_ns":1788563194346025000,"stream":"btcusdt@depth@100ms","event_type":"depthUpdate","event_time_ms":1788563194381,"raw_json":"{\"stream\":\"btcusdt@depth@100ms\",\"data\":{\"e\":\"depthUpdate\",\"E\":1788563194381,\"T\":1788563194379,\"s\":\"BTCUSDT\",\"ps\":\"BTCUSDT\",\"U\":11478222548841,\"u\":11478222553507,\"pu\":11478222548768,\"b\":[[\"1000.00\",\"24.604\"],[\"29107.10\",\"1.645\"],[\"29507.10\",\"0.455\"],[\"71646.30\",\"0.002\"],[\"78241.90\",\"0.511\"],[\"78811.00\",\"3.496\"],[\"79209.10\",\"0.529\"],[\"79434.00\",\"0.427\"],[\"79478.40\",\"0.000\"],[\"79479.20\",\"0.000\"],[\"79479.70\",\"0.558\"],[\"79487.70\",\"1.507\"],[\"79491.70\",\"0.075\"],[\"79607.10\",\"9.812\"]],\"a\":[[\"79611.20\",\"0.000\"],[\"79728.60\",\"0.000\"],[\"79973.40\",\"1.150\"],[\"80004.30\",\"0.543\"],[\"80005.20\",\"0.261\"],[\"80244.10\",\"0.996\"],[\"80403.30\",\"7.055\"],[\"80701.00\",\"1.238\"]],\"st\":1}}"}
{"receive_ns":1788563194353076000,"stream":"btcusdt@bookTicker","event_type":"bookTicker","event_time_ms":1788563194387,"raw_json":"{\"stream\":\"btcusdt@bookTicker\",\"data\":{\"e\":\"bookTicker\",\"u\":11478222553771,\"s\":\"BTCUSDT\",\"ps\":\"BTCUSDT\",\"b\":\"79607.10\",\"B\":\"10.289\",\"a\":\"79607.20\",\"A\":\"1.765\",\"T\":1788563194387,\"E\":1788563194387,\"st\":1}}"}
{"receive_ns":1788563194353347000,"stream":"btcusdt@bookTicker","event_type":"bookTicker","event_time_ms":1788563194388,"raw_json":"{\"stream\":\"btcusdt@bookTicker\",\"data\":{\"e\":\"bookTicker\",\"u\":11478222553818,\"s\":\"BTCUSDT\",\"ps\":\"BTCUSDT\",\"b\":\"79607.10\",\"B\":\"10.287\",\"a\":\"79607.20\",\"A\":\"1.765\",\"T\":1788563194388,\"E\":1788563194388,\"st\":1}}"}
{"receive_ns":1788563194370594000,"stream":"btcusdt@bookTicker","event_type":"bookTicker","event_time_ms":1788563194404,"raw_json":"{\"stream\":\"btcusdt@bookTicker\",\"data\":{\"e\":\"bookTicker\",\"u\":11478222554397,\"s\":\"BTCUSDT\",\"ps\":\"BTCUSDT\",\"b\":\"79607.10\",\"B\":\"10.387\",\"a\":\"79607.20\",\"A\":\"1.765\",\"T\":1788563194404,\"E\":1788563194404,\"st\":1}}"}
{"receive_ns":1788563194370881000,"stream":"btcusdt@bookTicker","event_type":"bookTicker","event_time_ms":1788563194405,"raw_json":"{\"stream\":\"btcusdt@bookTicker\",\"data\":{\"e\":\"bookTicker\",\"u\":11478222554473,\"s\":\"BTCUSDT\",\"ps\":\"BTCUSDT\",\"b\":\"79607.10\",\"B\":\"10.389\",\"a\":\"79607.20\",\"A\":\"1.765\",\"T\":1788563194405,\"E\":1788563194405,\"st\":1}}"}
{"receive_ns":1788563194419308000,"stream":"btcusdt@bookTicker","event_type":"bookTicker","event_time_ms":1788563194454,"raw_json":"{\"stream\":\"btcusdt@bookTicker\",\"data\":{\"e\":\"bookTicker\",\"u\":11478222556933,\"s\":\"BTCUSDT\",\"ps\":\"BTCUSDT\",\"b\":\"79607.10\",\"B\":\"10.397\",\"a\":\"79607.20\",\"A\":\"1.765\",\"T\":1788563194453,\"E\":1788563194454,\"st\":1}}"}
{"receive_ns":1788563194419583000,"stream":"btcusdt@bookTicker","event_type":"bookTicker","event_time_ms":1788563194454,"raw_json":"{\"stream\":\"btcusdt@bookTicker\",\"data\":{\"e\":\"bookTicker\",\"u\":11478222556935,\"s\":\"BTCUSDT\",\"ps\":\"BTCUSDT\",\"b\":\"79607.10\",\"B\":\"10.416\",\"a\":\"79607.20\",\"A\":\"1.765\",\"T\":1788563194454,\"E\":1788563194454,\"st\":1}}"}
{"receive_ns":1788563194419781000,"stream":"btcusdt@bookTicker","event_type":"bookTicker","event_time_ms":1788563194454,"raw_json":"{\"stream\":\"btcusdt@bookTicker\",\"data\":{\"e\":\"bookTicker\",\"u\":11478222556974,\"s\":\"BTCUSDT\",\"ps\":\"BTCUSDT\",\"b\":\"79607.10\",\"B\":\"10.408\",\"a\":\"79607.20\",\"A\":\"1.765\",\"T\":1788563194454,\"E\":1788563194454,\"st\":1}}"}
{"receive_ns":1788563194420024000,"stream":"btcusdt@bookTicker","event_type":"bookTicker","event_time_ms":1788563194455,"raw_json":"{\"stream\":\"btcusdt@bookTicker\",\"data\":{\"e\":\"bookTicker\",\"u\":11478222556983,\"s\":\"BTCUSDT\",\"ps\":\"BTCUSDT\",\"b\":\"79607.10\",\"B\":\"10.389\",\"a\":\"79607.20\",\"A\":\"1.765\",\"T\":1788563194454,\"E\":1788563194455,\"st\":1}}"}
{"receive_ns":1788563194446528000,"stream":"btcusdt@depth@100ms","event_type":"depthUpdate","event_time_ms":1788563194483,"raw_json":"{\"stream\":\"btcusdt@depth@100ms\",\"data\":{\"e\":\"depthUpdate\",\"E\":1788563194483,\"T\":1788563194482,\"s\":\"BTCUSDT\",\"ps\":\"BTCUSDT\",\"U\":11478222553567,\"u\":11478222558416,\"pu\":11478222553507,\"b\":[[\"29107.10\",\"1.463\"],[\"29507.10\",\"0.637\"],[\"71646.30\",\"0.002\"],[\"76422.80\",\"0.000\"],[\"78413.00\",\"0.574\"],[\"78572.20\",\"0.781\"],[\"78642.30\",\"0.000\"],[\"78811.00\",\"3.492\"],[\"79209.10\",\"0.529\"],[\"79236.90\",\"0.247\"],[\"79344.70\",\"0.000\"],[\"79392.60\",\"3.150\"],[\"79434.00\",\"0.076\"],[\"79440.30\",\"0.021\"],[\"79440.40\",\"2.854\"],[\"79479.00\",\"1.013\"],[\"79479.80\",\"0.938\"],[\"79491.70\",\"1.630\"],[\"79516.00\",\"1.256\"],[\"79516.10\",\"3.469\"],[\"79534.00\",\"23.532\"],[\"79535.40\",\"0.002\"],[\"79536.70\",\"0.000\"],[\"79600.50\",\"0.252\"],[\"79602.20\",\"0.000\"],[\"79603.00\",\"0.001\"],[\"79607.00\",\"0.033\"],[\"79607.10\",\"10.389\"]],\"a\":[[\"79607.70\",\"0.000\"],[\"79607.80\",\"0.001\"],[\"79608.20\",\"0.003\"],[\"79608.50\",\"0.000\"],[\"79608.60\",\"0.000\"],[\"79608.80\",\"0.001\"],[\"79608.90\",\"0.000\"],[\"79609.10\",\"0.000\"],[\"79609.20\",\"0.000\"],[\"79609.30\",\"0.027\"],[\"79609.40\",\"0.030\"],[\"79611.20\",\"0.251\"],[\"79663.00\",\"0.002\"],[\"79674.90\",\"0.462\"],[\"79728.60\",\"0.340\"],[\"79768.00\",\"1.921\"],[\"79788.30\",\"0.414\"],[\"79973.40\",\"2.003\"],[\"80000.40\",\"2.994\"],[\"80387.60\",\"0.000\"],[\"80403.30\",\"7.057\"],[\"80482.90\",\"2.482\"],[\"81199.30\",\"0.015\"]],\"st\":1}}"}
{"receive_ns":1788563194467859000,"stream":"btcusdt@bookTicker","event_type":"bookTicker","event_time_ms":1788563194502,"raw_json":"{\"stream\":\"btcusdt@bookTicker\",\"data\":{\"e\":\"bookTicker\",\"u\":11478222559250,\"s\":\"BTCUSDT\",\"ps\":\"BTCUSDT\",\"b\":\"79607.10\",\"B\":\"10.096\",\"a\":\"79607.20\",\"A\":\"1.765\",\"T\":1788563194502,\"E\":1788563194502,\"st\":1}}"}
{"receive_ns":1788563194468274000,"stream":"btcusdt@bookTicker","event_type":"bookTicker","event_time_ms":1788563194503,"raw_json":"{\"stream\":\"btcusdt@bookTicker\",\"data\":{\"e\":\"bookTicker\",\"u\":11478222559338,\"s\":\"BTCUSDT\",\"ps\":\"BTCUSDT\",\"b\":\"79607.10\",\"B\":\"10.096\",\"a\":\"79607.20\",\"A\":\"1.778\",\"T\":1788563194503,\"E\":1788563194503,\"st\":1}}"}
{"receive_ns":1788563194471250000,"stream":"btcusdt@bookTicker","event_type":"bookTicker","event_time_ms":1788563194505,"raw_json":"{\"stream\":\"btcusdt@bookTicker\",\"data\":{\"e\":\"bookTicker\",\"u\":11478222559487,\"s\":\"BTCUSDT\",\"ps\":\"BTCUSDT\",\"b\":\"79607.10\",\"B\":\"10.396\",\"a\":\"79607.20\",\"A\":\"1.778\",\"T\":1788563194505,\"E\":1788563194505,\"st\":1}}"}
{"receive_ns":1788563194471666000,"stream":"btcusdt@bookTicker","event_type":"bookTicker","event_time_ms":1788563194506,"raw_json":"{\"stream\":\"btcusdt@bookTicker\",\"data\":{\"e\":\"bookTicker\",\"u\":11478222559545,\"s\":\"BTCUSDT\",\"ps\":\"BTCUSDT\",\"b\":\"79607.10\",\"B\":\"10.415\",\"a\":\"79607.20\",\"A\":\"1.778\",\"T\":1788563194506,\"E\":1788563194506,\"st\":1}}"}
{"receive_ns":1788563194471939000,"stream":"btcusdt@bookTicker","event_type":"bookTicker","event_time_ms":1788563194506,"raw_json":"{\"stream\":\"btcusdt@bookTicker\",\"data\":{\"e\":\"bookTicker\",\"u\":11478222559585,\"s\":\"BTCUSDT\",\"ps\":\"BTCUSDT\",\"b\":\"79607.10\",\"B\":\"10.413\",\"a\":\"79607.20\",\"A\":\"1.778\",\"T\":1788563194506,\"E\":1788563194506,\"st\":1}}"}
{"receive_ns":1788563194472186000,"stream":"btcusdt@bookTicker","event_type":"bookTicker","event_time_ms":1788563194507,"raw_json":"{\"stream\":\"btcusdt@bookTicker\",\"data\":{\"e\":\"bookTicker\",\"u\":11478222559597,\"s\":\"BTCUSDT\",\"ps\":\"BTCUSDT\",\"b\":\"79607.10\",\"B\":\"10.394\",\"a\":\"79607.20\",\"A\":\"1.778\",\"T\":1788563194507,\"E\":1788563194507,\"st\":1}}"}
{"receive_ns":1788563194494105000,"stream":"btcusdt@bookTicker","event_type":"bookTicker","event_time_ms":1788563194521,"raw_json":"{\"stream\":\"btcusdt@bookTicker\",\"data\":{\"e\":\"bookTicker\",\"u\":11478222560274,\"s\":\"BTCUSDT\",\"ps\":\"BTCUSDT\",\"b\":\"79607.10\",\"B\":\"10.413\",\"a\":\"79607.20\",\"A\":\"1.778\",\"T\":1788563194521,\"E\":1788563194521,\"st\":1}}"}
{"receive_ns":1788563194495543000,"stream":"btcusdt@bookTicker","event_type":"bookTicker","event_time_ms":1788563194522,"raw_json":"{\"stream\":\"btcusdt@bookTicker\",\"data\":{\"e\":\"bookTicker\",\"u\":11478222560309,\"s\":\"BTCUSDT\",\"ps\":\"BTCUSDT\",\"b\":\"79607.10\",\"B\":\"10.394\",\"a\":\"79607.20\",\"A\":\"1.778\",\"T\":1788563194522,\"E\":1788563194522,\"st\":1}}"}
{"receive_ns":1788563194495817000,"stream":"btcusdt@bookTicker","event_type":"bookTicker","event_time_ms":1788563194522,"raw_json":"{\"stream\":\"btcusdt@bookTicker\",\"data\":{\"e\":\"bookTicker\",\"u\":11478222560334,\"s\":\"BTCUSDT\",\"ps\":\"BTCUSDT\",\"b\":\"79607.10\",\"B\":\"10.396\",\"a\":\"79607.20\",\"A\":\"1.778\",\"T\":1788563194522,\"E\":1788563194522,\"st\":1}}"}
{"receive_ns":1788563194549251000,"stream":"btcusdt@depth@100ms","event_type":"depthUpdate","event_time_ms":1788563194585,"raw_json":"{\"stream\":\"btcusdt@depth@100ms\",\"data\":{\"e\":\"depthUpdate\",\"E\":1788563194585,\"T\":1788563194582,\"s\":\"BTCUSDT\",\"ps\":\"BTCUSDT\",\"U\":11478222558476,\"u\":11478222563361,\"pu\":11478222558416,\"b\":[[\"1000.00\",\"24.604\"],[\"29107.10\",\"1.288\"],[\"29507.10\",\"0.812\"],[\"63686.00\",\"0.002\"],[\"71646.30\",\"0.002\"],[\"76422.80\",\"0.002\"],[\"78811.00\",\"3.492\"],[\"79209.00\",\"0.001\"],[\"79478.80\",\"0.375\"],[\"79479.80\",\"0.938\"],[\"79487.70\",\"0.001\"],[\"79575.40\",\"0.002\"],[\"79577.00\",\"0.008\"],[\"79584.80\",\"0.309\"],[\"79600.60\",\"0.078\"],[\"79605.70\",\"0.126\"],[\"79607.10\",\"10.396\"]],\"a\":[[\"79607.20\",\"1.778\"],[\"79608.80\",\"0.001\"],[\"79608.90\",\"0.000\"],[\"79609.00\",\"0.105\"],[\"79609.10\",\"0.000\"],[\"79609.20\",\"0.026\"],[\"79609.60\",\"0.026\"],[\"79609.70\",\"0.026\"],[\"79609.80\",\"0.026\"],[\"79609.90\",\"0.028\"],[\"79610.00\",\"0.030\"],[\"79653.20\",\"0.006\"],[\"79661.50\",\"0.000\"],[\"79674.90\",\"0.211\"],[\"79728.60\",\"0.340\"],[\"79973.40\",\"0.969\"],[\"80403.30\",\"7.055\"]],\"st\":1}}"}
{"receive_ns":1788563194617769000,"stream":"btcusdt@bookTicker","event_type":"bookTicker","event_time_ms":1788563194652,"raw_json":"{\"stream\":\"btcusdt@bookTicker\",\"data\":{\"e\":\"bookTicker\",\"u\":11478222566515,\"s\":\"BTCUSDT\",\"ps\":\"BTCUSDT\",\"b\":\"79607.10\",\"B\":\"10.415\",\"a\":\"79607.20\",\"A\":\"1.778\",\"T\":1788563194651,\"E\":1788563194652,\"st\":1}}"}
{"receive_ns":1788563194618031000,"stream":"btcusdt@bookTicker","event_type":"bookTicker","event_time_ms":1788563194652,"raw_json":"{\"stream\":\"btcusdt@bookTicker\",\"data\":{\"e\":\"bookTicker\",\"u\":11478222566561,\"s\":\"BTCUSDT\",\"ps\":\"BTCUSDT\",\"b\":\"79607.10\",\"B\":\"10.396\",\"a\":\"79607.20\",\"A\":\"1.778\",\"T\":1788563194652,\"E\":1788563194652,\"st\":1}}"}
{"receive_ns":1788563194651491000,"stream":"btcusdt@depth@100ms","event_type":"depthUpdate","event_time_ms":1788563194687,"raw_json":"{\"stream\":\"btcusdt@depth@100ms\",\"data\":{\"e\":\"depthUpdate\",\"E\":1788563194687,\"T\":1788563194686,\"s\":\"BTCUSDT\",\"ps\":\"BTCUSDT\",\"U\":11478222563608,\"u\":11478222568177,\"pu\":11478222563361,\"b\":[[\"1000.00\",\"24.604\"],[\"29107.10\",\"1.106\"],[\"29507.10\",\"0.994\"],[\"63686.00\",\"0.002\"],[\"71646.30\",\"0.002\"],[\"76422.80\",\"0.000\"],[\"78811.00\",\"3.492\"],[\"79209.10\",\"0.378\"],[\"79236.90\",\"0.015\"],[\"79487.70\",\"1.507\"],[\"79491.70\",\"1.204\"],[\"79607.10\",\"10.396\"]],\"a\":[[\"79608.60\",\"0.026\"],[\"79608.80\",\"0.027\"],[\"79608.90\",\"0.026\"],[\"79609.90\",\"0.002\"],[\"79610.00\",\"0.004\"],[\"79611.20\",\"0.000\"],[\"79617.00\",\"0.002\"],[\"79617.30\",\"0.067\"],[\"79649.80\",\"0.033\"],[\"79651.30\",\"0.043\"],[\"79674.90\",\"0.410\"],[\"79788.30\",\"0.215\"],[\"79973.40\",\"1.713\"],[\"80000.40\",\"2.869\"],[\"80005.30\",\"0.002\"],[\"80403.30\",\"7.055\"],[\"80697.80\",\"0.988\"]],\"st\":1}}"}
{"receive_ns":1788563194662662000,"stream":"btcusdt@bookTicker","event_type":"bookTicker","event_time_ms":1788563194696,"raw_json":"{\"stream\":\"btcusdt@bookTicker\",\"data\":{\"e\":\"bookTicker\",\"u\":11478222568698,\"s\":\"BTCUSDT\",\"ps\":\"BTCUSDT\",\"b\":\"79607.10\",\"B\":\"10.415\",\"a\":\"79607.20\",\"A\":\"1.778\",\"T\":1788563194696,\"E\":1788563194696,\"st\":1}}"}
{"receive_ns":1788563194662928000,"stream":"btcusdt@bookTicker","event_type":"bookTicker","event_time_ms":1788563194697,"raw_json":"{\"stream\":\"btcusdt@bookTicker\",\"data\":{\"e\":\"bookTicker\",\"u\":11478222568764,\"s\":\"BTCUSDT\",\"ps\":\"BTCUSDT\",\"b\":\"79607.10\",\"B\":\"10.396\",\"a\":\"79607.20\",\"A\":\"1.778\",\"T\":1788563194696,\"E\":1788563194697,\"st\":1}}"}
{"receive_ns":1788563194683569000,"stream":"btcusdt@bookTicker","event_type":"bookTicker","event_time_ms":1788563194714,"raw_json":"{\"stream\":\"btcusdt@bookTicker\",\"data\":{\"e\":\"bookTicker\",\"u\":11478222570165,\"s\":\"BTCUSDT\",\"ps\":\"BTCUSDT\",\"b\":\"79607.10\",\"B\":\"10.415\",\"a\":\"79607.20\",\"A\":\"1.778\",\"T\":1788563194714,\"E\":1788563194714,\"st\":1}}"}
{"receive_ns":1788563194683867000,"stream":"btcusdt@bookTicker","event_type":"bookTicker","event_time_ms":1788563194714,"raw_json":"{\"stream\":\"btcusdt@bookTicker\",\"data\":{\"e\":\"bookTicker\",\"u\":11478222570212,\"s\":\"BTCUSDT\",\"ps\":\"BTCUSDT\",\"b\":\"79607.10\",\"B\":\"10.396\",\"a\":\"79607.20\",\"A\":\"1.778\",\"T\":1788563194714,\"E\":1788563194714,\"st\":1}}"}
{"receive_ns":1788563194700516000,"stream":"btcusdt@bookTicker","event_type":"bookTicker","event_time_ms":1788563194734,"raw_json":"{\"stream\":\"btcusdt@bookTicker\",\"data\":{\"e\":\"bookTicker\",\"u\":11478222571449,\"s\":\"BTCUSDT\",\"ps\":\"BTCUSDT\",\"b\":\"79607.10\",\"B\":\"10.396\",\"a\":\"79607.20\",\"A\":\"1.795\",\"T\":1788563194734,\"E\":1788563194734,\"st\":1}}"}
{"receive_ns":1788563194700749000,"stream":"btcusdt@bookTicker","event_type":"bookTicker","event_time_ms":1788563194735,"raw_json":"{\"stream\":\"btcusdt@bookTicker\",\"data\":{\"e\":\"bookTicker\",\"u\":11478222571462,\"s\":\"BTCUSDT\",\"ps\":\"BTCUSDT\",\"b\":\"79607.10\",\"B\":\"10.415\",\"a\":\"79607.20\",\"A\":\"1.795\",\"T\":1788563194734,\"E\":1788563194735,\"st\":1}}"}
{"receive_ns":1788563194700934000,"stream":"btcusdt@bookTicker","event_type":"bookTicker","event_time_ms":1788563194735,"raw_json":"{\"stream\":\"btcusdt@bookTicker\",\"data\":{\"e\":\"bookTicker\",\"u\":11478222571536,\"s\":\"BTCUSDT\",\"ps\":\"BTCUSDT\",\"b\":\"79607.10\",\"B\":\"10.415\",\"a\":\"79607.20\",\"A\":\"1.794\",\"T\":1788563194735,\"E\":1788563194735,\"st\":1}}"}
{"receive_ns":1788563194701172000,"stream":"btcusdt@bookTicker","event_type":"bookTicker","event_time_ms":1788563194735,"raw_json":"{\"stream\":\"btcusdt@bookTicker\",\"data\":{\"e\":\"bookTicker\",\"u\":11478222571546,\"s\":\"BTCUSDT\",\"ps\":\"BTCUSDT\",\"b\":\"79607.10\",\"B\":\"10.396\",\"a\":\"79607.20\",\"A\":\"1.794\",\"T\":1788563194735,\"E\":1788563194735,\"st\":1}}"}
{"receive_ns":1788563194719552000,"stream":"btcusdt@bookTicker","event_type":"bookTicker","event_time_ms":1788563194754,"raw_json":"{\"stream\":\"btcusdt@bookTicker\",\"data\":{\"e\":\"bookTicker\",\"u\":11478222572456,\"s\":\"BTCUSDT\",\"ps\":\"BTCUSDT\",\"b\":\"79607.10\",\"B\":\"10.415\",\"a\":\"79607.20\",\"A\":\"1.794\",\"T\":1788563194754,\"E\":1788563194754,\"st\":1}}"}
{"receive_ns":1788563194719822000,"stream":"btcusdt@bookTicker","event_type":"bookTicker","event_time_ms":1788563194755,"raw_json":"{\"stream\":\"btcusdt@bookTicker\",\"data\":{\"e\":\"bookTicker\",\"u\":11478222572491,\"s\":\"BTCUSDT\",\"ps\":\"BTCUSDT\",\"b\":\"79607.10\",\"B\":\"10.396\",\"a\":\"79607.20\",\"A\":\"1.794\",\"T\":1788563194754,\"E\":1788563194755,\"st\":1}}"}
{"receive_ns":1788563194719990000,"stream":"btcusdt@bookTicker","event_type":"bookTicker","event_time_ms":1788563194755,"raw_json":"{\"stream\":\"btcusdt@bookTicker\",\"data\":{\"e\":\"bookTicker\",\"u\":11478222572532,\"s\":\"BTCUSDT\",\"ps\":\"BTCUSDT\",\"b\":\"79607.10\",\"B\":\"10.396\",\"a\":\"79607.20\",\"A\":\"1.795\",\"T\":1788563194755,\"E\":1788563194755,\"st\":1}}"}
{"receive_ns":1788563194725721000,"stream":"btcusdt@bookTicker","event_type":"bookTicker","event_time_ms":1788563194761,"raw_json":"{\"stream\":\"btcusdt@bookTicker\",\"data\":{\"e\":\"bookTicker\",\"u\":11478222572880,\"s\":\"BTCUSDT\",\"ps\":\"BTCUSDT\",\"b\":\"79607.10\",\"B\":\"10.396\",\"a\":\"79607.20\",\"A\":\"1.772\",\"T\":1788563194760,\"E\":1788563194761,\"st\":1}}"}
{"receive_ns":1788563194737238000,"stream":"btcusdt@bookTicker","event_type":"bookTicker","event_time_ms":1788563194773,"raw_json":"{\"stream\":\"btcusdt@bookTicker\",\"data\":{\"e\":\"bookTicker\",\"u\":11478222573381,\"s\":\"BTCUSDT\",\"ps\":\"BTCUSDT\",\"b\":\"79607.10\",\"B\":\"10.395\",\"a\":\"79607.20\",\"A\":\"1.772\",\"T\":1788563194773,\"E\":1788563194773,\"st\":1}}"}
{"receive_ns":1788563194743160000,"stream":"btcusdt@bookTicker","event_type":"bookTicker","event_time_ms":1788563194778,"raw_json":"{\"stream\":\"btcusdt@bookTicker\",\"data\":{\"e\":\"bookTicker\",\"u\":11478222573635,\"s\":\"BTCUSDT\",\"ps\":\"BTCUSDT\",\"b\":\"79607.10\",\"B\":\"10.414\",\"a\":\"79607.20\",\"A\":\"1.772\",\"T\":1788563194778,\"E\":1788563194778,\"st\":1}}"}
{"receive_ns":1788563194743359000,"stream":"btcusdt@bookTicker","event_type":"bookTicker","event_time_ms":1788563194778,"raw_json":"{\"stream\":\"btcusdt@bookTicker\",\"data\":{\"e\":\"bookTicker\",\"u\":11478222573646,\"s\":\"BTCUSDT\",\"ps\":\"BTCUSDT\",\"b\":\"79607.10\",\"B\":\"10.422\",\"a\":\"79607.20\",\"A\":\"1.772\",\"T\":1788563194778,\"E\":1788563194778,\"st\":1}}"}
{"receive_ns":1788563194743577000,"stream":"btcusdt@bookTicker","event_type":"bookTicker","event_time_ms":1788563194779,"raw_json":"{\"stream\":\"btcusdt@bookTicker\",\"data\":{\"e\":\"bookTicker\",\"u\":11478222573682,\"s\":\"BTCUSDT\",\"ps\":\"BTCUSDT\",\"b\":\"79607.10\",\"B\":\"10.403\",\"a\":\"79607.20\",\"A\":\"1.772\",\"T\":1788563194779,\"E\":1788563194779,\"st\":1}}"}
{"receive_ns":1788563194743740000,"stream":"btcusdt@bookTicker","event_type":"bookTicker","event_time_ms":1788563194779,"raw_json":"{\"stream\":\"btcusdt@bookTicker\",\"data\":{\"e\":\"bookTicker\",\"u\":11478222573684,\"s\":\"BTCUSDT\",\"ps\":\"BTCUSDT\",\"b\":\"79607.10\",\"B\":\"10.395\",\"a\":\"79607.20\",\"A\":\"1.772\",\"T\":1788563194779,\"E\":1788563194779,\"st\":1}}"}
{"receive_ns":1788563194754011000,"stream":"btcusdt@depth@100ms","event_type":"depthUpdate","event_time_ms":1788563194789,"raw_json":"{\"stream\":\"btcusdt@depth@100ms\",\"data\":{\"e\":\"depthUpdate\",\"E\":1788563194789,\"T\":1788563194785,\"s\":\"BTCUSDT\",\"ps\":\"BTCUSDT\",\"U\":11478222568222,\"u\":11478222574006,\"pu\":11478222568177,\"b\":[[\"29107.10\",\"0.931\"],[\"29507.10\",\"1.169\"],[\"63686.00\",\"0.002\"],[\"71646.30\",\"0.002\"],[\"76422.80\",\"0.002\"],[\"77616.90\",\"0.967\"],[\"78492.60\",\"6.234\"],[\"78612.00\",\"1.476\"],[\"78675.70\",\"1.339\"],[\"78811.00\",\"3.492\"],[\"78965.50\",\"1.518\"],[\"79209.10\",\"0.519\"],[\"79236.90\",\"0.247\"],[\"79491.70\",\"1.630\"],[\"79534.00\",\"0.001\"],[\"79536.70\",\"23.544\"],[\"79575.90\",\"0.007\"],[\"79577.00\",\"0.002\"],[\"79583.40\",\"1.873\"],[\"79593.20\",\"0.221\"],[\"79593.90\",\"0.017\"],[\"79606.70\",\"0.000\"],[\"79607.00\",\"0.007\"],[\"79607.10\",\"10.395\"]],\"a\":[[\"79607.20\",\"1.772\"],[\"79607.30\",\"0.029\"],[\"79608.10\",\"0.027\"],[\"79608.40\",\"0.275\"],[\"79609.60\",\"0.000\"],[\"79609.70\",\"0.000\"],[\"79609.80\",\"0.000\"],[\"79611.20\",\"0.251\"],[\"79614.20\",\"0.002\"],[\"79617.00\",\"0.006\"],[\"79617.30\",\"0.063\"],[\"79617.50\",\"0.641\"],[\"79623.30\",\"0.043\"],[\"79674.90\",\"0.410\"],[\"79973.40\",\"1.913\"],[\"79996.20\",\"0.000\"],[\"80005.20\",\"0.635\"],[\"80403.30\",\"7.055\"],[\"81199.30\",\"0.018\"]],\"st\":1}}"}
{"receive_ns":1788563194770675000,"stream":"btcusdt@bookTicker","event_type":"bookTicker","event_time_ms":1788563194806,"raw_json":"{\"stream\":\"btcusdt@bookTicker\",\"data\":{\"e\":\"bookTicker\",\"u\":11478222575013,\"s\":\"BTCUSDT\",\"ps\":\"BTCUSDT\",\"b\":\"79607.10\",\"B\":\"10.403\",\"a\":\"79607.20\",\"A\":\"1.772\",\"T\":1788563194805,\"E\":1788563194806,\"st\":1}}"}
{"receive_ns":1788563194770887000,"stream":"btcusdt@bookTicker","event_type":"bookTicker","event_time_ms":1788563194806,"raw_json":"{\"stream\":\"btcusdt@bookTicker\",\"data\":{\"e\":\"bookTicker\",\"u\":11478222575026,\"s\":\"BTCUSDT\",\"ps\":\"BTCUSDT\",\"b\":\"79607.10\",\"B\":\"10.422\",\"a\":\"79607.20\",\"A\":\"1.772\",\"T\":1788563194805,\"E\":1788563194806,\"st\":1}}"}
{"receive_ns":1788563194771096000,"stream":"btcusdt@bookTicker","event_type":"bookTicker","event_time_ms":1788563194806,"raw_json":"{\"stream\":\"btcusdt@bookTicker\",\"data\":{\"e\":\"bookTicker\",\"u\":11478222575086,\"s\":\"BTCUSDT\",\"ps\":\"BTCUSDT\",\"b\":\"79607.10\",\"B\":\"10.414\",\"a\":\"79607.20\",\"A\":\"1.772\",\"T\":1788563194806,\"E\":1788563194806,\"st\":1}}"}
{"receive_ns":1788563194771263000,"stream":"btcusdt@bookTicker","event_type":"bookTicker","event_time_ms":1788563194806,"raw_json":"{\"stream\":\"btcusdt@bookTicker\",\"data\":{\"e\":\"bookTicker\",\"u\":11478222575093,\"s\":\"BTCUSDT\",\"ps\":\"BTCUSDT\",\"b\":\"79607.10\",\"B\":\"10.395\",\"a\":\"79607.20\",\"A\":\"1.772\",\"T\":1788563194806,\"E\":1788563194806,\"st\":1}}"}
{"receive_ns":1788563194850509000,"stream":"btcusdt@bookTicker","event_type":"bookTicker","event_time_ms":1788563194884,"raw_json":"{\"stream\":\"btcusdt@bookTicker\",\"data\":{\"e\":\"bookTicker\",\"u\":11478222578361,\"s\":\"BTCUSDT\",\"ps\":\"BTCUSDT\",\"b\":\"79607.10\",\"B\":\"10.414\",\"a\":\"79607.20\",\"A\":\"1.772\",\"T\":1788563194883,\"E\":1788563194884,\"st\":1}}"}
{"receive_ns":1788563194850721000,"stream":"btcusdt@bookTicker","event_type":"bookTicker","event_time_ms":1788563194884,"raw_json":"{\"stream\":\"btcusdt@bookTicker\",\"data\":{\"e\":\"bookTicker\",\"u\":11478222578376,\"s\":\"BTCUSDT\",\"ps\":\"BTCUSDT\",\"b\":\"79607.10\",\"B\":\"10.422\",\"a\":\"79607.20\",\"A\":\"1.772\",\"T\":1788563194883,\"E\":1788563194884,\"st\":1}}"}
{"receive_ns":1788563194850905000,"stream":"btcusdt@bookTicker","event_type":"bookTicker","event_time_ms":1788563194884,"raw_json":"{\"stream\":\"btcusdt@bookTicker\",\"data\":{\"e\":\"bookTicker\",\"u\":11478222578414,\"s\":\"BTCUSDT\",\"ps\":\"BTCUSDT\",\"b\":\"79607.10\",\"B\":\"10.403\",\"a\":\"79607.20\",\"A\":\"1.772\",\"T\":1788563194884,\"E\":1788563194884,\"st\":1}}"}
{"receive_ns":1788563194851057000,"stream":"btcusdt@bookTicker","event_type":"bookTicker","event_time_ms":1788563194884,"raw_json":"{\"stream\":\"btcusdt@bookTicker\",\"data\":{\"e\":\"bookTicker\",\"u\":11478222578418,\"s\":\"BTCUSDT\",\"ps\":\"BTCUSDT\",\"b\":\"79607.10\",\"B\":\"10.395\",\"a\":\"79607.20\",\"A\":\"1.772\",\"T\":1788563194884,\"E\":1788563194884,\"st\":1}}"}
{"receive_ns":1788563194851265000,"stream":"btcusdt@bookTicker","event_type":"bookTicker","event_time_ms":1788563194886,"raw_json":"{\"stream\":\"btcusdt@bookTicker\",\"data\":{\"e\":\"bookTicker\",\"u\":11478222578531,\"s\":\"BTCUSDT\",\"ps\":\"BTCUSDT\",\"b\":\"79607.10\",\"B\":\"10.394\",\"a\":\"79607.20\",\"A\":\"1.772\",\"T\":1788563194886,\"E\":1788563194886,\"st\":1}}"}
{"receive_ns":1788563194851480000,"stream":"btcusdt@bookTicker","event_type":"bookTicker","event_time_ms":1788563194887,"raw_json":"{\"stream\":\"btcusdt@bookTicker\",\"data\":{\"e\":\"bookTicker\",\"u\":11478222578602,\"s\":\"BTCUSDT\",\"ps\":\"BTCUSDT\",\"b\":\"79607.10\",\"B\":\"10.395\",\"a\":\"79607.20\",\"A\":\"1.772\",\"T\":1788563194887,\"E\":1788563194887,\"st\":1}}"}
{"receive_ns":1788563194856453000,"stream":"btcusdt@depth@100ms","event_type":"depthUpdate","event_time_ms":1788563194891,"raw_json":"{\"stream\":\"btcusdt@depth@100ms\",\"data\":{\"e\":\"depthUpdate\",\"E\":1788563194891,\"T\":1788563194889,\"s\":\"BTCUSDT\",\"ps\":\"BTCUSDT\",\"U\":11478222574339,\"u\":11478222578693,\"pu\":11478222574006,\"b\":[[\"1000.00\",\"24.604\"],[\"29107.10\",\"0.763\"],[\"29507.10\",\"1.337\"],[\"71646.30\",\"0.002\"],[\"78015.00\",\"0.134\"],[\"78651.80\",\"5.902\"],[\"78811.00\",\"3.492\"],[\"79209.10\",\"0.644\"],[\"79478.80\",\"0.250\"],[\"79487.70\",\"1.507\"],[\"79491.70\",\"1.430\"],[\"79583.40\",\"1.875\"],[\"79605.70\",\"0.152\"],[\"79606.50\",\"0.026\"],[\"79607.10\",\"10.395\"]],\"a\":[[\"79612.00\",\"0.255\"],[\"79612.80\",\"0.029\"],[\"79623.30\",\"0.045\"],[\"79648.80\",\"0.516\"],[\"79674.90\",\"0.211\"],[\"79973.40\",\"1.913\"],[\"80005.20\",\"1.259\"],[\"80403.30\",\"7.055\"],[\"80717.60\",\"0.000\"]],\"st\":1}}"}
{"receive_ns":1788563194985757000,"stream":"btcusdt@depth@100ms","event_type":"depthUpdate","event_time_ms":1788563194993,"raw_json":"{\"stream\":\"btcusdt@depth@100ms\",\"data\":{\"e\":\"depthUpdate\",\"E\":1788563194993,\"T\":1788563194989,\"s\":\"BTCUSDT\",\"ps\":\"BTCUSDT\",\"U\":11478222578767,\"u\":11478222582692,\"pu\":11478222578693,\"b\":[[\"1000.00\",\"24.604\"],[\"29107.10\",\"0.574\"],[\"29507.10\",\"1.526\"],[\"63685.70\",\"0.001\"],[\"63686.00\",\"0.002\"],[\"71646.30\",\"0.002\"],[\"76422.80\",\"0.000\"],[\"78797.70\",\"8.854\"],[\"78811.00\",\"3.492\"],[\"79209.10\",\"0.644\"],[\"79236.90\",\"0.247\"],[\"79440.40\",\"0.000\"],[\"79479.80\",\"0.340\"],[\"79491.70\",\"1.630\"],[\"79556.60\",\"0.207\"],[\"79607.00\",\"0.033\"]],\"a\":[[\"79607.30\",\"0.003\"],[\"79611.20\",\"0.251\"],[\"79728.60\",\"0.000\"],[\"79768.00\",\"0.064\"],[\"79788.30\",\"0.665\"],[\"79973.40\",\"2.003\"],[\"80000.40\",\"2.744\"],[\"80403.30\",\"7.055\"],[\"80602.30\",\"3.258\"],[\"80679.50\",\"0.002\"],[\"80681.90\",\"2.782\"],[\"80706.00\",\"3.896\"],[\"80721.70\",\"9.897\"]],\"st\":1}}"}
{"receive_ns":1788563194986042000,"stream":"btcusdt@bookTicker","event_type":"bookTicker","event_time_ms":1788563194999,"raw_json":"{\"stream\":\"btcusdt@bookTicker\",\"data\":{\"e\":\"bookTicker\",\"u\":11478222583068,\"s\":\"BTCUSDT\",\"ps\":\"BTCUSDT\",\"b\":\"79607.10\",\"B\":\"10.392\",\"a\":\"79607.20\",\"A\":\"1.772\",\"T\":1788563194999,\"E\":1788563194999,\"st\":1}}"}
{"receive_ns":1788563194986226000,"stream":"btcusdt@trade","event_type":"trade","event_time_ms":1788563194999,"raw_json":"{\"stream\":\"btcusdt@trade\",\"data\":{\"e\":\"trade\",\"E\":1788563194999,\"T\":1788563194999,\"s\":\"BTCUSDT\",\"t\":8054082671,\"p\":\"79607.10\",\"q\":\"0.003\",\"X\":\"MARKET\",\"m\":true,\"st\":1}}"}
{"receive_ns":1788563194986434000,"stream":"btcusdt@bookTicker","event_type":"bookTicker","event_time_ms":1788563195000,"raw_json":"{\"stream\":\"btcusdt@bookTicker\",\"data\":{\"e\":\"bookTicker\",\"u\":11478222583145,\"s\":\"BTCUSDT\",\"ps\":\"BTCUSDT\",\"b\":\"79607.10\",\"B\":\"10.411\",\"a\":\"79607.20\",\"A\":\"1.772\",\"T\":1788563195000,\"E\":1788563195000,\"st\":1}}"}
{"receive_ns":1788563194986597000,"stream":"btcusdt@bookTicker","event_type":"bookTicker","event_time_ms":1788563195000,"raw_json":"{\"stream\":\"btcusdt@bookTicker\",\"data\":{\"e\":\"bookTicker\",\"u\":11478222583174,\"s\":\"BTCUSDT\",\"ps\":\"BTCUSDT\",\"b\":\"79607.10\",\"B\":\"10.419\",\"a\":\"79607.20\",\"A\":\"1.772\",\"T\":1788563195000,\"E\":1788563195000,\"st\":1}}"}
{"receive_ns":1788563194986769000,"stream":"btcusdt@bookTicker","event_type":"bookTicker","event_time_ms":1788563195001,"raw_json":"{\"stream\":\"btcusdt@bookTicker\",\"data\":{\"e\":\"bookTicker\",\"u\":11478222583253,\"s\":\"BTCUSDT\",\"ps\":\"BTCUSDT\",\"b\":\"79607.10\",\"B\":\"10.400\",\"a\":\"79607.20\",\"A\":\"1.772\",\"T\":1788563195001,\"E\":1788563195001,\"st\":1}}"}
{"receive_ns":1788563194986952000,"stream":"btcusdt@bookTicker","event_type":"bookTicker","event_time_ms":1788563195001,"raw_json":"{\"stream\":\"btcusdt@bookTicker\",\"data\":{\"e\":\"bookTicker\",\"u\":11478222583262,\"s\":\"BTCUSDT\",\"ps\":\"BTCUSDT\",\"b\":\"79607.10\",\"B\":\"10.392\",\"a\":\"79607.20\",\"A\":\"1.772\",\"T\":1788563195001,\"E\":1788563195001,\"st\":1}}"}
{"receive_ns":1788563195013959000,"stream":"btcusdt@bookTicker","event_type":"bookTicker","event_time_ms":1788563195049,"raw_json":"{\"stream\":\"btcusdt@bookTicker\",\"data\":{\"e\":\"bookTicker\",\"u\":11478222586009,\"s\":\"BTCUSDT\",\"ps\":\"BTCUSDT\",\"b\":\"79607.10\",\"B\":\"10.205\",\"a\":\"79607.20\",\"A\":\"1.772\",\"T\":1788563195049,\"E\":1788563195049,\"st\":1}}"}
{"receive_ns":1788563195015060000,"stream":"btcusdt@bookTicker","event_type":"bookTicker","event_time_ms":1788563195052,"raw_json":"{\"stream\":\"btcusdt@bookTicker\",\"data\":{\"e\":\"bookTicker\",\"u\":11478222586144,\"s\":\"BTCUSDT\",\"ps\":\"BTCUSDT\",\"b\":\"79607.10\",\"B\":\"10.224\",\"a\":\"79607.20\",\"A\":\"1.772\",\"T\":1788563195052,\"E\":1788563195052,\"st\":1}}"}
{"receive_ns":1788563195016527000,"stream":"btcusdt@bookTicker","event_type":"bookTicker","event_time_ms":1788563195052,"raw_json":"{\"stream\":\"btcusdt@bookTicker\",\"data\":{\"e\":\"bookTicker\",\"u\":11478222586165,\"s\":\"BTCUSDT\",\"ps\":\"BTCUSDT\",\"b\":\"79607.10\",\"B\":\"10.232\",\"a\":\"79607.20\",\"A\":\"1.772\",\"T\":1788563195052,\"E\":1788563195052,\"st\":1}}"}
{"receive_ns":1788563195016764000,"stream":"btcusdt@bookTicker","event_type":"bookTicker","event_time_ms":1788563195052,"raw_json":"{\"stream\":\"btcusdt@bookTicker\",\"data\":{\"e\":\"bookTicker\",\"u\":11478222586195,\"s\":\"BTCUSDT\",\"ps\":\"BTCUSDT\",\"b\":\"79607.10\",\"B\":\"10.213\",\"a\":\"79607.20\",\"A\":\"1.772\",\"T\":1788563195052,\"E\":1788563195052,\"st\":1}}"}
{"receive_ns":1788563195016927000,"stream":"btcusdt@bookTicker","event_type":"bookTicker","event_time_ms":1788563195052,"raw_json":"{\"stream\":\"btcusdt@bookTicker\",\"data\":{\"e\":\"bookTicker\",\"u\":11478222586198,\"s\":\"BTCUSDT\",\"ps\":\"BTCUSDT\",\"b\":\"79607.10\",\"B\":\"10.205\",\"a\":\"79607.20\",\"A\":\"1.772\",\"T\":1788563195052,\"E\":1788563195052,\"st\":1}}"}
{"receive_ns":1788563195019257000,"stream":"btcusdt@bookTicker","event_type":"bookTicker","event_time_ms":1788563195055,"raw_json":"{\"stream\":\"btcusdt@bookTicker\",\"data\":{\"e\":\"bookTicker\",\"u\":11478222586327,\"s\":\"BTCUSDT\",\"ps\":\"BTCUSDT\",\"b\":\"79607.10\",\"B\":\"10.393\",\"a\":\"79607.20\",\"A\":\"1.772\",\"T\":1788563195054,\"E\":1788563195055,\"st\":1}}"}
{"receive_ns":1788563195020422000,"stream":"btcusdt@bookTicker","event_type":"bookTicker","event_time_ms":1788563195056,"raw_json":"{\"stream\":\"btcusdt@bookTicker\",\"data\":{\"e\":\"bookTicker\",\"u\":11478222586380,\"s\":\"BTCUSDT\",\"ps\":\"BTCUSDT\",\"b\":\"79607.10\",\"B\":\"10.391\",\"a\":\"79607.20\",\"A\":\"1.772\",\"T\":1788563195056,\"E\":1788563195056,\"st\":1}}"}
{"receive_ns":1788563195058689000,"stream":"btcusdt@depth@100ms","event_type":"depthUpdate","event_time_ms":1788563195095,"raw_json":"{\"stream\":\"btcusdt@depth@100ms\",\"data\":{\"e\":\"depthUpdate\",\"E\":1788563195095,\"T\":1788563195089,\"s\":\"BTCUSDT\",\"ps\":\"BTCUSDT\",\"U\":11478222582865,\"u\":11478222587764,\"pu\":11478222582692,\"b\":[[\"29107.10\",\"0.399\"],[\"29507.10\",\"1.701\"],[\"71646.30\",\"0.002\"],[\"76422.80\",\"0.002\"],[\"78394.60\",\"0.022\"],[\"78811.00\",\"3.492\"],[\"78970.20\",\"1.516\"],[\"79440.40\",\"2.857\"],[\"79443.60\",\"0.945\"],[\"79479.80\",\"0.938\"],[\"79487.70\",\"0.001\"],[\"79493.70\",\"2.137\"],[\"79534.00\",\"23.545\"],[\"79534.10\",\"4.515\"],[\"79536.70\",\"0.000\"],[\"79592.80\",\"0.003\"],[\"79605.70\",\"0.204\"],[\"79607.00\",\"0.007\"],[\"79607.10\",\"10.391\"]],\"a\":[[\"79607.60\",\"0.026\"],[\"79607.70\",\"0.026\"],[\"79607.90\",\"0.102\"],[\"79609.30\",\"0.001\"],[\"79609.40\",\"0.004\"],[\"79611.20\",\"0.000\"],[\"79728.60\",\"0.340\"],[\"79729.40\",\"2.117\"],[\"79768.00\",\"1.948\"],[\"79801.00\",\"1.872\"],[\"79973.40\",\"2.003\"],[\"80403.30\",\"7.055\"],[\"80562.50\",\"12.958\"],[\"80721.70\",\"11.753\"],[\"80819.70\",\"0.000\"],[\"81199.30\",\"0.021\"]],\"st\":1}}"}
{"receive_ns":1788563195164666000,"stream":"btcusdt@depth@100ms","event_type":"depthUpdate","event_time_ms":1788563195197,"raw_json":"{\"stream\":\"btcusdt@depth@100ms\",\"data\":{\"e\":\"depthUpdate\",\"E\":1788563195197,\"T\":1788563195194,\"s\":\"BTCUSDT\",\"ps\":\"BTCUSDT\",\"U\":11478222587981,\"u\":11478222592098,\"pu\":11478222587764,\"b\":[[\"1000.00\",\"24.604\"],[\"29107.10\",\"0.259\"],[\"29407.10\",\"0.042\"],[\"29507.10\",\"1.799\"],[\"63686.00\",\"0.002\"],[\"71646.30\",\"0.002\"],[\"76422.80\",\"0.000\"],[\"78394.60\",\"0.028\"],[\"78612.00\",\"1.761\"],[\"78811.00\",\"3.492\"],[\"79209.00\",\"0.000\"],[\"79209.10\",\"0.644\"],[\"79236.90\",\"0.247\"],[\"79479.40\",\"0.125\"],[\"79487.70\",\"0.352\"],[\"79491.70\",\"1.279\"],[\"79534.00\",\"23.545\"],[\"79534.10\",\"1.183\"],[\"79536.70\",\"0.000\"]],\"a\":[[\"79607.40\",\"0.128\"],[\"79609.20\",\"0.000\"],[\"79682.80\",\"0.002\"],[\"79688.50\",\"1.938\"],[\"79788.30\",\"0.916\"],[\"79973.40\",\"2.003\"],[\"80403.30\",\"7.055\"],[\"80712.60\",\"10.632\"],[\"80713.70\",\"2.695\"],[\"80721.70\",\"12.000\"],[\"81040.10\",\"0.505\"]],\"st\":1}}"}
{"receive_ns":1788563195203807000,"stream":"btcusdt@bookTicker","event_type":"bookTicker","event_time_ms":1788563195238,"raw_json":"{\"stream\":\"btcusdt@bookTicker\",\"data\":{\"e\":\"bookTicker\",\"u\":11478222593944,\"s\":\"BTCUSDT\",\"ps\":\"BTCUSDT\",\"b\":\"79607.10\",\"B\":\"10.410\",\"a\":\"79607.20\",\"A\":\"1.772\",\"T\":1788563195238,\"E\":1788563195238,\"st\":1}}"}
{"receive_ns":1788563195204080000,"stream":"btcusdt@bookTicker","event_type":"bookTicker","event_time_ms":1788563195239,"raw_json":"{\"stream\":\"btcusdt@bookTicker\",\"data\":{\"e\":\"bookTicker\",\"u\":11478222593967,\"s\":\"BTCUSDT\",\"ps\":\"BTCUSDT\",\"b\":\"79607.10\",\"B\":\"10.391\",\"a\":\"79607.20\",\"A\":\"1.772\",\"T\":1788563195239,\"E\":1788563195239,\"st\":1}}"}
{"receive_ns":1788563195204644000,"stream":"btcusdt@bookTicker","event_type":"bookTicker","event_time_ms":1788563195240,"raw_json":"{\"stream\":\"btcusdt@bookTicker\",\"data\":{\"e\":\"bookTicker\",\"u\":11478222594004,\"s\":\"BTCUSDT\",\"ps\":\"BTCUSDT\",\"b\":\"79607.10\",\"B\":\"10.393\",\"a\":\"79607.20\",\"A\":\"1.772\",\"T\":1788563195239,\"E\":1788563195240,\"st\":1}}"}
{"receive_ns":1788563195204833000,"stream":"btcusdt@bookTicker","event_type":"bookTicker","event_time_ms":1788563195240,"raw_json":"{\"stream\":\"btcusdt@bookTicker\",\"data\":{\"e\":\"bookTicker\",\"u\":11478222594008,\"s\":\"BTCUSDT\",\"ps\":\"BTCUSDT\",\"b\":\"79607.10\",\"B\":\"10.401\",\"a\":\"79607.20\",\"A\":\"1.772\",\"T\":1788563195239,\"E\":1788563195240,\"st\":1}}"}
{"receive_ns":1788563195204994000,"stream":"btcusdt@bookTicker","event_type":"bookTicker","event_time_ms":1788563195240,"raw_json":"{\"stream\":\"btcusdt@bookTicker\",\"data\":{\"e\":\"bookTicker\",\"u\":11478222594046,\"s\":\"BTCUSDT\",\"ps\":\"BTCUSDT\",\"b\":\"79607.10\",\"B\":\"10.420\",\"a\":\"79607.20\",\"A\":\"1.772\",\"T\":1788563195239,\"E\":1788563195240,\"st\":1}}"}
{"receive_ns":1788563195205279000,"stream":"btcusdt@bookTicker","event_type":"bookTicker","event_time_ms":1788563195240,"raw_json":"{\"stream\":\"btcusdt@bookTicker\",\"data\":{\"e\":\"bookTicker\",\"u\":11478222594086,\"s\":\"BTCUSDT\",\"ps\":\"BTCUSDT\",\"b\":\"79607.10\",\"B\":\"10.412\",\"a\":\"79607.20\",\"A\":\"1.772\",\"T\":1788563195240,\"E\":1788563195240,\"st\":1}}"}
{"receive_ns":1788563195205459000,"stream":"btcusdt@bookTicker","event_type":"bookTicker","event_time_ms":1788563195240,"raw_json":"{\"stream\":\"btcusdt@bookTicker\",\"data\":{\"e\":\"bookTicker\",\"u\":11478222594094,\"s\":\"BTCUSDT\",\"ps\":\"BTCUSDT\",\"b\":\"79607.10\",\"B\":\"10.393\",\"a\":\"79607.20\",\"A\":\"1.772\",\"T\":1788563195240,\"E\":1788563195240,\"st\":1}}"}
{"receive_ns":1788563195207454000,"stream":"btcusdt@bookTicker","event_type":"bookTicker","event_time_ms":1788563195241,"raw_json":"{\"stream\":\"btcusdt@bookTicker\",\"data\":{\"e\":\"bookTicker\",\"u\":11478222594155,\"s\":\"BTCUSDT\",\"ps\":\"BTCUSDT\",\"b\":\"79607.10\",\"B\":\"10.393\",\"a\":\"79607.20\",\"A\":\"1.332\",\"T\":1788563195241,\"E\":1788563195241,\"st\":1}}"}
{"receive_ns":1788563195207734000,"stream":"btcusdt@bookTicker","event_type":"bookTicker","event_time_ms":1788563195243,"raw_json":"{\"stream\":\"btcusdt@bookTicker\",\"data\":{\"e\":\"bookTicker\",\"u\":11478222594240,\"s\":\"BTCUSDT\",\"ps\":\"BTCUSDT\",\"b\":\"79607.10\",\"B\":\"10.401\",\"a\":\"79607.20\",\"A\":\"1.332\",\"T\":1788563195242,\"E\":1788563195243,\"st\":1}}"}
{"receive_ns":1788563195207912000,"stream":"btcusdt@bookTicker","event_type":"bookTicker","event_time_ms":1788563195243,"raw_json":"{\"stream\":\"btcusdt@bookTicker\",\"data\":{\"e\":\"bookTicker\",\"u\":11478222594243,\"s\":\"BTCUSDT\",\"ps\":\"BTCUSDT\",\"b\":\"79607.10\",\"B\":\"10.401\",\"a\":\"79607.20\",\"A\":\"1.182\",\"T\":1788563195242,\"E\":1788563195243,\"st\":1}}"}
{"receive_ns":1788563195208064000,"stream":"btcusdt@bookTicker","event_type":"bookTicker","event_time_ms":1788563195243,"raw_json":"{\"stream\":\"btcusdt@bookTicker\",\"data\":{\"e\":\"bookTicker\",\"u\":11478222594257,\"s\":\"BTCUSDT\",\"ps\":\"BTCUSDT\",\"b\":\"79607.10\",\"B\":\"10.420\",\"a\":\"79607.20\",\"A\":\"1.182\",\"T\":1788563195242,\"E\":1788563195243,\"st\":1}}"}
{"receive_ns":1788563195208273000,"stream":"btcusdt@bookTicker","event_type":"bookTicker","event_time_ms":1788563195243,"raw_json":"{\"stream\":\"btcusdt@bookTicker\",\"data\":{\"e\":\"bookTicker\",\"u\":11478222594331,\"s\":\"BTCUSDT\",\"ps\":\"BTCUSDT\",\"b\":\"79607.10\",\"B\":\"10.412\",\"a\":\"79607.20\",\"A\":\"1.182\",\"T\":1788563195243,\"E\":1788563195243,\"st\":1}}"}
{"receive_ns":1788563195208433000,"stream":"btcusdt@bookTicker","event_type":"bookTicker","event_time_ms":1788563195243,"raw_json":"{\"stream\":\"btcusdt@bookTicker\",\"data\":{\"e\":\"bookTicker\",\"u\":11478222594332,\"s\":\"BTCUSDT\",\"ps\":\"BTCUSDT\",\"b\":\"79607.10\",\"B\":\"10.393\",\"a\":\"79607.20\",\"A\":\"1.182\",\"T\":1788563195243,\"E\":1788563195243,\"st\":1}}"}
{"receive_ns":1788563195208862000,"stream":"btcusdt@bookTicker","event_type":"bookTicker","event_time_ms":1788563195244,"raw_json":"{\"stream\":\"btcusdt@bookTicker\",\"data\":{\"e\":\"bookTicker\",\"u\":11478222594383,\"s\":\"BTCUSDT\",\"ps\":\"BTCUSDT\",\"b\":\"79607.10\",\"B\":\"10.393\",\"a\":\"79607.20\",\"A\":\"1.183\",\"T\":1788563195244,\"E\":1788563195244,\"st\":1}}"}
{"receive_ns":1788563195209044000,"stream":"btcusdt@bookTicker","event_type":"bookTicker","event_time_ms":1788563195244,"raw_json":"{\"stream\":\"btcusdt@bookTicker\",\"data\":{\"e\":\"bookTicker\",\"u\":11478222594392,\"s\":\"BTCUSDT\",\"ps\":\"BTCUSDT\",\"b\":\"79607.10\",\"B\":\"10.412\",\"a\":\"79607.20\",\"A\":\"1.183\",\"T\":1788563195244,\"E\":1788563195244,\"st\":1}}"}
{"receive_ns":1788563195209253000,"stream":"btcusdt@bookTicker","event_type":"bookTicker","event_time_ms":1788563195244,"raw_json":"{\"stream\":\"btcusdt@bookTicker\",\"data\":{\"e\":\"bookTicker\",\"u\":11478222594415,\"s\":\"BTCUSDT\",\"ps\":\"BTCUSDT\",\"b\":\"79607.10\",\"B\":\"10.420\",\"a\":\"79607.20\",\"A\":\"1.183\",\"T\":1788563195244,\"E\":1788563195244,\"st\":1}}"}
{"receive_ns":1788563195209408000,"stream":"btcusdt@bookTicker","event_type":"bookTicker","event_time_ms":1788563195244,"raw_json":"{\"stream\":\"btcusdt@bookTicker\",\"data\":{\"e\":\"bookTicker\",\"u\":11478222594445,\"s\":\"BTCUSDT\",\"ps\":\"BTCUSDT\",\"b\":\"79607.10\",\"B\":\"10.420\",\"a\":\"79607.20\",\"A\":\"1.182\",\"T\":1788563195244,\"E\":1788563195244,\"st\":1}}"}
{"receive_ns":1788563195212565000,"stream":"btcusdt@bookTicker","event_type":"bookTicker","event_time_ms":1788563195245,"raw_json":"{\"stream\":\"btcusdt@bookTicker\",\"data\":{\"e\":\"bookTicker\",\"u\":11478222594491,\"s\":\"BTCUSDT\",\"ps\":\"BTCUSDT\",\"b\":\"79607.10\",\"B\":\"10.401\",\"a\":\"79607.20\",\"A\":\"1.182\",\"T\":1788563195245,\"E\":1788563195245,\"st\":1}}"}
{"receive_ns":1788563195212769000,"stream":"btcusdt@bookTicker","event_type":"bookTicker","event_time_ms":1788563195245,"raw_json":"{\"stream\":\"btcusdt@bookTicker\",\"data\":{\"e\":\"bookTicker\",\"u\":11478222594494,\"s\":\"BTCUSDT\",\"ps\":\"BTCUSDT\",\"b\":\"79607.10\",\"B\":\"10.393\",\"a\":\"79607.20\",\"A\":\"1.182\",\"T\":1788563195245,\"E\":1788563195245,\"st\":1}}"}
{"receive_ns":1788563195240507000,"stream":"btcusdt@bookTicker","event_type":"bookTicker","event_time_ms":1788563195276,"raw_json":"{\"stream\":\"btcusdt@bookTicker\",\"data\":{\"e\":\"bookTicker\",\"u\":11478222596059,\"s\":\"BTCUSDT\",\"ps\":\"BTCUSDT\",\"b\":\"79607.10\",\"B\":\"10.396\",\"a\":\"79607.20\",\"A\":\"1.182\",\"T\":1788563195276,\"E\":1788563195276,\"st\":1}}"}
{"receive_ns":1788563195255588000,"stream":"btcusdt@bookTicker","event_type":"bookTicker","event_time_ms":1788563195290,"raw_json":"{\"stream\":\"btcusdt@bookTicker\",\"data\":{\"e\":\"bookTicker\",\"u\":11478222596611,\"s\":\"BTCUSDT\",\"ps\":\"BTCUSDT\",\"b\":\"79607.10\",\"B\":\"10.415\",\"a\":\"79607.20\",\"A\":\"1.182\",\"T\":1788563195290,\"E\":1788563195290,\"st\":1}}"}
{"receive_ns":1788563195255849000,"stream":"btcusdt@bookTicker","event_type":"bookTicker","event_time_ms":1788563195290,"raw_json":"{\"stream\":\"btcusdt@bookTicker\",\"data\":{\"e\":\"bookTicker\",\"u\":11478222596646,\"s\":\"BTCUSDT\",\"ps\":\"BTCUSDT\",\"b\":\"79607.10\",\"B\":\"10.396\",\"a\":\"79607.20\",\"A\":\"1.182\",\"T\":1788563195290,\"E\":1788563195290,\"st\":1}}"}
{"receive_ns":1788563195265416000,"stream":"btcusdt@depth@100ms","event_type":"depthUpdate","event_time_ms":1788563195299,"raw_json":"{\"stream\":\"btcusdt@depth@100ms\",\"data\":{\"e\":\"depthUpdate\",\"E\":1788563195299,\"T\":1788563195298,\"s\":\"BTCUSDT\",\"ps\":\"BTCUSDT\",\"U\":11478222592206,\"u\":11478222596956,\"pu\":11478222592098,\"b\":[[\"1000.00\",\"24.604\"],[\"29107.10\",\"0.140\"],[\"29407.10\",\"0.105\"],[\"29507.10\",\"1.855\"],[\"71646.30\",\"0.002\"],[\"76422.80\",\"0.002\"],[\"78399.70\",\"12.548\"],[\"78574.80\",\"0.018\"],[\"78797.60\",\"0.006\"],[\"78811.00\",\"3.492\"],[\"79209.10\",\"0.644\"],[\"79440.40\",\"2.865\"],[\"79478.70\",\"0.125\"],[\"79479.40\",\"0.000\"],[\"79479.80\",\"0.938\"],[\"79493.70\",\"0.631\"],[\"79516.10\",\"4.989\"],[\"79534.00\",\"0.001\"],[\"79534.90\",\"0.720\"],[\"79536.70\",\"23.544\"],[\"79551.00\",\"0.001\"],[\"79575.30\",\"0.001\"],[\"79576.20\",\"0.001\"],[\"79577.40\",\"0.452\"],[\"79582.20\",\"0.001\"],[\"79582.90\",\"0.000\"],[\"79585.30\",\"0.441\"],[\"79585.70\",\"0.373\"],[\"79600.80\",\"0.005\"],[\"79602.30\",\"0.200\"],[\"79603.60\",\"0.076\"],[\"79606.90\",\"0.032\"],[\"79607.00\",\"0.033\"],[\"79607.10\",\"10.396\"]],\"a\":[[\"79607.20\",\"1.182\"],[\"79607.30\",\"0.002\"],[\"79607.40\",\"0.102\"],[\"79607.60\",\"0.000\"],[\"79607.70\",\"0.000\"],[\"79607.90\",\"0.076\"],[\"79608.10\",\"0.001\"],[\"79608.40\",\"0.249\"],[\"79608.60\",\"0.000\"],[\"79608.80\",\"0.001\"],[\"79608.90\",\"0.000\"],[\"79609.00\",\"0.079\"],[\"79609.20\",\"0.000\"],[\"79609.30\",\"0.001\"],[\"79609.40\",\"0.004\"],[\"79610.00\",\"0.030\"],[\"79610.10\",\"0.001\"],[\"79610.20\",\"0.051\"],[\"79610.30\",\"0.716\"],[\"79610.40\",\"1.346\"],[\"79610.50\",\"0.002\"],[\"79610.60\",\"0.345\"],[\"79610.70\",\"0.029\"],[\"79610.90\",\"0.027\"],[\"79611.00\",\"0.029\"],[\"79611.10\",\"0.103\"],[\"79611.20\",\"0.026\"],[\"79611.30\",\"0.367\"],[\"79611.40\",\"1.322\"],[\"79611.60\",\"0.027\"],[\"79614.60\",\"0.568\"],[\"79615.90\",\"0.003\"],[\"79617.00\",\"0.002\"],[\"79617.30\",\"0.067\"],[\"79620.40\",\"0.000\"],[\"79621.40\",\"0.699\"],[\"79624.60\",\"0.054\"],[\"79624.90\",\"0.002\"],[\"79625.60\",\"0.374\"],[\"79626.00\",\"0.024\"],[\"79626.40\",\"0.000\"],[\"79627.10\",\"0.453\"],[\"79627.90\",\"0.006\"],[\"79639.20\",\"0.062\"],[\"79640.40\",\"0.046\"],[\"79652.60\",\"2.271\"],[\"79652.70\",\"0.000\"],[\"79654.20\",\"9.826\"],[\"79728.60\",\"0.340\"],[\"79768.00\",\"1.948\"],[\"79788.30\",\"0.665\"],[\"79788.80\",\"0.000\"],[\"79973.40\",\"1.059\"],[\"80005.30\",\"0.003\"],[\"80389.60\",\"4.303\"],[\"80403.30\",\"7.055\"],[\"80593.20\",\"2.897\"],[\"80612.50\",\"0.020\"],[\"80787.60\",\"16.333\"],[\"80819.60\",\"0.028\"]],\"st\":1}}"}
{"receive_ns":1788563195333994000,"stream":"btcusdt@bookTicker","event_type":"bookTicker","event_time_ms":1788563195366,"raw_json":"{\"stream\":\"btcusdt@bookTicker\",\"data\":{\"e\":\"bookTicker\",\"u\":11478222600643,\"s\":\"BTCUSDT\",\"ps\":\"BTCUSDT\",\"b\":\"79607.10\",\"B\":\"10.443\",\"a\":\"79607.20\",\"A\":\"1.182\",\"T\":1788563195366,\"E\":1788563195366,\"st\":1}}"}
{"receive_ns":1788563195343293000,"stream":"btcusdt@bookTicker","event_type":"bookTicker","event_time_ms":1788563195377,"raw_json":"{\"stream\":\"btcusdt@bookTicker\",\"data\":{\"e\":\"bookTicker\",\"u\":11478222601087,\"s\":\"BTCUSDT\",\"ps\":\"BTCUSDT\",\"b\":\"79607.10\",\"B\":\"10.430\",\"a\":\"79607.20\",\"A\":\"1.182\",\"T\":1788563195377,\"E\":1788563195377,\"st\":1}}"}
{"receive_ns":1788563195354475000,"stream":"btcusdt@bookTicker","event_type":"bookTicker","event_time_ms":1788563195380,"raw_json":"{\"stream\":\"btcusdt@bookTicker\",\"data\":{\"e\":\"bookTicker\",\"u\":11478222601188,\"s\":\"BTCUSDT\",\"ps\":\"BTCUSDT\",\"b\":\"79607.10\",\"B\":\"10.444\",\"a\":\"79607.20\",\"A\":\"1.182\",\"T\":1788563195380,\"E\":1788563195380,\"st\":1}}"}
{"receive_ns":1788563195374137000,"stream":"btcusdt@depth@100ms","event_type":"depthUpdate","event_time_ms":1788563195401,"raw_json":"{\"stream\":\"btcusdt@depth@100ms\",\"data\":{\"e\":\"depthUpdate\",\"E\":1788563195401,\"T\":1788563195400,\"s\":\"BTCUSDT\",\"ps\":\"BTCUSDT\",\"U\":11478222597010,\"u\":11478222602151,\"pu\":11478222596956,\"b\":[[\"29107.10\",\"0.021\"],[\"29407.10\",\"0.161\"],[\"29507.10\",\"1.918\"],[\"71646.30\",\"0.002\"],[\"71680.00\",\"0.127\"],[\"75626.70\",\"0.019\"],[\"78015.00\",\"0.131\"],[\"78118.40\",\"1.404\"],[\"78492.60\",\"8.143\"],[\"78797.60\",\"0.000\"],[\"78811.00\",\"3.492\"],[\"79491.70\",\"1.581\"],[\"79493.70\",\"1.835\"],[\"79516.10\",\"3.321\"],[\"79583.70\",\"0.779\"],[\"79584.30\",\"0.373\"],[\"79585.30\",\"0.002\"],[\"79585.70\",\"0.000\"],[\"79607.10\",\"10.444\"]],\"a\":[[\"79609.30\",\"0.001\"],[\"79610.00\",\"0.004\"],[\"79788.30\",\"0.665\"],[\"79973.40\",\"2.003\"],[\"80403.30\",\"7.055\"],[\"81199.30\",\"0.024\"],[\"81438.20\",\"0.491\"]],\"st\":1}}"}
{"receive_ns":1788563195467959000,"stream":"btcusdt@depth@100ms","event_type":"depthUpdate","event_time_ms":1788563195503,"raw_json":"{\"stream\":\"btcusdt@depth@100ms\",\"data\":{\"e\":\"depthUpdate\",\"E\":1788563195503,\"T\":1788563195501,\"s\":\"BTCUSDT\",\"ps\":\"BTCUSDT\",\"U\":11478222602303,\"u\":11478222607357,\"pu\":11478222602151,\"b\":[[\"1000.00\",\"24.604\"],[\"29107.10\",\"0.000\"],[\"29407.10\",\"0.322\"],[\"29507.10\",\"1.778\"],[\"71646.30\",\"0.002\"],[\"76422.80\",\"0.000\"],[\"78001.70\",\"0.018\"],[\"78399.70\",\"12.542\"],[\"78454.00\",\"2.832\"],[\"78574.80\",\"0.006\"],[\"78811.00\",\"3.492\"],[\"79209.10\",\"0.644\"],[\"79236.90\",\"0.247\"],[\"79487.70\",\"0.427\"],[\"79491.70\",\"1.506\"],[\"79534.00\",\"23.545\"],[\"79536.70\",\"0.000\"],[\"79571.50\",\"0.176\"]],\"a\":[[\"79610.40\",\"1.372\"],[\"79611.20\",\"0.277\"],[\"79647.90\",\"0.002\"],[\"79650.00\",\"0.195\"],[\"79788.30\",\"0.665\"],[\"79973.40\",\"2.003\"],[\"80389.60\",\"4.291\"],[\"80403.30\",\"7.055\"],[\"80602.30\",\"3.536\"],[\"80612.50\",\"0.014\"],[\"80787.60\",\"16.327\"],[\"81185.60\",\"0.018\"]],\"st\":1}}"}
{"receive_ns":1788563195473112000,"stream":"btcusdt@bookTicker","event_type":"bookTicker","event_time_ms":1788563195508,"raw_json":"{\"stream\":\"btcusdt@bookTicker\",\"data\":{\"e\":\"bookTicker\",\"u\":11478222607615,\"s\":\"BTCUSDT\",\"ps\":\"BTCUSDT\",\"b\":\"79607.10\",\"B\":\"10.144\",\"a\":\"79607.20\",\"A\":\"1.182\",\"T\":1788563195507,\"E\":1788563195508,\"st\":1}}"}
{"receive_ns":1788563195476393000,"stream":"btcusdt@bookTicker","event_type":"bookTicker","event_time_ms":1788563195510,"raw_json":"{\"stream\":\"btcusdt@bookTicker\",\"data\":{\"e\":\"bookTicker\",\"u\":11478222607839,\"s\":\"BTCUSDT\",\"ps\":\"BTCUSDT\",\"b\":\"79607.10\",\"B\":\"10.449\",\"a\":\"79607.20\",\"A\":\"1.182\",\"T\":1788563195510,\"E\":1788563195510,\"st\":1}}"}
{"receive_ns":1788563195524102000,"stream":"btcusdt@bookTicker","event_type":"bookTicker","event_time_ms":1788563195557,"raw_json":"{\"stream\":\"btcusdt@bookTicker\",\"data\":{\"e\":\"bookTicker\",\"u\":11478222610563,\"s\":\"BTCUSDT\",\"ps\":\"BTCUSDT\",\"b\":\"79607.10\",\"B\":\"10.261\",\"a\":\"79607.20\",\"A\":\"1.182\",\"T\":1788563195557,\"E\":1788563195557,\"st\":1}}"}
{"receive_ns":1788563195524375000,"stream":"btcusdt@bookTicker","event_type":"bookTicker","event_time_ms":1788563195560,"raw_json":"{\"stream\":\"btcusdt@bookTicker\",\"data\":{\"e\":\"bookTicker\",\"u\":11478222610715,\"s\":\"BTCUSDT\",\"ps\":\"BTCUSDT\",\"b\":\"79607.10\",\"B\":\"10.450\",\"a\":\"79607.20\",\"A\":\"1.182\",\"T\":1788563195559,\"E\":1788563195560,\"st\":1}}"}
{"receive_ns":1788563195568819000,"stream":"btcusdt@depth@100ms","event_type":"depthUpdate","event_time_ms":1788563195605,"raw_json":"{\"stream\":\"btcusdt@depth@100ms\",\"data\":{\"e\":\"depthUpdate\",\"E\":1788563195605,\"T\":1788563195601,\"s\":\"BTCUSDT\",\"ps\":\"BTCUSDT\",\"U\":11478222607439,\"u\":11478222612987,\"pu\":11478222607357,\"b\":[[\"1000.00\",\"24.604\"],[\"29407.10\",\"0.497\"],[\"29507.10\",\"1.603\"],[\"71646.30\",\"0.002\"],[\"76422.80\",\"0.002\"],[\"78589.80\",\"0.003\"],[\"78600.50\",\"0.000\"],[\"78612.60\",\"1.274\"],[\"78618.70\",\"0.000\"],[\"78811.00\",\"3.492\"],[\"79209.10\",\"0.644\"],[\"79400.70\",\"0.006\"],[\"79448.70\",\"0.001\"],[\"79487.70\",\"0.929\"],[\"79491.70\",\"1.004\"],[\"79493.70\",\"0.631\"],[\"79516.10\",\"4.980\"],[\"79534.90\",\"0.029\"],[\"79601.90\",\"0.005\"],[\"79602.00\",\"0.105\"],[\"79605.70\",\"0.206\"],[\"79607.10\",\"10.450\"]],\"a\":[[\"79788.30\",\"0.466\"],[\"79973.40\",\"1.240\"],[\"80005.30\",\"0.002\"],[\"80403.30\",\"7.055\"]],\"st\":1}}"}
{"receive_ns":1788563195609747000,"stream":"btcusdt@bookTicker","event_type":"bookTicker","event_time_ms":1788563195644,"raw_json":"{\"stream\":\"btcusdt@bookTicker\",\"data\":{\"e\":\"bookTicker\",\"u\":11478222614865,\"s\":\"BTCUSDT\",\"ps\":\"BTCUSDT\",\"b\":\"79607.10\",\"B\":\"10.453\",\"a\":\"79607.20\",\"A\":\"1.182\",\"T\":1788563195644,\"E\":1788563195644,\"st\":1}}"}
{"receive_ns":1788563195659485000,"stream":"btcusdt@bookTicker","event_type":"bookTicker","event_time_ms":1788563195694,"raw_json":"{\"stream\":\"btcusdt@bookTicker\",\"data\":{\"e\":\"bookTicker\",\"u\":11478222617135,\"s\":\"BTCUSDT\",\"ps\":\"BTCUSDT\",\"b\":\"79607.10\",\"B\":\"10.472\",\"a\":\"79607.20\",\"A\":\"1.182\",\"T\":1788563195693,\"E\":1788563195694,\"st\":1}}"}
{"receive_ns":1788563195659760000,"stream":"btcusdt@bookTicker","event_type":"bookTicker","event_time_ms":1788563195694,"raw_json":"{\"stream\":\"btcusdt@bookTicker\",\"data\":{\"e\":\"bookTicker\",\"u\":11478222617192,\"s\":\"BTCUSDT\",\"ps\":\"BTCUSDT\",\"b\":\"79607.10\",\"B\":\"10.453\",\"a\":\"79607.20\",\"A\":\"1.182\",\"T\":1788563195694,\"E\":1788563195694,\"st\":1}}"}
{"receive_ns":1788563195672436000,"stream":"btcusdt@depth@100ms","event_type":"depthUpdate","event_time_ms":1788563195707,"raw_json":"{\"stream\":\"btcusdt@depth@100ms\",\"data\":{\"e\":\"depthUpdate\",\"E\":1788563195707,\"T\":1788563195706,\"s\":\"BTCUSDT\",\"ps\":\"BTCUSDT\",\"U\":11478222613180,\"u\":11478222618018,\"pu\":11478222612987,\"b\":[[\"29407.10\",\"0.679\"],[\"29507.10\",\"1.421\"],[\"63686.00\",\"0.002\"],[\"71646.30\",\"0.002\"],[\"76422.80\",\"0.000\"],[\"78413.00\",\"0.861\"],[\"78452.80\",\"1.807\"],[\"78493.80\",\"0.509\"],[\"78811.00\",\"3.492\"],[\"79209.00\",\"0.001\"],[\"79209.10\",\"0.644\"],[\"79236.90\",\"0.247\"],[\"79453.90\",\"0.555\"],[\"79487.70\",\"0.503\"],[\"79491.70\",\"2.208\"],[\"79493.70\",\"0.706\"],[\"79535.40\",\"0.002\"],[\"79567.80\",\"0.003\"],[\"79571.50\",\"0.583\"],[\"79602.00\",\"0.004\"],[\"79602.10\",\"0.177\"],[\"79607.10\",\"10.453\"]],\"a\":[[\"79611.20\",\"0.277\"],[\"79626.80\",\"0.001\"],[\"79663.00\",\"0.002\"],[\"79788.30\",\"0.665\"],[\"79973.40\",\"2.003\"],[\"80403.30\",\"7.055\"]],\"st\":1}}"}
{"receive_ns":1788563195733480000,"stream":"btcusdt@bookTicker","event_type":"bookTicker","event_time_ms":1788563195760,"raw_json":"{\"stream\":\"btcusdt@bookTicker\",\"data\":{\"e\":\"bookTicker\",\"u\":11478222622298,\"s\":\"BTCUSDT\",\"ps\":\"BTCUSDT\",\"b\":\"79607.10\",\"B\":\"10.453\",\"a\":\"79607.20\",\"A\":\"1.205\",\"T\":1788563195760,\"E\":1788563195760,\"st\":1}}"}
{"receive_ns":1788563195733748000,"stream":"btcusdt@bookTicker","event_type":"bookTicker","event_time_ms":1788563195762,"raw_json":"{\"stream\":\"btcusdt@bookTicker\",\"data\":{\"e\":\"bookTicker\",\"u\":11478222622363,\"s\":\"BTCUSDT\",\"ps\":\"BTCUSDT\",\"b\":\"79607.10\",\"B\":\"10.453\",\"a\":\"79607.20\",\"A\":\"1.204\",\"T\":1788563195761,\"E\":1788563195762,\"st\":1}}"}
{"receive_ns":1788563195758987000,"stream":"btcusdt@bookTicker","event_type":"bookTicker","event_time_ms":1788563195793,"raw_json":"{\"stream\":\"btcusdt@bookTicker\",\"data\":{\"e\":\"bookTicker\",\"u\":11478222624259,\"s\":\"BTCUSDT\",\"ps\":\"BTCUSDT\",\"b\":\"79607.10\",\"B\":\"10.450\",\"a\":\"79607.20\",\"A\":\"1.204\",\"T\":1788563195793,\"E\":1788563195793,\"st\":1}}"}
{"receive_ns":1788563195775251000,"stream":"btcusdt@depth@100ms","event_type":"depthUpdate","event_time_ms":1788563195809,"raw_json":"{\"stream\":\"btcusdt@depth@100ms\",\"data\":{\"e\":\"depthUpdate\",\"E\":1788563195809,\"T\":1788563195807,\"s\":\"BTCUSDT\",\"ps\":\"BTCUSDT\",\"U\":11478222618146,\"u\":11478222624929,\"pu\":11478222618018,\"b\":[[\"1000.00\",\"24.604\"],[\"29407.10\",\"0.854\"],[\"29507.10\",\"1.246\"],[\"71646.30\",\"0.002\"],[\"75626.80\",\"0.006\"],[\"78001.70\",\"0.012\"],[\"78399.70\",\"12.536\"],[\"78574.80\",\"0.000\"],[\"78797.70\",\"8.848\"],[\"78811.00\",\"3.492\"],[\"79479.80\",\"0.340\"],[\"79487.70\",\"1.507\"],[\"79491.70\",\"1.204\"],[\"79607.10\",\"10.450\"]],\"a\":[[\"79607.20\",\"1.204\"],[\"79609.70\",\"0.026\"],[\"79609.90\",\"0.028\"],[\"79611.60\",\"0.001\"],[\"79614.10\",\"0.042\"],[\"79617.40\",\"0.497\"],[\"79702.80\",\"0.008\"],[\"79728.60\",\"0.000\"],[\"79788.30\",\"0.414\"],[\"79973.40\",\"1.913\"],[\"80389.60\",\"4.285\"],[\"80403.30\",\"7.055\"],[\"80612.50\",\"0.008\"],[\"80760.30\",\"0.000\"],[\"80787.60\",\"16.321\"],[\"81185.60\",\"0.012\"]],\"st\":1}}"}
{"receive_ns":1788563195799239000,"stream":"btcusdt@bookTicker","event_type":"bookTicker","event_time_ms":1788563195833,"raw_json":"{\"stream\":\"btcusdt@bookTicker\",\"data\":{\"e\":\"bookTicker\",\"u\":11478222627420,\"s\":\"BTCUSDT\",\"ps\":\"BTCUSDT\",\"b\":\"79607.10\",\"B\":\"10.469\",\"a\":\"79607.20\",\"A\":\"1.204\",\"T\":1788563195833,\"E\":1788563195833,\"st\":1}}"}
{"receive_ns":1788563195799483000,"stream":"btcusdt@bookTicker","event_type":"bookTicker","event_time_ms":1788563195834,"raw_json":"{\"stream\":\"btcusdt@bookTicker\",\"data\":{\"e\":\"bookTicker\",\"u\":11478222627507,\"s\":\"BTCUSDT\",\"ps\":\"BTCUSDT\",\"b\":\"79607.10\",\"B\":\"10.450\",\"a\":\"79607.20\",\"A\":\"1.204\",\"T\":1788563195834,\"E\":1788563195834,\"st\":1}}"}
{"receive_ns":1788563195799699000,"stream":"btcusdt@bookTicker","event_type":"bookTicker","event_time_ms":1788563195835,"raw_json":"{\"stream\":\"btcusdt@bookTicker\",\"data\":{\"e\":\"bookTicker\",\"u\":11478222627589,\"s\":\"BTCUSDT\",\"ps\":\"BTCUSDT\",\"b\":\"79607.10\",\"B\":\"10.448\",\"a\":\"79607.20\",\"A\":\"1.204\",\"T\":1788563195834,\"E\":1788563195835,\"st\":1}}"}
{"receive_ns":1788563195799864000,"stream":"btcusdt@bookTicker","event_type":"bookTicker","event_time_ms":1788563195835,"raw_json":"{\"stream\":\"btcusdt@bookTicker\",\"data\":{\"e\":\"bookTicker\",\"u\":11478222627631,\"s\":\"BTCUSDT\",\"ps\":\"BTCUSDT\",\"b\":\"79607.10\",\"B\":\"10.448\",\"a\":\"79607.20\",\"A\":\"1.205\",\"T\":1788563195834,\"E\":1788563195835,\"st\":1}}"}
{"receive_ns":1788563195850808000,"stream":"btcusdt@bookTicker","event_type":"bookTicker","event_time_ms":1788563195885,"raw_json":"{\"stream\":\"btcusdt@bookTicker\",\"data\":{\"e\":\"bookTicker\",\"u\":11478222632120,\"s\":\"BTCUSDT\",\"ps\":\"BTCUSDT\",\"b\":\"79607.10\",\"B\":\"10.467\",\"a\":\"79607.20\",\"A\":\"1.205\",\"T\":1788563195885,\"E\":1788563195885,\"st\":1}}"}
{"receive_ns":1788563195851148000,"stream":"btcusdt@bookTicker","event_type":"bookTicker","event_time_ms":1788563195886,"raw_json":"{\"stream\":\"btcusdt@bookTicker\",\"data\":{\"e\":\"bookTicker\",\"u\":11478222632279,\"s\":\"BTCUSDT\",\"ps\":\"BTCUSDT\",\"b\":\"79607.10\",\"B\":\"10.469\",\"a\":\"79607.20\",\"A\":\"1.205\",\"T\":1788563195886,\"E\":1788563195886,\"st\":1}}"}
{"receive_ns":1788563195851338000,"stream":"btcusdt@bookTicker","event_type":"bookTicker","event_time_ms":1788563195886,"raw_json":"{\"stream\":\"btcusdt@bookTicker\",\"data\":{\"e\":\"bookTicker\",\"u\":11478222632294,\"s\":\"BTCUSDT\",\"ps\":\"BTCUSDT\",\"b\":\"79607.10\",\"B\":\"10.450\",\"a\":\"79607.20\",\"A\":\"1.205\",\"T\":1788563195886,\"E\":1788563195886,\"st\":1}}"}
{"receive_ns":1788563195867218000,"stream":"btcusdt@bookTicker","event_type":"bookTicker","event_time_ms":1788563195901,"raw_json":"{\"stream\":\"btcusdt@bookTicker\",\"data\":{\"e\":\"bookTicker\",\"u\":11478222633488,\"s\":\"BTCUSDT\",\"ps\":\"BTCUSDT\",\"b\":\"79607.10\",\"B\":\"10.450\",\"a\":\"79607.20\",\"A\":\"1.087\",\"T\":1788563195900,\"E\":1788563195901,\"st\":1}}"}
{"receive_ns":1788563195867455000,"stream":"btcusdt@trade","event_type":"trade","event_time_ms":1788563195901,"raw_json":"{\"stream\":\"btcusdt@trade\",\"data\":{\"e\":\"trade\",\"E\":1788563195901,\"T\":1788563195900,\"s\":\"BTCUSDT\",\"t\":8054082672,\"p\":\"79607.20\",\"q\":\"0.118\",\"X\":\"MARKET\",\"m\":false,\"st\":1}}"}
{"receive_ns":1788563195867668000,"stream":"btcusdt@bookTicker","event_type":"bookTicker","event_time_ms":1788563195902,"raw_json":"{\"stream\":\"btcusdt@bookTicker\",\"data\":{\"e\":\"bookTicker\",\"u\":11478222633630,\"s\":\"BTCUSDT\",\"ps\":\"BTCUSDT\",\"b\":\"79607.10\",\"B\":\"10.469\",\"a\":\"79607.20\",\"A\":\"1.087\",\"T\":1788563195902,\"E\":1788563195902,\"st\":1}}"}
{"receive_ns":1788563195867828000,"stream":"btcusdt@bookTicker","event_type":"bookTicker","event_time_ms":1788563195902,"raw_json":"{\"stream\":\"btcusdt@bookTicker\",\"data\":{\"e\":\"bookTicker\",\"u\":11478222633649,\"s\":\"BTCUSDT\",\"ps\":\"BTCUSDT\",\"b\":\"79607.10\",\"B\":\"10.477\",\"a\":\"79607.20\",\"A\":\"1.087\",\"T\":1788563195902,\"E\":1788563195902,\"st\":1}}"}
{"receive_ns":1788563195868105000,"stream":"btcusdt@bookTicker","event_type":"bookTicker","event_time_ms":1788563195903,"raw_json":"{\"stream\":\"btcusdt@bookTicker\",\"data\":{\"e\":\"bookTicker\",\"u\":11478222633836,\"s\":\"BTCUSDT\",\"ps\":\"BTCUSDT\",\"b\":\"79607.10\",\"B\":\"10.458\",\"a\":\"79607.20\",\"A\":\"1.087\",\"T\":1788563195903,\"E\":1788563195903,\"st\":1}}"}
{"receive_ns":1788563195868290000,"stream":"btcusdt@bookTicker","event_type":"bookTicker","event_time_ms":1788563195903,"raw_json":"{\"stream\":\"btcusdt@bookTicker\",\"data\":{\"e\":\"bookTicker\",\"u\":11478222633838,\"s\":\"BTCUSDT\",\"ps\":\"BTCUSDT\",\"b\":\"79607.10\",\"B\":\"10.450\",\"a\":\"79607.20\",\"A\":\"1.087\",\"T\":1788563195903,\"E\":1788563195903,\"st\":1}}"}
{"receive_ns":1788563195876192000,"stream":"btcusdt@depth@100ms","event_type":"depthUpdate","event_time_ms":1788563195911,"raw_json":"{\"stream\":\"btcusdt@depth@100ms\",\"data\":{\"e\":\"depthUpdate\",\"E\":1788563195911,\"T\":1788563195910,\"s\":\"BTCUSDT\",\"ps\":\"BTCUSDT\",\"U\":11478222625072,\"u\":11478222634750,\"pu\":11478222624929,\"b\":[[\"1000.00\",\"24.604\"],[\"29407.10\",\"1.036\"],[\"29507.10\",\"1.064\"],[\"71646.30\",\"0.002\"],[\"76422.80\",\"0.002\"],[\"78001.70\",\"0.006\"],[\"78483.70\",\"12.165\"],[\"78563.30\",\"6.994\"],[\"78811.00\",\"3.492\"],[\"79209.10\",\"0.513\"],[\"79236.90\",\"0.015\"],[\"79453.90\",\"0.204\"],[\"79479.90\",\"0.677\"],[\"79491.70\",\"1.204\"],[\"79492.40\",\"0.106\"],[\"79493.70\",\"0.631\"],[\"79575.30\",\"0.453\"],[\"79577.40\",\"0.000\"],[\"79579.20\",\"0.002\"],[\"79582.20\",\"0.441\"],[\"79582.80\",\"0.374\"],[\"79583.40\",\"1.875\"],[\"79583.70\",\"0.340\"],[\"79584.30\",\"0.000\"],[\"79591.60\",\"0.069\"],[\"79605.80\",\"0.102\"],[\"79607.10\",\"10.450\"]],\"a\":[[\"79607.20\",\"1.087\"],[\"79607.90\",\"0.000\"],[\"79609.70\",\"0.000\"],[\"79609.90\",\"0.002\"],[\"79610.40\",\"1.346\"],[\"79610.70\",\"0.003\"],[\"79610.90\",\"0.001\"],[\"79611.00\",\"0.003\"],[\"79611.10\",\"0.077\"],[\"79611.20\",\"0.000\"],[\"79611.30\",\"0.341\"],[\"79611.40\",\"1.296\"],[\"79611.60\",\"0.001\"],[\"79611.70\",\"0.003\"],[\"79611.80\",\"0.026\"],[\"79611.90\",\"0.104\"],[\"79612.00\",\"0.281\"],[\"79612.20\",\"0.931\"],[\"79612.30\",\"2.675\"],[\"79612.40\",\"0.027\"],[\"79612.50\",\"0.027\"],[\"79612.60\",\"0.026\"],[\"79612.70\",\"0.036\"],[\"79612.80\",\"0.055\"],[\"79619.00\",\"0.194\"],[\"79620.40\",\"0.439\"],[\"79621.40\",\"0.260\"],[\"79622.70\",\"0.000\"],[\"79623.30\",\"0.045\"],[\"79623.80\",\"0.006\"],[\"79624.80\",\"0.945\"],[\"79625.60\",\"0.002\"],[\"79625.90\",\"0.007\"],[\"79627.90\",\"0.000\"],[\"79637.30\",\"0.003\"],[\"79638.50\",\"0.046\"],[\"79640.40\",\"0.000\"],[\"79658.90\",\"2.177\"],[\"79674.40\",\"0.002\"],[\"79682.40\",\"0.079\"],[\"79728.60\",\"0.340\"],[\"79788.30\",\"0.215\"],[\"79973.40\",\"1.713\"],[\"80204.30\",\"1.245\"],[\"80403.30\",\"7.055\"],[\"80721.70\",\"13.856\"],[\"80976.40\",\"0.502\"],[\"81185.60\",\"0.006\"],[\"81199.30\",\"0.027\"]],\"st\":1}}"}
{"receive_ns":1788563195878464000,"stream":"btcusdt@bookTicker","event_type":"bookTicker","event_time_ms":1788563195912,"raw_json":"{\"stream\":\"btcusdt@bookTicker\",\"data\":{\"e\":\"bookTicker\",\"u\":11478222634997,\"s\":\"BTCUSDT\",\"ps\":\"BTCUSDT\",\"b\":\"79607.10\",\"B\":\"10.469\",\"a\":\"79607.20\",\"A\":\"1.087\",\"T\":1788563195911,\"E\":1788563195912,\"st\":1}}"}
{"receive_ns":1788563195878764000,"stream":"btcusdt@bookTicker","event_type":"bookTicker","event_time_ms":1788563195912,"raw_json":"{\"stream\":\"btcusdt@bookTicker\",\"data\":{\"e\":\"bookTicker\",\"u\":11478222635022,\"s\":\"BTCUSDT\",\"ps\":\"BTCUSDT\",\"b\":\"79607.10\",\"B\":\"10.477\",\"a\":\"79607.20\",\"A\":\"1.087\",\"T\":1788563195912,\"E\":1788563195912,\"st\":1}}"}
{"receive_ns":1788563195879024000,"stream":"btcusdt@bookTicker","event_type":"bookTicker","event_time_ms":1788563195912,"raw_json":"{\"stream\":\"btcusdt@bookTicker\",\"data\":{\"e\":\"bookTicker\",\"u\":11478222635098,\"s\":\"BTCUSDT\",\"ps\":\"BTCUSDT\",\"b\":\"79607.10\",\"B\":\"10.458\",\"a\":\"79607.20\",\"A\":\"1.087\",\"T\":1788563195912,\"E\":1788563195912,\"st\":1}}"}
{"receive_ns":1788563195879192000,"stream":"btcusdt@bookTicker","event_type":"bookTicker","event_time_ms":1788563195912,"raw_json":"{\"stream\":\"btcusdt@bookTicker\",\"data\":{\"e\":\"bookTicker\",\"u\":11478222635110,\"s\":\"BTCUSDT\",\"ps\":\"BTCUSDT\",\"b\":\"79607.10\",\"B\":\"10.450\",\"a\":\"79607.20\",\"A\":\"1.087\",\"T\":1788563195912,\"E\":1788563195912,\"st\":1}}"}
{"receive_ns":1788563195911088000,"stream":"btcusdt@bookTicker","event_type":"bookTicker","event_time_ms":1788563195945,"raw_json":"{\"stream\":\"btcusdt@bookTicker\",\"data\":{\"e\":\"bookTicker\",\"u\":11478222637277,\"s\":\"BTCUSDT\",\"ps\":\"BTCUSDT\",\"b\":\"79607.10\",\"B\":\"10.450\",\"a\":\"79607.20\",\"A\":\"1.076\",\"T\":1788563195945,\"E\":1788563195945,\"st\":1}}"}
{"receive_ns":1788563195911321000,"stream":"btcusdt@trade","event_type":"trade","event_time_ms":1788563195945,"raw_json":"{\"stream\":\"btcusdt@trade\",\"data\":{\"e\":\"trade\",\"E\":1788563195945,\"T\":1788563195945,\"s\":\"BTCUSDT\",\"t\":8054082673,\"p\":\"79607.20\",\"q\":\"0.011\",\"X\":\"MARKET\",\"m\":false,\"st\":1}}"}
{"receive_ns":1788563195911505000,"stream":"btcusdt@bookTicker","event_type":"bookTicker","event_time_ms":1788563195946,"raw_json":"{\"stream\":\"btcusdt@bookTicker\",\"data\":{\"e\":\"bookTicker\",\"u\":11478222637342,\"s\":\"BTCUSDT\",\"ps\":\"BTCUSDT\",\"b\":\"79607.10\",\"B\":\"10.469\",\"a\":\"79607.20\",\"A\":\"1.076\",\"T\":1788563195946,\"E\":1788563195946,\"st\":1}}"}
{"receive_ns":1788563195911685000,"stream":"btcusdt@bookTicker","event_type":"bookTicker","event_time_ms":1788563195946,"raw_json":"{\"stream\":\"btcusdt@bookTicker\",\"data\":{\"e\":\"bookTicker\",\"u\":11478222637413,\"s\":\"BTCUSDT\",\"ps\":\"BTCUSDT\",\"b\":\"79607.10\",\"B\":\"10.477\",\"a\":\"79607.20\",\"A\":\"1.076\",\"T\":1788563195946,\"E\":1788563195946,\"st\":1}}"}
{"receive_ns":1788563195911892000,"stream":"btcusdt@bookTicker","event_type":"bookTicker","event_time_ms":1788563195947,"raw_json":"{\"stream\":\"btcusdt@bookTicker\",\"data\":{\"e\":\"bookTicker\",\"u\":11478222637552,\"s\":\"BTCUSDT\",\"ps\":\"BTCUSDT\",\"b\":\"79607.10\",\"B\":\"10.458\",\"a\":\"79607.20\",\"A\":\"1.076\",\"T\":1788563195946,\"E\":1788563195947,\"st\":1}}"}
{"receive_ns":1788563195912047000,"stream":"btcusdt@bookTicker","event_type":"bookTicker","event_time_ms":1788563195947,"raw_json":"{\"stream\":\"btcusdt@bookTicker\",\"data\":{\"e\":\"bookTicker\",\"u\":11478222637569,\"s\":\"BTCUSDT\",\"ps\":\"BTCUSDT\",\"b\":\"79607.10\",\"B\":\"10.450\",\"a\":\"79607.20\",\"A\":\"1.076\",\"T\":1788563195947,\"E\":1788563195947,\"st\":1}}"}
{"receive_ns":1788563195977643000,"stream":"btcusdt@bookTicker","event_type":"bookTicker","event_time_ms":1788563196009,"raw_json":"{\"stream\":\"btcusdt@bookTicker\",\"data\":{\"e\":\"bookTicker\",\"u\":11478222641338,\"s\":\"BTCUSDT\",\"ps\":\"BTCUSDT\",\"b\":\"79607.10\",\"B\":\"10.447\",\"a\":\"79607.20\",\"A\":\"1.076\",\"T\":1788563196009,\"E\":1788563196009,\"st\":1}}"}
{"receive_ns":1788563195977847000,"stream":"btcusdt@trade","event_type":"trade","event_time_ms":1788563196009,"raw_json":"{\"stream\":\"btcusdt@trade\",\"data\":{\"e\":\"trade\",\"E\":1788563196009,\"T\":1788563196009,\"s\":\"BTCUSDT\",\"t\":8054082674,\"p\":\"79607.10\",\"q\":\"0.003\",\"X\":\"MARKET\",\"m\":true,\"st\":1}}"}
{"receive_ns":1788563195978031000,"stream":"btcusdt@bookTicker","event_type":"bookTicker","event_time_ms":1788563196011,"raw_json":"{\"stream\":\"btcusdt@bookTicker\",\"data\":{\"e\":\"bookTicker\",\"u\":11478222641419,\"s\":\"BTCUSDT\",\"ps\":\"BTCUSDT\",\"b\":\"79607.10\",\"B\":\"10.466\",\"a\":\"79607.20\",\"A\":\"1.076\",\"T\":1788563196010,\"E\":1788563196011,\"st\":1}}"}
{"receive_ns":1788563195978208000,"stream":"btcusdt@bookTicker","event_type":"bookTicker","event_time_ms":1788563196011,"raw_json":"{\"stream\":\"btcusdt@bookTicker\",\"data\":{\"e\":\"bookTicker\",\"u\":11478222641440,\"s\":\"BTCUSDT\",\"ps\":\"BTCUSDT\",\"b\":\"79607.10\",\"B\":\"10.474\",\"a\":\"79607.20\",\"A\":\"1.076\",\"T\":1788563196010,\"E\":1788563196011,\"st\":1}}"}
{"receive_ns":1788563195978379000,"stream":"btcusdt@bookTicker","event_type":"bookTicker","event_time_ms":1788563196011,"raw_json":"{\"stream\":\"btcusdt@bookTicker\",\"data\":{\"e\":\"bookTicker\",\"u\":11478222641516,\"s\":\"BTCUSDT\",\"ps\":\"BTCUSDT\",\"b\":\"79607.10\",\"B\":\"10.466\",\"a\":\"79607.20\",\"A\":\"1.076\",\"T\":1788563196011,\"E\":1788563196011,\"st\":1}}"}
{"receive_ns":1788563195978526000,"stream":"btcusdt@bookTicker","event_type":"bookTicker","event_time_ms":1788563196011,"raw_json":"{\"stream\":\"btcusdt@bookTicker\",\"data\":{\"e\":\"bookTicker\",\"u\":11478222641518,\"s\":\"BTCUSDT\",\"ps\":\"BTCUSDT\",\"b\":\"79607.10\",\"B\":\"10.447\",\"a\":\"79607.20\",\"A\":\"1.076\",\"T\":1788563196011,\"E\":1788563196011,\"st\":1}}"}
{"receive_ns":1788563195978952000,"stream":"btcusdt@depth@100ms","event_type":"depthUpdate","event_time_ms":1788563196013,"raw_json":"{\"stream\":\"btcusdt@depth@100ms\",\"data\":{\"e\":\"depthUpdate\",\"E\":1788563196013,\"T\":1788563196012,\"s\":\"BTCUSDT\",\"ps\":\"BTCUSDT\",\"U\":11478222634861,\"u\":11478222641605,\"pu\":11478222634750,\"b\":[[\"29407.10\",\"1.211\"],[\"29507.10\",\"0.889\"],[\"63685.70\",\"0.001\"],[\"63686.00\",\"0.002\"],[\"71646.30\",\"0.002\"],[\"76422.80\",\"0.000\"],[\"78001.70\",\"0.000\"],[\"78399.70\",\"12.530\"],[\"78811.00\",\"3.492\"],[\"79209.10\",\"0.654\"],[\"79236.90\",\"0.247\"],[\"79325.80\",\"0.180\"],[\"79406.20\",\"0.015\"],[\"79487.70\",\"0.001\"],[\"79491.70\",\"1.630\"],[\"79511.50\",\"0.024\"],[\"79579.80\",\"0.253\"],[\"79590.20\",\"0.002\"],[\"79594.20\",\"0.015\"],[\"79602.10\",\"0.076\"],[\"79602.30\",\"0.200\"],[\"79602.40\",\"0.159\"],[\"79607.10\",\"10.447\"]],\"a\":[[\"79607.20\",\"1.076\"],[\"79607.80\",\"0.077\"],[\"79610.30\",\"0.002\"],[\"79611.20\",\"0.277\"],[\"79611.60\",\"0.027\"],[\"79611.80\",\"0.000\"],[\"79611.90\",\"0.078\"],[\"79612.00\",\"0.029\"],[\"79612.70\",\"0.288\"],[\"79615.20\",\"0.065\"],[\"79615.30\",\"0.702\"],[\"79632.00\",\"1.385\"],[\"79638.50\",\"0.000\"],[\"79639.60\",\"0.047\"],[\"79641.30\",\"0.020\"],[\"79658.90\",\"0.002\"],[\"79678.90\",\"0.018\"],[\"79788.30\",\"0.466\"],[\"79973.40\",\"1.059\"],[\"80403.30\",\"7.057\"],[\"80612.50\",\"0.002\"],[\"80787.60\",\"16.315\"],[\"81185.60\",\"0.000\"]],\"st\":1}}"}
{"receive_ns":1788563196008751000,"stream":"btcusdt@bookTicker","event_type":"bookTicker","event_time_ms":1788563196042,"raw_json":"{\"stream\":\"btcusdt@bookTicker\",\"data\":{\"e\":\"bookTicker\",\"u\":11478222644111,\"s\":\"BTCUSDT\",\"ps\":\"BTCUSDT\",\"b\":\"79607.10\",\"B\":\"10.450\",\"a\":\"79607.20\",\"A\":\"1.076\",\"T\":1788563196042,\"E\":1788563196042,\"st\":1}}"}
{"receive_ns":1788563196079805000,"stream":"btcusdt@depth@100ms","event_type":"depthUpdate","event_time_ms":1788563196115,"raw_json":"{\"stream\":\"btcusdt@depth@100ms\",\"data\":{\"e\":\"depthUpdate\",\"E\":1788563196115,\"T\":1788563196113,\"s\":\"BTCUSDT\",\"ps\":\"BTCUSDT\",\"U\":11478222641615,\"u\":11478222647933,\"pu\":11478222641605,\"b\":[[\"1000.00\",\"24.604\"],[\"29407.10\",\"1.393\"],[\"29507.10\",\"0.707\"],[\"63686.00\",\"0.002\"],[\"71646.30\",\"0.002\"],[\"76422.80\",\"0.002\"],[\"78572.10\",\"0.588\"],[\"78811.00\",\"3.492\"],[\"79204.30\",\"3.087\"],[\"79478.10\",\"0.000\"],[\"79478.20\",\"0.013\"],[\"79487.70\",\"1.507\"],[\"79491.70\",\"1.630\"],[\"79516.10\",\"3.018\"],[\"79534.10\",\"4.515\"],[\"79592.80\",\"0.003\"],[\"79605.80\",\"0.026\"],[\"79607.10\",\"10.450\"]],\"a\":[[\"79609.90\",\"0.028\"],[\"79610.10\",\"0.027\"],[\"79610.30\",\"0.663\"],[\"79611.10\",\"0.103\"],[\"79612.60\",\"0.000\"],[\"79612.70\",\"0.262\"],[\"79612.80\",\"0.029\"],[\"79788.30\",\"0.215\"],[\"79793.60\",\"0.852\"],[\"79973.40\",\"1.913\"],[\"80005.20\",\"1.259\"],[\"80403.30\",\"7.055\"],[\"80729.70\",\"1.236\"]],\"st\":1}}"}
{"receive_ns":1788563196103041000,"stream":"btcusdt@bookTicker","event_type":"bookTicker","event_time_ms":1788563196138,"raw_json":"{\"stream\":\"btcusdt@bookTicker\",\"data\":{\"e\":\"bookTicker\",\"u\":11478222649359,\"s\":\"BTCUSDT\",\"ps\":\"BTCUSDT\",\"b\":\"79607.10\",\"B\":\"10.122\",\"a\":\"79607.20\",\"A\":\"1.076\",\"T\":1788563196138,\"E\":1788563196138,\"st\":1}}"}
{"receive_ns":1788563196107136000,"stream":"btcusdt@bookTicker","event_type":"bookTicker","event_time_ms":1788563196142,"raw_json":"{\"stream\":\"btcusdt@bookTicker\",\"data\":{\"e\":\"bookTicker\",\"u\":11478222649549,\"s\":\"BTCUSDT\",\"ps\":\"BTCUSDT\",\"b\":\"79607.10\",\"B\":\"10.457\",\"a\":\"79607.20\",\"A\":\"1.076\",\"T\":1788563196141,\"E\":1788563196142,\"st\":1}}"}
{"receive_ns":1788563196143299000,"stream":"btcusdt@bookTicker","event_type":"bookTicker","event_time_ms":1788563196178,"raw_json":"{\"stream\":\"btcusdt@bookTicker\",\"data\":{\"e\":\"bookTicker\",\"u\":11478222651499,\"s\":\"BTCUSDT\",\"ps\":\"BTCUSDT\",\"b\":\"79607.10\",\"B\":\"10.152\",\"a\":\"79607.20\",\"A\":\"1.076\",\"T\":1788563196178,\"E\":1788563196178,\"st\":1}}"}
{"receive_ns":1788563196154811000,"stream":"btcusdt@bookTicker","event_type":"bookTicker","event_time_ms":1788563196181,"raw_json":"{\"stream\":\"btcusdt@bookTicker\",\"data\":{\"e\":\"bookTicker\",\"u\":11478222651711,\"s\":\"BTCUSDT\",\"ps\":\"BTCUSDT\",\"b\":\"79607.10\",\"B\":\"10.461\",\"a\":\"79607.20\",\"A\":\"1.076\",\"T\":1788563196181,\"E\":1788563196181,\"st\":1}}"}
{"receive_ns":1788563196181606000,"stream":"btcusdt@depth@100ms","event_type":"depthUpdate","event_time_ms":1788563196217,"raw_json":"{\"stream\":\"btcusdt@depth@100ms\",\"data\":{\"e\":\"depthUpdate\",\"E\":1788563196217,\"T\":1788563196216,\"s\":\"BTCUSDT\",\"ps\":\"BTCUSDT\",\"U\":11478222648025,\"u\":11478222654302,\"pu\":11478222647933,\"b\":[[\"1000.00\",\"24.604\"],[\"29407.10\",\"1.568\"],[\"29507.10\",\"0.532\"],[\"71646.30\",\"0.002\"],[\"76422.80\",\"0.000\"],[\"78269.70\",\"1.019\"],[\"78404.10\",\"7.910\"],[\"78811.00\",\"3.492\"],[\"79209.10\",\"0.644\"],[\"79236.90\",\"0.247\"],[\"79434.00\",\"0.176\"],[\"79453.90\",\"0.455\"],[\"79491.70\",\"1.279\"],[\"79600.20\",\"0.002\"],[\"79600.80\",\"0.003\"],[\"79607.10\",\"10.461\"]],\"a\":[[\"79609.20\",\"0.251\"],[\"79609.90\",\"0.002\"],[\"79610.10\",\"0.001\"],[\"79611.20\",\"0.367\"],[\"79614.10\",\"0.000\"],[\"79617.40\",\"0.392\"],[\"79620.50\",\"2.062\"],[\"79622.70\",\"0.001\"],[\"79688.50\",\"1.939\"],[\"79788.30\",\"0.215\"],[\"79824.60\",\"0.011\"],[\"79872.60\",\"0.055\"],[\"79973.40\",\"1.913\"],[\"80403.30\",\"7.989\"],[\"80557.60\",\"16.030\"],[\"81005.70\",\"0.017\"]],\"st\":1}}"}
{"receive_ns":1788563196201982000,"stream":"btcusdt@bookTicker","event_type":"bookTicker","event_time_ms":1788563196229,"raw_json":"{\"stream\":\"btcusdt@bookTicker\",\"data\":{\"e\":\"bookTicker\",\"u\":11478222655158,\"s\":\"BTCUSDT\",\"ps\":\"BTCUSDT\",\"b\":\"79607.10\",\"B\":\"10.460\",\"a\":\"79607.20\",\"A\":\"1.076\",\"T\":1788563196229,\"E\":1788563196229,\"st\":1}}"}
{"receive_ns":1788563196205666000,"stream":"btcusdt@bookTicker","event_type":"bookTicker","event_time_ms":1788563196242,"raw_json":"{\"stream\":\"btcusdt@bookTicker\",\"data\":{\"e\":\"bookTicker\",\"u\":11478222656085,\"s\":\"BTCUSDT\",\"ps\":\"BTCUSDT\",\"b\":\"79607.10\",\"B\":\"10.457\",\"a\":\"79607.20\",\"A\":\"1.076\",\"T\":1788563196242,\"E\":1788563196242,\"st\":1}}"}
{"receive_ns":1788563196214199000,"stream":"btcusdt@bookTicker","event_type":"bookTicker","event_time_ms":1788563196248,"raw_json":"{\"stream\":\"btcusdt@bookTicker\",\"data\":{\"e\":\"bookTicker\",\"u\":11478222656455,\"s\":\"BTCUSDT\",\"ps\":\"BTCUSDT\",\"b\":\"79607.10\",\"B\":\"10.476\",\"a\":\"79607.20\",\"A\":\"1.076\",\"T\":1788563196248,\"E\":1788563196248,\"st\":1}}"}
{"receive_ns":1788563196214483000,"stream":"btcusdt@bookTicker","event_type":"bookTicker","event_time_ms":1788563196249,"raw_json":"{\"stream\":\"btcusdt@bookTicker\",\"data\":{\"e\":\"bookTicker\",\"u\":11478222656475,\"s\":\"BTCUSDT\",\"ps\":\"BTCUSDT\",\"b\":\"79607.10\",\"B\":\"10.457\",\"a\":\"79607.20\",\"A\":\"1.076\",\"T\":1788563196249,\"E\":1788563196249,\"st\":1}}"}
{"receive_ns":1788563196232095000,"stream":"btcusdt@bookTicker","event_type":"bookTicker","event_time_ms":1788563196266,"raw_json":"{\"stream\":\"btcusdt@bookTicker\",\"data\":{\"e\":\"bookTicker\",\"u\":11478222657515,\"s\":\"BTCUSDT\",\"ps\":\"BTCUSDT\",\"b\":\"79607.10\",\"B\":\"10.458\",\"a\":\"79607.20\",\"A\":\"1.076\",\"T\":1788563196266,\"E\":1788563196266,\"st\":1}}"}
{"receive_ns":1788563196236466000,"stream":"btcusdt@bookTicker","event_type":"bookTicker","event_time_ms":1788563196270,"raw_json":"{\"stream\":\"btcusdt@bookTicker\",\"data\":{\"e\":\"bookTicker\",\"u\":11478222658029,\"s\":\"BTCUSDT\",\"ps\":\"BTCUSDT\",\"b\":\"79607.10\",\"B\":\"10.197\",\"a\":\"79607.20\",\"A\":\"1.076\",\"T\":1788563196270,\"E\":1788563196270,\"st\":1}}"}
{"receive_ns":1788563196239177000,"stream":"btcusdt@bookTicker","event_type":"bookTicker","event_time_ms":1788563196275,"raw_json":"{\"stream\":\"btcusdt@bookTicker\",\"data\":{\"e\":\"bookTicker\",\"u\":11478222658576,\"s\":\"BTCUSDT\",\"ps\":\"BTCUSDT\",\"b\":\"79607.10\",\"B\":\"10.457\",\"a\":\"79607.20\",\"A\":\"1.076\",\"T\":1788563196275,\"E\":1788563196275,\"st\":1}}"}
{"receive_ns":1788563196285010000,"stream":"btcusdt@depth@100ms","event_type":"depthUpdate","event_time_ms":1788563196319,"raw_json":"{\"stream\":\"btcusdt@depth@100ms\",\"data\":{\"e\":\"depthUpdate\",\"E\":1788563196319,\"T\":1788563196318,\"s\":\"BTCUSDT\",\"ps\":\"BTCUSDT\",\"U\":11478222654435,\"u\":11478222661827,\"pu\":11478222654302,\"b\":[[\"29407.10\",\"1.750\"],[\"29507.10\",\"0.350\"],[\"71646.30\",\"0.002\"],[\"78811.00\",\"3.492\"],[\"79209.00\",\"0.002\"],[\"79209.10\",\"1.022\"],[\"79210.10\",\"0.152\"],[\"79453.90\",\"0.957\"],[\"79478.50\",\"0.125\"],[\"79478.70\",\"0.000\"],[\"79478.80\",\"0.250\"],[\"79479.30\",\"0.061\"],[\"79479.90\",\"0.079\"],[\"79480.00\",\"1.123\"],[\"79487.70\",\"1.005\"],[\"79516.10\",\"4.965\"],[\"79534.00\",\"0.001\"],[\"79534.40\",\"0.032\"],[\"79536.70\",\"23.519\"],[\"79587.20\",\"0.012\"],[\"79607.10\",\"10.457\"]],\"a\":[[\"79728.60\",\"0.340\"],[\"79973.40\",\"1.913\"],[\"80005.30\",\"0.001\"],[\"80329.30\",\"0.005\"],[\"80403.30\",\"7.987\"]],\"st\":1}}"}
{"receive_ns":1788563196302913000,"stream":"btcusdt@bookTicker","event_type":"bookTicker","event_time_ms":1788563196336,"raw_json":"{\"stream\":\"btcusdt@bookTicker\",\"data\":{\"e\":\"bookTicker\",\"u\":11478222664101,\"s\":\"BTCUSDT\",\"ps\":\"BTCUSDT\",\"b\":\"79607.10\",\"B\":\"10.457\",\"a\":\"79607.20\",\"A\":\"0.851\",\"T\":1788563196336,\"E\":1788563196336,\"st\":1}}"}
{"receive_ns":1788563196303165000,"stream":"btcusdt@trade","event_type":"trade","event_time_ms":1788563196336,"raw_json":"{\"stream\":\"btcusdt@trade\",\"data\":{\"e\":\"trade\",\"E\":1788563196336,\"T\":1788563196336,\"s\":\"BTCUSDT\",\"t\":8054082675,\"p\":\"79607.20\",\"q\":\"0.225\",\"X\":\"MARKET\",\"m\":false,\"st\":1}}"}
{"receive_ns":1788563196304568000,"stream":"btcusdt@bookTicker","event_type":"bookTicker","event_time_ms":1788563196337,"raw_json":"{\"stream\":\"btcusdt@bookTicker\",\"data\":{\"e\":\"bookTicker\",\"u\":11478222664241,\"s\":\"BTCUSDT\",\"ps\":\"BTCUSDT\",\"b\":\"79607.10\",\"B\":\"10.465\",\"a\":\"79607.20\",\"A\":\"0.851\",\"T\":1788563196337,\"E\":1788563196337,\"st\":1}}"}
{"receive_ns":1788563196304749000,"stream":"btcusdt@bookTicker","event_type":"bookTicker","event_time_ms":1788563196337,"raw_json":"{\"stream\":\"btcusdt@bookTicker\",\"data\":{\"e\":\"bookTicker\",\"u\":11478222664263,\"s\":\"BTCUSDT\",\"ps\":\"BTCUSDT\",\"b\":\"79607.10\",\"B\":\"10.484\",\"a\":\"79607.20\",\"A\":\"0.851\",\"T\":1788563196337,\"E\":1788563196337,\"st\":1}}"}
{"receive_ns":1788563196304901000,"stream":"btcusdt@bookTicker","event_type":"bookTicker","event_time_ms":1788563196337,"raw_json":"{\"stream\":\"btcusdt@bookTicker\",\"data\":{\"e\":\"bookTicker\",\"u\":11478222664339,\"s\":\"BTCUSDT\",\"ps\":\"BTCUSDT\",\"b\":\"79607.10\",\"B\":\"10.503\",\"a\":\"79607.20\",\"A\":\"0.851\",\"T\":1788563196337,\"E\":1788563196337,\"st\":1}}"}
{"receive_ns":1788563196305070000,"stream":"btcusdt@bookTicker","event_type":"bookTicker","event_time_ms":1788563196338,"raw_json":"{\"stream\":\"btcusdt@bookTicker\",\"data\":{\"e\":\"bookTicker\",\"u\":11478222664430,\"s\":\"BTCUSDT\",\"ps\":\"BTCUSDT\",\"b\":\"79607.10\",\"B\":\"10.484\",\"a\":\"79607.20\",\"A\":\"0.851\",\"T\":1788563196338,\"E\":1788563196338,\"st\":1}}"}
{"receive_ns":1788563196305218000,"stream":"btcusdt@bookTicker","event_type":"bookTicker","event_time_ms":1788563196338,"raw_json":"{\"stream\":\"btcusdt@bookTicker\",\"data\":{\"e\":\"bookTicker\",\"u\":11478222664453,\"s\":\"BTCUSDT\",\"ps\":\"BTCUSDT\",\"b\":\"79607.10\",\"B\":\"10.476\",\"a\":\"79607.20\",\"A\":\"0.851\",\"T\":1788563196338,\"E\":1788563196338,\"st\":1}}"}
{"receive_ns":1788563196305359000,"stream":"btcusdt@bookTicker","event_type":"bookTicker","event_time_ms":1788563196338,"raw_json":"{\"stream\":\"btcusdt@bookTicker\",\"data\":{\"e\":\"bookTicker\",\"u\":11478222664470,\"s\":\"BTCUSDT\",\"ps\":\"BTCUSDT\",\"b\":\"79607.10\",\"B\":\"10.457\",\"a\":\"79607.20\",\"A\":\"0.851\",\"T\":1788563196338,\"E\":1788563196338,\"st\":1}}"}
{"receive_ns":1788563196305522000,"stream":"btcusdt@bookTicker","event_type":"bookTicker","event_time_ms":1788563196339,"raw_json":"{\"stream\":\"btcusdt@bookTicker\",\"data\":{\"e\":\"bookTicker\",\"u\":11478222664563,\"s\":\"BTCUSDT\",\"ps\":\"BTCUSDT\",\"b\":\"79607.10\",\"B\":\"10.457\",\"a\":\"79607.20\",\"A\":\"1.066\",\"T\":1788563196339,\"E\":1788563196339,\"st\":1}}"}
{"receive_ns":1788563196305687000,"stream":"btcusdt@bookTicker","event_type":"bookTicker","event_time_ms":1788563196340,"raw_json":"{\"stream\":\"btcusdt@bookTicker\",\"data\":{\"e\":\"bookTicker\",\"u\":11478222664777,\"s\":\"BTCUSDT\",\"ps\":\"BTCUSDT\",\"b\":\"79607.10\",\"B\":\"10.476\",\"a\":\"79607.20\",\"A\":\"1.066\",\"T\":1788563196340,\"E\":1788563196340,\"st\":1}}"}
{"receive_ns":1788563196305834000,"stream":"btcusdt@bookTicker","event_type":"bookTicker","event_time_ms":1788563196340,"raw_json":"{\"stream\":\"btcusdt@bookTicker\",\"data\":{\"e\":\"bookTicker\",\"u\":11478222664800,\"s\":\"BTCUSDT\",\"ps\":\"BTCUSDT\",\"b\":\"79607.10\",\"B\":\"10.476\",\"a\":\"79607.20\",\"A\":\"1.065\",\"T\":1788563196340,\"E\":1788563196340,\"st\":1}}"}
{"receive_ns":1788563196305975000,"stream":"btcusdt@bookTicker","event_type":"bookTicker","event_time_ms":1788563196340,"raw_json":"{\"stream\":\"btcusdt@bookTicker\",\"data\":{\"e\":\"bookTicker\",\"u\":11478222664816,\"s\":\"BTCUSDT\",\"ps\":\"BTCUSDT\",\"b\":\"79607.10\",\"B\":\"10.484\",\"a\":\"79607.20\",\"A\":\"1.065\",\"T\":1788563196340,\"E\":1788563196340,\"st\":1}}"}
{"receive_ns":1788563196313898000,"stream":"btcusdt@bookTicker","event_type":"bookTicker","event_time_ms":1788563196341,"raw_json":"{\"stream\":\"btcusdt@bookTicker\",\"data\":{\"e\":\"bookTicker\",\"u\":11478222664945,\"s\":\"BTCUSDT\",\"ps\":\"BTCUSDT\",\"b\":\"79607.10\",\"B\":\"10.476\",\"a\":\"79607.20\",\"A\":\"1.065\",\"T\":1788563196341,\"E\":1788563196341,\"st\":1}}"}
{"receive_ns":1788563196314089000,"stream":"btcusdt@bookTicker","event_type":"bookTicker","event_time_ms":1788563196341,"raw_json":"{\"stream\":\"btcusdt@bookTicker\",\"data\":{\"e\":\"bookTicker\",\"u\":11478222664956,\"s\":\"BTCUSDT\",\"ps\":\"BTCUSDT\",\"b\":\"79607.10\",\"B\":\"10.457\",\"a\":\"79607.20\",\"A\":\"1.065\",\"T\":1788563196341,\"E\":1788563196341,\"st\":1}}"}
{"receive_ns":1788563196314263000,"stream":"btcusdt@bookTicker","event_type":"bookTicker","event_time_ms":1788563196341,"raw_json":"{\"stream\":\"btcusdt@bookTicker\",\"data\":{\"e\":\"bookTicker\",\"u\":11478222664994,\"s\":\"BTCUSDT\",\"ps\":\"BTCUSDT\",\"b\":\"79607.10\",\"B\":\"10.457\",\"a\":\"79607.20\",\"A\":\"1.066\",\"T\":1788563196341,\"E\":1788563196341,\"st\":1}}"}
{"receive_ns":1788563196360752000,"stream":"btcusdt@bookTicker","event_type":"bookTicker","event_time_ms":1788563196367,"raw_json":"{\"stream\":\"btcusdt@bookTicker\",\"data\":{\"e\":\"bookTicker\",\"u\":11478222667129,\"s\":\"BTCUSDT\",\"ps\":\"BTCUSDT\",\"b\":\"79607.10\",\"B\":\"10.268\",\"a\":\"79607.20\",\"A\":\"1.066\",\"T\":1788563196367,\"E\":1788563196367,\"st\":1}}"}
{"receive_ns":1788563196361000000,"stream":"btcusdt@bookTicker","event_type":"bookTicker","event_time_ms":1788563196371,"raw_json":"{\"stream\":\"btcusdt@bookTicker\",\"data\":{\"e\":\"bookTicker\",\"u\":11478222667404,\"s\":\"BTCUSDT\",\"ps\":\"BTCUSDT\",\"b\":\"79607.10\",\"B\":\"10.460\",\"a\":\"79607.20\",\"A\":\"1.066\",\"T\":1788563196371,\"E\":1788563196371,\"st\":1}}"}
{"receive_ns":1788563196361220000,"stream":"btcusdt@bookTicker","event_type":"bookTicker","event_time_ms":1788563196392,"raw_json":"{\"stream\":\"btcusdt@bookTicker\",\"data\":{\"e\":\"bookTicker\",\"u\":11478222668469,\"s\":\"BTCUSDT\",\"ps\":\"BTCUSDT\",\"b\":\"79607.10\",\"B\":\"9.983\",\"a\":\"79607.20\",\"A\":\"1.066\",\"T\":1788563196392,\"E\":1788563196392,\"st\":1}}"}
{"receive_ns":1788563196365470000,"stream":"btcusdt@bookTicker","event_type":"bookTicker","event_time_ms":1788563196401,"raw_json":"{\"stream\":\"btcusdt@bookTicker\",\"data\":{\"e\":\"bookTicker\",\"u\":11478222669044,\"s\":\"BTCUSDT\",\"ps\":\"BTCUSDT\",\"b\":\"79607.10\",\"B\":\"9.776\",\"a\":\"79607.20\",\"A\":\"1.066\",\"T\":1788563196401,\"E\":1788563196401,\"st\":1}}"}
{"receive_ns":1788563196366735000,"stream":"btcusdt@bookTicker","event_type":"bookTicker","event_time_ms":1788563196403,"raw_json":"{\"stream\":\"btcusdt@bookTicker\",\"data\":{\"e\":\"bookTicker\",\"u\":11478222669228,\"s\":\"BTCUSDT\",\"ps\":\"BTCUSDT\",\"b\":\"79607.10\",\"B\":\"10.257\",\"a\":\"79607.20\",\"A\":\"1.066\",\"T\":1788563196403,\"E\":1788563196403,\"st\":1}}"}
{"receive_ns":1788563196369300000,"stream":"btcusdt@bookTicker","event_type":"bookTicker","event_time_ms":1788563196405,"raw_json":"{\"stream\":\"btcusdt@bookTicker\",\"data\":{\"e\":\"bookTicker\",\"u\":11478222669343,\"s\":\"BTCUSDT\",\"ps\":\"BTCUSDT\",\"b\":\"79607.10\",\"B\":\"10.469\",\"a\":\"79607.20\",\"A\":\"1.066\",\"T\":1788563196405,\"E\":1788563196405,\"st\":1}}"}
{"receive_ns":1788563196369566000,"stream":"btcusdt@bookTicker","event_type":"bookTicker","event_time_ms":1788563196406,"raw_json":"{\"stream\":\"btcusdt@bookTicker\",\"data\":{\"e\":\"bookTicker\",\"u\":11478222669479,\"s\":\"BTCUSDT\",\"ps\":\"BTCUSDT\",\"b\":\"79607.10\",\"B\":\"10.467\",\"a\":\"79607.20\",\"A\":\"1.066\",\"T\":1788563196406,\"E\":1788563196406,\"st\":1}}"}
{"receive_ns":1788563196394091000,"stream":"btcusdt@depth@100ms","event_type":"depthUpdate","event_time_ms":1788563196421,"raw_json":"{\"stream\":\"btcusdt@depth@100ms\",\"data\":{\"e\":\"depthUpdate\",\"E\":1788563196421,\"T\":1788563196417,\"s\":\"BTCUSDT\",\"ps\":\"BTCUSDT\",\"U\":11478222662393,\"u\":11478222670306,\"pu\":11478222661827,\"b\":[[\"1000.00\",\"24.604\"],[\"29307.10\",\"0.056\"],[\"29407.10\",\"1.813\"],[\"29507.10\",\"0.231\"],[\"71646.30\",\"0.002\"],[\"71680.00\",\"0.130\"],[\"75626.80\",\"0.004\"],[\"76422.80\",\"0.002\"],[\"78015.00\",\"0.125\"],[\"78678.30\",\"0.914\"],[\"78811.00\",\"3.492\"],[\"79005.30\",\"1.896\"],[\"79209.10\",\"1.022\"],[\"79236.90\",\"0.247\"],[\"79434.00\",\"0.076\"],[\"79453.90\",\"0.706\"],[\"79487.70\",\"1.356\"],[\"79491.70\",\"1.279\"],[\"79534.00\",\"23.520\"],[\"79534.10\",\"1.183\"],[\"79536.70\",\"0.000\"],[\"79563.10\",\"0.005\"],[\"79581.40\",\"2.323\"],[\"79582.10\",\"9.935\"],[\"79585.20\",\"0.002\"],[\"79585.30\",\"0.630\"],[\"79588.60\",\"0.005\"],[\"79588.70\",\"1.305\"],[\"79591.40\",\"1.415\"],[\"79591.60\",\"0.069\"],[\"79593.20\",\"0.203\"],[\"79601.20\",\"0.105\"],[\"79602.40\",\"0.058\"],[\"79603.00\",\"0.001\"],[\"79607.00\",\"0.109\"],[\"79607.10\",\"10.467\"]],\"a\":[[\"79607.20\",\"1.066\"],[\"79607.80\",\"0.001\"],[\"79609.00\",\"0.003\"],[\"79609.20\",\"0.000\"],[\"79610.30\",\"0.613\"],[\"79611.10\",\"0.077\"],[\"79611.20\",\"0.251\"],[\"79611.50\",\"0.596\"],[\"79611.60\",\"0.027\"],[\"79611.70\",\"0.003\"],[\"79611.90\",\"0.104\"],[\"79612.00\",\"0.003\"],[\"79612.20\",\"0.905\"],[\"79612.30\",\"2.649\"],[\"79612.40\",\"0.001\"],[\"79612.50\",\"0.001\"],[\"79612.60\",\"0.026\"],[\"79612.90\",\"0.027\"],[\"79613.10\",\"0.028\"],[\"79613.20\",\"0.026\"],[\"79613.30\",\"0.029\"],[\"79613.40\",\"0.105\"],[\"79613.50\",\"0.026\"],[\"79613.60\",\"0.005\"],[\"79613.80\",\"0.000\"],[\"79614.70\",\"0.000\"],[\"79615.30\",\"0.702\"],[\"79615.70\",\"0.002\"],[\"79652.60\",\"2.272\"],[\"79653.00\",\"0.001\"],[\"79788.30\",\"0.665\"],[\"79881.50\",\"0.080\"],[\"79929.60\",\"0.007\"],[\"79973.40\",\"2.003\"],[\"80005.20\",\"1.384\"],[\"80403.30\",\"7.987\"],[\"80562.50\",\"13.577\"],[\"81199.30\",\"0.030\"]],\"st\":1}}"}
{"receive_ns":1788563196394549000,"stream":"btcusdt@bookTicker","event_type":"bookTicker","event_time_ms":1788563196430,"raw_json":"{\"stream\":\"btcusdt@bookTicker\",\"data\":{\"e\":\"bookTicker\",\"u\":11478222670963,\"s\":\"BTCUSDT\",\"ps\":\"BTCUSDT\",\"b\":\"79607.10\",\"B\":\"10.486\",\"a\":\"79607.20\",\"A\":\"1.066\",\"T\":1788563196430,\"E\":1788563196430,\"st\":1}}"}
{"receive_ns":1788563196394795000,"stream":"btcusdt@bookTicker","event_type":"bookTicker","event_time_ms":1788563196431,"raw_json":"{\"stream\":\"btcusdt@bookTicker\",\"data\":{\"e\":\"bookTicker\",\"u\":11478222671002,\"s\":\"BTCUSDT\",\"ps\":\"BTCUSDT\",\"b\":\"79607.10\",\"B\":\"10.467\",\"a\":\"79607.20\",\"A\":\"1.066\",\"T\":1788563196431,\"E\":1788563196431,\"st\":1}}"}
{"receive_ns":1788563196395791000,"stream":"btcusdt@bookTicker","event_type":"bookTicker","event_time_ms":1788563196432,"raw_json":"{\"stream\":\"btcusdt@bookTicker\",\"data\":{\"e\":\"bookTicker\",\"u\":11478222671057,\"s\":\"BTCUSDT\",\"ps\":\"BTCUSDT\",\"b\":\"79607.10\",\"B\":\"10.469\",\"a\":\"79607.20\",\"A\":\"1.066\",\"T\":1788563196431,\"E\":1788563196432,\"st\":1}}"}
{"receive_ns":1788563196427077000,"stream":"btcusdt@bookTicker","event_type":"bookTicker","event_time_ms":1788563196462,"raw_json":"{\"stream\":\"btcusdt@bookTicker\",\"data\":{\"e\":\"bookTicker\",\"u\":11478222672571,\"s\":\"BTCUSDT\",\"ps\":\"BTCUSDT\",\"b\":\"79607.10\",\"B\":\"10.488\",\"a\":\"79607.20\",\"A\":\"1.066\",\"T\":1788563196462,\"E\":1788563196462,\"st\":1}}"}
{"receive_ns":1788563196427312000,"stream":"btcusdt@bookTicker","event_type":"bookTicker","event_time_ms":1788563196462,"raw_json":"{\"stream\":\"btcusdt@bookTicker\",\"data\":{\"e\":\"bookTicker\",\"u\":11478222672649,\"s\":\"BTCUSDT\",\"ps\":\"BTCUSDT\",\"b\":\"79607.10\",\"B\":\"10.469\",\"a\":\"79607.20\",\"A\":\"1.066\",\"T\":1788563196462,\"E\":1788563196462,\"st\":1}}"}
{"receive_ns":1788563196427523000,"stream":"btcusdt@bookTicker","event_type":"bookTicker","event_time_ms":1788563196463,"raw_json":"{\"stream\":\"btcusdt@bookTicker\",\"data\":{\"e\":\"bookTicker\",\"u\":11478222672767,\"s\":\"BTCUSDT\",\"ps\":\"BTCUSDT\",\"b\":\"79607.10\",\"B\":\"10.488\",\"a\":\"79607.20\",\"A\":\"1.066\",\"T\":1788563196463,\"E\":1788563196463,\"st\":1}}"}
{"receive_ns":1788563196427680000,"stream":"btcusdt@bookTicker","event_type":"bookTicker","event_time_ms":1788563196463,"raw_json":"{\"stream\":\"btcusdt@bookTicker\",\"data\":{\"e\":\"bookTicker\",\"u\":11478222672787,\"s\":\"BTCUSDT\",\"ps\":\"BTCUSDT\",\"b\":\"79607.10\",\"B\":\"11.528\",\"a\":\"79607.20\",\"A\":\"1.066\",\"T\":1788563196463,\"E\":1788563196463,\"st\":1}}"}
{"receive_ns":1788563196428252000,"stream":"btcusdt@bookTicker","event_type":"bookTicker","event_time_ms":1788563196464,"raw_json":"{\"stream\":\"btcusdt@bookTicker\",\"data\":{\"e\":\"bookTicker\",\"u\":11478222672855,\"s\":\"BTCUSDT\",\"ps\":\"BTCUSDT\",\"b\":\"79607.10\",\"B\":\"11.509\",\"a\":\"79607.20\",\"A\":\"1.066\",\"T\":1788563196464,\"E\":1788563196464,\"st\":1}}"}
{"receive_ns":1788563196428483000,"stream":"btcusdt@bookTicker","event_type":"bookTicker","event_time_ms":1788563196464,"raw_json":"{\"stream\":\"btcusdt@bookTicker\",\"data\":{\"e\":\"bookTicker\",\"u\":11478222672867,\"s\":\"BTCUSDT\",\"ps\":\"BTCUSDT\",\"b\":\"79607.10\",\"B\":\"11.507\",\"a\":\"79607.20\",\"A\":\"1.066\",\"T\":1788563196464,\"E\":1788563196464,\"st\":1}}"}
{"receive_ns":1788563196428644000,"stream":"btcusdt@bookTicker","event_type":"bookTicker","event_time_ms":1788563196464,"raw_json":"{\"stream\":\"btcusdt@bookTicker\",\"data\":{\"e\":\"bookTicker\",\"u\":11478222672904,\"s\":\"BTCUSDT\",\"ps\":\"BTCUSDT\",\"b\":\"79607.10\",\"B\":\"11.526\",\"a\":\"79607.20\",\"A\":\"1.066\",\"T\":1788563196464,\"E\":1788563196464,\"st\":1}}"}
{"receive_ns":1788563196428793000,"stream":"btcusdt@bookTicker","event_type":"bookTicker","event_time_ms":1788563196464,"raw_json":"{\"stream\":\"btcusdt@bookTicker\",\"data\":{\"e\":\"bookTicker\",\"u\":11478222672905,\"s\":\"BTCUSDT\",\"ps\":\"BTCUSDT\",\"b\":\"79607.10\",\"B\":\"11.534\",\"a\":\"79607.20\",\"A\":\"1.066\",\"T\":1788563196464,\"E\":1788563196464,\"st\":1}}"}
{"receive_ns":1788563196429640000,"stream":"btcusdt@bookTicker","event_type":"bookTicker","event_time_ms":1788563196465,"raw_json":"{\"stream\":\"btcusdt@bookTicker\",\"data\":{\"e\":\"bookTicker\",\"u\":11478222673011,\"s\":\"BTCUSDT\",\"ps\":\"BTCUSDT\",\"b\":\"79607.10\",\"B\":\"11.515\",\"a\":\"79607.20\",\"A\":\"1.066\",\"T\":1788563196465,\"E\":1788563196465,\"st\":1}}"}
{"receive_ns":1788563196429898000,"stream":"btcusdt@bookTicker","event_type":"bookTicker","event_time_ms":1788563196465,"raw_json":"{\"stream\":\"btcusdt@bookTicker\",\"data\":{\"e\":\"bookTicker\",\"u\":11478222673026,\"s\":\"BTCUSDT\",\"ps\":\"BTCUSDT\",\"b\":\"79607.10\",\"B\":\"11.507\",\"a\":\"79607.20\",\"A\":\"1.066\",\"T\":1788563196465,\"E\":1788563196465,\"st\":1}}"}
{"receive_ns":1788563196430064000,"stream":"btcusdt@bookTicker","event_type":"bookTicker","event_time_ms":1788563196465,"raw_json":"{\"stream\":\"btcusdt@bookTicker\",\"data\":{\"e\":\"bookTicker\",\"u\":11478222673041,\"s\":\"BTCUSDT\",\"ps\":\"BTCUSDT\",\"b\":\"79607.10\",\"B\":\"10.467\",\"a\":\"79607.20\",\"A\":\"1.066\",\"T\":1788563196465,\"E\":1788563196465,\"st\":1}}"}
{"receive_ns":1788563196430227000,"stream":"btcusdt@bookTicker","event_type":"bookTicker","event_time_ms":1788563196465,"raw_json":"{\"stream\":\"btcusdt@bookTicker\",\"data\":{\"e\":\"bookTicker\",\"u\":11478222673064,\"s\":\"BTCUSDT\",\"ps\":\"BTCUSDT\",\"b\":\"79607.10\",\"B\":\"10.469\",\"a\":\"79607.20\",\"A\":\"1.066\",\"T\":1788563196465,\"E\":1788563196465,\"st\":1}}"}
{"receive_ns":1788563196446266000,"stream":"btcusdt@bookTicker","event_type":"bookTicker","event_time_ms":1788563196482,"raw_json":"{\"stream\":\"btcusdt@bookTicker\",\"data\":{\"e\":\"bookTicker\",\"u\":11478222674216,\"s\":\"BTCUSDT\",\"ps\":\"BTCUSDT\",\"b\":\"79607.10\",\"B\":\"10.488\",\"a\":\"79607.20\",\"A\":\"1.066\",\"T\":1788563196482,\"E\":1788563196482,\"st\":1}}"}
{"receive_ns":1788563196446481000,"stream":"btcusdt@bookTicker","event_type":"bookTicker","event_time_ms":1788563196483,"raw_json":"{\"stream\":\"btcusdt@bookTicker\",\"data\":{\"e\":\"bookTicker\",\"u\":11478222674241,\"s\":\"BTCUSDT\",\"ps\":\"BTCUSDT\",\"b\":\"79607.10\",\"B\":\"10.469\",\"a\":\"79607.20\",\"A\":\"1.066\",\"T\":1788563196483,\"E\":1788563196483,\"st\":1}}"}
{"receive_ns":1788563196446691000,"stream":"btcusdt@bookTicker","event_type":"bookTicker","event_time_ms":1788563196484,"raw_json":"{\"stream\":\"btcusdt@bookTicker\",\"data\":{\"e\":\"bookTicker\",\"u\":11478222674282,\"s\":\"BTCUSDT\",\"ps\":\"BTCUSDT\",\"b\":\"79607.10\",\"B\":\"10.488\",\"a\":\"79607.20\",\"A\":\"1.066\",\"T\":1788563196483,\"E\":1788563196484,\"st\":1}}"}
{"receive_ns":1788563196446848000,"stream":"btcusdt@bookTicker","event_type":"bookTicker","event_time_ms":1788563196484,"raw_json":"{\"stream\":\"btcusdt@bookTicker\",\"data\":{\"e\":\"bookTicker\",\"u\":11478222674313,\"s\":\"BTCUSDT\",\"ps\":\"BTCUSDT\",\"b\":\"79607.10\",\"B\":\"10.496\",\"a\":\"79607.20\",\"A\":\"1.066\",\"T\":1788563196483,\"E\":1788563196484,\"st\":1}}"}
{"receive_ns":1788563196447440000,"stream":"btcusdt@bookTicker","event_type":"bookTicker","event_time_ms":1788563196484,"raw_json":"{\"stream\":\"btcusdt@bookTicker\",\"data\":{\"e\":\"bookTicker\",\"u\":11478222674398,\"s\":\"BTCUSDT\",\"ps\":\"BTCUSDT\",\"b\":\"79607.10\",\"B\":\"10.477\",\"a\":\"79607.20\",\"A\":\"1.066\",\"T\":1788563196484,\"E\":1788563196484,\"st\":1}}"}
{"receive_ns":1788563196447619000,"stream":"btcusdt@bookTicker","event_type":"bookTicker","event_time_ms":1788563196484,"raw_json":"{\"stream\":\"btcusdt@bookTicker\",\"data\":{\"e\":\"bookTicker\",\"u\":11478222674413,\"s\":\"BTCUSDT\",\"ps\":\"BTCUSDT\",\"b\":\"79607.10\",\"B\":\"10.469\",\"a\":\"79607.20\",\"A\":\"1.066\",\"T\":1788563196484,\"E\":1788563196484,\"st\":1}}"}
{"receive_ns":1788563196487952000,"stream":"btcusdt@depth@100ms","event_type":"depthUpdate","event_time_ms":1788563196523,"raw_json":"{\"stream\":\"btcusdt@depth@100ms\",\"data\":{\"e\":\"depthUpdate\",\"E\":1788563196523,\"T\":1788563196522,\"s\":\"BTCUSDT\",\"ps\":\"BTCUSDT\",\"U\":11478222670564,\"u\":11478222676823,\"pu\":11478222670306,\"b\":[[\"1000.00\",\"24.604\"],[\"29307.10\",\"0.119\"],[\"29407.10\",\"1.869\"],[\"29507.10\",\"0.112\"],[\"71646.30\",\"0.002\"],[\"71680.00\",\"0.127\"],[\"76422.80\",\"0.000\"],[\"77150.00\",\"1.072\"],[\"78811.00\",\"3.492\"],[\"78970.20\",\"2.275\"],[\"79209.10\",\"1.022\"],[\"79453.90\",\"0.204\"],[\"79487.70\",\"0.352\"],[\"79489.70\",\"0.004\"],[\"79492.70\",\"0.000\"],[\"79503.40\",\"0.033\"],[\"79506.50\",\"0.009\"],[\"79514.10\",\"0.000\"],[\"79516.10\",\"3.037\"],[\"79557.90\",\"0.237\"],[\"79572.60\",\"0.002\"],[\"79580.00\",\"0.005\"],[\"79585.30\",\"0.002\"],[\"79587.70\",\"0.046\"],[\"79589.00\",\"0.629\"],[\"79590.40\",\"0.207\"],[\"79591.50\",\"0.415\"],[\"79592.00\",\"0.010\"],[\"79592.10\",\"0.001\"],[\"79592.20\",\"0.665\"],[\"79593.00\",\"0.000\"],[\"79593.40\",\"0.042\"],[\"79594.10\",\"0.316\"],[\"79595.30\",\"0.003\"],[\"79595.60\",\"0.104\"],[\"79595.80\",\"0.181\"],[\"79596.10\",\"0.017\"],[\"79596.30\",\"0.000\"],[\"79596.80\",\"0.032\"],[\"79597.30\",\"0.009\"],[\"79597.50\",\"0.007\"],[\"79597.60\",\"0.283\"],[\"79602.20\",\"0.046\"],[\"79603.00\",\"0.001\"],[\"79603.50\",\"0.000\"],[\"79604.90\",\"0.000\"],[\"79605.80\",\"0.026\"],[\"79605.90\",\"0.002\"],[\"79607.10\",\"10.469\"]],\"a\":[[\"79610.40\",\"1.270\"],[\"79611.50\",\"0.570\"],[\"79611.60\",\"0.001\"],[\"79611.90\",\"0.001\"],[\"79612.30\",\"2.725\"],[\"79612.60\",\"0.000\"],[\"79612.70\",\"0.010\"],[\"79612.80\",\"0.029\"],[\"79612.90\",\"0.027\"],[\"79613.00\",\"0.028\"],[\"79613.10\",\"0.002\"],[\"79613.20\",\"0.001\"],[\"79613.30\",\"0.001\"],[\"79613.40\",\"0.079\"],[\"79613.50\",\"0.000\"],[\"79613.60\",\"0.005\"],[\"79613.80\",\"0.026\"],[\"79613.90\",\"0.029\"],[\"79614.00\",\"0.032\"],[\"79614.10\",\"0.026\"],[\"79614.20\",\"0.028\"],[\"79614.40\",\"0.026\"],[\"79614.70\",\"0.026\"],[\"79614.80\",\"0.026\"],[\"79614.90\",\"0.077\"],[\"79615.00\",\"0.033\"],[\"79615.10\",\"0.000\"],[\"79615.20\",\"0.065\"],[\"79615.30\",\"0.694\"],[\"79615.40\",\"1.321\"],[\"79615.50\",\"0.058\"],[\"79615.60\",\"0.004\"],[\"79615.70\",\"0.002\"],[\"79616.10\",\"0.552\"],[\"79616.20\",\"0.862\"],[\"79617.30\",\"0.001\"],[\"79617.40\",\"0.079\"],[\"79618.80\",\"0.005\"],[\"79618.90\",\"0.375\"],[\"79620.50\",\"2.061\"],[\"79620.60\",\"7.702\"],[\"79620.70\",\"0.762\"],[\"79621.50\",\"1.147\"],[\"79621.70\",\"0.003\"],[\"79621.80\",\"1.108\"],[\"79624.50\",\"0.480\"],[\"79625.80\",\"0.534\"],[\"79625.90\",\"0.001\"],[\"79626.80\",\"0.007\"],[\"79627.10\",\"0.001\"],[\"79628.90\",\"0.019\"],[\"79629.80\",\"0.647\"],[\"79652.60\",\"1.057\"],[\"79654.20\",\"0.001\"],[\"79663.60\",\"0.353\"],[\"79675.80\",\"0.001\"],[\"79746.40\",\"0.002\"],[\"79788.30\",\"0.215\"],[\"79973.40\",\"0.969\"],[\"80363.50\",\"1.093\"],[\"80403.30\",\"7.987\"],[\"83577.10\",\"0.020\"]],\"st\":1}}"}
{"receive_ns":1788563196491906000,"stream":"btcusdt@bookTicker","event_type":"bookTicker","event_time_ms":1788563196527,"raw_json":"{\"stream\":\"btcusdt@bookTicker\",\"data\":{\"e\":\"bookTicker\",\"u\":11478222677303,\"s\":\"BTCUSDT\",\"ps\":\"BTCUSDT\",\"b\":\"79607.10\",\"B\":\"10.369\",\"a\":\"79607.20\",\"A\":\"1.066\",\"T\":1788563196527,\"E\":1788563196527,\"st\":1}}"}
{"receive_ns":1788563196492193000,"stream":"btcusdt@trade","event_type":"trade","event_time_ms":1788563196527,"raw_json":"{\"stream\":\"btcusdt@trade\",\"data\":{\"e\":\"trade\",\"E\":1788563196527,\"T\":1788563196527,\"s\":\"BTCUSDT\",\"t\":8054082676,\"p\":\"79607.10\",\"q\":\"0.100\",\"X\":\"MARKET\",\"m\":true,\"st\":1}}"}
{"receive_ns":1788563196493016000,"stream":"btcusdt@bookTicker","event_type":"bookTicker","event_time_ms":1788563196529,"raw_json":"{\"stream\":\"btcusdt@bookTicker\",\"data\":{\"e\":\"bookTicker\",\"u\":11478222677455,\"s\":\"BTCUSDT\",\"ps\":\"BTCUSDT\",\"b\":\"79607.10\",\"B\":\"10.388\",\"a\":\"79607.20\",\"A\":\"1.066\",\"T\":1788563196528,\"E\":1788563196529,\"st\":1}}"}
{"receive_ns":1788563196493209000,"stream":"btcusdt@bookTicker","event_type":"bookTicker","event_time_ms":1788563196529,"raw_json":"{\"stream\":\"btcusdt@bookTicker\",\"data\":{\"e\":\"bookTicker\",\"u\":11478222677457,\"s\":\"BTCUSDT\",\"ps\":\"BTCUSDT\",\"b\":\"79607.10\",\"B\":\"10.396\",\"a\":\"79607.20\",\"A\":\"1.066\",\"T\":1788563196528,\"E\":1788563196529,\"st\":1}}"}
{"receive_ns":1788563196493470000,"stream":"btcusdt@bookTicker","event_type":"bookTicker","event_time_ms":1788563196529,"raw_json":"{\"stream\":\"btcusdt@bookTicker\",\"data\":{\"e\":\"bookTicker\",\"u\":11478222677542,\"s\":\"BTCUSDT\",\"ps\":\"BTCUSDT\",\"b\":\"79607.10\",\"B\":\"10.377\",\"a\":\"79607.20\",\"A\":\"1.066\",\"T\":1788563196529,\"E\":1788563196529,\"st\":1}}"}
{"receive_ns":1788563196493916000,"stream":"btcusdt@bookTicker","event_type":"bookTicker","event_time_ms":1788563196530,"raw_json":"{\"stream\":\"btcusdt@bookTicker\",\"data\":{\"e\":\"bookTicker\",\"u\":11478222677554,\"s\":\"BTCUSDT\",\"ps\":\"BTCUSDT\",\"b\":\"79607.10\",\"B\":\"10.369\",\"a\":\"79607.20\",\"A\":\"1.066\",\"T\":1788563196529,\"E\":1788563196530,\"st\":1}}"}
{"receive_ns":1788563196530603000,"stream":"btcusdt@bookTicker","event_type":"bookTicker","event_time_ms":1788563196566,"raw_json":"{\"stream\":\"btcusdt@bookTicker\",\"data\":{\"e\":\"bookTicker\",\"u\":11478222679815,\"s\":\"BTCUSDT\",\"ps\":\"BTCUSDT\",\"b\":\"79607.10\",\"B\":\"10.369\",\"a\":\"79607.20\",\"A\":\"1.060\",\"T\":1788563196566,\"E\":1788563196566,\"st\":1}}"}
{"receive_ns":1788563196530869000,"stream":"btcusdt@trade","event_type":"trade","event_time_ms":1788563196566,"raw_json":"{\"stream\":\"btcusdt@trade\",\"data\":{\"e\":\"trade\",\"E\":1788563196566,\"T\":1788563196566,\"s\":\"BTCUSDT\",\"t\":8054082677,\"p\":\"79607.20\",\"q\":\"0.006\",\"X\":\"MARKET\",\"m\":false,\"st\":1}}"}
{"receive_ns":1788563196532837000,"stream":"btcusdt@bookTicker","event_type":"bookTicker","event_time_ms":1788563196567,"raw_json":"{\"stream\":\"btcusdt@bookTicker\",\"data\":{\"e\":\"bookTicker\",\"u\":11478222679915,\"s\":\"BTCUSDT\",\"ps\":\"BTCUSDT\",\"b\":\"79607.10\",\"B\":\"10.377\",\"a\":\"79607.20\",\"A\":\"1.060\",\"T\":1788563196567,\"E\":1788563196567,\"st\":1}}"}
{"receive_ns":1788563196533024000,"stream":"btcusdt@bookTicker","event_type":"bookTicker","event_time_ms":1788563196568,"raw_json":"{\"stream\":\"btcusdt@bookTicker\",\"data\":{\"e\":\"bookTicker\",\"u\":11478222680013,\"s\":\"BTCUSDT\",\"ps\":\"BTCUSDT\",\"b\":\"79607.10\",\"B\":\"10.396\",\"a\":\"79607.20\",\"A\":\"1.060\",\"T\":1788563196567,\"E\":1788563196568,\"st\":1}}"}
{"receive_ns":1788563196533204000,"stream":"btcusdt@bookTicker","event_type":"bookTicker","event_time_ms":1788563196568,"raw_json":"{\"stream\":\"btcusdt@bookTicker\",\"data\":{\"e\":\"bookTicker\",\"u\":11478222680053,\"s\":\"BTCUSDT\",\"ps\":\"BTCUSDT\",\"b\":\"79607.10\",\"B\":\"10.388\",\"a\":\"79607.20\",\"A\":\"1.060\",\"T\":1788563196568,\"E\":1788563196568,\"st\":1}}"}
{"receive_ns":1788563196533408000,"stream":"btcusdt@bookTicker","event_type":"bookTicker","event_time_ms":1788563196568,"raw_json":"{\"stream\":\"btcusdt@bookTicker\",\"data\":{\"e\":\"bookTicker\",\"u\":11478222680088,\"s\":\"BTCUSDT\",\"ps\":\"BTCUSDT\",\"b\":\"79607.10\",\"B\":\"10.369\",\"a\":\"79607.20\",\"A\":\"1.060\",\"T\":1788563196568,\"E\":1788563196568,\"st\":1}}"}
{"receive_ns":1788563196589032000,"stream":"btcusdt@depth@100ms","event_type":"depthUpdate","event_time_ms":1788563196625,"raw_json":"{\"stream\":\"btcusdt@depth@100ms\",\"data\":{\"e\":\"depthUpdate\",\"E\":1788563196625,\"T\":1788563196622,\"s\":\"BTCUSDT\",\"ps\":\"BTCUSDT\",\"U\":11478222676989,\"u\":11478222682559,\"pu\":11478222676823,\"b\":[[\"29307.10\",\"0.189\"],[\"29407.10\",\"1.904\"],[\"29507.10\",\"0.007\"],[\"63686.00\",\"0.002\"],[\"71646.30\",\"0.002\"],[\"76422.80\",\"0.002\"],[\"78479.30\",\"15.991\"],[\"78811.00\",\"3.492\"],[\"79005.30\",\"1.264\"],[\"79204.30\",\"2.961\"],[\"79209.10\",\"0.881\"],[\"79236.90\",\"0.015\"],[\"79487.70\",\"1.005\"],[\"79491.70\",\"1.506\"],[\"79516.10\",\"3.037\"],[\"79533.20\",\"0.679\"],[\"79534.00\",\"0.001\"],[\"79536.70\",\"23.519\"],[\"79542.90\",\"0.040\"],[\"79552.00\",\"1.628\"],[\"79591.40\",\"1.315\"],[\"79591.50\",\"0.315\"],[\"79592.70\",\"0.001\"],[\"79593.50\",\"0.001\"],[\"79595.10\",\"0.071\"],[\"79595.40\",\"0.100\"],[\"79601.20\",\"0.004\"],[\"79602.20\",\"0.046\"],[\"79602.30\",\"0.301\"],[\"79604.90\",\"0.076\"],[\"79607.00\",\"0.109\"],[\"79607.10\",\"10.369\"]],\"a\":[[\"79607.20\",\"1.060\"],[\"79608.10\",\"0.001\"],[\"79609.40\",\"0.080\"],[\"79610.50\",\"0.002\"],[\"79611.20\",\"0.000\"],[\"79611.40\",\"1.322\"],[\"79611.70\",\"0.029\"],[\"79612.40\",\"0.253\"],[\"79613.40\",\"0.079\"],[\"79613.70\",\"0.002\"],[\"79614.40\",\"0.000\"],[\"79614.70\",\"0.000\"],[\"79614.80\",\"0.000\"],[\"79621.80\",\"1.032\"],[\"79659.20\",\"9.813\"],[\"79788.30\",\"0.414\"],[\"79836.30\",\"0.020\"],[\"79836.40\",\"0.004\"],[\"79973.40\",\"1.713\"],[\"80403.30\",\"7.987\"],[\"80570.40\",\"0.000\"],[\"87567.90\",\"0.002\"]],\"st\":1}}"}
{"receive_ns":1788563196608666000,"stream":"btcusdt@bookTicker","event_type":"bookTicker","event_time_ms":1788563196644,"raw_json":"{\"stream\":\"btcusdt@bookTicker\",\"data\":{\"e\":\"bookTicker\",\"u\":11478222683476,\"s\":\"BTCUSDT\",\"ps\":\"BTCUSDT\",\"b\":\"79607.10\",\"B\":\"10.369\",\"a\":\"79607.20\",\"A\":\"1.047\",\"T\":1788563196643,\"E\":1788563196644,\"st\":1}}"}
{"receive_ns":1788563196608897000,"stream":"btcusdt@trade","event_type":"trade","event_time_ms":1788563196644,"raw_json":"{\"stream\":\"btcusdt@trade\",\"data\":{\"e\":\"trade\",\"E\":1788563196644,\"T\":1788563196643,\"s\":\"BTCUSDT\",\"t\":8054082678,\"p\":\"79607.20\",\"q\":\"0.013\",\"X\":\"MARKET\",\"m\":false,\"st\":1}}"}
{"receive_ns":1788563196609112000,"stream":"btcusdt@bookTicker","event_type":"bookTicker","event_time_ms":1788563196645,"raw_json":"{\"stream\":\"btcusdt@bookTicker\",\"data\":{\"e\":\"bookTicker\",\"u\":11478222683615,\"s\":\"BTCUSDT\",\"ps\":\"BTCUSDT\",\"b\":\"79607.10\",\"B\":\"10.388\",\"a\":\"79607.20\",\"A\":\"1.047\",\"T\":1788563196645,\"E\":1788563196645,\"st\":1}}"}
{"receive_ns":1788563196609281000,"stream":"btcusdt@bookTicker","event_type":"bookTicker","event_time_ms":1788563196645,"raw_json":"{\"stream\":\"btcusdt@bookTicker\",\"data\":{\"e\":\"bookTicker\",\"u\":11478222683633,\"s\":\"BTCUSDT\",\"ps\":\"BTCUSDT\",\"b\":\"79607.10\",\"B\":\"10.396\",\"a\":\"79607.20\",\"A\":\"1.047\",\"T\":1788563196645,\"E\":1788563196645,\"st\":1}}"}
{"receive_ns":1788563196609597000,"stream":"btcusdt@bookTicker","event_type":"bookTicker","event_time_ms":1788563196646,"raw_json":"{\"stream\":\"btcusdt@bookTicker\",\"data\":{\"e\":\"bookTicker\",\"u\":11478222683759,\"s\":\"BTCUSDT\",\"ps\":\"BTCUSDT\",\"b\":\"79607.10\",\"B\":\"10.388\",\"a\":\"79607.20\",\"A\":\"1.047\",\"T\":1788563196646,\"E\":1788563196646,\"st\":1}}"}
{"receive_ns":1788563196609785000,"stream":"btcusdt@bookTicker","event_type":"bookTicker","event_time_ms":1788563196646,"raw_json":"{\"stream\":\"btcusdt@bookTicker\",\"data\":{\"e\":\"bookTicker\",\"u\":11478222683764,\"s\":\"BTCUSDT\",\"ps\":\"BTCUSDT\",\"b\":\"79607.10\",\"B\":\"10.369\",\"a\":\"79607.20\",\"A\":\"1.047\",\"T\":1788563196646,\"E\":1788563196646,\"st\":1}}"}
{"receive_ns":1788563196648703000,"stream":"btcusdt@bookTicker","event_type":"bookTicker","event_time_ms":1788563196683,"raw_json":"{\"stream\":\"btcusdt@bookTicker\",\"data\":{\"e\":\"bookTicker\",\"u\":11478222685774,\"s\":\"BTCUSDT\",\"ps\":\"BTCUSDT\",\"b\":\"79607.10\",\"B\":\"10.388\",\"a\":\"79607.20\",\"A\":\"1.047\",\"T\":1788563196683,\"E\":1788563196683,\"st\":1}}"}
{"receive_ns":1788563196649073000,"stream":"btcusdt@bookTicker","event_type":"bookTicker","event_time_ms":1788563196684,"raw_json":"{\"stream\":\"btcusdt@bookTicker\",\"data\":{\"e\":\"bookTicker\",\"u\":11478222685779,\"s\":\"BTCUSDT\",\"ps\":\"BTCUSDT\",\"b\":\"79607.10\",\"B\":\"11.428\",\"a\":\"79607.20\",\"A\":\"1.047\",\"T\":1788563196683,\"E\":1788563196684,\"st\":1}}"}
{"receive_ns":1788563196649363000,"stream":"btcusdt@bookTicker","event_type":"bookTicker","event_time_ms":1788563196684,"raw_json":"{\"stream\":\"btcusdt@bookTicker\",\"data\":{\"e\":\"bookTicker\",\"u\":11478222685841,\"s\":\"BTCUSDT\",\"ps\":\"BTCUSDT\",\"b\":\"79607.10\",\"B\":\"11.409\",\"a\":\"79607.20\",\"A\":\"1.047\",\"T\":1788563196684,\"E\":1788563196684,\"st\":1}}"}
{"receive_ns":1788563196649612000,"stream":"btcusdt@bookTicker","event_type":"bookTicker","event_time_ms":1788563196684,"raw_json":"{\"stream\":\"btcusdt@bookTicker\",\"data\":{\"e\":\"bookTicker\",\"u\":11478222685865,\"s\":\"BTCUSDT\",\"ps\":\"BTCUSDT\",\"b\":\"79607.10\",\"B\":\"11.428\",\"a\":\"79607.20\",\"A\":\"1.047\",\"T\":1788563196684,\"E\":1788563196684,\"st\":1}}"}
{"receive_ns":1788563196649801000,"stream":"btcusdt@bookTicker","event_type":"bookTicker","event_time_ms":1788563196685,"raw_json":"{\"stream\":\"btcusdt@bookTicker\",\"data\":{\"e\":\"bookTicker\",\"u\":11478222685945,\"s\":\"BTCUSDT\",\"ps\":\"BTCUSDT\",\"b\":\"79607.10\",\"B\":\"11.426\",\"a\":\"79607.20\",\"A\":\"1.047\",\"T\":1788563196685,\"E\":1788563196685,\"st\":1}}"}
{"receive_ns":1788563196649973000,"stream":"btcusdt@bookTicker","event_type":"bookTicker","event_time_ms":1788563196685,"raw_json":"{\"stream\":\"btcusdt@bookTicker\",\"data\":{\"e\":\"bookTicker\",\"u\":11478222685964,\"s\":\"BTCUSDT\",\"ps\":\"BTCUSDT\",\"b\":\"79607.10\",\"B\":\"11.407\",\"a\":\"79607.20\",\"A\":\"1.047\",\"T\":1788563196685,\"E\":1788563196685,\"st\":1}}"}
{"receive_ns":1788563196650149000,"stream":"btcusdt@bookTicker","event_type":"bookTicker","event_time_ms":1788563196686,"raw_json":"{\"stream\":\"btcusdt@bookTicker\",\"data\":{\"e\":\"bookTicker\",\"u\":11478222686005,\"s\":\"BTCUSDT\",\"ps\":\"BTCUSDT\",\"b\":\"79607.10\",\"B\":\"10.367\",\"a\":\"79607.20\",\"A\":\"1.047\",\"T\":1788563196685,\"E\":1788563196686,\"st\":1}}"}
{"receive_ns":1788563196650296000,"stream":"btcusdt@bookTicker","event_type":"bookTicker","event_time_ms":1788563196686,"raw_json":"{\"stream\":\"btcusdt@bookTicker\",\"data\":{\"e\":\"bookTicker\",\"u\":11478222686018,\"s\":\"BTCUSDT\",\"ps\":\"BTCUSDT\",\"b\":\"79607.10\",\"B\":\"11.407\",\"a\":\"79607.20\",\"A\":\"1.047\",\"T\":1788563196685,\"E\":1788563196686,\"st\":1}}"}
{"receive_ns":1788563196651224000,"stream":"btcusdt@bookTicker","event_type":"bookTicker","event_time_ms":1788563196687,"raw_json":"{\"stream\":\"btcusdt@bookTicker\",\"data\":{\"e\":\"bookTicker\",\"u\":11478222686194,\"s\":\"BTCUSDT\",\"ps\":\"BTCUSDT\",\"b\":\"79607.10\",\"B\":\"11.408\",\"a\":\"79607.20\",\"A\":\"1.047\",\"T\":1788563196687,\"E\":1788563196687,\"st\":1}}"}
{"receive_ns":1788563196651452000,"stream":"btcusdt@bookTicker","event_type":"bookTicker","event_time_ms":1788563196687,"raw_json":"{\"stream\":\"btcusdt@bookTicker\",\"data\":{\"e\":\"bookTicker\",\"u\":11478222686202,\"s\":\"BTCUSDT\",\"ps\":\"BTCUSDT\",\"b\":\"79607.10\",\"B\":\"11.407\",\"a\":\"79607.20\",\"A\":\"1.047\",\"T\":1788563196687,\"E\":1788563196687,\"st\":1}}"}
{"receive_ns":1788563196652548000,"stream":"btcusdt@bookTicker","event_type":"bookTicker","event_time_ms":1788563196688,"raw_json":"{\"stream\":\"btcusdt@bookTicker\",\"data\":{\"e\":\"bookTicker\",\"u\":11478222686308,\"s\":\"BTCUSDT\",\"ps\":\"BTCUSDT\",\"b\":\"79607.10\",\"B\":\"10.367\",\"a\":\"79607.20\",\"A\":\"1.047\",\"T\":1788563196688,\"E\":1788563196688,\"st\":1}}"}
{"receive_ns":1788563196671211000,"stream":"btcusdt@bookTicker","event_type":"bookTicker","event_time_ms":1788563196705,"raw_json":"{\"stream\":\"btcusdt@bookTicker\",\"data\":{\"e\":\"bookTicker\",\"u\":11478222687141,\"s\":\"BTCUSDT\",\"ps\":\"BTCUSDT\",\"b\":\"79607.10\",\"B\":\"10.386\",\"a\":\"79607.20\",\"A\":\"1.047\",\"T\":1788563196705,\"E\":1788563196705,\"st\":1}}"}
{"receive_ns":1788563196671465000,"stream":"btcusdt@bookTicker","event_type":"bookTicker","event_time_ms":1788563196706,"raw_json":"{\"stream\":\"btcusdt@bookTicker\",\"data\":{\"e\":\"bookTicker\",\"u\":11478222687192,\"s\":\"BTCUSDT\",\"ps\":\"BTCUSDT\",\"b\":\"79607.10\",\"B\":\"10.367\",\"a\":\"79607.20\",\"A\":\"1.047\",\"T\":1788563196706,\"E\":1788563196706,\"st\":1}}"}
{"receive_ns":1788563196671628000,"stream":"btcusdt@bookTicker","event_type":"bookTicker","event_time_ms":1788563196707,"raw_json":"{\"stream\":\"btcusdt@bookTicker\",\"data\":{\"e\":\"bookTicker\",\"u\":11478222687247,\"s\":\"BTCUSDT\",\"ps\":\"BTCUSDT\",\"b\":\"79607.10\",\"B\":\"10.369\",\"a\":\"79607.20\",\"A\":\"1.047\",\"T\":1788563196706,\"E\":1788563196707,\"st\":1}}"}
{"receive_ns":1788563196682897000,"stream":"btcusdt@bookTicker","event_type":"bookTicker","event_time_ms":1788563196717,"raw_json":"{\"stream\":\"btcusdt@bookTicker\",\"data\":{\"e\":\"bookTicker\",\"u\":11478222688601,\"s\":\"BTCUSDT\",\"ps\":\"BTCUSDT\",\"b\":\"79607.10\",\"B\":\"10.388\",\"a\":\"79607.20\",\"A\":\"1.047\",\"T\":1788563196717,\"E\":1788563196717,\"st\":1}}"}
{"receive_ns":1788563196683148000,"stream":"btcusdt@bookTicker","event_type":"bookTicker","event_time_ms":1788563196718,"raw_json":"{\"stream\":\"btcusdt@bookTicker\",\"data\":{\"e\":\"bookTicker\",\"u\":11478222688664,\"s\":\"BTCUSDT\",\"ps\":\"BTCUSDT\",\"b\":\"79607.10\",\"B\":\"10.369\",\"a\":\"79607.20\",\"A\":\"1.047\",\"T\":1788563196717,\"E\":1788563196718,\"st\":1}}"}
{"receive_ns":1788563196691430000,"stream":"btcusdt@bookTicker","event_type":"bookTicker","event_time_ms":1788563196726,"raw_json":"{\"stream\":\"btcusdt@bookTicker\",\"data\":{\"e\":\"bookTicker\",\"u\":11478222689297,\"s\":\"BTCUSDT\",\"ps\":\"BTCUSDT\",\"b\":\"79607.10\",\"B\":\"10.372\",\"a\":\"79607.20\",\"A\":\"1.047\",\"T\":1788563196726,\"E\":1788563196726,\"st\":1}}"}
{"receive_ns":1788563196691935000,"stream":"btcusdt@depth@100ms","event_type":"depthUpdate","event_time_ms":1788563196727,"raw_json":"{\"stream\":\"btcusdt@depth@100ms\",\"data\":{\"e\":\"depthUpdate\",\"E\":1788563196727,\"T\":1788563196726,\"s\":\"BTCUSDT\",\"ps\":\"BTCUSDT\",\"U\":11478222682675,\"u\":11478222689304,\"pu\":11478222682559,\"b\":[[\"1000.00\",\"24.604\"],[\"29307.10\",\"0.364\"],[\"29407.10\",\"1.736\"],[\"29507.10\",\"0.000\"],[\"71646.30\",\"0.002\"],[\"78811.00\",\"3.492\"],[\"79209.00\",\"0.001\"],[\"79209.10\",\"1.022\"],[\"79236.90\",\"0.247\"],[\"79434.00\",\"0.176\"],[\"79491.70\",\"1.706\"],[\"79493.70\",\"0.957\"],[\"79563.00\",\"0.000\"],[\"79590.70\",\"0.070\"],[\"79590.80\",\"0.002\"],[\"79591.10\",\"0.656\"],[\"79592.50\",\"0.001\"],[\"79595.00\",\"0.082\"],[\"79595.80\",\"0.251\"],[\"79595.90\",\"1.985\"],[\"79596.40\",\"0.149\"],[\"79597.20\",\"0.142\"],[\"79598.00\",\"0.034\"],[\"79607.10\",\"10.372\"]],\"a\":[[\"79607.20\",\"1.047\"],[\"79610.40\",\"1.296\"],[\"79610.60\",\"0.371\"],[\"79610.70\",\"0.029\"],[\"79611.20\",\"0.592\"],[\"79611.40\",\"1.296\"],[\"79613.90\",\"0.027\"],[\"79614.10\",\"0.028\"],[\"79614.20\",\"0.002\"],[\"79614.70\",\"0.252\"],[\"79788.30\",\"0.215\"],[\"79973.40\",\"1.913\"],[\"80005.30\",\"0.002\"],[\"80403.30\",\"7.989\"],[\"80672.80\",\"10.948\"],[\"80721.70\",\"15.712\"],[\"81199.30\",\"0.033\"],[\"87567.90\",\"0.000\"]],\"st\":1}}"}
{"receive_ns":1788563196795897000,"stream":"btcusdt@depth@100ms","event_type":"depthUpdate","event_time_ms":1788563196829,"raw_json":"{\"stream\":\"btcusdt@depth@100ms\",\"data\":{\"e\":\"depthUpdate\",\"E\":1788563196829,\"T\":1788563196825,\"s\":\"BTCUSDT\",\"ps\":\"BTCUSDT\",\"U\":11478222689365,\"u\":11478222697707,\"pu\":11478222689304,\"b\":[[\"1000.00\",\"24.604\"],[\"29307.10\",\"0.539\"],[\"29407.10\",\"1.561\"],[\"71646.30\",\"0.002\"],[\"76422.80\",\"0.000\"],[\"78811.00\",\"3.492\"],[\"79209.10\",\"1.158\"],[\"79392.50\",\"0.000\"],[\"79392.80\",\"3.513\"],[\"79426.10\",\"0.010\"],[\"79449.50\",\"0.001\"],[\"79487.70\",\"1.507\"],[\"79491.70\",\"1.204\"],[\"79516.30\",\"0.015\"],[\"79533.80\",\"3.492\"],[\"79534.00\",\"0.001\"],[\"79536.70\",\"23.511\"],[\"79539.50\",\"0.125\"],[\"79551.60\",\"3.502\"],[\"79555.00\",\"0.066\"],[\"79591.00\",\"0.070\"],[\"79591.60\",\"0.073\"],[\"79591.70\",\"0.000\"],[\"79592.20\",\"0.629\"],[\"79593.80\",\"0.578\"],[\"79594.90\",\"0.070\"],[\"79595.20\",\"0.401\"],[\"79595.50\",\"0.101\"],[\"79595.60\",\"0.174\"],[\"79595.80\",\"0.252\"],[\"79596.00\",\"0.751\"]],\"a\":[[\"79610.40\",\"1.270\"],[\"79610.60\",\"0.345\"],[\"79610.70\",\"0.003\"],[\"79613.10\",\"0.028\"],[\"79620.50\",\"2.058\"],[\"79625.00\",\"0.005\"],[\"79973.40\",\"1.913\"],[\"80005.20\",\"1.509\"],[\"80403.30\",\"7.987\"]],\"st\":1}}"}
{"receive_ns":1788563196896371000,"stream":"btcusdt@depth@100ms","event_type":"depthUpdate","event_time_ms":1788563196931,"raw_json":"{\"stream\":\"btcusdt@depth@100ms\",\"data\":{\"e\":\"depthUpdate\",\"E\":1788563196931,\"T\":1788563196929,\"s\":\"BTCUSDT\",\"ps\":\"BTCUSDT\",\"U\":11478222697973,\"u\":11478222704644,\"pu\":11478222697707,\"b\":[[\"29307.10\",\"0.721\"],[\"29407.10\",\"1.379\"],[\"71646.30\",\"0.002\"],[\"76422.80\",\"0.002\"],[\"78563.30\",\"6.740\"],[\"78811.00\",\"3.492\"],[\"79209.10\",\"1.158\"],[\"79236.90\",\"0.247\"],[\"79390.40\",\"0.194\"],[\"79413.80\",\"0.001\"],[\"79434.00\",\"0.427\"],[\"79491.70\",\"1.279\"],[\"79493.70\",\"0.631\"],[\"79534.00\",\"23.512\"],[\"79536.70\",\"0.000\"],[\"79562.30\",\"0.736\"],[\"79562.90\",\"0.000\"],[\"79567.40\",\"0.103\"],[\"79575.30\",\"0.001\"],[\"79576.50\",\"0.454\"],[\"79583.40\",\"1.875\"],[\"79588.10\",\"0.629\"],[\"79590.60\",\"0.234\"],[\"79591.10\",\"0.556\"],[\"79591.20\",\"1.354\"],[\"79591.30\",\"0.001\"],[\"79591.40\",\"1.314\"],[\"79591.60\",\"0.011\"],[\"79591.80\",\"0.152\"],[\"79592.20\",\"0.001\"],[\"79592.30\",\"0.139\"],[\"79592.90\",\"0.462\"],[\"79594.90\",\"0.140\"],[\"79595.20\",\"0.471\"],[\"79595.30\",\"0.103\"],[\"79595.40\",\"0.200\"],[\"79596.00\",\"0.992\"],[\"79597.60\",\"0.032\"],[\"79598.80\",\"0.252\"]],\"a\":[[\"79609.20\",\"0.502\"],[\"79611.20\",\"0.289\"],[\"79623.30\",\"0.045\"],[\"79628.70\",\"0.342\"],[\"79632.90\",\"0.001\"],[\"79633.60\",\"0.717\"],[\"79673.50\",\"0.060\"],[\"79682.40\",\"0.019\"],[\"79973.40\",\"1.913\"],[\"80403.30\",\"7.987\"],[\"80721.70\",\"15.959\"]],\"st\":1}}"}
{"receive_ns":1788563196916311000,"stream":"btcusdt@bookTicker","event_type":"bookTicker","event_time_ms":1788563196950,"raw_json":"{\"stream\":\"btcusdt@bookTicker\",\"data\":{\"e\":\"bookTicker\",\"u\":11478222708808,\"s\":\"BTCUSDT\",\"ps\":\"BTCUSDT\",\"b\":\"79607.10\",\"B\":\"10.367\",\"a\":\"79607.20\",\"A\":\"1.047\",\"T\":1788563196950,\"E\":1788563196950,\"st\":1}}"}
{"receive_ns":1788563196990732000,"stream":"btcusdt@bookTicker","event_type":"bookTicker","event_time_ms":1788563197026,"raw_json":"{\"stream\":\"btcusdt@bookTicker\",\"data\":{\"e\":\"bookTicker\",\"u\":11478222716509,\"s\":\"BTCUSDT\",\"ps\":\"BTCUSDT\",\"b\":\"79607.10\",\"B\":\"10.386\",\"a\":\"79607.20\",\"A\":\"1.047\",\"T\":1788563197025,\"E\":1788563197026,\"st\":1}}"}
{"receive_ns":1788563196990993000,"stream":"btcusdt@bookTicker","event_type":"bookTicker","event_time_ms":1788563197026,"raw_json":"{\"stream\":\"btcusdt@bookTicker\",\"data\":{\"e\":\"bookTicker\",\"u\":11478222716627,\"s\":\"BTCUSDT\",\"ps\":\"BTCUSDT\",\"b\":\"79607.10\",\"B\":\"10.367\",\"a\":\"79607.20\",\"A\":\"1.047\",\"T\":1788563197026,\"E\":1788563197026,\"st\":1}}"}
{"receive_ns":1788563196993427000,"stream":"btcusdt@bookTicker","event_type":"bookTicker","event_time_ms":1788563197028,"raw_json":"{\"stream\":\"btcusdt@bookTicker\",\"data\":{\"e\":\"bookTicker\",\"u\":11478222717233,\"s\":\"BTCUSDT\",\"ps\":\"BTCUSDT\",\"b\":\"79607.10\",\"B\":\"10.375\",\"a\":\"79607.20\",\"A\":\"1.047\",\"T\":1788563197028,\"E\":1788563197028,\"st\":1}}"}
{"receive_ns":1788563196993666000,"stream":"btcusdt@bookTicker","event_type":"bookTicker","event_time_ms":1788563197029,"raw_json":"{\"stream\":\"btcusdt@bookTicker\",\"data\":{\"e\":\"bookTicker\",\"u\":11478222717443,\"s\":\"BTCUSDT\",\"ps\":\"BTCUSDT\",\"b\":\"79607.10\",\"B\":\"10.367\",\"a\":\"79607.20\",\"A\":\"1.047\",\"T\":1788563197029,\"E\":1788563197029,\"st\":1}}"}
{"receive_ns":1788563196994840000,"stream":"btcusdt@bookTicker","event_type":"bookTicker","event_time_ms":1788563197030,"raw_json":"{\"stream\":\"btcusdt@bookTicker\",\"data\":{\"e\":\"bookTicker\",\"u\":11478222717750,\"s\":\"BTCUSDT\",\"ps\":\"BTCUSDT\",\"b\":\"79607.10\",\"B\":\"10.375\",\"a\":\"79607.20\",\"A\":\"1.047\",\"T\":1788563197030,\"E\":1788563197030,\"st\":1}}"}
{"receive_ns":1788563196995742000,"stream":"btcusdt@bookTicker","event_type":"bookTicker","event_time_ms":1788563197031,"raw_json":"{\"stream\":\"btcusdt@bookTicker\",\"data\":{\"e\":\"bookTicker\",\"u\":11478222717884,\"s\":\"BTCUSDT\",\"ps\":\"BTCUSDT\",\"b\":\"79607.10\",\"B\":\"10.367\",\"a\":\"79607.20\",\"A\":\"1.047\",\"T\":1788563197031,\"E\":1788563197031,\"st\":1}}"}
{"receive_ns":1788563197006137000,"stream":"btcusdt@depth@100ms","event_type":"depthUpdate","event_time_ms":1788563197033,"raw_json":"{\"stream\":\"btcusdt@depth@100ms\",\"data\":{\"e\":\"depthUpdate\",\"E\":1788563197033,\"T\":1788563197032,\"s\":\"BTCUSDT\",\"ps\":\"BTCUSDT\",\"U\":11478222704723,\"u\":11478222718059,\"pu\":11478222704644,\"b\":[[\"1000.00\",\"24.604\"],[\"29307.10\",\"0.896\"],[\"29407.10\",\"1.204\"],[\"63685.70\",\"0.001\"],[\"71646.30\",\"0.002\"],[\"76422.80\",\"0.000\"],[\"78233.90\",\"1.022\"],[\"78811.00\",\"3.492\"],[\"79303.60\",\"0.000\"],[\"79326.90\",\"0.003\"],[\"79487.70\",\"1.005\"],[\"79511.50\",\"0.024\"],[\"79516.70\",\"0.033\"],[\"79534.00\",\"0.001\"],[\"79535.40\",\"0.000\"],[\"79536.70\",\"23.511\"],[\"79546.80\",\"0.080\"],[\"79555.00\",\"0.006\"],[\"79571.30\",\"0.101\"],[\"79575.30\",\"0.453\"],[\"79576.50\",\"0.002\"],[\"79590.70\",\"0.000\"],[\"79591.00\",\"0.000\"],[\"79591.10\",\"0.456\"],[\"79591.80\",\"0.082\"],[\"79597.30\",\"0.003\"],[\"79599.00\",\"0.056\"],[\"79607.10\",\"10.367\"]],\"a\":[[\"79609.70\",\"0.000\"],[\"79609.90\",\"0.002\"],[\"79610.50\",\"0.028\"],[\"79610.70\",\"0.029\"],[\"79614.10\",\"0.002\"],[\"79624.70\",\"1.197\"],[\"79625.80\",\"0.082\"],[\"79663.00\",\"0.002\"],[\"79678.90\",\"0.016\"],[\"79785.60\",\"0.006\"],[\"79973.40\",\"1.494\"],[\"80403.30\",\"7.989\"],[\"80602.30\",\"3.814\"],[\"81199.30\",\"0.036\"]],\"st\":1}}"}
{"receive_ns":1788563197032299000,"stream":"btcusdt@bookTicker","event_type":"bookTicker","event_time_ms":1788563197067,"raw_json":"{\"stream\":\"btcusdt@bookTicker\",\"data\":{\"e\":\"bookTicker\",\"u\":11478222723179,\"s\":\"BTCUSDT\",\"ps\":\"BTCUSDT\",\"b\":\"79607.10\",\"B\":\"10.364\",\"a\":\"79607.20\",\"A\":\"1.047\",\"T\":1788563197067,\"E\":1788563197067,\"st\":1}}"}
{"receive_ns":1788563197032588000,"stream":"btcusdt@trade","event_type":"trade","event_time_ms":1788563197067,"raw_json":"{\"stream\":\"btcusdt@trade\",\"data\":{\"e\":\"trade\",\"E\":1788563197067,\"T\":1788563197067,\"s\":\"BTCUSDT\",\"t\":8054082679,\"p\":\"79607.10\",\"q\":\"0.003\",\"X\":\"MARKET\",\"m\":true,\"st\":1}}"}
{"receive_ns":1788563197033470000,"stream":"btcusdt@bookTicker","event_type":"bookTicker","event_time_ms":1788563197068,"raw_json":"{\"stream\":\"btcusdt@bookTicker\",\"data\":{\"e\":\"bookTicker\",\"u\":11478222723391,\"s\":\"BTCUSDT\",\"ps\":\"BTCUSDT\",\"b\":\"79607.10\",\"B\":\"10.372\",\"a\":\"79607.20\",\"A\":\"1.047\",\"T\":1788563197068,\"E\":1788563197068,\"st\":1}}"}
{"receive_ns":1788563197033666000,"stream":"btcusdt@bookTicker","event_type":"bookTicker","event_time_ms":1788563197068,"raw_json":"{\"stream\":\"btcusdt@bookTicker\",\"data\":{\"e\":\"bookTicker\",\"u\":11478222723481,\"s\":\"BTCUSDT\",\"ps\":\"BTCUSDT\",\"b\":\"79607.10\",\"B\":\"10.391\",\"a\":\"79607.20\",\"A\":\"1.047\",\"T\":1788563197068,\"E\":1788563197068,\"st\":1}}"}
{"receive_ns":1788563197033839000,"stream":"btcusdt@bookTicker","event_type":"bookTicker","event_time_ms":1788563197069,"raw_json":"{\"stream\":\"btcusdt@bookTicker\",\"data\":{\"e\":\"bookTicker\",\"u\":11478222723616,\"s\":\"BTCUSDT\",\"ps\":\"BTCUSDT\",\"b\":\"79607.10\",\"B\":\"10.383\",\"a\":\"79607.20\",\"A\":\"1.047\",\"T\":1788563197069,\"E\":1788563197069,\"st\":1}}"}
{"receive_ns":1788563197034048000,"stream":"btcusdt@bookTicker","event_type":"bookTicker","event_time_ms":1788563197069,"raw_json":"{\"stream\":\"btcusdt@bookTicker\",\"data\":{\"e\":\"bookTicker\",\"u\":11478222723637,\"s\":\"BTCUSDT\",\"ps\":\"BTCUSDT\",\"b\":\"79607.10\",\"B\":\"10.364\",\"a\":\"79607.20\",\"A\":\"1.047\",\"T\":1788563197069,\"E\":1788563197069,\"st\":1}}"}
{"receive_ns":1788563197049819000,"stream":"btcusdt@bookTicker","event_type":"bookTicker","event_time_ms":1788563197083,"raw_json":"{\"stream\":\"btcusdt@bookTicker\",\"data\":{\"e\":\"bookTicker\",\"u\":11478222724939,\"s\":\"BTCUSDT\",\"ps\":\"BTCUSDT\",\"b\":\"79607.10\",\"B\":\"10.383\",\"a\":\"79607.20\",\"A\":\"1.047\",\"T\":1788563197083,\"E\":1788563197083,\"st\":1}}"}
{"receive_ns":1788563197050082000,"stream":"btcusdt@bookTicker","event_type":"bookTicker","event_time_ms":1788563197083,"raw_json":"{\"stream\":\"btcusdt@bookTicker\",\"data\":{\"e\":\"bookTicker\",\"u\":11478222725007,\"s\":\"BTCUSDT\",\"ps\":\"BTCUSDT\",\"b\":\"79607.10\",\"B\":\"10.364\",\"a\":\"79607.20\",\"A\":\"1.047\",\"T\":1788563197083,\"E\":1788563197083,\"st\":1}}"}
{"receive_ns":1788563197052348000,"stream":"btcusdt@bookTicker","event_type":"bookTicker","event_time_ms":1788563197086,"raw_json":"{\"stream\":\"btcusdt@bookTicker\",\"data\":{\"e\":\"bookTicker\",\"u\":11478222725360,\"s\":\"BTCUSDT\",\"ps\":\"BTCUSDT\",\"b\":\"79607.10\",\"B\":\"10.372\",\"a\":\"79607.20\",\"A\":\"1.047\",\"T\":1788563197086,\"E\":1788563197086,\"st\":1}}"}
{"receive_ns":1788563197052781000,"stream":"btcusdt@bookTicker","event_type":"bookTicker","event_time_ms":1788563197087,"raw_json":"{\"stream\":\"btcusdt@bookTicker\",\"data\":{\"e\":\"bookTicker\",\"u\":11478222725431,\"s\":\"BTCUSDT\",\"ps\":\"BTCUSDT\",\"b\":\"79607.10\",\"B\":\"10.364\",\"a\":\"79607.20\",\"A\":\"1.047\",\"T\":1788563197087,\"E\":1788563197087,\"st\":1}}"}
{"receive_ns":1788563197074783000,"stream":"btcusdt@bookTicker","event_type":"bookTicker","event_time_ms":1788563197108,"raw_json":"{\"stream\":\"btcusdt@bookTicker\",\"data\":{\"e\":\"bookTicker\",\"u\":11478222727422,\"s\":\"BTCUSDT\",\"ps\":\"BTCUSDT\",\"b\":\"79607.10\",\"B\":\"10.383\",\"a\":\"79607.20\",\"A\":\"1.047\",\"T\":1788563197107,\"E\":1788563197108,\"st\":1}}"}
{"receive_ns":1788563197074990000,"stream":"btcusdt@bookTicker","event_type":"bookTicker","event_time_ms":1788563197108,"raw_json":"{\"stream\":\"btcusdt@bookTicker\",\"data\":{\"e\":\"bookTicker\",\"u\":11478222727448,\"s\":\"BTCUSDT\",\"ps\":\"BTCUSDT\",\"b\":\"79607.10\",\"B\":\"10.391\",\"a\":\"79607.20\",\"A\":\"1.047\",\"T\":1788563197108,\"E\":1788563197108,\"st\":1}}"}
{"receive_ns":1788563197075166000,"stream":"btcusdt@bookTicker","event_type":"bookTicker","event_time_ms":1788563197108,"raw_json":"{\"stream\":\"btcusdt@bookTicker\",\"data\":{\"e\":\"bookTicker\",\"u\":11478222727524,\"s\":\"BTCUSDT\",\"ps\":\"BTCUSDT\",\"b\":\"79607.10\",\"B\":\"10.372\",\"a\":\"79607.20\",\"A\":\"1.047\",\"T\":1788563197108,\"E\":1788563197108,\"st\":1}}"}
{"receive_ns":1788563197075334000,"stream":"btcusdt@bookTicker","event_type":"bookTicker","event_time_ms":1788563197109,"raw_json":"{\"stream\":\"btcusdt@bookTicker\",\"data\":{\"e\":\"bookTicker\",\"u\":11478222727555,\"s\":\"BTCUSDT\",\"ps\":\"BTCUSDT\",\"b\":\"79607.10\",\"B\":\"10.364\",\"a\":\"79607.20\",\"A\":\"1.047\",\"T\":1788563197108,\"E\":1788563197109,\"st\":1}}"}
{"receive_ns":1788563197075562000,"stream":"btcusdt@bookTicker","event_type":"bookTicker","event_time_ms":1788563197109,"raw_json":"{\"stream\":\"btcusdt@bookTicker\",\"data\":{\"e\":\"bookTicker\",\"u\":11478222727689,\"s\":\"BTCUSDT\",\"ps\":\"BTCUSDT\",\"b\":\"79607.10\",\"B\":\"10.362\",\"a\":\"79607.20\",\"A\":\"1.047\",\"T\":1788563197109,\"E\":1788563197109,\"st\":1}}"}
{"receive_ns":1788563197092019000,"stream":"btcusdt@bookTicker","event_type":"bookTicker","event_time_ms":1788563197125,"raw_json":"{\"stream\":\"btcusdt@bookTicker\",\"data\":{\"e\":\"bookTicker\",\"u\":11478222728873,\"s\":\"BTCUSDT\",\"ps\":\"BTCUSDT\",\"b\":\"79607.10\",\"B\":\"10.354\",\"a\":\"79607.20\",\"A\":\"1.047\",\"T\":1788563197125,\"E\":1788563197125,\"st\":1}}"}
{"receive_ns":1788563197092244000,"stream":"btcusdt@trade","event_type":"trade","event_time_ms":1788563197125,"raw_json":"{\"stream\":\"btcusdt@trade\",\"data\":{\"e\":\"trade\",\"E\":1788563197125,\"T\":1788563197125,\"s\":\"BTCUSDT\",\"t\":8054082680,\"p\":\"79607.10\",\"q\":\"0.008\",\"X\":\"MARKET\",\"m\":true,\"st\":1}}"}
{"receive_ns":1788563197092422000,"stream":"btcusdt@bookTicker","event_type":"bookTicker","event_time_ms":1788563197126,"raw_json":"{\"stream\":\"btcusdt@bookTicker\",\"data\":{\"e\":\"bookTicker\",\"u\":11478222729029,\"s\":\"BTCUSDT\",\"ps\":\"BTCUSDT\",\"b\":\"79607.10\",\"B\":\"10.373\",\"a\":\"79607.20\",\"A\":\"1.047\",\"T\":1788563197126,\"E\":1788563197126,\"st\":1}}"}
{"receive_ns":1788563197092574000,"stream":"btcusdt@bookTicker","event_type":"bookTicker","event_time_ms":1788563197126,"raw_json":"{\"stream\":\"btcusdt@bookTicker\",\"data\":{\"e\":\"bookTicker\",\"u\":11478222729087,\"s\":\"BTCUSDT\",\"ps\":\"BTCUSDT\",\"b\":\"79607.10\",\"B\":\"10.381\",\"a\":\"79607.20\",\"A\":\"1.047\",\"T\":1788563197126,\"E\":1788563197126,\"st\":1}}"}
{"receive_ns":1788563197092744000,"stream":"btcusdt@bookTicker","event_type":"bookTicker","event_time_ms":1788563197127,"raw_json":"{\"stream\":\"btcusdt@bookTicker\",\"data\":{\"e\":\"bookTicker\",\"u\":11478222729167,\"s\":\"BTCUSDT\",\"ps\":\"BTCUSDT\",\"b\":\"79607.10\",\"B\":\"10.362\",\"a\":\"79607.20\",\"A\":\"1.047\",\"T\":1788563197127,\"E\":1788563197127,\"st\":1}}"}
{"receive_ns":1788563197092949000,"stream":"btcusdt@bookTicker","event_type":"bookTicker","event_time_ms":1788563197127,"raw_json":"{\"stream\":\"btcusdt@bookTicker\",\"data\":{\"e\":\"bookTicker\",\"u\":11478222729184,\"s\":\"BTCUSDT\",\"ps\":\"BTCUSDT\",\"b\":\"79607.10\",\"B\":\"10.354\",\"a\":\"79607.20\",\"A\":\"1.047\",\"T\":1788563197127,\"E\":1788563197127,\"st\":1}}"}
{"receive_ns":1788563197101719000,"stream":"btcusdt@depth@100ms","event_type":"depthUpdate","event_time_ms":1788563197135,"raw_json":"{\"stream\":\"btcusdt@depth@100ms\",\"data\":{\"e\":\"depthUpdate\",\"E\":1788563197135,\"T\":1788563197134,\"s\":\"BTCUSDT\",\"ps\":\"BTCUSDT\",\"U\":11478222718132,\"u\":11478222729914,\"pu\":11478222718059,\"b\":[[\"1000.00\",\"24.604\"],[\"29307.10\",\"1.078\"],[\"29407.10\",\"1.022\"],[\"71646.30\",\"0.002\"],[\"75626.70\",\"0.017\"],[\"75626.80\",\"0.006\"],[\"76422.80\",\"0.002\"],[\"78125.10\",\"0.037\"],[\"78165.30\",\"4.691\"],[\"78394.60\",\"0.020\"],[\"78811.00\",\"3.492\"],[\"79209.10\",\"1.017\"],[\"79236.90\",\"0.015\"],[\"79246.00\",\"0.000\"],[\"79269.40\",\"0.001\"],[\"79410.80\",\"0.000\"],[\"79434.00\",\"0.076\"],[\"79452.70\",\"0.002\"],[\"79453.90\",\"0.706\"],[\"79487.70\",\"2.209\"],[\"79491.70\",\"0.000\"],[\"79531.30\",\"23.522\"],[\"79536.70\",\"0.000\"],[\"79538.40\",\"0.795\"],[\"79566.80\",\"0.071\"],[\"79584.80\",\"0.277\"],[\"79592.80\",\"0.003\"],[\"79594.30\",\"0.162\"],[\"79607.00\",\"0.033\"],[\"79607.10\",\"10.354\"]],\"a\":[[\"79607.70\",\"0.076\"],[\"79609.20\",\"0.000\"],[\"79609.50\",\"0.031\"],[\"79610.00\",\"0.030\"],[\"79610.10\",\"0.027\"],[\"79610.20\",\"0.051\"],[\"79610.30\",\"0.613\"],[\"79610.40\",\"1.296\"],[\"79610.50\",\"0.002\"],[\"79611.20\",\"0.000\"],[\"79611.80\",\"0.026\"],[\"79611.90\",\"0.027\"],[\"79613.10\",\"0.002\"],[\"79613.80\",\"0.000\"],[\"79613.90\",\"0.001\"],[\"79614.00\",\"0.006\"],[\"79624.70\",\"0.745\"],[\"79625.70\",\"0.001\"],[\"79626.50\",\"0.452\"],[\"79656.20\",\"2.568\"],[\"79670.50\",\"0.211\"],[\"79673.50\",\"0.000\"],[\"79685.30\",\"0.061\"],[\"79812.00\",\"0.997\"],[\"79824.70\",\"0.014\"],[\"79866.70\",\"0.001\"],[\"79973.40\",\"1.713\"],[\"80403.30\",\"7.989\"],[\"80467.20\",\"0.008\"],[\"80819.60\",\"0.020\"]],\"st\":1}}"}
{"receive_ns":1788563197149773000,"stream":"btcusdt@bookTicker","event_type":"bookTicker","event_time_ms":1788563197184,"raw_json":"{\"stream\":\"btcusdt@bookTicker\",\"data\":{\"e\":\"bookTicker\",\"u\":11478222733961,\"s\":\"BTCUSDT\",\"ps\":\"BTCUSDT\",\"b\":\"79607.10\",\"B\":\"10.045\",\"a\":\"79607.20\",\"A\":\"1.047\",\"T\":1788563197184,\"E\":1788563197184,\"st\":1}}"}
{"receive_ns":1788563197152066000,"stream":"btcusdt@bookTicker","event_type":"bookTicker","event_time_ms":1788563197187,"raw_json":"{\"stream\":\"btcusdt@bookTicker\",\"data\":{\"e\":\"bookTicker\",\"u\":11478222734235,\"s\":\"BTCUSDT\",\"ps\":\"BTCUSDT\",\"b\":\"79607.10\",\"B\":\"10.356\",\"a\":\"79607.20\",\"A\":\"1.047\",\"T\":1788563197187,\"E\":1788563197187,\"st\":1}}"}
{"receive_ns":1788563197202602000,"stream":"btcusdt@depth@100ms","event_type":"depthUpdate","event_time_ms":1788563197237,"raw_json":"{\"stream\":\"btcusdt@depth@100ms\",\"data\":{\"e\":\"depthUpdate\",\"E\":1788563197237,\"T\":1788563197234,\"s\":\"BTCUSDT\",\"ps\":\"BTCUSDT\",\"U\":11478222729959,\"u\":11478222737605,\"pu\":11478222729914,\"b\":[[\"29307.10\",\"1.253\"],[\"29407.10\",\"0.847\"],[\"71646.30\",\"0.002\"],[\"78174.20\",\"0.013\"],[\"78249.10\",\"0.511\"],[\"78394.60\",\"0.028\"],[\"78811.00\",\"3.492\"],[\"79209.10\",\"1.158\"],[\"79236.90\",\"0.247\"],[\"79453.90\",\"0.806\"],[\"79491.70\",\"0.326\"],[\"79531.30\",\"0.011\"],[\"79534.00\",\"23.512\"],[\"79566.40\",\"0.012\"],[\"79566.50\",\"0.071\"],[\"79567.20\",\"0.310\"],[\"79607.10\",\"10.356\"]],\"a\":[[\"79608.90\",\"0.026\"],[\"79609.30\",\"0.027\"],[\"79611.20\",\"0.592\"],[\"79612.90\",\"0.001\"],[\"79613.00\",\"0.002\"],[\"79679.90\",\"0.002\"],[\"79682.80\",\"0.001\"],[\"79688.50\",\"1.938\"],[\"79973.40\",\"1.913\"],[\"80403.30\",\"7.987\"],[\"80547.50\",\"4.938\"],[\"80819.70\",\"0.008\"],[\"81199.30\",\"0.039\"]],\"st\":1}}"}
{"receive_ns":1788563197221293000,"stream":"btcusdt@bookTicker","event_type":"bookTicker","event_time_ms":1788563197256,"raw_json":"{\"stream\":\"btcusdt@bookTicker\",\"data\":{\"e\":\"bookTicker\",\"u\":11478222738925,\"s\":\"BTCUSDT\",\"ps\":\"BTCUSDT\",\"b\":\"79607.10\",\"B\":\"10.367\",\"a\":\"79607.20\",\"A\":\"1.047\",\"T\":1788563197256,\"E\":1788563197256,\"st\":1}}"}
{"receive_ns":1788563197304860000,"stream":"btcusdt@depth@100ms","event_type":"depthUpdate","event_time_ms":1788563197339,"raw_json":"{\"stream\":\"btcusdt@depth@100ms\",\"data\":{\"e\":\"depthUpdate\",\"E\":1788563197339,\"T\":1788563197337,\"s\":\"BTCUSDT\",\"ps\":\"BTCUSDT\",\"U\":11478222737869,\"u\":11478222744335,\"pu\":11478222737605,\"b\":[[\"1000.00\",\"24.604\"],[\"29307.10\",\"1.435\"],[\"29407.10\",\"0.665\"],[\"71646.30\",\"0.002\"],[\"76422.80\",\"0.000\"],[\"78806.30\",\"3.105\"],[\"78811.00\",\"3.492\"],[\"79201.80\",\"0.087\"],[\"79204.30\",\"2.835\"],[\"79209.00\",\"0.000\"],[\"79453.90\",\"0.304\"],[\"79480.00\",\"0.525\"],[\"79481.60\",\"0.686\"],[\"79487.70\",\"0.503\"],[\"79491.70\",\"1.330\"],[\"79519.80\",\"0.829\"],[\"79534.00\",\"23.512\"],[\"79535.70\",\"0.692\"],[\"79536.70\",\"0.000\"],[\"79607.10\",\"10.367\"]],\"a\":[[\"79728.60\",\"0.000\"],[\"79731.00\",\"0.693\"],[\"79733.30\",\"0.017\"],[\"79746.40\",\"0.000\"],[\"79973.40\",\"1.150\"],[\"80403.30\",\"7.987\"],[\"80557.60\",\"15.039\"],[\"87568.00\",\"0.001\"]],\"st\":1}}"}
{"receive_ns":1788563197321919000,"stream":"btcusdt@bookTicker","event_type":"bookTicker","event_time_ms":1788563197355,"raw_json":"{\"stream\":\"btcusdt@bookTicker\",\"data\":{\"e\":\"bookTicker\",\"u\":11478222745380,\"s\":\"BTCUSDT\",\"ps\":\"BTCUSDT\",\"b\":\"79607.10\",\"B\":\"10.386\",\"a\":\"79607.20\",\"A\":\"1.047\",\"T\":1788563197355,\"E\":1788563197355,\"st\":1}}"}
{"receive_ns":1788563197322181000,"stream":"btcusdt@bookTicker","event_type":"bookTicker","event_time_ms":1788563197356,"raw_json":"{\"stream\":\"btcusdt@bookTicker\",\"data\":{\"e\":\"bookTicker\",\"u\":11478222745437,\"s\":\"BTCUSDT\",\"ps\":\"BTCUSDT\",\"b\":\"79607.10\",\"B\":\"10.367\",\"a\":\"79607.20\",\"A\":\"1.047\",\"T\":1788563197356,\"E\":1788563197356,\"st\":1}}"}
{"receive_ns":1788563197330517000,"stream":"btcusdt@bookTicker","event_type":"bookTicker","event_time_ms":1788563197365,"raw_json":"{\"stream\":\"btcusdt@bookTicker\",\"data\":{\"e\":\"bookTicker\",\"u\":11478222746085,\"s\":\"BTCUSDT\",\"ps\":\"BTCUSDT\",\"b\":\"79607.10\",\"B\":\"10.366\",\"a\":\"79607.20\",\"A\":\"1.047\",\"T\":1788563197365,\"E\":1788563197365,\"st\":1}}"}
{"receive_ns":1788563197336361000,"stream":"btcusdt@bookTicker","event_type":"bookTicker","event_time_ms":1788563197372,"raw_json":"{\"stream\":\"btcusdt@bookTicker\",\"data\":{\"e\":\"bookTicker\",\"u\":11478222746592,\"s\":\"BTCUSDT\",\"ps\":\"BTCUSDT\",\"b\":\"79607.10\",\"B\":\"10.367\",\"a\":\"79607.20\",\"A\":\"1.047\",\"T\":1788563197371,\"E\":1788563197372,\"st\":1}}"}
{"receive_ns":1788563197340264000,"stream":"btcusdt@bookTicker","event_type":"bookTicker","event_time_ms":1788563197374,"raw_json":"{\"stream\":\"btcusdt@bookTicker\",\"data\":{\"e\":\"bookTicker\",\"u\":11478222746791,\"s\":\"BTCUSDT\",\"ps\":\"BTCUSDT\",\"b\":\"79607.10\",\"B\":\"10.175\",\"a\":\"79607.20\",\"A\":\"1.047\",\"T\":1788563197374,\"E\":1788563197374,\"st\":1}}"}
{"receive_ns":1788563197343188000,"stream":"btcusdt@bookTicker","event_type":"bookTicker","event_time_ms":1788563197377,"raw_json":"{\"stream\":\"btcusdt@bookTicker\",\"data\":{\"e\":\"bookTicker\",\"u\":11478222746919,\"s\":\"BTCUSDT\",\"ps\":\"BTCUSDT\",\"b\":\"79607.10\",\"B\":\"10.371\",\"a\":\"79607.20\",\"A\":\"1.047\",\"T\":1788563197377,\"E\":1788563197377,\"st\":1}}"}
{"receive_ns":1788563197374683000,"stream":"btcusdt@bookTicker","event_type":"bookTicker","event_time_ms":1788563197409,"raw_json":"{\"stream\":\"btcusdt@bookTicker\",\"data\":{\"e\":\"bookTicker\",\"u\":11478222749035,\"s\":\"BTCUSDT\",\"ps\":\"BTCUSDT\",\"b\":\"79607.10\",\"B\":\"9.890\",\"a\":\"79607.20\",\"A\":\"1.047\",\"T\":1788563197409,\"E\":1788563197409,\"st\":1}}"}
{"receive_ns":1788563197384722000,"stream":"btcusdt@bookTicker","event_type":"bookTicker","event_time_ms":1788563197418,"raw_json":"{\"stream\":\"btcusdt@bookTicker\",\"data\":{\"e\":\"bookTicker\",\"u\":11478222749696,\"s\":\"BTCUSDT\",\"ps\":\"BTCUSDT\",\"b\":\"79607.10\",\"B\":\"10.372\",\"a\":\"79607.20\",\"A\":\"1.047\",\"T\":1788563197418,\"E\":1788563197418,\"st\":1}}"}
{"receive_ns":1788563197414215000,"stream":"btcusdt@depth@100ms","event_type":"depthUpdate","event_time_ms":1788563197441,"raw_json":"{\"stream\":\"btcusdt@depth@100ms\",\"data\":{\"e\":\"depthUpdate\",\"E\":1788563197441,\"T\":1788563197438,\"s\":\"BTCUSDT\",\"ps\":\"BTCUSDT\",\"U\":11478222744434,\"u\":11478222750595,\"pu\":11478222744335,\"b\":[[\"29307.10\",\"1.610\"],[\"29407.10\",\"0.490\"],[\"71646.30\",\"0.002\"],[\"76422.80\",\"0.002\"],[\"78253.80\",\"5.230\"],[\"78500.00\",\"85.614\"],[\"78811.00\",\"3.492\"],[\"79209.10\",\"1.158\"],[\"79236.90\",\"0.247\"],[\"79453.90\",\"0.304\"],[\"79487.70\",\"2.033\"],[\"79491.70\",\"1.004\"],[\"79519.80\",\"0.000\"],[\"79535.70\",\"0.001\"],[\"79607.10\",\"10.372\"]],\"a\":[[\"79608.70\",\"0.026\"],[\"79608.90\",\"0.026\"],[\"79609.00\",\"0.029\"],[\"79609.10\",\"0.026\"],[\"79611.20\",\"0.592\"],[\"79611.70\",\"0.003\"],[\"79611.80\",\"0.000\"],[\"79611.90\",\"0.001\"],[\"79653.90\",\"0.128\"],[\"79654.00\",\"2.189\"],[\"79654.50\",\"0.001\"],[\"79656.20\",\"1.361\"],[\"79659.20\",\"0.002\"],[\"79788.30\",\"0.414\"],[\"79788.80\",\"0.006\"],[\"79973.40\",\"1.913\"],[\"80005.30\",\"0.003\"],[\"80403.30\",\"7.987\"],[\"87568.00\",\"0.000\"]],\"st\":1}}"}
{"receive_ns":1788563197430445000,"stream":"btcusdt@bookTicker","event_type":"bookTicker","event_time_ms":1788563197464,"raw_json":"{\"stream\":\"btcusdt@bookTicker\",\"data\":{\"e\":\"bookTicker\",\"u\":11478222751931,\"s\":\"BTCUSDT\",\"ps\":\"BTCUSDT\",\"b\":\"79607.10\",\"B\":\"10.380\",\"a\":\"79607.20\",\"A\":\"1.047\",\"T\":1788563197464,\"E\":1788563197464,\"st\":1}}"}
{"receive_ns":1788563197430686000,"stream":"btcusdt@bookTicker","event_type":"bookTicker","event_time_ms":1788563197464,"raw_json":"{\"stream\":\"btcusdt@bookTicker\",\"data\":{\"e\":\"bookTicker\",\"u\":11478222751937,\"s\":\"BTCUSDT\",\"ps\":\"BTCUSDT\",\"b\":\"79607.10\",\"B\":\"10.399\",\"a\":\"79607.20\",\"A\":\"1.047\",\"T\":1788563197464,\"E\":1788563197464,\"st\":1}}"}
{"receive_ns":1788563197430946000,"stream":"btcusdt@bookTicker","event_type":"bookTicker","event_time_ms":1788563197464,"raw_json":"{\"stream\":\"btcusdt@bookTicker\",\"data\":{\"e\":\"bookTicker\",\"u\":11478222751965,\"s\":\"BTCUSDT\",\"ps\":\"BTCUSDT\",\"b\":\"79607.10\",\"B\":\"10.391\",\"a\":\"79607.20\",\"A\":\"1.047\",\"T\":1788563197464,\"E\":1788563197464,\"st\":1}}"}
{"receive_ns":1788563197431140000,"stream":"btcusdt@bookTicker","event_type":"bookTicker","event_time_ms":1788563197464,"raw_json":"{\"stream\":\"btcusdt@bookTicker\",\"data\":{\"e\":\"bookTicker\",\"u\":11478222751966,\"s\":\"BTCUSDT\",\"ps\":\"BTCUSDT\",\"b\":\"79607.10\",\"B\":\"10.372\",\"a\":\"79607.20\",\"A\":\"1.047\",\"T\":1788563197464,\"E\":1788563197464,\"st\":1}}"}
{"receive_ns":1788563197461161000,"stream":"btcusdt@bookTicker","event_type":"bookTicker","event_time_ms":1788563197496,"raw_json":"{\"stream\":\"btcusdt@bookTicker\",\"data\":{\"e\":\"bookTicker\",\"u\":11478222753373,\"s\":\"BTCUSDT\",\"ps\":\"BTCUSDT\",\"b\":\"79607.10\",\"B\":\"10.372\",\"a\":\"79607.20\",\"A\":\"1.045\",\"T\":1788563197496,\"E\":1788563197496,\"st\":1}}"}
{"receive_ns":1788563197478240000,"stream":"btcusdt@bookTicker","event_type":"bookTicker","event_time_ms":1788563197503,"raw_json":"{\"stream\":\"btcusdt@bookTicker\",\"data\":{\"e\":\"bookTicker\",\"u\":11478222753834,\"s\":\"BTCUSDT\",\"ps\":\"BTCUSDT\",\"b\":\"79607.10\",\"B\":\"10.372\",\"a\":\"79607.20\",\"A\":\"1.060\",\"T\":1788563197503,\"E\":1788563197503,\"st\":1}}"}
{"receive_ns":1788563197478551000,"stream":"btcusdt@bookTicker","event_type":"bookTicker","event_time_ms":1788563197504,"raw_json":"{\"stream\":\"btcusdt@bookTicker\",\"data\":{\"e\":\"bookTicker\",\"u\":11478222753918,\"s\":\"BTCUSDT\",\"ps\":\"BTCUSDT\",\"b\":\"79607.10\",\"B\":\"10.372\",\"a\":\"79607.20\",\"A\":\"1.059\",\"T\":1788563197504,\"E\":1788563197504,\"st\":1}}"}
{"receive_ns":1788563197485579000,"stream":"btcusdt@bookTicker","event_type":"bookTicker","event_time_ms":1788563197520,"raw_json":"{\"stream\":\"btcusdt@bookTicker\",\"data\":{\"e\":\"bookTicker\",\"u\":11478222755063,\"s\":\"BTCUSDT\",\"ps\":\"BTCUSDT\",\"b\":\"79607.10\",\"B\":\"10.380\",\"a\":\"79607.20\",\"A\":\"1.059\",\"T\":1788563197520,\"E\":1788563197520,\"st\":1}}"}
{"receive_ns":1788563197485869000,"stream":"btcusdt@bookTicker","event_type":"bookTicker","event_time_ms":1788563197520,"raw_json":"{\"stream\":\"btcusdt@bookTicker\",\"data\":{\"e\":\"bookTicker\",\"u\":11478222755088,\"s\":\"BTCUSDT\",\"ps\":\"BTCUSDT\",\"b\":\"79607.10\",\"B\":\"10.399\",\"a\":\"79607.20\",\"A\":\"1.059\",\"T\":1788563197520,\"E\":1788563197520,\"st\":1}}"}
{"receive_ns":1788563197493438000,"stream":"btcusdt@bookTicker","event_type":"bookTicker","event_time_ms":1788563197520,"raw_json":"{\"stream\":\"btcusdt@bookTicker\",\"data\":{\"e\":\"bookTicker\",\"u\":11478222755147,\"s\":\"BTCUSDT\",\"ps\":\"BTCUSDT\",\"b\":\"79607.10\",\"B\":\"10.391\",\"a\":\"79607.20\",\"A\":\"1.059\",\"T\":1788563197520,\"E\":1788563197520,\"st\":1}}"}
{"receive_ns":1788563197493625000,"stream":"btcusdt@bookTicker","event_type":"bookTicker","event_time_ms":1788563197521,"raw_json":"{\"stream\":\"btcusdt@bookTicker\",\"data\":{\"e\":\"bookTicker\",\"u\":11478222755159,\"s\":\"BTCUSDT\",\"ps\":\"BTCUSDT\",\"b\":\"79607.10\",\"B\":\"10.372\",\"a\":\"79607.20\",\"A\":\"1.059\",\"T\":1788563197521,\"E\":1788563197521,\"st\":1}}"}
{"receive_ns":1788563197493838000,"stream":"btcusdt@bookTicker","event_type":"bookTicker","event_time_ms":1788563197521,"raw_json":"{\"stream\":\"btcusdt@bookTicker\",\"data\":{\"e\":\"bookTicker\",\"u\":11478222755201,\"s\":\"BTCUSDT\",\"ps\":\"BTCUSDT\",\"b\":\"79607.10\",\"B\":\"10.372\",\"a\":\"79607.20\",\"A\":\"1.060\",\"T\":1788563197521,\"E\":1788563197521,\"st\":1}}"}
{"receive_ns":1788563197509098000,"stream":"btcusdt@depth@100ms","event_type":"depthUpdate","event_time_ms":1788563197543,"raw_json":"{\"stream\":\"btcusdt@depth@100ms\",\"data\":{\"e\":\"depthUpdate\",\"E\":1788563197543,\"T\":1788563197541,\"s\":\"BTCUSDT\",\"ps\":\"BTCUSDT\",\"U\":11478222750782,\"u\":11478222756212,\"pu\":11478222750595,\"b\":[[\"29207.10\",\"0.014\"],[\"29307.10\",\"1.764\"],[\"29407.10\",\"0.322\"],[\"71646.30\",\"0.002\"],[\"71681.00\",\"0.000\"],[\"76422.80\",\"0.000\"],[\"78492.60\",\"10.052\"],[\"78811.00\",\"3.492\"],[\"79487.70\",\"1.531\"],[\"79491.70\",\"1.004\"],[\"79606.40\",\"0.184\"],[\"79607.10\",\"10.372\"]],\"a\":[[\"79607.20\",\"1.060\"],[\"79607.70\",\"0.000\"],[\"79608.40\",\"0.275\"],[\"79608.60\",\"0.026\"],[\"79610.40\",\"1.270\"],[\"79610.70\",\"0.003\"],[\"79973.40\",\"1.494\"],[\"80403.30\",\"7.987\"],[\"80769.50\",\"0.402\"],[\"81199.30\",\"0.036\"]],\"st\":1}}"}
{"receive_ns":1788563197540458000,"stream":"btcusdt@bookTicker","event_type":"bookTicker","event_time_ms":1788563197575,"raw_json":"{\"stream\":\"btcusdt@bookTicker\",\"data\":{\"e\":\"bookTicker\",\"u\":11478222757843,\"s\":\"BTCUSDT\",\"ps\":\"BTCUSDT\",\"b\":\"79607.10\",\"B\":\"10.380\",\"a\":\"79607.20\",\"A\":\"1.060\",\"T\":1788563197575,\"E\":1788563197575,\"st\":1}}"}
{"receive_ns":1788563197540706000,"stream":"btcusdt@bookTicker","event_type":"bookTicker","event_time_ms":1788563197575,"raw_json":"{\"stream\":\"btcusdt@bookTicker\",\"data\":{\"e\":\"bookTicker\",\"u\":11478222757850,\"s\":\"BTCUSDT\",\"ps\":\"BTCUSDT\",\"b\":\"79607.10\",\"B\":\"10.399\",\"a\":\"79607.20\",\"A\":\"1.060\",\"T\":1788563197575,\"E\":1788563197575,\"st\":1}}"}
{"receive_ns":1788563197540927000,"stream":"btcusdt@bookTicker","event_type":"bookTicker","event_time_ms":1788563197576,"raw_json":"{\"stream\":\"btcusdt@bookTicker\",\"data\":{\"e\":\"bookTicker\",\"u\":11478222757905,\"s\":\"BTCUSDT\",\"ps\":\"BTCUSDT\",\"b\":\"79607.10\",\"B\":\"10.380\",\"a\":\"79607.20\",\"A\":\"1.060\",\"T\":1788563197576,\"E\":1788563197576,\"st\":1}}"}
{"receive_ns":1788563197541175000,"stream":"btcusdt@bookTicker","event_type":"bookTicker","event_time_ms":1788563197576,"raw_json":"{\"stream\":\"btcusdt@bookTicker\",\"data\":{\"e\":\"bookTicker\",\"u\":11478222757919,\"s\":\"BTCUSDT\",\"ps\":\"BTCUSDT\",\"b\":\"79607.10\",\"B\":\"10.372\",\"a\":\"79607.20\",\"A\":\"1.060\",\"T\":1788563197576,\"E\":1788563197576,\"st\":1}}"}
{"receive_ns":1788563197594953000,"stream":"btcusdt@bookTicker","event_type":"bookTicker","event_time_ms":1788563197629,"raw_json":"{\"stream\":\"btcusdt@bookTicker\",\"data\":{\"e\":\"bookTicker\",\"u\":11478222761292,\"s\":\"BTCUSDT\",\"ps\":\"BTCUSDT\",\"b\":\"79607.10\",\"B\":\"10.391\",\"a\":\"79607.20\",\"A\":\"1.060\",\"T\":1788563197629,\"E\":1788563197629,\"st\":1}}"}
{"receive_ns":1788563197595231000,"stream":"btcusdt@bookTicker","event_type":"bookTicker","event_time_ms":1788563197630,"raw_json":"{\"stream\":\"btcusdt@bookTicker\",\"data\":{\"e\":\"bookTicker\",\"u\":11478222761347,\"s\":\"BTCUSDT\",\"ps\":\"BTCUSDT\",\"b\":\"79607.10\",\"B\":\"10.372\",\"a\":\"79607.20\",\"A\":\"1.060\",\"T\":1788563197630,\"E\":1788563197630,\"st\":1}}"}
{"receive_ns":1788563197609728000,"stream":"btcusdt@depth@100ms","event_type":"depthUpdate","event_time_ms":1788563197645,"raw_json":"{\"stream\":\"btcusdt@depth@100ms\",\"data\":{\"e\":\"depthUpdate\",\"E\":1788563197645,\"T\":1788563197641,\"s\":\"BTCUSDT\",\"ps\":\"BTCUSDT\",\"U\":11478222756301,\"u\":11478222761993,\"pu\":11478222756212,\"b\":[[\"1000.00\",\"24.604\"],[\"29207.10\",\"0.070\"],[\"29307.10\",\"1.827\"],[\"29407.10\",\"0.203\"],[\"63686.00\",\"0.002\"],[\"71646.30\",\"0.002\"],[\"76422.80\",\"0.002\"],[\"78492.60\",\"10.434\"],[\"78811.00\",\"3.492\"],[\"79209.10\",\"1.284\"],[\"79236.90\",\"0.247\"],[\"79434.00\",\"0.176\"],[\"79453.90\",\"0.455\"],[\"79454.80\",\"0.009\"],[\"79455.10\",\"0.033\"],[\"79487.70\",\"1.205\"],[\"79491.70\",\"1.506\"],[\"79493.70\",\"0.706\"],[\"79607.10\",\"10.372\"]],\"a\":[[\"79608.40\",\"0.249\"],[\"79608.60\",\"0.000\"],[\"79608.70\",\"0.000\"],[\"79608.90\",\"0.000\"],[\"79609.00\",\"0.003\"],[\"79609.10\",\"0.000\"],[\"79609.20\",\"0.502\"],[\"79609.30\",\"0.001\"],[\"79609.60\",\"0.026\"],[\"79609.80\",\"0.026\"],[\"79610.20\",\"0.077\"],[\"79610.30\",\"0.639\"],[\"79610.40\",\"1.296\"],[\"79611.20\",\"0.289\"],[\"79614.10\",\"0.034\"],[\"79617.40\",\"0.179\"],[\"79637.10\",\"0.046\"],[\"79639.60\",\"0.001\"],[\"79788.30\",\"0.215\"],[\"79973.40\",\"1.913\"],[\"80403.30\",\"7.987\"],[\"80562.50\",\"14.568\"],[\"80593.20\",\"2.686\"]],\"st\":1}}"}
{"receive_ns":1788563197652680000,"stream":"btcusdt@bookTicker","event_type":"bookTicker","event_time_ms":1788563197686,"raw_json":"{\"stream\":\"btcusdt@bookTicker\",\"data\":{\"e\":\"bookTicker\",\"u\":11478222764633,\"s\":\"BTCUSDT\",\"ps\":\"BTCUSDT\",\"b\":\"79607.10\",\"B\":\"10.391\",\"a\":\"79607.20\",\"A\":\"1.060\",\"T\":1788563197686,\"E\":1788563197686,\"st\":1}}"}
{"receive_ns":1788563197653002000,"stream":"btcusdt@bookTicker","event_type":"bookTicker","event_time_ms":1788563197686,"raw_json":"{\"stream\":\"btcusdt@bookTicker\",\"data\":{\"e\":\"bookTicker\",\"u\":11478222764689,\"s\":\"BTCUSDT\",\"ps\":\"BTCUSDT\",\"b\":\"79607.10\",\"B\":\"10.372\",\"a\":\"79607.20\",\"A\":\"1.060\",\"T\":1788563197686,\"E\":1788563197686,\"st\":1}}"}
{"receive_ns":1788563197679317000,"stream":"btcusdt@bookTicker","event_type":"bookTicker","event_time_ms":1788563197713,"raw_json":"{\"stream\":\"btcusdt@bookTicker\",\"data\":{\"e\":\"bookTicker\",\"u\":11478222766044,\"s\":\"BTCUSDT\",\"ps\":\"BTCUSDT\",\"b\":\"79607.10\",\"B\":\"10.369\",\"a\":\"79607.20\",\"A\":\"1.060\",\"T\":1788563197713,\"E\":1788563197713,\"st\":1}}"}
{"receive_ns":1788563197684852000,"stream":"btcusdt@bookTicker","event_type":"bookTicker","event_time_ms":1788563197719,"raw_json":"{\"stream\":\"btcusdt@bookTicker\",\"data\":{\"e\":\"bookTicker\",\"u\":11478222766428,\"s\":\"BTCUSDT\",\"ps\":\"BTCUSDT\",\"b\":\"79607.10\",\"B\":\"10.369\",\"a\":\"79607.20\",\"A\":\"1.062\",\"T\":1788563197718,\"E\":1788563197719,\"st\":1}}"}
{"receive_ns":1788563197711898000,"stream":"btcusdt@depth@100ms","event_type":"depthUpdate","event_time_ms":1788563197747,"raw_json":"{\"stream\":\"btcusdt@depth@100ms\",\"data\":{\"e\":\"depthUpdate\",\"E\":1788563197747,\"T\":1788563197746,\"s\":\"BTCUSDT\",\"ps\":\"BTCUSDT\",\"U\":11478222762197,\"u\":11478222767836,\"pu\":11478222761993,\"b\":[[\"29207.10\",\"0.133\"],[\"29307.10\",\"1.883\"],[\"29407.10\",\"0.084\"],[\"63686.00\",\"0.002\"],[\"71646.30\",\"0.002\"],[\"75626.80\",\"0.004\"],[\"78015.00\",\"0.125\"],[\"78146.40\",\"1.797\"],[\"78572.20\",\"1.035\"],[\"78811.00\",\"3.492\"],[\"79209.10\",\"1.274\"],[\"79491.70\",\"0.502\"],[\"79607.10\",\"10.369\"]],\"a\":[[\"79607.20\",\"1.062\"],[\"79608.20\",\"0.001\"],[\"79608.30\",\"0.077\"],[\"79608.40\",\"0.249\"],[\"79609.00\",\"0.029\"],[\"79609.30\",\"0.027\"],[\"79609.40\",\"0.106\"],[\"79610.40\",\"1.270\"],[\"79611.20\",\"0.090\"],[\"79619.30\",\"0.779\"],[\"79620.40\",\"0.000\"],[\"79621.40\",\"0.260\"],[\"79637.10\",\"0.000\"],[\"79638.30\",\"0.015\"],[\"79639.40\",\"0.048\"],[\"79973.40\",\"1.388\"],[\"80005.30\",\"0.002\"],[\"80403.30\",\"7.987\"],[\"80557.60\",\"14.667\"]],\"st\":1}}"}
{"receive_ns":1788563197712291000,"stream":"btcusdt@bookTicker","event_type":"bookTicker","event_time_ms":1788563197747,"raw_json":"{\"stream\":\"btcusdt@bookTicker\",\"data\":{\"e\":\"bookTicker\",\"u\":11478222768000,\"s\":\"BTCUSDT\",\"ps\":\"BTCUSDT\",\"b\":\"79607.10\",\"B\":\"10.388\",\"a\":\"79607.20\",\"A\":\"1.062\",\"T\":1788563197747,\"E\":1788563197747,\"st\":1}}"}
{"receive_ns":1788563197712957000,"stream":"btcusdt@bookTicker","event_type":"bookTicker","event_time_ms":1788563197748,"raw_json":"{\"stream\":\"btcusdt@bookTicker\",\"data\":{\"e\":\"bookTicker\",\"u\":11478222768090,\"s\":\"BTCUSDT\",\"ps\":\"BTCUSDT\",\"b\":\"79607.10\",\"B\":\"10.369\",\"a\":\"79607.20\",\"A\":\"1.062\",\"T\":1788563197748,\"E\":1788563197748,\"st\":1}}"}
{"receive_ns":1788563197725164000,"stream":"btcusdt@bookTicker","event_type":"bookTicker","event_time_ms":1788563197760,"raw_json":"{\"stream\":\"btcusdt@bookTicker\",\"data\":{\"e\":\"bookTicker\",\"u\":11478222768813,\"s\":\"BTCUSDT\",\"ps\":\"BTCUSDT\",\"b\":\"79607.10\",\"B\":\"10.377\",\"a\":\"79607.20\",\"A\":\"1.062\",\"T\":1788563197759,\"E\":1788563197760,\"st\":1}}"}
