{"receive_ns":1788563188124710000,"stream":"btcusdt@depth@100ms","event_type":"depthUpdate","event_time_ms":1788563188159,"raw_json":"{\"stream\":\"btcusdt@depth@100ms\",\"data\":{\"e\":\"depthUpdate\",\"E\":1788563188159,\"T\":1788563188158,\"s\":\"BTCUSDT\",\"ps\":\"BTCUSDT\",\"U\":11478222171751,\"u\":11478222181004,\"pu\":11478222171671,\"b\":[[\"29107.10\",\"1.890\"],[\"29207.10\",\"0.070\"],[\"29507.10\",\"0.140\"],[\"71646.30\",\"0.002\"],[\"76422.80\",\"0.000\"],[\"78015.00\",\"0.137\"],[\"78572.20\",\"0.527\"],[\"78811.00\",\"2.226\"],[\"78970.30\",\"0.002\"],[\"79209.10\",\"0.141\"],[\"79236.90\",\"0.247\"],[\"79434.00\",\"1.933\"],[\"79487.70\",\"0.076\"],[\"79511.40\",\"0.937\"],[\"79535.40\",\"0.002\"],[\"79582.60\",\"0.000\"],[\"79594.60\",\"0.041\"],[\"79604.50\",\"0.029\"],[\"79607.10\",\"10.039\"]],\"a\":[[\"79609.20\",\"0.502\"],[\"79609.90\",\"0.028\"],[\"79610.10\",\"0.027\"],[\"79610.60\",\"0.345\"],[\"79610.80\",\"0.002\"],[\"79611.20\",\"0.315\"],[\"79611.50\",\"0.596\"],[\"79613.00\",\"0.002\"],[\"79613.10\",\"0.002\"],[\"79613.30\",\"0.001\"],[\"79678.90\",\"0.018\"],[\"79682.80\",\"0.003\"],[\"79688.20\",\"0.001\"],[\"79688.40\",\"3.100\"],[\"79707.60\",\"8.783\"],[\"79714.70\",\"0.009\"],[\"79722.60\",\"1.568\"],[\"79755.00\",\"0.183\"],[\"79755.20\",\"0.000\"],[\"79802.30\",\"6.264\"],[\"79973.40\",\"1.913\"],[\"80403.30\",\"6.124\"],[\"80557.50\",\"2.481\"]],\"st\":1}}"}
{"receive_ns":1788563188184807000,"stream":"btcusdt@bookTicker","event_type":"bookTicker","event_time_ms":1788563188219,"raw_json":"{\"stream\":\"btcusdt@bookTicker\",\"data\":{\"e\":\"bookTicker\",\"u\":11478222184862,\"s\":\"BTCUSDT\",\"ps\":\"BTCUSDT\",\"b\":\"79607.10\",\"B\":\"10.229\",\"a\":\"79607.20\",\"A\":\"1.399\",\"T\":1788563188218,\"E\":1788563188219,\"st\":1}}"}
{"receive_ns":1788563188185006000,"stream":"btcusdt@bookTicker","event_type":"bookTicker","event_time_ms":1788563188220,"raw_json":"{\"stream\":\"btcusdt@bookTicker\",\"data\":{\"e\":\"bookTicker\",\"u\":11478222184910,\"s\":\"BTCUSDT\",\"ps\":\"BTCUSDT\",\"b\":\"79607.10\",\"B\":\"10.227\",\"a\":\"79607.20\",\"A\":\"1.399\",\"T\":1788563188220,\"E\":1788563188220,\"st\":1}}"}
{"receive_ns":1788563188234939000,"stream":"btcusdt@depth@100ms","event_type":"depthUpdate","event_time_ms":1788563188261,"raw_json":"{\"stream\":\"btcusdt@depth@100ms\",\"data\":{\"e\":\"depthUpdate\",\"E\":1788563188261,\"T\":1788563188258,\"s\":\"BTCUSDT\",\"ps\":\"BTCUSDT\",\"U\":11478222181044,\"u\":11478222187348,\"pu\":11478222181004,\"b\":[[\"1000.00\",\"24.604\"],[\"29107.10\",\"1.855\"],[\"29207.10\",\"0.000\"],[\"29507.10\",\"0.245\"],[\"71646.30\",\"0.002\"],[\"77925.70\",\"0.002\"],[\"78393.40\",\"0.631\"],[\"78404.10\",\"9.345\"],[\"78764.50\",\"0.000\"],[\"78811.00\",\"2.226\"],[\"79209.00\",\"0.001\"],[\"79434.00\",\"1.933\"],[\"79453.90\",\"0.204\"],[\"79479.00\",\"1.013\"],[\"79479.10\",\"0.596\"],[\"79531.30\",\"23.134\"],[\"79536.70\",\"0.000\"],[\"79538.40\",\"0.795\"],[\"79602.10\",\"0.000\"],[\"79602.40\",\"0.059\"],[\"79603.00\",\"0.001\"],[\"79607.10\",\"10.227\"]],\"a\":[[\"79609.20\",\"0.921\"],[\"79609.60\",\"0.033\"],[\"79609.70\",\"0.026\"],[\"79610.30\",\"0.690\"],[\"79610.40\",\"1.440\"],[\"79611.10\",\"0.001\"],[\"79611.20\",\"0.116\"],[\"79612.50\",\"0.001\"],[\"79612.80\",\"0.004\"],[\"79612.90\",\"0.001\"],[\"79614.40\",\"0.002\"],[\"79615.40\",\"1.321\"],[\"79707.80\",\"0.001\"],[\"79728.70\",\"0.418\"],[\"79755.10\",\"0.000\"],[\"79755.60\",\"0.000\"],[\"79973.40\",\"0.731\"],[\"80403.30\",\"6.124\"],[\"80557.50\",\"1.241\"],[\"80716.70\",\"0.927\"],[\"80952.60\",\"0.493\"]],\"st\":1}}"}
{"receive_ns":1788563188291734000,"stream":"btcusdt@bookTicker","event_type":"bookTicker","event_time_ms":1788563188326,"raw_json":"{\"stream\":\"btcusdt@bookTicker\",\"data\":{\"e\":\"bookTicker\",\"u\":11478222190838,\"s\":\"BTCUSDT\",\"ps\":\"BTCUSDT\",\"b\":\"79607.10\",\"B\":\"9.853\",\"a\":\"79607.20\",\"A\":\"1.399\",\"T\":1788563188326,\"E\":1788563188326,\"st\":1}}"}
{"receive_ns":1788563188299232000,"stream":"btcusdt@bookTicker","event_type":"bookTicker","event_time_ms":1788563188333,"raw_json":"{\"stream\":\"btcusdt@bookTicker\",\"data\":{\"e\":\"bookTicker\",\"u\":11478222191192,\"s\":\"BTCUSDT\",\"ps\":\"BTCUSDT\",\"b\":\"79607.10\",\"B\":\"9.872\",\"a\":\"79607.20\",\"A\":\"1.399\",\"T\":1788563188332,\"E\":1788563188333,\"st\":1}}"}
{"receive_ns":1788563188299524000,"stream":"btcusdt@bookTicker","event_type":"bookTicker","event_time_ms":1788563188333,"raw_json":"{\"stream\":\"btcusdt@bookTicker\",\"data\":{\"e\":\"bookTicker\",\"u\":11478222191221,\"s\":\"BTCUSDT\",\"ps\":\"BTCUSDT\",\"b\":\"79607.10\",\"B\":\"9.853\",\"a\":\"79607.20\",\"A\":\"1.399\",\"T\":1788563188333,\"E\":1788563188333,\"st\":1}}"}
{"receive_ns":1788563188299708000,"stream":"btcusdt@bookTicker","event_type":"bookTicker","event_time_ms":1788563188334,"raw_json":"{\"stream\":\"btcusdt@bookTicker\",\"data\":{\"e\":\"bookTicker\",\"u\":11478222191255,\"s\":\"BTCUSDT\",\"ps\":\"BTCUSDT\",\"b\":\"79607.10\",\"B\":\"9.855\",\"a\":\"79607.20\",\"A\":\"1.399\",\"T\":1788563188334,\"E\":1788563188334,\"st\":1}}"}
{"receive_ns":1788563188300488000,"stream":"btcusdt@bookTicker","event_type":"bookTicker","event_time_ms":1788563188335,"raw_json":"{\"stream\":\"btcusdt@bookTicker\",\"data\":{\"e\":\"bookTicker\",\"u\":11478222191314,\"s\":\"BTCUSDT\",\"ps\":\"BTCUSDT\",\"b\":\"79607.10\",\"B\":\"10.276\",\"a\":\"79607.20\",\"A\":\"1.399\",\"T\":1788563188335,\"E\":1788563188335,\"st\":1}}"}
{"receive_ns":1788563188317888000,"stream":"btcusdt@bookTicker","event_type":"bookTicker","event_time_ms":1788563188352,"raw_json":"{\"stream\":\"btcusdt@bookTicker\",\"data\":{\"e\":\"bookTicker\",\"u\":11478222192025,\"s\":\"BTCUSDT\",\"ps\":\"BTCUSDT\",\"b\":\"79607.10\",\"B\":\"10.095\",\"a\":\"79607.20\",\"A\":\"1.399\",\"T\":1788563188352,\"E\":1788563188352,\"st\":1}}"}
{"receive_ns":1788563188320502000,"stream":"btcusdt@bookTicker","event_type":"bookTicker","event_time_ms":1788563188355,"raw_json":"{\"stream\":\"btcusdt@bookTicker\",\"data\":{\"e\":\"bookTicker\",\"u\":11478222192245,\"s\":\"BTCUSDT\",\"ps\":\"BTCUSDT\",\"b\":\"79607.10\",\"B\":\"10.278\",\"a\":\"79607.20\",\"A\":\"1.399\",\"T\":1788563188355,\"E\":1788563188355,\"st\":1}}"}
{"receive_ns":1788563188320856000,"stream":"btcusdt@bookTicker","event_type":"bookTicker","event_time_ms":1788563188357,"raw_json":"{\"stream\":\"btcusdt@bookTicker\",\"data\":{\"e\":\"bookTicker\",\"u\":11478222192286,\"s\":\"BTCUSDT\",\"ps\":\"BTCUSDT\",\"b\":\"79607.10\",\"B\":\"10.276\",\"a\":\"79607.20\",\"A\":\"1.399\",\"T\":1788563188356,\"E\":1788563188357,\"st\":1}}"}
{"receive_ns":1788563188371071000,"stream":"btcusdt@depth@100ms","event_type":"depthUpdate","event_time_ms":1788563188363,"raw_json":"{\"stream\":\"btcusdt@depth@100ms\",\"data\":{\"e\":\"depthUpdate\",\"E\":1788563188363,\"T\":1788563188361,\"s\":\"BTCUSDT\",\"ps\":\"BTCUSDT\",\"U\":11478222187492,\"u\":11478222192557,\"pu\":11478222187348,\"b\":[[\"1000.00\",\"24.604\"],[\"29107.10\",\"1.673\"],[\"29507.10\",\"0.427\"],[\"63686.00\",\"0.002\"],[\"71646.30\",\"0.002\"],[\"76422.80\",\"0.002\"],[\"78444.80\",\"0.382\"],[\"78811.00\",\"2.226\"],[\"79209.10\",\"0.141\"],[\"79211.10\",\"0.000\"],[\"79236.90\",\"0.247\"],[\"79434.00\",\"1.933\"],[\"79453.90\",\"0.236\"],[\"79454.10\",\"1.578\"],[\"79487.70\",\"1.205\"],[\"79491.70\",\"0.075\"],[\"79518.90\",\"0.000\"],[\"79531.30\",\"0.011\"],[\"79534.00\",\"23.124\"],[\"79534.80\",\"0.000\"],[\"79597.70\",\"0.002\"],[\"79601.20\",\"0.131\"],[\"79602.20\",\"0.026\"],[\"79603.00\",\"0.001\"],[\"79607.10\",\"10.276\"]],\"a\":[[\"79609.20\",\"0.502\"],[\"79611.20\",\"0.315\"],[\"79614.40\",\"0.000\"],[\"79615.10\",\"0.002\"],[\"79628.00\",\"1.354\"],[\"79630.00\",\"3.512\"],[\"79674.10\",\"0.024\"],[\"79755.60\",\"0.000\"],[\"79973.40\",\"1.494\"],[\"80005.30\",\"0.002\"],[\"80403.30\",\"6.124\"]],\"st\":1}}"}
{"receive_ns":1788563188371436000,"stream":"btcusdt@bookTicker","event_type":"bookTicker","event_time_ms":1788563188369,"raw_json":"{\"stream\":\"btcusdt@bookTicker\",\"data\":{\"e\":\"bookTicker\",\"u\":11478222192841,\"s\":\"BTCUSDT\",\"ps\":\"BTCUSDT\",\"b\":\"79607.10\",\"B\":\"10.077\",\"a\":\"79607.20\",\"A\":\"1.399\",\"T\":1788563188369,\"E\":1788563188369,\"st\":1}}"}
{"receive_ns":1788563188371675000,"stream":"btcusdt@bookTicker","event_type":"bookTicker","event_time_ms":1788563188374,"raw_json":"{\"stream\":\"btcusdt@bookTicker\",\"data\":{\"e\":\"bookTicker\",\"u\":11478222193150,\"s\":\"BTCUSDT\",\"ps\":\"BTCUSDT\",\"b\":\"79607.10\",\"B\":\"10.277\",\"a\":\"79607.20\",\"A\":\"1.399\",\"T\":1788563188374,\"E\":1788563188374,\"st\":1}}"}
{"receive_ns":1788563188371913000,"stream":"btcusdt@bookTicker","event_type":"bookTicker","event_time_ms":1788563188375,"raw_json":"{\"stream\":\"btcusdt@bookTicker\",\"data\":{\"e\":\"bookTicker\",\"u\":11478222193181,\"s\":\"BTCUSDT\",\"ps\":\"BTCUSDT\",\"b\":\"79607.10\",\"B\":\"10.279\",\"a\":\"79607.20\",\"A\":\"1.399\",\"T\":1788563188375,\"E\":1788563188375,\"st\":1}}"}
{"receive_ns":1788563188372156000,"stream":"btcusdt@bookTicker","event_type":"bookTicker","event_time_ms":1788563188395,"raw_json":"{\"stream\":\"btcusdt@bookTicker\",\"data\":{\"e\":\"bookTicker\",\"u\":11478222194190,\"s\":\"BTCUSDT\",\"ps\":\"BTCUSDT\",\"b\":\"79607.10\",\"B\":\"10.279\",\"a\":\"79607.20\",\"A\":\"1.400\",\"T\":1788563188395,\"E\":1788563188395,\"st\":1}}"}
{"receive_ns":1788563188416438000,"stream":"btcusdt@bookTicker","event_type":"bookTicker","event_time_ms":1788563188452,"raw_json":"{\"stream\":\"btcusdt@bookTicker\",\"data\":{\"e\":\"bookTicker\",\"u\":11478222196765,\"s\":\"BTCUSDT\",\"ps\":\"BTCUSDT\",\"b\":\"79607.10\",\"B\":\"10.280\",\"a\":\"79607.20\",\"A\":\"1.400\",\"T\":1788563188452,\"E\":1788563188452,\"st\":1}}"}
{"receive_ns":1788563188429033000,"stream":"btcusdt@depth@100ms","event_type":"depthUpdate","event_time_ms":1788563188465,"raw_json":"{\"stream\":\"btcusdt@depth@100ms\",\"data\":{\"e\":\"depthUpdate\",\"E\":1788563188465,\"T\":1788563188462,\"s\":\"BTCUSDT\",\"ps\":\"BTCUSDT\",\"U\":11478222192622,\"u\":11478222197202,\"pu\":11478222192557,\"b\":[[\"29107.10\",\"1.498\"],[\"29507.10\",\"0.602\"],[\"71646.30\",\"0.002\"],[\"75626.70\",\"0.011\"],[\"76422.80\",\"0.000\"],[\"78811.00\",\"2.226\"],[\"79434.00\",\"0.427\"],[\"79453.90\",\"0.706\"],[\"79454.80\",\"0.041\"],[\"79487.70\",\"2.209\"],[\"79602.40\",\"0.059\"],[\"79603.00\",\"0.001\"],[\"79607.10\",\"10.280\"]],\"a\":[[\"79607.20\",\"1.400\"],[\"79632.00\",\"1.405\"],[\"79640.10\",\"0.000\"],[\"79973.40\",\"1.913\"],[\"80403.30\",\"6.124\"],[\"80562.50\",\"1.865\"],[\"81199.30\",\"0.021\"]],\"st\":1}}"}
{"receive_ns":1788563188453921000,"stream":"btcusdt@bookTicker","event_type":"bookTicker","event_time_ms":1788563188488,"raw_json":"{\"stream\":\"btcusdt@bookTicker\",\"data\":{\"e\":\"bookTicker\",\"u\":11478222198487,\"s\":\"BTCUSDT\",\"ps\":\"BTCUSDT\",\"b\":\"79607.10\",\"B\":\"10.016\",\"a\":\"79607.20\",\"A\":\"1.400\",\"T\":1788563188488,\"E\":1788563188488,\"st\":1}}"}
{"receive_ns":1788563188455335000,"stream":"btcusdt@bookTicker","event_type":"bookTicker","event_time_ms":1788563188491,"raw_json":"{\"stream\":\"btcusdt@bookTicker\",\"data\":{\"e\":\"bookTicker\",\"u\":11478222198708,\"s\":\"BTCUSDT\",\"ps\":\"BTCUSDT\",\"b\":\"79607.10\",\"B\":\"10.282\",\"a\":\"79607.20\",\"A\":\"1.400\",\"T\":1788563188491,\"E\":1788563188491,\"st\":1}}"}
{"receive_ns":1788563188469661000,"stream":"btcusdt@bookTicker","event_type":"bookTicker","event_time_ms":1788563188503,"raw_json":"{\"stream\":\"btcusdt@bookTicker\",\"data\":{\"e\":\"bookTicker\",\"u\":11478222199209,\"s\":\"BTCUSDT\",\"ps\":\"BTCUSDT\",\"b\":\"79607.10\",\"B\":\"10.282\",\"a\":\"79607.20\",\"A\":\"1.410\",\"T\":1788563188503,\"E\":1788563188503,\"st\":1}}"}
{"receive_ns":1788563188482336000,"stream":"btcusdt@bookTicker","event_type":"bookTicker","event_time_ms":1788563188510,"raw_json":"{\"stream\":\"btcusdt@bookTicker\",\"data\":{\"e\":\"bookTicker\",\"u\":11478222199648,\"s\":\"BTCUSDT\",\"ps\":\"BTCUSDT\",\"b\":\"79607.10\",\"B\":\"10.000\",\"a\":\"79607.20\",\"A\":\"1.410\",\"T\":1788563188510,\"E\":1788563188510,\"st\":1}}"}
{"receive_ns":1788563188490032000,"stream":"btcusdt@bookTicker","event_type":"bookTicker","event_time_ms":1788563188513,"raw_json":"{\"stream\":\"btcusdt@bookTicker\",\"data\":{\"e\":\"bookTicker\",\"u\":11478222199789,\"s\":\"BTCUSDT\",\"ps\":\"BTCUSDT\",\"b\":\"79607.10\",\"B\":\"10.287\",\"a\":\"79607.20\",\"A\":\"1.410\",\"T\":1788563188512,\"E\":1788563188513,\"st\":1}}"}
{"receive_ns":1788563188490373000,"stream":"btcusdt@bookTicker","event_type":"bookTicker","event_time_ms":1788563188513,"raw_json":"{\"stream\":\"btcusdt@bookTicker\",\"data\":{\"e\":\"bookTicker\",\"u\":11478222199837,\"s\":\"BTCUSDT\",\"ps\":\"BTCUSDT\",\"b\":\"79607.10\",\"B\":\"10.287\",\"a\":\"79607.20\",\"A\":\"1.409\",\"T\":1788563188513,\"E\":1788563188513,\"st\":1}}"}
{"receive_ns":1788563188490681000,"stream":"btcusdt@bookTicker","event_type":"bookTicker","event_time_ms":1788563188514,"raw_json":"{\"stream\":\"btcusdt@bookTicker\",\"data\":{\"e\":\"bookTicker\",\"u\":11478222199842,\"s\":\"BTCUSDT\",\"ps\":\"BTCUSDT\",\"b\":\"79607.10\",\"B\":\"10.286\",\"a\":\"79607.20\",\"A\":\"1.409\",\"T\":1788563188513,\"E\":1788563188514,\"st\":1}}"}
{"receive_ns":1788563188491045000,"stream":"btcusdt@bookTicker","event_type":"bookTicker","event_time_ms":1788563188515,"raw_json":"{\"stream\":\"btcusdt@bookTicker\",\"data\":{\"e\":\"bookTicker\",\"u\":11478222199906,\"s\":\"BTCUSDT\",\"ps\":\"BTCUSDT\",\"b\":\"79607.10\",\"B\":\"10.287\",\"a\":\"79607.20\",\"A\":\"1.409\",\"T\":1788563188514,\"E\":1788563188515,\"st\":1}}"}
{"receive_ns":1788563188528298000,"stream":"btcusdt@bookTicker","event_type":"bookTicker","event_time_ms":1788563188563,"raw_json":"{\"stream\":\"btcusdt@bookTicker\",\"data\":{\"e\":\"bookTicker\",\"u\":11478222202542,\"s\":\"BTCUSDT\",\"ps\":\"BTCUSDT\",\"b\":\"79607.10\",\"B\":\"10.306\",\"a\":\"79607.20\",\"A\":\"1.409\",\"T\":1788563188563,\"E\":1788563188563,\"st\":1}}"}
{"receive_ns":1788563188529611000,"stream":"btcusdt@bookTicker","event_type":"bookTicker","event_time_ms":1788563188564,"raw_json":"{\"stream\":\"btcusdt@bookTicker\",\"data\":{\"e\":\"bookTicker\",\"u\":11478222202572,\"s\":\"BTCUSDT\",\"ps\":\"BTCUSDT\",\"b\":\"79607.10\",\"B\":\"10.287\",\"a\":\"79607.20\",\"A\":\"1.409\",\"T\":1788563188564,\"E\":1788563188564,\"st\":1}}"}
{"receive_ns":1788563188530007000,"stream":"btcusdt@bookTicker","event_type":"bookTicker","event_time_ms":1788563188565,"raw_json":"{\"stream\":\"btcusdt@bookTicker\",\"data\":{\"e\":\"bookTicker\",\"u\":11478222202596,\"s\":\"BTCUSDT\",\"ps\":\"BTCUSDT\",\"b\":\"79607.10\",\"B\":\"10.287\",\"a\":\"79607.20\",\"A\":\"1.410\",\"T\":1788563188564,\"E\":1788563188565,\"st\":1}}"}
{"receive_ns":1788563188531029000,"stream":"btcusdt@depth@100ms","event_type":"depthUpdate","event_time_ms":1788563188567,"raw_json":"{\"stream\":\"btcusdt@depth@100ms\",\"data\":{\"e\":\"depthUpdate\",\"E\":1788563188567,\"T\":1788563188566,\"s\":\"BTCUSDT\",\"ps\":\"BTCUSDT\",\"U\":11478222197370,\"u\":11478222202728,\"pu\":11478222197202,\"b\":[[\"1000.00\",\"24.604\"],[\"29107.10\",\"1.316\"],[\"29507.10\",\"0.784\"],[\"71646.30\",\"0.002\"],[\"76422.80\",\"0.002\"],[\"78616.30\",\"0.000\"],[\"78618.70\",\"0.002\"],[\"78810.40\",\"0.443\"],[\"78811.00\",\"2.228\"],[\"79209.10\",\"0.141\"],[\"79221.80\",\"0.002\"],[\"79236.90\",\"0.247\"],[\"79301.50\",\"0.007\"],[\"79434.00\",\"0.427\"],[\"79439.60\",\"1.096\"],[\"79479.10\",\"0.000\"],[\"79487.70\",\"2.209\"],[\"79491.70\",\"0.075\"],[\"79604.90\",\"0.002\"],[\"79605.10\",\"0.000\"],[\"79607.10\",\"10.287\"]],\"a\":[[\"79607.20\",\"1.410\"],[\"79609.20\",\"0.592\"],[\"79609.60\",\"0.033\"],[\"79609.70\",\"0.000\"],[\"79609.90\",\"0.002\"],[\"79610.10\",\"0.001\"],[\"79610.30\",\"0.716\"],[\"79610.80\",\"0.028\"],[\"79611.20\",\"0.225\"],[\"79611.30\",\"0.367\"],[\"79617.40\",\"0.392\"],[\"79728.70\",\"0.000\"],[\"79768.10\",\"0.000\"],[\"79973.40\",\"1.913\"],[\"80000.40\",\"3.493\"],[\"80403.30\",\"6.126\"],[\"80562.50\",\"3.105\"],[\"80721.70\",\"6.185\"]],\"st\":1}}"}
{"receive_ns":1788563188603345000,"stream":"btcusdt@bookTicker","event_type":"bookTicker","event_time_ms":1788563188612,"raw_json":"{\"stream\":\"btcusdt@bookTicker\",\"data\":{\"e\":\"bookTicker\",\"u\":11478222205058,\"s\":\"BTCUSDT\",\"ps\":\"BTCUSDT\",\"b\":\"79607.10\",\"B\":\"10.306\",\"a\":\"79607.20\",\"A\":\"1.410\",\"T\":1788563188612,\"E\":1788563188612,\"st\":1}}"}
{"receive_ns":1788563188603975000,"stream":"btcusdt@bookTicker","event_type":"bookTicker","event_time_ms":1788563188613,"raw_json":"{\"stream\":\"btcusdt@bookTicker\",\"data\":{\"e\":\"bookTicker\",\"u\":11478222205113,\"s\":\"BTCUSDT\",\"ps\":\"BTCUSDT\",\"b\":\"79607.10\",\"B\":\"10.287\",\"a\":\"79607.20\",\"A\":\"1.410\",\"T\":1788563188613,\"E\":1788563188613,\"st\":1}}"}
{"receive_ns":1788563188604352000,"stream":"btcusdt@bookTicker","event_type":"bookTicker","event_time_ms":1788563188625,"raw_json":"{\"stream\":\"btcusdt@bookTicker\",\"data\":{\"e\":\"bookTicker\",\"u\":11478222206026,\"s\":\"BTCUSDT\",\"ps\":\"BTCUSDT\",\"b\":\"79607.10\",\"B\":\"10.306\",\"a\":\"79607.20\",\"A\":\"1.410\",\"T\":1788563188625,\"E\":1788563188625,\"st\":1}}"}
{"receive_ns":1788563188604781000,"stream":"btcusdt@bookTicker","event_type":"bookTicker","event_time_ms":1788563188626,"raw_json":"{\"stream\":\"btcusdt@bookTicker\",\"data\":{\"e\":\"bookTicker\",\"u\":11478222206111,\"s\":\"BTCUSDT\",\"ps\":\"BTCUSDT\",\"b\":\"79607.10\",\"B\":\"10.287\",\"a\":\"79607.20\",\"A\":\"1.410\",\"T\":1788563188625,\"E\":1788563188626,\"st\":1}}"}
{"receive_ns":1788563188616559000,"stream":"btcusdt@bookTicker","event_type":"bookTicker","event_time_ms":1788563188651,"raw_json":"{\"stream\":\"btcusdt@bookTicker\",\"data\":{\"e\":\"bookTicker\",\"u\":11478222207832,\"s\":\"BTCUSDT\",\"ps\":\"BTCUSDT\",\"b\":\"79607.10\",\"B\":\"10.287\",\"a\":\"79607.20\",\"A\":\"1.406\",\"T\":1788563188651,\"E\":1788563188651,\"st\":1}}"}
{"receive_ns":1788563188633551000,"stream":"btcusdt@depth@100ms","event_type":"depthUpdate","event_time_ms":1788563188669,"raw_json":"{\"stream\":\"btcusdt@depth@100ms\",\"data\":{\"e\":\"depthUpdate\",\"E\":1788563188669,\"T\":1788563188667,\"s\":\"BTCUSDT\",\"ps\":\"BTCUSDT\",\"U\":11478222202741,\"u\":11478222208833,\"pu\":11478222202728,\"b\":[[\"1000.00\",\"24.604\"],[\"29107.10\",\"1.141\"],[\"29507.10\",\"0.959\"],[\"63686.00\",\"0.002\"],[\"71646.30\",\"0.002\"],[\"71680.00\",\"0.127\"],[\"76422.80\",\"0.000\"],[\"78452.80\",\"0.916\"],[\"78811.00\",\"2.225\"],[\"79209.10\",\"0.151\"],[\"79439.70\",\"2.636\"],[\"79479.10\",\"0.633\"],[\"79582.70\",\"0.001\"],[\"79583.40\",\"1.875\"],[\"79583.60\",\"2.775\"],[\"79584.80\",\"0.309\"],[\"79607.10\",\"10.287\"]],\"a\":[[\"79607.20\",\"1.406\"],[\"79609.60\",\"0.033\"],[\"79609.80\",\"0.000\"],[\"79610.00\",\"0.004\"],[\"79610.10\",\"0.027\"],[\"79610.20\",\"0.077\"],[\"79611.80\",\"0.000\"],[\"79611.90\",\"0.078\"],[\"79612.70\",\"0.010\"],[\"79617.00\",\"0.002\"],[\"79617.30\",\"0.067\"],[\"79623.30\",\"0.045\"],[\"79623.80\",\"0.006\"],[\"79624.70\",\"1.117\"],[\"79728.70\",\"0.418\"],[\"79768.10\",\"1.978\"],[\"79797.70\",\"0.000\"],[\"79800.60\",\"0.095\"],[\"80399.20\",\"0.721\"],[\"80403.30\",\"6.124\"],[\"80593.20\",\"4.396\"]],\"st\":1}}"}
{"receive_ns":1788563188654927000,"stream":"btcusdt@bookTicker","event_type":"bookTicker","event_time_ms":1788563188690,"raw_json":"{\"stream\":\"btcusdt@bookTicker\",\"data\":{\"e\":\"bookTicker\",\"u\":11478222210404,\"s\":\"BTCUSDT\",\"ps\":\"BTCUSDT\",\"b\":\"79607.10\",\"B\":\"10.306\",\"a\":\"79607.20\",\"A\":\"1.406\",\"T\":1788563188690,\"E\":1788563188690,\"st\":1}}"}
{"receive_ns":1788563188655395000,"stream":"btcusdt@bookTicker","event_type":"bookTicker","event_time_ms":1788563188691,"raw_json":"{\"stream\":\"btcusdt@bookTicker\",\"data\":{\"e\":\"bookTicker\",\"u\":11478222210453,\"s\":\"BTCUSDT\",\"ps\":\"BTCUSDT\",\"b\":\"79607.10\",\"B\":\"10.287\",\"a\":\"79607.20\",\"A\":\"1.406\",\"T\":1788563188690,\"E\":1788563188691,\"st\":1}}"}
{"receive_ns":1788563188672630000,"stream":"btcusdt@bookTicker","event_type":"bookTicker","event_time_ms":1788563188708,"raw_json":"{\"stream\":\"btcusdt@bookTicker\",\"data\":{\"e\":\"bookTicker\",\"u\":11478222211608,\"s\":\"BTCUSDT\",\"ps\":\"BTCUSDT\",\"b\":\"79607.10\",\"B\":\"10.306\",\"a\":\"79607.20\",\"A\":\"1.406\",\"T\":1788563188707,\"E\":1788563188708,\"st\":1}}"}
{"receive_ns":1788563188673122000,"stream":"btcusdt@bookTicker","event_type":"bookTicker","event_time_ms":1788563188708,"raw_json":"{\"stream\":\"btcusdt@bookTicker\",\"data\":{\"e\":\"bookTicker\",\"u\":11478222211794,\"s\":\"BTCUSDT\",\"ps\":\"BTCUSDT\",\"b\":\"79607.10\",\"B\":\"10.287\",\"a\":\"79607.20\",\"A\":\"1.406\",\"T\":1788563188708,\"E\":1788563188708,\"st\":1}}"}
{"receive_ns":1788563188736309000,"stream":"btcusdt@depth@100ms","event_type":"depthUpdate","event_time_ms":1788563188771,"raw_json":"{\"stream\":\"btcusdt@depth@100ms\",\"data\":{\"e\":\"depthUpdate\",\"E\":1788563188771,\"T\":1788563188770,\"s\":\"BTCUSDT\",\"ps\":\"BTCUSDT\",\"U\":11478222209125,\"u\":11478222215484,\"pu\":11478222208833,\"b\":[[\"29107.10\",\"0.959\"],[\"29507.10\",\"1.141\"],[\"63686.00\",\"0.002\"],[\"71646.30\",\"0.002\"],[\"78015.00\",\"0.134\"],[\"78811.00\",\"2.225\"],[\"79453.90\",\"0.204\"],[\"79487.70\",\"1.507\"],[\"79491.70\",\"1.279\"],[\"79607.10\",\"10.287\"]],\"a\":[[\"79610.10\",\"0.001\"],[\"79610.20\",\"0.051\"],[\"79610.30\",\"0.690\"],[\"79610.80\",\"0.002\"],[\"79610.90\",\"0.001\"],[\"79611.20\",\"0.225\"],[\"79611.80\",\"0.026\"],[\"79611.90\",\"0.104\"],[\"79612.00\",\"0.054\"],[\"79612.10\",\"0.028\"],[\"79973.40\",\"1.913\"],[\"80403.30\",\"6.124\"],[\"80681.90\",\"0.988\"],[\"81199.30\",\"0.018\"]],\"st\":1}}"}
{"receive_ns":1788563188800954000,"stream":"btcusdt@bookTicker","event_type":"bookTicker","event_time_ms":1788563188835,"raw_json":"{\"stream\":\"btcusdt@bookTicker\",\"data\":{\"e\":\"bookTicker\",\"u\":11478222219091,\"s\":\"BTCUSDT\",\"ps\":\"BTCUSDT\",\"b\":\"79607.10\",\"B\":\"10.287\",\"a\":\"79607.20\",\"A\":\"1.136\",\"T\":1788563188835,\"E\":1788563188835,\"st\":1}}"}
{"receive_ns":1788563188801422000,"stream":"btcusdt@trade","event_type":"trade","event_time_ms":1788563188835,"raw_json":"{\"stream\":\"btcusdt@trade\",\"data\":{\"e\":\"trade\",\"E\":1788563188835,\"T\":1788563188835,\"s\":\"BTCUSDT\",\"t\":8054082654,\"p\":\"79607.20\",\"q\":\"0.270\",\"X\":\"MARKET\",\"m\":false,\"st\":1}}"}
{"receive_ns":1788563188801861000,"stream":"btcusdt@bookTicker","event_type":"bookTicker","event_time_ms":1788563188835,"raw_json":"{\"stream\":\"btcusdt@bookTicker\",\"data\":{\"e\":\"bookTicker\",\"u\":11478222219135,\"s\":\"BTCUSDT\",\"ps\":\"BTCUSDT\",\"b\":\"79607.10\",\"B\":\"10.051\",\"a\":\"79607.20\",\"A\":\"1.136\",\"T\":1788563188835,\"E\":1788563188835,\"st\":1}}"}
{"receive_ns":1788563188802270000,"stream":"btcusdt@trade","event_type":"trade","event_time_ms":1788563188835,"raw_json":"{\"stream\":\"btcusdt@trade\",\"data\":{\"e\":\"trade\",\"E\":1788563188835,\"T\":1788563188835,\"s\":\"BTCUSDT\",\"t\":8054082655,\"p\":\"79607.10\",\"q\":\"0.236\",\"X\":\"MARKET\",\"m\":true,\"st\":1}}"}
{"receive_ns":1788563188802704000,"stream":"btcusdt@bookTicker","event_type":"bookTicker","event_time_ms":1788563188836,"raw_json":"{\"stream\":\"btcusdt@bookTicker\",\"data\":{\"e\":\"bookTicker\",\"u\":11478222219192,\"s\":\"BTCUSDT\",\"ps\":\"BTCUSDT\",\"b\":\"79607.10\",\"B\":\"10.052\",\"a\":\"79607.20\",\"A\":\"1.136\",\"T\":1788563188836,\"E\":1788563188836,\"st\":1}}"}
{"receive_ns":1788563188803132000,"stream":"btcusdt@bookTicker","event_type":"bookTicker","event_time_ms":1788563188836,"raw_json":"{\"stream\":\"btcusdt@bookTicker\",\"data\":{\"e\":\"bookTicker\",\"u\":11478222219212,\"s\":\"BTCUSDT\",\"ps\":\"BTCUSDT\",\"b\":\"79607.10\",\"B\":\"10.052\",\"a\":\"79607.20\",\"A\":\"1.137\",\"T\":1788563188836,\"E\":1788563188836,\"st\":1}}"}
{"receive_ns":1788563188803580000,"stream":"btcusdt@bookTicker","event_type":"bookTicker","event_time_ms":1788563188836,"raw_json":"{\"stream\":\"btcusdt@bookTicker\",\"data\":{\"e\":\"bookTicker\",\"u\":11478222219296,\"s\":\"BTCUSDT\",\"ps\":\"BTCUSDT\",\"b\":\"79607.10\",\"B\":\"10.060\",\"a\":\"79607.20\",\"A\":\"1.137\",\"T\":1788563188836,\"E\":1788563188836,\"st\":1}}"}
{"receive_ns":1788563188804020000,"stream":"btcusdt@bookTicker","event_type":"bookTicker","event_time_ms":1788563188836,"raw_json":"{\"stream\":\"btcusdt@bookTicker\",\"data\":{\"e\":\"bookTicker\",\"u\":11478222219297,\"s\":\"BTCUSDT\",\"ps\":\"BTCUSDT\",\"b\":\"79607.10\",\"B\":\"10.079\",\"a\":\"79607.20\",\"A\":\"1.137\",\"T\":1788563188836,\"E\":1788563188836,\"st\":1}}"}
{"receive_ns":1788563188804480000,"stream":"btcusdt@bookTicker","event_type":"bookTicker","event_time_ms":1788563188837,"raw_json":"{\"stream\":\"btcusdt@bookTicker\",\"data\":{\"e\":\"bookTicker\",\"u\":11478222219398,\"s\":\"BTCUSDT\",\"ps\":\"BTCUSDT\",\"b\":\"79607.10\",\"B\":\"10.087\",\"a\":\"79607.20\",\"A\":\"1.137\",\"T\":1788563188836,\"E\":1788563188837,\"st\":1}}"}
{"receive_ns":1788563188804927000,"stream":"btcusdt@bookTicker","event_type":"bookTicker","event_time_ms":1788563188837,"raw_json":"{\"stream\":\"btcusdt@bookTicker\",\"data\":{\"e\":\"bookTicker\",\"u\":11478222219466,\"s\":\"BTCUSDT\",\"ps\":\"BTCUSDT\",\"b\":\"79607.10\",\"B\":\"10.087\",\"a\":\"79607.20\",\"A\":\"1.287\",\"T\":1788563188837,\"E\":1788563188837,\"st\":1}}"}
{"receive_ns":1788563188805381000,"stream":"btcusdt@bookTicker","event_type":"bookTicker","event_time_ms":1788563188837,"raw_json":"{\"stream\":\"btcusdt@bookTicker\",\"data\":{\"e\":\"bookTicker\",\"u\":11478222219483,\"s\":\"BTCUSDT\",\"ps\":\"BTCUSDT\",\"b\":\"79607.10\",\"B\":\"10.068\",\"a\":\"79607.20\",\"A\":\"1.287\",\"T\":1788563188837,\"E\":1788563188837,\"st\":1}}"}
{"receive_ns":1788563188805839000,"stream":"btcusdt@bookTicker","event_type":"bookTicker","event_time_ms":1788563188837,"raw_json":"{\"stream\":\"btcusdt@bookTicker\",\"data\":{\"e\":\"bookTicker\",\"u\":11478222219489,\"s\":\"BTCUSDT\",\"ps\":\"BTCUSDT\",\"b\":\"79607.10\",\"B\":\"10.060\",\"a\":\"79607.20\",\"A\":\"1.287\",\"T\":1788563188837,\"E\":1788563188837,\"st\":1}}"}
{"receive_ns":1788563188806432000,"stream":"btcusdt@bookTicker","event_type":"bookTicker","event_time_ms":1788563188837,"raw_json":"{\"stream\":\"btcusdt@bookTicker\",\"data\":{\"e\":\"bookTicker\",\"u\":11478222219562,\"s\":\"BTCUSDT\",\"ps\":\"BTCUSDT\",\"b\":\"79607.10\",\"B\":\"10.052\",\"a\":\"79607.20\",\"A\":\"1.287\",\"T\":1788563188837,\"E\":1788563188837,\"st\":1}}"}
{"receive_ns":1788563188806965000,"stream":"btcusdt@bookTicker","event_type":"bookTicker","event_time_ms":1788563188837,"raw_json":"{\"stream\":\"btcusdt@bookTicker\",\"data\":{\"e\":\"bookTicker\",\"u\":11478222219581,\"s\":\"BTCUSDT\",\"ps\":\"BTCUSDT\",\"b\":\"79607.10\",\"B\":\"10.052\",\"a\":\"79607.20\",\"A\":\"1.137\",\"T\":1788563188837,\"E\":1788563188837,\"st\":1}}"}
{"receive_ns":1788563188807933000,"stream":"btcusdt@bookTicker","event_type":"bookTicker","event_time_ms":1788563188838,"raw_json":"{\"stream\":\"btcusdt@bookTicker\",\"data\":{\"e\":\"bookTicker\",\"u\":11478222219606,\"s\":\"BTCUSDT\",\"ps\":\"BTCUSDT\",\"b\":\"79607.10\",\"B\":\"10.051\",\"a\":\"79607.20\",\"A\":\"1.137\",\"T\":1788563188837,\"E\":1788563188838,\"st\":1}}"}
{"receive_ns":1788563188808646000,"stream":"btcusdt@bookTicker","event_type":"bookTicker","event_time_ms":1788563188838,"raw_json":"{\"stream\":\"btcusdt@bookTicker\",\"data\":{\"e\":\"bookTicker\",\"u\":11478222219610,\"s\":\"BTCUSDT\",\"ps\":\"BTCUSDT\",\"b\":\"79607.10\",\"B\":\"10.051\",\"a\":\"79607.20\",\"A\":\"1.136\",\"T\":1788563188837,\"E\":1788563188838,\"st\":1}}"}
{"receive_ns":1788563188809155000,"stream":"btcusdt@bookTicker","event_type":"bookTicker","event_time_ms":1788563188838,"raw_json":"{\"stream\":\"btcusdt@bookTicker\",\"data\":{\"e\":\"bookTicker\",\"u\":11478222219663,\"s\":\"BTCUSDT\",\"ps\":\"BTCUSDT\",\"b\":\"79607.10\",\"B\":\"10.051\",\"a\":\"79607.20\",\"A\":\"1.135\",\"T\":1788563188838,\"E\":1788563188838,\"st\":1}}"}
{"receive_ns":1788563188809661000,"stream":"btcusdt@bookTicker","event_type":"bookTicker","event_time_ms":1788563188838,"raw_json":"{\"stream\":\"btcusdt@bookTicker\",\"data\":{\"e\":\"bookTicker\",\"u\":11478222219676,\"s\":\"BTCUSDT\",\"ps\":\"BTCUSDT\",\"b\":\"79607.10\",\"B\":\"10.070\",\"a\":\"79607.20\",\"A\":\"1.135\",\"T\":1788563188838,\"E\":1788563188838,\"st\":1}}"}
{"receive_ns":1788563188810192000,"stream":"btcusdt@bookTicker","event_type":"bookTicker","event_time_ms":1788563188838,"raw_json":"{\"stream\":\"btcusdt@bookTicker\",\"data\":{\"e\":\"bookTicker\",\"u\":11478222219685,\"s\":\"BTCUSDT\",\"ps\":\"BTCUSDT\",\"b\":\"79607.10\",\"B\":\"10.078\",\"a\":\"79607.20\",\"A\":\"1.135\",\"T\":1788563188838,\"E\":1788563188838,\"st\":1}}"}
{"receive_ns":1788563188810698000,"stream":"btcusdt@bookTicker","event_type":"bookTicker","event_time_ms":1788563188839,"raw_json":"{\"stream\":\"btcusdt@bookTicker\",\"data\":{\"e\":\"bookTicker\",\"u\":11478222219758,\"s\":\"BTCUSDT\",\"ps\":\"BTCUSDT\",\"b\":\"79607.10\",\"B\":\"10.086\",\"a\":\"79607.20\",\"A\":\"1.135\",\"T\":1788563188838,\"E\":1788563188839,\"st\":1}}"}
{"receive_ns":1788563188811242000,"stream":"btcusdt@bookTicker","event_type":"bookTicker","event_time_ms":1788563188839,"raw_json":"{\"stream\":\"btcusdt@bookTicker\",\"data\":{\"e\":\"bookTicker\",\"u\":11478222219827,\"s\":\"BTCUSDT\",\"ps\":\"BTCUSDT\",\"b\":\"79607.10\",\"B\":\"10.067\",\"a\":\"79607.20\",\"A\":\"1.135\",\"T\":1788563188839,\"E\":1788563188839,\"st\":1}}"}
{"receive_ns":1788563188811768000,"stream":"btcusdt@bookTicker","event_type":"bookTicker","event_time_ms":1788563188839,"raw_json":"{\"stream\":\"btcusdt@bookTicker\",\"data\":{\"e\":\"bookTicker\",\"u\":11478222219845,\"s\":\"BTCUSDT\",\"ps\":\"BTCUSDT\",\"b\":\"79607.10\",\"B\":\"10.067\",\"a\":\"79607.20\",\"A\":\"1.136\",\"T\":1788563188839,\"E\":1788563188839,\"st\":1}}"}
{"receive_ns":1788563188812291000,"stream":"btcusdt@bookTicker","event_type":"bookTicker","event_time_ms":1788563188839,"raw_json":"{\"stream\":\"btcusdt@bookTicker\",\"data\":{\"e\":\"bookTicker\",\"u\":11478222219855,\"s\":\"BTCUSDT\",\"ps\":\"BTCUSDT\",\"b\":\"79607.10\",\"B\":\"10.059\",\"a\":\"79607.20\",\"A\":\"1.136\",\"T\":1788563188839,\"E\":1788563188839,\"st\":1}}"}
{"receive_ns":1788563188812837000,"stream":"btcusdt@bookTicker","event_type":"bookTicker","event_time_ms":1788563188839,"raw_json":"{\"stream\":\"btcusdt@bookTicker\",\"data\":{\"e\":\"bookTicker\",\"u\":11478222219868,\"s\":\"BTCUSDT\",\"ps\":\"BTCUSDT\",\"b\":\"79607.10\",\"B\":\"10.051\",\"a\":\"79607.20\",\"A\":\"1.136\",\"T\":1788563188839,\"E\":1788563188839,\"st\":1}}"}
{"receive_ns":1788563188813390000,"stream":"btcusdt@bookTicker","event_type":"bookTicker","event_time_ms":1788563188845,"raw_json":"{\"stream\":\"btcusdt@bookTicker\",\"data\":{\"e\":\"bookTicker\",\"u\":11478222220352,\"s\":\"BTCUSDT\",\"ps\":\"BTCUSDT\",\"b\":\"79607.10\",\"B\":\"10.051\",\"a\":\"79607.20\",\"A\":\"1.135\",\"T\":1788563188845,\"E\":1788563188845,\"st\":1}}"}
{"receive_ns":1788563188813938000,"stream":"btcusdt@trade","event_type":"trade","event_time_ms":1788563188845,"raw_json":"{\"stream\":\"btcusdt@trade\",\"data\":{\"e\":\"trade\",\"E\":1788563188845,\"T\":1788563188845,\"s\":\"BTCUSDT\",\"t\":8054082656,\"p\":\"79607.20\",\"q\":\"0.001\",\"X\":\"MARKET\",\"m\":false,\"st\":1}}"}
{"receive_ns":1788563188814505000,"stream":"btcusdt@bookTicker","event_type":"bookTicker","event_time_ms":1788563188847,"raw_json":"{\"stream\":\"btcusdt@bookTicker\",\"data\":{\"e\":\"bookTicker\",\"u\":11478222220464,\"s\":\"BTCUSDT\",\"ps\":\"BTCUSDT\",\"b\":\"79607.10\",\"B\":\"10.059\",\"a\":\"79607.20\",\"A\":\"1.135\",\"T\":1788563188846,\"E\":1788563188847,\"st\":1}}"}
{"receive_ns":1788563188815447000,"stream":"btcusdt@bookTicker","event_type":"bookTicker","event_time_ms":1788563188847,"raw_json":"{\"stream\":\"btcusdt@bookTicker\",\"data\":{\"e\":\"bookTicker\",\"u\":11478222220525,\"s\":\"BTCUSDT\",\"ps\":\"BTCUSDT\",\"b\":\"79607.10\",\"B\":\"10.078\",\"a\":\"79607.20\",\"A\":\"1.135\",\"T\":1788563188847,\"E\":1788563188847,\"st\":1}}"}
{"receive_ns":1788563188819576000,"stream":"btcusdt@bookTicker","event_type":"bookTicker","event_time_ms":1788563188847,"raw_json":"{\"stream\":\"btcusdt@bookTicker\",\"data\":{\"e\":\"bookTicker\",\"u\":11478222220663,\"s\":\"BTCUSDT\",\"ps\":\"BTCUSDT\",\"b\":\"79607.10\",\"B\":\"10.070\",\"a\":\"79607.20\",\"A\":\"1.135\",\"T\":1788563188847,\"E\":1788563188847,\"st\":1}}"}
{"receive_ns":1788563188820192000,"stream":"btcusdt@bookTicker","event_type":"bookTicker","event_time_ms":1788563188848,"raw_json":"{\"stream\":\"btcusdt@bookTicker\",\"data\":{\"e\":\"bookTicker\",\"u\":11478222220679,\"s\":\"BTCUSDT\",\"ps\":\"BTCUSDT\",\"b\":\"79607.10\",\"B\":\"10.051\",\"a\":\"79607.20\",\"A\":\"1.135\",\"T\":1788563188847,\"E\":1788563188848,\"st\":1}}"}
{"receive_ns":1788563188838954000,"stream":"btcusdt@depth@100ms","event_type":"depthUpdate","event_time_ms":1788563188873,"raw_json":"{\"stream\":\"btcusdt@depth@100ms\",\"data\":{\"e\":\"depthUpdate\",\"E\":1788563188873,\"T\":1788563188872,\"s\":\"BTCUSDT\",\"ps\":\"BTCUSDT\",\"U\":11478222215557,\"u\":11478222221838,\"pu\":11478222215484,\"b\":[[\"1000.00\",\"24.604\"],[\"29107.10\",\"0.784\"],[\"29507.10\",\"1.316\"],[\"63685.70\",\"0.003\"],[\"71646.30\",\"0.002\"],[\"76422.80\",\"0.002\"],[\"78811.00\",\"2.225\"],[\"79209.10\",\"0.151\"],[\"79236.90\",\"0.247\"],[\"79434.00\",\"0.176\"],[\"79439.70\",\"0.000\"],[\"79439.80\",\"2.575\"],[\"79477.80\",\"0.000\"],[\"79477.90\",\"0.830\"],[\"79479.10\",\"0.000\"],[\"79479.20\",\"0.596\"],[\"79491.70\",\"1.530\"],[\"79575.30\",\"0.453\"],[\"79576.20\",\"0.001\"],[\"79582.60\",\"0.373\"],[\"79583.60\",\"2.402\"],[\"79586.70\",\"0.000\"],[\"79589.20\",\"0.195\"],[\"79594.60\",\"0.061\"],[\"79595.50\",\"0.001\"],[\"79601.90\",\"0.081\"],[\"79602.40\",\"0.060\"],[\"79603.00\",\"0.000\"],[\"79604.90\",\"0.000\"],[\"79605.10\",\"0.076\"],[\"79605.30\",\"0.003\"],[\"79607.10\",\"10.051\"]],\"a\":[[\"79607.20\",\"1.135\"],[\"79607.30\",\"0.003\"],[\"79607.80\",\"0.077\"],[\"79609.20\",\"0.000\"],[\"79609.60\",\"0.032\"],[\"79611.20\",\"0.251\"],[\"79611.30\",\"0.341\"],[\"79611.50\",\"0.570\"],[\"79611.60\",\"0.001\"],[\"79611.70\",\"0.003\"],[\"79611.80\",\"0.000\"],[\"79611.90\",\"0.078\"],[\"79612.00\",\"0.280\"],[\"79612.10\",\"0.002\"],[\"79612.20\",\"0.905\"],[\"79612.30\",\"2.649\"],[\"79612.40\",\"0.001\"],[\"79612.50\",\"0.001\"],[\"79612.60\",\"0.026\"],[\"79612.70\",\"0.036\"],[\"79612.80\",\"0.030\"],[\"79613.00\",\"0.028\"],[\"79613.10\",\"0.028\"],[\"79613.20\",\"0.026\"],[\"79613.30\",\"0.027\"],[\"79613.40\",\"0.105\"],[\"79614.30\",\"0.002\"],[\"79614.70\",\"0.252\"],[\"79615.20\",\"0.065\"],[\"79615.30\",\"0.700\"],[\"79622.50\",\"0.372\"],[\"79624.70\",\"0.745\"],[\"79625.70\",\"0.453\"],[\"79626.40\",\"0.006\"],[\"79626.50\",\"0.000\"],[\"79650.40\",\"0.003\"],[\"79690.00\",\"0.362\"],[\"79702.80\",\"0.008\"],[\"79728.70\",\"0.418\"],[\"79768.10\",\"1.978\"],[\"79822.40\",\"0.026\"],[\"79834.10\",\"0.001\"],[\"79973.40\",\"1.913\"],[\"80403.30\",\"6.126\"],[\"80756.60\",\"6.186\"],[\"80836.20\",\"3.245\"]],\"st\":1}}"}
{"receive_ns":1788563188839916000,"stream":"btcusdt@bookTicker","event_type":"bookTicker","event_time_ms":1788563188873,"raw_json":"{\"stream\":\"btcusdt@bookTicker\",\"data\":{\"e\":\"bookTicker\",\"u\":11478222221854,\"s\":\"BTCUSDT\",\"ps\":\"BTCUSDT\",\"b\":\"79607.10\",\"B\":\"10.070\",\"a\":\"79607.20\",\"A\":\"1.135\",\"T\":1788563188873,\"E\":1788563188873,\"st\":1}}"}
{"receive_ns":1788563188841131000,"stream":"btcusdt@bookTicker","event_type":"bookTicker","event_time_ms":1788563188873,"raw_json":"{\"stream\":\"btcusdt@bookTicker\",\"data\":{\"e\":\"bookTicker\",\"u\":11478222221879,\"s\":\"BTCUSDT\",\"ps\":\"BTCUSDT\",\"b\":\"79607.10\",\"B\":\"10.051\",\"a\":\"79607.20\",\"A\":\"1.135\",\"T\":1788563188873,\"E\":1788563188873,\"st\":1}}"}
{"receive_ns":1788563188900231000,"stream":"btcusdt@bookTicker","event_type":"bookTicker","event_time_ms":1788563188934,"raw_json":"{\"stream\":\"btcusdt@bookTicker\",\"data\":{\"e\":\"bookTicker\",\"u\":11478222224953,\"s\":\"BTCUSDT\",\"ps\":\"BTCUSDT\",\"b\":\"79607.10\",\"B\":\"10.052\",\"a\":\"79607.20\",\"A\":\"1.135\",\"T\":1788563188934,\"E\":1788563188934,\"st\":1}}"}
{"receive_ns":1788563188940380000,"stream":"btcusdt@depth@100ms","event_type":"depthUpdate","event_time_ms":1788563188975,"raw_json":"{\"stream\":\"btcusdt@depth@100ms\",\"data\":{\"e\":\"depthUpdate\",\"E\":1788563188975,\"T\":1788563188974,\"s\":\"BTCUSDT\",\"ps\":\"BTCUSDT\",\"U\":11478222221854,\"u\":11478222227775,\"pu\":11478222221838,\"b\":[[\"1000.00\",\"24.604\"],[\"29107.10\",\"0.602\"],[\"29507.10\",\"1.498\"],[\"63685.70\",\"0.001\"],[\"63686.00\",\"0.004\"],[\"71646.30\",\"0.002\"],[\"75626.70\",\"0.009\"],[\"75626.80\",\"0.002\"],[\"76422.80\",\"0.000\"],[\"78404.10\",\"9.058\"],[\"78811.00\",\"2.225\"],[\"79204.30\",\"3.842\"],[\"79209.00\",\"0.000\"],[\"79209.10\",\"0.151\"],[\"79434.00\",\"1.682\"],[\"79487.70\",\"0.001\"],[\"79575.30\",\"0.001\"],[\"79576.70\",\"0.807\"],[\"79593.40\",\"0.046\"],[\"79594.60\",\"0.021\"],[\"79607.10\",\"10.052\"]],\"a\":[[\"79607.30\",\"0.002\"],[\"79611.20\",\"0.670\"],[\"79612.50\",\"0.027\"],[\"79622.50\",\"0.000\"],[\"79623.90\",\"1.672\"],[\"79625.70\",\"0.001\"],[\"79626.30\",\"0.455\"],[\"79653.00\",\"0.001\"],[\"79752.60\",\"0.012\"],[\"79826.50\",\"0.002\"],[\"79834.10\",\"0.000\"],[\"79973.40\",\"1.494\"],[\"80277.70\",\"0.005\"],[\"80403.30\",\"6.124\"],[\"81199.30\",\"0.021\"]],\"st\":1}}"}
{"receive_ns":1788563188988066000,"stream":"btcusdt@bookTicker","event_type":"bookTicker","event_time_ms":1788563189020,"raw_json":"{\"stream\":\"btcusdt@bookTicker\",\"data\":{\"e\":\"bookTicker\",\"u\":11478222230385,\"s\":\"BTCUSDT\",\"ps\":\"BTCUSDT\",\"b\":\"79607.10\",\"B\":\"10.048\",\"a\":\"79607.20\",\"A\":\"1.135\",\"T\":1788563189019,\"E\":1788563189020,\"st\":1}}"}
{"receive_ns":1788563188988771000,"stream":"btcusdt@trade","event_type":"trade","event_time_ms":1788563189020,"raw_json":"{\"stream\":\"btcusdt@trade\",\"data\":{\"e\":\"trade\",\"E\":1788563189020,\"T\":1788563189019,\"s\":\"BTCUSDT\",\"t\":8054082657,\"p\":\"79607.10\",\"q\":\"0.004\",\"X\":\"MARKET\",\"m\":true,\"st\":1}}"}
{"receive_ns":1788563188989425000,"stream":"btcusdt@bookTicker","event_type":"bookTicker","event_time_ms":1788563189021,"raw_json":"{\"stream\":\"btcusdt@bookTicker\",\"data\":{\"e\":\"bookTicker\",\"u\":11478222230489,\"s\":\"BTCUSDT\",\"ps\":\"BTCUSDT\",\"b\":\"79607.10\",\"B\":\"10.056\",\"a\":\"79607.20\",\"A\":\"1.135\",\"T\":1788563189021,\"E\":1788563189021,\"st\":1}}"}
{"receive_ns":1788563188990077000,"stream":"btcusdt@bookTicker","event_type":"bookTicker","event_time_ms":1788563189021,"raw_json":"{\"stream\":\"btcusdt@bookTicker\",\"data\":{\"e\":\"bookTicker\",\"u\":11478222230500,\"s\":\"BTCUSDT\",\"ps\":\"BTCUSDT\",\"b\":\"79607.10\",\"B\":\"10.075\",\"a\":\"79607.20\",\"A\":\"1.135\",\"T\":1788563189021,\"E\":1788563189021,\"st\":1}}"}
{"receive_ns":1788563188990725000,"stream":"btcusdt@bookTicker","event_type":"bookTicker","event_time_ms":1788563189021,"raw_json":"{\"stream\":\"btcusdt@bookTicker\",\"data\":{\"e\":\"bookTicker\",\"u\":11478222230576,\"s\":\"BTCUSDT\",\"ps\":\"BTCUSDT\",\"b\":\"79607.10\",\"B\":\"10.028\",\"a\":\"79607.20\",\"A\":\"1.135\",\"T\":1788563189021,\"E\":1788563189021,\"st\":1}}"}
{"receive_ns":1788563188991397000,"stream":"btcusdt@bookTicker","event_type":"bookTicker","event_time_ms":1788563189021,"raw_json":"{\"stream\":\"btcusdt@bookTicker\",\"data\":{\"e\":\"bookTicker\",\"u\":11478222230593,\"s\":\"BTCUSDT\",\"ps\":\"BTCUSDT\",\"b\":\"79607.10\",\"B\":\"10.028\",\"a\":\"79607.20\",\"A\":\"1.112\",\"T\":1788563189021,\"E\":1788563189021,\"st\":1}}"}
{"receive_ns":1788563188992059000,"stream":"btcusdt@bookTicker","event_type":"bookTicker","event_time_ms":1788563189021,"raw_json":"{\"stream\":\"btcusdt@bookTicker\",\"data\":{\"e\":\"bookTicker\",\"u\":11478222230596,\"s\":\"BTCUSDT\",\"ps\":\"BTCUSDT\",\"b\":\"79607.10\",\"B\":\"10.020\",\"a\":\"79607.20\",\"A\":\"1.112\",\"T\":1788563189021,\"E\":1788563189021,\"st\":1}}"}
{"receive_ns":1788563188992724000,"stream":"btcusdt@bookTicker","event_type":"bookTicker","event_time_ms":1788563189022,"raw_json":"{\"stream\":\"btcusdt@bookTicker\",\"data\":{\"e\":\"bookTicker\",\"u\":11478222230611,\"s\":\"BTCUSDT\",\"ps\":\"BTCUSDT\",\"b\":\"79607.10\",\"B\":\"10.001\",\"a\":\"79607.20\",\"A\":\"1.112\",\"T\":1788563189021,\"E\":1788563189022,\"st\":1}}"}
{"receive_ns":1788563189037636000,"stream":"btcusdt@bookTicker","event_type":"bookTicker","event_time_ms":1788563189073,"raw_json":"{\"stream\":\"btcusdt@bookTicker\",\"data\":{\"e\":\"bookTicker\",\"u\":11478222233886,\"s\":\"BTCUSDT\",\"ps\":\"BTCUSDT\",\"b\":\"79607.10\",\"B\":\"10.001\",\"a\":\"79607.20\",\"A\":\"1.110\",\"T\":1788563189073,\"E\":1788563189073,\"st\":1}}"}
{"receive_ns":1788563189041647000,"stream":"btcusdt@depth@100ms","event_type":"depthUpdate","event_time_ms":1788563189077,"raw_json":"{\"stream\":\"btcusdt@depth@100ms\",\"data\":{\"e\":\"depthUpdate\",\"E\":1788563189077,\"T\":1788563189075,\"s\":\"BTCUSDT\",\"ps\":\"BTCUSDT\",\"U\":11478222227819,\"u\":11478222233988,\"pu\":11478222227775,\"b\":[[\"29107.10\",\"0.427\"],[\"29507.10\",\"1.673\"],[\"63686.00\",\"0.002\"],[\"71646.30\",\"0.002\"],[\"76422.80\",\"0.002\"],[\"78394.60\",\"0.020\"],[\"78706.00\",\"2.482\"],[\"78811.00\",\"2.225\"],[\"79209.10\",\"0.151\"],[\"79211.10\",\"0.000\"],[\"79236.90\",\"0.247\"],[\"79434.00\",\"2.937\"],[\"79453.90\",\"0.479\"],[\"79491.70\",\"0.000\"],[\"79518.40\",\"0.829\"],[\"79534.10\",\"4.445\"],[\"79534.40\",\"0.723\"],[\"79573.30\",\"0.643\"],[\"79592.70\",\"0.077\"],[\"79605.10\",\"0.002\"],[\"79605.30\",\"0.001\"],[\"79607.10\",\"10.001\"]],\"a\":[[\"79607.20\",\"1.110\"],[\"79609.20\",\"0.791\"],[\"79610.30\",\"0.690\"],[\"79611.20\",\"0.419\"],[\"79611.90\",\"0.104\"],[\"79612.30\",\"2.675\"],[\"79613.40\",\"0.079\"],[\"79621.20\",\"0.012\"],[\"79753.10\",\"0.023\"],[\"79753.30\",\"0.000\"],[\"79801.00\",\"1.683\"],[\"79829.40\",\"0.000\"],[\"79836.00\",\"0.011\"],[\"79836.10\",\"0.003\"],[\"79973.40\",\"1.494\"],[\"80005.30\",\"0.003\"],[\"80403.30\",\"6.126\"],[\"80819.70\",\"0.013\"]],\"st\":1}}"}
{"receive_ns":1788563189120076000,"stream":"btcusdt@bookTicker","event_type":"bookTicker","event_time_ms":1788563189155,"raw_json":"{\"stream\":\"btcusdt@bookTicker\",\"data\":{\"e\":\"bookTicker\",\"u\":11478222238073,\"s\":\"BTCUSDT\",\"ps\":\"BTCUSDT\",\"b\":\"79607.10\",\"B\":\"10.020\",\"a\":\"79607.20\",\"A\":\"1.110\",\"T\":1788563189154,\"E\":1788563189155,\"st\":1}}"}
{"receive_ns":1788563189120887000,"stream":"btcusdt@bookTicker","event_type":"bookTicker","event_time_ms":1788563189155,"raw_json":"{\"stream\":\"btcusdt@bookTicker\",\"data\":{\"e\":\"bookTicker\",\"u\":11478222238100,\"s\":\"BTCUSDT\",\"ps\":\"BTCUSDT\",\"b\":\"79607.10\",\"B\":\"10.001\",\"a\":\"79607.20\",\"A\":\"1.110\",\"T\":1788563189155,\"E\":1788563189155,\"st\":1}}"}
{"receive_ns":1788563189147065000,"stream":"btcusdt@depth@100ms","event_type":"depthUpdate","event_time_ms":1788563189179,"raw_json":"{\"stream\":\"btcusdt@depth@100ms\",\"data\":{\"e\":\"depthUpdate\",\"E\":1788563189179,\"T\":1788563189177,\"s\":\"BTCUSDT\",\"ps\":\"BTCUSDT\",\"U\":11478222234191,\"u\":11478222239115,\"pu\":11478222233988,\"b\":[[\"1000.00\",\"24.604\"],[\"29107.10\",\"0.280\"],[\"29407.10\",\"0.035\"],[\"29507.10\",\"1.785\"],[\"63686.00\",\"0.002\"],[\"71646.30\",\"0.002\"],[\"77369.40\",\"0.258\"],[\"78394.60\",\"0.028\"],[\"78739.40\",\"0.571\"],[\"78811.00\",\"2.225\"],[\"79434.00\",\"1.431\"],[\"79479.20\",\"0.596\"],[\"79561.90\",\"0.000\"],[\"79572.20\",\"0.953\"],[\"79575.30\",\"0.453\"],[\"79576.70\",\"0.355\"],[\"79600.30\",\"0.505\"],[\"79607.10\",\"10.001\"]],\"a\":[[\"79610.70\",\"0.003\"],[\"79611.20\",\"0.000\"],[\"79613.30\",\"0.001\"],[\"79728.70\",\"0.418\"],[\"79754.60\",\"0.486\"],[\"79973.40\",\"0.969\"],[\"80324.00\",\"0.031\"],[\"80403.30\",\"6.124\"],[\"80642.10\",\"3.901\"],[\"80716.80\",\"18.055\"],[\"80761.50\",\"0.866\"],[\"80841.10\",\"0.866\"]],\"st\":1}}"}
{"receive_ns":1788563189147951000,"stream":"btcusdt@bookTicker","event_type":"bookTicker","event_time_ms":1788563189179,"raw_json":"{\"stream\":\"btcusdt@bookTicker\",\"data\":{\"e\":\"bookTicker\",\"u\":11478222239232,\"s\":\"BTCUSDT\",\"ps\":\"BTCUSDT\",\"b\":\"79607.10\",\"B\":\"10.002\",\"a\":\"79607.20\",\"A\":\"1.110\",\"T\":1788563189179,\"E\":1788563189179,\"st\":1}}"}
{"receive_ns":1788563189183044000,"stream":"btcusdt@bookTicker","event_type":"bookTicker","event_time_ms":1788563189210,"raw_json":"{\"stream\":\"btcusdt@bookTicker\",\"data\":{\"e\":\"bookTicker\",\"u\":11478222240889,\"s\":\"BTCUSDT\",\"ps\":\"BTCUSDT\",\"b\":\"79607.10\",\"B\":\"10.021\",\"a\":\"79607.20\",\"A\":\"1.110\",\"T\":1788563189210,\"E\":1788563189210,\"st\":1}}"}
{"receive_ns":1788563189184076000,"stream":"btcusdt@bookTicker","event_type":"bookTicker","event_time_ms":1788563189211,"raw_json":"{\"stream\":\"btcusdt@bookTicker\",\"data\":{\"e\":\"bookTicker\",\"u\":11478222240952,\"s\":\"BTCUSDT\",\"ps\":\"BTCUSDT\",\"b\":\"79607.10\",\"B\":\"10.002\",\"a\":\"79607.20\",\"A\":\"1.110\",\"T\":1788563189210,\"E\":1788563189211,\"st\":1}}"}
{"receive_ns":1788563189195547000,"stream":"btcusdt@bookTicker","event_type":"bookTicker","event_time_ms":1788563189231,"raw_json":"{\"stream\":\"btcusdt@bookTicker\",\"data\":{\"e\":\"bookTicker\",\"u\":11478222241873,\"s\":\"BTCUSDT\",\"ps\":\"BTCUSDT\",\"b\":\"79607.10\",\"B\":\"9.995\",\"a\":\"79607.20\",\"A\":\"1.110\",\"T\":1788563189230,\"E\":1788563189231,\"st\":1}}"}
{"receive_ns":1788563189253741000,"stream":"btcusdt@depth@100ms","event_type":"depthUpdate","event_time_ms":1788563189281,"raw_json":"{\"stream\":\"btcusdt@depth@100ms\",\"data\":{\"e\":\"depthUpdate\",\"E\":1788563189281,\"T\":1788563189280,\"s\":\"BTCUSDT\",\"ps\":\"BTCUSDT\",\"U\":11478222239232,\"u\":11478222244582,\"pu\":11478222239115,\"b\":[[\"1000.00\",\"24.604\"],[\"29107.10\",\"0.161\"],[\"29407.10\",\"0.091\"],[\"29507.10\",\"1.848\"],[\"71646.30\",\"0.002\"],[\"76422.80\",\"0.000\"],[\"78467.80\",\"0.612\"],[\"78811.00\",\"2.225\"],[\"79061.10\",\"0.000\"],[\"79209.10\",\"0.151\"],[\"79235.40\",\"0.001\"],[\"79235.50\",\"1.530\"],[\"79236.90\",\"0.015\"],[\"79354.40\",\"0.000\"],[\"79355.70\",\"6.524\"],[\"79434.00\",\"0.829\"],[\"79453.90\",\"1.283\"],[\"79487.70\",\"1.205\"],[\"79493.10\",\"0.008\"],[\"79582.60\",\"0.000\"],[\"79583.70\",\"0.759\"],[\"79584.80\",\"0.288\"],[\"79584.90\",\"0.733\"],[\"79607.10\",\"9.995\"]],\"a\":[[\"79609.20\",\"0.251\"],[\"79611.20\",\"0.199\"],[\"79611.30\",\"0.341\"],[\"79611.60\",\"0.027\"],[\"79611.70\",\"0.029\"],[\"79613.20\",\"0.000\"],[\"79614.20\",\"0.051\"],[\"79617.50\",\"0.732\"],[\"79623.90\",\"1.300\"],[\"79624.80\",\"0.945\"],[\"79682.80\",\"0.001\"],[\"79688.40\",\"3.098\"],[\"79688.60\",\"0.002\"],[\"79707.80\",\"0.000\"],[\"79707.90\",\"0.002\"],[\"79710.50\",\"0.000\"],[\"79768.00\",\"0.064\"],[\"79852.10\",\"0.635\"],[\"79854.60\",\"0.001\"],[\"79973.30\",\"0.738\"],[\"79973.40\",\"1.913\"],[\"79973.50\",\"0.001\"],[\"79974.40\",\"0.502\"],[\"80150.40\",\"0.000\"],[\"80403.30\",\"6.126\"],[\"80721.70\",\"8.041\"],[\"80728.50\",\"0.455\"],[\"80819.60\",\"0.015\"]],\"st\":1}}"}
{"receive_ns":1788563189254692000,"stream":"btcusdt@bookTicker","event_type":"bookTicker","event_time_ms":1788563189288,"raw_json":"{\"stream\":\"btcusdt@bookTicker\",\"data\":{\"e\":\"bookTicker\",\"u\":11478222245043,\"s\":\"BTCUSDT\",\"ps\":\"BTCUSDT\",\"b\":\"79607.10\",\"B\":\"10.014\",\"a\":\"79607.20\",\"A\":\"1.110\",\"T\":1788563189288,\"E\":1788563189288,\"st\":1}}"}
{"receive_ns":1788563189255585000,"stream":"btcusdt@bookTicker","event_type":"bookTicker","event_time_ms":1788563189289,"raw_json":"{\"stream\":\"btcusdt@bookTicker\",\"data\":{\"e\":\"bookTicker\",\"u\":11478222245072,\"s\":\"BTCUSDT\",\"ps\":\"BTCUSDT\",\"b\":\"79607.10\",\"B\":\"9.995\",\"a\":\"79607.20\",\"A\":\"1.110\",\"T\":1788563189288,\"E\":1788563189289,\"st\":1}}"}
{"receive_ns":1788563189308414000,"stream":"btcusdt@bookTicker","event_type":"bookTicker","event_time_ms":1788563189343,"raw_json":"{\"stream\":\"btcusdt@bookTicker\",\"data\":{\"e\":\"bookTicker\",\"u\":11478222247646,\"s\":\"BTCUSDT\",\"ps\":\"BTCUSDT\",\"b\":\"79607.10\",\"B\":\"9.995\",\"a\":\"79607.20\",\"A\":\"1.112\",\"T\":1788563189343,\"E\":1788563189343,\"st\":1}}"}
{"receive_ns":1788563189323463000,"stream":"btcusdt@bookTicker","event_type":"bookTicker","event_time_ms":1788563189358,"raw_json":"{\"stream\":\"btcusdt@bookTicker\",\"data\":{\"e\":\"bookTicker\",\"u\":11478222248253,\"s\":\"BTCUSDT\",\"ps\":\"BTCUSDT\",\"b\":\"79607.10\",\"B\":\"9.812\",\"a\":\"79607.20\",\"A\":\"1.112\",\"T\":1788563189358,\"E\":1788563189358,\"st\":1}}"}
{"receive_ns":1788563189326000000,"stream":"btcusdt@bookTicker","event_type":"bookTicker","event_time_ms":1788563189360,"raw_json":"{\"stream\":\"btcusdt@bookTicker\",\"data\":{\"e\":\"bookTicker\",\"u\":11478222248371,\"s\":\"BTCUSDT\",\"ps\":\"BTCUSDT\",\"b\":\"79607.10\",\"B\":\"9.996\",\"a\":\"79607.20\",\"A\":\"1.112\",\"T\":1788563189360,\"E\":1788563189360,\"st\":1}}"}
{"receive_ns":1788563189330942000,"stream":"btcusdt@bookTicker","event_type":"bookTicker","event_time_ms":1788563189366,"raw_json":"{\"stream\":\"btcusdt@bookTicker\",\"data\":{\"e\":\"bookTicker\",\"u\":11478222248721,\"s\":\"BTCUSDT\",\"ps\":\"BTCUSDT\",\"b\":\"79607.10\",\"B\":\"10.043\",\"a\":\"79607.20\",\"A\":\"1.112\",\"T\":1788563189366,\"E\":1788563189366,\"st\":1}}"}
{"receive_ns":1788563189331859000,"stream":"btcusdt@bookTicker","event_type":"bookTicker","event_time_ms":1788563189367,"raw_json":"{\"stream\":\"btcusdt@bookTicker\",\"data\":{\"e\":\"bookTicker\",\"u\":11478222248802,\"s\":\"BTCUSDT\",\"ps\":\"BTCUSDT\",\"b\":\"79607.10\",\"B\":\"10.041\",\"a\":\"79607.20\",\"A\":\"1.112\",\"T\":1788563189367,\"E\":1788563189367,\"st\":1}}"}
{"receive_ns":1788563189342157000,"stream":"btcusdt@bookTicker","event_type":"bookTicker","event_time_ms":1788563189377,"raw_json":"{\"stream\":\"btcusdt@bookTicker\",\"data\":{\"e\":\"bookTicker\",\"u\":11478222249179,\"s\":\"BTCUSDT\",\"ps\":\"BTCUSDT\",\"b\":\"79607.10\",\"B\":\"9.841\",\"a\":\"79607.20\",\"A\":\"1.112\",\"T\":1788563189377,\"E\":1788563189377,\"st\":1}}"}
{"receive_ns":1788563189346136000,"stream":"btcusdt@bookTicker","event_type":"bookTicker","event_time_ms":1788563189380,"raw_json":"{\"stream\":\"btcusdt@bookTicker\",\"data\":{\"e\":\"bookTicker\",\"u\":11478222249304,\"s\":\"BTCUSDT\",\"ps\":\"BTCUSDT\",\"b\":\"79607.10\",\"B\":\"10.043\",\"a\":\"79607.20\",\"A\":\"1.112\",\"T\":1788563189380,\"E\":1788563189380,\"st\":1}}"}
{"receive_ns":1788563189347079000,"stream":"btcusdt@bookTicker","event_type":"bookTicker","event_time_ms":1788563189381,"raw_json":"{\"stream\":\"btcusdt@bookTicker\",\"data\":{\"e\":\"bookTicker\",\"u\":11478222249354,\"s\":\"BTCUSDT\",\"ps\":\"BTCUSDT\",\"b\":\"79607.10\",\"B\":\"10.045\",\"a\":\"79607.20\",\"A\":\"1.112\",\"T\":1788563189381,\"E\":1788563189381,\"st\":1}}"}
{"receive_ns":1788563189348222000,"stream":"btcusdt@depth@100ms","event_type":"depthUpdate","event_time_ms":1788563189383,"raw_json":"{\"stream\":\"btcusdt@depth@100ms\",\"data\":{\"e\":\"depthUpdate\",\"E\":1788563189383,\"T\":1788563189382,\"s\":\"BTCUSDT\",\"ps\":\"BTCUSDT\",\"U\":11478222244629,\"u\":11478222249417,\"pu\":11478222244582,\"b\":[[\"29107.10\",\"0.042\"],[\"29407.10\",\"0.154\"],[\"29507.10\",\"1.904\"],[\"71646.30\",\"0.002\"],[\"75626.70\",\"0.011\"],[\"76422.80\",\"0.002\"],[\"78811.00\",\"2.225\"],[\"78847.70\",\"3.241\"],[\"78888.10\",\"0.648\"],[\"79000.10\",\"0.212\"],[\"79061.20\",\"0.000\"],[\"79209.10\",\"0.734\"],[\"79235.50\",\"1.368\"],[\"79434.00\",\"0.578\"],[\"79453.90\",\"1.208\"],[\"79491.70\",\"0.075\"],[\"79492.40\",\"0.081\"],[\"79534.40\",\"0.032\"],[\"79535.40\",\"0.000\"],[\"79557.40\",\"6.980\"],[\"79584.80\",\"0.309\"],[\"79602.20\",\"0.027\"],[\"79602.40\",\"0.059\"],[\"79607.10\",\"10.045\"]],\"a\":[[\"79607.20\",\"1.112\"],[\"79609.20\",\"0.502\"],[\"79611.20\",\"0.315\"],[\"79611.40\",\"1.398\"],[\"79611.50\",\"0.596\"],[\"79612.80\",\"0.004\"],[\"79613.00\",\"0.002\"],[\"79613.10\",\"0.002\"],[\"79663.00\",\"0.002\"],[\"79678.90\",\"0.016\"],[\"79682.90\",\"0.001\"],[\"79688.60\",\"0.003\"],[\"79707.90\",\"0.003\"],[\"79715.20\",\"0.002\"],[\"79741.00\",\"0.000\"],[\"79973.40\",\"1.713\"],[\"79974.30\",\"0.000\"],[\"79995.30\",\"0.326\"],[\"79999.90\",\"10.724\"],[\"80005.30\",\"0.002\"],[\"80403.30\",\"6.128\"],[\"81199.30\",\"0.021\"]],\"st\":1}}"}
{"receive_ns":1788563189428800000,"stream":"btcusdt@bookTicker","event_type":"bookTicker","event_time_ms":1788563189462,"raw_json":"{\"stream\":\"btcusdt@bookTicker\",\"data\":{\"e\":\"bookTicker\",\"u\":11478222252911,\"s\":\"BTCUSDT\",\"ps\":\"BTCUSDT\",\"b\":\"79607.10\",\"B\":\"10.032\",\"a\":\"79607.20\",\"A\":\"1.112\",\"T\":1788563189462,\"E\":1788563189462,\"st\":1}}"}
{"receive_ns":1788563189431274000,"stream":"btcusdt@bookTicker","event_type":"bookTicker","event_time_ms":1788563189466,"raw_json":"{\"stream\":\"btcusdt@bookTicker\",\"data\":{\"e\":\"bookTicker\",\"u\":11478222253125,\"s\":\"BTCUSDT\",\"ps\":\"BTCUSDT\",\"b\":\"79607.10\",\"B\":\"10.046\",\"a\":\"79607.20\",\"A\":\"1.112\",\"T\":1788563189466,\"E\":1788563189466,\"st\":1}}"}
{"receive_ns":1788563189449827000,"stream":"btcusdt@depth@100ms","event_type":"depthUpdate","event_time_ms":1788563189485,"raw_json":"{\"stream\":\"btcusdt@depth@100ms\",\"data\":{\"e\":\"depthUpdate\",\"E\":1788563189485,\"T\":1788563189482,\"s\":\"BTCUSDT\",\"ps\":\"BTCUSDT\",\"U\":11478222249431,\"u\":11478222255352,\"pu\":11478222249417,\"b\":[[\"1000.00\",\"24.604\"],[\"29107.10\",\"0.000\"],[\"29407.10\",\"0.287\"],[\"29507.10\",\"1.813\"],[\"71646.30\",\"0.002\"],[\"76422.80\",\"0.000\"],[\"78253.80\",\"0.893\"],[\"78587.40\",\"0.000\"],[\"78811.00\",\"2.225\"],[\"78847.60\",\"0.653\"],[\"79209.00\",\"0.001\"],[\"79209.10\",\"2.240\"],[\"79434.00\",\"0.076\"],[\"79453.90\",\"0.204\"],[\"79487.70\",\"0.001\"],[\"79492.40\",\"0.091\"],[\"79594.30\",\"0.165\"],[\"79596.00\",\"0.687\"],[\"79605.40\",\"0.009\"],[\"79607.10\",\"10.046\"]],\"a\":[[\"79610.00\",\"0.030\"],[\"79611.20\",\"0.116\"],[\"79612.70\",\"0.010\"],[\"79741.00\",\"0.006\"],[\"79973.30\",\"0.007\"],[\"79973.40\",\"0.006\"],[\"79987.30\",\"0.419\"],[\"79999.30\",\"0.536\"],[\"80366.80\",\"0.000\"],[\"80403.30\",\"6.124\"],[\"80632.00\",\"0.000\"],[\"80729.70\",\"0.618\"]],\"st\":1}}"}
{"receive_ns":1788563189481134000,"stream":"btcusdt@bookTicker","event_type":"bookTicker","event_time_ms":1788563189515,"raw_json":"{\"stream\":\"btcusdt@bookTicker\",\"data\":{\"e\":\"bookTicker\",\"u\":11478222257069,\"s\":\"BTCUSDT\",\"ps\":\"BTCUSDT\",\"b\":\"79607.10\",\"B\":\"9.759\",\"a\":\"79607.20\",\"A\":\"1.112\",\"T\":1788563189515,\"E\":1788563189515,\"st\":1}}"}
{"receive_ns":1788563189483665000,"stream":"btcusdt@bookTicker","event_type":"bookTicker","event_time_ms":1788563189518,"raw_json":"{\"stream\":\"btcusdt@bookTicker\",\"data\":{\"e\":\"bookTicker\",\"u\":11478222257246,\"s\":\"BTCUSDT\",\"ps\":\"BTCUSDT\",\"b\":\"79607.10\",\"B\":\"10.067\",\"a\":\"79607.20\",\"A\":\"1.112\",\"T\":1788563189518,\"E\":1788563189518,\"st\":1}}"}
{"receive_ns":1788563189555437000,"stream":"btcusdt@depth@100ms","event_type":"depthUpdate","event_time_ms":1788563189587,"raw_json":"{\"stream\":\"btcusdt@depth@100ms\",\"data\":{\"e\":\"depthUpdate\",\"E\":1788563189587,\"T\":1788563189586,\"s\":\"BTCUSDT\",\"ps\":\"BTCUSDT\",\"U\":11478222255636,\"u\":11478222260469,\"pu\":11478222255352,\"b\":[[\"1000.00\",\"24.604\"],[\"29407.10\",\"0.469\"],[\"29507.10\",\"1.631\"],[\"71646.30\",\"0.002\"],[\"76422.80\",\"0.002\"],[\"78597.00\",\"200.000\"],[\"78598.00\",\"0.603\"],[\"78811.00\",\"2.225\"],[\"79061.20\",\"56.893\"],[\"79209.10\",\"2.851\"],[\"79235.50\",\"46.260\"],[\"79235.60\",\"7.093\"],[\"79236.90\",\"0.247\"],[\"79354.50\",\"36.567\"],[\"79355.70\",\"11.384\"],[\"79434.00\",\"0.427\"],[\"79487.70\",\"0.076\"],[\"79491.70\",\"0.000\"],[\"79607.10\",\"10.067\"]],\"a\":[[\"79609.20\",\"0.502\"],[\"79610.00\",\"0.004\"],[\"79610.60\",\"0.371\"],[\"79611.20\",\"0.315\"],[\"79615.30\",\"0.692\"],[\"79615.70\",\"0.010\"],[\"79617.30\",\"0.005\"],[\"79617.40\",\"0.454\"],[\"79670.90\",\"0.006\"],[\"79679.50\",\"0.451\"],[\"79852.10\",\"5.901\"],[\"79855.70\",\"35.663\"],[\"79975.40\",\"0.203\"],[\"79975.50\",\"45.171\"],[\"79995.30\",\"0.889\"],[\"80151.50\",\"55.161\"],[\"80403.30\",\"6.124\"],[\"81012.90\",\"0.000\"],[\"81199.30\",\"0.018\"]],\"st\":1}}"}
{"receive_ns":1788563189619559000,"stream":"btcusdt@bookTicker","event_type":"bookTicker","event_time_ms":1788563189649,"raw_json":"{\"stream\":\"btcusdt@bookTicker\",\"data\":{\"e\":\"bookTicker\",\"u\":11478222263569,\"s\":\"BTCUSDT\",\"ps\":\"BTCUSDT\",\"b\":\"79607.10\",\"B\":\"10.086\",\"a\":\"79607.20\",\"A\":\"1.112\",\"T\":1788563189649,\"E\":1788563189649,\"st\":1}}"}
{"receive_ns":1788563189620606000,"stream":"btcusdt@bookTicker","event_type":"bookTicker","event_time_ms":1788563189650,"raw_json":"{\"stream\":\"btcusdt@bookTicker\",\"data\":{\"e\":\"bookTicker\",\"u\":11478222263614,\"s\":\"BTCUSDT\",\"ps\":\"BTCUSDT\",\"b\":\"79607.10\",\"B\":\"10.067\",\"a\":\"79607.20\",\"A\":\"1.112\",\"T\":1788563189649,\"E\":1788563189650,\"st\":1}}"}
{"receive_ns":1788563189655737000,"stream":"btcusdt@depth@100ms","event_type":"depthUpdate","event_time_ms":1788563189689,"raw_json":"{\"stream\":\"btcusdt@depth@100ms\",\"data\":{\"e\":\"depthUpdate\",\"E\":1788563189689,\"T\":1788563189685,\"s\":\"BTCUSDT\",\"ps\":\"BTCUSDT\",\"U\":11478222260494,\"u\":11478222265359,\"pu\":11478222260469,\"b\":[[\"29407.10\",\"0.644\"],[\"29507.10\",\"1.456\"],[\"63686.00\",\"0.002\"],[\"71646.30\",\"0.002\"],[\"71646.40\",\"0.034\"],[\"71680.00\",\"0.130\"],[\"75626.70\",\"0.009\"],[\"75626.80\",\"0.004\"],[\"78603.10\",\"7.779\"],[\"78811.00\",\"2.225\"],[\"78847.70\",\"71.301\"],[\"78888.10\",\"3.240\"],[\"79000.10\",\"0.050\"],[\"79061.30\",\"0.652\"],[\"79209.10\",\"1.345\"],[\"79235.60\",\"7.255\"],[\"79391.90\",\"0.000\"],[\"79392.10\",\"5.365\"],[\"79439.80\",\"0.001\"],[\"79439.90\",\"1.342\"],[\"79567.20\",\"0.240\"],[\"79571.70\",\"0.104\"],[\"79581.40\",\"2.324\"],[\"79583.40\",\"1.875\"],[\"79583.50\",\"0.002\"],[\"79583.60\",\"2.403\"],[\"79607.10\",\"10.067\"]],\"a\":[[\"79623.30\",\"0.045\"],[\"79644.20\",\"2.538\"],[\"79644.60\",\"0.000\"],[\"79678.90\",\"0.018\"],[\"79828.50\",\"0.001\"],[\"79829.00\",\"8.445\"],[\"79975.40\",\"0.851\"],[\"79987.30\",\"0.000\"],[\"79999.30\",\"0.011\"],[\"79999.90\",\"10.076\"],[\"80367.90\",\"68.755\"],[\"80403.30\",\"6.124\"]],\"st\":1}}"}
{"receive_ns":1788563189672353000,"stream":"btcusdt@bookTicker","event_type":"bookTicker","event_time_ms":1788563189707,"raw_json":"{\"stream\":\"btcusdt@bookTicker\",\"data\":{\"e\":\"bookTicker\",\"u\":11478222266248,\"s\":\"BTCUSDT\",\"ps\":\"BTCUSDT\",\"b\":\"79607.10\",\"B\":\"10.086\",\"a\":\"79607.20\",\"A\":\"1.112\",\"T\":1788563189707,\"E\":1788563189707,\"st\":1}}"}
{"receive_ns":1788563189673718000,"stream":"btcusdt@bookTicker","event_type":"bookTicker","event_time_ms":1788563189708,"raw_json":"{\"stream\":\"btcusdt@bookTicker\",\"data\":{\"e\":\"bookTicker\",\"u\":11478222266297,\"s\":\"BTCUSDT\",\"ps\":\"BTCUSDT\",\"b\":\"79607.10\",\"B\":\"10.067\",\"a\":\"79607.20\",\"A\":\"1.112\",\"T\":1788563189708,\"E\":1788563189708,\"st\":1}}"}
{"receive_ns":1788563189717558000,"stream":"btcusdt@bookTicker","event_type":"bookTicker","event_time_ms":1788563189752,"raw_json":"{\"stream\":\"btcusdt@bookTicker\",\"data\":{\"e\":\"bookTicker\",\"u\":11478222268667,\"s\":\"BTCUSDT\",\"ps\":\"BTCUSDT\",\"b\":\"79607.10\",\"B\":\"10.086\",\"a\":\"79607.20\",\"A\":\"1.112\",\"T\":1788563189752,\"E\":1788563189752,\"st\":1}}"}
{"receive_ns":1788563189718639000,"stream":"btcusdt@bookTicker","event_type":"bookTicker","event_time_ms":1788563189752,"raw_json":"{\"stream\":\"btcusdt@bookTicker\",\"data\":{\"e\":\"bookTicker\",\"u\":11478222268701,\"s\":\"BTCUSDT\",\"ps\":\"BTCUSDT\",\"b\":\"79607.10\",\"B\":\"10.067\",\"a\":\"79607.20\",\"A\":\"1.112\",\"T\":1788563189752,\"E\":1788563189752,\"st\":1}}"}
{"receive_ns":1788563189726758000,"stream":"btcusdt@bookTicker","event_type":"bookTicker","event_time_ms":1788563189760,"raw_json":"{\"stream\":\"btcusdt@bookTicker\",\"data\":{\"e\":\"bookTicker\",\"u\":11478222269266,\"s\":\"BTCUSDT\",\"ps\":\"BTCUSDT\",\"b\":\"79607.10\",\"B\":\"10.067\",\"a\":\"79607.20\",\"A\":\"1.135\",\"T\":1788563189760,\"E\":1788563189760,\"st\":1}}"}
{"receive_ns":1788563189727842000,"stream":"btcusdt@bookTicker","event_type":"bookTicker","event_time_ms":1788563189761,"raw_json":"{\"stream\":\"btcusdt@bookTicker\",\"data\":{\"e\":\"bookTicker\",\"u\":11478222269321,\"s\":\"BTCUSDT\",\"ps\":\"BTCUSDT\",\"b\":\"79607.10\",\"B\":\"10.067\",\"a\":\"79607.20\",\"A\":\"1.134\",\"T\":1788563189761,\"E\":1788563189761,\"st\":1}}"}
{"receive_ns":1788563189754490000,"stream":"btcusdt@depth@100ms","event_type":"depthUpdate","event_time_ms":1788563189791,"raw_json":"{\"stream\":\"btcusdt@depth@100ms\",\"data\":{\"e\":\"depthUpdate\",\"E\":1788563189791,\"T\":1788563189790,\"s\":\"BTCUSDT\",\"ps\":\"BTCUSDT\",\"U\":11478222265540,\"u\":11478222270468,\"pu\":11478222265359,\"b\":[[\"1000.00\",\"24.604\"],[\"29407.10\",\"0.826\"],[\"29507.10\",\"1.274\"],[\"71646.30\",\"0.002\"],[\"71646.40\",\"0.032\"],[\"71680.00\",\"0.127\"],[\"76422.80\",\"0.000\"],[\"78015.00\",\"0.137\"],[\"78500.00\",\"85.676\"],[\"78811.00\",\"2.225\"],[\"79204.30\",\"3.716\"],[\"79209.10\",\"0.000\"],[\"79236.90\",\"0.015\"],[\"79434.00\",\"0.578\"],[\"79479.20\",\"0.000\"],[\"79479.30\",\"0.657\"],[\"79485.40\",\"0.000\"],[\"79487.70\",\"1.005\"],[\"79491.70\",\"1.204\"],[\"79493.70\",\"0.631\"],[\"79582.80\",\"0.374\"],[\"79583.70\",\"0.386\"],[\"79602.20\",\"0.026\"],[\"79602.60\",\"0.002\"],[\"79603.00\",\"0.076\"],[\"79607.10\",\"10.067\"]],\"a\":[[\"79607.20\",\"1.134\"],[\"79609.20\",\"0.000\"],[\"79610.60\",\"0.345\"],[\"79611.20\",\"0.225\"],[\"79617.30\",\"0.001\"],[\"79617.50\",\"0.736\"],[\"79728.60\",\"0.340\"],[\"79728.70\",\"0.000\"],[\"79975.40\",\"2.358\"],[\"79995.30\",\"0.126\"],[\"80403.30\",\"6.124\"],[\"80555.20\",\"0.005\"],[\"81047.30\",\"3.326\"]],\"st\":1}}"}
{"receive_ns":1788563189771836000,"stream":"btcusdt@bookTicker","event_type":"bookTicker","event_time_ms":1788563189806,"raw_json":"{\"stream\":\"btcusdt@bookTicker\",\"data\":{\"e\":\"bookTicker\",\"u\":11478222271201,\"s\":\"BTCUSDT\",\"ps\":\"BTCUSDT\",\"b\":\"79607.10\",\"B\":\"10.086\",\"a\":\"79607.20\",\"A\":\"1.134\",\"T\":1788563189806,\"E\":1788563189806,\"st\":1}}"}
{"receive_ns":1788563189773487000,"stream":"btcusdt@bookTicker","event_type":"bookTicker","event_time_ms":1788563189807,"raw_json":"{\"stream\":\"btcusdt@bookTicker\",\"data\":{\"e\":\"bookTicker\",\"u\":11478222271232,\"s\":\"BTCUSDT\",\"ps\":\"BTCUSDT\",\"b\":\"79607.10\",\"B\":\"10.067\",\"a\":\"79607.20\",\"A\":\"1.134\",\"T\":1788563189807,\"E\":1788563189807,\"st\":1}}"}
{"receive_ns":1788563189775075000,"stream":"btcusdt@bookTicker","event_type":"bookTicker","event_time_ms":1788563189808,"raw_json":"{\"stream\":\"btcusdt@bookTicker\",\"data\":{\"e\":\"bookTicker\",\"u\":11478222271271,\"s\":\"BTCUSDT\",\"ps\":\"BTCUSDT\",\"b\":\"79607.10\",\"B\":\"10.067\",\"a\":\"79607.20\",\"A\":\"1.135\",\"T\":1788563189807,\"E\":1788563189808,\"st\":1}}"}
{"receive_ns":1788563189859215000,"stream":"btcusdt@depth@100ms","event_type":"depthUpdate","event_time_ms":1788563189893,"raw_json":"{\"stream\":\"btcusdt@depth@100ms\",\"data\":{\"e\":\"depthUpdate\",\"E\":1788563189893,\"T\":1788563189888,\"s\":\"BTCUSDT\",\"ps\":\"BTCUSDT\",\"U\":11478222270509,\"u\":11478222275591,\"pu\":11478222270468,\"b\":[[\"1000.00\",\"24.604\"],[\"29407.10\",\"0.994\"],[\"29507.10\",\"1.106\"],[\"63685.70\",\"0.001\"],[\"63686.00\",\"0.002\"],[\"71646.30\",\"0.002\"],[\"75626.70\",\"0.011\"],[\"76422.80\",\"0.002\"],[\"78811.00\",\"2.225\"],[\"79209.10\",\"0.151\"],[\"79236.90\",\"0.247\"],[\"79434.00\",\"0.929\"],[\"79491.70\",\"1.279\"],[\"79510.80\",\"1.466\"],[\"79524.50\",\"0.567\"],[\"79564.00\",\"1.273\"],[\"79574.50\",\"0.900\"],[\"79575.30\",\"0.001\"],[\"79576.20\",\"0.453\"],[\"79576.50\",\"0.002\"],[\"79577.40\",\"0.000\"],[\"79607.10\",\"10.067\"]],\"a\":[[\"79607.20\",\"1.135\"],[\"79609.20\",\"0.502\"],[\"79610.10\",\"0.001\"],[\"79610.30\",\"0.690\"],[\"79611.10\",\"0.001\"],[\"79611.20\",\"0.315\"],[\"79612.00\",\"0.306\"],[\"79612.50\",\"0.001\"],[\"79612.60\",\"0.000\"],[\"79617.40\",\"0.392\"],[\"79617.50\",\"0.798\"],[\"79625.70\",\"0.453\"],[\"79626.30\",\"0.003\"],[\"79627.10\",\"0.001\"],[\"79975.40\",\"2.558\"],[\"80403.30\",\"6.124\"],[\"80652.30\",\"0.619\"],[\"80728.50\",\"0.159\"],[\"81470.20\",\"0.001\"]],\"st\":1}}"}
{"receive_ns":1788563189939768000,"stream":"btcusdt@bookTicker","event_type":"bookTicker","event_time_ms":1788563189974,"raw_json":"{\"stream\":\"btcusdt@bookTicker\",\"data\":{\"e\":\"bookTicker\",\"u\":11478222279791,\"s\":\"BTCUSDT\",\"ps\":\"BTCUSDT\",\"b\":\"79607.10\",\"B\":\"10.292\",\"a\":\"79607.20\",\"A\":\"1.135\",\"T\":1788563189974,\"E\":1788563189974,\"st\":1}}"}
{"receive_ns":1788563189941884000,"stream":"btcusdt@bookTicker","event_type":"bookTicker","event_time_ms":1788563189975,"raw_json":"{\"stream\":\"btcusdt@bookTicker\",\"data\":{\"e\":\"bookTicker\",\"u\":11478222279829,\"s\":\"BTCUSDT\",\"ps\":\"BTCUSDT\",\"b\":\"79607.10\",\"B\":\"10.290\",\"a\":\"79607.20\",\"A\":\"1.135\",\"T\":1788563189975,\"E\":1788563189975,\"st\":1}}"}
{"receive_ns":1788563189959628000,"stream":"btcusdt@depth@100ms","event_type":"depthUpdate","event_time_ms":1788563189995,"raw_json":"{\"stream\":\"btcusdt@depth@100ms\",\"data\":{\"e\":\"depthUpdate\",\"E\":1788563189995,\"T\":1788563189993,\"s\":\"BTCUSDT\",\"ps\":\"BTCUSDT\",\"U\":11478222275796,\"u\":11478222281150,\"pu\":11478222275591,\"b\":[[\"29407.10\",\"1.183\"],[\"29507.10\",\"0.917\"],[\"63686.00\",\"0.004\"],[\"71646.30\",\"0.002\"],[\"76422.80\",\"0.000\"],[\"77589.30\",\"0.000\"],[\"77935.40\",\"0.258\"],[\"78398.50\",\"0.704\"],[\"78412.90\",\"0.287\"],[\"78811.00\",\"2.225\"],[\"79434.00\",\"1.933\"],[\"79479.30\",\"0.061\"],[\"79487.70\",\"1.005\"],[\"79489.90\",\"0.198\"],[\"79491.70\",\"0.075\"],[\"79520.40\",\"0.018\"],[\"79529.30\",\"0.001\"],[\"79591.60\",\"0.069\"],[\"79592.00\",\"0.010\"],[\"79601.20\",\"0.030\"],[\"79601.80\",\"0.107\"],[\"79602.60\",\"0.001\"],[\"79603.00\",\"0.077\"],[\"79607.10\",\"10.290\"]],\"a\":[[\"79611.20\",\"0.090\"],[\"79611.40\",\"1.372\"],[\"79612.10\",\"0.028\"],[\"79612.40\",\"0.027\"],[\"79728.60\",\"0.000\"],[\"79973.40\",\"0.425\"],[\"79975.40\",\"2.139\"],[\"80403.30\",\"6.124\"],[\"80833.70\",\"0.026\"]],\"st\":1}}"}
{"receive_ns":1788563189997118000,"stream":"btcusdt@bookTicker","event_type":"bookTicker","event_time_ms":1788563190032,"raw_json":"{\"stream\":\"btcusdt@bookTicker\",\"data\":{\"e\":\"bookTicker\",\"u\":11478222284066,\"s\":\"BTCUSDT\",\"ps\":\"BTCUSDT\",\"b\":\"79607.10\",\"B\":\"10.286\",\"a\":\"79607.20\",\"A\":\"1.135\",\"T\":1788563190032,\"E\":1788563190032,\"st\":1}}"}
{"receive_ns":1788563189998667000,"stream":"btcusdt@trade","event_type":"trade","event_time_ms":1788563190032,"raw_json":"{\"stream\":\"btcusdt@trade\",\"data\":{\"e\":\"trade\",\"E\":1788563190032,\"T\":1788563190032,\"s\":\"BTCUSDT\",\"t\":8054082658,\"p\":\"79607.10\",\"q\":\"0.004\",\"X\":\"MARKET\",\"m\":true,\"st\":1}}"}
{"receive_ns":1788563190000188000,"stream":"btcusdt@bookTicker","event_type":"bookTicker","event_time_ms":1788563190033,"raw_json":"{\"stream\":\"btcusdt@bookTicker\",\"data\":{\"e\":\"bookTicker\",\"u\":11478222284221,\"s\":\"BTCUSDT\",\"ps\":\"BTCUSDT\",\"b\":\"79607.10\",\"B\":\"10.305\",\"a\":\"79607.20\",\"A\":\"1.135\",\"T\":1788563190033,\"E\":1788563190033,\"st\":1}}"}
{"receive_ns":1788563190001381000,"stream":"btcusdt@bookTicker","event_type":"bookTicker","event_time_ms":1788563190033,"raw_json":"{\"stream\":\"btcusdt@bookTicker\",\"data\":{\"e\":\"bookTicker\",\"u\":11478222284270,\"s\":\"BTCUSDT\",\"ps\":\"BTCUSDT\",\"b\":\"79607.10\",\"B\":\"10.313\",\"a\":\"79607.20\",\"A\":\"1.135\",\"T\":1788563190033,\"E\":1788563190033,\"st\":1}}"}
{"receive_ns":1788563190002481000,"stream":"btcusdt@bookTicker","event_type":"bookTicker","event_time_ms":1788563190034,"raw_json":"{\"stream\":\"btcusdt@bookTicker\",\"data\":{\"e\":\"bookTicker\",\"u\":11478222284395,\"s\":\"BTCUSDT\",\"ps\":\"BTCUSDT\",\"b\":\"79607.10\",\"B\":\"10.294\",\"a\":\"79607.20\",\"A\":\"1.135\",\"T\":1788563190034,\"E\":1788563190034,\"st\":1}}"}
{"receive_ns":1788563190003656000,"stream":"btcusdt@bookTicker","event_type":"bookTicker","event_time_ms":1788563190034,"raw_json":"{\"stream\":\"btcusdt@bookTicker\",\"data\":{\"e\":\"bookTicker\",\"u\":11478222284443,\"s\":\"BTCUSDT\",\"ps\":\"BTCUSDT\",\"b\":\"79607.10\",\"B\":\"10.286\",\"a\":\"79607.20\",\"A\":\"1.135\",\"T\":1788563190034,\"E\":1788563190034,\"st\":1}}"}
{"receive_ns":1788563190006549000,"stream":"btcusdt@bookTicker","event_type":"bookTicker","event_time_ms":1788563190034,"raw_json":"{\"stream\":\"btcusdt@bookTicker\",\"data\":{\"e\":\"bookTicker\",\"u\":11478222284518,\"s\":\"BTCUSDT\",\"ps\":\"BTCUSDT\",\"b\":\"79607.10\",\"B\":\"10.288\",\"a\":\"79607.20\",\"A\":\"1.135\",\"T\":1788563190034,\"E\":1788563190034,\"st\":1}}"}
{"receive_ns":1788563190015317000,"stream":"btcusdt@bookTicker","event_type":"bookTicker","event_time_ms":1788563190048,"raw_json":"{\"stream\":\"btcusdt@bookTicker\",\"data\":{\"e\":\"bookTicker\",\"u\":11478222285582,\"s\":\"BTCUSDT\",\"ps\":\"BTCUSDT\",\"b\":\"79607.10\",\"B\":\"10.293\",\"a\":\"79607.20\",\"A\":\"1.135\",\"T\":1788563190048,\"E\":1788563190048,\"st\":1}}"}
{"receive_ns":1788563190032279000,"stream":"btcusdt@bookTicker","event_type":"bookTicker","event_time_ms":1788563190067,"raw_json":"{\"stream\":\"btcusdt@bookTicker\",\"data\":{\"e\":\"bookTicker\",\"u\":11478222287575,\"s\":\"BTCUSDT\",\"ps\":\"BTCUSDT\",\"b\":\"79607.10\",\"B\":\"10.312\",\"a\":\"79607.20\",\"A\":\"1.135\",\"T\":1788563190067,\"E\":1788563190067,\"st\":1}}"}
{"receive_ns":1788563190033637000,"stream":"btcusdt@bookTicker","event_type":"bookTicker","event_time_ms":1788563190068,"raw_json":"{\"stream\":\"btcusdt@bookTicker\",\"data\":{\"e\":\"bookTicker\",\"u\":11478222287621,\"s\":\"BTCUSDT\",\"ps\":\"BTCUSDT\",\"b\":\"79607.10\",\"B\":\"10.293\",\"a\":\"79607.20\",\"A\":\"1.135\",\"T\":1788563190068,\"E\":1788563190068,\"st\":1}}"}
{"receive_ns":1788563190064467000,"stream":"btcusdt@depth@100ms","event_type":"depthUpdate","event_time_ms":1788563190097,"raw_json":"{\"stream\":\"btcusdt@depth@100ms\",\"data\":{\"e\":\"depthUpdate\",\"E\":1788563190097,\"T\":1788563190096,\"s\":\"BTCUSDT\",\"ps\":\"BTCUSDT\",\"U\":11478222281252,\"u\":11478222289212,\"pu\":11478222281150,\"b\":[[\"1000.00\",\"24.604\"],[\"29407.10\",\"1.358\"],[\"29507.10\",\"0.742\"],[\"63686.00\",\"0.004\"],[\"71646.30\",\"0.002\"],[\"78384.80\",\"0.000\"],[\"78504.50\",\"1.274\"],[\"78706.00\",\"1.912\"],[\"78811.00\",\"2.225\"],[\"78970.20\",\"1.516\"],[\"79209.00\",\"0.002\"],[\"79209.10\",\"0.151\"],[\"79211.10\",\"0.000\"],[\"79236.90\",\"0.247\"],[\"79434.00\",\"1.582\"],[\"79453.90\",\"0.555\"],[\"79479.30\",\"0.657\"],[\"79487.70\",\"1.205\"],[\"79491.70\",\"0.075\"],[\"79495.70\",\"1.445\"],[\"79519.40\",\"1.464\"],[\"79527.90\",\"0.116\"],[\"79531.60\",\"0.002\"],[\"79532.70\",\"0.051\"],[\"79534.40\",\"0.723\"],[\"79538.70\",\"0.037\"],[\"79592.80\",\"0.003\"],[\"79594.30\",\"0.162\"],[\"79607.10\",\"10.293\"]],\"a\":[[\"79609.20\",\"0.251\"],[\"79611.20\",\"0.341\"],[\"79659.10\",\"0.000\"],[\"79660.10\",\"0.052\"],[\"79728.60\",\"0.340\"],[\"79975.40\",\"2.139\"],[\"80005.30\",\"0.001\"],[\"80403.30\",\"6.124\"],[\"80732.80\",\"1.730\"],[\"80820.00\",\"0.003\"]],\"st\":1}}"}
{"receive_ns":1788563190164306000,"stream":"btcusdt@depth@100ms","event_type":"depthUpdate","event_time_ms":1788563190199,"raw_json":"{\"stream\":\"btcusdt@depth@100ms\",\"data\":{\"e\":\"depthUpdate\",\"E\":1788563190199,\"T\":1788563190198,\"s\":\"BTCUSDT\",\"ps\":\"BTCUSDT\",\"U\":11478222289328,\"u\":11478222295833,\"pu\":11478222289212,\"b\":[[\"1000.00\",\"24.604\"],[\"29407.10\",\"1.540\"],[\"29507.10\",\"0.560\"],[\"63686.00\",\"0.002\"],[\"71646.30\",\"0.002\"],[\"76422.80\",\"0.002\"],[\"78389.30\",\"0.017\"],[\"78642.30\",\"0.444\"],[\"78739.40\",\"1.141\"],[\"78811.00\",\"2.225\"],[\"79209.10\",\"0.141\"],[\"79434.00\",\"0.578\"],[\"79461.20\",\"0.000\"],[\"79479.30\",\"0.061\"],[\"79487.70\",\"2.209\"],[\"79552.80\",\"0.003\"],[\"79552.90\",\"0.002\"],[\"79554.10\",\"0.675\"]],\"a\":[[\"79611.00\",\"0.029\"],[\"79611.10\",\"0.027\"],[\"79611.30\",\"0.341\"],[\"79682.90\",\"0.002\"],[\"79688.50\",\"1.939\"],[\"79688.60\",\"0.004\"],[\"79707.80\",\"0.001\"],[\"79720.30\",\"0.001\"],[\"79728.60\",\"0.000\"],[\"79973.40\",\"0.425\"],[\"79975.40\",\"2.139\"],[\"80403.30\",\"6.124\"],[\"80570.40\",\"1.300\"]],\"st\":1}}"}
{"receive_ns":1788563190226765000,"stream":"btcusdt@bookTicker","event_type":"bookTicker","event_time_ms":1788563190229,"raw_json":"{\"stream\":\"btcusdt@bookTicker\",\"data\":{\"e\":\"bookTicker\",\"u\":11478222297707,\"s\":\"BTCUSDT\",\"ps\":\"BTCUSDT\",\"b\":\"79607.10\",\"B\":\"10.292\",\"a\":\"79607.20\",\"A\":\"1.135\",\"T\":1788563190229,\"E\":1788563190229,\"st\":1}}"}
{"receive_ns":1788563190244348000,"stream":"btcusdt@bookTicker","event_type":"bookTicker","event_time_ms":1788563190248,"raw_json":"{\"stream\":\"btcusdt@bookTicker\",\"data\":{\"e\":\"bookTicker\",\"u\":11478222298919,\"s\":\"BTCUSDT\",\"ps\":\"BTCUSDT\",\"b\":\"79607.10\",\"B\":\"10.293\",\"a\":\"79607.20\",\"A\":\"1.135\",\"T\":1788563190247,\"E\":1788563190248,\"st\":1}}"}
{"receive_ns":1788563190273608000,"stream":"btcusdt@depth@100ms","event_type":"depthUpdate","event_time_ms":1788563190301,"raw_json":"{\"stream\":\"btcusdt@depth@100ms\",\"data\":{\"e\":\"depthUpdate\",\"E\":1788563190301,\"T\":1788563190298,\"s\":\"BTCUSDT\",\"ps\":\"BTCUSDT\",\"U\":11478222295984,\"u\":11478222301515,\"pu\":11478222295833,\"b\":[[\"29407.10\",\"1.715\"],[\"29507.10\",\"0.385\"],[\"71646.30\",\"0.002\"],[\"76422.80\",\"0.000\"],[\"78225.20\",\"0.000\"],[\"78563.30\",\"7.756\"],[\"78811.00\",\"2.225\"],[\"79209.10\",\"0.141\"],[\"79236.90\",\"0.247\"],[\"79434.00\",\"1.933\"],[\"79439.90\",\"0.000\"],[\"79453.90\",\"0.204\"],[\"79469.10\",\"0.258\"],[\"79487.70\",\"1.280\"],[\"79491.70\",\"0.000\"],[\"79498.40\",\"0.002\"],[\"79501.60\",\"0.628\"],[\"79607.10\",\"10.293\"]],\"a\":[[\"79609.20\",\"0.502\"],[\"79611.20\",\"0.289\"],[\"79707.80\",\"0.002\"],[\"79768.10\",\"0.000\"],[\"79975.40\",\"2.139\"],[\"80005.20\",\"0.136\"],[\"80403.30\",\"7.055\"],[\"80478.80\",\"1.230\"],[\"80679.50\",\"1.239\"],[\"80761.50\",\"0.990\"],[\"80824.80\",\"0.008\"],[\"81199.30\",\"0.015\"]],\"st\":1}}"}
{"receive_ns":1788563190289346000,"stream":"btcusdt@bookTicker","event_type":"bookTicker","event_time_ms":1788563190324,"raw_json":"{\"stream\":\"btcusdt@bookTicker\",\"data\":{\"e\":\"bookTicker\",\"u\":11478222302985,\"s\":\"BTCUSDT\",\"ps\":\"BTCUSDT\",\"b\":\"79607.10\",\"B\":\"9.985\",\"a\":\"79607.20\",\"A\":\"1.135\",\"T\":1788563190324,\"E\":1788563190324,\"st\":1}}"}
{"receive_ns":1788563190292981000,"stream":"btcusdt@bookTicker","event_type":"bookTicker","event_time_ms":1788563190328,"raw_json":"{\"stream\":\"btcusdt@bookTicker\",\"data\":{\"e\":\"bookTicker\",\"u\":11478222303195,\"s\":\"BTCUSDT\",\"ps\":\"BTCUSDT\",\"b\":\"79607.10\",\"B\":\"10.296\",\"a\":\"79607.20\",\"A\":\"1.135\",\"T\":1788563190327,\"E\":1788563190328,\"st\":1}}"}
{"receive_ns":1788563190306444000,"stream":"btcusdt@bookTicker","event_type":"bookTicker","event_time_ms":1788563190341,"raw_json":"{\"stream\":\"btcusdt@bookTicker\",\"data\":{\"e\":\"bookTicker\",\"u\":11478222303761,\"s\":\"BTCUSDT\",\"ps\":\"BTCUSDT\",\"b\":\"79607.10\",\"B\":\"9.875\",\"a\":\"79607.20\",\"A\":\"1.135\",\"T\":1788563190340,\"E\":1788563190341,\"st\":1}}"}
{"receive_ns":1788563190318142000,"stream":"btcusdt@bookTicker","event_type":"bookTicker","event_time_ms":1788563190352,"raw_json":"{\"stream\":\"btcusdt@bookTicker\",\"data\":{\"e\":\"bookTicker\",\"u\":11478222304219,\"s\":\"BTCUSDT\",\"ps\":\"BTCUSDT\",\"b\":\"79607.10\",\"B\":\"9.894\",\"a\":\"79607.20\",\"A\":\"1.135\",\"T\":1788563190351,\"E\":1788563190352,\"st\":1}}"}
{"receive_ns":1788563190318518000,"stream":"btcusdt@bookTicker","event_type":"bookTicker","event_time_ms":1788563190352,"raw_json":"{\"stream\":\"btcusdt@bookTicker\",\"data\":{\"e\":\"bookTicker\",\"u\":11478222304248,\"s\":\"BTCUSDT\",\"ps\":\"BTCUSDT\",\"b\":\"79607.10\",\"B\":\"9.875\",\"a\":\"79607.20\",\"A\":\"1.135\",\"T\":1788563190352,\"E\":1788563190352,\"st\":1}}"}
{"receive_ns":1788563190319541000,"stream":"btcusdt@bookTicker","event_type":"bookTicker","event_time_ms":1788563190354,"raw_json":"{\"stream\":\"btcusdt@bookTicker\",\"data\":{\"e\":\"bookTicker\",\"u\":11478222304391,\"s\":\"BTCUSDT\",\"ps\":\"BTCUSDT\",\"b\":\"79607.10\",\"B\":\"10.310\",\"a\":\"79607.20\",\"A\":\"1.135\",\"T\":1788563190354,\"E\":1788563190354,\"st\":1}}"}
{"receive_ns":1788563190320230000,"stream":"btcusdt@bookTicker","event_type":"bookTicker","event_time_ms":1788563190356,"raw_json":"{\"stream\":\"btcusdt@bookTicker\",\"data\":{\"e\":\"bookTicker\",\"u\":11478222304482,\"s\":\"BTCUSDT\",\"ps\":\"BTCUSDT\",\"b\":\"79607.10\",\"B\":\"10.308\",\"a\":\"79607.20\",\"A\":\"1.135\",\"T\":1788563190355,\"E\":1788563190356,\"st\":1}}"}
{"receive_ns":1788563190362726000,"stream":"btcusdt@bookTicker","event_type":"bookTicker","event_time_ms":1788563190397,"raw_json":"{\"stream\":\"btcusdt@bookTicker\",\"data\":{\"e\":\"bookTicker\",\"u\":11478222306913,\"s\":\"BTCUSDT\",\"ps\":\"BTCUSDT\",\"b\":\"79607.10\",\"B\":\"10.302\",\"a\":\"79607.20\",\"A\":\"1.135\",\"T\":1788563190397,\"E\":1788563190397,\"st\":1}}"}
{"receive_ns":1788563190363139000,"stream":"btcusdt@trade","event_type":"trade","event_time_ms":1788563190397,"raw_json":"{\"stream\":\"btcusdt@trade\",\"data\":{\"e\":\"trade\",\"E\":1788563190397,\"T\":1788563190397,\"s\":\"BTCUSDT\",\"t\":8054082659,\"p\":\"79607.10\",\"q\":\"0.006\",\"X\":\"MARKET\",\"m\":true,\"st\":1}}"}
{"receive_ns":1788563190363452000,"stream":"btcusdt@bookTicker","event_type":"bookTicker","event_time_ms":1788563190398,"raw_json":"{\"stream\":\"btcusdt@bookTicker\",\"data\":{\"e\":\"bookTicker\",\"u\":11478222306959,\"s\":\"BTCUSDT\",\"ps\":\"BTCUSDT\",\"b\":\"79607.10\",\"B\":\"10.321\",\"a\":\"79607.20\",\"A\":\"1.135\",\"T\":1788563190398,\"E\":1788563190398,\"st\":1}}"}
{"receive_ns":1788563190363663000,"stream":"btcusdt@bookTicker","event_type":"bookTicker","event_time_ms":1788563190399,"raw_json":"{\"stream\":\"btcusdt@bookTicker\",\"data\":{\"e\":\"bookTicker\",\"u\":11478222307019,\"s\":\"BTCUSDT\",\"ps\":\"BTCUSDT\",\"b\":\"79607.10\",\"B\":\"10.329\",\"a\":\"79607.20\",\"A\":\"1.135\",\"T\":1788563190399,\"E\":1788563190399,\"st\":1}}"}
{"receive_ns":1788563190363848000,"stream":"btcusdt@bookTicker","event_type":"bookTicker","event_time_ms":1788563190399,"raw_json":"{\"stream\":\"btcusdt@bookTicker\",\"data\":{\"e\":\"bookTicker\",\"u\":11478222307046,\"s\":\"BTCUSDT\",\"ps\":\"BTCUSDT\",\"b\":\"79607.10\",\"B\":\"10.310\",\"a\":\"79607.20\",\"A\":\"1.135\",\"T\":1788563190399,\"E\":1788563190399,\"st\":1}}"}
{"receive_ns":1788563190364028000,"stream":"btcusdt@bookTicker","event_type":"bookTicker","event_time_ms":1788563190400,"raw_json":"{\"stream\":\"btcusdt@bookTicker\",\"data\":{\"e\":\"bookTicker\",\"u\":11478222307058,\"s\":\"BTCUSDT\",\"ps\":\"BTCUSDT\",\"b\":\"79607.10\",\"B\":\"10.312\",\"a\":\"79607.20\",\"A\":\"1.135\",\"T\":1788563190399,\"E\":1788563190400,\"st\":1}}"}
{"receive_ns":1788563190364187000,"stream":"btcusdt@bookTicker","event_type":"bookTicker","event_time_ms":1788563190400,"raw_json":"{\"stream\":\"btcusdt@bookTicker\",\"data\":{\"e\":\"bookTicker\",\"u\":11478222307065,\"s\":\"BTCUSDT\",\"ps\":\"BTCUSDT\",\"b\":\"79607.10\",\"B\":\"10.304\",\"a\":\"79607.20\",\"A\":\"1.135\",\"T\":1788563190399,\"E\":1788563190400,\"st\":1}}"}
{"receive_ns":1788563190364666000,"stream":"btcusdt@bookTicker","event_type":"bookTicker","event_time_ms":1788563190400,"raw_json":"{\"stream\":\"btcusdt@bookTicker\",\"data\":{\"e\":\"bookTicker\",\"u\":11478222307111,\"s\":\"BTCUSDT\",\"ps\":\"BTCUSDT\",\"b\":\"79607.10\",\"B\":\"10.323\",\"a\":\"79607.20\",\"A\":\"1.135\",\"T\":1788563190400,\"E\":1788563190400,\"st\":1}}"}
{"receive_ns":1788563190364958000,"stream":"btcusdt@bookTicker","event_type":"bookTicker","event_time_ms":1788563190401,"raw_json":"{\"stream\":\"btcusdt@bookTicker\",\"data\":{\"e\":\"bookTicker\",\"u\":11478222307207,\"s\":\"BTCUSDT\",\"ps\":\"BTCUSDT\",\"b\":\"79607.10\",\"B\":\"10.304\",\"a\":\"79607.20\",\"A\":\"1.135\",\"T\":1788563190401,\"E\":1788563190401,\"st\":1}}"}
{"receive_ns":1788563190366618000,"stream":"btcusdt@depth@100ms","event_type":"depthUpdate","event_time_ms":1788563190403,"raw_json":"{\"stream\":\"btcusdt@depth@100ms\",\"data\":{\"e\":\"depthUpdate\",\"E\":1788563190403,\"T\":1788563190402,\"s\":\"BTCUSDT\",\"ps\":\"BTCUSDT\",\"U\":11478222301746,\"u\":11478222307330,\"pu\":11478222301515,\"b\":[[\"1000.00\",\"24.604\"],[\"29307.10\",\"0.049\"],[\"29407.10\",\"1.799\"],[\"29507.10\",\"0.252\"],[\"71646.30\",\"0.002\"],[\"76422.80\",\"0.002\"],[\"78015.00\",\"0.140\"],[\"78587.50\",\"92.291\"],[\"78675.70\",\"0.896\"],[\"78811.00\",\"2.227\"],[\"79392.10\",\"0.000\"],[\"79392.20\",\"5.820\"],[\"79434.00\",\"1.431\"],[\"79440.00\",\"3.927\"],[\"79443.60\",\"0.892\"],[\"79479.40\",\"0.693\"],[\"79487.70\",\"0.276\"],[\"79507.40\",\"0.007\"],[\"79518.40\",\"0.000\"],[\"79531.30\",\"23.036\"],[\"79534.00\",\"0.001\"],[\"79534.10\",\"1.183\"],[\"79534.40\",\"0.032\"],[\"79536.70\",\"0.000\"],[\"79584.80\",\"0.277\"],[\"79602.30\",\"0.227\"],[\"79603.00\",\"0.077\"],[\"79607.10\",\"10.304\"]],\"a\":[[\"79609.30\",\"0.033\"],[\"79610.10\",\"0.027\"],[\"79610.40\",\"1.347\"],[\"79612.40\",\"0.001\"],[\"79728.60\",\"0.309\"],[\"79768.10\",\"1.719\"],[\"79812.00\",\"0.907\"],[\"79815.80\",\"2.526\"],[\"79817.70\",\"0.001\"],[\"79865.70\",\"0.001\"],[\"79973.40\",\"0.006\"],[\"79975.40\",\"1.614\"],[\"80345.30\",\"0.000\"],[\"80403.30\",\"7.057\"],[\"80602.30\",\"1.696\"],[\"80633.10\",\"86.881\"],[\"81199.30\",\"0.012\"]],\"st\":1}}"}
{"receive_ns":1788563190469171000,"stream":"btcusdt@depth@100ms","event_type":"depthUpdate","event_time_ms":1788563190505,"raw_json":"{\"stream\":\"btcusdt@depth@100ms\",\"data\":{\"e\":\"depthUpdate\",\"E\":1788563190505,\"T\":1788563190504,\"s\":\"BTCUSDT\",\"ps\":\"BTCUSDT\",\"U\":11478222307357,\"u\":11478222313044,\"pu\":11478222307330,\"b\":[[\"1000.00\",\"24.604\"],[\"29307.10\",\"0.105\"],[\"29407.10\",\"1.862\"],[\"29507.10\",\"0.133\"],[\"71646.30\",\"0.002\"],[\"76422.80\",\"0.000\"],[\"78811.00\",\"2.225\"],[\"79209.00\",\"0.001\"],[\"79209.10\",\"0.151\"],[\"79434.00\",\"0.427\"],[\"79479.40\",\"0.568\"],[\"79487.70\",\"1.582\"],[\"79491.70\",\"1.204\"],[\"79531.30\",\"0.011\"],[\"79534.00\",\"0.001\"],[\"79536.70\",\"23.025\"]],\"a\":[[\"79610.10\",\"0.001\"],[\"79610.80\",\"0.028\"],[\"79611.20\",\"0.289\"],[\"79625.70\",\"0.001\"],[\"79627.10\",\"0.453\"],[\"79722.60\",\"0.001\"],[\"79802.30\",\"0.000\"],[\"79973.40\",\"0.425\"],[\"79975.40\",\"2.139\"],[\"80005.30\",\"0.002\"],[\"80403.30\",\"7.055\"]],\"st\":1}}"}
{"receive_ns":1788563190580814000,"stream":"btcusdt@depth@100ms","event_type":"depthUpdate","event_time_ms":1788563190607,"raw_json":"{\"stream\":\"btcusdt@depth@100ms\",\"data\":{\"e\":\"depthUpdate\",\"E\":1788563190607,\"T\":1788563190605,\"s\":\"BTCUSDT\",\"ps\":\"BTCUSDT\",\"U\":11478222313163,\"u\":11478222317801,\"pu\":11478222313044,\"b\":[[\"29307.10\",\"0.175\"],[\"29407.10\",\"1.904\"],[\"29507.10\",\"0.021\"],[\"63686.00\",\"0.002\"],[\"71646.30\",\"0.002\"],[\"78090.70\",\"0.000\"],[\"78483.70\",\"12.547\"],[\"78598.00\",\"0.599\"],[\"78600.50\",\"0.003\"],[\"78811.00\",\"2.225\"],[\"79209.10\",\"0.151\"],[\"79236.90\",\"0.247\"],[\"79434.00\",\"0.427\"],[\"79487.70\",\"1.507\"],[\"79491.70\",\"1.279\"],[\"79535.40\",\"0.002\"],[\"79594.30\",\"0.165\"]],\"a\":[[\"79609.20\",\"0.502\"],[\"79610.50\",\"0.028\"],[\"79611.20\",\"0.289\"],[\"79612.30\",\"2.649\"],[\"79615.30\",\"0.700\"],[\"79615.70\",\"0.002\"],[\"79663.00\",\"0.002\"],[\"79678.90\",\"0.016\"],[\"79801.00\",\"0.878\"],[\"79975.40\",\"2.139\"],[\"80403.30\",\"7.055\"],[\"80557.60\",\"21.855\"],[\"80713.70\",\"1.459\"]],\"st\":1}}"}
{"receive_ns":1788563190606390000,"stream":"btcusdt@bookTicker","event_type":"bookTicker","event_time_ms":1788563190632,"raw_json":"{\"stream\":\"btcusdt@bookTicker\",\"data\":{\"e\":\"bookTicker\",\"u\":11478222318924,\"s\":\"BTCUSDT\",\"ps\":\"BTCUSDT\",\"b\":\"79607.10\",\"B\":\"10.305\",\"a\":\"79607.20\",\"A\":\"1.135\",\"T\":1788563190632,\"E\":1788563190632,\"st\":1}}"}
{"receive_ns":1788563190634110000,"stream":"btcusdt@bookTicker","event_type":"bookTicker","event_time_ms":1788563190669,"raw_json":"{\"stream\":\"btcusdt@bookTicker\",\"data\":{\"e\":\"bookTicker\",\"u\":11478222321462,\"s\":\"BTCUSDT\",\"ps\":\"BTCUSDT\",\"b\":\"79607.10\",\"B\":\"10.324\",\"a\":\"79607.20\",\"A\":\"1.135\",\"T\":1788563190669,\"E\":1788563190669,\"st\":1}}"}
{"receive_ns":1788563190634395000,"stream":"btcusdt@bookTicker","event_type":"bookTicker","event_time_ms":1788563190670,"raw_json":"{\"stream\":\"btcusdt@bookTicker\",\"data\":{\"e\":\"bookTicker\",\"u\":11478222321517,\"s\":\"BTCUSDT\",\"ps\":\"BTCUSDT\",\"b\":\"79607.10\",\"B\":\"10.305\",\"a\":\"79607.20\",\"A\":\"1.135\",\"T\":1788563190670,\"E\":1788563190670,\"st\":1}}"}
{"receive_ns":1788563190666332000,"stream":"btcusdt@bookTicker","event_type":"bookTicker","event_time_ms":1788563190701,"raw_json":"{\"stream\":\"btcusdt@bookTicker\",\"data\":{\"e\":\"bookTicker\",\"u\":11478222323300,\"s\":\"BTCUSDT\",\"ps\":\"BTCUSDT\",\"b\":\"79607.10\",\"B\":\"10.305\",\"a\":\"79607.20\",\"A\":\"1.136\",\"T\":1788563190701,\"E\":1788563190701,\"st\":1}}"}
{"receive_ns":1788563190673262000,"stream":"btcusdt@depth@100ms","event_type":"depthUpdate","event_time_ms":1788563190709,"raw_json":"{\"stream\":\"btcusdt@depth@100ms\",\"data\":{\"e\":\"depthUpdate\",\"E\":1788563190709,\"T\":1788563190707,\"s\":\"BTCUSDT\",\"ps\":\"BTCUSDT\",\"U\":11478222317866,\"u\":11478222323766,\"pu\":11478222317801,\"b\":[[\"1000.00\",\"24.604\"],[\"29307.10\",\"0.329\"],[\"29407.10\",\"1.771\"],[\"29507.10\",\"0.000\"],[\"71646.30\",\"0.002\"],[\"75626.70\",\"0.016\"],[\"76422.80\",\"0.002\"],[\"78811.00\",\"2.225\"],[\"79434.00\",\"0.929\"],[\"79479.40\",\"0.000\"],[\"79487.70\",\"1.005\"],[\"79491.70\",\"0.075\"],[\"79583.40\",\"1.875\"],[\"79603.00\",\"0.001\"],[\"79607.10\",\"10.305\"]],\"a\":[[\"79607.20\",\"1.136\"],[\"79608.70\",\"0.026\"],[\"79608.80\",\"0.027\"],[\"79609.10\",\"0.026\"],[\"79609.30\",\"0.059\"],[\"79611.20\",\"0.090\"],[\"79611.70\",\"0.003\"],[\"79611.90\",\"0.078\"],[\"79612.00\",\"0.280\"],[\"79612.10\",\"0.002\"],[\"79623.30\",\"0.045\"],[\"79728.60\",\"0.000\"],[\"79973.40\",\"0.006\"],[\"79975.40\",\"1.795\"],[\"80005.20\",\"0.138\"],[\"80324.00\",\"0.062\"],[\"80379.40\",\"1.960\"],[\"80403.30\",\"7.055\"],[\"80557.60\",\"18.136\"],[\"81199.30\",\"0.009\"]],\"st\":1}}"}
{"receive_ns":1788563190673571000,"stream":"btcusdt@bookTicker","event_type":"bookTicker","event_time_ms":1788563190709,"raw_json":"{\"stream\":\"btcusdt@bookTicker\",\"data\":{\"e\":\"bookTicker\",\"u\":11478222323906,\"s\":\"BTCUSDT\",\"ps\":\"BTCUSDT\",\"b\":\"79607.10\",\"B\":\"10.324\",\"a\":\"79607.20\",\"A\":\"1.136\",\"T\":1788563190709,\"E\":1788563190709,\"st\":1}}"}
{"receive_ns":1788563190673740000,"stream":"btcusdt@bookTicker","event_type":"bookTicker","event_time_ms":1788563190710,"raw_json":"{\"stream\":\"btcusdt@bookTicker\",\"data\":{\"e\":\"bookTicker\",\"u\":11478222323941,\"s\":\"BTCUSDT\",\"ps\":\"BTCUSDT\",\"b\":\"79607.10\",\"B\":\"10.332\",\"a\":\"79607.20\",\"A\":\"1.136\",\"T\":1788563190709,\"E\":1788563190710,\"st\":1}}"}
{"receive_ns":1788563190674152000,"stream":"btcusdt@bookTicker","event_type":"bookTicker","event_time_ms":1788563190710,"raw_json":"{\"stream\":\"btcusdt@bookTicker\",\"data\":{\"e\":\"bookTicker\",\"u\":11478222323988,\"s\":\"BTCUSDT\",\"ps\":\"BTCUSDT\",\"b\":\"79607.10\",\"B\":\"10.313\",\"a\":\"79607.20\",\"A\":\"1.136\",\"T\":1788563190710,\"E\":1788563190710,\"st\":1}}"}
{"receive_ns":1788563190674379000,"stream":"btcusdt@bookTicker","event_type":"bookTicker","event_time_ms":1788563190710,"raw_json":"{\"stream\":\"btcusdt@bookTicker\",\"data\":{\"e\":\"bookTicker\",\"u\":11478222323998,\"s\":\"BTCUSDT\",\"ps\":\"BTCUSDT\",\"b\":\"79607.10\",\"B\":\"10.305\",\"a\":\"79607.20\",\"A\":\"1.136\",\"T\":1788563190710,\"E\":1788563190710,\"st\":1}}"}
{"receive_ns":1788563190690460000,"stream":"btcusdt@bookTicker","event_type":"bookTicker","event_time_ms":1788563190725,"raw_json":"{\"stream\":\"btcusdt@bookTicker\",\"data\":{\"e\":\"bookTicker\",\"u\":11478222324817,\"s\":\"BTCUSDT\",\"ps\":\"BTCUSDT\",\"b\":\"79607.10\",\"B\":\"10.324\",\"a\":\"79607.20\",\"A\":\"1.136\",\"T\":1788563190725,\"E\":1788563190725,\"st\":1}}"}
{"receive_ns":1788563190690856000,"stream":"btcusdt@bookTicker","event_type":"bookTicker","event_time_ms":1788563190726,"raw_json":"{\"stream\":\"btcusdt@bookTicker\",\"data\":{\"e\":\"bookTicker\",\"u\":11478222324852,\"s\":\"BTCUSDT\",\"ps\":\"BTCUSDT\",\"b\":\"79607.10\",\"B\":\"10.305\",\"a\":\"79607.20\",\"A\":\"1.136\",\"T\":1788563190726,\"E\":1788563190726,\"st\":1}}"}
{"receive_ns":1788563190784874000,"stream":"btcusdt@depth@100ms","event_type":"depthUpdate","event_time_ms":1788563190811,"raw_json":"{\"stream\":\"btcusdt@depth@100ms\",\"data\":{\"e\":\"depthUpdate\",\"E\":1788563190811,\"T\":1788563190810,\"s\":\"BTCUSDT\",\"ps\":\"BTCUSDT\",\"U\":11478222323906,\"u\":11478222328665,\"pu\":11478222323766,\"b\":[[\"1000.00\",\"24.604\"],[\"29307.10\",\"0.511\"],[\"29407.10\",\"1.589\"],[\"71646.30\",\"0.002\"],[\"71680.00\",\"0.130\"],[\"76422.80\",\"0.000\"],[\"78226.00\",\"0.640\"],[\"78413.00\",\"0.287\"],[\"78811.00\",\"2.225\"],[\"79204.30\",\"3.590\"],[\"79209.10\",\"0.277\"],[\"79236.90\",\"0.247\"],[\"79434.00\",\"0.929\"],[\"79479.40\",\"0.598\"],[\"79487.70\",\"2.209\"],[\"79491.70\",\"0.075\"],[\"79607.10\",\"10.305\"]],\"a\":[[\"79609.20\",\"0.502\"],[\"79611.20\",\"0.289\"],[\"79728.60\",\"0.340\"],[\"79975.40\",\"2.558\"],[\"80005.20\",\"0.136\"],[\"80403.30\",\"7.055\"]],\"st\":1}}"}
{"receive_ns":1788563190879802000,"stream":"btcusdt@depth@100ms","event_type":"depthUpdate","event_time_ms":1788563190913,"raw_json":"{\"stream\":\"btcusdt@depth@100ms\",\"data\":{\"e\":\"depthUpdate\",\"E\":1788563190913,\"T\":1788563190911,\"s\":\"BTCUSDT\",\"ps\":\"BTCUSDT\",\"U\":11478222328731,\"u\":11478222333697,\"pu\":11478222328665,\"b\":[[\"29307.10\",\"0.686\"],[\"29407.10\",\"1.414\"],[\"63685.70\",\"0.001\"],[\"71646.30\",\"0.002\"],[\"71680.00\",\"0.127\"],[\"75622.30\",\"0.002\"],[\"76422.80\",\"0.002\"],[\"77378.10\",\"0.516\"],[\"78811.00\",\"2.227\"],[\"79434.00\",\"0.427\"],[\"79487.70\",\"1.205\"]],\"a\":[[\"79625.90\",\"0.453\"],[\"79627.10\",\"0.001\"],[\"79975.40\",\"1.614\"],[\"80403.30\",\"7.055\"],[\"80562.50\",\"6.823\"],[\"80653.20\",\"1.740\"],[\"87568.00\",\"0.000\"]],\"st\":1}}"}
{"receive_ns":1788563190907163000,"stream":"btcusdt@bookTicker","event_type":"bookTicker","event_time_ms":1788563190942,"raw_json":"{\"stream\":\"btcusdt@bookTicker\",\"data\":{\"e\":\"bookTicker\",\"u\":11478222335750,\"s\":\"BTCUSDT\",\"ps\":\"BTCUSDT\",\"b\":\"79607.10\",\"B\":\"10.324\",\"a\":\"79607.20\",\"A\":\"1.136\",\"T\":1788563190942,\"E\":1788563190942,\"st\":1}}"}
{"receive_ns":1788563190908582000,"stream":"btcusdt@bookTicker","event_type":"bookTicker","event_time_ms":1788563190943,"raw_json":"{\"stream\":\"btcusdt@bookTicker\",\"data\":{\"e\":\"bookTicker\",\"u\":11478222335778,\"s\":\"BTCUSDT\",\"ps\":\"BTCUSDT\",\"b\":\"79607.10\",\"B\":\"10.305\",\"a\":\"79607.20\",\"A\":\"1.136\",\"T\":1788563190943,\"E\":1788563190943,\"st\":1}}"}
{"receive_ns":1788563190914066000,"stream":"btcusdt@bookTicker","event_type":"bookTicker","event_time_ms":1788563190948,"raw_json":"{\"stream\":\"btcusdt@bookTicker\",\"data\":{\"e\":\"bookTicker\",\"u\":11478222336034,\"s\":\"BTCUSDT\",\"ps\":\"BTCUSDT\",\"b\":\"79607.10\",\"B\":\"10.343\",\"a\":\"79607.20\",\"A\":\"1.136\",\"T\":1788563190948,\"E\":1788563190948,\"st\":1}}"}
{"receive_ns":1788563190914338000,"stream":"btcusdt@bookTicker","event_type":"bookTicker","event_time_ms":1788563190948,"raw_json":"{\"stream\":\"btcusdt@bookTicker\",\"data\":{\"e\":\"bookTicker\",\"u\":11478222336046,\"s\":\"BTCUSDT\",\"ps\":\"BTCUSDT\",\"b\":\"79607.10\",\"B\":\"10.381\",\"a\":\"79607.20\",\"A\":\"1.136\",\"T\":1788563190948,\"E\":1788563190948,\"st\":1}}"}
{"receive_ns":1788563190934119000,"stream":"btcusdt@bookTicker","event_type":"bookTicker","event_time_ms":1788563190968,"raw_json":"{\"stream\":\"btcusdt@bookTicker\",\"data\":{\"e\":\"bookTicker\",\"u\":11478222337003,\"s\":\"BTCUSDT\",\"ps\":\"BTCUSDT\",\"b\":\"79607.10\",\"B\":\"10.400\",\"a\":\"79607.20\",\"A\":\"1.136\",\"T\":1788563190967,\"E\":1788563190968,\"st\":1}}"}
{"receive_ns":1788563190934379000,"stream":"btcusdt@bookTicker","event_type":"bookTicker","event_time_ms":1788563190968,"raw_json":"{\"stream\":\"btcusdt@bookTicker\",\"data\":{\"e\":\"bookTicker\",\"u\":11478222337021,\"s\":\"BTCUSDT\",\"ps\":\"BTCUSDT\",\"b\":\"79607.10\",\"B\":\"10.408\",\"a\":\"79607.20\",\"A\":\"1.136\",\"T\":1788563190968,\"E\":1788563190968,\"st\":1}}"}
{"receive_ns":1788563190934567000,"stream":"btcusdt@bookTicker","event_type":"bookTicker","event_time_ms":1788563190968,"raw_json":"{\"stream\":\"btcusdt@bookTicker\",\"data\":{\"e\":\"bookTicker\",\"u\":11478222337080,\"s\":\"BTCUSDT\",\"ps\":\"BTCUSDT\",\"b\":\"79607.10\",\"B\":\"10.400\",\"a\":\"79607.20\",\"A\":\"1.136\",\"T\":1788563190968,\"E\":1788563190968,\"st\":1}}"}
{"receive_ns":1788563190934719000,"stream":"btcusdt@bookTicker","event_type":"bookTicker","event_time_ms":1788563190968,"raw_json":"{\"stream\":\"btcusdt@bookTicker\",\"data\":{\"e\":\"bookTicker\",\"u\":11478222337081,\"s\":\"BTCUSDT\",\"ps\":\"BTCUSDT\",\"b\":\"79607.10\",\"B\":\"10.381\",\"a\":\"79607.20\",\"A\":\"1.136\",\"T\":1788563190968,\"E\":1788563190968,\"st\":1}}"}
{"receive_ns":1788563190934928000,"stream":"btcusdt@bookTicker","event_type":"bookTicker","event_time_ms":1788563190970,"raw_json":"{\"stream\":\"btcusdt@bookTicker\",\"data\":{\"e\":\"bookTicker\",\"u\":11478222337237,\"s\":\"BTCUSDT\",\"ps\":\"BTCUSDT\",\"b\":\"79607.10\",\"B\":\"10.115\",\"a\":\"79607.20\",\"A\":\"1.136\",\"T\":1788563190970,\"E\":1788563190970,\"st\":1}}"}
{"receive_ns":1788563190938298000,"stream":"btcusdt@bookTicker","event_type":"bookTicker","event_time_ms":1788563190973,"raw_json":"{\"stream\":\"btcusdt@bookTicker\",\"data\":{\"e\":\"bookTicker\",\"u\":11478222337378,\"s\":\"BTCUSDT\",\"ps\":\"BTCUSDT\",\"b\":\"79607.10\",\"B\":\"10.392\",\"a\":\"79607.20\",\"A\":\"1.136\",\"T\":1788563190973,\"E\":1788563190973,\"st\":1}}"}
{"receive_ns":1788563190960358000,"stream":"btcusdt@bookTicker","event_type":"bookTicker","event_time_ms":1788563190995,"raw_json":"{\"stream\":\"btcusdt@bookTicker\",\"data\":{\"e\":\"bookTicker\",\"u\":11478222338463,\"s\":\"BTCUSDT\",\"ps\":\"BTCUSDT\",\"b\":\"79607.10\",\"B\":\"10.411\",\"a\":\"79607.20\",\"A\":\"1.136\",\"T\":1788563190995,\"E\":1788563190995,\"st\":1}}"}
{"receive_ns":1788563190960621000,"stream":"btcusdt@bookTicker","event_type":"bookTicker","event_time_ms":1788563190995,"raw_json":"{\"stream\":\"btcusdt@bookTicker\",\"data\":{\"e\":\"bookTicker\",\"u\":11478222338498,\"s\":\"BTCUSDT\",\"ps\":\"BTCUSDT\",\"b\":\"79607.10\",\"B\":\"10.392\",\"a\":\"79607.20\",\"A\":\"1.136\",\"T\":1788563190995,\"E\":1788563190995,\"st\":1}}"}
{"receive_ns":1788563190960854000,"stream":"btcusdt@bookTicker","event_type":"bookTicker","event_time_ms":1788563190996,"raw_json":"{\"stream\":\"btcusdt@bookTicker\",\"data\":{\"e\":\"bookTicker\",\"u\":11478222338554,\"s\":\"BTCUSDT\",\"ps\":\"BTCUSDT\",\"b\":\"79607.10\",\"B\":\"10.390\",\"a\":\"79607.20\",\"A\":\"1.136\",\"T\":1788563190996,\"E\":1788563190996,\"st\":1}}"}
{"receive_ns":1788563190963404000,"stream":"btcusdt@bookTicker","event_type":"bookTicker","event_time_ms":1788563190998,"raw_json":"{\"stream\":\"btcusdt@bookTicker\",\"data\":{\"e\":\"bookTicker\",\"u\":11478222338705,\"s\":\"BTCUSDT\",\"ps\":\"BTCUSDT\",\"b\":\"79607.10\",\"B\":\"10.385\",\"a\":\"79607.20\",\"A\":\"1.136\",\"T\":1788563190998,\"E\":1788563190998,\"st\":1}}"}
{"receive_ns":1788563190980572000,"stream":"btcusdt@depth@100ms","event_type":"depthUpdate","event_time_ms":1788563191015,"raw_json":"{\"stream\":\"btcusdt@depth@100ms\",\"data\":{\"e\":\"depthUpdate\",\"E\":1788563191015,\"T\":1788563191014,\"s\":\"BTCUSDT\",\"ps\":\"BTCUSDT\",\"U\":11478222333866,\"u\":11478222339693,\"pu\":11478222333697,\"b\":[[\"1000.00\",\"24.604\"],[\"29307.10\",\"0.868\"],[\"29407.10\",\"1.232\"],[\"71646.30\",\"0.002\"],[\"76422.80\",\"0.000\"],[\"78015.00\",\"0.143\"],[\"78811.00\",\"2.225\"],[\"79209.10\",\"0.136\"],[\"79236.90\",\"0.015\"],[\"79392.20\",\"6.424\"],[\"79434.00\",\"0.578\"],[\"79440.00\",\"4.088\"],[\"79479.40\",\"0.598\"],[\"79479.70\",\"0.683\"],[\"79487.70\",\"2.209\"],[\"79491.70\",\"0.000\"],[\"79531.30\",\"23.199\"],[\"79536.70\",\"0.000\"],[\"79575.30\",\"0.001\"],[\"79576.20\",\"0.001\"],[\"79577.40\",\"0.452\"],[\"79607.10\",\"10.385\"]],\"a\":[[\"79608.30\",\"0.028\"],[\"79608.70\",\"0.000\"],[\"79608.80\",\"0.001\"],[\"79609.20\",\"0.000\"],[\"79611.20\",\"0.199\"],[\"79625.90\",\"0.001\"],[\"79627.10\",\"0.453\"],[\"79728.60\",\"0.340\"],[\"79768.00\",\"1.957\"],[\"79768.10\",\"0.000\"],[\"79815.80\",\"3.222\"],[\"79975.40\",\"2.358\"],[\"80403.30\",\"7.055\"],[\"80737.60\",\"0.592\"]],\"st\":1}}"}
{"receive_ns":1788563191024802000,"stream":"btcusdt@bookTicker","event_type":"bookTicker","event_time_ms":1788563191059,"raw_json":"{\"stream\":\"btcusdt@bookTicker\",\"data\":{\"e\":\"bookTicker\",\"u\":11478222342917,\"s\":\"BTCUSDT\",\"ps\":\"BTCUSDT\",\"b\":\"79607.10\",\"B\":\"10.386\",\"a\":\"79607.20\",\"A\":\"1.136\",\"T\":1788563191059,\"E\":1788563191059,\"st\":1}}"}
{"receive_ns":1788563191039701000,"stream":"btcusdt@bookTicker","event_type":"bookTicker","event_time_ms":1788563191074,"raw_json":"{\"stream\":\"btcusdt@bookTicker\",\"data\":{\"e\":\"bookTicker\",\"u\":11478222344653,\"s\":\"BTCUSDT\",\"ps\":\"BTCUSDT\",\"b\":\"79607.10\",\"B\":\"10.394\",\"a\":\"79607.20\",\"A\":\"1.136\",\"T\":1788563191073,\"E\":1788563191074,\"st\":1}}"}
{"receive_ns":1788563191039904000,"stream":"btcusdt@bookTicker","event_type":"bookTicker","event_time_ms":1788563191074,"raw_json":"{\"stream\":\"btcusdt@bookTicker\",\"data\":{\"e\":\"bookTicker\",\"u\":11478222344658,\"s\":\"BTCUSDT\",\"ps\":\"BTCUSDT\",\"b\":\"79607.10\",\"B\":\"10.413\",\"a\":\"79607.20\",\"A\":\"1.136\",\"T\":1788563191073,\"E\":1788563191074,\"st\":1}}"}
{"receive_ns":1788563191040087000,"stream":"btcusdt@bookTicker","event_type":"bookTicker","event_time_ms":1788563191074,"raw_json":"{\"stream\":\"btcusdt@bookTicker\",\"data\":{\"e\":\"bookTicker\",\"u\":11478222344758,\"s\":\"BTCUSDT\",\"ps\":\"BTCUSDT\",\"b\":\"79607.10\",\"B\":\"10.405\",\"a\":\"79607.20\",\"A\":\"1.136\",\"T\":1788563191074,\"E\":1788563191074,\"st\":1}}"}
{"receive_ns":1788563191040241000,"stream":"btcusdt@bookTicker","event_type":"bookTicker","event_time_ms":1788563191074,"raw_json":"{\"stream\":\"btcusdt@bookTicker\",\"data\":{\"e\":\"bookTicker\",\"u\":11478222344763,\"s\":\"BTCUSDT\",\"ps\":\"BTCUSDT\",\"b\":\"79607.10\",\"B\":\"10.386\",\"a\":\"79607.20\",\"A\":\"1.136\",\"T\":1788563191074,\"E\":1788563191074,\"st\":1}}"}
{"receive_ns":1788563191040449000,"stream":"btcusdt@bookTicker","event_type":"bookTicker","event_time_ms":1788563191075,"raw_json":"{\"stream\":\"btcusdt@bookTicker\",\"data\":{\"e\":\"bookTicker\",\"u\":11478222344795,\"s\":\"BTCUSDT\",\"ps\":\"BTCUSDT\",\"b\":\"79607.10\",\"B\":\"10.388\",\"a\":\"79607.20\",\"A\":\"1.136\",\"T\":1788563191075,\"E\":1788563191075,\"st\":1}}"}
{"receive_ns":1788563191049248000,"stream":"btcusdt@bookTicker","event_type":"bookTicker","event_time_ms":1788563191084,"raw_json":"{\"stream\":\"btcusdt@bookTicker\",\"data\":{\"e\":\"bookTicker\",\"u\":11478222345296,\"s\":\"BTCUSDT\",\"ps\":\"BTCUSDT\",\"b\":\"79607.10\",\"B\":\"10.407\",\"a\":\"79607.20\",\"A\":\"1.136\",\"T\":1788563191083,\"E\":1788563191084,\"st\":1}}"}
{"receive_ns":1788563191049490000,"stream":"btcusdt@bookTicker","event_type":"bookTicker","event_time_ms":1788563191084,"raw_json":"{\"stream\":\"btcusdt@bookTicker\",\"data\":{\"e\":\"bookTicker\",\"u\":11478222345400,\"s\":\"BTCUSDT\",\"ps\":\"BTCUSDT\",\"b\":\"79607.10\",\"B\":\"10.388\",\"a\":\"79607.20\",\"A\":\"1.136\",\"T\":1788563191084,\"E\":1788563191084,\"st\":1}}"}
{"receive_ns":1788563191056252000,"stream":"btcusdt@bookTicker","event_type":"bookTicker","event_time_ms":1788563191092,"raw_json":"{\"stream\":\"btcusdt@bookTicker\",\"data\":{\"e\":\"bookTicker\",\"u\":11478222346207,\"s\":\"BTCUSDT\",\"ps\":\"BTCUSDT\",\"b\":\"79607.10\",\"B\":\"10.385\",\"a\":\"79607.20\",\"A\":\"1.136\",\"T\":1788563191092,\"E\":1788563191092,\"st\":1}}"}
{"receive_ns":1788563191056488000,"stream":"btcusdt@trade","event_type":"trade","event_time_ms":1788563191092,"raw_json":"{\"stream\":\"btcusdt@trade\",\"data\":{\"e\":\"trade\",\"E\":1788563191092,\"T\":1788563191092,\"s\":\"BTCUSDT\",\"t\":8054082660,\"p\":\"79607.10\",\"q\":\"0.003\",\"X\":\"MARKET\",\"m\":true,\"st\":1}}"}
{"receive_ns":1788563191057419000,"stream":"btcusdt@bookTicker","event_type":"bookTicker","event_time_ms":1788563191093,"raw_json":"{\"stream\":\"btcusdt@bookTicker\",\"data\":{\"e\":\"bookTicker\",\"u\":11478222346277,\"s\":\"BTCUSDT\",\"ps\":\"BTCUSDT\",\"b\":\"79607.10\",\"B\":\"10.393\",\"a\":\"79607.20\",\"A\":\"1.136\",\"T\":1788563191093,\"E\":1788563191093,\"st\":1}}"}
{"receive_ns":1788563191057604000,"stream":"btcusdt@bookTicker","event_type":"bookTicker","event_time_ms":1788563191093,"raw_json":"{\"stream\":\"btcusdt@bookTicker\",\"data\":{\"e\":\"bookTicker\",\"u\":11478222346292,\"s\":\"BTCUSDT\",\"ps\":\"BTCUSDT\",\"b\":\"79607.10\",\"B\":\"10.412\",\"a\":\"79607.20\",\"A\":\"1.136\",\"T\":1788563191093,\"E\":1788563191093,\"st\":1}}"}
{"receive_ns":1788563191057950000,"stream":"btcusdt@bookTicker","event_type":"bookTicker","event_time_ms":1788563191094,"raw_json":"{\"stream\":\"btcusdt@bookTicker\",\"data\":{\"e\":\"bookTicker\",\"u\":11478222346380,\"s\":\"BTCUSDT\",\"ps\":\"BTCUSDT\",\"b\":\"79607.10\",\"B\":\"10.404\",\"a\":\"79607.20\",\"A\":\"1.136\",\"T\":1788563191094,\"E\":1788563191094,\"st\":1}}"}
{"receive_ns":1788563191058138000,"stream":"btcusdt@bookTicker","event_type":"bookTicker","event_time_ms":1788563191094,"raw_json":"{\"stream\":\"btcusdt@bookTicker\",\"data\":{\"e\":\"bookTicker\",\"u\":11478222346388,\"s\":\"BTCUSDT\",\"ps\":\"BTCUSDT\",\"b\":\"79607.10\",\"B\":\"10.385\",\"a\":\"79607.20\",\"A\":\"1.136\",\"T\":1788563191094,\"E\":1788563191094,\"st\":1}}"}
{"receive_ns":1788563191068000000,"stream":"btcusdt@bookTicker","event_type":"bookTicker","event_time_ms":1788563191102,"raw_json":"{\"stream\":\"btcusdt@bookTicker\",\"data\":{\"e\":\"bookTicker\",\"u\":11478222347049,\"s\":\"BTCUSDT\",\"ps\":\"BTCUSDT\",\"b\":\"79607.10\",\"B\":\"10.393\",\"a\":\"79607.20\",\"A\":\"1.136\",\"T\":1788563191102,\"E\":1788563191102,\"st\":1}}"}
{"receive_ns":1788563191068187000,"stream":"btcusdt@bookTicker","event_type":"bookTicker","event_time_ms":1788563191102,"raw_json":"{\"stream\":\"btcusdt@bookTicker\",\"data\":{\"e\":\"bookTicker\",\"u\":11478222347052,\"s\":\"BTCUSDT\",\"ps\":\"BTCUSDT\",\"b\":\"79607.10\",\"B\":\"10.412\",\"a\":\"79607.20\",\"A\":\"1.136\",\"T\":1788563191102,\"E\":1788563191102,\"st\":1}}"}
{"receive_ns":1788563191068400000,"stream":"btcusdt@bookTicker","event_type":"bookTicker","event_time_ms":1788563191103,"raw_json":"{\"stream\":\"btcusdt@bookTicker\",\"data\":{\"e\":\"bookTicker\",\"u\":11478222347115,\"s\":\"BTCUSDT\",\"ps\":\"BTCUSDT\",\"b\":\"79607.10\",\"B\":\"10.393\",\"a\":\"79607.20\",\"A\":\"1.136\",\"T\":1788563191103,\"E\":1788563191103,\"st\":1}}"}
{"receive_ns":1788563191068559000,"stream":"btcusdt@bookTicker","event_type":"bookTicker","event_time_ms":1788563191103,"raw_json":"{\"stream\":\"btcusdt@bookTicker\",\"data\":{\"e\":\"bookTicker\",\"u\":11478222347120,\"s\":\"BTCUSDT\",\"ps\":\"BTCUSDT\",\"b\":\"79607.10\",\"B\":\"10.385\",\"a\":\"79607.20\",\"A\":\"1.136\",\"T\":1788563191103,\"E\":1788563191103,\"st\":1}}"}
{"receive_ns":1788563191082035000,"stream":"btcusdt@depth@100ms","event_type":"depthUpdate","event_time_ms":1788563191117,"raw_json":"{\"stream\":\"btcusdt@depth@100ms\",\"data\":{\"e\":\"depthUpdate\",\"E\":1788563191117,\"T\":1788563191113,\"s\":\"BTCUSDT\",\"ps\":\"BTCUSDT\",\"U\":11478222339808,\"u\":11478222347785,\"pu\":11478222339693,\"b\":[[\"1000.00\",\"24.604\"],[\"29307.10\",\"1.043\"],[\"29407.10\",\"1.057\"],[\"71646.30\",\"0.002\"],[\"78015.00\",\"0.146\"],[\"78476.70\",\"0.307\"],[\"78721.90\",\"0.317\"],[\"78811.00\",\"2.225\"],[\"79209.00\",\"0.000\"],[\"79209.10\",\"0.277\"],[\"79211.10\",\"0.067\"],[\"79236.90\",\"0.247\"],[\"79434.00\",\"0.929\"],[\"79479.30\",\"0.186\"],[\"79479.70\",\"0.558\"],[\"79491.70\",\"0.075\"],[\"79518.60\",\"0.829\"],[\"79531.80\",\"4.142\"],[\"79534.50\",\"0.691\"],[\"79563.20\",\"2.243\"],[\"79576.20\",\"0.453\"],[\"79577.40\",\"0.000\"],[\"79592.80\",\"0.003\"],[\"79600.50\",\"0.000\"],[\"79602.30\",\"0.226\"],[\"79605.70\",\"0.000\"],[\"79607.10\",\"10.385\"]],\"a\":[[\"79607.90\",\"0.026\"],[\"79608.00\",\"0.029\"],[\"79608.30\",\"0.002\"],[\"79608.60\",\"0.026\"],[\"79608.80\",\"0.027\"],[\"79608.90\",\"0.026\"],[\"79609.20\",\"0.502\"],[\"79611.10\",\"0.001\"],[\"79611.20\",\"0.289\"],[\"79611.50\",\"0.570\"],[\"79611.60\",\"0.001\"],[\"79975.40\",\"9.302\"],[\"80005.30\",\"0.003\"],[\"80403.30\",\"7.055\"],[\"80557.60\",\"16.649\"]],\"st\":1}}"}
{"receive_ns":1788563191122488000,"stream":"btcusdt@bookTicker","event_type":"bookTicker","event_time_ms":1788563191156,"raw_json":"{\"stream\":\"btcusdt@bookTicker\",\"data\":{\"e\":\"bookTicker\",\"u\":11478222351303,\"s\":\"BTCUSDT\",\"ps\":\"BTCUSDT\",\"b\":\"79607.10\",\"B\":\"10.404\",\"a\":\"79607.20\",\"A\":\"1.136\",\"T\":1788563191156,\"E\":1788563191156,\"st\":1}}"}
{"receive_ns":1788563191122704000,"stream":"btcusdt@bookTicker","event_type":"bookTicker","event_time_ms":1788563191156,"raw_json":"{\"stream\":\"btcusdt@bookTicker\",\"data\":{\"e\":\"bookTicker\",\"u\":11478222351316,\"s\":\"BTCUSDT\",\"ps\":\"BTCUSDT\",\"b\":\"79607.10\",\"B\":\"10.412\",\"a\":\"79607.20\",\"A\":\"1.136\",\"T\":1788563191156,\"E\":1788563191156,\"st\":1}}"}
{"receive_ns":1788563191122887000,"stream":"btcusdt@bookTicker","event_type":"bookTicker","event_time_ms":1788563191156,"raw_json":"{\"stream\":\"btcusdt@bookTicker\",\"data\":{\"e\":\"bookTicker\",\"u\":11478222351385,\"s\":\"BTCUSDT\",\"ps\":\"BTCUSDT\",\"b\":\"79607.10\",\"B\":\"10.393\",\"a\":\"79607.20\",\"A\":\"1.136\",\"T\":1788563191156,\"E\":1788563191156,\"st\":1}}"}
{"receive_ns":1788563191123157000,"stream":"btcusdt@bookTicker","event_type":"bookTicker","event_time_ms":1788563191157,"raw_json":"{\"stream\":\"btcusdt@bookTicker\",\"data\":{\"e\":\"bookTicker\",\"u\":11478222351457,\"s\":\"BTCUSDT\",\"ps\":\"BTCUSDT\",\"b\":\"79607.10\",\"B\":\"10.385\",\"a\":\"79607.20\",\"A\":\"1.136\",\"T\":1788563191157,\"E\":1788563191157,\"st\":1}}"}
{"receive_ns":1788563191181991000,"stream":"btcusdt@bookTicker","event_type":"bookTicker","event_time_ms":1788563191216,"raw_json":"{\"stream\":\"btcusdt@bookTicker\",\"data\":{\"e\":\"bookTicker\",\"u\":11478222355591,\"s\":\"BTCUSDT\",\"ps\":\"BTCUSDT\",\"b\":\"79607.10\",\"B\":\"10.404\",\"a\":\"79607.20\",\"A\":\"1.136\",\"T\":1788563191216,\"E\":1788563191216,\"st\":1}}"}
{"receive_ns":1788563191182261000,"stream":"btcusdt@bookTicker","event_type":"bookTicker","event_time_ms":1788563191217,"raw_json":"{\"stream\":\"btcusdt@bookTicker\",\"data\":{\"e\":\"bookTicker\",\"u\":11478222355628,\"s\":\"BTCUSDT\",\"ps\":\"BTCUSDT\",\"b\":\"79607.10\",\"B\":\"10.385\",\"a\":\"79607.20\",\"A\":\"1.136\",\"T\":1788563191217,\"E\":1788563191217,\"st\":1}}"}
{"receive_ns":1788563191184774000,"stream":"btcusdt@depth@100ms","event_type":"depthUpdate","event_time_ms":1788563191219,"raw_json":"{\"stream\":\"btcusdt@depth@100ms\",\"data\":{\"e\":\"depthUpdate\",\"E\":1788563191219,\"T\":1788563191218,\"s\":\"BTCUSDT\",\"ps\":\"BTCUSDT\",\"U\":11478222348072,\"u\":11478222355830,\"pu\":11478222347785,\"b\":[[\"29307.10\",\"1.225\"],[\"29407.10\",\"0.875\"],[\"63686.00\",\"0.002\"],[\"71646.30\",\"0.002\"],[\"76422.80\",\"0.002\"],[\"78493.80\",\"6.185\"],[\"78811.00\",\"2.227\"],[\"79209.10\",\"0.136\"],[\"79236.90\",\"0.015\"],[\"79434.00\",\"0.578\"],[\"79479.40\",\"0.000\"],[\"79487.70\",\"1.005\"],[\"79491.70\",\"1.204\"],[\"79531.30\",\"0.011\"],[\"79531.80\",\"0.757\"],[\"79534.00\",\"23.189\"],[\"79563.10\",\"1.230\"],[\"79597.50\",\"0.006\"],[\"79598.00\",\"0.002\"],[\"79607.10\",\"10.385\"]],\"a\":[[\"79607.90\",\"0.000\"],[\"79608.00\",\"0.003\"],[\"79608.60\",\"0.000\"],[\"79609.20\",\"0.000\"],[\"79609.40\",\"0.030\"],[\"79611.20\",\"0.000\"],[\"79682.90\",\"0.003\"],[\"79688.50\",\"1.938\"],[\"79688.60\",\"0.005\"],[\"79707.80\",\"0.003\"],[\"79728.60\",\"0.000\"],[\"79973.40\",\"1.713\"],[\"79975.40\",\"7.395\"],[\"80403.30\",\"7.055\"],[\"80558.40\",\"4.920\"],[\"80593.20\",\"4.247\"]],\"st\":1}}"}
{"receive_ns":1788563191185025000,"stream":"btcusdt@bookTicker","event_type":"bookTicker","event_time_ms":1788563191220,"raw_json":"{\"stream\":\"btcusdt@bookTicker\",\"data\":{\"e\":\"bookTicker\",\"u\":11478222355908,\"s\":\"BTCUSDT\",\"ps\":\"BTCUSDT\",\"b\":\"79607.10\",\"B\":\"10.404\",\"a\":\"79607.20\",\"A\":\"1.136\",\"T\":1788563191220,\"E\":1788563191220,\"st\":1}}"}
{"receive_ns":1788563191185198000,"stream":"btcusdt@bookTicker","event_type":"bookTicker","event_time_ms":1788563191220,"raw_json":"{\"stream\":\"btcusdt@bookTicker\",\"data\":{\"e\":\"bookTicker\",\"u\":11478222355909,\"s\":\"BTCUSDT\",\"ps\":\"BTCUSDT\",\"b\":\"79607.10\",\"B\":\"10.412\",\"a\":\"79607.20\",\"A\":\"1.136\",\"T\":1788563191220,\"E\":1788563191220,\"st\":1}}"}
{"receive_ns":1788563191185405000,"stream":"btcusdt@bookTicker","event_type":"bookTicker","event_time_ms":1788563191220,"raw_json":"{\"stream\":\"btcusdt@bookTicker\",\"data\":{\"e\":\"bookTicker\",\"u\":11478222355980,\"s\":\"BTCUSDT\",\"ps\":\"BTCUSDT\",\"b\":\"79607.10\",\"B\":\"10.393\",\"a\":\"79607.20\",\"A\":\"1.136\",\"T\":1788563191220,\"E\":1788563191220,\"st\":1}}"}
{"receive_ns":1788563191185566000,"stream":"btcusdt@bookTicker","event_type":"bookTicker","event_time_ms":1788563191220,"raw_json":"{\"stream\":\"btcusdt@bookTicker\",\"data\":{\"e\":\"bookTicker\",\"u\":11478222355982,\"s\":\"BTCUSDT\",\"ps\":\"BTCUSDT\",\"b\":\"79607.10\",\"B\":\"10.385\",\"a\":\"79607.20\",\"A\":\"1.136\",\"T\":1788563191220,\"E\":1788563191220,\"st\":1}}"}
{"receive_ns":1788563191190425000,"stream":"btcusdt@bookTicker","event_type":"bookTicker","event_time_ms":1788563191224,"raw_json":"{\"stream\":\"btcusdt@bookTicker\",\"data\":{\"e\":\"bookTicker\",\"u\":11478222356205,\"s\":\"BTCUSDT\",\"ps\":\"BTCUSDT\",\"b\":\"79607.10\",\"B\":\"10.195\",\"a\":\"79607.20\",\"A\":\"1.136\",\"T\":1788563191224,\"E\":1788563191224,\"st\":1}}"}
{"receive_ns":1788563191194110000,"stream":"btcusdt@bookTicker","event_type":"bookTicker","event_time_ms":1788563191228,"raw_json":"{\"stream\":\"btcusdt@bookTicker\",\"data\":{\"e\":\"bookTicker\",\"u\":11478222357072,\"s\":\"BTCUSDT\",\"ps\":\"BTCUSDT\",\"b\":\"79607.10\",\"B\":\"10.478\",\"a\":\"79607.20\",\"A\":\"1.136\",\"T\":1788563191227,\"E\":1788563191228,\"st\":1}}"}
{"receive_ns":1788563191287539000,"stream":"btcusdt@depth@100ms","event_type":"depthUpdate","event_time_ms":1788563191321,"raw_json":"{\"stream\":\"btcusdt@depth@100ms\",\"data\":{\"e\":\"depthUpdate\",\"E\":1788563191321,\"T\":1788563191318,\"s\":\"BTCUSDT\",\"ps\":\"BTCUSDT\",\"U\":11478222355860,\"u\":11478222363491,\"pu\":11478222355830,\"b\":[[\"1000.00\",\"24.604\"],[\"29307.10\",\"1.400\"],[\"29407.10\",\"0.700\"],[\"71646.30\",\"0.002\"],[\"75622.30\",\"0.000\"],[\"76422.80\",\"0.000\"],[\"78612.00\",\"1.260\"],[\"78811.00\",\"2.225\"],[\"79209.10\",\"0.277\"],[\"79211.10\",\"0.000\"],[\"79236.90\",\"0.247\"],[\"79434.00\",\"0.929\"],[\"79479.50\",\"0.598\"],[\"79487.70\",\"1.080\"],[\"79534.50\",\"0.000\"],[\"79583.70\",\"0.340\"],[\"79585.50\",\"0.044\"],[\"79593.20\",\"0.236\"],[\"79594.30\",\"0.162\"],[\"79602.40\",\"0.059\"],[\"79603.00\",\"0.001\"],[\"79607.10\",\"10.478\"]],\"a\":[[\"79608.80\",\"0.001\"],[\"79609.20\",\"0.592\"],[\"79609.50\",\"0.031\"],[\"79611.20\",\"0.199\"],[\"79622.50\",\"0.000\"],[\"79623.70\",\"0.376\"],[\"79624.80\",\"0.573\"],[\"79707.70\",\"0.010\"],[\"79728.60\",\"0.340\"],[\"79973.40\",\"1.913\"],[\"80403.30\",\"7.055\"],[\"83577.10\",\"0.026\"]],\"st\":1}}"}
{"receive_ns":1788563191301685000,"stream":"btcusdt@bookTicker","event_type":"bookTicker","event_time_ms":1788563191336,"raw_json":"{\"stream\":\"btcusdt@bookTicker\",\"data\":{\"e\":\"bookTicker\",\"u\":11478222364690,\"s\":\"BTCUSDT\",\"ps\":\"BTCUSDT\",\"b\":\"79607.10\",\"B\":\"10.478\",\"a\":\"79607.20\",\"A\":\"1.132\",\"T\":1788563191336,\"E\":1788563191336,\"st\":1}}"}
{"receive_ns":1788563191332476000,"stream":"btcusdt@bookTicker","event_type":"bookTicker","event_time_ms":1788563191366,"raw_json":"{\"stream\":\"btcusdt@bookTicker\",\"data\":{\"e\":\"bookTicker\",\"u\":11478222365909,\"s\":\"BTCUSDT\",\"ps\":\"BTCUSDT\",\"b\":\"79607.10\",\"B\":\"10.294\",\"a\":\"79607.20\",\"A\":\"1.132\",\"T\":1788563191365,\"E\":1788563191366,\"st\":1}}"}
{"receive_ns":1788563191334145000,"stream":"btcusdt@bookTicker","event_type":"bookTicker","event_time_ms":1788563191368,"raw_json":"{\"stream\":\"btcusdt@bookTicker\",\"data\":{\"e\":\"bookTicker\",\"u\":11478222366016,\"s\":\"BTCUSDT\",\"ps\":\"BTCUSDT\",\"b\":\"79607.10\",\"B\":\"10.479\",\"a\":\"79607.20\",\"A\":\"1.132\",\"T\":1788563191368,\"E\":1788563191368,\"st\":1}}"}
{"receive_ns":1788563191388589000,"stream":"btcusdt@depth@100ms","event_type":"depthUpdate","event_time_ms":1788563191423,"raw_json":"{\"stream\":\"btcusdt@depth@100ms\",\"data\":{\"e\":\"depthUpdate\",\"E\":1788563191423,\"T\":1788563191422,\"s\":\"BTCUSDT\",\"ps\":\"BTCUSDT\",\"U\":11478222363605,\"u\":11478222369068,\"pu\":11478222363491,\"b\":[[\"1000.00\",\"24.604\"],[\"29307.10\",\"1.582\"],[\"29407.10\",\"0.518\"],[\"63686.00\",\"0.002\"],[\"71646.30\",\"0.002\"],[\"76422.80\",\"0.002\"],[\"78755.30\",\"0.760\"],[\"78811.00\",\"2.225\"],[\"79209.10\",\"0.277\"],[\"79434.00\",\"0.929\"],[\"79440.00\",\"1.425\"],[\"79453.90\",\"1.208\"],[\"79479.50\",\"0.000\"],[\"79487.70\",\"0.076\"],[\"79599.70\",\"0.002\"],[\"79607.10\",\"10.479\"]],\"a\":[[\"79607.20\",\"1.132\"],[\"79611.20\",\"0.618\"],[\"79728.60\",\"0.000\"],[\"79768.00\",\"0.064\"],[\"79973.40\",\"1.494\"],[\"80005.30\",\"0.002\"],[\"80403.30\",\"7.055\"],[\"87568.00\",\"0.000\"]],\"st\":1}}"}
{"receive_ns":1788563191411329000,"stream":"btcusdt@bookTicker","event_type":"bookTicker","event_time_ms":1788563191446,"raw_json":"{\"stream\":\"btcusdt@bookTicker\",\"data\":{\"e\":\"bookTicker\",\"u\":11478222370271,\"s\":\"BTCUSDT\",\"ps\":\"BTCUSDT\",\"b\":\"79607.10\",\"B\":\"10.478\",\"a\":\"79607.20\",\"A\":\"1.132\",\"T\":1788563191446,\"E\":1788563191446,\"st\":1}}"}
{"receive_ns":1788563191411706000,"stream":"btcusdt@trade","event_type":"trade","event_time_ms":1788563191446,"raw_json":"{\"stream\":\"btcusdt@trade\",\"data\":{\"e\":\"trade\",\"E\":1788563191446,\"T\":1788563191446,\"s\":\"BTCUSDT\",\"t\":8054082661,\"p\":\"79607.10\",\"q\":\"0.001\",\"X\":\"MARKET\",\"m\":true,\"st\":1}}"}
{"receive_ns":1788563191411965000,"stream":"btcusdt@bookTicker","event_type":"bookTicker","event_time_ms":1788563191447,"raw_json":"{\"stream\":\"btcusdt@bookTicker\",\"data\":{\"e\":\"bookTicker\",\"u\":11478222370386,\"s\":\"BTCUSDT\",\"ps\":\"BTCUSDT\",\"b\":\"79607.10\",\"B\":\"10.486\",\"a\":\"79607.20\",\"A\":\"1.132\",\"T\":1788563191447,\"E\":1788563191447,\"st\":1}}"}
{"receive_ns":1788563191412163000,"stream":"btcusdt@bookTicker","event_type":"bookTicker","event_time_ms":1788563191447,"raw_json":"{\"stream\":\"btcusdt@bookTicker\",\"data\":{\"e\":\"bookTicker\",\"u\":11478222370416,\"s\":\"BTCUSDT\",\"ps\":\"BTCUSDT\",\"b\":\"79607.10\",\"B\":\"10.505\",\"a\":\"79607.20\",\"A\":\"1.132\",\"T\":1788563191447,\"E\":1788563191447,\"st\":1}}"}
{"receive_ns":1788563191412523000,"stream":"btcusdt@bookTicker","event_type":"bookTicker","event_time_ms":1788563191448,"raw_json":"{\"stream\":\"btcusdt@bookTicker\",\"data\":{\"e\":\"bookTicker\",\"u\":11478222370463,\"s\":\"BTCUSDT\",\"ps\":\"BTCUSDT\",\"b\":\"79607.10\",\"B\":\"10.497\",\"a\":\"79607.20\",\"A\":\"1.132\",\"T\":1788563191448,\"E\":1788563191448,\"st\":1}}"}
{"receive_ns":1788563191413457000,"stream":"btcusdt@bookTicker","event_type":"bookTicker","event_time_ms":1788563191449,"raw_json":"{\"stream\":\"btcusdt@bookTicker\",\"data\":{\"e\":\"bookTicker\",\"u\":11478222370490,\"s\":\"BTCUSDT\",\"ps\":\"BTCUSDT\",\"b\":\"79607.10\",\"B\":\"10.478\",\"a\":\"79607.20\",\"A\":\"1.132\",\"T\":1788563191448,\"E\":1788563191449,\"st\":1}}"}
{"receive_ns":1788563191413733000,"stream":"btcusdt@bookTicker","event_type":"bookTicker","event_time_ms":1788563191449,"raw_json":"{\"stream\":\"btcusdt@bookTicker\",\"data\":{\"e\":\"bookTicker\",\"u\":11478222370526,\"s\":\"BTCUSDT\",\"ps\":\"BTCUSDT\",\"b\":\"79607.10\",\"B\":\"10.476\",\"a\":\"79607.20\",\"A\":\"1.132\",\"T\":1788563191449,\"E\":1788563191449,\"st\":1}}"}
{"receive_ns":1788563191443109000,"stream":"btcusdt@bookTicker","event_type":"bookTicker","event_time_ms":1788563191477,"raw_json":"{\"stream\":\"btcusdt@bookTicker\",\"data\":{\"e\":\"bookTicker\",\"u\":11478222371594,\"s\":\"BTCUSDT\",\"ps\":\"BTCUSDT\",\"b\":\"79607.10\",\"B\":\"10.199\",\"a\":\"79607.20\",\"A\":\"1.132\",\"T\":1788563191477,\"E\":1788563191477,\"st\":1}}"}
{"receive_ns":1788563191445384000,"stream":"btcusdt@bookTicker","event_type":"bookTicker","event_time_ms":1788563191480,"raw_json":"{\"stream\":\"btcusdt@bookTicker\",\"data\":{\"e\":\"bookTicker\",\"u\":11478222371817,\"s\":\"BTCUSDT\",\"ps\":\"BTCUSDT\",\"b\":\"79607.10\",\"B\":\"10.482\",\"a\":\"79607.20\",\"A\":\"1.132\",\"T\":1788563191479,\"E\":1788563191480,\"st\":1}}"}
{"receive_ns":1788563191445590000,"stream":"btcusdt@bookTicker","event_type":"bookTicker","event_time_ms":1788563191480,"raw_json":"{\"stream\":\"btcusdt@bookTicker\",\"data\":{\"e\":\"bookTicker\",\"u\":11478222371835,\"s\":\"BTCUSDT\",\"ps\":\"BTCUSDT\",\"b\":\"79607.10\",\"B\":\"10.479\",\"a\":\"79607.20\",\"A\":\"1.132\",\"T\":1788563191480,\"E\":1788563191480,\"st\":1}}"}
{"receive_ns":1788563191446085000,"stream":"btcusdt@bookTicker","event_type":"bookTicker","event_time_ms":1788563191481,"raw_json":"{\"stream\":\"btcusdt@bookTicker\",\"data\":{\"e\":\"bookTicker\",\"u\":11478222371904,\"s\":\"BTCUSDT\",\"ps\":\"BTCUSDT\",\"b\":\"79607.10\",\"B\":\"10.481\",\"a\":\"79607.20\",\"A\":\"1.132\",\"T\":1788563191481,\"E\":1788563191481,\"st\":1}}"}
{"receive_ns":1788563191459053000,"stream":"btcusdt@bookTicker","event_type":"bookTicker","event_time_ms":1788563191495,"raw_json":"{\"stream\":\"btcusdt@bookTicker\",\"data\":{\"e\":\"bookTicker\",\"u\":11478222372575,\"s\":\"BTCUSDT\",\"ps\":\"BTCUSDT\",\"b\":\"79607.10\",\"B\":\"10.500\",\"a\":\"79607.20\",\"A\":\"1.132\",\"T\":1788563191494,\"E\":1788563191495,\"st\":1}}"}
{"receive_ns":1788563191459971000,"stream":"btcusdt@bookTicker","event_type":"bookTicker","event_time_ms":1788563191495,"raw_json":"{\"stream\":\"btcusdt@bookTicker\",\"data\":{\"e\":\"bookTicker\",\"u\":11478222372602,\"s\":\"BTCUSDT\",\"ps\":\"BTCUSDT\",\"b\":\"79607.10\",\"B\":\"10.481\",\"a\":\"79607.20\",\"A\":\"1.132\",\"T\":1788563191495,\"E\":1788563191495,\"st\":1}}"}
{"receive_ns":1788563191460224000,"stream":"btcusdt@bookTicker","event_type":"bookTicker","event_time_ms":1788563191496,"raw_json":"{\"stream\":\"btcusdt@bookTicker\",\"data\":{\"e\":\"bookTicker\",\"u\":11478222372647,\"s\":\"BTCUSDT\",\"ps\":\"BTCUSDT\",\"b\":\"79607.10\",\"B\":\"10.500\",\"a\":\"79607.20\",\"A\":\"1.132\",\"T\":1788563191496,\"E\":1788563191496,\"st\":1}}"}
{"receive_ns":1788563191461106000,"stream":"btcusdt@bookTicker","event_type":"bookTicker","event_time_ms":1788563191497,"raw_json":"{\"stream\":\"btcusdt@bookTicker\",\"data\":{\"e\":\"bookTicker\",\"u\":11478222372693,\"s\":\"BTCUSDT\",\"ps\":\"BTCUSDT\",\"b\":\"79607.10\",\"B\":\"10.481\",\"a\":\"79607.20\",\"A\":\"1.132\",\"T\":1788563191496,\"E\":1788563191497,\"st\":1}}"}
{"receive_ns":1788563191467740000,"stream":"btcusdt@bookTicker","event_type":"bookTicker","event_time_ms":1788563191503,"raw_json":"{\"stream\":\"btcusdt@bookTicker\",\"data\":{\"e\":\"bookTicker\",\"u\":11478222373137,\"s\":\"BTCUSDT\",\"ps\":\"BTCUSDT\",\"b\":\"79607.10\",\"B\":\"10.481\",\"a\":\"79607.20\",\"A\":\"1.139\",\"T\":1788563191503,\"E\":1788563191503,\"st\":1}}"}
{"receive_ns":1788563191482205000,"stream":"btcusdt@bookTicker","event_type":"bookTicker","event_time_ms":1788563191516,"raw_json":"{\"stream\":\"btcusdt@bookTicker\",\"data\":{\"e\":\"bookTicker\",\"u\":11478222373929,\"s\":\"BTCUSDT\",\"ps\":\"BTCUSDT\",\"b\":\"79607.10\",\"B\":\"10.500\",\"a\":\"79607.20\",\"A\":\"1.139\",\"T\":1788563191516,\"E\":1788563191516,\"st\":1}}"}
{"receive_ns":1788563191482415000,"stream":"btcusdt@bookTicker","event_type":"bookTicker","event_time_ms":1788563191516,"raw_json":"{\"stream\":\"btcusdt@bookTicker\",\"data\":{\"e\":\"bookTicker\",\"u\":11478222373982,\"s\":\"BTCUSDT\",\"ps\":\"BTCUSDT\",\"b\":\"79607.10\",\"B\":\"10.508\",\"a\":\"79607.20\",\"A\":\"1.139\",\"T\":1788563191516,\"E\":1788563191516,\"st\":1}}"}
{"receive_ns":1788563191489739000,"stream":"btcusdt@bookTicker","event_type":"bookTicker","event_time_ms":1788563191517,"raw_json":"{\"stream\":\"btcusdt@bookTicker\",\"data\":{\"e\":\"bookTicker\",\"u\":11478222374019,\"s\":\"BTCUSDT\",\"ps\":\"BTCUSDT\",\"b\":\"79607.10\",\"B\":\"10.489\",\"a\":\"79607.20\",\"A\":\"1.139\",\"T\":1788563191516,\"E\":1788563191517,\"st\":1}}"}
{"receive_ns":1788563191490134000,"stream":"btcusdt@bookTicker","event_type":"bookTicker","event_time_ms":1788563191517,"raw_json":"{\"stream\":\"btcusdt@bookTicker\",\"data\":{\"e\":\"bookTicker\",\"u\":11478222374029,\"s\":\"BTCUSDT\",\"ps\":\"BTCUSDT\",\"b\":\"79607.10\",\"B\":\"10.481\",\"a\":\"79607.20\",\"A\":\"1.139\",\"T\":1788563191517,\"E\":1788563191517,\"st\":1}}"}
{"receive_ns":1788563191498603000,"stream":"btcusdt@depth@100ms","event_type":"depthUpdate","event_time_ms":1788563191525,"raw_json":"{\"stream\":\"btcusdt@depth@100ms\",\"data\":{\"e\":\"depthUpdate\",\"E\":1788563191525,\"T\":1788563191521,\"s\":\"BTCUSDT\",\"ps\":\"BTCUSDT\",\"U\":11478222369150,\"u\":11478222374268,\"pu\":11478222369068,\"b\":[[\"29307.10\",\"1.757\"],[\"29407.10\",\"0.343\"],[\"71646.30\",\"0.002\"],[\"78015.00\",\"0.143\"],[\"78404.10\",\"8.771\"],[\"78811.00\",\"2.225\"],[\"79209.00\",\"0.001\"],[\"79209.10\",\"0.403\"],[\"79236.90\",\"0.247\"],[\"79392.20\",\"0.974\"],[\"79434.00\",\"2.133\"],[\"79443.60\",\"0.613\"],[\"79487.70\",\"0.076\"],[\"79491.70\",\"0.000\"],[\"79602.40\",\"0.059\"],[\"79603.00\",\"0.001\"],[\"79607.10\",\"10.481\"]],\"a\":[[\"79607.20\",\"1.139\"],[\"79608.50\",\"0.026\"],[\"79608.70\",\"0.026\"],[\"79609.20\",\"0.791\"],[\"79611.20\",\"0.419\"],[\"79812.00\",\"0.607\"],[\"79815.80\",\"0.000\"],[\"79973.40\",\"1.494\"],[\"80403.30\",\"7.055\"],[\"80593.20\",\"4.036\"],[\"81268.80\",\"0.000\"]],\"st\":1}}"}
{"receive_ns":1788563191504077000,"stream":"btcusdt@bookTicker","event_type":"bookTicker","event_time_ms":1788563191539,"raw_json":"{\"stream\":\"btcusdt@bookTicker\",\"data\":{\"e\":\"bookTicker\",\"u\":11478222374971,\"s\":\"BTCUSDT\",\"ps\":\"BTCUSDT\",\"b\":\"79607.10\",\"B\":\"10.500\",\"a\":\"79607.20\",\"A\":\"1.139\",\"T\":1788563191539,\"E\":1788563191539,\"st\":1}}"}
{"receive_ns":1788563191504317000,"stream":"btcusdt@bookTicker","event_type":"bookTicker","event_time_ms":1788563191540,"raw_json":"{\"stream\":\"btcusdt@bookTicker\",\"data\":{\"e\":\"bookTicker\",\"u\":11478222375013,\"s\":\"BTCUSDT\",\"ps\":\"BTCUSDT\",\"b\":\"79607.10\",\"B\":\"10.481\",\"a\":\"79607.20\",\"A\":\"1.139\",\"T\":1788563191540,\"E\":1788563191540,\"st\":1}}"}
{"receive_ns":1788563191509503000,"stream":"btcusdt@bookTicker","event_type":"bookTicker","event_time_ms":1788563191544,"raw_json":"{\"stream\":\"btcusdt@bookTicker\",\"data\":{\"e\":\"bookTicker\",\"u\":11478222375192,\"s\":\"BTCUSDT\",\"ps\":\"BTCUSDT\",\"b\":\"79607.10\",\"B\":\"10.500\",\"a\":\"79607.20\",\"A\":\"1.139\",\"T\":1788563191543,\"E\":1788563191544,\"st\":1}}"}
{"receive_ns":1788563191509691000,"stream":"btcusdt@bookTicker","event_type":"bookTicker","event_time_ms":1788563191544,"raw_json":"{\"stream\":\"btcusdt@bookTicker\",\"data\":{\"e\":\"bookTicker\",\"u\":11478222375194,\"s\":\"BTCUSDT\",\"ps\":\"BTCUSDT\",\"b\":\"79607.10\",\"B\":\"10.508\",\"a\":\"79607.20\",\"A\":\"1.139\",\"T\":1788563191543,\"E\":1788563191544,\"st\":1}}"}
{"receive_ns":1788563191509903000,"stream":"btcusdt@bookTicker","event_type":"bookTicker","event_time_ms":1788563191544,"raw_json":"{\"stream\":\"btcusdt@bookTicker\",\"data\":{\"e\":\"bookTicker\",\"u\":11478222375254,\"s\":\"BTCUSDT\",\"ps\":\"BTCUSDT\",\"b\":\"79607.10\",\"B\":\"10.500\",\"a\":\"79607.20\",\"A\":\"1.139\",\"T\":1788563191544,\"E\":1788563191544,\"st\":1}}"}
{"receive_ns":1788563191510062000,"stream":"btcusdt@bookTicker","event_type":"bookTicker","event_time_ms":1788563191544,"raw_json":"{\"stream\":\"btcusdt@bookTicker\",\"data\":{\"e\":\"bookTicker\",\"u\":11478222375255,\"s\":\"BTCUSDT\",\"ps\":\"BTCUSDT\",\"b\":\"79607.10\",\"B\":\"10.481\",\"a\":\"79607.20\",\"A\":\"1.139\",\"T\":1788563191544,\"E\":1788563191544,\"st\":1}}"}
{"receive_ns":1788563191552198000,"stream":"btcusdt@bookTicker","event_type":"bookTicker","event_time_ms":1788563191588,"raw_json":"{\"stream\":\"btcusdt@bookTicker\",\"data\":{\"e\":\"bookTicker\",\"u\":11478222377037,\"s\":\"BTCUSDT\",\"ps\":\"BTCUSDT\",\"b\":\"79607.10\",\"B\":\"10.500\",\"a\":\"79607.20\",\"A\":\"1.139\",\"T\":1788563191588,\"E\":1788563191588,\"st\":1}}"}
{"receive_ns":1788563191552473000,"stream":"btcusdt@bookTicker","event_type":"bookTicker","event_time_ms":1788563191589,"raw_json":"{\"stream\":\"btcusdt@bookTicker\",\"data\":{\"e\":\"bookTicker\",\"u\":11478222377060,\"s\":\"BTCUSDT\",\"ps\":\"BTCUSDT\",\"b\":\"79607.10\",\"B\":\"10.481\",\"a\":\"79607.20\",\"A\":\"1.139\",\"T\":1788563191589,\"E\":1788563191589,\"st\":1}}"}
{"receive_ns":1788563191590073000,"stream":"btcusdt@depth@100ms","event_type":"depthUpdate","event_time_ms":1788563191627,"raw_json":"{\"stream\":\"btcusdt@depth@100ms\",\"data\":{\"e\":\"depthUpdate\",\"E\":1788563191627,\"T\":1788563191625,\"s\":\"BTCUSDT\",\"ps\":\"BTCUSDT\",\"U\":11478222374406,\"u\":11478222379516,\"pu\":11478222374268,\"b\":[[\"1000.00\",\"24.604\"],[\"29207.10\",\"0.063\"],[\"29307.10\",\"1.813\"],[\"29407.10\",\"0.224\"],[\"63686.00\",\"0.002\"],[\"71646.30\",\"0.002\"],[\"76422.80\",\"0.000\"],[\"78811.00\",\"2.225\"],[\"79392.30\",\"28.234\"],[\"79434.00\",\"1.631\"],[\"79440.10\",\"3.162\"],[\"79453.90\",\"0.204\"],[\"79479.50\",\"0.598\"],[\"79607.10\",\"10.481\"]],\"a\":[[\"79608.10\",\"0.027\"],[\"79608.30\",\"0.028\"],[\"79608.50\",\"0.000\"],[\"79608.70\",\"0.000\"],[\"79611.20\",\"0.000\"],[\"79623.70\",\"0.004\"],[\"79624.80\",\"0.945\"],[\"79661.50\",\"0.006\"],[\"79670.90\",\"0.000\"],[\"79728.60\",\"0.340\"],[\"79768.00\",\"1.965\"],[\"79815.80\",\"3.245\"],[\"79973.40\",\"0.969\"],[\"80403.30\",\"7.055\"],[\"80602.30\",\"2.315\"],[\"80737.60\",\"0.888\"],[\"80880.90\",\"0.443\"],[\"81517.80\",\"0.429\"]],\"st\":1}}"}
{"receive_ns":1788563191695578000,"stream":"btcusdt@depth@100ms","event_type":"depthUpdate","event_time_ms":1788563191729,"raw_json":"{\"stream\":\"btcusdt@depth@100ms\",\"data\":{\"e\":\"depthUpdate\",\"E\":1788563191729,\"T\":1788563191725,\"s\":\"BTCUSDT\",\"ps\":\"BTCUSDT\",\"U\":11478222379593,\"u\":11478222384603,\"pu\":11478222379516,\"b\":[[\"1000.00\",\"24.604\"],[\"29207.10\",\"0.119\"],[\"29307.10\",\"1.876\"],[\"29407.10\",\"0.105\"],[\"63686.00\",\"0.002\"],[\"71646.30\",\"0.002\"],[\"76422.80\",\"0.002\"],[\"77616.90\",\"0.966\"],[\"78811.00\",\"2.225\"],[\"79209.10\",\"0.403\"],[\"79434.00\",\"0.929\"],[\"79479.30\",\"0.061\"],[\"79487.70\",\"2.284\"],[\"79583.40\",\"1.875\"]],\"a\":[[\"79608.10\",\"0.001\"],[\"79608.30\",\"0.002\"],[\"79609.20\",\"0.592\"],[\"79611.20\",\"0.199\"],[\"79623.30\",\"0.045\"],[\"79665.00\",\"0.003\"],[\"79973.40\",\"1.913\"],[\"80403.30\",\"7.055\"],[\"80593.20\",\"3.825\"],[\"80653.10\",\"0.000\"],[\"80672.80\",\"11.566\"]],\"st\":1}}"}
{"receive_ns":1788563191795782000,"stream":"btcusdt@depth@100ms","event_type":"depthUpdate","event_time_ms":1788563191831,"raw_json":"{\"stream\":\"btcusdt@depth@100ms\",\"data\":{\"e\":\"depthUpdate\",\"E\":1788563191831,\"T\":1788563191830,\"s\":\"BTCUSDT\",\"ps\":\"BTCUSDT\",\"U\":11478222384740,\"u\":11478222390303,\"pu\":11478222384603,\"b\":[[\"29207.10\",\"0.203\"],[\"29307.10\",\"1.890\"],[\"29407.10\",\"0.007\"],[\"71646.30\",\"0.002\"],[\"76422.80\",\"0.000\"],[\"78532.40\",\"0.382\"],[\"78811.00\",\"2.225\"],[\"79209.10\",\"0.403\"],[\"79236.90\",\"0.247\"],[\"79434.00\",\"0.929\"],[\"79440.10\",\"0.499\"],[\"79479.50\",\"0.000\"],[\"79487.70\",\"2.209\"],[\"79491.70\",\"0.075\"]],\"a\":[[\"79609.20\",\"0.502\"],[\"79611.20\",\"0.289\"],[\"79625.90\",\"0.453\"],[\"79627.10\",\"0.001\"],[\"79728.60\",\"0.000\"],[\"79768.00\",\"0.064\"],[\"79973.40\",\"1.913\"],[\"80403.30\",\"7.055\"]],\"st\":1}}"}
{"receive_ns":1788563191877691000,"stream":"btcusdt@bookTicker","event_type":"bookTicker","event_time_ms":1788563191912,"raw_json":"{\"stream\":\"btcusdt@bookTicker\",\"data\":{\"e\":\"bookTicker\",\"u\":11478222394116,\"s\":\"BTCUSDT\",\"ps\":\"BTCUSDT\",\"b\":\"79607.10\",\"B\":\"10.481\",\"a\":\"79607.20\",\"A\":\"1.144\",\"T\":1788563191912,\"E\":1788563191912,\"st\":1}}"}
{"receive_ns":1788563191898972000,"stream":"btcusdt@depth@100ms","event_type":"depthUpdate","event_time_ms":1788563191933,"raw_json":"{\"stream\":\"btcusdt@depth@100ms\",\"data\":{\"e\":\"depthUpdate\",\"E\":1788563191933,\"T\":1788563191930,\"s\":\"BTCUSDT\",\"ps\":\"BTCUSDT\",\"U\":11478222390418,\"u\":11478222395040,\"pu\":11478222390303,\"b\":[[\"1000.00\",\"24.604\"],[\"29207.10\",\"0.371\"],[\"29307.10\",\"1.729\"],[\"29407.10\",\"0.000\"],[\"63685.70\",\"0.001\"],[\"71646.30\",\"0.002\"],[\"75626.70\",\"0.018\"],[\"76422.80\",\"0.002\"],[\"78806.30\",\"3.739\"],[\"78811.00\",\"2.225\"],[\"79392.30\",\"22.784\"],[\"79434.00\",\"1.933\"],[\"79487.70\",\"0.001\"],[\"79535.40\",\"0.002\"],[\"79587.10\",\"0.015\"]],\"a\":[[\"79607.20\",\"1.144\"],[\"79611.20\",\"0.090\"],[\"79642.40\",\"3.021\"],[\"79644.00\",\"0.024\"],[\"79663.00\",\"0.002\"],[\"79713.80\",\"0.074\"],[\"79815.80\",\"0.000\"],[\"79973.40\",\"1.150\"]],\"st\":1}}"}
{"receive_ns":1788563191998861000,"stream":"btcusdt@depth@100ms","event_type":"depthUpdate","event_time_ms":1788563192035,"raw_json":"{\"stream\":\"btcusdt@depth@100ms\",\"data\":{\"e\":\"depthUpdate\",\"E\":1788563192035,\"T\":1788563192033,\"s\":\"BTCUSDT\",\"ps\":\"BTCUSDT\",\"U\":11478222395169,\"u\":11478222401751,\"pu\":11478222395040,\"b\":[[\"29207.10\",\"0.553\"],[\"29307.10\",\"1.547\"],[\"63686.00\",\"0.002\"],[\"71646.30\",\"0.002\"],[\"71680.00\",\"0.127\"],[\"78015.00\",\"0.140\"],[\"78237.90\",\"0.510\"],[\"78572.10\",\"0.334\"],[\"78811.00\",\"2.225\"],[\"79209.10\",\"0.403\"],[\"79236.90\",\"0.247\"],[\"79392.30\",\"28.212\"],[\"79434.00\",\"1.933\"],[\"79440.10\",\"3.154\"],[\"79479.50\",\"0.598\"],[\"79487.70\",\"1.205\"],[\"79491.70\",\"0.075\"],[\"79548.20\",\"0.001\"],[\"79562.90\",\"0.070\"],[\"79590.50\",\"0.006\"],[\"79596.00\",\"0.681\"]],\"a\":[[\"79608.90\",\"0.000\"],[\"79609.10\",\"0.000\"],[\"79609.20\",\"0.502\"],[\"79610.60\",\"0.371\"],[\"79611.10\",\"0.027\"],[\"79611.20\",\"0.289\"],[\"79647.70\",\"0.204\"],[\"79713.80\",\"0.000\"],[\"79728.60\",\"0.340\"],[\"79768.00\",\"1.954\"],[\"79815.80\",\"3.214\"],[\"79973.40\",\"1.913\"],[\"80403.30\",\"7.055\"],[\"80562.50\",\"8.434\"]],\"st\":1}}"}
{"receive_ns":1788563192006937000,"stream":"btcusdt@bookTicker","event_type":"bookTicker","event_time_ms":1788563192042,"raw_json":"{\"stream\":\"btcusdt@bookTicker\",\"data\":{\"e\":\"bookTicker\",\"u\":11478222402264,\"s\":\"BTCUSDT\",\"ps\":\"BTCUSDT\",\"b\":\"79607.10\",\"B\":\"10.486\",\"a\":\"79607.20\",\"A\":\"1.144\",\"T\":1788563192041,\"E\":1788563192042,\"st\":1}}"}
{"receive_ns":1788563192020001000,"stream":"btcusdt@bookTicker","event_type":"bookTicker","event_time_ms":1788563192054,"raw_json":"{\"stream\":\"btcusdt@bookTicker\",\"data\":{\"e\":\"bookTicker\",\"u\":11478222402841,\"s\":\"BTCUSDT\",\"ps\":\"BTCUSDT\",\"b\":\"79607.10\",\"B\":\"10.284\",\"a\":\"79607.20\",\"A\":\"1.144\",\"T\":1788563192054,\"E\":1788563192054,\"st\":1}}"}
{"receive_ns":1788563192025294000,"stream":"btcusdt@bookTicker","event_type":"bookTicker","event_time_ms":1788563192059,"raw_json":"{\"stream\":\"btcusdt@bookTicker\",\"data\":{\"e\":\"bookTicker\",\"u\":11478222403057,\"s\":\"BTCUSDT\",\"ps\":\"BTCUSDT\",\"b\":\"79607.10\",\"B\":\"10.487\",\"a\":\"79607.20\",\"A\":\"1.144\",\"T\":1788563192059,\"E\":1788563192059,\"st\":1}}"}
{"receive_ns":1788563192025545000,"stream":"btcusdt@bookTicker","event_type":"bookTicker","event_time_ms":1788563192060,"raw_json":"{\"stream\":\"btcusdt@bookTicker\",\"data\":{\"e\":\"bookTicker\",\"u\":11478222403150,\"s\":\"BTCUSDT\",\"ps\":\"BTCUSDT\",\"b\":\"79607.10\",\"B\":\"10.487\",\"a\":\"79607.20\",\"A\":\"1.143\",\"T\":1788563192060,\"E\":1788563192060,\"st\":1}}"}
{"receive_ns":1788563192043456000,"stream":"btcusdt@bookTicker","event_type":"bookTicker","event_time_ms":1788563192078,"raw_json":"{\"stream\":\"btcusdt@bookTicker\",\"data\":{\"e\":\"bookTicker\",\"u\":11478222404192,\"s\":\"BTCUSDT\",\"ps\":\"BTCUSDT\",\"b\":\"79607.10\",\"B\":\"10.484\",\"a\":\"79607.20\",\"A\":\"1.143\",\"T\":1788563192078,\"E\":1788563192078,\"st\":1}}"}
{"receive_ns":1788563192043687000,"stream":"btcusdt@trade","event_type":"trade","event_time_ms":1788563192078,"raw_json":"{\"stream\":\"btcusdt@trade\",\"data\":{\"e\":\"trade\",\"E\":1788563192078,\"T\":1788563192078,\"s\":\"BTCUSDT\",\"t\":8054082662,\"p\":\"79607.10\",\"q\":\"0.003\",\"X\":\"MARKET\",\"m\":true,\"st\":1}}"}
{"receive_ns":1788563192043900000,"stream":"btcusdt@bookTicker","event_type":"bookTicker","event_time_ms":1788563192079,"raw_json":"{\"stream\":\"btcusdt@bookTicker\",\"data\":{\"e\":\"bookTicker\",\"u\":11478222404302,\"s\":\"BTCUSDT\",\"ps\":\"BTCUSDT\",\"b\":\"79607.10\",\"B\":\"10.503\",\"a\":\"79607.20\",\"A\":\"1.143\",\"T\":1788563192079,\"E\":1788563192079,\"st\":1}}"}
{"receive_ns":1788563192044060000,"stream":"btcusdt@bookTicker","event_type":"bookTicker","event_time_ms":1788563192079,"raw_json":"{\"stream\":\"btcusdt@bookTicker\",\"data\":{\"e\":\"bookTicker\",\"u\":11478222404341,\"s\":\"BTCUSDT\",\"ps\":\"BTCUSDT\",\"b\":\"79607.10\",\"B\":\"10.511\",\"a\":\"79607.20\",\"A\":\"1.143\",\"T\":1788563192079,\"E\":1788563192079,\"st\":1}}"}
{"receive_ns":1788563192045086000,"stream":"btcusdt@bookTicker","event_type":"bookTicker","event_time_ms":1788563192080,"raw_json":"{\"stream\":\"btcusdt@bookTicker\",\"data\":{\"e\":\"bookTicker\",\"u\":11478222404427,\"s\":\"BTCUSDT\",\"ps\":\"BTCUSDT\",\"b\":\"79607.10\",\"B\":\"10.492\",\"a\":\"79607.20\",\"A\":\"1.143\",\"T\":1788563192080,\"E\":1788563192080,\"st\":1}}"}
{"receive_ns":1788563192045337000,"stream":"btcusdt@bookTicker","event_type":"bookTicker","event_time_ms":1788563192080,"raw_json":"{\"stream\":\"btcusdt@bookTicker\",\"data\":{\"e\":\"bookTicker\",\"u\":11478222404474,\"s\":\"BTCUSDT\",\"ps\":\"BTCUSDT\",\"b\":\"79607.10\",\"B\":\"10.484\",\"a\":\"79607.20\",\"A\":\"1.143\",\"T\":1788563192080,\"E\":1788563192080,\"st\":1}}"}
{"receive_ns":1788563192045520000,"stream":"btcusdt@bookTicker","event_type":"bookTicker","event_time_ms":1788563192080,"raw_json":"{\"stream\":\"btcusdt@bookTicker\",\"data\":{\"e\":\"bookTicker\",\"u\":11478222404509,\"s\":\"BTCUSDT\",\"ps\":\"BTCUSDT\",\"b\":\"79607.10\",\"B\":\"10.484\",\"a\":\"79607.20\",\"A\":\"1.144\",\"T\":1788563192080,\"E\":1788563192080,\"st\":1}}"}
{"receive_ns":1788563192060916000,"stream":"btcusdt@bookTicker","event_type":"bookTicker","event_time_ms":1788563192096,"raw_json":"{\"stream\":\"btcusdt@bookTicker\",\"data\":{\"e\":\"bookTicker\",\"u\":11478222406334,\"s\":\"BTCUSDT\",\"ps\":\"BTCUSDT\",\"b\":\"79607.10\",\"B\":\"10.470\",\"a\":\"79607.20\",\"A\":\"1.144\",\"T\":1788563192096,\"E\":1788563192096,\"st\":1}}"}
{"receive_ns":1788563192070875000,"stream":"btcusdt@bookTicker","event_type":"bookTicker","event_time_ms":1788563192098,"raw_json":"{\"stream\":\"btcusdt@bookTicker\",\"data\":{\"e\":\"bookTicker\",\"u\":11478222406564,\"s\":\"BTCUSDT\",\"ps\":\"BTCUSDT\",\"b\":\"79607.10\",\"B\":\"10.483\",\"a\":\"79607.20\",\"A\":\"1.144\",\"T\":1788563192098,\"E\":1788563192098,\"st\":1}}"}
{"receive_ns":1788563192096911000,"stream":"btcusdt@bookTicker","event_type":"bookTicker","event_time_ms":1788563192132,"raw_json":"{\"stream\":\"btcusdt@bookTicker\",\"data\":{\"e\":\"bookTicker\",\"u\":11478222408464,\"s\":\"BTCUSDT\",\"ps\":\"BTCUSDT\",\"b\":\"79607.10\",\"B\":\"10.502\",\"a\":\"79607.20\",\"A\":\"1.144\",\"T\":1788563192132,\"E\":1788563192132,\"st\":1}}"}
{"receive_ns":1788563192097174000,"stream":"btcusdt@bookTicker","event_type":"bookTicker","event_time_ms":1788563192133,"raw_json":"{\"stream\":\"btcusdt@bookTicker\",\"data\":{\"e\":\"bookTicker\",\"u\":11478222408485,\"s\":\"BTCUSDT\",\"ps\":\"BTCUSDT\",\"b\":\"79607.10\",\"B\":\"10.483\",\"a\":\"79607.20\",\"A\":\"1.144\",\"T\":1788563192133,\"E\":1788563192133,\"st\":1}}"}
{"receive_ns":1788563192100404000,"stream":"btcusdt@depth@100ms","event_type":"depthUpdate","event_time_ms":1788563192137,"raw_json":"{\"stream\":\"btcusdt@depth@100ms\",\"data\":{\"e\":\"depthUpdate\",\"E\":1788563192137,\"T\":1788563192136,\"s\":\"BTCUSDT\",\"ps\":\"BTCUSDT\",\"U\":11478222401874,\"u\":11478222408762,\"pu\":11478222401751,\"b\":[[\"29207.10\",\"0.728\"],[\"29307.10\",\"1.372\"],[\"63686.00\",\"0.002\"],[\"71646.30\",\"0.002\"],[\"76422.80\",\"0.000\"],[\"78394.60\",\"0.021\"],[\"78474.30\",\"0.004\"],[\"78811.00\",\"2.225\"],[\"79209.00\",\"0.002\"],[\"79211.10\",\"0.086\"],[\"79434.00\",\"0.427\"],[\"79443.60\",\"0.915\"],[\"79477.90\",\"0.827\"],[\"79478.00\",\"0.004\"],[\"79479.40\",\"0.125\"],[\"79534.10\",\"4.462\"],[\"79538.90\",\"0.108\"],[\"79575.30\",\"0.453\"],[\"79576.20\",\"0.001\"],[\"79592.80\",\"0.003\"],[\"79603.00\",\"0.077\"],[\"79607.10\",\"10.483\"]],\"a\":[[\"79607.20\",\"1.144\"],[\"79609.30\",\"0.033\"],[\"79609.40\",\"0.004\"],[\"79609.50\",\"0.005\"],[\"79611.20\",\"0.315\"],[\"79611.30\",\"0.367\"],[\"79611.50\",\"0.596\"],[\"79677.30\",\"0.088\"],[\"79812.00\",\"1.009\"],[\"79836.10\",\"0.000\"],[\"79836.20\",\"0.007\"],[\"79973.40\",\"0.969\"],[\"80005.30\",\"0.001\"],[\"80239.20\",\"2.488\"],[\"80403.30\",\"7.055\"],[\"80482.90\",\"1.241\"],[\"80740.10\",\"0.000\"],[\"80819.60\",\"0.008\"],[\"80819.70\",\"0.006\"]],\"st\":1}}"}
{"receive_ns":1788563192149502000,"stream":"btcusdt@bookTicker","event_type":"bookTicker","event_time_ms":1788563192184,"raw_json":"{\"stream\":\"btcusdt@bookTicker\",\"data\":{\"e\":\"bookTicker\",\"u\":11478222411432,\"s\":\"BTCUSDT\",\"ps\":\"BTCUSDT\",\"b\":\"79607.10\",\"B\":\"10.502\",\"a\":\"79607.20\",\"A\":\"1.144\",\"T\":1788563192184,\"E\":1788563192184,\"st\":1}}"}
{"receive_ns":1788563192149764000,"stream":"btcusdt@bookTicker","event_type":"bookTicker","event_time_ms":1788563192184,"raw_json":"{\"stream\":\"btcusdt@bookTicker\",\"data\":{\"e\":\"bookTicker\",\"u\":11478222411458,\"s\":\"BTCUSDT\",\"ps\":\"BTCUSDT\",\"b\":\"79607.10\",\"B\":\"10.483\",\"a\":\"79607.20\",\"A\":\"1.144\",\"T\":1788563192184,\"E\":1788563192184,\"st\":1}}"}
{"receive_ns":1788563192197869000,"stream":"btcusdt@bookTicker","event_type":"bookTicker","event_time_ms":1788563192231,"raw_json":"{\"stream\":\"btcusdt@bookTicker\",\"data\":{\"e\":\"bookTicker\",\"u\":11478222414532,\"s\":\"BTCUSDT\",\"ps\":\"BTCUSDT\",\"b\":\"79607.10\",\"B\":\"10.200\",\"a\":\"79607.20\",\"A\":\"1.144\",\"T\":1788563192231,\"E\":1788563192231,\"st\":1}}"}
{"receive_ns":1788563192199800000,"stream":"btcusdt@bookTicker","event_type":"bookTicker","event_time_ms":1788563192234,"raw_json":"{\"stream\":\"btcusdt@bookTicker\",\"data\":{\"e\":\"bookTicker\",\"u\":11478222414725,\"s\":\"BTCUSDT\",\"ps\":\"BTCUSDT\",\"b\":\"79607.10\",\"B\":\"10.485\",\"a\":\"79607.20\",\"A\":\"1.144\",\"T\":1788563192234,\"E\":1788563192234,\"st\":1}}"}
{"receive_ns":1788563192203852000,"stream":"btcusdt@depth@100ms","event_type":"depthUpdate","event_time_ms":1788563192239,"raw_json":"{\"stream\":\"btcusdt@depth@100ms\",\"data\":{\"e\":\"depthUpdate\",\"E\":1788563192239,\"T\":1788563192238,\"s\":\"BTCUSDT\",\"ps\":\"BTCUSDT\",\"U\":11478222408820,\"u\":11478222414996,\"pu\":11478222408762,\"b\":[[\"1000.00\",\"24.604\"],[\"29207.10\",\"0.910\"],[\"29307.10\",\"1.190\"],[\"71646.30\",\"0.002\"],[\"75626.70\",\"0.023\"],[\"75626.80\",\"0.002\"],[\"76422.80\",\"0.002\"],[\"78394.60\",\"0.028\"],[\"78474.10\",\"0.007\"],[\"78552.60\",\"0.000\"],[\"78811.00\",\"2.225\"],[\"79209.10\",\"0.252\"],[\"79236.90\",\"0.015\"],[\"79434.00\",\"0.076\"],[\"79453.90\",\"0.706\"],[\"79479.40\",\"0.000\"],[\"79487.70\",\"1.205\"],[\"79491.70\",\"1.004\"],[\"79575.30\",\"0.001\"],[\"79576.20\",\"0.453\"],[\"79577.40\",\"0.000\"],[\"79602.90\",\"0.002\"],[\"79603.00\",\"0.076\"],[\"79607.10\",\"10.485\"]],\"a\":[[\"79609.20\",\"0.000\"],[\"79609.30\",\"0.059\"],[\"79609.50\",\"0.005\"],[\"79609.80\",\"0.026\"],[\"79610.00\",\"0.030\"],[\"79611.20\",\"0.225\"],[\"79611.50\",\"0.570\"],[\"79615.30\",\"0.692\"],[\"79625.90\",\"0.001\"],[\"79627.10\",\"0.453\"],[\"79688.40\",\"3.099\"],[\"79707.60\",\"8.784\"],[\"79973.40\",\"1.713\"],[\"80403.30\",\"7.055\"],[\"80602.80\",\"2.456\"],[\"80740.00\",\"5.070\"],[\"80819.60\",\"0.022\"],[\"81199.30\",\"0.012\"]],\"st\":1}}"}
{"receive_ns":1788563192262180000,"stream":"btcusdt@bookTicker","event_type":"bookTicker","event_time_ms":1788563192296,"raw_json":"{\"stream\":\"btcusdt@bookTicker\",\"data\":{\"e\":\"bookTicker\",\"u\":11478222419415,\"s\":\"BTCUSDT\",\"ps\":\"BTCUSDT\",\"b\":\"79607.10\",\"B\":\"10.484\",\"a\":\"79607.20\",\"A\":\"1.144\",\"T\":1788563192296,\"E\":1788563192296,\"st\":1}}"}
{"receive_ns":1788563192279355000,"stream":"btcusdt@bookTicker","event_type":"bookTicker","event_time_ms":1788563192314,"raw_json":"{\"stream\":\"btcusdt@bookTicker\",\"data\":{\"e\":\"bookTicker\",\"u\":11478222420686,\"s\":\"BTCUSDT\",\"ps\":\"BTCUSDT\",\"b\":\"79607.10\",\"B\":\"10.483\",\"a\":\"79607.20\",\"A\":\"1.144\",\"T\":1788563192314,\"E\":1788563192314,\"st\":1}}"}
{"receive_ns":1788563192279818000,"stream":"btcusdt@trade","event_type":"trade","event_time_ms":1788563192314,"raw_json":"{\"stream\":\"btcusdt@trade\",\"data\":{\"e\":\"trade\",\"E\":1788563192314,\"T\":1788563192314,\"s\":\"BTCUSDT\",\"t\":8054082663,\"p\":\"79607.10\",\"q\":\"0.001\",\"X\":\"MARKET\",\"m\":true,\"st\":1}}"}
{"receive_ns":1788563192280065000,"stream":"btcusdt@bookTicker","event_type":"bookTicker","event_time_ms":1788563192315,"raw_json":"{\"stream\":\"btcusdt@bookTicker\",\"data\":{\"e\":\"bookTicker\",\"u\":11478222420770,\"s\":\"BTCUSDT\",\"ps\":\"BTCUSDT\",\"b\":\"79607.10\",\"B\":\"10.502\",\"a\":\"79607.20\",\"A\":\"1.144\",\"T\":1788563192315,\"E\":1788563192315,\"st\":1}}"}
{"receive_ns":1788563192280234000,"stream":"btcusdt@bookTicker","event_type":"bookTicker","event_time_ms":1788563192315,"raw_json":"{\"stream\":\"btcusdt@bookTicker\",\"data\":{\"e\":\"bookTicker\",\"u\":11478222420826,\"s\":\"BTCUSDT\",\"ps\":\"BTCUSDT\",\"b\":\"79607.10\",\"B\":\"10.510\",\"a\":\"79607.20\",\"A\":\"1.144\",\"T\":1788563192315,\"E\":1788563192315,\"st\":1}}"}
{"receive_ns":1788563192281460000,"stream":"btcusdt@bookTicker","event_type":"bookTicker","event_time_ms":1788563192316,"raw_json":"{\"stream\":\"btcusdt@bookTicker\",\"data\":{\"e\":\"bookTicker\",\"u\":11478222420880,\"s\":\"BTCUSDT\",\"ps\":\"BTCUSDT\",\"b\":\"79607.10\",\"B\":\"10.491\",\"a\":\"79607.20\",\"A\":\"1.144\",\"T\":1788563192316,\"E\":1788563192316,\"st\":1}}"}
{"receive_ns":1788563192281678000,"stream":"btcusdt@bookTicker","event_type":"bookTicker","event_time_ms":1788563192316,"raw_json":"{\"stream\":\"btcusdt@bookTicker\",\"data\":{\"e\":\"bookTicker\",\"u\":11478222420887,\"s\":\"BTCUSDT\",\"ps\":\"BTCUSDT\",\"b\":\"79607.10\",\"B\":\"10.483\",\"a\":\"79607.20\",\"A\":\"1.144\",\"T\":1788563192316,\"E\":1788563192316,\"st\":1}}"}
{"receive_ns":1788563192290317000,"stream":"btcusdt@bookTicker","event_type":"bookTicker","event_time_ms":1788563192317,"raw_json":"{\"stream\":\"btcusdt@bookTicker\",\"data\":{\"e\":\"bookTicker\",\"u\":11478222420928,\"s\":\"BTCUSDT\",\"ps\":\"BTCUSDT\",\"b\":\"79607.10\",\"B\":\"10.481\",\"a\":\"79607.20\",\"A\":\"1.144\",\"T\":1788563192316,\"E\":1788563192317,\"st\":1}}"}
{"receive_ns":1788563192296994000,"stream":"btcusdt@bookTicker","event_type":"bookTicker","event_time_ms":1788563192333,"raw_json":"{\"stream\":\"btcusdt@bookTicker\",\"data\":{\"e\":\"bookTicker\",\"u\":11478222421881,\"s\":\"BTCUSDT\",\"ps\":\"BTCUSDT\",\"b\":\"79607.10\",\"B\":\"10.480\",\"a\":\"79607.20\",\"A\":\"1.144\",\"T\":1788563192332,\"E\":1788563192333,\"st\":1}}"}
{"receive_ns":1788563192297249000,"stream":"btcusdt@trade","event_type":"trade","event_time_ms":1788563192333,"raw_json":"{\"stream\":\"btcusdt@trade\",\"data\":{\"e\":\"trade\",\"E\":1788563192333,\"T\":1788563192332,\"s\":\"BTCUSDT\",\"t\":8054082664,\"p\":\"79607.10\",\"q\":\"0.001\",\"X\":\"MARKET\",\"m\":true,\"st\":1}}"}
{"receive_ns":1788563192298831000,"stream":"btcusdt@bookTicker","event_type":"bookTicker","event_time_ms":1788563192334,"raw_json":"{\"stream\":\"btcusdt@bookTicker\",\"data\":{\"e\":\"bookTicker\",\"u\":11478222421998,\"s\":\"BTCUSDT\",\"ps\":\"BTCUSDT\",\"b\":\"79607.10\",\"B\":\"10.499\",\"a\":\"79607.20\",\"A\":\"1.144\",\"T\":1788563192334,\"E\":1788563192334,\"st\":1}}"}
{"receive_ns":1788563192299011000,"stream":"btcusdt@bookTicker","event_type":"bookTicker","event_time_ms":1788563192334,"raw_json":"{\"stream\":\"btcusdt@bookTicker\",\"data\":{\"e\":\"bookTicker\",\"u\":11478222422006,\"s\":\"BTCUSDT\",\"ps\":\"BTCUSDT\",\"b\":\"79607.10\",\"B\":\"10.507\",\"a\":\"79607.20\",\"A\":\"1.144\",\"T\":1788563192334,\"E\":1788563192334,\"st\":1}}"}
{"receive_ns":1788563192299199000,"stream":"btcusdt@bookTicker","event_type":"bookTicker","event_time_ms":1788563192335,"raw_json":"{\"stream\":\"btcusdt@bookTicker\",\"data\":{\"e\":\"bookTicker\",\"u\":11478222422059,\"s\":\"BTCUSDT\",\"ps\":\"BTCUSDT\",\"b\":\"79607.10\",\"B\":\"10.499\",\"a\":\"79607.20\",\"A\":\"1.144\",\"T\":1788563192335,\"E\":1788563192335,\"st\":1}}"}
{"receive_ns":1788563192299351000,"stream":"btcusdt@bookTicker","event_type":"bookTicker","event_time_ms":1788563192335,"raw_json":"{\"stream\":\"btcusdt@bookTicker\",\"data\":{\"e\":\"bookTicker\",\"u\":11478222422065,\"s\":\"BTCUSDT\",\"ps\":\"BTCUSDT\",\"b\":\"79607.10\",\"B\":\"10.480\",\"a\":\"79607.20\",\"A\":\"1.144\",\"T\":1788563192335,\"E\":1788563192335,\"st\":1}}"}
{"receive_ns":1788563192299557000,"stream":"btcusdt@bookTicker","event_type":"bookTicker","event_time_ms":1788563192335,"raw_json":"{\"stream\":\"btcusdt@bookTicker\",\"data\":{\"e\":\"bookTicker\",\"u\":11478222422108,\"s\":\"BTCUSDT\",\"ps\":\"BTCUSDT\",\"b\":\"79607.10\",\"B\":\"10.482\",\"a\":\"79607.20\",\"A\":\"1.144\",\"T\":1788563192335,\"E\":1788563192335,\"st\":1}}"}
{"receive_ns":1788563192307519000,"stream":"btcusdt@depth@100ms","event_type":"depthUpdate","event_time_ms":1788563192341,"raw_json":"{\"stream\":\"btcusdt@depth@100ms\",\"data\":{\"e\":\"depthUpdate\",\"E\":1788563192341,\"T\":1788563192339,\"s\":\"BTCUSDT\",\"ps\":\"BTCUSDT\",\"U\":11478222415057,\"u\":11478222422285,\"pu\":11478222414996,\"b\":[[\"29207.10\",\"1.085\"],[\"29307.10\",\"1.015\"],[\"63686.00\",\"0.002\"],[\"71646.30\",\"0.002\"],[\"76422.80\",\"0.000\"],[\"78015.00\",\"0.143\"],[\"78118.40\",\"0.638\"],[\"78492.60\",\"0.508\"],[\"78811.00\",\"2.225\"],[\"79209.10\",\"0.393\"],[\"79211.10\",\"0.000\"],[\"79236.90\",\"0.247\"],[\"79434.00\",\"0.427\"],[\"79480.40\",\"0.000\"],[\"79480.50\",\"0.000\"],[\"79491.70\",\"1.079\"],[\"79607.10\",\"10.482\"]],\"a\":[[\"79609.20\",\"0.502\"],[\"79609.30\",\"0.000\"],[\"79611.20\",\"0.116\"],[\"79615.30\",\"0.700\"],[\"79615.70\",\"0.002\"],[\"79973.40\",\"1.913\"],[\"80403.30\",\"7.055\"]],\"st\":1}}"}
{"receive_ns":1788563192316509000,"stream":"btcusdt@bookTicker","event_type":"bookTicker","event_time_ms":1788563192350,"raw_json":"{\"stream\":\"btcusdt@bookTicker\",\"data\":{\"e\":\"bookTicker\",\"u\":11478222422782,\"s\":\"BTCUSDT\",\"ps\":\"BTCUSDT\",\"b\":\"79607.10\",\"B\":\"10.171\",\"a\":\"79607.20\",\"A\":\"1.144\",\"T\":1788563192350,\"E\":1788563192350,\"st\":1}}"}
{"receive_ns":1788563192316720000,"stream":"btcusdt@bookTicker","event_type":"bookTicker","event_time_ms":1788563192350,"raw_json":"{\"stream\":\"btcusdt@bookTicker\",\"data\":{\"e\":\"bookTicker\",\"u\":11478222422785,\"s\":\"BTCUSDT\",\"ps\":\"BTCUSDT\",\"b\":\"79607.10\",\"B\":\"10.171\",\"a\":\"79607.20\",\"A\":\"1.143\",\"T\":1788563192350,\"E\":1788563192350,\"st\":1}}"}
{"receive_ns":1788563192317007000,"stream":"btcusdt@trade","event_type":"trade","event_time_ms":1788563192350,"raw_json":"{\"stream\":\"btcusdt@trade\",\"data\":{\"e\":\"trade\",\"E\":1788563192350,\"T\":1788563192350,\"s\":\"BTCUSDT\",\"t\":8054082665,\"p\":\"79607.20\",\"q\":\"0.001\",\"X\":\"MARKET\",\"m\":false,\"st\":1}}"}
{"receive_ns":1788563192317294000,"stream":"btcusdt@bookTicker","event_type":"bookTicker","event_time_ms":1788563192352,"raw_json":"{\"stream\":\"btcusdt@bookTicker\",\"data\":{\"e\":\"bookTicker\",\"u\":11478222422835,\"s\":\"BTCUSDT\",\"ps\":\"BTCUSDT\",\"b\":\"79607.10\",\"B\":\"10.190\",\"a\":\"79607.20\",\"A\":\"1.143\",\"T\":1788563192351,\"E\":1788563192352,\"st\":1}}"}
{"receive_ns":1788563192317469000,"stream":"btcusdt@bookTicker","event_type":"bookTicker","event_time_ms":1788563192352,"raw_json":"{\"stream\":\"btcusdt@bookTicker\",\"data\":{\"e\":\"bookTicker\",\"u\":11478222422879,\"s\":\"BTCUSDT\",\"ps\":\"BTCUSDT\",\"b\":\"79607.10\",\"B\":\"10.198\",\"a\":\"79607.20\",\"A\":\"1.143\",\"T\":1788563192352,\"E\":1788563192352,\"st\":1}}"}
{"receive_ns":1788563192317649000,"stream":"btcusdt@bookTicker","event_type":"bookTicker","event_time_ms":1788563192352,"raw_json":"{\"stream\":\"btcusdt@bookTicker\",\"data\":{\"e\":\"bookTicker\",\"u\":11478222423014,\"s\":\"BTCUSDT\",\"ps\":\"BTCUSDT\",\"b\":\"79607.10\",\"B\":\"10.179\",\"a\":\"79607.20\",\"A\":\"1.143\",\"T\":1788563192352,\"E\":1788563192352,\"st\":1}}"}
{"receive_ns":1788563192317800000,"stream":"btcusdt@bookTicker","event_type":"bookTicker","event_time_ms":1788563192352,"raw_json":"{\"stream\":\"btcusdt@bookTicker\",\"data\":{\"e\":\"bookTicker\",\"u\":11478222423016,\"s\":\"BTCUSDT\",\"ps\":\"BTCUSDT\",\"b\":\"79607.10\",\"B\":\"10.171\",\"a\":\"79607.20\",\"A\":\"1.143\",\"T\":1788563192352,\"E\":1788563192352,\"st\":1}}"}
{"receive_ns":1788563192317998000,"stream":"btcusdt@bookTicker","event_type":"bookTicker","event_time_ms":1788563192353,"raw_json":"{\"stream\":\"btcusdt@bookTicker\",\"data\":{\"e\":\"bookTicker\",\"u\":11478222423103,\"s\":\"BTCUSDT\",\"ps\":\"BTCUSDT\",\"b\":\"79607.10\",\"B\":\"10.492\",\"a\":\"79607.20\",\"A\":\"1.143\",\"T\":1788563192353,\"E\":1788563192353,\"st\":1}}"}
{"receive_ns":1788563192321477000,"stream":"btcusdt@bookTicker","event_type":"bookTicker","event_time_ms":1788563192355,"raw_json":"{\"stream\":\"btcusdt@bookTicker\",\"data\":{\"e\":\"bookTicker\",\"u\":11478222423186,\"s\":\"BTCUSDT\",\"ps\":\"BTCUSDT\",\"b\":\"79607.10\",\"B\":\"10.490\",\"a\":\"79607.20\",\"A\":\"1.143\",\"T\":1788563192354,\"E\":1788563192355,\"st\":1}}"}
{"receive_ns":1788563192407264000,"stream":"btcusdt@depth@100ms","event_type":"depthUpdate","event_time_ms":1788563192443,"raw_json":"{\"stream\":\"btcusdt@depth@100ms\",\"data\":{\"e\":\"depthUpdate\",\"E\":1788563192443,\"T\":1788563192441,\"s\":\"BTCUSDT\",\"ps\":\"BTCUSDT\",\"U\":11478222422395,\"u\":11478222427461,\"pu\":11478222422285,\"b\":[[\"29207.10\",\"1.267\"],[\"29307.10\",\"0.833\"],[\"71646.30\",\"0.002\"],[\"76422.80\",\"0.002\"],[\"78253.80\",\"1.402\"],[\"78811.00\",\"2.225\"],[\"79440.10\",\"0.499\"],[\"79443.60\",\"0.613\"],[\"79453.90\",\"0.204\"],[\"79479.40\",\"0.125\"],[\"79479.50\",\"0.000\"],[\"79487.70\",\"0.001\"],[\"79491.70\",\"1.581\"],[\"79518.60\",\"0.000\"],[\"79534.00\",\"0.001\"],[\"79534.10\",\"1.183\"],[\"79536.70\",\"23.294\"],[\"79590.50\",\"0.000\"],[\"79593.40\",\"0.052\"],[\"79607.10\",\"10.490\"]],\"a\":[[\"79607.20\",\"1.143\"],[\"79609.70\",\"0.000\"],[\"79609.80\",\"0.000\"],[\"79610.00\",\"0.004\"],[\"79611.50\",\"0.596\"],[\"79728.60\",\"0.000\"],[\"79768.00\",\"0.064\"],[\"79973.40\",\"1.150\"],[\"80403.30\",\"7.055\"],[\"80562.50\",\"8.991\"],[\"80603.10\",\"0.620\"]],\"st\":1}}"}
{"receive_ns":1788563192448793000,"stream":"btcusdt@bookTicker","event_type":"bookTicker","event_time_ms":1788563192483,"raw_json":"{\"stream\":\"btcusdt@bookTicker\",\"data\":{\"e\":\"bookTicker\",\"u\":11478222429613,\"s\":\"BTCUSDT\",\"ps\":\"BTCUSDT\",\"b\":\"79607.10\",\"B\":\"10.207\",\"a\":\"79607.20\",\"A\":\"1.143\",\"T\":1788563192483,\"E\":1788563192483,\"st\":1}}"}
{"receive_ns":1788563192452390000,"stream":"btcusdt@bookTicker","event_type":"bookTicker","event_time_ms":1788563192486,"raw_json":"{\"stream\":\"btcusdt@bookTicker\",\"data\":{\"e\":\"bookTicker\",\"u\":11478222429758,\"s\":\"BTCUSDT\",\"ps\":\"BTCUSDT\",\"b\":\"79607.10\",\"B\":\"10.492\",\"a\":\"79607.20\",\"A\":\"1.143\",\"T\":1788563192486,\"E\":1788563192486,\"st\":1}}"}
{"receive_ns":1788563192452640000,"stream":"btcusdt@bookTicker","event_type":"bookTicker","event_time_ms":1788563192487,"raw_json":"{\"stream\":\"btcusdt@bookTicker\",\"data\":{\"e\":\"bookTicker\",\"u\":11478222429815,\"s\":\"BTCUSDT\",\"ps\":\"BTCUSDT\",\"b\":\"79607.10\",\"B\":\"10.494\",\"a\":\"79607.20\",\"A\":\"1.143\",\"T\":1788563192487,\"E\":1788563192487,\"st\":1}}"}
{"receive_ns":1788563192492704000,"stream":"btcusdt@bookTicker","event_type":"bookTicker","event_time_ms":1788563192526,"raw_json":"{\"stream\":\"btcusdt@bookTicker\",\"data\":{\"e\":\"bookTicker\",\"u\":11478222431812,\"s\":\"BTCUSDT\",\"ps\":\"BTCUSDT\",\"b\":\"79607.10\",\"B\":\"10.493\",\"a\":\"79607.20\",\"A\":\"1.143\",\"T\":1788563192526,\"E\":1788563192526,\"st\":1}}"}
{"receive_ns":1788563192492980000,"stream":"btcusdt@trade","event_type":"trade","event_time_ms":1788563192526,"raw_json":"{\"stream\":\"btcusdt@trade\",\"data\":{\"e\":\"trade\",\"E\":1788563192526,\"T\":1788563192526,\"s\":\"BTCUSDT\",\"t\":8054082666,\"p\":\"79607.10\",\"q\":\"0.001\",\"X\":\"MARKET\",\"m\":true,\"st\":1}}"}
{"receive_ns":1788563192493202000,"stream":"btcusdt@bookTicker","event_type":"bookTicker","event_time_ms":1788563192527,"raw_json":"{\"stream\":\"btcusdt@bookTicker\",\"data\":{\"e\":\"bookTicker\",\"u\":11478222431872,\"s\":\"BTCUSDT\",\"ps\":\"BTCUSDT\",\"b\":\"79607.10\",\"B\":\"10.512\",\"a\":\"79607.20\",\"A\":\"1.143\",\"T\":1788563192527,\"E\":1788563192527,\"st\":1}}"}
{"receive_ns":1788563192493393000,"stream":"btcusdt@bookTicker","event_type":"bookTicker","event_time_ms":1788563192527,"raw_json":"{\"stream\":\"btcusdt@bookTicker\",\"data\":{\"e\":\"bookTicker\",\"u\":11478222431889,\"s\":\"BTCUSDT\",\"ps\":\"BTCUSDT\",\"b\":\"79607.10\",\"B\":\"10.520\",\"a\":\"79607.20\",\"A\":\"1.143\",\"T\":1788563192527,\"E\":1788563192527,\"st\":1}}"}
{"receive_ns":1788563192493644000,"stream":"btcusdt@bookTicker","event_type":"bookTicker","event_time_ms":1788563192528,"raw_json":"{\"stream\":\"btcusdt@bookTicker\",\"data\":{\"e\":\"bookTicker\",\"u\":11478222431982,\"s\":\"BTCUSDT\",\"ps\":\"BTCUSDT\",\"b\":\"79607.10\",\"B\":\"10.501\",\"a\":\"79607.20\",\"A\":\"1.143\",\"T\":1788563192528,\"E\":1788563192528,\"st\":1}}"}
{"receive_ns":1788563192493834000,"stream":"btcusdt@bookTicker","event_type":"bookTicker","event_time_ms":1788563192528,"raw_json":"{\"stream\":\"btcusdt@bookTicker\",\"data\":{\"e\":\"bookTicker\",\"u\":11478222431992,\"s\":\"BTCUSDT\",\"ps\":\"BTCUSDT\",\"b\":\"79607.10\",\"B\":\"10.493\",\"a\":\"79607.20\",\"A\":\"1.143\",\"T\":1788563192528,\"E\":1788563192528,\"st\":1}}"}
{"receive_ns":1788563192509361000,"stream":"btcusdt@depth@100ms","event_type":"depthUpdate","event_time_ms":1788563192545,"raw_json":"{\"stream\":\"btcusdt@depth@100ms\",\"data\":{\"e\":\"depthUpdate\",\"E\":1788563192545,\"T\":1788563192541,\"s\":\"BTCUSDT\",\"ps\":\"BTCUSDT\",\"U\":11478222427560,\"u\":11478222432793,\"pu\":11478222427461,\"b\":[[\"1000.00\",\"24.604\"],[\"29207.10\",\"1.442\"],[\"29307.10\",\"0.658\"],[\"71646.30\",\"0.002\"],[\"75626.70\",\"0.021\"],[\"75626.80\",\"0.004\"],[\"78015.00\",\"0.134\"],[\"78101.20\",\"0.849\"],[\"78811.00\",\"2.225\"],[\"79209.00\",\"0.001\"],[\"79209.10\",\"0.529\"],[\"79236.90\",\"0.247\"],[\"79392.30\",\"22.784\"],[\"79434.00\",\"0.427\"],[\"79479.40\",\"0.000\"],[\"79487.70\",\"1.205\"],[\"79491.70\",\"1.506\"],[\"79493.70\",\"0.706\"],[\"79534.00\",\"23.406\"],[\"79536.70\",\"0.000\"],[\"79590.60\",\"0.304\"],[\"79604.20\",\"0.076\"],[\"79607.10\",\"10.493\"]],\"a\":[[\"79609.20\",\"0.502\"],[\"79611.20\",\"0.116\"],[\"79812.00\",\"0.607\"],[\"79815.80\",\"0.000\"],[\"79973.40\",\"1.913\"],[\"80005.30\",\"0.002\"],[\"80403.30\",\"7.055\"],[\"80681.90\",\"1.359\"],[\"81199.30\",\"0.015\"]],\"st\":1}}"}
{"receive_ns":1788563192526418000,"stream":"btcusdt@bookTicker","event_type":"bookTicker","event_time_ms":1788563192562,"raw_json":"{\"stream\":\"btcusdt@bookTicker\",\"data\":{\"e\":\"bookTicker\",\"u\":11478222434590,\"s\":\"BTCUSDT\",\"ps\":\"BTCUSDT\",\"b\":\"79607.10\",\"B\":\"10.290\",\"a\":\"79607.20\",\"A\":\"1.143\",\"T\":1788563192562,\"E\":1788563192562,\"st\":1}}"}
{"receive_ns":1788563192530181000,"stream":"btcusdt@bookTicker","event_type":"bookTicker","event_time_ms":1788563192565,"raw_json":"{\"stream\":\"btcusdt@bookTicker\",\"data\":{\"e\":\"bookTicker\",\"u\":11478222434806,\"s\":\"BTCUSDT\",\"ps\":\"BTCUSDT\",\"b\":\"79607.10\",\"B\":\"10.495\",\"a\":\"79607.20\",\"A\":\"1.143\",\"T\":1788563192565,\"E\":1788563192565,\"st\":1}}"}
{"receive_ns":1788563192531846000,"stream":"btcusdt@bookTicker","event_type":"bookTicker","event_time_ms":1788563192566,"raw_json":"{\"stream\":\"btcusdt@bookTicker\",\"data\":{\"e\":\"bookTicker\",\"u\":11478222434868,\"s\":\"BTCUSDT\",\"ps\":\"BTCUSDT\",\"b\":\"79607.10\",\"B\":\"10.494\",\"a\":\"79607.20\",\"A\":\"1.143\",\"T\":1788563192566,\"E\":1788563192566,\"st\":1}}"}
{"receive_ns":1788563192532085000,"stream":"btcusdt@bookTicker","event_type":"bookTicker","event_time_ms":1788563192567,"raw_json":"{\"stream\":\"btcusdt@bookTicker\",\"data\":{\"e\":\"bookTicker\",\"u\":11478222434946,\"s\":\"BTCUSDT\",\"ps\":\"BTCUSDT\",\"b\":\"79607.10\",\"B\":\"10.495\",\"a\":\"79607.20\",\"A\":\"1.143\",\"T\":1788563192567,\"E\":1788563192567,\"st\":1}}"}
{"receive_ns":1788563192578676000,"stream":"btcusdt@bookTicker","event_type":"bookTicker","event_time_ms":1788563192612,"raw_json":"{\"stream\":\"btcusdt@bookTicker\",\"data\":{\"e\":\"bookTicker\",\"u\":11478222438340,\"s\":\"BTCUSDT\",\"ps\":\"BTCUSDT\",\"b\":\"79607.10\",\"B\":\"10.494\",\"a\":\"79607.20\",\"A\":\"1.143\",\"T\":1788563192612,\"E\":1788563192612,\"st\":1}}"}
{"receive_ns":1788563192578941000,"stream":"btcusdt@trade","event_type":"trade","event_time_ms":1788563192612,"raw_json":"{\"stream\":\"btcusdt@trade\",\"data\":{\"e\":\"trade\",\"E\":1788563192612,\"T\":1788563192612,\"s\":\"BTCUSDT\",\"t\":8054082667,\"p\":\"79607.10\",\"q\":\"0.001\",\"X\":\"MARKET\",\"m\":true,\"st\":1}}"}
{"receive_ns":1788563192579172000,"stream":"btcusdt@bookTicker","event_type":"bookTicker","event_time_ms":1788563192614,"raw_json":"{\"stream\":\"btcusdt@bookTicker\",\"data\":{\"e\":\"bookTicker\",\"u\":11478222438443,\"s\":\"BTCUSDT\",\"ps\":\"BTCUSDT\",\"b\":\"79607.10\",\"B\":\"10.502\",\"a\":\"79607.20\",\"A\":\"1.143\",\"T\":1788563192613,\"E\":1788563192614,\"st\":1}}"}
{"receive_ns":1788563192579364000,"stream":"btcusdt@bookTicker","event_type":"bookTicker","event_time_ms":1788563192614,"raw_json":"{\"stream\":\"btcusdt@bookTicker\",\"data\":{\"e\":\"bookTicker\",\"u\":11478222438447,\"s\":\"BTCUSDT\",\"ps\":\"BTCUSDT\",\"b\":\"79607.10\",\"B\":\"10.521\",\"a\":\"79607.20\",\"A\":\"1.143\",\"T\":1788563192613,\"E\":1788563192614,\"st\":1}}"}
{"receive_ns":1788563192579609000,"stream":"btcusdt@bookTicker","event_type":"bookTicker","event_time_ms":1788563192614,"raw_json":"{\"stream\":\"btcusdt@bookTicker\",\"data\":{\"e\":\"bookTicker\",\"u\":11478222438527,\"s\":\"BTCUSDT\",\"ps\":\"BTCUSDT\",\"b\":\"79607.10\",\"B\":\"10.513\",\"a\":\"79607.20\",\"A\":\"1.143\",\"T\":1788563192614,\"E\":1788563192614,\"st\":1}}"}
{"receive_ns":1788563192579796000,"stream":"btcusdt@bookTicker","event_type":"bookTicker","event_time_ms":1788563192615,"raw_json":"{\"stream\":\"btcusdt@bookTicker\",\"data\":{\"e\":\"bookTicker\",\"u\":11478222438542,\"s\":\"BTCUSDT\",\"ps\":\"BTCUSDT\",\"b\":\"79607.10\",\"B\":\"10.494\",\"a\":\"79607.20\",\"A\":\"1.143\",\"T\":1788563192614,\"E\":1788563192615,\"st\":1}}"}
{"receive_ns":1788563192591434000,"stream":"btcusdt@bookTicker","event_type":"bookTicker","event_time_ms":1788563192625,"raw_json":"{\"stream\":\"btcusdt@bookTicker\",\"data\":{\"e\":\"bookTicker\",\"u\":11478222439193,\"s\":\"BTCUSDT\",\"ps\":\"BTCUSDT\",\"b\":\"79607.10\",\"B\":\"10.513\",\"a\":\"79607.20\",\"A\":\"1.143\",\"T\":1788563192624,\"E\":1788563192625,\"st\":1}}"}
{"receive_ns":1788563192591755000,"stream":"btcusdt@bookTicker","event_type":"bookTicker","event_time_ms":1788563192625,"raw_json":"{\"stream\":\"btcusdt@bookTicker\",\"data\":{\"e\":\"bookTicker\",\"u\":11478222439268,\"s\":\"BTCUSDT\",\"ps\":\"BTCUSDT\",\"b\":\"79607.10\",\"B\":\"10.494\",\"a\":\"79607.20\",\"A\":\"1.143\",\"T\":1788563192625,\"E\":1788563192625,\"st\":1}}"}
{"receive_ns":1788563192613711000,"stream":"btcusdt@depth@100ms","event_type":"depthUpdate","event_time_ms":1788563192647,"raw_json":"{\"stream\":\"btcusdt@depth@100ms\",\"data\":{\"e\":\"depthUpdate\",\"E\":1788563192647,\"T\":1788563192645,\"s\":\"BTCUSDT\",\"ps\":\"BTCUSDT\",\"U\":11478222432981,\"u\":11478222440518,\"pu\":11478222432793,\"b\":[[\"29207.10\",\"1.624\"],[\"29307.10\",\"0.476\"],[\"63686.00\",\"0.002\"],[\"71646.30\",\"0.002\"],[\"76422.80\",\"0.000\"],[\"78493.80\",\"4.293\"],[\"78811.00\",\"2.225\"],[\"79479.60\",\"0.149\"],[\"79487.70\",\"1.707\"],[\"79491.70\",\"1.004\"],[\"79607.10\",\"10.494\"]],\"a\":[[\"79609.20\",\"0.534\"],[\"79667.70\",\"1.544\"],[\"79973.40\",\"1.913\"],[\"80403.30\",\"7.055\"]],\"st\":1}}"}
{"receive_ns":1788563192636066000,"stream":"btcusdt@bookTicker","event_type":"bookTicker","event_time_ms":1788563192671,"raw_json":"{\"stream\":\"btcusdt@bookTicker\",\"data\":{\"e\":\"bookTicker\",\"u\":11478222442769,\"s\":\"BTCUSDT\",\"ps\":\"BTCUSDT\",\"b\":\"79607.10\",\"B\":\"10.513\",\"a\":\"79607.20\",\"A\":\"1.143\",\"T\":1788563192671,\"E\":1788563192671,\"st\":1}}"}
{"receive_ns":1788563192636367000,"stream":"btcusdt@bookTicker","event_type":"bookTicker","event_time_ms":1788563192672,"raw_json":"{\"stream\":\"btcusdt@bookTicker\",\"data\":{\"e\":\"bookTicker\",\"u\":11478222442935,\"s\":\"BTCUSDT\",\"ps\":\"BTCUSDT\",\"b\":\"79607.10\",\"B\":\"10.494\",\"a\":\"79607.20\",\"A\":\"1.143\",\"T\":1788563192672,\"E\":1788563192672,\"st\":1}}"}
{"receive_ns":1788563192645611000,"stream":"btcusdt@bookTicker","event_type":"bookTicker","event_time_ms":1788563192680,"raw_json":"{\"stream\":\"btcusdt@bookTicker\",\"data\":{\"e\":\"bookTicker\",\"u\":11478222444176,\"s\":\"BTCUSDT\",\"ps\":\"BTCUSDT\",\"b\":\"79607.10\",\"B\":\"10.513\",\"a\":\"79607.20\",\"A\":\"1.143\",\"T\":1788563192680,\"E\":1788563192680,\"st\":1}}"}
{"receive_ns":1788563192645900000,"stream":"btcusdt@bookTicker","event_type":"bookTicker","event_time_ms":1788563192681,"raw_json":"{\"stream\":\"btcusdt@bookTicker\",\"data\":{\"e\":\"bookTicker\",\"u\":11478222444252,\"s\":\"BTCUSDT\",\"ps\":\"BTCUSDT\",\"b\":\"79607.10\",\"B\":\"10.494\",\"a\":\"79607.20\",\"A\":\"1.143\",\"T\":1788563192681,\"E\":1788563192681,\"st\":1}}"}
{"receive_ns":1788563192689340000,"stream":"btcusdt@bookTicker","event_type":"bookTicker","event_time_ms":1788563192725,"raw_json":"{\"stream\":\"btcusdt@bookTicker\",\"data\":{\"e\":\"bookTicker\",\"u\":11478222447741,\"s\":\"BTCUSDT\",\"ps\":\"BTCUSDT\",\"b\":\"79607.10\",\"B\":\"10.513\",\"a\":\"79607.20\",\"A\":\"1.143\",\"T\":1788563192725,\"E\":1788563192725,\"st\":1}}"}
{"receive_ns":1788563192689841000,"stream":"btcusdt@bookTicker","event_type":"bookTicker","event_time_ms":1788563192726,"raw_json":"{\"stream\":\"btcusdt@bookTicker\",\"data\":{\"e\":\"bookTicker\",\"u\":11478222447800,\"s\":\"BTCUSDT\",\"ps\":\"BTCUSDT\",\"b\":\"79607.10\",\"B\":\"10.494\",\"a\":\"79607.20\",\"A\":\"1.143\",\"T\":1788563192726,\"E\":1788563192726,\"st\":1}}"}
{"receive_ns":1788563192697103000,"stream":"btcusdt@bookTicker","event_type":"bookTicker","event_time_ms":1788563192731,"raw_json":"{\"stream\":\"btcusdt@bookTicker\",\"data\":{\"e\":\"bookTicker\",\"u\":11478222448181,\"s\":\"BTCUSDT\",\"ps\":\"BTCUSDT\",\"b\":\"79607.10\",\"B\":\"10.496\",\"a\":\"79607.20\",\"A\":\"1.143\",\"T\":1788563192730,\"E\":1788563192731,\"st\":1}}"}
{"receive_ns":1788563192714917000,"stream":"btcusdt@depth@100ms","event_type":"depthUpdate","event_time_ms":1788563192749,"raw_json":"{\"stream\":\"btcusdt@depth@100ms\",\"data\":{\"e\":\"depthUpdate\",\"E\":1788563192749,\"T\":1788563192745,\"s\":\"BTCUSDT\",\"ps\":\"BTCUSDT\",\"U\":11478222440679,\"u\":11478222449067,\"pu\":11478222440518,\"b\":[[\"29107.10\",\"0.014\"],[\"29207.10\",\"1.771\"],[\"29307.10\",\"0.315\"],[\"71646.30\",\"0.002\"],[\"76422.80\",\"0.002\"],[\"78404.10\",\"8.484\"],[\"78492.60\",\"2.416\"],[\"78563.30\",\"7.502\"],[\"78811.00\",\"2.225\"],[\"79209.10\",\"0.529\"],[\"79236.90\",\"0.247\"],[\"79392.40\",\"5.521\"],[\"79434.00\",\"0.427\"],[\"79440.20\",\"1.766\"],[\"79479.60\",\"0.609\"],[\"79487.70\",\"1.782\"],[\"79493.70\",\"0.631\"],[\"79516.00\",\"6.279\"],[\"79583.40\",\"1.875\"],[\"79607.10\",\"10.496\"]],\"a\":[[\"79609.20\",\"0.283\"],[\"79610.50\",\"0.002\"],[\"79610.60\",\"0.345\"],[\"79611.20\",\"0.566\"],[\"79611.60\",\"0.027\"],[\"79611.70\",\"0.029\"],[\"79623.30\",\"0.045\"],[\"79728.60\",\"0.280\"],[\"79768.00\",\"1.281\"],[\"79815.80\",\"1.830\"],[\"79973.40\",\"1.913\"],[\"80000.40\",\"3.368\"],[\"80403.30\",\"7.056\"],[\"80478.80\",\"0.000\"]],\"st\":1}}"}
{"receive_ns":1788563192739541000,"stream":"btcusdt@bookTicker","event_type":"bookTicker","event_time_ms":1788563192774,"raw_json":"{\"stream\":\"btcusdt@bookTicker\",\"data\":{\"e\":\"bookTicker\",\"u\":11478222450694,\"s\":\"BTCUSDT\",\"ps\":\"BTCUSDT\",\"b\":\"79607.10\",\"B\":\"10.515\",\"a\":\"79607.20\",\"A\":\"1.143\",\"T\":1788563192774,\"E\":1788563192774,\"st\":1}}"}
{"receive_ns":1788563192739856000,"stream":"btcusdt@bookTicker","event_type":"bookTicker","event_time_ms":1788563192775,"raw_json":"{\"stream\":\"btcusdt@bookTicker\",\"data\":{\"e\":\"bookTicker\",\"u\":11478222450729,\"s\":\"BTCUSDT\",\"ps\":\"BTCUSDT\",\"b\":\"79607.10\",\"B\":\"10.496\",\"a\":\"79607.20\",\"A\":\"1.143\",\"T\":1788563192775,\"E\":1788563192775,\"st\":1}}"}
{"receive_ns":1788563192748022000,"stream":"btcusdt@bookTicker","event_type":"bookTicker","event_time_ms":1788563192782,"raw_json":"{\"stream\":\"btcusdt@bookTicker\",\"data\":{\"e\":\"bookTicker\",\"u\":11478222451071,\"s\":\"BTCUSDT\",\"ps\":\"BTCUSDT\",\"b\":\"79607.10\",\"B\":\"10.515\",\"a\":\"79607.20\",\"A\":\"1.143\",\"T\":1788563192782,\"E\":1788563192782,\"st\":1}}"}
{"receive_ns":1788563192748287000,"stream":"btcusdt@bookTicker","event_type":"bookTicker","event_time_ms":1788563192783,"raw_json":"{\"stream\":\"btcusdt@bookTicker\",\"data\":{\"e\":\"bookTicker\",\"u\":11478222451100,\"s\":\"BTCUSDT\",\"ps\":\"BTCUSDT\",\"b\":\"79607.10\",\"B\":\"10.496\",\"a\":\"79607.20\",\"A\":\"1.143\",\"T\":1788563192782,\"E\":1788563192783,\"st\":1}}"}
{"receive_ns":1788563192815756000,"stream":"btcusdt@depth@100ms","event_type":"depthUpdate","event_time_ms":1788563192851,"raw_json":"{\"stream\":\"btcusdt@depth@100ms\",\"data\":{\"e\":\"depthUpdate\",\"E\":1788563192851,\"T\":1788563192849,\"s\":\"BTCUSDT\",\"ps\":\"BTCUSDT\",\"U\":11478222449322,\"u\":11478222453893,\"pu\":11478222449067,\"b\":[[\"1000.00\",\"24.604\"],[\"29107.10\",\"0.077\"],[\"29207.10\",\"1.827\"],[\"29307.10\",\"0.196\"],[\"63686.00\",\"0.005\"],[\"71646.30\",\"0.002\"],[\"76422.80\",\"0.000\"],[\"78134.40\",\"0.830\"],[\"78811.00\",\"2.225\"],[\"79209.10\",\"0.519\"],[\"79487.70\",\"1.280\"],[\"79491.70\",\"0.000\"],[\"79516.00\",\"4.562\"],[\"79604.20\",\"0.000\"],[\"79607.10\",\"10.496\"]],\"a\":[[\"79609.90\",\"0.028\"],[\"79611.20\",\"0.367\"],[\"79615.30\",\"0.692\"],[\"79615.70\",\"0.010\"],[\"79620.40\",\"0.000\"],[\"79621.40\",\"0.699\"],[\"79675.80\",\"0.003\"],[\"79690.00\",\"0.360\"],[\"79973.40\",\"0.969\"],[\"80403.30\",\"7.056\"],[\"80562.50\",\"10.478\"]],\"st\":1}}"}
{"receive_ns":1788563192918657000,"stream":"btcusdt@depth@100ms","event_type":"depthUpdate","event_time_ms":1788563192953,"raw_json":"{\"stream\":\"btcusdt@depth@100ms\",\"data\":{\"e\":\"depthUpdate\",\"E\":1788563192953,\"T\":1788563192951,\"s\":\"BTCUSDT\",\"ps\":\"BTCUSDT\",\"U\":11478222454002,\"u\":11478222459354,\"pu\":11478222453893,\"b\":[[\"29107.10\",\"0.133\"],[\"29207.10\",\"1.890\"],[\"29307.10\",\"0.077\"],[\"63685.70\",\"0.001\"],[\"63686.00\",\"0.002\"],[\"71646.30\",\"0.002\"],[\"78479.30\",\"17.883\"],[\"78492.60\",\"4.325\"],[\"78811.00\",\"2.225\"],[\"79209.10\",\"0.378\"],[\"79236.90\",\"0.015\"],[\"79434.00\",\"0.076\"],[\"79487.70\",\"1.707\"],[\"79491.70\",\"1.004\"],[\"79511.50\",\"0.024\"],[\"79593.40\",\"0.046\"],[\"79595.30\",\"0.009\"]],\"a\":[[\"79609.20\",\"0.032\"],[\"79609.40\",\"0.030\"],[\"79609.90\",\"0.002\"],[\"79610.60\",\"0.371\"],[\"79611.20\",\"0.026\"],[\"79615.30\",\"0.700\"],[\"79615.70\",\"0.002\"],[\"79666.90\",\"0.086\"],[\"79678.90\",\"0.018\"],[\"79973.40\",\"1.713\"],[\"80403.30\",\"7.056\"],[\"80562.50\",\"11.718\"],[\"80602.30\",\"2.464\"],[\"81199.30\",\"0.018\"]],\"st\":1}}"}
{"receive_ns":1788563192943791000,"stream":"btcusdt@bookTicker","event_type":"bookTicker","event_time_ms":1788563192977,"raw_json":"{\"stream\":\"btcusdt@bookTicker\",\"data\":{\"e\":\"bookTicker\",\"u\":11478222460694,\"s\":\"BTCUSDT\",\"ps\":\"BTCUSDT\",\"b\":\"79607.10\",\"B\":\"10.504\",\"a\":\"79607.20\",\"A\":\"1.143\",\"T\":1788563192976,\"E\":1788563192977,\"st\":1}}"}
{"receive_ns":1788563192944052000,"stream":"btcusdt@bookTicker","event_type":"bookTicker","event_time_ms":1788563192977,"raw_json":"{\"stream\":\"btcusdt@bookTicker\",\"data\":{\"e\":\"bookTicker\",\"u\":11478222460909,\"s\":\"BTCUSDT\",\"ps\":\"BTCUSDT\",\"b\":\"79607.10\",\"B\":\"11.544\",\"a\":\"79607.20\",\"A\":\"1.143\",\"T\":1788563192977,\"E\":1788563192977,\"st\":1}}"}
{"receive_ns":1788563192944237000,"stream":"btcusdt@bookTicker","event_type":"bookTicker","event_time_ms":1788563192977,"raw_json":"{\"stream\":\"btcusdt@bookTicker\",\"data\":{\"e\":\"bookTicker\",\"u\":11478222461220,\"s\":\"BTCUSDT\",\"ps\":\"BTCUSDT\",\"b\":\"79607.10\",\"B\":\"11.536\",\"a\":\"79607.20\",\"A\":\"1.143\",\"T\":1788563192977,\"E\":1788563192977,\"st\":1}}"}
{"receive_ns":1788563192944419000,"stream":"btcusdt@bookTicker","event_type":"bookTicker","event_time_ms":1788563192978,"raw_json":"{\"stream\":\"btcusdt@bookTicker\",\"data\":{\"e\":\"bookTicker\",\"u\":11478222461832,\"s\":\"BTCUSDT\",\"ps\":\"BTCUSDT\",\"b\":\"79607.10\",\"B\":\"11.534\",\"a\":\"79607.20\",\"A\":\"1.143\",\"T\":1788563192978,\"E\":1788563192978,\"st\":1}}"}
{"receive_ns":1788563192944599000,"stream":"btcusdt@bookTicker","event_type":"bookTicker","event_time_ms":1788563192979,"raw_json":"{\"stream\":\"btcusdt@bookTicker\",\"data\":{\"e\":\"bookTicker\",\"u\":11478222461988,\"s\":\"BTCUSDT\",\"ps\":\"BTCUSDT\",\"b\":\"79607.10\",\"B\":\"11.542\",\"a\":\"79607.20\",\"A\":\"1.143\",\"T\":1788563192978,\"E\":1788563192979,\"st\":1}}"}
{"receive_ns":1788563192944752000,"stream":"btcusdt@bookTicker","event_type":"bookTicker","event_time_ms":1788563192979,"raw_json":"{\"stream\":\"btcusdt@bookTicker\",\"data\":{\"e\":\"bookTicker\",\"u\":11478222462044,\"s\":\"BTCUSDT\",\"ps\":\"BTCUSDT\",\"b\":\"79607.10\",\"B\":\"11.561\",\"a\":\"79607.20\",\"A\":\"1.143\",\"T\":1788563192979,\"E\":1788563192979,\"st\":1}}"}
{"receive_ns":1788563192944922000,"stream":"btcusdt@bookTicker","event_type":"bookTicker","event_time_ms":1788563192979,"raw_json":"{\"stream\":\"btcusdt@bookTicker\",\"data\":{\"e\":\"bookTicker\",\"u\":11478222462592,\"s\":\"BTCUSDT\",\"ps\":\"BTCUSDT\",\"b\":\"79607.10\",\"B\":\"11.553\",\"a\":\"79607.20\",\"A\":\"1.143\",\"T\":1788563192979,\"E\":1788563192979,\"st\":1}}"}
{"receive_ns":1788563192945094000,"stream":"btcusdt@bookTicker","event_type":"bookTicker","event_time_ms":1788563192980,"raw_json":"{\"stream\":\"btcusdt@bookTicker\",\"data\":{\"e\":\"bookTicker\",\"u\":11478222462723,\"s\":\"BTCUSDT\",\"ps\":\"BTCUSDT\",\"b\":\"79607.10\",\"B\":\"10.513\",\"a\":\"79607.20\",\"A\":\"1.143\",\"T\":1788563192979,\"E\":1788563192980,\"st\":1}}"}
{"receive_ns":1788563192945243000,"stream":"btcusdt@bookTicker","event_type":"bookTicker","event_time_ms":1788563192980,"raw_json":"{\"stream\":\"btcusdt@bookTicker\",\"data\":{\"e\":\"bookTicker\",\"u\":11478222462738,\"s\":\"BTCUSDT\",\"ps\":\"BTCUSDT\",\"b\":\"79607.10\",\"B\":\"10.494\",\"a\":\"79607.20\",\"A\":\"1.143\",\"T\":1788563192979,\"E\":1788563192980,\"st\":1}}"}
{"receive_ns":1788563192945452000,"stream":"btcusdt@bookTicker","event_type":"bookTicker","event_time_ms":1788563192980,"raw_json":"{\"stream\":\"btcusdt@bookTicker\",\"data\":{\"e\":\"bookTicker\",\"u\":11478222463081,\"s\":\"BTCUSDT\",\"ps\":\"BTCUSDT\",\"b\":\"79607.10\",\"B\":\"10.496\",\"a\":\"79607.20\",\"A\":\"1.143\",\"T\":1788563192980,\"E\":1788563192980,\"st\":1}}"}
{"receive_ns":1788563192948522000,"stream":"btcusdt@bookTicker","event_type":"bookTicker","event_time_ms":1788563192984,"raw_json":"{\"stream\":\"btcusdt@bookTicker\",\"data\":{\"e\":\"bookTicker\",\"u\":11478222464620,\"s\":\"BTCUSDT\",\"ps\":\"BTCUSDT\",\"b\":\"79607.10\",\"B\":\"10.515\",\"a\":\"79607.20\",\"A\":\"1.143\",\"T\":1788563192984,\"E\":1788563192984,\"st\":1}}"}
{"receive_ns":1788563192949496000,"stream":"btcusdt@bookTicker","event_type":"bookTicker","event_time_ms":1788563192985,"raw_json":"{\"stream\":\"btcusdt@bookTicker\",\"data\":{\"e\":\"bookTicker\",\"u\":11478222464811,\"s\":\"BTCUSDT\",\"ps\":\"BTCUSDT\",\"b\":\"79607.10\",\"B\":\"10.496\",\"a\":\"79607.20\",\"A\":\"1.143\",\"T\":1788563192984,\"E\":1788563192985,\"st\":1}}"}
{"receive_ns":1788563192960210000,"stream":"btcusdt@bookTicker","event_type":"bookTicker","event_time_ms":1788563192995,"raw_json":"{\"stream\":\"btcusdt@bookTicker\",\"data\":{\"e\":\"bookTicker\",\"u\":11478222468029,\"s\":\"BTCUSDT\",\"ps\":\"BTCUSDT\",\"b\":\"79607.10\",\"B\":\"10.515\",\"a\":\"79607.20\",\"A\":\"1.143\",\"T\":1788563192995,\"E\":1788563192995,\"st\":1}}"}
{"receive_ns":1788563192960486000,"stream":"btcusdt@bookTicker","event_type":"bookTicker","event_time_ms":1788563192996,"raw_json":"{\"stream\":\"btcusdt@bookTicker\",\"data\":{\"e\":\"bookTicker\",\"u\":11478222468430,\"s\":\"BTCUSDT\",\"ps\":\"BTCUSDT\",\"b\":\"79607.10\",\"B\":\"10.496\",\"a\":\"79607.20\",\"A\":\"1.143\",\"T\":1788563192996,\"E\":1788563192996,\"st\":1}}"}
{"receive_ns":1788563192962534000,"stream":"btcusdt@bookTicker","event_type":"bookTicker","event_time_ms":1788563192998,"raw_json":"{\"stream\":\"btcusdt@bookTicker\",\"data\":{\"e\":\"bookTicker\",\"u\":11478222468959,\"s\":\"BTCUSDT\",\"ps\":\"BTCUSDT\",\"b\":\"79607.10\",\"B\":\"10.496\",\"a\":\"79607.20\",\"A\":\"1.583\",\"T\":1788563192998,\"E\":1788563192998,\"st\":1}}"}
{"receive_ns":1788563192964096000,"stream":"btcusdt@bookTicker","event_type":"bookTicker","event_time_ms":1788563192999,"raw_json":"{\"stream\":\"btcusdt@bookTicker\",\"data\":{\"e\":\"bookTicker\",\"u\":11478222469218,\"s\":\"BTCUSDT\",\"ps\":\"BTCUSDT\",\"b\":\"79607.10\",\"B\":\"10.496\",\"a\":\"79607.20\",\"A\":\"1.582\",\"T\":1788563192999,\"E\":1788563192999,\"st\":1}}"}
{"receive_ns":1788563192964295000,"stream":"btcusdt@bookTicker","event_type":"bookTicker","event_time_ms":1788563192999,"raw_json":"{\"stream\":\"btcusdt@bookTicker\",\"data\":{\"e\":\"bookTicker\",\"u\":11478222469228,\"s\":\"BTCUSDT\",\"ps\":\"BTCUSDT\",\"b\":\"79607.10\",\"B\":\"10.504\",\"a\":\"79607.20\",\"A\":\"1.582\",\"T\":1788563192999,\"E\":1788563192999,\"st\":1}}"}
{"receive_ns":1788563192964454000,"stream":"btcusdt@bookTicker","event_type":"bookTicker","event_time_ms":1788563192999,"raw_json":"{\"stream\":\"btcusdt@bookTicker\",\"data\":{\"e\":\"bookTicker\",\"u\":11478222469250,\"s\":\"BTCUSDT\",\"ps\":\"BTCUSDT\",\"b\":\"79607.10\",\"B\":\"10.523\",\"a\":\"79607.20\",\"A\":\"1.582\",\"T\":1788563192999,\"E\":1788563192999,\"st\":1}}"}
{"receive_ns":1788563192964607000,"stream":"btcusdt@bookTicker","event_type":"bookTicker","event_time_ms":1788563192999,"raw_json":"{\"stream\":\"btcusdt@bookTicker\",\"data\":{\"e\":\"bookTicker\",\"u\":11478222469261,\"s\":\"BTCUSDT\",\"ps\":\"BTCUSDT\",\"b\":\"79607.10\",\"B\":\"10.523\",\"a\":\"79607.20\",\"A\":\"1.732\",\"T\":1788563192999,\"E\":1788563192999,\"st\":1}}"}
{"receive_ns":1788563192964762000,"stream":"btcusdt@bookTicker","event_type":"bookTicker","event_time_ms":1788563192999,"raw_json":"{\"stream\":\"btcusdt@bookTicker\",\"data\":{\"e\":\"bookTicker\",\"u\":11478222469263,\"s\":\"BTCUSDT\",\"ps\":\"BTCUSDT\",\"b\":\"79607.10\",\"B\":\"10.523\",\"a\":\"79607.20\",\"A\":\"1.731\",\"T\":1788563192999,\"E\":1788563192999,\"st\":1}}"}
{"receive_ns":1788563192964939000,"stream":"btcusdt@bookTicker","event_type":"bookTicker","event_time_ms":1788563193000,"raw_json":"{\"stream\":\"btcusdt@bookTicker\",\"data\":{\"e\":\"bookTicker\",\"u\":11478222469347,\"s\":\"BTCUSDT\",\"ps\":\"BTCUSDT\",\"b\":\"79607.10\",\"B\":\"10.515\",\"a\":\"79607.20\",\"A\":\"1.731\",\"T\":1788563193000,\"E\":1788563193000,\"st\":1}}"}
{"receive_ns":1788563192965090000,"stream":"btcusdt@bookTicker","event_type":"bookTicker","event_time_ms":1788563193000,"raw_json":"{\"stream\":\"btcusdt@bookTicker\",\"data\":{\"e\":\"bookTicker\",\"u\":11478222469374,\"s\":\"BTCUSDT\",\"ps\":\"BTCUSDT\",\"b\":\"79607.10\",\"B\":\"10.515\",\"a\":\"79607.20\",\"A\":\"1.732\",\"T\":1788563193000,\"E\":1788563193000,\"st\":1}}"}
{"receive_ns":1788563192965247000,"stream":"btcusdt@bookTicker","event_type":"bookTicker","event_time_ms":1788563193000,"raw_json":"{\"stream\":\"btcusdt@bookTicker\",\"data\":{\"e\":\"bookTicker\",\"u\":11478222469375,\"s\":\"BTCUSDT\",\"ps\":\"BTCUSDT\",\"b\":\"79607.10\",\"B\":\"10.496\",\"a\":\"79607.20\",\"A\":\"1.732\",\"T\":1788563193000,\"E\":1788563193000,\"st\":1}}"}
{"receive_ns":1788563192965465000,"stream":"btcusdt@bookTicker","event_type":"bookTicker","event_time_ms":1788563193000,"raw_json":"{\"stream\":\"btcusdt@bookTicker\",\"data\":{\"e\":\"bookTicker\",\"u\":11478222469412,\"s\":\"BTCUSDT\",\"ps\":\"BTCUSDT\",\"b\":\"79607.10\",\"B\":\"10.496\",\"a\":\"79607.20\",\"A\":\"1.733\",\"T\":1788563193000,\"E\":1788563193000,\"st\":1}}"}
{"receive_ns":1788563192968982000,"stream":"btcusdt@bookTicker","event_type":"bookTicker","event_time_ms":1788563193004,"raw_json":"{\"stream\":\"btcusdt@bookTicker\",\"data\":{\"e\":\"bookTicker\",\"u\":11478222469909,\"s\":\"BTCUSDT\",\"ps\":\"BTCUSDT\",\"b\":\"79607.10\",\"B\":\"10.493\",\"a\":\"79607.20\",\"A\":\"1.733\",\"T\":1788563193004,\"E\":1788563193004,\"st\":1}}"}
{"receive_ns":1788563192969232000,"stream":"btcusdt@trade","event_type":"trade","event_time_ms":1788563193004,"raw_json":"{\"stream\":\"btcusdt@trade\",\"data\":{\"e\":\"trade\",\"E\":1788563193004,\"T\":1788563193004,\"s\":\"BTCUSDT\",\"t\":8054082668,\"p\":\"79607.10\",\"q\":\"0.003\",\"X\":\"MARKET\",\"m\":true,\"st\":1}}"}
{"receive_ns":1788563192969452000,"stream":"btcusdt@bookTicker","event_type":"bookTicker","event_time_ms":1788563193006,"raw_json":"{\"stream\":\"btcusdt@bookTicker\",\"data\":{\"e\":\"bookTicker\",\"u\":11478222470092,\"s\":\"BTCUSDT\",\"ps\":\"BTCUSDT\",\"b\":\"79607.10\",\"B\":\"10.512\",\"a\":\"79607.20\",\"A\":\"1.733\",\"T\":1788563193005,\"E\":1788563193006,\"st\":1}}"}
{"receive_ns":1788563192970135000,"stream":"btcusdt@bookTicker","event_type":"bookTicker","event_time_ms":1788563193006,"raw_json":"{\"stream\":\"btcusdt@bookTicker\",\"data\":{\"e\":\"bookTicker\",\"u\":11478222470134,\"s\":\"BTCUSDT\",\"ps\":\"BTCUSDT\",\"b\":\"79607.10\",\"B\":\"10.520\",\"a\":\"79607.20\",\"A\":\"1.733\",\"T\":1788563193005,\"E\":1788563193006,\"st\":1}}"}
{"receive_ns":1788563192970518000,"stream":"btcusdt@bookTicker","event_type":"bookTicker","event_time_ms":1788563193006,"raw_json":"{\"stream\":\"btcusdt@bookTicker\",\"data\":{\"e\":\"bookTicker\",\"u\":11478222470241,\"s\":\"BTCUSDT\",\"ps\":\"BTCUSDT\",\"b\":\"79607.10\",\"B\":\"10.501\",\"a\":\"79607.20\",\"A\":\"1.733\",\"T\":1788563193006,\"E\":1788563193006,\"st\":1}}"}
{"receive_ns":1788563192970704000,"stream":"btcusdt@bookTicker","event_type":"bookTicker","event_time_ms":1788563193006,"raw_json":"{\"stream\":\"btcusdt@bookTicker\",\"data\":{\"e\":\"bookTicker\",\"u\":11478222470246,\"s\":\"BTCUSDT\",\"ps\":\"BTCUSDT\",\"b\":\"79607.10\",\"B\":\"10.493\",\"a\":\"79607.20\",\"A\":\"1.733\",\"T\":1788563193006,\"E\":1788563193006,\"st\":1}}"}
{"receive_ns":1788563192974026000,"stream":"btcusdt@bookTicker","event_type":"bookTicker","event_time_ms":1788563193009,"raw_json":"{\"stream\":\"btcusdt@bookTicker\",\"data\":{\"e\":\"bookTicker\",\"u\":11478222470541,\"s\":\"BTCUSDT\",\"ps\":\"BTCUSDT\",\"b\":\"79607.10\",\"B\":\"10.493\",\"a\":\"79607.20\",\"A\":\"1.734\",\"T\":1788563193009,\"E\":1788563193009,\"st\":1}}"}
{"receive_ns":1788563192988821000,"stream":"btcusdt@bookTicker","event_type":"bookTicker","event_time_ms":1788563193024,"raw_json":"{\"stream\":\"btcusdt@bookTicker\",\"data\":{\"e\":\"bookTicker\",\"u\":11478222471800,\"s\":\"BTCUSDT\",\"ps\":\"BTCUSDT\",\"b\":\"79607.10\",\"B\":\"10.512\",\"a\":\"79607.20\",\"A\":\"1.734\",\"T\":1788563193024,\"E\":1788563193024,\"st\":1}}"}
{"receive_ns":1788563192989058000,"stream":"btcusdt@bookTicker","event_type":"bookTicker","event_time_ms":1788563193024,"raw_json":"{\"stream\":\"btcusdt@bookTicker\",\"data\":{\"e\":\"bookTicker\",\"u\":11478222471844,\"s\":\"BTCUSDT\",\"ps\":\"BTCUSDT\",\"b\":\"79607.10\",\"B\":\"10.520\",\"a\":\"79607.20\",\"A\":\"1.734\",\"T\":1788563193024,\"E\":1788563193024,\"st\":1}}"}
{"receive_ns":1788563192989268000,"stream":"btcusdt@bookTicker","event_type":"bookTicker","event_time_ms":1788563193025,"raw_json":"{\"stream\":\"btcusdt@bookTicker\",\"data\":{\"e\":\"bookTicker\",\"u\":11478222471870,\"s\":\"BTCUSDT\",\"ps\":\"BTCUSDT\",\"b\":\"79607.10\",\"B\":\"10.501\",\"a\":\"79607.20\",\"A\":\"1.734\",\"T\":1788563193024,\"E\":1788563193025,\"st\":1}}"}
{"receive_ns":1788563192989429000,"stream":"btcusdt@bookTicker","event_type":"bookTicker","event_time_ms":1788563193025,"raw_json":"{\"stream\":\"btcusdt@bookTicker\",\"data\":{\"e\":\"bookTicker\",\"u\":11478222471882,\"s\":\"BTCUSDT\",\"ps\":\"BTCUSDT\",\"b\":\"79607.10\",\"B\":\"10.493\",\"a\":\"79607.20\",\"A\":\"1.734\",\"T\":1788563193024,\"E\":1788563193025,\"st\":1}}"}
{"receive_ns":1788563193020335000,"stream":"btcusdt@depth@100ms","event_type":"depthUpdate","event_time_ms":1788563193055,"raw_json":"{\"stream\":\"btcusdt@depth@100ms\",\"data\":{\"e\":\"depthUpdate\",\"E\":1788563193055,\"T\":1788563193054,\"s\":\"BTCUSDT\",\"ps\":\"BTCUSDT\",\"U\":11478222459429,\"u\":11478222474895,\"pu\":11478222459354,\"b\":[[\"1000.00\",\"24.754\"],[\"29107.10\",\"0.238\"],[\"29207.10\",\"1.862\"],[\"29307.10\",\"0.000\"],[\"63686.00\",\"0.004\"],[\"71646.30\",\"0.002\"],[\"76422.80\",\"0.002\"],[\"77608.10\",\"1.262\"],[\"78603.10\",\"7.563\"],[\"78605.30\",\"0.004\"],[\"78611.50\",\"0.000\"],[\"78811.00\",\"2.225\"],[\"79209.10\",\"0.519\"],[\"79236.90\",\"0.247\"],[\"79434.00\",\"0.427\"],[\"79478.00\",\"0.001\"],[\"79478.10\",\"0.003\"],[\"79478.80\",\"0.250\"],[\"79479.60\",\"0.747\"],[\"79486.80\",\"3.775\"],[\"79491.70\",\"1.079\"],[\"79492.40\",\"0.106\"],[\"79494.70\",\"0.000\"],[\"79500.40\",\"0.333\"],[\"79502.70\",\"0.001\"],[\"79508.40\",\"0.017\"],[\"79510.70\",\"0.000\"],[\"79516.30\",\"0.047\"],[\"79523.70\",\"0.017\"],[\"79542.80\",\"1.366\"],[\"79552.50\",\"0.220\"],[\"79558.40\",\"0.002\"],[\"79571.50\",\"0.176\"],[\"79572.10\",\"0.083\"],[\"79575.30\",\"0.453\"],[\"79576.20\",\"0.001\"],[\"79592.70\",\"0.001\"],[\"79592.80\",\"0.007\"],[\"79594.30\",\"0.165\"],[\"79600.30\",\"0.253\"],[\"79601.80\",\"0.006\"],[\"79601.90\",\"0.182\"],[\"79604.20\",\"0.076\"],[\"79605.40\",\"0.009\"],[\"79607.10\",\"10.493\"]],\"a\":[[\"79607.20\",\"1.734\"],[\"79607.30\",\"0.003\"],[\"79607.80\",\"0.001\"],[\"79607.90\",\"0.076\"],[\"79608.30\",\"0.001\"],[\"79609.00\",\"0.079\"],[\"79609.20\",\"0.534\"],[\"79609.40\",\"0.004\"],[\"79609.80\",\"0.026\"],[\"79609.90\",\"0.028\"],[\"79610.10\",\"0.027\"],[\"79610.30\",\"0.716\"],[\"79610.60\",\"0.345\"],[\"79610.80\",\"0.028\"],[\"79610.90\",\"0.027\"],[\"79611.00\",\"0.029\"],[\"79611.10\",\"0.077\"],[\"79611.20\",\"0.315\"],[\"79611.30\",\"0.341\"],[\"79611.40\",\"1.296\"],[\"79611.50\",\"0.570\"],[\"79611.60\",\"0.001\"],[\"79611.70\",\"0.003\"],[\"79611.80\",\"0.026\"],[\"79611.90\",\"0.078\"],[\"79612.00\",\"0.280\"],[\"79612.10\",\"0.002\"],[\"79612.20\",\"0.905\"],[\"79612.30\",\"2.675\"],[\"79612.40\",\"0.027\"],[\"79612.50\",\"0.001\"],[\"79612.60\",\"0.000\"],[\"79612.70\",\"0.010\"],[\"79612.80\",\"0.004\"],[\"79613.00\",\"0.002\"],[\"79613.10\",\"0.002\"],[\"79615.30\",\"0.700\"],[\"79615.70\",\"0.002\"],[\"79619.00\",\"0.633\"],[\"79621.40\",\"0.260\"],[\"79622.50\",\"0.372\"],[\"79624.80\",\"0.573\"],[\"79624.90\",\"0.002\"],[\"79625.70\",\"0.453\"],[\"79627.10\",\"0.001\"],[\"79632.00\",\"1.385\"],[\"79640.10\",\"0.020\"],[\"79653.00\",\"0.002\"],[\"79655.50\",\"2.154\"],[\"79656.20\",\"1.361\"],[\"79657.10\",\"0.201\"],[\"79660.80\",\"2.055\"],[\"79661.60\",\"0.000\"],[\"79675.30\",\"0.000\"],[\"79683.60\",\"0.063\"],[\"79728.60\",\"0.340\"],[\"79788.80\",\"0.012\"],[\"79836.20\",\"0.004\"],[\"79836.30\",\"0.023\"],[\"79973.40\",\"1.913\"],[\"80403.30\",\"7.056\"],[\"80669.10\",\"0.495\"],[\"81199.30\",\"0.015\"]],\"st\":1}}"}
{"receive_ns":1788563193033801000,"stream":"btcusdt@bookTicker","event_type":"bookTicker","event_time_ms":1788563193068,"raw_json":"{\"stream\":\"btcusdt@bookTicker\",\"data\":{\"e\":\"bookTicker\",\"u\":11478222475928,\"s\":\"BTCUSDT\",\"ps\":\"BTCUSDT\",\"b\":\"79607.10\",\"B\":\"10.288\",\"a\":\"79607.20\",\"A\":\"1.734\",\"T\":1788563193068,\"E\":1788563193068,\"st\":1}}"}
{"receive_ns":1788563193037520000,"stream":"btcusdt@bookTicker","event_type":"bookTicker","event_time_ms":1788563193071,"raw_json":"{\"stream\":\"btcusdt@bookTicker\",\"data\":{\"e\":\"bookTicker\",\"u\":11478222476152,\"s\":\"BTCUSDT\",\"ps\":\"BTCUSDT\",\"b\":\"79607.10\",\"B\":\"10.494\",\"a\":\"79607.20\",\"A\":\"1.734\",\"T\":1788563193071,\"E\":1788563193071,\"st\":1}}"}
{"receive_ns":1788563193122444000,"stream":"btcusdt@depth@100ms","event_type":"depthUpdate","event_time_ms":1788563193157,"raw_json":"{\"stream\":\"btcusdt@depth@100ms\",\"data\":{\"e\":\"depthUpdate\",\"E\":1788563193157,\"T\":1788563193156,\"s\":\"BTCUSDT\",\"ps\":\"BTCUSDT\",\"U\":11478222474948,\"u\":11478222482189,\"pu\":11478222474895,\"b\":[[\"1000.00\",\"24.604\"],[\"29107.10\",\"0.413\"],[\"29207.10\",\"1.687\"],[\"63686.00\",\"0.002\"],[\"71646.30\",\"0.002\"],[\"71680.00\",\"0.127\"],[\"75626.70\",\"0.017\"],[\"75626.80\",\"0.008\"],[\"76422.80\",\"0.000\"],[\"78015.00\",\"0.131\"],[\"78647.10\",\"22.856\"],[\"78811.00\",\"2.227\"],[\"79204.30\",\"3.465\"],[\"79209.00\",\"0.000\"],[\"79209.10\",\"0.529\"],[\"79210.10\",\"0.088\"],[\"79434.00\",\"1.933\"],[\"79471.70\",\"0.040\"],[\"79478.80\",\"0.375\"],[\"79479.60\",\"0.149\"],[\"79487.70\",\"1.205\"],[\"79491.70\",\"0.075\"],[\"79511.50\",\"0.022\"],[\"79514.10\",\"0.829\"],[\"79530.00\",\"0.922\"],[\"79534.10\",\"4.494\"],[\"79535.40\",\"0.000\"],[\"79544.50\",\"0.212\"],[\"79552.50\",\"0.010\"],[\"79592.80\",\"0.003\"],[\"79604.20\",\"0.000\"],[\"79607.10\",\"10.494\"]],\"a\":[[\"79608.90\",\"0.026\"],[\"79609.00\",\"0.105\"],[\"79609.50\",\"0.031\"],[\"79609.60\",\"0.058\"],[\"79611.20\",\"0.708\"],[\"79611.80\",\"0.000\"],[\"79612.30\",\"2.649\"],[\"79612.40\",\"0.001\"],[\"79632.00\",\"1.405\"],[\"79640.10\",\"0.000\"],[\"79663.00\",\"0.000\"],[\"79674.20\",\"0.007\"],[\"79676.80\",\"0.076\"],[\"79676.90\",\"0.207\"],[\"79677.30\",\"0.095\"],[\"79678.90\",\"0.016\"],[\"79679.60\",\"24.797\"],[\"79682.90\",\"0.000\"],[\"79688.40\",\"3.098\"],[\"79702.80\",\"0.008\"],[\"79728.60\",\"0.000\"],[\"79973.40\",\"1.494\"],[\"80005.30\",\"0.003\"],[\"80403.30\",\"7.056\"],[\"80593.20\",\"3.639\"],[\"80653.20\",\"1.246\"]],\"st\":1}}"}
{"receive_ns":1788563193158796000,"stream":"btcusdt@bookTicker","event_type":"bookTicker","event_time_ms":1788563193191,"raw_json":"{\"stream\":\"btcusdt@bookTicker\",\"data\":{\"e\":\"bookTicker\",\"u\":11478222486795,\"s\":\"BTCUSDT\",\"ps\":\"BTCUSDT\",\"b\":\"79607.10\",\"B\":\"10.494\",\"a\":\"79607.20\",\"A\":\"1.733\",\"T\":1788563193191,\"E\":1788563193191,\"st\":1}}"}
{"receive_ns":1788563193159026000,"stream":"btcusdt@trade","event_type":"trade","event_time_ms":1788563193191,"raw_json":"{\"stream\":\"btcusdt@trade\",\"data\":{\"e\":\"trade\",\"E\":1788563193191,\"T\":1788563193191,\"s\":\"BTCUSDT\",\"t\":8054082669,\"p\":\"79607.20\",\"q\":\"0.001\",\"X\":\"MARKET\",\"m\":false,\"st\":1}}"}
{"receive_ns":1788563193159208000,"stream":"btcusdt@bookTicker","event_type":"bookTicker","event_time_ms":1788563193192,"raw_json":"{\"stream\":\"btcusdt@bookTicker\",\"data\":{\"e\":\"bookTicker\",\"u\":11478222486897,\"s\":\"BTCUSDT\",\"ps\":\"BTCUSDT\",\"b\":\"79607.10\",\"B\":\"10.513\",\"a\":\"79607.20\",\"A\":\"1.733\",\"T\":1788563193192,\"E\":1788563193192,\"st\":1}}"}
{"receive_ns":1788563193159382000,"stream":"btcusdt@bookTicker","event_type":"bookTicker","event_time_ms":1788563193192,"raw_json":"{\"stream\":\"btcusdt@bookTicker\",\"data\":{\"e\":\"bookTicker\",\"u\":11478222486954,\"s\":\"BTCUSDT\",\"ps\":\"BTCUSDT\",\"b\":\"79607.10\",\"B\":\"10.521\",\"a\":\"79607.20\",\"A\":\"1.733\",\"T\":1788563193192,\"E\":1788563193192,\"st\":1}}"}
{"receive_ns":1788563193159553000,"stream":"btcusdt@bookTicker","event_type":"bookTicker","event_time_ms":1788563193193,"raw_json":"{\"stream\":\"btcusdt@bookTicker\",\"data\":{\"e\":\"bookTicker\",\"u\":11478222487095,\"s\":\"BTCUSDT\",\"ps\":\"BTCUSDT\",\"b\":\"79607.10\",\"B\":\"10.502\",\"a\":\"79607.20\",\"A\":\"1.733\",\"T\":1788563193193,\"E\":1788563193193,\"st\":1}}"}
{"receive_ns":1788563193159758000,"stream":"btcusdt@bookTicker","event_type":"bookTicker","event_time_ms":1788563193193,"raw_json":"{\"stream\":\"btcusdt@bookTicker\",\"data\":{\"e\":\"bookTicker\",\"u\":11478222487145,\"s\":\"BTCUSDT\",\"ps\":\"BTCUSDT\",\"b\":\"79607.10\",\"B\":\"10.494\",\"a\":\"79607.20\",\"A\":\"1.733\",\"T\":1788563193193,\"E\":1788563193193,\"st\":1}}"}
{"receive_ns":1788563193194832000,"stream":"btcusdt@bookTicker","event_type":"bookTicker","event_time_ms":1788563193229,"raw_json":"{\"stream\":\"btcusdt@bookTicker\",\"data\":{\"e\":\"bookTicker\",\"u\":11478222490192,\"s\":\"BTCUSDT\",\"ps\":\"BTCUSDT\",\"b\":\"79607.10\",\"B\":\"10.494\",\"a\":\"79607.20\",\"A\":\"1.730\",\"T\":1788563193229,\"E\":1788563193229,\"st\":1}}"}
{"receive_ns":1788563193222998000,"stream":"btcusdt@depth@100ms","event_type":"depthUpdate","event_time_ms":1788563193259,"raw_json":"{\"stream\":\"btcusdt@depth@100ms\",\"data\":{\"e\":\"depthUpdate\",\"E\":1788563193259,\"T\":1788563193257,\"s\":\"BTCUSDT\",\"ps\":\"BTCUSDT\",\"U\":11478222482269,\"u\":11478222491841,\"pu\":11478222482189,\"b\":[[\"29107.10\",\"0.595\"],[\"29207.10\",\"1.505\"],[\"71646.30\",\"0.002\"],[\"76422.80\",\"0.002\"],[\"78412.90\",\"0.574\"],[\"78811.00\",\"2.225\"],[\"79209.10\",\"0.529\"],[\"79236.90\",\"0.247\"],[\"79434.00\",\"1.933\"],[\"79440.20\",\"0.003\"],[\"79453.90\",\"1.408\"],[\"79478.80\",\"0.250\"],[\"79487.70\",\"0.076\"],[\"79491.70\",\"0.000\"],[\"79602.40\",\"0.058\"],[\"79607.10\",\"10.494\"]],\"a\":[[\"79607.20\",\"1.730\"],[\"79608.90\",\"0.000\"],[\"79609.00\",\"0.079\"],[\"79609.20\",\"0.733\"],[\"79609.30\",\"0.026\"],[\"79611.20\",\"0.090\"],[\"79613.50\",\"0.000\"],[\"79614.70\",\"0.252\"],[\"79615.10\",\"0.000\"],[\"79615.30\",\"0.702\"],[\"79674.40\",\"0.062\"],[\"79676.90\",\"24.659\"],[\"79679.60\",\"0.345\"],[\"79683.60\",\"0.003\"],[\"79707.60\",\"8.783\"],[\"79768.00\",\"0.064\"],[\"79973.40\",\"1.494\"],[\"80403.30\",\"7.056\"],[\"81199.30\",\"0.018\"],[\"81279.00\",\"0.246\"]],\"st\":1}}"}
{"receive_ns":1788563193276788000,"stream":"btcusdt@bookTicker","event_type":"bookTicker","event_time_ms":1788563193311,"raw_json":"{\"stream\":\"btcusdt@bookTicker\",\"data\":{\"e\":\"bookTicker\",\"u\":11478222495531,\"s\":\"BTCUSDT\",\"ps\":\"BTCUSDT\",\"b\":\"79607.10\",\"B\":\"10.494\",\"a\":\"79607.20\",\"A\":\"1.751\",\"T\":1788563193311,\"E\":1788563193311,\"st\":1}}"}
{"receive_ns":1788563193277113000,"stream":"btcusdt@bookTicker","event_type":"bookTicker","event_time_ms":1788563193312,"raw_json":"{\"stream\":\"btcusdt@bookTicker\",\"data\":{\"e\":\"bookTicker\",\"u\":11478222495630,\"s\":\"BTCUSDT\",\"ps\":\"BTCUSDT\",\"b\":\"79607.10\",\"B\":\"10.494\",\"a\":\"79607.20\",\"A\":\"1.750\",\"T\":1788563193312,\"E\":1788563193312,\"st\":1}}"}
{"receive_ns":1788563193294595000,"stream":"btcusdt@bookTicker","event_type":"bookTicker","event_time_ms":1788563193329,"raw_json":"{\"stream\":\"btcusdt@bookTicker\",\"data\":{\"e\":\"bookTicker\",\"u\":11478222496802,\"s\":\"BTCUSDT\",\"ps\":\"BTCUSDT\",\"b\":\"79607.10\",\"B\":\"10.513\",\"a\":\"79607.20\",\"A\":\"1.750\",\"T\":1788563193328,\"E\":1788563193329,\"st\":1}}"}
{"receive_ns":1788563193294823000,"stream":"btcusdt@bookTicker","event_type":"bookTicker","event_time_ms":1788563193329,"raw_json":"{\"stream\":\"btcusdt@bookTicker\",\"data\":{\"e\":\"bookTicker\",\"u\":11478222496820,\"s\":\"BTCUSDT\",\"ps\":\"BTCUSDT\",\"b\":\"79607.10\",\"B\":\"10.513\",\"a\":\"79607.20\",\"A\":\"1.310\",\"T\":1788563193329,\"E\":1788563193329,\"st\":1}}"}
{"receive_ns":1788563193295006000,"stream":"btcusdt@bookTicker","event_type":"bookTicker","event_time_ms":1788563193329,"raw_json":"{\"stream\":\"btcusdt@bookTicker\",\"data\":{\"e\":\"bookTicker\",\"u\":11478222496847,\"s\":\"BTCUSDT\",\"ps\":\"BTCUSDT\",\"b\":\"79607.10\",\"B\":\"10.494\",\"a\":\"79607.20\",\"A\":\"1.310\",\"T\":1788563193329,\"E\":1788563193329,\"st\":1}}"}
{"receive_ns":1788563193295181000,"stream":"btcusdt@bookTicker","event_type":"bookTicker","event_time_ms":1788563193330,"raw_json":"{\"stream\":\"btcusdt@bookTicker\",\"data\":{\"e\":\"bookTicker\",\"u\":11478222496899,\"s\":\"BTCUSDT\",\"ps\":\"BTCUSDT\",\"b\":\"79607.10\",\"B\":\"10.513\",\"a\":\"79607.20\",\"A\":\"1.310\",\"T\":1788563193330,\"E\":1788563193330,\"st\":1}}"}
{"receive_ns":1788563193295397000,"stream":"btcusdt@bookTicker","event_type":"bookTicker","event_time_ms":1788563193330,"raw_json":"{\"stream\":\"btcusdt@bookTicker\",\"data\":{\"e\":\"bookTicker\",\"u\":11478222496924,\"s\":\"BTCUSDT\",\"ps\":\"BTCUSDT\",\"b\":\"79607.10\",\"B\":\"10.513\",\"a\":\"79607.20\",\"A\":\"1.160\",\"T\":1788563193330,\"E\":1788563193330,\"st\":1}}"}
{"receive_ns":1788563193295560000,"stream":"btcusdt@bookTicker","event_type":"bookTicker","event_time_ms":1788563193330,"raw_json":"{\"stream\":\"btcusdt@bookTicker\",\"data\":{\"e\":\"bookTicker\",\"u\":11478222496938,\"s\":\"BTCUSDT\",\"ps\":\"BTCUSDT\",\"b\":\"79607.10\",\"B\":\"10.513\",\"a\":\"79607.20\",\"A\":\"1.161\",\"T\":1788563193330,\"E\":1788563193330,\"st\":1}}"}
{"receive_ns":1788563193295707000,"stream":"btcusdt@bookTicker","event_type":"bookTicker","event_time_ms":1788563193330,"raw_json":"{\"stream\":\"btcusdt@bookTicker\",\"data\":{\"e\":\"bookTicker\",\"u\":11478222496968,\"s\":\"BTCUSDT\",\"ps\":\"BTCUSDT\",\"b\":\"79607.10\",\"B\":\"10.521\",\"a\":\"79607.20\",\"A\":\"1.161\",\"T\":1788563193330,\"E\":1788563193330,\"st\":1}}"}
{"receive_ns":1788563193295903000,"stream":"btcusdt@bookTicker","event_type":"bookTicker","event_time_ms":1788563193331,"raw_json":"{\"stream\":\"btcusdt@bookTicker\",\"data\":{\"e\":\"bookTicker\",\"u\":11478222497017,\"s\":\"BTCUSDT\",\"ps\":\"BTCUSDT\",\"b\":\"79607.10\",\"B\":\"10.502\",\"a\":\"79607.20\",\"A\":\"1.161\",\"T\":1788563193331,\"E\":1788563193331,\"st\":1}}"}
{"receive_ns":1788563193296059000,"stream":"btcusdt@bookTicker","event_type":"bookTicker","event_time_ms":1788563193331,"raw_json":"{\"stream\":\"btcusdt@bookTicker\",\"data\":{\"e\":\"bookTicker\",\"u\":11478222497032,\"s\":\"BTCUSDT\",\"ps\":\"BTCUSDT\",\"b\":\"79607.10\",\"B\":\"10.494\",\"a\":\"79607.20\",\"A\":\"1.161\",\"T\":1788563193331,\"E\":1788563193331,\"st\":1}}"}
{"receive_ns":1788563193297220000,"stream":"btcusdt@bookTicker","event_type":"bookTicker","event_time_ms":1788563193332,"raw_json":"{\"stream\":\"btcusdt@bookTicker\",\"data\":{\"e\":\"bookTicker\",\"u\":11478222497116,\"s\":\"BTCUSDT\",\"ps\":\"BTCUSDT\",\"b\":\"79607.10\",\"B\":\"10.513\",\"a\":\"79607.20\",\"A\":\"1.161\",\"T\":1788563193332,\"E\":1788563193332,\"st\":1}}"}
{"receive_ns":1788563193297407000,"stream":"btcusdt@bookTicker","event_type":"bookTicker","event_time_ms":1788563193332,"raw_json":"{\"stream\":\"btcusdt@bookTicker\",\"data\":{\"e\":\"bookTicker\",\"u\":11478222497146,\"s\":\"BTCUSDT\",\"ps\":\"BTCUSDT\",\"b\":\"79607.10\",\"B\":\"10.521\",\"a\":\"79607.20\",\"A\":\"1.161\",\"T\":1788563193332,\"E\":1788563193332,\"st\":1}}"}
{"receive_ns":1788563193297618000,"stream":"btcusdt@bookTicker","event_type":"bookTicker","event_time_ms":1788563193333,"raw_json":"{\"stream\":\"btcusdt@bookTicker\",\"data\":{\"e\":\"bookTicker\",\"u\":11478222497186,\"s\":\"BTCUSDT\",\"ps\":\"BTCUSDT\",\"b\":\"79607.10\",\"B\":\"10.502\",\"a\":\"79607.20\",\"A\":\"1.161\",\"T\":1788563193332,\"E\":1788563193333,\"st\":1}}"}
