{"receive_ns":1788580699719728000,"stream":"btcusdt@depth@100ms","event_type":"depthUpdate","event_time_ms":1788580699757,"raw_json":"{\"stream\":\"btcusdt@depth@100ms\",\"data\":{\"e\":\"depthUpdate\",\"E\":1788580699757,\"T\":1788580699756,\"s\":\"BTCUSDT\",\"ps\":\"BTCUSDT\",\"U\":11479472691126,\"u\":11479472693803,\"pu\":11479472691108,\"b\":[[\"29243.90\",\"0.140\"],[\"29343.90\",\"1.883\"],[\"29443.90\",\"0.077\"],[\"63635.00\",\"0.000\"],[\"71589.50\",\"0.006\"],[\"78068.80\",\"7.251\"],[\"78390.50\",\"5.479\"],[\"78589.40\",\"16.072\"],[\"78748.50\",\"3.170\"],[\"78840.40\",\"11.336\"],[\"79332.10\",\"5.136\"],[\"79335.50\",\"1.179\"],[\"79379.80\",\"1.812\"],[\"79419.20\",\"0.378\"],[\"79480.30\",\"0.739\"],[\"79499.90\",\"0.004\"],[\"79540.60\",\"0.253\"],[\"79543.90\",\"6.440\"]],\"a\":[[\"79544.00\",\"5.291\"],[\"79574.40\",\"0.042\"],[\"79666.40\",\"0.349\"],[\"79705.80\",\"1.557\"],[\"79753.50\",\"5.608\"],[\"79939.70\",\"0.136\"],[\"80180.40\",\"1.742\"],[\"80339.40\",\"2.672\"],[\"80539.10\",\"4.314\"],[\"80896.20\",\"5.688\"]],\"st\":1}}"}
{"receive_ns":1788580699720009000,"stream":"btcusdt@bookTicker","event_type":"bookTicker","event_time_ms":1788580699757,"raw_json":"{\"stream\":\"btcusdt@bookTicker\",\"data\":{\"e\":\"bookTicker\",\"u\":11479472693823,\"s\":\"BTCUSDT\",\"ps\":\"BTCUSDT\",\"b\":\"79543.90\",\"B\":\"6.439\",\"a\":\"79544.00\",\"A\":\"5.291\",\"T\":1788580699756,\"E\":1788580699757,\"st\":1}}"}
{"receive_ns":1788580699720254000,"stream":"btcusdt@bookTicker","event_type":"bookTicker","event_time_ms":1788580699764,"raw_json":"{\"stream\":\"btcusdt@bookTicker\",\"data\":{\"e\":\"bookTicker\",\"u\":11479472694006,\"s\":\"BTCUSDT\",\"ps\":\"BTCUSDT\",\"b\":\"79543.90\",\"B\":\"6.441\",\"a\":\"79544.00\",\"A\":\"5.291\",\"T\":1788580699764,\"E\":1788580699764,\"st\":1}}"}
{"receive_ns":1788580699860741000,"stream":"btcusdt@depth@100ms","event_type":"depthUpdate","event_time_ms":1788580699859,"raw_json":"{\"stream\":\"btcusdt@depth@100ms\",\"data\":{\"e\":\"depthUpdate\",\"E\":1788580699859,\"T\":1788580699857,\"s\":\"BTCUSDT\",\"ps\":\"BTCUSDT\",\"U\":11479472693823,\"u\":11479472696700,\"pu\":11479472693803,\"b\":[[\"1000.00\",\"25.354\"],[\"29243.90\",\"0.245\"],[\"29343.90\",\"1.855\"],[\"29443.90\",\"0.000\"],[\"71589.50\",\"0.006\"],[\"76362.10\",\"0.000\"],[\"78589.40\",\"16.707\"],[\"78607.60\",\"0.004\"],[\"78609.10\",\"0.002\"],[\"78612.30\",\"0.003\"],[\"78619.50\",\"0.002\"],[\"78748.50\",\"3.170\"],[\"79140.90\",\"1.325\"],[\"79146.20\",\"3.025\"],[\"79480.30\",\"0.519\"],[\"79482.90\",\"0.586\"],[\"79539.90\",\"0.021\"],[\"79540.60\",\"0.252\"],[\"79543.90\",\"6.441\"]],\"a\":[[\"79620.40\",\"0.003\"],[\"79621.20\",\"0.002\"],[\"79936.40\",\"0.251\"],[\"79937.70\",\"0.004\"],[\"79939.70\",\"0.005\"],[\"80339.40\",\"2.672\"],[\"80720.30\",\"3.464\"]],\"st\":1}}"}
{"receive_ns":1788580699908179000,"stream":"btcusdt@depth@100ms","event_type":"depthUpdate","event_time_ms":1788580699961,"raw_json":"{\"stream\":\"btcusdt@depth@100ms\",\"data\":{\"e\":\"depthUpdate\",\"E\":1788580699961,\"T\":1788580699957,\"s\":\"BTCUSDT\",\"ps\":\"BTCUSDT\",\"U\":11479472696752,\"u\":11479472700408,\"pu\":11479472696700,\"b\":[[\"1000.00\",\"25.354\"],[\"29243.90\",\"0.420\"],[\"29343.90\",\"1.680\"],[\"71589.50\",\"0.006\"],[\"71623.00\",\"0.000\"],[\"76362.10\",\"0.002\"],[\"78452.60\",\"13.369\"],[\"78748.50\",\"3.170\"],[\"79456.40\",\"0.032\"],[\"79480.30\",\"0.785\"],[\"79482.90\",\"0.606\"],[\"79518.50\",\"0.452\"],[\"79518.80\",\"0.002\"],[\"79519.80\",\"0.000\"],[\"79524.90\",\"0.065\"],[\"79525.60\",\"0.047\"],[\"79526.70\",\"0.080\"],[\"79527.40\",\"0.018\"],[\"79527.80\",\"0.145\"],[\"79527.90\",\"0.073\"],[\"79528.40\",\"0.617\"],[\"79528.70\",\"0.301\"],[\"79529.40\",\"0.154\"],[\"79540.60\",\"0.252\"],[\"79541.40\",\"0.117\"]],\"a\":[[\"79564.90\",\"0.002\"],[\"79565.00\",\"1.264\"],[\"79565.30\",\"0.002\"],[\"79565.80\",\"0.442\"],[\"79566.20\",\"0.057\"],[\"79568.30\",\"0.405\"],[\"79569.20\",\"0.457\"],[\"79589.50\",\"0.383\"],[\"79589.60\",\"0.252\"],[\"79590.50\",\"0.249\"],[\"79621.50\",\"0.125\"],[\"79690.40\",\"0.006\"],[\"79933.80\",\"0.037\"],[\"79936.40\",\"0.258\"],[\"79937.70\",\"0.022\"],[\"79939.70\",\"0.131\"],[\"80339.40\",\"2.672\"]],\"st\":1}}"}
{"receive_ns":1788580699921577000,"stream":"btcusdt@bookTicker","event_type":"bookTicker","event_time_ms":1788580699977,"raw_json":"{\"stream\":\"btcusdt@bookTicker\",\"data\":{\"e\":\"bookTicker\",\"u\":11479472700970,\"s\":\"BTCUSDT\",\"ps\":\"BTCUSDT\",\"b\":\"79543.90\",\"B\":\"6.439\",\"a\":\"79544.00\",\"A\":\"5.291\",\"T\":1788580699977,\"E\":1788580699977,\"st\":1}}"}
{"receive_ns":1788580699921874000,"stream":"btcusdt@bookTicker","event_type":"bookTicker","event_time_ms":1788580699979,"raw_json":"{\"stream\":\"btcusdt@bookTicker\",\"data\":{\"e\":\"bookTicker\",\"u\":11479472701073,\"s\":\"BTCUSDT\",\"ps\":\"BTCUSDT\",\"b\":\"79543.90\",\"B\":\"6.440\",\"a\":\"79544.00\",\"A\":\"5.291\",\"T\":1788580699979,\"E\":1788580699979,\"st\":1}}"}
{"receive_ns":1788580700028064000,"stream":"btcusdt@bookTicker","event_type":"bookTicker","event_time_ms":1788580700059,"raw_json":"{\"stream\":\"btcusdt@bookTicker\",\"data\":{\"e\":\"bookTicker\",\"u\":11479472704961,\"s\":\"BTCUSDT\",\"ps\":\"BTCUSDT\",\"b\":\"79543.90\",\"B\":\"6.398\",\"a\":\"79544.00\",\"A\":\"5.291\",\"T\":1788580700059,\"E\":1788580700059,\"st\":1}}"}
{"receive_ns":1788580700028276000,"stream":"btcusdt@bookTicker","event_type":"bookTicker","event_time_ms":1788580700059,"raw_json":"{\"stream\":\"btcusdt@bookTicker\",\"data\":{\"e\":\"bookTicker\",\"u\":11479472704969,\"s\":\"BTCUSDT\",\"ps\":\"BTCUSDT\",\"b\":\"79543.90\",\"B\":\"5.202\",\"a\":\"79544.00\",\"A\":\"5.291\",\"T\":1788580700059,\"E\":1788580700059,\"st\":1}}"}
{"receive_ns":1788580700028400000,"stream":"btcusdt@bookTicker","event_type":"bookTicker","event_time_ms":1788580700059,"raw_json":"{\"stream\":\"btcusdt@bookTicker\",\"data\":{\"e\":\"bookTicker\",\"u\":11479472704999,\"s\":\"BTCUSDT\",\"ps\":\"BTCUSDT\",\"b\":\"79543.90\",\"B\":\"5.201\",\"a\":\"79544.00\",\"A\":\"5.291\",\"T\":1788580700059,\"E\":1788580700059,\"st\":1}}"}
{"receive_ns":1788580700028511000,"stream":"btcusdt@bookTicker","event_type":"bookTicker","event_time_ms":1788580700059,"raw_json":"{\"stream\":\"btcusdt@bookTicker\",\"data\":{\"e\":\"bookTicker\",\"u\":11479472705006,\"s\":\"BTCUSDT\",\"ps\":\"BTCUSDT\",\"b\":\"79543.90\",\"B\":\"5.199\",\"a\":\"79544.00\",\"A\":\"5.291\",\"T\":1788580700059,\"E\":1788580700059,\"st\":1}}"}
{"receive_ns":1788580700028646000,"stream":"btcusdt@bookTicker","event_type":"bookTicker","event_time_ms":1788580700060,"raw_json":"{\"stream\":\"btcusdt@bookTicker\",\"data\":{\"e\":\"bookTicker\",\"u\":11479472705169,\"s\":\"BTCUSDT\",\"ps\":\"BTCUSDT\",\"b\":\"79543.90\",\"B\":\"5.201\",\"a\":\"79544.00\",\"A\":\"5.291\",\"T\":1788580700060,\"E\":1788580700060,\"st\":1}}"}
{"receive_ns":1788580700028782000,"stream":"btcusdt@bookTicker","event_type":"bookTicker","event_time_ms":1788580700061,"raw_json":"{\"stream\":\"btcusdt@bookTicker\",\"data\":{\"e\":\"bookTicker\",\"u\":11479472705302,\"s\":\"BTCUSDT\",\"ps\":\"BTCUSDT\",\"b\":\"79543.90\",\"B\":\"5.245\",\"a\":\"79544.00\",\"A\":\"5.291\",\"T\":1788580700061,\"E\":1788580700061,\"st\":1}}"}
{"receive_ns":1788580700028891000,"stream":"btcusdt@bookTicker","event_type":"bookTicker","event_time_ms":1788580700061,"raw_json":"{\"stream\":\"btcusdt@bookTicker\",\"data\":{\"e\":\"bookTicker\",\"u\":11479472705355,\"s\":\"BTCUSDT\",\"ps\":\"BTCUSDT\",\"b\":\"79543.90\",\"B\":\"5.247\",\"a\":\"79544.00\",\"A\":\"5.291\",\"T\":1788580700061,\"E\":1788580700061,\"st\":1}}"}
{"receive_ns":1788580700029196000,"stream":"btcusdt@depth@100ms","event_type":"depthUpdate","event_time_ms":1788580700063,"raw_json":"{\"stream\":\"btcusdt@depth@100ms\",\"data\":{\"e\":\"depthUpdate\",\"E\":1788580700063,\"T\":1788580700062,\"s\":\"BTCUSDT\",\"ps\":\"BTCUSDT\",\"U\":11479472700505,\"u\":11479472705520,\"pu\":11479472700408,\"b\":[[\"29243.90\",\"0.595\"],[\"29343.90\",\"1.505\"],[\"63635.00\",\"0.000\"],[\"63635.10\",\"0.000\"],[\"71589.50\",\"0.006\"],[\"76362.10\",\"0.000\"],[\"78430.30\",\"14.900\"],[\"78748.50\",\"3.172\"],[\"79146.10\",\"0.008\"],[\"79146.20\",\"3.025\"],[\"79480.30\",\"0.795\"],[\"79520.20\",\"2.395\"],[\"79525.00\",\"0.375\"],[\"79525.50\",\"0.001\"],[\"79529.60\",\"0.002\"],[\"79538.20\",\"0.007\"],[\"79538.30\",\"0.002\"],[\"79539.70\",\"1.944\"],[\"79540.60\",\"0.252\"],[\"79543.90\",\"5.247\"]],\"a\":[[\"79560.10\",\"0.004\"],[\"79564.90\",\"0.441\"],[\"79565.00\",\"1.964\"],[\"79565.80\",\"0.003\"],[\"79591.80\",\"0.228\"],[\"79621.50\",\"0.000\"],[\"79621.70\",\"0.127\"],[\"79939.70\",\"0.136\"],[\"79941.80\",\"0.000\"],[\"80339.40\",\"2.674\"],[\"80424.80\",\"0.187\"],[\"80617.80\",\"0.681\"],[\"80720.30\",\"2.598\"],[\"80899.00\",\"0.355\"],[\"81134.80\",\"0.015\"]],\"st\":1}}"}
{"receive_ns":1788580700043390000,"stream":"btcusdt@bookTicker","event_type":"bookTicker","event_time_ms":1788580700100,"raw_json":"{\"stream\":\"btcusdt@bookTicker\",\"data\":{\"e\":\"bookTicker\",\"u\":11479472707761,\"s\":\"BTCUSDT\",\"ps\":\"BTCUSDT\",\"b\":\"79543.90\",\"B\":\"5.247\",\"a\":\"79544.00\",\"A\":\"5.288\",\"T\":1788580700100,\"E\":1788580700100,\"st\":1}}"}
{"receive_ns":1788580700090064000,"stream":"btcusdt@bookTicker","event_type":"bookTicker","event_time_ms":1788580700101,"raw_json":"{\"stream\":\"btcusdt@bookTicker\",\"data\":{\"e\":\"bookTicker\",\"u\":11479472707912,\"s\":\"BTCUSDT\",\"ps\":\"BTCUSDT\",\"b\":\"79543.90\",\"B\":\"5.243\",\"a\":\"79544.00\",\"A\":\"5.288\",\"T\":1788580700101,\"E\":1788580700101,\"st\":1}}"}
{"receive_ns":1788580700090258000,"stream":"btcusdt@bookTicker","event_type":"bookTicker","event_time_ms":1788580700105,"raw_json":"{\"stream\":\"btcusdt@bookTicker\",\"data\":{\"e\":\"bookTicker\",\"u\":11479472708339,\"s\":\"BTCUSDT\",\"ps\":\"BTCUSDT\",\"b\":\"79543.90\",\"B\":\"5.243\",\"a\":\"79544.00\",\"A\":\"5.291\",\"T\":1788580700105,\"E\":1788580700105,\"st\":1}}"}
{"receive_ns":1788580700090396000,"stream":"btcusdt@bookTicker","event_type":"bookTicker","event_time_ms":1788580700138,"raw_json":"{\"stream\":\"btcusdt@bookTicker\",\"data\":{\"e\":\"bookTicker\",\"u\":11479472710322,\"s\":\"BTCUSDT\",\"ps\":\"BTCUSDT\",\"b\":\"79543.90\",\"B\":\"5.243\",\"a\":\"79544.00\",\"A\":\"5.881\",\"T\":1788580700138,\"E\":1788580700138,\"st\":1}}"}
{"receive_ns":1788580700090559000,"stream":"btcusdt@bookTicker","event_type":"bookTicker","event_time_ms":1788580700140,"raw_json":"{\"stream\":\"btcusdt@bookTicker\",\"data\":{\"e\":\"bookTicker\",\"u\":11479472710363,\"s\":\"BTCUSDT\",\"ps\":\"BTCUSDT\",\"b\":\"79543.90\",\"B\":\"5.243\",\"a\":\"79544.00\",\"A\":\"5.880\",\"T\":1788580700139,\"E\":1788580700140,\"st\":1}}"}
{"receive_ns":1788580700090684000,"stream":"btcusdt@bookTicker","event_type":"bookTicker","event_time_ms":1788580700140,"raw_json":"{\"stream\":\"btcusdt@bookTicker\",\"data\":{\"e\":\"bookTicker\",\"u\":11479472710391,\"s\":\"BTCUSDT\",\"ps\":\"BTCUSDT\",\"b\":\"79543.90\",\"B\":\"5.243\",\"a\":\"79544.00\",\"A\":\"5.878\",\"T\":1788580700140,\"E\":1788580700140,\"st\":1}}"}
{"receive_ns":1788580700090916000,"stream":"btcusdt@bookTicker","event_type":"bookTicker","event_time_ms":1788580700141,"raw_json":"{\"stream\":\"btcusdt@bookTicker\",\"data\":{\"e\":\"bookTicker\",\"u\":11479472710448,\"s\":\"BTCUSDT\",\"ps\":\"BTCUSDT\",\"b\":\"79543.90\",\"B\":\"5.243\",\"a\":\"79544.00\",\"A\":\"5.879\",\"T\":1788580700141,\"E\":1788580700141,\"st\":1}}"}
{"receive_ns":1788580700108298000,"stream":"btcusdt@depth@100ms","event_type":"depthUpdate","event_time_ms":1788580700165,"raw_json":"{\"stream\":\"btcusdt@depth@100ms\",\"data\":{\"e\":\"depthUpdate\",\"E\":1788580700165,\"T\":1788580700164,\"s\":\"BTCUSDT\",\"ps\":\"BTCUSDT\",\"U\":11479472705537,\"u\":11479472711789,\"pu\":11479472705520,\"b\":[[\"1000.00\",\"25.354\"],[\"29243.90\",\"0.777\"],[\"29343.90\",\"1.323\"],[\"63635.00\",\"0.000\"],[\"71589.50\",\"0.006\"],[\"76362.10\",\"0.002\"],[\"78190.30\",\"1.111\"],[\"78748.50\",\"3.170\"],[\"78840.50\",\"11.547\"],[\"79146.10\",\"0.009\"],[\"79456.40\",\"0.032\"],[\"79468.20\",\"0.002\"],[\"79469.00\",\"0.050\"],[\"79480.30\",\"0.795\"],[\"79482.90\",\"0.606\"],[\"79486.80\",\"0.612\"],[\"79499.30\",\"0.000\"],[\"79499.90\",\"0.002\"],[\"79502.70\",\"0.038\"],[\"79539.60\",\"1.373\"],[\"79543.80\",\"0.085\"],[\"79543.90\",\"5.243\"]],\"a\":[[\"79544.00\",\"5.879\"],[\"79550.90\",\"0.011\"],[\"79551.50\",\"0.509\"],[\"79553.70\",\"0.311\"],[\"79554.20\",\"0.005\"],[\"79576.00\",\"4.527\"],[\"79576.10\",\"0.149\"],[\"79584.40\",\"0.051\"],[\"79584.50\",\"0.001\"],[\"79584.60\",\"0.561\"],[\"79589.20\",\"0.172\"],[\"79590.50\",\"0.203\"],[\"79595.60\",\"0.500\"],[\"79596.30\",\"3.607\"],[\"79605.50\",\"0.000\"],[\"79605.60\",\"0.061\"],[\"79605.70\",\"0.014\"],[\"79624.80\",\"1.751\"],[\"79625.40\",\"0.001\"],[\"79625.50\",\"0.002\"],[\"79625.60\",\"0.199\"],[\"79637.40\",\"0.001\"],[\"79637.50\",\"0.000\"],[\"79637.60\",\"0.013\"],[\"79639.90\",\"3.190\"],[\"79640.00\",\"3.639\"],[\"79640.10\",\"0.907\"],[\"79640.90\",\"0.000\"],[\"79641.00\",\"0.002\"],[\"79668.10\",\"0.007\"],[\"79693.60\",\"0.000\"],[\"79933.80\",\"0.037\"],[\"79936.40\",\"0.251\"],[\"79937.70\",\"0.022\"],[\"79939.70\",\"0.136\"],[\"79941.80\",\"0.001\"],[\"80259.90\",\"1.323\"],[\"80339.40\",\"2.672\"],[\"80697.40\",\"6.124\"],[\"81087.20\",\"0.001\"]],\"st\":1}}"}
{"receive_ns":1788580700210491000,"stream":"btcusdt@depth@100ms","event_type":"depthUpdate","event_time_ms":1788580700267,"raw_json":"{\"stream\":\"btcusdt@depth@100ms\",\"data\":{\"e\":\"depthUpdate\",\"E\":1788580700267,\"T\":1788580700266,\"s\":\"BTCUSDT\",\"ps\":\"BTCUSDT\",\"U\":11479472711825,\"u\":11479472717204,\"pu\":11479472711789,\"b\":[[\"1000.00\",\"25.354\"],[\"29243.90\",\"0.959\"],[\"29343.90\",\"1.141\"],[\"71589.50\",\"0.006\"],[\"78430.30\",\"16.810\"],[\"78748.50\",\"3.170\"],[\"79480.30\",\"0.795\"],[\"79482.00\",\"0.002\"],[\"79482.80\",\"1.722\"],[\"79517.30\",\"0.454\"],[\"79518.50\",\"0.000\"],[\"79524.10\",\"0.655\"],[\"79524.60\",\"3.602\"],[\"79525.00\",\"0.002\"],[\"79525.60\",\"0.001\"],[\"79526.90\",\"0.441\"],[\"79528.40\",\"0.177\"]],\"a\":[[\"79563.90\",\"0.441\"],[\"79564.00\",\"1.564\"],[\"79564.90\",\"0.002\"],[\"79565.00\",\"1.591\"],[\"79572.10\",\"0.186\"],[\"79572.60\",\"1.443\"],[\"79618.20\",\"0.003\"],[\"79620.00\",\"16.148\"],[\"79621.70\",\"0.002\"],[\"79623.00\",\"30.130\"],[\"79624.70\",\"0.514\"],[\"79624.90\",\"0.002\"],[\"79625.60\",\"0.200\"],[\"79628.30\",\"0.000\"],[\"79636.10\",\"0.078\"],[\"79636.20\",\"0.001\"],[\"79636.30\",\"0.004\"],[\"79641.00\",\"0.003\"],[\"79690.40\",\"0.000\"],[\"79936.40\",\"0.258\"],[\"79939.70\",\"0.136\"],[\"80339.40\",\"2.672\"],[\"80500.50\",\"0.000\"],[\"80538.30\",\"3.068\"],[\"80551.10\",\"6.638\"]],\"st\":1}}"}
{"receive_ns":1788580700229020000,"stream":"btcusdt@bookTicker","event_type":"bookTicker","event_time_ms":1788580700284,"raw_json":"{\"stream\":\"btcusdt@bookTicker\",\"data\":{\"e\":\"bookTicker\",\"u\":11479472718184,\"s\":\"BTCUSDT\",\"ps\":\"BTCUSDT\",\"b\":\"79543.90\",\"B\":\"5.242\",\"a\":\"79544.00\",\"A\":\"5.879\",\"T\":1788580700284,\"E\":1788580700284,\"st\":1}}"}
{"receive_ns":1788580700229238000,"stream":"btcusdt@bookTicker","event_type":"bookTicker","event_time_ms":1788580700285,"raw_json":"{\"stream\":\"btcusdt@bookTicker\",\"data\":{\"e\":\"bookTicker\",\"u\":11479472718242,\"s\":\"BTCUSDT\",\"ps\":\"BTCUSDT\",\"b\":\"79543.90\",\"B\":\"5.125\",\"a\":\"79544.00\",\"A\":\"5.879\",\"T\":1788580700285,\"E\":1788580700285,\"st\":1}}"}
{"receive_ns":1788580700231371000,"stream":"btcusdt@bookTicker","event_type":"bookTicker","event_time_ms":1788580700287,"raw_json":"{\"stream\":\"btcusdt@bookTicker\",\"data\":{\"e\":\"bookTicker\",\"u\":11479472718407,\"s\":\"BTCUSDT\",\"ps\":\"BTCUSDT\",\"b\":\"79543.90\",\"B\":\"5.266\",\"a\":\"79544.00\",\"A\":\"5.879\",\"T\":1788580700287,\"E\":1788580700287,\"st\":1}}"}
{"receive_ns":1788580700231691000,"stream":"btcusdt@bookTicker","event_type":"bookTicker","event_time_ms":1788580700288,"raw_json":"{\"stream\":\"btcusdt@bookTicker\",\"data\":{\"e\":\"bookTicker\",\"u\":11479472718452,\"s\":\"BTCUSDT\",\"ps\":\"BTCUSDT\",\"b\":\"79543.90\",\"B\":\"5.266\",\"a\":\"79544.00\",\"A\":\"5.881\",\"T\":1788580700288,\"E\":1788580700288,\"st\":1}}"}
{"receive_ns":1788580700231847000,"stream":"btcusdt@bookTicker","event_type":"bookTicker","event_time_ms":1788580700288,"raw_json":"{\"stream\":\"btcusdt@bookTicker\",\"data\":{\"e\":\"bookTicker\",\"u\":11479472718462,\"s\":\"BTCUSDT\",\"ps\":\"BTCUSDT\",\"b\":\"79543.90\",\"B\":\"5.265\",\"a\":\"79544.00\",\"A\":\"5.881\",\"T\":1788580700288,\"E\":1788580700288,\"st\":1}}"}
{"receive_ns":1788580700265728000,"stream":"btcusdt@bookTicker","event_type":"bookTicker","event_time_ms":1788580700301,"raw_json":"{\"stream\":\"btcusdt@bookTicker\",\"data\":{\"e\":\"bookTicker\",\"u\":11479472719098,\"s\":\"BTCUSDT\",\"ps\":\"BTCUSDT\",\"b\":\"79543.90\",\"B\":\"5.267\",\"a\":\"79544.00\",\"A\":\"5.881\",\"T\":1788580700301,\"E\":1788580700301,\"st\":1}}"}
{"receive_ns":1788580700265920000,"stream":"btcusdt@bookTicker","event_type":"bookTicker","event_time_ms":1788580700312,"raw_json":"{\"stream\":\"btcusdt@bookTicker\",\"data\":{\"e\":\"bookTicker\",\"u\":11479472719881,\"s\":\"BTCUSDT\",\"ps\":\"BTCUSDT\",\"b\":\"79543.90\",\"B\":\"5.266\",\"a\":\"79544.00\",\"A\":\"5.881\",\"T\":1788580700312,\"E\":1788580700312,\"st\":1}}"}
{"receive_ns":1788580700266096000,"stream":"btcusdt@bookTicker","event_type":"bookTicker","event_time_ms":1788580700315,"raw_json":"{\"stream\":\"btcusdt@bookTicker\",\"data\":{\"e\":\"bookTicker\",\"u\":11479472720040,\"s\":\"BTCUSDT\",\"ps\":\"BTCUSDT\",\"b\":\"79543.90\",\"B\":\"5.267\",\"a\":\"79544.00\",\"A\":\"5.881\",\"T\":1788580700314,\"E\":1788580700315,\"st\":1}}"}
{"receive_ns":1788580700328506000,"stream":"btcusdt@depth@100ms","event_type":"depthUpdate","event_time_ms":1788580700369,"raw_json":"{\"stream\":\"btcusdt@depth@100ms\",\"data\":{\"e\":\"depthUpdate\",\"E\":1788580700369,\"T\":1788580700367,\"s\":\"BTCUSDT\",\"ps\":\"BTCUSDT\",\"U\":11479472717270,\"u\":11479472722117,\"pu\":11479472717204,\"b\":[[\"29243.90\",\"1.134\"],[\"29343.90\",\"0.966\"],[\"63635.00\",\"0.000\"],[\"71589.50\",\"0.006\"],[\"76362.10\",\"0.000\"],[\"78549.60\",\"4.773\"],[\"78748.50\",\"3.170\"],[\"78827.90\",\"2.154\"],[\"78840.40\",\"10.449\"],[\"79146.20\",\"3.035\"],[\"79456.40\",\"0.000\"],[\"79480.30\",\"0.519\"],[\"79482.90\",\"0.586\"],[\"79486.70\",\"0.830\"],[\"79502.60\",\"1.259\"],[\"79524.10\",\"0.282\"],[\"79525.20\",\"0.373\"],[\"79526.90\",\"0.001\"],[\"79527.80\",\"0.585\"],[\"79543.90\",\"5.267\"]],\"a\":[[\"79544.00\",\"5.881\"],[\"79554.30\",\"0.005\"],[\"79554.50\",\"0.785\"],[\"79563.90\",\"0.002\"],[\"79564.00\",\"1.191\"],[\"79564.90\",\"0.441\"],[\"79565.20\",\"1.051\"],[\"79620.50\",\"0.000\"],[\"79620.70\",\"0.125\"],[\"79636.30\",\"0.005\"],[\"79690.40\",\"0.006\"],[\"79933.80\",\"0.000\"],[\"79936.40\",\"0.251\"],[\"79937.70\",\"0.004\"],[\"79939.70\",\"0.005\"],[\"80259.90\",\"1.510\"],[\"80339.40\",\"2.672\"],[\"80438.20\",\"0.000\"],[\"81047.40\",\"0.373\"],[\"81963.90\",\"0.000\"]],\"st\":1}}"}
{"receive_ns":1788580700394928000,"stream":"btcusdt@bookTicker","event_type":"bookTicker","event_time_ms":1788580700450,"raw_json":"{\"stream\":\"btcusdt@bookTicker\",\"data\":{\"e\":\"bookTicker\",\"u\":11479472725417,\"s\":\"BTCUSDT\",\"ps\":\"BTCUSDT\",\"b\":\"79543.90\",\"B\":\"6.441\",\"a\":\"79544.00\",\"A\":\"5.881\",\"T\":1788580700450,\"E\":1788580700450,\"st\":1}}"}
{"receive_ns":1788580700395167000,"stream":"btcusdt@bookTicker","event_type":"bookTicker","event_time_ms":1788580700450,"raw_json":"{\"stream\":\"btcusdt@bookTicker\",\"data\":{\"e\":\"bookTicker\",\"u\":11479472725437,\"s\":\"BTCUSDT\",\"ps\":\"BTCUSDT\",\"b\":\"79543.90\",\"B\":\"5.267\",\"a\":\"79544.00\",\"A\":\"5.881\",\"T\":1788580700450,\"E\":1788580700450,\"st\":1}}"}
{"receive_ns":1788580700395325000,"stream":"btcusdt@bookTicker","event_type":"bookTicker","event_time_ms":1788580700450,"raw_json":"{\"stream\":\"btcusdt@bookTicker\",\"data\":{\"e\":\"bookTicker\",\"u\":11479472725438,\"s\":\"BTCUSDT\",\"ps\":\"BTCUSDT\",\"b\":\"79543.90\",\"B\":\"5.223\",\"a\":\"79544.00\",\"A\":\"5.881\",\"T\":1788580700450,\"E\":1788580700450,\"st\":1}}"}
{"receive_ns":1788580700395506000,"stream":"btcusdt@bookTicker","event_type":"bookTicker","event_time_ms":1788580700450,"raw_json":"{\"stream\":\"btcusdt@bookTicker\",\"data\":{\"e\":\"bookTicker\",\"u\":11479472725447,\"s\":\"BTCUSDT\",\"ps\":\"BTCUSDT\",\"b\":\"79543.90\",\"B\":\"5.221\",\"a\":\"79544.00\",\"A\":\"5.881\",\"T\":1788580700450,\"E\":1788580700450,\"st\":1}}"}
{"receive_ns":1788580700395705000,"stream":"btcusdt@bookTicker","event_type":"bookTicker","event_time_ms":1788580700450,"raw_json":"{\"stream\":\"btcusdt@bookTicker\",\"data\":{\"e\":\"bookTicker\",\"u\":11479472725448,\"s\":\"BTCUSDT\",\"ps\":\"BTCUSDT\",\"b\":\"79543.90\",\"B\":\"5.219\",\"a\":\"79544.00\",\"A\":\"5.881\",\"T\":1788580700450,\"E\":1788580700450,\"st\":1}}"}
{"receive_ns":1788580700395891000,"stream":"btcusdt@bookTicker","event_type":"bookTicker","event_time_ms":1788580700451,"raw_json":"{\"stream\":\"btcusdt@bookTicker\",\"data\":{\"e\":\"bookTicker\",\"u\":11479472725610,\"s\":\"BTCUSDT\",\"ps\":\"BTCUSDT\",\"b\":\"79543.90\",\"B\":\"5.220\",\"a\":\"79544.00\",\"A\":\"5.881\",\"T\":1788580700451,\"E\":1788580700451,\"st\":1}}"}
{"receive_ns":1788580700396064000,"stream":"btcusdt@bookTicker","event_type":"bookTicker","event_time_ms":1788580700452,"raw_json":"{\"stream\":\"btcusdt@bookTicker\",\"data\":{\"e\":\"bookTicker\",\"u\":11479472725826,\"s\":\"BTCUSDT\",\"ps\":\"BTCUSDT\",\"b\":\"79543.90\",\"B\":\"5.221\",\"a\":\"79544.00\",\"A\":\"5.881\",\"T\":1788580700452,\"E\":1788580700452,\"st\":1}}"}
{"receive_ns":1788580700396237000,"stream":"btcusdt@bookTicker","event_type":"bookTicker","event_time_ms":1788580700452,"raw_json":"{\"stream\":\"btcusdt@bookTicker\",\"data\":{\"e\":\"bookTicker\",\"u\":11479472725856,\"s\":\"BTCUSDT\",\"ps\":\"BTCUSDT\",\"b\":\"79543.90\",\"B\":\"5.220\",\"a\":\"79544.00\",\"A\":\"5.881\",\"T\":1788580700452,\"E\":1788580700452,\"st\":1}}"}
{"receive_ns":1788580700396391000,"stream":"btcusdt@bookTicker","event_type":"bookTicker","event_time_ms":1788580700452,"raw_json":"{\"stream\":\"btcusdt@bookTicker\",\"data\":{\"e\":\"bookTicker\",\"u\":11479472726010,\"s\":\"BTCUSDT\",\"ps\":\"BTCUSDT\",\"b\":\"79543.90\",\"B\":\"5.270\",\"a\":\"79544.00\",\"A\":\"5.881\",\"T\":1788580700452,\"E\":1788580700452,\"st\":1}}"}
{"receive_ns":1788580700396848000,"stream":"btcusdt@bookTicker","event_type":"bookTicker","event_time_ms":1788580700453,"raw_json":"{\"stream\":\"btcusdt@bookTicker\",\"data\":{\"e\":\"bookTicker\",\"u\":11479472726177,\"s\":\"BTCUSDT\",\"ps\":\"BTCUSDT\",\"b\":\"79543.90\",\"B\":\"5.220\",\"a\":\"79544.00\",\"A\":\"5.881\",\"T\":1788580700453,\"E\":1788580700453,\"st\":1}}"}
{"receive_ns":1788580700399431000,"stream":"btcusdt@bookTicker","event_type":"bookTicker","event_time_ms":1788580700455,"raw_json":"{\"stream\":\"btcusdt@bookTicker\",\"data\":{\"e\":\"bookTicker\",\"u\":11479472726385,\"s\":\"BTCUSDT\",\"ps\":\"BTCUSDT\",\"b\":\"79543.90\",\"B\":\"5.219\",\"a\":\"79544.00\",\"A\":\"5.881\",\"T\":1788580700454,\"E\":1788580700455,\"st\":1}}"}
{"receive_ns":1788580700399662000,"stream":"btcusdt@bookTicker","event_type":"bookTicker","event_time_ms":1788580700456,"raw_json":"{\"stream\":\"btcusdt@bookTicker\",\"data\":{\"e\":\"bookTicker\",\"u\":11479472726542,\"s\":\"BTCUSDT\",\"ps\":\"BTCUSDT\",\"b\":\"79543.90\",\"B\":\"5.220\",\"a\":\"79544.00\",\"A\":\"5.881\",\"T\":1788580700456,\"E\":1788580700456,\"st\":1}}"}
{"receive_ns":1788580700414203000,"stream":"btcusdt@depth@100ms","event_type":"depthUpdate","event_time_ms":1788580700471,"raw_json":"{\"stream\":\"btcusdt@depth@100ms\",\"data\":{\"e\":\"depthUpdate\",\"E\":1788580700471,\"T\":1788580700469,\"s\":\"BTCUSDT\",\"ps\":\"BTCUSDT\",\"U\":11479472722219,\"u\":11479472727375,\"pu\":11479472722117,\"b\":[[\"1000.00\",\"25.354\"],[\"29243.90\",\"1.316\"],[\"29343.90\",\"0.784\"],[\"63635.00\",\"0.000\"],[\"71589.50\",\"0.006\"],[\"76362.10\",\"0.002\"],[\"77953.10\",\"0.012\"],[\"78748.50\",\"3.170\"],[\"79140.90\",\"1.199\"],[\"79379.80\",\"0.000\"],[\"79379.90\",\"1.796\"],[\"79419.20\",\"0.378\"],[\"79456.40\",\"0.010\"],[\"79480.30\",\"0.817\"],[\"79482.90\",\"0.586\"],[\"79486.70\",\"0.000\"],[\"79502.60\",\"0.568\"],[\"79539.60\",\"1.373\"],[\"79539.70\",\"1.944\"],[\"79543.80\",\"0.085\"],[\"79543.90\",\"5.220\"]],\"a\":[[\"79550.40\",\"0.033\"],[\"79550.60\",\"0.062\"],[\"79554.30\",\"0.003\"],[\"79554.50\",\"0.783\"],[\"79557.80\",\"0.001\"],[\"79573.70\",\"0.194\"],[\"79666.40\",\"0.367\"],[\"79705.70\",\"1.634\"],[\"79705.80\",\"0.007\"],[\"79933.80\",\"0.037\"],[\"79936.40\",\"0.258\"],[\"79937.70\",\"0.022\"],[\"79939.70\",\"0.136\"],[\"80339.40\",\"2.672\"]],\"st\":1}}"}
{"receive_ns":1788580700452543000,"stream":"btcusdt@bookTicker","event_type":"bookTicker","event_time_ms":1788580700503,"raw_json":"{\"stream\":\"btcusdt@bookTicker\",\"data\":{\"e\":\"bookTicker\",\"u\":11479472729016,\"s\":\"BTCUSDT\",\"ps\":\"BTCUSDT\",\"b\":\"79543.90\",\"B\":\"5.218\",\"a\":\"79544.00\",\"A\":\"5.881\",\"T\":1788580700503,\"E\":1788580700503,\"st\":1}}"}
{"receive_ns":1788580700453616000,"stream":"btcusdt@bookTicker","event_type":"bookTicker","event_time_ms":1788580700510,"raw_json":"{\"stream\":\"btcusdt@bookTicker\",\"data\":{\"e\":\"bookTicker\",\"u\":11479472729357,\"s\":\"BTCUSDT\",\"ps\":\"BTCUSDT\",\"b\":\"79543.90\",\"B\":\"5.219\",\"a\":\"79544.00\",\"A\":\"5.881\",\"T\":1788580700510,\"E\":1788580700510,\"st\":1}}"}
{"receive_ns":1788580700516011000,"stream":"btcusdt@depth@100ms","event_type":"depthUpdate","event_time_ms":1788580700573,"raw_json":"{\"stream\":\"btcusdt@depth@100ms\",\"data\":{\"e\":\"depthUpdate\",\"E\":1788580700573,\"T\":1788580700570,\"s\":\"BTCUSDT\",\"ps\":\"BTCUSDT\",\"U\":11479472727517,\"u\":11479472731489,\"pu\":11479472727375,\"b\":[[\"1000.00\",\"25.354\"],[\"29243.90\",\"1.491\"],[\"29343.90\",\"0.609\"],[\"71589.50\",\"0.006\"],[\"76362.10\",\"0.000\"],[\"78549.60\",\"5.058\"],[\"78562.00\",\"8.926\"],[\"78662.50\",\"0.264\"],[\"78748.50\",\"3.170\"],[\"79452.40\",\"0.050\"],[\"79517.30\",\"0.002\"],[\"79518.80\",\"0.454\"],[\"79539.70\",\"1.944\"],[\"79543.90\",\"5.219\"]],\"a\":[[\"79545.10\",\"0.002\"],[\"79547.50\",\"0.001\"],[\"79550.40\",\"0.095\"],[\"79550.60\",\"0.000\"],[\"79568.20\",\"0.453\"],[\"79569.20\",\"0.005\"],[\"79605.70\",\"0.018\"],[\"79620.30\",\"30.126\"],[\"79623.00\",\"0.009\"],[\"79624.90\",\"0.003\"],[\"79625.50\",\"0.003\"],[\"79635.90\",\"0.452\"],[\"79636.30\",\"0.006\"],[\"79637.60\",\"0.016\"],[\"79640.10\",\"0.910\"],[\"79641.00\",\"0.007\"],[\"79668.10\",\"0.013\"],[\"79693.60\",\"0.006\"],[\"79696.80\",\"1.704\"],[\"80339.40\",\"2.672\"],[\"80617.80\",\"1.299\"]],\"st\":1}}"}
{"receive_ns":1788580700520043000,"stream":"btcusdt@bookTicker","event_type":"bookTicker","event_time_ms":1788580700578,"raw_json":"{\"stream\":\"btcusdt@bookTicker\",\"data\":{\"e\":\"bookTicker\",\"u\":11479472731673,\"s\":\"BTCUSDT\",\"ps\":\"BTCUSDT\",\"b\":\"79543.90\",\"B\":\"5.219\",\"a\":\"79544.00\",\"A\":\"5.884\",\"T\":1788580700578,\"E\":1788580700578,\"st\":1}}"}
{"receive_ns":1788580700532895000,"stream":"btcusdt@bookTicker","event_type":"bookTicker","event_time_ms":1788580700588,"raw_json":"{\"stream\":\"btcusdt@bookTicker\",\"data\":{\"e\":\"bookTicker\",\"u\":11479472732041,\"s\":\"BTCUSDT\",\"ps\":\"BTCUSDT\",\"b\":\"79543.90\",\"B\":\"6.496\",\"a\":\"79544.00\",\"A\":\"5.884\",\"T\":1788580700588,\"E\":1788580700588,\"st\":1}}"}
{"receive_ns":1788580700533053000,"stream":"btcusdt@bookTicker","event_type":"bookTicker","event_time_ms":1788580700588,"raw_json":"{\"stream\":\"btcusdt@bookTicker\",\"data\":{\"e\":\"bookTicker\",\"u\":11479472732044,\"s\":\"BTCUSDT\",\"ps\":\"BTCUSDT\",\"b\":\"79543.90\",\"B\":\"6.536\",\"a\":\"79544.00\",\"A\":\"5.884\",\"T\":1788580700588,\"E\":1788580700588,\"st\":1}}"}
{"receive_ns":1788580700533209000,"stream":"btcusdt@bookTicker","event_type":"bookTicker","event_time_ms":1788580700589,"raw_json":"{\"stream\":\"btcusdt@bookTicker\",\"data\":{\"e\":\"bookTicker\",\"u\":11479472732112,\"s\":\"BTCUSDT\",\"ps\":\"BTCUSDT\",\"b\":\"79543.90\",\"B\":\"6.535\",\"a\":\"79544.00\",\"A\":\"5.884\",\"T\":1788580700589,\"E\":1788580700589,\"st\":1}}"}
{"receive_ns":1788580700576678000,"stream":"btcusdt@bookTicker","event_type":"bookTicker","event_time_ms":1788580700630,"raw_json":"{\"stream\":\"btcusdt@bookTicker\",\"data\":{\"e\":\"bookTicker\",\"u\":11479472736059,\"s\":\"BTCUSDT\",\"ps\":\"BTCUSDT\",\"b\":\"79543.90\",\"B\":\"6.535\",\"a\":\"79544.00\",\"A\":\"5.881\",\"T\":1788580700630,\"E\":1788580700630,\"st\":1}}"}
{"receive_ns":1788580700596545000,"stream":"btcusdt@bookTicker","event_type":"bookTicker","event_time_ms":1788580700652,"raw_json":"{\"stream\":\"btcusdt@bookTicker\",\"data\":{\"e\":\"bookTicker\",\"u\":11479472737317,\"s\":\"BTCUSDT\",\"ps\":\"BTCUSDT\",\"b\":\"79543.90\",\"B\":\"6.535\",\"a\":\"79544.00\",\"A\":\"5.635\",\"T\":1788580700651,\"E\":1788580700652,\"st\":1}}"}
{"receive_ns":1788580700596763000,"stream":"btcusdt@bookTicker","event_type":"bookTicker","event_time_ms":1788580700653,"raw_json":"{\"stream\":\"btcusdt@bookTicker\",\"data\":{\"e\":\"bookTicker\",\"u\":11479472737379,\"s\":\"BTCUSDT\",\"ps\":\"BTCUSDT\",\"b\":\"79543.90\",\"B\":\"6.536\",\"a\":\"79544.00\",\"A\":\"5.635\",\"T\":1788580700653,\"E\":1788580700653,\"st\":1}}"}
{"receive_ns":1788580700634609000,"stream":"btcusdt@depth@100ms","event_type":"depthUpdate","event_time_ms":1788580700675,"raw_json":"{\"stream\":\"btcusdt@depth@100ms\",\"data\":{\"e\":\"depthUpdate\",\"E\":1788580700675,\"T\":1788580700673,\"s\":\"BTCUSDT\",\"ps\":\"BTCUSDT\",\"U\":11479472731547,\"u\":11479472738316,\"pu\":11479472731489,\"b\":[[\"29243.90\",\"1.673\"],[\"29343.90\",\"0.427\"],[\"63635.00\",\"0.000\"],[\"71589.50\",\"0.006\"],[\"76362.10\",\"0.002\"],[\"78549.60\",\"5.249\"],[\"78748.50\",\"3.170\"],[\"79146.20\",\"3.035\"],[\"79398.80\",\"18.923\"],[\"79399.80\",\"0.005\"],[\"79400.00\",\"21.587\"],[\"79411.40\",\"0.126\"],[\"79412.00\",\"1.561\"],[\"79452.30\",\"2.921\"],[\"79456.40\",\"0.000\"],[\"79480.30\",\"0.509\"],[\"79488.20\",\"0.130\"],[\"79518.80\",\"0.002\"],[\"79519.30\",\"0.452\"],[\"79520.70\",\"0.012\"],[\"79524.60\",\"3.556\"],[\"79526.00\",\"0.128\"],[\"79527.40\",\"0.012\"],[\"79527.60\",\"0.004\"],[\"79527.80\",\"0.145\"],[\"79528.10\",\"0.147\"],[\"79528.40\",\"0.617\"],[\"79529.10\",\"0.229\"],[\"79529.30\",\"1.048\"],[\"79529.40\",\"0.160\"],[\"79529.80\",\"0.029\"],[\"79531.30\",\"0.263\"],[\"79531.80\",\"0.252\"],[\"79532.40\",\"0.000\"],[\"79532.70\",\"0.002\"],[\"79532.90\",\"0.171\"],[\"79534.00\",\"0.001\"],[\"79536.10\",\"0.004\"],[\"79538.20\",\"0.003\"],[\"79538.80\",\"1.006\"],[\"79539.30\",\"0.000\"],[\"79539.60\",\"1.372\"],[\"79539.70\",\"1.944\"],[\"79543.80\",\"0.086\"],[\"79543.90\",\"6.536\"]],\"a\":[[\"79544.00\",\"5.635\"],[\"79549.00\",\"0.003\"],[\"79550.40\",\"0.029\"],[\"79550.70\",\"0.018\"],[\"79550.90\",\"0.009\"],[\"79551.20\",\"0.004\"],[\"79551.30\",\"0.377\"],[\"79551.40\",\"0.367\"],[\"79553.70\",\"0.060\"],[\"79554.50\",\"0.155\"],[\"79554.90\",\"0.325\"],[\"79559.40\",\"0.628\"],[\"79562.10\",\"0.001\"],[\"79562.40\",\"0.004\"],[\"79562.70\",\"0.636\"],[\"79563.00\",\"0.103\"],[\"79564.90\",\"0.441\"],[\"79565.20\",\"0.678\"],[\"79565.70\",\"1.246\"],[\"79565.90\",\"0.000\"],[\"79566.70\",\"0.628\"],[\"79567.00\",\"0.003\"],[\"79568.10\",\"0.167\"],[\"79568.20\",\"0.001\"],[\"79570.10\",\"0.999\"],[\"79577.60\",\"0.080\"],[\"79578.90\",\"0.008\"],[\"79589.20\",\"0.126\"],[\"79589.80\",\"0.299\"],[\"79591.40\",\"0.063\"],[\"79615.60\",\"0.006\"],[\"79635.50\",\"3.909\"],[\"79668.20\",\"1.908\"],[\"79668.40\",\"0.015\"],[\"79688.00\",\"3.107\"],[\"79689.00\",\"17.578\"],[\"79690.40\",\"0.000\"],[\"79693.60\",\"0.000\"],[\"79696.80\",\"1.698\"],[\"79700.10\",\"0.000\"],[\"79701.50\",\"0.005\"],[\"79766.10\",\"19.770\"],[\"79766.20\",\"0.000\"],[\"79791.20\",\"19.542\"],[\"79791.80\",\"0.001\"],[\"79933.80\",\"0.000\"],[\"79936.40\",\"0.251\"],[\"79937.70\",\"0.004\"],[\"79939.70\",\"0.000\"],[\"80339.40\",\"2.672\"],[\"83515.60\",\"0.004\"]],\"st\":1}}"}
{"receive_ns":1788580700701991000,"stream":"btcusdt@bookTicker","event_type":"bookTicker","event_time_ms":1788580700737,"raw_json":"{\"stream\":\"btcusdt@bookTicker\",\"data\":{\"e\":\"bookTicker\",\"u\":11479472741027,\"s\":\"BTCUSDT\",\"ps\":\"BTCUSDT\",\"b\":\"79543.90\",\"B\":\"6.543\",\"a\":\"79544.00\",\"A\":\"5.635\",\"T\":1788580700737,\"E\":1788580700737,\"st\":1}}"}
{"receive_ns":1788580700702185000,"stream":"btcusdt@bookTicker","event_type":"bookTicker","event_time_ms":1788580700741,"raw_json":"{\"stream\":\"btcusdt@bookTicker\",\"data\":{\"e\":\"bookTicker\",\"u\":11479472741265,\"s\":\"BTCUSDT\",\"ps\":\"BTCUSDT\",\"b\":\"79543.90\",\"B\":\"6.542\",\"a\":\"79544.00\",\"A\":\"5.635\",\"T\":1788580700741,\"E\":1788580700741,\"st\":1}}"}
{"receive_ns":1788580700702352000,"stream":"btcusdt@bookTicker","event_type":"bookTicker","event_time_ms":1788580700745,"raw_json":"{\"stream\":\"btcusdt@bookTicker\",\"data\":{\"e\":\"bookTicker\",\"u\":11479472741518,\"s\":\"BTCUSDT\",\"ps\":\"BTCUSDT\",\"b\":\"79543.90\",\"B\":\"6.544\",\"a\":\"79544.00\",\"A\":\"5.635\",\"T\":1788580700745,\"E\":1788580700745,\"st\":1}}"}
{"receive_ns":1788580700720911000,"stream":"btcusdt@depth@100ms","event_type":"depthUpdate","event_time_ms":1788580700777,"raw_json":"{\"stream\":\"btcusdt@depth@100ms\",\"data\":{\"e\":\"depthUpdate\",\"E\":1788580700777,\"T\":1788580700776,\"s\":\"BTCUSDT\",\"ps\":\"BTCUSDT\",\"U\":11479472738345,\"u\":11479472742740,\"pu\":11479472738316,\"b\":[[\"1000.00\",\"25.354\"],[\"29143.90\",\"0.028\"],[\"29243.90\",\"1.785\"],[\"29343.90\",\"0.287\"],[\"65000.00\",\"523.457\"],[\"71589.50\",\"0.006\"],[\"78385.30\",\"6.728\"],[\"78594.30\",\"2.259\"],[\"78597.30\",\"0.002\"],[\"78623.90\",\"5.715\"],[\"78748.50\",\"3.170\"],[\"79453.10\",\"0.020\"],[\"79456.40\",\"0.318\"],[\"79474.60\",\"0.001\"],[\"79476.00\",\"1.485\"],[\"79477.20\",\"22.995\"],[\"79539.70\",\"1.945\"],[\"79543.90\",\"6.544\"]],\"a\":[[\"79549.00\",\"0.021\"],[\"79550.70\",\"0.380\"],[\"79551.20\",\"0.000\"],[\"79551.30\",\"0.001\"],[\"79572.10\",\"0.180\"],[\"79620.70\",\"0.000\"],[\"79786.60\",\"2.950\"],[\"79936.40\",\"0.258\"],[\"79937.70\",\"0.022\"],[\"79939.70\",\"0.168\"],[\"80180.40\",\"1.991\"],[\"80265.70\",\"0.187\"],[\"80339.40\",\"2.672\"],[\"80692.00\",\"9.406\"],[\"80720.30\",\"1.732\"]],\"st\":1}}"}
{"receive_ns":1788580700789092000,"stream":"btcusdt@bookTicker","event_type":"bookTicker","event_time_ms":1788580700779,"raw_json":"{\"stream\":\"btcusdt@bookTicker\",\"data\":{\"e\":\"bookTicker\",\"u\":11479472742810,\"s\":\"BTCUSDT\",\"ps\":\"BTCUSDT\",\"b\":\"79543.90\",\"B\":\"6.544\",\"a\":\"79544.00\",\"A\":\"5.045\",\"T\":1788580700778,\"E\":1788580700779,\"st\":1}}"}
{"receive_ns":1788580700790524000,"stream":"btcusdt@bookTicker","event_type":"bookTicker","event_time_ms":1788580700802,"raw_json":"{\"stream\":\"btcusdt@bookTicker\",\"data\":{\"e\":\"bookTicker\",\"u\":11479472745029,\"s\":\"BTCUSDT\",\"ps\":\"BTCUSDT\",\"b\":\"79543.90\",\"B\":\"6.543\",\"a\":\"79544.00\",\"A\":\"5.045\",\"T\":1788580700802,\"E\":1788580700802,\"st\":1}}"}
{"receive_ns":1788580700790716000,"stream":"btcusdt@bookTicker","event_type":"bookTicker","event_time_ms":1788580700810,"raw_json":"{\"stream\":\"btcusdt@bookTicker\",\"data\":{\"e\":\"bookTicker\",\"u\":11479472745994,\"s\":\"BTCUSDT\",\"ps\":\"BTCUSDT\",\"b\":\"79543.90\",\"B\":\"6.545\",\"a\":\"79544.00\",\"A\":\"5.045\",\"T\":1788580700810,\"E\":1788580700810,\"st\":1}}"}
{"receive_ns":1788580700800229000,"stream":"btcusdt@bookTicker","event_type":"bookTicker","event_time_ms":1788580700856,"raw_json":"{\"stream\":\"btcusdt@bookTicker\",\"data\":{\"e\":\"bookTicker\",\"u\":11479472750326,\"s\":\"BTCUSDT\",\"ps\":\"BTCUSDT\",\"b\":\"79543.90\",\"B\":\"6.544\",\"a\":\"79544.00\",\"A\":\"5.045\",\"T\":1788580700856,\"E\":1788580700856,\"st\":1}}"}
{"receive_ns":1788580700801029000,"stream":"btcusdt@bookTicker","event_type":"bookTicker","event_time_ms":1788580700858,"raw_json":"{\"stream\":\"btcusdt@bookTicker\",\"data\":{\"e\":\"bookTicker\",\"u\":11479472750416,\"s\":\"BTCUSDT\",\"ps\":\"BTCUSDT\",\"b\":\"79543.90\",\"B\":\"6.545\",\"a\":\"79544.00\",\"A\":\"5.045\",\"T\":1788580700858,\"E\":1788580700858,\"st\":1}}"}
{"receive_ns":1788580700859002000,"stream":"btcusdt@depth@100ms","event_type":"depthUpdate","event_time_ms":1788580700879,"raw_json":"{\"stream\":\"btcusdt@depth@100ms\",\"data\":{\"e\":\"depthUpdate\",\"E\":1788580700879,\"T\":1788580700878,\"s\":\"BTCUSDT\",\"ps\":\"BTCUSDT\",\"U\":11479472742744,\"u\":11479472751463,\"pu\":11479472742740,\"b\":[[\"1000.00\",\"25.354\"],[\"29143.90\",\"0.084\"],[\"29243.90\",\"1.855\"],[\"29343.90\",\"0.161\"],[\"71589.50\",\"0.006\"],[\"75561.80\",\"0.000\"],[\"75566.80\",\"0.002\"],[\"76362.10\",\"0.000\"],[\"78450.60\",\"0.000\"],[\"78562.00\",\"8.773\"],[\"78748.50\",\"3.170\"],[\"79146.20\",\"3.160\"],[\"79419.20\",\"0.002\"],[\"79419.30\",\"0.845\"],[\"79488.20\",\"0.128\"],[\"79499.70\",\"0.370\"],[\"79499.90\",\"0.004\"],[\"79504.10\",\"0.004\"],[\"79510.20\",\"0.324\"],[\"79525.20\",\"0.373\"],[\"79526.50\",\"0.003\"],[\"79529.80\",\"0.003\"],[\"79531.60\",\"0.000\"],[\"79539.70\",\"1.944\"],[\"79543.90\",\"6.545\"]],\"a\":[[\"79544.00\",\"5.045\"],[\"79545.10\",\"0.000\"],[\"79549.20\",\"0.448\"],[\"79550.70\",\"0.318\"],[\"79551.30\",\"0.063\"],[\"79551.40\",\"0.365\"],[\"79551.60\",\"0.006\"],[\"79564.90\",\"0.441\"],[\"79565.70\",\"0.873\"],[\"79566.40\",\"0.399\"],[\"79566.60\",\"0.205\"],[\"79577.70\",\"0.273\"],[\"79589.80\",\"0.253\"],[\"79590.60\",\"0.058\"],[\"79599.70\",\"0.052\"],[\"79615.60\",\"0.004\"],[\"79666.40\",\"0.437\"],[\"80339.40\",\"2.672\"],[\"80551.10\",\"6.360\"],[\"80670.40\",\"17.724\"]],\"st\":1}}"}
{"receive_ns":1788580700924370000,"stream":"btcusdt@depth@100ms","event_type":"depthUpdate","event_time_ms":1788580700981,"raw_json":"{\"stream\":\"btcusdt@depth@100ms\",\"data\":{\"e\":\"depthUpdate\",\"E\":1788580700981,\"T\":1788580700978,\"s\":\"BTCUSDT\",\"ps\":\"BTCUSDT\",\"U\":11479472751598,\"u\":11479472757689,\"pu\":11479472751463,\"b\":[[\"29143.90\",\"0.154\"],[\"29243.90\",\"1.897\"],[\"29343.90\",\"0.049\"],[\"63635.00\",\"0.000\"],[\"71589.50\",\"0.006\"],[\"75566.70\",\"0.015\"],[\"76362.10\",\"0.002\"],[\"78390.50\",\"6.371\"],[\"78611.70\",\"12.576\"],[\"78629.10\",\"1.633\"],[\"78748.50\",\"3.170\"],[\"79146.20\",\"3.150\"],[\"79453.10\",\"0.020\"],[\"79456.40\",\"0.318\"],[\"79528.60\",\"0.107\"],[\"79534.10\",\"0.000\"],[\"79538.50\",\"0.338\"],[\"79538.80\",\"1.004\"],[\"79539.70\",\"1.944\"],[\"79540.00\",\"0.005\"]],\"a\":[[\"79544.90\",\"0.064\"],[\"79545.00\",\"0.001\"],[\"79551.60\",\"0.004\"],[\"79551.80\",\"0.456\"],[\"79554.50\",\"0.783\"],[\"79559.40\",\"0.000\"],[\"79620.30\",\"30.126\"],[\"79620.60\",\"0.001\"],[\"79786.60\",\"2.945\"],[\"79933.80\",\"0.037\"],[\"79936.40\",\"0.258\"],[\"79937.70\",\"0.022\"],[\"79939.70\",\"0.136\"],[\"80339.40\",\"2.672\"],[\"80697.40\",\"6.990\"]],\"st\":1}}"}
{"receive_ns":1788580701050760000,"stream":"btcusdt@depth@100ms","event_type":"depthUpdate","event_time_ms":1788580701083,"raw_json":"{\"stream\":\"btcusdt@depth@100ms\",\"data\":{\"e\":\"depthUpdate\",\"E\":1788580701083,\"T\":1788580701082,\"s\":\"BTCUSDT\",\"ps\":\"BTCUSDT\",\"U\":11479472758026,\"u\":11479472763977,\"pu\":11479472757689,\"b\":[[\"1000.00\",\"25.354\"],[\"29143.90\",\"0.287\"],[\"29243.90\",\"1.813\"],[\"29343.90\",\"0.000\"],[\"63635.00\",\"0.000\"],[\"63635.10\",\"0.000\"],[\"71589.50\",\"0.006\"],[\"71623.00\",\"0.000\"],[\"76362.10\",\"0.000\"],[\"78438.20\",\"5.318\"],[\"78748.50\",\"3.170\"],[\"79520.20\",\"2.395\"],[\"79525.10\",\"0.410\"],[\"79525.20\",\"0.000\"],[\"79526.30\",\"0.003\"],[\"79528.40\",\"0.617\"],[\"79528.60\",\"0.081\"],[\"79529.40\",\"0.160\"],[\"79529.60\",\"0.002\"],[\"79539.70\",\"1.944\"]],\"a\":[[\"79560.10\",\"0.004\"],[\"79564.90\",\"0.002\"],[\"79565.00\",\"1.964\"],[\"79565.20\",\"0.678\"],[\"79565.60\",\"1.199\"],[\"79566.20\",\"0.057\"],[\"79566.40\",\"0.026\"],[\"79605.50\",\"0.002\"],[\"79620.70\",\"0.000\"],[\"79941.70\",\"1.498\"],[\"79952.60\",\"0.480\"],[\"79954.40\",\"0.249\"],[\"80339.40\",\"2.672\"],[\"80591.70\",\"0.004\"],[\"80670.40\",\"17.353\"],[\"81134.80\",\"0.012\"],[\"81209.00\",\"0.149\"]],\"st\":1}}"}
{"receive_ns":1788580701051959000,"stream":"btcusdt@bookTicker","event_type":"bookTicker","event_time_ms":1788580701108,"raw_json":"{\"stream\":\"btcusdt@bookTicker\",\"data\":{\"e\":\"bookTicker\",\"u\":11479472766665,\"s\":\"BTCUSDT\",\"ps\":\"BTCUSDT\",\"b\":\"79543.90\",\"B\":\"6.545\",\"a\":\"79544.00\",\"A\":\"5.048\",\"T\":1788580701108,\"E\":1788580701108,\"st\":1}}"}
{"receive_ns":1788580701113100000,"stream":"btcusdt@bookTicker","event_type":"bookTicker","event_time_ms":1788580701146,"raw_json":"{\"stream\":\"btcusdt@bookTicker\",\"data\":{\"e\":\"bookTicker\",\"u\":11479472769213,\"s\":\"BTCUSDT\",\"ps\":\"BTCUSDT\",\"b\":\"79543.90\",\"B\":\"6.505\",\"a\":\"79544.00\",\"A\":\"5.048\",\"T\":1788580701146,\"E\":1788580701146,\"st\":1}}"}
{"receive_ns":1788580701113843000,"stream":"btcusdt@bookTicker","event_type":"bookTicker","event_time_ms":1788580701164,"raw_json":"{\"stream\":\"btcusdt@bookTicker\",\"data\":{\"e\":\"bookTicker\",\"u\":11479472769910,\"s\":\"BTCUSDT\",\"ps\":\"BTCUSDT\",\"b\":\"79543.90\",\"B\":\"6.505\",\"a\":\"79544.00\",\"A\":\"5.022\",\"T\":1788580701163,\"E\":1788580701164,\"st\":1}}"}
{"receive_ns":1788580701114065000,"stream":"btcusdt@bookTicker","event_type":"bookTicker","event_time_ms":1788580701167,"raw_json":"{\"stream\":\"btcusdt@bookTicker\",\"data\":{\"e\":\"bookTicker\",\"u\":11479472770085,\"s\":\"BTCUSDT\",\"ps\":\"BTCUSDT\",\"b\":\"79543.90\",\"B\":\"6.505\",\"a\":\"79544.00\",\"A\":\"5.053\",\"T\":1788580701166,\"E\":1788580701167,\"st\":1}}"}
{"receive_ns":1788580701128861000,"stream":"btcusdt@depth@100ms","event_type":"depthUpdate","event_time_ms":1788580701185,"raw_json":"{\"stream\":\"btcusdt@depth@100ms\",\"data\":{\"e\":\"depthUpdate\",\"E\":1788580701185,\"T\":1788580701182,\"s\":\"BTCUSDT\",\"ps\":\"BTCUSDT\",\"U\":11479472764039,\"u\":11479472770630,\"pu\":11479472763977,\"b\":[[\"1000.00\",\"25.354\"],[\"29143.90\",\"0.462\"],[\"29243.90\",\"1.638\"],[\"63635.00\",\"0.000\"],[\"71589.50\",\"0.006\"],[\"77300.00\",\"12.947\"],[\"78425.10\",\"31.857\"],[\"78611.70\",\"11.306\"],[\"78748.50\",\"3.170\"],[\"79146.10\",\"0.009\"],[\"79419.30\",\"0.408\"],[\"79453.10\",\"0.020\"],[\"79456.40\",\"0.318\"],[\"79488.20\",\"0.130\"],[\"79534.80\",\"0.022\"],[\"79538.00\",\"0.003\"],[\"79543.90\",\"6.505\"]],\"a\":[[\"79544.00\",\"5.053\"],[\"79550.40\",\"0.033\"],[\"79550.70\",\"0.314\"],[\"79615.60\",\"0.006\"],[\"79619.80\",\"0.000\"],[\"79620.60\",\"0.001\"],[\"79621.10\",\"0.000\"],[\"79624.70\",\"0.515\"],[\"79625.30\",\"0.001\"],[\"79625.40\",\"0.002\"],[\"79636.20\",\"0.002\"],[\"79637.40\",\"0.004\"],[\"79639.90\",\"3.193\"],[\"79640.90\",\"0.002\"],[\"79666.40\",\"0.000\"],[\"79784.60\",\"0.005\"],[\"79933.80\",\"0.000\"],[\"79936.40\",\"0.258\"],[\"79937.70\",\"0.059\"],[\"79939.70\",\"0.131\"],[\"79941.80\",\"0.001\"],[\"80339.40\",\"2.672\"],[\"80419.00\",\"2.359\"],[\"80493.20\",\"17.744\"],[\"80652.20\",\"34.807\"],[\"81134.80\",\"0.015\"]],\"st\":1}}"}
{"receive_ns":1788580701171897000,"stream":"btcusdt@bookTicker","event_type":"bookTicker","event_time_ms":1788580701206,"raw_json":"{\"stream\":\"btcusdt@bookTicker\",\"data\":{\"e\":\"bookTicker\",\"u\":11479472771731,\"s\":\"BTCUSDT\",\"ps\":\"BTCUSDT\",\"b\":\"79543.90\",\"B\":\"6.505\",\"a\":\"79544.00\",\"A\":\"5.040\",\"T\":1788580701206,\"E\":1788580701206,\"st\":1}}"}
{"receive_ns":1788580701172095000,"stream":"btcusdt@bookTicker","event_type":"bookTicker","event_time_ms":1788580701208,"raw_json":"{\"stream\":\"btcusdt@bookTicker\",\"data\":{\"e\":\"bookTicker\",\"u\":11479472771936,\"s\":\"BTCUSDT\",\"ps\":\"BTCUSDT\",\"b\":\"79543.90\",\"B\":\"6.503\",\"a\":\"79544.00\",\"A\":\"5.040\",\"T\":1788580701208,\"E\":1788580701208,\"st\":1}}"}
{"receive_ns":1788580701172243000,"stream":"btcusdt@bookTicker","event_type":"bookTicker","event_time_ms":1788580701210,"raw_json":"{\"stream\":\"btcusdt@bookTicker\",\"data\":{\"e\":\"bookTicker\",\"u\":11479472772010,\"s\":\"BTCUSDT\",\"ps\":\"BTCUSDT\",\"b\":\"79543.90\",\"B\":\"6.503\",\"a\":\"79544.00\",\"A\":\"5.054\",\"T\":1788580701209,\"E\":1788580701210,\"st\":1}}"}
{"receive_ns":1788580701172419000,"stream":"btcusdt@bookTicker","event_type":"bookTicker","event_time_ms":1788580701217,"raw_json":"{\"stream\":\"btcusdt@bookTicker\",\"data\":{\"e\":\"bookTicker\",\"u\":11479472772342,\"s\":\"BTCUSDT\",\"ps\":\"BTCUSDT\",\"b\":\"79543.90\",\"B\":\"6.504\",\"a\":\"79544.00\",\"A\":\"5.054\",\"T\":1788580701217,\"E\":1788580701217,\"st\":1}}"}
{"receive_ns":1788580701225279000,"stream":"btcusdt@bookTicker","event_type":"bookTicker","event_time_ms":1788580701260,"raw_json":"{\"stream\":\"btcusdt@bookTicker\",\"data\":{\"e\":\"bookTicker\",\"u\":11479472774691,\"s\":\"BTCUSDT\",\"ps\":\"BTCUSDT\",\"b\":\"79543.90\",\"B\":\"6.504\",\"a\":\"79544.00\",\"A\":\"5.051\",\"T\":1788580701260,\"E\":1788580701260,\"st\":1}}"}
{"receive_ns":1788580701225525000,"stream":"btcusdt@bookTicker","event_type":"bookTicker","event_time_ms":1788580701263,"raw_json":"{\"stream\":\"btcusdt@bookTicker\",\"data\":{\"e\":\"bookTicker\",\"u\":11479472774816,\"s\":\"BTCUSDT\",\"ps\":\"BTCUSDT\",\"b\":\"79543.90\",\"B\":\"6.504\",\"a\":\"79544.00\",\"A\":\"5.055\",\"T\":1788580701263,\"E\":1788580701263,\"st\":1}}"}
{"receive_ns":1788580701239246000,"stream":"btcusdt@depth@100ms","event_type":"depthUpdate","event_time_ms":1788580701287,"raw_json":"{\"stream\":\"btcusdt@depth@100ms\",\"data\":{\"e\":\"depthUpdate\",\"E\":1788580701287,\"T\":1788580701285,\"s\":\"BTCUSDT\",\"ps\":\"BTCUSDT\",\"U\":11479472770922,\"u\":11479472775947,\"pu\":11479472770630,\"b\":[[\"29143.90\",\"0.644\"],[\"29243.90\",\"1.456\"],[\"71589.50\",\"0.006\"],[\"76362.10\",\"0.002\"],[\"78509.60\",\"0.891\"],[\"78562.00\",\"8.557\"],[\"78748.50\",\"3.170\"],[\"79146.20\",\"3.150\"],[\"79419.30\",\"0.845\"],[\"79456.40\",\"0.318\"],[\"79478.80\",\"4.558\"],[\"79525.00\",\"0.375\"],[\"79525.10\",\"0.037\"],[\"79526.10\",\"0.000\"],[\"79528.40\",\"0.617\"],[\"79529.40\",\"0.160\"],[\"79538.40\",\"0.058\"],[\"79538.80\",\"1.002\"],[\"79543.90\",\"6.504\"]],\"a\":[[\"79544.00\",\"5.055\"],[\"79550.40\",\"0.033\"],[\"79550.60\",\"0.000\"],[\"79564.90\",\"0.375\"],[\"79565.00\",\"1.591\"],[\"79566.10\",\"0.000\"],[\"79572.60\",\"1.449\"],[\"79584.10\",\"0.930\"],[\"79620.00\",\"20.633\"],[\"79620.10\",\"0.446\"],[\"79621.10\",\"0.000\"],[\"79624.70\",\"0.516\"],[\"79637.40\",\"0.007\"],[\"79666.40\",\"0.437\"],[\"79668.10\",\"0.007\"],[\"79753.40\",\"1.477\"],[\"79753.50\",\"4.900\"],[\"79939.70\",\"0.131\"],[\"80339.40\",\"2.672\"],[\"80511.30\",\"16.028\"],[\"80851.10\",\"1.421\"],[\"82095.00\",\"0.000\"]],\"st\":1}}"}
{"receive_ns":1788580701311256000,"stream":"btcusdt@bookTicker","event_type":"bookTicker","event_time_ms":1788580701367,"raw_json":"{\"stream\":\"btcusdt@bookTicker\",\"data\":{\"e\":\"bookTicker\",\"u\":11479472780380,\"s\":\"BTCUSDT\",\"ps\":\"BTCUSDT\",\"b\":\"79543.90\",\"B\":\"6.503\",\"a\":\"79544.00\",\"A\":\"5.055\",\"T\":1788580701366,\"E\":1788580701367,\"st\":1}}"}
{"receive_ns":1788580701313321000,"stream":"btcusdt@bookTicker","event_type":"bookTicker","event_time_ms":1788580701368,"raw_json":"{\"stream\":\"btcusdt@bookTicker\",\"data\":{\"e\":\"bookTicker\",\"u\":11479472780576,\"s\":\"BTCUSDT\",\"ps\":\"BTCUSDT\",\"b\":\"79543.90\",\"B\":\"6.504\",\"a\":\"79544.00\",\"A\":\"5.055\",\"T\":1788580701368,\"E\":1788580701368,\"st\":1}}"}
{"receive_ns":1788580701353172000,"stream":"btcusdt@depth@100ms","event_type":"depthUpdate","event_time_ms":1788580701389,"raw_json":"{\"stream\":\"btcusdt@depth@100ms\",\"data\":{\"e\":\"depthUpdate\",\"E\":1788580701389,\"T\":1788580701385,\"s\":\"BTCUSDT\",\"ps\":\"BTCUSDT\",\"U\":11479472776127,\"u\":11479472781326,\"pu\":11479472775947,\"b\":[[\"1000.00\",\"25.354\"],[\"29143.90\",\"0.819\"],[\"29243.90\",\"1.281\"],[\"71589.50\",\"0.006\"],[\"76362.10\",\"0.000\"],[\"78748.50\",\"3.170\"],[\"79146.20\",\"3.276\"],[\"79419.30\",\"0.784\"],[\"79453.10\",\"0.000\"],[\"79456.40\",\"0.010\"],[\"79486.70\",\"0.830\"],[\"79502.60\",\"1.259\"],[\"79528.60\",\"0.107\"],[\"79538.60\",\"0.440\"],[\"79543.90\",\"6.504\"]],\"a\":[[\"79557.80\",\"0.692\"],[\"79573.70\",\"1.024\"],[\"79620.30\",\"0.005\"],[\"79620.60\",\"0.001\"],[\"79623.00\",\"0.009\"],[\"79628.30\",\"30.018\"],[\"79666.40\",\"0.375\"],[\"79784.60\",\"0.000\"],[\"79936.40\",\"0.126\"],[\"79937.70\",\"0.004\"],[\"79939.70\",\"0.005\"],[\"79941.70\",\"2.123\"],[\"80339.40\",\"2.672\"],[\"80400.00\",\"38.170\"],[\"80655.80\",\"0.001\"],[\"80856.50\",\"1.730\"]],\"st\":1}}"}
{"receive_ns":1788580701353436000,"stream":"btcusdt@bookTicker","event_type":"bookTicker","event_time_ms":1788580701397,"raw_json":"{\"stream\":\"btcusdt@bookTicker\",\"data\":{\"e\":\"bookTicker\",\"u\":11479472781831,\"s\":\"BTCUSDT\",\"ps\":\"BTCUSDT\",\"b\":\"79543.90\",\"B\":\"6.504\",\"a\":\"79544.00\",\"A\":\"5.026\",\"T\":1788580701397,\"E\":1788580701397,\"st\":1}}"}
{"receive_ns":1788580701353617000,"stream":"btcusdt@bookTicker","event_type":"bookTicker","event_time_ms":1788580701400,"raw_json":"{\"stream\":\"btcusdt@bookTicker\",\"data\":{\"e\":\"bookTicker\",\"u\":11479472781982,\"s\":\"BTCUSDT\",\"ps\":\"BTCUSDT\",\"b\":\"79543.90\",\"B\":\"6.504\",\"a\":\"79544.00\",\"A\":\"5.056\",\"T\":1788580701400,\"E\":1788580701400,\"st\":1}}"}
{"receive_ns":1788580701370607000,"stream":"btcusdt@bookTicker","event_type":"bookTicker","event_time_ms":1788580701426,"raw_json":"{\"stream\":\"btcusdt@bookTicker\",\"data\":{\"e\":\"bookTicker\",\"u\":11479472783187,\"s\":\"BTCUSDT\",\"ps\":\"BTCUSDT\",\"b\":\"79543.90\",\"B\":\"6.503\",\"a\":\"79544.00\",\"A\":\"5.056\",\"T\":1788580701426,\"E\":1788580701426,\"st\":1}}"}
{"receive_ns":1788580701409083000,"stream":"btcusdt@bookTicker","event_type":"bookTicker","event_time_ms":1788580701434,"raw_json":"{\"stream\":\"btcusdt@bookTicker\",\"data\":{\"e\":\"bookTicker\",\"u\":11479472783596,\"s\":\"BTCUSDT\",\"ps\":\"BTCUSDT\",\"b\":\"79543.90\",\"B\":\"6.505\",\"a\":\"79544.00\",\"A\":\"5.056\",\"T\":1788580701434,\"E\":1788580701434,\"st\":1}}"}
{"receive_ns":1788580701435112000,"stream":"btcusdt@depth@100ms","event_type":"depthUpdate","event_time_ms":1788580701491,"raw_json":"{\"stream\":\"btcusdt@depth@100ms\",\"data\":{\"e\":\"depthUpdate\",\"E\":1788580701491,\"T\":1788580701490,\"s\":\"BTCUSDT\",\"ps\":\"BTCUSDT\",\"U\":11479472781481,\"u\":11479472786751,\"pu\":11479472781326,\"b\":[[\"1000.00\",\"25.354\"],[\"29143.90\",\"1.001\"],[\"29243.90\",\"1.099\"],[\"71589.50\",\"0.006\"],[\"76362.10\",\"0.002\"],[\"78056.40\",\"1.151\"],[\"78430.30\",\"18.720\"],[\"78452.60\",\"11.459\"],[\"78748.50\",\"3.170\"],[\"78827.90\",\"3.041\"],[\"79448.40\",\"0.018\"],[\"79452.30\",\"2.963\"],[\"79453.10\",\"0.020\"],[\"79456.40\",\"0.318\"],[\"79539.70\",\"1.944\"],[\"79543.90\",\"6.505\"]],\"a\":[[\"79544.00\",\"5.056\"],[\"79563.00\",\"0.027\"],[\"79620.00\",\"16.148\"],[\"79620.80\",\"0.126\"],[\"79623.00\",\"30.027\"],[\"79625.60\",\"0.200\"],[\"79628.30\",\"0.000\"],[\"79635.40\",\"3.870\"],[\"79635.50\",\"0.000\"],[\"79668.10\",\"0.013\"],[\"79766.00\",\"19.359\"],[\"79766.10\",\"0.031\"],[\"79871.00\",\"0.000\"],[\"79936.40\",\"0.133\"],[\"79939.70\",\"0.191\"],[\"80339.40\",\"2.672\"],[\"80498.50\",\"19.597\"],[\"80538.30\",\"3.217\"],[\"80657.60\",\"19.386\"],[\"81200.00\",\"24.305\"]],\"st\":1}}"}
{"receive_ns":1788580701536961000,"stream":"btcusdt@depth@100ms","event_type":"depthUpdate","event_time_ms":1788580701593,"raw_json":"{\"stream\":\"btcusdt@depth@100ms\",\"data\":{\"e\":\"depthUpdate\",\"E\":1788580701593,\"T\":1788580701591,\"s\":\"BTCUSDT\",\"ps\":\"BTCUSDT\",\"U\":11479472786829,\"u\":11479472792079,\"pu\":11479472786751,\"b\":[[\"29143.90\",\"1.176\"],[\"29243.90\",\"0.924\"],[\"71589.50\",\"0.006\"],[\"76362.10\",\"0.000\"],[\"77991.30\",\"0.000\"],[\"78430.30\",\"20.630\"],[\"78748.50\",\"3.170\"],[\"78977.00\",\"3.870\"],[\"79146.20\",\"3.286\"],[\"79419.30\",\"0.408\"],[\"79518.70\",\"0.591\"],[\"79519.30\",\"0.000\"],[\"79531.50\",\"0.254\"],[\"79531.80\",\"0.001\"],[\"79539.70\",\"1.944\"]],\"a\":[[\"79550.40\",\"0.091\"],[\"79550.60\",\"0.004\"],[\"79551.30\",\"0.001\"],[\"79553.90\",\"0.253\"],[\"79554.90\",\"0.074\"],[\"79568.20\",\"0.453\"],[\"79570.10\",\"0.547\"],[\"79577.50\",\"0.272\"],[\"79578.90\",\"0.002\"],[\"79619.40\",\"6.166\"],[\"79666.40\",\"0.000\"],[\"80339.40\",\"2.672\"],[\"80601.00\",\"1.859\"]],\"st\":1}}"}
{"receive_ns":1788580701596985000,"stream":"btcusdt@bookTicker","event_type":"bookTicker","event_time_ms":1788580701652,"raw_json":"{\"stream\":\"btcusdt@bookTicker\",\"data\":{\"e\":\"bookTicker\",\"u\":11479472794958,\"s\":\"BTCUSDT\",\"ps\":\"BTCUSDT\",\"b\":\"79543.90\",\"B\":\"6.503\",\"a\":\"79544.00\",\"A\":\"5.056\",\"T\":1788580701651,\"E\":1788580701652,\"st\":1}}"}
{"receive_ns":1788580701597735000,"stream":"btcusdt@bookTicker","event_type":"bookTicker","event_time_ms":1788580701654,"raw_json":"{\"stream\":\"btcusdt@bookTicker\",\"data\":{\"e\":\"bookTicker\",\"u\":11479472795125,\"s\":\"BTCUSDT\",\"ps\":\"BTCUSDT\",\"b\":\"79543.90\",\"B\":\"6.323\",\"a\":\"79544.00\",\"A\":\"5.056\",\"T\":1788580701654,\"E\":1788580701654,\"st\":1}}"}
{"receive_ns":1788580701601563000,"stream":"btcusdt@bookTicker","event_type":"bookTicker","event_time_ms":1788580701657,"raw_json":"{\"stream\":\"btcusdt@bookTicker\",\"data\":{\"e\":\"bookTicker\",\"u\":11479472795295,\"s\":\"BTCUSDT\",\"ps\":\"BTCUSDT\",\"b\":\"79543.90\",\"B\":\"6.502\",\"a\":\"79544.00\",\"A\":\"5.056\",\"T\":1788580701657,\"E\":1788580701657,\"st\":1}}"}
{"receive_ns":1788580701601956000,"stream":"btcusdt@bookTicker","event_type":"bookTicker","event_time_ms":1788580701657,"raw_json":"{\"stream\":\"btcusdt@bookTicker\",\"data\":{\"e\":\"bookTicker\",\"u\":11479472795311,\"s\":\"BTCUSDT\",\"ps\":\"BTCUSDT\",\"b\":\"79543.90\",\"B\":\"6.503\",\"a\":\"79544.00\",\"A\":\"5.056\",\"T\":1788580701657,\"E\":1788580701657,\"st\":1}}"}
{"receive_ns":1788580701658286000,"stream":"btcusdt@depth@100ms","event_type":"depthUpdate","event_time_ms":1788580701695,"raw_json":"{\"stream\":\"btcusdt@depth@100ms\",\"data\":{\"e\":\"depthUpdate\",\"E\":1788580701695,\"T\":1788580701694,\"s\":\"BTCUSDT\",\"ps\":\"BTCUSDT\",\"U\":11479472792161,\"u\":11479472796487,\"pu\":11479472792079,\"b\":[[\"1000.00\",\"25.354\"],[\"29143.90\",\"1.358\"],[\"29243.90\",\"0.742\"],[\"71589.50\",\"0.006\"],[\"78743.20\",\"5.643\"],[\"78748.50\",\"3.170\"],[\"79146.80\",\"0.087\"],[\"79379.90\",\"0.001\"],[\"79453.10\",\"0.020\"],[\"79456.40\",\"0.258\"],[\"79474.60\",\"22.943\"],[\"79477.20\",\"0.027\"],[\"79478.80\",\"1.282\"],[\"79480.30\",\"0.559\"],[\"79502.60\",\"0.568\"],[\"79539.70\",\"1.944\"],[\"79542.60\",\"0.003\"],[\"79543.80\",\"0.085\"],[\"79543.90\",\"6.503\"]],\"a\":[[\"79550.40\",\"0.091\"],[\"79550.60\",\"0.004\"],[\"79562.40\",\"0.080\"],[\"79619.40\",\"6.166\"],[\"79620.20\",\"0.133\"],[\"79705.70\",\"0.000\"],[\"79936.40\",\"0.133\"],[\"79937.70\",\"0.059\"],[\"79939.70\",\"0.131\"],[\"80339.40\",\"2.672\"],[\"80493.20\",\"17.372\"],[\"87498.40\",\"0.001\"]],\"st\":1}}"}
{"receive_ns":1788580701784969000,"stream":"btcusdt@depth@100ms","event_type":"depthUpdate","event_time_ms":1788580701797,"raw_json":"{\"stream\":\"btcusdt@depth@100ms\",\"data\":{\"e\":\"depthUpdate\",\"E\":1788580701797,\"T\":1788580701793,\"s\":\"BTCUSDT\",\"ps\":\"BTCUSDT\",\"U\":11479472796521,\"u\":11479472799932,\"pu\":11479472796487,\"b\":[[\"1000.00\",\"25.354\"],[\"29143.90\",\"1.533\"],[\"29243.90\",\"0.567\"],[\"71589.50\",\"0.006\"],[\"76362.10\",\"0.002\"],[\"77953.00\",\"5.135\"],[\"78385.30\",\"5.836\"],[\"78584.10\",\"25.706\"],[\"78589.40\",\"17.342\"],[\"78592.80\",\"0.003\"],[\"78594.30\",\"2.255\"],[\"78604.70\",\"0.004\"],[\"78607.60\",\"0.001\"],[\"78623.90\",\"4.953\"],[\"78748.50\",\"3.170\"],[\"78902.30\",\"1.770\"],[\"78981.30\",\"0.009\"],[\"79332.10\",\"0.101\"],[\"79400.00\",\"21.587\"],[\"79456.40\",\"0.268\"],[\"79457.90\",\"0.072\"],[\"79474.60\",\"0.001\"],[\"79477.20\",\"22.969\"],[\"79539.70\",\"1.944\"]],\"a\":[[\"79550.40\",\"0.033\"],[\"79550.60\",\"0.062\"],[\"79561.20\",\"0.715\"],[\"79572.60\",\"1.443\"],[\"79574.30\",\"0.007\"],[\"79620.20\",\"0.008\"],[\"79668.20\",\"1.908\"],[\"79753.50\",\"0.014\"],[\"79779.60\",\"0.003\"],[\"79939.70\",\"0.136\"],[\"80175.00\",\"5.113\"],[\"80273.50\",\"0.000\"],[\"80334.10\",\"5.558\"],[\"80339.40\",\"2.672\"],[\"80692.00\",\"8.539\"]],\"st\":1}}"}
{"receive_ns":1788580701838996000,"stream":"btcusdt@bookTicker","event_type":"bookTicker","event_time_ms":1788580701862,"raw_json":"{\"stream\":\"btcusdt@bookTicker\",\"data\":{\"e\":\"bookTicker\",\"u\":11479472803187,\"s\":\"BTCUSDT\",\"ps\":\"BTCUSDT\",\"b\":\"79543.90\",\"B\":\"6.499\",\"a\":\"79544.00\",\"A\":\"5.056\",\"T\":1788580701862,\"E\":1788580701862,\"st\":1}}"}
{"receive_ns":1788580701839185000,"stream":"btcusdt@trade","event_type":"trade","event_time_ms":1788580701862,"raw_json":"{\"stream\":\"btcusdt@trade\",\"data\":{\"e\":\"trade\",\"E\":1788580701862,\"T\":1788580701862,\"s\":\"BTCUSDT\",\"t\":8054266637,\"p\":\"79543.90\",\"q\":\"0.004\",\"X\":\"MARKET\",\"m\":true,\"st\":1}}"}
{"receive_ns":1788580701839365000,"stream":"btcusdt@bookTicker","event_type":"bookTicker","event_time_ms":1788580701863,"raw_json":"{\"stream\":\"btcusdt@bookTicker\",\"data\":{\"e\":\"bookTicker\",\"u\":11479472803385,\"s\":\"BTCUSDT\",\"ps\":\"BTCUSDT\",\"b\":\"79543.90\",\"B\":\"6.499\",\"a\":\"79544.00\",\"A\":\"5.302\",\"T\":1788580701863,\"E\":1788580701863,\"st\":1}}"}
{"receive_ns":1788580701839513000,"stream":"btcusdt@bookTicker","event_type":"bookTicker","event_time_ms":1788580701865,"raw_json":"{\"stream\":\"btcusdt@bookTicker\",\"data\":{\"e\":\"bookTicker\",\"u\":11479472803514,\"s\":\"BTCUSDT\",\"ps\":\"BTCUSDT\",\"b\":\"79543.90\",\"B\":\"6.499\",\"a\":\"79544.00\",\"A\":\"5.300\",\"T\":1788580701864,\"E\":1788580701865,\"st\":1}}"}
{"receive_ns":1788580701839660000,"stream":"btcusdt@bookTicker","event_type":"bookTicker","event_time_ms":1788580701866,"raw_json":"{\"stream\":\"btcusdt@bookTicker\",\"data\":{\"e\":\"bookTicker\",\"u\":11479472803675,\"s\":\"BTCUSDT\",\"ps\":\"BTCUSDT\",\"b\":\"79543.90\",\"B\":\"6.498\",\"a\":\"79544.00\",\"A\":\"5.300\",\"T\":1788580701866,\"E\":1788580701866,\"st\":1}}"}
{"receive_ns":1788580701839803000,"stream":"btcusdt@bookTicker","event_type":"bookTicker","event_time_ms":1788580701874,"raw_json":"{\"stream\":\"btcusdt@bookTicker\",\"data\":{\"e\":\"bookTicker\",\"u\":11479472804106,\"s\":\"BTCUSDT\",\"ps\":\"BTCUSDT\",\"b\":\"79543.90\",\"B\":\"6.500\",\"a\":\"79544.00\",\"A\":\"5.300\",\"T\":1788580701874,\"E\":1788580701874,\"st\":1}}"}
{"receive_ns":1788580701839941000,"stream":"btcusdt@bookTicker","event_type":"bookTicker","event_time_ms":1788580701885,"raw_json":"{\"stream\":\"btcusdt@bookTicker\",\"data\":{\"e\":\"bookTicker\",\"u\":11479472804731,\"s\":\"BTCUSDT\",\"ps\":\"BTCUSDT\",\"b\":\"79543.90\",\"B\":\"6.499\",\"a\":\"79544.00\",\"A\":\"5.300\",\"T\":1788580701885,\"E\":1788580701885,\"st\":1}}"}
{"receive_ns":1788580701840109000,"stream":"btcusdt@bookTicker","event_type":"bookTicker","event_time_ms":1788580701887,"raw_json":"{\"stream\":\"btcusdt@bookTicker\",\"data\":{\"e\":\"bookTicker\",\"u\":11479472804886,\"s\":\"BTCUSDT\",\"ps\":\"BTCUSDT\",\"b\":\"79543.90\",\"B\":\"6.500\",\"a\":\"79544.00\",\"A\":\"5.300\",\"T\":1788580701887,\"E\":1788580701887,\"st\":1}}"}
{"receive_ns":1788580701843193000,"stream":"btcusdt@depth@100ms","event_type":"depthUpdate","event_time_ms":1788580701899,"raw_json":"{\"stream\":\"btcusdt@depth@100ms\",\"data\":{\"e\":\"depthUpdate\",\"E\":1788580701899,\"T\":1788580701897,\"s\":\"BTCUSDT\",\"ps\":\"BTCUSDT\",\"U\":11479472800023,\"u\":11479472805301,\"pu\":11479472799932,\"b\":[[\"29143.90\",\"1.715\"],[\"29243.90\",\"0.385\"],[\"71589.50\",\"0.006\"],[\"76362.10\",\"0.000\"],[\"78748.50\",\"3.170\"],[\"78828.00\",\"1.270\"],[\"79146.20\",\"3.286\"],[\"79335.50\",\"0.488\"],[\"79356.80\",\"3.149\"],[\"79358.70\",\"3.144\"],[\"79400.00\",\"21.587\"],[\"79453.10\",\"0.000\"],[\"79456.40\",\"0.130\"],[\"79457.10\",\"0.020\"],[\"79458.50\",\"0.236\"],[\"79459.10\",\"0.000\"],[\"79480.30\",\"0.647\"],[\"79531.90\",\"0.940\"],[\"79532.70\",\"0.003\"],[\"79539.70\",\"1.944\"],[\"79543.90\",\"6.500\"]],\"a\":[[\"79544.00\",\"5.300\"],[\"79560.10\",\"0.080\"],[\"79572.10\",\"0.104\"],[\"79633.60\",\"0.039\"],[\"79634.20\",\"0.132\"],[\"79668.20\",\"1.908\"],[\"79683.60\",\"0.016\"],[\"79687.50\",\"3.144\"],[\"79753.40\",\"0.037\"],[\"79936.40\",\"0.126\"],[\"79937.70\",\"0.041\"],[\"79939.70\",\"0.122\"],[\"80339.40\",\"2.672\"],[\"80480.70\",\"0.000\"],[\"80538.30\",\"3.403\"],[\"80880.30\",\"0.493\"],[\"80926.50\",\"0.020\"],[\"81134.80\",\"0.018\"],[\"87498.40\",\"0.001\"]],\"st\":1}}"}
{"receive_ns":1788580701969636000,"stream":"btcusdt@depth@100ms","event_type":"depthUpdate","event_time_ms":1788580702001,"raw_json":"{\"stream\":\"btcusdt@depth@100ms\",\"data\":{\"e\":\"depthUpdate\",\"E\":1788580702001,\"T\":1788580702000,\"s\":\"BTCUSDT\",\"ps\":\"BTCUSDT\",\"U\":11479472805354,\"u\":11479472810118,\"pu\":11479472805301,\"b\":[[\"1000.00\",\"25.354\"],[\"29043.90\",\"0.049\"],[\"29143.90\",\"1.792\"],[\"29243.90\",\"0.259\"],[\"71589.50\",\"0.006\"],[\"75566.70\",\"0.017\"],[\"76362.10\",\"0.002\"],[\"78629.10\",\"2.395\"],[\"78748.50\",\"3.170\"],[\"78827.80\",\"1.983\"],[\"79456.40\",\"0.180\"],[\"79461.50\",\"0.000\"],[\"79475.30\",\"0.001\"],[\"79527.80\",\"0.225\"],[\"79528.60\",\"0.027\"],[\"79534.80\",\"0.000\"],[\"79539.70\",\"1.944\"]],\"a\":[[\"79622.40\",\"0.126\"],[\"79936.40\",\"0.133\"],[\"79937.70\",\"0.059\"],[\"79939.70\",\"0.136\"],[\"80339.40\",\"2.672\"],[\"80680.50\",\"5.571\"],[\"80686.30\",\"0.447\"],[\"80697.40\",\"7.856\"]],\"st\":1}}"}
{"receive_ns":1788580702014162000,"stream":"btcusdt@trade","event_type":"trade","event_time_ms":1788580702059,"raw_json":"{\"stream\":\"btcusdt@trade\",\"data\":{\"e\":\"trade\",\"E\":1788580702059,\"T\":1788580702059,\"s\":\"BTCUSDT\",\"t\":8054266638,\"p\":\"79543.90\",\"q\":\"0.020\",\"X\":\"MARKET\",\"m\":true,\"st\":1}}"}
{"receive_ns":1788580702014359000,"stream":"btcusdt@bookTicker","event_type":"bookTicker","event_time_ms":1788580702059,"raw_json":"{\"stream\":\"btcusdt@bookTicker\",\"data\":{\"e\":\"bookTicker\",\"u\":11479472813041,\"s\":\"BTCUSDT\",\"ps\":\"BTCUSDT\",\"b\":\"79543.90\",\"B\":\"6.480\",\"a\":\"79544.00\",\"A\":\"5.300\",\"T\":1788580702059,\"E\":1788580702059,\"st\":1}}"}
{"receive_ns":1788580702014513000,"stream":"btcusdt@bookTicker","event_type":"bookTicker","event_time_ms":1788580702061,"raw_json":"{\"stream\":\"btcusdt@bookTicker\",\"data\":{\"e\":\"bookTicker\",\"u\":11479472813269,\"s\":\"BTCUSDT\",\"ps\":\"BTCUSDT\",\"b\":\"79543.90\",\"B\":\"6.479\",\"a\":\"79544.00\",\"A\":\"5.300\",\"T\":1788580702061,\"E\":1788580702061,\"st\":1}}"}
{"receive_ns":1788580702014657000,"stream":"btcusdt@bookTicker","event_type":"bookTicker","event_time_ms":1788580702063,"raw_json":"{\"stream\":\"btcusdt@bookTicker\",\"data\":{\"e\":\"bookTicker\",\"u\":11479472813395,\"s\":\"BTCUSDT\",\"ps\":\"BTCUSDT\",\"b\":\"79543.90\",\"B\":\"6.480\",\"a\":\"79544.00\",\"A\":\"5.300\",\"T\":1788580702063,\"E\":1788580702063,\"st\":1}}"}
{"receive_ns":1788580702014792000,"stream":"btcusdt@bookTicker","event_type":"bookTicker","event_time_ms":1788580702068,"raw_json":"{\"stream\":\"btcusdt@bookTicker\",\"data\":{\"e\":\"bookTicker\",\"u\":11479472813652,\"s\":\"BTCUSDT\",\"ps\":\"BTCUSDT\",\"b\":\"79543.90\",\"B\":\"6.480\",\"a\":\"79544.00\",\"A\":\"5.269\",\"T\":1788580702068,\"E\":1788580702068,\"st\":1}}"}
{"receive_ns":1788580702014940000,"stream":"btcusdt@bookTicker","event_type":"bookTicker","event_time_ms":1788580702070,"raw_json":"{\"stream\":\"btcusdt@bookTicker\",\"data\":{\"e\":\"bookTicker\",\"u\":11479472813776,\"s\":\"BTCUSDT\",\"ps\":\"BTCUSDT\",\"b\":\"79543.90\",\"B\":\"6.480\",\"a\":\"79544.00\",\"A\":\"5.304\",\"T\":1788580702070,\"E\":1788580702070,\"st\":1}}"}
{"receive_ns":1788580702015075000,"stream":"btcusdt@bookTicker","event_type":"bookTicker","event_time_ms":1788580702071,"raw_json":"{\"stream\":\"btcusdt@bookTicker\",\"data\":{\"e\":\"bookTicker\",\"u\":11479472813835,\"s\":\"BTCUSDT\",\"ps\":\"BTCUSDT\",\"b\":\"79543.90\",\"B\":\"6.480\",\"a\":\"79544.00\",\"A\":\"5.306\",\"T\":1788580702071,\"E\":1788580702071,\"st\":1}}"}
{"receive_ns":1788580702071958000,"stream":"btcusdt@bookTicker","event_type":"bookTicker","event_time_ms":1788580702088,"raw_json":"{\"stream\":\"btcusdt@bookTicker\",\"data\":{\"e\":\"bookTicker\",\"u\":11479472814737,\"s\":\"BTCUSDT\",\"ps\":\"BTCUSDT\",\"b\":\"79543.90\",\"B\":\"6.478\",\"a\":\"79544.00\",\"A\":\"5.306\",\"T\":1788580702088,\"E\":1788580702088,\"st\":1}}"}
{"receive_ns":1788580702072152000,"stream":"btcusdt@bookTicker","event_type":"bookTicker","event_time_ms":1788580702092,"raw_json":"{\"stream\":\"btcusdt@bookTicker\",\"data\":{\"e\":\"bookTicker\",\"u\":11479472815120,\"s\":\"BTCUSDT\",\"ps\":\"BTCUSDT\",\"b\":\"79543.90\",\"B\":\"6.479\",\"a\":\"79544.00\",\"A\":\"5.306\",\"T\":1788580702092,\"E\":1788580702092,\"st\":1}}"}
{"receive_ns":1788580702072470000,"stream":"btcusdt@depth@100ms","event_type":"depthUpdate","event_time_ms":1788580702103,"raw_json":"{\"stream\":\"btcusdt@depth@100ms\",\"data\":{\"e\":\"depthUpdate\",\"E\":1788580702103,\"T\":1788580702102,\"s\":\"BTCUSDT\",\"ps\":\"BTCUSDT\",\"U\":11479472810211,\"u\":11479472815918,\"pu\":11479472810118,\"b\":[[\"1000.00\",\"25.354\"],[\"29043.90\",\"0.105\"],[\"29143.90\",\"1.862\"],[\"29243.90\",\"0.133\"],[\"63635.10\",\"0.000\"],[\"71589.50\",\"0.006\"],[\"76362.10\",\"0.000\"],[\"78390.50\",\"7.263\"],[\"78748.50\",\"3.170\"],[\"78920.00\",\"0.900\"],[\"79332.20\",\"5.079\"],[\"79335.50\",\"1.184\"],[\"79379.90\",\"2.068\"],[\"79419.30\",\"0.828\"],[\"79456.40\",\"0.060\"],[\"79457.10\",\"0.000\"],[\"79480.30\",\"0.509\"],[\"79488.20\",\"0.130\"],[\"79504.10\",\"0.002\"],[\"79520.20\",\"2.395\"],[\"79528.60\",\"0.001\"],[\"79529.60\",\"0.002\"],[\"79539.70\",\"1.944\"],[\"79543.90\",\"6.479\"]],\"a\":[[\"79544.00\",\"5.306\"],[\"79560.10\",\"0.080\"],[\"79567.90\",\"0.354\"],[\"79599.70\",\"0.052\"],[\"79615.60\",\"0.004\"],[\"79666.40\",\"0.418\"],[\"79705.70\",\"1.859\"],[\"79753.50\",\"4.927\"],[\"79936.40\",\"0.126\"],[\"79937.70\",\"0.022\"],[\"79939.70\",\"0.019\"],[\"80339.40\",\"2.672\"],[\"80521.40\",\"11.654\"],[\"80913.70\",\"3.332\"],[\"81930.30\",\"0.853\"]],\"st\":1}}"}
{"receive_ns":1788580702088471000,"stream":"btcusdt@bookTicker","event_type":"bookTicker","event_time_ms":1788580702138,"raw_json":"{\"stream\":\"btcusdt@bookTicker\",\"data\":{\"e\":\"bookTicker\",\"u\":11479472819220,\"s\":\"BTCUSDT\",\"ps\":\"BTCUSDT\",\"b\":\"79543.90\",\"B\":\"6.402\",\"a\":\"79544.00\",\"A\":\"5.306\",\"T\":1788580702138,\"E\":1788580702138,\"st\":1}}"}
{"receive_ns":1788580702093883000,"stream":"btcusdt@bookTicker","event_type":"bookTicker","event_time_ms":1788580702141,"raw_json":"{\"stream\":\"btcusdt@bookTicker\",\"data\":{\"e\":\"bookTicker\",\"u\":11479472819896,\"s\":\"BTCUSDT\",\"ps\":\"BTCUSDT\",\"b\":\"79543.90\",\"B\":\"6.494\",\"a\":\"79544.00\",\"A\":\"5.306\",\"T\":1788580702141,\"E\":1788580702141,\"st\":1}}"}
{"receive_ns":1788580702148885000,"stream":"btcusdt@depth@100ms","event_type":"depthUpdate","event_time_ms":1788580702205,"raw_json":"{\"stream\":\"btcusdt@depth@100ms\",\"data\":{\"e\":\"depthUpdate\",\"E\":1788580702205,\"T\":1788580702201,\"s\":\"BTCUSDT\",\"ps\":\"BTCUSDT\",\"U\":11479472816012,\"u\":11479472824487,\"pu\":11479472815918,\"b\":[[\"29043.90\",\"0.168\"],[\"29143.90\",\"1.911\"],[\"29243.90\",\"0.021\"],[\"71589.50\",\"0.006\"],[\"71623.00\",\"0.000\"],[\"78305.80\",\"4.338\"],[\"78385.30\",\"4.944\"],[\"78549.60\",\"5.534\"],[\"78691.30\",\"0.000\"],[\"78748.50\",\"3.170\"],[\"79146.10\",\"0.009\"],[\"79146.20\",\"3.412\"],[\"79419.30\",\"0.845\"],[\"79453.10\",\"0.020\"],[\"79456.40\",\"0.308\"],[\"79474.60\",\"22.943\"],[\"79477.20\",\"0.027\"],[\"79517.30\",\"0.454\"],[\"79518.70\",\"0.139\"],[\"79524.20\",\"2.520\"],[\"79524.70\",\"0.047\"],[\"79525.00\",\"0.002\"],[\"79526.00\",\"0.082\"],[\"79527.80\",\"0.665\"],[\"79528.40\",\"0.177\"],[\"79543.90\",\"6.494\"]],\"a\":[[\"79550.40\",\"0.033\"],[\"79550.60\",\"0.062\"],[\"79556.10\",\"0.634\"],[\"79556.90\",\"0.001\"],[\"79563.90\",\"0.441\"],[\"79565.60\",\"0.760\"],[\"79588.50\",\"4.846\"],[\"79590.60\",\"0.012\"],[\"79624.70\",\"0.514\"],[\"79624.80\",\"1.752\"],[\"79625.30\",\"0.000\"],[\"79625.40\",\"0.004\"],[\"79636.20\",\"0.001\"],[\"79636.30\",\"0.007\"],[\"79637.40\",\"0.004\"],[\"79637.50\",\"0.001\"],[\"79640.90\",\"0.000\"],[\"79641.00\",\"0.008\"],[\"79666.30\",\"0.437\"],[\"79666.40\",\"0.000\"],[\"79936.40\",\"0.133\"],[\"79937.70\",\"0.022\"],[\"79939.70\",\"0.168\"],[\"79941.80\",\"0.001\"],[\"80339.40\",\"2.672\"],[\"80424.80\",\"0.373\"]],\"st\":1}}"}
{"receive_ns":1788580702200495000,"stream":"btcusdt@bookTicker","event_type":"bookTicker","event_time_ms":1788580702227,"raw_json":"{\"stream\":\"btcusdt@bookTicker\",\"data\":{\"e\":\"bookTicker\",\"u\":11479472826026,\"s\":\"BTCUSDT\",\"ps\":\"BTCUSDT\",\"b\":\"79543.90\",\"B\":\"6.494\",\"a\":\"79544.00\",\"A\":\"5.060\",\"T\":1788580702227,\"E\":1788580702227,\"st\":1}}"}
{"receive_ns":1788580702200728000,"stream":"btcusdt@bookTicker","event_type":"bookTicker","event_time_ms":1788580702234,"raw_json":"{\"stream\":\"btcusdt@bookTicker\",\"data\":{\"e\":\"bookTicker\",\"u\":11479472826523,\"s\":\"BTCUSDT\",\"ps\":\"BTCUSDT\",\"b\":\"79543.90\",\"B\":\"6.494\",\"a\":\"79544.00\",\"A\":\"5.046\",\"T\":1788580702233,\"E\":1788580702234,\"st\":1}}"}
{"receive_ns":1788580702200892000,"stream":"btcusdt@bookTicker","event_type":"bookTicker","event_time_ms":1788580702236,"raw_json":"{\"stream\":\"btcusdt@bookTicker\",\"data\":{\"e\":\"bookTicker\",\"u\":11479472826731,\"s\":\"BTCUSDT\",\"ps\":\"BTCUSDT\",\"b\":\"79543.90\",\"B\":\"6.494\",\"a\":\"79544.00\",\"A\":\"5.062\",\"T\":1788580702236,\"E\":1788580702236,\"st\":1}}"}
{"receive_ns":1788580702277100000,"stream":"btcusdt@depth@100ms","event_type":"depthUpdate","event_time_ms":1788580702307,"raw_json":"{\"stream\":\"btcusdt@depth@100ms\",\"data\":{\"e\":\"depthUpdate\",\"E\":1788580702307,\"T\":1788580702305,\"s\":\"BTCUSDT\",\"ps\":\"BTCUSDT\",\"U\":11479472824635,\"u\":11479472830632,\"pu\":11479472824487,\"b\":[[\"1000.00\",\"25.354\"],[\"29043.90\",\"0.329\"],[\"29143.90\",\"1.771\"],[\"29243.90\",\"0.000\"],[\"71589.50\",\"0.006\"],[\"76362.10\",\"0.002\"],[\"78158.50\",\"0.000\"],[\"78748.50\",\"3.170\"],[\"79400.00\",\"23.604\"],[\"79476.00\",\"4.374\"],[\"79480.30\",\"0.519\"],[\"79524.20\",\"2.147\"],[\"79525.40\",\"0.419\"],[\"79538.30\",\"0.004\"],[\"79538.40\",\"0.056\"]],\"a\":[[\"79544.00\",\"5.062\"],[\"79563.90\",\"0.002\"],[\"79564.90\",\"0.814\"],[\"79588.50\",\"4.800\"],[\"79589.60\",\"0.298\"],[\"79620.00\",\"16.148\"],[\"79623.00\",\"29.943\"],[\"79624.70\",\"0.515\"],[\"79628.30\",\"0.000\"],[\"79633.10\",\"0.000\"],[\"79636.20\",\"0.002\"],[\"79668.10\",\"0.007\"],[\"79684.20\",\"0.928\"],[\"79753.40\",\"1.481\"],[\"79939.70\",\"0.173\"],[\"80339.40\",\"2.672\"]],\"st\":1}}"}
{"receive_ns":1788580702345133000,"stream":"btcusdt@bookTicker","event_type":"bookTicker","event_time_ms":1788580702376,"raw_json":"{\"stream\":\"btcusdt@bookTicker\",\"data\":{\"e\":\"bookTicker\",\"u\":11479472835026,\"s\":\"BTCUSDT\",\"ps\":\"BTCUSDT\",\"b\":\"79543.90\",\"B\":\"6.493\",\"a\":\"79544.00\",\"A\":\"5.062\",\"T\":1788580702376,\"E\":1788580702376,\"st\":1}}"}
{"receive_ns":1788580702345419000,"stream":"btcusdt@bookTicker","event_type":"bookTicker","event_time_ms":1788580702386,"raw_json":"{\"stream\":\"btcusdt@bookTicker\",\"data\":{\"e\":\"bookTicker\",\"u\":11479472835747,\"s\":\"BTCUSDT\",\"ps\":\"BTCUSDT\",\"b\":\"79543.90\",\"B\":\"6.495\",\"a\":\"79544.00\",\"A\":\"5.062\",\"T\":1788580702385,\"E\":1788580702386,\"st\":1}}"}
{"receive_ns":1788580702345743000,"stream":"btcusdt@bookTicker","event_type":"bookTicker","event_time_ms":1788580702394,"raw_json":"{\"stream\":\"btcusdt@bookTicker\",\"data\":{\"e\":\"bookTicker\",\"u\":11479472836269,\"s\":\"BTCUSDT\",\"ps\":\"BTCUSDT\",\"b\":\"79543.90\",\"B\":\"6.494\",\"a\":\"79544.00\",\"A\":\"5.062\",\"T\":1788580702394,\"E\":1788580702394,\"st\":1}}"}
{"receive_ns":1788580702347355000,"stream":"btcusdt@bookTicker","event_type":"bookTicker","event_time_ms":1788580702396,"raw_json":"{\"stream\":\"btcusdt@bookTicker\",\"data\":{\"e\":\"bookTicker\",\"u\":11479472836412,\"s\":\"BTCUSDT\",\"ps\":\"BTCUSDT\",\"b\":\"79543.90\",\"B\":\"6.495\",\"a\":\"79544.00\",\"A\":\"5.062\",\"T\":1788580702396,\"E\":1788580702396,\"st\":1}}"}
{"receive_ns":1788580702353155000,"stream":"btcusdt@depth@100ms","event_type":"depthUpdate","event_time_ms":1788580702409,"raw_json":"{\"stream\":\"btcusdt@depth@100ms\",\"data\":{\"e\":\"depthUpdate\",\"E\":1788580702409,\"T\":1788580702405,\"s\":\"BTCUSDT\",\"ps\":\"BTCUSDT\",\"U\":11479472830694,\"u\":11479472837474,\"pu\":11479472830632,\"b\":[[\"29043.90\",\"0.504\"],[\"29143.90\",\"1.596\"],[\"71589.50\",\"0.006\"],[\"76362.10\",\"0.000\"],[\"78125.30\",\"0.000\"],[\"78390.50\",\"8.155\"],[\"78748.50\",\"3.170\"],[\"79453.10\",\"0.000\"],[\"79456.40\",\"0.007\"],[\"79480.30\",\"0.820\"],[\"79482.90\",\"0.606\"],[\"79502.60\",\"1.259\"],[\"79524.30\",\"0.005\"],[\"79525.40\",\"0.046\"],[\"79525.50\",\"0.374\"],[\"79538.30\",\"0.006\"],[\"79538.50\",\"0.336\"],[\"79539.70\",\"1.944\"],[\"79543.90\",\"6.495\"]],\"a\":[[\"79563.90\",\"0.002\"],[\"79564.90\",\"0.441\"],[\"79565.40\",\"2.679\"],[\"79668.10\",\"0.013\"],[\"79936.40\",\"0.133\"],[\"79937.70\",\"0.004\"],[\"79939.70\",\"0.191\"],[\"80312.30\",\"2.857\"],[\"80339.40\",\"2.672\"]],\"st\":1}}"}
{"receive_ns":1788580702353545000,"stream":"btcusdt@bookTicker","event_type":"bookTicker","event_time_ms":1788580702410,"raw_json":"{\"stream\":\"btcusdt@bookTicker\",\"data\":{\"e\":\"bookTicker\",\"u\":11479472837780,\"s\":\"BTCUSDT\",\"ps\":\"BTCUSDT\",\"b\":\"79543.90\",\"B\":\"6.488\",\"a\":\"79544.00\",\"A\":\"5.062\",\"T\":1788580702410,\"E\":1788580702410,\"st\":1}}"}
{"receive_ns":1788580702469111000,"stream":"btcusdt@bookTicker","event_type":"bookTicker","event_time_ms":1788580702503,"raw_json":"{\"stream\":\"btcusdt@bookTicker\",\"data\":{\"e\":\"bookTicker\",\"u\":11479472842525,\"s\":\"BTCUSDT\",\"ps\":\"BTCUSDT\",\"b\":\"79543.90\",\"B\":\"6.490\",\"a\":\"79544.00\",\"A\":\"5.062\",\"T\":1788580702503,\"E\":1788580702503,\"st\":1}}"}
{"receive_ns":1788580702469592000,"stream":"btcusdt@depth@100ms","event_type":"depthUpdate","event_time_ms":1788580702511,"raw_json":"{\"stream\":\"btcusdt@depth@100ms\",\"data\":{\"e\":\"depthUpdate\",\"E\":1788580702511,\"T\":1788580702509,\"s\":\"BTCUSDT\",\"ps\":\"BTCUSDT\",\"U\":11479472837730,\"u\":11479472843044,\"pu\":11479472837474,\"b\":[[\"29043.90\",\"0.686\"],[\"29143.90\",\"1.414\"],[\"71589.50\",\"0.006\"],[\"76362.10\",\"0.002\"],[\"78311.00\",\"4.703\"],[\"78748.50\",\"3.170\"],[\"78999.60\",\"0.000\"],[\"79146.20\",\"3.402\"],[\"79416.60\",\"0.184\"],[\"79419.30\",\"0.408\"],[\"79480.30\",\"0.820\"],[\"79534.30\",\"0.367\"],[\"79539.70\",\"1.944\"],[\"79543.90\",\"6.490\"]],\"a\":[[\"79666.30\",\"0.000\"],[\"79939.70\",\"0.191\"],[\"80339.40\",\"2.672\"],[\"80657.60\",\"19.757\"]],\"st\":1}}"}
{"receive_ns":1788580702540085000,"stream":"btcusdt@bookTicker","event_type":"bookTicker","event_time_ms":1788580702595,"raw_json":"{\"stream\":\"btcusdt@bookTicker\",\"data\":{\"e\":\"bookTicker\",\"u\":11479472846937,\"s\":\"BTCUSDT\",\"ps\":\"BTCUSDT\",\"b\":\"79543.90\",\"B\":\"6.488\",\"a\":\"79544.00\",\"A\":\"5.062\",\"T\":1788580702595,\"E\":1788580702595,\"st\":1}}"}
{"receive_ns":1788580702547336000,"stream":"btcusdt@bookTicker","event_type":"bookTicker","event_time_ms":1788580702604,"raw_json":"{\"stream\":\"btcusdt@bookTicker\",\"data\":{\"e\":\"bookTicker\",\"u\":11479472847586,\"s\":\"BTCUSDT\",\"ps\":\"BTCUSDT\",\"b\":\"79543.90\",\"B\":\"6.489\",\"a\":\"79544.00\",\"A\":\"5.062\",\"T\":1788580702603,\"E\":1788580702604,\"st\":1}}"}
{"receive_ns":1788580702555398000,"stream":"btcusdt@depth@100ms","event_type":"depthUpdate","event_time_ms":1788580702613,"raw_json":"{\"stream\":\"btcusdt@depth@100ms\",\"data\":{\"e\":\"depthUpdate\",\"E\":1788580702613,\"T\":1788580702612,\"s\":\"BTCUSDT\",\"ps\":\"BTCUSDT\",\"U\":11479472843199,\"u\":11479472848121,\"pu\":11479472843044,\"b\":[[\"1000.00\",\"25.354\"],[\"29043.90\",\"0.861\"],[\"29143.90\",\"1.239\"],[\"63635.00\",\"0.000\"],[\"71589.50\",\"0.006\"],[\"77953.10\",\"0.015\"],[\"78120.10\",\"0.386\"],[\"78549.60\",\"5.687\"],[\"78589.40\",\"18.613\"],[\"79419.30\",\"0.845\"],[\"79456.40\",\"0.000\"],[\"79480.30\",\"0.519\"],[\"79482.90\",\"0.586\"],[\"79517.30\",\"0.002\"],[\"79518.80\",\"0.454\"],[\"79521.40\",\"0.058\"],[\"79521.60\",\"0.004\"],[\"79523.40\",\"0.001\"],[\"79524.20\",\"2.148\"],[\"79539.70\",\"1.945\"],[\"79543.90\",\"6.489\"]],\"a\":[[\"79567.90\",\"0.332\"],[\"79666.30\",\"0.437\"],[\"79936.40\",\"0.126\"],[\"79939.70\",\"0.005\"],[\"80299.70\",\"1.741\"],[\"80339.40\",\"2.672\"],[\"80493.20\",\"16.131\"],[\"80538.30\",\"3.681\"],[\"80697.40\",\"8.722\"]],\"st\":1}}"}
{"receive_ns":1788580702659358000,"stream":"btcusdt@depth@100ms","event_type":"depthUpdate","event_time_ms":1788580702715,"raw_json":"{\"stream\":\"btcusdt@depth@100ms\",\"data\":{\"e\":\"depthUpdate\",\"E\":1788580702715,\"T\":1788580702714,\"s\":\"BTCUSDT\",\"ps\":\"BTCUSDT\",\"U\":11479472848181,\"u\":11479472854669,\"pu\":11479472848121,\"b\":[[\"29043.90\",\"1.043\"],[\"29143.90\",\"1.057\"],[\"63635.00\",\"0.000\"],[\"71589.50\",\"0.006\"],[\"75566.70\",\"0.015\"],[\"75566.80\",\"0.004\"],[\"76362.10\",\"0.000\"],[\"78611.70\",\"10.035\"],[\"78623.90\",\"4.191\"],[\"78748.50\",\"3.170\"],[\"78987.10\",\"0.068\"],[\"79456.40\",\"0.007\"],[\"79480.30\",\"0.810\"],[\"79482.90\",\"0.606\"],[\"79515.40\",\"0.763\"],[\"79517.30\",\"0.002\"],[\"79518.80\",\"0.454\"],[\"79524.30\",\"0.005\"],[\"79525.50\",\"0.374\"],[\"79527.80\",\"0.665\"],[\"79528.80\",\"0.083\"],[\"79539.70\",\"1.944\"],[\"79542.60\",\"0.002\"],[\"79543.80\",\"0.086\"]],\"a\":[[\"79548.20\",\"0.019\"],[\"79548.50\",\"0.002\"],[\"79563.90\",\"0.002\"],[\"79564.30\",\"0.000\"],[\"79564.90\",\"0.441\"],[\"79565.30\",\"0.375\"],[\"79565.40\",\"2.306\"],[\"79567.20\",\"0.006\"],[\"79568.20\",\"0.001\"],[\"79568.30\",\"0.857\"],[\"79936.40\",\"0.133\"],[\"79939.70\",\"0.186\"],[\"80339.40\",\"2.672\"],[\"80439.80\",\"0.001\"],[\"80692.00\",\"7.672\"],[\"81134.80\",\"0.015\"]],\"st\":1}}"}
{"receive_ns":1788580702778046000,"stream":"btcusdt@depth@100ms","event_type":"depthUpdate","event_time_ms":1788580702817,"raw_json":"{\"stream\":\"btcusdt@depth@100ms\",\"data\":{\"e\":\"depthUpdate\",\"E\":1788580702817,\"T\":1788580702813,\"s\":\"BTCUSDT\",\"ps\":\"BTCUSDT\",\"U\":11479472854684,\"u\":11479472860063,\"pu\":11479472854669,\"b\":[[\"29043.90\",\"1.218\"],[\"29143.90\",\"0.882\"],[\"71589.50\",\"0.006\"],[\"75566.80\",\"0.002\"],[\"76362.10\",\"0.002\"],[\"78452.60\",\"9.550\"],[\"78589.40\",\"19.884\"],[\"78748.50\",\"3.170\"],[\"79146.20\",\"3.412\"],[\"79419.30\",\"0.408\"],[\"79480.30\",\"0.820\"],[\"79539.70\",\"1.944\"]],\"a\":[[\"79548.20\",\"0.002\"],[\"79548.60\",\"0.000\"],[\"79558.60\",\"0.076\"],[\"79571.00\",\"0.003\"],[\"79666.30\",\"0.000\"],[\"79939.70\",\"0.191\"],[\"80339.40\",\"2.672\"],[\"80498.50\",\"20.838\"],[\"80578.30\",\"1.061\"],[\"80657.60\",\"20.128\"]],\"st\":1}}"}
{"receive_ns":1788580702778292000,"stream":"btcusdt@bookTicker","event_type":"bookTicker","event_time_ms":1788580702819,"raw_json":"{\"stream\":\"btcusdt@bookTicker\",\"data\":{\"e\":\"bookTicker\",\"u\":11479472860996,\"s\":\"BTCUSDT\",\"ps\":\"BTCUSDT\",\"b\":\"79543.90\",\"B\":\"6.489\",\"a\":\"79544.00\",\"A\":\"5.061\",\"T\":1788580702818,\"E\":1788580702819,\"st\":1}}"}
{"receive_ns":1788580702778425000,"stream":"btcusdt@trade","event_type":"trade","event_time_ms":1788580702819,"raw_json":"{\"stream\":\"btcusdt@trade\",\"data\":{\"e\":\"trade\",\"E\":1788580702819,\"T\":1788580702818,\"s\":\"BTCUSDT\",\"t\":8054266639,\"p\":\"79544.00\",\"q\":\"0.001\",\"X\":\"MARKET\",\"m\":false,\"st\":1}}"}
{"receive_ns":1788580702838030000,"stream":"btcusdt@bookTicker","event_type":"bookTicker","event_time_ms":1788580702859,"raw_json":"{\"stream\":\"btcusdt@bookTicker\",\"data\":{\"e\":\"bookTicker\",\"u\":11479472864186,\"s\":\"BTCUSDT\",\"ps\":\"BTCUSDT\",\"b\":\"79543.90\",\"B\":\"6.488\",\"a\":\"79544.00\",\"A\":\"5.061\",\"T\":1788580702859,\"E\":1788580702859,\"st\":1}}"}
{"receive_ns":1788580702838191000,"stream":"btcusdt@bookTicker","event_type":"bookTicker","event_time_ms":1788580702860,"raw_json":"{\"stream\":\"btcusdt@bookTicker\",\"data\":{\"e\":\"bookTicker\",\"u\":11479472864316,\"s\":\"BTCUSDT\",\"ps\":\"BTCUSDT\",\"b\":\"79543.90\",\"B\":\"6.489\",\"a\":\"79544.00\",\"A\":\"5.061\",\"T\":1788580702860,\"E\":1788580702860,\"st\":1}}"}
{"receive_ns":1788580702838340000,"stream":"btcusdt@bookTicker","event_type":"bookTicker","event_time_ms":1788580702879,"raw_json":"{\"stream\":\"btcusdt@bookTicker\",\"data\":{\"e\":\"bookTicker\",\"u\":11479472865477,\"s\":\"BTCUSDT\",\"ps\":\"BTCUSDT\",\"b\":\"79543.90\",\"B\":\"6.489\",\"a\":\"79544.00\",\"A\":\"5.062\",\"T\":1788580702879,\"E\":1788580702879,\"st\":1}}"}
{"receive_ns":1788580702844530000,"stream":"btcusdt@bookTicker","event_type":"bookTicker","event_time_ms":1788580702900,"raw_json":"{\"stream\":\"btcusdt@bookTicker\",\"data\":{\"e\":\"bookTicker\",\"u\":11479472866570,\"s\":\"BTCUSDT\",\"ps\":\"BTCUSDT\",\"b\":\"79543.90\",\"B\":\"6.488\",\"a\":\"79544.00\",\"A\":\"5.062\",\"T\":1788580702900,\"E\":1788580702900,\"st\":1}}"}
{"receive_ns":1788580702891589000,"stream":"btcusdt@bookTicker","event_type":"bookTicker","event_time_ms":1788580702914,"raw_json":"{\"stream\":\"btcusdt@bookTicker\",\"data\":{\"e\":\"bookTicker\",\"u\":11479472867449,\"s\":\"BTCUSDT\",\"ps\":\"BTCUSDT\",\"b\":\"79543.90\",\"B\":\"6.490\",\"a\":\"79544.00\",\"A\":\"5.062\",\"T\":1788580702913,\"E\":1788580702914,\"st\":1}}"}
{"receive_ns":1788580702891971000,"stream":"btcusdt@depth@100ms","event_type":"depthUpdate","event_time_ms":1788580702919,"raw_json":"{\"stream\":\"btcusdt@depth@100ms\",\"data\":{\"e\":\"depthUpdate\",\"E\":1788580702919,\"T\":1788580702918,\"s\":\"BTCUSDT\",\"ps\":\"BTCUSDT\",\"U\":11479472860742,\"u\":11479472867695,\"pu\":11479472860063,\"b\":[[\"1000.00\",\"25.354\"],[\"29043.90\",\"1.400\"],[\"29143.90\",\"0.700\"],[\"63635.00\",\"0.000\"],[\"71589.50\",\"0.006\"],[\"76362.10\",\"0.000\"],[\"78629.10\",\"3.157\"],[\"78748.50\",\"3.170\"],[\"79400.00\",\"23.605\"],[\"79419.40\",\"0.450\"],[\"79456.40\",\"0.032\"],[\"79480.30\",\"0.795\"],[\"79482.90\",\"0.606\"],[\"79540.60\",\"0.252\"],[\"79543.90\",\"6.490\"]],\"a\":[[\"79544.00\",\"5.062\"],[\"79547.60\",\"0.000\"],[\"79548.40\",\"0.001\"],[\"79558.60\",\"0.000\"],[\"79596.30\",\"3.557\"],[\"79596.50\",\"0.051\"],[\"79666.30\",\"0.437\"],[\"79933.80\",\"0.018\"],[\"79936.40\",\"0.133\"],[\"79939.70\",\"0.173\"],[\"80312.30\",\"2.298\"],[\"80339.40\",\"2.672\"],[\"80697.40\",\"9.588\"],[\"81044.30\",\"3.517\"],[\"81214.40\",\"2.109\"]],\"st\":1}}"}
{"receive_ns":1788580702964569000,"stream":"btcusdt@depth@100ms","event_type":"depthUpdate","event_time_ms":1788580703021,"raw_json":"{\"stream\":\"btcusdt@depth@100ms\",\"data\":{\"e\":\"depthUpdate\",\"E\":1788580703021,\"T\":1788580703020,\"s\":\"BTCUSDT\",\"ps\":\"BTCUSDT\",\"U\":11479472867739,\"u\":11479472872525,\"pu\":11479472867695,\"b\":[[\"29043.90\",\"1.575\"],[\"29143.90\",\"0.525\"],[\"63635.00\",\"0.000\"],[\"71589.50\",\"0.006\"],[\"75566.70\",\"0.013\"],[\"75566.80\",\"0.004\"],[\"76362.10\",\"0.002\"],[\"77953.10\",\"0.015\"],[\"78549.60\",\"5.903\"],[\"78748.50\",\"3.172\"],[\"79480.30\",\"0.795\"],[\"79540.60\",\"0.253\"]],\"a\":[[\"79560.10\",\"0.004\"],[\"79939.70\",\"0.173\"],[\"80339.40\",\"2.672\"],[\"80633.80\",\"0.504\"],[\"81134.80\",\"0.012\"]],\"st\":1}}"}
{"receive_ns":1788580703019988000,"stream":"btcusdt@bookTicker","event_type":"bookTicker","event_time_ms":1788580703076,"raw_json":"{\"stream\":\"btcusdt@bookTicker\",\"data\":{\"e\":\"bookTicker\",\"u\":11479472875100,\"s\":\"BTCUSDT\",\"ps\":\"BTCUSDT\",\"b\":\"79543.90\",\"B\":\"6.490\",\"a\":\"79544.00\",\"A\":\"5.027\",\"T\":1788580703076,\"E\":1788580703076,\"st\":1}}"}
{"receive_ns":1788580703076670000,"stream":"btcusdt@bookTicker","event_type":"bookTicker","event_time_ms":1788580703079,"raw_json":"{\"stream\":\"btcusdt@bookTicker\",\"data\":{\"e\":\"bookTicker\",\"u\":11479472875241,\"s\":\"BTCUSDT\",\"ps\":\"BTCUSDT\",\"b\":\"79543.90\",\"B\":\"6.490\",\"a\":\"79544.00\",\"A\":\"5.064\",\"T\":1788580703079,\"E\":1788580703079,\"st\":1}}"}
{"receive_ns":1788580703091688000,"stream":"btcusdt@depth@100ms","event_type":"depthUpdate","event_time_ms":1788580703123,"raw_json":"{\"stream\":\"btcusdt@depth@100ms\",\"data\":{\"e\":\"depthUpdate\",\"E\":1788580703123,\"T\":1788580703121,\"s\":\"BTCUSDT\",\"ps\":\"BTCUSDT\",\"U\":11479472872552,\"u\":11479472878176,\"pu\":11479472872525,\"b\":[[\"29043.90\",\"1.757\"],[\"29143.90\",\"0.343\"],[\"63635.00\",\"0.000\"],[\"63635.10\",\"0.000\"],[\"71589.50\",\"0.008\"],[\"75566.70\",\"0.016\"],[\"78748.40\",\"0.001\"],[\"78748.50\",\"3.170\"],[\"79146.20\",\"3.402\"],[\"79456.40\",\"0.025\"],[\"79480.30\",\"0.544\"],[\"79482.90\",\"0.586\"],[\"79520.20\",\"2.395\"],[\"79529.60\",\"0.002\"],[\"79531.60\",\"0.003\"],[\"79538.50\",\"0.068\"],[\"79540.60\",\"0.252\"]],\"a\":[[\"79544.00\",\"5.064\"],[\"79560.10\",\"0.004\"],[\"79596.30\",\"3.607\"],[\"79596.50\",\"0.001\"],[\"79625.20\",\"0.005\"],[\"79633.10\",\"0.022\"],[\"79936.40\",\"0.126\"],[\"79939.70\",\"0.019\"],[\"79941.70\",\"2.248\"],[\"80339.40\",\"2.672\"],[\"80498.50\",\"21.458\"]],\"st\":1}}"}
{"receive_ns":1788580703140855000,"stream":"btcusdt@bookTicker","event_type":"bookTicker","event_time_ms":1788580703181,"raw_json":"{\"stream\":\"btcusdt@bookTicker\",\"data\":{\"e\":\"bookTicker\",\"u\":11479472881817,\"s\":\"BTCUSDT\",\"ps\":\"BTCUSDT\",\"b\":\"79543.90\",\"B\":\"6.490\",\"a\":\"79544.00\",\"A\":\"5.310\",\"T\":1788580703181,\"E\":1788580703181,\"st\":1}}"}
{"receive_ns":1788580703141084000,"stream":"btcusdt@bookTicker","event_type":"bookTicker","event_time_ms":1788580703182,"raw_json":"{\"stream\":\"btcusdt@bookTicker\",\"data\":{\"e\":\"bookTicker\",\"u\":11479472881939,\"s\":\"BTCUSDT\",\"ps\":\"BTCUSDT\",\"b\":\"79543.90\",\"B\":\"6.490\",\"a\":\"79544.00\",\"A\":\"5.308\",\"T\":1788580703182,\"E\":1788580703182,\"st\":1}}"}
{"receive_ns":1788580703192229000,"stream":"btcusdt@depth@100ms","event_type":"depthUpdate","event_time_ms":1788580703225,"raw_json":"{\"stream\":\"btcusdt@depth@100ms\",\"data\":{\"e\":\"depthUpdate\",\"E\":1788580703225,\"T\":1788580703223,\"s\":\"BTCUSDT\",\"ps\":\"BTCUSDT\",\"U\":11479472878367,\"u\":11479472884403,\"pu\":11479472878176,\"b\":[[\"1000.00\",\"25.354\"],[\"29043.90\",\"1.806\"],[\"29143.90\",\"0.231\"],[\"29443.90\",\"0.063\"],[\"71589.50\",\"0.010\"],[\"71623.00\",\"0.000\"],[\"76362.10\",\"0.000\"],[\"78333.20\",\"3.570\"],[\"78748.50\",\"3.170\"],[\"79146.10\",\"0.009\"],[\"79419.40\",\"0.013\"],[\"79456.40\",\"0.000\"],[\"79472.30\",\"0.380\"],[\"79480.30\",\"0.817\"],[\"79482.90\",\"0.606\"],[\"79502.60\",\"0.568\"]],\"a\":[[\"79544.00\",\"5.308\"],[\"79549.40\",\"0.023\"],[\"79615.60\",\"0.006\"],[\"79624.50\",\"0.005\"],[\"79624.60\",\"0.001\"],[\"79625.20\",\"0.006\"],[\"79635.90\",\"0.453\"],[\"79636.00\",\"0.002\"],[\"79637.20\",\"0.017\"],[\"79640.80\",\"0.002\"],[\"79666.30\",\"0.000\"],[\"79933.80\",\"0.000\"],[\"79936.40\",\"0.133\"],[\"79937.70\",\"0.022\"],[\"79939.70\",\"0.168\"],[\"79941.80\",\"0.001\"],[\"80175.00\",\"4.865\"],[\"80299.70\",\"2.300\"],[\"80339.40\",\"2.672\"],[\"80521.40\",\"10.414\"]],\"st\":1}}"}
{"receive_ns":1788580703259114000,"stream":"btcusdt@bookTicker","event_type":"bookTicker","event_time_ms":1788580703291,"raw_json":"{\"stream\":\"btcusdt@bookTicker\",\"data\":{\"e\":\"bookTicker\",\"u\":11479472889040,\"s\":\"BTCUSDT\",\"ps\":\"BTCUSDT\",\"b\":\"79543.90\",\"B\":\"6.489\",\"a\":\"79544.00\",\"A\":\"5.308\",\"T\":1788580703291,\"E\":1788580703291,\"st\":1}}"}
{"receive_ns":1788580703259347000,"stream":"btcusdt@bookTicker","event_type":"bookTicker","event_time_ms":1788580703293,"raw_json":"{\"stream\":\"btcusdt@bookTicker\",\"data\":{\"e\":\"bookTicker\",\"u\":11479472889158,\"s\":\"BTCUSDT\",\"ps\":\"BTCUSDT\",\"b\":\"79543.90\",\"B\":\"6.490\",\"a\":\"79544.00\",\"A\":\"5.308\",\"T\":1788580703293,\"E\":1788580703293,\"st\":1}}"}
{"receive_ns":1788580703270182000,"stream":"btcusdt@depth@100ms","event_type":"depthUpdate","event_time_ms":1788580703327,"raw_json":"{\"stream\":\"btcusdt@depth@100ms\",\"data\":{\"e\":\"depthUpdate\",\"E\":1788580703327,\"T\":1788580703325,\"s\":\"BTCUSDT\",\"ps\":\"BTCUSDT\",\"U\":11479472884517,\"u\":11479472890588,\"pu\":11479472884403,\"b\":[[\"29043.90\",\"1.876\"],[\"29143.90\",\"0.105\"],[\"29443.90\",\"0.119\"],[\"71589.50\",\"0.010\"],[\"76362.10\",\"0.002\"],[\"78311.00\",\"5.596\"],[\"78468.80\",\"0.000\"],[\"78562.00\",\"8.272\"],[\"78748.50\",\"3.170\"],[\"79419.40\",\"0.450\"],[\"79456.40\",\"0.010\"],[\"79474.60\",\"22.947\"],[\"79476.00\",\"1.485\"],[\"79477.20\",\"0.027\"],[\"79478.80\",\"1.282\"],[\"79517.30\",\"0.454\"],[\"79518.80\",\"0.002\"],[\"79524.30\",\"0.005\"],[\"79525.40\",\"0.419\"],[\"79525.50\",\"0.001\"],[\"79543.90\",\"6.490\"]],\"a\":[[\"79563.90\",\"0.002\"],[\"79564.10\",\"0.451\"],[\"79564.90\",\"0.441\"],[\"79565.30\",\"0.375\"],[\"79614.00\",\"0.011\"],[\"79620.00\",\"16.148\"],[\"79623.00\",\"0.009\"],[\"79628.30\",\"29.852\"],[\"79666.30\",\"0.437\"],[\"79668.10\",\"0.013\"],[\"79701.30\",\"0.100\"],[\"79939.70\",\"0.173\"],[\"80339.40\",\"2.672\"],[\"80578.10\",\"0.374\"],[\"80591.60\",\"4.957\"],[\"80686.30\",\"0.298\"],[\"87498.40\",\"0.003\"]],\"st\":1}}"}
{"receive_ns":1788580703321999000,"stream":"btcusdt@bookTicker","event_type":"bookTicker","event_time_ms":1788580703336,"raw_json":"{\"stream\":\"btcusdt@bookTicker\",\"data\":{\"e\":\"bookTicker\",\"u\":11479472891129,\"s\":\"BTCUSDT\",\"ps\":\"BTCUSDT\",\"b\":\"79543.90\",\"B\":\"6.398\",\"a\":\"79544.00\",\"A\":\"5.308\",\"T\":1788580703336,\"E\":1788580703336,\"st\":1}}"}
{"receive_ns":1788580703322172000,"stream":"btcusdt@bookTicker","event_type":"bookTicker","event_time_ms":1788580703339,"raw_json":"{\"stream\":\"btcusdt@bookTicker\",\"data\":{\"e\":\"bookTicker\",\"u\":11479472891350,\"s\":\"BTCUSDT\",\"ps\":\"BTCUSDT\",\"b\":\"79543.90\",\"B\":\"6.498\",\"a\":\"79544.00\",\"A\":\"5.308\",\"T\":1788580703339,\"E\":1788580703339,\"st\":1}}"}
{"receive_ns":1788580703322684000,"stream":"btcusdt@bookTicker","event_type":"bookTicker","event_time_ms":1788580703340,"raw_json":"{\"stream\":\"btcusdt@bookTicker\",\"data\":{\"e\":\"bookTicker\",\"u\":11479472891460,\"s\":\"BTCUSDT\",\"ps\":\"BTCUSDT\",\"b\":\"79543.90\",\"B\":\"6.498\",\"a\":\"79544.00\",\"A\":\"5.310\",\"T\":1788580703340,\"E\":1788580703340,\"st\":1}}"}
{"receive_ns":1788580703322821000,"stream":"btcusdt@bookTicker","event_type":"bookTicker","event_time_ms":1788580703348,"raw_json":"{\"stream\":\"btcusdt@bookTicker\",\"data\":{\"e\":\"bookTicker\",\"u\":11479472891903,\"s\":\"BTCUSDT\",\"ps\":\"BTCUSDT\",\"b\":\"79543.90\",\"B\":\"6.496\",\"a\":\"79544.00\",\"A\":\"5.310\",\"T\":1788580703348,\"E\":1788580703348,\"st\":1}}"}
{"receive_ns":1788580703322945000,"stream":"btcusdt@bookTicker","event_type":"bookTicker","event_time_ms":1788580703357,"raw_json":"{\"stream\":\"btcusdt@bookTicker\",\"data\":{\"e\":\"bookTicker\",\"u\":11479472892397,\"s\":\"BTCUSDT\",\"ps\":\"BTCUSDT\",\"b\":\"79543.90\",\"B\":\"6.497\",\"a\":\"79544.00\",\"A\":\"5.310\",\"T\":1788580703356,\"E\":1788580703357,\"st\":1}}"}
{"receive_ns":1788580703383006000,"stream":"btcusdt@depth@100ms","event_type":"depthUpdate","event_time_ms":1788580703429,"raw_json":"{\"stream\":\"btcusdt@depth@100ms\",\"data\":{\"e\":\"depthUpdate\",\"E\":1788580703429,\"T\":1788580703428,\"s\":\"BTCUSDT\",\"ps\":\"BTCUSDT\",\"U\":11479472890679,\"u\":11479472896885,\"pu\":11479472890588,\"b\":[[\"1000.00\",\"25.504\"],[\"29043.90\",\"1.897\"],[\"29143.90\",\"0.007\"],[\"29443.90\",\"0.196\"],[\"71589.50\",\"0.010\"],[\"76362.10\",\"0.000\"],[\"78748.50\",\"3.170\"],[\"79146.20\",\"3.402\"],[\"79453.10\",\"0.020\"],[\"79456.40\",\"0.318\"],[\"79472.30\",\"0.380\"],[\"79480.30\",\"0.509\"],[\"79482.90\",\"0.586\"],[\"79488.20\",\"0.128\"],[\"79518.30\",\"0.766\"],[\"79524.80\",\"1.010\"],[\"79525.40\",\"0.046\"],[\"79527.50\",\"0.011\"],[\"79528.10\",\"0.141\"],[\"79528.40\",\"0.491\"],[\"79529.30\",\"0.106\"],[\"79529.40\",\"0.160\"],[\"79531.10\",\"0.258\"],[\"79531.50\",\"0.003\"],[\"79538.00\",\"0.007\"],[\"79538.30\",\"0.002\"],[\"79539.70\",\"1.944\"],[\"79540.60\",\"0.252\"],[\"79543.90\",\"6.497\"]],\"a\":[[\"79544.00\",\"5.310\"],[\"79560.00\",\"0.089\"],[\"79599.70\",\"0.052\"],[\"79615.60\",\"0.004\"],[\"79623.00\",\"29.861\"],[\"79628.30\",\"0.000\"],[\"79933.80\",\"0.037\"],[\"79936.40\",\"0.133\"],[\"79937.70\",\"0.004\"],[\"79939.70\",\"0.154\"],[\"80260.00\",\"1.450\"],[\"80339.40\",\"2.672\"],[\"87498.40\",\"0.005\"]],\"st\":1}}"}
{"receive_ns":1788580703450566000,"stream":"btcusdt@bookTicker","event_type":"bookTicker","event_time_ms":1788580703483,"raw_json":"{\"stream\":\"btcusdt@bookTicker\",\"data\":{\"e\":\"bookTicker\",\"u\":11479472899812,\"s\":\"BTCUSDT\",\"ps\":\"BTCUSDT\",\"b\":\"79543.90\",\"B\":\"6.381\",\"a\":\"79544.00\",\"A\":\"5.310\",\"T\":1788580703483,\"E\":1788580703483,\"st\":1}}"}
{"receive_ns":1788580703450833000,"stream":"btcusdt@bookTicker","event_type":"bookTicker","event_time_ms":1788580703486,"raw_json":"{\"stream\":\"btcusdt@bookTicker\",\"data\":{\"e\":\"bookTicker\",\"u\":11479472899970,\"s\":\"BTCUSDT\",\"ps\":\"BTCUSDT\",\"b\":\"79543.90\",\"B\":\"6.509\",\"a\":\"79544.00\",\"A\":\"5.310\",\"T\":1788580703486,\"E\":1788580703486,\"st\":1}}"}
{"receive_ns":1788580703501964000,"stream":"btcusdt@depth@100ms","event_type":"depthUpdate","event_time_ms":1788580703531,"raw_json":"{\"stream\":\"btcusdt@depth@100ms\",\"data\":{\"e\":\"depthUpdate\",\"E\":1788580703531,\"T\":1788580703530,\"s\":\"BTCUSDT\",\"ps\":\"BTCUSDT\",\"U\":11479472896933,\"u\":11479472901706,\"pu\":11479472896885,\"b\":[[\"1000.00\",\"25.354\"],[\"29043.90\",\"1.729\"],[\"29143.90\",\"0.000\"],[\"29443.90\",\"0.371\"],[\"71589.50\",\"0.010\"],[\"76362.10\",\"0.002\"],[\"77727.50\",\"0.003\"],[\"78430.30\",\"21.394\"],[\"78748.50\",\"4.438\"],[\"79456.40\",\"0.318\"],[\"79500.10\",\"0.692\"],[\"79518.30\",\"0.138\"],[\"79518.40\",\"0.026\"],[\"79523.80\",\"0.373\"],[\"79524.70\",\"0.001\"],[\"79524.80\",\"0.637\"],[\"79525.20\",\"0.046\"],[\"79525.90\",\"0.011\"],[\"79526.40\",\"0.003\"],[\"79526.90\",\"0.007\"],[\"79527.50\",\"0.005\"],[\"79527.80\",\"0.225\"],[\"79528.40\",\"0.617\"],[\"79529.10\",\"0.229\"],[\"79529.30\",\"0.032\"],[\"79529.40\",\"0.154\"],[\"79529.50\",\"0.317\"],[\"79529.60\",\"0.002\"],[\"79529.70\",\"0.159\"],[\"79529.80\",\"0.631\"],[\"79533.50\",\"0.081\"],[\"79539.70\",\"1.944\"],[\"79543.90\",\"6.509\"]],\"a\":[[\"79560.00\",\"0.013\"],[\"79564.40\",\"0.530\"],[\"79564.70\",\"0.375\"],[\"79564.90\",\"0.002\"],[\"79565.30\",\"0.002\"],[\"79565.50\",\"0.118\"],[\"79565.90\",\"0.000\"],[\"79589.60\",\"0.252\"],[\"79590.30\",\"0.046\"],[\"79626.80\",\"0.009\"],[\"79939.70\",\"0.154\"],[\"80339.40\",\"2.672\"],[\"80458.80\",\"0.248\"],[\"80493.20\",\"14.890\"]],\"st\":1}}"}
{"receive_ns":1788580703502276000,"stream":"btcusdt@bookTicker","event_type":"bookTicker","event_time_ms":1788580703546,"raw_json":"{\"stream\":\"btcusdt@bookTicker\",\"data\":{\"e\":\"bookTicker\",\"u\":11479472902405,\"s\":\"BTCUSDT\",\"ps\":\"BTCUSDT\",\"b\":\"79543.90\",\"B\":\"6.330\",\"a\":\"79544.00\",\"A\":\"5.310\",\"T\":1788580703545,\"E\":1788580703546,\"st\":1}}"}
{"receive_ns":1788580703502564000,"stream":"btcusdt@bookTicker","event_type":"bookTicker","event_time_ms":1788580703548,"raw_json":"{\"stream\":\"btcusdt@bookTicker\",\"data\":{\"e\":\"bookTicker\",\"u\":11479472902559,\"s\":\"BTCUSDT\",\"ps\":\"BTCUSDT\",\"b\":\"79543.90\",\"B\":\"6.528\",\"a\":\"79544.00\",\"A\":\"5.310\",\"T\":1788580703548,\"E\":1788580703548,\"st\":1}}"}
{"receive_ns":1788580703509936000,"stream":"btcusdt@bookTicker","event_type":"bookTicker","event_time_ms":1788580703567,"raw_json":"{\"stream\":\"btcusdt@bookTicker\",\"data\":{\"e\":\"bookTicker\",\"u\":11479472903223,\"s\":\"BTCUSDT\",\"ps\":\"BTCUSDT\",\"b\":\"79543.90\",\"B\":\"6.527\",\"a\":\"79544.00\",\"A\":\"5.310\",\"T\":1788580703566,\"E\":1788580703567,\"st\":1}}"}
{"receive_ns":1788580703519602000,"stream":"btcusdt@bookTicker","event_type":"bookTicker","event_time_ms":1788580703575,"raw_json":"{\"stream\":\"btcusdt@bookTicker\",\"data\":{\"e\":\"bookTicker\",\"u\":11479472903562,\"s\":\"BTCUSDT\",\"ps\":\"BTCUSDT\",\"b\":\"79543.90\",\"B\":\"6.529\",\"a\":\"79544.00\",\"A\":\"5.310\",\"T\":1788580703575,\"E\":1788580703575,\"st\":1}}"}
{"receive_ns":1788580703525583000,"stream":"btcusdt@bookTicker","event_type":"bookTicker","event_time_ms":1788580703582,"raw_json":"{\"stream\":\"btcusdt@bookTicker\",\"data\":{\"e\":\"bookTicker\",\"u\":11479472903758,\"s\":\"BTCUSDT\",\"ps\":\"BTCUSDT\",\"b\":\"79543.90\",\"B\":\"6.528\",\"a\":\"79544.00\",\"A\":\"5.310\",\"T\":1788580703581,\"E\":1788580703582,\"st\":1}}"}
{"receive_ns":1788580703580405000,"stream":"btcusdt@depth@100ms","event_type":"depthUpdate","event_time_ms":1788580703633,"raw_json":"{\"stream\":\"btcusdt@depth@100ms\",\"data\":{\"e\":\"depthUpdate\",\"E\":1788580703633,\"T\":1788580703632,\"s\":\"BTCUSDT\",\"ps\":\"BTCUSDT\",\"U\":11479472901765,\"u\":11479472906383,\"pu\":11479472901706,\"b\":[[\"29043.90\",\"1.554\"],[\"29443.90\",\"0.546\"],[\"63635.00\",\"0.000\"],[\"71589.50\",\"0.012\"],[\"78589.40\",\"20.265\"],[\"78748.50\",\"4.438\"],[\"78907.50\",\"5.944\"],[\"79453.10\",\"0.020\"],[\"79456.40\",\"0.268\"],[\"79517.30\",\"0.002\"],[\"79518.70\",\"0.591\"],[\"79520.70\",\"0.012\"],[\"79523.80\",\"0.000\"],[\"79524.50\",\"0.049\"],[\"79525.20\",\"0.373\"],[\"79526.90\",\"0.001\"],[\"79527.50\",\"0.011\"],[\"79528.20\",\"0.102\"],[\"79528.40\",\"0.177\"],[\"79528.50\",\"0.440\"],[\"79529.30\",\"0.736\"],[\"79529.60\",\"0.006\"],[\"79529.80\",\"0.003\"],[\"79530.00\",\"0.003\"],[\"79533.50\",\"0.001\"],[\"79538.00\",\"0.003\"],[\"79538.30\",\"0.006\"],[\"79539.70\",\"1.944\"],[\"79543.90\",\"6.528\"]],\"a\":[[\"79549.40\",\"0.000\"],[\"79564.40\",\"0.091\"],[\"79564.90\",\"0.441\"],[\"79567.00\",\"0.003\"],[\"79568.20\",\"0.453\"],[\"79568.30\",\"0.405\"],[\"79570.60\",\"0.048\"],[\"79571.20\",\"0.000\"],[\"79588.30\",\"0.201\"],[\"79589.40\",\"0.063\"],[\"79590.30\",\"0.000\"],[\"79933.80\",\"0.037\"],[\"79936.40\",\"0.133\"],[\"79939.70\",\"0.122\"],[\"80180.40\",\"2.240\"],[\"80339.40\",\"3.915\"],[\"80498.50\",\"23.071\"],[\"80652.20\",\"32.950\"],[\"80657.60\",\"21.986\"]],\"st\":1}}"}
{"receive_ns":1788580703686124000,"stream":"btcusdt@depth@100ms","event_type":"depthUpdate","event_time_ms":1788580703735,"raw_json":"{\"stream\":\"btcusdt@depth@100ms\",\"data\":{\"e\":\"depthUpdate\",\"E\":1788580703735,\"T\":1788580703734,\"s\":\"BTCUSDT\",\"ps\":\"BTCUSDT\",\"U\":11479472906408,\"u\":11479472910894,\"pu\":11479472906383,\"b\":[[\"1000.00\",\"25.354\"],[\"29043.90\",\"1.372\"],[\"29443.90\",\"0.728\"],[\"71589.50\",\"0.010\"],[\"76362.10\",\"0.000\"],[\"78748.50\",\"4.438\"],[\"79146.20\",\"3.402\"],[\"79456.40\",\"0.308\"],[\"79474.60\",\"0.001\"],[\"79477.20\",\"22.973\"],[\"79539.70\",\"1.944\"],[\"79543.90\",\"6.527\"]],\"a\":[[\"79550.40\",\"0.029\"],[\"79550.60\",\"0.066\"],[\"79939.70\",\"0.149\"],[\"80339.40\",\"3.915\"],[\"80498.50\",\"24.312\"],[\"80551.10\",\"5.988\"],[\"80686.30\",\"0.149\"],[\"80771.50\",\"5.935\"],[\"81134.80\",\"0.015\"]],\"st\":1}}"}
{"receive_ns":1788580703686417000,"stream":"btcusdt@bookTicker","event_type":"bookTicker","event_time_ms":1788580703734,"raw_json":"{\"stream\":\"btcusdt@bookTicker\",\"data\":{\"e\":\"bookTicker\",\"u\":11479472910894,\"s\":\"BTCUSDT\",\"ps\":\"BTCUSDT\",\"b\":\"79543.90\",\"B\":\"6.527\",\"a\":\"79544.00\",\"A\":\"5.310\",\"T\":1788580703734,\"E\":1788580703734,\"st\":1}}"}
{"receive_ns":1788580703686607000,"stream":"btcusdt@bookTicker","event_type":"bookTicker","event_time_ms":1788580703736,"raw_json":"{\"stream\":\"btcusdt@bookTicker\",\"data\":{\"e\":\"bookTicker\",\"u\":11479472911044,\"s\":\"BTCUSDT\",\"ps\":\"BTCUSDT\",\"b\":\"79543.90\",\"B\":\"6.528\",\"a\":\"79544.00\",\"A\":\"5.310\",\"T\":1788580703736,\"E\":1788580703736,\"st\":1}}"}
{"receive_ns":1788580703704543000,"stream":"btcusdt@bookTicker","event_type":"bookTicker","event_time_ms":1788580703760,"raw_json":"{\"stream\":\"btcusdt@bookTicker\",\"data\":{\"e\":\"bookTicker\",\"u\":11479472911817,\"s\":\"BTCUSDT\",\"ps\":\"BTCUSDT\",\"b\":\"79543.90\",\"B\":\"6.528\",\"a\":\"79544.00\",\"A\":\"5.287\",\"T\":1788580703760,\"E\":1788580703760,\"st\":1}}"}
{"receive_ns":1788580703745583000,"stream":"btcusdt@bookTicker","event_type":"bookTicker","event_time_ms":1788580703793,"raw_json":"{\"stream\":\"btcusdt@bookTicker\",\"data\":{\"e\":\"bookTicker\",\"u\":11479472914548,\"s\":\"BTCUSDT\",\"ps\":\"BTCUSDT\",\"b\":\"79543.90\",\"B\":\"6.526\",\"a\":\"79544.00\",\"A\":\"5.287\",\"T\":1788580703793,\"E\":1788580703793,\"st\":1}}"}
{"receive_ns":1788580703745840000,"stream":"btcusdt@bookTicker","event_type":"bookTicker","event_time_ms":1788580703800,"raw_json":"{\"stream\":\"btcusdt@bookTicker\",\"data\":{\"e\":\"bookTicker\",\"u\":11479472915047,\"s\":\"BTCUSDT\",\"ps\":\"BTCUSDT\",\"b\":\"79543.90\",\"B\":\"6.527\",\"a\":\"79544.00\",\"A\":\"5.287\",\"T\":1788580703800,\"E\":1788580703800,\"st\":1}}"}
{"receive_ns":1788580703810653000,"stream":"btcusdt@depth@100ms","event_type":"depthUpdate","event_time_ms":1788580703837,"raw_json":"{\"stream\":\"btcusdt@depth@100ms\",\"data\":{\"e\":\"depthUpdate\",\"E\":1788580703837,\"T\":1788580703833,\"s\":\"BTCUSDT\",\"ps\":\"BTCUSDT\",\"U\":11479472910900,\"u\":11479472916496,\"pu\":11479472910894,\"b\":[[\"1000.00\",\"25.354\"],[\"29043.90\",\"1.197\"],[\"29443.90\",\"0.903\"],[\"71589.50\",\"0.010\"],[\"76362.10\",\"0.002\"],[\"78452.60\",\"7.640\"],[\"78748.50\",\"4.438\"],[\"78907.50\",\"6.197\"],[\"79452.30\",\"0.001\"],[\"79453.10\",\"0.000\"],[\"79456.40\",\"0.060\"],[\"79474.60\",\"22.947\"],[\"79477.20\",\"0.027\"],[\"79539.70\",\"1.945\"],[\"79543.90\",\"6.527\"]],\"a\":[[\"79544.00\",\"5.287\"],[\"79574.30\",\"0.001\"],[\"79580.70\",\"0.149\"],[\"79590.50\",\"0.056\"],[\"79635.40\",\"0.015\"],[\"79933.80\",\"0.000\"],[\"79936.40\",\"0.126\"],[\"79939.70\",\"0.037\"],[\"80339.40\",\"3.915\"],[\"80630.60\",\"10.739\"],[\"80673.50\",\"0.596\"],[\"80776.90\",\"4.357\"]],\"st\":1}}"}
{"receive_ns":1788580703811011000,"stream":"btcusdt@bookTicker","event_type":"bookTicker","event_time_ms":1788580703843,"raw_json":"{\"stream\":\"btcusdt@bookTicker\",\"data\":{\"e\":\"bookTicker\",\"u\":11479472916898,\"s\":\"BTCUSDT\",\"ps\":\"BTCUSDT\",\"b\":\"79543.90\",\"B\":\"6.525\",\"a\":\"79544.00\",\"A\":\"5.287\",\"T\":1788580703843,\"E\":1788580703843,\"st\":1}}"}
{"receive_ns":1788580703882787000,"stream":"btcusdt@depth@100ms","event_type":"depthUpdate","event_time_ms":1788580703939,"raw_json":"{\"stream\":\"btcusdt@depth@100ms\",\"data\":{\"e\":\"depthUpdate\",\"E\":1788580703939,\"T\":1788580703933,\"s\":\"BTCUSDT\",\"ps\":\"BTCUSDT\",\"U\":11479472916645,\"u\":11479472921758,\"pu\":11479472916496,\"b\":[[\"29043.90\",\"1.022\"],[\"29443.90\",\"1.078\"],[\"63635.00\",\"0.000\"],[\"71589.50\",\"0.010\"],[\"75566.70\",\"0.018\"],[\"76362.10\",\"0.000\"],[\"78668.90\",\"2.409\"],[\"78748.50\",\"4.438\"],[\"78840.50\",\"11.357\"],[\"79358.70\",\"0.001\"],[\"79360.10\",\"3.143\"],[\"79364.00\",\"1.185\"],[\"79456.40\",\"0.268\"],[\"79457.10\",\"0.020\"],[\"79458.30\",\"0.057\"],[\"79458.50\",\"0.198\"],[\"79480.30\",\"0.559\"],[\"79543.90\",\"6.525\"]],\"a\":[[\"79633.40\",\"0.039\"],[\"79633.60\",\"0.001\"],[\"79687.40\",\"3.143\"],[\"79687.50\",\"0.001\"],[\"79936.40\",\"0.133\"],[\"79937.70\",\"0.059\"],[\"79939.70\",\"0.136\"],[\"80339.40\",\"3.915\"],[\"80439.00\",\"0.001\"],[\"80657.60\",\"23.843\"]],\"st\":1}}"}
{"receive_ns":1788580703962709000,"stream":"btcusdt@bookTicker","event_type":"bookTicker","event_time_ms":1788580704010,"raw_json":"{\"stream\":\"btcusdt@bookTicker\",\"data\":{\"e\":\"bookTicker\",\"u\":11479472924963,\"s\":\"BTCUSDT\",\"ps\":\"BTCUSDT\",\"b\":\"79543.90\",\"B\":\"6.524\",\"a\":\"79544.00\",\"A\":\"5.287\",\"T\":1788580704010,\"E\":1788580704010,\"st\":1}}"}
{"receive_ns":1788580703963030000,"stream":"btcusdt@bookTicker","event_type":"bookTicker","event_time_ms":1788580704012,"raw_json":"{\"stream\":\"btcusdt@bookTicker\",\"data\":{\"e\":\"bookTicker\",\"u\":11479472925083,\"s\":\"BTCUSDT\",\"ps\":\"BTCUSDT\",\"b\":\"79543.90\",\"B\":\"6.526\",\"a\":\"79544.00\",\"A\":\"5.287\",\"T\":1788580704012,\"E\":1788580704012,\"st\":1}}"}
{"receive_ns":1788580704016943000,"stream":"btcusdt@depth@100ms","event_type":"depthUpdate","event_time_ms":1788580704041,"raw_json":"{\"stream\":\"btcusdt@depth@100ms\",\"data\":{\"e\":\"depthUpdate\",\"E\":1788580704041,\"T\":1788580704039,\"s\":\"BTCUSDT\",\"ps\":\"BTCUSDT\",\"U\":11479472922029,\"u\":11479472926102,\"pu\":11479472921758,\"b\":[[\"1000.00\",\"25.354\"],[\"29043.90\",\"0.840\"],[\"29443.90\",\"1.260\"],[\"63635.00\",\"0.000\"],[\"71589.50\",\"0.010\"],[\"78112.10\",\"0.510\"],[\"78748.40\",\"0.000\"],[\"78748.50\",\"4.438\"],[\"79146.20\",\"3.402\"],[\"79398.80\",\"19.135\"],[\"79400.00\",\"21.350\"],[\"79419.40\",\"0.300\"],[\"79452.30\",\"2.959\"],[\"79456.40\",\"0.268\"],[\"79529.60\",\"0.010\"],[\"79543.90\",\"6.526\"]],\"a\":[[\"79635.20\",\"3.894\"],[\"79666.30\",\"0.288\"],[\"79668.10\",\"0.013\"],[\"79688.00\",\"0.569\"],[\"79688.70\",\"17.568\"],[\"79689.00\",\"0.010\"],[\"79693.60\",\"0.000\"],[\"79765.90\",\"19.178\"],[\"79766.00\",\"0.196\"],[\"79939.70\",\"0.136\"],[\"80339.40\",\"3.915\"],[\"81395.70\",\"0.003\"]],\"st\":1}}"}
{"receive_ns":1788580704075279000,"stream":"btcusdt@bookTicker","event_type":"bookTicker","event_time_ms":1788580704095,"raw_json":"{\"stream\":\"btcusdt@bookTicker\",\"data\":{\"e\":\"bookTicker\",\"u\":11479472929103,\"s\":\"BTCUSDT\",\"ps\":\"BTCUSDT\",\"b\":\"79543.90\",\"B\":\"6.526\",\"a\":\"79544.00\",\"A\":\"5.250\",\"T\":1788580704095,\"E\":1788580704095,\"st\":1}}"}
{"receive_ns":1788580704075524000,"stream":"btcusdt@bookTicker","event_type":"bookTicker","event_time_ms":1788580704101,"raw_json":"{\"stream\":\"btcusdt@bookTicker\",\"data\":{\"e\":\"bookTicker\",\"u\":11479472929675,\"s\":\"BTCUSDT\",\"ps\":\"BTCUSDT\",\"b\":\"79543.90\",\"B\":\"6.526\",\"a\":\"79544.00\",\"A\":\"5.290\",\"T\":1788580704100,\"E\":1788580704101,\"st\":1}}"}
{"receive_ns":1788580704085663000,"stream":"btcusdt@depth@100ms","event_type":"depthUpdate","event_time_ms":1788580704143,"raw_json":"{\"stream\":\"btcusdt@depth@100ms\",\"data\":{\"e\":\"depthUpdate\",\"E\":1788580704143,\"T\":1788580704141,\"s\":\"BTCUSDT\",\"ps\":\"BTCUSDT\",\"U\":11479472926158,\"u\":11479472932321,\"pu\":11479472926102,\"b\":[[\"1000.00\",\"25.354\"],[\"29043.90\",\"0.658\"],[\"29443.90\",\"1.442\"],[\"63635.00\",\"0.000\"],[\"63635.10\",\"0.000\"],[\"71589.50\",\"0.010\"],[\"75566.70\",\"0.016\"],[\"75566.80\",\"0.006\"],[\"76362.10\",\"0.002\"],[\"78482.50\",\"11.992\"],[\"78748.50\",\"4.438\"],[\"79453.10\",\"0.020\"],[\"79456.40\",\"0.268\"],[\"79457.10\",\"0.000\"],[\"79480.30\",\"0.509\"],[\"79520.20\",\"2.393\"],[\"79529.60\",\"0.006\"]],\"a\":[[\"79544.00\",\"5.290\"],[\"79549.50\",\"0.023\"],[\"79554.50\",\"0.155\"],[\"79559.40\",\"0.628\"],[\"79560.10\",\"0.002\"],[\"79624.50\",\"0.006\"],[\"79625.20\",\"0.004\"],[\"79933.80\",\"0.037\"],[\"79936.40\",\"0.133\"],[\"79937.70\",\"0.004\"],[\"79939.70\",\"0.122\"],[\"80339.40\",\"3.915\"]],\"st\":1}}"}
{"receive_ns":1788580704192029000,"stream":"btcusdt@bookTicker","event_type":"bookTicker","event_time_ms":1788580704235,"raw_json":"{\"stream\":\"btcusdt@bookTicker\",\"data\":{\"e\":\"bookTicker\",\"u\":11479472939327,\"s\":\"BTCUSDT\",\"ps\":\"BTCUSDT\",\"b\":\"79543.90\",\"B\":\"6.524\",\"a\":\"79544.00\",\"A\":\"5.290\",\"T\":1788580704235,\"E\":1788580704235,\"st\":1}}"}
{"receive_ns":1788580704192227000,"stream":"btcusdt@bookTicker","event_type":"bookTicker","event_time_ms":1788580704243,"raw_json":"{\"stream\":\"btcusdt@bookTicker\",\"data\":{\"e\":\"bookTicker\",\"u\":11479472939900,\"s\":\"BTCUSDT\",\"ps\":\"BTCUSDT\",\"b\":\"79543.90\",\"B\":\"6.525\",\"a\":\"79544.00\",\"A\":\"5.290\",\"T\":1788580704243,\"E\":1788580704243,\"st\":1}}"}
{"receive_ns":1788580704192528000,"stream":"btcusdt@depth@100ms","event_type":"depthUpdate","event_time_ms":1788580704245,"raw_json":"{\"stream\":\"btcusdt@depth@100ms\",\"data\":{\"e\":\"depthUpdate\",\"E\":1788580704245,\"T\":1788580704244,\"s\":\"BTCUSDT\",\"ps\":\"BTCUSDT\",\"U\":11479472932498,\"u\":11479472939940,\"pu\":11479472932321,\"b\":[[\"29043.90\",\"0.483\"],[\"29443.90\",\"1.617\"],[\"71589.50\",\"0.010\"],[\"76362.10\",\"0.000\"],[\"77953.10\",\"0.012\"],[\"78611.70\",\"8.766\"],[\"78748.50\",\"4.438\"],[\"78907.50\",\"6.197\"],[\"79146.10\",\"0.009\"],[\"79456.40\",\"0.308\"],[\"79520.20\",\"2.395\"],[\"79543.90\",\"6.525\"]],\"a\":[[\"79554.50\",\"0.783\"],[\"79559.40\",\"0.000\"],[\"79560.10\",\"0.004\"],[\"79575.80\",\"0.282\"],[\"79620.00\",\"20.611\"],[\"79635.90\",\"0.452\"],[\"79688.00\",\"3.106\"],[\"79937.70\",\"0.022\"],[\"79939.70\",\"0.131\"],[\"79941.80\",\"0.001\"],[\"79954.40\",\"0.124\"],[\"80279.80\",\"0.001\"],[\"80339.40\",\"3.917\"],[\"81134.80\",\"0.012\"]],\"st\":1}}"}
{"receive_ns":1788580704318875000,"stream":"btcusdt@bookTicker","event_type":"bookTicker","event_time_ms":1788580704293,"raw_json":"{\"stream\":\"btcusdt@bookTicker\",\"data\":{\"e\":\"bookTicker\",\"u\":11479472943238,\"s\":\"BTCUSDT\",\"ps\":\"BTCUSDT\",\"b\":\"79543.90\",\"B\":\"6.525\",\"a\":\"79544.00\",\"A\":\"5.274\",\"T\":1788580704293,\"E\":1788580704293,\"st\":1}}"}
{"receive_ns":1788580704319152000,"stream":"btcusdt@bookTicker","event_type":"bookTicker","event_time_ms":1788580704295,"raw_json":"{\"stream\":\"btcusdt@bookTicker\",\"data\":{\"e\":\"bookTicker\",\"u\":11479472943485,\"s\":\"BTCUSDT\",\"ps\":\"BTCUSDT\",\"b\":\"79543.90\",\"B\":\"6.525\",\"a\":\"79544.00\",\"A\":\"5.291\",\"T\":1788580704295,\"E\":1788580704295,\"st\":1}}"}
{"receive_ns":1788580704319520000,"stream":"btcusdt@bookTicker","event_type":"bookTicker","event_time_ms":1788580704312,"raw_json":"{\"stream\":\"btcusdt@bookTicker\",\"data\":{\"e\":\"bookTicker\",\"u\":11479472944697,\"s\":\"BTCUSDT\",\"ps\":\"BTCUSDT\",\"b\":\"79543.90\",\"B\":\"6.524\",\"a\":\"79544.00\",\"A\":\"5.291\",\"T\":1788580704311,\"E\":1788580704312,\"st\":1}}"}
{"receive_ns":1788580704319803000,"stream":"btcusdt@bookTicker","event_type":"bookTicker","event_time_ms":1788580704314,"raw_json":"{\"stream\":\"btcusdt@bookTicker\",\"data\":{\"e\":\"bookTicker\",\"u\":11479472944833,\"s\":\"BTCUSDT\",\"ps\":\"BTCUSDT\",\"b\":\"79543.90\",\"B\":\"6.525\",\"a\":\"79544.00\",\"A\":\"5.291\",\"T\":1788580704314,\"E\":1788580704314,\"st\":1}}"}
{"receive_ns":1788580704320174000,"stream":"btcusdt@depth@100ms","event_type":"depthUpdate","event_time_ms":1788580704347,"raw_json":"{\"stream\":\"btcusdt@depth@100ms\",\"data\":{\"e\":\"depthUpdate\",\"E\":1788580704347,\"T\":1788580704345,\"s\":\"BTCUSDT\",\"ps\":\"BTCUSDT\",\"U\":11479472939989,\"u\":11479472946494,\"pu\":11479472939940,\"b\":[[\"1000.00\",\"25.354\"],[\"29043.90\",\"0.315\"],[\"29343.90\",\"0.014\"],[\"29443.90\",\"1.771\"],[\"71589.50\",\"0.010\"],[\"71623.00\",\"0.000\"],[\"75566.70\",\"0.014\"],[\"75566.80\",\"0.008\"],[\"76362.10\",\"0.002\"],[\"78305.80\",\"3.445\"],[\"78748.50\",\"4.438\"],[\"79146.20\",\"3.402\"],[\"79453.10\",\"0.000\"],[\"79456.40\",\"0.060\"],[\"79488.20\",\"0.130\"],[\"79518.50\",\"0.002\"],[\"79543.90\",\"6.525\"]],\"a\":[[\"79544.00\",\"5.291\"],[\"79550.10\",\"0.004\"],[\"79581.70\",\"0.253\"],[\"79615.60\",\"0.006\"],[\"79620.00\",\"16.148\"],[\"79623.00\",\"29.747\"],[\"79626.80\",\"0.033\"],[\"79628.30\",\"0.000\"],[\"79668.10\",\"0.013\"],[\"79933.80\",\"0.000\"],[\"79936.40\",\"0.126\"],[\"79939.70\",\"0.019\"],[\"80339.40\",\"3.915\"],[\"80493.20\",\"14.395\"]],\"st\":1}}"}
{"receive_ns":1788580704320392000,"stream":"btcusdt@bookTicker","event_type":"bookTicker","event_time_ms":1788580704358,"raw_json":"{\"stream\":\"btcusdt@bookTicker\",\"data\":{\"e\":\"bookTicker\",\"u\":11479472947190,\"s\":\"BTCUSDT\",\"ps\":\"BTCUSDT\",\"b\":\"79543.90\",\"B\":\"6.525\",\"a\":\"79544.00\",\"A\":\"5.288\",\"T\":1788580704358,\"E\":1788580704358,\"st\":1}}"}
{"receive_ns":1788580704320606000,"stream":"btcusdt@trade","event_type":"trade","event_time_ms":1788580704358,"raw_json":"{\"stream\":\"btcusdt@trade\",\"data\":{\"e\":\"trade\",\"E\":1788580704358,\"T\":1788580704358,\"s\":\"BTCUSDT\",\"t\":8054266640,\"p\":\"79544.00\",\"q\":\"0.003\",\"X\":\"MARKET\",\"m\":false,\"st\":1}}"}
{"receive_ns":1788580704380235000,"stream":"btcusdt@bookTicker","event_type":"bookTicker","event_time_ms":1788580704432,"raw_json":"{\"stream\":\"btcusdt@bookTicker\",\"data\":{\"e\":\"bookTicker\",\"u\":11479472950608,\"s\":\"BTCUSDT\",\"ps\":\"BTCUSDT\",\"b\":\"79543.90\",\"B\":\"6.525\",\"a\":\"79544.00\",\"A\":\"5.258\",\"T\":1788580704432,\"E\":1788580704432,\"st\":1}}"}
{"receive_ns":1788580704380504000,"stream":"btcusdt@bookTicker","event_type":"bookTicker","event_time_ms":1788580704435,"raw_json":"{\"stream\":\"btcusdt@bookTicker\",\"data\":{\"e\":\"bookTicker\",\"u\":11479472950880,\"s\":\"BTCUSDT\",\"ps\":\"BTCUSDT\",\"b\":\"79543.90\",\"B\":\"6.525\",\"a\":\"79544.00\",\"A\":\"5.289\",\"T\":1788580704434,\"E\":1788580704435,\"st\":1}}"}
{"receive_ns":1788580704391125000,"stream":"btcusdt@depth@100ms","event_type":"depthUpdate","event_time_ms":1788580704449,"raw_json":"{\"stream\":\"btcusdt@depth@100ms\",\"data\":{\"e\":\"depthUpdate\",\"E\":1788580704449,\"T\":1788580704445,\"s\":\"BTCUSDT\",\"ps\":\"BTCUSDT\",\"U\":11479472946617,\"u\":11479472951788,\"pu\":11479472946494,\"b\":[[\"1000.00\",\"25.354\"],[\"29043.90\",\"0.203\"],[\"29343.90\",\"0.077\"],[\"29443.90\",\"1.820\"],[\"71589.50\",\"0.010\"],[\"76362.10\",\"0.000\"],[\"78204.80\",\"4.342\"],[\"78589.40\",\"22.806\"],[\"78748.50\",\"4.438\"],[\"79419.40\",\"0.013\"],[\"79453.10\",\"0.020\"],[\"79456.40\",\"0.318\"],[\"79499.70\",\"0.368\"]],\"a\":[[\"79544.00\",\"5.289\"],[\"79554.00\",\"0.552\"],[\"79666.30\",\"0.000\"],[\"79936.40\",\"0.133\"],[\"79937.70\",\"0.004\"],[\"79939.70\",\"0.191\"],[\"80339.40\",\"3.915\"],[\"80425.60\",\"0.260\"],[\"80493.20\",\"13.154\"],[\"80539.00\",\"1.847\"]],\"st\":1}}"}
{"receive_ns":1788580704443609000,"stream":"btcusdt@bookTicker","event_type":"bookTicker","event_time_ms":1788580704487,"raw_json":"{\"stream\":\"btcusdt@bookTicker\",\"data\":{\"e\":\"bookTicker\",\"u\":11479472954891,\"s\":\"BTCUSDT\",\"ps\":\"BTCUSDT\",\"b\":\"79543.90\",\"B\":\"6.524\",\"a\":\"79544.00\",\"A\":\"5.289\",\"T\":1788580704487,\"E\":1788580704487,\"st\":1}}"}
{"receive_ns":1788580704443893000,"stream":"btcusdt@bookTicker","event_type":"bookTicker","event_time_ms":1788580704493,"raw_json":"{\"stream\":\"btcusdt@bookTicker\",\"data\":{\"e\":\"bookTicker\",\"u\":11479472955491,\"s\":\"BTCUSDT\",\"ps\":\"BTCUSDT\",\"b\":\"79543.90\",\"B\":\"6.526\",\"a\":\"79544.00\",\"A\":\"5.289\",\"T\":1788580704493,\"E\":1788580704493,\"st\":1}}"}
{"receive_ns":1788580704454364000,"stream":"btcusdt@bookTicker","event_type":"bookTicker","event_time_ms":1788580704511,"raw_json":"{\"stream\":\"btcusdt@bookTicker\",\"data\":{\"e\":\"bookTicker\",\"u\":11479472956602,\"s\":\"BTCUSDT\",\"ps\":\"BTCUSDT\",\"b\":\"79543.90\",\"B\":\"6.526\",\"a\":\"79544.00\",\"A\":\"5.298\",\"T\":1788580704511,\"E\":1788580704511,\"st\":1}}"}
{"receive_ns":1788580704495564000,"stream":"btcusdt@depth@100ms","event_type":"depthUpdate","event_time_ms":1788580704551,"raw_json":"{\"stream\":\"btcusdt@depth@100ms\",\"data\":{\"e\":\"depthUpdate\",\"E\":1788580704551,\"T\":1788580704549,\"s\":\"BTCUSDT\",\"ps\":\"BTCUSDT\",\"U\":11479472952087,\"u\":11479472958538,\"pu\":11479472951788,\"b\":[[\"29043.90\",\"0.077\"],[\"29343.90\",\"0.133\"],[\"29443.90\",\"1.890\"],[\"71589.50\",\"0.010\"],[\"75566.70\",\"0.012\"],[\"75566.80\",\"0.010\"],[\"78311.00\",\"6.489\"],[\"78562.00\",\"8.119\"],[\"78642.40\",\"2.286\"],[\"78748.50\",\"4.438\"],[\"79332.20\",\"0.010\"],[\"79335.50\",\"0.488\"],[\"79379.90\",\"0.001\"],[\"79456.40\",\"0.318\"],[\"79543.90\",\"6.526\"]],\"a\":[[\"79544.00\",\"5.298\"],[\"79554.00\",\"0.550\"],[\"79705.70\",\"0.000\"],[\"79753.40\",\"0.748\"],[\"79753.50\",\"0.014\"],[\"79939.70\",\"0.191\"],[\"80339.40\",\"3.915\"],[\"80423.70\",\"1.736\"],[\"80498.50\",\"24.807\"]],\"st\":1}}"}
{"receive_ns":1788580704511264000,"stream":"btcusdt@bookTicker","event_type":"bookTicker","event_time_ms":1788580704567,"raw_json":"{\"stream\":\"btcusdt@bookTicker\",\"data\":{\"e\":\"bookTicker\",\"u\":11479472959346,\"s\":\"BTCUSDT\",\"ps\":\"BTCUSDT\",\"b\":\"79543.90\",\"B\":\"6.328\",\"a\":\"79544.00\",\"A\":\"5.298\",\"T\":1788580704567,\"E\":1788580704567,\"st\":1}}"}
{"receive_ns":1788580704512413000,"stream":"btcusdt@bookTicker","event_type":"bookTicker","event_time_ms":1788580704569,"raw_json":"{\"stream\":\"btcusdt@bookTicker\",\"data\":{\"e\":\"bookTicker\",\"u\":11479472959459,\"s\":\"BTCUSDT\",\"ps\":\"BTCUSDT\",\"b\":\"79543.90\",\"B\":\"6.556\",\"a\":\"79544.00\",\"A\":\"5.298\",\"T\":1788580704569,\"E\":1788580704569,\"st\":1}}"}
{"receive_ns":1788580704513817000,"stream":"btcusdt@bookTicker","event_type":"bookTicker","event_time_ms":1788580704570,"raw_json":"{\"stream\":\"btcusdt@bookTicker\",\"data\":{\"e\":\"bookTicker\",\"u\":11479472959504,\"s\":\"BTCUSDT\",\"ps\":\"BTCUSDT\",\"b\":\"79543.90\",\"B\":\"6.555\",\"a\":\"79544.00\",\"A\":\"5.298\",\"T\":1788580704570,\"E\":1788580704570,\"st\":1}}"}
{"receive_ns":1788580704552950000,"stream":"btcusdt@bookTicker","event_type":"bookTicker","event_time_ms":1788580704581,"raw_json":"{\"stream\":\"btcusdt@bookTicker\",\"data\":{\"e\":\"bookTicker\",\"u\":11479472959977,\"s\":\"BTCUSDT\",\"ps\":\"BTCUSDT\",\"b\":\"79543.90\",\"B\":\"6.556\",\"a\":\"79544.00\",\"A\":\"5.298\",\"T\":1788580704581,\"E\":1788580704581,\"st\":1}}"}
{"receive_ns":1788580704553918000,"stream":"btcusdt@bookTicker","event_type":"bookTicker","event_time_ms":1788580704605,"raw_json":"{\"stream\":\"btcusdt@bookTicker\",\"data\":{\"e\":\"bookTicker\",\"u\":11479472960993,\"s\":\"BTCUSDT\",\"ps\":\"BTCUSDT\",\"b\":\"79543.90\",\"B\":\"6.563\",\"a\":\"79544.00\",\"A\":\"5.298\",\"T\":1788580704605,\"E\":1788580704605,\"st\":1}}"}
{"receive_ns":1788580704621332000,"stream":"btcusdt@depth@100ms","event_type":"depthUpdate","event_time_ms":1788580704653,"raw_json":"{\"stream\":\"btcusdt@depth@100ms\",\"data\":{\"e\":\"depthUpdate\",\"E\":1788580704653,\"T\":1788580704652,\"s\":\"BTCUSDT\",\"ps\":\"BTCUSDT\",\"U\":11479472958638,\"u\":11479472963907,\"pu\":11479472958538,\"b\":[[\"1000.00\",\"25.354\"],[\"29043.90\",\"0.000\"],[\"29343.90\",\"0.231\"],[\"29443.90\",\"1.869\"],[\"63635.00\",\"0.000\"],[\"71589.50\",\"0.010\"],[\"76362.10\",\"0.002\"],[\"78430.30\",\"23.304\"],[\"78482.50\",\"11.801\"],[\"78590.10\",\"0.004\"],[\"78592.80\",\"0.000\"],[\"78602.00\",\"5.720\"],[\"78604.70\",\"0.000\"],[\"78613.90\",\"0.003\"],[\"78619.50\",\"0.000\"],[\"78748.50\",\"4.438\"],[\"79146.20\",\"3.412\"],[\"79332.30\",\"5.068\"],[\"79335.50\",\"1.184\"],[\"79380.10\",\"2.189\"],[\"79419.40\",\"0.452\"],[\"79448.40\",\"0.020\"],[\"79453.10\",\"0.020\"],[\"79456.40\",\"0.318\"],[\"79472.30\",\"0.378\"],[\"79488.20\",\"0.128\"],[\"79538.30\",\"0.002\"],[\"79538.60\",\"0.444\"],[\"79543.90\",\"6.563\"]],\"a\":[[\"79554.50\",\"0.155\"],[\"79559.40\",\"0.628\"],[\"79599.70\",\"0.052\"],[\"79615.60\",\"0.004\"],[\"79666.30\",\"0.437\"],[\"79705.70\",\"1.946\"],[\"79753.40\",\"5.850\"],[\"79933.80\",\"0.018\"],[\"79936.40\",\"0.133\"],[\"79939.70\",\"0.173\"],[\"80339.40\",\"3.915\"],[\"80498.50\",\"26.048\"],[\"80652.20\",\"31.094\"],[\"80771.50\",\"5.069\"],[\"81031.50\",\"2.235\"]],\"st\":1}}"}
{"receive_ns":1788580704621632000,"stream":"btcusdt@bookTicker","event_type":"bookTicker","event_time_ms":1788580704665,"raw_json":"{\"stream\":\"btcusdt@bookTicker\",\"data\":{\"e\":\"bookTicker\",\"u\":11479472964410,\"s\":\"BTCUSDT\",\"ps\":\"BTCUSDT\",\"b\":\"79543.90\",\"B\":\"6.563\",\"a\":\"79544.00\",\"A\":\"5.256\",\"T\":1788580704665,\"E\":1788580704665,\"st\":1}}"}
{"receive_ns":1788580704649076000,"stream":"btcusdt@bookTicker","event_type":"bookTicker","event_time_ms":1788580704705,"raw_json":"{\"stream\":\"btcusdt@bookTicker\",\"data\":{\"e\":\"bookTicker\",\"u\":11479472966781,\"s\":\"BTCUSDT\",\"ps\":\"BTCUSDT\",\"b\":\"79543.90\",\"B\":\"6.561\",\"a\":\"79544.00\",\"A\":\"5.256\",\"T\":1788580704704,\"E\":1788580704705,\"st\":1}}"}
{"receive_ns":1788580704681432000,"stream":"btcusdt@bookTicker","event_type":"bookTicker","event_time_ms":1788580704711,"raw_json":"{\"stream\":\"btcusdt@bookTicker\",\"data\":{\"e\":\"bookTicker\",\"u\":11479472967302,\"s\":\"BTCUSDT\",\"ps\":\"BTCUSDT\",\"b\":\"79543.90\",\"B\":\"6.562\",\"a\":\"79544.00\",\"A\":\"5.256\",\"T\":1788580704711,\"E\":1788580704711,\"st\":1}}"}
{"receive_ns":1788580704681615000,"stream":"btcusdt@bookTicker","event_type":"bookTicker","event_time_ms":1788580704728,"raw_json":"{\"stream\":\"btcusdt@bookTicker\",\"data\":{\"e\":\"bookTicker\",\"u\":11479472968413,\"s\":\"BTCUSDT\",\"ps\":\"BTCUSDT\",\"b\":\"79543.90\",\"B\":\"6.462\",\"a\":\"79544.00\",\"A\":\"5.256\",\"T\":1788580704728,\"E\":1788580704728,\"st\":1}}"}
{"receive_ns":1788580704681763000,"stream":"btcusdt@bookTicker","event_type":"bookTicker","event_time_ms":1788580704731,"raw_json":"{\"stream\":\"btcusdt@bookTicker\",\"data\":{\"e\":\"bookTicker\",\"u\":11479472968526,\"s\":\"BTCUSDT\",\"ps\":\"BTCUSDT\",\"b\":\"79543.90\",\"B\":\"6.566\",\"a\":\"79544.00\",\"A\":\"5.256\",\"T\":1788580704731,\"E\":1788580704731,\"st\":1}}"}
{"receive_ns":1788580704681944000,"stream":"btcusdt@bookTicker","event_type":"bookTicker","event_time_ms":1788580704732,"raw_json":"{\"stream\":\"btcusdt@bookTicker\",\"data\":{\"e\":\"bookTicker\",\"u\":11479472968570,\"s\":\"BTCUSDT\",\"ps\":\"BTCUSDT\",\"b\":\"79543.90\",\"B\":\"6.567\",\"a\":\"79544.00\",\"A\":\"5.256\",\"T\":1788580704732,\"E\":1788580704732,\"st\":1}}"}
{"receive_ns":1788580704699089000,"stream":"btcusdt@depth@100ms","event_type":"depthUpdate","event_time_ms":1788580704755,"raw_json":"{\"stream\":\"btcusdt@depth@100ms\",\"data\":{\"e\":\"depthUpdate\",\"E\":1788580704755,\"T\":1788580704753,\"s\":\"BTCUSDT\",\"ps\":\"BTCUSDT\",\"U\":11479472963956,\"u\":11479472969415,\"pu\":11479472963907,\"b\":[[\"1000.00\",\"25.354\"],[\"29343.90\",\"0.413\"],[\"29443.90\",\"1.687\"],[\"71589.50\",\"0.010\"],[\"76362.10\",\"0.000\"],[\"78748.50\",\"4.438\"],[\"79419.40\",\"0.013\"],[\"79419.50\",\"0.439\"],[\"79456.40\",\"0.318\"],[\"79543.90\",\"6.567\"]],\"a\":[[\"79544.00\",\"5.256\"],[\"79575.80\",\"0.276\"],[\"79666.30\",\"0.418\"],[\"79939.70\",\"0.173\"],[\"80272.60\",\"9.640\"],[\"80339.40\",\"3.915\"],[\"80411.00\",\"2.728\"],[\"80657.60\",\"25.699\"],[\"81134.80\",\"0.015\"]],\"st\":1}}"}
{"receive_ns":1788580704749759000,"stream":"btcusdt@bookTicker","event_type":"bookTicker","event_time_ms":1788580704760,"raw_json":"{\"stream\":\"btcusdt@bookTicker\",\"data\":{\"e\":\"bookTicker\",\"u\":11479472969671,\"s\":\"BTCUSDT\",\"ps\":\"BTCUSDT\",\"b\":\"79543.90\",\"B\":\"6.567\",\"a\":\"79544.00\",\"A\":\"5.279\",\"T\":1788580704760,\"E\":1788580704760,\"st\":1}}"}
{"receive_ns":1788580704809361000,"stream":"btcusdt@depth@100ms","event_type":"depthUpdate","event_time_ms":1788580704857,"raw_json":"{\"stream\":\"btcusdt@depth@100ms\",\"data\":{\"e\":\"depthUpdate\",\"E\":1788580704857,\"T\":1788580704855,\"s\":\"BTCUSDT\",\"ps\":\"BTCUSDT\",\"U\":11479472969480,\"u\":11479472974970,\"pu\":11479472969415,\"b\":[[\"29343.90\",\"0.588\"],[\"29443.90\",\"1.512\"],[\"71589.50\",\"0.010\"],[\"76362.10\",\"0.002\"],[\"78748.50\",\"4.438\"],[\"79456.40\",\"0.010\"],[\"79495.20\",\"0.001\"],[\"79495.40\",\"0.064\"],[\"79503.90\",\"0.000\"],[\"79536.60\",\"0.006\"],[\"79540.70\",\"0.040\"],[\"79542.70\",\"0.000\"],[\"79543.40\",\"0.007\"],[\"79543.50\",\"0.001\"]],\"a\":[[\"79544.00\",\"5.279\"],[\"79933.80\",\"0.000\"],[\"79939.70\",\"0.005\"],[\"80339.40\",\"3.915\"],[\"80776.90\",\"5.223\"]],\"st\":1}}"}
{"receive_ns":1788580704831362000,"stream":"btcusdt@bookTicker","event_type":"bookTicker","event_time_ms":1788580704887,"raw_json":"{\"stream\":\"btcusdt@bookTicker\",\"data\":{\"e\":\"bookTicker\",\"u\":11479472976533,\"s\":\"BTCUSDT\",\"ps\":\"BTCUSDT\",\"b\":\"79543.90\",\"B\":\"6.566\",\"a\":\"79544.00\",\"A\":\"5.279\",\"T\":1788580704887,\"E\":1788580704887,\"st\":1}}"}
{"receive_ns":1788580704877802000,"stream":"btcusdt@bookTicker","event_type":"bookTicker","event_time_ms":1788580704889,"raw_json":"{\"stream\":\"btcusdt@bookTicker\",\"data\":{\"e\":\"bookTicker\",\"u\":11479472976675,\"s\":\"BTCUSDT\",\"ps\":\"BTCUSDT\",\"b\":\"79543.90\",\"B\":\"6.567\",\"a\":\"79544.00\",\"A\":\"5.279\",\"T\":1788580704889,\"E\":1788580704889,\"st\":1}}"}
{"receive_ns":1788580704938131000,"stream":"btcusdt@depth@100ms","event_type":"depthUpdate","event_time_ms":1788580704959,"raw_json":"{\"stream\":\"btcusdt@depth@100ms\",\"data\":{\"e\":\"depthUpdate\",\"E\":1788580704959,\"T\":1788580704957,\"s\":\"BTCUSDT\",\"ps\":\"BTCUSDT\",\"U\":11479472975026,\"u\":11479472979471,\"pu\":11479472974970,\"b\":[[\"1000.00\",\"25.354\"],[\"29343.90\",\"0.770\"],[\"29443.90\",\"1.330\"],[\"71589.50\",\"0.010\"],[\"76362.10\",\"0.000\"],[\"78549.60\",\"6.188\"],[\"78562.00\",\"7.928\"],[\"78588.80\",\"1.625\"],[\"78590.10\",\"0.000\"],[\"78612.60\",\"0.004\"],[\"78613.90\",\"0.000\"],[\"78748.50\",\"4.438\"],[\"79146.20\",\"3.412\"],[\"79158.70\",\"0.628\"],[\"79452.20\",\"3.344\"],[\"79452.30\",\"0.001\"],[\"79453.10\",\"0.000\"],[\"79454.80\",\"0.025\"],[\"79456.40\",\"0.268\"],[\"79480.30\",\"0.559\"],[\"79482.90\",\"0.606\"],[\"79524.50\",\"0.003\"],[\"79525.60\",\"0.047\"],[\"79526.70\",\"0.080\"],[\"79543.90\",\"6.567\"]],\"a\":[[\"79564.70\",\"0.002\"],[\"79564.90\",\"0.375\"],[\"79565.60\",\"1.199\"],[\"79566.10\",\"0.000\"],[\"79566.60\",\"0.205\"],[\"79568.20\",\"0.001\"],[\"79569.10\",\"0.704\"],[\"79589.40\",\"0.017\"],[\"79590.50\",\"0.102\"],[\"79635.20\",\"3.821\"],[\"79765.80\",\"19.214\"],[\"79765.90\",\"0.000\"],[\"79933.80\",\"0.055\"],[\"79936.40\",\"0.133\"],[\"79939.70\",\"0.136\"],[\"80339.40\",\"3.915\"],[\"80498.50\",\"27.289\"],[\"80673.50\",\"0.745\"]],\"st\":1}}"}
{"receive_ns":1788580704999059000,"stream":"btcusdt@bookTicker","event_type":"bookTicker","event_time_ms":1788580705016,"raw_json":"{\"stream\":\"btcusdt@bookTicker\",\"data\":{\"e\":\"bookTicker\",\"u\":11479472982099,\"s\":\"BTCUSDT\",\"ps\":\"BTCUSDT\",\"b\":\"79543.90\",\"B\":\"6.566\",\"a\":\"79544.00\",\"A\":\"5.279\",\"T\":1788580705016,\"E\":1788580705016,\"st\":1}}"}
{"receive_ns":1788580704999268000,"stream":"btcusdt@bookTicker","event_type":"bookTicker","event_time_ms":1788580705025,"raw_json":"{\"stream\":\"btcusdt@bookTicker\",\"data\":{\"e\":\"bookTicker\",\"u\":11479472982814,\"s\":\"BTCUSDT\",\"ps\":\"BTCUSDT\",\"b\":\"79543.90\",\"B\":\"6.568\",\"a\":\"79544.00\",\"A\":\"5.279\",\"T\":1788580705024,\"E\":1788580705025,\"st\":1}}"}
{"receive_ns":1788580705004441000,"stream":"btcusdt@depth@100ms","event_type":"depthUpdate","event_time_ms":1788580705061,"raw_json":"{\"stream\":\"btcusdt@depth@100ms\",\"data\":{\"e\":\"depthUpdate\",\"E\":1788580705061,\"T\":1788580705057,\"s\":\"BTCUSDT\",\"ps\":\"BTCUSDT\",\"U\":11479472979562,\"u\":11479472984294,\"pu\":11479472979471,\"b\":[[\"1000.00\",\"25.354\"],[\"29343.90\",\"0.945\"],[\"29443.90\",\"1.155\"],[\"71589.50\",\"0.010\"],[\"77953.10\",\"0.015\"],[\"78584.10\",\"24.435\"],[\"78748.50\",\"4.438\"],[\"79456.40\",\"0.268\"],[\"79499.80\",\"0.075\"],[\"79499.90\",\"0.002\"],[\"79529.60\",\"0.006\"],[\"79543.90\",\"6.568\"]],\"a\":[[\"79554.50\",\"0.783\"],[\"79559.40\",\"0.000\"],[\"79626.80\",\"0.024\"],[\"79939.70\",\"0.136\"],[\"80120.80\",\"0.000\"],[\"80175.00\",\"4.368\"],[\"80180.40\",\"2.488\"],[\"80339.40\",\"3.915\"],[\"80578.10\",\"1.242\"],[\"81134.80\",\"0.012\"]],\"st\":1}}"}
{"receive_ns":1788580705058917000,"stream":"btcusdt@bookTicker","event_type":"bookTicker","event_time_ms":1788580705115,"raw_json":"{\"stream\":\"btcusdt@bookTicker\",\"data\":{\"e\":\"bookTicker\",\"u\":11479472987339,\"s\":\"BTCUSDT\",\"ps\":\"BTCUSDT\",\"b\":\"79543.90\",\"B\":\"6.568\",\"a\":\"79544.00\",\"A\":\"5.239\",\"T\":1788580705115,\"E\":1788580705115,\"st\":1}}"}
{"receive_ns":1788580705061807000,"stream":"btcusdt@bookTicker","event_type":"bookTicker","event_time_ms":1788580705118,"raw_json":"{\"stream\":\"btcusdt@bookTicker\",\"data\":{\"e\":\"bookTicker\",\"u\":11479472987540,\"s\":\"BTCUSDT\",\"ps\":\"BTCUSDT\",\"b\":\"79543.90\",\"B\":\"6.568\",\"a\":\"79544.00\",\"A\":\"5.281\",\"T\":1788580705117,\"E\":1788580705118,\"st\":1}}"}
{"receive_ns":1788580705114617000,"stream":"btcusdt@depth@100ms","event_type":"depthUpdate","event_time_ms":1788580705163,"raw_json":"{\"stream\":\"btcusdt@depth@100ms\",\"data\":{\"e\":\"depthUpdate\",\"E\":1788580705163,\"T\":1788580705162,\"s\":\"BTCUSDT\",\"ps\":\"BTCUSDT\",\"U\":11479472984466,\"u\":11479472989852,\"pu\":11479472984294,\"b\":[[\"29343.90\",\"1.127\"],[\"29443.90\",\"0.973\"],[\"63635.10\",\"0.000\"],[\"71589.50\",\"0.010\"],[\"76362.10\",\"0.002\"],[\"78748.50\",\"4.438\"],[\"79453.10\",\"0.020\"],[\"79456.40\",\"0.318\"],[\"79480.30\",\"0.509\"],[\"79482.90\",\"0.586\"],[\"79520.20\",\"2.393\"]],\"a\":[[\"79544.00\",\"5.281\"],[\"79560.10\",\"0.002\"],[\"79624.90\",\"0.004\"],[\"79625.10\",\"0.001\"],[\"79933.80\",\"0.055\"],[\"79936.40\",\"0.133\"],[\"79939.70\",\"0.136\"],[\"80121.50\",\"0.094\"],[\"80280.70\",\"0.000\"],[\"80339.40\",\"3.915\"],[\"80439.90\",\"0.000\"]],\"st\":1}}"}
{"receive_ns":1788580705181491000,"stream":"btcusdt@bookTicker","event_type":"bookTicker","event_time_ms":1788580705238,"raw_json":"{\"stream\":\"btcusdt@bookTicker\",\"data\":{\"e\":\"bookTicker\",\"u\":11479472993279,\"s\":\"BTCUSDT\",\"ps\":\"BTCUSDT\",\"b\":\"79543.90\",\"B\":\"6.566\",\"a\":\"79544.00\",\"A\":\"5.281\",\"T\":1788580705237,\"E\":1788580705238,\"st\":1}}"}
{"receive_ns":1788580705185645000,"stream":"btcusdt@bookTicker","event_type":"bookTicker","event_time_ms":1788580705241,"raw_json":"{\"stream\":\"btcusdt@bookTicker\",\"data\":{\"e\":\"bookTicker\",\"u\":11479472993527,\"s\":\"BTCUSDT\",\"ps\":\"BTCUSDT\",\"b\":\"79543.90\",\"B\":\"6.567\",\"a\":\"79544.00\",\"A\":\"5.281\",\"T\":1788580705241,\"E\":1788580705241,\"st\":1}}"}
{"receive_ns":1788580705244558000,"stream":"btcusdt@depth@100ms","event_type":"depthUpdate","event_time_ms":1788580705265,"raw_json":"{\"stream\":\"btcusdt@depth@100ms\",\"data\":{\"e\":\"depthUpdate\",\"E\":1788580705265,\"T\":1788580705264,\"s\":\"BTCUSDT\",\"ps\":\"BTCUSDT\",\"U\":11479472989911,\"u\":11479472994613,\"pu\":11479472989852,\"b\":[[\"1000.00\",\"25.354\"],[\"29343.90\",\"1.302\"],[\"29443.90\",\"0.798\"],[\"71589.50\",\"0.010\"],[\"75566.70\",\"0.010\"],[\"75566.80\",\"0.012\"],[\"76362.10\",\"0.000\"],[\"77714.40\",\"1.286\"],[\"78078.90\",\"0.000\"],[\"78589.40\",\"24.077\"],[\"78748.50\",\"4.440\"],[\"79146.10\",\"0.008\"],[\"79146.20\",\"3.412\"],[\"79380.10\",\"0.022\"],[\"79400.00\",\"23.667\"],[\"79419.50\",\"0.000\"],[\"79456.40\",\"0.318\"],[\"79476.00\",\"4.375\"],[\"79488.20\",\"0.130\"],[\"79520.20\",\"2.395\"],[\"79543.90\",\"6.567\"]],\"a\":[[\"79560.10\",\"0.004\"],[\"79615.60\",\"0.006\"],[\"79617.20\",\"0.042\"],[\"79620.00\",\"16.148\"],[\"79623.00\",\"0.009\"],[\"79626.80\",\"0.060\"],[\"79628.30\",\"29.738\"],[\"79635.80\",\"0.001\"],[\"79666.30\",\"0.000\"],[\"79668.10\",\"0.007\"],[\"79705.70\",\"0.000\"],[\"79765.80\",\"18.942\"],[\"79939.70\",\"0.136\"],[\"79941.80\",\"0.000\"],[\"79959.10\",\"0.118\"],[\"80118.10\",\"0.117\"],[\"80180.40\",\"2.737\"],[\"80277.10\",\"0.116\"],[\"80334.10\",\"5.483\"],[\"80339.40\",\"3.915\"],[\"80436.10\",\"0.116\"],[\"80599.10\",\"0.001\"]],\"st\":1}}"}
{"receive_ns":1788580705297272000,"stream":"btcusdt@bookTicker","event_type":"bookTicker","event_time_ms":1788580705319,"raw_json":"{\"stream\":\"btcusdt@bookTicker\",\"data\":{\"e\":\"bookTicker\",\"u\":11479472997535,\"s\":\"BTCUSDT\",\"ps\":\"BTCUSDT\",\"b\":\"79543.90\",\"B\":\"6.566\",\"a\":\"79544.00\",\"A\":\"5.281\",\"T\":1788580705319,\"E\":1788580705319,\"st\":1}}"}
{"receive_ns":1788580705297511000,"stream":"btcusdt@bookTicker","event_type":"bookTicker","event_time_ms":1788580705321,"raw_json":"{\"stream\":\"btcusdt@bookTicker\",\"data\":{\"e\":\"bookTicker\",\"u\":11479472997706,\"s\":\"BTCUSDT\",\"ps\":\"BTCUSDT\",\"b\":\"79543.90\",\"B\":\"6.567\",\"a\":\"79544.00\",\"A\":\"5.281\",\"T\":1788580705321,\"E\":1788580705321,\"st\":1}}"}
{"receive_ns":1788580705310049000,"stream":"btcusdt@depth@100ms","event_type":"depthUpdate","event_time_ms":1788580705367,"raw_json":"{\"stream\":\"btcusdt@depth@100ms\",\"data\":{\"e\":\"depthUpdate\",\"E\":1788580705367,\"T\":1788580705365,\"s\":\"BTCUSDT\",\"ps\":\"BTCUSDT\",\"U\":11479472994655,\"u\":11479473000624,\"pu\":11479472994613,\"b\":[[\"1000.00\",\"25.354\"],[\"29343.90\",\"1.477\"],[\"29443.90\",\"0.623\"],[\"63635.00\",\"0.000\"],[\"71589.50\",\"0.010\"],[\"71623.00\",\"0.000\"],[\"76362.10\",\"0.002\"],[\"78040.50\",\"0.384\"],[\"78748.50\",\"4.438\"],[\"79146.10\",\"0.009\"],[\"79332.30\",\"0.000\"],[\"79332.40\",\"5.068\"],[\"79335.50\",\"0.488\"],[\"79380.10\",\"2.189\"],[\"79419.50\",\"0.439\"],[\"79453.10\",\"0.000\"],[\"79456.40\",\"0.010\"],[\"79501.90\",\"0.215\"],[\"79524.20\",\"2.521\"],[\"79525.20\",\"0.000\"],[\"79539.80\",\"0.010\"],[\"79543.90\",\"6.567\"]],\"a\":[[\"79554.50\",\"0.155\"],[\"79559.40\",\"0.628\"],[\"79617.20\",\"0.072\"],[\"79623.00\",\"29.631\"],[\"79628.30\",\"0.000\"],[\"79666.30\",\"0.437\"],[\"79668.10\",\"0.013\"],[\"79705.70\",\"1.953\"],[\"79753.40\",\"5.660\"],[\"79933.80\",\"0.000\"],[\"79936.40\",\"0.126\"],[\"79939.70\",\"0.005\"],[\"79941.80\",\"0.001\"],[\"80339.40\",\"3.915\"],[\"80561.20\",\"0.636\"],[\"80692.00\",\"6.805\"],[\"87498.40\",\"0.005\"]],\"st\":1}}"}
{"receive_ns":1788580705320463000,"stream":"btcusdt@bookTicker","event_type":"bookTicker","event_time_ms":1788580705371,"raw_json":"{\"stream\":\"btcusdt@bookTicker\",\"data\":{\"e\":\"bookTicker\",\"u\":11479473001085,\"s\":\"BTCUSDT\",\"ps\":\"BTCUSDT\",\"b\":\"79543.90\",\"B\":\"6.426\",\"a\":\"79544.00\",\"A\":\"5.281\",\"T\":1788580705371,\"E\":1788580705371,\"st\":1}}"}
{"receive_ns":1788580705356973000,"stream":"btcusdt@bookTicker","event_type":"bookTicker","event_time_ms":1788580705374,"raw_json":"{\"stream\":\"btcusdt@bookTicker\",\"data\":{\"e\":\"bookTicker\",\"u\":11479473001319,\"s\":\"BTCUSDT\",\"ps\":\"BTCUSDT\",\"b\":\"79543.90\",\"B\":\"6.572\",\"a\":\"79544.00\",\"A\":\"5.281\",\"T\":1788580705374,\"E\":1788580705374,\"st\":1}}"}
{"receive_ns":1788580705357205000,"stream":"btcusdt@bookTicker","event_type":"bookTicker","event_time_ms":1788580705376,"raw_json":"{\"stream\":\"btcusdt@bookTicker\",\"data\":{\"e\":\"bookTicker\",\"u\":11479473001505,\"s\":\"BTCUSDT\",\"ps\":\"BTCUSDT\",\"b\":\"79543.90\",\"B\":\"6.444\",\"a\":\"79544.00\",\"A\":\"5.281\",\"T\":1788580705376,\"E\":1788580705376,\"st\":1}}"}
{"receive_ns":1788580705357446000,"stream":"btcusdt@bookTicker","event_type":"bookTicker","event_time_ms":1788580705380,"raw_json":"{\"stream\":\"btcusdt@bookTicker\",\"data\":{\"e\":\"bookTicker\",\"u\":11479473001825,\"s\":\"BTCUSDT\",\"ps\":\"BTCUSDT\",\"b\":\"79543.90\",\"B\":\"6.571\",\"a\":\"79544.00\",\"A\":\"5.281\",\"T\":1788580705380,\"E\":1788580705380,\"st\":1}}"}
{"receive_ns":1788580705422491000,"stream":"btcusdt@depth@100ms","event_type":"depthUpdate","event_time_ms":1788580705469,"raw_json":"{\"stream\":\"btcusdt@depth@100ms\",\"data\":{\"e\":\"depthUpdate\",\"E\":1788580705469,\"T\":1788580705466,\"s\":\"BTCUSDT\",\"ps\":\"BTCUSDT\",\"U\":11479473000697,\"u\":11479473007159,\"pu\":11479473000624,\"b\":[[\"29343.90\",\"1.659\"],[\"29443.90\",\"0.441\"],[\"71589.50\",\"0.010\"],[\"77953.10\",\"0.012\"],[\"78748.50\",\"4.438\"],[\"78971.50\",\"0.000\"],[\"79145.60\",\"0.000\"],[\"79146.20\",\"3.412\"],[\"79146.30\",\"0.568\"],[\"79264.50\",\"0.000\"],[\"79267.80\",\"1.315\"],[\"79453.10\",\"0.020\"],[\"79456.40\",\"0.308\"],[\"79517.30\",\"0.454\"],[\"79518.70\",\"0.139\"],[\"79524.20\",\"2.148\"],[\"79524.80\",\"0.683\"],[\"79525.40\",\"0.419\"],[\"79525.60\",\"0.001\"],[\"79527.80\",\"0.665\"],[\"79528.40\",\"1.434\"],[\"79528.50\",\"0.000\"],[\"79529.30\",\"0.112\"],[\"79529.60\",\"0.002\"],[\"79543.90\",\"6.571\"]],\"a\":[[\"79554.50\",\"0.155\"],[\"79559.40\",\"0.000\"],[\"79559.80\",\"0.076\"],[\"79563.00\",\"0.655\"],[\"79563.90\",\"0.002\"],[\"79564.90\",\"0.814\"],[\"79565.60\",\"0.760\"],[\"79567.10\",\"0.014\"],[\"79568.30\",\"0.857\"],[\"79569.10\",\"0.252\"],[\"79588.50\",\"4.800\"],[\"79589.60\",\"0.298\"],[\"79590.50\",\"0.056\"],[\"79820.70\",\"1.959\"],[\"79823.50\",\"0.158\"],[\"79936.40\",\"0.133\"],[\"79937.70\",\"0.022\"],[\"79939.70\",\"0.168\"],[\"79940.70\",\"0.970\"],[\"79943.20\",\"0.000\"],[\"80119.10\",\"0.000\"],[\"80175.00\",\"3.622\"],[\"80339.40\",\"3.915\"],[\"80538.30\",\"3.867\"],[\"80652.20\",\"29.237\"]],\"st\":1}}"}
{"receive_ns":1788580705545561000,"stream":"btcusdt@bookTicker","event_type":"bookTicker","event_time_ms":1788580705543,"raw_json":"{\"stream\":\"btcusdt@bookTicker\",\"data\":{\"e\":\"bookTicker\",\"u\":11479473010887,\"s\":\"BTCUSDT\",\"ps\":\"BTCUSDT\",\"b\":\"79543.90\",\"B\":\"6.570\",\"a\":\"79544.00\",\"A\":\"5.281\",\"T\":1788580705543,\"E\":1788580705543,\"st\":1}}"}
{"receive_ns":1788580705546150000,"stream":"btcusdt@bookTicker","event_type":"bookTicker","event_time_ms":1788580705550,"raw_json":"{\"stream\":\"btcusdt@bookTicker\",\"data\":{\"e\":\"bookTicker\",\"u\":11479473011256,\"s\":\"BTCUSDT\",\"ps\":\"BTCUSDT\",\"b\":\"79543.90\",\"B\":\"6.572\",\"a\":\"79544.00\",\"A\":\"5.281\",\"T\":1788580705550,\"E\":1788580705550,\"st\":1}}"}
{"receive_ns":1788580705596418000,"stream":"btcusdt@depth@100ms","event_type":"depthUpdate","event_time_ms":1788580705571,"raw_json":"{\"stream\":\"btcusdt@depth@100ms\",\"data\":{\"e\":\"depthUpdate\",\"E\":1788580705571,\"T\":1788580705570,\"s\":\"BTCUSDT\",\"ps\":\"BTCUSDT\",\"U\":11479473007280,\"u\":11479473012303,\"pu\":11479473007159,\"b\":[[\"1000.00\",\"25.354\"],[\"29243.90\",\"0.028\"],[\"29343.90\",\"1.785\"],[\"29443.90\",\"0.287\"],[\"71589.50\",\"0.010\"],[\"76362.10\",\"0.000\"],[\"78425.10\",\"29.947\"],[\"78748.50\",\"4.438\"],[\"78840.50\",\"11.167\"],[\"79456.40\",\"0.318\"],[\"79524.80\",\"0.637\"],[\"79525.70\",\"0.049\"],[\"79526.80\",\"1.887\"],[\"79527.80\",\"0.225\"],[\"79528.50\",\"0.440\"],[\"79529.10\",\"0.229\"],[\"79543.90\",\"6.572\"]],\"a\":[[\"79554.00\",\"0.552\"],[\"79554.20\",\"0.007\"],[\"79558.40\",\"0.001\"],[\"79564.90\",\"0.002\"],[\"79565.00\",\"1.964\"],[\"79565.60\",\"1.199\"],[\"79566.20\",\"0.057\"],[\"79566.60\",\"0.205\"],[\"79589.60\",\"0.252\"],[\"79590.60\",\"0.058\"],[\"79630.60\",\"0.015\"],[\"79641.50\",\"0.131\"],[\"79643.40\",\"0.001\"],[\"79657.60\",\"1.510\"],[\"79939.70\",\"0.173\"],[\"80273.30\",\"0.000\"],[\"80339.40\",\"3.915\"],[\"80538.30\",\"4.673\"],[\"80617.80\",\"1.893\"],[\"80697.40\",\"10.454\"]],\"st\":1}}"}
{"receive_ns":1788580705596643000,"stream":"btcusdt@bookTicker","event_type":"bookTicker","event_time_ms":1788580705574,"raw_json":"{\"stream\":\"btcusdt@bookTicker\",\"data\":{\"e\":\"bookTicker\",\"u\":11479473012457,\"s\":\"BTCUSDT\",\"ps\":\"BTCUSDT\",\"b\":\"79543.90\",\"B\":\"6.344\",\"a\":\"79544.00\",\"A\":\"5.281\",\"T\":1788580705574,\"E\":1788580705574,\"st\":1}}"}
{"receive_ns":1788580705596807000,"stream":"btcusdt@bookTicker","event_type":"bookTicker","event_time_ms":1788580705577,"raw_json":"{\"stream\":\"btcusdt@bookTicker\",\"data\":{\"e\":\"bookTicker\",\"u\":11479473012599,\"s\":\"BTCUSDT\",\"ps\":\"BTCUSDT\",\"b\":\"79543.90\",\"B\":\"6.573\",\"a\":\"79544.00\",\"A\":\"5.281\",\"T\":1788580705577,\"E\":1788580705577,\"st\":1}}"}
{"receive_ns":1788580705663292000,"stream":"btcusdt@depth@100ms","event_type":"depthUpdate","event_time_ms":1788580705673,"raw_json":"{\"stream\":\"btcusdt@depth@100ms\",\"data\":{\"e\":\"depthUpdate\",\"E\":1788580705673,\"T\":1788580705671,\"s\":\"BTCUSDT\",\"ps\":\"BTCUSDT\",\"U\":11479473012373,\"u\":11479473017221,\"pu\":11479473012303,\"b\":[[\"1000.00\",\"25.354\"],[\"29243.90\",\"0.091\"],[\"29343.90\",\"1.834\"],[\"29443.90\",\"0.175\"],[\"63635.00\",\"0.000\"],[\"71589.50\",\"0.010\"],[\"76362.10\",\"0.002\"],[\"78430.30\",\"27.124\"],[\"78498.30\",\"0.030\"],[\"78748.50\",\"4.438\"],[\"78758.20\",\"0.002\"],[\"78939.00\",\"3.240\"],[\"79000.10\",\"7.288\"],[\"79219.60\",\"8.152\"],[\"79264.60\",\"1.473\"],[\"79453.10\",\"0.000\"],[\"79456.40\",\"0.042\"],[\"79472.30\",\"0.380\"],[\"79480.30\",\"0.785\"],[\"79482.90\",\"0.606\"],[\"79517.30\",\"0.002\"],[\"79519.70\",\"0.503\"],[\"79528.40\",\"0.177\"],[\"79529.30\",\"1.369\"],[\"79538.40\",\"0.060\"],[\"79538.60\",\"0.440\"],[\"79543.90\",\"6.573\"]],\"a\":[[\"79565.00\",\"1.591\"],[\"79565.60\",\"1.199\"],[\"79566.10\",\"0.373\"],[\"79566.60\",\"0.205\"],[\"79568.30\",\"0.405\"],[\"79569.10\",\"0.704\"],[\"79639.50\",\"0.002\"],[\"79823.40\",\"10.555\"],[\"79936.40\",\"0.133\"],[\"79937.70\",\"0.004\"],[\"79939.70\",\"0.191\"],[\"79943.10\",\"0.000\"],[\"79999.90\",\"5.222\"],[\"80099.90\",\"7.854\"],[\"80180.40\",\"3.483\"],[\"80235.10\",\"3.240\"],[\"80335.40\",\"0.000\"],[\"80339.40\",\"3.917\"],[\"80425.50\",\"0.187\"],[\"80600.50\",\"0.620\"],[\"80652.20\",\"27.380\"],[\"80673.50\",\"0.894\"]],\"st\":1}}"}
{"receive_ns":1788580705792236000,"stream":"btcusdt@depth@100ms","event_type":"depthUpdate","event_time_ms":1788580705775,"raw_json":"{\"stream\":\"btcusdt@depth@100ms\",\"data\":{\"e\":\"depthUpdate\",\"E\":1788580705775,\"T\":1788580705773,\"s\":\"BTCUSDT\",\"ps\":\"BTCUSDT\",\"U\":11479473017283,\"u\":11479473021470,\"pu\":11479473017221,\"b\":[[\"29243.90\",\"0.147\"],[\"29343.90\",\"1.904\"],[\"29443.90\",\"0.049\"],[\"63635.00\",\"0.000\"],[\"71589.50\",\"0.010\"],[\"76362.10\",\"0.000\"],[\"77953.10\",\"0.015\"],[\"78588.80\",\"1.622\"],[\"78599.40\",\"0.037\"],[\"78602.00\",\"5.717\"],[\"78611.40\",\"0.007\"],[\"78611.70\",\"7.496\"],[\"78674.70\",\"0.000\"],[\"78748.50\",\"4.438\"],[\"78828.00\",\"1.460\"],[\"78973.00\",\"52.320\"],[\"79146.20\",\"3.412\"],[\"79147.10\",\"39.796\"],[\"79266.00\",\"33.485\"],[\"79267.80\",\"6.101\"],[\"79416.60\",\"0.178\"],[\"79456.40\",\"0.032\"],[\"79480.30\",\"0.795\"],[\"79518.50\",\"0.454\"],[\"79519.70\",\"0.051\"]],\"a\":[[\"79564.90\",\"0.375\"],[\"79566.10\",\"0.000\"],[\"79824.00\",\"5.531\"],[\"79827.00\",\"31.255\"],[\"79939.70\",\"0.191\"],[\"79944.50\",\"6.383\"],[\"79946.70\",\"38.943\"],[\"80122.60\",\"47.815\"],[\"80339.40\",\"3.915\"],[\"80657.60\",\"27.556\"]],\"st\":1}}"}
{"receive_ns":1788580705803800000,"stream":"btcusdt@bookTicker","event_type":"bookTicker","event_time_ms":1788580705784,"raw_json":"{\"stream\":\"btcusdt@bookTicker\",\"data\":{\"e\":\"bookTicker\",\"u\":11479473021855,\"s\":\"BTCUSDT\",\"ps\":\"BTCUSDT\",\"b\":\"79543.90\",\"B\":\"6.572\",\"a\":\"79544.00\",\"A\":\"5.281\",\"T\":1788580705784,\"E\":1788580705784,\"st\":1}}"}
{"receive_ns":1788580705838382000,"stream":"btcusdt@bookTicker","event_type":"bookTicker","event_time_ms":1788580705787,"raw_json":"{\"stream\":\"btcusdt@bookTicker\",\"data\":{\"e\":\"bookTicker\",\"u\":11479473022093,\"s\":\"BTCUSDT\",\"ps\":\"BTCUSDT\",\"b\":\"79543.90\",\"B\":\"6.573\",\"a\":\"79544.00\",\"A\":\"5.281\",\"T\":1788580705787,\"E\":1788580705787,\"st\":1}}"}
{"receive_ns":1788580705915649000,"stream":"btcusdt@depth@100ms","event_type":"depthUpdate","event_time_ms":1788580705877,"raw_json":"{\"stream\":\"btcusdt@depth@100ms\",\"data\":{\"e\":\"depthUpdate\",\"E\":1788580705877,\"T\":1788580705874,\"s\":\"BTCUSDT\",\"ps\":\"BTCUSDT\",\"U\":11479473021559,\"u\":11479473026072,\"pu\":11479473021470,\"b\":[[\"1000.00\",\"25.354\"],[\"29243.90\",\"0.273\"],[\"29343.90\",\"1.827\"],[\"29443.90\",\"0.000\"],[\"71589.50\",\"0.010\"],[\"75566.80\",\"0.010\"],[\"76362.10\",\"0.002\"],[\"77953.10\",\"0.012\"],[\"78584.10\",\"23.928\"],[\"78623.90\",\"3.429\"],[\"78629.10\",\"3.919\"],[\"78748.50\",\"4.438\"],[\"78759.70\",\"62.320\"],[\"79416.60\",\"0.197\"],[\"79419.50\",\"0.000\"],[\"79456.40\",\"0.032\"],[\"79480.20\",\"2.192\"],[\"79480.30\",\"0.795\"],[\"79482.90\",\"0.606\"],[\"79543.90\",\"6.573\"]],\"a\":[[\"79666.30\",\"0.000\"],[\"79933.80\",\"0.037\"],[\"79936.40\",\"0.126\"],[\"79937.70\",\"0.022\"],[\"79939.70\",\"0.136\"],[\"80338.90\",\"59.844\"],[\"80339.40\",\"3.915\"],[\"81373.50\",\"0.614\"]],\"st\":1}}"}
{"receive_ns":1788580705915918000,"stream":"btcusdt@bookTicker","event_type":"bookTicker","event_time_ms":1788580705908,"raw_json":"{\"stream\":\"btcusdt@bookTicker\",\"data\":{\"e\":\"bookTicker\",\"u\":11479473027390,\"s\":\"BTCUSDT\",\"ps\":\"BTCUSDT\",\"b\":\"79543.90\",\"B\":\"6.571\",\"a\":\"79544.00\",\"A\":\"5.281\",\"T\":1788580705908,\"E\":1788580705908,\"st\":1}}"}
{"receive_ns":1788580705917107000,"stream":"btcusdt@bookTicker","event_type":"bookTicker","event_time_ms":1788580705910,"raw_json":"{\"stream\":\"btcusdt@bookTicker\",\"data\":{\"e\":\"bookTicker\",\"u\":11479473027548,\"s\":\"BTCUSDT\",\"ps\":\"BTCUSDT\",\"b\":\"79543.90\",\"B\":\"6.556\",\"a\":\"79544.00\",\"A\":\"5.281\",\"T\":1788580705910,\"E\":1788580705910,\"st\":1}}"}
{"receive_ns":1788580705930592000,"stream":"btcusdt@bookTicker","event_type":"bookTicker","event_time_ms":1788580705916,"raw_json":"{\"stream\":\"btcusdt@bookTicker\",\"data\":{\"e\":\"bookTicker\",\"u\":11479473027784,\"s\":\"BTCUSDT\",\"ps\":\"BTCUSDT\",\"b\":\"79543.90\",\"B\":\"6.557\",\"a\":\"79544.00\",\"A\":\"5.281\",\"T\":1788580705916,\"E\":1788580705916,\"st\":1}}"}
{"receive_ns":1788580705980891000,"stream":"btcusdt@depth@100ms","event_type":"depthUpdate","event_time_ms":1788580705979,"raw_json":"{\"stream\":\"btcusdt@depth@100ms\",\"data\":{\"e\":\"depthUpdate\",\"E\":1788580705979,\"T\":1788580705977,\"s\":\"BTCUSDT\",\"ps\":\"BTCUSDT\",\"U\":11479473026147,\"u\":11479473030793,\"pu\":11479473026072,\"b\":[[\"1000.00\",\"25.354\"],[\"29243.90\",\"0.455\"],[\"29343.90\",\"1.645\"],[\"63635.00\",\"0.002\"],[\"71589.50\",\"0.010\"],[\"76200.00\",\"29.535\"],[\"78470.10\",\"2.418\"],[\"78748.50\",\"4.438\"],[\"78939.00\",\"0.000\"],[\"79000.10\",\"9.880\"],[\"79140.90\",\"1.073\"],[\"79219.60\",\"8.638\"],[\"79266.10\",\"0.162\"],[\"79332.40\",\"0.000\"],[\"79380.10\",\"0.022\"],[\"79448.40\",\"0.018\"],[\"79456.40\",\"0.042\"],[\"79472.30\",\"0.378\"],[\"79480.20\",\"2.142\"],[\"79480.30\",\"0.785\"],[\"79488.20\",\"0.130\"],[\"79542.20\",\"0.035\"],[\"79543.90\",\"6.557\"]],\"a\":[[\"79583.70\",\"0.001\"],[\"79583.80\",\"0.066\"],[\"79599.70\",\"0.052\"],[\"79615.60\",\"0.004\"],[\"79639.50\",\"0.000\"],[\"79705.70\",\"0.000\"],[\"79753.40\",\"0.748\"],[\"79826.90\",\"0.162\"],[\"79936.40\",\"0.008\"],[\"79939.70\",\"0.136\"],[\"79941.70\",\"2.373\"],[\"79946.60\",\"0.658\"],[\"79999.90\",\"5.060\"],[\"80099.90\",\"10.446\"],[\"80135.20\",\"1.246\"],[\"80235.10\",\"0.000\"],[\"80265.90\",\"0.187\"],[\"80339.40\",\"3.915\"],[\"80493.20\",\"11.913\"],[\"80657.60\",\"29.413\"]],\"st\":1}}"}
{"receive_ns":1788580706049006000,"stream":"btcusdt@bookTicker","event_type":"bookTicker","event_time_ms":1788580706032,"raw_json":"{\"stream\":\"btcusdt@bookTicker\",\"data\":{\"e\":\"bookTicker\",\"u\":11479473033295,\"s\":\"BTCUSDT\",\"ps\":\"BTCUSDT\",\"b\":\"79543.90\",\"B\":\"6.557\",\"a\":\"79544.00\",\"A\":\"5.278\",\"T\":1788580706032,\"E\":1788580706032,\"st\":1}}"}
{"receive_ns":1788580706050163000,"stream":"btcusdt@depth@100ms","event_type":"depthUpdate","event_time_ms":1788580706081,"raw_json":"{\"stream\":\"btcusdt@depth@100ms\",\"data\":{\"e\":\"depthUpdate\",\"E\":1788580706081,\"T\":1788580706079,\"s\":\"BTCUSDT\",\"ps\":\"BTCUSDT\",\"U\":11479473030838,\"u\":11479473036026,\"pu\":11479473030793,\"b\":[[\"29243.90\",\"0.630\"],[\"29343.90\",\"1.470\"],[\"63635.00\",\"0.000\"],[\"63635.10\",\"0.002\"],[\"71589.50\",\"0.012\"],[\"76362.10\",\"0.000\"],[\"78748.50\",\"4.438\"],[\"79146.20\",\"3.402\"],[\"79332.40\",\"5.135\"],[\"79380.10\",\"2.206\"],[\"79419.50\",\"0.481\"],[\"79480.20\",\"2.180\"],[\"79524.20\",\"2.521\"],[\"79525.40\",\"0.046\"],[\"79527.80\",\"0.665\"],[\"79528.50\",\"0.000\"],[\"79529.60\",\"0.002\"]],\"a\":[[\"79544.00\",\"5.278\"],[\"79559.80\",\"0.000\"],[\"79563.90\",\"0.441\"],[\"79565.60\",\"0.760\"],[\"79666.30\",\"0.437\"],[\"79705.70\",\"1.956\"],[\"79753.40\",\"5.670\"],[\"80339.40\",\"3.915\"]],\"st\":1}}"}
{"receive_ns":1788580706095779000,"stream":"btcusdt@bookTicker","event_type":"bookTicker","event_time_ms":1788580706125,"raw_json":"{\"stream\":\"btcusdt@bookTicker\",\"data\":{\"e\":\"bookTicker\",\"u\":11479473040190,\"s\":\"BTCUSDT\",\"ps\":\"BTCUSDT\",\"b\":\"79543.90\",\"B\":\"6.556\",\"a\":\"79544.00\",\"A\":\"5.278\",\"T\":1788580706125,\"E\":1788580706125,\"st\":1}}"}
{"receive_ns":1788580706095972000,"stream":"btcusdt@bookTicker","event_type":"bookTicker","event_time_ms":1788580706133,"raw_json":"{\"stream\":\"btcusdt@bookTicker\",\"data\":{\"e\":\"bookTicker\",\"u\":11479473040734,\"s\":\"BTCUSDT\",\"ps\":\"BTCUSDT\",\"b\":\"79543.90\",\"B\":\"6.558\",\"a\":\"79544.00\",\"A\":\"5.278\",\"T\":1788580706132,\"E\":1788580706133,\"st\":1}}"}
{"receive_ns":1788580706096152000,"stream":"btcusdt@bookTicker","event_type":"bookTicker","event_time_ms":1788580706150,"raw_json":"{\"stream\":\"btcusdt@bookTicker\",\"data\":{\"e\":\"bookTicker\",\"u\":11479473041520,\"s\":\"BTCUSDT\",\"ps\":\"BTCUSDT\",\"b\":\"79543.90\",\"B\":\"6.558\",\"a\":\"79544.00\",\"A\":\"5.236\",\"T\":1788580706150,\"E\":1788580706150,\"st\":1}}"}
{"receive_ns":1788580706098090000,"stream":"btcusdt@bookTicker","event_type":"bookTicker","event_time_ms":1788580706154,"raw_json":"{\"stream\":\"btcusdt@bookTicker\",\"data\":{\"e\":\"bookTicker\",\"u\":11479473041707,\"s\":\"BTCUSDT\",\"ps\":\"BTCUSDT\",\"b\":\"79543.90\",\"B\":\"6.558\",\"a\":\"79544.00\",\"A\":\"5.279\",\"T\":1788580706154,\"E\":1788580706154,\"st\":1}}"}
{"receive_ns":1788580706156636000,"stream":"btcusdt@depth@100ms","event_type":"depthUpdate","event_time_ms":1788580706183,"raw_json":"{\"stream\":\"btcusdt@depth@100ms\",\"data\":{\"e\":\"depthUpdate\",\"E\":1788580706183,\"T\":1788580706177,\"s\":\"BTCUSDT\",\"ps\":\"BTCUSDT\",\"U\":11479473036079,\"u\":11479473042778,\"pu\":11479473036026,\"b\":[[\"1000.00\",\"25.354\"],[\"29243.90\",\"0.805\"],[\"29343.90\",\"1.295\"],[\"63635.00\",\"0.000\"],[\"63635.10\",\"0.000\"],[\"71589.50\",\"0.012\"],[\"76362.10\",\"0.002\"],[\"77953.10\",\"0.015\"],[\"78191.70\",\"5.747\"],[\"78470.10\",\"2.609\"],[\"78589.40\",\"24.584\"],[\"78748.50\",\"4.438\"],[\"79454.80\",\"0.000\"],[\"79456.40\",\"0.243\"],[\"79480.30\",\"0.584\"],[\"79482.90\",\"0.606\"],[\"79517.30\",\"0.454\"],[\"79518.50\",\"0.002\"],[\"79524.20\",\"2.148\"],[\"79524.80\",\"0.683\"],[\"79525.40\",\"0.419\"],[\"79525.70\",\"0.003\"],[\"79528.40\",\"1.434\"],[\"79529.30\",\"0.112\"],[\"79531.60\",\"0.000\"],[\"79543.90\",\"6.558\"]],\"a\":[[\"79544.00\",\"5.279\"],[\"79563.90\",\"0.002\"],[\"79564.90\",\"0.814\"],[\"79567.10\",\"0.014\"],[\"79568.30\",\"0.857\"],[\"79569.10\",\"0.252\"],[\"79588.50\",\"4.800\"],[\"79589.70\",\"0.138\"],[\"79590.60\",\"0.012\"],[\"79933.80\",\"0.000\"],[\"79936.40\",\"0.008\"],[\"79937.70\",\"0.059\"],[\"79939.70\",\"0.136\"],[\"79941.70\",\"2.498\"],[\"80339.40\",\"3.915\"],[\"80498.50\",\"28.530\"]],\"st\":1}}"}
{"receive_ns":1788580706228535000,"stream":"btcusdt@depth@100ms","event_type":"depthUpdate","event_time_ms":1788580706285,"raw_json":"{\"stream\":\"btcusdt@depth@100ms\",\"data\":{\"e\":\"depthUpdate\",\"E\":1788580706285,\"T\":1788580706284,\"s\":\"BTCUSDT\",\"ps\":\"BTCUSDT\",\"U\":11479473042989,\"u\":11479473047840,\"pu\":11479473042778,\"b\":[[\"1000.00\",\"25.354\"],[\"29243.90\",\"0.987\"],[\"29343.90\",\"1.113\"],[\"71589.50\",\"0.014\"],[\"76362.10\",\"0.000\"],[\"78549.60\",\"6.341\"],[\"78629.10\",\"4.173\"],[\"78748.50\",\"4.438\"],[\"79146.20\",\"3.528\"],[\"79335.50\",\"1.194\"],[\"79456.40\",\"0.243\"],[\"79520.20\",\"2.395\"]],\"a\":[[\"79560.10\",\"0.004\"],[\"79620.00\",\"20.577\"],[\"79668.10\",\"0.007\"],[\"79753.30\",\"1.451\"],[\"79753.40\",\"4.959\"],[\"79939.70\",\"0.136\"],[\"80339.40\",\"3.915\"],[\"80493.20\",\"10.672\"],[\"80539.10\",\"4.934\"],[\"80639.80\",\"0.000\"],[\"87498.40\",\"0.007\"]],\"st\":1}}"}
{"receive_ns":1788580706288811000,"stream":"btcusdt@bookTicker","event_type":"bookTicker","event_time_ms":1788580706335,"raw_json":"{\"stream\":\"btcusdt@bookTicker\",\"data\":{\"e\":\"bookTicker\",\"u\":11479473050090,\"s\":\"BTCUSDT\",\"ps\":\"BTCUSDT\",\"b\":\"79543.90\",\"B\":\"6.558\",\"a\":\"79544.00\",\"A\":\"5.278\",\"T\":1788580706335,\"E\":1788580706335,\"st\":1}}"}
{"receive_ns":1788580706289015000,"stream":"btcusdt@trade","event_type":"trade","event_time_ms":1788580706335,"raw_json":"{\"stream\":\"btcusdt@trade\",\"data\":{\"e\":\"trade\",\"E\":1788580706335,\"T\":1788580706335,\"s\":\"BTCUSDT\",\"t\":8054266641,\"p\":\"79544.00\",\"q\":\"0.001\",\"X\":\"MARKET\",\"m\":false,\"st\":1}}"}
{"receive_ns":1788580706295105000,"stream":"btcusdt@bookTicker","event_type":"bookTicker","event_time_ms":1788580706351,"raw_json":"{\"stream\":\"btcusdt@bookTicker\",\"data\":{\"e\":\"bookTicker\",\"u\":11479473050901,\"s\":\"BTCUSDT\",\"ps\":\"BTCUSDT\",\"b\":\"79543.90\",\"B\":\"6.557\",\"a\":\"79544.00\",\"A\":\"5.278\",\"T\":1788580706351,\"E\":1788580706351,\"st\":1}}"}
{"receive_ns":1788580706296264000,"stream":"btcusdt@bookTicker","event_type":"bookTicker","event_time_ms":1788580706353,"raw_json":"{\"stream\":\"btcusdt@bookTicker\",\"data\":{\"e\":\"bookTicker\",\"u\":11479473051030,\"s\":\"BTCUSDT\",\"ps\":\"BTCUSDT\",\"b\":\"79543.90\",\"B\":\"6.558\",\"a\":\"79544.00\",\"A\":\"5.278\",\"T\":1788580706353,\"E\":1788580706353,\"st\":1}}"}
{"receive_ns":1788580706337777000,"stream":"btcusdt@bookTicker","event_type":"bookTicker","event_time_ms":1788580706379,"raw_json":"{\"stream\":\"btcusdt@bookTicker\",\"data\":{\"e\":\"bookTicker\",\"u\":11479473052192,\"s\":\"BTCUSDT\",\"ps\":\"BTCUSDT\",\"b\":\"79543.90\",\"B\":\"6.412\",\"a\":\"79544.00\",\"A\":\"5.278\",\"T\":1788580706378,\"E\":1788580706379,\"st\":1}}"}
{"receive_ns":1788580706337992000,"stream":"btcusdt@bookTicker","event_type":"bookTicker","event_time_ms":1788580706381,"raw_json":"{\"stream\":\"btcusdt@bookTicker\",\"data\":{\"e\":\"bookTicker\",\"u\":11479473052326,\"s\":\"BTCUSDT\",\"ps\":\"BTCUSDT\",\"b\":\"79543.90\",\"B\":\"6.549\",\"a\":\"79544.00\",\"A\":\"5.278\",\"T\":1788580706381,\"E\":1788580706381,\"st\":1}}"}
{"receive_ns":1788580706338286000,"stream":"btcusdt@depth@100ms","event_type":"depthUpdate","event_time_ms":1788580706387,"raw_json":"{\"stream\":\"btcusdt@depth@100ms\",\"data\":{\"e\":\"depthUpdate\",\"E\":1788580706387,\"T\":1788580706385,\"s\":\"BTCUSDT\",\"ps\":\"BTCUSDT\",\"U\":11479473047904,\"u\":11479473052507,\"pu\":11479473047840,\"b\":[[\"29243.90\",\"1.169\"],[\"29343.90\",\"0.931\"],[\"63635.00\",\"0.000\"],[\"71589.50\",\"0.014\"],[\"71623.00\",\"0.003\"],[\"78452.60\",\"5.730\"],[\"78748.50\",\"4.438\"],[\"79146.10\",\"0.009\"],[\"79146.20\",\"3.538\"],[\"79419.50\",\"0.000\"],[\"79453.10\",\"0.020\"],[\"79456.40\",\"0.268\"],[\"79480.30\",\"0.559\"],[\"79482.90\",\"0.586\"],[\"79543.90\",\"6.549\"]],\"a\":[[\"79544.00\",\"5.278\"],[\"79596.30\",\"3.557\"],[\"79596.50\",\"0.051\"],[\"79666.30\",\"0.000\"],[\"79936.40\",\"0.008\"],[\"79937.70\",\"0.059\"],[\"79939.70\",\"0.136\"],[\"79941.80\",\"0.001\"],[\"80339.40\",\"3.915\"],[\"81134.80\",\"0.009\"],[\"87498.40\",\"0.009\"]],\"st\":1}}"}
{"receive_ns":1788580706338471000,"stream":"btcusdt@bookTicker","event_type":"bookTicker","event_time_ms":1788580706388,"raw_json":"{\"stream\":\"btcusdt@bookTicker\",\"data\":{\"e\":\"bookTicker\",\"u\":11479473052712,\"s\":\"BTCUSDT\",\"ps\":\"BTCUSDT\",\"b\":\"79543.90\",\"B\":\"6.549\",\"a\":\"79544.00\",\"A\":\"5.274\",\"T\":1788580706388,\"E\":1788580706388,\"st\":1}}"}
{"receive_ns":1788580706338625000,"stream":"btcusdt@bookTicker","event_type":"bookTicker","event_time_ms":1788580706391,"raw_json":"{\"stream\":\"btcusdt@bookTicker\",\"data\":{\"e\":\"bookTicker\",\"u\":11479473052868,\"s\":\"BTCUSDT\",\"ps\":\"BTCUSDT\",\"b\":\"79543.90\",\"B\":\"6.549\",\"a\":\"79544.00\",\"A\":\"5.281\",\"T\":1788580706391,\"E\":1788580706391,\"st\":1}}"}
{"receive_ns":1788580706424820000,"stream":"btcusdt@trade","event_type":"trade","event_time_ms":1788580706482,"raw_json":"{\"stream\":\"btcusdt@trade\",\"data\":{\"e\":\"trade\",\"E\":1788580706482,\"T\":1788580706482,\"s\":\"BTCUSDT\",\"t\":8054266642,\"p\":\"79544.00\",\"q\":\"0.108\",\"X\":\"MARKET\",\"m\":false,\"st\":1}}"}
{"receive_ns":1788580706425076000,"stream":"btcusdt@bookTicker","event_type":"bookTicker","event_time_ms":1788580706482,"raw_json":"{\"stream\":\"btcusdt@bookTicker\",\"data\":{\"e\":\"bookTicker\",\"u\":11479473057406,\"s\":\"BTCUSDT\",\"ps\":\"BTCUSDT\",\"b\":\"79543.90\",\"B\":\"6.549\",\"a\":\"79544.00\",\"A\":\"4.739\",\"T\":1788580706482,\"E\":1788580706482,\"st\":1}}"}
{"receive_ns":1788580706425260000,"stream":"btcusdt@trade","event_type":"trade","event_time_ms":1788580706482,"raw_json":"{\"stream\":\"btcusdt@trade\",\"data\":{\"e\":\"trade\",\"E\":1788580706482,\"T\":1788580706482,\"s\":\"BTCUSDT\",\"t\":8054266643,\"p\":\"79544.00\",\"q\":\"0.013\",\"X\":\"MARKET\",\"m\":false,\"st\":1}}"}
{"receive_ns":1788580706425376000,"stream":"btcusdt@trade","event_type":"trade","event_time_ms":1788580706482,"raw_json":"{\"stream\":\"btcusdt@trade\",\"data\":{\"e\":\"trade\",\"E\":1788580706482,\"T\":1788580706482,\"s\":\"BTCUSDT\",\"t\":8054266644,\"p\":\"79544.00\",\"q\":\"0.382\",\"X\":\"MARKET\",\"m\":false,\"st\":1}}"}
{"receive_ns":1788580706425485000,"stream":"btcusdt@trade","event_type":"trade","event_time_ms":1788580706482,"raw_json":"{\"stream\":\"btcusdt@trade\",\"data\":{\"e\":\"trade\",\"E\":1788580706482,\"T\":1788580706482,\"s\":\"BTCUSDT\",\"t\":8054266645,\"p\":\"79544.00\",\"q\":\"0.013\",\"X\":\"MARKET\",\"m\":false,\"st\":1}}"}
{"receive_ns":1788580706425587000,"stream":"btcusdt@trade","event_type":"trade","event_time_ms":1788580706482,"raw_json":"{\"stream\":\"btcusdt@trade\",\"data\":{\"e\":\"trade\",\"E\":1788580706482,\"T\":1788580706482,\"s\":\"BTCUSDT\",\"t\":8054266646,\"p\":\"79544.00\",\"q\":\"0.026\",\"X\":\"MARKET\",\"m\":false,\"st\":1}}"}
{"receive_ns":1788580706425893000,"stream":"btcusdt@bookTicker","event_type":"bookTicker","event_time_ms":1788580706484,"raw_json":"{\"stream\":\"btcusdt@bookTicker\",\"data\":{\"e\":\"bookTicker\",\"u\":11479473057592,\"s\":\"BTCUSDT\",\"ps\":\"BTCUSDT\",\"b\":\"79543.90\",\"B\":\"6.549\",\"a\":\"79544.00\",\"A\":\"5.325\",\"T\":1788580706483,\"E\":1788580706484,\"st\":1}}"}
{"receive_ns":1788580706426082000,"stream":"btcusdt@bookTicker","event_type":"bookTicker","event_time_ms":1788580706484,"raw_json":"{\"stream\":\"btcusdt@bookTicker\",\"data\":{\"e\":\"bookTicker\",\"u\":11479473057635,\"s\":\"BTCUSDT\",\"ps\":\"BTCUSDT\",\"b\":\"79543.90\",\"B\":\"6.549\",\"a\":\"79544.00\",\"A\":\"5.079\",\"T\":1788580706484,\"E\":1788580706484,\"st\":1}}"}
{"receive_ns":1788580706460724000,"stream":"btcusdt@bookTicker","event_type":"bookTicker","event_time_ms":1788580706485,"raw_json":"{\"stream\":\"btcusdt@bookTicker\",\"data\":{\"e\":\"bookTicker\",\"u\":11479473057708,\"s\":\"BTCUSDT\",\"ps\":\"BTCUSDT\",\"b\":\"79543.90\",\"B\":\"6.549\",\"a\":\"79544.00\",\"A\":\"5.077\",\"T\":1788580706484,\"E\":1788580706485,\"st\":1}}"}
{"receive_ns":1788580706460883000,"stream":"btcusdt@bookTicker","event_type":"bookTicker","event_time_ms":1788580706485,"raw_json":"{\"stream\":\"btcusdt@bookTicker\",\"data\":{\"e\":\"bookTicker\",\"u\":11479473057745,\"s\":\"BTCUSDT\",\"ps\":\"BTCUSDT\",\"b\":\"79543.90\",\"B\":\"6.549\",\"a\":\"79544.00\",\"A\":\"5.136\",\"T\":1788580706485,\"E\":1788580706485,\"st\":1}}"}
{"receive_ns":1788580706460998000,"stream":"btcusdt@bookTicker","event_type":"bookTicker","event_time_ms":1788580706485,"raw_json":"{\"stream\":\"btcusdt@bookTicker\",\"data\":{\"e\":\"bookTicker\",\"u\":11479473057747,\"s\":\"BTCUSDT\",\"ps\":\"BTCUSDT\",\"b\":\"79543.90\",\"B\":\"6.549\",\"a\":\"79544.00\",\"A\":\"5.195\",\"T\":1788580706485,\"E\":1788580706485,\"st\":1}}"}
{"receive_ns":1788580706461123000,"stream":"btcusdt@bookTicker","event_type":"bookTicker","event_time_ms":1788580706486,"raw_json":"{\"stream\":\"btcusdt@bookTicker\",\"data\":{\"e\":\"bookTicker\",\"u\":11479473057880,\"s\":\"BTCUSDT\",\"ps\":\"BTCUSDT\",\"b\":\"79543.90\",\"B\":\"6.549\",\"a\":\"79544.00\",\"A\":\"5.197\",\"T\":1788580706486,\"E\":1788580706486,\"st\":1}}"}
{"receive_ns":1788580706461387000,"stream":"btcusdt@depth@100ms","event_type":"depthUpdate","event_time_ms":1788580706489,"raw_json":"{\"stream\":\"btcusdt@depth@100ms\",\"data\":{\"e\":\"depthUpdate\",\"E\":1788580706489,\"T\":1788580706488,\"s\":\"BTCUSDT\",\"ps\":\"BTCUSDT\",\"U\":11479473052621,\"u\":11479473058004,\"pu\":11479473052507,\"b\":[[\"1000.00\",\"25.354\"],[\"29243.90\",\"1.344\"],[\"29343.90\",\"0.756\"],[\"71589.50\",\"0.014\"],[\"71623.00\",\"0.000\"],[\"76362.10\",\"0.002\"],[\"77666.70\",\"0.000\"],[\"78748.50\",\"4.440\"],[\"79419.50\",\"0.442\"],[\"79456.40\",\"0.268\"],[\"79480.20\",\"2.201\"],[\"79500.10\",\"0.001\"],[\"79504.80\",\"0.304\"],[\"79509.70\",\"2.002\"],[\"79514.40\",\"0.692\"],[\"79528.80\",\"0.109\"],[\"79530.70\",\"0.057\"],[\"79540.60\",\"0.504\"]],\"a\":[[\"79544.00\",\"5.197\"],[\"79561.20\",\"0.639\"],[\"79571.00\",\"0.079\"],[\"79572.50\",\"0.319\"],[\"79617.20\",\"0.084\"],[\"79617.60\",\"0.001\"],[\"79619.40\",\"6.167\"],[\"79620.00\",\"16.148\"],[\"79623.00\",\"0.009\"],[\"79628.30\",\"29.622\"],[\"79633.10\",\"0.000\"],[\"79665.00\",\"0.202\"],[\"79666.30\",\"0.437\"],[\"79668.10\",\"0.007\"],[\"79939.70\",\"0.136\"],[\"80259.90\",\"1.697\"],[\"80339.40\",\"3.915\"]],\"st\":1}}"}
{"receive_ns":1788580706534320000,"stream":"btcusdt@depth@100ms","event_type":"depthUpdate","event_time_ms":1788580706591,"raw_json":"{\"stream\":\"btcusdt@depth@100ms\",\"data\":{\"e\":\"depthUpdate\",\"E\":1788580706591,\"T\":1788580706590,\"s\":\"BTCUSDT\",\"ps\":\"BTCUSDT\",\"U\":11479473058025,\"u\":11479473064634,\"pu\":11479473058004,\"b\":[[\"1000.00\",\"25.354\"],[\"29243.90\",\"1.526\"],[\"29343.90\",\"0.574\"],[\"63635.00\",\"0.002\"],[\"71589.50\",\"0.014\"],[\"76362.10\",\"0.000\"],[\"77634.80\",\"0.645\"],[\"78499.80\",\"78.677\"],[\"78748.50\",\"4.438\"],[\"79453.10\",\"0.000\"],[\"79456.40\",\"0.010\"],[\"79474.60\",\"0.001\"],[\"79476.00\",\"1.485\"],[\"79477.30\",\"22.996\"],[\"79478.80\",\"4.556\"],[\"79480.30\",\"0.509\"],[\"79486.70\",\"0.000\"],[\"79496.10\",\"0.422\"],[\"79504.70\",\"0.000\"],[\"79509.40\",\"0.002\"],[\"79514.40\",\"0.001\"],[\"79528.40\",\"1.434\"],[\"79528.80\",\"0.083\"],[\"79529.30\",\"0.108\"],[\"79529.60\",\"0.002\"],[\"79529.70\",\"0.159\"],[\"79540.60\",\"0.252\"],[\"79540.70\",\"0.040\"]],\"a\":[[\"79560.00\",\"0.089\"],[\"79572.50\",\"0.322\"],[\"79596.30\",\"3.607\"],[\"79596.50\",\"0.001\"],[\"79623.00\",\"29.515\"],[\"79625.60\",\"0.200\"],[\"79627.40\",\"0.017\"],[\"79628.30\",\"0.000\"],[\"79633.10\",\"0.022\"],[\"79641.50\",\"0.125\"],[\"79936.40\",\"0.001\"],[\"79937.70\",\"0.004\"],[\"79939.70\",\"0.005\"],[\"80339.40\",\"3.915\"],[\"80498.50\",\"29.771\"],[\"80603.30\",\"75.279\"]],\"st\":1}}"}
{"receive_ns":1788580706590038000,"stream":"btcusdt@bookTicker","event_type":"bookTicker","event_time_ms":1788580706641,"raw_json":"{\"stream\":\"btcusdt@bookTicker\",\"data\":{\"e\":\"bookTicker\",\"u\":11479473067447,\"s\":\"BTCUSDT\",\"ps\":\"BTCUSDT\",\"b\":\"79543.90\",\"B\":\"6.549\",\"a\":\"79544.00\",\"A\":\"5.443\",\"T\":1788580706641,\"E\":1788580706641,\"st\":1}}"}
{"receive_ns":1788580706590244000,"stream":"btcusdt@bookTicker","event_type":"bookTicker","event_time_ms":1788580706642,"raw_json":"{\"stream\":\"btcusdt@bookTicker\",\"data\":{\"e\":\"bookTicker\",\"u\":11479473067466,\"s\":\"BTCUSDT\",\"ps\":\"BTCUSDT\",\"b\":\"79543.90\",\"B\":\"6.549\",\"a\":\"79544.00\",\"A\":\"5.412\",\"T\":1788580706641,\"E\":1788580706642,\"st\":1}}"}
{"receive_ns":1788580706590395000,"stream":"btcusdt@bookTicker","event_type":"bookTicker","event_time_ms":1788580706643,"raw_json":"{\"stream\":\"btcusdt@bookTicker\",\"data\":{\"e\":\"bookTicker\",\"u\":11479473067545,\"s\":\"BTCUSDT\",\"ps\":\"BTCUSDT\",\"b\":\"79543.90\",\"B\":\"6.549\",\"a\":\"79544.00\",\"A\":\"5.410\",\"T\":1788580706642,\"E\":1788580706643,\"st\":1}}"}
{"receive_ns":1788580706590547000,"stream":"btcusdt@bookTicker","event_type":"bookTicker","event_time_ms":1788580706644,"raw_json":"{\"stream\":\"btcusdt@bookTicker\",\"data\":{\"e\":\"bookTicker\",\"u\":11479473067660,\"s\":\"BTCUSDT\",\"ps\":\"BTCUSDT\",\"b\":\"79543.90\",\"B\":\"6.549\",\"a\":\"79544.00\",\"A\":\"5.445\",\"T\":1788580706644,\"E\":1788580706644,\"st\":1}}"}
{"receive_ns":1788580706590695000,"stream":"btcusdt@bookTicker","event_type":"bookTicker","event_time_ms":1788580706645,"raw_json":"{\"stream\":\"btcusdt@bookTicker\",\"data\":{\"e\":\"bookTicker\",\"u\":11479473067721,\"s\":\"BTCUSDT\",\"ps\":\"BTCUSDT\",\"b\":\"79543.90\",\"B\":\"6.549\",\"a\":\"79544.00\",\"A\":\"5.447\",\"T\":1788580706645,\"E\":1788580706645,\"st\":1}}"}
{"receive_ns":1788580706648377000,"stream":"btcusdt@depth@100ms","event_type":"depthUpdate","event_time_ms":1788580706693,"raw_json":"{\"stream\":\"btcusdt@depth@100ms\",\"data\":{\"e\":\"depthUpdate\",\"E\":1788580706693,\"T\":1788580706691,\"s\":\"BTCUSDT\",\"ps\":\"BTCUSDT\",\"U\":11479473064714,\"u\":11479473070284,\"pu\":11479473064634,\"b\":[[\"29243.90\",\"1.701\"],[\"29343.90\",\"0.399\"],[\"63635.00\",\"0.000\"],[\"71589.50\",\"0.014\"],[\"76362.10\",\"0.002\"],[\"77953.10\",\"0.018\"],[\"78748.50\",\"4.438\"],[\"78840.50\",\"10.977\"],[\"79146.20\",\"3.654\"],[\"79456.40\",\"0.243\"],[\"79471.90\",\"22.955\"],[\"79477.30\",\"0.041\"],[\"79480.30\",\"0.584\"],[\"79482.90\",\"0.606\"],[\"79505.90\",\"0.167\"],[\"79506.00\",\"10.003\"],[\"79509.40\",\"0.001\"],[\"79509.70\",\"0.002\"],[\"79529.30\",\"0.112\"]],\"a\":[[\"79544.00\",\"5.447\"],[\"79668.10\",\"0.013\"],[\"79936.40\",\"0.008\"],[\"79937.70\",\"0.059\"],[\"79939.70\",\"0.136\"],[\"80312.30\",\"1.677\"],[\"80339.40\",\"3.915\"]],\"st\":1}}"}
{"receive_ns":1788580706719039000,"stream":"btcusdt@bookTicker","event_type":"bookTicker","event_time_ms":1788580706745,"raw_json":"{\"stream\":\"btcusdt@bookTicker\",\"data\":{\"e\":\"bookTicker\",\"u\":11479473073429,\"s\":\"BTCUSDT\",\"ps\":\"BTCUSDT\",\"b\":\"79543.90\",\"B\":\"6.549\",\"a\":\"79544.00\",\"A\":\"5.443\",\"T\":1788580706745,\"E\":1788580706745,\"st\":1}}"}
{"receive_ns":1788580706719249000,"stream":"btcusdt@trade","event_type":"trade","event_time_ms":1788580706745,"raw_json":"{\"stream\":\"btcusdt@trade\",\"data\":{\"e\":\"trade\",\"E\":1788580706745,\"T\":1788580706745,\"s\":\"BTCUSDT\",\"t\":8054266647,\"p\":\"79544.00\",\"q\":\"0.004\",\"X\":\"MARKET\",\"m\":false,\"st\":1}}"}
{"receive_ns":1788580706784027000,"stream":"btcusdt@bookTicker","event_type":"bookTicker","event_time_ms":1788580706790,"raw_json":"{\"stream\":\"btcusdt@bookTicker\",\"data\":{\"e\":\"bookTicker\",\"u\":11479473075174,\"s\":\"BTCUSDT\",\"ps\":\"BTCUSDT\",\"b\":\"79543.90\",\"B\":\"6.320\",\"a\":\"79544.00\",\"A\":\"5.443\",\"T\":1788580706790,\"E\":1788580706790,\"st\":1}}"}
{"receive_ns":1788580706784218000,"stream":"btcusdt@bookTicker","event_type":"bookTicker","event_time_ms":1788580706792,"raw_json":"{\"stream\":\"btcusdt@bookTicker\",\"data\":{\"e\":\"bookTicker\",\"u\":11479473075282,\"s\":\"BTCUSDT\",\"ps\":\"BTCUSDT\",\"b\":\"79543.90\",\"B\":\"6.558\",\"a\":\"79544.00\",\"A\":\"5.443\",\"T\":1788580706792,\"E\":1788580706792,\"st\":1}}"}
{"receive_ns":1788580706784360000,"stream":"btcusdt@bookTicker","event_type":"bookTicker","event_time_ms":1788580706794,"raw_json":"{\"stream\":\"btcusdt@bookTicker\",\"data\":{\"e\":\"bookTicker\",\"u\":11479473075353,\"s\":\"BTCUSDT\",\"ps\":\"BTCUSDT\",\"b\":\"79543.90\",\"B\":\"6.557\",\"a\":\"79544.00\",\"A\":\"5.443\",\"T\":1788580706794,\"E\":1788580706794,\"st\":1}}"}
{"receive_ns":1788580706784679000,"stream":"btcusdt@depth@100ms","event_type":"depthUpdate","event_time_ms":1788580706795,"raw_json":"{\"stream\":\"btcusdt@depth@100ms\",\"data\":{\"e\":\"depthUpdate\",\"E\":1788580706795,\"T\":1788580706794,\"s\":\"BTCUSDT\",\"ps\":\"BTCUSDT\",\"U\":11479473070455,\"u\":11479473075356,\"pu\":11479473070284,\"b\":[[\"1000.00\",\"25.354\"],[\"29143.90\",\"0.042\"],[\"29243.90\",\"1.799\"],[\"29343.90\",\"0.259\"],[\"71589.50\",\"0.014\"],[\"76362.10\",\"0.000\"],[\"78549.60\",\"6.532\"],[\"78598.20\",\"0.004\"],[\"78599.40\",\"0.034\"],[\"78748.50\",\"4.440\"],[\"79419.50\",\"0.000\"],[\"79456.40\",\"0.233\"],[\"79471.90\",\"0.000\"],[\"79472.30\",\"0.388\"],[\"79473.90\",\"0.062\"],[\"79474.60\",\"22.956\"],[\"79478.80\",\"1.282\"],[\"79482.90\",\"0.586\"],[\"79504.20\",\"0.025\"],[\"79543.90\",\"6.557\"]],\"a\":[[\"79544.00\",\"5.443\"],[\"79574.70\",\"0.007\"],[\"79596.30\",\"3.557\"],[\"79596.50\",\"0.051\"],[\"79620.30\",\"29.511\"],[\"79623.00\",\"0.009\"],[\"79639.20\",\"0.012\"],[\"79666.30\",\"0.000\"],[\"79939.70\",\"0.136\"],[\"80106.70\",\"0.103\"],[\"80180.40\",\"3.731\"],[\"80299.70\",\"2.921\"],[\"80339.40\",\"3.915\"],[\"80521.30\",\"0.000\"],[\"80551.10\",\"5.710\"]],\"st\":1}}"}
{"receive_ns":1788580706784892000,"stream":"btcusdt@bookTicker","event_type":"bookTicker","event_time_ms":1788580706802,"raw_json":"{\"stream\":\"btcusdt@bookTicker\",\"data\":{\"e\":\"bookTicker\",\"u\":11479473075622,\"s\":\"BTCUSDT\",\"ps\":\"BTCUSDT\",\"b\":\"79543.90\",\"B\":\"6.558\",\"a\":\"79544.00\",\"A\":\"5.443\",\"T\":1788580706802,\"E\":1788580706802,\"st\":1}}"}
{"receive_ns":1788580706834066000,"stream":"btcusdt@bookTicker","event_type":"bookTicker","event_time_ms":1788580706862,"raw_json":"{\"stream\":\"btcusdt@bookTicker\",\"data\":{\"e\":\"bookTicker\",\"u\":11479473080340,\"s\":\"BTCUSDT\",\"ps\":\"BTCUSDT\",\"b\":\"79543.90\",\"B\":\"6.557\",\"a\":\"79544.00\",\"A\":\"5.443\",\"T\":1788580706861,\"E\":1788580706862,\"st\":1}}"}
{"receive_ns":1788580706834309000,"stream":"btcusdt@bookTicker","event_type":"bookTicker","event_time_ms":1788580706863,"raw_json":"{\"stream\":\"btcusdt@bookTicker\",\"data\":{\"e\":\"bookTicker\",\"u\":11479473080487,\"s\":\"BTCUSDT\",\"ps\":\"BTCUSDT\",\"b\":\"79543.90\",\"B\":\"6.558\",\"a\":\"79544.00\",\"A\":\"5.443\",\"T\":1788580706863,\"E\":1788580706863,\"st\":1}}"}
{"receive_ns":1788580706834484000,"stream":"btcusdt@bookTicker","event_type":"bookTicker","event_time_ms":1788580706867,"raw_json":"{\"stream\":\"btcusdt@bookTicker\",\"data\":{\"e\":\"bookTicker\",\"u\":11479473080657,\"s\":\"BTCUSDT\",\"ps\":\"BTCUSDT\",\"b\":\"79543.90\",\"B\":\"6.543\",\"a\":\"79544.00\",\"A\":\"5.443\",\"T\":1788580706867,\"E\":1788580706867,\"st\":1}}"}
{"receive_ns":1788580706834723000,"stream":"btcusdt@trade","event_type":"trade","event_time_ms":1788580706867,"raw_json":"{\"stream\":\"btcusdt@trade\",\"data\":{\"e\":\"trade\",\"E\":1788580706867,\"T\":1788580706867,\"s\":\"BTCUSDT\",\"t\":8054266648,\"p\":\"79543.90\",\"q\":\"0.015\",\"X\":\"MARKET\",\"m\":true,\"st\":1}}"}
{"receive_ns":1788580706841629000,"stream":"btcusdt@depth@100ms","event_type":"depthUpdate","event_time_ms":1788580706897,"raw_json":"{\"stream\":\"btcusdt@depth@100ms\",\"data\":{\"e\":\"depthUpdate\",\"E\":1788580706897,\"T\":1788580706895,\"s\":\"BTCUSDT\",\"ps\":\"BTCUSDT\",\"U\":11479473075382,\"u\":11479473082644,\"pu\":11479473075356,\"b\":[[\"1000.00\",\"25.354\"],[\"29143.90\",\"0.105\"],[\"29243.90\",\"1.848\"],[\"29343.90\",\"0.147\"],[\"63635.00\",\"0.000\"],[\"71589.50\",\"0.014\"],[\"78522.20\",\"9.416\"],[\"78748.50\",\"4.438\"],[\"79419.50\",\"0.442\"],[\"79453.10\",\"0.020\"],[\"79454.80\",\"0.012\"],[\"79456.40\",\"0.308\"],[\"79480.30\",\"0.509\"],[\"79510.80\",\"0.136\"],[\"79526.60\",\"0.005\"],[\"79543.90\",\"6.543\"]],\"a\":[[\"79558.10\",\"0.076\"],[\"79563.90\",\"0.051\"],[\"79573.40\",\"0.111\"],[\"79666.30\",\"0.437\"],[\"79936.40\",\"0.008\"],[\"79937.70\",\"0.059\"],[\"79939.70\",\"0.136\"],[\"80339.40\",\"3.915\"]],\"st\":1}}"}
{"receive_ns":1788580706890228000,"stream":"btcusdt@bookTicker","event_type":"bookTicker","event_time_ms":1788580706942,"raw_json":"{\"stream\":\"btcusdt@bookTicker\",\"data\":{\"e\":\"bookTicker\",\"u\":11479473085174,\"s\":\"BTCUSDT\",\"ps\":\"BTCUSDT\",\"b\":\"79543.90\",\"B\":\"6.543\",\"a\":\"79544.00\",\"A\":\"5.426\",\"T\":1788580706941,\"E\":1788580706942,\"st\":1}}"}
{"receive_ns":1788580706896333000,"stream":"btcusdt@bookTicker","event_type":"bookTicker","event_time_ms":1788580706944,"raw_json":"{\"stream\":\"btcusdt@bookTicker\",\"data\":{\"e\":\"bookTicker\",\"u\":11479473085350,\"s\":\"BTCUSDT\",\"ps\":\"BTCUSDT\",\"b\":\"79543.90\",\"B\":\"6.543\",\"a\":\"79544.00\",\"A\":\"5.438\",\"T\":1788580706944,\"E\":1788580706944,\"st\":1}}"}
{"receive_ns":1788580706955538000,"stream":"btcusdt@depth@100ms","event_type":"depthUpdate","event_time_ms":1788580706999,"raw_json":"{\"stream\":\"btcusdt@depth@100ms\",\"data\":{\"e\":\"depthUpdate\",\"E\":1788580706999,\"T\":1788580706998,\"s\":\"BTCUSDT\",\"ps\":\"BTCUSDT\",\"U\":11479473082747,\"u\":11479473088662,\"pu\":11479473082644,\"b\":[[\"29143.90\",\"0.161\"],[\"29243.90\",\"1.918\"],[\"29343.90\",\"0.021\"],[\"63635.00\",\"0.000\"],[\"71589.50\",\"0.014\"],[\"76362.10\",\"0.002\"],[\"78748.50\",\"4.438\"],[\"79146.20\",\"3.654\"],[\"79419.50\",\"0.000\"],[\"79456.40\",\"0.318\"],[\"79472.30\",\"0.378\"]],\"a\":[[\"79544.00\",\"5.438\"],[\"79558.10\",\"0.000\"],[\"79596.30\",\"3.607\"],[\"79596.50\",\"0.001\"],[\"79666.30\",\"0.000\"],[\"79939.70\",\"0.136\"],[\"80339.40\",\"3.915\"],[\"80652.20\",\"25.523\"],[\"80720.30\",\"0.866\"]],\"st\":1}}"}
{"receive_ns":1788580706968071000,"stream":"btcusdt@bookTicker","event_type":"bookTicker","event_time_ms":1788580707024,"raw_json":"{\"stream\":\"btcusdt@bookTicker\",\"data\":{\"e\":\"bookTicker\",\"u\":11479473090164,\"s\":\"BTCUSDT\",\"ps\":\"BTCUSDT\",\"b\":\"79543.90\",\"B\":\"6.543\",\"a\":\"79544.00\",\"A\":\"5.441\",\"T\":1788580707024,\"E\":1788580707024,\"st\":1}}"}
{"receive_ns":1788580707014839000,"stream":"btcusdt@bookTicker","event_type":"bookTicker","event_time_ms":1788580707060,"raw_json":"{\"stream\":\"btcusdt@bookTicker\",\"data\":{\"e\":\"bookTicker\",\"u\":11479473092257,\"s\":\"BTCUSDT\",\"ps\":\"BTCUSDT\",\"b\":\"79543.90\",\"B\":\"6.543\",\"a\":\"79544.00\",\"A\":\"5.408\",\"T\":1788580707060,\"E\":1788580707060,\"st\":1}}"}
{"receive_ns":1788580707014995000,"stream":"btcusdt@trade","event_type":"trade","event_time_ms":1788580707060,"raw_json":"{\"stream\":\"btcusdt@trade\",\"data\":{\"e\":\"trade\",\"E\":1788580707060,\"T\":1788580707060,\"s\":\"BTCUSDT\",\"t\":8054266649,\"p\":\"79544.00\",\"q\":\"0.033\",\"X\":\"MARKET\",\"m\":false,\"st\":1}}"}
{"receive_ns":1788580707074338000,"stream":"btcusdt@depth@100ms","event_type":"depthUpdate","event_time_ms":1788580707101,"raw_json":"{\"stream\":\"btcusdt@depth@100ms\",\"data\":{\"e\":\"depthUpdate\",\"E\":1788580707101,\"T\":1788580707100,\"s\":\"BTCUSDT\",\"ps\":\"BTCUSDT\",\"U\":11479473088783,\"u\":11479473094207,\"pu\":11479473088662,\"b\":[[\"1000.00\",\"25.354\"],[\"29143.90\",\"0.315\"],[\"29243.90\",\"1.785\"],[\"29343.90\",\"0.000\"],[\"63635.00\",\"0.000\"],[\"63635.10\",\"0.000\"],[\"71589.50\",\"0.014\"],[\"76362.10\",\"0.000\"],[\"78584.10\",\"23.294\"],[\"78748.50\",\"4.438\"],[\"79419.50\",\"0.442\"],[\"79453.10\",\"0.000\"],[\"79456.40\",\"0.010\"],[\"79526.40\",\"0.029\"],[\"79529.60\",\"0.002\"]],\"a\":[[\"79544.00\",\"5.408\"],[\"79558.80\",\"0.005\"],[\"79560.00\",\"0.013\"],[\"79561.30\",\"0.097\"],[\"79666.30\",\"0.437\"],[\"79790.70\",\"20.092\"],[\"79791.20\",\"0.001\"],[\"79936.40\",\"0.001\"],[\"79937.70\",\"0.004\"],[\"79939.70\",\"0.005\"],[\"80121.50\",\"0.000\"],[\"80339.40\",\"3.990\"],[\"80680.50\",\"3.714\"]],\"st\":1}}"}
{"receive_ns":1788580707094340000,"stream":"btcusdt@bookTicker","event_type":"bookTicker","event_time_ms":1788580707149,"raw_json":"{\"stream\":\"btcusdt@bookTicker\",\"data\":{\"e\":\"bookTicker\",\"u\":11479473096551,\"s\":\"BTCUSDT\",\"ps\":\"BTCUSDT\",\"b\":\"79543.90\",\"B\":\"6.543\",\"a\":\"79544.00\",\"A\":\"5.373\",\"T\":1788580707148,\"E\":1788580707149,\"st\":1}}"}
{"receive_ns":1788580707094648000,"stream":"btcusdt@bookTicker","event_type":"bookTicker","event_time_ms":1788580707150,"raw_json":"{\"stream\":\"btcusdt@bookTicker\",\"data\":{\"e\":\"bookTicker\",\"u\":11479473096637,\"s\":\"BTCUSDT\",\"ps\":\"BTCUSDT\",\"b\":\"79543.90\",\"B\":\"6.542\",\"a\":\"79544.00\",\"A\":\"5.373\",\"T\":1788580707150,\"E\":1788580707150,\"st\":1}}"}
{"receive_ns":1788580707096401000,"stream":"btcusdt@bookTicker","event_type":"bookTicker","event_time_ms":1788580707152,"raw_json":"{\"stream\":\"btcusdt@bookTicker\",\"data\":{\"e\":\"bookTicker\",\"u\":11479473096732,\"s\":\"BTCUSDT\",\"ps\":\"BTCUSDT\",\"b\":\"79543.90\",\"B\":\"6.542\",\"a\":\"79544.00\",\"A\":\"5.411\",\"T\":1788580707151,\"E\":1788580707152,\"st\":1}}"}
{"receive_ns":1788580707096540000,"stream":"btcusdt@bookTicker","event_type":"bookTicker","event_time_ms":1788580707152,"raw_json":"{\"stream\":\"btcusdt@bookTicker\",\"data\":{\"e\":\"bookTicker\",\"u\":11479473096774,\"s\":\"BTCUSDT\",\"ps\":\"BTCUSDT\",\"b\":\"79543.90\",\"B\":\"6.543\",\"a\":\"79544.00\",\"A\":\"5.411\",\"T\":1788580707152,\"E\":1788580707152,\"st\":1}}"}
{"receive_ns":1788580707147288000,"stream":"btcusdt@depth@100ms","event_type":"depthUpdate","event_time_ms":1788580707203,"raw_json":"{\"stream\":\"btcusdt@depth@100ms\",\"data\":{\"e\":\"depthUpdate\",\"E\":1788580707203,\"T\":1788580707201,\"s\":\"BTCUSDT\",\"ps\":\"BTCUSDT\",\"U\":11479473094320,\"u\":11479473099084,\"pu\":11479473094207,\"b\":[[\"1000.00\",\"25.354\"],[\"29143.90\",\"0.497\"],[\"29243.90\",\"1.603\"],[\"71589.50\",\"0.014\"],[\"75566.80\",\"0.008\"],[\"76362.10\",\"0.002\"],[\"78442.70\",\"13.979\"],[\"78748.50\",\"4.438\"],[\"78828.00\",\"1.650\"],[\"79453.10\",\"0.020\"],[\"79456.40\",\"0.308\"],[\"79488.20\",\"0.130\"],[\"79543.90\",\"6.543\"]],\"a\":[[\"79544.00\",\"5.411\"],[\"79599.70\",\"0.052\"],[\"79784.60\",\"0.005\"],[\"79936.40\",\"0.008\"],[\"79937.70\",\"0.059\"],[\"79939.70\",\"0.126\"],[\"80260.00\",\"2.321\"],[\"80339.40\",\"3.990\"]],\"st\":1}}"}
{"receive_ns":1788580707270616000,"stream":"btcusdt@depth@100ms","event_type":"depthUpdate","event_time_ms":1788580707305,"raw_json":"{\"stream\":\"btcusdt@depth@100ms\",\"data\":{\"e\":\"depthUpdate\",\"E\":1788580707305,\"T\":1788580707301,\"s\":\"BTCUSDT\",\"ps\":\"BTCUSDT\",\"U\":11479473099153,\"u\":11479473104266,\"pu\":11479473099084,\"b\":[[\"29143.90\",\"0.672\"],[\"29243.90\",\"1.428\"],[\"71589.50\",\"0.014\"],[\"75561.60\",\"0.030\"],[\"76362.10\",\"0.000\"],[\"78589.40\",\"25.218\"],[\"78681.40\",\"9.709\"],[\"78748.50\",\"4.438\"],[\"78840.50\",\"10.787\"],[\"79146.20\",\"3.664\"],[\"79146.30\",\"0.000\"],[\"79147.20\",\"6.567\"],[\"79456.40\",\"0.318\"],[\"79474.60\",\"0.001\"],[\"79477.20\",\"22.982\"],[\"79517.30\",\"0.002\"],[\"79518.50\",\"0.454\"],[\"79519.70\",\"0.051\"],[\"79520.20\",\"2.395\"],[\"79524.80\",\"0.637\"],[\"79525.60\",\"0.047\"],[\"79526.70\",\"0.080\"],[\"79527.80\",\"0.225\"],[\"79528.50\",\"0.440\"],[\"79529.10\",\"0.229\"]],\"a\":[[\"79559.90\",\"0.791\"],[\"79560.10\",\"0.004\"],[\"79564.90\",\"0.375\"],[\"79565.60\",\"1.199\"],[\"79566.10\",\"0.000\"],[\"79566.60\",\"0.205\"],[\"79568.30\",\"0.405\"],[\"79569.10\",\"0.704\"],[\"79589.70\",\"0.092\"],[\"79590.50\",\"0.102\"],[\"79620.00\",\"20.559\"],[\"79790.70\",\"13.153\"],[\"79939.70\",\"0.131\"],[\"80339.40\",\"3.990\"],[\"80657.60\",\"31.270\"],[\"80697.40\",\"11.320\"]],\"st\":1}}"}
{"receive_ns":1788580707293110000,"stream":"btcusdt@bookTicker","event_type":"bookTicker","event_time_ms":1788580707348,"raw_json":"{\"stream\":\"btcusdt@bookTicker\",\"data\":{\"e\":\"bookTicker\",\"u\":11479473106661,\"s\":\"BTCUSDT\",\"ps\":\"BTCUSDT\",\"b\":\"79543.90\",\"B\":\"6.542\",\"a\":\"79544.00\",\"A\":\"5.411\",\"T\":1788580707348,\"E\":1788580707348,\"st\":1}}"}
{"receive_ns":1788580707294449000,"stream":"btcusdt@bookTicker","event_type":"bookTicker","event_time_ms":1788580707350,"raw_json":"{\"stream\":\"btcusdt@bookTicker\",\"data\":{\"e\":\"bookTicker\",\"u\":11479473106802,\"s\":\"BTCUSDT\",\"ps\":\"BTCUSDT\",\"b\":\"79543.90\",\"B\":\"6.543\",\"a\":\"79544.00\",\"A\":\"5.411\",\"T\":1788580707350,\"E\":1788580707350,\"st\":1}}"}
{"receive_ns":1788580707330606000,"stream":"btcusdt@bookTicker","event_type":"bookTicker","event_time_ms":1788580707388,"raw_json":"{\"stream\":\"btcusdt@bookTicker\",\"data\":{\"e\":\"bookTicker\",\"u\":11479473108931,\"s\":\"BTCUSDT\",\"ps\":\"BTCUSDT\",\"b\":\"79543.90\",\"B\":\"6.416\",\"a\":\"79544.00\",\"A\":\"5.411\",\"T\":1788580707387,\"E\":1788580707388,\"st\":1}}"}
{"receive_ns":1788580707334469000,"stream":"btcusdt@bookTicker","event_type":"bookTicker","event_time_ms":1788580707390,"raw_json":"{\"stream\":\"btcusdt@bookTicker\",\"data\":{\"e\":\"bookTicker\",\"u\":11479473109100,\"s\":\"BTCUSDT\",\"ps\":\"BTCUSDT\",\"b\":\"79543.90\",\"B\":\"6.566\",\"a\":\"79544.00\",\"A\":\"5.411\",\"T\":1788580707390,\"E\":1788580707390,\"st\":1}}"}
{"receive_ns":1788580707345158000,"stream":"btcusdt@bookTicker","event_type":"bookTicker","event_time_ms":1788580707400,"raw_json":"{\"stream\":\"btcusdt@bookTicker\",\"data\":{\"e\":\"bookTicker\",\"u\":11479473109758,\"s\":\"BTCUSDT\",\"ps\":\"BTCUSDT\",\"b\":\"79543.90\",\"B\":\"6.566\",\"a\":\"79544.00\",\"A\":\"5.404\",\"T\":1788580707400,\"E\":1788580707400,\"st\":1}}"}
{"receive_ns":1788580707346191000,"stream":"btcusdt@bookTicker","event_type":"bookTicker","event_time_ms":1788580707403,"raw_json":"{\"stream\":\"btcusdt@bookTicker\",\"data\":{\"e\":\"bookTicker\",\"u\":11479473109895,\"s\":\"BTCUSDT\",\"ps\":\"BTCUSDT\",\"b\":\"79543.90\",\"B\":\"6.566\",\"a\":\"79544.00\",\"A\":\"5.414\",\"T\":1788580707403,\"E\":1788580707403,\"st\":1}}"}
{"receive_ns":1788580707349400000,"stream":"btcusdt@depth@100ms","event_type":"depthUpdate","event_time_ms":1788580707407,"raw_json":"{\"stream\":\"btcusdt@depth@100ms\",\"data\":{\"e\":\"depthUpdate\",\"E\":1788580707407,\"T\":1788580707406,\"s\":\"BTCUSDT\",\"ps\":\"BTCUSDT\",\"U\":11479473104454,\"u\":11479473110101,\"pu\":11479473104266,\"b\":[[\"1000.00\",\"25.354\"],[\"29143.90\",\"0.847\"],[\"29243.90\",\"1.253\"],[\"34000.00\",\"0.975\"],[\"71589.50\",\"0.014\"],[\"78743.20\",\"4.375\"],[\"78748.50\",\"4.438\"],[\"79146.10\",\"0.009\"],[\"79419.20\",\"0.000\"],[\"79453.10\",\"0.020\"],[\"79456.40\",\"0.318\"],[\"79472.30\",\"0.380\"],[\"79543.90\",\"6.566\"]],\"a\":[[\"79544.00\",\"5.414\"],[\"79570.60\",\"0.046\"],[\"79615.60\",\"0.006\"],[\"79784.60\",\"0.000\"],[\"79936.40\",\"0.008\"],[\"79937.70\",\"0.059\"],[\"79939.70\",\"0.136\"],[\"79941.80\",\"0.001\"],[\"80339.40\",\"3.990\"]],\"st\":1}}"}
{"receive_ns":1788580707459049000,"stream":"btcusdt@bookTicker","event_type":"bookTicker","event_time_ms":1788580707491,"raw_json":"{\"stream\":\"btcusdt@bookTicker\",\"data\":{\"e\":\"bookTicker\",\"u\":11479473114166,\"s\":\"BTCUSDT\",\"ps\":\"BTCUSDT\",\"b\":\"79543.90\",\"B\":\"6.622\",\"a\":\"79544.00\",\"A\":\"5.414\",\"T\":1788580707491,\"E\":1788580707491,\"st\":1}}"}
{"receive_ns":1788580707459232000,"stream":"btcusdt@bookTicker","event_type":"bookTicker","event_time_ms":1788580707493,"raw_json":"{\"stream\":\"btcusdt@bookTicker\",\"data\":{\"e\":\"bookTicker\",\"u\":11479473114273,\"s\":\"BTCUSDT\",\"ps\":\"BTCUSDT\",\"b\":\"79543.90\",\"B\":\"6.621\",\"a\":\"79544.00\",\"A\":\"5.414\",\"T\":1788580707492,\"E\":1788580707493,\"st\":1}}"}
{"receive_ns":1788580707459543000,"stream":"btcusdt@depth@100ms","event_type":"depthUpdate","event_time_ms":1788580707509,"raw_json":"{\"stream\":\"btcusdt@depth@100ms\",\"data\":{\"e\":\"depthUpdate\",\"E\":1788580707509,\"T\":1788580707508,\"s\":\"BTCUSDT\",\"ps\":\"BTCUSDT\",\"U\":11479473110162,\"u\":11479473114896,\"pu\":11479473110101,\"b\":[[\"1000.00\",\"25.354\"],[\"29143.90\",\"1.029\"],[\"29243.90\",\"1.071\"],[\"71589.50\",\"0.014\"],[\"71623.00\",\"0.000\"],[\"76362.10\",\"0.002\"],[\"78589.40\",\"26.489\"],[\"78748.50\",\"4.438\"],[\"79380.10\",\"0.022\"],[\"79419.50\",\"0.000\"],[\"79456.40\",\"0.318\"],[\"79477.20\",\"0.027\"],[\"79487.90\",\"1.030\"],[\"79503.80\",\"0.691\"],[\"79543.90\",\"6.621\"]],\"a\":[[\"79559.90\",\"0.715\"],[\"79666.30\",\"0.000\"],[\"79705.70\",\"0.000\"],[\"79939.70\",\"0.136\"],[\"80339.40\",\"3.990\"],[\"80431.70\",\"12.053\"],[\"80493.20\",\"10.300\"]],\"st\":1}}"}
{"receive_ns":1788580707578105000,"stream":"btcusdt@depth@100ms","event_type":"depthUpdate","event_time_ms":1788580707611,"raw_json":"{\"stream\":\"btcusdt@depth@100ms\",\"data\":{\"e\":\"depthUpdate\",\"E\":1788580707611,\"T\":1788580707609,\"s\":\"BTCUSDT\",\"ps\":\"BTCUSDT\",\"U\":11479473114958,\"u\":11479473119662,\"pu\":11479473114896,\"b\":[[\"29143.90\",\"1.211\"],[\"29243.90\",\"0.889\"],[\"71589.50\",\"0.014\"],[\"76362.10\",\"0.000\"],[\"78663.10\",\"0.191\"],[\"78748.50\",\"4.438\"],[\"79146.20\",\"3.664\"],[\"79380.20\",\"2.182\"],[\"79419.60\",\"0.574\"],[\"79453.10\",\"0.000\"],[\"79456.40\",\"0.318\"],[\"79474.60\",\"22.935\"],[\"79503.70\",\"0.173\"]],\"a\":[[\"79621.60\",\"0.016\"],[\"79630.60\",\"0.000\"],[\"79666.30\",\"0.437\"],[\"79705.70\",\"1.955\"],[\"79933.80\",\"0.018\"],[\"79936.40\",\"0.001\"],[\"79937.70\",\"0.041\"],[\"79939.70\",\"0.136\"],[\"80339.40\",\"3.990\"]],\"st\":1}}"}
{"receive_ns":1788580707636598000,"stream":"btcusdt@bookTicker","event_type":"bookTicker","event_time_ms":1788580707657,"raw_json":"{\"stream\":\"btcusdt@bookTicker\",\"data\":{\"e\":\"bookTicker\",\"u\":11479473121626,\"s\":\"BTCUSDT\",\"ps\":\"BTCUSDT\",\"b\":\"79543.90\",\"B\":\"6.621\",\"a\":\"79544.00\",\"A\":\"5.413\",\"T\":1788580707656,\"E\":1788580707657,\"st\":1}}"}
{"receive_ns":1788580707636788000,"stream":"btcusdt@bookTicker","event_type":"bookTicker","event_time_ms":1788580707657,"raw_json":"{\"stream\":\"btcusdt@bookTicker\",\"data\":{\"e\":\"bookTicker\",\"u\":11479473121632,\"s\":\"BTCUSDT\",\"ps\":\"BTCUSDT\",\"b\":\"79543.90\",\"B\":\"6.621\",\"a\":\"79544.00\",\"A\":\"5.412\",\"T\":1788580707656,\"E\":1788580707657,\"st\":1}}"}
{"receive_ns":1788580707636929000,"stream":"btcusdt@bookTicker","event_type":"bookTicker","event_time_ms":1788580707657,"raw_json":"{\"stream\":\"btcusdt@bookTicker\",\"data\":{\"e\":\"bookTicker\",\"u\":11479473121635,\"s\":\"BTCUSDT\",\"ps\":\"BTCUSDT\",\"b\":\"79543.90\",\"B\":\"6.621\",\"a\":\"79544.00\",\"A\":\"5.411\",\"T\":1788580707656,\"E\":1788580707657,\"st\":1}}"}
{"receive_ns":1788580707637115000,"stream":"btcusdt@trade","event_type":"trade","event_time_ms":1788580707657,"raw_json":"{\"stream\":\"btcusdt@trade\",\"data\":{\"e\":\"trade\",\"E\":1788580707657,\"T\":1788580707656,\"s\":\"BTCUSDT\",\"t\":8054266650,\"p\":\"79544.00\",\"q\":\"0.001\",\"X\":\"MARKET\",\"m\":false,\"st\":1}}"}
{"receive_ns":1788580707637240000,"stream":"btcusdt@trade","event_type":"trade","event_time_ms":1788580707657,"raw_json":"{\"stream\":\"btcusdt@trade\",\"data\":{\"e\":\"trade\",\"E\":1788580707657,\"T\":1788580707656,\"s\":\"BTCUSDT\",\"t\":8054266651,\"p\":\"79544.00\",\"q\":\"0.001\",\"X\":\"MARKET\",\"m\":false,\"st\":1}}"}
{"receive_ns":1788580707637367000,"stream":"btcusdt@trade","event_type":"trade","event_time_ms":1788580707657,"raw_json":"{\"stream\":\"btcusdt@trade\",\"data\":{\"e\":\"trade\",\"E\":1788580707657,\"T\":1788580707656,\"s\":\"BTCUSDT\",\"t\":8054266652,\"p\":\"79544.00\",\"q\":\"0.001\",\"X\":\"MARKET\",\"m\":false,\"st\":1}}"}
{"receive_ns":1788580707656894000,"stream":"btcusdt@depth@100ms","event_type":"depthUpdate","event_time_ms":1788580707713,"raw_json":"{\"stream\":\"btcusdt@depth@100ms\",\"data\":{\"e\":\"depthUpdate\",\"E\":1788580707713,\"T\":1788580707710,\"s\":\"BTCUSDT\",\"ps\":\"BTCUSDT\",\"U\":11479473119730,\"u\":11479473123846,\"pu\":11479473119662,\"b\":[[\"1000.00\",\"25.354\"],[\"29143.90\",\"1.386\"],[\"29243.90\",\"0.714\"],[\"71589.50\",\"0.014\"],[\"76362.10\",\"0.002\"],[\"77880.00\",\"0.440\"],[\"77932.00\",\"0.001\"],[\"77953.10\",\"0.021\"],[\"77984.00\",\"0.006\"],[\"78036.00\",\"0.004\"],[\"78088.00\",\"2.256\"],[\"78140.00\",\"0.126\"],[\"78192.00\",\"0.002\"],[\"78244.00\",\"0.567\"],[\"78296.00\",\"0.001\"],[\"78348.00\",\"0.020\"],[\"78400.00\",\"19.039\"],[\"78452.00\",\"0.016\"],[\"78504.00\",\"0.013\"],[\"78556.00\",\"0.081\"],[\"78608.00\",\"1.542\"],[\"78660.00\",\"0.459\"],[\"78712.00\",\"0.001\"],[\"78748.50\",\"4.438\"],[\"78764.00\",\"0.001\"],[\"78816.00\",\"52.516\"],[\"78868.00\",\"0.246\"],[\"78920.00\",\"0.901\"],[\"78972.00\",\"0.695\"],[\"79024.00\",\"0.002\"],[\"79076.00\",\"0.001\"],[\"79128.00\",\"0.578\"],[\"79180.00\",\"3.763\"],[\"79232.00\",\"0.265\"],[\"79284.00\",\"0.007\"],[\"79336.00\",\"0.001\"],[\"79388.00\",\"0.342\"],[\"79440.00\",\"4.515\"],[\"79453.10\",\"0.020\"],[\"79456.40\",\"0.308\"],[\"79474.60\",\"22.935\"],[\"79477.20\",\"0.027\"],[\"79492.00\",\"0.111\"]],\"a\":[[\"79544.00\",\"5.411\"],[\"79550.60\",\"0.000\"],[\"79550.70\",\"0.000\"],[\"79551.30\",\"0.381\"],[\"79589.60\",\"0.359\"],[\"79596.00\",\"0.006\"],[\"79648.00\",\"3.853\"],[\"79700.00\",\"3.750\"],[\"79936.40\",\"0.008\"],[\"79939.70\",\"0.131\"],[\"80140.60\",\"3.116\"],[\"80339.40\",\"3.990\"],[\"80539.10\",\"4.319\"]],\"st\":1}}"}
{"receive_ns":1788580707695297000,"stream":"btcusdt@bookTicker","event_type":"bookTicker","event_time_ms":1788580707721,"raw_json":"{\"stream\":\"btcusdt@bookTicker\",\"data\":{\"e\":\"bookTicker\",\"u\":11479473124784,\"s\":\"BTCUSDT\",\"ps\":\"BTCUSDT\",\"b\":\"79543.90\",\"B\":\"6.621\",\"a\":\"79544.00\",\"A\":\"5.165\",\"T\":1788580707721,\"E\":1788580707721,\"st\":1}}"}
{"receive_ns":1788580707695495000,"stream":"btcusdt@bookTicker","event_type":"bookTicker","event_time_ms":1788580707723,"raw_json":"{\"stream\":\"btcusdt@bookTicker\",\"data\":{\"e\":\"bookTicker\",\"u\":11479473124979,\"s\":\"BTCUSDT\",\"ps\":\"BTCUSDT\",\"b\":\"79543.90\",\"B\":\"6.622\",\"a\":\"79544.00\",\"A\":\"5.165\",\"T\":1788580707722,\"E\":1788580707723,\"st\":1}}"}
{"receive_ns":1788580707695644000,"stream":"btcusdt@bookTicker","event_type":"bookTicker","event_time_ms":1788580707740,"raw_json":"{\"stream\":\"btcusdt@bookTicker\",\"data\":{\"e\":\"bookTicker\",\"u\":11479473127184,\"s\":\"BTCUSDT\",\"ps\":\"BTCUSDT\",\"b\":\"79543.90\",\"B\":\"6.607\",\"a\":\"79544.00\",\"A\":\"5.165\",\"T\":1788580707739,\"E\":1788580707740,\"st\":1}}"}
{"receive_ns":1788580707695843000,"stream":"btcusdt@trade","event_type":"trade","event_time_ms":1788580707740,"raw_json":"{\"stream\":\"btcusdt@trade\",\"data\":{\"e\":\"trade\",\"E\":1788580707740,\"T\":1788580707739,\"s\":\"BTCUSDT\",\"t\":8054266653,\"p\":\"79543.90\",\"q\":\"0.015\",\"X\":\"MARKET\",\"m\":true,\"st\":1}}"}
{"receive_ns":1788580707782919000,"stream":"btcusdt@bookTicker","event_type":"bookTicker","event_time_ms":1788580707790,"raw_json":"{\"stream\":\"btcusdt@bookTicker\",\"data\":{\"e\":\"bookTicker\",\"u\":11479473130205,\"s\":\"BTCUSDT\",\"ps\":\"BTCUSDT\",\"b\":\"79543.90\",\"B\":\"6.606\",\"a\":\"79544.00\",\"A\":\"5.165\",\"T\":1788580707790,\"E\":1788580707790,\"st\":1}}"}
{"receive_ns":1788580707783154000,"stream":"btcusdt@bookTicker","event_type":"bookTicker","event_time_ms":1788580707792,"raw_json":"{\"stream\":\"btcusdt@bookTicker\",\"data\":{\"e\":\"bookTicker\",\"u\":11479473130399,\"s\":\"BTCUSDT\",\"ps\":\"BTCUSDT\",\"b\":\"79543.90\",\"B\":\"6.607\",\"a\":\"79544.00\",\"A\":\"5.165\",\"T\":1788580707792,\"E\":1788580707792,\"st\":1}}"}
{"receive_ns":1788580707783470000,"stream":"btcusdt@depth@100ms","event_type":"depthUpdate","event_time_ms":1788580707815,"raw_json":"{\"stream\":\"btcusdt@depth@100ms\",\"data\":{\"e\":\"depthUpdate\",\"E\":1788580707815,\"T\":1788580707813,\"s\":\"BTCUSDT\",\"ps\":\"BTCUSDT\",\"U\":11479473123941,\"u\":11479473131917,\"pu\":11479473123846,\"b\":[[\"29143.90\",\"1.568\"],[\"29243.90\",\"0.532\"],[\"71589.50\",\"0.014\"],[\"77953.10\",\"0.018\"],[\"78748.50\",\"4.438\"],[\"79419.60\",\"0.132\"],[\"79456.40\",\"0.318\"],[\"79509.40\",\"0.121\"],[\"79518.30\",\"0.018\"],[\"79543.90\",\"6.607\"]],\"a\":[[\"79544.00\",\"5.165\"],[\"79550.70\",\"0.380\"],[\"79551.30\",\"0.001\"],[\"79558.40\",\"0.077\"],[\"79571.20\",\"0.001\"],[\"79574.70\",\"0.001\"],[\"79617.80\",\"0.630\"],[\"79666.30\",\"0.000\"],[\"79939.70\",\"0.136\"],[\"80339.40\",\"3.990\"],[\"80498.50\",\"30.056\"],[\"81134.80\",\"0.006\"]],\"st\":1}}"}
{"receive_ns":1788580707867905000,"stream":"btcusdt@depth@100ms","event_type":"depthUpdate","event_time_ms":1788580707917,"raw_json":"{\"stream\":\"btcusdt@depth@100ms\",\"data\":{\"e\":\"depthUpdate\",\"E\":1788580707917,\"T\":1788580707914,\"s\":\"BTCUSDT\",\"ps\":\"BTCUSDT\",\"U\":11479473132037,\"u\":11479473137508,\"pu\":11479473131917,\"b\":[[\"29143.90\",\"1.743\"],[\"29243.90\",\"0.357\"],[\"71589.50\",\"0.014\"],[\"76362.10\",\"0.000\"],[\"78748.50\",\"4.438\"],[\"78992.90\",\"0.000\"],[\"79146.20\",\"3.654\"],[\"79380.20\",\"2.182\"],[\"79419.60\",\"0.574\"],[\"79453.10\",\"0.020\"],[\"79456.40\",\"0.318\"],[\"79457.90\",\"0.047\"]],\"a\":[[\"79665.00\",\"0.208\"],[\"79666.30\",\"0.437\"],[\"79668.10\",\"0.007\"],[\"79705.70\",\"1.955\"],[\"79790.70\",\"8.855\"],[\"79933.80\",\"0.000\"],[\"79936.40\",\"0.008\"],[\"79937.70\",\"0.059\"],[\"79939.70\",\"0.136\"],[\"80339.40\",\"3.990\"],[\"80538.10\",\"0.000\"]],\"st\":1}}"}
{"receive_ns":1788580707977240000,"stream":"btcusdt@depth@100ms","event_type":"depthUpdate","event_time_ms":1788580708019,"raw_json":"{\"stream\":\"btcusdt@depth@100ms\",\"data\":{\"e\":\"depthUpdate\",\"E\":1788580708019,\"T\":1788580708013,\"s\":\"BTCUSDT\",\"ps\":\"BTCUSDT\",\"U\":11479473137668,\"u\":11479473144358,\"pu\":11479473137508,\"b\":[[\"1000.00\",\"25.354\"],[\"29043.90\",\"0.056\"],[\"29143.90\",\"1.806\"],[\"29243.90\",\"0.238\"],[\"71589.50\",\"0.014\"],[\"76362.10\",\"0.002\"],[\"78743.20\",\"3.107\"],[\"78748.50\",\"4.438\"],[\"78942.10\",\"1.898\"],[\"79456.40\",\"0.318\"],[\"79457.90\",\"0.033\"]],\"a\":[[\"79939.70\",\"0.136\"],[\"80339.40\",\"3.990\"],[\"80521.40\",\"9.174\"],[\"80539.10\",\"4.939\"],[\"80617.80\",\"2.389\"]],\"st\":1}}"}
{"receive_ns":1788580707988812000,"stream":"btcusdt@bookTicker","event_type":"bookTicker","event_time_ms":1788580708037,"raw_json":"{\"stream\":\"btcusdt@bookTicker\",\"data\":{\"e\":\"bookTicker\",\"u\":11479473145598,\"s\":\"BTCUSDT\",\"ps\":\"BTCUSDT\",\"b\":\"79543.90\",\"B\":\"6.607\",\"a\":\"79544.00\",\"A\":\"5.175\",\"T\":1788580708037,\"E\":1788580708037,\"st\":1}}"}
{"receive_ns":1788580707989189000,"stream":"btcusdt@bookTicker","event_type":"bookTicker","event_time_ms":1788580708038,"raw_json":"{\"stream\":\"btcusdt@bookTicker\",\"data\":{\"e\":\"bookTicker\",\"u\":11479473145641,\"s\":\"BTCUSDT\",\"ps\":\"BTCUSDT\",\"b\":\"79543.90\",\"B\":\"6.607\",\"a\":\"79544.00\",\"A\":\"5.172\",\"T\":1788580708038,\"E\":1788580708038,\"st\":1}}"}
{"receive_ns":1788580708029098000,"stream":"btcusdt@bookTicker","event_type":"bookTicker","event_time_ms":1788580708085,"raw_json":"{\"stream\":\"btcusdt@bookTicker\",\"data\":{\"e\":\"bookTicker\",\"u\":11479473147958,\"s\":\"BTCUSDT\",\"ps\":\"BTCUSDT\",\"b\":\"79543.90\",\"B\":\"6.470\",\"a\":\"79544.00\",\"A\":\"5.172\",\"T\":1788580708085,\"E\":1788580708085,\"st\":1}}"}
{"receive_ns":1788580708032722000,"stream":"btcusdt@bookTicker","event_type":"bookTicker","event_time_ms":1788580708088,"raw_json":"{\"stream\":\"btcusdt@bookTicker\",\"data\":{\"e\":\"bookTicker\",\"u\":11479473148135,\"s\":\"BTCUSDT\",\"ps\":\"BTCUSDT\",\"b\":\"79543.90\",\"B\":\"6.608\",\"a\":\"79544.00\",\"A\":\"5.172\",\"T\":1788580708088,\"E\":1788580708088,\"st\":1}}"}
{"receive_ns":1788580708093020000,"stream":"btcusdt@depth@100ms","event_type":"depthUpdate","event_time_ms":1788580708121,"raw_json":"{\"stream\":\"btcusdt@depth@100ms\",\"data\":{\"e\":\"depthUpdate\",\"E\":1788580708121,\"T\":1788580708120,\"s\":\"BTCUSDT\",\"ps\":\"BTCUSDT\",\"U\":11479473144599,\"u\":11479473150344,\"pu\":11479473144358,\"b\":[[\"29043.90\",\"0.119\"],[\"29143.90\",\"1.862\"],[\"29243.90\",\"0.119\"],[\"63635.10\",\"0.000\"],[\"71589.50\",\"0.014\"],[\"76362.10\",\"0.000\"],[\"78748.50\",\"4.438\"],[\"79453.10\",\"0.020\"],[\"79456.40\",\"0.318\"],[\"79503.80\",\"0.000\"],[\"79529.60\",\"0.002\"],[\"79531.60\",\"0.003\"],[\"79543.90\",\"6.608\"]],\"a\":[[\"79544.00\",\"5.172\"],[\"79554.00\",\"0.550\"],[\"79554.20\",\"0.005\"],[\"79936.40\",\"0.008\"],[\"79937.70\",\"0.059\"],[\"79939.70\",\"0.136\"],[\"80339.40\",\"3.992\"],[\"81784.20\",\"0.245\"]],\"st\":1}}"}
{"receive_ns":1788580708107149000,"stream":"btcusdt@bookTicker","event_type":"bookTicker","event_time_ms":1788580708163,"raw_json":"{\"stream\":\"btcusdt@bookTicker\",\"data\":{\"e\":\"bookTicker\",\"u\":11479473153327,\"s\":\"BTCUSDT\",\"ps\":\"BTCUSDT\",\"b\":\"79543.90\",\"B\":\"6.601\",\"a\":\"79544.00\",\"A\":\"5.172\",\"T\":1788580708163,\"E\":1788580708163,\"st\":1}}"}
{"receive_ns":1788580708155343000,"stream":"btcusdt@bookTicker","event_type":"bookTicker","event_time_ms":1788580708173,"raw_json":"{\"stream\":\"btcusdt@bookTicker\",\"data\":{\"e\":\"bookTicker\",\"u\":11479473153859,\"s\":\"BTCUSDT\",\"ps\":\"BTCUSDT\",\"b\":\"79543.90\",\"B\":\"6.601\",\"a\":\"79544.00\",\"A\":\"5.132\",\"T\":1788580708173,\"E\":1788580708173,\"st\":1}}"}
{"receive_ns":1788580708155546000,"stream":"btcusdt@trade","event_type":"trade","event_time_ms":1788580708173,"raw_json":"{\"stream\":\"btcusdt@trade\",\"data\":{\"e\":\"trade\",\"E\":1788580708173,\"T\":1788580708173,\"s\":\"BTCUSDT\",\"t\":8054266654,\"p\":\"79544.00\",\"q\":\"0.006\",\"X\":\"MARKET\",\"m\":false,\"st\":1}}"}
{"receive_ns":1788580708155673000,"stream":"btcusdt@trade","event_type":"trade","event_time_ms":1788580708173,"raw_json":"{\"stream\":\"btcusdt@trade\",\"data\":{\"e\":\"trade\",\"E\":1788580708173,\"T\":1788580708173,\"s\":\"BTCUSDT\",\"t\":8054266655,\"p\":\"79544.00\",\"q\":\"0.001\",\"X\":\"MARKET\",\"m\":false,\"st\":1}}"}
