{"receive_ns":1788580708155789000,"stream":"btcusdt@trade","event_type":"trade","event_time_ms":1788580708173,"raw_json":"{\"stream\":\"btcusdt@trade\",\"data\":{\"e\":\"trade\",\"E\":1788580708173,\"T\":1788580708173,\"s\":\"BTCUSDT\",\"t\":8054266656,\"p\":\"79544.00\",\"q\":\"0.013\",\"X\":\"MARKET\",\"m\":false,\"st\":1}}"}
{"receive_ns":1788580708155901000,"stream":"btcusdt@trade","event_type":"trade","event_time_ms":1788580708173,"raw_json":"{\"stream\":\"btcusdt@trade\",\"data\":{\"e\":\"trade\",\"E\":1788580708173,\"T\":1788580708173,\"s\":\"BTCUSDT\",\"t\":8054266657,\"p\":\"79544.00\",\"q\":\"0.001\",\"X\":\"MARKET\",\"m\":false,\"st\":1}}"}
{"receive_ns":1788580708156013000,"stream":"btcusdt@trade","event_type":"trade","event_time_ms":1788580708173,"raw_json":"{\"stream\":\"btcusdt@trade\",\"data\":{\"e\":\"trade\",\"E\":1788580708173,\"T\":1788580708173,\"s\":\"BTCUSDT\",\"t\":8054266658,\"p\":\"79544.00\",\"q\":\"0.001\",\"X\":\"MARKET\",\"m\":false,\"st\":1}}"}
{"receive_ns":1788580708156137000,"stream":"btcusdt@trade","event_type":"trade","event_time_ms":1788580708173,"raw_json":"{\"stream\":\"btcusdt@trade\",\"data\":{\"e\":\"trade\",\"E\":1788580708173,\"T\":1788580708173,\"s\":\"BTCUSDT\",\"t\":8054266659,\"p\":\"79544.00\",\"q\":\"0.018\",\"X\":\"MARKET\",\"m\":false,\"st\":1}}"}
{"receive_ns":1788580708156279000,"stream":"btcusdt@bookTicker","event_type":"bookTicker","event_time_ms":1788580708175,"raw_json":"{\"stream\":\"btcusdt@bookTicker\",\"data\":{\"e\":\"bookTicker\",\"u\":11479473153984,\"s\":\"BTCUSDT\",\"ps\":\"BTCUSDT\",\"b\":\"79543.90\",\"B\":\"6.601\",\"a\":\"79544.00\",\"A\":\"4.899\",\"T\":1788580708175,\"E\":1788580708175,\"st\":1}}"}
{"receive_ns":1788580708156434000,"stream":"btcusdt@bookTicker","event_type":"bookTicker","event_time_ms":1788580708176,"raw_json":"{\"stream\":\"btcusdt@bookTicker\",\"data\":{\"e\":\"bookTicker\",\"u\":11479473153998,\"s\":\"BTCUSDT\",\"ps\":\"BTCUSDT\",\"b\":\"79543.90\",\"B\":\"6.601\",\"a\":\"79544.00\",\"A\":\"4.912\",\"T\":1788580708176,\"E\":1788580708176,\"st\":1}}"}
{"receive_ns":1788580708210529000,"stream":"btcusdt@depth@100ms","event_type":"depthUpdate","event_time_ms":1788580708223,"raw_json":"{\"stream\":\"btcusdt@depth@100ms\",\"data\":{\"e\":\"depthUpdate\",\"E\":1788580708223,\"T\":1788580708222,\"s\":\"BTCUSDT\",\"ps\":\"BTCUSDT\",\"U\":11479473150433,\"u\":11479473156573,\"pu\":11479473150344,\"b\":[[\"29043.90\",\"0.189\"],[\"29143.90\",\"1.904\"],[\"29243.90\",\"0.007\"],[\"71589.50\",\"0.014\"],[\"76362.10\",\"0.002\"],[\"78430.30\",\"29.034\"],[\"78532.10\",\"0.000\"],[\"78748.50\",\"4.438\"],[\"79146.20\",\"3.664\"],[\"79419.60\",\"0.574\"],[\"79456.40\",\"0.318\"],[\"79457.90\",\"0.052\"],[\"79474.60\",\"0.001\"],[\"79477.20\",\"22.961\"],[\"79543.90\",\"6.601\"]],\"a\":[[\"79544.00\",\"4.912\"],[\"79552.70\",\"0.168\"],[\"79553.80\",\"0.242\"],[\"79558.40\",\"0.001\"],[\"79666.30\",\"0.437\"],[\"79668.10\",\"0.007\"],[\"79939.70\",\"0.136\"],[\"80339.40\",\"3.990\"],[\"80339.50\",\"0.001\"]],\"st\":1}}"}
{"receive_ns":1788580708271535000,"stream":"btcusdt@bookTicker","event_type":"bookTicker","event_time_ms":1788580708288,"raw_json":"{\"stream\":\"btcusdt@bookTicker\",\"data\":{\"e\":\"bookTicker\",\"u\":11479473159250,\"s\":\"BTCUSDT\",\"ps\":\"BTCUSDT\",\"b\":\"79543.90\",\"B\":\"6.600\",\"a\":\"79544.00\",\"A\":\"4.912\",\"T\":1788580708288,\"E\":1788580708288,\"st\":1}}"}
{"receive_ns":1788580708271745000,"stream":"btcusdt@bookTicker","event_type":"bookTicker","event_time_ms":1788580708290,"raw_json":"{\"stream\":\"btcusdt@bookTicker\",\"data\":{\"e\":\"bookTicker\",\"u\":11479473159329,\"s\":\"BTCUSDT\",\"ps\":\"BTCUSDT\",\"b\":\"79543.90\",\"B\":\"6.600\",\"a\":\"79544.00\",\"A\":\"5.153\",\"T\":1788580708290,\"E\":1788580708290,\"st\":1}}"}
{"receive_ns":1788580708271893000,"stream":"btcusdt@bookTicker","event_type":"bookTicker","event_time_ms":1788580708291,"raw_json":"{\"stream\":\"btcusdt@bookTicker\",\"data\":{\"e\":\"bookTicker\",\"u\":11479473159359,\"s\":\"BTCUSDT\",\"ps\":\"BTCUSDT\",\"b\":\"79543.90\",\"B\":\"6.601\",\"a\":\"79544.00\",\"A\":\"5.153\",\"T\":1788580708290,\"E\":1788580708291,\"st\":1}}"}
{"receive_ns":1788580708272068000,"stream":"btcusdt@bookTicker","event_type":"bookTicker","event_time_ms":1788580708291,"raw_json":"{\"stream\":\"btcusdt@bookTicker\",\"data\":{\"e\":\"bookTicker\",\"u\":11479473159409,\"s\":\"BTCUSDT\",\"ps\":\"BTCUSDT\",\"b\":\"79543.90\",\"B\":\"6.601\",\"a\":\"79544.00\",\"A\":\"5.151\",\"T\":1788580708291,\"E\":1788580708291,\"st\":1}}"}
{"receive_ns":1788580708275266000,"stream":"btcusdt@depth@100ms","event_type":"depthUpdate","event_time_ms":1788580708325,"raw_json":"{\"stream\":\"btcusdt@depth@100ms\",\"data\":{\"e\":\"depthUpdate\",\"E\":1788580708325,\"T\":1788580708323,\"s\":\"BTCUSDT\",\"ps\":\"BTCUSDT\",\"U\":11479473156751,\"u\":11479473161341,\"pu\":11479473156573,\"b\":[[\"1000.00\",\"25.354\"],[\"29043.90\",\"0.357\"],[\"29143.90\",\"1.743\"],[\"29243.90\",\"0.000\"],[\"71589.50\",\"0.014\"],[\"75566.70\",\"0.012\"],[\"78748.50\",\"4.438\"],[\"78879.20\",\"0.001\"],[\"79452.20\",\"0.380\"],[\"79453.10\",\"0.000\"],[\"79456.40\",\"0.010\"],[\"79478.80\",\"4.553\"],[\"79520.20\",\"2.395\"],[\"79543.90\",\"6.601\"]],\"a\":[[\"79544.00\",\"5.151\"],[\"79560.10\",\"0.004\"],[\"79575.10\",\"0.016\"],[\"79617.70\",\"3.438\"],[\"79635.20\",\"0.025\"],[\"79936.40\",\"0.001\"],[\"79937.70\",\"0.004\"],[\"79939.70\",\"0.005\"],[\"80339.40\",\"3.990\"],[\"80894.00\",\"0.000\"],[\"81134.80\",\"0.009\"]],\"st\":1}}"}
{"receive_ns":1788580708286315000,"stream":"btcusdt@bookTicker","event_type":"bookTicker","event_time_ms":1788580708332,"raw_json":"{\"stream\":\"btcusdt@bookTicker\",\"data\":{\"e\":\"bookTicker\",\"u\":11479473161792,\"s\":\"BTCUSDT\",\"ps\":\"BTCUSDT\",\"b\":\"79543.90\",\"B\":\"6.601\",\"a\":\"79544.00\",\"A\":\"5.108\",\"T\":1788580708332,\"E\":1788580708332,\"st\":1}}"}
{"receive_ns":1788580708287435000,"stream":"btcusdt@bookTicker","event_type":"bookTicker","event_time_ms":1788580708334,"raw_json":"{\"stream\":\"btcusdt@bookTicker\",\"data\":{\"e\":\"bookTicker\",\"u\":11479473162072,\"s\":\"BTCUSDT\",\"ps\":\"BTCUSDT\",\"b\":\"79543.90\",\"B\":\"6.601\",\"a\":\"79544.00\",\"A\":\"5.152\",\"T\":1788580708334,\"E\":1788580708334,\"st\":1}}"}
{"receive_ns":1788580708287734000,"stream":"btcusdt@bookTicker","event_type":"bookTicker","event_time_ms":1788580708335,"raw_json":"{\"stream\":\"btcusdt@bookTicker\",\"data\":{\"e\":\"bookTicker\",\"u\":11479473162133,\"s\":\"BTCUSDT\",\"ps\":\"BTCUSDT\",\"b\":\"79543.90\",\"B\":\"6.601\",\"a\":\"79544.00\",\"A\":\"5.154\",\"T\":1788580708335,\"E\":1788580708335,\"st\":1}}"}
{"receive_ns":1788580708330118000,"stream":"btcusdt@bookTicker","event_type":"bookTicker","event_time_ms":1788580708371,"raw_json":"{\"stream\":\"btcusdt@bookTicker\",\"data\":{\"e\":\"bookTicker\",\"u\":11479473164111,\"s\":\"BTCUSDT\",\"ps\":\"BTCUSDT\",\"b\":\"79543.90\",\"B\":\"6.602\",\"a\":\"79544.00\",\"A\":\"5.154\",\"T\":1788580708371,\"E\":1788580708371,\"st\":1}}"}
{"receive_ns":1788580708389831000,"stream":"btcusdt@depth@100ms","event_type":"depthUpdate","event_time_ms":1788580708427,"raw_json":"{\"stream\":\"btcusdt@depth@100ms\",\"data\":{\"e\":\"depthUpdate\",\"E\":1788580708427,\"T\":1788580708425,\"s\":\"BTCUSDT\",\"ps\":\"BTCUSDT\",\"U\":11479473161454,\"u\":11479473166819,\"pu\":11479473161341,\"b\":[[\"29043.90\",\"0.539\"],[\"29143.90\",\"1.561\"],[\"63635.00\",\"0.000\"],[\"71589.50\",\"0.014\"],[\"75566.80\",\"0.006\"],[\"76362.10\",\"0.000\"],[\"78748.50\",\"4.438\"],[\"79146.10\",\"0.008\"],[\"79332.40\",\"0.000\"],[\"79332.50\",\"5.358\"],[\"79452.20\",\"3.330\"],[\"79453.10\",\"0.020\"],[\"79456.40\",\"0.308\"],[\"79543.90\",\"6.602\"]],\"a\":[[\"79544.00\",\"5.154\"],[\"79635.00\",\"4.086\"],[\"79668.10\",\"0.007\"],[\"79765.70\",\"19.248\"],[\"79765.80\",\"0.000\"],[\"79936.40\",\"0.008\"],[\"79937.70\",\"0.059\"],[\"79939.70\",\"0.131\"],[\"79941.80\",\"0.000\"],[\"80272.60\",\"8.769\"],[\"80334.10\",\"4.240\"],[\"80339.40\",\"3.990\"]],\"st\":1}}"}
{"receive_ns":1788580708390073000,"stream":"btcusdt@bookTicker","event_type":"bookTicker","event_time_ms":1788580708434,"raw_json":"{\"stream\":\"btcusdt@bookTicker\",\"data\":{\"e\":\"bookTicker\",\"u\":11479473167251,\"s\":\"BTCUSDT\",\"ps\":\"BTCUSDT\",\"b\":\"79543.90\",\"B\":\"6.602\",\"a\":\"79544.00\",\"A\":\"5.144\",\"T\":1788580708433,\"E\":1788580708434,\"st\":1}}"}
{"receive_ns":1788580708390250000,"stream":"btcusdt@bookTicker","event_type":"bookTicker","event_time_ms":1788580708436,"raw_json":"{\"stream\":\"btcusdt@bookTicker\",\"data\":{\"e\":\"bookTicker\",\"u\":11479473167460,\"s\":\"BTCUSDT\",\"ps\":\"BTCUSDT\",\"b\":\"79543.90\",\"B\":\"6.602\",\"a\":\"79544.00\",\"A\":\"5.155\",\"T\":1788580708436,\"E\":1788580708436,\"st\":1}}"}
{"receive_ns":1788580708457544000,"stream":"btcusdt@bookTicker","event_type":"bookTicker","event_time_ms":1788580708506,"raw_json":"{\"stream\":\"btcusdt@bookTicker\",\"data\":{\"e\":\"bookTicker\",\"u\":11479473170643,\"s\":\"BTCUSDT\",\"ps\":\"BTCUSDT\",\"b\":\"79543.90\",\"B\":\"6.546\",\"a\":\"79544.00\",\"A\":\"5.155\",\"T\":1788580708506,\"E\":1788580708506,\"st\":1}}"}
{"receive_ns":1788580708472541000,"stream":"btcusdt@depth@100ms","event_type":"depthUpdate","event_time_ms":1788580708529,"raw_json":"{\"stream\":\"btcusdt@depth@100ms\",\"data\":{\"e\":\"depthUpdate\",\"E\":1788580708529,\"T\":1788580708525,\"s\":\"BTCUSDT\",\"ps\":\"BTCUSDT\",\"U\":11479473166958,\"u\":11479473171796,\"pu\":11479473166819,\"b\":[[\"29043.90\",\"0.714\"],[\"29143.90\",\"1.386\"],[\"63400.00\",\"0.200\"],[\"71589.50\",\"0.014\"],[\"71623.00\",\"0.000\"],[\"76362.10\",\"0.002\"],[\"78333.20\",\"2.678\"],[\"78509.80\",\"3.133\"],[\"78748.50\",\"4.438\"],[\"78828.00\",\"1.840\"],[\"78866.90\",\"0.594\"],[\"79146.10\",\"0.009\"],[\"79146.20\",\"3.664\"],[\"79419.60\",\"0.132\"],[\"79456.40\",\"0.318\"],[\"79472.30\",\"0.378\"],[\"79488.20\",\"0.130\"],[\"79499.70\",\"0.368\"],[\"79499.90\",\"0.002\"],[\"79501.40\",\"0.693\"],[\"79531.60\",\"0.000\"],[\"79543.90\",\"6.546\"]],\"a\":[[\"79544.00\",\"5.155\"],[\"79599.70\",\"0.052\"],[\"79615.60\",\"0.004\"],[\"79666.30\",\"0.000\"],[\"79939.70\",\"0.136\"],[\"79941.80\",\"0.001\"],[\"80339.40\",\"3.990\"],[\"80538.30\",\"4.951\"],[\"80995.80\",\"3.328\"]],\"st\":1}}"}
{"receive_ns":1788580708508263000,"stream":"btcusdt@bookTicker","event_type":"bookTicker","event_time_ms":1788580708530,"raw_json":"{\"stream\":\"btcusdt@bookTicker\",\"data\":{\"e\":\"bookTicker\",\"u\":11479473172032,\"s\":\"BTCUSDT\",\"ps\":\"BTCUSDT\",\"b\":\"79543.90\",\"B\":\"6.546\",\"a\":\"79544.00\",\"A\":\"5.157\",\"T\":1788580708530,\"E\":1788580708530,\"st\":1}}"}
{"receive_ns":1788580708537225000,"stream":"btcusdt@bookTicker","event_type":"bookTicker","event_time_ms":1788580708593,"raw_json":"{\"stream\":\"btcusdt@bookTicker\",\"data\":{\"e\":\"bookTicker\",\"u\":11479473175709,\"s\":\"BTCUSDT\",\"ps\":\"BTCUSDT\",\"b\":\"79543.90\",\"B\":\"6.546\",\"a\":\"79544.00\",\"A\":\"5.403\",\"T\":1788580708593,\"E\":1788580708593,\"st\":1}}"}
{"receive_ns":1788580708537443000,"stream":"btcusdt@bookTicker","event_type":"bookTicker","event_time_ms":1788580708594,"raw_json":"{\"stream\":\"btcusdt@bookTicker\",\"data\":{\"e\":\"bookTicker\",\"u\":11479473175760,\"s\":\"BTCUSDT\",\"ps\":\"BTCUSDT\",\"b\":\"79543.90\",\"B\":\"6.546\",\"a\":\"79544.00\",\"A\":\"5.401\",\"T\":1788580708594,\"E\":1788580708594,\"st\":1}}"}
{"receive_ns":1788580708584919000,"stream":"btcusdt@bookTicker","event_type":"bookTicker","event_time_ms":1788580708609,"raw_json":"{\"stream\":\"btcusdt@bookTicker\",\"data\":{\"e\":\"bookTicker\",\"u\":11479473176733,\"s\":\"BTCUSDT\",\"ps\":\"BTCUSDT\",\"b\":\"79543.90\",\"B\":\"6.546\",\"a\":\"79544.00\",\"A\":\"5.389\",\"T\":1788580708609,\"E\":1788580708609,\"st\":1}}"}
{"receive_ns":1788580708585416000,"stream":"btcusdt@depth@100ms","event_type":"depthUpdate","event_time_ms":1788580708631,"raw_json":"{\"stream\":\"btcusdt@depth@100ms\",\"data\":{\"e\":\"depthUpdate\",\"E\":1788580708631,\"T\":1788580708630,\"s\":\"BTCUSDT\",\"ps\":\"BTCUSDT\",\"U\":11479473171976,\"u\":11479473178307,\"pu\":11479473171796,\"b\":[[\"1000.00\",\"25.354\"],[\"29043.90\",\"0.896\"],[\"29143.90\",\"1.204\"],[\"63635.00\",\"0.000\"],[\"71589.50\",\"0.014\"],[\"76362.10\",\"0.000\"],[\"78748.50\",\"4.438\"],[\"79380.20\",\"2.249\"],[\"79419.60\",\"0.574\"],[\"79453.10\",\"0.020\"],[\"79456.40\",\"0.318\"],[\"79501.40\",\"0.002\"]],\"a\":[[\"79544.00\",\"5.389\"],[\"79610.60\",\"0.011\"],[\"79627.40\",\"0.011\"],[\"79666.30\",\"0.419\"],[\"79705.70\",\"1.864\"],[\"79936.40\",\"0.008\"],[\"79937.70\",\"0.059\"],[\"79939.70\",\"0.073\"],[\"79941.70\",\"2.561\"],[\"79958.20\",\"0.087\"],[\"80339.40\",\"3.990\"]],\"st\":1}}"}
{"receive_ns":1788580708597708000,"stream":"btcusdt@bookTicker","event_type":"bookTicker","event_time_ms":1788580708645,"raw_json":"{\"stream\":\"btcusdt@bookTicker\",\"data\":{\"e\":\"bookTicker\",\"u\":11479473179308,\"s\":\"BTCUSDT\",\"ps\":\"BTCUSDT\",\"b\":\"79543.90\",\"B\":\"6.546\",\"a\":\"79544.00\",\"A\":\"5.351\",\"T\":1788580708645,\"E\":1788580708645,\"st\":1}}"}
{"receive_ns":1788580708599963000,"stream":"btcusdt@bookTicker","event_type":"bookTicker","event_time_ms":1788580708648,"raw_json":"{\"stream\":\"btcusdt@bookTicker\",\"data\":{\"e\":\"bookTicker\",\"u\":11479473179562,\"s\":\"BTCUSDT\",\"ps\":\"BTCUSDT\",\"b\":\"79543.90\",\"B\":\"6.546\",\"a\":\"79544.00\",\"A\":\"5.390\",\"T\":1788580708648,\"E\":1788580708648,\"st\":1}}"}
{"receive_ns":1788580708600158000,"stream":"btcusdt@bookTicker","event_type":"bookTicker","event_time_ms":1788580708649,"raw_json":"{\"stream\":\"btcusdt@bookTicker\",\"data\":{\"e\":\"bookTicker\",\"u\":11479473179651,\"s\":\"BTCUSDT\",\"ps\":\"BTCUSDT\",\"b\":\"79543.90\",\"B\":\"6.546\",\"a\":\"79544.00\",\"A\":\"5.392\",\"T\":1788580708649,\"E\":1788580708649,\"st\":1}}"}
{"receive_ns":1788580708658687000,"stream":"btcusdt@bookTicker","event_type":"bookTicker","event_time_ms":1788580708714,"raw_json":"{\"stream\":\"btcusdt@bookTicker\",\"data\":{\"e\":\"bookTicker\",\"u\":11479473183727,\"s\":\"BTCUSDT\",\"ps\":\"BTCUSDT\",\"b\":\"79543.90\",\"B\":\"6.544\",\"a\":\"79544.00\",\"A\":\"5.392\",\"T\":1788580708714,\"E\":1788580708714,\"st\":1}}"}
{"receive_ns":1788580708741264000,"stream":"btcusdt@depth@100ms","event_type":"depthUpdate","event_time_ms":1788580708733,"raw_json":"{\"stream\":\"btcusdt@depth@100ms\",\"data\":{\"e\":\"depthUpdate\",\"E\":1788580708733,\"T\":1788580708730,\"s\":\"BTCUSDT\",\"ps\":\"BTCUSDT\",\"U\":11479473178446,\"u\":11479473184421,\"pu\":11479473178307,\"b\":[[\"29043.90\",\"1.071\"],[\"29143.90\",\"1.029\"],[\"63635.00\",\"0.000\"],[\"71589.50\",\"0.014\"],[\"76362.10\",\"0.002\"],[\"78748.50\",\"4.438\"],[\"79419.60\",\"0.512\"],[\"79456.40\",\"0.318\"],[\"79543.90\",\"6.544\"]],\"a\":[[\"79544.00\",\"5.392\"],[\"79666.30\",\"0.357\"],[\"79939.70\",\"0.073\"],[\"80272.60\",\"8.582\"],[\"80339.40\",\"3.990\"]],\"st\":1}}"}
{"receive_ns":1788580708741489000,"stream":"btcusdt@bookTicker","event_type":"bookTicker","event_time_ms":1788580708738,"raw_json":"{\"stream\":\"btcusdt@bookTicker\",\"data\":{\"e\":\"bookTicker\",\"u\":11479473184754,\"s\":\"BTCUSDT\",\"ps\":\"BTCUSDT\",\"b\":\"79543.90\",\"B\":\"6.544\",\"a\":\"79544.00\",\"A\":\"5.982\",\"T\":1788580708738,\"E\":1788580708738,\"st\":1}}"}
{"receive_ns":1788580708741646000,"stream":"btcusdt@bookTicker","event_type":"bookTicker","event_time_ms":1788580708740,"raw_json":"{\"stream\":\"btcusdt@bookTicker\",\"data\":{\"e\":\"bookTicker\",\"u\":11479473184843,\"s\":\"BTCUSDT\",\"ps\":\"BTCUSDT\",\"b\":\"79543.90\",\"B\":\"6.544\",\"a\":\"79544.00\",\"A\":\"5.980\",\"T\":1788580708740,\"E\":1788580708740,\"st\":1}}"}
{"receive_ns":1788580708741839000,"stream":"btcusdt@bookTicker","event_type":"bookTicker","event_time_ms":1788580708740,"raw_json":"{\"stream\":\"btcusdt@bookTicker\",\"data\":{\"e\":\"bookTicker\",\"u\":11479473184844,\"s\":\"BTCUSDT\",\"ps\":\"BTCUSDT\",\"b\":\"79543.90\",\"B\":\"6.544\",\"a\":\"79544.00\",\"A\":\"5.979\",\"T\":1788580708740,\"E\":1788580708740,\"st\":1}}"}
{"receive_ns":1788580708742073000,"stream":"btcusdt@bookTicker","event_type":"bookTicker","event_time_ms":1788580708741,"raw_json":"{\"stream\":\"btcusdt@bookTicker\",\"data\":{\"e\":\"bookTicker\",\"u\":11479473184926,\"s\":\"BTCUSDT\",\"ps\":\"BTCUSDT\",\"b\":\"79543.90\",\"B\":\"6.544\",\"a\":\"79544.00\",\"A\":\"5.980\",\"T\":1788580708741,\"E\":1788580708741,\"st\":1}}"}
{"receive_ns":1788580708742284000,"stream":"btcusdt@bookTicker","event_type":"bookTicker","event_time_ms":1788580708799,"raw_json":"{\"stream\":\"btcusdt@bookTicker\",\"data\":{\"e\":\"bookTicker\",\"u\":11479473187088,\"s\":\"BTCUSDT\",\"ps\":\"BTCUSDT\",\"b\":\"79543.90\",\"B\":\"6.543\",\"a\":\"79544.00\",\"A\":\"5.980\",\"T\":1788580708799,\"E\":1788580708799,\"st\":1}}"}
{"receive_ns":1788580708745623000,"stream":"btcusdt@bookTicker","event_type":"bookTicker","event_time_ms":1788580708801,"raw_json":"{\"stream\":\"btcusdt@bookTicker\",\"data\":{\"e\":\"bookTicker\",\"u\":11479473187222,\"s\":\"BTCUSDT\",\"ps\":\"BTCUSDT\",\"b\":\"79543.90\",\"B\":\"6.544\",\"a\":\"79544.00\",\"A\":\"5.980\",\"T\":1788580708801,\"E\":1788580708801,\"st\":1}}"}
{"receive_ns":1788580708791803000,"stream":"btcusdt@depth@100ms","event_type":"depthUpdate","event_time_ms":1788580708835,"raw_json":"{\"stream\":\"btcusdt@depth@100ms\",\"data\":{\"e\":\"depthUpdate\",\"E\":1788580708835,\"T\":1788580708834,\"s\":\"BTCUSDT\",\"ps\":\"BTCUSDT\",\"U\":11479473184569,\"u\":11479473188758,\"pu\":11479473184421,\"b\":[[\"1000.00\",\"25.504\"],[\"29043.90\",\"1.253\"],[\"29143.90\",\"0.847\"],[\"71589.50\",\"0.014\"],[\"77953.10\",\"0.021\"],[\"78425.10\",\"28.037\"],[\"78482.50\",\"11.166\"],[\"78748.50\",\"4.438\"],[\"79146.20\",\"3.664\"],[\"79453.10\",\"0.000\"],[\"79456.40\",\"0.318\"],[\"79487.90\",\"0.200\"],[\"79543.90\",\"6.544\"]],\"a\":[[\"79544.00\",\"5.980\"],[\"79575.10\",\"0.010\"],[\"79620.00\",\"16.148\"],[\"79620.30\",\"0.005\"],[\"79628.30\",\"29.644\"],[\"79936.40\",\"0.001\"],[\"79937.70\",\"0.059\"],[\"79939.70\",\"0.136\"],[\"79941.70\",\"2.498\"],[\"80106.90\",\"0.103\"],[\"80312.30\",\"1.118\"],[\"80339.40\",\"3.990\"],[\"80493.20\",\"9.059\"],[\"80657.60\",\"33.128\"]],\"st\":1}}"}
{"receive_ns":1788580708860423000,"stream":"btcusdt@bookTicker","event_type":"bookTicker","event_time_ms":1788580708893,"raw_json":"{\"stream\":\"btcusdt@bookTicker\",\"data\":{\"e\":\"bookTicker\",\"u\":11479473191623,\"s\":\"BTCUSDT\",\"ps\":\"BTCUSDT\",\"b\":\"79543.90\",\"B\":\"6.541\",\"a\":\"79544.00\",\"A\":\"5.980\",\"T\":1788580708893,\"E\":1788580708893,\"st\":1}}"}
{"receive_ns":1788580708860868000,"stream":"btcusdt@trade","event_type":"trade","event_time_ms":1788580708893,"raw_json":"{\"stream\":\"btcusdt@trade\",\"data\":{\"e\":\"trade\",\"E\":1788580708893,\"T\":1788580708893,\"s\":\"BTCUSDT\",\"t\":8054266660,\"p\":\"79543.90\",\"q\":\"0.003\",\"X\":\"MARKET\",\"m\":true,\"st\":1}}"}
{"receive_ns":1788580708919555000,"stream":"btcusdt@depth@100ms","event_type":"depthUpdate","event_time_ms":1788580708937,"raw_json":"{\"stream\":\"btcusdt@depth@100ms\",\"data\":{\"e\":\"depthUpdate\",\"E\":1788580708937,\"T\":1788580708933,\"s\":\"BTCUSDT\",\"ps\":\"BTCUSDT\",\"U\":11479473188844,\"u\":11479473193752,\"pu\":11479473188758,\"b\":[[\"1000.00\",\"25.354\"],[\"29043.90\",\"1.428\"],[\"29143.90\",\"0.672\"],[\"63635.00\",\"0.000\"],[\"71202.30\",\"0.000\"],[\"71589.50\",\"0.014\"],[\"75566.70\",\"0.014\"],[\"76362.10\",\"0.000\"],[\"77953.10\",\"0.018\"],[\"78430.30\",\"29.289\"],[\"78467.40\",\"0.000\"],[\"78748.50\",\"4.438\"],[\"78800.60\",\"2.340\"],[\"79419.60\",\"0.419\"],[\"79452.20\",\"3.306\"],[\"79453.10\",\"0.020\"],[\"79456.40\",\"0.308\"],[\"79528.40\",\"0.177\"],[\"79529.30\",\"1.307\"],[\"79529.60\",\"0.064\"],[\"79543.90\",\"6.541\"]],\"a\":[[\"79550.40\",\"0.050\"],[\"79558.60\",\"0.076\"],[\"79568.20\",\"0.453\"],[\"79569.10\",\"0.252\"],[\"79623.00\",\"29.653\"],[\"79628.30\",\"0.000\"],[\"79635.00\",\"4.164\"],[\"79666.30\",\"0.288\"],[\"79765.60\",\"19.596\"],[\"79765.70\",\"0.010\"],[\"79784.90\",\"0.003\"],[\"79785.00\",\"0.426\"],[\"79936.40\",\"0.008\"],[\"79939.70\",\"0.131\"],[\"80299.70\",\"3.480\"],[\"80339.40\",\"3.990\"],[\"80498.50\",\"31.297\"],[\"80692.00\",\"5.939\"],[\"81134.80\",\"0.006\"],[\"81174.80\",\"0.185\"]],\"st\":1}}"}
{"receive_ns":1788580708983593000,"stream":"btcusdt@depth@100ms","event_type":"depthUpdate","event_time_ms":1788580709039,"raw_json":"{\"stream\":\"btcusdt@depth@100ms\",\"data\":{\"e\":\"depthUpdate\",\"E\":1788580709039,\"T\":1788580709037,\"s\":\"BTCUSDT\",\"ps\":\"BTCUSDT\",\"U\":11479473193951,\"u\":11479473199164,\"pu\":11479473193752,\"b\":[[\"29043.90\",\"1.610\"],[\"29143.90\",\"0.490\"],[\"63635.00\",\"0.000\"],[\"71589.50\",\"0.014\"],[\"75566.70\",\"0.016\"],[\"76362.10\",\"0.002\"],[\"78430.30\",\"31.199\"],[\"78748.50\",\"4.438\"],[\"78828.00\",\"2.030\"],[\"79456.40\",\"0.318\"],[\"79529.60\",\"0.068\"]],\"a\":[[\"79549.00\",\"0.033\"],[\"79939.70\",\"0.136\"],[\"79954.20\",\"0.001\"],[\"80008.50\",\"0.004\"],[\"80062.80\",\"0.001\"],[\"80117.10\",\"0.001\"],[\"80171.40\",\"0.002\"],[\"80225.70\",\"0.001\"],[\"80280.00\",\"2.173\"],[\"80312.30\",\"0.559\"],[\"80334.20\",\"0.001\"],[\"80339.40\",\"3.990\"],[\"80388.50\",\"0.001\"],[\"80442.80\",\"0.026\"],[\"80497.10\",\"0.691\"],[\"80551.40\",\"0.001\"],[\"80605.70\",\"0.010\"],[\"80660.00\",\"0.021\"],[\"80714.20\",\"0.031\"],[\"80768.50\",\"0.007\"],[\"80771.50\",\"4.203\"],[\"80822.80\",\"0.006\"],[\"80877.10\",\"0.001\"],[\"80931.40\",\"0.001\"],[\"80985.70\",\"0.001\"],[\"81040.00\",\"0.106\"],[\"81094.20\",\"0.001\"],[\"81131.80\",\"0.000\"],[\"81148.50\",\"1.281\"],[\"81202.80\",\"0.001\"],[\"81257.10\",\"0.011\"],[\"81311.40\",\"0.001\"],[\"81365.70\",\"0.006\"],[\"81420.00\",\"0.250\"],[\"81474.20\",\"0.001\"],[\"81528.50\",\"0.004\"],[\"81582.80\",\"0.001\"],[\"81637.10\",\"0.003\"],[\"81691.40\",\"0.001\"],[\"81745.70\",\"0.001\"],[\"81800.00\",\"11.733\"]],\"st\":1}}"}
{"receive_ns":1788580709035031000,"stream":"btcusdt@bookTicker","event_type":"bookTicker","event_time_ms":1788580709070,"raw_json":"{\"stream\":\"btcusdt@bookTicker\",\"data\":{\"e\":\"bookTicker\",\"u\":11479473200610,\"s\":\"BTCUSDT\",\"ps\":\"BTCUSDT\",\"b\":\"79543.90\",\"B\":\"6.541\",\"a\":\"79544.00\",\"A\":\"5.968\",\"T\":1788580709070,\"E\":1788580709070,\"st\":1}}"}
{"receive_ns":1788580709035352000,"stream":"btcusdt@bookTicker","event_type":"bookTicker","event_time_ms":1788580709073,"raw_json":"{\"stream\":\"btcusdt@bookTicker\",\"data\":{\"e\":\"bookTicker\",\"u\":11479473200777,\"s\":\"BTCUSDT\",\"ps\":\"BTCUSDT\",\"b\":\"79543.90\",\"B\":\"6.541\",\"a\":\"79544.00\",\"A\":\"5.985\",\"T\":1788580709073,\"E\":1788580709073,\"st\":1}}"}
{"receive_ns":1788580709035641000,"stream":"btcusdt@bookTicker","event_type":"bookTicker","event_time_ms":1788580709075,"raw_json":"{\"stream\":\"btcusdt@bookTicker\",\"data\":{\"e\":\"bookTicker\",\"u\":11479473200839,\"s\":\"BTCUSDT\",\"ps\":\"BTCUSDT\",\"b\":\"79543.90\",\"B\":\"6.541\",\"a\":\"79544.00\",\"A\":\"5.987\",\"T\":1788580709074,\"E\":1788580709075,\"st\":1}}"}
{"receive_ns":1788580709094553000,"stream":"btcusdt@depth@100ms","event_type":"depthUpdate","event_time_ms":1788580709141,"raw_json":"{\"stream\":\"btcusdt@depth@100ms\",\"data\":{\"e\":\"depthUpdate\",\"E\":1788580709141,\"T\":1788580709137,\"s\":\"BTCUSDT\",\"ps\":\"BTCUSDT\",\"U\":11479473199285,\"u\":11479473204973,\"pu\":11479473199164,\"b\":[[\"1000.00\",\"25.354\"],[\"29043.90\",\"1.757\"],[\"29143.90\",\"0.329\"],[\"29443.90\",\"0.014\"],[\"63635.00\",\"0.000\"],[\"63635.10\",\"0.000\"],[\"71202.30\",\"0.019\"],[\"71589.50\",\"0.014\"],[\"76362.10\",\"0.000\"],[\"78204.80\",\"3.832\"],[\"78668.90\",\"2.599\"],[\"78748.50\",\"5.706\"],[\"79146.20\",\"3.664\"],[\"79419.60\",\"0.132\"],[\"79453.10\",\"0.020\"],[\"79456.40\",\"0.318\"],[\"79529.60\",\"0.064\"]],\"a\":[[\"79544.00\",\"5.987\"],[\"79554.00\",\"0.552\"],[\"79554.20\",\"0.007\"],[\"79624.90\",\"0.003\"],[\"79666.30\",\"0.000\"],[\"79936.40\",\"0.008\"],[\"79937.70\",\"0.059\"],[\"79939.70\",\"0.136\"],[\"80339.40\",\"3.990\"],[\"81134.90\",\"1.846\"],[\"81545.50\",\"1.776\"]],\"st\":1}}"}
{"receive_ns":1788580709182065000,"stream":"btcusdt@bookTicker","event_type":"bookTicker","event_time_ms":1788580709210,"raw_json":"{\"stream\":\"btcusdt@bookTicker\",\"data\":{\"e\":\"bookTicker\",\"u\":11479473209195,\"s\":\"BTCUSDT\",\"ps\":\"BTCUSDT\",\"b\":\"79543.90\",\"B\":\"6.540\",\"a\":\"79544.00\",\"A\":\"5.987\",\"T\":1788580709210,\"E\":1788580709210,\"st\":1}}"}
{"receive_ns":1788580709182272000,"stream":"btcusdt@bookTicker","event_type":"bookTicker","event_time_ms":1788580709212,"raw_json":"{\"stream\":\"btcusdt@bookTicker\",\"data\":{\"e\":\"bookTicker\",\"u\":11479473209315,\"s\":\"BTCUSDT\",\"ps\":\"BTCUSDT\",\"b\":\"79543.90\",\"B\":\"6.541\",\"a\":\"79544.00\",\"A\":\"5.987\",\"T\":1788580709211,\"E\":1788580709212,\"st\":1}}"}
{"receive_ns":1788580709215706000,"stream":"btcusdt@depth@100ms","event_type":"depthUpdate","event_time_ms":1788580709243,"raw_json":"{\"stream\":\"btcusdt@depth@100ms\",\"data\":{\"e\":\"depthUpdate\",\"E\":1788580709243,\"T\":1788580709241,\"s\":\"BTCUSDT\",\"ps\":\"BTCUSDT\",\"U\":11479473205248,\"u\":11479473211221,\"pu\":11479473204973,\"b\":[[\"1000.00\",\"25.354\"],[\"29043.90\",\"1.827\"],[\"29143.90\",\"0.203\"],[\"29443.90\",\"0.070\"],[\"71202.30\",\"0.000\"],[\"71589.50\",\"0.014\"],[\"75566.70\",\"0.018\"],[\"78748.50\",\"5.706\"],[\"78788.20\",\"1.328\"],[\"78907.50\",\"6.197\"],[\"79380.20\",\"0.008\"],[\"79456.40\",\"0.318\"],[\"79543.90\",\"6.541\"]],\"a\":[[\"79575.60\",\"0.453\"],[\"79620.30\",\"29.649\"],[\"79623.00\",\"0.009\"],[\"79705.70\",\"0.000\"],[\"79939.70\",\"0.136\"],[\"80299.70\",\"4.039\"],[\"80339.40\",\"3.990\"],[\"80339.50\",\"0.000\"],[\"80419.00\",\"2.545\"],[\"80697.40\",\"12.186\"],[\"80776.90\",\"6.089\"],[\"81784.20\",\"0.001\"]],\"st\":1}}"}
{"receive_ns":1788580709457306000,"stream":"btcusdt@depth@100ms","event_type":"depthUpdate","event_time_ms":1788580709345,"raw_json":"{\"stream\":\"btcusdt@depth@100ms\",\"data\":{\"e\":\"depthUpdate\",\"E\":1788580709345,\"T\":1788580709341,\"s\":\"BTCUSDT\",\"ps\":\"BTCUSDT\",\"U\":11479473211306,\"u\":11479473216791,\"pu\":11479473211221,\"b\":[[\"29043.90\",\"1.876\"],[\"29143.90\",\"0.091\"],[\"29443.90\",\"0.133\"],[\"71589.50\",\"0.014\"],[\"76362.10\",\"0.002\"],[\"79332.50\",\"5.139\"],[\"79380.30\",\"2.104\"],[\"79399.70\",\"1.886\"],[\"79400.00\",\"21.781\"],[\"79419.60\",\"0.556\"],[\"79453.10\",\"0.020\"],[\"79456.40\",\"0.318\"],[\"79520.20\",\"2.395\"],[\"79543.80\",\"0.087\"]],\"a\":[[\"79560.10\",\"0.004\"],[\"79579.80\",\"0.080\"],[\"79579.90\",\"0.130\"],[\"79590.60\",\"0.012\"],[\"79620.00\",\"20.582\"],[\"79666.30\",\"0.419\"],[\"79667.90\",\"1.886\"],[\"79668.20\",\"0.022\"],[\"79705.60\",\"1.865\"],[\"79753.40\",\"4.958\"],[\"79933.80\",\"0.018\"],[\"79936.40\",\"0.008\"],[\"79937.70\",\"0.041\"],[\"79939.70\",\"0.136\"],[\"80339.40\",\"3.990\"],[\"80498.50\",\"31.669\"],[\"80591.40\",\"2.107\"],[\"81174.80\",\"0.000\"]],\"st\":1}}"}
{"receive_ns":1788580709458440000,"stream":"btcusdt@bookTicker","event_type":"bookTicker","event_time_ms":1788580709386,"raw_json":"{\"stream\":\"btcusdt@bookTicker\",\"data\":{\"e\":\"bookTicker\",\"u\":11479473219037,\"s\":\"BTCUSDT\",\"ps\":\"BTCUSDT\",\"b\":\"79543.90\",\"B\":\"6.530\",\"a\":\"79544.00\",\"A\":\"5.987\",\"T\":1788580709386,\"E\":1788580709386,\"st\":1}}"}
{"receive_ns":1788580709458653000,"stream":"btcusdt@trade","event_type":"trade","event_time_ms":1788580709386,"raw_json":"{\"stream\":\"btcusdt@trade\",\"data\":{\"e\":\"trade\",\"E\":1788580709386,\"T\":1788580709386,\"s\":\"BTCUSDT\",\"t\":8054266661,\"p\":\"79543.90\",\"q\":\"0.011\",\"X\":\"MARKET\",\"m\":true,\"st\":1}}"}
{"receive_ns":1788580709458815000,"stream":"btcusdt@bookTicker","event_type":"bookTicker","event_time_ms":1788580709388,"raw_json":"{\"stream\":\"btcusdt@bookTicker\",\"data\":{\"e\":\"bookTicker\",\"u\":11479473219244,\"s\":\"BTCUSDT\",\"ps\":\"BTCUSDT\",\"b\":\"79543.90\",\"B\":\"6.529\",\"a\":\"79544.00\",\"A\":\"5.987\",\"T\":1788580709388,\"E\":1788580709388,\"st\":1}}"}
{"receive_ns":1788580709458972000,"stream":"btcusdt@bookTicker","event_type":"bookTicker","event_time_ms":1788580709388,"raw_json":"{\"stream\":\"btcusdt@bookTicker\",\"data\":{\"e\":\"bookTicker\",\"u\":11479473219283,\"s\":\"BTCUSDT\",\"ps\":\"BTCUSDT\",\"b\":\"79543.90\",\"B\":\"6.529\",\"a\":\"79544.00\",\"A\":\"5.964\",\"T\":1788580709388,\"E\":1788580709388,\"st\":1}}"}
{"receive_ns":1788580709460285000,"stream":"btcusdt@bookTicker","event_type":"bookTicker","event_time_ms":1788580709421,"raw_json":"{\"stream\":\"btcusdt@bookTicker\",\"data\":{\"e\":\"bookTicker\",\"u\":11479473220947,\"s\":\"BTCUSDT\",\"ps\":\"BTCUSDT\",\"b\":\"79543.90\",\"B\":\"6.529\",\"a\":\"79544.00\",\"A\":\"5.954\",\"T\":1788580709421,\"E\":1788580709421,\"st\":1}}"}
{"receive_ns":1788580709460447000,"stream":"btcusdt@trade","event_type":"trade","event_time_ms":1788580709421,"raw_json":"{\"stream\":\"btcusdt@trade\",\"data\":{\"e\":\"trade\",\"E\":1788580709421,\"T\":1788580709421,\"s\":\"BTCUSDT\",\"t\":8054266662,\"p\":\"79544.00\",\"q\":\"0.010\",\"X\":\"MARKET\",\"m\":false,\"st\":1}}"}
{"receive_ns":1788580709460777000,"stream":"btcusdt@bookTicker","event_type":"bookTicker","event_time_ms":1788580709439,"raw_json":"{\"stream\":\"btcusdt@bookTicker\",\"data\":{\"e\":\"bookTicker\",\"u\":11479473222110,\"s\":\"BTCUSDT\",\"ps\":\"BTCUSDT\",\"b\":\"79543.90\",\"B\":\"6.529\",\"a\":\"79544.00\",\"A\":\"5.943\",\"T\":1788580709439,\"E\":1788580709439,\"st\":1}}"}
{"receive_ns":1788580709461080000,"stream":"btcusdt@bookTicker","event_type":"bookTicker","event_time_ms":1788580709442,"raw_json":"{\"stream\":\"btcusdt@bookTicker\",\"data\":{\"e\":\"bookTicker\",\"u\":11479473222353,\"s\":\"BTCUSDT\",\"ps\":\"BTCUSDT\",\"b\":\"79543.90\",\"B\":\"6.529\",\"a\":\"79544.00\",\"A\":\"5.955\",\"T\":1788580709442,\"E\":1788580709442,\"st\":1}}"}
{"receive_ns":1788580709461283000,"stream":"btcusdt@bookTicker","event_type":"bookTicker","event_time_ms":1788580709445,"raw_json":"{\"stream\":\"btcusdt@bookTicker\",\"data\":{\"e\":\"bookTicker\",\"u\":11479473222610,\"s\":\"BTCUSDT\",\"ps\":\"BTCUSDT\",\"b\":\"79543.90\",\"B\":\"5.999\",\"a\":\"79544.00\",\"A\":\"5.955\",\"T\":1788580709445,\"E\":1788580709445,\"st\":1}}"}
{"receive_ns":1788580709461477000,"stream":"btcusdt@trade","event_type":"trade","event_time_ms":1788580709445,"raw_json":"{\"stream\":\"btcusdt@trade\",\"data\":{\"e\":\"trade\",\"E\":1788580709445,\"T\":1788580709445,\"s\":\"BTCUSDT\",\"t\":8054266663,\"p\":\"79543.90\",\"q\":\"0.530\",\"X\":\"MARKET\",\"m\":true,\"st\":1}}"}
{"receive_ns":1788580709461791000,"stream":"btcusdt@depth@100ms","event_type":"depthUpdate","event_time_ms":1788580709447,"raw_json":"{\"stream\":\"btcusdt@depth@100ms\",\"data\":{\"e\":\"depthUpdate\",\"E\":1788580709447,\"T\":1788580709446,\"s\":\"BTCUSDT\",\"ps\":\"BTCUSDT\",\"U\":11479473217058,\"u\":11479473222634,\"pu\":11479473216791,\"b\":[[\"1000.00\",\"25.354\"],[\"29043.90\",\"1.876\"],[\"29143.90\",\"0.000\"],[\"29443.90\",\"0.224\"],[\"71589.50\",\"0.014\"],[\"75566.80\",\"0.004\"],[\"76362.10\",\"0.000\"],[\"78333.20\",\"1.786\"],[\"78452.60\",\"3.820\"],[\"78681.40\",\"9.519\"],[\"78748.50\",\"5.706\"],[\"79146.10\",\"0.008\"],[\"79146.20\",\"3.664\"],[\"79424.50\",\"0.002\"],[\"79456.40\",\"0.318\"],[\"79472.30\",\"0.380\"],[\"79528.40\",\"0.203\"],[\"79543.90\",\"5.999\"]],\"a\":[[\"79544.00\",\"5.955\"],[\"79550.40\",\"0.029\"],[\"79558.60\",\"0.000\"],[\"79575.90\",\"0.712\"],[\"79615.60\",\"0.006\"],[\"79765.60\",\"19.654\"],[\"79939.70\",\"0.136\"],[\"79941.80\",\"0.000\"],[\"80272.60\",\"7.711\"],[\"80339.40\",\"3.990\"]],\"st\":1}}"}
{"receive_ns":1788580709461977000,"stream":"btcusdt@bookTicker","event_type":"bookTicker","event_time_ms":1788580709447,"raw_json":"{\"stream\":\"btcusdt@bookTicker\",\"data\":{\"e\":\"bookTicker\",\"u\":11479473222662,\"s\":\"BTCUSDT\",\"ps\":\"BTCUSDT\",\"b\":\"79543.90\",\"B\":\"5.999\",\"a\":\"79544.00\",\"A\":\"5.956\",\"T\":1788580709446,\"E\":1788580709447,\"st\":1}}"}
{"receive_ns":1788580709462100000,"stream":"btcusdt@bookTicker","event_type":"bookTicker","event_time_ms":1788580709447,"raw_json":"{\"stream\":\"btcusdt@bookTicker\",\"data\":{\"e\":\"bookTicker\",\"u\":11479473222670,\"s\":\"BTCUSDT\",\"ps\":\"BTCUSDT\",\"b\":\"79543.90\",\"B\":\"6.000\",\"a\":\"79544.00\",\"A\":\"5.956\",\"T\":1788580709446,\"E\":1788580709447,\"st\":1}}"}
{"receive_ns":1788580709462230000,"stream":"btcusdt@bookTicker","event_type":"bookTicker","event_time_ms":1788580709450,"raw_json":"{\"stream\":\"btcusdt@bookTicker\",\"data\":{\"e\":\"bookTicker\",\"u\":11479473223172,\"s\":\"BTCUSDT\",\"ps\":\"BTCUSDT\",\"b\":\"79543.90\",\"B\":\"4.723\",\"a\":\"79544.00\",\"A\":\"5.956\",\"T\":1788580709450,\"E\":1788580709450,\"st\":1}}"}
{"receive_ns":1788580709462444000,"stream":"btcusdt@bookTicker","event_type":"bookTicker","event_time_ms":1788580709451,"raw_json":"{\"stream\":\"btcusdt@bookTicker\",\"data\":{\"e\":\"bookTicker\",\"u\":11479473223210,\"s\":\"BTCUSDT\",\"ps\":\"BTCUSDT\",\"b\":\"79543.90\",\"B\":\"4.722\",\"a\":\"79544.00\",\"A\":\"5.956\",\"T\":1788580709451,\"E\":1788580709451,\"st\":1}}"}
{"receive_ns":1788580709462589000,"stream":"btcusdt@bookTicker","event_type":"bookTicker","event_time_ms":1788580709451,"raw_json":"{\"stream\":\"btcusdt@bookTicker\",\"data\":{\"e\":\"bookTicker\",\"u\":11479473223216,\"s\":\"BTCUSDT\",\"ps\":\"BTCUSDT\",\"b\":\"79543.90\",\"B\":\"4.722\",\"a\":\"79544.00\",\"A\":\"5.955\",\"T\":1788580709451,\"E\":1788580709451,\"st\":1}}"}
{"receive_ns":1788580709462729000,"stream":"btcusdt@bookTicker","event_type":"bookTicker","event_time_ms":1788580709497,"raw_json":"{\"stream\":\"btcusdt@bookTicker\",\"data\":{\"e\":\"bookTicker\",\"u\":11479473225790,\"s\":\"BTCUSDT\",\"ps\":\"BTCUSDT\",\"b\":\"79543.90\",\"B\":\"4.722\",\"a\":\"79544.00\",\"A\":\"5.956\",\"T\":1788580709496,\"E\":1788580709497,\"st\":1}}"}
{"receive_ns":1788580709462906000,"stream":"btcusdt@bookTicker","event_type":"bookTicker","event_time_ms":1788580709498,"raw_json":"{\"stream\":\"btcusdt@bookTicker\",\"data\":{\"e\":\"bookTicker\",\"u\":11479473225930,\"s\":\"BTCUSDT\",\"ps\":\"BTCUSDT\",\"b\":\"79543.90\",\"B\":\"4.584\",\"a\":\"79544.00\",\"A\":\"5.956\",\"T\":1788580709498,\"E\":1788580709498,\"st\":1}}"}
{"receive_ns":1788580709463049000,"stream":"btcusdt@bookTicker","event_type":"bookTicker","event_time_ms":1788580709501,"raw_json":"{\"stream\":\"btcusdt@bookTicker\",\"data\":{\"e\":\"bookTicker\",\"u\":11479473226213,\"s\":\"BTCUSDT\",\"ps\":\"BTCUSDT\",\"b\":\"79543.90\",\"B\":\"4.721\",\"a\":\"79544.00\",\"A\":\"5.956\",\"T\":1788580709501,\"E\":1788580709501,\"st\":1}}"}
{"receive_ns":1788580709463192000,"stream":"btcusdt@bookTicker","event_type":"bookTicker","event_time_ms":1788580709510,"raw_json":"{\"stream\":\"btcusdt@bookTicker\",\"data\":{\"e\":\"bookTicker\",\"u\":11479473227004,\"s\":\"BTCUSDT\",\"ps\":\"BTCUSDT\",\"b\":\"79543.90\",\"B\":\"6.341\",\"a\":\"79544.00\",\"A\":\"5.956\",\"T\":1788580709509,\"E\":1788580709510,\"st\":1}}"}
{"receive_ns":1788580709463363000,"stream":"btcusdt@bookTicker","event_type":"bookTicker","event_time_ms":1788580709511,"raw_json":"{\"stream\":\"btcusdt@bookTicker\",\"data\":{\"e\":\"bookTicker\",\"u\":11479473227238,\"s\":\"BTCUSDT\",\"ps\":\"BTCUSDT\",\"b\":\"79543.90\",\"B\":\"6.340\",\"a\":\"79544.00\",\"A\":\"5.956\",\"T\":1788580709511,\"E\":1788580709511,\"st\":1}}"}
{"receive_ns":1788580709521557000,"stream":"btcusdt@bookTicker","event_type":"bookTicker","event_time_ms":1788580709540,"raw_json":"{\"stream\":\"btcusdt@bookTicker\",\"data\":{\"e\":\"bookTicker\",\"u\":11479473229030,\"s\":\"BTCUSDT\",\"ps\":\"BTCUSDT\",\"b\":\"79543.90\",\"B\":\"6.340\",\"a\":\"79544.00\",\"A\":\"5.954\",\"T\":1788580709540,\"E\":1788580709540,\"st\":1}}"}
{"receive_ns":1788580709522104000,"stream":"btcusdt@depth@100ms","event_type":"depthUpdate","event_time_ms":1788580709549,"raw_json":"{\"stream\":\"btcusdt@depth@100ms\",\"data\":{\"e\":\"depthUpdate\",\"E\":1788580709549,\"T\":1788580709547,\"s\":\"BTCUSDT\",\"ps\":\"BTCUSDT\",\"U\":11479473222662,\"u\":11479473229528,\"pu\":11479473222634,\"b\":[[\"1000.00\",\"25.354\"],[\"29043.90\",\"1.701\"],[\"29443.90\",\"0.399\"],[\"71589.50\",\"0.014\"],[\"71623.00\",\"0.003\"],[\"76362.10\",\"0.002\"],[\"78743.20\",\"1.839\"],[\"78748.50\",\"5.706\"],[\"78942.10\",\"1.265\"],[\"79146.10\",\"0.009\"],[\"79453.10\",\"0.000\"],[\"79456.40\",\"0.010\"],[\"79477.10\",\"3.462\"],[\"79477.20\",\"22.962\"],[\"79485.00\",\"0.330\"],[\"79500.10\",\"0.002\"],[\"79500.90\",\"2.002\"],[\"79505.90\",\"0.166\"],[\"79506.00\",\"0.003\"],[\"79507.10\",\"3.840\"],[\"79509.30\",\"0.000\"],[\"79524.80\",\"1.010\"],[\"79525.20\",\"0.000\"],[\"79525.40\",\"0.046\"],[\"79526.00\",\"0.108\"],[\"79526.40\",\"0.003\"],[\"79528.40\",\"0.177\"],[\"79529.30\",\"0.346\"],[\"79529.50\",\"0.003\"],[\"79529.60\",\"0.002\"],[\"79533.50\",\"0.070\"],[\"79533.60\",\"0.011\"],[\"79533.70\",\"0.077\"],[\"79533.80\",\"0.003\"],[\"79533.90\",\"1.261\"],[\"79534.70\",\"0.000\"],[\"79536.50\",\"0.255\"],[\"79536.80\",\"0.000\"],[\"79538.20\",\"0.007\"],[\"79538.40\",\"0.056\"],[\"79540.00\",\"0.003\"],[\"79540.10\",\"0.003\"],[\"79540.50\",\"0.002\"],[\"79540.60\",\"0.252\"],[\"79540.70\",\"0.001\"],[\"79542.30\",\"0.061\"],[\"79543.70\",\"0.003\"],[\"79543.80\",\"0.086\"],[\"79543.90\",\"6.340\"]],\"a\":[[\"79544.00\",\"5.954\"],[\"79546.30\",\"0.000\"],[\"79550.40\",\"0.057\"],[\"79550.60\",\"0.004\"],[\"79550.70\",\"0.376\"],[\"79552.00\",\"0.568\"],[\"79556.00\",\"0.425\"],[\"79557.40\",\"0.083\"],[\"79557.80\",\"0.001\"],[\"79564.40\",\"0.091\"],[\"79564.90\",\"0.814\"],[\"79565.60\",\"0.760\"],[\"79569.00\",\"2.076\"],[\"79569.10\",\"0.253\"],[\"79573.70\",\"0.194\"],[\"79576.20\",\"2.096\"],[\"79576.50\",\"2.322\"],[\"79583.80\",\"0.757\"],[\"79591.80\",\"0.260\"],[\"79599.70\",\"0.052\"],[\"79620.00\",\"20.581\"],[\"79620.30\",\"29.650\"],[\"79626.80\",\"0.024\"],[\"79933.80\",\"0.000\"],[\"79936.40\",\"0.001\"],[\"79937.70\",\"0.004\"],[\"79939.70\",\"0.005\"],[\"79941.80\",\"0.001\"],[\"80135.20\",\"0.623\"],[\"80339.40\",\"3.990\"],[\"81134.90\",\"2.031\"]],\"st\":1}}"}
{"receive_ns":1788580709522320000,"stream":"btcusdt@bookTicker","event_type":"bookTicker","event_time_ms":1788580709560,"raw_json":"{\"stream\":\"btcusdt@bookTicker\",\"data\":{\"e\":\"bookTicker\",\"u\":11479473230129,\"s\":\"BTCUSDT\",\"ps\":\"BTCUSDT\",\"b\":\"79543.90\",\"B\":\"6.334\",\"a\":\"79544.00\",\"A\":\"5.954\",\"T\":1788580709559,\"E\":1788580709560,\"st\":1}}"}
{"receive_ns":1788580709522458000,"stream":"btcusdt@trade","event_type":"trade","event_time_ms":1788580709560,"raw_json":"{\"stream\":\"btcusdt@trade\",\"data\":{\"e\":\"trade\",\"E\":1788580709560,\"T\":1788580709559,\"s\":\"BTCUSDT\",\"t\":8054266664,\"p\":\"79543.90\",\"q\":\"0.006\",\"X\":\"MARKET\",\"m\":true,\"st\":1}}"}
{"receive_ns":1788580709526892000,"stream":"btcusdt@bookTicker","event_type":"bookTicker","event_time_ms":1788580709582,"raw_json":"{\"stream\":\"btcusdt@bookTicker\",\"data\":{\"e\":\"bookTicker\",\"u\":11479473231465,\"s\":\"BTCUSDT\",\"ps\":\"BTCUSDT\",\"b\":\"79543.90\",\"B\":\"6.335\",\"a\":\"79544.00\",\"A\":\"5.954\",\"T\":1788580709582,\"E\":1788580709582,\"st\":1}}"}
{"receive_ns":1788580709661759000,"stream":"btcusdt@depth@100ms","event_type":"depthUpdate","event_time_ms":1788580709651,"raw_json":"{\"stream\":\"btcusdt@depth@100ms\",\"data\":{\"e\":\"depthUpdate\",\"E\":1788580709651,\"T\":1788580709650,\"s\":\"BTCUSDT\",\"ps\":\"BTCUSDT\",\"U\":11479473229686,\"u\":11479473236194,\"pu\":11479473229528,\"b\":[[\"29043.90\",\"1.519\"],[\"29443.90\",\"0.581\"],[\"63635.00\",\"0.000\"],[\"71589.50\",\"0.014\"],[\"71623.00\",\"0.000\"],[\"76362.10\",\"0.000\"],[\"78595.90\",\"0.003\"],[\"78598.20\",\"0.000\"],[\"78612.60\",\"0.000\"],[\"78619.80\",\"0.002\"],[\"78748.50\",\"5.706\"],[\"78980.90\",\"0.285\"],[\"79453.10\",\"0.020\"],[\"79456.40\",\"0.318\"],[\"79529.30\",\"0.032\"],[\"79529.40\",\"1.801\"],[\"79529.50\",\"0.007\"],[\"79533.50\",\"0.001\"],[\"79533.60\",\"0.003\"],[\"79533.90\",\"0.000\"],[\"79543.90\",\"6.335\"]],\"a\":[[\"79617.60\",\"0.006\"],[\"79936.40\",\"0.008\"],[\"79937.70\",\"0.041\"],[\"79939.70\",\"0.100\"],[\"79941.70\",\"2.547\"],[\"80175.00\",\"3.373\"],[\"80339.40\",\"3.992\"],[\"80498.50\",\"32.289\"]],\"st\":1}}"}
{"receive_ns":1788580709664033000,"stream":"btcusdt@bookTicker","event_type":"bookTicker","event_time_ms":1788580709708,"raw_json":"{\"stream\":\"btcusdt@bookTicker\",\"data\":{\"e\":\"bookTicker\",\"u\":11479473241534,\"s\":\"BTCUSDT\",\"ps\":\"BTCUSDT\",\"b\":\"79543.90\",\"B\":\"6.334\",\"a\":\"79544.00\",\"A\":\"5.954\",\"T\":1788580709708,\"E\":1788580709708,\"st\":1}}"}
{"receive_ns":1788580709664214000,"stream":"btcusdt@bookTicker","event_type":"bookTicker","event_time_ms":1788580709710,"raw_json":"{\"stream\":\"btcusdt@bookTicker\",\"data\":{\"e\":\"bookTicker\",\"u\":11479473241710,\"s\":\"BTCUSDT\",\"ps\":\"BTCUSDT\",\"b\":\"79543.90\",\"B\":\"6.335\",\"a\":\"79544.00\",\"A\":\"5.954\",\"T\":1788580709709,\"E\":1788580709710,\"st\":1}}"}
{"receive_ns":1788580709704120000,"stream":"btcusdt@depth@100ms","event_type":"depthUpdate","event_time_ms":1788580709753,"raw_json":"{\"stream\":\"btcusdt@depth@100ms\",\"data\":{\"e\":\"depthUpdate\",\"E\":1788580709753,\"T\":1788580709750,\"s\":\"BTCUSDT\",\"ps\":\"BTCUSDT\",\"U\":11479473236239,\"u\":11479473243474,\"pu\":11479473236194,\"b\":[[\"1000.00\",\"25.354\"],[\"29043.90\",\"1.344\"],[\"29443.90\",\"0.756\"],[\"71589.50\",\"0.014\"],[\"78311.00\",\"7.382\"],[\"78748.50\",\"6.974\"],[\"78947.30\",\"2.532\"],[\"79146.20\",\"3.664\"],[\"79419.60\",\"0.132\"],[\"79448.40\",\"0.018\"],[\"79456.40\",\"0.318\"],[\"79472.30\",\"0.378\"],[\"79488.20\",\"0.128\"],[\"79538.20\",\"0.003\"],[\"79538.50\",\"0.072\"],[\"79543.90\",\"6.335\"]],\"a\":[[\"79569.00\",\"0.076\"],[\"79599.70\",\"0.050\"],[\"79615.60\",\"0.004\"],[\"79617.60\",\"0.006\"],[\"79620.20\",\"29.410\"],[\"79620.30\",\"0.006\"],[\"79639.50\",\"0.000\"],[\"79666.30\",\"0.000\"],[\"79939.70\",\"0.100\"],[\"80180.40\",\"3.980\"],[\"80339.40\",\"3.990\"],[\"81771.20\",\"0.243\"]],\"st\":1}}"}
{"receive_ns":1788580709704583000,"stream":"btcusdt@bookTicker","event_type":"bookTicker","event_time_ms":1788580709760,"raw_json":"{\"stream\":\"btcusdt@bookTicker\",\"data\":{\"e\":\"bookTicker\",\"u\":11479473243875,\"s\":\"BTCUSDT\",\"ps\":\"BTCUSDT\",\"b\":\"79543.90\",\"B\":\"6.335\",\"a\":\"79544.00\",\"A\":\"5.977\",\"T\":1788580709760,\"E\":1788580709760,\"st\":1}}"}
{"receive_ns":1788580709704918000,"stream":"btcusdt@bookTicker","event_type":"bookTicker","event_time_ms":1788580709762,"raw_json":"{\"stream\":\"btcusdt@bookTicker\",\"data\":{\"e\":\"bookTicker\",\"u\":11479473243962,\"s\":\"BTCUSDT\",\"ps\":\"BTCUSDT\",\"b\":\"79543.90\",\"B\":\"6.336\",\"a\":\"79544.00\",\"A\":\"5.977\",\"T\":1788580709761,\"E\":1788580709762,\"st\":1}}"}
{"receive_ns":1788580709835684000,"stream":"btcusdt@depth@100ms","event_type":"depthUpdate","event_time_ms":1788580709855,"raw_json":"{\"stream\":\"btcusdt@depth@100ms\",\"data\":{\"e\":\"depthUpdate\",\"E\":1788580709855,\"T\":1788580709854,\"s\":\"BTCUSDT\",\"ps\":\"BTCUSDT\",\"U\":11479473243638,\"u\":11479473250149,\"pu\":11479473243474,\"b\":[[\"1000.00\",\"25.354\"],[\"29043.90\",\"1.162\"],[\"29443.90\",\"0.938\"],[\"63635.00\",\"0.000\"],[\"71589.50\",\"0.014\"],[\"76362.10\",\"0.002\"],[\"78721.10\",\"3.146\"],[\"78748.50\",\"6.974\"],[\"79380.30\",\"2.095\"],[\"79419.70\",\"1.933\"],[\"79453.10\",\"0.020\"],[\"79456.40\",\"0.318\"],[\"79531.10\",\"0.007\"],[\"79531.80\",\"0.252\"],[\"79538.50\",\"0.068\"],[\"79538.90\",\"1.004\"],[\"79543.90\",\"6.336\"]],\"a\":[[\"79544.00\",\"5.977\"],[\"79550.60\",\"0.000\"],[\"79550.70\",\"0.000\"],[\"79551.30\",\"0.381\"],[\"79553.90\",\"0.002\"],[\"79554.20\",\"0.258\"],[\"79568.20\",\"0.001\"],[\"79568.50\",\"0.453\"],[\"79572.60\",\"2.732\"],[\"79572.80\",\"10.001\"],[\"79572.90\",\"0.002\"],[\"79617.60\",\"0.001\"],[\"79666.30\",\"0.419\"],[\"79705.60\",\"1.881\"],[\"79933.80\",\"0.037\"],[\"79936.40\",\"0.008\"],[\"79937.70\",\"0.022\"],[\"79939.70\",\"0.059\"],[\"79941.70\",\"2.575\"],[\"80272.70\",\"1.750\"],[\"80339.40\",\"3.990\"],[\"80498.50\",\"33.530\"],[\"80880.30\",\"0.986\"],[\"81134.80\",\"0.009\"]],\"st\":1}}"}
{"receive_ns":1788580709899878000,"stream":"btcusdt@depth@100ms","event_type":"depthUpdate","event_time_ms":1788580709957,"raw_json":"{\"stream\":\"btcusdt@depth@100ms\",\"data\":{\"e\":\"depthUpdate\",\"E\":1788580709957,\"T\":1788580709954,\"s\":\"BTCUSDT\",\"ps\":\"BTCUSDT\",\"U\":11479473250217,\"u\":11479473254975,\"pu\":11479473250149,\"b\":[[\"29043.90\",\"0.987\"],[\"29443.90\",\"1.113\"],[\"71589.50\",\"0.014\"],[\"76362.10\",\"0.000\"],[\"78748.50\",\"6.974\"],[\"79456.40\",\"0.318\"]],\"a\":[[\"79939.70\",\"0.059\"],[\"80120.90\",\"0.000\"],[\"80339.40\",\"3.990\"],[\"80662.30\",\"0.009\"]],\"st\":1}}"}
{"receive_ns":1788580710009136000,"stream":"btcusdt@bookTicker","event_type":"bookTicker","event_time_ms":1788580710034,"raw_json":"{\"stream\":\"btcusdt@bookTicker\",\"data\":{\"e\":\"bookTicker\",\"u\":11479473259263,\"s\":\"BTCUSDT\",\"ps\":\"BTCUSDT\",\"b\":\"79543.90\",\"B\":\"6.336\",\"a\":\"79544.00\",\"A\":\"5.980\",\"T\":1788580710034,\"E\":1788580710034,\"st\":1}}"}
{"receive_ns":1788580710010969000,"stream":"btcusdt@depth@100ms","event_type":"depthUpdate","event_time_ms":1788580710059,"raw_json":"{\"stream\":\"btcusdt@depth@100ms\",\"data\":{\"e\":\"depthUpdate\",\"E\":1788580710059,\"T\":1788580710057,\"s\":\"BTCUSDT\",\"ps\":\"BTCUSDT\",\"U\":11479473255118,\"u\":11479473261318,\"pu\":11479473254975,\"b\":[[\"1000.00\",\"25.354\"],[\"29043.90\",\"0.805\"],[\"29443.90\",\"1.295\"],[\"63635.00\",\"0.000\"],[\"71589.50\",\"0.014\"],[\"76362.10\",\"0.002\"],[\"77953.10\",\"0.015\"],[\"78385.30\",\"4.052\"],[\"78451.50\",\"2.040\"],[\"78509.80\",\"3.324\"],[\"78748.50\",\"6.974\"],[\"78902.30\",\"1.518\"],[\"78942.10\",\"0.633\"],[\"79146.20\",\"3.664\"],[\"79453.10\",\"0.000\"],[\"79456.40\",\"0.010\"],[\"79458.30\",\"0.059\"],[\"79469.00\",\"0.000\"],[\"79469.40\",\"0.065\"],[\"79493.60\",\"0.001\"],[\"79529.60\",\"0.002\"],[\"79536.80\",\"0.025\"],[\"79537.60\",\"0.467\"]],\"a\":[[\"79544.00\",\"5.980\"],[\"79550.70\",\"0.380\"],[\"79551.30\",\"0.001\"],[\"79583.80\",\"0.066\"],[\"79596.30\",\"3.557\"],[\"79596.80\",\"0.052\"],[\"79605.90\",\"0.315\"],[\"79642.60\",\"0.024\"],[\"79933.80\",\"0.000\"],[\"79936.40\",\"0.001\"],[\"79937.70\",\"0.004\"],[\"79939.70\",\"0.005\"],[\"79941.70\",\"2.498\"],[\"80135.20\",\"0.000\"],[\"80259.90\",\"2.568\"],[\"80273.20\",\"0.000\"],[\"80334.10\",\"2.997\"],[\"80339.40\",\"5.233\"],[\"80487.30\",\"0.433\"],[\"83521.20\",\"0.016\"]],\"st\":1}}"}
{"receive_ns":1788580710134390000,"stream":"btcusdt@depth@100ms","event_type":"depthUpdate","event_time_ms":1788580710161,"raw_json":"{\"stream\":\"btcusdt@depth@100ms\",\"data\":{\"e\":\"depthUpdate\",\"E\":1788580710161,\"T\":1788580710159,\"s\":\"BTCUSDT\",\"ps\":\"BTCUSDT\",\"U\":11479473261469,\"u\":11479473266780,\"pu\":11479473261318,\"b\":[[\"1000.00\",\"25.354\"],[\"29043.90\",\"0.630\"],[\"29443.90\",\"1.470\"],[\"63635.00\",\"0.000\"],[\"63635.10\",\"0.000\"],[\"71589.50\",\"0.014\"],[\"76362.10\",\"0.000\"],[\"78562.00\",\"7.775\"],[\"78748.50\",\"6.974\"],[\"78833.70\",\"0.000\"],[\"78840.40\",\"9.562\"],[\"79140.90\",\"0.947\"],[\"79453.10\",\"0.020\"],[\"79456.40\",\"0.308\"],[\"79458.30\",\"0.057\"],[\"79501.10\",\"0.002\"],[\"79528.10\",\"0.141\"]],\"a\":[[\"79549.00\",\"0.033\"],[\"79550.40\",\"0.057\"],[\"79550.70\",\"0.380\"],[\"79551.30\",\"0.001\"],[\"79557.30\",\"0.076\"],[\"79557.40\",\"0.007\"],[\"79558.70\",\"0.077\"],[\"79571.00\",\"0.003\"],[\"79605.50\",\"0.004\"],[\"79624.80\",\"1.753\"],[\"79642.60\",\"0.022\"],[\"79936.40\",\"0.008\"],[\"79937.70\",\"0.059\"],[\"79939.70\",\"0.131\"],[\"80339.40\",\"5.233\"],[\"81134.80\",\"0.006\"]],\"st\":1}}"}
{"receive_ns":1788580710134739000,"stream":"btcusdt@bookTicker","event_type":"bookTicker","event_time_ms":1788580710163,"raw_json":"{\"stream\":\"btcusdt@bookTicker\",\"data\":{\"e\":\"bookTicker\",\"u\":11479473266999,\"s\":\"BTCUSDT\",\"ps\":\"BTCUSDT\",\"b\":\"79543.90\",\"B\":\"6.335\",\"a\":\"79544.00\",\"A\":\"5.980\",\"T\":1788580710163,\"E\":1788580710163,\"st\":1}}"}
{"receive_ns":1788580710134929000,"stream":"btcusdt@bookTicker","event_type":"bookTicker","event_time_ms":1788580710165,"raw_json":"{\"stream\":\"btcusdt@bookTicker\",\"data\":{\"e\":\"bookTicker\",\"u\":11479473267126,\"s\":\"BTCUSDT\",\"ps\":\"BTCUSDT\",\"b\":\"79543.90\",\"B\":\"6.336\",\"a\":\"79544.00\",\"A\":\"5.980\",\"T\":1788580710165,\"E\":1788580710165,\"st\":1}}"}
{"receive_ns":1788580710202749000,"stream":"btcusdt@bookTicker","event_type":"bookTicker","event_time_ms":1788580710258,"raw_json":"{\"stream\":\"btcusdt@bookTicker\",\"data\":{\"e\":\"bookTicker\",\"u\":11479473273321,\"s\":\"BTCUSDT\",\"ps\":\"BTCUSDT\",\"b\":\"79543.90\",\"B\":\"6.338\",\"a\":\"79544.00\",\"A\":\"5.980\",\"T\":1788580710258,\"E\":1788580710258,\"st\":1}}"}
{"receive_ns":1788580710206601000,"stream":"btcusdt@depth@100ms","event_type":"depthUpdate","event_time_ms":1788580710263,"raw_json":"{\"stream\":\"btcusdt@depth@100ms\",\"data\":{\"e\":\"depthUpdate\",\"E\":1788580710263,\"T\":1788580710262,\"s\":\"BTCUSDT\",\"ps\":\"BTCUSDT\",\"U\":11479473266942,\"u\":11479473273483,\"pu\":11479473266780,\"b\":[[\"29043.90\",\"0.448\"],[\"29443.90\",\"1.652\"],[\"71589.50\",\"0.014\"],[\"75566.70\",\"0.020\"],[\"78311.00\",\"8.275\"],[\"78562.00\",\"7.490\"],[\"78748.50\",\"6.974\"],[\"79358.90\",\"3.144\"],[\"79360.10\",\"0.000\"],[\"79364.00\",\"0.832\"],[\"79380.30\",\"0.022\"],[\"79419.70\",\"1.509\"],[\"79456.40\",\"0.148\"],[\"79458.00\",\"0.039\"],[\"79458.30\",\"0.019\"],[\"79538.60\",\"0.444\"],[\"79538.90\",\"1.000\"],[\"79543.90\",\"6.338\"]],\"a\":[[\"79575.60\",\"0.447\"],[\"79633.10\",\"0.060\"],[\"79633.40\",\"0.001\"],[\"79666.30\",\"0.000\"],[\"79687.00\",\"3.143\"],[\"79687.40\",\"0.000\"],[\"79705.60\",\"0.002\"],[\"79937.70\",\"0.022\"],[\"79939.70\",\"0.068\"],[\"80339.40\",\"5.233\"],[\"80474.70\",\"0.446\"],[\"80493.20\",\"8.687\"],[\"80551.10\",\"5.524\"],[\"80649.70\",\"2.920\"]],\"st\":1}}"}
{"receive_ns":1788580710217464000,"stream":"btcusdt@bookTicker","event_type":"bookTicker","event_time_ms":1788580710274,"raw_json":"{\"stream\":\"btcusdt@bookTicker\",\"data\":{\"e\":\"bookTicker\",\"u\":11479473274143,\"s\":\"BTCUSDT\",\"ps\":\"BTCUSDT\",\"b\":\"79543.90\",\"B\":\"6.338\",\"a\":\"79544.00\",\"A\":\"5.941\",\"T\":1788580710273,\"E\":1788580710274,\"st\":1}}"}
{"receive_ns":1788580710254031000,"stream":"btcusdt@bookTicker","event_type":"bookTicker","event_time_ms":1788580710276,"raw_json":"{\"stream\":\"btcusdt@bookTicker\",\"data\":{\"e\":\"bookTicker\",\"u\":11479473274339,\"s\":\"BTCUSDT\",\"ps\":\"BTCUSDT\",\"b\":\"79543.90\",\"B\":\"6.338\",\"a\":\"79544.00\",\"A\":\"5.981\",\"T\":1788580710276,\"E\":1788580710276,\"st\":1}}"}
{"receive_ns":1788580710255764000,"stream":"btcusdt@bookTicker","event_type":"bookTicker","event_time_ms":1788580710297,"raw_json":"{\"stream\":\"btcusdt@bookTicker\",\"data\":{\"e\":\"bookTicker\",\"u\":11479473275455,\"s\":\"BTCUSDT\",\"ps\":\"BTCUSDT\",\"b\":\"79543.90\",\"B\":\"6.338\",\"a\":\"79544.00\",\"A\":\"5.391\",\"T\":1788580710297,\"E\":1788580710297,\"st\":1}}"}
{"receive_ns":1788580710270951000,"stream":"btcusdt@bookTicker","event_type":"bookTicker","event_time_ms":1788580710328,"raw_json":"{\"stream\":\"btcusdt@bookTicker\",\"data\":{\"e\":\"bookTicker\",\"u\":11479473277488,\"s\":\"BTCUSDT\",\"ps\":\"BTCUSDT\",\"b\":\"79543.90\",\"B\":\"6.338\",\"a\":\"79544.00\",\"A\":\"5.347\",\"T\":1788580710327,\"E\":1788580710328,\"st\":1}}"}
{"receive_ns":1788580710274688000,"stream":"btcusdt@bookTicker","event_type":"bookTicker","event_time_ms":1788580710330,"raw_json":"{\"stream\":\"btcusdt@bookTicker\",\"data\":{\"e\":\"bookTicker\",\"u\":11479473277656,\"s\":\"BTCUSDT\",\"ps\":\"BTCUSDT\",\"b\":\"79543.90\",\"B\":\"6.338\",\"a\":\"79544.00\",\"A\":\"5.393\",\"T\":1788580710330,\"E\":1788580710330,\"st\":1}}"}
{"receive_ns":1788580710316749000,"stream":"btcusdt@depth@100ms","event_type":"depthUpdate","event_time_ms":1788580710365,"raw_json":"{\"stream\":\"btcusdt@depth@100ms\",\"data\":{\"e\":\"depthUpdate\",\"E\":1788580710365,\"T\":1788580710364,\"s\":\"BTCUSDT\",\"ps\":\"BTCUSDT\",\"U\":11479473273562,\"u\":11479473279912,\"pu\":11479473273483,\"b\":[[\"1000.00\",\"25.354\"],[\"29043.90\",\"0.301\"],[\"29343.90\",\"0.028\"],[\"29443.90\",\"1.771\"],[\"71589.50\",\"0.014\"],[\"76362.10\",\"0.002\"],[\"77953.10\",\"0.018\"],[\"78390.50\",\"9.047\"],[\"78470.10\",\"3.244\"],[\"78748.50\",\"6.974\"],[\"79146.20\",\"3.790\"],[\"79380.30\",\"2.095\"],[\"79419.70\",\"1.933\"],[\"79453.10\",\"0.020\"],[\"79456.40\",\"0.318\"],[\"79520.20\",\"2.395\"]],\"a\":[[\"79544.00\",\"5.393\"],[\"79550.70\",\"0.000\"],[\"79551.30\",\"0.377\"],[\"79557.30\",\"0.000\"],[\"79560.10\",\"0.004\"],[\"79617.60\",\"0.006\"],[\"79666.30\",\"0.419\"],[\"79705.60\",\"1.881\"],[\"79936.40\",\"0.008\"],[\"79937.70\",\"0.059\"],[\"79939.70\",\"0.131\"],[\"80283.40\",\"0.000\"],[\"80339.40\",\"5.233\"],[\"80601.00\",\"0.000\"],[\"80975.80\",\"0.494\"]],\"st\":1}}"}
{"receive_ns":1788580710389726000,"stream":"btcusdt@bookTicker","event_type":"bookTicker","event_time_ms":1788580710378,"raw_json":"{\"stream\":\"btcusdt@bookTicker\",\"data\":{\"e\":\"bookTicker\",\"u\":11479473280601,\"s\":\"BTCUSDT\",\"ps\":\"BTCUSDT\",\"b\":\"79543.90\",\"B\":\"6.338\",\"a\":\"79544.00\",\"A\":\"5.392\",\"T\":1788580710378,\"E\":1788580710378,\"st\":1}}"}
{"receive_ns":1788580710389883000,"stream":"btcusdt@trade","event_type":"trade","event_time_ms":1788580710378,"raw_json":"{\"stream\":\"btcusdt@trade\",\"data\":{\"e\":\"trade\",\"E\":1788580710378,\"T\":1788580710378,\"s\":\"BTCUSDT\",\"t\":8054266665,\"p\":\"79544.00\",\"q\":\"0.001\",\"X\":\"MARKET\",\"m\":false,\"st\":1}}"}
{"receive_ns":1788580710390026000,"stream":"btcusdt@bookTicker","event_type":"bookTicker","event_time_ms":1788580710396,"raw_json":"{\"stream\":\"btcusdt@bookTicker\",\"data\":{\"e\":\"bookTicker\",\"u\":11479473282116,\"s\":\"BTCUSDT\",\"ps\":\"BTCUSDT\",\"b\":\"79543.90\",\"B\":\"6.201\",\"a\":\"79544.00\",\"A\":\"5.392\",\"T\":1788580710396,\"E\":1788580710396,\"st\":1}}"}
{"receive_ns":1788580710390183000,"stream":"btcusdt@bookTicker","event_type":"bookTicker","event_time_ms":1788580710401,"raw_json":"{\"stream\":\"btcusdt@bookTicker\",\"data\":{\"e\":\"bookTicker\",\"u\":11479473282503,\"s\":\"BTCUSDT\",\"ps\":\"BTCUSDT\",\"b\":\"79543.90\",\"B\":\"6.344\",\"a\":\"79544.00\",\"A\":\"5.392\",\"T\":1788580710401,\"E\":1788580710401,\"st\":1}}"}
{"receive_ns":1788580710436750000,"stream":"btcusdt@depth@100ms","event_type":"depthUpdate","event_time_ms":1788580710467,"raw_json":"{\"stream\":\"btcusdt@depth@100ms\",\"data\":{\"e\":\"depthUpdate\",\"E\":1788580710467,\"T\":1788580710466,\"s\":\"BTCUSDT\",\"ps\":\"BTCUSDT\",\"U\":11479473279967,\"u\":11479473286410,\"pu\":11479473279912,\"b\":[[\"1000.00\",\"25.354\"],[\"29043.90\",\"0.175\"],[\"29343.90\",\"0.084\"],[\"29443.90\",\"1.841\"],[\"71589.50\",\"0.014\"],[\"76362.10\",\"0.000\"],[\"78748.50\",\"6.976\"],[\"79426.90\",\"0.024\"],[\"79427.00\",\"0.031\"],[\"79456.40\",\"0.318\"],[\"79474.60\",\"23.013\"],[\"79476.00\",\"4.388\"],[\"79477.20\",\"0.028\"],[\"79478.80\",\"1.282\"],[\"79500.10\",\"0.001\"],[\"79500.90\",\"0.002\"],[\"79505.50\",\"0.091\"],[\"79505.60\",\"10.000\"],[\"79528.80\",\"0.109\"],[\"79541.30\",\"0.001\"],[\"79543.70\",\"0.002\"],[\"79543.90\",\"6.344\"]],\"a\":[[\"79544.00\",\"5.392\"],[\"79550.40\",\"0.029\"],[\"79550.70\",\"0.318\"],[\"79551.30\",\"0.063\"],[\"79558.70\",\"0.001\"],[\"79559.70\",\"0.687\"],[\"79939.70\",\"0.131\"],[\"80339.40\",\"5.233\"],[\"80498.50\",\"33.902\"]],\"st\":1}}"}
{"receive_ns":1788580710511784000,"stream":"btcusdt@depth@100ms","event_type":"depthUpdate","event_time_ms":1788580710569,"raw_json":"{\"stream\":\"btcusdt@depth@100ms\",\"data\":{\"e\":\"depthUpdate\",\"E\":1788580710569,\"T\":1788580710566,\"s\":\"BTCUSDT\",\"ps\":\"BTCUSDT\",\"U\":11479473286458,\"u\":11479473292006,\"pu\":11479473286410,\"b\":[[\"29043.90\",\"0.063\"],[\"29343.90\",\"0.147\"],[\"29443.90\",\"1.890\"],[\"63635.00\",\"0.000\"],[\"71589.50\",\"0.014\"],[\"76362.10\",\"0.002\"],[\"78482.50\",\"10.556\"],[\"78748.50\",\"6.974\"],[\"79146.10\",\"0.008\"],[\"79452.40\",\"0.358\"],[\"79453.10\",\"0.020\"],[\"79454.80\",\"0.026\"],[\"79454.90\",\"0.000\"],[\"79456.40\",\"0.010\"],[\"79482.70\",\"0.001\"],[\"79482.80\",\"0.010\"],[\"79502.50\",\"0.000\"],[\"79502.60\",\"0.001\"],[\"79517.30\",\"0.454\"],[\"79518.50\",\"0.002\"],[\"79527.80\",\"0.225\"],[\"79528.40\",\"0.617\"],[\"79528.50\",\"0.000\"],[\"79529.10\",\"0.229\"],[\"79531.60\",\"0.003\"],[\"79541.30\",\"0.000\"],[\"79543.70\",\"0.003\"]],\"a\":[[\"79559.70\",\"0.611\"],[\"79567.90\",\"0.354\"],[\"79587.10\",\"0.000\"],[\"79602.10\",\"0.006\"],[\"79607.00\",\"0.785\"],[\"79610.60\",\"0.005\"],[\"79611.10\",\"0.015\"],[\"79617.60\",\"0.001\"],[\"79621.60\",\"0.001\"],[\"79634.90\",\"0.000\"],[\"79668.10\",\"0.013\"],[\"79936.40\",\"0.008\"],[\"79937.70\",\"0.009\"],[\"79939.70\",\"0.186\"],[\"79941.80\",\"0.000\"],[\"80259.90\",\"2.755\"],[\"80339.40\",\"5.233\"]],\"st\":1}}"}
{"receive_ns":1788580710555170000,"stream":"btcusdt@bookTicker","event_type":"bookTicker","event_time_ms":1788580710600,"raw_json":"{\"stream\":\"btcusdt@bookTicker\",\"data\":{\"e\":\"bookTicker\",\"u\":11479473294147,\"s\":\"BTCUSDT\",\"ps\":\"BTCUSDT\",\"b\":\"79543.90\",\"B\":\"6.342\",\"a\":\"79544.00\",\"A\":\"5.392\",\"T\":1788580710600,\"E\":1788580710600,\"st\":1}}"}
{"receive_ns":1788580710555394000,"stream":"btcusdt@bookTicker","event_type":"bookTicker","event_time_ms":1788580710605,"raw_json":"{\"stream\":\"btcusdt@bookTicker\",\"data\":{\"e\":\"bookTicker\",\"u\":11479473294465,\"s\":\"BTCUSDT\",\"ps\":\"BTCUSDT\",\"b\":\"79543.90\",\"B\":\"6.343\",\"a\":\"79544.00\",\"A\":\"5.392\",\"T\":1788580710604,\"E\":1788580710605,\"st\":1}}"}
{"receive_ns":1788580710643927000,"stream":"btcusdt@depth@100ms","event_type":"depthUpdate","event_time_ms":1788580710671,"raw_json":"{\"stream\":\"btcusdt@depth@100ms\",\"data\":{\"e\":\"depthUpdate\",\"E\":1788580710671,\"T\":1788580710670,\"s\":\"BTCUSDT\",\"ps\":\"BTCUSDT\",\"U\":11479473292194,\"u\":11479473298135,\"pu\":11479473292006,\"b\":[[\"1000.00\",\"25.354\"],[\"29043.90\",\"0.000\"],[\"29343.90\",\"0.266\"],[\"29443.90\",\"1.834\"],[\"71589.50\",\"0.014\"],[\"71623.00\",\"0.000\"],[\"75561.60\",\"0.025\"],[\"78454.10\",\"1.022\"],[\"78748.50\",\"6.974\"],[\"79146.10\",\"0.009\"],[\"79146.20\",\"3.790\"],[\"79407.00\",\"0.015\"],[\"79415.20\",\"0.000\"],[\"79415.30\",\"1.998\"],[\"79452.40\",\"0.368\"],[\"79454.80\",\"0.038\"],[\"79456.40\",\"0.000\"],[\"79474.60\",\"0.001\"],[\"79476.00\",\"1.485\"],[\"79477.20\",\"22.952\"],[\"79486.70\",\"0.830\"],[\"79488.20\",\"0.130\"],[\"79501.90\",\"0.216\"],[\"79502.60\",\"0.692\"],[\"79517.30\",\"0.002\"],[\"79518.80\",\"0.454\"],[\"79543.90\",\"6.343\"]],\"a\":[[\"79550.70\",\"0.004\"],[\"79551.30\",\"0.377\"],[\"79557.80\",\"0.692\"],[\"79559.60\",\"0.081\"],[\"79573.70\",\"1.024\"],[\"79599.70\",\"0.052\"],[\"79618.30\",\"0.132\"],[\"79672.60\",\"1.106\"],[\"79674.70\",\"0.000\"],[\"79687.20\",\"0.006\"],[\"79939.70\",\"0.186\"],[\"79941.80\",\"0.001\"],[\"80339.40\",\"5.233\"],[\"80551.10\",\"5.338\"],[\"81028.30\",\"0.800\"],[\"81134.80\",\"0.009\"],[\"87498.40\",\"0.011\"]],\"st\":1}}"}
{"receive_ns":1788580710644260000,"stream":"btcusdt@bookTicker","event_type":"bookTicker","event_time_ms":1788580710672,"raw_json":"{\"stream\":\"btcusdt@bookTicker\",\"data\":{\"e\":\"bookTicker\",\"u\":11479473298239,\"s\":\"BTCUSDT\",\"ps\":\"BTCUSDT\",\"b\":\"79543.90\",\"B\":\"6.342\",\"a\":\"79544.00\",\"A\":\"5.392\",\"T\":1788580710672,\"E\":1788580710672,\"st\":1}}"}
{"receive_ns":1788580710644486000,"stream":"btcusdt@bookTicker","event_type":"bookTicker","event_time_ms":1788580710674,"raw_json":"{\"stream\":\"btcusdt@bookTicker\",\"data\":{\"e\":\"bookTicker\",\"u\":11479473298447,\"s\":\"BTCUSDT\",\"ps\":\"BTCUSDT\",\"b\":\"79543.90\",\"B\":\"6.343\",\"a\":\"79544.00\",\"A\":\"5.392\",\"T\":1788580710674,\"E\":1788580710674,\"st\":1}}"}
{"receive_ns":1788580710712829000,"stream":"btcusdt@bookTicker","event_type":"bookTicker","event_time_ms":1788580710735,"raw_json":"{\"stream\":\"btcusdt@bookTicker\",\"data\":{\"e\":\"bookTicker\",\"u\":11479473301416,\"s\":\"BTCUSDT\",\"ps\":\"BTCUSDT\",\"b\":\"79543.90\",\"B\":\"6.239\",\"a\":\"79544.00\",\"A\":\"5.392\",\"T\":1788580710735,\"E\":1788580710735,\"st\":1}}"}
{"receive_ns":1788580710713044000,"stream":"btcusdt@bookTicker","event_type":"bookTicker","event_time_ms":1788580710738,"raw_json":"{\"stream\":\"btcusdt@bookTicker\",\"data\":{\"e\":\"bookTicker\",\"u\":11479473301640,\"s\":\"BTCUSDT\",\"ps\":\"BTCUSDT\",\"b\":\"79543.90\",\"B\":\"6.344\",\"a\":\"79544.00\",\"A\":\"5.392\",\"T\":1788580710738,\"E\":1788580710738,\"st\":1}}"}
{"receive_ns":1788580710773245000,"stream":"btcusdt@depth@100ms","event_type":"depthUpdate","event_time_ms":1788580710773,"raw_json":"{\"stream\":\"btcusdt@depth@100ms\",\"data\":{\"e\":\"depthUpdate\",\"E\":1788580710773,\"T\":1788580710772,\"s\":\"BTCUSDT\",\"ps\":\"BTCUSDT\",\"U\":11479473298239,\"u\":11479473305044,\"pu\":11479473298135,\"b\":[[\"1000.00\",\"25.354\"],[\"29343.90\",\"0.441\"],[\"29443.90\",\"1.659\"],[\"71589.50\",\"0.014\"],[\"76362.10\",\"0.000\"],[\"77953.10\",\"0.015\"],[\"78748.50\",\"6.974\"],[\"79401.50\",\"0.017\"],[\"79407.00\",\"0.027\"],[\"79415.30\",\"1.992\"],[\"79419.70\",\"1.509\"],[\"79452.40\",\"0.060\"],[\"79453.10\",\"0.000\"],[\"79454.70\",\"6.000\"],[\"79474.60\",\"22.925\"],[\"79477.20\",\"0.028\"],[\"79482.50\",\"4.128\"],[\"79502.40\",\"0.564\"],[\"79542.10\",\"0.000\"],[\"79543.70\",\"0.003\"],[\"79543.90\",\"6.344\"]],\"a\":[[\"79550.70\",\"0.380\"],[\"79551.30\",\"0.001\"],[\"79588.00\",\"0.804\"],[\"79607.90\",\"3.501\"],[\"79623.60\",\"0.002\"],[\"79635.80\",\"6.001\"],[\"79666.30\",\"0.000\"],[\"79668.10\",\"0.007\"],[\"79936.40\",\"0.001\"],[\"79937.70\",\"0.004\"],[\"79939.70\",\"0.005\"],[\"79941.70\",\"2.498\"],[\"80339.40\",\"5.233\"],[\"80590.80\",\"25.234\"],[\"81119.00\",\"1.238\"],[\"87498.40\",\"0.009\"]],\"st\":1}}"}
{"receive_ns":1788580710776021000,"stream":"btcusdt@bookTicker","event_type":"bookTicker","event_time_ms":1788580710788,"raw_json":"{\"stream\":\"btcusdt@bookTicker\",\"data\":{\"e\":\"bookTicker\",\"u\":11479473305872,\"s\":\"BTCUSDT\",\"ps\":\"BTCUSDT\",\"b\":\"79543.90\",\"B\":\"6.220\",\"a\":\"79544.00\",\"A\":\"5.392\",\"T\":1788580710788,\"E\":1788580710788,\"st\":1}}"}
{"receive_ns":1788580710776243000,"stream":"btcusdt@trade","event_type":"trade","event_time_ms":1788580710788,"raw_json":"{\"stream\":\"btcusdt@trade\",\"data\":{\"e\":\"trade\",\"E\":1788580710788,\"T\":1788580710788,\"s\":\"BTCUSDT\",\"t\":8054266666,\"p\":\"79543.90\",\"q\":\"0.052\",\"X\":\"MARKET\",\"m\":true,\"st\":1}}"}
{"receive_ns":1788580710776420000,"stream":"btcusdt@trade","event_type":"trade","event_time_ms":1788580710788,"raw_json":"{\"stream\":\"btcusdt@trade\",\"data\":{\"e\":\"trade\",\"E\":1788580710788,\"T\":1788580710788,\"s\":\"BTCUSDT\",\"t\":8054266667,\"p\":\"79543.90\",\"q\":\"0.036\",\"X\":\"MARKET\",\"m\":true,\"st\":1}}"}
{"receive_ns":1788580710776559000,"stream":"btcusdt@trade","event_type":"trade","event_time_ms":1788580710788,"raw_json":"{\"stream\":\"btcusdt@trade\",\"data\":{\"e\":\"trade\",\"E\":1788580710788,\"T\":1788580710788,\"s\":\"BTCUSDT\",\"t\":8054266668,\"p\":\"79543.90\",\"q\":\"0.036\",\"X\":\"MARKET\",\"m\":true,\"st\":1}}"}
{"receive_ns":1788580710776772000,"stream":"btcusdt@bookTicker","event_type":"bookTicker","event_time_ms":1788580710793,"raw_json":"{\"stream\":\"btcusdt@bookTicker\",\"data\":{\"e\":\"bookTicker\",\"u\":11479473306206,\"s\":\"BTCUSDT\",\"ps\":\"BTCUSDT\",\"b\":\"79543.90\",\"B\":\"6.218\",\"a\":\"79544.00\",\"A\":\"5.392\",\"T\":1788580710792,\"E\":1788580710793,\"st\":1}}"}
{"receive_ns":1788580710777487000,"stream":"btcusdt@bookTicker","event_type":"bookTicker","event_time_ms":1788580710796,"raw_json":"{\"stream\":\"btcusdt@bookTicker\",\"data\":{\"e\":\"bookTicker\",\"u\":11479473306354,\"s\":\"BTCUSDT\",\"ps\":\"BTCUSDT\",\"b\":\"79543.90\",\"B\":\"6.220\",\"a\":\"79544.00\",\"A\":\"5.392\",\"T\":1788580710796,\"E\":1788580710796,\"st\":1}}"}
{"receive_ns":1788580710777981000,"stream":"btcusdt@bookTicker","event_type":"bookTicker","event_time_ms":1788580710818,"raw_json":"{\"stream\":\"btcusdt@bookTicker\",\"data\":{\"e\":\"bookTicker\",\"u\":11479473307701,\"s\":\"BTCUSDT\",\"ps\":\"BTCUSDT\",\"b\":\"79543.90\",\"B\":\"6.220\",\"a\":\"79544.00\",\"A\":\"5.389\",\"T\":1788580710818,\"E\":1788580710818,\"st\":1}}"}
{"receive_ns":1788580710787323000,"stream":"btcusdt@bookTicker","event_type":"bookTicker","event_time_ms":1788580710843,"raw_json":"{\"stream\":\"btcusdt@bookTicker\",\"data\":{\"e\":\"bookTicker\",\"u\":11479473309214,\"s\":\"BTCUSDT\",\"ps\":\"BTCUSDT\",\"b\":\"79543.90\",\"B\":\"6.219\",\"a\":\"79544.00\",\"A\":\"5.389\",\"T\":1788580710843,\"E\":1788580710843,\"st\":1}}"}
{"receive_ns":1788580710831882000,"stream":"btcusdt@depth@100ms","event_type":"depthUpdate","event_time_ms":1788580710875,"raw_json":"{\"stream\":\"btcusdt@depth@100ms\",\"data\":{\"e\":\"depthUpdate\",\"E\":1788580710875,\"T\":1788580710873,\"s\":\"BTCUSDT\",\"ps\":\"BTCUSDT\",\"U\":11479473305169,\"u\":11479473310886,\"pu\":11479473305044,\"b\":[[\"29343.90\",\"0.623\"],[\"29443.90\",\"1.477\"],[\"71589.50\",\"0.014\"],[\"76362.10\",\"0.002\"],[\"78091.00\",\"1.080\"],[\"78191.70\",\"6.257\"],[\"78562.00\",\"7.205\"],[\"78593.70\",\"0.005\"],[\"78595.90\",\"0.000\"],[\"78748.50\",\"6.974\"],[\"79146.20\",\"3.790\"],[\"79380.30\",\"2.262\"],[\"79419.70\",\"1.951\"],[\"79452.40\",\"0.050\"],[\"79453.10\",\"0.020\"],[\"79456.40\",\"0.308\"],[\"79528.80\",\"0.083\"],[\"79542.10\",\"0.001\"],[\"79543.70\",\"0.002\"],[\"79543.90\",\"6.219\"]],\"a\":[[\"79544.00\",\"5.389\"],[\"79557.00\",\"0.106\"],[\"79591.80\",\"0.228\"],[\"79666.30\",\"0.437\"],[\"79705.60\",\"1.972\"],[\"79933.80\",\"0.005\"],[\"79936.40\",\"0.008\"],[\"79939.70\",\"0.181\"],[\"80334.10\",\"2.375\"],[\"80339.40\",\"5.233\"],[\"81015.60\",\"0.801\"],[\"81028.30\",\"0.000\"],[\"81532.60\",\"0.005\"]],\"st\":1}}"}
{"receive_ns":1788580710951285000,"stream":"btcusdt@depth@100ms","event_type":"depthUpdate","event_time_ms":1788580710977,"raw_json":"{\"stream\":\"btcusdt@depth@100ms\",\"data\":{\"e\":\"depthUpdate\",\"E\":1788580710977,\"T\":1788580710973,\"s\":\"BTCUSDT\",\"ps\":\"BTCUSDT\",\"U\":11479473311020,\"u\":11479473316689,\"pu\":11479473310886,\"b\":[[\"1000.00\",\"25.354\"],[\"29343.90\",\"0.798\"],[\"29443.90\",\"1.302\"],[\"71589.50\",\"0.014\"],[\"76362.10\",\"0.000\"],[\"78748.50\",\"6.974\"],[\"79401.50\",\"0.011\"],[\"79414.90\",\"13.146\"],[\"79415.00\",\"0.139\"],[\"79448.40\",\"0.004\"],[\"79456.40\",\"0.318\"],[\"79534.30\",\"0.345\"]],\"a\":[[\"79550.70\",\"0.376\"],[\"79551.30\",\"0.005\"],[\"79672.60\",\"2.456\"],[\"79675.60\",\"10.000\"],[\"79939.70\",\"0.186\"],[\"80339.40\",\"5.233\"],[\"81771.20\",\"0.487\"]],\"st\":1}}"}
{"receive_ns":1788580710971854000,"stream":"btcusdt@bookTicker","event_type":"bookTicker","event_time_ms":1788580711028,"raw_json":"{\"stream\":\"btcusdt@bookTicker\",\"data\":{\"e\":\"bookTicker\",\"u\":11479473319906,\"s\":\"BTCUSDT\",\"ps\":\"BTCUSDT\",\"b\":\"79543.90\",\"B\":\"6.218\",\"a\":\"79544.00\",\"A\":\"5.389\",\"T\":1788580711027,\"E\":1788580711028,\"st\":1}}"}
{"receive_ns":1788580711006383000,"stream":"btcusdt@bookTicker","event_type":"bookTicker","event_time_ms":1788580711032,"raw_json":"{\"stream\":\"btcusdt@bookTicker\",\"data\":{\"e\":\"bookTicker\",\"u\":11479473320205,\"s\":\"BTCUSDT\",\"ps\":\"BTCUSDT\",\"b\":\"79543.90\",\"B\":\"6.220\",\"a\":\"79544.00\",\"A\":\"5.389\",\"T\":1788580711032,\"E\":1788580711032,\"st\":1}}"}
{"receive_ns":1788580711024104000,"stream":"btcusdt@depth@100ms","event_type":"depthUpdate","event_time_ms":1788580711079,"raw_json":"{\"stream\":\"btcusdt@depth@100ms\",\"data\":{\"e\":\"depthUpdate\",\"E\":1788580711079,\"T\":1788580711077,\"s\":\"BTCUSDT\",\"ps\":\"BTCUSDT\",\"U\":11479473316863,\"u\":11479473323164,\"pu\":11479473316689,\"b\":[[\"1000.00\",\"25.354\"],[\"29343.90\",\"0.980\"],[\"29443.90\",\"1.120\"],[\"71589.50\",\"0.014\"],[\"76362.10\",\"0.002\"],[\"78226.20\",\"1.047\"],[\"78748.50\",\"6.974\"],[\"79453.10\",\"0.020\"],[\"79456.40\",\"0.318\"],[\"79488.20\",\"0.130\"],[\"79529.60\",\"0.002\"],[\"79543.90\",\"6.220\"]],\"a\":[[\"79550.70\",\"0.380\"],[\"79551.30\",\"0.001\"],[\"79599.70\",\"0.052\"],[\"79620.20\",\"0.008\"],[\"79628.30\",\"29.433\"],[\"79933.80\",\"0.018\"],[\"79936.40\",\"0.008\"],[\"79937.70\",\"0.041\"],[\"79939.70\",\"0.136\"],[\"80339.40\",\"5.233\"],[\"80432.20\",\"0.008\"],[\"80578.10\",\"2.110\"],[\"80851.10\",\"0.556\"],[\"81015.60\",\"1.601\"]],\"st\":1}}"}
{"receive_ns":1788580711083133000,"stream":"btcusdt@bookTicker","event_type":"bookTicker","event_time_ms":1788580711139,"raw_json":"{\"stream\":\"btcusdt@bookTicker\",\"data\":{\"e\":\"bookTicker\",\"u\":11479473327420,\"s\":\"BTCUSDT\",\"ps\":\"BTCUSDT\",\"b\":\"79543.90\",\"B\":\"6.219\",\"a\":\"79544.00\",\"A\":\"5.389\",\"T\":1788580711139,\"E\":1788580711139,\"st\":1}}"}
{"receive_ns":1788580711085814000,"stream":"btcusdt@bookTicker","event_type":"bookTicker","event_time_ms":1788580711142,"raw_json":"{\"stream\":\"btcusdt@bookTicker\",\"data\":{\"e\":\"bookTicker\",\"u\":11479473327583,\"s\":\"BTCUSDT\",\"ps\":\"BTCUSDT\",\"b\":\"79543.90\",\"B\":\"6.220\",\"a\":\"79544.00\",\"A\":\"5.389\",\"T\":1788580711142,\"E\":1788580711142,\"st\":1}}"}
{"receive_ns":1788580711091781000,"stream":"btcusdt@bookTicker","event_type":"bookTicker","event_time_ms":1788580711147,"raw_json":"{\"stream\":\"btcusdt@bookTicker\",\"data\":{\"e\":\"bookTicker\",\"u\":11479473327809,\"s\":\"BTCUSDT\",\"ps\":\"BTCUSDT\",\"b\":\"79543.90\",\"B\":\"6.221\",\"a\":\"79544.00\",\"A\":\"5.389\",\"T\":1788580711147,\"E\":1788580711147,\"st\":1}}"}
{"receive_ns":1788580711137843000,"stream":"btcusdt@depth@100ms","event_type":"depthUpdate","event_time_ms":1788580711181,"raw_json":"{\"stream\":\"btcusdt@depth@100ms\",\"data\":{\"e\":\"depthUpdate\",\"E\":1788580711181,\"T\":1788580711177,\"s\":\"BTCUSDT\",\"ps\":\"BTCUSDT\",\"U\":11479473323320,\"u\":11479473329954,\"pu\":11479473323164,\"b\":[[\"29343.90\",\"1.155\"],[\"29443.90\",\"0.945\"],[\"63635.00\",\"0.016\"],[\"63635.10\",\"0.000\"],[\"71589.50\",\"0.014\"],[\"78430.30\",\"33.109\"],[\"78748.50\",\"6.974\"],[\"79146.20\",\"3.790\"],[\"79419.70\",\"1.509\"],[\"79456.40\",\"0.318\"],[\"79543.80\",\"0.087\"],[\"79543.90\",\"6.221\"]],\"a\":[[\"79620.00\",\"16.147\"],[\"79624.80\",\"1.752\"],[\"79625.60\",\"29.710\"],[\"79626.80\",\"0.060\"],[\"79628.20\",\"0.501\"],[\"79628.30\",\"0.000\"],[\"79629.30\",\"0.001\"],[\"79666.30\",\"0.000\"],[\"79939.70\",\"0.136\"],[\"80259.90\",\"3.626\"],[\"80279.90\",\"0.000\"],[\"80339.40\",\"5.233\"]],\"st\":1}}"}
{"receive_ns":1788580711263372000,"stream":"btcusdt@depth@100ms","event_type":"depthUpdate","event_time_ms":1788580711283,"raw_json":"{\"stream\":\"btcusdt@depth@100ms\",\"data\":{\"e\":\"depthUpdate\",\"E\":1788580711283,\"T\":1788580711281,\"s\":\"BTCUSDT\",\"ps\":\"BTCUSDT\",\"U\":11479473330131,\"u\":11479473335380,\"pu\":11479473329954,\"b\":[[\"1000.00\",\"25.354\"],[\"29343.90\",\"1.337\"],[\"29443.90\",\"0.763\"],[\"63635.00\",\"0.000\"],[\"71589.50\",\"0.014\"],[\"76362.10\",\"0.000\"],[\"77953.10\",\"0.012\"],[\"78668.90\",\"2.789\"],[\"78748.50\",\"8.242\"],[\"78902.30\",\"1.012\"],[\"79380.30\",\"0.022\"],[\"79453.10\",\"0.000\"],[\"79456.40\",\"0.318\"],[\"79457.90\",\"0.033\"],[\"79540.00\",\"0.043\"]],\"a\":[[\"79705.60\",\"0.002\"],[\"79933.80\",\"0.000\"],[\"79936.40\",\"0.008\"],[\"79937.70\",\"0.059\"],[\"79939.70\",\"0.136\"],[\"80272.60\",\"6.840\"],[\"80339.40\",\"5.233\"],[\"80901.90\",\"0.002\"]],\"st\":1}}"}
{"receive_ns":1788580711264435000,"stream":"btcusdt@bookTicker","event_type":"bookTicker","event_time_ms":1788580711302,"raw_json":"{\"stream\":\"btcusdt@bookTicker\",\"data\":{\"e\":\"bookTicker\",\"u\":11479473336316,\"s\":\"BTCUSDT\",\"ps\":\"BTCUSDT\",\"b\":\"79543.90\",\"B\":\"6.221\",\"a\":\"79544.00\",\"A\":\"5.392\",\"T\":1788580711302,\"E\":1788580711302,\"st\":1}}"}
{"receive_ns":1788580711273554000,"stream":"btcusdt@bookTicker","event_type":"bookTicker","event_time_ms":1788580711321,"raw_json":"{\"stream\":\"btcusdt@bookTicker\",\"data\":{\"e\":\"bookTicker\",\"u\":11479473337199,\"s\":\"BTCUSDT\",\"ps\":\"BTCUSDT\",\"b\":\"79543.90\",\"B\":\"6.221\",\"a\":\"79544.00\",\"A\":\"5.146\",\"T\":1788580711321,\"E\":1788580711321,\"st\":1}}"}
{"receive_ns":1788580711330451000,"stream":"btcusdt@depth@100ms","event_type":"depthUpdate","event_time_ms":1788580711385,"raw_json":"{\"stream\":\"btcusdt@depth@100ms\",\"data\":{\"e\":\"depthUpdate\",\"E\":1788580711385,\"T\":1788580711382,\"s\":\"BTCUSDT\",\"ps\":\"BTCUSDT\",\"U\":11479473335436,\"u\":11479473341502,\"pu\":11479473335380,\"b\":[[\"1000.00\",\"25.354\"],[\"29343.90\",\"1.512\"],[\"29443.90\",\"0.588\"],[\"63635.00\",\"0.000\"],[\"71589.50\",\"0.014\"],[\"75566.80\",\"0.002\"],[\"76362.10\",\"0.002\"],[\"78231.40\",\"2.009\"],[\"78611.70\",\"6.225\"],[\"78708.70\",\"0.697\"],[\"78748.50\",\"8.242\"],[\"78947.30\",\"3.165\"],[\"79332.50\",\"0.005\"],[\"79332.60\",\"5.355\"],[\"79335.50\",\"1.226\"],[\"79358.60\",\"3.163\"],[\"79358.90\",\"0.001\"],[\"79380.30\",\"2.262\"],[\"79419.70\",\"2.012\"],[\"79453.10\",\"0.020\"],[\"79456.40\",\"0.308\"],[\"79457.90\",\"0.071\"],[\"79458.00\",\"0.001\"],[\"79510.50\",\"0.009\"],[\"79520.20\",\"2.395\"],[\"79524.80\",\"0.637\"],[\"79526.10\",\"0.373\"],[\"79528.10\",\"0.167\"],[\"79528.40\",\"0.177\"],[\"79529.40\",\"1.795\"],[\"79529.50\",\"0.447\"],[\"79531.80\",\"0.001\"],[\"79532.80\",\"0.252\"],[\"79538.60\",\"0.440\"],[\"79539.30\",\"0.006\"],[\"79539.40\",\"0.025\"],[\"79539.60\",\"1.374\"]],\"a\":[[\"79544.00\",\"5.146\"],[\"79549.00\",\"0.025\"],[\"79550.40\",\"0.029\"],[\"79550.70\",\"0.008\"],[\"79551.30\",\"0.001\"],[\"79551.60\",\"0.384\"],[\"79554.20\",\"0.007\"],[\"79554.90\",\"0.325\"],[\"79557.00\",\"0.030\"],[\"79557.90\",\"0.000\"],[\"79560.10\",\"0.004\"],[\"79562.70\",\"0.008\"],[\"79563.00\",\"0.027\"],[\"79563.50\",\"0.632\"],[\"79564.90\",\"0.002\"],[\"79565.50\",\"0.557\"],[\"79566.10\",\"0.373\"],[\"79566.50\",\"0.000\"],[\"79566.60\",\"0.205\"],[\"79566.70\",\"0.000\"],[\"79567.50\",\"0.629\"],[\"79571.00\",\"0.631\"],[\"79577.50\",\"0.266\"],[\"79578.90\",\"0.008\"],[\"79598.40\",\"0.004\"],[\"79633.00\",\"0.038\"],[\"79633.10\",\"0.022\"],[\"79649.20\",\"0.000\"],[\"79649.40\",\"1.175\"],[\"79665.20\",\"0.876\"],[\"79665.40\",\"0.007\"],[\"79666.20\",\"0.437\"],[\"79687.00\",\"3.143\"],[\"79705.60\",\"1.972\"],[\"79753.30\",\"5.696\"],[\"79753.40\",\"0.037\"],[\"79939.70\",\"0.131\"],[\"80140.60\",\"3.739\"],[\"80334.10\",\"1.132\"],[\"80339.40\",\"5.233\"],[\"80856.50\",\"2.595\"]],\"st\":1}}"}
{"receive_ns":1788580711336892000,"stream":"btcusdt@bookTicker","event_type":"bookTicker","event_time_ms":1788580711392,"raw_json":"{\"stream\":\"btcusdt@bookTicker\",\"data\":{\"e\":\"bookTicker\",\"u\":11479473342123,\"s\":\"BTCUSDT\",\"ps\":\"BTCUSDT\",\"b\":\"79543.90\",\"B\":\"6.071\",\"a\":\"79544.00\",\"A\":\"5.146\",\"T\":1788580711392,\"E\":1788580711392,\"st\":1}}"}
{"receive_ns":1788580711337138000,"stream":"btcusdt@bookTicker","event_type":"bookTicker","event_time_ms":1788580711395,"raw_json":"{\"stream\":\"btcusdt@bookTicker\",\"data\":{\"e\":\"bookTicker\",\"u\":11479473342278,\"s\":\"BTCUSDT\",\"ps\":\"BTCUSDT\",\"b\":\"79543.90\",\"B\":\"6.204\",\"a\":\"79544.00\",\"A\":\"5.146\",\"T\":1788580711395,\"E\":1788580711395,\"st\":1}}"}
{"receive_ns":1788580711380259000,"stream":"btcusdt@bookTicker","event_type":"bookTicker","event_time_ms":1788580711404,"raw_json":"{\"stream\":\"btcusdt@bookTicker\",\"data\":{\"e\":\"bookTicker\",\"u\":11479473342704,\"s\":\"BTCUSDT\",\"ps\":\"BTCUSDT\",\"b\":\"79543.90\",\"B\":\"6.061\",\"a\":\"79544.00\",\"A\":\"5.146\",\"T\":1788580711404,\"E\":1788580711404,\"st\":1}}"}
{"receive_ns":1788580711380505000,"stream":"btcusdt@bookTicker","event_type":"bookTicker","event_time_ms":1788580711407,"raw_json":"{\"stream\":\"btcusdt@bookTicker\",\"data\":{\"e\":\"bookTicker\",\"u\":11479473342881,\"s\":\"BTCUSDT\",\"ps\":\"BTCUSDT\",\"b\":\"79543.90\",\"B\":\"6.233\",\"a\":\"79544.00\",\"A\":\"5.146\",\"T\":1788580711407,\"E\":1788580711407,\"st\":1}}"}
{"receive_ns":1788580711380674000,"stream":"btcusdt@bookTicker","event_type":"bookTicker","event_time_ms":1788580711418,"raw_json":"{\"stream\":\"btcusdt@bookTicker\",\"data\":{\"e\":\"bookTicker\",\"u\":11479473343346,\"s\":\"BTCUSDT\",\"ps\":\"BTCUSDT\",\"b\":\"79543.90\",\"B\":\"6.233\",\"a\":\"79544.00\",\"A\":\"5.142\",\"T\":1788580711417,\"E\":1788580711418,\"st\":1}}"}
{"receive_ns":1788580711380873000,"stream":"btcusdt@bookTicker","event_type":"bookTicker","event_time_ms":1788580711420,"raw_json":"{\"stream\":\"btcusdt@bookTicker\",\"data\":{\"e\":\"bookTicker\",\"u\":11479473343516,\"s\":\"BTCUSDT\",\"ps\":\"BTCUSDT\",\"b\":\"79543.90\",\"B\":\"6.233\",\"a\":\"79544.00\",\"A\":\"5.147\",\"T\":1788580711420,\"E\":1788580711420,\"st\":1}}"}
{"receive_ns":1788580711387633000,"stream":"btcusdt@bookTicker","event_type":"bookTicker","event_time_ms":1788580711442,"raw_json":"{\"stream\":\"btcusdt@bookTicker\",\"data\":{\"e\":\"bookTicker\",\"u\":11479473344637,\"s\":\"BTCUSDT\",\"ps\":\"BTCUSDT\",\"b\":\"79543.90\",\"B\":\"6.233\",\"a\":\"79544.00\",\"A\":\"5.135\",\"T\":1788580711442,\"E\":1788580711442,\"st\":1}}"}
{"receive_ns":1788580711390210000,"stream":"btcusdt@bookTicker","event_type":"bookTicker","event_time_ms":1788580711445,"raw_json":"{\"stream\":\"btcusdt@bookTicker\",\"data\":{\"e\":\"bookTicker\",\"u\":11479473344812,\"s\":\"BTCUSDT\",\"ps\":\"BTCUSDT\",\"b\":\"79543.90\",\"B\":\"6.233\",\"a\":\"79544.00\",\"A\":\"5.148\",\"T\":1788580711445,\"E\":1788580711445,\"st\":1}}"}
{"receive_ns":1788580711399263000,"stream":"btcusdt@bookTicker","event_type":"bookTicker","event_time_ms":1788580711454,"raw_json":"{\"stream\":\"btcusdt@bookTicker\",\"data\":{\"e\":\"bookTicker\",\"u\":11479473345130,\"s\":\"BTCUSDT\",\"ps\":\"BTCUSDT\",\"b\":\"79543.90\",\"B\":\"6.233\",\"a\":\"79544.00\",\"A\":\"5.147\",\"T\":1788580711454,\"E\":1788580711454,\"st\":1}}"}
{"receive_ns":1788580711399429000,"stream":"btcusdt@bookTicker","event_type":"bookTicker","event_time_ms":1788580711454,"raw_json":"{\"stream\":\"btcusdt@bookTicker\",\"data\":{\"e\":\"bookTicker\",\"u\":11479473345133,\"s\":\"BTCUSDT\",\"ps\":\"BTCUSDT\",\"b\":\"79543.90\",\"B\":\"6.233\",\"a\":\"79544.00\",\"A\":\"5.101\",\"T\":1788580711454,\"E\":1788580711454,\"st\":1}}"}
{"receive_ns":1788580711399591000,"stream":"btcusdt@trade","event_type":"trade","event_time_ms":1788580711454,"raw_json":"{\"stream\":\"btcusdt@trade\",\"data\":{\"e\":\"trade\",\"E\":1788580711454,\"T\":1788580711454,\"s\":\"BTCUSDT\",\"t\":8054266669,\"p\":\"79544.00\",\"q\":\"0.001\",\"X\":\"MARKET\",\"m\":false,\"st\":1}}"}
{"receive_ns":1788580711403099000,"stream":"btcusdt@bookTicker","event_type":"bookTicker","event_time_ms":1788580711457,"raw_json":"{\"stream\":\"btcusdt@bookTicker\",\"data\":{\"e\":\"bookTicker\",\"u\":11479473345322,\"s\":\"BTCUSDT\",\"ps\":\"BTCUSDT\",\"b\":\"79543.90\",\"B\":\"6.233\",\"a\":\"79544.00\",\"A\":\"5.149\",\"T\":1788580711457,\"E\":1788580711457,\"st\":1}}"}
{"receive_ns":1788580711438782000,"stream":"btcusdt@depth@100ms","event_type":"depthUpdate","event_time_ms":1788580711487,"raw_json":"{\"stream\":\"btcusdt@depth@100ms\",\"data\":{\"e\":\"depthUpdate\",\"E\":1788580711487,\"T\":1788580711485,\"s\":\"BTCUSDT\",\"ps\":\"BTCUSDT\",\"U\":11479473341765,\"u\":11479473346739,\"pu\":11479473341502,\"b\":[[\"29343.90\",\"1.694\"],[\"29443.90\",\"0.406\"],[\"71589.50\",\"0.014\"],[\"75561.60\",\"0.020\"],[\"75566.70\",\"0.022\"],[\"76362.10\",\"0.000\"],[\"78743.20\",\"1.712\"],[\"78748.50\",\"8.242\"],[\"78907.50\",\"6.702\"],[\"79146.20\",\"3.780\"],[\"79456.40\",\"0.010\"],[\"79472.30\",\"0.380\"],[\"79510.80\",\"0.110\"],[\"79523.30\",\"0.001\"],[\"79525.50\",\"0.374\"],[\"79526.10\",\"0.000\"],[\"79529.60\",\"0.008\"],[\"79530.10\",\"0.031\"],[\"79532.00\",\"0.255\"],[\"79532.80\",\"0.001\"],[\"79534.00\",\"0.024\"],[\"79538.90\",\"1.004\"],[\"79539.30\",\"0.000\"],[\"79539.40\",\"0.023\"],[\"79539.60\",\"1.372\"],[\"79540.50\",\"0.003\"],[\"79542.10\",\"0.000\"],[\"79543.90\",\"6.233\"]],\"a\":[[\"79544.00\",\"5.149\"],[\"79549.00\",\"0.033\"],[\"79550.70\",\"0.000\"],[\"79551.30\",\"0.005\"],[\"79551.60\",\"0.380\"],[\"79558.40\",\"0.001\"],[\"79559.60\",\"0.005\"],[\"79563.00\",\"0.655\"],[\"79571.00\",\"0.003\"],[\"79615.60\",\"0.006\"],[\"79617.40\",\"0.000\"],[\"79620.30\",\"29.516\"],[\"79625.60\",\"0.200\"],[\"79937.70\",\"0.004\"],[\"79939.70\",\"0.005\"],[\"80272.70\",\"0.879\"],[\"80339.40\",\"5.233\"],[\"80630.60\",\"9.626\"]],\"st\":1}}"}
{"receive_ns":1788580711467052000,"stream":"btcusdt@bookTicker","event_type":"bookTicker","event_time_ms":1788580711522,"raw_json":"{\"stream\":\"btcusdt@bookTicker\",\"data\":{\"e\":\"bookTicker\",\"u\":11479473348360,\"s\":\"BTCUSDT\",\"ps\":\"BTCUSDT\",\"b\":\"79543.90\",\"B\":\"6.226\",\"a\":\"79544.00\",\"A\":\"5.149\",\"T\":1788580711522,\"E\":1788580711522,\"st\":1}}"}
{"receive_ns":1788580711467301000,"stream":"btcusdt@trade","event_type":"trade","event_time_ms":1788580711522,"raw_json":"{\"stream\":\"btcusdt@trade\",\"data\":{\"e\":\"trade\",\"E\":1788580711522,\"T\":1788580711522,\"s\":\"BTCUSDT\",\"t\":8054266670,\"p\":\"79543.90\",\"q\":\"0.007\",\"X\":\"MARKET\",\"m\":true,\"st\":1}}"}
{"receive_ns":1788580711567736000,"stream":"btcusdt@depth@100ms","event_type":"depthUpdate","event_time_ms":1788580711589,"raw_json":"{\"stream\":\"btcusdt@depth@100ms\",\"data\":{\"e\":\"depthUpdate\",\"E\":1788580711589,\"T\":1788580711588,\"s\":\"BTCUSDT\",\"ps\":\"BTCUSDT\",\"U\":11479473346828,\"u\":11479473351985,\"pu\":11479473346739,\"b\":[[\"1000.00\",\"25.354\"],[\"29243.90\",\"0.042\"],[\"29343.90\",\"1.785\"],[\"29443.90\",\"0.273\"],[\"71589.50\",\"0.014\"],[\"76362.10\",\"0.002\"],[\"78483.30\",\"2.671\"],[\"78748.50\",\"8.242\"],[\"79453.10\",\"0.020\"],[\"79456.40\",\"0.318\"],[\"79523.30\",\"0.002\"],[\"79528.40\",\"0.617\"],[\"79529.40\",\"0.538\"],[\"79529.50\",\"0.635\"],[\"79530.10\",\"0.005\"],[\"79543.90\",\"6.226\"]],\"a\":[[\"79558.40\",\"0.077\"],[\"79559.40\",\"0.628\"],[\"79563.00\",\"0.027\"],[\"79617.40\",\"0.001\"],[\"79620.30\",\"0.006\"],[\"79625.60\",\"29.710\"],[\"79628.30\",\"0.000\"],[\"79645.90\",\"0.000\"],[\"79668.10\",\"0.007\"],[\"79936.40\",\"0.008\"],[\"79939.70\",\"0.191\"],[\"80107.10\",\"0.130\"],[\"80260.00\",\"3.192\"],[\"80339.40\",\"5.233\"],[\"80720.30\",\"0.000\"]],\"st\":1}}"}
{"receive_ns":1788580711625432000,"stream":"btcusdt@bookTicker","event_type":"bookTicker","event_time_ms":1788580711668,"raw_json":"{\"stream\":\"btcusdt@bookTicker\",\"data\":{\"e\":\"bookTicker\",\"u\":11479473357832,\"s\":\"BTCUSDT\",\"ps\":\"BTCUSDT\",\"b\":\"79543.90\",\"B\":\"6.225\",\"a\":\"79544.00\",\"A\":\"5.149\",\"T\":1788580711668,\"E\":1788580711668,\"st\":1}}"}
{"receive_ns":1788580711625700000,"stream":"btcusdt@bookTicker","event_type":"bookTicker","event_time_ms":1788580711670,"raw_json":"{\"stream\":\"btcusdt@bookTicker\",\"data\":{\"e\":\"bookTicker\",\"u\":11479473357936,\"s\":\"BTCUSDT\",\"ps\":\"BTCUSDT\",\"b\":\"79543.90\",\"B\":\"6.226\",\"a\":\"79544.00\",\"A\":\"5.149\",\"T\":1788580711670,\"E\":1788580711670,\"st\":1}}"}
{"receive_ns":1788580711634090000,"stream":"btcusdt@depth@100ms","event_type":"depthUpdate","event_time_ms":1788580711691,"raw_json":"{\"stream\":\"btcusdt@depth@100ms\",\"data\":{\"e\":\"depthUpdate\",\"E\":1788580711691,\"T\":1788580711689,\"s\":\"BTCUSDT\",\"ps\":\"BTCUSDT\",\"U\":11479473352150,\"u\":11479473358941,\"pu\":11479473351985,\"b\":[[\"1000.00\",\"25.354\"],[\"29243.90\",\"0.098\"],[\"29343.90\",\"1.855\"],[\"29443.90\",\"0.147\"],[\"63635.00\",\"0.000\"],[\"71589.50\",\"0.014\"],[\"71623.00\",\"0.000\"],[\"77953.10\",\"0.009\"],[\"78426.80\",\"0.306\"],[\"78438.20\",\"5.953\"],[\"78571.90\",\"1.277\"],[\"78748.50\",\"8.242\"],[\"78907.50\",\"6.954\"],[\"79146.10\",\"0.009\"],[\"79456.40\",\"0.318\"],[\"79474.60\",\"0.001\"],[\"79477.20\",\"22.951\"],[\"79543.90\",\"6.226\"]],\"a\":[[\"79551.30\",\"0.067\"],[\"79551.60\",\"0.318\"],[\"79620.30\",\"29.516\"],[\"79625.60\",\"0.200\"],[\"79939.70\",\"0.191\"],[\"79941.80\",\"0.001\"],[\"80339.40\",\"5.233\"],[\"80670.40\",\"16.982\"],[\"81134.80\",\"0.012\"]],\"st\":1}}"}
{"receive_ns":1788580711638716000,"stream":"btcusdt@bookTicker","event_type":"bookTicker","event_time_ms":1788580711695,"raw_json":"{\"stream\":\"btcusdt@bookTicker\",\"data\":{\"e\":\"bookTicker\",\"u\":11479473359285,\"s\":\"BTCUSDT\",\"ps\":\"BTCUSDT\",\"b\":\"79543.90\",\"B\":\"6.226\",\"a\":\"79544.00\",\"A\":\"5.395\",\"T\":1788580711695,\"E\":1788580711695,\"st\":1}}"}
{"receive_ns":1788580711639005000,"stream":"btcusdt@bookTicker","event_type":"bookTicker","event_time_ms":1788580711697,"raw_json":"{\"stream\":\"btcusdt@bookTicker\",\"data\":{\"e\":\"bookTicker\",\"u\":11479473359354,\"s\":\"BTCUSDT\",\"ps\":\"BTCUSDT\",\"b\":\"79543.90\",\"B\":\"6.226\",\"a\":\"79544.00\",\"A\":\"5.393\",\"T\":1788580711696,\"E\":1788580711697,\"st\":1}}"}
{"receive_ns":1788580711741961000,"stream":"btcusdt@depth@100ms","event_type":"depthUpdate","event_time_ms":1788580711793,"raw_json":"{\"stream\":\"btcusdt@depth@100ms\",\"data\":{\"e\":\"depthUpdate\",\"E\":1788580711793,\"T\":1788580711790,\"s\":\"BTCUSDT\",\"ps\":\"BTCUSDT\",\"U\":11479473359078,\"u\":11479473364055,\"pu\":11479473358941,\"b\":[[\"29243.90\",\"0.161\"],[\"29343.90\",\"1.904\"],[\"29443.90\",\"0.035\"],[\"63635.00\",\"0.000\"],[\"71589.50\",\"0.014\"],[\"76362.10\",\"0.000\"],[\"78442.70\",\"13.966\"],[\"78486.40\",\"0.000\"],[\"78549.60\",\"7.168\"],[\"78592.70\",\"0.003\"],[\"78593.70\",\"0.001\"],[\"78604.70\",\"0.004\"],[\"78611.40\",\"0.004\"],[\"78748.50\",\"8.242\"],[\"78947.30\",\"3.797\"],[\"79146.20\",\"3.780\"],[\"79453.10\",\"0.020\"],[\"79456.40\",\"0.318\"],[\"79474.60\",\"22.924\"],[\"79477.20\",\"0.028\"],[\"79497.30\",\"0.698\"],[\"79502.60\",\"0.001\"],[\"79518.30\",\"0.470\"],[\"79518.80\",\"0.002\"],[\"79524.80\",\"1.010\"],[\"79525.50\",\"0.001\"],[\"79528.10\",\"0.141\"],[\"79538.50\",\"0.072\"],[\"79538.90\",\"1.000\"]],\"a\":[[\"79544.00\",\"5.393\"],[\"79550.70\",\"0.380\"],[\"79551.30\",\"0.001\"],[\"79551.60\",\"0.004\"],[\"79554.50\",\"0.155\"],[\"79557.20\",\"0.336\"],[\"79559.40\",\"0.628\"],[\"79564.40\",\"0.091\"],[\"79564.70\",\"0.375\"],[\"79564.90\",\"0.441\"],[\"79565.50\",\"0.118\"],[\"79566.10\",\"0.000\"],[\"79567.80\",\"0.454\"],[\"79568.50\",\"0.001\"],[\"79588.30\",\"0.001\"],[\"79620.30\",\"0.006\"],[\"79623.00\",\"0.009\"],[\"79625.60\",\"29.710\"],[\"79628.30\",\"0.000\"],[\"79933.80\",\"0.037\"],[\"79936.40\",\"0.008\"],[\"79937.70\",\"0.022\"],[\"79939.70\",\"0.136\"],[\"80140.60\",\"4.362\"],[\"80260.00\",\"4.063\"],[\"80339.40\",\"5.233\"],[\"80697.40\",\"13.052\"],[\"84080.60\",\"0.000\"]],\"st\":1}}"}
{"receive_ns":1788580711868001000,"stream":"btcusdt@depth@100ms","event_type":"depthUpdate","event_time_ms":1788580711895,"raw_json":"{\"stream\":\"btcusdt@depth@100ms\",\"data\":{\"e\":\"depthUpdate\",\"E\":1788580711895,\"T\":1788580711893,\"s\":\"BTCUSDT\",\"ps\":\"BTCUSDT\",\"U\":11479473364202,\"u\":11479473371958,\"pu\":11479473364055,\"b\":[[\"1000.00\",\"25.354\"],[\"29243.90\",\"0.308\"],[\"29343.90\",\"1.792\"],[\"29443.90\",\"0.000\"],[\"71589.50\",\"0.014\"],[\"75561.60\",\"0.015\"],[\"76362.10\",\"0.002\"],[\"78748.50\",\"8.242\"],[\"78821.80\",\"0.191\"],[\"79456.40\",\"0.318\"]],\"a\":[[\"79550.70\",\"0.000\"],[\"79551.30\",\"0.381\"],[\"79620.30\",\"29.516\"],[\"79625.60\",\"0.200\"],[\"79939.70\",\"0.136\"],[\"80175.00\",\"3.125\"],[\"80339.40\",\"6.476\"]],\"st\":1}}"}
{"receive_ns":1788580711941040000,"stream":"btcusdt@depth@100ms","event_type":"depthUpdate","event_time_ms":1788580711997,"raw_json":"{\"stream\":\"btcusdt@depth@100ms\",\"data\":{\"e\":\"depthUpdate\",\"E\":1788580711997,\"T\":1788580711994,\"s\":\"BTCUSDT\",\"ps\":\"BTCUSDT\",\"U\":11479473372164,\"u\":11479473377315,\"pu\":11479473371958,\"b\":[[\"1000.00\",\"25.354\"],[\"29243.90\",\"0.483\"],[\"29343.90\",\"1.617\"],[\"63635.00\",\"0.000\"],[\"71589.50\",\"0.014\"],[\"76362.10\",\"0.000\"],[\"78333.20\",\"0.893\"],[\"78430.30\",\"33.122\"],[\"78549.60\",\"7.606\"],[\"78611.70\",\"4.954\"],[\"78748.50\",\"8.242\"],[\"79416.60\",\"0.185\"],[\"79524.00\",\"0.004\"]],\"a\":[[\"79550.40\",\"0.050\"],[\"79550.70\",\"0.000\"],[\"79551.30\",\"0.381\"],[\"79620.30\",\"0.006\"],[\"79625.60\",\"29.710\"],[\"79628.30\",\"0.000\"],[\"80339.40\",\"6.476\"],[\"80686.30\",\"0.000\"],[\"87498.40\",\"0.009\"]],\"st\":1}}"}
{"receive_ns":1788580711996597000,"stream":"btcusdt@bookTicker","event_type":"bookTicker","event_time_ms":1788580712052,"raw_json":"{\"stream\":\"btcusdt@bookTicker\",\"data\":{\"e\":\"bookTicker\",\"u\":11479473380303,\"s\":\"BTCUSDT\",\"ps\":\"BTCUSDT\",\"b\":\"79543.90\",\"B\":\"6.226\",\"a\":\"79544.00\",\"A\":\"5.390\",\"T\":1788580712052,\"E\":1788580712052,\"st\":1}}"}
{"receive_ns":1788580712009230000,"stream":"btcusdt@bookTicker","event_type":"bookTicker","event_time_ms":1788580712065,"raw_json":"{\"stream\":\"btcusdt@bookTicker\",\"data\":{\"e\":\"bookTicker\",\"u\":11479473380825,\"s\":\"BTCUSDT\",\"ps\":\"BTCUSDT\",\"b\":\"79543.90\",\"B\":\"6.223\",\"a\":\"79544.00\",\"A\":\"5.390\",\"T\":1788580712065,\"E\":1788580712065,\"st\":1}}"}
{"receive_ns":1788580712009522000,"stream":"btcusdt@trade","event_type":"trade","event_time_ms":1788580712065,"raw_json":"{\"stream\":\"btcusdt@trade\",\"data\":{\"e\":\"trade\",\"E\":1788580712065,\"T\":1788580712065,\"s\":\"BTCUSDT\",\"t\":8054266671,\"p\":\"79543.90\",\"q\":\"0.003\",\"X\":\"MARKET\",\"m\":true,\"st\":1}}"}
{"receive_ns":1788580712047494000,"stream":"btcusdt@depth@100ms","event_type":"depthUpdate","event_time_ms":1788580712099,"raw_json":"{\"stream\":\"btcusdt@depth@100ms\",\"data\":{\"e\":\"depthUpdate\",\"E\":1788580712099,\"T\":1788580712098,\"s\":\"BTCUSDT\",\"ps\":\"BTCUSDT\",\"U\":11479473377503,\"u\":11479473382635,\"pu\":11479473377315,\"b\":[[\"29243.90\",\"0.665\"],[\"29343.90\",\"1.435\"],[\"63635.00\",\"0.000\"],[\"71589.50\",\"0.014\"],[\"78311.00\",\"9.168\"],[\"78748.50\",\"8.242\"],[\"78827.90\",\"3.928\"],[\"79146.20\",\"3.790\"],[\"79453.10\",\"0.020\"],[\"79456.40\",\"0.318\"],[\"79474.60\",\"22.908\"],[\"79477.20\",\"0.028\"],[\"79529.60\",\"0.008\"],[\"79543.90\",\"6.223\"]],\"a\":[[\"79544.00\",\"5.390\"],[\"79550.40\",\"0.029\"],[\"79578.10\",\"0.320\"],[\"79620.30\",\"29.516\"],[\"79625.60\",\"0.200\"],[\"79626.80\",\"0.036\"],[\"79933.80\",\"0.000\"],[\"79936.40\",\"0.008\"],[\"79937.70\",\"0.059\"],[\"79939.70\",\"0.136\"],[\"80260.20\",\"0.031\"],[\"80339.40\",\"6.476\"],[\"80538.30\",\"5.137\"],[\"80578.10\",\"3.969\"]],\"st\":1}}"}
{"receive_ns":1788580712059254000,"stream":"btcusdt@bookTicker","event_type":"bookTicker","event_time_ms":1788580712115,"raw_json":"{\"stream\":\"btcusdt@bookTicker\",\"data\":{\"e\":\"bookTicker\",\"u\":11479473383989,\"s\":\"BTCUSDT\",\"ps\":\"BTCUSDT\",\"b\":\"79543.90\",\"B\":\"6.223\",\"a\":\"79544.00\",\"A\":\"5.373\",\"T\":1788580712114,\"E\":1788580712115,\"st\":1}}"}
{"receive_ns":1788580712062765000,"stream":"btcusdt@bookTicker","event_type":"bookTicker","event_time_ms":1788580712118,"raw_json":"{\"stream\":\"btcusdt@bookTicker\",\"data\":{\"e\":\"bookTicker\",\"u\":11479473384137,\"s\":\"BTCUSDT\",\"ps\":\"BTCUSDT\",\"b\":\"79543.90\",\"B\":\"6.223\",\"a\":\"79544.00\",\"A\":\"5.391\",\"T\":1788580712118,\"E\":1788580712118,\"st\":1}}"}
{"receive_ns":1788580712063116000,"stream":"btcusdt@bookTicker","event_type":"bookTicker","event_time_ms":1788580712119,"raw_json":"{\"stream\":\"btcusdt@bookTicker\",\"data\":{\"e\":\"bookTicker\",\"u\":11479473384214,\"s\":\"BTCUSDT\",\"ps\":\"BTCUSDT\",\"b\":\"79543.90\",\"B\":\"6.223\",\"a\":\"79544.00\",\"A\":\"5.393\",\"T\":1788580712119,\"E\":1788580712119,\"st\":1}}"}
{"receive_ns":1788580712067160000,"stream":"btcusdt@bookTicker","event_type":"bookTicker","event_time_ms":1788580712122,"raw_json":"{\"stream\":\"btcusdt@bookTicker\",\"data\":{\"e\":\"bookTicker\",\"u\":11479473384384,\"s\":\"BTCUSDT\",\"ps\":\"BTCUSDT\",\"b\":\"79543.90\",\"B\":\"6.222\",\"a\":\"79544.00\",\"A\":\"5.393\",\"T\":1788580712122,\"E\":1788580712122,\"st\":1}}"}
{"receive_ns":1788580712067406000,"stream":"btcusdt@bookTicker","event_type":"bookTicker","event_time_ms":1788580712125,"raw_json":"{\"stream\":\"btcusdt@bookTicker\",\"data\":{\"e\":\"bookTicker\",\"u\":11479473384477,\"s\":\"BTCUSDT\",\"ps\":\"BTCUSDT\",\"b\":\"79543.90\",\"B\":\"6.223\",\"a\":\"79544.00\",\"A\":\"5.393\",\"T\":1788580712124,\"E\":1788580712125,\"st\":1}}"}
{"receive_ns":1788580712171479000,"stream":"btcusdt@depth@100ms","event_type":"depthUpdate","event_time_ms":1788580712201,"raw_json":"{\"stream\":\"btcusdt@depth@100ms\",\"data\":{\"e\":\"depthUpdate\",\"E\":1788580712201,\"T\":1788580712198,\"s\":\"BTCUSDT\",\"ps\":\"BTCUSDT\",\"U\":11479473382933,\"u\":11479473388533,\"pu\":11479473382635,\"b\":[[\"1000.00\",\"25.354\"],[\"29243.90\",\"0.840\"],[\"29343.90\",\"1.260\"],[\"63635.10\",\"0.000\"],[\"71589.50\",\"0.014\"],[\"75566.70\",\"0.020\"],[\"75566.80\",\"0.004\"],[\"76362.10\",\"0.002\"],[\"78425.10\",\"26.127\"],[\"78499.70\",\"0.751\"],[\"78584.10\",\"21.452\"],[\"78611.70\",\"3.684\"],[\"78748.50\",\"8.242\"],[\"79456.40\",\"0.318\"],[\"79538.50\",\"0.070\"],[\"79538.90\",\"1.002\"],[\"79543.90\",\"6.223\"]],\"a\":[[\"79544.00\",\"5.393\"],[\"79620.30\",\"0.006\"],[\"79625.00\",\"0.078\"],[\"79625.60\",\"29.413\"],[\"79626.80\",\"0.054\"],[\"79628.30\",\"0.000\"],[\"79939.70\",\"0.136\"],[\"80339.40\",\"6.476\"],[\"80539.00\",\"1.232\"],[\"84049.60\",\"0.751\"]],\"st\":1}}"}
{"receive_ns":1788580712234484000,"stream":"btcusdt@bookTicker","event_type":"bookTicker","event_time_ms":1788580712280,"raw_json":"{\"stream\":\"btcusdt@bookTicker\",\"data\":{\"e\":\"bookTicker\",\"u\":11479473393053,\"s\":\"BTCUSDT\",\"ps\":\"BTCUSDT\",\"b\":\"79543.90\",\"B\":\"6.223\",\"a\":\"79544.00\",\"A\":\"5.353\",\"T\":1788580712280,\"E\":1788580712280,\"st\":1}}"}
{"receive_ns":1788580712235418000,"stream":"btcusdt@bookTicker","event_type":"bookTicker","event_time_ms":1788580712282,"raw_json":"{\"stream\":\"btcusdt@bookTicker\",\"data\":{\"e\":\"bookTicker\",\"u\":11479473393190,\"s\":\"BTCUSDT\",\"ps\":\"BTCUSDT\",\"b\":\"79543.90\",\"B\":\"6.223\",\"a\":\"79544.00\",\"A\":\"5.391\",\"T\":1788580712282,\"E\":1788580712282,\"st\":1}}"}
{"receive_ns":1788580712246871000,"stream":"btcusdt@depth@100ms","event_type":"depthUpdate","event_time_ms":1788580712303,"raw_json":"{\"stream\":\"btcusdt@depth@100ms\",\"data\":{\"e\":\"depthUpdate\",\"E\":1788580712303,\"T\":1788580712301,\"s\":\"BTCUSDT\",\"ps\":\"BTCUSDT\",\"U\":11479473388912,\"u\":11479473394084,\"pu\":11479473388533,\"b\":[[\"1000.00\",\"25.354\"],[\"29243.90\",\"1.022\"],[\"29343.90\",\"1.078\"],[\"71589.50\",\"0.014\"],[\"75566.70\",\"0.018\"],[\"75566.80\",\"0.006\"],[\"76362.10\",\"0.000\"],[\"78470.10\",\"3.854\"],[\"78584.10\",\"19.419\"],[\"78748.50\",\"8.242\"],[\"79419.70\",\"1.509\"],[\"79453.10\",\"0.000\"],[\"79456.40\",\"0.318\"],[\"79472.30\",\"0.378\"],[\"79474.60\",\"0.001\"],[\"79477.20\",\"22.935\"],[\"79488.20\",\"0.130\"]],\"a\":[[\"79544.00\",\"5.391\"],[\"79599.70\",\"0.052\"],[\"79615.60\",\"0.004\"],[\"79623.00\",\"29.222\"],[\"79625.60\",\"0.200\"],[\"79666.20\",\"0.000\"],[\"79936.40\",\"0.008\"],[\"79937.70\",\"0.022\"],[\"79939.70\",\"0.173\"],[\"80339.40\",\"6.476\"],[\"80538.30\",\"5.323\"]],\"st\":1}}"}
{"receive_ns":1788580712348175000,"stream":"btcusdt@bookTicker","event_type":"bookTicker","event_time_ms":1788580712352,"raw_json":"{\"stream\":\"btcusdt@bookTicker\",\"data\":{\"e\":\"bookTicker\",\"u\":11479473397040,\"s\":\"BTCUSDT\",\"ps\":\"BTCUSDT\",\"b\":\"79543.90\",\"B\":\"5.985\",\"a\":\"79544.00\",\"A\":\"5.391\",\"T\":1788580712352,\"E\":1788580712352,\"st\":1}}"}
{"receive_ns":1788580712348382000,"stream":"btcusdt@bookTicker","event_type":"bookTicker","event_time_ms":1788580712355,"raw_json":"{\"stream\":\"btcusdt@bookTicker\",\"data\":{\"e\":\"bookTicker\",\"u\":11479473397197,\"s\":\"BTCUSDT\",\"ps\":\"BTCUSDT\",\"b\":\"79543.90\",\"B\":\"6.218\",\"a\":\"79544.00\",\"A\":\"5.391\",\"T\":1788580712355,\"E\":1788580712355,\"st\":1}}"}
{"receive_ns":1788580712348581000,"stream":"btcusdt@bookTicker","event_type":"bookTicker","event_time_ms":1788580712356,"raw_json":"{\"stream\":\"btcusdt@bookTicker\",\"data\":{\"e\":\"bookTicker\",\"u\":11479473397262,\"s\":\"BTCUSDT\",\"ps\":\"BTCUSDT\",\"b\":\"79543.90\",\"B\":\"6.217\",\"a\":\"79544.00\",\"A\":\"5.391\",\"T\":1788580712356,\"E\":1788580712356,\"st\":1}}"}
{"receive_ns":1788580712350512000,"stream":"btcusdt@depth@100ms","event_type":"depthUpdate","event_time_ms":1788580712405,"raw_json":"{\"stream\":\"btcusdt@depth@100ms\",\"data\":{\"e\":\"depthUpdate\",\"E\":1788580712405,\"T\":1788580712401,\"s\":\"BTCUSDT\",\"ps\":\"BTCUSDT\",\"U\":11479473394174,\"u\":11479473399630,\"pu\":11479473394084,\"b\":[[\"29243.90\",\"1.197\"],[\"29343.90\",\"0.903\"],[\"63635.00\",\"0.000\"],[\"71589.50\",\"0.014\"],[\"76362.10\",\"0.002\"],[\"77953.10\",\"0.012\"],[\"78425.10\",\"24.217\"],[\"78430.30\",\"35.032\"],[\"78584.10\",\"18.148\"],[\"78589.40\",\"27.760\"],[\"78748.50\",\"8.242\"],[\"79146.20\",\"3.790\"],[\"79380.30\",\"0.022\"],[\"79380.40\",\"1.927\"],[\"79407.00\",\"0.015\"],[\"79415.30\",\"3.274\"],[\"79419.70\",\"1.955\"],[\"79453.10\",\"0.020\"],[\"79456.40\",\"0.318\"],[\"79474.60\",\"22.908\"],[\"79476.00\",\"4.373\"],[\"79477.20\",\"0.028\"],[\"79497.30\",\"0.007\"],[\"79517.30\",\"0.454\"],[\"79518.30\",\"0.018\"],[\"79520.20\",\"2.395\"],[\"79524.20\",\"2.521\"],[\"79524.80\",\"0.637\"],[\"79527.80\",\"0.225\"],[\"79528.40\",\"0.177\"],[\"79529.10\",\"0.669\"],[\"79543.90\",\"6.217\"]],\"a\":[[\"79560.10\",\"0.004\"],[\"79564.70\",\"0.002\"],[\"79565.30\",\"0.375\"],[\"79623.00\",\"0.009\"],[\"79625.60\",\"29.413\"],[\"79628.20\",\"0.501\"],[\"79628.30\",\"0.000\"],[\"79666.20\",\"0.404\"],[\"79705.60\",\"1.776\"],[\"79753.20\",\"1.470\"],[\"79753.30\",\"4.980\"],[\"79939.70\",\"0.173\"],[\"80280.40\",\"0.000\"],[\"80339.40\",\"6.476\"],[\"80539.10\",\"5.559\"]],\"st\":1}}"}
{"receive_ns":1788580712416887000,"stream":"btcusdt@bookTicker","event_type":"bookTicker","event_time_ms":1788580712461,"raw_json":"{\"stream\":\"btcusdt@bookTicker\",\"data\":{\"e\":\"bookTicker\",\"u\":11479473402472,\"s\":\"BTCUSDT\",\"ps\":\"BTCUSDT\",\"b\":\"79543.90\",\"B\":\"6.217\",\"a\":\"79544.00\",\"A\":\"5.343\",\"T\":1788580712461,\"E\":1788580712461,\"st\":1}}"}
{"receive_ns":1788580712417108000,"stream":"btcusdt@bookTicker","event_type":"bookTicker","event_time_ms":1788580712462,"raw_json":"{\"stream\":\"btcusdt@bookTicker\",\"data\":{\"e\":\"bookTicker\",\"u\":11479473402550,\"s\":\"BTCUSDT\",\"ps\":\"BTCUSDT\",\"b\":\"79543.90\",\"B\":\"6.218\",\"a\":\"79544.00\",\"A\":\"5.343\",\"T\":1788580712462,\"E\":1788580712462,\"st\":1}}"}
{"receive_ns":1788580712417263000,"stream":"btcusdt@bookTicker","event_type":"bookTicker","event_time_ms":1788580712464,"raw_json":"{\"stream\":\"btcusdt@bookTicker\",\"data\":{\"e\":\"bookTicker\",\"u\":11479473402621,\"s\":\"BTCUSDT\",\"ps\":\"BTCUSDT\",\"b\":\"79543.90\",\"B\":\"6.218\",\"a\":\"79544.00\",\"A\":\"5.330\",\"T\":1788580712463,\"E\":1788580712464,\"st\":1}}"}
{"receive_ns":1788580712417414000,"stream":"btcusdt@bookTicker","event_type":"bookTicker","event_time_ms":1788580712467,"raw_json":"{\"stream\":\"btcusdt@bookTicker\",\"data\":{\"e\":\"bookTicker\",\"u\":11479473402732,\"s\":\"BTCUSDT\",\"ps\":\"BTCUSDT\",\"b\":\"79543.90\",\"B\":\"6.218\",\"a\":\"79544.00\",\"A\":\"5.346\",\"T\":1788580712467,\"E\":1788580712467,\"st\":1}}"}
{"receive_ns":1788580712417588000,"stream":"btcusdt@bookTicker","event_type":"bookTicker","event_time_ms":1788580712470,"raw_json":"{\"stream\":\"btcusdt@bookTicker\",\"data\":{\"e\":\"bookTicker\",\"u\":11479473402825,\"s\":\"BTCUSDT\",\"ps\":\"BTCUSDT\",\"b\":\"79543.90\",\"B\":\"6.218\",\"a\":\"79544.00\",\"A\":\"5.395\",\"T\":1788580712469,\"E\":1788580712470,\"st\":1}}"}
{"receive_ns":1788580712472312000,"stream":"btcusdt@depth@100ms","event_type":"depthUpdate","event_time_ms":1788580712507,"raw_json":"{\"stream\":\"btcusdt@depth@100ms\",\"data\":{\"e\":\"depthUpdate\",\"E\":1788580712507,\"T\":1788580712505,\"s\":\"BTCUSDT\",\"ps\":\"BTCUSDT\",\"U\":11479473399919,\"u\":11479473404893,\"pu\":11479473399630,\"b\":[[\"1000.00\",\"25.354\"],[\"29243.90\",\"1.379\"],[\"29343.90\",\"0.721\"],[\"71589.50\",\"0.014\"],[\"76362.10\",\"0.000\"],[\"78204.00\",\"6.323\"],[\"78430.30\",\"36.942\"],[\"78483.30\",\"2.163\"],[\"78584.10\",\"16.877\"],[\"78589.40\",\"31.572\"],[\"78748.50\",\"8.242\"],[\"79098.90\",\"0.000\"],[\"79453.10\",\"0.000\"],[\"79456.40\",\"0.010\"],[\"79474.60\",\"0.001\"],[\"79476.00\",\"1.485\"],[\"79477.20\",\"22.935\"],[\"79528.40\",\"0.617\"],[\"79529.10\",\"0.229\"],[\"79537.60\",\"0.457\"],[\"79543.90\",\"6.218\"]],\"a\":[[\"79544.00\",\"5.395\"],[\"79936.40\",\"0.001\"],[\"79937.70\",\"0.004\"],[\"79939.70\",\"0.005\"],[\"80175.00\",\"0.012\"],[\"80339.40\",\"6.476\"],[\"80578.10\",\"4.837\"]],\"st\":1}}"}
{"receive_ns":1788580712487689000,"stream":"btcusdt@bookTicker","event_type":"bookTicker","event_time_ms":1788580712542,"raw_json":"{\"stream\":\"btcusdt@bookTicker\",\"data\":{\"e\":\"bookTicker\",\"u\":11479473406316,\"s\":\"BTCUSDT\",\"ps\":\"BTCUSDT\",\"b\":\"79543.90\",\"B\":\"6.218\",\"a\":\"79544.00\",\"A\":\"5.398\",\"T\":1788580712542,\"E\":1788580712542,\"st\":1}}"}
{"receive_ns":1788580712553255000,"stream":"btcusdt@bookTicker","event_type":"bookTicker","event_time_ms":1788580712555,"raw_json":"{\"stream\":\"btcusdt@bookTicker\",\"data\":{\"e\":\"bookTicker\",\"u\":11479473406990,\"s\":\"BTCUSDT\",\"ps\":\"BTCUSDT\",\"b\":\"79543.90\",\"B\":\"6.217\",\"a\":\"79544.00\",\"A\":\"5.398\",\"T\":1788580712555,\"E\":1788580712555,\"st\":1}}"}
{"receive_ns":1788580712553499000,"stream":"btcusdt@bookTicker","event_type":"bookTicker","event_time_ms":1788580712557,"raw_json":"{\"stream\":\"btcusdt@bookTicker\",\"data\":{\"e\":\"bookTicker\",\"u\":11479473407089,\"s\":\"BTCUSDT\",\"ps\":\"BTCUSDT\",\"b\":\"79543.90\",\"B\":\"6.218\",\"a\":\"79544.00\",\"A\":\"5.398\",\"T\":1788580712557,\"E\":1788580712557,\"st\":1}}"}
{"receive_ns":1788580712553793000,"stream":"btcusdt@depth@100ms","event_type":"depthUpdate","event_time_ms":1788580712609,"raw_json":"{\"stream\":\"btcusdt@depth@100ms\",\"data\":{\"e\":\"depthUpdate\",\"E\":1788580712609,\"T\":1788580712608,\"s\":\"BTCUSDT\",\"ps\":\"BTCUSDT\",\"U\":11479473404980,\"u\":11479473409306,\"pu\":11479473404893,\"b\":[[\"1000.00\",\"25.354\"],[\"29243.90\",\"1.554\"],[\"29343.90\",\"0.546\"],[\"63635.00\",\"0.002\"],[\"71589.50\",\"0.014\"],[\"78549.60\",\"7.891\"],[\"78589.40\",\"33.604\"],[\"78748.50\",\"8.242\"],[\"79146.80\",\"0.087\"],[\"79453.10\",\"0.020\"],[\"79456.40\",\"0.308\"],[\"79543.90\",\"6.218\"]],\"a\":[[\"79544.00\",\"5.398\"],[\"79933.80\",\"0.037\"],[\"79936.40\",\"0.008\"],[\"79937.70\",\"0.022\"],[\"79939.70\",\"0.131\"],[\"80339.40\",\"7.098\"],[\"80459.30\",\"0.738\"],[\"80459.50\",\"4.428\"],[\"80459.60\",\"9.606\"],[\"82095.00\",\"0.049\"]],\"st\":1}}"}
{"receive_ns":1788580712620630000,"stream":"btcusdt@bookTicker","event_type":"bookTicker","event_time_ms":1788580712672,"raw_json":"{\"stream\":\"btcusdt@bookTicker\",\"data\":{\"e\":\"bookTicker\",\"u\":11479473411768,\"s\":\"BTCUSDT\",\"ps\":\"BTCUSDT\",\"b\":\"79543.90\",\"B\":\"6.218\",\"a\":\"79544.00\",\"A\":\"5.397\",\"T\":1788580712671,\"E\":1788580712672,\"st\":1}}"}
{"receive_ns":1788580712620848000,"stream":"btcusdt@trade","event_type":"trade","event_time_ms":1788580712672,"raw_json":"{\"stream\":\"btcusdt@trade\",\"data\":{\"e\":\"trade\",\"E\":1788580712672,\"T\":1788580712671,\"s\":\"BTCUSDT\",\"t\":8054266672,\"p\":\"79544.00\",\"q\":\"0.001\",\"X\":\"MARKET\",\"m\":false,\"st\":1}}"}
{"receive_ns":1788580712627884000,"stream":"btcusdt@bookTicker","event_type":"bookTicker","event_time_ms":1788580712683,"raw_json":"{\"stream\":\"btcusdt@bookTicker\",\"data\":{\"e\":\"bookTicker\",\"u\":11479473412147,\"s\":\"BTCUSDT\",\"ps\":\"BTCUSDT\",\"b\":\"79543.90\",\"B\":\"6.085\",\"a\":\"79544.00\",\"A\":\"5.397\",\"T\":1788580712683,\"E\":1788580712683,\"st\":1}}"}
{"receive_ns":1788580712630541000,"stream":"btcusdt@bookTicker","event_type":"bookTicker","event_time_ms":1788580712686,"raw_json":"{\"stream\":\"btcusdt@bookTicker\",\"data\":{\"e\":\"bookTicker\",\"u\":11479473412249,\"s\":\"BTCUSDT\",\"ps\":\"BTCUSDT\",\"b\":\"79543.90\",\"B\":\"6.265\",\"a\":\"79544.00\",\"A\":\"5.397\",\"T\":1788580712685,\"E\":1788580712686,\"st\":1}}"}
{"receive_ns":1788580712637224000,"stream":"btcusdt@bookTicker","event_type":"bookTicker","event_time_ms":1788580712687,"raw_json":"{\"stream\":\"btcusdt@bookTicker\",\"data\":{\"e\":\"bookTicker\",\"u\":11479473412286,\"s\":\"BTCUSDT\",\"ps\":\"BTCUSDT\",\"b\":\"79543.90\",\"B\":\"6.265\",\"a\":\"79544.00\",\"A\":\"5.395\",\"T\":1788580712687,\"E\":1788580712687,\"st\":1}}"}
{"receive_ns":1788580712680782000,"stream":"btcusdt@depth@100ms","event_type":"depthUpdate","event_time_ms":1788580712711,"raw_json":"{\"stream\":\"btcusdt@depth@100ms\",\"data\":{\"e\":\"depthUpdate\",\"E\":1788580712711,\"T\":1788580712710,\"s\":\"BTCUSDT\",\"ps\":\"BTCUSDT\",\"U\":11479473409354,\"u\":11479473413080,\"pu\":11479473409306,\"b\":[[\"29243.90\",\"1.736\"],[\"29343.90\",\"0.364\"],[\"63635.00\",\"0.000\"],[\"71589.50\",\"0.014\"],[\"75561.60\",\"0.010\"],[\"76362.10\",\"0.002\"],[\"78748.50\",\"8.242\"],[\"79146.10\",\"0.008\"],[\"79146.20\",\"3.790\"],[\"79419.70\",\"1.509\"],[\"79456.40\",\"0.318\"],[\"79517.30\",\"0.002\"],[\"79518.80\",\"0.454\"],[\"79543.90\",\"6.265\"]],\"a\":[[\"79544.00\",\"5.395\"],[\"79557.20\",\"0.260\"],[\"79567.80\",\"0.002\"],[\"79568.20\",\"0.453\"],[\"79620.90\",\"0.000\"],[\"79666.20\",\"0.000\"],[\"79939.70\",\"0.136\"],[\"79941.70\",\"2.498\"],[\"79941.80\",\"0.000\"],[\"80180.40\",\"7.092\"],[\"80339.40\",\"7.098\"]],\"st\":1}}"}
{"receive_ns":1788580712762642000,"stream":"btcusdt@depth@100ms","event_type":"depthUpdate","event_time_ms":1788580712813,"raw_json":"{\"stream\":\"btcusdt@depth@100ms\",\"data\":{\"e\":\"depthUpdate\",\"E\":1788580712813,\"T\":1788580712812,\"s\":\"BTCUSDT\",\"ps\":\"BTCUSDT\",\"U\":11479473413167,\"u\":11479473417482,\"pu\":11479473413080,\"b\":[[\"1000.00\",\"25.354\"],[\"29143.90\",\"0.056\"],[\"29243.90\",\"1.799\"],[\"29343.90\",\"0.245\"],[\"71589.50\",\"0.014\"],[\"71623.00\",\"0.000\"],[\"76362.10\",\"0.000\"],[\"78425.10\",\"22.308\"],[\"78462.40\",\"0.063\"],[\"78571.90\",\"0.641\"],[\"78584.10\",\"15.606\"],[\"78748.50\",\"8.242\"],[\"79060.90\",\"0.001\"],[\"79146.10\",\"0.009\"],[\"79419.80\",\"0.988\"],[\"79453.10\",\"0.020\"],[\"79456.40\",\"0.318\"],[\"79518.50\",\"0.454\"],[\"79518.80\",\"0.002\"],[\"79519.80\",\"0.000\"],[\"79520.70\",\"0.012\"],[\"79524.20\",\"2.148\"],[\"79525.10\",\"0.410\"],[\"79526.30\",\"0.003\"],[\"79528.40\",\"0.177\"],[\"79528.50\",\"0.440\"],[\"79529.40\",\"0.468\"],[\"79529.50\",\"0.003\"],[\"79529.60\",\"0.008\"],[\"79529.70\",\"0.787\"],[\"79533.50\",\"0.075\"]],\"a\":[[\"79564.80\",\"0.441\"],[\"79564.90\",\"0.002\"],[\"79565.30\",\"0.002\"],[\"79566.20\",\"0.430\"],[\"79567.40\",\"0.000\"],[\"79568.20\",\"0.001\"],[\"79569.20\",\"0.457\"],[\"79613.30\",\"0.075\"],[\"79666.20\",\"0.435\"],[\"79933.80\",\"0.000\"],[\"79936.40\",\"0.008\"],[\"79937.70\",\"0.059\"],[\"79939.70\",\"0.136\"],[\"79941.80\",\"0.001\"],[\"80339.40\",\"7.098\"],[\"80419.00\",\"2.731\"],[\"80631.40\",\"0.530\"],[\"80711.00\",\"0.745\"],[\"87498.40\",\"0.009\"]],\"st\":1}}"}
{"receive_ns":1788580712864431000,"stream":"btcusdt@depth@100ms","event_type":"depthUpdate","event_time_ms":1788580712915,"raw_json":"{\"stream\":\"btcusdt@depth@100ms\",\"data\":{\"e\":\"depthUpdate\",\"E\":1788580712915,\"T\":1788580712913,\"s\":\"BTCUSDT\",\"ps\":\"BTCUSDT\",\"U\":11479473417526,\"u\":11479473423469,\"pu\":11479473417482,\"b\":[[\"1000.00\",\"25.354\"],[\"29143.90\",\"0.112\"],[\"29243.90\",\"1.869\"],[\"29343.90\",\"0.119\"],[\"63635.00\",\"0.000\"],[\"71589.50\",\"0.014\"],[\"75566.80\",\"0.004\"],[\"76362.10\",\"0.002\"],[\"77953.10\",\"0.015\"],[\"78549.60\",\"8.527\"],[\"78748.50\",\"8.242\"],[\"78902.30\",\"0.253\"],[\"79419.80\",\"0.988\"],[\"79456.40\",\"0.318\"],[\"79474.60\",\"22.908\"],[\"79477.20\",\"0.028\"],[\"79529.60\",\"0.002\"],[\"79533.50\",\"0.081\"]],\"a\":[[\"79666.20\",\"0.435\"],[\"79939.70\",\"0.136\"],[\"80266.20\",\"0.207\"],[\"80339.40\",\"7.098\"],[\"80459.50\",\"3.690\"],[\"80459.60\",\"12.593\"]],\"st\":1}}"}
{"receive_ns":1788580712984301000,"stream":"btcusdt@depth@100ms","event_type":"depthUpdate","event_time_ms":1788580713017,"raw_json":"{\"stream\":\"btcusdt@depth@100ms\",\"data\":{\"e\":\"depthUpdate\",\"E\":1788580713017,\"T\":1788580713014,\"s\":\"BTCUSDT\",\"ps\":\"BTCUSDT\",\"U\":11479473423629,\"u\":11479473428882,\"pu\":11479473423469,\"b\":[[\"29143.90\",\"0.182\"],[\"29243.90\",\"1.904\"],[\"29343.90\",\"0.014\"],[\"63635.00\",\"0.000\"],[\"71589.50\",\"0.014\"],[\"78425.10\",\"20.399\"],[\"78452.60\",\"1.910\"],[\"78611.70\",\"2.413\"],[\"78748.50\",\"8.242\"],[\"79146.20\",\"3.790\"],[\"79399.60\",\"1.886\"],[\"79399.70\",\"0.000\"],[\"79453.10\",\"0.020\"],[\"79456.40\",\"0.085\"],[\"79473.90\",\"0.050\"],[\"79499.80\",\"0.073\"],[\"79536.10\",\"0.006\"],[\"79538.70\",\"0.107\"],[\"79538.90\",\"1.000\"]],\"a\":[[\"79554.00\",\"0.803\"],[\"79554.90\",\"0.074\"],[\"79564.90\",\"0.375\"],[\"79566.20\",\"0.057\"],[\"79667.80\",\"1.886\"],[\"79667.90\",\"0.000\"],[\"79933.80\",\"0.037\"],[\"79936.40\",\"0.008\"],[\"79937.70\",\"0.004\"],[\"79939.70\",\"0.019\"],[\"80339.40\",\"7.098\"],[\"80888.30\",\"1.604\"],[\"81134.80\",\"0.015\"]],\"st\":1}}"}
{"receive_ns":1788580713062322000,"stream":"btcusdt@depth@100ms","event_type":"depthUpdate","event_time_ms":1788580713119,"raw_json":"{\"stream\":\"btcusdt@depth@100ms\",\"data\":{\"e\":\"depthUpdate\",\"E\":1788580713119,\"T\":1788580713118,\"s\":\"BTCUSDT\",\"ps\":\"BTCUSDT\",\"U\":11479473429094,\"u\":11479473435219,\"pu\":11479473428882,\"b\":[[\"1000.00\",\"25.354\"],[\"29143.90\",\"0.350\"],[\"29243.90\",\"1.750\"],[\"29343.90\",\"0.000\"],[\"63635.00\",\"0.000\"],[\"71589.50\",\"0.014\"],[\"76362.10\",\"0.000\"],[\"78430.30\",\"39.488\"],[\"78589.40\",\"34.875\"],[\"78748.50\",\"8.369\"],[\"78907.50\",\"7.712\"],[\"79456.40\",\"0.318\"],[\"79474.60\",\"22.845\"],[\"79477.20\",\"0.028\"],[\"79529.60\",\"0.002\"]],\"a\":[[\"79623.00\",\"0.009\"],[\"79625.60\",\"0.200\"],[\"79628.30\",\"28.918\"],[\"79937.70\",\"0.022\"],[\"79939.70\",\"0.136\"],[\"80259.90\",\"4.497\"],[\"80312.30\",\"0.000\"],[\"80339.40\",\"7.098\"],[\"80617.80\",\"3.503\"],[\"80697.40\",\"13.176\"]],\"st\":1}}"}
{"receive_ns":1788580713063421000,"stream":"btcusdt@bookTicker","event_type":"bookTicker","event_time_ms":1788580713121,"raw_json":"{\"stream\":\"btcusdt@bookTicker\",\"data\":{\"e\":\"bookTicker\",\"u\":11479473435409,\"s\":\"BTCUSDT\",\"ps\":\"BTCUSDT\",\"b\":\"79543.90\",\"B\":\"6.265\",\"a\":\"79544.00\",\"A\":\"5.377\",\"T\":1788580713121,\"E\":1788580713121,\"st\":1}}"}
{"receive_ns":1788580713102777000,"stream":"btcusdt@bookTicker","event_type":"bookTicker","event_time_ms":1788580713124,"raw_json":"{\"stream\":\"btcusdt@bookTicker\",\"data\":{\"e\":\"bookTicker\",\"u\":11479473435818,\"s\":\"BTCUSDT\",\"ps\":\"BTCUSDT\",\"b\":\"79543.90\",\"B\":\"6.265\",\"a\":\"79544.00\",\"A\":\"5.394\",\"T\":1788580713124,\"E\":1788580713124,\"st\":1}}"}
{"receive_ns":1788580713102988000,"stream":"btcusdt@bookTicker","event_type":"bookTicker","event_time_ms":1788580713125,"raw_json":"{\"stream\":\"btcusdt@bookTicker\",\"data\":{\"e\":\"bookTicker\",\"u\":11479473435912,\"s\":\"BTCUSDT\",\"ps\":\"BTCUSDT\",\"b\":\"79543.90\",\"B\":\"6.265\",\"a\":\"79544.00\",\"A\":\"5.396\",\"T\":1788580713125,\"E\":1788580713125,\"st\":1}}"}
{"receive_ns":1788580713103134000,"stream":"btcusdt@bookTicker","event_type":"bookTicker","event_time_ms":1788580713154,"raw_json":"{\"stream\":\"btcusdt@bookTicker\",\"data\":{\"e\":\"bookTicker\",\"u\":11479473437519,\"s\":\"BTCUSDT\",\"ps\":\"BTCUSDT\",\"b\":\"79543.90\",\"B\":\"6.265\",\"a\":\"79544.00\",\"A\":\"5.380\",\"T\":1788580713154,\"E\":1788580713154,\"st\":1}}"}
{"receive_ns":1788580713103318000,"stream":"btcusdt@bookTicker","event_type":"bookTicker","event_time_ms":1788580713156,"raw_json":"{\"stream\":\"btcusdt@bookTicker\",\"data\":{\"e\":\"bookTicker\",\"u\":11479473437700,\"s\":\"BTCUSDT\",\"ps\":\"BTCUSDT\",\"b\":\"79543.90\",\"B\":\"6.265\",\"a\":\"79544.00\",\"A\":\"5.397\",\"T\":1788580713156,\"E\":1788580713156,\"st\":1}}"}
{"receive_ns":1788580713107755000,"stream":"btcusdt@bookTicker","event_type":"bookTicker","event_time_ms":1788580713164,"raw_json":"{\"stream\":\"btcusdt@bookTicker\",\"data\":{\"e\":\"bookTicker\",\"u\":11479473438088,\"s\":\"BTCUSDT\",\"ps\":\"BTCUSDT\",\"b\":\"79543.90\",\"B\":\"6.264\",\"a\":\"79544.00\",\"A\":\"5.397\",\"T\":1788580713164,\"E\":1788580713164,\"st\":1}}"}
{"receive_ns":1788580713109074000,"stream":"btcusdt@bookTicker","event_type":"bookTicker","event_time_ms":1788580713166,"raw_json":"{\"stream\":\"btcusdt@bookTicker\",\"data\":{\"e\":\"bookTicker\",\"u\":11479473438186,\"s\":\"BTCUSDT\",\"ps\":\"BTCUSDT\",\"b\":\"79543.90\",\"B\":\"6.265\",\"a\":\"79544.00\",\"A\":\"5.397\",\"T\":1788580713165,\"E\":1788580713166,\"st\":1}}"}
{"receive_ns":1788580713164406000,"stream":"btcusdt@depth@100ms","event_type":"depthUpdate","event_time_ms":1788580713221,"raw_json":"{\"stream\":\"btcusdt@depth@100ms\",\"data\":{\"e\":\"depthUpdate\",\"E\":1788580713221,\"T\":1788580713217,\"s\":\"BTCUSDT\",\"ps\":\"BTCUSDT\",\"U\":11479473435362,\"u\":11479473441409,\"pu\":11479473435219,\"b\":[[\"29143.90\",\"0.525\"],[\"29243.90\",\"1.575\"],[\"63635.10\",\"0.000\"],[\"71589.50\",\"0.014\"],[\"76362.10\",\"0.002\"],[\"78589.40\",\"36.146\"],[\"78748.50\",\"8.369\"],[\"79503.00\",\"0.699\"],[\"79543.90\",\"6.265\"]],\"a\":[[\"79544.00\",\"5.397\"],[\"79554.00\",\"0.801\"],[\"80180.30\",\"0.000\"],[\"80260.00\",\"4.934\"],[\"80339.40\",\"8.341\"],[\"80591.40\",\"1.239\"]],\"st\":1}}"}
{"receive_ns":1788580713238225000,"stream":"btcusdt@bookTicker","event_type":"bookTicker","event_time_ms":1788580713293,"raw_json":"{\"stream\":\"btcusdt@bookTicker\",\"data\":{\"e\":\"bookTicker\",\"u\":11479473445476,\"s\":\"BTCUSDT\",\"ps\":\"BTCUSDT\",\"b\":\"79543.90\",\"B\":\"6.265\",\"a\":\"79544.00\",\"A\":\"5.359\",\"T\":1788580713293,\"E\":1788580713293,\"st\":1}}"}
{"receive_ns":1788580713239606000,"stream":"btcusdt@bookTicker","event_type":"bookTicker","event_time_ms":1788580713296,"raw_json":"{\"stream\":\"btcusdt@bookTicker\",\"data\":{\"e\":\"bookTicker\",\"u\":11479473445589,\"s\":\"BTCUSDT\",\"ps\":\"BTCUSDT\",\"b\":\"79543.90\",\"B\":\"6.265\",\"a\":\"79544.00\",\"A\":\"5.398\",\"T\":1788580713296,\"E\":1788580713296,\"st\":1}}"}
{"receive_ns":1788580713288014000,"stream":"btcusdt@depth@100ms","event_type":"depthUpdate","event_time_ms":1788580713323,"raw_json":"{\"stream\":\"btcusdt@depth@100ms\",\"data\":{\"e\":\"depthUpdate\",\"E\":1788580713323,\"T\":1788580713321,\"s\":\"BTCUSDT\",\"ps\":\"BTCUSDT\",\"U\":11479473441627,\"u\":11479473446784,\"pu\":11479473441409,\"b\":[[\"29143.90\",\"0.707\"],[\"29243.90\",\"1.393\"],[\"71589.50\",\"0.014\"],[\"76362.10\",\"0.000\"],[\"77985.00\",\"0.033\"],[\"78430.30\",\"41.397\"],[\"78470.10\",\"4.489\"],[\"78748.50\",\"8.369\"],[\"79146.20\",\"3.790\"],[\"79380.40\",\"1.353\"],[\"79419.80\",\"0.851\"],[\"79452.20\",\"0.380\"],[\"79453.10\",\"0.020\"],[\"79456.40\",\"0.318\"],[\"79473.90\",\"0.038\"]],\"a\":[[\"79544.00\",\"5.398\"],[\"79558.40\",\"0.001\"],[\"79559.40\",\"0.704\"],[\"79625.60\",\"29.118\"],[\"79628.30\",\"0.000\"],[\"79635.00\",\"0.201\"],[\"79666.20\",\"0.306\"],[\"79668.10\",\"0.013\"],[\"79705.60\",\"1.295\"],[\"79933.80\",\"0.000\"],[\"79936.40\",\"0.008\"],[\"79937.70\",\"0.059\"],[\"79939.70\",\"0.136\"],[\"80299.70\",\"4.598\"],[\"80339.40\",\"8.341\"],[\"80657.60\",\"33.499\"]],\"st\":1}}"}
{"receive_ns":1788580713400356000,"stream":"btcusdt@depth@100ms","event_type":"depthUpdate","event_time_ms":1788580713425,"raw_json":"{\"stream\":\"btcusdt@depth@100ms\",\"data\":{\"e\":\"depthUpdate\",\"E\":1788580713425,\"T\":1788580713421,\"s\":\"BTCUSDT\",\"ps\":\"BTCUSDT\",\"U\":11479473446886,\"u\":11479473452357,\"pu\":11479473446784,\"b\":[[\"1000.00\",\"25.354\"],[\"29143.90\",\"0.882\"],[\"29243.90\",\"1.218\"],[\"71589.50\",\"0.014\"],[\"75566.70\",\"0.014\"],[\"75566.80\",\"0.008\"],[\"76362.10\",\"0.002\"],[\"78414.40\",\"0.459\"],[\"78748.40\",\"0.001\"],[\"78748.50\",\"8.369\"],[\"78834.00\",\"0.047\"],[\"78888.00\",\"46.218\"],[\"78942.10\",\"0.000\"],[\"79452.10\",\"6.082\"],[\"79456.40\",\"0.318\"],[\"79476.00\",\"4.360\"],[\"79520.20\",\"2.393\"]],\"a\":[[\"79560.10\",\"0.002\"],[\"79624.70\",\"4.785\"],[\"79634.80\",\"4.012\"],[\"79668.10\",\"0.007\"],[\"79765.50\",\"19.406\"],[\"79765.60\",\"0.000\"],[\"79939.70\",\"0.131\"],[\"79941.60\",\"0.000\"],[\"79941.70\",\"2.503\"],[\"80339.40\",\"8.341\"],[\"81134.80\",\"0.012\"]],\"st\":1}}"}
{"receive_ns":1788580713425243000,"stream":"btcusdt@bookTicker","event_type":"bookTicker","event_time_ms":1788580713480,"raw_json":"{\"stream\":\"btcusdt@bookTicker\",\"data\":{\"e\":\"bookTicker\",\"u\":11479473455083,\"s\":\"BTCUSDT\",\"ps\":\"BTCUSDT\",\"b\":\"79543.90\",\"B\":\"6.265\",\"a\":\"79544.00\",\"A\":\"5.349\",\"T\":1788580713480,\"E\":1788580713480,\"st\":1}}"}
{"receive_ns":1788580713426317000,"stream":"btcusdt@bookTicker","event_type":"bookTicker","event_time_ms":1788580713483,"raw_json":"{\"stream\":\"btcusdt@bookTicker\",\"data\":{\"e\":\"bookTicker\",\"u\":11479473455322,\"s\":\"BTCUSDT\",\"ps\":\"BTCUSDT\",\"b\":\"79543.90\",\"B\":\"6.265\",\"a\":\"79544.00\",\"A\":\"5.396\",\"T\":1788580713483,\"E\":1788580713483,\"st\":1}}"}
{"receive_ns":1788580713469133000,"stream":"btcusdt@bookTicker","event_type":"bookTicker","event_time_ms":1788580713499,"raw_json":"{\"stream\":\"btcusdt@bookTicker\",\"data\":{\"e\":\"bookTicker\",\"u\":11479473456576,\"s\":\"BTCUSDT\",\"ps\":\"BTCUSDT\",\"b\":\"79543.90\",\"B\":\"6.160\",\"a\":\"79544.00\",\"A\":\"5.396\",\"T\":1788580713499,\"E\":1788580713499,\"st\":1}}"}
{"receive_ns":1788580713469446000,"stream":"btcusdt@bookTicker","event_type":"bookTicker","event_time_ms":1788580713501,"raw_json":"{\"stream\":\"btcusdt@bookTicker\",\"data\":{\"e\":\"bookTicker\",\"u\":11479473456686,\"s\":\"BTCUSDT\",\"ps\":\"BTCUSDT\",\"b\":\"79543.90\",\"B\":\"6.159\",\"a\":\"79544.00\",\"A\":\"5.396\",\"T\":1788580713500,\"E\":1788580713501,\"st\":1}}"}
{"receive_ns":1788580713469661000,"stream":"btcusdt@bookTicker","event_type":"bookTicker","event_time_ms":1788580713502,"raw_json":"{\"stream\":\"btcusdt@bookTicker\",\"data\":{\"e\":\"bookTicker\",\"u\":11479473456758,\"s\":\"BTCUSDT\",\"ps\":\"BTCUSDT\",\"b\":\"79543.90\",\"B\":\"6.160\",\"a\":\"79544.00\",\"A\":\"5.396\",\"T\":1788580713501,\"E\":1788580713502,\"st\":1}}"}
{"receive_ns":1788580713469791000,"stream":"btcusdt@bookTicker","event_type":"bookTicker","event_time_ms":1788580713502,"raw_json":"{\"stream\":\"btcusdt@bookTicker\",\"data\":{\"e\":\"bookTicker\",\"u\":11479473456791,\"s\":\"BTCUSDT\",\"ps\":\"BTCUSDT\",\"b\":\"79543.90\",\"B\":\"6.279\",\"a\":\"79544.00\",\"A\":\"5.396\",\"T\":1788580713502,\"E\":1788580713502,\"st\":1}}"}
{"receive_ns":1788580713471132000,"stream":"btcusdt@depth@100ms","event_type":"depthUpdate","event_time_ms":1788580713527,"raw_json":"{\"stream\":\"btcusdt@depth@100ms\",\"data\":{\"e\":\"depthUpdate\",\"E\":1788580713527,\"T\":1788580713526,\"s\":\"BTCUSDT\",\"ps\":\"BTCUSDT\",\"U\":11479473452609,\"u\":11479473458278,\"pu\":11479473452357,\"b\":[[\"29143.90\",\"1.057\"],[\"29243.90\",\"1.043\"],[\"71589.50\",\"0.014\"],[\"78452.60\",\"0.000\"],[\"78748.50\",\"8.371\"],[\"79452.10\",\"3.146\"],[\"79453.10\",\"0.020\"],[\"79456.40\",\"0.173\"],[\"79472.30\",\"0.378\"],[\"79488.20\",\"0.128\"],[\"79499.70\",\"0.370\"],[\"79520.20\",\"2.395\"],[\"79543.90\",\"6.279\"]],\"a\":[[\"79544.00\",\"5.396\"],[\"79560.10\",\"0.004\"],[\"79599.70\",\"0.050\"],[\"79615.60\",\"0.004\"],[\"79634.80\",\"0.001\"],[\"79933.80\",\"0.037\"],[\"79936.40\",\"0.008\"],[\"79937.70\",\"0.004\"],[\"79939.70\",\"0.000\"],[\"79941.70\",\"2.566\"],[\"80140.60\",\"3.739\"],[\"80273.10\",\"0.000\"],[\"80339.40\",\"8.341\"],[\"80498.40\",\"1.241\"],[\"80657.50\",\"0.248\"]],\"st\":1}}"}
{"receive_ns":1788580713539429000,"stream":"btcusdt@bookTicker","event_type":"bookTicker","event_time_ms":1788580713590,"raw_json":"{\"stream\":\"btcusdt@bookTicker\",\"data\":{\"e\":\"bookTicker\",\"u\":11479473460813,\"s\":\"BTCUSDT\",\"ps\":\"BTCUSDT\",\"b\":\"79543.90\",\"B\":\"6.152\",\"a\":\"79544.00\",\"A\":\"5.396\",\"T\":1788580713590,\"E\":1788580713590,\"st\":1}}"}
{"receive_ns":1788580713539628000,"stream":"btcusdt@trade","event_type":"trade","event_time_ms":1788580713590,"raw_json":"{\"stream\":\"btcusdt@trade\",\"data\":{\"e\":\"trade\",\"E\":1788580713590,\"T\":1788580713590,\"s\":\"BTCUSDT\",\"t\":8054266673,\"p\":\"79543.90\",\"q\":\"0.127\",\"X\":\"MARKET\",\"m\":true,\"st\":1}}"}
{"receive_ns":1788580713603969000,"stream":"btcusdt@bookTicker","event_type":"bookTicker","event_time_ms":1788580713625,"raw_json":"{\"stream\":\"btcusdt@bookTicker\",\"data\":{\"e\":\"bookTicker\",\"u\":11479473462647,\"s\":\"BTCUSDT\",\"ps\":\"BTCUSDT\",\"b\":\"79543.90\",\"B\":\"6.152\",\"a\":\"79544.00\",\"A\":\"5.986\",\"T\":1788580713624,\"E\":1788580713625,\"st\":1}}"}
{"receive_ns":1788580713604165000,"stream":"btcusdt@bookTicker","event_type":"bookTicker","event_time_ms":1788580713626,"raw_json":"{\"stream\":\"btcusdt@bookTicker\",\"data\":{\"e\":\"bookTicker\",\"u\":11479473462718,\"s\":\"BTCUSDT\",\"ps\":\"BTCUSDT\",\"b\":\"79543.90\",\"B\":\"6.152\",\"a\":\"79544.00\",\"A\":\"5.984\",\"T\":1788580713626,\"E\":1788580713626,\"st\":1}}"}
{"receive_ns":1788580713604434000,"stream":"btcusdt@depth@100ms","event_type":"depthUpdate","event_time_ms":1788580713629,"raw_json":"{\"stream\":\"btcusdt@depth@100ms\",\"data\":{\"e\":\"depthUpdate\",\"E\":1788580713629,\"T\":1788580713628,\"s\":\"BTCUSDT\",\"ps\":\"BTCUSDT\",\"U\":11479473458295,\"u\":11479473462893,\"pu\":11479473458278,\"b\":[[\"29143.90\",\"1.239\"],[\"29243.90\",\"0.861\"],[\"71589.50\",\"0.014\"],[\"76362.10\",\"0.000\"],[\"77953.00\",\"6.288\"],[\"78689.20\",\"0.573\"],[\"78748.50\",\"8.369\"],[\"79146.20\",\"3.780\"],[\"79343.30\",\"0.113\"],[\"79452.10\",\"6.077\"],[\"79456.40\",\"0.318\"],[\"79486.70\",\"0.000\"],[\"79521.40\",\"0.057\"],[\"79526.00\",\"0.082\"],[\"79526.70\",\"0.106\"],[\"79543.90\",\"6.152\"]],\"a\":[[\"79544.00\",\"5.984\"],[\"79556.10\",\"0.634\"],[\"79557.00\",\"0.106\"],[\"79593.80\",\"0.265\"],[\"79602.10\",\"0.000\"],[\"79634.80\",\"4.012\"],[\"79765.40\",\"19.485\"],[\"79765.50\",\"0.029\"],[\"79937.70\",\"0.022\"],[\"79939.70\",\"0.005\"],[\"79941.70\",\"4.502\"],[\"80339.40\",\"8.341\"]],\"st\":1}}"}
{"receive_ns":1788580713604600000,"stream":"btcusdt@bookTicker","event_type":"bookTicker","event_time_ms":1788580713631,"raw_json":"{\"stream\":\"btcusdt@bookTicker\",\"data\":{\"e\":\"bookTicker\",\"u\":11479473462983,\"s\":\"BTCUSDT\",\"ps\":\"BTCUSDT\",\"b\":\"79543.90\",\"B\":\"6.152\",\"a\":\"79544.00\",\"A\":\"5.983\",\"T\":1788580713631,\"E\":1788580713631,\"st\":1}}"}
{"receive_ns":1788580713604732000,"stream":"btcusdt@trade","event_type":"trade","event_time_ms":1788580713631,"raw_json":"{\"stream\":\"btcusdt@trade\",\"data\":{\"e\":\"trade\",\"E\":1788580713631,\"T\":1788580713631,\"s\":\"BTCUSDT\",\"t\":8054266674,\"p\":\"79544.00\",\"q\":\"0.001\",\"X\":\"MARKET\",\"m\":false,\"st\":1}}"}
{"receive_ns":1788580713604872000,"stream":"btcusdt@bookTicker","event_type":"bookTicker","event_time_ms":1788580713636,"raw_json":"{\"stream\":\"btcusdt@bookTicker\",\"data\":{\"e\":\"bookTicker\",\"u\":11479473463223,\"s\":\"BTCUSDT\",\"ps\":\"BTCUSDT\",\"b\":\"79543.90\",\"B\":\"6.152\",\"a\":\"79544.00\",\"A\":\"5.980\",\"T\":1788580713636,\"E\":1788580713636,\"st\":1}}"}
{"receive_ns":1788580713605003000,"stream":"btcusdt@bookTicker","event_type":"bookTicker","event_time_ms":1788580713642,"raw_json":"{\"stream\":\"btcusdt@bookTicker\",\"data\":{\"e\":\"bookTicker\",\"u\":11479473463457,\"s\":\"BTCUSDT\",\"ps\":\"BTCUSDT\",\"b\":\"79543.90\",\"B\":\"6.151\",\"a\":\"79544.00\",\"A\":\"5.980\",\"T\":1788580713641,\"E\":1788580713642,\"st\":1}}"}
{"receive_ns":1788580713605172000,"stream":"btcusdt@bookTicker","event_type":"bookTicker","event_time_ms":1788580713644,"raw_json":"{\"stream\":\"btcusdt@bookTicker\",\"data\":{\"e\":\"bookTicker\",\"u\":11479473463528,\"s\":\"BTCUSDT\",\"ps\":\"BTCUSDT\",\"b\":\"79543.90\",\"B\":\"6.152\",\"a\":\"79544.00\",\"A\":\"5.980\",\"T\":1788580713643,\"E\":1788580713644,\"st\":1}}"}
{"receive_ns":1788580713611777000,"stream":"btcusdt@bookTicker","event_type":"bookTicker","event_time_ms":1788580713660,"raw_json":"{\"stream\":\"btcusdt@bookTicker\",\"data\":{\"e\":\"bookTicker\",\"u\":11479473464200,\"s\":\"BTCUSDT\",\"ps\":\"BTCUSDT\",\"b\":\"79543.90\",\"B\":\"5.972\",\"a\":\"79544.00\",\"A\":\"5.980\",\"T\":1788580713660,\"E\":1788580713660,\"st\":1}}"}
{"receive_ns":1788580713612381000,"stream":"btcusdt@bookTicker","event_type":"bookTicker","event_time_ms":1788580713662,"raw_json":"{\"stream\":\"btcusdt@bookTicker\",\"data\":{\"e\":\"bookTicker\",\"u\":11479473464332,\"s\":\"BTCUSDT\",\"ps\":\"BTCUSDT\",\"b\":\"79543.90\",\"B\":\"6.151\",\"a\":\"79544.00\",\"A\":\"5.980\",\"T\":1788580713662,\"E\":1788580713662,\"st\":1}}"}
{"receive_ns":1788580713612560000,"stream":"btcusdt@bookTicker","event_type":"bookTicker","event_time_ms":1788580713663,"raw_json":"{\"stream\":\"btcusdt@bookTicker\",\"data\":{\"e\":\"bookTicker\",\"u\":11479473464374,\"s\":\"BTCUSDT\",\"ps\":\"BTCUSDT\",\"b\":\"79543.90\",\"B\":\"6.151\",\"a\":\"79544.00\",\"A\":\"5.982\",\"T\":1788580713663,\"E\":1788580713663,\"st\":1}}"}
{"receive_ns":1788580713662356000,"stream":"btcusdt@bookTicker","event_type":"bookTicker","event_time_ms":1788580713698,"raw_json":"{\"stream\":\"btcusdt@bookTicker\",\"data\":{\"e\":\"bookTicker\",\"u\":11479473465940,\"s\":\"BTCUSDT\",\"ps\":\"BTCUSDT\",\"b\":\"79543.90\",\"B\":\"4.531\",\"a\":\"79544.00\",\"A\":\"5.982\",\"T\":1788580713698,\"E\":1788580713698,\"st\":1}}"}
{"receive_ns":1788580713674532000,"stream":"btcusdt@depth@100ms","event_type":"depthUpdate","event_time_ms":1788580713731,"raw_json":"{\"stream\":\"btcusdt@depth@100ms\",\"data\":{\"e\":\"depthUpdate\",\"E\":1788580713731,\"T\":1788580713729,\"s\":\"BTCUSDT\",\"ps\":\"BTCUSDT\",\"U\":11479473462939,\"u\":11479473467765,\"pu\":11479473462893,\"b\":[[\"1000.00\",\"25.354\"],[\"29143.90\",\"1.421\"],[\"29243.90\",\"0.679\"],[\"71589.50\",\"0.014\"],[\"75566.70\",\"0.019\"],[\"76362.10\",\"0.002\"],[\"78589.40\",\"37.417\"],[\"78748.50\",\"8.369\"],[\"79453.10\",\"0.000\"],[\"79456.40\",\"0.243\"],[\"79474.60\",\"0.001\"],[\"79476.00\",\"1.485\"],[\"79477.20\",\"22.872\"],[\"79499.70\",\"0.368\"],[\"79503.00\",\"0.008\"],[\"79505.50\",\"0.090\"],[\"79505.60\",\"0.001\"],[\"79507.10\",\"3.839\"],[\"79529.30\",\"0.660\"],[\"79529.40\",\"0.154\"],[\"79529.70\",\"0.159\"],[\"79533.50\",\"0.395\"],[\"79538.50\",\"0.072\"],[\"79538.70\",\"0.105\"],[\"79543.90\",\"4.531\"]],\"a\":[[\"79544.00\",\"5.982\"],[\"79550.70\",\"0.380\"],[\"79551.30\",\"0.001\"],[\"79554.50\",\"0.155\"],[\"79557.00\",\"0.030\"],[\"79559.30\",\"0.628\"],[\"79559.40\",\"0.076\"],[\"79567.80\",\"0.454\"],[\"79569.20\",\"0.005\"],[\"79571.60\",\"3.388\"],[\"79572.80\",\"10.002\"],[\"79933.80\",\"0.000\"],[\"79936.40\",\"0.001\"],[\"79941.70\",\"4.488\"],[\"80180.40\",\"7.340\"],[\"80339.40\",\"8.341\"],[\"80521.40\",\"7.934\"],[\"80673.50\",\"1.043\"],[\"81486.40\",\"0.000\"]],\"st\":1}}"}
{"receive_ns":1788580713726526000,"stream":"btcusdt@bookTicker","event_type":"bookTicker","event_time_ms":1788580713744,"raw_json":"{\"stream\":\"btcusdt@bookTicker\",\"data\":{\"e\":\"bookTicker\",\"u\":11479473468451,\"s\":\"BTCUSDT\",\"ps\":\"BTCUSDT\",\"b\":\"79543.90\",\"B\":\"4.531\",\"a\":\"79544.00\",\"A\":\"5.985\",\"T\":1788580713744,\"E\":1788580713744,\"st\":1}}"}
{"receive_ns":1788580713779646000,"stream":"btcusdt@depth@100ms","event_type":"depthUpdate","event_time_ms":1788580713833,"raw_json":"{\"stream\":\"btcusdt@depth@100ms\",\"data\":{\"e\":\"depthUpdate\",\"E\":1788580713833,\"T\":1788580713830,\"s\":\"BTCUSDT\",\"ps\":\"BTCUSDT\",\"U\":11479473467869,\"u\":11479473474804,\"pu\":11479473467765,\"b\":[[\"29143.90\",\"1.596\"],[\"29243.90\",\"0.504\"],[\"71589.50\",\"0.014\"],[\"71623.00\",\"0.003\"],[\"76362.10\",\"0.000\"],[\"77953.10\",\"0.012\"],[\"78589.40\",\"37.988\"],[\"78748.50\",\"8.369\"],[\"78907.50\",\"7.460\"],[\"79146.10\",\"0.008\"],[\"79453.10\",\"0.020\"],[\"79456.40\",\"0.308\"],[\"79474.60\",\"22.845\"],[\"79477.20\",\"0.028\"],[\"79480.00\",\"0.484\"],[\"79483.00\",\"0.023\"],[\"79502.00\",\"10.042\"],[\"79502.10\",\"2.369\"],[\"79529.40\",\"0.548\"],[\"79533.50\",\"0.001\"]],\"a\":[[\"79544.00\",\"5.985\"],[\"79550.60\",\"0.380\"],[\"79550.70\",\"0.000\"],[\"79551.30\",\"0.001\"],[\"79575.80\",\"0.232\"],[\"79587.90\",\"0.252\"],[\"79609.50\",\"0.028\"],[\"79617.60\",\"0.001\"],[\"79799.10\",\"0.000\"],[\"79933.80\",\"0.037\"],[\"79936.40\",\"0.008\"],[\"79937.70\",\"0.004\"],[\"79939.70\",\"0.126\"],[\"79941.70\",\"4.371\"],[\"79941.80\",\"0.000\"],[\"80339.40\",\"8.341\"],[\"80498.50\",\"35.143\"],[\"80657.60\",\"35.357\"],[\"80726.00\",\"1.141\"]],\"st\":1}}"}
{"receive_ns":1788580713902306000,"stream":"btcusdt@depth@100ms","event_type":"depthUpdate","event_time_ms":1788580713935,"raw_json":"{\"stream\":\"btcusdt@depth@100ms\",\"data\":{\"e\":\"depthUpdate\",\"E\":1788580713935,\"T\":1788580713934,\"s\":\"BTCUSDT\",\"ps\":\"BTCUSDT\",\"U\":11479473475059,\"u\":11479473480402,\"pu\":11479473474804,\"b\":[[\"29043.90\",\"0.007\"],[\"29143.90\",\"1.764\"],[\"29243.90\",\"0.329\"],[\"71589.50\",\"0.014\"],[\"71623.00\",\"0.000\"],[\"76362.10\",\"0.002\"],[\"78132.40\",\"0.002\"],[\"78629.10\",\"3.411\"],[\"78676.90\",\"2.217\"],[\"78748.50\",\"8.369\"],[\"78973.00\",\"0.000\"],[\"79146.10\",\"0.009\"],[\"79146.20\",\"3.780\"],[\"79147.10\",\"0.001\"],[\"79266.00\",\"0.752\"],[\"79456.40\",\"0.318\"]],\"a\":[[\"79550.40\",\"0.073\"],[\"79827.00\",\"0.008\"],[\"79939.70\",\"0.131\"],[\"79941.80\",\"0.001\"],[\"79946.70\",\"0.000\"],[\"80122.60\",\"0.000\"],[\"80339.40\",\"8.341\"],[\"80690.70\",\"0.746\"],[\"81134.80\",\"0.015\"],[\"81453.10\",\"1.043\"]],\"st\":1}}"}
{"receive_ns":1788580714063063000,"stream":"btcusdt@depth@100ms","event_type":"depthUpdate","event_time_ms":1788580714037,"raw_json":"{\"stream\":\"btcusdt@depth@100ms\",\"data\":{\"e\":\"depthUpdate\",\"E\":1788580714037,\"T\":1788580714035,\"s\":\"BTCUSDT\",\"ps\":\"BTCUSDT\",\"U\":11479473480485,\"u\":11479473485124,\"pu\":11479473480402,\"b\":[[\"1000.00\",\"25.354\"],[\"29043.90\",\"0.070\"],[\"29143.90\",\"1.813\"],[\"29243.90\",\"0.217\"],[\"71589.50\",\"0.014\"],[\"78748.50\",\"8.369\"],[\"78939.00\",\"3.240\"],[\"79000.10\",\"7.288\"],[\"79147.20\",\"0.645\"],[\"79219.60\",\"8.152\"],[\"79266.10\",\"0.000\"],[\"79267.80\",\"1.315\"],[\"79416.60\",\"0.210\"],[\"79453.10\",\"0.020\"],[\"79456.40\",\"0.293\"],[\"79474.60\",\"22.845\"],[\"79477.20\",\"0.028\"],[\"79529.60\",\"0.006\"]],\"a\":[[\"79550.00\",\"0.026\"],[\"79567.80\",\"0.002\"],[\"79568.20\",\"0.453\"],[\"79620.30\",\"28.924\"],[\"79623.00\",\"0.009\"],[\"79624.70\",\"0.515\"],[\"79625.60\",\"0.200\"],[\"79824.00\",\"0.993\"],[\"79826.90\",\"0.000\"],[\"79933.80\",\"0.000\"],[\"79936.40\",\"0.008\"],[\"79939.70\",\"0.168\"],[\"79944.50\",\"0.675\"],[\"79946.60\",\"0.010\"],[\"79999.90\",\"5.222\"],[\"80099.90\",\"7.854\"],[\"80235.10\",\"3.240\"],[\"80339.40\",\"8.341\"],[\"80657.60\",\"35.976\"],[\"80713.30\",\"1.608\"]],\"st\":1}}"}
{"receive_ns":1788580714063275000,"stream":"btcusdt@bookTicker","event_type":"bookTicker","event_time_ms":1788580714046,"raw_json":"{\"stream\":\"btcusdt@bookTicker\",\"data\":{\"e\":\"bookTicker\",\"u\":11479473485718,\"s\":\"BTCUSDT\",\"ps\":\"BTCUSDT\",\"b\":\"79543.90\",\"B\":\"5.273\",\"a\":\"79544.00\",\"A\":\"5.985\",\"T\":1788580714046,\"E\":1788580714046,\"st\":1}}"}
{"receive_ns":1788580714063420000,"stream":"btcusdt@bookTicker","event_type":"bookTicker","event_time_ms":1788580714046,"raw_json":"{\"stream\":\"btcusdt@bookTicker\",\"data\":{\"e\":\"bookTicker\",\"u\":11479473485754,\"s\":\"BTCUSDT\",\"ps\":\"BTCUSDT\",\"b\":\"79543.90\",\"B\":\"6.151\",\"a\":\"79544.00\",\"A\":\"5.985\",\"T\":1788580714046,\"E\":1788580714046,\"st\":1}}"}
{"receive_ns":1788580714063557000,"stream":"btcusdt@bookTicker","event_type":"bookTicker","event_time_ms":1788580714047,"raw_json":"{\"stream\":\"btcusdt@bookTicker\",\"data\":{\"e\":\"bookTicker\",\"u\":11479473485823,\"s\":\"BTCUSDT\",\"ps\":\"BTCUSDT\",\"b\":\"79543.90\",\"B\":\"6.150\",\"a\":\"79544.00\",\"A\":\"5.985\",\"T\":1788580714047,\"E\":1788580714047,\"st\":1}}"}
{"receive_ns":1788580714082580000,"stream":"btcusdt@depth@100ms","event_type":"depthUpdate","event_time_ms":1788580714139,"raw_json":"{\"stream\":\"btcusdt@depth@100ms\",\"data\":{\"e\":\"depthUpdate\",\"E\":1788580714139,\"T\":1788580714138,\"s\":\"BTCUSDT\",\"ps\":\"BTCUSDT\",\"U\":11479473485230,\"u\":11479473490661,\"pu\":11479473485124,\"b\":[[\"29043.90\",\"0.126\"],[\"29143.90\",\"1.883\"],[\"29243.90\",\"0.091\"],[\"71589.50\",\"0.014\"],[\"75566.70\",\"0.024\"],[\"76362.10\",\"0.000\"],[\"78499.80\",\"0.030\"],[\"78748.50\",\"8.369\"],[\"78759.70\",\"0.000\"],[\"79416.60\",\"0.220\"],[\"79456.40\",\"0.283\"],[\"79505.60\",\"0.000\"],[\"79507.10\",\"3.840\"],[\"79529.60\",\"0.002\"],[\"79538.50\",\"0.068\"],[\"79539.00\",\"1.007\"],[\"79543.90\",\"6.150\"]],\"a\":[[\"79546.40\",\"0.026\"],[\"79547.20\",\"0.004\"],[\"79549.00\",\"0.033\"],[\"79550.60\",\"0.000\"],[\"79550.70\",\"0.000\"],[\"79551.30\",\"0.381\"],[\"79554.50\",\"0.157\"],[\"79557.80\",\"0.001\"],[\"79573.70\",\"0.194\"],[\"79589.60\",\"0.466\"],[\"79624.50\",\"0.005\"],[\"79625.00\",\"0.077\"],[\"79625.10\",\"0.000\"],[\"79668.10\",\"0.013\"],[\"79790.40\",\"46.272\"],[\"79790.70\",\"0.000\"],[\"79939.70\",\"0.131\"],[\"80266.30\",\"0.187\"],[\"80338.90\",\"0.000\"],[\"80339.40\",\"8.341\"],[\"80603.30\",\"0.000\"]],\"st\":1}}"}
{"receive_ns":1788580714127924000,"stream":"btcusdt@bookTicker","event_type":"bookTicker","event_time_ms":1788580714179,"raw_json":"{\"stream\":\"btcusdt@bookTicker\",\"data\":{\"e\":\"bookTicker\",\"u\":11479473492599,\"s\":\"BTCUSDT\",\"ps\":\"BTCUSDT\",\"b\":\"79543.90\",\"B\":\"6.149\",\"a\":\"79544.00\",\"A\":\"5.985\",\"T\":1788580714179,\"E\":1788580714179,\"st\":1}}"}
{"receive_ns":1788580714129873000,"stream":"btcusdt@bookTicker","event_type":"bookTicker","event_time_ms":1788580714186,"raw_json":"{\"stream\":\"btcusdt@bookTicker\",\"data\":{\"e\":\"bookTicker\",\"u\":11479473492952,\"s\":\"BTCUSDT\",\"ps\":\"BTCUSDT\",\"b\":\"79543.90\",\"B\":\"6.149\",\"a\":\"79544.00\",\"A\":\"5.984\",\"T\":1788580714186,\"E\":1788580714186,\"st\":1}}"}
{"receive_ns":1788580714130014000,"stream":"btcusdt@trade","event_type":"trade","event_time_ms":1788580714186,"raw_json":"{\"stream\":\"btcusdt@trade\",\"data\":{\"e\":\"trade\",\"E\":1788580714186,\"T\":1788580714186,\"s\":\"BTCUSDT\",\"t\":8054266675,\"p\":\"79544.00\",\"q\":\"0.001\",\"X\":\"MARKET\",\"m\":false,\"st\":1}}"}
{"receive_ns":1788580714130716000,"stream":"btcusdt@bookTicker","event_type":"bookTicker","event_time_ms":1788580714187,"raw_json":"{\"stream\":\"btcusdt@bookTicker\",\"data\":{\"e\":\"bookTicker\",\"u\":11479473493025,\"s\":\"BTCUSDT\",\"ps\":\"BTCUSDT\",\"b\":\"79543.90\",\"B\":\"6.148\",\"a\":\"79544.00\",\"A\":\"5.984\",\"T\":1788580714187,\"E\":1788580714187,\"st\":1}}"}
{"receive_ns":1788580714132555000,"stream":"btcusdt@bookTicker","event_type":"bookTicker","event_time_ms":1788580714188,"raw_json":"{\"stream\":\"btcusdt@bookTicker\",\"data\":{\"e\":\"bookTicker\",\"u\":11479473493057,\"s\":\"BTCUSDT\",\"ps\":\"BTCUSDT\",\"b\":\"79543.90\",\"B\":\"6.148\",\"a\":\"79544.00\",\"A\":\"5.961\",\"T\":1788580714188,\"E\":1788580714188,\"st\":1}}"}
{"receive_ns":1788580714182794000,"stream":"btcusdt@bookTicker","event_type":"bookTicker","event_time_ms":1788580714240,"raw_json":"{\"stream\":\"btcusdt@bookTicker\",\"data\":{\"e\":\"bookTicker\",\"u\":11479473496185,\"s\":\"BTCUSDT\",\"ps\":\"BTCUSDT\",\"b\":\"79543.90\",\"B\":\"6.147\",\"a\":\"79544.00\",\"A\":\"5.961\",\"T\":1788580714240,\"E\":1788580714240,\"st\":1}}"}
{"receive_ns":1788580714183204000,"stream":"btcusdt@depth@100ms","event_type":"depthUpdate","event_time_ms":1788580714241,"raw_json":"{\"stream\":\"btcusdt@depth@100ms\",\"data\":{\"e\":\"depthUpdate\",\"E\":1788580714241,\"T\":1788580714240,\"s\":\"BTCUSDT\",\"ps\":\"BTCUSDT\",\"U\":11479473490762,\"u\":11479473496185,\"pu\":11479473490661,\"b\":[[\"1000.00\",\"25.354\"],[\"29043.90\",\"0.210\"],[\"29143.90\",\"1.890\"],[\"29243.90\",\"0.000\"],[\"63635.10\",\"0.000\"],[\"71589.50\",\"0.014\"],[\"76362.10\",\"0.002\"],[\"78470.10\",\"4.997\"],[\"78571.90\",\"0.006\"],[\"78636.00\",\"0.038\"],[\"78748.50\",\"8.369\"],[\"78907.50\",\"7.460\"],[\"78972.80\",\"47.502\"],[\"79146.20\",\"3.780\"],[\"79147.00\",\"37.816\"],[\"79265.90\",\"31.242\"],[\"79267.80\",\"5.849\"],[\"79416.60\",\"0.195\"],[\"79453.10\",\"0.020\"],[\"79455.70\",\"0.001\"],[\"79456.40\",\"0.075\"],[\"79486.70\",\"0.830\"],[\"79502.60\",\"0.692\"],[\"79543.90\",\"6.147\"]],\"a\":[[\"79544.00\",\"5.961\"],[\"79550.00\",\"0.003\"],[\"79557.80\",\"0.692\"],[\"79573.70\",\"1.024\"],[\"79624.50\",\"0.004\"],[\"79635.80\",\"6.000\"],[\"79636.00\",\"0.003\"],[\"79637.20\",\"0.014\"],[\"79637.30\",\"0.002\"],[\"79668.10\",\"0.007\"],[\"79826.00\",\"31.563\"],[\"79936.40\",\"0.001\"],[\"79937.70\",\"0.041\"],[\"79939.70\",\"0.019\"],[\"79944.50\",\"6.278\"],[\"79945.80\",\"38.235\"],[\"80121.60\",\"48.908\"],[\"80339.40\",\"8.341\"],[\"80591.50\",\"0.000\"]],\"st\":1}}"}
{"receive_ns":1788580714185641000,"stream":"btcusdt@bookTicker","event_type":"bookTicker","event_time_ms":1788580714242,"raw_json":"{\"stream\":\"btcusdt@bookTicker\",\"data\":{\"e\":\"bookTicker\",\"u\":11479473496297,\"s\":\"BTCUSDT\",\"ps\":\"BTCUSDT\",\"b\":\"79543.90\",\"B\":\"6.148\",\"a\":\"79544.00\",\"A\":\"5.961\",\"T\":1788580714242,\"E\":1788580714242,\"st\":1}}"}
{"receive_ns":1788580714247644000,"stream":"btcusdt@bookTicker","event_type":"bookTicker","event_time_ms":1788580714279,"raw_json":"{\"stream\":\"btcusdt@bookTicker\",\"data\":{\"e\":\"bookTicker\",\"u\":11479473499316,\"s\":\"BTCUSDT\",\"ps\":\"BTCUSDT\",\"b\":\"79543.90\",\"B\":\"6.148\",\"a\":\"79544.00\",\"A\":\"5.960\",\"T\":1788580714279,\"E\":1788580714279,\"st\":1}}"}
{"receive_ns":1788580714247826000,"stream":"btcusdt@trade","event_type":"trade","event_time_ms":1788580714279,"raw_json":"{\"stream\":\"btcusdt@trade\",\"data\":{\"e\":\"trade\",\"E\":1788580714279,\"T\":1788580714279,\"s\":\"BTCUSDT\",\"t\":8054266676,\"p\":\"79544.00\",\"q\":\"0.001\",\"X\":\"MARKET\",\"m\":false,\"st\":1}}"}
{"receive_ns":1788580714247962000,"stream":"btcusdt@bookTicker","event_type":"bookTicker","event_time_ms":1788580714288,"raw_json":"{\"stream\":\"btcusdt@bookTicker\",\"data\":{\"e\":\"bookTicker\",\"u\":11479473500104,\"s\":\"BTCUSDT\",\"ps\":\"BTCUSDT\",\"b\":\"79543.90\",\"B\":\"6.299\",\"a\":\"79544.00\",\"A\":\"5.960\",\"T\":1788580714287,\"E\":1788580714288,\"st\":1}}"}
{"receive_ns":1788580714248124000,"stream":"btcusdt@bookTicker","event_type":"bookTicker","event_time_ms":1788580714289,"raw_json":"{\"stream\":\"btcusdt@bookTicker\",\"data\":{\"e\":\"bookTicker\",\"u\":11479473500156,\"s\":\"BTCUSDT\",\"ps\":\"BTCUSDT\",\"b\":\"79543.90\",\"B\":\"6.300\",\"a\":\"79544.00\",\"A\":\"5.960\",\"T\":1788580714288,\"E\":1788580714289,\"st\":1}}"}
{"receive_ns":1788580714305844000,"stream":"btcusdt@depth@100ms","event_type":"depthUpdate","event_time_ms":1788580714343,"raw_json":"{\"stream\":\"btcusdt@depth@100ms\",\"data\":{\"e\":\"depthUpdate\",\"E\":1788580714343,\"T\":1788580714342,\"s\":\"BTCUSDT\",\"ps\":\"BTCUSDT\",\"U\":11479473496247,\"u\":11479473503117,\"pu\":11479473496185,\"b\":[[\"1000.00\",\"25.354\"],[\"29043.90\",\"0.392\"],[\"29143.90\",\"1.708\"],[\"71589.50\",\"0.014\"],[\"76362.10\",\"0.000\"],[\"78191.70\",\"6.640\"],[\"78435.50\",\"0.000\"],[\"78748.40\",\"0.000\"],[\"78748.50\",\"8.369\"],[\"78759.60\",\"62.288\"],[\"79416.60\",\"0.185\"],[\"79456.40\",\"0.308\"],[\"79459.40\",\"0.171\"],[\"79459.90\",\"0.000\"],[\"79508.50\",\"0.019\"],[\"79514.30\",\"1.025\"],[\"79531.60\",\"0.000\"],[\"79532.70\",\"0.002\"],[\"79533.50\",\"0.002\"],[\"79535.00\",\"0.043\"],[\"79538.80\",\"1.006\"],[\"79539.00\",\"1.003\"],[\"79543.90\",\"6.300\"]],\"a\":[[\"79544.00\",\"5.960\"],[\"79559.30\",\"0.000\"],[\"79559.50\",\"0.001\"],[\"79560.40\",\"0.628\"],[\"79624.50\",\"0.005\"],[\"79933.80\",\"0.005\"],[\"79936.40\",\"0.008\"],[\"79939.70\",\"0.144\"],[\"80338.00\",\"62.374\"],[\"80339.40\",\"8.341\"]],\"st\":1}}"}
{"receive_ns":1788580714369302000,"stream":"btcusdt@bookTicker","event_type":"bookTicker","event_time_ms":1788580714413,"raw_json":"{\"stream\":\"btcusdt@bookTicker\",\"data\":{\"e\":\"bookTicker\",\"u\":11479473506211,\"s\":\"BTCUSDT\",\"ps\":\"BTCUSDT\",\"b\":\"79543.90\",\"B\":\"6.316\",\"a\":\"79544.00\",\"A\":\"5.960\",\"T\":1788580714413,\"E\":1788580714413,\"st\":1}}"}
{"receive_ns":1788580714369587000,"stream":"btcusdt@bookTicker","event_type":"bookTicker","event_time_ms":1788580714414,"raw_json":"{\"stream\":\"btcusdt@bookTicker\",\"data\":{\"e\":\"bookTicker\",\"u\":11479473506310,\"s\":\"BTCUSDT\",\"ps\":\"BTCUSDT\",\"b\":\"79543.90\",\"B\":\"6.314\",\"a\":\"79544.00\",\"A\":\"5.960\",\"T\":1788580714414,\"E\":1788580714414,\"st\":1}}"}
{"receive_ns":1788580714369765000,"stream":"btcusdt@bookTicker","event_type":"bookTicker","event_time_ms":1788580714422,"raw_json":"{\"stream\":\"btcusdt@bookTicker\",\"data\":{\"e\":\"bookTicker\",\"u\":11479473506625,\"s\":\"BTCUSDT\",\"ps\":\"BTCUSDT\",\"b\":\"79543.90\",\"B\":\"6.315\",\"a\":\"79544.00\",\"A\":\"5.960\",\"T\":1788580714422,\"E\":1788580714422,\"st\":1}}"}
{"receive_ns":1788580714389635000,"stream":"btcusdt@depth@100ms","event_type":"depthUpdate","event_time_ms":1788580714445,"raw_json":"{\"stream\":\"btcusdt@depth@100ms\",\"data\":{\"e\":\"depthUpdate\",\"E\":1788580714445,\"T\":1788580714442,\"s\":\"BTCUSDT\",\"ps\":\"BTCUSDT\",\"U\":11479473503224,\"u\":11479473507303,\"pu\":11479473503117,\"b\":[[\"29043.90\",\"0.567\"],[\"29143.90\",\"1.533\"],[\"63635.00\",\"0.000\"],[\"71589.50\",\"0.014\"],[\"78226.20\",\"0.153\"],[\"78549.60\",\"9.163\"],[\"78623.90\",\"2.667\"],[\"78748.50\",\"7.735\"],[\"78939.00\",\"0.000\"],[\"79000.10\",\"9.880\"],[\"79219.60\",\"8.638\"],[\"79266.00\",\"0.914\"],[\"79419.80\",\"0.511\"],[\"79456.40\",\"0.318\"],[\"79476.00\",\"4.360\"],[\"79520.20\",\"2.393\"],[\"79540.50\",\"0.002\"],[\"79542.20\",\"0.001\"],[\"79543.30\",\"0.001\"],[\"79543.90\",\"6.315\"]],\"a\":[[\"79560.10\",\"0.002\"],[\"79620.00\",\"20.461\"],[\"79666.20\",\"0.000\"],[\"79825.90\",\"0.162\"],[\"79939.70\",\"0.149\"],[\"79945.70\",\"3.893\"],[\"79999.90\",\"5.060\"],[\"80099.90\",\"10.446\"],[\"80235.10\",\"0.000\"],[\"80339.40\",\"8.341\"],[\"81776.50\",\"0.000\"]],\"st\":1}}"}
{"receive_ns":1788580714494625000,"stream":"btcusdt@depth@100ms","event_type":"depthUpdate","event_time_ms":1788580714547,"raw_json":"{\"stream\":\"btcusdt@depth@100ms\",\"data\":{\"e\":\"depthUpdate\",\"E\":1788580714547,\"T\":1788580714546,\"s\":\"BTCUSDT\",\"ps\":\"BTCUSDT\",\"U\":11479473507425,\"u\":11479473511900,\"pu\":11479473507303,\"b\":[[\"1000.00\",\"25.354\"],[\"29043.90\",\"0.749\"],[\"29143.90\",\"1.351\"],[\"71589.50\",\"0.014\"],[\"76362.10\",\"0.002\"],[\"77953.10\",\"0.009\"],[\"78385.30\",\"3.160\"],[\"78554.60\",\"0.286\"],[\"78748.50\",\"7.735\"],[\"79146.20\",\"3.790\"],[\"79380.40\",\"2.054\"],[\"79399.50\",\"1.886\"],[\"79399.60\",\"0.000\"],[\"79419.80\",\"0.971\"],[\"79453.10\",\"0.020\"],[\"79456.40\",\"0.318\"],[\"79520.20\",\"2.395\"],[\"79529.40\",\"0.568\"],[\"79539.30\",\"0.006\"]],\"a\":[[\"79549.00\",\"0.025\"],[\"79550.70\",\"0.008\"],[\"79554.00\",\"0.550\"],[\"79554.60\",\"4.587\"],[\"79559.40\",\"0.000\"],[\"79560.10\",\"0.080\"],[\"79564.80\",\"0.002\"],[\"79564.90\",\"0.002\"],[\"79565.30\",\"0.441\"],[\"79565.50\",\"0.491\"],[\"79617.60\",\"0.024\"],[\"79620.00\",\"16.147\"],[\"79620.30\",\"0.006\"],[\"79628.30\",\"28.629\"],[\"79666.20\",\"0.408\"],[\"79667.70\",\"1.912\"],[\"79667.80\",\"0.000\"],[\"79705.60\",\"1.840\"],[\"79933.80\",\"0.000\"],[\"79936.40\",\"0.008\"],[\"79937.70\",\"0.041\"],[\"79939.70\",\"0.131\"],[\"80339.40\",\"8.341\"],[\"80459.60\",\"13.338\"],[\"80521.40\",\"6.694\"]],\"st\":1}}"}
{"receive_ns":1788580714552873000,"stream":"btcusdt@bookTicker","event_type":"bookTicker","event_time_ms":1788580714581,"raw_json":"{\"stream\":\"btcusdt@bookTicker\",\"data\":{\"e\":\"bookTicker\",\"u\":11479473513759,\"s\":\"BTCUSDT\",\"ps\":\"BTCUSDT\",\"b\":\"79543.90\",\"B\":\"6.316\",\"a\":\"79544.00\",\"A\":\"5.960\",\"T\":1788580714581,\"E\":1788580714581,\"st\":1}}"}
{"receive_ns":1788580714613329000,"stream":"btcusdt@bookTicker","event_type":"bookTicker","event_time_ms":1788580714638,"raw_json":"{\"stream\":\"btcusdt@bookTicker\",\"data\":{\"e\":\"bookTicker\",\"u\":11479473516487,\"s\":\"BTCUSDT\",\"ps\":\"BTCUSDT\",\"b\":\"79543.90\",\"B\":\"6.315\",\"a\":\"79544.00\",\"A\":\"5.960\",\"T\":1788580714638,\"E\":1788580714638,\"st\":1}}"}
{"receive_ns":1788580714613535000,"stream":"btcusdt@bookTicker","event_type":"bookTicker","event_time_ms":1788580714647,"raw_json":"{\"stream\":\"btcusdt@bookTicker\",\"data\":{\"e\":\"bookTicker\",\"u\":11479473516953,\"s\":\"BTCUSDT\",\"ps\":\"BTCUSDT\",\"b\":\"79543.90\",\"B\":\"6.317\",\"a\":\"79544.00\",\"A\":\"5.960\",\"T\":1788580714647,\"E\":1788580714647,\"st\":1}}"}
{"receive_ns":1788580714613831000,"stream":"btcusdt@depth@100ms","event_type":"depthUpdate","event_time_ms":1788580714649,"raw_json":"{\"stream\":\"btcusdt@depth@100ms\",\"data\":{\"e\":\"depthUpdate\",\"E\":1788580714649,\"T\":1788580714648,\"s\":\"BTCUSDT\",\"ps\":\"BTCUSDT\",\"U\":11479473511943,\"u\":11479473517006,\"pu\":11479473511900,\"b\":[[\"1000.00\",\"25.354\"],[\"29043.90\",\"0.924\"],[\"29143.90\",\"1.176\"],[\"63635.00\",\"0.000\"],[\"71589.50\",\"0.014\"],[\"76362.10\",\"0.000\"],[\"78590.80\",\"0.004\"],[\"78592.70\",\"0.000\"],[\"78602.80\",\"0.004\"],[\"78604.70\",\"0.000\"],[\"78614.80\",\"0.005\"],[\"78619.80\",\"0.000\"],[\"78748.50\",\"7.737\"],[\"79416.60\",\"0.195\"],[\"79419.80\",\"0.511\"],[\"79456.40\",\"0.308\"],[\"79459.40\",\"0.046\"],[\"79461.10\",\"0.138\"],[\"79529.50\",\"0.009\"],[\"79539.30\",\"0.000\"],[\"79543.90\",\"6.317\"]],\"a\":[[\"79549.00\",\"0.033\"],[\"79550.70\",\"0.000\"],[\"79570.60\",\"0.046\"],[\"79620.30\",\"28.635\"],[\"79628.30\",\"0.000\"],[\"79666.20\",\"0.000\"],[\"79668.10\",\"0.013\"],[\"79939.70\",\"0.131\"],[\"80339.40\",\"8.341\"],[\"80617.80\",\"3.875\"]],\"st\":1}}"}
{"receive_ns":1788580714714432000,"stream":"btcusdt@bookTicker","event_type":"bookTicker","event_time_ms":1788580714748,"raw_json":"{\"stream\":\"btcusdt@bookTicker\",\"data\":{\"e\":\"bookTicker\",\"u\":11479473521673,\"s\":\"BTCUSDT\",\"ps\":\"BTCUSDT\",\"b\":\"79543.90\",\"B\":\"6.315\",\"a\":\"79544.00\",\"A\":\"5.960\",\"T\":1788580714748,\"E\":1788580714748,\"st\":1}}"}
{"receive_ns":1788580714714610000,"stream":"btcusdt@trade","event_type":"trade","event_time_ms":1788580714748,"raw_json":"{\"stream\":\"btcusdt@trade\",\"data\":{\"e\":\"trade\",\"E\":1788580714748,\"T\":1788580714748,\"s\":\"BTCUSDT\",\"t\":8054266677,\"p\":\"79543.90\",\"q\":\"0.002\",\"X\":\"MARKET\",\"m\":true,\"st\":1}}"}
{"receive_ns":1788580714714893000,"stream":"btcusdt@depth@100ms","event_type":"depthUpdate","event_time_ms":1788580714751,"raw_json":"{\"stream\":\"btcusdt@depth@100ms\",\"data\":{\"e\":\"depthUpdate\",\"E\":1788580714751,\"T\":1788580714750,\"s\":\"BTCUSDT\",\"ps\":\"BTCUSDT\",\"U\":11479473517044,\"u\":11479473521844,\"pu\":11479473517006,\"b\":[[\"29043.90\",\"1.106\"],[\"29143.90\",\"0.994\"],[\"63635.00\",\"0.000\"],[\"71589.50\",\"0.014\"],[\"75566.70\",\"0.024\"],[\"75566.80\",\"0.010\"],[\"76362.10\",\"0.002\"],[\"78231.40\",\"2.903\"],[\"78390.50\",\"9.939\"],[\"78430.30\",\"43.307\"],[\"78623.90\",\"1.905\"],[\"78629.10\",\"4.173\"],[\"78748.50\",\"7.737\"],[\"79322.10\",\"0.007\"],[\"79416.60\",\"0.252\"],[\"79419.80\",\"0.511\"],[\"79453.10\",\"0.020\"],[\"79456.40\",\"0.251\"],[\"79458.50\",\"0.323\"],[\"79460.00\",\"0.809\"],[\"79461.10\",\"0.013\"],[\"79529.40\",\"0.542\"],[\"79543.90\",\"6.315\"]],\"a\":[[\"79556.90\",\"0.000\"],[\"79557.60\",\"0.077\"],[\"79557.70\",\"0.081\"],[\"79617.60\",\"0.024\"],[\"79666.20\",\"0.000\"],[\"79936.40\",\"0.008\"],[\"79937.70\",\"0.041\"],[\"79939.70\",\"0.131\"],[\"80339.40\",\"8.343\"]],\"st\":1}}"}
{"receive_ns":1788580714715064000,"stream":"btcusdt@bookTicker","event_type":"bookTicker","event_time_ms":1788580714761,"raw_json":"{\"stream\":\"btcusdt@bookTicker\",\"data\":{\"e\":\"bookTicker\",\"u\":11479473522312,\"s\":\"BTCUSDT\",\"ps\":\"BTCUSDT\",\"b\":\"79543.90\",\"B\":\"6.315\",\"a\":\"79544.00\",\"A\":\"5.983\",\"T\":1788580714760,\"E\":1788580714761,\"st\":1}}"}
{"receive_ns":1788580714767747000,"stream":"btcusdt@bookTicker","event_type":"bookTicker","event_time_ms":1788580714803,"raw_json":"{\"stream\":\"btcusdt@bookTicker\",\"data\":{\"e\":\"bookTicker\",\"u\":11479473523847,\"s\":\"BTCUSDT\",\"ps\":\"BTCUSDT\",\"b\":\"79543.90\",\"B\":\"6.314\",\"a\":\"79544.00\",\"A\":\"5.983\",\"T\":1788580714802,\"E\":1788580714803,\"st\":1}}"}
{"receive_ns":1788580714767971000,"stream":"btcusdt@bookTicker","event_type":"bookTicker","event_time_ms":1788580714804,"raw_json":"{\"stream\":\"btcusdt@bookTicker\",\"data\":{\"e\":\"bookTicker\",\"u\":11479473523928,\"s\":\"BTCUSDT\",\"ps\":\"BTCUSDT\",\"b\":\"79543.90\",\"B\":\"6.315\",\"a\":\"79544.00\",\"A\":\"5.983\",\"T\":1788580714804,\"E\":1788580714804,\"st\":1}}"}
{"receive_ns":1788580714847484000,"stream":"btcusdt@depth@100ms","event_type":"depthUpdate","event_time_ms":1788580714853,"raw_json":"{\"stream\":\"btcusdt@depth@100ms\",\"data\":{\"e\":\"depthUpdate\",\"E\":1788580714853,\"T\":1788580714852,\"s\":\"BTCUSDT\",\"ps\":\"BTCUSDT\",\"U\":11479473521856,\"u\":11479473525686,\"pu\":11479473521844,\"b\":[[\"1000.00\",\"25.354\"],[\"29043.90\",\"1.281\"],[\"29143.90\",\"0.819\"],[\"71589.50\",\"0.014\"],[\"76362.10\",\"0.000\"],[\"78589.40\",\"39.259\"],[\"78748.50\",\"7.737\"],[\"79146.10\",\"0.008\"],[\"79146.20\",\"3.412\"],[\"79315.30\",\"0.000\"],[\"79416.60\",\"0.242\"],[\"79419.80\",\"0.961\"],[\"79517.30\",\"0.002\"],[\"79518.50\",\"0.002\"],[\"79518.80\",\"0.454\"],[\"79524.30\",\"0.378\"],[\"79525.10\",\"0.037\"],[\"79527.80\",\"0.225\"],[\"79528.50\",\"0.000\"],[\"79529.10\",\"0.669\"],[\"79543.90\",\"6.315\"]],\"a\":[[\"79544.00\",\"5.983\"],[\"79563.90\",\"0.051\"],[\"79564.40\",\"0.091\"],[\"79565.10\",\"0.440\"],[\"79565.30\",\"0.002\"],[\"79666.20\",\"0.395\"],[\"79784.80\",\"0.003\"],[\"79784.90\",\"0.000\"],[\"79939.70\",\"0.126\"],[\"79941.70\",\"4.371\"],[\"79941.80\",\"0.000\"],[\"80339.40\",\"8.341\"],[\"80578.20\",\"2.604\"]],\"st\":1}}"}
{"receive_ns":1788580714848829000,"stream":"btcusdt@bookTicker","event_type":"bookTicker","event_time_ms":1788580714883,"raw_json":"{\"stream\":\"btcusdt@bookTicker\",\"data\":{\"e\":\"bookTicker\",\"u\":11479473526847,\"s\":\"BTCUSDT\",\"ps\":\"BTCUSDT\",\"b\":\"79543.90\",\"B\":\"6.314\",\"a\":\"79544.00\",\"A\":\"5.983\",\"T\":1788580714883,\"E\":1788580714883,\"st\":1}}"}
{"receive_ns":1788580714915736000,"stream":"btcusdt@depth@100ms","event_type":"depthUpdate","event_time_ms":1788580714955,"raw_json":"{\"stream\":\"btcusdt@depth@100ms\",\"data\":{\"e\":\"depthUpdate\",\"E\":1788580714955,\"T\":1788580714954,\"s\":\"BTCUSDT\",\"ps\":\"BTCUSDT\",\"U\":11479473525693,\"u\":11479473530526,\"pu\":11479473525686,\"b\":[[\"1000.00\",\"25.354\"],[\"29043.90\",\"1.463\"],[\"29143.90\",\"0.637\"],[\"63635.00\",\"0.000\"],[\"71589.50\",\"0.014\"],[\"78426.80\",\"0.153\"],[\"78589.80\",\"0.004\"],[\"78590.80\",\"0.000\"],[\"78601.90\",\"0.004\"],[\"78602.80\",\"0.001\"],[\"78748.50\",\"7.735\"],[\"79146.10\",\"0.009\"],[\"79146.20\",\"1.521\"],[\"79416.60\",\"0.252\"],[\"79453.10\",\"0.000\"],[\"79456.40\",\"0.176\"],[\"79543.90\",\"6.314\"]],\"a\":[[\"79550.70\",\"0.004\"],[\"79551.30\",\"0.377\"],[\"79556.30\",\"0.077\"],[\"79568.20\",\"0.001\"],[\"79569.20\",\"0.457\"],[\"79569.90\",\"0.087\"],[\"79620.30\",\"0.006\"],[\"79625.60\",\"28.829\"],[\"79628.30\",\"0.000\"],[\"79936.40\",\"0.001\"],[\"79937.70\",\"0.004\"],[\"79939.70\",\"0.117\"],[\"79941.80\",\"0.001\"],[\"80180.40\",\"7.589\"],[\"80339.40\",\"8.341\"],[\"82000.00\",\"86.875\"]],\"st\":1}}"}
{"receive_ns":1788580714971957000,"stream":"btcusdt@bookTicker","event_type":"bookTicker","event_time_ms":1788580715014,"raw_json":"{\"stream\":\"btcusdt@bookTicker\",\"data\":{\"e\":\"bookTicker\",\"u\":11479473538915,\"s\":\"BTCUSDT\",\"ps\":\"BTCUSDT\",\"b\":\"79543.90\",\"B\":\"6.314\",\"a\":\"79544.00\",\"A\":\"5.930\",\"T\":1788580715014,\"E\":1788580715014,\"st\":1}}"}
{"receive_ns":1788580714972177000,"stream":"btcusdt@trade","event_type":"trade","event_time_ms":1788580715014,"raw_json":"{\"stream\":\"btcusdt@trade\",\"data\":{\"e\":\"trade\",\"E\":1788580715014,\"T\":1788580715014,\"s\":\"BTCUSDT\",\"t\":8054266678,\"p\":\"79544.00\",\"q\":\"0.028\",\"X\":\"MARKET\",\"m\":false,\"st\":1}}"}
{"receive_ns":1788580714973126000,"stream":"btcusdt@trade","event_type":"trade","event_time_ms":1788580715014,"raw_json":"{\"stream\":\"btcusdt@trade\",\"data\":{\"e\":\"trade\",\"E\":1788580715014,\"T\":1788580715014,\"s\":\"BTCUSDT\",\"t\":8054266679,\"p\":\"79544.00\",\"q\":\"0.001\",\"X\":\"MARKET\",\"m\":false,\"st\":1}}"}
{"receive_ns":1788580714973263000,"stream":"btcusdt@trade","event_type":"trade","event_time_ms":1788580715014,"raw_json":"{\"stream\":\"btcusdt@trade\",\"data\":{\"e\":\"trade\",\"E\":1788580715014,\"T\":1788580715014,\"s\":\"BTCUSDT\",\"t\":8054266680,\"p\":\"79544.00\",\"q\":\"0.001\",\"X\":\"MARKET\",\"m\":false,\"st\":1}}"}
{"receive_ns":1788580714973378000,"stream":"btcusdt@trade","event_type":"trade","event_time_ms":1788580715014,"raw_json":"{\"stream\":\"btcusdt@trade\",\"data\":{\"e\":\"trade\",\"E\":1788580715014,\"T\":1788580715014,\"s\":\"BTCUSDT\",\"t\":8054266681,\"p\":\"79544.00\",\"q\":\"0.023\",\"X\":\"MARKET\",\"m\":false,\"st\":1}}"}
{"receive_ns":1788580714973541000,"stream":"btcusdt@bookTicker","event_type":"bookTicker","event_time_ms":1788580715015,"raw_json":"{\"stream\":\"btcusdt@bookTicker\",\"data\":{\"e\":\"bookTicker\",\"u\":11479473539056,\"s\":\"BTCUSDT\",\"ps\":\"BTCUSDT\",\"b\":\"79543.90\",\"B\":\"6.336\",\"a\":\"79544.00\",\"A\":\"5.930\",\"T\":1788580715015,\"E\":1788580715015,\"st\":1}}"}
{"receive_ns":1788580715031248000,"stream":"btcusdt@depth@100ms","event_type":"depthUpdate","event_time_ms":1788580715057,"raw_json":"{\"stream\":\"btcusdt@depth@100ms\",\"data\":{\"e\":\"depthUpdate\",\"E\":1788580715057,\"T\":1788580715055,\"s\":\"BTCUSDT\",\"ps\":\"BTCUSDT\",\"U\":11479473530613,\"u\":11479473542393,\"pu\":11479473530526,\"b\":[[\"29043.90\",\"1.638\"],[\"29143.90\",\"0.462\"],[\"63635.00\",\"0.000\"],[\"71589.50\",\"0.014\"],[\"71623.00\",\"0.000\"],[\"75561.60\",\"0.005\"],[\"76362.10\",\"0.002\"],[\"78191.70\",\"2.809\"],[\"78499.70\",\"75.484\"],[\"78629.10\",\"4.935\"],[\"78748.50\",\"7.735\"],[\"78947.30\",\"4.430\"],[\"79146.20\",\"1.899\"],[\"79416.60\",\"0.195\"],[\"79453.10\",\"0.020\"],[\"79456.40\",\"0.308\"],[\"79458.50\",\"0.198\"],[\"79459.70\",\"0.125\"],[\"79478.80\",\"1.492\"],[\"79486.80\",\"0.402\"],[\"79510.80\",\"0.136\"],[\"79512.00\",\"0.043\"],[\"79524.30\",\"0.005\"],[\"79525.20\",\"0.373\"],[\"79526.00\",\"0.108\"],[\"79526.30\",\"0.003\"],[\"79526.70\",\"0.080\"],[\"79528.40\",\"0.617\"],[\"79529.10\",\"0.229\"],[\"79529.60\",\"0.002\"],[\"79536.50\",\"0.255\"],[\"79538.50\",\"0.070\"],[\"79538.80\",\"1.002\"],[\"79539.00\",\"1.005\"],[\"79543.90\",\"6.336\"]],\"a\":[[\"79544.00\",\"5.930\"],[\"79544.90\",\"0.064\"],[\"79546.50\",\"0.022\"],[\"79546.60\",\"0.007\"],[\"79549.00\",\"0.033\"],[\"79550.40\",\"0.073\"],[\"79550.70\",\"0.000\"],[\"79551.20\",\"0.000\"],[\"79551.30\",\"0.381\"],[\"79553.80\",\"0.242\"],[\"79554.50\",\"0.157\"],[\"79555.00\",\"0.002\"],[\"79556.30\",\"0.001\"],[\"79558.70\",\"0.077\"],[\"79560.30\",\"0.688\"],[\"79560.40\",\"0.000\"],[\"79564.70\",\"0.375\"],[\"79564.90\",\"0.441\"],[\"79565.10\",\"0.001\"],[\"79565.50\",\"0.118\"],[\"79566.20\",\"0.057\"],[\"79567.40\",\"0.000\"],[\"79567.70\",\"0.002\"],[\"79567.90\",\"0.332\"],[\"79568.80\",\"0.010\"],[\"79569.20\",\"0.507\"],[\"79578.00\",\"0.002\"],[\"79595.20\",\"0.041\"],[\"79603.30\",\"2.412\"],[\"79604.90\",\"0.002\"],[\"79614.60\",\"0.000\"],[\"79617.60\",\"0.001\"],[\"79933.80\",\"0.005\"],[\"79936.40\",\"0.008\"],[\"79939.70\",\"0.186\"],[\"80260.00\",\"5.121\"],[\"80339.40\",\"8.341\"],[\"80561.20\",\"0.016\"],[\"80603.10\",\"79.504\"],[\"81134.80\",\"0.012\"]],\"st\":1}}"}
{"receive_ns":1788580715102882000,"stream":"btcusdt@depth@100ms","event_type":"depthUpdate","event_time_ms":1788580715159,"raw_json":"{\"stream\":\"btcusdt@depth@100ms\",\"data\":{\"e\":\"depthUpdate\",\"E\":1788580715159,\"T\":1788580715157,\"s\":\"BTCUSDT\",\"ps\":\"BTCUSDT\",\"U\":11479473542530,\"u\":11479473546831,\"pu\":11479473542393,\"b\":[[\"1000.00\",\"25.354\"],[\"29043.90\",\"1.778\"],[\"29143.90\",\"0.301\"],[\"29443.90\",\"0.021\"],[\"63635.00\",\"0.000\"],[\"71589.50\",\"0.014\"],[\"76362.10\",\"0.000\"],[\"77953.10\",\"0.012\"],[\"78589.40\",\"37.988\"],[\"78748.50\",\"7.735\"],[\"78821.70\",\"0.192\"],[\"79146.20\",\"3.790\"],[\"79416.60\",\"0.185\"],[\"79456.40\",\"0.318\"],[\"79458.50\",\"0.323\"],[\"79459.70\",\"0.000\"]],\"a\":[[\"79625.30\",\"0.001\"],[\"79636.00\",\"0.001\"],[\"79637.30\",\"0.003\"],[\"79640.80\",\"0.000\"],[\"79939.70\",\"0.186\"],[\"80339.40\",\"8.341\"]],\"st\":1}}"}
{"receive_ns":1788580715219883000,"stream":"btcusdt@depth@100ms","event_type":"depthUpdate","event_time_ms":1788580715261,"raw_json":"{\"stream\":\"btcusdt@depth@100ms\",\"data\":{\"e\":\"depthUpdate\",\"E\":1788580715261,\"T\":1788580715260,\"s\":\"BTCUSDT\",\"ps\":\"BTCUSDT\",\"U\":11479473546894,\"u\":11479473552722,\"pu\":11479473546831,\"b\":[[\"1000.00\",\"25.354\"],[\"29043.90\",\"1.827\"],[\"29143.90\",\"0.189\"],[\"29443.90\",\"0.084\"],[\"63635.10\",\"0.000\"],[\"71589.50\",\"0.014\"],[\"76362.10\",\"0.002\"],[\"78191.70\",\"6.640\"],[\"78430.30\",\"45.217\"],[\"78515.30\",\"0.000\"],[\"78907.50\",\"7.207\"],[\"79416.60\",\"0.292\"],[\"79453.10\",\"0.020\"],[\"79456.40\",\"0.211\"],[\"79538.60\",\"0.442\"],[\"79539.00\",\"1.003\"]],\"a\":[[\"79550.00\",\"0.026\"],[\"79550.70\",\"0.376\"],[\"79551.30\",\"0.005\"],[\"79620.30\",\"28.635\"],[\"79624.50\",\"0.004\"],[\"79624.60\",\"0.002\"],[\"79625.20\",\"0.005\"],[\"79625.60\",\"0.200\"],[\"79933.80\",\"0.000\"],[\"79936.40\",\"0.008\"],[\"79939.70\",\"0.168\"],[\"80140.60\",\"4.362\"],[\"80339.40\",\"8.343\"],[\"80680.50\",\"1.857\"]],\"st\":1}}"}
{"receive_ns":1788580715273067000,"stream":"btcusdt@bookTicker","event_type":"bookTicker","event_time_ms":1788580715310,"raw_json":"{\"stream\":\"btcusdt@bookTicker\",\"data\":{\"e\":\"bookTicker\",\"u\":11479473555034,\"s\":\"BTCUSDT\",\"ps\":\"BTCUSDT\",\"b\":\"79543.90\",\"B\":\"6.336\",\"a\":\"79544.00\",\"A\":\"5.869\",\"T\":1788580715310,\"E\":1788580715310,\"st\":1}}"}
{"receive_ns":1788580715273234000,"stream":"btcusdt@trade","event_type":"trade","event_time_ms":1788580715310,"raw_json":"{\"stream\":\"btcusdt@trade\",\"data\":{\"e\":\"trade\",\"E\":1788580715310,\"T\":1788580715310,\"s\":\"BTCUSDT\",\"t\":8054266682,\"p\":\"79544.00\",\"q\":\"0.061\",\"X\":\"MARKET\",\"m\":false,\"st\":1}}"}
{"receive_ns":1788580715273418000,"stream":"btcusdt@bookTicker","event_type":"bookTicker","event_time_ms":1788580715311,"raw_json":"{\"stream\":\"btcusdt@bookTicker\",\"data\":{\"e\":\"bookTicker\",\"u\":11479473555098,\"s\":\"BTCUSDT\",\"ps\":\"BTCUSDT\",\"b\":\"79543.90\",\"B\":\"6.337\",\"a\":\"79544.00\",\"A\":\"5.869\",\"T\":1788580715311,\"E\":1788580715311,\"st\":1}}"}
{"receive_ns":1788580715273552000,"stream":"btcusdt@bookTicker","event_type":"bookTicker","event_time_ms":1788580715311,"raw_json":"{\"stream\":\"btcusdt@bookTicker\",\"data\":{\"e\":\"bookTicker\",\"u\":11479473555099,\"s\":\"BTCUSDT\",\"ps\":\"BTCUSDT\",\"b\":\"79543.90\",\"B\":\"6.337\",\"a\":\"79544.00\",\"A\":\"5.870\",\"T\":1788580715311,\"E\":1788580715311,\"st\":1}}"}
{"receive_ns":1788580715273768000,"stream":"btcusdt@bookTicker","event_type":"bookTicker","event_time_ms":1788580715330,"raw_json":"{\"stream\":\"btcusdt@bookTicker\",\"data\":{\"e\":\"bookTicker\",\"u\":11479473556417,\"s\":\"BTCUSDT\",\"ps\":\"BTCUSDT\",\"b\":\"79543.90\",\"B\":\"6.337\",\"a\":\"79544.00\",\"A\":\"5.831\",\"T\":1788580715330,\"E\":1788580715330,\"st\":1}}"}
{"receive_ns":1788580715276208000,"stream":"btcusdt@bookTicker","event_type":"bookTicker","event_time_ms":1788580715332,"raw_json":"{\"stream\":\"btcusdt@bookTicker\",\"data\":{\"e\":\"bookTicker\",\"u\":11479473556616,\"s\":\"BTCUSDT\",\"ps\":\"BTCUSDT\",\"b\":\"79543.90\",\"B\":\"6.337\",\"a\":\"79544.00\",\"A\":\"5.241\",\"T\":1788580715332,\"E\":1788580715332,\"st\":1}}"}
{"receive_ns":1788580715276523000,"stream":"btcusdt@bookTicker","event_type":"bookTicker","event_time_ms":1788580715333,"raw_json":"{\"stream\":\"btcusdt@bookTicker\",\"data\":{\"e\":\"bookTicker\",\"u\":11479473556680,\"s\":\"BTCUSDT\",\"ps\":\"BTCUSDT\",\"b\":\"79543.90\",\"B\":\"6.337\",\"a\":\"79544.00\",\"A\":\"5.277\",\"T\":1788580715333,\"E\":1788580715333,\"st\":1}}"}
{"receive_ns":1788580715276707000,"stream":"btcusdt@bookTicker","event_type":"bookTicker","event_time_ms":1788580715333,"raw_json":"{\"stream\":\"btcusdt@bookTicker\",\"data\":{\"e\":\"bookTicker\",\"u\":11479473556745,\"s\":\"BTCUSDT\",\"ps\":\"BTCUSDT\",\"b\":\"79543.90\",\"B\":\"6.336\",\"a\":\"79544.00\",\"A\":\"5.277\",\"T\":1788580715333,\"E\":1788580715333,\"st\":1}}"}
{"receive_ns":1788580715277558000,"stream":"btcusdt@bookTicker","event_type":"bookTicker","event_time_ms":1788580715334,"raw_json":"{\"stream\":\"btcusdt@bookTicker\",\"data\":{\"e\":\"bookTicker\",\"u\":11479473556767,\"s\":\"BTCUSDT\",\"ps\":\"BTCUSDT\",\"b\":\"79543.90\",\"B\":\"6.336\",\"a\":\"79544.00\",\"A\":\"5.276\",\"T\":1788580715334,\"E\":1788580715334,\"st\":1}}"}
{"receive_ns":1788580715277697000,"stream":"btcusdt@bookTicker","event_type":"bookTicker","event_time_ms":1788580715334,"raw_json":"{\"stream\":\"btcusdt@bookTicker\",\"data\":{\"e\":\"bookTicker\",\"u\":11479473556786,\"s\":\"BTCUSDT\",\"ps\":\"BTCUSDT\",\"b\":\"79543.90\",\"B\":\"6.336\",\"a\":\"79544.00\",\"A\":\"5.274\",\"T\":1788580715334,\"E\":1788580715334,\"st\":1}}"}
{"receive_ns":1788580715278487000,"stream":"btcusdt@bookTicker","event_type":"bookTicker","event_time_ms":1788580715335,"raw_json":"{\"stream\":\"btcusdt@bookTicker\",\"data\":{\"e\":\"bookTicker\",\"u\":11479473556842,\"s\":\"BTCUSDT\",\"ps\":\"BTCUSDT\",\"b\":\"79543.90\",\"B\":\"6.335\",\"a\":\"79544.00\",\"A\":\"5.274\",\"T\":1788580715335,\"E\":1788580715335,\"st\":1}}"}
{"receive_ns":1788580715281578000,"stream":"btcusdt@bookTicker","event_type":"bookTicker","event_time_ms":1788580715337,"raw_json":"{\"stream\":\"btcusdt@bookTicker\",\"data\":{\"e\":\"bookTicker\",\"u\":11479473556985,\"s\":\"BTCUSDT\",\"ps\":\"BTCUSDT\",\"b\":\"79543.90\",\"B\":\"6.336\",\"a\":\"79544.00\",\"A\":\"5.274\",\"T\":1788580715337,\"E\":1788580715337,\"st\":1}}"}
{"receive_ns":1788580715285013000,"stream":"btcusdt@bookTicker","event_type":"bookTicker","event_time_ms":1788580715340,"raw_json":"{\"stream\":\"btcusdt@bookTicker\",\"data\":{\"e\":\"bookTicker\",\"u\":11479473557219,\"s\":\"BTCUSDT\",\"ps\":\"BTCUSDT\",\"b\":\"79543.90\",\"B\":\"6.336\",\"a\":\"79544.00\",\"A\":\"5.269\",\"T\":1788580715340,\"E\":1788580715340,\"st\":1}}"}
{"receive_ns":1788580715286296000,"stream":"btcusdt@bookTicker","event_type":"bookTicker","event_time_ms":1788580715343,"raw_json":"{\"stream\":\"btcusdt@bookTicker\",\"data\":{\"e\":\"bookTicker\",\"u\":11479473557416,\"s\":\"BTCUSDT\",\"ps\":\"BTCUSDT\",\"b\":\"79543.90\",\"B\":\"6.336\",\"a\":\"79544.00\",\"A\":\"5.275\",\"T\":1788580715342,\"E\":1788580715343,\"st\":1}}"}
{"receive_ns":1788580715334723000,"stream":"btcusdt@depth@100ms","event_type":"depthUpdate","event_time_ms":1788580715363,"raw_json":"{\"stream\":\"btcusdt@depth@100ms\",\"data\":{\"e\":\"depthUpdate\",\"E\":1788580715363,\"T\":1788580715362,\"s\":\"BTCUSDT\",\"ps\":\"BTCUSDT\",\"U\":11479473552831,\"u\":11479473558267,\"pu\":11479473552722,\"b\":[[\"29043.90\",\"1.897\"],[\"29143.90\",\"0.063\"],[\"29443.90\",\"0.140\"],[\"71589.50\",\"0.014\"],[\"75566.80\",\"0.008\"],[\"76362.10\",\"0.000\"],[\"77953.10\",\"0.009\"],[\"78430.30\",\"43.308\"],[\"78562.00\",\"6.989\"],[\"78589.40\",\"36.717\"],[\"78748.50\",\"7.735\"],[\"78902.30\",\"0.000\"],[\"79416.60\",\"0.302\"],[\"79419.80\",\"0.855\"],[\"79452.10\",\"6.054\"],[\"79456.40\",\"0.201\"],[\"79469.40\",\"0.015\"],[\"79469.50\",\"0.050\"],[\"79502.60\",\"0.001\"],[\"79515.40\",\"0.763\"],[\"79524.20\",\"2.147\"],[\"79525.00\",\"0.003\"],[\"79543.90\",\"6.336\"]],\"a\":[[\"79544.00\",\"5.275\"],[\"79550.00\",\"0.003\"],[\"79550.70\",\"0.000\"],[\"79551.30\",\"0.381\"],[\"79556.10\",\"0.460\"],[\"79557.60\",\"0.001\"],[\"79557.80\",\"0.001\"],[\"79561.50\",\"1.328\"],[\"79567.70\",\"0.078\"],[\"79634.70\",\"4.291\"],[\"79634.80\",\"0.001\"],[\"79644.80\",\"0.000\"],[\"79645.10\",\"0.032\"],[\"79666.20\",\"0.298\"],[\"79684.70\",\"0.006\"],[\"79685.00\",\"0.127\"],[\"79765.40\",\"19.997\"],[\"79939.70\",\"0.168\"],[\"80339.40\",\"8.341\"],[\"80521.40\",\"5.454\"],[\"80538.30\",\"5.943\"],[\"80647.30\",\"0.000\"]],\"st\":1}}"}
{"receive_ns":1788580715430274000,"stream":"btcusdt@bookTicker","event_type":"bookTicker","event_time_ms":1788580715462,"raw_json":"{\"stream\":\"btcusdt@bookTicker\",\"data\":{\"e\":\"bookTicker\",\"u\":11479473562712,\"s\":\"BTCUSDT\",\"ps\":\"BTCUSDT\",\"b\":\"79543.90\",\"B\":\"6.336\",\"a\":\"79544.00\",\"A\":\"5.258\",\"T\":1788580715462,\"E\":1788580715462,\"st\":1}}"}
{"receive_ns":1788580715430644000,"stream":"btcusdt@depth@100ms","event_type":"depthUpdate","event_time_ms":1788580715465,"raw_json":"{\"stream\":\"btcusdt@depth@100ms\",\"data\":{\"e\":\"depthUpdate\",\"E\":1788580715465,\"T\":1788580715464,\"s\":\"BTCUSDT\",\"ps\":\"BTCUSDT\",\"U\":11479473558336,\"u\":11479473562824,\"pu\":11479473558267,\"b\":[[\"1000.00\",\"25.354\"],[\"29043.90\",\"1.848\"],[\"29143.90\",\"0.000\"],[\"29443.90\",\"0.252\"],[\"71589.50\",\"0.014\"],[\"78430.30\",\"45.217\"],[\"78482.50\",\"10.047\"],[\"78589.40\",\"37.988\"],[\"78748.50\",\"7.737\"],[\"78800.60\",\"1.771\"],[\"78907.50\",\"7.712\"],[\"79146.20\",\"3.790\"],[\"79147.20\",\"6.208\"],[\"79416.60\",\"0.270\"],[\"79453.10\",\"0.020\"],[\"79456.40\",\"0.000\"],[\"79482.60\",\"1.669\"],[\"79517.30\",\"0.454\"],[\"79518.80\",\"0.002\"],[\"79524.30\",\"0.378\"],[\"79525.20\",\"0.000\"],[\"79527.80\",\"0.665\"],[\"79528.40\",\"0.177\"]],\"a\":[[\"79544.00\",\"5.258\"],[\"79549.00\",\"0.025\"],[\"79550.70\",\"0.008\"],[\"79617.60\",\"0.038\"],[\"79620.00\",\"20.418\"],[\"79668.10\",\"0.007\"],[\"79790.30\",\"11.056\"],[\"79790.40\",\"35.000\"],[\"79824.00\",\"5.547\"],[\"79936.40\",\"0.008\"],[\"79939.70\",\"0.019\"],[\"79941.70\",\"4.247\"],[\"80339.40\",\"8.341\"],[\"80498.50\",\"36.384\"]],\"st\":1}}"}
{"receive_ns":1788580715430834000,"stream":"btcusdt@bookTicker","event_type":"bookTicker","event_time_ms":1788580715465,"raw_json":"{\"stream\":\"btcusdt@bookTicker\",\"data\":{\"e\":\"bookTicker\",\"u\":11479473562876,\"s\":\"BTCUSDT\",\"ps\":\"BTCUSDT\",\"b\":\"79543.90\",\"B\":\"6.336\",\"a\":\"79544.00\",\"A\":\"5.281\",\"T\":1788580715465,\"E\":1788580715465,\"st\":1}}"}
{"receive_ns":1788580715431060000,"stream":"btcusdt@bookTicker","event_type":"bookTicker","event_time_ms":1788580715466,"raw_json":"{\"stream\":\"btcusdt@bookTicker\",\"data\":{\"e\":\"bookTicker\",\"u\":11479473562916,\"s\":\"BTCUSDT\",\"ps\":\"BTCUSDT\",\"b\":\"79543.90\",\"B\":\"6.336\",\"a\":\"79544.00\",\"A\":\"5.283\",\"T\":1788580715466,\"E\":1788580715466,\"st\":1}}"}
{"receive_ns":1788580715490971000,"stream":"btcusdt@bookTicker","event_type":"bookTicker","event_time_ms":1788580715514,"raw_json":"{\"stream\":\"btcusdt@bookTicker\",\"data\":{\"e\":\"bookTicker\",\"u\":11479473564721,\"s\":\"BTCUSDT\",\"ps\":\"BTCUSDT\",\"b\":\"79543.90\",\"B\":\"6.336\",\"a\":\"79544.00\",\"A\":\"5.236\",\"T\":1788580715514,\"E\":1788580715514,\"st\":1}}"}
{"receive_ns":1788580715491851000,"stream":"btcusdt@bookTicker","event_type":"bookTicker","event_time_ms":1788580715517,"raw_json":"{\"stream\":\"btcusdt@bookTicker\",\"data\":{\"e\":\"bookTicker\",\"u\":11479473564917,\"s\":\"BTCUSDT\",\"ps\":\"BTCUSDT\",\"b\":\"79543.90\",\"B\":\"6.336\",\"a\":\"79544.00\",\"A\":\"5.285\",\"T\":1788580715517,\"E\":1788580715517,\"st\":1}}"}
{"receive_ns":1788580715520381000,"stream":"btcusdt@depth@100ms","event_type":"depthUpdate","event_time_ms":1788580715567,"raw_json":"{\"stream\":\"btcusdt@depth@100ms\",\"data\":{\"e\":\"depthUpdate\",\"E\":1788580715567,\"T\":1788580715565,\"s\":\"BTCUSDT\",\"ps\":\"BTCUSDT\",\"U\":11479473562858,\"u\":11479473566788,\"pu\":11479473562824,\"b\":[[\"1000.00\",\"25.354\"],[\"29043.90\",\"1.666\"],[\"29443.90\",\"0.434\"],[\"71589.50\",\"0.014\"],[\"76362.10\",\"0.002\"],[\"78111.10\",\"1.156\"],[\"78748.50\",\"7.735\"],[\"78788.20\",\"1.897\"],[\"78907.50\",\"4.549\"],[\"79416.60\",\"0.317\"],[\"79456.40\",\"0.176\"],[\"79480.20\",\"2.182\"],[\"79488.20\",\"0.130\"],[\"79520.20\",\"2.395\"],[\"79527.80\",\"0.225\"],[\"79528.40\",\"0.617\"],[\"79529.10\",\"0.229\"]],\"a\":[[\"79544.00\",\"5.285\"],[\"79549.00\",\"0.033\"],[\"79550.00\",\"0.026\"],[\"79550.70\",\"0.000\"],[\"79554.20\",\"0.005\"],[\"79554.50\",\"0.155\"],[\"79560.10\",\"0.080\"],[\"79564.70\",\"0.002\"],[\"79565.30\",\"0.375\"],[\"79599.70\",\"0.052\"],[\"79620.00\",\"16.147\"],[\"79620.30\",\"0.006\"],[\"79625.60\",\"28.828\"],[\"79628.30\",\"0.000\"],[\"79668.10\",\"0.013\"],[\"79737.60\",\"0.000\"],[\"79939.70\",\"0.063\"],[\"79941.70\",\"4.310\"],[\"80272.70\",\"0.008\"],[\"80339.40\",\"8.341\"],[\"81134.80\",\"0.015\"],[\"81168.10\",\"0.005\"],[\"87498.40\",\"0.010\"]],\"st\":1}}"}
{"receive_ns":1788580715628599000,"stream":"btcusdt@depth@100ms","event_type":"depthUpdate","event_time_ms":1788580715669,"raw_json":"{\"stream\":\"btcusdt@depth@100ms\",\"data\":{\"e\":\"depthUpdate\",\"E\":1788580715669,\"T\":1788580715666,\"s\":\"BTCUSDT\",\"ps\":\"BTCUSDT\",\"U\":11479473566858,\"u\":11479473571682,\"pu\":11479473566788,\"b\":[[\"29043.90\",\"1.491\"],[\"29443.90\",\"0.609\"],[\"63635.00\",\"0.000\"],[\"71589.50\",\"0.014\"],[\"76362.10\",\"0.000\"],[\"78748.50\",\"7.735\"],[\"79399.50\",\"1.886\"],[\"79416.60\",\"0.308\"],[\"79472.30\",\"0.380\"],[\"79502.20\",\"0.272\"],[\"79514.80\",\"0.015\"],[\"79524.30\",\"0.005\"],[\"79525.70\",\"0.376\"],[\"79529.50\",\"0.003\"],[\"79538.50\",\"0.068\"],[\"79539.30\",\"0.008\"]],\"a\":[[\"79548.40\",\"0.000\"],[\"79549.00\",\"0.025\"],[\"79549.20\",\"0.449\"],[\"79550.70\",\"0.008\"],[\"79557.10\",\"0.001\"],[\"79565.40\",\"2.930\"],[\"79571.10\",\"0.002\"],[\"79577.50\",\"0.252\"],[\"79590.70\",\"0.052\"],[\"79615.60\",\"0.006\"],[\"79620.30\",\"28.634\"],[\"79625.60\",\"0.200\"],[\"79667.70\",\"1.912\"],[\"79742.90\",\"0.004\"],[\"79939.70\",\"0.068\"],[\"80283.00\",\"0.000\"],[\"80339.40\",\"8.341\"],[\"87498.40\",\"0.009\"]],\"st\":1}}"}
{"receive_ns":1788580715628998000,"stream":"btcusdt@bookTicker","event_type":"bookTicker","event_time_ms":1788580715670,"raw_json":"{\"stream\":\"btcusdt@bookTicker\",\"data\":{\"e\":\"bookTicker\",\"u\":11479473571928,\"s\":\"BTCUSDT\",\"ps\":\"BTCUSDT\",\"b\":\"79543.90\",\"B\":\"6.335\",\"a\":\"79544.00\",\"A\":\"5.285\",\"T\":1788580715669,\"E\":1788580715670,\"st\":1}}"}
{"receive_ns":1788580715629237000,"stream":"btcusdt@trade","event_type":"trade","event_time_ms":1788580715670,"raw_json":"{\"stream\":\"btcusdt@trade\",\"data\":{\"e\":\"trade\",\"E\":1788580715670,\"T\":1788580715669,\"s\":\"BTCUSDT\",\"t\":8054266683,\"p\":\"79543.90\",\"q\":\"0.001\",\"X\":\"MARKET\",\"m\":true,\"st\":1}}"}
{"receive_ns":1788580715713859000,"stream":"btcusdt@depth@100ms","event_type":"depthUpdate","event_time_ms":1788580715771,"raw_json":"{\"stream\":\"btcusdt@depth@100ms\",\"data\":{\"e\":\"depthUpdate\",\"E\":1788580715771,\"T\":1788580715769,\"s\":\"BTCUSDT\",\"ps\":\"BTCUSDT\",\"U\":11479473571923,\"u\":11479473580049,\"pu\":11479473571682,\"b\":[[\"1000.00\",\"25.354\"],[\"29043.90\",\"1.309\"],[\"29443.90\",\"0.791\"],[\"71589.50\",\"0.014\"],[\"76362.10\",\"0.002\"],[\"78357.00\",\"0.223\"],[\"78629.10\",\"5.697\"],[\"78748.50\",\"7.735\"],[\"78907.50\",\"7.712\"],[\"79146.20\",\"3.780\"],[\"79416.60\",\"0.283\"],[\"79453.10\",\"0.020\"],[\"79456.40\",\"0.201\"],[\"79458.50\",\"0.198\"],[\"79460.20\",\"0.001\"],[\"79480.20\",\"2.163\"],[\"79481.30\",\"0.001\"],[\"79495.60\",\"0.025\"],[\"79499.70\",\"0.370\"],[\"79499.90\",\"0.004\"],[\"79517.30\",\"0.002\"],[\"79518.80\",\"0.454\"],[\"79529.50\",\"0.009\"],[\"79538.60\",\"0.440\"],[\"79539.20\",\"1.006\"],[\"79539.30\",\"0.002\"],[\"79543.90\",\"6.335\"]],\"a\":[[\"79550.00\",\"0.021\"],[\"79556.50\",\"0.001\"],[\"79557.30\",\"0.076\"],[\"79568.40\",\"2.099\"],[\"79571.20\",\"0.000\"],[\"79617.60\",\"0.038\"],[\"79936.40\",\"0.008\"],[\"79939.70\",\"0.131\"],[\"79941.70\",\"4.247\"],[\"80339.40\",\"8.341\"],[\"80515.00\",\"0.011\"],[\"81134.80\",\"0.012\"],[\"81134.90\",\"3.139\"],[\"87498.40\",\"0.009\"]],\"st\":1}}"}
{"receive_ns":1788580715755919000,"stream":"btcusdt@bookTicker","event_type":"bookTicker","event_time_ms":1788580715811,"raw_json":"{\"stream\":\"btcusdt@bookTicker\",\"data\":{\"e\":\"bookTicker\",\"u\":11479473582126,\"s\":\"BTCUSDT\",\"ps\":\"BTCUSDT\",\"b\":\"79543.90\",\"B\":\"6.334\",\"a\":\"79544.00\",\"A\":\"5.285\",\"T\":1788580715811,\"E\":1788580715811,\"st\":1}}"}
{"receive_ns":1788580715757700000,"stream":"btcusdt@bookTicker","event_type":"bookTicker","event_time_ms":1788580715813,"raw_json":"{\"stream\":\"btcusdt@bookTicker\",\"data\":{\"e\":\"bookTicker\",\"u\":11479473582247,\"s\":\"BTCUSDT\",\"ps\":\"BTCUSDT\",\"b\":\"79543.90\",\"B\":\"6.335\",\"a\":\"79544.00\",\"A\":\"5.285\",\"T\":1788580715813,\"E\":1788580715813,\"st\":1}}"}
{"receive_ns":1788580715825180000,"stream":"btcusdt@bookTicker","event_type":"bookTicker","event_time_ms":1788580715871,"raw_json":"{\"stream\":\"btcusdt@bookTicker\",\"data\":{\"e\":\"bookTicker\",\"u\":11479473584864,\"s\":\"BTCUSDT\",\"ps\":\"BTCUSDT\",\"b\":\"79543.90\",\"B\":\"6.334\",\"a\":\"79544.00\",\"A\":\"5.285\",\"T\":1788580715871,\"E\":1788580715871,\"st\":1}}"}
{"receive_ns":1788580715825403000,"stream":"btcusdt@trade","event_type":"trade","event_time_ms":1788580715871,"raw_json":"{\"stream\":\"btcusdt@trade\",\"data\":{\"e\":\"trade\",\"E\":1788580715871,\"T\":1788580715871,\"s\":\"BTCUSDT\",\"t\":8054266684,\"p\":\"79543.90\",\"q\":\"0.001\",\"X\":\"MARKET\",\"m\":true,\"st\":1}}"}
{"receive_ns":1788580715825772000,"stream":"btcusdt@depth@100ms","event_type":"depthUpdate","event_time_ms":1788580715873,"raw_json":"{\"stream\":\"btcusdt@depth@100ms\",\"data\":{\"e\":\"depthUpdate\",\"E\":1788580715873,\"T\":1788580715872,\"s\":\"BTCUSDT\",\"ps\":\"BTCUSDT\",\"U\":11479473580181,\"u\":11479473584944,\"pu\":11479473580049,\"b\":[[\"1000.00\",\"25.354\"],[\"29043.90\",\"1.134\"],[\"29443.90\",\"0.966\"],[\"63635.00\",\"0.000\"],[\"71589.50\",\"0.014\"],[\"78624.70\",\"0.057\"],[\"78748.50\",\"7.737\"],[\"79416.60\",\"0.273\"],[\"79419.80\",\"0.511\"],[\"79419.90\",\"0.497\"],[\"79456.40\",\"0.211\"],[\"79459.50\",\"1.544\"],[\"79474.60\",\"0.001\"],[\"79477.20\",\"22.856\"],[\"79480.20\",\"2.187\"],[\"79501.90\",\"0.215\"],[\"79502.00\",\"0.042\"],[\"79502.10\",\"0.021\"],[\"79507.30\",\"2.002\"],[\"79543.90\",\"6.334\"]],\"a\":[[\"79550.00\",\"0.003\"],[\"79666.20\",\"0.425\"],[\"79939.70\",\"0.131\"],[\"80339.40\",\"8.343\"],[\"81134.80\",\"0.015\"]],\"st\":1}}"}
{"receive_ns":1788580715918041000,"stream":"btcusdt@depth@100ms","event_type":"depthUpdate","event_time_ms":1788580715975,"raw_json":"{\"stream\":\"btcusdt@depth@100ms\",\"data\":{\"e\":\"depthUpdate\",\"E\":1788580715975,\"T\":1788580715973,\"s\":\"BTCUSDT\",\"ps\":\"BTCUSDT\",\"U\":11479473585036,\"u\":11479473589067,\"pu\":11479473584944,\"b\":[[\"29043.90\",\"0.952\"],[\"29443.90\",\"1.148\"],[\"71589.50\",\"0.014\"],[\"76362.10\",\"0.000\"],[\"78311.00\",\"8.275\"],[\"78522.30\",\"16.979\"],[\"78748.50\",\"7.735\"],[\"79146.10\",\"0.008\"],[\"79416.60\",\"0.166\"],[\"79453.10\",\"0.000\"],[\"79455.10\",\"0.662\"],[\"79456.40\",\"0.318\"],[\"79458.10\",\"0.183\"],[\"79476.00\",\"1.485\"],[\"79477.20\",\"0.028\"],[\"79480.00\",\"23.312\"]],\"a\":[[\"79617.20\",\"0.084\"],[\"79617.30\",\"0.015\"],[\"79617.60\",\"0.024\"],[\"79626.30\",\"0.001\"],[\"79936.40\",\"0.008\"],[\"79937.70\",\"0.041\"],[\"79939.70\",\"0.131\"],[\"79941.80\",\"0.000\"],[\"80339.40\",\"8.341\"],[\"80498.50\",\"37.006\"],[\"80578.30\",\"1.929\"],[\"80697.40\",\"12.310\"],[\"80776.90\",\"5.223\"]],\"st\":1}}"}
{"receive_ns":1788580716022246000,"stream":"btcusdt@bookTicker","event_type":"bookTicker","event_time_ms":1788580716052,"raw_json":"{\"stream\":\"btcusdt@bookTicker\",\"data\":{\"e\":\"bookTicker\",\"u\":11479473593000,\"s\":\"BTCUSDT\",\"ps\":\"BTCUSDT\",\"b\":\"79543.90\",\"B\":\"6.334\",\"a\":\"79544.00\",\"A\":\"5.282\",\"T\":1788580716052,\"E\":1788580716052,\"st\":1}}"}
{"receive_ns":1788580716023182000,"stream":"btcusdt@bookTicker","event_type":"bookTicker","event_time_ms":1788580716053,"raw_json":"{\"stream\":\"btcusdt@bookTicker\",\"data\":{\"e\":\"bookTicker\",\"u\":11479473593065,\"s\":\"BTCUSDT\",\"ps\":\"BTCUSDT\",\"b\":\"79543.90\",\"B\":\"6.334\",\"a\":\"79544.00\",\"A\":\"5.276\",\"T\":1788580716053,\"E\":1788580716053,\"st\":1}}"}
{"receive_ns":1788580716023338000,"stream":"btcusdt@bookTicker","event_type":"bookTicker","event_time_ms":1788580716057,"raw_json":"{\"stream\":\"btcusdt@bookTicker\",\"data\":{\"e\":\"bookTicker\",\"u\":11479473593312,\"s\":\"BTCUSDT\",\"ps\":\"BTCUSDT\",\"b\":\"79543.90\",\"B\":\"6.334\",\"a\":\"79544.00\",\"A\":\"5.283\",\"T\":1788580716057,\"E\":1788580716057,\"st\":1}}"}
{"receive_ns":1788580716023629000,"stream":"btcusdt@depth@100ms","event_type":"depthUpdate","event_time_ms":1788580716077,"raw_json":"{\"stream\":\"btcusdt@depth@100ms\",\"data\":{\"e\":\"depthUpdate\",\"E\":1788580716077,\"T\":1788580716073,\"s\":\"BTCUSDT\",\"ps\":\"BTCUSDT\",\"U\":11479473589117,\"u\":11479473594045,\"pu\":11479473589067,\"b\":[[\"1000.00\",\"25.354\"],[\"29043.90\",\"0.777\"],[\"29443.90\",\"1.323\"],[\"63635.00\",\"0.000\"],[\"71589.50\",\"0.014\"],[\"71623.00\",\"0.000\"],[\"76362.10\",\"0.002\"],[\"78748.50\",\"7.735\"],[\"79146.10\",\"0.009\"],[\"79146.20\",\"3.790\"],[\"79448.40\",\"0.006\"],[\"79456.40\",\"0.308\"],[\"79472.30\",\"0.378\"],[\"79488.20\",\"0.128\"],[\"79529.60\",\"0.002\"],[\"79538.60\",\"0.437\"],[\"79539.00\",\"1.005\"],[\"79539.30\",\"0.000\"]],\"a\":[[\"79544.00\",\"5.283\"],[\"79546.40\",\"0.001\"],[\"79547.20\",\"0.029\"],[\"79599.70\",\"0.052\"],[\"79615.60\",\"0.004\"],[\"79939.70\",\"0.126\"],[\"79941.80\",\"0.001\"],[\"80339.40\",\"8.341\"],[\"80766.60\",\"0.002\"]],\"st\":1}}"}
{"receive_ns":1788580716088382000,"stream":"btcusdt@bookTicker","event_type":"bookTicker","event_time_ms":1788580716127,"raw_json":"{\"stream\":\"btcusdt@bookTicker\",\"data\":{\"e\":\"bookTicker\",\"u\":11479473597095,\"s\":\"BTCUSDT\",\"ps\":\"BTCUSDT\",\"b\":\"79543.90\",\"B\":\"6.334\",\"a\":\"79544.00\",\"A\":\"5.266\",\"T\":1788580716126,\"E\":1788580716127,\"st\":1}}"}
{"receive_ns":1788580716088599000,"stream":"btcusdt@bookTicker","event_type":"bookTicker","event_time_ms":1788580716129,"raw_json":"{\"stream\":\"btcusdt@bookTicker\",\"data\":{\"e\":\"bookTicker\",\"u\":11479473597259,\"s\":\"BTCUSDT\",\"ps\":\"BTCUSDT\",\"b\":\"79543.90\",\"B\":\"6.334\",\"a\":\"79544.00\",\"A\":\"5.277\",\"T\":1788580716129,\"E\":1788580716129,\"st\":1}}"}
{"receive_ns":1788580716169549000,"stream":"btcusdt@depth@100ms","event_type":"depthUpdate","event_time_ms":1788580716179,"raw_json":"{\"stream\":\"btcusdt@depth@100ms\",\"data\":{\"e\":\"depthUpdate\",\"E\":1788580716179,\"T\":1788580716177,\"s\":\"BTCUSDT\",\"ps\":\"BTCUSDT\",\"U\":11479473594254,\"u\":11479473600295,\"pu\":11479473594045,\"b\":[[\"1000.00\",\"25.354\"],[\"29043.90\",\"0.595\"],[\"29443.90\",\"1.505\"],[\"63635.00\",\"0.000\"],[\"71589.50\",\"0.014\"],[\"75756.10\",\"0.001\"],[\"76362.10\",\"0.000\"],[\"78223.70\",\"0.000\"],[\"78422.30\",\"1.782\"],[\"78748.50\",\"7.735\"],[\"79419.90\",\"0.016\"],[\"79455.10\",\"0.642\"],[\"79456.40\",\"0.243\"]],\"a\":[[\"79544.00\",\"5.277\"],[\"79576.80\",\"2.717\"],[\"79617.60\",\"0.001\"],[\"79624.70\",\"0.514\"],[\"79625.20\",\"0.004\"],[\"79625.30\",\"0.000\"],[\"79633.10\",\"0.000\"],[\"79637.30\",\"0.000\"],[\"79637.40\",\"0.001\"],[\"79666.20\",\"0.000\"],[\"79936.40\",\"0.001\"],[\"79937.70\",\"0.004\"],[\"79939.70\",\"0.117\"],[\"80339.40\",\"8.341\"],[\"81771.20\",\"0.731\"]],\"st\":1}}"}
{"receive_ns":1788580716170465000,"stream":"btcusdt@bookTicker","event_type":"bookTicker","event_time_ms":1788580716221,"raw_json":"{\"stream\":\"btcusdt@bookTicker\",\"data\":{\"e\":\"bookTicker\",\"u\":11479473602828,\"s\":\"BTCUSDT\",\"ps\":\"BTCUSDT\",\"b\":\"79543.90\",\"B\":\"6.333\",\"a\":\"79544.00\",\"A\":\"5.277\",\"T\":1788580716221,\"E\":1788580716221,\"st\":1}}"}
{"receive_ns":1788580716170675000,"stream":"btcusdt@bookTicker","event_type":"bookTicker","event_time_ms":1788580716223,"raw_json":"{\"stream\":\"btcusdt@bookTicker\",\"data\":{\"e\":\"bookTicker\",\"u\":11479473602966,\"s\":\"BTCUSDT\",\"ps\":\"BTCUSDT\",\"b\":\"79543.90\",\"B\":\"6.334\",\"a\":\"79544.00\",\"A\":\"5.277\",\"T\":1788580716223,\"E\":1788580716223,\"st\":1}}"}
{"receive_ns":1788580716239143000,"stream":"btcusdt@depth@100ms","event_type":"depthUpdate","event_time_ms":1788580716281,"raw_json":"{\"stream\":\"btcusdt@depth@100ms\",\"data\":{\"e\":\"depthUpdate\",\"E\":1788580716281,\"T\":1788580716280,\"s\":\"BTCUSDT\",\"ps\":\"BTCUSDT\",\"U\":11479473600400,\"u\":11479473606245,\"pu\":11479473600295,\"b\":[[\"29043.90\",\"0.420\"],[\"29443.90\",\"1.680\"],[\"63635.10\",\"0.000\"],[\"71589.50\",\"0.014\"],[\"76362.10\",\"0.002\"],[\"78549.60\",\"9.354\"],[\"78748.50\",\"8.369\"],[\"79146.20\",\"3.780\"],[\"79452.40\",\"0.283\"],[\"79453.10\",\"0.020\"],[\"79454.70\",\"0.000\"],[\"79456.40\",\"0.085\"],[\"79482.50\",\"0.628\"],[\"79502.00\",\"0.041\"],[\"79502.40\",\"0.005\"],[\"79543.90\",\"6.334\"]],\"a\":[[\"79577.60\",\"0.081\"],[\"79588.00\",\"0.244\"],[\"79607.90\",\"0.001\"],[\"79617.60\",\"0.006\"],[\"79624.60\",\"0.000\"],[\"79624.80\",\"1.753\"],[\"79635.80\",\"0.000\"],[\"79636.20\",\"0.003\"],[\"79640.80\",\"0.001\"],[\"79936.40\",\"0.008\"],[\"79937.70\",\"0.041\"],[\"79939.70\",\"0.149\"],[\"80339.40\",\"8.341\"],[\"80498.50\",\"38.247\"]],\"st\":1}}"}
{"receive_ns":1788580716382101000,"stream":"btcusdt@depth@100ms","event_type":"depthUpdate","event_time_ms":1788580716383,"raw_json":"{\"stream\":\"btcusdt@depth@100ms\",\"data\":{\"e\":\"depthUpdate\",\"E\":1788580716383,\"T\":1788580716381,\"s\":\"BTCUSDT\",\"ps\":\"BTCUSDT\",\"U\":11479473606257,\"u\":11479473611134,\"pu\":11479473606245,\"b\":[[\"1000.00\",\"25.354\"],[\"29043.90\",\"0.273\"],[\"29343.90\",\"0.035\"],[\"29443.90\",\"1.792\"],[\"71589.50\",\"0.014\"],[\"78191.70\",\"7.023\"],[\"78333.20\",\"0.000\"],[\"78748.50\",\"8.369\"],[\"79146.20\",\"3.790\"],[\"79398.60\",\"0.078\"],[\"79401.50\",\"0.017\"],[\"79414.90\",\"3.146\"],[\"79415.00\",\"0.133\"],[\"79415.30\",\"1.992\"],[\"79438.40\",\"0.686\"],[\"79452.10\",\"3.146\"],[\"79452.40\",\"0.293\"],[\"79456.40\",\"0.075\"],[\"79458.10\",\"0.058\"],[\"79460.40\",\"0.001\"],[\"79478.20\",\"0.263\"],[\"79480.20\",\"2.166\"],[\"79502.00\",\"0.891\"]],\"a\":[[\"79545.20\",\"0.028\"],[\"79554.70\",\"0.004\"],[\"79562.20\",\"0.253\"],[\"79600.90\",\"0.002\"],[\"79617.20\",\"0.072\"],[\"79620.00\",\"20.417\"],[\"79632.50\",\"1.468\"],[\"79634.70\",\"0.378\"],[\"79639.50\",\"0.022\"],[\"79672.60\",\"1.106\"],[\"79675.60\",\"0.000\"],[\"79696.80\",\"1.704\"],[\"79939.70\",\"0.149\"],[\"80339.40\",\"8.341\"],[\"80670.40\",\"16.734\"]],\"st\":1}}"}
{"receive_ns":1788580716433946000,"stream":"btcusdt@depth@100ms","event_type":"depthUpdate","event_time_ms":1788580716485,"raw_json":"{\"stream\":\"btcusdt@depth@100ms\",\"data\":{\"e\":\"depthUpdate\",\"E\":1788580716485,\"T\":1788580716484,\"s\":\"BTCUSDT\",\"ps\":\"BTCUSDT\",\"U\":11479473611178,\"u\":11479473615662,\"pu\":11479473611134,\"b\":[[\"1000.00\",\"25.354\"],[\"29043.90\",\"0.161\"],[\"29343.90\",\"0.098\"],[\"29443.90\",\"1.841\"],[\"71589.50\",\"0.014\"],[\"75566.80\",\"0.006\"],[\"76362.10\",\"0.000\"],[\"78357.00\",\"0.000\"],[\"78748.50\",\"8.369\"],[\"79406.70\",\"0.123\"],[\"79407.00\",\"0.034\"],[\"79452.10\",\"6.024\"],[\"79452.40\",\"0.060\"],[\"79453.10\",\"0.000\"],[\"79454.70\",\"6.000\"],[\"79455.10\",\"0.662\"],[\"79456.40\",\"0.201\"],[\"79459.90\",\"0.125\"],[\"79482.50\",\"4.128\"],[\"79501.90\",\"0.216\"],[\"79502.40\",\"0.558\"]],\"a\":[[\"79557.30\",\"0.000\"],[\"79588.00\",\"0.809\"],[\"79607.90\",\"3.501\"],[\"79617.60\",\"0.001\"],[\"79634.70\",\"4.282\"],[\"79635.70\",\"6.000\"],[\"79696.80\",\"1.698\"],[\"79765.40\",\"20.551\"],[\"79933.80\",\"0.005\"],[\"79936.40\",\"0.008\"],[\"79937.70\",\"0.004\"],[\"79939.70\",\"0.186\"],[\"80339.40\",\"8.341\"],[\"80925.00\",\"1.056\"]],\"st\":1}}"}
{"receive_ns":1788580716497871000,"stream":"btcusdt@bookTicker","event_type":"bookTicker","event_time_ms":1788580716521,"raw_json":"{\"stream\":\"btcusdt@bookTicker\",\"data\":{\"e\":\"bookTicker\",\"u\":11479473617718,\"s\":\"BTCUSDT\",\"ps\":\"BTCUSDT\",\"b\":\"79543.90\",\"B\":\"6.334\",\"a\":\"79544.00\",\"A\":\"5.228\",\"T\":1788580716520,\"E\":1788580716521,\"st\":1}}"}
{"receive_ns":1788580716553401000,"stream":"btcusdt@bookTicker","event_type":"bookTicker","event_time_ms":1788580716524,"raw_json":"{\"stream\":\"btcusdt@bookTicker\",\"data\":{\"e\":\"bookTicker\",\"u\":11479473617934,\"s\":\"BTCUSDT\",\"ps\":\"BTCUSDT\",\"b\":\"79543.90\",\"B\":\"6.334\",\"a\":\"79544.00\",\"A\":\"5.280\",\"T\":1788580716523,\"E\":1788580716524,\"st\":1}}"}
{"receive_ns":1788580716553695000,"stream":"btcusdt@bookTicker","event_type":"bookTicker","event_time_ms":1788580716548,"raw_json":"{\"stream\":\"btcusdt@bookTicker\",\"data\":{\"e\":\"bookTicker\",\"u\":11479473619173,\"s\":\"BTCUSDT\",\"ps\":\"BTCUSDT\",\"b\":\"79543.90\",\"B\":\"6.334\",\"a\":\"79544.00\",\"A\":\"5.282\",\"T\":1788580716548,\"E\":1788580716548,\"st\":1}}"}
{"receive_ns":1788580716560143000,"stream":"btcusdt@depth@100ms","event_type":"depthUpdate","event_time_ms":1788580716587,"raw_json":"{\"stream\":\"btcusdt@depth@100ms\",\"data\":{\"e\":\"depthUpdate\",\"E\":1788580716587,\"T\":1788580716585,\"s\":\"BTCUSDT\",\"ps\":\"BTCUSDT\",\"U\":11479473615688,\"u\":11479473620501,\"pu\":11479473615662,\"b\":[[\"29043.90\",\"0.035\"],[\"29343.90\",\"0.154\"],[\"29443.90\",\"1.911\"],[\"63635.00\",\"0.000\"],[\"71589.50\",\"0.014\"],[\"76362.10\",\"0.002\"],[\"78311.00\",\"9.168\"],[\"78748.50\",\"8.369\"],[\"79146.20\",\"3.780\"],[\"79332.60\",\"0.006\"],[\"79332.80\",\"4.869\"],[\"79335.50\",\"1.154\"],[\"79380.40\",\"0.000\"],[\"79380.50\",\"2.109\"],[\"79415.00\",\"10.133\"],[\"79415.30\",\"3.273\"],[\"79419.90\",\"0.497\"],[\"79452.40\",\"0.050\"],[\"79456.40\",\"0.211\"],[\"79459.90\",\"0.000\"],[\"79474.60\",\"22.829\"],[\"79476.00\",\"4.357\"],[\"79480.00\",\"0.484\"],[\"79503.70\",\"0.864\"],[\"79520.20\",\"2.395\"]],\"a\":[[\"79544.00\",\"5.282\"],[\"79560.10\",\"0.080\"],[\"79639.50\",\"0.000\"],[\"79666.20\",\"0.425\"],[\"79668.10\",\"0.007\"],[\"79672.60\",\"2.456\"],[\"79675.60\",\"10.000\"],[\"79705.60\",\"1.921\"],[\"79753.20\",\"0.727\"],[\"79753.30\",\"4.791\"],[\"79939.70\",\"0.186\"],[\"80339.40\",\"8.341\"]],\"st\":1}}"}
{"receive_ns":1788580716634324000,"stream":"btcusdt@depth@100ms","event_type":"depthUpdate","event_time_ms":1788580716689,"raw_json":"{\"stream\":\"btcusdt@depth@100ms\",\"data\":{\"e\":\"depthUpdate\",\"E\":1788580716689,\"T\":1788580716688,\"s\":\"BTCUSDT\",\"ps\":\"BTCUSDT\",\"U\":11479473620562,\"u\":11479473624282,\"pu\":11479473620501,\"b\":[[\"1000.00\",\"25.354\"],[\"29043.90\",\"0.000\"],[\"29343.90\",\"0.294\"],[\"29443.90\",\"1.806\"],[\"71589.50\",\"0.014\"],[\"76362.10\",\"0.000\"],[\"77953.10\",\"0.012\"],[\"78414.40\",\"0.612\"],[\"78426.80\",\"0.000\"],[\"78748.50\",\"8.369\"],[\"79358.30\",\"3.144\"],[\"79358.60\",\"0.020\"],[\"79401.50\",\"0.011\"],[\"79406.70\",\"0.016\"],[\"79415.10\",\"0.024\"],[\"79453.10\",\"0.020\"],[\"79455.10\",\"0.642\"],[\"79456.40\",\"0.085\"],[\"79457.70\",\"0.039\"],[\"79457.90\",\"0.033\"],[\"79460.90\",\"0.128\"],[\"79474.60\",\"0.001\"],[\"79476.00\",\"1.485\"],[\"79477.20\",\"22.850\"],[\"79525.10\",\"0.410\"],[\"79525.70\",\"0.003\"]],\"a\":[[\"79556.20\",\"0.077\"],[\"79564.80\",\"0.441\"],[\"79564.90\",\"0.002\"],[\"79565.30\",\"0.002\"],[\"79566.20\",\"0.430\"],[\"79567.40\",\"0.000\"],[\"79617.20\",\"0.078\"],[\"79617.60\",\"0.038\"],[\"79632.80\",\"0.040\"],[\"79633.00\",\"0.000\"],[\"79686.70\",\"3.167\"],[\"79687.00\",\"0.000\"],[\"79933.80\",\"0.000\"],[\"79936.40\",\"0.001\"],[\"79939.70\",\"0.019\"],[\"80339.40\",\"8.341\"]],\"st\":1}}"}
{"receive_ns":1788580716688051000,"stream":"btcusdt@bookTicker","event_type":"bookTicker","event_time_ms":1788580716743,"raw_json":"{\"stream\":\"btcusdt@bookTicker\",\"data\":{\"e\":\"bookTicker\",\"u\":11479473626902,\"s\":\"BTCUSDT\",\"ps\":\"BTCUSDT\",\"b\":\"79543.90\",\"B\":\"6.334\",\"a\":\"79544.00\",\"A\":\"5.259\",\"T\":1788580716742,\"E\":1788580716743,\"st\":1}}"}
{"receive_ns":1788580716697379000,"stream":"btcusdt@bookTicker","event_type":"bookTicker","event_time_ms":1788580716746,"raw_json":"{\"stream\":\"btcusdt@bookTicker\",\"data\":{\"e\":\"bookTicker\",\"u\":11479473627142,\"s\":\"BTCUSDT\",\"ps\":\"BTCUSDT\",\"b\":\"79543.90\",\"B\":\"6.334\",\"a\":\"79544.00\",\"A\":\"5.283\",\"T\":1788580716745,\"E\":1788580716746,\"st\":1}}"}
{"receive_ns":1788580716748351000,"stream":"btcusdt@depth@100ms","event_type":"depthUpdate","event_time_ms":1788580716791,"raw_json":"{\"stream\":\"btcusdt@depth@100ms\",\"data\":{\"e\":\"depthUpdate\",\"E\":1788580716791,\"T\":1788580716790,\"s\":\"BTCUSDT\",\"ps\":\"BTCUSDT\",\"U\":11479473624345,\"u\":11479473629098,\"pu\":11479473624282,\"b\":[[\"1000.00\",\"25.354\"],[\"29343.90\",\"0.476\"],[\"29443.90\",\"1.624\"],[\"71589.50\",\"0.014\"],[\"76362.10\",\"0.002\"],[\"78589.40\",\"39.259\"],[\"78748.50\",\"8.369\"],[\"79456.40\",\"0.318\"],[\"79460.10\",\"2.266\"],[\"79461.10\",\"0.013\"]],\"a\":[[\"79544.00\",\"5.283\"],[\"79617.60\",\"0.061\"],[\"79936.40\",\"0.008\"],[\"79939.70\",\"0.131\"],[\"80339.40\",\"8.341\"],[\"80799.90\",\"1.731\"]],\"st\":1}}"}
{"receive_ns":1788580716774791000,"stream":"btcusdt@bookTicker","event_type":"bookTicker","event_time_ms":1788580716808,"raw_json":"{\"stream\":\"btcusdt@bookTicker\",\"data\":{\"e\":\"bookTicker\",\"u\":11479473629703,\"s\":\"BTCUSDT\",\"ps\":\"BTCUSDT\",\"b\":\"79543.90\",\"B\":\"6.333\",\"a\":\"79544.00\",\"A\":\"5.283\",\"T\":1788580716808,\"E\":1788580716808,\"st\":1}}"}
{"receive_ns":1788580716775010000,"stream":"btcusdt@bookTicker","event_type":"bookTicker","event_time_ms":1788580716810,"raw_json":"{\"stream\":\"btcusdt@bookTicker\",\"data\":{\"e\":\"bookTicker\",\"u\":11479473629827,\"s\":\"BTCUSDT\",\"ps\":\"BTCUSDT\",\"b\":\"79543.90\",\"B\":\"6.334\",\"a\":\"79544.00\",\"A\":\"5.283\",\"T\":1788580716810,\"E\":1788580716810,\"st\":1}}"}
{"receive_ns":1788580716866032000,"stream":"btcusdt@depth@100ms","event_type":"depthUpdate","event_time_ms":1788580716893,"raw_json":"{\"stream\":\"btcusdt@depth@100ms\",\"data\":{\"e\":\"depthUpdate\",\"E\":1788580716893,\"T\":1788580716890,\"s\":\"BTCUSDT\",\"ps\":\"BTCUSDT\",\"U\":11479473629199,\"u\":11479473632761,\"pu\":11479473629098,\"b\":[[\"29343.90\",\"0.651\"],[\"29443.90\",\"1.449\"],[\"71589.50\",\"0.014\"],[\"78600.20\",\"0.181\"],[\"78601.90\",\"0.000\"],[\"78612.20\",\"0.004\"],[\"78614.80\",\"0.002\"],[\"78748.50\",\"8.369\"],[\"79146.20\",\"3.790\"],[\"79419.90\",\"0.016\"],[\"79454.80\",\"0.026\"],[\"79456.40\",\"0.318\"],[\"79459.80\",\"0.002\"],[\"79460.10\",\"2.141\"],[\"79460.30\",\"0.018\"],[\"79543.90\",\"6.334\"]],\"a\":[[\"79620.00\",\"16.147\"],[\"79620.30\",\"0.006\"],[\"79628.30\",\"28.583\"],[\"79666.20\",\"0.000\"],[\"79668.10\",\"0.013\"],[\"79939.70\",\"0.131\"],[\"80339.40\",\"8.341\"]],\"st\":1}}"}
{"receive_ns":1788580716939909000,"stream":"btcusdt@depth@100ms","event_type":"depthUpdate","event_time_ms":1788580716995,"raw_json":"{\"stream\":\"btcusdt@depth@100ms\",\"data\":{\"e\":\"depthUpdate\",\"E\":1788580716995,\"T\":1788580716994,\"s\":\"BTCUSDT\",\"ps\":\"BTCUSDT\",\"U\":11479473632855,\"u\":11479473636574,\"pu\":11479473632761,\"b\":[[\"1000.00\",\"25.354\"],[\"29343.90\",\"0.833\"],[\"29443.90\",\"1.267\"],[\"71589.50\",\"0.014\"],[\"76362.10\",\"0.000\"],[\"78390.50\",\"9.047\"],[\"78442.60\",\"26.100\"],[\"78503.50\",\"0.223\"],[\"78554.60\",\"0.001\"],[\"78748.50\",\"8.369\"],[\"79419.90\",\"0.497\"],[\"79453.10\",\"0.020\"],[\"79454.80\",\"0.038\"],[\"79456.40\",\"0.318\"],[\"79460.40\",\"0.126\"],[\"79517.30\",\"0.454\"],[\"79518.80\",\"0.002\"],[\"79524.20\",\"2.520\"],[\"79525.10\",\"0.037\"],[\"79527.80\",\"0.225\"],[\"79528.40\",\"0.177\"],[\"79529.10\",\"0.669\"]],\"a\":[[\"79556.20\",\"0.001\"],[\"79557.20\",\"0.336\"],[\"79564.10\",\"0.451\"],[\"79565.30\",\"0.375\"],[\"79566.20\",\"0.057\"],[\"79567.10\",\"0.014\"],[\"79568.30\",\"0.857\"],[\"79569.20\",\"0.055\"],[\"79617.60\",\"0.024\"],[\"79620.30\",\"28.589\"],[\"79625.60\",\"0.200\"],[\"79628.30\",\"0.000\"],[\"79666.20\",\"0.425\"],[\"79936.40\",\"0.008\"],[\"79937.70\",\"0.041\"],[\"79939.70\",\"0.131\"],[\"80339.40\",\"8.341\"],[\"80590.90\",\"1.375\"],[\"80657.60\",\"37.834\"],[\"80799.90\",\"0.866\"]],\"st\":1}}"}
{"receive_ns":1788580717100574000,"stream":"btcusdt@depth@100ms","event_type":"depthUpdate","event_time_ms":1788580717097,"raw_json":"{\"stream\":\"btcusdt@depth@100ms\",\"data\":{\"e\":\"depthUpdate\",\"E\":1788580717097,\"T\":1788580717095,\"s\":\"BTCUSDT\",\"ps\":\"BTCUSDT\",\"U\":11479473636632,\"u\":11479473640398,\"pu\":11479473636574,\"b\":[[\"1000.00\",\"25.354\"],[\"29343.90\",\"1.008\"],[\"29443.90\",\"1.092\"],[\"71589.50\",\"0.014\"],[\"71623.00\",\"0.000\"],[\"76362.10\",\"0.002\"],[\"78748.50\",\"8.369\"],[\"78907.50\",\"7.965\"],[\"79146.10\",\"0.008\"],[\"79456.40\",\"0.318\"],[\"79459.80\",\"0.127\"],[\"79460.40\",\"0.001\"],[\"79528.40\",\"0.617\"],[\"79529.10\",\"0.229\"],[\"79529.60\",\"0.002\"]],\"a\":[[\"79549.00\",\"0.033\"],[\"79550.70\",\"0.000\"],[\"79939.70\",\"0.131\"],[\"79941.80\",\"0.000\"],[\"80339.40\",\"8.343\"],[\"80498.50\",\"39.488\"],[\"80633.80\",\"0.998\"],[\"80680.70\",\"0.003\"],[\"80776.90\",\"6.954\"]],\"st\":1}}"}
{"receive_ns":1788580717161853000,"stream":"btcusdt@depth@100ms","event_type":"depthUpdate","event_time_ms":1788580717199,"raw_json":"{\"stream\":\"btcusdt@depth@100ms\",\"data\":{\"e\":\"depthUpdate\",\"E\":1788580717199,\"T\":1788580717198,\"s\":\"BTCUSDT\",\"ps\":\"BTCUSDT\",\"U\":11479473640432,\"u\":11479473647506,\"pu\":11479473640398,\"b\":[[\"29343.90\",\"1.190\"],[\"29443.90\",\"0.910\"],[\"71589.50\",\"0.014\"],[\"76362.10\",\"0.000\"],[\"78549.60\",\"9.570\"],[\"78589.40\",\"38.752\"],[\"78748.50\",\"8.369\"],[\"79146.10\",\"0.009\"],[\"79146.20\",\"3.790\"],[\"79453.10\",\"0.020\"],[\"79456.40\",\"0.085\"],[\"79459.30\",\"0.125\"],[\"79459.80\",\"0.002\"],[\"79460.30\",\"0.018\"]],\"a\":[[\"79549.00\",\"0.025\"],[\"79550.70\",\"0.008\"],[\"79617.60\",\"0.038\"],[\"79624.60\",\"0.001\"],[\"79625.20\",\"0.005\"],[\"79636.00\",\"0.002\"],[\"79637.30\",\"0.002\"],[\"79936.40\",\"0.008\"],[\"79937.70\",\"0.004\"],[\"79939.70\",\"0.019\"],[\"79941.70\",\"4.371\"],[\"79941.80\",\"0.001\"],[\"80339.40\",\"8.341\"],[\"80498.50\",\"35.767\"]],\"st\":1}}"}
{"receive_ns":1788580717275607000,"stream":"btcusdt@bookTicker","event_type":"bookTicker","event_time_ms":1788580717299,"raw_json":"{\"stream\":\"btcusdt@bookTicker\",\"data\":{\"e\":\"bookTicker\",\"u\":11479473653576,\"s\":\"BTCUSDT\",\"ps\":\"BTCUSDT\",\"b\":\"79543.90\",\"B\":\"6.334\",\"a\":\"79544.00\",\"A\":\"5.247\",\"T\":1788580717299,\"E\":1788580717299,\"st\":1}}"}
{"receive_ns":1788580717282823000,"stream":"btcusdt@depth@100ms","event_type":"depthUpdate","event_time_ms":1788580717301,"raw_json":"{\"stream\":\"btcusdt@depth@100ms\",\"data\":{\"e\":\"depthUpdate\",\"E\":1788580717301,\"T\":1788580717299,\"s\":\"BTCUSDT\",\"ps\":\"BTCUSDT\",\"U\":11479473647626,\"u\":11479473653576,\"pu\":11479473647506,\"b\":[[\"1000.00\",\"25.354\"],[\"29343.90\",\"1.365\"],[\"29443.90\",\"0.735\"],[\"63635.10\",\"0.000\"],[\"71589.50\",\"0.014\"],[\"75566.70\",\"0.022\"],[\"75566.80\",\"0.008\"],[\"78470.10\",\"5.506\"],[\"78681.00\",\"0.635\"],[\"78748.50\",\"8.369\"],[\"79403.00\",\"0.213\"],[\"79442.80\",\"0.003\"],[\"79456.40\",\"0.308\"],[\"79459.30\",\"0.000\"],[\"79460.30\",\"0.018\"],[\"79482.60\",\"1.671\"]],\"a\":[[\"79544.00\",\"5.247\"],[\"79549.60\",\"0.004\"],[\"79550.00\",\"0.003\"],[\"79557.60\",\"0.003\"],[\"79565.60\",\"0.762\"],[\"79605.40\",\"0.002\"],[\"79939.70\",\"0.077\"],[\"79941.70\",\"4.420\"],[\"80260.00\",\"5.992\"],[\"80260.20\",\"0.062\"],[\"80339.40\",\"8.341\"],[\"80423.70\",\"1.116\"]],\"st\":1}}"}
{"receive_ns":1788580717283190000,"stream":"btcusdt@bookTicker","event_type":"bookTicker","event_time_ms":1788580717302,"raw_json":"{\"stream\":\"btcusdt@bookTicker\",\"data\":{\"e\":\"bookTicker\",\"u\":11479473653733,\"s\":\"BTCUSDT\",\"ps\":\"BTCUSDT\",\"b\":\"79543.90\",\"B\":\"6.334\",\"a\":\"79544.00\",\"A\":\"5.282\",\"T\":1788580717302,\"E\":1788580717302,\"st\":1}}"}
