{"receive_ns":1788580690648274000,"stream":"btcusdt@depth@100ms","event_type":"depthUpdate","event_time_ms":1788580690679,"raw_json":"{\"stream\":\"btcusdt@depth@100ms\",\"data\":{\"e\":\"depthUpdate\",\"E\":1788580690679,\"T\":1788580690677,\"s\":\"BTCUSDT\",\"ps\":\"BTCUSDT\",\"U\":11479472080427,\"u\":11479472086031,\"pu\":11479472080405,\"b\":[[\"1000.00\",\"25.354\"],[\"29043.90\",\"0.980\"],[\"29143.90\",\"1.120\"],[\"63635.00\",\"0.000\"],[\"71589.50\",\"0.006\"],[\"76362.10\",\"0.000\"],[\"77328.90\",\"0.515\"],[\"78117.20\",\"0.000\"],[\"78562.00\",\"11.190\"],[\"78601.80\",\"13.574\"],[\"78611.40\",\"0.007\"],[\"78668.90\",\"0.760\"],[\"78748.50\",\"1.902\"],[\"78828.00\",\"0.890\"],[\"79143.00\",\"0.000\"],[\"79146.80\",\"0.087\"],[\"79480.90\",\"0.021\"],[\"79482.30\",\"0.022\"],[\"79488.20\",\"0.128\"],[\"79504.10\",\"0.002\"],[\"79506.70\",\"0.024\"],[\"79522.60\",\"0.800\"],[\"79539.30\",\"0.004\"],[\"79539.60\",\"1.491\"],[\"79539.70\",\"0.062\"],[\"79539.90\",\"0.244\"]],\"a\":[[\"79546.50\",\"0.022\"],[\"79599.70\",\"0.050\"],[\"79615.60\",\"0.004\"],[\"79616.70\",\"3.204\"],[\"79616.80\",\"0.001\"],[\"79617.00\",\"0.000\"],[\"79617.30\",\"0.126\"],[\"79703.10\",\"0.002\"],[\"79934.40\",\"0.386\"],[\"79939.70\",\"0.191\"],[\"80339.40\",\"0.186\"],[\"80934.20\",\"0.000\"]],\"st\":1}}"}
{"receive_ns":1788580690667516000,"stream":"btcusdt@bookTicker","event_type":"bookTicker","event_time_ms":1788580690724,"raw_json":"{\"stream\":\"btcusdt@bookTicker\",\"data\":{\"e\":\"bookTicker\",\"u\":11479472089092,\"s\":\"BTCUSDT\",\"ps\":\"BTCUSDT\",\"b\":\"79543.90\",\"B\":\"5.233\",\"a\":\"79544.00\",\"A\":\"7.899\",\"T\":1788580690724,\"E\":1788580690724,\"st\":1}}"}
{"receive_ns":1788580690710532000,"stream":"btcusdt@bookTicker","event_type":"bookTicker","event_time_ms":1788580690727,"raw_json":"{\"stream\":\"btcusdt@bookTicker\",\"data\":{\"e\":\"bookTicker\",\"u\":11479472089324,\"s\":\"BTCUSDT\",\"ps\":\"BTCUSDT\",\"b\":\"79543.90\",\"B\":\"5.234\",\"a\":\"79544.00\",\"A\":\"7.899\",\"T\":1788580690727,\"E\":1788580690727,\"st\":1}}"}
{"receive_ns":1788580690710737000,"stream":"btcusdt@bookTicker","event_type":"bookTicker","event_time_ms":1788580690736,"raw_json":"{\"stream\":\"btcusdt@bookTicker\",\"data\":{\"e\":\"bookTicker\",\"u\":11479472089780,\"s\":\"BTCUSDT\",\"ps\":\"BTCUSDT\",\"b\":\"79543.90\",\"B\":\"5.235\",\"a\":\"79544.00\",\"A\":\"7.899\",\"T\":1788580690736,\"E\":1788580690736,\"st\":1}}"}
{"receive_ns":1788580690710896000,"stream":"btcusdt@bookTicker","event_type":"bookTicker","event_time_ms":1788580690766,"raw_json":"{\"stream\":\"btcusdt@bookTicker\",\"data\":{\"e\":\"bookTicker\",\"u\":11479472091456,\"s\":\"BTCUSDT\",\"ps\":\"BTCUSDT\",\"b\":\"79543.90\",\"B\":\"5.235\",\"a\":\"79544.00\",\"A\":\"7.850\",\"T\":1788580690765,\"E\":1788580690766,\"st\":1}}"}
{"receive_ns":1788580690711052000,"stream":"btcusdt@trade","event_type":"trade","event_time_ms":1788580690766,"raw_json":"{\"stream\":\"btcusdt@trade\",\"data\":{\"e\":\"trade\",\"E\":1788580690766,\"T\":1788580690765,\"s\":\"BTCUSDT\",\"t\":8054266627,\"p\":\"79544.00\",\"q\":\"0.049\",\"X\":\"MARKET\",\"m\":false,\"st\":1}}"}
{"receive_ns":1788580690725660000,"stream":"btcusdt@depth@100ms","event_type":"depthUpdate","event_time_ms":1788580690781,"raw_json":"{\"stream\":\"btcusdt@depth@100ms\",\"data\":{\"e\":\"depthUpdate\",\"E\":1788580690781,\"T\":1788580690778,\"s\":\"BTCUSDT\",\"ps\":\"BTCUSDT\",\"U\":11479472086102,\"u\":11479472092095,\"pu\":11479472086031,\"b\":[[\"29043.90\",\"1.155\"],[\"29143.90\",\"0.945\"],[\"63635.00\",\"0.000\"],[\"71589.50\",\"0.006\"],[\"76362.10\",\"0.002\"],[\"78105.00\",\"3.457\"],[\"78571.90\",\"2.549\"],[\"78748.50\",\"1.902\"],[\"78826.50\",\"0.887\"],[\"79146.20\",\"2.269\"],[\"79358.30\",\"0.001\"],[\"79379.20\",\"0.000\"],[\"79379.30\",\"1.367\"],[\"79399.60\",\"1.886\"],[\"79401.00\",\"0.365\"],[\"79418.60\",\"0.344\"],[\"79452.40\",\"2.844\"],[\"79459.60\",\"0.001\"],[\"79496.10\",\"0.389\"],[\"79520.20\",\"2.395\"],[\"79527.90\",\"0.073\"],[\"79529.30\",\"0.412\"],[\"79533.50\",\"0.007\"],[\"79533.60\",\"0.003\"],[\"79533.70\",\"0.081\"],[\"79533.80\",\"1.260\"],[\"79533.90\",\"0.004\"],[\"79538.60\",\"0.442\"],[\"79539.60\",\"1.492\"],[\"79539.70\",\"0.058\"],[\"79539.90\",\"0.307\"],[\"79540.00\",\"0.007\"],[\"79543.90\",\"5.235\"]],\"a\":[[\"79544.00\",\"7.850\"],[\"79548.20\",\"0.002\"],[\"79560.10\",\"0.004\"],[\"79573.80\",\"0.012\"],[\"79617.60\",\"0.001\"],[\"79620.20\",\"28.611\"],[\"79634.70\",\"0.378\"],[\"79636.50\",\"4.104\"],[\"79666.50\",\"0.287\"],[\"79668.80\",\"1.897\"],[\"79669.30\",\"0.000\"],[\"79687.60\",\"0.000\"],[\"79705.90\",\"1.213\"],[\"79939.70\",\"0.191\"],[\"80272.70\",\"2.621\"],[\"80339.40\",\"0.186\"],[\"80697.40\",\"2.598\"],[\"80856.50\",\"0.865\"]],\"st\":1}}"}
{"receive_ns":1788580690893067000,"stream":"btcusdt@depth@100ms","event_type":"depthUpdate","event_time_ms":1788580690883,"raw_json":"{\"stream\":\"btcusdt@depth@100ms\",\"data\":{\"e\":\"depthUpdate\",\"E\":1788580690883,\"T\":1788580690881,\"s\":\"BTCUSDT\",\"ps\":\"BTCUSDT\",\"U\":11479472092209,\"u\":11479472099076,\"pu\":11479472092095,\"b\":[[\"1000.00\",\"25.354\"],[\"29043.90\",\"1.337\"],[\"29143.90\",\"0.763\"],[\"63635.10\",\"0.000\"],[\"71589.50\",\"0.006\"],[\"78748.50\",\"1.902\"],[\"79358.20\",\"3.143\"],[\"79459.40\",\"0.084\"],[\"79480.90\",\"0.001\"],[\"79482.30\",\"0.015\"],[\"79539.90\",\"0.109\"]],\"a\":[[\"79616.10\",\"5.338\"],[\"79634.50\",\"0.038\"],[\"79665.00\",\"0.208\"],[\"79684.20\",\"0.929\"],[\"79687.30\",\"3.146\"],[\"79934.40\",\"0.379\"],[\"79939.70\",\"0.049\"],[\"80193.10\",\"1.244\"],[\"80339.40\",\"0.186\"]],\"st\":1}}"}
{"receive_ns":1788580690950693000,"stream":"btcusdt@depth@100ms","event_type":"depthUpdate","event_time_ms":1788580690985,"raw_json":"{\"stream\":\"btcusdt@depth@100ms\",\"data\":{\"e\":\"depthUpdate\",\"E\":1788580690985,\"T\":1788580690981,\"s\":\"BTCUSDT\",\"ps\":\"BTCUSDT\",\"U\":11479472099176,\"u\":11479472106063,\"pu\":11479472099076,\"b\":[[\"1000.00\",\"25.354\"],[\"29043.90\",\"1.512\"],[\"29143.90\",\"0.588\"],[\"63635.00\",\"0.000\"],[\"71589.50\",\"0.006\"],[\"76362.10\",\"0.000\"],[\"78748.50\",\"1.902\"],[\"79480.90\",\"0.021\"],[\"79482.30\",\"0.022\"],[\"79539.60\",\"1.491\"],[\"79539.70\",\"0.058\"],[\"79539.90\",\"0.332\"],[\"79540.00\",\"0.007\"]],\"a\":[[\"79617.60\",\"28.716\"],[\"79620.20\",\"0.008\"],[\"79936.40\",\"1.257\"],[\"79939.70\",\"0.191\"],[\"79941.70\",\"0.499\"],[\"80339.40\",\"0.186\"]],\"st\":1}}"}
{"receive_ns":1788580691021166000,"stream":"btcusdt@bookTicker","event_type":"bookTicker","event_time_ms":1788580691077,"raw_json":"{\"stream\":\"btcusdt@bookTicker\",\"data\":{\"e\":\"bookTicker\",\"u\":11479472115518,\"s\":\"BTCUSDT\",\"ps\":\"BTCUSDT\",\"b\":\"79543.90\",\"B\":\"5.235\",\"a\":\"79544.00\",\"A\":\"7.829\",\"T\":1788580691077,\"E\":1788580691077,\"st\":1}}"}
{"receive_ns":1788580691023484000,"stream":"btcusdt@bookTicker","event_type":"bookTicker","event_time_ms":1788580691081,"raw_json":"{\"stream\":\"btcusdt@bookTicker\",\"data\":{\"e\":\"bookTicker\",\"u\":11479472115800,\"s\":\"BTCUSDT\",\"ps\":\"BTCUSDT\",\"b\":\"79543.90\",\"B\":\"5.235\",\"a\":\"79544.00\",\"A\":\"7.851\",\"T\":1788580691081,\"E\":1788580691081,\"st\":1}}"}
{"receive_ns":1788580691029954000,"stream":"btcusdt@depth@100ms","event_type":"depthUpdate","event_time_ms":1788580691087,"raw_json":"{\"stream\":\"btcusdt@depth@100ms\",\"data\":{\"e\":\"depthUpdate\",\"E\":1788580691087,\"T\":1788580691085,\"s\":\"BTCUSDT\",\"ps\":\"BTCUSDT\",\"U\":11479472107109,\"u\":11479472116115,\"pu\":11479472106063,\"b\":[[\"29043.90\",\"1.694\"],[\"29143.90\",\"0.406\"],[\"71589.50\",\"0.006\"],[\"76362.10\",\"0.002\"],[\"78191.70\",\"4.598\"],[\"78430.30\",\"7.005\"],[\"78549.60\",\"2.227\"],[\"78611.70\",\"13.847\"],[\"78748.50\",\"1.902\"],[\"79146.20\",\"2.269\"],[\"79379.30\",\"2.089\"],[\"79418.60\",\"0.476\"],[\"79529.60\",\"0.002\"]],\"a\":[[\"79544.00\",\"7.851\"],[\"79616.10\",\"8.175\"],[\"79665.00\",\"0.202\"],[\"79665.90\",\"0.015\"],[\"79666.50\",\"0.349\"],[\"79705.90\",\"1.867\"],[\"79748.20\",\"0.740\"],[\"79936.40\",\"1.132\"],[\"80339.40\",\"0.186\"],[\"80605.80\",\"0.000\"],[\"80614.00\",\"0.376\"]],\"st\":1}}"}
{"receive_ns":1788580691136094000,"stream":"btcusdt@bookTicker","event_type":"bookTicker","event_time_ms":1788580691144,"raw_json":"{\"stream\":\"btcusdt@bookTicker\",\"data\":{\"e\":\"bookTicker\",\"u\":11479472120265,\"s\":\"BTCUSDT\",\"ps\":\"BTCUSDT\",\"b\":\"79543.90\",\"B\":\"5.234\",\"a\":\"79544.00\",\"A\":\"7.851\",\"T\":1788580691144,\"E\":1788580691144,\"st\":1}}"}
{"receive_ns":1788580691136328000,"stream":"btcusdt@bookTicker","event_type":"bookTicker","event_time_ms":1788580691146,"raw_json":"{\"stream\":\"btcusdt@bookTicker\",\"data\":{\"e\":\"bookTicker\",\"u\":11479472120378,\"s\":\"BTCUSDT\",\"ps\":\"BTCUSDT\",\"b\":\"79543.90\",\"B\":\"5.235\",\"a\":\"79544.00\",\"A\":\"7.851\",\"T\":1788580691146,\"E\":1788580691146,\"st\":1}}"}
{"receive_ns":1788580691137092000,"stream":"btcusdt@depth@100ms","event_type":"depthUpdate","event_time_ms":1788580691189,"raw_json":"{\"stream\":\"btcusdt@depth@100ms\",\"data\":{\"e\":\"depthUpdate\",\"E\":1788580691189,\"T\":1788580691188,\"s\":\"BTCUSDT\",\"ps\":\"BTCUSDT\",\"U\":11479472116250,\"u\":11479472123673,\"pu\":11479472116115,\"b\":[[\"1000.00\",\"25.354\"],[\"29043.90\",\"1.785\"],[\"29143.90\",\"0.273\"],[\"29443.90\",\"0.042\"],[\"63635.00\",\"0.000\"],[\"71589.50\",\"0.006\"],[\"71623.00\",\"0.000\"],[\"76362.10\",\"0.000\"],[\"78430.30\",\"7.260\"],[\"78549.60\",\"2.443\"],[\"78589.40\",\"9.147\"],[\"78748.50\",\"1.902\"],[\"79464.30\",\"0.040\"],[\"79480.90\",\"0.021\"],[\"79482.30\",\"0.032\"],[\"79539.70\",\"0.062\"],[\"79539.90\",\"0.322\"],[\"79540.00\",\"0.003\"],[\"79543.90\",\"5.235\"]],\"a\":[[\"79624.30\",\"0.379\"],[\"79624.70\",\"0.528\"],[\"79624.80\",\"1.752\"],[\"79635.70\",\"0.001\"],[\"79637.20\",\"0.016\"],[\"79639.30\",\"0.003\"],[\"79640.40\",\"1.919\"],[\"79934.40\",\"0.386\"],[\"79936.40\",\"1.125\"],[\"79939.70\",\"0.191\"],[\"80339.40\",\"0.186\"],[\"80720.30\",\"5.196\"],[\"81731.80\",\"0.000\"]],\"st\":1}}"}
{"receive_ns":1788580691194705000,"stream":"btcusdt@bookTicker","event_type":"bookTicker","event_time_ms":1788580691251,"raw_json":"{\"stream\":\"btcusdt@bookTicker\",\"data\":{\"e\":\"bookTicker\",\"u\":11479472128558,\"s\":\"BTCUSDT\",\"ps\":\"BTCUSDT\",\"b\":\"79543.90\",\"B\":\"5.227\",\"a\":\"79544.00\",\"A\":\"7.851\",\"T\":1788580691251,\"E\":1788580691251,\"st\":1}}"}
{"receive_ns":1788580691196938000,"stream":"btcusdt@bookTicker","event_type":"bookTicker","event_time_ms":1788580691254,"raw_json":"{\"stream\":\"btcusdt@bookTicker\",\"data\":{\"e\":\"bookTicker\",\"u\":11479472129048,\"s\":\"BTCUSDT\",\"ps\":\"BTCUSDT\",\"b\":\"79543.90\",\"B\":\"5.233\",\"a\":\"79544.00\",\"A\":\"7.851\",\"T\":1788580691254,\"E\":1788580691254,\"st\":1}}"}
{"receive_ns":1788580691256909000,"stream":"btcusdt@depth@100ms","event_type":"depthUpdate","event_time_ms":1788580691291,"raw_json":"{\"stream\":\"btcusdt@depth@100ms\",\"data\":{\"e\":\"depthUpdate\",\"E\":1788580691291,\"T\":1788580691289,\"s\":\"BTCUSDT\",\"ps\":\"BTCUSDT\",\"U\":11479472123722,\"u\":11479472131834,\"pu\":11479472123673,\"b\":[[\"1000.00\",\"25.354\"],[\"29043.90\",\"1.855\"],[\"29143.90\",\"0.147\"],[\"29443.90\",\"0.098\"],[\"71589.50\",\"0.006\"],[\"78562.00\",\"10.905\"],[\"78748.50\",\"1.902\"],[\"78827.90\",\"1.077\"],[\"78947.30\",\"1.267\"],[\"79539.70\",\"0.058\"],[\"79539.90\",\"0.322\"],[\"79540.00\",\"0.007\"],[\"79543.90\",\"5.233\"]],\"a\":[[\"79571.10\",\"2.929\"],[\"79637.20\",\"0.017\"],[\"79939.70\",\"0.191\"],[\"80339.40\",\"1.429\"],[\"81134.80\",\"0.012\"],[\"81691.70\",\"0.733\"]],\"st\":1}}"}
{"receive_ns":1788580691257214000,"stream":"btcusdt@bookTicker","event_type":"bookTicker","event_time_ms":1788580691312,"raw_json":"{\"stream\":\"btcusdt@bookTicker\",\"data\":{\"e\":\"bookTicker\",\"u\":11479472133833,\"s\":\"BTCUSDT\",\"ps\":\"BTCUSDT\",\"b\":\"79543.90\",\"B\":\"5.115\",\"a\":\"79544.00\",\"A\":\"7.851\",\"T\":1788580691312,\"E\":1788580691312,\"st\":1}}"}
{"receive_ns":1788580691257466000,"stream":"btcusdt@bookTicker","event_type":"bookTicker","event_time_ms":1788580691314,"raw_json":"{\"stream\":\"btcusdt@bookTicker\",\"data\":{\"e\":\"bookTicker\",\"u\":11479472133948,\"s\":\"BTCUSDT\",\"ps\":\"BTCUSDT\",\"b\":\"79543.90\",\"B\":\"5.114\",\"a\":\"79544.00\",\"A\":\"7.851\",\"T\":1788580691314,\"E\":1788580691314,\"st\":1}}"}
{"receive_ns":1788580691258239000,"stream":"btcusdt@bookTicker","event_type":"bookTicker","event_time_ms":1788580691315,"raw_json":"{\"stream\":\"btcusdt@bookTicker\",\"data\":{\"e\":\"bookTicker\",\"u\":11479472134041,\"s\":\"BTCUSDT\",\"ps\":\"BTCUSDT\",\"b\":\"79543.90\",\"B\":\"5.231\",\"a\":\"79544.00\",\"A\":\"7.851\",\"T\":1788580691315,\"E\":1788580691315,\"st\":1}}"}
{"receive_ns":1788580691258487000,"stream":"btcusdt@bookTicker","event_type":"bookTicker","event_time_ms":1788580691315,"raw_json":"{\"stream\":\"btcusdt@bookTicker\",\"data\":{\"e\":\"bookTicker\",\"u\":11479472134043,\"s\":\"BTCUSDT\",\"ps\":\"BTCUSDT\",\"b\":\"79543.90\",\"B\":\"5.232\",\"a\":\"79544.00\",\"A\":\"7.851\",\"T\":1788580691315,\"E\":1788580691315,\"st\":1}}"}
{"receive_ns":1788580691317300000,"stream":"btcusdt@bookTicker","event_type":"bookTicker","event_time_ms":1788580691372,"raw_json":"{\"stream\":\"btcusdt@bookTicker\",\"data\":{\"e\":\"bookTicker\",\"u\":11479472138015,\"s\":\"BTCUSDT\",\"ps\":\"BTCUSDT\",\"b\":\"79543.90\",\"B\":\"5.232\",\"a\":\"79544.00\",\"A\":\"7.830\",\"T\":1788580691372,\"E\":1788580691372,\"st\":1}}"}
{"receive_ns":1788580691319115000,"stream":"btcusdt@bookTicker","event_type":"bookTicker","event_time_ms":1788580691375,"raw_json":"{\"stream\":\"btcusdt@bookTicker\",\"data\":{\"e\":\"bookTicker\",\"u\":11479472138172,\"s\":\"BTCUSDT\",\"ps\":\"BTCUSDT\",\"b\":\"79543.90\",\"B\":\"5.232\",\"a\":\"79544.00\",\"A\":\"7.848\",\"T\":1788580691375,\"E\":1788580691375,\"st\":1}}"}
{"receive_ns":1788580691336732000,"stream":"btcusdt@depth@100ms","event_type":"depthUpdate","event_time_ms":1788580691393,"raw_json":"{\"stream\":\"btcusdt@depth@100ms\",\"data\":{\"e\":\"depthUpdate\",\"E\":1788580691393,\"T\":1788580691390,\"s\":\"BTCUSDT\",\"ps\":\"BTCUSDT\",\"U\":11479472132034,\"u\":11479472139040,\"pu\":11479472131834,\"b\":[[\"29043.90\",\"1.904\"],[\"29143.90\",\"0.035\"],[\"29443.90\",\"0.161\"],[\"71589.50\",\"0.006\"],[\"75566.70\",\"0.011\"],[\"76362.10\",\"0.002\"],[\"77953.10\",\"0.012\"],[\"78748.50\",\"1.902\"],[\"78828.00\",\"1.080\"],[\"79146.10\",\"0.009\"],[\"79146.20\",\"2.279\"],[\"79379.30\",\"0.002\"],[\"79418.60\",\"0.001\"],[\"79480.90\",\"0.001\"],[\"79482.30\",\"0.015\"],[\"79533.50\",\"1.264\"],[\"79533.70\",\"0.077\"],[\"79533.80\",\"0.003\"],[\"79533.90\",\"0.000\"],[\"79534.00\",\"0.007\"],[\"79534.10\",\"0.004\"],[\"79539.60\",\"1.491\"],[\"79539.70\",\"0.062\"],[\"79539.90\",\"0.109\"],[\"79540.00\",\"0.003\"],[\"79543.90\",\"5.232\"]],\"a\":[[\"79544.00\",\"7.848\"],[\"79624.20\",\"0.002\"],[\"79626.80\",\"0.000\"],[\"79635.60\",\"0.006\"],[\"79666.50\",\"0.000\"],[\"79705.90\",\"0.016\"],[\"79934.40\",\"0.379\"],[\"79939.70\",\"0.049\"],[\"79941.80\",\"0.001\"],[\"80339.40\",\"1.429\"]],\"st\":1}}"}
{"receive_ns":1788580691430259000,"stream":"btcusdt@bookTicker","event_type":"bookTicker","event_time_ms":1788580691479,"raw_json":"{\"stream\":\"btcusdt@bookTicker\",\"data\":{\"e\":\"bookTicker\",\"u\":11479472144844,\"s\":\"BTCUSDT\",\"ps\":\"BTCUSDT\",\"b\":\"79543.90\",\"B\":\"5.232\",\"a\":\"79544.00\",\"A\":\"7.849\",\"T\":1788580691478,\"E\":1788580691479,\"st\":1}}"}
{"receive_ns":1788580691439044000,"stream":"btcusdt@depth@100ms","event_type":"depthUpdate","event_time_ms":1788580691495,"raw_json":"{\"stream\":\"btcusdt@depth@100ms\",\"data\":{\"e\":\"depthUpdate\",\"E\":1788580691495,\"T\":1788580691493,\"s\":\"BTCUSDT\",\"ps\":\"BTCUSDT\",\"U\":11479472139393,\"u\":11479472145735,\"pu\":11479472139040,\"b\":[[\"1000.00\",\"25.504\"],[\"29043.90\",\"1.792\"],[\"29143.90\",\"0.000\"],[\"29443.90\",\"0.308\"],[\"71589.50\",\"0.006\"],[\"76362.10\",\"0.000\"],[\"78026.20\",\"0.123\"],[\"78748.50\",\"1.902\"],[\"79140.90\",\"2.206\"],[\"79331.50\",\"0.000\"],[\"79331.60\",\"4.806\"],[\"79379.30\",\"1.762\"],[\"79418.70\",\"0.416\"],[\"79480.90\",\"0.021\"],[\"79482.30\",\"0.195\"],[\"79529.30\",\"0.036\"],[\"79533.60\",\"0.383\"],[\"79533.70\",\"0.081\"],[\"79534.00\",\"0.003\"],[\"79534.10\",\"0.000\"],[\"79539.90\",\"0.159\"]],\"a\":[[\"79544.00\",\"7.849\"],[\"79666.50\",\"0.287\"],[\"79705.90\",\"1.551\"],[\"79753.60\",\"4.846\"],[\"79934.40\",\"0.386\"],[\"79939.70\",\"0.191\"],[\"80140.60\",\"1.247\"],[\"80259.90\",\"0.377\"],[\"80339.40\",\"1.429\"],[\"80431.80\",\"0.187\"]],\"st\":1}}"}
{"receive_ns":1788580691549438000,"stream":"btcusdt@bookTicker","event_type":"bookTicker","event_time_ms":1788580691576,"raw_json":"{\"stream\":\"btcusdt@bookTicker\",\"data\":{\"e\":\"bookTicker\",\"u\":11479472151651,\"s\":\"BTCUSDT\",\"ps\":\"BTCUSDT\",\"b\":\"79543.90\",\"B\":\"5.231\",\"a\":\"79544.00\",\"A\":\"7.849\",\"T\":1788580691575,\"E\":1788580691576,\"st\":1}}"}
{"receive_ns":1788580691549777000,"stream":"btcusdt@bookTicker","event_type":"bookTicker","event_time_ms":1788580691577,"raw_json":"{\"stream\":\"btcusdt@bookTicker\",\"data\":{\"e\":\"bookTicker\",\"u\":11479472151773,\"s\":\"BTCUSDT\",\"ps\":\"BTCUSDT\",\"b\":\"79543.90\",\"B\":\"5.232\",\"a\":\"79544.00\",\"A\":\"7.849\",\"T\":1788580691577,\"E\":1788580691577,\"st\":1}}"}
{"receive_ns":1788580691550216000,"stream":"btcusdt@depth@100ms","event_type":"depthUpdate","event_time_ms":1788580691597,"raw_json":"{\"stream\":\"btcusdt@depth@100ms\",\"data\":{\"e\":\"depthUpdate\",\"E\":1788580691597,\"T\":1788580691595,\"s\":\"BTCUSDT\",\"ps\":\"BTCUSDT\",\"U\":11479472145846,\"u\":11479472153318,\"pu\":11479472145735,\"b\":[[\"1000.00\",\"25.354\"],[\"29043.90\",\"1.617\"],[\"29443.90\",\"0.483\"],[\"71589.50\",\"0.006\"],[\"76362.10\",\"0.002\"],[\"78311.00\",\"2.024\"],[\"78333.20\",\"5.355\"],[\"78452.60\",\"19.098\"],[\"78470.10\",\"1.273\"],[\"78505.50\",\"0.508\"],[\"78748.50\",\"1.902\"],[\"79452.40\",\"0.050\"],[\"79464.30\",\"0.021\"],[\"79482.30\",\"0.107\"],[\"79519.40\",\"0.010\"],[\"79539.60\",\"1.492\"],[\"79543.90\",\"5.232\"]],\"a\":[[\"79636.50\",\"0.005\"],[\"80339.40\",\"1.429\"]],\"st\":1}}"}
{"receive_ns":1788580691672013000,"stream":"btcusdt@depth@100ms","event_type":"depthUpdate","event_time_ms":1788580691699,"raw_json":"{\"stream\":\"btcusdt@depth@100ms\",\"data\":{\"e\":\"depthUpdate\",\"E\":1788580691699,\"T\":1788580691697,\"s\":\"BTCUSDT\",\"ps\":\"BTCUSDT\",\"U\":11479472153596,\"u\":11479472162771,\"pu\":11479472153318,\"b\":[[\"29043.90\",\"1.435\"],[\"29443.90\",\"0.665\"],[\"63635.00\",\"0.000\"],[\"71589.50\",\"0.006\"],[\"76362.10\",\"0.000\"],[\"78592.90\",\"5.715\"],[\"78597.70\",\"0.004\"],[\"78748.50\",\"1.902\"],[\"79146.20\",\"2.279\"],[\"79452.40\",\"2.840\"],[\"79464.30\",\"0.000\"],[\"79478.00\",\"0.100\"],[\"79480.90\",\"0.001\"],[\"79482.30\",\"0.022\"],[\"79492.40\",\"0.014\"],[\"79521.60\",\"0.678\"],[\"79529.30\",\"0.036\"],[\"79533.50\",\"0.007\"],[\"79533.70\",\"1.338\"],[\"79534.60\",\"0.201\"],[\"79539.60\",\"1.492\"],[\"79539.70\",\"0.058\"],[\"79539.90\",\"0.244\"],[\"79540.00\",\"0.007\"]],\"a\":[[\"79610.00\",\"0.252\"],[\"79615.20\",\"0.091\"],[\"79629.40\",\"3.203\"],[\"79630.00\",\"0.359\"],[\"79633.10\",\"0.015\"],[\"79636.40\",\"4.092\"],[\"79665.00\",\"0.202\"],[\"79934.40\",\"0.386\"],[\"79939.70\",\"0.142\"],[\"80339.40\",\"1.429\"],[\"80431.70\",\"12.425\"],[\"80657.60\",\"9.477\"]],\"st\":1}}"}
{"receive_ns":1788580691672387000,"stream":"btcusdt@bookTicker","event_type":"bookTicker","event_time_ms":1788580691707,"raw_json":"{\"stream\":\"btcusdt@bookTicker\",\"data\":{\"e\":\"bookTicker\",\"u\":11479472163793,\"s\":\"BTCUSDT\",\"ps\":\"BTCUSDT\",\"b\":\"79543.90\",\"B\":\"5.232\",\"a\":\"79544.00\",\"A\":\"7.847\",\"T\":1788580691706,\"E\":1788580691707,\"st\":1}}"}
{"receive_ns":1788580691672698000,"stream":"btcusdt@trade","event_type":"trade","event_time_ms":1788580691707,"raw_json":"{\"stream\":\"btcusdt@trade\",\"data\":{\"e\":\"trade\",\"E\":1788580691707,\"T\":1788580691706,\"s\":\"BTCUSDT\",\"t\":8054266628,\"p\":\"79544.00\",\"q\":\"0.002\",\"X\":\"MARKET\",\"m\":false,\"st\":1}}"}
{"receive_ns":1788580691744541000,"stream":"btcusdt@depth@100ms","event_type":"depthUpdate","event_time_ms":1788580691801,"raw_json":"{\"stream\":\"btcusdt@depth@100ms\",\"data\":{\"e\":\"depthUpdate\",\"E\":1788580691801,\"T\":1788580691798,\"s\":\"BTCUSDT\",\"ps\":\"BTCUSDT\",\"U\":11479472162855,\"u\":11479472169723,\"pu\":11479472162771,\"b\":[[\"1000.00\",\"25.354\"],[\"29043.90\",\"1.260\"],[\"29443.90\",\"0.840\"],[\"71589.50\",\"0.006\"],[\"78748.50\",\"1.902\"],[\"79418.70\",\"0.327\"],[\"79451.60\",\"0.001\"],[\"79520.20\",\"2.395\"],[\"79529.30\",\"0.412\"],[\"79533.60\",\"0.003\"],[\"79533.70\",\"0.077\"],[\"79533.80\",\"1.260\"],[\"79533.90\",\"0.008\"],[\"79539.60\",\"1.491\"],[\"79539.90\",\"0.297\"],[\"79540.60\",\"0.252\"]],\"a\":[[\"79544.00\",\"7.847\"],[\"79560.10\",\"0.004\"],[\"79571.10\",\"2.923\"],[\"79575.60\",\"0.453\"],[\"79589.10\",\"0.523\"],[\"79590.00\",\"0.130\"],[\"79616.10\",\"5.338\"],[\"79617.60\",\"0.001\"],[\"79619.60\",\"0.016\"],[\"79620.20\",\"28.723\"],[\"79629.40\",\"3.189\"],[\"79666.50\",\"0.287\"],[\"79939.70\",\"0.191\"],[\"80140.60\",\"1.870\"],[\"80339.40\",\"1.429\"],[\"80580.30\",\"0.868\"],[\"80680.50\",\"12.999\"],[\"81134.80\",\"0.015\"]],\"st\":1}}"}
{"receive_ns":1788580691807787000,"stream":"btcusdt@bookTicker","event_type":"bookTicker","event_time_ms":1788580691843,"raw_json":"{\"stream\":\"btcusdt@bookTicker\",\"data\":{\"e\":\"bookTicker\",\"u\":11479472172514,\"s\":\"BTCUSDT\",\"ps\":\"BTCUSDT\",\"b\":\"79543.90\",\"B\":\"5.231\",\"a\":\"79544.00\",\"A\":\"7.847\",\"T\":1788580691843,\"E\":1788580691843,\"st\":1}}"}
{"receive_ns":1788580691867601000,"stream":"btcusdt@depth@100ms","event_type":"depthUpdate","event_time_ms":1788580691903,"raw_json":"{\"stream\":\"btcusdt@depth@100ms\",\"data\":{\"e\":\"depthUpdate\",\"E\":1788580691903,\"T\":1788580691901,\"s\":\"BTCUSDT\",\"ps\":\"BTCUSDT\",\"U\":11479472170064,\"u\":11479472176513,\"pu\":11479472169723,\"b\":[[\"29043.90\",\"1.078\"],[\"29443.90\",\"1.022\"],[\"63635.00\",\"0.000\"],[\"63635.10\",\"0.000\"],[\"71589.50\",\"0.006\"],[\"76362.10\",\"0.002\"],[\"78748.50\",\"1.902\"],[\"79482.30\",\"0.015\"],[\"79539.60\",\"1.491\"],[\"79539.70\",\"0.062\"],[\"79539.90\",\"0.109\"],[\"79540.00\",\"0.003\"],[\"79543.90\",\"5.231\"]],\"a\":[[\"79559.40\",\"0.000\"],[\"79589.10\",\"0.317\"],[\"79665.00\",\"0.220\"],[\"79934.40\",\"0.379\"],[\"79936.40\",\"0.626\"],[\"79939.70\",\"0.049\"],[\"80339.40\",\"1.429\"],[\"80493.20\",\"20.099\"]],\"st\":1}}"}
{"receive_ns":1788580691869511000,"stream":"btcusdt@bookTicker","event_type":"bookTicker","event_time_ms":1788580691919,"raw_json":"{\"stream\":\"btcusdt@bookTicker\",\"data\":{\"e\":\"bookTicker\",\"u\":11479472177701,\"s\":\"BTCUSDT\",\"ps\":\"BTCUSDT\",\"b\":\"79543.90\",\"B\":\"5.236\",\"a\":\"79544.00\",\"A\":\"7.847\",\"T\":1788580691919,\"E\":1788580691919,\"st\":1}}"}
{"receive_ns":1788580691949591000,"stream":"btcusdt@depth@100ms","event_type":"depthUpdate","event_time_ms":1788580692005,"raw_json":"{\"stream\":\"btcusdt@depth@100ms\",\"data\":{\"e\":\"depthUpdate\",\"E\":1788580692005,\"T\":1788580692001,\"s\":\"BTCUSDT\",\"ps\":\"BTCUSDT\",\"U\":11479472176617,\"u\":11479472182935,\"pu\":11479472176513,\"b\":[[\"29043.90\",\"0.903\"],[\"29443.90\",\"1.197\"],[\"63635.00\",\"0.000\"],[\"71589.50\",\"0.006\"],[\"76362.10\",\"0.000\"],[\"78509.80\",\"1.797\"],[\"78522.20\",\"14.756\"],[\"78748.50\",\"1.902\"],[\"79146.20\",\"2.269\"],[\"79418.70\",\"0.002\"],[\"79452.90\",\"0.010\"],[\"79455.90\",\"1.953\"],[\"79480.70\",\"0.002\"],[\"79482.00\",\"1.013\"],[\"79482.30\",\"0.057\"],[\"79500.60\",\"0.165\"],[\"79534.60\",\"0.201\"],[\"79539.60\",\"1.491\"],[\"79539.70\",\"0.058\"],[\"79539.90\",\"0.297\"],[\"79540.00\",\"0.007\"],[\"79543.90\",\"5.236\"]],\"a\":[[\"79586.40\",\"0.001\"],[\"79589.10\",\"0.108\"],[\"79606.30\",\"0.000\"],[\"79634.10\",\"0.000\"],[\"79666.50\",\"0.000\"],[\"79936.40\",\"0.633\"],[\"79939.70\",\"0.191\"],[\"80261.70\",\"0.871\"],[\"80339.40\",\"1.429\"],[\"80459.30\",\"1.476\"],[\"80657.60\",\"11.335\"],[\"80737.60\",\"0.062\"]],\"st\":1}}"}
{"receive_ns":1788580692019926000,"stream":"btcusdt@bookTicker","event_type":"bookTicker","event_time_ms":1788580692076,"raw_json":"{\"stream\":\"btcusdt@bookTicker\",\"data\":{\"e\":\"bookTicker\",\"u\":11479472189263,\"s\":\"BTCUSDT\",\"ps\":\"BTCUSDT\",\"b\":\"79543.90\",\"B\":\"5.234\",\"a\":\"79544.00\",\"A\":\"7.847\",\"T\":1788580692076,\"E\":1788580692076,\"st\":1}}"}
{"receive_ns":1788580692032066000,"stream":"btcusdt@bookTicker","event_type":"bookTicker","event_time_ms":1788580692087,"raw_json":"{\"stream\":\"btcusdt@bookTicker\",\"data\":{\"e\":\"bookTicker\",\"u\":11479472189975,\"s\":\"BTCUSDT\",\"ps\":\"BTCUSDT\",\"b\":\"79543.90\",\"B\":\"5.234\",\"a\":\"79544.00\",\"A\":\"7.828\",\"T\":1788580692086,\"E\":1788580692087,\"st\":1}}"}
{"receive_ns":1788580692032541000,"stream":"btcusdt@bookTicker","event_type":"bookTicker","event_time_ms":1788580692090,"raw_json":"{\"stream\":\"btcusdt@bookTicker\",\"data\":{\"e\":\"bookTicker\",\"u\":11479472190240,\"s\":\"BTCUSDT\",\"ps\":\"BTCUSDT\",\"b\":\"79543.90\",\"B\":\"5.234\",\"a\":\"79544.00\",\"A\":\"7.848\",\"T\":1788580692089,\"E\":1788580692090,\"st\":1}}"}
{"receive_ns":1788580692037039000,"stream":"btcusdt@bookTicker","event_type":"bookTicker","event_time_ms":1788580692093,"raw_json":"{\"stream\":\"btcusdt@bookTicker\",\"data\":{\"e\":\"bookTicker\",\"u\":11479472191077,\"s\":\"BTCUSDT\",\"ps\":\"BTCUSDT\",\"b\":\"79543.90\",\"B\":\"5.236\",\"a\":\"79544.00\",\"A\":\"7.848\",\"T\":1788580692093,\"E\":1788580692093,\"st\":1}}"}
{"receive_ns":1788580692074905000,"stream":"btcusdt@depth@100ms","event_type":"depthUpdate","event_time_ms":1788580692107,"raw_json":"{\"stream\":\"btcusdt@depth@100ms\",\"data\":{\"e\":\"depthUpdate\",\"E\":1788580692107,\"T\":1788580692105,\"s\":\"BTCUSDT\",\"ps\":\"BTCUSDT\",\"U\":11479472183240,\"u\":11479472192857,\"pu\":11479472182935,\"b\":[[\"1000.00\",\"25.354\"],[\"29043.90\",\"0.721\"],[\"29443.90\",\"1.379\"],[\"63635.00\",\"0.000\"],[\"71589.50\",\"0.006\"],[\"76362.10\",\"0.002\"],[\"78748.50\",\"1.902\"],[\"79146.20\",\"2.269\"],[\"79413.20\",\"1.168\"],[\"79413.40\",\"0.123\"],[\"79415.00\",\"1.696\"],[\"79416.60\",\"0.166\"],[\"79418.70\",\"0.459\"],[\"79526.70\",\"0.106\"],[\"79529.60\",\"0.002\"],[\"79539.90\",\"0.247\"],[\"79543.90\",\"5.236\"]],\"a\":[[\"79544.00\",\"7.848\"],[\"79589.10\",\"0.001\"],[\"79594.40\",\"0.038\"],[\"79616.10\",\"8.213\"],[\"79617.60\",\"28.958\"],[\"79620.20\",\"0.008\"],[\"79665.90\",\"0.894\"],[\"79666.50\",\"0.417\"],[\"79668.10\",\"0.013\"],[\"79672.60\",\"1.106\"],[\"79673.90\",\"0.040\"],[\"79693.60\",\"0.006\"],[\"79941.70\",\"0.998\"],[\"80339.40\",\"1.429\"]],\"st\":1}}"}
{"receive_ns":1788580692136560000,"stream":"btcusdt@bookTicker","event_type":"bookTicker","event_time_ms":1788580692171,"raw_json":"{\"stream\":\"btcusdt@bookTicker\",\"data\":{\"e\":\"bookTicker\",\"u\":11479472197176,\"s\":\"BTCUSDT\",\"ps\":\"BTCUSDT\",\"b\":\"79543.90\",\"B\":\"5.235\",\"a\":\"79544.00\",\"A\":\"7.848\",\"T\":1788580692171,\"E\":1788580692171,\"st\":1}}"}
{"receive_ns":1788580692137235000,"stream":"btcusdt@bookTicker","event_type":"bookTicker","event_time_ms":1788580692173,"raw_json":"{\"stream\":\"btcusdt@bookTicker\",\"data\":{\"e\":\"bookTicker\",\"u\":11479472197309,\"s\":\"BTCUSDT\",\"ps\":\"BTCUSDT\",\"b\":\"79543.90\",\"B\":\"5.236\",\"a\":\"79544.00\",\"A\":\"7.848\",\"T\":1788580692173,\"E\":1788580692173,\"st\":1}}"}
{"receive_ns":1788580692156299000,"stream":"btcusdt@depth@100ms","event_type":"depthUpdate","event_time_ms":1788580692209,"raw_json":"{\"stream\":\"btcusdt@depth@100ms\",\"data\":{\"e\":\"depthUpdate\",\"E\":1788580692209,\"T\":1788580692208,\"s\":\"BTCUSDT\",\"ps\":\"BTCUSDT\",\"U\":11479472192999,\"u\":11479472199174,\"pu\":11479472192857,\"b\":[[\"29043.90\",\"0.546\"],[\"29443.90\",\"1.554\"],[\"34000.00\",\"0.975\"],[\"71589.50\",\"0.006\"],[\"71623.00\",\"0.000\"],[\"75566.70\",\"0.013\"],[\"76362.10\",\"0.000\"],[\"77953.10\",\"0.009\"],[\"78425.10\",\"33.767\"],[\"78500.90\",\"0.637\"],[\"78584.10\",\"30.562\"],[\"78748.50\",\"1.902\"],[\"79411.50\",\"0.007\"],[\"79413.30\",\"0.000\"],[\"79452.90\",\"6.010\"],[\"79456.60\",\"0.039\"],[\"79480.20\",\"2.180\"],[\"79480.70\",\"3.502\"],[\"79480.90\",\"0.021\"],[\"79482.00\",\"1.474\"],[\"79482.30\",\"0.157\"],[\"79500.60\",\"0.733\"],[\"79529.30\",\"0.412\"],[\"79533.80\",\"0.003\"],[\"79533.90\",\"0.004\"],[\"79534.00\",\"0.003\"],[\"79534.10\",\"1.261\"],[\"79539.30\",\"0.000\"],[\"79539.70\",\"0.066\"],[\"79539.90\",\"0.197\"],[\"79540.00\",\"0.003\"],[\"79543.90\",\"5.236\"]],\"a\":[[\"79586.40\",\"0.552\"],[\"79589.60\",\"0.145\"],[\"79606.30\",\"3.500\"],[\"79616.10\",\"5.338\"],[\"79617.60\",\"0.001\"],[\"79620.20\",\"28.965\"],[\"79624.20\",\"0.001\"],[\"79624.70\",\"0.528\"],[\"79624.80\",\"1.753\"],[\"79634.10\",\"6.000\"],[\"79635.60\",\"0.005\"],[\"79637.20\",\"0.014\"],[\"79639.30\",\"0.000\"],[\"79639.40\",\"0.037\"],[\"79640.40\",\"1.921\"],[\"79665.00\",\"0.220\"],[\"79668.10\",\"0.007\"],[\"79696.80\",\"1.698\"],[\"79933.80\",\"0.037\"],[\"79936.40\",\"0.633\"],[\"79937.70\",\"0.022\"],[\"79939.70\",\"0.136\"],[\"80339.40\",\"1.429\"],[\"80419.00\",\"1.615\"],[\"80459.60\",\"10.344\"],[\"81134.80\",\"0.012\"]],\"st\":1}}"}
{"receive_ns":1788580692265189000,"stream":"btcusdt@depth@100ms","event_type":"depthUpdate","event_time_ms":1788580692311,"raw_json":"{\"stream\":\"btcusdt@depth@100ms\",\"data\":{\"e\":\"depthUpdate\",\"E\":1788580692311,\"T\":1788580692309,\"s\":\"BTCUSDT\",\"ps\":\"BTCUSDT\",\"U\":11479472199245,\"u\":11479472206424,\"pu\":11479472199174,\"b\":[[\"29043.90\",\"0.364\"],[\"29443.90\",\"1.736\"],[\"71589.50\",\"0.006\"],[\"78549.60\",\"2.634\"],[\"78748.50\",\"1.902\"],[\"79146.20\",\"2.269\"],[\"79413.20\",\"11.168\"],[\"79459.00\",\"0.003\"],[\"79460.90\",\"0.128\"],[\"79480.20\",\"2.161\"],[\"79508.40\",\"0.002\"],[\"79531.10\",\"0.007\"],[\"79531.90\",\"0.941\"],[\"79533.50\",\"0.001\"],[\"79533.90\",\"0.000\"],[\"79534.10\",\"1.257\"],[\"79534.40\",\"0.015\"],[\"79539.90\",\"0.109\"]],\"a\":[[\"79573.50\",\"0.265\"],[\"79575.60\",\"0.447\"],[\"79617.60\",\"29.176\"],[\"79620.20\",\"0.008\"],[\"79624.30\",\"0.380\"],[\"79673.90\",\"10.040\"],[\"80339.40\",\"1.429\"],[\"81007.60\",\"8.034\"]],\"st\":1}}"}
{"receive_ns":1788580692379349000,"stream":"btcusdt@depth@100ms","event_type":"depthUpdate","event_time_ms":1788580692413,"raw_json":"{\"stream\":\"btcusdt@depth@100ms\",\"data\":{\"e\":\"depthUpdate\",\"E\":1788580692413,\"T\":1788580692412,\"s\":\"BTCUSDT\",\"ps\":\"BTCUSDT\",\"U\":11479472206593,\"u\":11479472213685,\"pu\":11479472206424,\"b\":[[\"1000.00\",\"25.354\"],[\"29043.90\",\"0.245\"],[\"29343.90\",\"0.056\"],[\"29443.90\",\"1.799\"],[\"71589.50\",\"0.006\"],[\"76362.10\",\"0.002\"],[\"77316.70\",\"0.774\"],[\"78584.10\",\"29.546\"],[\"78748.50\",\"1.904\"],[\"79146.10\",\"0.008\"],[\"79411.50\",\"0.001\"],[\"79413.30\",\"0.006\"],[\"79415.00\",\"3.056\"],[\"79480.90\",\"0.001\"],[\"79482.30\",\"0.015\"],[\"79529.30\",\"0.408\"],[\"79529.40\",\"1.425\"],[\"79533.50\",\"0.001\"],[\"79534.10\",\"0.000\"],[\"79534.40\",\"0.001\"],[\"79539.60\",\"1.492\"],[\"79539.90\",\"0.021\"]],\"a\":[[\"79693.60\",\"0.000\"],[\"79933.80\",\"0.000\"],[\"79936.40\",\"0.626\"],[\"79937.70\",\"0.004\"],[\"79939.70\",\"0.000\"],[\"79941.80\",\"0.000\"],[\"80260.00\",\"0.392\"],[\"80339.40\",\"1.429\"],[\"80551.10\",\"8.038\"],[\"80912.20\",\"0.616\"]],\"st\":1}}"}
{"receive_ns":1788580692457475000,"stream":"btcusdt@depth@100ms","event_type":"depthUpdate","event_time_ms":1788580692515,"raw_json":"{\"stream\":\"btcusdt@depth@100ms\",\"data\":{\"e\":\"depthUpdate\",\"E\":1788580692515,\"T\":1788580692513,\"s\":\"BTCUSDT\",\"ps\":\"BTCUSDT\",\"U\":11479472213689,\"u\":11479472219535,\"pu\":11479472213685,\"b\":[[\"29043.90\",\"0.119\"],[\"29343.90\",\"0.112\"],[\"29443.90\",\"1.869\"],[\"71589.50\",\"0.006\"],[\"75566.70\",\"0.015\"],[\"76362.10\",\"0.000\"],[\"78748.50\",\"1.902\"],[\"79454.40\",\"0.094\"],[\"79461.40\",\"0.000\"],[\"79480.20\",\"2.142\"],[\"79480.90\",\"0.021\"],[\"79482.30\",\"0.241\"],[\"79529.30\",\"0.032\"],[\"79529.40\",\"0.154\"],[\"79533.50\",\"1.652\"],[\"79539.60\",\"1.491\"]],\"a\":[[\"79555.30\",\"0.072\"],[\"79556.10\",\"0.916\"],[\"79633.10\",\"0.022\"],[\"79936.40\",\"0.633\"],[\"79939.70\",\"0.191\"],[\"80339.40\",\"1.429\"],[\"83521.20\",\"0.008\"]],\"st\":1}}"}
{"receive_ns":1788580692525357000,"stream":"btcusdt@bookTicker","event_type":"bookTicker","event_time_ms":1788580692581,"raw_json":"{\"stream\":\"btcusdt@bookTicker\",\"data\":{\"e\":\"bookTicker\",\"u\":11479472223950,\"s\":\"BTCUSDT\",\"ps\":\"BTCUSDT\",\"b\":\"79543.90\",\"B\":\"5.235\",\"a\":\"79544.00\",\"A\":\"7.848\",\"T\":1788580692581,\"E\":1788580692581,\"st\":1}}"}
{"receive_ns":1788580692565537000,"stream":"btcusdt@depth@100ms","event_type":"depthUpdate","event_time_ms":1788580692617,"raw_json":"{\"stream\":\"btcusdt@depth@100ms\",\"data\":{\"e\":\"depthUpdate\",\"E\":1788580692617,\"T\":1788580692616,\"s\":\"BTCUSDT\",\"ps\":\"BTCUSDT\",\"U\":11479472219718,\"u\":11479472226067,\"pu\":11479472219535,\"b\":[[\"29043.90\",\"0.014\"],[\"29343.90\",\"0.182\"],[\"29443.90\",\"1.904\"],[\"63635.00\",\"0.000\"],[\"71589.50\",\"0.006\"],[\"76362.10\",\"0.002\"],[\"78748.50\",\"1.902\"],[\"79146.10\",\"0.009\"],[\"79146.20\",\"2.269\"],[\"79331.60\",\"0.000\"],[\"79379.30\",\"0.002\"],[\"79418.70\",\"0.002\"],[\"79460.30\",\"0.143\"],[\"79461.10\",\"0.013\"],[\"79538.60\",\"0.441\"],[\"79539.60\",\"1.491\"],[\"79543.90\",\"5.235\"]],\"a\":[[\"79571.20\",\"0.045\"],[\"79581.20\",\"0.000\"],[\"79615.20\",\"0.055\"],[\"79617.30\",\"0.001\"],[\"79617.80\",\"0.125\"],[\"79630.00\",\"0.352\"],[\"79666.50\",\"0.000\"],[\"79705.90\",\"0.016\"],[\"79753.50\",\"0.267\"],[\"79753.60\",\"0.001\"],[\"79941.80\",\"0.001\"],[\"80339.40\",\"1.429\"],[\"80680.50\",\"11.142\"],[\"80967.80\",\"0.370\"],[\"81134.80\",\"0.009\"]],\"st\":1}}"}
{"receive_ns":1788580692636631000,"stream":"btcusdt@bookTicker","event_type":"bookTicker","event_time_ms":1788580692692,"raw_json":"{\"stream\":\"btcusdt@bookTicker\",\"data\":{\"e\":\"bookTicker\",\"u\":11479472230790,\"s\":\"BTCUSDT\",\"ps\":\"BTCUSDT\",\"b\":\"79543.90\",\"B\":\"5.234\",\"a\":\"79544.00\",\"A\":\"7.848\",\"T\":1788580692692,\"E\":1788580692692,\"st\":1}}"}
{"receive_ns":1788580692637287000,"stream":"btcusdt@bookTicker","event_type":"bookTicker","event_time_ms":1788580692694,"raw_json":"{\"stream\":\"btcusdt@bookTicker\",\"data\":{\"e\":\"bookTicker\",\"u\":11479472230925,\"s\":\"BTCUSDT\",\"ps\":\"BTCUSDT\",\"b\":\"79543.90\",\"B\":\"5.235\",\"a\":\"79544.00\",\"A\":\"7.848\",\"T\":1788580692694,\"E\":1788580692694,\"st\":1}}"}
{"receive_ns":1788580692637831000,"stream":"btcusdt@bookTicker","event_type":"bookTicker","event_time_ms":1788580692694,"raw_json":"{\"stream\":\"btcusdt@bookTicker\",\"data\":{\"e\":\"bookTicker\",\"u\":11479472230957,\"s\":\"BTCUSDT\",\"ps\":\"BTCUSDT\",\"b\":\"79543.90\",\"B\":\"5.236\",\"a\":\"79544.00\",\"A\":\"7.848\",\"T\":1788580692694,\"E\":1788580692694,\"st\":1}}"}
{"receive_ns":1788580692677801000,"stream":"btcusdt@bookTicker","event_type":"bookTicker","event_time_ms":1788580692704,"raw_json":"{\"stream\":\"btcusdt@bookTicker\",\"data\":{\"e\":\"bookTicker\",\"u\":11479472231503,\"s\":\"BTCUSDT\",\"ps\":\"BTCUSDT\",\"b\":\"79543.90\",\"B\":\"5.236\",\"a\":\"79544.00\",\"A\":\"7.855\",\"T\":1788580692703,\"E\":1788580692704,\"st\":1}}"}
{"receive_ns":1788580692682064000,"stream":"btcusdt@depth@100ms","event_type":"depthUpdate","event_time_ms":1788580692719,"raw_json":"{\"stream\":\"btcusdt@depth@100ms\",\"data\":{\"e\":\"depthUpdate\",\"E\":1788580692719,\"T\":1788580692718,\"s\":\"BTCUSDT\",\"ps\":\"BTCUSDT\",\"U\":11479472226144,\"u\":11479472232345,\"pu\":11479472226067,\"b\":[[\"1000.00\",\"25.354\"],[\"29043.90\",\"0.000\"],[\"29343.90\",\"0.350\"],[\"29443.90\",\"1.750\"],[\"71589.50\",\"0.006\"],[\"78589.40\",\"11.434\"],[\"78748.40\",\"0.001\"],[\"78748.50\",\"1.902\"],[\"79454.40\",\"0.044\"],[\"79480.90\",\"0.021\"],[\"79482.30\",\"0.203\"],[\"79539.60\",\"1.491\"],[\"79539.90\",\"0.109\"],[\"79543.90\",\"5.236\"]],\"a\":[[\"79544.00\",\"7.855\"],[\"79933.80\",\"0.037\"],[\"79936.40\",\"0.633\"],[\"79937.70\",\"0.022\"],[\"79939.70\",\"0.136\"],[\"80180.40\",\"0.497\"],[\"80339.40\",\"1.429\"]],\"st\":1}}"}
{"receive_ns":1788580692704312000,"stream":"btcusdt@bookTicker","event_type":"bookTicker","event_time_ms":1788580692760,"raw_json":"{\"stream\":\"btcusdt@bookTicker\",\"data\":{\"e\":\"bookTicker\",\"u\":11479472234188,\"s\":\"BTCUSDT\",\"ps\":\"BTCUSDT\",\"b\":\"79543.90\",\"B\":\"5.236\",\"a\":\"79544.00\",\"A\":\"7.832\",\"T\":1788580692760,\"E\":1788580692760,\"st\":1}}"}
{"receive_ns":1788580692765804000,"stream":"btcusdt@depth@100ms","event_type":"depthUpdate","event_time_ms":1788580692821,"raw_json":"{\"stream\":\"btcusdt@depth@100ms\",\"data\":{\"e\":\"depthUpdate\",\"E\":1788580692821,\"T\":1788580692818,\"s\":\"BTCUSDT\",\"ps\":\"BTCUSDT\",\"U\":11479472232395,\"u\":11479472236717,\"pu\":11479472232345,\"b\":[[\"29343.90\",\"0.525\"],[\"29443.90\",\"1.575\"],[\"71589.50\",\"0.006\"],[\"75561.70\",\"0.003\"],[\"75561.80\",\"0.004\"],[\"75566.70\",\"0.013\"],[\"75566.80\",\"0.004\"],[\"76362.10\",\"0.000\"],[\"76374.30\",\"0.000\"],[\"78748.50\",\"1.902\"],[\"79331.60\",\"3.239\"],[\"79379.40\",\"1.269\"],[\"79418.70\",\"0.327\"],[\"79504.10\",\"0.004\"],[\"79512.00\",\"0.011\"],[\"79520.20\",\"2.395\"],[\"79522.60\",\"0.799\"],[\"79523.40\",\"0.002\"],[\"79528.30\",\"2.801\"],[\"79528.90\",\"0.001\"],[\"79529.10\",\"0.229\"],[\"79530.40\",\"0.431\"],[\"79539.60\",\"1.491\"]],\"a\":[[\"79544.00\",\"7.832\"],[\"79560.10\",\"0.004\"],[\"79573.50\",\"0.259\"],[\"79575.10\",\"0.016\"],[\"79599.70\",\"0.052\"],[\"79666.50\",\"0.289\"],[\"79705.80\",\"1.214\"],[\"79753.60\",\"3.585\"],[\"79941.70\",\"1.123\"],[\"80324.20\",\"0.000\"],[\"80339.40\",\"1.429\"],[\"80587.00\",\"0.625\"],[\"81134.80\",\"0.012\"]],\"st\":1}}"}
{"receive_ns":1788580692801606000,"stream":"btcusdt@bookTicker","event_type":"bookTicker","event_time_ms":1788580692828,"raw_json":"{\"stream\":\"btcusdt@bookTicker\",\"data\":{\"e\":\"bookTicker\",\"u\":11479472237032,\"s\":\"BTCUSDT\",\"ps\":\"BTCUSDT\",\"b\":\"79543.90\",\"B\":\"5.235\",\"a\":\"79544.00\",\"A\":\"7.832\",\"T\":1788580692828,\"E\":1788580692828,\"st\":1}}"}
{"receive_ns":1788580692802066000,"stream":"btcusdt@bookTicker","event_type":"bookTicker","event_time_ms":1788580692847,"raw_json":"{\"stream\":\"btcusdt@bookTicker\",\"data\":{\"e\":\"bookTicker\",\"u\":11479472239293,\"s\":\"BTCUSDT\",\"ps\":\"BTCUSDT\",\"b\":\"79543.90\",\"B\":\"5.235\",\"a\":\"79544.00\",\"A\":\"7.814\",\"T\":1788580692847,\"E\":1788580692847,\"st\":1}}"}
{"receive_ns":1788580692814412000,"stream":"btcusdt@bookTicker","event_type":"bookTicker","event_time_ms":1788580692860,"raw_json":"{\"stream\":\"btcusdt@bookTicker\",\"data\":{\"e\":\"bookTicker\",\"u\":11479472241680,\"s\":\"BTCUSDT\",\"ps\":\"BTCUSDT\",\"b\":\"79543.90\",\"B\":\"5.235\",\"a\":\"79544.00\",\"A\":\"7.831\",\"T\":1788580692860,\"E\":1788580692860,\"st\":1}}"}
{"receive_ns":1788580692867320000,"stream":"btcusdt@bookTicker","event_type":"bookTicker","event_time_ms":1788580692899,"raw_json":"{\"stream\":\"btcusdt@bookTicker\",\"data\":{\"e\":\"bookTicker\",\"u\":11479472249396,\"s\":\"BTCUSDT\",\"ps\":\"BTCUSDT\",\"b\":\"79543.90\",\"B\":\"5.235\",\"a\":\"79544.00\",\"A\":\"7.873\",\"T\":1788580692899,\"E\":1788580692899,\"st\":1}}"}
{"receive_ns":1788580692867717000,"stream":"btcusdt@depth@100ms","event_type":"depthUpdate","event_time_ms":1788580692923,"raw_json":"{\"stream\":\"btcusdt@depth@100ms\",\"data\":{\"e\":\"depthUpdate\",\"E\":1788580692923,\"T\":1788580692922,\"s\":\"BTCUSDT\",\"ps\":\"BTCUSDT\",\"U\":11479472236823,\"u\":11479472251942,\"pu\":11479472236717,\"b\":[[\"1000.00\",\"25.354\"],[\"29343.90\",\"0.700\"],[\"29443.90\",\"1.400\"],[\"63635.10\",\"0.000\"],[\"71589.50\",\"0.006\"],[\"76362.10\",\"0.002\"],[\"78748.50\",\"1.902\"],[\"79146.20\",\"2.279\"],[\"79418.70\",\"0.002\"],[\"79418.80\",\"0.475\"],[\"79454.40\",\"0.002\"],[\"79480.90\",\"0.001\"],[\"79482.30\",\"0.072\"],[\"79486.60\",\"0.000\"],[\"79517.30\",\"0.454\"],[\"79518.20\",\"0.254\"],[\"79523.80\",\"0.373\"],[\"79524.60\",\"3.556\"],[\"79526.90\",\"0.001\"],[\"79527.80\",\"0.585\"],[\"79528.50\",\"0.000\"],[\"79534.60\",\"0.221\"],[\"79536.80\",\"0.002\"],[\"79539.60\",\"1.492\"],[\"79539.90\",\"0.194\"],[\"79543.90\",\"5.235\"]],\"a\":[[\"79544.00\",\"7.873\"],[\"79545.90\",\"0.004\"],[\"79563.80\",\"0.373\"],[\"79563.90\",\"0.441\"],[\"79564.70\",\"0.002\"],[\"79564.90\",\"0.002\"],[\"79577.40\",\"0.001\"],[\"79578.10\",\"0.006\"],[\"79666.50\",\"0.436\"],[\"79933.80\",\"0.018\"],[\"79936.40\",\"0.633\"],[\"79937.70\",\"0.004\"],[\"79939.70\",\"0.124\"],[\"80339.40\",\"1.429\"],[\"80423.70\",\"2.728\"],[\"80697.40\",\"3.526\"]],\"st\":1}}"}
{"receive_ns":1788580692999788000,"stream":"btcusdt@depth@100ms","event_type":"depthUpdate","event_time_ms":1788580693025,"raw_json":"{\"stream\":\"btcusdt@depth@100ms\",\"data\":{\"e\":\"depthUpdate\",\"E\":1788580693025,\"T\":1788580693021,\"s\":\"BTCUSDT\",\"ps\":\"BTCUSDT\",\"U\":11479472251997,\"u\":11479472261925,\"pu\":11479472251942,\"b\":[[\"1000.00\",\"25.354\"],[\"29343.90\",\"0.882\"],[\"29443.90\",\"1.218\"],[\"71589.50\",\"0.006\"],[\"76362.10\",\"0.000\"],[\"78068.80\",\"7.763\"],[\"78522.20\",\"13.866\"],[\"78549.60\",\"2.919\"],[\"78748.50\",\"1.902\"],[\"79517.30\",\"0.002\"],[\"79518.50\",\"0.452\"],[\"79523.80\",\"0.000\"],[\"79525.00\",\"0.375\"],[\"79526.70\",\"0.080\"],[\"79527.80\",\"0.145\"],[\"79528.50\",\"0.440\"],[\"79534.60\",\"0.201\"],[\"79539.60\",\"1.491\"],[\"79539.70\",\"0.062\"],[\"79539.90\",\"0.021\"],[\"79540.00\",\"0.007\"]],\"a\":[[\"79546.80\",\"0.000\"],[\"79547.60\",\"0.001\"],[\"79563.80\",\"0.000\"],[\"79563.90\",\"0.002\"],[\"79564.90\",\"0.814\"],[\"79939.70\",\"0.173\"],[\"80175.00\",\"5.860\"],[\"80305.40\",\"0.112\"],[\"80339.40\",\"1.429\"],[\"80720.30\",\"4.330\"]],\"st\":1}}"}
{"receive_ns":1788580693049203000,"stream":"btcusdt@bookTicker","event_type":"bookTicker","event_time_ms":1788580693092,"raw_json":"{\"stream\":\"btcusdt@bookTicker\",\"data\":{\"e\":\"bookTicker\",\"u\":11479472267998,\"s\":\"BTCUSDT\",\"ps\":\"BTCUSDT\",\"b\":\"79543.90\",\"B\":\"5.235\",\"a\":\"79544.00\",\"A\":\"7.853\",\"T\":1788580693092,\"E\":1788580693092,\"st\":1}}"}
{"receive_ns":1788580693049393000,"stream":"btcusdt@bookTicker","event_type":"bookTicker","event_time_ms":1788580693095,"raw_json":"{\"stream\":\"btcusdt@bookTicker\",\"data\":{\"e\":\"bookTicker\",\"u\":11479472268234,\"s\":\"BTCUSDT\",\"ps\":\"BTCUSDT\",\"b\":\"79543.90\",\"B\":\"5.235\",\"a\":\"79544.00\",\"A\":\"7.881\",\"T\":1788580693095,\"E\":1788580693095,\"st\":1}}"}
{"receive_ns":1788580693049575000,"stream":"btcusdt@bookTicker","event_type":"bookTicker","event_time_ms":1788580693098,"raw_json":"{\"stream\":\"btcusdt@bookTicker\",\"data\":{\"e\":\"bookTicker\",\"u\":11479472268634,\"s\":\"BTCUSDT\",\"ps\":\"BTCUSDT\",\"b\":\"79543.90\",\"B\":\"5.053\",\"a\":\"79544.00\",\"A\":\"7.881\",\"T\":1788580693098,\"E\":1788580693098,\"st\":1}}"}
{"receive_ns":1788580693125611000,"stream":"btcusdt@depth@100ms","event_type":"depthUpdate","event_time_ms":1788580693127,"raw_json":"{\"stream\":\"btcusdt@depth@100ms\",\"data\":{\"e\":\"depthUpdate\",\"E\":1788580693127,\"T\":1788580693126,\"s\":\"BTCUSDT\",\"ps\":\"BTCUSDT\",\"U\":11479472262288,\"u\":11479472271232,\"pu\":11479472261925,\"b\":[[\"29343.90\",\"1.064\"],[\"29443.90\",\"1.036\"],[\"71589.50\",\"0.006\"],[\"76362.10\",\"0.002\"],[\"78562.00\",\"10.620\"],[\"78748.50\",\"1.902\"],[\"79482.30\",\"0.015\"],[\"79528.40\",\"0.177\"],[\"79529.60\",\"0.002\"],[\"79532.50\",\"0.216\"],[\"79538.50\",\"0.337\"],[\"79538.60\",\"0.440\"],[\"79539.70\",\"0.066\"],[\"79540.00\",\"0.003\"],[\"79543.90\",\"5.053\"]],\"a\":[[\"79544.00\",\"7.881\"],[\"79605.00\",\"0.025\"],[\"79616.10\",\"8.246\"],[\"79624.70\",\"0.527\"],[\"79624.80\",\"1.751\"],[\"79625.00\",\"0.078\"],[\"79639.40\",\"0.031\"],[\"79665.00\",\"0.202\"],[\"79672.60\",\"2.456\"],[\"79933.80\",\"0.000\"],[\"79936.40\",\"0.626\"],[\"79939.70\",\"0.049\"],[\"80339.40\",\"1.429\"],[\"80411.00\",\"1.736\"],[\"80419.00\",\"1.801\"]],\"st\":1}}"}
{"receive_ns":1788580693125868000,"stream":"btcusdt@bookTicker","event_type":"bookTicker","event_time_ms":1788580693130,"raw_json":"{\"stream\":\"btcusdt@bookTicker\",\"data\":{\"e\":\"bookTicker\",\"u\":11479472271506,\"s\":\"BTCUSDT\",\"ps\":\"BTCUSDT\",\"b\":\"79543.90\",\"B\":\"5.221\",\"a\":\"79544.00\",\"A\":\"7.881\",\"T\":1788580693130,\"E\":1788580693130,\"st\":1}}"}
{"receive_ns":1788580693127039000,"stream":"btcusdt@bookTicker","event_type":"bookTicker","event_time_ms":1788580693169,"raw_json":"{\"stream\":\"btcusdt@bookTicker\",\"data\":{\"e\":\"bookTicker\",\"u\":11479472274807,\"s\":\"BTCUSDT\",\"ps\":\"BTCUSDT\",\"b\":\"79543.90\",\"B\":\"5.220\",\"a\":\"79544.00\",\"A\":\"7.881\",\"T\":1788580693169,\"E\":1788580693169,\"st\":1}}"}
{"receive_ns":1788580693127322000,"stream":"btcusdt@bookTicker","event_type":"bookTicker","event_time_ms":1788580693171,"raw_json":"{\"stream\":\"btcusdt@bookTicker\",\"data\":{\"e\":\"bookTicker\",\"u\":11479472274987,\"s\":\"BTCUSDT\",\"ps\":\"BTCUSDT\",\"b\":\"79543.90\",\"B\":\"5.221\",\"a\":\"79544.00\",\"A\":\"7.881\",\"T\":1788580693171,\"E\":1788580693171,\"st\":1}}"}
{"receive_ns":1788580693200930000,"stream":"btcusdt@bookTicker","event_type":"bookTicker","event_time_ms":1788580693225,"raw_json":"{\"stream\":\"btcusdt@bookTicker\",\"data\":{\"e\":\"bookTicker\",\"u\":11479472278817,\"s\":\"BTCUSDT\",\"ps\":\"BTCUSDT\",\"b\":\"79543.90\",\"B\":\"5.221\",\"a\":\"79544.00\",\"A\":\"7.859\",\"T\":1788580693225,\"E\":1788580693225,\"st\":1}}"}
{"receive_ns":1788580693201213000,"stream":"btcusdt@bookTicker","event_type":"bookTicker","event_time_ms":1788580693228,"raw_json":"{\"stream\":\"btcusdt@bookTicker\",\"data\":{\"e\":\"bookTicker\",\"u\":11479472279024,\"s\":\"BTCUSDT\",\"ps\":\"BTCUSDT\",\"b\":\"79543.90\",\"B\":\"5.221\",\"a\":\"79544.00\",\"A\":\"7.882\",\"T\":1788580693228,\"E\":1788580693228,\"st\":1}}"}
{"receive_ns":1788580693201802000,"stream":"btcusdt@depth@100ms","event_type":"depthUpdate","event_time_ms":1788580693229,"raw_json":"{\"stream\":\"btcusdt@depth@100ms\",\"data\":{\"e\":\"depthUpdate\",\"E\":1788580693229,\"T\":1788580693228,\"s\":\"BTCUSDT\",\"ps\":\"BTCUSDT\",\"U\":11479472271343,\"u\":11479472279059,\"pu\":11479472271232,\"b\":[[\"1000.00\",\"25.354\"],[\"29343.90\",\"1.232\"],[\"29443.90\",\"0.868\"],[\"71589.50\",\"0.006\"],[\"71623.00\",\"0.003\"],[\"75561.60\",\"0.041\"],[\"78430.30\",\"9.170\"],[\"78748.50\",\"1.902\"],[\"78840.50\",\"12.814\"],[\"79146.20\",\"2.269\"],[\"79418.80\",\"0.000\"],[\"79454.40\",\"0.027\"],[\"79459.50\",\"1.669\"],[\"79460.30\",\"0.018\"],[\"79480.90\",\"0.021\"],[\"79482.30\",\"0.220\"],[\"79488.20\",\"0.130\"],[\"79504.10\",\"0.002\"],[\"79538.50\",\"0.336\"],[\"79538.70\",\"0.106\"],[\"79539.90\",\"0.109\"],[\"79543.90\",\"5.221\"]],\"a\":[[\"79544.00\",\"7.882\"],[\"79599.70\",\"0.052\"],[\"79624.30\",\"0.378\"],[\"79625.00\",\"0.078\"],[\"79635.70\",\"0.002\"],[\"79637.30\",\"0.002\"],[\"79639.50\",\"0.001\"],[\"79640.40\",\"1.923\"],[\"79666.50\",\"0.000\"],[\"79936.40\",\"0.633\"],[\"79939.70\",\"0.191\"],[\"80339.40\",\"1.429\"],[\"80670.40\",\"18.466\"],[\"80697.40\",\"4.392\"]],\"st\":1}}"}
{"receive_ns":1788580693274270000,"stream":"btcusdt@depth@100ms","event_type":"depthUpdate","event_time_ms":1788580693331,"raw_json":"{\"stream\":\"btcusdt@depth@100ms\",\"data\":{\"e\":\"depthUpdate\",\"E\":1788580693331,\"T\":1788580693330,\"s\":\"BTCUSDT\",\"ps\":\"BTCUSDT\",\"U\":11479472279103,\"u\":11479472285897,\"pu\":11479472279059,\"b\":[[\"1000.00\",\"25.354\"],[\"29343.90\",\"1.421\"],[\"29443.90\",\"0.679\"],[\"71589.50\",\"0.006\"],[\"71623.00\",\"0.000\"],[\"76362.10\",\"0.000\"],[\"78562.00\",\"10.335\"],[\"78748.50\",\"1.902\"],[\"79146.20\",\"2.395\"],[\"79379.40\",\"0.001\"]],\"a\":[[\"79571.80\",\"2.945\"],[\"79575.10\",\"0.010\"],[\"79624.40\",\"0.006\"],[\"79705.80\",\"0.007\"],[\"80339.40\",\"1.429\"],[\"80910.40\",\"0.494\"]],\"st\":1}}"}
{"receive_ns":1788580693384038000,"stream":"btcusdt@depth@100ms","event_type":"depthUpdate","event_time_ms":1788580693433,"raw_json":"{\"stream\":\"btcusdt@depth@100ms\",\"data\":{\"e\":\"depthUpdate\",\"E\":1788580693433,\"T\":1788580693429,\"s\":\"BTCUSDT\",\"ps\":\"BTCUSDT\",\"U\":11479472286007,\"u\":11479472293092,\"pu\":11479472285897,\"b\":[[\"29343.90\",\"1.596\"],[\"29443.90\",\"0.504\"],[\"63635.00\",\"0.000\"],[\"71589.50\",\"0.006\"],[\"75566.70\",\"0.011\"],[\"75566.80\",\"0.006\"],[\"76362.10\",\"0.002\"],[\"78509.80\",\"2.051\"],[\"78748.50\",\"1.902\"],[\"79331.60\",\"0.000\"],[\"79454.40\",\"0.044\"],[\"79480.90\",\"0.021\"],[\"79482.30\",\"0.291\"],[\"79538.60\",\"0.441\"],[\"79538.70\",\"0.105\"],[\"79539.60\",\"1.491\"],[\"79539.90\",\"0.021\"]],\"a\":[[\"79753.60\",\"0.001\"],[\"79933.80\",\"0.018\"],[\"79936.40\",\"0.633\"],[\"79939.70\",\"0.173\"],[\"80339.40\",\"1.429\"],[\"80910.40\",\"0.000\"]],\"st\":1}}"}
{"receive_ns":1788580693450986000,"stream":"btcusdt@bookTicker","event_type":"bookTicker","event_time_ms":1788580693492,"raw_json":"{\"stream\":\"btcusdt@bookTicker\",\"data\":{\"e\":\"bookTicker\",\"u\":11479472297077,\"s\":\"BTCUSDT\",\"ps\":\"BTCUSDT\",\"b\":\"79543.90\",\"B\":\"5.165\",\"a\":\"79544.00\",\"A\":\"7.882\",\"T\":1788580693492,\"E\":1788580693492,\"st\":1}}"}
{"receive_ns":1788580693451200000,"stream":"btcusdt@bookTicker","event_type":"bookTicker","event_time_ms":1788580693503,"raw_json":"{\"stream\":\"btcusdt@bookTicker\",\"data\":{\"e\":\"bookTicker\",\"u\":11479472297922,\"s\":\"BTCUSDT\",\"ps\":\"BTCUSDT\",\"b\":\"79543.90\",\"B\":\"5.171\",\"a\":\"79544.00\",\"A\":\"7.882\",\"T\":1788580693503,\"E\":1788580693503,\"st\":1}}"}
{"receive_ns":1788580693504214000,"stream":"btcusdt@depth@100ms","event_type":"depthUpdate","event_time_ms":1788580693535,"raw_json":"{\"stream\":\"btcusdt@depth@100ms\",\"data\":{\"e\":\"depthUpdate\",\"E\":1788580693535,\"T\":1788580693533,\"s\":\"BTCUSDT\",\"ps\":\"BTCUSDT\",\"U\":11479472293342,\"u\":11479472299765,\"pu\":11479472293092,\"b\":[[\"1000.00\",\"25.354\"],[\"29243.90\",\"0.007\"],[\"29343.90\",\"1.764\"],[\"29443.90\",\"0.329\"],[\"71589.50\",\"0.006\"],[\"76362.10\",\"0.000\"],[\"78509.40\",\"2.223\"],[\"78522.20\",\"12.976\"],[\"78674.30\",\"0.190\"],[\"78748.50\",\"1.902\"],[\"79140.90\",\"1.702\"],[\"79143.80\",\"0.935\"],[\"79146.20\",\"2.395\"],[\"79331.70\",\"4.773\"],[\"79343.10\",\"0.001\"],[\"79379.40\",\"2.088\"],[\"79418.80\",\"0.475\"],[\"79517.30\",\"0.002\"],[\"79518.50\",\"0.452\"],[\"79523.80\",\"0.000\"],[\"79524.70\",\"0.001\"],[\"79525.00\",\"0.375\"],[\"79525.20\",\"0.000\"],[\"79525.80\",\"0.538\"],[\"79526.30\",\"0.029\"],[\"79526.90\",\"0.001\"],[\"79527.80\",\"0.145\"],[\"79528.40\",\"0.617\"],[\"79528.50\",\"0.000\"],[\"79538.50\",\"0.337\"],[\"79538.60\",\"0.440\"],[\"79539.60\",\"1.491\"],[\"79543.90\",\"5.171\"]],\"a\":[[\"79563.80\",\"0.000\"],[\"79563.90\",\"0.002\"],[\"79564.90\",\"0.814\"],[\"79567.60\",\"0.034\"],[\"79568.00\",\"0.456\"],[\"79588.40\",\"1.998\"],[\"79589.40\",\"0.017\"],[\"79589.60\",\"0.191\"],[\"79666.50\",\"0.436\"],[\"79705.80\",\"1.950\"],[\"79753.60\",\"4.853\"],[\"80339.40\",\"1.429\"],[\"80419.00\",\"1.987\"],[\"81134.80\",\"0.015\"]],\"st\":1}}"}
{"receive_ns":1788580693525960000,"stream":"btcusdt@bookTicker","event_type":"bookTicker","event_time_ms":1788580693582,"raw_json":"{\"stream\":\"btcusdt@bookTicker\",\"data\":{\"e\":\"bookTicker\",\"u\":11479472302128,\"s\":\"BTCUSDT\",\"ps\":\"BTCUSDT\",\"b\":\"79543.90\",\"B\":\"5.172\",\"a\":\"79544.00\",\"A\":\"7.882\",\"T\":1788580693581,\"E\":1788580693582,\"st\":1}}"}
{"receive_ns":1788580693584123000,"stream":"btcusdt@bookTicker","event_type":"bookTicker","event_time_ms":1788580693634,"raw_json":"{\"stream\":\"btcusdt@bookTicker\",\"data\":{\"e\":\"bookTicker\",\"u\":11479472305234,\"s\":\"BTCUSDT\",\"ps\":\"BTCUSDT\",\"b\":\"79543.90\",\"B\":\"5.171\",\"a\":\"79544.00\",\"A\":\"7.882\",\"T\":1788580693634,\"E\":1788580693634,\"st\":1}}"}
{"receive_ns":1788580693584310000,"stream":"btcusdt@bookTicker","event_type":"bookTicker","event_time_ms":1788580693636,"raw_json":"{\"stream\":\"btcusdt@bookTicker\",\"data\":{\"e\":\"bookTicker\",\"u\":11479472305448,\"s\":\"BTCUSDT\",\"ps\":\"BTCUSDT\",\"b\":\"79543.90\",\"B\":\"5.172\",\"a\":\"79544.00\",\"A\":\"7.882\",\"T\":1788580693636,\"E\":1788580693636,\"st\":1}}"}
{"receive_ns":1788580693584592000,"stream":"btcusdt@depth@100ms","event_type":"depthUpdate","event_time_ms":1788580693637,"raw_json":"{\"stream\":\"btcusdt@depth@100ms\",\"data\":{\"e\":\"depthUpdate\",\"E\":1788580693637,\"T\":1788580693636,\"s\":\"BTCUSDT\",\"ps\":\"BTCUSDT\",\"U\":11479472299874,\"u\":11479472305491,\"pu\":11479472299765,\"b\":[[\"1000.00\",\"25.354\"],[\"29243.90\",\"0.063\"],[\"29343.90\",\"1.820\"],[\"29443.90\",\"0.217\"],[\"63635.00\",\"0.000\"],[\"71589.50\",\"0.006\"],[\"76362.10\",\"0.002\"],[\"77513.60\",\"0.350\"],[\"78281.20\",\"0.003\"],[\"78748.40\",\"0.000\"],[\"78748.50\",\"1.902\"],[\"79146.10\",\"0.009\"],[\"79418.80\",\"0.000\"],[\"79454.40\",\"0.094\"],[\"79459.00\",\"0.003\"],[\"79459.50\",\"1.544\"],[\"79480.90\",\"0.001\"],[\"79482.30\",\"0.153\"],[\"79506.40\",\"10.033\"],[\"79507.10\",\"3.839\"],[\"79539.60\",\"1.491\"],[\"79543.90\",\"5.172\"]],\"a\":[[\"79574.90\",\"10.139\"],[\"79575.30\",\"0.002\"],[\"79666.50\",\"0.000\"],[\"79933.80\",\"0.000\"],[\"79936.40\",\"0.626\"],[\"79939.70\",\"0.142\"],[\"79941.80\",\"0.001\"],[\"80339.40\",\"1.429\"],[\"80521.40\",\"15.374\"]],\"st\":1}}"}
{"receive_ns":1788580693631571000,"stream":"btcusdt@bookTicker","event_type":"bookTicker","event_time_ms":1788580693667,"raw_json":"{\"stream\":\"btcusdt@bookTicker\",\"data\":{\"e\":\"bookTicker\",\"u\":11479472307478,\"s\":\"BTCUSDT\",\"ps\":\"BTCUSDT\",\"b\":\"79543.90\",\"B\":\"5.004\",\"a\":\"79544.00\",\"A\":\"7.882\",\"T\":1788580693667,\"E\":1788580693667,\"st\":1}}"}
{"receive_ns":1788580693631797000,"stream":"btcusdt@bookTicker","event_type":"bookTicker","event_time_ms":1788580693669,"raw_json":"{\"stream\":\"btcusdt@bookTicker\",\"data\":{\"e\":\"bookTicker\",\"u\":11479472307724,\"s\":\"BTCUSDT\",\"ps\":\"BTCUSDT\",\"b\":\"79543.90\",\"B\":\"5.171\",\"a\":\"79544.00\",\"A\":\"7.882\",\"T\":1788580693669,\"E\":1788580693669,\"st\":1}}"}
{"receive_ns":1788580693694090000,"stream":"btcusdt@depth@100ms","event_type":"depthUpdate","event_time_ms":1788580693739,"raw_json":"{\"stream\":\"btcusdt@depth@100ms\",\"data\":{\"e\":\"depthUpdate\",\"E\":1788580693739,\"T\":1788580693738,\"s\":\"BTCUSDT\",\"ps\":\"BTCUSDT\",\"U\":11479472305571,\"u\":11479472311461,\"pu\":11479472305491,\"b\":[[\"29243.90\",\"0.126\"],[\"29343.90\",\"1.883\"],[\"29443.90\",\"0.091\"],[\"63635.00\",\"0.000\"],[\"71589.50\",\"0.006\"],[\"78333.20\",\"4.463\"],[\"78532.10\",\"0.191\"],[\"78743.20\",\"6.911\"],[\"78748.50\",\"1.902\"],[\"79146.20\",\"2.899\"],[\"79418.80\",\"0.343\"],[\"79453.10\",\"0.020\"],[\"79460.40\",\"0.001\"],[\"79460.90\",\"0.128\"],[\"79482.30\",\"0.241\"],[\"79539.60\",\"1.492\"],[\"79543.90\",\"5.171\"]],\"a\":[[\"79666.50\",\"0.307\"],[\"79934.40\",\"0.386\"],[\"79939.70\",\"0.191\"],[\"80339.40\",\"1.429\"],[\"80423.70\",\"2.294\"],[\"80498.50\",\"13.519\"]],\"st\":1}}"}
{"receive_ns":1788580693704506000,"stream":"btcusdt@bookTicker","event_type":"bookTicker","event_time_ms":1788580693760,"raw_json":"{\"stream\":\"btcusdt@bookTicker\",\"data\":{\"e\":\"bookTicker\",\"u\":11479472312826,\"s\":\"BTCUSDT\",\"ps\":\"BTCUSDT\",\"b\":\"79543.90\",\"B\":\"5.171\",\"a\":\"79544.00\",\"A\":\"7.905\",\"T\":1788580693760,\"E\":1788580693760,\"st\":1}}"}
{"receive_ns":1788580693704674000,"stream":"btcusdt@bookTicker","event_type":"bookTicker","event_time_ms":1788580693762,"raw_json":"{\"stream\":\"btcusdt@bookTicker\",\"data\":{\"e\":\"bookTicker\",\"u\":11479472312931,\"s\":\"BTCUSDT\",\"ps\":\"BTCUSDT\",\"b\":\"79543.90\",\"B\":\"5.171\",\"a\":\"79544.00\",\"A\":\"7.903\",\"T\":1788580693761,\"E\":1788580693762,\"st\":1}}"}
{"receive_ns":1788580693748332000,"stream":"btcusdt@bookTicker","event_type":"bookTicker","event_time_ms":1788580693795,"raw_json":"{\"stream\":\"btcusdt@bookTicker\",\"data\":{\"e\":\"bookTicker\",\"u\":11479472314845,\"s\":\"BTCUSDT\",\"ps\":\"BTCUSDT\",\"b\":\"79543.90\",\"B\":\"5.107\",\"a\":\"79544.00\",\"A\":\"7.903\",\"T\":1788580693795,\"E\":1788580693795,\"st\":1}}"}
{"receive_ns":1788580693748568000,"stream":"btcusdt@bookTicker","event_type":"bookTicker","event_time_ms":1788580693798,"raw_json":"{\"stream\":\"btcusdt@bookTicker\",\"data\":{\"e\":\"bookTicker\",\"u\":11479472315063,\"s\":\"BTCUSDT\",\"ps\":\"BTCUSDT\",\"b\":\"79543.90\",\"B\":\"5.180\",\"a\":\"79544.00\",\"A\":\"7.903\",\"T\":1788580693798,\"E\":1788580693798,\"st\":1}}"}
{"receive_ns":1788580693748814000,"stream":"btcusdt@bookTicker","event_type":"bookTicker","event_time_ms":1788580693799,"raw_json":"{\"stream\":\"btcusdt@bookTicker\",\"data\":{\"e\":\"bookTicker\",\"u\":11479472315119,\"s\":\"BTCUSDT\",\"ps\":\"BTCUSDT\",\"b\":\"79543.90\",\"B\":\"5.180\",\"a\":\"79544.00\",\"A\":\"7.905\",\"T\":1788580693799,\"E\":1788580693799,\"st\":1}}"}
{"receive_ns":1788580693755489000,"stream":"btcusdt@bookTicker","event_type":"bookTicker","event_time_ms":1788580693811,"raw_json":"{\"stream\":\"btcusdt@bookTicker\",\"data\":{\"e\":\"bookTicker\",\"u\":11479472316289,\"s\":\"BTCUSDT\",\"ps\":\"BTCUSDT\",\"b\":\"79543.90\",\"B\":\"5.179\",\"a\":\"79544.00\",\"A\":\"7.905\",\"T\":1788580693811,\"E\":1788580693811,\"st\":1}}"}
{"receive_ns":1788580693755745000,"stream":"btcusdt@trade","event_type":"trade","event_time_ms":1788580693811,"raw_json":"{\"stream\":\"btcusdt@trade\",\"data\":{\"e\":\"trade\",\"E\":1788580693811,\"T\":1788580693811,\"s\":\"BTCUSDT\",\"t\":8054266629,\"p\":\"79543.90\",\"q\":\"0.001\",\"X\":\"MARKET\",\"m\":true,\"st\":1}}"}
{"receive_ns":1788580693772671000,"stream":"btcusdt@bookTicker","event_type":"bookTicker","event_time_ms":1788580693828,"raw_json":"{\"stream\":\"btcusdt@bookTicker\",\"data\":{\"e\":\"bookTicker\",\"u\":11479472317482,\"s\":\"BTCUSDT\",\"ps\":\"BTCUSDT\",\"b\":\"79543.90\",\"B\":\"5.178\",\"a\":\"79544.00\",\"A\":\"7.905\",\"T\":1788580693828,\"E\":1788580693828,\"st\":1}}"}
{"receive_ns":1788580693806848000,"stream":"btcusdt@depth@100ms","event_type":"depthUpdate","event_time_ms":1788580693841,"raw_json":"{\"stream\":\"btcusdt@depth@100ms\",\"data\":{\"e\":\"depthUpdate\",\"E\":1788580693841,\"T\":1788580693840,\"s\":\"BTCUSDT\",\"ps\":\"BTCUSDT\",\"U\":11479472311522,\"u\":11479472318378,\"pu\":11479472311461,\"b\":[[\"1000.00\",\"25.354\"],[\"29243.90\",\"0.210\"],[\"29343.90\",\"1.890\"],[\"29443.90\",\"0.000\"],[\"71589.50\",\"0.006\"],[\"76362.10\",\"0.000\"],[\"77953.10\",\"0.012\"],[\"78748.50\",\"1.904\"],[\"78840.50\",\"12.624\"],[\"79146.20\",\"2.899\"],[\"79356.80\",\"6.292\"],[\"79358.20\",\"0.000\"],[\"79397.80\",\"1.890\"],[\"79399.60\",\"0.000\"],[\"79418.80\",\"0.000\"],[\"79459.10\",\"0.038\"],[\"79459.20\",\"0.126\"],[\"79459.40\",\"0.046\"],[\"79460.10\",\"2.141\"],[\"79520.20\",\"2.395\"],[\"79526.30\",\"0.003\"],[\"79539.60\",\"1.491\"],[\"79543.90\",\"5.178\"]],\"a\":[[\"79544.00\",\"7.905\"],[\"79559.40\",\"0.076\"],[\"79560.10\",\"0.004\"],[\"79634.20\",\"0.170\"],[\"79634.50\",\"0.000\"],[\"79666.50\",\"0.000\"],[\"79668.60\",\"4.090\"],[\"79668.80\",\"0.011\"],[\"79683.60\",\"3.159\"],[\"79684.20\",\"0.526\"],[\"79687.30\",\"0.003\"],[\"80339.40\",\"1.429\"],[\"83521.20\",\"0.012\"]],\"st\":1}}"}
{"receive_ns":1788580693885892000,"stream":"btcusdt@depth@100ms","event_type":"depthUpdate","event_time_ms":1788580693943,"raw_json":"{\"stream\":\"btcusdt@depth@100ms\",\"data\":{\"e\":\"depthUpdate\",\"E\":1788580693943,\"T\":1788580693942,\"s\":\"BTCUSDT\",\"ps\":\"BTCUSDT\",\"U\":11479472318430,\"u\":11479472324296,\"pu\":11479472318378,\"b\":[[\"1000.00\",\"25.354\"],[\"29243.90\",\"0.392\"],[\"29343.90\",\"1.708\"],[\"63635.10\",\"0.000\"],[\"71589.50\",\"0.006\"],[\"76362.10\",\"0.002\"],[\"78522.20\",\"12.086\"],[\"78562.00\",\"9.903\"],[\"78748.50\",\"1.902\"],[\"79453.10\",\"0.020\"],[\"79454.40\",\"0.094\"],[\"79482.30\",\"0.241\"],[\"79539.60\",\"1.492\"]],\"a\":[[\"79934.40\",\"0.386\"],[\"79939.70\",\"0.191\"],[\"80339.40\",\"1.429\"]],\"st\":1}}"}
{"receive_ns":1788580693989030000,"stream":"btcusdt@depth@100ms","event_type":"depthUpdate","event_time_ms":1788580694045,"raw_json":"{\"stream\":\"btcusdt@depth@100ms\",\"data\":{\"e\":\"depthUpdate\",\"E\":1788580694045,\"T\":1788580694042,\"s\":\"BTCUSDT\",\"ps\":\"BTCUSDT\",\"U\":11479472324399,\"u\":11479472330506,\"pu\":11479472324296,\"b\":[[\"29243.90\",\"0.567\"],[\"29343.90\",\"1.533\"],[\"63635.00\",\"0.000\"],[\"71589.50\",\"0.006\"],[\"75566.80\",\"0.004\"],[\"76362.10\",\"0.000\"],[\"78430.30\",\"11.080\"],[\"78589.40\",\"12.705\"],[\"78748.50\",\"1.902\"],[\"79146.20\",\"2.909\"],[\"79418.80\",\"0.457\"],[\"79524.70\",\"0.374\"],[\"79525.00\",\"0.002\"],[\"79525.50\",\"0.047\"],[\"79525.80\",\"0.492\"],[\"79525.90\",\"0.011\"],[\"79526.60\",\"0.005\"],[\"79529.60\",\"0.006\"],[\"79539.60\",\"1.491\"]],\"a\":[[\"79564.50\",\"1.219\"],[\"79564.60\",\"0.577\"],[\"79564.90\",\"0.002\"],[\"79565.60\",\"0.760\"],[\"79565.70\",\"0.873\"],[\"79589.30\",\"2.678\"],[\"79589.60\",\"0.145\"],[\"79590.40\",\"0.214\"],[\"79666.50\",\"0.417\"],[\"80339.40\",\"1.429\"],[\"80411.00\",\"2.170\"]],\"st\":1}}"}
{"receive_ns":1788580694064286000,"stream":"btcusdt@bookTicker","event_type":"bookTicker","event_time_ms":1788580694076,"raw_json":"{\"stream\":\"btcusdt@bookTicker\",\"data\":{\"e\":\"bookTicker\",\"u\":11479472332749,\"s\":\"BTCUSDT\",\"ps\":\"BTCUSDT\",\"b\":\"79543.90\",\"B\":\"5.177\",\"a\":\"79544.00\",\"A\":\"7.905\",\"T\":1788580694076,\"E\":1788580694076,\"st\":1}}"}
{"receive_ns":1788580694064505000,"stream":"btcusdt@bookTicker","event_type":"bookTicker","event_time_ms":1788580694078,"raw_json":"{\"stream\":\"btcusdt@bookTicker\",\"data\":{\"e\":\"bookTicker\",\"u\":11479472332890,\"s\":\"BTCUSDT\",\"ps\":\"BTCUSDT\",\"b\":\"79543.90\",\"B\":\"5.178\",\"a\":\"79544.00\",\"A\":\"7.905\",\"T\":1788580694078,\"E\":1788580694078,\"st\":1}}"}
{"receive_ns":1788580694064755000,"stream":"btcusdt@bookTicker","event_type":"bookTicker","event_time_ms":1788580694114,"raw_json":"{\"stream\":\"btcusdt@bookTicker\",\"data\":{\"e\":\"bookTicker\",\"u\":11479472335224,\"s\":\"BTCUSDT\",\"ps\":\"BTCUSDT\",\"b\":\"79543.90\",\"B\":\"5.178\",\"a\":\"79544.00\",\"A\":\"7.907\",\"T\":1788580694114,\"E\":1788580694114,\"st\":1}}"}
{"receive_ns":1788580694089887000,"stream":"btcusdt@depth@100ms","event_type":"depthUpdate","event_time_ms":1788580694147,"raw_json":"{\"stream\":\"btcusdt@depth@100ms\",\"data\":{\"e\":\"depthUpdate\",\"E\":1788580694147,\"T\":1788580694145,\"s\":\"BTCUSDT\",\"ps\":\"BTCUSDT\",\"U\":11479472330804,\"u\":11479472337449,\"pu\":11479472330506,\"b\":[[\"1000.00\",\"25.354\"],[\"29243.90\",\"0.749\"],[\"29343.90\",\"1.351\"],[\"63635.00\",\"0.000\"],[\"71589.50\",\"0.006\"],[\"78748.50\",\"1.902\"],[\"78907.50\",\"3.921\"],[\"79453.10\",\"0.000\"],[\"79454.40\",\"0.044\"],[\"79482.30\",\"0.291\"],[\"79529.60\",\"0.002\"],[\"79543.90\",\"5.178\"]],\"a\":[[\"79544.00\",\"7.907\"],[\"79605.10\",\"0.019\"],[\"79605.20\",\"3.407\"],[\"79624.40\",\"0.007\"],[\"79625.00\",\"0.077\"],[\"79625.10\",\"0.002\"],[\"79632.50\",\"2.204\"],[\"79635.70\",\"0.000\"],[\"79639.50\",\"0.000\"],[\"79639.60\",\"0.002\"],[\"79640.40\",\"1.918\"],[\"79668.10\",\"0.007\"],[\"79687.20\",\"0.000\"],[\"79753.50\",\"0.959\"],[\"79934.40\",\"0.379\"],[\"79939.70\",\"0.191\"],[\"80339.40\",\"1.429\"],[\"80670.40\",\"18.095\"],[\"80679.20\",\"0.619\"]],\"st\":1}}"}
{"receive_ns":1788580694201329000,"stream":"btcusdt@depth@100ms","event_type":"depthUpdate","event_time_ms":1788580694249,"raw_json":"{\"stream\":\"btcusdt@depth@100ms\",\"data\":{\"e\":\"depthUpdate\",\"E\":1788580694249,\"T\":1788580694248,\"s\":\"BTCUSDT\",\"ps\":\"BTCUSDT\",\"U\":11479472337580,\"u\":11479472343975,\"pu\":11479472337449,\"b\":[[\"1000.00\",\"25.354\"],[\"29243.90\",\"0.924\"],[\"29343.90\",\"1.176\"],[\"71589.50\",\"0.006\"],[\"76362.10\",\"0.002\"],[\"78452.60\",\"17.189\"],[\"78748.50\",\"1.904\"],[\"79480.90\",\"0.021\"]],\"a\":[[\"79564.50\",\"0.780\"],[\"79564.90\",\"0.441\"],[\"79624.40\",\"0.008\"],[\"79639.60\",\"0.004\"],[\"79755.20\",\"3.050\"],[\"79934.40\",\"0.386\"],[\"80538.30\",\"2.003\"],[\"80551.10\",\"7.760\"],[\"80657.60\",\"13.193\"]],\"st\":1}}"}
{"receive_ns":1788580694339138000,"stream":"btcusdt@depth@100ms","event_type":"depthUpdate","event_time_ms":1788580694351,"raw_json":"{\"stream\":\"btcusdt@depth@100ms\",\"data\":{\"e\":\"depthUpdate\",\"E\":1788580694351,\"T\":1788580694349,\"s\":\"BTCUSDT\",\"ps\":\"BTCUSDT\",\"U\":11479472344052,\"u\":11479472351661,\"pu\":11479472343975,\"b\":[[\"29243.90\",\"1.106\"],[\"29343.90\",\"0.994\"],[\"63635.00\",\"0.000\"],[\"71589.50\",\"0.006\"],[\"71623.00\",\"0.000\"],[\"76362.10\",\"0.000\"],[\"78426.80\",\"0.459\"],[\"78748.50\",\"1.902\"],[\"79146.20\",\"2.909\"],[\"79459.20\",\"0.001\"],[\"79460.70\",\"0.126\"],[\"79517.30\",\"0.454\"],[\"79518.50\",\"0.000\"]],\"a\":[[\"80339.40\",\"1.429\"]],\"st\":1}}"}
{"receive_ns":1788580694411089000,"stream":"btcusdt@depth@100ms","event_type":"depthUpdate","event_time_ms":1788580694453,"raw_json":"{\"stream\":\"btcusdt@depth@100ms\",\"data\":{\"e\":\"depthUpdate\",\"E\":1788580694453,\"T\":1788580694449,\"s\":\"BTCUSDT\",\"ps\":\"BTCUSDT\",\"U\":11479472351761,\"u\":11479472358855,\"pu\":11479472351661,\"b\":[[\"1000.00\",\"25.354\"],[\"29243.90\",\"1.281\"],[\"29343.90\",\"0.819\"],[\"71589.50\",\"0.006\"],[\"76362.10\",\"0.002\"],[\"78748.50\",\"1.902\"],[\"79453.10\",\"0.020\"],[\"79454.40\",\"0.094\"],[\"79460.70\",\"0.001\"],[\"79480.90\",\"0.001\"],[\"79482.30\",\"0.241\"],[\"79517.30\",\"0.002\"],[\"79518.40\",\"0.478\"],[\"79523.80\",\"0.000\"],[\"79524.60\",\"3.556\"],[\"79524.70\",\"0.001\"],[\"79525.00\",\"0.375\"],[\"79525.50\",\"0.001\"],[\"79525.70\",\"0.049\"],[\"79526.90\",\"0.001\"],[\"79527.80\",\"0.145\"],[\"79528.40\",\"0.617\"],[\"79539.60\",\"1.491\"]],\"a\":[[\"79563.80\",\"0.000\"],[\"79563.90\",\"0.002\"],[\"79564.60\",\"0.204\"],[\"79564.80\",\"0.375\"],[\"79564.90\",\"0.441\"],[\"79588.30\",\"0.201\"],[\"79589.30\",\"2.632\"],[\"79589.50\",\"0.429\"],[\"79699.10\",\"0.498\"],[\"79786.50\",\"0.000\"],[\"79791.80\",\"12.161\"],[\"79934.40\",\"0.386\"],[\"79939.70\",\"0.173\"],[\"80339.40\",\"1.429\"],[\"80551.10\",\"7.611\"]],\"st\":1}}"}
{"receive_ns":1788580694530632000,"stream":"btcusdt@depth@100ms","event_type":"depthUpdate","event_time_ms":1788580694555,"raw_json":"{\"stream\":\"btcusdt@depth@100ms\",\"data\":{\"e\":\"depthUpdate\",\"E\":1788580694555,\"T\":1788580694554,\"s\":\"BTCUSDT\",\"ps\":\"BTCUSDT\",\"U\":11479472359125,\"u\":11479472367347,\"pu\":11479472358855,\"b\":[[\"1000.00\",\"25.354\"],[\"29243.90\",\"1.456\"],[\"29343.90\",\"0.644\"],[\"63635.00\",\"0.094\"],[\"71589.50\",\"0.006\"],[\"76362.10\",\"0.000\"],[\"78615.60\",\"0.000\"],[\"78617.40\",\"0.002\"],[\"78748.50\",\"1.902\"],[\"79321.30\",\"0.000\"],[\"79460.80\",\"0.125\"],[\"79488.20\",\"0.128\"],[\"79504.10\",\"0.004\"],[\"79539.60\",\"1.491\"]],\"a\":[[\"79564.20\",\"0.051\"],[\"79573.00\",\"0.002\"],[\"79599.70\",\"0.052\"],[\"79614.00\",\"0.047\"],[\"79617.20\",\"0.042\"],[\"79785.30\",\"0.911\"],[\"80339.40\",\"1.429\"],[\"80521.40\",\"14.134\"],[\"81134.80\",\"0.018\"]],\"st\":1}}"}
{"receive_ns":1788580694580570000,"stream":"btcusdt@bookTicker","event_type":"bookTicker","event_time_ms":1788580694616,"raw_json":"{\"stream\":\"btcusdt@bookTicker\",\"data\":{\"e\":\"bookTicker\",\"u\":11479472371543,\"s\":\"BTCUSDT\",\"ps\":\"BTCUSDT\",\"b\":\"79543.90\",\"B\":\"5.177\",\"a\":\"79544.00\",\"A\":\"7.907\",\"T\":1788580694616,\"E\":1788580694616,\"st\":1}}"}
{"receive_ns":1788580694580786000,"stream":"btcusdt@trade","event_type":"trade","event_time_ms":1788580694616,"raw_json":"{\"stream\":\"btcusdt@trade\",\"data\":{\"e\":\"trade\",\"E\":1788580694616,\"T\":1788580694616,\"s\":\"BTCUSDT\",\"t\":8054266630,\"p\":\"79543.90\",\"q\":\"0.001\",\"X\":\"MARKET\",\"m\":true,\"st\":1}}"}
{"receive_ns":1788580694593951000,"stream":"btcusdt@bookTicker","event_type":"bookTicker","event_time_ms":1788580694649,"raw_json":"{\"stream\":\"btcusdt@bookTicker\",\"data\":{\"e\":\"bookTicker\",\"u\":11479472373912,\"s\":\"BTCUSDT\",\"ps\":\"BTCUSDT\",\"b\":\"79543.90\",\"B\":\"5.176\",\"a\":\"79544.00\",\"A\":\"7.907\",\"T\":1788580694649,\"E\":1788580694649,\"st\":1}}"}
{"receive_ns":1788580694594226000,"stream":"btcusdt@bookTicker","event_type":"bookTicker","event_time_ms":1788580694651,"raw_json":"{\"stream\":\"btcusdt@bookTicker\",\"data\":{\"e\":\"bookTicker\",\"u\":11479472374129,\"s\":\"BTCUSDT\",\"ps\":\"BTCUSDT\",\"b\":\"79543.90\",\"B\":\"5.177\",\"a\":\"79544.00\",\"A\":\"7.907\",\"T\":1788580694650,\"E\":1788580694651,\"st\":1}}"}
{"receive_ns":1788580694602185000,"stream":"btcusdt@depth@100ms","event_type":"depthUpdate","event_time_ms":1788580694657,"raw_json":"{\"stream\":\"btcusdt@depth@100ms\",\"data\":{\"e\":\"depthUpdate\",\"E\":1788580694657,\"T\":1788580694655,\"s\":\"BTCUSDT\",\"ps\":\"BTCUSDT\",\"U\":11479472367449,\"u\":11479472374523,\"pu\":11479472367347,\"b\":[[\"29243.90\",\"1.638\"],[\"29343.90\",\"0.462\"],[\"63635.00\",\"0.000\"],[\"71589.50\",\"0.006\"],[\"75566.70\",\"0.009\"],[\"75566.80\",\"0.006\"],[\"78549.60\",\"3.204\"],[\"78748.50\",\"1.902\"],[\"79146.10\",\"0.008\"],[\"79146.20\",\"2.909\"],[\"79418.80\",\"0.000\"],[\"79418.90\",\"0.475\"],[\"79453.10\",\"0.000\"],[\"79454.40\",\"0.094\"],[\"79460.80\",\"0.000\"],[\"79461.10\",\"0.013\"],[\"79480.90\",\"0.021\"],[\"79481.90\",\"1.417\"],[\"79482.30\",\"0.241\"],[\"79482.90\",\"0.586\"],[\"79489.90\",\"0.062\"],[\"79490.90\",\"0.229\"],[\"79505.80\",\"0.330\"],[\"79506.80\",\"0.653\"],[\"79517.30\",\"0.454\"],[\"79518.40\",\"0.026\"],[\"79523.80\",\"0.373\"],[\"79524.70\",\"0.047\"],[\"79525.00\",\"0.002\"],[\"79525.70\",\"0.003\"],[\"79527.80\",\"0.585\"],[\"79528.40\",\"0.177\"],[\"79539.60\",\"1.492\"],[\"79543.90\",\"5.177\"]],\"a\":[[\"79563.80\",\"0.373\"],[\"79563.90\",\"0.441\"],[\"79564.80\",\"0.002\"],[\"79564.90\",\"0.002\"],[\"79595.50\",\"0.136\"],[\"79595.60\",\"0.500\"],[\"79612.40\",\"0.002\"],[\"79617.20\",\"0.063\"],[\"79620.10\",\"0.446\"],[\"79648.00\",\"3.852\"],[\"79666.40\",\"0.436\"],[\"79666.50\",\"0.000\"],[\"79699.10\",\"0.480\"],[\"79934.40\",\"0.379\"],[\"79939.70\",\"0.191\"],[\"79941.80\",\"0.000\"],[\"80339.40\",\"1.429\"]],\"st\":1}}"}
{"receive_ns":1788580694716831000,"stream":"btcusdt@depth@100ms","event_type":"depthUpdate","event_time_ms":1788580694759,"raw_json":"{\"stream\":\"btcusdt@depth@100ms\",\"data\":{\"e\":\"depthUpdate\",\"E\":1788580694759,\"T\":1788580694758,\"s\":\"BTCUSDT\",\"ps\":\"BTCUSDT\",\"U\":11479472374592,\"u\":11479472380286,\"pu\":11479472374523,\"b\":[[\"1000.00\",\"25.354\"],[\"29143.90\",\"0.021\"],[\"29243.90\",\"1.778\"],[\"29343.90\",\"0.301\"],[\"71589.50\",\"0.006\"],[\"76362.10\",\"0.002\"],[\"78056.40\",\"0.639\"],[\"78412.80\",\"2.675\"],[\"78509.30\",\"0.955\"],[\"78748.50\",\"1.904\"],[\"78833.40\",\"0.190\"],[\"79146.10\",\"0.009\"],[\"79356.00\",\"0.128\"],[\"79397.70\",\"1.988\"],[\"79397.80\",\"0.004\"],[\"79460.80\",\"0.125\"],[\"79488.20\",\"0.130\"],[\"79504.70\",\"0.000\"],[\"79523.80\",\"0.373\"],[\"79525.00\",\"0.002\"],[\"79539.60\",\"1.492\"]],\"a\":[[\"79558.20\",\"0.179\"],[\"79563.80\",\"0.000\"],[\"79563.90\",\"0.441\"],[\"79564.90\",\"0.375\"],[\"79569.90\",\"0.087\"],[\"79571.80\",\"2.939\"],[\"79573.70\",\"1.030\"],[\"79600.30\",\"0.015\"],[\"79607.50\",\"0.057\"],[\"79615.60\",\"0.006\"],[\"79668.50\",\"1.891\"],[\"79668.60\",\"2.204\"],[\"79936.40\",\"0.633\"],[\"79941.80\",\"0.001\"],[\"80180.40\",\"1.244\"],[\"80272.80\",\"0.000\"],[\"80312.30\",\"3.416\"],[\"80339.40\",\"1.429\"]],\"st\":1}}"}
{"receive_ns":1788580694822516000,"stream":"btcusdt@depth@100ms","event_type":"depthUpdate","event_time_ms":1788580694861,"raw_json":"{\"stream\":\"btcusdt@depth@100ms\",\"data\":{\"e\":\"depthUpdate\",\"E\":1788580694861,\"T\":1788580694858,\"s\":\"BTCUSDT\",\"ps\":\"BTCUSDT\",\"U\":11479472380298,\"u\":11479472386229,\"pu\":11479472380286,\"b\":[[\"1000.00\",\"25.354\"],[\"29143.90\",\"0.084\"],[\"29243.90\",\"1.827\"],[\"29343.90\",\"0.189\"],[\"63635.00\",\"0.003\"],[\"71589.50\",\"0.006\"],[\"76362.10\",\"0.000\"],[\"78390.50\",\"1.911\"],[\"78592.10\",\"0.103\"],[\"78597.70\",\"0.000\"],[\"78615.60\",\"0.003\"],[\"78617.40\",\"0.000\"],[\"78625.60\",\"0.444\"],[\"78748.50\",\"1.902\"],[\"79454.40\",\"0.002\"],[\"79460.70\",\"0.126\"],[\"79460.80\",\"0.000\"],[\"79480.90\",\"0.001\"],[\"79482.30\",\"0.015\"],[\"79520.20\",\"2.395\"],[\"79539.60\",\"1.491\"]],\"a\":[[\"79546.60\",\"0.007\"],[\"79550.60\",\"0.000\"],[\"79553.40\",\"0.298\"],[\"79560.10\",\"0.004\"],[\"79561.70\",\"0.080\"],[\"79563.90\",\"0.002\"],[\"79564.90\",\"0.814\"],[\"79936.40\",\"0.626\"],[\"79939.70\",\"0.000\"],[\"80339.40\",\"1.429\"],[\"80657.60\",\"13.441\"]],\"st\":1}}"}
{"receive_ns":1788580694886107000,"stream":"btcusdt@bookTicker","event_type":"bookTicker","event_time_ms":1788580694933,"raw_json":"{\"stream\":\"btcusdt@bookTicker\",\"data\":{\"e\":\"bookTicker\",\"u\":11479472391050,\"s\":\"BTCUSDT\",\"ps\":\"BTCUSDT\",\"b\":\"79543.90\",\"B\":\"5.175\",\"a\":\"79544.00\",\"A\":\"7.907\",\"T\":1788580694933,\"E\":1788580694933,\"st\":1}}"}
{"receive_ns":1788580694886498000,"stream":"btcusdt@trade","event_type":"trade","event_time_ms":1788580694933,"raw_json":"{\"stream\":\"btcusdt@trade\",\"data\":{\"e\":\"trade\",\"E\":1788580694933,\"T\":1788580694933,\"s\":\"BTCUSDT\",\"t\":8054266631,\"p\":\"79543.90\",\"q\":\"0.002\",\"X\":\"MARKET\",\"m\":true,\"st\":1}}"}
{"receive_ns":1788580694906366000,"stream":"btcusdt@depth@100ms","event_type":"depthUpdate","event_time_ms":1788580694963,"raw_json":"{\"stream\":\"btcusdt@depth@100ms\",\"data\":{\"e\":\"depthUpdate\",\"E\":1788580694963,\"T\":1788580694961,\"s\":\"BTCUSDT\",\"ps\":\"BTCUSDT\",\"U\":11479472386464,\"u\":11479472392886,\"pu\":11479472386229,\"b\":[[\"29143.90\",\"0.140\"],[\"29243.90\",\"1.897\"],[\"29343.90\",\"0.063\"],[\"63635.00\",\"0.000\"],[\"63635.10\",\"0.000\"],[\"71589.50\",\"0.006\"],[\"76362.10\",\"0.002\"],[\"77953.10\",\"0.009\"],[\"78748.50\",\"1.902\"],[\"78827.70\",\"0.887\"],[\"79146.20\",\"2.909\"],[\"79454.40\",\"0.034\"],[\"79460.30\",\"0.018\"],[\"79460.70\",\"0.001\"],[\"79472.30\",\"0.380\"],[\"79480.90\",\"0.021\"],[\"79482.30\",\"0.213\"],[\"79490.80\",\"0.057\"],[\"79539.60\",\"1.491\"],[\"79539.90\",\"0.109\"],[\"79543.90\",\"5.175\"]],\"a\":[[\"79586.50\",\"0.000\"],[\"79595.50\",\"0.086\"],[\"79595.60\",\"0.550\"],[\"79639.50\",\"0.002\"],[\"79936.40\",\"0.508\"],[\"79939.70\",\"0.191\"],[\"80339.40\",\"1.429\"],[\"80760.40\",\"0.000\"]],\"st\":1}}"}
{"receive_ns":1788580695005322000,"stream":"btcusdt@bookTicker","event_type":"bookTicker","event_time_ms":1788580695058,"raw_json":"{\"stream\":\"btcusdt@bookTicker\",\"data\":{\"e\":\"bookTicker\",\"u\":11479472399276,\"s\":\"BTCUSDT\",\"ps\":\"BTCUSDT\",\"b\":\"79543.90\",\"B\":\"5.174\",\"a\":\"79544.00\",\"A\":\"7.907\",\"T\":1788580695057,\"E\":1788580695058,\"st\":1}}"}
{"receive_ns":1788580695005567000,"stream":"btcusdt@bookTicker","event_type":"bookTicker","event_time_ms":1788580695059,"raw_json":"{\"stream\":\"btcusdt@bookTicker\",\"data\":{\"e\":\"bookTicker\",\"u\":11479472399413,\"s\":\"BTCUSDT\",\"ps\":\"BTCUSDT\",\"b\":\"79543.90\",\"B\":\"5.175\",\"a\":\"79544.00\",\"A\":\"7.907\",\"T\":1788580695059,\"E\":1788580695059,\"st\":1}}"}
{"receive_ns":1788580695008430000,"stream":"btcusdt@depth@100ms","event_type":"depthUpdate","event_time_ms":1788580695065,"raw_json":"{\"stream\":\"btcusdt@depth@100ms\",\"data\":{\"e\":\"depthUpdate\",\"E\":1788580695065,\"T\":1788580695062,\"s\":\"BTCUSDT\",\"ps\":\"BTCUSDT\",\"U\":11479472392927,\"u\":11479472399600,\"pu\":11479472392886,\"b\":[[\"1000.00\",\"25.354\"],[\"29143.90\",\"0.252\"],[\"29243.90\",\"1.848\"],[\"29343.90\",\"0.000\"],[\"63635.00\",\"0.000\"],[\"71589.50\",\"0.006\"],[\"76362.10\",\"0.000\"],[\"78613.20\",\"0.444\"],[\"78748.50\",\"1.902\"],[\"79460.80\",\"0.000\"],[\"79480.50\",\"0.014\"],[\"79492.40\",\"0.000\"],[\"79523.80\",\"0.000\"],[\"79524.70\",\"0.001\"],[\"79525.00\",\"0.375\"],[\"79525.70\",\"0.049\"],[\"79527.80\",\"0.145\"],[\"79528.40\",\"0.617\"],[\"79529.60\",\"0.002\"],[\"79534.00\",\"0.006\"],[\"79536.50\",\"0.253\"],[\"79539.60\",\"1.491\"],[\"79543.90\",\"5.175\"]],\"a\":[[\"80135.20\",\"1.869\"],[\"80299.70\",\"1.182\"],[\"80339.40\",\"1.429\"],[\"80888.30\",\"0.494\"],[\"80909.10\",\"3.863\"],[\"81131.80\",\"0.616\"]],\"st\":1}}"}
{"receive_ns":1788580695125500000,"stream":"btcusdt@depth@100ms","event_type":"depthUpdate","event_time_ms":1788580695167,"raw_json":"{\"stream\":\"btcusdt@depth@100ms\",\"data\":{\"e\":\"depthUpdate\",\"E\":1788580695167,\"T\":1788580695165,\"s\":\"BTCUSDT\",\"ps\":\"BTCUSDT\",\"U\":11479472399808,\"u\":11479472405408,\"pu\":11479472399600,\"b\":[[\"1000.00\",\"25.354\"],[\"29143.90\",\"0.434\"],[\"29243.90\",\"1.666\"],[\"63635.00\",\"0.000\"],[\"71589.50\",\"0.006\"],[\"78509.20\",\"0.907\"],[\"78549.60\",\"3.489\"],[\"78681.40\",\"10.089\"],[\"78748.50\",\"1.902\"],[\"78840.40\",\"12.223\"],[\"79454.40\",\"0.027\"],[\"79454.80\",\"0.020\"],[\"79461.00\",\"0.135\"],[\"79480.50\",\"0.000\"],[\"79480.90\",\"0.021\"],[\"79482.30\",\"0.220\"],[\"79489.90\",\"0.076\"],[\"79539.90\",\"0.109\"]],\"a\":[[\"79605.20\",\"3.403\"],[\"79605.30\",\"0.040\"],[\"79625.10\",\"0.004\"],[\"79635.80\",\"0.005\"],[\"79639.60\",\"0.005\"],[\"79640.50\",\"0.003\"],[\"79753.50\",\"1.326\"],[\"79936.40\",\"0.508\"],[\"79939.70\",\"0.191\"],[\"79941.70\",\"1.248\"],[\"80339.40\",\"1.429\"],[\"80888.30\",\"0.987\"],[\"80900.00\",\"2.634\"]],\"st\":1}}"}
{"receive_ns":1788580695147480000,"stream":"btcusdt@bookTicker","event_type":"bookTicker","event_time_ms":1788580695199,"raw_json":"{\"stream\":\"btcusdt@bookTicker\",\"data\":{\"e\":\"bookTicker\",\"u\":11479472407351,\"s\":\"BTCUSDT\",\"ps\":\"BTCUSDT\",\"b\":\"79543.90\",\"B\":\"5.175\",\"a\":\"79544.00\",\"A\":\"7.884\",\"T\":1788580695199,\"E\":1788580695199,\"st\":1}}"}
{"receive_ns":1788580695147844000,"stream":"btcusdt@bookTicker","event_type":"bookTicker","event_time_ms":1788580695202,"raw_json":"{\"stream\":\"btcusdt@bookTicker\",\"data\":{\"e\":\"bookTicker\",\"u\":11479472407594,\"s\":\"BTCUSDT\",\"ps\":\"BTCUSDT\",\"b\":\"79543.90\",\"B\":\"5.175\",\"a\":\"79544.00\",\"A\":\"7.908\",\"T\":1788580695201,\"E\":1788580695202,\"st\":1}}"}
{"receive_ns":1788580695212804000,"stream":"btcusdt@depth@100ms","event_type":"depthUpdate","event_time_ms":1788580695269,"raw_json":"{\"stream\":\"btcusdt@depth@100ms\",\"data\":{\"e\":\"depthUpdate\",\"E\":1788580695269,\"T\":1788580695267,\"s\":\"BTCUSDT\",\"ps\":\"BTCUSDT\",\"U\":11479472405584,\"u\":11479472412404,\"pu\":11479472405408,\"b\":[[\"29143.90\",\"0.609\"],[\"29243.90\",\"1.491\"],[\"71589.50\",\"0.006\"],[\"76362.10\",\"0.002\"],[\"78628.30\",\"5.285\"],[\"78662.90\",\"0.190\"],[\"78748.50\",\"1.902\"],[\"79146.20\",\"2.909\"],[\"79418.90\",\"0.475\"],[\"79454.80\",\"0.027\"],[\"79461.00\",\"0.010\"],[\"79523.80\",\"0.373\"],[\"79524.70\",\"0.047\"],[\"79525.00\",\"0.002\"],[\"79525.70\",\"0.003\"],[\"79527.80\",\"0.585\"],[\"79528.40\",\"0.177\"],[\"79537.90\",\"0.120\"],[\"79539.30\",\"0.004\"],[\"79539.60\",\"1.371\"],[\"79539.70\",\"0.062\"]],\"a\":[[\"79544.00\",\"7.908\"],[\"79563.80\",\"0.373\"],[\"79563.90\",\"0.441\"],[\"79564.90\",\"0.002\"],[\"79588.40\",\"2.044\"],[\"79589.50\",\"0.383\"],[\"79635.80\",\"0.006\"],[\"79666.40\",\"0.436\"],[\"79911.60\",\"0.000\"],[\"80339.40\",\"1.429\"],[\"80493.20\",\"19.604\"],[\"80498.50\",\"14.760\"]],\"st\":1}}"}
{"receive_ns":1788580695307740000,"stream":"btcusdt@bookTicker","event_type":"bookTicker","event_time_ms":1788580695340,"raw_json":"{\"stream\":\"btcusdt@bookTicker\",\"data\":{\"e\":\"bookTicker\",\"u\":11479472416678,\"s\":\"BTCUSDT\",\"ps\":\"BTCUSDT\",\"b\":\"79543.90\",\"B\":\"5.102\",\"a\":\"79544.00\",\"A\":\"7.908\",\"T\":1788580695340,\"E\":1788580695340,\"st\":1}}"}
{"receive_ns":1788580695307959000,"stream":"btcusdt@bookTicker","event_type":"bookTicker","event_time_ms":1788580695343,"raw_json":"{\"stream\":\"btcusdt@bookTicker\",\"data\":{\"e\":\"bookTicker\",\"u\":11479472416886,\"s\":\"BTCUSDT\",\"ps\":\"BTCUSDT\",\"b\":\"79543.90\",\"B\":\"5.176\",\"a\":\"79544.00\",\"A\":\"7.908\",\"T\":1788580695343,\"E\":1788580695343,\"st\":1}}"}
{"receive_ns":1788580695308131000,"stream":"btcusdt@bookTicker","event_type":"bookTicker","event_time_ms":1788580695360,"raw_json":"{\"stream\":\"btcusdt@bookTicker\",\"data\":{\"e\":\"bookTicker\",\"u\":11479472417933,\"s\":\"BTCUSDT\",\"ps\":\"BTCUSDT\",\"b\":\"79543.90\",\"B\":\"5.176\",\"a\":\"79544.00\",\"A\":\"7.907\",\"T\":1788580695360,\"E\":1788580695360,\"st\":1}}"}
{"receive_ns":1788580695308344000,"stream":"btcusdt@bookTicker","event_type":"bookTicker","event_time_ms":1788580695364,"raw_json":"{\"stream\":\"btcusdt@bookTicker\",\"data\":{\"e\":\"bookTicker\",\"u\":11479472418299,\"s\":\"BTCUSDT\",\"ps\":\"BTCUSDT\",\"b\":\"79543.90\",\"B\":\"5.176\",\"a\":\"79544.00\",\"A\":\"7.910\",\"T\":1788580695364,\"E\":1788580695364,\"st\":1}}"}
{"receive_ns":1788580695314828000,"stream":"btcusdt@depth@100ms","event_type":"depthUpdate","event_time_ms":1788580695371,"raw_json":"{\"stream\":\"btcusdt@depth@100ms\",\"data\":{\"e\":\"depthUpdate\",\"E\":1788580695371,\"T\":1788580695366,\"s\":\"BTCUSDT\",\"ps\":\"BTCUSDT\",\"U\":11479472412589,\"u\":11479472418553,\"pu\":11479472412404,\"b\":[[\"1000.00\",\"25.354\"],[\"29143.90\",\"0.784\"],[\"29243.90\",\"1.316\"],[\"71589.50\",\"0.006\"],[\"71623.00\",\"0.000\"],[\"75566.70\",\"0.011\"],[\"76362.10\",\"0.000\"],[\"77953.10\",\"0.003\"],[\"78748.50\",\"1.902\"],[\"79454.40\",\"0.002\"],[\"79461.00\",\"0.135\"],[\"79480.90\",\"0.001\"],[\"79482.30\",\"0.015\"],[\"79523.80\",\"0.000\"],[\"79524.10\",\"0.655\"],[\"79524.70\",\"0.001\"],[\"79524.90\",\"0.111\"],[\"79525.10\",\"0.037\"],[\"79525.20\",\"0.000\"],[\"79525.80\",\"0.492\"],[\"79526.00\",\"0.082\"],[\"79527.80\",\"0.585\"],[\"79528.40\",\"0.177\"],[\"79528.50\",\"0.000\"],[\"79539.30\",\"0.000\"],[\"79539.70\",\"0.066\"],[\"79539.90\",\"0.021\"],[\"79543.90\",\"5.176\"]],\"a\":[[\"79544.00\",\"7.910\"],[\"79563.80\",\"0.000\"],[\"79563.90\",\"0.441\"],[\"79564.00\",\"1.191\"],[\"79564.90\",\"0.002\"],[\"79565.10\",\"0.374\"],[\"79588.40\",\"1.998\"],[\"79588.60\",\"0.657\"],[\"79589.60\",\"0.145\"],[\"79589.70\",\"0.138\"],[\"79605.20\",\"3.405\"],[\"79936.40\",\"0.501\"],[\"79939.70\",\"0.000\"],[\"80339.40\",\"1.429\"],[\"80687.60\",\"0.325\"]],\"st\":1}}"}
{"receive_ns":1788580695435219000,"stream":"btcusdt@depth@100ms","event_type":"depthUpdate","event_time_ms":1788580695473,"raw_json":"{\"stream\":\"btcusdt@depth@100ms\",\"data\":{\"e\":\"depthUpdate\",\"E\":1788580695473,\"T\":1788580695471,\"s\":\"BTCUSDT\",\"ps\":\"BTCUSDT\",\"U\":11479472418900,\"u\":11479472425144,\"pu\":11479472418553,\"b\":[[\"1000.00\",\"25.354\"],[\"29143.90\",\"0.966\"],[\"29243.90\",\"1.134\"],[\"71589.50\",\"0.006\"],[\"76362.10\",\"0.002\"],[\"78311.00\",\"2.917\"],[\"78509.80\",\"2.242\"],[\"78628.30\",\"6.046\"],[\"78748.50\",\"3.170\"],[\"78992.60\",\"0.098\"],[\"79454.40\",\"0.044\"],[\"79460.80\",\"0.125\"],[\"79461.00\",\"0.010\"],[\"79480.90\",\"0.021\"],[\"79482.30\",\"0.291\"],[\"79517.30\",\"0.002\"],[\"79517.60\",\"0.452\"],[\"79518.80\",\"0.002\"],[\"79527.80\",\"0.585\"],[\"79528.40\",\"0.177\"],[\"79529.10\",\"0.229\"],[\"79539.60\",\"1.371\"]],\"a\":[[\"79563.90\",\"0.002\"],[\"79565.10\",\"0.813\"],[\"79936.40\",\"0.508\"],[\"79939.70\",\"0.191\"],[\"80339.40\",\"1.429\"],[\"80431.80\",\"0.001\"]],\"st\":1}}"}
{"receive_ns":1788580695449663000,"stream":"btcusdt@bookTicker","event_type":"bookTicker","event_time_ms":1788580695505,"raw_json":"{\"stream\":\"btcusdt@bookTicker\",\"data\":{\"e\":\"bookTicker\",\"u\":11479472427619,\"s\":\"BTCUSDT\",\"ps\":\"BTCUSDT\",\"b\":\"79543.90\",\"B\":\"5.170\",\"a\":\"79544.00\",\"A\":\"7.910\",\"T\":1788580695505,\"E\":1788580695505,\"st\":1}}"}
{"receive_ns":1788580695453017000,"stream":"btcusdt@bookTicker","event_type":"bookTicker","event_time_ms":1788580695508,"raw_json":"{\"stream\":\"btcusdt@bookTicker\",\"data\":{\"e\":\"bookTicker\",\"u\":11479472427778,\"s\":\"BTCUSDT\",\"ps\":\"BTCUSDT\",\"b\":\"79543.90\",\"B\":\"5.175\",\"a\":\"79544.00\",\"A\":\"7.910\",\"T\":1788580695508,\"E\":1788580695508,\"st\":1}}"}
{"receive_ns":1788580695453867000,"stream":"btcusdt@bookTicker","event_type":"bookTicker","event_time_ms":1788580695511,"raw_json":"{\"stream\":\"btcusdt@bookTicker\",\"data\":{\"e\":\"bookTicker\",\"u\":11479472428000,\"s\":\"BTCUSDT\",\"ps\":\"BTCUSDT\",\"b\":\"79543.90\",\"B\":\"5.066\",\"a\":\"79544.00\",\"A\":\"7.910\",\"T\":1788580695510,\"E\":1788580695511,\"st\":1}}"}
{"receive_ns":1788580695487057000,"stream":"btcusdt@bookTicker","event_type":"bookTicker","event_time_ms":1788580695514,"raw_json":"{\"stream\":\"btcusdt@bookTicker\",\"data\":{\"e\":\"bookTicker\",\"u\":11479472428352,\"s\":\"BTCUSDT\",\"ps\":\"BTCUSDT\",\"b\":\"79543.90\",\"B\":\"5.182\",\"a\":\"79544.00\",\"A\":\"7.910\",\"T\":1788580695514,\"E\":1788580695514,\"st\":1}}"}
{"receive_ns":1788580695501445000,"stream":"btcusdt@bookTicker","event_type":"bookTicker","event_time_ms":1788580695557,"raw_json":"{\"stream\":\"btcusdt@bookTicker\",\"data\":{\"e\":\"bookTicker\",\"u\":11479472431553,\"s\":\"BTCUSDT\",\"ps\":\"BTCUSDT\",\"b\":\"79543.90\",\"B\":\"5.182\",\"a\":\"79544.00\",\"A\":\"7.972\",\"T\":1788580695557,\"E\":1788580695557,\"st\":1}}"}
{"receive_ns":1788580695501664000,"stream":"btcusdt@bookTicker","event_type":"bookTicker","event_time_ms":1788580695558,"raw_json":"{\"stream\":\"btcusdt@bookTicker\",\"data\":{\"e\":\"bookTicker\",\"u\":11479472431679,\"s\":\"BTCUSDT\",\"ps\":\"BTCUSDT\",\"b\":\"79543.90\",\"B\":\"5.189\",\"a\":\"79544.00\",\"A\":\"7.972\",\"T\":1788580695558,\"E\":1788580695558,\"st\":1}}"}
{"receive_ns":1788580695553934000,"stream":"btcusdt@depth@100ms","event_type":"depthUpdate","event_time_ms":1788580695575,"raw_json":"{\"stream\":\"btcusdt@depth@100ms\",\"data\":{\"e\":\"depthUpdate\",\"E\":1788580695575,\"T\":1788580695574,\"s\":\"BTCUSDT\",\"ps\":\"BTCUSDT\",\"U\":11479472425265,\"u\":11479472432665,\"pu\":11479472425144,\"b\":[[\"29143.90\",\"1.148\"],[\"29243.90\",\"0.952\"],[\"71589.50\",\"0.006\"],[\"75566.70\",\"0.009\"],[\"75566.80\",\"0.008\"],[\"78748.50\",\"3.170\"],[\"78993.40\",\"0.000\"],[\"79146.20\",\"2.899\"],[\"79460.80\",\"0.000\"],[\"79482.30\",\"0.115\"],[\"79531.50\",\"0.003\"],[\"79531.60\",\"0.003\"],[\"79539.60\",\"1.372\"],[\"79543.90\",\"5.189\"]],\"a\":[[\"79544.00\",\"7.972\"],[\"79555.90\",\"0.229\"],[\"79556.00\",\"0.425\"],[\"79639.60\",\"0.006\"],[\"80339.40\",\"1.429\"]],\"st\":1}}"}
{"receive_ns":1788580695554955000,"stream":"btcusdt@bookTicker","event_type":"bookTicker","event_time_ms":1788580695612,"raw_json":"{\"stream\":\"btcusdt@bookTicker\",\"data\":{\"e\":\"bookTicker\",\"u\":11479472435746,\"s\":\"BTCUSDT\",\"ps\":\"BTCUSDT\",\"b\":\"79543.90\",\"B\":\"5.188\",\"a\":\"79544.00\",\"A\":\"7.972\",\"T\":1788580695612,\"E\":1788580695612,\"st\":1}}"}
{"receive_ns":1788580695558168000,"stream":"btcusdt@bookTicker","event_type":"bookTicker","event_time_ms":1788580695614,"raw_json":"{\"stream\":\"btcusdt@bookTicker\",\"data\":{\"e\":\"bookTicker\",\"u\":11479472435975,\"s\":\"BTCUSDT\",\"ps\":\"BTCUSDT\",\"b\":\"79543.90\",\"B\":\"5.189\",\"a\":\"79544.00\",\"A\":\"7.972\",\"T\":1788580695614,\"E\":1788580695614,\"st\":1}}"}
{"receive_ns":1788580695624822000,"stream":"btcusdt@depth@100ms","event_type":"depthUpdate","event_time_ms":1788580695677,"raw_json":"{\"stream\":\"btcusdt@depth@100ms\",\"data\":{\"e\":\"depthUpdate\",\"E\":1788580695677,\"T\":1788580695676,\"s\":\"BTCUSDT\",\"ps\":\"BTCUSDT\",\"U\":11479472432701,\"u\":11479472439687,\"pu\":11479472432665,\"b\":[[\"1000.00\",\"25.354\"],[\"29143.90\",\"1.323\"],[\"29243.90\",\"0.777\"],[\"71589.50\",\"0.006\"],[\"76362.10\",\"0.000\"],[\"78475.60\",\"0.001\"],[\"78509.40\",\"3.114\"],[\"78549.60\",\"3.921\"],[\"78748.50\",\"3.170\"],[\"78827.90\",\"1.267\"],[\"79448.40\",\"0.006\"],[\"79454.40\",\"0.027\"],[\"79455.70\",\"0.126\"],[\"79480.90\",\"0.021\"],[\"79482.30\",\"0.082\"],[\"79496.10\",\"0.391\"],[\"79539.60\",\"1.371\"],[\"79539.70\",\"0.062\"],[\"79539.90\",\"0.247\"],[\"79540.00\",\"0.007\"],[\"79543.90\",\"5.189\"]],\"a\":[[\"79576.40\",\"0.654\"],[\"79578.10\",\"0.000\"],[\"79591.80\",\"0.260\"],[\"79679.30\",\"0.003\"],[\"79936.40\",\"0.508\"],[\"79939.70\",\"0.191\"],[\"80339.40\",\"1.429\"],[\"80551.10\",\"7.400\"],[\"87498.40\",\"0.001\"]],\"st\":1}}"}
{"receive_ns":1788580695740545000,"stream":"btcusdt@depth@100ms","event_type":"depthUpdate","event_time_ms":1788580695779,"raw_json":"{\"stream\":\"btcusdt@depth@100ms\",\"data\":{\"e\":\"depthUpdate\",\"E\":1788580695779,\"T\":1788580695778,\"s\":\"BTCUSDT\",\"ps\":\"BTCUSDT\",\"U\":11479472439759,\"u\":11479472446891,\"pu\":11479472439687,\"b\":[[\"1000.00\",\"25.354\"],[\"29143.90\",\"1.505\"],[\"29243.90\",\"0.595\"],[\"71589.50\",\"0.006\"],[\"76362.10\",\"0.002\"],[\"78590.40\",\"0.004\"],[\"78592.10\",\"0.100\"],[\"78602.20\",\"0.031\"],[\"78611.40\",\"0.004\"],[\"78748.50\",\"3.170\"],[\"79146.10\",\"0.008\"],[\"79424.60\",\"0.023\"],[\"79448.40\",\"0.004\"],[\"79472.30\",\"0.378\"],[\"79488.20\",\"0.128\"],[\"79504.10\",\"0.004\"],[\"79539.60\",\"1.371\"]],\"a\":[[\"79599.70\",\"0.052\"],[\"79615.60\",\"0.004\"],[\"79627.40\",\"0.011\"],[\"79639.50\",\"0.000\"],[\"79679.30\",\"0.001\"],[\"79941.80\",\"0.000\"],[\"80339.40\",\"1.429\"],[\"80538.30\",\"2.281\"],[\"80665.60\",\"1.361\"]],\"st\":1}}"}
{"receive_ns":1788580695824802000,"stream":"btcusdt@depth@100ms","event_type":"depthUpdate","event_time_ms":1788580695881,"raw_json":"{\"stream\":\"btcusdt@depth@100ms\",\"data\":{\"e\":\"depthUpdate\",\"E\":1788580695881,\"T\":1788580695877,\"s\":\"BTCUSDT\",\"ps\":\"BTCUSDT\",\"U\":11479472446992,\"u\":11479472456177,\"pu\":11479472446891,\"b\":[[\"29143.90\",\"1.680\"],[\"29243.90\",\"0.420\"],[\"71589.50\",\"0.006\"],[\"75561.60\",\"0.038\"],[\"76362.10\",\"0.000\"],[\"78748.50\",\"3.170\"],[\"79146.10\",\"0.009\"],[\"79146.20\",\"2.909\"],[\"79416.60\",\"0.172\"],[\"79452.40\",\"2.813\"],[\"79454.40\",\"0.002\"],[\"79480.90\",\"0.001\"],[\"79482.30\",\"0.065\"],[\"79520.20\",\"2.393\"],[\"79539.70\",\"0.066\"],[\"79539.90\",\"0.021\"],[\"79540.00\",\"0.003\"]],\"a\":[[\"79560.10\",\"0.002\"],[\"79635.90\",\"4.529\"],[\"79636.30\",\"0.002\"],[\"79636.40\",\"0.001\"],[\"79665.00\",\"0.202\"],[\"79936.40\",\"0.501\"],[\"79939.70\",\"0.032\"],[\"79941.80\",\"0.001\"],[\"80339.40\",\"1.429\"],[\"80657.60\",\"13.812\"]],\"st\":1}}"}
{"receive_ns":1788580695860966000,"stream":"btcusdt@bookTicker","event_type":"bookTicker","event_time_ms":1788580695894,"raw_json":"{\"stream\":\"btcusdt@bookTicker\",\"data\":{\"e\":\"bookTicker\",\"u\":11479472457437,\"s\":\"BTCUSDT\",\"ps\":\"BTCUSDT\",\"b\":\"79543.90\",\"B\":\"5.189\",\"a\":\"79544.00\",\"A\":\"7.971\",\"T\":1788580695894,\"E\":1788580695894,\"st\":1}}"}
{"receive_ns":1788580695861185000,"stream":"btcusdt@trade","event_type":"trade","event_time_ms":1788580695894,"raw_json":"{\"stream\":\"btcusdt@trade\",\"data\":{\"e\":\"trade\",\"E\":1788580695894,\"T\":1788580695894,\"s\":\"BTCUSDT\",\"t\":8054266632,\"p\":\"79544.00\",\"q\":\"0.001\",\"X\":\"MARKET\",\"m\":false,\"st\":1}}"}
{"receive_ns":1788580695924217000,"stream":"btcusdt@bookTicker","event_type":"bookTicker","event_time_ms":1788580695971,"raw_json":"{\"stream\":\"btcusdt@bookTicker\",\"data\":{\"e\":\"bookTicker\",\"u\":11479472464597,\"s\":\"BTCUSDT\",\"ps\":\"BTCUSDT\",\"b\":\"79543.90\",\"B\":\"5.189\",\"a\":\"79544.00\",\"A\":\"7.746\",\"T\":1788580695971,\"E\":1788580695971,\"st\":1}}"}
{"receive_ns":1788580695924458000,"stream":"btcusdt@trade","event_type":"trade","event_time_ms":1788580695971,"raw_json":"{\"stream\":\"btcusdt@trade\",\"data\":{\"e\":\"trade\",\"E\":1788580695971,\"T\":1788580695971,\"s\":\"BTCUSDT\",\"t\":8054266633,\"p\":\"79544.00\",\"q\":\"0.225\",\"X\":\"MARKET\",\"m\":false,\"st\":1}}"}
{"receive_ns":1788580695926296000,"stream":"btcusdt@depth@100ms","event_type":"depthUpdate","event_time_ms":1788580695983,"raw_json":"{\"stream\":\"btcusdt@depth@100ms\",\"data\":{\"e\":\"depthUpdate\",\"E\":1788580695983,\"T\":1788580695981,\"s\":\"BTCUSDT\",\"ps\":\"BTCUSDT\",\"U\":11479472456434,\"u\":11479472465438,\"pu\":11479472456177,\"b\":[[\"1000.00\",\"25.354\"],[\"29043.90\",\"0.035\"],[\"29143.90\",\"1.785\"],[\"29243.90\",\"0.280\"],[\"63635.10\",\"0.000\"],[\"71589.50\",\"0.006\"],[\"76362.10\",\"0.002\"],[\"78430.30\",\"12.990\"],[\"78748.50\",\"3.170\"],[\"78902.30\",\"3.288\"],[\"79140.90\",\"1.576\"],[\"79480.20\",\"2.167\"],[\"79480.90\",\"0.021\"],[\"79482.30\",\"0.107\"],[\"79520.20\",\"2.395\"],[\"79526.60\",\"0.031\"],[\"79526.80\",\"1.893\"],[\"79527.50\",\"0.005\"],[\"79528.80\",\"0.129\"],[\"79539.70\",\"0.062\"],[\"79539.90\",\"0.109\"],[\"79540.00\",\"0.007\"],[\"79540.60\",\"0.253\"]],\"a\":[[\"79544.00\",\"7.746\"],[\"79558.20\",\"0.103\"],[\"79559.40\",\"0.000\"],[\"79560.10\",\"0.004\"],[\"79560.60\",\"0.202\"],[\"79936.40\",\"0.508\"],[\"79939.70\",\"0.191\"],[\"80339.40\",\"1.429\"]],\"st\":1}}"}
{"receive_ns":1788580696042052000,"stream":"btcusdt@bookTicker","event_type":"bookTicker","event_time_ms":1788580696073,"raw_json":"{\"stream\":\"btcusdt@bookTicker\",\"data\":{\"e\":\"bookTicker\",\"u\":11479472474073,\"s\":\"BTCUSDT\",\"ps\":\"BTCUSDT\",\"b\":\"79543.90\",\"B\":\"5.189\",\"a\":\"79544.00\",\"A\":\"7.500\",\"T\":1788580696073,\"E\":1788580696073,\"st\":1}}"}
{"receive_ns":1788580696042399000,"stream":"btcusdt@bookTicker","event_type":"bookTicker","event_time_ms":1788580696073,"raw_json":"{\"stream\":\"btcusdt@bookTicker\",\"data\":{\"e\":\"bookTicker\",\"u\":11479472474248,\"s\":\"BTCUSDT\",\"ps\":\"BTCUSDT\",\"b\":\"79543.90\",\"B\":\"5.229\",\"a\":\"79544.00\",\"A\":\"7.500\",\"T\":1788580696073,\"E\":1788580696073,\"st\":1}}"}
{"receive_ns":1788580696042685000,"stream":"btcusdt@bookTicker","event_type":"bookTicker","event_time_ms":1788580696074,"raw_json":"{\"stream\":\"btcusdt@bookTicker\",\"data\":{\"e\":\"bookTicker\",\"u\":11479472474685,\"s\":\"BTCUSDT\",\"ps\":\"BTCUSDT\",\"b\":\"79543.90\",\"B\":\"5.229\",\"a\":\"79544.00\",\"A\":\"6.950\",\"T\":1788580696074,\"E\":1788580696074,\"st\":1}}"}
{"receive_ns":1788580696043111000,"stream":"btcusdt@bookTicker","event_type":"bookTicker","event_time_ms":1788580696074,"raw_json":"{\"stream\":\"btcusdt@bookTicker\",\"data\":{\"e\":\"bookTicker\",\"u\":11479472474799,\"s\":\"BTCUSDT\",\"ps\":\"BTCUSDT\",\"b\":\"79543.90\",\"B\":\"6.455\",\"a\":\"79544.00\",\"A\":\"6.950\",\"T\":1788580696074,\"E\":1788580696074,\"st\":1}}"}
{"receive_ns":1788580696043419000,"stream":"btcusdt@bookTicker","event_type":"bookTicker","event_time_ms":1788580696074,"raw_json":"{\"stream\":\"btcusdt@bookTicker\",\"data\":{\"e\":\"bookTicker\",\"u\":11479472474896,\"s\":\"BTCUSDT\",\"ps\":\"BTCUSDT\",\"b\":\"79543.90\",\"B\":\"6.455\",\"a\":\"79544.00\",\"A\":\"6.823\",\"T\":1788580696074,\"E\":1788580696074,\"st\":1}}"}
{"receive_ns":1788580696043711000,"stream":"btcusdt@bookTicker","event_type":"bookTicker","event_time_ms":1788580696074,"raw_json":"{\"stream\":\"btcusdt@bookTicker\",\"data\":{\"e\":\"bookTicker\",\"u\":11479472474924,\"s\":\"BTCUSDT\",\"ps\":\"BTCUSDT\",\"b\":\"79543.90\",\"B\":\"6.455\",\"a\":\"79544.00\",\"A\":\"6.557\",\"T\":1788580696074,\"E\":1788580696074,\"st\":1}}"}
{"receive_ns":1788580696044192000,"stream":"btcusdt@bookTicker","event_type":"bookTicker","event_time_ms":1788580696075,"raw_json":"{\"stream\":\"btcusdt@bookTicker\",\"data\":{\"e\":\"bookTicker\",\"u\":11479472475182,\"s\":\"BTCUSDT\",\"ps\":\"BTCUSDT\",\"b\":\"79543.90\",\"B\":\"6.454\",\"a\":\"79544.00\",\"A\":\"6.557\",\"T\":1788580696075,\"E\":1788580696075,\"st\":1}}"}
{"receive_ns":1788580696044416000,"stream":"btcusdt@bookTicker","event_type":"bookTicker","event_time_ms":1788580696075,"raw_json":"{\"stream\":\"btcusdt@bookTicker\",\"data\":{\"e\":\"bookTicker\",\"u\":11479472475338,\"s\":\"BTCUSDT\",\"ps\":\"BTCUSDT\",\"b\":\"79543.90\",\"B\":\"6.455\",\"a\":\"79544.00\",\"A\":\"6.557\",\"T\":1788580696075,\"E\":1788580696075,\"st\":1}}"}
{"receive_ns":1788580696044658000,"stream":"btcusdt@bookTicker","event_type":"bookTicker","event_time_ms":1788580696076,"raw_json":"{\"stream\":\"btcusdt@bookTicker\",\"data\":{\"e\":\"bookTicker\",\"u\":11479472476151,\"s\":\"BTCUSDT\",\"ps\":\"BTCUSDT\",\"b\":\"79543.90\",\"B\":\"6.456\",\"a\":\"79544.00\",\"A\":\"6.557\",\"T\":1788580696076,\"E\":1788580696076,\"st\":1}}"}
{"receive_ns":1788580696044827000,"stream":"btcusdt@bookTicker","event_type":"bookTicker","event_time_ms":1788580696076,"raw_json":"{\"stream\":\"btcusdt@bookTicker\",\"data\":{\"e\":\"bookTicker\",\"u\":11479472476325,\"s\":\"BTCUSDT\",\"ps\":\"BTCUSDT\",\"b\":\"79543.90\",\"B\":\"6.456\",\"a\":\"79544.00\",\"A\":\"6.556\",\"T\":1788580696076,\"E\":1788580696076,\"st\":1}}"}
{"receive_ns":1788580696045036000,"stream":"btcusdt@bookTicker","event_type":"bookTicker","event_time_ms":1788580696076,"raw_json":"{\"stream\":\"btcusdt@bookTicker\",\"data\":{\"e\":\"bookTicker\",\"u\":11479472476381,\"s\":\"BTCUSDT\",\"ps\":\"BTCUSDT\",\"b\":\"79543.90\",\"B\":\"6.456\",\"a\":\"79544.00\",\"A\":\"6.484\",\"T\":1788580696076,\"E\":1788580696076,\"st\":1}}"}
{"receive_ns":1788580696045251000,"stream":"btcusdt@bookTicker","event_type":"bookTicker","event_time_ms":1788580696077,"raw_json":"{\"stream\":\"btcusdt@bookTicker\",\"data\":{\"e\":\"bookTicker\",\"u\":11479472476596,\"s\":\"BTCUSDT\",\"ps\":\"BTCUSDT\",\"b\":\"79543.90\",\"B\":\"6.456\",\"a\":\"79544.00\",\"A\":\"6.412\",\"T\":1788580696076,\"E\":1788580696077,\"st\":1}}"}
{"receive_ns":1788580696045441000,"stream":"btcusdt@bookTicker","event_type":"bookTicker","event_time_ms":1788580696077,"raw_json":"{\"stream\":\"btcusdt@bookTicker\",\"data\":{\"e\":\"bookTicker\",\"u\":11479472476685,\"s\":\"BTCUSDT\",\"ps\":\"BTCUSDT\",\"b\":\"79543.90\",\"B\":\"6.457\",\"a\":\"79544.00\",\"A\":\"6.412\",\"T\":1788580696076,\"E\":1788580696077,\"st\":1}}"}
{"receive_ns":1788580696045765000,"stream":"btcusdt@bookTicker","event_type":"bookTicker","event_time_ms":1788580696078,"raw_json":"{\"stream\":\"btcusdt@bookTicker\",\"data\":{\"e\":\"bookTicker\",\"u\":11479472478094,\"s\":\"BTCUSDT\",\"ps\":\"BTCUSDT\",\"b\":\"79543.90\",\"B\":\"6.661\",\"a\":\"79544.00\",\"A\":\"6.412\",\"T\":1788580696078,\"E\":1788580696078,\"st\":1}}"}
{"receive_ns":1788580696045982000,"stream":"btcusdt@bookTicker","event_type":"bookTicker","event_time_ms":1788580696080,"raw_json":"{\"stream\":\"btcusdt@bookTicker\",\"data\":{\"e\":\"bookTicker\",\"u\":11479472479630,\"s\":\"BTCUSDT\",\"ps\":\"BTCUSDT\",\"b\":\"79543.90\",\"B\":\"6.661\",\"a\":\"79544.00\",\"A\":\"5.920\",\"T\":1788580696080,\"E\":1788580696080,\"st\":1}}"}
{"receive_ns":1788580696046167000,"stream":"btcusdt@bookTicker","event_type":"bookTicker","event_time_ms":1788580696080,"raw_json":"{\"stream\":\"btcusdt@bookTicker\",\"data\":{\"e\":\"bookTicker\",\"u\":11479472479708,\"s\":\"BTCUSDT\",\"ps\":\"BTCUSDT\",\"b\":\"79543.90\",\"B\":\"6.662\",\"a\":\"79544.00\",\"A\":\"5.920\",\"T\":1788580696080,\"E\":1788580696080,\"st\":1}}"}
{"receive_ns":1788580696046366000,"stream":"btcusdt@bookTicker","event_type":"bookTicker","event_time_ms":1788580696081,"raw_json":"{\"stream\":\"btcusdt@bookTicker\",\"data\":{\"e\":\"bookTicker\",\"u\":11479472480243,\"s\":\"BTCUSDT\",\"ps\":\"BTCUSDT\",\"b\":\"79543.90\",\"B\":\"6.458\",\"a\":\"79544.00\",\"A\":\"5.920\",\"T\":1788580696081,\"E\":1788580696081,\"st\":1}}"}
{"receive_ns":1788580696046597000,"stream":"btcusdt@bookTicker","event_type":"bookTicker","event_time_ms":1788580696082,"raw_json":"{\"stream\":\"btcusdt@bookTicker\",\"data\":{\"e\":\"bookTicker\",\"u\":11479472481344,\"s\":\"BTCUSDT\",\"ps\":\"BTCUSDT\",\"b\":\"79543.90\",\"B\":\"6.458\",\"a\":\"79544.00\",\"A\":\"5.521\",\"T\":1788580696082,\"E\":1788580696082,\"st\":1}}"}
{"receive_ns":1788580696047921000,"stream":"btcusdt@depth@100ms","event_type":"depthUpdate","event_time_ms":1788580696085,"raw_json":"{\"stream\":\"btcusdt@depth@100ms\",\"data\":{\"e\":\"depthUpdate\",\"E\":1788580696085,\"T\":1788580696084,\"s\":\"BTCUSDT\",\"ps\":\"BTCUSDT\",\"U\":11479472465491,\"u\":11479472482975,\"pu\":11479472465438,\"b\":[[\"1000.00\",\"25.354\"],[\"29043.90\",\"0.098\"],[\"29143.90\",\"1.841\"],[\"29243.90\",\"0.161\"],[\"71589.50\",\"0.006\"],[\"75561.80\",\"0.002\"],[\"78748.50\",\"3.170\"],[\"78907.50\",\"4.174\"],[\"78942.10\",\"2.531\"],[\"79146.20\",\"3.035\"],[\"79176.00\",\"0.057\"],[\"79199.40\",\"0.006\"],[\"79280.60\",\"0.019\"],[\"79304.00\",\"2.415\"],[\"79329.70\",\"0.500\"],[\"79353.10\",\"0.025\"],[\"79479.90\",\"0.000\"],[\"79480.70\",\"3.503\"],[\"79480.90\",\"0.001\"],[\"79482.30\",\"0.015\"],[\"79486.70\",\"0.000\"],[\"79488.00\",\"0.063\"],[\"79497.40\",\"0.019\"],[\"79498.80\",\"0.004\"],[\"79505.50\",\"0.090\"],[\"79506.40\",\"0.033\"],[\"79509.50\",\"0.824\"],[\"79510.80\",\"0.110\"],[\"79511.50\",\"2.011\"],[\"79512.70\",\"0.009\"],[\"79513.50\",\"0.005\"],[\"79513.60\",\"0.000\"],[\"79514.50\",\"0.693\"],[\"79515.50\",\"1.182\"],[\"79517.50\",\"0.000\"],[\"79517.60\",\"0.000\"],[\"79518.70\",\"0.792\"],[\"79519.70\",\"0.453\"],[\"79521.60\",\"0.050\"],[\"79521.90\",\"0.000\"],[\"79522.70\",\"0.628\"],[\"79524.10\",\"0.282\"],[\"79524.90\",\"0.065\"],[\"79525.10\",\"0.037\"],[\"79525.90\",\"0.057\"],[\"79526.40\",\"0.376\"],[\"79527.80\",\"0.145\"],[\"79528.80\",\"0.103\"],[\"79529.10\",\"0.669\"],[\"79529.30\",\"0.058\"],[\"79529.60\",\"0.002\"],[\"79530.40\",\"0.180\"],[\"79531.20\",\"0.190\"],[\"79531.60\",\"0.254\"],[\"79532.60\",\"0.006\"],[\"79533.20\",\"0.027\"],[\"79533.50\",\"1.646\"],[\"79537.60\",\"0.492\"],[\"79537.70\",\"0.000\"],[\"79538.50\",\"0.336\"],[\"79538.80\",\"1.002\"],[\"79539.10\",\"1.010\"],[\"79539.30\",\"0.002\"],[\"79539.50\",\"0.245\"],[\"79539.70\",\"0.058\"],[\"79539.90\",\"0.021\"],[\"79540.00\",\"0.255\"],[\"79540.10\",\"0.009\"],[\"79540.60\",\"0.252\"],[\"79540.70\",\"0.071\"],[\"79543.80\",\"0.086\"],[\"79543.90\",\"6.458\"]],\"a\":[[\"79544.00\",\"5.521\"],[\"79546.10\",\"0.002\"],[\"79547.40\",\"0.000\"],[\"79548.00\",\"0.006\"],[\"79549.00\",\"0.009\"],[\"79550.30\",\"0.001\"],[\"79550.40\",\"0.085\"],[\"79550.70\",\"0.000\"],[\"79551.10\",\"0.074\"],[\"79551.30\",\"0.381\"],[\"79551.60\",\"0.002\"],[\"79553.40\",\"0.027\"],[\"79554.00\",\"0.550\"],[\"79554.20\",\"0.256\"],[\"79554.70\",\"0.006\"],[\"79556.50\",\"0.001\"],[\"79557.80\",\"0.001\"],[\"79560.30\",\"0.060\"],[\"79561.30\",\"0.021\"],[\"79561.70\",\"0.004\"],[\"79561.80\",\"0.000\"],[\"79562.10\",\"0.001\"],[\"79562.60\",\"0.001\"],[\"79563.00\",\"0.027\"],[\"79563.10\",\"1.949\"],[\"79563.30\",\"4.400\"],[\"79564.20\",\"0.002\"],[\"79564.40\",\"0.015\"],[\"79565.10\",\"0.001\"],[\"79565.50\",\"0.042\"],[\"79565.60\",\"0.760\"],[\"79566.30\",\"0.374\"],[\"79566.50\",\"0.001\"],[\"79567.40\",\"0.628\"],[\"79567.90\",\"0.771\"],[\"79568.00\",\"0.004\"],[\"79568.20\",\"0.629\"],[\"79568.60\",\"0.957\"],[\"79569.10\",\"0.704\"],[\"79569.90\",\"0.163\"],[\"79570.00\",\"0.153\"],[\"79571.00\",\"0.079\"],[\"79571.30\",\"0.628\"],[\"79572.10\",\"0.181\"],[\"79573.20\",\"0.127\"],[\"79573.70\",\"0.200\"],[\"79574.30\",\"0.077\"],[\"79575.00\",\"0.082\"],[\"79576.40\",\"0.648\"],[\"79577.60\",\"0.016\"],[\"79579.90\",\"0.130\"],[\"79586.40\",\"0.622\"],[\"79589.70\",\"0.092\"],[\"79590.40\",\"0.260\"],[\"79605.20\",\"3.407\"],[\"79606.10\",\"0.039\"],[\"79614.40\",\"0.087\"],[\"79617.50\",\"0.000\"],[\"79617.60\",\"0.002\"],[\"79620.30\",\"30.432\"],[\"79696.20\",\"0.000\"],[\"79704.00\",\"2.541\"],[\"79745.50\",\"0.000\"],[\"79753.30\",\"0.037\"],[\"79939.70\",\"0.098\"],[\"80339.40\",\"1.433\"],[\"80680.50\",\"9.285\"],[\"81134.80\",\"0.018\"]],\"st\":1}}"}
{"receive_ns":1788580696048436000,"stream":"btcusdt@bookTicker","event_type":"bookTicker","event_time_ms":1788580696086,"raw_json":"{\"stream\":\"btcusdt@bookTicker\",\"data\":{\"e\":\"bookTicker\",\"u\":11479472483782,\"s\":\"BTCUSDT\",\"ps\":\"BTCUSDT\",\"b\":\"79543.90\",\"B\":\"6.458\",\"a\":\"79544.00\",\"A\":\"5.518\",\"T\":1788580696085,\"E\":1788580696086,\"st\":1}}"}
{"receive_ns":1788580696048743000,"stream":"btcusdt@bookTicker","event_type":"bookTicker","event_time_ms":1788580696095,"raw_json":"{\"stream\":\"btcusdt@bookTicker\",\"data\":{\"e\":\"bookTicker\",\"u\":11479472489395,\"s\":\"BTCUSDT\",\"ps\":\"BTCUSDT\",\"b\":\"79543.90\",\"B\":\"6.458\",\"a\":\"79544.00\",\"A\":\"4.928\",\"T\":1788580696095,\"E\":1788580696095,\"st\":1}}"}
{"receive_ns":1788580696110820000,"stream":"btcusdt@bookTicker","event_type":"bookTicker","event_time_ms":1788580696145,"raw_json":"{\"stream\":\"btcusdt@bookTicker\",\"data\":{\"e\":\"bookTicker\",\"u\":11479472505119,\"s\":\"BTCUSDT\",\"ps\":\"BTCUSDT\",\"b\":\"79543.90\",\"B\":\"6.457\",\"a\":\"79544.00\",\"A\":\"4.928\",\"T\":1788580696144,\"E\":1788580696145,\"st\":1}}"}
{"receive_ns":1788580696111007000,"stream":"btcusdt@bookTicker","event_type":"bookTicker","event_time_ms":1788580696146,"raw_json":"{\"stream\":\"btcusdt@bookTicker\",\"data\":{\"e\":\"bookTicker\",\"u\":11479472505589,\"s\":\"BTCUSDT\",\"ps\":\"BTCUSDT\",\"b\":\"79543.90\",\"B\":\"6.458\",\"a\":\"79544.00\",\"A\":\"4.928\",\"T\":1788580696146,\"E\":1788580696146,\"st\":1}}"}
{"receive_ns":1788580696111168000,"stream":"btcusdt@bookTicker","event_type":"bookTicker","event_time_ms":1788580696156,"raw_json":"{\"stream\":\"btcusdt@bookTicker\",\"data\":{\"e\":\"bookTicker\",\"u\":11479472507200,\"s\":\"BTCUSDT\",\"ps\":\"BTCUSDT\",\"b\":\"79543.90\",\"B\":\"6.458\",\"a\":\"79544.00\",\"A\":\"4.940\",\"T\":1788580696156,\"E\":1788580696156,\"st\":1}}"}
{"receive_ns":1788580696111340000,"stream":"btcusdt@bookTicker","event_type":"bookTicker","event_time_ms":1788580696158,"raw_json":"{\"stream\":\"btcusdt@bookTicker\",\"data\":{\"e\":\"bookTicker\",\"u\":11479472507420,\"s\":\"BTCUSDT\",\"ps\":\"BTCUSDT\",\"b\":\"79543.90\",\"B\":\"6.458\",\"a\":\"79544.00\",\"A\":\"4.938\",\"T\":1788580696157,\"E\":1788580696158,\"st\":1}}"}
{"receive_ns":1788580696164044000,"stream":"btcusdt@depth@100ms","event_type":"depthUpdate","event_time_ms":1788580696187,"raw_json":"{\"stream\":\"btcusdt@depth@100ms\",\"data\":{\"e\":\"depthUpdate\",\"E\":1788580696187,\"T\":1788580696186,\"s\":\"BTCUSDT\",\"ps\":\"BTCUSDT\",\"U\":11479472483138,\"u\":11479472511404,\"pu\":11479472482975,\"b\":[[\"29043.90\",\"0.154\"],[\"29143.90\",\"1.911\"],[\"29243.90\",\"0.035\"],[\"71589.50\",\"0.006\"],[\"76362.10\",\"0.000\"],[\"78414.40\",\"0.306\"],[\"78748.50\",\"3.170\"],[\"78920.00\",\"1.153\"],[\"79146.20\",\"3.025\"],[\"79437.30\",\"0.000\"],[\"79445.20\",\"0.000\"],[\"79453.10\",\"0.020\"],[\"79453.20\",\"0.000\"],[\"79454.40\",\"0.059\"],[\"79454.80\",\"0.015\"],[\"79456.40\",\"0.085\"],[\"79456.60\",\"0.001\"],[\"79457.50\",\"0.038\"],[\"79461.10\",\"0.000\"],[\"79469.20\",\"0.000\"],[\"79469.70\",\"0.000\"],[\"79470.10\",\"0.038\"],[\"79474.60\",\"0.001\"],[\"79474.70\",\"0.000\"],[\"79476.00\",\"1.485\"],[\"79477.10\",\"3.463\"],[\"79477.20\",\"0.027\"],[\"79477.30\",\"0.041\"],[\"79478.50\",\"0.000\"],[\"79478.80\",\"1.282\"],[\"79480.00\",\"23.300\"],[\"79480.20\",\"2.220\"],[\"79481.30\",\"0.015\"],[\"79482.30\",\"0.191\"],[\"79483.10\",\"0.002\"],[\"79484.10\",\"0.071\"],[\"79485.50\",\"0.060\"],[\"79486.80\",\"0.612\"],[\"79487.20\",\"0.010\"],[\"79488.00\",\"0.025\"],[\"79488.80\",\"0.388\"],[\"79489.50\",\"0.054\"],[\"79489.90\",\"0.062\"],[\"79490.50\",\"0.058\"],[\"79492.00\",\"0.110\"],[\"79492.60\",\"0.031\"],[\"79495.80\",\"0.003\"],[\"79496.30\",\"0.072\"],[\"79498.10\",\"0.000\"],[\"79505.80\",\"0.210\"],[\"79506.30\",\"0.366\"],[\"79509.50\",\"0.764\"],[\"79510.70\",\"0.013\"],[\"79511.30\",\"0.009\"],[\"79515.20\",\"0.010\"],[\"79516.80\",\"0.030\"],[\"79517.10\",\"0.006\"],[\"79518.30\",\"0.138\"],[\"79519.70\",\"0.503\"],[\"79519.90\",\"0.024\"],[\"79525.90\",\"0.011\"],[\"79526.00\",\"0.455\"],[\"79526.40\",\"0.003\"],[\"79527.20\",\"0.086\"],[\"79527.90\",\"0.073\"],[\"79528.60\",\"0.081\"],[\"79528.80\",\"0.083\"],[\"79529.30\",\"0.058\"],[\"79533.20\",\"0.001\"],[\"79533.40\",\"1.936\"],[\"79533.50\",\"0.381\"],[\"79533.60\",\"0.009\"],[\"79533.70\",\"1.338\"],[\"79536.50\",\"0.618\"],[\"79538.90\",\"1.002\"],[\"79539.00\",\"1.005\"],[\"79539.10\",\"1.002\"],[\"79539.30\",\"0.000\"],[\"79539.40\",\"0.023\"],[\"79539.70\",\"0.066\"],[\"79540.10\",\"0.001\"],[\"79543.90\",\"6.458\"]],\"a\":[[\"79544.00\",\"4.938\"],[\"79544.90\",\"0.156\"],[\"79545.10\",\"0.000\"],[\"79547.00\",\"0.000\"],[\"79547.30\",\"0.002\"],[\"79547.40\",\"0.252\"],[\"79549.00\",\"0.021\"],[\"79549.10\",\"1.080\"],[\"79549.20\",\"0.448\"],[\"79550.40\",\"0.033\"],[\"79550.70\",\"0.376\"],[\"79550.90\",\"0.009\"],[\"79551.30\",\"0.001\"],[\"79551.50\",\"0.509\"],[\"79551.60\",\"0.004\"],[\"79551.80\",\"0.204\"],[\"79552.00\",\"0.372\"],[\"79552.80\",\"1.625\"],[\"79553.50\",\"0.002\"],[\"79555.10\",\"0.386\"],[\"79556.10\",\"0.635\"],[\"79559.80\",\"0.000\"],[\"79561.00\",\"0.130\"],[\"79563.20\",\"0.664\"],[\"79564.10\",\"0.451\"],[\"79566.20\",\"0.057\"],[\"79567.80\",\"0.037\"],[\"79568.10\",\"0.167\"],[\"79568.20\",\"0.001\"],[\"79568.50\",\"0.002\"],[\"79568.60\",\"0.956\"],[\"79573.20\",\"0.078\"],[\"79575.00\",\"0.002\"],[\"79576.20\",\"2.097\"],[\"79579.00\",\"0.046\"],[\"79579.90\",\"0.210\"],[\"79582.20\",\"0.051\"],[\"79584.30\",\"0.000\"],[\"79584.40\",\"1.454\"],[\"79584.50\",\"4.523\"],[\"79584.60\",\"0.562\"],[\"79586.30\",\"0.001\"],[\"79586.80\",\"0.058\"],[\"79587.00\",\"0.124\"],[\"79587.80\",\"0.001\"],[\"79589.90\",\"0.032\"],[\"79590.10\",\"0.004\"],[\"79590.40\",\"0.214\"],[\"79591.00\",\"0.113\"],[\"79591.70\",\"0.110\"],[\"79593.90\",\"0.369\"],[\"79595.90\",\"0.000\"],[\"79600.60\",\"0.000\"],[\"79600.80\",\"0.673\"],[\"79602.00\",\"0.001\"],[\"79603.70\",\"0.023\"],[\"79603.80\",\"0.040\"],[\"79605.20\",\"3.409\"],[\"79605.70\",\"0.012\"],[\"79608.80\",\"0.019\"],[\"79615.00\",\"0.052\"],[\"79616.10\",\"0.407\"],[\"79616.70\",\"3.190\"],[\"79618.50\",\"0.337\"],[\"79619.60\",\"0.002\"],[\"79620.00\",\"16.148\"],[\"79620.30\",\"0.005\"],[\"79622.10\",\"0.002\"],[\"79623.00\",\"0.009\"],[\"79624.00\",\"0.234\"],[\"79624.70\",\"0.514\"],[\"79625.10\",\"0.006\"],[\"79625.60\",\"30.770\"],[\"79626.80\",\"0.027\"],[\"79628.30\",\"0.000\"],[\"79628.90\",\"0.000\"],[\"79629.80\",\"0.047\"],[\"79632.60\",\"0.000\"],[\"79633.00\",\"0.000\"],[\"79635.10\",\"0.015\"],[\"79639.50\",\"0.001\"],[\"79640.50\",\"0.005\"],[\"79640.60\",\"0.003\"],[\"79665.00\",\"0.202\"],[\"79699.10\",\"0.503\"],[\"79936.40\",\"0.508\"],[\"79939.70\",\"0.168\"],[\"80339.40\",\"1.431\"]],\"st\":1}}"}
{"receive_ns":1788580696164368000,"stream":"btcusdt@bookTicker","event_type":"bookTicker","event_time_ms":1788580696203,"raw_json":"{\"stream\":\"btcusdt@bookTicker\",\"data\":{\"e\":\"bookTicker\",\"u\":11479472513928,\"s\":\"BTCUSDT\",\"ps\":\"BTCUSDT\",\"b\":\"79543.90\",\"B\":\"6.291\",\"a\":\"79544.00\",\"A\":\"4.938\",\"T\":1788580696203,\"E\":1788580696203,\"st\":1}}"}
{"receive_ns":1788580696164517000,"stream":"btcusdt@bookTicker","event_type":"bookTicker","event_time_ms":1788580696206,"raw_json":"{\"stream\":\"btcusdt@bookTicker\",\"data\":{\"e\":\"bookTicker\",\"u\":11479472514497,\"s\":\"BTCUSDT\",\"ps\":\"BTCUSDT\",\"b\":\"79543.90\",\"B\":\"6.464\",\"a\":\"79544.00\",\"A\":\"4.938\",\"T\":1788580696206,\"E\":1788580696206,\"st\":1}}"}
{"receive_ns":1788580696164680000,"stream":"btcusdt@bookTicker","event_type":"bookTicker","event_time_ms":1788580696207,"raw_json":"{\"stream\":\"btcusdt@bookTicker\",\"data\":{\"e\":\"bookTicker\",\"u\":11479472514702,\"s\":\"BTCUSDT\",\"ps\":\"BTCUSDT\",\"b\":\"79543.90\",\"B\":\"6.464\",\"a\":\"79544.00\",\"A\":\"4.940\",\"T\":1788580696207,\"E\":1788580696207,\"st\":1}}"}
{"receive_ns":1788580696226149000,"stream":"btcusdt@bookTicker","event_type":"bookTicker","event_time_ms":1788580696264,"raw_json":"{\"stream\":\"btcusdt@bookTicker\",\"data\":{\"e\":\"bookTicker\",\"u\":11479472519772,\"s\":\"BTCUSDT\",\"ps\":\"BTCUSDT\",\"b\":\"79543.90\",\"B\":\"6.464\",\"a\":\"79544.00\",\"A\":\"4.916\",\"T\":1788580696264,\"E\":1788580696264,\"st\":1}}"}
{"receive_ns":1788580696227234000,"stream":"btcusdt@bookTicker","event_type":"bookTicker","event_time_ms":1788580696267,"raw_json":"{\"stream\":\"btcusdt@bookTicker\",\"data\":{\"e\":\"bookTicker\",\"u\":11479472520005,\"s\":\"BTCUSDT\",\"ps\":\"BTCUSDT\",\"b\":\"79543.90\",\"B\":\"6.464\",\"a\":\"79544.00\",\"A\":\"4.939\",\"T\":1788580696267,\"E\":1788580696267,\"st\":1}}"}
{"receive_ns":1788580696232730000,"stream":"btcusdt@depth@100ms","event_type":"depthUpdate","event_time_ms":1788580696289,"raw_json":"{\"stream\":\"btcusdt@depth@100ms\",\"data\":{\"e\":\"depthUpdate\",\"E\":1788580696289,\"T\":1788580696288,\"s\":\"BTCUSDT\",\"ps\":\"BTCUSDT\",\"U\":11479472511619,\"u\":11479472521470,\"pu\":11479472511404,\"b\":[[\"1000.00\",\"25.354\"],[\"29043.90\",\"0.294\"],[\"29143.90\",\"1.806\"],[\"29243.90\",\"0.000\"],[\"71589.50\",\"0.006\"],[\"76362.10\",\"0.002\"],[\"78450.60\",\"3.307\"],[\"78681.40\",\"9.899\"],[\"78748.50\",\"3.170\"],[\"78992.60\",\"0.003\"],[\"79397.70\",\"0.102\"],[\"79397.80\",\"1.890\"],[\"79437.30\",\"0.013\"],[\"79445.20\",\"0.016\"],[\"79453.20\",\"0.014\"],[\"79454.80\",\"0.040\"],[\"79461.10\",\"0.013\"],[\"79474.60\",\"0.001\"],[\"79477.30\",\"22.857\"],[\"79480.00\",\"0.484\"],[\"79514.70\",\"0.644\"],[\"79515.50\",\"0.554\"],[\"79516.80\",\"0.034\"],[\"79525.60\",\"0.374\"],[\"79526.00\",\"0.082\"],[\"79526.50\",\"0.049\"],[\"79527.20\",\"0.040\"],[\"79529.30\",\"0.058\"],[\"79529.40\",\"1.801\"],[\"79533.50\",\"0.001\"],[\"79533.60\",\"0.003\"],[\"79533.70\",\"0.077\"],[\"79533.80\",\"0.003\"],[\"79533.90\",\"0.004\"],[\"79534.00\",\"0.006\"],[\"79538.60\",\"0.442\"],[\"79538.70\",\"0.107\"],[\"79538.90\",\"1.000\"],[\"79539.00\",\"1.003\"],[\"79539.60\",\"1.372\"],[\"79539.70\",\"1.948\"],[\"79539.80\",\"0.004\"],[\"79541.70\",\"0.001\"],[\"79543.80\",\"0.085\"],[\"79543.90\",\"6.464\"]],\"a\":[[\"79544.00\",\"4.939\"],[\"79544.40\",\"0.001\"],[\"79550.40\",\"0.029\"],[\"79550.60\",\"0.004\"],[\"79562.00\",\"0.002\"],[\"79565.50\",\"0.491\"],[\"79565.60\",\"1.199\"],[\"79566.30\",\"0.001\"],[\"79567.90\",\"0.332\"],[\"79569.00\",\"0.076\"],[\"79572.00\",\"0.727\"],[\"79578.00\",\"0.052\"],[\"79586.30\",\"0.006\"],[\"79586.80\",\"0.008\"],[\"79590.00\",\"0.176\"],[\"79591.70\",\"0.064\"],[\"79605.60\",\"0.061\"],[\"79614.40\",\"0.027\"],[\"79616.00\",\"0.163\"],[\"79616.30\",\"0.013\"],[\"79620.30\",\"30.577\"],[\"79623.00\",\"0.009\"],[\"79625.60\",\"0.198\"],[\"79634.00\",\"0.179\"],[\"79642.00\",\"0.014\"],[\"79649.90\",\"0.015\"],[\"79657.90\",\"3.817\"],[\"79665.80\",\"0.016\"],[\"79668.40\",\"1.901\"],[\"79668.50\",\"0.005\"],[\"80339.40\",\"1.429\"],[\"80498.50\",\"16.001\"],[\"80538.30\",\"2.430\"]],\"st\":1}}"}
{"receive_ns":1788580696334595000,"stream":"btcusdt@depth@100ms","event_type":"depthUpdate","event_time_ms":1788580696391,"raw_json":"{\"stream\":\"btcusdt@depth@100ms\",\"data\":{\"e\":\"depthUpdate\",\"E\":1788580696391,\"T\":1788580696389,\"s\":\"BTCUSDT\",\"ps\":\"BTCUSDT\",\"U\":11479472521567,\"u\":11479472527754,\"pu\":11479472521470,\"b\":[[\"1000.00\",\"25.354\"],[\"29043.90\",\"0.469\"],[\"29143.90\",\"1.631\"],[\"63635.00\",\"0.000\"],[\"71589.50\",\"0.006\"],[\"76362.10\",\"0.000\"],[\"78675.10\",\"0.000\"],[\"78748.50\",\"3.170\"],[\"79036.00\",\"0.017\"],[\"79061.30\",\"0.007\"],[\"79453.10\",\"0.020\"],[\"79454.40\",\"0.027\"],[\"79456.40\",\"0.117\"],[\"79482.30\",\"0.191\"],[\"79523.30\",\"0.002\"],[\"79529.50\",\"0.007\"],[\"79533.40\",\"1.935\"],[\"79533.90\",\"0.000\"]],\"a\":[[\"79550.40\",\"0.077\"],[\"79550.60\",\"0.000\"],[\"79551.80\",\"0.456\"],[\"79564.40\",\"0.091\"],[\"79572.70\",\"0.991\"],[\"79573.40\",\"0.160\"],[\"79582.20\",\"0.002\"],[\"79614.60\",\"0.210\"],[\"79617.40\",\"0.001\"],[\"79620.30\",\"0.005\"],[\"79623.00\",\"30.581\"],[\"79624.00\",\"0.024\"],[\"79626.30\",\"0.015\"],[\"79635.10\",\"0.001\"],[\"79672.50\",\"0.000\"],[\"79697.70\",\"0.012\"],[\"79699.10\",\"0.498\"],[\"79934.40\",\"0.386\"],[\"79936.40\",\"0.501\"],[\"79937.70\",\"0.041\"],[\"79939.70\",\"0.136\"],[\"80260.70\",\"0.871\"],[\"80339.40\",\"1.429\"],[\"80890.90\",\"3.086\"]],\"st\":1}}"}
{"receive_ns":1788580696451029000,"stream":"btcusdt@bookTicker","event_type":"bookTicker","event_time_ms":1788580696479,"raw_json":"{\"stream\":\"btcusdt@bookTicker\",\"data\":{\"e\":\"bookTicker\",\"u\":11479472532943,\"s\":\"BTCUSDT\",\"ps\":\"BTCUSDT\",\"b\":\"79543.90\",\"B\":\"6.520\",\"a\":\"79544.00\",\"A\":\"4.939\",\"T\":1788580696479,\"E\":1788580696479,\"st\":1}}"}
{"receive_ns":1788580696451429000,"stream":"btcusdt@depth@100ms","event_type":"depthUpdate","event_time_ms":1788580696493,"raw_json":"{\"stream\":\"btcusdt@depth@100ms\",\"data\":{\"e\":\"depthUpdate\",\"E\":1788580696493,\"T\":1788580696490,\"s\":\"BTCUSDT\",\"ps\":\"BTCUSDT\",\"U\":11479472527826,\"u\":11479472533680,\"pu\":11479472527754,\"b\":[[\"29043.90\",\"0.651\"],[\"29143.90\",\"1.449\"],[\"71589.50\",\"0.006\"],[\"71623.00\",\"0.003\"],[\"71624.70\",\"0.004\"],[\"78390.50\",\"2.803\"],[\"78522.20\",\"11.196\"],[\"78562.00\",\"9.687\"],[\"78748.50\",\"3.170\"],[\"79146.20\",\"3.035\"],[\"79477.30\",\"0.041\"],[\"79480.00\",\"23.300\"],[\"79498.90\",\"0.002\"],[\"79499.20\",\"1.031\"],[\"79511.50\",\"0.011\"],[\"79518.80\",\"0.454\"],[\"79519.70\",\"0.051\"],[\"79528.40\",\"0.617\"],[\"79529.10\",\"0.229\"],[\"79531.20\",\"0.164\"],[\"79538.40\",\"0.060\"],[\"79538.60\",\"0.440\"],[\"79538.70\",\"0.105\"],[\"79541.70\",\"0.000\"],[\"79543.80\",\"0.086\"],[\"79543.90\",\"6.520\"]],\"a\":[[\"79550.40\",\"0.077\"],[\"79555.30\",\"0.070\"],[\"79559.60\",\"0.005\"],[\"79564.90\",\"0.441\"],[\"79565.60\",\"0.760\"],[\"79569.00\",\"0.776\"],[\"79572.60\",\"0.868\"],[\"79574.90\",\"0.139\"],[\"79578.10\",\"0.120\"],[\"79587.00\",\"0.004\"],[\"79620.30\",\"30.577\"],[\"79623.00\",\"0.009\"],[\"80339.40\",\"1.429\"],[\"81134.80\",\"0.015\"]],\"st\":1}}"}
{"receive_ns":1788580696451665000,"stream":"btcusdt@bookTicker","event_type":"bookTicker","event_time_ms":1788580696503,"raw_json":"{\"stream\":\"btcusdt@bookTicker\",\"data\":{\"e\":\"bookTicker\",\"u\":11479472534455,\"s\":\"BTCUSDT\",\"ps\":\"BTCUSDT\",\"b\":\"79543.90\",\"B\":\"6.526\",\"a\":\"79544.00\",\"A\":\"4.939\",\"T\":1788580696503,\"E\":1788580696503,\"st\":1}}"}
{"receive_ns":1788580696503978000,"stream":"btcusdt@bookTicker","event_type":"bookTicker","event_time_ms":1788580696539,"raw_json":"{\"stream\":\"btcusdt@bookTicker\",\"data\":{\"e\":\"bookTicker\",\"u\":11479472536488,\"s\":\"BTCUSDT\",\"ps\":\"BTCUSDT\",\"b\":\"79543.90\",\"B\":\"6.526\",\"a\":\"79544.00\",\"A\":\"4.936\",\"T\":1788580696539,\"E\":1788580696539,\"st\":1}}"}
{"receive_ns":1788580696504340000,"stream":"btcusdt@bookTicker","event_type":"bookTicker","event_time_ms":1788580696542,"raw_json":"{\"stream\":\"btcusdt@bookTicker\",\"data\":{\"e\":\"bookTicker\",\"u\":11479472536667,\"s\":\"BTCUSDT\",\"ps\":\"BTCUSDT\",\"b\":\"79543.90\",\"B\":\"6.526\",\"a\":\"79544.00\",\"A\":\"4.938\",\"T\":1788580696542,\"E\":1788580696542,\"st\":1}}"}
{"receive_ns":1788580696561889000,"stream":"btcusdt@depth@100ms","event_type":"depthUpdate","event_time_ms":1788580696595,"raw_json":"{\"stream\":\"btcusdt@depth@100ms\",\"data\":{\"e\":\"depthUpdate\",\"E\":1788580696595,\"T\":1788580696594,\"s\":\"BTCUSDT\",\"ps\":\"BTCUSDT\",\"U\":11479472533893,\"u\":11479472539337,\"pu\":11479472533680,\"b\":[[\"1000.00\",\"25.354\"],[\"29043.90\",\"0.833\"],[\"29143.90\",\"1.267\"],[\"63635.00\",\"0.000\"],[\"71589.50\",\"0.006\"],[\"71623.00\",\"0.000\"],[\"75566.70\",\"0.011\"],[\"75566.80\",\"0.006\"],[\"76362.10\",\"0.002\"],[\"78438.20\",\"2.011\"],[\"78748.50\",\"3.170\"],[\"78821.90\",\"0.690\"],[\"79454.40\",\"0.002\"],[\"79456.40\",\"0.092\"],[\"79471.90\",\"22.816\"],[\"79480.00\",\"0.484\"],[\"79508.90\",\"0.001\"],[\"79509.00\",\"10.128\"],[\"79511.30\",\"0.008\"],[\"79511.90\",\"2.648\"],[\"79540.60\",\"0.252\"],[\"79543.90\",\"6.526\"]],\"a\":[[\"79544.00\",\"4.938\"],[\"79568.00\",\"0.704\"],[\"79569.00\",\"0.076\"],[\"79575.00\",\"0.001\"],[\"79577.50\",\"10.266\"],[\"79577.60\",\"0.087\"],[\"79586.40\",\"0.552\"],[\"79620.30\",\"0.005\"],[\"79623.00\",\"30.581\"],[\"79699.10\",\"0.480\"],[\"79939.70\",\"0.122\"],[\"80339.40\",\"1.429\"],[\"87541.40\",\"0.006\"]],\"st\":1}}"}
{"receive_ns":1788580696565042000,"stream":"btcusdt@bookTicker","event_type":"bookTicker","event_time_ms":1788580696622,"raw_json":"{\"stream\":\"btcusdt@bookTicker\",\"data\":{\"e\":\"bookTicker\",\"u\":11479472540970,\"s\":\"BTCUSDT\",\"ps\":\"BTCUSDT\",\"b\":\"79543.90\",\"B\":\"6.526\",\"a\":\"79544.00\",\"A\":\"4.941\",\"T\":1788580696622,\"E\":1788580696622,\"st\":1}}"}
{"receive_ns":1788580696640492000,"stream":"btcusdt@depth@100ms","event_type":"depthUpdate","event_time_ms":1788580696697,"raw_json":"{\"stream\":\"btcusdt@depth@100ms\",\"data\":{\"e\":\"depthUpdate\",\"E\":1788580696697,\"T\":1788580696696,\"s\":\"BTCUSDT\",\"ps\":\"BTCUSDT\",\"U\":11479472539448,\"u\":11479472545096,\"pu\":11479472539337,\"b\":[[\"1000.00\",\"25.354\"],[\"29043.90\",\"1.008\"],[\"29143.90\",\"1.092\"],[\"71589.50\",\"0.006\"],[\"76362.10\",\"0.000\"],[\"78625.60\",\"0.000\"],[\"78748.50\",\"3.170\"],[\"79453.10\",\"0.020\"],[\"79454.40\",\"0.207\"],[\"79456.40\",\"0.000\"],[\"79471.90\",\"0.000\"],[\"79472.30\",\"0.403\"],[\"79474.60\",\"22.817\"],[\"79482.30\",\"0.103\"],[\"79514.50\",\"0.002\"],[\"79540.60\",\"0.253\"]],\"a\":[[\"79544.00\",\"4.941\"],[\"79546.10\",\"0.003\"],[\"79560.20\",\"0.030\"],[\"79572.10\",\"0.180\"],[\"79585.50\",\"0.021\"],[\"79763.20\",\"0.029\"],[\"79933.80\",\"0.018\"],[\"79934.40\",\"0.379\"],[\"79936.40\",\"0.508\"],[\"79937.70\",\"0.041\"],[\"79939.70\",\"0.136\"],[\"80339.40\",\"1.429\"],[\"80896.20\",\"5.071\"],[\"87498.40\",\"0.003\"],[\"87541.40\",\"0.004\"]],\"st\":1}}"}
{"receive_ns":1788580696689026000,"stream":"btcusdt@bookTicker","event_type":"bookTicker","event_time_ms":1788580696732,"raw_json":"{\"stream\":\"btcusdt@bookTicker\",\"data\":{\"e\":\"bookTicker\",\"u\":11479472547030,\"s\":\"BTCUSDT\",\"ps\":\"BTCUSDT\",\"b\":\"79543.90\",\"B\":\"6.525\",\"a\":\"79544.00\",\"A\":\"4.941\",\"T\":1788580696732,\"E\":1788580696732,\"st\":1}}"}
{"receive_ns":1788580696689241000,"stream":"btcusdt@bookTicker","event_type":"bookTicker","event_time_ms":1788580696735,"raw_json":"{\"stream\":\"btcusdt@bookTicker\",\"data\":{\"e\":\"bookTicker\",\"u\":11479472547212,\"s\":\"BTCUSDT\",\"ps\":\"BTCUSDT\",\"b\":\"79543.90\",\"B\":\"6.526\",\"a\":\"79544.00\",\"A\":\"4.941\",\"T\":1788580696735,\"E\":1788580696735,\"st\":1}}"}
{"receive_ns":1788580696758743000,"stream":"btcusdt@depth@100ms","event_type":"depthUpdate","event_time_ms":1788580696799,"raw_json":"{\"stream\":\"btcusdt@depth@100ms\",\"data\":{\"e\":\"depthUpdate\",\"E\":1788580696799,\"T\":1788580696798,\"s\":\"BTCUSDT\",\"ps\":\"BTCUSDT\",\"U\":11479472545136,\"u\":11479472550507,\"pu\":11479472545096,\"b\":[[\"29043.90\",\"1.190\"],[\"29143.90\",\"0.910\"],[\"63635.00\",\"0.000\"],[\"71589.50\",\"0.006\"],[\"76362.10\",\"0.002\"],[\"77953.10\",\"0.006\"],[\"78588.70\",\"0.003\"],[\"78590.40\",\"0.000\"],[\"78612.30\",\"0.007\"],[\"78615.60\",\"0.000\"],[\"78668.90\",\"0.950\"],[\"78748.50\",\"3.170\"],[\"79146.10\",\"0.008\"],[\"79146.20\",\"3.025\"],[\"79529.40\",\"0.544\"],[\"79529.50\",\"0.635\"],[\"79540.00\",\"0.003\"],[\"79540.60\",\"0.253\"],[\"79540.70\",\"0.039\"],[\"79543.90\",\"6.526\"]],\"a\":[[\"79554.50\",\"0.783\"],[\"79563.20\",\"0.036\"],[\"79588.60\",\"0.625\"],[\"79588.70\",\"0.036\"],[\"79941.80\",\"0.000\"],[\"80140.60\",\"2.493\"],[\"80273.30\",\"0.871\"],[\"80339.40\",\"1.429\"],[\"80737.60\",\"0.124\"],[\"81119.00\",\"0.622\"],[\"87498.40\",\"0.001\"]],\"st\":1}}"}
{"receive_ns":1788580696762509000,"stream":"btcusdt@bookTicker","event_type":"bookTicker","event_time_ms":1788580696818,"raw_json":"{\"stream\":\"btcusdt@bookTicker\",\"data\":{\"e\":\"bookTicker\",\"u\":11479472551920,\"s\":\"BTCUSDT\",\"ps\":\"BTCUSDT\",\"b\":\"79543.90\",\"B\":\"6.527\",\"a\":\"79544.00\",\"A\":\"4.941\",\"T\":1788580696818,\"E\":1788580696818,\"st\":1}}"}
{"receive_ns":1788580696814625000,"stream":"btcusdt@bookTicker","event_type":"bookTicker","event_time_ms":1788580696867,"raw_json":"{\"stream\":\"btcusdt@bookTicker\",\"data\":{\"e\":\"bookTicker\",\"u\":11479472555250,\"s\":\"BTCUSDT\",\"ps\":\"BTCUSDT\",\"b\":\"79543.90\",\"B\":\"6.526\",\"a\":\"79544.00\",\"A\":\"4.941\",\"T\":1788580696867,\"E\":1788580696867,\"st\":1}}"}
{"receive_ns":1788580696814808000,"stream":"btcusdt@bookTicker","event_type":"bookTicker","event_time_ms":1788580696868,"raw_json":"{\"stream\":\"btcusdt@bookTicker\",\"data\":{\"e\":\"bookTicker\",\"u\":11479472555332,\"s\":\"BTCUSDT\",\"ps\":\"BTCUSDT\",\"b\":\"79543.90\",\"B\":\"6.526\",\"a\":\"79544.00\",\"A\":\"4.953\",\"T\":1788580696868,\"E\":1788580696868,\"st\":1}}"}
{"receive_ns":1788580696814953000,"stream":"btcusdt@bookTicker","event_type":"bookTicker","event_time_ms":1788580696869,"raw_json":"{\"stream\":\"btcusdt@bookTicker\",\"data\":{\"e\":\"bookTicker\",\"u\":11479472555378,\"s\":\"BTCUSDT\",\"ps\":\"BTCUSDT\",\"b\":\"79543.90\",\"B\":\"6.525\",\"a\":\"79544.00\",\"A\":\"4.953\",\"T\":1788580696869,\"E\":1788580696869,\"st\":1}}"}
{"receive_ns":1788580696836145000,"stream":"btcusdt@bookTicker","event_type":"bookTicker","event_time_ms":1788580696892,"raw_json":"{\"stream\":\"btcusdt@bookTicker\",\"data\":{\"e\":\"bookTicker\",\"u\":11479472556541,\"s\":\"BTCUSDT\",\"ps\":\"BTCUSDT\",\"b\":\"79543.90\",\"B\":\"6.524\",\"a\":\"79544.00\",\"A\":\"4.953\",\"T\":1788580696892,\"E\":1788580696892,\"st\":1}}"}
{"receive_ns":1788580696872255000,"stream":"btcusdt@depth@100ms","event_type":"depthUpdate","event_time_ms":1788580696901,"raw_json":"{\"stream\":\"btcusdt@depth@100ms\",\"data\":{\"e\":\"depthUpdate\",\"E\":1788580696901,\"T\":1788580696900,\"s\":\"BTCUSDT\",\"ps\":\"BTCUSDT\",\"U\":11479472550532,\"u\":11479472557138,\"pu\":11479472550507,\"b\":[[\"1000.00\",\"25.354\"],[\"29043.90\",\"1.365\"],[\"29143.90\",\"0.735\"],[\"63635.00\",\"0.004\"],[\"71589.50\",\"0.006\"],[\"76362.10\",\"0.000\"],[\"78689.20\",\"0.953\"],[\"78748.50\",\"3.170\"],[\"78827.60\",\"0.887\"],[\"78902.30\",\"2.782\"],[\"79146.10\",\"0.009\"],[\"79418.90\",\"0.000\"],[\"79453.10\",\"0.020\"],[\"79454.40\",\"0.144\"],[\"79456.40\",\"0.088\"],[\"79472.30\",\"0.378\"],[\"79475.00\",\"0.801\"],[\"79482.30\",\"0.103\"],[\"79520.20\",\"2.393\"],[\"79540.60\",\"0.252\"],[\"79543.90\",\"6.524\"]],\"a\":[[\"79544.00\",\"4.953\"],[\"79560.10\",\"0.002\"],[\"79666.40\",\"0.000\"],[\"79933.80\",\"0.018\"],[\"79934.40\",\"0.386\"],[\"79936.40\",\"0.501\"],[\"79937.70\",\"0.041\"],[\"79939.70\",\"0.136\"],[\"79941.80\",\"0.001\"],[\"80339.40\",\"1.429\"],[\"80590.90\",\"3.110\"],[\"80896.20\",\"5.318\"]],\"st\":1}}"}
{"receive_ns":1788580696949526000,"stream":"btcusdt@depth@100ms","event_type":"depthUpdate","event_time_ms":1788580697003,"raw_json":"{\"stream\":\"btcusdt@depth@100ms\",\"data\":{\"e\":\"depthUpdate\",\"E\":1788580697003,\"T\":1788580697001,\"s\":\"BTCUSDT\",\"ps\":\"BTCUSDT\",\"U\":11479472557237,\"u\":11479472561728,\"pu\":11479472557138,\"b\":[[\"29043.90\",\"1.547\"],[\"29143.90\",\"0.553\"],[\"63635.00\",\"0.000\"],[\"63635.10\",\"0.000\"],[\"71589.50\",\"0.006\"],[\"77953.10\",\"0.009\"],[\"78613.20\",\"0.888\"],[\"78748.50\",\"3.170\"],[\"79419.00\",\"0.429\"],[\"79518.70\",\"0.767\"],[\"79520.20\",\"2.395\"],[\"79524.00\",\"0.029\"],[\"79540.60\",\"0.252\"]],\"a\":[[\"79560.10\",\"0.004\"],[\"79666.40\",\"0.428\"],[\"80339.40\",\"1.429\"],[\"80498.50\",\"16.496\"],[\"80630.60\",\"11.950\"],[\"80680.50\",\"7.428\"]],\"st\":1}}"}
{"receive_ns":1788580697031942000,"stream":"btcusdt@bookTicker","event_type":"bookTicker","event_time_ms":1788580697049,"raw_json":"{\"stream\":\"btcusdt@bookTicker\",\"data\":{\"e\":\"bookTicker\",\"u\":11479472564378,\"s\":\"BTCUSDT\",\"ps\":\"BTCUSDT\",\"b\":\"79543.90\",\"B\":\"6.523\",\"a\":\"79544.00\",\"A\":\"4.953\",\"T\":1788580697049,\"E\":1788580697049,\"st\":1}}"}
{"receive_ns":1788580697032141000,"stream":"btcusdt@bookTicker","event_type":"bookTicker","event_time_ms":1788580697050,"raw_json":"{\"stream\":\"btcusdt@bookTicker\",\"data\":{\"e\":\"bookTicker\",\"u\":11479472564402,\"s\":\"BTCUSDT\",\"ps\":\"BTCUSDT\",\"b\":\"79543.90\",\"B\":\"6.522\",\"a\":\"79544.00\",\"A\":\"4.953\",\"T\":1788580697049,\"E\":1788580697050,\"st\":1}}"}
{"receive_ns":1788580697032272000,"stream":"btcusdt@bookTicker","event_type":"bookTicker","event_time_ms":1788580697050,"raw_json":"{\"stream\":\"btcusdt@bookTicker\",\"data\":{\"e\":\"bookTicker\",\"u\":11479472564405,\"s\":\"BTCUSDT\",\"ps\":\"BTCUSDT\",\"b\":\"79543.90\",\"B\":\"5.296\",\"a\":\"79544.00\",\"A\":\"4.953\",\"T\":1788580697049,\"E\":1788580697050,\"st\":1}}"}
{"receive_ns":1788580697032427000,"stream":"btcusdt@bookTicker","event_type":"bookTicker","event_time_ms":1788580697051,"raw_json":"{\"stream\":\"btcusdt@bookTicker\",\"data\":{\"e\":\"bookTicker\",\"u\":11479472564531,\"s\":\"BTCUSDT\",\"ps\":\"BTCUSDT\",\"b\":\"79543.90\",\"B\":\"5.297\",\"a\":\"79544.00\",\"A\":\"4.953\",\"T\":1788580697050,\"E\":1788580697051,\"st\":1}}"}
{"receive_ns":1788580697032552000,"stream":"btcusdt@bookTicker","event_type":"bookTicker","event_time_ms":1788580697051,"raw_json":"{\"stream\":\"btcusdt@bookTicker\",\"data\":{\"e\":\"bookTicker\",\"u\":11479472564576,\"s\":\"BTCUSDT\",\"ps\":\"BTCUSDT\",\"b\":\"79543.90\",\"B\":\"5.257\",\"a\":\"79544.00\",\"A\":\"4.953\",\"T\":1788580697051,\"E\":1788580697051,\"st\":1}}"}
{"receive_ns":1788580697032690000,"stream":"btcusdt@bookTicker","event_type":"bookTicker","event_time_ms":1788580697078,"raw_json":"{\"stream\":\"btcusdt@bookTicker\",\"data\":{\"e\":\"bookTicker\",\"u\":11479472566401,\"s\":\"BTCUSDT\",\"ps\":\"BTCUSDT\",\"b\":\"79543.90\",\"B\":\"5.257\",\"a\":\"79544.00\",\"A\":\"4.950\",\"T\":1788580697078,\"E\":1788580697078,\"st\":1}}"}
{"receive_ns":1788580697042103000,"stream":"btcusdt@bookTicker","event_type":"bookTicker","event_time_ms":1788580697098,"raw_json":"{\"stream\":\"btcusdt@bookTicker\",\"data\":{\"e\":\"bookTicker\",\"u\":11479472567421,\"s\":\"BTCUSDT\",\"ps\":\"BTCUSDT\",\"b\":\"79543.90\",\"B\":\"5.257\",\"a\":\"79544.00\",\"A\":\"5.196\",\"T\":1788580697098,\"E\":1788580697098,\"st\":1}}"}
{"receive_ns":1788580697042373000,"stream":"btcusdt@bookTicker","event_type":"bookTicker","event_time_ms":1788580697099,"raw_json":"{\"stream\":\"btcusdt@bookTicker\",\"data\":{\"e\":\"bookTicker\",\"u\":11479472567503,\"s\":\"BTCUSDT\",\"ps\":\"BTCUSDT\",\"b\":\"79543.90\",\"B\":\"5.257\",\"a\":\"79544.00\",\"A\":\"5.194\",\"T\":1788580697099,\"E\":1788580697099,\"st\":1}}"}
{"receive_ns":1788580697057573000,"stream":"btcusdt@depth@100ms","event_type":"depthUpdate","event_time_ms":1788580697105,"raw_json":"{\"stream\":\"btcusdt@depth@100ms\",\"data\":{\"e\":\"depthUpdate\",\"E\":1788580697105,\"T\":1788580697104,\"s\":\"BTCUSDT\",\"ps\":\"BTCUSDT\",\"U\":11479472561755,\"u\":11479472567877,\"pu\":11479472561728,\"b\":[[\"29043.90\",\"1.722\"],[\"29143.90\",\"0.378\"],[\"63635.00\",\"0.000\"],[\"71589.50\",\"0.006\"],[\"76362.10\",\"0.002\"],[\"77965.40\",\"3.585\"],[\"78053.80\",\"0.000\"],[\"78142.20\",\"0.000\"],[\"78230.60\",\"0.000\"],[\"78319.00\",\"0.000\"],[\"78407.40\",\"0.000\"],[\"78495.70\",\"0.000\"],[\"78584.10\",\"29.518\"],[\"78672.50\",\"13.970\"],[\"78676.90\",\"1.837\"],[\"78748.50\",\"3.170\"],[\"78760.90\",\"10.485\"],[\"78907.50\",\"4.680\"],[\"79146.20\",\"3.035\"],[\"79453.10\",\"0.000\"],[\"79454.40\",\"0.052\"],[\"79456.40\",\"0.000\"],[\"79482.30\",\"0.015\"],[\"79486.80\",\"1.442\"],[\"79499.20\",\"1.029\"],[\"79502.70\",\"0.038\"],[\"79504.10\",\"0.004\"],[\"79504.80\",\"10.303\"],[\"79509.00\",\"0.129\"],[\"79510.50\",\"0.010\"],[\"79511.90\",\"1.383\"],[\"79512.70\",\"0.035\"],[\"79518.10\",\"0.692\"],[\"79518.70\",\"0.139\"],[\"79522.10\",\"0.633\"],[\"79522.70\",\"0.000\"],[\"79525.20\",\"0.373\"],[\"79525.60\",\"0.001\"],[\"79525.70\",\"0.049\"],[\"79526.50\",\"0.003\"],[\"79527.80\",\"0.585\"],[\"79528.40\",\"0.177\"],[\"79529.30\",\"0.032\"],[\"79529.40\",\"0.154\"],[\"79529.50\",\"0.631\"],[\"79529.60\",\"0.002\"],[\"79533.50\",\"0.395\"],[\"79536.50\",\"0.253\"],[\"79538.10\",\"0.074\"],[\"79538.40\",\"0.056\"],[\"79539.60\",\"1.373\"],[\"79543.80\",\"0.085\"],[\"79543.90\",\"5.257\"]],\"a\":[[\"79544.00\",\"5.194\"],[\"79550.40\",\"0.073\"],[\"79550.60\",\"0.004\"],[\"79557.80\",\"0.692\"],[\"79562.10\",\"0.629\"],[\"79562.40\",\"0.080\"],[\"79563.30\",\"3.772\"],[\"79565.90\",\"0.628\"],[\"79567.40\",\"0.000\"],[\"79568.40\",\"3.030\"],[\"79568.50\",\"0.001\"],[\"79573.70\",\"1.030\"],[\"79574.30\",\"0.001\"],[\"79599.70\",\"0.052\"],[\"79605.20\",\"3.410\"],[\"79668.10\",\"0.013\"],[\"79693.60\",\"0.006\"],[\"79933.80\",\"0.018\"],[\"79934.40\",\"0.379\"],[\"79937.70\",\"0.004\"],[\"79939.70\",\"0.014\"],[\"80119.80\",\"0.000\"],[\"80339.40\",\"1.431\"],[\"80352.10\",\"5.222\"],[\"80440.50\",\"4.969\"],[\"80528.90\",\"0.002\"],[\"80617.30\",\"0.000\"],[\"80665.60\",\"1.980\"],[\"80705.60\",\"0.000\"],[\"80794.00\",\"0.000\"],[\"80882.40\",\"0.000\"],[\"80970.80\",\"0.000\"],[\"81059.20\",\"0.001\"],[\"81134.80\",\"0.012\"],[\"81147.60\",\"3.446\"]],\"st\":1}}"}
{"receive_ns":1788580697100726000,"stream":"btcusdt@bookTicker","event_type":"bookTicker","event_time_ms":1788580697143,"raw_json":"{\"stream\":\"btcusdt@bookTicker\",\"data\":{\"e\":\"bookTicker\",\"u\":11479472569672,\"s\":\"BTCUSDT\",\"ps\":\"BTCUSDT\",\"b\":\"79543.90\",\"B\":\"5.257\",\"a\":\"79544.00\",\"A\":\"5.166\",\"T\":1788580697143,\"E\":1788580697143,\"st\":1}}"}
{"receive_ns":1788580697100915000,"stream":"btcusdt@bookTicker","event_type":"bookTicker","event_time_ms":1788580697145,"raw_json":"{\"stream\":\"btcusdt@bookTicker\",\"data\":{\"e\":\"bookTicker\",\"u\":11479472569762,\"s\":\"BTCUSDT\",\"ps\":\"BTCUSDT\",\"b\":\"79543.90\",\"B\":\"5.257\",\"a\":\"79544.00\",\"A\":\"5.285\",\"T\":1788580697145,\"E\":1788580697145,\"st\":1}}"}
{"receive_ns":1788580697101117000,"stream":"btcusdt@bookTicker","event_type":"bookTicker","event_time_ms":1788580697146,"raw_json":"{\"stream\":\"btcusdt@bookTicker\",\"data\":{\"e\":\"bookTicker\",\"u\":11479472569802,\"s\":\"BTCUSDT\",\"ps\":\"BTCUSDT\",\"b\":\"79543.90\",\"B\":\"5.257\",\"a\":\"79544.00\",\"A\":\"5.287\",\"T\":1788580697146,\"E\":1788580697146,\"st\":1}}"}
{"receive_ns":1788580697101241000,"stream":"btcusdt@bookTicker","event_type":"bookTicker","event_time_ms":1788580697146,"raw_json":"{\"stream\":\"btcusdt@bookTicker\",\"data\":{\"e\":\"bookTicker\",\"u\":11479472569809,\"s\":\"BTCUSDT\",\"ps\":\"BTCUSDT\",\"b\":\"79543.90\",\"B\":\"5.257\",\"a\":\"79544.00\",\"A\":\"5.316\",\"T\":1788580697146,\"E\":1788580697146,\"st\":1}}"}
{"receive_ns":1788580697159391000,"stream":"btcusdt@bookTicker","event_type":"bookTicker","event_time_ms":1788580697178,"raw_json":"{\"stream\":\"btcusdt@bookTicker\",\"data\":{\"e\":\"bookTicker\",\"u\":11479472571274,\"s\":\"BTCUSDT\",\"ps\":\"BTCUSDT\",\"b\":\"79543.90\",\"B\":\"5.257\",\"a\":\"79544.00\",\"A\":\"5.906\",\"T\":1788580697178,\"E\":1788580697178,\"st\":1}}"}
{"receive_ns":1788580697159641000,"stream":"btcusdt@bookTicker","event_type":"bookTicker","event_time_ms":1788580697179,"raw_json":"{\"stream\":\"btcusdt@bookTicker\",\"data\":{\"e\":\"bookTicker\",\"u\":11479472571316,\"s\":\"BTCUSDT\",\"ps\":\"BTCUSDT\",\"b\":\"79543.90\",\"B\":\"5.257\",\"a\":\"79544.00\",\"A\":\"5.904\",\"T\":1788580697179,\"E\":1788580697179,\"st\":1}}"}
{"receive_ns":1788580697160134000,"stream":"btcusdt@depth@100ms","event_type":"depthUpdate","event_time_ms":1788580697207,"raw_json":"{\"stream\":\"btcusdt@depth@100ms\",\"data\":{\"e\":\"depthUpdate\",\"E\":1788580697207,\"T\":1788580697206,\"s\":\"BTCUSDT\",\"ps\":\"BTCUSDT\",\"U\":11479472567958,\"u\":11479472572528,\"pu\":11479472567877,\"b\":[[\"1000.00\",\"25.354\"],[\"29043.90\",\"1.806\"],[\"29143.90\",\"0.245\"],[\"29443.90\",\"0.049\"],[\"71589.50\",\"0.006\"],[\"76362.10\",\"0.000\"],[\"78748.50\",\"3.170\"],[\"79453.10\",\"0.020\"],[\"79454.40\",\"0.094\"],[\"79456.40\",\"0.226\"],[\"79476.70\",\"0.060\"],[\"79485.50\",\"0.000\"],[\"79486.80\",\"0.612\"],[\"79504.70\",\"0.001\"],[\"79508.90\",\"0.000\"],[\"79514.00\",\"0.629\"],[\"79514.10\",\"0.140\"],[\"79514.70\",\"0.016\"],[\"79524.90\",\"0.111\"],[\"79525.70\",\"0.003\"]],\"a\":[[\"79544.00\",\"5.904\"],[\"79550.40\",\"0.077\"],[\"79550.60\",\"0.000\"],[\"79550.90\",\"0.011\"],[\"79551.80\",\"0.454\"],[\"79563.90\",\"0.002\"],[\"79564.40\",\"0.530\"],[\"79564.90\",\"0.002\"],[\"79588.70\",\"0.082\"],[\"79590.00\",\"0.130\"],[\"79620.00\",\"16.148\"],[\"79623.00\",\"0.009\"],[\"79624.40\",\"0.001\"],[\"79624.50\",\"0.004\"],[\"79625.10\",\"0.000\"],[\"79625.20\",\"0.005\"],[\"79625.30\",\"0.001\"],[\"79628.30\",\"30.572\"],[\"79635.80\",\"0.000\"],[\"79635.90\",\"4.527\"],[\"79639.50\",\"0.000\"],[\"79639.60\",\"0.000\"],[\"79639.70\",\"0.004\"],[\"79640.50\",\"0.001\"],[\"79640.60\",\"0.000\"],[\"79640.70\",\"0.001\"],[\"79668.10\",\"0.007\"],[\"79690.40\",\"0.006\"],[\"79693.60\",\"0.000\"],[\"79753.30\",\"0.000\"],[\"79753.40\",\"0.037\"],[\"79936.40\",\"0.508\"],[\"79937.70\",\"0.041\"],[\"79939.70\",\"0.136\"],[\"80339.40\",\"1.429\"],[\"80538.30\",\"2.641\"]],\"st\":1}}"}
{"receive_ns":1788580697160438000,"stream":"btcusdt@bookTicker","event_type":"bookTicker","event_time_ms":1788580697211,"raw_json":"{\"stream\":\"btcusdt@bookTicker\",\"data\":{\"e\":\"bookTicker\",\"u\":11479472572760,\"s\":\"BTCUSDT\",\"ps\":\"BTCUSDT\",\"b\":\"79543.90\",\"B\":\"5.084\",\"a\":\"79544.00\",\"A\":\"5.904\",\"T\":1788580697210,\"E\":1788580697211,\"st\":1}}"}
{"receive_ns":1788580697160596000,"stream":"btcusdt@bookTicker","event_type":"bookTicker","event_time_ms":1788580697213,"raw_json":"{\"stream\":\"btcusdt@bookTicker\",\"data\":{\"e\":\"bookTicker\",\"u\":11479472572947,\"s\":\"BTCUSDT\",\"ps\":\"BTCUSDT\",\"b\":\"79543.90\",\"B\":\"5.264\",\"a\":\"79544.00\",\"A\":\"5.904\",\"T\":1788580697213,\"E\":1788580697213,\"st\":1}}"}
{"receive_ns":1788580697160783000,"stream":"btcusdt@bookTicker","event_type":"bookTicker","event_time_ms":1788580697214,"raw_json":"{\"stream\":\"btcusdt@bookTicker\",\"data\":{\"e\":\"bookTicker\",\"u\":11479472572987,\"s\":\"BTCUSDT\",\"ps\":\"BTCUSDT\",\"b\":\"79543.90\",\"B\":\"5.263\",\"a\":\"79544.00\",\"A\":\"5.904\",\"T\":1788580697214,\"E\":1788580697214,\"st\":1}}"}
{"receive_ns":1788580697161028000,"stream":"btcusdt@bookTicker","event_type":"bookTicker","event_time_ms":1788580697215,"raw_json":"{\"stream\":\"btcusdt@bookTicker\",\"data\":{\"e\":\"bookTicker\",\"u\":11479472572989,\"s\":\"BTCUSDT\",\"ps\":\"BTCUSDT\",\"b\":\"79543.90\",\"B\":\"5.263\",\"a\":\"79544.00\",\"A\":\"5.906\",\"T\":1788580697214,\"E\":1788580697215,\"st\":1}}"}
{"receive_ns":1788580697167579000,"stream":"btcusdt@bookTicker","event_type":"bookTicker","event_time_ms":1788580697215,"raw_json":"{\"stream\":\"btcusdt@bookTicker\",\"data\":{\"e\":\"bookTicker\",\"u\":11479472573027,\"s\":\"BTCUSDT\",\"ps\":\"BTCUSDT\",\"b\":\"79543.90\",\"B\":\"5.264\",\"a\":\"79544.00\",\"A\":\"5.906\",\"T\":1788580697215,\"E\":1788580697215,\"st\":1}}"}
{"receive_ns":1788580697283676000,"stream":"btcusdt@bookTicker","event_type":"bookTicker","event_time_ms":1788580697276,"raw_json":"{\"stream\":\"btcusdt@bookTicker\",\"data\":{\"e\":\"bookTicker\",\"u\":11479472576663,\"s\":\"BTCUSDT\",\"ps\":\"BTCUSDT\",\"b\":\"79543.90\",\"B\":\"5.263\",\"a\":\"79544.00\",\"A\":\"5.906\",\"T\":1788580697276,\"E\":1788580697276,\"st\":1}}"}
{"receive_ns":1788580697283935000,"stream":"btcusdt@bookTicker","event_type":"bookTicker","event_time_ms":1788580697278,"raw_json":"{\"stream\":\"btcusdt@bookTicker\",\"data\":{\"e\":\"bookTicker\",\"u\":11479472576755,\"s\":\"BTCUSDT\",\"ps\":\"BTCUSDT\",\"b\":\"79543.90\",\"B\":\"5.264\",\"a\":\"79544.00\",\"A\":\"5.906\",\"T\":1788580697278,\"E\":1788580697278,\"st\":1}}"}
{"receive_ns":1788580697284128000,"stream":"btcusdt@bookTicker","event_type":"bookTicker","event_time_ms":1788580697285,"raw_json":"{\"stream\":\"btcusdt@bookTicker\",\"data\":{\"e\":\"bookTicker\",\"u\":11479472577176,\"s\":\"BTCUSDT\",\"ps\":\"BTCUSDT\",\"b\":\"79543.90\",\"B\":\"5.264\",\"a\":\"79544.00\",\"A\":\"5.883\",\"T\":1788580697285,\"E\":1788580697285,\"st\":1}}"}
{"receive_ns":1788580697284289000,"stream":"btcusdt@bookTicker","event_type":"bookTicker","event_time_ms":1788580697289,"raw_json":"{\"stream\":\"btcusdt@bookTicker\",\"data\":{\"e\":\"bookTicker\",\"u\":11479472577330,\"s\":\"BTCUSDT\",\"ps\":\"BTCUSDT\",\"b\":\"79543.90\",\"B\":\"5.264\",\"a\":\"79544.00\",\"A\":\"5.907\",\"T\":1788580697288,\"E\":1788580697289,\"st\":1}}"}
{"receive_ns":1788580697284992000,"stream":"btcusdt@bookTicker","event_type":"bookTicker","event_time_ms":1788580697298,"raw_json":"{\"stream\":\"btcusdt@bookTicker\",\"data\":{\"e\":\"bookTicker\",\"u\":11479472577798,\"s\":\"BTCUSDT\",\"ps\":\"BTCUSDT\",\"b\":\"79543.90\",\"B\":\"5.264\",\"a\":\"79544.00\",\"A\":\"5.890\",\"T\":1788580697298,\"E\":1788580697298,\"st\":1}}"}
{"receive_ns":1788580697285244000,"stream":"btcusdt@bookTicker","event_type":"bookTicker","event_time_ms":1788580697301,"raw_json":"{\"stream\":\"btcusdt@bookTicker\",\"data\":{\"e\":\"bookTicker\",\"u\":11479472577925,\"s\":\"BTCUSDT\",\"ps\":\"BTCUSDT\",\"b\":\"79543.90\",\"B\":\"5.264\",\"a\":\"79544.00\",\"A\":\"5.903\",\"T\":1788580697301,\"E\":1788580697301,\"st\":1}}"}
{"receive_ns":1788580697285812000,"stream":"btcusdt@depth@100ms","event_type":"depthUpdate","event_time_ms":1788580697309,"raw_json":"{\"stream\":\"btcusdt@depth@100ms\",\"data\":{\"e\":\"depthUpdate\",\"E\":1788580697309,\"T\":1788580697306,\"s\":\"BTCUSDT\",\"ps\":\"BTCUSDT\",\"U\":11479472572591,\"u\":11479472578132,\"pu\":11479472572528,\"b\":[[\"29043.90\",\"1.855\"],[\"29143.90\",\"0.133\"],[\"29443.90\",\"0.112\"],[\"71589.50\",\"0.006\"],[\"76362.10\",\"0.002\"],[\"78213.00\",\"2.367\"],[\"78454.10\",\"0.514\"],[\"78748.50\",\"3.170\"],[\"78980.90\",\"0.095\"],[\"78981.70\",\"0.095\"],[\"79454.40\",\"0.044\"],[\"79474.60\",\"0.001\"],[\"79477.20\",\"23.039\"],[\"79498.90\",\"0.000\"],[\"79527.60\",\"0.004\"],[\"79532.90\",\"0.024\"],[\"79543.90\",\"5.264\"]],\"a\":[[\"79544.00\",\"5.903\"],[\"79558.90\",\"0.035\"],[\"79561.10\",\"0.002\"],[\"79567.80\",\"0.002\"],[\"79572.80\",\"2.001\"],[\"79573.70\",\"1.024\"],[\"79577.50\",\"0.266\"],[\"79577.60\",\"0.086\"],[\"79620.20\",\"30.562\"],[\"79628.30\",\"0.000\"],[\"79661.80\",\"0.000\"],[\"79668.10\",\"0.013\"],[\"79696.80\",\"1.704\"],[\"79933.80\",\"0.000\"],[\"79939.70\",\"0.122\"],[\"80339.40\",\"1.429\"],[\"80419.00\",\"2.173\"],[\"80493.20\",\"18.985\"],[\"80590.90\",\"2.243\"]],\"st\":1}}"}
{"receive_ns":1788580697340477000,"stream":"btcusdt@bookTicker","event_type":"bookTicker","event_time_ms":1788580697377,"raw_json":"{\"stream\":\"btcusdt@bookTicker\",\"data\":{\"e\":\"bookTicker\",\"u\":11479472581522,\"s\":\"BTCUSDT\",\"ps\":\"BTCUSDT\",\"b\":\"79543.90\",\"B\":\"5.190\",\"a\":\"79544.00\",\"A\":\"5.903\",\"T\":1788580697377,\"E\":1788580697377,\"st\":1}}"}
{"receive_ns":1788580697340694000,"stream":"btcusdt@bookTicker","event_type":"bookTicker","event_time_ms":1788580697381,"raw_json":"{\"stream\":\"btcusdt@bookTicker\",\"data\":{\"e\":\"bookTicker\",\"u\":11479472581647,\"s\":\"BTCUSDT\",\"ps\":\"BTCUSDT\",\"b\":\"79543.90\",\"B\":\"5.267\",\"a\":\"79544.00\",\"A\":\"5.903\",\"T\":1788580697380,\"E\":1788580697381,\"st\":1}}"}
{"receive_ns":1788580697396908000,"stream":"btcusdt@depth@100ms","event_type":"depthUpdate","event_time_ms":1788580697411,"raw_json":"{\"stream\":\"btcusdt@depth@100ms\",\"data\":{\"e\":\"depthUpdate\",\"E\":1788580697411,\"T\":1788580697409,\"s\":\"BTCUSDT\",\"ps\":\"BTCUSDT\",\"U\":11479472578292,\"u\":11479472582858,\"pu\":11479472578132,\"b\":[[\"29043.90\",\"1.911\"],[\"29143.90\",\"0.014\"],[\"29443.90\",\"0.175\"],[\"71589.50\",\"0.006\"],[\"76362.10\",\"0.000\"],[\"78601.80\",\"13.003\"],[\"78748.50\",\"3.170\"],[\"79146.20\",\"3.025\"],[\"79453.10\",\"0.020\"],[\"79454.40\",\"0.034\"],[\"79456.40\",\"0.198\"],[\"79474.60\",\"23.013\"],[\"79477.20\",\"0.027\"],[\"79482.30\",\"0.103\"],[\"79517.30\",\"0.454\"],[\"79518.30\",\"0.138\"],[\"79518.80\",\"0.002\"],[\"79524.10\",\"0.282\"],[\"79525.20\",\"0.373\"],[\"79526.90\",\"0.001\"],[\"79527.80\",\"0.145\"],[\"79528.40\",\"0.617\"],[\"79529.30\",\"1.054\"],[\"79529.50\",\"0.003\"],[\"79533.50\",\"0.001\"],[\"79543.90\",\"5.267\"]],\"a\":[[\"79564.00\",\"1.191\"],[\"79564.40\",\"0.091\"],[\"79564.90\",\"0.441\"],[\"79565.20\",\"1.051\"],[\"79565.50\",\"0.118\"],[\"79567.00\",\"0.003\"],[\"79568.20\",\"0.453\"],[\"79569.10\",\"0.252\"],[\"79588.70\",\"0.036\"],[\"79589.50\",\"0.429\"],[\"79635.90\",\"4.528\"],[\"79699.10\",\"0.485\"],[\"79933.80\",\"0.037\"],[\"79936.40\",\"0.508\"],[\"79937.70\",\"0.022\"],[\"79939.70\",\"0.131\"],[\"80339.40\",\"1.429\"]],\"st\":1}}"}
{"receive_ns":1788580697461761000,"stream":"btcusdt@bookTicker","event_type":"bookTicker","event_time_ms":1788580697483,"raw_json":"{\"stream\":\"btcusdt@bookTicker\",\"data\":{\"e\":\"bookTicker\",\"u\":11479472587278,\"s\":\"BTCUSDT\",\"ps\":\"BTCUSDT\",\"b\":\"79543.90\",\"B\":\"5.211\",\"a\":\"79544.00\",\"A\":\"5.903\",\"T\":1788580697483,\"E\":1788580697483,\"st\":1}}"}
{"receive_ns":1788580697464125000,"stream":"btcusdt@depth@100ms","event_type":"depthUpdate","event_time_ms":1788580697513,"raw_json":"{\"stream\":\"btcusdt@depth@100ms\",\"data\":{\"e\":\"depthUpdate\",\"E\":1788580697513,\"T\":1788580697512,\"s\":\"BTCUSDT\",\"ps\":\"BTCUSDT\",\"U\":11479472582927,\"u\":11479472589231,\"pu\":11479472582858,\"b\":[[\"1000.00\",\"25.354\"],[\"29043.90\",\"1.764\"],[\"29143.90\",\"0.000\"],[\"29443.90\",\"0.336\"],[\"71589.50\",\"0.006\"],[\"77328.90\",\"0.258\"],[\"78450.60\",\"2.544\"],[\"78748.50\",\"3.170\"],[\"78902.30\",\"2.023\"],[\"79524.30\",\"0.378\"],[\"79525.20\",\"0.000\"],[\"79527.80\",\"0.585\"],[\"79528.40\",\"0.177\"],[\"79539.70\",\"1.948\"],[\"79543.90\",\"5.211\"]],\"a\":[[\"79545.10\",\"0.002\"],[\"79549.20\",\"0.446\"],[\"79563.90\",\"0.441\"],[\"79564.10\",\"0.824\"],[\"79564.90\",\"0.002\"],[\"79565.20\",\"0.678\"],[\"79568.00\",\"0.705\"],[\"80339.40\",\"1.429\"],[\"80498.50\",\"17.115\"],[\"81134.80\",\"0.015\"]],\"st\":1}}"}
{"receive_ns":1788580697474735000,"stream":"btcusdt@bookTicker","event_type":"bookTicker","event_time_ms":1788580697529,"raw_json":"{\"stream\":\"btcusdt@bookTicker\",\"data\":{\"e\":\"bookTicker\",\"u\":11479472590131,\"s\":\"BTCUSDT\",\"ps\":\"BTCUSDT\",\"b\":\"79543.90\",\"B\":\"5.206\",\"a\":\"79544.00\",\"A\":\"5.903\",\"T\":1788580697529,\"E\":1788580697529,\"st\":1}}"}
{"receive_ns":1788580697482047000,"stream":"btcusdt@bookTicker","event_type":"bookTicker","event_time_ms":1788580697532,"raw_json":"{\"stream\":\"btcusdt@bookTicker\",\"data\":{\"e\":\"bookTicker\",\"u\":11479472590241,\"s\":\"BTCUSDT\",\"ps\":\"BTCUSDT\",\"b\":\"79543.90\",\"B\":\"5.208\",\"a\":\"79544.00\",\"A\":\"5.903\",\"T\":1788580697532,\"E\":1788580697532,\"st\":1}}"}
{"receive_ns":1788580697515318000,"stream":"btcusdt@bookTicker","event_type":"bookTicker","event_time_ms":1788580697558,"raw_json":"{\"stream\":\"btcusdt@bookTicker\",\"data\":{\"e\":\"bookTicker\",\"u\":11479472591495,\"s\":\"BTCUSDT\",\"ps\":\"BTCUSDT\",\"b\":\"79543.90\",\"B\":\"5.208\",\"a\":\"79544.00\",\"A\":\"5.906\",\"T\":1788580697558,\"E\":1788580697558,\"st\":1}}"}
{"receive_ns":1788580697579848000,"stream":"btcusdt@bookTicker","event_type":"bookTicker","event_time_ms":1788580697612,"raw_json":"{\"stream\":\"btcusdt@bookTicker\",\"data\":{\"e\":\"bookTicker\",\"u\":11479472594797,\"s\":\"BTCUSDT\",\"ps\":\"BTCUSDT\",\"b\":\"79543.90\",\"B\":\"5.223\",\"a\":\"79544.00\",\"A\":\"5.906\",\"T\":1788580697612,\"E\":1788580697612,\"st\":1}}"}
{"receive_ns":1788580697580282000,"stream":"btcusdt@depth@100ms","event_type":"depthUpdate","event_time_ms":1788580697615,"raw_json":"{\"stream\":\"btcusdt@depth@100ms\",\"data\":{\"e\":\"depthUpdate\",\"E\":1788580697615,\"T\":1788580697614,\"s\":\"BTCUSDT\",\"ps\":\"BTCUSDT\",\"U\":11479472589326,\"u\":11479472594961,\"pu\":11479472589231,\"b\":[[\"29043.90\",\"1.582\"],[\"29443.90\",\"0.518\"],[\"63635.00\",\"0.002\"],[\"71589.50\",\"0.006\"],[\"76362.10\",\"0.002\"],[\"78748.50\",\"3.170\"],[\"79453.10\",\"0.000\"],[\"79454.40\",\"0.027\"],[\"79456.40\",\"0.025\"],[\"79482.30\",\"0.040\"],[\"79524.30\",\"0.005\"],[\"79525.40\",\"0.419\"],[\"79539.70\",\"1.949\"],[\"79539.90\",\"0.109\"],[\"79541.80\",\"0.003\"],[\"79543.90\",\"5.223\"]],\"a\":[[\"79544.00\",\"5.906\"],[\"79548.20\",\"0.024\"],[\"79554.10\",\"0.060\"],[\"79554.20\",\"0.258\"],[\"79563.90\",\"0.002\"],[\"79564.10\",\"0.451\"],[\"79564.90\",\"0.441\"],[\"79565.30\",\"0.375\"],[\"79567.00\",\"0.703\"],[\"79568.00\",\"0.005\"],[\"79568.40\",\"3.029\"],[\"79699.10\",\"0.480\"],[\"79933.80\",\"0.000\"],[\"79936.40\",\"0.501\"],[\"79937.70\",\"0.022\"],[\"79939.70\",\"0.077\"],[\"79956.10\",\"0.000\"],[\"79958.20\",\"0.087\"],[\"80339.40\",\"1.429\"]],\"st\":1}}"}
{"receive_ns":1788580697660387000,"stream":"btcusdt@depth@100ms","event_type":"depthUpdate","event_time_ms":1788580697717,"raw_json":"{\"stream\":\"btcusdt@depth@100ms\",\"data\":{\"e\":\"depthUpdate\",\"E\":1788580697717,\"T\":1788580697715,\"s\":\"BTCUSDT\",\"ps\":\"BTCUSDT\",\"U\":11479472594986,\"u\":11479472599049,\"pu\":11479472594961,\"b\":[[\"29043.90\",\"1.407\"],[\"29443.90\",\"0.693\"],[\"63635.00\",\"0.000\"],[\"71589.50\",\"0.006\"],[\"71623.00\",\"0.003\"],[\"75566.70\",\"0.009\"],[\"75566.80\",\"0.008\"],[\"76362.10\",\"0.000\"],[\"78491.50\",\"0.700\"],[\"78748.50\",\"3.170\"],[\"79146.20\",\"3.035\"],[\"79452.90\",\"0.010\"],[\"79456.40\",\"0.032\"],[\"79474.60\",\"0.001\"],[\"79477.20\",\"23.039\"],[\"79480.30\",\"0.569\"],[\"79480.70\",\"0.003\"],[\"79480.90\",\"0.001\"],[\"79482.00\",\"1.013\"],[\"79500.60\",\"0.165\"],[\"79534.00\",\"0.004\"],[\"79539.70\",\"1.944\"],[\"79539.80\",\"0.000\"],[\"79539.90\",\"0.197\"],[\"79540.00\",\"0.013\"]],\"a\":[[\"79586.40\",\"0.001\"],[\"79606.30\",\"0.000\"],[\"79634.10\",\"0.000\"],[\"79901.20\",\"0.082\"],[\"79935.80\",\"0.058\"],[\"79936.40\",\"0.508\"],[\"79939.70\",\"0.136\"],[\"80339.40\",\"1.431\"],[\"81134.80\",\"0.018\"]],\"st\":1}}"}
{"receive_ns":1788580697707784000,"stream":"btcusdt@bookTicker","event_type":"bookTicker","event_time_ms":1788580697755,"raw_json":"{\"stream\":\"btcusdt@bookTicker\",\"data\":{\"e\":\"bookTicker\",\"u\":11479472600399,\"s\":\"BTCUSDT\",\"ps\":\"BTCUSDT\",\"b\":\"79543.90\",\"B\":\"5.223\",\"a\":\"79544.00\",\"A\":\"5.316\",\"T\":1788580697755,\"E\":1788580697755,\"st\":1}}"}
{"receive_ns":1788580697724090000,"stream":"btcusdt@bookTicker","event_type":"bookTicker","event_time_ms":1788580697780,"raw_json":"{\"stream\":\"btcusdt@bookTicker\",\"data\":{\"e\":\"bookTicker\",\"u\":11479472601316,\"s\":\"BTCUSDT\",\"ps\":\"BTCUSDT\",\"b\":\"79543.90\",\"B\":\"6.460\",\"a\":\"79544.00\",\"A\":\"5.316\",\"T\":1788580697780,\"E\":1788580697780,\"st\":1}}"}
{"receive_ns":1788580697726197000,"stream":"btcusdt@bookTicker","event_type":"bookTicker","event_time_ms":1788580697782,"raw_json":"{\"stream\":\"btcusdt@bookTicker\",\"data\":{\"e\":\"bookTicker\",\"u\":11479472601486,\"s\":\"BTCUSDT\",\"ps\":\"BTCUSDT\",\"b\":\"79543.90\",\"B\":\"6.459\",\"a\":\"79544.00\",\"A\":\"5.316\",\"T\":1788580697781,\"E\":1788580697782,\"st\":1}}"}
{"receive_ns":1788580697760436000,"stream":"btcusdt@bookTicker","event_type":"bookTicker","event_time_ms":1788580697809,"raw_json":"{\"stream\":\"btcusdt@bookTicker\",\"data\":{\"e\":\"bookTicker\",\"u\":11479472602742,\"s\":\"BTCUSDT\",\"ps\":\"BTCUSDT\",\"b\":\"79543.90\",\"B\":\"6.458\",\"a\":\"79544.00\",\"A\":\"5.316\",\"T\":1788580697809,\"E\":1788580697809,\"st\":1}}"}
{"receive_ns":1788580697760693000,"stream":"btcusdt@bookTicker","event_type":"bookTicker","event_time_ms":1788580697811,"raw_json":"{\"stream\":\"btcusdt@bookTicker\",\"data\":{\"e\":\"bookTicker\",\"u\":11479472602864,\"s\":\"BTCUSDT\",\"ps\":\"BTCUSDT\",\"b\":\"79543.90\",\"B\":\"6.459\",\"a\":\"79544.00\",\"A\":\"5.316\",\"T\":1788580697811,\"E\":1788580697811,\"st\":1}}"}
{"receive_ns":1788580697763718000,"stream":"btcusdt@depth@100ms","event_type":"depthUpdate","event_time_ms":1788580697819,"raw_json":"{\"stream\":\"btcusdt@depth@100ms\",\"data\":{\"e\":\"depthUpdate\",\"E\":1788580697819,\"T\":1788580697817,\"s\":\"BTCUSDT\",\"ps\":\"BTCUSDT\",\"U\":11479472599097,\"u\":11479472603134,\"pu\":11479472599049,\"b\":[[\"1000.00\",\"25.354\"],[\"29043.90\",\"1.225\"],[\"29443.90\",\"0.875\"],[\"71589.50\",\"0.006\"],[\"71623.00\",\"0.000\"],[\"75566.80\",\"0.006\"],[\"76362.10\",\"0.002\"],[\"78438.20\",\"2.774\"],[\"78748.50\",\"3.170\"],[\"78907.50\",\"4.932\"],[\"79411.50\",\"0.007\"],[\"79413.20\",\"1.168\"],[\"79413.30\",\"0.000\"],[\"79415.00\",\"1.696\"],[\"79419.00\",\"0.001\"],[\"79419.10\",\"0.373\"],[\"79454.40\",\"0.002\"],[\"79456.40\",\"0.007\"],[\"79475.00\",\"0.501\"],[\"79482.30\",\"0.015\"],[\"79527.80\",\"0.145\"],[\"79528.40\",\"0.617\"],[\"79529.10\",\"0.229\"],[\"79539.60\",\"1.372\"],[\"79539.70\",\"1.944\"],[\"79539.80\",\"0.008\"],[\"79539.90\",\"0.109\"],[\"79540.00\",\"0.005\"],[\"79543.80\",\"0.086\"],[\"79543.90\",\"6.459\"]],\"a\":[[\"79544.00\",\"5.316\"],[\"79545.10\",\"0.000\"],[\"79547.50\",\"0.003\"],[\"79548.70\",\"0.000\"],[\"79550.90\",\"0.009\"],[\"79551.50\",\"0.511\"],[\"79554.90\",\"0.076\"],[\"79557.80\",\"0.001\"],[\"79573.70\",\"0.194\"],[\"79584.50\",\"4.524\"],[\"79616.70\",\"3.190\"],[\"79617.60\",\"30.556\"],[\"79617.80\",\"0.000\"],[\"79620.20\",\"0.008\"],[\"79666.40\",\"0.368\"],[\"79672.60\",\"1.106\"],[\"79673.90\",\"0.040\"],[\"79936.40\",\"0.501\"],[\"79937.70\",\"0.004\"],[\"79939.70\",\"0.059\"],[\"80339.40\",\"1.429\"],[\"80339.50\",\"0.001\"]],\"st\":1}}"}
{"receive_ns":1788580697768567000,"stream":"btcusdt@bookTicker","event_type":"bookTicker","event_time_ms":1788580697823,"raw_json":"{\"stream\":\"btcusdt@bookTicker\",\"data\":{\"e\":\"bookTicker\",\"u\":11479472603675,\"s\":\"BTCUSDT\",\"ps\":\"BTCUSDT\",\"b\":\"79543.90\",\"B\":\"6.459\",\"a\":\"79544.00\",\"A\":\"5.313\",\"T\":1788580697823,\"E\":1788580697823,\"st\":1}}"}
{"receive_ns":1788580697880564000,"stream":"btcusdt@depth@100ms","event_type":"depthUpdate","event_time_ms":1788580697921,"raw_json":"{\"stream\":\"btcusdt@depth@100ms\",\"data\":{\"e\":\"depthUpdate\",\"E\":1788580697921,\"T\":1788580697919,\"s\":\"BTCUSDT\",\"ps\":\"BTCUSDT\",\"U\":11479472603437,\"u\":11479472608447,\"pu\":11479472603134,\"b\":[[\"29043.90\",\"1.050\"],[\"29443.90\",\"1.050\"],[\"63635.00\",\"0.000\"],[\"71589.50\",\"0.006\"],[\"77868.30\",\"1.924\"],[\"78663.60\",\"0.190\"],[\"78748.50\",\"3.170\"],[\"78947.30\",\"1.899\"],[\"79146.10\",\"0.009\"],[\"79454.90\",\"6.000\"],[\"79456.40\",\"0.117\"],[\"79474.60\",\"23.013\"],[\"79477.20\",\"0.027\"],[\"79480.30\",\"0.534\"],[\"79482.70\",\"3.501\"],[\"79482.90\",\"0.606\"],[\"79502.60\",\"0.568\"],[\"79520.20\",\"2.393\"],[\"79531.60\",\"0.251\"],[\"79532.10\",\"0.080\"],[\"79532.90\",\"0.193\"],[\"79539.70\",\"1.944\"],[\"79539.90\",\"0.110\"]],\"a\":[[\"79544.00\",\"5.313\"],[\"79550.40\",\"0.073\"],[\"79550.60\",\"0.004\"],[\"79560.10\",\"0.002\"],[\"79587.10\",\"0.570\"],[\"79607.00\",\"4.285\"],[\"79617.30\",\"0.001\"],[\"79617.60\",\"0.002\"],[\"79617.80\",\"0.125\"],[\"79620.20\",\"30.562\"],[\"79634.90\",\"6.000\"],[\"79933.80\",\"0.005\"],[\"79935.80\",\"0.021\"],[\"79936.40\",\"0.508\"],[\"79939.70\",\"0.186\"],[\"79941.80\",\"0.001\"],[\"80339.40\",\"1.429\"],[\"80551.10\",\"7.251\"],[\"80657.60\",\"15.670\"]],\"st\":1}}"}
{"receive_ns":1788580697967330000,"stream":"btcusdt@depth@100ms","event_type":"depthUpdate","event_time_ms":1788580698023,"raw_json":"{\"stream\":\"btcusdt@depth@100ms\",\"data\":{\"e\":\"depthUpdate\",\"E\":1788580698023,\"T\":1788580698022,\"s\":\"BTCUSDT\",\"ps\":\"BTCUSDT\",\"U\":11479472608477,\"u\":11479472614179,\"pu\":11479472608447,\"b\":[[\"29043.90\",\"0.868\"],[\"29443.90\",\"1.232\"],[\"63635.00\",\"0.000\"],[\"63635.10\",\"0.000\"],[\"71589.50\",\"0.006\"],[\"76362.10\",\"0.000\"],[\"78412.80\",\"1.784\"],[\"78584.10\",\"27.993\"],[\"78748.50\",\"3.170\"],[\"78833.40\",\"0.000\"],[\"78980.90\",\"0.190\"],[\"79146.20\",\"3.025\"],[\"79415.20\",\"10.000\"],[\"79419.10\",\"0.435\"],[\"79457.90\",\"0.053\"],[\"79520.20\",\"2.395\"],[\"79524.40\",\"0.002\"],[\"79525.40\",\"0.046\"],[\"79525.50\",\"0.374\"],[\"79527.80\",\"0.145\"],[\"79528.40\",\"0.177\"],[\"79529.10\",\"0.669\"],[\"79539.90\",\"0.109\"]],\"a\":[[\"79550.40\",\"0.033\"],[\"79550.60\",\"0.000\"],[\"79560.10\",\"0.004\"],[\"79575.80\",\"0.276\"],[\"79666.40\",\"0.411\"],[\"79674.70\",\"10.000\"],[\"80339.40\",\"1.429\"],[\"80909.10\",\"3.493\"],[\"81134.80\",\"0.015\"]],\"st\":1}}"}
{"receive_ns":1788580698015027000,"stream":"btcusdt@bookTicker","event_type":"bookTicker","event_time_ms":1788580698065,"raw_json":"{\"stream\":\"btcusdt@bookTicker\",\"data\":{\"e\":\"bookTicker\",\"u\":11479472616580,\"s\":\"BTCUSDT\",\"ps\":\"BTCUSDT\",\"b\":\"79543.90\",\"B\":\"6.459\",\"a\":\"79544.00\",\"A\":\"5.067\",\"T\":1788580698065,\"E\":1788580698065,\"st\":1}}"}
{"receive_ns":1788580698015229000,"stream":"btcusdt@bookTicker","event_type":"bookTicker","event_time_ms":1788580698066,"raw_json":"{\"stream\":\"btcusdt@bookTicker\",\"data\":{\"e\":\"bookTicker\",\"u\":11479472616686,\"s\":\"BTCUSDT\",\"ps\":\"BTCUSDT\",\"b\":\"79543.90\",\"B\":\"6.460\",\"a\":\"79544.00\",\"A\":\"5.067\",\"T\":1788580698066,\"E\":1788580698066,\"st\":1}}"}
{"receive_ns":1788580698081801000,"stream":"btcusdt@depth@100ms","event_type":"depthUpdate","event_time_ms":1788580698125,"raw_json":"{\"stream\":\"btcusdt@depth@100ms\",\"data\":{\"e\":\"depthUpdate\",\"E\":1788580698125,\"T\":1788580698122,\"s\":\"BTCUSDT\",\"ps\":\"BTCUSDT\",\"U\":11479472614207,\"u\":11479472619530,\"pu\":11479472614179,\"b\":[[\"1000.00\",\"25.354\"],[\"29043.90\",\"0.693\"],[\"29443.90\",\"1.407\"],[\"63635.00\",\"0.000\"],[\"71589.50\",\"0.006\"],[\"76362.10\",\"0.002\"],[\"78668.90\",\"1.140\"],[\"78748.50\",\"3.170\"],[\"79397.80\",\"0.004\"],[\"79399.80\",\"1.891\"],[\"79411.50\",\"0.001\"],[\"79415.00\",\"0.133\"],[\"79415.30\",\"3.490\"],[\"79456.40\",\"0.075\"],[\"79480.30\",\"0.509\"],[\"79482.90\",\"0.586\"],[\"79499.30\",\"0.002\"],[\"79499.50\",\"0.002\"],[\"79528.40\",\"0.617\"],[\"79529.10\",\"0.229\"],[\"79529.60\",\"0.002\"],[\"79531.60\",\"0.254\"],[\"79539.90\",\"0.021\"],[\"79543.90\",\"6.460\"]],\"a\":[[\"79544.00\",\"5.067\"],[\"79554.10\",\"0.058\"],[\"79554.20\",\"0.256\"],[\"79572.80\",\"0.001\"],[\"79605.20\",\"3.403\"],[\"79605.30\",\"0.039\"],[\"79615.90\",\"0.001\"],[\"79617.80\",\"0.000\"],[\"79625.20\",\"0.004\"],[\"79625.30\",\"0.000\"],[\"79625.50\",\"0.003\"],[\"79639.70\",\"0.000\"],[\"79640.00\",\"3.640\"],[\"79668.40\",\"1.901\"],[\"79672.60\",\"2.456\"],[\"79933.80\",\"0.000\"],[\"79936.40\",\"0.501\"],[\"79939.70\",\"0.046\"],[\"80339.40\",\"1.429\"]],\"st\":1}}"}
{"receive_ns":1788580698137812000,"stream":"btcusdt@bookTicker","event_type":"bookTicker","event_time_ms":1788580698169,"raw_json":"{\"stream\":\"btcusdt@bookTicker\",\"data\":{\"e\":\"bookTicker\",\"u\":11479472622496,\"s\":\"BTCUSDT\",\"ps\":\"BTCUSDT\",\"b\":\"79543.90\",\"B\":\"6.460\",\"a\":\"79544.00\",\"A\":\"5.056\",\"T\":1788580698169,\"E\":1788580698169,\"st\":1}}"}
{"receive_ns":1788580698138031000,"stream":"btcusdt@trade","event_type":"trade","event_time_ms":1788580698169,"raw_json":"{\"stream\":\"btcusdt@trade\",\"data\":{\"e\":\"trade\",\"E\":1788580698169,\"T\":1788580698169,\"s\":\"BTCUSDT\",\"t\":8054266634,\"p\":\"79544.00\",\"q\":\"0.011\",\"X\":\"MARKET\",\"m\":false,\"st\":1}}"}
{"receive_ns":1788580698138223000,"stream":"btcusdt@bookTicker","event_type":"bookTicker","event_time_ms":1788580698171,"raw_json":"{\"stream\":\"btcusdt@bookTicker\",\"data\":{\"e\":\"bookTicker\",\"u\":11479472622718,\"s\":\"BTCUSDT\",\"ps\":\"BTCUSDT\",\"b\":\"79543.90\",\"B\":\"6.459\",\"a\":\"79544.00\",\"A\":\"5.056\",\"T\":1788580698171,\"E\":1788580698171,\"st\":1}}"}
{"receive_ns":1788580698138360000,"stream":"btcusdt@bookTicker","event_type":"bookTicker","event_time_ms":1788580698171,"raw_json":"{\"stream\":\"btcusdt@bookTicker\",\"data\":{\"e\":\"bookTicker\",\"u\":11479472622722,\"s\":\"BTCUSDT\",\"ps\":\"BTCUSDT\",\"b\":\"79543.90\",\"B\":\"6.459\",\"a\":\"79544.00\",\"A\":\"5.033\",\"T\":1788580698171,\"E\":1788580698171,\"st\":1}}"}
{"receive_ns":1788580698250785000,"stream":"btcusdt@depth@100ms","event_type":"depthUpdate","event_time_ms":1788580698227,"raw_json":"{\"stream\":\"btcusdt@depth@100ms\",\"data\":{\"e\":\"depthUpdate\",\"E\":1788580698227,\"T\":1788580698226,\"s\":\"BTCUSDT\",\"ps\":\"BTCUSDT\",\"U\":11479472619722,\"u\":11479472625264,\"pu\":11479472619530,\"b\":[[\"29043.90\",\"0.511\"],[\"29443.90\",\"1.589\"],[\"71589.50\",\"0.006\"],[\"76362.10\",\"0.000\"],[\"78452.60\",\"15.279\"],[\"78509.50\",\"0.903\"],[\"78748.50\",\"3.170\"],[\"79456.40\",\"0.082\"],[\"79476.00\",\"4.385\"],[\"79480.30\",\"0.745\"],[\"79482.90\",\"0.606\"],[\"79487.00\",\"1.399\"],[\"79502.50\",\"0.001\"],[\"79502.90\",\"0.692\"],[\"79543.90\",\"6.459\"]],\"a\":[[\"79544.00\",\"5.033\"],[\"79544.40\",\"0.002\"],[\"79546.10\",\"0.002\"],[\"79546.90\",\"0.004\"],[\"79557.80\",\"0.692\"],[\"79573.70\",\"1.024\"],[\"79576.20\",\"3.236\"],[\"79576.50\",\"12.321\"],[\"79616.10\",\"0.407\"],[\"79618.70\",\"0.125\"],[\"79620.00\",\"16.148\"],[\"79620.20\",\"0.008\"],[\"79625.40\",\"0.002\"],[\"79628.30\",\"30.554\"],[\"79635.90\",\"4.527\"],[\"79636.30\",\"0.003\"],[\"79637.30\",\"0.000\"],[\"79637.40\",\"0.001\"],[\"79640.00\",\"3.642\"],[\"79640.70\",\"0.000\"],[\"79640.90\",\"0.002\"],[\"79665.00\",\"0.208\"],[\"79668.10\",\"0.007\"],[\"79690.40\",\"0.000\"],[\"79696.80\",\"1.698\"],[\"79933.80\",\"0.037\"],[\"79936.40\",\"0.508\"],[\"79939.70\",\"0.154\"],[\"80334.10\",\"6.801\"],[\"80339.40\",\"1.429\"],[\"80639.80\",\"0.495\"]],\"st\":1}}"}
{"receive_ns":1788580698261645000,"stream":"btcusdt@bookTicker","event_type":"bookTicker","event_time_ms":1788580698243,"raw_json":"{\"stream\":\"btcusdt@bookTicker\",\"data\":{\"e\":\"bookTicker\",\"u\":11479472626153,\"s\":\"BTCUSDT\",\"ps\":\"BTCUSDT\",\"b\":\"79543.90\",\"B\":\"6.458\",\"a\":\"79544.00\",\"A\":\"5.033\",\"T\":1788580698243,\"E\":1788580698243,\"st\":1}}"}
{"receive_ns":1788580698265205000,"stream":"btcusdt@bookTicker","event_type":"bookTicker","event_time_ms":1788580698245,"raw_json":"{\"stream\":\"btcusdt@bookTicker\",\"data\":{\"e\":\"bookTicker\",\"u\":11479472626289,\"s\":\"BTCUSDT\",\"ps\":\"BTCUSDT\",\"b\":\"79543.90\",\"B\":\"6.459\",\"a\":\"79544.00\",\"A\":\"5.033\",\"T\":1788580698244,\"E\":1788580698245,\"st\":1}}"}
{"receive_ns":1788580698314219000,"stream":"btcusdt@bookTicker","event_type":"bookTicker","event_time_ms":1788580698306,"raw_json":"{\"stream\":\"btcusdt@bookTicker\",\"data\":{\"e\":\"bookTicker\",\"u\":11479472629318,\"s\":\"BTCUSDT\",\"ps\":\"BTCUSDT\",\"b\":\"79543.90\",\"B\":\"6.459\",\"a\":\"79544.00\",\"A\":\"5.036\",\"T\":1788580698306,\"E\":1788580698306,\"st\":1}}"}
{"receive_ns":1788580698324704000,"stream":"btcusdt@depth@100ms","event_type":"depthUpdate","event_time_ms":1788580698329,"raw_json":"{\"stream\":\"btcusdt@depth@100ms\",\"data\":{\"e\":\"depthUpdate\",\"E\":1788580698329,\"T\":1788580698327,\"s\":\"BTCUSDT\",\"ps\":\"BTCUSDT\",\"U\":11479472625361,\"u\":11479472630235,\"pu\":11479472625264,\"b\":[[\"1000.00\",\"25.354\"],[\"29043.90\",\"0.343\"],[\"29343.90\",\"0.007\"],[\"29443.90\",\"1.750\"],[\"71589.50\",\"0.006\"],[\"76362.10\",\"0.002\"],[\"77948.80\",\"1.311\"],[\"78037.20\",\"0.028\"],[\"78125.60\",\"0.028\"],[\"78213.90\",\"0.162\"],[\"78302.30\",\"0.028\"],[\"78390.70\",\"0.028\"],[\"78479.10\",\"0.029\"],[\"78549.60\",\"4.137\"],[\"78567.40\",\"0.028\"],[\"78650.60\",\"0.763\"],[\"78655.80\",\"0.028\"],[\"78744.20\",\"0.028\"],[\"78748.50\",\"3.170\"],[\"79146.20\",\"3.035\"],[\"79480.30\",\"0.657\"],[\"79488.20\",\"0.130\"],[\"79495.10\",\"0.001\"],[\"79495.20\",\"0.064\"],[\"79504.10\",\"0.002\"],[\"79524.30\",\"0.005\"],[\"79525.50\",\"0.374\"],[\"79526.80\",\"1.887\"],[\"79527.80\",\"0.585\"],[\"79528.40\",\"0.177\"],[\"79528.50\",\"0.006\"],[\"79538.60\",\"0.439\"],[\"79543.90\",\"6.459\"]],\"a\":[[\"79544.00\",\"5.036\"],[\"79563.90\",\"0.002\"],[\"79564.90\",\"0.441\"],[\"79571.80\",\"2.945\"],[\"79599.70\",\"0.052\"],[\"79623.00\",\"30.334\"],[\"79624.80\",\"1.753\"],[\"79628.30\",\"0.000\"],[\"79636.20\",\"0.002\"],[\"79936.40\",\"0.383\"],[\"80335.00\",\"0.029\"],[\"80339.40\",\"1.429\"],[\"80423.40\",\"0.028\"],[\"80438.80\",\"0.126\"],[\"80511.80\",\"0.029\"],[\"80521.40\",\"12.894\"],[\"80600.10\",\"4.303\"],[\"80688.50\",\"0.033\"],[\"80776.90\",\"3.491\"],[\"80865.30\",\"0.028\"],[\"80953.60\",\"0.028\"],[\"81042.00\",\"0.039\"],[\"81130.40\",\"0.028\"]],\"st\":1}}"}
{"receive_ns":1788580698395068000,"stream":"btcusdt@bookTicker","event_type":"bookTicker","event_time_ms":1788580698403,"raw_json":"{\"stream\":\"btcusdt@bookTicker\",\"data\":{\"e\":\"bookTicker\",\"u\":11479472634072,\"s\":\"BTCUSDT\",\"ps\":\"BTCUSDT\",\"b\":\"79543.90\",\"B\":\"6.459\",\"a\":\"79544.00\",\"A\":\"5.282\",\"T\":1788580698403,\"E\":1788580698403,\"st\":1}}"}
{"receive_ns":1788580698430680000,"stream":"btcusdt@bookTicker","event_type":"bookTicker","event_time_ms":1788580698405,"raw_json":"{\"stream\":\"btcusdt@bookTicker\",\"data\":{\"e\":\"bookTicker\",\"u\":11479472634166,\"s\":\"BTCUSDT\",\"ps\":\"BTCUSDT\",\"b\":\"79543.90\",\"B\":\"6.459\",\"a\":\"79544.00\",\"A\":\"5.280\",\"T\":1788580698404,\"E\":1788580698405,\"st\":1}}"}
{"receive_ns":1788580698431271000,"stream":"btcusdt@depth@100ms","event_type":"depthUpdate","event_time_ms":1788580698431,"raw_json":"{\"stream\":\"btcusdt@depth@100ms\",\"data\":{\"e\":\"depthUpdate\",\"E\":1788580698431,\"T\":1788580698429,\"s\":\"BTCUSDT\",\"ps\":\"BTCUSDT\",\"U\":11479472630368,\"u\":11479472635215,\"pu\":11479472630235,\"b\":[[\"1000.00\",\"25.354\"],[\"29043.90\",\"0.217\"],[\"29343.90\",\"0.063\"],[\"29443.90\",\"1.820\"],[\"71589.50\",\"0.006\"],[\"78202.90\",\"0.019\"],[\"78748.50\",\"3.170\"],[\"79419.10\",\"0.000\"],[\"79419.20\",\"0.439\"],[\"79454.80\",\"0.032\"],[\"79456.40\",\"0.057\"],[\"79480.30\",\"0.682\"],[\"79482.90\",\"0.606\"],[\"79502.90\",\"0.001\"],[\"79539.90\",\"0.109\"],[\"79540.60\",\"0.252\"]],\"a\":[[\"79544.00\",\"5.280\"],[\"79666.40\",\"0.410\"],[\"79933.80\",\"0.000\"],[\"79936.40\",\"0.383\"],[\"79937.70\",\"0.059\"],[\"79939.70\",\"0.136\"],[\"80260.00\",\"0.579\"],[\"80301.30\",\"0.036\"],[\"80339.40\",\"1.429\"]],\"st\":1}}"}
{"receive_ns":1788580698431599000,"stream":"btcusdt@bookTicker","event_type":"bookTicker","event_time_ms":1788580698449,"raw_json":"{\"stream\":\"btcusdt@bookTicker\",\"data\":{\"e\":\"bookTicker\",\"u\":11479472635878,\"s\":\"BTCUSDT\",\"ps\":\"BTCUSDT\",\"b\":\"79543.90\",\"B\":\"6.430\",\"a\":\"79544.00\",\"A\":\"5.280\",\"T\":1788580698449,\"E\":1788580698449,\"st\":1}}"}
{"receive_ns":1788580698431748000,"stream":"btcusdt@trade","event_type":"trade","event_time_ms":1788580698449,"raw_json":"{\"stream\":\"btcusdt@trade\",\"data\":{\"e\":\"trade\",\"E\":1788580698449,\"T\":1788580698449,\"s\":\"BTCUSDT\",\"t\":8054266635,\"p\":\"79543.90\",\"q\":\"0.029\",\"X\":\"MARKET\",\"m\":true,\"st\":1}}"}
{"receive_ns":1788580698431947000,"stream":"btcusdt@bookTicker","event_type":"bookTicker","event_time_ms":1788580698460,"raw_json":"{\"stream\":\"btcusdt@bookTicker\",\"data\":{\"e\":\"bookTicker\",\"u\":11479472636483,\"s\":\"BTCUSDT\",\"ps\":\"BTCUSDT\",\"b\":\"79543.90\",\"B\":\"6.430\",\"a\":\"79544.00\",\"A\":\"5.268\",\"T\":1788580698460,\"E\":1788580698460,\"st\":1}}"}
{"receive_ns":1788580698487933000,"stream":"btcusdt@depth@100ms","event_type":"depthUpdate","event_time_ms":1788580698533,"raw_json":"{\"stream\":\"btcusdt@depth@100ms\",\"data\":{\"e\":\"depthUpdate\",\"E\":1788580698533,\"T\":1788580698530,\"s\":\"BTCUSDT\",\"ps\":\"BTCUSDT\",\"U\":11479472635269,\"u\":11479472639676,\"pu\":11479472635215,\"b\":[[\"29043.90\",\"0.105\"],[\"29343.90\",\"0.126\"],[\"29443.90\",\"1.869\"],[\"71589.50\",\"0.006\"],[\"71624.70\",\"0.000\"],[\"76362.10\",\"0.000\"],[\"78450.60\",\"1.272\"],[\"78748.50\",\"3.170\"],[\"79539.70\",\"1.944\"],[\"79539.90\",\"0.021\"],[\"79543.90\",\"6.430\"]],\"a\":[[\"79544.00\",\"5.268\"],[\"79560.30\",\"0.136\"],[\"79573.20\",\"0.002\"],[\"79690.40\",\"0.006\"],[\"80339.40\",\"1.429\"],[\"80498.50\",\"18.356\"],[\"80551.10\",\"6.973\"],[\"87541.40\",\"0.000\"]],\"st\":1}}"}
{"receive_ns":1788580698551632000,"stream":"btcusdt@bookTicker","event_type":"bookTicker","event_time_ms":1788580698582,"raw_json":"{\"stream\":\"btcusdt@bookTicker\",\"data\":{\"e\":\"bookTicker\",\"u\":11479472641547,\"s\":\"BTCUSDT\",\"ps\":\"BTCUSDT\",\"b\":\"79543.90\",\"B\":\"6.431\",\"a\":\"79544.00\",\"A\":\"5.268\",\"T\":1788580698582,\"E\":1788580698582,\"st\":1}}"}
{"receive_ns":1788580698560713000,"stream":"btcusdt@bookTicker","event_type":"bookTicker","event_time_ms":1788580698616,"raw_json":"{\"stream\":\"btcusdt@bookTicker\",\"data\":{\"e\":\"bookTicker\",\"u\":11479472643008,\"s\":\"BTCUSDT\",\"ps\":\"BTCUSDT\",\"b\":\"79543.90\",\"B\":\"5.194\",\"a\":\"79544.00\",\"A\":\"5.268\",\"T\":1788580698616,\"E\":1788580698616,\"st\":1}}"}
{"receive_ns":1788580698561274000,"stream":"btcusdt@bookTicker","event_type":"bookTicker","event_time_ms":1788580698617,"raw_json":"{\"stream\":\"btcusdt@bookTicker\",\"data\":{\"e\":\"bookTicker\",\"u\":11479472643262,\"s\":\"BTCUSDT\",\"ps\":\"BTCUSDT\",\"b\":\"79543.90\",\"B\":\"5.236\",\"a\":\"79544.00\",\"A\":\"5.268\",\"T\":1788580698617,\"E\":1788580698617,\"st\":1}}"}
{"receive_ns":1788580698561420000,"stream":"btcusdt@bookTicker","event_type":"bookTicker","event_time_ms":1788580698617,"raw_json":"{\"stream\":\"btcusdt@bookTicker\",\"data\":{\"e\":\"bookTicker\",\"u\":11479472643263,\"s\":\"BTCUSDT\",\"ps\":\"BTCUSDT\",\"b\":\"79543.90\",\"B\":\"5.236\",\"a\":\"79544.00\",\"A\":\"5.270\",\"T\":1788580698617,\"E\":1788580698617,\"st\":1}}"}
{"receive_ns":1788580698561546000,"stream":"btcusdt@bookTicker","event_type":"bookTicker","event_time_ms":1788580698617,"raw_json":"{\"stream\":\"btcusdt@bookTicker\",\"data\":{\"e\":\"bookTicker\",\"u\":11479472643308,\"s\":\"BTCUSDT\",\"ps\":\"BTCUSDT\",\"b\":\"79543.90\",\"B\":\"5.194\",\"a\":\"79544.00\",\"A\":\"5.270\",\"T\":1788580698617,\"E\":1788580698617,\"st\":1}}"}
{"receive_ns":1788580698561701000,"stream":"btcusdt@bookTicker","event_type":"bookTicker","event_time_ms":1788580698618,"raw_json":"{\"stream\":\"btcusdt@bookTicker\",\"data\":{\"e\":\"bookTicker\",\"u\":11479472643387,\"s\":\"BTCUSDT\",\"ps\":\"BTCUSDT\",\"b\":\"79543.90\",\"B\":\"6.432\",\"a\":\"79544.00\",\"A\":\"5.270\",\"T\":1788580698618,\"E\":1788580698618,\"st\":1}}"}
{"receive_ns":1788580698561894000,"stream":"btcusdt@bookTicker","event_type":"bookTicker","event_time_ms":1788580698618,"raw_json":"{\"stream\":\"btcusdt@bookTicker\",\"data\":{\"e\":\"bookTicker\",\"u\":11479472643458,\"s\":\"BTCUSDT\",\"ps\":\"BTCUSDT\",\"b\":\"79543.90\",\"B\":\"6.434\",\"a\":\"79544.00\",\"A\":\"5.270\",\"T\":1788580698618,\"E\":1788580698618,\"st\":1}}"}
{"receive_ns":1788580698562046000,"stream":"btcusdt@bookTicker","event_type":"bookTicker","event_time_ms":1788580698619,"raw_json":"{\"stream\":\"btcusdt@bookTicker\",\"data\":{\"e\":\"bookTicker\",\"u\":11479472643514,\"s\":\"BTCUSDT\",\"ps\":\"BTCUSDT\",\"b\":\"79543.90\",\"B\":\"6.476\",\"a\":\"79544.00\",\"A\":\"5.270\",\"T\":1788580698618,\"E\":1788580698619,\"st\":1}}"}
{"receive_ns":1788580698565338000,"stream":"btcusdt@bookTicker","event_type":"bookTicker","event_time_ms":1788580698619,"raw_json":"{\"stream\":\"btcusdt@bookTicker\",\"data\":{\"e\":\"bookTicker\",\"u\":11479472643529,\"s\":\"BTCUSDT\",\"ps\":\"BTCUSDT\",\"b\":\"79543.90\",\"B\":\"5.238\",\"a\":\"79544.00\",\"A\":\"5.270\",\"T\":1788580698619,\"E\":1788580698619,\"st\":1}}"}
{"receive_ns":1788580698565489000,"stream":"btcusdt@bookTicker","event_type":"bookTicker","event_time_ms":1788580698619,"raw_json":"{\"stream\":\"btcusdt@bookTicker\",\"data\":{\"e\":\"bookTicker\",\"u\":11479472643540,\"s\":\"BTCUSDT\",\"ps\":\"BTCUSDT\",\"b\":\"79543.90\",\"B\":\"5.237\",\"a\":\"79544.00\",\"A\":\"5.270\",\"T\":1788580698619,\"E\":1788580698619,\"st\":1}}"}
{"receive_ns":1788580698565662000,"stream":"btcusdt@bookTicker","event_type":"bookTicker","event_time_ms":1788580698620,"raw_json":"{\"stream\":\"btcusdt@bookTicker\",\"data\":{\"e\":\"bookTicker\",\"u\":11479472643657,\"s\":\"BTCUSDT\",\"ps\":\"BTCUSDT\",\"b\":\"79543.90\",\"B\":\"5.236\",\"a\":\"79544.00\",\"A\":\"5.270\",\"T\":1788580698620,\"E\":1788580698620,\"st\":1}}"}
{"receive_ns":1788580698565788000,"stream":"btcusdt@bookTicker","event_type":"bookTicker","event_time_ms":1788580698620,"raw_json":"{\"stream\":\"btcusdt@bookTicker\",\"data\":{\"e\":\"bookTicker\",\"u\":11479472643675,\"s\":\"BTCUSDT\",\"ps\":\"BTCUSDT\",\"b\":\"79543.90\",\"B\":\"5.237\",\"a\":\"79544.00\",\"A\":\"5.270\",\"T\":1788580698620,\"E\":1788580698620,\"st\":1}}"}
{"receive_ns":1788580698565905000,"stream":"btcusdt@bookTicker","event_type":"bookTicker","event_time_ms":1788580698620,"raw_json":"{\"stream\":\"btcusdt@bookTicker\",\"data\":{\"e\":\"bookTicker\",\"u\":11479472643679,\"s\":\"BTCUSDT\",\"ps\":\"BTCUSDT\",\"b\":\"79543.90\",\"B\":\"5.238\",\"a\":\"79544.00\",\"A\":\"5.270\",\"T\":1788580698620,\"E\":1788580698620,\"st\":1}}"}
{"receive_ns":1788580698611498000,"stream":"btcusdt@bookTicker","event_type":"bookTicker","event_time_ms":1788580698624,"raw_json":"{\"stream\":\"btcusdt@bookTicker\",\"data\":{\"e\":\"bookTicker\",\"u\":11479472644009,\"s\":\"BTCUSDT\",\"ps\":\"BTCUSDT\",\"b\":\"79543.90\",\"B\":\"6.434\",\"a\":\"79544.00\",\"A\":\"5.270\",\"T\":1788580698624,\"E\":1788580698624,\"st\":1}}"}
{"receive_ns":1788580698611669000,"stream":"btcusdt@bookTicker","event_type":"bookTicker","event_time_ms":1788580698625,"raw_json":"{\"stream\":\"btcusdt@bookTicker\",\"data\":{\"e\":\"bookTicker\",\"u\":11479472644024,\"s\":\"BTCUSDT\",\"ps\":\"BTCUSDT\",\"b\":\"79543.90\",\"B\":\"6.435\",\"a\":\"79544.00\",\"A\":\"5.270\",\"T\":1788580698624,\"E\":1788580698625,\"st\":1}}"}
{"receive_ns":1788580698611814000,"stream":"btcusdt@bookTicker","event_type":"bookTicker","event_time_ms":1788580698625,"raw_json":"{\"stream\":\"btcusdt@bookTicker\",\"data\":{\"e\":\"bookTicker\",\"u\":11479472644068,\"s\":\"BTCUSDT\",\"ps\":\"BTCUSDT\",\"b\":\"79543.90\",\"B\":\"6.434\",\"a\":\"79544.00\",\"A\":\"5.270\",\"T\":1788580698625,\"E\":1788580698625,\"st\":1}}"}
{"receive_ns":1788580698612200000,"stream":"btcusdt@depth@100ms","event_type":"depthUpdate","event_time_ms":1788580698635,"raw_json":"{\"stream\":\"btcusdt@depth@100ms\",\"data\":{\"e\":\"depthUpdate\",\"E\":1788580698635,\"T\":1788580698634,\"s\":\"BTCUSDT\",\"ps\":\"BTCUSDT\",\"U\":11479472639808,\"u\":11479472644420,\"pu\":11479472639676,\"b\":[[\"1000.00\",\"25.354\"],[\"29043.90\",\"0.000\"],[\"29343.90\",\"0.203\"],[\"29443.90\",\"1.897\"],[\"63635.00\",\"0.000\"],[\"71589.50\",\"0.006\"],[\"75561.60\",\"0.035\"],[\"76362.10\",\"0.002\"],[\"77953.10\",\"0.012\"],[\"78226.20\",\"1.941\"],[\"78412.80\",\"0.892\"],[\"78571.90\",\"1.913\"],[\"78629.10\",\"0.871\"],[\"78748.50\",\"3.170\"],[\"78840.50\",\"11.737\"],[\"79146.20\",\"3.025\"],[\"79379.40\",\"0.001\"],[\"79379.80\",\"2.140\"],[\"79419.20\",\"0.439\"],[\"79456.40\",\"0.025\"],[\"79480.30\",\"0.647\"],[\"79482.90\",\"0.586\"],[\"79487.00\",\"0.569\"],[\"79499.50\",\"0.000\"],[\"79534.10\",\"0.002\"],[\"79539.60\",\"1.372\"],[\"79540.00\",\"0.003\"],[\"79540.60\",\"0.252\"],[\"79543.80\",\"0.086\"],[\"79543.90\",\"6.434\"]],\"a\":[[\"79544.00\",\"5.270\"],[\"79550.10\",\"0.002\"],[\"79550.40\",\"0.029\"],[\"79550.60\",\"0.004\"],[\"79554.90\",\"0.074\"],[\"79557.80\",\"0.001\"],[\"79573.70\",\"0.194\"],[\"79618.70\",\"0.000\"],[\"79645.90\",\"0.000\"],[\"79666.40\",\"0.410\"],[\"79668.10\",\"0.013\"],[\"79693.60\",\"0.006\"],[\"79705.80\",\"1.869\"],[\"79936.40\",\"0.376\"],[\"79937.70\",\"0.022\"],[\"79939.70\",\"0.077\"],[\"79941.70\",\"1.373\"],[\"80106.50\",\"0.093\"],[\"80272.60\",\"9.827\"],[\"80339.40\",\"1.429\"]],\"st\":1}}"}
{"receive_ns":1788580698675093000,"stream":"btcusdt@bookTicker","event_type":"bookTicker","event_time_ms":1788580698728,"raw_json":"{\"stream\":\"btcusdt@bookTicker\",\"data\":{\"e\":\"bookTicker\",\"u\":11479472648318,\"s\":\"BTCUSDT\",\"ps\":\"BTCUSDT\",\"b\":\"79543.90\",\"B\":\"6.433\",\"a\":\"79544.00\",\"A\":\"5.270\",\"T\":1788580698728,\"E\":1788580698728,\"st\":1}}"}
{"receive_ns":1788580698675317000,"stream":"btcusdt@bookTicker","event_type":"bookTicker","event_time_ms":1788580698730,"raw_json":"{\"stream\":\"btcusdt@bookTicker\",\"data\":{\"e\":\"bookTicker\",\"u\":11479472648471,\"s\":\"BTCUSDT\",\"ps\":\"BTCUSDT\",\"b\":\"79543.90\",\"B\":\"6.434\",\"a\":\"79544.00\",\"A\":\"5.270\",\"T\":1788580698730,\"E\":1788580698730,\"st\":1}}"}
{"receive_ns":1788580698679572000,"stream":"btcusdt@depth@100ms","event_type":"depthUpdate","event_time_ms":1788580698737,"raw_json":"{\"stream\":\"btcusdt@depth@100ms\",\"data\":{\"e\":\"depthUpdate\",\"E\":1788580698737,\"T\":1788580698736,\"s\":\"BTCUSDT\",\"ps\":\"BTCUSDT\",\"U\":11479472644443,\"u\":11479472648749,\"pu\":11479472644420,\"b\":[[\"1000.00\",\"25.354\"],[\"29343.90\",\"0.378\"],[\"29443.90\",\"1.722\"],[\"71589.50\",\"0.006\"],[\"76362.10\",\"0.000\"],[\"78438.20\",\"4.046\"],[\"78748.50\",\"3.170\"],[\"79419.20\",\"0.002\"],[\"79453.10\",\"0.020\"],[\"79456.40\",\"0.042\"],[\"79480.30\",\"0.785\"],[\"79539.70\",\"1.944\"],[\"79540.60\",\"0.252\"],[\"79543.90\",\"6.434\"]],\"a\":[[\"79573.80\",\"0.011\"],[\"79576.00\",\"0.004\"],[\"79666.40\",\"0.000\"],[\"79936.40\",\"0.383\"],[\"79937.70\",\"0.059\"],[\"79939.70\",\"0.136\"],[\"80339.40\",\"1.429\"],[\"80578.20\",\"0.868\"],[\"80617.80\",\"0.186\"],[\"80630.60\",\"11.332\"],[\"80657.60\",\"17.528\"]],\"st\":1}}"}
{"receive_ns":1788580698732803000,"stream":"btcusdt@bookTicker","event_type":"bookTicker","event_time_ms":1788580698752,"raw_json":"{\"stream\":\"btcusdt@bookTicker\",\"data\":{\"e\":\"bookTicker\",\"u\":11479472649467,\"s\":\"BTCUSDT\",\"ps\":\"BTCUSDT\",\"b\":\"79543.90\",\"B\":\"6.434\",\"a\":\"79544.00\",\"A\":\"5.271\",\"T\":1788580698752,\"E\":1788580698752,\"st\":1}}"}
{"receive_ns":1788580698732998000,"stream":"btcusdt@bookTicker","event_type":"bookTicker","event_time_ms":1788580698760,"raw_json":"{\"stream\":\"btcusdt@bookTicker\",\"data\":{\"e\":\"bookTicker\",\"u\":11479472649959,\"s\":\"BTCUSDT\",\"ps\":\"BTCUSDT\",\"b\":\"79543.90\",\"B\":\"6.434\",\"a\":\"79544.00\",\"A\":\"5.294\",\"T\":1788580698760,\"E\":1788580698760,\"st\":1}}"}
{"receive_ns":1788580698733200000,"stream":"btcusdt@bookTicker","event_type":"bookTicker","event_time_ms":1788580698762,"raw_json":"{\"stream\":\"btcusdt@bookTicker\",\"data\":{\"e\":\"bookTicker\",\"u\":11479472650154,\"s\":\"BTCUSDT\",\"ps\":\"BTCUSDT\",\"b\":\"79543.90\",\"B\":\"6.435\",\"a\":\"79544.00\",\"A\":\"5.294\",\"T\":1788580698762,\"E\":1788580698762,\"st\":1}}"}
{"receive_ns":1788580698792081000,"stream":"btcusdt@depth@100ms","event_type":"depthUpdate","event_time_ms":1788580698839,"raw_json":"{\"stream\":\"btcusdt@depth@100ms\",\"data\":{\"e\":\"depthUpdate\",\"E\":1788580698839,\"T\":1788580698838,\"s\":\"BTCUSDT\",\"ps\":\"BTCUSDT\",\"U\":11479472648790,\"u\":11479472653267,\"pu\":11479472648749,\"b\":[[\"29343.90\",\"0.560\"],[\"29443.90\",\"1.540\"],[\"71589.50\",\"0.006\"],[\"71623.00\",\"0.003\"],[\"75566.80\",\"0.004\"],[\"78390.50\",\"3.695\"],[\"78562.00\",\"9.211\"],[\"78674.30\",\"0.000\"],[\"78748.50\",\"3.170\"],[\"79419.20\",\"0.439\"],[\"79456.40\",\"0.017\"],[\"79480.30\",\"0.735\"],[\"79517.30\",\"0.002\"],[\"79518.80\",\"0.454\"],[\"79524.30\",\"0.005\"],[\"79525.50\",\"0.374\"],[\"79527.90\",\"0.079\"],[\"79528.50\",\"0.000\"],[\"79531.30\",\"0.514\"],[\"79531.60\",\"0.003\"],[\"79538.10\",\"0.070\"],[\"79538.30\",\"0.006\"],[\"79539.70\",\"1.944\"],[\"79543.90\",\"6.435\"]],\"a\":[[\"79544.00\",\"5.294\"],[\"79550.40\",\"0.091\"],[\"79550.70\",\"0.314\"],[\"79563.90\",\"0.002\"],[\"79564.90\",\"0.441\"],[\"79567.20\",\"0.006\"],[\"79568.20\",\"0.001\"],[\"79568.30\",\"0.857\"],[\"79571.80\",\"2.939\"],[\"79617.80\",\"0.000\"],[\"79618.30\",\"0.134\"],[\"79666.40\",\"0.410\"],[\"79937.70\",\"0.041\"],[\"79939.70\",\"0.108\"],[\"80339.40\",\"1.429\"],[\"80339.50\",\"0.000\"],[\"81134.80\",\"0.018\"]],\"st\":1}}"}
{"receive_ns":1788580698860165000,"stream":"btcusdt@bookTicker","event_type":"bookTicker","event_time_ms":1788580698903,"raw_json":"{\"stream\":\"btcusdt@bookTicker\",\"data\":{\"e\":\"bookTicker\",\"u\":11479472655687,\"s\":\"BTCUSDT\",\"ps\":\"BTCUSDT\",\"b\":\"79543.90\",\"B\":\"6.435\",\"a\":\"79544.00\",\"A\":\"5.286\",\"T\":1788580698903,\"E\":1788580698903,\"st\":1}}"}
{"receive_ns":1788580698860509000,"stream":"btcusdt@trade","event_type":"trade","event_time_ms":1788580698903,"raw_json":"{\"stream\":\"btcusdt@trade\",\"data\":{\"e\":\"trade\",\"E\":1788580698903,\"T\":1788580698903,\"s\":\"BTCUSDT\",\"t\":8054266636,\"p\":\"79544.00\",\"q\":\"0.008\",\"X\":\"MARKET\",\"m\":false,\"st\":1}}"}
{"receive_ns":1788580698933228000,"stream":"btcusdt@depth@100ms","event_type":"depthUpdate","event_time_ms":1788580698941,"raw_json":"{\"stream\":\"btcusdt@depth@100ms\",\"data\":{\"e\":\"depthUpdate\",\"E\":1788580698941,\"T\":1788580698939,\"s\":\"BTCUSDT\",\"ps\":\"BTCUSDT\",\"U\":11479472653385,\"u\":11479472656702,\"pu\":11479472653267,\"b\":[[\"1000.00\",\"25.354\"],[\"29343.90\",\"0.735\"],[\"29443.90\",\"1.365\"],[\"71589.50\",\"0.006\"],[\"71623.00\",\"0.000\"],[\"76362.10\",\"0.002\"],[\"78231.40\",\"1.115\"],[\"78584.10\",\"26.722\"],[\"78748.50\",\"3.170\"],[\"79146.10\",\"0.008\"],[\"79146.20\",\"3.025\"],[\"79427.00\",\"0.034\"],[\"79427.10\",\"0.002\"],[\"79453.10\",\"0.000\"],[\"79456.40\",\"0.000\"],[\"79474.60\",\"22.949\"],[\"79476.00\",\"1.485\"],[\"79477.20\",\"0.027\"],[\"79480.30\",\"0.641\"],[\"79482.90\",\"0.606\"],[\"79539.70\",\"1.944\"],[\"79539.90\",\"0.197\"],[\"79540.60\",\"0.252\"]],\"a\":[[\"79544.00\",\"5.286\"],[\"79550.40\",\"0.029\"],[\"79550.60\",\"0.066\"],[\"79560.30\",\"0.060\"],[\"79618.50\",\"0.337\"],[\"79618.80\",\"0.000\"],[\"79933.80\",\"0.018\"],[\"79936.40\",\"0.383\"],[\"79937.70\",\"0.041\"],[\"79939.70\",\"0.131\"],[\"79941.80\",\"0.000\"],[\"80339.40\",\"1.429\"],[\"80726.00\",\"1.573\"]],\"st\":1}}"}
{"receive_ns":1788580699007912000,"stream":"btcusdt@bookTicker","event_type":"bookTicker","event_time_ms":1788580699028,"raw_json":"{\"stream\":\"btcusdt@bookTicker\",\"data\":{\"e\":\"bookTicker\",\"u\":11479472659736,\"s\":\"BTCUSDT\",\"ps\":\"BTCUSDT\",\"b\":\"79543.90\",\"B\":\"6.435\",\"a\":\"79544.00\",\"A\":\"5.283\",\"T\":1788580699028,\"E\":1788580699028,\"st\":1}}"}
{"receive_ns":1788580699009028000,"stream":"btcusdt@depth@100ms","event_type":"depthUpdate","event_time_ms":1788580699043,"raw_json":"{\"stream\":\"btcusdt@depth@100ms\",\"data\":{\"e\":\"depthUpdate\",\"E\":1788580699043,\"T\":1788580699042,\"s\":\"BTCUSDT\",\"ps\":\"BTCUSDT\",\"U\":11479472656842,\"u\":11479472660539,\"pu\":11479472656702,\"b\":[[\"1000.00\",\"25.354\"],[\"29343.90\",\"0.910\"],[\"29443.90\",\"1.190\"],[\"63635.10\",\"0.000\"],[\"71589.50\",\"0.006\"],[\"76362.10\",\"0.000\"],[\"78191.70\",\"5.236\"],[\"78748.50\",\"3.170\"],[\"78907.50\",\"5.691\"],[\"79146.10\",\"0.009\"],[\"79480.30\",\"0.651\"],[\"79505.10\",\"0.000\"],[\"79506.40\",\"0.032\"],[\"79507.10\",\"3.840\"],[\"79507.30\",\"0.002\"],[\"79511.40\",\"0.004\"],[\"79520.20\",\"2.395\"],[\"79529.60\",\"0.006\"],[\"79540.60\",\"0.252\"]],\"a\":[[\"79544.00\",\"5.283\"],[\"79560.10\",\"0.004\"],[\"79576.20\",\"3.235\"],[\"79576.50\",\"12.322\"],[\"79619.10\",\"0.000\"],[\"79619.70\",\"0.168\"],[\"79636.20\",\"0.003\"],[\"79939.70\",\"0.136\"],[\"79941.80\",\"0.001\"],[\"80193.10\",\"0.995\"],[\"80339.40\",\"1.429\"],[\"80578.20\",\"1.736\"]],\"st\":1}}"}
{"receive_ns":1788580699027575000,"stream":"btcusdt@bookTicker","event_type":"bookTicker","event_time_ms":1788580699074,"raw_json":"{\"stream\":\"btcusdt@bookTicker\",\"data\":{\"e\":\"bookTicker\",\"u\":11479472662080,\"s\":\"BTCUSDT\",\"ps\":\"BTCUSDT\",\"b\":\"79543.90\",\"B\":\"6.433\",\"a\":\"79544.00\",\"A\":\"5.283\",\"T\":1788580699074,\"E\":1788580699074,\"st\":1}}"}
{"receive_ns":1788580699030351000,"stream":"btcusdt@bookTicker","event_type":"bookTicker","event_time_ms":1788580699077,"raw_json":"{\"stream\":\"btcusdt@bookTicker\",\"data\":{\"e\":\"bookTicker\",\"u\":11479472662262,\"s\":\"BTCUSDT\",\"ps\":\"BTCUSDT\",\"b\":\"79543.90\",\"B\":\"6.437\",\"a\":\"79544.00\",\"A\":\"5.283\",\"T\":1788580699076,\"E\":1788580699077,\"st\":1}}"}
{"receive_ns":1788580699089732000,"stream":"btcusdt@depth@100ms","event_type":"depthUpdate","event_time_ms":1788580699145,"raw_json":"{\"stream\":\"btcusdt@depth@100ms\",\"data\":{\"e\":\"depthUpdate\",\"E\":1788580699145,\"T\":1788580699143,\"s\":\"BTCUSDT\",\"ps\":\"BTCUSDT\",\"U\":11479472660763,\"u\":11479472665132,\"pu\":11479472660539,\"b\":[[\"29343.90\",\"1.092\"],[\"29443.90\",\"1.008\"],[\"71589.50\",\"0.006\"],[\"76362.10\",\"0.002\"],[\"77316.70\",\"1.031\"],[\"78305.80\",\"5.231\"],[\"78385.30\",\"7.620\"],[\"78589.40\",\"14.547\"],[\"78748.50\",\"3.170\"],[\"78907.50\",\"5.693\"],[\"79140.90\",\"1.451\"],[\"79456.40\",\"0.025\"],[\"79480.30\",\"0.569\"],[\"79482.90\",\"0.586\"],[\"79504.10\",\"0.004\"],[\"79529.60\",\"0.002\"],[\"79539.90\",\"0.021\"],[\"79543.90\",\"6.437\"]],\"a\":[[\"79554.20\",\"0.258\"],[\"79605.50\",\"0.003\"],[\"79605.60\",\"0.064\"],[\"79615.60\",\"0.006\"],[\"79625.40\",\"0.003\"],[\"79637.50\",\"0.002\"],[\"79639.90\",\"3.192\"],[\"79640.00\",\"3.644\"],[\"79640.90\",\"0.003\"],[\"79933.80\",\"0.018\"],[\"79936.40\",\"0.376\"],[\"79937.70\",\"0.004\"],[\"79939.70\",\"0.033\"],[\"80279.00\",\"0.056\"],[\"80339.40\",\"1.429\"],[\"81134.80\",\"0.015\"]],\"st\":1}}"}
{"receive_ns":1788580699097099000,"stream":"btcusdt@bookTicker","event_type":"bookTicker","event_time_ms":1788580699152,"raw_json":"{\"stream\":\"btcusdt@bookTicker\",\"data\":{\"e\":\"bookTicker\",\"u\":11479472665502,\"s\":\"BTCUSDT\",\"ps\":\"BTCUSDT\",\"b\":\"79543.90\",\"B\":\"6.436\",\"a\":\"79544.00\",\"A\":\"5.283\",\"T\":1788580699152,\"E\":1788580699152,\"st\":1}}"}
{"receive_ns":1788580699128511000,"stream":"btcusdt@bookTicker","event_type":"bookTicker","event_time_ms":1788580699154,"raw_json":"{\"stream\":\"btcusdt@bookTicker\",\"data\":{\"e\":\"bookTicker\",\"u\":11479472665601,\"s\":\"BTCUSDT\",\"ps\":\"BTCUSDT\",\"b\":\"79543.90\",\"B\":\"6.437\",\"a\":\"79544.00\",\"A\":\"5.283\",\"T\":1788580699154,\"E\":1788580699154,\"st\":1}}"}
{"receive_ns":1788580699190230000,"stream":"btcusdt@bookTicker","event_type":"bookTicker","event_time_ms":1788580699209,"raw_json":"{\"stream\":\"btcusdt@bookTicker\",\"data\":{\"e\":\"bookTicker\",\"u\":11479472668341,\"s\":\"BTCUSDT\",\"ps\":\"BTCUSDT\",\"b\":\"79543.90\",\"B\":\"6.437\",\"a\":\"79544.00\",\"A\":\"5.281\",\"T\":1788580699208,\"E\":1788580699209,\"st\":1}}"}
{"receive_ns":1788580699190454000,"stream":"btcusdt@bookTicker","event_type":"bookTicker","event_time_ms":1788580699211,"raw_json":"{\"stream\":\"btcusdt@bookTicker\",\"data\":{\"e\":\"bookTicker\",\"u\":11479472668467,\"s\":\"BTCUSDT\",\"ps\":\"BTCUSDT\",\"b\":\"79543.90\",\"B\":\"6.437\",\"a\":\"79544.00\",\"A\":\"5.285\",\"T\":1788580699211,\"E\":1788580699211,\"st\":1}}"}
{"receive_ns":1788580699190690000,"stream":"btcusdt@bookTicker","event_type":"bookTicker","event_time_ms":1788580699229,"raw_json":"{\"stream\":\"btcusdt@bookTicker\",\"data\":{\"e\":\"bookTicker\",\"u\":11479472670202,\"s\":\"BTCUSDT\",\"ps\":\"BTCUSDT\",\"b\":\"79543.90\",\"B\":\"6.436\",\"a\":\"79544.00\",\"A\":\"5.285\",\"T\":1788580699228,\"E\":1788580699229,\"st\":1}}"}
{"receive_ns":1788580699198183000,"stream":"btcusdt@bookTicker","event_type":"bookTicker","event_time_ms":1788580699237,"raw_json":"{\"stream\":\"btcusdt@bookTicker\",\"data\":{\"e\":\"bookTicker\",\"u\":11479472670722,\"s\":\"BTCUSDT\",\"ps\":\"BTCUSDT\",\"b\":\"79543.90\",\"B\":\"6.438\",\"a\":\"79544.00\",\"A\":\"5.285\",\"T\":1788580699237,\"E\":1788580699237,\"st\":1}}"}
{"receive_ns":1788580699212253000,"stream":"btcusdt@depth@100ms","event_type":"depthUpdate","event_time_ms":1788580699247,"raw_json":"{\"stream\":\"btcusdt@depth@100ms\",\"data\":{\"e\":\"depthUpdate\",\"E\":1788580699247,\"T\":1788580699245,\"s\":\"BTCUSDT\",\"ps\":\"BTCUSDT\",\"U\":11479472665308,\"u\":11479472671083,\"pu\":11479472665132,\"b\":[[\"1000.00\",\"25.354\"],[\"29343.90\",\"1.274\"],[\"29443.90\",\"0.826\"],[\"63635.00\",\"0.000\"],[\"71589.50\",\"0.006\"],[\"75566.70\",\"0.011\"],[\"76362.10\",\"0.000\"],[\"78601.80\",\"12.368\"],[\"78748.50\",\"3.170\"],[\"78907.50\",\"5.691\"],[\"79146.20\",\"3.035\"],[\"79379.80\",\"0.000\"],[\"79419.20\",\"0.002\"],[\"79456.40\",\"0.032\"],[\"79476.00\",\"4.376\"],[\"79480.30\",\"0.619\"],[\"79482.90\",\"0.606\"],[\"79486.80\",\"1.442\"],[\"79502.70\",\"0.729\"],[\"79539.90\",\"0.197\"],[\"79543.90\",\"6.438\"]],\"a\":[[\"79544.00\",\"5.285\"],[\"79554.20\",\"0.256\"],[\"79557.80\",\"0.692\"],[\"79573.70\",\"1.024\"],[\"79574.40\",\"0.048\"],[\"79619.70\",\"0.043\"],[\"79620.00\",\"20.663\"],[\"79623.00\",\"0.009\"],[\"79624.70\",\"0.515\"],[\"79624.80\",\"1.754\"],[\"79625.40\",\"0.004\"],[\"79628.30\",\"30.325\"],[\"79636.10\",\"0.079\"],[\"79636.20\",\"0.004\"],[\"79637.40\",\"0.003\"],[\"79640.90\",\"0.004\"],[\"79666.40\",\"0.000\"],[\"79668.10\",\"0.007\"],[\"79690.40\",\"0.000\"],[\"79693.60\",\"0.000\"],[\"79705.80\",\"0.007\"],[\"79936.40\",\"0.383\"],[\"79937.70\",\"0.041\"],[\"79939.70\",\"0.136\"],[\"80339.40\",\"1.429\"],[\"80713.30\",\"1.176\"],[\"87498.40\",\"0.001\"]],\"st\":1}}"}
{"receive_ns":1788580699258530000,"stream":"btcusdt@bookTicker","event_type":"bookTicker","event_time_ms":1788580699296,"raw_json":"{\"stream\":\"btcusdt@bookTicker\",\"data\":{\"e\":\"bookTicker\",\"u\":11479472673638,\"s\":\"BTCUSDT\",\"ps\":\"BTCUSDT\",\"b\":\"79543.90\",\"B\":\"6.438\",\"a\":\"79544.00\",\"A\":\"5.286\",\"T\":1788580699295,\"E\":1788580699296,\"st\":1}}"}
{"receive_ns":1788580699258779000,"stream":"btcusdt@bookTicker","event_type":"bookTicker","event_time_ms":1788580699296,"raw_json":"{\"stream\":\"btcusdt@bookTicker\",\"data\":{\"e\":\"bookTicker\",\"u\":11479472673642,\"s\":\"BTCUSDT\",\"ps\":\"BTCUSDT\",\"b\":\"79543.90\",\"B\":\"6.437\",\"a\":\"79544.00\",\"A\":\"5.286\",\"T\":1788580699295,\"E\":1788580699296,\"st\":1}}"}
{"receive_ns":1788580699321221000,"stream":"btcusdt@depth@100ms","event_type":"depthUpdate","event_time_ms":1788580699349,"raw_json":"{\"stream\":\"btcusdt@depth@100ms\",\"data\":{\"e\":\"depthUpdate\",\"E\":1788580699349,\"T\":1788580699345,\"s\":\"BTCUSDT\",\"ps\":\"BTCUSDT\",\"U\":11479472671126,\"u\":11479472676542,\"pu\":11479472671083,\"b\":[[\"1000.00\",\"25.354\"],[\"29343.90\",\"1.449\"],[\"29443.90\",\"0.651\"],[\"71589.50\",\"0.006\"],[\"78748.50\",\"3.170\"],[\"79331.70\",\"0.000\"],[\"79456.40\",\"0.007\"],[\"79480.30\",\"0.569\"],[\"79543.90\",\"6.437\"]],\"a\":[[\"79544.00\",\"5.286\"],[\"79619.60\",\"0.002\"],[\"79620.00\",\"16.148\"],[\"79625.60\",\"30.436\"],[\"79628.30\",\"0.000\"],[\"79753.50\",\"0.722\"],[\"79753.60\",\"0.001\"],[\"79933.80\",\"0.000\"],[\"79939.70\",\"0.108\"],[\"80339.40\",\"1.429\"],[\"80431.70\",\"12.239\"]],\"st\":1}}"}
{"receive_ns":1788580699436792000,"stream":"btcusdt@depth@100ms","event_type":"depthUpdate","event_time_ms":1788580699451,"raw_json":"{\"stream\":\"btcusdt@depth@100ms\",\"data\":{\"e\":\"depthUpdate\",\"E\":1788580699451,\"T\":1788580699449,\"s\":\"BTCUSDT\",\"ps\":\"BTCUSDT\",\"U\":11479472676643,\"u\":11479472681453,\"pu\":11479472676542,\"b\":[[\"29343.90\",\"1.631\"],[\"29443.90\",\"0.469\"],[\"71589.50\",\"0.006\"],[\"76362.10\",\"0.002\"],[\"78311.00\",\"3.810\"],[\"78390.50\",\"4.587\"],[\"78748.50\",\"3.170\"],[\"79456.40\",\"0.000\"],[\"79480.30\",\"0.729\"],[\"79482.90\",\"0.606\"],[\"79503.20\",\"0.100\"],[\"79504.80\",\"10.304\"],[\"79528.70\",\"0.327\"],[\"79539.90\",\"0.109\"],[\"79540.60\",\"0.252\"]],\"a\":[[\"79616.10\",\"0.406\"],[\"79616.70\",\"3.191\"],[\"79620.10\",\"0.446\"],[\"79620.40\",\"0.128\"],[\"79623.00\",\"30.247\"],[\"79625.60\",\"0.198\"],[\"79766.20\",\"19.339\"],[\"79767.40\",\"0.010\"],[\"79933.80\",\"0.037\"],[\"79936.40\",\"0.258\"],[\"79937.70\",\"0.022\"],[\"79939.70\",\"0.131\"],[\"80339.40\",\"1.429\"]],\"st\":1}}"}
{"receive_ns":1788580699437568000,"stream":"btcusdt@bookTicker","event_type":"bookTicker","event_time_ms":1788580699487,"raw_json":"{\"stream\":\"btcusdt@bookTicker\",\"data\":{\"e\":\"bookTicker\",\"u\":11479472684744,\"s\":\"BTCUSDT\",\"ps\":\"BTCUSDT\",\"b\":\"79543.90\",\"B\":\"6.435\",\"a\":\"79544.00\",\"A\":\"5.286\",\"T\":1788580699486,\"E\":1788580699487,\"st\":1}}"}
{"receive_ns":1788580699438362000,"stream":"btcusdt@bookTicker","event_type":"bookTicker","event_time_ms":1788580699494,"raw_json":"{\"stream\":\"btcusdt@bookTicker\",\"data\":{\"e\":\"bookTicker\",\"u\":11479472685092,\"s\":\"BTCUSDT\",\"ps\":\"BTCUSDT\",\"b\":\"79543.90\",\"B\":\"6.436\",\"a\":\"79544.00\",\"A\":\"5.286\",\"T\":1788580699494,\"E\":1788580699494,\"st\":1}}"}
{"receive_ns":1788580699454334000,"stream":"btcusdt@bookTicker","event_type":"bookTicker","event_time_ms":1788580699503,"raw_json":"{\"stream\":\"btcusdt@bookTicker\",\"data\":{\"e\":\"bookTicker\",\"u\":11479472685537,\"s\":\"BTCUSDT\",\"ps\":\"BTCUSDT\",\"b\":\"79543.90\",\"B\":\"6.440\",\"a\":\"79544.00\",\"A\":\"5.286\",\"T\":1788580699503,\"E\":1788580699503,\"st\":1}}"}
{"receive_ns":1788580699456419000,"stream":"btcusdt@bookTicker","event_type":"bookTicker","event_time_ms":1788580699512,"raw_json":"{\"stream\":\"btcusdt@bookTicker\",\"data\":{\"e\":\"bookTicker\",\"u\":11479472685936,\"s\":\"BTCUSDT\",\"ps\":\"BTCUSDT\",\"b\":\"79543.90\",\"B\":\"6.440\",\"a\":\"79544.00\",\"A\":\"5.289\",\"T\":1788580699512,\"E\":1788580699512,\"st\":1}}"}
{"receive_ns":1788580699507851000,"stream":"btcusdt@depth@100ms","event_type":"depthUpdate","event_time_ms":1788580699553,"raw_json":"{\"stream\":\"btcusdt@depth@100ms\",\"data\":{\"e\":\"depthUpdate\",\"E\":1788580699553,\"T\":1788580699550,\"s\":\"BTCUSDT\",\"ps\":\"BTCUSDT\",\"U\":11479472681579,\"u\":11479472687401,\"pu\":11479472681453,\"b\":[[\"1000.00\",\"25.354\"],[\"29243.90\",\"0.021\"],[\"29343.90\",\"1.764\"],[\"29443.90\",\"0.315\"],[\"71589.50\",\"0.006\"],[\"76362.10\",\"0.000\"],[\"78470.10\",\"1.909\"],[\"78584.10\",\"26.087\"],[\"78748.50\",\"3.170\"],[\"79146.20\",\"3.035\"],[\"79480.30\",\"0.739\"],[\"79540.60\",\"0.252\"],[\"79543.90\",\"6.440\"]],\"a\":[[\"79544.00\",\"5.289\"],[\"79550.40\",\"0.091\"],[\"79550.60\",\"0.004\"],[\"79620.20\",\"0.008\"],[\"79620.40\",\"0.003\"],[\"79939.70\",\"0.136\"],[\"80175.00\",\"5.362\"],[\"80339.40\",\"1.429\"],[\"81134.80\",\"0.012\"]],\"st\":1}}"}
{"receive_ns":1788580699652154000,"stream":"btcusdt@depth@100ms","event_type":"depthUpdate","event_time_ms":1788580699655,"raw_json":"{\"stream\":\"btcusdt@depth@100ms\",\"data\":{\"e\":\"depthUpdate\",\"E\":1788580699655,\"T\":1788580699654,\"s\":\"BTCUSDT\",\"ps\":\"BTCUSDT\",\"U\":11479472687632,\"u\":11479472691108,\"pu\":11479472687401,\"b\":[[\"1000.00\",\"25.354\"],[\"29243.90\",\"0.077\"],[\"29343.90\",\"1.834\"],[\"29443.90\",\"0.189\"],[\"63635.00\",\"0.000\"],[\"71589.50\",\"0.006\"],[\"75566.70\",\"0.013\"],[\"76362.10\",\"0.002\"],[\"77873.50\",\"0.257\"],[\"78522.20\",\"10.306\"],[\"78588.70\",\"0.000\"],[\"78597.30\",\"0.005\"],[\"78602.20\",\"0.028\"],[\"78609.10\",\"0.006\"],[\"78748.50\",\"3.170\"],[\"78821.60\",\"0.190\"],[\"79271.20\",\"0.004\"],[\"79271.90\",\"0.131\"],[\"79373.50\",\"0.178\"],[\"79480.30\",\"0.739\"],[\"79482.90\",\"0.606\"],[\"79488.20\",\"0.128\"],[\"79504.10\",\"0.004\"],[\"79539.90\",\"0.109\"],[\"79540.60\",\"0.252\"]],\"a\":[[\"79599.70\",\"0.052\"],[\"79615.60\",\"0.004\"],[\"79620.70\",\"0.000\"],[\"79933.80\",\"0.000\"],[\"79936.40\",\"0.258\"],[\"79937.70\",\"0.059\"],[\"79939.70\",\"0.136\"],[\"80339.40\",\"1.429\"],[\"80538.30\",\"2.790\"],[\"80539.10\",\"3.694\"],[\"80551.10\",\"6.824\"]],\"st\":1}}"}
{"receive_ns":1788580699652394000,"stream":"btcusdt@bookTicker","event_type":"bookTicker","event_time_ms":1788580699655,"raw_json":"{\"stream\":\"btcusdt@bookTicker\",\"data\":{\"e\":\"bookTicker\",\"u\":11479472691126,\"s\":\"BTCUSDT\",\"ps\":\"BTCUSDT\",\"b\":\"79543.90\",\"B\":\"6.440\",\"a\":\"79544.00\",\"A\":\"5.265\",\"T\":1788580699655,\"E\":1788580699655,\"st\":1}}"}
{"receive_ns":1788580699652554000,"stream":"btcusdt@bookTicker","event_type":"bookTicker","event_time_ms":1788580699658,"raw_json":"{\"stream\":\"btcusdt@bookTicker\",\"data\":{\"e\":\"bookTicker\",\"u\":11479472691244,\"s\":\"BTCUSDT\",\"ps\":\"BTCUSDT\",\"b\":\"79543.90\",\"B\":\"6.440\",\"a\":\"79544.00\",\"A\":\"5.291\",\"T\":1788580699658,\"E\":1788580699658,\"st\":1}}"}
{"receive_ns":1788580699652801000,"stream":"btcusdt@bookTicker","event_type":"bookTicker","event_time_ms":1788580699704,"raw_json":"{\"stream\":\"btcusdt@bookTicker\",\"data\":{\"e\":\"bookTicker\",\"u\":11479472692500,\"s\":\"BTCUSDT\",\"ps\":\"BTCUSDT\",\"b\":\"79543.90\",\"B\":\"6.439\",\"a\":\"79544.00\",\"A\":\"5.291\",\"T\":1788580699704,\"E\":1788580699704,\"st\":1}}"}
{"receive_ns":1788580699653027000,"stream":"btcusdt@bookTicker","event_type":"bookTicker","event_time_ms":1788580699706,"raw_json":"{\"stream\":\"btcusdt@bookTicker\",\"data\":{\"e\":\"bookTicker\",\"u\":11479472692566,\"s\":\"BTCUSDT\",\"ps\":\"BTCUSDT\",\"b\":\"79543.90\",\"B\":\"6.440\",\"a\":\"79544.00\",\"A\":\"5.291\",\"T\":1788580699706,\"E\":1788580699706,\"st\":1}}"}
