{"receive_ns":1788564452847390000,"stream":"btcusdt@depth@100ms","event_type":"depthUpdate","event_time_ms":1788564452865,"raw_json":"{\"stream\":\"btcusdt@depth@100ms\",\"data\":{\"e\":\"depthUpdate\",\"E\":1788564452865,\"T\":1788564452864,\"s\":\"BTCUSDT\",\"ps\":\"BTCUSDT\",\"U\":11478296360356,\"u\":11478296366051,\"pu\":11478296360273,\"b\":[[\"1000.00\",\"24.754\"],[\"29216.80\",\"0.084\"],[\"29316.80\",\"1.834\"],[\"29416.80\",\"0.182\"],[\"63774.00\",\"0.000\"],[\"71745.10\",\"0.000\"],[\"76528.10\",\"0.002\"],[\"78481.20\",\"1.783\"],[\"78919.60\",\"2.865\"],[\"79318.20\",\"3.158\"],[\"79497.60\",\"0.733\"],[\"79500.80\",\"1.003\"],[\"79501.60\",\"0.628\"],[\"79529.50\",\"1.003\"],[\"79530.70\",\"0.001\"],[\"79531.50\",\"0.206\"],[\"79533.50\",\"0.001\"],[\"79565.40\",\"1.893\"],[\"79565.50\",\"0.009\"],[\"79698.90\",\"0.490\"],[\"79711.00\",\"0.026\"],[\"79711.60\",\"0.000\"],[\"79712.00\",\"0.016\"],[\"79715.10\",\"0.002\"],[\"79716.80\",\"2.652\"]],\"a\":[[\"79725.40\",\"0.062\"],[\"79727.10\",\"0.166\"],[\"79792.60\",\"0.701\"],[\"79825.00\",\"1.027\"],[\"79838.90\",\"0.040\"],[\"79839.00\",\"1.884\"],[\"79852.20\",\"0.977\"],[\"79886.30\",\"0.090\"],[\"80078.80\",\"0.764\"],[\"80087.60\",\"1.147\"],[\"80334.00\",\"3.853\"],[\"80514.10\",\"0.638\"]],\"st\":1}}"}
{"receive_ns":1788564452949370000,"stream":"btcusdt@depth@100ms","event_type":"depthUpdate","event_time_ms":1788564452967,"raw_json":"{\"stream\":\"btcusdt@depth@100ms\",\"data\":{\"e\":\"depthUpdate\",\"E\":1788564452967,\"T\":1788564452965,\"s\":\"BTCUSDT\",\"ps\":\"BTCUSDT\",\"U\":11478296366057,\"u\":11478296371941,\"pu\":11478296366051,\"b\":[[\"29216.80\",\"0.147\"],[\"29316.80\",\"1.890\"],[\"29416.80\",\"0.063\"],[\"63773.00\",\"0.000\"],[\"71745.10\",\"0.002\"],[\"75731.00\",\"0.067\"],[\"75731.10\",\"0.002\"],[\"76528.10\",\"0.000\"],[\"78592.80\",\"1.398\"],[\"78600.80\",\"12.095\"],[\"78919.60\",\"2.865\"],[\"79079.10\",\"1.771\"],[\"79320.20\",\"0.000\"],[\"79529.50\",\"1.203\"],[\"79531.50\",\"0.006\"],[\"79594.40\",\"0.651\"],[\"79698.90\",\"0.991\"]],\"a\":[[\"79792.60\",\"0.451\"],[\"79840.30\",\"0.351\"],[\"80087.60\",\"1.147\"],[\"80354.60\",\"2.237\"],[\"80652.80\",\"11.768\"],[\"80713.40\",\"4.473\"],[\"81271.40\",\"1.228\"]],\"st\":1}}"}
{"receive_ns":1788564453041712000,"stream":"btcusdt@bookTicker","event_type":"bookTicker","event_time_ms":1788564453066,"raw_json":"{\"stream\":\"btcusdt@bookTicker\",\"data\":{\"e\":\"bookTicker\",\"u\":11478296377858,\"s\":\"BTCUSDT\",\"ps\":\"BTCUSDT\",\"b\":\"79716.80\",\"B\":\"2.652\",\"a\":\"79716.90\",\"A\":\"15.191\",\"T\":1788564453066,\"E\":1788564453066,\"st\":1}}"}
{"receive_ns":1788564453048343000,"stream":"btcusdt@bookTicker","event_type":"bookTicker","event_time_ms":1788564453066,"raw_json":"{\"stream\":\"btcusdt@bookTicker\",\"data\":{\"e\":\"bookTicker\",\"u\":11478296377910,\"s\":\"BTCUSDT\",\"ps\":\"BTCUSDT\",\"b\":\"79716.80\",\"B\":\"2.652\",\"a\":\"79716.90\",\"A\":\"15.172\",\"T\":1788564453066,\"E\":1788564453066,\"st\":1}}"}
{"receive_ns":1788564453063773000,"stream":"btcusdt@bookTicker","event_type":"bookTicker","event_time_ms":1788564453067,"raw_json":"{\"stream\":\"btcusdt@bookTicker\",\"data\":{\"e\":\"bookTicker\",\"u\":11478296377943,\"s\":\"BTCUSDT\",\"ps\":\"BTCUSDT\",\"b\":\"79716.80\",\"B\":\"2.652\",\"a\":\"79716.90\",\"A\":\"15.171\",\"T\":1788564453067,\"E\":1788564453067,\"st\":1}}"}
{"receive_ns":1788564453075567000,"stream":"btcusdt@depth@100ms","event_type":"depthUpdate","event_time_ms":1788564453069,"raw_json":"{\"stream\":\"btcusdt@depth@100ms\",\"data\":{\"e\":\"depthUpdate\",\"E\":1788564453069,\"T\":1788564453068,\"s\":\"BTCUSDT\",\"ps\":\"BTCUSDT\",\"U\":11478296372044,\"u\":11478296378033,\"pu\":11478296371941,\"b\":[[\"1000.00\",\"24.754\"],[\"29216.80\",\"0.259\"],[\"29316.80\",\"1.841\"],[\"29416.80\",\"0.000\"],[\"63773.00\",\"0.000\"],[\"63774.00\",\"0.000\"],[\"71745.10\",\"0.002\"],[\"78919.60\",\"2.869\"],[\"79079.10\",\"1.769\"],[\"79320.20\",\"0.140\"],[\"79399.60\",\"0.002\"],[\"79497.60\",\"0.502\"],[\"79500.80\",\"0.000\"],[\"79529.50\",\"0.200\"],[\"79594.40\",\"0.000\"],[\"79698.30\",\"0.078\"],[\"79698.90\",\"0.065\"],[\"79702.50\",\"0.000\"],[\"79709.50\",\"0.001\"],[\"79709.70\",\"0.000\"],[\"79709.80\",\"0.099\"],[\"79709.90\",\"0.104\"],[\"79711.20\",\"0.032\"],[\"79711.40\",\"0.026\"],[\"79711.80\",\"0.027\"],[\"79712.40\",\"0.026\"],[\"79712.50\",\"0.026\"]],\"a\":[[\"79716.90\",\"15.171\"],[\"79717.90\",\"0.006\"],[\"79722.10\",\"0.008\"],[\"79727.80\",\"0.008\"],[\"79731.40\",\"0.000\"],[\"79790.30\",\"0.045\"],[\"79792.60\",\"0.451\"],[\"79840.30\",\"0.001\"],[\"79886.30\",\"0.000\"],[\"80078.80\",\"0.002\"],[\"80087.60\",\"0.579\"],[\"80514.10\",\"0.638\"],[\"80646.20\",\"15.964\"],[\"81390.70\",\"0.000\"]],\"st\":1}}"}
{"receive_ns":1788564453087725000,"stream":"btcusdt@bookTicker","event_type":"bookTicker","event_time_ms":1788564453106,"raw_json":"{\"stream\":\"btcusdt@bookTicker\",\"data\":{\"e\":\"bookTicker\",\"u\":11478296380610,\"s\":\"BTCUSDT\",\"ps\":\"BTCUSDT\",\"b\":\"79716.80\",\"B\":\"2.652\",\"a\":\"79716.90\",\"A\":\"15.160\",\"T\":1788564453106,\"E\":1788564453106,\"st\":1}}"}
{"receive_ns":1788564453100901000,"stream":"btcusdt@bookTicker","event_type":"bookTicker","event_time_ms":1788564453109,"raw_json":"{\"stream\":\"btcusdt@bookTicker\",\"data\":{\"e\":\"bookTicker\",\"u\":11478296380863,\"s\":\"BTCUSDT\",\"ps\":\"BTCUSDT\",\"b\":\"79716.80\",\"B\":\"2.652\",\"a\":\"79716.90\",\"A\":\"15.170\",\"T\":1788564453109,\"E\":1788564453109,\"st\":1}}"}
{"receive_ns":1788564453171032000,"stream":"btcusdt@depth@100ms","event_type":"depthUpdate","event_time_ms":1788564453171,"raw_json":"{\"stream\":\"btcusdt@depth@100ms\",\"data\":{\"e\":\"depthUpdate\",\"E\":1788564453171,\"T\":1788564453169,\"s\":\"BTCUSDT\",\"ps\":\"BTCUSDT\",\"U\":11478296378052,\"u\":11478296386235,\"pu\":11478296378033,\"b\":[[\"1000.00\",\"24.754\"],[\"29216.80\",\"0.441\"],[\"29316.80\",\"1.659\"],[\"63773.00\",\"0.000\"],[\"71745.10\",\"0.002\"],[\"75731.00\",\"0.067\"],[\"75731.10\",\"0.004\"],[\"76528.10\",\"0.002\"],[\"78480.80\",\"0.037\"],[\"78919.60\",\"2.865\"],[\"79318.20\",\"3.148\"],[\"79497.60\",\"0.733\"],[\"79500.80\",\"1.003\"],[\"79529.50\",\"1.604\"],[\"79594.40\",\"0.651\"],[\"79698.90\",\"0.140\"],[\"79707.90\",\"0.124\"],[\"79712.40\",\"0.000\"],[\"79712.50\",\"0.000\"]],\"a\":[[\"79716.90\",\"15.170\"],[\"79717.90\",\"0.006\"],[\"79722.10\",\"0.008\"],[\"79792.60\",\"0.502\"],[\"79840.30\",\"0.351\"],[\"79886.30\",\"0.090\"],[\"80078.80\",\"0.764\"],[\"80087.60\",\"1.147\"],[\"80092.90\",\"0.703\"],[\"80094.90\",\"0.000\"],[\"80514.10\",\"0.638\"],[\"80673.50\",\"18.193\"],[\"80830.40\",\"4.937\"],[\"80952.80\",\"0.015\"],[\"80952.90\",\"0.007\"]],\"st\":1}}"}
{"receive_ns":1788564453259377000,"stream":"btcusdt@depth@100ms","event_type":"depthUpdate","event_time_ms":1788564453273,"raw_json":"{\"stream\":\"btcusdt@depth@100ms\",\"data\":{\"e\":\"depthUpdate\",\"E\":1788564453273,\"T\":1788564453271,\"s\":\"BTCUSDT\",\"ps\":\"BTCUSDT\",\"U\":11478296386350,\"u\":11478296393004,\"pu\":11478296386235,\"b\":[[\"29216.80\",\"0.616\"],[\"29316.80\",\"1.484\"],[\"63773.40\",\"0.000\"],[\"71745.10\",\"0.002\"],[\"76528.10\",\"0.000\"],[\"77484.70\",\"0.516\"],[\"78300.80\",\"0.077\"],[\"78574.40\",\"3.780\"],[\"78919.60\",\"2.865\"],[\"79320.20\",\"0.140\"],[\"79529.50\",\"1.804\"],[\"79693.10\",\"0.003\"],[\"79698.30\",\"0.002\"],[\"79709.20\",\"0.027\"],[\"79709.30\",\"1.026\"],[\"79709.40\",\"0.198\"],[\"79709.50\",\"0.027\"],[\"79709.60\",\"0.028\"],[\"79709.80\",\"0.125\"],[\"79709.90\",\"0.130\"],[\"79710.00\",\"0.041\"],[\"79710.10\",\"0.000\"],[\"79710.30\",\"0.001\"],[\"79710.40\",\"0.029\"],[\"79710.60\",\"0.000\"],[\"79710.80\",\"0.012\"],[\"79711.00\",\"0.000\"],[\"79711.20\",\"0.006\"],[\"79711.40\",\"0.000\"],[\"79711.80\",\"0.001\"]],\"a\":[[\"79717.90\",\"0.006\"],[\"79722.10\",\"0.008\"],[\"79733.00\",\"0.630\"],[\"79792.60\",\"0.701\"],[\"80087.60\",\"0.992\"],[\"80115.50\",\"1.373\"],[\"80514.10\",\"0.638\"],[\"80952.80\",\"0.029\"],[\"81311.20\",\"0.030\"],[\"81709.80\",\"0.491\"]],\"st\":1}}"}
{"receive_ns":1788564453276784000,"stream":"btcusdt@bookTicker","event_type":"bookTicker","event_time_ms":1788564453301,"raw_json":"{\"stream\":\"btcusdt@bookTicker\",\"data\":{\"e\":\"bookTicker\",\"u\":11478296394937,\"s\":\"BTCUSDT\",\"ps\":\"BTCUSDT\",\"b\":\"79716.80\",\"B\":\"2.652\",\"a\":\"79716.90\",\"A\":\"15.189\",\"T\":1788564453301,\"E\":1788564453301,\"st\":1}}"}
{"receive_ns":1788564453277042000,"stream":"btcusdt@bookTicker","event_type":"bookTicker","event_time_ms":1788564453302,"raw_json":"{\"stream\":\"btcusdt@bookTicker\",\"data\":{\"e\":\"bookTicker\",\"u\":11478296394966,\"s\":\"BTCUSDT\",\"ps\":\"BTCUSDT\",\"b\":\"79716.80\",\"B\":\"2.652\",\"a\":\"79716.90\",\"A\":\"15.170\",\"T\":1788564453301,\"E\":1788564453302,\"st\":1}}"}
{"receive_ns":1788564453283360000,"stream":"btcusdt@bookTicker","event_type":"bookTicker","event_time_ms":1788564453302,"raw_json":"{\"stream\":\"btcusdt@bookTicker\",\"data\":{\"e\":\"bookTicker\",\"u\":11478296395001,\"s\":\"BTCUSDT\",\"ps\":\"BTCUSDT\",\"b\":\"79716.80\",\"B\":\"2.652\",\"a\":\"79716.90\",\"A\":\"15.171\",\"T\":1788564453302,\"E\":1788564453302,\"st\":1}}"}
{"receive_ns":1788564453356017000,"stream":"btcusdt@depth@100ms","event_type":"depthUpdate","event_time_ms":1788564453375,"raw_json":"{\"stream\":\"btcusdt@depth@100ms\",\"data\":{\"e\":\"depthUpdate\",\"E\":1788564453375,\"T\":1788564453373,\"s\":\"BTCUSDT\",\"ps\":\"BTCUSDT\",\"U\":11478296393101,\"u\":11478296399064,\"pu\":11478296393004,\"b\":[[\"1000.00\",\"24.754\"],[\"29216.80\",\"0.798\"],[\"29316.80\",\"1.302\"],[\"71745.10\",\"0.002\"],[\"76528.10\",\"0.002\"],[\"78122.50\",\"0.161\"],[\"78687.70\",\"0.191\"],[\"78919.60\",\"2.865\"],[\"79058.70\",\"3.662\"],[\"79318.20\",\"3.149\"],[\"79497.60\",\"0.502\"],[\"79500.80\",\"1.003\"],[\"79501.60\",\"0.859\"],[\"79529.50\",\"1.704\"],[\"79531.50\",\"0.256\"],[\"79695.10\",\"0.440\"],[\"79696.50\",\"0.361\"],[\"79698.90\",\"0.240\"],[\"79710.30\",\"0.027\"]],\"a\":[[\"79716.90\",\"15.171\"],[\"79792.60\",\"0.701\"],[\"79886.30\",\"0.090\"],[\"80078.80\",\"0.764\"],[\"80087.60\",\"1.147\"],[\"80115.50\",\"3.242\"],[\"80514.10\",\"0.638\"]],\"st\":1}}"}
{"receive_ns":1788564453404524000,"stream":"btcusdt@bookTicker","event_type":"bookTicker","event_time_ms":1788564453423,"raw_json":"{\"stream\":\"btcusdt@bookTicker\",\"data\":{\"e\":\"bookTicker\",\"u\":11478296402634,\"s\":\"BTCUSDT\",\"ps\":\"BTCUSDT\",\"b\":\"79716.80\",\"B\":\"2.639\",\"a\":\"79716.90\",\"A\":\"15.171\",\"T\":1788564453423,\"E\":1788564453423,\"st\":1}}"}
{"receive_ns":1788564453411404000,"stream":"btcusdt@trade","event_type":"trade","event_time_ms":1788564453423,"raw_json":"{\"stream\":\"btcusdt@trade\",\"data\":{\"e\":\"trade\",\"E\":1788564453423,\"T\":1788564453423,\"s\":\"BTCUSDT\",\"t\":8054096469,\"p\":\"79716.80\",\"q\":\"0.013\",\"X\":\"MARKET\",\"m\":true,\"st\":1}}"}
{"receive_ns":1788564453416774000,"stream":"btcusdt@bookTicker","event_type":"bookTicker","event_time_ms":1788564453424,"raw_json":"{\"stream\":\"btcusdt@bookTicker\",\"data\":{\"e\":\"bookTicker\",\"u\":11478296402722,\"s\":\"BTCUSDT\",\"ps\":\"BTCUSDT\",\"b\":\"79716.80\",\"B\":\"2.639\",\"a\":\"79716.90\",\"A\":\"15.190\",\"T\":1788564453424,\"E\":1788564453424,\"st\":1}}"}
{"receive_ns":1788564453423381000,"stream":"btcusdt@bookTicker","event_type":"bookTicker","event_time_ms":1788564453424,"raw_json":"{\"stream\":\"btcusdt@bookTicker\",\"data\":{\"e\":\"bookTicker\",\"u\":11478296402730,\"s\":\"BTCUSDT\",\"ps\":\"BTCUSDT\",\"b\":\"79716.80\",\"B\":\"2.639\",\"a\":\"79716.90\",\"A\":\"15.198\",\"T\":1788564453424,\"E\":1788564453424,\"st\":1}}"}
{"receive_ns":1788564453423639000,"stream":"btcusdt@bookTicker","event_type":"bookTicker","event_time_ms":1788564453424,"raw_json":"{\"stream\":\"btcusdt@bookTicker\",\"data\":{\"e\":\"bookTicker\",\"u\":11478296402761,\"s\":\"BTCUSDT\",\"ps\":\"BTCUSDT\",\"b\":\"79716.80\",\"B\":\"2.639\",\"a\":\"79716.90\",\"A\":\"15.200\",\"T\":1788564453424,\"E\":1788564453424,\"st\":1}}"}
{"receive_ns":1788564453423857000,"stream":"btcusdt@bookTicker","event_type":"bookTicker","event_time_ms":1788564453425,"raw_json":"{\"stream\":\"btcusdt@bookTicker\",\"data\":{\"e\":\"bookTicker\",\"u\":11478296402933,\"s\":\"BTCUSDT\",\"ps\":\"BTCUSDT\",\"b\":\"79716.80\",\"B\":\"2.639\",\"a\":\"79716.90\",\"A\":\"15.181\",\"T\":1788564453425,\"E\":1788564453425,\"st\":1}}"}
{"receive_ns":1788564453424035000,"stream":"btcusdt@bookTicker","event_type":"bookTicker","event_time_ms":1788564453425,"raw_json":"{\"stream\":\"btcusdt@bookTicker\",\"data\":{\"e\":\"bookTicker\",\"u\":11478296402952,\"s\":\"BTCUSDT\",\"ps\":\"BTCUSDT\",\"b\":\"79716.80\",\"B\":\"2.639\",\"a\":\"79716.90\",\"A\":\"15.179\",\"T\":1788564453425,\"E\":1788564453425,\"st\":1}}"}
{"receive_ns":1788564453430600000,"stream":"btcusdt@bookTicker","event_type":"bookTicker","event_time_ms":1788564453447,"raw_json":"{\"stream\":\"btcusdt@bookTicker\",\"data\":{\"e\":\"bookTicker\",\"u\":11478296404361,\"s\":\"BTCUSDT\",\"ps\":\"BTCUSDT\",\"b\":\"79716.80\",\"B\":\"2.634\",\"a\":\"79716.90\",\"A\":\"15.179\",\"T\":1788564453447,\"E\":1788564453447,\"st\":1}}"}
{"receive_ns":1788564453430797000,"stream":"btcusdt@trade","event_type":"trade","event_time_ms":1788564453447,"raw_json":"{\"stream\":\"btcusdt@trade\",\"data\":{\"e\":\"trade\",\"E\":1788564453447,\"T\":1788564453447,\"s\":\"BTCUSDT\",\"t\":8054096470,\"p\":\"79716.80\",\"q\":\"0.005\",\"X\":\"MARKET\",\"m\":true,\"st\":1}}"}
{"receive_ns":1788564453442575000,"stream":"btcusdt@bookTicker","event_type":"bookTicker","event_time_ms":1788564453449,"raw_json":"{\"stream\":\"btcusdt@bookTicker\",\"data\":{\"e\":\"bookTicker\",\"u\":11478296404433,\"s\":\"BTCUSDT\",\"ps\":\"BTCUSDT\",\"b\":\"79716.80\",\"B\":\"2.634\",\"a\":\"79716.90\",\"A\":\"15.181\",\"T\":1788564453448,\"E\":1788564453449,\"st\":1}}"}
{"receive_ns":1788564453451459000,"stream":"btcusdt@bookTicker","event_type":"bookTicker","event_time_ms":1788564453449,"raw_json":"{\"stream\":\"btcusdt@bookTicker\",\"data\":{\"e\":\"bookTicker\",\"u\":11478296404454,\"s\":\"BTCUSDT\",\"ps\":\"BTCUSDT\",\"b\":\"79716.80\",\"B\":\"2.634\",\"a\":\"79716.90\",\"A\":\"15.173\",\"T\":1788564453448,\"E\":1788564453449,\"st\":1}}"}
{"receive_ns":1788564453462975000,"stream":"btcusdt@bookTicker","event_type":"bookTicker","event_time_ms":1788564453449,"raw_json":"{\"stream\":\"btcusdt@bookTicker\",\"data\":{\"e\":\"bookTicker\",\"u\":11478296404470,\"s\":\"BTCUSDT\",\"ps\":\"BTCUSDT\",\"b\":\"79716.80\",\"B\":\"2.634\",\"a\":\"79716.90\",\"A\":\"15.192\",\"T\":1788564453448,\"E\":1788564453449,\"st\":1}}"}
{"receive_ns":1788564453468509000,"stream":"btcusdt@bookTicker","event_type":"bookTicker","event_time_ms":1788564453449,"raw_json":"{\"stream\":\"btcusdt@bookTicker\",\"data\":{\"e\":\"bookTicker\",\"u\":11478296404631,\"s\":\"BTCUSDT\",\"ps\":\"BTCUSDT\",\"b\":\"79716.80\",\"B\":\"2.634\",\"a\":\"79716.90\",\"A\":\"15.190\",\"T\":1788564453449,\"E\":1788564453449,\"st\":1}}"}
{"receive_ns":1788564453474861000,"stream":"btcusdt@bookTicker","event_type":"bookTicker","event_time_ms":1788564453449,"raw_json":"{\"stream\":\"btcusdt@bookTicker\",\"data\":{\"e\":\"bookTicker\",\"u\":11478296404640,\"s\":\"BTCUSDT\",\"ps\":\"BTCUSDT\",\"b\":\"79716.80\",\"B\":\"2.634\",\"a\":\"79716.90\",\"A\":\"15.171\",\"T\":1788564453449,\"E\":1788564453449,\"st\":1}}"}
{"receive_ns":1788564453481590000,"stream":"btcusdt@depth@100ms","event_type":"depthUpdate","event_time_ms":1788564453477,"raw_json":"{\"stream\":\"btcusdt@depth@100ms\",\"data\":{\"e\":\"depthUpdate\",\"E\":1788564453477,\"T\":1788564453474,\"s\":\"BTCUSDT\",\"ps\":\"BTCUSDT\",\"U\":11478296399117,\"u\":11478296406207,\"pu\":11478296399064,\"b\":[[\"1000.00\",\"24.754\"],[\"29216.80\",\"0.973\"],[\"29316.80\",\"1.127\"],[\"71745.10\",\"0.002\"],[\"75831.90\",\"0.102\"],[\"76528.10\",\"0.000\"],[\"78919.60\",\"2.865\"],[\"79318.20\",\"3.149\"],[\"79320.20\",\"0.140\"],[\"79529.50\",\"1.203\"],[\"79698.90\",\"0.140\"],[\"79709.40\",\"0.200\"],[\"79710.70\",\"0.029\"],[\"79711.20\",\"0.004\"],[\"79716.80\",\"2.634\"]],\"a\":[[\"79716.90\",\"15.171\"],[\"79717.90\",\"0.014\"],[\"79719.80\",\"0.002\"],[\"79722.10\",\"0.000\"],[\"79792.60\",\"0.701\"],[\"80087.60\",\"1.147\"],[\"80112.00\",\"0.557\"],[\"80314.80\",\"1.884\"],[\"80514.10\",\"0.638\"],[\"80888.70\",\"2.036\"]],\"st\":1}}"}
{"receive_ns":1788564453557760000,"stream":"btcusdt@depth@100ms","event_type":"depthUpdate","event_time_ms":1788564453579,"raw_json":"{\"stream\":\"btcusdt@depth@100ms\",\"data\":{\"e\":\"depthUpdate\",\"E\":1788564453579,\"T\":1788564453578,\"s\":\"BTCUSDT\",\"ps\":\"BTCUSDT\",\"U\":11478296406405,\"u\":11478296411568,\"pu\":11478296406207,\"b\":[[\"29216.80\",\"1.155\"],[\"29316.80\",\"0.945\"],[\"71745.10\",\"0.002\"],[\"78606.90\",\"0.222\"],[\"78743.20\",\"0.127\"],[\"78919.60\",\"2.865\"],[\"79500.80\",\"0.000\"],[\"79501.60\",\"0.628\"],[\"79529.50\",\"0.200\"],[\"79531.50\",\"0.006\"],[\"79698.90\",\"0.315\"],[\"79708.70\",\"0.027\"],[\"79708.80\",\"0.031\"],[\"79708.90\",\"1.564\"],[\"79709.10\",\"0.027\"],[\"79709.60\",\"0.002\"],[\"79709.80\",\"0.099\"],[\"79709.90\",\"0.104\"],[\"79710.00\",\"0.015\"],[\"79710.30\",\"0.001\"],[\"79710.70\",\"0.003\"],[\"79715.20\",\"0.002\"]],\"a\":[[\"79792.60\",\"0.451\"],[\"79886.30\",\"0.000\"],[\"80078.80\",\"0.002\"],[\"80087.60\",\"0.579\"],[\"80115.50\",\"3.241\"],[\"80514.10\",\"0.638\"]],\"st\":1}}"}
{"receive_ns":1788564453656152000,"stream":"btcusdt@depth@100ms","event_type":"depthUpdate","event_time_ms":1788564453681,"raw_json":"{\"stream\":\"btcusdt@depth@100ms\",\"data\":{\"e\":\"depthUpdate\",\"E\":1788564453681,\"T\":1788564453678,\"s\":\"BTCUSDT\",\"ps\":\"BTCUSDT\",\"U\":11478296411637,\"u\":11478296416753,\"pu\":11478296411568,\"b\":[[\"1000.00\",\"24.754\"],[\"29216.80\",\"1.330\"],[\"29316.80\",\"0.770\"],[\"71745.10\",\"0.002\"],[\"76528.10\",\"0.002\"],[\"78720.30\",\"1.734\"],[\"78899.30\",\"4.747\"],[\"78919.60\",\"2.865\"],[\"79320.20\",\"0.000\"],[\"79497.60\",\"0.733\"],[\"79500.80\",\"1.003\"],[\"79529.50\",\"1.003\"],[\"79698.90\",\"0.991\"]],\"a\":[[\"79792.60\",\"0.252\"],[\"79886.30\",\"0.090\"],[\"80078.80\",\"0.764\"],[\"80087.60\",\"1.147\"],[\"80486.80\",\"0.000\"],[\"80514.10\",\"0.638\"],[\"80673.50\",\"19.431\"],[\"80817.80\",\"0.018\"],[\"80852.00\",\"4.617\"],[\"80880.80\",\"0.247\"],[\"80931.70\",\"0.865\"]],\"st\":1}}"}
{"receive_ns":1788564453667634000,"stream":"btcusdt@bookTicker","event_type":"bookTicker","event_time_ms":1788564453681,"raw_json":"{\"stream\":\"btcusdt@bookTicker\",\"data\":{\"e\":\"bookTicker\",\"u\":11478296416898,\"s\":\"BTCUSDT\",\"ps\":\"BTCUSDT\",\"b\":\"79716.80\",\"B\":\"2.634\",\"a\":\"79716.90\",\"A\":\"15.190\",\"T\":1788564453681,\"E\":1788564453681,\"st\":1}}"}
{"receive_ns":1788564453674352000,"stream":"btcusdt@bookTicker","event_type":"bookTicker","event_time_ms":1788564453682,"raw_json":"{\"stream\":\"btcusdt@bookTicker\",\"data\":{\"e\":\"bookTicker\",\"u\":11478296416976,\"s\":\"BTCUSDT\",\"ps\":\"BTCUSDT\",\"b\":\"79716.80\",\"B\":\"2.634\",\"a\":\"79716.90\",\"A\":\"15.171\",\"T\":1788564453682,\"E\":1788564453682,\"st\":1}}"}
{"receive_ns":1788564453764438000,"stream":"btcusdt@bookTicker","event_type":"bookTicker","event_time_ms":1788564453777,"raw_json":"{\"stream\":\"btcusdt@bookTicker\",\"data\":{\"e\":\"bookTicker\",\"u\":11478296421216,\"s\":\"BTCUSDT\",\"ps\":\"BTCUSDT\",\"b\":\"79716.80\",\"B\":\"2.634\",\"a\":\"79716.90\",\"A\":\"15.155\",\"T\":1788564453777,\"E\":1788564453777,\"st\":1}}"}
{"receive_ns":1788564453770012000,"stream":"btcusdt@bookTicker","event_type":"bookTicker","event_time_ms":1788564453780,"raw_json":"{\"stream\":\"btcusdt@bookTicker\",\"data\":{\"e\":\"bookTicker\",\"u\":11478296421382,\"s\":\"BTCUSDT\",\"ps\":\"BTCUSDT\",\"b\":\"79716.80\",\"B\":\"2.634\",\"a\":\"79716.90\",\"A\":\"15.170\",\"T\":1788564453780,\"E\":1788564453780,\"st\":1}}"}
{"receive_ns":1788564453781521000,"stream":"btcusdt@depth@100ms","event_type":"depthUpdate","event_time_ms":1788564453783,"raw_json":"{\"stream\":\"btcusdt@depth@100ms\",\"data\":{\"e\":\"depthUpdate\",\"E\":1788564453783,\"T\":1788564453782,\"s\":\"BTCUSDT\",\"ps\":\"BTCUSDT\",\"U\":11478296416898,\"u\":11478296421528,\"pu\":11478296416753,\"b\":[[\"1000.00\",\"24.754\"],[\"29216.80\",\"1.512\"],[\"29316.80\",\"0.588\"],[\"71745.10\",\"0.002\"],[\"71782.00\",\"0.000\"],[\"76528.10\",\"0.000\"],[\"78606.90\",\"0.000\"],[\"78800.10\",\"0.786\"],[\"78919.60\",\"2.865\"],[\"79318.20\",\"3.150\"],[\"79320.20\",\"0.140\"],[\"79507.10\",\"6.807\"],[\"79529.50\",\"1.453\"],[\"79625.20\",\"0.000\"],[\"79625.40\",\"3.754\"],[\"79698.90\",\"0.140\"],[\"79710.40\",\"0.055\"],[\"79710.60\",\"0.026\"]],\"a\":[[\"79716.90\",\"15.170\"],[\"79717.90\",\"0.014\"],[\"79722.10\",\"0.000\"],[\"79792.60\",\"0.701\"],[\"79807.70\",\"0.002\"],[\"79807.80\",\"3.866\"],[\"79927.50\",\"7.569\"],[\"79927.60\",\"0.017\"],[\"79938.70\",\"8.497\"],[\"80087.60\",\"1.147\"],[\"80514.10\",\"0.640\"],[\"81311.20\",\"0.027\"]],\"st\":1}}"}
{"receive_ns":1788564453860833000,"stream":"btcusdt@depth@100ms","event_type":"depthUpdate","event_time_ms":1788564453885,"raw_json":"{\"stream\":\"btcusdt@depth@100ms\",\"data\":{\"e\":\"depthUpdate\",\"E\":1788564453885,\"T\":1788564453881,\"s\":\"BTCUSDT\",\"ps\":\"BTCUSDT\",\"U\":11478296421552,\"u\":11478296427725,\"pu\":11478296421528,\"b\":[[\"29216.80\",\"1.687\"],[\"29316.80\",\"0.413\"],[\"71745.10\",\"0.002\"],[\"76528.10\",\"0.002\"],[\"78919.60\",\"2.865\"],[\"79497.60\",\"0.733\"],[\"79500.80\",\"1.003\"],[\"79529.50\",\"1.628\"],[\"79629.80\",\"0.009\"],[\"79631.80\",\"1.215\"],[\"79645.00\",\"0.004\"],[\"79658.50\",\"0.077\"],[\"79679.20\",\"0.071\"],[\"79698.90\",\"0.065\"]],\"a\":[[\"79717.90\",\"0.014\"],[\"79722.10\",\"0.000\"],[\"79752.80\",\"0.315\"],[\"79756.80\",\"0.730\"],[\"79772.80\",\"0.314\"],[\"79773.60\",\"0.009\"],[\"79788.30\",\"6.071\"],[\"79790.30\",\"31.824\"],[\"79792.60\",\"0.701\"],[\"79792.90\",\"1.937\"],[\"79793.00\",\"0.014\"],[\"79800.00\",\"4.325\"],[\"79802.30\",\"0.000\"],[\"79886.30\",\"0.090\"],[\"80078.80\",\"0.764\"],[\"80087.60\",\"0.729\"],[\"80514.10\",\"1.879\"],[\"80872.80\",\"4.103\"],[\"80952.50\",\"3.332\"]],\"st\":1}}"}
{"receive_ns":1788564453969084000,"stream":"btcusdt@depth@100ms","event_type":"depthUpdate","event_time_ms":1788564453987,"raw_json":"{\"stream\":\"btcusdt@depth@100ms\",\"data\":{\"e\":\"depthUpdate\",\"E\":1788564453987,\"T\":1788564453986,\"s\":\"BTCUSDT\",\"ps\":\"BTCUSDT\",\"U\":11478296427947,\"u\":11478296433281,\"pu\":11478296427725,\"b\":[[\"1000.00\",\"24.754\"],[\"29216.80\",\"1.785\"],[\"29316.80\",\"0.273\"],[\"29616.80\",\"0.042\"],[\"71745.10\",\"0.002\"],[\"75716.90\",\"0.006\"],[\"78584.80\",\"0.456\"],[\"78919.60\",\"2.865\"],[\"79320.20\",\"0.140\"],[\"79501.60\",\"0.828\"],[\"79529.50\",\"1.679\"],[\"79589.20\",\"0.001\"],[\"79591.70\",\"2.063\"],[\"79700.00\",\"0.314\"],[\"79708.00\",\"0.007\"]],\"a\":[[\"79786.70\",\"0.199\"],[\"79792.60\",\"0.002\"],[\"79840.70\",\"0.562\"],[\"79843.00\",\"0.002\"],[\"79866.40\",\"0.250\"],[\"80087.60\",\"0.992\"],[\"80514.10\",\"1.879\"]],\"st\":1}}"}
{"receive_ns":1788564454047729000,"stream":"btcusdt@bookTicker","event_type":"bookTicker","event_time_ms":1788564454066,"raw_json":"{\"stream\":\"btcusdt@bookTicker\",\"data\":{\"e\":\"bookTicker\",\"u\":11478296438876,\"s\":\"BTCUSDT\",\"ps\":\"BTCUSDT\",\"b\":\"79716.80\",\"B\":\"2.634\",\"a\":\"79716.90\",\"A\":\"15.189\",\"T\":1788564454066,\"E\":1788564454066,\"st\":1}}"}
{"receive_ns":1788564454059569000,"stream":"btcusdt@bookTicker","event_type":"bookTicker","event_time_ms":1788564454067,"raw_json":"{\"stream\":\"btcusdt@bookTicker\",\"data\":{\"e\":\"bookTicker\",\"u\":11478296438931,\"s\":\"BTCUSDT\",\"ps\":\"BTCUSDT\",\"b\":\"79716.80\",\"B\":\"2.634\",\"a\":\"79716.90\",\"A\":\"15.170\",\"T\":1788564454066,\"E\":1788564454067,\"st\":1}}"}
{"receive_ns":1788564454081912000,"stream":"btcusdt@depth@100ms","event_type":"depthUpdate","event_time_ms":1788564454089,"raw_json":"{\"stream\":\"btcusdt@depth@100ms\",\"data\":{\"e\":\"depthUpdate\",\"E\":1788564454089,\"T\":1788564454087,\"s\":\"BTCUSDT\",\"ps\":\"BTCUSDT\",\"U\":11478296433350,\"u\":11478296439886,\"pu\":11478296433281,\"b\":[[\"1000.00\",\"24.754\"],[\"29216.80\",\"1.848\"],[\"29316.80\",\"0.154\"],[\"29616.80\",\"0.098\"],[\"71745.10\",\"0.002\"],[\"76528.10\",\"0.000\"],[\"78122.50\",\"0.164\"],[\"78919.60\",\"2.866\"],[\"78978.60\",\"0.000\"],[\"79318.20\",\"3.160\"],[\"79497.60\",\"0.733\"],[\"79500.80\",\"1.003\"],[\"79529.50\",\"1.929\"],[\"79629.80\",\"6.153\"],[\"79631.80\",\"1.922\"],[\"79658.50\",\"3.661\"],[\"79679.20\",\"0.497\"],[\"79699.20\",\"0.069\"],[\"79699.40\",\"0.006\"],[\"79700.80\",\"0.001\"],[\"79701.00\",\"0.020\"],[\"79702.50\",\"0.000\"],[\"79708.70\",\"0.001\"],[\"79708.80\",\"0.005\"],[\"79710.70\",\"0.029\"],[\"79711.10\",\"0.051\"]],\"a\":[[\"79716.90\",\"15.170\"],[\"79717.90\",\"0.014\"],[\"79722.10\",\"0.000\"],[\"79724.10\",\"0.252\"],[\"79726.00\",\"1.295\"],[\"79751.70\",\"0.431\"],[\"79772.50\",\"5.511\"],[\"79787.10\",\"0.038\"],[\"79788.30\",\"1.367\"],[\"79790.30\",\"0.045\"],[\"79792.60\",\"0.252\"],[\"79793.00\",\"31.812\"],[\"79793.50\",\"0.046\"],[\"79795.70\",\"0.000\"],[\"79801.20\",\"6.156\"],[\"79886.30\",\"0.090\"],[\"80078.80\",\"0.764\"],[\"80087.60\",\"1.147\"],[\"80454.90\",\"0.000\"],[\"80514.10\",\"1.879\"],[\"80848.90\",\"0.592\"]],\"st\":1}}"}
{"receive_ns":1788564454099045000,"stream":"btcusdt@bookTicker","event_type":"bookTicker","event_time_ms":1788564454109,"raw_json":"{\"stream\":\"btcusdt@bookTicker\",\"data\":{\"e\":\"bookTicker\",\"u\":11478296441300,\"s\":\"BTCUSDT\",\"ps\":\"BTCUSDT\",\"b\":\"79716.80\",\"B\":\"2.613\",\"a\":\"79716.90\",\"A\":\"15.170\",\"T\":1788564454109,\"E\":1788564454109,\"st\":1}}"}
{"receive_ns":1788564454105630000,"stream":"btcusdt@bookTicker","event_type":"bookTicker","event_time_ms":1788564454112,"raw_json":"{\"stream\":\"btcusdt@bookTicker\",\"data\":{\"e\":\"bookTicker\",\"u\":11478296441501,\"s\":\"BTCUSDT\",\"ps\":\"BTCUSDT\",\"b\":\"79716.80\",\"B\":\"2.633\",\"a\":\"79716.90\",\"A\":\"15.170\",\"T\":1788564454112,\"E\":1788564454112,\"st\":1}}"}
{"receive_ns":1788564454105914000,"stream":"btcusdt@bookTicker","event_type":"bookTicker","event_time_ms":1788564454121,"raw_json":"{\"stream\":\"btcusdt@bookTicker\",\"data\":{\"e\":\"bookTicker\",\"u\":11478296442121,\"s\":\"BTCUSDT\",\"ps\":\"BTCUSDT\",\"b\":\"79716.80\",\"B\":\"2.633\",\"a\":\"79716.90\",\"A\":\"15.189\",\"T\":1788564454120,\"E\":1788564454121,\"st\":1}}"}
{"receive_ns":1788564454112477000,"stream":"btcusdt@bookTicker","event_type":"bookTicker","event_time_ms":1788564454121,"raw_json":"{\"stream\":\"btcusdt@bookTicker\",\"data\":{\"e\":\"bookTicker\",\"u\":11478296442166,\"s\":\"BTCUSDT\",\"ps\":\"BTCUSDT\",\"b\":\"79716.80\",\"B\":\"2.633\",\"a\":\"79716.90\",\"A\":\"15.170\",\"T\":1788564454121,\"E\":1788564454121,\"st\":1}}"}
{"receive_ns":1788564454132049000,"stream":"btcusdt@bookTicker","event_type":"bookTicker","event_time_ms":1788564454151,"raw_json":"{\"stream\":\"btcusdt@bookTicker\",\"data\":{\"e\":\"bookTicker\",\"u\":11478296443868,\"s\":\"BTCUSDT\",\"ps\":\"BTCUSDT\",\"b\":\"79716.80\",\"B\":\"2.633\",\"a\":\"79716.90\",\"A\":\"15.105\",\"T\":1788564454151,\"E\":1788564454151,\"st\":1}}"}
{"receive_ns":1788564454137394000,"stream":"btcusdt@trade","event_type":"trade","event_time_ms":1788564454151,"raw_json":"{\"stream\":\"btcusdt@trade\",\"data\":{\"e\":\"trade\",\"E\":1788564454151,\"T\":1788564454151,\"s\":\"BTCUSDT\",\"t\":8054096471,\"p\":\"79716.90\",\"q\":\"0.065\",\"X\":\"MARKET\",\"m\":false,\"st\":1}}"}
{"receive_ns":1788564454150359000,"stream":"btcusdt@bookTicker","event_type":"bookTicker","event_time_ms":1788564454152,"raw_json":"{\"stream\":\"btcusdt@bookTicker\",\"data\":{\"e\":\"bookTicker\",\"u\":11478296443981,\"s\":\"BTCUSDT\",\"ps\":\"BTCUSDT\",\"b\":\"79716.80\",\"B\":\"2.633\",\"a\":\"79716.90\",\"A\":\"15.107\",\"T\":1788564454152,\"E\":1788564454152,\"st\":1}}"}
{"receive_ns":1788564454150586000,"stream":"btcusdt@bookTicker","event_type":"bookTicker","event_time_ms":1788564454152,"raw_json":"{\"stream\":\"btcusdt@bookTicker\",\"data\":{\"e\":\"bookTicker\",\"u\":11478296443989,\"s\":\"BTCUSDT\",\"ps\":\"BTCUSDT\",\"b\":\"79716.80\",\"B\":\"2.633\",\"a\":\"79716.90\",\"A\":\"15.126\",\"T\":1788564454152,\"E\":1788564454152,\"st\":1}}"}
{"receive_ns":1788564454163380000,"stream":"btcusdt@bookTicker","event_type":"bookTicker","event_time_ms":1788564454153,"raw_json":"{\"stream\":\"btcusdt@bookTicker\",\"data\":{\"e\":\"bookTicker\",\"u\":11478296444107,\"s\":\"BTCUSDT\",\"ps\":\"BTCUSDT\",\"b\":\"79716.80\",\"B\":\"2.633\",\"a\":\"79716.90\",\"A\":\"15.124\",\"T\":1788564454153,\"E\":1788564454153,\"st\":1}}"}
{"receive_ns":1788564454163607000,"stream":"btcusdt@bookTicker","event_type":"bookTicker","event_time_ms":1788564454153,"raw_json":"{\"stream\":\"btcusdt@bookTicker\",\"data\":{\"e\":\"bookTicker\",\"u\":11478296444122,\"s\":\"BTCUSDT\",\"ps\":\"BTCUSDT\",\"b\":\"79716.80\",\"B\":\"2.633\",\"a\":\"79716.90\",\"A\":\"15.105\",\"T\":1788564454153,\"E\":1788564454153,\"st\":1}}"}
{"receive_ns":1788564454180255000,"stream":"btcusdt@depth@100ms","event_type":"depthUpdate","event_time_ms":1788564454191,"raw_json":"{\"stream\":\"btcusdt@depth@100ms\",\"data\":{\"e\":\"depthUpdate\",\"E\":1788564454191,\"T\":1788564454190,\"s\":\"BTCUSDT\",\"ps\":\"BTCUSDT\",\"U\":11478296440023,\"u\":11478296446543,\"pu\":11478296439886,\"b\":[[\"29216.80\",\"1.904\"],[\"29316.80\",\"0.035\"],[\"29616.80\",\"0.161\"],[\"71745.10\",\"0.002\"],[\"76528.10\",\"0.002\"],[\"78487.20\",\"0.002\"],[\"78731.90\",\"1.257\"],[\"78733.80\",\"2.514\"],[\"78919.60\",\"2.866\"],[\"78978.60\",\"0.005\"],[\"79501.60\",\"0.628\"],[\"79529.50\",\"2.129\"],[\"79588.80\",\"10.242\"],[\"79698.60\",\"1.793\"],[\"79699.40\",\"0.002\"],[\"79700.70\",\"1.394\"],[\"79700.80\",\"0.012\"],[\"79701.90\",\"0.270\"],[\"79708.90\",\"1.538\"],[\"79709.10\",\"0.001\"],[\"79709.20\",\"0.001\"],[\"79709.30\",\"1.000\"],[\"79710.20\",\"0.252\"],[\"79711.40\",\"0.026\"],[\"79712.10\",\"0.028\"],[\"79712.80\",\"0.026\"],[\"79712.90\",\"0.026\"],[\"79713.60\",\"0.002\"],[\"79716.80\",\"2.633\"]],\"a\":[[\"79716.90\",\"15.105\"],[\"79724.10\",\"0.002\"],[\"79724.70\",\"0.269\"],[\"79786.70\",\"0.000\"],[\"79790.30\",\"0.059\"],[\"79792.60\",\"0.451\"],[\"79841.90\",\"10.241\"],[\"79877.70\",\"0.000\"],[\"80087.60\",\"1.147\"],[\"80514.10\",\"1.879\"],[\"80713.40\",\"4.683\"],[\"80812.10\",\"16.933\"],[\"80848.90\",\"0.740\"]],\"st\":1}}"}
{"receive_ns":1788564454275543000,"stream":"btcusdt@bookTicker","event_type":"bookTicker","event_time_ms":1788564454290,"raw_json":"{\"stream\":\"btcusdt@bookTicker\",\"data\":{\"e\":\"bookTicker\",\"u\":11478296453598,\"s\":\"BTCUSDT\",\"ps\":\"BTCUSDT\",\"b\":\"79716.80\",\"B\":\"2.633\",\"a\":\"79716.90\",\"A\":\"15.090\",\"T\":1788564454290,\"E\":1788564454290,\"st\":1}}"}
{"receive_ns":1788564454288288000,"stream":"btcusdt@depth@100ms","event_type":"depthUpdate","event_time_ms":1788564454293,"raw_json":"{\"stream\":\"btcusdt@depth@100ms\",\"data\":{\"e\":\"depthUpdate\",\"E\":1788564454293,\"T\":1788564454292,\"s\":\"BTCUSDT\",\"ps\":\"BTCUSDT\",\"U\":11478296446646,\"u\":11478296453878,\"pu\":11478296446543,\"b\":[[\"1000.00\",\"24.754\"],[\"29216.80\",\"1.799\"],[\"29316.80\",\"0.000\"],[\"29616.80\",\"0.301\"],[\"63773.40\",\"0.000\"],[\"71745.10\",\"0.002\"],[\"75731.00\",\"0.069\"],[\"76528.10\",\"0.000\"],[\"78743.20\",\"0.000\"],[\"78899.30\",\"3.481\"],[\"79257.00\",\"0.030\"],[\"79318.20\",\"3.150\"],[\"79320.20\",\"0.140\"],[\"79477.60\",\"0.003\"],[\"79497.60\",\"0.502\"],[\"79500.80\",\"0.000\"],[\"79529.50\",\"0.951\"],[\"79591.70\",\"2.929\"],[\"79594.40\",\"0.000\"],[\"79621.10\",\"0.040\"],[\"79693.10\",\"0.003\"],[\"79709.30\",\"1.001\"],[\"79710.20\",\"0.001\"],[\"79710.30\",\"0.252\"],[\"79711.30\",\"0.026\"],[\"79712.10\",\"0.002\"],[\"79712.70\",\"0.026\"],[\"79712.80\",\"0.000\"],[\"79712.90\",\"0.000\"]],\"a\":[[\"79716.90\",\"15.090\"],[\"79733.00\",\"0.630\"],[\"79790.30\",\"31.857\"],[\"79792.60\",\"0.451\"],[\"79793.00\",\"0.014\"],[\"79840.30\",\"0.001\"],[\"79840.70\",\"1.972\"],[\"79866.40\",\"0.000\"],[\"79886.30\",\"0.000\"],[\"80036.90\",\"0.000\"],[\"80040.10\",\"0.188\"],[\"80078.80\",\"0.002\"],[\"80087.60\",\"0.579\"],[\"80196.10\",\"0.000\"],[\"80199.50\",\"0.684\"],[\"80355.30\",\"1.296\"],[\"80358.90\",\"0.188\"],[\"80454.90\",\"0.005\"],[\"80514.10\",\"1.881\"],[\"80684.40\",\"5.943\"],[\"80832.90\",\"20.203\"]],\"st\":1}}"}
{"receive_ns":1788564454294395000,"stream":"btcusdt@bookTicker","event_type":"bookTicker","event_time_ms":1788564454293,"raw_json":"{\"stream\":\"btcusdt@bookTicker\",\"data\":{\"e\":\"bookTicker\",\"u\":11478296453891,\"s\":\"BTCUSDT\",\"ps\":\"BTCUSDT\",\"b\":\"79716.80\",\"B\":\"2.633\",\"a\":\"79716.90\",\"A\":\"15.111\",\"T\":1788564454292,\"E\":1788564454293,\"st\":1}}"}
{"receive_ns":1788564454299923000,"stream":"btcusdt@bookTicker","event_type":"bookTicker","event_time_ms":1788564454294,"raw_json":"{\"stream\":\"btcusdt@bookTicker\",\"data\":{\"e\":\"bookTicker\",\"u\":11478296454032,\"s\":\"BTCUSDT\",\"ps\":\"BTCUSDT\",\"b\":\"79716.80\",\"B\":\"2.633\",\"a\":\"79716.90\",\"A\":\"15.110\",\"T\":1788564454294,\"E\":1788564454294,\"st\":1}}"}
{"receive_ns":1788564454310735000,"stream":"btcusdt@trade","event_type":"trade","event_time_ms":1788564454294,"raw_json":"{\"stream\":\"btcusdt@trade\",\"data\":{\"e\":\"trade\",\"E\":1788564454294,\"T\":1788564454294,\"s\":\"BTCUSDT\",\"t\":8054096472,\"p\":\"79716.90\",\"q\":\"0.001\",\"X\":\"MARKET\",\"m\":false,\"st\":1}}"}
{"receive_ns":1788564454317007000,"stream":"btcusdt@bookTicker","event_type":"bookTicker","event_time_ms":1788564454296,"raw_json":"{\"stream\":\"btcusdt@bookTicker\",\"data\":{\"e\":\"bookTicker\",\"u\":11478296454110,\"s\":\"BTCUSDT\",\"ps\":\"BTCUSDT\",\"b\":\"79716.80\",\"B\":\"2.633\",\"a\":\"79716.90\",\"A\":\"15.129\",\"T\":1788564454296,\"E\":1788564454296,\"st\":1}}"}
{"receive_ns":1788564454323055000,"stream":"btcusdt@bookTicker","event_type":"bookTicker","event_time_ms":1788564454296,"raw_json":"{\"stream\":\"btcusdt@bookTicker\",\"data\":{\"e\":\"bookTicker\",\"u\":11478296454165,\"s\":\"BTCUSDT\",\"ps\":\"BTCUSDT\",\"b\":\"79716.80\",\"B\":\"2.633\",\"a\":\"79716.90\",\"A\":\"15.131\",\"T\":1788564454296,\"E\":1788564454296,\"st\":1}}"}
{"receive_ns":1788564454341565000,"stream":"btcusdt@bookTicker","event_type":"bookTicker","event_time_ms":1788564454297,"raw_json":"{\"stream\":\"btcusdt@bookTicker\",\"data\":{\"e\":\"bookTicker\",\"u\":11478296454214,\"s\":\"BTCUSDT\",\"ps\":\"BTCUSDT\",\"b\":\"79716.80\",\"B\":\"2.633\",\"a\":\"79716.90\",\"A\":\"15.112\",\"T\":1788564454296,\"E\":1788564454297,\"st\":1}}"}
{"receive_ns":1788564454364667000,"stream":"btcusdt@bookTicker","event_type":"bookTicker","event_time_ms":1788564454297,"raw_json":"{\"stream\":\"btcusdt@bookTicker\",\"data\":{\"e\":\"bookTicker\",\"u\":11478296454228,\"s\":\"BTCUSDT\",\"ps\":\"BTCUSDT\",\"b\":\"79716.80\",\"B\":\"2.633\",\"a\":\"79716.90\",\"A\":\"15.110\",\"T\":1788564454297,\"E\":1788564454297,\"st\":1}}"}
{"receive_ns":1788564454375869000,"stream":"btcusdt@depth@100ms","event_type":"depthUpdate","event_time_ms":1788564454395,"raw_json":"{\"stream\":\"btcusdt@depth@100ms\",\"data\":{\"e\":\"depthUpdate\",\"E\":1788564454395,\"T\":1788564454393,\"s\":\"BTCUSDT\",\"ps\":\"BTCUSDT\",\"U\":11478296453891,\"u\":11478296459292,\"pu\":11478296453878,\"b\":[[\"1000.00\",\"24.754\"],[\"29216.80\",\"1.617\"],[\"29616.80\",\"0.483\"],[\"71745.10\",\"0.002\"],[\"75718.00\",\"0.513\"],[\"76528.10\",\"0.002\"],[\"78122.50\",\"0.161\"],[\"78919.60\",\"2.866\"],[\"79318.20\",\"3.149\"],[\"79500.80\",\"1.003\"],[\"79501.60\",\"0.859\"],[\"79529.50\",\"1.929\"],[\"79594.40\",\"0.722\"],[\"79709.40\",\"0.198\"],[\"79711.70\",\"0.026\"],[\"79712.50\",\"0.026\"],[\"79712.70\",\"0.000\"],[\"79713.40\",\"0.000\"]],\"a\":[[\"79716.90\",\"15.110\"],[\"79717.90\",\"0.006\"],[\"79722.10\",\"0.008\"],[\"79772.80\",\"0.316\"],[\"79788.60\",\"0.251\"],[\"79792.60\",\"0.252\"],[\"79840.20\",\"0.351\"],[\"79876.40\",\"1.447\"],[\"79886.30\",\"0.090\"],[\"80078.80\",\"0.764\"],[\"80087.60\",\"1.147\"],[\"80514.10\",\"1.879\"],[\"80518.30\",\"0.191\"]],\"st\":1}}"}
{"receive_ns":1788564454446027000,"stream":"btcusdt@bookTicker","event_type":"bookTicker","event_time_ms":1788564454471,"raw_json":"{\"stream\":\"btcusdt@bookTicker\",\"data\":{\"e\":\"bookTicker\",\"u\":11478296464468,\"s\":\"BTCUSDT\",\"ps\":\"BTCUSDT\",\"b\":\"79716.80\",\"B\":\"2.620\",\"a\":\"79716.90\",\"A\":\"15.110\",\"T\":1788564454470,\"E\":1788564454471,\"st\":1}}"}
{"receive_ns":1788564454446244000,"stream":"btcusdt@trade","event_type":"trade","event_time_ms":1788564454471,"raw_json":"{\"stream\":\"btcusdt@trade\",\"data\":{\"e\":\"trade\",\"E\":1788564454471,\"T\":1788564454470,\"s\":\"BTCUSDT\",\"t\":8054096473,\"p\":\"79716.80\",\"q\":\"0.013\",\"X\":\"MARKET\",\"m\":true,\"st\":1}}"}
{"receive_ns":1788564454457919000,"stream":"btcusdt@bookTicker","event_type":"bookTicker","event_time_ms":1788564454472,"raw_json":"{\"stream\":\"btcusdt@bookTicker\",\"data\":{\"e\":\"bookTicker\",\"u\":11478296464554,\"s\":\"BTCUSDT\",\"ps\":\"BTCUSDT\",\"b\":\"79716.80\",\"B\":\"2.620\",\"a\":\"79716.90\",\"A\":\"15.129\",\"T\":1788564454471,\"E\":1788564454472,\"st\":1}}"}
{"receive_ns":1788564454469988000,"stream":"btcusdt@bookTicker","event_type":"bookTicker","event_time_ms":1788564454472,"raw_json":"{\"stream\":\"btcusdt@bookTicker\",\"data\":{\"e\":\"bookTicker\",\"u\":11478296464629,\"s\":\"BTCUSDT\",\"ps\":\"BTCUSDT\",\"b\":\"79716.80\",\"B\":\"2.620\",\"a\":\"79716.90\",\"A\":\"15.131\",\"T\":1788564454472,\"E\":1788564454472,\"st\":1}}"}
{"receive_ns":1788564454470250000,"stream":"btcusdt@bookTicker","event_type":"bookTicker","event_time_ms":1788564454473,"raw_json":"{\"stream\":\"btcusdt@bookTicker\",\"data\":{\"e\":\"bookTicker\",\"u\":11478296464756,\"s\":\"BTCUSDT\",\"ps\":\"BTCUSDT\",\"b\":\"79716.80\",\"B\":\"2.620\",\"a\":\"79716.90\",\"A\":\"15.112\",\"T\":1788564454472,\"E\":1788564454473,\"st\":1}}"}
{"receive_ns":1788564454470422000,"stream":"btcusdt@bookTicker","event_type":"bookTicker","event_time_ms":1788564454473,"raw_json":"{\"stream\":\"btcusdt@bookTicker\",\"data\":{\"e\":\"bookTicker\",\"u\":11478296464764,\"s\":\"BTCUSDT\",\"ps\":\"BTCUSDT\",\"b\":\"79716.80\",\"B\":\"2.620\",\"a\":\"79716.90\",\"A\":\"15.110\",\"T\":1788564454472,\"E\":1788564454473,\"st\":1}}"}
{"receive_ns":1788564454470811000,"stream":"btcusdt@depth@100ms","event_type":"depthUpdate","event_time_ms":1788564454497,"raw_json":"{\"stream\":\"btcusdt@depth@100ms\",\"data\":{\"e\":\"depthUpdate\",\"E\":1788564454497,\"T\":1788564454496,\"s\":\"BTCUSDT\",\"ps\":\"BTCUSDT\",\"U\":11478296459427,\"u\":11478296466053,\"pu\":11478296459292,\"b\":[[\"29216.80\",\"1.442\"],[\"29616.80\",\"0.658\"],[\"71745.10\",\"0.002\"],[\"75601.90\",\"0.002\"],[\"77742.40\",\"0.643\"],[\"78760.20\",\"16.356\"],[\"78919.60\",\"2.866\"],[\"79320.20\",\"0.140\"],[\"79529.50\",\"1.879\"],[\"79531.50\",\"0.256\"],[\"79594.40\",\"0.000\"],[\"79698.60\",\"1.583\"],[\"79700.70\",\"1.318\"],[\"79708.00\",\"0.005\"],[\"79709.40\",\"0.172\"],[\"79710.40\",\"0.057\"],[\"79712.40\",\"0.000\"],[\"79712.50\",\"0.000\"],[\"79713.00\",\"0.001\"],[\"79716.80\",\"2.620\"]],\"a\":[[\"79716.90\",\"15.110\"],[\"79717.90\",\"0.006\"],[\"79720.60\",\"0.110\"],[\"79722.10\",\"0.008\"],[\"79788.60\",\"0.450\"],[\"79792.60\",\"0.002\"],[\"79840.20\",\"0.001\"],[\"79866.40\",\"0.250\"],[\"80087.60\",\"1.147\"],[\"80115.50\",\"3.242\"],[\"80514.10\",\"1.879\"],[\"80812.10\",\"15.079\"],[\"80832.90\",\"22.057\"],[\"80852.00\",\"3.752\"]],\"st\":1}}"}
{"receive_ns":1788564454484684000,"stream":"btcusdt@bookTicker","event_type":"bookTicker","event_time_ms":1788564454503,"raw_json":"{\"stream\":\"btcusdt@bookTicker\",\"data\":{\"e\":\"bookTicker\",\"u\":11478296466418,\"s\":\"BTCUSDT\",\"ps\":\"BTCUSDT\",\"b\":\"79716.80\",\"B\":\"2.620\",\"a\":\"79716.90\",\"A\":\"15.132\",\"T\":1788564454503,\"E\":1788564454503,\"st\":1}}"}
{"receive_ns":1788564454529777000,"stream":"btcusdt@bookTicker","event_type":"bookTicker","event_time_ms":1788564454540,"raw_json":"{\"stream\":\"btcusdt@bookTicker\",\"data\":{\"e\":\"bookTicker\",\"u\":11478296469311,\"s\":\"BTCUSDT\",\"ps\":\"BTCUSDT\",\"b\":\"79716.80\",\"B\":\"2.620\",\"a\":\"79716.90\",\"A\":\"15.151\",\"T\":1788564454540,\"E\":1788564454540,\"st\":1}}"}
{"receive_ns":1788564454536435000,"stream":"btcusdt@bookTicker","event_type":"bookTicker","event_time_ms":1788564454541,"raw_json":"{\"stream\":\"btcusdt@bookTicker\",\"data\":{\"e\":\"bookTicker\",\"u\":11478296469351,\"s\":\"BTCUSDT\",\"ps\":\"BTCUSDT\",\"b\":\"79716.80\",\"B\":\"2.620\",\"a\":\"79716.90\",\"A\":\"15.132\",\"T\":1788564454541,\"E\":1788564454541,\"st\":1}}"}
{"receive_ns":1788564454580946000,"stream":"btcusdt@depth@100ms","event_type":"depthUpdate","event_time_ms":1788564454599,"raw_json":"{\"stream\":\"btcusdt@depth@100ms\",\"data\":{\"e\":\"depthUpdate\",\"E\":1788564454599,\"T\":1788564454597,\"s\":\"BTCUSDT\",\"ps\":\"BTCUSDT\",\"U\":11478296466106,\"u\":11478296473310,\"pu\":11478296466053,\"b\":[[\"1000.00\",\"24.754\"],[\"29216.80\",\"1.260\"],[\"29616.80\",\"0.840\"],[\"63773.00\",\"0.002\"],[\"71745.10\",\"0.002\"],[\"75731.00\",\"0.071\"],[\"76528.10\",\"0.000\"],[\"78122.50\",\"0.164\"],[\"78574.20\",\"11.594\"],[\"78800.10\",\"0.913\"],[\"78919.60\",\"2.866\"],[\"79318.20\",\"3.149\"],[\"79500.80\",\"1.003\"],[\"79501.60\",\"0.859\"],[\"79514.00\",\"0.001\"],[\"79514.60\",\"0.032\"],[\"79529.50\",\"1.879\"],[\"79594.40\",\"0.722\"],[\"79661.20\",\"0.001\"],[\"79689.10\",\"0.001\"],[\"79689.40\",\"0.454\"],[\"79690.90\",\"0.001\"],[\"79693.60\",\"0.002\"],[\"79694.30\",\"0.373\"],[\"79695.10\",\"0.001\"],[\"79695.50\",\"0.001\"],[\"79696.50\",\"0.800\"],[\"79697.30\",\"0.100\"],[\"79700.80\",\"0.005\"],[\"79701.90\",\"0.000\"],[\"79708.70\",\"0.027\"],[\"79708.80\",\"0.031\"],[\"79708.90\",\"1.564\"],[\"79709.10\",\"0.027\"],[\"79709.20\",\"0.027\"],[\"79709.30\",\"1.027\"],[\"79709.40\",\"0.198\"],[\"79710.30\",\"0.252\"],[\"79710.40\",\"0.031\"],[\"79710.60\",\"0.000\"],[\"79710.70\",\"0.003\"],[\"79711.00\",\"0.000\"],[\"79711.10\",\"0.025\"],[\"79711.30\",\"0.000\"],[\"79711.40\",\"0.000\"],[\"79711.70\",\"0.000\"]],\"a\":[[\"79716.90\",\"15.132\"],[\"79732.60\",\"0.501\"],[\"79732.90\",\"0.193\"],[\"79734.30\",\"0.003\"],[\"79734.90\",\"0.000\"],[\"79735.60\",\"0.372\"],[\"79739.40\",\"0.078\"],[\"79740.50\",\"0.460\"],[\"79788.60\",\"0.450\"],[\"79790.30\",\"31.819\"],[\"79795.70\",\"0.000\"],[\"79840.20\",\"0.351\"],[\"79886.30\",\"0.090\"],[\"80078.80\",\"0.764\"],[\"80087.60\",\"1.147\"],[\"80514.10\",\"1.879\"],[\"80872.80\",\"4.968\"],[\"80978.60\",\"0.000\"],[\"81019.20\",\"0.923\"]],\"st\":1}}"}
{"receive_ns":1788564454636798000,"stream":"btcusdt@bookTicker","event_type":"bookTicker","event_time_ms":1788564454654,"raw_json":"{\"stream\":\"btcusdt@bookTicker\",\"data\":{\"e\":\"bookTicker\",\"u\":11478296476553,\"s\":\"BTCUSDT\",\"ps\":\"BTCUSDT\",\"b\":\"79716.80\",\"B\":\"2.620\",\"a\":\"79716.90\",\"A\":\"15.151\",\"T\":1788564454654,\"E\":1788564454654,\"st\":1}}"}
{"receive_ns":1788564454648768000,"stream":"btcusdt@bookTicker","event_type":"bookTicker","event_time_ms":1788564454655,"raw_json":"{\"stream\":\"btcusdt@bookTicker\",\"data\":{\"e\":\"bookTicker\",\"u\":11478296476624,\"s\":\"BTCUSDT\",\"ps\":\"BTCUSDT\",\"b\":\"79716.80\",\"B\":\"2.620\",\"a\":\"79716.90\",\"A\":\"15.132\",\"T\":1788564454655,\"E\":1788564454655,\"st\":1}}"}
{"receive_ns":1788564454661152000,"stream":"btcusdt@bookTicker","event_type":"bookTicker","event_time_ms":1788564454686,"raw_json":"{\"stream\":\"btcusdt@bookTicker\",\"data\":{\"e\":\"bookTicker\",\"u\":11478296478439,\"s\":\"BTCUSDT\",\"ps\":\"BTCUSDT\",\"b\":\"79716.80\",\"B\":\"2.620\",\"a\":\"79716.90\",\"A\":\"15.151\",\"T\":1788564454686,\"E\":1788564454686,\"st\":1}}"}
{"receive_ns":1788564454673205000,"stream":"btcusdt@bookTicker","event_type":"bookTicker","event_time_ms":1788564454687,"raw_json":"{\"stream\":\"btcusdt@bookTicker\",\"data\":{\"e\":\"bookTicker\",\"u\":11478296478764,\"s\":\"BTCUSDT\",\"ps\":\"BTCUSDT\",\"b\":\"79716.80\",\"B\":\"2.620\",\"a\":\"79716.90\",\"A\":\"15.132\",\"T\":1788564454686,\"E\":1788564454687,\"st\":1}}"}
{"receive_ns":1788564454684964000,"stream":"btcusdt@depth@100ms","event_type":"depthUpdate","event_time_ms":1788564454701,"raw_json":"{\"stream\":\"btcusdt@depth@100ms\",\"data\":{\"e\":\"depthUpdate\",\"E\":1788564454701,\"T\":1788564454699,\"s\":\"BTCUSDT\",\"ps\":\"BTCUSDT\",\"U\":11478296473434,\"u\":11478296479802,\"pu\":11478296473310,\"b\":[[\"1000.00\",\"24.754\"],[\"29216.80\",\"1.085\"],[\"29616.80\",\"1.015\"],[\"63773.00\",\"0.002\"],[\"71745.10\",\"0.002\"],[\"76528.10\",\"0.002\"],[\"77883.30\",\"1.923\"],[\"78849.10\",\"1.130\"],[\"78919.60\",\"2.866\"],[\"79098.60\",\"1.262\"],[\"79318.20\",\"3.148\"],[\"79320.20\",\"0.000\"],[\"79501.60\",\"1.059\"],[\"79529.50\",\"1.679\"],[\"79563.70\",\"0.046\"],[\"79594.40\",\"0.000\"],[\"79678.90\",\"0.005\"],[\"79708.70\",\"0.001\"],[\"79708.80\",\"0.005\"],[\"79708.90\",\"1.538\"],[\"79709.60\",\"0.028\"],[\"79709.80\",\"0.125\"],[\"79709.90\",\"0.130\"],[\"79710.00\",\"0.041\"],[\"79710.20\",\"0.027\"]],\"a\":[[\"79716.90\",\"15.132\"],[\"79788.60\",\"0.450\"],[\"79788.70\",\"0.023\"],[\"79840.20\",\"0.001\"],[\"79866.40\",\"0.000\"],[\"79916.20\",\"0.002\"],[\"80087.60\",\"1.147\"],[\"80514.10\",\"1.879\"],[\"80673.50\",\"20.669\"],[\"80832.90\",\"23.910\"],[\"81311.20\",\"0.030\"]],\"st\":1}}"}
{"receive_ns":1788564454789175000,"stream":"btcusdt@depth@100ms","event_type":"depthUpdate","event_time_ms":1788564454803,"raw_json":"{\"stream\":\"btcusdt@depth@100ms\",\"data\":{\"e\":\"depthUpdate\",\"E\":1788564454803,\"T\":1788564454801,\"s\":\"BTCUSDT\",\"ps\":\"BTCUSDT\",\"U\":11478296480063,\"u\":11478296486576,\"pu\":11478296479802,\"b\":[[\"29216.80\",\"0.903\"],[\"29616.80\",\"1.197\"],[\"63773.00\",\"0.000\"],[\"71745.10\",\"0.002\"],[\"76528.10\",\"0.000\"],[\"78919.60\",\"2.866\"],[\"79320.20\",\"0.140\"],[\"79500.80\",\"0.000\"],[\"79501.60\",\"0.828\"],[\"79529.50\",\"0.501\"],[\"79531.50\",\"0.256\"],[\"79554.90\",\"0.004\"],[\"79638.00\",\"0.019\"]],\"a\":[[\"79788.60\",\"0.450\"],[\"79879.70\",\"0.004\"],[\"79886.30\",\"0.000\"],[\"80078.80\",\"0.002\"],[\"80087.60\",\"0.579\"],[\"80115.50\",\"3.243\"],[\"80487.90\",\"0.000\"],[\"80514.10\",\"1.879\"]],\"st\":1}}"}
{"receive_ns":1788564454890856000,"stream":"btcusdt@depth@100ms","event_type":"depthUpdate","event_time_ms":1788564454905,"raw_json":"{\"stream\":\"btcusdt@depth@100ms\",\"data\":{\"e\":\"depthUpdate\",\"E\":1788564454905,\"T\":1788564454904,\"s\":\"BTCUSDT\",\"ps\":\"BTCUSDT\",\"U\":11478296486733,\"u\":11478296492750,\"pu\":11478296486576,\"b\":[[\"1000.00\",\"24.754\"],[\"29216.80\",\"0.728\"],[\"29616.80\",\"1.372\"],[\"63773.00\",\"0.004\"],[\"71745.10\",\"0.002\"],[\"71782.00\",\"0.003\"],[\"76528.10\",\"0.002\"],[\"78847.90\",\"1.770\"],[\"78919.60\",\"2.866\"],[\"79297.80\",\"0.000\"],[\"79318.20\",\"3.158\"],[\"79497.60\",\"0.733\"],[\"79500.80\",\"1.003\"],[\"79501.60\",\"0.628\"],[\"79529.50\",\"1.679\"],[\"79554.90\",\"2.804\"],[\"79555.30\",\"0.739\"],[\"79594.40\",\"0.722\"]],\"a\":[[\"79788.60\",\"0.501\"],[\"79808.20\",\"0.000\"],[\"79811.10\",\"0.076\"],[\"79825.40\",\"6.950\"],[\"79840.20\",\"0.351\"],[\"79879.70\",\"2.457\"],[\"79886.30\",\"0.090\"],[\"80078.80\",\"0.764\"],[\"80087.60\",\"1.147\"],[\"80334.00\",\"3.356\"],[\"80514.10\",\"1.879\"]],\"st\":1}}"}
{"receive_ns":1788564454902596000,"stream":"btcusdt@bookTicker","event_type":"bookTicker","event_time_ms":1788564454924,"raw_json":"{\"stream\":\"btcusdt@bookTicker\",\"data\":{\"e\":\"bookTicker\",\"u\":11478296493928,\"s\":\"BTCUSDT\",\"ps\":\"BTCUSDT\",\"b\":\"79716.80\",\"B\":\"2.620\",\"a\":\"79716.90\",\"A\":\"15.122\",\"T\":1788564454924,\"E\":1788564454924,\"st\":1}}"}
{"receive_ns":1788564454913724000,"stream":"btcusdt@bookTicker","event_type":"bookTicker","event_time_ms":1788564454927,"raw_json":"{\"stream\":\"btcusdt@bookTicker\",\"data\":{\"e\":\"bookTicker\",\"u\":11478296494167,\"s\":\"BTCUSDT\",\"ps\":\"BTCUSDT\",\"b\":\"79716.80\",\"B\":\"2.620\",\"a\":\"79716.90\",\"A\":\"15.131\",\"T\":1788564454927,\"E\":1788564454927,\"st\":1}}"}
{"receive_ns":1788564454988635000,"stream":"btcusdt@depth@100ms","event_type":"depthUpdate","event_time_ms":1788564455007,"raw_json":"{\"stream\":\"btcusdt@depth@100ms\",\"data\":{\"e\":\"depthUpdate\",\"E\":1788564455007,\"T\":1788564455006,\"s\":\"BTCUSDT\",\"ps\":\"BTCUSDT\",\"U\":11478296492841,\"u\":11478296498742,\"pu\":11478296492750,\"b\":[[\"1000.00\",\"24.754\"],[\"29216.80\",\"0.546\"],[\"29616.80\",\"1.554\"],[\"63773.00\",\"0.000\"],[\"71745.10\",\"0.002\"],[\"71782.00\",\"0.000\"],[\"78600.80\",\"14.001\"],[\"78720.30\",\"2.018\"],[\"78919.60\",\"2.865\"],[\"79079.10\",\"2.021\"],[\"79273.50\",\"0.388\"],[\"79320.20\",\"0.140\"],[\"79501.60\",\"0.828\"],[\"79529.50\",\"1.929\"],[\"79531.50\",\"0.006\"],[\"79710.30\",\"0.001\"]],\"a\":[[\"79716.90\",\"15.131\"],[\"79788.60\",\"0.450\"],[\"79866.40\",\"0.250\"],[\"80087.60\",\"1.147\"],[\"80490.20\",\"0.537\"],[\"80514.10\",\"1.879\"],[\"80644.60\",\"1.859\"]],\"st\":1}}"}
{"receive_ns":1788564455039499000,"stream":"btcusdt@bookTicker","event_type":"bookTicker","event_time_ms":1788564455065,"raw_json":"{\"stream\":\"btcusdt@bookTicker\",\"data\":{\"e\":\"bookTicker\",\"u\":11478296503077,\"s\":\"BTCUSDT\",\"ps\":\"BTCUSDT\",\"b\":\"79716.80\",\"B\":\"2.620\",\"a\":\"79716.90\",\"A\":\"15.150\",\"T\":1788564455065,\"E\":1788564455065,\"st\":1}}"}
{"receive_ns":1788564455052489000,"stream":"btcusdt@bookTicker","event_type":"bookTicker","event_time_ms":1788564455065,"raw_json":"{\"stream\":\"btcusdt@bookTicker\",\"data\":{\"e\":\"bookTicker\",\"u\":11478296503131,\"s\":\"BTCUSDT\",\"ps\":\"BTCUSDT\",\"b\":\"79716.80\",\"B\":\"2.620\",\"a\":\"79716.90\",\"A\":\"15.131\",\"T\":1788564455065,\"E\":1788564455065,\"st\":1}}"}
{"receive_ns":1788564455064394000,"stream":"btcusdt@bookTicker","event_type":"bookTicker","event_time_ms":1788564455066,"raw_json":"{\"stream\":\"btcusdt@bookTicker\",\"data\":{\"e\":\"bookTicker\",\"u\":11478296503220,\"s\":\"BTCUSDT\",\"ps\":\"BTCUSDT\",\"b\":\"79716.80\",\"B\":\"2.620\",\"a\":\"79716.90\",\"A\":\"15.150\",\"T\":1788564455066,\"E\":1788564455066,\"st\":1}}"}
{"receive_ns":1788564455080558000,"stream":"btcusdt@bookTicker","event_type":"bookTicker","event_time_ms":1788564455067,"raw_json":"{\"stream\":\"btcusdt@bookTicker\",\"data\":{\"e\":\"bookTicker\",\"u\":11478296503308,\"s\":\"BTCUSDT\",\"ps\":\"BTCUSDT\",\"b\":\"79716.80\",\"B\":\"2.620\",\"a\":\"79716.90\",\"A\":\"15.131\",\"T\":1788564455067,\"E\":1788564455067,\"st\":1}}"}
{"receive_ns":1788564455093569000,"stream":"btcusdt@depth@100ms","event_type":"depthUpdate","event_time_ms":1788564455109,"raw_json":"{\"stream\":\"btcusdt@depth@100ms\",\"data\":{\"e\":\"depthUpdate\",\"E\":1788564455109,\"T\":1788564455106,\"s\":\"BTCUSDT\",\"ps\":\"BTCUSDT\",\"U\":11478296498847,\"u\":11478296508195,\"pu\":11478296498742,\"b\":[[\"29216.80\",\"0.371\"],[\"29616.80\",\"1.729\"],[\"63773.00\",\"0.000\"],[\"71745.10\",\"0.002\"],[\"75486.90\",\"0.002\"],[\"76528.10\",\"0.000\"],[\"78122.50\",\"0.161\"],[\"78361.60\",\"4.669\"],[\"78671.80\",\"0.000\"],[\"78919.60\",\"2.865\"],[\"79318.20\",\"3.284\"],[\"79497.60\",\"0.502\"],[\"79500.80\",\"0.000\"],[\"79501.60\",\"1.059\"],[\"79529.50\",\"0.250\"],[\"79531.50\",\"1.184\"],[\"79532.70\",\"2.292\"],[\"79621.10\",\"0.038\"],[\"79645.00\",\"0.004\"],[\"79693.40\",\"0.431\"],[\"79694.30\",\"0.001\"],[\"79695.10\",\"0.440\"],[\"79696.50\",\"0.361\"],[\"79701.60\",\"0.014\"],[\"79702.50\",\"0.000\"],[\"79709.10\",\"0.001\"],[\"79710.60\",\"0.026\"]],\"a\":[[\"79716.90\",\"15.131\"],[\"79733.40\",\"1.272\"],[\"79734.60\",\"0.374\"],[\"79735.60\",\"0.000\"],[\"79738.60\",\"0.000\"],[\"79739.60\",\"0.455\"],[\"79740.50\",\"0.009\"],[\"79756.80\",\"0.730\"],[\"79772.80\",\"0.314\"],[\"79788.60\",\"0.200\"],[\"79788.70\",\"0.021\"],[\"79866.40\",\"0.500\"],[\"79886.30\",\"0.090\"],[\"80078.80\",\"0.764\"],[\"80087.60\",\"0.729\"],[\"80354.60\",\"2.486\"],[\"80514.10\",\"1.879\"],[\"80759.50\",\"0.000\"]],\"st\":1}}"}
{"receive_ns":1788564455105374000,"stream":"btcusdt@bookTicker","event_type":"bookTicker","event_time_ms":1788564455124,"raw_json":"{\"stream\":\"btcusdt@bookTicker\",\"data\":{\"e\":\"bookTicker\",\"u\":11478296509535,\"s\":\"BTCUSDT\",\"ps\":\"BTCUSDT\",\"b\":\"79716.80\",\"B\":\"2.617\",\"a\":\"79716.90\",\"A\":\"15.131\",\"T\":1788564455124,\"E\":1788564455124,\"st\":1}}"}
{"receive_ns":1788564455147087000,"stream":"btcusdt@bookTicker","event_type":"bookTicker","event_time_ms":1788564455163,"raw_json":"{\"stream\":\"btcusdt@bookTicker\",\"data\":{\"e\":\"bookTicker\",\"u\":11478296511991,\"s\":\"BTCUSDT\",\"ps\":\"BTCUSDT\",\"b\":\"79716.80\",\"B\":\"2.617\",\"a\":\"79716.90\",\"A\":\"15.132\",\"T\":1788564455163,\"E\":1788564455163,\"st\":1}}"}
{"receive_ns":1788564455176944000,"stream":"btcusdt@bookTicker","event_type":"bookTicker","event_time_ms":1788564455197,"raw_json":"{\"stream\":\"btcusdt@bookTicker\",\"data\":{\"e\":\"bookTicker\",\"u\":11478296514142,\"s\":\"BTCUSDT\",\"ps\":\"BTCUSDT\",\"b\":\"79716.80\",\"B\":\"2.617\",\"a\":\"79716.90\",\"A\":\"15.127\",\"T\":1788564455197,\"E\":1788564455197,\"st\":1}}"}
{"receive_ns":1788564455193892000,"stream":"btcusdt@bookTicker","event_type":"bookTicker","event_time_ms":1788564455200,"raw_json":"{\"stream\":\"btcusdt@bookTicker\",\"data\":{\"e\":\"bookTicker\",\"u\":11478296514331,\"s\":\"BTCUSDT\",\"ps\":\"BTCUSDT\",\"b\":\"79716.80\",\"B\":\"2.617\",\"a\":\"79716.90\",\"A\":\"15.134\",\"T\":1788564455200,\"E\":1788564455200,\"st\":1}}"}
{"receive_ns":1788564455200553000,"stream":"btcusdt@depth@100ms","event_type":"depthUpdate","event_time_ms":1788564455211,"raw_json":"{\"stream\":\"btcusdt@depth@100ms\",\"data\":{\"e\":\"depthUpdate\",\"E\":1788564455211,\"T\":1788564455209,\"s\":\"BTCUSDT\",\"ps\":\"BTCUSDT\",\"U\":11478296508452,\"u\":11478296515094,\"pu\":11478296508195,\"b\":[[\"1000.00\",\"24.754\"],[\"29216.80\",\"0.245\"],[\"29516.80\",\"0.056\"],[\"29616.80\",\"1.799\"],[\"71745.10\",\"0.002\"],[\"75731.00\",\"0.073\"],[\"76528.10\",\"0.002\"],[\"78919.60\",\"2.865\"],[\"79318.20\",\"3.274\"],[\"79320.20\",\"0.140\"],[\"79476.80\",\"0.002\"],[\"79478.50\",\"0.339\"],[\"79479.40\",\"0.806\"],[\"79501.60\",\"0.859\"],[\"79514.60\",\"0.000\"],[\"79515.40\",\"0.032\"],[\"79529.50\",\"0.200\"],[\"79533.50\",\"0.502\"],[\"79639.80\",\"0.352\"],[\"79639.90\",\"0.001\"],[\"79663.70\",\"0.000\"],[\"79674.90\",\"0.003\"],[\"79675.00\",\"0.072\"],[\"79675.10\",\"0.561\"],[\"79686.20\",\"0.005\"],[\"79687.30\",\"0.001\"],[\"79710.60\",\"0.000\"],[\"79716.80\",\"2.617\"]],\"a\":[[\"79716.90\",\"15.134\"],[\"79738.30\",\"0.086\"],[\"79738.40\",\"0.083\"],[\"79750.00\",\"0.500\"],[\"79788.60\",\"0.001\"],[\"79790.30\",\"0.059\"],[\"79792.60\",\"0.252\"],[\"79794.60\",\"0.904\"],[\"79795.70\",\"31.760\"],[\"79824.40\",\"0.000\"],[\"79866.40\",\"0.250\"],[\"79904.40\",\"2.872\"],[\"79907.80\",\"0.049\"],[\"80087.60\",\"0.992\"],[\"80294.10\",\"1.468\"],[\"80514.10\",\"1.879\"]],\"st\":1}}"}
{"receive_ns":1788564455296257000,"stream":"btcusdt@depth@100ms","event_type":"depthUpdate","event_time_ms":1788564455313,"raw_json":"{\"stream\":\"btcusdt@depth@100ms\",\"data\":{\"e\":\"depthUpdate\",\"E\":1788564455313,\"T\":1788564455309,\"s\":\"BTCUSDT\",\"ps\":\"BTCUSDT\",\"U\":11478296515224,\"u\":11478296520957,\"pu\":11478296515094,\"b\":[[\"1000.00\",\"24.754\"],[\"29216.80\",\"0.126\"],[\"29516.80\",\"0.112\"],[\"29616.80\",\"1.862\"],[\"63773.40\",\"0.000\"],[\"71745.10\",\"0.002\"],[\"76528.10\",\"0.000\"],[\"78655.00\",\"10.849\"],[\"78919.60\",\"4.131\"],[\"79250.00\",\"1.888\"],[\"79501.60\",\"0.628\"],[\"79529.50\",\"0.450\"],[\"79531.50\",\"0.006\"],[\"79532.70\",\"1.289\"],[\"79594.40\",\"0.000\"],[\"79604.10\",\"0.350\"],[\"79639.40\",\"0.296\"],[\"79693.10\",\"0.003\"],[\"79709.20\",\"0.001\"],[\"79709.30\",\"1.001\"],[\"79709.40\",\"0.172\"],[\"79710.60\",\"0.026\"],[\"79711.40\",\"0.026\"],[\"79711.60\",\"0.026\"],[\"79711.80\",\"0.027\"]],\"a\":[[\"79733.00\",\"0.630\"],[\"79736.40\",\"2.730\"],[\"79792.90\",\"6.197\"],[\"79793.00\",\"31.774\"],[\"79794.60\",\"0.705\"],[\"79795.70\",\"0.000\"],[\"79840.20\",\"0.001\"],[\"79866.40\",\"0.000\"],[\"79886.30\",\"0.000\"],[\"80078.80\",\"0.002\"],[\"80087.60\",\"0.579\"],[\"80514.10\",\"1.879\"]],\"st\":1}}"}
{"receive_ns":1788564455308756000,"stream":"btcusdt@bookTicker","event_type":"bookTicker","event_time_ms":1788564455319,"raw_json":"{\"stream\":\"btcusdt@bookTicker\",\"data\":{\"e\":\"bookTicker\",\"u\":11478296521486,\"s\":\"BTCUSDT\",\"ps\":\"BTCUSDT\",\"b\":\"79716.80\",\"B\":\"2.617\",\"a\":\"79716.90\",\"A\":\"15.113\",\"T\":1788564455319,\"E\":1788564455319,\"st\":1}}"}
{"receive_ns":1788564455315058000,"stream":"btcusdt@bookTicker","event_type":"bookTicker","event_time_ms":1788564455322,"raw_json":"{\"stream\":\"btcusdt@bookTicker\",\"data\":{\"e\":\"bookTicker\",\"u\":11478296521667,\"s\":\"BTCUSDT\",\"ps\":\"BTCUSDT\",\"b\":\"79716.80\",\"B\":\"2.617\",\"a\":\"79716.90\",\"A\":\"15.136\",\"T\":1788564455322,\"E\":1788564455322,\"st\":1}}"}
{"receive_ns":1788564455360523000,"stream":"btcusdt@bookTicker","event_type":"bookTicker","event_time_ms":1788564455380,"raw_json":"{\"stream\":\"btcusdt@bookTicker\",\"data\":{\"e\":\"bookTicker\",\"u\":11478296524837,\"s\":\"BTCUSDT\",\"ps\":\"BTCUSDT\",\"b\":\"79716.80\",\"B\":\"2.618\",\"a\":\"79716.90\",\"A\":\"15.136\",\"T\":1788564455380,\"E\":1788564455380,\"st\":1}}"}
{"receive_ns":1788564455396735000,"stream":"btcusdt@depth@100ms","event_type":"depthUpdate","event_time_ms":1788564455415,"raw_json":"{\"stream\":\"btcusdt@depth@100ms\",\"data\":{\"e\":\"depthUpdate\",\"E\":1788564455415,\"T\":1788564455413,\"s\":\"BTCUSDT\",\"ps\":\"BTCUSDT\",\"U\":11478296521164,\"u\":11478296526608,\"pu\":11478296520957,\"b\":[[\"29216.80\",\"0.014\"],[\"29516.80\",\"0.182\"],[\"29616.80\",\"1.904\"],[\"71745.10\",\"0.002\"],[\"75731.00\",\"0.075\"],[\"78733.80\",\"1.257\"],[\"78919.60\",\"4.131\"],[\"79497.60\",\"0.733\"],[\"79501.60\",\"1.329\"],[\"79507.10\",\"0.000\"],[\"79507.80\",\"0.283\"],[\"79529.50\",\"1.353\"],[\"79530.70\",\"1.004\"],[\"79533.50\",\"0.001\"],[\"79554.90\",\"0.004\"],[\"79555.30\",\"0.423\"],[\"79644.80\",\"0.690\"],[\"79648.40\",\"0.340\"],[\"79698.90\",\"0.065\"],[\"79716.80\",\"2.618\"]],\"a\":[[\"79716.90\",\"15.136\"],[\"79792.60\",\"0.701\"],[\"79879.70\",\"0.004\"],[\"79924.40\",\"2.130\"],[\"79927.50\",\"0.000\"],[\"79938.10\",\"0.090\"],[\"80078.80\",\"0.764\"],[\"80087.60\",\"1.147\"],[\"80514.10\",\"2.809\"],[\"81203.90\",\"0.077\"]],\"st\":1}}"}
{"receive_ns":1788564455439001000,"stream":"btcusdt@bookTicker","event_type":"bookTicker","event_time_ms":1788564455457,"raw_json":"{\"stream\":\"btcusdt@bookTicker\",\"data\":{\"e\":\"bookTicker\",\"u\":11478296528761,\"s\":\"BTCUSDT\",\"ps\":\"BTCUSDT\",\"b\":\"79716.80\",\"B\":\"2.605\",\"a\":\"79716.90\",\"A\":\"15.136\",\"T\":1788564455457,\"E\":1788564455457,\"st\":1}}"}
{"receive_ns":1788564455445567000,"stream":"btcusdt@trade","event_type":"trade","event_time_ms":1788564455457,"raw_json":"{\"stream\":\"btcusdt@trade\",\"data\":{\"e\":\"trade\",\"E\":1788564455457,\"T\":1788564455457,\"s\":\"BTCUSDT\",\"t\":8054096474,\"p\":\"79716.80\",\"q\":\"0.013\",\"X\":\"MARKET\",\"m\":true,\"st\":1}}"}
{"receive_ns":1788564455463592000,"stream":"btcusdt@bookTicker","event_type":"bookTicker","event_time_ms":1788564455458,"raw_json":"{\"stream\":\"btcusdt@bookTicker\",\"data\":{\"e\":\"bookTicker\",\"u\":11478296528850,\"s\":\"BTCUSDT\",\"ps\":\"BTCUSDT\",\"b\":\"79716.80\",\"B\":\"2.605\",\"a\":\"79716.90\",\"A\":\"15.138\",\"T\":1788564455458,\"E\":1788564455458,\"st\":1}}"}
{"receive_ns":1788564455472839000,"stream":"btcusdt@bookTicker","event_type":"bookTicker","event_time_ms":1788564455458,"raw_json":"{\"stream\":\"btcusdt@bookTicker\",\"data\":{\"e\":\"bookTicker\",\"u\":11478296528854,\"s\":\"BTCUSDT\",\"ps\":\"BTCUSDT\",\"b\":\"79716.80\",\"B\":\"2.605\",\"a\":\"79716.90\",\"A\":\"15.157\",\"T\":1788564455458,\"E\":1788564455458,\"st\":1}}"}
{"receive_ns":1788564455489700000,"stream":"btcusdt@bookTicker","event_type":"bookTicker","event_time_ms":1788564455459,"raw_json":"{\"stream\":\"btcusdt@bookTicker\",\"data\":{\"e\":\"bookTicker\",\"u\":11478296529020,\"s\":\"BTCUSDT\",\"ps\":\"BTCUSDT\",\"b\":\"79716.80\",\"B\":\"2.605\",\"a\":\"79716.90\",\"A\":\"15.155\",\"T\":1788564455459,\"E\":1788564455459,\"st\":1}}"}
{"receive_ns":1788564455495339000,"stream":"btcusdt@bookTicker","event_type":"bookTicker","event_time_ms":1788564455459,"raw_json":"{\"stream\":\"btcusdt@bookTicker\",\"data\":{\"e\":\"bookTicker\",\"u\":11478296529040,\"s\":\"BTCUSDT\",\"ps\":\"BTCUSDT\",\"b\":\"79716.80\",\"B\":\"2.605\",\"a\":\"79716.90\",\"A\":\"15.136\",\"T\":1788564455459,\"E\":1788564455459,\"st\":1}}"}
{"receive_ns":1788564455512607000,"stream":"btcusdt@depth@100ms","event_type":"depthUpdate","event_time_ms":1788564455517,"raw_json":"{\"stream\":\"btcusdt@depth@100ms\",\"data\":{\"e\":\"depthUpdate\",\"E\":1788564455517,\"T\":1788564455513,\"s\":\"BTCUSDT\",\"ps\":\"BTCUSDT\",\"U\":11478296526714,\"u\":11478296531689,\"pu\":11478296526608,\"b\":[[\"1000.00\",\"24.754\"],[\"29216.80\",\"0.000\"],[\"29516.80\",\"0.343\"],[\"29616.80\",\"1.757\"],[\"71745.10\",\"0.002\"],[\"76528.10\",\"0.002\"],[\"77691.60\",\"0.000\"],[\"78919.60\",\"4.131\"],[\"79318.20\",\"3.284\"],[\"79320.20\",\"0.140\"],[\"79503.60\",\"0.250\"],[\"79529.50\",\"1.103\"],[\"79531.80\",\"0.001\"],[\"79608.30\",\"0.000\"],[\"79641.20\",\"0.016\"],[\"79709.40\",\"0.198\"],[\"79710.40\",\"0.029\"],[\"79711.40\",\"0.000\"],[\"79711.50\",\"0.030\"],[\"79711.60\",\"0.000\"],[\"79711.80\",\"0.001\"],[\"79716.80\",\"2.605\"]],\"a\":[[\"79716.90\",\"15.136\"],[\"79792.60\",\"0.701\"],[\"80087.60\",\"1.147\"],[\"80115.50\",\"3.242\"],[\"80514.10\",\"2.809\"],[\"80848.90\",\"0.888\"],[\"80852.00\",\"2.887\"],[\"81011.40\",\"0.863\"]],\"st\":1}}"}
{"receive_ns":1788564455601284000,"stream":"btcusdt@depth@100ms","event_type":"depthUpdate","event_time_ms":1788564455619,"raw_json":"{\"stream\":\"btcusdt@depth@100ms\",\"data\":{\"e\":\"depthUpdate\",\"E\":1788564455619,\"T\":1788564455617,\"s\":\"BTCUSDT\",\"ps\":\"BTCUSDT\",\"U\":11478296531923,\"u\":11478296536527,\"pu\":11478296531689,\"b\":[[\"1000.00\",\"24.754\"],[\"29516.80\",\"0.525\"],[\"29616.80\",\"1.575\"],[\"63773.00\",\"0.000\"],[\"71745.10\",\"0.002\"],[\"75371.90\",\"0.002\"],[\"76528.10\",\"0.000\"],[\"78620.80\",\"0.191\"],[\"78655.10\",\"0.240\"],[\"78919.60\",\"4.131\"],[\"79098.60\",\"0.631\"],[\"79318.20\",\"3.285\"],[\"79497.60\",\"0.733\"],[\"79501.60\",\"0.828\"],[\"79507.10\",\"7.240\"],[\"79507.80\",\"1.292\"],[\"79524.70\",\"1.005\"],[\"79529.50\",\"1.679\"],[\"79530.70\",\"0.001\"],[\"79554.90\",\"2.804\"],[\"79594.40\",\"0.721\"],[\"79621.10\",\"0.040\"],[\"79703.50\",\"0.002\"],[\"79709.40\",\"0.172\"],[\"79710.40\",\"0.280\"],[\"79711.60\",\"0.026\"],[\"79711.80\",\"0.027\"]],\"a\":[[\"79721.40\",\"0.002\"],[\"79724.70\",\"0.019\"],[\"79725.50\",\"0.671\"],[\"79772.80\",\"0.316\"],[\"79790.30\",\"0.045\"],[\"79792.60\",\"0.701\"],[\"79840.20\",\"0.351\"],[\"79879.70\",\"2.477\"],[\"79927.50\",\"7.689\"],[\"79938.10\",\"0.090\"],[\"79938.70\",\"8.691\"],[\"80078.80\",\"0.764\"],[\"80087.60\",\"1.147\"],[\"80294.10\",\"0.846\"],[\"80514.10\",\"2.809\"],[\"81351.10\",\"2.824\"]],\"st\":1}}"}
{"receive_ns":1788564455695616000,"stream":"btcusdt@depth@100ms","event_type":"depthUpdate","event_time_ms":1788564455721,"raw_json":"{\"stream\":\"btcusdt@depth@100ms\",\"data\":{\"e\":\"depthUpdate\",\"E\":1788564455721,\"T\":1788564455720,\"s\":\"BTCUSDT\",\"ps\":\"BTCUSDT\",\"U\":11478296536600,\"u\":11478296542529,\"pu\":11478296536527,\"b\":[[\"29516.80\",\"0.700\"],[\"29616.80\",\"1.400\"],[\"71745.10\",\"0.002\"],[\"76528.10\",\"0.002\"],[\"78919.60\",\"4.131\"],[\"79320.20\",\"0.140\"],[\"79492.40\",\"2.410\"],[\"79501.60\",\"0.628\"],[\"79503.60\",\"0.000\"],[\"79529.50\",\"1.879\"],[\"79578.60\",\"2.456\"],[\"79659.40\",\"0.042\"],[\"79661.70\",\"2.708\"],[\"79674.10\",\"0.001\"],[\"79674.20\",\"2.210\"],[\"79685.50\",\"0.002\"],[\"79685.60\",\"0.900\"],[\"79707.80\",\"0.001\"],[\"79708.30\",\"0.004\"],[\"79710.50\",\"0.026\"]],\"a\":[[\"79736.50\",\"1.003\"],[\"79737.00\",\"1.818\"],[\"79760.50\",\"1.271\"],[\"79761.00\",\"3.152\"],[\"79761.10\",\"0.002\"],[\"79792.60\",\"0.701\"],[\"79925.50\",\"3.422\"],[\"80087.60\",\"0.992\"],[\"80514.10\",\"2.809\"],[\"80872.80\",\"5.833\"]],\"st\":1}}"}
{"receive_ns":1788564455738917000,"stream":"btcusdt@bookTicker","event_type":"bookTicker","event_time_ms":1788564455757,"raw_json":"{\"stream\":\"btcusdt@bookTicker\",\"data\":{\"e\":\"bookTicker\",\"u\":11478296544233,\"s\":\"BTCUSDT\",\"ps\":\"BTCUSDT\",\"b\":\"79716.80\",\"B\":\"2.570\",\"a\":\"79716.90\",\"A\":\"15.136\",\"T\":1788564455757,\"E\":1788564455757,\"st\":1}}"}
{"receive_ns":1788564455744693000,"stream":"btcusdt@trade","event_type":"trade","event_time_ms":1788564455757,"raw_json":"{\"stream\":\"btcusdt@trade\",\"data\":{\"e\":\"trade\",\"E\":1788564455757,\"T\":1788564455757,\"s\":\"BTCUSDT\",\"t\":8054096475,\"p\":\"79716.80\",\"q\":\"0.035\",\"X\":\"MARKET\",\"m\":true,\"st\":1}}"}
{"receive_ns":1788564455765601000,"stream":"btcusdt@bookTicker","event_type":"bookTicker","event_time_ms":1788564455758,"raw_json":"{\"stream\":\"btcusdt@bookTicker\",\"data\":{\"e\":\"bookTicker\",\"u\":11478296544343,\"s\":\"BTCUSDT\",\"ps\":\"BTCUSDT\",\"b\":\"79716.80\",\"B\":\"2.570\",\"a\":\"79716.90\",\"A\":\"15.155\",\"T\":1788564455758,\"E\":1788564455758,\"st\":1}}"}
{"receive_ns":1788564455772338000,"stream":"btcusdt@bookTicker","event_type":"bookTicker","event_time_ms":1788564455758,"raw_json":"{\"stream\":\"btcusdt@bookTicker\",\"data\":{\"e\":\"bookTicker\",\"u\":11478296544346,\"s\":\"BTCUSDT\",\"ps\":\"BTCUSDT\",\"b\":\"79716.80\",\"B\":\"2.570\",\"a\":\"79716.90\",\"A\":\"15.157\",\"T\":1788564455758,\"E\":1788564455758,\"st\":1}}"}
{"receive_ns":1788564455784481000,"stream":"btcusdt@bookTicker","event_type":"bookTicker","event_time_ms":1788564455759,"raw_json":"{\"stream\":\"btcusdt@bookTicker\",\"data\":{\"e\":\"bookTicker\",\"u\":11478296544512,\"s\":\"BTCUSDT\",\"ps\":\"BTCUSDT\",\"b\":\"79716.80\",\"B\":\"2.570\",\"a\":\"79716.90\",\"A\":\"15.138\",\"T\":1788564455758,\"E\":1788564455759,\"st\":1}}"}
{"receive_ns":1788564455791257000,"stream":"btcusdt@bookTicker","event_type":"bookTicker","event_time_ms":1788564455759,"raw_json":"{\"stream\":\"btcusdt@bookTicker\",\"data\":{\"e\":\"bookTicker\",\"u\":11478296544514,\"s\":\"BTCUSDT\",\"ps\":\"BTCUSDT\",\"b\":\"79716.80\",\"B\":\"2.570\",\"a\":\"79716.90\",\"A\":\"15.136\",\"T\":1788564455758,\"E\":1788564455759,\"st\":1}}"}
{"receive_ns":1788564455812208000,"stream":"btcusdt@depth@100ms","event_type":"depthUpdate","event_time_ms":1788564455823,"raw_json":"{\"stream\":\"btcusdt@depth@100ms\",\"data\":{\"e\":\"depthUpdate\",\"E\":1788564455823,\"T\":1788564455822,\"s\":\"BTCUSDT\",\"ps\":\"BTCUSDT\",\"U\":11478296542561,\"u\":11478296548914,\"pu\":11478296542529,\"b\":[[\"1000.00\",\"24.754\"],[\"29516.80\",\"0.882\"],[\"29616.80\",\"1.218\"],[\"71745.10\",\"0.002\"],[\"75731.00\",\"0.073\"],[\"75731.10\",\"0.006\"],[\"76528.10\",\"0.000\"],[\"78122.50\",\"0.161\"],[\"78919.60\",\"4.131\"],[\"79318.20\",\"3.285\"],[\"79497.60\",\"0.502\"],[\"79501.60\",\"0.859\"],[\"79522.70\",\"1.004\"],[\"79524.70\",\"0.002\"],[\"79529.50\",\"1.804\"],[\"79531.50\",\"0.256\"],[\"79698.90\",\"0.140\"],[\"79708.80\",\"0.031\"],[\"79708.90\",\"1.564\"],[\"79709.10\",\"0.027\"],[\"79709.20\",\"0.027\"],[\"79709.30\",\"1.027\"],[\"79709.40\",\"0.198\"],[\"79709.80\",\"0.099\"],[\"79709.90\",\"0.104\"],[\"79710.00\",\"0.015\"],[\"79710.20\",\"0.001\"],[\"79710.50\",\"0.002\"],[\"79710.60\",\"0.000\"],[\"79711.50\",\"0.004\"],[\"79711.60\",\"0.000\"],[\"79711.80\",\"0.001\"],[\"79716.80\",\"2.570\"]],\"a\":[[\"79716.90\",\"15.136\"],[\"79792.60\",\"0.701\"],[\"79886.30\",\"0.090\"],[\"79938.10\",\"0.000\"],[\"80078.80\",\"0.764\"],[\"80087.60\",\"1.147\"],[\"80115.50\",\"3.241\"],[\"80514.10\",\"2.809\"],[\"81032.20\",\"2.958\"]],\"st\":1}}"}
{"receive_ns":1788564455907343000,"stream":"btcusdt@depth@100ms","event_type":"depthUpdate","event_time_ms":1788564455925,"raw_json":"{\"stream\":\"btcusdt@depth@100ms\",\"data\":{\"e\":\"depthUpdate\",\"E\":1788564455925,\"T\":1788564455922,\"s\":\"BTCUSDT\",\"ps\":\"BTCUSDT\",\"U\":11478296549004,\"u\":11478296554046,\"pu\":11478296548914,\"b\":[[\"29516.80\",\"1.057\"],[\"29616.80\",\"1.043\"],[\"71745.10\",\"0.002\"],[\"78487.00\",\"0.001\"],[\"78542.00\",\"0.057\"],[\"78760.20\",\"17.624\"],[\"78919.60\",\"5.397\"],[\"79318.20\",\"3.286\"],[\"79320.20\",\"0.000\"],[\"79529.50\",\"1.804\"],[\"79709.80\",\"0.125\"]],\"a\":[[\"79729.40\",\"0.129\"],[\"79733.40\",\"1.269\"],[\"79748.20\",\"2.930\"],[\"79792.60\",\"0.451\"],[\"80087.60\",\"1.147\"],[\"80514.10\",\"2.809\"],[\"80530.50\",\"0.000\"]],\"st\":1}}"}
{"receive_ns":1788564456008276000,"stream":"btcusdt@depth@100ms","event_type":"depthUpdate","event_time_ms":1788564456027,"raw_json":"{\"stream\":\"btcusdt@depth@100ms\",\"data\":{\"e\":\"depthUpdate\",\"E\":1788564456027,\"T\":1788564456025,\"s\":\"BTCUSDT\",\"ps\":\"BTCUSDT\",\"U\":11478296554230,\"u\":11478296560199,\"pu\":11478296554046,\"b\":[[\"29516.80\",\"1.239\"],[\"29616.80\",\"0.861\"],[\"63773.00\",\"0.000\"],[\"71745.10\",\"0.002\"],[\"76528.10\",\"0.002\"],[\"78919.60\",\"5.397\"],[\"79320.20\",\"0.140\"],[\"79501.60\",\"0.628\"],[\"79522.70\",\"0.001\"],[\"79529.50\",\"0.951\"],[\"79531.50\",\"0.006\"],[\"79698.90\",\"0.065\"],[\"79700.00\",\"0.524\"],[\"79703.40\",\"0.290\"]],\"a\":[[\"79792.60\",\"0.451\"],[\"79886.30\",\"0.000\"],[\"80078.80\",\"0.002\"],[\"80087.60\",\"0.579\"],[\"80514.10\",\"2.809\"],[\"80753.20\",\"0.680\"]],\"st\":1}}"}
{"receive_ns":1788564456042281000,"stream":"btcusdt@bookTicker","event_type":"bookTicker","event_time_ms":1788564456067,"raw_json":"{\"stream\":\"btcusdt@bookTicker\",\"data\":{\"e\":\"bookTicker\",\"u\":11478296563646,\"s\":\"BTCUSDT\",\"ps\":\"BTCUSDT\",\"b\":\"79716.80\",\"B\":\"2.570\",\"a\":\"79716.90\",\"A\":\"15.155\",\"T\":1788564456067,\"E\":1788564456067,\"st\":1}}"}
{"receive_ns":1788564456054204000,"stream":"btcusdt@bookTicker","event_type":"bookTicker","event_time_ms":1788564456068,"raw_json":"{\"stream\":\"btcusdt@bookTicker\",\"data\":{\"e\":\"bookTicker\",\"u\":11478296563705,\"s\":\"BTCUSDT\",\"ps\":\"BTCUSDT\",\"b\":\"79716.80\",\"B\":\"2.570\",\"a\":\"79716.90\",\"A\":\"15.136\",\"T\":1788564456067,\"E\":1788564456068,\"st\":1}}"}
{"receive_ns":1788564456111821000,"stream":"btcusdt@depth@100ms","event_type":"depthUpdate","event_time_ms":1788564456129,"raw_json":"{\"stream\":\"btcusdt@depth@100ms\",\"data\":{\"e\":\"depthUpdate\",\"E\":1788564456129,\"T\":1788564456127,\"s\":\"BTCUSDT\",\"ps\":\"BTCUSDT\",\"U\":11478296560326,\"u\":11478296567552,\"pu\":11478296560199,\"b\":[[\"1000.00\",\"24.754\"],[\"29516.80\",\"1.414\"],[\"29616.80\",\"0.686\"],[\"63773.00\",\"0.000\"],[\"71745.10\",\"0.002\"],[\"71782.00\",\"0.000\"],[\"76528.10\",\"0.000\"],[\"78919.60\",\"5.397\"],[\"79318.20\",\"3.286\"],[\"79501.60\",\"0.859\"],[\"79515.40\",\"0.000\"],[\"79516.10\",\"0.032\"],[\"79522.70\",\"1.004\"],[\"79529.50\",\"1.754\"],[\"79698.90\",\"0.240\"],[\"79702.50\",\"0.000\"],[\"79708.80\",\"0.005\"],[\"79710.50\",\"0.028\"],[\"79711.00\",\"0.026\"]],\"a\":[[\"79716.90\",\"15.136\"],[\"79722.20\",\"0.508\"],[\"79792.60\",\"0.252\"],[\"79866.40\",\"0.250\"],[\"79938.10\",\"0.090\"],[\"80078.80\",\"0.764\"],[\"80087.60\",\"1.147\"],[\"80514.10\",\"2.809\"],[\"80706.60\",\"0.995\"],[\"80736.20\",\"0.002\"],[\"80747.20\",\"0.381\"],[\"80766.70\",\"11.169\"],[\"80776.50\",\"0.000\"]],\"st\":1}}"}
{"receive_ns":1788564456214320000,"stream":"btcusdt@depth@100ms","event_type":"depthUpdate","event_time_ms":1788564456231,"raw_json":"{\"stream\":\"btcusdt@depth@100ms\",\"data\":{\"e\":\"depthUpdate\",\"E\":1788564456231,\"T\":1788564456229,\"s\":\"BTCUSDT\",\"ps\":\"BTCUSDT\",\"U\":11478296567731,\"u\":11478296574092,\"pu\":11478296567552,\"b\":[[\"29516.80\",\"1.596\"],[\"29616.80\",\"0.504\"],[\"71745.10\",\"0.002\"],[\"76528.10\",\"0.002\"],[\"78731.90\",\"0.000\"],[\"78733.60\",\"13.327\"],[\"78919.60\",\"5.397\"],[\"79318.20\",\"3.286\"],[\"79320.20\",\"0.140\"],[\"79529.50\",\"1.954\"]],\"a\":[[\"79792.60\",\"0.451\"],[\"79816.20\",\"0.001\"],[\"79817.70\",\"0.001\"],[\"80087.60\",\"1.147\"],[\"80514.10\",\"2.809\"]],\"st\":1}}"}
{"receive_ns":1788564456225494000,"stream":"btcusdt@bookTicker","event_type":"bookTicker","event_time_ms":1788564456237,"raw_json":"{\"stream\":\"btcusdt@bookTicker\",\"data\":{\"e\":\"bookTicker\",\"u\":11478296574604,\"s\":\"BTCUSDT\",\"ps\":\"BTCUSDT\",\"b\":\"79716.80\",\"B\":\"2.569\",\"a\":\"79716.90\",\"A\":\"15.136\",\"T\":1788564456237,\"E\":1788564456237,\"st\":1}}"}
{"receive_ns":1788564456225736000,"stream":"btcusdt@trade","event_type":"trade","event_time_ms":1788564456237,"raw_json":"{\"stream\":\"btcusdt@trade\",\"data\":{\"e\":\"trade\",\"E\":1788564456237,\"T\":1788564456237,\"s\":\"BTCUSDT\",\"t\":8054096476,\"p\":\"79716.80\",\"q\":\"0.001\",\"X\":\"MARKET\",\"m\":true,\"st\":1}}"}
{"receive_ns":1788564456225974000,"stream":"btcusdt@bookTicker","event_type":"bookTicker","event_time_ms":1788564456239,"raw_json":"{\"stream\":\"btcusdt@bookTicker\",\"data\":{\"e\":\"bookTicker\",\"u\":11478296574667,\"s\":\"BTCUSDT\",\"ps\":\"BTCUSDT\",\"b\":\"79716.80\",\"B\":\"2.569\",\"a\":\"79716.90\",\"A\":\"15.155\",\"T\":1788564456238,\"E\":1788564456239,\"st\":1}}"}
{"receive_ns":1788564456226169000,"stream":"btcusdt@bookTicker","event_type":"bookTicker","event_time_ms":1788564456239,"raw_json":"{\"stream\":\"btcusdt@bookTicker\",\"data\":{\"e\":\"bookTicker\",\"u\":11478296574802,\"s\":\"BTCUSDT\",\"ps\":\"BTCUSDT\",\"b\":\"79716.80\",\"B\":\"2.569\",\"a\":\"79716.90\",\"A\":\"15.157\",\"T\":1788564456239,\"E\":1788564456239,\"st\":1}}"}
{"receive_ns":1788564456232698000,"stream":"btcusdt@bookTicker","event_type":"bookTicker","event_time_ms":1788564456239,"raw_json":"{\"stream\":\"btcusdt@bookTicker\",\"data\":{\"e\":\"bookTicker\",\"u\":11478296574851,\"s\":\"BTCUSDT\",\"ps\":\"BTCUSDT\",\"b\":\"79716.80\",\"B\":\"2.569\",\"a\":\"79716.90\",\"A\":\"15.138\",\"T\":1788564456239,\"E\":1788564456239,\"st\":1}}"}
{"receive_ns":1788564456239381000,"stream":"btcusdt@bookTicker","event_type":"bookTicker","event_time_ms":1788564456240,"raw_json":"{\"stream\":\"btcusdt@bookTicker\",\"data\":{\"e\":\"bookTicker\",\"u\":11478296574879,\"s\":\"BTCUSDT\",\"ps\":\"BTCUSDT\",\"b\":\"79716.80\",\"B\":\"2.569\",\"a\":\"79716.90\",\"A\":\"15.136\",\"T\":1788564456239,\"E\":1788564456240,\"st\":1}}"}
{"receive_ns":1788564456316048000,"stream":"btcusdt@depth@100ms","event_type":"depthUpdate","event_time_ms":1788564456333,"raw_json":"{\"stream\":\"btcusdt@depth@100ms\",\"data\":{\"e\":\"depthUpdate\",\"E\":1788564456333,\"T\":1788564456330,\"s\":\"BTCUSDT\",\"ps\":\"BTCUSDT\",\"U\":11478296574273,\"u\":11478296580391,\"pu\":11478296574092,\"b\":[[\"29416.80\",\"0.007\"],[\"29516.80\",\"1.757\"],[\"29616.80\",\"0.336\"],[\"63773.40\",\"0.000\"],[\"71745.10\",\"0.002\"],[\"75731.10\",\"0.004\"],[\"76528.10\",\"0.000\"],[\"78600.80\",\"15.907\"],[\"78919.60\",\"5.397\"],[\"79501.60\",\"0.859\"],[\"79522.20\",\"0.036\"],[\"79522.70\",\"1.004\"],[\"79529.50\",\"1.553\"],[\"79531.80\",\"0.033\"],[\"79555.30\",\"0.739\"],[\"79675.10\",\"0.835\"],[\"79693.10\",\"0.003\"],[\"79698.80\",\"0.579\"],[\"79698.90\",\"0.140\"],[\"79700.00\",\"0.314\"],[\"79703.40\",\"0.020\"],[\"79710.00\",\"0.041\"],[\"79710.50\",\"0.002\"],[\"79711.00\",\"0.000\"],[\"79716.80\",\"2.569\"]],\"a\":[[\"79716.90\",\"15.136\"],[\"79733.00\",\"0.630\"],[\"79792.60\",\"0.701\"],[\"79808.00\",\"3.024\"],[\"79814.00\",\"0.196\"],[\"79814.20\",\"0.020\"],[\"79814.30\",\"0.000\"],[\"79866.40\",\"0.000\"],[\"79886.30\",\"0.090\"],[\"79924.40\",\"3.666\"],[\"79938.10\",\"0.000\"],[\"80078.80\",\"0.764\"],[\"80087.60\",\"0.729\"],[\"80334.00\",\"0.250\"],[\"80514.10\",\"2.809\"],[\"80652.80\",\"10.530\"],[\"81072.10\",\"0.942\"],[\"81311.20\",\"0.027\"]],\"st\":1}}"}
{"receive_ns":1788564456334317000,"stream":"btcusdt@bookTicker","event_type":"bookTicker","event_time_ms":1788564456353,"raw_json":"{\"stream\":\"btcusdt@bookTicker\",\"data\":{\"e\":\"bookTicker\",\"u\":11478296581626,\"s\":\"BTCUSDT\",\"ps\":\"BTCUSDT\",\"b\":\"79716.80\",\"B\":\"2.569\",\"a\":\"79716.90\",\"A\":\"15.137\",\"T\":1788564456353,\"E\":1788564456353,\"st\":1}}"}
{"receive_ns":1788564456368424000,"stream":"btcusdt@bookTicker","event_type":"bookTicker","event_time_ms":1788564456389,"raw_json":"{\"stream\":\"btcusdt@bookTicker\",\"data\":{\"e\":\"bookTicker\",\"u\":11478296583597,\"s\":\"BTCUSDT\",\"ps\":\"BTCUSDT\",\"b\":\"79716.80\",\"B\":\"2.569\",\"a\":\"79716.90\",\"A\":\"15.130\",\"T\":1788564456389,\"E\":1788564456389,\"st\":1}}"}
{"receive_ns":1788564456381463000,"stream":"btcusdt@bookTicker","event_type":"bookTicker","event_time_ms":1788564456391,"raw_json":"{\"stream\":\"btcusdt@bookTicker\",\"data\":{\"e\":\"bookTicker\",\"u\":11478296583759,\"s\":\"BTCUSDT\",\"ps\":\"BTCUSDT\",\"b\":\"79716.80\",\"B\":\"2.569\",\"a\":\"79716.90\",\"A\":\"15.136\",\"T\":1788564456391,\"E\":1788564456391,\"st\":1}}"}
{"receive_ns":1788564456417225000,"stream":"btcusdt@depth@100ms","event_type":"depthUpdate","event_time_ms":1788564456435,"raw_json":"{\"stream\":\"btcusdt@depth@100ms\",\"data\":{\"e\":\"depthUpdate\",\"E\":1788564456435,\"T\":1788564456434,\"s\":\"BTCUSDT\",\"ps\":\"BTCUSDT\",\"U\":11478296580561,\"u\":11478296586749,\"pu\":11478296580391,\"b\":[[\"1000.00\",\"24.754\"],[\"29416.80\",\"0.070\"],[\"29516.80\",\"1.813\"],[\"29616.80\",\"0.217\"],[\"71745.10\",\"0.002\"],[\"78454.70\",\"2.750\"],[\"78580.20\",\"0.000\"],[\"78733.60\",\"12.070\"],[\"78919.60\",\"5.399\"],[\"79058.70\",\"3.409\"],[\"79118.90\",\"1.907\"],[\"79318.20\",\"3.276\"],[\"79320.20\",\"0.000\"],[\"79507.10\",\"6.691\"],[\"79507.80\",\"0.283\"],[\"79529.50\",\"2.054\"],[\"79594.40\",\"0.660\"],[\"79621.10\",\"0.040\"],[\"79645.00\",\"0.002\"],[\"79698.90\",\"0.065\"],[\"79707.90\",\"0.122\"],[\"79708.50\",\"0.002\"],[\"79708.90\",\"1.538\"],[\"79709.10\",\"0.001\"],[\"79710.50\",\"0.028\"],[\"79711.30\",\"0.026\"],[\"79711.50\",\"0.030\"]],\"a\":[[\"79716.90\",\"15.136\"],[\"79756.80\",\"0.728\"],[\"79772.80\",\"0.314\"],[\"79788.70\",\"0.021\"],[\"79792.60\",\"0.451\"],[\"79840.20\",\"0.290\"],[\"79927.50\",\"7.341\"],[\"79938.70\",\"0.006\"],[\"79938.80\",\"8.404\"],[\"80087.60\",\"1.147\"],[\"80514.10\",\"2.809\"],[\"80682.50\",\"0.848\"],[\"80825.00\",\"3.212\"],[\"80992.40\",\"0.345\"]],\"st\":1}}"}
{"receive_ns":1788564456496752000,"stream":"btcusdt@bookTicker","event_type":"bookTicker","event_time_ms":1788564456521,"raw_json":"{\"stream\":\"btcusdt@bookTicker\",\"data\":{\"e\":\"bookTicker\",\"u\":11478296591313,\"s\":\"BTCUSDT\",\"ps\":\"BTCUSDT\",\"b\":\"79716.80\",\"B\":\"2.556\",\"a\":\"79716.90\",\"A\":\"15.136\",\"T\":1788564456521,\"E\":1788564456521,\"st\":1}}"}
{"receive_ns":1788564456502546000,"stream":"btcusdt@trade","event_type":"trade","event_time_ms":1788564456521,"raw_json":"{\"stream\":\"btcusdt@trade\",\"data\":{\"e\":\"trade\",\"E\":1788564456521,\"T\":1788564456521,\"s\":\"BTCUSDT\",\"t\":8054096477,\"p\":\"79716.80\",\"q\":\"0.013\",\"X\":\"MARKET\",\"m\":true,\"st\":1}}"}
{"receive_ns":1788564456513356000,"stream":"btcusdt@bookTicker","event_type":"bookTicker","event_time_ms":1788564456522,"raw_json":"{\"stream\":\"btcusdt@bookTicker\",\"data\":{\"e\":\"bookTicker\",\"u\":11478296591448,\"s\":\"BTCUSDT\",\"ps\":\"BTCUSDT\",\"b\":\"79716.80\",\"B\":\"2.556\",\"a\":\"79716.90\",\"A\":\"15.138\",\"T\":1788564456522,\"E\":1788564456522,\"st\":1}}"}
{"receive_ns":1788564456513573000,"stream":"btcusdt@bookTicker","event_type":"bookTicker","event_time_ms":1788564456522,"raw_json":"{\"stream\":\"btcusdt@bookTicker\",\"data\":{\"e\":\"bookTicker\",\"u\":11478296591471,\"s\":\"BTCUSDT\",\"ps\":\"BTCUSDT\",\"b\":\"79716.80\",\"B\":\"2.556\",\"a\":\"79716.90\",\"A\":\"15.157\",\"T\":1788564456522,\"E\":1788564456522,\"st\":1}}"}
{"receive_ns":1788564456520122000,"stream":"btcusdt@bookTicker","event_type":"bookTicker","event_time_ms":1788564456523,"raw_json":"{\"stream\":\"btcusdt@bookTicker\",\"data\":{\"e\":\"bookTicker\",\"u\":11478296591580,\"s\":\"BTCUSDT\",\"ps\":\"BTCUSDT\",\"b\":\"79716.80\",\"B\":\"2.556\",\"a\":\"79716.90\",\"A\":\"15.155\",\"T\":1788564456523,\"E\":1788564456523,\"st\":1}}"}
{"receive_ns":1788564456520320000,"stream":"btcusdt@bookTicker","event_type":"bookTicker","event_time_ms":1788564456523,"raw_json":"{\"stream\":\"btcusdt@bookTicker\",\"data\":{\"e\":\"bookTicker\",\"u\":11478296591591,\"s\":\"BTCUSDT\",\"ps\":\"BTCUSDT\",\"b\":\"79716.80\",\"B\":\"2.556\",\"a\":\"79716.90\",\"A\":\"15.136\",\"T\":1788564456523,\"E\":1788564456523,\"st\":1}}"}
{"receive_ns":1788564456527029000,"stream":"btcusdt@depth@100ms","event_type":"depthUpdate","event_time_ms":1788564456537,"raw_json":"{\"stream\":\"btcusdt@depth@100ms\",\"data\":{\"e\":\"depthUpdate\",\"E\":1788564456537,\"T\":1788564456533,\"s\":\"BTCUSDT\",\"ps\":\"BTCUSDT\",\"U\":11478296586841,\"u\":11478296592192,\"pu\":11478296586749,\"b\":[[\"29416.80\",\"0.126\"],[\"29516.80\",\"1.876\"],[\"29616.80\",\"0.098\"],[\"71745.10\",\"0.002\"],[\"76528.10\",\"0.002\"],[\"78458.60\",\"2.038\"],[\"78919.60\",\"5.397\"],[\"79320.20\",\"0.140\"],[\"79501.60\",\"0.628\"],[\"79522.70\",\"0.001\"],[\"79529.50\",\"0.951\"],[\"79711.50\",\"0.030\"],[\"79716.80\",\"2.556\"]],\"a\":[[\"79716.90\",\"15.136\"],[\"79792.60\",\"0.451\"],[\"79886.30\",\"0.000\"],[\"80078.80\",\"0.002\"],[\"80087.60\",\"0.579\"],[\"80354.60\",\"5.592\"],[\"80514.10\",\"2.809\"],[\"80646.20\",\"14.736\"],[\"80673.50\",\"21.907\"]],\"st\":1}}"}
{"receive_ns":1788564456591348000,"stream":"btcusdt@bookTicker","event_type":"bookTicker","event_time_ms":1788564456609,"raw_json":"{\"stream\":\"btcusdt@bookTicker\",\"data\":{\"e\":\"bookTicker\",\"u\":11478296596438,\"s\":\"BTCUSDT\",\"ps\":\"BTCUSDT\",\"b\":\"79716.80\",\"B\":\"2.556\",\"a\":\"79716.90\",\"A\":\"15.135\",\"T\":1788564456609,\"E\":1788564456609,\"st\":1}}"}
{"receive_ns":1788564456597823000,"stream":"btcusdt@trade","event_type":"trade","event_time_ms":1788564456609,"raw_json":"{\"stream\":\"btcusdt@trade\",\"data\":{\"e\":\"trade\",\"E\":1788564456609,\"T\":1788564456609,\"s\":\"BTCUSDT\",\"t\":8054096478,\"p\":\"79716.90\",\"q\":\"0.001\",\"X\":\"MARKET\",\"m\":false,\"st\":1}}"}
{"receive_ns":1788564456615671000,"stream":"btcusdt@bookTicker","event_type":"bookTicker","event_time_ms":1788564456610,"raw_json":"{\"stream\":\"btcusdt@bookTicker\",\"data\":{\"e\":\"bookTicker\",\"u\":11478296596530,\"s\":\"BTCUSDT\",\"ps\":\"BTCUSDT\",\"b\":\"79716.80\",\"B\":\"2.556\",\"a\":\"79716.90\",\"A\":\"15.154\",\"T\":1788564456610,\"E\":1788564456610,\"st\":1}}"}
{"receive_ns":1788564456615884000,"stream":"btcusdt@bookTicker","event_type":"bookTicker","event_time_ms":1788564456611,"raw_json":"{\"stream\":\"btcusdt@bookTicker\",\"data\":{\"e\":\"bookTicker\",\"u\":11478296596592,\"s\":\"BTCUSDT\",\"ps\":\"BTCUSDT\",\"b\":\"79716.80\",\"B\":\"2.556\",\"a\":\"79716.90\",\"A\":\"15.156\",\"T\":1788564456610,\"E\":1788564456611,\"st\":1}}"}
{"receive_ns":1788564456621550000,"stream":"btcusdt@bookTicker","event_type":"bookTicker","event_time_ms":1788564456611,"raw_json":"{\"stream\":\"btcusdt@bookTicker\",\"data\":{\"e\":\"bookTicker\",\"u\":11478296596677,\"s\":\"BTCUSDT\",\"ps\":\"BTCUSDT\",\"b\":\"79716.80\",\"B\":\"2.556\",\"a\":\"79716.90\",\"A\":\"15.137\",\"T\":1788564456611,\"E\":1788564456611,\"st\":1}}"}
{"receive_ns":1788564456621742000,"stream":"btcusdt@bookTicker","event_type":"bookTicker","event_time_ms":1788564456611,"raw_json":"{\"stream\":\"btcusdt@bookTicker\",\"data\":{\"e\":\"bookTicker\",\"u\":11478296596682,\"s\":\"BTCUSDT\",\"ps\":\"BTCUSDT\",\"b\":\"79716.80\",\"B\":\"2.556\",\"a\":\"79716.90\",\"A\":\"15.135\",\"T\":1788564456611,\"E\":1788564456611,\"st\":1}}"}
{"receive_ns":1788564456635768000,"stream":"btcusdt@depth@100ms","event_type":"depthUpdate","event_time_ms":1788564456639,"raw_json":"{\"stream\":\"btcusdt@depth@100ms\",\"data\":{\"e\":\"depthUpdate\",\"E\":1788564456639,\"T\":1788564456638,\"s\":\"BTCUSDT\",\"ps\":\"BTCUSDT\",\"U\":11478296592442,\"u\":11478296598628,\"pu\":11478296592192,\"b\":[[\"29416.80\",\"0.210\"],[\"29516.80\",\"1.890\"],[\"29616.80\",\"0.000\"],[\"63773.00\",\"0.000\"],[\"71745.10\",\"0.002\"],[\"76528.10\",\"0.000\"],[\"78188.20\",\"0.000\"],[\"78570.70\",\"0.204\"],[\"78919.60\",\"5.397\"],[\"79318.20\",\"3.275\"],[\"79500.80\",\"1.003\"],[\"79501.60\",\"1.862\"],[\"79529.50\",\"1.126\"],[\"79698.70\",\"0.003\"],[\"79699.00\",\"0.064\"],[\"79699.10\",\"0.637\"],[\"79699.20\",\"0.065\"],[\"79700.00\",\"0.390\"],[\"79700.50\",\"0.320\"],[\"79700.80\",\"0.330\"],[\"79709.20\",\"0.001\"],[\"79709.30\",\"1.001\"],[\"79710.40\",\"0.029\"],[\"79710.50\",\"0.026\"],[\"79711.50\",\"0.004\"],[\"79711.60\",\"0.026\"],[\"79712.50\",\"0.026\"],[\"79712.60\",\"0.027\"]],\"a\":[[\"79716.90\",\"15.135\"],[\"79723.00\",\"0.012\"],[\"79725.50\",\"0.421\"],[\"79726.10\",\"0.334\"],[\"79792.60\",\"0.701\"],[\"79886.30\",\"0.090\"],[\"80078.80\",\"0.764\"],[\"80087.60\",\"1.147\"],[\"80115.50\",\"3.242\"],[\"80354.60\",\"5.840\"],[\"80514.10\",\"2.809\"],[\"80713.40\",\"5.611\"],[\"80931.70\",\"0.001\"],[\"87688.60\",\"0.002\"]],\"st\":1}}"}
{"receive_ns":1788564456641654000,"stream":"btcusdt@bookTicker","event_type":"bookTicker","event_time_ms":1788564456639,"raw_json":"{\"stream\":\"btcusdt@bookTicker\",\"data\":{\"e\":\"bookTicker\",\"u\":11478296598697,\"s\":\"BTCUSDT\",\"ps\":\"BTCUSDT\",\"b\":\"79716.80\",\"B\":\"2.556\",\"a\":\"79716.90\",\"A\":\"15.154\",\"T\":1788564456639,\"E\":1788564456639,\"st\":1}}"}
{"receive_ns":1788564456648235000,"stream":"btcusdt@bookTicker","event_type":"bookTicker","event_time_ms":1788564456640,"raw_json":"{\"stream\":\"btcusdt@bookTicker\",\"data\":{\"e\":\"bookTicker\",\"u\":11478296598762,\"s\":\"BTCUSDT\",\"ps\":\"BTCUSDT\",\"b\":\"79716.80\",\"B\":\"2.556\",\"a\":\"79716.90\",\"A\":\"15.135\",\"T\":1788564456639,\"E\":1788564456640,\"st\":1}}"}
{"receive_ns":1788564456648450000,"stream":"btcusdt@bookTicker","event_type":"bookTicker","event_time_ms":1788564456677,"raw_json":"{\"stream\":\"btcusdt@bookTicker\",\"data\":{\"e\":\"bookTicker\",\"u\":11478296601991,\"s\":\"BTCUSDT\",\"ps\":\"BTCUSDT\",\"b\":\"79716.80\",\"B\":\"2.556\",\"a\":\"79716.90\",\"A\":\"15.154\",\"T\":1788564456677,\"E\":1788564456677,\"st\":1}}"}
{"receive_ns":1788564456660325000,"stream":"btcusdt@bookTicker","event_type":"bookTicker","event_time_ms":1788564456678,"raw_json":"{\"stream\":\"btcusdt@bookTicker\",\"data\":{\"e\":\"bookTicker\",\"u\":11478296602090,\"s\":\"BTCUSDT\",\"ps\":\"BTCUSDT\",\"b\":\"79716.80\",\"B\":\"2.556\",\"a\":\"79716.90\",\"A\":\"15.135\",\"T\":1788564456678,\"E\":1788564456678,\"st\":1}}"}
{"receive_ns":1788564456723517000,"stream":"btcusdt@depth@100ms","event_type":"depthUpdate","event_time_ms":1788564456741,"raw_json":"{\"stream\":\"btcusdt@depth@100ms\",\"data\":{\"e\":\"depthUpdate\",\"E\":1788564456741,\"T\":1788564456738,\"s\":\"BTCUSDT\",\"ps\":\"BTCUSDT\",\"U\":11478296598697,\"u\":11478296606695,\"pu\":11478296598628,\"b\":[[\"1000.00\",\"24.754\"],[\"29416.80\",\"0.385\"],[\"29516.80\",\"1.715\"],[\"71745.10\",\"0.002\"],[\"76528.10\",\"0.002\"],[\"78600.80\",\"16.669\"],[\"78919.60\",\"5.397\"],[\"79318.20\",\"3.285\"],[\"79320.20\",\"0.140\"],[\"79529.50\",\"1.126\"],[\"79608.30\",\"0.032\"],[\"79688.90\",\"0.000\"],[\"79689.40\",\"0.003\"],[\"79690.10\",\"0.920\"],[\"79698.60\",\"1.582\"],[\"79699.10\",\"0.627\"],[\"79699.20\",\"0.087\"],[\"79700.80\",\"0.019\"],[\"79701.00\",\"0.020\"],[\"79701.10\",\"0.077\"],[\"79701.20\",\"0.313\"],[\"79709.40\",\"0.172\"],[\"79713.00\",\"0.027\"]],\"a\":[[\"79716.90\",\"15.135\"],[\"79738.60\",\"0.000\"],[\"79739.60\",\"0.455\"],[\"79790.30\",\"0.059\"],[\"79792.60\",\"0.701\"],[\"80087.60\",\"1.147\"],[\"80514.10\",\"2.809\"],[\"80952.50\",\"4.196\"],[\"87688.60\",\"0.000\"]],\"st\":1}}"}
{"receive_ns":1788564456730158000,"stream":"btcusdt@bookTicker","event_type":"bookTicker","event_time_ms":1788564456750,"raw_json":"{\"stream\":\"btcusdt@bookTicker\",\"data\":{\"e\":\"bookTicker\",\"u\":11478296607432,\"s\":\"BTCUSDT\",\"ps\":\"BTCUSDT\",\"b\":\"79716.80\",\"B\":\"2.556\",\"a\":\"79716.90\",\"A\":\"15.154\",\"T\":1788564456749,\"E\":1788564456750,\"st\":1}}"}
{"receive_ns":1788564456735866000,"stream":"btcusdt@bookTicker","event_type":"bookTicker","event_time_ms":1788564456750,"raw_json":"{\"stream\":\"btcusdt@bookTicker\",\"data\":{\"e\":\"bookTicker\",\"u\":11478296607508,\"s\":\"BTCUSDT\",\"ps\":\"BTCUSDT\",\"b\":\"79716.80\",\"B\":\"2.556\",\"a\":\"79716.90\",\"A\":\"15.135\",\"T\":1788564456750,\"E\":1788564456750,\"st\":1}}"}
{"receive_ns":1788564456826913000,"stream":"btcusdt@depth@100ms","event_type":"depthUpdate","event_time_ms":1788564456843,"raw_json":"{\"stream\":\"btcusdt@depth@100ms\",\"data\":{\"e\":\"depthUpdate\",\"E\":1788564456843,\"T\":1788564456841,\"s\":\"BTCUSDT\",\"ps\":\"BTCUSDT\",\"U\":11478296606937,\"u\":11478296614486,\"pu\":11478296606695,\"b\":[[\"29416.80\",\"0.567\"],[\"29516.80\",\"1.533\"],[\"71745.10\",\"0.002\"],[\"78281.90\",\"0.776\"],[\"78733.70\",\"1.257\"],[\"78899.30\",\"2.215\"],[\"78919.60\",\"5.397\"],[\"79500.80\",\"1.003\"],[\"79501.60\",\"1.962\"],[\"79529.50\",\"0.525\"],[\"79663.50\",\"0.000\"],[\"79697.60\",\"0.107\"]],\"a\":[[\"79716.90\",\"15.135\"],[\"79769.70\",\"0.000\"],[\"79792.60\",\"0.701\"],[\"79886.30\",\"0.090\"],[\"80078.80\",\"0.764\"],[\"80087.60\",\"0.729\"],[\"80514.10\",\"2.809\"],[\"80793.10\",\"0.816\"]],\"st\":1}}"}
{"receive_ns":1788564456926288000,"stream":"btcusdt@depth@100ms","event_type":"depthUpdate","event_time_ms":1788564456945,"raw_json":"{\"stream\":\"btcusdt@depth@100ms\",\"data\":{\"e\":\"depthUpdate\",\"E\":1788564456945,\"T\":1788564456942,\"s\":\"BTCUSDT\",\"ps\":\"BTCUSDT\",\"U\":11478296614674,\"u\":11478296621694,\"pu\":11478296614486,\"b\":[[\"29416.80\",\"0.742\"],[\"29516.80\",\"1.358\"],[\"71745.10\",\"0.002\"],[\"75256.90\",\"0.002\"],[\"76528.10\",\"0.000\"],[\"78727.30\",\"1.774\"],[\"78745.90\",\"0.635\"],[\"78919.60\",\"5.397\"],[\"79318.20\",\"3.284\"],[\"79320.20\",\"0.140\"],[\"79501.60\",\"2.162\"],[\"79529.50\",\"0.576\"],[\"79594.40\",\"0.000\"],[\"79663.90\",\"0.003\"],[\"79699.20\",\"0.087\"],[\"79700.80\",\"0.019\"],[\"79710.40\",\"0.055\"],[\"79711.70\",\"0.026\"],[\"79712.50\",\"0.000\"],[\"79712.60\",\"0.001\"],[\"79713.00\",\"0.001\"]],\"a\":[[\"79769.70\",\"0.001\"],[\"79792.60\",\"0.701\"],[\"79840.20\",\"0.001\"],[\"80087.60\",\"0.992\"]],\"st\":1}}"}
{"receive_ns":1788564457033247000,"stream":"btcusdt@depth@100ms","event_type":"depthUpdate","event_time_ms":1788564457047,"raw_json":"{\"stream\":\"btcusdt@depth@100ms\",\"data\":{\"e\":\"depthUpdate\",\"E\":1788564457047,\"T\":1788564457045,\"s\":\"BTCUSDT\",\"ps\":\"BTCUSDT\",\"U\":11478296621856,\"u\":11478296627313,\"pu\":11478296621694,\"b\":[[\"1000.00\",\"24.754\"],[\"29416.80\",\"0.924\"],[\"29516.80\",\"1.176\"],[\"71745.10\",\"0.002\"],[\"76528.10\",\"0.002\"],[\"77723.90\",\"0.001\"],[\"78339.20\",\"0.000\"],[\"78760.20\",\"18.892\"],[\"78919.60\",\"5.397\"],[\"79318.20\",\"3.284\"],[\"79500.80\",\"1.003\"],[\"79501.60\",\"2.062\"],[\"79529.50\",\"0.926\"],[\"79594.40\",\"0.673\"],[\"79699.20\",\"0.079\"],[\"79700.80\",\"0.027\"],[\"79702.50\",\"0.004\"]],\"a\":[[\"79792.60\",\"0.701\"],[\"79840.20\",\"0.351\"],[\"79886.30\",\"0.090\"],[\"80078.80\",\"0.764\"],[\"80087.60\",\"1.147\"],[\"80314.80\",\"2.506\"],[\"80514.10\",\"2.809\"],[\"80852.00\",\"2.022\"],[\"81011.40\",\"0.000\"]],\"st\":1}}"}
{"receive_ns":1788564457132093000,"stream":"btcusdt@depth@100ms","event_type":"depthUpdate","event_time_ms":1788564457149,"raw_json":"{\"stream\":\"btcusdt@depth@100ms\",\"data\":{\"e\":\"depthUpdate\",\"E\":1788564457149,\"T\":1788564457148,\"s\":\"BTCUSDT\",\"ps\":\"BTCUSDT\",\"U\":11478296627419,\"u\":11478296633995,\"pu\":11478296627313,\"b\":[[\"29416.80\",\"1.099\"],[\"29516.80\",\"1.001\"],[\"71745.10\",\"0.002\"],[\"76528.10\",\"0.000\"],[\"78681.60\",\"0.254\"],[\"78739.90\",\"11.733\"],[\"78760.20\",\"20.793\"],[\"78784.10\",\"0.886\"],[\"78919.60\",\"5.397\"],[\"79501.60\",\"2.062\"],[\"79529.50\",\"0.926\"],[\"79625.40\",\"0.001\"],[\"79699.20\",\"0.087\"],[\"79700.80\",\"0.019\"],[\"79702.50\",\"0.000\"],[\"79712.60\",\"0.027\"]],\"a\":[[\"79792.60\",\"0.701\"],[\"79807.80\",\"0.500\"],[\"79814.30\",\"0.001\"],[\"79816.20\",\"0.002\"],[\"79817.70\",\"0.002\"],[\"80087.60\",\"1.147\"],[\"80115.50\",\"3.243\"],[\"80514.10\",\"2.811\"]],\"st\":1}}"}
{"receive_ns":1788564457144256000,"stream":"btcusdt@bookTicker","event_type":"bookTicker","event_time_ms":1788564457158,"raw_json":"{\"stream\":\"btcusdt@bookTicker\",\"data\":{\"e\":\"bookTicker\",\"u\":11478296634472,\"s\":\"BTCUSDT\",\"ps\":\"BTCUSDT\",\"b\":\"79716.80\",\"B\":\"2.556\",\"a\":\"79716.90\",\"A\":\"15.126\",\"T\":1788564457157,\"E\":1788564457158,\"st\":1}}"}
{"receive_ns":1788564457160484000,"stream":"btcusdt@bookTicker","event_type":"bookTicker","event_time_ms":1788564457160,"raw_json":"{\"stream\":\"btcusdt@bookTicker\",\"data\":{\"e\":\"bookTicker\",\"u\":11478296634696,\"s\":\"BTCUSDT\",\"ps\":\"BTCUSDT\",\"b\":\"79716.80\",\"B\":\"2.556\",\"a\":\"79716.90\",\"A\":\"15.137\",\"T\":1788564457160,\"E\":1788564457160,\"st\":1}}"}
{"receive_ns":1788564457160730000,"stream":"btcusdt@bookTicker","event_type":"bookTicker","event_time_ms":1788564457175,"raw_json":"{\"stream\":\"btcusdt@bookTicker\",\"data\":{\"e\":\"bookTicker\",\"u\":11478296635641,\"s\":\"BTCUSDT\",\"ps\":\"BTCUSDT\",\"b\":\"79716.80\",\"B\":\"2.556\",\"a\":\"79716.90\",\"A\":\"15.139\",\"T\":1788564457175,\"E\":1788564457175,\"st\":1}}"}
{"receive_ns":1788564457160899000,"stream":"btcusdt@bookTicker","event_type":"bookTicker","event_time_ms":1788564457176,"raw_json":"{\"stream\":\"btcusdt@bookTicker\",\"data\":{\"e\":\"bookTicker\",\"u\":11478296635678,\"s\":\"BTCUSDT\",\"ps\":\"BTCUSDT\",\"b\":\"79716.80\",\"B\":\"2.556\",\"a\":\"79716.90\",\"A\":\"15.158\",\"T\":1788564457176,\"E\":1788564457176,\"st\":1}}"}
{"receive_ns":1788564457169024000,"stream":"btcusdt@bookTicker","event_type":"bookTicker","event_time_ms":1788564457176,"raw_json":"{\"stream\":\"btcusdt@bookTicker\",\"data\":{\"e\":\"bookTicker\",\"u\":11478296635743,\"s\":\"BTCUSDT\",\"ps\":\"BTCUSDT\",\"b\":\"79716.80\",\"B\":\"2.556\",\"a\":\"79716.90\",\"A\":\"15.156\",\"T\":1788564457176,\"E\":1788564457176,\"st\":1}}"}
{"receive_ns":1788564457169244000,"stream":"btcusdt@bookTicker","event_type":"bookTicker","event_time_ms":1788564457177,"raw_json":"{\"stream\":\"btcusdt@bookTicker\",\"data\":{\"e\":\"bookTicker\",\"u\":11478296635783,\"s\":\"BTCUSDT\",\"ps\":\"BTCUSDT\",\"b\":\"79716.80\",\"B\":\"2.556\",\"a\":\"79716.90\",\"A\":\"15.137\",\"T\":1788564457176,\"E\":1788564457177,\"st\":1}}"}
{"receive_ns":1788564457175193000,"stream":"btcusdt@bookTicker","event_type":"bookTicker","event_time_ms":1788564457181,"raw_json":"{\"stream\":\"btcusdt@bookTicker\",\"data\":{\"e\":\"bookTicker\",\"u\":11478296636009,\"s\":\"BTCUSDT\",\"ps\":\"BTCUSDT\",\"b\":\"79716.80\",\"B\":\"2.656\",\"a\":\"79716.90\",\"A\":\"15.137\",\"T\":1788564457181,\"E\":1788564457181,\"st\":1}}"}
{"receive_ns":1788564457187729000,"stream":"btcusdt@bookTicker","event_type":"bookTicker","event_time_ms":1788564457182,"raw_json":"{\"stream\":\"btcusdt@bookTicker\",\"data\":{\"e\":\"bookTicker\",\"u\":11478296636055,\"s\":\"BTCUSDT\",\"ps\":\"BTCUSDT\",\"b\":\"79716.80\",\"B\":\"2.654\",\"a\":\"79716.90\",\"A\":\"15.137\",\"T\":1788564457182,\"E\":1788564457182,\"st\":1}}"}
{"receive_ns":1788564457187995000,"stream":"btcusdt@bookTicker","event_type":"bookTicker","event_time_ms":1788564457202,"raw_json":"{\"stream\":\"btcusdt@bookTicker\",\"data\":{\"e\":\"bookTicker\",\"u\":11478296637101,\"s\":\"BTCUSDT\",\"ps\":\"BTCUSDT\",\"b\":\"79716.80\",\"B\":\"2.654\",\"a\":\"79716.90\",\"A\":\"15.156\",\"T\":1788564457202,\"E\":1788564457202,\"st\":1}}"}
{"receive_ns":1788564457194497000,"stream":"btcusdt@bookTicker","event_type":"bookTicker","event_time_ms":1788564457202,"raw_json":"{\"stream\":\"btcusdt@bookTicker\",\"data\":{\"e\":\"bookTicker\",\"u\":11478296637140,\"s\":\"BTCUSDT\",\"ps\":\"BTCUSDT\",\"b\":\"79716.80\",\"B\":\"2.654\",\"a\":\"79716.90\",\"A\":\"15.158\",\"T\":1788564457202,\"E\":1788564457202,\"st\":1}}"}
{"receive_ns":1788564457194717000,"stream":"btcusdt@bookTicker","event_type":"bookTicker","event_time_ms":1788564457203,"raw_json":"{\"stream\":\"btcusdt@bookTicker\",\"data\":{\"e\":\"bookTicker\",\"u\":11478296637193,\"s\":\"BTCUSDT\",\"ps\":\"BTCUSDT\",\"b\":\"79716.80\",\"B\":\"2.654\",\"a\":\"79716.90\",\"A\":\"15.139\",\"T\":1788564457203,\"E\":1788564457203,\"st\":1}}"}
{"receive_ns":1788564457199689000,"stream":"btcusdt@bookTicker","event_type":"bookTicker","event_time_ms":1788564457203,"raw_json":"{\"stream\":\"btcusdt@bookTicker\",\"data\":{\"e\":\"bookTicker\",\"u\":11478296637221,\"s\":\"BTCUSDT\",\"ps\":\"BTCUSDT\",\"b\":\"79716.80\",\"B\":\"2.654\",\"a\":\"79716.90\",\"A\":\"15.137\",\"T\":1788564457203,\"E\":1788564457203,\"st\":1}}"}
{"receive_ns":1788564457212649000,"stream":"btcusdt@bookTicker","event_type":"bookTicker","event_time_ms":1788564457204,"raw_json":"{\"stream\":\"btcusdt@bookTicker\",\"data\":{\"e\":\"bookTicker\",\"u\":11478296637248,\"s\":\"BTCUSDT\",\"ps\":\"BTCUSDT\",\"b\":\"79716.80\",\"B\":\"2.656\",\"a\":\"79716.90\",\"A\":\"15.137\",\"T\":1788564457203,\"E\":1788564457204,\"st\":1}}"}
{"receive_ns":1788564457224368000,"stream":"btcusdt@bookTicker","event_type":"bookTicker","event_time_ms":1788564457204,"raw_json":"{\"stream\":\"btcusdt@bookTicker\",\"data\":{\"e\":\"bookTicker\",\"u\":11478296637250,\"s\":\"BTCUSDT\",\"ps\":\"BTCUSDT\",\"b\":\"79716.80\",\"B\":\"2.656\",\"a\":\"79716.90\",\"A\":\"15.136\",\"T\":1788564457203,\"E\":1788564457204,\"st\":1}}"}
{"receive_ns":1788564457231171000,"stream":"btcusdt@depth@100ms","event_type":"depthUpdate","event_time_ms":1788564457251,"raw_json":"{\"stream\":\"btcusdt@depth@100ms\",\"data\":{\"e\":\"depthUpdate\",\"E\":1788564457251,\"T\":1788564457249,\"s\":\"BTCUSDT\",\"ps\":\"BTCUSDT\",\"U\":11478296634025,\"u\":11478296639613,\"pu\":11478296633995,\"b\":[[\"1000.00\",\"24.754\"],[\"29416.80\",\"1.281\"],[\"29516.80\",\"0.819\"],[\"71745.10\",\"0.002\"],[\"76528.10\",\"0.002\"],[\"78122.50\",\"0.161\"],[\"78680.50\",\"2.158\"],[\"78919.60\",\"5.397\"],[\"79320.20\",\"0.140\"],[\"79529.50\",\"0.926\"],[\"79594.40\",\"0.673\"],[\"79602.00\",\"0.033\"],[\"79625.50\",\"3.869\"],[\"79699.20\",\"0.087\"],[\"79700.80\",\"0.019\"],[\"79709.50\",\"0.001\"],[\"79712.80\",\"0.026\"],[\"79715.10\",\"0.000\"],[\"79715.40\",\"0.001\"],[\"79715.70\",\"0.000\"],[\"79715.90\",\"0.315\"],[\"79716.00\",\"0.006\"],[\"79716.20\",\"0.000\"],[\"79716.80\",\"2.656\"]],\"a\":[[\"79716.90\",\"15.136\"],[\"79723.80\",\"0.004\"],[\"79792.60\",\"0.701\"],[\"79807.80\",\"3.963\"],[\"79814.20\",\"0.021\"],[\"79816.20\",\"0.003\"],[\"79840.20\",\"0.351\"],[\"79938.80\",\"8.299\"],[\"80087.60\",\"1.147\"],[\"80514.10\",\"2.809\"],[\"80861.20\",\"0.000\"]],\"st\":1}}"}
{"receive_ns":1788564457247794000,"stream":"btcusdt@bookTicker","event_type":"bookTicker","event_time_ms":1788564457262,"raw_json":"{\"stream\":\"btcusdt@bookTicker\",\"data\":{\"e\":\"bookTicker\",\"u\":11478296640265,\"s\":\"BTCUSDT\",\"ps\":\"BTCUSDT\",\"b\":\"79716.80\",\"B\":\"2.656\",\"a\":\"79716.90\",\"A\":\"15.135\",\"T\":1788564457262,\"E\":1788564457262,\"st\":1}}"}
{"receive_ns":1788564457248030000,"stream":"btcusdt@trade","event_type":"trade","event_time_ms":1788564457262,"raw_json":"{\"stream\":\"btcusdt@trade\",\"data\":{\"e\":\"trade\",\"E\":1788564457262,\"T\":1788564457262,\"s\":\"BTCUSDT\",\"t\":8054096479,\"p\":\"79716.90\",\"q\":\"0.001\",\"X\":\"MARKET\",\"m\":false,\"st\":1}}"}
{"receive_ns":1788564457248270000,"stream":"btcusdt@bookTicker","event_type":"bookTicker","event_time_ms":1788564457263,"raw_json":"{\"stream\":\"btcusdt@bookTicker\",\"data\":{\"e\":\"bookTicker\",\"u\":11478296640356,\"s\":\"BTCUSDT\",\"ps\":\"BTCUSDT\",\"b\":\"79716.80\",\"B\":\"2.656\",\"a\":\"79716.90\",\"A\":\"15.154\",\"T\":1788564457263,\"E\":1788564457263,\"st\":1}}"}
{"receive_ns":1788564457248460000,"stream":"btcusdt@bookTicker","event_type":"bookTicker","event_time_ms":1788564457263,"raw_json":"{\"stream\":\"btcusdt@bookTicker\",\"data\":{\"e\":\"bookTicker\",\"u\":11478296640376,\"s\":\"BTCUSDT\",\"ps\":\"BTCUSDT\",\"b\":\"79716.80\",\"B\":\"2.656\",\"a\":\"79716.90\",\"A\":\"15.156\",\"T\":1788564457263,\"E\":1788564457263,\"st\":1}}"}
{"receive_ns":1788564457255004000,"stream":"btcusdt@bookTicker","event_type":"bookTicker","event_time_ms":1788564457264,"raw_json":"{\"stream\":\"btcusdt@bookTicker\",\"data\":{\"e\":\"bookTicker\",\"u\":11478296640459,\"s\":\"BTCUSDT\",\"ps\":\"BTCUSDT\",\"b\":\"79716.80\",\"B\":\"2.656\",\"a\":\"79716.90\",\"A\":\"15.137\",\"T\":1788564457264,\"E\":1788564457264,\"st\":1}}"}
{"receive_ns":1788564457255203000,"stream":"btcusdt@bookTicker","event_type":"bookTicker","event_time_ms":1788564457264,"raw_json":"{\"stream\":\"btcusdt@bookTicker\",\"data\":{\"e\":\"bookTicker\",\"u\":11478296640465,\"s\":\"BTCUSDT\",\"ps\":\"BTCUSDT\",\"b\":\"79716.80\",\"B\":\"2.656\",\"a\":\"79716.90\",\"A\":\"15.135\",\"T\":1788564457264,\"E\":1788564457264,\"st\":1}}"}
{"receive_ns":1788564457261593000,"stream":"btcusdt@bookTicker","event_type":"bookTicker","event_time_ms":1788564457265,"raw_json":"{\"stream\":\"btcusdt@bookTicker\",\"data\":{\"e\":\"bookTicker\",\"u\":11478296640510,\"s\":\"BTCUSDT\",\"ps\":\"BTCUSDT\",\"b\":\"79716.80\",\"B\":\"2.656\",\"a\":\"79716.90\",\"A\":\"15.136\",\"T\":1788564457264,\"E\":1788564457265,\"st\":1}}"}
{"receive_ns":1788564457282588000,"stream":"btcusdt@bookTicker","event_type":"bookTicker","event_time_ms":1788564457290,"raw_json":"{\"stream\":\"btcusdt@bookTicker\",\"data\":{\"e\":\"bookTicker\",\"u\":11478296641725,\"s\":\"BTCUSDT\",\"ps\":\"BTCUSDT\",\"b\":\"79716.80\",\"B\":\"2.656\",\"a\":\"79716.90\",\"A\":\"15.130\",\"T\":1788564457290,\"E\":1788564457290,\"st\":1}}"}
{"receive_ns":1788564457289227000,"stream":"btcusdt@bookTicker","event_type":"bookTicker","event_time_ms":1788564457292,"raw_json":"{\"stream\":\"btcusdt@bookTicker\",\"data\":{\"e\":\"bookTicker\",\"u\":11478296641868,\"s\":\"BTCUSDT\",\"ps\":\"BTCUSDT\",\"b\":\"79716.80\",\"B\":\"2.656\",\"a\":\"79716.90\",\"A\":\"15.137\",\"T\":1788564457292,\"E\":1788564457292,\"st\":1}}"}
{"receive_ns":1788564457318332000,"stream":"btcusdt@bookTicker","event_type":"bookTicker","event_time_ms":1788564457343,"raw_json":"{\"stream\":\"btcusdt@bookTicker\",\"data\":{\"e\":\"bookTicker\",\"u\":11478296644511,\"s\":\"BTCUSDT\",\"ps\":\"BTCUSDT\",\"b\":\"79716.80\",\"B\":\"2.656\",\"a\":\"79716.90\",\"A\":\"15.114\",\"T\":1788564457343,\"E\":1788564457343,\"st\":1}}"}
{"receive_ns":1788564457324977000,"stream":"btcusdt@bookTicker","event_type":"bookTicker","event_time_ms":1788564457347,"raw_json":"{\"stream\":\"btcusdt@bookTicker\",\"data\":{\"e\":\"bookTicker\",\"u\":11478296644717,\"s\":\"BTCUSDT\",\"ps\":\"BTCUSDT\",\"b\":\"79716.80\",\"B\":\"2.656\",\"a\":\"79716.90\",\"A\":\"15.119\",\"T\":1788564457347,\"E\":1788564457347,\"st\":1}}"}
{"receive_ns":1788564457331815000,"stream":"btcusdt@depth@100ms","event_type":"depthUpdate","event_time_ms":1788564457353,"raw_json":"{\"stream\":\"btcusdt@depth@100ms\",\"data\":{\"e\":\"depthUpdate\",\"E\":1788564457353,\"T\":1788564457350,\"s\":\"BTCUSDT\",\"ps\":\"BTCUSDT\",\"U\":11478296639711,\"u\":11478296644925,\"pu\":11478296639613,\"b\":[[\"1000.00\",\"24.754\"],[\"29416.80\",\"1.456\"],[\"29516.80\",\"0.644\"],[\"63773.40\",\"0.000\"],[\"71745.10\",\"0.002\"],[\"71782.00\",\"0.000\"],[\"75731.00\",\"0.071\"],[\"75731.10\",\"0.006\"],[\"78481.20\",\"2.546\"],[\"78919.60\",\"5.397\"],[\"79118.90\",\"2.538\"],[\"79318.20\",\"3.284\"],[\"79500.80\",\"1.003\"],[\"79501.60\",\"0.859\"],[\"79507.80\",\"1.210\"],[\"79529.50\",\"1.929\"],[\"79693.10\",\"0.003\"],[\"79699.20\",\"0.322\"],[\"79700.80\",\"0.093\"],[\"79701.00\",\"0.024\"],[\"79701.20\",\"0.000\"],[\"79709.60\",\"0.002\"],[\"79709.80\",\"0.099\"],[\"79710.30\",\"0.252\"],[\"79712.90\",\"0.026\"],[\"79713.50\",\"0.028\"]],\"a\":[[\"79716.90\",\"15.119\"],[\"79733.00\",\"0.630\"],[\"79792.60\",\"0.502\"],[\"79800.00\",\"5.013\"],[\"79863.20\",\"0.018\"],[\"79864.80\",\"0.014\"],[\"79886.30\",\"0.090\"],[\"79952.20\",\"2.908\"],[\"79952.30\",\"1.953\"],[\"80078.80\",\"0.764\"],[\"80087.60\",\"1.147\"],[\"80314.80\",\"3.128\"],[\"80514.10\",\"2.809\"],[\"80872.80\",\"6.697\"],[\"81032.20\",\"3.821\"]],\"st\":1}}"}
{"receive_ns":1788564457374573000,"stream":"btcusdt@bookTicker","event_type":"bookTicker","event_time_ms":1788564457394,"raw_json":"{\"stream\":\"btcusdt@bookTicker\",\"data\":{\"e\":\"bookTicker\",\"u\":11478296647024,\"s\":\"BTCUSDT\",\"ps\":\"BTCUSDT\",\"b\":\"79716.80\",\"B\":\"2.656\",\"a\":\"79716.90\",\"A\":\"14.869\",\"T\":1788564457394,\"E\":1788564457394,\"st\":1}}"}
{"receive_ns":1788564457380581000,"stream":"btcusdt@trade","event_type":"trade","event_time_ms":1788564457394,"raw_json":"{\"stream\":\"btcusdt@trade\",\"data\":{\"e\":\"trade\",\"E\":1788564457394,\"T\":1788564457394,\"s\":\"BTCUSDT\",\"t\":8054096480,\"p\":\"79716.90\",\"q\":\"0.250\",\"X\":\"MARKET\",\"m\":false,\"st\":1}}"}
{"receive_ns":1788564457380803000,"stream":"btcusdt@bookTicker","event_type":"bookTicker","event_time_ms":1788564457395,"raw_json":"{\"stream\":\"btcusdt@bookTicker\",\"data\":{\"e\":\"bookTicker\",\"u\":11478296647181,\"s\":\"BTCUSDT\",\"ps\":\"BTCUSDT\",\"b\":\"79716.80\",\"B\":\"2.656\",\"a\":\"79716.90\",\"A\":\"14.888\",\"T\":1788564457395,\"E\":1788564457395,\"st\":1}}"}
{"receive_ns":1788564457386689000,"stream":"btcusdt@bookTicker","event_type":"bookTicker","event_time_ms":1788564457395,"raw_json":"{\"stream\":\"btcusdt@bookTicker\",\"data\":{\"e\":\"bookTicker\",\"u\":11478296647207,\"s\":\"BTCUSDT\",\"ps\":\"BTCUSDT\",\"b\":\"79716.80\",\"B\":\"2.656\",\"a\":\"79716.90\",\"A\":\"14.890\",\"T\":1788564457395,\"E\":1788564457395,\"st\":1}}"}
{"receive_ns":1788564457386907000,"stream":"btcusdt@bookTicker","event_type":"bookTicker","event_time_ms":1788564457396,"raw_json":"{\"stream\":\"btcusdt@bookTicker\",\"data\":{\"e\":\"bookTicker\",\"u\":11478296647285,\"s\":\"BTCUSDT\",\"ps\":\"BTCUSDT\",\"b\":\"79716.80\",\"B\":\"2.656\",\"a\":\"79716.90\",\"A\":\"14.871\",\"T\":1788564457396,\"E\":1788564457396,\"st\":1}}"}
{"receive_ns":1788564457387079000,"stream":"btcusdt@bookTicker","event_type":"bookTicker","event_time_ms":1788564457396,"raw_json":"{\"stream\":\"btcusdt@bookTicker\",\"data\":{\"e\":\"bookTicker\",\"u\":11478296647291,\"s\":\"BTCUSDT\",\"ps\":\"BTCUSDT\",\"b\":\"79716.80\",\"B\":\"2.656\",\"a\":\"79716.90\",\"A\":\"14.869\",\"T\":1788564457396,\"E\":1788564457396,\"st\":1}}"}
{"receive_ns":1788564457393373000,"stream":"btcusdt@bookTicker","event_type":"bookTicker","event_time_ms":1788564457398,"raw_json":"{\"stream\":\"btcusdt@bookTicker\",\"data\":{\"e\":\"bookTicker\",\"u\":11478296647469,\"s\":\"BTCUSDT\",\"ps\":\"BTCUSDT\",\"b\":\"79716.80\",\"B\":\"2.988\",\"a\":\"79716.90\",\"A\":\"14.869\",\"T\":1788564457398,\"E\":1788564457398,\"st\":1}}"}
{"receive_ns":1788564457399917000,"stream":"btcusdt@bookTicker","event_type":"bookTicker","event_time_ms":1788564457399,"raw_json":"{\"stream\":\"btcusdt@bookTicker\",\"data\":{\"e\":\"bookTicker\",\"u\":11478296647563,\"s\":\"BTCUSDT\",\"ps\":\"BTCUSDT\",\"b\":\"79716.80\",\"B\":\"2.656\",\"a\":\"79716.90\",\"A\":\"14.869\",\"T\":1788564457399,\"E\":1788564457399,\"st\":1}}"}
{"receive_ns":1788564457400172000,"stream":"btcusdt@bookTicker","event_type":"bookTicker","event_time_ms":1788564457399,"raw_json":"{\"stream\":\"btcusdt@bookTicker\",\"data\":{\"e\":\"bookTicker\",\"u\":11478296647566,\"s\":\"BTCUSDT\",\"ps\":\"BTCUSDT\",\"b\":\"79716.80\",\"B\":\"2.654\",\"a\":\"79716.90\",\"A\":\"14.869\",\"T\":1788564457399,\"E\":1788564457399,\"st\":1}}"}
{"receive_ns":1788564457400391000,"stream":"btcusdt@bookTicker","event_type":"bookTicker","event_time_ms":1788564457399,"raw_json":"{\"stream\":\"btcusdt@bookTicker\",\"data\":{\"e\":\"bookTicker\",\"u\":11478296647611,\"s\":\"BTCUSDT\",\"ps\":\"BTCUSDT\",\"b\":\"79716.80\",\"B\":\"2.654\",\"a\":\"79716.90\",\"A\":\"14.888\",\"T\":1788564457399,\"E\":1788564457399,\"st\":1}}"}
{"receive_ns":1788564457400561000,"stream":"btcusdt@bookTicker","event_type":"bookTicker","event_time_ms":1788564457399,"raw_json":"{\"stream\":\"btcusdt@bookTicker\",\"data\":{\"e\":\"bookTicker\",\"u\":11478296647623,\"s\":\"BTCUSDT\",\"ps\":\"BTCUSDT\",\"b\":\"79716.80\",\"B\":\"2.654\",\"a\":\"79716.90\",\"A\":\"14.890\",\"T\":1788564457399,\"E\":1788564457399,\"st\":1}}"}
{"receive_ns":1788564457400749000,"stream":"btcusdt@bookTicker","event_type":"bookTicker","event_time_ms":1788564457400,"raw_json":"{\"stream\":\"btcusdt@bookTicker\",\"data\":{\"e\":\"bookTicker\",\"u\":11478296647686,\"s\":\"BTCUSDT\",\"ps\":\"BTCUSDT\",\"b\":\"79716.80\",\"B\":\"2.654\",\"a\":\"79716.90\",\"A\":\"14.888\",\"T\":1788564457399,\"E\":1788564457400,\"st\":1}}"}
{"receive_ns":1788564457400917000,"stream":"btcusdt@bookTicker","event_type":"bookTicker","event_time_ms":1788564457400,"raw_json":"{\"stream\":\"btcusdt@bookTicker\",\"data\":{\"e\":\"bookTicker\",\"u\":11478296647694,\"s\":\"BTCUSDT\",\"ps\":\"BTCUSDT\",\"b\":\"79716.80\",\"B\":\"2.654\",\"a\":\"79716.90\",\"A\":\"14.869\",\"T\":1788564457400,\"E\":1788564457400,\"st\":1}}"}
{"receive_ns":1788564457407408000,"stream":"btcusdt@bookTicker","event_type":"bookTicker","event_time_ms":1788564457400,"raw_json":"{\"stream\":\"btcusdt@bookTicker\",\"data\":{\"e\":\"bookTicker\",\"u\":11478296647714,\"s\":\"BTCUSDT\",\"ps\":\"BTCUSDT\",\"b\":\"79716.80\",\"B\":\"2.656\",\"a\":\"79716.90\",\"A\":\"14.869\",\"T\":1788564457400,\"E\":1788564457400,\"st\":1}}"}
{"receive_ns":1788564457407595000,"stream":"btcusdt@bookTicker","event_type":"bookTicker","event_time_ms":1788564457400,"raw_json":"{\"stream\":\"btcusdt@bookTicker\",\"data\":{\"e\":\"bookTicker\",\"u\":11478296647744,\"s\":\"BTCUSDT\",\"ps\":\"BTCUSDT\",\"b\":\"79716.80\",\"B\":\"2.656\",\"a\":\"79716.90\",\"A\":\"14.888\",\"T\":1788564457400,\"E\":1788564457400,\"st\":1}}"}
{"receive_ns":1788564457407762000,"stream":"btcusdt@bookTicker","event_type":"bookTicker","event_time_ms":1788564457400,"raw_json":"{\"stream\":\"btcusdt@bookTicker\",\"data\":{\"e\":\"bookTicker\",\"u\":11478296647745,\"s\":\"BTCUSDT\",\"ps\":\"BTCUSDT\",\"b\":\"79716.80\",\"B\":\"2.656\",\"a\":\"79716.90\",\"A\":\"14.890\",\"T\":1788564457400,\"E\":1788564457400,\"st\":1}}"}
{"receive_ns":1788564457413187000,"stream":"btcusdt@bookTicker","event_type":"bookTicker","event_time_ms":1788564457401,"raw_json":"{\"stream\":\"btcusdt@bookTicker\",\"data\":{\"e\":\"bookTicker\",\"u\":11478296647867,\"s\":\"BTCUSDT\",\"ps\":\"BTCUSDT\",\"b\":\"79716.80\",\"B\":\"2.656\",\"a\":\"79716.90\",\"A\":\"14.888\",\"T\":1788564457400,\"E\":1788564457401,\"st\":1}}"}
{"receive_ns":1788564457425256000,"stream":"btcusdt@bookTicker","event_type":"bookTicker","event_time_ms":1788564457401,"raw_json":"{\"stream\":\"btcusdt@bookTicker\",\"data\":{\"e\":\"bookTicker\",\"u\":11478296647874,\"s\":\"BTCUSDT\",\"ps\":\"BTCUSDT\",\"b\":\"79716.80\",\"B\":\"2.656\",\"a\":\"79716.90\",\"A\":\"14.869\",\"T\":1788564457401,\"E\":1788564457401,\"st\":1}}"}
{"receive_ns":1788564457425491000,"stream":"btcusdt@bookTicker","event_type":"bookTicker","event_time_ms":1788564457411,"raw_json":"{\"stream\":\"btcusdt@bookTicker\",\"data\":{\"e\":\"bookTicker\",\"u\":11478296648578,\"s\":\"BTCUSDT\",\"ps\":\"BTCUSDT\",\"b\":\"79716.80\",\"B\":\"2.656\",\"a\":\"79716.90\",\"A\":\"14.871\",\"T\":1788564457411,\"E\":1788564457411,\"st\":1}}"}
{"receive_ns":1788564457425662000,"stream":"btcusdt@bookTicker","event_type":"bookTicker","event_time_ms":1788564457412,"raw_json":"{\"stream\":\"btcusdt@bookTicker\",\"data\":{\"e\":\"bookTicker\",\"u\":11478296648624,\"s\":\"BTCUSDT\",\"ps\":\"BTCUSDT\",\"b\":\"79716.80\",\"B\":\"2.656\",\"a\":\"79716.90\",\"A\":\"14.890\",\"T\":1788564457411,\"E\":1788564457412,\"st\":1}}"}
{"receive_ns":1788564457431481000,"stream":"btcusdt@bookTicker","event_type":"bookTicker","event_time_ms":1788564457412,"raw_json":"{\"stream\":\"btcusdt@bookTicker\",\"data\":{\"e\":\"bookTicker\",\"u\":11478296648673,\"s\":\"BTCUSDT\",\"ps\":\"BTCUSDT\",\"b\":\"79716.80\",\"B\":\"2.656\",\"a\":\"79716.90\",\"A\":\"14.888\",\"T\":1788564457412,\"E\":1788564457412,\"st\":1}}"}
{"receive_ns":1788564457431765000,"stream":"btcusdt@bookTicker","event_type":"bookTicker","event_time_ms":1788564457412,"raw_json":"{\"stream\":\"btcusdt@bookTicker\",\"data\":{\"e\":\"bookTicker\",\"u\":11478296648691,\"s\":\"BTCUSDT\",\"ps\":\"BTCUSDT\",\"b\":\"79716.80\",\"B\":\"2.656\",\"a\":\"79716.90\",\"A\":\"14.869\",\"T\":1788564457412,\"E\":1788564457412,\"st\":1}}"}
{"receive_ns":1788564457444477000,"stream":"btcusdt@bookTicker","event_type":"bookTicker","event_time_ms":1788564457413,"raw_json":"{\"stream\":\"btcusdt@bookTicker\",\"data\":{\"e\":\"bookTicker\",\"u\":11478296648755,\"s\":\"BTCUSDT\",\"ps\":\"BTCUSDT\",\"b\":\"79716.80\",\"B\":\"2.656\",\"a\":\"79716.90\",\"A\":\"14.888\",\"T\":1788564457413,\"E\":1788564457413,\"st\":1}}"}
{"receive_ns":1788564457444688000,"stream":"btcusdt@bookTicker","event_type":"bookTicker","event_time_ms":1788564457413,"raw_json":"{\"stream\":\"btcusdt@bookTicker\",\"data\":{\"e\":\"bookTicker\",\"u\":11478296648763,\"s\":\"BTCUSDT\",\"ps\":\"BTCUSDT\",\"b\":\"79716.80\",\"B\":\"2.656\",\"a\":\"79716.90\",\"A\":\"14.890\",\"T\":1788564457413,\"E\":1788564457413,\"st\":1}}"}
{"receive_ns":1788564457451259000,"stream":"btcusdt@bookTicker","event_type":"bookTicker","event_time_ms":1788564457413,"raw_json":"{\"stream\":\"btcusdt@bookTicker\",\"data\":{\"e\":\"bookTicker\",\"u\":11478296648789,\"s\":\"BTCUSDT\",\"ps\":\"BTCUSDT\",\"b\":\"79716.80\",\"B\":\"2.656\",\"a\":\"79716.90\",\"A\":\"14.873\",\"T\":1788564457413,\"E\":1788564457413,\"st\":1}}"}
{"receive_ns":1788564457463177000,"stream":"btcusdt@bookTicker","event_type":"bookTicker","event_time_ms":1788564457414,"raw_json":"{\"stream\":\"btcusdt@bookTicker\",\"data\":{\"e\":\"bookTicker\",\"u\":11478296648888,\"s\":\"BTCUSDT\",\"ps\":\"BTCUSDT\",\"b\":\"79716.80\",\"B\":\"2.656\",\"a\":\"79716.90\",\"A\":\"14.871\",\"T\":1788564457413,\"E\":1788564457414,\"st\":1}}"}
{"receive_ns":1788564457463382000,"stream":"btcusdt@bookTicker","event_type":"bookTicker","event_time_ms":1788564457414,"raw_json":"{\"stream\":\"btcusdt@bookTicker\",\"data\":{\"e\":\"bookTicker\",\"u\":11478296648894,\"s\":\"BTCUSDT\",\"ps\":\"BTCUSDT\",\"b\":\"79716.80\",\"B\":\"2.656\",\"a\":\"79716.90\",\"A\":\"14.852\",\"T\":1788564457414,\"E\":1788564457414,\"st\":1}}"}
{"receive_ns":1788564457469473000,"stream":"btcusdt@bookTicker","event_type":"bookTicker","event_time_ms":1788564457420,"raw_json":"{\"stream\":\"btcusdt@bookTicker\",\"data\":{\"e\":\"bookTicker\",\"u\":11478296649355,\"s\":\"BTCUSDT\",\"ps\":\"BTCUSDT\",\"b\":\"79716.80\",\"B\":\"2.656\",\"a\":\"79716.90\",\"A\":\"14.871\",\"T\":1788564457420,\"E\":1788564457420,\"st\":1}}"}
{"receive_ns":1788564457469687000,"stream":"btcusdt@bookTicker","event_type":"bookTicker","event_time_ms":1788564457421,"raw_json":"{\"stream\":\"btcusdt@bookTicker\",\"data\":{\"e\":\"bookTicker\",\"u\":11478296649392,\"s\":\"BTCUSDT\",\"ps\":\"BTCUSDT\",\"b\":\"79716.80\",\"B\":\"2.656\",\"a\":\"79716.90\",\"A\":\"14.852\",\"T\":1788564457421,\"E\":1788564457421,\"st\":1}}"}
{"receive_ns":1788564457481383000,"stream":"btcusdt@bookTicker","event_type":"bookTicker","event_time_ms":1788564457440,"raw_json":"{\"stream\":\"btcusdt@bookTicker\",\"data\":{\"e\":\"bookTicker\",\"u\":11478296650367,\"s\":\"BTCUSDT\",\"ps\":\"BTCUSDT\",\"b\":\"79716.80\",\"B\":\"2.656\",\"a\":\"79716.90\",\"A\":\"14.871\",\"T\":1788564457440,\"E\":1788564457440,\"st\":1}}"}
{"receive_ns":1788564457481625000,"stream":"btcusdt@bookTicker","event_type":"bookTicker","event_time_ms":1788564457441,"raw_json":"{\"stream\":\"btcusdt@bookTicker\",\"data\":{\"e\":\"bookTicker\",\"u\":11478296650418,\"s\":\"BTCUSDT\",\"ps\":\"BTCUSDT\",\"b\":\"79716.80\",\"B\":\"2.656\",\"a\":\"79716.90\",\"A\":\"14.852\",\"T\":1788564457440,\"E\":1788564457441,\"st\":1}}"}
{"receive_ns":1788564457482101000,"stream":"btcusdt@depth@100ms","event_type":"depthUpdate","event_time_ms":1788564457455,"raw_json":"{\"stream\":\"btcusdt@depth@100ms\",\"data\":{\"e\":\"depthUpdate\",\"E\":1788564457455,\"T\":1788564457454,\"s\":\"BTCUSDT\",\"ps\":\"BTCUSDT\",\"U\":11478296645091,\"u\":11478296651153,\"pu\":11478296644925,\"b\":[[\"29416.80\",\"1.638\"],[\"29516.80\",\"0.462\"],[\"71745.10\",\"0.002\"],[\"75141.90\",\"0.003\"],[\"76528.10\",\"0.000\"],[\"78122.50\",\"0.164\"],[\"78919.60\",\"5.397\"],[\"78923.70\",\"0.792\"],[\"79320.20\",\"0.140\"],[\"79501.60\",\"1.059\"],[\"79529.50\",\"1.679\"],[\"79531.50\",\"0.256\"],[\"79620.10\",\"1.508\"],[\"79632.40\",\"0.010\"],[\"79636.00\",\"0.690\"],[\"79644.80\",\"0.000\"],[\"79662.50\",\"0.024\"],[\"79668.20\",\"0.000\"],[\"79671.30\",\"1.272\"],[\"79674.00\",\"2.459\"],[\"79697.60\",\"0.139\"],[\"79699.20\",\"0.316\"],[\"79699.30\",\"0.069\"],[\"79700.10\",\"0.006\"],[\"79700.80\",\"0.015\"],[\"79701.00\",\"0.020\"],[\"79702.70\",\"0.077\"],[\"79703.70\",\"0.005\"],[\"79705.40\",\"2.386\"],[\"79705.50\",\"0.024\"],[\"79708.30\",\"0.002\"],[\"79708.90\",\"1.540\"],[\"79709.20\",\"0.252\"],[\"79710.00\",\"0.015\"],[\"79710.40\",\"0.057\"],[\"79714.30\",\"0.504\"],[\"79715.00\",\"0.002\"],[\"79716.80\",\"2.656\"]],\"a\":[[\"79716.90\",\"14.852\"],[\"79718.70\",\"1.395\"],[\"79719.60\",\"0.000\"],[\"79724.80\",\"0.049\"],[\"79725.10\",\"0.705\"],[\"79742.70\",\"0.001\"],[\"79746.90\",\"0.024\"],[\"79792.60\",\"0.701\"],[\"80087.60\",\"1.147\"],[\"80514.10\",\"2.809\"]],\"st\":1}}"}
{"receive_ns":1788564457482358000,"stream":"btcusdt@bookTicker","event_type":"bookTicker","event_time_ms":1788564457460,"raw_json":"{\"stream\":\"btcusdt@bookTicker\",\"data\":{\"e\":\"bookTicker\",\"u\":11478296651441,\"s\":\"BTCUSDT\",\"ps\":\"BTCUSDT\",\"b\":\"79716.80\",\"B\":\"2.656\",\"a\":\"79716.90\",\"A\":\"14.871\",\"T\":1788564457459,\"E\":1788564457460,\"st\":1}}"}
{"receive_ns":1788564457482556000,"stream":"btcusdt@bookTicker","event_type":"bookTicker","event_time_ms":1788564457460,"raw_json":"{\"stream\":\"btcusdt@bookTicker\",\"data\":{\"e\":\"bookTicker\",\"u\":11478296651505,\"s\":\"BTCUSDT\",\"ps\":\"BTCUSDT\",\"b\":\"79716.80\",\"B\":\"2.656\",\"a\":\"79716.90\",\"A\":\"14.852\",\"T\":1788564457460,\"E\":1788564457460,\"st\":1}}"}
{"receive_ns":1788564457489051000,"stream":"btcusdt@bookTicker","event_type":"bookTicker","event_time_ms":1788564457503,"raw_json":"{\"stream\":\"btcusdt@bookTicker\",\"data\":{\"e\":\"bookTicker\",\"u\":11478296654813,\"s\":\"BTCUSDT\",\"ps\":\"BTCUSDT\",\"b\":\"79716.80\",\"B\":\"2.656\",\"a\":\"79716.90\",\"A\":\"14.873\",\"T\":1788564457503,\"E\":1788564457503,\"st\":1}}"}
{"receive_ns":1788564457500437000,"stream":"btcusdt@bookTicker","event_type":"bookTicker","event_time_ms":1788564457513,"raw_json":"{\"stream\":\"btcusdt@bookTicker\",\"data\":{\"e\":\"bookTicker\",\"u\":11478296655654,\"s\":\"BTCUSDT\",\"ps\":\"BTCUSDT\",\"b\":\"79716.80\",\"B\":\"2.656\",\"a\":\"79716.90\",\"A\":\"14.875\",\"T\":1788564457513,\"E\":1788564457513,\"st\":1}}"}
{"receive_ns":1788564457542172000,"stream":"btcusdt@depth@100ms","event_type":"depthUpdate","event_time_ms":1788564457557,"raw_json":"{\"stream\":\"btcusdt@depth@100ms\",\"data\":{\"e\":\"depthUpdate\",\"E\":1788564457557,\"T\":1788564457555,\"s\":\"BTCUSDT\",\"ps\":\"BTCUSDT\",\"U\":11478296651228,\"u\":11478296658020,\"pu\":11478296651153,\"b\":[[\"1000.00\",\"24.754\"],[\"29316.80\",\"0.021\"],[\"29416.80\",\"1.771\"],[\"29516.80\",\"0.308\"],[\"71745.10\",\"0.002\"],[\"76528.10\",\"0.002\"],[\"78142.10\",\"0.001\"],[\"78919.60\",\"5.399\"],[\"79477.90\",\"0.827\"],[\"79497.60\",\"0.733\"],[\"79500.80\",\"1.003\"],[\"79501.60\",\"0.828\"],[\"79529.50\",\"1.679\"],[\"79673.90\",\"0.003\"],[\"79689.30\",\"0.198\"],[\"79690.40\",\"0.017\"],[\"79705.30\",\"0.344\"],[\"79710.40\",\"0.031\"],[\"79710.50\",\"0.000\"],[\"79711.30\",\"0.000\"],[\"79712.40\",\"0.076\"],[\"79713.60\",\"0.104\"],[\"79713.80\",\"0.029\"],[\"79714.00\",\"0.027\"],[\"79714.50\",\"0.027\"]],\"a\":[[\"79716.90\",\"14.875\"],[\"79746.90\",\"0.004\"],[\"79749.10\",\"0.020\"],[\"79792.60\",\"0.701\"],[\"79886.30\",\"0.090\"],[\"80078.80\",\"0.764\"],[\"80087.60\",\"1.147\"],[\"80514.10\",\"2.809\"]],\"st\":1}}"}
{"receive_ns":1788564457555083000,"stream":"btcusdt@bookTicker","event_type":"bookTicker","event_time_ms":1788564457569,"raw_json":"{\"stream\":\"btcusdt@bookTicker\",\"data\":{\"e\":\"bookTicker\",\"u\":11478296658795,\"s\":\"BTCUSDT\",\"ps\":\"BTCUSDT\",\"b\":\"79716.80\",\"B\":\"2.643\",\"a\":\"79716.90\",\"A\":\"14.875\",\"T\":1788564457569,\"E\":1788564457569,\"st\":1}}"}
{"receive_ns":1788564457555314000,"stream":"btcusdt@trade","event_type":"trade","event_time_ms":1788564457569,"raw_json":"{\"stream\":\"btcusdt@trade\",\"data\":{\"e\":\"trade\",\"E\":1788564457569,\"T\":1788564457569,\"s\":\"BTCUSDT\",\"t\":8054096481,\"p\":\"79716.80\",\"q\":\"0.013\",\"X\":\"MARKET\",\"m\":true,\"st\":1}}"}
{"receive_ns":1788564457560687000,"stream":"btcusdt@bookTicker","event_type":"bookTicker","event_time_ms":1788564457570,"raw_json":"{\"stream\":\"btcusdt@bookTicker\",\"data\":{\"e\":\"bookTicker\",\"u\":11478296658875,\"s\":\"BTCUSDT\",\"ps\":\"BTCUSDT\",\"b\":\"79716.80\",\"B\":\"2.643\",\"a\":\"79716.90\",\"A\":\"14.894\",\"T\":1788564457570,\"E\":1788564457570,\"st\":1}}"}
{"receive_ns":1788564457560959000,"stream":"btcusdt@bookTicker","event_type":"bookTicker","event_time_ms":1788564457570,"raw_json":"{\"stream\":\"btcusdt@bookTicker\",\"data\":{\"e\":\"bookTicker\",\"u\":11478296658966,\"s\":\"BTCUSDT\",\"ps\":\"BTCUSDT\",\"b\":\"79716.80\",\"B\":\"2.643\",\"a\":\"79716.90\",\"A\":\"14.896\",\"T\":1788564457570,\"E\":1788564457570,\"st\":1}}"}
{"receive_ns":1788564457561182000,"stream":"btcusdt@bookTicker","event_type":"bookTicker","event_time_ms":1788564457571,"raw_json":"{\"stream\":\"btcusdt@bookTicker\",\"data\":{\"e\":\"bookTicker\",\"u\":11478296659059,\"s\":\"BTCUSDT\",\"ps\":\"BTCUSDT\",\"b\":\"79716.80\",\"B\":\"2.643\",\"a\":\"79716.90\",\"A\":\"14.877\",\"T\":1788564457571,\"E\":1788564457571,\"st\":1}}"}
{"receive_ns":1788564457561351000,"stream":"btcusdt@bookTicker","event_type":"bookTicker","event_time_ms":1788564457571,"raw_json":"{\"stream\":\"btcusdt@bookTicker\",\"data\":{\"e\":\"bookTicker\",\"u\":11478296659099,\"s\":\"BTCUSDT\",\"ps\":\"BTCUSDT\",\"b\":\"79716.80\",\"B\":\"2.643\",\"a\":\"79716.90\",\"A\":\"14.875\",\"T\":1788564457571,\"E\":1788564457571,\"st\":1}}"}
{"receive_ns":1788564457595002000,"stream":"btcusdt@bookTicker","event_type":"bookTicker","event_time_ms":1788564457620,"raw_json":"{\"stream\":\"btcusdt@bookTicker\",\"data\":{\"e\":\"bookTicker\",\"u\":11478296661538,\"s\":\"BTCUSDT\",\"ps\":\"BTCUSDT\",\"b\":\"79716.80\",\"B\":\"2.643\",\"a\":\"79716.90\",\"A\":\"14.894\",\"T\":1788564457620,\"E\":1788564457620,\"st\":1}}"}
{"receive_ns":1788564457600827000,"stream":"btcusdt@bookTicker","event_type":"bookTicker","event_time_ms":1788564457621,"raw_json":"{\"stream\":\"btcusdt@bookTicker\",\"data\":{\"e\":\"bookTicker\",\"u\":11478296661611,\"s\":\"BTCUSDT\",\"ps\":\"BTCUSDT\",\"b\":\"79716.80\",\"B\":\"2.643\",\"a\":\"79716.90\",\"A\":\"14.875\",\"T\":1788564457621,\"E\":1788564457621,\"st\":1}}"}
{"receive_ns":1788564457635403000,"stream":"btcusdt@depth@100ms","event_type":"depthUpdate","event_time_ms":1788564457659,"raw_json":"{\"stream\":\"btcusdt@depth@100ms\",\"data\":{\"e\":\"depthUpdate\",\"E\":1788564457659,\"T\":1788564457657,\"s\":\"BTCUSDT\",\"ps\":\"BTCUSDT\",\"U\":11478296658103,\"u\":11478296663309,\"pu\":11478296658020,\"b\":[[\"1000.00\",\"24.754\"],[\"29316.80\",\"0.084\"],[\"29416.80\",\"1.827\"],[\"29516.80\",\"0.189\"],[\"63773.00\",\"0.000\"],[\"71745.10\",\"0.002\"],[\"76528.10\",\"0.000\"],[\"78542.10\",\"0.057\"],[\"78690.20\",\"1.263\"],[\"78919.60\",\"5.397\"],[\"79318.20\",\"3.284\"],[\"79320.20\",\"0.000\"],[\"79366.00\",\"0.012\"],[\"79501.60\",\"0.828\"],[\"79529.50\",\"1.679\"],[\"79593.50\",\"0.078\"],[\"79593.60\",\"0.003\"],[\"79602.00\",\"0.040\"],[\"79621.10\",\"0.038\"],[\"79645.00\",\"0.004\"],[\"79689.40\",\"0.454\"],[\"79690.10\",\"0.469\"],[\"79697.60\",\"0.107\"],[\"79708.60\",\"0.003\"],[\"79708.90\",\"1.538\"],[\"79709.80\",\"0.175\"],[\"79710.90\",\"0.029\"],[\"79711.00\",\"0.026\"],[\"79711.10\",\"0.051\"],[\"79711.20\",\"0.030\"],[\"79711.30\",\"0.026\"],[\"79711.40\",\"0.026\"],[\"79712.10\",\"0.002\"],[\"79712.30\",\"0.002\"],[\"79712.40\",\"0.000\"],[\"79712.50\",\"0.000\"],[\"79712.60\",\"0.001\"],[\"79712.80\",\"0.000\"],[\"79712.90\",\"0.000\"],[\"79713.10\",\"0.002\"],[\"79713.50\",\"0.002\"],[\"79713.60\",\"0.002\"],[\"79713.80\",\"0.003\"],[\"79714.00\",\"0.001\"],[\"79714.50\",\"0.001\"],[\"79716.80\",\"2.643\"]],\"a\":[[\"79716.90\",\"14.875\"],[\"79719.70\",\"0.251\"],[\"79720.00\",\"0.024\"],[\"79756.80\",\"0.730\"],[\"79792.60\",\"0.451\"],[\"80087.60\",\"1.147\"],[\"80115.50\",\"3.242\"],[\"80514.10\",\"2.809\"],[\"80597.90\",\"1.239\"]],\"st\":1}}"}
{"receive_ns":1788564457737186000,"stream":"btcusdt@depth@100ms","event_type":"depthUpdate","event_time_ms":1788564457761,"raw_json":"{\"stream\":\"btcusdt@depth@100ms\",\"data\":{\"e\":\"depthUpdate\",\"E\":1788564457761,\"T\":1788564457759,\"s\":\"BTCUSDT\",\"ps\":\"BTCUSDT\",\"U\":11478296663411,\"u\":11478296671086,\"pu\":11478296663309,\"b\":[[\"29316.80\",\"0.140\"],[\"29416.80\",\"1.890\"],[\"29516.80\",\"0.070\"],[\"63773.00\",\"0.000\"],[\"71745.10\",\"0.002\"],[\"76528.10\",\"0.002\"],[\"78919.60\",\"5.397\"],[\"79318.20\",\"3.285\"],[\"79320.20\",\"0.140\"],[\"79497.60\",\"0.502\"],[\"79500.80\",\"0.000\"],[\"79529.50\",\"0.501\"],[\"79531.50\",\"0.256\"],[\"79699.30\",\"0.003\"],[\"79699.50\",\"0.286\"],[\"79700.00\",\"0.600\"],[\"79700.50\",\"0.070\"],[\"79700.80\",\"0.081\"],[\"79702.60\",\"0.348\"],[\"79703.40\",\"0.290\"],[\"79703.70\",\"0.004\"],[\"79709.20\",\"0.001\"],[\"79711.00\",\"0.000\"],[\"79711.10\",\"0.025\"],[\"79711.20\",\"0.004\"],[\"79711.30\",\"0.000\"],[\"79711.40\",\"0.000\"],[\"79711.60\",\"0.000\"],[\"79711.70\",\"0.000\"],[\"79715.90\",\"0.317\"]],\"a\":[[\"79717.90\",\"0.006\"],[\"79722.10\",\"0.008\"],[\"79792.60\",\"0.451\"],[\"79886.30\",\"0.000\"],[\"80078.80\",\"0.002\"],[\"80087.60\",\"0.579\"],[\"80334.00\",\"0.002\"],[\"80514.10\",\"2.809\"],[\"80682.40\",\"0.000\"],[\"81220.50\",\"0.554\"],[\"82741.30\",\"0.000\"],[\"87688.60\",\"0.000\"]],\"st\":1}}"}
{"receive_ns":1788564457840686000,"stream":"btcusdt@depth@100ms","event_type":"depthUpdate","event_time_ms":1788564457863,"raw_json":"{\"stream\":\"btcusdt@depth@100ms\",\"data\":{\"e\":\"depthUpdate\",\"E\":1788564457863,\"T\":1788564457862,\"s\":\"BTCUSDT\",\"ps\":\"BTCUSDT\",\"U\":11478296671327,\"u\":11478296678249,\"pu\":11478296671086,\"b\":[[\"1000.00\",\"24.754\"],[\"29316.80\",\"0.252\"],[\"29416.80\",\"1.848\"],[\"29516.80\",\"0.000\"],[\"63773.00\",\"0.000\"],[\"71745.10\",\"0.002\"],[\"78448.30\",\"0.002\"],[\"78919.60\",\"5.397\"],[\"79058.70\",\"0.252\"],[\"79497.60\",\"0.733\"],[\"79500.80\",\"1.003\"],[\"79501.60\",\"0.628\"],[\"79529.50\",\"1.679\"],[\"79702.60\",\"0.347\"],[\"79703.50\",\"0.003\"],[\"79709.40\",\"0.198\"],[\"79709.50\",\"0.027\"],[\"79709.60\",\"0.028\"],[\"79709.80\",\"0.201\"],[\"79709.90\",\"0.130\"],[\"79710.00\",\"0.041\"],[\"79710.10\",\"0.026\"],[\"79710.20\",\"0.027\"],[\"79710.90\",\"0.003\"]],\"a\":[[\"79792.60\",\"0.592\"],[\"80078.80\",\"0.764\"],[\"80087.60\",\"1.147\"],[\"80493.40\",\"4.032\"],[\"80514.10\",\"2.809\"]],\"st\":1}}"}
{"receive_ns":1788564457933407000,"stream":"btcusdt@bookTicker","event_type":"bookTicker","event_time_ms":1788564457945,"raw_json":"{\"stream\":\"btcusdt@bookTicker\",\"data\":{\"e\":\"bookTicker\",\"u\":11478296682382,\"s\":\"BTCUSDT\",\"ps\":\"BTCUSDT\",\"b\":\"79716.80\",\"B\":\"2.643\",\"a\":\"79716.90\",\"A\":\"14.894\",\"T\":1788564457945,\"E\":1788564457945,\"st\":1}}"}
{"receive_ns":1788564457939996000,"stream":"btcusdt@bookTicker","event_type":"bookTicker","event_time_ms":1788564457946,"raw_json":"{\"stream\":\"btcusdt@bookTicker\",\"data\":{\"e\":\"bookTicker\",\"u\":11478296682422,\"s\":\"BTCUSDT\",\"ps\":\"BTCUSDT\",\"b\":\"79716.80\",\"B\":\"2.643\",\"a\":\"79716.90\",\"A\":\"14.875\",\"T\":1788564457946,\"E\":1788564457946,\"st\":1}}"}
{"receive_ns":1788564457945760000,"stream":"btcusdt@depth@100ms","event_type":"depthUpdate","event_time_ms":1788564457965,"raw_json":"{\"stream\":\"btcusdt@depth@100ms\",\"data\":{\"e\":\"depthUpdate\",\"E\":1788564457965,\"T\":1788564457961,\"s\":\"BTCUSDT\",\"ps\":\"BTCUSDT\",\"U\":11478296678360,\"u\":11478296683237,\"pu\":11478296678249,\"b\":[[\"1000.00\",\"24.754\"],[\"29316.80\",\"0.427\"],[\"29416.80\",\"1.673\"],[\"71745.10\",\"0.002\"],[\"75026.90\",\"0.002\"],[\"75731.00\",\"0.069\"],[\"75731.10\",\"0.008\"],[\"76528.10\",\"0.000\"],[\"78122.50\",\"0.167\"],[\"78653.30\",\"5.414\"],[\"78760.20\",\"22.061\"],[\"78919.60\",\"5.397\"],[\"79079.10\",\"5.177\"],[\"79318.20\",\"3.285\"],[\"79320.20\",\"0.140\"],[\"79531.50\",\"0.456\"],[\"79594.40\",\"0.695\"],[\"79674.00\",\"0.459\"]],\"a\":[[\"79716.90\",\"14.875\"],[\"79792.60\",\"0.791\"],[\"79840.20\",\"0.351\"],[\"80087.60\",\"1.147\"],[\"80232.90\",\"0.000\"],[\"80514.10\",\"2.809\"]],\"st\":1}}"}
{"receive_ns":1788564457967715000,"stream":"btcusdt@bookTicker","event_type":"bookTicker","event_time_ms":1788564457991,"raw_json":"{\"stream\":\"btcusdt@bookTicker\",\"data\":{\"e\":\"bookTicker\",\"u\":11478296685024,\"s\":\"BTCUSDT\",\"ps\":\"BTCUSDT\",\"b\":\"79716.80\",\"B\":\"2.643\",\"a\":\"79716.90\",\"A\":\"14.894\",\"T\":1788564457991,\"E\":1788564457991,\"st\":1}}"}
{"receive_ns":1788564457974303000,"stream":"btcusdt@bookTicker","event_type":"bookTicker","event_time_ms":1788564457992,"raw_json":"{\"stream\":\"btcusdt@bookTicker\",\"data\":{\"e\":\"bookTicker\",\"u\":11478296685190,\"s\":\"BTCUSDT\",\"ps\":\"BTCUSDT\",\"b\":\"79716.80\",\"B\":\"2.643\",\"a\":\"79716.90\",\"A\":\"14.875\",\"T\":1788564457992,\"E\":1788564457992,\"st\":1}}"}
{"receive_ns":1788564458048143000,"stream":"btcusdt@depth@100ms","event_type":"depthUpdate","event_time_ms":1788564458067,"raw_json":"{\"stream\":\"btcusdt@depth@100ms\",\"data\":{\"e\":\"depthUpdate\",\"E\":1788564458067,\"T\":1788564458066,\"s\":\"BTCUSDT\",\"ps\":\"BTCUSDT\",\"U\":11478296683425,\"u\":11478296690019,\"pu\":11478296683237,\"b\":[[\"29316.80\",\"0.609\"],[\"29416.80\",\"1.491\"],[\"63773.00\",\"0.000\"],[\"71745.10\",\"0.002\"],[\"76528.10\",\"0.002\"],[\"78760.20\",\"23.329\"],[\"78919.60\",\"5.397\"],[\"79079.10\",\"5.177\"],[\"79497.60\",\"0.733\"],[\"79500.80\",\"1.003\"],[\"79501.60\",\"1.731\"],[\"79522.20\",\"0.004\"],[\"79525.40\",\"0.022\"],[\"79529.50\",\"0.075\"],[\"79669.30\",\"11.299\"],[\"79671.30\",\"2.626\"],[\"79673.90\",\"0.002\"],[\"79702.50\",\"0.000\"]],\"a\":[[\"79716.90\",\"14.875\"],[\"79717.40\",\"0.872\"],[\"79792.60\",\"0.701\"],[\"79886.30\",\"0.090\"],[\"80078.80\",\"0.764\"],[\"80087.60\",\"0.729\"],[\"80115.50\",\"3.241\"],[\"80514.10\",\"2.809\"]],\"st\":1}}"}
{"receive_ns":1788564458083990000,"stream":"btcusdt@bookTicker","event_type":"bookTicker","event_time_ms":1788564458101,"raw_json":"{\"stream\":\"btcusdt@bookTicker\",\"data\":{\"e\":\"bookTicker\",\"u\":11478296691791,\"s\":\"BTCUSDT\",\"ps\":\"BTCUSDT\",\"b\":\"79716.80\",\"B\":\"2.641\",\"a\":\"79716.90\",\"A\":\"14.875\",\"T\":1788564458101,\"E\":1788564458101,\"st\":1}}"}
{"receive_ns":1788564458084258000,"stream":"btcusdt@trade","event_type":"trade","event_time_ms":1788564458101,"raw_json":"{\"stream\":\"btcusdt@trade\",\"data\":{\"e\":\"trade\",\"E\":1788564458101,\"T\":1788564458101,\"s\":\"BTCUSDT\",\"t\":8054096482,\"p\":\"79716.80\",\"q\":\"0.002\",\"X\":\"MARKET\",\"m\":true,\"st\":1}}"}
{"receive_ns":1788564458084477000,"stream":"btcusdt@bookTicker","event_type":"bookTicker","event_time_ms":1788564458102,"raw_json":"{\"stream\":\"btcusdt@bookTicker\",\"data\":{\"e\":\"bookTicker\",\"u\":11478296691891,\"s\":\"BTCUSDT\",\"ps\":\"BTCUSDT\",\"b\":\"79716.80\",\"B\":\"2.641\",\"a\":\"79716.90\",\"A\":\"14.877\",\"T\":1788564458102,\"E\":1788564458102,\"st\":1}}"}
{"receive_ns":1788564458084651000,"stream":"btcusdt@bookTicker","event_type":"bookTicker","event_time_ms":1788564458102,"raw_json":"{\"stream\":\"btcusdt@bookTicker\",\"data\":{\"e\":\"bookTicker\",\"u\":11478296691901,\"s\":\"BTCUSDT\",\"ps\":\"BTCUSDT\",\"b\":\"79716.80\",\"B\":\"2.641\",\"a\":\"79716.90\",\"A\":\"14.896\",\"T\":1788564458102,\"E\":1788564458102,\"st\":1}}"}
{"receive_ns":1788564458091147000,"stream":"btcusdt@bookTicker","event_type":"bookTicker","event_time_ms":1788564458103,"raw_json":"{\"stream\":\"btcusdt@bookTicker\",\"data\":{\"e\":\"bookTicker\",\"u\":11478296692049,\"s\":\"BTCUSDT\",\"ps\":\"BTCUSDT\",\"b\":\"79716.80\",\"B\":\"2.641\",\"a\":\"79716.90\",\"A\":\"14.877\",\"T\":1788564458103,\"E\":1788564458103,\"st\":1}}"}
{"receive_ns":1788564458091372000,"stream":"btcusdt@bookTicker","event_type":"bookTicker","event_time_ms":1788564458103,"raw_json":"{\"stream\":\"btcusdt@bookTicker\",\"data\":{\"e\":\"bookTicker\",\"u\":11478296692070,\"s\":\"BTCUSDT\",\"ps\":\"BTCUSDT\",\"b\":\"79716.80\",\"B\":\"2.641\",\"a\":\"79716.90\",\"A\":\"14.875\",\"T\":1788564458103,\"E\":1788564458103,\"st\":1}}"}
{"receive_ns":1788564458147753000,"stream":"btcusdt@bookTicker","event_type":"bookTicker","event_time_ms":1788564458155,"raw_json":"{\"stream\":\"btcusdt@bookTicker\",\"data\":{\"e\":\"bookTicker\",\"u\":11478296694646,\"s\":\"BTCUSDT\",\"ps\":\"BTCUSDT\",\"b\":\"79716.80\",\"B\":\"2.641\",\"a\":\"79716.90\",\"A\":\"14.894\",\"T\":1788564458155,\"E\":1788564458155,\"st\":1}}"}
{"receive_ns":1788564458154344000,"stream":"btcusdt@bookTicker","event_type":"bookTicker","event_time_ms":1788564458155,"raw_json":"{\"stream\":\"btcusdt@bookTicker\",\"data\":{\"e\":\"bookTicker\",\"u\":11478296694698,\"s\":\"BTCUSDT\",\"ps\":\"BTCUSDT\",\"b\":\"79716.80\",\"B\":\"2.641\",\"a\":\"79716.90\",\"A\":\"14.875\",\"T\":1788564458155,\"E\":1788564458155,\"st\":1}}"}
{"receive_ns":1788564458154886000,"stream":"btcusdt@depth@100ms","event_type":"depthUpdate","event_time_ms":1788564458169,"raw_json":"{\"stream\":\"btcusdt@depth@100ms\",\"data\":{\"e\":\"depthUpdate\",\"E\":1788564458169,\"T\":1788564458165,\"s\":\"BTCUSDT\",\"ps\":\"BTCUSDT\",\"U\":11478296690043,\"u\":11478296695207,\"pu\":11478296690019,\"b\":[[\"1000.00\",\"24.754\"],[\"29316.80\",\"0.784\"],[\"29416.80\",\"1.316\"],[\"63773.00\",\"0.000\"],[\"71745.10\",\"0.002\"],[\"75731.00\",\"0.067\"],[\"75731.10\",\"0.010\"],[\"76528.10\",\"0.000\"],[\"78480.80\",\"0.037\"],[\"78481.20\",\"3.437\"],[\"78560.50\",\"0.031\"],[\"78600.80\",\"18.575\"],[\"78760.20\",\"24.597\"],[\"78919.60\",\"5.397\"],[\"79318.20\",\"3.286\"],[\"79320.20\",\"0.140\"],[\"79522.20\",\"0.004\"],[\"79529.50\",\"0.776\"],[\"79531.50\",\"0.006\"],[\"79639.40\",\"0.303\"],[\"79688.80\",\"0.457\"],[\"79689.40\",\"0.003\"],[\"79699.30\",\"0.069\"],[\"79700.00\",\"0.390\"],[\"79700.80\",\"0.015\"],[\"79703.40\",\"0.020\"],[\"79703.50\",\"0.006\"],[\"79709.40\",\"0.172\"],[\"79709.50\",\"0.001\"],[\"79710.60\",\"0.026\"],[\"79710.70\",\"0.029\"],[\"79711.50\",\"0.030\"],[\"79712.00\",\"0.042\"],[\"79716.80\",\"2.641\"]],\"a\":[[\"79716.90\",\"14.875\"],[\"79738.60\",\"0.451\"],[\"79739.60\",\"0.004\"],[\"79792.60\",\"0.701\"],[\"80087.60\",\"0.992\"],[\"80514.10\",\"2.809\"],[\"80673.50\",\"23.145\"],[\"80713.40\",\"5.888\"],[\"80873.10\",\"0.013\"],[\"80952.80\",\"0.022\"],[\"82000.00\",\"82.621\"],[\"83688.40\",\"0.004\"]],\"st\":1}}"}
{"receive_ns":1788564458247046000,"stream":"btcusdt@depth@100ms","event_type":"depthUpdate","event_time_ms":1788564458271,"raw_json":"{\"stream\":\"btcusdt@depth@100ms\",\"data\":{\"e\":\"depthUpdate\",\"E\":1788564458271,\"T\":1788564458270,\"s\":\"BTCUSDT\",\"ps\":\"BTCUSDT\",\"U\":11478296695338,\"u\":11478296700163,\"pu\":11478296695207,\"b\":[[\"1000.00\",\"24.754\"],[\"29316.80\",\"0.966\"],[\"29416.80\",\"1.134\"],[\"71745.10\",\"0.002\"],[\"78919.60\",\"5.397\"],[\"79079.10\",\"5.430\"],[\"79318.20\",\"3.286\"],[\"79497.60\",\"0.733\"],[\"79500.80\",\"0.000\"],[\"79501.60\",\"0.628\"],[\"79522.20\",\"0.036\"],[\"79529.50\",\"2.129\"],[\"79530.70\",\"1.004\"],[\"79629.80\",\"0.009\"],[\"79631.80\",\"1.215\"],[\"79658.50\",\"0.077\"],[\"79679.20\",\"0.071\"]],\"a\":[[\"79724.60\",\"0.003\"],[\"79738.60\",\"0.000\"],[\"79739.60\",\"0.455\"],[\"79751.70\",\"0.000\"],[\"79754.00\",\"0.199\"],[\"79755.40\",\"0.778\"],[\"79756.20\",\"0.129\"],[\"79763.40\",\"0.001\"],[\"79772.50\",\"1.927\"],[\"79792.60\",\"0.701\"],[\"79800.00\",\"4.325\"],[\"79801.20\",\"0.012\"],[\"79814.20\",\"0.022\"],[\"79886.30\",\"0.090\"],[\"80078.80\",\"0.764\"],[\"80087.60\",\"1.147\"],[\"80514.10\",\"2.809\"],[\"80873.10\",\"0.020\"],[\"80952.80\",\"0.029\"],[\"81138.00\",\"0.491\"]],\"st\":1}}"}
{"receive_ns":1788564458272535000,"stream":"btcusdt@bookTicker","event_type":"bookTicker","event_time_ms":1788564458295,"raw_json":"{\"stream\":\"btcusdt@bookTicker\",\"data\":{\"e\":\"bookTicker\",\"u\":11478296701117,\"s\":\"BTCUSDT\",\"ps\":\"BTCUSDT\",\"b\":\"79716.80\",\"B\":\"2.641\",\"a\":\"79716.90\",\"A\":\"14.868\",\"T\":1788564458295,\"E\":1788564458295,\"st\":1}}"}
{"receive_ns":1788564458283200000,"stream":"btcusdt@bookTicker","event_type":"bookTicker","event_time_ms":1788564458298,"raw_json":"{\"stream\":\"btcusdt@bookTicker\",\"data\":{\"e\":\"bookTicker\",\"u\":11478296701277,\"s\":\"BTCUSDT\",\"ps\":\"BTCUSDT\",\"b\":\"79716.80\",\"B\":\"2.641\",\"a\":\"79716.90\",\"A\":\"14.877\",\"T\":1788564458298,\"E\":1788564458298,\"st\":1}}"}
{"receive_ns":1788564458334503000,"stream":"btcusdt@bookTicker","event_type":"bookTicker","event_time_ms":1788564458349,"raw_json":"{\"stream\":\"btcusdt@bookTicker\",\"data\":{\"e\":\"bookTicker\",\"u\":11478296703801,\"s\":\"BTCUSDT\",\"ps\":\"BTCUSDT\",\"b\":\"79716.80\",\"B\":\"2.641\",\"a\":\"79716.90\",\"A\":\"14.872\",\"T\":1788564458349,\"E\":1788564458349,\"st\":1}}"}
{"receive_ns":1788564458341158000,"stream":"btcusdt@bookTicker","event_type":"bookTicker","event_time_ms":1788564458352,"raw_json":"{\"stream\":\"btcusdt@bookTicker\",\"data\":{\"e\":\"bookTicker\",\"u\":11478296703945,\"s\":\"BTCUSDT\",\"ps\":\"BTCUSDT\",\"b\":\"79716.80\",\"B\":\"2.641\",\"a\":\"79716.90\",\"A\":\"14.882\",\"T\":1788564458352,\"E\":1788564458352,\"st\":1}}"}
{"receive_ns":1788564458354705000,"stream":"btcusdt@depth@100ms","event_type":"depthUpdate","event_time_ms":1788564458373,"raw_json":"{\"stream\":\"btcusdt@depth@100ms\",\"data\":{\"e\":\"depthUpdate\",\"E\":1788564458373,\"T\":1788564458371,\"s\":\"BTCUSDT\",\"ps\":\"BTCUSDT\",\"U\":11478296700216,\"u\":11478296704781,\"pu\":11478296700163,\"b\":[[\"29316.80\",\"1.141\"],[\"29416.80\",\"0.959\"],[\"63773.00\",\"0.000\"],[\"63773.40\",\"0.000\"],[\"71745.10\",\"0.002\"],[\"75731.10\",\"0.008\"],[\"76528.10\",\"0.002\"],[\"78122.50\",\"0.167\"],[\"78600.80\",\"18.829\"],[\"78793.80\",\"0.000\"],[\"78899.30\",\"0.949\"],[\"78919.60\",\"5.397\"],[\"79529.50\",\"1.628\"],[\"79531.50\",\"0.507\"],[\"79588.80\",\"0.001\"],[\"79591.70\",\"2.063\"],[\"79693.10\",\"0.003\"],[\"79707.10\",\"0.076\"],[\"79709.80\",\"0.125\"],[\"79711.50\",\"0.004\"],[\"79712.00\",\"0.016\"],[\"79712.10\",\"0.002\"]],\"a\":[[\"79716.90\",\"14.882\"],[\"79733.00\",\"0.630\"],[\"79734.40\",\"0.795\"],[\"79738.70\",\"0.001\"],[\"79792.60\",\"0.502\"],[\"79840.70\",\"0.562\"],[\"79841.90\",\"0.000\"],[\"79866.40\",\"0.199\"],[\"80087.60\",\"1.147\"],[\"80294.10\",\"0.224\"],[\"80493.40\",\"2.791\"],[\"80514.10\",\"2.809\"],[\"80766.70\",\"10.452\"]],\"st\":1}}"}
{"receive_ns":1788564458360850000,"stream":"btcusdt@bookTicker","event_type":"bookTicker","event_time_ms":1788564458376,"raw_json":"{\"stream\":\"btcusdt@bookTicker\",\"data\":{\"e\":\"bookTicker\",\"u\":11478296704968,\"s\":\"BTCUSDT\",\"ps\":\"BTCUSDT\",\"b\":\"79716.80\",\"B\":\"2.621\",\"a\":\"79716.90\",\"A\":\"14.882\",\"T\":1788564458376,\"E\":1788564458376,\"st\":1}}"}
{"receive_ns":1788564458367368000,"stream":"btcusdt@bookTicker","event_type":"bookTicker","event_time_ms":1788564458379,"raw_json":"{\"stream\":\"btcusdt@bookTicker\",\"data\":{\"e\":\"bookTicker\",\"u\":11478296705135,\"s\":\"BTCUSDT\",\"ps\":\"BTCUSDT\",\"b\":\"79716.80\",\"B\":\"2.642\",\"a\":\"79716.90\",\"A\":\"14.882\",\"T\":1788564458379,\"E\":1788564458379,\"st\":1}}"}
{"receive_ns":1788564458460840000,"stream":"btcusdt@depth@100ms","event_type":"depthUpdate","event_time_ms":1788564458475,"raw_json":"{\"stream\":\"btcusdt@depth@100ms\",\"data\":{\"e\":\"depthUpdate\",\"E\":1788564458475,\"T\":1788564458473,\"s\":\"BTCUSDT\",\"ps\":\"BTCUSDT\",\"U\":11478296704874,\"u\":11478296710810,\"pu\":11478296704781,\"b\":[[\"1000.00\",\"24.754\"],[\"29316.80\",\"1.323\"],[\"29416.80\",\"0.777\"],[\"71745.10\",\"0.002\"],[\"71782.00\",\"0.000\"],[\"76528.10\",\"0.000\"],[\"78919.60\",\"5.397\"],[\"79236.90\",\"0.000\"],[\"79320.20\",\"0.140\"],[\"79529.50\",\"1.378\"],[\"79531.50\",\"0.757\"],[\"79632.10\",\"6.000\"],[\"79635.80\",\"1.686\"],[\"79659.90\",\"5.460\"],[\"79672.30\",\"0.000\"],[\"79679.90\",\"1.734\"],[\"79696.10\",\"0.001\"],[\"79716.80\",\"2.642\"]],\"a\":[[\"79750.70\",\"0.697\"],[\"79768.40\",\"1.886\"],[\"79770.70\",\"3.753\"],[\"79770.90\",\"0.596\"],[\"79772.80\",\"0.316\"],[\"79792.60\",\"0.252\"],[\"79798.00\",\"3.866\"],[\"79798.60\",\"6.076\"],[\"79866.40\",\"0.449\"],[\"80087.60\",\"1.147\"],[\"80514.10\",\"2.809\"],[\"80682.50\",\"0.699\"],[\"81051.20\",\"0.370\"],[\"81311.20\",\"0.024\"]],\"st\":1}}"}
{"receive_ns":1788564458505709000,"stream":"btcusdt@bookTicker","event_type":"bookTicker","event_time_ms":1788564458524,"raw_json":"{\"stream\":\"btcusdt@bookTicker\",\"data\":{\"e\":\"bookTicker\",\"u\":11478296714013,\"s\":\"BTCUSDT\",\"ps\":\"BTCUSDT\",\"b\":\"79716.80\",\"B\":\"2.629\",\"a\":\"79716.90\",\"A\":\"14.882\",\"T\":1788564458524,\"E\":1788564458524,\"st\":1}}"}
{"receive_ns":1788564458505955000,"stream":"btcusdt@trade","event_type":"trade","event_time_ms":1788564458524,"raw_json":"{\"stream\":\"btcusdt@trade\",\"data\":{\"e\":\"trade\",\"E\":1788564458524,\"T\":1788564458524,\"s\":\"BTCUSDT\",\"t\":8054096483,\"p\":\"79716.80\",\"q\":\"0.013\",\"X\":\"MARKET\",\"m\":true,\"st\":1}}"}
{"receive_ns":1788564458512547000,"stream":"btcusdt@bookTicker","event_type":"bookTicker","event_time_ms":1788564458526,"raw_json":"{\"stream\":\"btcusdt@bookTicker\",\"data\":{\"e\":\"bookTicker\",\"u\":11478296714119,\"s\":\"BTCUSDT\",\"ps\":\"BTCUSDT\",\"b\":\"79716.80\",\"B\":\"2.629\",\"a\":\"79716.90\",\"A\":\"14.901\",\"T\":1788564458525,\"E\":1788564458526,\"st\":1}}"}
{"receive_ns":1788564458512741000,"stream":"btcusdt@bookTicker","event_type":"bookTicker","event_time_ms":1788564458526,"raw_json":"{\"stream\":\"btcusdt@bookTicker\",\"data\":{\"e\":\"bookTicker\",\"u\":11478296714193,\"s\":\"BTCUSDT\",\"ps\":\"BTCUSDT\",\"b\":\"79716.80\",\"B\":\"2.629\",\"a\":\"79716.90\",\"A\":\"14.903\",\"T\":1788564458526,\"E\":1788564458526,\"st\":1}}"}
{"receive_ns":1788564458518557000,"stream":"btcusdt@bookTicker","event_type":"bookTicker","event_time_ms":1788564458526,"raw_json":"{\"stream\":\"btcusdt@bookTicker\",\"data\":{\"e\":\"bookTicker\",\"u\":11478296714296,\"s\":\"BTCUSDT\",\"ps\":\"BTCUSDT\",\"b\":\"79716.80\",\"B\":\"2.629\",\"a\":\"79716.90\",\"A\":\"14.884\",\"T\":1788564458526,\"E\":1788564458526,\"st\":1}}"}
{"receive_ns":1788564458523990000,"stream":"btcusdt@bookTicker","event_type":"bookTicker","event_time_ms":1788564458527,"raw_json":"{\"stream\":\"btcusdt@bookTicker\",\"data\":{\"e\":\"bookTicker\",\"u\":11478296714313,\"s\":\"BTCUSDT\",\"ps\":\"BTCUSDT\",\"b\":\"79716.80\",\"B\":\"2.629\",\"a\":\"79716.90\",\"A\":\"14.882\",\"T\":1788564458526,\"E\":1788564458527,\"st\":1}}"}
{"receive_ns":1788564458558399000,"stream":"btcusdt@depth@100ms","event_type":"depthUpdate","event_time_ms":1788564458577,"raw_json":"{\"stream\":\"btcusdt@depth@100ms\",\"data\":{\"e\":\"depthUpdate\",\"E\":1788564458577,\"T\":1788564458574,\"s\":\"BTCUSDT\",\"ps\":\"BTCUSDT\",\"U\":11478296710942,\"u\":11478296717187,\"pu\":11478296710810,\"b\":[[\"1000.00\",\"24.754\"],[\"29316.80\",\"1.498\"],[\"29416.80\",\"0.602\"],[\"63773.00\",\"0.000\"],[\"71745.10\",\"0.002\"],[\"74911.90\",\"0.002\"],[\"76528.10\",\"0.002\"],[\"78919.60\",\"5.397\"],[\"79318.20\",\"3.286\"],[\"79497.60\",\"0.733\"],[\"79529.50\",\"1.178\"],[\"79530.70\",\"0.001\"],[\"79531.50\",\"0.757\"],[\"79532.70\",\"2.292\"],[\"79592.60\",\"16.918\"],[\"79710.80\",\"0.038\"],[\"79716.80\",\"2.629\"]],\"a\":[[\"79716.90\",\"14.882\"],[\"79754.30\",\"1.343\"],[\"79792.60\",\"0.252\"],[\"79838.50\",\"10.002\"],[\"79866.40\",\"0.250\"],[\"79886.30\",\"0.090\"],[\"80078.80\",\"0.764\"],[\"80087.60\",\"1.147\"],[\"80514.10\",\"2.809\"],[\"80682.50\",\"0.489\"],[\"80825.00\",\"3.929\"],[\"83688.40\",\"0.000\"]],\"st\":1}}"}
{"receive_ns":1788564458630780000,"stream":"btcusdt@bookTicker","event_type":"bookTicker","event_time_ms":1788564458650,"raw_json":"{\"stream\":\"btcusdt@bookTicker\",\"data\":{\"e\":\"bookTicker\",\"u\":11478296721330,\"s\":\"BTCUSDT\",\"ps\":\"BTCUSDT\",\"b\":\"79716.80\",\"B\":\"2.629\",\"a\":\"79716.90\",\"A\":\"14.901\",\"T\":1788564458649,\"E\":1788564458650,\"st\":1}}"}
{"receive_ns":1788564458636183000,"stream":"btcusdt@bookTicker","event_type":"bookTicker","event_time_ms":1788564458651,"raw_json":"{\"stream\":\"btcusdt@bookTicker\",\"data\":{\"e\":\"bookTicker\",\"u\":11478296721385,\"s\":\"BTCUSDT\",\"ps\":\"BTCUSDT\",\"b\":\"79716.80\",\"B\":\"2.629\",\"a\":\"79716.90\",\"A\":\"14.882\",\"T\":1788564458650,\"E\":1788564458651,\"st\":1}}"}
{"receive_ns":1788564458661096000,"stream":"btcusdt@depth@100ms","event_type":"depthUpdate","event_time_ms":1788564458679,"raw_json":"{\"stream\":\"btcusdt@depth@100ms\",\"data\":{\"e\":\"depthUpdate\",\"E\":1788564458679,\"T\":1788564458677,\"s\":\"BTCUSDT\",\"ps\":\"BTCUSDT\",\"U\":11478296717319,\"u\":11478296722646,\"pu\":11478296717187,\"b\":[[\"29316.80\",\"1.680\"],[\"29416.80\",\"0.420\"],[\"63773.00\",\"0.000\"],[\"71745.10\",\"0.002\"],[\"76528.10\",\"0.000\"],[\"78824.00\",\"0.013\"],[\"78919.60\",\"6.663\"],[\"79320.20\",\"0.140\"],[\"79522.20\",\"0.004\"],[\"79531.50\",\"0.507\"],[\"79533.50\",\"0.451\"],[\"79593.80\",\"3.212\"]],\"a\":[[\"79716.90\",\"14.882\"],[\"79792.60\",\"0.701\"],[\"79802.00\",\"0.261\"],[\"79836.30\",\"3.712\"],[\"79866.40\",\"0.000\"],[\"80087.60\",\"1.147\"],[\"80514.10\",\"2.809\"]],\"st\":1}}"}
{"receive_ns":1788564458685096000,"stream":"btcusdt@bookTicker","event_type":"bookTicker","event_time_ms":1788564458709,"raw_json":"{\"stream\":\"btcusdt@bookTicker\",\"data\":{\"e\":\"bookTicker\",\"u\":11478296724308,\"s\":\"BTCUSDT\",\"ps\":\"BTCUSDT\",\"b\":\"79716.80\",\"B\":\"2.629\",\"a\":\"79716.90\",\"A\":\"14.901\",\"T\":1788564458709,\"E\":1788564458709,\"st\":1}}"}
{"receive_ns":1788564458691557000,"stream":"btcusdt@bookTicker","event_type":"bookTicker","event_time_ms":1788564458710,"raw_json":"{\"stream\":\"btcusdt@bookTicker\",\"data\":{\"e\":\"bookTicker\",\"u\":11478296724370,\"s\":\"BTCUSDT\",\"ps\":\"BTCUSDT\",\"b\":\"79716.80\",\"B\":\"2.629\",\"a\":\"79716.90\",\"A\":\"14.882\",\"T\":1788564458710,\"E\":1788564458710,\"st\":1}}"}
{"receive_ns":1788564458706856000,"stream":"btcusdt@bookTicker","event_type":"bookTicker","event_time_ms":1788564458724,"raw_json":"{\"stream\":\"btcusdt@bookTicker\",\"data\":{\"e\":\"bookTicker\",\"u\":11478296725123,\"s\":\"BTCUSDT\",\"ps\":\"BTCUSDT\",\"b\":\"79716.80\",\"B\":\"2.629\",\"a\":\"79716.90\",\"A\":\"14.901\",\"T\":1788564458724,\"E\":1788564458724,\"st\":1}}"}
{"receive_ns":1788564458723158000,"stream":"btcusdt@bookTicker","event_type":"bookTicker","event_time_ms":1788564458725,"raw_json":"{\"stream\":\"btcusdt@bookTicker\",\"data\":{\"e\":\"bookTicker\",\"u\":11478296725195,\"s\":\"BTCUSDT\",\"ps\":\"BTCUSDT\",\"b\":\"79716.80\",\"B\":\"2.629\",\"a\":\"79716.90\",\"A\":\"14.882\",\"T\":1788564458725,\"E\":1788564458725,\"st\":1}}"}
{"receive_ns":1788564458728640000,"stream":"btcusdt@bookTicker","event_type":"bookTicker","event_time_ms":1788564458735,"raw_json":"{\"stream\":\"btcusdt@bookTicker\",\"data\":{\"e\":\"bookTicker\",\"u\":11478296725757,\"s\":\"BTCUSDT\",\"ps\":\"BTCUSDT\",\"b\":\"79716.80\",\"B\":\"2.629\",\"a\":\"79716.90\",\"A\":\"14.901\",\"T\":1788564458735,\"E\":1788564458735,\"st\":1}}"}
{"receive_ns":1788564458741629000,"stream":"btcusdt@bookTicker","event_type":"bookTicker","event_time_ms":1788564458736,"raw_json":"{\"stream\":\"btcusdt@bookTicker\",\"data\":{\"e\":\"bookTicker\",\"u\":11478296725824,\"s\":\"BTCUSDT\",\"ps\":\"BTCUSDT\",\"b\":\"79716.80\",\"B\":\"2.629\",\"a\":\"79716.90\",\"A\":\"14.882\",\"T\":1788564458736,\"E\":1788564458736,\"st\":1}}"}
{"receive_ns":1788564458762232000,"stream":"btcusdt@depth@100ms","event_type":"depthUpdate","event_time_ms":1788564458781,"raw_json":"{\"stream\":\"btcusdt@depth@100ms\",\"data\":{\"e\":\"depthUpdate\",\"E\":1788564458781,\"T\":1788564458780,\"s\":\"BTCUSDT\",\"ps\":\"BTCUSDT\",\"U\":11478296722751,\"u\":11478296727929,\"pu\":11478296722646,\"b\":[[\"1000.00\",\"24.754\"],[\"29216.80\",\"0.035\"],[\"29316.80\",\"1.785\"],[\"29416.80\",\"0.280\"],[\"71745.10\",\"0.002\"],[\"78313.10\",\"0.000\"],[\"78427.90\",\"0.026\"],[\"78739.90\",\"11.099\"],[\"78919.60\",\"6.663\"],[\"79318.20\",\"3.285\"],[\"79497.60\",\"0.733\"],[\"79500.80\",\"1.003\"],[\"79529.50\",\"1.178\"],[\"79532.70\",\"1.289\"],[\"79661.80\",\"0.000\"]],\"a\":[[\"79716.90\",\"14.882\"],[\"79792.60\",\"0.701\"],[\"79793.50\",\"0.027\"],[\"79886.30\",\"0.090\"],[\"80078.80\",\"0.764\"],[\"80087.60\",\"1.147\"],[\"80115.50\",\"3.242\"],[\"80514.10\",\"2.809\"],[\"81029.50\",\"0.017\"],[\"81072.10\",\"4.637\"],[\"81311.20\",\"0.027\"]],\"st\":1}}"}
{"receive_ns":1788564458866858000,"stream":"btcusdt@depth@100ms","event_type":"depthUpdate","event_time_ms":1788564458883,"raw_json":"{\"stream\":\"btcusdt@depth@100ms\",\"data\":{\"e\":\"depthUpdate\",\"E\":1788564458883,\"T\":1788564458881,\"s\":\"BTCUSDT\",\"ps\":\"BTCUSDT\",\"U\":11478296727964,\"u\":11478296733121,\"pu\":11478296727929,\"b\":[[\"1000.00\",\"24.754\"],[\"29216.80\",\"0.091\"],[\"29316.80\",\"1.848\"],[\"29416.80\",\"0.161\"],[\"63773.00\",\"0.000\"],[\"71745.10\",\"0.002\"],[\"75731.00\",\"0.069\"],[\"76528.10\",\"0.002\"],[\"78919.60\",\"6.663\"],[\"79098.60\",\"0.000\"],[\"79318.20\",\"3.275\"],[\"79320.20\",\"0.000\"],[\"79501.60\",\"0.828\"],[\"79507.10\",\"6.538\"],[\"79529.50\",\"1.679\"],[\"79531.50\",\"0.006\"],[\"79533.50\",\"0.251\"]],\"a\":[[\"79792.60\",\"0.451\"],[\"79927.50\",\"7.719\"],[\"79938.80\",\"8.412\"],[\"80087.60\",\"1.147\"],[\"80514.10\",\"2.809\"],[\"80682.50\",\"0.279\"]],\"st\":1}}"}
{"receive_ns":1788564458948416000,"stream":"btcusdt@bookTicker","event_type":"bookTicker","event_time_ms":1788564458966,"raw_json":"{\"stream\":\"btcusdt@bookTicker\",\"data\":{\"e\":\"bookTicker\",\"u\":11478296737300,\"s\":\"BTCUSDT\",\"ps\":\"BTCUSDT\",\"b\":\"79716.80\",\"B\":\"2.645\",\"a\":\"79716.90\",\"A\":\"14.882\",\"T\":1788564458966,\"E\":1788564458966,\"st\":1}}"}
{"receive_ns":1788564458969605000,"stream":"btcusdt@depth@100ms","event_type":"depthUpdate","event_time_ms":1788564458985,"raw_json":"{\"stream\":\"btcusdt@depth@100ms\",\"data\":{\"e\":\"depthUpdate\",\"E\":1788564458985,\"T\":1788564458984,\"s\":\"BTCUSDT\",\"ps\":\"BTCUSDT\",\"U\":11478296733234,\"u\":11478296738366,\"pu\":11478296733121,\"b\":[[\"29216.80\",\"0.154\"],[\"29316.80\",\"1.904\"],[\"29416.80\",\"0.042\"],[\"63773.00\",\"0.000\"],[\"71745.10\",\"0.002\"],[\"76528.10\",\"0.000\"],[\"78760.20\",\"25.231\"],[\"78919.60\",\"6.663\"],[\"78932.10\",\"4.375\"],[\"78943.50\",\"1.391\"],[\"79320.20\",\"0.140\"],[\"79497.60\",\"0.502\"],[\"79500.80\",\"0.000\"],[\"79529.50\",\"0.751\"],[\"79533.50\",\"0.001\"],[\"79645.00\",\"0.004\"],[\"79690.40\",\"0.093\"],[\"79702.70\",\"0.001\"],[\"79707.10\",\"0.000\"],[\"79716.80\",\"2.645\"]],\"a\":[[\"79756.80\",\"0.730\"],[\"79772.80\",\"0.314\"],[\"79792.60\",\"0.451\"],[\"79886.30\",\"0.000\"],[\"80078.80\",\"0.002\"],[\"80087.60\",\"0.579\"],[\"80514.10\",\"2.809\"],[\"80913.10\",\"0.278\"]],\"st\":1}}"}
{"receive_ns":1788564459040376000,"stream":"btcusdt@bookTicker","event_type":"bookTicker","event_time_ms":1788564459058,"raw_json":"{\"stream\":\"btcusdt@bookTicker\",\"data\":{\"e\":\"bookTicker\",\"u\":11478296742269,\"s\":\"BTCUSDT\",\"ps\":\"BTCUSDT\",\"b\":\"79716.80\",\"B\":\"2.645\",\"a\":\"79716.90\",\"A\":\"14.883\",\"T\":1788564459058,\"E\":1788564459058,\"st\":1}}"}
{"receive_ns":1788564459067495000,"stream":"btcusdt@depth@100ms","event_type":"depthUpdate","event_time_ms":1788564459087,"raw_json":"{\"stream\":\"btcusdt@depth@100ms\",\"data\":{\"e\":\"depthUpdate\",\"E\":1788564459087,\"T\":1788564459085,\"s\":\"BTCUSDT\",\"ps\":\"BTCUSDT\",\"U\":11478296738439,\"u\":11478296743589,\"pu\":11478296738366,\"b\":[[\"1000.00\",\"24.754\"],[\"29216.80\",\"0.294\"],[\"29316.80\",\"1.806\"],[\"29416.80\",\"0.000\"],[\"63773.00\",\"0.000\"],[\"71202.30\",\"0.000\"],[\"71745.10\",\"0.002\"],[\"74796.90\",\"0.002\"],[\"75730.90\",\"0.019\"],[\"76528.10\",\"0.002\"],[\"78122.50\",\"0.164\"],[\"78454.70\",\"1.867\"],[\"78480.80\",\"0.022\"],[\"78739.90\",\"10.529\"],[\"78919.60\",\"6.663\"],[\"79500.80\",\"1.003\"],[\"79501.60\",\"0.859\"],[\"79529.50\",\"1.428\"],[\"79531.50\",\"0.507\"],[\"79628.90\",\"0.015\"],[\"79688.80\",\"0.006\"],[\"79689.90\",\"0.631\"],[\"79702.50\",\"0.000\"],[\"79711.10\",\"0.051\"]],\"a\":[[\"79716.90\",\"14.883\"],[\"79792.60\",\"0.502\"],[\"79886.30\",\"0.090\"],[\"80078.80\",\"0.764\"],[\"80087.60\",\"1.147\"],[\"80514.10\",\"2.809\"],[\"80652.80\",\"9.912\"],[\"80684.10\",\"1.912\"],[\"80952.80\",\"0.021\"],[\"80952.90\",\"0.000\"]],\"st\":1}}"}
{"receive_ns":1788564459135778000,"stream":"btcusdt@bookTicker","event_type":"bookTicker","event_time_ms":1788564459154,"raw_json":"{\"stream\":\"btcusdt@bookTicker\",\"data\":{\"e\":\"bookTicker\",\"u\":11478296746665,\"s\":\"BTCUSDT\",\"ps\":\"BTCUSDT\",\"b\":\"79716.80\",\"B\":\"2.645\",\"a\":\"79716.90\",\"A\":\"14.884\",\"T\":1788564459154,\"E\":1788564459154,\"st\":1}}"}
{"receive_ns":1788564459171930000,"stream":"btcusdt@depth@100ms","event_type":"depthUpdate","event_time_ms":1788564459189,"raw_json":"{\"stream\":\"btcusdt@depth@100ms\",\"data\":{\"e\":\"depthUpdate\",\"E\":1788564459189,\"T\":1788564459188,\"s\":\"BTCUSDT\",\"ps\":\"BTCUSDT\",\"U\":11478296743709,\"u\":11478296748755,\"pu\":11478296743589,\"b\":[[\"1000.00\",\"24.754\"],[\"29216.80\",\"0.469\"],[\"29316.80\",\"1.631\"],[\"63773.00\",\"0.000\"],[\"71745.10\",\"0.002\"],[\"76528.10\",\"0.000\"],[\"78305.10\",\"2.560\"],[\"78480.80\",\"0.037\"],[\"78919.60\",\"6.663\"],[\"78999.30\",\"0.082\"],[\"79173.50\",\"0.000\"],[\"79318.20\",\"3.284\"],[\"79320.20\",\"0.140\"],[\"79348.50\",\"1.582\"],[\"79468.20\",\"0.001\"],[\"79529.50\",\"1.628\"],[\"79594.40\",\"0.653\"],[\"79679.70\",\"0.206\"],[\"79702.50\",\"0.001\"],[\"79703.50\",\"0.005\"],[\"79709.60\",\"0.002\"],[\"79710.30\",\"0.001\"],[\"79711.30\",\"0.026\"]],\"a\":[[\"79716.90\",\"14.884\"],[\"79792.60\",\"0.701\"],[\"79840.20\",\"0.351\"],[\"79967.50\",\"0.000\"],[\"80087.60\",\"1.147\"],[\"80087.90\",\"0.011\"],[\"80514.10\",\"2.809\"]],\"st\":1}}"}
{"receive_ns":1788564459273384000,"stream":"btcusdt@depth@100ms","event_type":"depthUpdate","event_time_ms":1788564459291,"raw_json":"{\"stream\":\"btcusdt@depth@100ms\",\"data\":{\"e\":\"depthUpdate\",\"E\":1788564459291,\"T\":1788564459289,\"s\":\"BTCUSDT\",\"ps\":\"BTCUSDT\",\"U\":11478296748798,\"u\":11478296757727,\"pu\":11478296748755,\"b\":[[\"29216.80\",\"0.651\"],[\"29316.80\",\"1.449\"],[\"71745.10\",\"0.002\"],[\"78919.60\",\"6.663\"],[\"79320.20\",\"0.371\"],[\"79351.90\",\"1.561\"],[\"79471.90\",\"0.627\"],[\"79500.80\",\"1.003\"],[\"79501.60\",\"0.628\"],[\"79529.50\",\"1.628\"],[\"79531.50\",\"0.006\"],[\"79699.30\",\"0.069\"],[\"79699.50\",\"0.036\"],[\"79700.90\",\"0.467\"],[\"79701.80\",\"0.070\"],[\"79705.50\",\"0.024\"]],\"a\":[[\"79726.10\",\"0.084\"],[\"79727.00\",\"0.796\"],[\"79792.60\",\"0.701\"],[\"79886.30\",\"0.000\"],[\"79964.30\",\"1.439\"],[\"80078.80\",\"0.002\"],[\"80084.70\",\"0.528\"],[\"80087.60\",\"0.161\"],[\"80098.80\",\"0.762\"],[\"80099.50\",\"0.658\"],[\"80115.50\",\"3.243\"],[\"80264.50\",\"0.017\"],[\"80514.10\",\"2.810\"],[\"80952.80\",\"0.036\"]],\"st\":1}}"}
{"receive_ns":1788564459289422000,"stream":"btcusdt@bookTicker","event_type":"bookTicker","event_time_ms":1788564459307,"raw_json":"{\"stream\":\"btcusdt@bookTicker\",\"data\":{\"e\":\"bookTicker\",\"u\":11478296758997,\"s\":\"BTCUSDT\",\"ps\":\"BTCUSDT\",\"b\":\"79716.80\",\"B\":\"2.690\",\"a\":\"79716.90\",\"A\":\"14.884\",\"T\":1788564459307,\"E\":1788564459307,\"st\":1}}"}
{"receive_ns":1788564459296129000,"stream":"btcusdt@bookTicker","event_type":"bookTicker","event_time_ms":1788564459309,"raw_json":"{\"stream\":\"btcusdt@bookTicker\",\"data\":{\"e\":\"bookTicker\",\"u\":11478296759077,\"s\":\"BTCUSDT\",\"ps\":\"BTCUSDT\",\"b\":\"79716.80\",\"B\":\"2.688\",\"a\":\"79716.90\",\"A\":\"14.884\",\"T\":1788564459309,\"E\":1788564459309,\"st\":1}}"}
{"receive_ns":1788564459342030000,"stream":"btcusdt@bookTicker","event_type":"bookTicker","event_time_ms":1788564459360,"raw_json":"{\"stream\":\"btcusdt@bookTicker\",\"data\":{\"e\":\"bookTicker\",\"u\":11478296761969,\"s\":\"BTCUSDT\",\"ps\":\"BTCUSDT\",\"b\":\"79716.80\",\"B\":\"2.688\",\"a\":\"79716.90\",\"A\":\"14.874\",\"T\":1788564459360,\"E\":1788564459360,\"st\":1}}"}
{"receive_ns":1788564459348273000,"stream":"btcusdt@bookTicker","event_type":"bookTicker","event_time_ms":1788564459363,"raw_json":"{\"stream\":\"btcusdt@bookTicker\",\"data\":{\"e\":\"bookTicker\",\"u\":11478296762216,\"s\":\"BTCUSDT\",\"ps\":\"BTCUSDT\",\"b\":\"79716.80\",\"B\":\"2.688\",\"a\":\"79716.90\",\"A\":\"14.883\",\"T\":1788564459363,\"E\":1788564459363,\"st\":1}}"}
{"receive_ns":1788564459374900000,"stream":"btcusdt@depth@100ms","event_type":"depthUpdate","event_time_ms":1788564459393,"raw_json":"{\"stream\":\"btcusdt@depth@100ms\",\"data\":{\"e\":\"depthUpdate\",\"E\":1788564459393,\"T\":1788564459389,\"s\":\"BTCUSDT\",\"ps\":\"BTCUSDT\",\"U\":11478296757870,\"u\":11478296763438,\"pu\":11478296757727,\"b\":[[\"1000.00\",\"24.754\"],[\"29216.80\",\"0.826\"],[\"29316.80\",\"1.274\"],[\"63773.40\",\"0.000\"],[\"71745.10\",\"0.002\"],[\"76528.10\",\"0.002\"],[\"78180.30\",\"0.121\"],[\"78552.00\",\"4.217\"],[\"78653.30\",\"4.462\"],[\"78698.80\",\"0.011\"],[\"78720.30\",\"2.234\"],[\"78919.60\",\"6.663\"],[\"78959.30\",\"0.000\"],[\"78959.40\",\"3.394\"],[\"79001.10\",\"0.714\"],[\"79173.60\",\"0.000\"],[\"79318.20\",\"3.284\"],[\"79320.20\",\"0.371\"],[\"79348.60\",\"0.001\"],[\"79529.50\",\"1.679\"],[\"79531.50\",\"0.206\"],[\"79594.40\",\"0.000\"],[\"79693.10\",\"0.001\"],[\"79716.80\",\"2.688\"]],\"a\":[[\"79716.90\",\"14.883\"],[\"79733.00\",\"0.628\"],[\"79792.60\",\"0.701\"],[\"79840.20\",\"0.001\"],[\"80084.70\",\"0.000\"],[\"80087.60\",\"0.006\"],[\"80087.80\",\"0.000\"],[\"80099.50\",\"1.076\"],[\"80099.90\",\"7.850\"],[\"80481.70\",\"0.000\"],[\"80514.10\",\"2.810\"],[\"80646.20\",\"13.508\"],[\"80747.70\",\"0.495\"],[\"80800.00\",\"15.899\"],[\"82500.80\",\"0.000\"]],\"st\":1}}"}
{"receive_ns":1788564459405285000,"stream":"btcusdt@bookTicker","event_type":"bookTicker","event_time_ms":1788564459420,"raw_json":"{\"stream\":\"btcusdt@bookTicker\",\"data\":{\"e\":\"bookTicker\",\"u\":11478296765521,\"s\":\"BTCUSDT\",\"ps\":\"BTCUSDT\",\"b\":\"79716.80\",\"B\":\"2.688\",\"a\":\"79716.90\",\"A\":\"14.884\",\"T\":1788564459420,\"E\":1788564459420,\"st\":1}}"}
{"receive_ns":1788564459417377000,"stream":"btcusdt@bookTicker","event_type":"bookTicker","event_time_ms":1788564459439,"raw_json":"{\"stream\":\"btcusdt@bookTicker\",\"data\":{\"e\":\"bookTicker\",\"u\":11478296766714,\"s\":\"BTCUSDT\",\"ps\":\"BTCUSDT\",\"b\":\"79716.80\",\"B\":\"2.675\",\"a\":\"79716.90\",\"A\":\"14.884\",\"T\":1788564459439,\"E\":1788564459439,\"st\":1}}"}
{"receive_ns":1788564459423101000,"stream":"btcusdt@trade","event_type":"trade","event_time_ms":1788564459439,"raw_json":"{\"stream\":\"btcusdt@trade\",\"data\":{\"e\":\"trade\",\"E\":1788564459439,\"T\":1788564459439,\"s\":\"BTCUSDT\",\"t\":8054096484,\"p\":\"79716.80\",\"q\":\"0.013\",\"X\":\"MARKET\",\"m\":true,\"st\":1}}"}
{"receive_ns":1788564459423343000,"stream":"btcusdt@bookTicker","event_type":"bookTicker","event_time_ms":1788564459440,"raw_json":"{\"stream\":\"btcusdt@bookTicker\",\"data\":{\"e\":\"bookTicker\",\"u\":11478296766782,\"s\":\"BTCUSDT\",\"ps\":\"BTCUSDT\",\"b\":\"79716.80\",\"B\":\"2.675\",\"a\":\"79716.90\",\"A\":\"14.903\",\"T\":1788564459439,\"E\":1788564459440,\"st\":1}}"}
{"receive_ns":1788564459428992000,"stream":"btcusdt@bookTicker","event_type":"bookTicker","event_time_ms":1788564459440,"raw_json":"{\"stream\":\"btcusdt@bookTicker\",\"data\":{\"e\":\"bookTicker\",\"u\":11478296766882,\"s\":\"BTCUSDT\",\"ps\":\"BTCUSDT\",\"b\":\"79716.80\",\"B\":\"2.675\",\"a\":\"79716.90\",\"A\":\"14.905\",\"T\":1788564459440,\"E\":1788564459440,\"st\":1}}"}
{"receive_ns":1788564459429270000,"stream":"btcusdt@bookTicker","event_type":"bookTicker","event_time_ms":1788564459440,"raw_json":"{\"stream\":\"btcusdt@bookTicker\",\"data\":{\"e\":\"bookTicker\",\"u\":11478296766971,\"s\":\"BTCUSDT\",\"ps\":\"BTCUSDT\",\"b\":\"79716.80\",\"B\":\"2.675\",\"a\":\"79716.90\",\"A\":\"14.886\",\"T\":1788564459440,\"E\":1788564459440,\"st\":1}}"}
{"receive_ns":1788564459429467000,"stream":"btcusdt@bookTicker","event_type":"bookTicker","event_time_ms":1788564459440,"raw_json":"{\"stream\":\"btcusdt@bookTicker\",\"data\":{\"e\":\"bookTicker\",\"u\":11478296766976,\"s\":\"BTCUSDT\",\"ps\":\"BTCUSDT\",\"b\":\"79716.80\",\"B\":\"2.677\",\"a\":\"79716.90\",\"A\":\"14.886\",\"T\":1788564459440,\"E\":1788564459440,\"st\":1}}"}
{"receive_ns":1788564459429630000,"stream":"btcusdt@bookTicker","event_type":"bookTicker","event_time_ms":1788564459441,"raw_json":"{\"stream\":\"btcusdt@bookTicker\",\"data\":{\"e\":\"bookTicker\",\"u\":11478296766991,\"s\":\"BTCUSDT\",\"ps\":\"BTCUSDT\",\"b\":\"79716.80\",\"B\":\"2.677\",\"a\":\"79716.90\",\"A\":\"14.884\",\"T\":1788564459440,\"E\":1788564459441,\"st\":1}}"}
{"receive_ns":1788564459464672000,"stream":"btcusdt@bookTicker","event_type":"bookTicker","event_time_ms":1788564459481,"raw_json":"{\"stream\":\"btcusdt@bookTicker\",\"data\":{\"e\":\"bookTicker\",\"u\":11478296769211,\"s\":\"BTCUSDT\",\"ps\":\"BTCUSDT\",\"b\":\"79716.80\",\"B\":\"2.610\",\"a\":\"79716.90\",\"A\":\"14.884\",\"T\":1788564459481,\"E\":1788564459481,\"st\":1}}"}
{"receive_ns":1788564459478044000,"stream":"btcusdt@trade","event_type":"trade","event_time_ms":1788564459481,"raw_json":"{\"stream\":\"btcusdt@trade\",\"data\":{\"e\":\"trade\",\"E\":1788564459481,\"T\":1788564459481,\"s\":\"BTCUSDT\",\"t\":8054096485,\"p\":\"79716.80\",\"q\":\"0.067\",\"X\":\"MARKET\",\"m\":true,\"st\":1}}"}
{"receive_ns":1788564459484553000,"stream":"btcusdt@bookTicker","event_type":"bookTicker","event_time_ms":1788564459483,"raw_json":"{\"stream\":\"btcusdt@bookTicker\",\"data\":{\"e\":\"bookTicker\",\"u\":11478296769276,\"s\":\"BTCUSDT\",\"ps\":\"BTCUSDT\",\"b\":\"79716.80\",\"B\":\"2.610\",\"a\":\"79716.90\",\"A\":\"14.903\",\"T\":1788564459483,\"E\":1788564459483,\"st\":1}}"}
{"receive_ns":1788564459484750000,"stream":"btcusdt@bookTicker","event_type":"bookTicker","event_time_ms":1788564459483,"raw_json":"{\"stream\":\"btcusdt@bookTicker\",\"data\":{\"e\":\"bookTicker\",\"u\":11478296769311,\"s\":\"BTCUSDT\",\"ps\":\"BTCUSDT\",\"b\":\"79716.80\",\"B\":\"2.610\",\"a\":\"79716.90\",\"A\":\"14.905\",\"T\":1788564459483,\"E\":1788564459483,\"st\":1}}"}
{"receive_ns":1788564459484955000,"stream":"btcusdt@bookTicker","event_type":"bookTicker","event_time_ms":1788564459484,"raw_json":"{\"stream\":\"btcusdt@bookTicker\",\"data\":{\"e\":\"bookTicker\",\"u\":11478296769479,\"s\":\"BTCUSDT\",\"ps\":\"BTCUSDT\",\"b\":\"79716.80\",\"B\":\"2.610\",\"a\":\"79716.90\",\"A\":\"14.886\",\"T\":1788564459483,\"E\":1788564459484,\"st\":1}}"}
{"receive_ns":1788564459485118000,"stream":"btcusdt@bookTicker","event_type":"bookTicker","event_time_ms":1788564459484,"raw_json":"{\"stream\":\"btcusdt@bookTicker\",\"data\":{\"e\":\"bookTicker\",\"u\":11478296769484,\"s\":\"BTCUSDT\",\"ps\":\"BTCUSDT\",\"b\":\"79716.80\",\"B\":\"2.610\",\"a\":\"79716.90\",\"A\":\"14.884\",\"T\":1788564459483,\"E\":1788564459484,\"st\":1}}"}
{"receive_ns":1788564459492004000,"stream":"btcusdt@depth@100ms","event_type":"depthUpdate","event_time_ms":1788564459495,"raw_json":"{\"stream\":\"btcusdt@depth@100ms\",\"data\":{\"e\":\"depthUpdate\",\"E\":1788564459495,\"T\":1788564459494,\"s\":\"BTCUSDT\",\"ps\":\"BTCUSDT\",\"U\":11478296763601,\"u\":11478296770072,\"pu\":11478296763438,\"b\":[[\"1000.00\",\"24.754\"],[\"29216.80\",\"1.008\"],[\"29316.80\",\"1.092\"],[\"71202.30\",\"0.019\"],[\"71745.10\",\"0.002\"],[\"75731.00\",\"0.071\"],[\"76528.10\",\"0.000\"],[\"78122.50\",\"0.167\"],[\"78554.80\",\"0.002\"],[\"78919.60\",\"6.663\"],[\"79175.00\",\"59.108\"],[\"79318.20\",\"3.284\"],[\"79320.20\",\"0.140\"],[\"79349.60\",\"45.149\"],[\"79351.90\",\"7.928\"],[\"79468.80\",\"35.112\"],[\"79471.90\",\"5.834\"],[\"79500.80\",\"0.000\"],[\"79507.10\",\"0.000\"],[\"79507.80\",\"0.283\"],[\"79522.20\",\"0.036\"],[\"79529.50\",\"0.501\"],[\"79531.50\",\"0.456\"],[\"79554.90\",\"0.004\"],[\"79555.30\",\"0.423\"],[\"79565.40\",\"0.011\"],[\"79565.70\",\"1.902\"],[\"79689.30\",\"0.274\"],[\"79693.10\",\"0.003\"],[\"79698.30\",\"0.078\"],[\"79700.00\",\"0.314\"],[\"79700.80\",\"0.001\"],[\"79709.40\",\"0.174\"],[\"79709.80\",\"0.099\"],[\"79709.90\",\"0.104\"],[\"79710.40\",\"0.029\"],[\"79711.10\",\"0.025\"],[\"79711.20\",\"0.030\"],[\"79711.30\",\"0.000\"],[\"79711.40\",\"0.026\"],[\"79711.70\",\"0.026\"],[\"79711.80\",\"0.027\"],[\"79716.80\",\"2.610\"]],\"a\":[[\"79716.90\",\"14.884\"],[\"79733.00\",\"0.630\"],[\"79792.60\",\"0.451\"],[\"79839.00\",\"0.002\"],[\"79839.20\",\"1.938\"],[\"79879.70\",\"0.004\"],[\"79927.50\",\"0.000\"],[\"79964.30\",\"7.093\"],[\"79967.20\",\"36.157\"],[\"80087.10\",\"45.864\"],[\"80098.80\",\"0.000\"],[\"80099.50\",\"0.573\"],[\"80263.30\",\"56.231\"],[\"80354.60\",\"6.088\"],[\"80514.10\",\"4.053\"],[\"80713.40\",\"6.074\"],[\"80734.80\",\"1.237\"],[\"81271.40\",\"1.842\"]],\"st\":1}}"}
{"receive_ns":1788564459580424000,"stream":"btcusdt@depth@100ms","event_type":"depthUpdate","event_time_ms":1788564459597,"raw_json":"{\"stream\":\"btcusdt@depth@100ms\",\"data\":{\"e\":\"depthUpdate\",\"E\":1788564459597,\"T\":1788564459594,\"s\":\"BTCUSDT\",\"ps\":\"BTCUSDT\",\"U\":11478296770103,\"u\":11478296774972,\"pu\":11478296770072,\"b\":[[\"29216.80\",\"1.183\"],[\"29316.80\",\"0.917\"],[\"71745.10\",\"0.002\"],[\"71782.00\",\"0.003\"],[\"76528.10\",\"0.002\"],[\"78495.90\",\"0.223\"],[\"78608.70\",\"1.270\"],[\"78613.50\",\"6.417\"],[\"78919.60\",\"6.663\"],[\"78961.20\",\"67.212\"],[\"79497.60\",\"0.733\"],[\"79500.80\",\"1.003\"],[\"79501.60\",\"2.307\"],[\"79503.60\",\"0.200\"],[\"79529.50\",\"0.000\"],[\"79531.50\",\"0.256\"],[\"79674.30\",\"0.083\"],[\"79710.00\",\"0.015\"],[\"79710.10\",\"0.000\"],[\"79712.00\",\"0.016\"],[\"79712.20\",\"0.028\"]],\"a\":[[\"79792.60\",\"0.701\"],[\"79936.80\",\"0.025\"],[\"79938.10\",\"0.090\"],[\"80085.60\",\"1.002\"],[\"80086.80\",\"0.778\"],[\"80099.50\",\"0.155\"],[\"80480.00\",\"74.433\"],[\"80514.10\",\"4.051\"],[\"81037.30\",\"0.000\"],[\"82803.30\",\"0.054\"]],\"st\":1}}"}
{"receive_ns":1788564459617514000,"stream":"btcusdt@bookTicker","event_type":"bookTicker","event_time_ms":1788564459639,"raw_json":"{\"stream\":\"btcusdt@bookTicker\",\"data\":{\"e\":\"bookTicker\",\"u\":11478296777473,\"s\":\"BTCUSDT\",\"ps\":\"BTCUSDT\",\"b\":\"79716.80\",\"B\":\"2.610\",\"a\":\"79716.90\",\"A\":\"14.903\",\"T\":1788564459638,\"E\":1788564459639,\"st\":1}}"}
{"receive_ns":1788564459630063000,"stream":"btcusdt@bookTicker","event_type":"bookTicker","event_time_ms":1788564459639,"raw_json":"{\"stream\":\"btcusdt@bookTicker\",\"data\":{\"e\":\"bookTicker\",\"u\":11478296777517,\"s\":\"BTCUSDT\",\"ps\":\"BTCUSDT\",\"b\":\"79716.80\",\"B\":\"2.610\",\"a\":\"79716.90\",\"A\":\"14.884\",\"T\":1788564459639,\"E\":1788564459639,\"st\":1}}"}
{"receive_ns":1788564459681973000,"stream":"btcusdt@depth@100ms","event_type":"depthUpdate","event_time_ms":1788564459699,"raw_json":"{\"stream\":\"btcusdt@depth@100ms\",\"data\":{\"e\":\"depthUpdate\",\"E\":1788564459699,\"T\":1788564459697,\"s\":\"BTCUSDT\",\"ps\":\"BTCUSDT\",\"U\":11478296775163,\"u\":11478296780156,\"pu\":11478296774972,\"b\":[[\"1000.00\",\"24.754\"],[\"29216.80\",\"1.365\"],[\"29316.80\",\"0.735\"],[\"71745.10\",\"0.002\"],[\"71782.00\",\"0.000\"],[\"78122.50\",\"0.164\"],[\"78720.30\",\"3.185\"],[\"78919.60\",\"6.663\"],[\"78959.40\",\"0.154\"],[\"78961.00\",\"0.100\"],[\"79001.10\",\"0.066\"],[\"79175.10\",\"3.797\"],[\"79320.20\",\"0.140\"],[\"79349.70\",\"0.648\"],[\"79503.60\",\"0.450\"],[\"79531.50\",\"0.006\"],[\"79621.10\",\"0.040\"],[\"79712.50\",\"0.000\"]],\"a\":[[\"79716.90\",\"14.884\"],[\"79749.10\",\"0.000\"],[\"79754.90\",\"0.022\"],[\"79772.80\",\"0.316\"],[\"79785.50\",\"5.643\"],[\"79792.60\",\"0.701\"],[\"79798.40\",\"0.021\"],[\"80085.60\",\"1.157\"],[\"80087.00\",\"0.648\"],[\"80099.50\",\"0.000\"],[\"80099.90\",\"7.202\"],[\"80514.10\",\"4.051\"],[\"80682.50\",\"0.001\"]],\"st\":1}}"}
{"receive_ns":1788564459721499000,"stream":"btcusdt@bookTicker","event_type":"bookTicker","event_time_ms":1788564459740,"raw_json":"{\"stream\":\"btcusdt@bookTicker\",\"data\":{\"e\":\"bookTicker\",\"u\":11478296781929,\"s\":\"BTCUSDT\",\"ps\":\"BTCUSDT\",\"b\":\"79716.80\",\"B\":\"2.610\",\"a\":\"79716.90\",\"A\":\"14.903\",\"T\":1788564459740,\"E\":1788564459740,\"st\":1}}"}
{"receive_ns":1788564459740600000,"stream":"btcusdt@bookTicker","event_type":"bookTicker","event_time_ms":1788564459741,"raw_json":"{\"stream\":\"btcusdt@bookTicker\",\"data\":{\"e\":\"bookTicker\",\"u\":11478296781999,\"s\":\"BTCUSDT\",\"ps\":\"BTCUSDT\",\"b\":\"79716.80\",\"B\":\"2.610\",\"a\":\"79716.90\",\"A\":\"14.884\",\"T\":1788564459741,\"E\":1788564459741,\"st\":1}}"}
{"receive_ns":1788564459752952000,"stream":"btcusdt@bookTicker","event_type":"bookTicker","event_time_ms":1788564459745,"raw_json":"{\"stream\":\"btcusdt@bookTicker\",\"data\":{\"e\":\"bookTicker\",\"u\":11478296782227,\"s\":\"BTCUSDT\",\"ps\":\"BTCUSDT\",\"b\":\"79716.80\",\"B\":\"2.610\",\"a\":\"79716.90\",\"A\":\"14.873\",\"T\":1788564459745,\"E\":1788564459745,\"st\":1}}"}
{"receive_ns":1788564459761906000,"stream":"btcusdt@bookTicker","event_type":"bookTicker","event_time_ms":1788564459747,"raw_json":"{\"stream\":\"btcusdt@bookTicker\",\"data\":{\"e\":\"bookTicker\",\"u\":11478296782443,\"s\":\"BTCUSDT\",\"ps\":\"BTCUSDT\",\"b\":\"79716.80\",\"B\":\"2.610\",\"a\":\"79716.90\",\"A\":\"14.885\",\"T\":1788564459747,\"E\":1788564459747,\"st\":1}}"}
{"receive_ns":1788564459784044000,"stream":"btcusdt@depth@100ms","event_type":"depthUpdate","event_time_ms":1788564459801,"raw_json":"{\"stream\":\"btcusdt@depth@100ms\",\"data\":{\"e\":\"depthUpdate\",\"E\":1788564459801,\"T\":1788564459799,\"s\":\"BTCUSDT\",\"ps\":\"BTCUSDT\",\"U\":11478296780269,\"u\":11478296784998,\"pu\":11478296780156,\"b\":[[\"1000.00\",\"24.754\"],[\"29216.80\",\"1.540\"],[\"29316.80\",\"0.560\"],[\"71745.10\",\"0.002\"],[\"76528.10\",\"0.000\"],[\"78488.30\",\"6.457\"],[\"78919.60\",\"6.663\"],[\"79318.20\",\"3.274\"],[\"79497.60\",\"0.733\"],[\"79500.80\",\"1.003\"],[\"79501.60\",\"2.307\"]],\"a\":[[\"79716.90\",\"14.885\"],[\"79792.60\",\"0.451\"],[\"79866.40\",\"0.250\"],[\"79938.10\",\"0.090\"],[\"80085.60\",\"1.157\"],[\"80086.80\",\"0.778\"],[\"80115.50\",\"3.242\"],[\"80514.10\",\"4.051\"],[\"80591.40\",\"1.299\"]],\"st\":1}}"}
{"receive_ns":1788564459877926000,"stream":"btcusdt@depth@100ms","event_type":"depthUpdate","event_time_ms":1788564459903,"raw_json":"{\"stream\":\"btcusdt@depth@100ms\",\"data\":{\"e\":\"depthUpdate\",\"E\":1788564459903,\"T\":1788564459902,\"s\":\"BTCUSDT\",\"ps\":\"BTCUSDT\",\"U\":11478296785133,\"u\":11478296790443,\"pu\":11478296784998,\"b\":[[\"29216.80\",\"1.722\"],[\"29316.80\",\"0.378\"],[\"71202.30\",\"0.000\"],[\"71745.10\",\"0.002\"],[\"76528.10\",\"0.002\"],[\"78268.50\",\"0.032\"],[\"78806.30\",\"0.000\"],[\"78919.60\",\"6.663\"],[\"79318.20\",\"3.275\"],[\"79320.20\",\"0.140\"],[\"79503.60\",\"0.200\"]],\"a\":[[\"79792.60\",\"0.201\"],[\"79866.40\",\"0.500\"],[\"80085.60\",\"1.002\"],[\"80514.10\",\"4.051\"],[\"81151.80\",\"0.295\"]],\"st\":1}}"}
{"receive_ns":1788564459920032000,"stream":"btcusdt@bookTicker","event_type":"bookTicker","event_time_ms":1788564459931,"raw_json":"{\"stream\":\"btcusdt@bookTicker\",\"data\":{\"e\":\"bookTicker\",\"u\":11478296791964,\"s\":\"BTCUSDT\",\"ps\":\"BTCUSDT\",\"b\":\"79716.80\",\"B\":\"2.610\",\"a\":\"79716.90\",\"A\":\"14.884\",\"T\":1788564459931,\"E\":1788564459931,\"st\":1}}"}
{"receive_ns":1788564459981276000,"stream":"btcusdt@depth@100ms","event_type":"depthUpdate","event_time_ms":1788564460005,"raw_json":"{\"stream\":\"btcusdt@depth@100ms\",\"data\":{\"e\":\"depthUpdate\",\"E\":1788564460005,\"T\":1788564460004,\"s\":\"BTCUSDT\",\"ps\":\"BTCUSDT\",\"U\":11478296790551,\"u\":11478296796675,\"pu\":11478296790443,\"b\":[[\"1000.00\",\"24.754\"],[\"29216.80\",\"1.792\"],[\"29316.80\",\"0.259\"],[\"29616.80\",\"0.049\"],[\"71745.10\",\"0.002\"],[\"76528.10\",\"0.000\"],[\"78629.20\",\"5.273\"],[\"78919.60\",\"6.663\"],[\"78959.50\",\"1.811\"],[\"79318.20\",\"3.285\"],[\"79497.60\",\"0.733\"],[\"79500.80\",\"1.003\"],[\"79501.60\",\"2.307\"],[\"79503.60\",\"0.450\"]],\"a\":[[\"79716.90\",\"14.884\"],[\"79734.40\",\"0.750\"],[\"79738.70\",\"0.046\"],[\"79866.40\",\"0.500\"],[\"79938.10\",\"0.090\"],[\"80085.60\",\"1.157\"],[\"80086.80\",\"0.778\"],[\"80514.10\",\"4.051\"],[\"80649.60\",\"0.864\"],[\"80830.40\",\"3.888\"],[\"80894.10\",\"0.000\"]],\"st\":1}}"}
{"receive_ns":1788564459981568000,"stream":"btcusdt@bookTicker","event_type":"bookTicker","event_time_ms":1788564460008,"raw_json":"{\"stream\":\"btcusdt@bookTicker\",\"data\":{\"e\":\"bookTicker\",\"u\":11478296796963,\"s\":\"BTCUSDT\",\"ps\":\"BTCUSDT\",\"b\":\"79716.80\",\"B\":\"2.610\",\"a\":\"79716.90\",\"A\":\"14.903\",\"T\":1788564460008,\"E\":1788564460008,\"st\":1}}"}
{"receive_ns":1788564459984262000,"stream":"btcusdt@bookTicker","event_type":"bookTicker","event_time_ms":1788564460009,"raw_json":"{\"stream\":\"btcusdt@bookTicker\",\"data\":{\"e\":\"bookTicker\",\"u\":11478296797007,\"s\":\"BTCUSDT\",\"ps\":\"BTCUSDT\",\"b\":\"79716.80\",\"B\":\"2.610\",\"a\":\"79716.90\",\"A\":\"14.884\",\"T\":1788564460009,\"E\":1788564460009,\"st\":1}}"}
{"receive_ns":1788564460084026000,"stream":"btcusdt@depth@100ms","event_type":"depthUpdate","event_time_ms":1788564460107,"raw_json":"{\"stream\":\"btcusdt@depth@100ms\",\"data\":{\"e\":\"depthUpdate\",\"E\":1788564460107,\"T\":1788564460106,\"s\":\"BTCUSDT\",\"ps\":\"BTCUSDT\",\"U\":11478296796797,\"u\":11478296802686,\"pu\":11478296796675,\"b\":[[\"1000.00\",\"24.754\"],[\"29216.80\",\"1.855\"],[\"29316.80\",\"0.133\"],[\"29616.80\",\"0.112\"],[\"71745.10\",\"0.002\"],[\"76528.10\",\"0.002\"],[\"78545.00\",\"4.202\"],[\"78687.70\",\"0.001\"],[\"78873.30\",\"0.965\"],[\"78919.60\",\"6.663\"],[\"79320.20\",\"0.000\"],[\"79501.60\",\"1.806\"],[\"79503.60\",\"0.250\"],[\"79507.10\",\"6.597\"],[\"79507.80\",\"1.196\"],[\"79529.50\",\"0.701\"],[\"79555.00\",\"2.591\"],[\"79555.30\",\"0.708\"],[\"79560.50\",\"0.610\"],[\"79594.40\",\"0.677\"],[\"79689.10\",\"0.001\"],[\"79689.90\",\"0.180\"],[\"79690.20\",\"0.453\"],[\"79702.50\",\"0.001\"],[\"79710.00\",\"0.015\"],[\"79710.10\",\"0.000\"],[\"79710.20\",\"0.001\"],[\"79710.40\",\"0.055\"],[\"79710.50\",\"0.026\"],[\"79711.20\",\"0.004\"],[\"79711.30\",\"0.000\"],[\"79711.40\",\"0.000\"],[\"79711.60\",\"0.026\"],[\"79711.70\",\"0.026\"],[\"79711.80\",\"0.027\"],[\"79711.90\",\"0.001\"],[\"79712.10\",\"0.028\"],[\"79712.20\",\"0.002\"],[\"79712.30\",\"0.028\"]],\"a\":[[\"79716.90\",\"14.884\"],[\"79781.00\",\"0.010\"],[\"79787.10\",\"0.019\"],[\"79792.60\",\"0.201\"],[\"79840.20\",\"0.351\"],[\"79866.40\",\"0.250\"],[\"79879.70\",\"2.457\"],[\"79927.50\",\"7.565\"],[\"80085.60\",\"1.157\"],[\"80514.10\",\"4.051\"],[\"80684.40\",\"4.086\"],[\"80713.40\",\"6.222\"],[\"81311.20\",\"0.024\"]],\"st\":1}}"}
{"receive_ns":1788564460102169000,"stream":"btcusdt@bookTicker","event_type":"bookTicker","event_time_ms":1788564460120,"raw_json":"{\"stream\":\"btcusdt@bookTicker\",\"data\":{\"e\":\"bookTicker\",\"u\":11478296803619,\"s\":\"BTCUSDT\",\"ps\":\"BTCUSDT\",\"b\":\"79716.80\",\"B\":\"2.610\",\"a\":\"79716.90\",\"A\":\"14.887\",\"T\":1788564460120,\"E\":1788564460120,\"st\":1}}"}
{"receive_ns":1788564460136623000,"stream":"btcusdt@bookTicker","event_type":"bookTicker","event_time_ms":1788564460157,"raw_json":"{\"stream\":\"btcusdt@bookTicker\",\"data\":{\"e\":\"bookTicker\",\"u\":11478296806031,\"s\":\"BTCUSDT\",\"ps\":\"BTCUSDT\",\"b\":\"79716.80\",\"B\":\"2.610\",\"a\":\"79716.90\",\"A\":\"14.878\",\"T\":1788564460157,\"E\":1788564460157,\"st\":1}}"}
{"receive_ns":1788564460147770000,"stream":"btcusdt@bookTicker","event_type":"bookTicker","event_time_ms":1788564460160,"raw_json":"{\"stream\":\"btcusdt@bookTicker\",\"data\":{\"e\":\"bookTicker\",\"u\":11478296806202,\"s\":\"BTCUSDT\",\"ps\":\"BTCUSDT\",\"b\":\"79716.80\",\"B\":\"2.610\",\"a\":\"79716.90\",\"A\":\"14.883\",\"T\":1788564460160,\"E\":1788564460160,\"st\":1}}"}
{"receive_ns":1788564460154201000,"stream":"btcusdt@bookTicker","event_type":"bookTicker","event_time_ms":1788564460177,"raw_json":"{\"stream\":\"btcusdt@bookTicker\",\"data\":{\"e\":\"bookTicker\",\"u\":11478296806918,\"s\":\"BTCUSDT\",\"ps\":\"BTCUSDT\",\"b\":\"79716.80\",\"B\":\"2.610\",\"a\":\"79716.90\",\"A\":\"14.878\",\"T\":1788564460176,\"E\":1788564460177,\"st\":1}}"}
{"receive_ns":1788564460154442000,"stream":"btcusdt@trade","event_type":"trade","event_time_ms":1788564460177,"raw_json":"{\"stream\":\"btcusdt@trade\",\"data\":{\"e\":\"trade\",\"E\":1788564460177,\"T\":1788564460176,\"s\":\"BTCUSDT\",\"t\":8054096486,\"p\":\"79716.90\",\"q\":\"0.005\",\"X\":\"MARKET\",\"m\":false,\"st\":1}}"}
{"receive_ns":1788564460161014000,"stream":"btcusdt@bookTicker","event_type":"bookTicker","event_time_ms":1788564460178,"raw_json":"{\"stream\":\"btcusdt@bookTicker\",\"data\":{\"e\":\"bookTicker\",\"u\":11478296806980,\"s\":\"BTCUSDT\",\"ps\":\"BTCUSDT\",\"b\":\"79716.80\",\"B\":\"2.610\",\"a\":\"79716.90\",\"A\":\"14.897\",\"T\":1788564460177,\"E\":1788564460178,\"st\":1}}"}
{"receive_ns":1788564460161220000,"stream":"btcusdt@bookTicker","event_type":"bookTicker","event_time_ms":1788564460178,"raw_json":"{\"stream\":\"btcusdt@bookTicker\",\"data\":{\"e\":\"bookTicker\",\"u\":11478296806999,\"s\":\"BTCUSDT\",\"ps\":\"BTCUSDT\",\"b\":\"79716.80\",\"B\":\"2.610\",\"a\":\"79716.90\",\"A\":\"14.899\",\"T\":1788564460178,\"E\":1788564460178,\"st\":1}}"}
{"receive_ns":1788564460167477000,"stream":"btcusdt@bookTicker","event_type":"bookTicker","event_time_ms":1788564460178,"raw_json":"{\"stream\":\"btcusdt@bookTicker\",\"data\":{\"e\":\"bookTicker\",\"u\":11478296807119,\"s\":\"BTCUSDT\",\"ps\":\"BTCUSDT\",\"b\":\"79716.80\",\"B\":\"2.610\",\"a\":\"79716.90\",\"A\":\"14.880\",\"T\":1788564460178,\"E\":1788564460178,\"st\":1}}"}
{"receive_ns":1788564460167693000,"stream":"btcusdt@bookTicker","event_type":"bookTicker","event_time_ms":1788564460179,"raw_json":"{\"stream\":\"btcusdt@bookTicker\",\"data\":{\"e\":\"bookTicker\",\"u\":11478296807125,\"s\":\"BTCUSDT\",\"ps\":\"BTCUSDT\",\"b\":\"79716.80\",\"B\":\"2.610\",\"a\":\"79716.90\",\"A\":\"14.878\",\"T\":1788564460178,\"E\":1788564460179,\"st\":1}}"}
{"receive_ns":1788564460173047000,"stream":"btcusdt@bookTicker","event_type":"bookTicker","event_time_ms":1788564460196,"raw_json":"{\"stream\":\"btcusdt@bookTicker\",\"data\":{\"e\":\"bookTicker\",\"u\":11478296808212,\"s\":\"BTCUSDT\",\"ps\":\"BTCUSDT\",\"b\":\"79716.80\",\"B\":\"2.610\",\"a\":\"79716.90\",\"A\":\"14.897\",\"T\":1788564460196,\"E\":1788564460196,\"st\":1}}"}
{"receive_ns":1788564460175905000,"stream":"btcusdt@bookTicker","event_type":"bookTicker","event_time_ms":1788564460197,"raw_json":"{\"stream\":\"btcusdt@bookTicker\",\"data\":{\"e\":\"bookTicker\",\"u\":11478296808239,\"s\":\"BTCUSDT\",\"ps\":\"BTCUSDT\",\"b\":\"79716.80\",\"B\":\"2.610\",\"a\":\"79716.90\",\"A\":\"14.878\",\"T\":1788564460197,\"E\":1788564460197,\"st\":1}}"}
{"receive_ns":1788564460192372000,"stream":"btcusdt@depth@100ms","event_type":"depthUpdate","event_time_ms":1788564460209,"raw_json":"{\"stream\":\"btcusdt@depth@100ms\",\"data\":{\"e\":\"depthUpdate\",\"E\":1788564460209,\"T\":1788564460207,\"s\":\"BTCUSDT\",\"ps\":\"BTCUSDT\",\"U\":11478296802835,\"u\":11478296808942,\"pu\":11478296802686,\"b\":[[\"29216.80\",\"1.904\"],[\"29316.80\",\"0.021\"],[\"29616.80\",\"0.175\"],[\"71745.10\",\"0.002\"],[\"78448.20\",\"0.002\"],[\"78733.60\",\"10.813\"],[\"78919.60\",\"7.929\"],[\"79320.20\",\"0.140\"],[\"79497.60\",\"0.502\"],[\"79500.80\",\"0.000\"],[\"79501.60\",\"0.628\"],[\"79503.60\",\"0.000\"],[\"79529.50\",\"0.951\"],[\"79594.40\",\"0.677\"],[\"79602.00\",\"0.008\"],[\"79621.10\",\"0.038\"],[\"79645.00\",\"0.002\"],[\"79656.40\",\"0.048\"],[\"79693.40\",\"0.059\"],[\"79695.10\",\"0.001\"],[\"79695.60\",\"0.373\"],[\"79697.30\",\"0.539\"],[\"79702.10\",\"0.076\"],[\"79709.40\",\"0.172\"],[\"79710.40\",\"0.029\"],[\"79710.50\",\"0.000\"],[\"79712.50\",\"0.026\"],[\"79712.90\",\"0.000\"],[\"79713.70\",\"0.000\"]],\"a\":[[\"79716.90\",\"14.878\"],[\"79724.90\",\"1.507\"],[\"79732.60\",\"0.063\"],[\"79734.30\",\"0.441\"],[\"79734.60\",\"0.002\"],[\"79735.60\",\"0.372\"],[\"79739.60\",\"0.004\"],[\"79740.50\",\"0.460\"],[\"79743.20\",\"0.007\"],[\"79760.90\",\"0.012\"],[\"79761.10\",\"0.052\"],[\"79772.80\",\"0.316\"],[\"79792.60\",\"0.451\"],[\"79840.20\",\"0.351\"],[\"79866.40\",\"0.000\"],[\"79938.10\",\"0.000\"],[\"80085.60\",\"0.589\"],[\"80086.80\",\"0.016\"],[\"80314.80\",\"3.750\"],[\"80514.10\",\"5.292\"]],\"st\":1}}"}
{"receive_ns":1788564460249536000,"stream":"btcusdt@bookTicker","event_type":"bookTicker","event_time_ms":1788564460265,"raw_json":"{\"stream\":\"btcusdt@bookTicker\",\"data\":{\"e\":\"bookTicker\",\"u\":11478296812091,\"s\":\"BTCUSDT\",\"ps\":\"BTCUSDT\",\"b\":\"79716.80\",\"B\":\"2.610\",\"a\":\"79716.90\",\"A\":\"14.933\",\"T\":1788564460265,\"E\":1788564460265,\"st\":1}}"}
{"receive_ns":1788564460292189000,"stream":"btcusdt@depth@100ms","event_type":"depthUpdate","event_time_ms":1788564460311,"raw_json":"{\"stream\":\"btcusdt@depth@100ms\",\"data\":{\"e\":\"depthUpdate\",\"E\":1788564460311,\"T\":1788564460309,\"s\":\"BTCUSDT\",\"ps\":\"BTCUSDT\",\"U\":11478296809141,\"u\":11478296814450,\"pu\":11478296808942,\"b\":[[\"1000.00\",\"24.754\"],[\"29216.80\",\"1.764\"],[\"29316.80\",\"0.000\"],[\"29616.80\",\"0.336\"],[\"71745.10\",\"0.002\"],[\"76528.10\",\"0.000\"],[\"78700.80\",\"86.810\"],[\"78749.70\",\"0.000\"],[\"78919.60\",\"7.929\"],[\"79318.20\",\"3.276\"],[\"79500.80\",\"1.003\"],[\"79501.60\",\"1.862\"],[\"79522.20\",\"0.036\"],[\"79529.50\",\"0.926\"],[\"79689.40\",\"0.454\"],[\"79690.20\",\"0.002\"],[\"79694.40\",\"0.375\"],[\"79695.60\",\"0.001\"],[\"79696.50\",\"0.800\"],[\"79697.30\",\"0.100\"],[\"79710.60\",\"0.000\"],[\"79710.70\",\"0.003\"],[\"79712.00\",\"0.042\"],[\"79713.10\",\"0.002\"],[\"79713.20\",\"0.001\"],[\"79714.10\",\"0.000\"]],\"a\":[[\"79716.90\",\"14.933\"],[\"79732.60\",\"0.501\"],[\"79734.30\",\"0.003\"],[\"79784.60\",\"2.068\"],[\"79792.60\",\"0.502\"],[\"79886.30\",\"0.090\"],[\"80085.60\",\"1.157\"],[\"80086.80\",\"0.778\"],[\"80087.00\",\"7.629\"],[\"80115.50\",\"3.241\"],[\"80124.60\",\"0.087\"],[\"80514.10\",\"5.291\"],[\"80713.40\",\"6.432\"],[\"80745.60\",\"88.076\"],[\"80888.70\",\"3.084\"]],\"st\":1}}"}
{"receive_ns":1788564460320094000,"stream":"btcusdt@bookTicker","event_type":"bookTicker","event_time_ms":1788564460332,"raw_json":"{\"stream\":\"btcusdt@bookTicker\",\"data\":{\"e\":\"bookTicker\",\"u\":11478296816055,\"s\":\"BTCUSDT\",\"ps\":\"BTCUSDT\",\"b\":\"79716.80\",\"B\":\"2.610\",\"a\":\"79716.90\",\"A\":\"14.952\",\"T\":1788564460332,\"E\":1788564460332,\"st\":1}}"}
{"receive_ns":1788564460329768000,"stream":"btcusdt@bookTicker","event_type":"bookTicker","event_time_ms":1788564460333,"raw_json":"{\"stream\":\"btcusdt@bookTicker\",\"data\":{\"e\":\"bookTicker\",\"u\":11478296816139,\"s\":\"BTCUSDT\",\"ps\":\"BTCUSDT\",\"b\":\"79716.80\",\"B\":\"2.610\",\"a\":\"79716.90\",\"A\":\"14.933\",\"T\":1788564460333,\"E\":1788564460333,\"st\":1}}"}
{"receive_ns":1788564460347516000,"stream":"btcusdt@bookTicker","event_type":"bookTicker","event_time_ms":1788564460333,"raw_json":"{\"stream\":\"btcusdt@bookTicker\",\"data\":{\"e\":\"bookTicker\",\"u\":11478296816202,\"s\":\"BTCUSDT\",\"ps\":\"BTCUSDT\",\"b\":\"79716.80\",\"B\":\"2.610\",\"a\":\"79716.90\",\"A\":\"14.932\",\"T\":1788564460333,\"E\":1788564460333,\"st\":1}}"}
{"receive_ns":1788564460357129000,"stream":"btcusdt@bookTicker","event_type":"bookTicker","event_time_ms":1788564460380,"raw_json":"{\"stream\":\"btcusdt@bookTicker\",\"data\":{\"e\":\"bookTicker\",\"u\":11478296818538,\"s\":\"BTCUSDT\",\"ps\":\"BTCUSDT\",\"b\":\"79716.80\",\"B\":\"2.610\",\"a\":\"79716.90\",\"A\":\"14.951\",\"T\":1788564460380,\"E\":1788564460380,\"st\":1}}"}
{"receive_ns":1788564460357385000,"stream":"btcusdt@bookTicker","event_type":"bookTicker","event_time_ms":1788564460381,"raw_json":"{\"stream\":\"btcusdt@bookTicker\",\"data\":{\"e\":\"bookTicker\",\"u\":11478296818575,\"s\":\"BTCUSDT\",\"ps\":\"BTCUSDT\",\"b\":\"79716.80\",\"B\":\"2.610\",\"a\":\"79716.90\",\"A\":\"14.932\",\"T\":1788564460381,\"E\":1788564460381,\"st\":1}}"}
{"receive_ns":1788564460369364000,"stream":"btcusdt@bookTicker","event_type":"bookTicker","event_time_ms":1788564460382,"raw_json":"{\"stream\":\"btcusdt@bookTicker\",\"data\":{\"e\":\"bookTicker\",\"u\":11478296818643,\"s\":\"BTCUSDT\",\"ps\":\"BTCUSDT\",\"b\":\"79716.80\",\"B\":\"2.610\",\"a\":\"79716.90\",\"A\":\"14.933\",\"T\":1788564460381,\"E\":1788564460382,\"st\":1}}"}
{"receive_ns":1788564460381504000,"stream":"btcusdt@bookTicker","event_type":"bookTicker","event_time_ms":1788564460405,"raw_json":"{\"stream\":\"btcusdt@bookTicker\",\"data\":{\"e\":\"bookTicker\",\"u\":11478296819852,\"s\":\"BTCUSDT\",\"ps\":\"BTCUSDT\",\"b\":\"79716.80\",\"B\":\"2.589\",\"a\":\"79716.90\",\"A\":\"14.933\",\"T\":1788564460405,\"E\":1788564460405,\"st\":1}}"}
{"receive_ns":1788564460394343000,"stream":"btcusdt@bookTicker","event_type":"bookTicker","event_time_ms":1788564460408,"raw_json":"{\"stream\":\"btcusdt@bookTicker\",\"data\":{\"e\":\"bookTicker\",\"u\":11478296820009,\"s\":\"BTCUSDT\",\"ps\":\"BTCUSDT\",\"b\":\"79716.80\",\"B\":\"2.611\",\"a\":\"79716.90\",\"A\":\"14.933\",\"T\":1788564460408,\"E\":1788564460408,\"st\":1}}"}
{"receive_ns":1788564460406485000,"stream":"btcusdt@depth@100ms","event_type":"depthUpdate","event_time_ms":1788564460413,"raw_json":"{\"stream\":\"btcusdt@depth@100ms\",\"data\":{\"e\":\"depthUpdate\",\"E\":1788564460413,\"T\":1788564460411,\"s\":\"BTCUSDT\",\"ps\":\"BTCUSDT\",\"U\":11478296814537,\"u\":11478296820178,\"pu\":11478296814450,\"b\":[[\"1000.00\",\"24.754\"],[\"29216.80\",\"1.589\"],[\"29616.80\",\"0.511\"],[\"63773.00\",\"0.000\"],[\"63773.40\",\"0.000\"],[\"71745.10\",\"0.002\"],[\"74681.90\",\"0.002\"],[\"76528.10\",\"0.002\"],[\"78369.60\",\"1.413\"],[\"78854.20\",\"0.568\"],[\"78919.60\",\"7.929\"],[\"79320.20\",\"0.140\"],[\"79522.20\",\"0.004\"],[\"79529.50\",\"1.126\"],[\"79660.90\",\"0.004\"],[\"79693.10\",\"0.001\"],[\"79710.80\",\"0.012\"],[\"79712.60\",\"0.027\"],[\"79712.80\",\"0.026\"],[\"79713.50\",\"0.028\"],[\"79716.80\",\"2.611\"]],\"a\":[[\"79716.90\",\"14.933\"],[\"79733.00\",\"0.628\"],[\"79746.80\",\"6.589\"],[\"79754.90\",\"0.002\"],[\"79788.70\",\"0.023\"],[\"79792.60\",\"0.451\"],[\"79866.40\",\"0.250\"],[\"80085.60\",\"1.157\"],[\"80514.10\",\"5.291\"],[\"80646.20\",\"12.280\"],[\"81088.00\",\"0.754\"]],\"st\":1}}"}
{"receive_ns":1788564460449888000,"stream":"btcusdt@bookTicker","event_type":"bookTicker","event_time_ms":1788564460469,"raw_json":"{\"stream\":\"btcusdt@bookTicker\",\"data\":{\"e\":\"bookTicker\",\"u\":11478296823371,\"s\":\"BTCUSDT\",\"ps\":\"BTCUSDT\",\"b\":\"79716.80\",\"B\":\"2.611\",\"a\":\"79716.90\",\"A\":\"14.936\",\"T\":1788564460469,\"E\":1788564460469,\"st\":1}}"}
{"receive_ns":1788564460461799000,"stream":"btcusdt@bookTicker","event_type":"bookTicker","event_time_ms":1788564460483,"raw_json":"{\"stream\":\"btcusdt@bookTicker\",\"data\":{\"e\":\"bookTicker\",\"u\":11478296824268,\"s\":\"BTCUSDT\",\"ps\":\"BTCUSDT\",\"b\":\"79716.80\",\"B\":\"2.598\",\"a\":\"79716.90\",\"A\":\"14.936\",\"T\":1788564460483,\"E\":1788564460483,\"st\":1}}"}
{"receive_ns":1788564460473532000,"stream":"btcusdt@trade","event_type":"trade","event_time_ms":1788564460483,"raw_json":"{\"stream\":\"btcusdt@trade\",\"data\":{\"e\":\"trade\",\"E\":1788564460483,\"T\":1788564460483,\"s\":\"BTCUSDT\",\"t\":8054096487,\"p\":\"79716.80\",\"q\":\"0.013\",\"X\":\"MARKET\",\"m\":true,\"st\":1}}"}
{"receive_ns":1788564460475197000,"stream":"btcusdt@bookTicker","event_type":"bookTicker","event_time_ms":1788564460485,"raw_json":"{\"stream\":\"btcusdt@bookTicker\",\"data\":{\"e\":\"bookTicker\",\"u\":11478296824431,\"s\":\"BTCUSDT\",\"ps\":\"BTCUSDT\",\"b\":\"79716.80\",\"B\":\"2.598\",\"a\":\"79716.90\",\"A\":\"14.955\",\"T\":1788564460485,\"E\":1788564460485,\"st\":1}}"}
{"receive_ns":1788564460485778000,"stream":"btcusdt@bookTicker","event_type":"bookTicker","event_time_ms":1788564460485,"raw_json":"{\"stream\":\"btcusdt@bookTicker\",\"data\":{\"e\":\"bookTicker\",\"u\":11478296824479,\"s\":\"BTCUSDT\",\"ps\":\"BTCUSDT\",\"b\":\"79716.80\",\"B\":\"2.598\",\"a\":\"79716.90\",\"A\":\"14.957\",\"T\":1788564460485,\"E\":1788564460485,\"st\":1}}"}
{"receive_ns":1788564460486109000,"stream":"btcusdt@bookTicker","event_type":"bookTicker","event_time_ms":1788564460486,"raw_json":"{\"stream\":\"btcusdt@bookTicker\",\"data\":{\"e\":\"bookTicker\",\"u\":11478296824615,\"s\":\"BTCUSDT\",\"ps\":\"BTCUSDT\",\"b\":\"79716.80\",\"B\":\"2.598\",\"a\":\"79716.90\",\"A\":\"14.938\",\"T\":1788564460486,\"E\":1788564460486,\"st\":1}}"}
{"receive_ns":1788564460491799000,"stream":"btcusdt@bookTicker","event_type":"bookTicker","event_time_ms":1788564460486,"raw_json":"{\"stream\":\"btcusdt@bookTicker\",\"data\":{\"e\":\"bookTicker\",\"u\":11478296824653,\"s\":\"BTCUSDT\",\"ps\":\"BTCUSDT\",\"b\":\"79716.80\",\"B\":\"2.598\",\"a\":\"79716.90\",\"A\":\"14.936\",\"T\":1788564460486,\"E\":1788564460486,\"st\":1}}"}
{"receive_ns":1788564460509160000,"stream":"btcusdt@bookTicker","event_type":"bookTicker","event_time_ms":1788564460503,"raw_json":"{\"stream\":\"btcusdt@bookTicker\",\"data\":{\"e\":\"bookTicker\",\"u\":11478296825796,\"s\":\"BTCUSDT\",\"ps\":\"BTCUSDT\",\"b\":\"79716.80\",\"B\":\"2.598\",\"a\":\"79716.90\",\"A\":\"14.958\",\"T\":1788564460503,\"E\":1788564460503,\"st\":1}}"}
{"receive_ns":1788564460516000000,"stream":"btcusdt@depth@100ms","event_type":"depthUpdate","event_time_ms":1788564460515,"raw_json":"{\"stream\":\"btcusdt@depth@100ms\",\"data\":{\"e\":\"depthUpdate\",\"E\":1788564460515,\"T\":1788564460514,\"s\":\"BTCUSDT\",\"ps\":\"BTCUSDT\",\"U\":11478296820314,\"u\":11478296826374,\"pu\":11478296820178,\"b\":[[\"29216.80\",\"1.407\"],[\"29616.80\",\"0.693\"],[\"63774.00\",\"0.000\"],[\"71745.10\",\"0.002\"],[\"76528.10\",\"0.000\"],[\"78122.50\",\"0.167\"],[\"78919.60\",\"7.929\"],[\"79500.80\",\"1.003\"],[\"79501.60\",\"0.859\"],[\"79522.20\",\"0.036\"],[\"79529.50\",\"1.628\"],[\"79560.50\",\"0.642\"],[\"79594.40\",\"0.000\"],[\"79684.80\",\"0.002\"],[\"79693.10\",\"0.003\"],[\"79697.60\",\"0.100\"],[\"79702.10\",\"0.000\"],[\"79712.80\",\"0.000\"],[\"79713.50\",\"0.002\"],[\"79716.80\",\"2.598\"]],\"a\":[[\"79716.90\",\"14.958\"],[\"79733.00\",\"0.630\"],[\"79790.30\",\"0.045\"],[\"79792.60\",\"0.201\"],[\"79840.20\",\"0.001\"],[\"79866.40\",\"0.500\"],[\"79886.30\",\"0.090\"],[\"80085.60\",\"0.739\"],[\"80086.80\",\"0.778\"],[\"80514.10\",\"5.291\"]],\"st\":1}}"}
{"receive_ns":1788564460601314000,"stream":"btcusdt@depth@100ms","event_type":"depthUpdate","event_time_ms":1788564460617,"raw_json":"{\"stream\":\"btcusdt@depth@100ms\",\"data\":{\"e\":\"depthUpdate\",\"E\":1788564460617,\"T\":1788564460613,\"s\":\"BTCUSDT\",\"ps\":\"BTCUSDT\",\"U\":11478296826464,\"u\":11478296832593,\"pu\":11478296826374,\"b\":[[\"1000.00\",\"24.754\"],[\"29216.80\",\"1.232\"],[\"29616.80\",\"0.868\"],[\"63773.00\",\"0.000\"],[\"71745.10\",\"0.002\"],[\"75731.10\",\"0.006\"],[\"78441.30\",\"0.357\"],[\"78847.90\",\"2.339\"],[\"78919.60\",\"7.929\"],[\"79058.70\",\"0.000\"],[\"79318.20\",\"3.286\"],[\"79320.20\",\"0.000\"],[\"79522.20\",\"0.004\"],[\"79529.50\",\"1.929\"],[\"79531.50\",\"0.206\"],[\"79594.50\",\"0.684\"],[\"79602.00\",\"0.040\"],[\"79703.50\",\"0.002\"],[\"79703.60\",\"0.255\"]],\"a\":[[\"79746.80\",\"6.569\"],[\"79754.20\",\"0.022\"],[\"79792.60\",\"0.201\"],[\"79840.20\",\"0.351\"],[\"79866.40\",\"0.250\"],[\"80085.60\",\"1.157\"],[\"80514.10\",\"5.291\"],[\"80713.40\",\"6.642\"]],\"st\":1}}"}
{"receive_ns":1788564460650890000,"stream":"btcusdt@bookTicker","event_type":"bookTicker","event_time_ms":1788564460669,"raw_json":"{\"stream\":\"btcusdt@bookTicker\",\"data\":{\"e\":\"bookTicker\",\"u\":11478296835736,\"s\":\"BTCUSDT\",\"ps\":\"BTCUSDT\",\"b\":\"79716.80\",\"B\":\"2.598\",\"a\":\"79716.90\",\"A\":\"14.960\",\"T\":1788564460669,\"E\":1788564460669,\"st\":1}}"}
{"receive_ns":1788564460694471000,"stream":"btcusdt@depth@100ms","event_type":"depthUpdate","event_time_ms":1788564460719,"raw_json":"{\"stream\":\"btcusdt@depth@100ms\",\"data\":{\"e\":\"depthUpdate\",\"E\":1788564460719,\"T\":1788564460717,\"s\":\"BTCUSDT\",\"ps\":\"BTCUSDT\",\"U\":11478296832805,\"u\":11478296838103,\"pu\":11478296832593,\"b\":[[\"1000.00\",\"24.754\"],[\"29216.80\",\"1.050\"],[\"29616.80\",\"1.050\"],[\"63773.00\",\"0.000\"],[\"71745.10\",\"0.002\"],[\"76528.10\",\"0.002\"],[\"78613.50\",\"4.511\"],[\"78690.20\",\"1.073\"],[\"78919.60\",\"7.929\"],[\"79320.20\",\"0.140\"],[\"79500.80\",\"0.000\"],[\"79501.60\",\"0.628\"],[\"79529.50\",\"0.751\"],[\"79693.40\",\"0.431\"],[\"79694.40\",\"0.003\"],[\"79695.10\",\"0.440\"],[\"79696.50\",\"0.361\"],[\"79699.40\",\"0.078\"],[\"79712.70\",\"0.026\"],[\"79713.10\",\"0.028\"]],\"a\":[[\"79716.90\",\"14.960\"],[\"79733.40\",\"1.269\"],[\"79734.60\",\"0.374\"],[\"79735.60\",\"0.000\"],[\"79792.60\",\"0.451\"],[\"79866.40\",\"0.000\"],[\"79886.30\",\"0.000\"],[\"80085.60\",\"0.589\"],[\"80086.80\",\"0.016\"],[\"80514.10\",\"5.291\"],[\"81101.00\",\"7.508\"]],\"st\":1}}"}
{"receive_ns":1788564460700683000,"stream":"btcusdt@bookTicker","event_type":"bookTicker","event_time_ms":1788564460724,"raw_json":"{\"stream\":\"btcusdt@bookTicker\",\"data\":{\"e\":\"bookTicker\",\"u\":11478296838371,\"s\":\"BTCUSDT\",\"ps\":\"BTCUSDT\",\"b\":\"79716.80\",\"B\":\"2.598\",\"a\":\"79716.90\",\"A\":\"14.979\",\"T\":1788564460724,\"E\":1788564460724,\"st\":1}}"}
{"receive_ns":1788564460703035000,"stream":"btcusdt@bookTicker","event_type":"bookTicker","event_time_ms":1788564460725,"raw_json":"{\"stream\":\"btcusdt@bookTicker\",\"data\":{\"e\":\"bookTicker\",\"u\":11478296838418,\"s\":\"BTCUSDT\",\"ps\":\"BTCUSDT\",\"b\":\"79716.80\",\"B\":\"2.598\",\"a\":\"79716.90\",\"A\":\"14.960\",\"T\":1788564460725,\"E\":1788564460725,\"st\":1}}"}
{"receive_ns":1788564460761910000,"stream":"btcusdt@bookTicker","event_type":"bookTicker","event_time_ms":1788564460781,"raw_json":"{\"stream\":\"btcusdt@bookTicker\",\"data\":{\"e\":\"bookTicker\",\"u\":11478296841284,\"s\":\"BTCUSDT\",\"ps\":\"BTCUSDT\",\"b\":\"79716.80\",\"B\":\"2.598\",\"a\":\"79716.90\",\"A\":\"14.979\",\"T\":1788564460781,\"E\":1788564460781,\"st\":1}}"}
{"receive_ns":1788564460774760000,"stream":"btcusdt@bookTicker","event_type":"bookTicker","event_time_ms":1788564460782,"raw_json":"{\"stream\":\"btcusdt@bookTicker\",\"data\":{\"e\":\"bookTicker\",\"u\":11478296841374,\"s\":\"BTCUSDT\",\"ps\":\"BTCUSDT\",\"b\":\"79716.80\",\"B\":\"2.598\",\"a\":\"79716.90\",\"A\":\"14.960\",\"T\":1788564460782,\"E\":1788564460782,\"st\":1}}"}
{"receive_ns":1788564460802479000,"stream":"btcusdt@depth@100ms","event_type":"depthUpdate","event_time_ms":1788564460821,"raw_json":"{\"stream\":\"btcusdt@depth@100ms\",\"data\":{\"e\":\"depthUpdate\",\"E\":1788564460821,\"T\":1788564460817,\"s\":\"BTCUSDT\",\"ps\":\"BTCUSDT\",\"U\":11478296838186,\"u\":11478296843756,\"pu\":11478296838103,\"b\":[[\"29216.80\",\"0.875\"],[\"29616.80\",\"1.225\"],[\"71745.10\",\"0.002\"],[\"71782.00\",\"0.000\"],[\"76528.10\",\"0.000\"],[\"78481.20\",\"4.328\"],[\"78919.60\",\"7.929\"],[\"79118.90\",\"3.169\"],[\"79397.00\",\"0.007\"],[\"79500.80\",\"1.003\"],[\"79501.60\",\"0.859\"],[\"79522.20\",\"0.036\"],[\"79529.50\",\"1.929\"],[\"79531.50\",\"0.006\"],[\"79594.50\",\"0.684\"],[\"79669.30\",\"1.299\"],[\"79671.30\",\"1.272\"],[\"79689.30\",\"0.198\"],[\"79699.30\",\"0.065\"],[\"79699.80\",\"0.285\"],[\"79700.70\",\"1.394\"],[\"79700.80\",\"0.005\"],[\"79700.90\",\"0.217\"],[\"79711.60\",\"0.000\"],[\"79711.70\",\"0.000\"],[\"79711.80\",\"0.001\"],[\"79712.00\",\"0.016\"],[\"79713.00\",\"0.027\"],[\"79713.40\",\"0.026\"],[\"79713.70\",\"0.000\"],[\"79713.90\",\"0.002\"],[\"79714.20\",\"0.001\"]],\"a\":[[\"79716.90\",\"14.960\"],[\"79717.90\",\"0.006\"],[\"79722.10\",\"0.008\"],[\"79724.90\",\"1.757\"],[\"79727.00\",\"0.546\"],[\"79792.60\",\"0.252\"],[\"79840.20\",\"0.351\"],[\"79866.40\",\"0.250\"],[\"79886.30\",\"0.090\"],[\"80085.60\",\"1.157\"],[\"80086.80\",\"0.778\"],[\"80514.10\",\"5.291\"],[\"80673.50\",\"23.763\"],[\"80713.40\",\"6.852\"]],\"st\":1}}"}
{"receive_ns":1788564460840228000,"stream":"btcusdt@bookTicker","event_type":"bookTicker","event_time_ms":1788564460857,"raw_json":"{\"stream\":\"btcusdt@bookTicker\",\"data\":{\"e\":\"bookTicker\",\"u\":11478296845781,\"s\":\"BTCUSDT\",\"ps\":\"BTCUSDT\",\"b\":\"79716.80\",\"B\":\"2.598\",\"a\":\"79716.90\",\"A\":\"14.979\",\"T\":1788564460857,\"E\":1788564460857,\"st\":1}}"}
