{"receive_ns":1788564460851744000,"stream":"btcusdt@bookTicker","event_type":"bookTicker","event_time_ms":1788564460858,"raw_json":"{\"stream\":\"btcusdt@bookTicker\",\"data\":{\"e\":\"bookTicker\",\"u\":11478296845815,\"s\":\"BTCUSDT\",\"ps\":\"BTCUSDT\",\"b\":\"79716.80\",\"B\":\"2.598\",\"a\":\"79716.90\",\"A\":\"14.960\",\"T\":1788564460857,\"E\":1788564460858,\"st\":1}}"}
{"receive_ns":1788564460869095000,"stream":"btcusdt@bookTicker","event_type":"bookTicker","event_time_ms":1788564460883,"raw_json":"{\"stream\":\"btcusdt@bookTicker\",\"data\":{\"e\":\"bookTicker\",\"u\":11478296846976,\"s\":\"BTCUSDT\",\"ps\":\"BTCUSDT\",\"b\":\"79716.80\",\"B\":\"2.598\",\"a\":\"79716.90\",\"A\":\"14.958\",\"T\":1788564460883,\"E\":1788564460883,\"st\":1}}"}
{"receive_ns":1788564460895338000,"stream":"btcusdt@bookTicker","event_type":"bookTicker","event_time_ms":1788564460914,"raw_json":"{\"stream\":\"btcusdt@bookTicker\",\"data\":{\"e\":\"bookTicker\",\"u\":11478296848657,\"s\":\"BTCUSDT\",\"ps\":\"BTCUSDT\",\"b\":\"79716.80\",\"B\":\"2.598\",\"a\":\"79716.90\",\"A\":\"14.946\",\"T\":1788564460914,\"E\":1788564460914,\"st\":1}}"}
{"receive_ns":1788564460900747000,"stream":"btcusdt@trade","event_type":"trade","event_time_ms":1788564460914,"raw_json":"{\"stream\":\"btcusdt@trade\",\"data\":{\"e\":\"trade\",\"E\":1788564460914,\"T\":1788564460914,\"s\":\"BTCUSDT\",\"t\":8054096488,\"p\":\"79716.90\",\"q\":\"0.012\",\"X\":\"MARKET\",\"m\":false,\"st\":1}}"}
{"receive_ns":1788564460910177000,"stream":"btcusdt@bookTicker","event_type":"bookTicker","event_time_ms":1788564460916,"raw_json":"{\"stream\":\"btcusdt@bookTicker\",\"data\":{\"e\":\"bookTicker\",\"u\":11478296848738,\"s\":\"BTCUSDT\",\"ps\":\"BTCUSDT\",\"b\":\"79716.80\",\"B\":\"2.598\",\"a\":\"79716.90\",\"A\":\"14.965\",\"T\":1788564460916,\"E\":1788564460916,\"st\":1}}"}
{"receive_ns":1788564460920753000,"stream":"btcusdt@bookTicker","event_type":"bookTicker","event_time_ms":1788564460916,"raw_json":"{\"stream\":\"btcusdt@bookTicker\",\"data\":{\"e\":\"bookTicker\",\"u\":11478296848764,\"s\":\"BTCUSDT\",\"ps\":\"BTCUSDT\",\"b\":\"79716.80\",\"B\":\"2.598\",\"a\":\"79716.90\",\"A\":\"14.967\",\"T\":1788564460916,\"E\":1788564460916,\"st\":1}}"}
{"receive_ns":1788564460926903000,"stream":"btcusdt@bookTicker","event_type":"bookTicker","event_time_ms":1788564460916,"raw_json":"{\"stream\":\"btcusdt@bookTicker\",\"data\":{\"e\":\"bookTicker\",\"u\":11478296848870,\"s\":\"BTCUSDT\",\"ps\":\"BTCUSDT\",\"b\":\"79716.80\",\"B\":\"2.598\",\"a\":\"79716.90\",\"A\":\"14.948\",\"T\":1788564460916,\"E\":1788564460916,\"st\":1}}"}
{"receive_ns":1788564460927104000,"stream":"btcusdt@bookTicker","event_type":"bookTicker","event_time_ms":1788564460917,"raw_json":"{\"stream\":\"btcusdt@bookTicker\",\"data\":{\"e\":\"bookTicker\",\"u\":11478296848880,\"s\":\"BTCUSDT\",\"ps\":\"BTCUSDT\",\"b\":\"79716.80\",\"B\":\"2.598\",\"a\":\"79716.90\",\"A\":\"14.946\",\"T\":1788564460916,\"E\":1788564460917,\"st\":1}}"}
{"receive_ns":1788564460932821000,"stream":"btcusdt@depth@100ms","event_type":"depthUpdate","event_time_ms":1788564460923,"raw_json":"{\"stream\":\"btcusdt@depth@100ms\",\"data\":{\"e\":\"depthUpdate\",\"E\":1788564460923,\"T\":1788564460921,\"s\":\"BTCUSDT\",\"ps\":\"BTCUSDT\",\"U\":11478296843929,\"u\":11478296849311,\"pu\":11478296843756,\"b\":[[\"1000.00\",\"24.754\"],[\"29216.80\",\"0.693\"],[\"29616.80\",\"1.407\"],[\"63773.00\",\"0.000\"],[\"71745.10\",\"0.002\"],[\"74566.90\",\"0.002\"],[\"75731.00\",\"0.069\"],[\"75731.10\",\"0.008\"],[\"76528.10\",\"0.002\"],[\"78361.60\",\"5.433\"],[\"78760.20\",\"25.801\"],[\"78919.60\",\"7.929\"],[\"79318.20\",\"3.275\"],[\"79320.20\",\"0.140\"],[\"79522.20\",\"0.004\"],[\"79529.50\",\"1.679\"],[\"79531.50\",\"0.456\"],[\"79667.00\",\"10.001\"],[\"79667.10\",\"2.076\"],[\"79690.40\",\"0.017\"],[\"79700.80\",\"0.019\"],[\"79703.10\",\"0.078\"],[\"79710.30\",\"0.252\"],[\"79712.10\",\"0.002\"],[\"79713.60\",\"0.028\"],[\"79714.10\",\"0.000\"],[\"79714.50\",\"0.027\"],[\"79715.00\",\"0.028\"]],\"a\":[[\"79716.90\",\"14.946\"],[\"79724.90\",\"1.507\"],[\"79725.70\",\"0.250\"],[\"79790.30\",\"0.059\"],[\"79792.60\",\"0.002\"],[\"79866.40\",\"0.699\"],[\"80085.60\",\"1.157\"],[\"80115.50\",\"3.242\"],[\"80514.10\",\"5.291\"],[\"80684.10\",\"1.634\"]],\"st\":1}}"}
{"receive_ns":1788564461005876000,"stream":"btcusdt@depth@100ms","event_type":"depthUpdate","event_time_ms":1788564461025,"raw_json":"{\"stream\":\"btcusdt@depth@100ms\",\"data\":{\"e\":\"depthUpdate\",\"E\":1788564461025,\"T\":1788564461023,\"s\":\"BTCUSDT\",\"ps\":\"BTCUSDT\",\"U\":11478296849430,\"u\":11478296853998,\"pu\":11478296849311,\"b\":[[\"1000.00\",\"24.754\"],[\"29216.80\",\"0.518\"],[\"29616.80\",\"1.582\"],[\"63773.00\",\"0.000\"],[\"71745.10\",\"0.002\"],[\"76528.10\",\"0.000\"],[\"78379.00\",\"0.000\"],[\"78919.60\",\"7.929\"],[\"79497.60\",\"0.733\"],[\"79500.80\",\"1.003\"],[\"79501.60\",\"0.628\"],[\"79529.50\",\"1.679\"],[\"79699.30\",\"0.069\"],[\"79700.80\",\"0.015\"],[\"79702.50\",\"0.000\"],[\"79703.50\",\"0.003\"]],\"a\":[[\"79792.60\",\"0.252\"],[\"79866.40\",\"0.449\"],[\"79886.30\",\"0.090\"],[\"80085.60\",\"1.157\"],[\"80086.80\",\"0.778\"],[\"80514.10\",\"5.291\"],[\"87688.60\",\"0.001\"]],\"st\":1}}"}
{"receive_ns":1788564461066603000,"stream":"btcusdt@bookTicker","event_type":"bookTicker","event_time_ms":1788564461086,"raw_json":"{\"stream\":\"btcusdt@bookTicker\",\"data\":{\"e\":\"bookTicker\",\"u\":11478296857809,\"s\":\"BTCUSDT\",\"ps\":\"BTCUSDT\",\"b\":\"79716.80\",\"B\":\"2.597\",\"a\":\"79716.90\",\"A\":\"14.946\",\"T\":1788564461086,\"E\":1788564461086,\"st\":1}}"}
{"receive_ns":1788564461073370000,"stream":"btcusdt@trade","event_type":"trade","event_time_ms":1788564461086,"raw_json":"{\"stream\":\"btcusdt@trade\",\"data\":{\"e\":\"trade\",\"E\":1788564461086,\"T\":1788564461086,\"s\":\"BTCUSDT\",\"t\":8054096489,\"p\":\"79716.80\",\"q\":\"0.001\",\"X\":\"MARKET\",\"m\":true,\"st\":1}}"}
{"receive_ns":1788564461079917000,"stream":"btcusdt@bookTicker","event_type":"bookTicker","event_time_ms":1788564461087,"raw_json":"{\"stream\":\"btcusdt@bookTicker\",\"data\":{\"e\":\"bookTicker\",\"u\":11478296858016,\"s\":\"BTCUSDT\",\"ps\":\"BTCUSDT\",\"b\":\"79716.80\",\"B\":\"2.597\",\"a\":\"79716.90\",\"A\":\"14.965\",\"T\":1788564461087,\"E\":1788564461087,\"st\":1}}"}
{"receive_ns":1788564461085638000,"stream":"btcusdt@bookTicker","event_type":"bookTicker","event_time_ms":1788564461087,"raw_json":"{\"stream\":\"btcusdt@bookTicker\",\"data\":{\"e\":\"bookTicker\",\"u\":11478296858068,\"s\":\"BTCUSDT\",\"ps\":\"BTCUSDT\",\"b\":\"79716.80\",\"B\":\"2.597\",\"a\":\"79716.90\",\"A\":\"14.967\",\"T\":1788564461087,\"E\":1788564461087,\"st\":1}}"}
{"receive_ns":1788564461102370000,"stream":"btcusdt@bookTicker","event_type":"bookTicker","event_time_ms":1788564461088,"raw_json":"{\"stream\":\"btcusdt@bookTicker\",\"data\":{\"e\":\"bookTicker\",\"u\":11478296858219,\"s\":\"BTCUSDT\",\"ps\":\"BTCUSDT\",\"b\":\"79716.80\",\"B\":\"2.597\",\"a\":\"79716.90\",\"A\":\"14.965\",\"T\":1788564461088,\"E\":1788564461088,\"st\":1}}"}
{"receive_ns":1788564461104484000,"stream":"btcusdt@bookTicker","event_type":"bookTicker","event_time_ms":1788564461088,"raw_json":"{\"stream\":\"btcusdt@bookTicker\",\"data\":{\"e\":\"bookTicker\",\"u\":11478296858240,\"s\":\"BTCUSDT\",\"ps\":\"BTCUSDT\",\"b\":\"79716.80\",\"B\":\"2.597\",\"a\":\"79716.90\",\"A\":\"14.946\",\"T\":1788564461088,\"E\":1788564461088,\"st\":1}}"}
{"receive_ns":1788564461110466000,"stream":"btcusdt@bookTicker","event_type":"bookTicker","event_time_ms":1788564461111,"raw_json":"{\"stream\":\"btcusdt@bookTicker\",\"data\":{\"e\":\"bookTicker\",\"u\":11478296861269,\"s\":\"BTCUSDT\",\"ps\":\"BTCUSDT\",\"b\":\"79716.80\",\"B\":\"2.597\",\"a\":\"79716.90\",\"A\":\"14.947\",\"T\":1788564461111,\"E\":1788564461111,\"st\":1}}"}
{"receive_ns":1788564461121745000,"stream":"btcusdt@depth@100ms","event_type":"depthUpdate","event_time_ms":1788564461127,"raw_json":"{\"stream\":\"btcusdt@depth@100ms\",\"data\":{\"e\":\"depthUpdate\",\"E\":1788564461127,\"T\":1788564461125,\"s\":\"BTCUSDT\",\"ps\":\"BTCUSDT\",\"U\":11478296854155,\"u\":11478296862174,\"pu\":11478296853998,\"b\":[[\"29216.80\",\"0.343\"],[\"29516.80\",\"0.007\"],[\"29616.80\",\"1.750\"],[\"63773.00\",\"0.000\"],[\"71745.10\",\"0.002\"],[\"75731.10\",\"0.006\"],[\"78919.60\",\"7.929\"],[\"79320.20\",\"0.140\"],[\"79529.50\",\"1.879\"],[\"79531.50\",\"0.006\"],[\"79594.50\",\"0.000\"],[\"79699.30\",\"0.065\"],[\"79700.80\",\"0.005\"],[\"79702.50\",\"0.000\"],[\"79703.10\",\"0.002\"],[\"79710.40\",\"0.031\"],[\"79715.00\",\"0.002\"],[\"79716.80\",\"2.597\"]],\"a\":[[\"79716.90\",\"14.947\"],[\"79761.00\",\"3.202\"],[\"79761.10\",\"0.002\"],[\"79762.40\",\"0.125\"],[\"79790.30\",\"0.052\"],[\"79792.60\",\"0.451\"],[\"79840.20\",\"0.001\"],[\"79866.40\",\"0.250\"],[\"80085.60\",\"1.002\"],[\"80514.10\",\"5.291\"],[\"80646.20\",\"11.052\"],[\"87688.60\",\"0.000\"]],\"st\":1}}"}
{"receive_ns":1788564461138063000,"stream":"btcusdt@bookTicker","event_type":"bookTicker","event_time_ms":1788564461142,"raw_json":"{\"stream\":\"btcusdt@bookTicker\",\"data\":{\"e\":\"bookTicker\",\"u\":11478296863295,\"s\":\"BTCUSDT\",\"ps\":\"BTCUSDT\",\"b\":\"79716.80\",\"B\":\"2.397\",\"a\":\"79716.90\",\"A\":\"14.947\",\"T\":1788564461142,\"E\":1788564461142,\"st\":1}}"}
{"receive_ns":1788564461149048000,"stream":"btcusdt@trade","event_type":"trade","event_time_ms":1788564461142,"raw_json":"{\"stream\":\"btcusdt@trade\",\"data\":{\"e\":\"trade\",\"E\":1788564461142,\"T\":1788564461142,\"s\":\"BTCUSDT\",\"t\":8054096490,\"p\":\"79716.80\",\"q\":\"0.029\",\"X\":\"MARKET\",\"m\":true,\"st\":1}}"}
{"receive_ns":1788564461159751000,"stream":"btcusdt@trade","event_type":"trade","event_time_ms":1788564461142,"raw_json":"{\"stream\":\"btcusdt@trade\",\"data\":{\"e\":\"trade\",\"E\":1788564461142,\"T\":1788564461142,\"s\":\"BTCUSDT\",\"t\":8054096491,\"p\":\"79716.80\",\"q\":\"0.149\",\"X\":\"MARKET\",\"m\":true,\"st\":1}}"}
{"receive_ns":1788564461160144000,"stream":"btcusdt@trade","event_type":"trade","event_time_ms":1788564461142,"raw_json":"{\"stream\":\"btcusdt@trade\",\"data\":{\"e\":\"trade\",\"E\":1788564461142,\"T\":1788564461142,\"s\":\"BTCUSDT\",\"t\":8054096492,\"p\":\"79716.80\",\"q\":\"0.001\",\"X\":\"MARKET\",\"m\":true,\"st\":1}}"}
{"receive_ns":1788564461160465000,"stream":"btcusdt@trade","event_type":"trade","event_time_ms":1788564461142,"raw_json":"{\"stream\":\"btcusdt@trade\",\"data\":{\"e\":\"trade\",\"E\":1788564461142,\"T\":1788564461142,\"s\":\"BTCUSDT\",\"t\":8054096493,\"p\":\"79716.80\",\"q\":\"0.021\",\"X\":\"MARKET\",\"m\":true,\"st\":1}}"}
{"receive_ns":1788564461171609000,"stream":"btcusdt@bookTicker","event_type":"bookTicker","event_time_ms":1788564461144,"raw_json":"{\"stream\":\"btcusdt@bookTicker\",\"data\":{\"e\":\"bookTicker\",\"u\":11478296863361,\"s\":\"BTCUSDT\",\"ps\":\"BTCUSDT\",\"b\":\"79716.80\",\"B\":\"2.397\",\"a\":\"79716.90\",\"A\":\"14.966\",\"T\":1788564461144,\"E\":1788564461144,\"st\":1}}"}
{"receive_ns":1788564461177070000,"stream":"btcusdt@bookTicker","event_type":"bookTicker","event_time_ms":1788564461144,"raw_json":"{\"stream\":\"btcusdt@bookTicker\",\"data\":{\"e\":\"bookTicker\",\"u\":11478296863462,\"s\":\"BTCUSDT\",\"ps\":\"BTCUSDT\",\"b\":\"79716.80\",\"B\":\"2.397\",\"a\":\"79716.90\",\"A\":\"14.968\",\"T\":1788564461144,\"E\":1788564461144,\"st\":1}}"}
{"receive_ns":1788564461194142000,"stream":"btcusdt@bookTicker","event_type":"bookTicker","event_time_ms":1788564461145,"raw_json":"{\"stream\":\"btcusdt@bookTicker\",\"data\":{\"e\":\"bookTicker\",\"u\":11478296863575,\"s\":\"BTCUSDT\",\"ps\":\"BTCUSDT\",\"b\":\"79716.80\",\"B\":\"2.397\",\"a\":\"79716.90\",\"A\":\"14.949\",\"T\":1788564461144,\"E\":1788564461145,\"st\":1}}"}
{"receive_ns":1788564461206140000,"stream":"btcusdt@bookTicker","event_type":"bookTicker","event_time_ms":1788564461145,"raw_json":"{\"stream\":\"btcusdt@bookTicker\",\"data\":{\"e\":\"bookTicker\",\"u\":11478296863596,\"s\":\"BTCUSDT\",\"ps\":\"BTCUSDT\",\"b\":\"79716.80\",\"B\":\"2.397\",\"a\":\"79716.90\",\"A\":\"14.947\",\"T\":1788564461145,\"E\":1788564461145,\"st\":1}}"}
{"receive_ns":1788564461213048000,"stream":"btcusdt@bookTicker","event_type":"bookTicker","event_time_ms":1788564461170,"raw_json":"{\"stream\":\"btcusdt@bookTicker\",\"data\":{\"e\":\"bookTicker\",\"u\":11478296865155,\"s\":\"BTCUSDT\",\"ps\":\"BTCUSDT\",\"b\":\"79716.80\",\"B\":\"2.397\",\"a\":\"79716.90\",\"A\":\"14.942\",\"T\":1788564461170,\"E\":1788564461170,\"st\":1}}"}
{"receive_ns":1788564461213411000,"stream":"btcusdt@bookTicker","event_type":"bookTicker","event_time_ms":1788564461173,"raw_json":"{\"stream\":\"btcusdt@bookTicker\",\"data\":{\"e\":\"bookTicker\",\"u\":11478296865355,\"s\":\"BTCUSDT\",\"ps\":\"BTCUSDT\",\"b\":\"79716.80\",\"B\":\"2.397\",\"a\":\"79716.90\",\"A\":\"14.955\",\"T\":1788564461173,\"E\":1788564461173,\"st\":1}}"}
{"receive_ns":1788564461224231000,"stream":"btcusdt@depth@100ms","event_type":"depthUpdate","event_time_ms":1788564461229,"raw_json":"{\"stream\":\"btcusdt@depth@100ms\",\"data\":{\"e\":\"depthUpdate\",\"E\":1788564461229,\"T\":1788564461226,\"s\":\"BTCUSDT\",\"ps\":\"BTCUSDT\",\"U\":11478296862279,\"u\":11478296868715,\"pu\":11478296862174,\"b\":[[\"1000.00\",\"24.754\"],[\"29216.80\",\"0.224\"],[\"29516.80\",\"0.063\"],[\"29616.80\",\"1.813\"],[\"71745.10\",\"0.002\"],[\"76528.10\",\"0.002\"],[\"78469.80\",\"1.430\"],[\"78584.80\",\"0.608\"],[\"78690.20\",\"0.788\"],[\"78720.30\",\"4.137\"],[\"78841.60\",\"0.027\"],[\"78919.60\",\"7.929\"],[\"79318.20\",\"3.275\"],[\"79497.60\",\"0.502\"],[\"79500.80\",\"1.003\"],[\"79501.60\",\"1.862\"],[\"79522.20\",\"0.036\"],[\"79529.50\",\"0.876\"],[\"79531.50\",\"0.256\"],[\"79594.50\",\"0.684\"],[\"79670.30\",\"0.014\"],[\"79682.40\",\"0.001\"],[\"79701.90\",\"0.001\"],[\"79702.50\",\"0.000\"],[\"79703.50\",\"0.002\"],[\"79710.30\",\"0.001\"],[\"79712.10\",\"0.002\"],[\"79712.20\",\"0.002\"],[\"79713.20\",\"0.027\"],[\"79713.40\",\"0.026\"],[\"79713.50\",\"0.028\"],[\"79713.60\",\"0.028\"],[\"79714.50\",\"0.001\"],[\"79716.80\",\"2.397\"]],\"a\":[[\"79716.90\",\"14.955\"],[\"79739.40\",\"0.529\"],[\"79740.50\",\"0.009\"],[\"79792.60\",\"0.451\"],[\"79840.20\",\"0.351\"],[\"79886.30\",\"0.090\"],[\"80085.60\",\"1.157\"],[\"80086.80\",\"0.778\"],[\"80514.10\",\"5.291\"],[\"80673.50\",\"25.001\"],[\"80706.60\",\"0.621\"],[\"80715.90\",\"0.375\"],[\"80747.20\",\"0.007\"],[\"80756.80\",\"0.139\"],[\"80793.10\",\"1.434\"],[\"81311.20\",\"0.027\"],[\"82564.50\",\"0.074\"]],\"st\":1}}"}
{"receive_ns":1788564461233070000,"stream":"btcusdt@bookTicker","event_type":"bookTicker","event_time_ms":1788564461249,"raw_json":"{\"stream\":\"btcusdt@bookTicker\",\"data\":{\"e\":\"bookTicker\",\"u\":11478296870089,\"s\":\"BTCUSDT\",\"ps\":\"BTCUSDT\",\"b\":\"79716.80\",\"B\":\"2.397\",\"a\":\"79716.90\",\"A\":\"14.974\",\"T\":1788564461249,\"E\":1788564461249,\"st\":1}}"}
{"receive_ns":1788564461244359000,"stream":"btcusdt@bookTicker","event_type":"bookTicker","event_time_ms":1788564461250,"raw_json":"{\"stream\":\"btcusdt@bookTicker\",\"data\":{\"e\":\"bookTicker\",\"u\":11478296870133,\"s\":\"BTCUSDT\",\"ps\":\"BTCUSDT\",\"b\":\"79716.80\",\"B\":\"2.397\",\"a\":\"79716.90\",\"A\":\"14.955\",\"T\":1788564461249,\"E\":1788564461250,\"st\":1}}"}
{"receive_ns":1788564461294080000,"stream":"btcusdt@bookTicker","event_type":"bookTicker","event_time_ms":1788564461307,"raw_json":"{\"stream\":\"btcusdt@bookTicker\",\"data\":{\"e\":\"bookTicker\",\"u\":11478296872992,\"s\":\"BTCUSDT\",\"ps\":\"BTCUSDT\",\"b\":\"79716.80\",\"B\":\"2.397\",\"a\":\"79716.90\",\"A\":\"14.959\",\"T\":1788564461306,\"E\":1788564461307,\"st\":1}}"}
{"receive_ns":1788564461304775000,"stream":"btcusdt@bookTicker","event_type":"bookTicker","event_time_ms":1788564461329,"raw_json":"{\"stream\":\"btcusdt@bookTicker\",\"data\":{\"e\":\"bookTicker\",\"u\":11478296874180,\"s\":\"BTCUSDT\",\"ps\":\"BTCUSDT\",\"b\":\"79716.80\",\"B\":\"2.397\",\"a\":\"79716.90\",\"A\":\"14.958\",\"T\":1788564461329,\"E\":1788564461329,\"st\":1}}"}
{"receive_ns":1788564461320689000,"stream":"btcusdt@depth@100ms","event_type":"depthUpdate","event_time_ms":1788564461331,"raw_json":"{\"stream\":\"btcusdt@depth@100ms\",\"data\":{\"e\":\"depthUpdate\",\"E\":1788564461331,\"T\":1788564461330,\"s\":\"BTCUSDT\",\"ps\":\"BTCUSDT\",\"U\":11478296868890,\"u\":11478296874252,\"pu\":11478296868715,\"b\":[[\"29216.80\",\"0.105\"],[\"29516.80\",\"0.126\"],[\"29616.80\",\"1.869\"],[\"63773.40\",\"0.002\"],[\"71745.10\",\"0.002\"],[\"76528.10\",\"0.000\"],[\"78521.00\",\"0.941\"],[\"78680.50\",\"4.062\"],[\"78919.60\",\"7.931\"],[\"79318.20\",\"3.274\"],[\"79320.20\",\"0.000\"],[\"79522.20\",\"0.004\"],[\"79529.50\",\"0.876\"],[\"79688.70\",\"0.045\"],[\"79688.90\",\"0.451\"],[\"79689.40\",\"0.003\"],[\"79699.30\",\"0.069\"],[\"79700.00\",\"0.524\"],[\"79700.70\",\"1.318\"],[\"79700.80\",\"0.077\"],[\"79703.40\",\"0.290\"],[\"79712.20\",\"0.002\"],[\"79712.30\",\"0.002\"],[\"79712.50\",\"0.000\"],[\"79712.60\",\"0.001\"],[\"79713.40\",\"0.026\"],[\"79713.50\",\"0.002\"],[\"79713.60\",\"0.028\"],[\"79713.70\",\"0.026\"],[\"79714.00\",\"0.027\"],[\"79714.20\",\"0.027\"],[\"79714.40\",\"0.028\"]],\"a\":[[\"79716.90\",\"14.958\"],[\"79761.00\",\"3.152\"],[\"79761.10\",\"0.052\"],[\"79792.60\",\"0.252\"],[\"79866.40\",\"0.199\"],[\"80085.60\",\"1.157\"],[\"80514.10\",\"5.291\"],[\"80713.40\",\"7.129\"]],\"st\":1}}"}
{"receive_ns":1788564461335823000,"stream":"btcusdt@bookTicker","event_type":"bookTicker","event_time_ms":1788564461336,"raw_json":"{\"stream\":\"btcusdt@bookTicker\",\"data\":{\"e\":\"bookTicker\",\"u\":11478296874529,\"s\":\"BTCUSDT\",\"ps\":\"BTCUSDT\",\"b\":\"79716.80\",\"B\":\"2.397\",\"a\":\"79716.90\",\"A\":\"14.960\",\"T\":1788564461335,\"E\":1788564461336,\"st\":1}}"}
{"receive_ns":1788564461405443000,"stream":"btcusdt@bookTicker","event_type":"bookTicker","event_time_ms":1788564461422,"raw_json":"{\"stream\":\"btcusdt@bookTicker\",\"data\":{\"e\":\"bookTicker\",\"u\":11478296878757,\"s\":\"BTCUSDT\",\"ps\":\"BTCUSDT\",\"b\":\"79716.80\",\"B\":\"2.397\",\"a\":\"79716.90\",\"A\":\"14.951\",\"T\":1788564461422,\"E\":1788564461422,\"st\":1}}"}
{"receive_ns":1788564461420490000,"stream":"btcusdt@bookTicker","event_type":"bookTicker","event_time_ms":1788564461425,"raw_json":"{\"stream\":\"btcusdt@bookTicker\",\"data\":{\"e\":\"bookTicker\",\"u\":11478296878955,\"s\":\"BTCUSDT\",\"ps\":\"BTCUSDT\",\"b\":\"79716.80\",\"B\":\"2.397\",\"a\":\"79716.90\",\"A\":\"14.961\",\"T\":1788564461425,\"E\":1788564461425,\"st\":1}}"}
{"receive_ns":1788564461441770000,"stream":"btcusdt@bookTicker","event_type":"bookTicker","event_time_ms":1788564461428,"raw_json":"{\"stream\":\"btcusdt@bookTicker\",\"data\":{\"e\":\"bookTicker\",\"u\":11478296879122,\"s\":\"BTCUSDT\",\"ps\":\"BTCUSDT\",\"b\":\"79716.80\",\"B\":\"2.375\",\"a\":\"79716.90\",\"A\":\"14.961\",\"T\":1788564461428,\"E\":1788564461428,\"st\":1}}"}
{"receive_ns":1788564461453216000,"stream":"btcusdt@bookTicker","event_type":"bookTicker","event_time_ms":1788564461429,"raw_json":"{\"stream\":\"btcusdt@bookTicker\",\"data\":{\"e\":\"bookTicker\",\"u\":11478296879159,\"s\":\"BTCUSDT\",\"ps\":\"BTCUSDT\",\"b\":\"79716.80\",\"B\":\"2.375\",\"a\":\"79716.90\",\"A\":\"14.980\",\"T\":1788564461429,\"E\":1788564461429,\"st\":1}}"}
{"receive_ns":1788564461459799000,"stream":"btcusdt@bookTicker","event_type":"bookTicker","event_time_ms":1788564461429,"raw_json":"{\"stream\":\"btcusdt@bookTicker\",\"data\":{\"e\":\"bookTicker\",\"u\":11478296879194,\"s\":\"BTCUSDT\",\"ps\":\"BTCUSDT\",\"b\":\"79716.80\",\"B\":\"2.375\",\"a\":\"79716.90\",\"A\":\"14.982\",\"T\":1788564461429,\"E\":1788564461429,\"st\":1}}"}
{"receive_ns":1788564461471399000,"stream":"btcusdt@bookTicker","event_type":"bookTicker","event_time_ms":1788564461430,"raw_json":"{\"stream\":\"btcusdt@bookTicker\",\"data\":{\"e\":\"bookTicker\",\"u\":11478296879252,\"s\":\"BTCUSDT\",\"ps\":\"BTCUSDT\",\"b\":\"79716.80\",\"B\":\"2.375\",\"a\":\"79716.90\",\"A\":\"14.963\",\"T\":1788564461430,\"E\":1788564461430,\"st\":1}}"}
{"receive_ns":1788564461476758000,"stream":"btcusdt@bookTicker","event_type":"bookTicker","event_time_ms":1788564461430,"raw_json":"{\"stream\":\"btcusdt@bookTicker\",\"data\":{\"e\":\"bookTicker\",\"u\":11478296879265,\"s\":\"BTCUSDT\",\"ps\":\"BTCUSDT\",\"b\":\"79716.80\",\"B\":\"2.375\",\"a\":\"79716.90\",\"A\":\"14.961\",\"T\":1788564461430,\"E\":1788564461430,\"st\":1}}"}
{"receive_ns":1788564461482080000,"stream":"btcusdt@bookTicker","event_type":"bookTicker","event_time_ms":1788564461431,"raw_json":"{\"stream\":\"btcusdt@bookTicker\",\"data\":{\"e\":\"bookTicker\",\"u\":11478296879323,\"s\":\"BTCUSDT\",\"ps\":\"BTCUSDT\",\"b\":\"79716.80\",\"B\":\"2.411\",\"a\":\"79716.90\",\"A\":\"14.961\",\"T\":1788564461431,\"E\":1788564461431,\"st\":1}}"}
{"receive_ns":1788564461492549000,"stream":"btcusdt@bookTicker","event_type":"bookTicker","event_time_ms":1788564461432,"raw_json":"{\"stream\":\"btcusdt@bookTicker\",\"data\":{\"e\":\"bookTicker\",\"u\":11478296879377,\"s\":\"BTCUSDT\",\"ps\":\"BTCUSDT\",\"b\":\"79716.80\",\"B\":\"2.409\",\"a\":\"79716.90\",\"A\":\"14.961\",\"T\":1788564461432,\"E\":1788564461432,\"st\":1}}"}
{"receive_ns":1788564461508747000,"stream":"btcusdt@depth@100ms","event_type":"depthUpdate","event_time_ms":1788564461433,"raw_json":"{\"stream\":\"btcusdt@depth@100ms\",\"data\":{\"e\":\"depthUpdate\",\"E\":1788564461433,\"T\":1788564461432,\"s\":\"BTCUSDT\",\"ps\":\"BTCUSDT\",\"U\":11478296874284,\"u\":11478296879384,\"pu\":11478296874252,\"b\":[[\"29216.80\",\"0.007\"],[\"29516.80\",\"0.203\"],[\"29616.80\",\"1.890\"],[\"63773.40\",\"0.000\"],[\"71745.10\",\"0.002\"],[\"74451.90\",\"0.002\"],[\"76528.10\",\"0.002\"],[\"77463.90\",\"0.003\"],[\"78919.60\",\"7.931\"],[\"79320.20\",\"0.140\"],[\"79500.80\",\"0.000\"],[\"79501.60\",\"0.628\"],[\"79529.50\",\"0.951\"],[\"79531.50\",\"0.006\"],[\"79699.30\",\"0.003\"],[\"79701.00\",\"0.086\"],[\"79701.90\",\"0.000\"],[\"79703.30\",\"0.001\"],[\"79710.40\",\"0.280\"],[\"79712.90\",\"0.026\"],[\"79714.00\",\"0.001\"],[\"79714.20\",\"0.001\"],[\"79714.40\",\"0.002\"],[\"79716.80\",\"2.409\"]],\"a\":[[\"79716.90\",\"14.961\"],[\"79792.60\",\"0.002\"],[\"79866.40\",\"0.449\"],[\"79886.30\",\"0.000\"],[\"80085.60\",\"0.589\"],[\"80086.80\",\"0.016\"],[\"80115.50\",\"3.243\"],[\"80514.10\",\"5.293\"],[\"81088.00\",\"1.247\"]],\"st\":1}}"}
{"receive_ns":1788564461525066000,"stream":"btcusdt@bookTicker","event_type":"bookTicker","event_time_ms":1788564461476,"raw_json":"{\"stream\":\"btcusdt@bookTicker\",\"data\":{\"e\":\"bookTicker\",\"u\":11478296881623,\"s\":\"BTCUSDT\",\"ps\":\"BTCUSDT\",\"b\":\"79716.80\",\"B\":\"2.396\",\"a\":\"79716.90\",\"A\":\"14.961\",\"T\":1788564461476,\"E\":1788564461476,\"st\":1}}"}
{"receive_ns":1788564461530483000,"stream":"btcusdt@trade","event_type":"trade","event_time_ms":1788564461476,"raw_json":"{\"stream\":\"btcusdt@trade\",\"data\":{\"e\":\"trade\",\"E\":1788564461476,\"T\":1788564461476,\"s\":\"BTCUSDT\",\"t\":8054096494,\"p\":\"79716.80\",\"q\":\"0.013\",\"X\":\"MARKET\",\"m\":true,\"st\":1}}"}
{"receive_ns":1788564461535776000,"stream":"btcusdt@bookTicker","event_type":"bookTicker","event_time_ms":1788564461478,"raw_json":"{\"stream\":\"btcusdt@bookTicker\",\"data\":{\"e\":\"bookTicker\",\"u\":11478296881778,\"s\":\"BTCUSDT\",\"ps\":\"BTCUSDT\",\"b\":\"79716.80\",\"B\":\"2.396\",\"a\":\"79716.90\",\"A\":\"14.963\",\"T\":1788564461478,\"E\":1788564461478,\"st\":1}}"}
{"receive_ns":1788564461535972000,"stream":"btcusdt@bookTicker","event_type":"bookTicker","event_time_ms":1788564461478,"raw_json":"{\"stream\":\"btcusdt@bookTicker\",\"data\":{\"e\":\"bookTicker\",\"u\":11478296881806,\"s\":\"BTCUSDT\",\"ps\":\"BTCUSDT\",\"b\":\"79716.80\",\"B\":\"2.396\",\"a\":\"79716.90\",\"A\":\"14.982\",\"T\":1788564461478,\"E\":1788564461478,\"st\":1}}"}
{"receive_ns":1788564461543090000,"stream":"btcusdt@bookTicker","event_type":"bookTicker","event_time_ms":1788564461479,"raw_json":"{\"stream\":\"btcusdt@bookTicker\",\"data\":{\"e\":\"bookTicker\",\"u\":11478296881936,\"s\":\"BTCUSDT\",\"ps\":\"BTCUSDT\",\"b\":\"79716.80\",\"B\":\"2.396\",\"a\":\"79716.90\",\"A\":\"14.980\",\"T\":1788564461478,\"E\":1788564461479,\"st\":1}}"}
{"receive_ns":1788564461543287000,"stream":"btcusdt@bookTicker","event_type":"bookTicker","event_time_ms":1788564461479,"raw_json":"{\"stream\":\"btcusdt@bookTicker\",\"data\":{\"e\":\"bookTicker\",\"u\":11478296881939,\"s\":\"BTCUSDT\",\"ps\":\"BTCUSDT\",\"b\":\"79716.80\",\"B\":\"2.396\",\"a\":\"79716.90\",\"A\":\"14.961\",\"T\":1788564461478,\"E\":1788564461479,\"st\":1}}"}
{"receive_ns":1788564461548686000,"stream":"btcusdt@bookTicker","event_type":"bookTicker","event_time_ms":1788564461479,"raw_json":"{\"stream\":\"btcusdt@bookTicker\",\"data\":{\"e\":\"bookTicker\",\"u\":11478296881960,\"s\":\"BTCUSDT\",\"ps\":\"BTCUSDT\",\"b\":\"79716.80\",\"B\":\"2.398\",\"a\":\"79716.90\",\"A\":\"14.961\",\"T\":1788564461479,\"E\":1788564461479,\"st\":1}}"}
{"receive_ns":1788564461554276000,"stream":"btcusdt@depth@100ms","event_type":"depthUpdate","event_time_ms":1788564461535,"raw_json":"{\"stream\":\"btcusdt@depth@100ms\",\"data\":{\"e\":\"depthUpdate\",\"E\":1788564461535,\"T\":1788564461533,\"s\":\"BTCUSDT\",\"ps\":\"BTCUSDT\",\"U\":11478296879395,\"u\":11478296885278,\"pu\":11478296879384,\"b\":[[\"1000.00\",\"24.754\"],[\"29216.80\",\"0.000\"],[\"29516.80\",\"0.378\"],[\"29616.80\",\"1.722\"],[\"34000.00\",\"0.975\"],[\"71745.10\",\"0.002\"],[\"76528.10\",\"0.000\"],[\"77604.30\",\"0.799\"],[\"78488.30\",\"6.013\"],[\"78739.90\",\"10.149\"],[\"78919.60\",\"7.929\"],[\"79318.20\",\"3.284\"],[\"79500.80\",\"1.003\"],[\"79501.60\",\"0.859\"],[\"79529.50\",\"1.829\"],[\"79645.00\",\"0.004\"],[\"79693.10\",\"0.003\"],[\"79698.90\",\"0.065\"],[\"79710.50\",\"0.002\"],[\"79716.80\",\"2.398\"]],\"a\":[[\"79716.90\",\"14.961\"],[\"79733.00\",\"0.630\"],[\"79772.80\",\"0.316\"],[\"79788.70\",\"0.021\"],[\"79866.40\",\"0.500\"],[\"79886.30\",\"0.090\"],[\"80085.60\",\"1.157\"],[\"80086.80\",\"0.778\"],[\"80514.10\",\"5.291\"],[\"80805.60\",\"14.704\"],[\"81311.20\",\"0.024\"]],\"st\":1}}"}
{"receive_ns":1788564461570191000,"stream":"btcusdt@bookTicker","event_type":"bookTicker","event_time_ms":1788564461547,"raw_json":"{\"stream\":\"btcusdt@bookTicker\",\"data\":{\"e\":\"bookTicker\",\"u\":11478296886020,\"s\":\"BTCUSDT\",\"ps\":\"BTCUSDT\",\"b\":\"79716.80\",\"B\":\"2.398\",\"a\":\"79716.90\",\"A\":\"14.959\",\"T\":1788564461547,\"E\":1788564461547,\"st\":1}}"}
{"receive_ns":1788564461608307000,"stream":"btcusdt@bookTicker","event_type":"bookTicker","event_time_ms":1788564461628,"raw_json":"{\"stream\":\"btcusdt@bookTicker\",\"data\":{\"e\":\"bookTicker\",\"u\":11478296890474,\"s\":\"BTCUSDT\",\"ps\":\"BTCUSDT\",\"b\":\"79716.80\",\"B\":\"2.395\",\"a\":\"79716.90\",\"A\":\"14.959\",\"T\":1788564461628,\"E\":1788564461628,\"st\":1}}"}
{"receive_ns":1788564461613627000,"stream":"btcusdt@trade","event_type":"trade","event_time_ms":1788564461628,"raw_json":"{\"stream\":\"btcusdt@trade\",\"data\":{\"e\":\"trade\",\"E\":1788564461628,\"T\":1788564461628,\"s\":\"BTCUSDT\",\"t\":8054096495,\"p\":\"79716.80\",\"q\":\"0.003\",\"X\":\"MARKET\",\"m\":true,\"st\":1}}"}
{"receive_ns":1788564461615783000,"stream":"btcusdt@bookTicker","event_type":"bookTicker","event_time_ms":1788564461629,"raw_json":"{\"stream\":\"btcusdt@bookTicker\",\"data\":{\"e\":\"bookTicker\",\"u\":11478296890624,\"s\":\"BTCUSDT\",\"ps\":\"BTCUSDT\",\"b\":\"79716.80\",\"B\":\"2.395\",\"a\":\"79716.90\",\"A\":\"14.961\",\"T\":1788564461629,\"E\":1788564461629,\"st\":1}}"}
{"receive_ns":1788564461615972000,"stream":"btcusdt@bookTicker","event_type":"bookTicker","event_time_ms":1788564461629,"raw_json":"{\"stream\":\"btcusdt@bookTicker\",\"data\":{\"e\":\"bookTicker\",\"u\":11478296890644,\"s\":\"BTCUSDT\",\"ps\":\"BTCUSDT\",\"b\":\"79716.80\",\"B\":\"2.395\",\"a\":\"79716.90\",\"A\":\"14.980\",\"T\":1788564461629,\"E\":1788564461629,\"st\":1}}"}
{"receive_ns":1788564461621500000,"stream":"btcusdt@bookTicker","event_type":"bookTicker","event_time_ms":1788564461630,"raw_json":"{\"stream\":\"btcusdt@bookTicker\",\"data\":{\"e\":\"bookTicker\",\"u\":11478296890713,\"s\":\"BTCUSDT\",\"ps\":\"BTCUSDT\",\"b\":\"79716.80\",\"B\":\"2.395\",\"a\":\"79716.90\",\"A\":\"14.978\",\"T\":1788564461630,\"E\":1788564461630,\"st\":1}}"}
{"receive_ns":1788564461621758000,"stream":"btcusdt@bookTicker","event_type":"bookTicker","event_time_ms":1788564461630,"raw_json":"{\"stream\":\"btcusdt@bookTicker\",\"data\":{\"e\":\"bookTicker\",\"u\":11478296890719,\"s\":\"BTCUSDT\",\"ps\":\"BTCUSDT\",\"b\":\"79716.80\",\"B\":\"2.395\",\"a\":\"79716.90\",\"A\":\"14.959\",\"T\":1788564461630,\"E\":1788564461630,\"st\":1}}"}
{"receive_ns":1788564461632437000,"stream":"btcusdt@depth@100ms","event_type":"depthUpdate","event_time_ms":1788564461637,"raw_json":"{\"stream\":\"btcusdt@depth@100ms\",\"data\":{\"e\":\"depthUpdate\",\"E\":1788564461637,\"T\":1788564461633,\"s\":\"BTCUSDT\",\"ps\":\"BTCUSDT\",\"U\":11478296885424,\"u\":11478296890913,\"pu\":11478296885278,\"b\":[[\"29516.80\",\"0.553\"],[\"29616.80\",\"1.547\"],[\"63773.00\",\"0.000\"],[\"71745.10\",\"0.002\"],[\"78122.50\",\"0.170\"],[\"78281.90\",\"1.082\"],[\"78919.60\",\"7.929\"],[\"79320.20\",\"0.140\"],[\"79423.00\",\"0.025\"],[\"79529.50\",\"1.829\"],[\"79531.50\",\"0.206\"],[\"79594.50\",\"0.684\"],[\"79716.80\",\"2.395\"]],\"a\":[[\"79716.90\",\"14.959\"],[\"79840.20\",\"0.351\"],[\"79866.40\",\"0.699\"],[\"80085.60\",\"1.157\"],[\"80514.10\",\"5.291\"]],\"st\":1}}"}
{"receive_ns":1788564461721716000,"stream":"btcusdt@depth@100ms","event_type":"depthUpdate","event_time_ms":1788564461739,"raw_json":"{\"stream\":\"btcusdt@depth@100ms\",\"data\":{\"e\":\"depthUpdate\",\"E\":1788564461739,\"T\":1788564461737,\"s\":\"BTCUSDT\",\"ps\":\"BTCUSDT\",\"U\":11478296891159,\"u\":11478296896474,\"pu\":11478296890913,\"b\":[[\"29516.80\",\"0.735\"],[\"29616.80\",\"1.365\"],[\"71745.10\",\"0.002\"],[\"76528.10\",\"0.002\"],[\"78690.20\",\"0.636\"],[\"78919.60\",\"7.929\"],[\"79500.80\",\"1.003\"],[\"79501.60\",\"0.859\"],[\"79522.20\",\"0.004\"],[\"79529.50\",\"1.428\"],[\"79594.50\",\"0.000\"],[\"79699.30\",\"0.069\"],[\"79700.00\",\"0.314\"],[\"79700.80\",\"0.001\"],[\"79701.00\",\"0.020\"],[\"79702.50\",\"0.001\"],[\"79703.30\",\"0.000\"],[\"79703.40\",\"0.020\"],[\"79712.30\",\"0.028\"],[\"79712.40\",\"0.026\"],[\"79712.50\",\"0.026\"],[\"79712.60\",\"0.027\"],[\"79713.20\",\"0.001\"],[\"79713.40\",\"0.000\"],[\"79713.60\",\"0.002\"],[\"79713.70\",\"0.000\"]],\"a\":[[\"79840.20\",\"0.001\"],[\"79866.40\",\"0.699\"],[\"79886.30\",\"0.090\"],[\"80085.60\",\"0.739\"],[\"80086.80\",\"0.778\"],[\"80514.10\",\"5.291\"],[\"80952.50\",\"4.690\"]],\"st\":1}}"}
{"receive_ns":1788564461772615000,"stream":"btcusdt@bookTicker","event_type":"bookTicker","event_time_ms":1788564461790,"raw_json":"{\"stream\":\"btcusdt@bookTicker\",\"data\":{\"e\":\"bookTicker\",\"u\":11478296898983,\"s\":\"BTCUSDT\",\"ps\":\"BTCUSDT\",\"b\":\"79716.80\",\"B\":\"2.394\",\"a\":\"79716.90\",\"A\":\"14.959\",\"T\":1788564461790,\"E\":1788564461790,\"st\":1}}"}
{"receive_ns":1788564461818170000,"stream":"btcusdt@depth@100ms","event_type":"depthUpdate","event_time_ms":1788564461841,"raw_json":"{\"stream\":\"btcusdt@depth@100ms\",\"data\":{\"e\":\"depthUpdate\",\"E\":1788564461841,\"T\":1788564461838,\"s\":\"BTCUSDT\",\"ps\":\"BTCUSDT\",\"U\":11478296896560,\"u\":11478296901508,\"pu\":11478296896474,\"b\":[[\"1000.00\",\"24.754\"],[\"29516.80\",\"0.910\"],[\"29616.80\",\"1.190\"],[\"71745.10\",\"0.002\"],[\"76528.10\",\"0.000\"],[\"78122.50\",\"0.173\"],[\"78545.00\",\"4.646\"],[\"78680.50\",\"4.316\"],[\"78919.60\",\"7.929\"],[\"79318.20\",\"3.274\"],[\"79320.20\",\"0.000\"],[\"79522.20\",\"0.004\"],[\"79529.50\",\"1.929\"],[\"79531.50\",\"0.206\"],[\"79555.00\",\"2.624\"],[\"79555.30\",\"0.712\"],[\"79594.50\",\"0.684\"],[\"79699.30\",\"0.065\"],[\"79700.70\",\"1.394\"],[\"79700.80\",\"0.005\"],[\"79708.50\",\"0.000\"],[\"79708.60\",\"0.001\"],[\"79709.10\",\"0.003\"],[\"79709.20\",\"0.003\"],[\"79714.10\",\"0.026\"],[\"79716.80\",\"2.394\"]],\"a\":[[\"79793.50\",\"0.002\"],[\"79840.20\",\"0.351\"],[\"79866.40\",\"0.449\"],[\"79879.60\",\"2.483\"],[\"79879.70\",\"0.004\"],[\"80085.60\",\"1.157\"],[\"80514.10\",\"5.291\"],[\"80753.20\",\"2.535\"]],\"st\":1}}"}
{"receive_ns":1788564461920280000,"stream":"btcusdt@depth@100ms","event_type":"depthUpdate","event_time_ms":1788564461943,"raw_json":"{\"stream\":\"btcusdt@depth@100ms\",\"data\":{\"e\":\"depthUpdate\",\"E\":1788564461943,\"T\":1788564461941,\"s\":\"BTCUSDT\",\"ps\":\"BTCUSDT\",\"U\":11478296901727,\"u\":11478296908078,\"pu\":11478296901508,\"b\":[[\"29516.80\",\"1.092\"],[\"29616.80\",\"1.008\"],[\"63773.00\",\"0.000\"],[\"71745.10\",\"0.002\"],[\"71782.00\",\"0.000\"],[\"76528.10\",\"0.002\"],[\"78496.00\",\"0.223\"],[\"78720.30\",\"4.327\"],[\"78735.30\",\"0.002\"],[\"78919.60\",\"7.929\"],[\"79073.70\",\"0.000\"],[\"79318.20\",\"3.275\"],[\"79320.20\",\"0.140\"],[\"79500.80\",\"0.000\"],[\"79501.60\",\"0.628\"],[\"79529.50\",\"0.751\"],[\"79625.50\",\"0.016\"],[\"79696.80\",\"0.324\"]],\"a\":[[\"79718.30\",\"0.028\"],[\"79720.50\",\"0.007\"],[\"79725.10\",\"0.078\"],[\"79727.80\",\"0.635\"],[\"79807.80\",\"0.500\"],[\"79866.40\",\"0.449\"],[\"79886.30\",\"0.000\"],[\"80085.60\",\"0.589\"],[\"80086.80\",\"0.016\"],[\"80115.50\",\"3.242\"],[\"80514.10\",\"5.291\"],[\"80684.20\",\"0.075\"]],\"st\":1}}"}
{"receive_ns":1788564461926465000,"stream":"btcusdt@bookTicker","event_type":"bookTicker","event_time_ms":1788564461943,"raw_json":"{\"stream\":\"btcusdt@bookTicker\",\"data\":{\"e\":\"bookTicker\",\"u\":11478296908263,\"s\":\"BTCUSDT\",\"ps\":\"BTCUSDT\",\"b\":\"79716.80\",\"B\":\"2.394\",\"a\":\"79716.90\",\"A\":\"14.965\",\"T\":1788564461943,\"E\":1788564461943,\"st\":1}}"}
{"receive_ns":1788564461926690000,"stream":"btcusdt@bookTicker","event_type":"bookTicker","event_time_ms":1788564461954,"raw_json":"{\"stream\":\"btcusdt@bookTicker\",\"data\":{\"e\":\"bookTicker\",\"u\":11478296908980,\"s\":\"BTCUSDT\",\"ps\":\"BTCUSDT\",\"b\":\"79716.80\",\"B\":\"2.484\",\"a\":\"79716.90\",\"A\":\"14.965\",\"T\":1788564461954,\"E\":1788564461954,\"st\":1}}"}
{"receive_ns":1788564461932148000,"stream":"btcusdt@bookTicker","event_type":"bookTicker","event_time_ms":1788564461956,"raw_json":"{\"stream\":\"btcusdt@bookTicker\",\"data\":{\"e\":\"bookTicker\",\"u\":11478296909055,\"s\":\"BTCUSDT\",\"ps\":\"BTCUSDT\",\"b\":\"79716.80\",\"B\":\"2.482\",\"a\":\"79716.90\",\"A\":\"14.965\",\"T\":1788564461955,\"E\":1788564461956,\"st\":1}}"}
{"receive_ns":1788564461964876000,"stream":"btcusdt@bookTicker","event_type":"bookTicker","event_time_ms":1788564461990,"raw_json":"{\"stream\":\"btcusdt@bookTicker\",\"data\":{\"e\":\"bookTicker\",\"u\":11478296910885,\"s\":\"BTCUSDT\",\"ps\":\"BTCUSDT\",\"b\":\"79716.80\",\"B\":\"2.481\",\"a\":\"79716.90\",\"A\":\"14.965\",\"T\":1788564461990,\"E\":1788564461990,\"st\":1}}"}
{"receive_ns":1788564461965119000,"stream":"btcusdt@trade","event_type":"trade","event_time_ms":1788564461990,"raw_json":"{\"stream\":\"btcusdt@trade\",\"data\":{\"e\":\"trade\",\"E\":1788564461990,\"T\":1788564461990,\"s\":\"BTCUSDT\",\"t\":8054096496,\"p\":\"79716.80\",\"q\":\"0.001\",\"X\":\"MARKET\",\"m\":true,\"st\":1}}"}
{"receive_ns":1788564461965324000,"stream":"btcusdt@bookTicker","event_type":"bookTicker","event_time_ms":1788564461991,"raw_json":"{\"stream\":\"btcusdt@bookTicker\",\"data\":{\"e\":\"bookTicker\",\"u\":11478296910964,\"s\":\"BTCUSDT\",\"ps\":\"BTCUSDT\",\"b\":\"79716.80\",\"B\":\"2.481\",\"a\":\"79716.90\",\"A\":\"14.984\",\"T\":1788564461991,\"E\":1788564461991,\"st\":1}}"}
{"receive_ns":1788564461970570000,"stream":"btcusdt@bookTicker","event_type":"bookTicker","event_time_ms":1788564461991,"raw_json":"{\"stream\":\"btcusdt@bookTicker\",\"data\":{\"e\":\"bookTicker\",\"u\":11478296911015,\"s\":\"BTCUSDT\",\"ps\":\"BTCUSDT\",\"b\":\"79716.80\",\"B\":\"2.481\",\"a\":\"79716.90\",\"A\":\"14.986\",\"T\":1788564461991,\"E\":1788564461991,\"st\":1}}"}
{"receive_ns":1788564461981995000,"stream":"btcusdt@bookTicker","event_type":"bookTicker","event_time_ms":1788564461992,"raw_json":"{\"stream\":\"btcusdt@bookTicker\",\"data\":{\"e\":\"bookTicker\",\"u\":11478296911125,\"s\":\"BTCUSDT\",\"ps\":\"BTCUSDT\",\"b\":\"79716.80\",\"B\":\"2.481\",\"a\":\"79716.90\",\"A\":\"14.967\",\"T\":1788564461992,\"E\":1788564461992,\"st\":1}}"}
{"receive_ns":1788564461988114000,"stream":"btcusdt@bookTicker","event_type":"bookTicker","event_time_ms":1788564461992,"raw_json":"{\"stream\":\"btcusdt@bookTicker\",\"data\":{\"e\":\"bookTicker\",\"u\":11478296911146,\"s\":\"BTCUSDT\",\"ps\":\"BTCUSDT\",\"b\":\"79716.80\",\"B\":\"2.481\",\"a\":\"79716.90\",\"A\":\"14.965\",\"T\":1788564461992,\"E\":1788564461992,\"st\":1}}"}
{"receive_ns":1788564461988321000,"stream":"btcusdt@bookTicker","event_type":"bookTicker","event_time_ms":1788564461992,"raw_json":"{\"stream\":\"btcusdt@bookTicker\",\"data\":{\"e\":\"bookTicker\",\"u\":11478296911150,\"s\":\"BTCUSDT\",\"ps\":\"BTCUSDT\",\"b\":\"79716.80\",\"B\":\"2.483\",\"a\":\"79716.90\",\"A\":\"14.965\",\"T\":1788564461992,\"E\":1788564461992,\"st\":1}}"}
{"receive_ns":1788564462019536000,"stream":"btcusdt@depth@100ms","event_type":"depthUpdate","event_time_ms":1788564462045,"raw_json":"{\"stream\":\"btcusdt@depth@100ms\",\"data\":{\"e\":\"depthUpdate\",\"E\":1788564462045,\"T\":1788564462042,\"s\":\"BTCUSDT\",\"ps\":\"BTCUSDT\",\"U\":11478296908263,\"u\":11478296913842,\"pu\":11478296908078,\"b\":[[\"29516.80\",\"1.267\"],[\"29616.80\",\"0.833\"],[\"63773.00\",\"0.000\"],[\"71745.10\",\"0.002\"],[\"74336.90\",\"0.002\"],[\"78058.50\",\"0.000\"],[\"78122.50\",\"0.170\"],[\"78396.90\",\"0.000\"],[\"78469.80\",\"1.144\"],[\"78760.20\",\"27.069\"],[\"78919.60\",\"7.929\"],[\"79500.80\",\"1.003\"],[\"79501.60\",\"0.859\"],[\"79507.10\",\"0.000\"],[\"79507.20\",\"6.416\"],[\"79522.20\",\"0.004\"],[\"79529.50\",\"1.929\"],[\"79531.50\",\"0.206\"],[\"79625.60\",\"3.896\"],[\"79627.50\",\"1.367\"],[\"79702.50\",\"0.005\"],[\"79714.60\",\"0.026\"],[\"79716.80\",\"2.483\"]],\"a\":[[\"79716.90\",\"14.965\"],[\"79790.30\",\"0.039\"],[\"79807.90\",\"3.301\"],[\"79866.40\",\"0.699\"],[\"79886.30\",\"0.090\"],[\"79927.50\",\"5.203\"],[\"79938.80\",\"8.425\"],[\"80085.60\",\"1.157\"],[\"80086.80\",\"0.778\"],[\"80514.10\",\"5.291\"],[\"80673.50\",\"26.239\"]],\"st\":1}}"}
{"receive_ns":1788564462019813000,"stream":"btcusdt@bookTicker","event_type":"bookTicker","event_time_ms":1788564462049,"raw_json":"{\"stream\":\"btcusdt@bookTicker\",\"data\":{\"e\":\"bookTicker\",\"u\":11478296914176,\"s\":\"BTCUSDT\",\"ps\":\"BTCUSDT\",\"b\":\"79716.80\",\"B\":\"2.433\",\"a\":\"79716.90\",\"A\":\"14.965\",\"T\":1788564462049,\"E\":1788564462049,\"st\":1}}"}
{"receive_ns":1788564462025310000,"stream":"btcusdt@trade","event_type":"trade","event_time_ms":1788564462049,"raw_json":"{\"stream\":\"btcusdt@trade\",\"data\":{\"e\":\"trade\",\"E\":1788564462049,\"T\":1788564462049,\"s\":\"BTCUSDT\",\"t\":8054096497,\"p\":\"79716.80\",\"q\":\"0.050\",\"X\":\"MARKET\",\"m\":true,\"st\":1}}"}
{"receive_ns":1788564462030748000,"stream":"btcusdt@bookTicker","event_type":"bookTicker","event_time_ms":1788564462050,"raw_json":"{\"stream\":\"btcusdt@bookTicker\",\"data\":{\"e\":\"bookTicker\",\"u\":11478296914309,\"s\":\"BTCUSDT\",\"ps\":\"BTCUSDT\",\"b\":\"79716.80\",\"B\":\"2.433\",\"a\":\"79716.90\",\"A\":\"14.984\",\"T\":1788564462050,\"E\":1788564462050,\"st\":1}}"}
{"receive_ns":1788564462030963000,"stream":"btcusdt@bookTicker","event_type":"bookTicker","event_time_ms":1788564462050,"raw_json":"{\"stream\":\"btcusdt@bookTicker\",\"data\":{\"e\":\"bookTicker\",\"u\":11478296914313,\"s\":\"BTCUSDT\",\"ps\":\"BTCUSDT\",\"b\":\"79716.80\",\"B\":\"2.433\",\"a\":\"79716.90\",\"A\":\"14.986\",\"T\":1788564462050,\"E\":1788564462050,\"st\":1}}"}
{"receive_ns":1788564462037576000,"stream":"btcusdt@bookTicker","event_type":"bookTicker","event_time_ms":1788564462051,"raw_json":"{\"stream\":\"btcusdt@bookTicker\",\"data\":{\"e\":\"bookTicker\",\"u\":11478296914460,\"s\":\"BTCUSDT\",\"ps\":\"BTCUSDT\",\"b\":\"79716.80\",\"B\":\"2.433\",\"a\":\"79716.90\",\"A\":\"14.967\",\"T\":1788564462051,\"E\":1788564462051,\"st\":1}}"}
{"receive_ns":1788564462037772000,"stream":"btcusdt@bookTicker","event_type":"bookTicker","event_time_ms":1788564462051,"raw_json":"{\"stream\":\"btcusdt@bookTicker\",\"data\":{\"e\":\"bookTicker\",\"u\":11478296914463,\"s\":\"BTCUSDT\",\"ps\":\"BTCUSDT\",\"b\":\"79716.80\",\"B\":\"2.433\",\"a\":\"79716.90\",\"A\":\"14.965\",\"T\":1788564462051,\"E\":1788564462051,\"st\":1}}"}
{"receive_ns":1788564462064169000,"stream":"btcusdt@bookTicker","event_type":"bookTicker","event_time_ms":1788564462088,"raw_json":"{\"stream\":\"btcusdt@bookTicker\",\"data\":{\"e\":\"bookTicker\",\"u\":11478296916844,\"s\":\"BTCUSDT\",\"ps\":\"BTCUSDT\",\"b\":\"79716.80\",\"B\":\"2.433\",\"a\":\"79716.90\",\"A\":\"14.984\",\"T\":1788564462087,\"E\":1788564462088,\"st\":1}}"}
{"receive_ns":1788564462064393000,"stream":"btcusdt@bookTicker","event_type":"bookTicker","event_time_ms":1788564462088,"raw_json":"{\"stream\":\"btcusdt@bookTicker\",\"data\":{\"e\":\"bookTicker\",\"u\":11478296916849,\"s\":\"BTCUSDT\",\"ps\":\"BTCUSDT\",\"b\":\"79716.80\",\"B\":\"2.433\",\"a\":\"79716.90\",\"A\":\"14.986\",\"T\":1788564462087,\"E\":1788564462088,\"st\":1}}"}
{"receive_ns":1788564462070997000,"stream":"btcusdt@bookTicker","event_type":"bookTicker","event_time_ms":1788564462088,"raw_json":"{\"stream\":\"btcusdt@bookTicker\",\"data\":{\"e\":\"bookTicker\",\"u\":11478296916944,\"s\":\"BTCUSDT\",\"ps\":\"BTCUSDT\",\"b\":\"79716.80\",\"B\":\"2.433\",\"a\":\"79716.90\",\"A\":\"14.967\",\"T\":1788564462088,\"E\":1788564462088,\"st\":1}}"}
{"receive_ns":1788564462071188000,"stream":"btcusdt@bookTicker","event_type":"bookTicker","event_time_ms":1788564462088,"raw_json":"{\"stream\":\"btcusdt@bookTicker\",\"data\":{\"e\":\"bookTicker\",\"u\":11478296916945,\"s\":\"BTCUSDT\",\"ps\":\"BTCUSDT\",\"b\":\"79716.80\",\"B\":\"2.433\",\"a\":\"79716.90\",\"A\":\"14.965\",\"T\":1788564462088,\"E\":1788564462088,\"st\":1}}"}
{"receive_ns":1788564462097341000,"stream":"btcusdt@bookTicker","event_type":"bookTicker","event_time_ms":1788564462116,"raw_json":"{\"stream\":\"btcusdt@bookTicker\",\"data\":{\"e\":\"bookTicker\",\"u\":11478296918506,\"s\":\"BTCUSDT\",\"ps\":\"BTCUSDT\",\"b\":\"79716.80\",\"B\":\"2.433\",\"a\":\"79716.90\",\"A\":\"14.984\",\"T\":1788564462115,\"E\":1788564462116,\"st\":1}}"}
{"receive_ns":1788564462097553000,"stream":"btcusdt@bookTicker","event_type":"bookTicker","event_time_ms":1788564462116,"raw_json":"{\"stream\":\"btcusdt@bookTicker\",\"data\":{\"e\":\"bookTicker\",\"u\":11478296918529,\"s\":\"BTCUSDT\",\"ps\":\"BTCUSDT\",\"b\":\"79716.80\",\"B\":\"2.433\",\"a\":\"79716.90\",\"A\":\"14.986\",\"T\":1788564462115,\"E\":1788564462116,\"st\":1}}"}
{"receive_ns":1788564462103048000,"stream":"btcusdt@bookTicker","event_type":"bookTicker","event_time_ms":1788564462116,"raw_json":"{\"stream\":\"btcusdt@bookTicker\",\"data\":{\"e\":\"bookTicker\",\"u\":11478296918580,\"s\":\"BTCUSDT\",\"ps\":\"BTCUSDT\",\"b\":\"79716.80\",\"B\":\"2.433\",\"a\":\"79716.90\",\"A\":\"14.967\",\"T\":1788564462116,\"E\":1788564462116,\"st\":1}}"}
{"receive_ns":1788564462115211000,"stream":"btcusdt@bookTicker","event_type":"bookTicker","event_time_ms":1788564462118,"raw_json":"{\"stream\":\"btcusdt@bookTicker\",\"data\":{\"e\":\"bookTicker\",\"u\":11478296918695,\"s\":\"BTCUSDT\",\"ps\":\"BTCUSDT\",\"b\":\"79716.80\",\"B\":\"2.433\",\"a\":\"79716.90\",\"A\":\"14.965\",\"T\":1788564462118,\"E\":1788564462118,\"st\":1}}"}
{"receive_ns":1788564462124909000,"stream":"btcusdt@bookTicker","event_type":"bookTicker","event_time_ms":1788564462142,"raw_json":"{\"stream\":\"btcusdt@bookTicker\",\"data\":{\"e\":\"bookTicker\",\"u\":11478296919738,\"s\":\"BTCUSDT\",\"ps\":\"BTCUSDT\",\"b\":\"79716.80\",\"B\":\"2.433\",\"a\":\"79716.90\",\"A\":\"14.984\",\"T\":1788564462142,\"E\":1788564462142,\"st\":1}}"}
{"receive_ns":1788564462131528000,"stream":"btcusdt@bookTicker","event_type":"bookTicker","event_time_ms":1788564462142,"raw_json":"{\"stream\":\"btcusdt@bookTicker\",\"data\":{\"e\":\"bookTicker\",\"u\":11478296919771,\"s\":\"BTCUSDT\",\"ps\":\"BTCUSDT\",\"b\":\"79716.80\",\"B\":\"2.433\",\"a\":\"79716.90\",\"A\":\"14.965\",\"T\":1788564462142,\"E\":1788564462142,\"st\":1}}"}
{"receive_ns":1788564462138315000,"stream":"btcusdt@depth@100ms","event_type":"depthUpdate","event_time_ms":1788564462147,"raw_json":"{\"stream\":\"btcusdt@depth@100ms\",\"data\":{\"e\":\"depthUpdate\",\"E\":1788564462147,\"T\":1788564462146,\"s\":\"BTCUSDT\",\"ps\":\"BTCUSDT\",\"U\":11478296914025,\"u\":11478296920004,\"pu\":11478296913842,\"b\":[[\"1000.00\",\"24.754\"],[\"29516.80\",\"1.449\"],[\"29616.80\",\"0.651\"],[\"63773.00\",\"0.000\"],[\"71745.10\",\"0.002\"],[\"76528.10\",\"0.000\"],[\"78919.60\",\"7.929\"],[\"79318.20\",\"3.275\"],[\"79320.20\",\"0.140\"],[\"79414.10\",\"1.670\"],[\"79414.80\",\"0.642\"],[\"79529.50\",\"1.929\"],[\"79594.50\",\"0.000\"],[\"79665.70\",\"0.008\"],[\"79688.90\",\"0.000\"],[\"79690.90\",\"0.452\"],[\"79695.10\",\"0.001\"],[\"79697.30\",\"0.539\"],[\"79701.90\",\"0.001\"],[\"79702.50\",\"0.000\"],[\"79712.30\",\"0.002\"],[\"79714.30\",\"0.530\"],[\"79714.50\",\"0.027\"],[\"79714.60\",\"0.000\"],[\"79715.90\",\"0.000\"],[\"79716.00\",\"0.003\"],[\"79716.40\",\"0.004\"],[\"79716.50\",\"0.315\"],[\"79716.80\",\"2.433\"]],\"a\":[[\"79716.90\",\"14.965\"],[\"79739.40\",\"0.078\"],[\"79740.50\",\"0.460\"],[\"79792.60\",\"0.252\"],[\"79840.20\",\"0.001\"],[\"79866.40\",\"0.449\"],[\"79952.30\",\"1.950\"],[\"79952.40\",\"0.003\"],[\"80085.60\",\"1.157\"],[\"80514.10\",\"5.291\"],[\"80742.50\",\"1.004\"],[\"87688.60\",\"0.000\"]],\"st\":1}}"}
{"receive_ns":1788564462176543000,"stream":"btcusdt@bookTicker","event_type":"bookTicker","event_time_ms":1788564462200,"raw_json":"{\"stream\":\"btcusdt@bookTicker\",\"data\":{\"e\":\"bookTicker\",\"u\":11478296922962,\"s\":\"BTCUSDT\",\"ps\":\"BTCUSDT\",\"b\":\"79716.80\",\"B\":\"2.433\",\"a\":\"79716.90\",\"A\":\"14.952\",\"T\":1788564462200,\"E\":1788564462200,\"st\":1}}"}
{"receive_ns":1788564462182229000,"stream":"btcusdt@bookTicker","event_type":"bookTicker","event_time_ms":1788564462203,"raw_json":"{\"stream\":\"btcusdt@bookTicker\",\"data\":{\"e\":\"bookTicker\",\"u\":11478296923218,\"s\":\"BTCUSDT\",\"ps\":\"BTCUSDT\",\"b\":\"79716.80\",\"B\":\"2.433\",\"a\":\"79716.90\",\"A\":\"14.964\",\"T\":1788564462203,\"E\":1788564462203,\"st\":1}}"}
{"receive_ns":1788564462193184000,"stream":"btcusdt@bookTicker","event_type":"bookTicker","event_time_ms":1788564462213,"raw_json":"{\"stream\":\"btcusdt@bookTicker\",\"data\":{\"e\":\"bookTicker\",\"u\":11478296923833,\"s\":\"BTCUSDT\",\"ps\":\"BTCUSDT\",\"b\":\"79716.80\",\"B\":\"2.433\",\"a\":\"79716.90\",\"A\":\"14.965\",\"T\":1788564462213,\"E\":1788564462213,\"st\":1}}"}
{"receive_ns":1788564462214758000,"stream":"btcusdt@bookTicker","event_type":"bookTicker","event_time_ms":1788564462241,"raw_json":"{\"stream\":\"btcusdt@bookTicker\",\"data\":{\"e\":\"bookTicker\",\"u\":11478296925267,\"s\":\"BTCUSDT\",\"ps\":\"BTCUSDT\",\"b\":\"79716.80\",\"B\":\"2.433\",\"a\":\"79716.90\",\"A\":\"14.984\",\"T\":1788564462241,\"E\":1788564462241,\"st\":1}}"}
{"receive_ns":1788564462220887000,"stream":"btcusdt@bookTicker","event_type":"bookTicker","event_time_ms":1788564462242,"raw_json":"{\"stream\":\"btcusdt@bookTicker\",\"data\":{\"e\":\"bookTicker\",\"u\":11478296925348,\"s\":\"BTCUSDT\",\"ps\":\"BTCUSDT\",\"b\":\"79716.80\",\"B\":\"2.433\",\"a\":\"79716.90\",\"A\":\"14.965\",\"T\":1788564462242,\"E\":1788564462242,\"st\":1}}"}
{"receive_ns":1788564462221100000,"stream":"btcusdt@bookTicker","event_type":"bookTicker","event_time_ms":1788564462242,"raw_json":"{\"stream\":\"btcusdt@bookTicker\",\"data\":{\"e\":\"bookTicker\",\"u\":11478296925404,\"s\":\"BTCUSDT\",\"ps\":\"BTCUSDT\",\"b\":\"79716.80\",\"B\":\"2.433\",\"a\":\"79716.90\",\"A\":\"14.964\",\"T\":1788564462242,\"E\":1788564462242,\"st\":1}}"}
{"receive_ns":1788564462226723000,"stream":"btcusdt@depth@100ms","event_type":"depthUpdate","event_time_ms":1788564462249,"raw_json":"{\"stream\":\"btcusdt@depth@100ms\",\"data\":{\"e\":\"depthUpdate\",\"E\":1788564462249,\"T\":1788564462246,\"s\":\"BTCUSDT\",\"ps\":\"BTCUSDT\",\"U\":11478296920009,\"u\":11478296925677,\"pu\":11478296920004,\"b\":[[\"29516.80\",\"1.624\"],[\"29616.80\",\"0.476\"],[\"71745.10\",\"0.002\"],[\"76528.10\",\"0.002\"],[\"78488.30\",\"4.996\"],[\"78919.60\",\"7.929\"],[\"79075.30\",\"2.150\"],[\"79497.60\",\"0.733\"],[\"79500.80\",\"1.003\"],[\"79501.60\",\"1.631\"],[\"79522.20\",\"0.036\"],[\"79529.50\",\"0.425\"],[\"79531.50\",\"0.006\"],[\"79594.50\",\"0.659\"],[\"79689.40\",\"0.454\"],[\"79690.90\",\"0.001\"],[\"79693.40\",\"0.059\"],[\"79694.30\",\"0.373\"],[\"79695.50\",\"0.001\"],[\"79696.50\",\"0.800\"],[\"79697.30\",\"0.100\"],[\"79699.20\",\"0.003\"],[\"79699.30\",\"0.003\"],[\"79700.80\",\"0.001\"],[\"79705.50\",\"0.403\"],[\"79714.30\",\"0.504\"],[\"79714.50\",\"0.001\"]],\"a\":[[\"79716.90\",\"14.964\"],[\"79732.60\",\"0.501\"],[\"79734.30\",\"0.003\"],[\"79734.60\",\"0.002\"],[\"79735.40\",\"0.372\"],[\"79792.60\",\"0.502\"],[\"79840.20\",\"0.351\"],[\"79866.40\",\"0.000\"],[\"79886.30\",\"0.090\"],[\"80085.60\",\"0.739\"],[\"80086.80\",\"0.778\"],[\"80514.10\",\"5.291\"]],\"st\":1}}"}
{"receive_ns":1788564462291942000,"stream":"btcusdt@bookTicker","event_type":"bookTicker","event_time_ms":1788564462311,"raw_json":"{\"stream\":\"btcusdt@bookTicker\",\"data\":{\"e\":\"bookTicker\",\"u\":11478296929268,\"s\":\"BTCUSDT\",\"ps\":\"BTCUSDT\",\"b\":\"79716.80\",\"B\":\"2.322\",\"a\":\"79716.90\",\"A\":\"14.964\",\"T\":1788564462311,\"E\":1788564462311,\"st\":1}}"}
{"receive_ns":1788564462303857000,"stream":"btcusdt@bookTicker","event_type":"bookTicker","event_time_ms":1788564462324,"raw_json":"{\"stream\":\"btcusdt@bookTicker\",\"data\":{\"e\":\"bookTicker\",\"u\":11478296930067,\"s\":\"BTCUSDT\",\"ps\":\"BTCUSDT\",\"b\":\"79716.80\",\"B\":\"2.433\",\"a\":\"79716.90\",\"A\":\"14.964\",\"T\":1788564462324,\"E\":1788564462324,\"st\":1}}"}
{"receive_ns":1788564462316341000,"stream":"btcusdt@bookTicker","event_type":"bookTicker","event_time_ms":1788564462326,"raw_json":"{\"stream\":\"btcusdt@bookTicker\",\"data\":{\"e\":\"bookTicker\",\"u\":11478296930136,\"s\":\"BTCUSDT\",\"ps\":\"BTCUSDT\",\"b\":\"79716.80\",\"B\":\"2.433\",\"a\":\"79716.90\",\"A\":\"14.965\",\"T\":1788564462325,\"E\":1788564462326,\"st\":1}}"}
{"receive_ns":1788564462330423000,"stream":"btcusdt@depth@100ms","event_type":"depthUpdate","event_time_ms":1788564462351,"raw_json":"{\"stream\":\"btcusdt@depth@100ms\",\"data\":{\"e\":\"depthUpdate\",\"E\":1788564462351,\"T\":1788564462350,\"s\":\"BTCUSDT\",\"ps\":\"BTCUSDT\",\"U\":11478296925807,\"u\":11478296931360,\"pu\":11478296925677,\"b\":[[\"1000.00\",\"24.904\"],[\"29416.80\",\"0.021\"],[\"29516.80\",\"1.764\"],[\"29616.80\",\"0.315\"],[\"63773.40\",\"0.000\"],[\"71745.10\",\"0.002\"],[\"76528.10\",\"0.000\"],[\"78122.50\",\"0.173\"],[\"78720.30\",\"4.517\"],[\"78736.50\",\"1.670\"],[\"78919.60\",\"7.929\"],[\"79079.10\",\"5.682\"],[\"79320.20\",\"0.140\"],[\"79501.60\",\"1.831\"],[\"79522.20\",\"0.036\"],[\"79529.50\",\"0.676\"],[\"79699.20\",\"0.382\"],[\"79701.90\",\"0.000\"],[\"79702.50\",\"0.001\"],[\"79703.50\",\"0.002\"],[\"79705.50\",\"0.024\"],[\"79716.80\",\"2.433\"]],\"a\":[[\"79716.90\",\"14.965\"],[\"79732.60\",\"0.063\"],[\"79733.60\",\"0.439\"],[\"79792.60\",\"0.701\"],[\"80085.60\",\"1.002\"],[\"80512.10\",\"0.492\"],[\"80514.10\",\"5.291\"]],\"st\":1}}"}
{"receive_ns":1788564462428966000,"stream":"btcusdt@depth@100ms","event_type":"depthUpdate","event_time_ms":1788564462453,"raw_json":"{\"stream\":\"btcusdt@depth@100ms\",\"data\":{\"e\":\"depthUpdate\",\"E\":1788564462453,\"T\":1788564462449,\"s\":\"BTCUSDT\",\"ps\":\"BTCUSDT\",\"U\":11478296931432,\"u\":11478296936782,\"pu\":11478296931360,\"b\":[[\"1000.00\",\"24.754\"],[\"29416.80\",\"0.077\"],[\"29516.80\",\"1.827\"],[\"29616.80\",\"0.196\"],[\"71745.10\",\"0.002\"],[\"75730.90\",\"0.024\"],[\"76528.10\",\"0.002\"],[\"78218.30\",\"0.002\"],[\"78225.40\",\"0.000\"],[\"78397.70\",\"1.675\"],[\"78680.50\",\"6.220\"],[\"78919.60\",\"7.929\"],[\"79318.20\",\"3.275\"],[\"79497.60\",\"0.733\"],[\"79500.80\",\"1.003\"],[\"79501.60\",\"1.931\"],[\"79522.20\",\"0.036\"],[\"79529.50\",\"0.826\"],[\"79699.20\",\"0.003\"],[\"79699.80\",\"0.035\"],[\"79701.50\",\"0.320\"],[\"79702.50\",\"0.000\"],[\"79703.50\",\"0.003\"],[\"79705.50\",\"0.403\"]],\"a\":[[\"79717.90\",\"0.006\"],[\"79718.00\",\"3.565\"],[\"79720.50\",\"0.001\"],[\"79722.10\",\"0.008\"],[\"79725.70\",\"0.000\"],[\"79726.40\",\"0.251\"],[\"79732.60\",\"0.001\"],[\"79733.70\",\"0.680\"],[\"79792.60\",\"0.701\"],[\"79886.30\",\"0.090\"],[\"80085.60\",\"1.157\"],[\"80086.80\",\"0.778\"],[\"80115.50\",\"3.241\"],[\"80514.10\",\"5.291\"],[\"80646.20\",\"9.824\"],[\"81151.80\",\"0.787\"]],\"st\":1}}"}
{"receive_ns":1788564462492012000,"stream":"btcusdt@bookTicker","event_type":"bookTicker","event_time_ms":1788564462509,"raw_json":"{\"stream\":\"btcusdt@bookTicker\",\"data\":{\"e\":\"bookTicker\",\"u\":11478296940606,\"s\":\"BTCUSDT\",\"ps\":\"BTCUSDT\",\"b\":\"79716.80\",\"B\":\"2.433\",\"a\":\"79716.90\",\"A\":\"15.148\",\"T\":1788564462509,\"E\":1788564462509,\"st\":1}}"}
{"receive_ns":1788564462503382000,"stream":"btcusdt@bookTicker","event_type":"bookTicker","event_time_ms":1788564462510,"raw_json":"{\"stream\":\"btcusdt@bookTicker\",\"data\":{\"e\":\"bookTicker\",\"u\":11478296940760,\"s\":\"BTCUSDT\",\"ps\":\"BTCUSDT\",\"b\":\"79716.80\",\"B\":\"2.433\",\"a\":\"79716.90\",\"A\":\"15.147\",\"T\":1788564462510,\"E\":1788564462510,\"st\":1}}"}
{"receive_ns":1788564462519880000,"stream":"btcusdt@bookTicker","event_type":"bookTicker","event_time_ms":1788564462511,"raw_json":"{\"stream\":\"btcusdt@bookTicker\",\"data\":{\"e\":\"bookTicker\",\"u\":11478296940816,\"s\":\"BTCUSDT\",\"ps\":\"BTCUSDT\",\"b\":\"79716.80\",\"B\":\"2.453\",\"a\":\"79716.90\",\"A\":\"15.147\",\"T\":1788564462511,\"E\":1788564462511,\"st\":1}}"}
{"receive_ns":1788564462531518000,"stream":"btcusdt@bookTicker","event_type":"bookTicker","event_time_ms":1788564462512,"raw_json":"{\"stream\":\"btcusdt@bookTicker\",\"data\":{\"e\":\"bookTicker\",\"u\":11478296941001,\"s\":\"BTCUSDT\",\"ps\":\"BTCUSDT\",\"b\":\"79716.80\",\"B\":\"2.453\",\"a\":\"79716.90\",\"A\":\"15.148\",\"T\":1788564462512,\"E\":1788564462512,\"st\":1}}"}
{"receive_ns":1788564462537243000,"stream":"btcusdt@depth@100ms","event_type":"depthUpdate","event_time_ms":1788564462555,"raw_json":"{\"stream\":\"btcusdt@depth@100ms\",\"data\":{\"e\":\"depthUpdate\",\"E\":1788564462555,\"T\":1788564462554,\"s\":\"BTCUSDT\",\"ps\":\"BTCUSDT\",\"U\":11478296936994,\"u\":11478296944595,\"pu\":11478296936782,\"b\":[[\"29416.80\",\"0.140\"],[\"29516.80\",\"1.883\"],[\"29616.80\",\"0.077\"],[\"63773.00\",\"0.010\"],[\"71745.10\",\"0.002\"],[\"74221.90\",\"0.002\"],[\"75731.00\",\"0.067\"],[\"75731.10\",\"0.008\"],[\"78545.00\",\"5.662\"],[\"78919.60\",\"7.929\"],[\"79318.20\",\"3.276\"],[\"79501.60\",\"1.731\"],[\"79522.20\",\"0.004\"],[\"79529.50\",\"1.026\"],[\"79621.10\",\"0.040\"],[\"79693.10\",\"0.003\"],[\"79709.10\",\"0.001\"],[\"79716.80\",\"2.453\"]],\"a\":[[\"79716.90\",\"15.148\"],[\"79733.00\",\"0.630\"],[\"79788.70\",\"0.023\"],[\"79790.30\",\"0.025\"],[\"79792.60\",\"0.701\"],[\"80085.60\",\"1.157\"],[\"80514.10\",\"5.823\"],[\"81650.90\",\"0.000\"]],\"st\":1}}"}
{"receive_ns":1788564462541416000,"stream":"btcusdt@bookTicker","event_type":"bookTicker","event_time_ms":1788564462564,"raw_json":"{\"stream\":\"btcusdt@bookTicker\",\"data\":{\"e\":\"bookTicker\",\"u\":11478296945249,\"s\":\"BTCUSDT\",\"ps\":\"BTCUSDT\",\"b\":\"79716.80\",\"B\":\"2.433\",\"a\":\"79716.90\",\"A\":\"15.148\",\"T\":1788564462564,\"E\":1788564462564,\"st\":1}}"}
{"receive_ns":1788564462541704000,"stream":"btcusdt@bookTicker","event_type":"bookTicker","event_time_ms":1788564462568,"raw_json":"{\"stream\":\"btcusdt@bookTicker\",\"data\":{\"e\":\"bookTicker\",\"u\":11478296945536,\"s\":\"BTCUSDT\",\"ps\":\"BTCUSDT\",\"b\":\"79716.80\",\"B\":\"2.420\",\"a\":\"79716.90\",\"A\":\"15.148\",\"T\":1788564462568,\"E\":1788564462568,\"st\":1}}"}
{"receive_ns":1788564462553839000,"stream":"btcusdt@trade","event_type":"trade","event_time_ms":1788564462568,"raw_json":"{\"stream\":\"btcusdt@trade\",\"data\":{\"e\":\"trade\",\"E\":1788564462568,\"T\":1788564462568,\"s\":\"BTCUSDT\",\"t\":8054096498,\"p\":\"79716.80\",\"q\":\"0.013\",\"X\":\"MARKET\",\"m\":true,\"st\":1}}"}
{"receive_ns":1788564462564870000,"stream":"btcusdt@bookTicker","event_type":"bookTicker","event_time_ms":1788564462569,"raw_json":"{\"stream\":\"btcusdt@bookTicker\",\"data\":{\"e\":\"bookTicker\",\"u\":11478296945591,\"s\":\"BTCUSDT\",\"ps\":\"BTCUSDT\",\"b\":\"79716.80\",\"B\":\"2.420\",\"a\":\"79716.90\",\"A\":\"15.150\",\"T\":1788564462569,\"E\":1788564462569,\"st\":1}}"}
{"receive_ns":1788564462570325000,"stream":"btcusdt@bookTicker","event_type":"bookTicker","event_time_ms":1788564462569,"raw_json":"{\"stream\":\"btcusdt@bookTicker\",\"data\":{\"e\":\"bookTicker\",\"u\":11478296945594,\"s\":\"BTCUSDT\",\"ps\":\"BTCUSDT\",\"b\":\"79716.80\",\"B\":\"2.420\",\"a\":\"79716.90\",\"A\":\"15.169\",\"T\":1788564462569,\"E\":1788564462569,\"st\":1}}"}
{"receive_ns":1788564462588271000,"stream":"btcusdt@bookTicker","event_type":"bookTicker","event_time_ms":1788564462570,"raw_json":"{\"stream\":\"btcusdt@bookTicker\",\"data\":{\"e\":\"bookTicker\",\"u\":11478296945743,\"s\":\"BTCUSDT\",\"ps\":\"BTCUSDT\",\"b\":\"79716.80\",\"B\":\"2.420\",\"a\":\"79716.90\",\"A\":\"15.167\",\"T\":1788564462570,\"E\":1788564462570,\"st\":1}}"}
{"receive_ns":1788564462593785000,"stream":"btcusdt@bookTicker","event_type":"bookTicker","event_time_ms":1788564462570,"raw_json":"{\"stream\":\"btcusdt@bookTicker\",\"data\":{\"e\":\"bookTicker\",\"u\":11478296945751,\"s\":\"BTCUSDT\",\"ps\":\"BTCUSDT\",\"b\":\"79716.80\",\"B\":\"2.420\",\"a\":\"79716.90\",\"A\":\"15.148\",\"T\":1788564462570,\"E\":1788564462570,\"st\":1}}"}
{"receive_ns":1788564462609936000,"stream":"btcusdt@bookTicker","event_type":"bookTicker","event_time_ms":1788564462584,"raw_json":"{\"stream\":\"btcusdt@bookTicker\",\"data\":{\"e\":\"bookTicker\",\"u\":11478296946598,\"s\":\"BTCUSDT\",\"ps\":\"BTCUSDT\",\"b\":\"79716.80\",\"B\":\"2.420\",\"a\":\"79716.90\",\"A\":\"15.167\",\"T\":1788564462584,\"E\":1788564462584,\"st\":1}}"}
{"receive_ns":1788564462620434000,"stream":"btcusdt@bookTicker","event_type":"bookTicker","event_time_ms":1788564462584,"raw_json":"{\"stream\":\"btcusdt@bookTicker\",\"data\":{\"e\":\"bookTicker\",\"u\":11478296946609,\"s\":\"BTCUSDT\",\"ps\":\"BTCUSDT\",\"b\":\"79716.80\",\"B\":\"2.420\",\"a\":\"79716.90\",\"A\":\"15.169\",\"T\":1788564462584,\"E\":1788564462584,\"st\":1}}"}
{"receive_ns":1788564462626536000,"stream":"btcusdt@bookTicker","event_type":"bookTicker","event_time_ms":1788564462585,"raw_json":"{\"stream\":\"btcusdt@bookTicker\",\"data\":{\"e\":\"bookTicker\",\"u\":11478296946680,\"s\":\"BTCUSDT\",\"ps\":\"BTCUSDT\",\"b\":\"79716.80\",\"B\":\"2.420\",\"a\":\"79716.90\",\"A\":\"15.150\",\"T\":1788564462585,\"E\":1788564462585,\"st\":1}}"}
{"receive_ns":1788564462632180000,"stream":"btcusdt@bookTicker","event_type":"bookTicker","event_time_ms":1788564462585,"raw_json":"{\"stream\":\"btcusdt@bookTicker\",\"data\":{\"e\":\"bookTicker\",\"u\":11478296946695,\"s\":\"BTCUSDT\",\"ps\":\"BTCUSDT\",\"b\":\"79716.80\",\"B\":\"2.420\",\"a\":\"79716.90\",\"A\":\"15.148\",\"T\":1788564462585,\"E\":1788564462585,\"st\":1}}"}
{"receive_ns":1788564462638064000,"stream":"btcusdt@bookTicker","event_type":"bookTicker","event_time_ms":1788564462598,"raw_json":"{\"stream\":\"btcusdt@bookTicker\",\"data\":{\"e\":\"bookTicker\",\"u\":11478296947391,\"s\":\"BTCUSDT\",\"ps\":\"BTCUSDT\",\"b\":\"79716.80\",\"B\":\"2.420\",\"a\":\"79716.90\",\"A\":\"15.141\",\"T\":1788564462598,\"E\":1788564462598,\"st\":1}}"}
{"receive_ns":1788564462638281000,"stream":"btcusdt@trade","event_type":"trade","event_time_ms":1788564462598,"raw_json":"{\"stream\":\"btcusdt@trade\",\"data\":{\"e\":\"trade\",\"E\":1788564462598,\"T\":1788564462598,\"s\":\"BTCUSDT\",\"t\":8054096499,\"p\":\"79716.90\",\"q\":\"0.007\",\"X\":\"MARKET\",\"m\":false,\"st\":1}}"}
{"receive_ns":1788564462649031000,"stream":"btcusdt@bookTicker","event_type":"bookTicker","event_time_ms":1788564462599,"raw_json":"{\"stream\":\"btcusdt@bookTicker\",\"data\":{\"e\":\"bookTicker\",\"u\":11478296947465,\"s\":\"BTCUSDT\",\"ps\":\"BTCUSDT\",\"b\":\"79716.80\",\"B\":\"2.420\",\"a\":\"79716.90\",\"A\":\"15.160\",\"T\":1788564462599,\"E\":1788564462599,\"st\":1}}"}
{"receive_ns":1788564462649260000,"stream":"btcusdt@bookTicker","event_type":"bookTicker","event_time_ms":1788564462599,"raw_json":"{\"stream\":\"btcusdt@bookTicker\",\"data\":{\"e\":\"bookTicker\",\"u\":11478296947485,\"s\":\"BTCUSDT\",\"ps\":\"BTCUSDT\",\"b\":\"79716.80\",\"B\":\"2.420\",\"a\":\"79716.90\",\"A\":\"15.162\",\"T\":1788564462599,\"E\":1788564462599,\"st\":1}}"}
{"receive_ns":1788564462650578000,"stream":"btcusdt@bookTicker","event_type":"bookTicker","event_time_ms":1788564462600,"raw_json":"{\"stream\":\"btcusdt@bookTicker\",\"data\":{\"e\":\"bookTicker\",\"u\":11478296947590,\"s\":\"BTCUSDT\",\"ps\":\"BTCUSDT\",\"b\":\"79716.80\",\"B\":\"2.420\",\"a\":\"79716.90\",\"A\":\"15.160\",\"T\":1788564462600,\"E\":1788564462600,\"st\":1}}"}
{"receive_ns":1788564462656022000,"stream":"btcusdt@bookTicker","event_type":"bookTicker","event_time_ms":1788564462600,"raw_json":"{\"stream\":\"btcusdt@bookTicker\",\"data\":{\"e\":\"bookTicker\",\"u\":11478296947605,\"s\":\"BTCUSDT\",\"ps\":\"BTCUSDT\",\"b\":\"79716.80\",\"B\":\"2.420\",\"a\":\"79716.90\",\"A\":\"15.141\",\"T\":1788564462600,\"E\":1788564462600,\"st\":1}}"}
{"receive_ns":1788564462673125000,"stream":"btcusdt@bookTicker","event_type":"bookTicker","event_time_ms":1788564462607,"raw_json":"{\"stream\":\"btcusdt@bookTicker\",\"data\":{\"e\":\"bookTicker\",\"u\":11478296948067,\"s\":\"BTCUSDT\",\"ps\":\"BTCUSDT\",\"b\":\"79716.80\",\"B\":\"2.420\",\"a\":\"79716.90\",\"A\":\"15.129\",\"T\":1788564462607,\"E\":1788564462607,\"st\":1}}"}
{"receive_ns":1788564462684559000,"stream":"btcusdt@bookTicker","event_type":"bookTicker","event_time_ms":1788564462610,"raw_json":"{\"stream\":\"btcusdt@bookTicker\",\"data\":{\"e\":\"bookTicker\",\"u\":11478296948233,\"s\":\"BTCUSDT\",\"ps\":\"BTCUSDT\",\"b\":\"79716.80\",\"B\":\"2.420\",\"a\":\"79716.90\",\"A\":\"15.136\",\"T\":1788564462610,\"E\":1788564462610,\"st\":1}}"}
{"receive_ns":1788564462690154000,"stream":"btcusdt@bookTicker","event_type":"bookTicker","event_time_ms":1788564462612,"raw_json":"{\"stream\":\"btcusdt@bookTicker\",\"data\":{\"e\":\"bookTicker\",\"u\":11478296948354,\"s\":\"BTCUSDT\",\"ps\":\"BTCUSDT\",\"b\":\"79716.80\",\"B\":\"2.420\",\"a\":\"79716.90\",\"A\":\"15.155\",\"T\":1788564462611,\"E\":1788564462612,\"st\":1}}"}
{"receive_ns":1788564462690405000,"stream":"btcusdt@bookTicker","event_type":"bookTicker","event_time_ms":1788564462612,"raw_json":"{\"stream\":\"btcusdt@bookTicker\",\"data\":{\"e\":\"bookTicker\",\"u\":11478296948376,\"s\":\"BTCUSDT\",\"ps\":\"BTCUSDT\",\"b\":\"79716.80\",\"B\":\"2.420\",\"a\":\"79716.90\",\"A\":\"15.157\",\"T\":1788564462611,\"E\":1788564462612,\"st\":1}}"}
{"receive_ns":1788564462690656000,"stream":"btcusdt@bookTicker","event_type":"bookTicker","event_time_ms":1788564462612,"raw_json":"{\"stream\":\"btcusdt@bookTicker\",\"data\":{\"e\":\"bookTicker\",\"u\":11478296948433,\"s\":\"BTCUSDT\",\"ps\":\"BTCUSDT\",\"b\":\"79716.80\",\"B\":\"2.420\",\"a\":\"79716.90\",\"A\":\"15.138\",\"T\":1788564462612,\"E\":1788564462612,\"st\":1}}"}
{"receive_ns":1788564462690824000,"stream":"btcusdt@bookTicker","event_type":"bookTicker","event_time_ms":1788564462612,"raw_json":"{\"stream\":\"btcusdt@bookTicker\",\"data\":{\"e\":\"bookTicker\",\"u\":11478296948441,\"s\":\"BTCUSDT\",\"ps\":\"BTCUSDT\",\"b\":\"79716.80\",\"B\":\"2.420\",\"a\":\"79716.90\",\"A\":\"15.136\",\"T\":1788564462612,\"E\":1788564462612,\"st\":1}}"}
{"receive_ns":1788564462702112000,"stream":"btcusdt@bookTicker","event_type":"bookTicker","event_time_ms":1788564462638,"raw_json":"{\"stream\":\"btcusdt@bookTicker\",\"data\":{\"e\":\"bookTicker\",\"u\":11478296949857,\"s\":\"BTCUSDT\",\"ps\":\"BTCUSDT\",\"b\":\"79716.80\",\"B\":\"2.420\",\"a\":\"79716.90\",\"A\":\"15.155\",\"T\":1788564462637,\"E\":1788564462638,\"st\":1}}"}
{"receive_ns":1788564462708467000,"stream":"btcusdt@bookTicker","event_type":"bookTicker","event_time_ms":1788564462638,"raw_json":"{\"stream\":\"btcusdt@bookTicker\",\"data\":{\"e\":\"bookTicker\",\"u\":11478296949862,\"s\":\"BTCUSDT\",\"ps\":\"BTCUSDT\",\"b\":\"79716.80\",\"B\":\"2.420\",\"a\":\"79716.90\",\"A\":\"15.157\",\"T\":1788564462637,\"E\":1788564462638,\"st\":1}}"}
{"receive_ns":1788564462714051000,"stream":"btcusdt@bookTicker","event_type":"bookTicker","event_time_ms":1788564462638,"raw_json":"{\"stream\":\"btcusdt@bookTicker\",\"data\":{\"e\":\"bookTicker\",\"u\":11478296949917,\"s\":\"BTCUSDT\",\"ps\":\"BTCUSDT\",\"b\":\"79716.80\",\"B\":\"2.420\",\"a\":\"79716.90\",\"A\":\"15.155\",\"T\":1788564462638,\"E\":1788564462638,\"st\":1}}"}
{"receive_ns":1788564462720690000,"stream":"btcusdt@bookTicker","event_type":"bookTicker","event_time_ms":1788564462639,"raw_json":"{\"stream\":\"btcusdt@bookTicker\",\"data\":{\"e\":\"bookTicker\",\"u\":11478296949930,\"s\":\"BTCUSDT\",\"ps\":\"BTCUSDT\",\"b\":\"79716.80\",\"B\":\"2.420\",\"a\":\"79716.90\",\"A\":\"15.136\",\"T\":1788564462639,\"E\":1788564462639,\"st\":1}}"}
{"receive_ns":1788564462726724000,"stream":"btcusdt@depth@100ms","event_type":"depthUpdate","event_time_ms":1788564462657,"raw_json":"{\"stream\":\"btcusdt@depth@100ms\",\"data\":{\"e\":\"depthUpdate\",\"E\":1788564462657,\"T\":1788564462654,\"s\":\"BTCUSDT\",\"ps\":\"BTCUSDT\",\"U\":11478296944716,\"u\":11478296950736,\"pu\":11478296944595,\"b\":[[\"1000.00\",\"24.754\"],[\"29416.80\",\"0.238\"],[\"29516.80\",\"1.862\"],[\"29616.80\",\"0.000\"],[\"63773.00\",\"0.000\"],[\"71745.10\",\"0.002\"],[\"76528.10\",\"0.000\"],[\"78122.50\",\"0.167\"],[\"78919.60\",\"7.929\"],[\"79320.20\",\"0.140\"],[\"79522.20\",\"0.004\"],[\"79529.50\",\"1.026\"],[\"79699.20\",\"0.382\"],[\"79702.50\",\"0.001\"],[\"79703.50\",\"0.002\"],[\"79703.60\",\"0.255\"],[\"79703.70\",\"0.080\"],[\"79705.50\",\"0.024\"],[\"79715.20\",\"0.028\"],[\"79715.90\",\"0.002\"],[\"79716.20\",\"0.315\"],[\"79716.30\",\"0.003\"],[\"79716.40\",\"0.001\"],[\"79716.50\",\"0.000\"],[\"79716.80\",\"2.420\"]],\"a\":[[\"79716.90\",\"15.136\"],[\"79790.30\",\"0.039\"],[\"79792.60\",\"0.701\"],[\"80000.00\",\"74.945\"],[\"80085.60\",\"1.157\"],[\"80514.10\",\"5.823\"],[\"80713.40\",\"7.406\"]],\"st\":1}}"}
{"receive_ns":1788564462732359000,"stream":"btcusdt@bookTicker","event_type":"bookTicker","event_time_ms":1788564462668,"raw_json":"{\"stream\":\"btcusdt@bookTicker\",\"data\":{\"e\":\"bookTicker\",\"u\":11478296951430,\"s\":\"BTCUSDT\",\"ps\":\"BTCUSDT\",\"b\":\"79716.80\",\"B\":\"2.420\",\"a\":\"79716.90\",\"A\":\"15.155\",\"T\":1788564462668,\"E\":1788564462668,\"st\":1}}"}
{"receive_ns":1788564462732804000,"stream":"btcusdt@bookTicker","event_type":"bookTicker","event_time_ms":1788564462669,"raw_json":"{\"stream\":\"btcusdt@bookTicker\",\"data\":{\"e\":\"bookTicker\",\"u\":11478296951512,\"s\":\"BTCUSDT\",\"ps\":\"BTCUSDT\",\"b\":\"79716.80\",\"B\":\"2.420\",\"a\":\"79716.90\",\"A\":\"15.136\",\"T\":1788564462668,\"E\":1788564462669,\"st\":1}}"}
{"receive_ns":1788564462739456000,"stream":"btcusdt@bookTicker","event_type":"bookTicker","event_time_ms":1788564462679,"raw_json":"{\"stream\":\"btcusdt@bookTicker\",\"data\":{\"e\":\"bookTicker\",\"u\":11478296951994,\"s\":\"BTCUSDT\",\"ps\":\"BTCUSDT\",\"b\":\"79716.80\",\"B\":\"2.420\",\"a\":\"79716.90\",\"A\":\"15.138\",\"T\":1788564462679,\"E\":1788564462679,\"st\":1}}"}
{"receive_ns":1788564462750128000,"stream":"btcusdt@bookTicker","event_type":"bookTicker","event_time_ms":1788564462686,"raw_json":"{\"stream\":\"btcusdt@bookTicker\",\"data\":{\"e\":\"bookTicker\",\"u\":11478296952373,\"s\":\"BTCUSDT\",\"ps\":\"BTCUSDT\",\"b\":\"79716.80\",\"B\":\"2.420\",\"a\":\"79716.90\",\"A\":\"15.157\",\"T\":1788564462686,\"E\":1788564462686,\"st\":1}}"}
{"receive_ns":1788564462767247000,"stream":"btcusdt@bookTicker","event_type":"bookTicker","event_time_ms":1788564462686,"raw_json":"{\"stream\":\"btcusdt@bookTicker\",\"data\":{\"e\":\"bookTicker\",\"u\":11478296952448,\"s\":\"BTCUSDT\",\"ps\":\"BTCUSDT\",\"b\":\"79716.80\",\"B\":\"2.420\",\"a\":\"79716.90\",\"A\":\"15.138\",\"T\":1788564462686,\"E\":1788564462686,\"st\":1}}"}
{"receive_ns":1788564462781665000,"stream":"btcusdt@bookTicker","event_type":"bookTicker","event_time_ms":1788564462746,"raw_json":"{\"stream\":\"btcusdt@bookTicker\",\"data\":{\"e\":\"bookTicker\",\"u\":11478296956052,\"s\":\"BTCUSDT\",\"ps\":\"BTCUSDT\",\"b\":\"79716.80\",\"B\":\"2.420\",\"a\":\"79716.90\",\"A\":\"15.137\",\"T\":1788564462746,\"E\":1788564462746,\"st\":1}}"}
{"receive_ns":1788564462793484000,"stream":"btcusdt@bookTicker","event_type":"bookTicker","event_time_ms":1788564462758,"raw_json":"{\"stream\":\"btcusdt@bookTicker\",\"data\":{\"e\":\"bookTicker\",\"u\":11478296956793,\"s\":\"BTCUSDT\",\"ps\":\"BTCUSDT\",\"b\":\"79716.80\",\"B\":\"2.420\",\"a\":\"79716.90\",\"A\":\"15.139\",\"T\":1788564462758,\"E\":1788564462758,\"st\":1}}"}
{"receive_ns":1788564462810360000,"stream":"btcusdt@depth@100ms","event_type":"depthUpdate","event_time_ms":1788564462759,"raw_json":"{\"stream\":\"btcusdt@depth@100ms\",\"data\":{\"e\":\"depthUpdate\",\"E\":1788564462759,\"T\":1788564462758,\"s\":\"BTCUSDT\",\"ps\":\"BTCUSDT\",\"U\":11478296950907,\"u\":11478296956793,\"pu\":11478296950736,\"b\":[[\"1000.00\",\"24.754\"],[\"29416.80\",\"0.420\"],[\"29516.80\",\"1.680\"],[\"71745.10\",\"0.002\"],[\"76528.10\",\"0.002\"],[\"78274.70\",\"3.444\"],[\"78919.60\",\"7.929\"],[\"79318.20\",\"3.286\"],[\"79497.60\",\"0.733\"],[\"79500.80\",\"1.003\"],[\"79501.60\",\"1.731\"],[\"79522.20\",\"0.036\"],[\"79529.50\",\"0.826\"],[\"79621.10\",\"0.040\"],[\"79645.00\",\"0.002\"]],\"a\":[[\"79716.90\",\"15.139\"],[\"79742.50\",\"2.024\"],[\"79754.20\",\"0.002\"],[\"79772.80\",\"0.316\"],[\"79788.70\",\"0.021\"],[\"79792.60\",\"0.502\"],[\"79886.30\",\"0.090\"],[\"80085.60\",\"1.157\"],[\"80086.80\",\"0.778\"],[\"80514.10\",\"5.823\"],[\"80766.70\",\"9.835\"]],\"st\":1}}"}
{"receive_ns":1788564462816756000,"stream":"btcusdt@bookTicker","event_type":"bookTicker","event_time_ms":1788564462794,"raw_json":"{\"stream\":\"btcusdt@bookTicker\",\"data\":{\"e\":\"bookTicker\",\"u\":11478296959192,\"s\":\"BTCUSDT\",\"ps\":\"BTCUSDT\",\"b\":\"79716.80\",\"B\":\"2.397\",\"a\":\"79716.90\",\"A\":\"15.139\",\"T\":1788564462794,\"E\":1788564462794,\"st\":1}}"}
{"receive_ns":1788564462817047000,"stream":"btcusdt@bookTicker","event_type":"bookTicker","event_time_ms":1788564462798,"raw_json":"{\"stream\":\"btcusdt@bookTicker\",\"data\":{\"e\":\"bookTicker\",\"u\":11478296959497,\"s\":\"BTCUSDT\",\"ps\":\"BTCUSDT\",\"b\":\"79716.80\",\"B\":\"2.420\",\"a\":\"79716.90\",\"A\":\"15.139\",\"T\":1788564462798,\"E\":1788564462798,\"st\":1}}"}
{"receive_ns":1788564462817279000,"stream":"btcusdt@bookTicker","event_type":"bookTicker","event_time_ms":1788564462834,"raw_json":"{\"stream\":\"btcusdt@bookTicker\",\"data\":{\"e\":\"bookTicker\",\"u\":11478296961816,\"s\":\"BTCUSDT\",\"ps\":\"BTCUSDT\",\"b\":\"79716.80\",\"B\":\"2.420\",\"a\":\"79716.90\",\"A\":\"15.158\",\"T\":1788564462834,\"E\":1788564462834,\"st\":1}}"}
{"receive_ns":1788564462822643000,"stream":"btcusdt@bookTicker","event_type":"bookTicker","event_time_ms":1788564462835,"raw_json":"{\"stream\":\"btcusdt@bookTicker\",\"data\":{\"e\":\"bookTicker\",\"u\":11478296961875,\"s\":\"BTCUSDT\",\"ps\":\"BTCUSDT\",\"b\":\"79716.80\",\"B\":\"2.420\",\"a\":\"79716.90\",\"A\":\"15.139\",\"T\":1788564462835,\"E\":1788564462835,\"st\":1}}"}
{"receive_ns":1788564462824727000,"stream":"btcusdt@bookTicker","event_type":"bookTicker","event_time_ms":1788564462838,"raw_json":"{\"stream\":\"btcusdt@bookTicker\",\"data\":{\"e\":\"bookTicker\",\"u\":11478296962105,\"s\":\"BTCUSDT\",\"ps\":\"BTCUSDT\",\"b\":\"79716.80\",\"B\":\"2.419\",\"a\":\"79716.90\",\"A\":\"15.139\",\"T\":1788564462837,\"E\":1788564462838,\"st\":1}}"}
{"receive_ns":1788564462836488000,"stream":"btcusdt@trade","event_type":"trade","event_time_ms":1788564462838,"raw_json":"{\"stream\":\"btcusdt@trade\",\"data\":{\"e\":\"trade\",\"E\":1788564462838,\"T\":1788564462837,\"s\":\"BTCUSDT\",\"t\":8054096500,\"p\":\"79716.80\",\"q\":\"0.001\",\"X\":\"MARKET\",\"m\":true,\"st\":1}}"}
{"receive_ns":1788564462841954000,"stream":"btcusdt@bookTicker","event_type":"bookTicker","event_time_ms":1788564462839,"raw_json":"{\"stream\":\"btcusdt@bookTicker\",\"data\":{\"e\":\"bookTicker\",\"u\":11478296962210,\"s\":\"BTCUSDT\",\"ps\":\"BTCUSDT\",\"b\":\"79716.80\",\"B\":\"2.419\",\"a\":\"79716.90\",\"A\":\"15.158\",\"T\":1788564462839,\"E\":1788564462839,\"st\":1}}"}
{"receive_ns":1788564462858424000,"stream":"btcusdt@bookTicker","event_type":"bookTicker","event_time_ms":1788564462839,"raw_json":"{\"stream\":\"btcusdt@bookTicker\",\"data\":{\"e\":\"bookTicker\",\"u\":11478296962293,\"s\":\"BTCUSDT\",\"ps\":\"BTCUSDT\",\"b\":\"79716.80\",\"B\":\"2.419\",\"a\":\"79716.90\",\"A\":\"15.160\",\"T\":1788564462839,\"E\":1788564462839,\"st\":1}}"}
{"receive_ns":1788564462867206000,"stream":"btcusdt@bookTicker","event_type":"bookTicker","event_time_ms":1788564462840,"raw_json":"{\"stream\":\"btcusdt@bookTicker\",\"data\":{\"e\":\"bookTicker\",\"u\":11478296962464,\"s\":\"BTCUSDT\",\"ps\":\"BTCUSDT\",\"b\":\"79716.80\",\"B\":\"2.419\",\"a\":\"79716.90\",\"A\":\"15.141\",\"T\":1788564462840,\"E\":1788564462840,\"st\":1}}"}
{"receive_ns":1788564462867448000,"stream":"btcusdt@bookTicker","event_type":"bookTicker","event_time_ms":1788564462840,"raw_json":"{\"stream\":\"btcusdt@bookTicker\",\"data\":{\"e\":\"bookTicker\",\"u\":11478296962510,\"s\":\"BTCUSDT\",\"ps\":\"BTCUSDT\",\"b\":\"79716.80\",\"B\":\"2.419\",\"a\":\"79716.90\",\"A\":\"15.139\",\"T\":1788564462840,\"E\":1788564462840,\"st\":1}}"}
{"receive_ns":1788564462867687000,"stream":"btcusdt@bookTicker","event_type":"bookTicker","event_time_ms":1788564462858,"raw_json":"{\"stream\":\"btcusdt@bookTicker\",\"data\":{\"e\":\"bookTicker\",\"u\":11478296963642,\"s\":\"BTCUSDT\",\"ps\":\"BTCUSDT\",\"b\":\"79716.80\",\"B\":\"2.419\",\"a\":\"79716.90\",\"A\":\"15.141\",\"T\":1788564462857,\"E\":1788564462858,\"st\":1}}"}
{"receive_ns":1788564462867903000,"stream":"btcusdt@bookTicker","event_type":"bookTicker","event_time_ms":1788564462858,"raw_json":"{\"stream\":\"btcusdt@bookTicker\",\"data\":{\"e\":\"bookTicker\",\"u\":11478296963685,\"s\":\"BTCUSDT\",\"ps\":\"BTCUSDT\",\"b\":\"79716.80\",\"B\":\"2.419\",\"a\":\"79716.90\",\"A\":\"15.160\",\"T\":1788564462858,\"E\":1788564462858,\"st\":1}}"}
{"receive_ns":1788564462885919000,"stream":"btcusdt@bookTicker","event_type":"bookTicker","event_time_ms":1788564462858,"raw_json":"{\"stream\":\"btcusdt@bookTicker\",\"data\":{\"e\":\"bookTicker\",\"u\":11478296963711,\"s\":\"BTCUSDT\",\"ps\":\"BTCUSDT\",\"b\":\"79716.80\",\"B\":\"2.419\",\"a\":\"79716.90\",\"A\":\"15.158\",\"T\":1788564462858,\"E\":1788564462858,\"st\":1}}"}
{"receive_ns":1788564462886140000,"stream":"btcusdt@bookTicker","event_type":"bookTicker","event_time_ms":1788564462858,"raw_json":"{\"stream\":\"btcusdt@bookTicker\",\"data\":{\"e\":\"bookTicker\",\"u\":11478296963723,\"s\":\"BTCUSDT\",\"ps\":\"BTCUSDT\",\"b\":\"79716.80\",\"B\":\"2.419\",\"a\":\"79716.90\",\"A\":\"15.139\",\"T\":1788564462858,\"E\":1788564462858,\"st\":1}}"}
{"receive_ns":1788564462892169000,"stream":"btcusdt@depth@100ms","event_type":"depthUpdate","event_time_ms":1788564462861,"raw_json":"{\"stream\":\"btcusdt@depth@100ms\",\"data\":{\"e\":\"depthUpdate\",\"E\":1788564462861,\"T\":1788564462860,\"s\":\"BTCUSDT\",\"ps\":\"BTCUSDT\",\"U\":11478296956860,\"u\":11478296963837,\"pu\":11478296956793,\"b\":[[\"29416.80\",\"0.595\"],[\"29516.80\",\"1.505\"],[\"71745.10\",\"0.002\"],[\"75731.00\",\"0.065\"],[\"75731.10\",\"0.010\"],[\"76528.10\",\"0.000\"],[\"78572.30\",\"0.385\"],[\"78919.60\",\"7.933\"],[\"79067.80\",\"0.108\"],[\"79068.00\",\"0.012\"],[\"79320.20\",\"0.140\"],[\"79522.20\",\"0.036\"],[\"79529.50\",\"1.026\"],[\"79693.40\",\"0.431\"],[\"79694.30\",\"0.001\"],[\"79695.10\",\"0.440\"],[\"79696.50\",\"0.361\"],[\"79700.80\",\"0.015\"],[\"79703.70\",\"0.004\"],[\"79712.40\",\"0.000\"],[\"79712.50\",\"0.000\"],[\"79714.00\",\"0.027\"],[\"79714.60\",\"0.026\"],[\"79715.20\",\"0.002\"],[\"79715.40\",\"0.001\"],[\"79715.50\",\"0.002\"],[\"79715.80\",\"0.000\"],[\"79716.20\",\"0.213\"],[\"79716.30\",\"0.000\"],[\"79716.80\",\"2.419\"]],\"a\":[[\"79716.90\",\"15.139\"],[\"79733.40\",\"1.641\"],[\"79735.40\",\"0.000\"],[\"79792.60\",\"0.701\"],[\"80085.60\",\"1.157\"],[\"80514.10\",\"5.823\"],[\"80673.50\",\"27.477\"],[\"80686.00\",\"1.320\"],[\"81311.20\",\"0.027\"]],\"st\":1}}"}
{"receive_ns":1788564462897870000,"stream":"btcusdt@bookTicker","event_type":"bookTicker","event_time_ms":1788564462907,"raw_json":"{\"stream\":\"btcusdt@bookTicker\",\"data\":{\"e\":\"bookTicker\",\"u\":11478296966542,\"s\":\"BTCUSDT\",\"ps\":\"BTCUSDT\",\"b\":\"79716.80\",\"B\":\"2.409\",\"a\":\"79716.90\",\"A\":\"15.139\",\"T\":1788564462907,\"E\":1788564462907,\"st\":1}}"}
{"receive_ns":1788564462903586000,"stream":"btcusdt@trade","event_type":"trade","event_time_ms":1788564462907,"raw_json":"{\"stream\":\"btcusdt@trade\",\"data\":{\"e\":\"trade\",\"E\":1788564462907,\"T\":1788564462907,\"s\":\"BTCUSDT\",\"t\":8054096501,\"p\":\"79716.80\",\"q\":\"0.010\",\"X\":\"MARKET\",\"m\":true,\"st\":1}}"}
{"receive_ns":1788564462912668000,"stream":"btcusdt@bookTicker","event_type":"bookTicker","event_time_ms":1788564462908,"raw_json":"{\"stream\":\"btcusdt@bookTicker\",\"data\":{\"e\":\"bookTicker\",\"u\":11478296966662,\"s\":\"BTCUSDT\",\"ps\":\"BTCUSDT\",\"b\":\"79716.80\",\"B\":\"2.409\",\"a\":\"79716.90\",\"A\":\"15.158\",\"T\":1788564462908,\"E\":1788564462908,\"st\":1}}"}
{"receive_ns":1788564462918528000,"stream":"btcusdt@bookTicker","event_type":"bookTicker","event_time_ms":1788564462909,"raw_json":"{\"stream\":\"btcusdt@bookTicker\",\"data\":{\"e\":\"bookTicker\",\"u\":11478296966719,\"s\":\"BTCUSDT\",\"ps\":\"BTCUSDT\",\"b\":\"79716.80\",\"B\":\"2.409\",\"a\":\"79716.90\",\"A\":\"15.160\",\"T\":1788564462908,\"E\":1788564462909,\"st\":1}}"}
{"receive_ns":1788564462929477000,"stream":"btcusdt@bookTicker","event_type":"bookTicker","event_time_ms":1788564462909,"raw_json":"{\"stream\":\"btcusdt@bookTicker\",\"data\":{\"e\":\"bookTicker\",\"u\":11478296966833,\"s\":\"BTCUSDT\",\"ps\":\"BTCUSDT\",\"b\":\"79716.80\",\"B\":\"2.409\",\"a\":\"79716.90\",\"A\":\"15.158\",\"T\":1788564462909,\"E\":1788564462909,\"st\":1}}"}
{"receive_ns":1788564462936126000,"stream":"btcusdt@bookTicker","event_type":"bookTicker","event_time_ms":1788564462909,"raw_json":"{\"stream\":\"btcusdt@bookTicker\",\"data\":{\"e\":\"bookTicker\",\"u\":11478296966834,\"s\":\"BTCUSDT\",\"ps\":\"BTCUSDT\",\"b\":\"79716.80\",\"B\":\"2.409\",\"a\":\"79716.90\",\"A\":\"15.139\",\"T\":1788564462909,\"E\":1788564462909,\"st\":1}}"}
{"receive_ns":1788564462942592000,"stream":"btcusdt@depth@100ms","event_type":"depthUpdate","event_time_ms":1788564462963,"raw_json":"{\"stream\":\"btcusdt@depth@100ms\",\"data\":{\"e\":\"depthUpdate\",\"E\":1788564462963,\"T\":1788564462961,\"s\":\"BTCUSDT\",\"ps\":\"BTCUSDT\",\"U\":11478296963848,\"u\":11478296970141,\"pu\":11478296963837,\"b\":[[\"1000.00\",\"24.754\"],[\"29416.80\",\"0.777\"],[\"29516.80\",\"1.323\"],[\"71745.10\",\"0.002\"],[\"76528.10\",\"0.002\"],[\"78122.50\",\"0.170\"],[\"78521.00\",\"1.227\"],[\"78583.90\",\"1.779\"],[\"78919.60\",\"7.929\"],[\"79318.20\",\"3.285\"],[\"79497.60\",\"0.733\"],[\"79500.80\",\"1.003\"],[\"79501.60\",\"1.731\"],[\"79522.20\",\"0.004\"],[\"79529.50\",\"1.026\"],[\"79701.90\",\"0.001\"],[\"79702.50\",\"0.000\"],[\"79713.90\",\"0.028\"],[\"79714.60\",\"0.000\"],[\"79716.20\",\"0.318\"],[\"79716.80\",\"2.409\"]],\"a\":[[\"79716.90\",\"15.139\"],[\"79718.00\",\"3.559\"],[\"79720.60\",\"0.116\"],[\"79733.40\",\"1.269\"],[\"79734.60\",\"0.374\"],[\"79792.60\",\"0.701\"],[\"79886.30\",\"0.090\"],[\"80085.60\",\"1.157\"],[\"80086.80\",\"0.778\"],[\"80514.10\",\"5.823\"],[\"80766.70\",\"8.599\"],[\"87688.60\",\"0.000\"]],\"st\":1}}"}
{"receive_ns":1788564462948082000,"stream":"btcusdt@bookTicker","event_type":"bookTicker","event_time_ms":1788564462969,"raw_json":"{\"stream\":\"btcusdt@bookTicker\",\"data\":{\"e\":\"bookTicker\",\"u\":11478296970525,\"s\":\"BTCUSDT\",\"ps\":\"BTCUSDT\",\"b\":\"79716.80\",\"B\":\"2.409\",\"a\":\"79716.90\",\"A\":\"15.137\",\"T\":1788564462969,\"E\":1788564462969,\"st\":1}}"}
{"receive_ns":1788564463046860000,"stream":"btcusdt@depth@100ms","event_type":"depthUpdate","event_time_ms":1788564463065,"raw_json":"{\"stream\":\"btcusdt@depth@100ms\",\"data\":{\"e\":\"depthUpdate\",\"E\":1788564463065,\"T\":1788564463061,\"s\":\"BTCUSDT\",\"ps\":\"BTCUSDT\",\"U\":11478296970246,\"u\":11478296975856,\"pu\":11478296970141,\"b\":[[\"1000.00\",\"24.754\"],[\"29416.80\",\"0.952\"],[\"29516.80\",\"1.148\"],[\"71745.10\",\"0.002\"],[\"78720.30\",\"4.801\"],[\"78833.90\",\"0.000\"],[\"78919.60\",\"7.929\"],[\"79079.10\",\"5.682\"],[\"79318.20\",\"3.285\"],[\"79320.20\",\"0.000\"],[\"79522.20\",\"0.004\"],[\"79529.50\",\"1.026\"],[\"79594.50\",\"0.697\"],[\"79700.80\",\"0.001\"],[\"79702.50\",\"0.000\"],[\"79712.30\",\"0.028\"],[\"79712.40\",\"0.026\"],[\"79712.50\",\"0.026\"],[\"79713.80\",\"0.003\"],[\"79713.90\",\"0.002\"],[\"79714.00\",\"0.001\"],[\"79714.10\",\"0.000\"]],\"a\":[[\"79716.90\",\"15.137\"],[\"79720.50\",\"0.004\"],[\"79722.50\",\"1.455\"],[\"79792.60\",\"0.252\"],[\"79840.20\",\"0.351\"],[\"79866.40\",\"0.199\"],[\"80085.60\",\"1.157\"],[\"80115.50\",\"3.242\"],[\"80514.10\",\"5.823\"]],\"st\":1}}"}
{"receive_ns":1788564463087133000,"stream":"btcusdt@bookTicker","event_type":"bookTicker","event_time_ms":1788564463110,"raw_json":"{\"stream\":\"btcusdt@bookTicker\",\"data\":{\"e\":\"bookTicker\",\"u\":11478296978823,\"s\":\"BTCUSDT\",\"ps\":\"BTCUSDT\",\"b\":\"79716.80\",\"B\":\"2.397\",\"a\":\"79716.90\",\"A\":\"15.137\",\"T\":1788564463110,\"E\":1788564463110,\"st\":1}}"}
{"receive_ns":1788564463092455000,"stream":"btcusdt@trade","event_type":"trade","event_time_ms":1788564463110,"raw_json":"{\"stream\":\"btcusdt@trade\",\"data\":{\"e\":\"trade\",\"E\":1788564463110,\"T\":1788564463110,\"s\":\"BTCUSDT\",\"t\":8054096502,\"p\":\"79716.80\",\"q\":\"0.012\",\"X\":\"MARKET\",\"m\":true,\"st\":1}}"}
{"receive_ns":1788564463103174000,"stream":"btcusdt@bookTicker","event_type":"bookTicker","event_time_ms":1788564463112,"raw_json":"{\"stream\":\"btcusdt@bookTicker\",\"data\":{\"e\":\"bookTicker\",\"u\":11478296978906,\"s\":\"BTCUSDT\",\"ps\":\"BTCUSDT\",\"b\":\"79716.80\",\"B\":\"2.397\",\"a\":\"79716.90\",\"A\":\"15.156\",\"T\":1788564463111,\"E\":1788564463112,\"st\":1}}"}
{"receive_ns":1788564463108941000,"stream":"btcusdt@bookTicker","event_type":"bookTicker","event_time_ms":1788564463112,"raw_json":"{\"stream\":\"btcusdt@bookTicker\",\"data\":{\"e\":\"bookTicker\",\"u\":11478296978939,\"s\":\"BTCUSDT\",\"ps\":\"BTCUSDT\",\"b\":\"79716.80\",\"B\":\"2.397\",\"a\":\"79716.90\",\"A\":\"15.158\",\"T\":1788564463111,\"E\":1788564463112,\"st\":1}}"}
{"receive_ns":1788564463109182000,"stream":"btcusdt@bookTicker","event_type":"bookTicker","event_time_ms":1788564463112,"raw_json":"{\"stream\":\"btcusdt@bookTicker\",\"data\":{\"e\":\"bookTicker\",\"u\":11478296979120,\"s\":\"BTCUSDT\",\"ps\":\"BTCUSDT\",\"b\":\"79716.80\",\"B\":\"2.397\",\"a\":\"79716.90\",\"A\":\"15.156\",\"T\":1788564463112,\"E\":1788564463112,\"st\":1}}"}
{"receive_ns":1788564463109360000,"stream":"btcusdt@bookTicker","event_type":"bookTicker","event_time_ms":1788564463113,"raw_json":"{\"stream\":\"btcusdt@bookTicker\",\"data\":{\"e\":\"bookTicker\",\"u\":11478296979141,\"s\":\"BTCUSDT\",\"ps\":\"BTCUSDT\",\"b\":\"79716.80\",\"B\":\"2.397\",\"a\":\"79716.90\",\"A\":\"15.137\",\"T\":1788564463112,\"E\":1788564463113,\"st\":1}}"}
{"receive_ns":1788564463115855000,"stream":"btcusdt@bookTicker","event_type":"bookTicker","event_time_ms":1788564463119,"raw_json":"{\"stream\":\"btcusdt@bookTicker\",\"data\":{\"e\":\"bookTicker\",\"u\":11478296979676,\"s\":\"BTCUSDT\",\"ps\":\"BTCUSDT\",\"b\":\"79716.80\",\"B\":\"2.397\",\"a\":\"79716.90\",\"A\":\"15.130\",\"T\":1788564463118,\"E\":1788564463119,\"st\":1}}"}
{"receive_ns":1788564463122114000,"stream":"btcusdt@bookTicker","event_type":"bookTicker","event_time_ms":1788564463122,"raw_json":"{\"stream\":\"btcusdt@bookTicker\",\"data\":{\"e\":\"bookTicker\",\"u\":11478296979963,\"s\":\"BTCUSDT\",\"ps\":\"BTCUSDT\",\"b\":\"79716.80\",\"B\":\"2.397\",\"a\":\"79716.90\",\"A\":\"15.133\",\"T\":1788564463122,\"E\":1788564463122,\"st\":1}}"}
{"receive_ns":1788564463133756000,"stream":"btcusdt@bookTicker","event_type":"bookTicker","event_time_ms":1788564463148,"raw_json":"{\"stream\":\"btcusdt@bookTicker\",\"data\":{\"e\":\"bookTicker\",\"u\":11478296981744,\"s\":\"BTCUSDT\",\"ps\":\"BTCUSDT\",\"b\":\"79716.80\",\"B\":\"2.397\",\"a\":\"79716.90\",\"A\":\"15.152\",\"T\":1788564463148,\"E\":1788564463148,\"st\":1}}"}
{"receive_ns":1788564463135259000,"stream":"btcusdt@bookTicker","event_type":"bookTicker","event_time_ms":1788564463148,"raw_json":"{\"stream\":\"btcusdt@bookTicker\",\"data\":{\"e\":\"bookTicker\",\"u\":11478296981793,\"s\":\"BTCUSDT\",\"ps\":\"BTCUSDT\",\"b\":\"79716.80\",\"B\":\"2.397\",\"a\":\"79716.90\",\"A\":\"15.133\",\"T\":1788564463148,\"E\":1788564463148,\"st\":1}}"}
{"receive_ns":1788564463144055000,"stream":"btcusdt@depth@100ms","event_type":"depthUpdate","event_time_ms":1788564463167,"raw_json":"{\"stream\":\"btcusdt@depth@100ms\",\"data\":{\"e\":\"depthUpdate\",\"E\":1788564463167,\"T\":1788564463165,\"s\":\"BTCUSDT\",\"ps\":\"BTCUSDT\",\"U\":11478296976045,\"u\":11478296982773,\"pu\":11478296975856,\"b\":[[\"29416.80\",\"1.134\"],[\"29516.80\",\"0.966\"],[\"71745.10\",\"0.002\"],[\"71782.00\",\"0.000\"],[\"76528.10\",\"0.000\"],[\"78480.80\",\"0.037\"],[\"78749.10\",\"1.268\"],[\"78919.60\",\"7.929\"],[\"79079.10\",\"6.439\"],[\"79265.30\",\"0.002\"],[\"79320.20\",\"0.140\"],[\"79497.60\",\"0.502\"],[\"79500.80\",\"0.000\"],[\"79501.60\",\"0.628\"],[\"79522.20\",\"0.036\"],[\"79529.50\",\"0.951\"],[\"79593.60\",\"0.000\"],[\"79593.70\",\"0.204\"],[\"79594.50\",\"0.666\"],[\"79625.60\",\"3.856\"],[\"79627.50\",\"0.716\"],[\"79689.40\",\"0.003\"],[\"79690.90\",\"0.452\"],[\"79693.40\",\"0.059\"],[\"79695.10\",\"0.001\"],[\"79695.50\",\"0.373\"],[\"79697.30\",\"0.539\"],[\"79700.10\",\"0.216\"],[\"79700.70\",\"1.318\"],[\"79701.90\",\"0.003\"],[\"79703.30\",\"0.001\"],[\"79703.40\",\"0.290\"],[\"79703.60\",\"0.252\"],[\"79711.90\",\"0.027\"],[\"79712.00\",\"0.042\"],[\"79712.20\",\"0.028\"],[\"79712.90\",\"0.000\"],[\"79713.00\",\"0.001\"],[\"79713.10\",\"0.002\"],[\"79715.20\",\"0.001\"],[\"79716.80\",\"2.397\"]],\"a\":[[\"79716.90\",\"15.133\"],[\"79726.00\",\"1.218\"],[\"79733.60\",\"0.001\"],[\"79734.30\",\"0.441\"],[\"79734.60\",\"0.002\"],[\"79735.40\",\"0.372\"],[\"79792.60\",\"0.002\"],[\"79807.90\",\"3.326\"],[\"79840.20\",\"0.320\"],[\"79866.40\",\"0.449\"],[\"79886.30\",\"0.000\"],[\"79938.80\",\"8.439\"],[\"80085.60\",\"0.589\"],[\"80086.80\",\"0.016\"],[\"80514.10\",\"5.823\"],[\"80952.80\",\"0.030\"],[\"81093.30\",\"0.680\"]],\"st\":1}}"}
{"receive_ns":1788564463245743000,"stream":"btcusdt@depth@100ms","event_type":"depthUpdate","event_time_ms":1788564463269,"raw_json":"{\"stream\":\"btcusdt@depth@100ms\",\"data\":{\"e\":\"depthUpdate\",\"E\":1788564463269,\"T\":1788564463265,\"s\":\"BTCUSDT\",\"ps\":\"BTCUSDT\",\"U\":11478296982906,\"u\":11478296988833,\"pu\":11478296982773,\"b\":[[\"1000.00\",\"24.754\"],[\"29416.80\",\"1.309\"],[\"29516.80\",\"0.791\"],[\"63773.00\",\"0.000\"],[\"71745.10\",\"0.002\"],[\"76528.10\",\"0.002\"],[\"78919.60\",\"7.929\"],[\"79500.80\",\"1.003\"],[\"79501.60\",\"0.859\"],[\"79522.20\",\"0.004\"],[\"79529.50\",\"1.428\"],[\"79531.50\",\"0.507\"],[\"79689.40\",\"0.454\"],[\"79690.90\",\"0.001\"],[\"79694.30\",\"0.373\"],[\"79695.50\",\"0.001\"],[\"79696.50\",\"0.800\"],[\"79697.30\",\"0.100\"],[\"79713.40\",\"0.026\"],[\"79713.50\",\"0.028\"]],\"a\":[[\"79732.60\",\"0.439\"],[\"79734.30\",\"0.003\"],[\"79739.30\",\"1.044\"],[\"79740.50\",\"0.009\"],[\"79866.40\",\"0.500\"],[\"79886.30\",\"0.090\"],[\"80085.60\",\"1.157\"],[\"80086.80\",\"0.778\"],[\"80514.10\",\"5.823\"],[\"80825.00\",\"5.164\"],[\"80832.90\",\"25.764\"],[\"80952.90\",\"0.006\"]],\"st\":1}}"}
{"receive_ns":1788564463310607000,"stream":"btcusdt@bookTicker","event_type":"bookTicker","event_time_ms":1788564463326,"raw_json":"{\"stream\":\"btcusdt@bookTicker\",\"data\":{\"e\":\"bookTicker\",\"u\":11478296992389,\"s\":\"BTCUSDT\",\"ps\":\"BTCUSDT\",\"b\":\"79716.80\",\"B\":\"2.611\",\"a\":\"79716.90\",\"A\":\"15.133\",\"T\":1788564463326,\"E\":1788564463326,\"st\":1}}"}
{"receive_ns":1788564463326913000,"stream":"btcusdt@bookTicker","event_type":"bookTicker","event_time_ms":1788564463328,"raw_json":"{\"stream\":\"btcusdt@bookTicker\",\"data\":{\"e\":\"bookTicker\",\"u\":11478296992598,\"s\":\"BTCUSDT\",\"ps\":\"BTCUSDT\",\"b\":\"79716.80\",\"B\":\"2.609\",\"a\":\"79716.90\",\"A\":\"15.133\",\"T\":1788564463327,\"E\":1788564463328,\"st\":1}}"}
{"receive_ns":1788564463330206000,"stream":"btcusdt@bookTicker","event_type":"bookTicker","event_time_ms":1788564463328,"raw_json":"{\"stream\":\"btcusdt@bookTicker\",\"data\":{\"e\":\"bookTicker\",\"u\":11478296992643,\"s\":\"BTCUSDT\",\"ps\":\"BTCUSDT\",\"b\":\"79716.80\",\"B\":\"2.608\",\"a\":\"79716.90\",\"A\":\"15.133\",\"T\":1788564463328,\"E\":1788564463328,\"st\":1}}"}
{"receive_ns":1788564463341483000,"stream":"btcusdt@bookTicker","event_type":"bookTicker","event_time_ms":1788564463329,"raw_json":"{\"stream\":\"btcusdt@bookTicker\",\"data\":{\"e\":\"bookTicker\",\"u\":11478296992910,\"s\":\"BTCUSDT\",\"ps\":\"BTCUSDT\",\"b\":\"79716.80\",\"B\":\"2.609\",\"a\":\"79716.90\",\"A\":\"15.133\",\"T\":1788564463329,\"E\":1788564463329,\"st\":1}}"}
{"receive_ns":1788564463354384000,"stream":"btcusdt@depth@100ms","event_type":"depthUpdate","event_time_ms":1788564463371,"raw_json":"{\"stream\":\"btcusdt@depth@100ms\",\"data\":{\"e\":\"depthUpdate\",\"E\":1788564463371,\"T\":1788564463370,\"s\":\"BTCUSDT\",\"ps\":\"BTCUSDT\",\"U\":11478296988968,\"u\":11478296996774,\"pu\":11478296988833,\"b\":[[\"1000.00\",\"24.754\"],[\"29416.80\",\"1.491\"],[\"29516.80\",\"0.609\"],[\"63773.00\",\"0.000\"],[\"63773.40\",\"0.000\"],[\"71745.10\",\"0.002\"],[\"74106.90\",\"0.022\"],[\"75731.10\",\"0.008\"],[\"76528.10\",\"0.000\"],[\"78583.90\",\"1.272\"],[\"78760.20\",\"27.449\"],[\"78919.60\",\"7.929\"],[\"79298.20\",\"0.090\"],[\"79318.20\",\"3.285\"],[\"79320.20\",\"0.140\"],[\"79522.20\",\"0.036\"],[\"79529.50\",\"1.628\"],[\"79627.50\",\"1.361\"],[\"79636.00\",\"0.000\"],[\"79647.90\",\"0.001\"],[\"79667.00\",\"0.001\"],[\"79667.10\",\"0.688\"],[\"79671.30\",\"0.502\"],[\"79671.70\",\"2.009\"],[\"79671.80\",\"1.189\"],[\"79711.90\",\"0.001\"],[\"79713.70\",\"0.000\"],[\"79716.80\",\"2.609\"]],\"a\":[[\"79866.40\",\"0.699\"],[\"80085.60\",\"1.157\"],[\"80514.10\",\"5.825\"]],\"st\":1}}"}
{"receive_ns":1788564463380191000,"stream":"btcusdt@bookTicker","event_type":"bookTicker","event_time_ms":1788564463400,"raw_json":"{\"stream\":\"btcusdt@bookTicker\",\"data\":{\"e\":\"bookTicker\",\"u\":11478296998890,\"s\":\"BTCUSDT\",\"ps\":\"BTCUSDT\",\"b\":\"79716.80\",\"B\":\"2.609\",\"a\":\"79716.90\",\"A\":\"15.135\",\"T\":1788564463400,\"E\":1788564463400,\"st\":1}}"}
{"receive_ns":1788564463425309000,"stream":"btcusdt@bookTicker","event_type":"bookTicker","event_time_ms":1788564463442,"raw_json":"{\"stream\":\"btcusdt@bookTicker\",\"data\":{\"e\":\"bookTicker\",\"u\":11478297002270,\"s\":\"BTCUSDT\",\"ps\":\"BTCUSDT\",\"b\":\"79716.80\",\"B\":\"2.573\",\"a\":\"79716.90\",\"A\":\"15.135\",\"T\":1788564463441,\"E\":1788564463442,\"st\":1}}"}
{"receive_ns":1788564463438393000,"stream":"btcusdt@bookTicker","event_type":"bookTicker","event_time_ms":1788564463445,"raw_json":"{\"stream\":\"btcusdt@bookTicker\",\"data\":{\"e\":\"bookTicker\",\"u\":11478297002564,\"s\":\"BTCUSDT\",\"ps\":\"BTCUSDT\",\"b\":\"79716.80\",\"B\":\"2.607\",\"a\":\"79716.90\",\"A\":\"15.135\",\"T\":1788564463445,\"E\":1788564463445,\"st\":1}}"}
{"receive_ns":1788564463450189000,"stream":"btcusdt@bookTicker","event_type":"bookTicker","event_time_ms":1788564463446,"raw_json":"{\"stream\":\"btcusdt@bookTicker\",\"data\":{\"e\":\"bookTicker\",\"u\":11478297002646,\"s\":\"BTCUSDT\",\"ps\":\"BTCUSDT\",\"b\":\"79716.80\",\"B\":\"2.609\",\"a\":\"79716.90\",\"A\":\"15.135\",\"T\":1788564463446,\"E\":1788564463446,\"st\":1}}"}
{"receive_ns":1788564463462297000,"stream":"btcusdt@bookTicker","event_type":"bookTicker","event_time_ms":1788564463460,"raw_json":"{\"stream\":\"btcusdt@bookTicker\",\"data\":{\"e\":\"bookTicker\",\"u\":11478297003520,\"s\":\"BTCUSDT\",\"ps\":\"BTCUSDT\",\"b\":\"79716.80\",\"B\":\"2.609\",\"a\":\"79716.90\",\"A\":\"15.154\",\"T\":1788564463460,\"E\":1788564463460,\"st\":1}}"}
{"receive_ns":1788564463469218000,"stream":"btcusdt@bookTicker","event_type":"bookTicker","event_time_ms":1788564463461,"raw_json":"{\"stream\":\"btcusdt@bookTicker\",\"data\":{\"e\":\"bookTicker\",\"u\":11478297003611,\"s\":\"BTCUSDT\",\"ps\":\"BTCUSDT\",\"b\":\"79716.80\",\"B\":\"2.609\",\"a\":\"79716.90\",\"A\":\"15.135\",\"T\":1788564463460,\"E\":1788564463461,\"st\":1}}"}
{"receive_ns":1788564463481813000,"stream":"btcusdt@depth@100ms","event_type":"depthUpdate","event_time_ms":1788564463473,"raw_json":"{\"stream\":\"btcusdt@depth@100ms\",\"data\":{\"e\":\"depthUpdate\",\"E\":1788564463473,\"T\":1788564463470,\"s\":\"BTCUSDT\",\"ps\":\"BTCUSDT\",\"U\":11478296996890,\"u\":11478297004637,\"pu\":11478296996774,\"b\":[[\"29416.80\",\"1.666\"],[\"29516.80\",\"0.434\"],[\"71745.10\",\"0.002\"],[\"78919.60\",\"7.929\"],[\"79500.80\",\"1.003\"],[\"79501.60\",\"0.859\"],[\"79529.50\",\"1.428\"],[\"79531.50\",\"0.006\"],[\"79565.70\",\"0.020\"],[\"79568.00\",\"1.837\"],[\"79570.40\",\"1.882\"],[\"79594.50\",\"0.000\"],[\"79671.20\",\"0.000\"],[\"79671.70\",\"2.010\"],[\"79700.10\",\"0.006\"],[\"79703.40\",\"0.020\"],[\"79711.90\",\"0.027\"],[\"79713.40\",\"0.000\"],[\"79713.50\",\"0.002\"],[\"79716.80\",\"2.609\"]],\"a\":[[\"79716.90\",\"15.135\"],[\"79718.70\",\"1.401\"],[\"79720.60\",\"0.110\"],[\"79732.60\",\"0.001\"],[\"79733.60\",\"0.439\"],[\"79739.30\",\"0.593\"],[\"79740.40\",\"0.451\"],[\"79792.60\",\"0.252\"],[\"79839.20\",\"0.056\"],[\"79839.30\",\"1.901\"],[\"79840.20\",\"0.001\"],[\"79866.40\",\"0.250\"],[\"79886.30\",\"0.090\"],[\"80085.60\",\"0.739\"],[\"80086.80\",\"0.778\"],[\"80514.10\",\"5.823\"],[\"80788.90\",\"0.252\"]],\"st\":1}}"}
{"receive_ns":1788564463488803000,"stream":"btcusdt@bookTicker","event_type":"bookTicker","event_time_ms":1788564463480,"raw_json":"{\"stream\":\"btcusdt@bookTicker\",\"data\":{\"e\":\"bookTicker\",\"u\":11478297005206,\"s\":\"BTCUSDT\",\"ps\":\"BTCUSDT\",\"b\":\"79716.80\",\"B\":\"2.609\",\"a\":\"79716.90\",\"A\":\"15.154\",\"T\":1788564463480,\"E\":1788564463480,\"st\":1}}"}
{"receive_ns":1788564463499966000,"stream":"btcusdt@bookTicker","event_type":"bookTicker","event_time_ms":1788564463480,"raw_json":"{\"stream\":\"btcusdt@bookTicker\",\"data\":{\"e\":\"bookTicker\",\"u\":11478297005295,\"s\":\"BTCUSDT\",\"ps\":\"BTCUSDT\",\"b\":\"79716.80\",\"B\":\"2.609\",\"a\":\"79716.90\",\"A\":\"15.135\",\"T\":1788564463480,\"E\":1788564463480,\"st\":1}}"}
{"receive_ns":1788564463507442000,"stream":"btcusdt@bookTicker","event_type":"bookTicker","event_time_ms":1788564463503,"raw_json":"{\"stream\":\"btcusdt@bookTicker\",\"data\":{\"e\":\"bookTicker\",\"u\":11478297006994,\"s\":\"BTCUSDT\",\"ps\":\"BTCUSDT\",\"b\":\"79716.80\",\"B\":\"2.609\",\"a\":\"79716.90\",\"A\":\"15.156\",\"T\":1788564463503,\"E\":1788564463503,\"st\":1}}"}
{"receive_ns":1788564463547933000,"stream":"btcusdt@bookTicker","event_type":"bookTicker","event_time_ms":1788564463572,"raw_json":"{\"stream\":\"btcusdt@bookTicker\",\"data\":{\"e\":\"bookTicker\",\"u\":11478297010729,\"s\":\"BTCUSDT\",\"ps\":\"BTCUSDT\",\"b\":\"79716.80\",\"B\":\"2.596\",\"a\":\"79716.90\",\"A\":\"15.156\",\"T\":1788564463572,\"E\":1788564463572,\"st\":1}}"}
{"receive_ns":1788564463558520000,"stream":"btcusdt@trade","event_type":"trade","event_time_ms":1788564463572,"raw_json":"{\"stream\":\"btcusdt@trade\",\"data\":{\"e\":\"trade\",\"E\":1788564463572,\"T\":1788564463572,\"s\":\"BTCUSDT\",\"t\":8054096503,\"p\":\"79716.80\",\"q\":\"0.013\",\"X\":\"MARKET\",\"m\":true,\"st\":1}}"}
{"receive_ns":1788564463564018000,"stream":"btcusdt@bookTicker","event_type":"bookTicker","event_time_ms":1788564463573,"raw_json":"{\"stream\":\"btcusdt@bookTicker\",\"data\":{\"e\":\"bookTicker\",\"u\":11478297010801,\"s\":\"BTCUSDT\",\"ps\":\"BTCUSDT\",\"b\":\"79716.80\",\"B\":\"2.596\",\"a\":\"79716.90\",\"A\":\"15.158\",\"T\":1788564463573,\"E\":1788564463573,\"st\":1}}"}
{"receive_ns":1788564463569589000,"stream":"btcusdt@bookTicker","event_type":"bookTicker","event_time_ms":1788564463573,"raw_json":"{\"stream\":\"btcusdt@bookTicker\",\"data\":{\"e\":\"bookTicker\",\"u\":11478297010818,\"s\":\"BTCUSDT\",\"ps\":\"BTCUSDT\",\"b\":\"79716.80\",\"B\":\"2.596\",\"a\":\"79716.90\",\"A\":\"15.177\",\"T\":1788564463573,\"E\":1788564463573,\"st\":1}}"}
{"receive_ns":1788564463581327000,"stream":"btcusdt@bookTicker","event_type":"bookTicker","event_time_ms":1788564463574,"raw_json":"{\"stream\":\"btcusdt@bookTicker\",\"data\":{\"e\":\"bookTicker\",\"u\":11478297010975,\"s\":\"BTCUSDT\",\"ps\":\"BTCUSDT\",\"b\":\"79716.80\",\"B\":\"2.596\",\"a\":\"79716.90\",\"A\":\"15.175\",\"T\":1788564463574,\"E\":1788564463574,\"st\":1}}"}
{"receive_ns":1788564463593274000,"stream":"btcusdt@bookTicker","event_type":"bookTicker","event_time_ms":1788564463574,"raw_json":"{\"stream\":\"btcusdt@bookTicker\",\"data\":{\"e\":\"bookTicker\",\"u\":11478297010978,\"s\":\"BTCUSDT\",\"ps\":\"BTCUSDT\",\"b\":\"79716.80\",\"B\":\"2.596\",\"a\":\"79716.90\",\"A\":\"15.156\",\"T\":1788564463574,\"E\":1788564463574,\"st\":1}}"}
{"receive_ns":1788564463601621000,"stream":"btcusdt@depth@100ms","event_type":"depthUpdate","event_time_ms":1788564463575,"raw_json":"{\"stream\":\"btcusdt@depth@100ms\",\"data\":{\"e\":\"depthUpdate\",\"E\":1788564463575,\"T\":1788564463574,\"s\":\"BTCUSDT\",\"ps\":\"BTCUSDT\",\"U\":11478297004824,\"u\":11478297011008,\"pu\":11478297004637,\"b\":[[\"1000.00\",\"24.754\"],[\"29316.80\",\"0.035\"],[\"29416.80\",\"1.778\"],[\"29516.80\",\"0.287\"],[\"71745.10\",\"0.002\"],[\"75731.00\",\"0.065\"],[\"75731.10\",\"0.010\"],[\"76528.10\",\"0.002\"],[\"78720.30\",\"4.953\"],[\"78727.30\",\"1.331\"],[\"78919.60\",\"7.933\"],[\"79318.20\",\"3.284\"],[\"79320.20\",\"0.140\"],[\"79529.50\",\"1.879\"],[\"79594.50\",\"0.715\"],[\"79643.60\",\"0.018\"],[\"79693.10\",\"0.003\"],[\"79711.90\",\"0.001\"],[\"79712.90\",\"0.026\"],[\"79713.00\",\"0.027\"],[\"79713.20\",\"0.027\"],[\"79716.80\",\"2.596\"]],\"a\":[[\"79716.90\",\"15.156\"],[\"79733.00\",\"0.630\"],[\"79787.10\",\"0.000\"],[\"79792.60\",\"0.451\"],[\"79840.10\",\"0.363\"],[\"79866.40\",\"0.250\"],[\"80085.60\",\"1.002\"],[\"80115.50\",\"3.243\"],[\"80514.10\",\"5.825\"]],\"st\":1}}"}
{"receive_ns":1788564463659183000,"stream":"btcusdt@depth@100ms","event_type":"depthUpdate","event_time_ms":1788564463677,"raw_json":"{\"stream\":\"btcusdt@depth@100ms\",\"data\":{\"e\":\"depthUpdate\",\"E\":1788564463677,\"T\":1788564463675,\"s\":\"BTCUSDT\",\"ps\":\"BTCUSDT\",\"U\":11478297011021,\"u\":11478297018988,\"pu\":11478297011008,\"b\":[[\"1000.00\",\"24.754\"],[\"29316.80\",\"0.091\"],[\"29416.80\",\"1.841\"],[\"29516.80\",\"0.168\"],[\"63773.00\",\"0.000\"],[\"71745.10\",\"0.004\"],[\"75730.90\",\"0.029\"],[\"75731.10\",\"0.008\"],[\"76528.10\",\"0.000\"],[\"78122.50\",\"0.164\"],[\"78572.30\",\"0.004\"],[\"78629.20\",\"5.019\"],[\"78739.90\",\"8.881\"],[\"78919.60\",\"7.929\"],[\"79318.20\",\"3.274\"],[\"79497.60\",\"0.733\"],[\"79500.80\",\"1.003\"],[\"79501.60\",\"0.628\"],[\"79529.50\",\"1.879\"],[\"79531.50\",\"0.256\"],[\"79640.70\",\"0.015\"],[\"79705.10\",\"0.215\"],[\"79705.40\",\"2.387\"],[\"79715.20\",\"0.002\"]],\"a\":[[\"79783.70\",\"3.124\"],[\"79785.50\",\"5.644\"],[\"79792.60\",\"0.201\"],[\"79866.40\",\"0.500\"],[\"79886.30\",\"0.090\"],[\"80085.60\",\"1.157\"],[\"80086.80\",\"0.778\"],[\"80514.10\",\"5.823\"],[\"80652.80\",\"8.674\"],[\"80812.10\",\"13.225\"]],\"st\":1}}"}
{"receive_ns":1788564463735662000,"stream":"btcusdt@bookTicker","event_type":"bookTicker","event_time_ms":1788564463753,"raw_json":"{\"stream\":\"btcusdt@bookTicker\",\"data\":{\"e\":\"bookTicker\",\"u\":11478297023417,\"s\":\"BTCUSDT\",\"ps\":\"BTCUSDT\",\"b\":\"79716.80\",\"B\":\"2.599\",\"a\":\"79716.90\",\"A\":\"15.156\",\"T\":1788564463752,\"E\":1788564463753,\"st\":1}}"}
{"receive_ns":1788564463754912000,"stream":"btcusdt@bookTicker","event_type":"bookTicker","event_time_ms":1788564463773,"raw_json":"{\"stream\":\"btcusdt@bookTicker\",\"data\":{\"e\":\"bookTicker\",\"u\":11478297024511,\"s\":\"BTCUSDT\",\"ps\":\"BTCUSDT\",\"b\":\"79716.80\",\"B\":\"2.599\",\"a\":\"79716.90\",\"A\":\"15.155\",\"T\":1788564463773,\"E\":1788564463773,\"st\":1}}"}
{"receive_ns":1788564463771670000,"stream":"btcusdt@trade","event_type":"trade","event_time_ms":1788564463773,"raw_json":"{\"stream\":\"btcusdt@trade\",\"data\":{\"e\":\"trade\",\"E\":1788564463773,\"T\":1788564463773,\"s\":\"BTCUSDT\",\"t\":8054096504,\"p\":\"79716.90\",\"q\":\"0.001\",\"X\":\"MARKET\",\"m\":false,\"st\":1}}"}
{"receive_ns":1788564463784323000,"stream":"btcusdt@bookTicker","event_type":"bookTicker","event_time_ms":1788564463774,"raw_json":"{\"stream\":\"btcusdt@bookTicker\",\"data\":{\"e\":\"bookTicker\",\"u\":11478297024587,\"s\":\"BTCUSDT\",\"ps\":\"BTCUSDT\",\"b\":\"79716.80\",\"B\":\"2.599\",\"a\":\"79716.90\",\"A\":\"15.157\",\"T\":1788564463774,\"E\":1788564463774,\"st\":1}}"}
{"receive_ns":1788564463796305000,"stream":"btcusdt@bookTicker","event_type":"bookTicker","event_time_ms":1788564463774,"raw_json":"{\"stream\":\"btcusdt@bookTicker\",\"data\":{\"e\":\"bookTicker\",\"u\":11478297024601,\"s\":\"BTCUSDT\",\"ps\":\"BTCUSDT\",\"b\":\"79716.80\",\"B\":\"2.599\",\"a\":\"79716.90\",\"A\":\"15.176\",\"T\":1788564463774,\"E\":1788564463774,\"st\":1}}"}
{"receive_ns":1788564463807144000,"stream":"btcusdt@bookTicker","event_type":"bookTicker","event_time_ms":1788564463775,"raw_json":"{\"stream\":\"btcusdt@bookTicker\",\"data\":{\"e\":\"bookTicker\",\"u\":11478297024703,\"s\":\"BTCUSDT\",\"ps\":\"BTCUSDT\",\"b\":\"79716.80\",\"B\":\"2.599\",\"a\":\"79716.90\",\"A\":\"15.174\",\"T\":1788564463775,\"E\":1788564463775,\"st\":1}}"}
{"receive_ns":1788564463815452000,"stream":"btcusdt@bookTicker","event_type":"bookTicker","event_time_ms":1788564463775,"raw_json":"{\"stream\":\"btcusdt@bookTicker\",\"data\":{\"e\":\"bookTicker\",\"u\":11478297024708,\"s\":\"BTCUSDT\",\"ps\":\"BTCUSDT\",\"b\":\"79716.80\",\"B\":\"2.599\",\"a\":\"79716.90\",\"A\":\"15.155\",\"T\":1788564463775,\"E\":1788564463775,\"st\":1}}"}
{"receive_ns":1788564463827739000,"stream":"btcusdt@depth@100ms","event_type":"depthUpdate","event_time_ms":1788564463779,"raw_json":"{\"stream\":\"btcusdt@depth@100ms\",\"data\":{\"e\":\"depthUpdate\",\"E\":1788564463779,\"T\":1788564463778,\"s\":\"BTCUSDT\",\"ps\":\"BTCUSDT\",\"U\":11478297019087,\"u\":11478297024912,\"pu\":11478297018988,\"b\":[[\"29316.80\",\"0.154\"],[\"29416.80\",\"1.897\"],[\"29516.80\",\"0.049\"],[\"63773.00\",\"0.000\"],[\"71745.10\",\"0.002\"],[\"75731.00\",\"0.067\"],[\"76528.10\",\"0.002\"],[\"78177.10\",\"0.638\"],[\"78521.00\",\"1.513\"],[\"78784.10\",\"1.329\"],[\"78919.60\",\"7.929\"],[\"79320.20\",\"0.000\"],[\"79529.50\",\"1.378\"],[\"79531.50\",\"0.757\"],[\"79594.50\",\"0.000\"],[\"79700.50\",\"0.146\"],[\"79703.60\",\"0.328\"],[\"79712.00\",\"0.016\"],[\"79712.20\",\"0.002\"],[\"79713.40\",\"0.026\"],[\"79714.30\",\"0.530\"],[\"79716.70\",\"0.010\"],[\"79716.80\",\"2.599\"]],\"a\":[[\"79716.90\",\"15.155\"],[\"79792.60\",\"0.201\"],[\"79840.10\",\"0.013\"],[\"79866.40\",\"0.250\"],[\"79938.80\",\"8.355\"],[\"80085.60\",\"1.157\"],[\"80514.10\",\"5.823\"],[\"80713.40\",\"7.616\"]],\"st\":1}}"}
{"receive_ns":1788564463860424000,"stream":"btcusdt@depth@100ms","event_type":"depthUpdate","event_time_ms":1788564463881,"raw_json":"{\"stream\":\"btcusdt@depth@100ms\",\"data\":{\"e\":\"depthUpdate\",\"E\":1788564463881,\"T\":1788564463877,\"s\":\"BTCUSDT\",\"ps\":\"BTCUSDT\",\"U\":11478297024974,\"u\":11478297030127,\"pu\":11478297024912,\"b\":[[\"1000.00\",\"24.754\"],[\"29316.80\",\"0.280\"],[\"29416.80\",\"1.820\"],[\"29516.80\",\"0.000\"],[\"71745.10\",\"0.002\"],[\"73991.90\",\"0.002\"],[\"75730.90\",\"0.034\"],[\"76528.10\",\"0.000\"],[\"78919.60\",\"7.929\"],[\"79320.20\",\"0.140\"],[\"79531.50\",\"0.757\"],[\"79555.00\",\"2.764\"],[\"79555.30\",\"0.423\"],[\"79594.50\",\"0.715\"]],\"a\":[[\"79840.10\",\"0.363\"],[\"79866.40\",\"0.500\"],[\"79879.60\",\"2.463\"],[\"80085.60\",\"1.157\"],[\"80514.10\",\"5.823\"],[\"80793.10\",\"2.051\"],[\"80805.60\",\"12.866\"]],\"st\":1}}"}
{"receive_ns":1788564463896379000,"stream":"btcusdt@bookTicker","event_type":"bookTicker","event_time_ms":1788564463914,"raw_json":"{\"stream\":\"btcusdt@bookTicker\",\"data\":{\"e\":\"bookTicker\",\"u\":11478297031985,\"s\":\"BTCUSDT\",\"ps\":\"BTCUSDT\",\"b\":\"79716.80\",\"B\":\"2.600\",\"a\":\"79716.90\",\"A\":\"15.155\",\"T\":1788564463913,\"E\":1788564463914,\"st\":1}}"}
{"receive_ns":1788564463918843000,"stream":"btcusdt@bookTicker","event_type":"bookTicker","event_time_ms":1788564463938,"raw_json":"{\"stream\":\"btcusdt@bookTicker\",\"data\":{\"e\":\"bookTicker\",\"u\":11478297033610,\"s\":\"BTCUSDT\",\"ps\":\"BTCUSDT\",\"b\":\"79716.80\",\"B\":\"2.600\",\"a\":\"79716.90\",\"A\":\"15.161\",\"T\":1788564463938,\"E\":1788564463938,\"st\":1}}"}
{"receive_ns":1788564463973534000,"stream":"btcusdt@depth@100ms","event_type":"depthUpdate","event_time_ms":1788564463983,"raw_json":"{\"stream\":\"btcusdt@depth@100ms\",\"data\":{\"e\":\"depthUpdate\",\"E\":1788564463983,\"T\":1788564463981,\"s\":\"BTCUSDT\",\"ps\":\"BTCUSDT\",\"U\":11478297030364,\"u\":11478297036170,\"pu\":11478297030127,\"b\":[[\"1000.00\",\"24.754\"],[\"29316.80\",\"0.462\"],[\"29416.80\",\"1.638\"],[\"63774.00\",\"0.002\"],[\"71745.10\",\"0.002\"],[\"78919.60\",\"7.929\"],[\"79107.60\",\"0.010\"],[\"79318.20\",\"3.284\"],[\"79497.60\",\"0.502\"],[\"79500.80\",\"1.003\"],[\"79501.60\",\"0.859\"],[\"79529.50\",\"1.178\"],[\"79531.50\",\"0.757\"],[\"79555.30\",\"0.733\"],[\"79621.10\",\"0.038\"],[\"79716.80\",\"2.600\"]],\"a\":[[\"79716.90\",\"15.161\"],[\"79718.70\",\"1.395\"],[\"79772.80\",\"0.314\"],[\"79792.60\",\"0.002\"],[\"79866.40\",\"0.500\"],[\"79886.30\",\"0.090\"],[\"80085.60\",\"1.157\"],[\"80086.80\",\"0.778\"],[\"80115.50\",\"3.242\"],[\"80514.10\",\"5.823\"],[\"81311.20\",\"0.030\"],[\"81681.40\",\"0.001\"]],\"st\":1}}"}
{"receive_ns":1788564464059282000,"stream":"btcusdt@bookTicker","event_type":"bookTicker","event_time_ms":1788564464077,"raw_json":"{\"stream\":\"btcusdt@bookTicker\",\"data\":{\"e\":\"bookTicker\",\"u\":11478297041938,\"s\":\"BTCUSDT\",\"ps\":\"BTCUSDT\",\"b\":\"79716.80\",\"B\":\"2.600\",\"a\":\"79716.90\",\"A\":\"15.162\",\"T\":1788564464076,\"E\":1788564464077,\"st\":1}}"}
{"receive_ns":1788564464072668000,"stream":"btcusdt@depth@100ms","event_type":"depthUpdate","event_time_ms":1788564464085,"raw_json":"{\"stream\":\"btcusdt@depth@100ms\",\"data\":{\"e\":\"depthUpdate\",\"E\":1788564464085,\"T\":1788564464082,\"s\":\"BTCUSDT\",\"ps\":\"BTCUSDT\",\"U\":11478297036279,\"u\":11478297042283,\"pu\":11478297036170,\"b\":[[\"29316.80\",\"0.637\"],[\"29416.80\",\"1.463\"],[\"63774.00\",\"0.000\"],[\"71745.10\",\"0.002\"],[\"76528.10\",\"0.002\"],[\"78480.80\",\"0.028\"],[\"78919.60\",\"7.929\"],[\"78978.60\",\"0.000\"],[\"79318.20\",\"3.285\"],[\"79320.20\",\"0.140\"],[\"79529.50\",\"1.378\"],[\"79531.50\",\"0.757\"],[\"79645.00\",\"0.004\"],[\"79700.30\",\"0.250\"],[\"79701.50\",\"0.070\"],[\"79702.50\",\"0.000\"]],\"a\":[[\"79716.90\",\"15.162\"],[\"79772.80\",\"0.316\"],[\"79792.60\",\"0.451\"],[\"79866.40\",\"0.250\"],[\"80085.60\",\"1.157\"],[\"80454.90\",\"0.000\"],[\"80514.10\",\"5.823\"],[\"80673.50\",\"28.715\"],[\"80952.80\",\"0.022\"]],\"st\":1}}"}
{"receive_ns":1788564464168549000,"stream":"btcusdt@depth@100ms","event_type":"depthUpdate","event_time_ms":1788564464187,"raw_json":"{\"stream\":\"btcusdt@depth@100ms\",\"data\":{\"e\":\"depthUpdate\",\"E\":1788564464187,\"T\":1788564464186,\"s\":\"BTCUSDT\",\"ps\":\"BTCUSDT\",\"U\":11478297042482,\"u\":11478297048142,\"pu\":11478297042283,\"b\":[[\"1000.00\",\"24.754\"],[\"29316.80\",\"0.819\"],[\"29416.80\",\"1.281\"],[\"63773.00\",\"0.000\"],[\"71745.10\",\"0.002\"],[\"76528.10\",\"0.000\"],[\"78281.90\",\"1.720\"],[\"78480.80\",\"0.037\"],[\"78919.60\",\"7.929\"],[\"78978.80\",\"0.013\"],[\"79254.80\",\"0.192\"],[\"79497.60\",\"0.733\"],[\"79500.80\",\"1.003\"],[\"79501.60\",\"0.628\"],[\"79529.50\",\"1.378\"],[\"79621.10\",\"0.040\"],[\"79714.30\",\"0.530\"]],\"a\":[[\"79788.70\",\"0.023\"],[\"79866.40\",\"0.250\"],[\"79886.30\",\"0.090\"],[\"80085.60\",\"1.157\"],[\"80086.80\",\"0.778\"],[\"80514.10\",\"5.823\"]],\"st\":1}}"}
{"receive_ns":1788564464205791000,"stream":"btcusdt@bookTicker","event_type":"bookTicker","event_time_ms":1788564464226,"raw_json":"{\"stream\":\"btcusdt@bookTicker\",\"data\":{\"e\":\"bookTicker\",\"u\":11478297049964,\"s\":\"BTCUSDT\",\"ps\":\"BTCUSDT\",\"b\":\"79716.80\",\"B\":\"2.600\",\"a\":\"79716.90\",\"A\":\"15.150\",\"T\":1788564464226,\"E\":1788564464226,\"st\":1}}"}
{"receive_ns":1788564464218713000,"stream":"btcusdt@bookTicker","event_type":"bookTicker","event_time_ms":1788564464229,"raw_json":"{\"stream\":\"btcusdt@bookTicker\",\"data\":{\"e\":\"bookTicker\",\"u\":11478297050301,\"s\":\"BTCUSDT\",\"ps\":\"BTCUSDT\",\"b\":\"79716.80\",\"B\":\"2.600\",\"a\":\"79716.90\",\"A\":\"15.164\",\"T\":1788564464229,\"E\":1788564464229,\"st\":1}}"}
{"receive_ns":1788564464271254000,"stream":"btcusdt@depth@100ms","event_type":"depthUpdate","event_time_ms":1788564464289,"raw_json":"{\"stream\":\"btcusdt@depth@100ms\",\"data\":{\"e\":\"depthUpdate\",\"E\":1788564464289,\"T\":1788564464285,\"s\":\"BTCUSDT\",\"ps\":\"BTCUSDT\",\"U\":11478297048207,\"u\":11478297053435,\"pu\":11478297048142,\"b\":[[\"1000.00\",\"24.754\"],[\"29316.80\",\"0.994\"],[\"29416.80\",\"1.106\"],[\"71745.10\",\"0.002\"],[\"71782.00\",\"0.003\"],[\"75731.00\",\"0.069\"],[\"76528.10\",\"0.002\"],[\"78494.00\",\"0.212\"],[\"78919.60\",\"7.929\"],[\"79318.20\",\"3.275\"],[\"79350.00\",\"2.138\"],[\"79529.50\",\"1.378\"],[\"79531.50\",\"0.757\"],[\"79604.10\",\"0.454\"],[\"79712.30\",\"0.002\"],[\"79714.60\",\"0.026\"]],\"a\":[[\"79716.90\",\"15.164\"],[\"79792.60\",\"0.451\"],[\"80085.60\",\"1.157\"],[\"80455.00\",\"0.655\"],[\"80514.10\",\"5.823\"],[\"80952.90\",\"0.014\"],[\"81709.80\",\"0.980\"],[\"81829.40\",\"0.735\"]],\"st\":1}}"}
{"receive_ns":1788564464374714000,"stream":"btcusdt@depth@100ms","event_type":"depthUpdate","event_time_ms":1788564464391,"raw_json":"{\"stream\":\"btcusdt@depth@100ms\",\"data\":{\"e\":\"depthUpdate\",\"E\":1788564464391,\"T\":1788564464390,\"s\":\"BTCUSDT\",\"ps\":\"BTCUSDT\",\"U\":11478297053646,\"u\":11478297059254,\"pu\":11478297053435,\"b\":[[\"29316.80\",\"1.176\"],[\"29416.80\",\"0.924\"],[\"63773.40\",\"0.000\"],[\"63774.00\",\"0.000\"],[\"71745.10\",\"0.002\"],[\"71782.00\",\"0.000\"],[\"76528.10\",\"0.000\"],[\"78919.60\",\"7.930\"],[\"79320.20\",\"0.140\"],[\"79497.60\",\"0.502\"],[\"79500.80\",\"0.000\"],[\"79529.50\",\"0.200\"],[\"79531.50\",\"0.757\"],[\"79701.10\",\"0.147\"],[\"79701.50\",\"0.170\"],[\"79702.30\",\"0.032\"],[\"79712.40\",\"0.000\"],[\"79715.00\",\"0.028\"]],\"a\":[[\"79792.60\",\"0.201\"],[\"79866.40\",\"0.250\"],[\"79886.30\",\"0.000\"],[\"80085.60\",\"0.589\"],[\"80086.80\",\"0.016\"],[\"80514.10\",\"5.823\"],[\"81100.40\",\"0.000\"]],\"st\":1}}"}
{"receive_ns":1788564464391769000,"stream":"btcusdt@bookTicker","event_type":"bookTicker","event_time_ms":1788564464406,"raw_json":"{\"stream\":\"btcusdt@bookTicker\",\"data\":{\"e\":\"bookTicker\",\"u\":11478297060188,\"s\":\"BTCUSDT\",\"ps\":\"BTCUSDT\",\"b\":\"79716.80\",\"B\":\"2.600\",\"a\":\"79716.90\",\"A\":\"15.139\",\"T\":1788564464405,\"E\":1788564464406,\"st\":1}}"}
{"receive_ns":1788564464392576000,"stream":"btcusdt@bookTicker","event_type":"bookTicker","event_time_ms":1788564464406,"raw_json":"{\"stream\":\"btcusdt@bookTicker\",\"data\":{\"e\":\"bookTicker\",\"u\":11478297060199,\"s\":\"BTCUSDT\",\"ps\":\"BTCUSDT\",\"b\":\"79716.80\",\"B\":\"2.600\",\"a\":\"79716.90\",\"A\":\"15.138\",\"T\":1788564464406,\"E\":1788564464406,\"st\":1}}"}
{"receive_ns":1788564464404584000,"stream":"btcusdt@trade","event_type":"trade","event_time_ms":1788564464406,"raw_json":"{\"stream\":\"btcusdt@trade\",\"data\":{\"e\":\"trade\",\"E\":1788564464406,\"T\":1788564464405,\"s\":\"BTCUSDT\",\"t\":8054096505,\"p\":\"79716.90\",\"q\":\"0.025\",\"X\":\"MARKET\",\"m\":false,\"st\":1}}"}
{"receive_ns":1788564464410627000,"stream":"btcusdt@bookTicker","event_type":"bookTicker","event_time_ms":1788564464407,"raw_json":"{\"stream\":\"btcusdt@bookTicker\",\"data\":{\"e\":\"bookTicker\",\"u\":11478297060302,\"s\":\"BTCUSDT\",\"ps\":\"BTCUSDT\",\"b\":\"79716.80\",\"B\":\"2.600\",\"a\":\"79716.90\",\"A\":\"15.157\",\"T\":1788564464407,\"E\":1788564464407,\"st\":1}}"}
{"receive_ns":1788564464423508000,"stream":"btcusdt@bookTicker","event_type":"bookTicker","event_time_ms":1788564464407,"raw_json":"{\"stream\":\"btcusdt@bookTicker\",\"data\":{\"e\":\"bookTicker\",\"u\":11478297060327,\"s\":\"BTCUSDT\",\"ps\":\"BTCUSDT\",\"b\":\"79716.80\",\"B\":\"2.600\",\"a\":\"79716.90\",\"A\":\"15.159\",\"T\":1788564464407,\"E\":1788564464407,\"st\":1}}"}
{"receive_ns":1788564464429319000,"stream":"btcusdt@bookTicker","event_type":"bookTicker","event_time_ms":1788564464408,"raw_json":"{\"stream\":\"btcusdt@bookTicker\",\"data\":{\"e\":\"bookTicker\",\"u\":11478297060384,\"s\":\"BTCUSDT\",\"ps\":\"BTCUSDT\",\"b\":\"79716.80\",\"B\":\"2.600\",\"a\":\"79716.90\",\"A\":\"15.140\",\"T\":1788564464407,\"E\":1788564464408,\"st\":1}}"}
{"receive_ns":1788564464433092000,"stream":"btcusdt@bookTicker","event_type":"bookTicker","event_time_ms":1788564464408,"raw_json":"{\"stream\":\"btcusdt@bookTicker\",\"data\":{\"e\":\"bookTicker\",\"u\":11478297060386,\"s\":\"BTCUSDT\",\"ps\":\"BTCUSDT\",\"b\":\"79716.80\",\"B\":\"2.600\",\"a\":\"79716.90\",\"A\":\"15.138\",\"T\":1788564464408,\"E\":1788564464408,\"st\":1}}"}
{"receive_ns":1788564464446196000,"stream":"btcusdt@bookTicker","event_type":"bookTicker","event_time_ms":1788564464432,"raw_json":"{\"stream\":\"btcusdt@bookTicker\",\"data\":{\"e\":\"bookTicker\",\"u\":11478297061774,\"s\":\"BTCUSDT\",\"ps\":\"BTCUSDT\",\"b\":\"79716.80\",\"B\":\"2.600\",\"a\":\"79716.90\",\"A\":\"15.157\",\"T\":1788564464432,\"E\":1788564464432,\"st\":1}}"}
{"receive_ns":1788564464451884000,"stream":"btcusdt@bookTicker","event_type":"bookTicker","event_time_ms":1788564464432,"raw_json":"{\"stream\":\"btcusdt@bookTicker\",\"data\":{\"e\":\"bookTicker\",\"u\":11478297061778,\"s\":\"BTCUSDT\",\"ps\":\"BTCUSDT\",\"b\":\"79716.80\",\"B\":\"2.600\",\"a\":\"79716.90\",\"A\":\"15.159\",\"T\":1788564464432,\"E\":1788564464432,\"st\":1}}"}
{"receive_ns":1788564464458382000,"stream":"btcusdt@bookTicker","event_type":"bookTicker","event_time_ms":1788564464433,"raw_json":"{\"stream\":\"btcusdt@bookTicker\",\"data\":{\"e\":\"bookTicker\",\"u\":11478297061845,\"s\":\"BTCUSDT\",\"ps\":\"BTCUSDT\",\"b\":\"79716.80\",\"B\":\"2.600\",\"a\":\"79716.90\",\"A\":\"15.140\",\"T\":1788564464433,\"E\":1788564464433,\"st\":1}}"}
{"receive_ns":1788564464458595000,"stream":"btcusdt@bookTicker","event_type":"bookTicker","event_time_ms":1788564464433,"raw_json":"{\"stream\":\"btcusdt@bookTicker\",\"data\":{\"e\":\"bookTicker\",\"u\":11478297061855,\"s\":\"BTCUSDT\",\"ps\":\"BTCUSDT\",\"b\":\"79716.80\",\"B\":\"2.600\",\"a\":\"79716.90\",\"A\":\"15.138\",\"T\":1788564464433,\"E\":1788564464433,\"st\":1}}"}
{"receive_ns":1788564464458819000,"stream":"btcusdt@bookTicker","event_type":"bookTicker","event_time_ms":1788564464436,"raw_json":"{\"stream\":\"btcusdt@bookTicker\",\"data\":{\"e\":\"bookTicker\",\"u\":11478297062070,\"s\":\"BTCUSDT\",\"ps\":\"BTCUSDT\",\"b\":\"79716.80\",\"B\":\"2.600\",\"a\":\"79716.90\",\"A\":\"15.128\",\"T\":1788564464436,\"E\":1788564464436,\"st\":1}}"}
{"receive_ns":1788564464464488000,"stream":"btcusdt@bookTicker","event_type":"bookTicker","event_time_ms":1788564464438,"raw_json":"{\"stream\":\"btcusdt@bookTicker\",\"data\":{\"e\":\"bookTicker\",\"u\":11478297062310,\"s\":\"BTCUSDT\",\"ps\":\"BTCUSDT\",\"b\":\"79716.80\",\"B\":\"2.600\",\"a\":\"79716.90\",\"A\":\"15.136\",\"T\":1788564464438,\"E\":1788564464438,\"st\":1}}"}
{"receive_ns":1788564464475524000,"stream":"btcusdt@bookTicker","event_type":"bookTicker","event_time_ms":1788564464447,"raw_json":"{\"stream\":\"btcusdt@bookTicker\",\"data\":{\"e\":\"bookTicker\",\"u\":11478297062798,\"s\":\"BTCUSDT\",\"ps\":\"BTCUSDT\",\"b\":\"79716.80\",\"B\":\"2.566\",\"a\":\"79716.90\",\"A\":\"15.136\",\"T\":1788564464447,\"E\":1788564464447,\"st\":1}}"}
{"receive_ns":1788564464475775000,"stream":"btcusdt@bookTicker","event_type":"bookTicker","event_time_ms":1788564464450,"raw_json":"{\"stream\":\"btcusdt@bookTicker\",\"data\":{\"e\":\"bookTicker\",\"u\":11478297063150,\"s\":\"BTCUSDT\",\"ps\":\"BTCUSDT\",\"b\":\"79716.80\",\"B\":\"2.601\",\"a\":\"79716.90\",\"A\":\"15.136\",\"T\":1788564464450,\"E\":1788564464450,\"st\":1}}"}
{"receive_ns":1788564464482081000,"stream":"btcusdt@depth@100ms","event_type":"depthUpdate","event_time_ms":1788564464493,"raw_json":"{\"stream\":\"btcusdt@depth@100ms\",\"data\":{\"e\":\"depthUpdate\",\"E\":1788564464493,\"T\":1788564464490,\"s\":\"BTCUSDT\",\"ps\":\"BTCUSDT\",\"U\":11478297059383,\"u\":11478297065328,\"pu\":11478297059254,\"b\":[[\"1000.00\",\"24.754\"],[\"29316.80\",\"1.351\"],[\"29416.80\",\"0.749\"],[\"71745.10\",\"0.002\"],[\"73876.90\",\"0.002\"],[\"78122.50\",\"0.167\"],[\"78906.20\",\"1.400\"],[\"78919.60\",\"7.930\"],[\"79500.80\",\"1.003\"],[\"79501.60\",\"0.859\"],[\"79529.50\",\"1.178\"],[\"79531.50\",\"0.757\"],[\"79643.80\",\"1.915\"],[\"79651.20\",\"0.003\"],[\"79697.00\",\"0.000\"],[\"79698.60\",\"1.550\"],[\"79702.70\",\"0.033\"],[\"79712.50\",\"0.000\"],[\"79714.60\",\"0.000\"],[\"79714.90\",\"0.026\"],[\"79715.00\",\"0.002\"],[\"79715.50\",\"0.028\"],[\"79715.70\",\"0.026\"],[\"79716.80\",\"2.601\"]],\"a\":[[\"79716.90\",\"15.136\"],[\"79727.50\",\"0.948\"],[\"79740.30\",\"0.000\"],[\"79792.60\",\"0.002\"],[\"79866.40\",\"0.500\"],[\"79886.30\",\"0.090\"],[\"80085.60\",\"1.157\"],[\"80086.80\",\"0.778\"],[\"80472.60\",\"0.001\"],[\"80514.10\",\"5.823\"],[\"81159.00\",\"4.300\"],[\"81311.20\",\"0.027\"]],\"st\":1}}"}
{"receive_ns":1788564464488363000,"stream":"btcusdt@bookTicker","event_type":"bookTicker","event_time_ms":1788564464503,"raw_json":"{\"stream\":\"btcusdt@bookTicker\",\"data\":{\"e\":\"bookTicker\",\"u\":11478297066140,\"s\":\"BTCUSDT\",\"ps\":\"BTCUSDT\",\"b\":\"79716.80\",\"B\":\"2.588\",\"a\":\"79716.90\",\"A\":\"15.136\",\"T\":1788564464503,\"E\":1788564464503,\"st\":1}}"}
{"receive_ns":1788564464488634000,"stream":"btcusdt@trade","event_type":"trade","event_time_ms":1788564464503,"raw_json":"{\"stream\":\"btcusdt@trade\",\"data\":{\"e\":\"trade\",\"E\":1788564464503,\"T\":1788564464503,\"s\":\"BTCUSDT\",\"t\":8054096506,\"p\":\"79716.80\",\"q\":\"0.013\",\"X\":\"MARKET\",\"m\":true,\"st\":1}}"}
{"receive_ns":1788564464495233000,"stream":"btcusdt@bookTicker","event_type":"bookTicker","event_time_ms":1788564464505,"raw_json":"{\"stream\":\"btcusdt@bookTicker\",\"data\":{\"e\":\"bookTicker\",\"u\":11478297066234,\"s\":\"BTCUSDT\",\"ps\":\"BTCUSDT\",\"b\":\"79716.80\",\"B\":\"2.588\",\"a\":\"79716.90\",\"A\":\"15.155\",\"T\":1788564464504,\"E\":1788564464505,\"st\":1}}"}
{"receive_ns":1788564464501125000,"stream":"btcusdt@bookTicker","event_type":"bookTicker","event_time_ms":1788564464505,"raw_json":"{\"stream\":\"btcusdt@bookTicker\",\"data\":{\"e\":\"bookTicker\",\"u\":11478297066302,\"s\":\"BTCUSDT\",\"ps\":\"BTCUSDT\",\"b\":\"79716.80\",\"B\":\"2.588\",\"a\":\"79716.90\",\"A\":\"15.157\",\"T\":1788564464505,\"E\":1788564464505,\"st\":1}}"}
{"receive_ns":1788564464507700000,"stream":"btcusdt@bookTicker","event_type":"bookTicker","event_time_ms":1788564464505,"raw_json":"{\"stream\":\"btcusdt@bookTicker\",\"data\":{\"e\":\"bookTicker\",\"u\":11478297066396,\"s\":\"BTCUSDT\",\"ps\":\"BTCUSDT\",\"b\":\"79716.80\",\"B\":\"2.588\",\"a\":\"79716.90\",\"A\":\"15.138\",\"T\":1788564464505,\"E\":1788564464505,\"st\":1}}"}
{"receive_ns":1788564464513383000,"stream":"btcusdt@bookTicker","event_type":"bookTicker","event_time_ms":1788564464506,"raw_json":"{\"stream\":\"btcusdt@bookTicker\",\"data\":{\"e\":\"bookTicker\",\"u\":11478297066398,\"s\":\"BTCUSDT\",\"ps\":\"BTCUSDT\",\"b\":\"79716.80\",\"B\":\"2.588\",\"a\":\"79716.90\",\"A\":\"15.136\",\"T\":1788564464505,\"E\":1788564464506,\"st\":1}}"}
{"receive_ns":1788564464516125000,"stream":"btcusdt@bookTicker","event_type":"bookTicker","event_time_ms":1788564464516,"raw_json":"{\"stream\":\"btcusdt@bookTicker\",\"data\":{\"e\":\"bookTicker\",\"u\":11478297067058,\"s\":\"BTCUSDT\",\"ps\":\"BTCUSDT\",\"b\":\"79716.80\",\"B\":\"2.588\",\"a\":\"79716.90\",\"A\":\"15.155\",\"T\":1788564464516,\"E\":1788564464516,\"st\":1}}"}
{"receive_ns":1788564464516320000,"stream":"btcusdt@bookTicker","event_type":"bookTicker","event_time_ms":1788564464516,"raw_json":"{\"stream\":\"btcusdt@bookTicker\",\"data\":{\"e\":\"bookTicker\",\"u\":11478297067075,\"s\":\"BTCUSDT\",\"ps\":\"BTCUSDT\",\"b\":\"79716.80\",\"B\":\"2.588\",\"a\":\"79716.90\",\"A\":\"15.157\",\"T\":1788564464516,\"E\":1788564464516,\"st\":1}}"}
{"receive_ns":1788564464522865000,"stream":"btcusdt@bookTicker","event_type":"bookTicker","event_time_ms":1788564464517,"raw_json":"{\"stream\":\"btcusdt@bookTicker\",\"data\":{\"e\":\"bookTicker\",\"u\":11478297067189,\"s\":\"BTCUSDT\",\"ps\":\"BTCUSDT\",\"b\":\"79716.80\",\"B\":\"2.588\",\"a\":\"79716.90\",\"A\":\"15.138\",\"T\":1788564464517,\"E\":1788564464517,\"st\":1}}"}
{"receive_ns":1788564464523067000,"stream":"btcusdt@bookTicker","event_type":"bookTicker","event_time_ms":1788564464517,"raw_json":"{\"stream\":\"btcusdt@bookTicker\",\"data\":{\"e\":\"bookTicker\",\"u\":11478297067204,\"s\":\"BTCUSDT\",\"ps\":\"BTCUSDT\",\"b\":\"79716.80\",\"B\":\"2.588\",\"a\":\"79716.90\",\"A\":\"15.136\",\"T\":1788564464517,\"E\":1788564464517,\"st\":1}}"}
{"receive_ns":1788564464571422000,"stream":"btcusdt@depth@100ms","event_type":"depthUpdate","event_time_ms":1788564464595,"raw_json":"{\"stream\":\"btcusdt@depth@100ms\",\"data\":{\"e\":\"depthUpdate\",\"E\":1788564464595,\"T\":1788564464594,\"s\":\"BTCUSDT\",\"ps\":\"BTCUSDT\",\"U\":11478297065562,\"u\":11478297071970,\"pu\":11478297065328,\"b\":[[\"1000.00\",\"24.754\"],[\"29316.80\",\"1.533\"],[\"29416.80\",\"0.567\"],[\"63773.00\",\"0.000\"],[\"71745.10\",\"0.002\"],[\"76528.10\",\"0.002\"],[\"78122.50\",\"0.164\"],[\"78560.90\",\"6.050\"],[\"78919.60\",\"7.930\"],[\"79079.10\",\"6.691\"],[\"79318.20\",\"3.285\"],[\"79320.20\",\"0.140\"],[\"79529.50\",\"1.378\"],[\"79531.50\",\"0.757\"],[\"79581.20\",\"0.002\"],[\"79693.10\",\"0.003\"],[\"79697.40\",\"0.002\"],[\"79698.20\",\"0.002\"],[\"79702.50\",\"0.000\"],[\"79703.30\",\"0.000\"],[\"79703.50\",\"0.003\"],[\"79703.60\",\"0.252\"],[\"79712.40\",\"0.026\"],[\"79712.50\",\"0.026\"],[\"79713.60\",\"0.028\"],[\"79714.10\",\"0.026\"],[\"79714.30\",\"0.504\"],[\"79714.90\",\"0.000\"],[\"79715.50\",\"0.002\"],[\"79715.70\",\"0.000\"],[\"79715.90\",\"0.320\"],[\"79716.20\",\"0.000\"],[\"79716.80\",\"2.588\"]],\"a\":[[\"79716.90\",\"15.136\"],[\"79725.20\",\"1.982\"],[\"79727.30\",\"0.703\"],[\"79727.80\",\"0.008\"],[\"79733.00\",\"0.630\"],[\"79790.30\",\"0.025\"],[\"79792.60\",\"0.252\"],[\"79812.60\",\"0.002\"],[\"79866.40\",\"0.449\"],[\"80085.60\",\"1.157\"],[\"80115.50\",\"3.241\"],[\"80514.10\",\"5.823\"],[\"80825.00\",\"5.781\"]],\"st\":1}}"}
{"receive_ns":1788564464585261000,"stream":"btcusdt@bookTicker","event_type":"bookTicker","event_time_ms":1788564464604,"raw_json":"{\"stream\":\"btcusdt@bookTicker\",\"data\":{\"e\":\"bookTicker\",\"u\":11478297072744,\"s\":\"BTCUSDT\",\"ps\":\"BTCUSDT\",\"b\":\"79716.80\",\"B\":\"2.581\",\"a\":\"79716.90\",\"A\":\"15.136\",\"T\":1788564464604,\"E\":1788564464604,\"st\":1}}"}
{"receive_ns":1788564464591571000,"stream":"btcusdt@bookTicker","event_type":"bookTicker","event_time_ms":1788564464606,"raw_json":"{\"stream\":\"btcusdt@bookTicker\",\"data\":{\"e\":\"bookTicker\",\"u\":11478297072823,\"s\":\"BTCUSDT\",\"ps\":\"BTCUSDT\",\"b\":\"79716.80\",\"B\":\"2.581\",\"a\":\"79716.90\",\"A\":\"15.137\",\"T\":1788564464605,\"E\":1788564464606,\"st\":1}}"}
{"receive_ns":1788564464647637000,"stream":"btcusdt@bookTicker","event_type":"bookTicker","event_time_ms":1788564464671,"raw_json":"{\"stream\":\"btcusdt@bookTicker\",\"data\":{\"e\":\"bookTicker\",\"u\":11478297076245,\"s\":\"BTCUSDT\",\"ps\":\"BTCUSDT\",\"b\":\"79716.80\",\"B\":\"2.581\",\"a\":\"79716.90\",\"A\":\"15.156\",\"T\":1788564464671,\"E\":1788564464671,\"st\":1}}"}
{"receive_ns":1788564464653416000,"stream":"btcusdt@bookTicker","event_type":"bookTicker","event_time_ms":1788564464672,"raw_json":"{\"stream\":\"btcusdt@bookTicker\",\"data\":{\"e\":\"bookTicker\",\"u\":11478297076283,\"s\":\"BTCUSDT\",\"ps\":\"BTCUSDT\",\"b\":\"79716.80\",\"B\":\"2.581\",\"a\":\"79716.90\",\"A\":\"15.137\",\"T\":1788564464672,\"E\":1788564464672,\"st\":1}}"}
{"receive_ns":1788564464673696000,"stream":"btcusdt@depth@100ms","event_type":"depthUpdate","event_time_ms":1788564464697,"raw_json":"{\"stream\":\"btcusdt@depth@100ms\",\"data\":{\"e\":\"depthUpdate\",\"E\":1788564464697,\"T\":1788564464696,\"s\":\"BTCUSDT\",\"ps\":\"BTCUSDT\",\"U\":11478297072124,\"u\":11478297077494,\"pu\":11478297071970,\"b\":[[\"29316.80\",\"1.708\"],[\"29416.80\",\"0.392\"],[\"63773.00\",\"0.000\"],[\"71745.10\",\"0.002\"],[\"75730.90\",\"0.039\"],[\"76528.10\",\"0.000\"],[\"78600.80\",\"19.210\"],[\"78640.60\",\"1.144\"],[\"78752.90\",\"1.460\"],[\"78919.60\",\"7.930\"],[\"79318.20\",\"3.286\"],[\"79500.80\",\"1.003\"],[\"79501.60\",\"0.859\"],[\"79507.20\",\"4.885\"],[\"79529.50\",\"1.378\"],[\"79531.50\",\"0.256\"],[\"79594.50\",\"0.592\"],[\"79625.60\",\"3.868\"],[\"79627.50\",\"0.716\"],[\"79631.90\",\"0.010\"],[\"79689.40\",\"0.003\"],[\"79690.90\",\"0.452\"],[\"79716.80\",\"2.581\"]],\"a\":[[\"79716.90\",\"15.156\"],[\"79725.10\",\"0.705\"],[\"79727.30\",\"0.076\"],[\"79807.90\",\"3.327\"],[\"79840.10\",\"0.246\"],[\"79866.40\",\"0.449\"],[\"79886.30\",\"0.090\"],[\"79927.40\",\"7.571\"],[\"79927.50\",\"0.000\"],[\"79938.80\",\"8.426\"],[\"80085.60\",\"0.739\"],[\"80086.80\",\"0.778\"],[\"80490.20\",\"1.218\"],[\"80514.10\",\"5.823\"],[\"80673.50\",\"27.477\"],[\"80713.40\",\"7.764\"],[\"80832.90\",\"23.910\"],[\"81151.80\",\"1.279\"]],\"st\":1}}"}
{"receive_ns":1788564464673992000,"stream":"btcusdt@bookTicker","event_type":"bookTicker","event_time_ms":1788564464696,"raw_json":"{\"stream\":\"btcusdt@bookTicker\",\"data\":{\"e\":\"bookTicker\",\"u\":11478297077494,\"s\":\"BTCUSDT\",\"ps\":\"BTCUSDT\",\"b\":\"79716.80\",\"B\":\"2.581\",\"a\":\"79716.90\",\"A\":\"15.156\",\"T\":1788564464696,\"E\":1788564464696,\"st\":1}}"}
{"receive_ns":1788564464674194000,"stream":"btcusdt@bookTicker","event_type":"bookTicker","event_time_ms":1788564464697,"raw_json":"{\"stream\":\"btcusdt@bookTicker\",\"data\":{\"e\":\"bookTicker\",\"u\":11478297077544,\"s\":\"BTCUSDT\",\"ps\":\"BTCUSDT\",\"b\":\"79716.80\",\"B\":\"2.581\",\"a\":\"79716.90\",\"A\":\"15.137\",\"T\":1788564464697,\"E\":1788564464697,\"st\":1}}"}
{"receive_ns":1788564464698207000,"stream":"btcusdt@bookTicker","event_type":"bookTicker","event_time_ms":1788564464721,"raw_json":"{\"stream\":\"btcusdt@bookTicker\",\"data\":{\"e\":\"bookTicker\",\"u\":11478297078906,\"s\":\"BTCUSDT\",\"ps\":\"BTCUSDT\",\"b\":\"79716.80\",\"B\":\"2.581\",\"a\":\"79716.90\",\"A\":\"15.156\",\"T\":1788564464721,\"E\":1788564464721,\"st\":1}}"}
{"receive_ns":1788564464704202000,"stream":"btcusdt@bookTicker","event_type":"bookTicker","event_time_ms":1788564464722,"raw_json":"{\"stream\":\"btcusdt@bookTicker\",\"data\":{\"e\":\"bookTicker\",\"u\":11478297078981,\"s\":\"BTCUSDT\",\"ps\":\"BTCUSDT\",\"b\":\"79716.80\",\"B\":\"2.581\",\"a\":\"79716.90\",\"A\":\"15.137\",\"T\":1788564464722,\"E\":1788564464722,\"st\":1}}"}
{"receive_ns":1788564464711121000,"stream":"btcusdt@bookTicker","event_type":"bookTicker","event_time_ms":1788564464728,"raw_json":"{\"stream\":\"btcusdt@bookTicker\",\"data\":{\"e\":\"bookTicker\",\"u\":11478297079392,\"s\":\"BTCUSDT\",\"ps\":\"BTCUSDT\",\"b\":\"79716.80\",\"B\":\"2.579\",\"a\":\"79716.90\",\"A\":\"15.137\",\"T\":1788564464728,\"E\":1788564464728,\"st\":1}}"}
{"receive_ns":1788564464711367000,"stream":"btcusdt@trade","event_type":"trade","event_time_ms":1788564464728,"raw_json":"{\"stream\":\"btcusdt@trade\",\"data\":{\"e\":\"trade\",\"E\":1788564464728,\"T\":1788564464728,\"s\":\"BTCUSDT\",\"t\":8054096507,\"p\":\"79716.80\",\"q\":\"0.002\",\"X\":\"MARKET\",\"m\":true,\"st\":1}}"}
{"receive_ns":1788564464723295000,"stream":"btcusdt@bookTicker","event_type":"bookTicker","event_time_ms":1788564464729,"raw_json":"{\"stream\":\"btcusdt@bookTicker\",\"data\":{\"e\":\"bookTicker\",\"u\":11478297079458,\"s\":\"BTCUSDT\",\"ps\":\"BTCUSDT\",\"b\":\"79716.80\",\"B\":\"2.579\",\"a\":\"79716.90\",\"A\":\"15.156\",\"T\":1788564464729,\"E\":1788564464729,\"st\":1}}"}
{"receive_ns":1788564464723552000,"stream":"btcusdt@bookTicker","event_type":"bookTicker","event_time_ms":1788564464729,"raw_json":"{\"stream\":\"btcusdt@bookTicker\",\"data\":{\"e\":\"bookTicker\",\"u\":11478297079565,\"s\":\"BTCUSDT\",\"ps\":\"BTCUSDT\",\"b\":\"79716.80\",\"B\":\"2.579\",\"a\":\"79716.90\",\"A\":\"15.158\",\"T\":1788564464729,\"E\":1788564464729,\"st\":1}}"}
{"receive_ns":1788564464723795000,"stream":"btcusdt@bookTicker","event_type":"bookTicker","event_time_ms":1788564464730,"raw_json":"{\"stream\":\"btcusdt@bookTicker\",\"data\":{\"e\":\"bookTicker\",\"u\":11478297079657,\"s\":\"BTCUSDT\",\"ps\":\"BTCUSDT\",\"b\":\"79716.80\",\"B\":\"2.579\",\"a\":\"79716.90\",\"A\":\"15.139\",\"T\":1788564464730,\"E\":1788564464730,\"st\":1}}"}
{"receive_ns":1788564464729435000,"stream":"btcusdt@bookTicker","event_type":"bookTicker","event_time_ms":1788564464730,"raw_json":"{\"stream\":\"btcusdt@bookTicker\",\"data\":{\"e\":\"bookTicker\",\"u\":11478297079701,\"s\":\"BTCUSDT\",\"ps\":\"BTCUSDT\",\"b\":\"79716.80\",\"B\":\"2.579\",\"a\":\"79716.90\",\"A\":\"15.137\",\"T\":1788564464730,\"E\":1788564464730,\"st\":1}}"}
{"receive_ns":1788564464779505000,"stream":"btcusdt@depth@100ms","event_type":"depthUpdate","event_time_ms":1788564464799,"raw_json":"{\"stream\":\"btcusdt@depth@100ms\",\"data\":{\"e\":\"depthUpdate\",\"E\":1788564464799,\"T\":1788564464798,\"s\":\"BTCUSDT\",\"ps\":\"BTCUSDT\",\"U\":11478297077544,\"u\":11478297083499,\"pu\":11478297077494,\"b\":[[\"1000.00\",\"24.754\"],[\"29216.80\",\"0.049\"],[\"29316.80\",\"1.792\"],[\"29416.80\",\"0.259\"],[\"71745.10\",\"0.002\"],[\"76528.10\",\"0.002\"],[\"78919.60\",\"7.930\"],[\"79320.20\",\"0.000\"],[\"79529.50\",\"1.879\"],[\"79531.50\",\"0.006\"],[\"79627.50\",\"1.362\"],[\"79669.50\",\"0.080\"],[\"79689.40\",\"0.454\"],[\"79690.90\",\"0.001\"],[\"79695.10\",\"0.440\"],[\"79696.50\",\"0.361\"],[\"79702.60\",\"0.348\"],[\"79703.50\",\"0.002\"],[\"79708.90\",\"1.540\"],[\"79709.20\",\"0.001\"],[\"79712.00\",\"0.042\"],[\"79712.20\",\"0.028\"],[\"79712.30\",\"0.028\"],[\"79713.00\",\"0.001\"],[\"79713.20\",\"0.001\"],[\"79713.40\",\"0.000\"],[\"79713.50\",\"0.002\"],[\"79713.60\",\"0.028\"],[\"79714.10\",\"0.000\"],[\"79716.80\",\"2.579\"]],\"a\":[[\"79716.90\",\"15.137\"],[\"79792.60\",\"0.201\"],[\"79866.40\",\"0.250\"],[\"80085.60\",\"1.002\"],[\"80514.10\",\"5.823\"],[\"80879.50\",\"2.762\"],[\"81311.20\",\"0.030\"]],\"st\":1}}"}
{"receive_ns":1788564464806938000,"stream":"btcusdt@bookTicker","event_type":"bookTicker","event_time_ms":1788564464826,"raw_json":"{\"stream\":\"btcusdt@bookTicker\",\"data\":{\"e\":\"bookTicker\",\"u\":11478297085315,\"s\":\"BTCUSDT\",\"ps\":\"BTCUSDT\",\"b\":\"79716.80\",\"B\":\"2.579\",\"a\":\"79716.90\",\"A\":\"15.156\",\"T\":1788564464826,\"E\":1788564464826,\"st\":1}}"}
{"receive_ns":1788564464822329000,"stream":"btcusdt@bookTicker","event_type":"bookTicker","event_time_ms":1788564464826,"raw_json":"{\"stream\":\"btcusdt@bookTicker\",\"data\":{\"e\":\"bookTicker\",\"u\":11478297085353,\"s\":\"BTCUSDT\",\"ps\":\"BTCUSDT\",\"b\":\"79716.80\",\"B\":\"2.579\",\"a\":\"79716.90\",\"A\":\"15.137\",\"T\":1788564464826,\"E\":1788564464826,\"st\":1}}"}
{"receive_ns":1788564464835193000,"stream":"btcusdt@bookTicker","event_type":"bookTicker","event_time_ms":1788564464856,"raw_json":"{\"stream\":\"btcusdt@bookTicker\",\"data\":{\"e\":\"bookTicker\",\"u\":11478297087022,\"s\":\"BTCUSDT\",\"ps\":\"BTCUSDT\",\"b\":\"79716.80\",\"B\":\"2.579\",\"a\":\"79716.90\",\"A\":\"15.156\",\"T\":1788564464856,\"E\":1788564464856,\"st\":1}}"}
{"receive_ns":1788564464847077000,"stream":"btcusdt@bookTicker","event_type":"bookTicker","event_time_ms":1788564464857,"raw_json":"{\"stream\":\"btcusdt@bookTicker\",\"data\":{\"e\":\"bookTicker\",\"u\":11478297087049,\"s\":\"BTCUSDT\",\"ps\":\"BTCUSDT\",\"b\":\"79716.80\",\"B\":\"2.579\",\"a\":\"79716.90\",\"A\":\"15.137\",\"T\":1788564464856,\"E\":1788564464857,\"st\":1}}"}
{"receive_ns":1788564464870784000,"stream":"btcusdt@bookTicker","event_type":"bookTicker","event_time_ms":1788564464892,"raw_json":"{\"stream\":\"btcusdt@bookTicker\",\"data\":{\"e\":\"bookTicker\",\"u\":11478297088738,\"s\":\"BTCUSDT\",\"ps\":\"BTCUSDT\",\"b\":\"79716.80\",\"B\":\"2.579\",\"a\":\"79716.90\",\"A\":\"15.138\",\"T\":1788564464891,\"E\":1788564464892,\"st\":1}}"}
{"receive_ns":1788564464888062000,"stream":"btcusdt@depth@100ms","event_type":"depthUpdate","event_time_ms":1788564464901,"raw_json":"{\"stream\":\"btcusdt@depth@100ms\",\"data\":{\"e\":\"depthUpdate\",\"E\":1788564464901,\"T\":1788564464900,\"s\":\"BTCUSDT\",\"ps\":\"BTCUSDT\",\"U\":11478297083564,\"u\":11478297089431,\"pu\":11478297083499,\"b\":[[\"1000.00\",\"24.754\"],[\"29216.80\",\"0.105\"],[\"29316.80\",\"1.855\"],[\"29416.80\",\"0.140\"],[\"63773.00\",\"0.002\"],[\"71745.10\",\"0.002\"],[\"78469.80\",\"0.858\"],[\"78760.20\",\"28.082\"],[\"78919.60\",\"7.932\"],[\"79318.20\",\"3.276\"],[\"79320.20\",\"0.140\"],[\"79497.60\",\"0.733\"],[\"79500.80\",\"1.003\"],[\"79501.60\",\"0.628\"],[\"79529.50\",\"0.801\"],[\"79531.50\",\"0.256\"],[\"79693.30\",\"0.374\"],[\"79694.30\",\"0.001\"],[\"79699.20\",\"0.065\"],[\"79700.10\",\"0.216\"],[\"79700.80\",\"0.318\"],[\"79702.60\",\"0.347\"],[\"79703.40\",\"0.290\"],[\"79703.50\",\"0.003\"],[\"79712.00\",\"0.016\"],[\"79712.20\",\"0.002\"],[\"79714.10\",\"0.026\"],[\"79714.30\",\"0.530\"],[\"79714.40\",\"0.028\"]],\"a\":[[\"79716.90\",\"15.138\"],[\"79733.30\",\"0.016\"],[\"79734.90\",\"0.372\"],[\"79735.40\",\"0.000\"],[\"79738.30\",\"0.086\"],[\"79739.60\",\"0.455\"],[\"79740.40\",\"0.000\"],[\"79741.40\",\"0.003\"],[\"79801.00\",\"0.122\"],[\"79866.40\",\"0.500\"],[\"79886.30\",\"0.090\"],[\"80085.60\",\"0.589\"],[\"80086.80\",\"0.778\"],[\"80514.10\",\"5.823\"]],\"st\":1}}"}
{"receive_ns":1788564464893444000,"stream":"btcusdt@bookTicker","event_type":"bookTicker","event_time_ms":1788564464901,"raw_json":"{\"stream\":\"btcusdt@bookTicker\",\"data\":{\"e\":\"bookTicker\",\"u\":11478297089470,\"s\":\"BTCUSDT\",\"ps\":\"BTCUSDT\",\"b\":\"79716.80\",\"B\":\"2.579\",\"a\":\"79716.90\",\"A\":\"15.137\",\"T\":1788564464901,\"E\":1788564464901,\"st\":1}}"}
{"receive_ns":1788564464893679000,"stream":"btcusdt@trade","event_type":"trade","event_time_ms":1788564464901,"raw_json":"{\"stream\":\"btcusdt@trade\",\"data\":{\"e\":\"trade\",\"E\":1788564464901,\"T\":1788564464901,\"s\":\"BTCUSDT\",\"t\":8054096508,\"p\":\"79716.90\",\"q\":\"0.001\",\"X\":\"MARKET\",\"m\":false,\"st\":1}}"}
{"receive_ns":1788564464905027000,"stream":"btcusdt@bookTicker","event_type":"bookTicker","event_time_ms":1788564464902,"raw_json":"{\"stream\":\"btcusdt@bookTicker\",\"data\":{\"e\":\"bookTicker\",\"u\":11478297089565,\"s\":\"BTCUSDT\",\"ps\":\"BTCUSDT\",\"b\":\"79716.80\",\"B\":\"2.579\",\"a\":\"79716.90\",\"A\":\"15.156\",\"T\":1788564464902,\"E\":1788564464902,\"st\":1}}"}
{"receive_ns":1788564464910877000,"stream":"btcusdt@bookTicker","event_type":"bookTicker","event_time_ms":1788564464902,"raw_json":"{\"stream\":\"btcusdt@bookTicker\",\"data\":{\"e\":\"bookTicker\",\"u\":11478297089588,\"s\":\"BTCUSDT\",\"ps\":\"BTCUSDT\",\"b\":\"79716.80\",\"B\":\"2.579\",\"a\":\"79716.90\",\"A\":\"15.158\",\"T\":1788564464902,\"E\":1788564464902,\"st\":1}}"}
{"receive_ns":1788564464922951000,"stream":"btcusdt@bookTicker","event_type":"bookTicker","event_time_ms":1788564464903,"raw_json":"{\"stream\":\"btcusdt@bookTicker\",\"data\":{\"e\":\"bookTicker\",\"u\":11478297089659,\"s\":\"BTCUSDT\",\"ps\":\"BTCUSDT\",\"b\":\"79716.80\",\"B\":\"2.579\",\"a\":\"79716.90\",\"A\":\"15.156\",\"T\":1788564464903,\"E\":1788564464903,\"st\":1}}"}
{"receive_ns":1788564464923179000,"stream":"btcusdt@bookTicker","event_type":"bookTicker","event_time_ms":1788564464903,"raw_json":"{\"stream\":\"btcusdt@bookTicker\",\"data\":{\"e\":\"bookTicker\",\"u\":11478297089662,\"s\":\"BTCUSDT\",\"ps\":\"BTCUSDT\",\"b\":\"79716.80\",\"B\":\"2.579\",\"a\":\"79716.90\",\"A\":\"15.137\",\"T\":1788564464903,\"E\":1788564464903,\"st\":1}}"}
{"receive_ns":1788564464985679000,"stream":"btcusdt@depth@100ms","event_type":"depthUpdate","event_time_ms":1788564465003,"raw_json":"{\"stream\":\"btcusdt@depth@100ms\",\"data\":{\"e\":\"depthUpdate\",\"E\":1788564465003,\"T\":1788564465002,\"s\":\"BTCUSDT\",\"ps\":\"BTCUSDT\",\"U\":11478297089470,\"u\":11478297094815,\"pu\":11478297089431,\"b\":[[\"29216.80\",\"0.168\"],[\"29316.80\",\"1.911\"],[\"29416.80\",\"0.021\"],[\"63773.00\",\"0.000\"],[\"71745.10\",\"0.002\"],[\"73761.90\",\"0.026\"],[\"76528.10\",\"0.000\"],[\"78760.20\",\"29.350\"],[\"78919.60\",\"7.930\"],[\"79529.50\",\"1.604\"],[\"79531.50\",\"0.456\"],[\"79653.00\",\"0.077\"],[\"79699.20\",\"0.382\"],[\"79700.80\",\"0.001\"],[\"79701.00\",\"0.020\"],[\"79701.10\",\"0.147\"],[\"79701.20\",\"0.000\"],[\"79702.50\",\"0.001\"],[\"79703.80\",\"0.647\"],[\"79703.90\",\"0.078\"],[\"79712.30\",\"0.002\"],[\"79712.40\",\"0.000\"],[\"79715.10\",\"0.026\"],[\"79715.30\",\"0.027\"]],\"a\":[[\"79716.90\",\"15.137\"],[\"79736.40\",\"2.719\"],[\"79790.30\",\"0.039\"],[\"79792.60\",\"0.002\"],[\"79866.40\",\"0.699\"],[\"80085.60\",\"1.157\"],[\"80514.10\",\"5.823\"],[\"80673.50\",\"28.715\"],[\"80832.90\",\"25.764\"],[\"80872.80\",\"7.562\"]],\"st\":1}}"}
{"receive_ns":1788564465088385000,"stream":"btcusdt@depth@100ms","event_type":"depthUpdate","event_time_ms":1788564465105,"raw_json":"{\"stream\":\"btcusdt@depth@100ms\",\"data\":{\"e\":\"depthUpdate\",\"E\":1788564465105,\"T\":1788564465104,\"s\":\"BTCUSDT\",\"ps\":\"BTCUSDT\",\"U\":11478297094972,\"u\":11478297100801,\"pu\":11478297094815,\"b\":[[\"1000.00\",\"24.754\"],[\"29216.80\",\"0.322\"],[\"29316.80\",\"1.778\"],[\"29416.80\",\"0.000\"],[\"63773.00\",\"0.000\"],[\"63774.00\",\"0.000\"],[\"71745.10\",\"0.002\"],[\"76528.10\",\"0.002\"],[\"78394.20\",\"0.011\"],[\"78480.80\",\"0.030\"],[\"78553.60\",\"0.001\"],[\"78560.50\",\"0.024\"],[\"78560.90\",\"6.940\"],[\"78607.30\",\"0.000\"],[\"78629.20\",\"4.765\"],[\"78640.60\",\"1.651\"],[\"78792.70\",\"0.359\"],[\"78800.10\",\"1.674\"],[\"78919.60\",\"7.930\"],[\"79318.20\",\"3.275\"],[\"79320.20\",\"0.140\"],[\"79531.50\",\"0.456\"],[\"79699.20\",\"0.378\"],[\"79700.80\",\"0.005\"],[\"79702.50\",\"0.001\"],[\"79715.10\",\"0.000\"],[\"79715.30\",\"0.001\"]],\"a\":[[\"79866.40\",\"0.699\"],[\"80085.60\",\"1.157\"],[\"80115.50\",\"3.242\"],[\"80514.10\",\"5.823\"],[\"80873.10\",\"0.013\"],[\"80952.80\",\"0.015\"]],\"st\":1}}"}
{"receive_ns":1788564465101948000,"stream":"btcusdt@bookTicker","event_type":"bookTicker","event_time_ms":1788564465120,"raw_json":"{\"stream\":\"btcusdt@bookTicker\",\"data\":{\"e\":\"bookTicker\",\"u\":11478297101788,\"s\":\"BTCUSDT\",\"ps\":\"BTCUSDT\",\"b\":\"79716.80\",\"B\":\"2.579\",\"a\":\"79716.90\",\"A\":\"15.156\",\"T\":1788564465120,\"E\":1788564465120,\"st\":1}}"}
{"receive_ns":1788564465109679000,"stream":"btcusdt@bookTicker","event_type":"bookTicker","event_time_ms":1788564465121,"raw_json":"{\"stream\":\"btcusdt@bookTicker\",\"data\":{\"e\":\"bookTicker\",\"u\":11478297101811,\"s\":\"BTCUSDT\",\"ps\":\"BTCUSDT\",\"b\":\"79716.80\",\"B\":\"2.579\",\"a\":\"79716.90\",\"A\":\"15.137\",\"T\":1788564465121,\"E\":1788564465121,\"st\":1}}"}
{"receive_ns":1788564465133790000,"stream":"btcusdt@bookTicker","event_type":"bookTicker","event_time_ms":1788564465151,"raw_json":"{\"stream\":\"btcusdt@bookTicker\",\"data\":{\"e\":\"bookTicker\",\"u\":11478297103667,\"s\":\"BTCUSDT\",\"ps\":\"BTCUSDT\",\"b\":\"79716.80\",\"B\":\"2.579\",\"a\":\"79716.90\",\"A\":\"15.134\",\"T\":1788564465151,\"E\":1788564465151,\"st\":1}}"}
{"receive_ns":1788564465139698000,"stream":"btcusdt@bookTicker","event_type":"bookTicker","event_time_ms":1788564465154,"raw_json":"{\"stream\":\"btcusdt@bookTicker\",\"data\":{\"e\":\"bookTicker\",\"u\":11478297103825,\"s\":\"BTCUSDT\",\"ps\":\"BTCUSDT\",\"b\":\"79716.80\",\"B\":\"2.581\",\"a\":\"79716.90\",\"A\":\"15.134\",\"T\":1788564465154,\"E\":1788564465154,\"st\":1}}"}
{"receive_ns":1788564465146400000,"stream":"btcusdt@bookTicker","event_type":"bookTicker","event_time_ms":1788564465160,"raw_json":"{\"stream\":\"btcusdt@bookTicker\",\"data\":{\"e\":\"bookTicker\",\"u\":11478297104275,\"s\":\"BTCUSDT\",\"ps\":\"BTCUSDT\",\"b\":\"79716.80\",\"B\":\"2.581\",\"a\":\"79716.90\",\"A\":\"15.138\",\"T\":1788564465160,\"E\":1788564465160,\"st\":1}}"}
{"receive_ns":1788564465192381000,"stream":"btcusdt@depth@100ms","event_type":"depthUpdate","event_time_ms":1788564465207,"raw_json":"{\"stream\":\"btcusdt@depth@100ms\",\"data\":{\"e\":\"depthUpdate\",\"E\":1788564465207,\"T\":1788564465201,\"s\":\"BTCUSDT\",\"ps\":\"BTCUSDT\",\"U\":11478297100902,\"u\":11478297106791,\"pu\":11478297100801,\"b\":[[\"1000.00\",\"24.754\"],[\"29216.80\",\"0.497\"],[\"29316.80\",\"1.603\"],[\"71745.10\",\"0.002\"],[\"76528.10\",\"0.000\"],[\"78401.50\",\"0.892\"],[\"78480.80\",\"0.037\"],[\"78560.50\",\"0.031\"],[\"78653.30\",\"3.510\"],[\"78919.60\",\"7.930\"],[\"79318.20\",\"3.285\"],[\"79497.60\",\"0.733\"],[\"79500.80\",\"1.003\"],[\"79529.50\",\"1.679\"],[\"79531.50\",\"0.256\"],[\"79653.00\",\"0.002\"],[\"79664.40\",\"0.000\"],[\"79699.20\",\"0.316\"],[\"79700.80\",\"0.067\"],[\"79716.80\",\"2.581\"]],\"a\":[[\"79716.90\",\"15.138\"],[\"79776.10\",\"0.002\"],[\"79866.40\",\"0.500\"],[\"79886.30\",\"0.090\"],[\"80085.60\",\"1.157\"],[\"80086.80\",\"0.778\"],[\"80514.10\",\"5.823\"],[\"80680.20\",\"3.073\"],[\"80839.60\",\"1.837\"],[\"80847.20\",\"0.618\"]],\"st\":1}}"}
{"receive_ns":1788564465292389000,"stream":"btcusdt@depth@100ms","event_type":"depthUpdate","event_time_ms":1788564465309,"raw_json":"{\"stream\":\"btcusdt@depth@100ms\",\"data\":{\"e\":\"depthUpdate\",\"E\":1788564465309,\"T\":1788564465307,\"s\":\"BTCUSDT\",\"ps\":\"BTCUSDT\",\"U\":11478297107118,\"u\":11478297112153,\"pu\":11478297106791,\"b\":[[\"29216.80\",\"0.679\"],[\"29316.80\",\"1.421\"],[\"71745.10\",\"0.002\"],[\"76528.10\",\"0.002\"],[\"78680.50\",\"6.474\"],[\"78919.60\",\"7.932\"],[\"79320.20\",\"0.000\"],[\"79531.50\",\"0.206\"],[\"79570.40\",\"0.000\"],[\"79570.50\",\"1.882\"],[\"79581.20\",\"0.000\"],[\"79621.10\",\"0.038\"],[\"79645.00\",\"0.004\"],[\"79699.30\",\"0.069\"],[\"79700.10\",\"0.006\"],[\"79700.80\",\"0.001\"],[\"79703.40\",\"0.020\"],[\"79713.40\",\"0.026\"],[\"79713.50\",\"0.028\"],[\"79714.30\",\"0.504\"],[\"79714.40\",\"0.002\"],[\"79714.80\",\"0.026\"],[\"79715.10\",\"0.000\"],[\"79715.40\",\"0.027\"]],\"a\":[[\"79718.90\",\"0.000\"],[\"79772.80\",\"0.316\"],[\"79788.70\",\"0.021\"],[\"79792.60\",\"0.201\"],[\"79812.60\",\"0.000\"],[\"79839.30\",\"1.901\"],[\"79866.40\",\"0.250\"],[\"80085.60\",\"1.002\"],[\"80514.10\",\"5.823\"],[\"80873.10\",\"0.020\"],[\"80959.20\",\"0.992\"],[\"81311.20\",\"0.033\"]],\"st\":1}}"}
{"receive_ns":1788564465352424000,"stream":"btcusdt@bookTicker","event_type":"bookTicker","event_time_ms":1788564465369,"raw_json":"{\"stream\":\"btcusdt@bookTicker\",\"data\":{\"e\":\"bookTicker\",\"u\":11478297115470,\"s\":\"BTCUSDT\",\"ps\":\"BTCUSDT\",\"b\":\"79716.80\",\"B\":\"2.581\",\"a\":\"79716.90\",\"A\":\"15.137\",\"T\":1788564465369,\"E\":1788564465369,\"st\":1}}"}
{"receive_ns":1788564465358645000,"stream":"btcusdt@bookTicker","event_type":"bookTicker","event_time_ms":1788564465370,"raw_json":"{\"stream\":\"btcusdt@bookTicker\",\"data\":{\"e\":\"bookTicker\",\"u\":11478297115540,\"s\":\"BTCUSDT\",\"ps\":\"BTCUSDT\",\"b\":\"79716.80\",\"B\":\"2.601\",\"a\":\"79716.90\",\"A\":\"15.137\",\"T\":1788564465370,\"E\":1788564465370,\"st\":1}}"}
{"receive_ns":1788564465370632000,"stream":"btcusdt@bookTicker","event_type":"bookTicker","event_time_ms":1788564465371,"raw_json":"{\"stream\":\"btcusdt@bookTicker\",\"data\":{\"e\":\"bookTicker\",\"u\":11478297115592,\"s\":\"BTCUSDT\",\"ps\":\"BTCUSDT\",\"b\":\"79716.80\",\"B\":\"2.599\",\"a\":\"79716.90\",\"A\":\"15.137\",\"T\":1788564465371,\"E\":1788564465371,\"st\":1}}"}
{"receive_ns":1788564465370927000,"stream":"btcusdt@bookTicker","event_type":"bookTicker","event_time_ms":1788564465379,"raw_json":"{\"stream\":\"btcusdt@bookTicker\",\"data\":{\"e\":\"bookTicker\",\"u\":11478297116040,\"s\":\"BTCUSDT\",\"ps\":\"BTCUSDT\",\"b\":\"79716.80\",\"B\":\"2.599\",\"a\":\"79716.90\",\"A\":\"15.136\",\"T\":1788564465379,\"E\":1788564465379,\"st\":1}}"}
{"receive_ns":1788564465377569000,"stream":"btcusdt@bookTicker","event_type":"bookTicker","event_time_ms":1788564465388,"raw_json":"{\"stream\":\"btcusdt@bookTicker\",\"data\":{\"e\":\"bookTicker\",\"u\":11478297116719,\"s\":\"BTCUSDT\",\"ps\":\"BTCUSDT\",\"b\":\"79716.80\",\"B\":\"2.599\",\"a\":\"79716.90\",\"A\":\"15.138\",\"T\":1788564465388,\"E\":1788564465388,\"st\":1}}"}
{"receive_ns":1788564465392949000,"stream":"btcusdt@depth@100ms","event_type":"depthUpdate","event_time_ms":1788564465411,"raw_json":"{\"stream\":\"btcusdt@depth@100ms\",\"data\":{\"e\":\"depthUpdate\",\"E\":1788564465411,\"T\":1788564465410,\"s\":\"BTCUSDT\",\"ps\":\"BTCUSDT\",\"U\":11478297112311,\"u\":11478297118047,\"pu\":11478297112153,\"b\":[[\"1000.00\",\"24.754\"],[\"29216.80\",\"0.861\"],[\"29316.80\",\"1.239\"],[\"63773.40\",\"0.000\"],[\"71745.10\",\"0.002\"],[\"71782.00\",\"0.003\"],[\"78600.80\",\"19.591\"],[\"78755.00\",\"12.201\"],[\"78760.20\",\"30.618\"],[\"78919.60\",\"7.929\"],[\"79320.20\",\"0.140\"],[\"79497.60\",\"0.502\"],[\"79500.80\",\"0.000\"],[\"79501.60\",\"0.859\"],[\"79529.50\",\"0.501\"],[\"79531.50\",\"1.634\"],[\"79532.70\",\"2.292\"],[\"79594.50\",\"0.660\"],[\"79699.20\",\"0.003\"],[\"79699.30\",\"0.003\"],[\"79705.50\",\"0.403\"],[\"79716.80\",\"2.599\"]],\"a\":[[\"79716.90\",\"15.138\"],[\"79717.40\",\"0.883\"],[\"79717.90\",\"0.006\"],[\"79722.10\",\"0.008\"],[\"79725.10\",\"0.078\"],[\"79727.30\",\"0.703\"],[\"79840.10\",\"0.363\"],[\"79866.40\",\"0.500\"],[\"79886.30\",\"0.090\"],[\"80085.60\",\"1.157\"],[\"80086.80\",\"0.778\"],[\"80514.10\",\"5.823\"],[\"80673.50\",\"31.191\"],[\"80832.90\",\"29.470\"],[\"80952.50\",\"5.554\"],[\"80952.80\",\"0.022\"]],\"st\":1}}"}
{"receive_ns":1788564465404126000,"stream":"btcusdt@bookTicker","event_type":"bookTicker","event_time_ms":1788564465424,"raw_json":"{\"stream\":\"btcusdt@bookTicker\",\"data\":{\"e\":\"bookTicker\",\"u\":11478297118920,\"s\":\"BTCUSDT\",\"ps\":\"BTCUSDT\",\"b\":\"79716.80\",\"B\":\"2.598\",\"a\":\"79716.90\",\"A\":\"15.138\",\"T\":1788564465424,\"E\":1788564465424,\"st\":1}}"}
{"receive_ns":1788564465410039000,"stream":"btcusdt@trade","event_type":"trade","event_time_ms":1788564465424,"raw_json":"{\"stream\":\"btcusdt@trade\",\"data\":{\"e\":\"trade\",\"E\":1788564465424,\"T\":1788564465424,\"s\":\"BTCUSDT\",\"t\":8054096509,\"p\":\"79716.80\",\"q\":\"0.001\",\"X\":\"MARKET\",\"m\":true,\"st\":1}}"}
{"receive_ns":1788564465416358000,"stream":"btcusdt@bookTicker","event_type":"bookTicker","event_time_ms":1788564465425,"raw_json":"{\"stream\":\"btcusdt@bookTicker\",\"data\":{\"e\":\"bookTicker\",\"u\":11478297118972,\"s\":\"BTCUSDT\",\"ps\":\"BTCUSDT\",\"b\":\"79716.80\",\"B\":\"2.598\",\"a\":\"79716.90\",\"A\":\"15.157\",\"T\":1788564465425,\"E\":1788564465425,\"st\":1}}"}
{"receive_ns":1788564465416626000,"stream":"btcusdt@bookTicker","event_type":"bookTicker","event_time_ms":1788564465425,"raw_json":"{\"stream\":\"btcusdt@bookTicker\",\"data\":{\"e\":\"bookTicker\",\"u\":11478297119057,\"s\":\"BTCUSDT\",\"ps\":\"BTCUSDT\",\"b\":\"79716.80\",\"B\":\"2.598\",\"a\":\"79716.90\",\"A\":\"15.159\",\"T\":1788564465425,\"E\":1788564465425,\"st\":1}}"}
{"receive_ns":1788564465433516000,"stream":"btcusdt@bookTicker","event_type":"bookTicker","event_time_ms":1788564465426,"raw_json":"{\"stream\":\"btcusdt@bookTicker\",\"data\":{\"e\":\"bookTicker\",\"u\":11478297119138,\"s\":\"BTCUSDT\",\"ps\":\"BTCUSDT\",\"b\":\"79716.80\",\"B\":\"2.598\",\"a\":\"79716.90\",\"A\":\"15.140\",\"T\":1788564465426,\"E\":1788564465426,\"st\":1}}"}
{"receive_ns":1788564465433737000,"stream":"btcusdt@bookTicker","event_type":"bookTicker","event_time_ms":1788564465426,"raw_json":"{\"stream\":\"btcusdt@bookTicker\",\"data\":{\"e\":\"bookTicker\",\"u\":11478297119159,\"s\":\"BTCUSDT\",\"ps\":\"BTCUSDT\",\"b\":\"79716.80\",\"B\":\"2.600\",\"a\":\"79716.90\",\"A\":\"15.140\",\"T\":1788564465426,\"E\":1788564465426,\"st\":1}}"}
{"receive_ns":1788564465433905000,"stream":"btcusdt@bookTicker","event_type":"bookTicker","event_time_ms":1788564465426,"raw_json":"{\"stream\":\"btcusdt@bookTicker\",\"data\":{\"e\":\"bookTicker\",\"u\":11478297119166,\"s\":\"BTCUSDT\",\"ps\":\"BTCUSDT\",\"b\":\"79716.80\",\"B\":\"2.600\",\"a\":\"79716.90\",\"A\":\"15.138\",\"T\":1788564465426,\"E\":1788564465426,\"st\":1}}"}
{"receive_ns":1788564465464999000,"stream":"btcusdt@bookTicker","event_type":"bookTicker","event_time_ms":1788564465489,"raw_json":"{\"stream\":\"btcusdt@bookTicker\",\"data\":{\"e\":\"bookTicker\",\"u\":11478297122289,\"s\":\"BTCUSDT\",\"ps\":\"BTCUSDT\",\"b\":\"79716.80\",\"B\":\"2.587\",\"a\":\"79716.90\",\"A\":\"15.138\",\"T\":1788564465489,\"E\":1788564465489,\"st\":1}}"}
{"receive_ns":1788564465465276000,"stream":"btcusdt@trade","event_type":"trade","event_time_ms":1788564465489,"raw_json":"{\"stream\":\"btcusdt@trade\",\"data\":{\"e\":\"trade\",\"E\":1788564465489,\"T\":1788564465489,\"s\":\"BTCUSDT\",\"t\":8054096510,\"p\":\"79716.80\",\"q\":\"0.013\",\"X\":\"MARKET\",\"m\":true,\"st\":1}}"}
{"receive_ns":1788564465465497000,"stream":"btcusdt@bookTicker","event_type":"bookTicker","event_time_ms":1788564465491,"raw_json":"{\"stream\":\"btcusdt@bookTicker\",\"data\":{\"e\":\"bookTicker\",\"u\":11478297122405,\"s\":\"BTCUSDT\",\"ps\":\"BTCUSDT\",\"b\":\"79716.80\",\"B\":\"2.587\",\"a\":\"79716.90\",\"A\":\"15.157\",\"T\":1788564465490,\"E\":1788564465491,\"st\":1}}"}
{"receive_ns":1788564465465682000,"stream":"btcusdt@bookTicker","event_type":"bookTicker","event_time_ms":1788564465491,"raw_json":"{\"stream\":\"btcusdt@bookTicker\",\"data\":{\"e\":\"bookTicker\",\"u\":11478297122419,\"s\":\"BTCUSDT\",\"ps\":\"BTCUSDT\",\"b\":\"79716.80\",\"B\":\"2.587\",\"a\":\"79716.90\",\"A\":\"15.159\",\"T\":1788564465490,\"E\":1788564465491,\"st\":1}}"}
{"receive_ns":1788564465473153000,"stream":"btcusdt@bookTicker","event_type":"bookTicker","event_time_ms":1788564465491,"raw_json":"{\"stream\":\"btcusdt@bookTicker\",\"data\":{\"e\":\"bookTicker\",\"u\":11478297122568,\"s\":\"BTCUSDT\",\"ps\":\"BTCUSDT\",\"b\":\"79716.80\",\"B\":\"2.587\",\"a\":\"79716.90\",\"A\":\"15.157\",\"T\":1788564465491,\"E\":1788564465491,\"st\":1}}"}
{"receive_ns":1788564465479729000,"stream":"btcusdt@bookTicker","event_type":"bookTicker","event_time_ms":1788564465492,"raw_json":"{\"stream\":\"btcusdt@bookTicker\",\"data\":{\"e\":\"bookTicker\",\"u\":11478297122579,\"s\":\"BTCUSDT\",\"ps\":\"BTCUSDT\",\"b\":\"79716.80\",\"B\":\"2.587\",\"a\":\"79716.90\",\"A\":\"15.138\",\"T\":1788564465491,\"E\":1788564465492,\"st\":1}}"}
{"receive_ns":1788564465491656000,"stream":"btcusdt@bookTicker","event_type":"bookTicker","event_time_ms":1788564465501,"raw_json":"{\"stream\":\"btcusdt@bookTicker\",\"data\":{\"e\":\"bookTicker\",\"u\":11478297123325,\"s\":\"BTCUSDT\",\"ps\":\"BTCUSDT\",\"b\":\"79716.80\",\"B\":\"2.567\",\"a\":\"79716.90\",\"A\":\"15.138\",\"T\":1788564465501,\"E\":1788564465501,\"st\":1}}"}
{"receive_ns":1788564465497449000,"stream":"btcusdt@depth@100ms","event_type":"depthUpdate","event_time_ms":1788564465513,"raw_json":"{\"stream\":\"btcusdt@depth@100ms\",\"data\":{\"e\":\"depthUpdate\",\"E\":1788564465513,\"T\":1788564465511,\"s\":\"BTCUSDT\",\"ps\":\"BTCUSDT\",\"U\":11478297118146,\"u\":11478297123823,\"pu\":11478297118047,\"b\":[[\"1000.00\",\"24.754\"],[\"29216.80\",\"1.036\"],[\"29316.80\",\"1.064\"],[\"71745.10\",\"0.002\"],[\"71782.00\",\"0.000\"],[\"73646.90\",\"0.002\"],[\"76528.10\",\"0.000\"],[\"78122.50\",\"0.161\"],[\"78226.10\",\"1.403\"],[\"78504.20\",\"1.527\"],[\"78919.60\",\"7.929\"],[\"79318.20\",\"3.285\"],[\"79529.50\",\"0.701\"],[\"79531.50\",\"1.434\"],[\"79701.90\",\"0.000\"],[\"79703.60\",\"0.255\"],[\"79703.90\",\"0.002\"],[\"79713.10\",\"0.028\"],[\"79713.20\",\"0.027\"],[\"79713.60\",\"0.028\"],[\"79713.90\",\"0.028\"],[\"79714.00\",\"0.001\"],[\"79714.10\",\"0.000\"],[\"79714.80\",\"0.000\"],[\"79715.40\",\"0.001\"],[\"79716.80\",\"2.567\"]],\"a\":[[\"79716.90\",\"15.138\"],[\"79792.60\",\"0.201\"],[\"80085.60\",\"1.157\"],[\"80514.10\",\"5.823\"]],\"st\":1}}"}
{"receive_ns":1788564465583226000,"stream":"btcusdt@bookTicker","event_type":"bookTicker","event_time_ms":1788564465603,"raw_json":"{\"stream\":\"btcusdt@bookTicker\",\"data\":{\"e\":\"bookTicker\",\"u\":11478297128731,\"s\":\"BTCUSDT\",\"ps\":\"BTCUSDT\",\"b\":\"79716.80\",\"B\":\"2.567\",\"a\":\"79716.90\",\"A\":\"15.136\",\"T\":1788564465603,\"E\":1788564465603,\"st\":1}}"}
{"receive_ns":1788564465598404000,"stream":"btcusdt@depth@100ms","event_type":"depthUpdate","event_time_ms":1788564465615,"raw_json":"{\"stream\":\"btcusdt@depth@100ms\",\"data\":{\"e\":\"depthUpdate\",\"E\":1788564465615,\"T\":1788564465613,\"s\":\"BTCUSDT\",\"ps\":\"BTCUSDT\",\"U\":11478297123982,\"u\":11478297129401,\"pu\":11478297123823,\"b\":[[\"29216.80\",\"1.218\"],[\"29316.80\",\"0.882\"],[\"71745.10\",\"0.002\"],[\"76528.10\",\"0.002\"],[\"78919.60\",\"7.929\"],[\"79111.60\",\"0.000\"],[\"79318.20\",\"3.284\"],[\"79320.20\",\"0.140\"],[\"79501.60\",\"0.628\"],[\"79529.50\",\"0.951\"],[\"79531.50\",\"0.006\"],[\"79532.70\",\"1.289\"],[\"79555.00\",\"0.000\"],[\"79555.30\",\"0.423\"],[\"79594.50\",\"0.000\"],[\"79693.10\",\"0.003\"],[\"79699.20\",\"0.382\"],[\"79705.50\",\"0.024\"]],\"a\":[[\"79716.90\",\"15.136\"],[\"79733.00\",\"0.630\"],[\"79754.30\",\"1.369\"],[\"79840.10\",\"0.013\"],[\"79866.40\",\"0.250\"],[\"79879.60\",\"0.011\"],[\"79886.30\",\"0.000\"],[\"80085.60\",\"0.589\"],[\"80086.80\",\"0.016\"],[\"80514.10\",\"5.823\"],[\"80646.20\",\"8.596\"],[\"80832.90\",\"31.324\"]],\"st\":1}}"}
{"receive_ns":1788564465636628000,"stream":"btcusdt@bookTicker","event_type":"bookTicker","event_time_ms":1788564465659,"raw_json":"{\"stream\":\"btcusdt@bookTicker\",\"data\":{\"e\":\"bookTicker\",\"u\":11478297131942,\"s\":\"BTCUSDT\",\"ps\":\"BTCUSDT\",\"b\":\"79716.80\",\"B\":\"2.566\",\"a\":\"79716.90\",\"A\":\"15.136\",\"T\":1788564465659,\"E\":1788564465659,\"st\":1}}"}
{"receive_ns":1788564465636876000,"stream":"btcusdt@trade","event_type":"trade","event_time_ms":1788564465659,"raw_json":"{\"stream\":\"btcusdt@trade\",\"data\":{\"e\":\"trade\",\"E\":1788564465659,\"T\":1788564465659,\"s\":\"BTCUSDT\",\"t\":8054096511,\"p\":\"79716.80\",\"q\":\"0.001\",\"X\":\"MARKET\",\"m\":true,\"st\":1}}"}
{"receive_ns":1788564465643416000,"stream":"btcusdt@bookTicker","event_type":"bookTicker","event_time_ms":1788564465660,"raw_json":"{\"stream\":\"btcusdt@bookTicker\",\"data\":{\"e\":\"bookTicker\",\"u\":11478297132078,\"s\":\"BTCUSDT\",\"ps\":\"BTCUSDT\",\"b\":\"79716.80\",\"B\":\"2.566\",\"a\":\"79716.90\",\"A\":\"15.138\",\"T\":1788564465660,\"E\":1788564465660,\"st\":1}}"}
{"receive_ns":1788564465649105000,"stream":"btcusdt@bookTicker","event_type":"bookTicker","event_time_ms":1788564465660,"raw_json":"{\"stream\":\"btcusdt@bookTicker\",\"data\":{\"e\":\"bookTicker\",\"u\":11478297132083,\"s\":\"BTCUSDT\",\"ps\":\"BTCUSDT\",\"b\":\"79716.80\",\"B\":\"2.566\",\"a\":\"79716.90\",\"A\":\"15.157\",\"T\":1788564465660,\"E\":1788564465660,\"st\":1}}"}
{"receive_ns":1788564465665838000,"stream":"btcusdt@bookTicker","event_type":"bookTicker","event_time_ms":1788564465661,"raw_json":"{\"stream\":\"btcusdt@bookTicker\",\"data\":{\"e\":\"bookTicker\",\"u\":11478297132187,\"s\":\"BTCUSDT\",\"ps\":\"BTCUSDT\",\"b\":\"79716.80\",\"B\":\"2.566\",\"a\":\"79716.90\",\"A\":\"15.155\",\"T\":1788564465661,\"E\":1788564465661,\"st\":1}}"}
{"receive_ns":1788564465666060000,"stream":"btcusdt@bookTicker","event_type":"bookTicker","event_time_ms":1788564465661,"raw_json":"{\"stream\":\"btcusdt@bookTicker\",\"data\":{\"e\":\"bookTicker\",\"u\":11478297132193,\"s\":\"BTCUSDT\",\"ps\":\"BTCUSDT\",\"b\":\"79716.80\",\"B\":\"2.566\",\"a\":\"79716.90\",\"A\":\"15.136\",\"T\":1788564465661,\"E\":1788564465661,\"st\":1}}"}
{"receive_ns":1788564465699689000,"stream":"btcusdt@depth@100ms","event_type":"depthUpdate","event_time_ms":1788564465717,"raw_json":"{\"stream\":\"btcusdt@depth@100ms\",\"data\":{\"e\":\"depthUpdate\",\"E\":1788564465717,\"T\":1788564465716,\"s\":\"BTCUSDT\",\"ps\":\"BTCUSDT\",\"U\":11478297129534,\"u\":11478297135177,\"pu\":11478297129401,\"b\":[[\"1000.00\",\"24.754\"],[\"29216.80\",\"1.393\"],[\"29316.80\",\"0.707\"],[\"71745.10\",\"0.002\"],[\"75731.10\",\"0.006\"],[\"76528.10\",\"0.000\"],[\"76528.20\",\"0.001\"],[\"78469.80\",\"0.572\"],[\"78580.60\",\"21.226\"],[\"78653.30\",\"2.875\"],[\"78919.60\",\"7.929\"],[\"79118.90\",\"3.800\"],[\"79318.20\",\"3.274\"],[\"79497.60\",\"0.733\"],[\"79529.50\",\"1.353\"],[\"79530.70\",\"1.004\"],[\"79531.50\",\"0.507\"],[\"79555.00\",\"2.624\"],[\"79555.30\",\"0.712\"],[\"79594.50\",\"0.684\"],[\"79653.00\",\"0.077\"],[\"79712.30\",\"0.028\"],[\"79712.40\",\"0.026\"],[\"79713.40\",\"0.000\"],[\"79713.50\",\"0.002\"],[\"79713.60\",\"0.002\"],[\"79713.90\",\"0.028\"],[\"79716.80\",\"2.566\"]],\"a\":[[\"79716.90\",\"15.136\"],[\"79761.00\",\"3.202\"],[\"79761.10\",\"0.002\"],[\"79792.60\",\"0.002\"],[\"79840.10\",\"0.363\"],[\"79866.40\",\"0.500\"],[\"79879.60\",\"2.444\"],[\"79886.30\",\"0.090\"],[\"80085.60\",\"1.157\"],[\"80086.80\",\"0.778\"],[\"80514.10\",\"5.825\"]],\"st\":1}}"}
{"receive_ns":1788564465802491000,"stream":"btcusdt@depth@100ms","event_type":"depthUpdate","event_time_ms":1788564465819,"raw_json":"{\"stream\":\"btcusdt@depth@100ms\",\"data\":{\"e\":\"depthUpdate\",\"E\":1788564465819,\"T\":1788564465818,\"s\":\"BTCUSDT\",\"ps\":\"BTCUSDT\",\"U\":11478297135250,\"u\":11478297140868,\"pu\":11478297135177,\"b\":[[\"1000.00\",\"24.754\"],[\"29216.80\",\"1.575\"],[\"29316.80\",\"0.525\"],[\"71745.10\",\"0.002\"],[\"76528.10\",\"0.002\"],[\"78560.90\",\"7.042\"],[\"78599.20\",\"0.000\"],[\"78919.60\",\"7.929\"],[\"79320.20\",\"0.140\"],[\"79529.50\",\"1.103\"],[\"79531.50\",\"0.957\"]],\"a\":[[\"79866.40\",\"0.699\"],[\"80085.60\",\"1.157\"],[\"80115.50\",\"3.243\"],[\"80514.10\",\"5.823\"],[\"80673.50\",\"32.428\"]],\"st\":1}}"}
{"receive_ns":1788564465902962000,"stream":"btcusdt@depth@100ms","event_type":"depthUpdate","event_time_ms":1788564465921,"raw_json":"{\"stream\":\"btcusdt@depth@100ms\",\"data\":{\"e\":\"depthUpdate\",\"E\":1788564465921,\"T\":1788564465917,\"s\":\"BTCUSDT\",\"ps\":\"BTCUSDT\",\"U\":11478297140941,\"u\":11478297146128,\"pu\":11478297140868,\"b\":[[\"29216.80\",\"1.750\"],[\"29316.80\",\"0.350\"],[\"71745.10\",\"0.002\"],[\"78469.80\",\"0.286\"],[\"78720.30\",\"5.587\"],[\"78919.60\",\"7.929\"],[\"79497.60\",\"0.733\"],[\"79500.80\",\"1.003\"],[\"79529.50\",\"1.103\"],[\"79530.70\",\"0.001\"],[\"79531.50\",\"0.456\"],[\"79653.00\",\"0.077\"]],\"a\":[[\"79725.20\",\"2.609\"],[\"79727.30\",\"0.076\"],[\"79866.40\",\"0.699\"],[\"79886.30\",\"0.090\"],[\"79938.80\",\"0.000\"],[\"79938.90\",\"8.667\"],[\"80085.60\",\"0.739\"],[\"80086.80\",\"0.778\"],[\"80514.10\",\"5.823\"],[\"80714.20\",\"6.160\"],[\"81311.20\",\"0.036\"]],\"st\":1}}"}
{"receive_ns":1788564466005922000,"stream":"btcusdt@depth@100ms","event_type":"depthUpdate","event_time_ms":1788564466023,"raw_json":"{\"stream\":\"btcusdt@depth@100ms\",\"data\":{\"e\":\"depthUpdate\",\"E\":1788564466023,\"T\":1788564466021,\"s\":\"BTCUSDT\",\"ps\":\"BTCUSDT\",\"U\":11478297146347,\"u\":11478297152467,\"pu\":11478297146128,\"b\":[[\"1000.00\",\"24.754\"],[\"29216.80\",\"1.806\"],[\"29316.80\",\"0.231\"],[\"29616.80\",\"0.063\"],[\"71745.10\",\"0.002\"],[\"76528.10\",\"0.000\"],[\"78599.00\",\"2.447\"],[\"78600.80\",\"21.497\"],[\"78758.40\",\"0.000\"],[\"78847.10\",\"0.162\"],[\"78919.60\",\"7.929\"],[\"78961.70\",\"1.630\"],[\"79318.20\",\"3.284\"],[\"79320.20\",\"0.000\"],[\"79529.50\",\"1.604\"],[\"79531.50\",\"0.206\"]],\"a\":[[\"79866.40\",\"0.449\"],[\"80085.60\",\"1.002\"],[\"80514.10\",\"5.823\"],[\"80520.70\",\"4.208\"],[\"80646.20\",\"7.368\"]],\"st\":1}}"}
{"receive_ns":1788564466078486000,"stream":"btcusdt@bookTicker","event_type":"bookTicker","event_time_ms":1788564466096,"raw_json":"{\"stream\":\"btcusdt@bookTicker\",\"data\":{\"e\":\"bookTicker\",\"u\":11478297158659,\"s\":\"BTCUSDT\",\"ps\":\"BTCUSDT\",\"b\":\"79716.80\",\"B\":\"2.566\",\"a\":\"79716.90\",\"A\":\"15.133\",\"T\":1788564466095,\"E\":1788564466096,\"st\":1}}"}
{"receive_ns":1788564466093659000,"stream":"btcusdt@bookTicker","event_type":"bookTicker","event_time_ms":1788564466099,"raw_json":"{\"stream\":\"btcusdt@bookTicker\",\"data\":{\"e\":\"bookTicker\",\"u\":11478297159051,\"s\":\"BTCUSDT\",\"ps\":\"BTCUSDT\",\"b\":\"79716.80\",\"B\":\"2.566\",\"a\":\"79716.90\",\"A\":\"15.142\",\"T\":1788564466099,\"E\":1788564466099,\"st\":1}}"}
{"receive_ns":1788564466106020000,"stream":"btcusdt@bookTicker","event_type":"bookTicker","event_time_ms":1788564466119,"raw_json":"{\"stream\":\"btcusdt@bookTicker\",\"data\":{\"e\":\"bookTicker\",\"u\":11478297160741,\"s\":\"BTCUSDT\",\"ps\":\"BTCUSDT\",\"b\":\"79716.80\",\"B\":\"2.554\",\"a\":\"79716.90\",\"A\":\"15.142\",\"T\":1788564466119,\"E\":1788564466119,\"st\":1}}"}
{"receive_ns":1788564466106220000,"stream":"btcusdt@trade","event_type":"trade","event_time_ms":1788564466119,"raw_json":"{\"stream\":\"btcusdt@trade\",\"data\":{\"e\":\"trade\",\"E\":1788564466119,\"T\":1788564466119,\"s\":\"BTCUSDT\",\"t\":8054096512,\"p\":\"79716.80\",\"q\":\"0.012\",\"X\":\"MARKET\",\"m\":true,\"st\":1}}"}
{"receive_ns":1788564466119097000,"stream":"btcusdt@bookTicker","event_type":"bookTicker","event_time_ms":1788564466120,"raw_json":"{\"stream\":\"btcusdt@bookTicker\",\"data\":{\"e\":\"bookTicker\",\"u\":11478297160811,\"s\":\"BTCUSDT\",\"ps\":\"BTCUSDT\",\"b\":\"79716.80\",\"B\":\"2.554\",\"a\":\"79716.90\",\"A\":\"15.161\",\"T\":1788564466120,\"E\":1788564466120,\"st\":1}}"}
{"receive_ns":1788564466127742000,"stream":"btcusdt@bookTicker","event_type":"bookTicker","event_time_ms":1788564466120,"raw_json":"{\"stream\":\"btcusdt@bookTicker\",\"data\":{\"e\":\"bookTicker\",\"u\":11478297160857,\"s\":\"BTCUSDT\",\"ps\":\"BTCUSDT\",\"b\":\"79716.80\",\"B\":\"2.554\",\"a\":\"79716.90\",\"A\":\"15.163\",\"T\":1788564466120,\"E\":1788564466120,\"st\":1}}"}
{"receive_ns":1788564466134324000,"stream":"btcusdt@bookTicker","event_type":"bookTicker","event_time_ms":1788564466121,"raw_json":"{\"stream\":\"btcusdt@bookTicker\",\"data\":{\"e\":\"bookTicker\",\"u\":11478297160986,\"s\":\"BTCUSDT\",\"ps\":\"BTCUSDT\",\"b\":\"79716.80\",\"B\":\"2.554\",\"a\":\"79716.90\",\"A\":\"15.144\",\"T\":1788564466121,\"E\":1788564466121,\"st\":1}}"}
{"receive_ns":1788564466134533000,"stream":"btcusdt@bookTicker","event_type":"bookTicker","event_time_ms":1788564466121,"raw_json":"{\"stream\":\"btcusdt@bookTicker\",\"data\":{\"e\":\"bookTicker\",\"u\":11478297161005,\"s\":\"BTCUSDT\",\"ps\":\"BTCUSDT\",\"b\":\"79716.80\",\"B\":\"2.554\",\"a\":\"79716.90\",\"A\":\"15.142\",\"T\":1788564466121,\"E\":1788564466121,\"st\":1}}"}
{"receive_ns":1788564466134945000,"stream":"btcusdt@depth@100ms","event_type":"depthUpdate","event_time_ms":1788564466125,"raw_json":"{\"stream\":\"btcusdt@depth@100ms\",\"data\":{\"e\":\"depthUpdate\",\"E\":1788564466125,\"T\":1788564466124,\"s\":\"BTCUSDT\",\"ps\":\"BTCUSDT\",\"U\":11478297152584,\"u\":11478297161222,\"pu\":11478297152467,\"b\":[[\"1000.00\",\"24.754\"],[\"29216.80\",\"1.869\"],[\"29316.80\",\"0.112\"],[\"29616.80\",\"0.119\"],[\"71745.10\",\"0.002\"],[\"76528.10\",\"0.002\"],[\"78914.50\",\"0.000\"],[\"78919.60\",\"7.929\"],[\"79318.20\",\"3.285\"],[\"79320.20\",\"0.140\"],[\"79497.60\",\"0.733\"],[\"79500.80\",\"1.003\"],[\"79529.50\",\"1.679\"],[\"79531.50\",\"0.456\"],[\"79531.80\",\"0.001\"],[\"79594.50\",\"0.000\"],[\"79653.00\",\"0.002\"],[\"79662.50\",\"0.012\"],[\"79702.50\",\"0.001\"],[\"79716.80\",\"2.554\"]],\"a\":[[\"79716.90\",\"15.142\"],[\"79761.00\",\"3.152\"],[\"79761.10\",\"0.052\"],[\"79790.30\",\"0.025\"],[\"79840.10\",\"0.013\"],[\"79866.40\",\"0.699\"],[\"79886.30\",\"0.090\"],[\"80085.60\",\"1.157\"],[\"80086.80\",\"0.778\"],[\"80115.50\",\"3.242\"],[\"80321.40\",\"0.002\"],[\"80514.10\",\"5.823\"],[\"80925.10\",\"3.432\"]],\"st\":1}}"}
{"receive_ns":1788564466203330000,"stream":"btcusdt@depth@100ms","event_type":"depthUpdate","event_time_ms":1788564466227,"raw_json":"{\"stream\":\"btcusdt@depth@100ms\",\"data\":{\"e\":\"depthUpdate\",\"E\":1788564466227,\"T\":1788564466225,\"s\":\"BTCUSDT\",\"ps\":\"BTCUSDT\",\"U\":11478297161287,\"u\":11478297167831,\"pu\":11478297161222,\"b\":[[\"29216.80\",\"1.897\"],[\"29316.80\",\"0.007\"],[\"29616.80\",\"0.196\"],[\"71745.10\",\"0.002\"],[\"76528.10\",\"0.000\"],[\"78600.80\",\"23.403\"],[\"78760.20\",\"31.886\"],[\"78863.80\",\"2.633\"],[\"78919.60\",\"8.056\"],[\"78959.50\",\"2.379\"],[\"79529.50\",\"1.178\"],[\"79531.50\",\"0.757\"],[\"79594.50\",\"0.684\"],[\"79702.50\",\"0.002\"],[\"79703.50\",\"0.002\"],[\"79710.40\",\"0.029\"],[\"79713.90\",\"0.002\"]],\"a\":[[\"79840.10\",\"0.363\"],[\"79866.40\",\"0.500\"],[\"80085.60\",\"1.157\"],[\"80514.10\",\"5.823\"],[\"80684.10\",\"1.448\"],[\"80715.90\",\"0.001\"],[\"80724.00\",\"0.374\"],[\"80756.80\",\"0.000\"],[\"80765.20\",\"0.373\"],[\"81089.80\",\"0.000\"]],\"st\":1}}"}
{"receive_ns":1788564466310235000,"stream":"btcusdt@depth@100ms","event_type":"depthUpdate","event_time_ms":1788564466329,"raw_json":"{\"stream\":\"btcusdt@depth@100ms\",\"data\":{\"e\":\"depthUpdate\",\"E\":1788564466329,\"T\":1788564466325,\"s\":\"BTCUSDT\",\"ps\":\"BTCUSDT\",\"U\":11478297167933,\"u\":11478297174313,\"pu\":11478297167831,\"b\":[[\"1000.00\",\"24.754\"],[\"29216.80\",\"1.736\"],[\"29316.80\",\"0.000\"],[\"29616.80\",\"0.364\"],[\"71745.10\",\"0.002\"],[\"78564.80\",\"0.000\"],[\"78919.60\",\"8.056\"],[\"79318.20\",\"3.285\"],[\"79320.20\",\"0.140\"],[\"79529.50\",\"1.378\"],[\"79531.50\",\"0.757\"],[\"79712.00\",\"0.042\"],[\"79712.20\",\"0.028\"],[\"79713.00\",\"0.027\"],[\"79713.10\",\"0.002\"],[\"79713.20\",\"0.001\"],[\"79713.60\",\"0.028\"]],\"a\":[[\"79792.60\",\"0.201\"],[\"79866.40\",\"0.500\"],[\"80085.60\",\"1.157\"],[\"80412.00\",\"0.000\"],[\"80514.10\",\"5.823\"],[\"80805.60\",\"11.028\"]],\"st\":1}}"}
{"receive_ns":1788564466400545000,"stream":"btcusdt@bookTicker","event_type":"bookTicker","event_time_ms":1788564466420,"raw_json":"{\"stream\":\"btcusdt@bookTicker\",\"data\":{\"e\":\"bookTicker\",\"u\":11478297178686,\"s\":\"BTCUSDT\",\"ps\":\"BTCUSDT\",\"b\":\"79716.80\",\"B\":\"2.541\",\"a\":\"79716.90\",\"A\":\"15.142\",\"T\":1788564466420,\"E\":1788564466420,\"st\":1}}"}
{"receive_ns":1788564466406657000,"stream":"btcusdt@trade","event_type":"trade","event_time_ms":1788564466420,"raw_json":"{\"stream\":\"btcusdt@trade\",\"data\":{\"e\":\"trade\",\"E\":1788564466420,\"T\":1788564466420,\"s\":\"BTCUSDT\",\"t\":8054096513,\"p\":\"79716.80\",\"q\":\"0.013\",\"X\":\"MARKET\",\"m\":true,\"st\":1}}"}
{"receive_ns":1788564466423812000,"stream":"btcusdt@bookTicker","event_type":"bookTicker","event_time_ms":1788564466422,"raw_json":"{\"stream\":\"btcusdt@bookTicker\",\"data\":{\"e\":\"bookTicker\",\"u\":11478297178813,\"s\":\"BTCUSDT\",\"ps\":\"BTCUSDT\",\"b\":\"79716.80\",\"B\":\"2.541\",\"a\":\"79716.90\",\"A\":\"15.161\",\"T\":1788564466421,\"E\":1788564466422,\"st\":1}}"}
{"receive_ns":1788564466429509000,"stream":"btcusdt@bookTicker","event_type":"bookTicker","event_time_ms":1788564466422,"raw_json":"{\"stream\":\"btcusdt@bookTicker\",\"data\":{\"e\":\"bookTicker\",\"u\":11478297178929,\"s\":\"BTCUSDT\",\"ps\":\"BTCUSDT\",\"b\":\"79716.80\",\"B\":\"2.541\",\"a\":\"79716.90\",\"A\":\"15.163\",\"T\":1788564466422,\"E\":1788564466422,\"st\":1}}"}
{"receive_ns":1788564466435156000,"stream":"btcusdt@bookTicker","event_type":"bookTicker","event_time_ms":1788564466422,"raw_json":"{\"stream\":\"btcusdt@bookTicker\",\"data\":{\"e\":\"bookTicker\",\"u\":11478297178985,\"s\":\"BTCUSDT\",\"ps\":\"BTCUSDT\",\"b\":\"79716.80\",\"B\":\"2.541\",\"a\":\"79716.90\",\"A\":\"15.144\",\"T\":1788564466422,\"E\":1788564466422,\"st\":1}}"}
{"receive_ns":1788564466435361000,"stream":"btcusdt@bookTicker","event_type":"bookTicker","event_time_ms":1788564466423,"raw_json":"{\"stream\":\"btcusdt@bookTicker\",\"data\":{\"e\":\"bookTicker\",\"u\":11478297179015,\"s\":\"BTCUSDT\",\"ps\":\"BTCUSDT\",\"b\":\"79716.80\",\"B\":\"2.541\",\"a\":\"79716.90\",\"A\":\"15.142\",\"T\":1788564466423,\"E\":1788564466423,\"st\":1}}"}
{"receive_ns":1788564466441082000,"stream":"btcusdt@bookTicker","event_type":"bookTicker","event_time_ms":1788564466423,"raw_json":"{\"stream\":\"btcusdt@bookTicker\",\"data\":{\"e\":\"bookTicker\",\"u\":11478297179064,\"s\":\"BTCUSDT\",\"ps\":\"BTCUSDT\",\"b\":\"79716.80\",\"B\":\"2.541\",\"a\":\"79716.90\",\"A\":\"15.146\",\"T\":1788564466423,\"E\":1788564466423,\"st\":1}}"}
{"receive_ns":1788564466447477000,"stream":"btcusdt@depth@100ms","event_type":"depthUpdate","event_time_ms":1788564466431,"raw_json":"{\"stream\":\"btcusdt@depth@100ms\",\"data\":{\"e\":\"depthUpdate\",\"E\":1788564466431,\"T\":1788564466430,\"s\":\"BTCUSDT\",\"ps\":\"BTCUSDT\",\"U\":11478297174464,\"u\":11478297179483,\"pu\":11478297174313,\"b\":[[\"1000.00\",\"24.754\"],[\"29216.80\",\"1.554\"],[\"29616.80\",\"0.546\"],[\"63773.00\",\"0.000\"],[\"63773.40\",\"0.000\"],[\"71745.10\",\"0.002\"],[\"75730.90\",\"0.044\"],[\"76528.10\",\"0.002\"],[\"78919.60\",\"8.056\"],[\"79497.60\",\"0.733\"],[\"79500.80\",\"1.003\"],[\"79529.50\",\"1.378\"],[\"79531.50\",\"0.757\"],[\"79594.50\",\"0.684\"],[\"79710.50\",\"0.000\"],[\"79712.00\",\"0.016\"],[\"79713.60\",\"0.002\"],[\"79713.80\",\"0.003\"],[\"79716.80\",\"2.541\"]],\"a\":[[\"79716.90\",\"15.146\"],[\"79840.10\",\"0.363\"],[\"79866.40\",\"0.500\"],[\"79886.30\",\"0.090\"],[\"80085.60\",\"1.157\"],[\"80086.80\",\"0.778\"],[\"80480.60\",\"1.947\"],[\"80514.10\",\"5.823\"],[\"80952.50\",\"6.417\"]],\"st\":1}}"}
{"receive_ns":1788564466459268000,"stream":"btcusdt@bookTicker","event_type":"bookTicker","event_time_ms":1788564466463,"raw_json":"{\"stream\":\"btcusdt@bookTicker\",\"data\":{\"e\":\"bookTicker\",\"u\":11478297181325,\"s\":\"BTCUSDT\",\"ps\":\"BTCUSDT\",\"b\":\"79716.80\",\"B\":\"1.022\",\"a\":\"79716.90\",\"A\":\"15.146\",\"T\":1788564466463,\"E\":1788564466463,\"st\":1}}"}
{"receive_ns":1788564466471851000,"stream":"btcusdt@trade","event_type":"trade","event_time_ms":1788564466463,"raw_json":"{\"stream\":\"btcusdt@trade\",\"data\":{\"e\":\"trade\",\"E\":1788564466463,\"T\":1788564466463,\"s\":\"BTCUSDT\",\"t\":8054096514,\"p\":\"79716.80\",\"q\":\"0.394\",\"X\":\"MARKET\",\"m\":true,\"st\":1}}"}
{"receive_ns":1788564466477654000,"stream":"btcusdt@trade","event_type":"trade","event_time_ms":1788564466463,"raw_json":"{\"stream\":\"btcusdt@trade\",\"data\":{\"e\":\"trade\",\"E\":1788564466463,\"T\":1788564466463,\"s\":\"BTCUSDT\",\"t\":8054096515,\"p\":\"79716.80\",\"q\":\"0.001\",\"X\":\"MARKET\",\"m\":true,\"st\":1}}"}
{"receive_ns":1788564466483079000,"stream":"btcusdt@trade","event_type":"trade","event_time_ms":1788564466463,"raw_json":"{\"stream\":\"btcusdt@trade\",\"data\":{\"e\":\"trade\",\"E\":1788564466463,\"T\":1788564466463,\"s\":\"BTCUSDT\",\"t\":8054096516,\"p\":\"79716.80\",\"q\":\"0.001\",\"X\":\"MARKET\",\"m\":true,\"st\":1}}"}
{"receive_ns":1788564466488112000,"stream":"btcusdt@trade","event_type":"trade","event_time_ms":1788564466463,"raw_json":"{\"stream\":\"btcusdt@trade\",\"data\":{\"e\":\"trade\",\"E\":1788564466463,\"T\":1788564466463,\"s\":\"BTCUSDT\",\"t\":8054096517,\"p\":\"79716.80\",\"q\":\"0.001\",\"X\":\"MARKET\",\"m\":true,\"st\":1}}"}
{"receive_ns":1788564466494160000,"stream":"btcusdt@trade","event_type":"trade","event_time_ms":1788564466463,"raw_json":"{\"stream\":\"btcusdt@trade\",\"data\":{\"e\":\"trade\",\"E\":1788564466463,\"T\":1788564466463,\"s\":\"BTCUSDT\",\"t\":8054096518,\"p\":\"79716.80\",\"q\":\"0.001\",\"X\":\"MARKET\",\"m\":true,\"st\":1}}"}
{"receive_ns":1788564466500248000,"stream":"btcusdt@trade","event_type":"trade","event_time_ms":1788564466463,"raw_json":"{\"stream\":\"btcusdt@trade\",\"data\":{\"e\":\"trade\",\"E\":1788564466463,\"T\":1788564466463,\"s\":\"BTCUSDT\",\"t\":8054096519,\"p\":\"79716.80\",\"q\":\"0.001\",\"X\":\"MARKET\",\"m\":true,\"st\":1}}"}
{"receive_ns":1788564466500433000,"stream":"btcusdt@trade","event_type":"trade","event_time_ms":1788564466463,"raw_json":"{\"stream\":\"btcusdt@trade\",\"data\":{\"e\":\"trade\",\"E\":1788564466463,\"T\":1788564466463,\"s\":\"BTCUSDT\",\"t\":8054096520,\"p\":\"79716.80\",\"q\":\"0.005\",\"X\":\"MARKET\",\"m\":true,\"st\":1}}"}
{"receive_ns":1788564466500610000,"stream":"btcusdt@trade","event_type":"trade","event_time_ms":1788564466463,"raw_json":"{\"stream\":\"btcusdt@trade\",\"data\":{\"e\":\"trade\",\"E\":1788564466463,\"T\":1788564466463,\"s\":\"BTCUSDT\",\"t\":8054096521,\"p\":\"79716.80\",\"q\":\"0.062\",\"X\":\"MARKET\",\"m\":true,\"st\":1}}"}
{"receive_ns":1788564466500769000,"stream":"btcusdt@trade","event_type":"trade","event_time_ms":1788564466463,"raw_json":"{\"stream\":\"btcusdt@trade\",\"data\":{\"e\":\"trade\",\"E\":1788564466463,\"T\":1788564466463,\"s\":\"BTCUSDT\",\"t\":8054096522,\"p\":\"79716.80\",\"q\":\"0.006\",\"X\":\"MARKET\",\"m\":true,\"st\":1}}"}
{"receive_ns":1788564466500935000,"stream":"btcusdt@trade","event_type":"trade","event_time_ms":1788564466463,"raw_json":"{\"stream\":\"btcusdt@trade\",\"data\":{\"e\":\"trade\",\"E\":1788564466463,\"T\":1788564466463,\"s\":\"BTCUSDT\",\"t\":8054096523,\"p\":\"79716.80\",\"q\":\"0.053\",\"X\":\"MARKET\",\"m\":true,\"st\":1}}"}
{"receive_ns":1788564466506581000,"stream":"btcusdt@trade","event_type":"trade","event_time_ms":1788564466463,"raw_json":"{\"stream\":\"btcusdt@trade\",\"data\":{\"e\":\"trade\",\"E\":1788564466463,\"T\":1788564466463,\"s\":\"BTCUSDT\",\"t\":8054096524,\"p\":\"79716.80\",\"q\":\"0.994\",\"X\":\"MARKET\",\"m\":true,\"st\":1}}"}
{"receive_ns":1788564466506851000,"stream":"btcusdt@bookTicker","event_type":"bookTicker","event_time_ms":1788564466464,"raw_json":"{\"stream\":\"btcusdt@bookTicker\",\"data\":{\"e\":\"bookTicker\",\"u\":11478297181400,\"s\":\"BTCUSDT\",\"ps\":\"BTCUSDT\",\"b\":\"79716.80\",\"B\":\"1.022\",\"a\":\"79716.90\",\"A\":\"15.165\",\"T\":1788564466464,\"E\":1788564466464,\"st\":1}}"}
{"receive_ns":1788564466507045000,"stream":"btcusdt@bookTicker","event_type":"bookTicker","event_time_ms":1788564466464,"raw_json":"{\"stream\":\"btcusdt@bookTicker\",\"data\":{\"e\":\"bookTicker\",\"u\":11478297181406,\"s\":\"BTCUSDT\",\"ps\":\"BTCUSDT\",\"b\":\"79716.80\",\"B\":\"1.022\",\"a\":\"79716.90\",\"A\":\"15.173\",\"T\":1788564466464,\"E\":1788564466464,\"st\":1}}"}
{"receive_ns":1788564466512764000,"stream":"btcusdt@bookTicker","event_type":"bookTicker","event_time_ms":1788564466464,"raw_json":"{\"stream\":\"btcusdt@bookTicker\",\"data\":{\"e\":\"bookTicker\",\"u\":11478297181416,\"s\":\"BTCUSDT\",\"ps\":\"BTCUSDT\",\"b\":\"79716.80\",\"B\":\"1.022\",\"a\":\"79716.90\",\"A\":\"15.175\",\"T\":1788564466464,\"E\":1788564466464,\"st\":1}}"}
{"receive_ns":1788564466519271000,"stream":"btcusdt@bookTicker","event_type":"bookTicker","event_time_ms":1788564466464,"raw_json":"{\"stream\":\"btcusdt@bookTicker\",\"data\":{\"e\":\"bookTicker\",\"u\":11478297181452,\"s\":\"BTCUSDT\",\"ps\":\"BTCUSDT\",\"b\":\"79716.80\",\"B\":\"1.022\",\"a\":\"79716.90\",\"A\":\"15.153\",\"T\":1788564466464,\"E\":1788564466464,\"st\":1}}"}
{"receive_ns":1788564466519476000,"stream":"btcusdt@bookTicker","event_type":"bookTicker","event_time_ms":1788564466464,"raw_json":"{\"stream\":\"btcusdt@bookTicker\",\"data\":{\"e\":\"bookTicker\",\"u\":11478297181456,\"s\":\"BTCUSDT\",\"ps\":\"BTCUSDT\",\"b\":\"79716.80\",\"B\":\"1.022\",\"a\":\"79716.90\",\"A\":\"15.146\",\"T\":1788564466464,\"E\":1788564466464,\"st\":1}}"}
{"receive_ns":1788564466519646000,"stream":"btcusdt@bookTicker","event_type":"bookTicker","event_time_ms":1788564466464,"raw_json":"{\"stream\":\"btcusdt@bookTicker\",\"data\":{\"e\":\"bookTicker\",\"u\":11478297181479,\"s\":\"BTCUSDT\",\"ps\":\"BTCUSDT\",\"b\":\"79716.80\",\"B\":\"1.022\",\"a\":\"79716.90\",\"A\":\"15.135\",\"T\":1788564466464,\"E\":1788564466464,\"st\":1}}"}
{"receive_ns":1788564466519807000,"stream":"btcusdt@bookTicker","event_type":"bookTicker","event_time_ms":1788564466464,"raw_json":"{\"stream\":\"btcusdt@bookTicker\",\"data\":{\"e\":\"bookTicker\",\"u\":11478297181484,\"s\":\"BTCUSDT\",\"ps\":\"BTCUSDT\",\"b\":\"79716.80\",\"B\":\"1.022\",\"a\":\"79716.90\",\"A\":\"15.133\",\"T\":1788564466464,\"E\":1788564466464,\"st\":1}}"}
{"receive_ns":1788564466519986000,"stream":"btcusdt@bookTicker","event_type":"bookTicker","event_time_ms":1788564466464,"raw_json":"{\"stream\":\"btcusdt@bookTicker\",\"data\":{\"e\":\"bookTicker\",\"u\":11478297181486,\"s\":\"BTCUSDT\",\"ps\":\"BTCUSDT\",\"b\":\"79716.80\",\"B\":\"1.608\",\"a\":\"79716.90\",\"A\":\"15.133\",\"T\":1788564466464,\"E\":1788564466464,\"st\":1}}"}
{"receive_ns":1788564466520144000,"stream":"btcusdt@bookTicker","event_type":"bookTicker","event_time_ms":1788564466464,"raw_json":"{\"stream\":\"btcusdt@bookTicker\",\"data\":{\"e\":\"bookTicker\",\"u\":11478297181497,\"s\":\"BTCUSDT\",\"ps\":\"BTCUSDT\",\"b\":\"79716.80\",\"B\":\"1.608\",\"a\":\"79716.90\",\"A\":\"15.098\",\"T\":1788564466464,\"E\":1788564466464,\"st\":1}}"}
{"receive_ns":1788564466520339000,"stream":"btcusdt@bookTicker","event_type":"bookTicker","event_time_ms":1788564466464,"raw_json":"{\"stream\":\"btcusdt@bookTicker\",\"data\":{\"e\":\"bookTicker\",\"u\":11478297181505,\"s\":\"BTCUSDT\",\"ps\":\"BTCUSDT\",\"b\":\"79716.80\",\"B\":\"1.608\",\"a\":\"79716.90\",\"A\":\"15.103\",\"T\":1788564466464,\"E\":1788564466464,\"st\":1}}"}
{"receive_ns":1788564466531212000,"stream":"btcusdt@bookTicker","event_type":"bookTicker","event_time_ms":1788564466464,"raw_json":"{\"stream\":\"btcusdt@bookTicker\",\"data\":{\"e\":\"bookTicker\",\"u\":11478297181512,\"s\":\"BTCUSDT\",\"ps\":\"BTCUSDT\",\"b\":\"79716.80\",\"B\":\"1.608\",\"a\":\"79716.90\",\"A\":\"15.096\",\"T\":1788564466464,\"E\":1788564466464,\"st\":1}}"}
{"receive_ns":1788564466537774000,"stream":"btcusdt@bookTicker","event_type":"bookTicker","event_time_ms":1788564466464,"raw_json":"{\"stream\":\"btcusdt@bookTicker\",\"data\":{\"e\":\"bookTicker\",\"u\":11478297181520,\"s\":\"BTCUSDT\",\"ps\":\"BTCUSDT\",\"b\":\"79716.80\",\"B\":\"1.608\",\"a\":\"79716.90\",\"A\":\"15.080\",\"T\":1788564466464,\"E\":1788564466464,\"st\":1}}"}
{"receive_ns":1788564466537958000,"stream":"btcusdt@bookTicker","event_type":"bookTicker","event_time_ms":1788564466464,"raw_json":"{\"stream\":\"btcusdt@bookTicker\",\"data\":{\"e\":\"bookTicker\",\"u\":11478297181530,\"s\":\"BTCUSDT\",\"ps\":\"BTCUSDT\",\"b\":\"79716.80\",\"B\":\"1.608\",\"a\":\"79716.90\",\"A\":\"15.031\",\"T\":1788564466464,\"E\":1788564466464,\"st\":1}}"}
{"receive_ns":1788564466538146000,"stream":"btcusdt@bookTicker","event_type":"bookTicker","event_time_ms":1788564466464,"raw_json":"{\"stream\":\"btcusdt@bookTicker\",\"data\":{\"e\":\"bookTicker\",\"u\":11478297181534,\"s\":\"BTCUSDT\",\"ps\":\"BTCUSDT\",\"b\":\"79716.80\",\"B\":\"1.608\",\"a\":\"79716.90\",\"A\":\"14.996\",\"T\":1788564466464,\"E\":1788564466464,\"st\":1}}"}
{"receive_ns":1788564466538307000,"stream":"btcusdt@bookTicker","event_type":"bookTicker","event_time_ms":1788564466464,"raw_json":"{\"stream\":\"btcusdt@bookTicker\",\"data\":{\"e\":\"bookTicker\",\"u\":11478297181537,\"s\":\"BTCUSDT\",\"ps\":\"BTCUSDT\",\"b\":\"79716.80\",\"B\":\"1.608\",\"a\":\"79716.90\",\"A\":\"14.977\",\"T\":1788564466464,\"E\":1788564466464,\"st\":1}}"}
{"receive_ns":1788564466538459000,"stream":"btcusdt@bookTicker","event_type":"bookTicker","event_time_ms":1788564466464,"raw_json":"{\"stream\":\"btcusdt@bookTicker\",\"data\":{\"e\":\"bookTicker\",\"u\":11478297181550,\"s\":\"BTCUSDT\",\"ps\":\"BTCUSDT\",\"b\":\"79716.80\",\"B\":\"1.457\",\"a\":\"79716.90\",\"A\":\"14.977\",\"T\":1788564466464,\"E\":1788564466464,\"st\":1}}"}
{"receive_ns":1788564466544135000,"stream":"btcusdt@bookTicker","event_type":"bookTicker","event_time_ms":1788564466464,"raw_json":"{\"stream\":\"btcusdt@bookTicker\",\"data\":{\"e\":\"bookTicker\",\"u\":11478297181557,\"s\":\"BTCUSDT\",\"ps\":\"BTCUSDT\",\"b\":\"79716.80\",\"B\":\"1.457\",\"a\":\"79716.90\",\"A\":\"14.907\",\"T\":1788564466464,\"E\":1788564466464,\"st\":1}}"}
{"receive_ns":1788564466550474000,"stream":"btcusdt@bookTicker","event_type":"bookTicker","event_time_ms":1788564466464,"raw_json":"{\"stream\":\"btcusdt@bookTicker\",\"data\":{\"e\":\"bookTicker\",\"u\":11478297181566,\"s\":\"BTCUSDT\",\"ps\":\"BTCUSDT\",\"b\":\"79716.80\",\"B\":\"1.457\",\"a\":\"79716.90\",\"A\":\"14.903\",\"T\":1788564466464,\"E\":1788564466464,\"st\":1}}"}
{"receive_ns":1788564466556956000,"stream":"btcusdt@bookTicker","event_type":"bookTicker","event_time_ms":1788564466464,"raw_json":"{\"stream\":\"btcusdt@bookTicker\",\"data\":{\"e\":\"bookTicker\",\"u\":11478297181578,\"s\":\"BTCUSDT\",\"ps\":\"BTCUSDT\",\"b\":\"79716.80\",\"B\":\"1.457\",\"a\":\"79716.90\",\"A\":\"14.895\",\"T\":1788564466464,\"E\":1788564466464,\"st\":1}}"}
{"receive_ns":1788564466562369000,"stream":"btcusdt@bookTicker","event_type":"bookTicker","event_time_ms":1788564466464,"raw_json":"{\"stream\":\"btcusdt@bookTicker\",\"data\":{\"e\":\"bookTicker\",\"u\":11478297181591,\"s\":\"BTCUSDT\",\"ps\":\"BTCUSDT\",\"b\":\"79716.80\",\"B\":\"1.810\",\"a\":\"79716.90\",\"A\":\"14.895\",\"T\":1788564466464,\"E\":1788564466464,\"st\":1}}"}
{"receive_ns":1788564466562615000,"stream":"btcusdt@bookTicker","event_type":"bookTicker","event_time_ms":1788564466464,"raw_json":"{\"stream\":\"btcusdt@bookTicker\",\"data\":{\"e\":\"bookTicker\",\"u\":11478297181669,\"s\":\"BTCUSDT\",\"ps\":\"BTCUSDT\",\"b\":\"79716.80\",\"B\":\"1.810\",\"a\":\"79716.90\",\"A\":\"14.864\",\"T\":1788564466464,\"E\":1788564466464,\"st\":1}}"}
{"receive_ns":1788564466568634000,"stream":"btcusdt@bookTicker","event_type":"bookTicker","event_time_ms":1788564466464,"raw_json":"{\"stream\":\"btcusdt@bookTicker\",\"data\":{\"e\":\"bookTicker\",\"u\":11478297181670,\"s\":\"BTCUSDT\",\"ps\":\"BTCUSDT\",\"b\":\"79716.80\",\"B\":\"1.872\",\"a\":\"79716.90\",\"A\":\"14.864\",\"T\":1788564466464,\"E\":1788564466464,\"st\":1}}"}
{"receive_ns":1788564466571189000,"stream":"btcusdt@bookTicker","event_type":"bookTicker","event_time_ms":1788564466464,"raw_json":"{\"stream\":\"btcusdt@bookTicker\",\"data\":{\"e\":\"bookTicker\",\"u\":11478297181671,\"s\":\"BTCUSDT\",\"ps\":\"BTCUSDT\",\"b\":\"79716.80\",\"B\":\"1.872\",\"a\":\"79716.90\",\"A\":\"14.871\",\"T\":1788564466464,\"E\":1788564466464,\"st\":1}}"}
{"receive_ns":1788564466576822000,"stream":"btcusdt@bookTicker","event_type":"bookTicker","event_time_ms":1788564466464,"raw_json":"{\"stream\":\"btcusdt@bookTicker\",\"data\":{\"e\":\"bookTicker\",\"u\":11478297181683,\"s\":\"BTCUSDT\",\"ps\":\"BTCUSDT\",\"b\":\"79716.80\",\"B\":\"1.872\",\"a\":\"79716.90\",\"A\":\"14.869\",\"T\":1788564466464,\"E\":1788564466464,\"st\":1}}"}
{"receive_ns":1788564466577052000,"stream":"btcusdt@bookTicker","event_type":"bookTicker","event_time_ms":1788564466464,"raw_json":"{\"stream\":\"btcusdt@bookTicker\",\"data\":{\"e\":\"bookTicker\",\"u\":11478297181725,\"s\":\"BTCUSDT\",\"ps\":\"BTCUSDT\",\"b\":\"79716.80\",\"B\":\"1.873\",\"a\":\"79716.90\",\"A\":\"14.869\",\"T\":1788564466464,\"E\":1788564466464,\"st\":1}}"}
{"receive_ns":1788564466589443000,"stream":"btcusdt@trade","event_type":"trade","event_time_ms":1788564466464,"raw_json":"{\"stream\":\"btcusdt@trade\",\"data\":{\"e\":\"trade\",\"E\":1788564466464,\"T\":1788564466464,\"s\":\"BTCUSDT\",\"t\":8054096525,\"p\":\"79716.80\",\"q\":\"0.151\",\"X\":\"MARKET\",\"m\":true,\"st\":1}}"}
{"receive_ns":1788564466595698000,"stream":"btcusdt@bookTicker","event_type":"bookTicker","event_time_ms":1788564466465,"raw_json":"{\"stream\":\"btcusdt@bookTicker\",\"data\":{\"e\":\"bookTicker\",\"u\":11478297181749,\"s\":\"BTCUSDT\",\"ps\":\"BTCUSDT\",\"b\":\"79716.80\",\"B\":\"1.882\",\"a\":\"79716.90\",\"A\":\"14.869\",\"T\":1788564466464,\"E\":1788564466465,\"st\":1}}"}
{"receive_ns":1788564466595898000,"stream":"btcusdt@bookTicker","event_type":"bookTicker","event_time_ms":1788564466465,"raw_json":"{\"stream\":\"btcusdt@bookTicker\",\"data\":{\"e\":\"bookTicker\",\"u\":11478297181758,\"s\":\"BTCUSDT\",\"ps\":\"BTCUSDT\",\"b\":\"79716.80\",\"B\":\"1.882\",\"a\":\"79716.90\",\"A\":\"14.867\",\"T\":1788564466464,\"E\":1788564466465,\"st\":1}}"}
{"receive_ns":1788564466596102000,"stream":"btcusdt@bookTicker","event_type":"bookTicker","event_time_ms":1788564466465,"raw_json":"{\"stream\":\"btcusdt@bookTicker\",\"data\":{\"e\":\"bookTicker\",\"u\":11478297181821,\"s\":\"BTCUSDT\",\"ps\":\"BTCUSDT\",\"b\":\"79716.80\",\"B\":\"1.882\",\"a\":\"79716.90\",\"A\":\"14.848\",\"T\":1788564466465,\"E\":1788564466465,\"st\":1}}"}
{"receive_ns":1788564466596337000,"stream":"btcusdt@bookTicker","event_type":"bookTicker","event_time_ms":1788564466465,"raw_json":"{\"stream\":\"btcusdt@bookTicker\",\"data\":{\"e\":\"bookTicker\",\"u\":11478297181830,\"s\":\"BTCUSDT\",\"ps\":\"BTCUSDT\",\"b\":\"79716.80\",\"B\":\"1.882\",\"a\":\"79716.90\",\"A\":\"14.846\",\"T\":1788564466465,\"E\":1788564466465,\"st\":1}}"}
{"receive_ns":1788564466602756000,"stream":"btcusdt@bookTicker","event_type":"bookTicker","event_time_ms":1788564466465,"raw_json":"{\"stream\":\"btcusdt@bookTicker\",\"data\":{\"e\":\"bookTicker\",\"u\":11478297181845,\"s\":\"BTCUSDT\",\"ps\":\"BTCUSDT\",\"b\":\"79716.80\",\"B\":\"1.882\",\"a\":\"79716.90\",\"A\":\"14.841\",\"T\":1788564466465,\"E\":1788564466465,\"st\":1}}"}
{"receive_ns":1788564466602958000,"stream":"btcusdt@bookTicker","event_type":"bookTicker","event_time_ms":1788564466465,"raw_json":"{\"stream\":\"btcusdt@bookTicker\",\"data\":{\"e\":\"bookTicker\",\"u\":11478297181877,\"s\":\"BTCUSDT\",\"ps\":\"BTCUSDT\",\"b\":\"79716.80\",\"B\":\"1.880\",\"a\":\"79716.90\",\"A\":\"14.841\",\"T\":1788564466465,\"E\":1788564466465,\"st\":1}}"}
{"receive_ns":1788564466617531000,"stream":"btcusdt@bookTicker","event_type":"bookTicker","event_time_ms":1788564466465,"raw_json":"{\"stream\":\"btcusdt@bookTicker\",\"data\":{\"e\":\"bookTicker\",\"u\":11478297181928,\"s\":\"BTCUSDT\",\"ps\":\"BTCUSDT\",\"b\":\"79716.80\",\"B\":\"1.880\",\"a\":\"79716.90\",\"A\":\"14.860\",\"T\":1788564466465,\"E\":1788564466465,\"st\":1}}"}
{"receive_ns":1788564466617740000,"stream":"btcusdt@bookTicker","event_type":"bookTicker","event_time_ms":1788564466465,"raw_json":"{\"stream\":\"btcusdt@bookTicker\",\"data\":{\"e\":\"bookTicker\",\"u\":11478297181939,\"s\":\"BTCUSDT\",\"ps\":\"BTCUSDT\",\"b\":\"79716.80\",\"B\":\"1.880\",\"a\":\"79716.90\",\"A\":\"14.853\",\"T\":1788564466465,\"E\":1788564466465,\"st\":1}}"}
{"receive_ns":1788564466617904000,"stream":"btcusdt@bookTicker","event_type":"bookTicker","event_time_ms":1788564466465,"raw_json":"{\"stream\":\"btcusdt@bookTicker\",\"data\":{\"e\":\"bookTicker\",\"u\":11478297181967,\"s\":\"BTCUSDT\",\"ps\":\"BTCUSDT\",\"b\":\"79716.80\",\"B\":\"1.880\",\"a\":\"79716.90\",\"A\":\"14.855\",\"T\":1788564466465,\"E\":1788564466465,\"st\":1}}"}
{"receive_ns":1788564466618060000,"stream":"btcusdt@bookTicker","event_type":"bookTicker","event_time_ms":1788564466465,"raw_json":"{\"stream\":\"btcusdt@bookTicker\",\"data\":{\"e\":\"bookTicker\",\"u\":11478297182028,\"s\":\"BTCUSDT\",\"ps\":\"BTCUSDT\",\"b\":\"79716.80\",\"B\":\"1.294\",\"a\":\"79716.90\",\"A\":\"14.855\",\"T\":1788564466465,\"E\":1788564466465,\"st\":1}}"}
{"receive_ns":1788564466618214000,"stream":"btcusdt@bookTicker","event_type":"bookTicker","event_time_ms":1788564466465,"raw_json":"{\"stream\":\"btcusdt@bookTicker\",\"data\":{\"e\":\"bookTicker\",\"u\":11478297182053,\"s\":\"BTCUSDT\",\"ps\":\"BTCUSDT\",\"b\":\"79716.80\",\"B\":\"1.347\",\"a\":\"79716.90\",\"A\":\"14.855\",\"T\":1788564466465,\"E\":1788564466465,\"st\":1}}"}
{"receive_ns":1788564466618432000,"stream":"btcusdt@bookTicker","event_type":"bookTicker","event_time_ms":1788564466465,"raw_json":"{\"stream\":\"btcusdt@bookTicker\",\"data\":{\"e\":\"bookTicker\",\"u\":11478297182064,\"s\":\"BTCUSDT\",\"ps\":\"BTCUSDT\",\"b\":\"79716.80\",\"B\":\"1.338\",\"a\":\"79716.90\",\"A\":\"14.855\",\"T\":1788564466465,\"E\":1788564466465,\"st\":1}}"}
{"receive_ns":1788564466624594000,"stream":"btcusdt@bookTicker","event_type":"bookTicker","event_time_ms":1788564466466,"raw_json":"{\"stream\":\"btcusdt@bookTicker\",\"data\":{\"e\":\"bookTicker\",\"u\":11478297182099,\"s\":\"BTCUSDT\",\"ps\":\"BTCUSDT\",\"b\":\"79716.80\",\"B\":\"1.339\",\"a\":\"79716.90\",\"A\":\"14.855\",\"T\":1788564466465,\"E\":1788564466466,\"st\":1}}"}
{"receive_ns":1788564466624792000,"stream":"btcusdt@bookTicker","event_type":"bookTicker","event_time_ms":1788564466466,"raw_json":"{\"stream\":\"btcusdt@bookTicker\",\"data\":{\"e\":\"bookTicker\",\"u\":11478297182113,\"s\":\"BTCUSDT\",\"ps\":\"BTCUSDT\",\"b\":\"79716.80\",\"B\":\"1.339\",\"a\":\"79716.90\",\"A\":\"14.857\",\"T\":1788564466465,\"E\":1788564466466,\"st\":1}}"}
{"receive_ns":1788564466624960000,"stream":"btcusdt@bookTicker","event_type":"bookTicker","event_time_ms":1788564466466,"raw_json":"{\"stream\":\"btcusdt@bookTicker\",\"data\":{\"e\":\"bookTicker\",\"u\":11478297182128,\"s\":\"BTCUSDT\",\"ps\":\"BTCUSDT\",\"b\":\"79716.80\",\"B\":\"1.338\",\"a\":\"79716.90\",\"A\":\"14.857\",\"T\":1788564466466,\"E\":1788564466466,\"st\":1}}"}
{"receive_ns":1788564466625117000,"stream":"btcusdt@bookTicker","event_type":"bookTicker","event_time_ms":1788564466466,"raw_json":"{\"stream\":\"btcusdt@bookTicker\",\"data\":{\"e\":\"bookTicker\",\"u\":11478297182137,\"s\":\"BTCUSDT\",\"ps\":\"BTCUSDT\",\"b\":\"79716.80\",\"B\":\"1.339\",\"a\":\"79716.90\",\"A\":\"14.857\",\"T\":1788564466466,\"E\":1788564466466,\"st\":1}}"}
{"receive_ns":1788564466625265000,"stream":"btcusdt@bookTicker","event_type":"bookTicker","event_time_ms":1788564466466,"raw_json":"{\"stream\":\"btcusdt@bookTicker\",\"data\":{\"e\":\"bookTicker\",\"u\":11478297182236,\"s\":\"BTCUSDT\",\"ps\":\"BTCUSDT\",\"b\":\"79716.80\",\"B\":\"1.339\",\"a\":\"79716.90\",\"A\":\"14.838\",\"T\":1788564466466,\"E\":1788564466466,\"st\":1}}"}
{"receive_ns":1788564466625418000,"stream":"btcusdt@bookTicker","event_type":"bookTicker","event_time_ms":1788564466466,"raw_json":"{\"stream\":\"btcusdt@bookTicker\",\"data\":{\"e\":\"bookTicker\",\"u\":11478297182242,\"s\":\"BTCUSDT\",\"ps\":\"BTCUSDT\",\"b\":\"79716.80\",\"B\":\"1.339\",\"a\":\"79716.90\",\"A\":\"14.840\",\"T\":1788564466466,\"E\":1788564466466,\"st\":1}}"}
{"receive_ns":1788564466625564000,"stream":"btcusdt@bookTicker","event_type":"bookTicker","event_time_ms":1788564466466,"raw_json":"{\"stream\":\"btcusdt@bookTicker\",\"data\":{\"e\":\"bookTicker\",\"u\":11478297182247,\"s\":\"BTCUSDT\",\"ps\":\"BTCUSDT\",\"b\":\"79716.80\",\"B\":\"1.339\",\"a\":\"79716.90\",\"A\":\"14.859\",\"T\":1788564466466,\"E\":1788564466466,\"st\":1}}"}
{"receive_ns":1788564466625717000,"stream":"btcusdt@bookTicker","event_type":"bookTicker","event_time_ms":1788564466466,"raw_json":"{\"stream\":\"btcusdt@bookTicker\",\"data\":{\"e\":\"bookTicker\",\"u\":11478297182258,\"s\":\"BTCUSDT\",\"ps\":\"BTCUSDT\",\"b\":\"79716.80\",\"B\":\"1.339\",\"a\":\"79716.90\",\"A\":\"14.857\",\"T\":1788564466466,\"E\":1788564466466,\"st\":1}}"}
{"receive_ns":1788564466637990000,"stream":"btcusdt@bookTicker","event_type":"bookTicker","event_time_ms":1788564466466,"raw_json":"{\"stream\":\"btcusdt@bookTicker\",\"data\":{\"e\":\"bookTicker\",\"u\":11478297182302,\"s\":\"BTCUSDT\",\"ps\":\"BTCUSDT\",\"b\":\"79716.80\",\"B\":\"1.339\",\"a\":\"79716.90\",\"A\":\"14.855\",\"T\":1788564466466,\"E\":1788564466466,\"st\":1}}"}
{"receive_ns":1788564466638205000,"stream":"btcusdt@bookTicker","event_type":"bookTicker","event_time_ms":1788564466466,"raw_json":"{\"stream\":\"btcusdt@bookTicker\",\"data\":{\"e\":\"bookTicker\",\"u\":11478297182325,\"s\":\"BTCUSDT\",\"ps\":\"BTCUSDT\",\"b\":\"79716.80\",\"B\":\"1.341\",\"a\":\"79716.90\",\"A\":\"14.855\",\"T\":1788564466466,\"E\":1788564466466,\"st\":1}}"}
{"receive_ns":1788564466638418000,"stream":"btcusdt@bookTicker","event_type":"bookTicker","event_time_ms":1788564466467,"raw_json":"{\"stream\":\"btcusdt@bookTicker\",\"data\":{\"e\":\"bookTicker\",\"u\":11478297182342,\"s\":\"BTCUSDT\",\"ps\":\"BTCUSDT\",\"b\":\"79716.80\",\"B\":\"1.341\",\"a\":\"79716.90\",\"A\":\"14.857\",\"T\":1788564466466,\"E\":1788564466467,\"st\":1}}"}
{"receive_ns":1788564466653168000,"stream":"btcusdt@bookTicker","event_type":"bookTicker","event_time_ms":1788564466467,"raw_json":"{\"stream\":\"btcusdt@bookTicker\",\"data\":{\"e\":\"bookTicker\",\"u\":11478297182446,\"s\":\"BTCUSDT\",\"ps\":\"BTCUSDT\",\"b\":\"79716.80\",\"B\":\"1.341\",\"a\":\"79716.90\",\"A\":\"14.838\",\"T\":1788564466467,\"E\":1788564466467,\"st\":1}}"}
{"receive_ns":1788564466653384000,"stream":"btcusdt@bookTicker","event_type":"bookTicker","event_time_ms":1788564466467,"raw_json":"{\"stream\":\"btcusdt@bookTicker\",\"data\":{\"e\":\"bookTicker\",\"u\":11478297182454,\"s\":\"BTCUSDT\",\"ps\":\"BTCUSDT\",\"b\":\"79716.80\",\"B\":\"1.341\",\"a\":\"79716.90\",\"A\":\"14.836\",\"T\":1788564466467,\"E\":1788564466467,\"st\":1}}"}
{"receive_ns":1788564466659961000,"stream":"btcusdt@bookTicker","event_type":"bookTicker","event_time_ms":1788564466467,"raw_json":"{\"stream\":\"btcusdt@bookTicker\",\"data\":{\"e\":\"bookTicker\",\"u\":11478297182551,\"s\":\"BTCUSDT\",\"ps\":\"BTCUSDT\",\"b\":\"79716.80\",\"B\":\"1.341\",\"a\":\"79716.90\",\"A\":\"14.834\",\"T\":1788564466467,\"E\":1788564466467,\"st\":1}}"}
{"receive_ns":1788564466660182000,"stream":"btcusdt@bookTicker","event_type":"bookTicker","event_time_ms":1788564466468,"raw_json":"{\"stream\":\"btcusdt@bookTicker\",\"data\":{\"e\":\"bookTicker\",\"u\":11478297182612,\"s\":\"BTCUSDT\",\"ps\":\"BTCUSDT\",\"b\":\"79716.80\",\"B\":\"1.341\",\"a\":\"79716.90\",\"A\":\"14.853\",\"T\":1788564466468,\"E\":1788564466468,\"st\":1}}"}
{"receive_ns":1788564466665659000,"stream":"btcusdt@bookTicker","event_type":"bookTicker","event_time_ms":1788564466468,"raw_json":"{\"stream\":\"btcusdt@bookTicker\",\"data\":{\"e\":\"bookTicker\",\"u\":11478297182763,\"s\":\"BTCUSDT\",\"ps\":\"BTCUSDT\",\"b\":\"79716.80\",\"B\":\"1.341\",\"a\":\"79716.90\",\"A\":\"14.834\",\"T\":1788564466468,\"E\":1788564466468,\"st\":1}}"}
{"receive_ns":1788564466676751000,"stream":"btcusdt@bookTicker","event_type":"bookTicker","event_time_ms":1788564466469,"raw_json":"{\"stream\":\"btcusdt@bookTicker\",\"data\":{\"e\":\"bookTicker\",\"u\":11478297182960,\"s\":\"BTCUSDT\",\"ps\":\"BTCUSDT\",\"b\":\"79716.80\",\"B\":\"1.341\",\"a\":\"79716.90\",\"A\":\"14.853\",\"T\":1788564466469,\"E\":1788564466469,\"st\":1}}"}
{"receive_ns":1788564466688019000,"stream":"btcusdt@bookTicker","event_type":"bookTicker","event_time_ms":1788564466470,"raw_json":"{\"stream\":\"btcusdt@bookTicker\",\"data\":{\"e\":\"bookTicker\",\"u\":11478297183066,\"s\":\"BTCUSDT\",\"ps\":\"BTCUSDT\",\"b\":\"79716.80\",\"B\":\"1.341\",\"a\":\"79716.90\",\"A\":\"14.834\",\"T\":1788564466470,\"E\":1788564466470,\"st\":1}}"}
{"receive_ns":1788564466692297000,"stream":"btcusdt@bookTicker","event_type":"bookTicker","event_time_ms":1788564466471,"raw_json":"{\"stream\":\"btcusdt@bookTicker\",\"data\":{\"e\":\"bookTicker\",\"u\":11478297183259,\"s\":\"BTCUSDT\",\"ps\":\"BTCUSDT\",\"b\":\"79716.80\",\"B\":\"1.341\",\"a\":\"79716.90\",\"A\":\"14.853\",\"T\":1788564466471,\"E\":1788564466471,\"st\":1}}"}
{"receive_ns":1788564466692571000,"stream":"btcusdt@bookTicker","event_type":"bookTicker","event_time_ms":1788564466472,"raw_json":"{\"stream\":\"btcusdt@bookTicker\",\"data\":{\"e\":\"bookTicker\",\"u\":11478297183424,\"s\":\"BTCUSDT\",\"ps\":\"BTCUSDT\",\"b\":\"79716.80\",\"B\":\"1.341\",\"a\":\"79716.90\",\"A\":\"14.834\",\"T\":1788564466472,\"E\":1788564466472,\"st\":1}}"}
{"receive_ns":1788564466692788000,"stream":"btcusdt@bookTicker","event_type":"bookTicker","event_time_ms":1788564466476,"raw_json":"{\"stream\":\"btcusdt@bookTicker\",\"data\":{\"e\":\"bookTicker\",\"u\":11478297183750,\"s\":\"BTCUSDT\",\"ps\":\"BTCUSDT\",\"b\":\"79716.80\",\"B\":\"1.341\",\"a\":\"79716.90\",\"A\":\"14.826\",\"T\":1788564466475,\"E\":1788564466476,\"st\":1}}"}
{"receive_ns":1788564466692991000,"stream":"btcusdt@bookTicker","event_type":"bookTicker","event_time_ms":1788564466476,"raw_json":"{\"stream\":\"btcusdt@bookTicker\",\"data\":{\"e\":\"bookTicker\",\"u\":11478297183768,\"s\":\"BTCUSDT\",\"ps\":\"BTCUSDT\",\"b\":\"79716.80\",\"B\":\"1.341\",\"a\":\"79716.90\",\"A\":\"14.845\",\"T\":1788564466475,\"E\":1788564466476,\"st\":1}}"}
{"receive_ns":1788564466693186000,"stream":"btcusdt@bookTicker","event_type":"bookTicker","event_time_ms":1788564466476,"raw_json":"{\"stream\":\"btcusdt@bookTicker\",\"data\":{\"e\":\"bookTicker\",\"u\":11478297183795,\"s\":\"BTCUSDT\",\"ps\":\"BTCUSDT\",\"b\":\"79716.80\",\"B\":\"1.341\",\"a\":\"79716.90\",\"A\":\"14.847\",\"T\":1788564466475,\"E\":1788564466476,\"st\":1}}"}
{"receive_ns":1788564466699518000,"stream":"btcusdt@bookTicker","event_type":"bookTicker","event_time_ms":1788564466476,"raw_json":"{\"stream\":\"btcusdt@bookTicker\",\"data\":{\"e\":\"bookTicker\",\"u\":11478297183884,\"s\":\"BTCUSDT\",\"ps\":\"BTCUSDT\",\"b\":\"79716.80\",\"B\":\"1.340\",\"a\":\"79716.90\",\"A\":\"14.847\",\"T\":1788564466476,\"E\":1788564466476,\"st\":1}}"}
