{"receive_ns":1788564446005975000,"stream":"btcusdt@depth@100ms","event_type":"depthUpdate","event_time_ms":1788564446031,"raw_json":"{\"stream\":\"btcusdt@depth@100ms\",\"data\":{\"e\":\"depthUpdate\",\"E\":1788564446031,\"T\":1788564446029,\"s\":\"BTCUSDT\",\"ps\":\"BTCUSDT\",\"U\":11478295958399,\"u\":11478295964812,\"pu\":11478295958332,\"b\":[[\"29316.80\",\"0.546\"],[\"29416.80\",\"1.554\"],[\"63773.00\",\"0.000\"],[\"71745.10\",\"0.002\"],[\"78092.60\",\"0.001\"],[\"78181.10\",\"0.013\"],[\"78269.70\",\"0.000\"],[\"78358.20\",\"0.000\"],[\"78446.70\",\"0.000\"],[\"78535.30\",\"0.002\"],[\"78623.80\",\"0.001\"],[\"78712.40\",\"0.000\"],[\"78733.80\",\"3.771\"],[\"78800.90\",\"0.000\"],[\"78889.40\",\"0.000\"],[\"78919.60\",\"1.265\"],[\"78996.90\",\"0.885\"],[\"79500.80\",\"1.003\"],[\"79501.60\",\"2.112\"],[\"79507.00\",\"6.664\"],[\"79529.50\",\"0.876\"],[\"79530.70\",\"0.001\"],[\"79625.20\",\"3.778\"],[\"79689.10\",\"0.001\"],[\"79690.20\",\"0.453\"],[\"79693.10\",\"0.630\"],[\"79698.70\",\"0.316\"],[\"79699.20\",\"0.069\"]],\"a\":[[\"79733.00\",\"0.630\"],[\"79792.60\",\"0.701\"],[\"79807.70\",\"3.340\"],[\"79886.30\",\"0.090\"],[\"79927.60\",\"7.816\"],[\"79938.60\",\"8.745\"],[\"79939.20\",\"0.051\"],[\"80078.80\",\"0.764\"],[\"80087.60\",\"1.147\"],[\"80115.50\",\"0.500\"],[\"80483.20\",\"1.088\"],[\"80514.10\",\"0.000\"],[\"80571.70\",\"0.001\"],[\"80652.80\",\"15.851\"],[\"80660.20\",\"0.000\"],[\"80748.80\",\"0.000\"],[\"80837.30\",\"0.000\"],[\"80925.90\",\"0.000\"],[\"81014.40\",\"0.000\"],[\"81102.90\",\"0.000\"],[\"81191.50\",\"0.000\"],[\"81280.00\",\"0.444\"]],\"st\":1}}"}
{"receive_ns":1788564446058556000,"stream":"btcusdt@bookTicker","event_type":"bookTicker","event_time_ms":1788564446077,"raw_json":"{\"stream\":\"btcusdt@bookTicker\",\"data\":{\"e\":\"bookTicker\",\"u\":11478295968129,\"s\":\"BTCUSDT\",\"ps\":\"BTCUSDT\",\"b\":\"79716.80\",\"B\":\"2.644\",\"a\":\"79716.90\",\"A\":\"15.528\",\"T\":1788564446077,\"E\":1788564446077,\"st\":1}}"}
{"receive_ns":1788564446063906000,"stream":"btcusdt@bookTicker","event_type":"bookTicker","event_time_ms":1788564446080,"raw_json":"{\"stream\":\"btcusdt@bookTicker\",\"data\":{\"e\":\"bookTicker\",\"u\":11478295968508,\"s\":\"BTCUSDT\",\"ps\":\"BTCUSDT\",\"b\":\"79716.80\",\"B\":\"2.644\",\"a\":\"79716.90\",\"A\":\"15.532\",\"T\":1788564446080,\"E\":1788564446080,\"st\":1}}"}
{"receive_ns":1788564446078517000,"stream":"btcusdt@bookTicker","event_type":"bookTicker","event_time_ms":1788564446106,"raw_json":"{\"stream\":\"btcusdt@bookTicker\",\"data\":{\"e\":\"bookTicker\",\"u\":11478295970128,\"s\":\"BTCUSDT\",\"ps\":\"BTCUSDT\",\"b\":\"79716.80\",\"B\":\"2.644\",\"a\":\"79716.90\",\"A\":\"15.551\",\"T\":1788564446105,\"E\":1788564446106,\"st\":1}}"}
{"receive_ns":1788564446078700000,"stream":"btcusdt@bookTicker","event_type":"bookTicker","event_time_ms":1788564446106,"raw_json":"{\"stream\":\"btcusdt@bookTicker\",\"data\":{\"e\":\"bookTicker\",\"u\":11478295970160,\"s\":\"BTCUSDT\",\"ps\":\"BTCUSDT\",\"b\":\"79716.80\",\"B\":\"2.644\",\"a\":\"79716.90\",\"A\":\"15.543\",\"T\":1788564446105,\"E\":1788564446106,\"st\":1}}"}
{"receive_ns":1788564446078850000,"stream":"btcusdt@bookTicker","event_type":"bookTicker","event_time_ms":1788564446106,"raw_json":"{\"stream\":\"btcusdt@bookTicker\",\"data\":{\"e\":\"bookTicker\",\"u\":11478295970201,\"s\":\"BTCUSDT\",\"ps\":\"BTCUSDT\",\"b\":\"79716.80\",\"B\":\"2.644\",\"a\":\"79716.90\",\"A\":\"15.545\",\"T\":1788564446106,\"E\":1788564446106,\"st\":1}}"}
{"receive_ns":1788564446079028000,"stream":"btcusdt@bookTicker","event_type":"bookTicker","event_time_ms":1788564446106,"raw_json":"{\"stream\":\"btcusdt@bookTicker\",\"data\":{\"e\":\"bookTicker\",\"u\":11478295970246,\"s\":\"BTCUSDT\",\"ps\":\"BTCUSDT\",\"b\":\"79716.80\",\"B\":\"2.644\",\"a\":\"79716.90\",\"A\":\"15.526\",\"T\":1788564446106,\"E\":1788564446106,\"st\":1}}"}
{"receive_ns":1788564446079206000,"stream":"btcusdt@bookTicker","event_type":"bookTicker","event_time_ms":1788564446106,"raw_json":"{\"stream\":\"btcusdt@bookTicker\",\"data\":{\"e\":\"bookTicker\",\"u\":11478295970263,\"s\":\"BTCUSDT\",\"ps\":\"BTCUSDT\",\"b\":\"79716.80\",\"B\":\"2.644\",\"a\":\"79716.90\",\"A\":\"15.524\",\"T\":1788564446106,\"E\":1788564446106,\"st\":1}}"}
{"receive_ns":1788564446109277000,"stream":"btcusdt@depth@100ms","event_type":"depthUpdate","event_time_ms":1788564446133,"raw_json":"{\"stream\":\"btcusdt@depth@100ms\",\"data\":{\"e\":\"depthUpdate\",\"E\":1788564446133,\"T\":1788564446129,\"s\":\"BTCUSDT\",\"ps\":\"BTCUSDT\",\"U\":11478295964958,\"u\":11478295971443,\"pu\":11478295964812,\"b\":[[\"29316.80\",\"0.721\"],[\"29416.80\",\"1.379\"],[\"63773.00\",\"0.000\"],[\"63773.40\",\"0.002\"],[\"71745.10\",\"0.002\"],[\"76528.10\",\"0.002\"],[\"77211.90\",\"1.005\"],[\"78488.30\",\"9.634\"],[\"78919.60\",\"1.265\"],[\"79318.20\",\"0.656\"],[\"79501.60\",\"1.862\"],[\"79529.50\",\"0.876\"],[\"79583.60\",\"0.012\"],[\"79645.00\",\"0.004\"],[\"79702.50\",\"0.000\"],[\"79709.40\",\"0.172\"],[\"79712.70\",\"0.000\"],[\"79713.30\",\"0.002\"],[\"79713.40\",\"0.000\"],[\"79715.90\",\"0.315\"],[\"79716.10\",\"0.000\"]],\"a\":[[\"79716.90\",\"15.524\"],[\"79725.70\",\"0.250\"],[\"79726.80\",\"0.003\"],[\"79751.20\",\"0.001\"],[\"79772.80\",\"0.316\"],[\"79792.60\",\"0.701\"],[\"80087.60\",\"0.992\"],[\"80514.10\",\"0.000\"],[\"80652.80\",\"15.357\"],[\"80734.80\",\"1.856\"],[\"81550.40\",\"1.837\"]],\"st\":1}}"}
{"receive_ns":1788564446109541000,"stream":"btcusdt@bookTicker","event_type":"bookTicker","event_time_ms":1788564446134,"raw_json":"{\"stream\":\"btcusdt@bookTicker\",\"data\":{\"e\":\"bookTicker\",\"u\":11478295971730,\"s\":\"BTCUSDT\",\"ps\":\"BTCUSDT\",\"b\":\"79716.80\",\"B\":\"2.644\",\"a\":\"79716.90\",\"A\":\"15.543\",\"T\":1788564446133,\"E\":1788564446134,\"st\":1}}"}
{"receive_ns":1788564446109755000,"stream":"btcusdt@bookTicker","event_type":"bookTicker","event_time_ms":1788564446134,"raw_json":"{\"stream\":\"btcusdt@bookTicker\",\"data\":{\"e\":\"bookTicker\",\"u\":11478295971740,\"s\":\"BTCUSDT\",\"ps\":\"BTCUSDT\",\"b\":\"79716.80\",\"B\":\"2.644\",\"a\":\"79716.90\",\"A\":\"15.545\",\"T\":1788564446133,\"E\":1788564446134,\"st\":1}}"}
{"receive_ns":1788564446109975000,"stream":"btcusdt@bookTicker","event_type":"bookTicker","event_time_ms":1788564446134,"raw_json":"{\"stream\":\"btcusdt@bookTicker\",\"data\":{\"e\":\"bookTicker\",\"u\":11478295971804,\"s\":\"BTCUSDT\",\"ps\":\"BTCUSDT\",\"b\":\"79716.80\",\"B\":\"2.644\",\"a\":\"79716.90\",\"A\":\"15.526\",\"T\":1788564446134,\"E\":1788564446134,\"st\":1}}"}
{"receive_ns":1788564446110221000,"stream":"btcusdt@bookTicker","event_type":"bookTicker","event_time_ms":1788564446134,"raw_json":"{\"stream\":\"btcusdt@bookTicker\",\"data\":{\"e\":\"bookTicker\",\"u\":11478295971807,\"s\":\"BTCUSDT\",\"ps\":\"BTCUSDT\",\"b\":\"79716.80\",\"B\":\"2.644\",\"a\":\"79716.90\",\"A\":\"15.524\",\"T\":1788564446134,\"E\":1788564446134,\"st\":1}}"}
{"receive_ns":1788564446140979000,"stream":"btcusdt@bookTicker","event_type":"bookTicker","event_time_ms":1788564446160,"raw_json":"{\"stream\":\"btcusdt@bookTicker\",\"data\":{\"e\":\"bookTicker\",\"u\":11478295973125,\"s\":\"BTCUSDT\",\"ps\":\"BTCUSDT\",\"b\":\"79716.80\",\"B\":\"2.644\",\"a\":\"79716.90\",\"A\":\"15.543\",\"T\":1788564446159,\"E\":1788564446160,\"st\":1}}"}
{"receive_ns":1788564446147569000,"stream":"btcusdt@bookTicker","event_type":"bookTicker","event_time_ms":1788564446160,"raw_json":"{\"stream\":\"btcusdt@bookTicker\",\"data\":{\"e\":\"bookTicker\",\"u\":11478295973143,\"s\":\"BTCUSDT\",\"ps\":\"BTCUSDT\",\"b\":\"79716.80\",\"B\":\"2.644\",\"a\":\"79716.90\",\"A\":\"15.545\",\"T\":1788564446160,\"E\":1788564446160,\"st\":1}}"}
{"receive_ns":1788564446184601000,"stream":"btcusdt@bookTicker","event_type":"bookTicker","event_time_ms":1788564446160,"raw_json":"{\"stream\":\"btcusdt@bookTicker\",\"data\":{\"e\":\"bookTicker\",\"u\":11478295973202,\"s\":\"BTCUSDT\",\"ps\":\"BTCUSDT\",\"b\":\"79716.80\",\"B\":\"2.644\",\"a\":\"79716.90\",\"A\":\"15.526\",\"T\":1788564446160,\"E\":1788564446160,\"st\":1}}"}
{"receive_ns":1788564446184873000,"stream":"btcusdt@bookTicker","event_type":"bookTicker","event_time_ms":1788564446161,"raw_json":"{\"stream\":\"btcusdt@bookTicker\",\"data\":{\"e\":\"bookTicker\",\"u\":11478295973227,\"s\":\"BTCUSDT\",\"ps\":\"BTCUSDT\",\"b\":\"79716.80\",\"B\":\"2.644\",\"a\":\"79716.90\",\"A\":\"15.524\",\"T\":1788564446160,\"E\":1788564446161,\"st\":1}}"}
{"receive_ns":1788564446190278000,"stream":"btcusdt@bookTicker","event_type":"bookTicker","event_time_ms":1788564446166,"raw_json":"{\"stream\":\"btcusdt@bookTicker\",\"data\":{\"e\":\"bookTicker\",\"u\":11478295973626,\"s\":\"BTCUSDT\",\"ps\":\"BTCUSDT\",\"b\":\"79716.80\",\"B\":\"2.619\",\"a\":\"79716.90\",\"A\":\"15.524\",\"T\":1788564446166,\"E\":1788564446166,\"st\":1}}"}
{"receive_ns":1788564446196897000,"stream":"btcusdt@trade","event_type":"trade","event_time_ms":1788564446166,"raw_json":"{\"stream\":\"btcusdt@trade\",\"data\":{\"e\":\"trade\",\"E\":1788564446166,\"T\":1788564446166,\"s\":\"BTCUSDT\",\"t\":8054096451,\"p\":\"79716.80\",\"q\":\"0.025\",\"X\":\"MARKET\",\"m\":true,\"st\":1}}"}
{"receive_ns":1788564446203209000,"stream":"btcusdt@bookTicker","event_type":"bookTicker","event_time_ms":1788564446167,"raw_json":"{\"stream\":\"btcusdt@bookTicker\",\"data\":{\"e\":\"bookTicker\",\"u\":11478295973720,\"s\":\"BTCUSDT\",\"ps\":\"BTCUSDT\",\"b\":\"79716.80\",\"B\":\"2.619\",\"a\":\"79716.90\",\"A\":\"15.532\",\"T\":1788564446167,\"E\":1788564446167,\"st\":1}}"}
{"receive_ns":1788564446203498000,"stream":"btcusdt@bookTicker","event_type":"bookTicker","event_time_ms":1788564446167,"raw_json":"{\"stream\":\"btcusdt@bookTicker\",\"data\":{\"e\":\"bookTicker\",\"u\":11478295973737,\"s\":\"BTCUSDT\",\"ps\":\"BTCUSDT\",\"b\":\"79716.80\",\"B\":\"2.619\",\"a\":\"79716.90\",\"A\":\"15.534\",\"T\":1788564446167,\"E\":1788564446167,\"st\":1}}"}
{"receive_ns":1788564446203758000,"stream":"btcusdt@bookTicker","event_type":"bookTicker","event_time_ms":1788564446167,"raw_json":"{\"stream\":\"btcusdt@bookTicker\",\"data\":{\"e\":\"bookTicker\",\"u\":11478295973752,\"s\":\"BTCUSDT\",\"ps\":\"BTCUSDT\",\"b\":\"79716.80\",\"B\":\"2.619\",\"a\":\"79716.90\",\"A\":\"15.553\",\"T\":1788564446167,\"E\":1788564446167,\"st\":1}}"}
{"receive_ns":1788564446209208000,"stream":"btcusdt@bookTicker","event_type":"bookTicker","event_time_ms":1788564446168,"raw_json":"{\"stream\":\"btcusdt@bookTicker\",\"data\":{\"e\":\"bookTicker\",\"u\":11478295973866,\"s\":\"BTCUSDT\",\"ps\":\"BTCUSDT\",\"b\":\"79716.80\",\"B\":\"2.619\",\"a\":\"79716.90\",\"A\":\"15.551\",\"T\":1788564446168,\"E\":1788564446168,\"st\":1}}"}
{"receive_ns":1788564446209511000,"stream":"btcusdt@bookTicker","event_type":"bookTicker","event_time_ms":1788564446168,"raw_json":"{\"stream\":\"btcusdt@bookTicker\",\"data\":{\"e\":\"bookTicker\",\"u\":11478295973870,\"s\":\"BTCUSDT\",\"ps\":\"BTCUSDT\",\"b\":\"79716.80\",\"B\":\"2.619\",\"a\":\"79716.90\",\"A\":\"15.532\",\"T\":1788564446168,\"E\":1788564446168,\"st\":1}}"}
{"receive_ns":1788564446216247000,"stream":"btcusdt@bookTicker","event_type":"bookTicker","event_time_ms":1788564446193,"raw_json":"{\"stream\":\"btcusdt@bookTicker\",\"data\":{\"e\":\"bookTicker\",\"u\":11478295975146,\"s\":\"BTCUSDT\",\"ps\":\"BTCUSDT\",\"b\":\"79716.80\",\"B\":\"2.657\",\"a\":\"79716.90\",\"A\":\"15.532\",\"T\":1788564446193,\"E\":1788564446193,\"st\":1}}"}
{"receive_ns":1788564446216669000,"stream":"btcusdt@bookTicker","event_type":"bookTicker","event_time_ms":1788564446193,"raw_json":"{\"stream\":\"btcusdt@bookTicker\",\"data\":{\"e\":\"bookTicker\",\"u\":11478295975156,\"s\":\"BTCUSDT\",\"ps\":\"BTCUSDT\",\"b\":\"79716.80\",\"B\":\"2.695\",\"a\":\"79716.90\",\"A\":\"15.532\",\"T\":1788564446193,\"E\":1788564446193,\"st\":1}}"}
{"receive_ns":1788564446218875000,"stream":"btcusdt@bookTicker","event_type":"bookTicker","event_time_ms":1788564446194,"raw_json":"{\"stream\":\"btcusdt@bookTicker\",\"data\":{\"e\":\"bookTicker\",\"u\":11478295975223,\"s\":\"BTCUSDT\",\"ps\":\"BTCUSDT\",\"b\":\"79716.80\",\"B\":\"2.694\",\"a\":\"79716.90\",\"A\":\"15.532\",\"T\":1788564446194,\"E\":1788564446194,\"st\":1}}"}
{"receive_ns":1788564446224892000,"stream":"btcusdt@bookTicker","event_type":"bookTicker","event_time_ms":1788564446194,"raw_json":"{\"stream\":\"btcusdt@bookTicker\",\"data\":{\"e\":\"bookTicker\",\"u\":11478295975250,\"s\":\"BTCUSDT\",\"ps\":\"BTCUSDT\",\"b\":\"79716.80\",\"B\":\"2.692\",\"a\":\"79716.90\",\"A\":\"15.532\",\"T\":1788564446194,\"E\":1788564446194,\"st\":1}}"}
{"receive_ns":1788564446231175000,"stream":"btcusdt@bookTicker","event_type":"bookTicker","event_time_ms":1788564446195,"raw_json":"{\"stream\":\"btcusdt@bookTicker\",\"data\":{\"e\":\"bookTicker\",\"u\":11478295975290,\"s\":\"BTCUSDT\",\"ps\":\"BTCUSDT\",\"b\":\"79716.80\",\"B\":\"2.693\",\"a\":\"79716.90\",\"A\":\"15.532\",\"T\":1788564446195,\"E\":1788564446195,\"st\":1}}"}
{"receive_ns":1788564446237870000,"stream":"btcusdt@bookTicker","event_type":"bookTicker","event_time_ms":1788564446216,"raw_json":"{\"stream\":\"btcusdt@bookTicker\",\"data\":{\"e\":\"bookTicker\",\"u\":11478295976565,\"s\":\"BTCUSDT\",\"ps\":\"BTCUSDT\",\"b\":\"79716.80\",\"B\":\"2.693\",\"a\":\"79716.90\",\"A\":\"15.524\",\"T\":1788564446215,\"E\":1788564446216,\"st\":1}}"}
{"receive_ns":1788564446238220000,"stream":"btcusdt@bookTicker","event_type":"bookTicker","event_time_ms":1788564446216,"raw_json":"{\"stream\":\"btcusdt@bookTicker\",\"data\":{\"e\":\"bookTicker\",\"u\":11478295976576,\"s\":\"BTCUSDT\",\"ps\":\"BTCUSDT\",\"b\":\"79716.80\",\"B\":\"2.693\",\"a\":\"79716.90\",\"A\":\"15.526\",\"T\":1788564446216,\"E\":1788564446216,\"st\":1}}"}
{"receive_ns":1788564446238542000,"stream":"btcusdt@bookTicker","event_type":"bookTicker","event_time_ms":1788564446216,"raw_json":"{\"stream\":\"btcusdt@bookTicker\",\"data\":{\"e\":\"bookTicker\",\"u\":11478295976596,\"s\":\"BTCUSDT\",\"ps\":\"BTCUSDT\",\"b\":\"79716.80\",\"B\":\"2.693\",\"a\":\"79716.90\",\"A\":\"15.545\",\"T\":1788564446216,\"E\":1788564446216,\"st\":1}}"}
{"receive_ns":1788564446244032000,"stream":"btcusdt@bookTicker","event_type":"bookTicker","event_time_ms":1788564446216,"raw_json":"{\"stream\":\"btcusdt@bookTicker\",\"data\":{\"e\":\"bookTicker\",\"u\":11478295976638,\"s\":\"BTCUSDT\",\"ps\":\"BTCUSDT\",\"b\":\"79716.80\",\"B\":\"2.693\",\"a\":\"79716.90\",\"A\":\"15.543\",\"T\":1788564446216,\"E\":1788564446216,\"st\":1}}"}
{"receive_ns":1788564446249732000,"stream":"btcusdt@bookTicker","event_type":"bookTicker","event_time_ms":1788564446217,"raw_json":"{\"stream\":\"btcusdt@bookTicker\",\"data\":{\"e\":\"bookTicker\",\"u\":11478295976650,\"s\":\"BTCUSDT\",\"ps\":\"BTCUSDT\",\"b\":\"79716.80\",\"B\":\"2.693\",\"a\":\"79716.90\",\"A\":\"15.524\",\"T\":1788564446217,\"E\":1788564446217,\"st\":1}}"}
{"receive_ns":1788564446250161000,"stream":"btcusdt@bookTicker","event_type":"bookTicker","event_time_ms":1788564446217,"raw_json":"{\"stream\":\"btcusdt@bookTicker\",\"data\":{\"e\":\"bookTicker\",\"u\":11478295976664,\"s\":\"BTCUSDT\",\"ps\":\"BTCUSDT\",\"b\":\"79716.80\",\"B\":\"2.695\",\"a\":\"79716.90\",\"A\":\"15.524\",\"T\":1788564446217,\"E\":1788564446217,\"st\":1}}"}
{"receive_ns":1788564446259265000,"stream":"btcusdt@depth@100ms","event_type":"depthUpdate","event_time_ms":1788564446235,"raw_json":"{\"stream\":\"btcusdt@depth@100ms\",\"data\":{\"e\":\"depthUpdate\",\"E\":1788564446235,\"T\":1788564446233,\"s\":\"BTCUSDT\",\"ps\":\"BTCUSDT\",\"U\":11478295971694,\"u\":11478295977460,\"pu\":11478295971443,\"b\":[[\"1000.00\",\"24.754\"],[\"29316.80\",\"0.903\"],[\"29416.80\",\"1.197\"],[\"63773.40\",\"0.000\"],[\"71745.10\",\"0.002\"],[\"76528.10\",\"0.000\"],[\"78123.70\",\"0.006\"],[\"78568.10\",\"5.507\"],[\"78733.60\",\"17.098\"],[\"78919.60\",\"1.265\"],[\"79297.80\",\"2.643\"],[\"79318.20\",\"0.655\"],[\"79351.90\",\"8.084\"],[\"79497.60\",\"0.733\"],[\"79500.80\",\"0.000\"],[\"79501.60\",\"0.628\"],[\"79529.50\",\"2.129\"],[\"79530.70\",\"1.004\"],[\"79591.70\",\"2.976\"],[\"79621.10\",\"0.038\"],[\"79627.50\",\"1.349\"],[\"79632.40\",\"0.838\"],[\"79645.00\",\"0.004\"],[\"79648.40\",\"1.030\"],[\"79659.90\",\"1.960\"],[\"79703.50\",\"0.005\"],[\"79704.20\",\"0.001\"],[\"79709.40\",\"0.200\"],[\"79709.50\",\"0.027\"],[\"79709.60\",\"0.028\"],[\"79709.70\",\"0.026\"],[\"79710.30\",\"0.027\"],[\"79710.70\",\"0.003\"],[\"79710.90\",\"0.003\"],[\"79711.00\",\"0.000\"],[\"79711.10\",\"0.025\"],[\"79711.20\",\"0.004\"],[\"79711.40\",\"0.000\"],[\"79712.80\",\"0.000\"],[\"79715.80\",\"0.318\"],[\"79715.90\",\"0.002\"],[\"79716.10\",\"0.000\"],[\"79716.80\",\"2.695\"]],\"a\":[[\"79716.90\",\"15.524\"],[\"79732.70\",\"0.693\"],[\"79749.30\",\"0.006\"],[\"79756.80\",\"0.794\"],[\"79772.80\",\"0.314\"],[\"79792.60\",\"0.791\"],[\"79800.00\",\"5.013\"],[\"79814.30\",\"0.001\"],[\"79816.20\",\"0.003\"],[\"79817.70\",\"0.002\"],[\"79840.70\",\"1.972\"],[\"79886.30\",\"0.000\"],[\"79957.00\",\"2.639\"],[\"80001.00\",\"0.028\"],[\"80078.80\",\"0.764\"],[\"80087.60\",\"1.147\"],[\"80115.50\",\"0.501\"],[\"80514.10\",\"0.000\"],[\"80713.40\",\"1.887\"]],\"st\":1}}"}
{"receive_ns":1788564446272167000,"stream":"btcusdt@bookTicker","event_type":"bookTicker","event_time_ms":1788564446236,"raw_json":"{\"stream\":\"btcusdt@bookTicker\",\"data\":{\"e\":\"bookTicker\",\"u\":11478295977580,\"s\":\"BTCUSDT\",\"ps\":\"BTCUSDT\",\"b\":\"79716.80\",\"B\":\"2.695\",\"a\":\"79716.90\",\"A\":\"15.526\",\"T\":1788564446236,\"E\":1788564446236,\"st\":1}}"}
{"receive_ns":1788564446272930000,"stream":"btcusdt@bookTicker","event_type":"bookTicker","event_time_ms":1788564446236,"raw_json":"{\"stream\":\"btcusdt@bookTicker\",\"data\":{\"e\":\"bookTicker\",\"u\":11478295977609,\"s\":\"BTCUSDT\",\"ps\":\"BTCUSDT\",\"b\":\"79716.80\",\"B\":\"2.695\",\"a\":\"79716.90\",\"A\":\"15.545\",\"T\":1788564446236,\"E\":1788564446236,\"st\":1}}"}
{"receive_ns":1788564446279746000,"stream":"btcusdt@bookTicker","event_type":"bookTicker","event_time_ms":1788564446236,"raw_json":"{\"stream\":\"btcusdt@bookTicker\",\"data\":{\"e\":\"bookTicker\",\"u\":11478295977635,\"s\":\"BTCUSDT\",\"ps\":\"BTCUSDT\",\"b\":\"79716.80\",\"B\":\"2.695\",\"a\":\"79716.90\",\"A\":\"15.543\",\"T\":1788564446236,\"E\":1788564446236,\"st\":1}}"}
{"receive_ns":1788564446286308000,"stream":"btcusdt@bookTicker","event_type":"bookTicker","event_time_ms":1788564446237,"raw_json":"{\"stream\":\"btcusdt@bookTicker\",\"data\":{\"e\":\"bookTicker\",\"u\":11478295977649,\"s\":\"BTCUSDT\",\"ps\":\"BTCUSDT\",\"b\":\"79716.80\",\"B\":\"2.695\",\"a\":\"79716.90\",\"A\":\"15.524\",\"T\":1788564446237,\"E\":1788564446237,\"st\":1}}"}
{"receive_ns":1788564446316601000,"stream":"btcusdt@depth@100ms","event_type":"depthUpdate","event_time_ms":1788564446337,"raw_json":"{\"stream\":\"btcusdt@depth@100ms\",\"data\":{\"e\":\"depthUpdate\",\"E\":1788564446337,\"T\":1788564446333,\"s\":\"BTCUSDT\",\"ps\":\"BTCUSDT\",\"U\":11478295977580,\"u\":11478295982857,\"pu\":11478295977460,\"b\":[[\"29316.80\",\"1.078\"],[\"29416.80\",\"1.022\"],[\"63773.00\",\"0.000\"],[\"71745.10\",\"0.002\"],[\"76528.10\",\"0.002\"],[\"78545.00\",\"1.026\"],[\"78919.60\",\"1.265\"],[\"79318.20\",\"0.655\"],[\"79460.80\",\"0.000\"],[\"79485.00\",\"0.003\"],[\"79529.50\",\"2.129\"],[\"79710.60\",\"0.026\"]],\"a\":[[\"79716.90\",\"15.524\"],[\"79725.70\",\"0.000\"],[\"79726.50\",\"0.340\"],[\"79792.60\",\"0.791\"],[\"80087.60\",\"1.147\"],[\"80514.10\",\"0.000\"],[\"80700.50\",\"0.372\"],[\"80713.40\",\"2.815\"],[\"80718.10\",\"0.014\"],[\"80726.50\",\"4.827\"],[\"80753.20\",\"0.247\"],[\"80757.70\",\"0.000\"],[\"80766.40\",\"0.140\"],[\"80809.00\",\"0.987\"]],\"st\":1}}"}
{"receive_ns":1788564446317059000,"stream":"btcusdt@bookTicker","event_type":"bookTicker","event_time_ms":1788564446338,"raw_json":"{\"stream\":\"btcusdt@bookTicker\",\"data\":{\"e\":\"bookTicker\",\"u\":11478295983067,\"s\":\"BTCUSDT\",\"ps\":\"BTCUSDT\",\"b\":\"79716.80\",\"B\":\"2.695\",\"a\":\"79716.90\",\"A\":\"15.523\",\"T\":1788564446338,\"E\":1788564446338,\"st\":1}}"}
{"receive_ns":1788564446317483000,"stream":"btcusdt@trade","event_type":"trade","event_time_ms":1788564446338,"raw_json":"{\"stream\":\"btcusdt@trade\",\"data\":{\"e\":\"trade\",\"E\":1788564446338,\"T\":1788564446338,\"s\":\"BTCUSDT\",\"t\":8054096452,\"p\":\"79716.90\",\"q\":\"0.001\",\"X\":\"MARKET\",\"m\":false,\"st\":1}}"}
{"receive_ns":1788564446317917000,"stream":"btcusdt@bookTicker","event_type":"bookTicker","event_time_ms":1788564446339,"raw_json":"{\"stream\":\"btcusdt@bookTicker\",\"data\":{\"e\":\"bookTicker\",\"u\":11478295983163,\"s\":\"BTCUSDT\",\"ps\":\"BTCUSDT\",\"b\":\"79716.80\",\"B\":\"2.695\",\"a\":\"79716.90\",\"A\":\"15.542\",\"T\":1788564446339,\"E\":1788564446339,\"st\":1}}"}
{"receive_ns":1788564446318357000,"stream":"btcusdt@bookTicker","event_type":"bookTicker","event_time_ms":1788564446339,"raw_json":"{\"stream\":\"btcusdt@bookTicker\",\"data\":{\"e\":\"bookTicker\",\"u\":11478295983184,\"s\":\"BTCUSDT\",\"ps\":\"BTCUSDT\",\"b\":\"79716.80\",\"B\":\"2.695\",\"a\":\"79716.90\",\"A\":\"15.544\",\"T\":1788564446339,\"E\":1788564446339,\"st\":1}}"}
{"receive_ns":1788564446325181000,"stream":"btcusdt@bookTicker","event_type":"bookTicker","event_time_ms":1788564446340,"raw_json":"{\"stream\":\"btcusdt@bookTicker\",\"data\":{\"e\":\"bookTicker\",\"u\":11478295983283,\"s\":\"BTCUSDT\",\"ps\":\"BTCUSDT\",\"b\":\"79716.80\",\"B\":\"2.695\",\"a\":\"79716.90\",\"A\":\"15.525\",\"T\":1788564446340,\"E\":1788564446340,\"st\":1}}"}
{"receive_ns":1788564446325657000,"stream":"btcusdt@bookTicker","event_type":"bookTicker","event_time_ms":1788564446340,"raw_json":"{\"stream\":\"btcusdt@bookTicker\",\"data\":{\"e\":\"bookTicker\",\"u\":11478295983299,\"s\":\"BTCUSDT\",\"ps\":\"BTCUSDT\",\"b\":\"79716.80\",\"B\":\"2.695\",\"a\":\"79716.90\",\"A\":\"15.523\",\"T\":1788564446340,\"E\":1788564446340,\"st\":1}}"}
{"receive_ns":1788564446336049000,"stream":"btcusdt@bookTicker","event_type":"bookTicker","event_time_ms":1788564446367,"raw_json":"{\"stream\":\"btcusdt@bookTicker\",\"data\":{\"e\":\"bookTicker\",\"u\":11478295984839,\"s\":\"BTCUSDT\",\"ps\":\"BTCUSDT\",\"b\":\"79716.80\",\"B\":\"2.695\",\"a\":\"79716.90\",\"A\":\"15.542\",\"T\":1788564446366,\"E\":1788564446367,\"st\":1}}"}
{"receive_ns":1788564446342542000,"stream":"btcusdt@bookTicker","event_type":"bookTicker","event_time_ms":1788564446367,"raw_json":"{\"stream\":\"btcusdt@bookTicker\",\"data\":{\"e\":\"bookTicker\",\"u\":11478295984927,\"s\":\"BTCUSDT\",\"ps\":\"BTCUSDT\",\"b\":\"79716.80\",\"B\":\"2.695\",\"a\":\"79716.90\",\"A\":\"15.523\",\"T\":1788564446367,\"E\":1788564446367,\"st\":1}}"}
{"receive_ns":1788564446390575000,"stream":"btcusdt@bookTicker","event_type":"bookTicker","event_time_ms":1788564446409,"raw_json":"{\"stream\":\"btcusdt@bookTicker\",\"data\":{\"e\":\"bookTicker\",\"u\":11478295987150,\"s\":\"BTCUSDT\",\"ps\":\"BTCUSDT\",\"b\":\"79716.80\",\"B\":\"2.695\",\"a\":\"79716.90\",\"A\":\"15.312\",\"T\":1788564446409,\"E\":1788564446409,\"st\":1}}"}
{"receive_ns":1788564446419877000,"stream":"btcusdt@depth@100ms","event_type":"depthUpdate","event_time_ms":1788564446439,"raw_json":"{\"stream\":\"btcusdt@depth@100ms\",\"data\":{\"e\":\"depthUpdate\",\"E\":1788564446439,\"T\":1788564446438,\"s\":\"BTCUSDT\",\"ps\":\"BTCUSDT\",\"U\":11478295983043,\"u\":11478295989513,\"pu\":11478295982857,\"b\":[[\"1000.00\",\"24.754\"],[\"29316.80\",\"1.260\"],[\"29416.80\",\"0.840\"],[\"34000.00\",\"0.975\"],[\"71745.10\",\"0.002\"],[\"76528.10\",\"0.000\"],[\"78122.50\",\"0.027\"],[\"78600.80\",\"0.024\"],[\"78760.20\",\"3.169\"],[\"78919.60\",\"1.265\"],[\"79318.20\",\"0.781\"],[\"79497.60\",\"0.502\"],[\"79529.50\",\"0.951\"],[\"79530.70\",\"0.001\"],[\"79699.70\",\"0.111\"],[\"79709.40\",\"0.174\"],[\"79709.50\",\"0.001\"],[\"79709.60\",\"0.002\"],[\"79709.70\",\"0.000\"],[\"79711.70\",\"0.026\"],[\"79712.50\",\"0.026\"],[\"79712.70\",\"0.026\"],[\"79712.80\",\"0.026\"]],\"a\":[[\"79716.90\",\"15.312\"],[\"79720.00\",\"0.024\"],[\"79720.40\",\"0.000\"],[\"79792.60\",\"0.451\"],[\"79952.10\",\"0.326\"],[\"80008.00\",\"0.516\"],[\"80078.80\",\"0.002\"],[\"80087.60\",\"0.579\"],[\"80514.10\",\"0.000\"],[\"80713.40\",\"3.025\"]],\"st\":1}}"}
{"receive_ns":1788564446509195000,"stream":"btcusdt@bookTicker","event_type":"bookTicker","event_time_ms":1788564446466,"raw_json":"{\"stream\":\"btcusdt@bookTicker\",\"data\":{\"e\":\"bookTicker\",\"u\":11478295991686,\"s\":\"BTCUSDT\",\"ps\":\"BTCUSDT\",\"b\":\"79716.80\",\"B\":\"2.695\",\"a\":\"79716.90\",\"A\":\"15.305\",\"T\":1788564446466,\"E\":1788564446466,\"st\":1}}"}
{"receive_ns":1788564446521291000,"stream":"btcusdt@bookTicker","event_type":"bookTicker","event_time_ms":1788564446469,"raw_json":"{\"stream\":\"btcusdt@bookTicker\",\"data\":{\"e\":\"bookTicker\",\"u\":11478295991906,\"s\":\"BTCUSDT\",\"ps\":\"BTCUSDT\",\"b\":\"79716.80\",\"B\":\"2.695\",\"a\":\"79716.90\",\"A\":\"15.313\",\"T\":1788564446469,\"E\":1788564446469,\"st\":1}}"}
{"receive_ns":1788564446537126000,"stream":"btcusdt@bookTicker","event_type":"bookTicker","event_time_ms":1788564446485,"raw_json":"{\"stream\":\"btcusdt@bookTicker\",\"data\":{\"e\":\"bookTicker\",\"u\":11478295992756,\"s\":\"BTCUSDT\",\"ps\":\"BTCUSDT\",\"b\":\"79716.80\",\"B\":\"2.695\",\"a\":\"79716.90\",\"A\":\"15.332\",\"T\":1788564446485,\"E\":1788564446485,\"st\":1}}"}
{"receive_ns":1788564446555440000,"stream":"btcusdt@bookTicker","event_type":"bookTicker","event_time_ms":1788564446486,"raw_json":"{\"stream\":\"btcusdt@bookTicker\",\"data\":{\"e\":\"bookTicker\",\"u\":11478295992790,\"s\":\"BTCUSDT\",\"ps\":\"BTCUSDT\",\"b\":\"79716.80\",\"B\":\"2.695\",\"a\":\"79716.90\",\"A\":\"15.313\",\"T\":1788564446486,\"E\":1788564446486,\"st\":1}}"}
{"receive_ns":1788564446562522000,"stream":"btcusdt@depth@100ms","event_type":"depthUpdate","event_time_ms":1788564446541,"raw_json":"{\"stream\":\"btcusdt@depth@100ms\",\"data\":{\"e\":\"depthUpdate\",\"E\":1788564446541,\"T\":1788564446537,\"s\":\"BTCUSDT\",\"ps\":\"BTCUSDT\",\"U\":11478295989605,\"u\":11478295996134,\"pu\":11478295989513,\"b\":[[\"1000.00\",\"24.754\"],[\"29316.80\",\"1.435\"],[\"29416.80\",\"0.665\"],[\"71745.10\",\"0.002\"],[\"78122.50\",\"0.030\"],[\"78461.00\",\"0.902\"],[\"78540.70\",\"5.429\"],[\"78760.20\",\"4.437\"],[\"78919.60\",\"1.265\"],[\"79318.20\",\"0.781\"],[\"79432.50\",\"1.096\"],[\"79434.30\",\"0.000\"],[\"79497.60\",\"0.733\"],[\"79529.50\",\"2.129\"],[\"79530.70\",\"1.004\"],[\"79594.30\",\"0.675\"],[\"79690.00\",\"0.478\"],[\"79690.20\",\"0.002\"],[\"79691.20\",\"0.113\"],[\"79694.00\",\"0.006\"],[\"79694.50\",\"0.372\"],[\"79695.70\",\"0.003\"]],\"a\":[[\"79716.90\",\"15.313\"],[\"79732.90\",\"0.631\"],[\"79733.60\",\"0.063\"],[\"79734.30\",\"0.003\"],[\"79739.90\",\"0.001\"],[\"79740.70\",\"1.347\"],[\"79792.60\",\"0.701\"],[\"79840.30\",\"0.370\"],[\"79886.30\",\"0.090\"],[\"80078.80\",\"0.764\"],[\"80087.60\",\"1.147\"],[\"80514.10\",\"0.000\"],[\"81312.40\",\"0.007\"]],\"st\":1}}"}
{"receive_ns":1788564446568217000,"stream":"btcusdt@bookTicker","event_type":"bookTicker","event_time_ms":1788564446541,"raw_json":"{\"stream\":\"btcusdt@bookTicker\",\"data\":{\"e\":\"bookTicker\",\"u\":11478295996328,\"s\":\"BTCUSDT\",\"ps\":\"BTCUSDT\",\"b\":\"79716.80\",\"B\":\"2.682\",\"a\":\"79716.90\",\"A\":\"15.313\",\"T\":1788564446541,\"E\":1788564446541,\"st\":1}}"}
{"receive_ns":1788564446568743000,"stream":"btcusdt@trade","event_type":"trade","event_time_ms":1788564446541,"raw_json":"{\"stream\":\"btcusdt@trade\",\"data\":{\"e\":\"trade\",\"E\":1788564446541,\"T\":1788564446541,\"s\":\"BTCUSDT\",\"t\":8054096453,\"p\":\"79716.80\",\"q\":\"0.013\",\"X\":\"MARKET\",\"m\":true,\"st\":1}}"}
{"receive_ns":1788564446573650000,"stream":"btcusdt@bookTicker","event_type":"bookTicker","event_time_ms":1788564446542,"raw_json":"{\"stream\":\"btcusdt@bookTicker\",\"data\":{\"e\":\"bookTicker\",\"u\":11478295996400,\"s\":\"BTCUSDT\",\"ps\":\"BTCUSDT\",\"b\":\"79716.80\",\"B\":\"2.682\",\"a\":\"79716.90\",\"A\":\"15.332\",\"T\":1788564446542,\"E\":1788564446542,\"st\":1}}"}
{"receive_ns":1788564446574274000,"stream":"btcusdt@bookTicker","event_type":"bookTicker","event_time_ms":1788564446542,"raw_json":"{\"stream\":\"btcusdt@bookTicker\",\"data\":{\"e\":\"bookTicker\",\"u\":11478295996484,\"s\":\"BTCUSDT\",\"ps\":\"BTCUSDT\",\"b\":\"79716.80\",\"B\":\"2.682\",\"a\":\"79716.90\",\"A\":\"15.334\",\"T\":1788564446542,\"E\":1788564446542,\"st\":1}}"}
{"receive_ns":1788564446581238000,"stream":"btcusdt@bookTicker","event_type":"bookTicker","event_time_ms":1788564446542,"raw_json":"{\"stream\":\"btcusdt@bookTicker\",\"data\":{\"e\":\"bookTicker\",\"u\":11478295996602,\"s\":\"BTCUSDT\",\"ps\":\"BTCUSDT\",\"b\":\"79716.80\",\"B\":\"2.682\",\"a\":\"79716.90\",\"A\":\"15.315\",\"T\":1788564446542,\"E\":1788564446542,\"st\":1}}"}
{"receive_ns":1788564446581827000,"stream":"btcusdt@bookTicker","event_type":"bookTicker","event_time_ms":1788564446543,"raw_json":"{\"stream\":\"btcusdt@bookTicker\",\"data\":{\"e\":\"bookTicker\",\"u\":11478295996612,\"s\":\"BTCUSDT\",\"ps\":\"BTCUSDT\",\"b\":\"79716.80\",\"B\":\"2.682\",\"a\":\"79716.90\",\"A\":\"15.313\",\"T\":1788564446543,\"E\":1788564446543,\"st\":1}}"}
{"receive_ns":1788564446618544000,"stream":"btcusdt@depth@100ms","event_type":"depthUpdate","event_time_ms":1788564446643,"raw_json":"{\"stream\":\"btcusdt@depth@100ms\",\"data\":{\"e\":\"depthUpdate\",\"E\":1788564446643,\"T\":1788564446641,\"s\":\"BTCUSDT\",\"ps\":\"BTCUSDT\",\"U\":11478295996328,\"u\":11478296002731,\"pu\":11478295996134,\"b\":[[\"29316.80\",\"1.617\"],[\"29416.80\",\"0.483\"],[\"63773.00\",\"0.000\"],[\"63774.00\",\"0.000\"],[\"71745.10\",\"0.002\"],[\"75732.20\",\"0.002\"],[\"76528.10\",\"0.002\"],[\"78123.70\",\"0.003\"],[\"78341.50\",\"1.783\"],[\"78919.60\",\"2.214\"],[\"79297.80\",\"2.517\"],[\"79318.20\",\"0.781\"],[\"79529.50\",\"2.129\"],[\"79642.20\",\"0.021\"],[\"79709.40\",\"0.172\"],[\"79710.50\",\"0.026\"],[\"79712.50\",\"0.000\"],[\"79712.70\",\"0.000\"],[\"79712.80\",\"0.000\"],[\"79716.80\",\"2.682\"]],\"a\":[[\"79716.90\",\"15.313\"],[\"79750.00\",\"3.598\"],[\"79792.60\",\"0.701\"],[\"80087.60\",\"1.147\"],[\"80514.10\",\"0.000\"]],\"st\":1}}"}
{"receive_ns":1788564446653305000,"stream":"btcusdt@bookTicker","event_type":"bookTicker","event_time_ms":1788564446677,"raw_json":"{\"stream\":\"btcusdt@bookTicker\",\"data\":{\"e\":\"bookTicker\",\"u\":11478296005626,\"s\":\"BTCUSDT\",\"ps\":\"BTCUSDT\",\"b\":\"79716.80\",\"B\":\"2.682\",\"a\":\"79716.90\",\"A\":\"15.312\",\"T\":1788564446677,\"E\":1788564446677,\"st\":1}}"}
{"receive_ns":1788564446660241000,"stream":"btcusdt@trade","event_type":"trade","event_time_ms":1788564446677,"raw_json":"{\"stream\":\"btcusdt@trade\",\"data\":{\"e\":\"trade\",\"E\":1788564446677,\"T\":1788564446677,\"s\":\"BTCUSDT\",\"t\":8054096454,\"p\":\"79716.90\",\"q\":\"0.001\",\"X\":\"MARKET\",\"m\":false,\"st\":1}}"}
{"receive_ns":1788564446660911000,"stream":"btcusdt@bookTicker","event_type":"bookTicker","event_time_ms":1788564446679,"raw_json":"{\"stream\":\"btcusdt@bookTicker\",\"data\":{\"e\":\"bookTicker\",\"u\":11478296005774,\"s\":\"BTCUSDT\",\"ps\":\"BTCUSDT\",\"b\":\"79716.80\",\"B\":\"2.682\",\"a\":\"79716.90\",\"A\":\"15.331\",\"T\":1788564446678,\"E\":1788564446679,\"st\":1}}"}
{"receive_ns":1788564446661541000,"stream":"btcusdt@bookTicker","event_type":"bookTicker","event_time_ms":1788564446679,"raw_json":"{\"stream\":\"btcusdt@bookTicker\",\"data\":{\"e\":\"bookTicker\",\"u\":11478296005793,\"s\":\"BTCUSDT\",\"ps\":\"BTCUSDT\",\"b\":\"79716.80\",\"B\":\"2.682\",\"a\":\"79716.90\",\"A\":\"15.333\",\"T\":1788564446678,\"E\":1788564446679,\"st\":1}}"}
{"receive_ns":1788564446662170000,"stream":"btcusdt@bookTicker","event_type":"bookTicker","event_time_ms":1788564446679,"raw_json":"{\"stream\":\"btcusdt@bookTicker\",\"data\":{\"e\":\"bookTicker\",\"u\":11478296005930,\"s\":\"BTCUSDT\",\"ps\":\"BTCUSDT\",\"b\":\"79716.80\",\"B\":\"2.682\",\"a\":\"79716.90\",\"A\":\"15.331\",\"T\":1788564446679,\"E\":1788564446679,\"st\":1}}"}
{"receive_ns":1788564446662765000,"stream":"btcusdt@bookTicker","event_type":"bookTicker","event_time_ms":1788564446680,"raw_json":"{\"stream\":\"btcusdt@bookTicker\",\"data\":{\"e\":\"bookTicker\",\"u\":11478296005939,\"s\":\"BTCUSDT\",\"ps\":\"BTCUSDT\",\"b\":\"79716.80\",\"B\":\"2.682\",\"a\":\"79716.90\",\"A\":\"15.312\",\"T\":1788564446679,\"E\":1788564446680,\"st\":1}}"}
{"receive_ns":1788564446663422000,"stream":"btcusdt@bookTicker","event_type":"bookTicker","event_time_ms":1788564446686,"raw_json":"{\"stream\":\"btcusdt@bookTicker\",\"data\":{\"e\":\"bookTicker\",\"u\":11478296006394,\"s\":\"BTCUSDT\",\"ps\":\"BTCUSDT\",\"b\":\"79716.80\",\"B\":\"2.682\",\"a\":\"79716.90\",\"A\":\"15.331\",\"T\":1788564446686,\"E\":1788564446686,\"st\":1}}"}
{"receive_ns":1788564446676590000,"stream":"btcusdt@bookTicker","event_type":"bookTicker","event_time_ms":1788564446687,"raw_json":"{\"stream\":\"btcusdt@bookTicker\",\"data\":{\"e\":\"bookTicker\",\"u\":11478296006453,\"s\":\"BTCUSDT\",\"ps\":\"BTCUSDT\",\"b\":\"79716.80\",\"B\":\"2.682\",\"a\":\"79716.90\",\"A\":\"15.312\",\"T\":1788564446687,\"E\":1788564446687,\"st\":1}}"}
{"receive_ns":1788564446706506000,"stream":"btcusdt@bookTicker","event_type":"bookTicker","event_time_ms":1788564446732,"raw_json":"{\"stream\":\"btcusdt@bookTicker\",\"data\":{\"e\":\"bookTicker\",\"u\":11478296009136,\"s\":\"BTCUSDT\",\"ps\":\"BTCUSDT\",\"b\":\"79716.80\",\"B\":\"2.682\",\"a\":\"79716.90\",\"A\":\"15.331\",\"T\":1788564446731,\"E\":1788564446732,\"st\":1}}"}
{"receive_ns":1788564446707155000,"stream":"btcusdt@bookTicker","event_type":"bookTicker","event_time_ms":1788564446732,"raw_json":"{\"stream\":\"btcusdt@bookTicker\",\"data\":{\"e\":\"bookTicker\",\"u\":11478296009230,\"s\":\"BTCUSDT\",\"ps\":\"BTCUSDT\",\"b\":\"79716.80\",\"B\":\"2.682\",\"a\":\"79716.90\",\"A\":\"15.333\",\"T\":1788564446732,\"E\":1788564446732,\"st\":1}}"}
{"receive_ns":1788564446707807000,"stream":"btcusdt@bookTicker","event_type":"bookTicker","event_time_ms":1788564446732,"raw_json":"{\"stream\":\"btcusdt@bookTicker\",\"data\":{\"e\":\"bookTicker\",\"u\":11478296009291,\"s\":\"BTCUSDT\",\"ps\":\"BTCUSDT\",\"b\":\"79716.80\",\"B\":\"2.682\",\"a\":\"79716.90\",\"A\":\"15.314\",\"T\":1788564446732,\"E\":1788564446732,\"st\":1}}"}
{"receive_ns":1788564446714315000,"stream":"btcusdt@bookTicker","event_type":"bookTicker","event_time_ms":1788564446733,"raw_json":"{\"stream\":\"btcusdt@bookTicker\",\"data\":{\"e\":\"bookTicker\",\"u\":11478296009319,\"s\":\"BTCUSDT\",\"ps\":\"BTCUSDT\",\"b\":\"79716.80\",\"B\":\"2.682\",\"a\":\"79716.90\",\"A\":\"15.312\",\"T\":1788564446732,\"E\":1788564446733,\"st\":1}}"}
{"receive_ns":1788564446721578000,"stream":"btcusdt@depth@100ms","event_type":"depthUpdate","event_time_ms":1788564446745,"raw_json":"{\"stream\":\"btcusdt@depth@100ms\",\"data\":{\"e\":\"depthUpdate\",\"E\":1788564446745,\"T\":1788564446741,\"s\":\"BTCUSDT\",\"ps\":\"BTCUSDT\",\"U\":11478296002860,\"u\":11478296009960,\"pu\":11478296002731,\"b\":[[\"1000.00\",\"24.754\"],[\"29216.80\",\"0.014\"],[\"29316.80\",\"1.764\"],[\"29416.80\",\"0.322\"],[\"71745.10\",\"0.002\"],[\"75947.40\",\"0.000\"],[\"75958.20\",\"0.206\"],[\"76528.10\",\"0.000\"],[\"77096.90\",\"0.005\"],[\"78739.90\",\"16.677\"],[\"78919.60\",\"2.214\"],[\"79497.60\",\"0.733\"],[\"79529.50\",\"2.129\"],[\"79530.70\",\"1.004\"],[\"79594.30\",\"0.001\"],[\"79700.80\",\"0.012\"],[\"79709.80\",\"0.099\"],[\"79710.00\",\"0.015\"],[\"79711.90\",\"0.027\"],[\"79712.10\",\"0.028\"],[\"79713.00\",\"0.027\"],[\"79713.20\",\"0.027\"],[\"79715.10\",\"0.002\"],[\"79715.90\",\"0.000\"]],\"a\":[[\"79716.90\",\"15.312\"],[\"79750.90\",\"0.002\"],[\"79790.30\",\"0.047\"],[\"79792.60\",\"0.701\"],[\"79840.30\",\"0.001\"],[\"79886.30\",\"0.090\"],[\"80078.80\",\"0.764\"],[\"80087.60\",\"1.147\"],[\"80514.10\",\"0.000\"],[\"80815.30\",\"1.988\"],[\"81064.10\",\"0.492\"]],\"st\":1}}"}
{"receive_ns":1788564446821194000,"stream":"btcusdt@bookTicker","event_type":"bookTicker","event_time_ms":1788564446840,"raw_json":"{\"stream\":\"btcusdt@bookTicker\",\"data\":{\"e\":\"bookTicker\",\"u\":11478296016919,\"s\":\"BTCUSDT\",\"ps\":\"BTCUSDT\",\"b\":\"79716.80\",\"B\":\"2.682\",\"a\":\"79716.90\",\"A\":\"15.331\",\"T\":1788564446840,\"E\":1788564446840,\"st\":1}}"}
{"receive_ns":1788564446827348000,"stream":"btcusdt@bookTicker","event_type":"bookTicker","event_time_ms":1788564446841,"raw_json":"{\"stream\":\"btcusdt@bookTicker\",\"data\":{\"e\":\"bookTicker\",\"u\":11478296016974,\"s\":\"BTCUSDT\",\"ps\":\"BTCUSDT\",\"b\":\"79716.80\",\"B\":\"2.682\",\"a\":\"79716.90\",\"A\":\"15.312\",\"T\":1788564446840,\"E\":1788564446841,\"st\":1}}"}
{"receive_ns":1788564446832612000,"stream":"btcusdt@bookTicker","event_type":"bookTicker","event_time_ms":1788564446841,"raw_json":"{\"stream\":\"btcusdt@bookTicker\",\"data\":{\"e\":\"bookTicker\",\"u\":11478296017014,\"s\":\"BTCUSDT\",\"ps\":\"BTCUSDT\",\"b\":\"79716.80\",\"B\":\"2.682\",\"a\":\"79716.90\",\"A\":\"15.311\",\"T\":1788564446841,\"E\":1788564446841,\"st\":1}}"}
{"receive_ns":1788564446833363000,"stream":"btcusdt@bookTicker","event_type":"bookTicker","event_time_ms":1788564446841,"raw_json":"{\"stream\":\"btcusdt@bookTicker\",\"data\":{\"e\":\"bookTicker\",\"u\":11478296017048,\"s\":\"BTCUSDT\",\"ps\":\"BTCUSDT\",\"b\":\"79716.80\",\"B\":\"2.682\",\"a\":\"79716.90\",\"A\":\"15.309\",\"T\":1788564446841,\"E\":1788564446841,\"st\":1}}"}
{"receive_ns":1788564446834289000,"stream":"btcusdt@depth@100ms","event_type":"depthUpdate","event_time_ms":1788564446847,"raw_json":"{\"stream\":\"btcusdt@depth@100ms\",\"data\":{\"e\":\"depthUpdate\",\"E\":1788564446847,\"T\":1788564446845,\"s\":\"BTCUSDT\",\"ps\":\"BTCUSDT\",\"U\":11478296010176,\"u\":11478296017370,\"pu\":11478296009960,\"b\":[[\"1000.00\",\"24.754\"],[\"29216.80\",\"0.077\"],[\"29316.80\",\"1.820\"],[\"29416.80\",\"0.203\"],[\"71745.10\",\"0.002\"],[\"76528.10\",\"0.002\"],[\"78122.50\",\"0.027\"],[\"78123.70\",\"0.000\"],[\"78361.60\",\"4.032\"],[\"78583.90\",\"2.287\"],[\"78592.80\",\"0.635\"],[\"78919.60\",\"2.214\"],[\"79318.20\",\"0.897\"],[\"79529.50\",\"1.879\"],[\"79564.80\",\"0.708\"],[\"79566.80\",\"1.884\"],[\"79594.30\",\"0.675\"],[\"79701.40\",\"0.186\"],[\"79710.10\",\"0.000\"],[\"79713.70\",\"0.000\"]],\"a\":[[\"79716.90\",\"15.309\"],[\"79739.60\",\"0.455\"],[\"79740.70\",\"0.896\"],[\"79792.60\",\"0.701\"],[\"79838.50\",\"0.002\"],[\"79838.80\",\"2.011\"],[\"79840.30\",\"0.370\"],[\"80087.60\",\"0.992\"],[\"80514.10\",\"0.000\"],[\"80811.60\",\"1.838\"]],\"st\":1}}"}
{"receive_ns":1788564446922682000,"stream":"btcusdt@depth@100ms","event_type":"depthUpdate","event_time_ms":1788564446949,"raw_json":"{\"stream\":\"btcusdt@depth@100ms\",\"data\":{\"e\":\"depthUpdate\",\"E\":1788564446949,\"T\":1788564446948,\"s\":\"BTCUSDT\",\"ps\":\"BTCUSDT\",\"U\":11478296017486,\"u\":11478296024434,\"pu\":11478296017370,\"b\":[[\"29216.80\",\"0.133\"],[\"29316.80\",\"1.883\"],[\"29416.80\",\"0.084\"],[\"63773.00\",\"0.000\"],[\"63774.00\",\"0.000\"],[\"71745.10\",\"0.002\"],[\"71782.00\",\"0.000\"],[\"78733.60\",\"15.841\"],[\"78784.70\",\"0.128\"],[\"78919.60\",\"2.214\"],[\"79497.60\",\"0.502\"],[\"79529.50\",\"0.951\"],[\"79530.70\",\"0.001\"]],\"a\":[[\"79719.90\",\"0.019\"],[\"79792.60\",\"0.451\"],[\"79886.30\",\"0.000\"],[\"80078.80\",\"0.002\"],[\"80087.60\",\"0.579\"],[\"80514.10\",\"0.000\"],[\"82924.00\",\"0.020\"]],\"st\":1}}"}
{"receive_ns":1788564447032695000,"stream":"btcusdt@depth@100ms","event_type":"depthUpdate","event_time_ms":1788564447051,"raw_json":"{\"stream\":\"btcusdt@depth@100ms\",\"data\":{\"e\":\"depthUpdate\",\"E\":1788564447051,\"T\":1788564447049,\"s\":\"BTCUSDT\",\"ps\":\"BTCUSDT\",\"U\":11478296024534,\"u\":11478296030041,\"pu\":11478296024434,\"b\":[[\"1000.00\",\"24.754\"],[\"29216.80\",\"0.231\"],[\"29316.80\",\"1.869\"],[\"29416.80\",\"0.000\"],[\"63773.00\",\"0.000\"],[\"71745.10\",\"0.002\"],[\"76528.10\",\"0.000\"],[\"78059.00\",\"0.006\"],[\"78457.20\",\"0.008\"],[\"78560.90\",\"2.046\"],[\"78632.60\",\"0.000\"],[\"78779.80\",\"2.283\"],[\"78855.60\",\"0.000\"],[\"78919.60\",\"2.214\"],[\"79318.20\",\"0.758\"],[\"79497.60\",\"0.733\"],[\"79500.80\",\"1.003\"],[\"79529.50\",\"1.428\"],[\"79572.10\",\"0.014\"],[\"79693.10\",\"0.630\"],[\"79702.50\",\"0.004\"]],\"a\":[[\"79733.00\",\"0.630\"],[\"79792.60\",\"0.342\"],[\"80078.80\",\"0.764\"],[\"80087.60\",\"0.729\"],[\"80115.50\",\"0.500\"],[\"80456.50\",\"0.001\"],[\"80514.10\",\"0.000\"],[\"80679.60\",\"0.001\"],[\"80848.90\",\"0.296\"],[\"80854.80\",\"0.000\"],[\"81253.10\",\"0.000\"]],\"st\":1}}"}
{"receive_ns":1788564447046431000,"stream":"btcusdt@bookTicker","event_type":"bookTicker","event_time_ms":1788564447066,"raw_json":"{\"stream\":\"btcusdt@bookTicker\",\"data\":{\"e\":\"bookTicker\",\"u\":11478296030900,\"s\":\"BTCUSDT\",\"ps\":\"BTCUSDT\",\"b\":\"79716.80\",\"B\":\"2.682\",\"a\":\"79716.90\",\"A\":\"15.328\",\"T\":1788564447065,\"E\":1788564447066,\"st\":1}}"}
{"receive_ns":1788564447052558000,"stream":"btcusdt@bookTicker","event_type":"bookTicker","event_time_ms":1788564447066,"raw_json":"{\"stream\":\"btcusdt@bookTicker\",\"data\":{\"e\":\"bookTicker\",\"u\":11478296030961,\"s\":\"BTCUSDT\",\"ps\":\"BTCUSDT\",\"b\":\"79716.80\",\"B\":\"2.682\",\"a\":\"79716.90\",\"A\":\"15.309\",\"T\":1788564447066,\"E\":1788564447066,\"st\":1}}"}
{"receive_ns":1788564447055660000,"stream":"btcusdt@bookTicker","event_type":"bookTicker","event_time_ms":1788564447083,"raw_json":"{\"stream\":\"btcusdt@bookTicker\",\"data\":{\"e\":\"bookTicker\",\"u\":11478296031853,\"s\":\"BTCUSDT\",\"ps\":\"BTCUSDT\",\"b\":\"79716.80\",\"B\":\"2.682\",\"a\":\"79716.90\",\"A\":\"15.305\",\"T\":1788564447083,\"E\":1788564447083,\"st\":1}}"}
{"receive_ns":1788564447062836000,"stream":"btcusdt@bookTicker","event_type":"bookTicker","event_time_ms":1788564447086,"raw_json":"{\"stream\":\"btcusdt@bookTicker\",\"data\":{\"e\":\"bookTicker\",\"u\":11478296032022,\"s\":\"BTCUSDT\",\"ps\":\"BTCUSDT\",\"b\":\"79716.80\",\"B\":\"2.682\",\"a\":\"79716.90\",\"A\":\"15.319\",\"T\":1788564447086,\"E\":1788564447086,\"st\":1}}"}
{"receive_ns":1788564447093012000,"stream":"btcusdt@bookTicker","event_type":"bookTicker","event_time_ms":1788564447110,"raw_json":"{\"stream\":\"btcusdt@bookTicker\",\"data\":{\"e\":\"bookTicker\",\"u\":11478296033644,\"s\":\"BTCUSDT\",\"ps\":\"BTCUSDT\",\"b\":\"79716.80\",\"B\":\"2.682\",\"a\":\"79716.90\",\"A\":\"15.307\",\"T\":1788564447109,\"E\":1788564447110,\"st\":1}}"}
{"receive_ns":1788564447093833000,"stream":"btcusdt@bookTicker","event_type":"bookTicker","event_time_ms":1788564447112,"raw_json":"{\"stream\":\"btcusdt@bookTicker\",\"data\":{\"e\":\"bookTicker\",\"u\":11478296033812,\"s\":\"BTCUSDT\",\"ps\":\"BTCUSDT\",\"b\":\"79716.80\",\"B\":\"2.682\",\"a\":\"79716.90\",\"A\":\"15.309\",\"T\":1788564447112,\"E\":1788564447112,\"st\":1}}"}
{"receive_ns":1788564447094633000,"stream":"btcusdt@bookTicker","event_type":"bookTicker","event_time_ms":1788564447124,"raw_json":"{\"stream\":\"btcusdt@bookTicker\",\"data\":{\"e\":\"bookTicker\",\"u\":11478296034621,\"s\":\"BTCUSDT\",\"ps\":\"BTCUSDT\",\"b\":\"79716.80\",\"B\":\"2.682\",\"a\":\"79716.90\",\"A\":\"15.328\",\"T\":1788564447124,\"E\":1788564447124,\"st\":1}}"}
{"receive_ns":1788564447095666000,"stream":"btcusdt@bookTicker","event_type":"bookTicker","event_time_ms":1788564447125,"raw_json":"{\"stream\":\"btcusdt@bookTicker\",\"data\":{\"e\":\"bookTicker\",\"u\":11478296034676,\"s\":\"BTCUSDT\",\"ps\":\"BTCUSDT\",\"b\":\"79716.80\",\"B\":\"2.682\",\"a\":\"79716.90\",\"A\":\"15.309\",\"T\":1788564447125,\"E\":1788564447125,\"st\":1}}"}
{"receive_ns":1788564447123254000,"stream":"btcusdt@bookTicker","event_type":"bookTicker","event_time_ms":1788564447142,"raw_json":"{\"stream\":\"btcusdt@bookTicker\",\"data\":{\"e\":\"bookTicker\",\"u\":11478296035619,\"s\":\"BTCUSDT\",\"ps\":\"BTCUSDT\",\"b\":\"79716.80\",\"B\":\"2.682\",\"a\":\"79716.90\",\"A\":\"15.311\",\"T\":1788564447142,\"E\":1788564447142,\"st\":1}}"}
{"receive_ns":1788564447124054000,"stream":"btcusdt@bookTicker","event_type":"bookTicker","event_time_ms":1788564447142,"raw_json":"{\"stream\":\"btcusdt@bookTicker\",\"data\":{\"e\":\"bookTicker\",\"u\":11478296035652,\"s\":\"BTCUSDT\",\"ps\":\"BTCUSDT\",\"b\":\"79716.80\",\"B\":\"2.682\",\"a\":\"79716.90\",\"A\":\"15.330\",\"T\":1788564447142,\"E\":1788564447142,\"st\":1}}"}
{"receive_ns":1788564447130535000,"stream":"btcusdt@bookTicker","event_type":"bookTicker","event_time_ms":1788564447143,"raw_json":"{\"stream\":\"btcusdt@bookTicker\",\"data\":{\"e\":\"bookTicker\",\"u\":11478296035708,\"s\":\"BTCUSDT\",\"ps\":\"BTCUSDT\",\"b\":\"79716.80\",\"B\":\"2.682\",\"a\":\"79716.90\",\"A\":\"15.328\",\"T\":1788564447142,\"E\":1788564447143,\"st\":1}}"}
{"receive_ns":1788564447134830000,"stream":"btcusdt@bookTicker","event_type":"bookTicker","event_time_ms":1788564447143,"raw_json":"{\"stream\":\"btcusdt@bookTicker\",\"data\":{\"e\":\"bookTicker\",\"u\":11478296035722,\"s\":\"BTCUSDT\",\"ps\":\"BTCUSDT\",\"b\":\"79716.80\",\"B\":\"2.682\",\"a\":\"79716.90\",\"A\":\"15.309\",\"T\":1788564447143,\"E\":1788564447143,\"st\":1}}"}
{"receive_ns":1788564447142583000,"stream":"btcusdt@depth@100ms","event_type":"depthUpdate","event_time_ms":1788564447153,"raw_json":"{\"stream\":\"btcusdt@depth@100ms\",\"data\":{\"e\":\"depthUpdate\",\"E\":1788564447153,\"T\":1788564447150,\"s\":\"BTCUSDT\",\"ps\":\"BTCUSDT\",\"U\":11478296030188,\"u\":11478296036121,\"pu\":11478296030041,\"b\":[[\"1000.00\",\"24.754\"],[\"29216.80\",\"0.406\"],[\"29316.80\",\"1.694\"],[\"63773.00\",\"0.000\"],[\"63773.40\",\"0.000\"],[\"63774.00\",\"0.000\"],[\"71745.10\",\"0.002\"],[\"76528.10\",\"0.002\"],[\"78122.50\",\"0.024\"],[\"78587.00\",\"0.138\"],[\"78919.60\",\"2.214\"],[\"79318.20\",\"0.898\"],[\"79529.50\",\"2.129\"],[\"79617.70\",\"0.009\"],[\"79649.80\",\"0.000\"],[\"79690.00\",\"0.027\"],[\"79691.10\",\"0.555\"],[\"79702.50\",\"0.000\"],[\"79709.40\",\"0.174\"],[\"79715.60\",\"0.315\"],[\"79715.80\",\"0.000\"],[\"79716.10\",\"0.003\"]],\"a\":[[\"79716.90\",\"15.309\"],[\"79732.90\",\"0.193\"],[\"79734.30\",\"0.441\"],[\"79739.60\",\"0.004\"],[\"79740.60\",\"0.461\"],[\"79792.60\",\"0.791\"],[\"80087.60\",\"1.147\"],[\"80514.10\",\"0.000\"],[\"80822.50\",\"0.006\"]],\"st\":1}}"}
{"receive_ns":1788564447149829000,"stream":"btcusdt@bookTicker","event_type":"bookTicker","event_time_ms":1788564447154,"raw_json":"{\"stream\":\"btcusdt@bookTicker\",\"data\":{\"e\":\"bookTicker\",\"u\":11478296036301,\"s\":\"BTCUSDT\",\"ps\":\"BTCUSDT\",\"b\":\"79716.80\",\"B\":\"2.682\",\"a\":\"79716.90\",\"A\":\"15.311\",\"T\":1788564447153,\"E\":1788564447154,\"st\":1}}"}
{"receive_ns":1788564447150704000,"stream":"btcusdt@bookTicker","event_type":"bookTicker","event_time_ms":1788564447154,"raw_json":"{\"stream\":\"btcusdt@bookTicker\",\"data\":{\"e\":\"bookTicker\",\"u\":11478296036303,\"s\":\"BTCUSDT\",\"ps\":\"BTCUSDT\",\"b\":\"79716.80\",\"B\":\"2.682\",\"a\":\"79716.90\",\"A\":\"15.330\",\"T\":1788564447153,\"E\":1788564447154,\"st\":1}}"}
{"receive_ns":1788564447157477000,"stream":"btcusdt@bookTicker","event_type":"bookTicker","event_time_ms":1788564447154,"raw_json":"{\"stream\":\"btcusdt@bookTicker\",\"data\":{\"e\":\"bookTicker\",\"u\":11478296036358,\"s\":\"BTCUSDT\",\"ps\":\"BTCUSDT\",\"b\":\"79716.80\",\"B\":\"2.682\",\"a\":\"79716.90\",\"A\":\"15.328\",\"T\":1788564447154,\"E\":1788564447154,\"st\":1}}"}
{"receive_ns":1788564447158349000,"stream":"btcusdt@bookTicker","event_type":"bookTicker","event_time_ms":1788564447154,"raw_json":"{\"stream\":\"btcusdt@bookTicker\",\"data\":{\"e\":\"bookTicker\",\"u\":11478296036363,\"s\":\"BTCUSDT\",\"ps\":\"BTCUSDT\",\"b\":\"79716.80\",\"B\":\"2.682\",\"a\":\"79716.90\",\"A\":\"15.309\",\"T\":1788564447154,\"E\":1788564447154,\"st\":1}}"}
{"receive_ns":1788564447236580000,"stream":"btcusdt@depth@100ms","event_type":"depthUpdate","event_time_ms":1788564447255,"raw_json":"{\"stream\":\"btcusdt@depth@100ms\",\"data\":{\"e\":\"depthUpdate\",\"E\":1788564447255,\"T\":1788564447254,\"s\":\"BTCUSDT\",\"ps\":\"BTCUSDT\",\"U\":11478296036252,\"u\":11478296042157,\"pu\":11478296036121,\"b\":[[\"29216.80\",\"0.588\"],[\"29316.80\",\"1.512\"],[\"71745.10\",\"0.002\"],[\"75720.20\",\"0.007\"],[\"75732.20\",\"0.000\"],[\"76528.10\",\"0.000\"],[\"77436.20\",\"0.000\"],[\"78105.90\",\"1.313\"],[\"78194.50\",\"0.028\"],[\"78283.00\",\"0.034\"],[\"78371.60\",\"0.043\"],[\"78460.10\",\"0.031\"],[\"78548.70\",\"0.028\"],[\"78637.20\",\"0.028\"],[\"78725.80\",\"0.028\"],[\"78760.20\",\"5.705\"],[\"78814.30\",\"0.030\"],[\"78902.90\",\"5.298\"],[\"78919.60\",\"2.214\"],[\"78926.80\",\"1.854\"],[\"79318.20\",\"0.899\"],[\"79497.60\",\"0.733\"],[\"79500.80\",\"0.000\"],[\"79529.50\",\"2.129\"],[\"79530.70\",\"1.004\"],[\"79558.50\",\"0.000\"],[\"79598.10\",\"0.444\"],[\"79604.70\",\"0.000\"],[\"79651.30\",\"4.683\"],[\"79689.90\",\"0.569\"],[\"79691.10\",\"0.104\"],[\"79712.00\",\"0.042\"],[\"79712.70\",\"0.000\"],[\"79713.00\",\"0.001\"],[\"79713.20\",\"0.001\"],[\"79713.40\",\"0.000\"]],\"a\":[[\"79716.90\",\"15.309\"],[\"79732.60\",\"0.439\"],[\"79734.30\",\"0.003\"],[\"79752.50\",\"0.002\"],[\"79792.60\",\"0.701\"],[\"79814.10\",\"0.017\"],[\"79886.30\",\"0.090\"],[\"80078.80\",\"0.764\"],[\"80087.60\",\"1.147\"],[\"80115.50\",\"0.499\"],[\"80496.90\",\"0.030\"],[\"80514.10\",\"0.000\"],[\"80585.50\",\"0.029\"],[\"80674.00\",\"1.266\"],[\"80762.60\",\"1.211\"],[\"80851.10\",\"0.028\"],[\"80939.70\",\"0.028\"],[\"81028.20\",\"0.048\"],[\"81116.80\",\"0.028\"]],\"st\":1}}"}
{"receive_ns":1788564447334980000,"stream":"btcusdt@depth@100ms","event_type":"depthUpdate","event_time_ms":1788564447357,"raw_json":"{\"stream\":\"btcusdt@depth@100ms\",\"data\":{\"e\":\"depthUpdate\",\"E\":1788564447357,\"T\":1788564447353,\"s\":\"BTCUSDT\",\"ps\":\"BTCUSDT\",\"U\":11478296042242,\"u\":11478296047335,\"pu\":11478296042157,\"b\":[[\"1000.00\",\"24.754\"],[\"29216.80\",\"0.763\"],[\"29316.80\",\"1.337\"],[\"71745.10\",\"0.002\"],[\"76528.10\",\"0.002\"],[\"78059.00\",\"0.000\"],[\"78457.20\",\"0.002\"],[\"78632.50\",\"0.040\"],[\"78823.40\",\"1.384\"],[\"78855.50\",\"0.003\"],[\"78919.60\",\"2.214\"],[\"79318.20\",\"0.899\"],[\"79529.50\",\"1.879\"],[\"79591.30\",\"0.206\"],[\"79594.30\",\"0.001\"],[\"79598.10\",\"0.339\"],[\"79711.20\",\"0.006\"]],\"a\":[[\"79792.60\",\"0.701\"],[\"79840.30\",\"0.001\"],[\"80087.60\",\"0.992\"],[\"80454.60\",\"0.000\"],[\"80652.80\",\"14.738\"],[\"80677.60\",\"0.000\"],[\"80852.80\",\"1.353\"],[\"81205.30\",\"0.031\"],[\"81251.40\",\"0.000\"],[\"81293.90\",\"0.030\"],[\"82853.60\",\"0.750\"]],\"st\":1}}"}
{"receive_ns":1788564447382713000,"stream":"btcusdt@bookTicker","event_type":"bookTicker","event_time_ms":1788564447395,"raw_json":"{\"stream\":\"btcusdt@bookTicker\",\"data\":{\"e\":\"bookTicker\",\"u\":11478296050409,\"s\":\"BTCUSDT\",\"ps\":\"BTCUSDT\",\"b\":\"79716.80\",\"B\":\"2.682\",\"a\":\"79716.90\",\"A\":\"15.308\",\"T\":1788564447395,\"E\":1788564447395,\"st\":1}}"}
{"receive_ns":1788564447389859000,"stream":"btcusdt@trade","event_type":"trade","event_time_ms":1788564447395,"raw_json":"{\"stream\":\"btcusdt@trade\",\"data\":{\"e\":\"trade\",\"E\":1788564447395,\"T\":1788564447395,\"s\":\"BTCUSDT\",\"t\":8054096455,\"p\":\"79716.90\",\"q\":\"0.001\",\"X\":\"MARKET\",\"m\":false,\"st\":1}}"}
{"receive_ns":1788564447396645000,"stream":"btcusdt@bookTicker","event_type":"bookTicker","event_time_ms":1788564447396,"raw_json":"{\"stream\":\"btcusdt@bookTicker\",\"data\":{\"e\":\"bookTicker\",\"u\":11478296050482,\"s\":\"BTCUSDT\",\"ps\":\"BTCUSDT\",\"b\":\"79716.80\",\"B\":\"2.682\",\"a\":\"79716.90\",\"A\":\"15.327\",\"T\":1788564447396,\"E\":1788564447396,\"st\":1}}"}
{"receive_ns":1788564447399567000,"stream":"btcusdt@bookTicker","event_type":"bookTicker","event_time_ms":1788564447396,"raw_json":"{\"stream\":\"btcusdt@bookTicker\",\"data\":{\"e\":\"bookTicker\",\"u\":11478296050555,\"s\":\"BTCUSDT\",\"ps\":\"BTCUSDT\",\"b\":\"79716.80\",\"B\":\"2.682\",\"a\":\"79716.90\",\"A\":\"15.329\",\"T\":1788564447396,\"E\":1788564447396,\"st\":1}}"}
{"receive_ns":1788564447406707000,"stream":"btcusdt@bookTicker","event_type":"bookTicker","event_time_ms":1788564447397,"raw_json":"{\"stream\":\"btcusdt@bookTicker\",\"data\":{\"e\":\"bookTicker\",\"u\":11478296050607,\"s\":\"BTCUSDT\",\"ps\":\"BTCUSDT\",\"b\":\"79716.80\",\"B\":\"2.682\",\"a\":\"79716.90\",\"A\":\"15.310\",\"T\":1788564447397,\"E\":1788564447397,\"st\":1}}"}
{"receive_ns":1788564447408620000,"stream":"btcusdt@bookTicker","event_type":"bookTicker","event_time_ms":1788564447397,"raw_json":"{\"stream\":\"btcusdt@bookTicker\",\"data\":{\"e\":\"bookTicker\",\"u\":11478296050617,\"s\":\"BTCUSDT\",\"ps\":\"BTCUSDT\",\"b\":\"79716.80\",\"B\":\"2.682\",\"a\":\"79716.90\",\"A\":\"15.308\",\"T\":1788564447397,\"E\":1788564447397,\"st\":1}}"}
{"receive_ns":1788564447440838000,"stream":"btcusdt@depth@100ms","event_type":"depthUpdate","event_time_ms":1788564447459,"raw_json":"{\"stream\":\"btcusdt@depth@100ms\",\"data\":{\"e\":\"depthUpdate\",\"E\":1788564447459,\"T\":1788564447458,\"s\":\"BTCUSDT\",\"ps\":\"BTCUSDT\",\"U\":11478296047631,\"u\":11478296053907,\"pu\":11478296047335,\"b\":[[\"1000.00\",\"24.754\"],[\"29216.80\",\"0.945\"],[\"29316.80\",\"1.155\"],[\"71745.10\",\"0.002\"],[\"78225.40\",\"0.638\"],[\"78919.60\",\"2.214\"],[\"78943.50\",\"0.696\"],[\"79118.90\",\"1.276\"],[\"79318.20\",\"0.899\"],[\"79497.60\",\"0.502\"],[\"79500.80\",\"1.003\"],[\"79501.60\",\"2.037\"],[\"79507.00\",\"0.000\"],[\"79507.80\",\"0.283\"],[\"79529.50\",\"0.951\"],[\"79530.70\",\"0.001\"],[\"79554.80\",\"0.089\"],[\"79555.30\",\"0.423\"],[\"79591.30\",\"0.000\"],[\"79636.40\",\"0.001\"],[\"79636.50\",\"0.050\"],[\"79699.10\",\"0.645\"],[\"79709.40\",\"0.172\"],[\"79712.30\",\"0.028\"]],\"a\":[[\"79716.90\",\"15.308\"],[\"79724.80\",\"0.676\"],[\"79725.30\",\"2.529\"],[\"79732.40\",\"0.079\"],[\"79764.00\",\"0.036\"],[\"79764.10\",\"0.051\"],[\"79792.60\",\"0.701\"],[\"79879.80\",\"0.125\"],[\"79886.30\",\"0.090\"],[\"79924.40\",\"2.130\"],[\"79927.60\",\"0.017\"],[\"80078.80\",\"0.764\"],[\"80087.60\",\"1.147\"],[\"80514.10\",\"0.000\"],[\"80673.50\",\"11.882\"],[\"80805.60\",\"20.218\"],[\"81311.20\",\"0.030\"]],\"st\":1}}"}
{"receive_ns":1788564447509951000,"stream":"btcusdt@bookTicker","event_type":"bookTicker","event_time_ms":1788564447531,"raw_json":"{\"stream\":\"btcusdt@bookTicker\",\"data\":{\"e\":\"bookTicker\",\"u\":11478296058746,\"s\":\"BTCUSDT\",\"ps\":\"BTCUSDT\",\"b\":\"79716.80\",\"B\":\"2.669\",\"a\":\"79716.90\",\"A\":\"15.308\",\"T\":1788564447530,\"E\":1788564447531,\"st\":1}}"}
{"receive_ns":1788564447516308000,"stream":"btcusdt@trade","event_type":"trade","event_time_ms":1788564447531,"raw_json":"{\"stream\":\"btcusdt@trade\",\"data\":{\"e\":\"trade\",\"E\":1788564447531,\"T\":1788564447530,\"s\":\"BTCUSDT\",\"t\":8054096456,\"p\":\"79716.80\",\"q\":\"0.013\",\"X\":\"MARKET\",\"m\":true,\"st\":1}}"}
{"receive_ns":1788564447519412000,"stream":"btcusdt@bookTicker","event_type":"bookTicker","event_time_ms":1788564447532,"raw_json":"{\"stream\":\"btcusdt@bookTicker\",\"data\":{\"e\":\"bookTicker\",\"u\":11478296058827,\"s\":\"BTCUSDT\",\"ps\":\"BTCUSDT\",\"b\":\"79716.80\",\"B\":\"2.669\",\"a\":\"79716.90\",\"A\":\"15.327\",\"T\":1788564447531,\"E\":1788564447532,\"st\":1}}"}
{"receive_ns":1788564447525762000,"stream":"btcusdt@bookTicker","event_type":"bookTicker","event_time_ms":1788564447532,"raw_json":"{\"stream\":\"btcusdt@bookTicker\",\"data\":{\"e\":\"bookTicker\",\"u\":11478296058857,\"s\":\"BTCUSDT\",\"ps\":\"BTCUSDT\",\"b\":\"79716.80\",\"B\":\"2.669\",\"a\":\"79716.90\",\"A\":\"15.329\",\"T\":1788564447532,\"E\":1788564447532,\"st\":1}}"}
{"receive_ns":1788564447533094000,"stream":"btcusdt@bookTicker","event_type":"bookTicker","event_time_ms":1788564447532,"raw_json":"{\"stream\":\"btcusdt@bookTicker\",\"data\":{\"e\":\"bookTicker\",\"u\":11478296059006,\"s\":\"BTCUSDT\",\"ps\":\"BTCUSDT\",\"b\":\"79716.80\",\"B\":\"2.669\",\"a\":\"79716.90\",\"A\":\"15.327\",\"T\":1788564447532,\"E\":1788564447532,\"st\":1}}"}
{"receive_ns":1788564447534203000,"stream":"btcusdt@bookTicker","event_type":"bookTicker","event_time_ms":1788564447532,"raw_json":"{\"stream\":\"btcusdt@bookTicker\",\"data\":{\"e\":\"bookTicker\",\"u\":11478296059019,\"s\":\"BTCUSDT\",\"ps\":\"BTCUSDT\",\"b\":\"79716.80\",\"B\":\"2.669\",\"a\":\"79716.90\",\"A\":\"15.308\",\"T\":1788564447532,\"E\":1788564447532,\"st\":1}}"}
{"receive_ns":1788564447541445000,"stream":"btcusdt@bookTicker","event_type":"bookTicker","event_time_ms":1788564447546,"raw_json":"{\"stream\":\"btcusdt@bookTicker\",\"data\":{\"e\":\"bookTicker\",\"u\":11478296059949,\"s\":\"BTCUSDT\",\"ps\":\"BTCUSDT\",\"b\":\"79716.80\",\"B\":\"2.669\",\"a\":\"79716.90\",\"A\":\"15.327\",\"T\":1788564447545,\"E\":1788564447546,\"st\":1}}"}
{"receive_ns":1788564447542929000,"stream":"btcusdt@bookTicker","event_type":"bookTicker","event_time_ms":1788564447546,"raw_json":"{\"stream\":\"btcusdt@bookTicker\",\"data\":{\"e\":\"bookTicker\",\"u\":11478296059986,\"s\":\"BTCUSDT\",\"ps\":\"BTCUSDT\",\"b\":\"79716.80\",\"B\":\"2.669\",\"a\":\"79716.90\",\"A\":\"15.329\",\"T\":1788564447546,\"E\":1788564447546,\"st\":1}}"}
{"receive_ns":1788564447550336000,"stream":"btcusdt@bookTicker","event_type":"bookTicker","event_time_ms":1788564447546,"raw_json":"{\"stream\":\"btcusdt@bookTicker\",\"data\":{\"e\":\"bookTicker\",\"u\":11478296060086,\"s\":\"BTCUSDT\",\"ps\":\"BTCUSDT\",\"b\":\"79716.80\",\"B\":\"2.669\",\"a\":\"79716.90\",\"A\":\"15.310\",\"T\":1788564447546,\"E\":1788564447546,\"st\":1}}"}
{"receive_ns":1788564447551357000,"stream":"btcusdt@bookTicker","event_type":"bookTicker","event_time_ms":1788564447547,"raw_json":"{\"stream\":\"btcusdt@bookTicker\",\"data\":{\"e\":\"bookTicker\",\"u\":11478296060090,\"s\":\"BTCUSDT\",\"ps\":\"BTCUSDT\",\"b\":\"79716.80\",\"B\":\"2.669\",\"a\":\"79716.90\",\"A\":\"15.308\",\"T\":1788564447546,\"E\":1788564447547,\"st\":1}}"}
{"receive_ns":1788564447564466000,"stream":"btcusdt@depth@100ms","event_type":"depthUpdate","event_time_ms":1788564447561,"raw_json":"{\"stream\":\"btcusdt@depth@100ms\",\"data\":{\"e\":\"depthUpdate\",\"E\":1788564447561,\"T\":1788564447560,\"s\":\"BTCUSDT\",\"ps\":\"BTCUSDT\",\"U\":11478296053959,\"u\":11478296060938,\"pu\":11478296053907,\"b\":[[\"29216.80\",\"1.120\"],[\"29316.80\",\"0.980\"],[\"71745.10\",\"0.002\"],[\"75731.00\",\"0.067\"],[\"76528.10\",\"0.000\"],[\"76981.90\",\"0.383\"],[\"78122.50\",\"0.021\"],[\"78919.60\",\"2.214\"],[\"79318.20\",\"0.899\"],[\"79507.00\",\"6.663\"],[\"79507.80\",\"1.206\"],[\"79529.50\",\"0.951\"],[\"79554.80\",\"2.743\"],[\"79555.30\",\"0.717\"],[\"79594.30\",\"0.693\"],[\"79604.30\",\"0.699\"],[\"79612.90\",\"0.000\"],[\"79621.10\",\"0.040\"],[\"79645.00\",\"0.002\"],[\"79659.30\",\"0.002\"],[\"79669.10\",\"0.013\"],[\"79688.10\",\"0.732\"],[\"79689.40\",\"0.003\"],[\"79691.80\",\"0.627\"],[\"79693.10\",\"0.003\"],[\"79699.70\",\"0.035\"],[\"79700.80\",\"0.005\"],[\"79701.40\",\"0.110\"],[\"79707.80\",\"0.003\"],[\"79708.10\",\"0.000\"],[\"79709.40\",\"0.174\"],[\"79709.70\",\"0.026\"],[\"79709.80\",\"0.125\"],[\"79710.00\",\"0.041\"],[\"79710.10\",\"0.026\"],[\"79710.20\",\"0.001\"],[\"79710.30\",\"0.001\"],[\"79710.50\",\"0.000\"],[\"79710.60\",\"0.000\"],[\"79711.70\",\"0.000\"],[\"79711.90\",\"0.001\"],[\"79712.00\",\"0.016\"],[\"79712.10\",\"0.002\"],[\"79712.30\",\"0.002\"],[\"79715.30\",\"0.316\"],[\"79715.50\",\"0.005\"],[\"79715.60\",\"0.000\"],[\"79716.10\",\"0.000\"],[\"79716.80\",\"2.669\"]],\"a\":[[\"79716.90\",\"15.308\"],[\"79717.90\",\"0.014\"],[\"79722.10\",\"0.000\"],[\"79725.20\",\"2.232\"],[\"79726.50\",\"0.090\"],[\"79756.80\",\"0.730\"],[\"79792.60\",\"0.701\"],[\"79840.30\",\"0.359\"],[\"79879.80\",\"2.579\"],[\"79924.40\",\"3.180\"],[\"79927.60\",\"7.588\"],[\"80087.60\",\"1.147\"],[\"80334.00\",\"5.343\"],[\"80514.10\",\"0.000\"],[\"80753.30\",\"0.494\"],[\"81311.20\",\"0.024\"],[\"83688.40\",\"0.008\"]],\"st\":1}}"}
{"receive_ns":1788564447617766000,"stream":"btcusdt@bookTicker","event_type":"bookTicker","event_time_ms":1788564447638,"raw_json":"{\"stream\":\"btcusdt@bookTicker\",\"data\":{\"e\":\"bookTicker\",\"u\":11478296066242,\"s\":\"BTCUSDT\",\"ps\":\"BTCUSDT\",\"b\":\"79716.80\",\"B\":\"2.669\",\"a\":\"79716.90\",\"A\":\"15.327\",\"T\":1788564447638,\"E\":1788564447638,\"st\":1}}"}
{"receive_ns":1788564447629590000,"stream":"btcusdt@bookTicker","event_type":"bookTicker","event_time_ms":1788564447639,"raw_json":"{\"stream\":\"btcusdt@bookTicker\",\"data\":{\"e\":\"bookTicker\",\"u\":11478296066298,\"s\":\"BTCUSDT\",\"ps\":\"BTCUSDT\",\"b\":\"79716.80\",\"B\":\"2.669\",\"a\":\"79716.90\",\"A\":\"15.308\",\"T\":1788564447638,\"E\":1788564447639,\"st\":1}}"}
{"receive_ns":1788564447642637000,"stream":"btcusdt@depth@100ms","event_type":"depthUpdate","event_time_ms":1788564447663,"raw_json":"{\"stream\":\"btcusdt@depth@100ms\",\"data\":{\"e\":\"depthUpdate\",\"E\":1788564447663,\"T\":1788564447662,\"s\":\"BTCUSDT\",\"ps\":\"BTCUSDT\",\"U\":11478296061006,\"u\":11478296067794,\"pu\":11478296060938,\"b\":[[\"1000.00\",\"24.754\"],[\"29216.80\",\"1.302\"],[\"29316.80\",\"0.798\"],[\"71745.10\",\"0.002\"],[\"75720.20\",\"0.005\"],[\"76528.10\",\"0.002\"],[\"78297.10\",\"0.000\"],[\"78760.20\",\"6.973\"],[\"78919.60\",\"2.214\"],[\"79500.80\",\"0.000\"],[\"79501.60\",\"0.628\"],[\"79529.50\",\"0.951\"],[\"79604.10\",\"0.251\"],[\"79681.80\",\"0.996\"],[\"79682.90\",\"0.000\"],[\"79693.40\",\"0.431\"],[\"79694.50\",\"0.000\"],[\"79695.10\",\"0.440\"],[\"79696.50\",\"0.361\"],[\"79709.30\",\"1.026\"],[\"79709.40\",\"0.200\"],[\"79709.50\",\"0.027\"],[\"79709.60\",\"0.028\"],[\"79710.50\",\"0.026\"],[\"79711.10\",\"0.051\"]],\"a\":[[\"79716.90\",\"15.308\"],[\"79717.90\",\"0.006\"],[\"79722.10\",\"0.008\"],[\"79733.40\",\"1.644\"],[\"79735.40\",\"0.000\"],[\"79764.00\",\"0.086\"],[\"79764.10\",\"0.001\"],[\"79792.60\",\"0.451\"],[\"79886.30\",\"0.000\"],[\"80078.80\",\"0.002\"],[\"80087.60\",\"0.579\"],[\"80094.90\",\"2.617\"],[\"80514.10\",\"0.000\"],[\"80686.70\",\"1.404\"],[\"80726.50\",\"4.208\"],[\"87688.60\",\"0.000\"]],\"st\":1}}"}
{"receive_ns":1788564447674394000,"stream":"btcusdt@bookTicker","event_type":"bookTicker","event_time_ms":1788564447686,"raw_json":"{\"stream\":\"btcusdt@bookTicker\",\"data\":{\"e\":\"bookTicker\",\"u\":11478296069100,\"s\":\"BTCUSDT\",\"ps\":\"BTCUSDT\",\"b\":\"79716.80\",\"B\":\"2.669\",\"a\":\"79716.90\",\"A\":\"15.300\",\"T\":1788564447686,\"E\":1788564447686,\"st\":1}}"}
{"receive_ns":1788564447680669000,"stream":"btcusdt@bookTicker","event_type":"bookTicker","event_time_ms":1788564447690,"raw_json":"{\"stream\":\"btcusdt@bookTicker\",\"data\":{\"e\":\"bookTicker\",\"u\":11478296069267,\"s\":\"BTCUSDT\",\"ps\":\"BTCUSDT\",\"b\":\"79716.80\",\"B\":\"2.669\",\"a\":\"79716.90\",\"A\":\"15.309\",\"T\":1788564447690,\"E\":1788564447690,\"st\":1}}"}
{"receive_ns":1788564447687794000,"stream":"btcusdt@bookTicker","event_type":"bookTicker","event_time_ms":1788564447710,"raw_json":"{\"stream\":\"btcusdt@bookTicker\",\"data\":{\"e\":\"bookTicker\",\"u\":11478296070114,\"s\":\"BTCUSDT\",\"ps\":\"BTCUSDT\",\"b\":\"79716.80\",\"B\":\"2.666\",\"a\":\"79716.90\",\"A\":\"15.309\",\"T\":1788564447709,\"E\":1788564447710,\"st\":1}}"}
{"receive_ns":1788564447694092000,"stream":"btcusdt@bookTicker","event_type":"bookTicker","event_time_ms":1788564447721,"raw_json":"{\"stream\":\"btcusdt@bookTicker\",\"data\":{\"e\":\"bookTicker\",\"u\":11478296070690,\"s\":\"BTCUSDT\",\"ps\":\"BTCUSDT\",\"b\":\"79716.80\",\"B\":\"2.666\",\"a\":\"79716.90\",\"A\":\"15.307\",\"T\":1788564447721,\"E\":1788564447721,\"st\":1}}"}
{"receive_ns":1788564447720128000,"stream":"btcusdt@bookTicker","event_type":"bookTicker","event_time_ms":1788564447726,"raw_json":"{\"stream\":\"btcusdt@bookTicker\",\"data\":{\"e\":\"bookTicker\",\"u\":11478296070953,\"s\":\"BTCUSDT\",\"ps\":\"BTCUSDT\",\"b\":\"79716.80\",\"B\":\"2.666\",\"a\":\"79716.90\",\"A\":\"15.310\",\"T\":1788564447726,\"E\":1788564447726,\"st\":1}}"}
{"receive_ns":1788564447744721000,"stream":"btcusdt@depth@100ms","event_type":"depthUpdate","event_time_ms":1788564447765,"raw_json":"{\"stream\":\"btcusdt@depth@100ms\",\"data\":{\"e\":\"depthUpdate\",\"E\":1788564447765,\"T\":1788564447763,\"s\":\"BTCUSDT\",\"ps\":\"BTCUSDT\",\"U\":11478296067866,\"u\":11478296072467,\"pu\":11478296067794,\"b\":[[\"1000.00\",\"24.754\"],[\"29216.80\",\"1.477\"],[\"29316.80\",\"0.623\"],[\"71745.10\",\"0.002\"],[\"75731.00\",\"0.069\"],[\"76528.10\",\"0.000\"],[\"77901.60\",\"0.385\"],[\"78580.60\",\"23.132\"],[\"78600.80\",\"1.930\"],[\"78919.60\",\"2.214\"],[\"79295.20\",\"0.001\"],[\"79318.20\",\"0.769\"],[\"79497.60\",\"0.733\"],[\"79529.50\",\"1.628\"],[\"79530.70\",\"1.004\"],[\"79695.10\",\"0.001\"],[\"79696.50\",\"0.800\"],[\"79711.10\",\"0.025\"],[\"79716.80\",\"2.666\"]],\"a\":[[\"79716.90\",\"15.310\"],[\"79717.90\",\"0.014\"],[\"79722.10\",\"0.000\"],[\"79733.40\",\"1.272\"],[\"79734.90\",\"0.372\"],[\"79754.10\",\"0.003\"],[\"79792.60\",\"0.451\"],[\"79886.30\",\"0.090\"],[\"80078.80\",\"0.764\"],[\"80087.60\",\"0.729\"],[\"80514.10\",\"0.000\"],[\"80673.50\",\"12.253\"]],\"st\":1}}"}
{"receive_ns":1788564447778244000,"stream":"btcusdt@bookTicker","event_type":"bookTicker","event_time_ms":1788564447797,"raw_json":"{\"stream\":\"btcusdt@bookTicker\",\"data\":{\"e\":\"bookTicker\",\"u\":11478296073901,\"s\":\"BTCUSDT\",\"ps\":\"BTCUSDT\",\"b\":\"79716.80\",\"B\":\"2.666\",\"a\":\"79716.90\",\"A\":\"15.311\",\"T\":1788564447797,\"E\":1788564447797,\"st\":1}}"}
{"receive_ns":1788564447849397000,"stream":"btcusdt@depth@100ms","event_type":"depthUpdate","event_time_ms":1788564447867,"raw_json":"{\"stream\":\"btcusdt@depth@100ms\",\"data\":{\"e\":\"depthUpdate\",\"E\":1788564447867,\"T\":1788564447865,\"s\":\"BTCUSDT\",\"ps\":\"BTCUSDT\",\"U\":11478296072550,\"u\":11478296076922,\"pu\":11478296072467,\"b\":[[\"29216.80\",\"1.659\"],[\"29316.80\",\"0.441\"],[\"71745.10\",\"0.002\"],[\"75730.90\",\"0.011\"],[\"78919.60\",\"2.214\"],[\"79318.20\",\"0.909\"],[\"79529.50\",\"1.378\"],[\"79653.00\",\"0.515\"],[\"79661.00\",\"0.259\"],[\"79689.90\",\"0.631\"],[\"79704.80\",\"0.004\"],[\"79711.20\",\"0.004\"]],\"a\":[[\"79716.90\",\"15.311\"],[\"79792.60\",\"0.701\"],[\"80087.60\",\"1.147\"],[\"80115.50\",\"0.624\"],[\"80514.10\",\"0.000\"],[\"80673.50\",\"12.747\"],[\"80793.10\",\"0.631\"],[\"80832.90\",\"8.154\"]],\"st\":1}}"}
{"receive_ns":1788564447915495000,"stream":"btcusdt@bookTicker","event_type":"bookTicker","event_time_ms":1788564447935,"raw_json":"{\"stream\":\"btcusdt@bookTicker\",\"data\":{\"e\":\"bookTicker\",\"u\":11478296080581,\"s\":\"BTCUSDT\",\"ps\":\"BTCUSDT\",\"b\":\"79716.80\",\"B\":\"2.666\",\"a\":\"79716.90\",\"A\":\"15.299\",\"T\":1788564447935,\"E\":1788564447935,\"st\":1}}"}
{"receive_ns":1788564447922585000,"stream":"btcusdt@trade","event_type":"trade","event_time_ms":1788564447935,"raw_json":"{\"stream\":\"btcusdt@trade\",\"data\":{\"e\":\"trade\",\"E\":1788564447935,\"T\":1788564447935,\"s\":\"BTCUSDT\",\"t\":8054096457,\"p\":\"79716.90\",\"q\":\"0.012\",\"X\":\"MARKET\",\"m\":false,\"st\":1}}"}
{"receive_ns":1788564447929240000,"stream":"btcusdt@bookTicker","event_type":"bookTicker","event_time_ms":1788564447936,"raw_json":"{\"stream\":\"btcusdt@bookTicker\",\"data\":{\"e\":\"bookTicker\",\"u\":11478296080667,\"s\":\"BTCUSDT\",\"ps\":\"BTCUSDT\",\"b\":\"79716.80\",\"B\":\"2.666\",\"a\":\"79716.90\",\"A\":\"15.318\",\"T\":1788564447936,\"E\":1788564447936,\"st\":1}}"}
{"receive_ns":1788564447930417000,"stream":"btcusdt@bookTicker","event_type":"bookTicker","event_time_ms":1788564447936,"raw_json":"{\"stream\":\"btcusdt@bookTicker\",\"data\":{\"e\":\"bookTicker\",\"u\":11478296080760,\"s\":\"BTCUSDT\",\"ps\":\"BTCUSDT\",\"b\":\"79716.80\",\"B\":\"2.666\",\"a\":\"79716.90\",\"A\":\"15.320\",\"T\":1788564447936,\"E\":1788564447936,\"st\":1}}"}
{"receive_ns":1788564447936916000,"stream":"btcusdt@bookTicker","event_type":"bookTicker","event_time_ms":1788564447937,"raw_json":"{\"stream\":\"btcusdt@bookTicker\",\"data\":{\"e\":\"bookTicker\",\"u\":11478296080786,\"s\":\"BTCUSDT\",\"ps\":\"BTCUSDT\",\"b\":\"79716.80\",\"B\":\"2.666\",\"a\":\"79716.90\",\"A\":\"15.301\",\"T\":1788564447937,\"E\":1788564447937,\"st\":1}}"}
{"receive_ns":1788564447945831000,"stream":"btcusdt@bookTicker","event_type":"bookTicker","event_time_ms":1788564447937,"raw_json":"{\"stream\":\"btcusdt@bookTicker\",\"data\":{\"e\":\"bookTicker\",\"u\":11478296080805,\"s\":\"BTCUSDT\",\"ps\":\"BTCUSDT\",\"b\":\"79716.80\",\"B\":\"2.666\",\"a\":\"79716.90\",\"A\":\"15.299\",\"T\":1788564447937,\"E\":1788564447937,\"st\":1}}"}
{"receive_ns":1788564447952897000,"stream":"btcusdt@depth@100ms","event_type":"depthUpdate","event_time_ms":1788564447969,"raw_json":"{\"stream\":\"btcusdt@depth@100ms\",\"data\":{\"e\":\"depthUpdate\",\"E\":1788564447969,\"T\":1788564447967,\"s\":\"BTCUSDT\",\"ps\":\"BTCUSDT\",\"U\":11478296077017,\"u\":11478296082280,\"pu\":11478296076922,\"b\":[[\"1000.00\",\"24.754\"],[\"29216.80\",\"1.778\"],[\"29316.80\",\"0.294\"],[\"29616.80\",\"0.028\"],[\"71745.10\",\"0.002\"],[\"75731.00\",\"0.067\"],[\"75731.10\",\"0.002\"],[\"76528.10\",\"0.002\"],[\"78042.70\",\"1.928\"],[\"78457.50\",\"0.171\"],[\"78568.10\",\"5.253\"],[\"78855.80\",\"0.196\"],[\"78919.60\",\"2.214\"],[\"79079.10\",\"1.011\"],[\"79497.60\",\"0.733\"],[\"79529.50\",\"1.303\"],[\"79530.70\",\"1.004\"],[\"79661.00\",\"0.334\"],[\"79699.60\",\"0.076\"],[\"79700.80\",\"0.012\"],[\"79709.10\",\"0.001\"],[\"79709.90\",\"0.104\"],[\"79710.30\",\"0.252\"],[\"79711.50\",\"0.030\"]],\"a\":[[\"79716.90\",\"15.299\"],[\"79731.40\",\"0.065\"],[\"79733.60\",\"0.001\"],[\"79792.60\",\"0.701\"],[\"79886.30\",\"0.090\"],[\"80078.80\",\"0.764\"],[\"80087.60\",\"1.147\"],[\"80453.50\",\"3.240\"],[\"80514.10\",\"0.000\"],[\"80676.50\",\"0.000\"],[\"80753.20\",\"0.494\"],[\"80805.60\",\"18.380\"],[\"80851.80\",\"0.000\"],[\"80872.80\",\"1.854\"],[\"81250.10\",\"0.000\"],[\"81311.20\",\"0.021\"]],\"st\":1}}"}
{"receive_ns":1788564447996568000,"stream":"btcusdt@bookTicker","event_type":"bookTicker","event_time_ms":1788564448015,"raw_json":"{\"stream\":\"btcusdt@bookTicker\",\"data\":{\"e\":\"bookTicker\",\"u\":11478296084460,\"s\":\"BTCUSDT\",\"ps\":\"BTCUSDT\",\"b\":\"79716.80\",\"B\":\"2.666\",\"a\":\"79716.90\",\"A\":\"15.300\",\"T\":1788564448015,\"E\":1788564448015,\"st\":1}}"}
{"receive_ns":1788564448048974000,"stream":"btcusdt@bookTicker","event_type":"bookTicker","event_time_ms":1788564448067,"raw_json":"{\"stream\":\"btcusdt@bookTicker\",\"data\":{\"e\":\"bookTicker\",\"u\":11478296087368,\"s\":\"BTCUSDT\",\"ps\":\"BTCUSDT\",\"b\":\"79716.80\",\"B\":\"2.666\",\"a\":\"79716.90\",\"A\":\"15.319\",\"T\":1788564448066,\"E\":1788564448067,\"st\":1}}"}
{"receive_ns":1788564448502762000,"stream":"btcusdt@bookTicker","event_type":"bookTicker","event_time_ms":1788564448067,"raw_json":"{\"stream\":\"btcusdt@bookTicker\",\"data\":{\"e\":\"bookTicker\",\"u\":11478296087430,\"s\":\"BTCUSDT\",\"ps\":\"BTCUSDT\",\"b\":\"79716.80\",\"B\":\"2.666\",\"a\":\"79716.90\",\"A\":\"15.300\",\"T\":1788564448067,\"E\":1788564448067,\"st\":1}}"}
{"receive_ns":1788564448509820000,"stream":"btcusdt@depth@100ms","event_type":"depthUpdate","event_time_ms":1788564448071,"raw_json":"{\"stream\":\"btcusdt@depth@100ms\",\"data\":{\"e\":\"depthUpdate\",\"E\":1788564448071,\"T\":1788564448070,\"s\":\"BTCUSDT\",\"ps\":\"BTCUSDT\",\"U\":11478296082360,\"u\":11478296087636,\"pu\":11478296082280,\"b\":[[\"1000.00\",\"24.754\"],[\"29216.80\",\"1.834\"],[\"29316.80\",\"0.175\"],[\"29616.80\",\"0.091\"],[\"71745.10\",\"0.002\"],[\"71782.00\",\"0.000\"],[\"76528.10\",\"0.000\"],[\"76866.90\",\"0.002\"],[\"78059.30\",\"0.000\"],[\"78488.30\",\"8.554\"],[\"78632.80\",\"0.001\"],[\"78799.60\",\"6.579\"],[\"78919.60\",\"2.214\"],[\"79318.20\",\"0.908\"],[\"79529.50\",\"1.303\"],[\"79653.00\",\"0.515\"],[\"79661.00\",\"0.084\"],[\"79693.10\",\"0.003\"],[\"79702.50\",\"0.000\"]],\"a\":[[\"79716.90\",\"15.300\"],[\"79733.00\",\"0.630\"],[\"79792.60\",\"0.701\"],[\"80087.60\",\"0.992\"],[\"80115.50\",\"0.625\"],[\"80514.10\",\"0.000\"],[\"81203.90\",\"1.922\"]],\"st\":1}}"}
{"receive_ns":1788564448523634000,"stream":"btcusdt@depth@100ms","event_type":"depthUpdate","event_time_ms":1788564448173,"raw_json":"{\"stream\":\"btcusdt@depth@100ms\",\"data\":{\"e\":\"depthUpdate\",\"E\":1788564448173,\"T\":1788564448172,\"s\":\"BTCUSDT\",\"ps\":\"BTCUSDT\",\"U\":11478296087754,\"u\":11478296092852,\"pu\":11478296087636,\"b\":[[\"29216.80\",\"1.897\"],[\"29316.80\",\"0.056\"],[\"29616.80\",\"0.147\"],[\"63773.40\",\"0.000\"],[\"71745.10\",\"0.002\"],[\"76528.10\",\"0.002\"],[\"78574.20\",\"15.374\"],[\"78919.60\",\"2.216\"],[\"79497.60\",\"0.502\"],[\"79529.50\",\"0.450\"],[\"79530.70\",\"1.004\"],[\"79641.80\",\"0.888\"],[\"79661.00\",\"0.009\"],[\"79709.30\",\"1.000\"],[\"79712.00\",\"0.042\"]],\"a\":[[\"79720.60\",\"0.108\"],[\"79792.60\",\"0.451\"],[\"79886.30\",\"0.000\"],[\"80078.80\",\"0.764\"],[\"80087.60\",\"0.579\"],[\"80514.10\",\"0.000\"],[\"81156.80\",\"0.614\"],[\"81351.10\",\"0.982\"],[\"84777.00\",\"0.314\"],[\"84955.00\",\"0.000\"]],\"st\":1}}"}
{"receive_ns":1788564448525185000,"stream":"btcusdt@bookTicker","event_type":"bookTicker","event_time_ms":1788564448193,"raw_json":"{\"stream\":\"btcusdt@bookTicker\",\"data\":{\"e\":\"bookTicker\",\"u\":11478296093906,\"s\":\"BTCUSDT\",\"ps\":\"BTCUSDT\",\"b\":\"79716.80\",\"B\":\"2.666\",\"a\":\"79716.90\",\"A\":\"15.291\",\"T\":1788564448193,\"E\":1788564448193,\"st\":1}}"}
{"receive_ns":1788564448547083000,"stream":"btcusdt@bookTicker","event_type":"bookTicker","event_time_ms":1788564448196,"raw_json":"{\"stream\":\"btcusdt@bookTicker\",\"data\":{\"e\":\"bookTicker\",\"u\":11478296094144,\"s\":\"BTCUSDT\",\"ps\":\"BTCUSDT\",\"b\":\"79716.80\",\"B\":\"2.666\",\"a\":\"79716.90\",\"A\":\"15.303\",\"T\":1788564448196,\"E\":1788564448196,\"st\":1}}"}
{"receive_ns":1788564448559348000,"stream":"btcusdt@bookTicker","event_type":"bookTicker","event_time_ms":1788564448219,"raw_json":"{\"stream\":\"btcusdt@bookTicker\",\"data\":{\"e\":\"bookTicker\",\"u\":11478296095589,\"s\":\"BTCUSDT\",\"ps\":\"BTCUSDT\",\"b\":\"79716.80\",\"B\":\"2.666\",\"a\":\"79716.90\",\"A\":\"15.322\",\"T\":1788564448218,\"E\":1788564448219,\"st\":1}}"}
{"receive_ns":1788564448571495000,"stream":"btcusdt@bookTicker","event_type":"bookTicker","event_time_ms":1788564448220,"raw_json":"{\"stream\":\"btcusdt@bookTicker\",\"data\":{\"e\":\"bookTicker\",\"u\":11478296095634,\"s\":\"BTCUSDT\",\"ps\":\"BTCUSDT\",\"b\":\"79716.80\",\"B\":\"2.666\",\"a\":\"79716.90\",\"A\":\"15.303\",\"T\":1788564448219,\"E\":1788564448220,\"st\":1}}"}
{"receive_ns":1788564448571758000,"stream":"btcusdt@bookTicker","event_type":"bookTicker","event_time_ms":1788564448230,"raw_json":"{\"stream\":\"btcusdt@bookTicker\",\"data\":{\"e\":\"bookTicker\",\"u\":11478296096075,\"s\":\"BTCUSDT\",\"ps\":\"BTCUSDT\",\"b\":\"79716.80\",\"B\":\"2.666\",\"a\":\"79716.90\",\"A\":\"15.300\",\"T\":1788564448230,\"E\":1788564448230,\"st\":1}}"}
{"receive_ns":1788564448572025000,"stream":"btcusdt@bookTicker","event_type":"bookTicker","event_time_ms":1788564448233,"raw_json":"{\"stream\":\"btcusdt@bookTicker\",\"data\":{\"e\":\"bookTicker\",\"u\":11478296096227,\"s\":\"BTCUSDT\",\"ps\":\"BTCUSDT\",\"b\":\"79716.80\",\"B\":\"2.666\",\"a\":\"79716.90\",\"A\":\"15.304\",\"T\":1788564448233,\"E\":1788564448233,\"st\":1}}"}
{"receive_ns":1788564448578276000,"stream":"btcusdt@depth@100ms","event_type":"depthUpdate","event_time_ms":1788564448275,"raw_json":"{\"stream\":\"btcusdt@depth@100ms\",\"data\":{\"e\":\"depthUpdate\",\"E\":1788564448275,\"T\":1788564448273,\"s\":\"BTCUSDT\",\"ps\":\"BTCUSDT\",\"U\":11478296092854,\"u\":11478296098135,\"pu\":11478296092852,\"b\":[[\"1000.00\",\"24.754\"],[\"29216.80\",\"1.827\"],[\"29316.80\",\"0.000\"],[\"29616.80\",\"0.273\"],[\"71745.10\",\"0.002\"],[\"76528.10\",\"0.000\"],[\"78545.00\",\"2.106\"],[\"78560.90\",\"2.936\"],[\"78799.30\",\"0.760\"],[\"78919.60\",\"2.214\"],[\"79318.20\",\"0.767\"],[\"79497.60\",\"0.733\"],[\"79503.90\",\"0.000\"],[\"79529.50\",\"1.353\"],[\"79543.70\",\"0.000\"],[\"79571.00\",\"0.014\"],[\"79632.50\",\"0.002\"],[\"79645.00\",\"0.004\"],[\"79653.00\",\"0.014\"],[\"79659.40\",\"0.049\"],[\"79675.00\",\"1.045\"],[\"79681.80\",\"0.950\"],[\"79682.90\",\"0.046\"],[\"79684.10\",\"0.008\"],[\"79689.90\",\"0.180\"],[\"79690.10\",\"0.920\"],[\"79691.20\",\"0.113\"],[\"79693.40\",\"0.059\"],[\"79694.50\",\"0.372\"],[\"79695.80\",\"0.007\"],[\"79698.90\",\"0.140\"]],\"a\":[[\"79716.90\",\"15.304\"],[\"79732.60\",\"0.001\"],[\"79732.90\",\"0.631\"],[\"79734.30\",\"0.003\"],[\"79734.40\",\"0.750\"],[\"79734.90\",\"0.000\"],[\"79735.70\",\"0.627\"],[\"79738.70\",\"0.045\"],[\"79767.10\",\"0.115\"],[\"79772.80\",\"0.316\"],[\"79792.60\",\"0.252\"],[\"79814.10\",\"0.016\"],[\"79814.20\",\"0.021\"],[\"79862.80\",\"0.000\"],[\"79886.30\",\"0.090\"],[\"80087.60\",\"0.729\"],[\"80514.10\",\"0.000\"],[\"81311.20\",\"0.024\"],[\"87688.60\",\"0.000\"]],\"st\":1}}"}
{"receive_ns":1788564448590258000,"stream":"btcusdt@bookTicker","event_type":"bookTicker","event_time_ms":1788564448317,"raw_json":"{\"stream\":\"btcusdt@bookTicker\",\"data\":{\"e\":\"bookTicker\",\"u\":11478296100011,\"s\":\"BTCUSDT\",\"ps\":\"BTCUSDT\",\"b\":\"79716.80\",\"B\":\"2.666\",\"a\":\"79716.90\",\"A\":\"15.290\",\"T\":1788564448316,\"E\":1788564448317,\"st\":1}}"}
{"receive_ns":1788564448607775000,"stream":"btcusdt@bookTicker","event_type":"bookTicker","event_time_ms":1788564448319,"raw_json":"{\"stream\":\"btcusdt@bookTicker\",\"data\":{\"e\":\"bookTicker\",\"u\":11478296100156,\"s\":\"BTCUSDT\",\"ps\":\"BTCUSDT\",\"b\":\"79716.80\",\"B\":\"2.666\",\"a\":\"79716.90\",\"A\":\"15.309\",\"T\":1788564448319,\"E\":1788564448319,\"st\":1}}"}
{"receive_ns":1788564448613591000,"stream":"btcusdt@bookTicker","event_type":"bookTicker","event_time_ms":1788564448359,"raw_json":"{\"stream\":\"btcusdt@bookTicker\",\"data\":{\"e\":\"bookTicker\",\"u\":11478296101865,\"s\":\"BTCUSDT\",\"ps\":\"BTCUSDT\",\"b\":\"79716.80\",\"B\":\"2.666\",\"a\":\"79716.90\",\"A\":\"15.307\",\"T\":1788564448359,\"E\":1788564448359,\"st\":1}}"}
{"receive_ns":1788564448628494000,"stream":"btcusdt@bookTicker","event_type":"bookTicker","event_time_ms":1788564448362,"raw_json":"{\"stream\":\"btcusdt@bookTicker\",\"data\":{\"e\":\"bookTicker\",\"u\":11478296102031,\"s\":\"BTCUSDT\",\"ps\":\"BTCUSDT\",\"b\":\"79716.80\",\"B\":\"2.683\",\"a\":\"79716.90\",\"A\":\"15.307\",\"T\":1788564448362,\"E\":1788564448362,\"st\":1}}"}
{"receive_ns":1788564448640633000,"stream":"btcusdt@depth@100ms","event_type":"depthUpdate","event_time_ms":1788564448377,"raw_json":"{\"stream\":\"btcusdt@depth@100ms\",\"data\":{\"e\":\"depthUpdate\",\"E\":1788564448377,\"T\":1788564448373,\"s\":\"BTCUSDT\",\"ps\":\"BTCUSDT\",\"U\":11478296098224,\"u\":11478296102556,\"pu\":11478296098135,\"b\":[[\"1000.00\",\"24.754\"],[\"29216.80\",\"1.652\"],[\"29616.80\",\"0.448\"],[\"63773.00\",\"0.000\"],[\"71745.10\",\"0.002\"],[\"75731.00\",\"0.065\"],[\"75731.10\",\"0.004\"],[\"78481.20\",\"0.892\"],[\"78739.90\",\"12.872\"],[\"78760.20\",\"8.241\"],[\"78919.60\",\"2.214\"],[\"79318.20\",\"0.907\"],[\"79529.50\",\"1.804\"],[\"79531.50\",\"0.256\"],[\"79698.90\",\"0.065\"],[\"79711.20\",\"0.006\"],[\"79716.80\",\"2.683\"]],\"a\":[[\"79716.90\",\"15.307\"],[\"79717.90\",\"0.006\"],[\"79722.10\",\"0.008\"],[\"79755.70\",\"0.256\"],[\"79792.60\",\"0.701\"],[\"80087.60\",\"1.147\"],[\"80115.50\",\"0.626\"],[\"80514.10\",\"0.000\"]],\"st\":1}}"}
{"receive_ns":1788564448652070000,"stream":"btcusdt@depth@100ms","event_type":"depthUpdate","event_time_ms":1788564448479,"raw_json":"{\"stream\":\"btcusdt@depth@100ms\",\"data\":{\"e\":\"depthUpdate\",\"E\":1788564448479,\"T\":1788564448478,\"s\":\"BTCUSDT\",\"ps\":\"BTCUSDT\",\"U\":11478296102783,\"u\":11478296107661,\"pu\":11478296102556,\"b\":[[\"29216.80\",\"1.470\"],[\"29616.80\",\"0.630\"],[\"71745.10\",\"0.002\"],[\"76528.10\",\"0.002\"],[\"78640.60\",\"0.636\"],[\"78760.20\",\"12.045\"],[\"78919.60\",\"2.214\"],[\"79497.60\",\"0.733\"],[\"79529.50\",\"1.704\"],[\"79530.70\",\"1.004\"],[\"79653.00\",\"0.114\"],[\"79698.90\",\"0.140\"],[\"79701.20\",\"0.076\"],[\"79709.40\",\"0.174\"],[\"79709.50\",\"0.001\"],[\"79709.60\",\"0.002\"],[\"79712.70\",\"0.026\"],[\"79713.30\",\"0.028\"],[\"79713.50\",\"0.028\"]],\"a\":[[\"79792.60\",\"0.701\"],[\"79886.30\",\"0.090\"],[\"80078.80\",\"0.764\"],[\"80087.60\",\"1.147\"],[\"80514.10\",\"0.000\"],[\"80805.60\",\"16.542\"],[\"80848.90\",\"0.444\"]],\"st\":1}}"}
{"receive_ns":1788564448657669000,"stream":"btcusdt@bookTicker","event_type":"bookTicker","event_time_ms":1788564448503,"raw_json":"{\"stream\":\"btcusdt@bookTicker\",\"data\":{\"e\":\"bookTicker\",\"u\":11478296108710,\"s\":\"BTCUSDT\",\"ps\":\"BTCUSDT\",\"b\":\"79716.80\",\"B\":\"2.683\",\"a\":\"79716.90\",\"A\":\"15.333\",\"T\":1788564448503,\"E\":1788564448503,\"st\":1}}"}
{"receive_ns":1788564448662855000,"stream":"btcusdt@bookTicker","event_type":"bookTicker","event_time_ms":1788564448508,"raw_json":"{\"stream\":\"btcusdt@bookTicker\",\"data\":{\"e\":\"bookTicker\",\"u\":11478296109002,\"s\":\"BTCUSDT\",\"ps\":\"BTCUSDT\",\"b\":\"79716.80\",\"B\":\"2.670\",\"a\":\"79716.90\",\"A\":\"15.333\",\"T\":1788564448508,\"E\":1788564448508,\"st\":1}}"}
{"receive_ns":1788564448674835000,"stream":"btcusdt@trade","event_type":"trade","event_time_ms":1788564448508,"raw_json":"{\"stream\":\"btcusdt@trade\",\"data\":{\"e\":\"trade\",\"E\":1788564448508,\"T\":1788564448508,\"s\":\"BTCUSDT\",\"t\":8054096458,\"p\":\"79716.80\",\"q\":\"0.013\",\"X\":\"MARKET\",\"m\":true,\"st\":1}}"}
{"receive_ns":1788564448686114000,"stream":"btcusdt@bookTicker","event_type":"bookTicker","event_time_ms":1788564448509,"raw_json":"{\"stream\":\"btcusdt@bookTicker\",\"data\":{\"e\":\"bookTicker\",\"u\":11478296109108,\"s\":\"BTCUSDT\",\"ps\":\"BTCUSDT\",\"b\":\"79716.80\",\"B\":\"2.670\",\"a\":\"79716.90\",\"A\":\"15.352\",\"T\":1788564448509,\"E\":1788564448509,\"st\":1}}"}
{"receive_ns":1788564448698340000,"stream":"btcusdt@bookTicker","event_type":"bookTicker","event_time_ms":1788564448509,"raw_json":"{\"stream\":\"btcusdt@bookTicker\",\"data\":{\"e\":\"bookTicker\",\"u\":11478296109180,\"s\":\"BTCUSDT\",\"ps\":\"BTCUSDT\",\"b\":\"79716.80\",\"B\":\"2.670\",\"a\":\"79716.90\",\"A\":\"15.354\",\"T\":1788564448509,\"E\":1788564448509,\"st\":1}}"}
{"receive_ns":1788564448706815000,"stream":"btcusdt@bookTicker","event_type":"bookTicker","event_time_ms":1788564448510,"raw_json":"{\"stream\":\"btcusdt@bookTicker\",\"data\":{\"e\":\"bookTicker\",\"u\":11478296109277,\"s\":\"BTCUSDT\",\"ps\":\"BTCUSDT\",\"b\":\"79716.80\",\"B\":\"2.670\",\"a\":\"79716.90\",\"A\":\"15.335\",\"T\":1788564448510,\"E\":1788564448510,\"st\":1}}"}
{"receive_ns":1788564448713432000,"stream":"btcusdt@bookTicker","event_type":"bookTicker","event_time_ms":1788564448510,"raw_json":"{\"stream\":\"btcusdt@bookTicker\",\"data\":{\"e\":\"bookTicker\",\"u\":11478296109298,\"s\":\"BTCUSDT\",\"ps\":\"BTCUSDT\",\"b\":\"79716.80\",\"B\":\"2.670\",\"a\":\"79716.90\",\"A\":\"15.333\",\"T\":1788564448510,\"E\":1788564448510,\"st\":1}}"}
{"receive_ns":1788564448731514000,"stream":"btcusdt@bookTicker","event_type":"bookTicker","event_time_ms":1788564448541,"raw_json":"{\"stream\":\"btcusdt@bookTicker\",\"data\":{\"e\":\"bookTicker\",\"u\":11478296110873,\"s\":\"BTCUSDT\",\"ps\":\"BTCUSDT\",\"b\":\"79716.80\",\"B\":\"2.670\",\"a\":\"79716.90\",\"A\":\"15.352\",\"T\":1788564448540,\"E\":1788564448541,\"st\":1}}"}
{"receive_ns":1788564448745999000,"stream":"btcusdt@bookTicker","event_type":"bookTicker","event_time_ms":1788564448541,"raw_json":"{\"stream\":\"btcusdt@bookTicker\",\"data\":{\"e\":\"bookTicker\",\"u\":11478296110910,\"s\":\"BTCUSDT\",\"ps\":\"BTCUSDT\",\"b\":\"79716.80\",\"B\":\"2.670\",\"a\":\"79716.90\",\"A\":\"15.333\",\"T\":1788564448541,\"E\":1788564448541,\"st\":1}}"}
{"receive_ns":1788564448746435000,"stream":"btcusdt@depth@100ms","event_type":"depthUpdate","event_time_ms":1788564448581,"raw_json":"{\"stream\":\"btcusdt@depth@100ms\",\"data\":{\"e\":\"depthUpdate\",\"E\":1788564448581,\"T\":1788564448580,\"s\":\"BTCUSDT\",\"ps\":\"BTCUSDT\",\"U\":11478296107713,\"u\":11478296112684,\"pu\":11478296107661,\"b\":[[\"1000.00\",\"24.754\"],[\"29216.80\",\"1.295\"],[\"29616.80\",\"0.805\"],[\"71745.10\",\"0.002\"],[\"76528.10\",\"0.000\"],[\"76751.90\",\"0.002\"],[\"78919.60\",\"2.214\"],[\"79297.80\",\"2.014\"],[\"79298.00\",\"0.420\"],[\"79318.20\",\"0.907\"],[\"79529.50\",\"1.203\"],[\"79531.50\",\"0.006\"],[\"79653.00\",\"0.615\"],[\"79698.90\",\"0.065\"],[\"79701.20\",\"0.000\"],[\"79710.40\",\"0.031\"],[\"79711.40\",\"0.026\"],[\"79712.70\",\"0.000\"],[\"79713.30\",\"0.002\"],[\"79713.50\",\"0.002\"],[\"79716.80\",\"2.670\"]],\"a\":[[\"79716.90\",\"15.333\"],[\"79719.10\",\"1.420\"],[\"79792.60\",\"0.701\"],[\"80087.60\",\"0.992\"],[\"80094.90\",\"2.119\"],[\"80514.10\",\"0.002\"],[\"80832.90\",\"10.007\"],[\"80852.00\",\"5.482\"],[\"80931.70\",\"1.729\"]],\"st\":1}}"}
{"receive_ns":1788564448746687000,"stream":"btcusdt@bookTicker","event_type":"bookTicker","event_time_ms":1788564448649,"raw_json":"{\"stream\":\"btcusdt@bookTicker\",\"data\":{\"e\":\"bookTicker\",\"u\":11478296116188,\"s\":\"BTCUSDT\",\"ps\":\"BTCUSDT\",\"b\":\"79716.80\",\"B\":\"2.670\",\"a\":\"79716.90\",\"A\":\"15.332\",\"T\":1788564448649,\"E\":1788564448649,\"st\":1}}"}
{"receive_ns":1788564448752945000,"stream":"btcusdt@bookTicker","event_type":"bookTicker","event_time_ms":1788564448657,"raw_json":"{\"stream\":\"btcusdt@bookTicker\",\"data\":{\"e\":\"bookTicker\",\"u\":11478296116581,\"s\":\"BTCUSDT\",\"ps\":\"BTCUSDT\",\"b\":\"79716.80\",\"B\":\"2.670\",\"a\":\"79716.90\",\"A\":\"15.334\",\"T\":1788564448657,\"E\":1788564448657,\"st\":1}}"}
{"receive_ns":1788564448758692000,"stream":"btcusdt@bookTicker","event_type":"bookTicker","event_time_ms":1788564448671,"raw_json":"{\"stream\":\"btcusdt@bookTicker\",\"data\":{\"e\":\"bookTicker\",\"u\":11478296117398,\"s\":\"BTCUSDT\",\"ps\":\"BTCUSDT\",\"b\":\"79716.80\",\"B\":\"2.670\",\"a\":\"79716.90\",\"A\":\"15.353\",\"T\":1788564448671,\"E\":1788564448671,\"st\":1}}"}
{"receive_ns":1788564448764879000,"stream":"btcusdt@bookTicker","event_type":"bookTicker","event_time_ms":1788564448672,"raw_json":"{\"stream\":\"btcusdt@bookTicker\",\"data\":{\"e\":\"bookTicker\",\"u\":11478296117445,\"s\":\"BTCUSDT\",\"ps\":\"BTCUSDT\",\"b\":\"79716.80\",\"B\":\"2.670\",\"a\":\"79716.90\",\"A\":\"15.334\",\"T\":1788564448671,\"E\":1788564448672,\"st\":1}}"}
{"receive_ns":1788564448778651000,"stream":"btcusdt@depth@100ms","event_type":"depthUpdate","event_time_ms":1788564448683,"raw_json":"{\"stream\":\"btcusdt@depth@100ms\",\"data\":{\"e\":\"depthUpdate\",\"E\":1788564448683,\"T\":1788564448681,\"s\":\"BTCUSDT\",\"ps\":\"BTCUSDT\",\"U\":11478296112689,\"u\":11478296118158,\"pu\":11478296112684,\"b\":[[\"1000.00\",\"24.754\"],[\"29216.80\",\"1.113\"],[\"29616.80\",\"0.987\"],[\"63773.00\",\"0.000\"],[\"71745.10\",\"0.002\"],[\"76528.10\",\"0.002\"],[\"78600.80\",\"3.836\"],[\"78760.20\",\"13.313\"],[\"78919.60\",\"2.214\"],[\"79318.20\",\"0.907\"],[\"79497.60\",\"0.733\"],[\"79529.50\",\"1.553\"],[\"79530.70\",\"1.004\"],[\"79594.30\",\"0.595\"],[\"79653.00\",\"0.515\"],[\"79661.00\",\"0.084\"],[\"79710.30\",\"0.278\"],[\"79711.70\",\"0.026\"],[\"79712.00\",\"0.016\"]],\"a\":[[\"79716.90\",\"15.334\"],[\"79719.30\",\"0.020\"],[\"79792.60\",\"0.701\"],[\"79840.30\",\"0.234\"],[\"79886.30\",\"0.090\"],[\"79927.60\",\"7.709\"],[\"79938.60\",\"0.252\"],[\"79938.70\",\"8.491\"],[\"80078.80\",\"0.764\"],[\"80087.60\",\"1.147\"],[\"80115.50\",\"1.124\"],[\"80514.10\",\"0.000\"]],\"st\":1}}"}
{"receive_ns":1788564448784376000,"stream":"btcusdt@bookTicker","event_type":"bookTicker","event_time_ms":1788564448685,"raw_json":"{\"stream\":\"btcusdt@bookTicker\",\"data\":{\"e\":\"bookTicker\",\"u\":11478296118469,\"s\":\"BTCUSDT\",\"ps\":\"BTCUSDT\",\"b\":\"79716.80\",\"B\":\"2.670\",\"a\":\"79716.90\",\"A\":\"15.353\",\"T\":1788564448685,\"E\":1788564448685,\"st\":1}}"}
{"receive_ns":1788564448802173000,"stream":"btcusdt@bookTicker","event_type":"bookTicker","event_time_ms":1788564448686,"raw_json":"{\"stream\":\"btcusdt@bookTicker\",\"data\":{\"e\":\"bookTicker\",\"u\":11478296118527,\"s\":\"BTCUSDT\",\"ps\":\"BTCUSDT\",\"b\":\"79716.80\",\"B\":\"2.670\",\"a\":\"79716.90\",\"A\":\"15.334\",\"T\":1788564448686,\"E\":1788564448686,\"st\":1}}"}
{"receive_ns":1788564448808551000,"stream":"btcusdt@bookTicker","event_type":"bookTicker","event_time_ms":1788564448714,"raw_json":"{\"stream\":\"btcusdt@bookTicker\",\"data\":{\"e\":\"bookTicker\",\"u\":11478296120010,\"s\":\"BTCUSDT\",\"ps\":\"BTCUSDT\",\"b\":\"79716.80\",\"B\":\"2.670\",\"a\":\"79716.90\",\"A\":\"15.353\",\"T\":1788564448713,\"E\":1788564448714,\"st\":1}}"}
{"receive_ns":1788564448823325000,"stream":"btcusdt@bookTicker","event_type":"bookTicker","event_time_ms":1788564448714,"raw_json":"{\"stream\":\"btcusdt@bookTicker\",\"data\":{\"e\":\"bookTicker\",\"u\":11478296120048,\"s\":\"BTCUSDT\",\"ps\":\"BTCUSDT\",\"b\":\"79716.80\",\"B\":\"2.670\",\"a\":\"79716.90\",\"A\":\"15.334\",\"T\":1788564448714,\"E\":1788564448714,\"st\":1}}"}
{"receive_ns":1788564448828893000,"stream":"btcusdt@bookTicker","event_type":"bookTicker","event_time_ms":1788564448717,"raw_json":"{\"stream\":\"btcusdt@bookTicker\",\"data\":{\"e\":\"bookTicker\",\"u\":11478296120197,\"s\":\"BTCUSDT\",\"ps\":\"BTCUSDT\",\"b\":\"79716.80\",\"B\":\"2.670\",\"a\":\"79716.90\",\"A\":\"15.310\",\"T\":1788564448716,\"E\":1788564448717,\"st\":1}}"}
{"receive_ns":1788564448841566000,"stream":"btcusdt@trade","event_type":"trade","event_time_ms":1788564448717,"raw_json":"{\"stream\":\"btcusdt@trade\",\"data\":{\"e\":\"trade\",\"E\":1788564448717,\"T\":1788564448716,\"s\":\"BTCUSDT\",\"t\":8054096459,\"p\":\"79716.90\",\"q\":\"0.024\",\"X\":\"MARKET\",\"m\":false,\"st\":1}}"}
{"receive_ns":1788564448858447000,"stream":"btcusdt@bookTicker","event_type":"bookTicker","event_time_ms":1788564448718,"raw_json":"{\"stream\":\"btcusdt@bookTicker\",\"data\":{\"e\":\"bookTicker\",\"u\":11478296120276,\"s\":\"BTCUSDT\",\"ps\":\"BTCUSDT\",\"b\":\"79716.80\",\"B\":\"2.670\",\"a\":\"79716.90\",\"A\":\"15.329\",\"T\":1788564448718,\"E\":1788564448718,\"st\":1}}"}
{"receive_ns":1788564448859226000,"stream":"btcusdt@bookTicker","event_type":"bookTicker","event_time_ms":1788564448718,"raw_json":"{\"stream\":\"btcusdt@bookTicker\",\"data\":{\"e\":\"bookTicker\",\"u\":11478296120294,\"s\":\"BTCUSDT\",\"ps\":\"BTCUSDT\",\"b\":\"79716.80\",\"B\":\"2.670\",\"a\":\"79716.90\",\"A\":\"15.331\",\"T\":1788564448718,\"E\":1788564448718,\"st\":1}}"}
{"receive_ns":1788564448871423000,"stream":"btcusdt@bookTicker","event_type":"bookTicker","event_time_ms":1788564448719,"raw_json":"{\"stream\":\"btcusdt@bookTicker\",\"data\":{\"e\":\"bookTicker\",\"u\":11478296120368,\"s\":\"BTCUSDT\",\"ps\":\"BTCUSDT\",\"b\":\"79716.80\",\"B\":\"2.670\",\"a\":\"79716.90\",\"A\":\"15.312\",\"T\":1788564448719,\"E\":1788564448719,\"st\":1}}"}
{"receive_ns":1788564448877416000,"stream":"btcusdt@bookTicker","event_type":"bookTicker","event_time_ms":1788564448719,"raw_json":"{\"stream\":\"btcusdt@bookTicker\",\"data\":{\"e\":\"bookTicker\",\"u\":11478296120380,\"s\":\"BTCUSDT\",\"ps\":\"BTCUSDT\",\"b\":\"79716.80\",\"B\":\"2.670\",\"a\":\"79716.90\",\"A\":\"15.310\",\"T\":1788564448719,\"E\":1788564448719,\"st\":1}}"}
{"receive_ns":1788564448889793000,"stream":"btcusdt@depth@100ms","event_type":"depthUpdate","event_time_ms":1788564448785,"raw_json":"{\"stream\":\"btcusdt@depth@100ms\",\"data\":{\"e\":\"depthUpdate\",\"E\":1788564448785,\"T\":1788564448782,\"s\":\"BTCUSDT\",\"ps\":\"BTCUSDT\",\"U\":11478296118394,\"u\":11478296123676,\"pu\":11478296118158,\"b\":[[\"29216.80\",\"0.938\"],[\"29616.80\",\"1.162\"],[\"63773.00\",\"0.000\"],[\"71745.10\",\"0.002\"],[\"76528.10\",\"0.000\"],[\"78800.10\",\"0.761\"],[\"78919.60\",\"2.214\"],[\"79318.20\",\"1.271\"],[\"79529.50\",\"2.054\"],[\"79621.10\",\"0.038\"],[\"79645.00\",\"0.004\"],[\"79653.00\",\"0.014\"],[\"79689.10\",\"0.452\"],[\"79690.10\",\"0.469\"],[\"79691.80\",\"0.628\"],[\"79693.80\",\"0.373\"],[\"79694.50\",\"0.000\"],[\"79695.10\",\"0.001\"],[\"79696.50\",\"0.361\"],[\"79697.20\",\"0.955\"],[\"79700.90\",\"0.293\"],[\"79705.30\",\"0.343\"],[\"79708.80\",\"0.005\"],[\"79709.40\",\"0.172\"],[\"79709.70\",\"0.000\"],[\"79712.30\",\"0.028\"],[\"79713.30\",\"0.004\"],[\"79713.60\",\"0.002\"]],\"a\":[[\"79716.90\",\"15.310\"],[\"79717.90\",\"0.014\"],[\"79722.10\",\"0.000\"],[\"79725.20\",\"1.982\"],[\"79726.00\",\"1.545\"],[\"79731.40\",\"0.003\"],[\"79732.60\",\"0.063\"],[\"79733.70\",\"0.618\"],[\"79734.90\",\"0.372\"],[\"79735.70\",\"0.255\"],[\"79756.80\",\"0.730\"],[\"79772.80\",\"0.314\"],[\"79792.60\",\"0.451\"],[\"80087.60\",\"1.147\"],[\"80112.00\",\"0.254\"],[\"80514.10\",\"0.000\"],[\"80652.80\",\"13.500\"],[\"80812.10\",\"18.787\"],[\"81311.20\",\"0.027\"]],\"st\":1}}"}
{"receive_ns":1788564448899903000,"stream":"btcusdt@bookTicker","event_type":"bookTicker","event_time_ms":1788564448870,"raw_json":"{\"stream\":\"btcusdt@bookTicker\",\"data\":{\"e\":\"bookTicker\",\"u\":11478296127880,\"s\":\"BTCUSDT\",\"ps\":\"BTCUSDT\",\"b\":\"79716.80\",\"B\":\"2.670\",\"a\":\"79716.90\",\"A\":\"15.308\",\"T\":1788564448870,\"E\":1788564448870,\"st\":1}}"}
{"receive_ns":1788564448911771000,"stream":"btcusdt@bookTicker","event_type":"bookTicker","event_time_ms":1788564448877,"raw_json":"{\"stream\":\"btcusdt@bookTicker\",\"data\":{\"e\":\"bookTicker\",\"u\":11478296128220,\"s\":\"BTCUSDT\",\"ps\":\"BTCUSDT\",\"b\":\"79716.80\",\"B\":\"2.670\",\"a\":\"79716.90\",\"A\":\"15.309\",\"T\":1788564448877,\"E\":1788564448877,\"st\":1}}"}
{"receive_ns":1788564448918151000,"stream":"btcusdt@depth@100ms","event_type":"depthUpdate","event_time_ms":1788564448887,"raw_json":"{\"stream\":\"btcusdt@depth@100ms\",\"data\":{\"e\":\"depthUpdate\",\"E\":1788564448887,\"T\":1788564448885,\"s\":\"BTCUSDT\",\"ps\":\"BTCUSDT\",\"U\":11478296123923,\"u\":11478296128736,\"pu\":11478296123676,\"b\":[[\"1000.00\",\"24.754\"],[\"29216.80\",\"0.756\"],[\"29616.80\",\"1.344\"],[\"71745.10\",\"0.002\"],[\"78122.50\",\"0.024\"],[\"78521.00\",\"0.293\"],[\"78568.10\",\"4.872\"],[\"78696.40\",\"0.012\"],[\"78899.30\",\"6.013\"],[\"78919.60\",\"2.220\"],[\"79318.20\",\"1.411\"],[\"79497.60\",\"0.502\"],[\"79529.50\",\"0.701\"],[\"79530.70\",\"0.001\"],[\"79653.00\",\"0.264\"],[\"79661.00\",\"0.009\"],[\"79689.10\",\"0.001\"],[\"79690.40\",\"0.544\"],[\"79696.50\",\"0.800\"],[\"79697.20\",\"0.516\"],[\"79700.80\",\"0.008\"],[\"79701.00\",\"0.024\"]],\"a\":[[\"79716.90\",\"15.309\"],[\"79717.90\",\"0.014\"],[\"79722.10\",\"0.000\"],[\"79792.60\",\"0.451\"],[\"79886.30\",\"0.000\"],[\"80078.80\",\"0.002\"],[\"80087.60\",\"0.579\"],[\"80514.10\",\"0.006\"],[\"80575.50\",\"0.000\"],[\"80737.30\",\"0.006\"],[\"80832.90\",\"11.861\"],[\"80912.70\",\"1.396\"],[\"81311.20\",\"0.033\"]],\"st\":1}}"}
{"receive_ns":1788564448968398000,"stream":"btcusdt@depth@100ms","event_type":"depthUpdate","event_time_ms":1788564448989,"raw_json":"{\"stream\":\"btcusdt@depth@100ms\",\"data\":{\"e\":\"depthUpdate\",\"E\":1788564448989,\"T\":1788564448987,\"s\":\"BTCUSDT\",\"ps\":\"BTCUSDT\",\"U\":11478296129033,\"u\":11478296134688,\"pu\":11478296128736,\"b\":[[\"1000.00\",\"24.754\"],[\"29216.80\",\"0.581\"],[\"29616.80\",\"1.519\"],[\"63773.00\",\"0.000\"],[\"63774.00\",\"0.000\"],[\"71745.10\",\"0.002\"],[\"76528.10\",\"0.002\"],[\"78321.00\",\"2.625\"],[\"78919.60\",\"2.220\"],[\"78998.30\",\"0.126\"],[\"79497.60\",\"0.733\"],[\"79509.60\",\"0.251\"],[\"79510.50\",\"0.034\"],[\"79529.50\",\"1.303\"],[\"79530.70\",\"1.004\"],[\"79653.00\",\"0.339\"],[\"79704.00\",\"0.079\"]],\"a\":[[\"79792.60\",\"0.701\"],[\"79886.30\",\"0.090\"],[\"80078.80\",\"0.764\"],[\"80087.60\",\"0.729\"],[\"80514.10\",\"0.006\"],[\"80633.60\",\"0.747\"],[\"80766.70\",\"12.405\"],[\"80832.90\",\"13.715\"]],\"st\":1}}"}
{"receive_ns":1788564448974285000,"stream":"btcusdt@bookTicker","event_type":"bookTicker","event_time_ms":1788564448996,"raw_json":"{\"stream\":\"btcusdt@bookTicker\",\"data\":{\"e\":\"bookTicker\",\"u\":11478296135224,\"s\":\"BTCUSDT\",\"ps\":\"BTCUSDT\",\"b\":\"79716.80\",\"B\":\"2.670\",\"a\":\"79716.90\",\"A\":\"15.328\",\"T\":1788564448995,\"E\":1788564448996,\"st\":1}}"}
{"receive_ns":1788564448979092000,"stream":"btcusdt@bookTicker","event_type":"bookTicker","event_time_ms":1788564448997,"raw_json":"{\"stream\":\"btcusdt@bookTicker\",\"data\":{\"e\":\"bookTicker\",\"u\":11478296135293,\"s\":\"BTCUSDT\",\"ps\":\"BTCUSDT\",\"b\":\"79716.80\",\"B\":\"2.670\",\"a\":\"79716.90\",\"A\":\"15.309\",\"T\":1788564448996,\"E\":1788564448997,\"st\":1}}"}
{"receive_ns":1788564449027692000,"stream":"btcusdt@bookTicker","event_type":"bookTicker","event_time_ms":1788564449050,"raw_json":"{\"stream\":\"btcusdt@bookTicker\",\"data\":{\"e\":\"bookTicker\",\"u\":11478296137993,\"s\":\"BTCUSDT\",\"ps\":\"BTCUSDT\",\"b\":\"79716.80\",\"B\":\"2.670\",\"a\":\"79716.90\",\"A\":\"15.328\",\"T\":1788564449049,\"E\":1788564449050,\"st\":1}}"}
{"receive_ns":1788564449040096000,"stream":"btcusdt@bookTicker","event_type":"bookTicker","event_time_ms":1788564449050,"raw_json":"{\"stream\":\"btcusdt@bookTicker\",\"data\":{\"e\":\"bookTicker\",\"u\":11478296138024,\"s\":\"BTCUSDT\",\"ps\":\"BTCUSDT\",\"b\":\"79716.80\",\"B\":\"2.670\",\"a\":\"79716.90\",\"A\":\"15.309\",\"T\":1788564449050,\"E\":1788564449050,\"st\":1}}"}
{"receive_ns":1788564449058352000,"stream":"btcusdt@bookTicker","event_type":"bookTicker","event_time_ms":1788564449068,"raw_json":"{\"stream\":\"btcusdt@bookTicker\",\"data\":{\"e\":\"bookTicker\",\"u\":11478296138833,\"s\":\"BTCUSDT\",\"ps\":\"BTCUSDT\",\"b\":\"79716.80\",\"B\":\"2.670\",\"a\":\"79716.90\",\"A\":\"15.328\",\"T\":1788564449068,\"E\":1788564449068,\"st\":1}}"}
{"receive_ns":1788564449074244000,"stream":"btcusdt@bookTicker","event_type":"bookTicker","event_time_ms":1788564449068,"raw_json":"{\"stream\":\"btcusdt@bookTicker\",\"data\":{\"e\":\"bookTicker\",\"u\":11478296138895,\"s\":\"BTCUSDT\",\"ps\":\"BTCUSDT\",\"b\":\"79716.80\",\"B\":\"2.670\",\"a\":\"79716.90\",\"A\":\"15.309\",\"T\":1788564449068,\"E\":1788564449068,\"st\":1}}"}
{"receive_ns":1788564449092211000,"stream":"btcusdt@depth@100ms","event_type":"depthUpdate","event_time_ms":1788564449091,"raw_json":"{\"stream\":\"btcusdt@depth@100ms\",\"data\":{\"e\":\"depthUpdate\",\"E\":1788564449091,\"T\":1788564449090,\"s\":\"BTCUSDT\",\"ps\":\"BTCUSDT\",\"U\":11478296134762,\"u\":11478296140027,\"pu\":11478296134688,\"b\":[[\"29216.80\",\"0.399\"],[\"29616.80\",\"1.701\"],[\"71745.10\",\"0.002\"],[\"76528.10\",\"0.000\"],[\"76636.90\",\"0.002\"],[\"77484.70\",\"0.258\"],[\"78090.00\",\"1.007\"],[\"78122.50\",\"0.021\"],[\"78521.00\",\"0.299\"],[\"78696.40\",\"0.018\"],[\"78919.60\",\"2.226\"],[\"79318.20\",\"1.411\"],[\"79510.50\",\"0.002\"],[\"79510.60\",\"0.032\"],[\"79529.50\",\"1.804\"],[\"79531.50\",\"0.256\"],[\"79653.00\",\"0.089\"],[\"79689.40\",\"0.454\"],[\"79690.40\",\"0.093\"],[\"79693.10\",\"0.003\"],[\"79695.10\",\"0.001\"],[\"79696.50\",\"0.361\"],[\"79697.30\",\"0.539\"],[\"79702.50\",\"0.000\"]],\"a\":[[\"79716.90\",\"15.309\"],[\"79717.90\",\"0.006\"],[\"79719.90\",\"0.003\"],[\"79722.10\",\"0.008\"],[\"79733.00\",\"0.630\"],[\"79738.90\",\"0.055\"],[\"79740.10\",\"1.379\"],[\"79740.60\",\"0.010\"],[\"79792.60\",\"0.701\"],[\"80087.60\",\"1.147\"],[\"80115.50\",\"1.123\"],[\"80294.10\",\"2.712\"],[\"80514.10\",\"0.013\"],[\"80726.50\",\"3.713\"],[\"80737.30\",\"0.012\"],[\"80774.50\",\"0.000\"],[\"80825.00\",\"1.977\"],[\"80912.70\",\"1.402\"],[\"81311.20\",\"0.030\"]],\"st\":1}}"}
{"receive_ns":1788564449156085000,"stream":"btcusdt@bookTicker","event_type":"bookTicker","event_time_ms":1788564449173,"raw_json":"{\"stream\":\"btcusdt@bookTicker\",\"data\":{\"e\":\"bookTicker\",\"u\":11478296143910,\"s\":\"BTCUSDT\",\"ps\":\"BTCUSDT\",\"b\":\"79716.80\",\"B\":\"2.670\",\"a\":\"79716.90\",\"A\":\"15.308\",\"T\":1788564449173,\"E\":1788564449173,\"st\":1}}"}
{"receive_ns":1788564449167855000,"stream":"btcusdt@bookTicker","event_type":"bookTicker","event_time_ms":1788564449180,"raw_json":"{\"stream\":\"btcusdt@bookTicker\",\"data\":{\"e\":\"bookTicker\",\"u\":11478296144228,\"s\":\"BTCUSDT\",\"ps\":\"BTCUSDT\",\"b\":\"79716.80\",\"B\":\"2.670\",\"a\":\"79716.90\",\"A\":\"15.310\",\"T\":1788564449180,\"E\":1788564449180,\"st\":1}}"}
{"receive_ns":1788564449176210000,"stream":"btcusdt@depth@100ms","event_type":"depthUpdate","event_time_ms":1788564449193,"raw_json":"{\"stream\":\"btcusdt@depth@100ms\",\"data\":{\"e\":\"depthUpdate\",\"E\":1788564449193,\"T\":1788564449191,\"s\":\"BTCUSDT\",\"ps\":\"BTCUSDT\",\"U\":11478296140094,\"u\":11478296145127,\"pu\":11478296140027,\"b\":[[\"1000.00\",\"24.754\"],[\"29216.80\",\"0.266\"],[\"29516.80\",\"0.042\"],[\"29616.80\",\"1.792\"],[\"63773.40\",\"0.000\"],[\"63774.00\",\"0.000\"],[\"71745.10\",\"0.002\"],[\"71782.00\",\"0.000\"],[\"76528.10\",\"0.002\"],[\"78122.50\",\"0.027\"],[\"78281.90\",\"0.610\"],[\"78534.40\",\"2.715\"],[\"78919.60\",\"2.226\"],[\"79307.80\",\"0.000\"],[\"79318.20\",\"1.402\"],[\"79497.60\",\"0.733\"],[\"79510.60\",\"0.000\"],[\"79511.80\",\"0.547\"],[\"79529.50\",\"1.804\"],[\"79530.70\",\"1.004\"],[\"79621.10\",\"0.040\"],[\"79653.00\",\"0.089\"],[\"79696.50\",\"0.800\"],[\"79697.30\",\"0.100\"]],\"a\":[[\"79716.90\",\"15.310\"],[\"79772.80\",\"0.316\"],[\"79792.60\",\"0.701\"],[\"79814.00\",\"0.197\"],[\"79886.30\",\"0.090\"],[\"80078.80\",\"0.764\"],[\"80087.60\",\"1.147\"],[\"80514.10\",\"0.013\"],[\"81013.60\",\"3.081\"],[\"81311.20\",\"0.036\"],[\"82028.30\",\"0.000\"]],\"st\":1}}"}
{"receive_ns":1788564449182950000,"stream":"btcusdt@bookTicker","event_type":"bookTicker","event_time_ms":1788564449203,"raw_json":"{\"stream\":\"btcusdt@bookTicker\",\"data\":{\"e\":\"bookTicker\",\"u\":11478296146192,\"s\":\"BTCUSDT\",\"ps\":\"BTCUSDT\",\"b\":\"79716.80\",\"B\":\"2.670\",\"a\":\"79716.90\",\"A\":\"15.298\",\"T\":1788564449202,\"E\":1788564449203,\"st\":1}}"}
{"receive_ns":1788564449189228000,"stream":"btcusdt@bookTicker","event_type":"bookTicker","event_time_ms":1788564449205,"raw_json":"{\"stream\":\"btcusdt@bookTicker\",\"data\":{\"e\":\"bookTicker\",\"u\":11478296146408,\"s\":\"BTCUSDT\",\"ps\":\"BTCUSDT\",\"b\":\"79716.80\",\"B\":\"2.670\",\"a\":\"79716.90\",\"A\":\"15.308\",\"T\":1788564449205,\"E\":1788564449205,\"st\":1}}"}
{"receive_ns":1788564449276103000,"stream":"btcusdt@depth@100ms","event_type":"depthUpdate","event_time_ms":1788564449295,"raw_json":"{\"stream\":\"btcusdt@depth@100ms\",\"data\":{\"e\":\"depthUpdate\",\"E\":1788564449295,\"T\":1788564449293,\"s\":\"BTCUSDT\",\"ps\":\"BTCUSDT\",\"U\":11478296145311,\"u\":11478296152722,\"pu\":11478296145127,\"b\":[[\"1000.00\",\"24.754\"],[\"29216.80\",\"0.147\"],[\"29516.80\",\"0.105\"],[\"29616.80\",\"1.848\"],[\"71745.10\",\"0.002\"],[\"78353.60\",\"0.637\"],[\"78418.80\",\"0.292\"],[\"78919.60\",\"2.226\"],[\"79318.20\",\"1.402\"],[\"79529.50\",\"1.804\"],[\"79531.50\",\"0.006\"]],\"a\":[[\"79716.90\",\"15.308\"],[\"79792.60\",\"0.701\"],[\"80087.60\",\"0.992\"],[\"80115.50\",\"1.122\"],[\"80334.00\",\"5.095\"],[\"80354.60\",\"0.747\"],[\"80514.10\",\"0.013\"],[\"80652.80\",\"13.006\"]],\"st\":1}}"}
{"receive_ns":1788564449377259000,"stream":"btcusdt@bookTicker","event_type":"bookTicker","event_time_ms":1788564449394,"raw_json":"{\"stream\":\"btcusdt@bookTicker\",\"data\":{\"e\":\"bookTicker\",\"u\":11478296158430,\"s\":\"BTCUSDT\",\"ps\":\"BTCUSDT\",\"b\":\"79716.80\",\"B\":\"2.670\",\"a\":\"79716.90\",\"A\":\"15.306\",\"T\":1788564449394,\"E\":1788564449394,\"st\":1}}"}
{"receive_ns":1788564449389007000,"stream":"btcusdt@depth@100ms","event_type":"depthUpdate","event_time_ms":1788564449397,"raw_json":"{\"stream\":\"btcusdt@depth@100ms\",\"data\":{\"e\":\"depthUpdate\",\"E\":1788564449397,\"T\":1788564449396,\"s\":\"BTCUSDT\",\"ps\":\"BTCUSDT\",\"U\":11478296152840,\"u\":11478296158793,\"pu\":11478296152722,\"b\":[[\"29216.80\",\"0.028\"],[\"29516.80\",\"0.161\"],[\"29616.80\",\"1.911\"],[\"71745.10\",\"0.002\"],[\"76528.10\",\"0.000\"],[\"78488.30\",\"7.537\"],[\"78687.70\",\"0.628\"],[\"78919.60\",\"2.228\"],[\"79022.20\",\"0.000\"],[\"79318.20\",\"1.403\"],[\"79361.30\",\"0.000\"],[\"79497.60\",\"0.502\"],[\"79529.50\",\"0.701\"],[\"79530.70\",\"1.004\"],[\"79531.50\",\"0.256\"],[\"79531.60\",\"0.000\"],[\"79606.10\",\"0.000\"],[\"79653.00\",\"0.014\"],[\"79659.70\",\"0.001\"]],\"a\":[[\"79716.90\",\"15.306\"],[\"79772.00\",\"0.503\"],[\"79792.60\",\"0.451\"],[\"79808.10\",\"3.791\"],[\"79876.20\",\"0.000\"],[\"79886.30\",\"0.000\"],[\"80078.80\",\"0.764\"],[\"80087.60\",\"0.579\"],[\"80093.00\",\"1.030\"],[\"80124.60\",\"0.087\"],[\"80404.80\",\"0.000\"],[\"80514.10\",\"0.013\"],[\"80872.80\",\"2.348\"]],\"st\":1}}"}
{"receive_ns":1788564449389520000,"stream":"btcusdt@bookTicker","event_type":"bookTicker","event_time_ms":1788564449399,"raw_json":"{\"stream\":\"btcusdt@bookTicker\",\"data\":{\"e\":\"bookTicker\",\"u\":11478296159140,\"s\":\"BTCUSDT\",\"ps\":\"BTCUSDT\",\"b\":\"79716.80\",\"B\":\"2.670\",\"a\":\"79716.90\",\"A\":\"15.302\",\"T\":1788564449399,\"E\":1788564449399,\"st\":1}}"}
{"receive_ns":1788564449407754000,"stream":"btcusdt@bookTicker","event_type":"bookTicker","event_time_ms":1788564449402,"raw_json":"{\"stream\":\"btcusdt@bookTicker\",\"data\":{\"e\":\"bookTicker\",\"u\":11478296159390,\"s\":\"BTCUSDT\",\"ps\":\"BTCUSDT\",\"b\":\"79716.80\",\"B\":\"2.670\",\"a\":\"79716.90\",\"A\":\"15.307\",\"T\":1788564449402,\"E\":1788564449402,\"st\":1}}"}
{"receive_ns":1788564449421930000,"stream":"btcusdt@bookTicker","event_type":"bookTicker","event_time_ms":1788564449409,"raw_json":"{\"stream\":\"btcusdt@bookTicker\",\"data\":{\"e\":\"bookTicker\",\"u\":11478296159860,\"s\":\"BTCUSDT\",\"ps\":\"BTCUSDT\",\"b\":\"79716.80\",\"B\":\"2.670\",\"a\":\"79716.90\",\"A\":\"15.308\",\"T\":1788564449409,\"E\":1788564449409,\"st\":1}}"}
{"receive_ns":1788564449440261000,"stream":"btcusdt@bookTicker","event_type":"bookTicker","event_time_ms":1788564449459,"raw_json":"{\"stream\":\"btcusdt@bookTicker\",\"data\":{\"e\":\"bookTicker\",\"u\":11478296162389,\"s\":\"BTCUSDT\",\"ps\":\"BTCUSDT\",\"b\":\"79716.80\",\"B\":\"2.669\",\"a\":\"79716.90\",\"A\":\"15.308\",\"T\":1788564449458,\"E\":1788564449459,\"st\":1}}"}
{"receive_ns":1788564449472516000,"stream":"btcusdt@bookTicker","event_type":"bookTicker","event_time_ms":1788564449491,"raw_json":"{\"stream\":\"btcusdt@bookTicker\",\"data\":{\"e\":\"bookTicker\",\"u\":11478296164105,\"s\":\"BTCUSDT\",\"ps\":\"BTCUSDT\",\"b\":\"79716.80\",\"B\":\"2.656\",\"a\":\"79716.90\",\"A\":\"15.308\",\"T\":1788564449491,\"E\":1788564449491,\"st\":1}}"}
{"receive_ns":1788564449477982000,"stream":"btcusdt@trade","event_type":"trade","event_time_ms":1788564449491,"raw_json":"{\"stream\":\"btcusdt@trade\",\"data\":{\"e\":\"trade\",\"E\":1788564449491,\"T\":1788564449491,\"s\":\"BTCUSDT\",\"t\":8054096460,\"p\":\"79716.80\",\"q\":\"0.013\",\"X\":\"MARKET\",\"m\":true,\"st\":1}}"}
{"receive_ns":1788564449489851000,"stream":"btcusdt@bookTicker","event_type":"bookTicker","event_time_ms":1788564449492,"raw_json":"{\"stream\":\"btcusdt@bookTicker\",\"data\":{\"e\":\"bookTicker\",\"u\":11478296164296,\"s\":\"BTCUSDT\",\"ps\":\"BTCUSDT\",\"b\":\"79716.80\",\"B\":\"2.656\",\"a\":\"79716.90\",\"A\":\"15.310\",\"T\":1788564449492,\"E\":1788564449492,\"st\":1}}"}
{"receive_ns":1788564449496436000,"stream":"btcusdt@bookTicker","event_type":"bookTicker","event_time_ms":1788564449492,"raw_json":"{\"stream\":\"btcusdt@bookTicker\",\"data\":{\"e\":\"bookTicker\",\"u\":11478296164305,\"s\":\"BTCUSDT\",\"ps\":\"BTCUSDT\",\"b\":\"79716.80\",\"B\":\"2.656\",\"a\":\"79716.90\",\"A\":\"15.329\",\"T\":1788564449492,\"E\":1788564449492,\"st\":1}}"}
{"receive_ns":1788564449501339000,"stream":"btcusdt@bookTicker","event_type":"bookTicker","event_time_ms":1788564449493,"raw_json":"{\"stream\":\"btcusdt@bookTicker\",\"data\":{\"e\":\"bookTicker\",\"u\":11478296164395,\"s\":\"BTCUSDT\",\"ps\":\"BTCUSDT\",\"b\":\"79716.80\",\"B\":\"2.656\",\"a\":\"79716.90\",\"A\":\"15.327\",\"T\":1788564449493,\"E\":1788564449493,\"st\":1}}"}
{"receive_ns":1788564449507841000,"stream":"btcusdt@bookTicker","event_type":"bookTicker","event_time_ms":1788564449493,"raw_json":"{\"stream\":\"btcusdt@bookTicker\",\"data\":{\"e\":\"bookTicker\",\"u\":11478296164404,\"s\":\"BTCUSDT\",\"ps\":\"BTCUSDT\",\"b\":\"79716.80\",\"B\":\"2.656\",\"a\":\"79716.90\",\"A\":\"15.308\",\"T\":1788564449493,\"E\":1788564449493,\"st\":1}}"}
{"receive_ns":1788564449526553000,"stream":"btcusdt@depth@100ms","event_type":"depthUpdate","event_time_ms":1788564449499,"raw_json":"{\"stream\":\"btcusdt@depth@100ms\",\"data\":{\"e\":\"depthUpdate\",\"E\":1788564449499,\"T\":1788564449498,\"s\":\"BTCUSDT\",\"ps\":\"BTCUSDT\",\"U\":11478296158829,\"u\":11478296164691,\"pu\":11478296158793,\"b\":[[\"1000.00\",\"24.754\"],[\"29216.80\",\"0.000\"],[\"29516.80\",\"0.315\"],[\"29616.80\",\"1.785\"],[\"71745.10\",\"0.002\"],[\"76528.10\",\"0.002\"],[\"78560.90\",\"3.572\"],[\"78600.80\",\"5.742\"],[\"78919.60\",\"2.226\"],[\"79299.20\",\"0.101\"],[\"79318.20\",\"1.273\"],[\"79497.60\",\"0.733\"],[\"79529.50\",\"1.103\"],[\"79565.50\",\"1.891\"],[\"79566.80\",\"0.002\"],[\"79653.00\",\"0.089\"],[\"79670.60\",\"0.001\"],[\"79699.60\",\"0.000\"],[\"79700.90\",\"0.217\"],[\"79709.40\",\"0.174\"],[\"79709.70\",\"0.026\"],[\"79710.20\",\"0.027\"],[\"79711.20\",\"0.032\"],[\"79711.30\",\"0.026\"],[\"79711.40\",\"0.000\"],[\"79711.50\",\"0.004\"],[\"79711.70\",\"0.000\"],[\"79712.10\",\"0.002\"],[\"79712.30\",\"0.002\"],[\"79716.80\",\"2.656\"]],\"a\":[[\"79716.90\",\"15.308\"],[\"79792.60\",\"0.252\"],[\"79838.80\",\"0.129\"],[\"79838.90\",\"1.922\"],[\"79886.30\",\"0.090\"],[\"80087.60\",\"0.729\"],[\"80493.40\",\"6.514\"],[\"80514.10\",\"0.013\"],[\"80673.50\",\"13.241\"],[\"80806.10\",\"0.001\"],[\"80925.10\",\"4.288\"]],\"st\":1}}"}
{"receive_ns":1788564449583087000,"stream":"btcusdt@depth@100ms","event_type":"depthUpdate","event_time_ms":1788564449601,"raw_json":"{\"stream\":\"btcusdt@depth@100ms\",\"data\":{\"e\":\"depthUpdate\",\"E\":1788564449601,\"T\":1788564449597,\"s\":\"BTCUSDT\",\"ps\":\"BTCUSDT\",\"U\":11478296164803,\"u\":11478296170051,\"pu\":11478296164691,\"b\":[[\"1000.00\",\"24.754\"],[\"29516.80\",\"0.490\"],[\"29616.80\",\"1.610\"],[\"71745.10\",\"0.002\"],[\"75000.00\",\"191.641\"],[\"76528.10\",\"0.000\"],[\"78534.40\",\"1.770\"],[\"78545.00\",\"3.122\"],[\"78919.60\",\"2.226\"],[\"79318.20\",\"1.413\"],[\"79529.50\",\"1.303\"],[\"79531.50\",\"0.006\"],[\"79653.00\",\"0.590\"],[\"79698.90\",\"0.315\"],[\"79703.20\",\"0.002\"],[\"79709.70\",\"0.000\"],[\"79711.50\",\"0.030\"],[\"79711.70\",\"0.000\"],[\"79711.80\",\"0.027\"]],\"a\":[[\"79792.60\",\"0.701\"],[\"80087.60\",\"1.147\"],[\"80514.10\",\"0.013\"]],\"st\":1}}"}
{"receive_ns":1788564449585333000,"stream":"btcusdt@bookTicker","event_type":"bookTicker","event_time_ms":1788564449616,"raw_json":"{\"stream\":\"btcusdt@bookTicker\",\"data\":{\"e\":\"bookTicker\",\"u\":11478296171131,\"s\":\"BTCUSDT\",\"ps\":\"BTCUSDT\",\"b\":\"79716.80\",\"B\":\"2.656\",\"a\":\"79716.90\",\"A\":\"15.307\",\"T\":1788564449616,\"E\":1788564449616,\"st\":1}}"}
{"receive_ns":1788564449683613000,"stream":"btcusdt@depth@100ms","event_type":"depthUpdate","event_time_ms":1788564449703,"raw_json":"{\"stream\":\"btcusdt@depth@100ms\",\"data\":{\"e\":\"depthUpdate\",\"E\":1788564449703,\"T\":1788564449701,\"s\":\"BTCUSDT\",\"ps\":\"BTCUSDT\",\"U\":11478296170342,\"u\":11478296175448,\"pu\":11478296170051,\"b\":[[\"29516.80\",\"0.672\"],[\"29616.80\",\"1.428\"],[\"63773.00\",\"0.000\"],[\"71745.10\",\"0.004\"],[\"76521.90\",\"0.002\"],[\"76528.10\",\"0.002\"],[\"78919.60\",\"2.226\"],[\"79497.60\",\"0.733\"],[\"79529.50\",\"1.203\"],[\"79530.70\",\"1.004\"],[\"79579.70\",\"0.794\"],[\"79589.20\",\"10.242\"],[\"79597.20\",\"2.511\"],[\"79653.00\",\"0.515\"],[\"79668.20\",\"10.000\"],[\"79671.30\",\"2.625\"],[\"79698.90\",\"0.490\"],[\"79709.80\",\"0.099\"],[\"79712.00\",\"0.042\"]],\"a\":[[\"79716.90\",\"15.307\"],[\"79748.80\",\"1.024\"],[\"79788.70\",\"0.023\"],[\"79792.60\",\"0.701\"],[\"79886.30\",\"0.090\"],[\"80078.80\",\"0.764\"],[\"80087.60\",\"1.147\"],[\"80514.10\",\"0.013\"],[\"80679.70\",\"4.184\"],[\"80952.50\",\"0.740\"]],\"st\":1}}"}
{"receive_ns":1788564449713756000,"stream":"btcusdt@bookTicker","event_type":"bookTicker","event_time_ms":1788564449735,"raw_json":"{\"stream\":\"btcusdt@bookTicker\",\"data\":{\"e\":\"bookTicker\",\"u\":11478296177472,\"s\":\"BTCUSDT\",\"ps\":\"BTCUSDT\",\"b\":\"79716.80\",\"B\":\"2.656\",\"a\":\"79716.90\",\"A\":\"15.298\",\"T\":1788564449735,\"E\":1788564449735,\"st\":1}}"}
{"receive_ns":1788564449720358000,"stream":"btcusdt@trade","event_type":"trade","event_time_ms":1788564449735,"raw_json":"{\"stream\":\"btcusdt@trade\",\"data\":{\"e\":\"trade\",\"E\":1788564449735,\"T\":1788564449735,\"s\":\"BTCUSDT\",\"t\":8054096461,\"p\":\"79716.90\",\"q\":\"0.009\",\"X\":\"MARKET\",\"m\":false,\"st\":1}}"}
{"receive_ns":1788564449726501000,"stream":"btcusdt@bookTicker","event_type":"bookTicker","event_time_ms":1788564449736,"raw_json":"{\"stream\":\"btcusdt@bookTicker\",\"data\":{\"e\":\"bookTicker\",\"u\":11478296177574,\"s\":\"BTCUSDT\",\"ps\":\"BTCUSDT\",\"b\":\"79716.80\",\"B\":\"2.656\",\"a\":\"79716.90\",\"A\":\"15.317\",\"T\":1788564449736,\"E\":1788564449736,\"st\":1}}"}
{"receive_ns":1788564449732770000,"stream":"btcusdt@bookTicker","event_type":"bookTicker","event_time_ms":1788564449736,"raw_json":"{\"stream\":\"btcusdt@bookTicker\",\"data\":{\"e\":\"bookTicker\",\"u\":11478296177622,\"s\":\"BTCUSDT\",\"ps\":\"BTCUSDT\",\"b\":\"79716.80\",\"B\":\"2.656\",\"a\":\"79716.90\",\"A\":\"15.319\",\"T\":1788564449736,\"E\":1788564449736,\"st\":1}}"}
{"receive_ns":1788564449737068000,"stream":"btcusdt@bookTicker","event_type":"bookTicker","event_time_ms":1788564449737,"raw_json":"{\"stream\":\"btcusdt@bookTicker\",\"data\":{\"e\":\"bookTicker\",\"u\":11478296177693,\"s\":\"BTCUSDT\",\"ps\":\"BTCUSDT\",\"b\":\"79716.80\",\"B\":\"2.656\",\"a\":\"79716.90\",\"A\":\"15.300\",\"T\":1788564449737,\"E\":1788564449737,\"st\":1}}"}
{"receive_ns":1788564449737274000,"stream":"btcusdt@bookTicker","event_type":"bookTicker","event_time_ms":1788564449737,"raw_json":"{\"stream\":\"btcusdt@bookTicker\",\"data\":{\"e\":\"bookTicker\",\"u\":11478296177710,\"s\":\"BTCUSDT\",\"ps\":\"BTCUSDT\",\"b\":\"79716.80\",\"B\":\"2.656\",\"a\":\"79716.90\",\"A\":\"15.298\",\"T\":1788564449737,\"E\":1788564449737,\"st\":1}}"}
{"receive_ns":1788564449785819000,"stream":"btcusdt@depth@100ms","event_type":"depthUpdate","event_time_ms":1788564449805,"raw_json":"{\"stream\":\"btcusdt@depth@100ms\",\"data\":{\"e\":\"depthUpdate\",\"E\":1788564449805,\"T\":1788564449803,\"s\":\"BTCUSDT\",\"ps\":\"BTCUSDT\",\"U\":11478296175585,\"u\":11478296180496,\"pu\":11478296175448,\"b\":[[\"1000.00\",\"24.754\"],[\"29516.80\",\"0.847\"],[\"29616.80\",\"1.253\"],[\"71745.10\",\"0.002\"],[\"78122.50\",\"0.033\"],[\"78521.00\",\"0.305\"],[\"78600.80\",\"5.996\"],[\"78696.40\",\"0.024\"],[\"78919.60\",\"2.232\"],[\"79318.20\",\"1.403\"],[\"79511.80\",\"0.515\"],[\"79512.70\",\"0.032\"],[\"79529.50\",\"1.003\"],[\"79531.50\",\"0.206\"],[\"79533.50\",\"0.502\"],[\"79602.00\",\"0.001\"],[\"79653.00\",\"0.014\"],[\"79698.90\",\"0.140\"],[\"79700.50\",\"0.356\"],[\"79710.00\",\"0.015\"],[\"79713.20\",\"0.027\"]],\"a\":[[\"79716.90\",\"15.298\"],[\"79764.00\",\"0.036\"],[\"79764.10\",\"0.051\"],[\"79792.60\",\"0.701\"],[\"80087.60\",\"0.992\"],[\"80514.10\",\"0.019\"],[\"80644.60\",\"2.788\"],[\"80737.30\",\"0.018\"],[\"80832.90\",\"15.569\"],[\"80912.70\",\"1.408\"],[\"80952.50\",\"1.604\"],[\"81311.20\",\"0.039\"]],\"st\":1}}"}
{"receive_ns":1788564449890983000,"stream":"btcusdt@depth@100ms","event_type":"depthUpdate","event_time_ms":1788564449907,"raw_json":"{\"stream\":\"btcusdt@depth@100ms\",\"data\":{\"e\":\"depthUpdate\",\"E\":1788564449907,\"T\":1788564449906,\"s\":\"BTCUSDT\",\"ps\":\"BTCUSDT\",\"U\":11478296180642,\"u\":11478296185830,\"pu\":11478296180496,\"b\":[[\"1000.00\",\"24.754\"],[\"29516.80\",\"1.029\"],[\"29616.80\",\"1.071\"],[\"63774.00\",\"0.000\"],[\"71745.10\",\"0.002\"],[\"75731.00\",\"0.067\"],[\"76528.10\",\"0.000\"],[\"78321.00\",\"2.116\"],[\"78600.80\",\"7.902\"],[\"78919.60\",\"2.232\"],[\"79497.60\",\"0.502\"],[\"79501.60\",\"0.859\"],[\"79529.50\",\"1.003\"],[\"79530.70\",\"1.004\"],[\"79594.30\",\"0.675\"],[\"79698.90\",\"0.415\"],[\"79700.90\",\"0.292\"],[\"79712.40\",\"0.026\"],[\"79713.20\",\"0.001\"]],\"a\":[[\"79792.60\",\"0.701\"],[\"79840.30\",\"0.351\"],[\"79886.30\",\"0.090\"],[\"80078.80\",\"0.764\"],[\"80087.60\",\"1.147\"],[\"80514.10\",\"0.019\"],[\"80830.40\",\"5.925\"],[\"81207.60\",\"0.617\"],[\"81311.20\",\"0.030\"],[\"87688.60\",\"0.001\"]],\"st\":1}}"}
{"receive_ns":1788564449896804000,"stream":"btcusdt@bookTicker","event_type":"bookTicker","event_time_ms":1788564449920,"raw_json":"{\"stream\":\"btcusdt@bookTicker\",\"data\":{\"e\":\"bookTicker\",\"u\":11478296186651,\"s\":\"BTCUSDT\",\"ps\":\"BTCUSDT\",\"b\":\"79716.80\",\"B\":\"2.690\",\"a\":\"79716.90\",\"A\":\"15.298\",\"T\":1788564449920,\"E\":1788564449920,\"st\":1}}"}
{"receive_ns":1788564449902788000,"stream":"btcusdt@bookTicker","event_type":"bookTicker","event_time_ms":1788564449921,"raw_json":"{\"stream\":\"btcusdt@bookTicker\",\"data\":{\"e\":\"bookTicker\",\"u\":11478296186742,\"s\":\"BTCUSDT\",\"ps\":\"BTCUSDT\",\"b\":\"79716.80\",\"B\":\"2.688\",\"a\":\"79716.90\",\"A\":\"15.298\",\"T\":1788564449921,\"E\":1788564449921,\"st\":1}}"}
{"receive_ns":1788564449989452000,"stream":"btcusdt@depth@100ms","event_type":"depthUpdate","event_time_ms":1788564450009,"raw_json":"{\"stream\":\"btcusdt@depth@100ms\",\"data\":{\"e\":\"depthUpdate\",\"E\":1788564450009,\"T\":1788564450006,\"s\":\"BTCUSDT\",\"ps\":\"BTCUSDT\",\"U\":11478296185885,\"u\":11478296192351,\"pu\":11478296185830,\"b\":[[\"29516.80\",\"1.204\"],[\"29616.80\",\"0.896\"],[\"63774.00\",\"0.000\"],[\"71745.10\",\"0.002\"],[\"76528.10\",\"0.002\"],[\"78854.30\",\"0.000\"],[\"78919.60\",\"2.232\"],[\"79297.80\",\"0.126\"],[\"79318.20\",\"1.263\"],[\"79531.50\",\"0.206\"],[\"79533.50\",\"0.001\"],[\"79574.10\",\"0.014\"],[\"79594.30\",\"0.001\"],[\"79698.90\",\"0.816\"],[\"79716.80\",\"2.688\"]],\"a\":[[\"79792.60\",\"0.451\"],[\"79840.30\",\"0.001\"],[\"80087.60\",\"1.147\"],[\"80514.10\",\"0.018\"],[\"87688.60\",\"0.000\"]],\"st\":1}}"}
{"receive_ns":1788564450037963000,"stream":"btcusdt@bookTicker","event_type":"bookTicker","event_time_ms":1788564450063,"raw_json":"{\"stream\":\"btcusdt@bookTicker\",\"data\":{\"e\":\"bookTicker\",\"u\":11478296195689,\"s\":\"BTCUSDT\",\"ps\":\"BTCUSDT\",\"b\":\"79716.80\",\"B\":\"2.687\",\"a\":\"79716.90\",\"A\":\"15.298\",\"T\":1788564450062,\"E\":1788564450063,\"st\":1}}"}
{"receive_ns":1788564450052828000,"stream":"btcusdt@trade","event_type":"trade","event_time_ms":1788564450063,"raw_json":"{\"stream\":\"btcusdt@trade\",\"data\":{\"e\":\"trade\",\"E\":1788564450063,\"T\":1788564450062,\"s\":\"BTCUSDT\",\"t\":8054096462,\"p\":\"79716.80\",\"q\":\"0.001\",\"X\":\"MARKET\",\"m\":true,\"st\":1}}"}
{"receive_ns":1788564450069506000,"stream":"btcusdt@bookTicker","event_type":"bookTicker","event_time_ms":1788564450064,"raw_json":"{\"stream\":\"btcusdt@bookTicker\",\"data\":{\"e\":\"bookTicker\",\"u\":11478296195777,\"s\":\"BTCUSDT\",\"ps\":\"BTCUSDT\",\"b\":\"79716.80\",\"B\":\"2.687\",\"a\":\"79716.90\",\"A\":\"15.317\",\"T\":1788564450063,\"E\":1788564450064,\"st\":1}}"}
{"receive_ns":1788564450080797000,"stream":"btcusdt@bookTicker","event_type":"bookTicker","event_time_ms":1788564450064,"raw_json":"{\"stream\":\"btcusdt@bookTicker\",\"data\":{\"e\":\"bookTicker\",\"u\":11478296195780,\"s\":\"BTCUSDT\",\"ps\":\"BTCUSDT\",\"b\":\"79716.80\",\"B\":\"2.687\",\"a\":\"79716.90\",\"A\":\"15.319\",\"T\":1788564450063,\"E\":1788564450064,\"st\":1}}"}
{"receive_ns":1788564450097465000,"stream":"btcusdt@bookTicker","event_type":"bookTicker","event_time_ms":1788564450064,"raw_json":"{\"stream\":\"btcusdt@bookTicker\",\"data\":{\"e\":\"bookTicker\",\"u\":11478296195958,\"s\":\"BTCUSDT\",\"ps\":\"BTCUSDT\",\"b\":\"79716.80\",\"B\":\"2.687\",\"a\":\"79716.90\",\"A\":\"15.317\",\"T\":1788564450064,\"E\":1788564450064,\"st\":1}}"}
{"receive_ns":1788564450103279000,"stream":"btcusdt@bookTicker","event_type":"bookTicker","event_time_ms":1788564450064,"raw_json":"{\"stream\":\"btcusdt@bookTicker\",\"data\":{\"e\":\"bookTicker\",\"u\":11478296195960,\"s\":\"BTCUSDT\",\"ps\":\"BTCUSDT\",\"b\":\"79716.80\",\"B\":\"2.687\",\"a\":\"79716.90\",\"A\":\"15.298\",\"T\":1788564450064,\"E\":1788564450064,\"st\":1}}"}
{"receive_ns":1788564450105576000,"stream":"btcusdt@bookTicker","event_type":"bookTicker","event_time_ms":1788564450065,"raw_json":"{\"stream\":\"btcusdt@bookTicker\",\"data\":{\"e\":\"bookTicker\",\"u\":11478296196002,\"s\":\"BTCUSDT\",\"ps\":\"BTCUSDT\",\"b\":\"79716.80\",\"B\":\"2.687\",\"a\":\"79716.90\",\"A\":\"15.297\",\"T\":1788564450065,\"E\":1788564450065,\"st\":1}}"}
{"receive_ns":1788564450111362000,"stream":"btcusdt@bookTicker","event_type":"bookTicker","event_time_ms":1788564450065,"raw_json":"{\"stream\":\"btcusdt@bookTicker\",\"data\":{\"e\":\"bookTicker\",\"u\":11478296196004,\"s\":\"BTCUSDT\",\"ps\":\"BTCUSDT\",\"b\":\"79716.80\",\"B\":\"2.689\",\"a\":\"79716.90\",\"A\":\"15.297\",\"T\":1788564450065,\"E\":1788564450065,\"st\":1}}"}
{"receive_ns":1788564450116974000,"stream":"btcusdt@bookTicker","event_type":"bookTicker","event_time_ms":1788564450066,"raw_json":"{\"stream\":\"btcusdt@bookTicker\",\"data\":{\"e\":\"bookTicker\",\"u\":11478296196082,\"s\":\"BTCUSDT\",\"ps\":\"BTCUSDT\",\"b\":\"79716.80\",\"B\":\"2.689\",\"a\":\"79716.90\",\"A\":\"15.316\",\"T\":1788564450065,\"E\":1788564450066,\"st\":1}}"}
{"receive_ns":1788564450128025000,"stream":"btcusdt@bookTicker","event_type":"bookTicker","event_time_ms":1788564450066,"raw_json":"{\"stream\":\"btcusdt@bookTicker\",\"data\":{\"e\":\"bookTicker\",\"u\":11478296196154,\"s\":\"BTCUSDT\",\"ps\":\"BTCUSDT\",\"b\":\"79716.80\",\"B\":\"2.689\",\"a\":\"79716.90\",\"A\":\"15.297\",\"T\":1788564450066,\"E\":1788564450066,\"st\":1}}"}
{"receive_ns":1788564450128285000,"stream":"btcusdt@bookTicker","event_type":"bookTicker","event_time_ms":1788564450067,"raw_json":"{\"stream\":\"btcusdt@bookTicker\",\"data\":{\"e\":\"bookTicker\",\"u\":11478296196224,\"s\":\"BTCUSDT\",\"ps\":\"BTCUSDT\",\"b\":\"79716.80\",\"B\":\"2.689\",\"a\":\"79716.90\",\"A\":\"15.298\",\"T\":1788564450067,\"E\":1788564450067,\"st\":1}}"}
{"receive_ns":1788564450134315000,"stream":"btcusdt@depth@100ms","event_type":"depthUpdate","event_time_ms":1788564450111,"raw_json":"{\"stream\":\"btcusdt@depth@100ms\",\"data\":{\"e\":\"depthUpdate\",\"E\":1788564450111,\"T\":1788564450109,\"s\":\"BTCUSDT\",\"ps\":\"BTCUSDT\",\"U\":11478296192539,\"u\":11478296200204,\"pu\":11478296192351,\"b\":[[\"1000.00\",\"24.754\"],[\"29516.80\",\"1.386\"],[\"29616.80\",\"0.714\"],[\"63773.00\",\"0.000\"],[\"71745.10\",\"0.002\"],[\"76528.10\",\"0.000\"],[\"78482.00\",\"0.000\"],[\"78574.20\",\"13.484\"],[\"78919.60\",\"2.232\"],[\"79226.40\",\"0.000\"],[\"79298.00\",\"0.016\"],[\"79318.20\",\"1.403\"],[\"79501.60\",\"0.628\"],[\"79529.50\",\"0.000\"],[\"79530.70\",\"0.001\"],[\"79560.60\",\"0.000\"],[\"79563.20\",\"0.057\"],[\"79578.10\",\"7.112\"],[\"79579.70\",\"1.797\"],[\"79594.30\",\"0.675\"],[\"79621.10\",\"0.038\"],[\"79636.50\",\"0.000\"],[\"79645.00\",\"0.004\"],[\"79693.10\",\"0.001\"],[\"79698.90\",\"0.315\"],[\"79700.50\",\"0.280\"],[\"79700.90\",\"0.217\"],[\"79702.50\",\"0.000\"],[\"79709.90\",\"0.130\"],[\"79710.00\",\"0.041\"],[\"79710.10\",\"0.026\"],[\"79711.50\",\"0.004\"],[\"79711.60\",\"0.026\"],[\"79711.80\",\"0.001\"],[\"79712.00\",\"0.016\"],[\"79712.40\",\"0.000\"],[\"79712.80\",\"0.002\"],[\"79713.10\",\"0.002\"],[\"79716.80\",\"2.689\"]],\"a\":[[\"79716.90\",\"15.298\"],[\"79717.00\",\"0.009\"],[\"79733.00\",\"0.628\"],[\"79756.80\",\"0.730\"],[\"79760.90\",\"0.062\"],[\"79764.10\",\"0.001\"],[\"79772.80\",\"0.314\"],[\"79788.70\",\"0.021\"],[\"79792.60\",\"0.451\"],[\"79840.30\",\"0.351\"],[\"79886.30\",\"0.000\"],[\"79952.10\",\"0.323\"],[\"79952.20\",\"2.911\"],[\"80078.80\",\"0.002\"],[\"80087.60\",\"0.579\"],[\"80514.10\",\"0.018\"],[\"80679.80\",\"1.028\"],[\"80954.00\",\"0.003\"]],\"st\":1}}"}
{"receive_ns":1788564450134611000,"stream":"btcusdt@bookTicker","event_type":"bookTicker","event_time_ms":1788564450120,"raw_json":"{\"stream\":\"btcusdt@bookTicker\",\"data\":{\"e\":\"bookTicker\",\"u\":11478296200768,\"s\":\"BTCUSDT\",\"ps\":\"BTCUSDT\",\"b\":\"79716.80\",\"B\":\"2.689\",\"a\":\"79716.90\",\"A\":\"15.317\",\"T\":1788564450119,\"E\":1788564450120,\"st\":1}}"}
{"receive_ns":1788564450140749000,"stream":"btcusdt@bookTicker","event_type":"bookTicker","event_time_ms":1788564450120,"raw_json":"{\"stream\":\"btcusdt@bookTicker\",\"data\":{\"e\":\"bookTicker\",\"u\":11478296200805,\"s\":\"BTCUSDT\",\"ps\":\"BTCUSDT\",\"b\":\"79716.80\",\"B\":\"2.689\",\"a\":\"79716.90\",\"A\":\"15.298\",\"T\":1788564450120,\"E\":1788564450120,\"st\":1}}"}
{"receive_ns":1788564450148500000,"stream":"btcusdt@bookTicker","event_type":"bookTicker","event_time_ms":1788564450177,"raw_json":"{\"stream\":\"btcusdt@bookTicker\",\"data\":{\"e\":\"bookTicker\",\"u\":11478296204494,\"s\":\"BTCUSDT\",\"ps\":\"BTCUSDT\",\"b\":\"79716.80\",\"B\":\"2.672\",\"a\":\"79716.90\",\"A\":\"15.298\",\"T\":1788564450176,\"E\":1788564450177,\"st\":1}}"}
{"receive_ns":1788564450160364000,"stream":"btcusdt@bookTicker","event_type":"bookTicker","event_time_ms":1788564450179,"raw_json":"{\"stream\":\"btcusdt@bookTicker\",\"data\":{\"e\":\"bookTicker\",\"u\":11478296204670,\"s\":\"BTCUSDT\",\"ps\":\"BTCUSDT\",\"b\":\"79716.80\",\"B\":\"2.690\",\"a\":\"79716.90\",\"A\":\"15.298\",\"T\":1788564450179,\"E\":1788564450179,\"st\":1}}"}
{"receive_ns":1788564450188240000,"stream":"btcusdt@depth@100ms","event_type":"depthUpdate","event_time_ms":1788564450213,"raw_json":"{\"stream\":\"btcusdt@depth@100ms\",\"data\":{\"e\":\"depthUpdate\",\"E\":1788564450213,\"T\":1788564450211,\"s\":\"BTCUSDT\",\"ps\":\"BTCUSDT\",\"U\":11478296200295,\"u\":11478296206749,\"pu\":11478296200204,\"b\":[[\"1000.00\",\"24.754\"],[\"29516.80\",\"1.561\"],[\"29616.80\",\"0.539\"],[\"63773.40\",\"0.000\"],[\"71745.10\",\"0.002\"],[\"78480.80\",\"0.037\"],[\"78854.20\",\"1.133\"],[\"78919.60\",\"2.232\"],[\"79298.00\",\"0.173\"],[\"79318.20\",\"3.289\"],[\"79497.60\",\"0.733\"],[\"79529.50\",\"1.103\"],[\"79530.70\",\"1.004\"],[\"79557.30\",\"0.002\"],[\"79560.50\",\"0.642\"],[\"79602.00\",\"0.033\"],[\"79693.10\",\"0.003\"],[\"79698.90\",\"0.140\"],[\"79709.00\",\"0.027\"],[\"79709.10\",\"0.027\"],[\"79709.20\",\"0.027\"],[\"79709.30\",\"1.026\"],[\"79709.40\",\"0.200\"],[\"79709.50\",\"0.027\"],[\"79709.60\",\"0.028\"],[\"79709.80\",\"0.125\"],[\"79709.90\",\"0.130\"],[\"79710.00\",\"0.015\"],[\"79710.10\",\"0.000\"],[\"79710.20\",\"0.001\"],[\"79710.30\",\"0.252\"],[\"79710.50\",\"0.000\"],[\"79711.20\",\"0.006\"],[\"79711.30\",\"0.000\"],[\"79711.60\",\"0.000\"],[\"79712.10\",\"0.002\"],[\"79712.40\",\"0.000\"],[\"79716.80\",\"2.690\"]],\"a\":[[\"79716.90\",\"15.298\"],[\"79724.90\",\"1.453\"],[\"79733.00\",\"0.630\"],[\"79752.90\",\"0.965\"],[\"79761.70\",\"0.000\"],[\"79792.60\",\"0.701\"],[\"79793.50\",\"0.002\"],[\"79886.30\",\"0.090\"],[\"79902.60\",\"0.000\"],[\"79942.50\",\"0.003\"],[\"80078.80\",\"0.764\"],[\"80087.60\",\"0.729\"],[\"80115.50\",\"1.123\"],[\"80365.80\",\"0.248\"],[\"80514.10\",\"0.018\"],[\"80888.70\",\"1.049\"],[\"81311.20\",\"0.033\"]],\"st\":1}}"}
{"receive_ns":1788564450224542000,"stream":"btcusdt@bookTicker","event_type":"bookTicker","event_time_ms":1788564450253,"raw_json":"{\"stream\":\"btcusdt@bookTicker\",\"data\":{\"e\":\"bookTicker\",\"u\":11478296209417,\"s\":\"BTCUSDT\",\"ps\":\"BTCUSDT\",\"b\":\"79716.80\",\"B\":\"2.690\",\"a\":\"79716.90\",\"A\":\"15.317\",\"T\":1788564450253,\"E\":1788564450253,\"st\":1}}"}
{"receive_ns":1788564450237606000,"stream":"btcusdt@bookTicker","event_type":"bookTicker","event_time_ms":1788564450253,"raw_json":"{\"stream\":\"btcusdt@bookTicker\",\"data\":{\"e\":\"bookTicker\",\"u\":11478296209460,\"s\":\"BTCUSDT\",\"ps\":\"BTCUSDT\",\"b\":\"79716.80\",\"B\":\"2.690\",\"a\":\"79716.90\",\"A\":\"15.298\",\"T\":1788564450253,\"E\":1788564450253,\"st\":1}}"}
{"receive_ns":1788564450294935000,"stream":"btcusdt@depth@100ms","event_type":"depthUpdate","event_time_ms":1788564450315,"raw_json":"{\"stream\":\"btcusdt@depth@100ms\",\"data\":{\"e\":\"depthUpdate\",\"E\":1788564450315,\"T\":1788564450313,\"s\":\"BTCUSDT\",\"ps\":\"BTCUSDT\",\"U\":11478296207022,\"u\":11478296213022,\"pu\":11478296206749,\"b\":[[\"29516.80\",\"1.743\"],[\"29616.80\",\"0.357\"],[\"71745.10\",\"0.002\"],[\"71782.00\",\"0.000\"],[\"76528.10\",\"0.002\"],[\"78919.60\",\"2.232\"],[\"79318.20\",\"3.149\"],[\"79320.20\",\"0.140\"],[\"79531.50\",\"0.707\"],[\"79594.30\",\"0.693\"],[\"79602.00\",\"0.040\"],[\"79621.10\",\"0.040\"],[\"79653.00\",\"0.008\"],[\"79688.70\",\"0.046\"],[\"79689.40\",\"0.003\"],[\"79690.10\",\"0.920\"],[\"79691.30\",\"0.002\"],[\"79693.80\",\"0.001\"],[\"79694.50\",\"0.372\"],[\"79695.80\",\"0.007\"],[\"79709.00\",\"0.001\"],[\"79710.00\",\"0.041\"],[\"79710.20\",\"0.027\"],[\"79710.80\",\"0.012\"]],\"a\":[[\"79716.90\",\"15.298\"],[\"79732.90\",\"0.631\"],[\"79734.30\",\"0.003\"],[\"79734.90\",\"0.000\"],[\"79735.70\",\"0.627\"],[\"79740.10\",\"0.928\"],[\"79740.80\",\"0.818\"],[\"79747.20\",\"0.033\"],[\"79748.10\",\"0.185\"],[\"79764.80\",\"0.348\"],[\"79772.80\",\"0.316\"],[\"79792.60\",\"0.701\"],[\"79840.30\",\"0.351\"],[\"80087.60\",\"0.992\"],[\"80514.10\",\"0.018\"],[\"80832.90\",\"17.423\"],[\"80952.90\",\"0.015\"]],\"st\":1}}"}
{"receive_ns":1788564450314947000,"stream":"btcusdt@bookTicker","event_type":"bookTicker","event_time_ms":1788564450333,"raw_json":"{\"stream\":\"btcusdt@bookTicker\",\"data\":{\"e\":\"bookTicker\",\"u\":11478296214260,\"s\":\"BTCUSDT\",\"ps\":\"BTCUSDT\",\"b\":\"79716.80\",\"B\":\"2.690\",\"a\":\"79716.90\",\"A\":\"15.160\",\"T\":1788564450333,\"E\":1788564450333,\"st\":1}}"}
{"receive_ns":1788564450398782000,"stream":"btcusdt@depth@100ms","event_type":"depthUpdate","event_time_ms":1788564450417,"raw_json":"{\"stream\":\"btcusdt@depth@100ms\",\"data\":{\"e\":\"depthUpdate\",\"E\":1788564450417,\"T\":1788564450416,\"s\":\"BTCUSDT\",\"ps\":\"BTCUSDT\",\"U\":11478296213193,\"u\":11478296218924,\"pu\":11478296213022,\"b\":[[\"1000.00\",\"24.754\"],[\"29416.80\",\"0.056\"],[\"29516.80\",\"1.806\"],[\"29616.80\",\"0.238\"],[\"71745.10\",\"0.002\"],[\"76528.10\",\"0.000\"],[\"78600.80\",\"8.283\"],[\"78919.60\",\"2.232\"],[\"79318.20\",\"3.148\"],[\"79497.60\",\"0.502\"],[\"79501.60\",\"0.859\"],[\"79529.50\",\"1.103\"],[\"79530.70\",\"1.004\"],[\"79533.50\",\"0.251\"],[\"79698.90\",\"0.140\"],[\"79709.10\",\"0.001\"],[\"79709.20\",\"0.001\"],[\"79710.30\",\"0.278\"],[\"79710.40\",\"0.057\"]],\"a\":[[\"79716.90\",\"15.160\"],[\"79718.10\",\"1.268\"],[\"79792.60\",\"0.701\"],[\"79886.30\",\"0.090\"],[\"80078.80\",\"0.764\"],[\"80087.60\",\"1.147\"],[\"80514.10\",\"0.018\"],[\"80872.80\",\"3.213\"],[\"80952.50\",\"2.468\"]],\"st\":1}}"}
{"receive_ns":1788564450415684000,"stream":"btcusdt@bookTicker","event_type":"bookTicker","event_time_ms":1788564450427,"raw_json":"{\"stream\":\"btcusdt@bookTicker\",\"data\":{\"e\":\"bookTicker\",\"u\":11478296219500,\"s\":\"BTCUSDT\",\"ps\":\"BTCUSDT\",\"b\":\"79716.80\",\"B\":\"2.689\",\"a\":\"79716.90\",\"A\":\"15.160\",\"T\":1788564450427,\"E\":1788564450427,\"st\":1}}"}
{"receive_ns":1788564450421432000,"stream":"btcusdt@trade","event_type":"trade","event_time_ms":1788564450427,"raw_json":"{\"stream\":\"btcusdt@trade\",\"data\":{\"e\":\"trade\",\"E\":1788564450427,\"T\":1788564450427,\"s\":\"BTCUSDT\",\"t\":8054096463,\"p\":\"79716.80\",\"q\":\"0.001\",\"X\":\"MARKET\",\"m\":true,\"st\":1}}"}
{"receive_ns":1788564450421857000,"stream":"btcusdt@bookTicker","event_type":"bookTicker","event_time_ms":1788564450428,"raw_json":"{\"stream\":\"btcusdt@bookTicker\",\"data\":{\"e\":\"bookTicker\",\"u\":11478296219565,\"s\":\"BTCUSDT\",\"ps\":\"BTCUSDT\",\"b\":\"79716.80\",\"B\":\"2.689\",\"a\":\"79716.90\",\"A\":\"15.179\",\"T\":1788564450428,\"E\":1788564450428,\"st\":1}}"}
{"receive_ns":1788564450439564000,"stream":"btcusdt@bookTicker","event_type":"bookTicker","event_time_ms":1788564450428,"raw_json":"{\"stream\":\"btcusdt@bookTicker\",\"data\":{\"e\":\"bookTicker\",\"u\":11478296219614,\"s\":\"BTCUSDT\",\"ps\":\"BTCUSDT\",\"b\":\"79716.80\",\"B\":\"2.689\",\"a\":\"79716.90\",\"A\":\"15.181\",\"T\":1788564450428,\"E\":1788564450428,\"st\":1}}"}
{"receive_ns":1788564450451166000,"stream":"btcusdt@bookTicker","event_type":"bookTicker","event_time_ms":1788564450429,"raw_json":"{\"stream\":\"btcusdt@bookTicker\",\"data\":{\"e\":\"bookTicker\",\"u\":11478296219723,\"s\":\"BTCUSDT\",\"ps\":\"BTCUSDT\",\"b\":\"79716.80\",\"B\":\"2.689\",\"a\":\"79716.90\",\"A\":\"15.162\",\"T\":1788564450429,\"E\":1788564450429,\"st\":1}}"}
{"receive_ns":1788564450457367000,"stream":"btcusdt@bookTicker","event_type":"bookTicker","event_time_ms":1788564450429,"raw_json":"{\"stream\":\"btcusdt@bookTicker\",\"data\":{\"e\":\"bookTicker\",\"u\":11478296219737,\"s\":\"BTCUSDT\",\"ps\":\"BTCUSDT\",\"b\":\"79716.80\",\"B\":\"2.689\",\"a\":\"79716.90\",\"A\":\"15.160\",\"T\":1788564450429,\"E\":1788564450429,\"st\":1}}"}
{"receive_ns":1788564450468383000,"stream":"btcusdt@bookTicker","event_type":"bookTicker","event_time_ms":1788564450437,"raw_json":"{\"stream\":\"btcusdt@bookTicker\",\"data\":{\"e\":\"bookTicker\",\"u\":11478296220306,\"s\":\"BTCUSDT\",\"ps\":\"BTCUSDT\",\"b\":\"79716.80\",\"B\":\"2.689\",\"a\":\"79716.90\",\"A\":\"15.159\",\"T\":1788564450437,\"E\":1788564450437,\"st\":1}}"}
{"receive_ns":1788564450487682000,"stream":"btcusdt@bookTicker","event_type":"bookTicker","event_time_ms":1788564450457,"raw_json":"{\"stream\":\"btcusdt@bookTicker\",\"data\":{\"e\":\"bookTicker\",\"u\":11478296221426,\"s\":\"BTCUSDT\",\"ps\":\"BTCUSDT\",\"b\":\"79716.80\",\"B\":\"2.676\",\"a\":\"79716.90\",\"A\":\"15.159\",\"T\":1788564450456,\"E\":1788564450457,\"st\":1}}"}
{"receive_ns":1788564450500821000,"stream":"btcusdt@trade","event_type":"trade","event_time_ms":1788564450457,"raw_json":"{\"stream\":\"btcusdt@trade\",\"data\":{\"e\":\"trade\",\"E\":1788564450457,\"T\":1788564450456,\"s\":\"BTCUSDT\",\"t\":8054096464,\"p\":\"79716.80\",\"q\":\"0.013\",\"X\":\"MARKET\",\"m\":true,\"st\":1}}"}
{"receive_ns":1788564450517791000,"stream":"btcusdt@bookTicker","event_type":"bookTicker","event_time_ms":1788564450458,"raw_json":"{\"stream\":\"btcusdt@bookTicker\",\"data\":{\"e\":\"bookTicker\",\"u\":11478296221499,\"s\":\"BTCUSDT\",\"ps\":\"BTCUSDT\",\"b\":\"79716.80\",\"B\":\"2.676\",\"a\":\"79716.90\",\"A\":\"15.178\",\"T\":1788564450458,\"E\":1788564450458,\"st\":1}}"}
{"receive_ns":1788564450522498000,"stream":"btcusdt@bookTicker","event_type":"bookTicker","event_time_ms":1788564450458,"raw_json":"{\"stream\":\"btcusdt@bookTicker\",\"data\":{\"e\":\"bookTicker\",\"u\":11478296221604,\"s\":\"BTCUSDT\",\"ps\":\"BTCUSDT\",\"b\":\"79716.80\",\"B\":\"2.676\",\"a\":\"79716.90\",\"A\":\"15.180\",\"T\":1788564450458,\"E\":1788564450458,\"st\":1}}"}
{"receive_ns":1788564450528034000,"stream":"btcusdt@bookTicker","event_type":"bookTicker","event_time_ms":1788564450459,"raw_json":"{\"stream\":\"btcusdt@bookTicker\",\"data\":{\"e\":\"bookTicker\",\"u\":11478296221720,\"s\":\"BTCUSDT\",\"ps\":\"BTCUSDT\",\"b\":\"79716.80\",\"B\":\"2.676\",\"a\":\"79716.90\",\"A\":\"15.161\",\"T\":1788564450458,\"E\":1788564450459,\"st\":1}}"}
{"receive_ns":1788564450540209000,"stream":"btcusdt@bookTicker","event_type":"bookTicker","event_time_ms":1788564450459,"raw_json":"{\"stream\":\"btcusdt@bookTicker\",\"data\":{\"e\":\"bookTicker\",\"u\":11478296221728,\"s\":\"BTCUSDT\",\"ps\":\"BTCUSDT\",\"b\":\"79716.80\",\"B\":\"2.676\",\"a\":\"79716.90\",\"A\":\"15.159\",\"T\":1788564450459,\"E\":1788564450459,\"st\":1}}"}
{"receive_ns":1788564450557890000,"stream":"btcusdt@bookTicker","event_type":"bookTicker","event_time_ms":1788564450483,"raw_json":"{\"stream\":\"btcusdt@bookTicker\",\"data\":{\"e\":\"bookTicker\",\"u\":11478296222849,\"s\":\"BTCUSDT\",\"ps\":\"BTCUSDT\",\"b\":\"79716.80\",\"B\":\"2.676\",\"a\":\"79716.90\",\"A\":\"15.178\",\"T\":1788564450483,\"E\":1788564450483,\"st\":1}}"}
{"receive_ns":1788564450576161000,"stream":"btcusdt@bookTicker","event_type":"bookTicker","event_time_ms":1788564450484,"raw_json":"{\"stream\":\"btcusdt@bookTicker\",\"data\":{\"e\":\"bookTicker\",\"u\":11478296222897,\"s\":\"BTCUSDT\",\"ps\":\"BTCUSDT\",\"b\":\"79716.80\",\"B\":\"2.676\",\"a\":\"79716.90\",\"A\":\"15.159\",\"T\":1788564450484,\"E\":1788564450484,\"st\":1}}"}
{"receive_ns":1788564450594000000,"stream":"btcusdt@bookTicker","event_type":"bookTicker","event_time_ms":1788564450486,"raw_json":"{\"stream\":\"btcusdt@bookTicker\",\"data\":{\"e\":\"bookTicker\",\"u\":11478296223044,\"s\":\"BTCUSDT\",\"ps\":\"BTCUSDT\",\"b\":\"79716.80\",\"B\":\"2.676\",\"a\":\"79716.90\",\"A\":\"15.178\",\"T\":1788564450486,\"E\":1788564450486,\"st\":1}}"}
{"receive_ns":1788564450608303000,"stream":"btcusdt@bookTicker","event_type":"bookTicker","event_time_ms":1788564450486,"raw_json":"{\"stream\":\"btcusdt@bookTicker\",\"data\":{\"e\":\"bookTicker\",\"u\":11478296223093,\"s\":\"BTCUSDT\",\"ps\":\"BTCUSDT\",\"b\":\"79716.80\",\"B\":\"2.676\",\"a\":\"79716.90\",\"A\":\"15.159\",\"T\":1788564450486,\"E\":1788564450486,\"st\":1}}"}
{"receive_ns":1788564450626235000,"stream":"btcusdt@bookTicker","event_type":"bookTicker","event_time_ms":1788564450487,"raw_json":"{\"stream\":\"btcusdt@bookTicker\",\"data\":{\"e\":\"bookTicker\",\"u\":11478296223137,\"s\":\"BTCUSDT\",\"ps\":\"BTCUSDT\",\"b\":\"79716.80\",\"B\":\"2.676\",\"a\":\"79716.90\",\"A\":\"15.178\",\"T\":1788564450487,\"E\":1788564450487,\"st\":1}}"}
{"receive_ns":1788564450642785000,"stream":"btcusdt@bookTicker","event_type":"bookTicker","event_time_ms":1788564450488,"raw_json":"{\"stream\":\"btcusdt@bookTicker\",\"data\":{\"e\":\"bookTicker\",\"u\":11478296223182,\"s\":\"BTCUSDT\",\"ps\":\"BTCUSDT\",\"b\":\"79716.80\",\"B\":\"2.676\",\"a\":\"79716.90\",\"A\":\"15.159\",\"T\":1788564450488,\"E\":1788564450488,\"st\":1}}"}
{"receive_ns":1788564450661137000,"stream":"btcusdt@depth@100ms","event_type":"depthUpdate","event_time_ms":1788564450519,"raw_json":"{\"stream\":\"btcusdt@depth@100ms\",\"data\":{\"e\":\"depthUpdate\",\"E\":1788564450519,\"T\":1788564450518,\"s\":\"BTCUSDT\",\"ps\":\"BTCUSDT\",\"U\":11478296219036,\"u\":11478296224811,\"pu\":11478296218924,\"b\":[[\"29416.80\",\"0.119\"],[\"29516.80\",\"1.862\"],[\"29616.80\",\"0.119\"],[\"71745.10\",\"0.002\"],[\"75730.90\",\"0.014\"],[\"76406.90\",\"0.004\"],[\"76528.10\",\"0.002\"],[\"78847.90\",\"0.569\"],[\"78919.60\",\"2.232\"],[\"79320.20\",\"0.000\"],[\"79531.50\",\"0.707\"],[\"79594.30\",\"0.631\"],[\"79698.90\",\"0.065\"],[\"79700.80\",\"0.001\"],[\"79709.30\",\"1.000\"],[\"79709.40\",\"0.174\"],[\"79710.30\",\"0.027\"],[\"79711.00\",\"0.000\"],[\"79711.10\",\"0.051\"],[\"79711.30\",\"0.026\"],[\"79716.80\",\"2.676\"]],\"a\":[[\"79716.90\",\"15.159\"],[\"79717.90\",\"0.014\"],[\"79722.10\",\"0.000\"],[\"79732.90\",\"0.631\"],[\"79734.30\",\"0.003\"],[\"79754.30\",\"1.318\"],[\"79790.30\",\"0.033\"],[\"79792.60\",\"0.451\"],[\"79840.30\",\"0.290\"],[\"79994.20\",\"0.000\"],[\"80087.60\",\"1.147\"],[\"80115.50\",\"1.124\"],[\"80178.00\",\"0.173\"],[\"80434.40\",\"0.125\"],[\"80514.10\",\"0.018\"],[\"80673.50\",\"14.479\"],[\"80832.90\",\"19.277\"]],\"st\":1}}"}
{"receive_ns":1788564450673165000,"stream":"btcusdt@depth@100ms","event_type":"depthUpdate","event_time_ms":1788564450621,"raw_json":"{\"stream\":\"btcusdt@depth@100ms\",\"data\":{\"e\":\"depthUpdate\",\"E\":1788564450621,\"T\":1788564450617,\"s\":\"BTCUSDT\",\"ps\":\"BTCUSDT\",\"U\":11478296224885,\"u\":11478296230220,\"pu\":11478296224811,\"b\":[[\"29416.80\",\"0.189\"],[\"29516.80\",\"1.897\"],[\"29616.80\",\"0.014\"],[\"63773.00\",\"0.000\"],[\"71745.10\",\"0.002\"],[\"76528.10\",\"0.000\"],[\"78919.60\",\"2.232\"],[\"79320.20\",\"0.140\"],[\"79497.60\",\"0.733\"],[\"79501.60\",\"0.628\"],[\"79529.50\",\"1.003\"],[\"79530.70\",\"1.004\"],[\"79533.50\",\"0.001\"],[\"79628.30\",\"0.050\"],[\"79698.90\",\"0.140\"],[\"79709.50\",\"0.001\"],[\"79709.60\",\"0.002\"],[\"79709.80\",\"0.099\"],[\"79711.40\",\"0.026\"],[\"79711.50\",\"0.030\"],[\"79711.70\",\"0.026\"]],\"a\":[[\"79717.90\",\"0.006\"],[\"79722.10\",\"0.008\"],[\"79788.30\",\"5.967\"],[\"79790.30\",\"31.915\"],[\"79792.60\",\"0.201\"],[\"79792.90\",\"1.937\"],[\"79793.00\",\"0.014\"],[\"79866.40\",\"0.250\"],[\"79886.30\",\"0.000\"],[\"80078.80\",\"0.764\"],[\"80087.60\",\"1.147\"],[\"80514.10\",\"0.018\"]],\"st\":1}}"}
{"receive_ns":1788564450685563000,"stream":"btcusdt@bookTicker","event_type":"bookTicker","event_time_ms":1788564450638,"raw_json":"{\"stream\":\"btcusdt@bookTicker\",\"data\":{\"e\":\"bookTicker\",\"u\":11478296231309,\"s\":\"BTCUSDT\",\"ps\":\"BTCUSDT\",\"b\":\"79716.80\",\"B\":\"2.676\",\"a\":\"79716.90\",\"A\":\"15.178\",\"T\":1788564450638,\"E\":1788564450638,\"st\":1}}"}
{"receive_ns":1788564450705270000,"stream":"btcusdt@bookTicker","event_type":"bookTicker","event_time_ms":1788564450639,"raw_json":"{\"stream\":\"btcusdt@bookTicker\",\"data\":{\"e\":\"bookTicker\",\"u\":11478296231350,\"s\":\"BTCUSDT\",\"ps\":\"BTCUSDT\",\"b\":\"79716.80\",\"B\":\"2.676\",\"a\":\"79716.90\",\"A\":\"15.159\",\"T\":1788564450638,\"E\":1788564450639,\"st\":1}}"}
{"receive_ns":1788564450722377000,"stream":"btcusdt@bookTicker","event_type":"bookTicker","event_time_ms":1788564450661,"raw_json":"{\"stream\":\"btcusdt@bookTicker\",\"data\":{\"e\":\"bookTicker\",\"u\":11478296232431,\"s\":\"BTCUSDT\",\"ps\":\"BTCUSDT\",\"b\":\"79716.80\",\"B\":\"2.676\",\"a\":\"79716.90\",\"A\":\"15.178\",\"T\":1788564450661,\"E\":1788564450661,\"st\":1}}"}
{"receive_ns":1788564450743524000,"stream":"btcusdt@bookTicker","event_type":"bookTicker","event_time_ms":1788564450661,"raw_json":"{\"stream\":\"btcusdt@bookTicker\",\"data\":{\"e\":\"bookTicker\",\"u\":11478296232494,\"s\":\"BTCUSDT\",\"ps\":\"BTCUSDT\",\"b\":\"79716.80\",\"B\":\"2.676\",\"a\":\"79716.90\",\"A\":\"15.159\",\"T\":1788564450661,\"E\":1788564450661,\"st\":1}}"}
{"receive_ns":1788564450754707000,"stream":"btcusdt@bookTicker","event_type":"bookTicker","event_time_ms":1788564450715,"raw_json":"{\"stream\":\"btcusdt@bookTicker\",\"data\":{\"e\":\"bookTicker\",\"u\":11478296235352,\"s\":\"BTCUSDT\",\"ps\":\"BTCUSDT\",\"b\":\"79716.80\",\"B\":\"2.676\",\"a\":\"79716.90\",\"A\":\"15.178\",\"T\":1788564450715,\"E\":1788564450715,\"st\":1}}"}
{"receive_ns":1788564450761167000,"stream":"btcusdt@bookTicker","event_type":"bookTicker","event_time_ms":1788564450716,"raw_json":"{\"stream\":\"btcusdt@bookTicker\",\"data\":{\"e\":\"bookTicker\",\"u\":11478296235400,\"s\":\"BTCUSDT\",\"ps\":\"BTCUSDT\",\"b\":\"79716.80\",\"B\":\"2.676\",\"a\":\"79716.90\",\"A\":\"15.159\",\"T\":1788564450716,\"E\":1788564450716,\"st\":1}}"}
{"receive_ns":1788564450767595000,"stream":"btcusdt@depth@100ms","event_type":"depthUpdate","event_time_ms":1788564450723,"raw_json":"{\"stream\":\"btcusdt@depth@100ms\",\"data\":{\"e\":\"depthUpdate\",\"E\":1788564450723,\"T\":1788564450721,\"s\":\"BTCUSDT\",\"ps\":\"BTCUSDT\",\"U\":11478296230456,\"u\":11478296235854,\"pu\":11478296230220,\"b\":[[\"1000.00\",\"24.754\"],[\"29416.80\",\"0.357\"],[\"29516.80\",\"1.743\"],[\"29616.80\",\"0.000\"],[\"71745.10\",\"0.002\"],[\"78122.50\",\"0.036\"],[\"78177.10\",\"1.277\"],[\"78377.60\",\"0.835\"],[\"78919.60\",\"2.865\"],[\"79318.20\",\"3.158\"],[\"79531.50\",\"0.006\"],[\"79594.30\",\"0.001\"],[\"79696.30\",\"0.437\"],[\"79698.90\",\"0.140\"],[\"79711.70\",\"0.000\"],[\"79712.80\",\"0.000\"],[\"79715.40\",\"0.001\"]],\"a\":[[\"79716.90\",\"15.159\"],[\"79717.40\",\"0.028\"],[\"79787.10\",\"0.019\"],[\"79788.30\",\"1.367\"],[\"79790.30\",\"0.033\"],[\"79792.60\",\"0.002\"],[\"79793.00\",\"31.857\"],[\"79793.50\",\"0.021\"],[\"79795.70\",\"0.000\"],[\"79840.30\",\"0.001\"],[\"79886.30\",\"0.090\"],[\"80087.60\",\"0.729\"],[\"80514.10\",\"0.018\"],[\"80782.60\",\"3.434\"]],\"st\":1}}"}
{"receive_ns":1788564450770673000,"stream":"btcusdt@bookTicker","event_type":"bookTicker","event_time_ms":1788564450724,"raw_json":"{\"stream\":\"btcusdt@bookTicker\",\"data\":{\"e\":\"bookTicker\",\"u\":11478296236138,\"s\":\"BTCUSDT\",\"ps\":\"BTCUSDT\",\"b\":\"79716.80\",\"B\":\"2.676\",\"a\":\"79716.90\",\"A\":\"15.161\",\"T\":1788564450724,\"E\":1788564450724,\"st\":1}}"}
{"receive_ns":1788564450770893000,"stream":"btcusdt@bookTicker","event_type":"bookTicker","event_time_ms":1788564450724,"raw_json":"{\"stream\":\"btcusdt@bookTicker\",\"data\":{\"e\":\"bookTicker\",\"u\":11478296236151,\"s\":\"BTCUSDT\",\"ps\":\"BTCUSDT\",\"b\":\"79716.80\",\"B\":\"2.676\",\"a\":\"79716.90\",\"A\":\"15.180\",\"T\":1788564450724,\"E\":1788564450724,\"st\":1}}"}
{"receive_ns":1788564450783504000,"stream":"btcusdt@bookTicker","event_type":"bookTicker","event_time_ms":1788564450725,"raw_json":"{\"stream\":\"btcusdt@bookTicker\",\"data\":{\"e\":\"bookTicker\",\"u\":11478296236238,\"s\":\"BTCUSDT\",\"ps\":\"BTCUSDT\",\"b\":\"79716.80\",\"B\":\"2.676\",\"a\":\"79716.90\",\"A\":\"15.178\",\"T\":1788564450725,\"E\":1788564450725,\"st\":1}}"}
{"receive_ns":1788564450789781000,"stream":"btcusdt@bookTicker","event_type":"bookTicker","event_time_ms":1788564450725,"raw_json":"{\"stream\":\"btcusdt@bookTicker\",\"data\":{\"e\":\"bookTicker\",\"u\":11478296236240,\"s\":\"BTCUSDT\",\"ps\":\"BTCUSDT\",\"b\":\"79716.80\",\"B\":\"2.676\",\"a\":\"79716.90\",\"A\":\"15.159\",\"T\":1788564450725,\"E\":1788564450725,\"st\":1}}"}
{"receive_ns":1788564450813778000,"stream":"btcusdt@bookTicker","event_type":"bookTicker","event_time_ms":1788564450780,"raw_json":"{\"stream\":\"btcusdt@bookTicker\",\"data\":{\"e\":\"bookTicker\",\"u\":11478296239885,\"s\":\"BTCUSDT\",\"ps\":\"BTCUSDT\",\"b\":\"79716.80\",\"B\":\"2.676\",\"a\":\"79716.90\",\"A\":\"15.160\",\"T\":1788564450780,\"E\":1788564450780,\"st\":1}}"}
{"receive_ns":1788564450820509000,"stream":"btcusdt@depth@100ms","event_type":"depthUpdate","event_time_ms":1788564450825,"raw_json":"{\"stream\":\"btcusdt@depth@100ms\",\"data\":{\"e\":\"depthUpdate\",\"E\":1788564450825,\"T\":1788564450823,\"s\":\"BTCUSDT\",\"ps\":\"BTCUSDT\",\"U\":11478296236103,\"u\":11478296242463,\"pu\":11478296235854,\"b\":[[\"29416.80\",\"0.532\"],[\"29516.80\",\"1.568\"],[\"71745.10\",\"0.002\"],[\"76528.10\",\"0.002\"],[\"78560.90\",\"4.525\"],[\"78919.60\",\"2.865\"],[\"79320.20\",\"0.140\"],[\"79531.50\",\"0.206\"],[\"79594.30\",\"0.669\"],[\"79698.90\",\"0.390\"],[\"79710.40\",\"0.055\"],[\"79711.50\",\"0.004\"]],\"a\":[[\"79716.90\",\"15.160\"],[\"79717.90\",\"0.014\"],[\"79722.10\",\"0.000\"],[\"79790.30\",\"31.876\"],[\"79792.60\",\"0.201\"],[\"79793.00\",\"0.014\"],[\"79840.30\",\"0.351\"],[\"80087.60\",\"1.147\"],[\"80094.90\",\"1.994\"],[\"80514.10\",\"0.018\"],[\"80832.90\",\"19.956\"]],\"st\":1}}"}
{"receive_ns":1788564450844135000,"stream":"btcusdt@bookTicker","event_type":"bookTicker","event_time_ms":1788564450866,"raw_json":"{\"stream\":\"btcusdt@bookTicker\",\"data\":{\"e\":\"bookTicker\",\"u\":11478296244740,\"s\":\"BTCUSDT\",\"ps\":\"BTCUSDT\",\"b\":\"79716.80\",\"B\":\"2.676\",\"a\":\"79716.90\",\"A\":\"15.179\",\"T\":1788564450866,\"E\":1788564450866,\"st\":1}}"}
{"receive_ns":1788564450850057000,"stream":"btcusdt@bookTicker","event_type":"bookTicker","event_time_ms":1788564450867,"raw_json":"{\"stream\":\"btcusdt@bookTicker\",\"data\":{\"e\":\"bookTicker\",\"u\":11478296244782,\"s\":\"BTCUSDT\",\"ps\":\"BTCUSDT\",\"b\":\"79716.80\",\"B\":\"2.676\",\"a\":\"79716.90\",\"A\":\"15.160\",\"T\":1788564450867,\"E\":1788564450867,\"st\":1}}"}
{"receive_ns":1788564450880599000,"stream":"btcusdt@bookTicker","event_type":"bookTicker","event_time_ms":1788564450906,"raw_json":"{\"stream\":\"btcusdt@bookTicker\",\"data\":{\"e\":\"bookTicker\",\"u\":11478296246800,\"s\":\"BTCUSDT\",\"ps\":\"BTCUSDT\",\"b\":\"79716.80\",\"B\":\"2.676\",\"a\":\"79716.90\",\"A\":\"15.141\",\"T\":1788564450906,\"E\":1788564450906,\"st\":1}}"}
{"receive_ns":1788564450887541000,"stream":"btcusdt@bookTicker","event_type":"bookTicker","event_time_ms":1788564450909,"raw_json":"{\"stream\":\"btcusdt@bookTicker\",\"data\":{\"e\":\"bookTicker\",\"u\":11478296246971,\"s\":\"BTCUSDT\",\"ps\":\"BTCUSDT\",\"b\":\"79716.80\",\"B\":\"2.676\",\"a\":\"79716.90\",\"A\":\"15.153\",\"T\":1788564450909,\"E\":1788564450909,\"st\":1}}"}
{"receive_ns":1788564450909861000,"stream":"btcusdt@depth@100ms","event_type":"depthUpdate","event_time_ms":1788564450927,"raw_json":"{\"stream\":\"btcusdt@depth@100ms\",\"data\":{\"e\":\"depthUpdate\",\"E\":1788564450927,\"T\":1788564450926,\"s\":\"BTCUSDT\",\"ps\":\"BTCUSDT\",\"U\":11478296242632,\"u\":11478296247687,\"pu\":11478296242463,\"b\":[[\"29416.80\",\"0.714\"],[\"29516.80\",\"1.386\"],[\"71745.10\",\"0.002\"],[\"76528.10\",\"0.000\"],[\"78122.50\",\"0.164\"],[\"78733.60\",\"14.584\"],[\"78919.60\",\"2.865\"],[\"79318.20\",\"3.158\"],[\"79497.60\",\"0.733\"],[\"79529.50\",\"1.178\"],[\"79530.70\",\"1.004\"],[\"79594.30\",\"0.669\"],[\"79698.90\",\"0.065\"],[\"79709.50\",\"0.027\"],[\"79709.70\",\"0.026\"],[\"79709.80\",\"0.125\"],[\"79710.00\",\"0.015\"],[\"79710.20\",\"0.001\"],[\"79710.30\",\"0.001\"],[\"79710.40\",\"0.029\"],[\"79711.10\",\"0.025\"],[\"79711.30\",\"0.000\"],[\"79711.40\",\"0.000\"],[\"79711.90\",\"0.001\"]],\"a\":[[\"79716.90\",\"15.153\"],[\"79717.90\",\"0.006\"],[\"79722.10\",\"0.008\"],[\"79732.90\",\"0.631\"],[\"79734.30\",\"0.003\"],[\"79790.30\",\"0.001\"],[\"79795.70\",\"31.843\"],[\"79840.30\",\"0.351\"],[\"79866.40\",\"0.250\"],[\"79886.30\",\"0.090\"],[\"80078.80\",\"0.764\"],[\"80087.60\",\"1.147\"],[\"80314.80\",\"1.262\"],[\"80514.10\",\"0.018\"],[\"81072.10\",\"0.696\"]],\"st\":1}}"}
{"receive_ns":1788564451005899000,"stream":"btcusdt@depth@100ms","event_type":"depthUpdate","event_time_ms":1788564451029,"raw_json":"{\"stream\":\"btcusdt@depth@100ms\",\"data\":{\"e\":\"depthUpdate\",\"E\":1788564451029,\"T\":1788564451026,\"s\":\"BTCUSDT\",\"ps\":\"BTCUSDT\",\"U\":11478296247758,\"u\":11478296253069,\"pu\":11478296247687,\"b\":[[\"1000.00\",\"24.754\"],[\"29416.80\",\"0.889\"],[\"29516.80\",\"1.211\"],[\"71745.10\",\"0.002\"],[\"75731.10\",\"0.002\"],[\"76291.90\",\"0.002\"],[\"76528.10\",\"0.002\"],[\"78919.60\",\"2.865\"],[\"79318.20\",\"3.148\"],[\"79320.20\",\"0.140\"],[\"79531.50\",\"0.707\"],[\"79698.60\",\"1.583\"],[\"79700.50\",\"0.070\"],[\"79703.80\",\"0.464\"],[\"79709.10\",\"0.027\"],[\"79709.20\",\"0.027\"],[\"79709.30\",\"1.026\"],[\"79709.40\",\"0.200\"]],\"a\":[[\"79790.30\",\"0.020\"],[\"79792.60\",\"0.451\"],[\"79793.00\",\"31.857\"],[\"79795.70\",\"0.000\"],[\"80087.60\",\"0.992\"],[\"80514.10\",\"0.018\"],[\"80646.20\",\"19.648\"],[\"82086.20\",\"0.210\"]],\"st\":1}}"}
{"receive_ns":1788564451044745000,"stream":"btcusdt@bookTicker","event_type":"bookTicker","event_time_ms":1788564451066,"raw_json":"{\"stream\":\"btcusdt@bookTicker\",\"data\":{\"e\":\"bookTicker\",\"u\":11478296255718,\"s\":\"BTCUSDT\",\"ps\":\"BTCUSDT\",\"b\":\"79716.80\",\"B\":\"2.676\",\"a\":\"79716.90\",\"A\":\"15.172\",\"T\":1788564451065,\"E\":1788564451066,\"st\":1}}"}
{"receive_ns":1788564451051444000,"stream":"btcusdt@bookTicker","event_type":"bookTicker","event_time_ms":1788564451066,"raw_json":"{\"stream\":\"btcusdt@bookTicker\",\"data\":{\"e\":\"bookTicker\",\"u\":11478296255790,\"s\":\"BTCUSDT\",\"ps\":\"BTCUSDT\",\"b\":\"79716.80\",\"B\":\"2.676\",\"a\":\"79716.90\",\"A\":\"15.153\",\"T\":1788564451066,\"E\":1788564451066,\"st\":1}}"}
{"receive_ns":1788564451115749000,"stream":"btcusdt@depth@100ms","event_type":"depthUpdate","event_time_ms":1788564451131,"raw_json":"{\"stream\":\"btcusdt@depth@100ms\",\"data\":{\"e\":\"depthUpdate\",\"E\":1788564451131,\"T\":1788564451129,\"s\":\"BTCUSDT\",\"ps\":\"BTCUSDT\",\"U\":11478296253303,\"u\":11478296261043,\"pu\":11478296253069,\"b\":[[\"29416.80\",\"1.071\"],[\"29516.80\",\"1.029\"],[\"71745.10\",\"0.002\"],[\"76528.10\",\"0.000\"],[\"78480.80\",\"0.022\"],[\"78560.50\",\"0.024\"],[\"78629.20\",\"5.527\"],[\"78720.30\",\"1.582\"],[\"78919.60\",\"2.865\"],[\"79497.60\",\"0.733\"],[\"79529.50\",\"1.103\"],[\"79530.70\",\"1.004\"],[\"79698.90\",\"0.390\"],[\"79702.50\",\"0.000\"],[\"79710.10\",\"0.026\"],[\"79711.30\",\"0.026\"]],\"a\":[[\"79716.90\",\"15.153\"],[\"79717.90\",\"0.014\"],[\"79722.10\",\"0.000\"],[\"79792.10\",\"0.000\"],[\"79792.60\",\"0.701\"],[\"79796.70\",\"0.015\"],[\"79866.40\",\"0.000\"],[\"79886.30\",\"0.090\"],[\"80078.80\",\"0.764\"],[\"80087.60\",\"1.147\"],[\"80115.50\",\"1.249\"],[\"80354.60\",\"0.995\"],[\"80514.10\",\"0.018\"],[\"80726.50\",\"3.339\"],[\"80736.20\",\"0.376\"],[\"80766.40\",\"0.001\"],[\"80776.50\",\"0.373\"],[\"80873.10\",\"0.013\"],[\"80952.80\",\"0.006\"],[\"81202.20\",\"0.000\"],[\"87688.60\",\"0.000\"]],\"st\":1}}"}
{"receive_ns":1788564451165687000,"stream":"btcusdt@bookTicker","event_type":"bookTicker","event_time_ms":1788564451184,"raw_json":"{\"stream\":\"btcusdt@bookTicker\",\"data\":{\"e\":\"bookTicker\",\"u\":11478296264204,\"s\":\"BTCUSDT\",\"ps\":\"BTCUSDT\",\"b\":\"79716.80\",\"B\":\"2.658\",\"a\":\"79716.90\",\"A\":\"15.153\",\"T\":1788564451184,\"E\":1788564451184,\"st\":1}}"}
{"receive_ns":1788564451171282000,"stream":"btcusdt@bookTicker","event_type":"bookTicker","event_time_ms":1788564451187,"raw_json":"{\"stream\":\"btcusdt@bookTicker\",\"data\":{\"e\":\"bookTicker\",\"u\":11478296264488,\"s\":\"BTCUSDT\",\"ps\":\"BTCUSDT\",\"b\":\"79716.80\",\"B\":\"2.677\",\"a\":\"79716.90\",\"A\":\"15.153\",\"T\":1788564451187,\"E\":1788564451187,\"st\":1}}"}
{"receive_ns":1788564451219520000,"stream":"btcusdt@depth@100ms","event_type":"depthUpdate","event_time_ms":1788564451233,"raw_json":"{\"stream\":\"btcusdt@depth@100ms\",\"data\":{\"e\":\"depthUpdate\",\"E\":1788564451233,\"T\":1788564451229,\"s\":\"BTCUSDT\",\"ps\":\"BTCUSDT\",\"U\":11478296261138,\"u\":11478296267113,\"pu\":11478296261043,\"b\":[[\"29416.80\",\"1.246\"],[\"29516.80\",\"0.854\"],[\"63773.00\",\"0.000\"],[\"63773.40\",\"0.000\"],[\"71745.10\",\"0.002\"],[\"75734.90\",\"0.000\"],[\"78356.90\",\"0.000\"],[\"78455.10\",\"0.004\"],[\"78480.80\",\"0.037\"],[\"78560.50\",\"0.031\"],[\"78574.40\",\"5.670\"],[\"78919.60\",\"2.865\"],[\"79177.00\",\"3.811\"],[\"79318.20\",\"3.149\"],[\"79319.60\",\"1.356\"],[\"79531.50\",\"0.206\"],[\"79562.70\",\"0.556\"],[\"79653.00\",\"0.002\"],[\"79693.10\",\"0.003\"],[\"79698.90\",\"0.891\"],[\"79700.80\",\"0.008\"],[\"79702.40\",\"0.002\"],[\"79711.30\",\"0.026\"],[\"79716.80\",\"2.677\"]],\"a\":[[\"79717.40\",\"0.436\"],[\"79717.90\",\"0.006\"],[\"79722.10\",\"0.008\"],[\"79733.00\",\"0.630\"],[\"79790.30\",\"0.034\"],[\"79792.00\",\"0.817\"],[\"79792.60\",\"0.701\"],[\"79814.00\",\"0.196\"],[\"80087.60\",\"1.147\"],[\"80115.50\",\"1.248\"],[\"80514.10\",\"0.638\"],[\"80679.80\",\"0.842\"],[\"80873.10\",\"0.020\"],[\"80952.80\",\"0.021\"],[\"81311.20\",\"0.036\"]],\"st\":1}}"}
{"receive_ns":1788564451312926000,"stream":"btcusdt@depth@100ms","event_type":"depthUpdate","event_time_ms":1788564451335,"raw_json":"{\"stream\":\"btcusdt@depth@100ms\",\"data\":{\"e\":\"depthUpdate\",\"E\":1788564451335,\"T\":1788564451333,\"s\":\"BTCUSDT\",\"ps\":\"BTCUSDT\",\"U\":11478296267306,\"u\":11478296273076,\"pu\":11478296267113,\"b\":[[\"1000.00\",\"24.754\"],[\"29416.80\",\"1.428\"],[\"29516.80\",\"0.672\"],[\"71745.10\",\"0.002\"],[\"76528.10\",\"0.002\"],[\"78149.00\",\"3.450\"],[\"78560.90\",\"5.478\"],[\"78919.60\",\"2.865\"],[\"79058.70\",\"4.419\"],[\"79318.20\",\"3.149\"],[\"79320.20\",\"0.140\"],[\"79497.60\",\"0.502\"],[\"79529.50\",\"0.000\"],[\"79530.70\",\"0.001\"],[\"79621.10\",\"0.038\"],[\"79645.00\",\"0.004\"],[\"79694.70\",\"0.077\"],[\"79698.90\",\"0.816\"]],\"a\":[[\"79754.70\",\"0.008\"],[\"79756.80\",\"0.730\"],[\"79772.80\",\"0.314\"],[\"79792.60\",\"0.451\"],[\"79886.30\",\"0.000\"],[\"80078.80\",\"0.002\"],[\"80087.60\",\"0.579\"],[\"80514.10\",\"0.638\"]],\"st\":1}}"}
{"receive_ns":1788564451427253000,"stream":"btcusdt@depth@100ms","event_type":"depthUpdate","event_time_ms":1788564451437,"raw_json":"{\"stream\":\"btcusdt@depth@100ms\",\"data\":{\"e\":\"depthUpdate\",\"E\":1788564451437,\"T\":1788564451433,\"s\":\"BTCUSDT\",\"ps\":\"BTCUSDT\",\"U\":11478296273191,\"u\":11478296279064,\"pu\":11478296273076,\"b\":[[\"29416.80\",\"1.603\"],[\"29516.80\",\"0.497\"],[\"63774.00\",\"0.000\"],[\"71745.10\",\"0.002\"],[\"71782.00\",\"0.000\"],[\"76528.10\",\"0.000\"],[\"78536.10\",\"0.001\"],[\"78634.10\",\"0.000\"],[\"78919.60\",\"2.865\"],[\"79045.00\",\"0.099\"],[\"79355.30\",\"0.053\"],[\"79501.60\",\"0.859\"],[\"79529.50\",\"1.103\"],[\"79530.70\",\"1.004\"],[\"79531.50\",\"0.006\"],[\"79541.40\",\"0.023\"],[\"79622.10\",\"0.010\"],[\"79653.10\",\"2.310\"],[\"79698.90\",\"0.065\"],[\"79700.90\",\"0.217\"]],\"a\":[[\"79768.70\",\"0.044\"],[\"79792.60\",\"0.502\"],[\"79799.80\",\"0.009\"],[\"79886.10\",\"0.063\"],[\"79886.30\",\"0.090\"],[\"79938.70\",\"8.494\"],[\"80078.80\",\"0.764\"],[\"80085.40\",\"0.053\"],[\"80087.60\",\"0.729\"],[\"80417.40\",\"0.097\"],[\"80514.10\",\"0.638\"]],\"st\":1}}"}
{"receive_ns":1788564451433974000,"stream":"btcusdt@bookTicker","event_type":"bookTicker","event_time_ms":1788564451458,"raw_json":"{\"stream\":\"btcusdt@bookTicker\",\"data\":{\"e\":\"bookTicker\",\"u\":11478296280355,\"s\":\"BTCUSDT\",\"ps\":\"BTCUSDT\",\"b\":\"79716.80\",\"B\":\"2.664\",\"a\":\"79716.90\",\"A\":\"15.153\",\"T\":1788564451458,\"E\":1788564451458,\"st\":1}}"}
{"receive_ns":1788564451439400000,"stream":"btcusdt@trade","event_type":"trade","event_time_ms":1788564451458,"raw_json":"{\"stream\":\"btcusdt@trade\",\"data\":{\"e\":\"trade\",\"E\":1788564451458,\"T\":1788564451458,\"s\":\"BTCUSDT\",\"t\":8054096465,\"p\":\"79716.80\",\"q\":\"0.013\",\"X\":\"MARKET\",\"m\":true,\"st\":1}}"}
{"receive_ns":1788564451445520000,"stream":"btcusdt@bookTicker","event_type":"bookTicker","event_time_ms":1788564451459,"raw_json":"{\"stream\":\"btcusdt@bookTicker\",\"data\":{\"e\":\"bookTicker\",\"u\":11478296280491,\"s\":\"BTCUSDT\",\"ps\":\"BTCUSDT\",\"b\":\"79716.80\",\"B\":\"2.664\",\"a\":\"79716.90\",\"A\":\"15.155\",\"T\":1788564451459,\"E\":1788564451459,\"st\":1}}"}
{"receive_ns":1788564451445779000,"stream":"btcusdt@bookTicker","event_type":"bookTicker","event_time_ms":1788564451460,"raw_json":"{\"stream\":\"btcusdt@bookTicker\",\"data\":{\"e\":\"bookTicker\",\"u\":11478296280589,\"s\":\"BTCUSDT\",\"ps\":\"BTCUSDT\",\"b\":\"79716.80\",\"B\":\"2.664\",\"a\":\"79716.90\",\"A\":\"15.174\",\"T\":1788564451459,\"E\":1788564451460,\"st\":1}}"}
{"receive_ns":1788564451451644000,"stream":"btcusdt@bookTicker","event_type":"bookTicker","event_time_ms":1788564451460,"raw_json":"{\"stream\":\"btcusdt@bookTicker\",\"data\":{\"e\":\"bookTicker\",\"u\":11478296280649,\"s\":\"BTCUSDT\",\"ps\":\"BTCUSDT\",\"b\":\"79716.80\",\"B\":\"2.664\",\"a\":\"79716.90\",\"A\":\"15.172\",\"T\":1788564451460,\"E\":1788564451460,\"st\":1}}"}
{"receive_ns":1788564451457309000,"stream":"btcusdt@bookTicker","event_type":"bookTicker","event_time_ms":1788564451460,"raw_json":"{\"stream\":\"btcusdt@bookTicker\",\"data\":{\"e\":\"bookTicker\",\"u\":11478296280657,\"s\":\"BTCUSDT\",\"ps\":\"BTCUSDT\",\"b\":\"79716.80\",\"B\":\"2.664\",\"a\":\"79716.90\",\"A\":\"15.153\",\"T\":1788564451460,\"E\":1788564451460,\"st\":1}}"}
{"receive_ns":1788564451490496000,"stream":"btcusdt@bookTicker","event_type":"bookTicker","event_time_ms":1788564451503,"raw_json":"{\"stream\":\"btcusdt@bookTicker\",\"data\":{\"e\":\"bookTicker\",\"u\":11478296283623,\"s\":\"BTCUSDT\",\"ps\":\"BTCUSDT\",\"b\":\"79716.80\",\"B\":\"2.664\",\"a\":\"79716.90\",\"A\":\"15.174\",\"T\":1788564451503,\"E\":1788564451503,\"st\":1}}"}
{"receive_ns":1788564451520773000,"stream":"btcusdt@depth@100ms","event_type":"depthUpdate","event_time_ms":1788564451539,"raw_json":"{\"stream\":\"btcusdt@depth@100ms\",\"data\":{\"e\":\"depthUpdate\",\"E\":1788564451539,\"T\":1788564451538,\"s\":\"BTCUSDT\",\"ps\":\"BTCUSDT\",\"U\":11478296279253,\"u\":11478296285695,\"pu\":11478296279064,\"b\":[[\"29316.80\",\"0.014\"],[\"29416.80\",\"1.757\"],[\"29516.80\",\"0.329\"],[\"71745.10\",\"0.002\"],[\"75731.10\",\"0.000\"],[\"76176.90\",\"0.003\"],[\"76528.10\",\"0.002\"],[\"77452.60\",\"0.000\"],[\"78413.40\",\"3.438\"],[\"78919.60\",\"2.865\"],[\"78965.80\",\"2.715\"],[\"79079.10\",\"1.264\"],[\"79318.20\",\"3.150\"],[\"79320.20\",\"0.140\"],[\"79531.50\",\"0.707\"],[\"79593.40\",\"0.000\"],[\"79593.50\",\"0.081\"],[\"79709.10\",\"0.001\"],[\"79709.20\",\"0.001\"],[\"79710.40\",\"0.055\"],[\"79710.60\",\"0.026\"],[\"79711.20\",\"0.006\"],[\"79711.30\",\"0.000\"],[\"79716.80\",\"2.664\"]],\"a\":[[\"79716.90\",\"15.174\"],[\"79792.60\",\"0.701\"],[\"80087.60\",\"1.147\"],[\"80115.50\",\"1.247\"],[\"80514.10\",\"0.638\"],[\"80713.40\",\"4.101\"],[\"81650.90\",\"0.489\"]],\"st\":1}}"}
{"receive_ns":1788564451533184000,"stream":"btcusdt@bookTicker","event_type":"bookTicker","event_time_ms":1788564451547,"raw_json":"{\"stream\":\"btcusdt@bookTicker\",\"data\":{\"e\":\"bookTicker\",\"u\":11478296286327,\"s\":\"BTCUSDT\",\"ps\":\"BTCUSDT\",\"b\":\"79716.80\",\"B\":\"2.663\",\"a\":\"79716.90\",\"A\":\"15.174\",\"T\":1788564451547,\"E\":1788564451547,\"st\":1}}"}
{"receive_ns":1788564451550649000,"stream":"btcusdt@trade","event_type":"trade","event_time_ms":1788564451547,"raw_json":"{\"stream\":\"btcusdt@trade\",\"data\":{\"e\":\"trade\",\"E\":1788564451547,\"T\":1788564451547,\"s\":\"BTCUSDT\",\"t\":8054096466,\"p\":\"79716.80\",\"q\":\"0.001\",\"X\":\"MARKET\",\"m\":true,\"st\":1}}"}
{"receive_ns":1788564451557263000,"stream":"btcusdt@bookTicker","event_type":"bookTicker","event_time_ms":1788564451549,"raw_json":"{\"stream\":\"btcusdt@bookTicker\",\"data\":{\"e\":\"bookTicker\",\"u\":11478296286428,\"s\":\"BTCUSDT\",\"ps\":\"BTCUSDT\",\"b\":\"79716.80\",\"B\":\"2.663\",\"a\":\"79716.90\",\"A\":\"15.193\",\"T\":1788564451549,\"E\":1788564451549,\"st\":1}}"}
{"receive_ns":1788564451563884000,"stream":"btcusdt@bookTicker","event_type":"bookTicker","event_time_ms":1788564451549,"raw_json":"{\"stream\":\"btcusdt@bookTicker\",\"data\":{\"e\":\"bookTicker\",\"u\":11478296286541,\"s\":\"BTCUSDT\",\"ps\":\"BTCUSDT\",\"b\":\"79716.80\",\"B\":\"2.663\",\"a\":\"79716.90\",\"A\":\"15.195\",\"T\":1788564451549,\"E\":1788564451549,\"st\":1}}"}
{"receive_ns":1788564451564132000,"stream":"btcusdt@bookTicker","event_type":"bookTicker","event_time_ms":1788564451550,"raw_json":"{\"stream\":\"btcusdt@bookTicker\",\"data\":{\"e\":\"bookTicker\",\"u\":11478296286667,\"s\":\"BTCUSDT\",\"ps\":\"BTCUSDT\",\"b\":\"79716.80\",\"B\":\"2.663\",\"a\":\"79716.90\",\"A\":\"15.176\",\"T\":1788564451549,\"E\":1788564451550,\"st\":1}}"}
{"receive_ns":1788564451581841000,"stream":"btcusdt@bookTicker","event_type":"bookTicker","event_time_ms":1788564451550,"raw_json":"{\"stream\":\"btcusdt@bookTicker\",\"data\":{\"e\":\"bookTicker\",\"u\":11478296286702,\"s\":\"BTCUSDT\",\"ps\":\"BTCUSDT\",\"b\":\"79716.80\",\"B\":\"2.663\",\"a\":\"79716.90\",\"A\":\"15.174\",\"T\":1788564451550,\"E\":1788564451550,\"st\":1}}"}
{"receive_ns":1788564451618853000,"stream":"btcusdt@depth@100ms","event_type":"depthUpdate","event_time_ms":1788564451641,"raw_json":"{\"stream\":\"btcusdt@depth@100ms\",\"data\":{\"e\":\"depthUpdate\",\"E\":1788564451641,\"T\":1788564451639,\"s\":\"BTCUSDT\",\"ps\":\"BTCUSDT\",\"U\":11478296285705,\"u\":11478296292594,\"pu\":11478296285695,\"b\":[[\"1000.00\",\"24.754\"],[\"29316.80\",\"0.070\"],[\"29416.80\",\"1.820\"],[\"29516.80\",\"0.210\"],[\"63773.00\",\"0.000\"],[\"71745.10\",\"0.002\"],[\"78122.50\",\"0.161\"],[\"78205.40\",\"3.450\"],[\"78377.60\",\"1.344\"],[\"78919.60\",\"2.865\"],[\"79318.20\",\"3.160\"],[\"79497.60\",\"0.733\"],[\"79501.60\",\"0.628\"],[\"79529.50\",\"1.178\"],[\"79530.70\",\"1.004\"],[\"79533.50\",\"0.251\"],[\"79709.30\",\"1.000\"],[\"79711.20\",\"0.032\"],[\"79711.50\",\"0.030\"],[\"79716.80\",\"2.663\"]],\"a\":[[\"79716.90\",\"15.174\"],[\"79719.30\",\"0.002\"],[\"79792.60\",\"0.701\"],[\"79886.30\",\"0.090\"],[\"79945.60\",\"1.025\"],[\"80018.30\",\"0.001\"],[\"80078.80\",\"0.764\"],[\"80087.60\",\"1.147\"],[\"80514.10\",\"0.638\"]],\"st\":1}}"}
{"receive_ns":1788564451718055000,"stream":"btcusdt@depth@100ms","event_type":"depthUpdate","event_time_ms":1788564451743,"raw_json":"{\"stream\":\"btcusdt@depth@100ms\",\"data\":{\"e\":\"depthUpdate\",\"E\":1788564451743,\"T\":1788564451742,\"s\":\"BTCUSDT\",\"ps\":\"BTCUSDT\",\"U\":11478296292714,\"u\":11478296298290,\"pu\":11478296292594,\"b\":[[\"29316.80\",\"0.133\"],[\"29416.80\",\"1.876\"],[\"29516.80\",\"0.091\"],[\"63773.00\",\"0.000\"],[\"71745.10\",\"0.002\"],[\"76528.10\",\"0.000\"],[\"78122.50\",\"0.158\"],[\"78690.80\",\"3.425\"],[\"78847.90\",\"1.138\"],[\"78919.60\",\"2.865\"],[\"78959.50\",\"1.243\"],[\"79320.20\",\"0.000\"],[\"79499.10\",\"0.000\"],[\"79531.50\",\"0.707\"],[\"79594.30\",\"0.701\"],[\"79709.40\",\"0.174\"],[\"79712.20\",\"0.002\"]],\"a\":[[\"79747.30\",\"0.066\"],[\"79792.60\",\"0.451\"],[\"79797.60\",\"0.092\"],[\"79840.30\",\"0.351\"],[\"80087.60\",\"1.147\"],[\"80514.10\",\"0.638\"],[\"81311.20\",\"0.033\"]],\"st\":1}}"}
{"receive_ns":1788564451827056000,"stream":"btcusdt@depth@100ms","event_type":"depthUpdate","event_time_ms":1788564451845,"raw_json":"{\"stream\":\"btcusdt@depth@100ms\",\"data\":{\"e\":\"depthUpdate\",\"E\":1788564451845,\"T\":1788564451843,\"s\":\"BTCUSDT\",\"ps\":\"BTCUSDT\",\"U\":11478296298563,\"u\":11478296305528,\"pu\":11478296298290,\"b\":[[\"1000.00\",\"24.754\"],[\"29316.80\",\"0.217\"],[\"29416.80\",\"1.883\"],[\"29516.80\",\"0.000\"],[\"71745.10\",\"0.002\"],[\"76528.10\",\"0.002\"],[\"78600.80\",\"10.189\"],[\"78919.60\",\"2.865\"],[\"79320.20\",\"0.140\"],[\"79497.60\",\"0.502\"],[\"79529.50\",\"0.000\"],[\"79530.70\",\"0.001\"],[\"79533.50\",\"0.251\"]],\"a\":[[\"79718.20\",\"0.030\"],[\"79719.10\",\"1.419\"],[\"79792.60\",\"0.451\"],[\"79886.30\",\"0.000\"],[\"80078.80\",\"0.002\"],[\"80087.60\",\"0.579\"],[\"80094.90\",\"1.869\"],[\"80294.10\",\"2.090\"],[\"80514.10\",\"0.638\"],[\"80713.40\",\"4.287\"],[\"80828.00\",\"0.000\"]],\"st\":1}}"}
{"receive_ns":1788564451837089000,"stream":"btcusdt@bookTicker","event_type":"bookTicker","event_time_ms":1788564451856,"raw_json":"{\"stream\":\"btcusdt@bookTicker\",\"data\":{\"e\":\"bookTicker\",\"u\":11478296306253,\"s\":\"BTCUSDT\",\"ps\":\"BTCUSDT\",\"b\":\"79716.80\",\"B\":\"2.663\",\"a\":\"79716.90\",\"A\":\"15.164\",\"T\":1788564451855,\"E\":1788564451856,\"st\":1}}"}
{"receive_ns":1788564451842554000,"stream":"btcusdt@bookTicker","event_type":"bookTicker","event_time_ms":1788564451859,"raw_json":"{\"stream\":\"btcusdt@bookTicker\",\"data\":{\"e\":\"bookTicker\",\"u\":11478296306494,\"s\":\"BTCUSDT\",\"ps\":\"BTCUSDT\",\"b\":\"79716.80\",\"B\":\"2.663\",\"a\":\"79716.90\",\"A\":\"15.175\",\"T\":1788564451858,\"E\":1788564451859,\"st\":1}}"}
{"receive_ns":1788564451927324000,"stream":"btcusdt@depth@100ms","event_type":"depthUpdate","event_time_ms":1788564451947,"raw_json":"{\"stream\":\"btcusdt@depth@100ms\",\"data\":{\"e\":\"depthUpdate\",\"E\":1788564451947,\"T\":1788564451945,\"s\":\"BTCUSDT\",\"ps\":\"BTCUSDT\",\"U\":11478296305643,\"u\":11478296312129,\"pu\":11478296305528,\"b\":[[\"1000.00\",\"24.754\"],[\"29316.80\",\"0.399\"],[\"29416.80\",\"1.701\"],[\"71745.10\",\"0.002\"],[\"76528.10\",\"0.000\"],[\"78687.70\",\"0.476\"],[\"78919.60\",\"2.865\"],[\"79318.20\",\"3.160\"],[\"79497.60\",\"0.733\"],[\"79507.00\",\"0.000\"],[\"79507.10\",\"4.871\"],[\"79529.50\",\"1.178\"],[\"79530.70\",\"1.004\"],[\"79531.50\",\"0.507\"],[\"79594.30\",\"0.571\"],[\"79696.80\",\"0.292\"]],\"a\":[[\"79716.90\",\"15.175\"],[\"79792.60\",\"0.502\"],[\"79840.30\",\"0.234\"],[\"79886.30\",\"0.090\"],[\"79927.60\",\"5.218\"],[\"80078.80\",\"0.764\"],[\"80087.60\",\"1.147\"],[\"80514.10\",\"0.638\"],[\"80591.40\",\"1.732\"]],\"st\":1}}"}
{"receive_ns":1788564452035131000,"stream":"btcusdt@depth@100ms","event_type":"depthUpdate","event_time_ms":1788564452049,"raw_json":"{\"stream\":\"btcusdt@depth@100ms\",\"data\":{\"e\":\"depthUpdate\",\"E\":1788564452049,\"T\":1788564452045,\"s\":\"BTCUSDT\",\"ps\":\"BTCUSDT\",\"U\":11478296312247,\"u\":11478296318506,\"pu\":11478296312129,\"b\":[[\"29316.80\",\"0.574\"],[\"29416.80\",\"1.526\"],[\"63773.00\",\"0.000\"],[\"71745.10\",\"0.002\"],[\"76528.10\",\"0.002\"],[\"79320.20\",\"0.140\"],[\"79501.60\",\"0.828\"],[\"79507.10\",\"6.867\"],[\"79533.50\",\"0.001\"],[\"79702.50\",\"0.004\"]],\"a\":[[\"79790.30\",\"0.059\"],[\"79791.50\",\"0.005\"],[\"79792.60\",\"0.701\"],[\"79927.60\",\"7.707\"],[\"79938.70\",\"8.482\"],[\"80087.60\",\"0.992\"],[\"80493.40\",\"5.273\"],[\"80514.10\",\"0.638\"],[\"80646.20\",\"18.420\"]],\"st\":1}}"}
{"receive_ns":1788564452059826000,"stream":"btcusdt@bookTicker","event_type":"bookTicker","event_time_ms":1788564452066,"raw_json":"{\"stream\":\"btcusdt@bookTicker\",\"data\":{\"e\":\"bookTicker\",\"u\":11478296319809,\"s\":\"BTCUSDT\",\"ps\":\"BTCUSDT\",\"b\":\"79716.80\",\"B\":\"2.663\",\"a\":\"79716.90\",\"A\":\"15.194\",\"T\":1788564452065,\"E\":1788564452066,\"st\":1}}"}
{"receive_ns":1788564452082528000,"stream":"btcusdt@bookTicker","event_type":"bookTicker","event_time_ms":1788564452066,"raw_json":"{\"stream\":\"btcusdt@bookTicker\",\"data\":{\"e\":\"bookTicker\",\"u\":11478296319870,\"s\":\"BTCUSDT\",\"ps\":\"BTCUSDT\",\"b\":\"79716.80\",\"B\":\"2.663\",\"a\":\"79716.90\",\"A\":\"15.175\",\"T\":1788564452066,\"E\":1788564452066,\"st\":1}}"}
{"receive_ns":1788564452115842000,"stream":"btcusdt@bookTicker","event_type":"bookTicker","event_time_ms":1788564452083,"raw_json":"{\"stream\":\"btcusdt@bookTicker\",\"data\":{\"e\":\"bookTicker\",\"u\":11478296320772,\"s\":\"BTCUSDT\",\"ps\":\"BTCUSDT\",\"b\":\"79716.80\",\"B\":\"2.663\",\"a\":\"79716.90\",\"A\":\"15.194\",\"T\":1788564452083,\"E\":1788564452083,\"st\":1}}"}
{"receive_ns":1788564452121242000,"stream":"btcusdt@bookTicker","event_type":"bookTicker","event_time_ms":1788564452084,"raw_json":"{\"stream\":\"btcusdt@bookTicker\",\"data\":{\"e\":\"bookTicker\",\"u\":11478296320815,\"s\":\"BTCUSDT\",\"ps\":\"BTCUSDT\",\"b\":\"79716.80\",\"B\":\"2.663\",\"a\":\"79716.90\",\"A\":\"15.175\",\"T\":1788564452084,\"E\":1788564452084,\"st\":1}}"}
{"receive_ns":1788564452127836000,"stream":"btcusdt@bookTicker","event_type":"bookTicker","event_time_ms":1788564452106,"raw_json":"{\"stream\":\"btcusdt@bookTicker\",\"data\":{\"e\":\"bookTicker\",\"u\":11478296322398,\"s\":\"BTCUSDT\",\"ps\":\"BTCUSDT\",\"b\":\"79716.80\",\"B\":\"2.663\",\"a\":\"79716.90\",\"A\":\"15.177\",\"T\":1788564452106,\"E\":1788564452106,\"st\":1}}"}
{"receive_ns":1788564452128045000,"stream":"btcusdt@bookTicker","event_type":"bookTicker","event_time_ms":1788564452106,"raw_json":"{\"stream\":\"btcusdt@bookTicker\",\"data\":{\"e\":\"bookTicker\",\"u\":11478296322429,\"s\":\"BTCUSDT\",\"ps\":\"BTCUSDT\",\"b\":\"79716.80\",\"B\":\"2.663\",\"a\":\"79716.90\",\"A\":\"15.196\",\"T\":1788564452106,\"E\":1788564452106,\"st\":1}}"}
{"receive_ns":1788564452135758000,"stream":"btcusdt@bookTicker","event_type":"bookTicker","event_time_ms":1788564452107,"raw_json":"{\"stream\":\"btcusdt@bookTicker\",\"data\":{\"e\":\"bookTicker\",\"u\":11478296322485,\"s\":\"BTCUSDT\",\"ps\":\"BTCUSDT\",\"b\":\"79716.80\",\"B\":\"2.663\",\"a\":\"79716.90\",\"A\":\"15.194\",\"T\":1788564452106,\"E\":1788564452107,\"st\":1}}"}
{"receive_ns":1788564452141059000,"stream":"btcusdt@bookTicker","event_type":"bookTicker","event_time_ms":1788564452107,"raw_json":"{\"stream\":\"btcusdt@bookTicker\",\"data\":{\"e\":\"bookTicker\",\"u\":11478296322486,\"s\":\"BTCUSDT\",\"ps\":\"BTCUSDT\",\"b\":\"79716.80\",\"B\":\"2.663\",\"a\":\"79716.90\",\"A\":\"15.175\",\"T\":1788564452106,\"E\":1788564452107,\"st\":1}}"}
{"receive_ns":1788564452141544000,"stream":"btcusdt@depth@100ms","event_type":"depthUpdate","event_time_ms":1788564452151,"raw_json":"{\"stream\":\"btcusdt@depth@100ms\",\"data\":{\"e\":\"depthUpdate\",\"E\":1788564452151,\"T\":1788564452150,\"s\":\"BTCUSDT\",\"ps\":\"BTCUSDT\",\"U\":11478296318746,\"u\":11478296325425,\"pu\":11478296318506,\"b\":[[\"1000.00\",\"24.754\"],[\"29316.80\",\"0.756\"],[\"29416.80\",\"1.344\"],[\"63774.00\",\"0.000\"],[\"71745.10\",\"0.002\"],[\"76061.90\",\"0.002\"],[\"78122.50\",\"0.155\"],[\"78552.20\",\"0.000\"],[\"78919.60\",\"2.865\"],[\"79497.60\",\"0.733\"],[\"79522.20\",\"0.004\"],[\"79529.50\",\"1.003\"],[\"79530.70\",\"1.004\"],[\"79698.90\",\"0.240\"],[\"79699.60\",\"0.001\"],[\"79700.60\",\"0.002\"],[\"79702.50\",\"0.000\"],[\"79709.40\",\"0.172\"],[\"79711.50\",\"0.004\"],[\"79711.60\",\"0.026\"],[\"79714.40\",\"0.002\"],[\"79715.30\",\"0.001\"],[\"79715.50\",\"0.002\"],[\"79715.80\",\"0.315\"],[\"79715.90\",\"0.003\"]],\"a\":[[\"79716.90\",\"15.175\"],[\"79717.90\",\"0.006\"],[\"79719.20\",\"0.018\"],[\"79722.10\",\"0.008\"],[\"79786.40\",\"0.013\"],[\"79792.60\",\"0.701\"],[\"79886.30\",\"0.090\"],[\"80078.80\",\"0.764\"],[\"80087.60\",\"1.147\"],[\"80115.50\",\"1.372\"],[\"80514.10\",\"0.638\"],[\"80649.60\",\"0.432\"]],\"st\":1}}"}
{"receive_ns":1788564452141808000,"stream":"btcusdt@bookTicker","event_type":"bookTicker","event_time_ms":1788564452171,"raw_json":"{\"stream\":\"btcusdt@bookTicker\",\"data\":{\"e\":\"bookTicker\",\"u\":11478296326867,\"s\":\"BTCUSDT\",\"ps\":\"BTCUSDT\",\"b\":\"79716.80\",\"B\":\"2.663\",\"a\":\"79716.90\",\"A\":\"15.164\",\"T\":1788564452171,\"E\":1788564452171,\"st\":1}}"}
{"receive_ns":1788564452141976000,"stream":"btcusdt@trade","event_type":"trade","event_time_ms":1788564452171,"raw_json":"{\"stream\":\"btcusdt@trade\",\"data\":{\"e\":\"trade\",\"E\":1788564452171,\"T\":1788564452171,\"s\":\"BTCUSDT\",\"t\":8054096467,\"p\":\"79716.90\",\"q\":\"0.011\",\"X\":\"MARKET\",\"m\":false,\"st\":1}}"}
{"receive_ns":1788564452153683000,"stream":"btcusdt@bookTicker","event_type":"bookTicker","event_time_ms":1788564452172,"raw_json":"{\"stream\":\"btcusdt@bookTicker\",\"data\":{\"e\":\"bookTicker\",\"u\":11478296327019,\"s\":\"BTCUSDT\",\"ps\":\"BTCUSDT\",\"b\":\"79716.80\",\"B\":\"2.663\",\"a\":\"79716.90\",\"A\":\"15.166\",\"T\":1788564452172,\"E\":1788564452172,\"st\":1}}"}
{"receive_ns":1788564452166608000,"stream":"btcusdt@bookTicker","event_type":"bookTicker","event_time_ms":1788564452172,"raw_json":"{\"stream\":\"btcusdt@bookTicker\",\"data\":{\"e\":\"bookTicker\",\"u\":11478296327033,\"s\":\"BTCUSDT\",\"ps\":\"BTCUSDT\",\"b\":\"79716.80\",\"B\":\"2.663\",\"a\":\"79716.90\",\"A\":\"15.170\",\"T\":1788564452172,\"E\":1788564452172,\"st\":1}}"}
{"receive_ns":1788564452166816000,"stream":"btcusdt@bookTicker","event_type":"bookTicker","event_time_ms":1788564452172,"raw_json":"{\"stream\":\"btcusdt@bookTicker\",\"data\":{\"e\":\"bookTicker\",\"u\":11478296327048,\"s\":\"BTCUSDT\",\"ps\":\"BTCUSDT\",\"b\":\"79716.80\",\"B\":\"2.663\",\"a\":\"79716.90\",\"A\":\"15.189\",\"T\":1788564452172,\"E\":1788564452172,\"st\":1}}"}
{"receive_ns":1788564452173405000,"stream":"btcusdt@bookTicker","event_type":"bookTicker","event_time_ms":1788564452173,"raw_json":"{\"stream\":\"btcusdt@bookTicker\",\"data\":{\"e\":\"bookTicker\",\"u\":11478296327103,\"s\":\"BTCUSDT\",\"ps\":\"BTCUSDT\",\"b\":\"79716.80\",\"B\":\"2.663\",\"a\":\"79716.90\",\"A\":\"15.187\",\"T\":1788564452173,\"E\":1788564452173,\"st\":1}}"}
{"receive_ns":1788564452173656000,"stream":"btcusdt@bookTicker","event_type":"bookTicker","event_time_ms":1788564452173,"raw_json":"{\"stream\":\"btcusdt@bookTicker\",\"data\":{\"e\":\"bookTicker\",\"u\":11478296327108,\"s\":\"BTCUSDT\",\"ps\":\"BTCUSDT\",\"b\":\"79716.80\",\"B\":\"2.663\",\"a\":\"79716.90\",\"A\":\"15.168\",\"T\":1788564452173,\"E\":1788564452173,\"st\":1}}"}
{"receive_ns":1788564452234775000,"stream":"btcusdt@depth@100ms","event_type":"depthUpdate","event_time_ms":1788564452253,"raw_json":"{\"stream\":\"btcusdt@depth@100ms\",\"data\":{\"e\":\"depthUpdate\",\"E\":1788564452253,\"T\":1788564452249,\"s\":\"BTCUSDT\",\"ps\":\"BTCUSDT\",\"U\":11478296325588,\"u\":11478296331549,\"pu\":11478296325425,\"b\":[[\"1000.00\",\"24.754\"],[\"29316.80\",\"0.931\"],[\"29416.80\",\"1.169\"],[\"63773.40\",\"0.000\"],[\"71745.10\",\"0.002\"],[\"76528.10\",\"0.000\"],[\"78122.50\",\"0.158\"],[\"78919.60\",\"2.865\"],[\"79318.20\",\"3.159\"],[\"79320.20\",\"0.140\"],[\"79387.90\",\"0.013\"],[\"79501.60\",\"0.628\"],[\"79512.70\",\"0.000\"],[\"79514.00\",\"0.033\"],[\"79522.20\",\"0.036\"],[\"79531.50\",\"0.206\"],[\"79644.10\",\"5.217\"],[\"79693.10\",\"0.003\"],[\"79698.90\",\"0.641\"],[\"79699.30\",\"0.079\"],[\"79699.60\",\"0.000\"],[\"79700.60\",\"0.003\"],[\"79710.30\",\"0.027\"],[\"79711.20\",\"0.006\"],[\"79711.60\",\"0.000\"],[\"79711.70\",\"0.026\"],[\"79712.70\",\"0.026\"],[\"79715.20\",\"0.001\"]],\"a\":[[\"79716.90\",\"15.168\"],[\"79733.00\",\"0.630\"],[\"79792.60\",\"0.701\"],[\"79792.90\",\"6.176\"],[\"79814.00\",\"0.198\"],[\"80087.60\",\"1.147\"],[\"80514.10\",\"0.638\"]],\"st\":1}}"}
{"receive_ns":1788564452247512000,"stream":"btcusdt@bookTicker","event_type":"bookTicker","event_time_ms":1788564452270,"raw_json":"{\"stream\":\"btcusdt@bookTicker\",\"data\":{\"e\":\"bookTicker\",\"u\":11478296332595,\"s\":\"BTCUSDT\",\"ps\":\"BTCUSDT\",\"b\":\"79716.80\",\"B\":\"2.663\",\"a\":\"79716.90\",\"A\":\"15.187\",\"T\":1788564452270,\"E\":1788564452270,\"st\":1}}"}
{"receive_ns":1788564452254140000,"stream":"btcusdt@bookTicker","event_type":"bookTicker","event_time_ms":1788564452271,"raw_json":"{\"stream\":\"btcusdt@bookTicker\",\"data\":{\"e\":\"bookTicker\",\"u\":11478296332647,\"s\":\"BTCUSDT\",\"ps\":\"BTCUSDT\",\"b\":\"79716.80\",\"B\":\"2.663\",\"a\":\"79716.90\",\"A\":\"15.168\",\"T\":1788564452271,\"E\":1788564452271,\"st\":1}}"}
{"receive_ns":1788564452275159000,"stream":"btcusdt@bookTicker","event_type":"bookTicker","event_time_ms":1788564452293,"raw_json":"{\"stream\":\"btcusdt@bookTicker\",\"data\":{\"e\":\"bookTicker\",\"u\":11478296333840,\"s\":\"BTCUSDT\",\"ps\":\"BTCUSDT\",\"b\":\"79716.80\",\"B\":\"2.552\",\"a\":\"79716.90\",\"A\":\"15.168\",\"T\":1788564452293,\"E\":1788564452293,\"st\":1}}"}
{"receive_ns":1788564452275417000,"stream":"btcusdt@bookTicker","event_type":"bookTicker","event_time_ms":1788564452298,"raw_json":"{\"stream\":\"btcusdt@bookTicker\",\"data\":{\"e\":\"bookTicker\",\"u\":11478296334081,\"s\":\"BTCUSDT\",\"ps\":\"BTCUSDT\",\"b\":\"79716.80\",\"B\":\"2.552\",\"a\":\"79716.90\",\"A\":\"15.170\",\"T\":1788564452298,\"E\":1788564452298,\"st\":1}}"}
{"receive_ns":1788564452275639000,"stream":"btcusdt@bookTicker","event_type":"bookTicker","event_time_ms":1788564452298,"raw_json":"{\"stream\":\"btcusdt@bookTicker\",\"data\":{\"e\":\"bookTicker\",\"u\":11478296334116,\"s\":\"BTCUSDT\",\"ps\":\"BTCUSDT\",\"b\":\"79716.80\",\"B\":\"2.552\",\"a\":\"79716.90\",\"A\":\"15.189\",\"T\":1788564452298,\"E\":1788564452298,\"st\":1}}"}
{"receive_ns":1788564452275867000,"stream":"btcusdt@bookTicker","event_type":"bookTicker","event_time_ms":1788564452298,"raw_json":"{\"stream\":\"btcusdt@bookTicker\",\"data\":{\"e\":\"bookTicker\",\"u\":11478296334166,\"s\":\"BTCUSDT\",\"ps\":\"BTCUSDT\",\"b\":\"79716.80\",\"B\":\"2.552\",\"a\":\"79716.90\",\"A\":\"15.187\",\"T\":1788564452298,\"E\":1788564452298,\"st\":1}}"}
{"receive_ns":1788564452281567000,"stream":"btcusdt@bookTicker","event_type":"bookTicker","event_time_ms":1788564452298,"raw_json":"{\"stream\":\"btcusdt@bookTicker\",\"data\":{\"e\":\"bookTicker\",\"u\":11478296334168,\"s\":\"BTCUSDT\",\"ps\":\"BTCUSDT\",\"b\":\"79716.80\",\"B\":\"2.552\",\"a\":\"79716.90\",\"A\":\"15.168\",\"T\":1788564452298,\"E\":1788564452298,\"st\":1}}"}
{"receive_ns":1788564452281812000,"stream":"btcusdt@bookTicker","event_type":"bookTicker","event_time_ms":1788564452306,"raw_json":"{\"stream\":\"btcusdt@bookTicker\",\"data\":{\"e\":\"bookTicker\",\"u\":11478296334554,\"s\":\"BTCUSDT\",\"ps\":\"BTCUSDT\",\"b\":\"79716.80\",\"B\":\"2.663\",\"a\":\"79716.90\",\"A\":\"15.168\",\"T\":1788564452306,\"E\":1788564452306,\"st\":1}}"}
{"receive_ns":1788564452285540000,"stream":"btcusdt@bookTicker","event_type":"bookTicker","event_time_ms":1788564452307,"raw_json":"{\"stream\":\"btcusdt@bookTicker\",\"data\":{\"e\":\"bookTicker\",\"u\":11478296334617,\"s\":\"BTCUSDT\",\"ps\":\"BTCUSDT\",\"b\":\"79716.80\",\"B\":\"2.661\",\"a\":\"79716.90\",\"A\":\"15.168\",\"T\":1788564452307,\"E\":1788564452307,\"st\":1}}"}
{"receive_ns":1788564452305100000,"stream":"btcusdt@bookTicker","event_type":"bookTicker","event_time_ms":1788564452324,"raw_json":"{\"stream\":\"btcusdt@bookTicker\",\"data\":{\"e\":\"bookTicker\",\"u\":11478296335720,\"s\":\"BTCUSDT\",\"ps\":\"BTCUSDT\",\"b\":\"79716.80\",\"B\":\"2.661\",\"a\":\"79716.90\",\"A\":\"15.170\",\"T\":1788564452324,\"E\":1788564452324,\"st\":1}}"}
{"receive_ns":1788564452311350000,"stream":"btcusdt@bookTicker","event_type":"bookTicker","event_time_ms":1788564452324,"raw_json":"{\"stream\":\"btcusdt@bookTicker\",\"data\":{\"e\":\"bookTicker\",\"u\":11478296335733,\"s\":\"BTCUSDT\",\"ps\":\"BTCUSDT\",\"b\":\"79716.80\",\"B\":\"2.661\",\"a\":\"79716.90\",\"A\":\"15.189\",\"T\":1788564452324,\"E\":1788564452324,\"st\":1}}"}
{"receive_ns":1788564452311577000,"stream":"btcusdt@bookTicker","event_type":"bookTicker","event_time_ms":1788564452325,"raw_json":"{\"stream\":\"btcusdt@bookTicker\",\"data\":{\"e\":\"bookTicker\",\"u\":11478296335777,\"s\":\"BTCUSDT\",\"ps\":\"BTCUSDT\",\"b\":\"79716.80\",\"B\":\"2.661\",\"a\":\"79716.90\",\"A\":\"15.187\",\"T\":1788564452325,\"E\":1788564452325,\"st\":1}}"}
{"receive_ns":1788564452311755000,"stream":"btcusdt@bookTicker","event_type":"bookTicker","event_time_ms":1788564452325,"raw_json":"{\"stream\":\"btcusdt@bookTicker\",\"data\":{\"e\":\"bookTicker\",\"u\":11478296335784,\"s\":\"BTCUSDT\",\"ps\":\"BTCUSDT\",\"b\":\"79716.80\",\"B\":\"2.661\",\"a\":\"79716.90\",\"A\":\"15.168\",\"T\":1788564452325,\"E\":1788564452325,\"st\":1}}"}
{"receive_ns":1788564452328954000,"stream":"btcusdt@bookTicker","event_type":"bookTicker","event_time_ms":1788564452325,"raw_json":"{\"stream\":\"btcusdt@bookTicker\",\"data\":{\"e\":\"bookTicker\",\"u\":11478296335847,\"s\":\"BTCUSDT\",\"ps\":\"BTCUSDT\",\"b\":\"79716.80\",\"B\":\"2.663\",\"a\":\"79716.90\",\"A\":\"15.168\",\"T\":1788564452325,\"E\":1788564452325,\"st\":1}}"}
{"receive_ns":1788564452334716000,"stream":"btcusdt@depth@100ms","event_type":"depthUpdate","event_time_ms":1788564452355,"raw_json":"{\"stream\":\"btcusdt@depth@100ms\",\"data\":{\"e\":\"depthUpdate\",\"E\":1788564452355,\"T\":1788564452354,\"s\":\"BTCUSDT\",\"ps\":\"BTCUSDT\",\"U\":11478296331750,\"u\":11478296337166,\"pu\":11478296331549,\"b\":[[\"29316.80\",\"1.113\"],[\"29416.80\",\"0.987\"],[\"63774.00\",\"0.000\"],[\"71745.10\",\"0.002\"],[\"76528.10\",\"0.002\"],[\"78739.90\",\"12.366\"],[\"78919.60\",\"2.865\"],[\"79297.20\",\"0.000\"],[\"79298.20\",\"0.090\"],[\"79497.60\",\"0.733\"],[\"79517.50\",\"0.002\"],[\"79529.50\",\"1.103\"],[\"79530.70\",\"1.004\"],[\"79533.50\",\"0.251\"],[\"79621.10\",\"0.040\"],[\"79698.90\",\"0.140\"],[\"79699.20\",\"0.069\"],[\"79699.90\",\"0.001\"],[\"79700.60\",\"0.003\"],[\"79715.10\",\"0.000\"],[\"79715.70\",\"0.315\"],[\"79715.80\",\"0.000\"],[\"79715.90\",\"0.003\"],[\"79716.80\",\"2.663\"]],\"a\":[[\"79716.90\",\"15.168\"],[\"79719.00\",\"2.504\"],[\"79772.80\",\"0.316\"],[\"79792.60\",\"0.701\"],[\"79836.50\",\"0.003\"],[\"79886.30\",\"0.090\"],[\"80078.80\",\"0.764\"],[\"80087.60\",\"1.147\"],[\"80115.50\",\"1.373\"],[\"80514.10\",\"0.638\"],[\"80679.80\",\"0.632\"],[\"80815.30\",\"1.840\"]],\"st\":1}}"}
{"receive_ns":1788564452369415000,"stream":"btcusdt@bookTicker","event_type":"bookTicker","event_time_ms":1788564452393,"raw_json":"{\"stream\":\"btcusdt@bookTicker\",\"data\":{\"e\":\"bookTicker\",\"u\":11478296339317,\"s\":\"BTCUSDT\",\"ps\":\"BTCUSDT\",\"b\":\"79716.80\",\"B\":\"2.650\",\"a\":\"79716.90\",\"A\":\"15.168\",\"T\":1788564452393,\"E\":1788564452393,\"st\":1}}"}
{"receive_ns":1788564452369698000,"stream":"btcusdt@trade","event_type":"trade","event_time_ms":1788564452393,"raw_json":"{\"stream\":\"btcusdt@trade\",\"data\":{\"e\":\"trade\",\"E\":1788564452393,\"T\":1788564452393,\"s\":\"BTCUSDT\",\"t\":8054096468,\"p\":\"79716.80\",\"q\":\"0.013\",\"X\":\"MARKET\",\"m\":true,\"st\":1}}"}
{"receive_ns":1788564452375128000,"stream":"btcusdt@bookTicker","event_type":"bookTicker","event_time_ms":1788564452394,"raw_json":"{\"stream\":\"btcusdt@bookTicker\",\"data\":{\"e\":\"bookTicker\",\"u\":11478296339462,\"s\":\"BTCUSDT\",\"ps\":\"BTCUSDT\",\"b\":\"79716.80\",\"B\":\"2.650\",\"a\":\"79716.90\",\"A\":\"15.170\",\"T\":1788564452394,\"E\":1788564452394,\"st\":1}}"}
{"receive_ns":1788564452375329000,"stream":"btcusdt@bookTicker","event_type":"bookTicker","event_time_ms":1788564452394,"raw_json":"{\"stream\":\"btcusdt@bookTicker\",\"data\":{\"e\":\"bookTicker\",\"u\":11478296339477,\"s\":\"BTCUSDT\",\"ps\":\"BTCUSDT\",\"b\":\"79716.80\",\"B\":\"2.650\",\"a\":\"79716.90\",\"A\":\"15.189\",\"T\":1788564452394,\"E\":1788564452394,\"st\":1}}"}
{"receive_ns":1788564452380847000,"stream":"btcusdt@bookTicker","event_type":"bookTicker","event_time_ms":1788564452395,"raw_json":"{\"stream\":\"btcusdt@bookTicker\",\"data\":{\"e\":\"bookTicker\",\"u\":11478296339647,\"s\":\"BTCUSDT\",\"ps\":\"BTCUSDT\",\"b\":\"79716.80\",\"B\":\"2.650\",\"a\":\"79716.90\",\"A\":\"15.170\",\"T\":1788564452395,\"E\":1788564452395,\"st\":1}}"}
{"receive_ns":1788564452381064000,"stream":"btcusdt@bookTicker","event_type":"bookTicker","event_time_ms":1788564452395,"raw_json":"{\"stream\":\"btcusdt@bookTicker\",\"data\":{\"e\":\"bookTicker\",\"u\":11478296339667,\"s\":\"BTCUSDT\",\"ps\":\"BTCUSDT\",\"b\":\"79716.80\",\"B\":\"2.650\",\"a\":\"79716.90\",\"A\":\"15.168\",\"T\":1788564452395,\"E\":1788564452395,\"st\":1}}"}
{"receive_ns":1788564452386930000,"stream":"btcusdt@bookTicker","event_type":"bookTicker","event_time_ms":1788564452405,"raw_json":"{\"stream\":\"btcusdt@bookTicker\",\"data\":{\"e\":\"bookTicker\",\"u\":11478296340296,\"s\":\"BTCUSDT\",\"ps\":\"BTCUSDT\",\"b\":\"79716.80\",\"B\":\"2.650\",\"a\":\"79716.90\",\"A\":\"15.170\",\"T\":1788564452405,\"E\":1788564452405,\"st\":1}}"}
{"receive_ns":1788564452387132000,"stream":"btcusdt@bookTicker","event_type":"bookTicker","event_time_ms":1788564452406,"raw_json":"{\"stream\":\"btcusdt@bookTicker\",\"data\":{\"e\":\"bookTicker\",\"u\":11478296340326,\"s\":\"BTCUSDT\",\"ps\":\"BTCUSDT\",\"b\":\"79716.80\",\"B\":\"2.650\",\"a\":\"79716.90\",\"A\":\"15.189\",\"T\":1788564452405,\"E\":1788564452406,\"st\":1}}"}
{"receive_ns":1788564452387375000,"stream":"btcusdt@bookTicker","event_type":"bookTicker","event_time_ms":1788564452406,"raw_json":"{\"stream\":\"btcusdt@bookTicker\",\"data\":{\"e\":\"bookTicker\",\"u\":11478296340400,\"s\":\"BTCUSDT\",\"ps\":\"BTCUSDT\",\"b\":\"79716.80\",\"B\":\"2.650\",\"a\":\"79716.90\",\"A\":\"15.187\",\"T\":1788564452406,\"E\":1788564452406,\"st\":1}}"}
{"receive_ns":1788564452387574000,"stream":"btcusdt@bookTicker","event_type":"bookTicker","event_time_ms":1788564452406,"raw_json":"{\"stream\":\"btcusdt@bookTicker\",\"data\":{\"e\":\"bookTicker\",\"u\":11478296340402,\"s\":\"BTCUSDT\",\"ps\":\"BTCUSDT\",\"b\":\"79716.80\",\"B\":\"2.650\",\"a\":\"79716.90\",\"A\":\"15.168\",\"T\":1788564452406,\"E\":1788564452406,\"st\":1}}"}
{"receive_ns":1788564452397260000,"stream":"btcusdt@bookTicker","event_type":"bookTicker","event_time_ms":1788564452413,"raw_json":"{\"stream\":\"btcusdt@bookTicker\",\"data\":{\"e\":\"bookTicker\",\"u\":11478296340767,\"s\":\"BTCUSDT\",\"ps\":\"BTCUSDT\",\"b\":\"79716.80\",\"B\":\"2.650\",\"a\":\"79716.90\",\"A\":\"15.156\",\"T\":1788564452412,\"E\":1788564452413,\"st\":1}}"}
{"receive_ns":1788564452397541000,"stream":"btcusdt@bookTicker","event_type":"bookTicker","event_time_ms":1788564452418,"raw_json":"{\"stream\":\"btcusdt@bookTicker\",\"data\":{\"e\":\"bookTicker\",\"u\":11478296341121,\"s\":\"BTCUSDT\",\"ps\":\"BTCUSDT\",\"b\":\"79716.80\",\"B\":\"2.650\",\"a\":\"79716.90\",\"A\":\"15.172\",\"T\":1788564452418,\"E\":1788564452418,\"st\":1}}"}
{"receive_ns":1788564452408874000,"stream":"btcusdt@bookTicker","event_type":"bookTicker","event_time_ms":1788564452418,"raw_json":"{\"stream\":\"btcusdt@bookTicker\",\"data\":{\"e\":\"bookTicker\",\"u\":11478296341138,\"s\":\"BTCUSDT\",\"ps\":\"BTCUSDT\",\"b\":\"79716.80\",\"B\":\"2.631\",\"a\":\"79716.90\",\"A\":\"15.172\",\"T\":1788564452418,\"E\":1788564452418,\"st\":1}}"}
{"receive_ns":1788564452415131000,"stream":"btcusdt@bookTicker","event_type":"bookTicker","event_time_ms":1788564452421,"raw_json":"{\"stream\":\"btcusdt@bookTicker\",\"data\":{\"e\":\"bookTicker\",\"u\":11478296341326,\"s\":\"BTCUSDT\",\"ps\":\"BTCUSDT\",\"b\":\"79716.80\",\"B\":\"2.652\",\"a\":\"79716.90\",\"A\":\"15.172\",\"T\":1788564452421,\"E\":1788564452421,\"st\":1}}"}
{"receive_ns":1788564452415364000,"stream":"btcusdt@bookTicker","event_type":"bookTicker","event_time_ms":1788564452432,"raw_json":"{\"stream\":\"btcusdt@bookTicker\",\"data\":{\"e\":\"bookTicker\",\"u\":11478296341936,\"s\":\"BTCUSDT\",\"ps\":\"BTCUSDT\",\"b\":\"79716.80\",\"B\":\"2.652\",\"a\":\"79716.90\",\"A\":\"15.191\",\"T\":1788564452432,\"E\":1788564452432,\"st\":1}}"}
{"receive_ns":1788564452415609000,"stream":"btcusdt@bookTicker","event_type":"bookTicker","event_time_ms":1788564452432,"raw_json":"{\"stream\":\"btcusdt@bookTicker\",\"data\":{\"e\":\"bookTicker\",\"u\":11478296341976,\"s\":\"BTCUSDT\",\"ps\":\"BTCUSDT\",\"b\":\"79716.80\",\"B\":\"2.652\",\"a\":\"79716.90\",\"A\":\"15.193\",\"T\":1788564452432,\"E\":1788564452432,\"st\":1}}"}
{"receive_ns":1788564452415830000,"stream":"btcusdt@bookTicker","event_type":"bookTicker","event_time_ms":1788564452433,"raw_json":"{\"stream\":\"btcusdt@bookTicker\",\"data\":{\"e\":\"bookTicker\",\"u\":11478296342014,\"s\":\"BTCUSDT\",\"ps\":\"BTCUSDT\",\"b\":\"79716.80\",\"B\":\"2.652\",\"a\":\"79716.90\",\"A\":\"15.191\",\"T\":1788564452432,\"E\":1788564452433,\"st\":1}}"}
{"receive_ns":1788564452421487000,"stream":"btcusdt@bookTicker","event_type":"bookTicker","event_time_ms":1788564452433,"raw_json":"{\"stream\":\"btcusdt@bookTicker\",\"data\":{\"e\":\"bookTicker\",\"u\":11478296342015,\"s\":\"BTCUSDT\",\"ps\":\"BTCUSDT\",\"b\":\"79716.80\",\"B\":\"2.652\",\"a\":\"79716.90\",\"A\":\"15.172\",\"T\":1788564452432,\"E\":1788564452433,\"st\":1}}"}
{"receive_ns":1788564452434871000,"stream":"btcusdt@depth@100ms","event_type":"depthUpdate","event_time_ms":1788564452457,"raw_json":"{\"stream\":\"btcusdt@depth@100ms\",\"data\":{\"e\":\"depthUpdate\",\"E\":1788564452457,\"T\":1788564452455,\"s\":\"BTCUSDT\",\"ps\":\"BTCUSDT\",\"U\":11478296337270,\"u\":11478296343400,\"pu\":11478296337166,\"b\":[[\"1000.00\",\"24.754\"],[\"29316.80\",\"1.288\"],[\"29416.80\",\"0.812\"],[\"71745.10\",\"0.002\"],[\"76528.10\",\"0.000\"],[\"78226.10\",\"0.765\"],[\"78919.60\",\"2.865\"],[\"79058.70\",\"3.914\"],[\"79531.50\",\"0.206\"],[\"79533.50\",\"0.752\"],[\"79554.80\",\"0.089\"],[\"79554.90\",\"2.658\"],[\"79594.30\",\"0.001\"],[\"79594.40\",\"0.675\"],[\"79698.60\",\"1.793\"],[\"79698.90\",\"0.065\"],[\"79700.10\",\"0.007\"],[\"79700.60\",\"0.002\"],[\"79701.90\",\"0.270\"],[\"79711.80\",\"0.027\"],[\"79712.70\",\"0.000\"],[\"79715.40\",\"0.316\"],[\"79715.70\",\"0.003\"],[\"79715.90\",\"0.000\"],[\"79716.80\",\"2.652\"]],\"a\":[[\"79716.90\",\"15.172\"],[\"79739.40\",\"0.529\"],[\"79740.80\",\"0.367\"],[\"79792.60\",\"0.701\"],[\"79840.30\",\"0.351\"],[\"79879.70\",\"2.477\"],[\"79879.80\",\"0.125\"],[\"80087.60\",\"1.147\"],[\"80514.10\",\"0.638\"],[\"80555.60\",\"1.570\"],[\"80814.50\",\"1.482\"],[\"80817.90\",\"0.743\"],[\"80840.90\",\"0.682\"],[\"81311.20\",\"0.033\"]],\"st\":1}}"}
{"receive_ns":1788564452491931000,"stream":"btcusdt@bookTicker","event_type":"bookTicker","event_time_ms":1788564452517,"raw_json":"{\"stream\":\"btcusdt@bookTicker\",\"data\":{\"e\":\"bookTicker\",\"u\":11478296346728,\"s\":\"BTCUSDT\",\"ps\":\"BTCUSDT\",\"b\":\"79716.80\",\"B\":\"2.652\",\"a\":\"79716.90\",\"A\":\"15.191\",\"T\":1788564452517,\"E\":1788564452517,\"st\":1}}"}
{"receive_ns":1788564452504416000,"stream":"btcusdt@bookTicker","event_type":"bookTicker","event_time_ms":1788564452518,"raw_json":"{\"stream\":\"btcusdt@bookTicker\",\"data\":{\"e\":\"bookTicker\",\"u\":11478296346778,\"s\":\"BTCUSDT\",\"ps\":\"BTCUSDT\",\"b\":\"79716.80\",\"B\":\"2.652\",\"a\":\"79716.90\",\"A\":\"15.172\",\"T\":1788564452517,\"E\":1788564452518,\"st\":1}}"}
{"receive_ns":1788564452537692000,"stream":"btcusdt@depth@100ms","event_type":"depthUpdate","event_time_ms":1788564452559,"raw_json":"{\"stream\":\"btcusdt@depth@100ms\",\"data\":{\"e\":\"depthUpdate\",\"E\":1788564452559,\"T\":1788564452558,\"s\":\"BTCUSDT\",\"ps\":\"BTCUSDT\",\"U\":11478296343637,\"u\":11478296348608,\"pu\":11478296343400,\"b\":[[\"1000.00\",\"24.754\"],[\"29316.80\",\"1.470\"],[\"29416.80\",\"0.630\"],[\"71745.10\",\"0.002\"],[\"71782.00\",\"0.003\"],[\"76528.10\",\"0.002\"],[\"78919.60\",\"2.865\"],[\"79318.20\",\"3.158\"],[\"79320.20\",\"0.140\"],[\"79448.80\",\"0.028\"],[\"79465.60\",\"0.095\"],[\"79533.50\",\"0.752\"],[\"79682.00\",\"0.050\"],[\"79682.90\",\"0.000\"],[\"79689.10\",\"0.452\"],[\"79690.10\",\"0.469\"],[\"79693.60\",\"0.374\"],[\"79694.50\",\"0.000\"],[\"79695.10\",\"0.440\"],[\"79696.50\",\"0.361\"],[\"79709.50\",\"0.001\"],[\"79709.70\",\"0.000\"],[\"79712.00\",\"0.042\"],[\"79712.10\",\"0.028\"]],\"a\":[[\"79716.90\",\"15.172\"],[\"79733.50\",\"0.110\"],[\"79734.90\",\"0.372\"],[\"79735.70\",\"0.255\"],[\"79745.90\",\"0.001\"],[\"79747.00\",\"0.085\"],[\"79748.10\",\"0.139\"],[\"79792.60\",\"0.701\"],[\"80087.60\",\"1.147\"],[\"80115.50\",\"1.374\"],[\"80334.00\",\"4.598\"],[\"80514.10\",\"0.638\"]],\"st\":1}}"}
{"receive_ns":1788564452630373000,"stream":"btcusdt@bookTicker","event_type":"bookTicker","event_time_ms":1788564452653,"raw_json":"{\"stream\":\"btcusdt@bookTicker\",\"data\":{\"e\":\"bookTicker\",\"u\":11478296353464,\"s\":\"BTCUSDT\",\"ps\":\"BTCUSDT\",\"b\":\"79716.80\",\"B\":\"2.652\",\"a\":\"79716.90\",\"A\":\"15.191\",\"T\":1788564452652,\"E\":1788564452653,\"st\":1}}"}
{"receive_ns":1788564452630621000,"stream":"btcusdt@bookTicker","event_type":"bookTicker","event_time_ms":1788564452653,"raw_json":"{\"stream\":\"btcusdt@bookTicker\",\"data\":{\"e\":\"bookTicker\",\"u\":11478296353531,\"s\":\"BTCUSDT\",\"ps\":\"BTCUSDT\",\"b\":\"79716.80\",\"B\":\"2.652\",\"a\":\"79716.90\",\"A\":\"15.172\",\"T\":1788564452653,\"E\":1788564452653,\"st\":1}}"}
{"receive_ns":1788564452637268000,"stream":"btcusdt@depth@100ms","event_type":"depthUpdate","event_time_ms":1788564452661,"raw_json":"{\"stream\":\"btcusdt@depth@100ms\",\"data\":{\"e\":\"depthUpdate\",\"E\":1788564452661,\"T\":1788564452660,\"s\":\"BTCUSDT\",\"ps\":\"BTCUSDT\",\"U\":11478296348679,\"u\":11478296354182,\"pu\":11478296348608,\"b\":[[\"29316.80\",\"1.645\"],[\"29416.80\",\"0.455\"],[\"63773.00\",\"0.000\"],[\"71745.10\",\"0.002\"],[\"71782.00\",\"0.000\"],[\"75946.90\",\"0.003\"],[\"78760.20\",\"15.088\"],[\"78919.60\",\"2.865\"],[\"79497.60\",\"0.502\"],[\"79501.60\",\"0.859\"],[\"79529.50\",\"1.178\"],[\"79530.70\",\"1.004\"],[\"79531.50\",\"0.006\"],[\"79533.50\",\"0.251\"],[\"79594.40\",\"0.614\"],[\"79621.10\",\"0.038\"],[\"79645.00\",\"0.004\"],[\"79669.80\",\"0.000\"],[\"79671.30\",\"2.626\"],[\"79694.00\",\"0.005\"]],\"a\":[[\"79716.90\",\"15.172\"],[\"79720.00\",\"0.006\"],[\"79756.80\",\"0.728\"],[\"79772.80\",\"0.316\"],[\"79792.60\",\"0.502\"],[\"79840.30\",\"0.290\"],[\"79886.30\",\"0.090\"],[\"80078.80\",\"0.764\"],[\"80087.60\",\"0.729\"],[\"80514.10\",\"0.638\"],[\"80646.20\",\"17.192\"],[\"80673.50\",\"15.717\"],[\"80799.40\",\"0.618\"],[\"80872.80\",\"3.238\"],[\"83702.70\",\"0.004\"]],\"st\":1}}"}
{"receive_ns":1788564452637554000,"stream":"btcusdt@bookTicker","event_type":"bookTicker","event_time_ms":1788564452668,"raw_json":"{\"stream\":\"btcusdt@bookTicker\",\"data\":{\"e\":\"bookTicker\",\"u\":11478296354540,\"s\":\"BTCUSDT\",\"ps\":\"BTCUSDT\",\"b\":\"79716.80\",\"B\":\"2.652\",\"a\":\"79716.90\",\"A\":\"15.191\",\"T\":1788564452668,\"E\":1788564452668,\"st\":1}}"}
{"receive_ns":1788564452659844000,"stream":"btcusdt@bookTicker","event_type":"bookTicker","event_time_ms":1788564452669,"raw_json":"{\"stream\":\"btcusdt@bookTicker\",\"data\":{\"e\":\"bookTicker\",\"u\":11478296354609,\"s\":\"BTCUSDT\",\"ps\":\"BTCUSDT\",\"b\":\"79716.80\",\"B\":\"2.652\",\"a\":\"79716.90\",\"A\":\"15.172\",\"T\":1788564452668,\"E\":1788564452669,\"st\":1}}"}
{"receive_ns":1788564452742899000,"stream":"btcusdt@depth@100ms","event_type":"depthUpdate","event_time_ms":1788564452763,"raw_json":"{\"stream\":\"btcusdt@depth@100ms\",\"data\":{\"e\":\"depthUpdate\",\"E\":1788564452763,\"T\":1788564452762,\"s\":\"BTCUSDT\",\"ps\":\"BTCUSDT\",\"U\":11478296354267,\"u\":11478296360273,\"pu\":11478296354182,\"b\":[[\"1000.00\",\"24.754\"],[\"29216.80\",\"0.028\"],[\"29316.80\",\"1.771\"],[\"29416.80\",\"0.301\"],[\"71745.10\",\"0.002\"],[\"75731.00\",\"0.069\"],[\"76528.10\",\"0.000\"],[\"78680.50\",\"0.254\"],[\"78919.60\",\"2.865\"],[\"79079.10\",\"1.769\"],[\"79320.20\",\"0.140\"],[\"79529.50\",\"1.103\"],[\"79530.00\",\"0.202\"],[\"79530.90\",\"3.208\"],[\"79531.50\",\"0.707\"],[\"79626.10\",\"0.001\"],[\"79626.80\",\"0.039\"],[\"79695.10\",\"0.001\"],[\"79696.50\",\"0.800\"],[\"79698.60\",\"1.583\"],[\"79699.30\",\"0.003\"],[\"79701.90\",\"0.000\"],[\"79709.50\",\"0.027\"],[\"79709.70\",\"0.026\"],[\"79711.60\",\"0.026\"],[\"79711.70\",\"0.000\"],[\"79711.80\",\"0.001\"],[\"79712.00\",\"0.016\"],[\"79712.10\",\"0.002\"]],\"a\":[[\"79716.90\",\"15.172\"],[\"79717.90\",\"0.014\"],[\"79722.10\",\"0.000\"],[\"79792.60\",\"0.701\"],[\"79801.50\",\"0.000\"],[\"79802.20\",\"0.038\"],[\"79852.20\",\"0.567\"],[\"79853.70\",\"3.443\"],[\"79854.20\",\"0.000\"],[\"80087.60\",\"1.147\"],[\"80354.60\",\"1.492\"],[\"80514.10\",\"0.640\"],[\"80673.50\",\"16.955\"]],\"st\":1}}"}
{"receive_ns":1788564452774261000,"stream":"btcusdt@bookTicker","event_type":"bookTicker","event_time_ms":1788564452788,"raw_json":"{\"stream\":\"btcusdt@bookTicker\",\"data\":{\"e\":\"bookTicker\",\"u\":11478296362031,\"s\":\"BTCUSDT\",\"ps\":\"BTCUSDT\",\"b\":\"79716.80\",\"B\":\"2.629\",\"a\":\"79716.90\",\"A\":\"15.172\",\"T\":1788564452788,\"E\":1788564452788,\"st\":1}}"}
{"receive_ns":1788564452780904000,"stream":"btcusdt@bookTicker","event_type":"bookTicker","event_time_ms":1788564452795,"raw_json":"{\"stream\":\"btcusdt@bookTicker\",\"data\":{\"e\":\"bookTicker\",\"u\":11478296362439,\"s\":\"BTCUSDT\",\"ps\":\"BTCUSDT\",\"b\":\"79716.80\",\"B\":\"2.652\",\"a\":\"79716.90\",\"A\":\"15.172\",\"T\":1788564452795,\"E\":1788564452795,\"st\":1}}"}
