{"kind": "depth", "E": 1787081880561, "U": 11315469105107, "u": 11315469121946, "recv_ms": 1787081880531, "bids": [[14194.2, 1.442], [14294.2, 2.758], [58224.7, 0.002], [61459.4, 0.0], [62106.4, 0.689], [63691.4, 7.69], [63694.2, 0.02], [63937.3, 3.852], [64047.3, 0.463], [64370.7, 5.042], [64497.2, 10.248], [64536.0, 5.067], [64553.0, 4.864], [64622.9, 35.712], [64625.1, 0.002], [64633.2, 0.001], [64634.1, 0.004], [64640.5, 0.005], [64650.6, 0.006], [64671.8, 0.008], [64672.1, 0.29], [64680.8, 0.63], [64685.4, 0.045], [64685.5, 0.157], [64686.6, 0.003], [64687.5, 0.006], [64687.7, 1.294], [64687.8, 0.007], [64687.9, 0.232], [64688.0, 0.022], [64688.3, 0.622], [64688.4, 0.598], [64688.5, 0.117], [64689.1, 0.004], [64690.5, 0.442], [64694.2, 7.97]], "asks": [[64700.5, 0.043], [64700.7, 0.464], [64700.8, 0.645], [64701.5, 0.164], [64701.7, 0.047], [64701.8, 2.961], [64705.3, 0.004], [64705.6, 0.085], [64861.0, 3.917], [64871.1, 0.045], [64890.2, 9.019], [65017.8, 4.784], [65341.2, 2.523], [65438.9, 7.328], [65503.0, 7.885], [65522.5, 4.766], [65694.3, 0.02]]}
{"kind": "depth", "E": 1787081880663, "U": 11315469122381, "u": 11315469139776, "recv_ms": 1787081880641, "bids": [[1000.0, 35.81], [14194.2, 1.806], [14294.2, 2.394], [51755.0, 0.0], [51755.4, 0.002], [58224.7, 0.002], [63691.4, 6.593], [63917.9, 31.231], [64047.3, 0.463], [64176.6, 9.8], [64370.7, 5.197], [64574.3, 0.38], [64577.2, 0.001], [64577.3, 3.865], [64620.7, 35.975], [64621.5, 0.046], [64622.9, 0.003], [64623.0, 0.014], [64624.3, 0.153], [64625.1, 0.002], [64627.1, 0.003], [64628.8, 3.563], [64660.7, 0.233], [64661.5, 0.012], [64685.4, 0.578], [64685.5, 0.265], [64685.6, 0.017], [64686.6, 0.004], [64687.5, 0.005], [64687.7, 1.294], [64687.8, 0.0], [64688.0, 0.022], [64688.3, 0.004], [64688.4, 0.21], [64688.5, 0.085], [64688.6, 0.002], [64689.1, 0.004], [64690.5, 0.271]], "asks": [[64697.1, 0.009], [64701.0, 0.044], [64734.5, 0.002], [64763.9, 0.0], [64764.0, 1.722], [64772.4, 0.125], [64828.1, 0.003], [64828.2, 4.079], [64835.5, 0.0], [64881.2, 0.007], [65341.2, 2.523], [65415.6, 3.815], [65600.0, 106.892], [65632.4, 19.664], [65697.1, 9.425]]}
{"kind": "depth", "E": 1787081880765, "U": 11315469140160, "u": 11315469149004, "recv_ms": 1787081880733, "bids": [[1000.0, 35.81], [14194.2, 2.156], [14294.2, 2.044], [51755.4, 0.0], [58224.7, 0.002], [62106.4, 0.692], [63659.1, 4.835], [63694.2, 0.0], [63713.9, 0.001], [63756.1, 21.425], [63837.1, 0.785], [63885.5, 8.833], [64047.3, 0.463], [64553.0, 4.864], [64597.2, 0.011], [64620.7, 0.183], [64621.7, 0.027], [64622.9, 35.795], [64625.1, 0.002], [64659.5, 0.057], [64660.2, 0.641], [64670.1, 0.562], [64670.8, 0.007], [64671.2, 0.005], [64671.7, 0.578], [64672.3, 0.133], [64675.7, 0.321], [64676.4, 0.033], [64676.6, 0.926], [64681.4, 0.126], [64684.0, 2.897], [64684.2, 0.468], [64685.4, 0.045], [64685.5, 0.157], [64685.6, 0.001], [64685.7, 0.038], [64686.6, 0.004], [64687.7, 1.294], [64687.8, 0.007], [64688.0, 0.64], [64688.3, 0.036], [64689.1, 0.004]], "asks": [[64694.9, 0.001], [64695.2, 0.089], [64696.6, 0.106], [64708.3, 0.0], [64708.8, 0.614], [64709.1, 0.929], [64710.6, 0.082], [64711.4, 0.094], [64711.5, 0.556], [64712.4, 0.087], [64713.1, 0.01], [64713.4, 0.387], [64714.0, 0.547], [64714.5, 0.929], [64715.4, 0.241], [64834.4, 5.398], [64891.3, 0.005], [65341.2, 2.523], [65694.3, 0.0], [65729.4, 4.682]]}
{"kind": "depth", "E": 1787081880867, "U": 11315469149538, "u": 11315469159055, "recv_ms": 1787081880842, "bids": [[14194.2, 2.52], [14294.2, 1.68], [58224.7, 0.002], [61459.4, 0.0], [62106.4, 0.689], [63174.7, 0.0], [63400.4, 0.081], [63659.1, 5.933], [63691.4, 7.69], [63756.1, 22.521], [63843.5, 3.128], [63885.5, 9.067], [63982.8, 0.011], [64047.3, 0.463], [64370.7, 5.197], [64574.3, 0.38], [64621.7, 0.009], [64628.8, 3.563], [64645.8, 2.508], [64661.5, 0.012], [64677.8, 0.369], [64685.4, 0.037], [64685.5, 0.165], [64687.7, 1.682], [64687.8, 0.194], [64688.0, 0.679], [64688.3, 0.004], [64688.4, 0.21], [64688.5, 0.085], [64689.1, 0.004], [64690.5, 0.451], [64691.8, 0.001], [64694.2, 7.97]], "asks": [[64702.0, 1.051], [64702.2, 0.003], [64706.4, 0.274], [64710.3, 0.212], [64734.5, 0.002], [64742.8, 2.491], [64772.4, 0.125], [64835.5, 0.0], [65017.8, 4.783], [65341.2, 2.523], [65632.4, 19.663], [65729.4, 5.746], [65988.1, 0.012]]}
{"kind": "depth", "E": 1787081880969, "U": 11315469159166, "u": 11315469166032, "recv_ms": 1787081880938, "bids": [[1000.0, 35.81], [14194.2, 2.87], [14294.2, 1.33], [58224.7, 0.002], [62106.4, 0.692], [63691.4, 8.788], [63694.2, 0.02], [63924.3, 8.44], [63950.4, 1.568], [64047.3, 0.463], [64114.0, 0.947], [64370.7, 5.198], [64677.8, 0.371], [64685.4, 0.122], [64685.5, 0.157], [64687.7, 1.682], [64687.8, 0.0], [64688.0, 0.029], [64688.3, 0.004], [64688.4, 0.21], [64688.5, 0.658], [64689.1, 0.73], [64691.7, 0.002]], "asks": [[64695.8, 0.088], [64701.0, 0.044], [64702.0, 0.151], [64710.3, 0.214], [65341.2, 2.523], [65500.0, 336.013], [65694.3, 0.02], [65697.1, 10.488], [65811.0, 0.015], [65858.9, 3.011]]}
{"kind": "depth", "E": 1787081881071, "U": 11315469166118, "u": 11315469173824, "recv_ms": 1787081881040, "bids": [[1000.0, 35.81], [14194.2, 3.234], [14294.2, 0.966], [58224.7, 0.002], [62106.4, 0.689], [63691.4, 7.69], [63701.0, 1.401], [63769.6, 6.652], [63875.9, 0.806], [63885.5, 9.332], [64047.3, 0.463], [64645.8, 3.761], [64659.5, 0.0], [64660.3, 0.057], [64673.6, 2.981], [64673.9, 1.262], [64682.6, 0.028], [64684.0, 2.356], [64684.2, 1.009], [64685.4, 0.702], [64687.7, 1.294], [64687.8, 0.0], [64688.0, 0.022], [64688.3, 0.004], [64688.5, 0.085], [64689.1, 0.004], [64689.2, 0.318], [64690.3, 0.0], [64690.5, 0.452]], "asks": [[64696.6, 0.106], [64696.7, 0.002], [64700.0, 0.198], [64700.3, 0.04], [64700.5, 0.544], [64700.8, 0.104], [64701.0, 0.944], [64890.2, 9.398], [65341.2, 2.523], [65632.4, 18.598], [65687.6, 0.027], [65697.1, 9.424], [65910.0, 0.843]]}
{"kind": "depth", "E": 1787081881173, "U": 11315469173926, "u": 11315469183311, "recv_ms": 1787081881142, "bids": [[14194.2, 3.584], [14294.2, 0.616], [58224.7, 0.002], [61459.4, 0.0], [63694.2, 0.0], [63701.0, 1.41], [63743.2, 2.435], [63924.3, 9.377], [64047.3, 0.463], [64370.7, 5.208], [64497.2, 10.109], [64536.0, 0.031], [64536.1, 4.956], [64553.0, 4.78], [64616.5, 0.286], [64635.9, 0.026], [64645.8, 5.014], [64654.5, 0.001], [64654.6, 0.436], [64664.7, 0.628], [64672.0, 1.399], [64685.4, 0.045], [64685.5, 0.157], [64685.7, 0.038], [64686.0, 0.035], [64686.6, 0.004], [64687.7, 1.21], [64687.8, 0.625], [64688.0, 0.054], [64690.5, 0.271], [64691.2, 0.09], [64691.7, 0.086]], "asks": [[64694.3, 7.442], [64695.8, 0.004], [64697.5, 0.045], [64698.4, 0.008], [64698.5, 0.0], [64698.6, 0.132], [64700.0, 0.004], [64700.3, 0.0], [64700.5, 0.645], [64700.8, 0.02], [64703.4, 1.598], [64709.1, 0.004], [64709.2, 1.499], [64725.7, 0.622], [64739.6, 0.003], [64804.3, 1.389], [64834.4, 5.398], [64890.2, 9.341], [64894.2, 4.687], [64894.3, 0.0], [64977.3, 0.054], [65042.3, 0.0], [65341.2, 2.523], [65632.4, 19.663], [65694.3, 0.0]]}
{"kind": "depth", "E": 1787081881275, "U": 11315469183549, "u": 11315469189754, "recv_ms": 1787081881244, "bids": [[1000.0, 35.81], [14194.2, 3.78], [14294.2, 0.336], [14594.2, 0.084], [51755.0, 0.0], [58224.7, 0.002], [61459.4, 0.0], [61459.5, 0.01], [61459.6, 2.445], [62106.4, 0.692], [62106.5, 0.0], [62733.4, 1.001], [63380.1, 0.301], [63400.4, 0.078], [63691.4, 8.788], [63985.7, 0.001], [64047.3, 0.463], [64574.3, 0.38], [64628.8, 3.563], [64642.4, 1.631], [64647.6, 0.03], [64660.3, 0.057], [64661.3, 0.004], [64661.5, 0.012], [64670.1, 0.005], [64671.2, 0.012], [64671.8, 0.001], [64672.1, 0.847], [64676.5, 0.928], [64676.6, 0.0], [64677.3, 2.321], [64677.5, 0.154], [64684.2, 1.009], [64685.3, 0.464], [64685.4, 0.121], [64685.5, 0.165], [64687.7, 1.598], [64687.8, 0.573], [64688.0, 0.022], [64688.3, 0.004], [64688.5, 0.085], [64688.6, 0.002], [64689.1, 0.004], [64690.5, 0.44], [64692.7, 0.04], [64694.2, 7.952]], "asks": [[64696.6, 0.106], [64697.5, 0.029], [64698.5, 0.0], [64698.6, 0.157], [64700.3, 0.092], [64700.5, 0.544], [64706.7, 0.003], [64709.0, 1.553], [64709.2, 0.574], [64709.9, 1.238], [64711.5, 0.0], [64712.3, 0.828], [64712.4, 0.03], [64713.2, 1.79], [64714.0, 0.547], [64714.4, 0.005], [64715.1, 0.061], [64715.4, 0.126], [64716.3, 0.115], [64725.4, 0.018], [64734.5, 0.002], [64772.4, 0.125], [64835.5, 0.0], [65341.2, 2.523], [65620.7, 8.424], [65632.4, 20.728], [65687.6, 0.036], [65697.1, 10.488], [65858.8, 0.364], [65904.1, 2.325]]}
{"kind": "depth", "E": 1787081881377, "U": 11315469189781, "u": 11315469197510, "recv_ms": 1787081881346, "bids": [[1000.0, 35.81], [14194.2, 3.654], [14294.2, 0.224], [14594.2, 0.322], [51755.0, 0.0], [58224.7, 0.002], [61439.9, 3.0], [61459.4, 0.0], [62086.7, 2.006], [62106.4, 0.689], [63694.2, 0.02], [64047.3, 0.463], [64150.8, 0.187], [64176.6, 9.489], [64370.7, 5.053], [64370.8, 1.443], [64642.4, 1.645], [64657.9, 0.448], [64681.2, 2.351], [64681.3, 1.334], [64685.4, 0.045], [64685.5, 0.157], [64687.7, 1.598], [64687.8, 0.077], [64688.0, 0.223], [64688.3, 0.577], [64688.5, 0.279], [64689.1, 0.004], [64689.3, 0.732], [64690.5, 0.271], [64694.2, 7.92]], "asks": [[64694.3, 7.445], [64725.4, 0.004], [64746.1, 2.887], [64823.7, 0.0], [65341.2, 2.523], [65473.9, 1.542], [65694.3, 0.02]]}
{"kind": "depth", "E": 1787081881479, "U": 11315469197657, "u": 11315469204431, "recv_ms": 1787081881448, "bids": [[14194.2, 3.542], [14294.2, 0.098], [14594.2, 0.56], [58224.7, 0.002], [60793.2, 4.0], [61459.5, 0.012], [62106.4, 0.692], [63885.5, 9.684], [63917.9, 30.451], [63977.8, 0.25], [64015.5, 6.387], [64047.3, 0.463], [64150.8, 0.279], [64370.7, 5.198], [64553.0, 0.015], [64642.4, 1.631], [64657.9, 0.434], [64685.3, 0.472], [64685.4, 0.037], [64685.5, 0.157], [64686.3, 0.115], [64686.6, 0.004], [64686.8, 0.004], [64686.9, 0.004], [64687.7, 1.598], [64687.8, 0.116], [64688.0, 0.563], [64688.3, 0.004], [64688.5, 0.085], [64688.6, 0.002], [64689.3, 0.732], [64690.5, 0.271]], "asks": [[64701.6, 0.407], [64704.5, 2.846], [64834.4, 0.0], [65341.2, 2.523], [65470.6, 25.033], [65545.0, 4.483], [65593.6, 4.076], [65672.5, 9.498], [65674.4, 3.8], [65988.1, 0.015]]}
{"kind": "depth", "E": 1787081881581, "U": 11315469204635, "u": 11315469211373, "recv_ms": 1787081881550, "bids": [[1000.0, 35.81], [14194.2, 3.374], [14294.2, 0.0], [14594.2, 0.826], [58224.7, 0.002], [61459.4, 0.0], [63694.2, 0.0], [63723.7, 3.106], [63875.9, 1.588], [63885.5, 10.035], [63917.9, 29.982], [64047.3, 0.463], [64150.8, 0.214], [64536.1, 5.029], [64536.3, 1.163], [64553.0, 4.851], [64671.1, 2.15], [64671.2, 0.005], [64672.0, 1.406], [64672.1, 0.29], [64685.3, 0.464], [64685.4, 0.037], [64685.5, 0.165], [64687.7, 1.598], [64687.8, 0.31], [64688.0, 0.563], [64688.3, 0.004], [64689.3, 0.732], [64694.2, 7.937]], "asks": [[64696.6, 0.106], [64711.3, 0.561], [64712.3, 0.272], [64715.2, 1.215], [64716.3, 0.0], [64834.4, 5.398], [64851.2, 2.671], [64851.4, 11.873], [64890.2, 9.153], [65017.8, 4.782], [65341.2, 2.523], [65694.3, 0.0], [65910.0, 0.117]]}
{"kind": "depth", "E": 1787081881683, "U": 11315469211423, "u": 11315469219083, "recv_ms": 1787081881651, "bids": [[1000.0, 35.81], [14194.2, 3.024], [14594.2, 1.176], [51755.4, 0.0], [58224.7, 0.002], [61459.4, 0.0], [61459.5, 0.01], [61459.6, 2.445], [62106.4, 0.689], [63917.9, 30.762], [63989.0, 5.231], [64047.3, 0.463], [64117.7, 5.138], [64176.6, 9.8], [64370.7, 5.199], [64536.1, 5.064], [64536.3, 0.444], [64553.0, 0.015], [64553.1, 4.851], [64574.3, 0.38], [64628.8, 3.563], [64661.5, 0.012], [64670.1, 0.341], [64671.7, 0.462], [64672.5, 0.118], [64685.4, 0.694], [64687.7, 1.598], [64687.8, 0.0], [64688.0, 0.022], [64688.3, 0.004], [64688.5, 0.085], [64689.3, 0.732], [64690.5, 0.435]], "asks": [[64694.3, 7.335], [64697.9, 0.001], [64698.6, 0.234], [64700.3, 0.015], [64717.6, 0.894], [64718.4, 1.111], [64720.2, 0.721], [64725.7, 0.004], [64728.0, 1.203], [64734.5, 0.002], [64772.4, 0.125], [64834.4, 0.0], [64834.5, 5.556], [64835.5, 0.0], [64890.2, 9.096], [65336.0, 13.147], [65341.2, 2.523], [65470.6, 26.559], [65584.5, 3.488], [65600.0, 107.075], [65645.3, 2.373], [65904.1, 3.051]]}
{"kind": "depth", "E": 1787081881785, "U": 11315469219277, "u": 11315469226666, "recv_ms": 1787081881753, "bids": [[14194.2, 2.688], [14594.2, 1.512], [51755.0, 0.006], [58224.7, 0.002], [62106.4, 0.692], [63400.4, 0.081], [63694.2, 0.02], [63917.9, 31.231], [64047.3, 0.463], [64176.7, 0.006], [64370.7, 5.199], [64497.2, 0.0], [64497.3, 6.7], [64536.1, 1.168], [64553.1, 2.169], [64574.3, 0.38], [64628.8, 3.563], [64661.5, 0.012], [64665.7, 0.161], [64670.1, 0.005], [64685.4, 0.061], [64687.7, 1.404], [64687.8, 0.084], [64688.0, 0.022], [64688.3, 0.004], [64688.5, 0.626], [64689.1, 0.367], [64689.3, 0.006]], "asks": [[64694.3, 7.38], [64696.6, 0.106], [64707.4, 1.215], [64723.4, 3.247], [64723.7, 14.179], [64728.0, 1.189], [64734.5, 0.002], [64758.6, 1.91], [64761.3, 0.0], [64761.6, 0.007], [64762.8, 1.528], [64763.5, 0.0], [64766.8, 0.036], [64767.9, 34.916], [64772.4, 0.125], [64835.5, 0.0], [64890.2, 15.414], [65341.2, 2.523], [65600.1, 5.366], [65694.3, 0.02]]}
{"kind": "depth", "E": 1787081881887, "U": 11315469226672, "u": 11315469238874, "recv_ms": 1787081881855, "bids": [[1000.0, 35.81], [14194.2, 2.31], [14594.2, 1.89], [51755.0, 0.0], [58224.7, 0.002], [61459.4, 0.0], [62106.4, 0.689], [64047.3, 0.463], [64112.0, 6.991], [64497.3, 9.593], [64536.1, 3.697], [64553.1, 4.159], [64603.0, 0.241], [64603.1, 0.006], [64642.4, 1.645], [64657.9, 0.448], [64667.0, 0.34], [64685.4, 0.13], [64687.7, 1.21], [64687.8, 0.007], [64688.0, 0.563], [64688.5, 0.085], [64688.6, 0.018], [64689.1, 0.004], [64690.5, 0.435], [64694.2, 7.934]], "asks": [[64763.5, 34.894], [64766.8, 0.027], [64767.9, 0.022], [65308.9, 8.985], [65341.2, 2.523], [65503.0, 8.227], [65539.6, 2.288], [65539.7, 0.002]]}
{"kind": "depth", "E": 1787081881989, "U": 11315469239004, "u": 11315469247083, "recv_ms": 1787081881958, "bids": [[1000.0, 35.81], [14194.2, 1.946], [14594.2, 2.254], [58224.7, 0.002], [61459.4, 0.0], [62106.4, 0.692], [63694.2, 0.0], [63756.1, 21.424], [63885.5, 10.269], [63940.5, 0.002], [64047.3, 0.463], [64150.8, 0.173], [64152.0, 0.029], [64370.7, 5.198], [64642.4, 1.645], [64661.3, 0.002], [64661.4, 1.661], [64661.5, 0.01], [64664.8, 0.084], [64664.9, 0.0], [64665.0, 0.054], [64673.7, 0.223], [64673.9, 1.26], [64677.8, 0.371], [64685.4, 0.694], [64685.5, 0.165], [64686.2, 0.0], [64686.6, 0.004], [64686.8, 0.004], [64687.7, 1.21], [64687.8, 0.0], [64688.0, 0.022], [64688.3, 0.004], [64688.5, 0.085], [64688.6, 0.002], [64688.7, 0.005], [64690.5, 0.439], [64691.7, 0.002], [64694.2, 7.934]], "asks": [[64694.3, 7.382], [64694.5, 0.626], [64696.6, 0.106], [64697.0, 0.903], [64698.6, 0.125], [64700.3, 0.124], [64702.3, 1.304], [64710.3, 0.214], [64711.9, 0.001], [65341.2, 2.523], [65512.6, 2.287], [65600.0, 109.359], [65669.2, 1.215], [65694.3, 0.0]]}
{"kind": "depth", "E": 1787081882091, "U": 11315469247267, "u": 11315469254190, "recv_ms": 1787081882062, "bids": [[14194.2, 1.596], [14594.2, 2.604], [51755.0, 0.0], [58224.7, 0.002], [61459.4, 0.0], [61459.5, 0.012], [63756.1, 20.327], [63807.5, 4.959], [63988.3, 7.422], [64047.3, 0.463], [64150.8, 0.136], [64370.7, 5.198], [64564.8, 3.533], [64574.3, 0.66], [64616.5, 0.289], [64623.0, 6.153], [64628.8, 3.731], [64642.4, 1.631], [64660.3, 0.057], [64661.2, 0.001], [64661.5, 0.083], [64671.2, 0.012], [64672.0, 1.399], [64676.4, 0.959], [64676.5, 0.002], [64677.3, 2.321], [64682.6, 0.028], [64684.2, 1.009], [64685.3, 0.464], [64685.4, 0.13], [64685.9, 0.0], [64686.6, 0.004], [64686.8, 0.004], [64687.7, 1.598], [64687.8, 0.541], [64688.5, 0.085], [64688.6, 0.025], [64688.7, 0.005], [64690.5, 0.439], [64691.7, 0.086]], "asks": [[64694.3, 7.202], [64695.7, 0.009], [64696.4, 0.002], [64697.1, 0.006], [64698.0, 0.015], [64698.6, 0.157], [64700.3, 0.092], [64708.9, 0.935], [64709.0, 0.628], [64709.8, 0.002], [64711.3, 0.005], [64712.2, 2.388], [64712.3, 0.215], [64713.0, 0.019], [64714.0, 0.547], [64714.6, 0.223], [64715.2, 1.1], [64716.1, 0.771], [64734.5, 0.075], [64772.4, 0.294], [64804.3, 1.392], [64835.5, 0.282], [64890.2, 9.454], [65017.8, 4.783], [65341.2, 2.523]]}
{"kind": "depth", "E": 1787081882193, "U": 11315469254494, "u": 11315469262110, "recv_ms": 1787081882162, "bids": [[1000.0, 35.81], [14194.2, 1.246], [14594.2, 2.954], [51755.0, 0.0], [58224.7, 0.002], [61459.4, 0.0], [62106.4, 0.689], [63424.3, 2.026], [63694.2, 0.02], [63756.1, 21.424], [63982.6, 1.772], [64047.3, 0.463], [64150.8, 0.105], [64641.4, 2.117], [64642.4, 1.645], [64643.2, 0.459], [64649.7, 2.163], [64650.6, 0.006], [64657.9, 2.559], [64658.0, 0.022], [64664.3, 0.776], [64664.7, 0.01], [64667.0, 0.004], [64672.0, 0.781], [64680.1, 0.318], [64680.5, 0.004], [64681.2, 2.356], [64681.3, 1.329], [64683.6, 0.312], [64683.9, 3.317], [64685.4, 0.662], [64686.2, 0.0], [64686.6, 0.004], [64686.8, 0.004], [64687.7, 1.598], [64687.8, 0.194], [64688.0, 0.038], [64688.3, 0.236], [64688.5, 0.101], [64688.6, 0.002], [64688.8, 0.085], [64688.9, 0.02], [64689.2, 0.086], [64689.3, 0.006], [64690.5, 0.271], [64691.6, 0.001], [64691.8, 0.001], [64691.9, 0.001]], "asks": [[64694.3, 8.409], [64696.6, 0.109], [64698.6, 0.125], [64700.3, 0.124], [64700.7, 0.465], [64703.4, 1.597], [64705.6, 0.085], [64707.2, 1.814], [64713.0, 0.019], [64719.7, 10.015], [64723.4, 2.033], [64723.7, 4.179], [64735.8, 0.0], [64746.1, 2.845], [64790.4, 5.013], [64790.5, 0.0], [64798.7, 2.106], [64798.8, 0.0], [64807.0, 2.127], [64807.1, 4.831], [65341.2, 2.523], [65694.3, 0.02], [65722.7, 0.0], [71163.8, 0.0]]}
{"kind": "depth", "E": 1787081882295, "U": 11315469262201, "u": 11315469269484, "recv_ms": 1787081882264, "bids": [[1000.0, 35.81], [14194.2, 0.896], [14594.2, 3.304], [51755.0, 0.0], [58224.7, 0.002], [62106.4, 0.692], [62106.5, 0.001], [63714.1, 0.786], [64047.3, 0.463], [64685.4, 0.694], [64687.7, 1.21], [64687.8, 0.0], [64688.0, 0.022], [64688.3, 0.236], [64688.5, 0.085], [64688.6, 0.002], [64691.3, 0.001], [64691.4, 0.019], [64691.6, 0.001], [64691.7, 0.002]], "asks": [[64694.3, 8.379], [64695.8, 0.088], [64698.0, 0.325], [64698.5, 0.541], [64698.6, 0.157], [64700.0, 0.101], [64700.3, 0.084], [64700.5, 0.011], [64890.2, 9.343], [65341.2, 2.523], [65503.0, 8.456]]}
{"kind": "depth", "E": 1787081882397, "U": 11315469269847, "u": 11315469276262, "recv_ms": 1787081882368, "bids": [[14194.2, 0.532], [14594.2, 3.668], [58224.7, 0.002], [61459.4, 0.0], [62106.4, 0.689], [63400.4, 0.084], [63694.2, 0.0], [63756.1, 22.521], [64047.3, 0.463], [64370.7, 5.198], [64671.5, 0.004], [64674.2, 0.001], [64685.6, 0.002], [64686.6, 0.003], [64686.8, 0.73], [64694.2, 7.934]], "asks": [[64696.6, 0.109], [64698.5, 0.0], [64698.6, 0.125], [64698.8, 0.006], [64700.0, 0.004], [64700.3, 0.092], [64700.5, 0.576], [64700.7, 0.464], [64823.7, 0.0], [65282.4, 1.161], [65341.2, 2.523], [65511.5, 1.525], [65694.3, 0.0]]}
{"kind": "depth", "E": 1787081882499, "U": 11315469276545, "u": 11315469288082, "recv_ms": 1787081882468, "bids": [[1000.0, 35.81], [14194.2, 0.308], [14494.2, 0.14], [14594.2, 3.752], [45286.0, 0.002], [58224.7, 0.002], [63133.1, 0.678], [63626.7, 2.198], [63820.8, 7.773], [64047.3, 0.463], [64150.8, 0.068], [64616.5, 0.286], [64635.9, 0.026], [64674.7, 0.165], [64685.4, 0.694], [64685.6, 0.001], [64686.6, 0.004], [64686.8, 0.004], [64687.7, 1.21], [64687.8, 0.0], [64688.5, 0.085], [64688.6, 0.002], [64689.1, 0.004], [64689.2, 0.086], [64690.5, 0.439]], "asks": [[64739.6, 0.003], [64804.3, 1.389], [65341.2, 2.523], [65761.8, 1.245]]}
{"kind": "depth", "E": 1787081882601, "U": 11315469288258, "u": 11315469294325, "recv_ms": 1787081882572, "bids": [[14194.2, 0.196], [14494.2, 0.378], [14594.2, 3.626], [58224.7, 0.002], [62106.4, 0.692], [63626.7, 3.297], [63694.2, 0.02], [63940.6, 3.196], [64047.3, 0.463], [64659.7, 0.001], [64660.3, 0.0], [64660.5, 0.057], [64670.1, 0.562], [64671.1, 1.593], [64671.2, 0.005], [64671.7, 0.578], [64672.0, 0.788], [64672.5, 0.002], [64675.8, 0.927], [64676.4, 0.033], [64681.4, 0.126], [64684.0, 2.897], [64684.2, 0.468], [64685.4, 0.578], [64685.9, 0.0], [64686.6, 0.004], [64686.8, 0.004], [64687.7, 1.21], [64687.8, 0.116], [64689.1, 0.004], [64690.5, 0.271]], "asks": [[64710.6, 0.082], [64711.5, 0.556], [64712.2, 1.775], [64712.3, 0.208], [64712.4, 0.087], [64712.8, 0.009], [64713.1, 0.01], [64713.4, 0.387], [64714.0, 0.547], [64714.5, 0.929], [64715.5, 0.743], [64716.1, 0.656], [65341.2, 2.523], [65632.4, 19.663], [65694.3, 0.02], [65761.8, 2.308]]}
{"kind": "depth", "E": 1787081882703, "U": 11315469294595, "u": 11315469302207, "recv_ms": 1787081882671, "bids": [[14194.2, 0.07], [14494.2, 0.616], [14594.2, 3.514], [51755.4, 0.0], [58224.7, 0.002], [61459.4, 0.0], [61459.5, 0.014], [62106.4, 0.689], [63924.3, 8.439], [64047.3, 0.463], [64370.7, 5.197], [64659.7, 0.058], [64660.5, 0.0], [64661.3, 0.004], [64661.4, 1.663], [64661.5, 0.085], [64664.8, 0.086], [64664.9, 0.002], [64665.0, 0.056], [64685.4, 0.671], [64685.5, 0.165], [64685.7, 0.038], [64686.6, 0.004], [64687.8, 0.0], [64688.3, 0.003], [64688.4, 0.21], [64688.5, 0.108], [64691.2, 0.113]], "asks": [[64694.3, 8.356], [64696.6, 0.109], [64714.0, 0.006], [64714.4, 0.546], [64746.1, 2.887], [65276.5, 4.512], [65341.2, 2.523], [65794.1, 7.117]]}
{"kind": "depth", "E": 1787081882805, "U": 11315469302254, "u": 11315469310133, "recv_ms": 1787081882773, "bids": [[1000.0, 35.81], [14194.2, 0.0], [14494.2, 0.91], [14594.2, 3.29], [58224.7, 0.002], [62106.4, 0.692], [63694.2, 0.0], [63904.6, 5.746], [63908.2, 7.034], [64047.3, 0.463], [64659.7, 0.001], [64660.3, 0.057], [64661.3, 0.004], [64670.1, 0.005], [64671.2, 0.012], [64671.7, 0.462], [64672.0, 0.781], [64672.1, 0.849], [64672.5, 0.118], [64673.4, 0.0], [64675.8, 0.001], [64676.5, 0.928], [64677.4, 0.043], [64684.0, 2.356], [64684.2, 1.009], [64685.4, 0.037], [64685.5, 0.165], [64686.6, 0.004], [64686.8, 0.004], [64687.7, 1.598], [64687.8, 0.65], [64688.0, 0.029], [64688.5, 0.085], [64688.9, 0.252], [64689.1, 0.73], [64694.2, 7.936]], "asks": [[64708.9, 0.01], [64709.9, 2.163], [64711.5, 0.0], [64712.3, 0.764], [64712.4, 0.03], [64713.2, 1.847], [64714.0, 0.547], [64714.4, 0.005], [64715.1, 0.061], [64715.5, 0.628], [64716.3, 0.115], [65017.8, 4.784], [65341.2, 2.523], [65632.4, 20.728], [65694.3, 0.0], [65988.1, 0.012]]}
{"kind": "depth", "E": 1787081882907, "U": 11315469310207, "u": 11315469317350, "recv_ms": 1787081882877, "bids": [[14494.2, 1.26], [14594.2, 2.94], [58224.7, 0.002], [61459.4, 0.001], [62106.4, 0.689], [63694.2, 0.02], [64047.3, 0.463], [64553.1, 4.85], [64574.3, 0.38], [64618.2, 0.004], [64621.9, 0.025], [64628.8, 3.563], [64635.3, 0.407], [64642.4, 1.631], [64642.9, 0.24], [64650.2, 0.443], [64650.3, 0.0], [64653.9, 2.36], [64657.9, 2.545], [64660.3, 0.0], [64661.5, 0.012], [64662.0, 0.036], [64663.4, 0.201], [64664.3, 0.44], [64665.3, 0.022], [64667.7, 0.866], [64668.2, 1.215], [64668.5, 0.039], [64668.8, 0.029], [64669.6, 0.374], [64670.0, 1.407], [64670.5, 0.233], [64671.0, 2.335], [64671.4, 0.023], [64671.8, 0.019], [64671.9, 0.002], [64672.5, 0.002], [64672.9, 0.336], [64673.7, 0.221], [64674.2, 0.001], [64674.7, 0.167], [64675.1, 0.123], [64676.5, 0.002], [64676.8, 0.022], [64677.2, 0.001], [64677.4, 0.003], [64677.6, 0.004], [64678.6, 0.213], [64678.7, 0.945], [64678.8, 0.0], [64679.5, 0.026], [64680.0, 0.243], [64680.1, 0.311], [64681.2, 2.403], [64682.4, 0.002], [64683.6, 0.003], [64683.9, 3.397], [64684.2, 0.468], [64684.4, 0.546], [64684.5, 0.161], [64684.8, 0.58], [64685.2, 0.001], [64685.3, 0.001], [64685.4, 0.037], [64685.5, 0.157], [64686.4, 0.036], [64686.6, 0.001], [64686.7, 0.034], [64686.8, 2.99], [64686.9, 0.004], [64687.6, 0.63], [64687.7, 1.21], [64687.8, 0.023], [64688.0, 0.029], [64688.1, 0.07], [64688.3, 2.281], [64688.4, 0.404], [64688.5, 0.11], [64688.8, 0.001], [64688.9, 0.074], [64689.1, 0.004], [64689.2, 0.003], [64689.3, 0.008], [64689.9, 0.397], [64690.1, 0.007], [64690.5, 0.703], [64691.2, 0.114], [64691.6, 0.085], [64691.9, 0.004], [64692.1, 0.087], [64692.4, 0.088], [64692.5, 0.085], [64693.0, 0.084], [64693.4, 0.084], [64693.8, 0.021], [64694.2, 7.951]], "asks": [[64694.3, 3.496], [64694.4, 0.117], [64694.8, 0.002], [64695.2, 0.082], [64695.8, 0.004], [64696.2, 0.001], [64696.4, 0.009], [64696.5, 0.002], [64696.6, 0.002], [64696.9, 0.0], [64697.3, 0.004], [64697.4, 0.003], [64697.5, 0.018], [64698.0, 0.004], [64698.5, 0.016], [64698.6, 2.32], [64698.7, 0.53], [64698.8, 0.004], [64699.2, 0.017], [64699.3, 0.003], [64700.0, 0.023], [64700.1, 0.41], [64700.3, 0.1], [64700.4, 0.287], [64700.5, 0.628], [64700.7, 0.001], [64700.8, 0.028], [64701.7, 2.377], [64701.8, 0.014], [64702.1, 0.0], [64702.2, 0.004], [64702.9, 0.365], [64703.0, 1.546], [64703.1, 0.315], [64703.3, 0.092], [64703.4, 0.36], [64703.5, 0.586], [64703.8, 0.31], [64703.9, 0.0], [64704.0, 0.421], [64704.2, 0.718], [64704.5, 0.547], [64704.9, 0.007], [64705.0, 0.001], [64705.2, 0.011], [64705.6, 0.005], [64706.4, 0.354], [64706.9, 0.602], [64707.2, 1.859], [64708.5, 0.254], [64709.2, 0.567], [64709.5, 0.006], [64709.6, 0.463], [64709.9, 1.238], [64710.5, 0.161], [64710.9, 0.81], [64711.4, 0.054], [64711.9, 0.934], [64712.3, 0.208], [64712.7, 0.163], [64712.8, 0.002], [64712.9, 0.16], [64713.0, 0.339], [64713.1, 0.027], [64713.2, 1.79], [64713.3, 0.041], [64713.6, 0.742], [64714.0, 0.006], [64714.4, 0.012], [64714.5, 1.485], [64715.2, 1.157], [64715.8, 0.0], [64716.1, 0.502], [64716.3, 0.0], [64716.7, 0.586], [64716.8, 1.249], [64717.1, 0.26], [64717.2, 0.01], [64718.0, 0.116], [64718.1, 0.007], [64719.7, 0.015], [64720.5, 2.181], [64720.7, 0.004], [64723.2, 0.23], [64725.1, 0.077], [64725.4, 0.018], [64726.5, 0.085], [64726.7, 6.03], [64727.0, 10.075], [64727.5, 1.776], [64734.0, 0.001], [64734.4, 1.519], [64734.5, 0.002], [64736.8, 0.001], [64738.1, 0.039], [64740.4, 0.241], [64759.0, 0.294], [64763.5, 0.0], [64769.4, 0.011], [64771.9, 0.124], [64772.0, 0.015], [64772.4, 0.125], [64774.5, 34.827], [64805.6, 0.0], [64834.5, 0.158], [64835.5, 5.172], [64851.4, 1.465], [64852.5, 7.425], [64883.2, 0.146], [65341.2, 2.523], [65522.5, 4.508], [65694.3, 0.02]]}
{"kind": "depth", "E": 1787081883009, "U": 11315469317424, "u": 11315469334056, "recv_ms": 1787081882981, "bids": [[14494.2, 1.61], [14594.2, 2.59], [58224.7, 0.002], [61459.4, 0.0], [63924.3, 9.377], [64047.3, 0.463], [64370.7, 5.207], [64371.7, 0.108], [64622.9, 0.003], [64623.0, 0.014], [64627.3, 35.799], [64632.0, 2.367], [64645.8, 5.016], [64645.9, 0.002], [64647.6, 0.002], [64648.9, 0.001], [64652.7, 0.108], [64662.5, 0.0], [64663.2, 0.059], [64663.4, 0.144], [64667.5, 0.214], [64669.2, 0.005], [64670.0, 1.716], [64672.9, 0.0], [64674.4, 0.015], [64674.7, 0.165], [64675.2, 2.713], [64675.5, 0.002], [64675.7, 0.321], [64676.0, 0.804], [64676.2, 0.001], [64676.7, 0.338], [64677.1, 0.0], [64677.6, 0.002], [64677.8, 0.371], [64678.7, 1.007], [64679.4, 0.008], [64679.7, 0.598], [64680.0, 1.143], [64681.2, 2.398], [64681.3, 1.334], [64683.4, 0.455], [64684.0, 2.326], [64684.2, 0.468], [64684.4, 0.237], [64684.7, 0.48], [64684.8, 1.229], [64686.1, 0.313], [64686.8, 2.449], [64686.9, 0.545], [64687.0, 0.432], [64687.6, 0.63], [64687.7, 1.229], [64687.8, 0.411], [64688.0, 0.216], [64688.2, 0.313], [64688.3, 0.003], [64688.4, 0.148], [64688.5, 0.001], [64688.6, 0.032], [64689.1, 0.727], [64689.5, 0.001], [64690.0, 0.003], [64690.5, 0.229], [64690.6, 0.001], [64691.2, 0.091], [64691.4, 0.0], [64691.9, 0.004], [64692.0, 0.002], [64692.1, 0.317], [64692.2, 0.0], [64692.4, 0.001], [64692.7, 0.001], [64693.3, 0.0], [64693.4, 0.129], [64693.5, 0.186], [64693.8, 0.003], [64693.9, 0.109], [64694.0, 0.086], [64694.1, 0.163], [64694.2, 10.396]], "asks": [[64694.3, 3.083], [64694.7, 0.101], [64694.8, 0.0], [64695.1, 0.848], [64696.4, 0.0], [64696.8, 0.002], [64696.9, 0.008], [64697.0, 0.003], [64697.1, 0.006], [64697.2, 0.009], [64697.3, 0.004], [64697.4, 0.001], [64697.5, 0.008], [64697.7, 0.004], [64698.0, 0.004], [64698.1, 0.001], [64698.5, 2.327], [64698.6, 0.001], [64698.7, 0.446], [64699.0, 0.012], [64699.3, 0.007], [64699.4, 0.094], [64700.0, 0.004], [64700.1, 0.26], [64700.2, 0.004], [64700.3, 0.007], [64700.4, 0.285], [64700.5, 0.087], [64700.7, 0.017], [64700.8, 0.682], [64700.9, 1.553], [64701.0, 0.045], [64701.1, 0.0], [64701.2, 0.084], [64701.6, 0.491], [64702.0, 0.152], [64703.3, 0.095], [64703.8, 0.001], [64704.0, 0.305], [64704.2, 0.594], [64705.0, 0.31], [64705.2, 0.103], [64706.8, 0.008], [64706.9, 0.47], [64709.8, 0.126], [64710.3, 0.214], [64710.5, 0.0], [64711.8, 0.163], [64712.7, 0.164], [64713.6, 0.74], [64713.7, 0.002], [64713.9, 0.466], [64714.1, 1.199], [64714.5, 1.485], [64714.6, 0.223], [64715.0, 0.012], [64716.7, 0.586], [64717.1, 0.106], [64717.5, 0.002], [64718.6, 0.162], [64722.2, 0.006], [64722.7, 0.0], [64722.8, 0.015], [64724.2, 0.38], [64726.7, 6.032], [64727.0, 0.073], [64729.5, 10.003], [64730.0, 0.029], [64731.9, 1.249], [64770.1, 0.648], [64772.0, 0.006], [64774.5, 0.001], [64778.1, 7.393], [64778.9, 34.829], [64851.4, 11.873], [64852.5, 0.029], [65341.2, 2.523], [65623.1, 0.0], [65988.1, 0.015]]}
{"kind": "depth", "E": 1787081883111, "U": 11315469334108, "u": 11315469353683, "recv_ms": 1787081883081, "bids": [[1000.0, 35.81], [14494.2, 1.974], [14594.2, 2.226], [58224.7, 0.002], [61459.4, 0.0], [62106.4, 0.692], [63400.4, 0.087], [64047.3, 0.463], [64513.9, 0.004], [64534.6, 0.519], [64536.3, 0.964], [64577.3, 0.001], [64577.4, 3.87], [64620.7, 0.183], [64621.5, 0.0], [64621.7, 0.055], [64625.1, 0.002], [64627.3, 35.825], [64630.1, 0.163], [64630.3, 0.076], [64663.0, 0.123], [64663.2, 0.002], [64663.3, 0.403], [64663.6, 0.142], [64663.9, 0.101], [64670.9, 0.582], [64673.7, 0.237], [64674.0, 0.614], [64676.7, 0.002], [64677.3, 2.361], [64678.7, 0.019], [64678.9, 0.001], [64679.4, 0.934], [64679.5, 0.026], [64679.7, 0.599], [64679.9, 0.078], [64680.2, 0.671], [64680.7, 0.538], [64681.1, 1.238], [64681.2, 2.358], [64681.3, 1.179], [64681.4, 0.589], [64681.5, 0.101], [64682.4, 0.001], [64682.6, 0.028], [64682.9, 0.003], [64683.5, 0.002], [64684.0, 2.388], [64684.4, 0.877], [64684.5, 0.169], [64684.8, 0.117], [64685.7, 0.037], [64686.0, 0.151], [64686.8, 2.452], [64686.9, 0.545], [64687.0, 0.044], [64687.1, 0.156], [64687.6, 0.629], [64687.7, 0.841], [64687.8, 0.023], [64687.9, 1.469], [64688.0, 0.748], [64688.1, 0.07], [64688.2, 0.317], [64688.5, 0.06], [64688.6, 0.002], [64689.1, 0.001], [64690.0, 0.004], [64690.1, 0.004], [64690.5, 0.229], [64690.6, 0.0], [64692.1, 0.085], [64692.2, 0.004], [64692.4, 0.233], [64693.2, 0.0], [64693.7, 0.0], [64694.0, 0.087], [64694.1, 0.164], [64694.2, 23.624]], "asks": [[64694.3, 2.675], [64694.4, 0.036], [64694.5, 0.429], [64695.1, 0.847], [64695.2, 0.002], [64696.7, 0.002], [64696.8, 0.002], [64697.1, 0.004], [64697.3, 0.001], [64697.5, 0.008], [64697.6, 0.654], [64698.2, 0.003], [64698.4, 0.148], [64698.6, 0.003], [64699.1, 0.086], [64699.4, 0.006], [64699.5, 0.004], [64699.7, 0.089], [64699.8, 0.001], [64699.9, 0.002], [64700.0, 0.004], [64700.4, 0.283], [64700.5, 0.397], [64700.6, 0.002], [64700.7, 0.001], [64700.8, 0.67], [64701.0, 0.043], [64701.3, 0.057], [64701.8, 0.014], [64702.0, 0.238], [64702.3, 1.388], [64702.6, 0.114], [64702.7, 0.278], [64702.9, 0.675], [64703.0, 1.236], [64703.1, 0.314], [64704.5, 0.527], [64706.8, 0.008], [64708.5, 0.214], [64709.2, 0.417], [64709.8, 0.126], [64710.1, 0.044], [64710.2, 0.0], [64711.8, 1.088], [64711.9, 0.029], [64712.7, 0.164], [64713.3, 0.001], [64715.2, 1.157], [64715.5, 0.668], [64715.8, 0.0], [64716.7, 0.586], [64717.5, 0.002], [64725.6, 0.002], [64725.7, 0.004], [64725.8, 0.157], [64726.6, 2.211], [64728.1, 0.103], [64729.5, 0.005], [64734.8, 10.002], [64764.0, 1.676], [64764.1, 0.229], [64765.7, 34.875], [64766.3, 0.956], [64767.9, 0.022], [64769.4, 0.002], [64778.1, 2.514], [64778.9, 0.003], [64785.6, 1.115], [64828.2, 0.215], [64828.6, 3.864], [64835.4, 1.995], [64836.1, 0.001], [65017.8, 4.783], [65031.6, 0.004], [65052.3, 0.0], [65341.2, 2.523], [65697.1, 9.424]]}
{"kind": "depth", "E": 1787081883213, "U": 11315469354161, "u": 11315469364166, "recv_ms": 1787081883187, "bids": [[14494.2, 2.324], [14594.2, 1.876], [58224.7, 0.002], [61459.4, 0.0], [62106.4, 0.689], [63400.4, 0.084], [63694.2, 0.0], [63988.3, 7.188], [64047.3, 0.465], [64241.4, 0.0], [64370.7, 5.208], [64620.7, 36.008], [64627.3, 0.0], [64630.7, 0.015], [64661.9, 0.68], [64662.5, 0.0], [64663.0, 0.066], [64664.8, 0.704], [64668.5, 0.04], [64668.6, 0.001], [64672.2, 0.02], [64676.9, 0.081], [64677.9, 0.001], [64678.1, 1.374], [64679.0, 1.8], [64679.4, 0.008], [64679.7, 0.598], [64681.0, 0.9], [64681.3, 1.655], [64681.4, 0.126], [64681.5, 0.085], [64684.4, 1.197], [64684.5, 0.71], [64684.8, 0.596], [64686.9, 0.004], [64687.7, 0.841], [64688.0, 0.216], [64688.3, 0.366], [64689.2, 0.002], [64690.5, 0.317], [64690.6, 0.001], [64692.4, 0.001], [64692.8, 0.232], [64694.1, 0.153], [64694.2, 23.636]], "asks": [[64694.3, 2.76], [64696.0, 0.005], [64701.5, 0.288], [64701.6, 0.491], [64710.6, 0.082], [64711.3, 0.93], [64711.8, 0.163], [64711.9, 0.009], [64713.3, 0.021], [64713.8, 0.074], [64714.5, 1.542], [64715.2, 1.1], [64715.4, 0.126], [64716.7, 0.586], [64725.7, 0.004], [64725.8, 0.621], [64725.9, 0.156], [64733.2, 0.659], [64851.4, 9.015], [65333.0, 8.557], [65341.2, 2.523], [65600.0, 111.643], [65694.3, 0.0]]}
{"kind": "depth", "E": 1787081883315, "U": 11315469364196, "u": 11315469372438, "recv_ms": 1787081883284, "bids": [[14494.2, 2.688], [14594.2, 1.512], [58224.7, 0.002], [62106.4, 0.692], [64015.1, 0.39], [64047.3, 0.463], [64370.7, 5.198], [64616.5, 0.289], [64620.7, 0.183], [64627.3, 0.0], [64664.8, 0.086], [64668.5, 0.039], [64679.9, 0.158], [64683.9, 3.317], [64687.7, 0.841], [64688.0, 0.022], [64688.3, 0.003], [64692.0, 0.005], [64692.2, 0.001], [64693.0, 0.121], [64693.4, 0.084], [64694.2, 23.673]], "asks": [[64694.3, 2.766], [64697.5, 0.008], [64698.3, 0.298], [64715.5, 1.209], [64716.7, 0.045], [64725.8, 0.003], [64725.9, 0.156], [64733.2, 0.041], [64804.3, 1.392], [64851.4, 9.015], [65341.2, 2.523], [65473.9, 0.03], [65697.1, 10.488]]}
{"kind": "depth", "E": 1787081883417, "U": 11315469372635, "u": 11315469379802, "recv_ms": 1787081883387, "bids": [[1000.0, 35.81], [14494.2, 3.038], [14594.2, 1.162], [58224.7, 0.002], [61459.4, 0.0], [62106.4, 0.689], [62106.5, 0.0], [63102.9, 0.11], [63691.6, 0.0], [63694.2, 0.02], [63875.7, 1.445], [63982.6, 2.006], [64047.3, 0.463], [64237.4, 0.331], [64620.7, 36.008], [64627.3, 0.0], [64668.4, 1.061], [64675.6, 0.0], [64687.7, 0.841], [64688.0, 0.216], [64688.3, 0.003], [64689.1, 0.001], [64691.0, 0.019], [64692.2, 0.0]], "asks": [[64694.3, 2.756], [64696.3, 0.0], [64696.7, 0.002], [64697.0, 0.001], [64697.5, 0.018], [64698.2, 0.013], [64698.4, 0.159], [64698.8, 0.088], [64699.2, 0.002], [64702.7, 0.194], [64707.3, 0.038], [64718.3, 0.018], [64805.8, 0.097], [64823.7, 0.0], [64851.4, 11.873], [65341.2, 2.523], [65567.7, 7.357], [65694.3, 0.02]]}
{"kind": "depth", "E": 1787081883519, "U": 11315469379872, "u": 11315469386142, "recv_ms": 1787081883489, "bids": [[14494.2, 3.402], [14594.2, 0.798], [58224.7, 0.002], [61459.6, 2.443], [64047.3, 0.463], [64114.9, 0.0], [64620.7, 0.183], [64627.3, 35.825], [64668.4, 1.06], [64679.0, 2.097], [64686.9, 0.392], [64687.7, 1.567], [64688.0, 0.41], [64689.1, 0.727], [64694.2, 23.642]], "asks": [[65341.2, 2.523], [65470.6, 28.085], [65490.2, 3.398], [65669.1, 1.52], [66632.4, 0.003]]}
{"kind": "depth", "E": 1787081883621, "U": 11315469386324, "u": 11315469392720, "recv_ms": 1787081883589, "bids": [[14394.2, 0.028], [14494.2, 3.696], [14594.2, 0.476], [51755.0, 0.0], [58224.7, 0.002], [61459.5, 0.016], [62106.4, 0.692], [63694.2, 0.0], [63853.2, 9.228], [64107.0, 0.643], [64370.7, 5.198], [64424.0, 1.935], [64425.6, 0.581], [64553.1, 0.003], [64671.2, 0.005], [64671.7, 0.463], [64673.8, 0.118], [64674.2, 0.008], [64675.1, 0.007], [64681.2, 2.351], [64682.9, 0.01], [64686.9, 0.004], [64687.7, 1.229], [64689.1, 0.727], [64693.9, 0.086], [64694.0, 0.068]], "asks": [[64712.8, 0.558], [64714.5, 0.986], [64716.6, 0.121], [64718.0, 0.001], [64835.4, 0.001], [64835.5, 0.0], [65211.9, 8.417], [65341.2, 2.523], [65480.1, 0.764], [65480.3, 6.979], [65558.4, 2.605], [65609.7, 6.09], [65694.3, 0.0], [65821.4, 1.213]]}
{"kind": "depth", "E": 1787081883723, "U": 11315469393044, "u": 11315469399597, "recv_ms": 1787081883693, "bids": [[1000.0, 35.81], [14394.2, 0.196], [14494.2, 3.724], [14594.2, 0.28], [45286.0, 0.0], [51755.4, 0.0], [58224.7, 0.002], [62106.4, 0.689], [63691.4, 9.886], [63917.9, 32.794], [64112.0, 8.392], [64616.5, 0.289], [64635.9, 0.023], [64687.7, 0.841], [64689.1, 0.001]], "asks": [[64696.8, 0.002], [64725.9, 0.156], [64739.6, 0.003], [64804.3, 1.389], [65341.2, 2.523], [65988.1, 0.018]]}
{"kind": "depth", "E": 1787081883825, "U": 11315469399783, "u": 11315469416741, "recv_ms": 1787081883796, "bids": [[14394.2, 0.448], [14494.2, 3.584], [14594.2, 0.168], [58224.7, 0.002], [61459.4, 0.0], [62106.4, 0.692], [63694.2, 0.02], [63788.5, 12.965], [64047.3, 0.463], [64370.7, 5.199], [64497.3, 10.349], [64536.1, 0.028], [64536.2, 5.19], [64553.1, 4.834], [64590.1, 0.002], [64604.1, 0.011], [64611.5, 0.001], [64620.7, 36.008], [64626.3, 0.393], [64627.3, 0.0], [64642.9, 0.03], [64644.3, 1.471], [64652.5, 0.001], [64661.0, 0.237], [64661.9, 0.623], [64671.7, 0.462], [64672.6, 0.04], [64673.1, 1.156], [64673.8, 0.002], [64677.1, 0.926], [64677.5, 0.117], [64678.1, 0.448], [64680.7, 0.202], [64680.9, 0.349], [64686.2, 0.001], [64686.9, 0.392], [64687.7, 0.841], [64688.0, 0.022], [64688.3, 0.729], [64690.0, 0.005], [64692.8, 0.0], [64693.0, 0.084], [64693.2, 0.276], [64693.5, 0.143], [64694.0, 0.09], [64694.1, 0.153], [64694.2, 23.683]], "asks": [[64694.3, 2.611], [64694.5, 0.002], [64696.9, 0.0], [64697.2, 0.002], [64697.5, 0.018], [64697.6, 0.876], [64697.8, 0.009], [64698.2, 0.013], [64698.4, 0.008], [64698.5, 0.008], [64698.6, 1.902], [64698.8, 0.004], [64699.1, 0.002], [64699.7, 0.005], [64700.0, 0.128], [64700.1, 0.176], [64700.3, 1.927], [64700.5, 0.003], [64700.7, 2.042], [64700.8, 0.669], [64700.9, 1.555], [64701.0, 0.041], [64701.3, 0.057], [64701.5, 0.164], [64701.8, 0.016], [64702.0, 0.236], [64702.4, 0.049], [64702.7, 0.278], [64702.8, 0.1], [64702.9, 0.365], [64703.1, 0.398], [64703.4, 0.444], [64704.3, 0.003], [64706.8, 0.008], [64709.6, 0.463], [64710.5, 0.925], [64710.6, 0.09], [64711.3, 0.005], [64712.9, 0.16], [64713.8, 0.131], [64714.4, 0.005], [64714.5, 0.929], [64714.9, 0.007], [64718.3, 0.023], [64723.5, 2.326], [64725.1, 0.017], [64726.5, 0.015], [64732.3, 5.923], [64734.0, 0.061], [64734.5, 0.072], [64752.3, 0.002], [64753.4, 0.31], [64758.9, 0.231], [64765.7, 0.001], [64767.9, 34.896], [64768.3, 0.192], [64834.5, 5.556], [64851.4, 11.873], [64890.2, 0.003], [64890.3, 8.835], [65017.8, 4.782], [65211.9, 9.336], [65341.2, 2.523], [65414.0, 0.008], [65674.1, 0.77], [65694.3, 0.02]]}
{"kind": "depth", "E": 1787081883927, "U": 11315469416851, "u": 11315469426185, "recv_ms": 1787081883896, "bids": [[1000.0, 35.81], [14394.2, 0.672], [14494.2, 3.486], [14594.2, 0.042], [58224.7, 0.002], [61459.4, 0.0], [63875.7, 0.507], [64047.3, 0.463], [64370.7, 5.209], [64620.7, 0.183], [64624.9, 0.146], [64627.3, 35.825], [64647.5, 0.009], [64663.7, 0.171], [64682.6, 0.028], [64682.7, 0.156], [64683.4, 0.456], [64686.2, 0.0], [64686.4, 0.036], [64686.9, 0.004], [64687.7, 0.841], [64688.3, 0.003], [64694.2, 23.683]], "asks": [[64694.3, 2.61], [64694.5, 0.379], [64696.8, 0.002], [64697.5, 0.026], [64697.6, 1.427], [64698.4, 0.132], [64698.5, 2.346], [64700.0, 0.004], [64700.2, 0.023], [64700.3, 1.908], [64700.4, 0.305], [64700.5, 0.087], [64700.7, 0.125], [64700.8, 0.593], [64701.0, 0.043], [64701.3, 0.041], [64701.8, 0.014], [64703.3, 0.095], [64703.4, 0.444], [64704.1, 0.011], [64706.8, 0.101], [64707.2, 1.788], [64715.5, 1.169], [64718.6, 0.202], [64720.5, 1.217], [64724.9, 0.122], [64725.9, 0.002], [64726.0, 0.159], [64732.3, 5.803], [64736.6, 0.03], [64759.0, 0.365], [64759.3, 0.001], [64765.7, 34.875], [64767.9, 0.022], [64851.4, 1.465], [64851.5, 10.411], [65341.2, 2.523], [65535.3, 12.884], [66339.1, 1.506], [67204.0, 0.064]]}
{"kind": "depth", "E": 1787081884029, "U": 11315469426451, "u": 11315469433504, "recv_ms": 1787081884003, "bids": [[1000.0, 35.81], [14394.2, 0.994], [14494.2, 3.206], [14594.2, 0.0], [58224.7, 0.002], [61459.4, 0.0], [62106.4, 0.689], [63694.2, 0.0], [63847.3, 3.629], [63853.2, 10.167], [64047.3, 0.463], [64575.2, 0.0], [64591.6, 0.001], [64591.7, 2.406], [64629.7, 0.03], [64677.1, 0.0], [64677.8, 0.371], [64677.9, 0.927], [64679.4, 0.026], [64687.7, 0.841], [64694.2, 23.683]], "asks": [[64694.5, 0.38], [64700.1, 0.26], [64700.3, 1.93], [64700.4, 0.283], [64710.3, 0.214], [64711.9, 0.025], [64735.4, 0.31], [64763.5, 34.874], [64765.7, 0.001], [64773.2, 0.16], [64790.4, 3.717], [64791.6, 0.004], [64791.7, 0.219], [64795.1, 0.008], [64836.4, 0.0], [65341.2, 2.523], [65694.3, 0.0]]}
{"kind": "depth", "E": 1787081884131, "U": 11315469433552, "u": 11315469441215, "recv_ms": 1787081884103, "bids": [[14394.2, 1.344], [14494.2, 2.856], [58224.7, 0.002], [62106.4, 0.692], [63400.4, 0.084], [63700.9, 0.002], [63701.0, 1.402], [64047.3, 0.463], [64620.7, 36.352], [64625.3, 6.006], [64627.3, 0.0], [64628.9, 0.147], [64635.9, 0.026], [64648.0, 5.187], [64661.0, 0.18], [64661.9, 0.68], [64664.1, 3.41], [64670.0, 1.717], [64671.5, 0.561], [64672.1, 0.292], [64677.1, 0.0], [64677.9, 0.001], [64678.1, 1.374], [64682.6, 0.028], [64686.9, 0.004], [64687.7, 0.841], [64694.2, 23.683]], "asks": [[64694.3, 2.431], [64696.8, 0.002], [64701.8, 0.015], [64709.5, 0.006], [64710.5, 0.925], [64712.8, 0.558], [64713.8, 0.131], [64714.4, 0.005], [64715.4, 0.667], [64715.5, 0.628], [64722.4, 0.977], [64733.7, 2.25], [64738.6, 3.501], [64761.3, 6.0], [64763.5, 0.0], [64767.9, 34.636], [64804.3, 1.392], [64836.1, 1.153], [64894.1, 0.003], [64894.2, 4.684], [65341.2, 2.523], [65522.5, 4.166], [65687.5, 0.012], [65687.6, 0.028], [67188.9, 0.34]]}
{"kind": "depth", "E": 1787081884233, "U": 11315469441362, "u": 11315469450157, "recv_ms": 1787081884202, "bids": [[1000.0, 35.81], [14394.2, 1.694], [14494.2, 2.506], [58224.7, 0.002], [61459.4, 0.0], [62106.4, 0.689], [63694.2, 0.02], [63701.0, 1.42], [63820.8, 8.399], [64047.3, 0.463], [64370.7, 5.198], [64529.8, 0.02], [64536.2, 5.172], [64553.1, 0.003], [64553.2, 4.843], [64593.0, 10.003], [64661.8, 0.621], [64669.2, 0.623], [64670.0, 1.716], [64671.4, 0.024], [64677.1, 0.926], [64678.1, 0.448], [64686.9, 0.392], [64688.0, 0.748], [64694.2, 23.683]], "asks": [[64694.3, 2.511], [64701.8, 0.014], [64709.6, 1.388], [64710.5, 0.0], [64714.6, 0.764], [64715.4, 0.126], [64726.0, 0.005], [64726.2, 2.475], [64728.4, 0.62], [64735.8, 0.618], [64794.7, 10.001], [64834.5, 5.377], [64851.5, 7.53], [65017.8, 4.783], [65341.2, 2.523], [65470.6, 28.847], [65672.8, 1.11], [65687.6, 0.046], [65694.3, 0.02]]}
{"kind": "depth", "E": 1787081884335, "U": 11315469450186, "u": 11315469465377, "recv_ms": 1787081884304, "bids": [[1000.0, 35.81], [14394.2, 2.058], [14494.2, 2.142], [51755.0, 0.0], [58224.7, 0.002], [62106.4, 0.692], [63811.1, 1.599], [64047.3, 0.463], [64661.0, 0.18], [64661.9, 0.68], [64671.4, 0.023], [64672.8, 0.003], [64677.1, 0.0], [64678.0, 1.355], [64684.1, 1.172], [64686.9, 0.73], [64688.0, 0.022], [64690.6, 0.002]], "asks": [[64696.8, 0.002], [64709.6, 0.463], [64710.5, 0.925], [64712.8, 0.558], [64713.7, 0.059], [64713.8, 0.074], [64714.6, 0.223], [64715.4, 0.667], [64793.7, 0.021], [64793.8, 3.195], [64795.1, 0.0], [64851.5, 10.411], [65341.2, 2.523], [65681.6, 4.485]]}
{"kind": "depth", "E": 1787081884437, "U": 11315469465954, "u": 11315469476090, "recv_ms": 1787081884406, "bids": [[1000.0, 36.01], [14394.2, 2.422], [14494.2, 1.778], [51755.0, 0.0], [58224.7, 0.002], [61459.4, 0.0], [61459.6, 2.441], [63694.2, 0.0], [63769.4, 0.717], [64047.3, 0.463], [64670.6, 0.369], [64672.8, 0.002], [64686.9, 0.73]], "asks": [[64694.3, 2.512], [64823.7, 0.0], [65341.2, 2.523], [65341.3, 1.404], [65522.5, 3.938], [65669.3, 0.267], [65694.3, 0.0]]}
{"kind": "depth", "E": 1787081884539, "U": 11315469476223, "u": 11315469484535, "recv_ms": 1787081884508, "bids": [[1000.0, 36.01], [14394.2, 2.772], [14494.2, 1.428], [58224.7, 0.002], [61459.4, 0.0], [62106.4, 0.689], [63743.2, 2.983], [64047.3, 0.463], [64370.7, 5.198], [64635.7, 0.26], [64670.6, 0.368], [64673.5, 0.004], [64683.4, 0.455], [64686.9, 0.73], [64694.2, 23.705]], "asks": [[64696.8, 0.002], [64700.6, 0.312], [64704.1, 0.01], [64790.6, 0.126], [64890.3, 8.837], [65336.0, 13.197], [65341.2, 2.523], [65503.0, 8.714], [65584.5, 3.107], [65664.7, 15.203]]}
{"kind": "depth", "E": 1787081884641, "U": 11315469484767, "u": 11315469492405, "recv_ms": 1787081884610, "bids": [[1000.0, 36.01], [14394.2, 3.122], [14494.2, 1.078], [58224.7, 0.002], [61459.4, 0.0], [61459.5, 0.014], [61459.6, 2.443], [62106.4, 0.692], [63352.3, 0.002], [63694.2, 0.02], [63885.5, 10.503], [64047.3, 0.463], [64620.7, 0.183], [64627.3, 36.169], [64673.5, 0.003], [64678.9, 0.002], [64686.9, 0.73], [64694.2, 23.707]], "asks": [[64694.4, 0.037], [64705.0, 0.001], [64705.7, 0.349], [65341.2, 2.523], [65604.4, 0.761], [65694.3, 0.02], [71163.7, 0.002]]}
{"kind": "depth", "E": 1787081884743, "U": 11315469492644, "u": 11315469499437, "recv_ms": 1787081884711, "bids": [[14394.2, 3.486], [14494.2, 0.714], [51755.4, 0.0], [58224.7, 0.002], [62106.4, 0.689], [64047.3, 0.463], [64655.7, 0.17], [64676.9, 0.082], [64678.9, 0.001], [64682.7, 0.176], [64686.9, 0.004], [64687.8, 0.003]], "asks": [[65341.2, 2.523], [65426.6, 8.306], [65470.6, 28.238], [65561.6, 0.012], [71163.7, 0.0]]}
{"kind": "depth", "E": 1787081884845, "U": 11315469499595, "u": 11315469514848, "recv_ms": 1787081884814, "bids": [[1000.0, 36.01], [14294.2, 0.056], [14394.2, 3.724], [14494.2, 0.42], [58224.7, 0.002], [62106.4, 0.692], [63175.2, 0.004], [63694.2, 0.0], [63847.3, 3.004], [64047.3, 0.463], [64370.7, 5.197], [64536.2, 5.172], [64536.3, 1.181], [64553.2, 4.831], [64575.1, 0.285], [64629.6, 0.48], [64686.9, 0.004], [64687.0, 0.044], [64688.0, 0.022], [64690.3, 0.001]], "asks": [[64696.8, 0.002], [64735.3, 0.073], [64773.2, 0.329], [64834.5, 5.556], [64836.3, 2.744], [64851.2, 1.28], [64851.5, 10.411], [65341.2, 2.523], [65537.6, 1.525], [65681.6, 4.105], [65694.3, 0.0], [65988.1, 0.018]]}
{"kind": "depth", "E": 1787081884947, "U": 11315469515276, "u": 11315469547494, "recv_ms": 1787081884919, "bids": [[1000.0, 36.21], [14294.2, 0.252], [14394.2, 3.696], [14494.2, 0.252], [58224.7, 0.002], [61459.4, 0.0], [64047.3, 0.463], [64522.7, 0.016], [64553.2, 4.831], [64575.1, 0.004], [64575.2, 0.0], [64584.2, 0.381], [64604.1, 0.006], [64612.1, 0.005], [64616.5, 0.286], [64620.7, 36.352], [64621.9, 0.008], [64626.0, 0.237], [64626.3, 0.367], [64627.3, 0.0], [64628.5, 0.004], [64629.6, 0.311], [64629.7, 0.03], [64630.5, 0.001], [64632.2, 1.169], [64633.0, 0.093], [64635.9, 0.023], [64644.3, 1.261], [64653.1, 0.213], [64653.9, 2.319], [64658.2, 0.001], [64658.5, 0.213], [64660.7, 0.233], [64661.0, 0.148], [64661.8, 0.003], [64661.9, 0.623], [64662.1, 1.556], [64662.7, 2.846], [64663.1, 0.015], [64663.7, 0.228], [64664.1, 3.412], [64664.4, 0.566], [64664.8, 0.088], [64665.9, 0.002], [64666.2, 0.391], [64667.9, 2.328], [64668.0, 0.433], [64668.8, 0.028], [64668.9, 0.012], [64669.0, 0.001], [64669.1, 0.005], [64669.2, 0.005], [64669.7, 0.207], [64670.0, 1.71], [64671.4, 0.0], [64671.5, 0.01], [64671.8, 0.001], [64672.3, 0.0], [64672.4, 1.775], [64673.1, 1.04], [64673.2, 1.05], [64674.0, 0.646], [64674.7, 0.281], [64675.1, 0.001], [64675.3, 0.005], [64675.4, 0.427], [64675.7, 0.321], [64675.9, 0.003], [64676.4, 1.033], [64676.9, 0.001], [64678.0, 0.002], [64678.3, 0.002], [64678.4, 1.336], [64678.7, 0.016], [64679.2, 0.926], [64679.5, 0.025], [64680.3, 0.003], [64680.4, 0.003], [64680.5, 0.137], [64680.7, 0.162], [64680.9, 0.013], [64681.4, 0.126], [64681.5, 0.084], [64682.0, 0.038], [64682.7, 0.156], [64682.8, 0.512], [64682.9, 0.003], [64684.0, 2.326], [64684.1, 1.234], [64684.2, 0.475], [64684.4, 0.579], [64684.5, 0.161], [64684.6, 0.205], [64684.8, 0.122], [64685.0, 0.647], [64685.1, 0.07], [64685.3, 0.004], [64685.4, 0.036], [64685.9, 0.001], [64686.1, 0.004], [64686.3, 0.115], [64686.8, 2.452], [64686.9, 0.994], [64687.0, 0.036], [64687.4, 0.309], [64687.5, 0.075], [64687.6, 1.081], [64687.7, 0.003], [64687.8, 0.0], [64687.9, 2.69], [64688.0, 1.152], [64688.1, 0.533], [64688.3, 0.003], [64688.4, 0.056], [64688.9, 0.017], [64689.1, 0.047], [64689.8, 0.103], [64689.9, 0.557], [64690.0, 0.005], [64690.2, 0.164], [64690.4, 0.088], [64690.5, 0.543], [64690.8, 0.106], [64691.3, 0.058], [64691.7, 0.003], [64691.9, 0.001], [64692.0, 0.002], [64692.4, 0.004], [64693.2, 0.045], [64693.4, 0.084], [64693.6, 0.005], [64693.9, 0.318], [64694.2, 23.885]], "asks": [[64694.3, 1.05], [64694.4, 0.034], [64694.5, 0.002], [64694.6, 0.002], [64694.7, 0.055], [64695.4, 0.092], [64695.7, 0.009], [64696.1, 0.055], [64696.8, 0.012], [64697.4, 0.001], [64697.5, 1.008], [64697.6, 0.866], [64697.8, 0.002], [64698.2, 0.003], [64698.3, 0.295], [64698.4, 0.008], [64698.5, 0.0], [64698.8, 0.011], [64700.0, 0.128], [64700.1, 0.176], [64700.2, 0.012], [64700.3, 1.901], [64700.4, 0.123], [64700.5, 0.003], [64700.6, 0.002], [64700.7, 0.001], [64700.8, 0.568], [64700.9, 1.449], [64701.0, 0.04], [64701.1, 0.004], [64701.2, 0.0], [64701.6, 0.407], [64701.7, 0.047], [64702.1, 0.085], [64702.2, 2.323], [64702.3, 1.429], [64702.4, 0.051], [64703.3, 0.252], [64703.4, 0.568], [64703.8, 0.085], [64704.0, 0.281], [64704.1, 0.086], [64704.2, 0.876], [64704.5, 0.611], [64704.8, 0.254], [64705.1, 2.393], [64705.2, 0.092], [64705.3, 0.004], [64705.7, 0.0], [64705.9, 0.021], [64706.4, 0.274], [64706.6, 0.329], [64706.7, 0.003], [64706.8, 0.019], [64706.9, 0.003], [64707.0, 0.001], [64707.2, 1.633], [64707.5, 0.002], [64708.0, 0.001], [64708.5, 0.214], [64708.6, 0.124], [64709.0, 1.528], [64709.2, 0.353], [64709.3, 0.581], [64709.8, 0.002], [64710.0, 0.127], [64710.1, 0.004], [64710.4, 0.023], [64710.5, 0.463], [64710.6, 0.245], [64710.9, 0.52], [64711.0, 0.0], [64711.4, 0.094], [64711.7, 0.96], [64711.8, 0.002], [64712.7, 0.084], [64712.8, 0.002], [64713.0, 0.019], [64713.1, 0.01], [64713.2, 1.944], [64713.3, 0.008], [64713.4, 0.374], [64713.6, 0.64], [64713.7, 0.002], [64714.0, 0.166], [64714.4, 0.561], [64714.5, 0.929], [64714.9, 0.327], [64715.0, 0.01], [64715.4, 0.126], [64715.6, 0.646], [64715.8, 0.002], [64716.6, 0.006], [64716.7, 0.04], [64717.2, 0.004], [64717.3, 0.002], [64717.5, 0.555], [64718.0, 0.116], [64718.2, 2.472], [64718.3, 0.018], [64718.6, 0.162], [64719.1, 0.016], [64719.3, 0.002], [64719.5, 0.032], [64719.8, 0.017], [64720.0, 0.035], [64720.4, 0.002], [64720.5, 1.176], [64720.7, 0.008], [64721.5, 0.231], [64721.8, 0.078], [64722.1, 0.071], [64722.4, 0.982], [64723.4, 2.125], [64724.8, 1.094], [64724.9, 0.002], [64726.4, 0.011], [64726.8, 1.765], [64727.4, 0.001], [64727.5, 1.77], [64728.4, 0.002], [64729.1, 0.111], [64729.4, 0.002], [64731.1, 0.02], [64732.3, 5.803], [64732.4, 0.007], [64733.1, 0.144], [64733.8, 0.003], [64733.9, 0.038], [64734.6, 0.003], [64735.3, 0.0], [64735.5, 0.0], [64735.8, 0.0], [64737.0, 0.124], [64737.9, 0.161], [64738.1, 0.016], [64739.6, 0.003], [64740.1, 1.656], [64740.4, 0.223], [64742.4, 0.007], [64743.9, 0.079], [64744.1, 0.0], [64744.5, 0.021], [64745.0, 0.0], [64746.9, 0.0], [64747.0, 0.0], [64748.7, 0.02], [64749.0, 1.759], [64750.7, 0.027], [64768.3, 0.166], [64773.2, 0.16], [64775.0, 0.075], [64804.3, 1.389], [64805.8, 0.011], [64806.2, 0.085], [64834.5, 5.556], [64836.3, 2.462], [64836.4, 0.0], [64851.5, 0.003], [64853.7, 7.708], [64857.6, 2.053], [64890.3, 11.794], [65017.8, 4.784], [65341.2, 2.523], [65399.5, 4.134], [65470.6, 28.847], [65573.6, 1.824], [65988.1, 0.018]]}
{"kind": "depth", "E": 1787081885049, "U": 11315469548139, "u": 11315469567200, "recv_ms": 1787081885018, "bids": [[14294.2, 0.49], [14394.2, 3.57], [14494.2, 0.14], [58224.7, 0.002], [61459.4, 0.0], [62106.4, 0.689], [63694.2, 0.02], [63778.6, 0.015], [63820.8, 9.024], [63924.3, 8.44], [64047.3, 0.463], [64370.7, 5.207], [64620.7, 0.183], [64625.1, 0.002], [64627.3, 36.441], [64632.2, 1.157], [64634.1, 0.016], [64662.8, 0.066], [64663.7, 0.171], [64664.4, 0.548], [64666.4, 0.016], [64667.1, 0.059], [64668.8, 0.034], [64668.9, 0.006], [64674.5, 5.466], [64676.8, 0.004], [64677.0, 0.0], [64677.4, 0.004], [64677.6, 0.02], [64677.8, 0.371], [64678.4, 0.977], [64678.8, 0.926], [64679.2, 0.0], [64679.9, 0.078], [64681.4, 0.597], [64682.0, 0.906], [64682.6, 0.033], [64684.0, 2.357], [64684.2, 0.405], [64684.4, 0.572], [64684.5, 0.802], [64684.7, 0.38], [64684.8, 0.114], [64685.1, 0.611], [64685.7, 0.005], [64686.7, 0.002], [64686.9, 0.453], [64687.7, 0.073], [64688.0, 0.272], [64688.1, 0.07], [64688.3, 0.011], [64688.4, 0.003], [64689.0, 0.232], [64689.1, 0.001], [64689.8, 0.003], [64689.9, 0.589], [64690.5, 0.407], [64691.7, 0.002], [64691.9, 0.055], [64692.6, 0.101], [64693.5, 0.003], [64694.0, 0.303], [64694.2, 23.905]], "asks": [[64694.5, 0.001], [64694.7, 0.001], [64695.1, 0.0], [64695.4, 0.0], [64695.6, 0.835], [64696.1, 0.001], [64696.8, 0.012], [64697.4, 0.001], [64697.5, 0.026], [64698.2, 0.057], [64698.5, 0.008], [64698.9, 0.156], [64699.0, 1.012], [64700.2, 0.02], [64700.7, 0.542], [64700.8, 0.027], [64701.5, 0.248], [64701.8, 0.014], [64702.1, 0.008], [64702.2, 2.416], [64702.3, 1.388], [64702.6, 0.114], [64703.4, 0.444], [64703.5, 0.586], [64703.6, 0.095], [64704.4, 0.034], [64705.9, 0.001], [64706.9, 0.011], [64707.0, 0.464], [64710.3, 0.214], [64710.5, 0.0], [64711.4, 0.054], [64711.9, 0.017], [64713.2, 1.984], [64714.5, 0.986], [64715.6, 0.589], [64716.7, 0.581], [64717.5, 0.014], [64718.5, 0.359], [64720.7, 0.002], [64721.2, 0.434], [64723.4, 2.113], [64725.4, 0.03], [64725.9, 0.122], [64726.8, 1.716], [64731.1, 0.002], [64733.1, 0.038], [64748.7, 0.002], [64750.7, 0.03], [64751.0, 0.007], [64752.6, 0.129], [64767.9, 0.022], [64770.1, 35.029], [64772.3, 0.014], [64790.6, 0.026], [64851.5, 10.411], [64853.7, 0.027], [65341.2, 2.523], [65694.3, 0.02]]}
{"kind": "depth", "E": 1787081885151, "U": 11315469567283, "u": 11315469583049, "recv_ms": 1787081885122, "bids": [[1000.0, 36.21], [14294.2, 0.728], [14394.2, 3.458], [14494.2, 0.014], [51755.0, 0.0], [58224.7, 0.002], [62106.4, 0.692], [63076.8, 0.476], [63701.0, 1.42], [63959.2, 0.781], [63973.0, 1.413], [64047.3, 0.465], [64150.8, 0.044], [64594.7, 2.519], [64620.7, 0.183], [64627.3, 0.0], [64628.9, 0.147], [64629.5, 36.48], [64662.3, 0.078], [64662.8, 0.009], [64667.2, 1.125], [64668.0, 0.317], [64674.4, 0.085], [64678.4, 1.903], [64678.8, 0.0], [64681.4, 0.589], [64682.6, 0.028], [64683.9, 3.397], [64684.2, 0.335], [64684.4, 0.362], [64684.7, 0.31], [64685.2, 0.009], [64687.4, 0.379], [64687.5, 0.075], [64687.7, 0.143], [64688.0, 0.192], [64688.3, 0.011], [64688.4, 0.002], [64688.7, 0.037], [64689.3, 0.04], [64690.6, 0.001], [64692.8, 0.002], [64694.2, 24.022]], "asks": [[64694.3, 1.027], [64695.0, 0.012], [64696.8, 0.002], [64697.5, 0.016], [64702.0, 0.131], [64703.0, 0.336], [64703.1, 0.503], [64703.6, 0.115], [64703.7, 0.022], [64704.6, 0.314], [64704.7, 0.003], [64706.6, 0.309], [64710.8, 3.263], [64711.7, 0.035], [64713.2, 1.964], [64717.5, 0.042], [64717.7, 0.478], [64767.9, 34.403], [64769.2, 2.055], [64770.1, 0.648], [64851.2, 2.671], [65341.2, 2.525], [65470.6, 29.061], [65687.6, 0.035], [65810.9, 0.0], [71163.8, 0.0]]}
{"kind": "depth", "E": 1787081885253, "U": 11315469583139, "u": 11315469602840, "recv_ms": 1787081885222, "bids": [[1000.0, 36.21], [14294.2, 1.078], [14394.2, 3.122], [14494.2, 0.0], [51755.0, 0.0], [58224.7, 0.002], [61459.4, 0.0], [62106.4, 0.689], [63694.2, 0.0], [63924.3, 9.377], [64031.0, 0.004], [64047.3, 0.463], [64370.7, 5.208], [64622.9, 36.444], [64629.5, 0.039], [64630.6, 0.0], [64635.7, 0.16], [64663.8, 0.002], [64681.4, 0.126], [64684.5, 0.702], [64684.8, 0.014], [64685.2, 0.572], [64685.4, 0.004], [64686.1, 0.003], [64686.4, 0.004], [64687.5, 0.075], [64687.6, 1.151], [64687.8, 0.1], [64687.9, 2.79], [64688.1, 0.27], [64688.2, 0.387], [64688.3, 0.111], [64688.4, 0.002], [64688.5, 0.06], [64689.6, 0.048], [64692.8, 0.061], [64694.2, 23.906]], "asks": [[64695.3, 0.0], [64695.6, 0.0], [64696.5, 0.132], [64696.6, 0.832], [64697.1, 0.004], [64703.4, 0.311], [64704.1, 0.097], [64705.0, 0.901], [64706.9, 0.003], [64707.0, 0.001], [64707.6, 0.003], [64708.6, 0.0], [64709.0, 0.628], [64709.8, 0.126], [64710.6, 0.716], [64711.7, 0.168], [64714.0, 0.006], [64714.7, 0.933], [64715.5, 0.628], [64716.7, 0.581], [64727.3, 0.073], [64734.5, 0.002], [64738.9, 0.0], [65017.8, 4.783], [65025.9, 0.001], [65034.3, 0.466], [65341.2, 2.523], [65567.7, 8.879], [65609.7, 6.851], [65687.6, 0.046], [65694.3, 0.0], [65794.1, 7.723]]}
{"kind": "depth", "E": 1787081885355, "U": 11315469602967, "u": 11315469635662, "recv_ms": 1787081885361, "bids": [[14294.2, 1.316], [14296.4, 0.014], [14296.5, 0.098], [14394.2, 2.772], [58224.7, 0.0], [58226.8, 0.002], [61459.4, 0.0], [63756.1, 23.461], [64047.3, 0.463], [64049.5, 1.171], [64352.0, 11.0], [64360.5, 0.129], [64370.7, 5.198], [64547.3, 0.015], [64557.8, 0.409], [64559.9, 0.001], [64572.7, 0.004], [64587.4, 0.408], [64588.7, 0.0], [64594.8, 0.0], [64612.1, 0.0], [64614.0, 0.762], [64614.1, 36.441], [64614.5, 0.022], [64616.0, 3.375], [64616.7, 0.053], [64617.6, 6.317], [64618.5, 0.006], [64619.6, 0.24], [64622.9, 0.003], [64627.3, 0.0], [64627.6, 0.462], [64629.5, 0.04], [64631.2, 0.119], [64632.0, 2.057], [64633.0, 0.067], [64634.1, 0.016], [64634.9, 0.048], [64635.8, 0.0], [64635.9, 0.026], [64636.2, 0.002], [64636.4, 0.0], [64638.5, 2.828], [64641.3, 2.112], [64641.4, 0.006], [64645.0, 0.936], [64646.2, 2.339], [64646.4, 6.038], [64646.5, 0.381], [64648.6, 0.0], [64648.9, 0.0], [64649.6, 2.422], [64649.7, 0.052], [64650.2, 0.442], [64650.8, 2.319], [64650.9, 0.02], [64651.9, 2.781], [64653.4, 0.016], [64654.2, 0.0], [64655.9, 0.0], [64657.9, 2.544], [64658.2, 0.005], [64659.4, 0.006], [64660.0, 0.521], [64660.3, 0.003], [64661.3, 0.002], [64661.4, 1.661], [64661.5, 0.01], [64661.6, 0.008], [64662.3, 0.021], [64663.4, 0.201], [64663.5, 0.003], [64663.6, 0.144], [64663.7, 0.173], [64664.0, 1.733], [64664.8, 0.086], [64664.9, 0.0], [64665.0, 0.054], [64666.2, 0.364], [64666.3, 0.0], [64666.4, 0.002], [64666.5, 0.565], [64666.8, 0.007], [64667.0, 0.006], [64667.1, 0.061], [64667.2, 1.127], [64667.8, 0.715], [64668.1, 0.232], [64668.8, 0.025], [64669.4, 0.114], [64669.6, 0.371], [64669.7, 0.192], [64670.4, 1.155], [64670.5, 0.265], [64670.7, 0.204], [64671.0, 2.349], [64671.4, 0.0], [64671.5, 0.036], [64672.0, 0.779], [64673.0, 0.001], [64673.6, 2.981], [64673.7, 0.213], [64674.0, 0.644], [64674.2, 0.001], [64674.8, 0.243], [64675.1, 0.0], [64675.2, 2.716], [64675.5, 0.122], [64675.8, 0.008], [64676.0, 0.802], [64676.2, 0.002], [64676.4, 0.033], [64676.8, 0.663], [64677.3, 2.321], [64677.5, 0.117], [64677.8, 0.525], [64678.2, 1.092], [64678.4, 0.977], [64679.0, 1.197], [64679.1, 0.253], [64679.3, 0.002], [64679.4, 0.019], [64679.6, 0.31], [64679.7, 0.444], [64679.8, 0.929], [64680.0, 1.079], [64680.3, 0.003], [64681.1, 1.237], [64681.2, 2.331], [64681.3, 1.652], [64681.4, 0.127], [64681.5, 0.004], [64681.6, 0.052], [64681.8, 0.208], [64681.9, 0.157], [64682.2, 0.003], [64682.3, 0.078], [64682.7, 0.005], [64682.8, 0.464], [64683.0, 0.9], [64683.2, 0.003], [64683.5, 0.002], [64683.6, 0.006], [64683.8, 0.061], [64683.9, 3.383], [64684.0, 2.334], [64684.1, 1.176], [64684.2, 0.791], [64684.3, 0.595], [64684.4, 0.346], [64684.5, 0.158], [64684.6, 0.205], [64684.8, 0.02], [64684.9, 0.336], [64685.0, 0.211], [64685.1, 0.0], [64685.2, 0.104], [64685.3, 0.004], [64685.4, 0.004], [64685.5, 0.158], [64685.6, 0.009], [64685.7, 0.005], [64685.9, 0.0], [64686.0, 0.123], [64686.3, 0.045], [64686.5, 0.001], [64686.7, 0.002], [64686.8, 2.449], [64686.9, 0.004], [64687.0, 0.035], [64687.1, 0.517], [64687.2, 0.002], [64687.7, 0.142], [64687.9, 2.683], [64688.0, 0.795], [64688.1, 0.896], [64688.2, 0.399], [64688.3, 0.105], [64688.4, 0.092], [64688.5, 0.067], [64688.7, 0.277], [64688.8, 0.008], [64688.9, 0.018], [64689.0, 0.033], [64689.3, 0.13], [64689.5, 0.152], [64689.9, 0.508], [64690.0, 0.012], [64690.1, 0.005], [64690.2, 0.161], [64690.4, 0.091], [64690.7, 0.204], [64690.8, 0.086], [64690.9, 0.383], [64691.0, 0.215], [64691.2, 0.094], [64691.3, 0.0], [64691.7, 0.006], [64691.9, 0.063], [64692.0, 0.004], [64692.2, 0.001], [64692.4, 0.002], [64692.7, 0.002], [64692.8, 0.063], [64692.9, 0.001], [64693.1, 0.001], [64693.2, 0.002], [64693.3, 0.006], [64693.4, 0.13], [64693.5, 0.004], [64693.6, 0.0], [64693.7, 0.001], [64693.9, 0.086], [64694.0, 0.091], [64694.1, 0.142], [64694.2, 7.913], [64694.3, 4.693], [64694.4, 0.003], [64694.5, 0.0], [64694.6, 0.0], [64694.8, 0.002], [64694.9, 0.0], [64695.0, 0.003], [64695.1, 0.0], [64695.2, 0.001], [64695.3, 0.002], [64695.6, 0.0], [64695.7, 0.0], [64695.8, 0.0], [64695.9, 0.003], [64696.0, 0.001], [64696.1, 0.31], [64696.2, 0.198], [64696.3, 0.002], [64696.4, 14.027], [64696.5, 25.075]], "asks": [[64694.3, 0.0], [64694.4, 0.0], [64694.5, 0.0], [64694.6, 0.0], [64694.7, 0.0], [64694.9, 0.0], [64695.0, 0.0], [64695.2, 0.0], [64695.7, 0.0], [64695.8, 0.0], [64695.9, 0.0], [64696.0, 0.0], [64696.1, 0.0], [64696.2, 0.0], [64696.5, 0.0], [64696.6, 1.112], [64696.7, 0.002], [64696.8, 0.001], [64697.1, 0.001], [64697.2, 0.001], [64697.4, 0.011], [64697.5, 0.005], [64697.6, 0.279], [64697.7, 0.001], [64697.8, 0.002], [64697.9, 0.0], [64698.0, 0.001], [64698.1, 0.0], [64698.2, 0.057], [64698.3, 0.296], [64698.4, 0.003], [64698.5, 0.0], [64698.6, 0.0], [64698.7, 0.004], [64698.8, 0.003], [64699.0, 0.012], [64699.3, 0.002], [64699.4, 0.007], [64699.5, 0.001], [64699.6, 0.003], [64699.7, 0.002], [64699.8, 0.003], [64700.0, 0.004], [64700.1, 0.08], [64700.2, 0.004], [64700.3, 0.0], [64700.4, 0.003], [64700.5, 0.004], [64700.6, 1.443], [64700.7, 0.001], [64700.8, 0.028], [64700.9, 0.978], [64701.0, 0.037], [64701.1, 0.006], [64701.3, 0.004], [64701.5, 0.004], [64701.7, 0.049], [64701.8, 0.014], [64702.0, 0.047], [64702.2, 0.004], [64702.3, 0.003], [64702.4, 0.047], [64702.5, 0.009], [64702.6, 0.154], [64702.7, 0.191], [64702.8, 0.224], [64702.9, 0.352], [64703.1, 0.415], [64703.2, 0.316], [64703.3, 0.091], [64703.5, 0.29], [64703.6, 0.095], [64703.7, 0.001], [64703.9, 0.008], [64704.0, 0.266], [64704.1, 0.097], [64704.3, 0.045], [64704.4, 0.017], [64704.6, 0.314], [64704.7, 0.002], [64704.8, 0.414], [64704.9, 0.098], [64705.0, 0.913], [64705.1, 2.392], [64705.2, 0.084], [64705.3, 0.002], [64705.5, 0.005], [64705.6, 0.089], [64705.7, 0.001], [64706.0, 0.32], [64706.2, 0.003], [64706.6, 0.0], [64706.9, 0.019], [64707.0, 0.619], [64707.1, 0.513], [64707.2, 1.632], [64707.3, 0.042], [64707.4, 1.251], [64707.6, 0.04], [64707.9, 0.176], [64708.9, 0.008], [64709.0, 0.0], [64709.3, 0.501], [64709.4, 0.037], [64709.6, 0.466], [64709.9, 0.001], [64710.0, 0.127], [64710.1, 0.096], [64710.5, 0.008], [64710.6, 0.627], [64710.8, 2.349], [64710.9, 0.416], [64711.2, 0.38], [64711.3, 0.005], [64712.0, 0.003], [64712.1, 0.0], [64712.3, 0.044], [64712.6, 0.003], [64712.7, 0.004], [64712.8, 0.929], [64712.9, 0.16], [64713.0, 0.012], [64713.2, 1.81], [64713.3, 0.001], [64713.6, 0.642], [64714.5, 0.929], [64714.7, 0.773], [64714.8, 0.001], [64714.9, 0.001], [64715.3, 0.125], [64715.5, 0.628], [64715.6, 0.59], [64715.8, 0.057], [64715.9, 0.682], [64716.1, 1.8], [64716.3, 0.16], [64716.7, 0.032], [64716.8, 1.403], [64717.0, 0.008], [64717.1, 0.106], [64717.3, 0.002], [64717.5, 0.049], [64717.6, 0.901], [64717.7, 0.003], [64718.0, 0.001], [64718.1, 0.548], [64718.3, 0.019], [64718.4, 1.979], [64718.6, 0.328], [64719.4, 0.474], [64719.6, 0.122], [64719.8, 0.013], [64720.0, 0.021], [64720.2, 0.74], [64720.4, 0.014], [64720.7, 0.092], [64721.0, 0.022], [64721.1, 0.631], [64721.2, 0.428], [64721.3, 0.062], [64722.4, 0.977], [64723.0, 0.002], [64723.2, 0.385], [64724.0, 0.16], [64724.2, 0.226], [64724.6, 0.076], [64725.3, 0.164], [64725.4, 0.024], [64726.2, 2.475], [64726.4, 0.006], [64726.6, 2.212], [64726.8, 1.715], [64727.0, 0.227], [64727.1, 0.31], [64727.3, 0.003], [64728.0, 1.183], [64728.7, 0.001], [64730.2, 0.12], [64730.7, 0.024], [64731.4, 0.387], [64731.9, 1.243], [64733.1, 0.024], [64733.6, 0.165], [64733.7, 0.856], [64733.8, 0.073], [64734.8, 0.004], [64736.0, 0.025], [64736.5, 0.003], [64736.7, 1.202], [64737.0, 0.118], [64737.1, 0.042], [64737.2, 0.077], [64738.6, 3.503], [64739.7, 0.094], [64740.1, 1.653], [64740.6, 10.001], [64741.3, 0.002], [64741.4, 0.063], [64742.4, 0.008], [64743.5, 0.004], [64744.3, 0.007], [64744.4, 0.0], [64746.2, 0.001], [64746.3, 0.003], [64746.5, 0.059], [64747.5, 0.0], [64748.2, 0.001], [64748.3, 0.02], [64750.3, 0.481], [64750.7, 0.013], [64751.0, 0.003], [64751.5, 0.014], [64752.4, 0.0], [64752.6, 0.115], [64752.8, 0.002], [64754.3, 0.0], [64754.8, 0.004], [64755.7, 0.018], [64759.0, 0.366], [64766.7, 0.004], [64766.8, 0.0], [64767.9, 0.022], [64770.1, 0.648], [64770.8, 0.04], [64771.9, 0.095], [64772.3, 34.395], [64773.9, 0.002], [64775.0, 0.049], [64776.0, 3.276], [64776.9, 0.049], [64790.4, 3.716], [64791.3, 0.029], [64797.8, 0.035], [64798.6, 2.149], [64798.7, 0.0], [64805.9, 0.003], [64806.2, 0.0], [64806.5, 0.003], [64806.9, 2.11], [64807.0, 0.021], [64807.9, 0.0], [64808.8, 0.018], [64810.6, 0.901], [64826.0, 0.029], [64833.0, 0.176], [64851.5, 0.003], [64853.8, 10.408], [64872.0, 3.514], [64890.3, 0.002], [64892.6, 63.78], [65019.9, 0.002], [65042.9, 0.442], [65341.2, 2.523], [65343.6, 0.002], [65438.3, 0.909], [65438.8, 0.908], [65438.9, 0.917], [65440.9, 12.094], [65503.0, 7.958], [65503.5, 2.268], [65505.5, 6.048], [65794.1, 8.482], [65988.1, 0.021], [65990.5, 0.006]]}
{"kind": "depth", "E": 1787081885457, "U": 11315469635732, "u": 11315469658863, "recv_ms": 1787081885430, "bids": [[1000.0, 36.21], [14296.5, 0.448], [14394.2, 2.422], [34000.0, 1.146], [58226.8, 0.002], [61461.6, 0.0], [62108.6, 0.003], [63402.6, 0.008], [63696.5, 0.02], [64049.5, 1.171], [64497.3, 0.0], [64500.1, 13.182], [64516.6, 0.007], [64519.8, 0.0], [64536.2, 0.032], [64536.3, 0.444], [64538.9, 7.782], [64593.0, 0.003], [64594.7, 1.177], [64601.6, 2.324], [64614.1, 0.0], [64620.7, 0.183], [64621.7, 0.009], [64622.9, 36.444], [64625.3, 0.006], [64628.9, 0.193], [64629.0, 5.729], [64629.1, 0.442], [64630.6, 0.032], [64633.3, 0.008], [64634.1, 0.004], [64635.3, 0.419], [64642.9, 1.5], [64643.0, 0.029], [64647.5, 0.001], [64648.0, 1.687], [64649.8, 0.012], [64653.4, 0.015], [64654.6, 0.375], [64656.8, 1.531], [64658.9, 0.002], [64661.4, 1.539], [64663.4, 0.144], [64664.0, 1.709], [64664.1, 2.422], [64664.7, 0.067], [64664.8, 0.084], [64665.6, 0.088], [64666.1, 0.1], [64666.7, 0.12], [64666.8, 0.001], [64667.1, 0.067], [64667.6, 0.039], [64668.0, 0.315], [64668.8, 0.022], [64669.8, 0.008], [64669.9, 0.18], [64670.2, 0.037], [64670.8, 0.039], [64673.0, 0.003], [64673.2, 0.444], [64673.6, 3.414], [64674.4, 0.082], [64674.8, 0.242], [64675.2, 2.719], [64675.4, 0.347], [64676.0, 0.339], [64676.1, 0.618], [64677.4, 0.036], [64678.0, 0.45], [64678.1, 0.0], [64678.6, 0.002], [64679.8, 0.003], [64680.0, 1.081], [64680.8, 1.556], [64680.9, 0.062], [64681.6, 0.229], [64681.7, 0.004], [64681.8, 0.206], [64683.1, 0.0], [64683.2, 0.003], [64684.0, 2.341], [64684.3, 0.525], [64684.4, 0.354], [64684.5, 0.058], [64684.6, 0.005], [64685.1, 0.014], [64685.2, 0.194], [64685.6, 0.001], [64685.8, 0.159], [64687.3, 0.008], [64688.1, 0.819], [64688.5, 0.06], [64689.0, 0.496], [64689.1, 0.009], [64690.0, 0.004], [64690.5, 0.569], [64691.3, 0.068], [64691.7, 0.002], [64691.8, 0.001], [64691.9, 0.055], [64692.0, 0.004], [64692.2, 0.001], [64692.4, 0.002], [64693.2, 0.003], [64693.8, 0.004], [64694.0, 0.069], [64694.1, 0.141], [64694.2, 7.815], [64694.3, 4.695], [64694.4, 0.014], [64696.2, 0.05], [64696.3, 0.001], [64696.4, 0.989], [64696.5, 38.024]], "asks": [[64696.6, 1.113], [64697.4, 0.001], [64697.6, 0.006], [64698.8, 0.001], [64699.0, 0.012], [64699.5, 0.637], [64699.6, 1.812], [64699.7, 0.002], [64699.8, 0.013], [64700.1, 0.078], [64700.3, 0.008], [64700.4, 0.127], [64700.5, 1.689], [64700.6, 0.443], [64700.9, 1.012], [64701.0, 0.04], [64701.7, 1.049], [64702.1, 0.092], [64702.4, 0.055], [64702.5, 2.32], [64702.6, 0.154], [64702.8, 0.1], [64703.0, 0.42], [64703.3, 0.093], [64703.6, 0.099], [64703.9, 0.0], [64704.1, 0.097], [64704.3, 0.003], [64704.4, 0.014], [64704.8, 0.254], [64704.9, 0.089], [64705.0, 0.913], [64705.1, 2.392], [64705.3, 0.0], [64705.4, 0.003], [64705.5, 0.027], [64705.6, 0.249], [64705.9, 0.024], [64706.0, 0.343], [64706.1, 0.023], [64706.5, 0.002], [64706.9, 0.003], [64707.0, 0.001], [64707.2, 1.069], [64707.4, 1.231], [64707.6, 0.037], [64707.8, 0.242], [64708.1, 0.025], [64708.5, 0.004], [64709.3, 0.581], [64710.5, 0.101], [64710.6, 0.712], [64711.5, 0.21], [64712.0, 0.903], [64712.8, 0.004], [64713.1, 0.473], [64713.2, 1.443], [64713.7, 0.925], [64714.4, 0.005], [64715.4, 0.682], [64715.5, 0.648], [64715.8, 0.0], [64715.9, 0.843], [64716.3, 0.0], [64716.9, 0.779], [64717.1, 0.453], [64717.5, 0.049], [64718.1, 0.007], [64718.9, 0.224], [64720.1, 0.557], [64720.4, 0.002], [64720.5, 1.177], [64720.6, 0.137], [64720.7, 0.01], [64722.1, 0.075], [64722.3, 0.442], [64723.2, 0.384], [64724.6, 0.076], [64725.3, 0.152], [64725.4, 0.018], [64725.7, 0.01], [64726.2, 2.321], [64726.6, 2.224], [64727.0, 0.073], [64727.2, 0.008], [64728.6, 0.0], [64730.5, 0.154], [64730.7, 0.0], [64732.2, 0.004], [64734.2, 0.019], [64739.9, 2.352], [64740.6, 10.003], [64740.9, 0.026], [64742.2, 0.0], [64744.5, 0.029], [64748.3, 0.001], [64748.8, 0.005], [64749.8, 0.342], [64750.3, 0.466], [64751.2, 0.322], [64751.8, 0.019], [64753.7, 2.333], [64758.3, 0.0], [64759.0, 0.338], [64760.5, 0.061], [64764.1, 0.183], [64770.1, 0.648], [64771.4, 0.144], [64772.3, 0.014], [64774.5, 34.382], [64802.1, 0.461], [64802.2, 0.005], [64808.3, 0.103], [64810.2, 0.0], [64822.8, 3.79], [64822.9, 0.001], [64823.5, 1.481], [64823.6, 0.211], [64828.6, 0.0], [64838.4, 3.964], [64851.2, 1.28], [64853.8, 0.0], [64857.4, 7.572], [64892.6, 50.876], [64896.2, 6.336], [64896.3, 2.23], [65155.2, 0.002], [65341.3, 1.403], [65343.6, 0.0], [65438.3, 0.001], [65438.8, 0.0], [65438.9, 0.001], [65440.9, 14.818], [65503.5, 0.0], [65505.5, 8.316], [65522.5, 3.71], [65530.1, 6.83], [65584.5, 2.727], [65696.6, 0.021], [65990.5, 0.015]]}
