{"kind": "depth", "E": 1787081860161, "U": 11315467773772, "u": 11315467779792, "recv_ms": 1787081860130, "bids": [[14394.2, 1.456], [14494.2, 2.744], [58224.7, 0.002], [61459.4, 0.0], [62106.4, 0.692], [63400.4, 0.084], [63701.0, 1.42], [64047.3, 0.073], [64215.3, 55.157], [64370.7, 0.932], [64623.8, 0.0], [64638.5, 3.034], [64645.3, 0.004], [64672.5, 0.235], [64673.8, 0.002], [64673.9, 0.58], [64675.1, 2.907], [64677.8, 0.44], [64679.2, 0.995], [64679.7, 0.01], [64680.1, 0.001], [64681.2, 0.916], [64681.3, 0.093], [64693.9, 0.002], [64694.0, 0.0], [64694.1, 0.009]], "asks": [[64696.8, 0.013], [64697.5, 0.038], [64699.6, 0.001], [64699.8, 0.549], [64703.2, 0.398], [64703.9, 0.012], [64713.4, 0.374], [64714.3, 0.558], [64715.4, 0.446], [64715.6, 0.629], [64717.3, 0.002], [64718.0, 0.116], [64726.2, 2.321], [64742.4, 0.011], [64750.9, 0.0], [65180.4, 52.061], [65341.2, 2.294], [65554.3, 0.001], [65687.6, 0.036]]}
{"kind": "depth", "E": 1787081860263, "U": 11315467779840, "u": 11315467784909, "recv_ms": 1787081860231, "bids": [[1000.0, 35.81], [14394.2, 1.806], [14494.2, 2.394], [51755.0, 0.0], [58224.7, 0.002], [61459.4, 0.0], [62106.4, 0.689], [63719.8, 0.031], [63808.4, 0.939], [63847.2, 0.0], [64047.2, 0.025], [64047.3, 0.073], [64370.7, 0.931], [64469.3, 0.001], [64498.8, 0.258], [64624.2, 0.001], [64673.4, 0.557], [64673.9, 0.023], [64677.8, 0.44], [64689.7, 0.0], [64694.2, 44.91]], "asks": [[64697.6, 1.055], [64698.4, 0.129], [64698.6, 1.917], [64698.8, 0.006], [64699.8, 0.001], [64699.9, 0.002], [64700.0, 0.552], [64700.7, 0.001], [64700.9, 0.978], [64701.5, 0.257], [64701.6, 1.902], [64701.7, 0.237], [64701.9, 0.501], [64702.5, 0.107], [64703.6, 0.006], [64703.9, 0.011], [64704.1, 0.473], [64704.2, 1.427], [64710.3, 0.214], [65017.8, 0.941], [65341.2, 2.294], [65496.0, 0.012], [65687.6, 0.046], [65983.2, 0.0]]}
{"kind": "depth", "E": 1787081860365, "U": 11315467785050, "u": 11315467790544, "recv_ms": 1787081860334, "bids": [[1000.0, 35.81], [14394.2, 2.156], [14494.2, 2.044], [51755.0, 0.0], [58224.7, 0.002], [61459.4, 0.001], [63620.7, 13.183], [63694.2, 0.0], [63853.1, 3.287], [63963.8, 4.846], [64047.3, 0.073], [64370.7, 0.932], [64623.2, 0.0], [64644.4, 0.002], [64644.7, 0.244], [64645.0, 0.937], [64645.4, 0.678], [64645.7, 0.185], [64646.2, 2.355], [64659.3, 0.262], [64659.4, 0.006], [64659.5, 0.0], [64659.6, 0.321], [64659.7, 0.001], [64659.8, 0.005], [64659.9, 0.002], [64660.0, 0.523], [64660.1, 0.018], [64660.3, 0.0], [64664.8, 0.072], [64665.2, 0.138], [64665.8, 0.016], [64666.1, 0.0], [64666.4, 0.002], [64666.8, 0.001], [64667.1, 0.059], [64670.5, 5.238], [64672.6, 0.561], [64673.4, 0.0], [64673.9, 0.139], [64674.7, 0.008], [64675.1, 2.791], [64678.0, 1.828], [64679.2, 0.069], [64681.7, 0.001], [64682.1, 0.027], [64684.3, 0.144], [64684.8, 0.868], [64685.5, 0.242], [64685.6, 0.004], [64685.7, 0.002], [64685.8, 0.323], [64685.9, 0.0], [64686.0, 0.441], [64686.1, 0.104], [64686.2, 0.008], [64686.3, 0.095], [64686.4, 0.001], [64686.5, 0.002], [64686.8, 0.002], [64687.1, 0.281], [64687.4, 0.0], [64687.7, 0.087], [64687.9, 0.264], [64688.1, 0.147], [64689.7, 0.0], [64690.2, 1.248], [64694.2, 47.396]], "asks": [[64697.0, 0.003], [64700.3, 0.0], [64701.6, 0.001], [64702.0, 0.108], [64703.6, 0.09], [64703.9, 0.043], [64704.1, 0.01], [64704.2, 1.419], [64704.3, 0.003], [64704.6, 0.328], [64704.9, 0.007], [64705.2, 0.0], [64705.6, 0.009], [64705.8, 0.196], [64705.9, 0.016], [64706.0, 1.431], [64706.1, 0.003], [64706.2, 0.002], [64706.3, 0.005], [64706.4, 0.093], [64706.5, 0.022], [64706.6, 0.0], [64706.7, 0.003], [64706.8, 0.0], [64707.1, 0.763], [64712.8, 0.558], [64714.3, 0.002], [64715.4, 0.987], [64716.7, 0.155], [64718.0, 0.001], [64721.2, 0.238], [64724.7, 0.032], [64725.5, 0.001], [64725.8, 0.003], [64726.1, 0.0], [64726.3, 0.156], [64726.4, 0.006], [64726.7, 6.032], [64727.1, 0.31], [64727.5, 1.77], [64729.4, 0.002], [64731.3, 0.266], [64731.9, 1.34], [64732.0, 0.041], [64732.2, 0.004], [64732.3, 2.321], [64732.4, 0.007], [64732.5, 0.041], [64732.6, 0.059], [64732.7, 0.026], [64732.8, 0.007], [64732.9, 0.166], [64733.0, 0.002], [64745.6, 0.037], [64746.6, 0.029], [64747.0, 0.0], [64747.3, 0.001], [64747.6, 0.369], [64747.9, 9.027], [64754.9, 4.248], [64823.7, 0.0], [64851.1, 0.0], [64851.2, 10.419], [65017.8, 0.942], [65341.2, 2.294], [65526.9, 4.114], [65544.4, 0.0], [65694.3, 0.0]]}
{"kind": "depth", "E": 1787081860467, "U": 11315467790636, "u": 11315467796705, "recv_ms": 1787081860436, "bids": [[14394.2, 2.52], [14494.2, 1.68], [51755.4, 0.0], [58224.7, 0.002], [61459.4, 0.0], [61459.5, 0.028], [62106.4, 0.692], [63723.8, 5.677], [63781.5, 1.408], [63820.8, 5.74], [64047.3, 0.073], [64302.1, 2.047], [64370.7, 0.932], [64597.2, 0.014], [64645.2, 0.032], [64645.5, 0.034], [64655.3, 4.211], [64684.3, 0.067], [64684.9, 0.424], [64685.6, 0.074], [64685.8, 0.423], [64685.9, 0.2], [64686.1, 0.204], [64686.2, 0.078], [64686.3, 0.195], [64686.4, 0.071], [64687.0, 0.068], [64687.3, 0.297]], "asks": [[64700.0, 0.004], [64701.5, 0.164], [64704.1, 1.122], [64704.5, 2.363], [64704.8, 0.049], [64705.4, 0.115], [64705.6, 0.297], [64705.7, 0.211], [64705.9, 0.166], [64706.0, 1.741], [64706.2, 0.107], [64707.1, 0.292], [64712.8, 0.002], [64713.7, 0.558], [64715.4, 0.446], [64716.7, 0.581], [64717.6, 0.116], [64725.4, 0.214], [64725.7, 0.049], [64726.3, 0.002], [64726.4, 0.35], [64726.8, 1.872], [64731.0, 0.501], [64731.2, 1.41], [64731.5, 0.152], [64731.6, 0.143], [64731.8, 0.399], [64746.3, 0.044], [64746.6, 0.074], [64752.0, 1.675], [65341.2, 2.294], [65480.3, 2.401]]}
{"kind": "depth", "E": 1787081860569, "U": 11315467796819, "u": 11315467803386, "recv_ms": 1787081860538, "bids": [[1000.0, 35.81], [14394.2, 2.884], [14494.2, 1.316], [58224.7, 0.002], [61458.9, 0.0], [61459.4, 0.0], [62106.4, 0.689], [63400.4, 0.081], [63597.7, 0.629], [63694.2, 0.02], [63769.6, 7.748], [63937.3, 1.664], [64047.3, 0.073], [64102.1, 0.012], [64176.6, 1.873], [64644.9, 0.036], [64645.9, 5.048], [64685.5, 0.312], [64685.6, 0.144], [64685.7, 0.072], [64685.9, 0.3], [64686.6, 0.033], [64687.6, 0.034], [64689.7, 0.004], [64694.2, 47.426]], "asks": [[64696.8, 0.003], [64697.5, 0.028], [64704.2, 1.457], [64705.2, 0.045], [64705.9, 0.301], [64706.1, 0.094], [64706.2, 0.226], [64706.3, 0.103], [64712.4, 0.052], [64725.1, 0.055], [64726.0, 0.05], [64731.4, 0.541], [64731.6, 0.234], [64731.7, 4.04], [64731.9, 1.438], [64745.9, 0.039], [64746.9, 0.045], [64793.7, 0.021], [64793.8, 3.211], [65282.5, 2.142], [65341.2, 2.294], [65535.5, 2.319], [65560.7, 0.0], [65694.3, 0.02]]}
{"kind": "depth", "E": 1787081860773, "U": 11315467808913, "u": 11315467815023, "recv_ms": 1787081860741, "bids": [[14394.2, 3.584], [14494.2, 0.616], [58224.7, 0.002], [61459.4, 0.0], [62106.4, 0.689], [63400.4, 0.084], [63694.2, 0.0], [63885.5, 4.021], [64047.3, 0.073], [64067.6, 64.006], [64370.7, 0.942], [64536.5, 0.919], [64624.4, 0.032], [64624.7, 0.032], [64635.9, 0.026], [64641.4, 2.116], [64641.5, 0.006], [64658.0, 2.132], [64659.9, 0.072], [64660.5, 0.1], [64677.5, 0.338], [64680.1, 0.464], [64681.2, 0.453], [64689.7, 0.004], [64692.6, 0.004], [64693.1, 0.552], [64694.2, 47.426]], "asks": [[64694.3, 3.33], [64696.8, 0.011], [64697.0, 0.003], [64698.6, 1.909], [64703.2, 0.088], [64726.5, 0.287], [64726.6, 2.211], [64728.4, 0.004], [64729.6, 3.504], [64732.6, 10.059], [64790.5, 2.105], [64790.6, 0.026], [64798.8, 2.105], [64798.9, 0.0], [64804.3, 1.392], [64807.1, 6.809], [64894.2, 4.684], [64963.3, 5.261], [65332.2, 65.084], [65341.2, 2.294], [65554.9, 0.307], [65694.3, 0.0], [65988.1, 0.009]]}
{"kind": "depth", "E": 1787081860875, "U": 11315467815110, "u": 11315467822368, "recv_ms": 1787081860843, "bids": [[1000.0, 35.81], [14294.2, 0.084], [14394.2, 3.78], [14494.2, 0.336], [58224.7, 0.002], [63858.9, 9.069], [64043.3, 1.411], [64047.3, 0.073], [64551.5, 0.015], [64551.6, 4.483], [64575.6, 0.0], [64584.2, 0.378], [64624.0, 0.079], [64625.0, 1.622], [64630.1, 2.987], [64635.9, 0.026], [64660.0, 0.593], [64660.2, 0.731], [64660.3, 0.1], [64660.6, 0.171], [64660.8, 1.254], [64665.0, 0.156], [64665.4, 0.102], [64667.9, 2.328], [64673.1, 1.635], [64673.6, 0.659], [64689.7, 0.0], [64694.2, 47.439]], "asks": [[64696.8, 0.021], [64697.5, 0.028], [64716.9, 0.719], [64718.5, 0.31], [64723.7, 3.827], [64735.8, 0.0], [64739.6, 0.003], [64773.6, 0.003], [64804.3, 1.389], [64836.8, 1.191], [65276.6, 5.748], [65341.2, 2.294], [65411.8, 0.916], [65538.0, 1.554]]}
{"kind": "depth", "E": 1787081860977, "U": 11315467822455, "u": 11315467826737, "recv_ms": 1787081860945, "bids": [[1000.0, 35.81], [14294.2, 0.322], [14394.2, 3.654], [14494.2, 0.224], [58224.7, 0.002], [61459.5, 0.022], [62106.4, 0.692], [62116.4, 0.002], [63694.2, 0.02], [63729.5, 6.53], [64047.3, 0.073], [64381.0, 0.428], [64383.8, 0.399], [64575.6, 0.0], [64630.1, 2.987], [64659.9, 0.142], [64660.1, 0.158], [64660.3, 0.2], [64679.7, 0.018], [64681.3, 0.085]], "asks": [[64697.5, 0.038], [64700.2, 1.09], [64735.8, 0.0], [64742.4, 0.007], [64750.9, 0.004], [64773.6, 0.003], [64836.8, 1.191], [65276.5, 2.753], [65341.2, 2.294], [65535.3, 8.618], [65593.3, 2.283], [65694.3, 0.02], [65852.0, 0.0], [71163.8, 0.0]]}
{"kind": "depth", "E": 1787081861079, "U": 11315467826812, "u": 11315467833561, "recv_ms": 1787081861047, "bids": [[14294.2, 0.56], [14394.2, 3.542], [14494.2, 0.098], [51755.0, 0.0], [58224.7, 0.002], [62106.4, 0.689], [63519.4, 0.786], [64047.3, 0.073], [64150.8, 0.077], [64370.7, 0.942], [64372.1, 0.108], [64575.6, 0.0], [64630.1, 2.987], [64660.1, 0.228], [64660.4, 0.071], [64682.6, 0.028]], "asks": [[64697.0, 0.003], [64735.8, 0.0], [64773.6, 0.003], [64836.8, 1.191], [65341.2, 2.294], [65405.9, 6.243], [65503.0, 2.696], [65519.8, 4.654], [65593.3, 1.522]]}
{"kind": "depth", "E": 1787081861181, "U": 11315467833824, "u": 11315467840795, "recv_ms": 1787081861149, "bids": [[1000.0, 35.81], [14294.2, 0.812], [14394.2, 3.388], [14494.2, 0.0], [51755.0, 0.0], [58224.7, 0.002], [61459.4, 0.0], [61459.6, 2.445], [62106.4, 0.692], [63694.2, 0.0], [63853.2, 4.144], [63912.0, 8.769], [64047.3, 0.073], [64495.6, 3.006], [64495.8, 11.442], [64534.5, 0.001], [64534.6, 5.437], [64536.5, 0.001], [64551.6, 4.54], [64575.6, 0.0], [64630.1, 2.987], [64670.9, 2.776], [64678.3, 2.939], [64680.1, 0.001], [64681.2, 0.916], [64689.7, 0.004]], "asks": [[64694.3, 3.32], [64704.1, 1.123], [64719.7, 0.633], [64727.1, 0.928], [64735.8, 0.0], [64744.1, 0.004], [64750.9, 0.0], [64773.6, 0.003], [64834.2, 5.406], [64836.8, 1.191], [64890.0, 10.927], [65341.2, 2.294], [65405.9, 6.472], [65567.7, 4.334], [65694.3, 0.0]]}
{"kind": "depth", "E": 1787081861385, "U": 11315467846764, "u": 11315467852173, "recv_ms": 1787081861352, "bids": [[14294.2, 1.526], [14394.2, 2.674], [58224.7, 0.002], [62106.4, 0.689], [63694.2, 0.02], [63858.9, 7.662], [63912.0, 8.067], [64047.3, 0.073], [64370.7, 0.941], [64638.5, 3.034], [64645.3, 0.0]], "asks": [[64823.7, 0.001], [65017.8, 0.941], [65282.4, 3.761], [65341.2, 2.294], [65694.3, 0.02], [65852.2, 0.758]]}
{"kind": "depth", "E": 1787081861487, "U": 11315467852302, "u": 11315467856625, "recv_ms": 1787081861454, "bids": [[1000.0, 35.81], [14294.2, 1.89], [14394.2, 2.31], [51755.4, 0.0], [58224.7, 0.002], [61459.4, 0.0], [61459.6, 2.443], [62106.4, 0.692], [63781.5, 0.0], [63842.8, 0.787], [63885.5, 4.138], [64047.3, 0.073], [64370.7, 0.942], [64551.6, 3.327], [64575.5, 0.012], [64630.0, 2.333], [64645.3, 0.004], [64689.7, 0.0], [64694.2, 47.426]], "asks": [[64697.0, 0.003], [64704.1, 1.122], [64735.7, 0.197], [64773.6, 0.003], [64823.7, 0.0], [64836.8, 1.191], [65017.8, 0.942], [65341.2, 2.294]]}
{"kind": "depth", "E": 1787081861589, "U": 11315467856933, "u": 11315467861328, "recv_ms": 1787081861557, "bids": [[14294.2, 2.254], [14394.2, 1.946], [51755.0, 0.0], [58224.7, 0.002], [61459.5, 0.024], [62106.4, 0.689], [63694.2, 0.0], [63853.1, 4.381], [63885.5, 4.841], [63972.9, 0.787], [64047.3, 0.073], [64504.3, 0.0], [64532.3, 0.019], [64551.6, 0.014], [64551.7, 4.568], [64627.7, 4.653], [64680.1, 0.464], [64681.2, 0.453]], "asks": [[64760.4, 2.784], [64760.5, 0.0], [65341.2, 2.294], [65503.0, 3.458], [65535.5, 3.385], [65694.3, 0.0], [70512.4, 0.0], [71163.8, 0.0]]}
{"kind": "depth", "E": 1787081861691, "U": 11315467861365, "u": 11315467865734, "recv_ms": 1787081861659, "bids": [[14294.2, 2.604], [14394.2, 1.596], [51755.0, 0.0], [58224.7, 0.002], [61459.4, 0.0], [61459.6, 2.441], [62106.4, 0.692], [63400.4, 0.087], [63594.4, 2.228], [63723.8, 7.087], [63853.2, 4.457], [64047.3, 0.073], [64370.7, 0.932], [64603.7, 0.086], [64603.8, 0.229], [64661.3, 0.004], [64661.4, 1.663], [64661.5, 0.069], [64664.8, 0.072], [64664.9, 0.002], [64665.0, 0.156], [64678.3, 2.321], [64680.1, 0.464], [64681.2, 0.453], [64681.3, 0.085], [64689.7, 0.0], [64692.6, 0.001], [64693.1, 0.493], [64694.2, 47.422]], "asks": [[64694.3, 3.21], [64697.0, 0.003], [64697.3, 1.669], [64697.5, 0.038], [64719.7, 0.015], [65276.5, 2.982], [65341.2, 2.294]]}
{"kind": "depth", "E": 1787081861793, "U": 11315467866148, "u": 11315467871849, "recv_ms": 1787081861761, "bids": [[1000.0, 35.81], [14294.2, 2.954], [14394.2, 1.246], [51755.0, 0.0], [58224.7, 0.002], [61459.5, 0.018], [63694.2, 0.02], [64047.3, 0.073], [64150.8, 0.081], [64495.8, 9.992], [64495.9, 2.852], [64534.8, 1.011], [64575.4, 0.0], [64575.5, 0.012], [64629.9, 0.0], [64689.7, 0.0], [64694.2, 47.422]], "asks": [[64694.3, 3.195], [64695.2, 0.435], [64697.2, 0.018], [64697.5, 0.028], [64698.6, 1.901], [64701.0, 0.063], [64701.7, 0.235], [64704.7, 0.22], [64707.5, 0.002], [64710.6, 0.082], [64717.6, 1.009], [64726.3, 0.002], [64726.4, 0.35], [64726.5, 0.133], [64735.6, 0.118], [64773.5, 1.093], [64836.7, 0.101], [65341.2, 2.294], [65620.7, 10.218], [65674.4, 1.52], [65694.3, 0.02]]}
{"kind": "depth", "E": 1787081861895, "U": 11315467871868, "u": 11315467876329, "recv_ms": 1787081861864, "bids": [[14294.2, 3.318], [14394.2, 0.882], [58224.7, 0.002], [62106.4, 0.689], [63782.0, 1.399], [64047.3, 0.073], [64176.7, 0.003]], "asks": [[64726.4, 0.196], [64726.5, 0.133], [64890.0, 10.93], [65336.0, 19.145], [65593.6, 2.281], [65955.8, 1.361], [68571.7, 0.0], [72500.0, 6.202]]}
{"kind": "depth", "E": 1787081861997, "U": 11315467876416, "u": 11315467880026, "recv_ms": 1787081861964, "bids": [[14294.2, 3.668], [14394.2, 0.532], [58224.7, 0.002], [62106.4, 0.692], [63694.2, 0.0], [64047.3, 0.073], [64370.7, 0.932], [64679.7, 0.01], [64681.2, 0.461]], "asks": [[64697.2, 0.01], [64698.5, 0.008], [64726.5, 0.287], [65341.2, 2.294], [65447.9, 0.777], [65629.8, 1.367], [65694.3, 0.0]]}
{"kind": "depth", "E": 1787081862099, "U": 11315467880057, "u": 11315467885481, "recv_ms": 1787081862067, "bids": [[1000.0, 35.81], [14194.2, 0.14], [14294.2, 3.752], [14394.2, 0.308], [58224.7, 0.002], [61459.4, 0.0], [62106.4, 0.689], [62116.4, 0.001], [63137.6, 0.0], [63400.4, 0.084], [63594.4, 3.169], [63619.6, 0.0], [64047.3, 0.073], [64176.6, 2.803], [64635.9, 0.026], [64682.6, 0.028], [64689.7, 0.0], [64692.2, 0.003], [64693.0, 0.06], [64694.1, 0.008], [64694.2, 47.422]], "asks": [[64694.3, 3.044], [64696.8, 0.011], [64697.0, 0.003], [64713.9, 0.466], [64727.1, 0.31], [64739.6, 0.0], [64744.1, 0.0], [64750.9, 0.004], [65341.2, 2.294], [65411.8, 0.687]]}
{"kind": "depth", "E": 1787081862201, "U": 11315467885587, "u": 11315467891114, "recv_ms": 1787081862169, "bids": [[14194.2, 0.378], [14294.2, 3.626], [14394.2, 0.196], [58224.7, 0.002], [61459.4, 0.001], [61459.6, 2.439], [62106.4, 0.692], [63562.1, 3.774], [63694.2, 0.02], [63858.9, 7.349], [64047.3, 0.073], [64551.7, 0.043], [64575.5, 0.012], [64630.0, 2.333], [64638.5, 3.038], [64645.3, 0.0], [64670.9, 2.158], [64675.8, 0.001], [64677.9, 0.002], [64681.3, 0.005], [64683.1, 0.087], [64689.7, 0.0], [64692.2, 0.0], [64694.2, 47.421]], "asks": [[64694.3, 3.042], [64696.8, 0.011], [64702.8, 0.09], [64719.4, 0.473], [64726.5, 0.133], [64726.6, 2.365], [64726.7, 6.032], [64735.7, 0.197], [64773.6, 0.003], [64834.2, 0.008], [64836.7, 0.101], [65308.9, 2.298], [65341.2, 2.296], [65426.6, 11.735], [65694.3, 0.02]]}
{"kind": "depth", "E": 1787081862303, "U": 11315467891158, "u": 11315467895425, "recv_ms": 1787081862270, "bids": [[1000.0, 35.81], [14194.2, 0.616], [14294.2, 3.514], [14394.2, 0.07], [51755.0, 0.0], [58224.7, 0.002], [61459.4, 0.0], [63545.9, 1.414], [64047.3, 0.073], [64133.8, 0.001], [64370.7, 0.942], [64410.1, 0.013], [64551.7, 4.568], [64576.1, 0.0], [64627.5, 6.0], [64638.5, 3.034], [64645.3, 0.004], [64656.6, 0.007], [64675.8, 0.001], [64677.8, 0.44], [64683.1, 0.087], [64689.7, 0.004], [64691.7, 0.002], [64694.1, 0.009]], "asks": [[64694.3, 3.061], [64710.3, 0.214], [64726.5, 0.133], [64726.6, 2.211], [64726.9, 0.155], [64744.1, 0.004], [64748.3, 0.001], [64750.9, 0.0], [64771.5, 0.0], [64833.9, 1.25], [64834.2, 5.406], [64890.0, 10.931], [65008.3, 0.0], [65257.2, 0.272], [65341.2, 2.294], [65399.5, 0.704], [65413.9, 0.465], [65512.6, 0.763], [65988.1, 0.012]]}
{"kind": "depth", "E": 1787081862405, "U": 11315467895520, "u": 11315467899332, "recv_ms": 1787081862373, "bids": [[1000.0, 35.81], [14194.2, 0.896], [14294.2, 3.304], [14394.2, 0.0], [58224.7, 0.002], [61459.4, 0.0], [61459.5, 0.016], [61459.6, 2.441], [62106.4, 0.689], [63270.9, 0.003], [63694.2, 0.0], [63853.2, 4.77], [64047.3, 0.073], [64150.8, 0.223], [64551.7, 0.043], [64575.5, 0.012], [64630.0, 2.333], [64674.3, 0.337], [64677.5, 0.002], [64682.4, 0.081], [64683.1, 0.007], [64689.7, 0.0], [64694.2, 47.434]], "asks": [[64694.3, 3.062], [64696.8, 0.011], [64697.0, 0.003], [64702.8, 0.089], [64735.7, 0.197], [64744.1, 0.0], [64750.9, 0.0], [64773.6, 0.003], [64823.7, 0.0], [64834.2, 0.008], [64836.7, 0.101], [65284.6, 1.07], [65341.2, 2.294], [65405.9, 6.701], [65694.3, 0.0]]}
{"kind": "depth", "E": 1787081862507, "U": 11315467899398, "u": 11315467906207, "recv_ms": 1787081862475, "bids": [[14194.2, 1.26], [14294.2, 2.94], [51755.4, 0.0], [58224.7, 0.002], [61459.4, 0.0], [62106.4, 0.692], [63012.1, 0.001], [64047.3, 0.073], [64150.8, 0.228], [64370.7, 0.942], [64534.6, 0.523], [64534.8, 0.143], [64689.7, 0.0], [64694.2, 47.434]], "asks": [[64694.3, 3.037], [64696.8, 0.011], [64744.1, 0.004], [64851.2, 0.011], [65017.8, 0.941], [65341.2, 2.294], [65753.9, 0.002]]}
{"kind": "depth", "E": 1787081862609, "U": 11315467906319, "u": 11315467912761, "recv_ms": 1787081862577, "bids": [[1000.0, 35.81], [14194.2, 1.624], [14294.2, 2.576], [51755.0, 0.0], [58224.7, 0.002], [61459.5, 0.01], [62106.4, 0.689], [63529.7, 0.63], [63694.2, 0.02], [64047.3, 0.073], [64370.7, 0.942]], "asks": [[64696.8, 0.021], [64701.8, 2.32], [64702.0, 0.085], [64702.1, 0.03], [65276.7, 1.071], [65341.2, 2.294], [65406.0, 1.262], [65694.3, 0.02]]}
{"kind": "depth", "E": 1787081862711, "U": 11315467912775, "u": 11315467919652, "recv_ms": 1787081862679, "bids": [[1000.0, 35.81], [14194.2, 1.974], [14294.2, 2.226], [58224.7, 0.002], [61459.4, 0.0], [61459.5, 0.012], [63723.8, 7.385], [64047.3, 0.073], [64234.1, 0.0], [64495.8, 0.0], [64495.9, 7.131], [64534.8, 2.503], [64551.7, 2.556], [64575.5, 0.012], [64627.7, 1.915], [64630.0, 2.333], [64689.7, 0.0], [64694.2, 47.434]], "asks": [[64694.3, 3.022], [64697.0, 0.003], [64725.4, 0.2], [64735.7, 0.197], [64760.4, 0.0], [64773.6, 0.003], [64834.2, 5.406], [64836.7, 0.101], [64851.2, 10.419], [64890.0, 16.07], [64894.8, 0.003], [64894.9, 4.792], [65017.8, 0.942], [65341.2, 2.294], [65803.8, 1.529], [65988.1, 0.015]]}
{"kind": "depth", "E": 1787081862813, "U": 11315467919874, "u": 11315467925126, "recv_ms": 1787081862781, "bids": [[14194.2, 2.338], [14294.2, 1.862], [58224.7, 0.002], [62106.4, 0.692], [63694.2, 0.0], [64047.3, 0.073], [64495.9, 0.059], [64496.0, 10.009], [64534.8, 5.062], [64536.3, 0.797], [64551.7, 0.043], [64551.8, 4.739], [64627.7, 4.675], [64661.9, 0.623], [64694.2, 47.532]], "asks": [[64713.8, 0.072], [64723.4, 1.705], [64726.7, 6.186], [64726.9, 0.001], [64744.1, 0.0], [64750.9, 0.004], [64760.4, 2.757], [64890.0, 10.924], [65341.2, 2.294], [65476.5, 15.525], [65503.0, 3.686], [65519.8, 4.312], [65545.0, 2.197], [65545.1, 0.762], [65694.3, 0.0]]}
{"kind": "depth", "E": 1787081862915, "U": 11315467925129, "u": 11315467929839, "recv_ms": 1787081862883, "bids": [[1000.0, 35.81], [14194.2, 2.688], [14294.2, 1.512], [58224.7, 0.002], [61459.4, 0.0], [62106.4, 0.689], [63270.9, 0.0], [64047.3, 0.073], [64308.5, 0.002], [64314.9, 0.92], [64370.7, 0.932], [64551.8, 2.869], [64575.5, 0.012], [64626.9, 0.006], [64627.5, 0.0], [64627.7, 1.915], [64630.0, 2.333], [64638.8, 0.084], [64645.3, 0.004], [64650.1, 0.0], [64666.3, 0.115], [64668.7, 2.116], [64674.9, 0.019], [64676.8, 0.663], [64681.8, 0.206], [64684.9, 0.432], [64689.7, 0.004], [64693.9, 0.002], [64694.0, 0.002], [64694.2, 47.519]], "asks": [[64715.1, 0.061], [64715.8, 0.002], [64724.3, 0.016], [64726.4, 0.35], [64726.7, 6.032], [64726.8, 1.872], [64735.7, 0.197], [64740.5, 0.0], [64750.9, 0.004], [64757.4, 0.078], [64760.4, 0.0], [64762.5, 0.026], [64762.8, 1.501], [64763.1, 0.002], [64773.6, 0.003], [64836.7, 0.101], [65341.2, 2.294], [65560.7, 0.0], [65567.3, 0.004], [65629.8, 1.14]]}
{"kind": "depth", "E": 1787081863017, "U": 11315467929951, "u": 11315467936389, "recv_ms": 1787081862985, "bids": [[1000.0, 35.81], [14194.2, 3.038], [14294.2, 1.162], [58224.7, 0.002], [62106.4, 0.692], [63400.4, 0.081], [63694.2, 0.02], [64047.3, 0.073], [64595.7, 0.007], [64598.1, 0.996], [64622.9, 0.003], [64623.0, 0.014], [64625.1, 42.734], [64627.1, 7.359], [64627.5, 6.0], [64627.7, 4.675], [64629.5, 0.035], [64650.2, 3.943], [64655.0, 0.145], [64666.3, 1.085], [64680.1, 0.001], [64681.2, 0.924], [64685.8, 0.44]], "asks": [[64702.0, 0.104], [64723.9, 1.283], [64740.0, 4.615], [64760.4, 2.723], [64762.6, 2.053], [64762.7, 6.072], [64762.8, 0.57], [64793.8, 1.713], [64795.5, 0.001], [65341.2, 2.294], [65487.4, 1.586], [65658.0, 0.861], [65659.7, 0.001], [65691.8, 0.0], [65694.3, 0.02]]}
{"kind": "depth", "E": 1787081863119, "U": 11315467936418, "u": 11315467942808, "recv_ms": 1787081863087, "bids": [[14194.2, 3.402], [14294.2, 0.798], [58224.7, 0.002], [62106.4, 0.689], [63701.0, 1.4], [64047.3, 0.073], [64117.7, 7.01], [64551.8, 4.762], [64575.5, 0.012], [64618.5, 42.729], [64625.1, 0.002], [64627.1, 1.099], [64630.0, 2.333], [64682.6, 0.028], [64685.8, 0.131], [64687.0, 0.377]], "asks": [[64706.0, 1.742], [64735.7, 0.197], [64744.1, 0.004], [64750.3, 0.466], [64750.9, 0.0], [64773.6, 0.003], [64781.3, 0.019], [64793.7, 0.013], [64795.1, 0.008], [64836.7, 0.101], [65284.5, 2.602], [65341.2, 2.296], [65470.6, 7.994], [65632.4, 13.273], [65687.6, 0.026], [65803.8, 2.288]]}
{"kind": "depth", "E": 1787081863221, "U": 11315467942860, "u": 11315467951865, "recv_ms": 1787081863195, "bids": [[1000.0, 35.81], [14194.2, 3.696], [14294.2, 0.476], [14594.2, 0.028], [58224.7, 0.002], [61459.4, 0.0], [63694.2, 0.0], [63701.0, 1.42], [63918.0, 9.343], [63924.3, 9.377], [63924.4, 3.137], [64370.7, 0.942], [64587.4, 0.411], [64595.8, 10.786], [64598.1, 2.361], [64624.3, 0.179], [64625.4, 0.002], [64656.6, 0.127], [64665.2, 0.018], [64666.5, 0.524], [64669.5, 0.016], [64671.7, 0.5], [64672.0, 0.78], [64674.3, 0.337], [64675.2, 1.678], [64678.5, 0.005], [64680.0, 0.552], [64680.3, 0.003], [64680.4, 0.003], [64681.2, 0.916], [64681.7, 0.001], [64682.8, 0.049], [64684.2, 0.025], [64684.3, 0.043], [64684.9, 0.424], [64686.2, 0.07], [64687.0, 0.068], [64688.0, 0.343], [64689.7, 0.004], [64691.2, 1.828], [64692.2, 0.084], [64693.0, 0.0], [64693.1, 0.179], [64693.5, 0.003], [64693.8, 0.003], [64694.2, 47.419]], "asks": [[64694.3, 3.07], [64696.4, 0.31], [64696.7, 0.005], [64696.9, 0.911], [64697.0, 0.003], [64697.3, 1.753], [64697.8, 0.086], [64698.7, 2.981], [64699.7, 0.086], [64700.9, 0.981], [64702.5, 0.023], [64703.0, 0.313], [64703.2, 0.004], [64703.4, 1.24], [64703.6, 0.006], [64721.7, 0.003], [64726.4, 0.35], [64729.1, 0.639], [64731.8, 0.339], [64738.5, 2.058], [64793.8, 3.21], [64795.0, 0.033], [64795.1, 10.0], [64890.0, 10.853], [65276.6, 5.977], [65341.2, 2.294], [65687.6, 0.035], [65694.3, 0.0], [67929.0, 0.005]]}
{"kind": "depth", "E": 1787081863323, "U": 11315467951904, "u": 11315468003909, "recv_ms": 1787081863299, "bids": [[1000.0, 35.81], [14194.2, 3.724], [14294.2, 0.28], [14594.2, 0.196], [51755.0, 0.0], [58224.7, 0.002], [61459.4, 0.0], [62106.4, 0.692], [63694.2, 0.02], [64047.3, 0.081], [64230.0, 0.849], [64349.5, 0.115], [64353.1, 0.325], [64424.0, 4.574], [64496.0, 11.295], [64522.7, 0.228], [64532.3, 0.0], [64532.4, 0.215], [64538.0, 0.492], [64574.6, 0.281], [64575.4, 0.0], [64579.4, 3.913], [64579.6, 0.432], [64580.2, 8.248], [64583.4, 0.003], [64585.4, 0.0], [64588.3, 2.32], [64588.9, 0.0], [64590.6, 0.217], [64592.9, 0.082], [64593.9, 0.032], [64594.2, 0.001], [64598.4, 0.029], [64600.9, 0.369], [64602.7, 1.237], [64604.0, 0.405], [64606.0, 5.518], [64606.1, 1.111], [64606.5, 0.0], [64608.1, 0.035], [64611.3, 1.078], [64613.1, 1.868], [64613.2, 0.0], [64613.7, 0.099], [64616.9, 0.018], [64617.6, 6.318], [64617.8, 0.029], [64618.4, 0.001], [64618.5, 42.729], [64619.4, 0.004], [64620.0, 3.049], [64620.7, 42.901], [64620.9, 0.072], [64621.2, 0.256], [64622.1, 0.08], [64622.4, 3.368], [64622.8, 0.383], [64622.9, 0.003], [64624.0, 0.389], [64624.2, 0.0], [64624.3, 0.153], [64626.8, 0.005], [64627.2, 0.013], [64627.4, 0.009], [64627.5, 6.002], [64628.0, 0.312], [64629.1, 2.08], [64629.5, 0.017], [64629.7, 0.03], [64629.9, 0.0], [64630.5, 0.001], [64631.0, 10.864], [64631.1, 0.0], [64631.4, 0.019], [64631.5, 0.002], [64631.8, 0.015], [64632.0, 2.39], [64632.3, 0.003], [64633.7, 0.025], [64635.0, 7.653], [64635.1, 0.001], [64635.7, 0.16], [64635.8, 0.0], [64636.0, 0.329], [64636.6, 0.001], [64637.0, 0.041], [64637.1, 0.124], [64637.7, 0.084], [64638.4, 1.276], [64638.5, 2.824], [64638.6, 0.375], [64639.3, 0.011], [64640.0, 2.039], [64640.3, 0.017], [64642.5, 0.089], [64642.6, 0.128], [64642.7, 0.05], [64642.9, 0.58], [64643.4, 0.003], [64645.6, 0.146], [64645.7, 0.185], [64646.4, 0.009], [64646.8, 0.003], [64647.5, 0.009], [64648.9, 0.005], [64649.0, 0.618], [64649.2, 0.086], [64649.3, 0.123], [64649.4, 0.295], [64649.9, 0.017], [64650.0, 3.93], [64650.1, 1.298], [64650.2, 3.957], [64650.5, 0.002], [64650.8, 2.32], [64651.3, 0.001], [64651.5, 0.15], [64651.9, 2.805], [64652.0, 0.485], [64652.7, 0.2], [64652.9, 0.072], [64653.4, 0.015], [64654.0, 0.135], [64655.3, 4.225], [64655.5, 0.181], [64655.6, 0.002], [64656.3, 0.005], [64656.4, 0.07], [64656.6, 0.134], [64657.1, 0.034], [64657.6, 1.43], [64658.1, 0.001], [64659.0, 0.003], [64659.3, 0.138], [64659.7, 0.001], [64659.9, 0.266], [64660.2, 0.741], [64660.5, 0.114], [64660.6, 0.171], [64660.9, 3.902], [64661.0, 0.057], [64661.2, 0.001], [64661.3, 0.002], [64661.4, 1.661], [64661.5, 0.01], [64661.8, 0.082], [64661.9, 1.621], [64662.0, 0.021], [64662.2, 0.004], [64662.5, 0.154], [64662.6, 0.0], [64663.1, 0.017], [64663.5, 0.001], [64663.8, 0.233], [64664.1, 2.32], [64664.3, 0.37], [64664.4, 0.554], [64664.5, 0.017], [64664.6, 0.311], [64664.8, 0.07], [64664.9, 0.0], [64665.0, 0.154], [64665.1, 0.831], [64665.2, 0.142], [64665.6, 0.088], [64665.7, 0.161], [64665.8, 0.043], [64666.0, 3.273], [64666.1, 0.032], [64666.3, 0.0], [64666.4, 0.559], [64666.5, 0.474], [64666.6, 0.049], [64667.1, 0.174], [64667.4, 1.239], [64667.5, 0.214], [64667.8, 0.715], [64668.0, 0.431], [64668.1, 0.001], [64668.2, 1.215], [64668.3, 0.072], [64668.5, 0.484], [64668.6, 0.016], [64668.7, 2.046], [64668.8, 0.13], [64669.5, 0.016], [64669.8, 0.006], [64670.3, 0.001], [64670.4, 1.549], [64670.5, 0.362], [64670.8, 0.086], [64670.9, 1.241], [64671.0, 2.335], [64671.1, 0.08], [64671.4, 0.0], [64671.5, 0.004], [64671.6, 0.012], [64671.7, 0.462], [64671.8, 0.001], [64671.9, 0.002], [64672.1, 0.308], [64672.3, 0.0], [64672.5, 0.004], [64672.6, 0.005], [64672.8, 0.022], [64673.1, 1.194], [64673.2, 0.442], [64673.4, 0.0], [64673.6, 2.979], [64673.7, 0.089], [64673.8, 0.002], [64673.9, 1.26], [64674.1, 0.336], [64674.3, 0.629], [64674.5, 0.401], [64674.9, 0.019], [64675.0, 0.318], [64675.1, 0.001], [64675.2, 1.677], [64675.3, 0.005], [64675.4, 0.007], [64675.6, 0.175], [64675.7, 0.321], [64675.8, 0.125], [64675.9, 0.003], [64676.2, 0.464], [64676.6, 0.0], [64676.7, 0.002], [64676.8, 0.004], [64676.9, 0.001], [64677.2, 0.001], [64677.3, 2.322], [64677.5, 0.002], [64677.8, 0.44], [64677.9, 0.001], [64678.0, 0.902], [64678.3, 0.002], [64678.4, 0.703], [64678.5, 0.005], [64678.6, 0.213], [64678.8, 0.003], [64678.9, 0.001], [64679.0, 0.0], [64679.1, 0.237], [64679.2, 0.069], [64679.4, 0.161], [64679.6, 1.317], [64679.7, 0.444], [64679.8, 0.003], [64679.9, 0.019], [64680.0, 0.243], [64680.1, 0.311], [64680.2, 0.674], [64680.3, 0.021], [64680.5, 1.046], [64680.6, 0.001], [64680.7, 0.202], [64680.8, 0.63], [64680.9, 0.839], [64681.0, 0.9], [64681.1, 1.238], [64681.2, 0.012], [64681.3, 0.005], [64681.4, 0.002], [64681.6, 0.017], [64681.7, 0.004], [64682.0, 0.006], [64682.1, 0.027], [64682.2, 0.542], [64682.3, 0.014], [64682.4, 0.001], [64682.5, 0.022], [64682.6, 0.031], [64682.9, 0.003], [64683.0, 0.0], [64683.1, 0.0], [64683.3, 0.016], [64683.5, 0.002], [64683.6, 0.381], [64683.9, 3.318], [64684.0, 0.091], [64684.1, 2.058], [64684.2, 0.36], [64684.3, 0.0], [64684.4, 0.112], [64684.7, 0.084], [64684.8, 0.038], [64684.9, 0.31], [64685.1, 0.0], [64685.2, 2.062], [64685.3, 0.001], [64685.4, 0.089], [64685.5, 0.312], [64685.6, 0.141], [64685.7, 0.143], [64685.8, 0.251], [64685.9, 0.3], [64686.0, 0.157], [64686.2, 0.458], [64686.3, 0.215], [64686.4, 0.881], [64686.5, 0.002], [64686.6, 0.033], [64686.9, 0.003], [64687.1, 0.001], [64687.2, 0.087], [64687.3, 0.033], [64687.6, 0.033], [64687.7, 0.087], [64687.8, 0.0], [64688.0, 0.022], [64688.1, 0.07], [64688.2, 0.003], [64688.3, 0.0], [64688.4, 0.086], [64688.6, 0.004], [64688.7, 0.005], [64688.8, 0.001], [64688.9, 0.017], [64689.0, 0.2], [64689.2, 0.022], [64689.4, 0.002], [64689.5, 0.001], [64689.7, 0.0], [64689.8, 0.003], [64689.9, 0.003], [64690.0, 0.003], [64690.1, 0.233], [64690.2, 0.175], [64690.3, 0.0], [64690.4, 0.001], [64690.5, 0.001], [64691.1, 0.02], [64691.2, 0.008], [64691.3, 0.0], [64691.4, 0.002], [64691.6, 0.001], [64691.9, 0.055], [64692.2, 0.0], [64692.3, 0.0], [64692.4, 0.0], [64692.6, 0.147], [64692.9, 0.005], [64693.1, 0.0], [64693.2, 0.0], [64693.3, 0.0], [64693.4, 0.002], [64693.5, 0.013], [64693.6, 0.002], [64693.7, 0.0], [64694.1, 0.008], [64694.2, 9.356]], "asks": [[64694.3, 9.436], [64694.4, 0.041], [64694.8, 0.084], [64695.1, 0.001], [64695.3, 0.584], [64695.8, 0.086], [64695.9, 0.001], [64696.3, 0.084], [64696.6, 0.002], [64696.8, 0.013], [64696.9, 0.911], [64697.1, 0.006], [64697.3, 0.085], [64697.4, 0.001], [64697.5, 0.029], [64697.6, 1.424], [64697.9, 0.06], [64698.0, 0.326], [64698.1, 0.001], [64698.2, 0.057], [64698.3, 0.006], [64698.4, 0.025], [64698.5, 0.0], [64698.6, 0.0], [64698.7, 2.981], [64698.8, 0.004], [64698.9, 0.156], [64699.9, 0.003], [64700.1, 0.188], [64700.2, 1.006], [64700.3, 0.002], [64700.7, 0.001], [64700.8, 0.02], [64701.0, 0.055], [64701.1, 0.015], [64701.2, 0.0], [64701.3, 0.041], [64701.5, 0.164], [64701.7, 0.641], [64702.0, 0.106], [64702.1, 0.008], [64702.3, 0.003], [64702.5, 0.001], [64702.8, 0.002], [64703.3, 0.009], [64703.6, 0.004], [64703.7, 0.0], [64704.0, 1.207], [64704.1, 0.782], [64704.2, 1.454], [64704.3, 0.006], [64704.7, 0.174], [64704.8, 0.108], [64706.0, 1.433], [64706.5, 0.002], [64706.7, 0.136], [64706.9, 0.003], [64707.0, 0.036], [64707.2, 2.029], [64707.3, 1.889], [64707.5, 0.157], [64707.6, 0.05], [64707.9, 0.173], [64708.0, 0.901], [64708.2, 0.315], [64708.3, 0.0], [64708.4, 0.002], [64708.6, 0.0], [64708.7, 0.002], [64708.9, 1.452], [64709.2, 0.574], [64709.3, 0.504], [64709.5, 0.001], [64709.8, 0.064], [64709.9, 1.238], [64710.3, 0.214], [64710.6, 0.623], [64710.7, 1.903], [64710.8, 2.338], [64711.5, 0.0], [64711.6, 0.03], [64711.8, 0.029], [64711.9, 1.298], [64712.0, 1.977], [64712.1, 0.003], [64712.3, 0.208], [64712.4, 0.125], [64712.7, 0.003], [64713.0, 0.059], [64713.4, 0.391], [64713.6, 1.012], [64713.7, 0.771], [64714.0, 0.086], [64714.4, 0.005], [64714.5, 0.915], [64714.6, 0.223], [64714.7, 0.843], [64715.1, 0.061], [64715.2, 1.26], [64715.4, 0.446], [64715.6, 0.589], [64715.7, 0.001], [64715.8, 0.0], [64716.3, 0.0], [64716.6, 0.004], [64716.8, 1.251], [64716.9, 0.719], [64717.3, 0.002], [64717.5, 0.002], [64717.6, 0.894], [64718.1, 0.007], [64718.3, 0.003], [64718.5, 0.324], [64718.8, 0.003], [64718.9, 0.393], [64719.8, 0.013], [64720.1, 0.016], [64720.6, 0.125], [64720.8, 2.32], [64721.3, 0.007], [64722.0, 0.676], [64722.3, 2.327], [64722.5, 0.092], [64722.7, 0.0], [64722.8, 0.001], [64722.9, 0.671], [64723.0, 0.003], [64723.2, 0.23], [64723.4, 1.825], [64723.6, 0.003], [64723.7, 3.829], [64724.1, 0.002], [64724.3, 0.002], [64724.5, 0.024], [64724.6, 0.121], [64724.7, 0.046], [64724.8, 1.126], [64725.9, 0.062], [64726.4, 0.196], [64726.5, 0.174], [64726.6, 2.211], [64727.2, 0.008], [64727.8, 0.001], [64728.4, 0.002], [64729.1, 0.021], [64729.6, 2.539], [64730.2, 0.115], [64730.5, 0.0], [64730.6, 0.006], [64731.1, 0.002], [64731.3, 0.25], [64731.4, 0.639], [64731.6, 0.259], [64731.8, 0.364], [64732.4, 0.007], [64732.6, 0.059], [64732.7, 0.211], [64733.0, 0.002], [64733.1, 0.024], [64734.5, 0.002], [64734.8, 0.075], [64735.6, 0.118], [64735.9, 0.127], [64736.1, 0.22], [64736.7, 1.206], [64737.5, 0.022], [64738.1, 0.016], [64738.5, 1.998], [64738.6, 0.003], [64738.9, 0.0], [64739.6, 0.003], [64739.7, 0.099], [64740.0, 4.614], [64740.5, 0.022], [64740.7, 0.019], [64740.9, 0.028], [64741.5, 0.028], [64741.6, 0.041], [64742.2, 0.008], [64742.8, 0.0], [64742.9, 2.681], [64743.4, 2.394], [64744.6, 0.003], [64745.4, 0.12], [64745.5, 0.0], [64745.6, 0.037], [64746.1, 2.842], [64746.5, 0.016], [64746.9, 0.045], [64747.8, 0.0], [64748.0, 0.027], [64748.9, 0.0], [64749.5, 2.003], [64750.0, 0.135], [64750.5, 0.002], [64750.7, 0.013], [64751.4, 0.019], [64752.8, 0.006], [64755.1, 0.311], [64755.7, 0.012], [64755.8, 0.001], [64756.2, 0.0], [64757.6, 0.218], [64758.9, 0.021], [64759.0, 0.128], [64760.2, 0.026], [64761.8, 0.005], [64762.7, 6.001], [64762.8, 0.545], [64762.9, 0.663], [64763.6, 0.002], [64765.4, 0.001], [64766.3, 0.024], [64766.8, 0.027], [64767.4, 2.341], [64770.8, 0.04], [64771.9, 0.053], [64772.7, 0.629], [64773.5, 1.093], [64775.8, 0.0], [64776.3, 0.002], [64776.6, 0.025], [64778.3, 0.357], [64781.3, 0.0], [64785.0, 0.101], [64785.5, 0.028], [64791.3, 0.0], [64793.7, 0.021], [64795.0, 0.025], [64803.0, 0.003], [64817.8, 0.003], [64824.6, 0.0], [64835.8, 0.528], [64836.6, 0.0], [64845.0, 0.006], [64851.2, 10.419], [64857.6, 1.841], [64864.8, 0.011], [64883.2, 0.036], [64885.8, 0.003], [64890.0, 12.649], [64891.2, 4.478], [64895.9, 0.028], [64937.2, 0.0], [65026.6, 0.0], [65035.3, 0.0], [65284.3, 0.0], [65341.2, 2.306], [65632.4, 14.338], [65687.6, 0.046], [65694.3, 0.02], [65899.0, 0.205], [65988.1, 0.012]]}
{"kind": "depth", "E": 1787081863425, "U": 11315468004123, "u": 11315468030611, "recv_ms": 1787081863397, "bids": [[14194.2, 3.598], [14294.2, 0.168], [14594.2, 0.434], [51755.0, 0.0], [58224.7, 0.002], [62106.4, 0.689], [63012.1, 0.0], [64047.3, 0.073], [64111.9, 2.18], [64349.5, 0.0], [64352.0, 11.115], [64370.7, 0.942], [64425.6, 0.948], [64528.9, 0.25], [64567.0, 0.0], [64567.1, 0.128], [64568.0, 6.18], [64574.6, 0.001], [64588.7, 0.026], [64590.2, 0.018], [64590.6, 0.212], [64605.3, 0.127], [64605.6, 0.0], [64615.9, 0.202], [64618.5, 42.729], [64619.1, 1.547], [64620.7, 0.183], [64629.1, 1.912], [64629.5, 0.018], [64632.0, 2.376], [64634.8, 0.0], [64635.0, 7.655], [64635.9, 0.026], [64637.4, 0.21], [64637.5, 0.0], [64638.4, 1.066], [64645.6, 0.026], [64646.1, 0.001], [64646.4, 0.01], [64646.7, 0.151], [64650.2, 3.957], [64650.3, 0.001], [64651.5, 0.101], [64651.9, 2.78], [64652.0, 0.329], [64652.1, 0.201], [64652.7, 0.11], [64652.9, 0.072], [64653.4, 0.016], [64655.8, 0.172], [64656.4, 0.02], [64658.3, 0.004], [64658.7, 0.004], [64659.3, 0.0], [64659.9, 0.232], [64660.3, 0.2], [64660.6, 0.532], [64660.9, 3.566], [64661.0, 0.181], [64661.8, 0.009], [64662.0, 0.022], [64662.1, 2.019], [64662.7, 0.004], [64663.6, 0.052], [64663.8, 0.002], [64664.0, 1.545], [64664.4, 0.548], [64664.5, 0.015], [64665.2, 0.018], [64665.6, 0.089], [64665.9, 0.004], [64666.0, 3.322], [64666.2, 0.364], [64666.3, 0.347], [64666.8, 0.001], [64666.9, 0.341], [64667.1, 0.059], [64667.6, 0.023], [64667.7, 0.866], [64668.1, 0.232], [64668.3, 0.037], [64668.5, 0.021], [64668.8, 0.285], [64669.1, 0.045], [64669.6, 0.378], [64669.7, 0.192], [64669.9, 0.18], [64670.1, 0.042], [64670.4, 1.202], [64670.5, 0.238], [64670.6, 0.368], [64670.8, 0.006], [64671.1, 0.543], [64671.6, 0.007], [64671.9, 0.002], [64672.0, 0.781], [64672.2, 0.021], [64672.3, 0.133], [64672.6, 0.003], [64672.7, 0.003], [64672.9, 0.0], [64673.0, 0.012], [64673.1, 1.04], [64673.4, 0.0], [64673.6, 2.981], [64673.7, 0.214], [64674.5, 0.401], [64674.9, 0.017], [64675.2, 2.025], [64675.3, 1.931], [64675.4, 0.354], [64675.5, 0.037], [64675.8, 0.001], [64676.1, 0.062], [64676.2, 0.001], [64676.9, 0.001], [64677.1, 0.018], [64677.3, 2.321], [64677.5, 0.002], [64677.6, 0.082], [64677.8, 0.6], [64678.4, 0.964], [64678.5, 0.005], [64678.6, 0.22], [64679.4, 0.001], [64679.6, 0.31], [64679.8, 0.083], [64679.9, 0.02], [64680.0, 0.239], [64680.2, 0.694], [64680.3, 0.003], [64680.9, 0.013], [64681.2, 2.877], [64681.3, 1.599], [64681.4, 0.465], [64682.0, 0.166], [64682.2, 0.003], [64682.6, 0.34], [64683.9, 3.317], [64684.0, 0.008], [64684.1, 0.003], [64684.2, 1.107], [64684.8, 0.038], [64684.9, 0.0], [64685.1, 0.0], [64685.2, 1.902], [64685.3, 0.078], [64685.4, 0.088], [64686.2, 0.07], [64686.4, 0.063], [64686.5, 0.566], [64686.6, 1.789], [64686.7, 0.001], [64686.8, 0.086], [64686.9, 0.366], [64687.0, 0.036], [64687.3, 0.001], [64687.6, 0.001], [64687.9, 0.233], [64688.2, 0.235], [64688.4, 0.14], [64688.6, 0.002], [64688.8, 0.001], [64688.9, 0.017], [64689.1, 0.047], [64689.2, 0.002], [64689.3, 0.006], [64689.6, 0.016], [64689.8, 0.103], [64690.1, 0.001], [64690.2, 0.203], [64690.3, 0.0], [64690.4, 0.019], [64690.5, 0.023], [64691.1, 0.002], [64691.2, 0.006], [64691.9, 0.001], [64692.5, 0.001], [64692.6, 0.001], [64694.1, 0.008], [64694.2, 7.439]], "asks": [[64694.3, 10.568], [64694.5, 0.693], [64694.6, 1.002], [64694.7, 0.055], [64695.2, 0.002], [64695.6, 0.0], [64696.5, 0.005], [64696.6, 0.002], [64696.8, 0.012], [64696.9, 0.084], [64697.0, 0.003], [64697.1, 0.007], [64697.2, 0.834], [64697.5, 0.029], [64697.6, 1.023], [64697.7, 0.006], [64697.9, 0.02], [64698.0, 0.348], [64698.2, 0.149], [64698.4, 0.005], [64698.6, 0.0], [64698.7, 2.981], [64698.8, 0.004], [64698.9, 0.01], [64699.9, 0.002], [64700.2, 0.006], [64700.3, 0.0], [64700.8, 0.028], [64701.0, 0.029], [64701.1, 0.002], [64701.4, 0.003], [64701.6, 0.658], [64701.7, 0.633], [64701.9, 0.514], [64702.1, 0.118], [64702.4, 0.255], [64703.2, 0.004], [64703.3, 0.464], [64703.4, 1.373], [64704.0, 0.462], [64704.1, 0.319], [64704.2, 1.454], [64704.4, 0.019], [64704.7, 0.125], [64704.9, 0.021], [64705.6, 0.337], [64706.6, 0.035], [64706.7, 0.003], [64707.0, 0.901], [64707.2, 2.266], [64707.5, 0.16], [64707.7, 3.245], [64708.2, 0.31], [64708.7, 0.558], [64708.8, 0.613], [64710.0, 1.023], [64710.5, 0.002], [64710.6, 0.082], [64711.0, 0.0], [64711.5, 0.049], [64711.8, 0.009], [64712.1, 0.001], [64712.3, 0.208], [64712.4, 0.045], [64712.5, 0.156], [64713.0, 0.019], [64713.4, 0.945], [64714.0, 0.201], [64714.7, 0.773], [64714.8, 0.001], [64716.9, 0.721], [64717.7, 10.468], [64718.7, 0.172], [64718.9, 0.391], [64719.0, 0.325], [64719.1, 0.02], [64721.8, 0.078], [64721.9, 0.093], [64722.5, 0.002], [64722.6, 0.007], [64722.9, 0.665], [64723.4, 1.705], [64729.1, 0.021], [64730.7, 0.12], [64730.9, 0.029], [64731.6, 0.234], [64732.3, 2.321], [64732.6, 0.061], [64732.7, 0.001], [64734.8, 0.002], [64735.4, 0.31], [64735.5, 0.002], [64738.1, 0.016], [64738.6, 0.001], [64738.9, 0.04], [64739.6, 0.003], [64743.9, 0.078], [64748.8, 0.005], [64750.6, 0.21], [64761.3, 32.445], [64763.5, 0.0], [64765.7, 0.001], [64766.8, 0.027], [64767.6, 0.021], [64767.9, 0.022], [64768.7, 0.218], [64772.7, 0.46], [64778.3, 0.191], [64781.6, 0.027], [64795.6, 0.0], [64801.1, 2.322], [64823.7, 0.0], [64834.2, 5.406], [64835.8, 0.246], [64851.2, 10.419], [64890.0, 9.02], [64902.8, 0.0], [65025.9, 0.116], [65026.5, 0.003], [65284.5, 2.373], [65341.2, 2.294], [65988.1, 0.015]]}
{"kind": "depth", "E": 1787081863527, "U": 11315468030740, "u": 11315468042729, "recv_ms": 1787081863495, "bids": [[1000.0, 35.81], [14194.2, 3.486], [14294.2, 0.042], [14594.2, 0.672], [51755.4, 0.0], [58224.7, 0.002], [61459.4, 0.0], [62106.4, 0.692], [63917.9, 12.796], [64047.3, 0.073], [64213.5, 0.312], [64336.7, 2.502], [64370.7, 0.941], [64482.8, 0.006], [64507.5, 0.015], [64574.0, 0.792], [64601.6, 2.35], [64603.2, 3.295], [64603.8, 0.261], [64620.0, 3.075], [64628.5, 0.004], [64640.7, 0.163], [64653.4, 0.017], [64654.7, 0.148], [64658.8, 0.128], [64661.2, 0.001], [64663.6, 0.092], [64665.6, 0.049], [64670.4, 1.282], [64671.1, 0.551], [64671.2, 0.005], [64674.0, 0.614], [64675.0, 0.164], [64677.6, 0.002], [64677.9, 0.001], [64678.0, 0.002], [64679.0, 0.9], [64679.8, 0.006], [64679.9, 0.019], [64680.6, 0.156], [64681.2, 2.336], [64681.3, 1.591], [64681.4, 0.465], [64681.5, 0.037], [64681.6, 0.018], [64682.6, 0.337], [64683.9, 3.349], [64684.0, 0.549], [64684.3, 0.088], [64684.8, 0.039], [64685.3, 0.171], [64685.5, 0.242], [64685.6, 0.001], [64685.7, 0.003], [64685.8, 0.151], [64685.9, 0.0], [64686.0, 0.087], [64686.1, 0.004], [64686.2, 0.0], [64686.3, 0.115], [64686.4, 0.001], [64686.5, 0.025], [64686.6, 0.733], [64686.7, 0.001], [64686.8, 1.473], [64686.9, 0.003], [64688.2, 0.003], [64688.5, 0.063], [64690.2, 0.161], [64690.3, 0.13], [64690.5, 0.001], [64694.2, 6.939]], "asks": [[64694.3, 10.569], [64694.5, 0.694], [64695.0, 0.004], [64697.0, 0.005], [64697.6, 1.042], [64697.8, 0.108], [64698.6, 0.0], [64699.5, 0.111], [64700.1, 0.311], [64700.8, 0.028], [64701.4, 0.25], [64701.5, 0.164], [64701.9, 0.559], [64702.0, 1.006], [64703.0, 1.448], [64703.1, 0.094], [64703.5, 0.538], [64704.7, 0.002], [64704.9, 0.461], [64707.2, 2.267], [64707.5, 0.005], [64707.7, 2.32], [64708.5, 0.374], [64708.6, 0.925], [64708.7, 0.002], [64709.8, 0.007], [64710.0, 0.123], [64710.5, 0.556], [64711.2, 0.073], [64711.4, 0.093], [64713.1, 0.01], [64714.0, 0.121], [64714.5, 0.916], [64715.2, 1.1], [64715.4, 0.126], [64716.9, 0.722], [64717.4, 0.091], [64722.0, 0.636], [64734.2, 0.003], [64737.1, 0.041], [64741.6, 0.001], [64759.8, 0.025], [64765.5, 0.029], [64772.1, 0.005], [64775.2, 0.985], [64834.2, 3.64], [64835.3, 0.0], [64851.2, 5.383], [64890.0, 8.858], [64961.6, 1.774], [65017.8, 0.943], [65150.5, 0.002], [65280.4, 0.23], [65341.2, 2.294], [65543.6, 0.001], [65658.0, 0.1], [67019.2, 0.0]]}
{"kind": "depth", "E": 1787081863629, "U": 11315468042878, "u": 11315468050762, "recv_ms": 1787081863597, "bids": [[1000.0, 35.81], [14194.2, 3.22], [14294.2, 0.0], [14594.2, 0.98], [58224.7, 0.002], [58224.8, 0.002], [63694.2, 0.0], [63726.9, 0.001], [64047.3, 0.073], [64490.6, 2.511], [64519.8, 0.001], [64604.1, 0.038], [64604.5, 2.352], [64618.5, 0.011], [64620.7, 42.901], [64634.4, 0.071], [64634.6, 0.425], [64634.7, 0.101], [64634.9, 0.122], [64635.0, 7.755], [64635.1, 0.071], [64642.7, 0.025], [64644.5, 0.233], [64652.3, 0.025], [64656.6, 0.064], [64660.5, 0.014], [64660.6, 0.462], [64663.9, 0.071], [64665.4, 0.002], [64680.4, 0.073], [64680.6, 0.256], [64680.7, 0.302], [64680.9, 0.113], [64681.0, 1.07], [64681.1, 1.338], [64681.5, 0.117], [64682.5, 0.054], [64682.8, 0.081], [64684.3, 0.008], [64685.3, 0.735], [64686.5, 0.002], [64686.8, 0.086], [64686.9, 0.003], [64687.0, 0.036], [64687.1, 0.001], [64687.2, 0.087], [64687.3, 0.847], [64688.3, 0.023], [64688.4, 0.159]], "asks": [[64694.5, 0.44], [64696.6, 0.002], [64697.2, 0.01], [64697.7, 0.004], [64698.0, 1.248], [64698.8, 0.006], [64700.5, 0.035], [64700.8, 0.036], [64700.9, 1.488], [64701.6, 0.65], [64702.2, 0.193], [64702.3, 0.101], [64702.4, 0.605], [64702.6, 0.151], [64702.7, 0.141], [64702.9, 0.12], [64704.2, 1.416], [64705.2, 0.0], [64705.6, 0.049], [64705.8, 0.104], [64706.0, 0.533], [64707.1, 0.416], [64707.2, 2.143], [64707.6, 0.0], [64714.3, 0.052], [64716.8, 1.253], [64717.0, 0.003], [64761.3, 0.0], [64767.9, 32.467], [64834.2, 5.406], [64851.2, 10.419], [64859.1, 0.0], [64859.2, 4.029], [64871.0, 0.056], [64895.7, 0.001], [65073.4, 0.008], [65141.6, 0.0], [65276.6, 6.207], [65341.2, 2.294], [65694.3, 0.0]]}
{"kind": "depth", "E": 1787081863731, "U": 11315468050844, "u": 11315468058994, "recv_ms": 1787081863699, "bids": [[14194.2, 2.856], [14594.2, 1.344], [58224.7, 0.002], [58224.8, 0.0], [61459.4, 0.0], [62106.4, 0.689], [64047.3, 0.073], [64370.7, 0.942], [64410.0, 0.237], [64429.8, 0.001], [64496.0, 0.02], [64496.1, 10.587], [64506.8, 0.005], [64572.6, 0.0], [64574.0, 1.072], [64579.4, 3.91], [64603.5, 0.057], [64603.8, 0.229], [64615.2, 0.443], [64621.7, 0.018], [64628.5, 0.172], [64634.4, 0.141], [64634.5, 0.07], [64634.6, 0.325], [64634.8, 0.1], [64635.3, 0.477], [64637.2, 0.014], [64644.1, 1.353], [64649.2, 0.026], [64652.7, 0.124], [64654.7, 0.149], [64655.5, 0.18], [64656.4, 0.08], [64660.2, 0.641], [64660.3, 0.1], [64660.6, 0.362], [64661.2, 0.074], [64663.6, 0.042], [64668.9, 0.027], [64670.1, 0.005], [64670.9, 1.291], [64671.7, 0.477], [64673.3, 0.003], [64676.0, 1.702], [64677.5, 0.039], [64680.4, 0.143], [64680.5, 1.116], [64680.7, 0.402], [64680.8, 0.73], [64681.0, 0.17], [64681.1, 1.359], [64681.3, 1.661], [64681.8, 0.238], [64683.6, 0.383], [64684.8, 0.349], [64685.3, 0.735], [64685.5, 0.227], [64685.8, 0.154], [64686.6, 0.235], [64687.3, 0.001], [64687.4, 0.0], [64687.5, 0.57], [64687.6, 1.573], [64688.0, 0.021], [64688.9, 0.101], [64691.0, 0.004], [64691.4, 0.001], [64694.1, 0.007]], "asks": [[64694.3, 10.553], [64694.7, 0.889], [64696.3, 0.085], [64697.5, 0.044], [64701.5, 0.209], [64702.1, 0.23], [64702.6, 0.301], [64702.7, 0.311], [64702.9, 0.239], [64703.0, 1.546], [64704.0, 0.477], [64705.7, 0.051], [64705.9, 0.151], [64706.0, 0.393], [64706.4, 0.002], [64707.2, 2.012], [64712.4, 0.03], [64713.7, 0.64], [64719.0, 0.31], [64726.8, 1.702], [64731.6, 0.094], [64734.2, 0.075], [64761.6, 0.034], [64763.5, 32.445], [64766.8, 0.027], [64767.9, 0.022], [64772.1, 0.172], [64835.2, 2.597], [64890.0, 10.491], [64927.6, 0.011], [64947.5, 0.006], [64993.1, 0.001], [65003.3, 9.331], [65017.8, 0.942], [65024.5, 0.006], [65032.5, 0.0], [65043.9, 0.005], [65090.5, 0.159], [65341.2, 2.294], [65464.3, 0.0], [65535.5, 4.452], [65543.3, 1.066], [65613.0, 1.237], [65616.9, 7.298], [65988.1, 0.018]]}
{"kind": "depth", "E": 1787081863833, "U": 11315468059195, "u": 11315468068152, "recv_ms": 1787081863802, "bids": [[1000.0, 35.81], [14194.2, 2.506], [14594.2, 1.694], [51755.0, 0.0], [58224.7, 0.002], [61459.4, 0.0], [62106.4, 0.692], [63395.2, 0.004], [63694.2, 0.02], [63719.6, 0.279], [63987.7, 0.783], [64041.4, 3.239], [64047.3, 0.073], [64495.7, 1.303], [64496.1, 10.771], [64497.2, 0.019], [64539.3, 1.203], [64574.0, 0.792], [64603.2, 3.263], [64603.5, 0.025], [64604.1, 0.006], [64628.5, 0.004], [64630.7, 0.115], [64634.4, 0.071], [64634.6, 0.395], [64634.7, 0.001], [64634.8, 0.17], [64652.5, 0.026], [64656.6, 0.007], [64659.9, 0.162], [64660.0, 0.523], [64660.1, 0.158], [64660.3, 0.057], [64660.4, 0.001], [64660.6, 0.337], [64660.8, 1.184], [64661.2, 0.001], [64665.0, 0.054], [64666.0, 3.273], [64668.8, 0.288], [64673.2, 0.491], [64680.6, 0.326], [64680.9, 0.183], [64684.1, 0.004], [64685.3, 0.735], [64685.4, 0.934], [64687.6, 0.001], [64687.7, 0.087], [64687.8, 0.003], [64687.9, 0.233], [64688.0, 0.021], [64688.1, 0.07], [64689.3, 0.09], [64690.3, 0.27], [64693.4, 0.0], [64694.2, 6.933]], "asks": [[64696.6, 0.002], [64698.0, 0.348], [64701.2, 0.042], [64702.5, 0.099], [64702.8, 0.093], [64703.9, 0.011], [64704.5, 2.321], [64704.8, 0.063], [64705.4, 0.003], [64705.8, 0.006], [64705.9, 0.001], [64706.0, 0.223], [64706.1, 0.108], [64706.2, 0.121], [64706.3, 0.005], [64711.5, 0.0], [64713.4, 0.404], [64713.7, 0.516], [64714.4, 0.546], [64717.6, 2.292], [64718.2, 2.521], [64721.3, 0.047], [64731.5, 0.002], [64731.8, 0.259], [64734.2, 0.003], [64739.9, 1.512], [64740.0, 3.623], [64753.2, 0.276], [64759.0, 0.155], [64761.3, 32.445], [64761.9, 0.264], [64763.5, 0.0], [64772.1, 0.005], [64781.1, 0.091], [64785.6, 1.215], [64834.2, 4.872], [64835.2, 2.319], [64851.2, 10.419], [64890.0, 10.24], [65021.5, 0.146], [65023.6, 0.0], [65341.2, 2.294], [65694.3, 0.02]]}
{"kind": "depth", "E": 1787081863935, "U": 11315468068378, "u": 11315468074709, "recv_ms": 1787081863904, "bids": [[1000.0, 35.81], [14194.2, 2.142], [14594.2, 2.058], [58224.7, 0.002], [62106.4, 0.689], [63400.4, 0.078], [63729.5, 6.177], [63901.9, 6.186], [64047.3, 0.073], [64496.1, 10.771], [64514.3, 0.0], [64523.3, 0.221], [64529.0, 0.504], [64566.9, 0.086], [64570.4, 0.0], [64574.0, 0.792], [64628.5, 0.004], [64634.5, 0.14], [64660.1, 0.088], [64661.2, 0.001], [64674.1, 0.016], [64675.3, 2.085], [64680.5, 1.186], [64681.2, 2.656], [64685.6, 0.063], [64685.8, 0.151], [64688.5, 0.001], [64690.3, 0.13], [64690.4, 0.02], [64694.2, 6.947]], "asks": [[64694.3, 10.55], [64695.8, 0.088], [64701.8, 2.322], [64702.8, 0.198], [64704.6, 0.326], [64706.2, 0.002], [64711.2, 0.071], [64711.9, 1.3], [64713.8, 5.072], [64734.2, 0.003], [64761.3, 0.0], [64761.6, 0.007], [64764.9, 0.027], [64765.7, 0.001], [64767.9, 32.467], [64772.1, 0.005], [64835.2, 2.319], [64851.2, 10.419], [64890.0, 10.184], [64917.2, 0.013], [64958.6, 0.0], [65341.2, 2.294], [65464.2, 5.867], [65535.4, 1.092], [65543.3, 0.0]]}
{"kind": "depth", "E": 1787081864037, "U": 11315468074866, "u": 11315468080929, "recv_ms": 1787081864005, "bids": [[14194.2, 1.792], [14594.2, 2.408], [58224.7, 0.002], [61459.4, 0.0], [62106.4, 0.692], [63694.2, 0.0], [64047.3, 0.073], [64370.7, 0.932], [64551.5, 0.017], [64591.4, 0.003], [64604.5, 2.32], [64634.5, 0.07], [64654.9, 0.071], [64655.1, 0.166], [64655.2, 1.865], [64660.1, 0.018], [64673.7, 0.213], [64675.3, 1.931], [64677.6, 0.003], [64682.6, 0.342], [64685.4, 0.088], [64685.5, 0.157], [64686.7, 0.001], [64687.5, 0.822], [64687.6, 0.847], [64689.3, 0.006], [64692.0, 0.002], [64692.1, 0.001], [64692.7, 0.001], [64694.2, 6.948]], "asks": [[64694.3, 10.574], [64696.3, 0.087], [64696.6, 0.002], [64697.9, 0.022], [64698.8, 0.004], [64700.0, 0.904], [64706.1, 0.003], [64728.2, 0.151], [64728.3, 0.604], [64728.5, 0.733], [64731.7, 4.04], [64763.5, 32.445], [64767.9, 0.022], [64834.2, 5.406], [64851.2, 10.419], [64890.0, 9.091], [65017.8, 1.71], [65284.6, 0.0], [65341.2, 2.294], [65694.3, 0.0]]}
{"kind": "depth", "E": 1787081864139, "U": 11315468080955, "u": 11315468088175, "recv_ms": 1787081864109, "bids": [[1000.0, 35.81], [14194.2, 1.428], [14594.2, 2.772], [51755.0, 0.0], [58224.7, 0.002], [61459.4, 0.0], [61990.0, 0.479], [62151.5, 0.015], [62313.4, 0.006], [62475.8, 0.079], [62638.6, 0.168], [62801.8, 0.002], [62965.5, 0.0], [63129.6, 0.005], [63294.1, 0.014], [63400.4, 0.081], [63459.0, 0.0], [63624.4, 0.002], [63694.2, 0.02], [63701.0, 1.412], [63723.8, 7.738], [63790.2, 0.0], [63956.4, 0.547], [64047.3, 0.264], [64104.4, 3.62], [64123.0, 0.054], [64150.8, 0.32], [64290.1, 0.003], [64457.7, 0.0], [64574.0, 0.792], [64579.7, 0.007], [64594.0, 0.001], [64603.6, 0.853], [64603.7, 0.083], [64624.0, 0.079], [64628.5, 0.004], [64659.8, 0.105], [64661.2, 0.001], [64670.4, 1.331], [64674.8, 0.387], [64677.9, 0.321], [64678.4, 1.336], [64681.2, 2.336], [64682.6, 0.337], [64682.7, 0.156], [64684.1, 0.003], [64684.3, 0.0], [64684.4, 0.113], [64685.1, 0.0], [64685.3, 0.743], [64685.6, 0.001], [64685.8, 0.154], [64686.7, 0.001], [64686.8, 0.089], [64687.6, 0.847], [64687.7, 0.087], [64687.8, 0.0], [64688.0, 0.021], [64688.4, 0.469], [64688.5, 0.002], [64689.1, 0.047], [64689.2, 0.064], [64689.4, 0.086], [64690.3, 0.19], [64694.2, 6.937]], "asks": [[64694.3, 11.002], [64699.0, 0.001], [64700.0, 1.098], [64706.0, 0.222], [64711.4, 0.036], [64712.4, 0.087], [64723.5, 2.496], [64734.2, 0.003], [64761.6, 0.025], [64772.1, 0.005], [64781.9, 0.035], [64782.0, 0.041], [64794.0, 0.061], [64835.2, 2.319], [64838.5, 0.005], [64852.8, 3.887], [64894.7, 0.005], [64894.8, 0.0], [64962.9, 0.013], [65129.9, 0.658], [65132.2, 0.0], [65301.9, 0.0], [65341.2, 2.294], [65472.0, 0.015], [65483.7, 0.917], [65535.4, 2.158], [65642.6, 0.001], [65687.6, 0.038], [65694.3, 0.02], [65813.7, 1.515], [65985.2, 0.003], [66157.1, 0.75], [66329.5, 0.0], [66502.4, 0.006], [66675.7, 0.003], [66849.4, 0.0], [67023.6, 0.0], [67198.3, 0.0], [67373.4, 0.0], [67548.9, 0.0], [67725.0, 0.005]]}
{"kind": "depth", "E": 1787081864241, "U": 11315468088380, "u": 11315468095351, "recv_ms": 1787081864210, "bids": [[1000.0, 35.81], [14194.2, 1.078], [14594.2, 3.122], [51755.0, 0.0], [58224.7, 0.002], [61459.4, 0.0], [62106.4, 0.689], [63701.0, 1.42], [64047.3, 0.264], [64565.5, 0.004], [64565.7, 1.59], [64630.7, 0.015], [64657.6, 1.416], [64665.1, 1.167], [64666.4, 0.002], [64668.0, 0.315], [64668.8, 0.302], [64670.4, 1.251], [64671.2, 0.562], [64672.5, 0.12], [64675.2, 2.179], [64678.0, 0.082], [64681.4, 0.002], [64682.1, 0.336], [64682.6, 0.028], [64684.3, 0.0], [64684.4, 0.029], [64685.3, 1.206], [64686.6, 0.003], [64687.5, 1.054], [64688.8, 0.02], [64688.9, 0.144], [64689.8, 0.187], [64692.4, 0.001], [64694.2, 7.463]], "asks": [[64694.3, 10.935], [64695.4, 0.092], [64695.9, 0.02], [64696.1, 0.055], [64696.2, 0.003], [64696.5, 0.027], [64696.6, 0.002], [64696.7, 0.002], [64697.1, 0.009], [64697.5, 0.044], [64697.6, 1.269], [64697.8, 0.086], [64697.9, 0.003], [64698.0, 0.325], [64698.2, 0.003], [64698.5, 0.0], [64698.6, 0.0], [64700.0, 0.004], [64700.2, 0.004], [64700.7, 0.078], [64700.8, 1.071], [64701.1, 0.0], [64701.5, 0.518], [64701.6, 0.001], [64703.3, 0.001], [64704.1, 0.01], [64710.5, 0.0], [64711.5, 0.556], [64714.0, 0.006], [64715.3, 0.12], [64717.7, 0.468], [64834.2, 3.615], [64851.2, 5.305], [65217.7, 0.001], [65341.2, 2.298], [65687.6, 0.046], [65705.5, 1.303]]}
{"kind": "depth", "E": 1787081864343, "U": 11315468095384, "u": 11315468102941, "recv_ms": 1787081864312, "bids": [[14194.2, 0.714], [14594.2, 3.486], [51755.0, 0.0], [58224.7, 0.002], [61459.4, 0.0], [62106.4, 0.692], [63923.6, 15.606], [64047.3, 0.264], [64136.3, 0.132], [64150.8, 0.296], [64182.4, 0.002], [64183.7, 0.115], [64370.7, 0.932], [64376.5, 0.002], [64376.7, 0.0], [64377.1, 0.082], [64399.3, 0.069], [64406.6, 0.092], [64483.7, 0.006], [64557.0, 0.243], [64574.1, 0.002], [64583.3, 0.024], [64625.4, 0.013], [64628.6, 0.004], [64634.3, 0.088], [64644.7, 0.313], [64651.7, 0.006], [64655.0, 0.215], [64657.6, 1.485], [64660.6, 0.001], [64661.3, 0.002], [64669.1, 0.005], [64669.6, 0.371], [64671.8, 0.008], [64675.2, 2.025], [64675.3, 1.159], [64675.4, 0.354], [64676.3, 0.043], [64677.1, 0.944], [64677.8, 0.531], [64679.2, 0.0], [64680.3, 0.073], [64680.5, 1.186], [64680.6, 0.327], [64684.3, 0.471], [64685.3, 0.735], [64685.4, 0.15], [64687.5, 0.802], [64687.9, 0.233], [64688.7, 0.005], [64688.8, 0.001], [64688.9, 0.144], [64689.2, 0.002], [64694.2, 6.939]], "asks": [[64694.9, 0.02], [64695.2, 0.024], [64695.9, 0.001], [64696.2, 0.003], [64696.5, 0.005], [64697.3, 0.085], [64698.2, 0.005], [64701.3, 0.042], [64707.2, 1.846], [64708.6, 0.0], [64709.5, 0.926], [64710.3, 0.214], [64717.6, 0.894], [64718.5, 0.31], [64718.7, 0.102], [64720.9, 10.002], [64725.6, 0.072], [64726.8, 1.716], [64727.9, 0.896], [64728.4, 0.107], [64734.3, 0.003], [64735.3, 0.618], [64742.7, 0.004], [64759.0, 0.321], [64768.4, 0.043], [64772.2, 0.005], [64834.2, 5.406], [64835.3, 0.029], [64851.2, 10.419], [64989.7, 5.972], [65247.0, 0.111], [65276.7, 2.141], [65341.2, 2.294], [65341.3, 1.404], [65464.2, 6.782]]}
{"kind": "depth", "E": 1787081864445, "U": 11315468103130, "u": 11315468108922, "recv_ms": 1787081864416, "bids": [[1000.0, 35.81], [14194.2, 0.42], [14494.2, 0.056], [14594.2, 3.724], [58224.7, 0.002], [61459.5, 0.014], [62106.4, 0.689], [63461.0, 0.089], [63694.2, 0.0], [64047.3, 0.266], [64590.4, 14.172], [64665.1, 0.831], [64675.2, 2.179], [64675.3, 1.005], [64675.4, 0.354], [64681.3, 1.785], [64685.3, 0.735], [64686.4, 0.004], [64686.8, 0.086], [64687.5, 0.57], [64687.6, 0.001], [64687.7, 0.087], [64687.8, 0.0], [64687.9, 1.079], [64688.0, 0.253], [64688.3, 0.0], [64689.0, 0.222], [64689.2, 0.022], [64689.8, 0.103], [64690.4, 0.019], [64694.2, 6.939]], "asks": [[64694.3, 11.019], [64696.4, 0.31], [64697.4, 0.003], [64698.2, 0.003], [64704.2, 1.941], [64716.6, 10.004], [64761.3, 32.749], [64761.6, 0.007], [64763.5, 0.0], [64823.7, 0.0], [65336.4, 0.001], [65341.2, 2.294], [65528.5, 1.526], [65694.3, 0.0]]}
{"kind": "depth", "E": 1787081864547, "U": 11315468108979, "u": 11315468115881, "recv_ms": 1787081864518, "bids": [[1000.0, 35.81], [14194.2, 0.252], [14494.2, 0.252], [14594.2, 3.696], [51755.4, 0.0], [58224.7, 0.002], [61459.4, 0.0], [62106.4, 0.692], [63917.9, 14.67], [64047.3, 0.264], [64150.8, 0.291], [64175.9, 0.16], [64176.6, 4.047], [64370.7, 1.709], [64483.3, 0.0], [64485.2, 0.373], [64493.7, 0.002], [64495.5, 0.005], [64504.1, 0.028], [64514.5, 0.0], [64524.9, 0.007], [64535.3, 0.002], [64545.7, 0.0], [64556.1, 0.205], [64566.5, 0.012], [64574.2, 0.0], [64576.9, 0.013], [64587.3, 0.0], [64597.7, 0.41], [64603.5, 0.028], [64603.6, 0.85], [64608.1, 0.03], [64618.5, 0.006], [64628.6, 0.004], [64628.9, 0.147], [64639.3, 0.006], [64648.6, 0.0], [64649.7, 2.13], [64659.2, 0.786], [64660.1, 0.013], [64661.3, 0.002], [64663.8, 0.002], [64664.7, 0.319], [64666.9, 0.032], [64670.5, 0.233], [64676.4, 0.959], [64677.1, 0.018], [64677.7, 0.008], [64678.0, 0.982], [64678.6, 0.213], [64681.4, 0.01], [64683.6, 0.003], [64683.8, 0.026], [64684.3, 1.309], [64684.4, 0.112], [64684.8, 0.039], [64685.2, 0.001], [64685.3, 0.194], [64685.4, 2.592], [64685.8, 0.151], [64686.4, 0.088], [64687.5, 0.424], [64687.6, 0.001], [64687.9, 0.233], [64688.0, 0.253], [64688.1, 0.07], [64688.2, 0.003], [64688.3, 0.002], [64688.4, 0.056], [64688.9, 0.06], [64689.0, 0.2], [64689.1, 0.145], [64689.2, 0.023], [64689.4, 0.002], [64689.9, 0.043], [64690.0, 0.022], [64690.3, 0.0], [64690.4, 0.001], [64690.5, 0.017], [64691.4, 0.0], [64691.6, 0.001], [64692.0, 0.003], [64694.2, 5.939]], "asks": [[64694.3, 11.028], [64694.9, 0.043], [64696.2, 0.003], [64696.4, 0.313], [64697.3, 0.085], [64698.3, 0.006], [64698.5, 1.128], [64698.6, 1.901], [64700.3, 0.0], [64700.7, 0.001], [64700.8, 0.02], [64701.3, 0.701], [64706.9, 0.127], [64707.1, 0.292], [64709.7, 0.007], [64709.8, 0.002], [64713.7, 0.392], [64713.8, 5.074], [64714.5, 0.914], [64720.0, 0.025], [64720.2, 0.608], [64720.9, 0.002], [64730.6, 0.001], [64734.3, 0.003], [64741.0, 0.0], [64751.4, 0.014], [64759.0, 0.294], [64761.3, 0.0], [64761.8, 0.0], [64763.5, 32.749], [64764.2, 0.0], [64767.9, 0.022], [64772.2, 0.0], [64782.6, 0.155], [64793.0, 0.134], [64803.4, 0.0], [64813.8, 0.0], [64824.2, 0.002], [64834.2, 3.673], [64834.6, 0.023], [64835.4, 0.001], [64845.0, 0.001], [64851.2, 7.646], [64855.4, 2.993], [64865.8, 0.013], [64876.2, 0.002], [64886.6, 0.018], [64890.0, 13.95], [64897.0, 0.017], [65017.8, 1.709], [65211.9, 3.675], [65341.2, 2.294]]}
{"kind": "depth", "E": 1787081864649, "U": 11315468116103, "u": 11315468122167, "recv_ms": 1787081864630, "bids": [[14194.2, 0.14], [14494.2, 0.49], [14594.2, 3.57], [58224.7, 0.002], [61459.4, 0.0], [61459.5, 0.016], [63566.9, 0.0], [63694.2, 0.02], [63807.4, 0.0], [63955.3, 0.819], [64047.3, 0.264], [64106.2, 8.425], [64370.7, 1.709], [64505.8, 0.006], [64635.9, 0.023], [64648.6, 0.004], [64674.8, 0.384], [64681.4, 0.01], [64684.3, 0.463], [64685.3, 0.171], [64685.4, 1.989], [64686.7, 1.776], [64686.8, 1.496], [64687.5, 0.784], [64687.6, 0.727], [64688.2, 0.065], [64688.4, 0.14], [64688.5, 0.001], [64688.7, 0.027], [64688.8, 0.105], [64689.1, 0.047], [64689.2, 0.003], [64689.9, 0.179], [64690.0, 0.003], [64694.2, 5.941]], "asks": [[64694.3, 11.03], [64694.4, 0.121], [64694.6, 1.022], [64695.2, 0.104], [64698.5, 0.0], [64698.6, 0.0], [64699.6, 0.003], [64700.0, 0.004], [64700.3, 0.008], [64700.8, 1.14], [64702.0, 1.906], [64714.6, 0.313], [64721.9, 0.003], [64730.3, 0.005], [64739.6, 0.0], [64761.3, 32.749], [64763.5, 0.0], [64772.1, 0.002], [64851.2, 10.419], [65308.9, 2.985], [65341.2, 2.294], [65463.8, 0.763], [65503.0, 4.028], [65694.3, 0.02]]}
{"kind": "depth", "E": 1787081864751, "U": 11315468122838, "u": 11315468128539, "recv_ms": 1787081864719, "bids": [[1000.0, 35.81], [14194.2, 0.014], [14494.2, 0.728], [14594.2, 3.458], [58224.7, 0.002], [62106.4, 0.689], [63694.2, 0.0], [64047.3, 0.264], [64079.6, 2.07], [64150.8, 0.254], [64370.7, 1.708], [64496.1, 0.001], [64496.2, 15.029], [64516.1, 0.008], [64526.4, 5.219], [64574.0, 1.074], [64628.5, 0.173], [64634.3, 0.018], [64661.2, 0.074], [64675.2, 2.025], [64679.3, 0.002], [64681.4, 0.465], [64683.8, 0.025], [64684.1, 0.003], [64684.3, 0.0], [64685.1, 0.001], [64686.8, 1.48], [64686.9, 0.011], [64687.6, 0.001], [64687.7, 0.087]], "asks": [[64696.4, 0.313], [64700.0, 0.004], [64700.3, 0.008], [64734.2, 0.076], [64740.6, 0.006], [64750.9, 0.005], [64772.1, 0.171], [64835.2, 2.601], [64890.0, 6.119], [65207.8, 5.205], [65341.2, 2.294], [65470.6, 8.208], [65497.9, 5.397], [65528.5, 0.764], [65609.7, 4.568], [65613.0, 1.464], [65694.3, 0.0]]}
{"kind": "depth", "E": 1787081864853, "U": 11315468128559, "u": 11315468133843, "recv_ms": 1787081864821, "bids": [[1000.0, 35.81], [14194.2, 0.0], [14494.2, 1.064], [14594.2, 3.136], [58224.7, 0.002], [62106.4, 0.692], [64047.3, 0.264], [64499.0, 6.422], [64536.3, 1.106], [64536.7, 0.005], [64574.0, 0.792], [64592.0, 2.294], [64620.1, 0.004], [64620.8, 9.157], [64628.5, 0.004], [64649.1, 0.683], [64661.2, 0.001], [64670.9, 0.582], [64671.1, 1.681], [64680.6, 0.326], [64681.4, 0.01], [64684.1, 0.004], [64684.3, 0.463], [64685.1, 0.0], [64686.9, 0.019], [64693.8, 0.313], [64694.1, 0.147]], "asks": [[64695.2, 0.082], [64700.3, 0.105], [64701.3, 0.7], [64714.1, 2.473], [64734.2, 0.003], [64759.4, 6.378], [64761.2, 0.005], [64772.1, 0.002], [64835.2, 2.319], [65017.8, 1.71], [65284.7, 0.012], [65341.2, 2.294], [65593.3, 0.761]]}
{"kind": "depth", "E": 1787081864955, "U": 11315468134026, "u": 11315468145804, "recv_ms": 1787081864924, "bids": [[14494.2, 1.428], [14594.2, 2.772], [58224.7, 0.002], [62106.4, 0.689], [62791.2, 0.682], [63694.2, 0.02], [63788.5, 7.703], [64047.3, 0.264], [64150.8, 0.182], [64370.7, 1.718], [64547.0, 0.008], [64557.3, 0.017], [64574.0, 0.792], [64628.5, 0.004], [64629.5, 0.037], [64636.0, 0.347], [64637.2, 0.0], [64642.5, 0.107], [64649.0, 0.636], [64655.5, 0.198], [64658.9, 0.004], [64661.2, 0.001], [64662.0, 0.04], [64668.5, 0.039], [64670.5, 0.79], [64671.2, 0.005], [64671.8, 0.124], [64671.9, 0.02], [64672.5, 0.004], [64674.7, 0.011], [64675.8, 0.927], [64676.4, 0.033], [64681.4, 0.465], [64684.3, 0.008], [64684.4, 0.112], [64684.7, 0.394], [64688.9, 0.082], [64691.3, 0.001], [64692.0, 0.002]], "asks": [[64694.3, 11.028], [64694.4, 0.144], [64696.4, 0.313], [64700.3, 0.008], [64704.2, 1.959], [64723.2, 0.232], [64723.3, 1.246], [64723.4, 1.707], [64726.2, 2.323], [64726.3, 0.004], [64726.4, 0.198], [64727.0, 0.075], [64727.2, 0.01], [64727.9, 0.278], [64729.3, 0.033], [64729.4, 0.004], [64734.2, 0.003], [64735.3, 0.0], [64736.7, 1.205], [64739.6, 0.003], [64759.0, 0.295], [64762.5, 0.008], [64762.6, 2.052], [64771.5, 0.005], [64772.1, 0.002], [64781.8, 0.027], [64835.2, 2.319], [65341.2, 2.294], [65470.6, 9.734], [65623.1, 4.546], [65694.3, 0.02]]}
{"kind": "depth", "E": 1787081865057, "U": 11315468145925, "u": 11315468156792, "recv_ms": 1787081865026, "bids": [[1000.0, 35.81], [14494.2, 1.778], [14594.2, 2.422], [58224.7, 0.002], [61459.4, 0.0], [63545.9, 0.786], [64047.3, 0.073], [64150.8, 0.151], [64567.6, 0.005], [64574.0, 0.792], [64628.5, 0.004], [64652.7, 0.11], [64661.0, 0.18], [64661.2, 0.001], [64664.5, 0.206], [64675.0, 0.164], [64677.6, 0.005], [64677.8, 0.371], [64681.4, 0.002], [64682.6, 0.028], [64684.0, 2.868], [64684.1, 1.173], [64684.2, 0.328], [64684.3, 0.631], [64684.4, 0.028], [64685.3, 0.172], [64688.2, 0.313], [64688.3, 0.003], [64689.1, 0.109], [64689.2, 0.002], [64689.3, 0.09], [64694.2, 6.467]], "asks": [[64694.3, 11.011], [64694.4, 0.121], [64694.6, 1.002], [64694.9, 0.0], [64695.6, 0.019], [64695.8, 0.111], [64700.1, 0.391], [64700.3, 0.008], [64701.8, 2.333], [64704.0, 0.397], [64705.6, 0.009], [64705.7, 0.04], [64706.9, 0.131], [64709.3, 0.504], [64711.8, 0.049], [64716.6, 10.006], [64716.8, 1.251], [64727.1, 0.312], [64729.2, 0.082], [64734.2, 0.003], [64772.1, 0.002], [64792.1, 0.006], [64835.2, 2.319], [65211.9, 3.98], [65276.8, 2.142], [65341.2, 2.296], [65584.5, 4.384], [65871.7, 0.606], [65988.1, 0.021]]}
{"kind": "depth", "E": 1787081865159, "U": 11315468156850, "u": 11315468166197, "recv_ms": 1787081865127, "bids": [[1000.0, 35.81], [14494.2, 2.142], [14594.2, 2.058], [51755.0, 0.0], [58224.7, 0.002], [61459.4, 0.0], [62106.4, 0.692], [63988.3, 8.826], [64047.3, 0.073], [64514.5, 2.929], [64517.0, 0.135], [64518.1, 0.309], [64577.9, 0.005], [64588.2, 0.011], [64637.4, 0.0], [64644.6, 0.522], [64677.2, 0.081], [64678.0, 0.902], [64689.0, 0.22], [64693.8, 0.003], [64693.9, 0.148]], "asks": [[64694.3, 11.026], [64700.3, 0.009], [64752.7, 0.0], [64802.4, 0.026], [64812.7, 0.007], [64851.2, 7.618], [64890.0, 6.763], [65341.2, 2.294], [65460.1, 1.68]]}
{"kind": "depth", "E": 1787081865261, "U": 11315468166317, "u": 11315468175301, "recv_ms": 1787081865229, "bids": [[14494.2, 2.492], [14594.2, 1.708], [58224.7, 0.002], [62106.4, 0.689], [63529.7, 1.258], [63600.1, 2.454], [63694.2, 0.0], [64047.3, 0.073], [64150.8, 0.114], [64370.7, 1.708], [64574.0, 0.792], [64574.1, 0.002], [64598.5, 0.008], [64628.5, 0.004], [64661.2, 0.001], [64674.9, 0.171], [64676.0, 1.782], [64677.2, 0.001], [64688.7, 0.005], [64688.8, 0.085], [64689.3, 0.113], [64689.5, 0.021]], "asks": [[64694.5, 0.459], [64694.8, 0.107], [64695.1, 0.021], [64695.3, 0.607], [64695.6, 0.0], [64695.8, 0.088], [64696.4, 0.313], [64734.2, 0.003], [64772.1, 0.002], [64823.0, 0.01], [64835.3, 0.029], [64851.2, 10.419], [64890.0, 3.699], [65276.6, 7.277], [65284.5, 1.303], [65336.0, 18.535], [65341.2, 2.294], [65600.0, 101.32], [65609.7, 5.329], [65694.3, 0.0], [65917.0, 0.758]]}
{"kind": "depth", "E": 1787081865363, "U": 11315468175379, "u": 11315468180518, "recv_ms": 1787081865331, "bids": [[1000.0, 35.81], [14494.2, 2.856], [14594.2, 1.344], [58224.7, 0.002], [62106.4, 0.692], [63594.4, 3.561], [63837.1, 2.192], [63982.6, 1.07], [64047.3, 0.073], [64150.8, 0.077], [64608.8, 0.1], [64619.1, 1.552], [64677.8, 0.371], [64685.3, 0.079], [64686.9, 0.112], [64689.3, 0.09], [64689.5, 0.001]], "asks": [[64694.5, 0.44], [64694.8, 0.084], [64710.3, 0.214], [64823.7, 0.0], [64833.3, 0.078], [64843.6, 0.005], [65341.2, 2.294], [65341.3, 1.403], [65600.0, 101.776]]}
{"kind": "depth", "E": 1787081865465, "U": 11315468180683, "u": 11315468188178, "recv_ms": 1787081865436, "bids": [[1000.0, 35.81], [14494.2, 3.206], [14594.2, 0.994], [58224.7, 0.002], [61459.4, 0.0], [62106.4, 0.689], [63694.2, 0.02], [63940.6, 1.634], [64014.9, 2.419], [64047.3, 0.073], [64574.1, 0.002], [64628.6, 0.004], [64629.4, 0.217], [64655.3, 4.145], [64661.2, 0.001], [64671.4, 0.618], [64674.9, 0.171], [64678.8, 0.621], [64685.5, 0.234], [64685.6, 0.017], [64686.9, 0.019], [64688.0, 0.021], [64688.7, 0.237], [64689.6, 0.035]], "asks": [[64694.3, 11.017], [64718.8, 0.621], [64726.1, 0.618], [64734.3, 0.003], [64772.1, 0.002], [64835.3, 0.029], [64851.2, 10.419], [64853.9, 0.375], [64890.0, 5.831], [65284.5, 0.232], [65308.9, 3.596], [65341.2, 2.294], [65426.6, 11.049], [65694.3, 0.02]]}
{"kind": "depth", "E": 1787081865567, "U": 11315468188430, "u": 11315468195210, "recv_ms": 1787081865534, "bids": [[14494.2, 3.57], [14594.2, 0.63], [51755.4, 0.0], [58224.7, 0.002], [61459.4, 0.0], [61459.6, 2.439], [63820.8, 6.522], [64047.3, 0.073], [64370.7, 1.717], [64603.4, 0.099], [64603.5, 0.025], [64639.7, 0.035], [64639.8, 0.295], [64650.0, 3.935], [64674.8, 0.538], [64674.9, 0.017], [64685.6, 0.001], [64686.9, 0.035]], "asks": [[64694.3, 11.017], [64696.5, 0.005], [64864.2, 0.006], [64874.5, 0.005], [64894.6, 0.014], [64894.7, 0.002], [65341.2, 2.294], [65464.2, 7.697], [65543.4, 0.0]]}
{"kind": "depth", "E": 1787081865669, "U": 11315468195355, "u": 11315468201927, "recv_ms": 1787081865638, "bids": [[1000.0, 35.81], [14394.2, 0.084], [14494.2, 3.752], [14594.2, 0.364], [51755.0, 0.0], [58224.7, 0.002], [62106.4, 0.692], [63400.4, 0.084], [63694.2, 0.0], [63885.5, 5.075], [64047.3, 0.073], [64176.6, 4.047], [64660.3, 0.062], [64674.7, 0.165], [64674.8, 0.384], [64679.9, 0.078], [64685.6, 0.017], [64686.8, 0.634], [64686.9, 0.019], [64689.4, 0.025]], "asks": [[64694.3, 11.002], [64694.5, 0.46], [64694.7, 0.911], [64884.8, 3.531], [65017.8, 1.711], [65341.2, 2.294], [65399.5, 1.39], [65541.2, 30.291], [65659.6, 12.171], [65694.3, 0.0]]}
{"kind": "depth", "E": 1787081865771, "U": 11315468202036, "u": 11315468210125, "recv_ms": 1787081865742, "bids": [[1000.0, 35.81], [14394.2, 0.308], [14494.2, 3.668], [14594.2, 0.224], [58224.7, 0.002], [61459.4, 0.0], [61459.5, 0.014], [61459.6, 2.441], [62106.4, 0.689], [63400.4, 0.081], [63863.3, 0.0], [64047.3, 0.073], [64652.7, 0.124], [64655.2, 0.163], [64655.3, 2.865], [64670.5, 0.233], [64670.6, 0.373], [64671.4, 0.0], [64671.5, 0.561], [64671.8, 0.008], [64672.9, 0.116], [64675.1, 0.081], [64676.0, 1.702], [64677.7, 0.001], [64678.8, 0.003], [64678.9, 0.008], [64684.6, 0.006], [64685.3, 0.078], [64685.5, 0.157], [64685.6, 0.001], [64686.8, 0.109], [64686.9, 0.096], [64687.0, 0.577], [64689.1, 0.132], [64689.2, 0.022], [64689.4, 0.002], [64689.6, 0.016], [64694.2, 7.143]], "asks": [[64694.3, 11.017], [64694.5, 0.44], [64696.5, 0.005], [64700.3, 0.008], [64715.3, 0.005], [64715.8, 0.115], [64718.8, 0.003], [64726.1, 0.0], [64759.0, 0.322], [64834.2, 3.809], [64835.3, 0.029], [64851.2, 5.245], [64890.0, 8.833], [64895.1, 0.007], [65276.6, 8.348], [65341.2, 2.294], [67282.1, 0.649]]}
{"kind": "depth", "E": 1787081865975, "U": 11315468219179, "u": 11315468226121, "recv_ms": 1787081865955, "bids": [[1000.0, 35.81], [14394.2, 0.798], [14494.2, 3.402], [14594.2, 0.0], [58224.7, 0.002], [61459.4, 0.0], [62106.4, 0.689], [63694.2, 0.02], [63821.4, 14.95], [64047.3, 0.307], [64172.7, 0.62], [64370.7, 1.718], [64496.3, 14.95], [64551.8, 0.212], [64552.1, 18.303], [64635.9, 0.026], [64675.8, 0.001], [64677.4, 0.929], [64684.0, 2.327], [64684.4, 0.569], [64685.5, 0.157], [64685.6, 0.001], [64686.8, 0.195], [64686.9, 0.551], [64687.0, 0.036], [64687.6, 0.001], [64689.3, 0.006], [64694.2, 7.079]], "asks": [[64694.3, 11.016], [64694.7, 0.889], [64696.5, 0.005], [64711.5, 0.0], [64712.2, 2.331], [64713.8, 0.074], [64714.4, 0.005], [64715.1, 0.602], [64739.6, 0.003], [64749.0, 1.789], [64749.2, 0.001], [64834.3, 3.608], [64851.2, 4.887], [64890.0, 0.659], [64890.1, 9.189], [65207.8, 1.377], [65341.2, 2.523], [65500.0, 335.74], [65535.3, 9.685], [65694.3, 0.02]]}
{"kind": "depth", "E": 1787081866077, "U": 11315468226216, "u": 11315468232267, "recv_ms": 1787081866045, "bids": [[1000.0, 35.81], [14394.2, 1.148], [14494.2, 3.052], [58224.7, 0.002], [61459.4, 0.0], [62106.5, 0.006], [63701.0, 1.412], [63768.0, 0.038], [63794.9, 0.782], [63901.9, 5.835], [64047.3, 0.307], [64150.8, 0.101], [64496.3, 14.95], [64646.4, 0.009], [64652.7, 0.11], [64659.4, 1.708], [64672.4, 1.891], [64672.9, 0.0], [64676.4, 0.959], [64677.4, 0.003], [64682.6, 0.028], [64684.6, 0.005], [64685.3, 0.079], [64685.4, 1.99], [64685.5, 0.25], [64686.8, 0.089], [64686.9, 0.01], [64687.0, 0.577], [64687.6, 0.017], [64688.9, 0.06], [64689.6, 0.039], [64694.2, 7.072]], "asks": [[64694.3, 10.882], [64694.6, 1.002], [64695.1, 0.001], [64695.3, 0.584], [64695.6, 0.02], [64695.7, 0.027], [64696.4, 0.31], [64700.1, 0.391], [64709.3, 0.504], [64711.4, 0.054], [64712.6, 0.663], [64834.3, 5.398], [64851.2, 7.265], [64890.1, 9.142], [64894.5, 0.003], [64894.6, 0.011], [65341.2, 2.523], [65470.7, 9.184], [65620.6, 1.522], [65687.6, 0.038]]}
{"kind": "depth", "E": 1787081866179, "U": 11315468232319, "u": 11315468238135, "recv_ms": 1787081866147, "bids": [[14394.2, 1.512], [14494.2, 2.688], [58224.7, 0.002], [61459.6, 2.439], [62106.4, 0.692], [63694.2, 0.0], [63701.0, 1.42], [63765.6, 0.03], [63768.0, 0.046], [64047.3, 0.307], [64370.7, 1.718], [64686.8, 0.086]], "asks": [[64696.4, 0.31], [64696.9, 0.087], [64697.4, 0.001], [64698.2, 0.005], [64699.3, 0.004], [64749.0, 1.759], [64749.2, 0.031], [64851.2, 10.419], [64890.1, 4.863], [65211.9, 7.808], [65276.5, 3.212], [65341.2, 2.523], [65480.3, 3.164], [65496.2, 0.765], [65622.9, 0.0], [65694.3, 0.0], [65988.1, 0.018], [71163.8, 0.0]]}
{"kind": "depth", "E": 1787081866281, "U": 11315468238204, "u": 11315468244948, "recv_ms": 1787081866249, "bids": [[1000.0, 35.81], [14394.2, 1.862], [14494.2, 2.338], [51755.0, 0.0], [58224.7, 0.002], [62106.4, 0.689], [64047.3, 0.307], [64176.6, 7.937], [64366.7, 0.62], [64670.1, 0.562], [64671.0, 2.335], [64671.5, 0.004], [64671.6, 0.123], [64672.4, 1.775], [64675.6, 1.101], [64676.4, 0.033], [64681.4, 0.543], [64684.4, 0.028], [64685.8, 0.154]], "asks": [[64711.3, 0.561], [64711.8, 0.042], [64712.2, 1.775], [64712.8, 0.009], [64713.4, 0.945], [64714.4, 0.12], [64715.1, 0.061], [64715.8, 0.0], [64890.1, 4.864], [65011.4, 0.193], [65013.8, 0.849], [65341.2, 2.523], [65415.6, 2.289], [65464.2, 8.612], [65470.6, 10.953], [65483.7, 0.002], [65620.6, 1.53], [65622.9, 0.008], [65687.6, 0.046]]}
{"kind": "depth", "E": 1787081866383, "U": 11315468244973, "u": 11315468252230, "recv_ms": 1787081866350, "bids": [[1000.0, 35.81], [14394.2, 2.226], [14494.2, 1.974], [51755.0, 0.0], [58224.7, 0.002], [61459.4, 0.0], [62106.4, 0.692], [63400.4, 0.084], [63520.1, 0.786], [63694.2, 0.02], [63908.2, 1.567], [63934.3, 4.763], [64047.3, 0.307], [64496.3, 0.004], [64496.4, 9.841], [64677.8, 0.369], [64681.4, 0.002], [64684.4, 0.569], [64688.0, 0.022], [64689.0, 0.2], [64689.5, 0.108], [64689.6, 0.016], [64689.7, 0.02], [64694.2, 7.071]], "asks": [[64694.9, 0.02], [64695.1, 0.001], [64696.4, 0.31], [64699.3, 0.003], [64701.3, 0.041], [64704.2, 1.434], [64710.3, 0.212], [64713.4, 0.404], [64714.0, 0.547], [64714.4, 0.005], [64715.3, 0.12], [64823.7, 0.0], [64890.1, 10.12], [65341.2, 2.523], [65694.3, 0.02]]}
{"kind": "depth", "E": 1787081866485, "U": 11315468252340, "u": 11315468257815, "recv_ms": 1787081866453, "bids": [[14394.2, 2.576], [14494.2, 1.624], [51755.0, 0.0], [51755.4, 0.0], [58224.7, 0.002], [61459.4, 0.0], [61459.5, 0.016], [63837.1, 1.567], [63901.9, 5.602], [64047.3, 0.307], [64370.7, 1.708], [64496.4, 9.841], [64660.3, 0.221], [64671.3, 0.001], [64677.8, 0.371], [64678.6, 0.213], [64681.2, 2.336], [64681.3, 1.785], [64681.4, 0.002], [64684.0, 2.868], [64684.3, 0.623], [64684.4, 0.028], [64684.7, 0.31], [64685.5, 0.165], [64687.1, 0.094], [64689.9, 0.263]], "asks": [[64694.3, 10.933], [64696.9, 0.084], [64710.3, 0.214], [64718.6, 0.008], [64723.2, 0.23], [64723.3, 1.244], [64723.4, 1.705], [64726.0, 0.668], [64726.2, 2.321], [64726.3, 0.002], [64726.4, 0.196], [64727.0, 0.073], [64727.1, 0.31], [64727.2, 0.008], [64729.2, 0.08], [64729.3, 0.031], [64729.4, 0.002], [64890.1, 10.121], [65017.8, 4.013], [65341.2, 2.523], [65480.3, 3.927]]}
{"kind": "depth", "E": 1787081866587, "U": 11315468257849, "u": 11315468264388, "recv_ms": 1787081866557, "bids": [[1000.0, 35.81], [14394.2, 2.94], [14494.2, 1.26], [51755.0, 0.0], [58224.7, 0.002], [62106.4, 0.689], [63600.1, 2.063], [63694.2, 0.0], [63763.6, 0.944], [64047.3, 0.307], [64370.7, 4.035], [64371.1, 1.988], [64496.4, 14.947], [64627.5, 0.002], [64637.2, 0.014], [64650.2, 0.457], [64661.9, 0.623], [64684.3, 0.16], [64685.5, 0.628], [64686.8, 0.736], [64686.9, 0.01], [64687.0, 0.036], [64687.1, 0.001], [64687.6, 0.001], [64690.0, 0.004], [64694.2, 7.099]], "asks": [[64694.3, 10.934], [64713.7, 0.321], [64723.9, 0.31], [64739.9, 0.99], [64740.0, 0.123], [64762.6, 0.073], [64762.7, 0.001], [64890.1, 5.548], [65341.2, 2.523], [65545.0, 2.959], [65694.3, 0.0]]}
{"kind": "depth", "E": 1787081866689, "U": 11315468264720, "u": 11315468270275, "recv_ms": 1787081866660, "bids": [[14394.2, 3.276], [14494.2, 0.924], [58224.7, 0.002], [61459.4, 0.0], [62106.4, 0.692], [62745.0, 0.743], [63400.4, 0.081], [63820.8, 7.147], [64047.3, 0.307], [64370.7, 4.036], [64595.8, 0.786], [64598.1, 0.996], [64618.5, 40.147], [64620.7, 0.183], [64620.8, 0.013], [64621.7, 0.009], [64622.9, 0.003], [64624.0, 0.047], [64624.3, 0.162], [64624.4, 0.0], [64624.7, 0.0], [64625.0, 1.59], [64625.3, 0.006], [64634.4, 0.001], [64634.5, 0.0], [64634.6, 0.325], [64634.8, 0.0], [64634.9, 0.022], [64635.0, 7.655], [64635.1, 0.001], [64635.3, 0.407], [64637.2, 0.0], [64644.5, 0.133], [64644.9, 0.004], [64645.2, 0.0], [64645.5, 0.002], [64645.9, 5.016], [64646.2, 2.323], [64646.4, 0.041], [64652.5, 0.001], [64654.9, 0.001], [64655.0, 0.145], [64655.1, 0.066], [64655.2, 0.063], [64659.8, 0.005], [64659.9, 0.092], [64661.4, 1.686], [64674.6, 5.358], [64675.2, 2.713], [64680.3, 0.003], [64680.4, 0.003], [64680.5, 1.046], [64680.6, 0.156], [64680.7, 0.202], [64680.8, 0.63], [64680.9, 0.013], [64681.0, 0.0], [64681.1, 1.259], [64681.3, 1.715], [64681.5, 0.085], [64681.8, 0.206], [64682.5, 0.022], [64682.8, 0.049], [64683.3, 0.086], [64683.9, 3.317], [64684.9, 0.032]], "asks": [[64694.3, 11.044], [64696.3, 0.087], [64700.5, 0.003], [64700.7, 0.464], [64700.8, 0.677], [64700.9, 1.45], [64701.2, 0.0], [64701.5, 0.473], [64701.9, 0.514], [64702.1, 0.118], [64702.2, 0.003], [64702.3, 0.003], [64702.4, 0.255], [64702.5, 0.001], [64702.6, 0.001], [64702.7, 0.001], [64702.8, 0.002], [64702.9, 0.015], [64703.0, 1.493], [64703.1, 0.003], [64704.5, 2.412], [64706.9, 0.131], [64722.2, 0.051], [64723.5, 2.326], [64724.7, 0.014], [64725.1, 0.017], [64725.4, 0.158], [64725.7, 0.004], [64726.0, 0.623], [64726.4, 0.006], [64726.8, 1.807], [64728.2, 0.001], [64728.3, 0.464], [64728.4, 0.002], [64728.5, 0.628], [64731.0, 0.389], [64731.2, 1.152], [64731.3, 0.06], [64731.4, 0.391], [64731.6, 0.003], [64731.7, 3.921], [64731.9, 1.249], [64741.4, 0.104], [64745.6, 0.005], [64745.9, 0.001], [64746.3, 0.002], [64746.6, 0.029], [64746.9, 0.0], [64795.1, 0.0], [65017.8, 4.012], [65341.2, 2.523], [65413.9, 0.236], [65567.7, 4.485], [65672.5, 11.321]]}
{"kind": "depth", "E": 1787081866791, "U": 11315468270351, "u": 11315468275957, "recv_ms": 1787081866762, "bids": [[14394.2, 3.654], [14494.2, 0.546], [58224.7, 0.002], [62106.4, 0.689], [63546.0, 0.3], [63694.2, 0.02], [64047.3, 0.307], [64370.7, 4.036], [64618.6, 7.293], [64619.1, 1.552], [64623.2, 6.0], [64645.9, 8.516], [64646.8, 0.035], [64662.0, 0.996], [64664.6, 0.312], [64665.6, 0.048], [64684.0, 2.968], [64684.2, 0.428], [64685.2, 0.033]], "asks": [[64695.3, 0.606], [64695.6, 0.0], [64695.7, 0.005], [64702.7, 0.043], [64703.7, 0.19], [64703.9, 0.201], [64719.8, 1.02], [64721.9, 0.045], [64722.9, 0.855], [64726.2, 2.511], [64736.0, 3.525], [64741.1, 0.167], [64758.7, 6.002], [64762.8, 1.528], [64793.7, 0.013], [64793.8, 1.713], [64795.1, 0.008], [65341.2, 2.523], [65519.8, 4.083], [65694.3, 0.02]]}
{"kind": "depth", "E": 1787081866893, "U": 11315468276037, "u": 11315468281228, "recv_ms": 1787081866862, "bids": [[1000.0, 35.81], [14294.2, 0.126], [14394.2, 3.752], [14494.2, 0.322], [58224.7, 0.002], [61459.5, 0.018], [62106.4, 0.692], [63416.7, 0.0], [63488.6, 0.315], [63560.5, 0.0], [63594.4, 3.953], [63632.4, 0.203], [63704.3, 0.395], [63723.8, 10.042], [63776.2, 0.001], [63848.1, 0.0], [63920.0, 0.952], [63991.9, 0.624], [64047.3, 0.307], [64057.5, 0.0], [64063.8, 0.001], [64590.9, 10.015], [64618.5, 0.006], [64618.6, 0.003], [64620.7, 40.324], [64646.1, 0.033], [64647.1, 0.133], [64683.4, 0.523], [64683.5, 0.142], [64683.7, 0.204], [64683.8, 0.125], [64684.0, 3.068], [64684.1, 1.243], [64684.3, 0.23], [64684.6, 0.037], [64685.5, 0.66]], "asks": [[64696.4, 0.31], [64702.3, 0.041], [64703.3, 0.046], [64703.6, 0.116], [64703.8, 0.259], [64704.1, 0.33], [64704.2, 1.574], [64704.3, 0.125], [64704.4, 0.124], [64704.5, 2.51], [64721.5, 0.269], [64722.5, 0.047], [64723.3, 1.414], [64725.8, 0.115], [64726.0, 0.721], [64726.1, 0.16], [64726.4, 0.156], [64726.5, 0.314], [64726.6, 2.33], [64726.7, 6.235], [64740.8, 1.245], [64741.7, 0.071], [64791.0, 10.0], [65341.2, 2.523], [65358.0, 2.087], [65406.0, 1.491], [65429.9, 0.002], [65466.6, 14.826], [65501.8, 0.002], [65573.7, 0.01], [65645.6, 0.0], [65717.5, 0.0], [65789.4, 0.011], [65861.3, 0.024], [65868.4, 0.759], [65933.2, 0.031], [66005.1, 2.371]]}
{"kind": "depth", "E": 1787081866995, "U": 11315468281319, "u": 11315468287406, "recv_ms": 1787081866965, "bids": [[14294.2, 0.364], [14394.2, 3.64], [14494.2, 0.196], [58224.7, 0.002], [61459.4, 0.0], [63694.2, 0.0], [64047.3, 0.307], [64370.7, 4.035], [64496.4, 0.002], [64499.0, 4.774], [64534.8, 0.143], [64536.3, 0.444], [64552.1, 13.502], [64592.0, 3.597], [64627.2, 0.045], [64647.4, 0.039], [64674.6, 0.358], [64683.6, 0.073], [64683.8, 0.225], [64683.9, 3.387], [64685.9, 0.032], [64694.2, 7.092]], "asks": [[64694.3, 11.045], [64696.8, 0.015], [64702.0, 1.038], [64704.0, 0.645], [64704.2, 1.665], [64721.2, 0.27], [64726.2, 2.609], [64726.3, 0.152], [64726.5, 0.405], [64740.4, 0.255], [64790.4, 2.905], [64834.3, 0.0], [64851.2, 0.011], [64890.1, 0.011], [65023.9, 0.008], [65341.2, 2.523], [65470.6, 15.529], [65645.3, 0.548], [65694.3, 0.0]]}
{"kind": "depth", "E": 1787081867097, "U": 11315468287612, "u": 11315468294090, "recv_ms": 1787081867068, "bids": [[14294.2, 0.602], [14394.2, 3.514], [14494.2, 0.084], [51755.0, 0.0], [58224.7, 0.002], [62106.4, 0.689], [62106.5, 0.0], [63934.3, 4.544], [64047.3, 0.307], [64370.7, 4.035], [64496.4, 15.507], [64535.2, 4.952], [64552.2, 4.709], [64557.6, 0.787], [64562.0, 0.006], [64620.7, 0.183], [64622.9, 40.144], [64627.5, 0.034], [64661.1, 0.213], [64682.6, 0.028], [64683.6, 0.143]], "asks": [[64704.3, 0.23], [64704.9, 0.447], [64726.6, 2.435], [64834.3, 5.398], [64851.2, 10.419], [64890.1, 4.864], [65017.6, 0.108], [65017.8, 4.013], [65341.2, 2.523], [65519.8, 3.825], [65672.5, 10.789]]}
{"kind": "depth", "E": 1787081867199, "U": 11315468294346, "u": 11315468300763, "recv_ms": 1787081867167, "bids": [[1000.0, 35.81], [14294.2, 0.882], [14394.2, 3.318], [14494.2, 0.0], [51755.0, 0.0], [58224.7, 0.004], [61459.4, 0.0], [62106.4, 0.706], [63694.2, 0.02], [64047.3, 0.463], [64150.8, 0.101], [64603.3, 0.023], [64603.4, 0.096], [64616.5, 0.286], [64618.5, 39.283], [64619.1, 1.561], [64622.9, 0.003], [64626.9, 0.038], [64627.9, 0.032], [64635.9, 0.023], [64655.4, 1.231], [64661.7, 0.101], [64661.8, 0.179], [64664.9, 0.114], [64668.4, 1.06], [64681.2, 2.336], [64681.3, 1.715]], "asks": [[64694.3, 11.032], [64695.1, 0.024], [64696.4, 0.31], [64701.3, 0.042], [64707.4, 1.215], [64714.0, 5.547], [64733.3, 0.0], [64739.6, 0.0], [64761.3, 0.0], [64765.7, 33.644], [64772.0, 0.006], [64807.8, 0.151], [64807.9, 0.0], [65341.2, 2.523], [65463.8, 0.0], [65645.3, 1.081], [65694.3, 0.02], [65915.8, 0.0]]}
{"kind": "depth", "E": 1787081867301, "U": 11315468300768, "u": 11315468306285, "recv_ms": 1787081867270, "bids": [[14294.2, 1.232], [14394.2, 2.968], [58224.7, 0.002], [61459.4, 0.0], [62106.4, 0.703], [64047.3, 0.463], [64403.3, 0.026], [64618.5, 0.006], [64619.1, 1.552], [64620.7, 39.46], [64621.7, 0.018], [64628.2, 0.823], [64661.1, 0.283], [64661.2, 0.071], [64661.3, 0.072], [64661.4, 1.786], [64661.5, 0.11], [64661.6, 0.102], [64662.0, 1.066], [64664.5, 0.306], [64670.1, 0.005], [64671.2, 0.562], [64671.6, 0.007], [64672.5, 0.12]], "asks": [[64694.3, 11.031], [64726.0, 0.103], [64759.4, 1.721], [64761.3, 33.643], [64763.5, 0.0], [64764.2, 0.0], [64765.7, 0.001], [65341.2, 2.525], [65988.1, 0.015]]}
{"kind": "depth", "E": 1787081867403, "U": 11315468306369, "u": 11315468312306, "recv_ms": 1787081867372, "bids": [[14294.2, 1.596], [14394.2, 2.604], [58224.7, 0.002], [61459.4, 0.0], [62106.4, 0.706], [63694.2, 0.0], [63769.6, 7.2], [63963.8, 4.299], [64047.3, 0.463], [64370.7, 4.035], [64552.2, 4.735], [64661.4, 1.856], [64661.6, 0.172], [64674.7, 0.011], [64677.8, 0.369], [64684.3, 0.231], [64684.4, 0.499], [64684.7, 0.31], [64685.3, 0.078], [64685.5, 0.189], [64689.9, 0.179], [64694.2, 5.886]], "asks": [[64694.3, 11.136], [64696.4, 0.31], [64701.3, 0.041], [64710.3, 0.212], [64732.8, 0.022], [64750.8, 0.0], [64823.7, 0.0], [64834.3, 5.398], [64851.2, 7.234], [64890.1, 8.725], [65284.2, 0.237], [65341.2, 2.523], [65694.3, 0.0]]}
{"kind": "depth", "E": 1787081867505, "U": 11315468312399, "u": 11315468317620, "recv_ms": 1787081867475, "bids": [[1000.0, 35.81], [14294.2, 1.946], [14394.2, 2.254], [51755.4, 0.0], [58224.7, 0.002], [63694.2, 0.02], [64047.3, 0.463], [64620.7, 0.183], [64622.9, 39.28], [64661.3, 0.142], [64674.7, 0.165], [64674.8, 0.384], [64677.8, 0.371], [64678.9, 0.626], [64688.7, 0.005], [64689.4, 0.022], [64689.5, 0.085], [64689.7, 0.0], [64690.0, 0.003]], "asks": [[64694.3, 11.136], [64699.0, 0.001], [64710.3, 0.214], [64851.2, 10.419], [64890.1, 5.239], [65257.1, 0.235], [65341.2, 2.523], [65616.9, 7.115], [65632.4, 14.49], [65694.3, 0.02], [65948.2, 4.088], [67282.1, 0.636]]}
{"kind": "depth", "E": 1787081867607, "U": 11315468317647, "u": 11315468324199, "recv_ms": 1787081867575, "bids": [[14294.2, 2.31], [14394.2, 1.89], [58224.7, 0.002], [61459.4, 0.0], [61459.5, 0.016], [61459.6, 2.441], [62106.4, 0.703], [63292.6, 0.004], [63293.3, 0.002], [63400.4, 0.084], [63743.2, 1.887], [64047.3, 0.463], [64439.2, 0.643], [64454.0, 0.002], [64621.7, 0.009], [64671.5, 0.622], [64675.6, 0.175], [64677.3, 3.247], [64687.9, 0.465], [64688.0, 0.023], [64689.5, 0.001], [64694.2, 5.885]], "asks": [[64694.3, 11.135], [64695.3, 0.584], [64696.4, 0.31], [64701.0, 0.929], [64711.3, 0.005], [64712.1, 0.557], [64714.0, 5.006], [64714.6, 0.854], [64715.3, 0.005], [64716.0, 0.258], [64718.9, 1.009], [64726.2, 3.227], [64761.3, 0.0], [64761.6, 0.025], [64763.5, 33.643], [64764.2, 0.0], [64765.7, 0.001], [64834.3, 5.398], [64851.2, 10.419], [64890.1, 5.239], [65341.2, 2.523], [65466.6, 14.064], [65470.6, 16.291], [65519.8, 3.597]]}
{"kind": "depth", "E": 1787081867709, "U": 11315468324356, "u": 11315468334619, "recv_ms": 1787081867696, "bids": [[1000.0, 35.81], [14294.2, 2.66], [14394.2, 1.54], [51755.0, 0.0], [58224.7, 0.002], [62106.4, 0.706], [63607.8, 0.0], [63885.5, 5.426], [63937.3, 2.211], [64047.3, 0.463], [64117.7, 6.776], [64148.1, 0.002], [64370.7, 4.044], [64428.6, 0.06], [64438.8, 0.144], [64454.5, 0.438], [64464.7, 0.016], [64480.3, 0.001], [64490.6, 2.51], [64506.2, 0.113], [64516.4, 0.008], [64532.1, 0.001], [64542.3, 0.0], [64618.5, 39.283], [64621.7, 0.018], [64622.9, 0.003], [64676.4, 0.959], [64677.3, 2.321]], "asks": [[64694.7, 0.909], [64694.8, 0.107], [64695.3, 0.604], [64698.0, 1.225], [64704.2, 1.286], [64705.0, 0.001], [64856.4, 0.002], [64882.3, 1.07], [64908.2, 0.556], [64934.0, 0.015], [64959.9, 0.001], [65017.8, 4.014], [65341.2, 2.523], [65920.9, 4.092]]}
{"kind": "depth", "E": 1787081867811, "U": 11315468334788, "u": 11315468341743, "recv_ms": 1787081867779, "bids": [[1000.0, 35.81], [14294.2, 3.024], [14394.2, 1.176], [51755.0, 0.0], [58224.7, 0.002], [62106.4, 0.703], [63620.7, 12.241], [63694.2, 0.0], [64047.3, 0.463], [64112.0, 5.197], [64148.6, 0.035], [64552.2, 0.024], [64618.5, 0.006], [64620.7, 39.46], [64620.8, 8.644], [64684.4, 0.491], [64685.5, 0.197]], "asks": [[64696.4, 0.31], [64699.7, 0.089], [64702.4, 0.252], [64762.8, 6.424], [64834.3, 0.0], [65341.2, 2.523], [65629.8, 0.684], [65694.3, 0.0]]}
{"kind": "depth", "E": 1787081867913, "U": 11315468341915, "u": 11315468348142, "recv_ms": 1787081867882, "bids": [[14294.2, 3.374], [14394.2, 0.826], [58224.7, 0.002], [61459.4, 0.0], [63581.5, 1.256], [64047.3, 0.463], [64552.3, 7.098], [64576.5, 4.867], [64579.4, 0.046], [64620.7, 39.506], [64623.7, 0.0], [64668.3, 1.079], [64670.6, 0.93], [64671.2, 0.005], [64674.6, 0.512], [64674.7, 0.011], [64680.5, 0.004], [64684.5, 0.066], [64685.5, 0.189], [64693.9, 0.002], [64694.0, 0.096], [64694.1, 0.149]], "asks": [[64694.3, 11.144], [64694.5, 0.695], [64697.0, 0.905], [64703.0, 0.593], [64710.8, 2.894], [64712.1, 0.001], [64763.2, 1.264], [64766.1, 0.072], [64827.4, 3.865], [64830.8, 1.062], [64834.3, 3.769], [64851.2, 4.887], [64890.1, 8.186], [65341.2, 2.523], [65988.1, 0.018]]}
{"kind": "depth", "E": 1787081868117, "U": 11315468365444, "u": 11315468373637, "recv_ms": 1787081868086, "bids": [[1000.0, 35.81], [14194.2, 0.196], [14294.2, 3.71], [14394.2, 0.294], [51755.0, 0.014], [58224.7, 0.002], [61459.4, 0.0], [62106.4, 0.703], [63635.0, 0.058], [63701.0, 1.41], [63706.9, 0.058], [63778.8, 0.934], [63850.8, 0.058], [63885.5, 5.66], [63890.5, 0.003], [63922.7, 0.682], [63994.6, 0.058], [64047.3, 0.463], [64066.5, 0.058], [64370.7, 4.045], [64496.5, 9.887], [64620.7, 0.229], [64622.9, 38.492], [64671.5, 0.004], [64678.9, 0.008], [64682.6, 0.028], [64684.3, 0.23], [64684.4, 0.028], [64684.5, 0.058], [64685.3, 0.079], [64685.4, 1.906], [64685.5, 0.66], [64687.9, 0.233], [64688.8, 0.317], [64689.2, 0.106], [64689.9, 0.263], [64690.3, 0.084], [64692.9, 0.0], [64693.5, 0.021], [64694.2, 6.411]], "asks": [[64694.3, 10.91], [64694.8, 0.023], [64697.1, 0.009], [64697.7, 0.006], [64700.1, 0.311], [64700.5, 0.003], [64700.7, 0.472], [64700.8, 0.669], [64701.6, 0.002], [64703.0, 1.493], [64704.0, 0.725], [64706.9, 0.131], [64710.8, 2.338], [64711.7, 0.591], [64714.0, 0.006], [64718.9, 0.391], [64726.2, 2.609], [64761.3, 33.643], [64761.6, 0.007], [64762.8, 1.528], [64763.5, 0.0], [64890.1, 10.155], [65017.8, 4.013], [65341.2, 2.523], [65360.7, 2.211], [65432.6, 0.058], [65504.5, 0.385], [65519.8, 3.255], [65576.4, 0.058], [65648.4, 0.058], [65687.6, 0.036], [65720.3, 0.061], [65792.2, 0.058], [65794.1, 0.67], [65864.1, 0.144], [65936.0, 0.059], [66007.9, 0.058]]}
{"kind": "depth", "E": 1787081868219, "U": 11315468373653, "u": 11315468380640, "recv_ms": 1787081868189, "bids": [[14194.2, 0.42], [14294.2, 3.612], [14394.2, 0.168], [51755.0, 0.0], [58224.7, 0.002], [61459.5, 0.018], [62106.4, 0.706], [63694.2, 0.0], [63701.0, 1.42], [63917.9, 14.889], [64020.1, 0.78], [64047.3, 0.463], [64496.5, 9.867], [64618.5, 38.495], [64620.8, 0.013], [64621.7, 0.009], [64622.9, 0.003], [64684.0, 2.527], [64684.2, 0.969], [64685.6, 0.001], [64689.9, 0.105], [64690.0, 0.246]], "asks": [[64834.3, 3.873], [64851.2, 2.032], [64851.3, 5.034], [64851.4, 1.465], [64890.1, 10.396], [65285.5, 0.0], [65321.8, 1.515], [65341.2, 2.523], [65519.8, 3.026], [65694.3, 0.0]]}
{"kind": "depth", "E": 1787081868321, "U": 11315468380826, "u": 11315468387055, "recv_ms": 1787081868292, "bids": [[1000.0, 35.81], [14194.2, 0.672], [14294.2, 3.472], [14394.2, 0.056], [51755.0, 0.0], [58224.7, 0.002], [62106.4, 0.703], [63821.4, 14.043], [64370.7, 4.045], [64618.5, 0.006], [64620.7, 38.718], [64635.9, 0.026], [64668.3, 1.082]], "asks": [[64696.4, 0.31], [64707.3, 1.892], [64739.6, 0.003], [65341.2, 2.523], [65687.6, 0.046]]}
{"kind": "depth", "E": 1787081868423, "U": 11315468387116, "u": 11315468393662, "recv_ms": 1787081868391, "bids": [[1000.0, 35.81], [14194.2, 0.966], [14294.2, 3.234], [14394.2, 0.0], [58224.7, 0.002], [61459.4, 0.0], [63694.2, 0.02], [64047.3, 0.463], [64620.7, 0.229], [64622.9, 38.492], [64694.2, 6.434]], "asks": [[64701.6, 0.001], [64702.0, 1.938], [64823.7, 0.0], [65281.4, 0.23], [65341.2, 2.523], [65503.0, 4.257], [65584.4, 1.217], [65694.3, 0.02]]}
{"kind": "depth", "E": 1787081868525, "U": 11315468393835, "u": 11315468400732, "recv_ms": 1787081868493, "bids": [[14194.2, 1.316], [14294.2, 2.884], [51755.4, 0.0], [58224.7, 0.002], [61459.4, 0.0], [61459.5, 0.02], [62106.4, 0.706], [63529.7, 1.266], [63794.9, 1.689], [64047.3, 0.463], [64535.2, 0.002], [64535.3, 5.103], [64552.3, 7.121], [64635.9, 0.026], [64677.8, 0.371], [64686.8, 0.738], [64688.0, 0.022], [64688.9, 0.017], [64692.6, 0.042], [64694.2, 6.456]], "asks": [[64694.3, 10.895], [64694.7, 0.889], [64696.4, 0.31], [64710.3, 0.214], [64739.6, 0.003], [64834.3, 3.836], [64851.2, 0.011], [64851.3, 4.977], [65341.2, 2.523], [65497.9, 3.886], [66012.9, 0.0]]}
{"kind": "depth", "E": 1787081868627, "U": 11315468400999, "u": 11315468408102, "recv_ms": 1787081868597, "bids": [[1000.0, 35.81], [14194.2, 1.68], [14294.2, 2.52], [51755.0, 0.0], [58224.7, 0.002], [62106.4, 0.703], [62791.2, 0.0], [63694.2, 0.0], [63834.3, 0.626], [64047.3, 0.463], [64370.7, 4.045], [64688.8, 0.085], [64689.6, 0.248]], "asks": [[64694.6, 1.021], [64834.3, 5.398], [64851.3, 10.408], [65341.2, 2.525], [65519.8, 2.797], [65694.3, 0.0], [67929.0, 0.01]]}
{"kind": "depth", "E": 1787081868729, "U": 11315468408332, "u": 11315468415020, "recv_ms": 1787081868699, "bids": [[1000.0, 35.81], [14194.2, 2.03], [14294.2, 2.17], [58224.7, 0.002], [62106.4, 0.706], [63807.9, 0.625], [64047.3, 0.463], [64552.3, 2.319], [64659.9, 0.002], [64667.1, 0.149]], "asks": [[64694.3, 10.896], [64695.3, 0.584], [64697.8, 0.106], [64834.3, 0.0], [65017.8, 4.012], [65341.2, 2.523], [65519.8, 2.569], [65567.7, 5.093]]}
{"kind": "depth", "E": 1787081868831, "U": 11315468415063, "u": 11315468422267, "recv_ms": 1787081868800, "bids": [[14194.2, 2.394], [14294.2, 1.806], [58224.7, 0.002], [61459.4, 0.0], [62106.4, 0.703], [63400.4, 0.087], [63694.2, 0.02], [63808.4, 0.001], [63917.9, 15.108], [64047.3, 0.463], [64370.7, 4.046], [64535.3, 0.002], [64585.3, 2.351], [64588.3, 0.001], [64639.8, 0.281], [64642.4, 1.645], [64655.3, 2.851], [64657.9, 0.448], [64671.2, 0.623], [64674.4, 5.012], [64678.6, 0.831], [64679.8, 0.003], [64682.4, 0.004], [64689.6, 0.016], [64690.0, 0.478]], "asks": [[64696.4, 0.31], [64718.6, 0.626], [64726.0, 0.721], [64799.4, 2.319], [64801.1, 0.003], [64851.3, 0.0], [65341.2, 2.523], [65415.6, 3.052], [65470.6, 17.816], [65503.0, 4.515], [65694.3, 0.02], [65988.1, 0.015]]}
{"kind": "depth", "E": 1787081868933, "U": 11315468422423, "u": 11315468428517, "recv_ms": 1787081868903, "bids": [[1000.0, 35.81], [14194.2, 2.744], [14294.2, 1.456], [58224.7, 0.002], [61459.6, 2.439], [63620.7, 11.614], [63766.0, 0.159], [64047.3, 0.463], [64172.7, 0.31], [64366.7, 0.465], [64623.0, 6.551], [64689.4, 0.044]], "asks": [[64701.4, 0.925], [64704.2, 1.811], [64707.2, 1.775], [64713.7, 0.25], [64759.4, 6.512], [65013.8, 0.695], [65341.2, 2.523], [65466.6, 13.379], [65519.8, 2.311], [65722.8, 0.76], [65867.2, 0.65], [66692.7, 0.0]]}
{"kind": "depth", "E": 1787081869035, "U": 11315468428674, "u": 11315468435704, "recv_ms": 1787081869002, "bids": [[1000.0, 35.81], [14194.2, 3.108], [14294.2, 1.092], [58224.7, 0.002], [61459.4, 0.0], [62106.4, 0.706], [63727.6, 0.02], [63763.6, 0.004], [64047.3, 0.463], [64496.5, 9.387], [64535.4, 3.892], [64536.3, 0.997], [64552.3, 6.53], [64682.6, 0.033]], "asks": [[64694.3, 10.895], [64696.4, 0.31], [64704.6, 0.314], [64834.3, 5.398], [64851.3, 10.408], [64890.1, 12.619], [65341.2, 2.523]]}
{"kind": "depth", "E": 1787081869137, "U": 11315468435892, "u": 11315468444497, "recv_ms": 1787081869106, "bids": [[14194.2, 3.458], [14294.2, 0.742], [58224.7, 0.002], [62106.4, 0.703], [63594.4, 4.58], [63694.2, 0.0], [63749.7, 1.096], [64047.3, 0.463], [64370.7, 4.035], [64680.5, 0.005], [64682.6, 0.028], [64689.2, 0.086]], "asks": [[64701.2, 0.001], [64701.6, 0.002], [64834.3, 5.398], [64851.3, 10.408], [65017.8, 4.013], [65207.8, 1.072], [65336.0, 17.848], [65341.2, 2.523], [65694.3, 0.0]]}
{"kind": "depth", "E": 1787081869239, "U": 11315468444710, "u": 11315468454717, "recv_ms": 1787081869208, "bids": [[1000.0, 35.81], [14194.2, 3.724], [14294.2, 0.434], [14594.2, 0.042], [51755.0, 0.0], [58224.7, 0.002], [61459.4, 0.0], [62106.4, 0.706], [63719.2, 0.274], [63858.9, 7.036], [64047.3, 0.463], [64176.6, 8.248], [64370.7, 4.19], [64616.5, 0.289], [64655.3, 2.854]], "asks": [[64694.3, 10.855], [64696.4, 0.31], [64733.2, 0.041], [64762.6, 0.027], [64804.3, 1.392], [64834.3, 5.398], [64851.3, 10.408], [65017.8, 4.167], [65341.2, 2.523], [65470.6, 18.501], [65600.0, 101.959], [67924.8, 0.0]]}
{"kind": "depth", "E": 1787081869341, "U": 11315468455147, "u": 11315468460689, "recv_ms": 1787081869340, "bids": [[1000.0, 35.81], [14194.2, 3.682], [14294.2, 0.266], [14594.2, 0.252], [58224.7, 0.002], [61459.4, 0.0], [63400.4, 0.084], [63694.2, 0.02], [63885.6, 7.826], [63901.9, 5.337], [64047.2, 0.026], [64047.3, 0.463], [64639.8, 0.295], [64655.3, 2.868], [64674.4, 0.012], [64690.1, 0.002]], "asks": [[64694.3, 10.853], [64746.0, 2.055], [64834.3, 3.775], [64851.3, 4.887], [64890.1, 10.431], [65211.9, 8.113], [65308.9, 4.283], [65341.2, 2.523], [65503.0, 4.743], [65613.0, 1.92], [65694.3, 0.02], [65988.1, 0.012]]}
{"kind": "depth", "E": 1787081869443, "U": 11315468460761, "u": 11315468467041, "recv_ms": 1787081869412, "bids": [[14194.2, 3.584], [14294.2, 0.14], [14594.2, 0.476], [51755.0, 0.0], [58224.7, 0.002], [61459.4, 0.0], [62106.4, 0.703], [63853.2, 5.396], [64047.3, 0.463], [64370.7, 4.19], [64497.2, 0.0], [64525.4, 0.019], [64627.5, 0.032], [64627.7, 4.677], [64659.2, 0.45], [64664.5, 0.642], [64671.2, 0.005], [64678.6, 0.213], [64686.7, 1.777], [64687.6, 0.063], [64689.1, 0.07], [64689.3, 0.238], [64690.0, 0.246], [64694.2, 7.127]], "asks": [[64694.3, 9.638], [64696.4, 0.31], [64696.8, 0.012], [64697.4, 0.003], [64697.7, 0.004], [64698.1, 0.003], [64698.4, 0.008], [64701.5, 0.164], [64701.6, 0.001], [64702.1, 0.427], [64718.6, 0.008], [64720.4, 0.002], [64726.0, 0.103], [64732.6, 0.059], [64733.8, 3.766], [64796.4, 0.029], [64823.7, 0.0], [64834.3, 3.41], [64851.3, 4.208], [65156.1, 0.0], [65341.2, 2.523], [65528.5, 0.002], [65623.1, 2.283]]}
{"kind": "depth", "E": 1787081869545, "U": 11315468467146, "u": 11315468474842, "recv_ms": 1787081869514, "bids": [[1000.0, 35.81], [14194.2, 3.458], [14294.2, 0.028], [14594.2, 0.714], [51755.4, 0.0], [58224.7, 0.002], [61459.4, 0.0], [62106.4, 0.706], [63694.2, 0.0], [63901.9, 5.104], [63913.9, 7.312], [64047.3, 0.463], [64677.8, 0.371], [64689.4, 0.022], [64689.6, 0.039], [64694.2, 7.152]], "asks": [[64694.6, 1.002], [64694.8, 0.0], [64694.9, 0.0], [64695.1, 0.001], [64699.0, 0.012], [64704.9, 0.127], [64708.2, 0.63], [64710.3, 0.214], [64716.8, 1.249], [64834.3, 5.398], [64851.3, 10.408], [64890.1, 10.087], [65152.1, 0.115], [65341.2, 2.525], [65694.3, 0.0]]}
{"kind": "depth", "E": 1787081869647, "U": 11315468474900, "u": 11315468480762, "recv_ms": 1787081869618, "bids": [[1000.0, 35.81], [14194.2, 3.15], [14294.2, 0.0], [14594.2, 1.05], [58224.7, 0.002], [62106.4, 0.689], [62116.4, 0.002], [63594.4, 5.522], [63858.7, 0.173], [63885.5, 5.816], [64047.3, 0.463], [64685.6, 0.001], [64686.8, 0.197], [64686.9, 0.01], [64687.0, 0.036], [64687.1, 0.542], [64687.9, 0.232], [64689.3, 0.006], [64689.8, 0.122], [64689.9, 0.105], [64690.3, 0.316], [64694.0, 0.001], [64694.1, 0.149], [64694.2, 7.774]], "asks": [[64695.5, 0.02], [64695.7, 0.028], [64696.5, 0.005], [65013.8, 0.541], [65341.2, 2.523]]}
{"kind": "depth", "E": 1787081869749, "U": 11315468480889, "u": 11315468486152, "recv_ms": 1787081869717, "bids": [[14194.2, 2.8], [14594.2, 1.4], [58224.7, 0.002], [61459.4, 0.0], [62106.4, 0.692], [63694.2, 0.02], [63917.9, 19.795], [64047.3, 0.463], [64370.7, 4.189], [64576.5, 1.003], [64576.6, 4.205], [64616.5, 0.286], [64620.7, 0.183], [64620.9, 0.118], [64635.9, 0.026], [64685.6, 0.549], [64686.0, 0.003], [64686.8, 0.197], [64686.9, 0.003], [64687.1, 0.001], [64687.6, 0.063], [64690.1, 0.001], [64690.8, 0.086], [64694.2, 7.869]], "asks": [[64739.6, 0.003], [64763.2, 1.218], [64763.3, 0.068], [64804.3, 1.389], [64827.4, 0.001], [64827.6, 4.457], [65017.8, 4.321], [65341.2, 2.523], [65694.3, 0.02], [65800.0, 68.357]]}
{"kind": "depth", "E": 1787081869851, "U": 11315468486290, "u": 11315468492545, "recv_ms": 1787081869819, "bids": [[1000.0, 35.81], [14194.2, 2.436], [14594.2, 1.764], [51755.0, 0.0], [58224.7, 0.002], [63791.9, 0.0], [63821.4, 12.479], [63843.5, 0.782], [63853.0, 1.213], [64047.3, 0.463], [64552.3, 2.319], [64552.4, 6.061], [64687.6, 0.789]], "asks": [[64696.5, 0.005], [64834.3, 5.398], [64890.1, 10.426], [65017.8, 4.322], [65341.2, 2.523]]}
{"kind": "depth", "E": 1787081869953, "U": 11315468492691, "u": 11315468499832, "recv_ms": 1787081869923, "bids": [[1000.0, 35.81], [14194.2, 2.086], [14594.2, 2.114], [58224.7, 0.002], [62106.4, 0.689], [63694.2, 0.0], [64047.3, 0.463], [64620.1, 2.392], [64660.5, 0.0], [64685.6, 0.549], [64685.7, 0.08], [64686.8, 0.088], [64687.6, 0.063], [64687.7, 0.087]], "asks": [[64700.3, 0.008], [64851.2, 2.834], [65341.2, 2.525], [65503.0, 5.314], [65694.3, 0.0], [65794.1, 1.048], [65917.0, 0.0]]}
{"kind": "depth", "E": 1787081870055, "U": 11315468499854, "u": 11315468505650, "recv_ms": 1787081870025, "bids": [[14194.2, 1.722], [14594.2, 2.478], [58224.7, 0.002], [61459.4, 0.0], [61459.5, 0.018], [61459.6, 2.441], [62106.4, 0.692], [63694.2, 0.02], [63794.9, 3.253], [63889.4, 0.0], [63955.4, 0.781], [63972.9, 1.568], [64015.5, 9.191], [64047.3, 0.467], [64370.7, 4.199], [64629.5, 0.036], [64639.8, 0.281], [64655.3, 2.854], [64657.1, 0.002], [64668.8, 0.187], [64668.9, 0.006], [64669.5, 0.634], [64670.7, 0.204], [64670.9, 0.601], [64671.9, 0.022], [64672.2, 0.023], [64673.2, 5.491], [64676.9, 0.619], [64679.1, 0.257], [64680.2, 0.674], [64682.6, 0.028], [64685.6, 0.001], [64685.7, 0.003], [64686.8, 0.197], [64686.9, 0.003], [64687.0, 0.584], [64690.4, 0.002], [64694.2, 7.875]], "asks": [[64694.3, 9.496], [64695.3, 0.5], [64702.0, 1.038], [64716.9, 0.722], [64717.0, 0.001], [64724.3, 0.002], [64759.0, 0.321], [65341.2, 2.523], [65496.2, 0.003], [65694.3, 0.02], [65705.7, 0.002], [65988.1, 0.009], [66321.5, 0.0]]}
{"kind": "depth", "E": 1787081870157, "U": 11315468505658, "u": 11315468510235, "recv_ms": 1787081870126, "bids": [[1000.0, 35.81], [14194.2, 1.358], [14594.2, 2.842], [51755.0, 0.0], [58224.7, 0.002], [62106.4, 0.689], [64047.3, 0.463], [64370.7, 4.2], [64574.2, 0.0], [64628.7, 0.104], [64661.3, 0.142], [64676.9, 0.001], [64677.5, 0.154], [64685.6, 0.549], [64686.8, 0.197], [64686.9, 0.003], [64687.0, 0.036], [64687.1, 0.001], [64687.6, 0.063], [64689.8, 0.103]], "asks": [[64696.5, 0.005], [64698.1, 0.001], [64698.8, 0.006], [64700.6, 0.313], [64734.4, 1.519], [64772.2, 0.0], [64835.4, 0.001], [64894.4, 26.851], [64894.5, 0.0], [65017.8, 4.321], [65341.2, 2.523]]}
{"kind": "depth", "E": 1787081870259, "U": 11315468510293, "u": 11315468515328, "recv_ms": 1787081870230, "bids": [[1000.0, 35.81], [14194.2, 1.008], [14594.2, 3.192], [51755.0, 0.002], [58224.7, 0.002], [61459.4, 0.0], [61459.5, 0.02], [63400.4, 0.087], [63620.7, 10.83], [63989.0, 2.427], [64047.3, 0.465], [64552.4, 1.26], [64552.5, 4.241], [64654.3, 0.063], [64654.8, 0.003], [64661.3, 0.144], [64661.4, 1.858], [64661.5, 0.112], [64664.8, 0.072], [64664.9, 0.116], [64665.0, 0.056], [64669.5, 0.016], [64672.2, 0.021], [64689.4, 0.002], [64689.6, 0.016], [64689.7, 0.023], [64689.9, 0.125], [64694.2, 7.878]], "asks": [[64698.1, 0.085], [64698.6, 0.657], [64699.9, 0.01], [64700.0, 0.904], [64700.3, 0.0], [64700.6, 0.312], [64700.7, 0.464], [64700.8, 0.02], [64757.9, 0.223], [64758.5, 0.442], [64834.3, 5.398], [65341.2, 2.523], [65629.8, 0.457], [65821.4, 1.971], [65964.2, 1.954], [65988.1, 0.012]]}
{"kind": "depth", "E": 1787081870361, "U": 11315468515377, "u": 11315468520110, "recv_ms": 1787081870331, "bids": [[14194.2, 0.658], [14594.2, 3.542], [34000.0, 1.146], [51755.0, 0.0], [58224.7, 0.002], [61459.4, 0.0], [62106.4, 0.692], [63694.2, 0.0], [63853.2, 6.335], [64047.2, 0.025], [64047.3, 0.463], [64370.7, 4.19], [64496.5, 0.08], [64496.7, 9.249], [64535.4, 0.003], [64535.5, 3.876], [64536.3, 0.444], [64552.5, 4.21], [64574.2, 0.0], [64628.7, 0.104], [64661.3, 0.144], [64672.9, 0.04], [64676.3, 0.003], [64689.1, 0.047], [64690.3, 0.335], [64694.2, 7.878]], "asks": [[64694.3, 9.481], [64696.5, 0.005], [64701.0, 0.032], [64704.3, 0.227], [64734.4, 1.519], [64759.4, 1.721], [64761.3, 0.0], [64761.6, 0.025], [64763.5, 34.707], [64764.2, 0.0], [64765.6, 0.441], [64765.7, 0.001], [64766.3, 0.024], [64772.2, 0.0], [64823.7, 0.0], [64834.3, 5.398], [64835.4, 0.001], [65341.2, 2.523], [65503.0, 5.543], [65519.8, 1.969], [65694.3, 0.0], [65722.8, 0.0], [66316.3, 4.368]]}
{"kind": "depth", "E": 1787081870463, "U": 11315468520117, "u": 11315468525387, "recv_ms": 1787081870432, "bids": [[1000.0, 35.81], [14194.2, 0.364], [14494.2, 0.07], [14594.2, 3.766], [58224.7, 0.002], [62106.4, 0.689], [62745.0, 1.425], [64047.3, 0.463], [64574.2, 0.0], [64628.7, 0.104], [64661.3, 0.144], [64690.1, 0.024]], "asks": [[64694.3, 9.468], [64695.2, 0.102], [64734.4, 1.519], [64761.3, 34.707], [64761.6, 0.007], [64763.5, 0.0], [64772.2, 0.0], [64835.4, 0.001], [65283.1, 0.0], [65341.2, 2.523], [65503.0, 5.771], [65607.8, 1.837], [65674.4, 2.28], [65948.2, 0.0]]}
{"kind": "depth", "E": 1787081870565, "U": 11315468525705, "u": 11315468531146, "recv_ms": 1787081870535, "bids": [[1000.0, 35.81], [14194.2, 0.238], [14494.2, 0.308], [14594.2, 3.654], [51755.4, 0.0], [58224.7, 0.002], [62106.4, 0.692], [63594.4, 6.306], [63694.2, 0.02], [63901.9, 4.87], [63950.3, 8.608], [64047.3, 0.463], [64566.9, 0.0], [64574.2, 0.0], [64628.6, 0.004], [64661.3, 0.144], [64677.8, 0.371]], "asks": [[64710.3, 0.214], [64734.3, 0.003], [64772.2, 0.0], [64835.4, 0.001], [65341.2, 2.523], [65694.3, 0.02]]}
{"kind": "depth", "E": 1787081870667, "U": 11315468531169, "u": 11315468535695, "recv_ms": 1787081870638, "bids": [[14194.2, 0.112], [14494.2, 0.532], [14594.2, 3.556], [58224.7, 0.002], [62106.4, 0.689], [63400.4, 0.084], [63782.0, 2.338], [64047.3, 0.463], [64150.8, 0.077], [64176.6, 8.248], [64370.7, 4.19], [64574.2, 0.0], [64597.2, 0.014], [64628.6, 0.004], [64661.3, 0.144], [64670.1, 0.562], [64670.6, 0.373], [64671.6, 0.123], [64672.5, 0.004], [64675.7, 1.247], [64676.4, 0.033], [64681.4, 0.543], [64684.2, 0.428], [64689.9, 0.105]], "asks": [[64695.2, 0.082], [64695.7, 0.005], [64696.5, 0.005], [64710.5, 0.556], [64711.7, 0.035], [64714.4, 0.12], [64716.0, 0.143], [64716.4, 0.004], [64734.3, 0.003], [64772.2, 0.0], [64835.4, 0.001], [65341.2, 2.523], [65503.0, 6.029], [65580.6, 1.216], [65920.9, 8.182], [66643.5, 0.642], [71163.7, 0.002]]}
{"kind": "depth", "E": 1787081870769, "U": 11315468535760, "u": 11315468540260, "recv_ms": 1787081870740, "bids": [[1000.0, 35.81], [14194.2, 0.0], [14494.2, 0.77], [14594.2, 3.43], [58224.7, 0.002], [61459.6, 2.439], [63694.2, 0.0], [63723.8, 10.982], [63955.3, 0.038], [64047.3, 0.463], [64106.2, 7.737], [64150.8, 0.012], [64670.1, 0.005], [64671.2, 0.562], [64681.4, 0.002], [64684.0, 3.068]], "asks": [[64710.5, 0.0], [64711.5, 0.556], [64714.4, 0.005], [64715.4, 0.241], [64890.1, 9.284], [65017.8, 4.32], [65276.6, 8.578], [65341.2, 2.523], [65694.3, 0.0], [71163.7, 0.0]]}
{"kind": "depth", "E": 1787081870871, "U": 11315468540428, "u": 11315468545685, "recv_ms": 1787081870842, "bids": [[1000.0, 35.81], [14494.2, 1.134], [14594.2, 3.066], [58224.7, 0.002], [61459.4, 0.0], [62106.4, 0.692], [62116.4, 0.001], [63885.5, 6.081], [64047.3, 0.463], [64117.5, 0.0], [64370.7, 4.191], [64535.5, 5.085], [64552.5, 4.797], [64574.2, 0.0], [64628.6, 0.004], [64636.3, 0.009], [64645.3, 0.0], [64661.3, 0.144], [64671.6, 0.007], [64673.4, 0.116], [64675.7, 0.321], [64677.5, 1.08], [64684.0, 2.527], [64685.6, 0.549], [64686.1, 0.088], [64686.9, 0.544], [64689.7, 0.0], [64689.9, 0.003], [64690.0, 0.17], [64690.3, 0.251], [64690.5, 0.036], [64690.8, 0.002], [64690.9, 0.019]], "asks": [[64694.3, 9.552], [64694.8, 0.084], [64695.4, 0.176], [64695.8, 0.11], [64696.4, 0.31], [64696.5, 0.008], [64698.1, 0.087], [64698.5, 0.541], [64698.6, 0.116], [64698.8, 0.004], [64699.7, 0.005], [64699.9, 0.002], [64700.7, 0.001], [64700.8, 0.028], [64701.4, 0.25], [64701.6, 0.464], [64704.2, 1.286], [64711.5, 0.0], [64712.2, 2.331], [64715.4, 0.126], [64716.3, 0.115], [64719.8, 0.985], [64734.3, 0.003], [64761.3, 0.0], [64762.6, 0.004], [64764.2, 0.018], [64765.7, 34.708], [64772.2, 0.0], [64799.2, 0.002], [64834.3, 5.398], [64835.4, 0.001], [64851.2, 0.011], [64851.3, 10.408], [64864.4, 0.0], [64890.1, 9.21], [65341.2, 2.523], [65466.6, 12.921], [67331.7, 0.0]]}
{"kind": "depth", "E": 1787081870973, "U": 11315468545794, "u": 11315468550537, "recv_ms": 1787081870958, "bids": [[14494.2, 1.498], [14594.2, 2.702], [58224.7, 0.002], [62106.4, 0.689], [63694.2, 0.02], [63950.3, 7.827], [64047.3, 0.463], [64117.7, 6.542], [64370.7, 4.191], [64536.3, 1.175], [64632.1, 2.964], [64635.9, 0.023], [64636.3, 0.005], [64645.1, 0.031], [64654.0, 0.002], [64672.4, 1.891], [64673.4, 0.0], [64676.4, 0.959], [64677.5, 0.154], [64684.2, 0.969], [64685.6, 0.001], [64686.9, 0.003], [64687.0, 0.043], [64687.1, 0.542], [64689.5, 0.085], [64694.2, 7.897]], "asks": [[64697.5, 0.044], [64698.4, 0.008], [64698.5, 0.0], [64698.6, 1.128], [64700.8, 0.02], [64701.6, 0.001], [64746.0, 2.078], [64761.3, 34.707], [64761.6, 0.007], [64763.5, 0.0], [64764.2, 0.0], [64765.7, 0.001], [64851.2, 2.834], [65341.2, 2.523], [65616.9, 6.932], [65694.3, 0.02]]}
{"kind": "depth", "E": 1787081871075, "U": 11315468550550, "u": 11315468559613, "recv_ms": 1787081871044, "bids": [[1000.0, 35.81], [14494.2, 1.848], [14594.2, 2.352], [58224.7, 0.002], [61459.4, 0.0], [62106.4, 0.692], [63600.9, 0.63], [63627.2, 0.016], [63710.3, 2.279], [63843.6, 0.782], [64020.1, 0.0], [64047.3, 0.463], [64079.6, 2.758], [64117.7, 6.308], [64566.8, 0.263], [64574.1, 0.002], [64628.6, 0.004], [64635.9, 0.026], [64654.7, 0.767], [64661.3, 0.144], [64662.1, 2.637], [64671.9, 0.02], [64682.6, 0.028], [64685.6, 0.001], [64686.8, 0.197], [64686.9, 0.544], [64687.1, 0.001], [64687.6, 0.063], [64690.2, 0.162], [64694.0, 0.0], [64694.2, 7.276]], "asks": [[64696.4, 0.31], [64697.5, 0.044], [64698.4, 0.008], [64698.5, 0.0], [64698.6, 0.0], [64700.8, 0.685], [64701.6, 0.464], [64713.2, 0.965], [64720.6, 0.743], [64725.2, 0.158], [64726.5, 0.251], [64734.3, 0.003], [64739.6, 0.003], [64772.1, 0.002], [64834.3, 3.651], [64835.3, 0.029], [64851.3, 5.068], [65282.4, 2.46], [65341.2, 2.523], [65519.8, 1.627]]}
{"kind": "depth", "E": 1787081871177, "U": 11315468560066, "u": 11315468566320, "recv_ms": 1787081871145, "bids": [[1000.0, 35.81], [14494.2, 2.198], [14594.2, 2.002], [58224.7, 0.002], [62106.4, 0.689], [63694.2, 0.0], [63913.9, 6.532], [64047.3, 0.463], [64111.8, 2.23], [64366.7, 0.31], [64370.7, 4.19], [64654.7, 0.149], [64655.3, 2.868], [64662.1, 2.019], [64685.8, 0.151], [64692.5, 0.041], [64692.6, 0.001], [64694.0, 0.002], [64694.1, 0.147]], "asks": [[64694.3, 9.567], [64697.5, 0.694], [64698.4, 0.008], [64698.5, 0.0], [64698.6, 0.0], [64700.8, 0.035], [64701.6, 0.464], [64702.3, 0.042], [64713.2, 0.347], [64720.6, 0.125], [64725.2, 0.004], [64725.3, 0.306], [64834.3, 5.398], [64851.2, 0.011], [64851.3, 10.408], [65207.8, 0.767], [65341.2, 2.523], [65426.6, 10.363], [65470.6, 18.959], [65480.3, 4.69], [65560.9, 0.011], [65600.0, 104.242], [65694.3, 0.0], [66061.8, 0.0]]}
{"kind": "depth", "E": 1787081871279, "U": 11315468566860, "u": 11315468572765, "recv_ms": 1787081871248, "bids": [[14494.2, 2.562], [14594.2, 1.638], [58224.7, 0.002], [63691.4, 6.592], [63955.4, 0.0], [64047.3, 0.463], [64112.0, 5.665], [64172.7, 0.0], [64370.7, 4.19], [64552.5, 4.885], [64574.1, 0.002], [64628.6, 0.004], [64661.3, 0.144], [64685.7, 0.006]], "asks": [[64696.4, 0.31], [64697.5, 0.153], [64698.4, 0.008], [64698.5, 0.0], [64698.6, 0.0], [64700.8, 0.576], [64716.3, 0.117], [64734.3, 0.003], [64772.2, 0.0], [64834.3, 3.818], [64835.3, 0.029], [64851.3, 4.979], [64890.1, 9.018], [65017.8, 4.321], [65155.6, 0.115], [65276.5, 4.283], [65341.2, 2.523], [65620.7, 9.306]]}
{"kind": "depth", "E": 1787081871381, "U": 11315468572870, "u": 11315468580462, "recv_ms": 1787081871351, "bids": [[1000.0, 35.81], [14494.2, 2.926], [14594.2, 1.274], [58224.7, 0.002], [61459.4, 0.0], [62106.4, 0.692], [63694.2, 0.02], [63901.9, 4.636], [64047.3, 0.463], [64370.7, 4.345], [64496.7, 9.159], [64535.5, 3.876], [64536.3, 0.444], [64552.5, 4.198], [64574.1, 0.002], [64597.2, 0.019], [64616.5, 0.289], [64628.6, 0.004], [64629.6, 0.311], [64661.3, 0.144], [64674.4, 0.166], [64674.5, 0.401], [64681.2, 2.336], [64681.3, 1.715], [64689.9, 0.087]], "asks": [[64694.3, 9.469], [64697.5, 0.044], [64698.6, 0.0], [64700.0, 0.004], [64700.7, 0.58], [64700.8, 0.569], [64701.6, 0.001], [64711.3, 0.561], [64712.2, 1.775], [64715.2, 1.215], [64716.3, 0.002], [64725.2, 0.004], [64725.3, 0.152], [64734.3, 0.003], [64772.2, 0.0], [64804.3, 1.392], [64823.7, 0.0], [64834.3, 3.321], [64835.3, 0.029], [64851.3, 4.444], [64890.1, 8.784], [65341.2, 2.523], [65399.5, 2.076], [65593.3, 0.0], [65593.6, 3.194], [65694.3, 0.02], [66304.2, 0.0]]}
{"kind": "depth", "E": 1787081871483, "U": 11315468580485, "u": 11315468591267, "recv_ms": 1787081871453, "bids": [[1000.0, 35.81], [14494.2, 3.276], [14594.2, 0.924], [58224.7, 0.002], [62106.4, 0.689], [63775.5, 2.227], [63885.5, 6.314], [63917.9, 20.575], [64047.3, 0.463], [64176.6, 8.558], [64574.1, 0.002], [64628.6, 0.004], [64655.3, 2.854], [64661.3, 0.144], [64671.2, 0.562], [64672.1, 0.308], [64672.4, 1.775], [64672.5, 0.12], [64673.4, 0.0], [64684.2, 0.428], [64684.3, 0.771], [64685.6, 0.001], [64686.1, 0.004], [64686.8, 0.112], [64686.9, 0.003], [64687.0, 0.043], [64687.1, 0.542], [64687.2, 0.172], [64687.6, 0.063], [64690.0, 0.003], [64690.2, 0.161], [64690.3, 0.019], [64690.4, 0.26], [64690.6, 0.084], [64690.7, 0.232], [64692.5, 0.001], [64694.1, 0.148], [64694.2, 7.903]], "asks": [[64694.8, 0.0], [64695.5, 0.0], [64695.8, 0.088], [64696.5, 0.005], [64696.9, 0.084], [64697.0, 0.005], [64697.5, 0.063], [64697.7, 0.027], [64702.3, 0.041], [64711.3, 0.005], [64712.3, 0.764], [64715.2, 1.1], [64716.3, 0.117], [64725.2, 0.158], [64734.3, 0.003], [64772.2, 0.0], [64834.3, 5.398], [64835.3, 0.029], [64851.3, 7.222], [64890.1, 12.921], [65211.9, 8.418], [65341.2, 2.523], [65412.5, 0.699], [65519.8, 1.399], [65616.9, 6.749], [65633.7, 1.52]]}
{"kind": "depth", "E": 1787081871585, "U": 11315468591330, "u": 11315468596961, "recv_ms": 1787081871553, "bids": [[14494.2, 3.64], [14594.2, 0.56], [51755.0, 0.0], [51755.4, 0.0], [58224.7, 0.002], [61459.5, 0.018], [61459.6, 2.441], [62106.4, 0.692], [63400.4, 0.081], [63694.2, 0.0], [64047.3, 0.463], [64370.7, 4.345], [64574.1, 0.002], [64628.6, 0.004], [64661.3, 0.144], [64668.8, 0.186], [64672.8, 0.002], [64675.5, 0.002], [64677.8, 0.371], [64681.2, 2.356], [64683.8, 0.26], [64685.6, 0.008], [64686.8, 0.923], [64686.9, 0.003], [64687.0, 0.577], [64687.1, 0.001], [64687.2, 0.087], [64691.2, 0.007]], "asks": [[64696.6, 0.002], [64697.5, 0.044], [64697.7, 0.004], [64701.0, 0.012], [64702.0, 1.938], [64707.5, 0.025], [64710.3, 0.214], [64711.8, 0.002], [64711.9, 1.34], [64725.2, 0.004], [64725.4, 0.312], [64734.3, 0.003], [64772.2, 0.0], [64834.3, 4.799], [64835.3, 0.029], [64851.3, 10.408], [64890.1, 9.298], [65151.6, 0.115], [65282.5, 1.071], [65341.2, 2.523], [65406.0, 1.72], [65694.3, 0.0], [66094.1, 0.0]]}
{"kind": "depth", "E": 1787081871687, "U": 11315468597074, "u": 11315468602007, "recv_ms": 1787081871656, "bids": [[1000.0, 35.96], [14394.2, 0.112], [14494.2, 3.766], [14594.2, 0.322], [58224.7, 0.002], [61459.4, 0.0], [63232.4, 0.791], [64047.3, 0.463], [64574.1, 0.002], [64628.6, 0.004], [64661.3, 0.144], [64674.4, 0.166], [64685.6, 0.658], [64686.8, 0.088], [64687.0, 0.036], [64687.1, 0.001], [64687.6, 0.789], [64687.7, 0.087], [64692.6, 0.046]], "asks": [[64694.3, 9.358], [64698.1, 0.085], [64698.3, 0.026], [64698.8, 0.006], [64716.3, 0.115], [64734.3, 0.003], [64772.2, 0.0], [64835.3, 0.029], [64851.3, 10.408], [64890.1, 9.168], [65341.2, 2.523], [65448.2, 1.595], [65473.9, 3.054], [65790.0, 0.22]]}
{"kind": "depth", "E": 1787081871789, "U": 11315468602101, "u": 11315468607009, "recv_ms": 1787081871758, "bids": [[1000.0, 35.81], [14394.2, 0.35], [14494.2, 3.64], [14594.2, 0.21], [58224.7, 0.002], [61459.5, 0.016], [61459.6, 2.443], [62106.4, 0.689], [63645.6, 0.001], [63687.5, 4.106], [63694.2, 0.02], [63946.3, 3.759], [64015.5, 8.568], [64047.3, 0.463], [64628.0, 0.002], [64657.9, 0.434], [64672.9, 0.0], [64681.2, 2.396], [64685.6, 0.658], [64686.4, 0.004], [64686.8, 0.198], [64687.6, 0.789], [64687.7, 0.087], [64687.8, 0.0], [64687.9, 0.232], [64690.9, 0.103], [64691.4, 0.084], [64692.4, 0.311]], "asks": [[64695.4, 0.092], [64695.8, 0.004], [64699.0, 0.096], [64699.4, 0.09], [64713.7, 0.126], [64961.6, 4.394], [65613.0, 2.147], [65694.3, 0.02], [65868.4, 1.517]]}
{"kind": "depth", "E": 1787081871891, "U": 11315468607091, "u": 11315468612244, "recv_ms": 1787081871861, "bids": [[14394.2, 0.588], [14494.2, 3.528], [14594.2, 0.084], [58224.7, 0.002], [61459.4, 0.0], [62106.4, 0.692], [63694.2, 0.0], [63752.2, 8.796], [63818.1, 0.027], [63908.2, 2.348], [63989.0, 3.05], [64047.3, 0.465], [64370.7, 4.354], [64536.3, 0.995], [64574.1, 0.002], [64583.4, 0.0], [64584.2, 0.381], [64628.6, 0.004], [64657.9, 0.448], [64661.3, 0.144], [64664.5, 0.306], [64668.8, 0.187], [64668.9, 0.342], [64671.6, 0.005], [64672.0, 0.783], [64672.5, 0.118], [64673.2, 5.493], [64673.6, 2.983], [64674.4, 0.012], [64678.9, 0.001], [64680.1, 0.318], [64685.6, 0.542], [64685.7, 0.122], [64686.8, 0.004], [64687.2, 0.003], [64687.6, 0.063], [64687.7, 0.087], [64688.3, 0.004], [64689.8, 0.106], [64690.3, 0.041], [64690.4, 0.261], [64690.5, 0.018], [64690.7, 0.02], [64690.9, 0.085], [64691.1, 0.234], [64691.2, 0.006], [64692.0, 0.086], [64692.1, 0.019], [64694.2, 7.902]], "asks": [[64694.3, 6.808], [64694.5, 0.429], [64694.9, 0.007], [64696.3, 0.002], [64696.4, 0.0], [64696.6, 0.002], [64698.0, 0.015], [64698.3, 0.006], [64698.4, 0.008], [64698.6, 0.626], [64698.8, 0.004], [64698.9, 0.03], [64699.0, 0.119], [64699.5, 0.001], [64699.8, 0.085], [64700.5, 0.005], [64700.7, 0.496], [64700.8, 0.028], [64702.1, 0.008], [64703.0, 1.802], [64707.2, 1.704], [64708.2, 0.31], [64711.9, 1.338], [64712.9, 0.162], [64714.1, 1.199], [64716.4, 0.002], [64716.6, 0.006], [64720.2, 0.679], [64724.9, 10.002], [64734.3, 0.003], [64735.9, 0.125], [64736.0, 3.527], [64743.5, 0.047], [64746.1, 2.856], [64748.7, 0.016], [64759.4, 6.671], [64772.2, 0.0], [64835.3, 0.029], [64851.2, 2.365], [64851.3, 10.408], [64885.8, 0.113], [64890.1, 8.844], [65017.8, 4.322], [65276.6, 9.649], [65341.2, 2.525], [65470.6, 20.485], [65664.7, 14.824], [65694.3, 0.0], [65988.1, 0.015]]}
{"kind": "depth", "E": 1787081871993, "U": 11315468612280, "u": 11315468628731, "recv_ms": 1787081871962, "bids": [[1000.0, 35.81], [14394.2, 0.854], [14494.2, 3.346], [14594.2, 0.0], [58224.7, 0.002], [62106.4, 0.689], [63626.7, 3.297], [64047.3, 0.463], [64157.9, 0.0], [64590.1, 0.007], [64590.2, 0.013], [64600.9, 0.343], [64611.5, 0.027], [64644.6, 0.312], [64648.8, 0.429], [64656.9, 0.0], [64658.9, 0.002], [64663.9, 0.001], [64668.8, 0.186], [64674.0, 0.684], [64679.3, 0.013], [64681.2, 2.394], [64681.3, 1.717], [64684.3, 1.142], [64685.3, 0.078], [64685.4, 0.005], [64685.5, 0.652], [64685.6, 0.001], [64685.7, 0.014], [64686.7, 1.778], [64686.8, 2.447], [64686.9, 0.012], [64687.5, 1.13], [64687.6, 0.691], [64687.7, 0.652], [64688.4, 0.056], [64688.8, 0.001], [64689.2, 0.086], [64689.8, 0.416], [64690.1, 0.001], [64690.3, 0.0], [64690.7, 0.0], [64691.1, 0.002], [64691.2, 0.007], [64691.4, 0.084], [64691.5, 0.001], [64691.9, 0.001], [64692.4, 0.395], [64692.5, 0.024], [64692.6, 0.001], [64692.7, 0.139], [64692.9, 0.251], [64693.3, 0.0], [64693.7, 0.0], [64694.2, 7.912]], "asks": [[64696.2, 0.001], [64696.6, 0.312], [64696.9, 0.0], [64697.2, 0.002], [64697.3, 0.085], [64697.5, 0.033], [64697.7, 0.088], [64697.8, 0.022], [64698.5, 0.541], [64698.6, 0.209], [64698.7, 2.857], [64698.8, 0.008], [64698.9, 0.01], [64699.0, 0.096], [64699.1, 0.002], [64699.4, 0.09], [64700.1, 0.395], [64700.2, 0.004], [64700.3, 0.0], [64700.5, 0.087], [64700.7, 0.001], [64700.8, 0.02], [64700.9, 1.531], [64701.7, 0.468], [64703.4, 1.373], [64704.0, 0.649], [64704.3, 0.232], [64704.4, 0.119], [64705.6, 0.089], [64706.6, 0.0], [64707.5, 0.005], [64708.5, 0.374], [64709.6, 0.783], [64711.4, 0.074], [64711.9, 1.298], [64713.0, 0.059], [64713.2, 0.382], [64714.3, 0.002], [64714.6, 0.764], [64720.9, 0.052], [64721.5, 0.359], [64723.4, 3.095], [64725.6, 0.002], [64729.8, 0.513], [64734.8, 0.072], [64742.9, 2.655], [64748.7, 0.002], [64750.6, 0.0], [64752.3, 0.212], [64753.4, 0.336], [64759.4, 1.721], [64759.8, 0.025], [64761.3, 0.0], [64763.5, 35.27], [64764.2, 0.018], [64765.7, 0.001], [64851.3, 7.267], [64890.1, 12.491], [65341.2, 2.523], [65460.1, 0.765], [65503.0, 6.371], [65628.3, 17.202], [65674.4, 3.04], [65794.1, 5.601]]}
{"kind": "depth", "E": 1787081872095, "U": 11315468629841, "u": 11315468641445, "recv_ms": 1787081872063, "bids": [[14394.2, 1.218], [14494.2, 2.982], [58224.7, 0.002], [61459.4, 0.0], [61459.5, 0.018], [62106.4, 0.692], [63458.9, 0.0], [63691.4, 7.69], [63701.0, 1.411], [63756.1, 20.173], [63950.2, 5.621], [64047.3, 0.463], [64131.4, 1.168], [64371.7, 0.108], [64372.1, 0.0], [64574.4, 1.398], [64628.8, 3.563], [64650.2, 0.443], [64657.9, 0.434], [64658.9, 0.004], [64661.3, 0.142], [64661.4, 1.856], [64661.5, 0.11], [64664.8, 0.07], [64664.9, 0.114], [64665.0, 0.054], [64667.0, 0.004], [64668.9, 0.006], [64672.8, 0.338], [64674.3, 0.629], [64674.4, 0.166], [64679.1, 0.237], [64681.2, 2.391], [64681.3, 1.72], [64682.6, 0.028], [64684.4, 0.491], [64685.5, 0.189], [64685.7, 0.006], [64686.9, 0.02], [64687.5, 0.779], [64687.6, 0.629], [64687.7, 1.398], [64687.9, 0.294], [64690.5, 0.002], [64692.4, 0.395], [64692.9, 0.251], [64694.1, 0.162], [64694.2, 7.913]], "asks": [[64694.3, 4.42], [64694.4, 0.119], [64696.6, 0.002], [64697.1, 0.007], [64697.3, 0.101], [64697.4, 0.018], [64697.5, 0.033], [64697.8, 0.002], [64698.4, 0.008], [64698.5, 0.557], [64698.6, 0.202], [64698.7, 2.877], [64698.8, 0.004], [64699.1, 0.004], [64699.7, 0.005], [64699.8, 0.085], [64700.8, 0.028], [64701.0, 0.014], [64708.8, 0.614], [64713.7, 0.002], [64721.9, 0.043], [64722.8, 0.015], [64723.4, 0.018], [64724.9, 0.002], [64728.0, 1.189], [64728.1, 10.103], [64728.6, 0.002], [64734.5, 0.002], [64735.4, 0.31], [64761.6, 0.025], [64764.2, 0.0], [64772.4, 0.125], [64835.6, 0.0], [64851.3, 10.408], [64883.2, 0.146], [64890.1, 8.627], [65341.2, 2.523], [65414.4, 0.01], [65687.6, 0.037], [65794.1, 6.359]]}
{"kind": "depth", "E": 1787081872197, "U": 11315468641638, "u": 11315468648677, "recv_ms": 1787081872166, "bids": [[14394.2, 1.568], [14494.2, 2.632], [58224.7, 0.002], [63694.2, 0.02], [63701.0, 1.42], [63807.9, 1.25], [63901.9, 4.285], [64047.3, 0.463], [64364.3, 0.0], [64370.7, 4.354], [64674.4, 0.012], [64680.0, 0.243], [64680.6, 0.001], [64684.1, 1.398], [64684.5, 0.066], [64686.9, 0.012], [64692.4, 0.627], [64692.9, 0.019]], "asks": [[64694.3, 4.422], [64698.6, 0.078], [64699.6, 0.003], [64700.2, 0.023], [64700.3, 0.022], [64702.0, 1.038], [64725.4, 0.326], [64761.3, 35.27], [64763.5, 0.0], [65341.2, 2.523], [65464.2, 9.527], [65632.4, 15.555], [65694.3, 0.02]]}
{"kind": "depth", "E": 1787081872299, "U": 11315468648986, "u": 11315468654806, "recv_ms": 1787081872267, "bids": [[1000.0, 35.81], [14394.2, 1.932], [14494.2, 2.268], [51755.0, 0.0], [58224.7, 0.002], [61459.4, 0.0], [61459.5, 0.016], [61459.6, 2.445], [62106.4, 0.689], [63885.5, 6.548], [64047.3, 0.463], [64370.7, 4.355], [64584.2, 0.378], [64616.5, 0.286], [64635.9, 0.026], [64674.4, 0.012], [64684.5, 0.058], [64686.9, 0.012], [64687.7, 0.131], [64687.8, 0.541], [64688.0, 0.03], [64693.9, 0.147], [64694.1, 0.148]], "asks": [[64694.3, 4.251], [64694.9, 0.0], [64695.6, 0.007], [64696.6, 0.002], [64702.0, 0.138], [64709.6, 0.463], [64711.5, 0.32], [64728.1, 10.105], [64729.6, 2.537], [64739.6, 0.003], [64785.6, 1.115], [64804.3, 1.389], [64851.3, 10.408], [64890.1, 8.865], [65017.8, 4.321], [65341.2, 2.523], [65487.4, 1.373], [65541.3, 1.073], [65687.6, 0.046]]}
{"kind": "depth", "E": 1787081872401, "U": 11315468654975, "u": 11315468663701, "recv_ms": 1787081872369, "bids": [[14394.2, 2.282], [14494.2, 1.918], [51755.0, 0.0], [58224.7, 0.002], [62106.4, 0.692], [63400.4, 0.084], [63694.2, 0.0], [63908.2, 3.129], [64047.3, 0.465], [64152.0, 1.429], [64306.0, 0.062], [64650.1, 0.0], [64662.0, 1.065], [64664.6, 1.61], [64664.7, 0.01], [64667.6, 0.332], [64667.8, 0.716], [64671.7, 0.462], [64672.1, 0.31], [64674.4, 0.166], [64675.6, 0.19], [64676.1, 0.061], [64679.5, 0.026], [64682.1, 0.027], [64684.0, 2.835], [64684.4, 0.028], [64685.3, 0.001], [64686.6, 0.004], [64686.9, 0.019], [64687.0, 0.499], [64687.7, 0.564], [64687.8, 0.142], [64688.0, 0.038], [64692.1, 0.001], [64693.0, 0.018], [64694.1, 0.148], [64694.2, 7.902]], "asks": [[64694.3, 4.236], [64697.5, 0.018], [64698.6, 0.202], [64700.8, 0.491], [64701.7, 0.005], [64704.0, 1.549], [64706.7, 0.001], [64714.5, 0.929], [64823.7, 0.0], [64851.3, 10.408], [64890.1, 12.276], [65341.2, 2.523], [65410.4, 0.229], [65426.6, 9.677], [65694.3, 0.0]]}
{"kind": "depth", "E": 1787081872503, "U": 11315468663759, "u": 11315468669937, "recv_ms": 1787081872472, "bids": [[14394.2, 2.646], [14494.2, 1.554], [58224.7, 0.002], [61459.4, 0.0], [62106.4, 0.689], [64047.3, 0.463], [64370.7, 4.345], [64630.7, 0.015], [64668.9, 0.342], [64672.8, 0.002], [64684.4, 0.028], [64686.9, 1.208], [64687.0, 0.036], [64687.1, 0.001], [64687.7, 0.023], [64688.0, 0.579], [64688.3, 0.012], [64692.5, 0.001], [64692.7, 0.119], [64692.9, 0.0], [64694.2, 7.903]], "asks": [[64694.3, 4.367], [64696.5, 0.315], [64696.6, 0.002], [64697.0, 0.003], [64700.0, 0.101], [64700.4, 0.296], [64707.4, 1.217], [64715.3, 0.12], [64716.3, 0.0], [64761.3, 0.0], [64767.9, 35.292], [65011.4, 0.134], [65013.8, 0.387], [65282.5, 0.0], [65341.2, 2.523], [65399.5, 2.762]]}
{"kind": "depth", "E": 1787081872605, "U": 11315468670118, "u": 11315468682635, "recv_ms": 1787081872573, "bids": [[1000.0, 35.81], [14394.2, 3.01], [14494.2, 1.19], [51755.4, 0.0], [58224.7, 0.002], [61459.4, 0.0], [62106.4, 0.692], [63400.4, 0.081], [63694.2, 0.02], [63834.3, 0.001], [63908.2, 3.91], [64047.3, 0.463], [64485.2, 0.368], [64487.1, 0.006], [64495.5, 0.0], [64497.3, 0.005], [64505.8, 0.001], [64516.1, 0.003], [64526.4, 5.214], [64536.7, 0.0], [64547.0, 0.003], [64557.3, 0.012], [64567.6, 0.0], [64577.9, 0.0], [64588.2, 0.006], [64598.5, 0.003], [64603.2, 3.266], [64603.3, 0.02], [64608.8, 0.095], [64619.1, 1.547], [64629.4, 0.212], [64639.7, 0.03], [64650.0, 3.93], [64657.9, 0.448], [64660.3, 0.216], [64661.3, 0.144], [64661.4, 1.858], [64661.5, 0.112], [64664.8, 0.072], [64664.9, 0.116], [64665.0, 0.056], [64670.6, 0.368], [64674.4, 0.166], [64677.8, 0.371], [64678.0, 1.329], [64679.1, 0.257], [64684.4, 0.492], [64684.5, 0.723], [64686.6, 0.003], [64686.7, 0.003], [64686.8, 2.323], [64686.9, 0.004], [64687.0, 0.036], [64687.5, 0.483], [64687.6, 0.629], [64687.7, 0.003], [64687.8, 0.057], [64688.0, 0.022], [64688.3, 0.004], [64688.4, 0.056], [64688.5, 0.085], [64688.8, 0.085], [64689.8, 0.103], [64690.4, 0.261], [64692.0, 0.002], [64692.2, 0.023], [64692.4, 0.543], [64692.5, 0.021], [64692.6, 0.019], [64692.7, 0.133], [64693.0, 0.0], [64693.9, 0.133], [64694.2, 7.892]], "asks": [[64694.3, 5.417], [64695.9, 0.085], [64696.6, 0.086], [64697.3, 0.085], [64697.4, 0.011], [64698.4, 0.031], [64700.0, 0.004], [64700.5, 0.003], [64700.8, 0.028], [64700.9, 1.447], [64701.1, 0.003], [64701.7, 0.468], [64707.2, 1.775], [64709.6, 0.468], [64709.7, 0.002], [64710.3, 0.214], [64711.1, 0.559], [64712.3, 0.208], [64713.7, 0.126], [64719.8, 0.99], [64720.0, 0.02], [64722.8, 0.001], [64724.1, 10.002], [64725.4, 0.312], [64726.5, 0.321], [64728.1, 0.105], [64730.3, 0.0], [64734.8, 0.002], [64740.6, 0.001], [64750.9, 0.0], [64761.2, 0.0], [64763.5, 35.27], [64766.8, 0.027], [64767.9, 0.022], [64771.5, 0.0], [64781.8, 0.022], [64792.1, 0.001], [64802.4, 0.021], [64812.7, 0.002], [64823.0, 0.005], [64833.3, 0.073], [64834.3, 5.398], [64843.6, 0.0], [64851.3, 10.408], [64853.9, 0.37], [64864.2, 0.001], [64874.5, 0.0], [64884.8, 3.526], [64895.1, 0.002], [65341.2, 2.523], [65426.6, 8.915], [65519.8, 1.14], [65535.4, 4.291], [65600.0, 104.425], [65694.3, 0.02], [65988.1, 0.018], [67282.1, 1.272]]}
{"kind": "depth", "E": 1787081872707, "U": 11315468682693, "u": 11315468692718, "recv_ms": 1787081872675, "bids": [[14394.2, 3.36], [14494.2, 0.84], [58224.7, 0.002], [63908.2, 4.691], [63963.8, 3.752], [63987.7, 0.002], [64047.3, 0.463], [64112.0, 5.821], [64507.5, 0.02], [64668.9, 0.006], [64670.7, 0.761], [64671.2, 0.005], [64672.0, 0.899], [64672.5, 0.002], [64674.2, 0.286], [64674.4, 0.012], [64684.4, 0.49], [64684.5, 0.058], [64684.9, 0.032], [64685.2, 1.934], [64685.3, 0.55], [64686.7, 0.003], [64686.9, 0.004], [64687.4, 0.084], [64687.5, 0.706], [64687.7, 0.203], [64687.8, 0.057], [64688.1, 0.154], [64690.6, 0.0], [64690.9, 0.001], [64691.4, 0.0]], "asks": [[64694.3, 7.17], [64695.0, 0.088], [64695.5, 0.084], [64697.2, 0.004], [64697.5, 0.328], [64698.4, 0.008], [64698.5, 0.0], [64698.6, 0.125], [64698.8, 0.006], [64699.8, 0.001], [64699.9, 0.021], [64700.0, 0.026], [64700.1, 0.311], [64700.8, 0.685], [64701.0, 0.012], [64723.7, 3.827], [64724.1, 10.004], [64730.0, 0.009], [64851.3, 7.081], [64890.1, 12.46], [65017.8, 4.475], [65341.2, 2.523]]}
{"kind": "depth", "E": 1787081872809, "U": 11315468692942, "u": 11315468699069, "recv_ms": 1787081872781, "bids": [[14294.2, 0.014], [14394.2, 3.682], [14494.2, 0.504], [58224.7, 0.002], [61459.4, 0.0], [62106.4, 0.689], [63694.2, 0.0], [63787.9, 0.0], [63972.9, 2.349], [64047.3, 0.463], [64370.7, 4.355], [64517.7, 0.01], [64527.9, 2.527], [64552.5, 0.0], [64552.6, 4.869], [64585.3, 0.032], [64585.9, 2.743], [64665.7, 0.497], [64685.4, 0.122], [64686.7, 0.002], [64687.7, 0.087], [64692.4, 0.233]], "asks": [[64694.3, 7.201], [64694.5, 0.513], [64696.5, 0.315], [64699.4, 0.006], [64702.0, 0.138], [64740.2, 0.416], [64743.5, 0.005], [64746.1, 2.842], [64750.4, 1.254], [64799.4, 0.0], [64799.7, 2.324], [64834.3, 5.398], [64851.3, 10.408], [64890.1, 9.168], [65276.6, 10.72], [65336.0, 17.161], [65341.2, 2.523], [65628.3, 16.137], [65694.3, 0.0], [66020.5, 1.361], [71163.8, 0.0]]}
{"kind": "depth", "E": 1787081872911, "U": 11315468699269, "u": 11315468704472, "recv_ms": 1787081872882, "bids": [[1000.0, 35.81], [14294.2, 0.168], [14394.2, 3.738], [14494.2, 0.294], [58224.7, 0.002], [61459.4, 0.0], [62106.4, 0.692], [63807.9, 1.875], [63934.3, 4.325], [63937.3, 2.758], [64047.3, 0.463], [64538.1, 0.005], [64552.6, 0.012], [64629.5, 0.039], [64692.7, 0.062], [64694.2, 7.911]], "asks": [[64694.3, 7.212], [64696.4, 0.002], [64699.1, 0.002], [64760.6, 0.035], [64762.8, 6.673], [64834.3, 0.0], [65017.8, 4.474], [65336.0, 16.474], [65341.2, 2.523], [65399.5, 3.524], [65503.0, 6.713], [65512.6, 1.525], [65594.8, 2.13]]}
{"kind": "depth", "E": 1787081873013, "U": 11315468704642, "u": 11315468709909, "recv_ms": 1787081872982, "bids": [[14294.2, 0.406], [14394.2, 3.612], [14494.2, 0.182], [58224.7, 0.002], [61459.4, 0.0], [62106.4, 0.689], [63694.2, 0.02], [63908.2, 5.472], [64047.3, 0.463], [64370.7, 4.356], [64535.5, 0.001], [64535.7, 4.111], [64536.3, 1.03], [64548.3, 0.005], [64552.6, 4.413], [64558.5, 2.33], [64626.9, 0.006], [64627.2, 0.013], [64627.5, 0.0], [64627.9, 0.0], [64628.2, 0.791], [64632.0, 2.367], [64646.1, 0.001], [64646.4, 0.009], [64646.7, 0.183], [64646.8, 0.003], [64647.1, 0.101], [64647.4, 0.007], [64661.1, 0.143], [64661.2, 0.001], [64661.3, 0.004], [64661.4, 1.688], [64661.5, 0.012], [64661.6, 0.002], [64661.7, 0.001], [64661.8, 0.009], [64662.0, 0.995], [64664.5, 0.206], [64664.9, 0.016], [64683.3, 0.016], [64683.4, 0.453], [64683.5, 0.002], [64683.6, 0.003], [64683.7, 0.004], [64683.8, 0.06], [64683.9, 3.317], [64684.0, 2.635], [64684.1, 1.328], [64684.2, 0.398], [64684.3, 1.072], [64684.6, 0.005], [64684.9, 0.0], [64685.2, 1.934], [64685.5, 0.157], [64685.9, 0.0]], "asks": [[64694.3, 7.213], [64696.4, 0.002], [64702.0, 1.006], [64702.3, 0.003], [64702.7, 0.046], [64703.0, 1.757], [64703.3, 0.001], [64703.6, 0.004], [64703.7, 0.098], [64703.8, 0.001], [64703.9, 0.011], [64704.0, 1.301], [64704.1, 0.01], [64704.2, 1.055], [64704.3, 0.008], [64704.4, 0.014], [64704.5, 2.321], [64721.2, 0.238], [64721.5, 0.321], [64721.9, 0.046], [64722.2, 0.006], [64722.5, 0.002], [64722.9, 0.665], [64723.3, 1.244], [64723.5, 2.446], [64725.8, 0.003], [64725.9, 0.16], [64726.0, 0.005], [64726.1, 0.0], [64726.2, 2.321], [64726.3, 0.002], [64726.4, 0.006], [64726.5, 0.09], [64726.6, 2.211], [64726.7, 6.032], [64726.8, 1.716], [64730.7, 0.0], [64740.4, 0.223], [64740.8, 1.207], [64741.1, 0.17], [64741.4, 0.059], [64741.7, 0.026], [64770.8, 0.045], [64781.0, 0.005], [64834.3, 5.398], [64851.2, 1.28], [64851.3, 10.408], [64890.1, 10.815], [65341.2, 2.523], [65570.9, 0.0], [65694.3, 0.02]]}
{"kind": "depth", "E": 1787081873115, "U": 11315468710080, "u": 11315468717656, "recv_ms": 1787081873095, "bids": [[1000.0, 35.81], [14294.2, 0.644], [14394.2, 3.5], [14494.2, 0.056], [51755.0, 0.002], [58224.7, 0.002], [61459.4, 0.0], [63400.4, 0.084], [63694.2, 0.0], [63701.0, 1.412], [63765.6, 0.022], [63768.0, 0.038], [63885.5, 6.782], [64047.3, 0.463], [64370.7, 4.346], [64496.7, 0.0], [64496.8, 9.545], [64568.7, 0.342], [64578.9, 0.007], [64618.2, 0.023], [64619.9, 0.002], [64622.1, 0.063], [64632.2, 1.157], [64639.8, 0.295], [64642.3, 0.212], [64647.0, 0.033], [64648.8, 0.219], [64650.2, 0.493], [64651.9, 2.78], [64652.6, 0.005], [64654.9, 0.015], [64655.3, 2.868], [64657.8, 0.042], [64658.5, 0.25], [64660.0, 0.523], [64660.3, 0.552], [64661.6, 0.002], [64661.8, 0.003], [64662.0, 0.999], [64663.6, 0.002], [64664.0, 1.539], [64664.9, 0.002], [64665.3, 0.028], [64665.6, 0.048], [64665.7, 0.161], [64665.8, 0.016], [64667.2, 1.195], [64667.7, 0.891], [64667.9, 2.343], [64668.0, 0.431], [64668.2, 1.234], [64668.6, 0.081], [64669.4, 0.105], [64669.8, 0.006], [64670.0, 1.481], [64670.3, 0.0], [64671.0, 2.341], [64671.1, 1.593], [64671.8, 0.163], [64672.1, 0.29], [64673.2, 0.493], [64673.7, 0.213], [64674.0, 0.614], [64674.5, 0.431], [64675.1, 0.001], [64675.6, 0.169], [64675.7, 1.247], [64676.0, 0.802], [64676.4, 0.033], [64677.4, 0.043], [64679.4, 0.008], [64680.0, 0.123], [64680.1, 0.311], [64680.5, 0.004], [64681.2, 2.356], [64681.3, 1.174], [64681.4, 0.002], [64682.2, 0.163], [64682.6, 0.028], [64682.7, 0.465], [64683.6, 0.073], [64683.8, 0.13], [64684.0, 2.867], [64684.1, 1.173], [64684.2, 0.399], [64684.3, 0.371], [64684.8, 0.009], [64685.4, 0.121], [64685.5, 0.189], [64686.4, 0.061], [64686.7, 1.903], [64686.8, 0.004], [64686.9, 0.004], [64687.5, 0.483], [64687.7, 0.087], [64687.8, 0.0], [64687.9, 0.313], [64688.0, 0.022], [64688.1, 0.154], [64688.2, 0.313], [64688.3, 0.236], [64689.3, 0.006], [64689.6, 0.016], [64689.7, 0.0], [64689.8, 0.104], [64690.4, 0.003], [64690.5, 0.02], [64692.0, 0.002], [64692.1, 0.001], [64692.2, 0.014], [64692.4, 0.001], [64692.5, 0.001], [64692.6, 0.001], [64692.7, 0.001], [64693.5, 0.003], [64693.9, 0.002], [64694.0, 0.068], [64694.1, 0.149], [64694.2, 6.852]], "asks": [[64694.3, 8.411], [64695.6, 0.0], [64696.2, 0.023], [64696.4, 0.021], [64696.6, 0.111], [64697.2, 0.002], [64697.4, 0.013], [64698.1, 0.085], [64698.4, 0.008], [64699.0, 0.096], [64699.2, 0.002], [64699.9, 0.002], [64700.0, 0.004], [64700.2, 0.004], [64700.3, 0.0], [64700.7, 0.464], [64700.8, 0.144], [64701.2, 0.0], [64701.7, 0.546], [64701.8, 2.961], [64702.3, 0.048], [64702.5, 0.002], [64704.0, 1.406], [64704.2, 1.146], [64706.9, 0.131], [64707.5, 0.002], [64709.5, 0.945], [64711.2, 0.071], [64711.6, 0.025], [64713.4, 0.387], [64713.6, 1.63], [64716.8, 1.299], [64718.2, 2.536], [64718.5, 0.31], [64718.9, 0.376], [64719.8, 10.99], [64720.7, 0.01], [64720.8, 2.32], [64721.0, 0.64], [64721.6, 1.138], [64722.6, 0.001], [64724.1, 0.004], [64724.8, 1.094], [64726.3, 0.107], [64726.5, 0.181], [64732.4, 0.01], [64734.0, 0.007], [64734.4, 1.544], [64736.1, 0.22], [64736.8, 0.02], [64738.5, 1.998], [64739.7, 0.096], [64740.5, 0.0], [64740.7, 0.001], [64740.8, 1.249], [64751.4, 0.008], [64754.5, 0.016], [64754.9, 4.25], [64759.0, 0.294], [64791.2, 0.009], [64811.6, 0.121], [64851.3, 7.193], [64890.1, 13.282], [65308.9, 4.97], [65341.2, 2.523], [65545.0, 3.721], [65567.7, 5.853], [65620.6, 1.522], [65622.9, 0.0], [65632.4, 16.62], [65633.7, 0.608], [65687.6, 0.038], [65694.3, 0.0], [66255.4, 0.646]]}
{"kind": "depth", "E": 1787081873217, "U": 11315468717756, "u": 11315468725299, "recv_ms": 1787081873186, "bids": [[1000.0, 35.81], [14294.2, 0.952], [14394.2, 3.248], [14494.2, 0.0], [51755.0, 0.0], [58224.7, 0.002], [58224.9, 0.0], [61459.4, 0.0], [61459.5, 0.014], [61459.6, 2.447], [62106.4, 0.692], [63700.9, 0.01], [63765.6, 0.03], [63767.9, 0.01], [63963.8, 3.205], [64047.3, 0.463], [64496.8, 0.0], [64496.9, 11.431], [64535.7, 5.819], [64589.1, 0.005], [64599.3, 0.006], [64635.3, 0.617], [64642.3, 0.002], [64646.4, 0.041], [64647.4, 0.039], [64658.8, 0.185], [64660.3, 0.495], [64662.0, 0.995], [64668.0, 0.431], [64668.8, 0.187], [64669.6, 0.928], [64670.7, 0.204], [64670.8, 0.013], [64671.1, 1.709], [64671.8, 0.001], [64672.0, 0.781], [64674.0, 0.618], [64674.5, 0.401], [64675.0, 1.09], [64675.6, 0.324], [64675.7, 0.321], [64679.1, 0.287], [64681.4, 0.126], [64683.7, 0.074], [64684.0, 2.426], [64684.1, 1.814], [64684.2, 0.398], [64684.3, 0.471], [64684.4, 0.66], [64684.5, 0.158], [64684.6, 0.006], [64684.8, 0.041], [64685.1, 0.0], [64685.4, 0.121], [64685.8, 0.183], [64686.8, 0.004], [64687.0, 0.12], [64687.5, 0.754], [64687.7, 0.087], [64687.8, 0.022], [64688.0, 0.023], [64688.1, 0.155], [64688.3, 0.004], [64689.8, 0.103], [64689.9, 0.003], [64690.0, 0.231], [64690.3, 0.232], [64690.5, 0.019], [64691.2, 0.006], [64693.9, 0.093], [64694.0, 0.002], [64694.1, 0.147], [64694.2, 7.253]], "asks": [[64694.3, 8.265], [64694.5, 0.796], [64695.9, 0.104], [64696.5, 0.315], [64697.0, 0.903], [64697.4, 0.013], [64697.5, 0.339], [64699.5, 0.111], [64702.0, 1.944], [64702.5, 0.001], [64703.0, 1.802], [64703.3, 0.191], [64703.4, 1.471], [64703.5, 0.888], [64703.7, 0.248], [64703.8, 0.141], [64704.0, 0.506], [64704.1, 0.115], [64707.4, 1.217], [64708.4, 0.927], [64709.5, 0.02], [64712.5, 0.156], [64713.4, 0.928], [64714.6, 0.223], [64715.3, 10.12], [64719.8, 0.99], [64720.2, 0.608], [64721.2, 0.276], [64722.2, 0.051], [64722.4, 0.192], [64725.4, 0.41], [64725.5, 0.161], [64725.6, 0.192], [64725.8, 0.153], [64725.9, 0.3], [64726.4, 0.111], [64740.5, 0.038], [64741.4, 0.104], [64759.0, 0.223], [64784.9, 2.771], [64801.4, 0.005], [64821.8, 0.006], [64834.3, 3.749], [64841.8, 0.429], [64851.3, 10.408], [64883.2, 0.036], [64885.8, 0.003], [64890.1, 10.048], [65308.9, 5.657], [65341.2, 2.525], [65535.3, 10.599], [65600.0, 104.608], [65606.5, 2.587], [71163.8, 0.001]]}
{"kind": "depth", "E": 1787081873319, "U": 11315468725333, "u": 11315468730765, "recv_ms": 1787081873288, "bids": [[14294.2, 1.302], [14394.2, 2.898], [58224.7, 0.002], [61459.4, 0.0], [62106.4, 0.689], [63820.8, 6.365], [64047.3, 0.465], [64370.7, 4.345], [64597.1, 0.003], [64609.5, 0.031], [64616.5, 0.289], [64619.7, 0.249], [64627.6, 0.032], [64648.0, 1.719], [64675.0, 0.164], [64675.6, 0.169], [64676.8, 0.93], [64679.1, 0.257], [64680.0, 0.239], [64680.5, 0.005], [64681.3, 1.329], [64683.7, 0.144], [64683.9, 3.387], [64684.0, 2.456], [64684.1, 1.914], [64684.2, 0.498], [64684.6, 0.076], [64684.7, 0.312], [64686.2, 0.032], [64686.8, 0.73]], "asks": [[64694.3, 8.496], [64697.8, 0.004], [64698.8, 0.004], [64700.0, 0.101], [64701.2, 0.001], [64701.6, 0.033], [64703.2, 0.116], [64703.7, 0.398], [64703.8, 0.311], [64704.0, 0.625], [64704.1, 0.213], [64707.2, 1.885], [64708.4, 0.002], [64709.3, 1.429], [64713.4, 0.387], [64714.0, 0.547], [64720.7, 0.042], [64722.9, 0.835], [64725.2, 0.116], [64725.7, 0.154], [64726.0, 0.124], [64726.2, 2.419], [64732.3, 5.803], [64733.8, 0.005], [64739.8, 0.106], [64804.3, 1.392], [64832.0, 2.347], [64842.2, 0.006], [64865.1, 3.493], [64868.5, 0.125], [65013.8, 0.233], [65341.2, 2.523], [65503.0, 6.941], [65620.5, 0.01], [65622.8, 0.008], [65687.5, 0.02], [66142.4, 0.0], [71163.8, 0.0]]}
{"kind": "depth", "E": 1787081873421, "U": 11315468730869, "u": 11315468736060, "recv_ms": 1787081873390, "bids": [[1000.0, 35.81], [14294.2, 1.652], [14394.2, 2.548], [58224.7, 0.002], [62106.4, 0.692], [63206.2, 1.107], [63694.2, 0.02], [63988.3, 8.592], [64047.3, 0.463], [64370.7, 4.355], [64627.9, 0.032], [64629.9, 0.005], [64662.1, 2.089], [64666.4, 0.311], [64667.6, 0.023], [64669.6, 0.371], [64671.1, 1.593], [64671.2, 0.562], [64672.7, 0.119], [64673.7, 0.221], [64684.0, 2.526], [64684.4, 0.197], [64685.3, 0.472], [64685.4, 0.098], [64686.8, 0.004], [64686.9, 0.004], [64687.7, 0.11], [64687.8, 0.022], [64688.0, 0.023], [64688.3, 0.545], [64691.0, 0.024]], "asks": [[64694.4, 0.121], [64694.7, 0.055], [64696.5, 0.315], [64697.4, 0.011], [64697.8, 0.002], [64698.8, 0.006], [64700.0, 0.101], [64700.3, 0.291], [64700.5, 0.466], [64700.7, 0.001], [64700.8, 0.027], [64701.6, 0.15], [64702.9, 0.035], [64703.9, 0.102], [64705.3, 0.04], [64711.1, 0.003], [64711.4, 0.054], [64711.6, 0.581], [64713.0, 0.019], [64725.9, 0.391], [64823.7, 0.0], [64852.4, 0.007], [65017.8, 4.475], [65341.2, 2.523], [65694.3, 0.02], [66632.4, 0.0]]}
{"kind": "depth", "E": 1787081873523, "U": 11315468736095, "u": 11315468740749, "recv_ms": 1787081873491, "bids": [[1000.0, 35.81], [14294.2, 2.016], [14394.2, 2.184], [51755.0, 0.002], [58224.7, 0.002], [62106.4, 0.689], [63879.6, 14.224], [63937.3, 3.305], [63982.5, 0.261], [64047.3, 0.463], [64616.5, 0.289], [64627.3, 0.032], [64628.3, 0.032], [64635.9, 0.023], [64640.1, 0.018], [64650.3, 0.006], [64657.8, 0.002], [64661.6, 0.072], [64661.8, 0.073], [64665.6, 0.088], [64670.7, 0.761], [64671.2, 0.005], [64672.0, 0.897], [64672.7, 0.003], [64676.1, 0.987], [64676.8, 0.004], [64685.4, 0.546], [64685.5, 0.197], [64686.8, 0.089], [64687.7, 0.11], [64688.3, 0.004]], "asks": [[64696.4, 0.002], [64696.6, 0.089], [64700.0, 0.004], [64700.3, 0.0], [64701.5, 0.742], [64702.4, 0.002], [64704.4, 0.539], [64739.6, 0.003], [64804.3, 1.389], [64834.3, 0.0], [64834.4, 5.017], [64851.3, 7.236], [64862.6, 0.033], [64872.8, 0.006], [64890.1, 13.565], [64961.6, 1.774], [65017.8, 4.629], [65341.2, 2.523], [65466.6, 12.311], [66052.9, 2.27]]}
{"kind": "depth", "E": 1787081873625, "U": 11315468740802, "u": 11315468751323, "recv_ms": 1787081873594, "bids": [[14294.2, 2.38], [14394.2, 1.82], [51755.0, 0.0], [51755.4, 0.0], [58224.7, 0.002], [63694.2, 0.0], [64047.3, 0.463], [64501.0, 0.41], [64628.9, 0.179], [64660.5, 0.005], [64661.7, 0.071], [64662.0, 1.095], [64662.1, 2.189], [64662.3, 0.621], [64662.4, 0.076], [64665.4, 0.102], [64670.0, 1.401], [64677.2, 0.081], [64677.8, 0.369], [64685.5, 0.274], [64685.6, 0.009], [64686.8, 0.004], [64687.8, 0.0], [64687.9, 0.294], [64688.5, 0.085], [64688.6, 0.002], [64688.7, 0.027], [64688.8, 0.104], [64688.9, 0.039], [64689.0, 0.22], [64690.3, 0.0], [64690.9, 0.233]], "asks": [[64694.5, 0.513], [64695.3, 0.5], [64695.4, 0.092], [64695.7, 0.005], [64695.8, 0.004], [64695.9, 0.085], [64696.2, 0.001], [64696.6, 0.109], [64696.9, 0.022], [64697.0, 0.003], [64700.0, 0.904], [64700.4, 0.393], [64710.3, 0.212], [64725.3, 0.306], [64725.4, 0.256], [64883.0, 0.072], [64961.6, 4.39], [65031.2, 0.444], [65070.6, 0.003], [65341.2, 2.523], [65694.3, 0.0]]}
{"kind": "depth", "E": 1787081873727, "U": 11315468751389, "u": 11315468756102, "recv_ms": 1787081873696, "bids": [[1000.0, 35.81], [14294.2, 2.73], [14394.2, 1.47], [51755.0, 0.0], [58224.7, 0.002], [61459.4, 0.0], [62106.4, 0.692], [63694.2, 0.02], [63752.2, 7.699], [63853.2, 7.039], [63934.3, 4.106], [64047.3, 0.463], [64370.7, 4.355], [64552.6, 0.012], [64552.7, 4.633], [64635.9, 0.026], [64661.7, 0.141], [64661.8, 0.143], [64662.1, 2.289], [64662.6, 0.07], [64665.0, 0.156], [64670.1, 0.562], [64670.7, 0.209], [64677.8, 0.371], [64681.4, 0.126], [64684.0, 3.067], [64684.1, 1.373], [64685.5, 0.305], [64685.6, 0.001], [64686.8, 0.73], [64687.7, 0.087], [64689.9, 0.087], [64690.4, 0.087], [64694.2, 7.253]], "asks": [[64694.5, 0.429], [64695.7, 0.009], [64696.5, 0.315], [64696.6, 0.106], [64698.6, 0.782], [64699.2, 0.017], [64699.9, 0.01], [64700.4, 0.296], [64700.8, 0.02], [64701.6, 0.033], [64701.7, 0.005], [64705.3, 0.0], [64706.5, 0.042], [64709.1, 0.004], [64710.3, 0.214], [64713.6, 1.012], [64713.9, 0.466], [64716.4, 0.006], [64721.0, 0.022], [64804.3, 1.392], [64834.4, 5.398], [64851.3, 10.408], [64890.1, 9.89], [64893.2, 0.009], [65341.2, 2.523], [65470.6, 21.095], [65694.3, 0.02]]}
{"kind": "depth", "E": 1787081873829, "U": 11315468756223, "u": 11315468760677, "recv_ms": 1787081873798, "bids": [[1000.0, 35.81], [14294.2, 3.08], [14394.2, 1.12], [58224.7, 0.002], [61459.4, 0.0], [62106.4, 0.689], [63400.4, 0.081], [64047.3, 0.463], [64624.2, 0.001], [64650.0, 3.933], [64656.8, 1.47], [64661.9, 0.693], [64684.6, 0.075], [64685.4, 0.099], [64685.5, 0.189], [64686.8, 0.004], [64687.7, 0.11], [64687.8, 0.0], [64688.0, 0.564], [64694.2, 7.255]], "asks": [[64697.4, 0.568], [64698.0, 0.915], [64698.6, 0.225], [64703.0, 0.902], [65341.2, 2.523], [65720.2, 0.0], [65988.1, 0.015]]}
{"kind": "depth", "E": 1787081873931, "U": 11315468760998, "u": 11315468766081, "recv_ms": 1787081873901, "bids": [[14294.2, 3.444], [14394.2, 0.756], [58224.7, 0.002], [62106.4, 0.692], [63432.7, 0.632], [63885.5, 7.133], [63928.0, 8.591], [64047.3, 0.463], [64186.9, 0.0], [64381.0, 0.04], [64552.7, 4.523], [64685.4, 0.64], [64685.5, 0.212], [64687.7, 0.087], [64688.0, 0.023]], "asks": [[64694.3, 8.489], [64694.9, 0.007], [64696.4, 0.002], [64697.4, 0.566], [64716.4, 0.004], [64723.4, 1.921], [64758.6, 2.758], [64759.4, 0.0], [64834.4, 5.398], [64890.1, 10.341], [65222.2, 0.043], [65341.2, 2.523], [65481.1, 8.511], [65697.1, 8.36], [71163.8, 0.0]]}
{"kind": "depth", "E": 1787081874033, "U": 11315468766268, "u": 11315468771999, "recv_ms": 1787081874005, "bids": [[1000.0, 35.81], [14194.2, 0.042], [14294.2, 3.724], [14394.2, 0.434], [58224.7, 0.002], [61459.4, 0.0], [61459.5, 0.018], [62106.4, 0.689], [63694.2, 0.0], [63756.1, 21.269], [63885.6, 7.044], [64047.3, 0.463], [64370.7, 4.354], [64676.8, 0.022], [64677.1, 0.0], [64687.7, 0.141], [64688.4, 0.048], [64689.1, 0.101], [64689.8, 0.003], [64694.2, 7.256]], "asks": [[64694.3, 8.543], [64694.7, 0.047], [64695.4, 0.1], [64696.1, 0.001], [64702.2, 0.275], [64713.6, 0.74], [64851.3, 7.236], [65017.8, 4.63], [65341.2, 2.523], [65541.2, 29.225], [65694.3, 0.0]]}
{"kind": "depth", "E": 1787081874135, "U": 11315468772098, "u": 11315468777859, "recv_ms": 1787081874103, "bids": [[1000.0, 35.81], [14194.2, 0.224], [14294.2, 3.71], [14394.2, 0.266], [58224.7, 0.002], [61459.4, 0.0], [63701.0, 1.393], [63804.8, 12.982], [63858.9, 5.941], [63934.3, 3.887], [64047.3, 0.463], [64370.7, 4.742], [64664.2, 0.635], [64671.6, 0.623], [64682.6, 0.028], [64685.4, 0.006], [64685.5, 0.189], [64687.0, 0.036], [64687.6, 0.629], [64687.7, 0.798], [64687.8, 0.0], [64688.1, 0.154], [64688.9, 0.017], [64689.0, 0.2], [64690.8, 0.003], [64690.9, 0.317], [64692.3, 0.31]], "asks": [[64694.3, 8.997], [64695.0, 0.004], [64695.5, 0.0], [64696.5, 0.315], [64697.1, 0.006], [64697.4, 0.566], [64698.4, 0.01], [64699.4, 0.09], [64699.5, 0.001], [64700.5, 0.467], [64706.7, 0.003], [64715.3, 0.005], [64716.0, 0.258], [64718.4, 11.109], [64725.3, 0.924], [64732.6, 0.677], [64736.1, 0.221], [64746.1, 2.842], [64759.0, 0.312], [64761.3, 35.403], [64761.6, 0.007], [64762.8, 1.528], [64763.5, 0.0], [64851.3, 7.236], [64885.8, 0.113], [64890.1, 12.925], [65211.9, 8.724], [65341.2, 2.523], [65470.6, 21.767], [65470.7, 7.672], [65584.5, 4.004], [65687.6, 0.019]]}
{"kind": "depth", "E": 1787081874237, "U": 11315468777916, "u": 11315468785125, "recv_ms": 1787081874206, "bids": [[14194.2, 0.462], [14294.2, 3.584], [14394.2, 0.154], [58224.7, 0.002], [62106.4, 0.692], [63694.2, 0.02], [63701.0, 1.412], [63853.2, 8.134], [63917.9, 21.511], [63940.6, 2.415], [64047.3, 0.465], [64176.6, 9.179], [64370.7, 4.742], [64625.7, 0.122], [64658.8, 0.128], [64661.5, 0.069], [64670.1, 0.005], [64671.2, 0.562], [64672.3, 0.133], [64676.1, 0.061], [64676.9, 0.927], [64677.7, 0.001], [64681.2, 2.356], [64681.3, 1.329], [64685.4, 0.631], [64686.8, 0.004], [64687.7, 0.149], [64687.8, 0.0], [64687.9, 0.294], [64688.0, 0.022], [64688.3, 0.004], [64689.0, 0.223], [64689.1, 0.12], [64690.9, 0.085], [64691.3, 0.233], [64694.2, 7.256]], "asks": [[64694.3, 8.983], [64700.5, 0.466], [64709.3, 0.504], [64710.1, 0.929], [64711.6, 0.025], [64712.5, 0.712], [64714.0, 0.006], [64714.6, 0.764], [64716.4, 0.006], [64761.3, 0.0], [64763.5, 35.426], [64766.8, 0.027], [64767.9, 0.022], [64785.6, 1.215], [64851.3, 10.408], [64890.1, 9.445], [65341.2, 2.523], [65535.4, 5.357], [65687.6, 0.038], [65694.3, 0.02], [65988.1, 0.012]]}
{"kind": "depth", "E": 1787081874339, "U": 11315468785128, "u": 11315468791575, "recv_ms": 1787081874308, "bids": [[1000.0, 35.81], [14194.2, 0.7], [14294.2, 3.472], [14394.2, 0.028], [51755.0, 0.0], [58224.7, 0.002], [62106.4, 0.689], [64047.3, 0.463], [64659.9, 0.059], [64661.5, 0.012], [64676.0, 1.728], [64676.9, 0.001], [64685.4, 0.083], [64685.5, 0.189], [64687.6, 1.355], [64687.7, 0.141], [64687.8, 0.039], [64688.0, 0.563]], "asks": [[64696.5, 0.315], [64708.4, 0.002], [64709.3, 1.429], [64710.1, 0.004], [64761.6, 0.025], [65341.2, 2.523], [65470.6, 23.293], [65470.7, 6.16]]}
{"kind": "depth", "E": 1787081874441, "U": 11315468791756, "u": 11315468798112, "recv_ms": 1787081874410, "bids": [[1000.0, 35.81], [14194.2, 1.036], [14294.2, 3.164], [14394.2, 0.0], [58224.7, 0.002], [61459.4, 0.0], [62106.4, 0.692], [63694.2, 0.0], [63918.2, 4.649], [64047.3, 0.463], [64117.7, 6.074], [64370.7, 4.743], [64625.7, 0.022], [64639.8, 0.281], [64655.3, 2.854], [64664.2, 0.017], [64670.6, 0.925], [64671.2, 0.005], [64671.6, 0.005], [64674.5, 5.401], [64685.2, 1.935], [64685.4, 0.005], [64686.1, 0.004], [64687.6, 0.629], [64687.7, 0.218], [64689.9, 0.088], [64690.8, 0.002], [64694.2, 6.639]], "asks": [[64698.3, 0.008], [64698.4, 0.008], [64711.1, 0.559], [64712.5, 0.156], [64725.3, 0.306], [64732.6, 0.059], [64823.7, 0.0], [65017.8, 4.629], [65341.2, 2.523], [65341.3, 1.404], [65503.0, 7.2], [65567.7, 6.233], [65694.3, 0.0]]}
{"kind": "depth", "E": 1787081874543, "U": 11315468798183, "u": 11315468803269, "recv_ms": 1787081874510, "bids": [[14194.2, 1.386], [14294.2, 2.814], [58224.7, 0.002], [63400.4, 0.084], [63782.0, 3.278], [64047.3, 0.463], [64112.0, 6.055], [64366.7, 0.155], [64370.7, 4.733], [64685.4, 0.005], [64686.8, 0.011], [64687.7, 0.226], [64687.8, 0.008], [64688.0, 0.579]], "asks": [[64696.3, 0.021], [64696.5, 0.315], [64697.4, 0.566], [64698.6, 0.225], [65016.9, 0.0], [65210.6, 0.0], [65341.2, 2.523], [65814.9, 0.001]]}
{"kind": "depth", "E": 1787081874645, "U": 11315468803298, "u": 11315468807786, "recv_ms": 1787081874615, "bids": [[1000.0, 35.81], [14194.2, 1.736], [14294.2, 2.464], [51755.4, 0.0], [58224.7, 0.002], [62106.4, 0.689], [63694.2, 0.02], [63917.9, 23.293], [64047.3, 0.463], [64370.7, 4.888], [64552.7, 0.019], [64677.8, 0.369], [64685.4, 0.546], [64686.8, 0.105], [64687.7, 0.156], [64687.8, 0.0], [64688.0, 0.022], [64688.3, 0.004], [64688.4, 0.048], [64688.7, 0.005], [64689.1, 0.101], [64690.5, 0.001], [64691.3, 0.001], [64691.9, 0.233], [64692.0, 0.02]], "asks": [[64696.6, 0.128], [64707.4, 1.215], [64710.3, 0.212], [64725.3, 0.152], [64725.4, 0.41], [64834.4, 0.0], [64890.1, 0.011], [64890.2, 9.888], [65017.8, 4.783], [65211.9, 9.03], [65341.2, 2.523], [65470.6, 24.819], [65694.3, 0.02]]}
{"kind": "depth", "E": 1787081874747, "U": 11315468807833, "u": 11315468812436, "recv_ms": 1787081874715, "bids": [[1000.0, 35.81], [14194.2, 2.1], [14294.2, 2.1], [58224.7, 0.002], [61459.4, 0.0], [62106.4, 0.692], [63200.0, 21.875], [64047.3, 0.463], [64552.8, 4.632], [64660.3, 0.336], [64677.8, 0.371], [64685.4, 0.546], [64686.8, 0.004], [64687.7, 0.156], [64687.8, 0.085], [64688.0, 0.038], [64688.8, 0.085], [64689.0, 0.2], [64689.8, 0.022], [64690.2, 0.183], [64690.9, 0.001], [64694.2, 6.639]], "asks": [[64695.2, 0.166], [64710.3, 0.214], [64834.4, 5.025], [64851.3, 7.237], [65336.0, 15.864], [65341.2, 2.523], [65438.3, 3.633], [65787.6, 1.214]]}
{"kind": "depth", "E": 1787081874849, "U": 11315468812483, "u": 11315468816609, "recv_ms": 1787081874818, "bids": [[14194.2, 2.45], [14294.2, 1.75], [58224.7, 0.002], [61459.6, 2.445], [62106.4, 0.689], [63694.2, 0.0], [63729.5, 5.824], [64047.3, 0.463], [64370.7, 4.898], [64616.5, 0.289], [64635.9, 0.023], [64686.8, 0.12], [64687.7, 0.141], [64687.8, 0.0], [64688.0, 0.022], [64690.4, 0.106]], "asks": [[64695.0, 0.014], [64739.6, 0.003], [64804.3, 1.389], [65528.6, 0.002], [65606.5, 3.499], [65668.0, 0.587], [65694.3, 0.0], [65988.1, 0.015]]}
{"kind": "depth", "E": 1787081874951, "U": 11315468816806, "u": 11315468820917, "recv_ms": 1787081874919, "bids": [[1000.0, 35.81], [14194.2, 2.814], [14294.2, 1.386], [58224.7, 0.002], [61459.4, 0.0], [62106.4, 0.692], [62106.5, 0.0], [64047.3, 0.463], [64535.7, 0.001], [64536.3, 0.444], [64552.8, 0.018], [64694.2, 6.663]], "asks": [[64696.5, 0.315], [64717.6, 2.425], [64762.8, 6.696], [64834.4, 0.0], [64851.3, 0.0], [64864.1, 1.245], [65308.9, 6.268], [65336.0, 15.177], [65341.2, 2.523], [65438.9, 0.917], [65478.3, 3.256], [65541.3, 0.006]]}
{"kind": "depth", "E": 1787081875053, "U": 11315468821037, "u": 11315468825060, "recv_ms": 1787081875022, "bids": [[1000.0, 35.81], [14194.2, 3.164], [14294.2, 1.036], [58224.7, 0.002], [63723.8, 11.335], [63890.6, 0.0], [63901.9, 4.02], [63917.2, 0.624], [64047.3, 0.463], [64176.0, 0.4], [64366.7, 0.0], [64535.8, 4.739], [64536.3, 1.123], [64552.8, 4.632], [64682.6, 0.033]], "asks": [[64698.0, 0.015], [64700.0, 0.004], [64702.0, 1.044], [64806.3, 0.0], [64834.4, 5.025], [64851.3, 7.237], [65017.8, 4.782], [65211.1, 0.248], [65284.2, 0.0], [65341.2, 2.523], [66093.6, 1.296]]}
{"kind": "depth", "E": 1787081875155, "U": 11315468825070, "u": 11315468831154, "recv_ms": 1787081875124, "bids": [[14194.2, 3.514], [14294.2, 0.686], [58224.7, 0.002], [61459.4, 0.0], [62106.4, 0.689], [63694.2, 0.02], [63778.8, 1.717], [64047.3, 0.463], [64370.7, 4.889], [64585.7, 2.33], [64585.9, 0.424], [64629.5, 0.04], [64654.9, 0.001], [64664.8, 0.086], [64682.6, 0.028], [64685.5, 0.273], [64685.6, 0.033], [64686.8, 0.004], [64690.8, 0.086], [64694.2, 7.245]], "asks": [[64694.3, 8.985], [64695.2, 0.082], [64695.6, 0.022], [64696.3, 0.002], [64696.4, 0.002], [64696.6, 0.108], [64696.9, 0.003], [64697.4, 0.009], [64698.6, 0.125], [64699.9, 0.002], [64700.8, 0.685], [64703.0, 1.802], [64705.0, 0.002], [64711.1, 0.003], [64711.8, 0.558], [64746.1, 2.884], [64759.0, 0.313], [64799.7, 0.005], [64799.9, 2.433], [64851.3, 10.408], [64890.2, 13.36], [65308.9, 6.955], [65341.2, 2.523], [65438.3, 2.725], [65451.2, 1.068], [65594.8, 1.522], [65632.4, 17.533], [65694.3, 0.02], [65808.4, 1.212]]}
{"kind": "depth", "E": 1787081875257, "U": 11315468831451, "u": 11315468835858, "recv_ms": 1787081875225, "bids": [[1000.0, 35.81], [14194.2, 3.752], [14294.2, 0.378], [14594.2, 0.07], [51755.0, 0.0], [58224.7, 0.002], [61459.4, 0.0], [61459.5, 0.016], [61459.6, 2.447], [62106.4, 0.692], [63400.4, 0.081], [64047.3, 0.463], [64176.6, 9.49], [64642.9, 0.03], [64643.9, 0.55], [64649.4, 0.095], [64650.4, 2.114], [64657.9, 0.448], [64660.3, 0.0], [64662.3, 0.221], [64663.3, 0.403], [64664.2, 0.353], [64664.4, 1.166], [64665.1, 1.196], [64671.7, 1.08], [64685.4, 0.005], [64685.5, 0.189], [64685.6, 0.001], [64687.6, 0.629], [64687.7, 0.798], [64690.7, 0.232], [64691.1, 0.02], [64691.9, 0.001], [64692.0, 0.002], [64694.2, 7.244]], "asks": [[64694.3, 8.971], [64695.4, 0.12], [64695.6, 0.0], [64701.0, 0.912], [64716.4, 0.004], [64725.4, 1.028], [64732.8, 0.64], [64746.1, 2.842], [64894.3, 0.003], [64894.4, 26.848], [65257.1, 0.472], [65341.2, 2.523], [65438.8, 9.08], [65528.4, 0.003], [65535.4, 6.424], [65567.7, 6.841]]}
{"kind": "depth", "E": 1787081875359, "U": 11315468835869, "u": 11315468839781, "recv_ms": 1787081875328, "bids": [[1000.0, 35.81], [14194.2, 3.682], [14294.2, 0.238], [14594.2, 0.28], [51755.0, 0.002], [58224.7, 0.002], [62106.4, 0.689], [63694.2, 0.0], [63885.6, 6.262], [63917.9, 23.918], [64047.3, 0.463], [64176.0, 0.09], [64370.0, 3.034], [64370.7, 5.044], [64685.2, 1.935], [64685.4, 0.662], [64686.6, 0.003], [64687.6, 0.629], [64687.7, 0.141], [64687.8, 0.0], [64687.9, 0.294], [64688.0, 0.022], [64688.3, 0.004], [64690.0, 0.231], [64691.1, 0.02], [64692.1, 0.001], [64694.2, 7.245]], "asks": [[64697.4, 0.011], [64698.3, 0.006], [64698.6, 0.775], [64699.9, 0.01], [64700.0, 0.904], [64700.3, 0.0], [64700.8, 0.027], [64823.7, 0.0], [65211.9, 9.336], [65341.2, 2.523], [65438.8, 8.172], [65694.3, 0.0], [65696.4, 0.007], [66299.0, 0.005]]}
{"kind": "depth", "E": 1787081875461, "U": 11315468839897, "u": 11315468845488, "recv_ms": 1787081875429, "bids": [[14194.2, 3.556], [14294.2, 0.126], [14594.2, 0.518], [32347.1, 0.0], [51755.0, 0.0], [58224.7, 0.002], [62106.4, 0.692], [63917.9, 24.137], [64047.3, 0.463], [64370.7, 5.043], [64552.8, 4.666]], "asks": [[64696.5, 0.315], [64834.4, 5.398], [64890.2, 9.73], [65096.3, 0.0], [65341.2, 2.523], [65341.3, 1.403], [65438.8, 7.264], [65438.9, 2.749], [65607.8, 1.229], [65781.2, 0.606]]}
{"kind": "depth", "E": 1787081875563, "U": 11315468845543, "u": 11315468850425, "recv_ms": 1787081875532, "bids": [[1000.0, 35.81], [14194.2, 3.444], [14294.2, 0.0], [14594.2, 0.756], [58224.7, 0.002], [61459.4, 0.0], [63694.2, 0.02], [63955.5, 0.009], [64047.3, 0.463], [64176.6, 9.8], [64370.7, 5.198], [64552.8, 0.018], [64694.2, 7.269]], "asks": [[64694.3, 8.971], [64805.6, 0.087], [64834.4, 0.0], [65341.2, 2.523], [65438.3, 1.817], [65694.3, 0.02]]}
{"kind": "depth", "E": 1787081875665, "U": 11315468850538, "u": 11315468858015, "recv_ms": 1787081875633, "bids": [[1000.0, 35.81], [14194.2, 3.094], [14594.2, 1.106], [51755.4, 0.0], [58224.7, 0.002], [62106.4, 0.689], [64047.3, 0.463], [64115.7, 0.009], [64176.6, 9.8], [64672.2, 0.018], [64678.7, 0.019]], "asks": [[65341.2, 2.525], [65438.9, 3.665], [65631.8, 0.001], [65632.5, 6.161], [65697.1, 9.424], [65811.0, 0.394]]}
{"kind": "depth", "E": 1787081875767, "U": 11315468858045, "u": 11315468864750, "recv_ms": 1787081875737, "bids": [[14194.2, 2.73], [14594.2, 1.47], [32347.1, 0.002], [51755.0, 0.0], [58224.7, 0.002], [61459.4, 0.0], [62106.4, 0.692], [63788.5, 7.891], [63796.2, 0.035], [63843.3, 0.782], [63918.2, 3.1], [63946.3, 2.822], [64015.1, 1.17], [64047.3, 0.463], [64370.7, 5.208], [64552.8, 4.666], [64635.9, 0.026], [64672.2, 0.02], [64677.8, 0.371], [64685.4, 0.005], [64687.6, 0.629], [64687.7, 0.257], [64687.8, 0.541], [64694.2, 7.269]], "asks": [[64695.8, 0.027], [64696.5, 0.315], [64698.5, 0.0], [64698.6, 0.125], [64699.9, 0.002], [64700.0, 0.004], [64700.5, 0.003], [64700.7, 0.666], [64700.8, 0.483], [64710.3, 0.214], [64804.3, 1.392], [64834.4, 5.398], [64851.3, 0.0], [64851.4, 8.67], [65017.8, 4.783], [65341.2, 2.523], [65438.8, 6.356], [65438.9, 5.496], [65580.6, 1.824], [65794.1, 6.737]]}
{"kind": "depth", "E": 1787081875869, "U": 11315468864900, "u": 11315468872221, "recv_ms": 1787081875837, "bids": [[1000.0, 35.81], [14194.2, 2.38], [14594.2, 1.82], [32347.1, 0.0], [51755.0, 0.0], [58224.7, 0.002], [62106.4, 0.689], [63285.2, 0.01], [63694.2, 0.0], [63901.9, 3.787], [63917.9, 24.356], [64107.6, 6.489], [64685.4, 0.662], [64687.7, 0.141], [64687.8, 0.0], [64687.9, 0.294], [64688.0, 0.022], [64688.3, 0.004]], "asks": [[65341.2, 2.523], [65632.4, 18.598], [65694.3, 0.0], [65852.2, 0.0], [65988.1, 0.018]]}
{"kind": "depth", "E": 1787081875971, "U": 11315468872424, "u": 11315468877295, "recv_ms": 1787081875940, "bids": [[1000.0, 35.81], [14194.2, 2.016], [14594.2, 2.184], [58224.7, 0.002], [61459.4, 0.0], [61459.5, 0.014], [61459.6, 2.449], [63950.2, 6.558], [64047.3, 0.463], [64496.9, 0.981], [64497.0, 7.351], [64535.8, 2.335], [64536.3, 0.444], [64552.8, 2.724], [64578.7, 11.527], [64580.2, 0.001], [64581.3, 2.591], [64626.2, 2.452], [64627.7, 1.917], [64694.2, 7.268]], "asks": [[64696.5, 0.315], [64696.6, 0.086], [64702.7, 0.049], [64709.3, 1.426], [64749.0, 1.789], [64749.2, 0.001], [64757.0, 0.031], [64760.1, 2.978], [64760.4, 0.0], [64766.3, 0.956], [64807.1, 5.585], [64807.6, 11.621], [64808.0, 6.661], [64834.4, 5.398], [64851.2, 2.672], [64851.4, 11.873], [65341.2, 2.523], [65438.9, 6.412], [65632.4, 19.663]]}
{"kind": "depth", "E": 1787081876073, "U": 11315468877445, "u": 11315468882308, "recv_ms": 1787081876041, "bids": [[14194.2, 1.666], [14594.2, 2.534], [58224.7, 0.002], [61459.4, 0.0], [62106.4, 0.692], [63694.2, 0.02], [63801.4, 4.054], [63917.9, 25.918], [64047.3, 0.463], [64117.7, 5.84], [64370.7, 5.207], [64497.0, 10.218], [64535.8, 4.793], [64552.8, 4.666], [64576.6, 0.341], [64577.0, 3.941], [64578.6, 0.174], [64578.8, 3.475], [64616.5, 0.286], [64620.9, 0.072], [64621.3, 0.048], [64635.9, 0.026], [64661.3, 0.002], [64661.4, 1.686], [64661.5, 0.01], [64664.8, 0.084], [64664.9, 0.0], [64665.0, 0.154], [64682.6, 0.028], [64687.4, 0.0], [64691.5, 0.085]], "asks": [[64694.3, 8.854], [64725.4, 0.41], [64739.6, 0.003], [64743.5, 0.047], [64763.3, 0.022], [64763.7, 0.046], [64804.3, 1.389], [64807.1, 6.936], [64827.6, 0.593], [64828.0, 4.919], [64851.4, 8.702], [64890.2, 13.201], [65341.2, 2.523], [65411.8, 0.458], [65694.3, 0.02], [65808.4, 0.606], [65988.1, 0.015]]}
{"kind": "depth", "E": 1787081876175, "U": 11315468882524, "u": 11315468887453, "recv_ms": 1787081876144, "bids": [[1000.0, 35.81], [14194.2, 1.302], [14594.2, 2.898], [51755.0, 0.002], [58224.7, 0.002], [62106.4, 0.689], [63700.9, 0.02], [63701.0, 1.402], [63756.1, 20.172], [64047.3, 0.463], [64689.8, 0.003], [64690.4, 0.087], [64690.5, 0.02]], "asks": [[64695.4, 0.1], [64695.5, 0.019], [64695.8, 0.004], [64695.9, 0.108], [64696.4, 0.002], [64700.7, 0.667], [64705.0, 0.001], [64749.0, 1.759], [64749.2, 0.031], [65014.6, 0.07], [65016.2, 0.029], [65341.2, 2.523], [65687.6, 0.028], [71163.8, 0.0]]}
{"kind": "depth", "E": 1787081876277, "U": 11315468887503, "u": 11315468892156, "recv_ms": 1787081876245, "bids": [[1000.0, 35.81], [14194.2, 0.938], [14594.2, 3.262], [51755.0, 0.0], [58224.7, 0.002], [61459.4, 0.0], [62106.4, 0.692], [63400.4, 0.084], [63694.2, 0.0], [63946.3, 1.885], [64047.3, 0.463], [64112.0, 6.289], [64552.8, 4.666], [64664.4, 0.548], [64670.1, 0.562], [64670.6, 0.368], [64671.7, 0.462], [64681.4, 0.126], [64684.0, 3.067], [64685.4, 0.036], [64686.8, 0.004], [64686.9, 0.63], [64694.2, 7.257]], "asks": [[64694.3, 8.846], [64701.0, 0.012], [64710.6, 0.082], [64711.5, 0.876], [64711.8, 0.002], [64714.5, 1.044], [64716.0, 0.143], [64725.5, 0.161], [64732.8, 0.022], [64834.4, 5.398], [64851.4, 11.873], [64890.2, 9.719], [65017.8, 4.63], [65341.2, 2.523], [65470.6, 24.361], [65629.8, 0.23], [65687.5, 0.03], [65694.3, 0.0], [65781.2, 1.212], [71163.8, 0.0]]}
{"kind": "depth", "E": 1787081876379, "U": 11315468892188, "u": 11315468900332, "recv_ms": 1787081876350, "bids": [[14194.2, 0.588], [14594.2, 3.612], [58224.7, 0.002], [62106.4, 0.689], [63539.8, 0.013], [63593.7, 0.0], [63756.1, 21.269], [63917.2, 0.0], [63986.0, 0.0], [64000.0, 130.908], [64047.3, 0.463], [64370.7, 5.197], [64625.7, 0.122], [64685.2, 1.935], [64685.4, 0.623], [64686.2, 0.032], [64686.9, 0.004], [64687.0, 0.036], [64687.7, 0.172], [64687.8, 0.0], [64687.9, 0.294], [64688.0, 0.03], [64694.2, 7.267]], "asks": [[64696.4, 0.002], [64698.5, 0.007], [64698.6, 0.234], [64700.3, 0.194], [64700.5, 0.003], [64700.7, 0.55], [64714.5, 0.929], [64715.4, 0.241], [64823.7, 0.0], [65341.2, 2.523], [65405.9, 6.93], [65470.6, 24.819]]}
{"kind": "depth", "E": 1787081876481, "U": 11315468900464, "u": 11315468906882, "recv_ms": 1787081876449, "bids": [[1000.0, 35.81], [14194.2, 0.336], [14494.2, 0.098], [14594.2, 3.766], [58224.7, 0.002], [63264.8, 0.0], [63529.7, 1.643], [63694.2, 0.02], [63893.0, 0.015], [63917.9, 26.542], [63950.2, 7.495], [63988.3, 8.358], [64015.5, 7.867], [64047.3, 0.463], [64552.8, 0.018], [64560.0, 0.445], [64651.6, 0.044], [64655.7, 0.33], [64670.1, 0.005], [64670.8, 0.009], [64671.2, 0.562], [64685.4, 0.028], [64685.5, 0.197], [64686.8, 0.004], [64686.9, 0.63], [64687.7, 0.141], [64688.0, 0.022], [64688.3, 0.004]], "asks": [[64697.3, 0.088], [64697.4, 0.011], [64698.3, 0.006], [64698.4, 0.008], [64698.5, 0.0], [64698.6, 0.125], [64699.7, 0.002], [64700.0, 0.004], [64700.3, 0.0], [64700.5, 0.003], [64700.7, 0.666], [64736.9, 0.488], [64774.6, 0.0], [64834.4, 0.0], [64926.6, 0.0], [64969.8, 2.049], [65017.8, 4.784], [65055.8, 0.0], [65341.2, 2.523], [65694.3, 0.02], [65808.4, 0.0]]}
{"kind": "depth", "E": 1787081876583, "U": 11315468907017, "u": 11315468912304, "recv_ms": 1787081876552, "bids": [[1000.0, 35.81], [14194.2, 0.21], [14494.2, 0.336], [14594.2, 3.654], [58224.7, 0.002], [61459.4, 0.0], [62106.4, 0.692], [63752.2, 6.603], [63853.2, 8.29], [63950.2, 6.559], [64047.3, 0.463], [64535.8, 0.009], [64535.9, 3.581], [64552.8, 4.072], [64625.7, 0.022], [64630.0, 2.643], [64661.3, 0.004], [64661.4, 1.688], [64661.5, 0.012], [64664.8, 0.086], [64664.9, 0.002], [64665.0, 0.156], [64680.5, 0.004], [64682.4, 0.001], [64684.8, 0.044], [64685.2, 1.934], [64685.4, 0.005], [64685.5, 0.196], [64686.6, 0.004], [64686.8, 0.004], [64686.9, 0.012], [64687.0, 0.036], [64687.7, 0.783], [64689.6, 0.039], [64689.8, 0.022], [64689.9, 0.087], [64690.2, 0.161], [64690.5, 0.001], [64690.7, 0.0], [64691.0, 0.004], [64692.3, 0.542], [64692.4, 0.099], [64694.0, 0.001], [64694.1, 0.149], [64694.2, 7.87]], "asks": [[64695.5, 0.0], [64695.9, 0.085], [64698.7, 2.857], [64700.1, 0.331], [64701.2, 0.0], [64702.0, 0.144], [64706.5, 0.002], [64708.1, 0.062], [64716.4, 0.002], [64722.3, 2.327], [64746.1, 2.856], [64834.4, 5.398], [64851.2, 1.28], [64851.4, 11.873], [65341.2, 2.523]]}
{"kind": "depth", "E": 1787081876685, "U": 11315468912444, "u": 11315468917206, "recv_ms": 1787081876655, "bids": [[14194.2, 0.098], [14494.2, 0.588], [14594.2, 3.514], [51755.4, 0.0], [58224.7, 0.002], [61459.4, 0.001], [62106.4, 0.689], [63594.4, 11.017], [63694.2, 0.0], [63788.8, 0.05], [63950.2, 7.495], [64047.3, 0.463], [64176.6, 9.489], [64370.7, 5.197], [64403.3, 0.079], [64624.3, 0.162], [64685.3, 0.473], [64685.4, 0.655], [64686.0, 0.003], [64686.6, 0.003], [64686.9, 0.004], [64687.7, 0.141], [64688.3, 0.004], [64694.2, 7.87]], "asks": [[64694.3, 8.956], [64695.9, 0.001], [64696.5, 0.315], [64696.7, 0.021], [64696.9, 0.0], [64697.5, 0.029], [64699.8, 0.085], [64702.0, 1.044], [64703.0, 2.702], [64851.4, 11.873], [64890.2, 9.557], [65017.8, 4.783], [65341.2, 2.523], [65480.3, 5.453], [65694.3, 0.0], [65781.2, 1.818]]}
{"kind": "depth", "E": 1787081876787, "U": 11315468917247, "u": 11315468920917, "recv_ms": 1787081876755, "bids": [[1000.0, 35.81], [14194.2, 0.0], [14494.2, 0.84], [14594.2, 3.36], [58224.7, 0.002], [61459.4, 0.0], [62106.4, 0.692], [63238.6, 0.631], [63691.4, 6.592], [63756.1, 21.267], [63843.5, 1.564], [63885.5, 7.398], [63901.9, 3.436], [63982.6, 1.304], [63989.0, 3.751], [64047.3, 0.463], [64370.7, 5.198], [64585.7, 0.011], [64586.0, 5.139], [64677.8, 0.371], [64685.3, 0.472], [64685.4, 0.005], [64686.2, 0.033], [64687.7, 0.867], [64687.8, 0.65], [64691.8, 0.233], [64692.3, 0.31]], "asks": [[64696.9, 0.023], [64710.3, 0.214], [64799.9, 0.114], [64800.0, 13.693], [65341.2, 2.523]]}
{"kind": "depth", "E": 1787081876889, "U": 11315468921038, "u": 11315468924666, "recv_ms": 1787081876859, "bids": [[1000.0, 35.81], [14494.2, 1.204], [14594.2, 2.996], [58224.7, 0.002], [61459.6, 2.447], [63694.2, 0.02], [63775.3, 0.001], [63831.6, 0.0], [63918.2, 1.551], [64047.3, 0.463], [64680.9, 0.014], [64685.3, 0.473], [64685.4, 0.662], [64685.5, 0.189], [64686.2, 0.032], [64687.7, 0.141], [64687.8, 0.0], [64688.0, 0.022], [64691.1, 0.002], [64692.5, 0.019]], "asks": [[64696.3, 0.0], [64696.6, 0.086], [64701.6, 0.034], [64704.8, 0.313], [64706.7, 0.001], [64890.2, 9.734], [65336.0, 14.521], [65341.2, 2.523], [65694.3, 0.02]]}
{"kind": "depth", "E": 1787081876991, "U": 11315468924780, "u": 11315468929642, "recv_ms": 1787081876960, "bids": [[14494.2, 1.554], [14594.2, 2.646], [58224.7, 0.002], [61459.4, 0.0], [62106.4, 0.689], [63691.4, 7.69], [63756.1, 22.364], [63788.5, 10.24], [63805.3, 4.226], [64047.3, 0.463], [64176.6, 9.8], [64370.7, 5.198], [64536.3, 0.949], [64672.2, 0.022], [64685.3, 0.472], [64685.4, 0.012], [64685.7, 0.007], [64686.2, 0.032], [64686.8, 0.004], [64686.9, 0.012], [64687.7, 1.509], [64694.2, 7.885]], "asks": [[64702.0, 1.044], [64703.0, 2.702], [64705.0, 0.161], [64708.5, 0.214], [64709.6, 0.788], [64711.5, 0.556], [64851.2, 2.672], [65341.2, 2.523], [65480.3, 6.216], [66255.4, 1.292]]}
{"kind": "depth", "E": 1787081877093, "U": 11315468929771, "u": 11315468935351, "recv_ms": 1787081877062, "bids": [[1000.0, 35.81], [14494.2, 1.904], [14594.2, 2.296], [58224.7, 0.002], [62106.4, 0.692], [63694.2, 0.0], [63904.6, 7.095], [63917.9, 28.105], [64047.3, 0.463], [64106.2, 7.037], [64603.1, 0.009], [64603.2, 3.263], [64623.2, 0.0], [64639.8, 0.309], [64645.9, 5.016], [64662.0, 0.139], [64682.6, 0.028], [64685.7, 0.006], [64686.6, 0.004], [64689.6, 0.271], [64689.7, 0.001], [64691.8, 0.001], [64692.4, 0.064], [64694.2, 7.883]], "asks": [[64694.4, 0.119], [64696.2, 0.085], [64696.6, 0.088], [64697.9, 0.311], [64702.0, 0.144], [64711.4, 0.054], [64719.8, 0.018], [64733.7, 0.852], [64736.0, 0.027], [64758.6, 1.91], [64758.7, 0.002], [64821.9, 0.013], [64822.0, 0.01], [65341.2, 2.523], [65694.3, 0.0]]}
{"kind": "depth", "E": 1787081877195, "U": 11315468935365, "u": 11315468940630, "recv_ms": 1787081877164, "bids": [[14494.2, 2.268], [14594.2, 1.932], [51755.0, 0.0], [58224.7, 0.002], [61459.4, 0.0], [61459.5, 0.012], [61459.6, 2.449], [62106.4, 0.689], [63756.1, 22.208], [63826.5, 4.848], [63843.5, 2.346], [63924.3, 8.44], [64047.3, 0.463], [64106.2, 6.349], [64117.7, 5.606], [64552.8, 0.018], [64552.9, 4.856], [64577.0, 0.077], [64577.1, 3.865], [64590.9, 0.015], [64592.0, 0.0], [64621.3, 0.002], [64621.4, 0.048], [64635.0, 1.628], [64636.1, 1.202], [64639.8, 0.281], [64646.4, 6.068], [64649.1, 1.535], [64672.2, 0.02], [64694.2, 7.883]], "asks": [[64696.6, 0.089], [64703.1, 0.004], [64749.0, 1.789], [64749.2, 0.001], [64763.7, 0.0], [64763.8, 0.046], [64790.4, 1.61], [64791.0, 0.0], [64828.0, 4.919], [64834.4, 5.398], [64890.2, 9.557], [65017.8, 4.782], [65341.2, 2.523], [65632.4, 18.598], [65655.7, 0.639]]}
{"kind": "depth", "E": 1787081877297, "U": 11315468940893, "u": 11315468946453, "recv_ms": 1787081877266, "bids": [[14494.2, 2.632], [14594.2, 1.568], [58224.7, 0.002], [61459.4, 0.0], [63694.2, 0.02], [63908.2, 6.253], [63924.3, 9.377], [64047.3, 0.463], [64079.6, 4.147], [64117.7, 5.372], [64370.7, 5.199], [64624.9, 6.146], [64627.1, 2.218], [64632.0, 2.385], [64647.5, 3.509], [64647.6, 0.03], [64657.9, 0.448], [64663.7, 1.003], [64664.7, 0.01], [64672.0, 0.897], [64680.9, 0.013], [64685.4, 0.005], [64686.2, 0.033], [64686.6, 0.003], [64687.8, 0.007], [64688.4, 0.148], [64689.1, 0.001], [64691.6, 0.019], [64692.2, 0.015], [64692.5, 0.001], [64694.0, 0.0], [64694.1, 0.15], [64694.2, 7.299]], "asks": [[64694.3, 8.942], [64694.7, 0.147], [64695.4, 0.0], [64701.0, 0.012], [64701.6, 0.033], [64702.0, 1.044], [64703.0, 1.802], [64703.1, 0.003], [64707.4, 1.217], [64720.5, 2.095], [64725.7, 0.154], [64733.1, 0.024], [64736.6, 3.53], [64746.1, 2.842], [64759.3, 6.001], [65341.2, 2.523], [65694.3, 0.02]]}
{"kind": "depth", "E": 1787081877399, "U": 11315468946502, "u": 11315468951520, "recv_ms": 1787081877367, "bids": [[1000.0, 35.81], [14494.2, 2.982], [14594.2, 1.218], [58224.7, 0.002], [61459.4, 0.001], [62106.4, 0.692], [63400.4, 0.081], [63820.8, 6.99], [64047.3, 0.463], [64112.0, 6.523], [64616.5, 0.289], [64635.9, 0.023], [64664.2, 0.017], [64668.0, 0.767], [64680.8, 0.631], [64685.2, 1.935], [64685.4, 0.562], [64686.2, 0.032], [64686.9, 0.004], [64687.7, 0.157], [64687.8, 0.007], [64688.0, 0.099], [64688.3, 0.73], [64691.2, 0.007], [64694.0, 0.001], [64694.1, 0.15]], "asks": [[64694.3, 7.062], [64696.3, 0.002], [64696.7, 0.021], [64698.8, 0.004], [64700.2, 0.006], [64701.5, 0.743], [64739.6, 0.003], [64746.1, 2.856], [64749.0, 1.759], [64749.2, 0.031], [64823.7, 0.0], [64851.4, 11.873], [64888.4, 0.201], [64890.2, 9.568], [65341.2, 2.523], [65414.5, 0.0], [65584.5, 3.777]]}
{"kind": "depth", "E": 1787081877501, "U": 11315468951568, "u": 11315468954986, "recv_ms": 1787081877472, "bids": [[14494.2, 3.346], [14594.2, 0.854], [58224.7, 0.002], [61459.4, 0.0], [62106.4, 0.689], [63407.5, 0.002], [63694.2, 0.0], [63756.1, 23.304], [63918.2, 0.002], [63972.9, 3.13], [64047.3, 0.463], [64591.6, 10.001], [64685.4, 0.005], [64685.5, 0.189], [64686.8, 0.004], [64687.7, 0.141], [64687.8, 0.0], [64688.0, 0.022], [64688.1, 0.247], [64688.3, 0.568], [64690.0, 0.32]], "asks": [[64701.0, 0.912], [64791.6, 0.012], [64791.7, 10.219], [64795.1, 0.0], [65341.2, 2.523], [65632.4, 19.663], [65638.8, 0.398], [65694.3, 0.0], [65803.5, 0.778]]}
{"kind": "depth", "E": 1787081877603, "U": 11315468955190, "u": 11315468959863, "recv_ms": 1787081877573, "bids": [[14494.2, 3.696], [14594.2, 0.504], [51755.0, 0.0], [58224.7, 0.002], [61459.6, 2.447], [62106.4, 0.692], [64047.3, 0.463], [64112.0, 6.757], [64370.7, 5.199], [64681.2, 2.351], [64681.3, 1.334], [64685.4, 0.662], [64688.1, 0.154], [64688.3, 0.004], [64689.6, 0.248], [64689.8, 0.003], [64690.0, 0.231]], "asks": [[64694.7, 1.004], [64696.6, 0.086], [64696.9, 0.0], [64698.8, 0.006], [64700.2, 0.004], [64701.0, 0.012], [64708.1, 0.022], [64711.4, 0.094], [65341.2, 2.523]]}
{"kind": "depth", "E": 1787081877705, "U": 11315468959988, "u": 11315468964228, "recv_ms": 1787081877674, "bids": [[1000.0, 35.81], [14394.2, 0.168], [14494.2, 3.724], [14594.2, 0.308], [51755.4, 0.0], [58224.7, 0.002], [58224.8, 0.002], [61459.4, 0.0], [62106.4, 0.689], [63659.1, 4.835], [63694.2, 0.02], [63885.5, 7.632], [64047.3, 0.463], [64370.7, 5.198], [64665.7, 0.497], [64668.0, 0.431], [64670.1, 0.562], [64671.2, 0.005], [64671.3, 0.001], [64671.8, 0.003], [64672.0, 0.781], [64672.5, 0.118], [64678.0, 0.429], [64679.0, 1.8], [64681.2, 2.356], [64681.3, 1.329], [64681.4, 0.126], [64684.0, 2.526], [64684.2, 1.039], [64685.4, 0.012], [64687.6, 0.629], [64687.7, 0.791], [64689.7, 0.0], [64690.7, 0.023], [64691.2, 0.027], [64691.6, 0.042], [64691.7, 0.021], [64694.2, 7.299]], "asks": [[64694.3, 8.966], [64696.2, 0.088], [64696.6, 0.086], [64697.0, 0.025], [64714.3, 0.002], [64715.3, 0.12], [64715.4, 0.126], [64743.5, 0.005], [65341.2, 2.523], [65410.7, 0.246], [65655.7, 0.335], [65694.3, 0.02], [65729.4, 4.682], [65988.1, 0.015]]}
{"kind": "depth", "E": 1787081877807, "U": 11315468964252, "u": 11315468967964, "recv_ms": 1787081877776, "bids": [[14394.2, 0.392], [14494.2, 3.626], [14594.2, 0.182], [58224.7, 0.002], [58224.8, 0.0], [61459.4, 0.0], [63917.9, 29.668], [64047.3, 0.463], [64635.9, 0.026], [64646.2, 2.321], [64646.4, 6.07], [64670.1, 0.005], [64671.2, 0.562], [64671.7, 0.578], [64672.5, 0.002], [64677.8, 0.371], [64681.4, 0.126], [64684.0, 3.067], [64684.2, 0.498], [64685.2, 1.934], [64685.4, 0.005], [64686.2, 0.033], [64687.7, 0.157], [64687.8, 0.634], [64688.0, 0.022], [64688.3, 0.011], [64690.7, 0.0]], "asks": [[64694.3, 8.968], [64701.0, 0.912], [64710.3, 0.214], [64717.7, 0.466], [64718.4, 11.111], [64725.4, 0.256], [64725.5, 0.315], [64746.2, 0.0], [64791.5, 0.0], [64804.3, 1.392], [65017.8, 4.783], [65341.2, 2.523], [65655.5, 4.525], [67326.4, 0.001]]}
{"kind": "depth", "E": 1787081877909, "U": 11315468968093, "u": 11315468971838, "recv_ms": 1787081877883, "bids": [[14394.2, 0.63], [14494.2, 3.5], [14594.2, 0.07], [58224.7, 0.002], [61459.4, 0.0], [62106.4, 0.692], [63694.2, 0.0], [64047.3, 0.463], [64370.7, 5.208], [64658.4, 0.002], [64662.7, 2.848], [64671.8, 0.001], [64685.2, 1.935], [64685.4, 0.662], [64686.2, 0.032], [64686.8, 0.73], [64687.7, 0.141], [64687.8, 0.0], [64688.0, 0.022], [64688.3, 0.004], [64694.2, 7.3]], "asks": [[64696.6, 0.086], [64702.0, 0.144], [64703.0, 2.702], [64708.9, 0.01], [64709.6, 0.788], [64713.2, 1.79], [65341.2, 2.523], [65613.0, 2.374], [65638.8, 0.702], [65694.3, 0.0]]}
{"kind": "depth", "E": 1787081878011, "U": 11315468971985, "u": 11315468977295, "recv_ms": 1787081877981, "bids": [[1000.0, 35.81], [14394.2, 0.924], [14494.2, 3.276], [14594.2, 0.0], [58224.7, 0.002], [61459.5, 0.014], [61459.6, 2.445], [62106.4, 0.689], [63659.1, 5.933], [63969.6, 0.008], [64047.3, 0.463], [64552.9, 4.879], [64586.0, 2.82], [64586.2, 5.349], [64591.7, 3.889], [64679.1, 0.237], [64680.2, 0.671], [64683.5, 0.005], [64685.2, 1.934], [64685.4, 0.012], [64686.2, 0.033], [64686.8, 0.004], [64686.9, 0.012], [64687.0, 0.036], [64687.7, 0.262], [64687.8, 0.541]], "asks": [[64694.3, 8.967], [64700.5, 0.043], [64700.7, 0.626], [64701.5, 0.165], [64704.4, 0.014], [64762.8, 1.528], [64763.5, 0.0], [64766.8, 0.045], [64767.9, 35.516], [64790.4, 2.906], [64800.0, 13.693], [64834.4, 5.027], [64851.4, 8.703], [65017.6, 0.108], [65632.4, 20.728], [65729.4, 5.746]]}
{"kind": "depth", "E": 1787081878113, "U": 11315468978279, "u": 11315468985615, "recv_ms": 1787081878083, "bids": [[14394.2, 1.274], [14494.2, 2.926], [58224.7, 0.002], [61459.4, 0.0], [62106.4, 0.692], [63694.2, 0.02], [63950.2, 6.558], [64047.3, 0.463], [64682.6, 0.028], [64685.2, 1.934], [64685.4, 0.098], [64686.2, 0.032], [64686.3, 0.116], [64686.8, 0.004], [64686.9, 0.004], [64687.7, 0.161], [64687.8, 0.0], [64688.0, 0.022], [64688.1, 0.155], [64688.3, 0.004], [64688.4, 0.712], [64691.2, 0.026], [64692.2, 0.014], [64693.7, 0.024], [64694.1, 0.151], [64694.2, 7.942]], "asks": [[64694.3, 7.653], [64694.7, 0.958], [64696.2, 0.085], [64702.0, 0.144], [64703.0, 1.802], [64851.4, 11.873], [65341.2, 2.523], [65470.6, 24.057], [65694.3, 0.02], [65988.1, 0.012]]}
{"kind": "depth", "E": 1787081878215, "U": 11315468985867, "u": 11315468991807, "recv_ms": 1787081878184, "bids": [[14394.2, 1.638], [14494.2, 2.562], [58224.7, 0.002], [61439.9, 0.0], [61459.4, 0.0], [62106.4, 0.689], [63380.1, 0.001], [63400.4, 0.084], [63659.1, 4.835], [63917.9, 29.199], [63950.2, 6.558], [64015.5, 7.166], [64047.3, 0.463], [64370.7, 5.207], [64642.4, 1.631], [64657.9, 0.434], [64671.5, 0.006], [64681.2, 2.351], [64681.3, 1.334], [64685.3, 0.472], [64685.4, 0.098], [64686.1, 0.005], [64686.3, 0.115], [64686.6, 0.003], [64686.8, 0.004], [64688.3, 0.004], [64688.4, 0.148], [64688.5, 0.085], [64688.6, 0.566]], "asks": [[64694.3, 7.646], [64696.6, 0.086], [64698.6, 0.698], [64699.8, 0.093], [64699.9, 0.002], [64700.0, 0.904], [64700.5, 0.003], [64700.7, 0.085], [64700.8, 0.483], [64701.5, 0.166], [64703.0, 2.702], [64763.5, 35.295], [64766.8, 0.027], [64767.9, 0.022], [64851.4, 11.873], [64890.2, 9.342], [65155.6, 0.0], [65341.2, 2.523]]}
{"kind": "depth", "E": 1787081878317, "U": 11315468991959, "u": 11315468997422, "recv_ms": 1787081878286, "bids": [[1000.0, 35.81], [14394.2, 1.988], [14494.2, 2.212], [51755.0, 0.0], [58224.7, 0.002], [60793.2, 0.0], [62086.7, 0.006], [63694.2, 0.0], [63901.9, 3.085], [63924.3, 8.439], [63988.3, 8.124], [64047.3, 0.463], [64584.2, 0.381], [64644.7, 0.244], [64664.4, 1.166], [64671.8, 0.619], [64678.2, 0.092], [64678.6, 0.233], [64684.0, 2.526], [64685.3, 0.472], [64685.4, 0.012], [64685.5, 0.73], [64685.7, 0.007], [64686.1, 0.004], [64686.6, 0.003], [64686.8, 0.004], [64687.7, 0.141], [64687.8, 0.65], [64688.3, 0.004], [64688.4, 0.148], [64688.6, 0.002], [64689.6, 0.016], [64690.4, 0.319], [64693.9, 0.002], [64694.0, 0.054], [64694.2, 7.942]], "asks": [[64696.7, 0.002], [64697.0, 0.003], [64697.3, 0.107], [64697.5, 0.051], [64698.5, 0.0], [64698.6, 0.125], [64699.8, 0.085], [64700.0, 0.004], [64700.7, 0.093], [64700.8, 0.593], [64701.0, 0.012], [64701.5, 0.165], [64701.7, 0.468], [64711.5, 0.0], [64712.2, 2.331], [64725.4, 0.874], [64732.8, 0.64], [64746.1, 2.859], [64890.2, 9.286], [65017.8, 4.784], [65282.4, 1.39], [65341.2, 2.523], [65694.3, 0.0], [65729.4, 4.682], [67282.1, 1.285]]}
{"kind": "depth", "E": 1787081878419, "U": 11315468997518, "u": 11315469002819, "recv_ms": 1787081878387, "bids": [[14394.2, 2.352], [14494.2, 1.848], [51755.0, 0.0], [58224.7, 0.002], [61459.6, 2.443], [62106.4, 0.692], [62733.4, 0.001], [63659.1, 5.933], [63917.9, 29.668], [63918.1, 0.001], [63924.3, 9.377], [63950.2, 7.495], [64047.3, 0.463], [64567.1, 0.014], [64630.7, 0.115], [64648.0, 1.779], [64656.4, 0.02], [64684.2, 1.039], [64685.3, 0.473], [64685.4, 0.662], [64685.5, 0.189], [64685.6, 0.001], [64685.7, 0.006], [64686.2, 0.032], [64686.6, 0.003], [64686.8, 0.004], [64687.8, 0.0], [64688.0, 0.022], [64688.3, 0.004], [64688.4, 0.148], [64689.9, 0.319], [64690.0, 0.231], [64690.4, 0.087]], "asks": [[64702.0, 1.044], [64823.7, 0.0], [64888.3, 0.002], [65151.9, 0.243], [65341.2, 2.523], [65470.6, 24.819], [65703.0, 3.224]]}
{"kind": "depth", "E": 1787081878521, "U": 11315469002980, "u": 11315469007529, "recv_ms": 1787081878490, "bids": [[1000.0, 35.81], [14394.2, 2.702], [14494.2, 1.498], [58224.7, 0.002], [61459.4, 0.001], [62106.4, 0.689], [63523.7, 3.917], [63694.2, 0.02], [63885.5, 7.983], [63989.0, 4.452], [64047.3, 0.465], [64049.5, 1.169], [64210.1, 0.0], [64370.7, 5.207], [64371.1, 1.985], [64532.5, 0.03], [64671.7, 0.462], [64672.3, 0.249], [64673.2, 0.493], [64685.3, 0.472], [64685.4, 0.63], [64686.2, 0.033], [64686.6, 0.003], [64686.8, 0.004], [64687.6, 1.017], [64687.7, 0.141], [64688.0, 0.022], [64688.3, 0.004], [64689.1, 0.727], [64694.2, 7.959]], "asks": [[64696.6, 0.086], [64700.7, 0.556], [64701.7, 0.005], [64715.3, 0.005], [64716.0, 0.258], [64861.9, 0.0], [64890.2, 9.232], [65024.1, 0.003], [65186.7, 0.026], [65341.2, 2.523], [65349.7, 0.0], [65413.9, 0.007], [65629.8, 0.003], [65694.3, 0.02], [65729.4, 5.746]]}
{"kind": "depth", "E": 1787081878623, "U": 11315469007556, "u": 11315469011549, "recv_ms": 1787081878592, "bids": [[1000.0, 35.81], [14394.2, 3.066], [14494.2, 1.134], [51755.0, 0.0], [58224.7, 0.002], [61459.4, 0.0], [62106.4, 0.692], [63626.7, 2.198], [63694.2, 0.0], [63719.1, 4.329], [63756.1, 22.208], [63804.8, 12.794], [63982.6, 1.538], [64047.3, 0.463], [64049.4, 0.008], [64210.0, 0.018], [64371.0, 0.136], [64532.4, 0.217], [64584.2, 0.378], [64616.5, 0.286], [64635.9, 0.026], [64685.4, 0.012], [64685.5, 0.189], [64686.8, 0.004], [64687.7, 0.141], [64687.8, 0.093], [64688.0, 0.579], [64689.1, 0.001]], "asks": [[64739.6, 0.003], [64804.3, 1.389], [64861.8, 0.002], [65017.8, 4.63], [65024.0, 0.008], [65186.6, 0.34], [65211.9, 9.03], [65276.6, 11.79], [65308.9, 7.611], [65341.2, 2.523], [65349.6, 0.012], [65519.8, 0.798], [65694.3, 0.0], [65697.1, 10.488], [65835.7, 0.0]]}
{"kind": "depth", "E": 1787081878725, "U": 11315469011655, "u": 11315469015319, "recv_ms": 1787081878694, "bids": [[14394.2, 3.43], [14494.2, 0.77], [51755.4, 0.0], [58224.7, 0.002], [61459.4, 0.0], [61459.5, 0.012], [61459.6, 2.445], [63497.4, 3.076], [63917.9, 31.231], [64047.3, 0.463], [64200.0, 41.243], [64535.9, 0.016], [64552.9, 0.149], [64685.4, 0.012], [64685.5, 0.189], [64685.7, 0.006], [64686.2, 0.032], [64686.6, 0.004], [64686.8, 0.004], [64687.6, 0.629], [64687.7, 0.141], [64687.8, 0.65], [64688.0, 0.022], [64688.3, 0.004], [64689.1, 0.001], [64690.0, 0.343], [64694.2, 7.959]], "asks": [[64698.6, 0.222], [64700.0, 0.295], [64700.3, 0.388], [64834.4, 0.0], [64851.4, 1.465], [65341.2, 2.523], [65410.4, 0.458]]}
{"kind": "depth", "E": 1787081878827, "U": 11315469015339, "u": 11315469019375, "recv_ms": 1787081878800, "bids": [[1000.0, 35.81], [14294.2, 0.028], [14394.2, 3.724], [14494.2, 0.448], [58224.7, 0.002], [62106.4, 0.689], [63692.7, 4.891], [63694.2, 0.02], [63885.5, 8.217], [64047.3, 0.463], [64370.7, 5.208], [64497.0, 0.18], [64497.1, 10.671], [64536.0, 4.972], [64536.3, 1.154], [64552.9, 4.915], [64657.9, 0.448], [64677.8, 0.371], [64685.3, 0.472], [64685.4, 0.646], [64686.6, 0.004], [64686.8, 0.004], [64687.8, 0.0], [64688.1, 0.154], [64688.3, 0.004], [64688.4, 0.164], [64690.0, 0.231], [64694.2, 7.956]], "asks": [[64694.9, 0.008], [64696.6, 0.086], [64697.5, 0.051], [64698.5, 0.0], [64698.6, 0.125], [64700.0, 0.004], [64700.3, 0.0], [64700.7, 0.001], [64700.8, 0.685], [64701.7, 0.468], [64710.3, 0.214], [64834.4, 5.398], [64851.2, 2.672], [64851.4, 11.873], [64890.2, 9.232], [65017.8, 4.629], [65341.2, 2.523], [65458.6, 0.063], [65464.2, 8.612], [65632.4, 19.663], [65694.3, 0.02], [65697.1, 9.424]]}
{"kind": "depth", "E": 1787081878929, "U": 11315469019422, "u": 11315469023212, "recv_ms": 1787081878897, "bids": [[1000.0, 35.81], [14294.2, 0.21], [14394.2, 3.71], [14494.2, 0.28], [58224.7, 0.002], [61459.4, 0.0], [62106.4, 0.692], [63626.7, 3.297], [63756.1, 23.304], [64047.3, 0.463], [64183.7, 0.0], [64483.3, 0.115], [64567.0, 0.116], [64661.3, 0.002], [64661.4, 1.686], [64661.5, 0.01], [64664.8, 0.084], [64664.9, 0.0], [64665.0, 0.154], [64685.3, 0.473], [64685.4, 0.662], [64685.5, 0.189], [64686.2, 0.032], [64686.6, 0.003], [64686.8, 0.392], [64687.6, 0.823], [64687.7, 0.141], [64688.3, 0.73], [64688.4, 0.148], [64691.7, 0.002]], "asks": [[65017.8, 4.783], [65211.9, 9.336], [65519.8, 0.456], [65808.3, 8.193], [67282.1, 1.272]]}
{"kind": "depth", "E": 1787081879133, "U": 11315469026870, "u": 11315469032184, "recv_ms": 1787081879102, "bids": [[1000.0, 35.81], [14294.2, 0.686], [14394.2, 3.472], [14494.2, 0.042], [51755.0, 0.0], [58224.7, 0.002], [61459.4, 0.0], [62106.4, 0.692], [63368.0, 2.448], [63400.4, 0.084], [63694.2, 0.0], [63756.1, 22.207], [64047.3, 0.463], [64150.8, 0.085], [64370.7, 5.208], [64497.1, 0.463], [64536.0, 0.031], [64536.3, 0.444], [64552.9, 0.149], [64657.9, 0.434], [64660.5, 0.019], [64682.6, 0.028], [64685.3, 0.472], [64685.4, 0.662], [64685.7, 0.007], [64686.2, 0.032], [64686.6, 0.003], [64686.8, 0.392], [64687.6, 1.017], [64687.7, 0.141], [64687.8, 0.0], [64688.0, 0.022], [64688.3, 0.004], [64688.4, 0.148], [64689.1, 0.727], [64690.0, 0.231], [64691.5, 0.001], [64694.2, 7.957]], "asks": [[64694.3, 7.636], [64695.7, 0.093], [64701.8, 2.962], [64725.5, 0.161], [64725.6, 0.346], [64834.4, 0.0], [64851.2, 1.28], [64851.4, 1.465], [64890.2, 0.003], [65336.0, 13.834], [65341.2, 2.523], [65567.7, 7.068], [65632.4, 19.663], [65694.3, 0.0], [65697.1, 10.488]]}
{"kind": "depth", "E": 1787081879235, "U": 11315469032245, "u": 11315469036072, "recv_ms": 1787081879204, "bids": [[1000.0, 35.81], [14294.2, 1.008], [14394.2, 3.192], [14494.2, 0.0], [51755.0, 0.0], [58224.7, 0.002], [61459.4, 0.0], [63788.7, 2.451], [63885.7, 0.003], [63904.6, 6.331], [64047.3, 0.463], [64497.2, 10.207], [64536.0, 4.972], [64553.0, 4.781], [64657.9, 0.434], [64660.5, 0.005], [64674.2, 0.155], [64685.4, 0.012], [64685.7, 0.006], [64686.6, 0.004], [64686.8, 0.004], [64687.6, 0.629], [64687.7, 0.529], [64687.8, 0.0], [64688.0, 0.672], [64689.1, 0.001], [64690.0, 0.232], [64694.2, 7.957]], "asks": [[64694.3, 7.622], [64697.0, 0.003], [64834.4, 5.398], [64851.4, 11.873], [64890.2, 9.232], [65284.5, 0.003], [65341.2, 2.523], [65632.4, 18.598]]}
{"kind": "depth", "E": 1787081879337, "U": 11315469036160, "u": 11315469039443, "recv_ms": 1787081879305, "bids": [[14294.2, 1.358], [14394.2, 2.842], [58224.7, 0.002], [62106.4, 0.689], [63694.2, 0.02], [63918.0, 8.562], [63988.3, 7.89], [64047.3, 0.463], [64176.6, 8.866], [64577.1, 0.001], [64577.2, 3.865], [64621.4, 0.002], [64621.5, 0.046], [64626.2, 0.0], [64626.6, 2.451], [64636.3, 0.009], [64645.1, 0.027], [64685.4, 0.662], [64688.0, 0.022], [64688.3, 0.004], [64688.4, 0.148], [64688.5, 0.085]], "asks": [[64696.6, 0.086], [64760.1, 2.957], [64763.8, 0.0], [64763.9, 0.046], [64828.0, 1.055], [64828.1, 3.867], [65017.8, 4.782], [65211.9, 8.417], [65308.9, 8.298], [65470.6, 22.989], [65694.3, 0.02]]}
{"kind": "depth", "E": 1787081879439, "U": 11315469039478, "u": 11315469044791, "recv_ms": 1787081879408, "bids": [[1000.0, 35.81], [14294.2, 1.722], [14394.2, 2.478], [58224.7, 0.002], [62106.4, 0.692], [63756.1, 23.304], [63788.5, 12.589], [64047.2, 0.026], [64047.3, 0.463], [64370.7, 5.209], [64553.0, 4.781], [64627.3, 0.0], [64627.6, 0.0], [64627.9, 0.0], [64628.3, 0.0], [64628.9, 0.147], [64646.4, 6.038], [64646.7, 0.151], [64647.0, 0.001], [64647.4, 0.007], [64648.0, 1.747], [64648.4, 0.495], [64661.6, 0.002], [64661.7, 0.001], [64661.8, 0.003], [64661.9, 0.623], [64662.0, 0.039], [64662.1, 2.019], [64662.3, 0.021], [64662.4, 0.006], [64662.6, 0.0], [64665.0, 0.054], [64665.4, 0.002], [64683.6, 0.003], [64683.7, 0.004], [64683.8, 0.06], [64683.9, 3.317], [64684.0, 2.356], [64684.1, 1.173], [64684.2, 0.869], [64684.3, 0.371], [64684.4, 0.097], [64684.5, 0.058], [64684.6, 0.005], [64684.7, 0.382], [64684.8, 0.012], [64685.2, 1.902], [64685.4, 0.695], [64685.5, 0.157], [64685.8, 0.151], [64686.2, 0.0], [64686.6, 0.003]], "asks": [[64701.6, 0.001], [64702.0, 1.006], [64702.3, 0.006], [64702.4, 0.047], [64702.7, 0.004], [64703.0, 2.755], [64703.2, 0.004], [64703.3, 0.092], [64703.4, 1.373], [64703.5, 0.538], [64703.7, 0.0], [64703.8, 0.001], [64703.9, 0.011], [64704.0, 0.401], [64704.1, 0.01], [64704.2, 1.055], [64720.7, 0.01], [64720.8, 2.365], [64721.2, 0.238], [64721.6, 1.096], [64721.9, 0.001], [64722.2, 0.006], [64722.4, 0.002], [64722.9, 0.665], [64723.8, 0.098], [64724.1, 0.095], [64725.2, 0.004], [64725.4, 0.79], [64725.5, 0.001], [64725.6, 0.156], [64725.7, 0.004], [64725.8, 0.003], [64725.9, 0.062], [64726.0, 0.005], [64726.2, 2.321], [64726.3, 0.002], [64726.4, 0.006], [64726.5, 0.09], [64739.8, 0.074], [64740.5, 0.0], [64740.8, 1.207], [64741.1, 0.125], [64741.4, 0.059], [64823.7, 0.0], [64834.4, 5.398], [65211.9, 8.111], [65341.2, 2.523], [65470.6, 24.819], [65632.4, 20.728]]}
{"kind": "depth", "E": 1787081879541, "U": 11315469044876, "u": 11315469050804, "recv_ms": 1787081879513, "bids": [[1000.0, 35.81], [14294.2, 2.086], [14394.2, 2.114], [58224.7, 0.002], [62106.4, 0.689], [63694.2, 0.0], [63982.5, 0.495], [63988.3, 7.656], [64047.3, 0.463], [64176.6, 9.8], [64487.1, 0.001], [64489.0, 0.152], [64497.3, 0.0], [64499.1, 0.006], [64507.5, 0.015], [64517.7, 0.005], [64527.9, 2.522], [64538.1, 0.0], [64548.3, 0.0], [64558.5, 2.325], [64568.7, 0.337], [64578.9, 0.002], [64589.1, 0.0], [64599.3, 0.001], [64609.5, 0.026], [64619.7, 0.244], [64629.9, 0.0], [64636.3, 0.005], [64640.1, 0.013], [64645.5, 0.006], [64649.4, 0.127], [64650.3, 0.001], [64660.5, 0.0], [64670.7, 0.204], [64684.2, 0.939], [64684.4, 0.167], [64686.4, 0.093]], "asks": [[64696.6, 0.106], [64700.7, 0.464], [64701.4, 0.288], [64701.7, 0.005], [64703.4, 1.478], [64703.6, 0.095], [64709.5, 0.025], [64709.6, 0.783], [64719.6, 0.007], [64719.8, 0.013], [64719.9, 0.039], [64724.2, 0.107], [64724.4, 0.474], [64730.0, 0.004], [64740.2, 0.411], [64750.4, 1.249], [64760.6, 0.03], [64770.8, 0.04], [64781.0, 0.0], [64791.2, 0.004], [64801.4, 0.0], [64811.6, 0.116], [64821.8, 0.001], [64832.0, 2.342], [64842.2, 0.001], [64852.4, 0.002], [64862.6, 0.028], [64872.8, 0.001], [64883.0, 0.067], [64893.2, 0.004], [65211.9, 9.03], [65281.0, 0.231], [65285.0, 1.136], [65341.2, 2.523], [65694.3, 0.0], [67282.1, 1.908]]}
{"kind": "depth", "E": 1787081879745, "U": 11315469057221, "u": 11315469060868, "recv_ms": 1787081879714, "bids": [[1000.0, 35.81], [14294.2, 2.8], [14394.2, 1.4], [51755.0, 0.0], [51755.4, 0.0], [58224.7, 0.002], [61459.4, 0.0], [63694.2, 0.02], [63901.9, 2.734], [64047.3, 0.463], [64519.3, 0.007], [64529.4, 0.023], [64629.9, 0.032], [64649.1, 1.567], [64684.2, 1.009], [64684.4, 0.237], [64684.6, 0.205], [64684.7, 0.482], [64685.1, 0.07], [64685.3, 0.472], [64685.4, 0.052], [64686.0, 0.035], [64686.6, 0.004], [64686.8, 0.392], [64687.5, 0.005], [64687.6, 0.629], [64687.7, 1.682], [64687.8, 0.077], [64688.0, 0.022], [64688.3, 0.561], [64689.1, 0.727], [64690.0, 0.004], [64690.3, 0.591], [64694.2, 7.957]], "asks": [[64694.3, 7.624], [64696.6, 0.106], [64701.7, 0.047], [64702.6, 0.113], [64703.1, 0.303], [64703.2, 0.314], [64703.4, 1.597], [64703.5, 0.741], [64720.2, 0.65], [64721.7, 0.173], [64723.4, 2.033], [64723.9, 0.61], [64724.2, 0.226], [64724.3, 0.205], [64739.3, 0.046], [64739.8, 0.079], [64749.9, 0.007], [65281.3, 0.24], [65341.2, 2.523], [65487.4, 1.16], [65604.3, 3.644], [65694.3, 0.02], [65728.7, 0.002]]}
{"kind": "depth", "E": 1787081879949, "U": 11315469064361, "u": 11315469068376, "recv_ms": 1787081879918, "bids": [[14294.2, 3.5], [14394.2, 0.7], [58224.7, 0.002], [62106.4, 0.692], [63694.2, 0.0], [63885.5, 8.568], [64047.3, 0.463], [64370.7, 5.208], [64549.6, 0.005], [64559.7, 0.014], [64630.3, 0.055], [64635.9, 0.026], [64663.4, 0.074], [64663.6, 0.072], [64674.5, 5.376], [64686.8, 0.392], [64689.1, 0.727], [64694.0, 0.067]], "asks": [[64696.6, 0.106], [64701.0, 0.044], [64739.0, 0.045], [64739.6, 0.003], [64770.1, 0.648], [64780.2, 0.005], [65341.2, 2.523], [65619.6, 2.922], [65694.3, 0.0], [65988.1, 0.015]]}
{"kind": "depth", "E": 1787081880051, "U": 11315469068426, "u": 11315469074298, "recv_ms": 1787081880061, "bids": [[1000.0, 35.81], [14194.2, 0.056], [14294.2, 3.752], [14394.2, 0.392], [58224.7, 0.002], [61459.4, 0.0], [62106.4, 0.689], [63694.2, 0.02], [63740.1, 0.706], [64047.3, 0.463], [64497.2, 9.647], [64536.0, 3.652], [64536.3, 0.957], [64553.0, 4.119], [64560.8, 0.657], [64569.8, 0.005], [64616.5, 0.289], [64630.6, 0.032], [64642.4, 1.645], [64645.9, 0.004], [64646.0, 1.934], [64659.9, 0.002], [64660.5, 0.057], [64661.3, 0.004], [64661.4, 1.688], [64661.5, 0.012], [64662.5, 0.0], [64663.5, 0.071], [64663.7, 1.173], [64663.8, 0.102], [64664.0, 1.709], [64664.1, 2.42], [64664.2, 0.241], [64664.8, 0.086], [64664.9, 0.002], [64665.0, 0.056], [64666.4, 0.002], [64666.5, 0.574], [64667.5, 0.523], [64668.8, 0.033], [64670.7, 0.358], [64670.8, 0.002], [64672.1, 0.297], [64675.4, 0.347], [64675.6, 0.015], [64676.0, 0.802], [64676.6, 0.926], [64677.1, 0.161], [64679.4, 0.001], [64680.5, 0.011], [64682.6, 0.033], [64682.7, 0.156], [64683.9, 3.626], [64685.4, 0.037], [64686.8, 0.004], [64687.7, 1.294], [64687.8, 0.618], [64688.0, 0.022], [64688.3, 0.02], [64688.4, 0.163], [64688.5, 0.085], [64689.1, 0.001], [64691.6, 0.024], [64692.5, 0.019]], "asks": [[64694.3, 7.63], [64696.7, 0.024], [64696.9, 0.025], [64700.5, 0.544], [64700.8, 0.144], [64702.0, 1.051], [64709.1, 0.929], [64709.3, 0.501], [64709.6, 0.937], [64711.5, 0.556], [64712.2, 1.775], [64712.3, 0.215], [64712.5, 0.002], [64712.8, 0.002], [64714.0, 0.547], [64714.6, 0.223], [64715.4, 0.241], [64716.0, 0.143], [64716.1, 0.656], [64718.9, 0.222], [64719.1, 0.016], [64719.8, 0.017], [64722.7, 0.154], [64725.4, 0.622], [64738.7, 0.044], [64742.9, 0.164], [64790.3, 0.005], [64791.4, 0.103], [64804.3, 1.392], [64834.4, 5.398], [64851.2, 2.671], [64851.4, 11.873], [64890.2, 11.71], [65341.2, 2.523], [65694.3, 0.02]]}
{"kind": "depth", "E": 1787081880153, "U": 11315469074430, "u": 11315469080097, "recv_ms": 1787081880127, "bids": [[1000.0, 35.81], [14194.2, 0.266], [14294.2, 3.682], [14394.2, 0.252], [51755.0, 0.048], [58224.7, 0.002], [58224.8, 0.051], [63659.1, 4.835], [63700.9, 0.012], [63701.0, 1.41], [63723.8, 11.726], [63765.6, 0.03], [63767.9, 0.002], [63768.0, 0.046], [64047.3, 0.465], [64406.6, 0.023], [64451.9, 0.04], [64574.3, 0.66], [64579.9, 0.005], [64590.0, 0.863], [64591.1, 0.069], [64628.8, 3.731], [64654.3, 0.002], [64654.5, 0.062], [64661.5, 0.085], [64663.4, 0.144], [64663.6, 0.142], [64663.9, 0.101], [64664.3, 0.44], [64666.1, 0.132], [64682.6, 0.028], [64685.4, 0.037], [64686.8, 0.004], [64687.7, 1.294], [64687.8, 0.0], [64688.0, 0.022], [64688.3, 0.096], [64688.4, 0.689], [64688.6, 0.002], [64688.7, 0.005], [64689.1, 0.004], [64690.0, 0.003], [64690.1, 0.004], [64690.3, 0.232], [64690.4, 0.087], [64690.5, 0.409], [64690.9, 0.003], [64691.8, 0.023], [64691.9, 0.003], [64694.2, 7.971]], "asks": [[64694.3, 7.31], [64696.6, 0.106], [64696.9, 0.022], [64698.5, 0.618], [64698.6, 0.132], [64700.0, 0.004], [64700.5, 0.003], [64700.7, 0.001], [64700.8, 0.052], [64701.7, 0.51], [64702.0, 0.151], [64723.7, 4.179], [64724.1, 0.093], [64725.4, 0.004], [64728.5, 1.246], [64732.8, 0.022], [64734.5, 0.074], [64735.8, 0.618], [64748.8, 0.035], [64749.2, 0.001], [64757.9, 0.162], [64758.3, 0.061], [64772.4, 0.292], [64800.4, 0.005], [64810.5, 0.005], [64835.5, 0.278], [65341.2, 2.523], [65519.8, 0.114], [65620.5, 0.002], [65622.8, 0.0], [65687.5, 0.022], [65729.4, 4.682], [65761.8, 1.245]]}
{"kind": "depth", "E": 1787081880255, "U": 11315469080119, "u": 11315469088506, "recv_ms": 1787081880224, "bids": [[14194.2, 0.504], [14294.2, 3.57], [14394.2, 0.126], [51755.0, 0.006], [58224.7, 0.002], [61459.4, 0.0], [62106.4, 0.692], [63788.5, 12.777], [64047.3, 0.463], [64370.7, 5.198], [64574.3, 0.38], [64600.1, 0.155], [64628.8, 3.563], [64629.5, 0.039], [64650.4, 2.139], [64660.2, 0.698], [64660.5, 0.0], [64661.4, 1.663], [64661.5, 0.012], [64664.4, 0.548], [64671.8, 0.001], [64676.4, 0.959], [64676.6, 0.0], [64685.4, 0.037], [64686.6, 0.003], [64686.7, 1.936], [64686.8, 0.004], [64687.7, 1.294], [64687.8, 0.0], [64688.0, 0.099], [64688.3, 0.019], [64688.4, 0.148], [64688.5, 0.101], [64688.6, 0.002], [64689.1, 0.004], [64689.2, 0.627], [64690.6, 0.001], [64691.2, 0.006], [64691.7, 0.086], [64691.9, 0.022]], "asks": [[64694.3, 7.446], [64695.7, 0.009], [64698.5, 0.0], [64698.6, 0.125], [64700.8, 0.677], [64708.8, 1.539], [64709.1, 0.004], [64718.1, 0.067], [64722.2, 0.031], [64725.9, 0.002], [64728.5, 0.628], [64730.9, 0.004], [64734.5, 0.002], [64759.0, 0.312], [64772.4, 0.125], [64820.6, 0.382], [64835.5, 0.0], [65341.2, 2.523], [65620.6, 1.53], [65622.9, 0.008], [65687.6, 0.036]]}
{"kind": "depth", "E": 1787081880357, "U": 11315469088572, "u": 11315469095954, "recv_ms": 1787081880325, "bids": [[1000.0, 35.81], [14194.2, 0.742], [14294.2, 3.444], [14394.2, 0.014], [51755.0, 0.0], [58224.7, 0.002], [61459.4, 0.0], [62106.4, 0.689], [62106.5, 0.006], [63659.1, 5.933], [63691.4, 6.592], [63694.2, 0.0], [63901.9, 2.5], [63917.9, 29.356], [64047.3, 0.463], [64610.2, 0.149], [64620.3, 2.324], [64648.0, 1.687], [64655.3, 2.914], [64685.4, 0.061], [64685.7, 0.038], [64686.2, 0.0], [64686.6, 0.004], [64686.7, 1.935], [64686.8, 0.004], [64687.7, 1.294], [64687.8, 0.0], [64688.0, 0.647], [64688.3, 0.004], [64688.5, 0.085], [64689.1, 0.004], [64689.2, 0.086], [64690.5, 0.271], [64694.2, 7.971]], "asks": [[64694.3, 7.456], [64700.3, 0.0], [64701.0, 0.944], [64823.7, 0.001], [64830.7, 0.006], [64840.8, 0.226], [65341.2, 2.523], [65438.8, 5.448], [65503.0, 7.543], [65560.8, 0.042], [65613.0, 2.601], [65694.3, 0.0], [65729.4, 5.746], [65761.8, 2.308]]}
{"kind": "depth", "E": 1787081880459, "U": 11315469096016, "u": 11315469104913, "recv_ms": 1787081880430, "bids": [[1000.0, 35.81], [14194.2, 1.092], [14294.2, 3.108], [14394.2, 0.0], [58224.7, 0.002], [61459.6, 2.443], [62106.4, 0.692], [63466.0, 0.145], [63756.1, 22.521], [63963.8, 2.658], [64047.2, 0.025], [64047.3, 0.463], [64176.6, 9.489], [64370.7, 5.042], [64574.3, 0.38], [64628.7, 0.104], [64628.8, 3.563], [64630.4, 2.349], [64661.4, 1.663], [64661.5, 0.012], [64685.3, 0.464], [64685.4, 0.045], [64685.5, 0.234], [64685.6, 0.001], [64686.2, 0.0], [64686.6, 0.004], [64686.8, 0.004], [64687.7, 1.294], [64687.8, 0.548], [64688.0, 0.054], [64688.3, 0.004], [64688.4, 0.148], [64688.5, 0.085], [64689.1, 0.004]], "asks": [[64696.6, 0.106], [64700.7, 0.017], [64700.8, 0.669], [64701.0, 0.044], [64734.4, 1.544], [64734.5, 0.002], [64772.3, 0.014], [64823.7, 0.0], [64835.5, 0.0], [64850.9, 0.056], [65341.2, 2.523], [65603.3, 0.188]]}
