{"kind": "depth", "E": 1787081837007, "U": 11315465949439, "u": 11315465955523, "recv_ms": 1787081837003, "bids": [[14290.2, 0.392], [14390.2, 3.626], [14490.2, 0.182], [58221.1, 0.002], [62102.5, 0.004], [63103.0, 1.979], [63396.4, 0.018], [63690.2, 0.02], [64043.3, 0.018], [64346.5, 0.004], [64347.7, 0.492], [64366.7, 2.329], [64549.3, 5.001], [64669.7, 0.695], [64677.1, 0.336], [64678.5, 0.503], [64684.2, 0.057], [64684.8, 0.628], [64685.1, 0.0], [64685.2, 0.078], [64685.3, 0.55], [64685.6, 0.086], [64685.7, 0.163], [64690.2, 29.745]], "asks": [[64690.3, 3.345], [64693.5, 0.009], [64713.4, 0.382], [64721.0, 0.64], [64728.4, 0.62], [64765.4, 0.026], [64800.3, 0.398], [64829.9, 5.399], [64885.7, 9.461], [65337.2, 0.005], [65499.6, 8.316], [65503.7, 0.01], [65563.6, 8.045], [65629.5, 0.0], [65690.3, 0.02], [65988.2, 0.005]]}
{"kind": "depth", "E": 1787081837109, "U": 11315465955547, "u": 11315465962260, "recv_ms": 1787081837077, "bids": [[1000.0, 35.81], [14290.2, 0.63], [14390.2, 3.5], [14490.2, 0.07], [51752.0, 0.0], [51752.2, 0.002], [58221.1, 0.002], [61455.6, 0.0], [63771.6, 0.234], [63825.6, 0.782], [64043.3, 0.016], [64493.5, 1.807], [64495.8, 1.45], [64604.4, 0.011], [64611.3, 1.048], [64647.7, 0.005], [64669.7, 0.077], [64671.6, 0.156], [64678.5, 0.04], [64678.6, 0.002], [64678.9, 0.001], [64684.2, 0.073], [64684.9, 0.589], [64685.1, 0.541], [64685.2, 0.001], [64685.3, 0.009], [64685.7, 0.167], [64686.9, 0.495], [64690.2, 28.049]], "asks": [[64690.3, 3.346], [64693.1, 0.012], [64721.0, 0.022], [64728.4, 0.002], [64728.9, 0.405], [64885.7, 15.413], [65337.2, 0.003], [65481.1, 11.18], [65914.4, 0.0]]}
{"kind": "depth", "E": 1787081837211, "U": 11315465962571, "u": 11315465969767, "recv_ms": 1787081837181, "bids": [[1000.0, 35.81], [14290.2, 0.924], [14390.2, 3.276], [14490.2, 0.0], [51752.0, 0.0], [51752.2, 0.0], [58221.1, 0.002], [61455.6, 0.0], [62102.5, 0.001], [63072.9, 0.581], [63690.2, 0.0], [64043.3, 0.016], [64493.5, 10.42], [64495.8, 2.66], [64573.3, 0.003], [64611.2, 0.002], [64618.6, 0.004], [64627.8, 0.038], [64628.0, 0.011], [64638.3, 0.001], [64638.4, 1.065], [64638.5, 2.827], [64638.6, 0.373], [64641.4, 0.003], [64659.3, 0.319], [64659.8, 0.005], [64660.5, 0.0], [64671.1, 0.116], [64671.6, 0.002], [64671.9, 0.001], [64675.4, 1.926], [64675.9, 0.003], [64681.7, 0.542], [64684.2, 0.073], [64685.7, 0.167], [64690.2, 28.03]], "asks": [[64693.1, 0.014], [64693.4, 0.003], [64697.0, 0.089], [64701.6, 0.001], [64733.5, 0.021], [64771.4, 0.098], [64804.3, 1.389], [64834.5, 0.158], [64885.7, 9.39], [64896.9, 0.003], [64897.0, 0.017], [65337.2, 0.003], [65690.3, 0.0], [65984.1, 0.03]]}
{"kind": "depth", "E": 1787081837415, "U": 11315465975907, "u": 11315465981419, "recv_ms": 1787081837395, "bids": [[1000.0, 35.81], [14290.2, 1.638], [14390.2, 2.562], [58221.1, 0.002], [61455.6, 0.0], [62102.5, 0.001], [64043.3, 0.018], [64111.3, 0.016], [64115.3, 0.025], [64671.5, 0.198], [64684.2, 0.065], [64685.2, 0.009], [64685.7, 0.163], [64690.2, 28.047]], "asks": [[64690.3, 3.35], [64693.1, 0.004], [64693.4, 0.003], [64819.7, 0.001], [64885.7, 9.567], [65111.5, 0.008], [65115.7, 0.0], [65274.3, 0.025], [65278.5, 0.0], [65337.2, 0.003], [65466.6, 14.597], [65563.6, 8.654], [65887.1, 0.984]]}
{"kind": "depth", "E": 1787081837517, "U": 11315465981486, "u": 11315465986728, "recv_ms": 1787081837487, "bids": [[1000.0, 35.81], [14290.2, 2.002], [14390.2, 2.198], [51752.0, 0.002], [58221.1, 0.002], [62102.5, 0.004], [63567.9, 0.0], [63690.2, 0.02], [64043.3, 0.016], [64271.5, 0.01], [64275.6, 0.001], [64432.2, 0.018], [64436.3, 0.019], [64549.3, 5.001], [64593.3, 0.099], [64597.4, 0.379], [64673.8, 0.002], [64674.0, 0.556], [64678.1, 0.0], [64681.7, 0.542], [64684.2, 0.065], [64685.7, 0.167], [64690.2, 28.046]], "asks": [[64693.1, 0.004], [64706.3, 0.003], [64722.5, 0.002], [64722.9, 0.819], [64746.0, 2.009], [64766.3, 1.59], [64787.2, 0.472], [64791.3, 0.029], [64829.9, 5.399], [64885.7, 9.563], [64949.2, 0.012], [64953.3, 0.006], [65337.2, 0.003], [65690.3, 0.02]]}
{"kind": "depth", "E": 1787081837619, "U": 11315465986794, "u": 11315465992890, "recv_ms": 1787081837586, "bids": [[14290.2, 2.352], [14390.2, 1.848], [51752.0, 0.0], [58221.1, 0.002], [61455.6, 0.0], [63400.5, 0.003], [63515.4, 0.786], [63752.2, 1.119], [64043.3, 0.016], [64187.3, 0.0], [64366.7, 2.338], [64584.1, 2.396], [64588.9, 0.0], [64673.8, 0.004], [64685.7, 0.167], [64690.2, 28.046]], "asks": [[64690.3, 3.342], [64693.1, 0.004], [64693.4, 0.003], [64700.4, 0.045], [64706.3, 0.005], [64801.7, 8.22], [64802.8, 0.0], [65013.8, 2.539], [65337.2, 0.003], [65412.3, 0.764], [65508.9, 3.533], [66413.7, 0.192]]}
{"kind": "depth", "E": 1787081837721, "U": 11315465993014, "u": 11315465998277, "recv_ms": 1787081837689, "bids": [[1000.0, 35.81], [14290.2, 2.716], [14390.2, 1.484], [51752.0, 0.0], [58221.1, 0.002], [61455.6, 0.0], [61455.7, 0.01], [61455.8, 0.002], [62102.5, 0.001], [63690.2, 0.0], [63891.2, 5.016], [64043.3, 0.016], [64366.7, 2.339], [64657.9, 0.412], [64658.0, 2.131], [64658.5, 0.27], [64659.3, 0.262], [64669.1, 0.562], [64670.1, 0.005], [64674.6, 1.284], [64675.4, 1.0], [64685.7, 0.167], [64690.1, 0.191], [64690.2, 28.047]], "asks": [[64698.3, 0.004], [64707.1, 0.024], [64708.0, 1.83], [64708.8, 0.047], [64710.5, 0.0], [64711.3, 0.062], [64712.0, 2.159], [64751.7, 0.074], [64751.8, 0.063], [64804.3, 1.389], [64805.8, 0.011], [64885.7, 9.458], [65212.8, 0.004], [65337.2, 0.003], [65690.3, 0.0], [66069.8, 0.005], [68571.7, 0.018]]}
{"kind": "depth", "E": 1787081837823, "U": 11315465998281, "u": 11315466004953, "recv_ms": 1787081837792, "bids": [[1000.0, 35.81], [14290.2, 3.066], [14390.2, 1.134], [58221.1, 0.002], [62102.5, 0.004], [64043.3, 0.016], [64186.9, 1.552], [64381.0, 2.491], [64504.3, 0.019], [64532.1, 0.0], [64669.1, 0.005], [64670.1, 0.562], [64680.4, 0.019]], "asks": [[65028.1, 0.77], [65337.2, 0.003], [65481.1, 10.494], [70512.4, 0.018]]}
{"kind": "depth", "E": 1787081837925, "U": 11315466005107, "u": 11315466013404, "recv_ms": 1787081837895, "bids": [[14290.2, 3.416], [14390.2, 0.784], [58221.1, 0.002], [61455.6, 0.0], [62102.5, 0.001], [63396.4, 0.021], [63690.2, 0.02], [63800.5, 4.352], [64043.3, 0.016], [64177.6, 4.669], [64347.7, 0.0], [64348.5, 0.493], [64366.7, 2.339], [64536.4, 0.0], [64536.5, 0.245], [64549.3, 0.027], [64685.7, 0.167], [64690.2, 28.046]], "asks": [[64693.4, 0.003], [64722.9, 0.819], [64829.9, 0.0], [64844.8, 1.22], [64847.4, 0.0], [65202.9, 4.594], [65337.2, 0.003], [65478.1, 0.0], [65690.3, 0.02], [67277.9, 0.64]]}
{"kind": "depth", "E": 1787081838129, "U": 11315466019240, "u": 11315466032048, "recv_ms": 1787081838104, "bids": [[1000.0, 35.81], [14190.2, 0.21], [14290.2, 3.71], [14390.2, 0.28], [51752.2, 0.0], [58221.1, 0.002], [61455.6, 0.001], [63690.2, 0.0], [63701.1, 0.0], [63765.8, 0.0], [63969.0, 0.787], [64043.3, 0.016], [64146.8, 0.382], [64172.7, 4.2], [64366.7, 2.494], [64424.0, 4.565], [64425.6, 0.947], [64604.4, 0.012], [64611.2, 0.004], [64618.6, 0.006], [64641.4, 0.004], [64647.7, 0.006], [64669.8, 0.624], [64677.1, 0.954], [64678.6, 0.002], [64685.7, 0.163]], "asks": [[64690.3, 3.33], [64693.4, 0.003], [64696.1, 0.473], [64699.5, 0.021], [64699.8, 0.1], [64700.4, 0.022], [64704.6, 0.692], [64719.2, 0.002], [64719.3, 0.051], [64719.4, 0.473], [64721.1, 0.62], [64722.2, 0.006], [64722.3, 0.442], [64722.4, 0.0], [64722.8, 0.155], [64722.9, 0.665], [64723.0, 0.003], [64723.1, 0.312], [64723.2, 0.244], [64725.3, 0.317], [64725.4, 0.004], [64725.5, 0.001], [64728.4, 0.62], [64805.8, 1.912], [64829.9, 0.0], [64830.5, 3.76], [64844.8, 2.619], [64846.9, 0.0], [64847.4, 6.542], [65013.8, 2.693], [65337.2, 0.005], [65466.6, 16.808], [65623.0, 0.152], [65687.7, 0.143], [65690.3, 0.0]]}
{"kind": "depth", "E": 1787081838231, "U": 11315466032156, "u": 11315466042511, "recv_ms": 1787081838199, "bids": [[14190.2, 0.448], [14290.2, 3.598], [14390.2, 0.154], [58221.1, 0.002], [61455.6, 0.0], [62102.5, 0.001], [63697.1, 0.667], [63761.6, 0.008], [63768.1, 0.783], [63784.5, 5.073], [64043.3, 0.016], [64094.5, 1.33], [64366.7, 2.494], [64611.2, 0.006], [64638.3, 0.003], [64641.4, 0.005], [64647.7, 0.007], [64677.1, 0.336], [64678.5, 0.04], [64684.2, 0.065], [64684.9, 0.504], [64685.1, 0.634], [64685.2, 0.001], [64685.3, 0.009], [64685.7, 0.163], [64690.2, 27.948]], "asks": [[64693.1, 0.004], [64696.8, 0.01], [64699.8, 0.099], [64700.0, 0.966], [64703.8, 0.062], [64703.9, 0.011], [64704.1, 0.045], [64706.9, 0.025], [64707.1, 0.571], [64710.2, 0.556], [64710.8, 2.354], [64714.1, 1.314], [64714.8, 0.001], [64722.8, 0.001], [64805.8, 0.011], [64829.9, 0.0], [64830.5, 3.77], [64846.9, 0.0], [64847.4, 6.566], [65337.2, 0.003], [65618.9, 0.013], [65620.7, 14.02]]}
{"kind": "depth", "E": 1787081838333, "U": 11315466042782, "u": 11315466051122, "recv_ms": 1787081838301, "bids": [[1000.0, 35.81], [14190.2, 0.686], [14290.2, 3.472], [14390.2, 0.042], [51752.0, 0.0], [58221.1, 0.002], [61455.6, 0.001], [62102.5, 0.004], [63590.5, 1.181], [63690.2, 0.02], [64043.3, 0.016], [64685.7, 0.167], [64690.2, 27.949]], "asks": [[64693.4, 0.003], [64702.8, 0.034], [64703.9, 0.011], [64704.1, 0.045], [64706.9, 0.109], [64707.1, 0.487], [64722.5, 0.002], [64722.7, 0.0], [64829.9, 5.399], [64830.5, 0.001], [64846.9, 10.409], [64847.4, 0.0], [65013.8, 2.692], [65337.2, 0.003], [65414.8, 0.008], [65683.5, 0.035], [65690.3, 0.02]]}
{"kind": "depth", "E": 1787081838435, "U": 11315466051136, "u": 11315466058834, "recv_ms": 1787081838403, "bids": [[1000.0, 35.81], [14190.2, 1.008], [14290.2, 3.192], [14390.2, 0.0], [58221.1, 0.002], [61455.6, 0.0], [62102.5, 0.001], [63400.5, 0.0], [63709.4, 3.584], [63764.0, 0.064], [64043.3, 0.016], [64664.3, 0.378]], "asks": [[64703.9, 0.011], [64704.1, 0.069], [64706.9, 0.085], [64722.7, 0.0], [64805.8, 1.912], [64819.7, 0.001], [64885.7, 9.458], [65337.2, 0.003], [65984.1, 0.027]]}
{"kind": "depth", "E": 1787081838537, "U": 11315466058996, "u": 11315466067981, "recv_ms": 1787081838505, "bids": [[14190.2, 1.358], [14290.2, 2.842], [58221.1, 0.002], [63690.2, 0.0], [64043.3, 0.087], [64366.7, 2.495], [64573.4, 0.0], [64596.6, 0.002], [64603.0, 0.238], [64605.7, 0.009], [64605.8, 0.028], [64611.0, 7.354], [64617.6, 6.316], [64623.4, 1.922], [64624.1, 0.001], [64627.9, 1.982], [64628.0, 0.002], [64630.6, 0.0], [64637.0, 0.067], [64643.5, 0.08], [64650.0, 3.93], [64656.5, 0.186], [64657.3, 0.273], [64657.4, 0.003], [64657.5, 0.453], [64660.6, 0.001], [64660.8, 1.186], [64660.9, 3.559], [64661.0, 0.026], [64662.9, 0.007], [64669.4, 0.105], [64673.8, 0.002], [64675.9, 0.0], [64677.2, 1.043], [64682.4, 0.071], [64684.8, 1.308], [64685.7, 0.163], [64688.8, 0.088], [64690.1, 0.292], [64690.2, 27.949]], "asks": [[64690.3, 3.314], [64693.4, 0.003], [64694.7, 4.069], [64696.2, 0.003], [64696.8, 0.002], [64700.2, 0.493], [64703.9, 0.011], [64704.1, 0.045], [64704.6, 0.689], [64706.3, 0.003], [64706.9, 0.093], [64710.7, 1.903], [64712.2, 1.775], [64714.2, 0.001], [64717.7, 0.003], [64721.2, 0.238], [64722.8, 0.001], [64727.1, 0.4], [64733.6, 0.165], [64740.0, 1.114], [64744.7, 0.231], [64746.5, 0.061], [64747.3, 0.001], [64753.0, 1.593], [64759.5, 6.545], [64762.8, 6.432], [64765.9, 0.0], [64771.4, 0.098], [64771.5, 0.011], [64772.4, 0.125], [64778.9, 0.003], [64796.0, 0.024], [64805.8, 0.011], [64834.6, 0.023], [64885.7, 9.563], [64896.8, 0.003], [64896.9, 0.0], [65337.2, 0.003], [65616.6, 0.008], [65690.3, 0.0], [65808.4, 1.818]]}
{"kind": "depth", "E": 1787081838639, "U": 11315466067984, "u": 11315466077324, "recv_ms": 1787081838607, "bids": [[1000.0, 35.81], [14190.2, 1.722], [14290.2, 2.478], [51752.0, 0.0], [58221.1, 0.002], [61455.6, 0.0], [62102.5, 0.004], [63968.2, 1.562], [64043.3, 0.085], [64146.8, 0.353], [64493.5, 10.061], [64532.3, 4.802], [64549.2, 4.836], [64549.3, 0.027], [64623.7, 2.836], [64627.9, 0.005], [64673.8, 0.004], [64684.8, 0.628], [64685.7, 0.163], [64690.2, 27.949]], "asks": [[64694.6, 1.27], [64694.8, 0.004], [64696.1, 0.155], [64697.0, 0.005], [64697.4, 0.003], [64697.7, 0.09], [64699.6, 0.025], [64701.6, 0.016], [64704.1, 0.085], [64704.6, 0.68], [64706.3, 0.005], [64706.9, 0.085], [64708.5, 0.004], [64721.1, 1.249], [64722.9, 0.819], [64756.1, 2.999], [64761.0, 0.023], [64763.5, 0.0], [64767.9, 32.796], [64879.2, 0.004], [64885.7, 10.066], [65222.2, 1.266], [65337.2, 0.003], [65984.1, 0.03]]}
{"kind": "depth", "E": 1787081838741, "U": 11315466077449, "u": 11315466084487, "recv_ms": 1787081838708, "bids": [[1000.0, 35.81], [14190.2, 2.072], [14290.2, 2.128], [58221.1, 0.002], [62102.5, 0.001], [63690.2, 0.02], [64043.3, 0.085], [64366.7, 2.494], [64573.4, 0.28], [64627.9, 0.173], [64660.6, 0.074], [64669.1, 0.562], [64670.1, 0.005], [64670.7, 0.288], [64671.1, 0.0], [64678.5, 0.048], [64685.1, 0.626]], "asks": [[64700.2, 0.47], [64712.1, 0.001], [64713.4, 0.923], [64714.0, 0.008], [64733.6, 0.238], [64762.8, 1.51], [64765.4, 0.035], [64771.5, 0.18], [64834.6, 0.305], [65337.2, 0.003], [65690.3, 0.02], [65984.1, 0.027], [67019.2, 0.029]]}
{"kind": "depth", "E": 1787081838843, "U": 11315466084735, "u": 11315466092892, "recv_ms": 1787081838811, "bids": [[14190.2, 2.436], [14290.2, 1.764], [58221.1, 0.002], [61455.6, 0.0], [61459.7, 0.002], [62102.5, 0.004], [63774.3, 0.802], [64043.3, 0.085], [64366.7, 2.494], [64573.4, 0.0], [64627.9, 0.005], [64660.6, 0.001], [64669.1, 0.005], [64670.1, 0.562], [64685.7, 0.167], [64690.2, 27.953]], "asks": [[64693.4, 0.003], [64733.6, 0.165], [64771.5, 0.011], [64834.6, 0.023], [65013.8, 2.693], [65207.8, 5.205], [65337.2, 0.003], [65508.9, 3.304], [65777.1, 1.365]]}
{"kind": "depth", "E": 1787081838945, "U": 11315466093033, "u": 11315466098456, "recv_ms": 1787081838912, "bids": [[1000.0, 35.81], [14190.2, 2.786], [14290.2, 1.414], [58221.1, 0.002], [61455.6, 0.0], [62102.5, 0.001], [63385.2, 0.0], [63690.2, 0.0], [64043.2, 0.004], [64043.3, 0.085], [64146.8, 0.322], [64348.5, 0.001], [64349.0, 5.494], [64678.5, 0.04], [64685.2, 0.009], [64685.7, 0.163]], "asks": [[64690.3, 3.319], [64765.7, 32.775], [64767.9, 0.022], [65337.2, 0.005], [65690.3, 0.0]]}
{"kind": "depth", "E": 1787081839047, "U": 11315466098499, "u": 11315466106407, "recv_ms": 1787081839081, "bids": [[1000.0, 35.81], [14190.2, 3.15], [14290.2, 1.05], [58221.1, 0.002], [61455.6, 0.0], [61455.7, 0.008], [61455.8, 0.004], [63631.5, 0.002], [64043.3, 0.085], [64146.8, 0.285], [64368.4, 0.114], [64372.5, 0.0], [64493.5, 10.176], [64532.3, 4.879], [64549.2, 4.896], [64612.5, 0.24], [64623.7, 0.0], [64623.8, 2.81], [64647.9, 0.035], [64654.4, 1.173], [64660.9, 3.568], [64678.6, 0.007], [64679.1, 0.26], [64681.1, 2.32], [64685.2, 0.009], [64685.6, 0.766], [64685.7, 0.167], [64688.0, 0.325], [64690.2, 27.961]], "asks": [[64693.4, 0.003], [64696.8, 0.018], [64698.9, 1.093], [64699.0, 1.003], [64704.1, 0.045], [64706.9, 0.109], [64756.1, 2.992], [64800.3, 0.398], [64829.9, 5.399], [64844.8, 1.22], [64846.9, 10.409], [64875.4, 0.0], [64885.7, 9.82], [65337.2, 0.003], [65387.6, 13.625]]}
{"kind": "depth", "E": 1787081839149, "U": 11315466106569, "u": 11315466119755, "recv_ms": 1787081839138, "bids": [[14190.2, 3.5], [14290.2, 0.7], [51752.2, 0.0], [58221.1, 0.002], [61455.6, 0.0], [62102.5, 0.004], [63690.2, 0.02], [63928.0, 11.556], [64043.3, 0.085], [64366.7, 2.484], [64573.4, 0.0], [64604.4, 0.01], [64618.5, 0.006], [64618.6, 0.001], [64627.9, 0.005], [64638.4, 1.066], [64641.4, 0.006], [64647.7, 0.008], [64660.6, 0.001], [64678.5, 0.04], [64678.6, 0.002], [64678.7, 0.019], [64684.2, 0.614], [64684.3, 0.68], [64684.9, 0.512], [64685.1, 0.077], [64685.2, 0.001], [64685.6, 0.086], [64685.7, 0.167], [64690.2, 27.961]], "asks": [[64690.3, 3.331], [64696.0, 0.314], [64697.1, 0.224], [64699.7, 0.003], [64733.6, 0.165], [64771.5, 0.011], [64834.6, 0.023], [64885.7, 9.819], [65028.1, 0.616], [65337.2, 0.003], [65368.3, 7.637], [65659.6, 12.741], [65690.3, 0.02], [67924.8, 0.004]]}
{"kind": "depth", "E": 1787081839251, "U": 11315466120046, "u": 11315466131052, "recv_ms": 1787081839228, "bids": [[1000.0, 35.81], [14190.2, 3.752], [14290.2, 0.392], [14590.2, 0.056], [51752.0, 0.0], [58221.1, 0.002], [62102.5, 0.001], [63517.4, 2.022], [63802.7, 0.05], [63959.8, 0.004], [64043.3, 0.085], [64605.6, 0.203], [64605.7, 0.006], [64612.5, 0.237], [64628.0, 0.011], [64644.9, 0.008], [64658.5, 0.213], [64659.9, 0.059], [64670.7, 0.172], [64671.8, 0.117], [64674.6, 0.358], [64675.8, 0.942], [64676.7, 0.622], [64681.7, 0.001], [64683.7, 0.019], [64684.0, 2.7], [64684.2, 1.155], [64684.3, 0.0], [64685.6, 0.086], [64685.7, 0.163], [64690.2, 27.946]], "asks": [[64694.7, 2.328], [64696.3, 0.086], [64698.5, 0.015], [64699.1, 0.027], [64699.7, 0.002], [64701.3, 0.004], [64701.4, 0.003], [64706.9, 0.102], [64708.0, 0.905], [64708.6, 0.925], [64710.2, 0.0], [64710.7, 2.459], [64714.1, 1.199], [64714.6, 0.462], [64726.6, 2.214], [64748.6, 0.016], [64800.3, 0.395], [64846.9, 10.409], [64847.4, 0.0], [64885.7, 9.704], [64886.2, 0.003], [65337.2, 0.003]]}
{"kind": "depth", "E": 1787081839353, "U": 11315466131290, "u": 11315466138956, "recv_ms": 1787081839335, "bids": [[1000.0, 35.81], [14190.2, 3.668], [14290.2, 0.252], [14590.2, 0.28], [58221.1, 0.002], [61455.6, 0.0], [62102.5, 0.004], [63396.4, 0.024], [63461.0, 0.115], [63690.2, 0.0], [63913.9, 9.093], [64043.3, 0.087], [64146.8, 0.281], [64493.4, 7.139], [64493.5, 0.071], [64532.3, 2.363], [64549.2, 2.905], [64573.5, 2.443], [64628.0, 0.011], [64660.7, 0.228], [64684.3, 0.0], [64685.7, 0.163], [64690.2, 27.946]], "asks": [[64693.4, 0.003], [64703.3, 0.447], [64726.6, 2.228], [64733.7, 2.698], [64771.6, 0.0], [64790.6, 2.23], [64819.7, 0.001], [64834.7, 0.0], [64885.7, 15.413], [65337.2, 0.003], [65498.9, 13.601], [65690.3, 0.0]]}
{"kind": "depth", "E": 1787081839455, "U": 11315466138977, "u": 11315466145397, "recv_ms": 1787081839436, "bids": [[14190.2, 3.556], [14290.2, 0.14], [14590.2, 0.504], [51752.0, 0.0], [58221.1, 0.002], [62102.5, 0.001], [63385.2, 0.97], [63784.5, 7.422], [63881.6, 0.473], [63933.3, 0.568], [64043.3, 0.085], [64146.8, 0.316], [64366.7, 2.484], [64493.4, 10.053], [64532.3, 4.911], [64549.2, 4.92], [64573.5, 2.443], [64625.5, 0.056], [64628.0, 0.011], [64660.7, 0.228], [64681.7, 0.542], [64684.2, 0.614], [64684.3, 0.0]], "asks": [[64698.5, 0.556], [64699.0, 1.022], [64707.0, 0.001], [64727.9, 0.348], [64733.7, 2.698], [64755.0, 0.2], [64771.6, 0.0], [64834.7, 0.0], [64885.7, 9.815], [65013.8, 2.847], [65337.2, 0.003], [65498.9, 13.859], [65680.8, 0.0]]}
{"kind": "depth", "E": 1787081839557, "U": 11315466145573, "u": 11315466152735, "recv_ms": 1787081839534, "bids": [[1000.0, 35.96], [14190.2, 3.444], [14290.2, 0.014], [14590.2, 0.742], [58221.1, 0.002], [61455.6, 0.0], [63690.2, 0.02], [64043.3, 0.085], [64366.7, 2.483], [64424.0, 1.935], [64425.6, 0.581], [64549.2, 4.92], [64626.9, 0.082], [64633.4, 0.006], [64642.5, 0.139], [64643.5, 0.001], [64673.8, 0.002], [64685.7, 0.167], [64690.2, 27.984]], "asks": [[64693.4, 0.003], [64698.7, 1.012], [64706.3, 0.003], [64738.5, 1.998], [64745.9, 0.005], [64765.6, 7.027], [64766.3, 0.024], [64829.9, 5.399], [64844.8, 2.619], [65337.2, 0.003], [65508.9, 3.076], [65690.3, 0.02]]}
{"kind": "depth", "E": 1787081839659, "U": 11315466152798, "u": 11315466158628, "recv_ms": 1787081839626, "bids": [[1000.0, 35.81], [14190.2, 3.122], [14290.2, 0.0], [14590.2, 1.078], [58221.1, 0.002], [62102.5, 0.004], [63396.4, 0.021], [64010.8, 0.0], [64043.3, 0.085], [64146.8, 0.279], [64633.4, 0.002], [64640.0, 1.877], [64673.8, 0.004], [64678.5, 0.503], [64678.6, 0.002], [64681.7, 0.001], [64684.0, 2.7], [64684.2, 0.614], [64684.9, 0.041], [64685.1, 0.077], [64685.2, 0.542], [64685.3, 0.017], [64685.7, 0.163], [64690.2, 27.984]], "asks": [[64690.3, 3.315], [64696.3, 0.002], [64706.3, 0.005], [64710.7, 1.903], [64711.2, 0.634], [64711.3, 0.005], [64712.3, 0.262], [64713.4, 0.382], [64714.0, 0.549], [64714.6, 0.347], [64715.3, 0.12], [64846.9, 0.0], [64847.4, 7.601], [64885.7, 0.001], [64886.2, 13.107], [64896.7, 0.003], [64896.8, 0.0], [65013.8, 2.848], [65337.2, 0.003], [65528.3, 3.81], [65984.1, 0.024], [66652.1, 0.003]]}
{"kind": "depth", "E": 1787081839761, "U": 11315466158725, "u": 11315466164760, "recv_ms": 1787081839729, "bids": [[14190.2, 2.758], [14590.2, 1.442], [51752.0, 0.004], [58221.1, 0.002], [62102.5, 0.001], [62791.0, 0.072], [63690.2, 0.0], [64043.3, 0.087], [64366.7, 2.483], [64678.5, 0.04], [64678.6, 0.002], [64678.7, 0.019], [64681.7, 0.542], [64684.2, 0.073], [64684.8, 0.628], [64684.9, 0.504], [64685.3, 0.009], [64685.4, 0.004]], "asks": [[64693.4, 0.003], [64699.0, 1.003], [64739.3, 0.005], [64745.9, 0.001], [64846.9, 10.409], [64847.4, 0.0], [65337.2, 0.003], [65628.3, 7.465], [65690.3, 0.0]]}
{"kind": "depth", "E": 1787081839863, "U": 11315466164831, "u": 11315466171679, "recv_ms": 1787081839831, "bids": [[1000.0, 35.81], [14190.2, 2.394], [14590.2, 1.806], [51752.0, 0.0], [58221.1, 0.002], [61455.6, 0.0], [62102.5, 0.004], [63800.5, 2.024], [63985.1, 0.701], [64019.9, 0.074], [64043.3, 0.085], [64549.2, 4.92], [64676.9, 1.215], [64677.8, 0.438], [64678.5, 0.04], [64678.6, 0.002], [64681.7, 0.001], [64684.0, 3.241], [64684.2, 0.614], [64684.9, 1.192], [64685.1, 0.077], [64685.2, 0.001], [64685.7, 0.006], [64686.9, 0.368], [64690.2, 27.984]], "asks": [[64690.3, 3.29], [64829.9, 5.399], [64846.9, 0.0], [64847.4, 6.918], [64885.7, 9.815], [64886.2, 0.003], [65013.8, 2.847], [65337.2, 0.003], [65639.9, 1.057], [65708.7, 0.001], [65984.1, 0.021], [66635.0, 2.177]]}
{"kind": "depth", "E": 1787081839965, "U": 11315466171760, "u": 11315466176929, "recv_ms": 1787081839934, "bids": [[14190.2, 2.044], [14590.2, 2.156], [58221.1, 0.002], [63396.4, 0.018], [63690.2, 0.02], [64043.2, 0.003], [64043.3, 0.085], [64349.0, 5.002], [64349.3, 0.978], [64424.0, 4.564], [64425.6, 0.946], [64651.4, 0.157], [64657.9, 0.444], [64664.4, 0.518], [64684.3, 0.0], [64684.9, 0.512], [64686.9, 0.492], [64688.0, 0.328]], "asks": [[64846.9, 10.409], [64847.4, 0.0], [65337.2, 0.003], [65620.7, 12.499], [65668.4, 0.395], [65690.3, 0.02]]}
{"kind": "depth", "E": 1787081840067, "U": 11315466177022, "u": 11315466184141, "recv_ms": 1787081840035, "bids": [[14190.2, 1.68], [14590.2, 2.52], [34000.0, 1.146], [58221.1, 0.002], [61455.6, 0.0], [62102.5, 0.001], [63784.5, 9.77], [64043.3, 0.085], [64366.7, 2.494], [64493.4, 10.105], [64532.3, 4.873], [64549.2, 4.893], [64573.5, 2.443], [64596.4, 0.003], [64602.8, 0.003], [64609.3, 0.025], [64615.8, 0.113], [64622.2, 0.003], [64623.8, 2.759], [64628.0, 0.011], [64628.7, 0.104], [64635.2, 1.098], [64641.7, 0.006], [64648.1, 0.025], [64654.6, 1.11], [64654.7, 0.134], [64660.7, 0.228], [64661.1, 0.136], [64664.4, 0.548], [64666.1, 0.015], [64667.5, 0.563], [64672.1, 0.154], [64674.0, 0.559], [64677.3, 0.007], [64678.5, 0.503], [64678.6, 0.01], [64680.5, 0.004], [64681.6, 1.253], [64684.2, 1.371], [64684.9, 0.041], [64685.1, 0.0], [64685.2, 0.001], [64685.3, 0.012], [64685.7, 0.002], [64686.9, 0.495], [64688.0, 0.332], [64690.2, 27.983]], "asks": [[64690.3, 3.298], [64693.4, 0.003], [64697.4, 0.001], [64697.6, 1.149], [64699.3, 0.021], [64705.8, 0.007], [64712.3, 0.265], [64718.7, 0.105], [64725.2, 0.004], [64733.7, 2.698], [64756.1, 3.028], [64771.6, 0.0], [64805.8, 0.011], [64834.7, 0.0], [64848.9, 0.0], [64885.7, 9.829], [65337.2, 0.003], [65628.3, 8.53], [65638.3, 4.297], [65693.0, 1.069], [71159.4, 0.0]]}
{"kind": "depth", "E": 1787081840169, "U": 11315466184328, "u": 11315466190645, "recv_ms": 1787081840137, "bids": [[1000.0, 35.81], [14190.2, 1.33], [14590.2, 2.87], [51752.0, 0.002], [51752.2, 0.0], [58221.1, 0.002], [61455.7, 0.01], [62102.5, 0.004], [63690.2, 0.0], [63923.6, 17.699], [64019.8, 3.12], [64043.3, 0.085], [64604.4, 0.013], [64618.6, 0.003], [64628.0, 0.002], [64633.4, 0.006], [64638.5, 2.829], [64640.0, 1.873], [64641.5, 2.147], [64647.9, 0.036], [64648.2, 0.003], [64650.1, 0.061], [64670.1, 0.005], [64671.1, 0.557], [64675.8, 0.016], [64676.7, 1.548], [64678.5, 0.503], [64678.6, 0.002], [64684.0, 2.7], [64684.2, 0.073], [64684.3, 0.541], [64684.8, 0.628], [64684.9, 0.59], [64685.1, 0.077]], "asks": [[64700.0, 0.967], [64708.6, 0.0], [64709.1, 0.944], [64731.7, 3.919], [64738.2, 0.025], [64739.3, 0.001], [64744.6, 0.003], [64745.9, 0.005], [64751.1, 0.027], [64751.8, 0.002], [64753.8, 0.061], [64757.6, 0.218], [64764.0, 1.335], [64770.5, 0.22], [64777.0, 0.264], [64783.4, 1.386], [64789.9, 1.246], [64796.4, 0.032], [64885.7, 9.713], [65337.2, 0.003], [65463.7, 1.526], [65641.3, 1.216], [65690.3, 0.0]]}
{"kind": "depth", "E": 1787081840271, "U": 11315466190788, "u": 11315466199985, "recv_ms": 1787081840241, "bids": [[14190.2, 0.966], [14590.2, 3.234], [51752.0, 0.0], [58221.1, 0.002], [61455.6, 0.001], [62102.5, 0.001], [63960.0, 0.298], [64043.3, 0.085], [64089.4, 0.0], [64573.5, 2.724], [64628.0, 0.171], [64633.4, 0.002], [64640.2, 0.04], [64660.7, 0.301], [64670.4, 1.759], [64671.1, 0.0], [64675.8, 0.942], [64676.7, 0.622], [64678.5, 0.04], [64678.6, 0.002], [64681.7, 0.001], [64684.0, 3.241], [64684.3, 0.0], [64684.9, 0.582], [64685.1, 0.548], [64685.2, 0.001], [64685.7, 0.006], [64690.2, 27.982]], "asks": [[64693.4, 0.003], [64698.9, 1.112], [64700.0, 0.966], [64708.2, 1.235], [64709.1, 0.019], [64722.8, 0.001], [64722.9, 0.665], [64733.7, 2.771], [64739.3, 0.005], [64745.9, 0.001], [64771.6, 0.169], [64834.8, 0.312], [65337.2, 0.003], [65589.5, 1.522], [65628.3, 9.595]]}
{"kind": "depth", "E": 1787081840373, "U": 11315466200065, "u": 11315466209299, "recv_ms": 1787081840341, "bids": [[14190.2, 0.602], [14590.2, 3.598], [58221.1, 0.002], [61455.6, 0.0], [61455.7, 0.01], [61455.8, 0.006], [62102.5, 0.004], [63396.4, 0.021], [63690.2, 0.02], [64043.3, 0.085], [64366.7, 2.484], [64573.5, 2.443], [64612.5, 0.24], [64628.0, 0.002], [64659.0, 0.06], [64659.9, 0.002], [64660.7, 0.228], [64669.7, 0.634], [64670.4, 1.202], [64671.0, 0.144], [64671.8, 0.001], [64675.1, 2.791], [64675.8, 0.016], [64675.9, 0.926], [64681.7, 0.001], [64684.0, 2.7], [64684.1, 2.622], [64685.2, 0.001], [64685.7, 0.002], [64689.3, 0.046], [64690.2, 27.967]], "asks": [[64690.3, 3.28], [64697.1, 0.14], [64698.5, 0.008], [64698.9, 1.093], [64699.1, 0.005], [64700.0, 0.066], [64703.8, 0.046], [64704.1, 0.076], [64706.9, 0.078], [64707.0, 0.542], [64709.9, 1.238], [64710.8, 2.91], [64711.1, 0.003], [64711.2, 0.078], [64711.6, 0.032], [64711.7, 0.092], [64712.3, 0.208], [64713.8, 0.069], [64714.8, 0.116], [64715.3, 0.005], [64722.9, 0.819], [64733.7, 2.698], [64771.6, 0.0], [64800.3, 0.398], [64819.7, 0.004], [64834.8, 0.03], [65337.2, 0.003], [65690.3, 0.02]]}
{"kind": "depth", "E": 1787081840475, "U": 11315466209408, "u": 11315466217506, "recv_ms": 1787081840442, "bids": [[1000.0, 35.81], [14190.2, 0.336], [14490.2, 0.084], [14590.2, 3.78], [58221.1, 0.002], [61455.6, 0.0], [64043.3, 0.085], [64584.1, 2.396], [64659.0, 0.003], [64660.3, 0.057], [64669.8, 0.006], [64675.2, 1.678], [64675.9, 0.0], [64676.5, 0.928], [64676.7, 0.004], [64681.7, 0.001], [64682.9, 0.175], [64684.1, 2.081], [64684.2, 0.606], [64685.2, 0.009], [64685.7, 0.002], [64688.0, 0.335], [64690.2, 27.967]], "asks": [[64690.3, 2.44], [64693.4, 0.003], [64696.0, 0.004], [64698.5, 0.556], [64699.1, 0.005], [64699.3, 0.021], [64704.1, 0.045], [64706.9, 0.001], [64707.0, 0.001], [64707.1, 0.588], [64708.2, 0.31], [64709.0, 1.793], [64711.7, 0.035], [64712.3, 0.265], [64716.3, 0.0], [64717.9, 0.321], [64721.1, 0.631], [64728.4, 0.002], [64735.7, 0.196], [64743.1, 0.003], [64801.4, 2.319], [64801.7, 5.901], [64846.9, 10.409], [64847.4, 0.0], [65337.2, 0.003], [65508.9, 2.734], [65984.1, 0.024], [66012.7, 1.296]]}
{"kind": "depth", "E": 1787081840577, "U": 11315466217727, "u": 11315466230120, "recv_ms": 1787081840547, "bids": [[14190.2, 0.224], [14490.2, 0.322], [14590.2, 3.654], [58221.1, 0.002], [61455.6, 0.0], [62102.5, 0.001], [63690.2, 0.0], [63781.3, 1.958], [64043.3, 0.087], [64172.7, 4.2], [64424.0, 1.935], [64425.6, 0.581], [64605.4, 0.006], [64605.6, 0.2], [64612.5, 0.237], [64644.9, 0.008], [64674.2, 0.132], [64684.2, 0.065], [64684.9, 1.123], [64685.1, 0.548], [64685.9, 0.084], [64690.1, 0.291], [64690.2, 27.968]], "asks": [[64690.3, 2.424], [64698.4, 0.003], [64698.5, 0.556], [64704.1, 0.045], [64707.0, 0.001], [64707.1, 0.588], [64709.0, 0.868], [64709.5, 0.927], [64710.8, 2.354], [64711.9, 1.855], [64712.3, 0.208], [64712.8, 0.059], [64714.0, 0.008], [64714.4, 0.563], [64748.6, 0.016], [64756.0, 1.449], [64756.7, 0.023], [64800.3, 0.395], [64896.6, 0.003], [64896.7, 0.0], [65337.2, 0.003], [65481.1, 10.036], [65498.9, 14.088], [65690.3, 0.0], [65984.1, 0.021]]}
{"kind": "depth", "E": 1787081840679, "U": 11315466230185, "u": 11315466239096, "recv_ms": 1787081840648, "bids": [[14190.2, 0.098], [14490.2, 0.56], [14590.2, 3.542], [58221.1, 0.002], [61455.7, 0.008], [61455.8, 0.008], [62102.5, 0.004], [63396.4, 0.015], [64043.3, 0.085], [64366.7, 2.494], [64381.0, 2.336], [64424.0, 4.563], [64673.0, 0.001], [64673.8, 0.004], [64676.9, 1.135], [64678.0, 0.082], [64681.3, 0.0], [64684.2, 0.606], [64684.9, 0.582], [64685.0, 1.09], [64685.6, 0.086], [64685.8, 0.014], [64688.0, 0.332], [64690.2, 27.968]], "asks": [[64690.3, 3.264], [64691.8, 0.001], [64693.5, 0.009], [64696.1, 0.465], [64697.1, 0.224], [64698.4, 0.003], [64698.5, 0.008], [64703.9, 0.011], [64704.1, 0.045], [64706.3, 0.005], [64706.9, 0.109], [64707.0, 0.542], [64707.1, 0.487], [64734.4, 1.52], [64743.4, 2.394], [65013.8, 2.846], [65337.2, 0.003], [65931.4, 0.609]]}
{"kind": "depth", "E": 1787081840781, "U": 11315466239199, "u": 11315466247558, "recv_ms": 1787081840752, "bids": [[1000.0, 35.81], [14190.2, 0.0], [14490.2, 0.812], [14590.2, 3.388], [58221.1, 0.002], [61455.6, 0.0], [62102.5, 0.001], [63600.1, 3.16], [63690.2, 0.02], [63707.8, 9.879], [63825.6, 0.0], [63895.1, 0.0], [63928.0, 10.776], [64043.3, 0.085], [64186.9, 1.242], [64366.7, 2.495], [64573.6, 0.282], [64628.1, 0.196], [64660.8, 1.259], [64683.0, 0.178], [64685.0, 0.412], [64685.6, 0.09], [64687.0, 0.021], [64690.2, 27.967]], "asks": [[64690.3, 3.284], [64699.5, 0.001], [64699.6, 0.003], [64700.1, 0.797], [64703.7, 0.001], [64704.1, 0.076], [64706.9, 0.078], [64733.8, 13.84], [64734.4, 1.519], [64759.5, 6.561], [64771.7, 0.171], [64834.8, 0.314], [65222.2, 0.961], [65337.2, 0.003], [65466.6, 17.266], [65649.2, 11.068], [65690.3, 0.02], [65984.1, 0.018]]}
{"kind": "depth", "E": 1787081840883, "U": 11315466247653, "u": 11315466255743, "recv_ms": 1787081840852, "bids": [[14490.2, 1.176], [14590.2, 3.024], [58221.1, 0.002], [61455.6, 0.0], [61455.8, 0.006], [62102.5, 0.004], [63580.1, 1.716], [63690.2, 0.0], [63772.5, 6.739], [64043.3, 0.085], [64573.6, 0.0], [64597.3, 0.0], [64628.1, 0.027], [64635.7, 0.16], [64660.8, 1.186], [64669.7, 0.077], [64671.0, 0.028], [64671.1, 0.557], [64672.3, 0.116], [64685.6, 0.09], [64690.2, 28.014]], "asks": [[64693.4, 0.003], [64698.5, 0.556], [64700.9, 0.953], [64703.8, 0.046], [64703.9, 0.011], [64704.0, 1.366], [64704.1, 0.045], [64706.9, 0.001], [64707.0, 0.001], [64707.1, 0.588], [64714.8, 0.001], [64715.3, 0.12], [64733.8, 13.766], [64771.7, 0.0], [64834.8, 0.03], [65337.2, 0.005], [65628.3, 9.747], [65690.3, 0.0], [65713.9, 7.297]]}
{"kind": "depth", "E": 1787081840985, "U": 11315466255763, "u": 11315466261049, "recv_ms": 1787081840953, "bids": [[1000.0, 35.81], [14490.2, 1.526], [14590.2, 2.674], [58221.1, 0.002], [63881.6, 1.255], [63913.9, 9.873], [64043.3, 0.085], [64172.7, 4.51], [64349.3, 0.486], [64349.5, 0.492], [64366.7, 2.649], [64579.6, 0.431], [64598.3, 0.0], [64622.9, 39.319], [64623.4, 7.692], [64625.0, 1.59], [64627.1, 1.099], [64658.9, 0.016], [64659.7, 0.063], [64660.3, 0.0], [64668.7, 3.028], [64670.1, 0.012], [64670.5, 5.79], [64670.9, 2.158], [64671.1, 0.0], [64671.7, 0.581], [64672.3, 0.0], [64675.8, 0.942], [64676.5, 0.002], [64681.7, 0.001], [64684.0, 3.241], [64684.2, 0.057], [64684.9, 0.574], [64685.1, 1.22], [64685.2, 0.033], [64685.3, 0.004], [64685.5, 0.289], [64685.6, 0.086], [64690.2, 28.015]], "asks": [[64703.8, 0.509], [64703.9, 0.112], [64707.1, 0.024], [64708.3, 1.049], [64709.5, 0.002], [64710.5, 0.007], [64710.7, 2.459], [64711.5, 0.057], [64711.6, 0.025], [64711.9, 1.299], [64712.8, 0.002], [64846.9, 10.409], [64847.3, 0.001], [65207.8, 5.51], [65337.2, 0.659], [65649.2, 10.003], [65852.1, 0.001]]}
{"kind": "depth", "E": 1787081841087, "U": 11315466261122, "u": 11315466267736, "recv_ms": 1787081841054, "bids": [[1000.0, 35.81], [14490.2, 1.89], [14590.2, 2.31], [58221.1, 0.002], [61455.6, 0.0], [62102.5, 0.001], [63687.5, 1.284], [63699.0, 0.033], [63752.2, 2.216], [64043.3, 0.085], [64612.5, 0.24], [64625.5, 0.065], [64665.2, 0.138], [64678.6, 0.002], [64680.6, 0.001], [64685.1, 0.54], [64685.2, 0.373], [64685.6, 0.09], [64689.8, 0.148], [64690.2, 27.865]], "asks": [[64693.4, 0.003], [64694.4, 0.161], [64696.0, 0.088], [64702.8, 0.598], [64703.4, 1.282], [64703.8, 0.05], [64703.9, 0.011], [64707.1, 0.024], [64713.4, 0.923], [64714.4, 0.022], [64800.3, 0.398], [64846.9, 10.409], [64847.3, 0.001], [65013.8, 2.847], [65337.2, 0.661], [65616.7, 0.001], [65628.3, 10.812], [65689.8, 0.0], [65693.0, 2.133]]}
{"kind": "depth", "E": 1787081841189, "U": 11315466267786, "u": 11315466276669, "recv_ms": 1787081841157, "bids": [[14490.2, 2.254], [14590.2, 1.946], [51752.0, 0.0], [51752.2, 0.0], [58221.1, 0.002], [61455.6, 0.0], [62102.5, 0.004], [63008.3, 0.001], [63690.2, 0.02], [63695.3, 0.011], [63784.5, 10.239], [63794.2, 10.732], [63929.9, 14.711], [64043.3, 0.085], [64618.7, 0.116], [64622.9, 0.003], [64625.0, 41.238], [64638.6, 0.374], [64647.9, 0.037], [64657.3, 0.271], [64657.4, 0.001], [64657.5, 0.451], [64658.9, 0.005], [64660.8, 1.184], [64660.9, 3.566], [64661.0, 0.024], [64662.5, 0.011], [64674.1, 0.02], [64675.5, 0.002], [64678.1, 0.154], [64678.5, 0.511], [64679.3, 0.002], [64681.1, 2.327], [64681.8, 0.04], [64685.1, 0.077], [64685.2, 0.025], [64685.3, 0.004], [64685.5, 0.165], [64685.6, 0.086], [64688.1, 0.079], [64689.2, 0.001], [64690.2, 27.864]], "asks": [[64690.3, 3.285], [64694.2, 0.021], [64694.5, 0.128], [64696.1, 0.472], [64696.7, 0.004], [64696.8, 0.01], [64697.2, 0.001], [64699.7, 0.002], [64699.8, 0.121], [64699.9, 0.001], [64708.3, 0.124], [64708.8, 0.972], [64710.5, 0.0], [64710.7, 1.903], [64711.2, 0.094], [64711.3, 0.568], [64711.5, 0.0], [64712.1, 0.058], [64713.0, 0.021], [64713.3, 0.542], [64713.4, 0.382], [64714.0, 0.008], [64714.4, 0.005], [64714.9, 0.0], [64722.9, 0.819], [64790.6, 2.13], [64885.7, 10.132], [65337.2, 0.659], [65628.3, 11.877], [65690.3, 0.02], [65984.1, 0.021]]}
{"kind": "depth", "E": 1787081841291, "U": 11315466276702, "u": 11315466282505, "recv_ms": 1787081841261, "bids": [[1000.0, 35.81], [14490.2, 2.59], [14590.2, 1.61], [58221.1, 0.002], [62102.5, 0.001], [63267.0, 1.009], [64043.3, 0.085], [64366.7, 2.649], [64620.0, 3.047], [64620.3, 2.319], [64620.7, 0.183], [64621.0, 0.015], [64621.3, 0.002], [64623.4, 0.005], [64641.2, 0.258], [64641.5, 2.147], [64641.9, 0.06], [64642.2, 0.025], [64642.5, 0.139], [64656.2, 0.001], [64656.3, 0.005], [64656.4, 0.02], [64656.5, 0.016], [64656.6, 0.025], [64656.7, 0.027], [64656.8, 0.002], [64656.9, 1.469], [64657.2, 0.06], [64661.6, 0.062], [64662.0, 0.05], [64668.1, 0.805], [64668.8, 0.017], [64671.5, 0.198], [64678.5, 0.503], [64678.6, 0.01], [64681.7, 0.542], [64681.8, 0.102], [64682.0, 0.026], [64682.4, 0.001], [64682.5, 0.022], [64682.6, 0.028], [64682.7, 0.164], [64682.8, 0.071], [64682.9, 0.075], [64683.0, 0.058], [64683.1, 0.019], [64683.2, 0.101], [64683.4, 0.247], [64683.6, 0.381], [64683.9, 3.661], [64684.0, 2.638], [64684.2, 0.102], [64684.6, 0.005], [64684.9, 0.574], [64685.0, 0.412], [64685.1, 0.008], [64685.2, 0.025], [64685.5, 0.157], [64685.6, 0.09], [64690.2, 27.875]], "asks": [[64693.1, 0.014], [64698.5, 0.015], [64699.5, 0.021], [64699.7, 0.025], [64699.8, 0.099], [64702.8, 0.002], [64703.1, 0.003], [64703.2, 0.352], [64703.4, 1.24], [64703.8, 0.005], [64704.1, 0.045], [64704.3, 0.001], [64704.4, 0.76], [64704.5, 2.321], [64704.6, 0.33], [64704.7, 0.005], [64704.8, 0.154], [64704.9, 0.027], [64705.0, 0.901], [64705.1, 0.193], [64705.2, 0.308], [64705.3, 0.0], [64706.9, 0.542], [64707.0, 0.086], [64707.1, 0.503], [64722.9, 0.665], [64723.0, 0.157], [64724.0, 0.011], [64724.3, 0.014], [64724.4, 0.433], [64724.6, 0.022], [64725.0, 0.0], [64725.3, 0.317], [64725.6, 0.0], [64726.0, 0.005], [64726.6, 3.482], [64728.0, 11.098], [64730.5, 0.0], [64730.7, 0.0], [64730.8, 0.002], [64730.9, 0.004], [64731.0, 0.539], [64731.1, 0.002], [64731.2, 1.157], [64731.3, 0.181], [64731.4, 0.389], [64731.5, 0.1], [64733.7, 1.693], [64733.8, 3.766], [64745.2, 0.146], [64745.5, 0.038], [64745.8, 0.0], [64746.1, 2.842], [64746.5, 0.061], [64747.3, 0.029], [65337.2, 0.659], [65642.8, 6.288], [65685.3, 0.011], [65804.6, 3.411]]}
{"kind": "depth", "E": 1787081841393, "U": 11315466282761, "u": 11315466288011, "recv_ms": 1787081841360, "bids": [[1000.0, 35.81], [14490.2, 2.954], [14590.2, 1.246], [58221.1, 0.002], [63690.2, 0.0], [63826.5, 6.098], [63913.9, 11.78], [63955.1, 0.0], [63968.2, 2.343], [64043.2, 0.346], [64043.3, 0.085], [64642.8, 0.034], [64658.7, 0.061], [64659.7, 0.006], [64669.5, 0.573], [64670.5, 5.233], [64670.8, 2.442], [64671.7, 0.465], [64674.8, 1.228], [64675.8, 0.016], [64683.0, 0.128], [64683.3, 0.086], [64684.1, 2.263], [64684.2, 0.102], [64684.9, 0.033], [64685.1, 0.549], [64685.2, 0.057]], "asks": [[64698.5, 0.556], [64702.8, 0.034], [64704.8, 0.252], [64705.0, 0.992], [64706.9, 0.001], [64707.3, 0.035], [64708.2, 1.235], [64708.8, 0.047], [64710.6, 0.082], [64711.5, 0.057], [64712.1, 0.001], [64724.0, 0.043], [64731.0, 0.637], [64731.2, 1.248], [64745.2, 0.178], [64819.7, 0.004], [65337.2, 0.659], [65498.9, 14.316], [65589.5, 3.043], [65690.3, 0.0], [65778.6, 1.063]]}
{"kind": "depth", "E": 1787081841495, "U": 11315466288096, "u": 11315466293562, "recv_ms": 1787081841463, "bids": [[14490.2, 3.318], [14590.2, 0.882], [58221.1, 0.002], [61455.6, 0.0], [62102.5, 0.004], [62741.1, 0.683], [63701.6, 3.062], [63766.3, 5.412], [63772.5, 5.643], [63816.9, 0.402], [63960.4, 1.902], [64043.3, 0.085], [64366.7, 2.649], [64573.5, 2.443], [64628.0, 0.002], [64641.9, 0.092], [64660.7, 0.228], [64669.9, 0.798], [64677.2, 1.661], [64678.6, 0.002], [64682.7, 0.234], [64682.9, 0.145], [64683.9, 3.97], [64684.1, 2.081], [64684.2, 0.707], [64684.3, 0.0], [64684.8, 0.319], [64684.9, 0.041], [64685.1, 0.0], [64685.2, 0.033], [64685.3, 0.004], [64685.6, 0.09], [64686.9, 0.286], [64690.2, 27.878]], "asks": [[64692.0, 0.003], [64692.9, 0.001], [64693.4, 0.003], [64697.2, 0.549], [64698.5, 0.008], [64699.6, 0.026], [64699.7, 0.002], [64703.8, 0.05], [64705.1, 0.298], [64705.3, 0.091], [64721.2, 0.856], [64725.0, 0.045], [64728.5, 1.246], [64731.3, 0.286], [64731.5, 0.191], [64733.7, 1.693], [64746.2, 0.048], [64747.3, 0.001], [64771.6, 0.0], [64834.7, 0.0], [65337.2, 0.659], [65474.6, 0.0], [65477.0, 1.083], [65628.3, 12.942], [65790.0, 4.773], [65984.1, 0.015]]}
{"kind": "depth", "E": 1787081841597, "U": 11315466293793, "u": 11315466300912, "recv_ms": 1787081841565, "bids": [[1000.0, 35.81], [14490.2, 3.668], [14590.2, 0.532], [51752.0, 0.0], [58221.1, 0.002], [61455.6, 0.0], [62102.5, 0.001], [63267.0, 1.006], [63687.5, 2.382], [63690.2, 0.02], [63752.2, 3.313], [63946.3, 0.948], [64043.3, 0.085], [64425.6, 0.946], [64549.2, 0.16], [64620.4, 0.032], [64621.3, 0.034], [64642.2, 0.057], [64662.5, 0.0], [64665.9, 0.013], [64678.5, 0.04], [64678.6, 0.002], [64681.8, 0.04], [64682.8, 0.133], [64682.9, 0.215], [64683.1, 0.219], [64683.3, 0.186], [64683.4, 0.347], [64683.5, 0.262], [64684.2, 0.707], [64684.3, 0.471], [64684.6, 0.037], [64684.7, 1.843], [64684.9, 0.033], [64685.6, 0.086], [64690.1, 0.292], [64690.2, 27.876]], "asks": [[64690.3, 3.269], [64702.8, 0.135], [64703.5, 0.442], [64704.5, 2.511], [64704.6, 0.588], [64704.7, 0.195], [64704.9, 0.177], [64705.0, 1.132], [64705.2, 0.413], [64707.0, 0.001], [64707.1, 0.487], [64711.2, 0.078], [64711.9, 1.315], [64719.2, 0.004], [64719.3, 0.053], [64719.4, 0.475], [64722.2, 0.008], [64722.3, 0.444], [64722.4, 0.002], [64723.0, 0.005], [64723.1, 0.468], [64723.2, 0.246], [64724.7, 0.042], [64725.3, 0.319], [64725.4, 0.006], [64725.5, 0.003], [64725.7, 0.192], [64730.8, 0.26], [64730.9, 0.194], [64731.1, 0.152], [64731.2, 1.388], [64731.4, 0.494], [64745.9, 0.043], [64829.9, 0.0], [64896.5, 0.003], [64896.6, 0.0], [65337.2, 0.659], [65690.3, 0.02]]}
{"kind": "depth", "E": 1787081841699, "U": 11315466300959, "u": 11315466310043, "recv_ms": 1787081841667, "bids": [[1000.0, 35.81], [14390.2, 0.14], [14490.2, 3.752], [14590.2, 0.308], [58221.1, 0.002], [61455.6, 0.0], [62102.5, 0.004], [63396.4, 0.018], [63752.2, 4.41], [64011.6, 0.019], [64043.3, 0.087], [64532.2, 4.933], [64532.3, 0.0], [64549.2, 4.917], [64621.6, 0.033], [64656.6, 0.095], [64656.7, 0.097], [64657.0, 0.1], [64658.7, 0.004], [64658.9, 0.003], [64660.1, 0.07], [64673.8, 0.004], [64674.8, 0.302], [64675.8, 0.942], [64678.5, 0.503], [64681.7, 0.001], [64682.8, 0.071], [64683.1, 0.319], [64683.6, 0.443], [64683.7, 0.089], [64684.1, 2.622], [64684.2, 0.142], [64684.3, 0.0], [64684.9, 0.033], [64685.1, 0.0], [64685.2, 0.598], [64685.6, 0.09], [64686.9, 0.363], [64690.2, 27.875]], "asks": [[64690.3, 3.159], [64693.4, 0.003], [64702.8, 0.598], [64704.3, 0.113], [64704.9, 0.347], [64706.3, 0.005], [64707.1, 0.024], [64708.2, 0.31], [64708.6, 0.0], [64709.0, 1.793], [64711.5, 0.0], [64712.0, 2.216], [64713.3, 0.001], [64714.0, 0.549], [64721.2, 0.238], [64726.1, 0.17], [64730.5, 0.112], [64731.4, 0.492], [64829.9, 5.399], [64846.9, 10.409], [64885.7, 9.779], [65337.2, 0.659], [65460.1, 2.596], [65757.7, 2.126]]}
{"kind": "depth", "E": 1787081841801, "U": 11315466310064, "u": 11315466320474, "recv_ms": 1787081841770, "bids": [[14390.2, 0.378], [14490.2, 3.626], [14590.2, 0.196], [58221.1, 0.002], [62102.5, 0.001], [63008.3, 0.0], [63690.2, 0.0], [63900.3, 0.004], [64043.3, 0.085], [64366.7, 2.638], [64573.6, 0.0], [64612.5, 0.237], [64620.7, 0.215], [64621.0, 0.047], [64628.1, 0.027], [64644.9, 0.008], [64656.8, 0.072], [64657.1, 0.072], [64658.9, 0.005], [64660.8, 1.184], [64675.6, 0.336], [64675.8, 0.016], [64676.8, 1.138], [64678.4, 2.061], [64678.5, 0.04], [64684.1, 2.081], [64684.8, 0.999], [64684.9, 1.045], [64685.6, 0.086]], "asks": [[64690.3, 3.157], [64710.0, 0.135], [64711.8, 0.154], [64712.0, 2.159], [64712.6, 0.078], [64714.0, 0.008], [64714.4, 0.546], [64723.1, 0.314], [64723.2, 0.4], [64726.6, 2.228], [64728.0, 1.098], [64728.7, 0.003], [64733.8, 3.766], [64739.3, 0.001], [64745.9, 0.047], [64747.3, 0.015], [64748.6, 0.016], [64771.7, 0.0], [64800.3, 0.395], [64805.8, 1.695], [64834.8, 0.03], [65013.8, 2.848], [65337.2, 0.659], [65528.3, 3.048], [65690.3, 0.0]]}
{"kind": "depth", "E": 1787081841903, "U": 11315466320505, "u": 11315466329402, "recv_ms": 1787081841872, "bids": [[1000.0, 35.81], [14390.2, 0.616], [14490.2, 3.514], [14590.2, 0.07], [58221.1, 0.002], [61455.6, 0.0], [63913.9, 11.999], [63968.9, 1.57], [63985.1, 1.324], [64043.3, 0.085], [64549.2, 0.16], [64573.6, 0.0], [64593.1, 0.009], [64628.1, 0.027], [64656.5, 0.086], [64656.7, 0.167], [64660.8, 1.184], [64669.5, 0.016], [64670.8, 2.326], [64671.6, 0.559], [64673.0, 0.117], [64675.6, 0.0], [64678.5, 0.503], [64678.6, 0.01], [64684.2, 0.737], [64684.8, 0.319], [64684.9, 0.574], [64685.1, 0.0], [64685.3, 0.089], [64685.7, 0.002], [64686.9, 0.451], [64690.2, 27.877]], "asks": [[64693.1, 0.004], [64693.4, 0.003], [64709.0, 0.868], [64709.5, 0.927], [64711.3, 0.012], [64711.9, 1.871], [64723.1, 0.468], [64723.2, 0.246], [64730.2, 10.115], [64733.8, 3.766], [64747.3, 0.001], [64762.8, 1.51], [64763.5, 0.0], [64765.4, 0.035], [64765.6, 0.441], [64765.7, 0.001], [64767.9, 32.681], [64771.7, 0.0], [64805.8, 0.011], [64829.9, 0.0], [64834.8, 0.03], [65337.2, 0.659], [65411.6, 0.764], [71159.4, 0.001]]}
{"kind": "depth", "E": 1787081842005, "U": 11315466329481, "u": 11315466336098, "recv_ms": 1787081841976, "bids": [[1000.0, 35.81], [14390.2, 0.91], [14490.2, 3.29], [14590.2, 0.0], [58221.1, 0.002], [62102.5, 0.004], [63690.2, 0.02], [64043.3, 0.085], [64187.0, 0.0], [64349.2, 0.494], [64349.5, 0.0], [64549.2, 0.16], [64656.6, 0.165], [64656.9, 1.669], [64657.1, 0.172], [64657.2, 0.16], [64657.3, 0.341], [64662.3, 0.521], [64678.6, 0.01], [64684.2, 0.737], [64685.1, 0.0], [64685.7, 0.002], [64690.2, 27.784]], "asks": [[64693.1, 0.002], [64700.1, 0.777], [64703.8, 0.046], [64715.3, 0.005], [64716.0, 0.258], [64723.1, 0.314], [64723.2, 0.4], [64765.7, 32.66], [64767.9, 0.022], [64829.9, 0.0], [64885.7, 9.922], [65337.2, 0.661], [65528.4, 0.765], [65690.3, 0.02], [71159.4, 0.0]]}
{"kind": "depth", "E": 1787081842107, "U": 11315466336199, "u": 11315466342084, "recv_ms": 1787081842075, "bids": [[14390.2, 1.26], [14490.2, 2.94], [58221.1, 0.002], [61455.6, 0.0], [61459.7, 0.0], [62102.5, 0.001], [63849.2, 0.469], [64043.3, 0.085], [64109.1, 0.005], [64366.7, 2.639], [64549.2, 4.799], [64618.7, 0.117], [64657.5, 0.521], [64661.9, 0.87], [64677.2, 1.043], [64678.6, 0.01], [64684.2, 0.737], [64685.1, 0.0], [64685.6, 0.086], [64685.7, 0.002], [64690.2, 27.786]], "asks": [[64690.3, 3.166], [64693.4, 0.003], [64698.8, 1.409], [64698.9, 1.116], [64700.1, 0.754], [64723.2, 0.4], [64829.9, 5.399], [64885.7, 10.202], [65013.8, 2.847], [65028.1, 0.462], [65337.2, 0.659]]}
{"kind": "depth", "E": 1787081842209, "U": 11315466342374, "u": 11315466349170, "recv_ms": 1787081842176, "bids": [[1000.0, 35.81], [14390.2, 1.61], [14490.2, 2.59], [51752.2, 0.0], [58221.1, 0.002], [61455.6, 0.0], [62102.5, 0.004], [63690.2, 0.0], [64043.3, 0.085], [64493.4, 7.079], [64532.2, 2.372], [64549.2, 2.887], [64573.6, 0.0], [64628.1, 0.027], [64638.7, 0.012], [64660.8, 1.184], [64678.6, 0.01], [64684.2, 0.737], [64685.1, 0.0], [64685.6, 0.086], [64690.2, 27.785]], "asks": [[64690.3, 3.15], [64698.7, 1.005], [64698.8, 1.409], [64699.5, 0.001], [64699.6, 0.003], [64723.2, 0.246], [64723.4, 1.327], [64733.8, 3.766], [64771.7, 0.0], [64834.8, 0.03], [64885.7, 15.413], [65337.2, 0.659], [65498.9, 14.658], [65690.3, 0.0], [65960.2, 0.649]]}
{"kind": "depth", "E": 1787081842311, "U": 11315466349358, "u": 11315466355668, "recv_ms": 1787081842279, "bids": [[1000.0, 35.81], [14390.2, 1.974], [14490.2, 2.226], [51752.0, 0.0], [58221.1, 0.002], [61455.8, 0.004], [62102.5, 0.001], [63771.6, 0.468], [64043.3, 0.087], [64106.9, 1.106], [64493.4, 9.92], [64532.2, 4.781], [64549.2, 4.796], [64678.6, 0.01], [64684.2, 0.057], [64685.1, 0.0]], "asks": [[64698.4, 0.022], [64698.6, 0.464], [64885.7, 10.205], [65013.8, 3.001], [65337.2, 0.659], [65713.9, 6.233]]}
{"kind": "depth", "E": 1787081842413, "U": 11315466355780, "u": 11315466361946, "recv_ms": 1787081842381, "bids": [[14390.2, 2.324], [14490.2, 1.876], [51752.0, 0.0], [58221.1, 0.002], [61455.6, 0.0], [63590.5, 1.574], [63690.2, 0.02], [64043.3, 0.085], [64366.7, 2.639], [64573.6, 0.0], [64628.1, 0.027], [64660.8, 1.184], [64685.6, 0.09]], "asks": [[64690.3, 3.152], [64693.4, 0.003], [64733.8, 3.766], [64771.7, 0.0], [64819.7, 0.004], [64834.8, 0.03], [65337.2, 0.659], [65649.2, 8.938], [65690.3, 0.02], [65900.0, 13.773], [65984.1, 0.018], [104929.0, 0.0]]}
{"kind": "depth", "E": 1787081842515, "U": 11315466362415, "u": 11315466373563, "recv_ms": 1787081842483, "bids": [[1000.0, 35.81], [14390.2, 2.688], [14490.2, 1.512], [58221.1, 0.002], [61455.6, 0.0], [62102.5, 0.004], [63774.9, 0.789], [64043.3, 0.085], [64532.2, 4.561], [64549.2, 4.626], [64605.3, 0.13], [64605.4, 0.003], [64677.2, 1.661], [64685.6, 0.086], [64690.2, 27.824]], "asks": [[64690.3, 3.136], [64698.4, 0.003], [64698.6, 0.441], [64721.1, 1.249], [64829.9, 5.399], [64844.8, 1.22], [64846.9, 10.409], [64885.7, 10.119], [65337.2, 0.659], [65640.0, 1.036], [65642.8, 5.223], [65799.7, 0.76]]}
{"kind": "depth", "E": 1787081842617, "U": 11315466373852, "u": 11315466382202, "recv_ms": 1787081842586, "bids": [[1000.0, 35.81], [14390.2, 3.038], [14490.2, 1.162], [51752.0, 0.0], [58221.1, 0.002], [62102.5, 0.001], [63396.4, 0.015], [63690.2, 0.0], [63858.9, 11.571], [63891.2, 4.665], [63957.9, 0.001], [64043.3, 0.085], [64625.5, 0.056], [64627.1, 6.888], [64660.1, 0.013], [64661.3, 0.059], [64672.3, 0.116], [64673.0, 0.001], [64678.5, 0.511], [64678.6, 0.002], [64683.6, 0.381], [64683.7, 0.151], [64684.1, 2.761], [64684.2, 0.057], [64684.9, 0.574], [64685.2, 0.057], [64685.3, 0.63], [64685.6, 0.09], [64690.2, 27.825]], "asks": [[64693.4, 0.003], [64696.0, 0.004], [64714.4, 0.005], [64715.1, 0.602], [64723.4, 1.173], [64723.5, 2.498], [64729.6, 3.721], [64844.8, 2.619], [65337.2, 0.659], [65628.3, 14.007], [65690.3, 0.0], [65693.0, 3.197], [65984.1, 0.015]]}
{"kind": "depth", "E": 1787081842719, "U": 11315466382503, "u": 11315466388487, "recv_ms": 1787081842686, "bids": [[14390.2, 3.402], [14490.2, 0.798], [58221.1, 0.002], [61455.6, 0.0], [62102.5, 0.004], [64043.3, 0.085], [64366.7, 2.639], [64673.8, 0.004], [64678.5, 0.503], [64678.6, 0.002], [64684.1, 2.081], [64684.2, 0.737], [64685.1, 0.008], [64685.6, 0.09], [64690.2, 27.824]], "asks": [[64694.4, 0.168], [64706.3, 0.005], [64804.1, 0.0], [65337.2, 0.659], [71159.3, 0.002], [104929.0, 0.236]]}
{"kind": "depth", "E": 1787081842821, "U": 11315466388642, "u": 11315466394183, "recv_ms": 1787081842789, "bids": [[1000.0, 35.81], [14290.2, 0.028], [14390.2, 3.696], [14490.2, 0.476], [58221.1, 0.002], [63615.2, 0.007], [63690.2, 0.02], [63772.5, 4.547], [63781.3, 1.724], [63849.2, 0.782], [63891.2, 4.314], [63946.3, 1.885], [64043.3, 0.085], [64146.8, 0.224], [64573.6, 0.0], [64628.1, 0.027], [64630.7, 0.115], [64660.8, 1.184], [64678.6, 0.01], [64684.2, 0.057], [64685.1, 0.0]], "asks": [[64733.8, 3.766], [64771.7, 0.0], [64790.6, 2.23], [64834.9, 0.0], [65013.8, 3.0], [65028.1, 0.308], [65337.2, 0.659], [65628.3, 16.137], [65690.3, 0.02], [71159.3, 0.0]]}
{"kind": "depth", "E": 1787081842923, "U": 11315466394583, "u": 11315466402855, "recv_ms": 1787081842892, "bids": [[1000.0, 35.81], [14290.2, 0.196], [14390.2, 3.724], [14490.2, 0.28], [58221.1, 0.002], [61455.6, 0.0], [62102.5, 0.001], [63690.2, 0.0], [64043.3, 0.085], [64146.8, 0.219], [64349.2, 0.002], [64349.4, 0.499], [64366.7, 2.64], [64532.2, 4.561], [64549.2, 4.626], [64669.9, 0.18], [64677.2, 1.043], [64685.6, 0.086], [64690.2, 27.9]], "asks": [[64690.3, 3.315], [64691.3, 0.502], [64693.4, 0.003], [64693.9, 0.004], [64696.6, 0.087], [64697.0, 0.007], [64697.7, 0.088], [64698.8, 1.411], [64709.5, 0.002], [64709.9, 2.163], [64712.6, 0.021], [64713.2, 0.404], [64721.1, 0.631], [64728.5, 0.628], [64730.2, 0.115], [64732.0, 10.041], [64755.9, 0.004], [64759.0, 0.022], [64829.9, 5.399], [64846.9, 10.409], [65337.2, 0.659], [65481.1, 9.426], [65690.3, 0.0]]}
{"kind": "depth", "E": 1787081843025, "U": 11315466402918, "u": 11315466409430, "recv_ms": 1787081842993, "bids": [[14290.2, 0.434], [14390.2, 3.598], [14490.2, 0.168], [58221.1, 0.002], [62102.5, 0.004], [64043.3, 0.085], [64146.8, 0.215], [64366.7, 2.64], [64644.9, 0.008], [64660.7, 0.285], [64661.3, 0.002], [64663.0, 0.066], [64677.2, 1.083], [64677.5, 0.022], [64679.8, 0.023], [64681.8, 0.0], [64684.8, 0.86], [64685.3, 0.089], [64685.7, 0.002], [64690.2, 27.818]], "asks": [[64690.3, 3.314], [64702.7, 0.001], [64702.8, 0.135], [64707.0, 0.005], [64707.1, 0.487], [64748.6, 0.016], [64846.9, 10.409], [64847.3, 0.001], [65337.2, 0.659], [65466.6, 17.876], [65508.9, 2.391], [65984.1, 0.012], [66642.9, 0.0], [66692.5, 0.002], [67213.4, 0.0]]}
{"kind": "depth", "E": 1787081843127, "U": 11315466409456, "u": 11315466414874, "recv_ms": 1787081843094, "bids": [[1000.0, 35.81], [14290.2, 0.672], [14390.2, 3.486], [14490.2, 0.042], [51752.0, 0.0], [58221.1, 0.002], [61455.6, 0.0], [62102.5, 0.001], [63620.7, 14.124], [63752.2, 5.507], [63766.3, 4.316], [63772.5, 3.451], [63808.4, 1.877], [63903.6, 0.781], [63966.6, 0.804], [64043.3, 0.085], [64146.8, 0.184], [64366.7, 2.639], [64618.7, 0.118], [64638.7, 0.011], [64678.6, 0.002], [64682.2, 0.001], [64685.1, 0.008], [64685.6, 0.09], [64690.1, 0.295], [64690.2, 27.819]], "asks": [[64690.3, 3.315], [64691.8, 0.003], [64693.4, 0.003], [64702.1, 0.012], [64719.2, 0.002], [64719.3, 0.051], [64719.4, 0.473], [64722.2, 0.006], [64722.3, 0.442], [64722.4, 0.0], [64723.0, 0.003], [64723.1, 0.312], [64723.2, 0.244], [64725.3, 0.317], [64725.4, 0.004], [64725.5, 0.001], [64739.3, 0.005], [64745.9, 0.043], [64760.2, 0.001], [65013.8, 3.155], [65337.2, 0.659], [65649.2, 7.873], [65778.6, 0.0]]}
{"kind": "depth", "E": 1787081843229, "U": 11315466415093, "u": 11315466422490, "recv_ms": 1787081843197, "bids": [[1000.0, 35.81], [14290.2, 0.994], [14390.2, 3.206], [14490.2, 0.0], [51752.0, 0.0], [51752.2, 0.0], [58221.1, 0.002], [61455.6, 0.0], [62102.5, 0.004], [63643.1, 1.29], [63690.2, 0.02], [64043.3, 0.085], [64678.5, 0.503], [64684.2, 0.057], [64684.3, 0.541], [64684.8, 0.319], [64685.1, 0.0], [64685.2, 0.057], [64685.3, 0.097], [64685.6, 0.09], [64690.2, 27.827]], "asks": [[64690.3, 3.313], [64709.0, 1.793], [64709.9, 1.238], [64714.0, 0.549], [64715.1, 0.061], [64746.7, 0.031], [64885.7, 9.922], [65337.2, 0.659], [65560.8, 0.804], [65607.6, 0.001], [65690.3, 0.02], [66631.0, 2.174]]}
{"kind": "depth", "E": 1787081843433, "U": 11315466429841, "u": 11315466436651, "recv_ms": 1787081843400, "bids": [[1000.0, 35.81], [14290.2, 1.694], [14390.2, 2.506], [58221.1, 0.002], [62102.5, 0.001], [63590.5, 2.359], [63622.8, 1.099], [63690.2, 0.0], [63752.2, 7.7], [64043.3, 0.085], [64651.3, 0.205], [64678.5, 0.503], [64685.1, 0.688], [64685.2, 0.057], [64685.3, 0.089]], "asks": [[64690.3, 3.297], [64723.4, 1.173], [64723.5, 2.344], [64819.7, 0.004], [65337.2, 0.659], [65690.3, 0.0], [65757.7, 3.189]]}
{"kind": "depth", "E": 1787081843535, "U": 11315466436683, "u": 11315466444461, "recv_ms": 1787081843505, "bids": [[1000.0, 35.81], [14290.2, 2.058], [14390.2, 2.142], [58221.1, 0.002], [61455.6, 0.0], [62102.5, 0.004], [63643.1, 0.191], [64043.3, 0.085], [64493.4, 6.584], [64532.2, 1.159], [64549.2, 2.31], [64573.6, 0.0], [64623.4, 2.074], [64623.8, 0.0], [64625.5, 0.056], [64628.0, 0.011], [64628.1, 0.027], [64633.4, 0.002], [64640.2, 0.04], [64660.8, 1.184], [64669.4, 0.723], [64676.8, 0.83], [64678.5, 0.503], [64680.7, 0.348], [64681.1, 2.32], [64682.3, 0.175], [64684.1, 2.445], [64684.2, 0.239], [64685.1, 0.688], [64685.2, 0.057], [64685.3, 0.089], [64685.6, 0.086], [64686.3, 0.089], [64690.2, 27.82]], "asks": [[64690.3, 3.3], [64693.4, 0.003], [64695.9, 0.085], [64698.6, 0.441], [64698.8, 1.391], [64698.9, 1.093], [64699.3, 0.043], [64700.9, 0.869], [64702.8, 0.135], [64720.7, 1.605], [64723.4, 1.173], [64723.5, 2.498], [64726.6, 2.214], [64728.1, 0.619], [64733.8, 3.766], [64756.0, 0.018], [64756.1, 0.0], [64765.6, 7.009], [64771.7, 0.0], [64834.9, 0.0], [64885.7, 15.413], [64896.4, 0.003], [64896.5, 0.0], [65100.0, 53.599], [65337.2, 0.659], [65400.6, 0.0], [65508.9, 2.049]]}
{"kind": "depth", "E": 1787081843637, "U": 11315466444635, "u": 11315466451172, "recv_ms": 1787081843605, "bids": [[14290.2, 2.408], [14390.2, 1.792], [58221.1, 0.002], [61455.6, 0.0], [62102.5, 0.001], [63396.4, 0.018], [63469.5, 0.016], [63690.2, 0.02], [63891.2, 3.963], [64043.3, 0.085], [64146.8, 0.119], [64366.7, 2.649], [64493.4, 10.011], [64532.2, 4.83], [64549.2, 4.837], [64576.2, 14.594], [64589.5, 0.002], [64590.7, 0.008], [64592.0, 2.303], [64592.1, 0.0], [64623.8, 2.801], [64678.5, 0.04], [64683.7, 0.089], [64683.9, 4.032], [64684.1, 2.081], [64684.2, 0.057], [64685.1, 0.008], [64685.2, 0.52], [64685.6, 0.09], [64690.1, 0.294]], "asks": [[64690.3, 3.319], [64694.4, 0.149], [64699.2, 0.304], [64723.5, 2.344], [64723.6, 0.157], [64756.1, 3.054], [64763.5, 32.567], [64765.4, 0.026], [64765.6, 0.441], [64765.7, 0.001], [64803.6, 10.764], [64816.7, 0.92], [64818.1, 0.039], [64885.7, 10.029], [65337.2, 0.659], [65477.0, 1.846], [65690.3, 0.02]]}
{"kind": "depth", "E": 1787081843739, "U": 11315466451251, "u": 11315466468885, "recv_ms": 1787081843707, "bids": [[1000.0, 35.81], [14290.2, 2.772], [14390.2, 1.428], [51752.0, 0.0], [58221.1, 0.002], [63707.8, 8.781], [63772.5, 2.355], [63922.8, 0.781], [64043.3, 0.085], [64146.8, 0.18], [64673.8, 0.004], [64678.5, 0.511], [64684.2, 0.057], [64685.1, 0.0], [64685.2, 0.057]], "asks": [[64693.4, 0.003], [64706.3, 0.005], [65337.2, 0.659], [65369.5, 0.839], [65482.8, 0.003], [65649.2, 6.808], [65713.9, 5.169]]}
{"kind": "depth", "E": 1787081843841, "U": 11315466469441, "u": 11315466477518, "recv_ms": 1787081843810, "bids": [[1000.0, 35.81], [14290.2, 3.136], [14390.2, 1.064], [58221.1, 0.002], [61455.6, 0.0], [62102.5, 0.004], [63622.8, 2.198], [63687.5, 3.48], [63690.2, 0.0], [63752.2, 8.797], [64043.3, 0.085], [64671.5, 0.044], [64673.0, 0.001], [64678.5, 0.503], [64684.2, 0.057], [64685.1, 0.008], [64685.2, 0.057], [64685.3, 0.089], [64685.6, 0.09], [64690.2, 27.82]], "asks": [[64698.6, 0.457], [64702.8, 0.119], [64723.5, 2.498], [64723.6, 0.003], [64723.7, 0.0], [65337.2, 0.659], [65476.1, 0.763], [65628.3, 18.267], [65690.3, 0.0], [65693.0, 4.261]]}
{"kind": "depth", "E": 1787081843943, "U": 11315466477624, "u": 11315466484226, "recv_ms": 1787081843913, "bids": [[14290.2, 3.486], [14390.2, 0.714], [58221.1, 0.002], [61455.6, 0.0], [61455.7, 0.008], [62102.5, 0.001], [63847.3, 6.412], [64043.3, 0.085], [64146.8, 0.143], [64172.8, 0.005], [64349.3, 0.978], [64349.4, 0.007], [64366.7, 2.648], [64381.0, 2.181], [64640.2, 0.036], [64647.0, 0.005], [64660.1, 0.07], [64660.7, 0.228], [64670.9, 2.715], [64671.6, 0.002], [64672.8, 0.002], [64672.9, 0.501], [64673.0, 0.001], [64678.5, 0.511], [64678.8, 0.0], [64679.0, 0.012], [64684.0, 2.635], [64684.1, 2.081], [64684.2, 0.057], [64685.1, 0.0], [64685.2, 0.057], [64685.3, 0.089], [64685.6, 0.086], [64687.1, 0.284], [64690.2, 27.825]], "asks": [[64690.3, 3.317], [64693.4, 0.003], [64694.2, 0.013], [64694.5, 0.136], [64696.8, 0.01], [64697.2, 0.001], [64697.6, 1.148], [64698.5, 0.556], [64698.6, 0.441], [64698.8, 1.411], [64699.0, 1.026], [64700.8, 0.249], [64702.8, 0.111], [64703.3, 0.447], [64704.0, 0.466], [64704.3, 0.422], [64704.9, 0.327], [64705.6, 0.003], [64707.0, 0.029], [64711.0, 0.0], [64711.3, 0.032], [64711.9, 1.928], [64712.7, 0.323], [64713.2, 0.347], [64723.5, 2.344], [64723.6, 0.157], [64763.5, 0.0], [64765.4, 0.044], [64765.7, 32.477], [64767.9, 0.022], [64846.9, 0.0], [64847.3, 7.628], [65013.8, 3.156], [65028.1, 0.154], [65222.2, 0.655], [65337.2, 0.659], [65337.3, 10.779], [65466.6, 19.402]]}
{"kind": "depth", "E": 1787081844045, "U": 11315466484325, "u": 11315466492681, "recv_ms": 1787081844014, "bids": [[1000.0, 35.81], [14190.2, 0.056], [14290.2, 3.724], [14390.2, 0.42], [58221.1, 0.002], [61455.6, 0.0], [62102.5, 0.004], [63396.4, 0.015], [63690.2, 0.02], [64043.3, 0.085], [64669.4, 0.105], [64676.8, 0.212], [64678.5, 0.503], [64678.6, 0.015], [64685.1, 0.0], [64685.2, 0.057], [64685.6, 0.09], [64685.8, 0.014], [64690.2, 27.826]], "asks": [[64690.3, 3.316], [64694.5, 0.136], [64696.5, 0.005], [64696.7, 0.001], [64696.8, 0.01], [64698.4, 0.544], [64698.5, 0.015], [64698.8, 1.391], [64699.0, 1.003], [64702.8, 0.034], [64704.0, 0.386], [64704.4, 1.084], [64704.7, 0.275], [64707.0, 0.106], [64719.2, 0.004], [64719.3, 0.053], [64719.4, 0.475], [64720.7, 0.987], [64722.2, 0.008], [64722.3, 0.444], [64722.4, 0.002], [64723.0, 0.005], [64723.1, 0.314], [64723.2, 0.246], [64723.6, 0.003], [64723.7, 0.154], [64725.3, 0.319], [64725.4, 0.006], [64725.5, 0.003], [64726.6, 2.228], [64728.1, 0.001], [64763.5, 32.156], [64765.4, 0.026], [64765.7, 0.001], [64846.9, 10.409], [64847.3, 0.001], [65337.2, 0.659], [65690.3, 0.02]]}
{"kind": "depth", "E": 1787081844147, "U": 11315466492692, "u": 11315466508918, "recv_ms": 1787081844137, "bids": [[1000.0, 35.81], [14190.2, 0.252], [14290.2, 3.682], [14390.2, 0.266], [51752.0, 0.0], [58221.1, 0.002], [61455.6, 0.0], [62102.5, 0.001], [63396.4, 0.018], [63690.2, 0.0], [63697.1, 0.649], [63707.8, 8.779], [63710.8, 0.024], [63847.3, 5.662], [64043.3, 0.093], [64247.1, 0.001], [64366.7, 2.649], [64566.8, 0.177], [64573.7, 0.002], [64584.0, 5.273], [64584.1, 0.077], [64604.9, 0.63], [64605.2, 0.021], [64605.3, 0.127], [64605.7, 0.0], [64611.6, 0.159], [64618.7, 0.119], [64622.9, 40.702], [64625.0, 1.59], [64628.0, 0.002], [64628.2, 0.791], [64629.5, 0.04], [64638.6, 0.375], [64643.5, 0.009], [64646.7, 0.028], [64647.1, 0.101], [64660.9, 3.566], [64661.1, 0.143], [64664.2, 0.017], [64665.9, 0.002], [64669.7, 0.088], [64672.8, 0.156], [64672.9, 0.347], [64677.1, 0.0], [64678.5, 0.04], [64678.6, 0.002], [64679.4, 0.337], [64680.7, 0.176], [64682.1, 0.034], [64683.1, 0.3], [64685.0, 0.413], [64685.1, 0.471], [64685.2, 0.057], [64685.6, 0.086], [64685.8, 0.034], [64686.1, 0.003], [64687.0, 0.022], [64687.3, 0.334], [64688.0, 0.335], [64688.6, 0.066], [64688.9, 0.017], [64689.9, 0.42], [64690.1, 0.294], [64690.2, 31.533], [64690.3, 6.474], [64690.4, 9.651], [64690.5, 3.93], [64691.1, 2.933], [64691.2, 1.147], [64691.4, 0.001], [64691.5, 4.236], [64691.6, 8.699], [64691.7, 1.497], [64691.8, 2.954], [64691.9, 2.337], [64692.0, 0.305], [64692.1, 0.0], [64692.3, 0.778], [64692.5, 0.274], [64692.6, 2.578], [64692.8, 0.986], [64693.1, 40.738]], "asks": [[64690.3, 0.0], [64690.4, 0.0], [64690.5, 0.0], [64691.2, 0.0], [64691.3, 0.0], [64691.7, 0.0], [64691.8, 0.0], [64691.9, 0.0], [64692.0, 0.0], [64692.1, 0.0], [64692.2, 0.0], [64692.4, 0.0], [64692.6, 0.0], [64692.7, 0.0], [64692.9, 0.0], [64693.0, 0.0], [64693.1, 0.0], [64693.2, 0.292], [64693.3, 0.001], [64693.4, 0.003], [64693.5, 0.008], [64693.7, 0.003], [64694.2, 0.002], [64694.5, 0.128], [64694.7, 0.001], [64695.9, 0.001], [64696.1, 0.147], [64696.5, 0.002], [64696.6, 0.003], [64696.8, 0.002], [64697.0, 0.014], [64697.1, 0.005], [64697.3, 0.001], [64697.5, 0.125], [64697.6, 1.147], [64697.7, 0.004], [64698.5, 0.091], [64698.7, 1.007], [64699.2, 0.405], [64699.3, 0.021], [64699.4, 0.09], [64700.0, 0.005], [64700.1, 0.714], [64700.5, 0.088], [64700.8, 0.25], [64700.9, 0.866], [64702.1, 0.0], [64702.8, 0.111], [64702.9, 0.188], [64703.4, 0.018], [64703.6, 0.004], [64704.0, 0.382], [64704.2, 0.741], [64704.7, 0.315], [64706.4, 0.004], [64707.0, 0.009], [64707.5, 0.218], [64707.9, 0.173], [64709.0, 0.708], [64709.5, 0.012], [64709.6, 1.388], [64710.0, 0.128], [64710.1, 0.164], [64711.3, 0.012], [64711.5, 0.007], [64711.6, 0.024], [64711.8, 0.162], [64711.9, 1.871], [64712.8, 0.059], [64713.0, 0.019], [64713.3, 0.021], [64713.6, 1.475], [64713.7, 0.002], [64714.0, 0.008], [64714.2, 0.036], [64714.6, 0.888], [64719.1, 0.016], [64720.8, 2.32], [64721.5, 0.231], [64723.5, 2.351], [64723.7, 0.154], [64724.0, 0.063], [64725.8, 0.008], [64732.0, 0.041], [64733.9, 0.169], [64734.9, 10.04], [64735.5, 0.0], [64735.6, 0.003], [64738.2, 0.033], [64739.5, 0.003], [64747.3, 0.015], [64748.1, 0.019], [64752.4, 0.025], [64756.4, 0.638], [64767.9, 32.178], [64771.7, 0.0], [64801.4, 0.0], [64802.2, 2.772], [64834.9, 0.0], [64846.9, 0.0], [64847.3, 7.609], [65013.8, 3.155], [65337.2, 0.665], [65683.5, 0.017], [65690.3, 0.0], [65852.0, 2.274], [65984.1, 0.012]]}
{"kind": "depth", "E": 1787081844249, "U": 11315466508926, "u": 11315466547000, "recv_ms": 1787081844331, "bids": [[14191.6, 0.014], [14193.1, 0.042], [14193.5, 0.182], [14290.2, 3.458], [14293.1, 0.028], [14293.5, 0.084], [14390.2, 0.14], [51752.0, 0.0], [51752.2, 0.0], [58221.1, 0.0], [58222.4, 0.0], [58224.1, 0.002], [61458.8, 0.003], [63693.1, 0.037], [63693.5, 0.046], [63697.0, 0.024], [63702.0, 0.683], [63705.8, 0.001], [63708.1, 0.0], [63710.8, 0.018], [63816.9, 1.027], [64043.3, 0.085], [64046.2, 0.07], [64046.6, 0.002], [64366.7, 2.794], [64487.1, 0.001], [64511.1, 0.399], [64514.2, 0.435], [64514.3, 0.001], [64527.6, 0.0], [64547.3, 0.018], [64576.6, 4.205], [64577.3, 0.001], [64587.4, 0.408], [64592.9, 0.082], [64597.9, 0.008], [64598.5, 0.008], [64603.1, 0.006], [64610.0, 0.912], [64611.6, 0.154], [64612.0, 0.375], [64612.5, 0.24], [64615.9, 0.203], [64616.2, 0.0], [64617.1, 0.027], [64617.6, 6.316], [64618.4, 0.0], [64620.9, 0.145], [64621.5, 0.0], [64622.7, 0.006], [64622.8, 41.111], [64622.9, 0.003], [64625.5, 0.026], [64627.1, 1.101], [64627.8, 0.012], [64628.8, 3.565], [64629.1, 1.912], [64629.2, 0.005], [64629.5, 0.034], [64630.3, 0.023], [64630.6, 0.0], [64630.7, 0.015], [64632.1, 2.831], [64632.2, 1.156], [64633.2, 0.005], [64635.0, 1.626], [64635.1, 0.001], [64635.3, 0.411], [64635.7, 0.175], [64637.7, 0.084], [64639.7, 0.033], [64640.3, 0.045], [64641.5, 2.148], [64642.1, 1.229], [64644.9, 0.007], [64645.3, 0.0], [64645.5, 0.002], [64645.8, 0.002], [64646.1, 0.125], [64646.7, 0.027], [64647.3, 0.02], [64647.5, 0.001], [64647.9, 0.036], [64649.0, 0.642], [64649.7, 2.13], [64649.8, 0.004], [64650.1, 0.0], [64650.3, 0.0], [64651.0, 0.0], [64652.0, 0.329], [64652.5, 0.226], [64653.4, 1.96], [64654.8, 0.007], [64655.0, 0.146], [64655.1, 0.066], [64655.2, 1.765], [64655.4, 0.007], [64655.5, 0.199], [64656.6, 0.151], [64656.8, 0.132], [64657.9, 0.434], [64658.2, 0.011], [64660.1, 0.013], [64661.6, 0.002], [64661.9, 0.716], [64662.6, 0.014], [64663.2, 0.059], [64663.3, 0.003], [64663.6, 0.002], [64663.9, 0.001], [64664.5, 0.019], [64664.6, 0.312], [64664.9, 0.008], [64665.1, 1.241], [64665.5, 0.003], [64665.7, 0.175], [64665.8, 0.016], [64666.5, 0.474], [64667.5, 0.37], [64667.6, 0.023], [64667.7, 0.3], [64668.1, 0.496], [64668.2, 0.192], [64668.8, 0.012], [64669.0, 0.001], [64669.1, 0.02], [64669.9, 0.295], [64670.1, 0.005], [64670.6, 0.368], [64670.8, 2.325], [64670.9, 2.158], [64671.0, 0.329], [64671.4, 0.069], [64672.3, 0.0], [64672.6, 0.011], [64673.0, 0.001], [64673.8, 0.561], [64674.0, 0.555], [64674.1, 0.131], [64674.2, 0.144], [64674.7, 0.342], [64675.0, 0.395], [64675.2, 1.693], [64675.3, 0.633], [64675.4, 0.032], [64675.8, 0.001], [64675.9, 0.0], [64676.0, 0.802], [64676.2, 0.003], [64676.4, 0.033], [64677.0, 0.9], [64677.2, 0.041], [64677.3, 0.002], [64677.4, 0.003], [64677.6, 0.002], [64678.0, 0.902], [64678.1, 0.602], [64678.2, 1.023], [64678.6, 0.213], [64678.7, 0.019], [64678.8, 0.0], [64678.9, 0.001], [64679.0, 0.001], [64679.1, 0.243], [64679.2, 0.069], [64679.3, 0.066], [64679.4, 0.001], [64679.9, 0.023], [64680.0, 1.62], [64680.2, 0.465], [64680.5, 1.046], [64680.6, 0.014], [64680.7, 0.169], [64681.2, 0.913], [64681.3, 0.16], [64681.4, 0.002], [64681.6, 1.253], [64681.7, 0.001], [64682.0, 0.006], [64682.1, 0.027], [64682.3, 0.094], [64682.5, 0.023], [64682.8, 0.119], [64683.0, 0.07], [64683.4, 0.361], [64683.5, 0.189], [64683.7, 0.074], [64683.8, 0.032], [64683.9, 3.675], [64684.1, 2.081], [64684.2, 0.691], [64684.3, 0.003], [64684.8, 0.319], [64684.9, 0.379], [64685.0, 0.008], [64685.1, 0.0], [64685.2, 0.033], [64685.3, 0.012], [64685.4, 0.005], [64685.5, 0.157], [64685.6, 0.002], [64685.7, 0.002], [64685.8, 0.014], [64685.9, 0.0], [64686.0, 0.136], [64686.3, 0.095], [64686.8, 0.01], [64686.9, 0.396], [64687.0, 0.036], [64687.1, 0.284], [64687.2, 0.003], [64687.3, 0.806], [64687.8, 0.269], [64687.9, 0.431], [64688.0, 0.346], [64688.1, 0.079], [64688.2, 0.004], [64688.3, 0.0], [64688.6, 0.063], [64689.0, 0.001], [64689.1, 0.055], [64689.2, 0.001], [64689.3, 0.008], [64689.4, 0.131], [64689.6, 0.036], [64689.8, 0.514], [64689.9, 0.542], [64690.0, 0.005], [64690.1, 0.01], [64690.2, 5.074], [64690.3, 2.503], [64690.4, 0.427], [64690.5, 0.02], [64690.9, 0.001], [64691.0, 0.002], [64691.1, 0.002], [64691.2, 1.742], [64691.3, 0.001], [64691.4, 0.0], [64691.5, 0.001], [64691.6, 0.089], [64691.7, 0.002], [64691.8, 0.001], [64691.9, 0.0], [64692.0, 0.001], [64692.1, 0.0], [64692.3, 0.31], [64692.4, 0.019], [64692.5, 0.001], [64692.6, 0.001], [64692.8, 0.0], [64692.9, 0.0], [64693.0, 0.001], [64693.1, 0.949], [64693.2, 0.003], [64693.3, 0.001], [64693.4, 0.055], [64693.5, 39.894]], "asks": [[64693.2, 0.0], [64693.3, 0.0], [64693.4, 0.0], [64693.5, 0.0], [64693.6, 2.579], [64693.7, 0.005], [64693.8, 0.001], [64693.9, 0.002], [64694.0, 0.598], [64694.2, 0.0], [64694.3, 0.479], [64694.4, 0.033], [64694.5, 0.003], [64694.6, 0.0], [64694.7, 0.001], [64694.8, 0.001], [64695.0, 0.004], [64695.1, 0.001], [64695.4, 0.065], [64695.5, 0.0], [64695.6, 0.0], [64695.7, 0.007], [64696.0, 0.003], [64696.1, 0.148], [64696.2, 0.001], [64696.3, 0.002], [64696.4, 0.001], [64696.6, 1.751], [64696.8, 0.005], [64696.9, 0.0], [64697.0, 0.005], [64697.1, 0.004], [64697.5, 0.013], [64697.6, 1.6], [64698.0, 0.005], [64698.1, 1.904], [64698.2, 0.003], [64698.3, 0.004], [64698.4, 0.137], [64698.5, 1.675], [64698.6, 0.0], [64698.7, 0.012], [64698.8, 0.389], [64698.9, 0.01], [64699.0, 0.003], [64699.1, 0.002], [64699.2, 0.329], [64699.3, 0.003], [64699.4, 0.169], [64699.8, 0.085], [64699.9, 0.002], [64700.0, 0.004], [64700.1, 2.331], [64700.2, 0.551], [64700.3, 2.27], [64700.4, 0.294], [64700.5, 0.003], [64700.6, 1.002], [64700.7, 0.003], [64700.8, 0.334], [64700.9, 0.56], [64701.0, 0.008], [64701.1, 0.086], [64701.4, 0.003], [64701.5, 0.163], [64701.7, 0.089], [64701.8, 0.001], [64702.0, 0.085], [64702.1, 0.008], [64702.2, 0.002], [64702.3, 0.003], [64702.5, 0.085], [64702.6, 0.001], [64702.7, 0.001], [64702.8, 0.034], [64702.9, 0.286], [64703.0, 0.315], [64703.2, 0.042], [64703.3, 0.532], [64703.4, 0.018], [64703.5, 0.425], [64703.6, 0.004], [64703.7, 0.0], [64703.8, 0.509], [64703.9, 0.011], [64704.0, 0.265], [64704.1, 0.053], [64704.2, 0.125], [64704.3, 0.216], [64704.4, 1.084], [64704.5, 2.515], [64704.6, 0.589], [64704.7, 0.41], [64704.9, 0.325], [64705.0, 1.132], [64705.1, 0.298], [64705.2, 0.24], [64705.4, 0.001], [64705.6, 0.003], [64705.8, 0.006], [64705.9, 0.001], [64706.0, 1.122], [64706.1, 0.312], [64706.2, 0.0], [64706.4, 0.174], [64706.5, 0.002], [64706.6, 0.002], [64707.0, 0.009], [64707.1, 0.024], [64707.5, 0.221], [64708.0, 0.003], [64708.3, 0.0], [64708.5, 0.214], [64708.7, 0.018], [64708.8, 0.499], [64709.0, 0.628], [64709.3, 0.584], [64709.4, 0.039], [64709.5, 0.023], [64709.6, 0.464], [64709.7, 0.002], [64710.0, 0.132], [64710.1, 0.119], [64710.2, 0.124], [64710.8, 2.453], [64711.1, 0.003], [64711.2, 0.071], [64711.3, 0.005], [64711.4, 0.037], [64711.5, 0.0], [64711.6, 0.025], [64711.7, 0.035], [64711.8, 0.0], [64711.9, 1.3], [64712.0, 2.212], [64712.1, 0.001], [64712.4, 0.955], [64712.6, 0.681], [64712.7, 0.003], [64712.8, 0.007], [64712.9, 0.16], [64713.0, 0.312], [64713.1, 0.164], [64713.2, 0.354], [64713.3, 0.021], [64713.4, 0.378], [64713.5, 2.415], [64713.6, 1.012], [64713.7, 0.007], [64714.5, 0.913], [64714.6, 0.223], [64715.1, 0.12], [64715.2, 1.133], [64715.4, 0.126], [64715.5, 1.184], [64715.8, 0.268], [64716.0, 0.143], [64716.5, 0.003], [64716.6, 0.054], [64716.7, 0.04], [64717.3, 0.322], [64717.8, 0.043], [64717.9, 0.167], [64718.0, 0.041], [64718.1, 0.548], [64718.3, 0.003], [64718.5, 1.661], [64719.1, 0.02], [64719.3, 0.004], [64719.4, 0.49], [64719.5, 0.195], [64719.7, 0.169], [64720.0, 0.021], [64720.2, 0.605], [64720.8, 2.32], [64721.1, 0.64], [64721.9, 0.003], [64722.1, 0.062], [64723.1, 0.314], [64723.2, 0.246], [64723.5, 2.332], [64723.7, 0.0], [64723.9, 0.31], [64724.0, 0.043], [64724.1, 0.007], [64724.4, 0.421], [64724.6, 0.119], [64724.8, 1.094], [64725.3, 0.199], [64725.8, 0.003], [64726.1, 0.324], [64726.5, 0.043], [64727.0, 0.088], [64727.1, 0.31], [64727.4, 0.001], [64727.5, 1.77], [64727.8, 0.05], [64727.9, 0.298], [64728.1, 0.103], [64729.2, 0.08], [64729.6, 2.537], [64730.1, 0.008], [64730.3, 0.004], [64730.4, 0.054], [64731.3, 0.284], [64731.7, 3.921], [64731.8, 0.414], [64732.0, 0.041], [64732.1, 0.0], [64732.2, 10.006], [64732.7, 0.026], [64733.7, 1.783], [64733.8, 3.764], [64733.9, 0.038], [64734.5, 0.002], [64734.9, 0.064], [64735.0, 0.698], [64735.3, 0.001], [64735.9, 0.128], [64736.7, 1.206], [64736.9, 3.984], [64738.7, 0.002], [64739.3, 0.001], [64740.9, 0.028], [64741.0, 0.0], [64741.4, 0.059], [64741.5, 0.028], [64741.6, 0.003], [64742.1, 0.017], [64742.4, 0.007], [64745.2, 0.148], [64747.6, 0.383], [64747.9, 9.027], [64748.4, 0.035], [64748.5, 0.0], [64748.9, 0.071], [64749.0, 1.759], [64749.1, 2.447], [64749.7, 0.002], [64750.2, 0.018], [64751.6, 0.0], [64751.7, 0.064], [64751.9, 0.004], [64752.0, 1.205], [64752.4, 0.005], [64753.8, 0.0], [64754.3, 0.0], [64756.4, 0.632], [64756.7, 0.233], [64757.0, 0.081], [64758.4, 0.001], [64759.7, 0.077], [64763.3, 0.068], [64763.5, 0.0], [64764.0, 1.676], [64767.9, 0.022], [64769.8, 0.0], [64770.8, 0.04], [64772.0, 0.003], [64772.6, 0.034], [64773.9, 0.001], [64774.0, 0.002], [64776.7, 32.158], [64788.7, 0.463], [64790.6, 2.231], [64792.4, 0.035], [64798.9, 2.105], [64803.2, 0.003], [64803.4, 0.0], [64805.0, 16.078], [64805.6, 0.0], [64807.1, 2.599], [64807.2, 10.629], [64807.3, 0.0], [64807.6, 0.013], [64808.7, 0.002], [64819.9, 0.0], [64822.9, 0.448], [64823.0, 0.005], [64823.2, 0.024], [64823.6, 1.677], [64823.7, 0.0], [64828.2, 0.215], [64829.0, 3.958], [64829.7, 0.001], [64844.8, 1.22], [64847.3, 0.001], [64850.2, 7.645], [64876.1, 0.002], [64879.3, 0.005], [64960.0, 6.063], [64961.6, 4.4], [65016.9, 0.154], [65019.9, 0.001], [65027.3, 0.0], [65035.3, 0.115], [65210.6, 0.306], [65337.2, 0.752], [65338.6, 2.4], [65340.1, 0.0], [65340.5, 0.115], [65434.9, 0.057], [65437.6, 4.758], [65437.7, 3.645], [65438.0, 6.99], [65499.6, 0.0], [65502.3, 0.759], [65502.4, 2.268], [65502.7, 5.292], [65683.4, 0.018], [65987.0, 0.344]]}
{"kind": "depth", "E": 1787081844351, "U": 11315466547006, "u": 11315466563910, "recv_ms": 1787081844339, "bids": [[1000.0, 35.81], [14193.5, 0.42], [14290.2, 3.22], [14293.5, 0.21], [14390.2, 0.014], [51752.0, 0.0], [51755.0, 0.0], [58224.1, 0.002], [61458.8, 0.003], [62105.7, 0.038], [63396.4, 0.015], [63399.7, 0.013], [63693.5, 0.066], [63816.9, 1.777], [64046.6, 0.0], [64091.2, 0.0], [64511.1, 0.398], [64612.5, 0.237], [64622.8, 0.412], [64623.5, 6.287], [64623.8, 0.0], [64627.2, 40.712], [64644.9, 0.004], [64648.2, 0.006], [64649.0, 0.638], [64654.6, 0.377], [64655.3, 1.296], [64663.2, 0.002], [64664.2, 0.074], [64664.3, 0.37], [64664.9, 0.006], [64665.7, 0.175], [64668.2, 0.194], [64668.8, 0.015], [64673.0, 0.001], [64674.1, 0.132], [64677.5, 0.02], [64679.5, 0.025], [64679.6, 1.246], [64680.0, 0.694], [64680.2, 0.465], [64680.6, 0.006], [64680.8, 0.002], [64681.3, 0.08], [64682.0, 0.906], [64683.3, 0.187], [64683.9, 3.674], [64684.8, 0.868], [64684.9, 0.387], [64685.4, 0.004], [64685.5, 0.172], [64686.0, 0.121], [64687.3, 0.265], [64687.4, 0.0], [64688.1, 0.148], [64689.6, 0.016], [64690.0, 0.006], [64690.1, 0.006], [64690.2, 3.886], [64690.4, 0.43], [64691.6, 0.087], [64692.0, 0.002], [64693.1, 0.969], [64693.3, 0.004], [64693.4, 0.056], [64693.5, 40.897]], "asks": [[64693.6, 2.23], [64694.0, 0.0], [64694.9, 0.854], [64696.3, 0.002], [64696.5, 0.01], [64697.5, 0.016], [64698.0, 0.129], [64698.4, 0.005], [64698.5, 0.008], [64699.9, 0.01], [64700.0, 0.545], [64700.2, 0.01], [64700.3, 0.394], [64700.7, 0.001], [64700.8, 0.335], [64701.0, 0.009], [64702.0, 0.085], [64702.4, 0.295], [64703.0, 0.313], [64704.0, 0.267], [64704.3, 0.216], [64704.6, 0.588], [64704.8, 0.25], [64706.0, 0.222], [64706.1, 0.31], [64706.3, 0.007], [64707.2, 1.63], [64709.0, 1.528], [64712.4, 0.03], [64712.6, 0.663], [64712.7, 0.004], [64713.0, 0.313], [64713.3, 0.946], [64713.7, 0.0], [64714.9, 0.007], [64715.1, 0.063], [64715.5, 0.646], [64715.6, 0.589], [64715.7, 0.058], [64716.5, 0.559], [64717.6, 0.001], [64718.0, 0.542], [64718.1, 0.007], [64718.9, 0.264], [64720.1, 0.016], [64720.6, 0.179], [64720.7, 1.007], [64723.2, 0.246], [64724.3, 0.016], [64726.5, 0.133], [64727.8, 0.071], [64727.9, 0.278], [64730.1, 0.006], [64733.3, 0.003], [64733.7, 1.693], [64735.0, 0.628], [64735.4, 0.312], [64735.9, 0.127], [64738.6, 0.003], [64740.0, 1.115], [64748.6, 0.013], [64749.1, 2.443], [64751.9, 0.007], [64752.8, 0.013], [64755.8, 0.005], [64755.9, 0.006], [64756.8, 1.204], [64767.9, 32.178], [64776.7, 0.002], [64790.6, 2.131], [64803.2, 0.0], [64805.2, 0.0], [64807.8, 0.138], [64823.0, 0.006], [64850.2, 0.1], [64851.4, 2.661], [64852.6, 10.409], [64876.1, 0.001], [64878.3, 1.857], [64879.8, 0.0], [64885.7, 12.503], [65337.9, 0.003], [65340.5, 0.113], [65341.1, 0.379], [65693.6, 0.026], [65987.4, 0.003]]}
{"kind": "depth", "E": 1787081844453, "U": 11315466564142, "u": 11315466574944, "recv_ms": 1787081844423, "bids": [[1000.0, 35.81], [14193.5, 0.77], [14290.2, 2.968], [14293.5, 0.126], [14390.2, 0.0], [58224.1, 0.002], [62105.7, 0.035], [63763.6, 5.421], [63771.6, 0.702], [63881.6, 1.957], [64046.6, 0.0], [64102.2, 0.012], [64469.3, 0.001], [64498.7, 0.219], [64625.1, 40.701], [64627.2, 0.013], [64649.3, 1.678], [64650.0, 4.045], [64658.2, 0.001], [64658.7, 0.014], [64659.4, 0.006], [64663.3, 0.06], [64664.2, 0.017], [64668.3, 0.001], [64669.9, 0.18], [64671.5, 0.046], [64674.1, 0.017], [64674.7, 0.006], [64675.6, 0.002], [64676.2, 0.001], [64677.2, 0.001], [64678.6, 0.549], [64683.3, 0.186], [64684.9, 0.427], [64686.4, 0.009], [64686.8, 0.002], [64688.1, 0.148], [64689.4, 0.086], [64689.6, 0.016], [64689.9, 0.519], [64690.2, 3.864], [64690.3, 2.505], [64691.6, 0.086], [64691.7, 0.001], [64692.4, 0.046], [64693.1, 0.968], [64693.2, 0.002], [64693.4, 0.075], [64693.5, 43.846]], "asks": [[64693.6, 2.231], [64696.0, 0.002], [64696.1, 0.147], [64696.5, 0.018], [64696.7, 0.002], [64696.8, 0.004], [64697.6, 1.189], [64699.2, 0.245], [64701.0, 0.007], [64701.6, 0.018], [64704.0, 0.266], [64706.9, 0.036], [64707.0, 0.001], [64710.1, 0.004], [64711.6, 0.95], [64711.9, 1.34], [64712.0, 2.097], [64713.3, 0.021], [64714.2, 0.001], [64716.4, 0.002], [64716.7, 0.581], [64718.0, 0.001], [64718.9, 0.224], [64735.6, 0.118], [64737.0, 0.121], [64752.0, 1.195], [64752.5, 0.011], [64823.0, 0.005], [64850.2, 7.481], [64852.6, 0.001], [65340.5, 0.117]]}
{"kind": "depth", "E": 1787081844555, "U": 11315466575038, "u": 11315466587193, "recv_ms": 1787081844525, "bids": [[14193.5, 1.12], [14290.2, 2.744], [14293.5, 0.0], [58224.1, 0.002], [61458.8, 0.003], [62105.7, 0.038], [63928.0, 10.151], [64046.6, 0.0], [64075.6, 1.479], [64186.9, 0.931], [64366.7, 2.794], [64424.0, 1.935], [64425.6, 0.581], [64625.5, 0.027], [64627.1, 7.042], [64636.0, 0.361], [64670.7, 0.79], [64671.4, 0.032], [64678.0, 1.52], [64678.8, 0.926], [64678.9, 0.038], [64679.6, 0.32], [64679.7, 0.01], [64680.7, 0.162], [64682.8, 0.121], [64682.9, 0.222], [64683.8, 0.025], [64687.8, 0.391], [64688.1, 0.148], [64689.5, 0.001], [64690.1, 0.004], [64690.2, 3.858], [64690.4, 0.427], [64693.4, 0.23], [64693.5, 42.921]], "asks": [[64693.7, 0.005], [64693.8, 0.0], [64693.9, 0.0], [64694.2, 0.001], [64694.9, 0.0], [64696.0, 0.421], [64696.5, 0.019], [64696.7, 0.003], [64696.8, 0.855], [64697.8, 0.002], [64707.9, 0.176], [64715.7, 0.074], [64719.8, 0.62], [64726.0, 0.159], [64727.1, 0.928], [64755.0, 0.201], [64756.0, 1.494], [64759.5, 6.563], [64851.4, 1.269], [65340.5, 0.113]]}
{"kind": "depth", "E": 1787081844657, "U": 11315466587468, "u": 11315466595197, "recv_ms": 1787081844627, "bids": [[1000.0, 35.81], [14193.5, 1.47], [14290.2, 2.422], [14293.1, 0.0], [51752.0, 0.0], [58224.1, 0.002], [61458.8, 0.003], [62105.7, 0.035], [63693.5, 0.046], [63729.8, 0.0], [63891.2, 3.611], [64046.6, 0.0], [64221.6, 0.001], [64381.0, 2.026], [64549.2, 0.16], [64625.1, 0.002], [64627.1, 1.101], [64627.2, 40.712], [64658.7, 0.004], [64659.2, 0.46], [64667.6, 0.053], [64689.4, 0.09], [64693.5, 42.935]], "asks": [[64693.6, 2.27], [64695.0, 0.002], [64698.8, 0.004], [64704.1, 0.055], [64726.0, 0.005], [64741.4, 0.063], [64752.5, 0.001], [64753.0, 1.603], [64755.8, 0.001], [64829.9, 0.0], [65222.2, 0.349], [65340.5, 0.113], [65693.6, 0.006], [65707.5, 0.0]]}
{"kind": "depth", "E": 1787081844759, "U": 11315466595459, "u": 11315466604502, "recv_ms": 1787081844729, "bids": [[1000.0, 35.81], [14193.5, 1.834], [14290.2, 2.058], [58224.1, 0.002], [61458.8, 0.003], [63778.1, 1.027], [64046.6, 0.0], [64176.0, 0.401], [64366.7, 2.949], [64532.2, 0.012], [64660.6, 0.003], [64660.7, 0.23], [64660.8, 1.186], [64664.1, 2.322], [64664.2, 0.019], [64664.3, 0.372], [64667.5, 0.216], [64672.1, 0.0], [64673.8, 0.559], [64674.9, 0.019], [64677.1, 0.002], [64678.1, 0.448], [64683.0, 0.224], [64686.2, 0.154], [64689.3, 0.012], [64689.4, 0.24], [64690.5, 0.021]], "asks": [[64693.6, 2.278], [64696.0, 0.295], [64696.4, 0.001], [64696.7, 0.003], [64696.8, 0.004], [64696.9, 0.827], [64701.6, 0.016], [64702.1, 0.01], [64705.7, 0.051], [64706.3, 0.005], [64709.5, 0.012], [64709.6, 0.466], [64713.1, 0.01], [64718.6, 0.162], [64719.7, 0.015], [64725.1, 0.171], [64726.1, 0.17], [64731.6, 0.157], [64850.2, 0.1], [65211.1, 0.554], [65340.5, 0.113], [65476.5, 17.354], [65502.3, 1.101], [66642.8, 0.645]]}
{"kind": "depth", "E": 1787081844861, "U": 11315466604763, "u": 11315466619244, "recv_ms": 1787081844834, "bids": [[14193.5, 2.198], [14290.2, 1.694], [58224.1, 0.002], [61458.8, 0.004], [62105.7, 0.038], [63399.7, 0.016], [63693.5, 0.066], [63891.2, 3.346], [63917.2, 0.625], [64046.6, 0.0], [64370.0, 3.044], [64493.0, 10.167], [64493.4, 0.0], [64531.8, 5.005], [64548.8, 5.847], [64635.4, 0.006], [64635.7, 0.16], [64637.0, 0.067], [64639.5, 1.465], [64640.7, 0.263], [64643.5, 0.001], [64646.8, 0.011], [64649.0, 0.638], [64659.2, 0.45], [64659.6, 0.331], [64664.9, 0.0], [64665.2, 0.138], [64665.5, 0.009], [64666.1, 0.0], [64668.2, 0.17], [64669.1, 0.005], [64669.4, 0.105], [64669.8, 0.021], [64670.7, 0.172], [64671.9, 0.026], [64674.2, 0.132], [64676.6, 0.072], [64678.0, 0.902], [64683.4, 0.347], [64683.5, 0.172], [64683.7, 0.074], [64684.1, 2.086], [64685.1, 0.0], [64685.4, 0.004], [64686.7, 0.002], [64686.9, 0.396], [64689.1, 0.001], [64689.2, 0.017], [64689.3, 0.008], [64689.5, 0.021], [64689.8, 0.422], [64690.2, 3.812], [64690.5, 0.167], [64693.1, 0.99], [64693.4, 0.289], [64693.5, 42.978]], "asks": [[64693.6, 0.773], [64693.7, 0.003], [64695.4, 0.011], [64696.0, 0.002], [64696.1, 0.001], [64696.5, 0.402], [64696.7, 0.002], [64701.0, 0.061], [64701.7, 0.235], [64702.1, 0.008], [64702.4, 0.252], [64702.5, 0.085], [64702.6, 0.001], [64702.9, 0.286], [64703.0, 0.003], [64703.4, 0.02], [64703.6, 0.023], [64704.4, 1.084], [64716.7, 0.04], [64718.1, 0.548], [64719.4, 0.475], [64719.8, 0.002], [64720.1, 0.031], [64720.7, 0.987], [64723.5, 2.326], [64723.8, 0.0], [64724.1, 0.013], [64725.7, 0.194], [64726.1, 0.324], [64726.7, 6.049], [64727.0, 0.073], [64727.1, 0.31], [64728.3, 0.464], [64730.8, 0.276], [64734.9, 0.04], [64736.0, 0.024], [64736.5, 0.002], [64738.2, 0.025], [64738.6, 0.028], [64741.5, 0.036], [64748.1, 0.016], [64750.2, 0.001], [64750.5, 0.005], [64752.0, 1.181], [64752.1, 0.015], [64753.0, 1.593], [64753.4, 0.32], [64753.6, 1.198], [64753.8, 0.0], [64755.3, 0.001], [64756.2, 0.02], [64757.8, 0.017], [64795.6, 0.1], [64805.8, 0.095], [64808.4, 2.435], [64833.2, 5.504], [64850.2, 7.345], [64883.5, 0.95], [64885.7, 2.475], [64889.0, 9.823], [65340.5, 0.113], [65511.9, 0.002], [65693.6, 0.026], [65696.4, 1.071]]}
{"kind": "depth", "E": 1787081844963, "U": 11315466619379, "u": 11315466629656, "recv_ms": 1787081844935, "bids": [[1000.0, 35.96], [14193.5, 2.534], [14290.2, 1.358], [58224.1, 0.002], [61458.8, 0.003], [62105.7, 0.035], [63399.7, 0.019], [63693.5, 0.046], [64019.8, 2.34], [64046.6, 0.0], [64186.9, 0.621], [64342.0, 5.492], [64349.3, 0.486], [64381.0, 1.871], [64532.4, 0.0], [64627.1, 1.099], [64627.2, 40.714], [64649.0, 0.642], [64659.6, 0.321], [64659.9, 0.012], [64672.1, 0.29], [64672.6, 0.004], [64674.9, 0.026], [64679.7, 0.01], [64681.2, 0.45], [64684.7, 1.844], [64685.0, 0.008], [64685.1, 0.463], [64689.8, 0.368], [64690.0, 0.004], [64690.3, 2.505], [64690.4, 0.427], [64690.5, 0.021], [64692.4, 0.001], [64692.5, 0.044], [64692.7, 0.0], [64692.9, 0.0], [64693.2, 0.003], [64693.3, 0.005], [64693.5, 43.38]], "asks": [[64693.6, 0.777], [64695.4, 0.002], [64695.6, 0.009], [64696.4, 0.01], [64696.5, 0.394], [64696.8, 0.012], [64700.3, 0.084], [64704.6, 0.586], [64705.4, 0.002], [64713.5, 2.319], [64714.4, 0.561], [64715.2, 1.117], [64716.5, 0.003], [64718.7, 0.121], [64725.6, 0.002], [64730.8, 0.274], [64731.9, 1.249], [64734.8, 0.002], [64735.3, 0.0], [64753.4, 0.31], [64753.7, 2.329], [65013.8, 3.154], [65337.3, 10.778], [65340.5, 0.113], [65511.9, 0.764], [65642.8, 4.158], [65693.6, 0.006]]}
{"kind": "depth", "E": 1787081845065, "U": 11315466629783, "u": 11315466660069, "recv_ms": 1787081845040, "bids": [[1000.0, 35.81], [14193.5, 2.576], [14194.2, 0.322], [14290.2, 0.994], [58224.1, 0.0], [58224.7, 0.002], [61455.7, 0.006], [61455.8, 0.008], [61458.8, 0.003], [62106.4, 0.003], [63764.0, 0.056], [64046.6, 0.0], [64047.3, 0.073], [64370.7, 0.024], [64555.5, 0.017], [64569.9, 0.002], [64573.9, 0.017], [64577.0, 0.077], [64581.0, 0.134], [64584.0, 5.26], [64588.0, 0.244], [64590.7, 0.0], [64591.1, 0.0], [64595.1, 0.664], [64596.9, 0.122], [64598.1, 0.996], [64598.5, 0.003], [64602.1, 0.013], [64604.2, 0.003], [64605.2, 0.005], [64606.5, 0.005], [64609.2, 0.013], [64612.2, 0.282], [64614.1, 40.699], [64616.2, 0.013], [64617.1, 0.001], [64617.6, 6.316], [64619.3, 0.0], [64622.7, 0.0], [64623.3, 2.37], [64625.0, 1.59], [64626.9, 0.108], [64627.2, 0.015], [64635.3, 0.407], [64636.2, 0.006], [64639.0, 0.008], [64639.5, 1.449], [64640.0, 1.889], [64644.4, 0.002], [64644.6, 0.312], [64645.4, 0.678], [64648.3, 0.004], [64648.6, 0.007], [64649.0, 0.638], [64651.9, 2.78], [64653.4, 1.899], [64654.1, 0.062], [64656.8, 1.601], [64656.9, 0.2], [64657.4, 0.45], [64657.5, 0.072], [64658.4, 2.644], [64659.0, 0.009], [64662.1, 1.613], [64663.3, 0.003], [64665.5, 0.003], [64666.0, 3.279], [64667.7, 0.748], [64667.8, 1.952], [64668.8, 0.015], [64669.5, 0.325], [64671.0, 0.02], [64672.3, 0.557], [64673.8, 0.002], [64674.1, 0.139], [64674.4, 0.012], [64674.9, 0.021], [64675.0, 0.279], [64675.2, 2.029], [64675.6, 0.0], [64676.8, 0.867], [64678.2, 0.949], [64678.6, 0.213], [64678.8, 0.0], [64679.3, 0.002], [64679.5, 0.025], [64679.6, 1.32], [64679.8, 0.023], [64679.9, 0.022], [64680.0, 0.758], [64680.1, 0.472], [64680.6, 0.001], [64680.7, 0.162], [64681.3, 0.085], [64681.7, 0.001], [64682.5, 0.022], [64682.6, 0.028], [64683.2, 0.104], [64683.7, 0.074], [64683.8, 0.026], [64684.1, 2.081], [64684.2, 0.683], [64684.7, 1.843], [64684.9, 0.435], [64685.0, 0.008], [64685.1, 0.0], [64685.3, 0.004], [64685.6, 0.001], [64685.7, 0.01], [64685.8, 0.323], [64686.4, 0.001], [64686.9, 0.003], [64687.9, 0.232], [64688.1, 0.147], [64689.0, 0.216], [64689.2, 0.002], [64690.2, 3.814], [64690.3, 2.502], [64690.5, 0.021], [64691.0, 0.004], [64691.1, 0.002], [64691.4, 0.001], [64692.0, 0.003], [64692.4, 0.002], [64692.7, 0.001], [64692.8, 0.059], [64692.9, 0.0], [64693.0, 0.001], [64693.1, 0.99], [64693.2, 0.001], [64693.3, 0.001], [64693.4, 0.005], [64693.5, 4.293], [64693.6, 3.35], [64693.7, 0.515], [64693.8, 0.001], [64693.9, 0.002], [64694.1, 0.005], [64694.2, 42.624]], "asks": [[64693.6, 0.0], [64693.7, 0.0], [64694.2, 0.0], [64694.3, 2.608], [64694.4, 0.036], [64694.5, 0.001], [64694.8, 0.0], [64695.4, 0.0], [64695.6, 0.01], [64695.7, 0.005], [64696.3, 0.012], [64696.4, 0.001], [64696.5, 0.002], [64696.6, 0.001], [64696.7, 0.002], [64696.8, 0.14], [64697.0, 0.003], [64697.2, 0.002], [64697.5, 0.027], [64697.6, 1.185], [64697.7, 0.011], [64698.0, 0.005], [64698.1, 0.004], [64698.2, 0.003], [64698.7, 0.569], [64698.8, 1.905], [64699.0, 0.001], [64699.5, 0.003], [64699.7, 0.126], [64699.8, 0.085], [64699.9, 1.902], [64700.0, 0.004], [64700.2, 0.004], [64700.6, 0.312], [64700.9, 0.854], [64701.1, 0.084], [64701.3, 1.004], [64701.5, 0.164], [64701.9, 0.501], [64702.0, 0.087], [64702.2, 0.003], [64702.3, 0.003], [64702.4, 0.252], [64702.9, 0.099], [64703.1, 0.096], [64703.2, 1.71], [64703.3, 0.532], [64703.4, 0.003], [64703.6, 0.045], [64703.9, 0.011], [64704.3, 1.928], [64704.4, 1.084], [64704.5, 2.511], [64704.6, 0.586], [64705.4, 0.001], [64705.6, 0.007], [64706.6, 0.0], [64707.5, 0.007], [64708.0, 0.001], [64709.0, 0.628], [64709.6, 0.465], [64710.6, 1.007], [64710.8, 2.455], [64711.0, 0.9], [64711.4, 0.036], [64711.6, 0.18], [64711.8, 0.002], [64711.9, 1.3], [64712.0, 1.977], [64712.5, 0.558], [64712.8, 0.002], [64713.0, 0.152], [64713.1, 0.05], [64713.2, 0.354], [64713.3, 0.061], [64713.7, 0.001], [64714.0, 0.145], [64714.4, 0.005], [64714.9, 0.0], [64715.2, 1.277], [64715.5, 1.187], [64715.6, 0.909], [64715.7, 0.017], [64715.9, 0.029], [64716.3, 0.0], [64716.7, 0.04], [64716.8, 1.251], [64717.0, 0.116], [64717.3, 0.002], [64718.1, 0.007], [64718.7, 0.105], [64719.0, 0.325], [64719.5, 0.08], [64720.8, 2.325], [64724.1, 0.007], [64724.5, 0.03], [64725.0, 0.046], [64728.0, 1.191], [64730.4, 0.048], [64730.8, 0.258], [64731.3, 0.3], [64732.2, 0.004], [64732.7, 10.028], [64735.1, 2.336], [64735.7, 0.197], [64748.4, 0.005], [64748.8, 0.045], [64749.2, 0.031], [64751.9, 0.003], [64752.8, 0.017], [64757.0, 0.02], [64757.6, 0.234], [64757.8, 0.062], [64759.7, 0.051], [64761.8, 0.006], [64762.8, 1.501], [64768.9, 0.026], [64805.8, 0.011], [64808.4, 2.319], [64812.5, 0.451], [64812.6, 0.001], [64837.5, 1.479], [64837.6, 0.03], [64850.2, 0.1], [64850.9, 10.459], [64851.4, 2.734], [64851.5, 0.003], [64855.4, 2.993], [64857.6, 2.053], [64862.2, 0.072], [64874.4, 0.002], [64877.6, 0.047], [64895.4, 0.011], [64896.4, 0.0], [65018.1, 0.004], [65023.9, 0.116], [65044.4, 0.004], [65337.2, 0.659], [65340.5, 0.113], [65341.2, 0.002], [65389.0, 0.135], [65437.6, 0.218], [65438.3, 4.541], [65502.3, 0.345], [65503.0, 1.412], [65616.6, 0.0], [65705.7, 0.914], [65988.1, 0.009]]}
{"kind": "depth", "E": 1787081845167, "U": 11315466660242, "u": 11315466676451, "recv_ms": 1787081845134, "bids": [[14194.2, 0.686], [14290.2, 0.63], [58224.7, 0.002], [61459.4, 0.0], [63400.4, 0.075], [63697.1, 0.632], [63700.4, 0.044], [63761.6, 0.0], [63765.0, 0.07], [63767.3, 0.008], [64047.3, 0.073], [64366.7, 2.948], [64370.0, 3.034], [64614.1, 0.0], [64621.8, 0.001], [64625.1, 41.168], [64627.2, 0.015], [64659.9, 0.002], [64660.2, 0.641], [64674.8, 0.303], [64686.1, 0.004], [64690.8, 0.0], [64691.9, 0.001], [64692.8, 0.0], [64693.4, 0.001], [64693.5, 2.541], [64693.7, 0.31], [64693.9, 0.004], [64694.0, 0.002], [64694.2, 44.392]], "asks": [[64694.3, 3.32], [64695.6, 0.0], [64696.3, 0.002], [64696.7, 0.012], [64696.9, 0.827], [64697.5, 0.037], [64698.7, 0.021], [64699.8, 0.633], [64701.4, 0.005], [64702.0, 0.085], [64703.0, 0.313], [64704.3, 0.117], [64708.7, 0.019], [64710.0, 1.032], [64713.7, 0.002], [64715.5, 0.646], [64716.7, 0.581], [64730.6, 0.015], [64736.0, 0.025], [64736.6, 0.03], [64748.7, 0.016], [64753.7, 2.319], [64754.0, 0.011], [64766.8, 0.036], [64823.2, 0.0], [64849.9, 0.026], [64877.6, 0.046], [65017.8, 0.02], [65044.0, 0.149], [65341.2, 0.002], [65437.7, 0.013], [65438.0, 0.634], [65438.8, 9.988], [65502.4, 0.0], [65502.7, 0.0], [65503.5, 7.56], [65618.9, 0.005], [65631.8, 1.066], [65683.5, 0.0], [65988.1, 0.012]]}
{"kind": "depth", "E": 1787081845269, "U": 11315466676712, "u": 11315466686746, "recv_ms": 1787081845243, "bids": [[1000.0, 35.81], [14194.2, 0.868], [14290.2, 0.364], [14594.2, 0.084], [51755.0, 0.0], [51755.4, 0.0], [58224.7, 0.002], [61459.4, 0.0], [62106.4, 0.0], [63288.4, 0.092], [63289.3, 0.003], [63459.9, 0.149], [63694.2, 0.02], [63923.6, 17.48], [64047.3, 0.073], [64176.0, 0.711], [64370.0, 3.189], [64548.8, 1.202], [64625.1, 0.002], [64627.2, 41.181], [64654.8, 0.003], [64655.9, 0.004], [64660.2, 0.631], [64660.5, 0.01], [64667.6, 0.023], [64671.5, 0.044], [64672.8, 0.002], [64674.7, 0.008], [64675.2, 2.183], [64684.2, 0.606], [64684.9, 0.512], [64690.7, 0.0], [64691.4, 0.0], [64692.5, 0.001], [64693.5, 0.551], [64693.8, 0.003], [64693.9, 0.0], [64694.0, 0.004], [64694.1, 0.007], [64694.2, 46.442]], "asks": [[64695.7, 0.003], [64696.3, 0.0], [64696.4, 0.0], [64697.2, 0.001], [64697.5, 0.037], [64700.2, 0.006], [64701.1, 0.086], [64703.1, 0.003], [64703.2, 0.042], [64703.8, 0.046], [64704.3, 0.117], [64705.0, 0.232], [64705.5, 0.446], [64707.1, 0.588], [64707.4, 1.745], [64712.5, 0.002], [64713.3, 0.617], [64730.3, 0.0], [64731.4, 0.496], [64741.9, 0.002], [64754.0, 0.001], [64754.3, 0.01], [64759.0, 0.024], [64833.2, 0.106], [65109.2, 0.002], [65174.0, 0.047], [65341.2, 0.002], [65619.9, 1.268], [65622.2, 0.026], [65687.0, 0.342], [65694.3, 0.02]]}
{"kind": "depth", "E": 1787081845371, "U": 11315466686850, "u": 11315466703442, "recv_ms": 1787081845345, "bids": [[14194.2, 0.784], [14290.2, 0.224], [14594.2, 0.308], [51755.0, 0.0], [58224.7, 0.002], [61459.4, 0.0], [62106.4, 0.003], [62872.3, 0.009], [63396.4, 0.012], [63881.6, 2.309], [63960.4, 0.965], [64047.3, 0.073], [64531.7, 4.885], [64531.8, 0.0], [64548.7, 4.554], [64625.1, 41.168], [64627.2, 0.015], [64660.5, 0.0], [64660.8, 1.196], [64675.1, 2.945], [64675.2, 2.029], [64690.7, 0.004], [64693.4, 0.0], [64693.7, 0.847], [64694.2, 46.442]], "asks": [[64696.7, 0.012], [64697.1, 0.004], [64697.2, 0.002], [64697.5, 0.028], [64704.3, 0.681], [64706.0, 1.122], [64707.1, 0.024], [64725.9, 0.156], [64726.1, 0.17], [64754.3, 0.0], [64754.6, 0.033], [64823.7, 0.0], [64833.9, 6.677], [64850.9, 10.459], [64887.8, 0.524], [64889.0, 0.027], [64889.7, 10.205], [64892.5, 0.216], [64976.8, 0.095], [65238.8, 7.671], [65341.1, 0.0], [65341.2, 0.002], [65341.8, 0.451], [65502.9, 0.343]]}
{"kind": "depth", "E": 1787081845473, "U": 11315466703779, "u": 11315466716399, "recv_ms": 1787081845441, "bids": [[14193.5, 2.52], [14194.2, 0.714], [14290.2, 0.112], [14594.2, 0.546], [58224.7, 0.002], [61459.4, 0.0], [62106.4, 0.0], [63694.2, 0.0], [63871.2, 0.782], [64047.3, 0.073], [64370.7, 0.034], [64564.0, 0.004], [64575.9, 0.28], [64604.1, 0.009], [64604.2, 0.0], [64630.4, 2.512], [64690.6, 0.0], [64690.7, 0.0], [64694.2, 46.445]], "asks": [[64694.3, 3.304], [64696.7, 0.012], [64697.5, 0.038], [64705.0, 1.132], [64710.6, 0.082], [64711.1, 0.928], [64725.9, 0.002], [64726.2, 2.321], [64726.3, 0.156], [64736.1, 0.293], [64774.0, 0.169], [64806.3, 0.087], [64808.8, 0.132], [64837.2, 0.346], [64889.7, 11.329], [64895.2, 0.004], [64895.4, 0.008], [65341.2, 0.002], [65694.3, 0.0]]}
{"kind": "depth", "E": 1787081845575, "U": 11315466716559, "u": 11315466728588, "recv_ms": 1787081845544, "bids": [[1000.0, 35.81], [14193.5, 2.408], [14194.2, 0.686], [14290.2, 0.0], [14594.2, 0.798], [58224.7, 0.002], [61455.8, 0.006], [61459.4, 0.0], [61459.5, 0.058], [62106.4, 0.003], [63707.8, 7.682], [63717.8, 10.186], [64047.3, 0.073], [64176.6, 0.002], [64575.9, 0.0], [64578.6, 3.846], [64618.4, 0.0], [64620.1, 8.222], [64622.9, 41.169], [64625.1, 0.002], [64630.4, 2.344], [64631.9, 0.013], [64635.2, 1.101], [64660.8, 1.186], [64661.0, 0.034], [64671.3, 0.619], [64678.2, 0.023], [64678.7, 0.637], [64679.3, 0.928], [64680.1, 0.464], [64681.6, 1.677], [64685.0, 0.016], [64690.6, 0.0], [64693.1, 0.97], [64693.5, 0.543], [64694.2, 46.479]], "asks": [[64694.3, 3.321], [64695.3, 0.5], [64697.0, 0.003], [64697.5, 0.038], [64697.7, 0.004], [64698.1, 0.011], [64698.7, 0.145], [64699.7, 0.002], [64704.9, 0.327], [64711.1, 0.003], [64711.6, 1.105], [64713.3, 0.061], [64714.0, 0.088], [64714.4, 0.561], [64714.9, 0.057], [64715.6, 0.909], [64717.0, 0.001], [64718.0, 0.116], [64719.2, 0.002], [64719.3, 0.002], [64719.4, 0.473], [64720.0, 0.639], [64722.2, 0.006], [64722.3, 0.442], [64725.3, 0.197], [64725.5, 0.001], [64726.3, 0.002], [64726.4, 0.006], [64727.3, 0.621], [64729.6, 3.75], [64736.1, 0.221], [64748.7, 0.002], [64754.6, 0.023], [64754.8, 0.01], [64767.6, 5.49], [64774.0, 0.002], [64803.6, 10.767], [64837.2, 0.068], [65028.1, 0.0], [65341.2, 0.002], [65481.1, 8.968], [65593.2, 0.001], [65984.1, 0.009]]}
{"kind": "depth", "E": 1787081845677, "U": 11315466728613, "u": 11315466741086, "recv_ms": 1787081845645, "bids": [[14193.5, 2.156], [14194.2, 0.574], [14594.2, 1.162], [58224.7, 0.002], [63694.2, 0.02], [63946.3, 3.759], [63960.4, 0.028], [64047.3, 0.073], [64500.0, 25.028], [64531.7, 0.0], [64548.7, 0.001], [64620.1, 2.39], [64656.4, 0.08], [64656.8, 1.541], [64664.6, 0.312], [64678.8, 0.926], [64679.3, 0.002], [64679.9, 0.03], [64684.3, 0.088], [64684.8, 0.327], [64684.9, 0.427], [64685.0, 0.008], [64686.0, 1.021], [64686.1, 0.545], [64690.6, 0.0], [64691.4, 0.001], [64693.1, 0.948], [64693.5, 0.501], [64694.2, 46.524]], "asks": [[64694.3, 3.303], [64696.7, 0.012], [64697.2, 0.002], [64697.5, 0.028], [64703.3, 0.551], [64703.4, 0.025], [64726.4, 0.006], [64726.6, 2.382], [64769.1, 0.012], [64773.3, 0.008], [64787.5, 0.372], [64791.7, 0.219], [64833.9, 1.279], [64850.9, 0.051], [65341.2, 0.002], [65694.3, 0.02], [65988.1, 0.015]]}
{"kind": "depth", "E": 1787081845779, "U": 11315466741159, "u": 11315466751150, "recv_ms": 1787081845747, "bids": [[14193.5, 1.932], [14194.2, 0.448], [14594.2, 1.512], [51755.0, 0.0], [58224.7, 0.002], [61469.2, 0.0], [62106.4, 0.0], [63687.5, 4.578], [63826.5, 5.707], [63946.3, 4.696], [64047.3, 0.073], [64370.7, 0.024], [64531.9, 5.704], [64548.8, 5.792], [64656.4, 0.02], [64661.0, 0.024], [64661.2, 1.017], [64664.8, 0.13], [64677.1, 0.0], [64690.2, 3.768]], "asks": [[64695.7, 0.005], [64697.0, 0.003], [64709.6, 0.463], [64726.4, 0.006], [64726.6, 2.382], [64754.8, 0.0], [64755.0, 0.211], [64833.9, 6.677], [64850.9, 10.459], [64889.7, 10.064], [65017.8, 0.174], [65341.2, 0.002], [65470.6, 0.46], [71163.8, 0.0]]}
{"kind": "depth", "E": 1787081845881, "U": 11315466751336, "u": 11315466760948, "recv_ms": 1787081845850, "bids": [[1000.0, 35.81], [14193.5, 1.694], [14194.2, 0.336], [14594.2, 1.862], [51755.0, 0.0], [58224.7, 0.002], [61459.4, 0.0], [62106.4, 0.003], [63470.8, 0.675], [63604.5, 1.181], [63687.5, 5.204], [63694.2, 0.0], [63766.3, 3.221], [64047.3, 0.073], [64240.6, 0.084], [64548.8, 1.202], [64548.9, 4.676], [64576.0, 0.007], [64630.4, 2.344], [64656.4, 0.02], [64661.2, 1.007], [64661.3, 0.012], [64664.7, 0.07], [64664.8, 0.07], [64668.3, 0.037], [64675.8, 0.081], [64677.8, 0.44], [64678.7, 0.019], [64681.3, 0.005], [64690.5, 0.021], [64693.5, 0.378], [64694.2, 46.647]], "asks": [[64694.3, 3.295], [64696.7, 0.012], [64710.3, 0.214], [64720.0, 0.021], [64722.4, 0.0], [64723.0, 0.003], [64723.1, 0.312], [64723.2, 0.244], [64725.4, 0.004], [64736.1, 0.221], [64755.0, 0.201], [64755.1, 0.321], [64774.0, 0.002], [64837.2, 0.068], [64885.0, 6.666], [64885.7, 0.001], [65041.5, 0.096], [65341.2, 0.002], [65694.3, 0.0], [65804.5, 1.529]]}
{"kind": "depth", "E": 1787081845983, "U": 11315466761448, "u": 11315466770077, "recv_ms": 1787081845954, "bids": [[14193.5, 1.456], [14194.2, 0.21], [14594.2, 2.226], [58224.7, 0.002], [61459.4, 0.0], [62106.4, 0.0], [63766.3, 2.124], [64047.3, 0.073], [64146.8, 0.119], [64336.7, 5.942], [64342.0, 5.0], [64344.6, 0.492], [64565.4, 0.084], [64672.3, 0.0], [64673.2, 0.558], [64674.1, 0.023], [64674.7, 0.124], [64675.8, 0.001], [64680.0, 0.759], [64682.4, 0.081], [64683.8, 0.025], [64690.5, 0.025], [64693.5, 0.375]], "asks": [[64694.3, 3.297], [64696.7, 0.002], [64697.0, 0.003], [64713.5, 2.875], [64714.4, 0.005], [64714.6, 0.23], [64715.9, 0.022], [65106.2, 1.055], [65529.9, 3.051]]}
{"kind": "depth", "E": 1787081846085, "U": 11315466770220, "u": 11315466779688, "recv_ms": 1787081846055, "bids": [[14193.5, 1.204], [14194.2, 0.098], [14594.2, 2.59], [51755.0, 0.0], [58224.7, 0.002], [61455.8, 0.004], [61459.4, 0.0], [62106.4, 0.003], [63406.1, 0.0], [63478.0, 0.0], [63549.9, 0.0], [63593.7, 4.711], [63621.8, 0.001], [63693.7, 0.0], [63694.2, 0.02], [63756.1, 1.884], [63765.5, 0.002], [63837.4, 0.025], [63909.3, 0.0], [63928.0, 9.527], [63981.2, 0.005], [64047.3, 0.073], [64053.1, 0.0], [64370.7, 0.033], [64649.0, 0.638], [64661.3, 0.002], [64661.4, 1.671], [64671.3, 0.001], [64673.2, 0.558], [64674.1, 0.023], [64674.5, 0.566], [64674.7, 0.008], [64675.4, 0.032], [64679.7, 0.473], [64680.1, 0.001], [64682.6, 0.028], [64690.4, 0.431], [64690.5, 0.021], [64691.0, 0.019], [64693.2, 0.045]], "asks": [[64694.3, 3.466], [64696.7, 0.012], [64699.4, 0.006], [64700.1, 2.503], [64700.2, 1.006], [64700.9, 0.562], [64701.3, 0.004], [64701.4, 0.003], [64705.6, 0.009], [64706.4, 0.002], [64707.1, 0.292], [64713.4, 0.374], [64713.5, 2.319], [64714.4, 0.561], [64715.8, 0.0], [64719.0, 0.34], [64755.1, 0.311], [64755.2, 0.015], [65341.2, 0.002], [65347.1, 0.116], [65419.0, 1.475], [65490.9, 0.316], [65562.8, 0.004], [65634.7, 0.947], [65694.3, 0.02], [65706.5, 0.001], [65778.4, 0.0], [65850.3, 0.0], [65922.2, 0.0], [65994.1, 6.355]]}
{"kind": "depth", "E": 1787081846187, "U": 11315466779711, "u": 11315466791541, "recv_ms": 1787081846158, "bids": [[1000.0, 35.81], [14193.5, 0.952], [14194.2, 0.0], [14594.2, 2.94], [51755.0, 0.0], [58224.7, 0.002], [61459.4, 0.0], [63679.1, 1.348], [63752.2, 9.893], [63847.3, 5.037], [63885.5, 0.746], [64047.3, 0.073], [64181.0, 0.0], [64604.0, 0.381], [64604.1, 0.006], [64616.5, 0.289], [64649.0, 0.642], [64672.3, 0.557], [64673.2, 0.001], [64675.8, 0.081], [64677.8, 1.366], [64678.8, 0.0], [64682.4, 0.001], [64684.3, 0.011], [64684.8, 0.868], [64684.9, 0.504], [64686.0, 0.121], [64686.1, 0.004], [64690.4, 0.427], [64694.2, 46.15]], "asks": [[64694.3, 3.49], [64696.7, 0.012], [64697.0, 0.003], [64697.5, 0.028], [64699.5, 0.087], [64703.6, 0.023], [64704.3, 0.681], [64708.7, 0.018], [64710.2, 1.049], [64711.6, 0.18], [64712.8, 0.558], [64713.5, 2.376], [64714.4, 0.005], [64714.9, 0.0], [64715.1, 0.604], [64716.7, 0.04], [64726.5, 0.133], [64726.6, 2.228], [64726.8, 1.856], [64726.9, 0.001], [64727.3, 0.003], [64748.7, 0.016], [65017.8, 0.174], [65170.9, 0.102], [65341.2, 0.002], [65988.1, 0.018]]}
{"kind": "depth", "E": 1787081846289, "U": 11315466791913, "u": 11315466801081, "recv_ms": 1787081846259, "bids": [[14190.2, 0.21], [14191.6, 0.0], [14193.1, 0.028], [14193.5, 0.672], [14594.2, 3.29], [51755.0, 0.0], [51755.4, 0.0], [58224.7, 0.002], [62106.4, 0.0], [63694.2, 0.0], [63917.2, 1.249], [64047.3, 0.073], [64370.7, 0.034], [64622.9, 0.003], [64625.0, 42.756], [64640.7, 0.163], [64661.4, 1.661], [64661.5, 0.077], [64662.1, 1.556], [64673.2, 0.008], [64674.1, 0.016], [64690.3, 2.506], [64690.4, 0.063], [64693.6, 0.85], [64694.2, 46.066]], "asks": [[64696.7, 0.002], [64697.5, 0.028], [64698.7, 0.586], [64704.8, 0.252], [64709.0, 1.528], [64726.8, 1.856], [64755.2, 0.005], [64755.3, 0.011], [65341.2, 0.002], [65694.3, 0.0]]}
{"kind": "depth", "E": 1787081846391, "U": 11315466801254, "u": 11315466809480, "recv_ms": 1787081846360, "bids": [[1000.0, 35.81], [14190.2, 0.098], [14193.1, 0.014], [14193.5, 0.434], [14594.2, 3.654], [58224.7, 0.002], [61459.4, 0.0], [61459.5, 0.052], [62106.4, 0.003], [63927.8, 0.0], [63950.3, 10.326], [64047.3, 0.073], [64111.8, 0.049], [64213.0, 0.314], [64370.7, 0.024], [64625.0, 1.59], [64627.3, 41.5], [64660.6, 0.001], [64660.7, 0.228], [64660.8, 1.184], [64661.3, 0.004], [64661.4, 1.663], [64661.5, 0.069], [64661.6, 0.012], [64664.1, 2.32], [64664.2, 0.017], [64664.3, 0.37], [64664.8, 0.072], [64664.9, 0.002], [64665.0, 0.056], [64673.3, 0.119], [64674.5, 0.45], [64677.1, 0.926], [64677.8, 0.44], [64690.3, 2.5], [64693.7, 0.448], [64694.2, 46.04]], "asks": [[64694.3, 3.489], [64696.6, 0.038], [64696.7, 0.012], [64697.0, 0.003], [64697.5, 0.038], [64699.0, 0.085], [64703.3, 0.467], [64705.2, 0.203], [64714.6, 0.23], [64715.1, 0.604], [64715.5, 0.646], [64726.8, 1.702], [64726.9, 0.155], [64728.5, 10.628], [64729.6, 2.537], [64730.6, 0.001], [64732.7, 0.028], [64748.7, 0.002], [64755.3, 0.001], [64755.4, 0.153], [64823.7, 0.0], [65331.9, 1.227], [65341.2, 0.002]]}
{"kind": "depth", "E": 1787081846493, "U": 11315466809679, "u": 11315466817578, "recv_ms": 1787081846464, "bids": [[1000.0, 35.81], [14190.2, 0.0], [14193.1, 0.0], [14193.5, 0.322], [14494.2, 0.126], [14594.2, 3.752], [58224.7, 0.002], [61455.8, 0.002], [61459.4, 0.0], [62106.4, 0.0], [63691.5, 5.803], [63694.2, 0.02], [63781.3, 1.49], [63820.8, 1.409], [63885.5, 1.011], [63950.2, 0.937], [64047.3, 0.073], [64105.5, 1.09], [64176.6, 0.313], [64548.9, 0.002], [64575.7, 0.0], [64630.2, 0.003], [64658.6, 0.536], [64677.1, 0.0], [64678.2, 0.949], [64690.3, 2.504], [64693.1, 0.946], [64694.2, 46.081]], "asks": [[64694.3, 3.486], [64698.7, 0.71], [64700.4, 0.296], [64700.9, 0.56], [64710.2, 0.124], [64710.7, 2.828], [64713.5, 2.319], [64714.1, 1.256], [64715.1, 0.063], [64716.7, 0.581], [64735.9, 0.127], [64773.8, 0.002], [64833.9, 1.279], [64837.0, 0.002], [65341.2, 0.002], [65463.7, 0.763], [65470.7, 13.604], [65528.3, 2.286], [65605.9, 22.54], [65642.8, 3.093], [65694.3, 0.02]]}
{"kind": "depth", "E": 1787081846595, "U": 11315466817731, "u": 11315466825602, "recv_ms": 1787081846566, "bids": [[14193.5, 0.196], [14494.2, 0.364], [14594.2, 3.64], [58224.7, 0.002], [61459.4, 0.0], [61459.5, 0.048], [63756.2, 7.547], [63969.0, 1.568], [64047.3, 0.073], [64549.1, 9.805], [64575.7, 0.0], [64620.6, 41.511], [64627.3, 0.0], [64630.1, 7.884], [64630.2, 0.003], [64661.6, 0.002], [64661.7, 0.011], [64671.4, 0.65], [64675.2, 1.693], [64677.3, 0.042], [64678.7, 0.019], [64682.5, 0.029], [64682.9, 0.215], [64684.9, 0.464], [64690.2, 3.772], [64690.3, 2.5], [64691.2, 1.741], [64694.2, 46.061]], "asks": [[64697.0, 0.003], [64706.2, 0.002], [64720.1, 0.649], [64726.6, 3.508], [64727.4, 0.619], [64735.9, 0.127], [64748.7, 0.002], [64755.4, 0.143], [64755.5, 0.01], [64773.8, 0.002], [64833.9, 6.677], [64837.0, 0.002], [64883.5, 1.476], [64889.7, 9.699], [65341.2, 0.002], [65470.6, 0.674]]}
{"kind": "depth", "E": 1787081846697, "U": 11315466825758, "u": 11315466832054, "recv_ms": 1787081846670, "bids": [[1000.0, 35.81], [14193.5, 0.084], [14494.2, 0.602], [14594.2, 3.514], [58224.7, 0.002], [61459.4, 0.0], [62106.4, 0.003], [63396.4, 0.009], [63694.2, 0.0], [63891.2, 3.08], [63924.3, 0.939], [64047.3, 0.073], [64370.7, 0.034], [64620.6, 0.011], [64625.0, 1.59], [64627.3, 41.5], [64630.1, 1.603], [64671.4, 0.032], [64672.3, 0.893], [64679.3, 0.465], [64679.7, 0.01], [64690.2, 3.768], [64691.2, 1.742], [64694.2, 46.062]], "asks": [[64694.3, 3.596], [64695.2, 0.22], [64696.8, 0.011], [64701.0, 0.064], [64708.0, 0.901], [64709.0, 0.628], [64726.8, 1.856], [64726.9, 0.001], [64728.0, 1.189], [64728.5, 10.63], [65308.9, 0.924], [65341.2, 0.002], [65694.3, 0.0]]}
{"kind": "depth", "E": 1787081846799, "U": 11315466832387, "u": 11315466838919, "recv_ms": 1787081846773, "bids": [[1000.0, 35.81], [14193.5, 0.0], [14494.2, 0.882], [14594.2, 3.318], [58224.7, 0.002], [62106.4, 0.0], [63691.4, 1.103], [63756.1, 4.077], [64575.7, 0.0], [64630.2, 0.003], [64677.8, 0.438], [64690.2, 3.772], [64694.2, 46.12]], "asks": [[64702.9, 0.121], [64710.3, 0.212], [64726.8, 1.856], [64735.9, 0.127], [64773.8, 0.002], [64836.9, 0.122], [64889.7, 9.819], [65341.2, 0.002], [65632.4, 1.293]]}
{"kind": "depth", "E": 1787081846901, "U": 11315466839117, "u": 11315466846060, "recv_ms": 1787081846870, "bids": [[14494.2, 1.246], [14594.2, 2.954], [58224.7, 0.002], [62106.4, 0.003], [63694.2, 0.02], [64047.3, 0.073], [64370.7, 0.034], [64549.1, 5.096], [64549.2, 4.831], [64616.5, 0.286], [64635.2, 1.098], [64635.7, 0.26], [64635.9, 0.026], [64656.4, 0.08], [64661.7, 0.001], [64661.8, 0.01], [64664.7, 0.01], [64677.8, 0.44]], "asks": [[64697.6, 1.186], [64702.6, 0.024], [64702.9, 0.099], [64705.4, 0.003], [64710.3, 0.214], [64720.0, 0.02], [64726.8, 1.856], [64755.5, 0.0], [64755.6, 0.014], [64803.6, 10.764], [64804.3, 1.392], [64833.9, 6.677], [64889.7, 9.82], [65335.8, 2.292], [65341.2, 0.002], [65594.8, 11.033], [65659.6, 12.627], [65694.3, 0.02], [65918.4, 0.992], [65988.1, 0.021]]}
{"kind": "depth", "E": 1787081847003, "U": 11315466846167, "u": 11315466852886, "recv_ms": 1787081846981, "bids": [[1000.0, 35.81], [14494.2, 1.596], [14594.2, 2.604], [58224.7, 0.002], [61455.7, 0.004], [61455.8, 0.004], [61459.4, 0.0], [62106.4, 0.0], [63659.2, 2.196], [63917.9, 2.562], [64047.3, 0.073], [64344.6, 0.0], [64348.1, 3.01], [64565.4, 0.0], [64575.7, 0.0], [64630.2, 0.003], [64661.5, 0.012], [64662.4, 0.063], [64663.3, 0.003], [64672.3, 0.336], [64673.3, 0.56], [64674.6, 0.474], [64678.2, 0.023], [64678.5, 0.966], [64679.4, 0.001], [64690.2, 3.772], [64693.2, 0.001], [64693.9, 0.084], [64694.2, 46.083]], "asks": [[64694.3, 3.605], [64697.0, 0.003], [64697.5, 0.038], [64703.4, 0.003], [64710.7, 1.903], [64711.9, 2.225], [64712.8, 0.002], [64713.5, 2.319], [64714.1, 1.199], [64714.4, 0.561], [64715.1, 0.12], [64717.4, 0.051], [64718.0, 0.001], [64718.2, 2.587], [64735.9, 0.127], [64773.8, 0.002], [64836.9, 0.122], [65341.2, 0.002], [65605.9, 20.276], [65739.9, 1.063]]}
{"kind": "depth", "E": 1787081847105, "U": 11315466853071, "u": 11315466860362, "recv_ms": 1787081847078, "bids": [[1000.0, 35.81], [14494.2, 1.946], [14594.2, 2.254], [58224.7, 0.002], [63694.2, 0.0], [63763.6, 4.334], [64047.3, 0.073], [64682.6, 0.028], [64694.1, 0.006]], "asks": [[64694.6, 0.002], [65276.6, 2.384], [65341.2, 0.002], [65470.6, 1.01], [65535.3, 2.296], [65594.8, 10.425], [65632.4, 1.407], [65694.3, 0.0], [65891.1, 0.984]]}
{"kind": "depth", "E": 1787081847309, "U": 11315466868189, "u": 11315466875231, "recv_ms": 1787081847279, "bids": [[1000.0, 35.81], [14494.2, 2.66], [14594.2, 1.54], [51755.4, 0.0], [58224.7, 0.002], [61459.4, 0.0], [62106.4, 0.0], [63416.7, 0.058], [63488.6, 0.373], [63560.5, 0.058], [63619.6, 1.256], [63632.4, 0.261], [63659.1, 1.102], [63694.2, 0.02], [63704.3, 0.453], [63776.2, 0.059], [63848.1, 0.058], [63920.0, 1.01], [63991.9, 0.682], [64047.3, 0.073], [64370.7, 0.034], [64679.9, 0.022], [64685.0, 0.016], [64690.1, 0.004], [64690.2, 3.768], [64694.2, 46.084]], "asks": [[64694.3, 3.612], [64702.4, 0.274], [64704.9, 0.327], [64741.4, 0.059], [64750.9, 0.004], [65341.2, 0.002], [65600.0, 80.526], [65694.3, 0.02], [65729.4, 1.065], [65988.1, 0.024]]}
{"kind": "depth", "E": 1787081847411, "U": 11315466875361, "u": 11315466885899, "recv_ms": 1787081847406, "bids": [[1000.0, 35.81], [14494.2, 3.024], [14594.2, 1.176], [58224.7, 0.002], [61459.5, 0.042], [62106.4, 0.003], [63756.1, 5.174], [63847.3, 4.255], [64047.3, 0.073], [64063.8, 0.059], [64079.6, 0.701], [64623.5, 1.237], [64627.8, 3.22]], "asks": [[64706.1, 0.312], [64726.8, 1.702], [64726.9, 0.155], [64750.9, 0.0], [64756.0, 1.043], [64756.1, 0.0], [64761.1, 2.845], [64823.7, 0.0], [64889.7, 0.0], [64889.8, 18.143], [65017.8, 0.174], [65204.5, 0.038], [65341.2, 0.002], [65358.0, 2.145], [65429.9, 0.06], [65501.8, 0.06], [65567.7, 0.608], [65573.7, 0.068], [65639.9, 0.001], [65645.6, 0.058], [65717.5, 0.058], [65789.4, 0.069], [65861.3, 0.082], [65933.2, 0.089], [66005.1, 2.429]]}
{"kind": "depth", "E": 1787081847513, "U": 11315466886144, "u": 11315466893537, "recv_ms": 1787081847487, "bids": [[14494.2, 3.374], [14594.2, 0.826], [58224.7, 0.002], [61459.4, 0.0], [62106.4, 0.0], [63659.3, 0.0], [63694.2, 0.0], [63723.8, 3.093], [63820.8, 1.8], [63891.2, 2.847], [63922.8, 0.0], [63924.5, 0.0], [63950.3, 9.389], [63950.4, 2.349], [64047.3, 0.073], [64370.7, 0.024], [64549.2, 0.16], [64566.3, 0.087], [64661.8, 0.0], [64661.9, 0.726], [64674.0, 0.122], [64678.0, 1.336], [64679.3, 0.002], [64685.0, 0.479], [64690.1, 0.004], [64691.2, 1.744], [64694.1, 0.007], [64694.2, 46.085]], "asks": [[64694.3, 3.594], [64694.4, 0.045], [64696.9, 0.827], [64703.6, 0.004], [64744.1, 0.004], [64755.6, 0.004], [64755.7, 0.012], [64833.9, 1.279], [65341.2, 0.004], [65694.3, 0.0], [65984.1, 0.006], [68228.8, 0.0]]}
{"kind": "depth", "E": 1787081847615, "U": 11315466893580, "u": 11315466901009, "recv_ms": 1787081847589, "bids": [[1000.0, 35.81], [14394.2, 0.014], [14494.2, 3.71], [14594.2, 0.476], [51755.0, 0.0], [58224.7, 0.002], [61459.4, 0.0], [63396.4, 0.006], [63424.3, 0.676], [63562.1, 2.517], [64047.3, 0.073], [64549.4, 4.67], [64620.4, 0.0], [64620.7, 41.683], [64621.0, 0.015], [64621.3, 0.002], [64621.6, 0.001], [64627.3, 0.0], [64630.1, 1.603], [64641.5, 2.116], [64641.9, 0.06], [64642.2, 0.025], [64642.5, 0.107], [64642.8, 0.002], [64645.7, 0.217], [64656.5, 0.016], [64656.6, 0.011], [64656.7, 0.027], [64656.8, 1.471], [64656.9, 0.0], [64657.0, 0.0], [64657.1, 0.002], [64657.2, 0.06], [64657.3, 0.271], [64657.5, 0.002], [64661.9, 0.626], [64662.3, 0.421], [64670.9, 2.776], [64678.2, 0.641], [64679.7, 0.473], [64679.8, 0.031], [64681.7, 0.009], [64682.7, 0.164], [64682.8, 0.051], [64682.9, 0.005], [64683.0, 0.155], [64683.1, 0.0], [64683.2, 0.004], [64683.3, 0.016], [64683.4, 0.247], [64683.5, 0.002], [64683.7, 0.004], [64683.9, 3.642], [64684.2, 0.574], [64684.3, 0.003], [64684.6, 0.005], [64684.9, 0.432], [64685.0, 0.008], [64685.2, 0.001], [64688.1, 0.179], [64690.1, 0.004], [64694.2, 46.085]], "asks": [[64694.3, 3.622], [64701.6, 0.001], [64702.4, 0.293], [64702.8, 0.002], [64703.2, 0.004], [64703.3, 0.448], [64703.5, 0.383], [64703.7, 0.001], [64703.8, 0.001], [64704.0, 0.304], [64704.1, 0.01], [64704.2, 0.588], [64704.3, 0.106], [64704.5, 2.321], [64704.6, 0.328], [64704.7, 0.22], [64704.8, 0.004], [64704.9, 0.007], [64705.0, 0.901], [64705.1, 0.074], [64705.2, 0.0], [64705.3, 0.0], [64705.6, 0.023], [64707.0, 0.001], [64724.0, 0.011], [64724.4, 0.383], [64724.7, 0.0], [64725.0, 0.001], [64725.2, 0.042], [64725.3, 0.152], [64725.7, 0.004], [64726.1, 0.0], [64730.5, 0.0], [64730.8, 0.0], [64730.9, 0.004], [64731.0, 0.389], [64731.1, 0.002], [64731.2, 1.157], [64731.3, 0.076], [64731.4, 0.391], [64731.5, 0.002], [64745.2, 0.116], [64745.5, 0.0], [64745.9, 0.001], [64746.2, 0.003], [64746.3, 0.04], [64746.5, 0.016], [64834.0, 5.427], [64889.8, 18.145], [65159.2, 0.079], [65341.2, 0.002], [65632.4, 2.472]]}
{"kind": "depth", "E": 1787081847819, "U": 11315466908967, "u": 11315466917696, "recv_ms": 1787081847788, "bids": [[14394.2, 0.42], [14494.2, 3.612], [14594.2, 0.168], [58224.7, 0.002], [61459.4, 0.0], [62106.4, 0.0], [63400.4, 0.078], [63659.1, 2.2], [63924.3, 1.877], [63950.2, 2.811], [64047.3, 0.073], [64370.7, 0.034], [64531.9, 0.776], [64532.4, 3.673], [64549.4, 3.972], [64645.0, 4.469], [64645.3, 0.032], [64669.7, 0.077], [64673.0, 0.012], [64686.2, 0.224], [64686.4, 0.171], [64687.4, 0.032], [64687.7, 0.117], [64690.0, 0.008], [64694.2, 46.086]], "asks": [[64696.9, 0.827], [64702.4, 0.274], [64704.3, 0.047], [64704.6, 0.373], [64705.6, 0.271], [64705.8, 0.097], [64725.5, 0.043], [64725.8, 0.048], [64731.8, 0.662], [64732.1, 0.21], [64746.7, 0.073], [64747.0, 0.045], [64834.0, 5.427], [64850.9, 10.459], [65341.2, 0.002]]}
{"kind": "depth", "E": 1787081847921, "U": 11315466917922, "u": 11315466925822, "recv_ms": 1787081847889, "bids": [[1000.0, 35.81], [14394.2, 0.672], [14494.2, 3.472], [14594.2, 0.056], [58224.7, 0.002], [62106.4, 0.003], [63694.2, 0.0], [63763.6, 3.247], [64042.6, 0.002], [64046.0, 0.409], [64047.3, 0.073], [64575.7, 0.0], [64624.5, 0.191], [64630.2, 0.003], [64644.7, 0.276], [64677.8, 1.366], [64685.9, 0.07], [64686.1, 0.144], [64687.1, 0.316]], "asks": [[64701.8, 0.02], [64704.9, 0.052], [64705.9, 0.225], [64706.1, 0.501], [64710.3, 0.214], [64726.1, 0.045], [64732.1, 0.315], [64732.3, 2.508], [64735.9, 0.127], [64747.3, 0.06], [64773.7, 0.009], [64836.9, 0.122], [65341.2, 0.002], [65470.6, 1.772], [65573.6, 3.346], [65633.7, 2.433], [65694.3, 0.0], [65835.6, 0.0], [65984.1, 0.003]]}
{"kind": "depth", "E": 1787081848023, "U": 11315466926159, "u": 11315466935050, "recv_ms": 1787081847993, "bids": [[1000.0, 35.81], [14394.2, 0.966], [14494.2, 3.234], [14594.2, 0.0], [58224.7, 0.002], [63917.9, 3.031], [64047.3, 0.073], [64348.1, 2.518], [64350.2, 0.492], [64532.4, 0.0], [64549.4, 4.55], [64624.8, 0.032], [64660.6, 0.071], [64665.1, 1.341], [64672.5, 0.235], [64673.3, 0.56], [64673.8, 0.002], [64674.6, 0.474], [64675.8, 0.001], [64682.4, 0.081], [64686.0, 0.261], [64686.2, 0.324], [64686.3, 0.295], [64686.5, 0.102], [64686.6, 0.171], [64686.7, 0.102], [64687.8, 0.583], [64690.0, 0.004], [64694.2, 46.047]], "asks": [[64696.9, 0.827], [64703.9, 0.011], [64704.1, 0.034], [64704.3, 0.587], [64705.3, 0.19], [64705.4, 0.261], [64705.5, 0.636], [64705.7, 0.371], [64705.8, 0.237], [64706.0, 1.227], [64712.8, 0.002], [64713.5, 2.875], [64717.4, 0.166], [64718.2, 2.472], [64726.5, 0.323], [64731.6, 0.255], [64731.7, 4.271], [64731.9, 1.399], [64732.0, 0.181], [64732.2, 0.109], [64834.0, 5.427], [64850.9, 0.051], [64889.8, 18.505], [65341.2, 0.002], [65729.5, 2.155], [66632.9, 0.0]]}
{"kind": "depth", "E": 1787081848125, "U": 11315466935104, "u": 11315466941994, "recv_ms": 1787081848092, "bids": [[14394.2, 1.316], [14494.2, 2.884], [58224.7, 0.002], [61459.4, 0.0], [62106.4, 0.0], [63694.2, 0.02], [63756.1, 6.271], [64047.3, 0.073], [64370.7, 0.024], [64532.5, 3.51], [64575.7, 0.28], [64616.5, 0.289], [64623.8, 0.032], [64624.2, 0.033], [64630.2, 0.171], [64635.9, 0.023], [64659.7, 0.076], [64659.9, 0.072], [64660.2, 0.731], [64675.8, 0.081], [64678.2, 0.023], [64682.4, 0.001], [64682.6, 0.028], [64690.0, 0.008], [64693.3, 0.044], [64694.2, 45.988]], "asks": [[64694.3, 3.622], [64704.8, 0.005], [64726.9, 0.171], [64735.9, 0.199], [64773.7, 0.176], [64804.3, 1.392], [64836.9, 0.4], [64850.9, 10.459], [65341.2, 0.002], [65415.6, 0.763], [65481.0, 1.23], [65600.0, 80.709], [65606.5, 0.761], [65618.8, 0.327], [65694.3, 0.02], [65808.3, 4.096]]}
{"kind": "depth", "E": 1787081848227, "U": 11315466942000, "u": 11315466956147, "recv_ms": 1787081848195, "bids": [[1000.0, 35.81], [14394.2, 1.68], [14494.2, 2.52], [58224.7, 0.002], [61459.4, 0.0], [62106.4, 0.003], [63775.5, 0.354], [64047.3, 0.073], [64111.3, 0.0], [64115.2, 0.016], [64271.5, 0.002], [64275.5, 0.008], [64370.7, 0.023], [64432.2, 0.014], [64436.2, 0.004], [64493.0, 0.073], [64493.7, 9.412], [64532.5, 3.678], [64549.4, 0.0], [64549.5, 5.125], [64575.7, 0.0], [64593.3, 0.097], [64597.3, 0.002], [64623.5, 1.269], [64630.2, 0.003], [64659.9, 0.142], [64660.0, 0.593], [64660.2, 0.801], [64690.0, 0.004], [64694.2, 46.01]], "asks": [[64726.7, 6.029], [64735.9, 0.127], [64744.7, 0.217], [64773.7, 0.009], [64787.2, 0.47], [64791.2, 0.004], [64836.9, 0.122], [64889.8, 23.738], [64949.2, 0.008], [64953.2, 0.13], [65017.9, 1.787], [65111.5, 0.0], [65115.6, 0.029], [65212.0, 2.245], [65274.3, 0.009], [65278.3, 0.016], [65341.2, 0.002], [65567.7, 0.988], [65623.1, 13.598], [65664.7, 2.236], [65729.4, 2.129]]}
{"kind": "depth", "E": 1787081848329, "U": 11315466956957, "u": 11315466967242, "recv_ms": 1787081848299, "bids": [[1000.0, 35.81], [14394.2, 2.03], [14494.2, 2.17], [51755.0, 0.0], [51755.4, 0.0], [58224.7, 0.002], [61459.4, 0.0], [61640.1, 0.015], [61643.9, 0.014], [62106.4, 0.0], [63694.2, 0.0], [63760.9, 0.002], [64047.3, 0.073], [64575.7, 0.0], [64630.1, 1.603], [64635.9, 0.026], [64659.7, 0.146], [64690.0, 0.004], [64694.2, 46.011]], "asks": [[64696.9, 0.827], [64704.8, 0.004], [64726.6, 3.508], [64726.7, 6.029], [64735.8, 0.0], [64773.7, 0.009], [64836.9, 0.122], [65017.8, 0.175], [65341.2, 0.002], [65464.3, 2.745], [65632.5, 14.671], [65694.3, 0.0], [65697.2, 4.255], [67721.0, 0.0], [67725.2, 0.042]]}
{"kind": "depth", "E": 1787081848431, "U": 11315466967333, "u": 11315466973332, "recv_ms": 1787081848401, "bids": [[14394.2, 2.394], [14494.2, 1.806], [51755.0, 0.0], [58224.7, 0.002], [61455.7, 0.002], [61455.8, 0.006], [61459.4, 0.0], [62106.4, 0.003], [63855.2, 0.0], [63885.5, 1.277], [64047.3, 0.073], [64370.7, 0.034], [64566.3, 0.0], [64575.7, 0.0], [64630.1, 1.603], [64659.8, 0.075], [64660.0, 0.693], [64660.1, 0.113], [64660.3, 0.1], [64660.4, 0.171], [64665.5, 0.103], [64675.8, 0.001], [64682.4, 0.081], [64690.0, 0.008]], "asks": [[64694.3, 3.619], [64698.7, 0.586], [64726.7, 6.029], [64726.8, 1.856], [64735.8, 0.0], [64773.7, 0.009], [64823.7, 0.0], [64836.9, 0.122], [64889.8, 18.403], [65017.8, 0.328], [65211.9, 0.307], [65341.2, 0.002], [65607.5, 2.265], [65632.5, 13.606], [65988.1, 0.027]]}
{"kind": "depth", "E": 1787081848533, "U": 11315466973381, "u": 11315466980292, "recv_ms": 1787081848508, "bids": [[1000.0, 35.81], [14394.2, 2.744], [14494.2, 1.456], [58224.7, 0.002], [63626.8, 1.099], [63694.2, 0.02], [63756.2, 5.354], [63781.3, 1.256], [63847.2, 0.625], [64047.3, 0.073], [64549.5, 1.186], [64620.7, 41.921], [64627.3, 0.0], [64675.8, 0.081], [64682.4, 0.001], [64690.0, 0.004], [64694.2, 46.037]], "asks": [[64694.3, 3.603], [64696.9, 0.827], [64697.5, 0.028], [64698.7, 0.71], [64701.0, 0.061], [64726.8, 1.856], [64834.0, 0.029], [65341.2, 0.002], [65464.2, 1.292], [65600.0, 82.992], [65632.4, 3.537], [65694.3, 0.02]]}
{"kind": "depth", "E": 1787081848635, "U": 11315466980551, "u": 11315466989098, "recv_ms": 1787081848605, "bids": [[1000.0, 35.81], [14394.2, 3.108], [14494.2, 1.092], [58224.7, 0.002], [61459.4, 0.0], [61459.5, 0.04], [61459.6, 2.439], [62106.4, 0.0], [63626.7, 1.099], [63756.1, 8.464], [63849.5, 1.13], [64047.3, 0.073], [64549.6, 3.939], [64620.1, 0.004], [64620.7, 0.183], [64620.8, 0.013], [64625.0, 1.59], [64627.2, 41.804], [64690.0, 0.008], [64694.2, 46.038]], "asks": [[64694.4, 0.038], [64697.5, 0.038], [64726.8, 1.702], [64834.0, 5.427], [64866.8, 0.013], [65341.2, 0.002], [65463.6, 3.064], [65600.0, 85.275], [65632.4, 4.602], [65657.8, 0.763], [65697.1, 1.065]]}
{"kind": "depth", "E": 1787081848737, "U": 11315466989242, "u": 11315466996377, "recv_ms": 1787081848707, "bids": [[14394.2, 3.458], [14494.2, 0.742], [58224.7, 0.002], [62106.4, 0.003], [63694.2, 0.0], [63820.8, 2.582], [64047.3, 0.073], [64370.7, 0.024], [64625.0, 43.379], [64627.2, 0.015], [64661.7, 0.001], [64662.4, 0.063], [64663.3, 0.003], [64677.8, 0.44], [64678.2, 0.641], [64678.5, 0.966], [64679.4, 0.001], [64690.0, 0.004], [64694.2, 46.039]], "asks": [[64711.2, 0.071], [64711.9, 2.225], [64713.5, 2.319], [64714.3, 0.558], [64714.4, 0.005], [64715.1, 0.12], [64717.4, 0.051], [64718.2, 2.587], [64726.9, 0.325], [64892.7, 0.007], [64918.5, 0.013], [64944.4, 0.002], [64970.3, 0.013], [65341.2, 0.002], [65694.3, 0.0], [65749.0, 3.797]]}
{"kind": "depth", "E": 1787081848839, "U": 11315466997411, "u": 11315467007823, "recv_ms": 1787081848808, "bids": [[1000.0, 35.81], [14294.2, 0.042], [14394.2, 3.738], [14494.2, 0.42], [58224.7, 0.002], [61459.4, 0.0], [62106.4, 0.0], [63439.9, 0.0], [63729.5, 7.573], [64047.3, 0.073], [64176.7, 1.559], [64690.0, 0.008], [64694.2, 46.039]], "asks": [[64696.9, 0.827], [64726.7, 6.029], [64726.8, 1.702], [64726.9, 0.171], [65212.0, 1.326], [65341.2, 0.002], [65470.7, 11.012]]}
{"kind": "depth", "E": 1787081848941, "U": 11315467008029, "u": 11315467022071, "recv_ms": 1787081848909, "bids": [[1000.0, 35.81], [14294.2, 0.238], [14394.2, 3.696], [14494.2, 0.266], [58224.7, 0.002], [62106.4, 0.003], [63694.2, 0.02], [64047.3, 0.073], [64331.0, 5.03], [64332.1, 2.871], [64350.2, 0.0], [64351.6, 0.493], [64427.7, 0.0], [64428.2, 0.538], [64493.7, 0.002], [64493.8, 0.0], [64493.9, 10.021], [64498.6, 0.0], [64499.0, 0.61], [64532.5, 0.037], [64532.7, 5.045], [64549.6, 0.0], [64549.7, 4.68], [64567.0, 0.087], [64635.7, 0.16], [64640.7, 0.263], [64677.8, 0.44], [64690.0, 0.004], [64694.2, 46.04]], "asks": [[64710.3, 0.214], [64726.8, 1.856], [64834.0, 4.043], [64850.9, 0.051], [64851.0, 6.953], [64889.8, 18.135], [64897.5, 2.39], [64897.9, 0.001], [64967.9, 0.267], [64969.3, 0.007], [65066.7, 0.011], [65341.2, 0.002], [65607.5, 0.002], [65632.5, 12.541], [65694.3, 0.02], [65862.1, 0.0]]}
{"kind": "depth", "E": 1787081849043, "U": 11315467022153, "u": 11315467030892, "recv_ms": 1787081849011, "bids": [[14294.2, 0.476], [14394.2, 3.584], [14494.2, 0.14], [58224.7, 0.002], [61459.4, 0.0], [63400.4, 0.081], [63723.8, 3.484], [63794.2, 10.544], [64047.2, 0.026], [64047.3, 0.075], [64067.5, 0.0], [64215.2, 0.002], [64370.7, 0.034], [64564.5, 0.022], [64625.0, 1.59], [64627.2, 41.804], [64673.3, 0.56], [64674.3, 0.001], [64674.6, 0.358], [64674.7, 0.124], [64675.6, 0.0], [64678.5, 0.04], [64678.7, 0.945], [64679.7, 0.473], [64682.6, 0.033], [64690.0, 0.008], [64693.1, 0.937], [64694.2, 46.05]], "asks": [[64696.9, 0.827], [64713.3, 0.021], [64713.7, 0.558], [64714.3, 0.002], [64714.6, 0.23], [64715.6, 0.949], [64716.7, 0.581], [64718.1, 0.007], [64718.2, 2.472], [64718.5, 1.776], [64834.0, 5.427], [64851.0, 10.428], [65183.9, 0.637], [65334.4, 0.948], [65341.2, 0.002], [65613.0, 0.329], [65729.4, 2.554]]}
{"kind": "depth", "E": 1787081849145, "U": 11315467030953, "u": 11315467037394, "recv_ms": 1787081849116, "bids": [[1000.0, 35.81], [14294.2, 0.714], [14394.2, 3.458], [14494.2, 0.028], [51755.0, 0.0], [58224.7, 0.002], [62106.4, 0.0], [63694.2, 0.0], [63820.8, 3.364], [63885.5, 1.51], [63891.2, 2.614], [64047.3, 0.073], [64176.6, 1.247], [64469.3, 0.217], [64498.1, 27.479], [64498.7, 0.003], [64575.7, 0.0], [64603.6, 0.85], [64630.2, 0.003], [64645.0, 0.969], [64655.3, 4.129], [64661.2, 0.001], [64682.6, 0.028]], "asks": [[64699.0, 0.001], [64706.7, 0.002], [64720.7, 0.002], [64735.9, 0.127], [64736.9, 0.484], [64748.7, 0.016], [64773.8, 0.002], [64834.0, 4.043], [64836.9, 0.122], [64851.0, 6.952], [64896.3, 6.162], [64896.4, 26.345], [64897.5, 0.002], [65211.9, 1.226], [65212.0, 1.02], [65341.2, 0.002], [65400.5, 0.0], [65470.6, 3.602], [65600.0, 87.559], [65632.4, 5.667], [65659.5, 0.004], [65694.3, 0.0], [65834.9, 0.759]]}
{"kind": "depth", "E": 1787081849247, "U": 11315467038500, "u": 11315467047881, "recv_ms": 1787081849217, "bids": [[1000.0, 35.81], [14294.2, 1.05], [14394.2, 3.15], [14494.2, 0.0], [51755.0, 0.0], [58224.7, 0.002], [61459.4, 0.0], [62106.4, 0.003], [63669.2, 0.314], [63766.3, 1.028], [64047.3, 0.073], [64532.7, 0.001], [64549.7, 0.013], [64575.7, 0.0], [64587.7, 2.971], [64630.2, 0.003], [64675.8, 0.001], [64678.2, 0.023], [64682.4, 0.081], [64689.9, 0.519], [64690.0, 0.004], [64694.2, 46.05]], "asks": [[64694.3, 3.598], [64696.9, 0.827], [64708.0, 0.001], [64735.9, 0.127], [64773.8, 0.002], [64834.0, 0.029], [64836.9, 0.122], [64851.0, 0.02], [64895.1, 0.005], [64895.2, 0.001], [65341.2, 0.002], [65623.1, 11.335], [65987.0, 0.341]]}
{"kind": "depth", "E": 1787081849349, "U": 11315467048006, "u": 11315467057053, "recv_ms": 1787081849322, "bids": [[14294.2, 1.4], [14394.2, 2.8], [51755.4, 0.0], [58224.7, 0.002], [61459.4, 0.0], [62106.4, 0.0], [63694.2, 0.02], [63871.3, 0.787], [63925.4, 6.205], [64047.3, 0.073], [64370.7, 0.035], [64493.9, 0.0], [64495.8, 1.45], [64689.9, 0.519], [64690.2, 3.767], [64692.8, 0.059], [64694.2, 46.051]], "asks": [[64694.3, 3.603], [64709.0, 1.528], [64773.8, 0.169], [64823.7, 0.001], [64836.9, 0.4], [64889.8, 8.327], [65017.8, 0.327], [65211.9, 1.532], [65341.2, 0.002], [65500.0, 335.804], [65600.0, 91.364], [65657.9, 0.763], [65694.3, 0.02]]}
{"kind": "depth", "E": 1787081849451, "U": 11315467057071, "u": 11315467065154, "recv_ms": 1787081849419, "bids": [[1000.0, 35.81], [14294.2, 1.764], [14394.2, 2.436], [51755.0, 0.0], [58224.7, 0.002], [63396.4, 0.0], [63399.7, 0.016], [63400.4, 0.084], [63659.1, 3.298], [63756.1, 9.56], [63917.9, 4.594], [64047.3, 0.073], [64370.7, 0.034], [64469.3, 0.001], [64498.2, 0.363], [64616.5, 0.286], [64635.9, 0.026], [64651.3, 0.125], [64681.3, 0.085], [64682.4, 0.001], [64687.1, 0.313], [64689.8, 0.371], [64689.9, 0.523], [64694.2, 46.051]], "asks": [[64694.3, 3.596], [64696.9, 0.827], [64697.6, 1.185], [64700.8, 0.334], [64704.0, 0.303], [64707.2, 1.629], [64709.0, 0.628], [64773.8, 0.002], [64804.3, 1.392], [64823.7, 0.0], [64836.9, 0.122], [65341.2, 2.294], [65600.0, 93.646], [65607.8, 2.445]]}
{"kind": "depth", "E": 1787081849553, "U": 11315467065250, "u": 11315467073276, "recv_ms": 1787081849524, "bids": [[1000.0, 35.81], [14294.2, 2.114], [14394.2, 2.086], [51755.0, 0.0], [58224.7, 0.002], [61459.4, 0.001], [62106.4, 0.003], [63659.2, 1.098], [63694.2, 0.0], [64047.3, 0.073], [64427.2, 34.114], [64428.2, 5.469], [64494.0, 10.08], [64532.8, 10.123], [64549.8, 4.587], [64568.0, 6.295], [64576.6, 0.341], [64579.6, 4.295], [64584.0, 2.941], [64588.9, 2.319], [64590.6, 0.212], [64592.0, 0.808], [64620.9, 0.099], [64622.4, 3.366], [64623.4, 0.005], [64623.9, 0.046], [64673.2, 0.001], [64674.7, 0.131], [64676.5, 0.338], [64683.9, 3.322], [64689.9, 0.523], [64690.5, 0.341], [64692.8, 0.0], [64694.2, 46.051]], "asks": [[64694.3, 3.58], [64697.5, 0.028], [64701.8, 0.001], [64702.2, 0.003], [64702.4, 0.252], [64702.6, 0.001], [64703.6, 0.004], [64704.0, 0.265], [64704.3, 0.545], [64704.6, 0.328], [64704.9, 0.007], [64705.2, 0.0], [64706.8, 0.032], [64707.7, 2.365], [64713.7, 0.002], [64714.4, 0.561], [64716.7, 0.04], [64716.8, 1.792], [64717.8, 0.003], [64718.1, 0.007], [64728.5, 0.63], [64729.9, 0.0], [64732.3, 12.508], [64733.1, 0.024], [64759.5, 0.563], [64763.3, 0.022], [64766.3, 0.07], [64767.2, 0.0], [64768.2, 0.085], [64792.5, 0.023], [64802.2, 0.453], [64803.1, 2.322], [64829.0, 0.094], [64831.2, 3.887], [64834.0, 5.427], [64851.0, 10.428], [64889.8, 18.399], [64967.8, 32.603], [65017.8, 0.328], [65341.2, 2.294], [65694.3, 0.0], [65729.5, 1.091], [65761.9, 1.066]]}
{"kind": "depth", "E": 1787081849655, "U": 11315467073289, "u": 11315467081176, "recv_ms": 1787081849622, "bids": [[14294.2, 2.478], [14394.2, 1.722], [51755.0, 0.0], [58224.7, 0.002], [58224.8, 0.002], [61459.4, 0.0], [61459.5, 0.042], [62106.4, 0.0], [64047.3, 0.073], [64370.7, 0.034], [64625.0, 43.482], [64625.5, 0.026], [64627.2, 0.015], [64630.1, 1.603], [64672.3, 0.0], [64675.8, 0.081], [64681.3, 0.005], [64689.9, 0.519], [64694.1, 0.006]], "asks": [[64694.3, 3.578], [64697.5, 0.028], [64697.6, 1.186], [64700.8, 0.335], [64702.6, 0.021], [64702.9, 0.121], [64704.0, 0.266], [64707.2, 1.63], [64707.4, 1.787], [64708.3, 0.112], [64726.6, 2.228], [64729.6, 3.544], [64755.0, 0.2], [64757.6, 0.346], [64759.4, 1.721], [64767.9, 32.178], [64790.4, 1.61], [64792.4, 0.027], [64795.1, 0.008], [65341.2, 2.294], [65383.1, 0.0], [65580.6, 0.608], [65852.0, 1.516]]}
{"kind": "depth", "E": 1787081849757, "U": 11315467081366, "u": 11315467087509, "recv_ms": 1787081849727, "bids": [[1000.0, 35.81], [14294.2, 2.828], [14394.2, 1.372], [51755.0, 0.0], [58224.7, 0.002], [58224.8, 0.0], [61459.4, 0.0], [62106.4, 0.003], [63659.1, 4.396], [63694.2, 0.02], [64047.3, 0.073], [64675.8, 0.081], [64677.5, 0.638], [64682.4, 0.001], [64689.9, 0.519], [64694.2, 46.05]], "asks": [[64696.9, 0.827], [64697.5, 0.038], [64707.1, 0.33], [64708.1, 0.067], [64710.7, 2.828], [64711.9, 1.3], [64720.0, 0.021], [64767.5, 0.022], [64768.5, 0.083], [65341.2, 2.294], [65483.7, 2.747], [65594.8, 9.817], [65613.0, 0.556], [65694.3, 0.02], [65724.3, 17.081], [65761.8, 1.063]]}
{"kind": "depth", "E": 1787081849859, "U": 11315467087532, "u": 11315467091971, "recv_ms": 1787081849830, "bids": [[1000.0, 35.81], [14294.2, 3.192], [14394.2, 1.008], [58224.7, 0.002], [62106.4, 0.0], [63078.6, 0.001], [63691.5, 4.705], [63918.0, 12.543], [63955.2, 1.576], [64047.3, 0.073], [64675.1, 2.791], [64675.8, 0.235]], "asks": [[64726.3, 0.002], [64726.4, 0.16], [64726.8, 1.702], [64768.2, 0.04], [64768.5, 0.038], [65341.2, 2.294], [65729.4, 3.618], [65814.9, 0.607], [65984.1, 0.0], [65987.4, 0.0]]}
{"kind": "depth", "E": 1787081849961, "U": 11315467092059, "u": 11315467096866, "recv_ms": 1787081849929, "bids": [[14294.2, 3.542], [14394.2, 0.658], [58224.7, 0.002], [61459.4, 0.0], [63694.2, 0.0], [64047.3, 0.073], [64067.5, 66.103], [64215.2, 54.828], [64331.0, 48.424], [64332.1, 9.031], [64351.6, 0.001], [64352.4, 0.493], [64370.7, 0.034], [64675.7, 1.715], [64675.8, 0.081], [64677.8, 0.44], [64689.9, 0.519], [64694.2, 46.051]], "asks": [[64696.9, 0.827], [64710.3, 0.214], [64757.6, 0.234], [64942.9, 0.0], [65054.4, 2.41], [65062.7, 7.216], [65065.2, 43.472], [65182.3, 52.819], [65332.2, 66.028], [65341.2, 2.294], [65694.3, 0.0]]}
{"kind": "depth", "E": 1787081850063, "U": 11315467096987, "u": 11315467108842, "recv_ms": 1787081850035, "bids": [[1000.0, 35.81], [14194.2, 0.07], [14294.2, 3.766], [14394.2, 0.364], [58224.7, 0.002], [61459.4, 0.0], [61459.5, 0.044], [62106.4, 0.003], [63072.2, 2.296], [63399.7, 0.013], [63691.5, 3.608], [63713.5, 0.79], [64047.2, 0.025], [64047.3, 0.073], [64368.4, 0.006], [64372.1, 0.108], [64575.7, 0.0], [64603.9, 0.029], [64604.0, 0.378], [64630.2, 0.003], [64654.1, 0.001], [64654.8, 0.064], [64682.6, 0.028], [64686.1, 0.146], [64689.9, 0.519], [64694.2, 46.051]], "asks": [[64694.3, 3.567], [64713.5, 2.875], [64714.4, 0.005], [64717.4, 0.166], [64717.7, 0.466], [64718.1, 0.009], [64718.5, 1.661], [64726.4, 0.16], [64735.9, 0.127], [64757.8, 0.001], [64758.5, 0.503], [64773.8, 0.002], [64836.9, 0.122], [64889.8, 18.582], [65341.2, 2.294], [65464.2, 2.207], [65567.7, 1.596], [65632.5, 11.477], [65664.7, 5.277], [65697.2, 3.192], [65931.4, 0.003], [65988.1, 0.021]]}
{"kind": "depth", "E": 1787081850165, "U": 11315467108929, "u": 11315467115611, "recv_ms": 1787081850133, "bids": [[1000.0, 35.81], [14194.2, 0.308], [14294.2, 3.654], [14394.2, 0.238], [58224.7, 0.002], [61455.8, 0.004], [61459.4, 0.0], [62106.4, 0.0], [63691.4, 2.201], [63694.2, 0.02], [63917.9, 6.469], [64047.3, 0.073], [64370.8, 0.776], [64549.8, 0.004], [64627.4, 6.039], [64650.0, 7.545], [64666.2, 1.222], [64670.9, 2.158], [64675.7, 1.561], [64676.5, 0.002], [64689.9, 0.519], [64694.2, 46.05]], "asks": [[64694.3, 3.749], [64696.9, 0.827], [64699.0, 0.085], [64724.3, 0.997], [64726.4, 0.006], [64726.7, 6.183], [64740.5, 3.5], [64763.1, 6.002], [64834.0, 0.029], [65341.2, 2.294], [65694.3, 0.02], [65787.6, 0.608], [65988.1, 0.018]]}
{"kind": "depth", "E": 1787081850267, "U": 11315467115698, "u": 11315467122005, "recv_ms": 1787081850238, "bids": [[14194.2, 0.532], [14294.2, 3.556], [14394.2, 0.112], [51755.0, 0.0], [58224.7, 0.002], [62106.4, 0.003], [63763.8, 3.417], [63782.5, 17.163], [64047.3, 0.073], [64176.7, 1.248], [64370.7, 0.024], [64549.9, 3.987], [64595.1, 10.664], [64674.1, 0.023], [64674.7, 0.124], [64675.6, 0.154], [64675.7, 1.561], [64677.5, 0.02]], "asks": [[64701.8, 0.02], [64701.9, 0.524], [64702.6, 0.001], [64702.9, 0.099], [64755.7, 0.002], [64755.8, 0.011], [64793.8, 3.224], [64795.5, 10.001], [64834.0, 5.427], [65341.2, 2.294], [65632.4, 6.731], [65632.5, 10.412]]}
{"kind": "depth", "E": 1787081850369, "U": 11315467122161, "u": 11315467130297, "recv_ms": 1787081850337, "bids": [[1000.0, 35.81], [14194.2, 0.784], [14294.2, 3.416], [14394.2, 0.0], [51755.4, 0.0], [58224.7, 0.002], [61459.4, 0.0], [63523.7, 4.938], [63659.2, 0.0], [63691.4, 3.298], [63691.5, 2.51], [63694.2, 0.0], [63756.2, 4.258], [63775.5, 0.588], [63924.4, 5.949], [64047.3, 0.073], [64370.7, 0.178], [64549.9, 0.049], [64593.1, 0.001], [64616.5, 0.289], [64648.6, 0.004], [64673.6, 0.995], [64678.7, 0.942], [64689.8, 0.371], [64694.2, 46.049]], "asks": [[64694.3, 3.752], [64718.7, 0.102], [64726.6, 2.225], [64793.7, 0.008], [64795.1, 0.0], [64823.7, 0.001], [64834.0, 0.029], [65017.8, 0.329], [65341.2, 2.294], [65416.3, 1.528], [65609.7, 1.524], [65618.8, 0.1], [65632.5, 9.347], [65694.3, 0.0], [65697.1, 2.128], [65697.2, 2.128], [65729.5, 0.027], [65739.9, 0.0], [65904.1, 0.66], [65988.1, 0.021], [71163.8, 0.0]]}
{"kind": "depth", "E": 1787081850471, "U": 11315467130355, "u": 11315467137258, "recv_ms": 1787081850446, "bids": [[14194.2, 1.134], [14294.2, 3.066], [58224.7, 0.002], [62106.4, 0.0], [63756.1, 10.657], [64047.3, 0.073], [64176.6, 1.558], [64550.0, 10.516], [64640.7, 0.163], [64661.7, 0.058], [64662.4, 0.006], [64672.5, 0.792], [64673.3, 0.003], [64673.8, 0.118], [64674.7, 0.008], [64675.8, 0.001], [64677.8, 1.366], [64678.7, 0.016], [64683.1, 0.08]], "asks": [[64696.9, 0.827], [64715.4, 0.667], [64716.8, 1.251], [64730.6, 0.015], [64823.7, 0.0], [64834.0, 5.427], [64889.8, 18.5], [65341.2, 2.294]]}
{"kind": "depth", "E": 1787081850573, "U": 11315467137435, "u": 11315467144474, "recv_ms": 1787081850540, "bids": [[14194.2, 1.498], [14294.2, 2.702], [58224.7, 0.002], [61459.4, 0.0], [62106.4, 0.003], [63400.3, 1.575], [63659.1, 5.494], [63694.2, 0.02], [64047.3, 0.073], [64176.6, 1.562], [64370.7, 0.178], [64479.5, 1.106], [64481.4, 0.193], [64490.1, 0.0], [64491.9, 0.005], [64500.7, 0.015], [64511.3, 0.002], [64521.9, 0.078], [64532.5, 0.032], [64543.1, 0.0], [64553.7, 0.006], [64564.3, 0.005], [64574.9, 0.0], [64585.5, 0.001], [64588.9, 2.319], [64596.1, 0.0], [64606.7, 0.001], [64617.3, 2.629], [64627.9, 0.0], [64638.5, 2.824], [64649.1, 0.108], [64659.7, 0.141], [64670.3, 0.001]], "asks": [[64694.3, 3.737], [64706.5, 0.022], [64709.9, 1.243], [64710.0, 1.027], [64710.7, 1.903], [64711.2, 0.996], [64713.3, 0.001], [64715.4, 0.126], [64716.7, 0.581], [64720.4, 0.007], [64720.6, 0.174], [64731.2, 1.152], [64741.8, 0.022], [64752.4, 0.0], [64763.0, 0.164], [64773.6, 0.003], [64784.2, 0.055], [64794.8, 0.0], [64803.0, 2.322], [64803.1, 0.003], [64805.4, 0.0], [64816.0, 2.441], [64826.6, 0.0], [64837.2, 0.063], [64847.8, 0.212], [64858.4, 0.002], [64869.0, 0.077], [64879.6, 0.118], [64890.2, 0.003], [64900.8, 0.014], [65017.8, 0.328], [65632.4, 7.796], [65694.3, 0.02], [65729.4, 4.682]]}
{"kind": "depth", "E": 1787081850675, "U": 11315467144528, "u": 11315467150077, "recv_ms": 1787081850645, "bids": [[1000.0, 35.81], [14194.2, 1.848], [14294.2, 2.352], [58224.7, 0.002], [61459.4, 0.0], [62106.4, 0.0], [63497.4, 2.055], [63691.4, 4.396], [63729.5, 7.181], [63756.1, 11.753], [63912.0, 9.003], [63924.3, 2.814], [63955.2, 0.795], [64019.8, 1.56], [64047.3, 0.073], [64176.6, 1.558], [64370.7, 0.179], [64499.0, 4.659], [64502.4, 5.356], [64575.7, 0.0], [64594.4, 0.067], [64595.2, 3.484], [64616.5, 0.286], [64627.1, 7.236], [64630.1, 1.603], [64635.9, 0.026], [64666.6, 0.377], [64673.1, 0.596], [64679.4, 0.155], [64683.0, 0.001], [64686.2, 0.17], [64689.4, 0.086], [64689.8, 0.371], [64694.2, 46.042]], "asks": [[64694.3, 3.734], [64696.9, 0.827], [64712.1, 0.155], [64718.4, 1.263], [64718.6, 0.008], [64724.9, 0.156], [64725.1, 0.017], [64730.9, 0.009], [64731.6, 0.101], [64735.8, 0.0], [64762.8, 2.334], [64773.7, 0.009], [64804.3, 1.392], [64836.9, 0.122], [64889.8, 18.313], [64967.7, 5.111], [64967.9, 0.028], [65341.2, 2.294], [65463.6, 2.301], [65632.4, 8.861], [65697.1, 3.192], [65729.4, 5.746]]}
{"kind": "depth", "E": 1787081850777, "U": 11315467150336, "u": 11315467157166, "recv_ms": 1787081850746, "bids": [[14194.2, 2.198], [14294.2, 2.002], [58224.7, 0.002], [61459.4, 0.001], [62106.4, 0.003], [63399.7, 0.01], [63694.2, 0.0], [63788.5, 2.537], [63918.0, 11.294], [64047.3, 0.073], [64176.7, 0.937], [64370.8, 0.621], [64494.0, 0.051], [64494.3, 10.001], [64512.9, 0.009], [64523.4, 0.018], [64532.8, 5.194], [64533.1, 5.036], [64550.0, 5.97], [64550.1, 7.303], [64653.5, 0.001], [64660.9, 3.566], [64689.8, 0.371], [64689.9, 0.519], [64693.2, 0.038], [64693.3, 0.001], [64693.9, 0.0], [64694.2, 44.752]], "asks": [[64705.7, 0.371], [64706.7, 0.003], [64713.0, 0.152], [64720.1, 0.031], [64727.4, 0.001], [64741.4, 0.064], [64751.9, 0.008], [64834.0, 5.427], [64889.8, 18.246], [65341.2, 2.294], [65605.9, 20.093], [65694.3, 0.0], [65988.1, 0.018], [71163.8, 0.0]]}
{"kind": "depth", "E": 1787081850879, "U": 11315467157221, "u": 11315467164711, "recv_ms": 1787081850848, "bids": [[14194.2, 2.562], [14294.2, 1.638], [58224.7, 0.002], [61459.4, 0.0], [63694.2, 0.02], [64047.3, 0.073], [64370.7, 0.166], [64533.9, 0.03], [64575.6, 0.28], [64630.1, 1.771], [64675.6, 0.154]], "asks": [[64735.8, 0.072], [64762.4, 0.005], [64773.7, 0.176], [64836.9, 0.4], [65341.2, 2.294], [65694.3, 0.02]]}
{"kind": "depth", "E": 1787081850981, "U": 11315467164842, "u": 11315467170290, "recv_ms": 1787081850950, "bids": [[1000.0, 35.81], [14194.2, 2.912], [14294.2, 1.288], [58224.7, 0.002], [61459.5, 0.046], [62106.4, 0.0], [63885.5, 1.744], [63917.9, 7.718], [64047.3, 0.073], [64176.6, 1.869], [64352.4, 0.001], [64352.9, 0.496], [64370.7, 0.321], [64544.4, 0.005], [64554.9, 0.249], [64575.6, 0.0], [64630.1, 1.603], [64675.4, 0.186], [64675.6, 0.0], [64677.8, 1.366]], "asks": [[64710.3, 0.214], [64735.8, 0.0], [64744.1, 0.0], [64750.9, 0.004], [64772.9, 0.006], [64773.7, 0.009], [64783.4, 1.391], [64836.9, 0.122], [65341.2, 2.294], [65609.7, 2.285]]}
{"kind": "depth", "E": 1787081851185, "U": 11315467177249, "u": 11315467184326, "recv_ms": 1787081851152, "bids": [[14194.2, 3.626], [14294.2, 0.574], [58224.7, 0.002], [61459.4, 0.0], [61459.5, 0.048], [62106.4, 0.0], [63694.2, 0.0], [63756.2, 3.161], [64047.3, 0.073], [64364.7, 2.545], [64370.7, 0.311], [64550.1, 2.639], [64575.9, 0.005], [64586.4, 0.294], [64675.8, 0.001], [64683.1, 0.08], [64689.8, 0.375], [64694.2, 44.753]], "asks": [[64703.9, 0.012], [64804.4, 0.207], [64814.9, 24.189], [64834.0, 0.029], [65463.6, 1.538], [65594.8, 8.903], [65694.3, 0.0]]}
{"kind": "depth", "E": 1787081851287, "U": 11315467184451, "u": 11315467190258, "recv_ms": 1787081851255, "bids": [[1000.0, 35.81], [14194.2, 3.766], [14294.2, 0.322], [14594.2, 0.112], [51755.0, 0.0], [51755.4, 0.002], [58224.7, 0.002], [61459.4, 0.0], [62106.4, 0.003], [63891.2, 2.38], [64047.3, 0.073], [64116.9, 0.0], [64533.1, 0.003], [64596.9, 0.127], [64635.7, 0.26], [64689.8, 0.371], [64694.2, 44.754]], "asks": [[64696.9, 0.827], [64726.2, 2.321], [64726.3, 0.002], [64726.7, 6.029], [64744.1, 0.004], [64750.9, 0.0], [64825.4, 0.006], [64851.0, 0.02], [65150.5, 2.602], [65335.8, 0.0], [65341.2, 2.294], [65804.5, 2.288], [65988.1, 0.015]]}
{"kind": "depth", "E": 1787081851389, "U": 11315467190312, "u": 11315467195961, "recv_ms": 1787081851356, "bids": [[14194.2, 3.64], [14294.2, 0.21], [14594.2, 0.35], [51755.0, 0.0], [51755.4, 0.0], [58224.7, 0.002], [63694.2, 0.02], [63756.2, 2.064], [64047.3, 0.073], [64533.2, 5.451], [64550.1, 7.302], [64575.6, 0.0], [64607.4, 0.022], [64617.9, 0.005], [64630.1, 1.603], [64653.4, 0.014]], "asks": [[64700.9, 0.397], [64703.3, 0.001], [64707.4, 1.26], [64722.3, 2.327], [64726.3, 0.002], [64726.5, 0.477], [64735.8, 0.0], [64748.7, 0.016], [64773.7, 0.009], [64799.9, 0.114], [64817.8, 0.003], [64823.7, 0.0], [64834.0, 5.427], [64835.9, 0.005], [64836.9, 0.122], [64846.4, 3.461], [64851.0, 10.428], [64889.8, 18.248], [65017.8, 0.327], [65341.2, 2.294], [65535.3, 3.21], [65694.3, 0.02]]}
{"kind": "depth", "E": 1787081851491, "U": 11315467196072, "u": 11315467203067, "recv_ms": 1787081851459, "bids": [[14194.2, 3.528], [14294.2, 0.084], [14594.2, 0.588], [58224.7, 0.002], [62106.4, 0.0], [63400.4, 0.081], [63756.1, 12.85], [63907.5, 0.781], [64047.3, 0.073], [64110.7, 1.103], [64370.7, 0.312], [64533.2, 0.418], [64550.1, 2.639], [64628.4, 0.005], [64653.4, 1.899]], "asks": [[64722.3, 0.442], [64834.0, 0.029], [64851.0, 0.02], [64856.9, 2.324], [65276.6, 4.678], [65341.2, 2.294]]}
{"kind": "depth", "E": 1787081851593, "U": 11315467203100, "u": 11315467209058, "recv_ms": 1787081851562, "bids": [[1000.0, 35.81], [14194.2, 3.332], [14294.2, 0.0], [14594.2, 0.868], [58224.7, 0.002], [61459.4, 0.0], [62106.4, 0.003], [63694.2, 0.0], [63755.4, 0.393], [64047.3, 0.073], [64370.7, 0.311], [64494.3, 0.001], [64494.4, 13.941], [64533.2, 4.147], [64550.2, 4.02], [64579.6, 4.295], [64623.8, 0.078], [64623.9, 0.0], [64638.9, 0.007], [64649.4, 0.3], [64661.3, 0.004], [64661.4, 1.663], [64661.5, 0.012], [64664.8, 0.072], [64664.9, 0.002], [64665.0, 0.056], [64689.8, 0.375], [64694.2, 44.769]], "asks": [[64694.3, 3.72], [64696.9, 0.827], [64703.9, 0.011], [64766.3, 0.07], [64817.8, 1.888], [64831.1, 3.865], [64831.2, 0.023], [64834.0, 5.427], [64851.0, 10.428], [64867.4, 0.158], [64877.9, 0.033], [64889.8, 20.668], [65341.2, 2.294], [65694.3, 0.0]]}
{"kind": "depth", "E": 1787081851695, "U": 11315467209163, "u": 11315467214790, "recv_ms": 1787081851664, "bids": [[14194.2, 2.982], [14594.2, 1.218], [58224.7, 0.002], [61459.4, 0.0], [62106.4, 0.0], [63400.4, 0.084], [63626.8, 0.0], [63749.7, 0.391], [63756.1, 13.947], [64047.3, 0.073], [64495.8, 2.528], [64623.0, 7.087], [64659.9, 0.147], [64689.8, 0.371]], "asks": [[64694.3, 3.61], [64888.4, 0.204], [65017.8, 0.328], [65341.2, 2.294], [65463.6, 0.775], [65761.9, 0.003]]}
{"kind": "depth", "E": 1787081851797, "U": 11315467214936, "u": 11315467219604, "recv_ms": 1787081851766, "bids": [[1000.0, 35.81], [14194.2, 2.632], [14594.2, 1.568], [51755.0, 0.0], [58224.7, 0.002], [61459.6, 2.437], [63694.2, 0.02], [63756.1, 15.044], [63780.3, 0.0], [63837.1, 3.754], [63891.2, 2.115], [63925.6, 1.549], [64047.3, 0.073], [64370.7, 0.321], [64635.7, 0.16], [64670.4, 1.207], [64673.8, 0.002], [64674.8, 0.419]], "asks": [[64696.9, 0.829], [64898.9, 0.005], [65341.2, 2.294], [65584.4, 2.433], [65694.3, 0.02]]}
{"kind": "depth", "E": 1787081851899, "U": 11315467219660, "u": 11315467225534, "recv_ms": 1787081851889, "bids": [[1000.0, 35.81], [14194.2, 2.268], [14594.2, 1.932], [58224.7, 0.002], [61459.4, 0.0], [62106.4, 0.003], [63626.7, 2.198], [63794.2, 10.075], [64047.3, 0.075], [64652.5, 0.211], [64657.5, 0.017], [64670.5, 5.851], [64677.9, 0.62], [64689.8, 0.371], [64694.2, 44.756]], "asks": [[64694.3, 3.609], [64696.9, 0.827], [64719.3, 0.62], [64726.7, 6.647], [65341.2, 2.294], [65620.6, 1.522]]}
{"kind": "depth", "E": 1787081852001, "U": 11315467225588, "u": 11315467230216, "recv_ms": 1787081851969, "bids": [[14194.2, 1.904], [14594.2, 2.296], [58224.7, 0.002], [62106.4, 0.0], [63694.2, 0.0], [63756.1, 15.201], [63820.8, 4.099], [64047.3, 0.073], [64352.9, 0.004], [64353.2, 0.492], [64575.6, 0.0], [64616.5, 0.289], [64630.1, 1.603], [64635.9, 0.023], [64677.8, 1.366]], "asks": [[64710.3, 0.214], [64735.8, 0.0], [64773.7, 0.009], [64804.3, 1.392], [64836.9, 0.122], [64889.8, 18.233], [65341.2, 2.294], [65694.3, 0.0], [65761.8, 2.126], [65988.1, 0.018]]}
{"kind": "depth", "E": 1787081852103, "U": 11315467230288, "u": 11315467235635, "recv_ms": 1787081852075, "bids": [[1000.0, 35.81], [14194.2, 1.554], [14594.2, 2.646], [58224.7, 0.002], [61459.4, 0.0], [62106.4, 0.003], [63695.3, 0.0], [63697.0, 0.014], [63700.4, 0.036], [63765.0, 0.062], [63767.3, 0.0], [63788.5, 3.006], [63911.9, 0.001], [63917.9, 9.281], [64047.3, 0.073], [64370.7, 0.311], [64618.6, 0.003], [64647.0, 0.001], [64649.5, 0.005], [64674.2, 0.248], [64674.8, 0.303], [64681.3, 0.085], [64682.6, 0.028], [64683.1, 0.0], [64684.3, 0.08], [64684.8, 0.327], [64684.9, 0.355], [64686.0, 0.581], [64686.1, 0.687], [64687.3, 0.265], [64689.8, 0.371], [64690.5, 0.021], [64691.2, 1.743], [64694.2, 44.769]], "asks": [[64694.3, 3.619], [64696.9, 0.827], [64698.6, 0.084], [64702.9, 0.015], [64715.5, 0.646], [64716.7, 0.581], [64744.1, 0.004], [64757.2, 2.33], [65341.2, 2.294], [65567.7, 2.204], [65613.0, 0.783], [65619.9, 1.26], [65622.2, 0.018], [65657.9, 0.002], [65683.4, 0.008], [65685.3, 0.0], [65687.0, 0.334]]}
{"kind": "depth", "E": 1787081852205, "U": 11315467235766, "u": 11315467241625, "recv_ms": 1787081852173, "bids": [[1000.0, 35.81], [14194.2, 1.19], [14594.2, 3.01], [51755.0, 0.0], [58224.7, 0.002], [61458.8, 0.001], [61458.9, 0.002], [62106.4, 0.0], [63694.2, 0.02], [63701.0, 1.403], [63723.8, 3.876], [63765.6, 0.03], [63768.0, 0.046], [63924.4, 5.011], [63969.3, 0.417], [64015.5, 9.97], [64047.3, 0.073], [64575.6, 0.0], [64630.1, 1.603], [64675.8, 0.081], [64681.3, 0.005], [64684.3, 0.088], [64684.9, 0.347], [64689.8, 0.371], [64690.2, 3.762], [64691.2, 1.744], [64694.1, 0.007], [64694.2, 44.769]], "asks": [[64694.3, 3.612], [64700.9, 0.4], [64703.5, 0.384], [64719.3, 0.002], [64735.8, 0.0], [64773.6, 0.003], [64836.8, 1.191], [65341.2, 2.294], [65403.1, 0.0], [65694.3, 0.02]]}
{"kind": "depth", "E": 1787081852307, "U": 11315467241684, "u": 11315467246979, "recv_ms": 1787081852276, "bids": [[14194.2, 0.84], [14594.2, 3.36], [51755.0, 0.0], [51755.4, 0.0], [58224.7, 0.002], [61459.4, 0.0], [63989.0, 1.648], [64047.3, 0.073], [64370.7, 0.311], [64575.6, 0.0], [64630.1, 1.603], [64675.8, 0.001], [64682.4, 0.081], [64689.8, 0.375]], "asks": [[64694.3, 3.614], [64703.5, 0.383], [64735.8, 0.0], [64773.6, 0.003], [64836.8, 1.191], [65341.2, 2.294], [65620.6, 1.53], [65622.9, 0.008], [65632.5, 8.282], [65687.6, 0.029], [65988.1, 0.015]]}
{"kind": "depth", "E": 1787081852409, "U": 11315467247085, "u": 11315467252039, "recv_ms": 1787081852377, "bids": [[1000.0, 35.81], [14194.2, 0.504], [14494.2, 0.014], [14594.2, 3.682], [58224.7, 0.002], [61459.4, 0.0], [62106.4, 0.003], [63694.2, 0.0], [63885.5, 1.9], [63907.5, 1.562], [63924.3, 3.752], [63972.8, 1.005], [64047.3, 0.073], [64575.6, 0.28], [64630.1, 1.771], [64635.9, 0.026], [64681.2, 0.453], [64689.8, 0.371], [64694.2, 44.756]], "asks": [[64696.9, 0.827], [64720.2, 0.608], [64735.8, 0.072], [64773.6, 0.17], [64823.7, 0.0], [64836.8, 1.469], [65341.2, 2.294], [65415.7, 0.769], [65632.4, 9.926], [65694.3, 0.0]]}
{"kind": "depth", "E": 1787081852511, "U": 11315467252304, "u": 11315467258883, "recv_ms": 1787081852478, "bids": [[1000.0, 35.81], [14194.2, 0.294], [14494.2, 0.168], [14594.2, 3.738], [58224.7, 0.002], [62106.4, 0.0], [63950.2, 3.748], [64047.3, 0.073], [64370.7, 0.31], [64575.6, 0.0], [64630.1, 1.603], [64679.0, 0.009], [64679.8, 0.023], [64682.1, 0.035], [64684.2, 0.566]], "asks": [[64699.7, 0.018], [64704.1, 0.018], [64735.8, 0.0], [64773.6, 0.003], [64836.8, 1.191], [65017.8, 0.329], [65341.2, 2.294], [65345.2, 1.3]]}
{"kind": "depth", "E": 1787081852613, "U": 11315467258961, "u": 11315467269396, "recv_ms": 1787081852581, "bids": [[14194.2, 0.182], [14494.2, 0.42], [14594.2, 3.598], [58224.7, 0.002], [61459.4, 0.0], [62106.4, 0.003], [63400.4, 0.087], [63694.2, 0.02], [63807.5, 5.147], [63925.6, 0.0], [64047.3, 0.073], [64370.7, 0.31], [64550.2, 0.002], [64550.4, 4.043], [64625.4, 0.028], [64626.9, 0.082], [64627.8, 2.7], [64645.5, 0.212], [64652.5, 0.001], [64666.6, 0.327], [64675.2, 1.743], [64689.8, 0.375], [64693.1, 0.637], [64693.8, 0.087], [64694.2, 44.769]], "asks": [[64694.3, 3.597], [64696.6, 0.001], [64696.9, 0.827], [64698.6, 0.0], [64698.7, 0.694], [64699.0, 0.001], [64699.5, 0.003], [64699.7, 0.002], [64700.9, 0.397], [64701.3, 0.041], [64702.8, 0.086], [64703.0, 0.003], [64704.1, 0.01], [64724.6, 0.239], [64726.5, 0.323], [64731.8, 0.542], [64760.8, 2.745], [64761.1, 0.0], [64767.4, 2.367], [64768.9, 0.0], [64834.0, 5.427], [65341.2, 2.294], [65463.7, 0.0], [65465.3, 1.527], [65600.0, 93.829], [65694.3, 0.02]]}
{"kind": "depth", "E": 1787081852715, "U": 11315467269536, "u": 11315467275412, "recv_ms": 1787081852685, "bids": [[1000.0, 35.81], [14194.2, 0.056], [14494.2, 0.644], [14594.2, 3.5], [58224.7, 0.002], [62106.4, 0.0], [63788.5, 5.354], [64047.3, 0.073], [64620.1, 2.384], [64638.5, 3.034], [64645.5, 0.002], [64685.1, 0.008], [64685.7, 0.002]], "asks": [[64698.6, 0.016], [64699.7, 0.018], [64704.2, 0.133], [64726.6, 2.379], [65017.8, 0.328], [65282.4, 4.22], [65341.2, 2.294], [65528.3, 1.524], [65988.1, 0.012]]}
{"kind": "depth", "E": 1787081852817, "U": 11315467275535, "u": 11315467280409, "recv_ms": 1787081852787, "bids": [[1000.0, 35.81], [14194.2, 0.0], [14494.2, 0.938], [14594.2, 3.262], [58224.7, 0.002], [61459.5, 0.046], [61459.6, 2.439], [63694.2, 0.0], [64047.3, 0.073], [64370.7, 0.311], [64575.6, 0.0], [64630.1, 1.603]], "asks": [[64696.9, 0.827], [64699.4, 0.09], [64726.6, 2.225], [64726.7, 6.801], [64735.7, 0.197], [64773.6, 0.003], [64836.8, 1.191], [64889.8, 8.327], [64889.9, 10.105], [65341.2, 2.294], [65405.9, 1.664], [65694.3, 0.0], [65697.2, 1.064], [65964.2, 0.656]]}
{"kind": "depth", "E": 1787081852919, "U": 11315467280533, "u": 11315467286335, "recv_ms": 1787081852887, "bids": [[14494.2, 1.302], [14594.2, 2.898], [58224.7, 0.002], [61459.4, 0.0], [62106.4, 0.003], [63400.4, 0.084], [63778.8, 0.876], [63885.5, 2.134], [63917.9, 10.844], [64047.3, 0.073], [64370.7, 0.321], [64494.4, 4.476], [64494.6, 7.182], [64533.2, 0.418], [64533.5, 2.397], [64550.4, 2.599], [64575.6, 0.0], [64627.8, 0.012], [64630.0, 2.333], [64689.8, 0.371]], "asks": [[64694.3, 3.594], [64701.0, 0.064], [64719.6, 0.62], [64735.7, 0.197], [64760.8, 0.011], [64773.6, 0.003], [64834.0, 0.029], [64834.1, 5.398], [64836.8, 1.191], [65276.5, 0.229], [65341.2, 2.294], [65415.7, 1.532], [65519.7, 3.333], [65528.3, 0.762]]}
{"kind": "depth", "E": 1787081853021, "U": 11315467286456, "u": 11315467291544, "recv_ms": 1787081852989, "bids": [[1000.0, 35.81], [14494.2, 1.652], [14594.2, 2.548], [58224.7, 0.002], [62106.4, 0.0], [63694.2, 0.02], [64047.3, 0.073], [64494.6, 0.047], [64494.7, 10.073], [64533.5, 4.915], [64550.4, 4.603], [64575.6, 0.0], [64627.8, 2.721], [64630.0, 2.333], [64677.8, 1.366]], "asks": [[64696.9, 0.827], [64702.8, 0.089], [64710.3, 0.214], [64724.3, 0.016], [64735.7, 0.197], [64741.4, 0.068], [64744.1, 0.0], [64753.7, 2.319], [64760.8, 2.705], [64773.6, 0.003], [64836.8, 1.191], [64889.9, 10.106], [65341.2, 2.294], [65694.3, 0.02], [65697.1, 4.256]]}
{"kind": "depth", "E": 1787081853123, "U": 11315467291705, "u": 11315467298043, "recv_ms": 1787081853090, "bids": [[1000.0, 35.81], [14494.2, 2.016], [14594.2, 2.184], [51755.0, 0.0], [58224.7, 0.002], [61459.4, 0.0], [62106.4, 0.003], [63781.3, 1.022], [64047.3, 0.073], [64575.6, 0.0], [64630.0, 2.333], [64675.4, 0.186], [64682.6, 0.028], [64689.8, 0.375], [64694.2, 44.756]], "asks": [[64694.3, 3.589], [64706.1, 0.502], [64719.6, 0.002], [64735.7, 0.197], [64773.6, 0.003], [64836.8, 1.191], [64895.0, 0.105], [64895.1, 0.002], [65212.0, 0.101], [65341.2, 2.294]]}
{"kind": "depth", "E": 1787081853225, "U": 11315467298213, "u": 11315467305003, "recv_ms": 1787081853192, "bids": [[14494.2, 2.366], [14594.2, 1.834], [58224.7, 0.002], [61459.4, 0.0], [63694.2, 0.0], [64047.3, 0.073], [64370.7, 0.311], [64575.6, 0.0], [64616.5, 0.286], [64630.1, 1.603], [64635.9, 0.026], [64677.8, 0.44], [64679.0, 0.935], [64689.8, 0.371], [64694.2, 44.748]], "asks": [[64694.3, 3.599], [64696.9, 0.827], [64723.9, 1.309], [64725.4, 0.018], [64726.6, 2.211], [64735.8, 0.0], [64773.6, 0.003], [64804.3, 1.392], [64836.8, 1.191], [64889.9, 9.789], [65341.2, 2.294], [65508.9, 1.791], [65694.3, 0.0], [65716.8, 1.959]]}
{"kind": "depth", "E": 1787081853327, "U": 11315467305207, "u": 11315467313712, "recv_ms": 1787081853297, "bids": [[1000.0, 35.81], [14494.2, 2.73], [14594.2, 1.47], [51755.4, 0.0], [58224.7, 0.002], [61459.5, 0.048], [62106.4, 0.0], [63500.6, 0.799], [63943.4, 6.557], [64047.3, 0.073], [64150.8, 0.049], [64550.4, 0.027], [64640.7, 0.263], [64675.4, 0.186], [64689.8, 0.375], [64694.2, 44.761]], "asks": [[64705.6, 0.257], [64834.1, 0.0], [65336.0, 19.832], [65341.2, 2.294], [65416.3, 2.291], [65483.7, 1.832], [65697.1, 5.32]]}
{"kind": "depth", "E": 1787081853429, "U": 11315467313896, "u": 11315467326417, "recv_ms": 1787081853397, "bids": [[1000.0, 35.81], [14494.2, 3.08], [14594.2, 1.12], [58224.7, 0.002], [61455.8, 0.002], [62106.4, 0.003], [63484.4, 0.79], [63694.2, 0.02], [64047.3, 0.073], [64150.8, 0.199], [64550.5, 4.636], [64575.6, 0.0], [64630.1, 1.603], [64640.0, 1.893], [64649.5, 0.001], [64675.4, 0.186], [64678.5, 0.966], [64679.0, 0.009]], "asks": [[64735.8, 0.0], [64773.7, 0.009], [64823.7, 0.0], [64834.1, 5.398], [64836.8, 1.191], [64889.9, 10.067], [65211.9, 2.451], [65341.2, 2.294], [65694.3, 0.02]]}
{"kind": "depth", "E": 1787081853531, "U": 11315467326806, "u": 11315467335968, "recv_ms": 1787081853500, "bids": [[14494.2, 3.444], [14594.2, 0.756], [58224.7, 0.002], [61459.4, 0.0], [62106.4, 0.0], [63694.2, 0.0], [64047.3, 0.073], [64370.7, 0.321], [64627.8, 0.012], [64675.8, 0.081], [64682.4, 0.001], [64689.8, 0.371], [64694.2, 44.765]], "asks": [[64694.3, 3.585], [64696.9, 0.827], [64699.4, 0.006], [64718.1, 0.007], [64760.8, 0.011], [65017.8, 0.327], [65341.2, 2.294], [65464.2, 3.122], [65613.0, 1.01], [65694.3, 0.0]]}
{"kind": "depth", "E": 1787081853633, "U": 11315467336030, "u": 11315467342470, "recv_ms": 1787081853601, "bids": [[1000.0, 35.81], [14394.2, 0.042], [14494.2, 3.724], [14594.2, 0.434], [58224.7, 0.002], [62106.4, 0.003], [63885.5, 2.399], [63924.3, 4.69], [64019.8, 0.78], [64047.3, 0.073], [64150.8, 0.168], [64370.7, 0.322], [64494.7, 0.059], [64494.8, 9.916], [64533.5, 0.0], [64533.6, 6.269], [64550.5, 0.001], [64550.6, 4.541], [64627.8, 2.7], [64675.8, 0.001], [64682.1, 0.027], [64683.1, 0.08], [64684.3, 0.096], [64685.1, 0.0], [64686.2, 0.178], [64689.8, 0.375]], "asks": [[64699.7, 0.002], [64704.2, 0.149], [64760.7, 2.776], [64834.1, 4.799], [64851.0, 8.398], [64889.9, 12.925], [65308.9, 1.611], [65341.2, 2.294], [65594.8, 7.989], [65605.9, 19.637], [65724.3, 15.501], [65988.1, 0.015]]}
{"kind": "depth", "E": 1787081853735, "U": 11315467342491, "u": 11315467350610, "recv_ms": 1787081853704, "bids": [[1000.0, 35.81], [14394.2, 0.224], [14494.2, 3.71], [14594.2, 0.266], [58224.7, 0.002], [61459.4, 0.0], [63885.5, 2.555], [63955.2, 0.014], [64047.3, 0.073], [64150.8, 0.144], [64630.1, 2.987], [64640.0, 1.889], [64647.0, 0.005], [64675.3, 0.787], [64675.4, 0.032], [64689.8, 0.375], [64694.2, 44.752]], "asks": [[64694.3, 3.586], [64696.9, 0.827], [64697.5, 0.028], [64699.8, 0.549], [64701.8, 0.001], [64701.9, 0.501], [64702.2, 0.026], [64703.2, 0.088], [65341.2, 2.294], [65600.0, 94.285], [65670.6, 27.575], [65800.0, 68.735], [71163.8, 0.0]]}
{"kind": "depth", "E": 1787081853837, "U": 11315467350841, "u": 11315467361748, "recv_ms": 1787081853807, "bids": [[14394.2, 0.462], [14494.2, 3.584], [14594.2, 0.154], [58224.7, 0.002], [61459.4, 0.0], [62106.4, 0.0], [63694.2, 0.02], [64047.3, 0.073], [64370.7, 0.311], [64533.6, 5.341], [64550.6, 3.326], [64575.6, 0.0], [64623.5, 1.237], [64623.8, 0.046], [64624.2, 0.001], [64624.5, 0.159], [64624.8, 0.0], [64630.1, 2.987], [64644.7, 0.244], [64645.0, 0.937], [64645.3, 0.0], [64645.7, 0.185], [64646.0, 2.765], [64659.7, 0.001], [64659.8, 0.005], [64659.9, 0.007], [64660.0, 0.523], [64660.1, 0.013], [64660.2, 0.631], [64660.3, 0.0], [64660.4, 0.001], [64660.6, 0.001], [64665.1, 1.241], [64665.5, 0.003], [64684.8, 0.868], [64685.8, 0.393], [64685.9, 0.0], [64686.0, 0.441], [64686.1, 0.006], [64686.2, 0.008], [64686.3, 0.095], [64686.4, 0.001], [64686.5, 0.002], [64686.6, 0.001], [64686.7, 0.002], [64686.9, 0.003], [64687.1, 0.281], [64687.4, 0.0], [64687.7, 0.085], [64688.1, 0.147], [64688.4, 0.086], [64689.8, 0.371]], "asks": [[64694.3, 3.593], [64697.5, 0.038], [64704.3, 0.082], [64705.3, 0.0], [64705.4, 0.003], [64705.5, 0.446], [64705.6, 0.009], [64705.7, 0.051], [64705.8, 0.006], [64705.9, 0.001], [64706.0, 1.122], [64706.1, 0.313], [64706.5, 0.127], [64706.8, 0.0], [64707.0, 0.464], [64707.1, 0.292], [64707.4, 1.218], [64707.7, 2.32], [64708.1, 0.022], [64708.3, 0.0], [64724.8, 1.094], [64725.2, 0.004], [64725.5, 0.001], [64725.8, 0.003], [64726.1, 0.0], [64726.5, 0.133], [64726.9, 0.001], [64731.4, 0.391], [64731.6, 0.003], [64731.7, 3.921], [64731.8, 0.294], [64731.9, 1.249], [64732.0, 0.041], [64732.1, 0.0], [64732.2, 0.004], [64732.3, 12.319], [64732.8, 0.112], [64735.8, 0.0], [64746.0, 2.009], [64746.3, 0.002], [64746.7, 0.031], [64747.0, 0.0], [64747.3, 0.015], [64773.7, 0.009], [64834.1, 5.398], [64836.8, 1.191], [64851.0, 0.02], [64851.1, 10.408], [65017.8, 0.328], [65341.2, 2.294], [65470.7, 10.403], [65609.7, 3.046], [65664.7, 6.858], [65694.3, 0.02], [67331.5, 0.0]]}
{"kind": "depth", "E": 1787081853939, "U": 11315467361919, "u": 11315467367868, "recv_ms": 1787081853907, "bids": [[1000.0, 35.81], [14394.2, 0.7], [14494.2, 3.472], [14594.2, 0.028], [58224.7, 0.002], [62106.4, 0.003], [64047.3, 0.073], [64150.8, 0.107], [64550.6, 4.575], [64644.4, 0.034], [64645.4, 0.71], [64649.0, 0.642], [64654.6, 0.375], [64655.3, 4.131], [64675.3, 0.787], [64675.8, 0.081], [64683.1, 0.0], [64684.3, 0.019], [64684.9, 0.424], [64685.6, 0.071], [64686.1, 0.004], [64686.8, 0.034], [64687.7, 0.117], [64689.8, 0.371], [64694.2, 44.766]], "asks": [[64696.9, 0.827], [64697.5, 0.028], [64704.2, 0.612], [64704.6, 0.366], [64705.6, 0.054], [64706.8, 0.091], [64707.0, 0.001], [64719.8, 0.62], [64725.8, 0.041], [64726.7, 6.846], [64732.3, 12.321], [64732.7, 0.026], [64733.0, 0.093], [64747.0, 0.038], [64747.9, 9.072], [65341.2, 2.294], [65535.3, 4.124], [65983.2, 0.604]]}
{"kind": "depth", "E": 1787081854041, "U": 11315467368118, "u": 11315467377339, "recv_ms": 1787081854010, "bids": [[1000.0, 35.81], [14394.2, 1.036], [14494.2, 3.164], [14594.2, 0.0], [58224.7, 0.002], [61459.4, 0.0], [62106.4, 0.0], [63694.2, 0.0], [64047.3, 0.073], [64575.6, 0.281], [64630.1, 3.156], [64645.7, 0.217], [64649.0, 0.638], [64675.8, 0.001], [64677.5, 0.002], [64677.8, 0.44], [64682.0, 0.924], [64682.4, 0.081], [64682.6, 0.033], [64685.7, 0.072], [64685.9, 0.1], [64686.0, 0.641], [64686.2, 0.208], [64686.3, 0.165], [64686.4, 0.101], [64686.5, 0.072], [64688.1, 0.179], [64689.8, 0.371]], "asks": [[64694.3, 3.598], [64697.5, 0.038], [64704.3, 0.114], [64704.7, 0.691], [64705.8, 0.118], [64705.9, 0.191], [64706.0, 1.22], [64706.1, 0.663], [64706.3, 0.325], [64706.4, 0.142], [64706.6, 0.105], [64707.5, 0.53], [64710.3, 0.214], [64725.5, 0.033], [64727.1, 0.5], [64727.5, 1.94], [64732.0, 0.153], [64732.2, 0.102], [64732.3, 12.671], [64732.5, 0.191], [64732.6, 0.199], [64732.8, 0.217], [64735.8, 0.073], [64746.6, 0.061], [64773.7, 0.178], [64836.8, 1.473], [65341.2, 2.294], [65470.6, 4.211], [65664.7, 7.162], [65694.3, 0.0]]}
{"kind": "depth", "E": 1787081854143, "U": 11315467377526, "u": 11315467396289, "recv_ms": 1787081854113, "bids": [[14394.2, 1.386], [14494.2, 2.814], [58224.7, 0.002], [61459.4, 0.0], [62106.4, 0.003], [63697.0, 0.006], [63700.4, 0.027], [64047.3, 0.073], [64370.7, 0.321], [64575.6, 0.0], [64630.1, 2.987], [64644.7, 0.276], [64645.0, 0.969], [64649.0, 0.642], [64679.0, 0.001], [64679.1, 0.24], [64679.7, 0.01], [64681.2, 0.924], [64682.5, 0.022], [64682.6, 0.028], [64683.5, 0.009], [64684.3, 0.096], [64684.8, 0.327], [64684.9, 0.347], [64685.3, 0.001], [64685.6, 0.144], [64685.8, 0.463], [64686.0, 0.741], [64686.1, 0.545], [64687.1, 0.313], [64687.4, 0.032], [64688.9, 0.02], [64689.8, 0.371], [64694.2, 44.772]], "asks": [[64694.3, 3.679], [64694.4, 0.038], [64695.0, 0.002], [64695.1, 0.0], [64696.8, 0.003], [64697.0, 0.003], [64697.5, 0.017], [64698.1, 0.004], [64698.3, 0.011], [64698.5, 0.0], [64698.6, 0.0], [64698.7, 0.702], [64698.9, 0.012], [64699.5, 0.001], [64699.8, 0.001], [64700.0, 0.004], [64700.1, 0.184], [64700.4, 0.294], [64702.1, 0.008], [64702.2, 0.003], [64702.6, 0.003], [64703.2, 0.089], [64703.3, 0.021], [64703.5, 0.405], [64704.2, 1.907], [64704.3, 3.04], [64704.4, 0.014], [64704.5, 2.323], [64704.9, 0.049], [64705.0, 0.901], [64705.2, 0.045], [64706.1, 0.353], [64706.2, 0.311], [64706.3, 0.475], [64706.6, 0.224], [64706.7, 0.101], [64707.5, 0.527], [64710.0, 1.027], [64710.1, 0.006], [64710.6, 0.09], [64710.8, 2.453], [64711.2, 0.996], [64712.1, 0.001], [64712.7, 0.165], [64713.2, 0.347], [64713.5, 2.319], [64713.7, 0.558], [64714.5, 0.977], [64714.6, 0.223], [64715.0, 0.01], [64715.1, 0.063], [64716.7, 0.581], [64717.4, 0.051], [64717.6, 0.116], [64718.4, 1.109], [64719.2, 0.156], [64720.0, 0.021], [64722.1, 0.06], [64723.6, 0.005], [64724.9, 0.002], [64725.0, 0.001], [64725.7, 0.158], [64726.1, 0.042], [64726.4, 0.051], [64732.5, 0.341], [64732.8, 0.336], [64732.9, 0.264], [64735.8, 0.0], [64747.3, 0.057], [64747.6, 0.428], [64773.7, 0.009], [64836.8, 1.191], [65341.2, 2.294], [65341.3, 1.404], [65683.4, 0.0], [65687.0, 0.325]]}
{"kind": "depth", "E": 1787081854347, "U": 11315467407735, "u": 11315467415192, "recv_ms": 1787081854317, "bids": [[1000.0, 35.81], [14394.2, 2.1], [14494.2, 2.1], [51755.0, 0.0], [51755.4, 0.0], [58224.7, 0.002], [62106.4, 0.0], [63890.4, 0.046], [63963.8, 5.393], [64000.0, 130.901], [64047.3, 0.073], [64624.5, 0.191], [64640.0, 2.055], [64659.3, 0.332], [64675.0, 0.433], [64675.2, 1.743]], "asks": [[64697.5, 0.038], [64823.7, 0.001], [65341.2, 2.294], [65415.6, 1.526], [65481.0, 1.993], [65988.1, 0.018]]}
{"kind": "depth", "E": 1787081854449, "U": 11315467415262, "u": 11315467420831, "recv_ms": 1787081854417, "bids": [[14394.2, 2.45], [14494.2, 1.75], [51755.0, 0.0], [58224.7, 0.002], [61459.4, 0.0], [62106.4, 0.003], [63694.2, 0.0], [64047.3, 0.073], [64370.7, 0.311], [64623.5, 1.269], [64623.8, 0.078], [64659.5, 0.07], [64659.7, 0.101], [64659.8, 0.105], [64660.0, 0.723], [64660.1, 0.083], [64660.3, 0.07], [64664.8, 0.172], [64665.2, 0.238], [64682.4, 0.081], [64683.1, 0.0], [64689.8, 0.371], [64694.2, 44.771]], "asks": [[64694.3, 3.682], [64697.0, 0.003], [64703.2, 0.398], [64823.7, 0.0], [65370.9, 0.001], [65694.3, 0.0]]}
{"kind": "depth", "E": 1787081854551, "U": 11315467421033, "u": 11315467428056, "recv_ms": 1787081854519, "bids": [[1000.0, 35.81], [14394.2, 2.814], [14494.2, 1.386], [58224.7, 0.002], [61459.4, 0.0], [62106.4, 0.0], [63937.3, 0.57], [64047.3, 0.073], [64494.8, 0.023], [64494.9, 1.748], [64495.8, 1.45], [64533.6, 1.448], [64533.8, 2.338], [64550.6, 0.0], [64550.7, 2.542], [64575.6, 0.0], [64627.8, 0.012], [64630.1, 2.987], [64635.9, 0.026], [64642.4, 1.631], [64659.4, 0.076], [64659.5, 0.14], [64659.8, 0.205], [64689.8, 0.375], [64694.2, 44.797]], "asks": [[64735.8, 0.0], [64759.0, 0.027], [64760.7, 0.0], [64773.7, 0.009], [64804.3, 1.392], [64834.1, 5.398], [64836.8, 1.191], [64851.1, 10.408], [65341.2, 2.294], [65480.3, 0.875], [65716.8, 0.904]]}
{"kind": "depth", "E": 1787081854653, "U": 11315467428160, "u": 11315467436247, "recv_ms": 1787081854621, "bids": [[1000.0, 35.81], [14394.2, 3.164], [14494.2, 1.036], [51755.0, 0.0], [58224.7, 0.002], [61459.4, 0.0], [63600.1, 2.846], [63694.2, 0.02], [64047.3, 0.073], [64370.7, 0.31], [64494.9, 0.007], [64495.0, 10.267], [64495.8, 2.591], [64533.8, 4.888], [64550.7, 0.065], [64550.8, 4.539], [64576.2, 1.198], [64578.6, 1.416], [64580.2, 13.417], [64581.3, 4.886], [64627.8, 2.7], [64659.6, 0.461], [64659.9, 0.077], [64689.8, 0.375], [64693.2, 0.001], [64694.1, 0.007], [64694.2, 44.815]], "asks": [[64694.3, 3.667], [64697.0, 0.003], [64701.0, 0.061], [64703.1, 0.025], [64760.7, 2.742], [64803.6, 0.0], [64806.4, 4.602], [64808.2, 10.604], [64889.9, 10.362], [65341.2, 2.294], [65503.0, 1.64], [65694.3, 0.02]]}
{"kind": "depth", "E": 1787081854857, "U": 11315467443033, "u": 11315467448910, "recv_ms": 1787081854826, "bids": [[1000.0, 35.81], [14294.2, 0.056], [14394.2, 3.752], [14494.2, 0.392], [58224.7, 0.002], [61459.4, 0.0], [61459.5, 0.048], [62106.4, 0.0], [63375.2, 0.0], [63400.4, 0.081], [63694.2, 0.0], [63775.5, 0.822], [63781.3, 0.788], [63924.4, 4.074], [64047.3, 0.073], [64370.7, 0.311], [64495.0, 7.007], [64533.8, 1.229], [64550.8, 1.97], [64689.8, 0.371], [64692.8, 0.059], [64694.2, 44.818]], "asks": [[64697.0, 0.003], [64705.9, 0.206], [64715.2, 1.262], [64834.1, 5.398], [65017.8, 0.328], [65341.2, 2.294], [65694.3, 0.0], [65697.1, 6.384]]}
{"kind": "depth", "E": 1787081854959, "U": 11315467449215, "u": 11315467454253, "recv_ms": 1787081854927, "bids": [[1000.0, 35.81], [14294.2, 0.28], [14394.2, 3.682], [14494.2, 0.238], [58224.7, 0.002], [62106.4, 0.003], [63781.3, 0.554], [63924.3, 5.627], [63987.5, 0.005], [64047.3, 0.073], [64627.8, 0.012], [64680.1, 0.464], [64681.2, 0.461], [64689.8, 0.375]], "asks": [[64694.3, 3.674], [64741.4, 0.064], [64746.1, 2.884], [64747.6, 0.414], [64750.9, 0.004], [64760.7, 0.0], [65341.2, 2.296]]}
{"kind": "depth", "E": 1787081855061, "U": 11315467454324, "u": 11315467460408, "recv_ms": 1787081855029, "bids": [[14294.2, 0.518], [14394.2, 3.556], [14494.2, 0.126], [58224.7, 0.002], [62106.4, 0.0], [63400.4, 0.084], [63694.2, 0.02], [63837.1, 2.973], [63924.3, 6.565], [64047.3, 0.073], [64370.7, 0.321], [64495.0, 10.394], [64533.8, 4.931], [64550.8, 4.576], [64580.2, 13.418], [64581.3, 2.591], [64627.8, 2.701], [64628.8, 3.563], [64677.8, 0.438], [64680.1, 0.001], [64681.2, 0.924], [64682.6, 0.028], [64690.8, 0.002]], "asks": [[64710.3, 0.212], [64712.6, 0.682], [64715.5, 0.628], [64742.4, 0.011], [64750.9, 0.0], [64760.7, 2.742], [64806.4, 0.007], [64808.2, 10.586], [64889.9, 10.16], [65341.2, 2.294], [65478.3, 3.79], [65503.0, 1.898], [65584.4, 1.825], [65694.3, 0.02]]}
{"kind": "depth", "E": 1787081855163, "U": 11315467460513, "u": 11315467466831, "recv_ms": 1787081855131, "bids": [[1000.0, 35.81], [14294.2, 0.756], [14394.2, 3.444], [14494.2, 0.0], [34000.0, 1.146], [51755.0, 0.0], [58224.7, 0.002], [61459.4, 0.0], [63341.4, 0.681], [63814.0, 6.385], [64047.3, 0.073], [64117.4, 0.081], [64575.6, 0.0], [64630.1, 2.987], [64649.0, 0.638], [64677.3, 0.002], [64677.8, 0.44], [64680.1, 0.001], [64681.2, 0.461], [64681.3, 0.468], [64684.3, 0.136], [64686.9, 0.005], [64689.8, 0.375], [64694.2, 44.819]], "asks": [[64694.3, 3.664], [64697.0, 0.003], [64704.1, 0.011], [64710.3, 0.214], [64720.7, 0.004], [64735.8, 0.0], [64766.8, 0.036], [64773.7, 0.009], [64836.8, 1.191], [65341.2, 2.294], [65341.3, 1.403], [65528.3, 0.0]]}
{"kind": "depth", "E": 1787081855265, "U": 11315467467032, "u": 11315467472798, "recv_ms": 1787081855284, "bids": [[1000.0, 35.81], [14294.2, 1.106], [14394.2, 3.094], [51755.0, 0.0], [58224.7, 0.002], [61459.4, 0.0], [62106.4, 0.003], [63289.3, 0.001], [63292.6, 0.006], [63400.4, 0.081], [63694.2, 0.0], [63820.8, 4.881], [63943.4, 4.683], [64047.3, 0.073], [64616.0, 3.37], [64661.5, 0.069], [64661.7, 0.001], [64662.5, 0.0], [64663.5, 1.298], [64672.3, 0.557], [64673.2, 0.001], [64673.6, 1.111], [64674.2, 0.132], [64674.6, 0.358], [64675.6, 0.0], [64675.8, 0.081], [64677.6, 0.928], [64678.5, 0.04], [64680.1, 0.472], [64681.2, 0.453], [64681.3, 0.005], [64682.4, 0.001], [64683.1, 0.007], [64683.5, 0.002], [64684.8, 0.868], [64686.1, 0.074], [64689.8, 0.375], [64694.2, 44.806]], "asks": [[64694.3, 3.656], [64699.8, 0.633], [64703.0, 0.044], [64703.1, 0.003], [64710.8, 3.378], [64711.2, 0.071], [64712.1, 0.001], [64712.5, 0.558], [64713.4, 0.431], [64713.7, 0.002], [64714.5, 0.92], [64715.1, 0.604], [64715.3, 0.005], [64716.4, 0.117], [64716.7, 0.04], [64716.8, 1.251], [64717.6, 0.001], [64718.1, 0.007], [64718.4, 1.109], [65325.1, 0.267], [65341.2, 2.296], [65451.2, 0.534], [65567.7, 2.812], [65694.3, 0.0], [65988.1, 0.015], [66324.5, 0.0]]}
{"kind": "depth", "E": 1787081855367, "U": 11315467472824, "u": 11315467484811, "recv_ms": 1787081855336, "bids": [[14294.2, 1.47], [14394.2, 2.73], [51755.4, 0.0], [58224.7, 0.002], [61459.4, 0.001], [62106.4, 0.0], [63891.2, 1.648], [63972.7, 0.784], [64047.3, 0.073], [64370.7, 0.311], [64519.4, 0.002], [64575.6, 0.28], [64630.1, 3.155], [64675.8, 0.001], [64683.1, 0.087], [64684.3, 0.136], [64684.8, 0.327], [64684.9, 0.347], [64686.1, 0.615], [64689.8, 0.371], [64694.2, 44.818]], "asks": [[64694.3, 3.658], [64694.4, 0.037], [64695.0, 0.001], [64697.0, 0.003], [64698.3, 0.004], [64698.9, 0.01], [64699.8, 0.085], [64700.0, 0.003], [64700.4, 0.294], [64704.1, 0.01], [64704.2, 1.443], [64704.3, 0.035], [64704.5, 2.321], [64705.0, 0.9], [64706.2, 0.1], [64710.0, 1.026], [64710.1, 0.004], [64710.8, 2.453], [64712.5, 0.002], [64712.7, 0.004], [64713.4, 0.374], [64714.3, 0.002], [64714.5, 0.913], [64715.0, 0.009], [64715.1, 0.063], [64716.4, 0.002], [64716.7, 0.04], [64719.2, 0.002], [64720.0, 0.02], [64723.6, 0.003], [64725.0, 0.0], [64725.7, 0.004], [64735.8, 0.073], [64773.7, 0.178], [64823.7, 0.0], [64836.8, 1.473], [65341.2, 2.294], [65657.1, 0.015], [65988.1, 0.012]]}
{"kind": "depth", "E": 1787081855469, "U": 11315467485587, "u": 11315467494833, "recv_ms": 1787081855440, "bids": [[1000.0, 35.81], [14294.2, 1.82], [14394.2, 2.38], [58224.7, 0.002], [61459.4, 0.0], [62106.4, 0.003], [63694.2, 0.02], [63756.1, 16.141], [63908.2, 0.786], [63924.3, 7.502], [63950.2, 4.684], [63969.2, 7.134], [64047.3, 0.073], [64111.8, 1.139], [64575.6, 0.0], [64629.0, 4.259], [64630.1, 2.987], [64649.0, 0.642], [64673.3, 0.021], [64675.2, 1.728], [64680.1, 0.464], [64681.2, 0.461], [64689.7, 0.004], [64692.8, 0.0], [64694.2, 44.812]], "asks": [[64694.4, 0.038], [64695.0, 0.002], [64698.1, 0.011], [64698.8, 1.907], [64699.4, 0.09], [64699.8, 0.633], [64700.0, 0.004], [64700.7, 0.003], [64701.9, 0.503], [64704.1, 0.55], [64705.0, 0.901], [64706.0, 1.529], [64708.9, 1.452], [64710.0, 1.027], [64711.0, 1.825], [64712.4, 0.037], [64712.5, 0.156], [64713.4, 0.93], [64714.2, 0.058], [64714.4, 0.012], [64715.0, 0.01], [64715.4, 0.667], [64716.7, 0.04], [64717.3, 0.117], [64718.9, 0.378], [64720.0, 0.021], [64722.4, 0.002], [64725.0, 0.001], [64725.4, 0.172], [64735.8, 0.0], [64773.7, 0.009], [64800.0, 11.374], [64836.8, 1.191], [65341.2, 2.294], [65594.8, 6.087], [65694.3, 0.02], [65794.1, 0.291], [66316.3, 2.184]]}
{"kind": "depth", "E": 1787081855571, "U": 11315467495097, "u": 11315467503336, "recv_ms": 1787081855539, "bids": [[1000.0, 35.81], [14294.2, 2.184], [14394.2, 2.016], [58224.7, 0.002], [61459.4, 0.0], [62106.4, 0.0], [63400.4, 0.084], [63858.7, 2.362], [63858.9, 11.258], [64047.3, 0.073], [64176.6, 1.869], [64649.0, 0.638], [64661.3, 0.002], [64661.4, 1.661], [64661.5, 0.067], [64664.8, 0.17], [64664.9, 0.0], [64665.0, 0.054], [64689.7, 0.0], [64694.2, 44.822]], "asks": [[64694.3, 3.658], [64697.0, 0.003], [64703.3, 0.001], [64703.5, 0.383], [64715.4, 0.126], [64716.7, 0.581], [64728.4, 10.002], [64732.3, 2.671], [65141.5, 0.001], [65341.2, 2.294], [65632.4, 10.991], [65852.0, 0.758], [67282.1, 0.636]]}
{"kind": "depth", "E": 1787081855673, "U": 11315467503406, "u": 11315467509211, "recv_ms": 1787081855641, "bids": [[14294.2, 2.534], [14394.2, 1.666], [51755.0, 0.0], [58224.7, 0.002], [61459.4, 0.0], [63694.2, 0.0], [64047.3, 0.073], [64150.8, 0.148], [64370.7, 0.311], [64581.3, 4.886], [64603.8, 0.232], [64603.9, 0.026], [64682.4, 0.081], [64683.1, 0.007], [64689.7, 0.0], [64689.8, 0.371], [64694.2, 44.822]], "asks": [[64694.3, 3.731], [64702.6, 0.021], [64702.7, 0.024], [64726.6, 3.641], [64729.6, 2.537], [64730.6, 0.001], [64807.1, 7.165], [64834.1, 3.561], [64851.1, 6.064], [65082.5, 0.046], [65341.2, 2.296], [65535.3, 6.028], [65694.3, 0.0], [65716.8, 0.0]]}
{"kind": "depth", "E": 1787081855775, "U": 11315467509250, "u": 11315467514141, "recv_ms": 1787081855743, "bids": [[1000.0, 35.81], [14294.2, 2.898], [14394.2, 1.302], [51755.0, 0.0], [58224.7, 0.002], [61459.4, 0.0], [62106.4, 0.003], [63853.2, 1.095], [64047.3, 0.073], [64117.7, 10.278], [64616.5, 0.289], [64635.9, 0.023], [64689.7, 0.004], [64694.2, 44.81]], "asks": [[64804.3, 1.392], [64834.1, 4.823], [64851.1, 8.395], [64889.9, 12.791], [65017.8, 0.327], [65341.2, 2.294], [65988.1, 0.015]]}
{"kind": "depth", "E": 1787081855877, "U": 11315467514263, "u": 11315467520812, "recv_ms": 1787081855844, "bids": [[14294.2, 3.248], [14394.2, 0.952], [58224.7, 0.002], [62106.4, 0.0], [63694.2, 0.02], [63775.1, 14.762], [63852.9, 1.094], [64047.3, 0.073], [64370.7, 0.311], [64550.8, 0.003], [64675.8, 0.001], [64682.4, 0.001], [64683.1, 0.087], [64689.7, 0.0], [64694.2, 44.856]], "asks": [[64697.0, 0.003], [64697.6, 1.185], [64834.1, 0.0], [65341.2, 2.294], [65464.3, 1.83], [65465.3, 0.002], [65694.3, 0.02], [65697.1, 7.296], [65724.3, 12.463]]}
{"kind": "depth", "E": 1787081855979, "U": 11315467520940, "u": 11315467527013, "recv_ms": 1787081855952, "bids": [[14294.2, 3.612], [14394.2, 0.588], [58224.7, 0.002], [61459.4, 0.0], [62106.4, 0.003], [63678.1, 0.0], [64047.3, 0.073], [64112.0, 1.537], [64150.8, 0.143], [64370.7, 0.321], [64495.0, 0.381], [64495.8, 1.45], [64533.8, 0.067], [64627.4, 0.039], [64650.0, 4.045], [64666.2, 0.24], [64689.7, 0.004], [64694.2, 44.869]], "asks": [[64723.9, 0.31], [64740.5, 0.0], [64762.8, 1.501], [64763.1, 0.002], [64851.1, 0.0], [64889.9, 0.0], [65017.8, 0.328], [65341.2, 2.294], [65464.2, 4.037], [65530.1, 7.629], [65670.6, 27.196]]}
{"kind": "depth", "E": 1787081856081, "U": 11315467527174, "u": 11315467534863, "recv_ms": 1787081856049, "bids": [[1000.0, 35.81], [14194.2, 0.112], [14294.2, 3.752], [14394.2, 0.336], [58224.7, 0.002], [61459.4, 0.001], [61459.5, 0.046], [61459.6, 2.441], [62152.0, 0.069], [63659.1, 5.933], [63694.2, 0.0], [63756.1, 18.02], [63842.9, 2.733], [63885.5, 2.789], [63912.0, 8.886], [64047.3, 0.073], [64495.2, 10.022], [64495.8, 2.606], [64534.0, 5.236], [64551.0, 4.557], [64575.5, 0.012], [64595.1, 0.664], [64595.2, 0.579], [64630.0, 2.333], [64672.3, 0.0], [64673.2, 0.558], [64673.6, 0.995], [64674.6, 0.474], [64677.8, 0.438], [64682.6, 0.028], [64689.7, 0.0], [64694.2, 44.856]], "asks": [[64697.0, 0.003], [64710.3, 0.212], [64735.7, 0.197], [64773.6, 0.003], [64834.1, 5.398], [64836.7, 0.101], [64851.1, 10.408], [64889.9, 10.269], [65023.9, 0.116], [65341.2, 2.296], [65370.8, 0.001], [65493.7, 7.571], [65657.8, 0.002], [65694.3, 0.0], [71163.8, 0.0]]}
{"kind": "depth", "E": 1787081856183, "U": 11315467534880, "u": 11315467541814, "recv_ms": 1787081856151, "bids": [[14194.2, 0.336], [14294.2, 3.654], [14394.2, 0.21], [51755.0, 0.0], [58224.7, 0.002], [61459.4, 0.0], [62106.4, 0.0], [64047.3, 0.073], [64627.5, 6.011], [64650.1, 3.5], [64666.3, 1.1], [64675.8, 0.081], [64677.8, 0.44], [64683.1, 0.007], [64689.7, 0.004], [64694.2, 44.869]], "asks": [[64694.3, 3.741], [64702.4, 0.275], [64703.0, 0.003], [64704.1, 0.551], [64710.3, 0.214], [64713.4, 0.374], [64713.7, 0.558], [64717.3, 0.002], [64717.6, 0.116], [64724.3, 1.004], [64740.5, 3.5], [64762.8, 2.334], [64763.1, 6.002], [64793.7, 0.0], [64793.8, 1.726], [64795.1, 0.008], [64795.5, 0.001], [65341.2, 2.294], [65405.9, 3.19], [65664.7, 10.582]]}
{"kind": "depth", "E": 1787081856285, "U": 11315467541955, "u": 11315467547958, "recv_ms": 1787081856253, "bids": [[14194.2, 0.574], [14294.2, 3.528], [14394.2, 0.098], [51755.0, 0.0], [58224.7, 0.002], [61459.5, 0.044], [61459.6, 2.443], [62106.4, 0.003], [63470.8, 0.001], [63694.2, 0.02], [63885.5, 2.906], [64047.3, 0.073], [64370.7, 0.311], [64575.6, 0.0], [64630.0, 2.333], [64675.8, 0.081], [64683.1, 0.007]], "asks": [[64697.0, 0.003], [64702.4, 0.252], [64735.7, 0.197], [64773.6, 0.003], [64836.8, 1.191], [65341.2, 2.294], [65503.0, 2.012], [65694.3, 0.02]]}
{"kind": "depth", "E": 1787081856387, "U": 11315467548139, "u": 11315467553881, "recv_ms": 1787081856357, "bids": [[1000.0, 35.81], [14194.2, 0.84], [14294.2, 3.36], [14394.2, 0.0], [51755.4, 0.0], [58224.7, 0.002], [61459.5, 0.042], [61459.6, 2.445], [62106.4, 0.0], [63341.4, 0.005], [63891.2, 1.383], [63943.4, 3.746], [64047.3, 0.073], [64500.1, 0.022], [64595.7, 10.007], [64675.8, 0.001], [64682.4, 0.081], [64683.1, 0.007]], "asks": [[64795.5, 10.001], [64823.7, 0.0], [64889.9, 10.36], [65312.9, 1.301], [65341.2, 2.294], [65470.6, 5.737]]}
{"kind": "depth", "E": 1787081856489, "U": 11315467554004, "u": 11315467559271, "recv_ms": 1787081856460, "bids": [[14194.2, 1.19], [14294.2, 3.01], [58224.7, 0.002], [62106.4, 0.003], [63694.2, 0.0], [63781.3, 0.085], [64117.7, 9.188], [64551.0, 0.023], [64575.5, 0.012], [64630.0, 2.333], [64679.3, 0.16], [64685.4, 0.006], [64686.9, 0.003]], "asks": [[64697.0, 0.003], [64697.6, 1.186], [64720.0, 0.02], [64735.7, 0.197], [64773.6, 0.003], [64834.1, 0.0], [64836.8, 1.191], [65341.2, 2.296], [65670.6, 26.907], [65694.3, 0.0]]}
{"kind": "depth", "E": 1787081856591, "U": 11315467559326, "u": 11315467565623, "recv_ms": 1787081856559, "bids": [[14194.2, 1.554], [14294.2, 2.646], [51755.0, 0.0], [58224.7, 0.002], [63400.4, 0.087], [63775.5, 1.056], [63924.3, 8.44], [63940.6, 0.853], [64047.3, 0.073], [64370.7, 0.321], [64551.0, 4.556], [64673.2, 0.558], [64674.1, 0.023], [64677.6, 0.002], [64678.6, 1.139], [64679.5, 0.025]], "asks": [[64702.0, 0.104], [64702.2, 0.025], [64711.0, 0.9], [64712.0, 2.902], [64713.7, 0.002], [64714.2, 0.001], [64714.4, 0.568], [64715.2, 1.319], [64717.6, 0.001], [64718.3, 0.118], [64834.1, 5.398], [64889.9, 10.361], [65341.2, 2.294], [65616.9, 7.754], [65920.9, 0.002]]}
{"kind": "depth", "E": 1787081856693, "U": 11315467565866, "u": 11315467576452, "recv_ms": 1787081856661, "bids": [[1000.0, 35.81], [14194.2, 1.918], [14294.2, 2.282], [58224.7, 0.002], [61455.8, 0.0], [61459.4, 0.0], [62106.4, 0.0], [63335.6, 2.365], [63694.2, 0.02], [63775.5, 1.29], [64047.3, 0.073], [64112.0, 2.628], [64135.1, 0.008], [64542.7, 0.001], [64575.6, 0.28], [64598.1, 2.361], [64630.0, 2.501], [64635.9, 0.026], [64661.3, 0.004], [64661.4, 1.663], [64661.5, 0.069], [64664.8, 0.172], [64664.9, 0.002], [64665.0, 0.056], [64676.2, 0.619], [64677.9, 0.002], [64689.7, 0.004], [64694.1, 0.007], [64694.2, 44.869]], "asks": [[64694.3, 3.825], [64697.0, 0.003], [64724.1, 0.004], [64735.7, 0.27], [64773.6, 0.172], [64793.8, 3.224], [64836.8, 1.473], [64856.1, 0.007], [65019.9, 0.0], [65341.2, 2.294], [65593.3, 3.044], [65623.2, 1.825], [65694.3, 0.02], [71163.7, 0.002]]}
{"kind": "depth", "E": 1787081856795, "U": 11315467576496, "u": 11315467583498, "recv_ms": 1787081856763, "bids": [[14194.2, 2.268], [14294.2, 1.932], [58224.7, 0.002], [62106.4, 0.003], [64047.3, 0.073], [64073.0, 0.006], [64075.6, 2.804], [64370.7, 0.32], [64575.6, 0.0], [64630.0, 2.333], [64658.9, 0.003], [64675.8, 0.081], [64682.4, 0.001]], "asks": [[64710.6, 1.015], [64712.0, 1.977], [64728.7, 0.001], [64735.7, 0.197], [64773.6, 0.003], [64793.7, 0.008], [64795.1, 0.0], [64836.8, 1.191], [65341.2, 2.294], [65519.8, 5.11], [65530.1, 7.515], [65593.1, 0.005], [71163.7, 0.0]]}
{"kind": "depth", "E": 1787081856897, "U": 11315467583559, "u": 11315467588765, "recv_ms": 1787081856865, "bids": [[1000.0, 35.96], [14194.2, 2.618], [14294.2, 1.582], [58224.7, 0.002], [61459.4, 0.0], [62106.4, 0.0], [63294.9, 0.703], [63694.2, 0.0], [64047.3, 0.073], [64150.8, 0.139], [64370.7, 0.31], [64584.2, 0.381], [64675.8, 0.001], [64682.4, 0.081], [64689.7, 0.004], [64694.2, 44.857]], "asks": [[64737.0, 0.118], [65341.2, 2.294], [65463.6, 0.012], [65480.3, 1.638], [65623.1, 9.072], [65694.3, 0.0]]}
{"kind": "depth", "E": 1787081857101, "U": 11315467594334, "u": 11315467605015, "recv_ms": 1787081857070, "bids": [[14194.2, 3.332], [14294.2, 0.868], [58224.7, 0.002], [61459.4, 0.0], [62106.4, 0.003], [63694.2, 0.02], [63755.4, 0.001], [63814.0, 5.446], [63885.5, 3.14], [64047.3, 0.073], [64150.8, 0.108], [64370.4, 0.0], [64635.9, 0.026], [64675.8, 0.081], [64677.8, 0.438], [64682.4, 0.001], [64682.6, 0.028], [64689.7, 0.0], [64693.5, 0.087], [64694.2, 44.872]], "asks": [[64694.3, 3.826], [64697.0, 0.003], [64702.2, 0.003], [64710.3, 0.212], [64713.4, 0.93], [64714.4, 0.012], [64717.3, 0.117], [64718.3, 0.003], [64726.7, 6.695], [65321.8, 0.84], [65341.2, 2.294], [65600.0, 96.569], [65694.3, 0.02], [65803.8, 0.77], [66142.3, 0.002]]}
{"kind": "depth", "E": 1787081857203, "U": 11315467605073, "u": 11315467613838, "recv_ms": 1787081857173, "bids": [[1000.0, 35.81], [14194.2, 3.696], [14294.2, 0.504], [58224.7, 0.002], [62106.4, 0.0], [63778.7, 1.098], [64047.3, 0.073], [64370.7, 0.321], [64675.8, 0.001], [64677.8, 0.44], [64679.7, 0.473], [64679.9, 0.022], [64680.1, 0.009], [64681.2, 0.453], [64682.4, 0.081], [64683.1, 0.007]], "asks": [[64702.0, 0.085], [64702.5, 0.107], [64710.3, 0.214], [64725.9, 0.002], [64726.0, 0.005], [64889.9, 9.987], [65341.2, 2.294]]}
{"kind": "depth", "E": 1787081857305, "U": 11315467613983, "u": 11315467619969, "recv_ms": 1787081857273, "bids": [[1000.0, 35.81], [14194.2, 3.738], [14294.2, 0.308], [14594.2, 0.154], [51755.0, 0.0], [58224.7, 0.002], [61459.4, 0.0], [62106.4, 0.003], [63694.2, 0.0], [64047.3, 0.073], [64689.7, 0.0]], "asks": [[64694.3, 3.827], [64697.0, 0.003], [64725.9, 0.002], [64726.0, 0.159], [65341.2, 2.294], [65694.3, 0.0]]}
{"kind": "depth", "E": 1787081857407, "U": 11315467620187, "u": 11315467625023, "recv_ms": 1787081857375, "bids": [[14194.2, 3.626], [14294.2, 0.182], [14594.2, 0.392], [51755.0, 0.0], [51755.4, 0.0], [58224.7, 0.002], [61459.4, 0.001], [62106.4, 0.0], [63756.1, 18.96], [64047.3, 0.073], [64152.0, 1.585], [64534.0, 0.417], [64534.2, 3.791], [64551.0, 0.023], [64551.2, 4.407], [64579.4, 3.91], [64579.6, 0.431], [64623.7, 0.046], [64623.8, 0.032], [64689.7, 0.0], [64694.2, 44.873]], "asks": [[64694.3, 3.83], [64726.0, 0.005], [64726.1, 0.196], [64766.1, 0.118], [64766.3, 0.024], [64823.7, 0.0], [64830.8, 4.926], [64831.1, 0.001], [64834.1, 5.398], [64851.1, 10.408], [65341.2, 2.294], [65464.3, 0.915], [65722.6, 1.185]]}
{"kind": "depth", "E": 1787081857509, "U": 11315467625165, "u": 11315467630446, "recv_ms": 1787081857477, "bids": [[1000.0, 35.81], [14194.2, 3.5], [14294.2, 0.07], [14594.2, 0.63], [58224.7, 0.002], [61459.4, 0.0], [63694.2, 0.02], [64047.3, 0.073], [64370.7, 0.321], [64575.5, 0.012], [64630.0, 2.333], [64678.0, 0.902], [64694.2, 44.898]], "asks": [[64697.0, 0.003], [64735.7, 0.197], [64742.4, 0.007], [64750.9, 0.004], [64773.6, 0.003], [64836.7, 0.101], [65341.2, 2.294], [65594.8, 3.804], [65694.3, 0.02]]}
{"kind": "depth", "E": 1787081857611, "U": 11315467630497, "u": 11315467634516, "recv_ms": 1787081857581, "bids": [[1000.0, 35.81], [14194.2, 3.276], [14294.2, 0.0], [14594.2, 0.924], [58224.7, 0.002], [61459.4, 0.0], [62106.4, 0.003], [63400.4, 0.084], [63858.7, 1.268], [63963.0, 0.016], [64047.3, 0.073], [64106.2, 9.125], [64481.4, 0.188], [64483.3, 0.005], [64491.9, 0.0], [64493.7, 0.007], [64502.4, 5.351], [64512.9, 0.004], [64523.4, 0.013], [64533.9, 0.025], [64544.4, 0.0], [64551.2, 5.03], [64554.9, 0.244], [64565.4, 0.0], [64575.9, 0.0], [64586.4, 0.289], [64596.9, 0.122], [64607.4, 0.017], [64617.9, 0.0], [64628.4, 0.0], [64638.9, 0.002], [64649.4, 0.295], [64659.9, 0.072], [64670.4, 1.202], [64689.7, 0.004]], "asks": [[64704.1, 0.55], [64709.8, 0.007], [64709.9, 1.238], [64720.2, 0.613], [64720.4, 0.002], [64730.9, 0.004], [64741.4, 0.059], [64744.1, 0.004], [64750.9, 0.0], [64751.9, 0.003], [64762.4, 0.0], [64772.9, 0.001], [64783.4, 1.386], [64793.9, 0.633], [64804.4, 0.202], [64814.9, 24.184], [64825.4, 0.001], [64835.9, 0.0], [64846.4, 3.456], [64856.9, 2.319], [64867.4, 0.153], [64877.9, 0.028], [64888.4, 0.199], [64898.9, 0.0], [65341.2, 2.294], [65464.2, 4.952]]}
{"kind": "depth", "E": 1787081857713, "U": 11315467634631, "u": 11315467639508, "recv_ms": 1787081857683, "bids": [[14194.2, 2.926], [14594.2, 1.274], [58224.7, 0.002], [61459.4, 0.0], [62106.4, 0.0], [63694.2, 0.0], [63918.0, 10.045], [64047.3, 0.073], [64370.8, 0.0], [64495.2, 0.037], [64495.4, 0.0], [64495.5, 10.075], [64504.1, 0.033], [64534.2, 0.095], [64534.3, 5.122], [64551.2, 0.377], [64551.3, 4.653], [64575.5, 0.294], [64594.7, 1.177], [64630.0, 2.502], [64689.7, 0.0], [64694.2, 44.896]], "asks": [[64694.3, 3.815], [64697.0, 0.003], [64700.7, 0.006], [64702.3, 0.022], [64730.6, 0.006], [64735.7, 0.271], [64744.1, 0.0], [64750.9, 0.004], [64773.6, 0.174], [64836.7, 0.385], [64889.9, 9.933], [65017.9, 1.173], [65341.2, 2.294], [65535.3, 8.313], [65694.3, 0.0], [65988.1, 0.015]]}
{"kind": "depth", "E": 1787081857815, "U": 11315467639629, "u": 11315467646476, "recv_ms": 1787081857783, "bids": [[1000.0, 35.81], [14194.2, 2.562], [14594.2, 1.638], [51755.0, 0.0], [58224.7, 0.002], [61459.4, 0.0], [61459.5, 0.04], [61459.6, 2.447], [62106.4, 0.003], [63853.1, 2.193], [63937.3, 1.117], [64047.3, 0.073], [64370.7, 0.311], [64514.5, 0.005], [64524.9, 0.012], [64535.3, 0.007], [64575.5, 0.012], [64630.0, 2.333], [64640.0, 2.059], [64647.0, 0.001], [64649.0, 0.642], [64673.1, 1.153], [64673.2, 0.001], [64674.0, 0.122], [64674.3, 0.117], [64674.6, 0.358], [64675.3, 0.633], [64689.7, 0.004], [64693.8, 0.003], [64694.2, 44.797]], "asks": [[64698.7, 2.981], [64703.2, 0.314], [64710.6, 0.09], [64711.8, 0.927], [64713.4, 0.374], [64714.3, 0.558], [64717.3, 0.002], [64718.1, 0.122], [64735.7, 0.197], [64741.0, 0.005], [64744.1, 0.004], [64749.5, 2.213], [64750.9, 0.0], [64751.4, 0.013], [64756.7, 0.023], [64761.8, 0.011], [64773.6, 0.003], [64836.7, 0.101], [65341.2, 2.294], [65480.2, 0.002], [66012.7, 0.0]]}
{"kind": "depth", "E": 1787081858019, "U": 11315467651133, "u": 11315467655930, "recv_ms": 1787081857989, "bids": [[14194.2, 1.848], [14594.2, 2.352], [58224.7, 0.002], [61459.5, 0.038], [61459.6, 2.449], [63400.4, 0.087], [63424.3, 1.351], [63901.9, 6.684], [64047.3, 0.073], [64370.7, 0.941], [64566.5, 0.017]], "asks": [[64793.0, 0.139], [65017.8, 0.941], [65341.2, 2.294], [65594.9, 0.0], [65724.3, 9.424]]}
{"kind": "depth", "E": 1787081858121, "U": 11315467656040, "u": 11315467661980, "recv_ms": 1787081858092, "bids": [[1000.0, 35.81], [14194.2, 1.484], [14594.2, 2.716], [51755.0, 0.002], [58224.7, 0.002], [62106.4, 0.692], [63694.2, 0.0], [63775.5, 1.759], [63785.1, 0.035], [64047.3, 0.073], [64370.7, 0.942], [64576.9, 0.018], [64587.3, 0.005], [64682.6, 0.028]], "asks": [[64706.5, 0.219], [64713.4, 0.93], [64714.3, 0.002], [64717.3, 0.117], [64718.1, 0.007], [64728.4, 10.004], [64728.5, 0.628], [64803.4, 0.005], [64813.8, 0.005], [65017.8, 0.942], [65341.2, 2.294], [65694.3, 0.0]]}
{"kind": "depth", "E": 1787081858223, "U": 11315467662004, "u": 11315467668532, "recv_ms": 1787081858192, "bids": [[1000.0, 35.81], [14194.2, 1.134], [14594.2, 3.066], [51755.0, 0.0], [58224.7, 0.002], [62106.4, 0.689], [63294.9, 1.379], [63885.5, 3.405], [64047.3, 0.073], [64551.3, 0.0], [64575.5, 0.012], [64597.7, 0.415], [64630.0, 2.333], [64677.8, 0.44], [64690.2, 3.748]], "asks": [[64697.0, 0.003], [64710.3, 0.214], [64725.8, 0.195], [64726.1, 0.042], [64735.7, 0.197], [64773.5, 1.093], [64824.2, 0.007], [64834.1, 0.0], [64836.7, 0.101], [65341.2, 2.294], [65600.0, 98.853], [65664.7, 10.871], [66632.4, 0.003]]}
{"kind": "depth", "E": 1787081858325, "U": 11315467668625, "u": 11315467674024, "recv_ms": 1787081858296, "bids": [[14194.2, 0.784], [14594.2, 3.416], [51755.0, 0.0], [58224.7, 0.002], [62106.4, 0.692], [63400.4, 0.084], [63619.9, 0.0], [63694.2, 0.02], [64047.3, 0.073], [64117.7, 8.099], [64370.7, 0.932], [64495.5, 7.091], [64534.3, 0.166], [64534.4, 2.421], [64551.3, 2.566], [64608.1, 0.007], [64618.5, 0.011], [64635.9, 0.026], [64676.8, 0.661], [64678.4, 1.855], [64680.0, 0.553], [64680.2, 0.671], [64681.6, 1.471], [64681.8, 0.206], [64683.4, 0.453], [64685.0, 0.211], [64689.7, 0.0], [64694.2, 44.892]], "asks": [[64694.3, 3.816], [64699.2, 0.002], [64700.8, 0.104], [64719.8, 0.002], [64721.2, 0.856], [64725.8, 0.195], [64725.9, 0.002], [64726.0, 0.005], [64739.6, 0.003], [64834.1, 5.398], [64834.6, 0.028], [64845.0, 0.008], [64851.1, 10.408], [65341.2, 2.294], [65567.7, 3.42], [65600.0, 99.036], [65659.6, 12.323], [65694.3, 0.02]]}
{"kind": "depth", "E": 1787081858427, "U": 11315467674048, "u": 11315467677862, "recv_ms": 1787081858396, "bids": [[1000.0, 35.81], [14194.2, 0.448], [14494.2, 0.028], [14594.2, 3.724], [51755.4, 0.0], [58224.7, 0.002], [61459.4, 0.0], [64047.3, 0.073], [64495.5, 9.979], [64534.4, 4.948], [64536.5, 0.954], [64551.3, 4.552], [64628.9, 0.152], [64675.0, 0.433]], "asks": [[64823.7, 0.001], [64855.4, 2.998], [64889.9, 10.223], [65341.2, 2.294], [65487.4, 1.799], [65545.0, 1.435], [65606.5, 1.674], [65904.1, 1.568]]}
{"kind": "depth", "E": 1787081858529, "U": 11315467677977, "u": 11315467682026, "recv_ms": 1787081858498, "bids": [[1000.0, 35.81], [14194.2, 0.28], [14494.2, 0.21], [14594.2, 3.71], [58224.7, 0.002], [62106.4, 0.689], [63694.2, 0.0], [64047.3, 0.073], [64111.9, 1.09], [64503.0, 0.0], [64534.4, 0.0], [64551.3, 0.0], [64627.7, 4.496], [64627.8, 0.012], [64639.3, 0.011], [64649.7, 2.135]], "asks": [[64725.7, 0.004], [64725.8, 0.195], [64760.5, 2.751], [64760.7, 0.0], [64834.1, 0.0], [64851.1, 0.0], [64865.8, 0.018], [64876.2, 0.007], [65341.2, 2.294], [65416.2, 2.221], [65503.0, 2.468], [65545.7, 0.762], [65694.3, 0.0]]}
{"kind": "depth", "E": 1787081858631, "U": 11315467682130, "u": 11315467687589, "recv_ms": 1787081858599, "bids": [[14194.2, 0.154], [14494.2, 0.448], [14594.2, 3.598], [51755.0, 0.0], [58224.7, 0.002], [61459.5, 0.032], [62106.4, 0.692], [63729.5, 6.828], [64047.3, 0.073], [64370.7, 0.932], [64536.5, 0.245], [64660.1, 0.088], [64689.7, 0.004], [64693.8, 0.087], [64694.2, 44.906]], "asks": [[64697.0, 0.003], [64702.6, 0.001], [64725.8, 0.195], [64823.7, 0.0], [64886.6, 0.023], [65341.2, 2.294], [65620.7, 10.978], [65632.4, 11.295], [65821.4, 2.729], [65988.1, 0.012]]}
{"kind": "depth", "E": 1787081858733, "U": 11315467687737, "u": 11315467696483, "recv_ms": 1787081858701, "bids": [[1000.0, 35.81], [14194.2, 0.042], [14494.2, 0.7], [14594.2, 3.458], [58224.7, 0.002], [61459.4, 0.0], [62106.4, 0.689], [63694.2, 0.02], [63820.8, 5.115], [64047.3, 0.073], [64302.1, 2.109], [64495.5, 9.961], [64500.1, 0.025], [64534.4, 4.916], [64551.3, 4.528], [64575.5, 0.012], [64616.5, 0.289], [64630.0, 2.333], [64670.5, 5.856], [64689.7, 0.0], [64694.2, 44.906]], "asks": [[64694.3, 3.801], [64698.7, 2.897], [64701.8, 2.34], [64725.8, 0.041], [64725.9, 0.002], [64726.2, 2.475], [64735.7, 0.197], [64773.5, 1.093], [64804.3, 1.392], [64834.1, 5.398], [64836.7, 0.101], [64851.1, 10.408], [64888.4, 0.202], [64889.9, 10.294], [64894.9, 4.795], [64895.0, 0.102], [64897.0, 0.022], [65341.2, 2.294], [65528.5, 2.288], [65541.3, 2.139], [65694.3, 0.02]]}
{"kind": "depth", "E": 1787081858835, "U": 11315467696525, "u": 11315467702903, "recv_ms": 1787081858803, "bids": [[1000.0, 35.81], [14194.2, 0.0], [14494.2, 1.008], [14594.2, 3.192], [58224.7, 0.002], [62106.4, 0.692], [63400.4, 0.087], [63749.7, 0.783], [64672.5, 0.792], [64673.1, 0.596], [64673.8, 0.118], [64674.3, 0.001], [64677.8, 1.366], [64678.6, 0.213], [64684.3, 0.136], [64684.8, 0.327], [64684.9, 0.347], [64686.1, 0.615], [64694.1, 0.006]], "asks": [[64710.3, 0.214], [64711.2, 0.996], [64711.8, 0.002], [64715.4, 0.126], [64716.7, 0.581], [64726.1, 0.042], [64726.2, 2.475], [65341.2, 2.294], [65535.5, 1.252], [65593.6, 1.521], [65761.8, 2.308]]}
{"kind": "depth", "E": 1787081859039, "U": 11315467709660, "u": 11315467716723, "recv_ms": 1787081859007, "bids": [[1000.0, 35.81], [14494.2, 1.722], [14594.2, 2.478], [58224.7, 0.002], [62106.4, 0.689], [63691.4, 5.494], [63694.2, 0.0], [63723.8, 4.111], [63901.9, 6.419], [63911.1, 0.01], [64047.3, 0.073], [64534.4, 4.998], [64551.3, 0.0], [64551.4, 4.609], [64682.6, 0.033]], "asks": [[64834.1, 5.398], [64851.1, 10.408], [64889.9, 10.021], [65341.2, 2.294], [65601.1, 0.002], [65694.3, 0.0]]}
{"kind": "depth", "E": 1787081859141, "U": 11315467716965, "u": 11315467722835, "recv_ms": 1787081859111, "bids": [[1000.0, 35.81], [14494.2, 2.072], [14594.2, 2.128], [58224.7, 0.002], [62106.4, 0.692], [63701.0, 1.412], [63765.6, 0.03], [63768.0, 0.038], [64047.3, 0.073], [64112.0, 4.963], [64370.7, 0.931], [64672.5, 0.235], [64673.2, 0.558], [64673.8, 0.002], [64674.6, 0.474], [64682.6, 0.028]], "asks": [[64697.0, 0.003], [64704.4, 0.015], [64706.5, 0.218], [65017.8, 0.941], [65282.4, 3.99], [65341.2, 2.294], [65620.6, 1.522], [65622.9, 0.0], [65674.4, 0.76], [65687.6, 0.038], [66311.7, 0.003]]}
{"kind": "depth", "E": 1787081859243, "U": 11315467722843, "u": 11315467727920, "recv_ms": 1787081859211, "bids": [[14494.2, 2.436], [14594.2, 1.764], [58224.7, 0.002], [61459.4, 0.0], [61459.5, 0.034], [62106.4, 0.689], [63694.2, 0.02], [63701.0, 1.42], [63768.0, 0.046], [63853.2, 3.049], [64047.2, 0.026], [64047.3, 0.073], [64370.7, 0.942], [64495.5, 0.0], [64495.6, 12.562], [64534.4, 3.688], [64551.4, 3.963], [64584.2, 0.381], [64627.7, 4.496], [64677.8, 1.366], [64689.7, 0.004], [64694.2, 44.893]], "asks": [[64704.4, 0.014], [64710.3, 0.214], [64760.5, 2.777], [64889.9, 15.411], [65017.8, 0.942], [65340.0, 0.796], [65341.2, 2.294], [65519.8, 4.882], [65620.6, 1.53], [65622.9, 0.008], [65632.5, 7.217], [65687.6, 0.046], [65694.3, 0.02]]}
{"kind": "depth", "E": 1787081859345, "U": 11315467728064, "u": 11315467734243, "recv_ms": 1787081859313, "bids": [[1000.0, 35.81], [14494.2, 2.786], [14594.2, 1.414], [58224.7, 0.002], [62106.4, 0.692], [63566.8, 0.0], [64047.3, 0.075], [64079.6, 1.37]], "asks": [[64726.2, 2.321], [65341.2, 2.294], [65470.6, 5.951], [65545.9, 0.665]]}
{"kind": "depth", "E": 1787081859447, "U": 11315467734274, "u": 11315467739452, "recv_ms": 1787081859414, "bids": [[1000.0, 35.81], [14494.2, 3.15], [14594.2, 1.05], [51755.4, 0.0], [58224.7, 0.002], [61459.4, 0.0], [63263.6, 0.0], [63694.2, 0.0], [64047.3, 0.073], [64534.4, 3.665], [64551.4, 3.943], [64689.7, 0.0], [64693.1, 0.493], [64694.2, 44.906]], "asks": [[64697.0, 0.003], [64726.0, 0.005], [64726.2, 2.321], [64744.1, 0.004], [64750.9, 0.0], [64823.7, 0.0], [64834.1, 0.0], [64834.2, 5.406], [64851.1, 10.408], [65276.5, 0.459], [65341.2, 2.294], [65594.8, 2.89], [65632.4, 12.36], [65694.3, 0.0]]}
{"kind": "depth", "E": 1787081859549, "U": 11315467739601, "u": 11315467744275, "recv_ms": 1787081859585, "bids": [[14494.2, 3.514], [14594.2, 0.686], [58224.7, 0.002], [61459.6, 2.447], [62106.4, 0.689], [64047.3, 0.073], [64370.7, 0.932], [64584.2, 0.381], [64616.5, 0.286], [64635.9, 0.023]], "asks": [[64726.0, 0.005], [64726.1, 0.196], [64739.6, 0.003], [64804.3, 1.389], [65285.5, 0.229], [65341.2, 2.294], [65469.5, 0.0], [65964.2, 1.305]]}
{"kind": "depth", "E": 1787081859651, "U": 11315467744369, "u": 11315467749873, "recv_ms": 1787081859621, "bids": [[1000.0, 35.81], [14394.2, 0.056], [14494.2, 3.752], [14594.2, 0.392], [51755.0, 0.0], [58224.7, 0.002], [61459.4, 0.0], [62106.4, 0.692], [63694.2, 0.02], [63782.5, 17.046], [64047.3, 0.073], [64495.6, 9.645], [64534.4, 1.153], [64551.4, 1.957], [64575.5, 0.012], [64627.7, 1.915], [64630.0, 2.333], [64681.3, 0.085], [64682.4, 0.001], [64689.7, 0.0], [64694.2, 44.906]], "asks": [[64694.3, 3.786], [64697.0, 0.003], [64726.1, 0.042], [64726.2, 2.321], [64735.6, 0.118], [64760.5, 0.0], [64773.5, 1.093], [64834.2, 5.406], [64836.7, 0.101], [64851.1, 10.408], [65341.2, 2.294], [65539.3, 0.267], [65694.3, 0.02], [65753.9, 0.653], [65988.1, 0.009]]}
{"kind": "depth", "E": 1787081859753, "U": 11315467749991, "u": 11315467755060, "recv_ms": 1787081859725, "bids": [[1000.0, 35.81], [14394.2, 0.266], [14494.2, 3.682], [14594.2, 0.252], [58224.7, 0.002], [62106.4, 0.689], [63885.5, 3.756], [64047.3, 0.073], [64331.0, 5.03], [64332.1, 2.871], [64427.2, 0.0], [64428.2, 0.538], [64495.6, 13.077], [64498.1, 0.217], [64499.0, 0.61], [64534.4, 0.0], [64534.5, 4.948], [64536.5, 0.387], [64551.4, 4.573], [64580.2, 13.324], [64581.3, 4.872], [64627.7, 4.496], [64694.2, 44.893]], "asks": [[64726.0, 0.005], [64726.1, 0.042], [64726.3, 0.002], [64760.5, 2.777], [64807.1, 5.585], [64808.0, 17.423], [64808.2, 0.0], [64889.9, 0.0], [64890.0, 10.793], [64896.3, 2.23], [64896.4, 0.0], [64967.7, 0.247], [64967.8, 0.014], [65062.7, 0.835], [65065.2, 0.003], [65341.2, 2.294], [65664.7, 13.912]]}
{"kind": "depth", "E": 1787081859855, "U": 11315467755194, "u": 11315467762844, "recv_ms": 1787081859823, "bids": [[14394.2, 0.504], [14494.2, 3.57], [14594.2, 0.126], [58224.7, 0.002], [63694.2, 0.0], [63756.1, 19.077], [63775.5, 1.993], [64019.8, 0.0], [64047.3, 0.073], [64067.5, 0.0], [64215.2, 0.002], [64370.7, 0.932], [64495.6, 10.19], [64534.5, 2.422], [64551.4, 2.587], [64623.5, 1.237], [64629.5, 0.034], [64666.1, 0.032], [64666.4, 0.034], [64673.8, 0.118], [64674.6, 0.358], [64689.7, 0.004]], "asks": [[64694.3, 3.785], [64697.0, 0.003], [64726.1, 0.196], [64726.4, 0.051], [64744.1, 0.0], [64750.9, 0.004], [64759.0, 0.027], [64890.0, 16.07], [65182.3, 0.124], [65276.8, 1.071], [65332.2, 0.006], [65341.2, 2.294], [65694.3, 0.0]]}
{"kind": "depth", "E": 1787081859957, "U": 11315467762917, "u": 11315467768155, "recv_ms": 1787081859935, "bids": [[1000.0, 35.81], [14394.2, 0.756], [14494.2, 3.43], [14594.2, 0.014], [58224.7, 0.002], [61459.4, 0.0], [62106.4, 0.692], [63620.6, 0.094], [63890.6, 0.782], [64047.3, 0.073], [64302.1, 2.078], [64469.3, 0.217], [64495.6, 12.957], [64498.2, 0.147], [64534.5, 4.838], [64551.4, 4.492], [64647.0, 0.001], [64665.8, 0.048], [64666.8, 0.033], [64672.5, 0.792], [64673.2, 0.001], [64684.8, 0.327], [64686.1, 0.615], [64689.7, 0.0], [64694.2, 44.906]], "asks": [[64715.4, 0.126], [64716.7, 0.581], [64726.1, 0.042], [64744.1, 0.0], [64750.9, 0.0], [64890.0, 11.096], [65341.2, 2.294]]}
{"kind": "depth", "E": 1787081860059, "U": 11315467768173, "u": 11315467773717, "recv_ms": 1787081860028, "bids": [[1000.0, 35.81], [14394.2, 1.092], [14494.2, 3.108], [14594.2, 0.0], [58224.7, 0.002], [61459.4, 0.001], [62106.4, 0.689], [63594.4, 1.601], [63694.2, 0.02], [63858.9, 10.164], [64047.3, 0.073], [64331.1, 42.092], [64332.1, 8.837], [64427.7, 33.587], [64428.2, 5.39], [64498.7, 27.594], [64499.0, 4.676], [64562.0, 0.884], [64578.4, 0.2], [64624.5, 0.159], [64638.5, 3.038], [64649.0, 0.638], [64667.1, 0.091], [64676.2, 0.001], [64680.6, 0.001], [64682.6, 0.028], [64689.7, 0.0], [64694.1, 0.007], [64694.2, 44.906]], "asks": [[64694.3, 3.645], [64696.7, 0.002], [64697.0, 0.003], [64697.5, 0.028], [64699.4, 0.006], [64700.7, 0.003], [64702.7, 0.001], [64726.7, 6.077], [64729.4, 0.62], [64750.9, 0.004], [64767.7, 0.002], [64894.4, 26.848], [64965.8, 33.183], [65062.7, 6.817], [65063.3, 40.795], [65341.2, 2.296], [65470.6, 6.165], [65694.3, 0.02], [65722.6, 0.425]]}
