{"receive_ns":1788563380601940000,"stream":"btcusdt@depth@100ms","event_type":"depthUpdate","event_time_ms":1788563380637,"raw_json":"{\"stream\":\"btcusdt@depth@100ms\",\"data\":{\"e\":\"depthUpdate\",\"E\":1788563380637,\"T\":1788563380635,\"s\":\"BTCUSDT\",\"ps\":\"BTCUSDT\",\"U\":11478232693179,\"u\":11478232697401,\"pu\":11478232693064,\"b\":[[\"29107.10\",\"1.197\"],[\"29507.10\",\"0.903\"],[\"63686.00\",\"0.000\"],[\"71646.30\",\"0.002\"],[\"78015.00\",\"10.557\"],[\"78811.00\",\"15.338\"],[\"79209.10\",\"3.967\"],[\"79232.90\",\"0.000\"],[\"79491.70\",\"0.000\"],[\"79560.10\",\"10.002\"],[\"79564.00\",\"2.773\"],[\"79564.50\",\"0.339\"],[\"79579.90\",\"0.502\"],[\"79581.80\",\"2.873\"],[\"79583.20\",\"0.077\"],[\"79589.20\",\"0.195\"],[\"79592.10\",\"0.001\"],[\"79595.70\",\"0.001\"],[\"79596.30\",\"0.033\"],[\"79601.80\",\"0.000\"],[\"79601.90\",\"0.026\"],[\"79602.70\",\"0.002\"],[\"79603.10\",\"0.226\"],[\"79603.30\",\"0.625\"],[\"79603.40\",\"0.026\"],[\"79603.50\",\"0.004\"],[\"79603.60\",\"1.545\"],[\"79606.60\",\"0.037\"],[\"79606.90\",\"0.196\"],[\"79607.10\",\"5.559\"]],\"a\":[[\"79607.20\",\"7.032\"],[\"79624.40\",\"0.000\"],[\"79625.40\",\"0.452\"],[\"79639.20\",\"0.432\"],[\"79668.10\",\"1.856\"],[\"79668.80\",\"0.316\"],[\"79676.80\",\"4.899\"],[\"79676.90\",\"26.004\"],[\"79677.70\",\"0.017\"],[\"79774.40\",\"2.003\"],[\"79963.40\",\"0.000\"],[\"79967.40\",\"0.000\"],[\"79995.80\",\"0.100\"],[\"79997.80\",\"0.000\"],[\"79999.30\",\"0.011\"],[\"80005.30\",\"0.003\"],[\"80323.90\",\"0.870\"],[\"80403.30\",\"22.288\"],[\"80523.50\",\"9.672\"],[\"80737.60\",\"2.072\"],[\"81199.30\",\"10.762\"]],\"st\":1}}"}
{"receive_ns":1788563380700728000,"stream":"btcusdt@depth@100ms","event_type":"depthUpdate","event_time_ms":1788563380739,"raw_json":"{\"stream\":\"btcusdt@depth@100ms\",\"data\":{\"e\":\"depthUpdate\",\"E\":1788563380739,\"T\":1788563380737,\"s\":\"BTCUSDT\",\"ps\":\"BTCUSDT\",\"U\":11478232697477,\"u\":11478232701599,\"pu\":11478232697401,\"b\":[[\"1000.00\",\"24.754\"],[\"29107.10\",\"1.015\"],[\"29507.10\",\"1.085\"],[\"63686.00\",\"0.000\"],[\"71646.30\",\"0.002\"],[\"75626.70\",\"0.028\"],[\"76422.80\",\"0.002\"],[\"78015.00\",\"10.560\"],[\"78811.00\",\"15.338\"],[\"79232.90\",\"0.141\"],[\"79482.90\",\"0.000\"],[\"79491.70\",\"0.483\"],[\"79575.30\",\"0.174\"],[\"79583.20\",\"0.504\"],[\"79583.80\",\"0.001\"],[\"79589.10\",\"0.019\"],[\"79589.20\",\"0.395\"],[\"79589.30\",\"0.017\"],[\"79592.10\",\"0.077\"],[\"79601.90\",\"0.000\"],[\"79604.00\",\"0.030\"]],\"a\":[[\"79671.50\",\"25.810\"],[\"79676.80\",\"0.076\"],[\"79676.90\",\"0.205\"],[\"79728.70\",\"0.000\"],[\"79774.40\",\"2.254\"],[\"79963.40\",\"0.760\"],[\"79967.40\",\"0.199\"],[\"79995.30\",\"0.002\"],[\"79995.80\",\"0.863\"],[\"79997.80\",\"0.525\"],[\"79999.30\",\"0.167\"],[\"80403.30\",\"22.286\"],[\"80920.70\",\"4.307\"]],\"st\":1}}"}
{"receive_ns":1788563380804069000,"stream":"btcusdt@depth@100ms","event_type":"depthUpdate","event_time_ms":1788563380841,"raw_json":"{\"stream\":\"btcusdt@depth@100ms\",\"data\":{\"e\":\"depthUpdate\",\"E\":1788563380841,\"T\":1788563380838,\"s\":\"BTCUSDT\",\"ps\":\"BTCUSDT\",\"U\":11478232701656,\"u\":11478232706920,\"pu\":11478232701599,\"b\":[[\"1000.00\",\"24.754\"],[\"29107.10\",\"0.840\"],[\"29507.10\",\"1.260\"],[\"71646.30\",\"0.002\"],[\"76422.80\",\"0.000\"],[\"78811.00\",\"15.338\"],[\"78938.30\",\"0.070\"],[\"79482.90\",\"0.526\"],[\"79583.20\",\"0.579\"],[\"79597.30\",\"0.054\"]],\"a\":[[\"79728.70\",\"0.294\"],[\"79995.30\",\"0.046\"],[\"80403.30\",\"22.286\"],[\"80523.50\",\"10.416\"],[\"80598.60\",\"14.254\"],[\"80718.10\",\"26.292\"]],\"st\":1}}"}
{"receive_ns":1788563380906146000,"stream":"btcusdt@depth@100ms","event_type":"depthUpdate","event_time_ms":1788563380943,"raw_json":"{\"stream\":\"btcusdt@depth@100ms\",\"data\":{\"e\":\"depthUpdate\",\"E\":1788563380943,\"T\":1788563380941,\"s\":\"BTCUSDT\",\"ps\":\"BTCUSDT\",\"U\":11478232707062,\"u\":11478232712755,\"pu\":11478232706920,\"b\":[[\"29107.10\",\"0.658\"],[\"29507.10\",\"1.442\"],[\"63686.00\",\"0.000\"],[\"71646.30\",\"0.002\"],[\"76422.80\",\"0.002\"],[\"78572.20\",\"29.796\"],[\"78811.00\",\"15.338\"],[\"79029.00\",\"0.004\"],[\"79209.10\",\"3.977\"],[\"79232.90\",\"0.141\"],[\"79491.70\",\"0.483\"],[\"79575.30\",\"0.074\"],[\"79580.60\",\"0.006\"],[\"79582.60\",\"2.331\"],[\"79583.20\",\"0.102\"],[\"79583.80\",\"0.001\"],[\"79589.20\",\"0.897\"],[\"79606.90\",\"0.198\"]],\"a\":[[\"79774.40\",\"2.254\"],[\"79828.60\",\"7.149\"],[\"79963.40\",\"0.869\"],[\"79967.40\",\"0.090\"],[\"79987.90\",\"0.763\"],[\"79995.30\",\"0.002\"],[\"79995.80\",\"0.100\"],[\"79997.80\",\"0.525\"],[\"79999.30\",\"0.167\"],[\"80403.30\",\"22.286\"],[\"80693.10\",\"0.000\"]],\"st\":1}}"}
{"receive_ns":1788563381009764000,"stream":"btcusdt@depth@100ms","event_type":"depthUpdate","event_time_ms":1788563381045,"raw_json":"{\"stream\":\"btcusdt@depth@100ms\",\"data\":{\"e\":\"depthUpdate\",\"E\":1788563381045,\"T\":1788563381042,\"s\":\"BTCUSDT\",\"ps\":\"BTCUSDT\",\"U\":11478232712823,\"u\":11478232717212,\"pu\":11478232712755,\"b\":[[\"1000.00\",\"24.754\"],[\"29107.10\",\"0.483\"],[\"29507.10\",\"1.617\"],[\"63686.00\",\"0.000\"],[\"71646.30\",\"0.002\"],[\"78015.00\",\"10.688\"],[\"78473.10\",\"1.071\"],[\"78527.80\",\"0.000\"],[\"78811.00\",\"15.338\"],[\"78850.80\",\"15.856\"],[\"78875.30\",\"0.190\"],[\"78890.60\",\"37.250\"],[\"78938.30\",\"0.040\"],[\"79511.50\",\"0.024\"],[\"79535.40\",\"0.000\"],[\"79589.20\",\"0.972\"],[\"79592.80\",\"0.008\"],[\"79602.00\",\"0.003\"],[\"79604.20\",\"0.027\"]],\"a\":[[\"79668.80\",\"26.124\"],[\"79671.50\",\"0.002\"],[\"79678.90\",\"0.015\"],[\"79707.20\",\"0.125\"],[\"79999.30\",\"0.211\"],[\"80403.30\",\"22.286\"],[\"80765.80\",\"0.371\"]],\"st\":1}}"}
{"receive_ns":1788563381103765000,"stream":"btcusdt@bookTicker","event_type":"bookTicker","event_time_ms":1788563381136,"raw_json":"{\"stream\":\"btcusdt@bookTicker\",\"data\":{\"e\":\"bookTicker\",\"u\":11478232721329,\"s\":\"BTCUSDT\",\"ps\":\"BTCUSDT\",\"b\":\"79607.10\",\"B\":\"5.136\",\"a\":\"79607.20\",\"A\":\"7.032\",\"T\":1788563381136,\"E\":1788563381136,\"st\":1}}"}
{"receive_ns":1788563381103994000,"stream":"btcusdt@bookTicker","event_type":"bookTicker","event_time_ms":1788563381137,"raw_json":"{\"stream\":\"btcusdt@bookTicker\",\"data\":{\"e\":\"bookTicker\",\"u\":11478232721383,\"s\":\"BTCUSDT\",\"ps\":\"BTCUSDT\",\"b\":\"79607.10\",\"B\":\"5.138\",\"a\":\"79607.20\",\"A\":\"7.032\",\"T\":1788563381137,\"E\":1788563381137,\"st\":1}}"}
{"receive_ns":1788563381104210000,"stream":"btcusdt@bookTicker","event_type":"bookTicker","event_time_ms":1788563381139,"raw_json":"{\"stream\":\"btcusdt@bookTicker\",\"data\":{\"e\":\"bookTicker\",\"u\":11478232721514,\"s\":\"BTCUSDT\",\"ps\":\"BTCUSDT\",\"b\":\"79607.10\",\"B\":\"5.563\",\"a\":\"79607.20\",\"A\":\"7.032\",\"T\":1788563381139,\"E\":1788563381139,\"st\":1}}"}
{"receive_ns":1788563381111046000,"stream":"btcusdt@depth@100ms","event_type":"depthUpdate","event_time_ms":1788563381147,"raw_json":"{\"stream\":\"btcusdt@depth@100ms\",\"data\":{\"e\":\"depthUpdate\",\"E\":1788563381147,\"T\":1788563381146,\"s\":\"BTCUSDT\",\"ps\":\"BTCUSDT\",\"U\":11478232717475,\"u\":11478232721745,\"pu\":11478232717212,\"b\":[[\"1000.00\",\"24.754\"],[\"29107.10\",\"0.322\"],[\"29407.10\",\"0.014\"],[\"29507.10\",\"1.764\"],[\"63686.00\",\"0.000\"],[\"71646.30\",\"0.002\"],[\"75626.70\",\"0.033\"],[\"76422.80\",\"0.000\"],[\"78394.60\",\"0.015\"],[\"78474.10\",\"0.000\"],[\"78811.00\",\"15.338\"],[\"78886.90\",\"3.607\"],[\"78938.30\",\"0.020\"],[\"79209.10\",\"3.851\"],[\"79232.90\",\"0.000\"],[\"79491.70\",\"0.000\"],[\"79573.90\",\"0.454\"],[\"79574.70\",\"0.003\"],[\"79579.90\",\"0.063\"],[\"79580.00\",\"0.445\"],[\"79581.80\",\"2.873\"],[\"79583.20\",\"0.002\"],[\"79589.20\",\"0.270\"],[\"79592.80\",\"0.004\"],[\"79593.20\",\"0.000\"],[\"79602.00\",\"0.029\"],[\"79603.60\",\"1.545\"],[\"79604.00\",\"0.004\"],[\"79604.20\",\"0.001\"],[\"79604.80\",\"0.002\"],[\"79607.10\",\"5.563\"]],\"a\":[[\"79623.50\",\"0.001\"],[\"79624.50\",\"0.931\"],[\"79625.40\",\"0.000\"],[\"79668.80\",\"0.316\"],[\"79676.90\",\"26.013\"],[\"79706.90\",\"0.000\"],[\"79707.20\",\"0.000\"],[\"79707.50\",\"0.125\"],[\"79774.40\",\"2.003\"],[\"79961.60\",\"0.235\"],[\"79963.40\",\"0.000\"],[\"79967.40\",\"0.000\"],[\"79987.90\",\"0.000\"],[\"79997.80\",\"0.000\"],[\"79999.30\",\"0.055\"],[\"80403.30\",\"22.286\"],[\"80633.00\",\"13.450\"],[\"80740.00\",\"5.063\"],[\"80819.60\",\"0.006\"]],\"st\":1}}"}
{"receive_ns":1788563381212488000,"stream":"btcusdt@depth@100ms","event_type":"depthUpdate","event_time_ms":1788563381249,"raw_json":"{\"stream\":\"btcusdt@depth@100ms\",\"data\":{\"e\":\"depthUpdate\",\"E\":1788563381249,\"T\":1788563381246,\"s\":\"BTCUSDT\",\"ps\":\"BTCUSDT\",\"U\":11478232721768,\"u\":11478232725512,\"pu\":11478232721745,\"b\":[[\"29107.10\",\"0.203\"],[\"29407.10\",\"0.077\"],[\"29507.10\",\"1.820\"],[\"71646.30\",\"0.002\"],[\"71684.00\",\"0.000\"],[\"76422.80\",\"0.002\"],[\"78528.70\",\"5.579\"],[\"78568.40\",\"2.718\"],[\"78722.90\",\"0.009\"],[\"78811.00\",\"15.338\"],[\"79209.10\",\"3.715\"],[\"79232.90\",\"0.141\"],[\"79359.70\",\"0.154\"],[\"79491.70\",\"0.483\"],[\"79573.90\",\"0.002\"],[\"79574.70\",\"0.455\"],[\"79575.90\",\"0.003\"],[\"79579.90\",\"0.502\"],[\"79580.00\",\"0.006\"],[\"79581.90\",\"0.061\"],[\"79582.80\",\"0.001\"],[\"79583.00\",\"0.001\"],[\"79583.20\",\"0.604\"],[\"79583.70\",\"0.644\"],[\"79583.80\",\"0.001\"],[\"79583.90\",\"0.060\"],[\"79588.20\",\"0.315\"],[\"79588.30\",\"0.008\"],[\"79589.20\",\"0.470\"],[\"79602.00\",\"0.003\"],[\"79603.70\",\"0.037\"],[\"79603.90\",\"0.027\"]],\"a\":[[\"79624.50\",\"0.479\"],[\"79625.50\",\"0.458\"],[\"79671.50\",\"25.810\"],[\"79676.90\",\"0.205\"],[\"79702.80\",\"0.010\"],[\"79707.20\",\"0.000\"],[\"79707.50\",\"0.000\"],[\"79707.60\",\"8.908\"],[\"79774.40\",\"2.505\"],[\"79961.60\",\"0.120\"],[\"79963.40\",\"0.618\"],[\"79967.40\",\"0.090\"],[\"79987.90\",\"0.763\"],[\"79997.80\",\"0.525\"],[\"79999.30\",\"0.211\"],[\"80403.30\",\"22.286\"],[\"80479.40\",\"0.188\"]],\"st\":1}}"}
{"receive_ns":1788563381313125000,"stream":"btcusdt@depth@100ms","event_type":"depthUpdate","event_time_ms":1788563381351,"raw_json":"{\"stream\":\"btcusdt@depth@100ms\",\"data\":{\"e\":\"depthUpdate\",\"E\":1788563381351,\"T\":1788563381350,\"s\":\"BTCUSDT\",\"ps\":\"BTCUSDT\",\"U\":11478232725641,\"u\":11478232730307,\"pu\":11478232725512,\"b\":[[\"1000.00\",\"24.754\"],[\"29107.10\",\"0.077\"],[\"29407.10\",\"0.133\"],[\"29507.10\",\"1.890\"],[\"71646.30\",\"0.002\"],[\"76422.80\",\"0.000\"],[\"78811.00\",\"15.338\"],[\"78938.30\",\"0.000\"],[\"79559.30\",\"0.113\"],[\"79602.10\",\"0.130\"],[\"79602.20\",\"0.020\"],[\"79604.40\",\"0.026\"],[\"79604.60\",\"0.026\"]],\"a\":[[\"79639.10\",\"0.033\"],[\"80403.30\",\"22.286\"],[\"80479.00\",\"2.460\"],[\"80642.10\",\"31.315\"]],\"st\":1}}"}
{"receive_ns":1788563381315118000,"stream":"btcusdt@bookTicker","event_type":"bookTicker","event_time_ms":1788563381353,"raw_json":"{\"stream\":\"btcusdt@bookTicker\",\"data\":{\"e\":\"bookTicker\",\"u\":11478232730392,\"s\":\"BTCUSDT\",\"ps\":\"BTCUSDT\",\"b\":\"79607.10\",\"B\":\"5.029\",\"a\":\"79607.20\",\"A\":\"7.032\",\"T\":1788563381353,\"E\":1788563381353,\"st\":1}}"}
{"receive_ns":1788563381316360000,"stream":"btcusdt@bookTicker","event_type":"bookTicker","event_time_ms":1788563381354,"raw_json":"{\"stream\":\"btcusdt@bookTicker\",\"data\":{\"e\":\"bookTicker\",\"u\":11478232730424,\"s\":\"BTCUSDT\",\"ps\":\"BTCUSDT\",\"b\":\"79607.10\",\"B\":\"5.027\",\"a\":\"79607.20\",\"A\":\"7.032\",\"T\":1788563381354,\"E\":1788563381354,\"st\":1}}"}
{"receive_ns":1788563381317642000,"stream":"btcusdt@bookTicker","event_type":"bookTicker","event_time_ms":1788563381356,"raw_json":"{\"stream\":\"btcusdt@bookTicker\",\"data\":{\"e\":\"bookTicker\",\"u\":11478232730507,\"s\":\"BTCUSDT\",\"ps\":\"BTCUSDT\",\"b\":\"79607.10\",\"B\":\"5.567\",\"a\":\"79607.20\",\"A\":\"7.032\",\"T\":1788563381355,\"E\":1788563381356,\"st\":1}}"}
{"receive_ns":1788563381319083000,"stream":"btcusdt@bookTicker","event_type":"bookTicker","event_time_ms":1788563381357,"raw_json":"{\"stream\":\"btcusdt@bookTicker\",\"data\":{\"e\":\"bookTicker\",\"u\":11478232730529,\"s\":\"BTCUSDT\",\"ps\":\"BTCUSDT\",\"b\":\"79607.10\",\"B\":\"5.569\",\"a\":\"79607.20\",\"A\":\"7.032\",\"T\":1788563381356,\"E\":1788563381357,\"st\":1}}"}
{"receive_ns":1788563381328700000,"stream":"btcusdt@bookTicker","event_type":"bookTicker","event_time_ms":1788563381367,"raw_json":"{\"stream\":\"btcusdt@bookTicker\",\"data\":{\"e\":\"bookTicker\",\"u\":11478232730902,\"s\":\"BTCUSDT\",\"ps\":\"BTCUSDT\",\"b\":\"79607.10\",\"B\":\"5.531\",\"a\":\"79607.20\",\"A\":\"7.032\",\"T\":1788563381366,\"E\":1788563381367,\"st\":1}}"}
{"receive_ns":1788563381415588000,"stream":"btcusdt@depth@100ms","event_type":"depthUpdate","event_time_ms":1788563381453,"raw_json":"{\"stream\":\"btcusdt@depth@100ms\",\"data\":{\"e\":\"depthUpdate\",\"E\":1788563381453,\"T\":1788563381452,\"s\":\"BTCUSDT\",\"ps\":\"BTCUSDT\",\"U\":11478232730352,\"u\":11478232733662,\"pu\":11478232730307,\"b\":[[\"1000.00\",\"24.754\"],[\"29107.10\",\"0.000\"],[\"29407.10\",\"0.231\"],[\"29507.10\",\"1.869\"],[\"71646.30\",\"0.002\"],[\"76422.80\",\"0.002\"],[\"78811.00\",\"15.340\"],[\"79209.10\",\"3.212\"],[\"79232.90\",\"0.141\"],[\"79491.70\",\"0.000\"],[\"79492.40\",\"0.092\"],[\"79580.60\",\"0.000\"],[\"79582.60\",\"2.337\"],[\"79583.20\",\"0.102\"],[\"79583.40\",\"0.006\"],[\"79583.80\",\"0.001\"],[\"79588.30\",\"0.004\"],[\"79589.20\",\"0.972\"],[\"79589.80\",\"1.014\"],[\"79595.70\",\"0.002\"],[\"79596.30\",\"0.032\"],[\"79606.60\",\"0.001\"],[\"79606.90\",\"0.234\"],[\"79607.10\",\"5.531\"]],\"a\":[[\"79623.30\",\"0.458\"],[\"79774.40\",\"2.003\"],[\"79963.40\",\"1.120\"],[\"79967.40\",\"0.090\"],[\"79987.90\",\"0.763\"],[\"79997.80\",\"0.525\"],[\"79999.30\",\"0.055\"],[\"80005.20\",\"3.131\"],[\"80403.30\",\"22.286\"],[\"80562.50\",\"48.972\"]],\"st\":1}}"}
{"receive_ns":1788563381430786000,"stream":"btcusdt@bookTicker","event_type":"bookTicker","event_time_ms":1788563381466,"raw_json":"{\"stream\":\"btcusdt@bookTicker\",\"data\":{\"e\":\"bookTicker\",\"u\":11478232734126,\"s\":\"BTCUSDT\",\"ps\":\"BTCUSDT\",\"b\":\"79607.10\",\"B\":\"5.533\",\"a\":\"79607.20\",\"A\":\"7.032\",\"T\":1788563381466,\"E\":1788563381466,\"st\":1}}"}
{"receive_ns":1788563381433479000,"stream":"btcusdt@bookTicker","event_type":"bookTicker","event_time_ms":1788563381470,"raw_json":"{\"stream\":\"btcusdt@bookTicker\",\"data\":{\"e\":\"bookTicker\",\"u\":11478232734316,\"s\":\"BTCUSDT\",\"ps\":\"BTCUSDT\",\"b\":\"79607.10\",\"B\":\"5.537\",\"a\":\"79607.20\",\"A\":\"7.032\",\"T\":1788563381470,\"E\":1788563381470,\"st\":1}}"}
{"receive_ns":1788563381517575000,"stream":"btcusdt@depth@100ms","event_type":"depthUpdate","event_time_ms":1788563381555,"raw_json":"{\"stream\":\"btcusdt@depth@100ms\",\"data\":{\"e\":\"depthUpdate\",\"E\":1788563381555,\"T\":1788563381553,\"s\":\"BTCUSDT\",\"ps\":\"BTCUSDT\",\"U\":11478232733674,\"u\":11478232737491,\"pu\":11478232733662,\"b\":[[\"29407.10\",\"0.413\"],[\"29507.10\",\"1.687\"],[\"63685.70\",\"0.001\"],[\"71646.30\",\"0.002\"],[\"78811.00\",\"15.338\"],[\"79029.60\",\"0.095\"],[\"79209.10\",\"3.222\"],[\"79533.70\",\"0.829\"],[\"79549.60\",\"0.691\"],[\"79575.30\",\"0.325\"],[\"79589.00\",\"0.000\"],[\"79589.20\",\"0.972\"],[\"79589.30\",\"0.083\"],[\"79589.80\",\"0.010\"],[\"79589.90\",\"0.002\"],[\"79602.40\",\"0.254\"],[\"79602.50\",\"0.001\"],[\"79604.80\",\"0.002\"],[\"79605.00\",\"0.656\"],[\"79607.10\",\"5.537\"]],\"a\":[[\"79999.30\",\"0.211\"],[\"80224.40\",\"0.000\"],[\"80403.30\",\"22.286\"]],\"st\":1}}"}
{"receive_ns":1788563381620935000,"stream":"btcusdt@depth@100ms","event_type":"depthUpdate","event_time_ms":1788563381657,"raw_json":"{\"stream\":\"btcusdt@depth@100ms\",\"data\":{\"e\":\"depthUpdate\",\"E\":1788563381657,\"T\":1788563381653,\"s\":\"BTCUSDT\",\"ps\":\"BTCUSDT\",\"U\":11478232737555,\"u\":11478232740967,\"pu\":11478232737491,\"b\":[[\"1000.00\",\"24.754\"],[\"29407.10\",\"0.588\"],[\"29507.10\",\"1.512\"],[\"63686.00\",\"0.000\"],[\"71646.30\",\"0.002\"],[\"76422.80\",\"0.000\"],[\"78710.60\",\"0.001\"],[\"78811.00\",\"15.338\"],[\"79209.10\",\"3.726\"],[\"79232.90\",\"0.000\"],[\"79583.20\",\"0.002\"],[\"79589.20\",\"0.270\"]],\"a\":[[\"79963.40\",\"0.000\"],[\"79967.40\",\"0.000\"],[\"79987.90\",\"0.000\"],[\"79997.80\",\"0.000\"],[\"80005.20\",\"3.630\"],[\"80005.30\",\"0.001\"],[\"80319.80\",\"0.063\"],[\"80403.30\",\"22.286\"],[\"80523.50\",\"9.672\"],[\"80642.30\",\"0.867\"]],\"st\":1}}"}
{"receive_ns":1788563381723355000,"stream":"btcusdt@depth@100ms","event_type":"depthUpdate","event_time_ms":1788563381759,"raw_json":"{\"stream\":\"btcusdt@depth@100ms\",\"data\":{\"e\":\"depthUpdate\",\"E\":1788563381759,\"T\":1788563381757,\"s\":\"BTCUSDT\",\"ps\":\"BTCUSDT\",\"U\":11478232741204,\"u\":11478232745348,\"pu\":11478232740967,\"b\":[[\"1000.00\",\"24.754\"],[\"29407.10\",\"0.770\"],[\"29507.10\",\"1.330\"],[\"71646.30\",\"0.002\"],[\"75626.70\",\"0.035\"],[\"76422.80\",\"0.002\"],[\"78811.00\",\"15.338\"],[\"79209.00\",\"0.002\"],[\"79232.90\",\"0.141\"],[\"79575.30\",\"0.325\"],[\"79579.90\",\"0.063\"],[\"79581.80\",\"3.312\"],[\"79583.20\",\"0.102\"],[\"79583.80\",\"0.001\"],[\"79589.20\",\"0.972\"],[\"79592.10\",\"0.001\"],[\"79593.50\",\"0.005\"],[\"79595.70\",\"0.001\"],[\"79596.30\",\"0.033\"],[\"79602.80\",\"0.026\"],[\"79602.90\",\"0.028\"],[\"79603.00\",\"0.029\"],[\"79603.20\",\"0.029\"],[\"79603.70\",\"0.011\"],[\"79603.90\",\"0.001\"],[\"79604.40\",\"0.026\"],[\"79604.60\",\"0.000\"],[\"79605.00\",\"0.630\"],[\"79605.40\",\"0.001\"]],\"a\":[[\"79828.60\",\"7.193\"],[\"79963.40\",\"1.120\"],[\"79967.40\",\"0.090\"],[\"79987.90\",\"0.763\"],[\"79995.30\",\"0.046\"],[\"79997.80\",\"0.525\"],[\"79999.30\",\"0.167\"],[\"80000.00\",\"76.690\"],[\"80323.70\",\"19.056\"],[\"80403.30\",\"22.286\"],[\"80555.60\",\"1.115\"],[\"80697.80\",\"2.472\"],[\"80734.00\",\"0.296\"],[\"80737.60\",\"2.220\"]],\"st\":1}}"}
{"receive_ns":1788563381728697000,"stream":"btcusdt@bookTicker","event_type":"bookTicker","event_time_ms":1788563381764,"raw_json":"{\"stream\":\"btcusdt@bookTicker\",\"data\":{\"e\":\"bookTicker\",\"u\":11478232745581,\"s\":\"BTCUSDT\",\"ps\":\"BTCUSDT\",\"b\":\"79607.10\",\"B\":\"5.521\",\"a\":\"79607.20\",\"A\":\"7.032\",\"T\":1788563381764,\"E\":1788563381764,\"st\":1}}"}
{"receive_ns":1788563381729973000,"stream":"btcusdt@bookTicker","event_type":"bookTicker","event_time_ms":1788563381767,"raw_json":"{\"stream\":\"btcusdt@bookTicker\",\"data\":{\"e\":\"bookTicker\",\"u\":11478232745657,\"s\":\"BTCUSDT\",\"ps\":\"BTCUSDT\",\"b\":\"79607.10\",\"B\":\"5.538\",\"a\":\"79607.20\",\"A\":\"7.032\",\"T\":1788563381767,\"E\":1788563381767,\"st\":1}}"}
{"receive_ns":1788563381824670000,"stream":"btcusdt@depth@100ms","event_type":"depthUpdate","event_time_ms":1788563381861,"raw_json":"{\"stream\":\"btcusdt@depth@100ms\",\"data\":{\"e\":\"depthUpdate\",\"E\":1788563381861,\"T\":1788563381859,\"s\":\"BTCUSDT\",\"ps\":\"BTCUSDT\",\"U\":11478232745391,\"u\":11478232748939,\"pu\":11478232745348,\"b\":[[\"29407.10\",\"0.945\"],[\"29507.10\",\"1.155\"],[\"63686.00\",\"0.000\"],[\"71646.30\",\"0.002\"],[\"75626.70\",\"0.033\"],[\"75626.80\",\"0.012\"],[\"76422.80\",\"0.000\"],[\"78261.70\",\"1.027\"],[\"78568.40\",\"1.828\"],[\"78727.70\",\"0.507\"],[\"78811.00\",\"15.338\"],[\"79209.10\",\"3.726\"],[\"79535.40\",\"0.002\"],[\"79579.90\",\"0.502\"],[\"79581.80\",\"2.873\"],[\"79592.10\",\"0.001\"],[\"79602.60\",\"0.001\"],[\"79602.70\",\"0.028\"],[\"79604.40\",\"0.000\"],[\"79604.50\",\"0.000\"],[\"79604.70\",\"0.001\"],[\"79604.90\",\"0.000\"],[\"79607.10\",\"5.538\"]],\"a\":[[\"79742.60\",\"0.002\"],[\"80403.30\",\"22.286\"],[\"81199.30\",\"10.759\"]],\"st\":1}}"}
{"receive_ns":1788563381928769000,"stream":"btcusdt@depth@100ms","event_type":"depthUpdate","event_time_ms":1788563381963,"raw_json":"{\"stream\":\"btcusdt@depth@100ms\",\"data\":{\"e\":\"depthUpdate\",\"E\":1788563381963,\"T\":1788563381962,\"s\":\"BTCUSDT\",\"ps\":\"BTCUSDT\",\"U\":11478232749023,\"u\":11478232752551,\"pu\":11478232748939,\"b\":[[\"1000.00\",\"24.754\"],[\"29407.10\",\"1.127\"],[\"29507.10\",\"0.973\"],[\"71646.30\",\"0.002\"],[\"76422.80\",\"0.002\"],[\"78452.80\",\"40.346\"],[\"78473.10\",\"0.918\"],[\"78811.00\",\"15.338\"],[\"79232.90\",\"0.141\"],[\"79482.90\",\"0.000\"],[\"79491.70\",\"0.483\"],[\"79575.30\",\"0.074\"],[\"79583.20\",\"0.102\"],[\"79583.80\",\"0.001\"],[\"79589.20\",\"0.897\"],[\"79592.50\",\"0.001\"],[\"79604.00\",\"0.004\"],[\"79606.90\",\"0.232\"]],\"a\":[[\"79728.70\",\"0.000\"],[\"79774.40\",\"2.254\"],[\"79963.40\",\"0.869\"],[\"79967.40\",\"0.090\"],[\"79987.90\",\"0.763\"],[\"79995.30\",\"0.002\"],[\"79997.80\",\"0.525\"],[\"79999.30\",\"0.167\"],[\"80403.30\",\"22.286\"],[\"80598.60\",\"14.043\"],[\"81836.20\",\"1.707\"]],\"st\":1}}"}
{"receive_ns":1788563381939643000,"stream":"btcusdt@bookTicker","event_type":"bookTicker","event_time_ms":1788563381975,"raw_json":"{\"stream\":\"btcusdt@bookTicker\",\"data\":{\"e\":\"bookTicker\",\"u\":11478232753078,\"s\":\"BTCUSDT\",\"ps\":\"BTCUSDT\",\"b\":\"79607.10\",\"B\":\"5.543\",\"a\":\"79607.20\",\"A\":\"7.032\",\"T\":1788563381975,\"E\":1788563381975,\"st\":1}}"}
{"receive_ns":1788563382035719000,"stream":"btcusdt@depth@100ms","event_type":"depthUpdate","event_time_ms":1788563382065,"raw_json":"{\"stream\":\"btcusdt@depth@100ms\",\"data\":{\"e\":\"depthUpdate\",\"E\":1788563382065,\"T\":1788563382062,\"s\":\"BTCUSDT\",\"ps\":\"BTCUSDT\",\"U\":11478232752563,\"u\":11478232757525,\"pu\":11478232752551,\"b\":[[\"1000.00\",\"24.754\"],[\"29407.10\",\"1.302\"],[\"29507.10\",\"0.798\"],[\"63686.00\",\"0.000\"],[\"71646.30\",\"0.002\"],[\"78015.00\",\"10.691\"],[\"78811.00\",\"15.338\"],[\"78886.90\",\"2.721\"],[\"79443.50\",\"0.009\"],[\"79443.60\",\"2.501\"],[\"79443.70\",\"0.958\"],[\"79483.00\",\"0.526\"],[\"79589.20\",\"0.972\"],[\"79592.20\",\"0.098\"],[\"79592.80\",\"0.004\"],[\"79603.70\",\"0.037\"],[\"79604.70\",\"0.027\"],[\"79607.10\",\"5.543\"]],\"a\":[[\"79613.60\",\"0.296\"],[\"79616.90\",\"0.192\"],[\"79624.40\",\"0.452\"],[\"79625.50\",\"0.006\"],[\"79668.10\",\"5.572\"],[\"79728.70\",\"0.294\"],[\"79768.10\",\"1.330\"],[\"79961.60\",\"0.235\"],[\"79995.30\",\"0.046\"],[\"80005.20\",\"3.754\"],[\"80403.30\",\"22.286\"],[\"80598.60\",\"13.857\"],[\"80681.90\",\"10.390\"]],\"st\":1}}"}
{"receive_ns":1788563382118954000,"stream":"btcusdt@bookTicker","event_type":"bookTicker","event_time_ms":1788563382156,"raw_json":"{\"stream\":\"btcusdt@bookTicker\",\"data\":{\"e\":\"bookTicker\",\"u\":11478232761258,\"s\":\"BTCUSDT\",\"ps\":\"BTCUSDT\",\"b\":\"79607.10\",\"B\":\"5.544\",\"a\":\"79607.20\",\"A\":\"7.032\",\"T\":1788563382156,\"E\":1788563382156,\"st\":1}}"}
{"receive_ns":1788563382129782000,"stream":"btcusdt@depth@100ms","event_type":"depthUpdate","event_time_ms":1788563382167,"raw_json":"{\"stream\":\"btcusdt@depth@100ms\",\"data\":{\"e\":\"depthUpdate\",\"E\":1788563382167,\"T\":1788563382166,\"s\":\"BTCUSDT\",\"ps\":\"BTCUSDT\",\"U\":11478232757737,\"u\":11478232761716,\"pu\":11478232757525,\"b\":[[\"29407.10\",\"1.477\"],[\"29507.10\",\"0.623\"],[\"63686.00\",\"0.000\"],[\"71646.30\",\"0.002\"],[\"76422.80\",\"0.000\"],[\"77378.10\",\"1.805\"],[\"78811.00\",\"15.338\"],[\"78982.70\",\"0.003\"],[\"79209.10\",\"3.716\"],[\"79232.90\",\"0.141\"],[\"79483.00\",\"0.000\"],[\"79491.70\",\"0.232\"],[\"79583.20\",\"0.604\"],[\"79583.80\",\"0.001\"],[\"79589.20\",\"0.395\"],[\"79606.40\",\"0.002\"],[\"79607.10\",\"5.544\"]],\"a\":[[\"79728.70\",\"0.000\"],[\"79774.40\",\"2.254\"],[\"79963.40\",\"0.760\"],[\"79967.40\",\"0.000\"],[\"79987.90\",\"0.000\"],[\"79995.30\",\"0.002\"],[\"79995.80\",\"0.863\"],[\"79997.80\",\"0.525\"],[\"79999.30\",\"0.011\"],[\"80323.70\",\"19.243\"],[\"80403.30\",\"22.286\"]],\"st\":1}}"}
{"receive_ns":1788563382199113000,"stream":"btcusdt@bookTicker","event_type":"bookTicker","event_time_ms":1788563382230,"raw_json":"{\"stream\":\"btcusdt@bookTicker\",\"data\":{\"e\":\"bookTicker\",\"u\":11478232765280,\"s\":\"BTCUSDT\",\"ps\":\"BTCUSDT\",\"b\":\"79607.10\",\"B\":\"5.537\",\"a\":\"79607.20\",\"A\":\"7.032\",\"T\":1788563382230,\"E\":1788563382230,\"st\":1}}"}
{"receive_ns":1788563382209396000,"stream":"btcusdt@bookTicker","event_type":"bookTicker","event_time_ms":1788563382246,"raw_json":"{\"stream\":\"btcusdt@bookTicker\",\"data\":{\"e\":\"bookTicker\",\"u\":11478232766382,\"s\":\"BTCUSDT\",\"ps\":\"BTCUSDT\",\"b\":\"79607.10\",\"B\":\"5.544\",\"a\":\"79607.20\",\"A\":\"7.032\",\"T\":1788563382246,\"E\":1788563382246,\"st\":1}}"}
{"receive_ns":1788563382232529000,"stream":"btcusdt@depth@100ms","event_type":"depthUpdate","event_time_ms":1788563382269,"raw_json":"{\"stream\":\"btcusdt@depth@100ms\",\"data\":{\"e\":\"depthUpdate\",\"E\":1788563382269,\"T\":1788563382268,\"s\":\"BTCUSDT\",\"ps\":\"BTCUSDT\",\"U\":11478232761758,\"u\":11478232767394,\"pu\":11478232761716,\"b\":[[\"1000.00\",\"24.754\"],[\"29407.10\",\"1.659\"],[\"29507.10\",\"0.441\"],[\"71646.30\",\"0.002\"],[\"75626.70\",\"0.031\"],[\"75626.80\",\"0.014\"],[\"76422.80\",\"0.002\"],[\"78500.00\",\"85.524\"],[\"78811.00\",\"15.338\"],[\"79395.70\",\"0.000\"],[\"79443.60\",\"0.000\"],[\"79443.70\",\"0.001\"],[\"79511.50\",\"0.022\"],[\"79535.40\",\"0.000\"],[\"79539.70\",\"0.151\"],[\"79543.10\",\"0.000\"],[\"79552.40\",\"0.065\"],[\"79552.60\",\"0.014\"],[\"79559.10\",\"0.000\"],[\"79582.00\",\"0.006\"],[\"79583.20\",\"0.855\"],[\"79589.00\",\"0.062\"],[\"79589.20\",\"0.470\"],[\"79589.30\",\"0.021\"],[\"79595.60\",\"0.168\"],[\"79606.90\",\"0.233\"],[\"79607.10\",\"5.544\"]],\"a\":[[\"79673.10\",\"0.103\"],[\"79678.90\",\"0.013\"],[\"79742.60\",\"0.000\"],[\"79768.10\",\"0.000\"],[\"79815.90\",\"0.012\"],[\"79967.40\",\"0.199\"],[\"79999.30\",\"0.211\"],[\"80005.20\",\"3.629\"],[\"80403.30\",\"22.286\"]],\"st\":1}}"}
{"receive_ns":1788563382254240000,"stream":"btcusdt@bookTicker","event_type":"bookTicker","event_time_ms":1788563382292,"raw_json":"{\"stream\":\"btcusdt@bookTicker\",\"data\":{\"e\":\"bookTicker\",\"u\":11478232768233,\"s\":\"BTCUSDT\",\"ps\":\"BTCUSDT\",\"b\":\"79607.10\",\"B\":\"4.385\",\"a\":\"79607.20\",\"A\":\"7.032\",\"T\":1788563382292,\"E\":1788563382292,\"st\":1}}"}
{"receive_ns":1788563382264561000,"stream":"btcusdt@bookTicker","event_type":"bookTicker","event_time_ms":1788563382301,"raw_json":"{\"stream\":\"btcusdt@bookTicker\",\"data\":{\"e\":\"bookTicker\",\"u\":11478232768861,\"s\":\"BTCUSDT\",\"ps\":\"BTCUSDT\",\"b\":\"79607.10\",\"B\":\"5.547\",\"a\":\"79607.20\",\"A\":\"7.032\",\"T\":1788563382301,\"E\":1788563382301,\"st\":1}}"}
{"receive_ns":1788563382267091000,"stream":"btcusdt@bookTicker","event_type":"bookTicker","event_time_ms":1788563382302,"raw_json":"{\"stream\":\"btcusdt@bookTicker\",\"data\":{\"e\":\"bookTicker\",\"u\":11478232768926,\"s\":\"BTCUSDT\",\"ps\":\"BTCUSDT\",\"b\":\"79607.10\",\"B\":\"5.546\",\"a\":\"79607.20\",\"A\":\"7.032\",\"T\":1788563382302,\"E\":1788563382302,\"st\":1}}"}
{"receive_ns":1788563382267315000,"stream":"btcusdt@bookTicker","event_type":"bookTicker","event_time_ms":1788563382302,"raw_json":"{\"stream\":\"btcusdt@bookTicker\",\"data\":{\"e\":\"bookTicker\",\"u\":11478232768930,\"s\":\"BTCUSDT\",\"ps\":\"BTCUSDT\",\"b\":\"79607.10\",\"B\":\"5.544\",\"a\":\"79607.20\",\"A\":\"7.032\",\"T\":1788563382302,\"E\":1788563382302,\"st\":1}}"}
{"receive_ns":1788563382267573000,"stream":"btcusdt@bookTicker","event_type":"bookTicker","event_time_ms":1788563382303,"raw_json":"{\"stream\":\"btcusdt@bookTicker\",\"data\":{\"e\":\"bookTicker\",\"u\":11478232768937,\"s\":\"BTCUSDT\",\"ps\":\"BTCUSDT\",\"b\":\"79607.10\",\"B\":\"5.545\",\"a\":\"79607.20\",\"A\":\"7.032\",\"T\":1788563382302,\"E\":1788563382303,\"st\":1}}"}
{"receive_ns":1788563382267883000,"stream":"btcusdt@bookTicker","event_type":"bookTicker","event_time_ms":1788563382303,"raw_json":"{\"stream\":\"btcusdt@bookTicker\",\"data\":{\"e\":\"bookTicker\",\"u\":11478232768986,\"s\":\"BTCUSDT\",\"ps\":\"BTCUSDT\",\"b\":\"79607.10\",\"B\":\"5.546\",\"a\":\"79607.20\",\"A\":\"7.032\",\"T\":1788563382303,\"E\":1788563382303,\"st\":1}}"}
{"receive_ns":1788563382269344000,"stream":"btcusdt@bookTicker","event_type":"bookTicker","event_time_ms":1788563382305,"raw_json":"{\"stream\":\"btcusdt@bookTicker\",\"data\":{\"e\":\"bookTicker\",\"u\":11478232769052,\"s\":\"BTCUSDT\",\"ps\":\"BTCUSDT\",\"b\":\"79607.10\",\"B\":\"5.558\",\"a\":\"79607.20\",\"A\":\"7.032\",\"T\":1788563382304,\"E\":1788563382305,\"st\":1}}"}
{"receive_ns":1788563382269613000,"stream":"btcusdt@bookTicker","event_type":"bookTicker","event_time_ms":1788563382305,"raw_json":"{\"stream\":\"btcusdt@bookTicker\",\"data\":{\"e\":\"bookTicker\",\"u\":11478232769060,\"s\":\"BTCUSDT\",\"ps\":\"BTCUSDT\",\"b\":\"79607.10\",\"B\":\"5.570\",\"a\":\"79607.20\",\"A\":\"7.032\",\"T\":1788563382305,\"E\":1788563382305,\"st\":1}}"}
{"receive_ns":1788563382269788000,"stream":"btcusdt@bookTicker","event_type":"bookTicker","event_time_ms":1788563382305,"raw_json":"{\"stream\":\"btcusdt@bookTicker\",\"data\":{\"e\":\"bookTicker\",\"u\":11478232769065,\"s\":\"BTCUSDT\",\"ps\":\"BTCUSDT\",\"b\":\"79607.10\",\"B\":\"5.582\",\"a\":\"79607.20\",\"A\":\"7.032\",\"T\":1788563382305,\"E\":1788563382305,\"st\":1}}"}
{"receive_ns":1788563382269999000,"stream":"btcusdt@bookTicker","event_type":"bookTicker","event_time_ms":1788563382305,"raw_json":"{\"stream\":\"btcusdt@bookTicker\",\"data\":{\"e\":\"bookTicker\",\"u\":11478232769094,\"s\":\"BTCUSDT\",\"ps\":\"BTCUSDT\",\"b\":\"79607.10\",\"B\":\"5.584\",\"a\":\"79607.20\",\"A\":\"7.032\",\"T\":1788563382305,\"E\":1788563382305,\"st\":1}}"}
{"receive_ns":1788563382275730000,"stream":"btcusdt@bookTicker","event_type":"bookTicker","event_time_ms":1788563382312,"raw_json":"{\"stream\":\"btcusdt@bookTicker\",\"data\":{\"e\":\"bookTicker\",\"u\":11478232769474,\"s\":\"BTCUSDT\",\"ps\":\"BTCUSDT\",\"b\":\"79607.10\",\"B\":\"5.584\",\"a\":\"79607.20\",\"A\":\"7.165\",\"T\":1788563382312,\"E\":1788563382312,\"st\":1}}"}
{"receive_ns":1788563382277086000,"stream":"btcusdt@bookTicker","event_type":"bookTicker","event_time_ms":1788563382313,"raw_json":"{\"stream\":\"btcusdt@bookTicker\",\"data\":{\"e\":\"bookTicker\",\"u\":11478232769587,\"s\":\"BTCUSDT\",\"ps\":\"BTCUSDT\",\"b\":\"79607.10\",\"B\":\"5.583\",\"a\":\"79607.20\",\"A\":\"7.165\",\"T\":1788563382313,\"E\":1788563382313,\"st\":1}}"}
{"receive_ns":1788563382278063000,"stream":"btcusdt@bookTicker","event_type":"bookTicker","event_time_ms":1788563382316,"raw_json":"{\"stream\":\"btcusdt@bookTicker\",\"data\":{\"e\":\"bookTicker\",\"u\":11478232769832,\"s\":\"BTCUSDT\",\"ps\":\"BTCUSDT\",\"b\":\"79607.10\",\"B\":\"5.571\",\"a\":\"79607.20\",\"A\":\"7.165\",\"T\":1788563382315,\"E\":1788563382316,\"st\":1}}"}
{"receive_ns":1788563382278702000,"stream":"btcusdt@bookTicker","event_type":"bookTicker","event_time_ms":1788563382316,"raw_json":"{\"stream\":\"btcusdt@bookTicker\",\"data\":{\"e\":\"bookTicker\",\"u\":11478232769842,\"s\":\"BTCUSDT\",\"ps\":\"BTCUSDT\",\"b\":\"79607.10\",\"B\":\"5.559\",\"a\":\"79607.20\",\"A\":\"7.165\",\"T\":1788563382315,\"E\":1788563382316,\"st\":1}}"}
{"receive_ns":1788563382278868000,"stream":"btcusdt@bookTicker","event_type":"bookTicker","event_time_ms":1788563382316,"raw_json":"{\"stream\":\"btcusdt@bookTicker\",\"data\":{\"e\":\"bookTicker\",\"u\":11478232769844,\"s\":\"BTCUSDT\",\"ps\":\"BTCUSDT\",\"b\":\"79607.10\",\"B\":\"5.547\",\"a\":\"79607.20\",\"A\":\"7.165\",\"T\":1788563382315,\"E\":1788563382316,\"st\":1}}"}
{"receive_ns":1788563382322302000,"stream":"btcusdt@bookTicker","event_type":"bookTicker","event_time_ms":1788563382360,"raw_json":"{\"stream\":\"btcusdt@bookTicker\",\"data\":{\"e\":\"bookTicker\",\"u\":11478232771984,\"s\":\"BTCUSDT\",\"ps\":\"BTCUSDT\",\"b\":\"79607.10\",\"B\":\"5.548\",\"a\":\"79607.20\",\"A\":\"7.165\",\"T\":1788563382360,\"E\":1788563382360,\"st\":1}}"}
{"receive_ns":1788563382338346000,"stream":"btcusdt@bookTicker","event_type":"bookTicker","event_time_ms":1788563382366,"raw_json":"{\"stream\":\"btcusdt@bookTicker\",\"data\":{\"e\":\"bookTicker\",\"u\":11478232772283,\"s\":\"BTCUSDT\",\"ps\":\"BTCUSDT\",\"b\":\"79607.10\",\"B\":\"5.586\",\"a\":\"79607.20\",\"A\":\"7.165\",\"T\":1788563382366,\"E\":1788563382366,\"st\":1}}"}
{"receive_ns":1788563382339022000,"stream":"btcusdt@depth@100ms","event_type":"depthUpdate","event_time_ms":1788563382371,"raw_json":"{\"stream\":\"btcusdt@depth@100ms\",\"data\":{\"e\":\"depthUpdate\",\"E\":1788563382371,\"T\":1788563382370,\"s\":\"BTCUSDT\",\"ps\":\"BTCUSDT\",\"U\":11478232767422,\"u\":11478232772459,\"pu\":11478232767394,\"b\":[[\"1000.00\",\"24.754\"],[\"29307.10\",\"0.028\"],[\"29407.10\",\"1.785\"],[\"29507.10\",\"0.287\"],[\"71646.30\",\"0.002\"],[\"71684.00\",\"0.000\"],[\"76422.80\",\"0.000\"],[\"78811.00\",\"15.338\"],[\"79232.90\",\"0.000\"],[\"79395.80\",\"4.937\"],[\"79443.60\",\"2.171\"],[\"79465.00\",\"0.180\"],[\"79483.00\",\"0.465\"],[\"79491.70\",\"0.000\"],[\"79511.50\",\"0.024\"],[\"79533.70\",\"0.000\"],[\"79549.60\",\"0.000\"],[\"79555.70\",\"0.002\"],[\"79568.20\",\"0.121\"],[\"79576.30\",\"0.049\"],[\"79583.20\",\"0.002\"],[\"79589.20\",\"0.270\"],[\"79595.50\",\"0.033\"],[\"79596.30\",\"0.033\"],[\"79603.50\",\"0.003\"],[\"79606.90\",\"0.235\"],[\"79607.10\",\"5.586\"]],\"a\":[[\"79607.20\",\"7.165\"],[\"79673.10\",\"0.104\"],[\"79678.90\",\"0.015\"],[\"79680.00\",\"0.089\"],[\"79694.50\",\"0.070\"],[\"79707.10\",\"0.000\"],[\"79707.30\",\"0.127\"],[\"79707.60\",\"8.783\"],[\"79728.70\",\"0.232\"],[\"79768.10\",\"0.997\"],[\"79774.40\",\"2.003\"],[\"79812.00\",\"1.001\"],[\"79815.90\",\"3.087\"],[\"79963.40\",\"0.000\"],[\"79967.40\",\"0.000\"],[\"79995.80\",\"0.100\"],[\"79997.80\",\"0.000\"],[\"80323.70\",\"19.430\"],[\"80353.50\",\"3.039\"],[\"80403.30\",\"22.286\"],[\"80479.10\",\"0.009\"],[\"80562.50\",\"48.477\"],[\"87568.00\",\"0.000\"]],\"st\":1}}"}
{"receive_ns":1788563382381859000,"stream":"btcusdt@bookTicker","event_type":"bookTicker","event_time_ms":1788563382420,"raw_json":"{\"stream\":\"btcusdt@bookTicker\",\"data\":{\"e\":\"bookTicker\",\"u\":11478232774714,\"s\":\"BTCUSDT\",\"ps\":\"BTCUSDT\",\"b\":\"79607.10\",\"B\":\"5.587\",\"a\":\"79607.20\",\"A\":\"7.165\",\"T\":1788563382420,\"E\":1788563382420,\"st\":1}}"}
{"receive_ns":1788563382437840000,"stream":"btcusdt@depth@100ms","event_type":"depthUpdate","event_time_ms":1788563382473,"raw_json":"{\"stream\":\"btcusdt@depth@100ms\",\"data\":{\"e\":\"depthUpdate\",\"E\":1788563382473,\"T\":1788563382472,\"s\":\"BTCUSDT\",\"ps\":\"BTCUSDT\",\"U\":11478232772546,\"u\":11478232777986,\"pu\":11478232772459,\"b\":[[\"29307.10\",\"0.091\"],[\"29407.10\",\"1.834\"],[\"29507.10\",\"0.175\"],[\"71646.30\",\"0.002\"],[\"78811.00\",\"15.338\"],[\"79209.10\",\"3.726\"],[\"79232.90\",\"0.141\"],[\"79491.70\",\"0.232\"],[\"79559.30\",\"0.144\"],[\"79560.10\",\"10.003\"],[\"79561.40\",\"3.880\"],[\"79573.90\",\"0.002\"],[\"79574.70\",\"0.003\"],[\"79575.90\",\"0.455\"],[\"79579.90\",\"0.063\"],[\"79580.90\",\"0.028\"],[\"79581.90\",\"0.500\"],[\"79582.60\",\"2.331\"],[\"79583.20\",\"0.855\"],[\"79583.40\",\"0.006\"],[\"79583.70\",\"0.645\"],[\"79583.80\",\"0.001\"],[\"79589.20\",\"0.470\"],[\"79593.30\",\"0.001\"],[\"79593.90\",\"0.000\"],[\"79594.10\",\"0.000\"],[\"79602.70\",\"0.002\"],[\"79602.80\",\"0.000\"],[\"79604.30\",\"0.026\"],[\"79604.70\",\"0.001\"],[\"79604.80\",\"0.028\"],[\"79605.00\",\"0.630\"],[\"79605.40\",\"0.001\"],[\"79605.50\",\"0.002\"],[\"79606.90\",\"0.199\"],[\"79607.10\",\"5.587\"]],\"a\":[[\"79623.30\",\"0.458\"],[\"79624.40\",\"0.000\"],[\"79625.50\",\"0.458\"],[\"79668.10\",\"5.573\"],[\"79668.80\",\"0.315\"],[\"79774.40\",\"2.254\"],[\"79961.60\",\"0.120\"],[\"79963.40\",\"0.869\"],[\"79967.40\",\"0.090\"],[\"79995.80\",\"0.863\"],[\"79997.80\",\"0.525\"],[\"79999.30\",\"0.211\"],[\"80005.20\",\"3.754\"],[\"80177.90\",\"0.093\"],[\"80403.30\",\"22.286\"],[\"81199.30\",\"10.756\"]],\"st\":1}}"}
{"receive_ns":1788563382537641000,"stream":"btcusdt@depth@100ms","event_type":"depthUpdate","event_time_ms":1788563382575,"raw_json":"{\"stream\":\"btcusdt@depth@100ms\",\"data\":{\"e\":\"depthUpdate\",\"E\":1788563382575,\"T\":1788563382574,\"s\":\"BTCUSDT\",\"ps\":\"BTCUSDT\",\"U\":11478232778054,\"u\":11478232782091,\"pu\":11478232777986,\"b\":[[\"1000.00\",\"24.754\"],[\"29307.10\",\"0.147\"],[\"29407.10\",\"1.904\"],[\"29507.10\",\"0.049\"],[\"63685.70\",\"0.001\"],[\"63686.00\",\"0.000\"],[\"71646.30\",\"0.002\"],[\"76422.80\",\"0.002\"],[\"78170.60\",\"9.386\"],[\"78682.70\",\"2.286\"],[\"78729.60\",\"4.495\"],[\"78811.00\",\"15.338\"],[\"79574.70\",\"0.455\"],[\"79575.90\",\"0.003\"],[\"79579.90\",\"0.502\"],[\"79581.90\",\"0.061\"],[\"79583.70\",\"0.644\"],[\"79593.40\",\"0.078\"],[\"79602.90\",\"0.002\"],[\"79604.90\",\"0.026\"],[\"79605.00\",\"0.656\"]],\"a\":[[\"80363.50\",\"13.536\"],[\"80403.30\",\"22.286\"],[\"80562.50\",\"48.972\"],[\"80602.30\",\"10.684\"],[\"80721.70\",\"58.650\"],[\"80961.70\",\"0.000\"]],\"st\":1}}"}
{"receive_ns":1788563382556350000,"stream":"btcusdt@bookTicker","event_type":"bookTicker","event_time_ms":1788563382594,"raw_json":"{\"stream\":\"btcusdt@bookTicker\",\"data\":{\"e\":\"bookTicker\",\"u\":11478232782863,\"s\":\"BTCUSDT\",\"ps\":\"BTCUSDT\",\"b\":\"79607.10\",\"B\":\"5.047\",\"a\":\"79607.20\",\"A\":\"7.165\",\"T\":1788563382593,\"E\":1788563382594,\"st\":1}}"}
{"receive_ns":1788563382560306000,"stream":"btcusdt@bookTicker","event_type":"bookTicker","event_time_ms":1788563382597,"raw_json":"{\"stream\":\"btcusdt@bookTicker\",\"data\":{\"e\":\"bookTicker\",\"u\":11478232783020,\"s\":\"BTCUSDT\",\"ps\":\"BTCUSDT\",\"b\":\"79607.10\",\"B\":\"5.596\",\"a\":\"79607.20\",\"A\":\"7.165\",\"T\":1788563382597,\"E\":1788563382597,\"st\":1}}"}
{"receive_ns":1788563382560591000,"stream":"btcusdt@bookTicker","event_type":"bookTicker","event_time_ms":1788563382598,"raw_json":"{\"stream\":\"btcusdt@bookTicker\",\"data\":{\"e\":\"bookTicker\",\"u\":11478232783056,\"s\":\"BTCUSDT\",\"ps\":\"BTCUSDT\",\"b\":\"79607.10\",\"B\":\"5.594\",\"a\":\"79607.20\",\"A\":\"7.165\",\"T\":1788563382598,\"E\":1788563382598,\"st\":1}}"}
{"receive_ns":1788563382639574000,"stream":"btcusdt@depth@100ms","event_type":"depthUpdate","event_time_ms":1788563382677,"raw_json":"{\"stream\":\"btcusdt@depth@100ms\",\"data\":{\"e\":\"depthUpdate\",\"E\":1788563382677,\"T\":1788563382676,\"s\":\"BTCUSDT\",\"ps\":\"BTCUSDT\",\"U\":11478232782194,\"u\":11478232787045,\"pu\":11478232782091,\"b\":[[\"1000.00\",\"24.754\"],[\"29307.10\",\"0.273\"],[\"29407.10\",\"1.827\"],[\"29507.10\",\"0.000\"],[\"71646.30\",\"0.002\"],[\"76422.80\",\"0.000\"],[\"78727.70\",\"0.317\"],[\"78811.00\",\"15.338\"],[\"79033.90\",\"0.095\"],[\"79232.90\",\"0.141\"],[\"79491.70\",\"0.232\"],[\"79521.90\",\"0.363\"],[\"79537.80\",\"0.785\"],[\"79575.90\",\"0.001\"],[\"79583.20\",\"0.353\"],[\"79583.80\",\"2.009\"],[\"79589.20\",\"0.972\"],[\"79593.40\",\"0.002\"],[\"79602.80\",\"0.026\"],[\"79602.90\",\"0.028\"],[\"79604.30\",\"0.000\"],[\"79604.80\",\"0.002\"],[\"79604.90\",\"0.026\"],[\"79605.00\",\"0.630\"],[\"79605.50\",\"0.001\"],[\"79606.50\",\"0.036\"],[\"79606.90\",\"0.198\"],[\"79607.10\",\"5.594\"]],\"a\":[[\"79774.40\",\"2.003\"],[\"79963.40\",\"0.921\"],[\"79967.40\",\"0.289\"],[\"79995.80\",\"0.863\"],[\"79997.80\",\"0.525\"],[\"80403.30\",\"22.288\"],[\"80697.80\",\"2.966\"],[\"81199.30\",\"10.759\"]],\"st\":1}}"}
{"receive_ns":1788563382743553000,"stream":"btcusdt@depth@100ms","event_type":"depthUpdate","event_time_ms":1788563382779,"raw_json":"{\"stream\":\"btcusdt@depth@100ms\",\"data\":{\"e\":\"depthUpdate\",\"E\":1788563382779,\"T\":1788563382777,\"s\":\"BTCUSDT\",\"ps\":\"BTCUSDT\",\"U\":11478232787069,\"u\":11478232791441,\"pu\":11478232787045,\"b\":[[\"29307.10\",\"0.455\"],[\"29407.10\",\"1.645\"],[\"71646.30\",\"0.002\"],[\"75626.80\",\"0.012\"],[\"76422.80\",\"0.002\"],[\"78174.20\",\"1.470\"],[\"78532.40\",\"10.529\"],[\"78691.60\",\"11.528\"],[\"78811.00\",\"15.338\"],[\"79209.00\",\"0.000\"],[\"79209.10\",\"3.842\"],[\"79583.20\",\"0.353\"],[\"79583.70\",\"0.644\"],[\"79583.80\",\"0.001\"],[\"79589.20\",\"0.972\"]],\"a\":[[\"79705.70\",\"0.001\"],[\"79706.80\",\"0.125\"],[\"79707.30\",\"0.002\"],[\"79999.30\",\"0.211\"],[\"80005.30\",\"0.003\"],[\"80235.50\",\"0.001\"],[\"80320.60\",\"0.002\"],[\"80403.30\",\"22.286\"],[\"80638.50\",\"3.593\"],[\"83587.50\",\"0.021\"]],\"st\":1}}"}
{"receive_ns":1788563382843291000,"stream":"btcusdt@depth@100ms","event_type":"depthUpdate","event_time_ms":1788563382881,"raw_json":"{\"stream\":\"btcusdt@depth@100ms\",\"data\":{\"e\":\"depthUpdate\",\"E\":1788563382881,\"T\":1788563382877,\"s\":\"BTCUSDT\",\"ps\":\"BTCUSDT\",\"U\":11478232791534,\"u\":11478232798611,\"pu\":11478232791441,\"b\":[[\"1000.00\",\"24.754\"],[\"29307.10\",\"0.630\"],[\"29407.10\",\"1.470\"],[\"71646.30\",\"0.002\"],[\"76422.80\",\"0.000\"],[\"78476.70\",\"1.684\"],[\"78572.20\",\"30.686\"],[\"78739.40\",\"6.713\"],[\"78811.00\",\"15.338\"],[\"78890.60\",\"37.440\"],[\"79209.10\",\"3.968\"],[\"79232.90\",\"0.000\"],[\"79491.70\",\"0.000\"],[\"79535.40\",\"0.002\"],[\"79583.20\",\"0.253\"],[\"79589.20\",\"0.270\"]],\"a\":[[\"79608.00\",\"0.146\"],[\"79617.90\",\"0.000\"],[\"79706.30\",\"0.126\"],[\"79706.80\",\"0.000\"],[\"79742.60\",\"0.002\"],[\"79963.40\",\"0.000\"],[\"79967.40\",\"0.000\"],[\"79995.80\",\"0.100\"],[\"79997.80\",\"0.000\"],[\"80244.70\",\"0.560\"],[\"80403.30\",\"22.286\"],[\"80598.60\",\"13.579\"],[\"80769.50\",\"0.278\"]],\"st\":1}}"}
{"receive_ns":1788563382917842000,"stream":"btcusdt@bookTicker","event_type":"bookTicker","event_time_ms":1788563382946,"raw_json":"{\"stream\":\"btcusdt@bookTicker\",\"data\":{\"e\":\"bookTicker\",\"u\":11478232802668,\"s\":\"BTCUSDT\",\"ps\":\"BTCUSDT\",\"b\":\"79607.10\",\"B\":\"5.597\",\"a\":\"79607.20\",\"A\":\"7.165\",\"T\":1788563382946,\"E\":1788563382946,\"st\":1}}"}
{"receive_ns":1788563382946252000,"stream":"btcusdt@depth@100ms","event_type":"depthUpdate","event_time_ms":1788563382983,"raw_json":"{\"stream\":\"btcusdt@depth@100ms\",\"data\":{\"e\":\"depthUpdate\",\"E\":1788563382983,\"T\":1788563382981,\"s\":\"BTCUSDT\",\"ps\":\"BTCUSDT\",\"U\":11478232798824,\"u\":11478232804963,\"pu\":11478232798611,\"b\":[[\"1000.00\",\"24.754\"],[\"29307.10\",\"0.812\"],[\"29407.10\",\"1.288\"],[\"71646.30\",\"0.002\"],[\"78811.00\",\"15.338\"],[\"79232.90\",\"0.141\"],[\"79491.70\",\"0.483\"],[\"79583.20\",\"0.102\"],[\"79583.70\",\"0.645\"],[\"79583.80\",\"0.001\"],[\"79589.20\",\"0.972\"],[\"79604.40\",\"0.026\"],[\"79604.90\",\"0.000\"],[\"79607.00\",\"0.064\"],[\"79607.10\",\"5.597\"]],\"a\":[[\"79706.00\",\"0.196\"],[\"79706.10\",\"0.125\"],[\"79706.30\",\"0.001\"],[\"79963.40\",\"1.120\"],[\"79967.40\",\"0.090\"],[\"79995.80\",\"0.863\"],[\"79997.80\",\"0.525\"],[\"79999.30\",\"0.211\"],[\"80403.30\",\"22.286\"]],\"st\":1}}"}
{"receive_ns":1788563383026232000,"stream":"btcusdt@bookTicker","event_type":"bookTicker","event_time_ms":1788563383062,"raw_json":"{\"stream\":\"btcusdt@bookTicker\",\"data\":{\"e\":\"bookTicker\",\"u\":11478232811754,\"s\":\"BTCUSDT\",\"ps\":\"BTCUSDT\",\"b\":\"79607.10\",\"B\":\"5.597\",\"a\":\"79607.20\",\"A\":\"7.166\",\"T\":1788563383062,\"E\":1788563383062,\"st\":1}}"}
{"receive_ns":1788563383037707000,"stream":"btcusdt@bookTicker","event_type":"bookTicker","event_time_ms":1788563383071,"raw_json":"{\"stream\":\"btcusdt@bookTicker\",\"data\":{\"e\":\"bookTicker\",\"u\":11478232812372,\"s\":\"BTCUSDT\",\"ps\":\"BTCUSDT\",\"b\":\"79607.10\",\"B\":\"5.144\",\"a\":\"79607.20\",\"A\":\"7.166\",\"T\":1788563383071,\"E\":1788563383071,\"st\":1}}"}
{"receive_ns":1788563383037944000,"stream":"btcusdt@bookTicker","event_type":"bookTicker","event_time_ms":1788563383072,"raw_json":"{\"stream\":\"btcusdt@bookTicker\",\"data\":{\"e\":\"bookTicker\",\"u\":11478232812427,\"s\":\"BTCUSDT\",\"ps\":\"BTCUSDT\",\"b\":\"79607.10\",\"B\":\"5.146\",\"a\":\"79607.20\",\"A\":\"7.166\",\"T\":1788563383072,\"E\":1788563383072,\"st\":1}}"}
{"receive_ns":1788563383038214000,"stream":"btcusdt@bookTicker","event_type":"bookTicker","event_time_ms":1788563383074,"raw_json":"{\"stream\":\"btcusdt@bookTicker\",\"data\":{\"e\":\"bookTicker\",\"u\":11478232812524,\"s\":\"BTCUSDT\",\"ps\":\"BTCUSDT\",\"b\":\"79607.10\",\"B\":\"5.611\",\"a\":\"79607.20\",\"A\":\"7.166\",\"T\":1788563383074,\"E\":1788563383074,\"st\":1}}"}
{"receive_ns":1788563383048110000,"stream":"btcusdt@depth@100ms","event_type":"depthUpdate","event_time_ms":1788563383085,"raw_json":"{\"stream\":\"btcusdt@depth@100ms\",\"data\":{\"e\":\"depthUpdate\",\"E\":1788563383085,\"T\":1788563383083,\"s\":\"BTCUSDT\",\"ps\":\"BTCUSDT\",\"U\":11478232805261,\"u\":11478232812969,\"pu\":11478232804963,\"b\":[[\"29307.10\",\"0.987\"],[\"29407.10\",\"1.113\"],[\"71646.30\",\"0.002\"],[\"75626.70\",\"0.029\"],[\"75626.80\",\"0.014\"],[\"76422.80\",\"0.002\"],[\"78532.40\",\"11.164\"],[\"78811.00\",\"15.339\"],[\"79209.10\",\"3.968\"],[\"79443.70\",\"0.956\"],[\"79492.40\",\"0.099\"],[\"79574.70\",\"0.455\"],[\"79575.40\",\"0.000\"],[\"79575.90\",\"0.001\"],[\"79579.90\",\"0.502\"],[\"79581.90\",\"0.061\"],[\"79592.80\",\"0.004\"],[\"79593.60\",\"0.007\"],[\"79595.70\",\"0.001\"],[\"79596.30\",\"0.032\"],[\"79596.60\",\"0.002\"],[\"79602.80\",\"0.000\"],[\"79603.90\",\"0.027\"],[\"79604.00\",\"0.030\"],[\"79604.10\",\"1.026\"],[\"79604.40\",\"0.000\"],[\"79605.00\",\"0.630\"],[\"79606.50\",\"0.000\"],[\"79607.00\",\"0.063\"],[\"79607.10\",\"5.611\"]],\"a\":[[\"79607.20\",\"7.166\"],[\"79610.10\",\"0.006\"],[\"79611.20\",\"0.248\"],[\"79616.20\",\"0.082\"],[\"79618.30\",\"0.440\"],[\"79618.90\",\"0.076\"],[\"79619.00\",\"0.194\"],[\"79619.20\",\"0.026\"],[\"79619.30\",\"0.343\"],[\"79624.40\",\"0.452\"],[\"79625.50\",\"0.006\"],[\"79630.50\",\"0.665\"],[\"79677.70\",\"0.870\"],[\"79705.90\",\"0.000\"],[\"79706.10\",\"0.000\"],[\"79961.60\",\"0.272\"],[\"80403.30\",\"22.286\"],[\"80482.90\",\"19.915\"],[\"80562.50\",\"48.415\"]],\"st\":1}}"}
{"receive_ns":1788563383063356000,"stream":"btcusdt@bookTicker","event_type":"bookTicker","event_time_ms":1788563383100,"raw_json":"{\"stream\":\"btcusdt@bookTicker\",\"data\":{\"e\":\"bookTicker\",\"u\":11478232813833,\"s\":\"BTCUSDT\",\"ps\":\"BTCUSDT\",\"b\":\"79607.10\",\"B\":\"5.062\",\"a\":\"79607.20\",\"A\":\"7.166\",\"T\":1788563383099,\"E\":1788563383100,\"st\":1}}"}
{"receive_ns":1788563383064136000,"stream":"btcusdt@bookTicker","event_type":"bookTicker","event_time_ms":1788563383101,"raw_json":"{\"stream\":\"btcusdt@bookTicker\",\"data\":{\"e\":\"bookTicker\",\"u\":11478232813989,\"s\":\"BTCUSDT\",\"ps\":\"BTCUSDT\",\"b\":\"79607.10\",\"B\":\"5.060\",\"a\":\"79607.20\",\"A\":\"7.166\",\"T\":1788563383101,\"E\":1788563383101,\"st\":1}}"}
{"receive_ns":1788563383064510000,"stream":"btcusdt@bookTicker","event_type":"bookTicker","event_time_ms":1788563383102,"raw_json":"{\"stream\":\"btcusdt@bookTicker\",\"data\":{\"e\":\"bookTicker\",\"u\":11478232814081,\"s\":\"BTCUSDT\",\"ps\":\"BTCUSDT\",\"b\":\"79607.10\",\"B\":\"5.612\",\"a\":\"79607.20\",\"A\":\"7.166\",\"T\":1788563383102,\"E\":1788563383102,\"st\":1}}"}
{"receive_ns":1788563383065582000,"stream":"btcusdt@bookTicker","event_type":"bookTicker","event_time_ms":1788563383103,"raw_json":"{\"stream\":\"btcusdt@bookTicker\",\"data\":{\"e\":\"bookTicker\",\"u\":11478232814149,\"s\":\"BTCUSDT\",\"ps\":\"BTCUSDT\",\"b\":\"79607.10\",\"B\":\"5.614\",\"a\":\"79607.20\",\"A\":\"7.166\",\"T\":1788563383103,\"E\":1788563383103,\"st\":1}}"}
{"receive_ns":1788563383151108000,"stream":"btcusdt@depth@100ms","event_type":"depthUpdate","event_time_ms":1788563383187,"raw_json":"{\"stream\":\"btcusdt@depth@100ms\",\"data\":{\"e\":\"depthUpdate\",\"E\":1788563383187,\"T\":1788563383185,\"s\":\"BTCUSDT\",\"ps\":\"BTCUSDT\",\"U\":11478232813027,\"u\":11478232818372,\"pu\":11478232812969,\"b\":[[\"1000.00\",\"24.754\"],[\"29307.10\",\"1.169\"],[\"29407.10\",\"0.931\"],[\"63686.00\",\"0.000\"],[\"71646.30\",\"0.002\"],[\"76422.80\",\"0.000\"],[\"78269.70\",\"2.545\"],[\"78527.70\",\"1.952\"],[\"78811.00\",\"15.339\"],[\"79057.20\",\"0.001\"],[\"79209.10\",\"4.109\"],[\"79227.00\",\"0.262\"],[\"79231.60\",\"0.000\"],[\"79231.90\",\"0.166\"],[\"79232.90\",\"0.000\"],[\"79350.60\",\"0.000\"],[\"79351.90\",\"1.090\"],[\"79491.70\",\"0.100\"],[\"79549.90\",\"2.855\"],[\"79550.20\",\"0.034\"],[\"79576.20\",\"0.005\"],[\"79583.20\",\"0.002\"],[\"79583.80\",\"2.009\"],[\"79589.20\",\"0.897\"],[\"79589.30\",\"0.005\"],[\"79593.40\",\"0.078\"],[\"79596.30\",\"0.033\"],[\"79596.60\",\"0.001\"],[\"79602.90\",\"0.028\"],[\"79604.00\",\"0.004\"],[\"79604.10\",\"1.000\"],[\"79604.30\",\"0.000\"],[\"79604.70\",\"0.027\"],[\"79605.00\",\"0.656\"],[\"79606.70\",\"0.036\"],[\"79606.90\",\"0.199\"],[\"79607.10\",\"5.614\"]],\"a\":[[\"79626.10\",\"0.631\"],[\"79626.40\",\"0.062\"],[\"79637.80\",\"0.048\"],[\"79638.20\",\"0.830\"],[\"79648.50\",\"0.844\"],[\"79650.00\",\"3.172\"],[\"79650.30\",\"0.002\"],[\"79668.20\",\"2.949\"],[\"79668.80\",\"26.073\"],[\"79671.50\",\"0.002\"],[\"79705.90\",\"0.000\"],[\"79844.80\",\"0.907\"],[\"79847.80\",\"0.001\"],[\"79961.60\",\"0.120\"],[\"79963.40\",\"0.419\"],[\"79964.30\",\"0.828\"],[\"79967.40\",\"0.000\"],[\"79967.60\",\"0.000\"],[\"79987.30\",\"0.199\"],[\"79995.30\",\"0.594\"],[\"79995.80\",\"0.863\"],[\"79997.80\",\"0.525\"],[\"79999.30\",\"0.011\"],[\"80143.50\",\"0.001\"],[\"80403.30\",\"22.286\"]],\"st\":1}}"}
{"receive_ns":1788563383227901000,"stream":"btcusdt@bookTicker","event_type":"bookTicker","event_time_ms":1788563383264,"raw_json":"{\"stream\":\"btcusdt@bookTicker\",\"data\":{\"e\":\"bookTicker\",\"u\":11478232821509,\"s\":\"BTCUSDT\",\"ps\":\"BTCUSDT\",\"b\":\"79607.10\",\"B\":\"4.997\",\"a\":\"79607.20\",\"A\":\"7.166\",\"T\":1788563383264,\"E\":1788563383264,\"st\":1}}"}
{"receive_ns":1788563383231176000,"stream":"btcusdt@bookTicker","event_type":"bookTicker","event_time_ms":1788563383267,"raw_json":"{\"stream\":\"btcusdt@bookTicker\",\"data\":{\"e\":\"bookTicker\",\"u\":11478232821668,\"s\":\"BTCUSDT\",\"ps\":\"BTCUSDT\",\"b\":\"79607.10\",\"B\":\"5.626\",\"a\":\"79607.20\",\"A\":\"7.166\",\"T\":1788563383266,\"E\":1788563383267,\"st\":1}}"}
{"receive_ns":1788563383231501000,"stream":"btcusdt@bookTicker","event_type":"bookTicker","event_time_ms":1788563383268,"raw_json":"{\"stream\":\"btcusdt@bookTicker\",\"data\":{\"e\":\"bookTicker\",\"u\":11478232821709,\"s\":\"BTCUSDT\",\"ps\":\"BTCUSDT\",\"b\":\"79607.10\",\"B\":\"5.624\",\"a\":\"79607.20\",\"A\":\"7.166\",\"T\":1788563383268,\"E\":1788563383268,\"st\":1}}"}
{"receive_ns":1788563383256446000,"stream":"btcusdt@depth@100ms","event_type":"depthUpdate","event_time_ms":1788563383289,"raw_json":"{\"stream\":\"btcusdt@depth@100ms\",\"data\":{\"e\":\"depthUpdate\",\"E\":1788563383289,\"T\":1788563383286,\"s\":\"BTCUSDT\",\"ps\":\"BTCUSDT\",\"U\":11478232818443,\"u\":11478232822332,\"pu\":11478232818372,\"b\":[[\"1000.00\",\"24.754\"],[\"29307.10\",\"1.344\"],[\"29407.10\",\"0.756\"],[\"71646.30\",\"0.002\"],[\"76422.80\",\"0.002\"],[\"78811.00\",\"15.339\"],[\"78870.50\",\"0.208\"],[\"79034.50\",\"0.095\"],[\"79209.10\",\"3.983\"],[\"79443.60\",\"2.498\"],[\"79443.70\",\"0.001\"],[\"79483.00\",\"0.526\"],[\"79491.70\",\"0.351\"],[\"79583.80\",\"0.001\"],[\"79585.20\",\"0.153\"],[\"79589.20\",\"0.395\"],[\"79595.70\",\"0.001\"],[\"79596.30\",\"0.033\"],[\"79596.60\",\"0.001\"],[\"79602.90\",\"0.002\"],[\"79605.10\",\"0.026\"],[\"79606.70\",\"0.000\"],[\"79606.90\",\"0.198\"],[\"79607.10\",\"5.624\"]],\"a\":[[\"79621.60\",\"0.002\"],[\"79668.80\",\"26.074\"],[\"79706.20\",\"0.001\"],[\"79706.30\",\"0.001\"],[\"79728.70\",\"0.294\"],[\"79768.10\",\"1.330\"],[\"79993.90\",\"0.359\"],[\"79995.30\",\"0.794\"],[\"80228.00\",\"4.691\"],[\"80316.80\",\"1.865\"],[\"80323.70\",\"19.617\"],[\"80403.30\",\"22.286\"],[\"80523.50\",\"10.416\"],[\"80737.60\",\"2.368\"]],\"st\":1}}"}
{"receive_ns":1788563383273472000,"stream":"btcusdt@bookTicker","event_type":"bookTicker","event_time_ms":1788563383311,"raw_json":"{\"stream\":\"btcusdt@bookTicker\",\"data\":{\"e\":\"bookTicker\",\"u\":11478232823859,\"s\":\"BTCUSDT\",\"ps\":\"BTCUSDT\",\"b\":\"79607.10\",\"B\":\"4.462\",\"a\":\"79607.20\",\"A\":\"7.166\",\"T\":1788563383311,\"E\":1788563383311,\"st\":1}}"}
{"receive_ns":1788563383274050000,"stream":"btcusdt@bookTicker","event_type":"bookTicker","event_time_ms":1788563383312,"raw_json":"{\"stream\":\"btcusdt@bookTicker\",\"data\":{\"e\":\"bookTicker\",\"u\":11478232823910,\"s\":\"BTCUSDT\",\"ps\":\"BTCUSDT\",\"b\":\"79607.10\",\"B\":\"4.464\",\"a\":\"79607.20\",\"A\":\"7.166\",\"T\":1788563383312,\"E\":1788563383312,\"st\":1}}"}
{"receive_ns":1788563383275659000,"stream":"btcusdt@bookTicker","event_type":"bookTicker","event_time_ms":1788563383312,"raw_json":"{\"stream\":\"btcusdt@bookTicker\",\"data\":{\"e\":\"bookTicker\",\"u\":11478232823936,\"s\":\"BTCUSDT\",\"ps\":\"BTCUSDT\",\"b\":\"79607.10\",\"B\":\"4.463\",\"a\":\"79607.20\",\"A\":\"7.166\",\"T\":1788563383312,\"E\":1788563383312,\"st\":1}}"}
{"receive_ns":1788563383276068000,"stream":"btcusdt@bookTicker","event_type":"bookTicker","event_time_ms":1788563383313,"raw_json":"{\"stream\":\"btcusdt@bookTicker\",\"data\":{\"e\":\"bookTicker\",\"u\":11478232824008,\"s\":\"BTCUSDT\",\"ps\":\"BTCUSDT\",\"b\":\"79607.10\",\"B\":\"4.464\",\"a\":\"79607.20\",\"A\":\"7.166\",\"T\":1788563383313,\"E\":1788563383313,\"st\":1}}"}
{"receive_ns":1788563383283096000,"stream":"btcusdt@bookTicker","event_type":"bookTicker","event_time_ms":1788563383321,"raw_json":"{\"stream\":\"btcusdt@bookTicker\",\"data\":{\"e\":\"bookTicker\",\"u\":11478232824447,\"s\":\"BTCUSDT\",\"ps\":\"BTCUSDT\",\"b\":\"79607.10\",\"B\":\"5.627\",\"a\":\"79607.20\",\"A\":\"7.166\",\"T\":1788563383321,\"E\":1788563383321,\"st\":1}}"}
{"receive_ns":1788563383284428000,"stream":"btcusdt@bookTicker","event_type":"bookTicker","event_time_ms":1788563383322,"raw_json":"{\"stream\":\"btcusdt@bookTicker\",\"data\":{\"e\":\"bookTicker\",\"u\":11478232824526,\"s\":\"BTCUSDT\",\"ps\":\"BTCUSDT\",\"b\":\"79607.10\",\"B\":\"5.625\",\"a\":\"79607.20\",\"A\":\"7.166\",\"T\":1788563383322,\"E\":1788563383322,\"st\":1}}"}
{"receive_ns":1788563383292739000,"stream":"btcusdt@bookTicker","event_type":"bookTicker","event_time_ms":1788563383330,"raw_json":"{\"stream\":\"btcusdt@bookTicker\",\"data\":{\"e\":\"bookTicker\",\"u\":11478232824950,\"s\":\"BTCUSDT\",\"ps\":\"BTCUSDT\",\"b\":\"79607.10\",\"B\":\"4.350\",\"a\":\"79607.20\",\"A\":\"7.166\",\"T\":1788563383330,\"E\":1788563383330,\"st\":1}}"}
{"receive_ns":1788563383293915000,"stream":"btcusdt@bookTicker","event_type":"bookTicker","event_time_ms":1788563383331,"raw_json":"{\"stream\":\"btcusdt@bookTicker\",\"data\":{\"e\":\"bookTicker\",\"u\":11478232824990,\"s\":\"BTCUSDT\",\"ps\":\"BTCUSDT\",\"b\":\"79607.10\",\"B\":\"4.352\",\"a\":\"79607.20\",\"A\":\"7.166\",\"T\":1788563383331,\"E\":1788563383331,\"st\":1}}"}
{"receive_ns":1788563383297187000,"stream":"btcusdt@bookTicker","event_type":"bookTicker","event_time_ms":1788563383333,"raw_json":"{\"stream\":\"btcusdt@bookTicker\",\"data\":{\"e\":\"bookTicker\",\"u\":11478232825143,\"s\":\"BTCUSDT\",\"ps\":\"BTCUSDT\",\"b\":\"79607.10\",\"B\":\"5.628\",\"a\":\"79607.20\",\"A\":\"7.166\",\"T\":1788563383333,\"E\":1788563383333,\"st\":1}}"}
{"receive_ns":1788563383328898000,"stream":"btcusdt@bookTicker","event_type":"bookTicker","event_time_ms":1788563383366,"raw_json":"{\"stream\":\"btcusdt@bookTicker\",\"data\":{\"e\":\"bookTicker\",\"u\":11478232826576,\"s\":\"BTCUSDT\",\"ps\":\"BTCUSDT\",\"b\":\"79607.10\",\"B\":\"5.632\",\"a\":\"79607.20\",\"A\":\"7.166\",\"T\":1788563383365,\"E\":1788563383366,\"st\":1}}"}
{"receive_ns":1788563383354167000,"stream":"btcusdt@depth@100ms","event_type":"depthUpdate","event_time_ms":1788563383391,"raw_json":"{\"stream\":\"btcusdt@depth@100ms\",\"data\":{\"e\":\"depthUpdate\",\"E\":1788563383391,\"T\":1788563383389,\"s\":\"BTCUSDT\",\"ps\":\"BTCUSDT\",\"U\":11478232822453,\"u\":11478232827555,\"pu\":11478232822332,\"b\":[[\"29307.10\",\"1.526\"],[\"29407.10\",\"0.574\"],[\"63686.00\",\"0.000\"],[\"71646.30\",\"0.002\"],[\"71684.00\",\"0.003\"],[\"75626.80\",\"0.012\"],[\"76422.80\",\"0.000\"],[\"78015.00\",\"10.694\"],[\"78490.80\",\"2.797\"],[\"78583.60\",\"0.000\"],[\"78811.00\",\"15.339\"],[\"78843.80\",\"0.005\"],[\"78890.70\",\"0.648\"],[\"79000.10\",\"0.212\"],[\"79057.30\",\"0.010\"],[\"79209.10\",\"3.852\"],[\"79227.00\",\"0.030\"],[\"79231.70\",\"0.000\"],[\"79491.70\",\"0.251\"],[\"79583.00\",\"0.629\"],[\"79583.20\",\"0.504\"],[\"79583.70\",\"0.017\"],[\"79589.20\",\"0.195\"],[\"79595.40\",\"0.100\"],[\"79595.50\",\"0.033\"],[\"79596.30\",\"0.033\"],[\"79596.60\",\"0.001\"],[\"79603.00\",\"0.003\"],[\"79605.50\",\"0.001\"],[\"79606.10\",\"0.036\"],[\"79606.40\",\"0.003\"],[\"79606.90\",\"0.196\"],[\"79607.10\",\"5.632\"]],\"a\":[[\"79616.20\",\"0.082\"],[\"79618.20\",\"0.440\"],[\"79618.30\",\"0.001\"],[\"79706.10\",\"0.000\"],[\"79963.40\",\"0.000\"],[\"79967.50\",\"0.000\"],[\"79987.30\",\"0.419\"],[\"79993.90\",\"0.188\"],[\"79995.30\",\"0.202\"],[\"79995.80\",\"0.100\"],[\"79997.80\",\"0.000\"],[\"79999.90\",\"10.724\"],[\"80362.60\",\"0.001\"],[\"80403.30\",\"22.286\"],[\"80598.60\",\"13.430\"],[\"80627.80\",\"0.000\"]],\"st\":1}}"}
{"receive_ns":1788563383457850000,"stream":"btcusdt@depth@100ms","event_type":"depthUpdate","event_time_ms":1788563383493,"raw_json":"{\"stream\":\"btcusdt@depth@100ms\",\"data\":{\"e\":\"depthUpdate\",\"E\":1788563383493,\"T\":1788563383490,\"s\":\"BTCUSDT\",\"ps\":\"BTCUSDT\",\"U\":11478232827635,\"u\":11478232832406,\"pu\":11478232827555,\"b\":[[\"1000.00\",\"24.754\"],[\"29307.10\",\"1.701\"],[\"29407.10\",\"0.399\"],[\"71646.30\",\"0.002\"],[\"71684.00\",\"0.000\"],[\"78715.50\",\"0.203\"],[\"78811.00\",\"15.339\"],[\"79058.00\",\"57.422\"],[\"79209.10\",\"3.993\"],[\"79232.30\",\"45.289\"],[\"79235.90\",\"6.988\"],[\"79351.40\",\"36.495\"],[\"79351.90\",\"6.269\"],[\"79491.70\",\"0.332\"],[\"79543.70\",\"0.371\"],[\"79575.20\",\"0.947\"],[\"79580.90\",\"0.022\"],[\"79583.40\",\"0.006\"],[\"79583.80\",\"0.001\"],[\"79584.30\",\"0.006\"],[\"79585.20\",\"0.329\"],[\"79589.20\",\"0.470\"],[\"79604.00\",\"0.030\"],[\"79604.10\",\"1.026\"],[\"79604.60\",\"0.026\"],[\"79604.70\",\"0.001\"],[\"79605.00\",\"0.630\"],[\"79605.10\",\"0.000\"],[\"79605.50\",\"0.002\"]],\"a\":[[\"79623.30\",\"0.458\"],[\"79706.10\",\"0.125\"],[\"79848.00\",\"6.879\"],[\"79850.50\",\"37.066\"],[\"79970.30\",\"46.862\"],[\"79987.30\",\"1.210\"],[\"79995.30\",\"0.046\"],[\"79997.80\",\"1.288\"],[\"79999.30\",\"0.167\"],[\"80403.30\",\"22.286\"],[\"80562.50\",\"46.928\"],[\"80694.00\",\"1.503\"],[\"80911.60\",\"0.000\"]],\"st\":1}}"}
{"receive_ns":1788563383467210000,"stream":"btcusdt@bookTicker","event_type":"bookTicker","event_time_ms":1788563383503,"raw_json":"{\"stream\":\"btcusdt@bookTicker\",\"data\":{\"e\":\"bookTicker\",\"u\":11478232833045,\"s\":\"BTCUSDT\",\"ps\":\"BTCUSDT\",\"b\":\"79607.10\",\"B\":\"5.632\",\"a\":\"79607.20\",\"A\":\"7.168\",\"T\":1788563383503,\"E\":1788563383503,\"st\":1}}"}
{"receive_ns":1788563383496158000,"stream":"btcusdt@bookTicker","event_type":"bookTicker","event_time_ms":1788563383529,"raw_json":"{\"stream\":\"btcusdt@bookTicker\",\"data\":{\"e\":\"bookTicker\",\"u\":11478232834670,\"s\":\"BTCUSDT\",\"ps\":\"BTCUSDT\",\"b\":\"79607.10\",\"B\":\"5.207\",\"a\":\"79607.20\",\"A\":\"7.168\",\"T\":1788563383529,\"E\":1788563383529,\"st\":1}}"}
{"receive_ns":1788563383496771000,"stream":"btcusdt@bookTicker","event_type":"bookTicker","event_time_ms":1788563383530,"raw_json":"{\"stream\":\"btcusdt@bookTicker\",\"data\":{\"e\":\"bookTicker\",\"u\":11478232834703,\"s\":\"BTCUSDT\",\"ps\":\"BTCUSDT\",\"b\":\"79607.10\",\"B\":\"5.205\",\"a\":\"79607.20\",\"A\":\"7.168\",\"T\":1788563383530,\"E\":1788563383530,\"st\":1}}"}
{"receive_ns":1788563383502255000,"stream":"btcusdt@bookTicker","event_type":"bookTicker","event_time_ms":1788563383533,"raw_json":"{\"stream\":\"btcusdt@bookTicker\",\"data\":{\"e\":\"bookTicker\",\"u\":11478232834911,\"s\":\"BTCUSDT\",\"ps\":\"BTCUSDT\",\"b\":\"79607.10\",\"B\":\"5.633\",\"a\":\"79607.20\",\"A\":\"7.168\",\"T\":1788563383533,\"E\":1788563383533,\"st\":1}}"}
{"receive_ns":1788563383504831000,"stream":"btcusdt@bookTicker","event_type":"bookTicker","event_time_ms":1788563383534,"raw_json":"{\"stream\":\"btcusdt@bookTicker\",\"data\":{\"e\":\"bookTicker\",\"u\":11478232834993,\"s\":\"BTCUSDT\",\"ps\":\"BTCUSDT\",\"b\":\"79607.10\",\"B\":\"5.632\",\"a\":\"79607.20\",\"A\":\"7.168\",\"T\":1788563383534,\"E\":1788563383534,\"st\":1}}"}
{"receive_ns":1788563383505090000,"stream":"btcusdt@bookTicker","event_type":"bookTicker","event_time_ms":1788563383534,"raw_json":"{\"stream\":\"btcusdt@bookTicker\",\"data\":{\"e\":\"bookTicker\",\"u\":11478232835008,\"s\":\"BTCUSDT\",\"ps\":\"BTCUSDT\",\"b\":\"79607.10\",\"B\":\"5.634\",\"a\":\"79607.20\",\"A\":\"7.168\",\"T\":1788563383534,\"E\":1788563383534,\"st\":1}}"}
{"receive_ns":1788563383505353000,"stream":"btcusdt@bookTicker","event_type":"bookTicker","event_time_ms":1788563383535,"raw_json":"{\"stream\":\"btcusdt@bookTicker\",\"data\":{\"e\":\"bookTicker\",\"u\":11478232835072,\"s\":\"BTCUSDT\",\"ps\":\"BTCUSDT\",\"b\":\"79607.10\",\"B\":\"5.635\",\"a\":\"79607.20\",\"A\":\"7.168\",\"T\":1788563383535,\"E\":1788563383535,\"st\":1}}"}
{"receive_ns":1788563383567432000,"stream":"btcusdt@depth@100ms","event_type":"depthUpdate","event_time_ms":1788563383595,"raw_json":"{\"stream\":\"btcusdt@depth@100ms\",\"data\":{\"e\":\"depthUpdate\",\"E\":1788563383595,\"T\":1788563383594,\"s\":\"BTCUSDT\",\"ps\":\"BTCUSDT\",\"U\":11478232832562,\"u\":11478232837427,\"pu\":11478232832406,\"b\":[[\"1000.00\",\"24.754\"],[\"29207.10\",\"0.042\"],[\"29307.10\",\"1.799\"],[\"29407.10\",\"0.259\"],[\"63685.70\",\"0.001\"],[\"63686.00\",\"0.002\"],[\"71646.30\",\"0.002\"],[\"76422.80\",\"0.002\"],[\"78572.20\",\"31.576\"],[\"78731.40\",\"8.689\"],[\"78811.00\",\"15.339\"],[\"78844.60\",\"72.794\"],[\"79483.00\",\"0.526\"],[\"79511.50\",\"0.024\"],[\"79535.40\",\"0.000\"],[\"79593.40\",\"0.002\"],[\"79593.90\",\"0.076\"],[\"79595.70\",\"0.001\"],[\"79596.30\",\"0.032\"],[\"79596.60\",\"0.002\"],[\"79602.80\",\"0.026\"],[\"79602.90\",\"0.028\"],[\"79603.00\",\"0.029\"],[\"79603.90\",\"0.001\"],[\"79604.00\",\"0.004\"],[\"79604.10\",\"1.000\"],[\"79604.30\",\"0.026\"],[\"79604.60\",\"0.000\"],[\"79604.80\",\"0.028\"],[\"79607.10\",\"5.635\"]],\"a\":[[\"79607.20\",\"7.168\"],[\"79678.90\",\"0.015\"],[\"79728.70\",\"0.294\"],[\"79742.60\",\"0.000\"],[\"80403.30\",\"22.286\"],[\"80479.20\",\"1.742\"],[\"80562.50\",\"48.786\"],[\"80767.40\",\"2.346\"]],\"st\":1}}"}
{"receive_ns":1788563383668421000,"stream":"btcusdt@depth@100ms","event_type":"depthUpdate","event_time_ms":1788563383697,"raw_json":"{\"stream\":\"btcusdt@depth@100ms\",\"data\":{\"e\":\"depthUpdate\",\"E\":1788563383697,\"T\":1788563383693,\"s\":\"BTCUSDT\",\"ps\":\"BTCUSDT\",\"U\":11478232837479,\"u\":11478232842665,\"pu\":11478232837427,\"b\":[[\"29207.10\",\"0.105\"],[\"29307.10\",\"1.848\"],[\"29407.10\",\"0.147\"],[\"63686.00\",\"0.000\"],[\"71646.30\",\"0.002\"],[\"76422.80\",\"0.000\"],[\"78261.70\",\"1.537\"],[\"78284.70\",\"1.467\"],[\"78293.60\",\"5.026\"],[\"78476.70\",\"1.837\"],[\"78500.60\",\"8.348\"],[\"78811.00\",\"15.339\"],[\"78890.70\",\"0.000\"],[\"79000.10\",\"0.050\"],[\"79058.10\",\"0.648\"],[\"79209.10\",\"3.842\"],[\"79232.40\",\"0.162\"],[\"79232.90\",\"0.141\"],[\"79491.70\",\"0.000\"],[\"79579.90\",\"0.063\"],[\"79580.00\",\"0.445\"],[\"79581.90\",\"0.061\"],[\"79583.20\",\"0.585\"],[\"79585.20\",\"0.078\"],[\"79588.30\",\"0.000\"],[\"79589.00\",\"0.000\"],[\"79589.10\",\"0.001\"],[\"79589.20\",\"0.897\"],[\"79589.80\",\"0.010\"],[\"79589.90\",\"0.068\"],[\"79590.60\",\"0.329\"],[\"79591.10\",\"0.033\"],[\"79591.20\",\"1.306\"],[\"79593.60\",\"0.083\"],[\"79593.90\",\"0.000\"],[\"79594.20\",\"0.001\"],[\"79598.80\",\"0.004\"],[\"79604.30\",\"0.000\"],[\"79604.80\",\"0.002\"],[\"79605.00\",\"0.656\"],[\"79605.20\",\"0.028\"],[\"79605.30\",\"0.000\"]],\"a\":[[\"79705.90\",\"0.000\"],[\"79706.10\",\"0.000\"],[\"79969.40\",\"1.211\"],[\"79970.00\",\"1.434\"],[\"79970.20\",\"0.651\"],[\"79987.30\",\"0.000\"],[\"79995.30\",\"0.046\"],[\"79997.80\",\"0.525\"],[\"79999.30\",\"0.167\"],[\"79999.90\",\"10.076\"],[\"80403.30\",\"22.286\"],[\"80602.30\",\"10.895\"],[\"80767.40\",\"1.914\"],[\"80777.40\",\"9.200\"],[\"81036.50\",\"1.599\"]],\"st\":1}}"}
{"receive_ns":1788563383762332000,"stream":"btcusdt@depth@100ms","event_type":"depthUpdate","event_time_ms":1788563383799,"raw_json":"{\"stream\":\"btcusdt@depth@100ms\",\"data\":{\"e\":\"depthUpdate\",\"E\":1788563383799,\"T\":1788563383798,\"s\":\"BTCUSDT\",\"ps\":\"BTCUSDT\",\"U\":11478232842809,\"u\":11478232846994,\"pu\":11478232842665,\"b\":[[\"1000.00\",\"24.754\"],[\"29207.10\",\"0.161\"],[\"29307.10\",\"1.918\"],[\"29407.10\",\"0.021\"],[\"63686.00\",\"0.000\"],[\"71646.30\",\"0.002\"],[\"76422.80\",\"0.002\"],[\"78015.00\",\"10.697\"],[\"78811.00\",\"15.339\"],[\"78890.60\",\"38.326\"],[\"79588.30\",\"0.004\"],[\"79589.30\",\"0.067\"],[\"79589.90\",\"0.002\"],[\"79591.00\",\"0.346\"],[\"79591.30\",\"0.016\"],[\"79593.60\",\"0.007\"],[\"79598.80\",\"0.002\"],[\"79604.30\",\"0.026\"],[\"79605.00\",\"0.630\"],[\"79605.20\",\"0.002\"]],\"a\":[[\"79705.80\",\"4.776\"],[\"79706.20\",\"0.001\"],[\"80005.30\",\"0.001\"],[\"80403.30\",\"22.286\"],[\"80602.30\",\"11.081\"],[\"80920.70\",\"5.171\"]],\"st\":1}}"}
{"receive_ns":1788563383766018000,"stream":"btcusdt@bookTicker","event_type":"bookTicker","event_time_ms":1788563383803,"raw_json":"{\"stream\":\"btcusdt@bookTicker\",\"data\":{\"e\":\"bookTicker\",\"u\":11478232847277,\"s\":\"BTCUSDT\",\"ps\":\"BTCUSDT\",\"b\":\"79607.10\",\"B\":\"5.635\",\"a\":\"79607.20\",\"A\":\"7.156\",\"T\":1788563383803,\"E\":1788563383803,\"st\":1}}"}
{"receive_ns":1788563383871034000,"stream":"btcusdt@depth@100ms","event_type":"depthUpdate","event_time_ms":1788563383901,"raw_json":"{\"stream\":\"btcusdt@depth@100ms\",\"data\":{\"e\":\"depthUpdate\",\"E\":1788563383901,\"T\":1788563383900,\"s\":\"BTCUSDT\",\"ps\":\"BTCUSDT\",\"U\":11478232847066,\"u\":11478232852128,\"pu\":11478232846994,\"b\":[[\"1000.00\",\"24.754\"],[\"29207.10\",\"0.315\"],[\"29307.10\",\"1.785\"],[\"29407.10\",\"0.000\"],[\"71646.30\",\"0.002\"],[\"75626.70\",\"0.027\"],[\"75626.80\",\"0.014\"],[\"76422.90\",\"0.001\"],[\"78811.00\",\"15.339\"],[\"78986.30\",\"3.791\"],[\"79209.00\",\"0.002\"],[\"79232.90\",\"0.000\"],[\"79483.00\",\"0.000\"],[\"79522.20\",\"1.752\"],[\"79533.90\",\"23.397\"],[\"79535.40\",\"0.002\"],[\"79549.80\",\"0.691\"],[\"79583.20\",\"0.253\"],[\"79589.20\",\"0.697\"],[\"79595.70\",\"1.005\"],[\"79606.90\",\"0.198\"]],\"a\":[[\"79607.20\",\"7.156\"],[\"79705.90\",\"0.000\"],[\"79706.00\",\"0.321\"],[\"79728.70\",\"0.000\"],[\"79742.60\",\"0.002\"],[\"79969.40\",\"0.420\"],[\"79970.00\",\"1.434\"],[\"79997.80\",\"0.000\"],[\"80403.30\",\"22.288\"]],\"st\":1}}"}
{"receive_ns":1788563383972086000,"stream":"btcusdt@depth@100ms","event_type":"depthUpdate","event_time_ms":1788563384003,"raw_json":"{\"stream\":\"btcusdt@depth@100ms\",\"data\":{\"e\":\"depthUpdate\",\"E\":1788563384003,\"T\":1788563384001,\"s\":\"BTCUSDT\",\"ps\":\"BTCUSDT\",\"U\":11478232852145,\"u\":11478232856389,\"pu\":11478232852128,\"b\":[[\"29207.10\",\"0.497\"],[\"29307.10\",\"1.603\"],[\"63686.00\",\"0.000\"],[\"71646.30\",\"0.002\"],[\"76422.80\",\"0.000\"],[\"76700.00\",\"38.346\"],[\"78811.00\",\"15.339\"],[\"79209.10\",\"3.852\"],[\"79232.90\",\"0.141\"],[\"79443.60\",\"0.000\"],[\"79519.50\",\"0.000\"],[\"79519.90\",\"0.965\"],[\"79523.60\",\"0.126\"],[\"79547.40\",\"1.600\"],[\"79567.30\",\"0.005\"],[\"79581.30\",\"0.007\"],[\"79583.20\",\"0.585\"],[\"79584.30\",\"0.000\"],[\"79589.20\",\"0.772\"],[\"79591.20\",\"1.231\"],[\"79595.20\",\"0.550\"],[\"79595.70\",\"0.001\"]],\"a\":[[\"79639.20\",\"0.013\"],[\"79657.80\",\"0.001\"],[\"79685.00\",\"0.760\"],[\"79685.70\",\"0.001\"],[\"79768.10\",\"0.000\"],[\"79969.40\",\"1.211\"],[\"79995.30\",\"0.002\"],[\"79997.30\",\"0.149\"],[\"79997.80\",\"0.525\"],[\"79999.30\",\"0.167\"],[\"80244.10\",\"6.877\"],[\"80403.30\",\"22.286\"],[\"80482.90\",\"20.101\"],[\"80777.40\",\"9.632\"],[\"81040.10\",\"3.204\"]],\"st\":1}}"}
{"receive_ns":1788563384046305000,"stream":"btcusdt@bookTicker","event_type":"bookTicker","event_time_ms":1788563384083,"raw_json":"{\"stream\":\"btcusdt@bookTicker\",\"data\":{\"e\":\"bookTicker\",\"u\":11478232859605,\"s\":\"BTCUSDT\",\"ps\":\"BTCUSDT\",\"b\":\"79607.10\",\"B\":\"5.637\",\"a\":\"79607.20\",\"A\":\"7.156\",\"T\":1788563384082,\"E\":1788563384083,\"st\":1}}"}
{"receive_ns":1788563384056004000,"stream":"btcusdt@bookTicker","event_type":"bookTicker","event_time_ms":1788563384087,"raw_json":"{\"stream\":\"btcusdt@bookTicker\",\"data\":{\"e\":\"bookTicker\",\"u\":11478232859825,\"s\":\"BTCUSDT\",\"ps\":\"BTCUSDT\",\"b\":\"79607.10\",\"B\":\"5.641\",\"a\":\"79607.20\",\"A\":\"7.156\",\"T\":1788563384087,\"E\":1788563384087,\"st\":1}}"}
{"receive_ns":1788563384056267000,"stream":"btcusdt@bookTicker","event_type":"bookTicker","event_time_ms":1788563384088,"raw_json":"{\"stream\":\"btcusdt@bookTicker\",\"data\":{\"e\":\"bookTicker\",\"u\":11478232859904,\"s\":\"BTCUSDT\",\"ps\":\"BTCUSDT\",\"b\":\"79607.10\",\"B\":\"5.642\",\"a\":\"79607.20\",\"A\":\"7.156\",\"T\":1788563384088,\"E\":1788563384088,\"st\":1}}"}
{"receive_ns":1788563384068340000,"stream":"btcusdt@depth@100ms","event_type":"depthUpdate","event_time_ms":1788563384105,"raw_json":"{\"stream\":\"btcusdt@depth@100ms\",\"data\":{\"e\":\"depthUpdate\",\"E\":1788563384105,\"T\":1788563384102,\"s\":\"BTCUSDT\",\"ps\":\"BTCUSDT\",\"U\":11478232856460,\"u\":11478232860420,\"pu\":11478232856389,\"b\":[[\"1000.00\",\"24.754\"],[\"29207.10\",\"0.672\"],[\"29307.10\",\"1.428\"],[\"63686.00\",\"0.000\"],[\"71646.30\",\"0.002\"],[\"75626.80\",\"0.012\"],[\"76422.80\",\"0.002\"],[\"78015.00\",\"10.694\"],[\"78711.40\",\"0.003\"],[\"78811.00\",\"15.338\"],[\"78870.00\",\"0.094\"],[\"79443.60\",\"2.503\"],[\"79443.70\",\"1.005\"],[\"79471.70\",\"0.042\"],[\"79479.80\",\"0.340\"],[\"79479.90\",\"0.545\"],[\"79483.00\",\"0.526\"],[\"79589.20\",\"0.270\"],[\"79592.80\",\"0.004\"],[\"79593.80\",\"0.502\"],[\"79604.80\",\"0.002\"],[\"79607.10\",\"5.642\"]],\"a\":[[\"79645.40\",\"0.001\"],[\"79705.90\",\"0.125\"],[\"79706.00\",\"0.196\"],[\"79724.40\",\"0.686\"],[\"79725.10\",\"0.077\"],[\"79728.70\",\"0.294\"],[\"79768.10\",\"1.324\"],[\"79969.40\",\"0.792\"],[\"79969.60\",\"7.457\"],[\"80344.20\",\"0.003\"],[\"80403.30\",\"22.286\"],[\"81199.30\",\"10.753\"]],\"st\":1}}"}
{"receive_ns":1788563384171001000,"stream":"btcusdt@depth@100ms","event_type":"depthUpdate","event_time_ms":1788563384207,"raw_json":"{\"stream\":\"btcusdt@depth@100ms\",\"data\":{\"e\":\"depthUpdate\",\"E\":1788563384207,\"T\":1788563384205,\"s\":\"BTCUSDT\",\"ps\":\"BTCUSDT\",\"U\":11478232860548,\"u\":11478232864629,\"pu\":11478232860420,\"b\":[[\"1000.00\",\"24.754\"],[\"29207.10\",\"0.854\"],[\"29307.10\",\"1.246\"],[\"71646.30\",\"0.002\"],[\"76422.80\",\"0.000\"],[\"78811.00\",\"15.338\"],[\"79209.10\",\"1.962\"],[\"79211.10\",\"0.342\"],[\"79232.90\",\"0.141\"],[\"79491.70\",\"0.251\"],[\"79520.50\",\"6.000\"],[\"79523.90\",\"2.523\"],[\"79548.30\",\"3.500\"],[\"79551.70\",\"1.173\"],[\"79568.20\",\"0.540\"],[\"79573.90\",\"0.454\"],[\"79574.70\",\"0.003\"],[\"79583.00\",\"0.001\"],[\"79583.20\",\"0.334\"],[\"79583.80\",\"0.001\"],[\"79583.90\",\"0.688\"],[\"79589.20\",\"0.972\"],[\"79595.20\",\"0.350\"],[\"79596.30\",\"0.032\"],[\"79596.60\",\"0.001\"],[\"79597.00\",\"0.001\"],[\"79603.80\",\"0.029\"],[\"79604.30\",\"0.000\"],[\"79604.40\",\"0.026\"]],\"a\":[[\"79637.50\",\"3.081\"],[\"79637.60\",\"0.011\"],[\"79639.10\",\"0.457\"],[\"79659.00\",\"3.501\"],[\"79668.10\",\"1.857\"],[\"79668.20\",\"2.948\"],[\"79668.30\",\"0.166\"],[\"79668.80\",\"0.316\"],[\"79671.50\",\"25.734\"],[\"79676.90\",\"0.205\"],[\"79685.00\",\"1.558\"],[\"79686.90\",\"6.002\"],[\"79705.90\",\"0.000\"],[\"79732.00\",\"0.133\"],[\"79733.90\",\"0.001\"],[\"79812.00\",\"1.400\"],[\"79815.20\",\"3.012\"],[\"79817.70\",\"0.001\"],[\"79968.00\",\"0.867\"],[\"79969.40\",\"1.367\"],[\"79970.00\",\"0.671\"],[\"79997.30\",\"0.149\"],[\"79997.80\",\"0.525\"],[\"79999.30\",\"0.011\"],[\"80180.10\",\"0.093\"],[\"80403.30\",\"22.286\"]],\"st\":1}}"}
{"receive_ns":1788563384187312000,"stream":"btcusdt@bookTicker","event_type":"bookTicker","event_time_ms":1788563384223,"raw_json":"{\"stream\":\"btcusdt@bookTicker\",\"data\":{\"e\":\"bookTicker\",\"u\":11478232865239,\"s\":\"BTCUSDT\",\"ps\":\"BTCUSDT\",\"b\":\"79607.10\",\"B\":\"5.642\",\"a\":\"79607.20\",\"A\":\"7.155\",\"T\":1788563384223,\"E\":1788563384223,\"st\":1}}"}
{"receive_ns":1788563384187551000,"stream":"btcusdt@trade","event_type":"trade","event_time_ms":1788563384223,"raw_json":"{\"stream\":\"btcusdt@trade\",\"data\":{\"e\":\"trade\",\"E\":1788563384223,\"T\":1788563384223,\"s\":\"BTCUSDT\",\"t\":8054083453,\"p\":\"79607.20\",\"q\":\"0.001\",\"X\":\"MARKET\",\"m\":false,\"st\":1}}"}
{"receive_ns":1788563384272493000,"stream":"btcusdt@depth@100ms","event_type":"depthUpdate","event_time_ms":1788563384309,"raw_json":"{\"stream\":\"btcusdt@depth@100ms\",\"data\":{\"e\":\"depthUpdate\",\"E\":1788563384309,\"T\":1788563384305,\"s\":\"BTCUSDT\",\"ps\":\"BTCUSDT\",\"U\":11478232864679,\"u\":11478232869183,\"pu\":11478232864629,\"b\":[[\"29207.10\",\"1.029\"],[\"29307.10\",\"1.071\"],[\"71646.30\",\"0.002\"],[\"76422.80\",\"0.002\"],[\"78114.70\",\"0.000\"],[\"78373.20\",\"9.761\"],[\"78584.40\",\"89.076\"],[\"78691.60\",\"10.766\"],[\"78731.40\",\"8.879\"],[\"78811.00\",\"15.338\"],[\"79197.30\",\"0.194\"],[\"79198.90\",\"0.090\"],[\"79209.10\",\"1.962\"],[\"79480.70\",\"10.000\"],[\"79523.60\",\"0.001\"],[\"79573.90\",\"0.454\"],[\"79575.10\",\"0.739\"],[\"79580.00\",\"0.006\"],[\"79580.10\",\"0.445\"],[\"79581.90\",\"0.061\"],[\"79593.30\",\"0.077\"],[\"79604.40\",\"0.026\"]],\"a\":[[\"79607.20\",\"7.155\"],[\"79624.40\",\"0.000\"],[\"79625.50\",\"0.458\"],[\"79706.00\",\"0.196\"],[\"79706.30\",\"0.126\"],[\"79724.40\",\"1.946\"],[\"79725.00\",\"11.517\"],[\"80005.20\",\"3.629\"],[\"80146.20\",\"56.338\"],[\"80362.60\",\"72.154\"],[\"80403.30\",\"22.286\"],[\"80627.80\",\"90.571\"],[\"80960.50\",\"11.716\"]],\"st\":1}}"}
{"receive_ns":1788563384373559000,"stream":"btcusdt@depth@100ms","event_type":"depthUpdate","event_time_ms":1788563384411,"raw_json":"{\"stream\":\"btcusdt@depth@100ms\",\"data\":{\"e\":\"depthUpdate\",\"E\":1788563384411,\"T\":1788563384409,\"s\":\"BTCUSDT\",\"ps\":\"BTCUSDT\",\"U\":11478232869362,\"u\":11478232874759,\"pu\":11478232869183,\"b\":[[\"1000.00\",\"24.904\"],[\"29207.10\",\"1.211\"],[\"29307.10\",\"0.889\"],[\"63686.00\",\"0.000\"],[\"71646.30\",\"0.002\"],[\"78373.20\",\"10.653\"],[\"78489.10\",\"19.069\"],[\"78691.60\",\"11.528\"],[\"78811.00\",\"14.071\"],[\"78887.10\",\"17.849\"],[\"79232.90\",\"0.141\"],[\"79491.70\",\"0.232\"],[\"79524.20\",\"0.164\"],[\"79575.30\",\"0.174\"],[\"79583.20\",\"0.504\"],[\"79583.80\",\"2.009\"],[\"79589.00\",\"0.062\"],[\"79589.20\",\"0.395\"],[\"79589.30\",\"0.005\"],[\"79593.30\",\"0.001\"],[\"79604.40\",\"0.000\"],[\"79604.70\",\"0.027\"]],\"a\":[[\"79608.00\",\"0.466\"],[\"79609.30\",\"0.000\"],[\"79610.10\",\"0.004\"],[\"79610.70\",\"0.006\"],[\"79968.00\",\"0.867\"],[\"79969.40\",\"1.211\"],[\"79997.30\",\"0.105\"],[\"79997.80\",\"0.525\"],[\"80403.30\",\"22.286\"],[\"80829.50\",\"0.024\"]],\"st\":1}}"}
{"receive_ns":1788563384476443000,"stream":"btcusdt@depth@100ms","event_type":"depthUpdate","event_time_ms":1788563384513,"raw_json":"{\"stream\":\"btcusdt@depth@100ms\",\"data\":{\"e\":\"depthUpdate\",\"E\":1788563384513,\"T\":1788563384511,\"s\":\"BTCUSDT\",\"ps\":\"BTCUSDT\",\"U\":11478232874803,\"u\":11478232880311,\"pu\":11478232874759,\"b\":[[\"1000.00\",\"24.754\"],[\"29207.10\",\"1.386\"],[\"29307.10\",\"0.714\"],[\"71646.30\",\"0.002\"],[\"71684.00\",\"0.000\"],[\"76422.80\",\"0.000\"],[\"78452.80\",\"40.321\"],[\"78651.80\",\"52.159\"],[\"78811.00\",\"14.071\"],[\"78970.20\",\"7.747\"],[\"79209.10\",\"3.852\"],[\"79211.10\",\"0.557\"],[\"79491.70\",\"0.483\"],[\"79583.40\",\"0.006\"],[\"79583.80\",\"0.001\"],[\"79589.20\",\"0.470\"],[\"79604.70\",\"0.027\"]],\"a\":[[\"79623.30\",\"0.458\"],[\"79680.00\",\"0.095\"],[\"79706.20\",\"0.001\"],[\"79706.30\",\"0.001\"],[\"79969.40\",\"1.411\"],[\"80323.80\",\"1.741\"],[\"80403.30\",\"22.286\"],[\"80876.90\",\"0.001\"]],\"st\":1}}"}
{"receive_ns":1788563384498287000,"stream":"btcusdt@bookTicker","event_type":"bookTicker","event_time_ms":1788563384533,"raw_json":"{\"stream\":\"btcusdt@bookTicker\",\"data\":{\"e\":\"bookTicker\",\"u\":11478232881429,\"s\":\"BTCUSDT\",\"ps\":\"BTCUSDT\",\"b\":\"79607.10\",\"B\":\"5.384\",\"a\":\"79607.20\",\"A\":\"7.155\",\"T\":1788563384533,\"E\":1788563384533,\"st\":1}}"}
{"receive_ns":1788563384499421000,"stream":"btcusdt@bookTicker","event_type":"bookTicker","event_time_ms":1788563384536,"raw_json":"{\"stream\":\"btcusdt@bookTicker\",\"data\":{\"e\":\"bookTicker\",\"u\":11478232881651,\"s\":\"BTCUSDT\",\"ps\":\"BTCUSDT\",\"b\":\"79607.10\",\"B\":\"5.643\",\"a\":\"79607.20\",\"A\":\"7.155\",\"T\":1788563384536,\"E\":1788563384536,\"st\":1}}"}
{"receive_ns":1788563384500969000,"stream":"btcusdt@bookTicker","event_type":"bookTicker","event_time_ms":1788563384537,"raw_json":"{\"stream\":\"btcusdt@bookTicker\",\"data\":{\"e\":\"bookTicker\",\"u\":11478232881715,\"s\":\"BTCUSDT\",\"ps\":\"BTCUSDT\",\"b\":\"79607.10\",\"B\":\"5.641\",\"a\":\"79607.20\",\"A\":\"7.155\",\"T\":1788563384537,\"E\":1788563384537,\"st\":1}}"}
{"receive_ns":1788563384506446000,"stream":"btcusdt@bookTicker","event_type":"bookTicker","event_time_ms":1788563384542,"raw_json":"{\"stream\":\"btcusdt@bookTicker\",\"data\":{\"e\":\"bookTicker\",\"u\":11478232881970,\"s\":\"BTCUSDT\",\"ps\":\"BTCUSDT\",\"b\":\"79607.10\",\"B\":\"5.213\",\"a\":\"79607.20\",\"A\":\"7.155\",\"T\":1788563384541,\"E\":1788563384542,\"st\":1}}"}
{"receive_ns":1788563384507229000,"stream":"btcusdt@bookTicker","event_type":"bookTicker","event_time_ms":1788563384543,"raw_json":"{\"stream\":\"btcusdt@bookTicker\",\"data\":{\"e\":\"bookTicker\",\"u\":11478232882027,\"s\":\"BTCUSDT\",\"ps\":\"BTCUSDT\",\"b\":\"79607.10\",\"B\":\"5.215\",\"a\":\"79607.20\",\"A\":\"7.155\",\"T\":1788563384542,\"E\":1788563384543,\"st\":1}}"}
{"receive_ns":1788563384507796000,"stream":"btcusdt@bookTicker","event_type":"bookTicker","event_time_ms":1788563384545,"raw_json":"{\"stream\":\"btcusdt@bookTicker\",\"data\":{\"e\":\"bookTicker\",\"u\":11478232882150,\"s\":\"BTCUSDT\",\"ps\":\"BTCUSDT\",\"b\":\"79607.10\",\"B\":\"5.648\",\"a\":\"79607.20\",\"A\":\"7.155\",\"T\":1788563384544,\"E\":1788563384545,\"st\":1}}"}
{"receive_ns":1788563384578091000,"stream":"btcusdt@depth@100ms","event_type":"depthUpdate","event_time_ms":1788563384615,"raw_json":"{\"stream\":\"btcusdt@depth@100ms\",\"data\":{\"e\":\"depthUpdate\",\"E\":1788563384615,\"T\":1788563384614,\"s\":\"BTCUSDT\",\"ps\":\"BTCUSDT\",\"U\":11478232880466,\"u\":11478232885139,\"pu\":11478232880311,\"b\":[[\"29207.10\",\"1.568\"],[\"29307.10\",\"0.532\"],[\"63685.70\",\"0.001\"],[\"63686.00\",\"0.000\"],[\"71646.30\",\"0.002\"],[\"76422.80\",\"0.002\"],[\"78811.00\",\"14.071\"],[\"78970.20\",\"8.000\"],[\"79232.90\",\"0.000\"],[\"79395.80\",\"0.000\"],[\"79395.90\",\"4.955\"],[\"79443.60\",\"0.000\"],[\"79443.70\",\"1.239\"],[\"79483.00\",\"0.000\"],[\"79483.10\",\"0.394\"],[\"79491.70\",\"0.251\"],[\"79515.70\",\"1.171\"],[\"79515.80\",\"5.177\"],[\"79533.90\",\"22.568\"],[\"79549.80\",\"0.000\"],[\"79575.30\",\"0.074\"],[\"79583.00\",\"0.629\"],[\"79583.20\",\"0.504\"],[\"79583.90\",\"0.060\"],[\"79589.20\",\"0.270\"],[\"79596.30\",\"0.032\"],[\"79597.00\",\"0.001\"],[\"79607.10\",\"5.648\"]],\"a\":[[\"79697.80\",\"0.001\"],[\"79697.90\",\"4.183\"],[\"79706.30\",\"0.126\"],[\"79728.70\",\"0.169\"],[\"79768.10\",\"0.654\"],[\"79828.60\",\"7.225\"],[\"79968.00\",\"0.104\"],[\"79969.40\",\"0.620\"],[\"79997.80\",\"0.000\"],[\"80403.30\",\"22.286\"],[\"80602.30\",\"11.359\"],[\"80642.10\",\"32.182\"],[\"80876.90\",\"0.049\"],[\"80956.90\",\"3.019\"]],\"st\":1}}"}
{"receive_ns":1788563384591502000,"stream":"btcusdt@bookTicker","event_type":"bookTicker","event_time_ms":1788563384630,"raw_json":"{\"stream\":\"btcusdt@bookTicker\",\"data\":{\"e\":\"bookTicker\",\"u\":11478232885723,\"s\":\"BTCUSDT\",\"ps\":\"BTCUSDT\",\"b\":\"79607.10\",\"B\":\"5.652\",\"a\":\"79607.20\",\"A\":\"7.155\",\"T\":1788563384630,\"E\":1788563384630,\"st\":1}}"}
{"receive_ns":1788563384681459000,"stream":"btcusdt@depth@100ms","event_type":"depthUpdate","event_time_ms":1788563384717,"raw_json":"{\"stream\":\"btcusdt@depth@100ms\",\"data\":{\"e\":\"depthUpdate\",\"E\":1788563384717,\"T\":1788563384715,\"s\":\"BTCUSDT\",\"ps\":\"BTCUSDT\",\"U\":11478232885165,\"u\":11478232889556,\"pu\":11478232885139,\"b\":[[\"1000.00\",\"24.754\"],[\"29207.10\",\"1.743\"],[\"29307.10\",\"0.357\"],[\"71646.30\",\"0.002\"],[\"76422.80\",\"0.000\"],[\"78452.80\",\"40.346\"],[\"78651.80\",\"52.666\"],[\"78811.00\",\"14.071\"],[\"79232.90\",\"0.141\"],[\"79491.70\",\"0.483\"],[\"79583.00\",\"0.001\"],[\"79583.20\",\"0.604\"],[\"79583.80\",\"0.001\"],[\"79583.90\",\"0.688\"],[\"79589.20\",\"0.470\"],[\"79607.10\",\"5.652\"]],\"a\":[[\"79706.20\",\"0.001\"],[\"79706.30\",\"0.001\"],[\"79968.00\",\"0.867\"],[\"79969.40\",\"1.411\"],[\"79997.80\",\"0.525\"],[\"80403.30\",\"22.286\"],[\"80496.60\",\"0.000\"],[\"80839.50\",\"6.668\"],[\"81155.70\",\"0.000\"],[\"81199.30\",\"10.750\"]],\"st\":1}}"}
{"receive_ns":1788563384782621000,"stream":"btcusdt@depth@100ms","event_type":"depthUpdate","event_time_ms":1788563384819,"raw_json":"{\"stream\":\"btcusdt@depth@100ms\",\"data\":{\"e\":\"depthUpdate\",\"E\":1788563384819,\"T\":1788563384817,\"s\":\"BTCUSDT\",\"ps\":\"BTCUSDT\",\"U\":11478232889711,\"u\":11478232893684,\"pu\":11478232889556,\"b\":[[\"29107.10\",\"0.056\"],[\"29207.10\",\"1.813\"],[\"29307.10\",\"0.231\"],[\"71646.30\",\"0.002\"],[\"76422.80\",\"0.002\"],[\"78811.00\",\"14.071\"],[\"79209.00\",\"0.000\"],[\"79209.10\",\"3.852\"],[\"79471.70\",\"0.040\"],[\"79511.50\",\"0.022\"],[\"79535.40\",\"0.000\"],[\"79551.30\",\"0.003\"],[\"79567.20\",\"0.238\"],[\"79583.20\",\"0.602\"],[\"79593.30\",\"0.077\"],[\"79594.00\",\"0.005\"],[\"79602.80\",\"0.000\"],[\"79605.10\",\"0.026\"],[\"79606.90\",\"0.196\"]],\"a\":[[\"79616.20\",\"0.082\"],[\"79618.10\",\"0.440\"],[\"79618.20\",\"0.001\"],[\"79631.10\",\"0.040\"],[\"79647.10\",\"0.065\"],[\"79663.00\",\"0.000\"],[\"79678.90\",\"0.013\"],[\"79702.80\",\"0.008\"],[\"79706.20\",\"0.001\"],[\"79706.40\",\"0.002\"],[\"79706.50\",\"0.076\"],[\"79742.60\",\"0.000\"],[\"80005.20\",\"3.504\"],[\"80403.30\",\"22.286\"],[\"80562.50\",\"49.343\"]],\"st\":1}}"}
{"receive_ns":1788563384883623000,"stream":"btcusdt@depth@100ms","event_type":"depthUpdate","event_time_ms":1788563384921,"raw_json":"{\"stream\":\"btcusdt@depth@100ms\",\"data\":{\"e\":\"depthUpdate\",\"E\":1788563384921,\"T\":1788563384920,\"s\":\"BTCUSDT\",\"ps\":\"BTCUSDT\",\"U\":11478232893844,\"u\":11478232897494,\"pu\":11478232893684,\"b\":[[\"29107.10\",\"0.119\"],[\"29207.10\",\"1.862\"],[\"29307.10\",\"0.119\"],[\"63686.00\",\"0.000\"],[\"71646.30\",\"0.002\"],[\"78269.70\",\"3.055\"],[\"78811.00\",\"14.071\"],[\"79232.90\",\"0.141\"],[\"79491.70\",\"0.483\"],[\"79575.30\",\"0.174\"],[\"79579.90\",\"0.502\"],[\"79580.10\",\"0.006\"],[\"79581.90\",\"0.061\"],[\"79583.20\",\"0.000\"],[\"79583.80\",\"0.001\"],[\"79589.20\",\"0.972\"],[\"79590.60\",\"0.314\"],[\"79591.00\",\"0.328\"],[\"79591.30\",\"0.000\"],[\"79593.30\",\"0.001\"],[\"79596.30\",\"0.033\"],[\"79597.00\",\"0.000\"],[\"79602.60\",\"0.027\"],[\"79602.70\",\"0.028\"],[\"79602.80\",\"0.026\"],[\"79603.60\",\"1.519\"],[\"79603.70\",\"0.011\"],[\"79603.80\",\"0.003\"],[\"79604.00\",\"0.004\"],[\"79604.50\",\"0.026\"],[\"79604.70\",\"0.027\"],[\"79605.10\",\"0.000\"]],\"a\":[[\"79706.40\",\"0.002\"],[\"79706.50\",\"0.076\"],[\"79968.00\",\"0.867\"],[\"79969.40\",\"1.411\"],[\"79997.80\",\"0.525\"],[\"80005.30\",\"0.003\"],[\"80403.30\",\"22.286\"]],\"st\":1}}"}
{"receive_ns":1788563384932123000,"stream":"btcusdt@bookTicker","event_type":"bookTicker","event_time_ms":1788563384963,"raw_json":"{\"stream\":\"btcusdt@bookTicker\",\"data\":{\"e\":\"bookTicker\",\"u\":11478232899380,\"s\":\"BTCUSDT\",\"ps\":\"BTCUSDT\",\"b\":\"79607.10\",\"B\":\"5.187\",\"a\":\"79607.20\",\"A\":\"7.155\",\"T\":1788563384963,\"E\":1788563384963,\"st\":1}}"}
{"receive_ns":1788563384932334000,"stream":"btcusdt@bookTicker","event_type":"bookTicker","event_time_ms":1788563384964,"raw_json":"{\"stream\":\"btcusdt@bookTicker\",\"data\":{\"e\":\"bookTicker\",\"u\":11478232899462,\"s\":\"BTCUSDT\",\"ps\":\"BTCUSDT\",\"b\":\"79607.10\",\"B\":\"5.185\",\"a\":\"79607.20\",\"A\":\"7.155\",\"T\":1788563384964,\"E\":1788563384964,\"st\":1}}"}
{"receive_ns":1788563384932488000,"stream":"btcusdt@bookTicker","event_type":"bookTicker","event_time_ms":1788563384966,"raw_json":"{\"stream\":\"btcusdt@bookTicker\",\"data\":{\"e\":\"bookTicker\",\"u\":11478232899637,\"s\":\"BTCUSDT\",\"ps\":\"BTCUSDT\",\"b\":\"79607.10\",\"B\":\"5.652\",\"a\":\"79607.20\",\"A\":\"7.155\",\"T\":1788563384966,\"E\":1788563384966,\"st\":1}}"}
{"receive_ns":1788563384932670000,"stream":"btcusdt@bookTicker","event_type":"bookTicker","event_time_ms":1788563384968,"raw_json":"{\"stream\":\"btcusdt@bookTicker\",\"data\":{\"e\":\"bookTicker\",\"u\":11478232899735,\"s\":\"BTCUSDT\",\"ps\":\"BTCUSDT\",\"b\":\"79607.10\",\"B\":\"5.654\",\"a\":\"79607.20\",\"A\":\"7.155\",\"T\":1788563384968,\"E\":1788563384968,\"st\":1}}"}
{"receive_ns":1788563384985300000,"stream":"btcusdt@depth@100ms","event_type":"depthUpdate","event_time_ms":1788563385023,"raw_json":"{\"stream\":\"btcusdt@depth@100ms\",\"data\":{\"e\":\"depthUpdate\",\"E\":1788563385023,\"T\":1788563385019,\"s\":\"BTCUSDT\",\"ps\":\"BTCUSDT\",\"U\":11478232897554,\"u\":11478232902379,\"pu\":11478232897494,\"b\":[[\"1000.00\",\"24.754\"],[\"29107.10\",\"0.189\"],[\"29207.10\",\"1.897\"],[\"29307.10\",\"0.014\"],[\"63686.00\",\"0.000\"],[\"71646.30\",\"0.002\"],[\"76422.80\",\"0.000\"],[\"76422.90\",\"0.000\"],[\"78532.40\",\"11.672\"],[\"78568.40\",\"0.938\"],[\"78608.50\",\"11.886\"],[\"78811.00\",\"14.071\"],[\"79209.10\",\"3.978\"],[\"79483.10\",\"0.527\"],[\"79491.70\",\"0.232\"],[\"79523.50\",\"0.000\"],[\"79539.50\",\"0.125\"],[\"79579.20\",\"0.008\"],[\"79581.30\",\"0.001\"],[\"79583.00\",\"0.629\"],[\"79583.90\",\"0.060\"],[\"79596.30\",\"0.032\"],[\"79597.00\",\"0.001\"],[\"79607.10\",\"5.654\"]],\"a\":[[\"79706.60\",\"0.301\"],[\"79706.80\",\"0.125\"],[\"79728.70\",\"0.294\"],[\"80403.30\",\"22.286\"],[\"81199.30\",\"10.753\"]],\"st\":1}}"}
{"receive_ns":1788563385092743000,"stream":"btcusdt@depth@100ms","event_type":"depthUpdate","event_time_ms":1788563385125,"raw_json":"{\"stream\":\"btcusdt@depth@100ms\",\"data\":{\"e\":\"depthUpdate\",\"E\":1788563385125,\"T\":1788563385124,\"s\":\"BTCUSDT\",\"ps\":\"BTCUSDT\",\"U\":11478232902623,\"u\":11478232907593,\"pu\":11478232902379,\"b\":[[\"29107.10\",\"0.357\"],[\"29207.10\",\"1.743\"],[\"29307.10\",\"0.000\"],[\"63686.00\",\"0.000\"],[\"71646.30\",\"0.002\"],[\"76422.80\",\"0.002\"],[\"78394.60\",\"0.009\"],[\"78651.80\",\"51.143\"],[\"78811.00\",\"14.071\"],[\"78875.40\",\"0.946\"],[\"79209.10\",\"3.968\"],[\"79232.90\",\"0.141\"],[\"79381.20\",\"1.006\"],[\"79385.50\",\"0.000\"],[\"79387.90\",\"2.550\"],[\"79388.00\",\"1.850\"],[\"79443.80\",\"0.816\"],[\"79465.70\",\"0.076\"],[\"79482.30\",\"3.288\"],[\"79491.70\",\"0.000\"],[\"79575.30\",\"0.074\"],[\"79583.20\",\"0.332\"],[\"79583.80\",\"1.005\"],[\"79589.20\",\"0.697\"],[\"79589.80\",\"1.014\"],[\"79592.80\",\"0.004\"],[\"79604.50\",\"0.000\"],[\"79604.70\",\"0.001\"]],\"a\":[[\"79706.80\",\"0.000\"],[\"79706.90\",\"0.125\"],[\"79968.00\",\"0.867\"],[\"79969.40\",\"1.012\"],[\"79997.80\",\"0.525\"],[\"80005.20\",\"3.629\"],[\"80244.10\",\"6.379\"],[\"80403.30\",\"22.286\"],[\"80602.30\",\"11.508\"],[\"80697.80\",\"3.460\"],[\"80819.60\",\"0.000\"]],\"st\":1}}"}
{"receive_ns":1788563385190476000,"stream":"btcusdt@depth@100ms","event_type":"depthUpdate","event_time_ms":1788563385227,"raw_json":"{\"stream\":\"btcusdt@depth@100ms\",\"data\":{\"e\":\"depthUpdate\",\"E\":1788563385227,\"T\":1788563385225,\"s\":\"BTCUSDT\",\"ps\":\"BTCUSDT\",\"U\":11478232907673,\"u\":11478232911485,\"pu\":11478232907593,\"b\":[[\"29107.10\",\"0.539\"],[\"29207.10\",\"1.561\"],[\"34000.00\",\"0.975\"],[\"71646.30\",\"0.002\"],[\"75626.80\",\"0.010\"],[\"76422.80\",\"0.000\"],[\"78045.90\",\"0.004\"],[\"78811.00\",\"14.071\"],[\"79447.80\",\"0.000\"],[\"79491.70\",\"0.251\"],[\"79583.00\",\"0.001\"],[\"79583.20\",\"0.075\"],[\"79583.80\",\"0.001\"],[\"79583.90\",\"0.688\"],[\"79589.00\",\"0.000\"],[\"79589.20\",\"0.897\"],[\"79589.30\",\"0.067\"],[\"79589.60\",\"0.117\"],[\"79589.70\",\"0.020\"],[\"79589.80\",\"0.010\"],[\"79589.90\",\"0.002\"],[\"79596.30\",\"0.033\"],[\"79597.00\",\"0.000\"],[\"79602.50\",\"0.027\"],[\"79603.40\",\"0.000\"]],\"a\":[[\"79609.30\",\"0.252\"],[\"79609.40\",\"0.017\"],[\"79610.70\",\"0.004\"],[\"79679.90\",\"0.001\"],[\"79686.90\",\"6.000\"],[\"79706.70\",\"0.027\"],[\"79706.80\",\"0.000\"],[\"79706.90\",\"0.125\"],[\"79969.40\",\"1.411\"],[\"80323.70\",\"20.922\"],[\"80562.50\",\"50.830\"],[\"80598.60\",\"13.244\"]],\"st\":1}}"}
{"receive_ns":1788563385258211000,"stream":"btcusdt@bookTicker","event_type":"bookTicker","event_time_ms":1788563385287,"raw_json":"{\"stream\":\"btcusdt@bookTicker\",\"data\":{\"e\":\"bookTicker\",\"u\":11478232913945,\"s\":\"BTCUSDT\",\"ps\":\"BTCUSDT\",\"b\":\"79607.10\",\"B\":\"5.653\",\"a\":\"79607.20\",\"A\":\"7.155\",\"T\":1788563385286,\"E\":1788563385287,\"st\":1}}"}
{"receive_ns":1788563385291282000,"stream":"btcusdt@bookTicker","event_type":"bookTicker","event_time_ms":1788563385328,"raw_json":"{\"stream\":\"btcusdt@bookTicker\",\"data\":{\"e\":\"bookTicker\",\"u\":11478232915619,\"s\":\"BTCUSDT\",\"ps\":\"BTCUSDT\",\"b\":\"79607.10\",\"B\":\"4.490\",\"a\":\"79607.20\",\"A\":\"7.155\",\"T\":1788563385328,\"E\":1788563385328,\"st\":1}}"}
{"receive_ns":1788563385292323000,"stream":"btcusdt@depth@100ms","event_type":"depthUpdate","event_time_ms":1788563385329,"raw_json":"{\"stream\":\"btcusdt@depth@100ms\",\"data\":{\"e\":\"depthUpdate\",\"E\":1788563385329,\"T\":1788563385328,\"s\":\"BTCUSDT\",\"ps\":\"BTCUSDT\",\"U\":11478232911526,\"u\":11478232915619,\"pu\":11478232911485,\"b\":[[\"1000.00\",\"24.754\"],[\"29107.10\",\"0.707\"],[\"29207.10\",\"1.393\"],[\"71646.30\",\"0.002\"],[\"78373.20\",\"9.761\"],[\"78811.00\",\"14.071\"],[\"79543.60\",\"0.021\"],[\"79552.60\",\"0.000\"],[\"79582.90\",\"0.704\"],[\"79583.90\",\"0.060\"],[\"79589.20\",\"0.395\"],[\"79606.90\",\"0.198\"],[\"79607.10\",\"4.490\"]],\"a\":[[\"79627.80\",\"0.002\"],[\"79627.90\",\"0.045\"],[\"79706.90\",\"0.000\"],[\"79707.00\",\"0.603\"],[\"79707.40\",\"0.126\"],[\"79969.40\",\"0.992\"],[\"80019.60\",\"0.087\"],[\"80244.10\",\"6.877\"],[\"80403.30\",\"22.211\"],[\"80482.90\",\"20.287\"]],\"st\":1}}"}
{"receive_ns":1788563385302340000,"stream":"btcusdt@bookTicker","event_type":"bookTicker","event_time_ms":1788563385338,"raw_json":"{\"stream\":\"btcusdt@bookTicker\",\"data\":{\"e\":\"bookTicker\",\"u\":11478232916155,\"s\":\"BTCUSDT\",\"ps\":\"BTCUSDT\",\"b\":\"79607.10\",\"B\":\"5.655\",\"a\":\"79607.20\",\"A\":\"7.155\",\"T\":1788563385338,\"E\":1788563385338,\"st\":1}}"}
{"receive_ns":1788563385303194000,"stream":"btcusdt@bookTicker","event_type":"bookTicker","event_time_ms":1788563385339,"raw_json":"{\"stream\":\"btcusdt@bookTicker\",\"data\":{\"e\":\"bookTicker\",\"u\":11478232916216,\"s\":\"BTCUSDT\",\"ps\":\"BTCUSDT\",\"b\":\"79607.10\",\"B\":\"5.653\",\"a\":\"79607.20\",\"A\":\"7.155\",\"T\":1788563385339,\"E\":1788563385339,\"st\":1}}"}
{"receive_ns":1788563385303381000,"stream":"btcusdt@bookTicker","event_type":"bookTicker","event_time_ms":1788563385340,"raw_json":"{\"stream\":\"btcusdt@bookTicker\",\"data\":{\"e\":\"bookTicker\",\"u\":11478232916258,\"s\":\"BTCUSDT\",\"ps\":\"BTCUSDT\",\"b\":\"79607.10\",\"B\":\"5.653\",\"a\":\"79607.20\",\"A\":\"7.154\",\"T\":1788563385340,\"E\":1788563385340,\"st\":1}}"}
{"receive_ns":1788563385303558000,"stream":"btcusdt@trade","event_type":"trade","event_time_ms":1788563385340,"raw_json":"{\"stream\":\"btcusdt@trade\",\"data\":{\"e\":\"trade\",\"E\":1788563385340,\"T\":1788563385340,\"s\":\"BTCUSDT\",\"t\":8054083454,\"p\":\"79607.20\",\"q\":\"0.001\",\"X\":\"MARKET\",\"m\":false,\"st\":1}}"}
{"receive_ns":1788563385394709000,"stream":"btcusdt@depth@100ms","event_type":"depthUpdate","event_time_ms":1788563385431,"raw_json":"{\"stream\":\"btcusdt@depth@100ms\",\"data\":{\"e\":\"depthUpdate\",\"E\":1788563385431,\"T\":1788563385430,\"s\":\"BTCUSDT\",\"ps\":\"BTCUSDT\",\"U\":11478232915700,\"u\":11478232924476,\"pu\":11478232915619,\"b\":[[\"29107.10\",\"0.896\"],[\"29207.10\",\"1.204\"],[\"71646.30\",\"0.002\"],[\"76422.80\",\"0.002\"],[\"78811.00\",\"14.071\"],[\"79209.10\",\"3.968\"],[\"79232.90\",\"0.141\"],[\"79491.70\",\"0.583\"],[\"79573.90\",\"0.002\"],[\"79575.90\",\"0.453\"],[\"79579.90\",\"0.063\"],[\"79581.90\",\"0.500\"],[\"79582.90\",\"0.076\"],[\"79583.20\",\"0.502\"],[\"79583.70\",\"0.017\"],[\"79583.80\",\"0.001\"],[\"79583.90\",\"0.688\"],[\"79584.80\",\"0.270\"],[\"79588.90\",\"0.108\"],[\"79589.20\",\"0.470\"],[\"79589.30\",\"0.005\"],[\"79591.10\",\"0.005\"],[\"79592.20\",\"0.022\"],[\"79592.50\",\"0.001\"],[\"79593.60\",\"0.007\"],[\"79595.50\",\"0.033\"],[\"79596.30\",\"0.032\"],[\"79596.40\",\"0.255\"],[\"79596.60\",\"0.002\"],[\"79597.00\",\"0.000\"],[\"79597.30\",\"0.053\"],[\"79598.60\",\"0.002\"],[\"79602.50\",\"0.001\"],[\"79603.50\",\"0.003\"],[\"79604.10\",\"1.000\"],[\"79604.70\",\"0.001\"],[\"79607.10\",\"5.653\"]],\"a\":[[\"79607.20\",\"7.154\"],[\"79615.00\",\"0.037\"],[\"79615.10\",\"0.375\"],[\"79615.30\",\"0.001\"],[\"79616.20\",\"0.082\"],[\"79618.00\",\"0.486\"],[\"79618.10\",\"0.001\"],[\"79624.10\",\"0.045\"],[\"79625.50\",\"0.458\"],[\"79680.10\",\"1.758\"],[\"79694.50\",\"0.056\"],[\"79968.00\",\"0.867\"],[\"79969.40\",\"1.411\"],[\"79997.80\",\"0.525\"],[\"80337.00\",\"2.485\"],[\"80403.30\",\"22.211\"]],\"st\":1}}"}
{"receive_ns":1788563385432504000,"stream":"btcusdt@bookTicker","event_type":"bookTicker","event_time_ms":1788563385470,"raw_json":"{\"stream\":\"btcusdt@bookTicker\",\"data\":{\"e\":\"bookTicker\",\"u\":11478232926756,\"s\":\"BTCUSDT\",\"ps\":\"BTCUSDT\",\"b\":\"79607.10\",\"B\":\"5.186\",\"a\":\"79607.20\",\"A\":\"7.154\",\"T\":1788563385470,\"E\":1788563385470,\"st\":1}}"}
{"receive_ns":1788563385432753000,"stream":"btcusdt@bookTicker","event_type":"bookTicker","event_time_ms":1788563385471,"raw_json":"{\"stream\":\"btcusdt@bookTicker\",\"data\":{\"e\":\"bookTicker\",\"u\":11478232926790,\"s\":\"BTCUSDT\",\"ps\":\"BTCUSDT\",\"b\":\"79607.10\",\"B\":\"5.188\",\"a\":\"79607.20\",\"A\":\"7.154\",\"T\":1788563385471,\"E\":1788563385471,\"st\":1}}"}
{"receive_ns":1788563385433981000,"stream":"btcusdt@bookTicker","event_type":"bookTicker","event_time_ms":1788563385472,"raw_json":"{\"stream\":\"btcusdt@bookTicker\",\"data\":{\"e\":\"bookTicker\",\"u\":11478232926863,\"s\":\"BTCUSDT\",\"ps\":\"BTCUSDT\",\"b\":\"79607.10\",\"B\":\"5.188\",\"a\":\"79607.20\",\"A\":\"7.184\",\"T\":1788563385472,\"E\":1788563385472,\"st\":1}}"}
{"receive_ns":1788563385434974000,"stream":"btcusdt@bookTicker","event_type":"bookTicker","event_time_ms":1788563385473,"raw_json":"{\"stream\":\"btcusdt@bookTicker\",\"data\":{\"e\":\"bookTicker\",\"u\":11478232926898,\"s\":\"BTCUSDT\",\"ps\":\"BTCUSDT\",\"b\":\"79607.10\",\"B\":\"5.654\",\"a\":\"79607.20\",\"A\":\"7.184\",\"T\":1788563385473,\"E\":1788563385473,\"st\":1}}"}
{"receive_ns":1788563385438336000,"stream":"btcusdt@bookTicker","event_type":"bookTicker","event_time_ms":1788563385475,"raw_json":"{\"stream\":\"btcusdt@bookTicker\",\"data\":{\"e\":\"bookTicker\",\"u\":11478232927033,\"s\":\"BTCUSDT\",\"ps\":\"BTCUSDT\",\"b\":\"79607.10\",\"B\":\"5.654\",\"a\":\"79607.20\",\"A\":\"7.185\",\"T\":1788563385475,\"E\":1788563385475,\"st\":1}}"}
{"receive_ns":1788563385495993000,"stream":"btcusdt@depth@100ms","event_type":"depthUpdate","event_time_ms":1788563385533,"raw_json":"{\"stream\":\"btcusdt@depth@100ms\",\"data\":{\"e\":\"depthUpdate\",\"E\":1788563385533,\"T\":1788563385530,\"s\":\"BTCUSDT\",\"ps\":\"BTCUSDT\",\"U\":11478232924562,\"u\":11478232929523,\"pu\":11478232924476,\"b\":[[\"29107.10\",\"1.071\"],[\"29207.10\",\"1.029\"],[\"71646.30\",\"0.002\"],[\"71684.00\",\"0.000\"],[\"76422.80\",\"0.000\"],[\"78811.00\",\"14.071\"],[\"78970.20\",\"8.000\"],[\"79574.70\",\"0.455\"],[\"79575.90\",\"0.001\"],[\"79577.20\",\"0.008\"],[\"79579.20\",\"0.002\"],[\"79579.90\",\"0.502\"],[\"79581.90\",\"0.061\"],[\"79583.40\",\"0.006\"],[\"79588.70\",\"0.007\"],[\"79589.30\",\"0.001\"],[\"79592.20\",\"0.098\"],[\"79595.70\",\"0.001\"],[\"79596.60\",\"0.002\"],[\"79598.60\",\"0.000\"],[\"79603.50\",\"0.029\"],[\"79603.60\",\"1.545\"],[\"79607.10\",\"5.654\"]],\"a\":[[\"79607.20\",\"7.185\"],[\"79623.30\",\"0.458\"],[\"79642.60\",\"0.008\"],[\"79653.80\",\"0.124\"],[\"79707.20\",\"0.125\"],[\"79707.40\",\"0.001\"],[\"80403.30\",\"22.211\"]],\"st\":1}}"}
{"receive_ns":1788563385502459000,"stream":"btcusdt@bookTicker","event_type":"bookTicker","event_time_ms":1788563385539,"raw_json":"{\"stream\":\"btcusdt@bookTicker\",\"data\":{\"e\":\"bookTicker\",\"u\":11478232930106,\"s\":\"BTCUSDT\",\"ps\":\"BTCUSDT\",\"b\":\"79607.10\",\"B\":\"5.647\",\"a\":\"79607.20\",\"A\":\"7.185\",\"T\":1788563385539,\"E\":1788563385539,\"st\":1}}"}
{"receive_ns":1788563385513510000,"stream":"btcusdt@bookTicker","event_type":"bookTicker","event_time_ms":1788563385551,"raw_json":"{\"stream\":\"btcusdt@bookTicker\",\"data\":{\"e\":\"bookTicker\",\"u\":11478232930686,\"s\":\"BTCUSDT\",\"ps\":\"BTCUSDT\",\"b\":\"79607.10\",\"B\":\"5.018\",\"a\":\"79607.20\",\"A\":\"7.185\",\"T\":1788563385551,\"E\":1788563385551,\"st\":1}}"}
{"receive_ns":1788563385514853000,"stream":"btcusdt@bookTicker","event_type":"bookTicker","event_time_ms":1788563385552,"raw_json":"{\"stream\":\"btcusdt@bookTicker\",\"data\":{\"e\":\"bookTicker\",\"u\":11478232930732,\"s\":\"BTCUSDT\",\"ps\":\"BTCUSDT\",\"b\":\"79607.10\",\"B\":\"5.016\",\"a\":\"79607.20\",\"A\":\"7.185\",\"T\":1788563385552,\"E\":1788563385552,\"st\":1}}"}
{"receive_ns":1788563385515008000,"stream":"btcusdt@bookTicker","event_type":"bookTicker","event_time_ms":1788563385552,"raw_json":"{\"stream\":\"btcusdt@bookTicker\",\"data\":{\"e\":\"bookTicker\",\"u\":11478232930738,\"s\":\"BTCUSDT\",\"ps\":\"BTCUSDT\",\"b\":\"79607.10\",\"B\":\"5.015\",\"a\":\"79607.20\",\"A\":\"7.185\",\"T\":1788563385552,\"E\":1788563385552,\"st\":1}}"}
{"receive_ns":1788563385515201000,"stream":"btcusdt@bookTicker","event_type":"bookTicker","event_time_ms":1788563385553,"raw_json":"{\"stream\":\"btcusdt@bookTicker\",\"data\":{\"e\":\"bookTicker\",\"u\":11478232930816,\"s\":\"BTCUSDT\",\"ps\":\"BTCUSDT\",\"b\":\"79607.10\",\"B\":\"5.016\",\"a\":\"79607.20\",\"A\":\"7.185\",\"T\":1788563385553,\"E\":1788563385553,\"st\":1}}"}
{"receive_ns":1788563385515860000,"stream":"btcusdt@bookTicker","event_type":"bookTicker","event_time_ms":1788563385554,"raw_json":"{\"stream\":\"btcusdt@bookTicker\",\"data\":{\"e\":\"bookTicker\",\"u\":11478232930845,\"s\":\"BTCUSDT\",\"ps\":\"BTCUSDT\",\"b\":\"79607.10\",\"B\":\"5.647\",\"a\":\"79607.20\",\"A\":\"7.185\",\"T\":1788563385553,\"E\":1788563385554,\"st\":1}}"}
{"receive_ns":1788563385516926000,"stream":"btcusdt@bookTicker","event_type":"bookTicker","event_time_ms":1788563385555,"raw_json":"{\"stream\":\"btcusdt@bookTicker\",\"data\":{\"e\":\"bookTicker\",\"u\":11478232930894,\"s\":\"BTCUSDT\",\"ps\":\"BTCUSDT\",\"b\":\"79607.10\",\"B\":\"5.649\",\"a\":\"79607.20\",\"A\":\"7.185\",\"T\":1788563385554,\"E\":1788563385555,\"st\":1}}"}
{"receive_ns":1788563385597479000,"stream":"btcusdt@depth@100ms","event_type":"depthUpdate","event_time_ms":1788563385635,"raw_json":"{\"stream\":\"btcusdt@depth@100ms\",\"data\":{\"e\":\"depthUpdate\",\"E\":1788563385635,\"T\":1788563385633,\"s\":\"BTCUSDT\",\"ps\":\"BTCUSDT\",\"U\":11478232929837,\"u\":11478232934511,\"pu\":11478232929523,\"b\":[[\"1000.00\",\"24.754\"],[\"29107.10\",\"1.253\"],[\"29207.10\",\"0.847\"],[\"63685.70\",\"0.001\"],[\"71646.30\",\"0.002\"],[\"71646.40\",\"0.075\"],[\"76422.80\",\"0.002\"],[\"78373.20\",\"10.653\"],[\"78811.00\",\"14.071\"],[\"79232.90\",\"0.000\"],[\"79491.70\",\"0.583\"],[\"79582.90\",\"0.704\"],[\"79583.20\",\"0.502\"],[\"79583.80\",\"2.009\"],[\"79583.90\",\"0.060\"],[\"79589.20\",\"0.395\"],[\"79592.20\",\"0.022\"],[\"79595.70\",\"0.001\"],[\"79596.30\",\"0.033\"],[\"79596.60\",\"0.001\"],[\"79603.60\",\"1.519\"],[\"79607.10\",\"5.649\"]],\"a\":[[\"79707.20\",\"0.000\"],[\"79774.40\",\"2.254\"],[\"79968.00\",\"0.867\"],[\"79969.40\",\"0.666\"],[\"79997.80\",\"0.525\"],[\"80244.10\",\"7.624\"],[\"80320.00\",\"5.237\"],[\"80403.30\",\"22.211\"],[\"80678.20\",\"4.798\"]],\"st\":1}}"}
{"receive_ns":1788563385625982000,"stream":"btcusdt@bookTicker","event_type":"bookTicker","event_time_ms":1788563385662,"raw_json":"{\"stream\":\"btcusdt@bookTicker\",\"data\":{\"e\":\"bookTicker\",\"u\":11478232935579,\"s\":\"BTCUSDT\",\"ps\":\"BTCUSDT\",\"b\":\"79607.10\",\"B\":\"5.632\",\"a\":\"79607.20\",\"A\":\"7.185\",\"T\":1788563385662,\"E\":1788563385662,\"st\":1}}"}
{"receive_ns":1788563385628738000,"stream":"btcusdt@bookTicker","event_type":"bookTicker","event_time_ms":1788563385665,"raw_json":"{\"stream\":\"btcusdt@bookTicker\",\"data\":{\"e\":\"bookTicker\",\"u\":11478232935739,\"s\":\"BTCUSDT\",\"ps\":\"BTCUSDT\",\"b\":\"79607.10\",\"B\":\"5.651\",\"a\":\"79607.20\",\"A\":\"7.185\",\"T\":1788563385664,\"E\":1788563385665,\"st\":1}}"}
{"receive_ns":1788563385649263000,"stream":"btcusdt@bookTicker","event_type":"bookTicker","event_time_ms":1788563385686,"raw_json":"{\"stream\":\"btcusdt@bookTicker\",\"data\":{\"e\":\"bookTicker\",\"u\":11478232936785,\"s\":\"BTCUSDT\",\"ps\":\"BTCUSDT\",\"b\":\"79607.10\",\"B\":\"5.651\",\"a\":\"79607.20\",\"A\":\"7.186\",\"T\":1788563385686,\"E\":1788563385686,\"st\":1}}"}
{"receive_ns":1788563385701676000,"stream":"btcusdt@depth@100ms","event_type":"depthUpdate","event_time_ms":1788563385737,"raw_json":"{\"stream\":\"btcusdt@depth@100ms\",\"data\":{\"e\":\"depthUpdate\",\"E\":1788563385737,\"T\":1788563385735,\"s\":\"BTCUSDT\",\"ps\":\"BTCUSDT\",\"U\":11478232934590,\"u\":11478232938505,\"pu\":11478232934511,\"b\":[[\"29107.10\",\"1.428\"],[\"29207.10\",\"0.672\"],[\"71646.30\",\"0.002\"],[\"71646.40\",\"0.073\"],[\"76422.80\",\"0.000\"],[\"78015.00\",\"10.694\"],[\"78811.00\",\"14.071\"],[\"79209.10\",\"3.978\"],[\"79232.90\",\"0.141\"],[\"79583.80\",\"0.001\"],[\"79589.20\",\"0.470\"],[\"79592.20\",\"0.098\"],[\"79593.40\",\"0.078\"],[\"79602.60\",\"0.001\"],[\"79602.70\",\"0.002\"],[\"79603.60\",\"1.545\"],[\"79603.80\",\"0.029\"],[\"79604.40\",\"0.026\"],[\"79605.00\",\"0.656\"],[\"79607.10\",\"5.651\"]],\"a\":[[\"79607.20\",\"7.186\"],[\"79668.80\",\"0.316\"],[\"79671.50\",\"25.546\"],[\"79707.30\",\"0.002\"],[\"79774.40\",\"2.505\"],[\"79969.40\",\"0.909\"],[\"80403.30\",\"22.213\"]],\"st\":1}}"}
{"receive_ns":1788563385716679000,"stream":"btcusdt@bookTicker","event_type":"bookTicker","event_time_ms":1788563385752,"raw_json":"{\"stream\":\"btcusdt@bookTicker\",\"data\":{\"e\":\"bookTicker\",\"u\":11478232939148,\"s\":\"BTCUSDT\",\"ps\":\"BTCUSDT\",\"b\":\"79607.10\",\"B\":\"5.658\",\"a\":\"79607.20\",\"A\":\"7.186\",\"T\":1788563385752,\"E\":1788563385752,\"st\":1}}"}
{"receive_ns":1788563385801027000,"stream":"btcusdt@bookTicker","event_type":"bookTicker","event_time_ms":1788563385832,"raw_json":"{\"stream\":\"btcusdt@bookTicker\",\"data\":{\"e\":\"bookTicker\",\"u\":11478232945891,\"s\":\"BTCUSDT\",\"ps\":\"BTCUSDT\",\"b\":\"79607.10\",\"B\":\"5.658\",\"a\":\"79607.20\",\"A\":\"7.160\",\"T\":1788563385832,\"E\":1788563385832,\"st\":1}}"}
{"receive_ns":1788563385804083000,"stream":"btcusdt@depth@100ms","event_type":"depthUpdate","event_time_ms":1788563385839,"raw_json":"{\"stream\":\"btcusdt@depth@100ms\",\"data\":{\"e\":\"depthUpdate\",\"E\":1788563385839,\"T\":1788563385837,\"s\":\"BTCUSDT\",\"ps\":\"BTCUSDT\",\"U\":11478232938565,\"u\":11478232946525,\"pu\":11478232938505,\"b\":[[\"1000.00\",\"24.754\"],[\"29107.10\",\"1.610\"],[\"29207.10\",\"0.490\"],[\"71646.30\",\"0.002\"],[\"75626.80\",\"0.008\"],[\"78716.10\",\"0.190\"],[\"78811.00\",\"14.071\"],[\"79209.00\",\"0.002\"],[\"79447.80\",\"0.002\"],[\"79491.70\",\"0.000\"],[\"79562.10\",\"0.352\"],[\"79582.90\",\"0.628\"],[\"79583.20\",\"0.000\"],[\"79589.20\",\"0.270\"],[\"79594.60\",\"0.148\"],[\"79596.30\",\"0.032\"],[\"79597.00\",\"0.001\"],[\"79598.90\",\"0.002\"],[\"79602.80\",\"0.000\"],[\"79602.90\",\"0.002\"],[\"79603.00\",\"0.003\"],[\"79603.20\",\"0.003\"],[\"79603.30\",\"0.599\"],[\"79603.50\",\"0.003\"],[\"79603.60\",\"1.519\"],[\"79603.80\",\"0.003\"],[\"79605.60\",\"0.051\"],[\"79605.80\",\"0.027\"],[\"79605.90\",\"0.026\"],[\"79606.20\",\"0.029\"],[\"79606.30\",\"0.092\"],[\"79606.50\",\"0.026\"],[\"79606.60\",\"0.027\"],[\"79606.80\",\"0.030\"],[\"79607.10\",\"5.658\"]],\"a\":[[\"79607.20\",\"7.160\"],[\"79607.40\",\"2.601\"],[\"79609.30\",\"0.000\"],[\"79609.90\",\"0.000\"],[\"79616.20\",\"0.521\"],[\"79618.00\",\"0.047\"],[\"79628.50\",\"0.000\"],[\"79640.10\",\"0.080\"],[\"79669.90\",\"0.007\"],[\"79686.90\",\"6.002\"],[\"79707.10\",\"0.000\"],[\"79707.20\",\"0.000\"],[\"79707.30\",\"0.127\"],[\"79736.10\",\"0.000\"],[\"79774.40\",\"2.254\"],[\"79968.00\",\"0.104\"],[\"79969.40\",\"0.045\"],[\"79997.80\",\"0.000\"],[\"80005.30\",\"0.001\"],[\"80403.30\",\"22.211\"]],\"st\":1}}"}
{"receive_ns":1788563385838497000,"stream":"btcusdt@bookTicker","event_type":"bookTicker","event_time_ms":1788563385875,"raw_json":"{\"stream\":\"btcusdt@bookTicker\",\"data\":{\"e\":\"bookTicker\",\"u\":11478232949080,\"s\":\"BTCUSDT\",\"ps\":\"BTCUSDT\",\"b\":\"79607.10\",\"B\":\"5.658\",\"a\":\"79607.20\",\"A\":\"6.721\",\"T\":1788563385875,\"E\":1788563385875,\"st\":1}}"}
{"receive_ns":1788563385900757000,"stream":"btcusdt@bookTicker","event_type":"bookTicker","event_time_ms":1788563385938,"raw_json":"{\"stream\":\"btcusdt@bookTicker\",\"data\":{\"e\":\"bookTicker\",\"u\":11478232952811,\"s\":\"BTCUSDT\",\"ps\":\"BTCUSDT\",\"b\":\"79607.10\",\"B\":\"5.658\",\"a\":\"79607.20\",\"A\":\"7.162\",\"T\":1788563385938,\"E\":1788563385938,\"st\":1}}"}
{"receive_ns":1788563385903690000,"stream":"btcusdt@depth@100ms","event_type":"depthUpdate","event_time_ms":1788563385941,"raw_json":"{\"stream\":\"btcusdt@depth@100ms\",\"data\":{\"e\":\"depthUpdate\",\"E\":1788563385941,\"T\":1788563385939,\"s\":\"BTCUSDT\",\"ps\":\"BTCUSDT\",\"U\":11478232946607,\"u\":11478232952891,\"pu\":11478232946525,\"b\":[[\"1000.00\",\"24.754\"],[\"29107.10\",\"1.764\"],[\"29207.10\",\"0.329\"],[\"29507.10\",\"0.007\"],[\"71646.30\",\"0.002\"],[\"75626.70\",\"0.029\"],[\"76422.80\",\"0.002\"],[\"78452.80\",\"39.455\"],[\"78492.60\",\"52.061\"],[\"78651.80\",\"48.603\"],[\"78665.90\",\"1.772\"],[\"78811.00\",\"14.073\"],[\"79232.90\",\"0.141\"],[\"79491.70\",\"0.583\"],[\"79529.40\",\"0.003\"],[\"79577.20\",\"0.002\"],[\"79579.90\",\"0.502\"],[\"79581.00\",\"0.001\"],[\"79581.90\",\"0.061\"],[\"79582.10\",\"0.418\"],[\"79583.20\",\"0.577\"],[\"79583.30\",\"0.199\"],[\"79583.80\",\"0.001\"],[\"79589.20\",\"0.395\"],[\"79594.60\",\"0.072\"],[\"79596.60\",\"0.002\"],[\"79597.00\",\"0.000\"],[\"79604.80\",\"0.028\"],[\"79605.20\",\"0.028\"],[\"79605.30\",\"0.026\"],[\"79605.40\",\"0.027\"],[\"79605.50\",\"0.028\"],[\"79605.80\",\"0.001\"],[\"79605.90\",\"0.000\"],[\"79606.20\",\"0.003\"],[\"79606.30\",\"0.066\"],[\"79606.50\",\"0.000\"],[\"79606.60\",\"0.001\"],[\"79606.80\",\"0.004\"]],\"a\":[[\"79607.20\",\"7.162\"],[\"79607.30\",\"1.377\"],[\"79607.40\",\"2.627\"],[\"79609.40\",\"0.015\"],[\"79610.10\",\"0.004\"],[\"79610.70\",\"0.006\"],[\"79616.20\",\"0.082\"],[\"79618.30\",\"0.440\"],[\"79627.30\",\"0.080\"],[\"79640.10\",\"0.000\"],[\"79680.10\",\"1.744\"],[\"79689.50\",\"0.015\"],[\"79707.30\",\"0.127\"],[\"79707.50\",\"0.000\"],[\"79713.70\",\"0.130\"],[\"79774.40\",\"2.254\"],[\"79968.00\",\"0.867\"],[\"79969.40\",\"1.160\"],[\"79997.80\",\"0.525\"],[\"80244.10\",\"6.878\"],[\"80403.30\",\"22.211\"],[\"80638.50\",\"2.726\"]],\"st\":1}}"}
{"receive_ns":1788563385932078000,"stream":"btcusdt@bookTicker","event_type":"bookTicker","event_time_ms":1788563385969,"raw_json":"{\"stream\":\"btcusdt@bookTicker\",\"data\":{\"e\":\"bookTicker\",\"u\":11478232954534,\"s\":\"BTCUSDT\",\"ps\":\"BTCUSDT\",\"b\":\"79607.10\",\"B\":\"5.657\",\"a\":\"79607.20\",\"A\":\"7.162\",\"T\":1788563385969,\"E\":1788563385969,\"st\":1}}"}
{"receive_ns":1788563386000642000,"stream":"btcusdt@bookTicker","event_type":"bookTicker","event_time_ms":1788563386034,"raw_json":"{\"stream\":\"btcusdt@bookTicker\",\"data\":{\"e\":\"bookTicker\",\"u\":11478232957825,\"s\":\"BTCUSDT\",\"ps\":\"BTCUSDT\",\"b\":\"79607.10\",\"B\":\"5.657\",\"a\":\"79607.20\",\"A\":\"7.165\",\"T\":1788563386034,\"E\":1788563386034,\"st\":1}}"}
{"receive_ns":1788563386006153000,"stream":"btcusdt@depth@100ms","event_type":"depthUpdate","event_time_ms":1788563386043,"raw_json":"{\"stream\":\"btcusdt@depth@100ms\",\"data\":{\"e\":\"depthUpdate\",\"E\":1788563386043,\"T\":1788563386041,\"s\":\"BTCUSDT\",\"ps\":\"BTCUSDT\",\"U\":11478232952938,\"u\":11478232958254,\"pu\":11478232952891,\"b\":[[\"29107.10\",\"1.827\"],[\"29207.10\",\"0.203\"],[\"29507.10\",\"0.070\"],[\"71646.30\",\"0.002\"],[\"76422.80\",\"0.000\"],[\"77616.90\",\"0.965\"],[\"78118.40\",\"5.938\"],[\"78492.60\",\"50.153\"],[\"78651.80\",\"47.333\"],[\"78811.00\",\"15.338\"],[\"79209.10\",\"3.968\"],[\"79529.40\",\"0.001\"],[\"79533.60\",\"0.830\"],[\"79549.60\",\"0.691\"],[\"79569.10\",\"0.002\"],[\"79581.00\",\"0.374\"],[\"79582.10\",\"0.045\"],[\"79592.80\",\"0.008\"],[\"79598.90\",\"0.000\"],[\"79604.50\",\"0.026\"],[\"79604.60\",\"0.026\"],[\"79604.70\",\"0.027\"],[\"79605.40\",\"0.027\"],[\"79605.50\",\"0.002\"],[\"79605.60\",\"0.025\"],[\"79607.10\",\"5.657\"]],\"a\":[[\"79607.20\",\"7.165\"],[\"79609.80\",\"0.092\"],[\"79616.20\",\"0.082\"],[\"79618.30\",\"0.440\"],[\"79673.90\",\"0.003\"],[\"79707.30\",\"0.002\"],[\"79713.70\",\"0.128\"],[\"80005.20\",\"3.754\"],[\"80204.30\",\"3.736\"],[\"80244.10\",\"7.624\"],[\"80403.30\",\"22.211\"]],\"st\":1}}"}
{"receive_ns":1788563386017854000,"stream":"btcusdt@bookTicker","event_type":"bookTicker","event_time_ms":1788563386056,"raw_json":"{\"stream\":\"btcusdt@bookTicker\",\"data\":{\"e\":\"bookTicker\",\"u\":11478232958867,\"s\":\"BTCUSDT\",\"ps\":\"BTCUSDT\",\"b\":\"79607.10\",\"B\":\"5.026\",\"a\":\"79607.20\",\"A\":\"7.165\",\"T\":1788563386056,\"E\":1788563386056,\"st\":1}}"}
{"receive_ns":1788563386021449000,"stream":"btcusdt@bookTicker","event_type":"bookTicker","event_time_ms":1788563386060,"raw_json":"{\"stream\":\"btcusdt@bookTicker\",\"data\":{\"e\":\"bookTicker\",\"u\":11478232959081,\"s\":\"BTCUSDT\",\"ps\":\"BTCUSDT\",\"b\":\"79607.10\",\"B\":\"5.660\",\"a\":\"79607.20\",\"A\":\"7.165\",\"T\":1788563386059,\"E\":1788563386060,\"st\":1}}"}
{"receive_ns":1788563386022182000,"stream":"btcusdt@bookTicker","event_type":"bookTicker","event_time_ms":1788563386061,"raw_json":"{\"stream\":\"btcusdt@bookTicker\",\"data\":{\"e\":\"bookTicker\",\"u\":11478232959148,\"s\":\"BTCUSDT\",\"ps\":\"BTCUSDT\",\"b\":\"79607.10\",\"B\":\"5.658\",\"a\":\"79607.20\",\"A\":\"7.165\",\"T\":1788563386061,\"E\":1788563386061,\"st\":1}}"}
{"receive_ns":1788563386105896000,"stream":"btcusdt@depth@100ms","event_type":"depthUpdate","event_time_ms":1788563386145,"raw_json":"{\"stream\":\"btcusdt@depth@100ms\",\"data\":{\"e\":\"depthUpdate\",\"E\":1788563386145,\"T\":1788563386143,\"s\":\"BTCUSDT\",\"ps\":\"BTCUSDT\",\"U\":11478232958376,\"u\":11478232963069,\"pu\":11478232958254,\"b\":[[\"1000.00\",\"24.754\"],[\"29107.10\",\"1.876\"],[\"29207.10\",\"0.091\"],[\"29507.10\",\"0.133\"],[\"71646.30\",\"0.002\"],[\"76422.80\",\"0.002\"],[\"78651.80\",\"48.603\"],[\"78811.00\",\"15.338\"],[\"78890.60\",\"38.516\"],[\"78970.20\",\"6.735\"],[\"79209.10\",\"3.843\"],[\"79232.90\",\"0.141\"],[\"79491.70\",\"0.583\"],[\"79515.80\",\"4.616\"],[\"79515.90\",\"1.270\"],[\"79531.40\",\"0.033\"],[\"79533.60\",\"0.001\"],[\"79549.60\",\"0.000\"],[\"79567.20\",\"0.240\"],[\"79579.90\",\"0.063\"],[\"79580.00\",\"0.445\"],[\"79581.90\",\"0.061\"],[\"79582.90\",\"0.000\"],[\"79583.20\",\"0.504\"],[\"79583.80\",\"1.005\"],[\"79583.90\",\"0.688\"],[\"79589.20\",\"0.470\"],[\"79592.80\",\"0.004\"],[\"79594.60\",\"0.072\"],[\"79595.70\",\"0.001\"],[\"79596.60\",\"0.002\"],[\"79604.10\",\"1.026\"],[\"79604.30\",\"0.026\"],[\"79605.20\",\"0.002\"],[\"79605.30\",\"0.000\"],[\"79605.40\",\"0.001\"],[\"79606.00\",\"0.000\"],[\"79607.10\",\"5.658\"]],\"a\":[[\"79631.10\",\"0.042\"],[\"79647.10\",\"0.067\"],[\"79668.10\",\"5.534\"],[\"79668.20\",\"2.949\"],[\"79682.90\",\"0.004\"],[\"79707.40\",\"0.001\"],[\"79707.50\",\"0.000\"],[\"79738.60\",\"0.582\"],[\"79774.40\",\"2.003\"],[\"79968.00\",\"0.867\"],[\"79969.40\",\"1.411\"],[\"79997.80\",\"0.525\"],[\"80403.30\",\"22.211\"],[\"80718.10\",\"26.045\"]],\"st\":1}}"}
{"receive_ns":1788563386213077000,"stream":"btcusdt@depth@100ms","event_type":"depthUpdate","event_time_ms":1788563386247,"raw_json":"{\"stream\":\"btcusdt@depth@100ms\",\"data\":{\"e\":\"depthUpdate\",\"E\":1788563386247,\"T\":1788563386246,\"s\":\"BTCUSDT\",\"ps\":\"BTCUSDT\",\"U\":11478232963126,\"u\":11478232968613,\"pu\":11478232963069,\"b\":[[\"1000.00\",\"24.754\"],[\"29107.10\",\"1.876\"],[\"29207.10\",\"0.000\"],[\"29507.10\",\"0.224\"],[\"71646.30\",\"0.002\"],[\"78452.80\",\"40.346\"],[\"78492.60\",\"54.224\"],[\"78651.80\",\"51.143\"],[\"78675.70\",\"3.998\"],[\"78811.00\",\"15.338\"],[\"79421.00\",\"0.000\"],[\"79421.10\",\"3.140\"],[\"79423.40\",\"1.041\"],[\"79519.30\",\"0.000\"],[\"79519.40\",\"0.038\"],[\"79583.80\",\"0.001\"],[\"79593.40\",\"0.002\"],[\"79604.00\",\"0.030\"],[\"79604.30\",\"0.026\"],[\"79604.40\",\"0.000\"],[\"79604.50\",\"0.026\"],[\"79604.60\",\"0.026\"],[\"79604.70\",\"0.027\"],[\"79604.80\",\"0.028\"],[\"79604.90\",\"0.026\"],[\"79605.00\",\"0.630\"]],\"a\":[[\"79677.90\",\"0.002\"],[\"79694.50\",\"0.018\"],[\"79694.60\",\"0.039\"],[\"79707.60\",\"8.783\"],[\"79708.00\",\"0.003\"],[\"79744.20\",\"1.038\"],[\"79746.60\",\"0.002\"],[\"79747.90\",\"3.146\"],[\"80005.20\",\"1.758\"],[\"80403.30\",\"22.211\"]],\"st\":1}}"}
{"receive_ns":1788563386313217000,"stream":"btcusdt@depth@100ms","event_type":"depthUpdate","event_time_ms":1788563386349,"raw_json":"{\"stream\":\"btcusdt@depth@100ms\",\"data\":{\"e\":\"depthUpdate\",\"E\":1788563386349,\"T\":1788563386347,\"s\":\"BTCUSDT\",\"ps\":\"BTCUSDT\",\"U\":11478232968667,\"u\":11478232973983,\"pu\":11478232968613,\"b\":[[\"29107.10\",\"1.701\"],[\"29507.10\",\"0.399\"],[\"71646.30\",\"0.002\"],[\"76422.80\",\"0.000\"],[\"78691.60\",\"10.766\"],[\"78811.00\",\"15.338\"],[\"78883.90\",\"1.899\"],[\"79209.10\",\"3.843\"],[\"79543.60\",\"0.007\"],[\"79553.10\",\"0.099\"],[\"79583.20\",\"0.504\"],[\"79589.20\",\"0.270\"],[\"79593.50\",\"0.081\"],[\"79605.10\",\"0.026\"],[\"79606.90\",\"0.196\"]],\"a\":[[\"79668.80\",\"25.860\"],[\"79671.50\",\"0.002\"],[\"79707.20\",\"0.125\"],[\"79707.30\",\"0.002\"],[\"79707.60\",\"8.783\"],[\"79828.60\",\"7.394\"],[\"79968.00\",\"0.104\"],[\"79969.40\",\"1.212\"],[\"80403.30\",\"22.211\"],[\"80498.60\",\"0.186\"],[\"80752.40\",\"2.474\"],[\"81159.50\",\"1.304\"]],\"st\":1}}"}
{"receive_ns":1788563386381068000,"stream":"btcusdt@bookTicker","event_type":"bookTicker","event_time_ms":1788563386418,"raw_json":"{\"stream\":\"btcusdt@bookTicker\",\"data\":{\"e\":\"bookTicker\",\"u\":11478232977054,\"s\":\"BTCUSDT\",\"ps\":\"BTCUSDT\",\"b\":\"79607.10\",\"B\":\"5.659\",\"a\":\"79607.20\",\"A\":\"7.165\",\"T\":1788563386418,\"E\":1788563386418,\"st\":1}}"}
{"receive_ns":1788563386415741000,"stream":"btcusdt@depth@100ms","event_type":"depthUpdate","event_time_ms":1788563386451,"raw_json":"{\"stream\":\"btcusdt@depth@100ms\",\"data\":{\"e\":\"depthUpdate\",\"E\":1788563386451,\"T\":1788563386450,\"s\":\"BTCUSDT\",\"ps\":\"BTCUSDT\",\"U\":11478232974040,\"u\":11478232978726,\"pu\":11478232973983,\"b\":[[\"1000.00\",\"24.754\"],[\"29107.10\",\"1.519\"],[\"29507.10\",\"0.581\"],[\"63686.00\",\"0.000\"],[\"71600.00\",\"7.270\"],[\"71646.30\",\"0.002\"],[\"76422.80\",\"0.002\"],[\"78452.80\",\"39.455\"],[\"78811.00\",\"15.338\"],[\"78970.20\",\"7.241\"],[\"79205.50\",\"0.125\"],[\"79207.10\",\"0.000\"],[\"79207.70\",\"0.228\"],[\"79232.90\",\"0.141\"],[\"79395.90\",\"0.000\"],[\"79443.70\",\"0.001\"],[\"79483.10\",\"0.001\"],[\"79491.70\",\"0.583\"],[\"79581.80\",\"2.879\"],[\"79583.80\",\"0.001\"],[\"79589.20\",\"0.470\"],[\"79593.50\",\"0.005\"],[\"79597.30\",\"0.054\"],[\"79604.50\",\"0.026\"],[\"79604.60\",\"0.026\"],[\"79604.70\",\"0.027\"],[\"79604.80\",\"0.002\"],[\"79604.90\",\"0.026\"],[\"79605.00\",\"0.656\"],[\"79605.10\",\"0.000\"],[\"79607.10\",\"5.659\"]],\"a\":[[\"79668.80\",\"0.316\"],[\"79676.90\",\"25.749\"],[\"79728.70\",\"0.000\"],[\"79768.10\",\"0.000\"],[\"79815.90\",\"0.012\"],[\"79968.00\",\"0.867\"],[\"79969.40\",\"1.411\"],[\"79997.80\",\"0.525\"],[\"80005.20\",\"3.629\"],[\"80403.30\",\"22.211\"],[\"80960.50\",\"11.963\"]],\"st\":1}}"}
{"receive_ns":1788563386438999000,"stream":"btcusdt@bookTicker","event_type":"bookTicker","event_time_ms":1788563386476,"raw_json":"{\"stream\":\"btcusdt@bookTicker\",\"data\":{\"e\":\"bookTicker\",\"u\":11478232980055,\"s\":\"BTCUSDT\",\"ps\":\"BTCUSDT\",\"b\":\"79607.10\",\"B\":\"5.193\",\"a\":\"79607.20\",\"A\":\"7.165\",\"T\":1788563386476,\"E\":1788563386476,\"st\":1}}"}
{"receive_ns":1788563386439226000,"stream":"btcusdt@bookTicker","event_type":"bookTicker","event_time_ms":1788563386477,"raw_json":"{\"stream\":\"btcusdt@bookTicker\",\"data\":{\"e\":\"bookTicker\",\"u\":11478232980109,\"s\":\"BTCUSDT\",\"ps\":\"BTCUSDT\",\"b\":\"79607.10\",\"B\":\"5.195\",\"a\":\"79607.20\",\"A\":\"7.165\",\"T\":1788563386477,\"E\":1788563386477,\"st\":1}}"}
{"receive_ns":1788563386442658000,"stream":"btcusdt@bookTicker","event_type":"bookTicker","event_time_ms":1788563386478,"raw_json":"{\"stream\":\"btcusdt@bookTicker\",\"data\":{\"e\":\"bookTicker\",\"u\":11478232980223,\"s\":\"BTCUSDT\",\"ps\":\"BTCUSDT\",\"b\":\"79607.10\",\"B\":\"5.664\",\"a\":\"79607.20\",\"A\":\"7.165\",\"T\":1788563386478,\"E\":1788563386478,\"st\":1}}"}
{"receive_ns":1788563386518047000,"stream":"btcusdt@depth@100ms","event_type":"depthUpdate","event_time_ms":1788563386553,"raw_json":"{\"stream\":\"btcusdt@depth@100ms\",\"data\":{\"e\":\"depthUpdate\",\"E\":1788563386553,\"T\":1788563386549,\"s\":\"BTCUSDT\",\"ps\":\"BTCUSDT\",\"U\":11478232978857,\"u\":11478232984245,\"pu\":11478232978726,\"b\":[[\"1000.00\",\"24.754\"],[\"29107.10\",\"1.344\"],[\"29507.10\",\"0.756\"],[\"71646.30\",\"0.002\"],[\"71684.00\",\"0.000\"],[\"75626.80\",\"0.006\"],[\"76422.80\",\"0.000\"],[\"78811.00\",\"15.338\"],[\"79515.80\",\"3.321\"],[\"79583.20\",\"0.002\"],[\"79583.40\",\"0.006\"],[\"79603.70\",\"0.037\"],[\"79603.80\",\"0.029\"],[\"79603.90\",\"0.027\"],[\"79604.70\",\"0.001\"],[\"79604.90\",\"0.000\"],[\"79605.00\",\"0.630\"],[\"79607.10\",\"5.664\"]],\"a\":[[\"79623.30\",\"0.458\"],[\"79668.10\",\"1.857\"],[\"79668.20\",\"2.948\"],[\"79671.50\",\"25.490\"],[\"79676.90\",\"0.205\"],[\"79697.90\",\"4.179\"],[\"79706.90\",\"0.000\"],[\"79707.20\",\"0.000\"],[\"79828.60\",\"8.494\"],[\"79969.40\",\"0.992\"],[\"80403.30\",\"22.211\"],[\"80777.10\",\"0.000\"]],\"st\":1}}"}
{"receive_ns":1788563386596973000,"stream":"btcusdt@bookTicker","event_type":"bookTicker","event_time_ms":1788563386632,"raw_json":"{\"stream\":\"btcusdt@bookTicker\",\"data\":{\"e\":\"bookTicker\",\"u\":11478232988514,\"s\":\"BTCUSDT\",\"ps\":\"BTCUSDT\",\"b\":\"79607.10\",\"B\":\"5.665\",\"a\":\"79607.20\",\"A\":\"7.165\",\"T\":1788563386632,\"E\":1788563386632,\"st\":1}}"}
{"receive_ns":1788563386617144000,"stream":"btcusdt@depth@100ms","event_type":"depthUpdate","event_time_ms":1788563386655,"raw_json":"{\"stream\":\"btcusdt@depth@100ms\",\"data\":{\"e\":\"depthUpdate\",\"E\":1788563386655,\"T\":1788563386653,\"s\":\"BTCUSDT\",\"ps\":\"BTCUSDT\",\"U\":11478232984537,\"u\":11478232989780,\"pu\":11478232984245,\"b\":[[\"29107.10\",\"1.162\"],[\"29507.10\",\"0.938\"],[\"63685.70\",\"0.001\"],[\"63686.00\",\"0.000\"],[\"71646.30\",\"0.002\"],[\"75626.70\",\"0.024\"],[\"76422.80\",\"0.002\"],[\"78452.80\",\"40.346\"],[\"78665.90\",\"1.329\"],[\"78691.60\",\"11.528\"],[\"78811.00\",\"15.338\"],[\"79209.10\",\"3.843\"],[\"79232.90\",\"0.141\"],[\"79395.90\",\"5.013\"],[\"79443.70\",\"2.504\"],[\"79483.10\",\"0.527\"],[\"79491.70\",\"0.583\"],[\"79573.80\",\"0.525\"],[\"79574.70\",\"0.003\"],[\"79583.20\",\"0.504\"],[\"79583.80\",\"0.001\"],[\"79585.20\",\"0.153\"],[\"79589.20\",\"0.395\"],[\"79593.40\",\"0.002\"],[\"79603.30\",\"0.625\"],[\"79603.40\",\"0.026\"],[\"79603.60\",\"1.545\"],[\"79604.30\",\"0.000\"],[\"79604.50\",\"0.000\"],[\"79604.60\",\"0.000\"],[\"79604.80\",\"0.002\"],[\"79607.10\",\"5.665\"]],\"a\":[[\"79616.20\",\"0.082\"],[\"79618.30\",\"0.440\"],[\"79623.50\",\"0.001\"],[\"79624.50\",\"0.931\"],[\"79625.50\",\"0.006\"],[\"79706.70\",\"0.152\"],[\"79706.80\",\"0.000\"],[\"79706.90\",\"0.000\"],[\"79728.70\",\"0.294\"],[\"79768.10\",\"1.353\"],[\"79774.40\",\"2.505\"],[\"79815.90\",\"3.174\"],[\"79968.00\",\"0.867\"],[\"79969.40\",\"0.909\"],[\"79997.80\",\"0.525\"],[\"80005.20\",\"3.504\"],[\"80403.30\",\"22.211\"],[\"80496.20\",\"0.000\"]],\"st\":1}}"}
{"receive_ns":1788563386621443000,"stream":"btcusdt@bookTicker","event_type":"bookTicker","event_time_ms":1788563386657,"raw_json":"{\"stream\":\"btcusdt@bookTicker\",\"data\":{\"e\":\"bookTicker\",\"u\":11478232989905,\"s\":\"BTCUSDT\",\"ps\":\"BTCUSDT\",\"b\":\"79607.10\",\"B\":\"5.669\",\"a\":\"79607.20\",\"A\":\"7.165\",\"T\":1788563386656,\"E\":1788563386657,\"st\":1}}"}
{"receive_ns":1788563386720114000,"stream":"btcusdt@depth@100ms","event_type":"depthUpdate","event_time_ms":1788563386757,"raw_json":"{\"stream\":\"btcusdt@depth@100ms\",\"data\":{\"e\":\"depthUpdate\",\"E\":1788563386757,\"T\":1788563386756,\"s\":\"BTCUSDT\",\"ps\":\"BTCUSDT\",\"U\":11478232989873,\"u\":11478232993968,\"pu\":11478232989780,\"b\":[[\"1000.00\",\"24.754\"],[\"29107.10\",\"0.987\"],[\"29507.10\",\"1.113\"],[\"63686.00\",\"0.000\"],[\"71646.30\",\"0.002\"],[\"78572.10\",\"1.860\"],[\"78612.00\",\"15.293\"],[\"78811.00\",\"15.338\"],[\"79209.10\",\"4.473\"],[\"79573.80\",\"0.073\"],[\"79575.90\",\"0.453\"],[\"79580.00\",\"0.006\"],[\"79580.10\",\"0.445\"],[\"79581.90\",\"0.061\"],[\"79589.60\",\"0.100\"],[\"79589.70\",\"0.004\"],[\"79592.00\",\"0.024\"],[\"79592.50\",\"0.017\"],[\"79606.90\",\"0.198\"],[\"79607.10\",\"5.669\"]],\"a\":[[\"79624.50\",\"0.479\"],[\"79625.50\",\"0.458\"],[\"79627.30\",\"0.000\"],[\"79630.10\",\"0.094\"],[\"79706.70\",\"0.027\"],[\"79706.80\",\"0.000\"],[\"79707.00\",\"0.728\"],[\"80005.20\",\"3.629\"],[\"80403.30\",\"22.211\"],[\"80777.40\",\"10.682\"]],\"st\":1}}"}
{"receive_ns":1788563386829206000,"stream":"btcusdt@depth@100ms","event_type":"depthUpdate","event_time_ms":1788563386859,"raw_json":"{\"stream\":\"btcusdt@depth@100ms\",\"data\":{\"e\":\"depthUpdate\",\"E\":1788563386859,\"T\":1788563386858,\"s\":\"BTCUSDT\",\"ps\":\"BTCUSDT\",\"U\":11478232994007,\"u\":11478232998094,\"pu\":11478232993968,\"b\":[[\"1000.00\",\"24.754\"],[\"29107.10\",\"0.805\"],[\"29507.10\",\"1.295\"],[\"71646.30\",\"0.002\"],[\"76422.80\",\"0.000\"],[\"78489.10\",\"19.056\"],[\"78651.80\",\"52.666\"],[\"78675.70\",\"4.441\"],[\"78811.00\",\"15.338\"],[\"79209.00\",\"0.000\"],[\"79232.90\",\"0.000\"],[\"79491.70\",\"0.000\"],[\"79583.20\",\"0.002\"],[\"79585.20\",\"0.078\"],[\"79589.20\",\"0.697\"],[\"79604.40\",\"0.026\"]],\"a\":[[\"79707.00\",\"0.603\"],[\"79707.20\",\"0.125\"],[\"79774.40\",\"2.003\"],[\"79968.00\",\"0.104\"],[\"79969.40\",\"0.420\"],[\"79997.80\",\"0.000\"],[\"80403.30\",\"22.211\"]],\"st\":1}}"}
{"receive_ns":1788563386924168000,"stream":"btcusdt@depth@100ms","event_type":"depthUpdate","event_time_ms":1788563386961,"raw_json":"{\"stream\":\"btcusdt@depth@100ms\",\"data\":{\"e\":\"depthUpdate\",\"E\":1788563386961,\"T\":1788563386958,\"s\":\"BTCUSDT\",\"ps\":\"BTCUSDT\",\"U\":11478232998160,\"u\":11478233002220,\"pu\":11478232998094,\"b\":[[\"29107.10\",\"0.630\"],[\"29507.10\",\"1.470\"],[\"63686.00\",\"0.000\"],[\"71646.30\",\"0.002\"],[\"75626.70\",\"0.017\"],[\"75626.80\",\"0.008\"],[\"76422.80\",\"0.002\"],[\"78054.80\",\"0.640\"],[\"78452.80\",\"39.455\"],[\"78691.60\",\"10.766\"],[\"78811.00\",\"15.338\"],[\"79209.10\",\"4.483\"],[\"79232.90\",\"0.141\"],[\"79491.70\",\"0.483\"],[\"79523.90\",\"2.648\"],[\"79524.20\",\"0.039\"],[\"79575.30\",\"0.174\"],[\"79583.80\",\"0.001\"],[\"79588.70\",\"0.003\"],[\"79588.90\",\"0.046\"],[\"79589.20\",\"0.972\"],[\"79589.30\",\"0.067\"],[\"79589.80\",\"0.010\"],[\"79589.90\",\"0.002\"],[\"79603.30\",\"0.624\"],[\"79604.40\",\"0.000\"]],\"a\":[[\"79668.80\",\"0.316\"],[\"79671.50\",\"25.490\"],[\"79676.90\",\"0.205\"],[\"79705.80\",\"4.776\"],[\"79706.10\",\"0.000\"],[\"79706.20\",\"0.001\"],[\"79706.80\",\"0.125\"],[\"79707.20\",\"0.000\"],[\"79828.60\",\"7.285\"],[\"79968.00\",\"0.867\"],[\"79969.40\",\"1.411\"],[\"79997.80\",\"0.525\"],[\"80005.20\",\"3.504\"],[\"80005.30\",\"0.003\"],[\"80339.30\",\"0.186\"],[\"80403.30\",\"22.211\"],[\"80602.30\",\"11.694\"],[\"80721.70\",\"56.794\"],[\"80761.50\",\"19.727\"],[\"80841.10\",\"9.516\"],[\"80944.60\",\"1.972\"]],\"st\":1}}"}
{"receive_ns":1788563387025543000,"stream":"btcusdt@depth@100ms","event_type":"depthUpdate","event_time_ms":1788563387063,"raw_json":"{\"stream\":\"btcusdt@depth@100ms\",\"data\":{\"e\":\"depthUpdate\",\"E\":1788563387063,\"T\":1788563387062,\"s\":\"BTCUSDT\",\"ps\":\"BTCUSDT\",\"U\":11478233002367,\"u\":11478233007272,\"pu\":11478233002220,\"b\":[[\"1000.00\",\"24.754\"],[\"29107.10\",\"0.448\"],[\"29507.10\",\"1.652\"],[\"63686.00\",\"0.000\"],[\"71646.30\",\"0.002\"],[\"76422.80\",\"0.000\"],[\"78015.00\",\"10.697\"],[\"78492.60\",\"52.329\"],[\"78651.80\",\"51.396\"],[\"78811.00\",\"15.338\"],[\"79589.20\",\"0.972\"],[\"79592.00\",\"0.007\"],[\"79592.50\",\"0.001\"],[\"79592.80\",\"0.022\"],[\"79593.30\",\"0.001\"],[\"79593.60\",\"0.024\"],[\"79594.00\",\"0.020\"],[\"79594.20\",\"0.017\"],[\"79602.90\",\"0.028\"],[\"79603.00\",\"0.029\"],[\"79603.10\",\"0.252\"],[\"79603.20\",\"0.029\"],[\"79603.80\",\"0.003\"],[\"79603.90\",\"0.001\"],[\"79604.00\",\"0.004\"],[\"79604.10\",\"1.000\"],[\"79604.50\",\"0.000\"]],\"a\":[[\"79630.10\",\"0.014\"],[\"79631.70\",\"0.080\"],[\"79706.60\",\"0.301\"],[\"79706.70\",\"0.027\"],[\"79706.80\",\"0.000\"],[\"79706.90\",\"0.125\"],[\"79969.40\",\"1.411\"],[\"80403.30\",\"22.211\"],[\"80562.50\",\"49.590\"],[\"80721.70\",\"54.938\"]],\"st\":1}}"}
{"receive_ns":1788563387044465000,"stream":"btcusdt@bookTicker","event_type":"bookTicker","event_time_ms":1788563387081,"raw_json":"{\"stream\":\"btcusdt@bookTicker\",\"data\":{\"e\":\"bookTicker\",\"u\":11478233008009,\"s\":\"BTCUSDT\",\"ps\":\"BTCUSDT\",\"b\":\"79607.10\",\"B\":\"5.664\",\"a\":\"79607.20\",\"A\":\"7.165\",\"T\":1788563387080,\"E\":1788563387081,\"st\":1}}"}
{"receive_ns":1788563387044702000,"stream":"btcusdt@trade","event_type":"trade","event_time_ms":1788563387081,"raw_json":"{\"stream\":\"btcusdt@trade\",\"data\":{\"e\":\"trade\",\"E\":1788563387081,\"T\":1788563387080,\"s\":\"BTCUSDT\",\"t\":8054083455,\"p\":\"79607.10\",\"q\":\"0.005\",\"X\":\"MARKET\",\"m\":true,\"st\":1}}"}
{"receive_ns":1788563387045321000,"stream":"btcusdt@bookTicker","event_type":"bookTicker","event_time_ms":1788563387082,"raw_json":"{\"stream\":\"btcusdt@bookTicker\",\"data\":{\"e\":\"bookTicker\",\"u\":11478233008189,\"s\":\"BTCUSDT\",\"ps\":\"BTCUSDT\",\"b\":\"79607.10\",\"B\":\"5.626\",\"a\":\"79607.20\",\"A\":\"7.165\",\"T\":1788563387082,\"E\":1788563387082,\"st\":1}}"}
{"receive_ns":1788563387109205000,"stream":"btcusdt@bookTicker","event_type":"bookTicker","event_time_ms":1788563387146,"raw_json":"{\"stream\":\"btcusdt@bookTicker\",\"data\":{\"e\":\"bookTicker\",\"u\":11478233011391,\"s\":\"BTCUSDT\",\"ps\":\"BTCUSDT\",\"b\":\"79607.10\",\"B\":\"4.992\",\"a\":\"79607.20\",\"A\":\"7.165\",\"T\":1788563387146,\"E\":1788563387146,\"st\":1}}"}
{"receive_ns":1788563387109525000,"stream":"btcusdt@bookTicker","event_type":"bookTicker","event_time_ms":1788563387148,"raw_json":"{\"stream\":\"btcusdt@bookTicker\",\"data\":{\"e\":\"bookTicker\",\"u\":11478233011492,\"s\":\"BTCUSDT\",\"ps\":\"BTCUSDT\",\"b\":\"79607.10\",\"B\":\"4.990\",\"a\":\"79607.20\",\"A\":\"7.165\",\"T\":1788563387147,\"E\":1788563387148,\"st\":1}}"}
{"receive_ns":1788563387110177000,"stream":"btcusdt@bookTicker","event_type":"bookTicker","event_time_ms":1788563387149,"raw_json":"{\"stream\":\"btcusdt@bookTicker\",\"data\":{\"e\":\"bookTicker\",\"u\":11478233011551,\"s\":\"BTCUSDT\",\"ps\":\"BTCUSDT\",\"b\":\"79607.10\",\"B\":\"5.634\",\"a\":\"79607.20\",\"A\":\"7.165\",\"T\":1788563387149,\"E\":1788563387149,\"st\":1}}"}
{"receive_ns":1788563387111278000,"stream":"btcusdt@bookTicker","event_type":"bookTicker","event_time_ms":1788563387150,"raw_json":"{\"stream\":\"btcusdt@bookTicker\",\"data\":{\"e\":\"bookTicker\",\"u\":11478233011633,\"s\":\"BTCUSDT\",\"ps\":\"BTCUSDT\",\"b\":\"79607.10\",\"B\":\"5.636\",\"a\":\"79607.20\",\"A\":\"7.165\",\"T\":1788563387150,\"E\":1788563387150,\"st\":1}}"}
{"receive_ns":1788563387128621000,"stream":"btcusdt@depth@100ms","event_type":"depthUpdate","event_time_ms":1788563387165,"raw_json":"{\"stream\":\"btcusdt@depth@100ms\",\"data\":{\"e\":\"depthUpdate\",\"E\":1788563387165,\"T\":1788563387162,\"s\":\"BTCUSDT\",\"ps\":\"BTCUSDT\",\"U\":11478233007342,\"u\":11478233012572,\"pu\":11478233007272,\"b\":[[\"1000.00\",\"24.754\"],[\"29107.10\",\"0.301\"],[\"29407.10\",\"0.028\"],[\"29507.10\",\"1.771\"],[\"63686.00\",\"0.000\"],[\"71646.30\",\"0.002\"],[\"76422.80\",\"0.002\"],[\"78691.60\",\"11.528\"],[\"78811.00\",\"15.338\"],[\"79232.90\",\"0.141\"],[\"79421.10\",\"3.140\"],[\"79461.30\",\"0.000\"],[\"79461.40\",\"1.884\"],[\"79491.70\",\"0.232\"],[\"79519.40\",\"0.038\"],[\"79533.50\",\"0.001\"],[\"79549.50\",\"0.037\"],[\"79574.90\",\"0.474\"],[\"79575.20\",\"0.915\"],[\"79575.30\",\"0.174\"],[\"79575.90\",\"0.001\"],[\"79581.80\",\"2.955\"],[\"79582.90\",\"0.076\"],[\"79583.80\",\"0.001\"],[\"79589.20\",\"0.972\"],[\"79589.30\",\"0.067\"],[\"79589.80\",\"0.010\"],[\"79589.90\",\"0.002\"],[\"79591.00\",\"0.252\"],[\"79591.40\",\"0.076\"],[\"79592.20\",\"0.022\"],[\"79592.80\",\"0.004\"],[\"79594.20\",\"0.001\"],[\"79595.70\",\"0.002\"],[\"79596.30\",\"0.032\"],[\"79596.60\",\"0.001\"],[\"79602.40\",\"0.280\"],[\"79602.50\",\"0.027\"],[\"79602.60\",\"0.027\"],[\"79602.80\",\"0.026\"],[\"79603.30\",\"0.598\"],[\"79603.40\",\"0.000\"],[\"79603.60\",\"1.519\"],[\"79603.70\",\"0.011\"],[\"79604.20\",\"0.027\"],[\"79607.10\",\"5.636\"]],\"a\":[[\"79609.40\",\"0.267\"],[\"79609.50\",\"0.007\"],[\"79610.70\",\"0.004\"],[\"79668.10\",\"5.525\"],[\"79682.90\",\"0.003\"],[\"79694.60\",\"0.039\"],[\"79706.80\",\"0.000\"],[\"79706.90\",\"0.000\"],[\"79729.70\",\"2.336\"],[\"79729.80\",\"1.884\"],[\"79744.20\",\"0.651\"],[\"79747.90\",\"0.006\"],[\"79748.30\",\"3.140\"],[\"79841.50\",\"0.001\"],[\"79841.60\",\"0.003\"],[\"79968.00\",\"0.867\"],[\"79969.40\",\"1.411\"],[\"79997.80\",\"0.525\"],[\"80403.30\",\"22.286\"],[\"80761.50\",\"20.593\"]],\"st\":1}}"}
{"receive_ns":1788563387229862000,"stream":"btcusdt@depth@100ms","event_type":"depthUpdate","event_time_ms":1788563387267,"raw_json":"{\"stream\":\"btcusdt@depth@100ms\",\"data\":{\"e\":\"depthUpdate\",\"E\":1788563387267,\"T\":1788563387265,\"s\":\"BTCUSDT\",\"ps\":\"BTCUSDT\",\"U\":11478233012764,\"u\":11478233019213,\"pu\":11478233012572,\"b\":[[\"29107.10\",\"0.175\"],[\"29407.10\",\"0.084\"],[\"29507.10\",\"1.841\"],[\"71646.30\",\"0.002\"],[\"75626.80\",\"0.006\"],[\"78443.90\",\"2.738\"],[\"78452.80\",\"40.346\"],[\"78665.90\",\"0.886\"],[\"78811.00\",\"15.338\"],[\"79209.10\",\"4.483\"],[\"79573.90\",\"0.454\"],[\"79574.90\",\"0.022\"],[\"79592.50\",\"0.001\"],[\"79593.20\",\"0.000\"],[\"79595.70\",\"0.001\"],[\"79596.30\",\"0.033\"],[\"79596.60\",\"0.001\"],[\"79602.40\",\"0.254\"],[\"79603.70\",\"0.037\"],[\"79603.80\",\"0.029\"],[\"79604.20\",\"0.001\"],[\"79604.80\",\"0.002\"],[\"79605.40\",\"0.001\"]],\"a\":[[\"79616.20\",\"0.082\"],[\"79618.20\",\"0.440\"],[\"79618.30\",\"0.001\"],[\"79668.20\",\"2.949\"],[\"79706.90\",\"0.000\"],[\"79707.00\",\"0.603\"],[\"79707.10\",\"0.125\"],[\"79707.20\",\"0.000\"],[\"79707.40\",\"0.002\"],[\"79708.20\",\"2.517\"],[\"80316.80\",\"0.000\"],[\"80403.30\",\"22.286\"],[\"80721.70\",\"56.794\"],[\"80761.50\",\"21.459\"],[\"80841.10\",\"10.381\"],[\"87568.00\",\"0.000\"]],\"st\":1}}"}
{"receive_ns":1788563387330716000,"stream":"btcusdt@bookTicker","event_type":"bookTicker","event_time_ms":1788563387367,"raw_json":"{\"stream\":\"btcusdt@bookTicker\",\"data\":{\"e\":\"bookTicker\",\"u\":11478233026232,\"s\":\"BTCUSDT\",\"ps\":\"BTCUSDT\",\"b\":\"79607.10\",\"B\":\"5.674\",\"a\":\"79607.20\",\"A\":\"7.165\",\"T\":1788563387366,\"E\":1788563387367,\"st\":1}}"}
{"receive_ns":1788563387340269000,"stream":"btcusdt@depth@100ms","event_type":"depthUpdate","event_time_ms":1788563387369,"raw_json":"{\"stream\":\"btcusdt@depth@100ms\",\"data\":{\"e\":\"depthUpdate\",\"E\":1788563387369,\"T\":1788563387368,\"s\":\"BTCUSDT\",\"ps\":\"BTCUSDT\",\"U\":11478233019320,\"u\":11478233026342,\"pu\":11478233019213,\"b\":[[\"1000.00\",\"24.754\"],[\"29107.10\",\"0.063\"],[\"29407.10\",\"0.147\"],[\"29507.10\",\"1.890\"],[\"71646.30\",\"0.002\"],[\"76422.80\",\"0.000\"],[\"78452.80\",\"41.237\"],[\"78492.60\",\"54.237\"],[\"78651.80\",\"52.666\"],[\"78811.00\",\"15.340\"],[\"79129.50\",\"0.290\"],[\"79232.90\",\"0.141\"],[\"79491.70\",\"0.232\"],[\"79575.30\",\"0.074\"],[\"79583.20\",\"0.353\"],[\"79583.80\",\"0.001\"],[\"79589.20\",\"0.972\"],[\"79589.80\",\"1.014\"],[\"79602.40\",\"0.280\"],[\"79603.70\",\"0.011\"],[\"79603.80\",\"0.003\"],[\"79607.10\",\"5.674\"]],\"a\":[[\"79707.10\",\"0.000\"],[\"79707.80\",\"0.125\"],[\"79968.00\",\"0.867\"],[\"79969.40\",\"1.367\"],[\"79997.80\",\"0.525\"],[\"79999.30\",\"0.055\"],[\"80337.10\",\"0.000\"],[\"80403.30\",\"22.286\"],[\"80562.50\",\"50.830\"],[\"80681.90\",\"10.576\"],[\"80721.70\",\"58.650\"]],\"st\":1}}"}
{"receive_ns":1788563387340631000,"stream":"btcusdt@bookTicker","event_type":"bookTicker","event_time_ms":1788563387373,"raw_json":"{\"stream\":\"btcusdt@bookTicker\",\"data\":{\"e\":\"bookTicker\",\"u\":11478233026588,\"s\":\"BTCUSDT\",\"ps\":\"BTCUSDT\",\"b\":\"79607.10\",\"B\":\"5.241\",\"a\":\"79607.20\",\"A\":\"7.165\",\"T\":1788563387373,\"E\":1788563387373,\"st\":1}}"}
{"receive_ns":1788563387341502000,"stream":"btcusdt@bookTicker","event_type":"bookTicker","event_time_ms":1788563387377,"raw_json":"{\"stream\":\"btcusdt@bookTicker\",\"data\":{\"e\":\"bookTicker\",\"u\":11478233026728,\"s\":\"BTCUSDT\",\"ps\":\"BTCUSDT\",\"b\":\"79607.10\",\"B\":\"5.676\",\"a\":\"79607.20\",\"A\":\"7.165\",\"T\":1788563387376,\"E\":1788563387377,\"st\":1}}"}
{"receive_ns":1788563387341756000,"stream":"btcusdt@bookTicker","event_type":"bookTicker","event_time_ms":1788563387378,"raw_json":"{\"stream\":\"btcusdt@bookTicker\",\"data\":{\"e\":\"bookTicker\",\"u\":11478233026793,\"s\":\"BTCUSDT\",\"ps\":\"BTCUSDT\",\"b\":\"79607.10\",\"B\":\"5.675\",\"a\":\"79607.20\",\"A\":\"7.165\",\"T\":1788563387378,\"E\":1788563387378,\"st\":1}}"}
{"receive_ns":1788563387341972000,"stream":"btcusdt@bookTicker","event_type":"bookTicker","event_time_ms":1788563387378,"raw_json":"{\"stream\":\"btcusdt@bookTicker\",\"data\":{\"e\":\"bookTicker\",\"u\":11478233026807,\"s\":\"BTCUSDT\",\"ps\":\"BTCUSDT\",\"b\":\"79607.10\",\"B\":\"5.673\",\"a\":\"79607.20\",\"A\":\"7.165\",\"T\":1788563387378,\"E\":1788563387378,\"st\":1}}"}
{"receive_ns":1788563387342239000,"stream":"btcusdt@bookTicker","event_type":"bookTicker","event_time_ms":1788563387379,"raw_json":"{\"stream\":\"btcusdt@bookTicker\",\"data\":{\"e\":\"bookTicker\",\"u\":11478233026841,\"s\":\"BTCUSDT\",\"ps\":\"BTCUSDT\",\"b\":\"79607.10\",\"B\":\"5.674\",\"a\":\"79607.20\",\"A\":\"7.165\",\"T\":1788563387379,\"E\":1788563387379,\"st\":1}}"}
{"receive_ns":1788563387436792000,"stream":"btcusdt@depth@100ms","event_type":"depthUpdate","event_time_ms":1788563387471,"raw_json":"{\"stream\":\"btcusdt@depth@100ms\",\"data\":{\"e\":\"depthUpdate\",\"E\":1788563387471,\"T\":1788563387470,\"s\":\"BTCUSDT\",\"ps\":\"BTCUSDT\",\"U\":11478233026361,\"u\":11478233031892,\"pu\":11478233026342,\"b\":[[\"1000.00\",\"24.754\"],[\"29107.10\",\"0.000\"],[\"29407.10\",\"0.266\"],[\"29507.10\",\"1.834\"],[\"71646.30\",\"0.002\"],[\"75626.80\",\"0.004\"],[\"76422.80\",\"0.002\"],[\"78675.70\",\"4.884\"],[\"78811.00\",\"15.338\"],[\"79583.20\",\"0.002\"],[\"79589.80\",\"0.010\"],[\"79590.70\",\"0.000\"],[\"79591.40\",\"0.000\"],[\"79595.70\",\"0.001\"],[\"79596.30\",\"0.032\"],[\"79596.60\",\"0.002\"],[\"79602.30\",\"0.028\"],[\"79603.20\",\"0.003\"],[\"79603.40\",\"0.000\"],[\"79607.10\",\"5.674\"]],\"a\":[[\"80323.70\",\"21.108\"],[\"80403.30\",\"22.286\"],[\"80479.20\",\"1.556\"],[\"80598.60\",\"13.033\"]],\"st\":1}}"}
{"receive_ns":1788563387439384000,"stream":"btcusdt@bookTicker","event_type":"bookTicker","event_time_ms":1788563387475,"raw_json":"{\"stream\":\"btcusdt@bookTicker\",\"data\":{\"e\":\"bookTicker\",\"u\":11478233032020,\"s\":\"BTCUSDT\",\"ps\":\"BTCUSDT\",\"b\":\"79607.10\",\"B\":\"5.673\",\"a\":\"79607.20\",\"A\":\"7.165\",\"T\":1788563387474,\"E\":1788563387475,\"st\":1}}"}
{"receive_ns":1788563387445109000,"stream":"btcusdt@bookTicker","event_type":"bookTicker","event_time_ms":1788563387481,"raw_json":"{\"stream\":\"btcusdt@bookTicker\",\"data\":{\"e\":\"bookTicker\",\"u\":11478233032324,\"s\":\"BTCUSDT\",\"ps\":\"BTCUSDT\",\"b\":\"79607.10\",\"B\":\"5.204\",\"a\":\"79607.20\",\"A\":\"7.165\",\"T\":1788563387481,\"E\":1788563387481,\"st\":1}}"}
{"receive_ns":1788563387458286000,"stream":"btcusdt@bookTicker","event_type":"bookTicker","event_time_ms":1788563387483,"raw_json":"{\"stream\":\"btcusdt@bookTicker\",\"data\":{\"e\":\"bookTicker\",\"u\":11478233032375,\"s\":\"BTCUSDT\",\"ps\":\"BTCUSDT\",\"b\":\"79607.10\",\"B\":\"5.206\",\"a\":\"79607.20\",\"A\":\"7.165\",\"T\":1788563387482,\"E\":1788563387483,\"st\":1}}"}
{"receive_ns":1788563387460123000,"stream":"btcusdt@bookTicker","event_type":"bookTicker","event_time_ms":1788563387484,"raw_json":"{\"stream\":\"btcusdt@bookTicker\",\"data\":{\"e\":\"bookTicker\",\"u\":11478233032557,\"s\":\"BTCUSDT\",\"ps\":\"BTCUSDT\",\"b\":\"79607.10\",\"B\":\"5.677\",\"a\":\"79607.20\",\"A\":\"7.165\",\"T\":1788563387484,\"E\":1788563387484,\"st\":1}}"}
{"receive_ns":1788563387488697000,"stream":"btcusdt@bookTicker","event_type":"bookTicker","event_time_ms":1788563387525,"raw_json":"{\"stream\":\"btcusdt@bookTicker\",\"data\":{\"e\":\"bookTicker\",\"u\":11478233034203,\"s\":\"BTCUSDT\",\"ps\":\"BTCUSDT\",\"b\":\"79607.10\",\"B\":\"5.125\",\"a\":\"79607.20\",\"A\":\"7.165\",\"T\":1788563387525,\"E\":1788563387525,\"st\":1}}"}
{"receive_ns":1788563387497341000,"stream":"btcusdt@bookTicker","event_type":"bookTicker","event_time_ms":1788563387526,"raw_json":"{\"stream\":\"btcusdt@bookTicker\",\"data\":{\"e\":\"bookTicker\",\"u\":11478233034236,\"s\":\"BTCUSDT\",\"ps\":\"BTCUSDT\",\"b\":\"79607.10\",\"B\":\"5.123\",\"a\":\"79607.20\",\"A\":\"7.165\",\"T\":1788563387526,\"E\":1788563387526,\"st\":1}}"}
{"receive_ns":1788563387497656000,"stream":"btcusdt@bookTicker","event_type":"bookTicker","event_time_ms":1788563387528,"raw_json":"{\"stream\":\"btcusdt@bookTicker\",\"data\":{\"e\":\"bookTicker\",\"u\":11478233034324,\"s\":\"BTCUSDT\",\"ps\":\"BTCUSDT\",\"b\":\"79607.10\",\"B\":\"5.677\",\"a\":\"79607.20\",\"A\":\"7.165\",\"T\":1788563387527,\"E\":1788563387528,\"st\":1}}"}
{"receive_ns":1788563387497805000,"stream":"btcusdt@bookTicker","event_type":"bookTicker","event_time_ms":1788563387528,"raw_json":"{\"stream\":\"btcusdt@bookTicker\",\"data\":{\"e\":\"bookTicker\",\"u\":11478233034328,\"s\":\"BTCUSDT\",\"ps\":\"BTCUSDT\",\"b\":\"79607.10\",\"B\":\"5.677\",\"a\":\"79607.20\",\"A\":\"7.164\",\"T\":1788563387528,\"E\":1788563387528,\"st\":1}}"}
{"receive_ns":1788563387497925000,"stream":"btcusdt@trade","event_type":"trade","event_time_ms":1788563387528,"raw_json":"{\"stream\":\"btcusdt@trade\",\"data\":{\"e\":\"trade\",\"E\":1788563387528,\"T\":1788563387528,\"s\":\"BTCUSDT\",\"t\":8054083456,\"p\":\"79607.20\",\"q\":\"0.001\",\"X\":\"MARKET\",\"m\":false,\"st\":1}}"}
{"receive_ns":1788563387498134000,"stream":"btcusdt@bookTicker","event_type":"bookTicker","event_time_ms":1788563387529,"raw_json":"{\"stream\":\"btcusdt@bookTicker\",\"data\":{\"e\":\"bookTicker\",\"u\":11478233034369,\"s\":\"BTCUSDT\",\"ps\":\"BTCUSDT\",\"b\":\"79607.10\",\"B\":\"5.679\",\"a\":\"79607.20\",\"A\":\"7.164\",\"T\":1788563387529,\"E\":1788563387529,\"st\":1}}"}
{"receive_ns":1788563387543438000,"stream":"btcusdt@depth@100ms","event_type":"depthUpdate","event_time_ms":1788563387573,"raw_json":"{\"stream\":\"btcusdt@depth@100ms\",\"data\":{\"e\":\"depthUpdate\",\"E\":1788563387573,\"T\":1788563387569,\"s\":\"BTCUSDT\",\"ps\":\"BTCUSDT\",\"U\":11478233031944,\"u\":11478233035823,\"pu\":11478233031892,\"b\":[[\"29407.10\",\"0.441\"],[\"29507.10\",\"1.659\"],[\"71646.30\",\"0.002\"],[\"71684.00\",\"0.003\"],[\"76422.80\",\"0.000\"],[\"78015.00\",\"10.697\"],[\"78811.00\",\"15.338\"],[\"79209.10\",\"4.473\"],[\"79232.90\",\"0.000\"],[\"79483.30\",\"0.001\"],[\"79483.40\",\"0.003\"],[\"79491.70\",\"0.000\"],[\"79583.20\",\"0.504\"],[\"79583.40\",\"0.006\"],[\"79589.20\",\"0.195\"],[\"79590.70\",\"0.076\"],[\"79592.20\",\"0.098\"],[\"79595.70\",\"0.001\"],[\"79596.60\",\"0.002\"],[\"79602.30\",\"0.002\"],[\"79603.20\",\"0.029\"],[\"79603.60\",\"1.545\"],[\"79603.70\",\"0.037\"],[\"79607.10\",\"5.679\"]],\"a\":[[\"79607.20\",\"7.164\"],[\"79623.30\",\"0.458\"],[\"79968.00\",\"0.104\"],[\"79969.40\",\"0.420\"],[\"79997.80\",\"0.000\"],[\"79999.30\",\"0.011\"],[\"80403.30\",\"22.286\"],[\"83587.50\",\"0.025\"]],\"st\":1}}"}
{"receive_ns":1788563387554706000,"stream":"btcusdt@trade","event_type":"trade","event_time_ms":1788563387591,"raw_json":"{\"stream\":\"btcusdt@trade\",\"data\":{\"e\":\"trade\",\"E\":1788563387591,\"T\":1788563387591,\"s\":\"BTCUSDT\",\"t\":8054083457,\"p\":\"79607.10\",\"q\":\"0.420\",\"X\":\"MARKET\",\"m\":true,\"st\":1}}"}
{"receive_ns":1788563387554878000,"stream":"btcusdt@trade","event_type":"trade","event_time_ms":1788563387591,"raw_json":"{\"stream\":\"btcusdt@trade\",\"data\":{\"e\":\"trade\",\"E\":1788563387591,\"T\":1788563387591,\"s\":\"BTCUSDT\",\"t\":8054083458,\"p\":\"79607.10\",\"q\":\"0.062\",\"X\":\"MARKET\",\"m\":true,\"st\":1}}"}
{"receive_ns":1788563387554997000,"stream":"btcusdt@trade","event_type":"trade","event_time_ms":1788563387591,"raw_json":"{\"stream\":\"btcusdt@trade\",\"data\":{\"e\":\"trade\",\"E\":1788563387591,\"T\":1788563387591,\"s\":\"BTCUSDT\",\"t\":8054083459,\"p\":\"79607.10\",\"q\":\"0.001\",\"X\":\"MARKET\",\"m\":true,\"st\":1}}"}
{"receive_ns":1788563387555109000,"stream":"btcusdt@trade","event_type":"trade","event_time_ms":1788563387591,"raw_json":"{\"stream\":\"btcusdt@trade\",\"data\":{\"e\":\"trade\",\"E\":1788563387591,\"T\":1788563387591,\"s\":\"BTCUSDT\",\"t\":8054083460,\"p\":\"79607.10\",\"q\":\"0.013\",\"X\":\"MARKET\",\"m\":true,\"st\":1}}"}
{"receive_ns":1788563387555218000,"stream":"btcusdt@trade","event_type":"trade","event_time_ms":1788563387591,"raw_json":"{\"stream\":\"btcusdt@trade\",\"data\":{\"e\":\"trade\",\"E\":1788563387591,\"T\":1788563387591,\"s\":\"BTCUSDT\",\"t\":8054083461,\"p\":\"79607.10\",\"q\":\"0.001\",\"X\":\"MARKET\",\"m\":true,\"st\":1}}"}
{"receive_ns":1788563387555325000,"stream":"btcusdt@trade","event_type":"trade","event_time_ms":1788563387591,"raw_json":"{\"stream\":\"btcusdt@trade\",\"data\":{\"e\":\"trade\",\"E\":1788563387591,\"T\":1788563387591,\"s\":\"BTCUSDT\",\"t\":8054083462,\"p\":\"79607.10\",\"q\":\"0.001\",\"X\":\"MARKET\",\"m\":true,\"st\":1}}"}
{"receive_ns":1788563387555432000,"stream":"btcusdt@trade","event_type":"trade","event_time_ms":1788563387591,"raw_json":"{\"stream\":\"btcusdt@trade\",\"data\":{\"e\":\"trade\",\"E\":1788563387591,\"T\":1788563387591,\"s\":\"BTCUSDT\",\"t\":8054083463,\"p\":\"79607.10\",\"q\":\"0.100\",\"X\":\"MARKET\",\"m\":true,\"st\":1}}"}
{"receive_ns":1788563387555537000,"stream":"btcusdt@trade","event_type":"trade","event_time_ms":1788563387591,"raw_json":"{\"stream\":\"btcusdt@trade\",\"data\":{\"e\":\"trade\",\"E\":1788563387591,\"T\":1788563387591,\"s\":\"BTCUSDT\",\"t\":8054083464,\"p\":\"79607.10\",\"q\":\"0.038\",\"X\":\"MARKET\",\"m\":true,\"st\":1}}"}
{"receive_ns":1788563387555643000,"stream":"btcusdt@trade","event_type":"trade","event_time_ms":1788563387591,"raw_json":"{\"stream\":\"btcusdt@trade\",\"data\":{\"e\":\"trade\",\"E\":1788563387591,\"T\":1788563387591,\"s\":\"BTCUSDT\",\"t\":8054083465,\"p\":\"79607.10\",\"q\":\"0.005\",\"X\":\"MARKET\",\"m\":true,\"st\":1}}"}
{"receive_ns":1788563387555753000,"stream":"btcusdt@trade","event_type":"trade","event_time_ms":1788563387591,"raw_json":"{\"stream\":\"btcusdt@trade\",\"data\":{\"e\":\"trade\",\"E\":1788563387591,\"T\":1788563387591,\"s\":\"BTCUSDT\",\"t\":8054083466,\"p\":\"79607.10\",\"q\":\"0.004\",\"X\":\"MARKET\",\"m\":true,\"st\":1}}"}
{"receive_ns":1788563387555858000,"stream":"btcusdt@trade","event_type":"trade","event_time_ms":1788563387591,"raw_json":"{\"stream\":\"btcusdt@trade\",\"data\":{\"e\":\"trade\",\"E\":1788563387591,\"T\":1788563387591,\"s\":\"BTCUSDT\",\"t\":8054083467,\"p\":\"79607.10\",\"q\":\"0.039\",\"X\":\"MARKET\",\"m\":true,\"st\":1}}"}
{"receive_ns":1788563387556087000,"stream":"btcusdt@trade","event_type":"trade","event_time_ms":1788563387591,"raw_json":"{\"stream\":\"btcusdt@trade\",\"data\":{\"e\":\"trade\",\"E\":1788563387591,\"T\":1788563387591,\"s\":\"BTCUSDT\",\"t\":8054083468,\"p\":\"79607.10\",\"q\":\"0.037\",\"X\":\"MARKET\",\"m\":true,\"st\":1}}"}
{"receive_ns":1788563387556379000,"stream":"btcusdt@trade","event_type":"trade","event_time_ms":1788563387591,"raw_json":"{\"stream\":\"btcusdt@trade\",\"data\":{\"e\":\"trade\",\"E\":1788563387591,\"T\":1788563387591,\"s\":\"BTCUSDT\",\"t\":8054083469,\"p\":\"79607.10\",\"q\":\"0.003\",\"X\":\"MARKET\",\"m\":true,\"st\":1}}"}
{"receive_ns":1788563387556537000,"stream":"btcusdt@trade","event_type":"trade","event_time_ms":1788563387591,"raw_json":"{\"stream\":\"btcusdt@trade\",\"data\":{\"e\":\"trade\",\"E\":1788563387591,\"T\":1788563387591,\"s\":\"BTCUSDT\",\"t\":8054083470,\"p\":\"79607.10\",\"q\":\"0.003\",\"X\":\"MARKET\",\"m\":true,\"st\":1}}"}
{"receive_ns":1788563387556655000,"stream":"btcusdt@trade","event_type":"trade","event_time_ms":1788563387591,"raw_json":"{\"stream\":\"btcusdt@trade\",\"data\":{\"e\":\"trade\",\"E\":1788563387591,\"T\":1788563387591,\"s\":\"BTCUSDT\",\"t\":8054083471,\"p\":\"79607.10\",\"q\":\"0.002\",\"X\":\"MARKET\",\"m\":true,\"st\":1}}"}
{"receive_ns":1788563387556766000,"stream":"btcusdt@trade","event_type":"trade","event_time_ms":1788563387591,"raw_json":"{\"stream\":\"btcusdt@trade\",\"data\":{\"e\":\"trade\",\"E\":1788563387591,\"T\":1788563387591,\"s\":\"BTCUSDT\",\"t\":8054083472,\"p\":\"79607.10\",\"q\":\"0.005\",\"X\":\"MARKET\",\"m\":true,\"st\":1}}"}
{"receive_ns":1788563387557018000,"stream":"btcusdt@trade","event_type":"trade","event_time_ms":1788563387591,"raw_json":"{\"stream\":\"btcusdt@trade\",\"data\":{\"e\":\"trade\",\"E\":1788563387591,\"T\":1788563387591,\"s\":\"BTCUSDT\",\"t\":8054083473,\"p\":\"79607.10\",\"q\":\"0.003\",\"X\":\"MARKET\",\"m\":true,\"st\":1}}"}
{"receive_ns":1788563387557179000,"stream":"btcusdt@trade","event_type":"trade","event_time_ms":1788563387591,"raw_json":"{\"stream\":\"btcusdt@trade\",\"data\":{\"e\":\"trade\",\"E\":1788563387591,\"T\":1788563387591,\"s\":\"BTCUSDT\",\"t\":8054083474,\"p\":\"79607.10\",\"q\":\"0.002\",\"X\":\"MARKET\",\"m\":true,\"st\":1}}"}
{"receive_ns":1788563387557297000,"stream":"btcusdt@trade","event_type":"trade","event_time_ms":1788563387591,"raw_json":"{\"stream\":\"btcusdt@trade\",\"data\":{\"e\":\"trade\",\"E\":1788563387591,\"T\":1788563387591,\"s\":\"BTCUSDT\",\"t\":8054083475,\"p\":\"79607.10\",\"q\":\"0.001\",\"X\":\"MARKET\",\"m\":true,\"st\":1}}"}
{"receive_ns":1788563387557494000,"stream":"btcusdt@trade","event_type":"trade","event_time_ms":1788563387591,"raw_json":"{\"stream\":\"btcusdt@trade\",\"data\":{\"e\":\"trade\",\"E\":1788563387591,\"T\":1788563387591,\"s\":\"BTCUSDT\",\"t\":8054083476,\"p\":\"79607.10\",\"q\":\"0.003\",\"X\":\"MARKET\",\"m\":true,\"st\":1}}"}
{"receive_ns":1788563387557610000,"stream":"btcusdt@trade","event_type":"trade","event_time_ms":1788563387591,"raw_json":"{\"stream\":\"btcusdt@trade\",\"data\":{\"e\":\"trade\",\"E\":1788563387591,\"T\":1788563387591,\"s\":\"BTCUSDT\",\"t\":8054083477,\"p\":\"79607.10\",\"q\":\"0.001\",\"X\":\"MARKET\",\"m\":true,\"st\":1}}"}
{"receive_ns":1788563387557722000,"stream":"btcusdt@trade","event_type":"trade","event_time_ms":1788563387591,"raw_json":"{\"stream\":\"btcusdt@trade\",\"data\":{\"e\":\"trade\",\"E\":1788563387591,\"T\":1788563387591,\"s\":\"BTCUSDT\",\"t\":8054083478,\"p\":\"79607.10\",\"q\":\"0.003\",\"X\":\"MARKET\",\"m\":true,\"st\":1}}"}
{"receive_ns":1788563387557830000,"stream":"btcusdt@trade","event_type":"trade","event_time_ms":1788563387591,"raw_json":"{\"stream\":\"btcusdt@trade\",\"data\":{\"e\":\"trade\",\"E\":1788563387591,\"T\":1788563387591,\"s\":\"BTCUSDT\",\"t\":8054083479,\"p\":\"79607.10\",\"q\":\"0.004\",\"X\":\"MARKET\",\"m\":true,\"st\":1}}"}
{"receive_ns":1788563387557936000,"stream":"btcusdt@trade","event_type":"trade","event_time_ms":1788563387591,"raw_json":"{\"stream\":\"btcusdt@trade\",\"data\":{\"e\":\"trade\",\"E\":1788563387591,\"T\":1788563387591,\"s\":\"BTCUSDT\",\"t\":8054083480,\"p\":\"79607.10\",\"q\":\"0.003\",\"X\":\"MARKET\",\"m\":true,\"st\":1}}"}
{"receive_ns":1788563387558041000,"stream":"btcusdt@trade","event_type":"trade","event_time_ms":1788563387591,"raw_json":"{\"stream\":\"btcusdt@trade\",\"data\":{\"e\":\"trade\",\"E\":1788563387591,\"T\":1788563387591,\"s\":\"BTCUSDT\",\"t\":8054083481,\"p\":\"79607.10\",\"q\":\"0.004\",\"X\":\"MARKET\",\"m\":true,\"st\":1}}"}
{"receive_ns":1788563387558146000,"stream":"btcusdt@trade","event_type":"trade","event_time_ms":1788563387591,"raw_json":"{\"stream\":\"btcusdt@trade\",\"data\":{\"e\":\"trade\",\"E\":1788563387591,\"T\":1788563387591,\"s\":\"BTCUSDT\",\"t\":8054083482,\"p\":\"79607.10\",\"q\":\"0.004\",\"X\":\"MARKET\",\"m\":true,\"st\":1}}"}
{"receive_ns":1788563387558250000,"stream":"btcusdt@trade","event_type":"trade","event_time_ms":1788563387591,"raw_json":"{\"stream\":\"btcusdt@trade\",\"data\":{\"e\":\"trade\",\"E\":1788563387591,\"T\":1788563387591,\"s\":\"BTCUSDT\",\"t\":8054083483,\"p\":\"79607.10\",\"q\":\"0.001\",\"X\":\"MARKET\",\"m\":true,\"st\":1}}"}
{"receive_ns":1788563387558353000,"stream":"btcusdt@trade","event_type":"trade","event_time_ms":1788563387591,"raw_json":"{\"stream\":\"btcusdt@trade\",\"data\":{\"e\":\"trade\",\"E\":1788563387591,\"T\":1788563387591,\"s\":\"BTCUSDT\",\"t\":8054083484,\"p\":\"79607.10\",\"q\":\"0.002\",\"X\":\"MARKET\",\"m\":true,\"st\":1}}"}
{"receive_ns":1788563387558457000,"stream":"btcusdt@trade","event_type":"trade","event_time_ms":1788563387591,"raw_json":"{\"stream\":\"btcusdt@trade\",\"data\":{\"e\":\"trade\",\"E\":1788563387591,\"T\":1788563387591,\"s\":\"BTCUSDT\",\"t\":8054083485,\"p\":\"79607.10\",\"q\":\"0.004\",\"X\":\"MARKET\",\"m\":true,\"st\":1}}"}
{"receive_ns":1788563387558560000,"stream":"btcusdt@trade","event_type":"trade","event_time_ms":1788563387591,"raw_json":"{\"stream\":\"btcusdt@trade\",\"data\":{\"e\":\"trade\",\"E\":1788563387591,\"T\":1788563387591,\"s\":\"BTCUSDT\",\"t\":8054083486,\"p\":\"79607.10\",\"q\":\"0.005\",\"X\":\"MARKET\",\"m\":true,\"st\":1}}"}
{"receive_ns":1788563387558664000,"stream":"btcusdt@trade","event_type":"trade","event_time_ms":1788563387591,"raw_json":"{\"stream\":\"btcusdt@trade\",\"data\":{\"e\":\"trade\",\"E\":1788563387591,\"T\":1788563387591,\"s\":\"BTCUSDT\",\"t\":8054083487,\"p\":\"79607.10\",\"q\":\"0.001\",\"X\":\"MARKET\",\"m\":true,\"st\":1}}"}
{"receive_ns":1788563387558768000,"stream":"btcusdt@trade","event_type":"trade","event_time_ms":1788563387591,"raw_json":"{\"stream\":\"btcusdt@trade\",\"data\":{\"e\":\"trade\",\"E\":1788563387591,\"T\":1788563387591,\"s\":\"BTCUSDT\",\"t\":8054083488,\"p\":\"79607.10\",\"q\":\"0.007\",\"X\":\"MARKET\",\"m\":true,\"st\":1}}"}
{"receive_ns":1788563387558871000,"stream":"btcusdt@trade","event_type":"trade","event_time_ms":1788563387591,"raw_json":"{\"stream\":\"btcusdt@trade\",\"data\":{\"e\":\"trade\",\"E\":1788563387591,\"T\":1788563387591,\"s\":\"BTCUSDT\",\"t\":8054083489,\"p\":\"79607.10\",\"q\":\"0.001\",\"X\":\"MARKET\",\"m\":true,\"st\":1}}"}
{"receive_ns":1788563387558975000,"stream":"btcusdt@trade","event_type":"trade","event_time_ms":1788563387591,"raw_json":"{\"stream\":\"btcusdt@trade\",\"data\":{\"e\":\"trade\",\"E\":1788563387591,\"T\":1788563387591,\"s\":\"BTCUSDT\",\"t\":8054083490,\"p\":\"79607.10\",\"q\":\"0.001\",\"X\":\"MARKET\",\"m\":true,\"st\":1}}"}
{"receive_ns":1788563387559080000,"stream":"btcusdt@trade","event_type":"trade","event_time_ms":1788563387591,"raw_json":"{\"stream\":\"btcusdt@trade\",\"data\":{\"e\":\"trade\",\"E\":1788563387591,\"T\":1788563387591,\"s\":\"BTCUSDT\",\"t\":8054083491,\"p\":\"79607.10\",\"q\":\"0.003\",\"X\":\"MARKET\",\"m\":true,\"st\":1}}"}
{"receive_ns":1788563387559184000,"stream":"btcusdt@trade","event_type":"trade","event_time_ms":1788563387591,"raw_json":"{\"stream\":\"btcusdt@trade\",\"data\":{\"e\":\"trade\",\"E\":1788563387591,\"T\":1788563387591,\"s\":\"BTCUSDT\",\"t\":8054083492,\"p\":\"79607.10\",\"q\":\"1.276\",\"X\":\"MARKET\",\"m\":true,\"st\":1}}"}
{"receive_ns":1788563387559288000,"stream":"btcusdt@trade","event_type":"trade","event_time_ms":1788563387591,"raw_json":"{\"stream\":\"btcusdt@trade\",\"data\":{\"e\":\"trade\",\"E\":1788563387591,\"T\":1788563387591,\"s\":\"BTCUSDT\",\"t\":8054083493,\"p\":\"79607.10\",\"q\":\"0.004\",\"X\":\"MARKET\",\"m\":true,\"st\":1}}"}
{"receive_ns":1788563387559392000,"stream":"btcusdt@trade","event_type":"trade","event_time_ms":1788563387591,"raw_json":"{\"stream\":\"btcusdt@trade\",\"data\":{\"e\":\"trade\",\"E\":1788563387591,\"T\":1788563387591,\"s\":\"BTCUSDT\",\"t\":8054083494,\"p\":\"79607.10\",\"q\":\"0.002\",\"X\":\"MARKET\",\"m\":true,\"st\":1}}"}
{"receive_ns":1788563387559497000,"stream":"btcusdt@trade","event_type":"trade","event_time_ms":1788563387591,"raw_json":"{\"stream\":\"btcusdt@trade\",\"data\":{\"e\":\"trade\",\"E\":1788563387591,\"T\":1788563387591,\"s\":\"BTCUSDT\",\"t\":8054083495,\"p\":\"79607.10\",\"q\":\"0.004\",\"X\":\"MARKET\",\"m\":true,\"st\":1}}"}
{"receive_ns":1788563387559649000,"stream":"btcusdt@bookTicker","event_type":"bookTicker","event_time_ms":1788563387591,"raw_json":"{\"stream\":\"btcusdt@bookTicker\",\"data\":{\"e\":\"bookTicker\",\"u\":11478233036485,\"s\":\"BTCUSDT\",\"ps\":\"BTCUSDT\",\"b\":\"79607.10\",\"B\":\"3.359\",\"a\":\"79607.20\",\"A\":\"7.164\",\"T\":1788563387591,\"E\":1788563387591,\"st\":1}}"}
{"receive_ns":1788563387559765000,"stream":"btcusdt@trade","event_type":"trade","event_time_ms":1788563387591,"raw_json":"{\"stream\":\"btcusdt@trade\",\"data\":{\"e\":\"trade\",\"E\":1788563387591,\"T\":1788563387591,\"s\":\"BTCUSDT\",\"t\":8054083496,\"p\":\"79607.10\",\"q\":\"0.001\",\"X\":\"MARKET\",\"m\":true,\"st\":1}}"}
{"receive_ns":1788563387559872000,"stream":"btcusdt@trade","event_type":"trade","event_time_ms":1788563387591,"raw_json":"{\"stream\":\"btcusdt@trade\",\"data\":{\"e\":\"trade\",\"E\":1788563387591,\"T\":1788563387591,\"s\":\"BTCUSDT\",\"t\":8054083497,\"p\":\"79607.10\",\"q\":\"0.246\",\"X\":\"MARKET\",\"m\":true,\"st\":1}}"}
{"receive_ns":1788563387560004000,"stream":"btcusdt@bookTicker","event_type":"bookTicker","event_time_ms":1788563387592,"raw_json":"{\"stream\":\"btcusdt@bookTicker\",\"data\":{\"e\":\"bookTicker\",\"u\":11478233036515,\"s\":\"BTCUSDT\",\"ps\":\"BTCUSDT\",\"b\":\"79607.10\",\"B\":\"3.945\",\"a\":\"79607.20\",\"A\":\"7.164\",\"T\":1788563387592,\"E\":1788563387592,\"st\":1}}"}
{"receive_ns":1788563387560121000,"stream":"btcusdt@bookTicker","event_type":"bookTicker","event_time_ms":1788563387592,"raw_json":"{\"stream\":\"btcusdt@bookTicker\",\"data\":{\"e\":\"bookTicker\",\"u\":11478233036522,\"s\":\"BTCUSDT\",\"ps\":\"BTCUSDT\",\"b\":\"79607.10\",\"B\":\"3.946\",\"a\":\"79607.20\",\"A\":\"7.164\",\"T\":1788563387592,\"E\":1788563387592,\"st\":1}}"}
{"receive_ns":1788563387560236000,"stream":"btcusdt@bookTicker","event_type":"bookTicker","event_time_ms":1788563387592,"raw_json":"{\"stream\":\"btcusdt@bookTicker\",\"data\":{\"e\":\"bookTicker\",\"u\":11478233036538,\"s\":\"BTCUSDT\",\"ps\":\"BTCUSDT\",\"b\":\"79607.10\",\"B\":\"3.946\",\"a\":\"79607.20\",\"A\":\"7.165\",\"T\":1788563387592,\"E\":1788563387592,\"st\":1}}"}
{"receive_ns":1788563387560367000,"stream":"btcusdt@bookTicker","event_type":"bookTicker","event_time_ms":1788563387592,"raw_json":"{\"stream\":\"btcusdt@bookTicker\",\"data\":{\"e\":\"bookTicker\",\"u\":11478233036600,\"s\":\"BTCUSDT\",\"ps\":\"BTCUSDT\",\"b\":\"79607.10\",\"B\":\"3.946\",\"a\":\"79607.20\",\"A\":\"7.365\",\"T\":1788563387592,\"E\":1788563387592,\"st\":1}}"}
{"receive_ns":1788563387560486000,"stream":"btcusdt@bookTicker","event_type":"bookTicker","event_time_ms":1788563387592,"raw_json":"{\"stream\":\"btcusdt@bookTicker\",\"data\":{\"e\":\"bookTicker\",\"u\":11478233036754,\"s\":\"BTCUSDT\",\"ps\":\"BTCUSDT\",\"b\":\"79607.10\",\"B\":\"4.008\",\"a\":\"79607.20\",\"A\":\"7.365\",\"T\":1788563387592,\"E\":1788563387592,\"st\":1}}"}
{"receive_ns":1788563387560600000,"stream":"btcusdt@bookTicker","event_type":"bookTicker","event_time_ms":1788563387592,"raw_json":"{\"stream\":\"btcusdt@bookTicker\",\"data\":{\"e\":\"bookTicker\",\"u\":11478233036771,\"s\":\"BTCUSDT\",\"ps\":\"BTCUSDT\",\"b\":\"79607.10\",\"B\":\"4.009\",\"a\":\"79607.20\",\"A\":\"7.365\",\"T\":1788563387592,\"E\":1788563387592,\"st\":1}}"}
{"receive_ns":1788563387560713000,"stream":"btcusdt@bookTicker","event_type":"bookTicker","event_time_ms":1788563387592,"raw_json":"{\"stream\":\"btcusdt@bookTicker\",\"data\":{\"e\":\"bookTicker\",\"u\":11478233036785,\"s\":\"BTCUSDT\",\"ps\":\"BTCUSDT\",\"b\":\"79607.10\",\"B\":\"4.057\",\"a\":\"79607.20\",\"A\":\"7.365\",\"T\":1788563387592,\"E\":1788563387592,\"st\":1}}"}
{"receive_ns":1788563387560845000,"stream":"btcusdt@bookTicker","event_type":"bookTicker","event_time_ms":1788563387593,"raw_json":"{\"stream\":\"btcusdt@bookTicker\",\"data\":{\"e\":\"bookTicker\",\"u\":11478233036853,\"s\":\"BTCUSDT\",\"ps\":\"BTCUSDT\",\"b\":\"79607.10\",\"B\":\"4.055\",\"a\":\"79607.20\",\"A\":\"7.365\",\"T\":1788563387593,\"E\":1788563387593,\"st\":1}}"}
{"receive_ns":1788563387560962000,"stream":"btcusdt@bookTicker","event_type":"bookTicker","event_time_ms":1788563387593,"raw_json":"{\"stream\":\"btcusdt@bookTicker\",\"data\":{\"e\":\"bookTicker\",\"u\":11478233036870,\"s\":\"BTCUSDT\",\"ps\":\"BTCUSDT\",\"b\":\"79607.10\",\"B\":\"4.055\",\"a\":\"79607.20\",\"A\":\"7.364\",\"T\":1788563387593,\"E\":1788563387593,\"st\":1}}"}
{"receive_ns":1788563387561076000,"stream":"btcusdt@bookTicker","event_type":"bookTicker","event_time_ms":1788563387593,"raw_json":"{\"stream\":\"btcusdt@bookTicker\",\"data\":{\"e\":\"bookTicker\",\"u\":11478233036871,\"s\":\"BTCUSDT\",\"ps\":\"BTCUSDT\",\"b\":\"79607.10\",\"B\":\"4.054\",\"a\":\"79607.20\",\"A\":\"7.364\",\"T\":1788563387593,\"E\":1788563387593,\"st\":1}}"}
{"receive_ns":1788563387561190000,"stream":"btcusdt@bookTicker","event_type":"bookTicker","event_time_ms":1788563387593,"raw_json":"{\"stream\":\"btcusdt@bookTicker\",\"data\":{\"e\":\"bookTicker\",\"u\":11478233036902,\"s\":\"BTCUSDT\",\"ps\":\"BTCUSDT\",\"b\":\"79607.10\",\"B\":\"4.077\",\"a\":\"79607.20\",\"A\":\"7.364\",\"T\":1788563387593,\"E\":1788563387593,\"st\":1}}"}
{"receive_ns":1788563387561322000,"stream":"btcusdt@bookTicker","event_type":"bookTicker","event_time_ms":1788563387593,"raw_json":"{\"stream\":\"btcusdt@bookTicker\",\"data\":{\"e\":\"bookTicker\",\"u\":11478233036918,\"s\":\"BTCUSDT\",\"ps\":\"BTCUSDT\",\"b\":\"79607.10\",\"B\":\"4.077\",\"a\":\"79607.20\",\"A\":\"7.694\",\"T\":1788563387593,\"E\":1788563387593,\"st\":1}}"}
{"receive_ns":1788563387561455000,"stream":"btcusdt@bookTicker","event_type":"bookTicker","event_time_ms":1788563387594,"raw_json":"{\"stream\":\"btcusdt@bookTicker\",\"data\":{\"e\":\"bookTicker\",\"u\":11478233037056,\"s\":\"BTCUSDT\",\"ps\":\"BTCUSDT\",\"b\":\"79607.10\",\"B\":\"4.079\",\"a\":\"79607.20\",\"A\":\"7.694\",\"T\":1788563387594,\"E\":1788563387594,\"st\":1}}"}
{"receive_ns":1788563387561588000,"stream":"btcusdt@bookTicker","event_type":"bookTicker","event_time_ms":1788563387594,"raw_json":"{\"stream\":\"btcusdt@bookTicker\",\"data\":{\"e\":\"bookTicker\",\"u\":11478233037133,\"s\":\"BTCUSDT\",\"ps\":\"BTCUSDT\",\"b\":\"79607.10\",\"B\":\"4.092\",\"a\":\"79607.20\",\"A\":\"7.694\",\"T\":1788563387594,\"E\":1788563387594,\"st\":1}}"}
{"receive_ns":1788563387561708000,"stream":"btcusdt@bookTicker","event_type":"bookTicker","event_time_ms":1788563387594,"raw_json":"{\"stream\":\"btcusdt@bookTicker\",\"data\":{\"e\":\"bookTicker\",\"u\":11478233037144,\"s\":\"BTCUSDT\",\"ps\":\"BTCUSDT\",\"b\":\"79607.10\",\"B\":\"4.093\",\"a\":\"79607.20\",\"A\":\"7.694\",\"T\":1788563387594,\"E\":1788563387594,\"st\":1}}"}
{"receive_ns":1788563387561925000,"stream":"btcusdt@bookTicker","event_type":"bookTicker","event_time_ms":1788563387596,"raw_json":"{\"stream\":\"btcusdt@bookTicker\",\"data\":{\"e\":\"bookTicker\",\"u\":11478233037359,\"s\":\"BTCUSDT\",\"ps\":\"BTCUSDT\",\"b\":\"79607.10\",\"B\":\"4.093\",\"a\":\"79607.20\",\"A\":\"8.104\",\"T\":1788563387596,\"E\":1788563387596,\"st\":1}}"}
{"receive_ns":1788563387581020000,"stream":"btcusdt@bookTicker","event_type":"bookTicker","event_time_ms":1788563387618,"raw_json":"{\"stream\":\"btcusdt@bookTicker\",\"data\":{\"e\":\"bookTicker\",\"u\":11478233038684,\"s\":\"BTCUSDT\",\"ps\":\"BTCUSDT\",\"b\":\"79607.10\",\"B\":\"4.094\",\"a\":\"79607.20\",\"A\":\"8.104\",\"T\":1788563387618,\"E\":1788563387618,\"st\":1}}"}
{"receive_ns":1788563387645417000,"stream":"btcusdt@depth@100ms","event_type":"depthUpdate","event_time_ms":1788563387675,"raw_json":"{\"stream\":\"btcusdt@depth@100ms\",\"data\":{\"e\":\"depthUpdate\",\"E\":1788563387675,\"T\":1788563387673,\"s\":\"BTCUSDT\",\"ps\":\"BTCUSDT\",\"U\":11478233035908,\"u\":11478233041386,\"pu\":11478233035823,\"b\":[[\"1000.00\",\"24.754\"],[\"29407.10\",\"0.623\"],[\"29507.10\",\"1.477\"],[\"63685.70\",\"0.001\"],[\"63686.00\",\"0.000\"],[\"71646.30\",\"0.002\"],[\"71684.00\",\"0.000\"],[\"78015.00\",\"10.700\"],[\"78811.00\",\"15.338\"],[\"78886.90\",\"1.835\"],[\"79232.90\",\"0.141\"],[\"79395.90\",\"0.000\"],[\"79396.00\",\"5.013\"],[\"79483.10\",\"0.527\"],[\"79491.70\",\"0.483\"],[\"79548.10\",\"0.003\"],[\"79552.50\",\"2.010\"],[\"79557.40\",\"6.975\"],[\"79559.80\",\"0.001\"],[\"79560.10\",\"0.003\"],[\"79564.00\",\"1.273\"],[\"79575.20\",\"0.901\"],[\"79575.30\",\"0.074\"],[\"79576.20\",\"0.001\"],[\"79578.50\",\"0.080\"],[\"79579.40\",\"0.000\"],[\"79579.60\",\"0.623\"],[\"79580.70\",\"0.076\"],[\"79583.80\",\"0.001\"],[\"79584.80\",\"0.256\"],[\"79587.30\",\"0.364\"],[\"79587.40\",\"0.078\"],[\"79587.70\",\"0.040\"],[\"79588.30\",\"0.008\"],[\"79588.50\",\"0.000\"],[\"79589.20\",\"0.470\"],[\"79589.30\",\"0.063\"],[\"79589.50\",\"0.077\"],[\"79589.60\",\"0.024\"],[\"79590.70\",\"0.000\"],[\"79592.20\",\"0.022\"],[\"79592.60\",\"0.004\"],[\"79592.70\",\"0.001\"],[\"79593.50\",\"0.003\"],[\"79593.60\",\"0.167\"],[\"79594.00\",\"0.005\"],[\"79595.20\",\"0.250\"],[\"79595.90\",\"0.004\"],[\"79596.40\",\"0.003\"],[\"79596.60\",\"0.001\"],[\"79597.20\",\"0.186\"],[\"79598.40\",\"0.006\"],[\"79598.90\",\"0.000\"],[\"79599.00\",\"0.007\"],[\"79599.10\",\"0.020\"],[\"79599.20\",\"0.003\"],[\"79599.30\",\"0.002\"],[\"79599.40\",\"0.001\"],[\"79599.60\",\"0.000\"],[\"79599.70\",\"0.000\"],[\"79599.80\",\"0.000\"],[\"79600.00\",\"0.008\"],[\"79600.10\",\"0.001\"],[\"79600.20\",\"0.026\"],[\"79600.50\",\"0.028\"],[\"79600.60\",\"0.029\"],[\"79600.80\",\"0.027\"],[\"79601.00\",\"0.676\"],[\"79601.30\",\"0.027\"],[\"79601.60\",\"0.027\"],[\"79602.20\",\"0.022\"],[\"79602.40\",\"0.280\"],[\"79602.50\",\"0.001\"],[\"79602.60\",\"0.001\"],[\"79602.70\",\"0.000\"],[\"79602.80\",\"0.026\"],[\"79602.90\",\"0.002\"],[\"79603.00\",\"0.003\"],[\"79603.10\",\"0.226\"],[\"79603.20\",\"0.003\"],[\"79603.60\",\"1.519\"],[\"79603.70\",\"0.011\"],[\"79606.10\",\"0.001\"],[\"79606.40\",\"0.038\"],[\"79607.00\",\"0.064\"],[\"79607.10\",\"4.094\"]],\"a\":[[\"79607.20\",\"8.104\"],[\"79608.10\",\"0.029\"],[\"79609.50\",\"0.005\"],[\"79611.00\",\"0.136\"],[\"79612.10\",\"0.002\"],[\"79613.40\",\"0.010\"],[\"79615.70\",\"1.197\"],[\"79618.20\",\"0.001\"],[\"79618.30\",\"0.440\"],[\"79620.60\",\"7.701\"],[\"79621.90\",\"0.372\"],[\"79623.00\",\"0.000\"],[\"79623.10\",\"0.565\"],[\"79624.40\",\"0.452\"],[\"79625.50\",\"0.006\"],[\"79630.20\",\"0.862\"],[\"79630.50\",\"0.038\"],[\"79650.00\",\"3.173\"],[\"79650.30\",\"0.001\"],[\"79680.70\",\"0.269\"],[\"79689.50\",\"0.001\"],[\"79728.70\",\"0.294\"],[\"79968.00\",\"0.867\"],[\"79969.40\",\"1.411\"],[\"79997.80\",\"0.525\"],[\"80403.30\",\"22.286\"]],\"st\":1}}"}
{"receive_ns":1788563387744967000,"stream":"btcusdt@depth@100ms","event_type":"depthUpdate","event_time_ms":1788563387777,"raw_json":"{\"stream\":\"btcusdt@depth@100ms\",\"data\":{\"e\":\"depthUpdate\",\"E\":1788563387777,\"T\":1788563387776,\"s\":\"BTCUSDT\",\"ps\":\"BTCUSDT\",\"U\":11478233041501,\"u\":11478233046110,\"pu\":11478233041386,\"b\":[[\"1000.00\",\"24.754\"],[\"29407.10\",\"0.798\"],[\"29507.10\",\"1.302\"],[\"71646.30\",\"0.002\"],[\"76422.80\",\"0.002\"],[\"77616.90\",\"1.480\"],[\"78452.80\",\"40.346\"],[\"78691.60\",\"10.766\"],[\"78811.00\",\"15.338\"],[\"78970.20\",\"8.000\"],[\"79523.80\",\"0.485\"],[\"79523.90\",\"2.523\"],[\"79588.50\",\"0.076\"],[\"79589.50\",\"0.001\"],[\"79592.50\",\"0.018\"],[\"79593.00\",\"0.017\"],[\"79601.40\",\"0.026\"],[\"79601.70\",\"0.026\"],[\"79601.90\",\"0.026\"],[\"79602.40\",\"0.254\"],[\"79602.80\",\"0.000\"],[\"79606.90\",\"0.196\"],[\"79607.00\",\"1.486\"]],\"a\":[[\"80204.30\",\"4.358\"],[\"80403.30\",\"22.286\"],[\"80642.10\",\"33.049\"],[\"80761.50\",\"20.593\"]],\"st\":1}}"}
{"receive_ns":1788563387842053000,"stream":"btcusdt@depth@100ms","event_type":"depthUpdate","event_time_ms":1788563387879,"raw_json":"{\"stream\":\"btcusdt@depth@100ms\",\"data\":{\"e\":\"depthUpdate\",\"E\":1788563387879,\"T\":1788563387878,\"s\":\"BTCUSDT\",\"ps\":\"BTCUSDT\",\"U\":11478233046154,\"u\":11478233050464,\"pu\":11478233046110,\"b\":[[\"29407.10\",\"0.980\"],[\"29507.10\",\"1.120\"],[\"63686.00\",\"0.000\"],[\"71646.30\",\"0.002\"],[\"76422.80\",\"0.000\"],[\"78811.00\",\"15.338\"],[\"79209.10\",\"4.473\"],[\"79232.90\",\"0.141\"],[\"79368.20\",\"0.000\"],[\"79491.70\",\"0.853\"],[\"79493.70\",\"0.863\"],[\"79567.20\",\"0.242\"],[\"79578.50\",\"0.004\"],[\"79582.80\",\"0.629\"],[\"79583.20\",\"0.277\"],[\"79583.80\",\"0.001\"],[\"79583.90\",\"0.060\"],[\"79589.20\",\"0.195\"],[\"79589.90\",\"0.078\"],[\"79595.20\",\"0.249\"],[\"79596.90\",\"0.001\"],[\"79597.00\",\"0.252\"],[\"79600.20\",\"0.000\"],[\"79600.50\",\"0.002\"],[\"79600.60\",\"0.003\"],[\"79600.80\",\"0.001\"],[\"79602.40\",\"0.280\"],[\"79602.90\",\"0.028\"],[\"79603.80\",\"0.029\"],[\"79603.90\",\"0.027\"],[\"79605.60\",\"0.026\"]],\"a\":[[\"79620.70\",\"0.748\"],[\"79639.10\",\"0.455\"],[\"79647.10\",\"0.069\"],[\"79774.40\",\"2.254\"],[\"79968.00\",\"0.867\"],[\"79969.40\",\"1.160\"],[\"79997.80\",\"0.525\"],[\"80353.50\",\"2.418\"],[\"80403.30\",\"22.286\"],[\"80721.70\",\"58.897\"]],\"st\":1}}"}
{"receive_ns":1788563387943510000,"stream":"btcusdt@depth@100ms","event_type":"depthUpdate","event_time_ms":1788563387981,"raw_json":"{\"stream\":\"btcusdt@depth@100ms\",\"data\":{\"e\":\"depthUpdate\",\"E\":1788563387981,\"T\":1788563387980,\"s\":\"BTCUSDT\",\"ps\":\"BTCUSDT\",\"U\":11478233050540,\"u\":11478233055513,\"pu\":11478233050464,\"b\":[[\"1000.00\",\"24.754\"],[\"29407.10\",\"1.155\"],[\"29507.10\",\"0.945\"],[\"63686.00\",\"0.002\"],[\"71646.30\",\"0.002\"],[\"76422.80\",\"0.002\"],[\"78293.60\",\"4.133\"],[\"78452.80\",\"41.237\"],[\"78492.60\",\"52.328\"],[\"78691.60\",\"11.528\"],[\"78811.00\",\"15.338\"],[\"78886.90\",\"0.949\"],[\"79209.10\",\"4.598\"],[\"79491.70\",\"0.351\"],[\"79579.50\",\"0.010\"],[\"79579.60\",\"0.547\"],[\"79581.80\",\"2.949\"],[\"79583.70\",\"0.016\"],[\"79591.20\",\"1.231\"],[\"79601.00\",\"0.650\"],[\"79604.50\",\"0.000\"]],\"a\":[[\"79616.00\",\"0.020\"],[\"79618.30\",\"0.440\"],[\"79621.90\",\"0.000\"],[\"79623.00\",\"0.372\"],[\"80005.30\",\"0.001\"],[\"80363.50\",\"14.156\"],[\"80403.30\",\"22.286\"],[\"80562.50\",\"49.590\"],[\"80598.60\",\"12.822\"],[\"80761.50\",\"21.459\"],[\"80920.70\",\"4.307\"]],\"st\":1}}"}
{"receive_ns":1788563388038618000,"stream":"btcusdt@bookTicker","event_type":"bookTicker","event_time_ms":1788563388075,"raw_json":"{\"stream\":\"btcusdt@bookTicker\",\"data\":{\"e\":\"bookTicker\",\"u\":11478233059868,\"s\":\"BTCUSDT\",\"ps\":\"BTCUSDT\",\"b\":\"79607.10\",\"B\":\"3.659\",\"a\":\"79607.20\",\"A\":\"8.104\",\"T\":1788563388075,\"E\":1788563388075,\"st\":1}}"}
{"receive_ns":1788563388042505000,"stream":"btcusdt@bookTicker","event_type":"bookTicker","event_time_ms":1788563388078,"raw_json":"{\"stream\":\"btcusdt@bookTicker\",\"data\":{\"e\":\"bookTicker\",\"u\":11478233060067,\"s\":\"BTCUSDT\",\"ps\":\"BTCUSDT\",\"b\":\"79607.10\",\"B\":\"4.093\",\"a\":\"79607.20\",\"A\":\"8.104\",\"T\":1788563388078,\"E\":1788563388078,\"st\":1}}"}
{"receive_ns":1788563388042759000,"stream":"btcusdt@bookTicker","event_type":"bookTicker","event_time_ms":1788563388079,"raw_json":"{\"stream\":\"btcusdt@bookTicker\",\"data\":{\"e\":\"bookTicker\",\"u\":11478233060113,\"s\":\"BTCUSDT\",\"ps\":\"BTCUSDT\",\"b\":\"79607.10\",\"B\":\"4.091\",\"a\":\"79607.20\",\"A\":\"8.104\",\"T\":1788563388079,\"E\":1788563388079,\"st\":1}}"}
{"receive_ns":1788563388042918000,"stream":"btcusdt@bookTicker","event_type":"bookTicker","event_time_ms":1788563388079,"raw_json":"{\"stream\":\"btcusdt@bookTicker\",\"data\":{\"e\":\"bookTicker\",\"u\":11478233060121,\"s\":\"BTCUSDT\",\"ps\":\"BTCUSDT\",\"b\":\"79607.10\",\"B\":\"4.090\",\"a\":\"79607.20\",\"A\":\"8.104\",\"T\":1788563388079,\"E\":1788563388079,\"st\":1}}"}
{"receive_ns":1788563388043797000,"stream":"btcusdt@bookTicker","event_type":"bookTicker","event_time_ms":1788563388080,"raw_json":"{\"stream\":\"btcusdt@bookTicker\",\"data\":{\"e\":\"bookTicker\",\"u\":11478233060163,\"s\":\"BTCUSDT\",\"ps\":\"BTCUSDT\",\"b\":\"79607.10\",\"B\":\"4.091\",\"a\":\"79607.20\",\"A\":\"8.104\",\"T\":1788563388080,\"E\":1788563388080,\"st\":1}}"}
{"receive_ns":1788563388047660000,"stream":"btcusdt@depth@100ms","event_type":"depthUpdate","event_time_ms":1788563388083,"raw_json":"{\"stream\":\"btcusdt@depth@100ms\",\"data\":{\"e\":\"depthUpdate\",\"E\":1788563388083,\"T\":1788563388081,\"s\":\"BTCUSDT\",\"ps\":\"BTCUSDT\",\"U\":11478233055571,\"u\":11478233060258,\"pu\":11478233055513,\"b\":[[\"1000.00\",\"24.754\"],[\"29407.10\",\"1.337\"],[\"29507.10\",\"0.763\"],[\"63686.00\",\"0.000\"],[\"71646.30\",\"0.002\"],[\"76422.80\",\"0.000\"],[\"78394.60\",\"0.000\"],[\"78691.60\",\"10.767\"],[\"78811.00\",\"15.338\"],[\"79010.00\",\"4.312\"],[\"79209.00\",\"0.002\"],[\"79232.90\",\"0.141\"],[\"79368.20\",\"0.002\"],[\"79491.70\",\"0.000\"],[\"79493.70\",\"0.631\"],[\"79523.80\",\"0.360\"],[\"79524.20\",\"0.164\"],[\"79524.60\",\"0.000\"],[\"79551.30\",\"0.005\"],[\"79552.50\",\"0.010\"],[\"79557.90\",\"10.205\"],[\"79583.20\",\"0.102\"],[\"79588.30\",\"0.004\"],[\"79589.20\",\"0.772\"],[\"79589.80\",\"0.006\"],[\"79589.90\",\"0.082\"],[\"79591.70\",\"0.000\"],[\"79592.80\",\"0.004\"],[\"79595.70\",\"0.001\"],[\"79595.90\",\"0.008\"],[\"79597.70\",\"0.004\"],[\"79601.30\",\"0.001\"],[\"79601.40\",\"0.000\"],[\"79601.60\",\"0.001\"],[\"79604.00\",\"0.030\"],[\"79604.20\",\"0.027\"],[\"79604.30\",\"0.026\"],[\"79604.70\",\"0.027\"],[\"79604.80\",\"0.002\"],[\"79606.40\",\"0.002\"],[\"79607.10\",\"4.091\"]],\"a\":[[\"79615.00\",\"0.033\"],[\"79615.10\",\"0.000\"],[\"79615.30\",\"0.067\"],[\"79618.20\",\"0.314\"],[\"79639.10\",\"0.457\"],[\"79663.00\",\"0.002\"],[\"79706.50\",\"0.076\"],[\"79706.90\",\"0.000\"],[\"79707.80\",\"0.000\"],[\"79774.40\",\"2.003\"],[\"79968.00\",\"0.867\"],[\"79969.40\",\"1.168\"],[\"79997.80\",\"0.525\"],[\"79999.30\",\"0.055\"],[\"80005.20\",\"3.629\"],[\"80177.90\",\"0.000\"],[\"80403.30\",\"22.289\"],[\"80819.70\",\"0.000\"]],\"st\":1}}"}
{"receive_ns":1788563388156242000,"stream":"btcusdt@depth@100ms","event_type":"depthUpdate","event_time_ms":1788563388185,"raw_json":"{\"stream\":\"btcusdt@depth@100ms\",\"data\":{\"e\":\"depthUpdate\",\"E\":1788563388185,\"T\":1788563388182,\"s\":\"BTCUSDT\",\"ps\":\"BTCUSDT\",\"U\":11478233060289,\"u\":11478233064742,\"pu\":11478233060258,\"b\":[[\"29407.10\",\"1.512\"],[\"29507.10\",\"0.588\"],[\"63686.00\",\"0.000\"],[\"71646.30\",\"0.002\"],[\"78512.70\",\"2.033\"],[\"78568.50\",\"5.976\"],[\"78811.00\",\"15.338\"],[\"78890.60\",\"39.845\"],[\"79209.10\",\"4.608\"],[\"79589.20\",\"0.972\"],[\"79589.30\",\"0.067\"],[\"79589.90\",\"0.078\"],[\"79591.20\",\"1.307\"],[\"79591.60\",\"0.004\"],[\"79591.80\",\"0.002\"],[\"79595.90\",\"0.004\"],[\"79601.70\",\"0.000\"],[\"79602.20\",\"0.020\"],[\"79603.00\",\"0.005\"],[\"79603.70\",\"0.037\"],[\"79604.30\",\"0.000\"],[\"79604.70\",\"0.001\"],[\"79604.90\",\"0.000\"]],\"a\":[[\"79615.00\",\"0.037\"],[\"79615.10\",\"0.313\"],[\"79615.30\",\"0.063\"],[\"79618.20\",\"0.001\"],[\"79630.50\",\"0.040\"],[\"79630.70\",\"0.005\"],[\"79682.60\",\"0.084\"],[\"79706.40\",\"0.002\"],[\"79706.60\",\"0.301\"],[\"79706.90\",\"0.000\"],[\"79707.10\",\"0.000\"],[\"79707.40\",\"0.002\"],[\"79969.40\",\"1.367\"],[\"80403.30\",\"22.287\"],[\"80761.50\",\"22.386\"]],\"st\":1}}"}
{"receive_ns":1788563388200327000,"stream":"btcusdt@bookTicker","event_type":"bookTicker","event_time_ms":1788563388238,"raw_json":"{\"stream\":\"btcusdt@bookTicker\",\"data\":{\"e\":\"bookTicker\",\"u\":11478233067665,\"s\":\"BTCUSDT\",\"ps\":\"BTCUSDT\",\"b\":\"79607.10\",\"B\":\"4.095\",\"a\":\"79607.20\",\"A\":\"8.104\",\"T\":1788563388238,\"E\":1788563388238,\"st\":1}}"}
{"receive_ns":1788563388249176000,"stream":"btcusdt@depth@100ms","event_type":"depthUpdate","event_time_ms":1788563388287,"raw_json":"{\"stream\":\"btcusdt@depth@100ms\",\"data\":{\"e\":\"depthUpdate\",\"E\":1788563388287,\"T\":1788563388286,\"s\":\"BTCUSDT\",\"ps\":\"BTCUSDT\",\"U\":11478233065004,\"u\":11478233069923,\"pu\":11478233064742,\"b\":[[\"1000.00\",\"24.754\"],[\"29407.10\",\"1.694\"],[\"29507.10\",\"0.406\"],[\"71646.30\",\"0.002\"],[\"75626.70\",\"0.019\"],[\"76422.80\",\"0.002\"],[\"78293.60\",\"5.026\"],[\"78373.20\",\"9.761\"],[\"78492.60\",\"54.237\"],[\"78691.60\",\"11.528\"],[\"78811.00\",\"15.338\"],[\"79483.10\",\"0.001\"],[\"79483.20\",\"0.518\"],[\"79524.00\",\"0.127\"],[\"79524.20\",\"0.039\"],[\"79533.70\",\"0.829\"],[\"79549.60\",\"0.691\"],[\"79589.20\",\"0.470\"],[\"79604.30\",\"0.026\"],[\"79606.60\",\"0.037\"],[\"79606.90\",\"0.198\"],[\"79607.10\",\"4.095\"]],\"a\":[[\"79668.10\",\"1.857\"],[\"79668.80\",\"0.316\"],[\"79671.50\",\"0.002\"],[\"79676.80\",\"4.843\"],[\"79676.90\",\"25.638\"],[\"79677.70\",\"0.017\"],[\"79705.30\",\"0.000\"],[\"79706.60\",\"0.301\"],[\"79706.90\",\"0.000\"],[\"79707.20\",\"0.000\"],[\"79707.30\",\"0.127\"],[\"79707.40\",\"0.003\"],[\"79728.70\",\"0.294\"],[\"79969.40\",\"0.948\"],[\"80403.30\",\"22.287\"],[\"80562.50\",\"50.830\"],[\"80678.00\",\"4.869\"],[\"80920.70\",\"5.171\"],[\"81199.30\",\"10.753\"]],\"st\":1}}"}
{"receive_ns":1788563388293424000,"stream":"btcusdt@bookTicker","event_type":"bookTicker","event_time_ms":1788563388330,"raw_json":"{\"stream\":\"btcusdt@bookTicker\",\"data\":{\"e\":\"bookTicker\",\"u\":11478233072220,\"s\":\"BTCUSDT\",\"ps\":\"BTCUSDT\",\"b\":\"79607.10\",\"B\":\"3.451\",\"a\":\"79607.20\",\"A\":\"8.104\",\"T\":1788563388330,\"E\":1788563388330,\"st\":1}}"}
{"receive_ns":1788563388299822000,"stream":"btcusdt@bookTicker","event_type":"bookTicker","event_time_ms":1788563388331,"raw_json":"{\"stream\":\"btcusdt@bookTicker\",\"data\":{\"e\":\"bookTicker\",\"u\":11478233072259,\"s\":\"BTCUSDT\",\"ps\":\"BTCUSDT\",\"b\":\"79607.10\",\"B\":\"3.453\",\"a\":\"79607.20\",\"A\":\"8.104\",\"T\":1788563388331,\"E\":1788563388331,\"st\":1}}"}
{"receive_ns":1788563388300129000,"stream":"btcusdt@bookTicker","event_type":"bookTicker","event_time_ms":1788563388333,"raw_json":"{\"stream\":\"btcusdt@bookTicker\",\"data\":{\"e\":\"bookTicker\",\"u\":11478233072410,\"s\":\"BTCUSDT\",\"ps\":\"BTCUSDT\",\"b\":\"79607.10\",\"B\":\"4.098\",\"a\":\"79607.20\",\"A\":\"8.104\",\"T\":1788563388333,\"E\":1788563388333,\"st\":1}}"}
{"receive_ns":1788563388311338000,"stream":"btcusdt@bookTicker","event_type":"bookTicker","event_time_ms":1788563388349,"raw_json":"{\"stream\":\"btcusdt@bookTicker\",\"data\":{\"e\":\"bookTicker\",\"u\":11478233072887,\"s\":\"BTCUSDT\",\"ps\":\"BTCUSDT\",\"b\":\"79607.10\",\"B\":\"2.933\",\"a\":\"79607.20\",\"A\":\"8.104\",\"T\":1788563388349,\"E\":1788563388349,\"st\":1}}"}
{"receive_ns":1788563388312213000,"stream":"btcusdt@bookTicker","event_type":"bookTicker","event_time_ms":1788563388350,"raw_json":"{\"stream\":\"btcusdt@bookTicker\",\"data\":{\"e\":\"bookTicker\",\"u\":11478233072932,\"s\":\"BTCUSDT\",\"ps\":\"BTCUSDT\",\"b\":\"79607.10\",\"B\":\"2.931\",\"a\":\"79607.20\",\"A\":\"8.104\",\"T\":1788563388350,\"E\":1788563388350,\"st\":1}}"}
{"receive_ns":1788563388312429000,"stream":"btcusdt@bookTicker","event_type":"bookTicker","event_time_ms":1788563388351,"raw_json":"{\"stream\":\"btcusdt@bookTicker\",\"data\":{\"e\":\"bookTicker\",\"u\":11478233073006,\"s\":\"BTCUSDT\",\"ps\":\"BTCUSDT\",\"b\":\"79607.10\",\"B\":\"3.313\",\"a\":\"79607.20\",\"A\":\"8.104\",\"T\":1788563388350,\"E\":1788563388351,\"st\":1}}"}
{"receive_ns":1788563388313387000,"stream":"btcusdt@bookTicker","event_type":"bookTicker","event_time_ms":1788563388352,"raw_json":"{\"stream\":\"btcusdt@bookTicker\",\"data\":{\"e\":\"bookTicker\",\"u\":11478233073084,\"s\":\"BTCUSDT\",\"ps\":\"BTCUSDT\",\"b\":\"79607.10\",\"B\":\"3.315\",\"a\":\"79607.20\",\"A\":\"8.104\",\"T\":1788563388352,\"E\":1788563388352,\"st\":1}}"}
{"receive_ns":1788563388329821000,"stream":"btcusdt@bookTicker","event_type":"bookTicker","event_time_ms":1788563388360,"raw_json":"{\"stream\":\"btcusdt@bookTicker\",\"data\":{\"e\":\"bookTicker\",\"u\":11478233073390,\"s\":\"BTCUSDT\",\"ps\":\"BTCUSDT\",\"b\":\"79607.10\",\"B\":\"4.481\",\"a\":\"79607.20\",\"A\":\"8.104\",\"T\":1788563388360,\"E\":1788563388360,\"st\":1}}"}
{"receive_ns":1788563388330095000,"stream":"btcusdt@bookTicker","event_type":"bookTicker","event_time_ms":1788563388361,"raw_json":"{\"stream\":\"btcusdt@bookTicker\",\"data\":{\"e\":\"bookTicker\",\"u\":11478233073437,\"s\":\"BTCUSDT\",\"ps\":\"BTCUSDT\",\"b\":\"79607.10\",\"B\":\"4.479\",\"a\":\"79607.20\",\"A\":\"8.104\",\"T\":1788563388361,\"E\":1788563388361,\"st\":1}}"}
{"receive_ns":1788563388330232000,"stream":"btcusdt@bookTicker","event_type":"bookTicker","event_time_ms":1788563388361,"raw_json":"{\"stream\":\"btcusdt@bookTicker\",\"data\":{\"e\":\"bookTicker\",\"u\":11478233073448,\"s\":\"BTCUSDT\",\"ps\":\"BTCUSDT\",\"b\":\"79607.10\",\"B\":\"4.480\",\"a\":\"79607.20\",\"A\":\"8.104\",\"T\":1788563388361,\"E\":1788563388361,\"st\":1}}"}
{"receive_ns":1788563388342727000,"stream":"btcusdt@bookTicker","event_type":"bookTicker","event_time_ms":1788563388380,"raw_json":"{\"stream\":\"btcusdt@bookTicker\",\"data\":{\"e\":\"bookTicker\",\"u\":11478233074226,\"s\":\"BTCUSDT\",\"ps\":\"BTCUSDT\",\"b\":\"79607.10\",\"B\":\"4.461\",\"a\":\"79607.20\",\"A\":\"8.104\",\"T\":1788563388380,\"E\":1788563388380,\"st\":1}}"}
{"receive_ns":1788563388345689000,"stream":"btcusdt@bookTicker","event_type":"bookTicker","event_time_ms":1788563388383,"raw_json":"{\"stream\":\"btcusdt@bookTicker\",\"data\":{\"e\":\"bookTicker\",\"u\":11478233074371,\"s\":\"BTCUSDT\",\"ps\":\"BTCUSDT\",\"b\":\"79607.10\",\"B\":\"4.478\",\"a\":\"79607.20\",\"A\":\"8.104\",\"T\":1788563388383,\"E\":1788563388383,\"st\":1}}"}
{"receive_ns":1788563388346435000,"stream":"btcusdt@bookTicker","event_type":"bookTicker","event_time_ms":1788563388384,"raw_json":"{\"stream\":\"btcusdt@bookTicker\",\"data\":{\"e\":\"bookTicker\",\"u\":11478233074441,\"s\":\"BTCUSDT\",\"ps\":\"BTCUSDT\",\"b\":\"79607.10\",\"B\":\"4.480\",\"a\":\"79607.20\",\"A\":\"8.104\",\"T\":1788563388384,\"E\":1788563388384,\"st\":1}}"}
{"receive_ns":1788563388351765000,"stream":"btcusdt@depth@100ms","event_type":"depthUpdate","event_time_ms":1788563388389,"raw_json":"{\"stream\":\"btcusdt@depth@100ms\",\"data\":{\"e\":\"depthUpdate\",\"E\":1788563388389,\"T\":1788563388387,\"s\":\"BTCUSDT\",\"ps\":\"BTCUSDT\",\"U\":11478233070014,\"u\":11478233074551,\"pu\":11478233069923,\"b\":[[\"1000.00\",\"24.754\"],[\"29307.10\",\"0.042\"],[\"29407.10\",\"1.785\"],[\"29507.10\",\"0.273\"],[\"71646.30\",\"0.002\"],[\"76422.80\",\"0.000\"],[\"78811.00\",\"15.338\"],[\"79010.00\",\"3.680\"],[\"79232.90\",\"0.141\"],[\"79533.70\",\"0.000\"],[\"79549.60\",\"0.000\"],[\"79557.40\",\"6.974\"],[\"79557.90\",\"10.206\"],[\"79560.10\",\"0.002\"],[\"79561.40\",\"3.881\"],[\"79583.20\",\"0.002\"],[\"79589.20\",\"0.972\"],[\"79589.80\",\"0.006\"],[\"79591.20\",\"1.307\"],[\"79595.70\",\"0.001\"],[\"79596.90\",\"0.000\"],[\"79597.10\",\"0.034\"],[\"79597.60\",\"0.002\"],[\"79597.70\",\"0.002\"],[\"79601.90\",\"0.000\"],[\"79602.70\",\"0.002\"],[\"79603.00\",\"0.003\"],[\"79604.40\",\"0.026\"],[\"79604.80\",\"0.028\"],[\"79606.00\",\"0.036\"],[\"79606.60\",\"0.001\"],[\"79607.10\",\"4.480\"]],\"a\":[[\"79611.00\",\"0.130\"],[\"79612.10\",\"0.008\"],[\"79615.00\",\"0.033\"],[\"79615.10\",\"0.000\"],[\"79615.30\",\"0.001\"],[\"79617.70\",\"0.000\"],[\"79618.20\",\"0.631\"],[\"79626.50\",\"0.002\"],[\"79627.30\",\"0.627\"],[\"79668.20\",\"2.948\"],[\"79671.50\",\"25.435\"],[\"79674.50\",\"2.898\"],[\"79676.80\",\"0.076\"],[\"79676.90\",\"0.206\"],[\"79685.70\",\"0.000\"],[\"79686.90\",\"6.003\"],[\"79707.20\",\"0.000\"],[\"79707.30\",\"0.002\"],[\"79707.50\",\"0.125\"],[\"79968.00\",\"0.867\"],[\"79969.40\",\"1.367\"],[\"79997.80\",\"0.525\"],[\"79999.30\",\"0.055\"],[\"80403.30\",\"22.287\"],[\"80498.50\",\"0.186\"]],\"st\":1}}"}
{"receive_ns":1788563388452727000,"stream":"btcusdt@bookTicker","event_type":"bookTicker","event_time_ms":1788563388488,"raw_json":"{\"stream\":\"btcusdt@bookTicker\",\"data\":{\"e\":\"bookTicker\",\"u\":11478233078771,\"s\":\"BTCUSDT\",\"ps\":\"BTCUSDT\",\"b\":\"79607.10\",\"B\":\"4.467\",\"a\":\"79607.20\",\"A\":\"8.104\",\"T\":1788563388487,\"E\":1788563388488,\"st\":1}}"}
{"receive_ns":1788563388453036000,"stream":"btcusdt@depth@100ms","event_type":"depthUpdate","event_time_ms":1788563388491,"raw_json":"{\"stream\":\"btcusdt@depth@100ms\",\"data\":{\"e\":\"depthUpdate\",\"E\":1788563388491,\"T\":1788563388490,\"s\":\"BTCUSDT\",\"ps\":\"BTCUSDT\",\"U\":11478233074629,\"u\":11478233078967,\"pu\":11478233074551,\"b\":[[\"29307.10\",\"0.098\"],[\"29407.10\",\"1.855\"],[\"29507.10\",\"0.147\"],[\"71646.30\",\"0.004\"],[\"76422.80\",\"0.002\"],[\"78373.20\",\"10.653\"],[\"78600.00\",\"26.011\"],[\"78811.00\",\"15.340\"],[\"78900.00\",\"4.691\"],[\"79209.10\",\"4.608\"],[\"79535.40\",\"0.002\"],[\"79579.50\",\"0.004\"],[\"79581.70\",\"1.017\"],[\"79587.20\",\"0.000\"],[\"79603.60\",\"1.545\"],[\"79604.30\",\"0.000\"],[\"79604.40\",\"0.000\"],[\"79604.80\",\"0.028\"],[\"79607.10\",\"4.467\"]],\"a\":[[\"79678.90\",\"0.015\"],[\"80244.10\",\"7.375\"],[\"80403.30\",\"22.287\"]],\"st\":1}}"}
{"receive_ns":1788563388453264000,"stream":"btcusdt@bookTicker","event_type":"bookTicker","event_time_ms":1788563388491,"raw_json":"{\"stream\":\"btcusdt@bookTicker\",\"data\":{\"e\":\"bookTicker\",\"u\":11478233078990,\"s\":\"BTCUSDT\",\"ps\":\"BTCUSDT\",\"b\":\"79607.10\",\"B\":\"4.480\",\"a\":\"79607.20\",\"A\":\"8.104\",\"T\":1788563388491,\"E\":1788563388491,\"st\":1}}"}
{"receive_ns":1788563388557666000,"stream":"btcusdt@depth@100ms","event_type":"depthUpdate","event_time_ms":1788563388593,"raw_json":"{\"stream\":\"btcusdt@depth@100ms\",\"data\":{\"e\":\"depthUpdate\",\"E\":1788563388593,\"T\":1788563388592,\"s\":\"BTCUSDT\",\"ps\":\"BTCUSDT\",\"U\":11478233078972,\"u\":11478233084315,\"pu\":11478233078967,\"b\":[[\"1000.00\",\"24.754\"],[\"29307.10\",\"0.161\"],[\"29407.10\",\"1.904\"],[\"29507.10\",\"0.035\"],[\"63685.70\",\"0.003\"],[\"63686.00\",\"0.000\"],[\"71646.30\",\"0.002\"],[\"76422.80\",\"0.000\"],[\"78364.30\",\"3.450\"],[\"78811.00\",\"15.340\"],[\"79232.90\",\"0.141\"],[\"79491.70\",\"0.583\"],[\"79523.30\",\"0.126\"],[\"79524.00\",\"0.002\"],[\"79580.70\",\"0.000\"],[\"79583.20\",\"0.579\"],[\"79583.40\",\"0.006\"],[\"79583.80\",\"2.009\"],[\"79587.20\",\"0.012\"],[\"79589.20\",\"0.395\"],[\"79591.20\",\"1.231\"],[\"79592.40\",\"0.348\"],[\"79595.30\",\"0.103\"],[\"79596.60\",\"0.252\"],[\"79604.00\",\"0.029\"],[\"79604.80\",\"0.002\"],[\"79605.40\",\"0.001\"],[\"79605.60\",\"0.027\"],[\"79607.10\",\"4.480\"]],\"a\":[[\"79611.00\",\"0.136\"],[\"79612.10\",\"0.002\"],[\"79615.10\",\"0.379\"],[\"79616.20\",\"0.082\"],[\"79618.10\",\"0.440\"],[\"79618.20\",\"0.252\"],[\"79618.30\",\"0.001\"],[\"79623.30\",\"0.458\"],[\"79774.40\",\"2.254\"],[\"79968.00\",\"0.867\"],[\"79969.40\",\"1.160\"],[\"79997.80\",\"0.525\"],[\"79999.30\",\"0.011\"],[\"80403.30\",\"22.287\"],[\"80944.60\",\"2.465\"]],\"st\":1}}"}
{"receive_ns":1788563388662683000,"stream":"btcusdt@depth@100ms","event_type":"depthUpdate","event_time_ms":1788563388695,"raw_json":"{\"stream\":\"btcusdt@depth@100ms\",\"data\":{\"e\":\"depthUpdate\",\"E\":1788563388695,\"T\":1788563388693,\"s\":\"BTCUSDT\",\"ps\":\"BTCUSDT\",\"U\":11478233084345,\"u\":11478233088863,\"pu\":11478233084315,\"b\":[[\"1000.00\",\"24.754\"],[\"29307.10\",\"0.308\"],[\"29407.10\",\"1.792\"],[\"29507.10\",\"0.000\"],[\"63685.70\",\"0.001\"],[\"71646.30\",\"0.002\"],[\"71684.00\",\"0.000\"],[\"78284.70\",\"0.893\"],[\"78373.20\",\"11.545\"],[\"78512.70\",\"1.525\"],[\"78811.00\",\"15.338\"],[\"79531.40\",\"0.031\"],[\"79535.40\",\"0.000\"],[\"79567.20\",\"0.242\"],[\"79583.80\",\"0.001\"],[\"79591.00\",\"0.328\"],[\"79602.30\",\"0.028\"],[\"79602.60\",\"0.027\"],[\"79602.80\",\"0.026\"],[\"79603.90\",\"0.001\"],[\"79604.00\",\"0.003\"],[\"79604.20\",\"0.001\"],[\"79604.50\",\"0.026\"],[\"79604.70\",\"0.027\"]],\"a\":[[\"79647.10\",\"0.067\"],[\"79663.00\",\"0.002\"],[\"79678.90\",\"0.013\"],[\"80005.20\",\"3.754\"],[\"80403.30\",\"22.287\"]],\"st\":1}}"}
{"receive_ns":1788563388701236000,"stream":"btcusdt@bookTicker","event_type":"bookTicker","event_time_ms":1788563388739,"raw_json":"{\"stream\":\"btcusdt@bookTicker\",\"data\":{\"e\":\"bookTicker\",\"u\":11478233091002,\"s\":\"BTCUSDT\",\"ps\":\"BTCUSDT\",\"b\":\"79607.10\",\"B\":\"4.485\",\"a\":\"79607.20\",\"A\":\"8.104\",\"T\":1788563388739,\"E\":1788563388739,\"st\":1}}"}
{"receive_ns":1788563388739579000,"stream":"btcusdt@bookTicker","event_type":"bookTicker","event_time_ms":1788563388774,"raw_json":"{\"stream\":\"btcusdt@bookTicker\",\"data\":{\"e\":\"bookTicker\",\"u\":11478233092701,\"s\":\"BTCUSDT\",\"ps\":\"BTCUSDT\",\"b\":\"79607.10\",\"B\":\"4.485\",\"a\":\"79607.20\",\"A\":\"7.774\",\"T\":1788563388774,\"E\":1788563388774,\"st\":1}}"}
{"receive_ns":1788563388749268000,"stream":"btcusdt@bookTicker","event_type":"bookTicker","event_time_ms":1788563388778,"raw_json":"{\"stream\":\"btcusdt@bookTicker\",\"data\":{\"e\":\"bookTicker\",\"u\":11478233093213,\"s\":\"BTCUSDT\",\"ps\":\"BTCUSDT\",\"b\":\"79607.10\",\"B\":\"4.485\",\"a\":\"79607.20\",\"A\":\"7.772\",\"T\":1788563388778,\"E\":1788563388778,\"st\":1}}"}
{"receive_ns":1788563388749501000,"stream":"btcusdt@trade","event_type":"trade","event_time_ms":1788563388778,"raw_json":"{\"stream\":\"btcusdt@trade\",\"data\":{\"e\":\"trade\",\"E\":1788563388778,\"T\":1788563388778,\"s\":\"BTCUSDT\",\"t\":8054083498,\"p\":\"79607.20\",\"q\":\"0.002\",\"X\":\"MARKET\",\"m\":false,\"st\":1}}"}
{"receive_ns":1788563388760889000,"stream":"btcusdt@depth@100ms","event_type":"depthUpdate","event_time_ms":1788563388797,"raw_json":"{\"stream\":\"btcusdt@depth@100ms\",\"data\":{\"e\":\"depthUpdate\",\"E\":1788563388797,\"T\":1788563388793,\"s\":\"BTCUSDT\",\"ps\":\"BTCUSDT\",\"U\":11478233089055,\"u\":11478233094103,\"pu\":11478233088863,\"b\":[[\"29307.10\",\"0.483\"],[\"29407.10\",\"1.617\"],[\"71646.30\",\"0.002\"],[\"76422.80\",\"0.002\"],[\"78427.10\",\"3.053\"],[\"78811.00\",\"15.338\"],[\"79209.10\",\"4.608\"],[\"79232.90\",\"0.000\"],[\"79421.10\",\"3.140\"],[\"79461.40\",\"1.884\"],[\"79483.20\",\"0.518\"],[\"79483.40\",\"0.000\"],[\"79483.50\",\"0.003\"],[\"79491.70\",\"0.000\"],[\"79519.40\",\"0.038\"],[\"79583.20\",\"0.002\"],[\"79589.20\",\"0.697\"],[\"79592.50\",\"0.094\"],[\"79593.10\",\"0.001\"],[\"79602.30\",\"0.002\"],[\"79602.40\",\"0.254\"],[\"79602.60\",\"0.001\"],[\"79605.00\",\"0.656\"],[\"79605.10\",\"0.026\"],[\"79605.30\",\"0.026\"],[\"79607.10\",\"4.485\"]],\"a\":[[\"79607.20\",\"7.772\"],[\"79630.50\",\"0.038\"],[\"79694.60\",\"0.039\"],[\"79728.70\",\"0.294\"],[\"79729.80\",\"1.884\"],[\"79748.30\",\"3.140\"],[\"79774.40\",\"2.003\"],[\"79841.60\",\"0.000\"],[\"79841.70\",\"0.016\"],[\"79968.00\",\"0.104\"],[\"79969.40\",\"0.420\"],[\"79997.80\",\"0.000\"],[\"80244.10\",\"7.624\"],[\"80403.30\",\"22.287\"]],\"st\":1}}"}
{"receive_ns":1788563388860748000,"stream":"btcusdt@depth@100ms","event_type":"depthUpdate","event_time_ms":1788563388899,"raw_json":"{\"stream\":\"btcusdt@depth@100ms\",\"data\":{\"e\":\"depthUpdate\",\"E\":1788563388899,\"T\":1788563388897,\"s\":\"BTCUSDT\",\"ps\":\"BTCUSDT\",\"U\":11478233094572,\"u\":11478233099436,\"pu\":11478233094103,\"b\":[[\"1000.00\",\"24.754\"],[\"29307.10\",\"0.665\"],[\"29407.10\",\"1.435\"],[\"71646.30\",\"0.002\"],[\"76422.80\",\"0.000\"],[\"78011.50\",\"0.000\"],[\"78100.00\",\"12.180\"],[\"78188.40\",\"0.002\"],[\"78276.90\",\"0.000\"],[\"78293.60\",\"5.600\"],[\"78365.30\",\"0.002\"],[\"78453.80\",\"0.000\"],[\"78542.20\",\"0.009\"],[\"78630.70\",\"0.195\"],[\"78719.10\",\"0.002\"],[\"78807.60\",\"2.620\"],[\"78811.00\",\"15.338\"],[\"79232.90\",\"0.141\"],[\"79491.70\",\"0.232\"],[\"79583.20\",\"0.002\"],[\"79583.80\",\"0.001\"],[\"79589.20\",\"0.972\"],[\"79589.30\",\"0.067\"],[\"79589.80\",\"0.006\"],[\"79591.30\",\"0.000\"],[\"79592.50\",\"0.018\"],[\"79597.30\",\"0.053\"],[\"79604.50\",\"0.000\"],[\"79604.70\",\"0.001\"],[\"79605.00\",\"0.630\"],[\"79605.10\",\"0.000\"],[\"79605.30\",\"0.000\"]],\"a\":[[\"79680.70\",\"0.255\"],[\"79689.50\",\"0.015\"],[\"79968.00\",\"0.867\"],[\"79969.40\",\"1.411\"],[\"79997.80\",\"0.525\"],[\"80323.70\",\"22.972\"],[\"80399.60\",\"0.545\"],[\"80403.30\",\"22.287\"],[\"80488.10\",\"0.394\"],[\"80576.50\",\"0.002\"],[\"80665.00\",\"0.006\"],[\"80753.40\",\"0.000\"],[\"80841.90\",\"0.000\"],[\"80930.30\",\"0.000\"],[\"81018.80\",\"0.000\"],[\"81107.20\",\"0.000\"],[\"81195.70\",\"3.136\"]],\"st\":1}}"}
{"receive_ns":1788563388977122000,"stream":"btcusdt@bookTicker","event_type":"bookTicker","event_time_ms":1788563388979,"raw_json":"{\"stream\":\"btcusdt@bookTicker\",\"data\":{\"e\":\"bookTicker\",\"u\":11478233102879,\"s\":\"BTCUSDT\",\"ps\":\"BTCUSDT\",\"b\":\"79607.10\",\"B\":\"4.485\",\"a\":\"79607.20\",\"A\":\"7.771\",\"T\":1788563388979,\"E\":1788563388979,\"st\":1}}"}
{"receive_ns":1788563388977579000,"stream":"btcusdt@depth@100ms","event_type":"depthUpdate","event_time_ms":1788563389001,"raw_json":"{\"stream\":\"btcusdt@depth@100ms\",\"data\":{\"e\":\"depthUpdate\",\"E\":1788563389001,\"T\":1788563389000,\"s\":\"BTCUSDT\",\"ps\":\"BTCUSDT\",\"U\":11478233099515,\"u\":11478233104016,\"pu\":11478233099436,\"b\":[[\"1000.00\",\"24.754\"],[\"29307.10\",\"0.840\"],[\"29407.10\",\"1.260\"],[\"71646.30\",\"0.002\"],[\"76422.80\",\"0.002\"],[\"78436.90\",\"7.680\"],[\"78811.00\",\"15.338\"],[\"79396.00\",\"5.012\"],[\"79443.70\",\"0.001\"],[\"79443.80\",\"2.056\"],[\"79483.20\",\"0.385\"],[\"79515.80\",\"0.001\"],[\"79515.90\",\"4.564\"],[\"79577.00\",\"0.008\"],[\"79581.70\",\"1.011\"],[\"79592.20\",\"0.098\"],[\"79603.40\",\"0.026\"],[\"79603.90\",\"0.027\"],[\"79604.10\",\"1.026\"]],\"a\":[[\"79607.20\",\"7.771\"],[\"79697.90\",\"4.041\"],[\"79728.70\",\"0.000\"],[\"79728.80\",\"0.169\"],[\"79768.10\",\"0.000\"],[\"79768.20\",\"0.635\"],[\"79828.60\",\"8.653\"],[\"80403.30\",\"22.287\"]],\"st\":1}}"}
{"receive_ns":1788563388984482000,"stream":"btcusdt@bookTicker","event_type":"bookTicker","event_time_ms":1788563389021,"raw_json":"{\"stream\":\"btcusdt@bookTicker\",\"data\":{\"e\":\"bookTicker\",\"u\":11478233105070,\"s\":\"BTCUSDT\",\"ps\":\"BTCUSDT\",\"b\":\"79607.10\",\"B\":\"4.485\",\"a\":\"79607.20\",\"A\":\"7.772\",\"T\":1788563389021,\"E\":1788563389021,\"st\":1}}"}
{"receive_ns":1788563388988160000,"stream":"btcusdt@bookTicker","event_type":"bookTicker","event_time_ms":1788563389026,"raw_json":"{\"stream\":\"btcusdt@bookTicker\",\"data\":{\"e\":\"bookTicker\",\"u\":11478233105300,\"s\":\"BTCUSDT\",\"ps\":\"BTCUSDT\",\"b\":\"79607.10\",\"B\":\"4.485\",\"a\":\"79607.20\",\"A\":\"7.773\",\"T\":1788563389025,\"E\":1788563389026,\"st\":1}}"}
{"receive_ns":1788563388993301000,"stream":"btcusdt@bookTicker","event_type":"bookTicker","event_time_ms":1788563389032,"raw_json":"{\"stream\":\"btcusdt@bookTicker\",\"data\":{\"e\":\"bookTicker\",\"u\":11478233105590,\"s\":\"BTCUSDT\",\"ps\":\"BTCUSDT\",\"b\":\"79607.10\",\"B\":\"4.472\",\"a\":\"79607.20\",\"A\":\"7.773\",\"T\":1788563389032,\"E\":1788563389032,\"st\":1}}"}
{"receive_ns":1788563388994764000,"stream":"btcusdt@bookTicker","event_type":"bookTicker","event_time_ms":1788563389033,"raw_json":"{\"stream\":\"btcusdt@bookTicker\",\"data\":{\"e\":\"bookTicker\",\"u\":11478233105695,\"s\":\"BTCUSDT\",\"ps\":\"BTCUSDT\",\"b\":\"79607.10\",\"B\":\"4.471\",\"a\":\"79607.20\",\"A\":\"7.773\",\"T\":1788563389033,\"E\":1788563389033,\"st\":1}}"}
{"receive_ns":1788563388997136000,"stream":"btcusdt@bookTicker","event_type":"bookTicker","event_time_ms":1788563389034,"raw_json":"{\"stream\":\"btcusdt@bookTicker\",\"data\":{\"e\":\"bookTicker\",\"u\":11478233105800,\"s\":\"BTCUSDT\",\"ps\":\"BTCUSDT\",\"b\":\"79607.10\",\"B\":\"4.472\",\"a\":\"79607.20\",\"A\":\"7.773\",\"T\":1788563389034,\"E\":1788563389034,\"st\":1}}"}
{"receive_ns":1788563388997335000,"stream":"btcusdt@bookTicker","event_type":"bookTicker","event_time_ms":1788563389035,"raw_json":"{\"stream\":\"btcusdt@bookTicker\",\"data\":{\"e\":\"bookTicker\",\"u\":11478233105913,\"s\":\"BTCUSDT\",\"ps\":\"BTCUSDT\",\"b\":\"79607.10\",\"B\":\"4.485\",\"a\":\"79607.20\",\"A\":\"7.773\",\"T\":1788563389035,\"E\":1788563389035,\"st\":1}}"}
{"receive_ns":1788563389066096000,"stream":"btcusdt@depth@100ms","event_type":"depthUpdate","event_time_ms":1788563389103,"raw_json":"{\"stream\":\"btcusdt@depth@100ms\",\"data\":{\"e\":\"depthUpdate\",\"E\":1788563389103,\"T\":1788563389101,\"s\":\"BTCUSDT\",\"ps\":\"BTCUSDT\",\"U\":11478233104074,\"u\":11478233109543,\"pu\":11478233104016,\"b\":[[\"29307.10\",\"1.022\"],[\"29407.10\",\"1.078\"],[\"71646.30\",\"0.002\"],[\"78811.00\",\"15.338\"],[\"79209.00\",\"0.000\"],[\"79209.10\",\"4.608\"],[\"79232.90\",\"0.141\"],[\"79491.70\",\"0.232\"],[\"79515.90\",\"3.295\"],[\"79516.00\",\"2.328\"],[\"79583.20\",\"0.855\"],[\"79583.80\",\"0.001\"],[\"79589.20\",\"0.470\"],[\"79592.80\",\"0.004\"],[\"79604.30\",\"0.026\"],[\"79607.10\",\"4.485\"]],\"a\":[[\"79607.20\",\"7.773\"],[\"79968.00\",\"0.867\"],[\"79969.40\",\"1.411\"],[\"79997.80\",\"0.525\"],[\"80339.30\",\"0.372\"],[\"80403.30\",\"22.286\"]],\"st\":1}}"}
{"receive_ns":1788563389111419000,"stream":"btcusdt@bookTicker","event_type":"bookTicker","event_time_ms":1788563389150,"raw_json":"{\"stream\":\"btcusdt@bookTicker\",\"data\":{\"e\":\"bookTicker\",\"u\":11478233112212,\"s\":\"BTCUSDT\",\"ps\":\"BTCUSDT\",\"b\":\"79607.10\",\"B\":\"4.051\",\"a\":\"79607.20\",\"A\":\"7.773\",\"T\":1788563389150,\"E\":1788563389150,\"st\":1}}"}
{"receive_ns":1788563389115782000,"stream":"btcusdt@bookTicker","event_type":"bookTicker","event_time_ms":1788563389153,"raw_json":"{\"stream\":\"btcusdt@bookTicker\",\"data\":{\"e\":\"bookTicker\",\"u\":11478233112401,\"s\":\"BTCUSDT\",\"ps\":\"BTCUSDT\",\"b\":\"79607.10\",\"B\":\"4.486\",\"a\":\"79607.20\",\"A\":\"7.773\",\"T\":1788563389153,\"E\":1788563389153,\"st\":1}}"}
{"receive_ns":1788563389120156000,"stream":"btcusdt@bookTicker","event_type":"bookTicker","event_time_ms":1788563389155,"raw_json":"{\"stream\":\"btcusdt@bookTicker\",\"data\":{\"e\":\"bookTicker\",\"u\":11478233112450,\"s\":\"BTCUSDT\",\"ps\":\"BTCUSDT\",\"b\":\"79607.10\",\"B\":\"4.484\",\"a\":\"79607.20\",\"A\":\"7.773\",\"T\":1788563389155,\"E\":1788563389155,\"st\":1}}"}
{"receive_ns":1788563389168418000,"stream":"btcusdt@depth@100ms","event_type":"depthUpdate","event_time_ms":1788563389205,"raw_json":"{\"stream\":\"btcusdt@depth@100ms\",\"data\":{\"e\":\"depthUpdate\",\"E\":1788563389205,\"T\":1788563389201,\"s\":\"BTCUSDT\",\"ps\":\"BTCUSDT\",\"U\":11478233109750,\"u\":11478233114546,\"pu\":11478233109543,\"b\":[[\"1000.00\",\"24.754\"],[\"29307.10\",\"1.197\"],[\"29407.10\",\"0.903\"],[\"71646.30\",\"0.002\"],[\"75626.70\",\"0.017\"],[\"75626.80\",\"0.006\"],[\"76422.80\",\"0.000\"],[\"78811.00\",\"15.338\"],[\"78883.90\",\"0.000\"],[\"79461.40\",\"1.884\"],[\"79523.30\",\"0.001\"],[\"79524.00\",\"0.127\"],[\"79575.20\",\"0.929\"],[\"79576.20\",\"0.003\"],[\"79584.80\",\"0.277\"],[\"79592.10\",\"0.077\"],[\"79592.20\",\"0.022\"],[\"79592.30\",\"0.001\"],[\"79596.00\",\"0.257\"],[\"79596.60\",\"0.001\"],[\"79602.30\",\"0.028\"],[\"79602.40\",\"0.280\"],[\"79602.50\",\"0.027\"],[\"79602.60\",\"0.027\"],[\"79602.80\",\"0.026\"],[\"79603.70\",\"0.011\"],[\"79603.80\",\"0.003\"],[\"79603.90\",\"0.001\"],[\"79604.10\",\"1.000\"],[\"79604.20\",\"0.027\"],[\"79604.30\",\"0.000\"],[\"79604.40\",\"0.026\"],[\"79604.60\",\"0.000\"],[\"79604.70\",\"0.001\"],[\"79604.90\",\"0.001\"],[\"79605.60\",\"0.026\"],[\"79606.90\",\"0.196\"],[\"79607.10\",\"4.484\"]],\"a\":[[\"79615.00\",\"0.095\"],[\"79615.10\",\"0.317\"],[\"79615.30\",\"0.001\"],[\"79616.00\",\"0.020\"],[\"79618.10\",\"0.001\"],[\"79618.30\",\"0.440\"],[\"79729.80\",\"1.884\"],[\"80005.30\",\"0.003\"],[\"80403.30\",\"22.286\"],[\"80482.90\",\"20.473\"],[\"80602.30\",\"11.905\"]],\"st\":1}}"}
