{"receive_ns":1788563389268599000,"stream":"btcusdt@depth@100ms","event_type":"depthUpdate","event_time_ms":1788563389307,"raw_json":"{\"stream\":\"btcusdt@depth@100ms\",\"data\":{\"e\":\"depthUpdate\",\"E\":1788563389307,\"T\":1788563389306,\"s\":\"BTCUSDT\",\"ps\":\"BTCUSDT\",\"U\":11478233114680,\"u\":11478233118746,\"pu\":11478233114546,\"b\":[[\"1000.00\",\"24.754\"],[\"29307.10\",\"1.379\"],[\"29407.10\",\"0.721\"],[\"71646.30\",\"0.002\"],[\"76422.80\",\"0.002\"],[\"78015.00\",\"10.703\"],[\"78811.00\",\"15.338\"],[\"79232.90\",\"0.141\"],[\"79491.70\",\"0.583\"],[\"79582.10\",\"0.001\"],[\"79583.20\",\"0.579\"],[\"79583.30\",\"0.243\"],[\"79583.80\",\"2.009\"],[\"79589.20\",\"0.395\"],[\"79592.10\",\"0.001\"],[\"79597.60\",\"0.000\"],[\"79601.90\",\"0.026\"],[\"79602.10\",\"0.156\"],[\"79602.20\",\"0.046\"],[\"79602.30\",\"0.028\"],[\"79602.90\",\"0.028\"],[\"79603.40\",\"0.000\"],[\"79603.60\",\"1.519\"],[\"79604.20\",\"0.001\"],[\"79604.40\",\"0.000\"],[\"79604.50\",\"0.000\"]],\"a\":[[\"79774.40\",\"2.505\"],[\"79968.00\",\"0.867\"],[\"79969.40\",\"0.710\"],[\"79997.80\",\"0.525\"],[\"80403.30\",\"22.286\"],[\"80841.10\",\"10.381\"]],\"st\":1}}"}
{"receive_ns":1788563389276841000,"stream":"btcusdt@bookTicker","event_type":"bookTicker","event_time_ms":1788563389315,"raw_json":"{\"stream\":\"btcusdt@bookTicker\",\"data\":{\"e\":\"bookTicker\",\"u\":11478233119062,\"s\":\"BTCUSDT\",\"ps\":\"BTCUSDT\",\"b\":\"79607.10\",\"B\":\"4.013\",\"a\":\"79607.20\",\"A\":\"7.773\",\"T\":1788563389315,\"E\":1788563389315,\"st\":1}}"}
{"receive_ns":1788563389277678000,"stream":"btcusdt@bookTicker","event_type":"bookTicker","event_time_ms":1788563389316,"raw_json":"{\"stream\":\"btcusdt@bookTicker\",\"data\":{\"e\":\"bookTicker\",\"u\":11478233119117,\"s\":\"BTCUSDT\",\"ps\":\"BTCUSDT\",\"b\":\"79607.10\",\"B\":\"4.015\",\"a\":\"79607.20\",\"A\":\"7.773\",\"T\":1788563389316,\"E\":1788563389316,\"st\":1}}"}
{"receive_ns":1788563389283390000,"stream":"btcusdt@bookTicker","event_type":"bookTicker","event_time_ms":1788563389320,"raw_json":"{\"stream\":\"btcusdt@bookTicker\",\"data\":{\"e\":\"bookTicker\",\"u\":11478233119483,\"s\":\"BTCUSDT\",\"ps\":\"BTCUSDT\",\"b\":\"79607.10\",\"B\":\"4.494\",\"a\":\"79607.20\",\"A\":\"7.773\",\"T\":1788563389320,\"E\":1788563389320,\"st\":1}}"}
{"receive_ns":1788563389283611000,"stream":"btcusdt@bookTicker","event_type":"bookTicker","event_time_ms":1788563389321,"raw_json":"{\"stream\":\"btcusdt@bookTicker\",\"data\":{\"e\":\"bookTicker\",\"u\":11478233119603,\"s\":\"BTCUSDT\",\"ps\":\"BTCUSDT\",\"b\":\"79607.10\",\"B\":\"4.492\",\"a\":\"79607.20\",\"A\":\"7.773\",\"T\":1788563389321,\"E\":1788563389321,\"st\":1}}"}
{"receive_ns":1788563389296613000,"stream":"btcusdt@bookTicker","event_type":"bookTicker","event_time_ms":1788563389335,"raw_json":"{\"stream\":\"btcusdt@bookTicker\",\"data\":{\"e\":\"bookTicker\",\"u\":11478233120141,\"s\":\"BTCUSDT\",\"ps\":\"BTCUSDT\",\"b\":\"79607.10\",\"B\":\"3.847\",\"a\":\"79607.20\",\"A\":\"7.773\",\"T\":1788563389335,\"E\":1788563389335,\"st\":1}}"}
{"receive_ns":1788563389297276000,"stream":"btcusdt@bookTicker","event_type":"bookTicker","event_time_ms":1788563389336,"raw_json":"{\"stream\":\"btcusdt@bookTicker\",\"data\":{\"e\":\"bookTicker\",\"u\":11478233120236,\"s\":\"BTCUSDT\",\"ps\":\"BTCUSDT\",\"b\":\"79607.10\",\"B\":\"3.849\",\"a\":\"79607.20\",\"A\":\"7.773\",\"T\":1788563389336,\"E\":1788563389336,\"st\":1}}"}
{"receive_ns":1788563389305248000,"stream":"btcusdt@bookTicker","event_type":"bookTicker","event_time_ms":1788563389338,"raw_json":"{\"stream\":\"btcusdt@bookTicker\",\"data\":{\"e\":\"bookTicker\",\"u\":11478233120309,\"s\":\"BTCUSDT\",\"ps\":\"BTCUSDT\",\"b\":\"79607.10\",\"B\":\"4.496\",\"a\":\"79607.20\",\"A\":\"7.773\",\"T\":1788563389337,\"E\":1788563389338,\"st\":1}}"}
{"receive_ns":1788563389375775000,"stream":"btcusdt@depth@100ms","event_type":"depthUpdate","event_time_ms":1788563389409,"raw_json":"{\"stream\":\"btcusdt@depth@100ms\",\"data\":{\"e\":\"depthUpdate\",\"E\":1788563389409,\"T\":1788563389406,\"s\":\"BTCUSDT\",\"ps\":\"BTCUSDT\",\"U\":11478233118787,\"u\":11478233123244,\"pu\":11478233118746,\"b\":[[\"29307.10\",\"1.554\"],[\"29407.10\",\"0.546\"],[\"63686.00\",\"0.000\"],[\"71646.30\",\"0.002\"],[\"76422.80\",\"0.000\"],[\"78489.10\",\"18.674\"],[\"78811.00\",\"15.338\"],[\"78890.60\",\"40.731\"],[\"79209.10\",\"4.608\"],[\"79523.40\",\"3.331\"],[\"79539.30\",\"0.000\"],[\"79576.20\",\"0.001\"],[\"79583.80\",\"0.001\"],[\"79588.80\",\"0.065\"],[\"79589.30\",\"0.005\"],[\"79592.10\",\"0.077\"],[\"79595.90\",\"0.004\"],[\"79596.60\",\"0.001\"],[\"79597.10\",\"0.033\"],[\"79597.20\",\"0.187\"],[\"79597.70\",\"0.004\"],[\"79601.90\",\"0.000\"],[\"79602.10\",\"0.130\"],[\"79602.20\",\"0.020\"],[\"79603.00\",\"0.029\"],[\"79603.20\",\"0.029\"],[\"79603.50\",\"0.029\"],[\"79604.20\",\"0.027\"],[\"79607.10\",\"4.496\"]],\"a\":[[\"79630.90\",\"0.718\"],[\"79631.70\",\"0.000\"],[\"79644.90\",\"0.000\"],[\"79969.40\",\"0.909\"],[\"80403.30\",\"22.286\"]],\"st\":1}}"}
{"receive_ns":1788563389472549000,"stream":"btcusdt@depth@100ms","event_type":"depthUpdate","event_time_ms":1788563389511,"raw_json":"{\"stream\":\"btcusdt@depth@100ms\",\"data\":{\"e\":\"depthUpdate\",\"E\":1788563389511,\"T\":1788563389510,\"s\":\"BTCUSDT\",\"ps\":\"BTCUSDT\",\"U\":11478233123369,\"u\":11478233127509,\"pu\":11478233123244,\"b\":[[\"1000.00\",\"24.754\"],[\"29307.10\",\"1.736\"],[\"29407.10\",\"0.364\"],[\"71646.30\",\"0.002\"],[\"76422.80\",\"0.002\"],[\"78015.00\",\"10.700\"],[\"78811.00\",\"15.338\"],[\"79577.00\",\"0.002\"],[\"79579.20\",\"0.008\"],[\"79583.20\",\"0.077\"]],\"a\":[[\"79969.40\",\"0.490\"],[\"80403.30\",\"22.286\"]],\"st\":1}}"}
{"receive_ns":1788563389502003000,"stream":"btcusdt@bookTicker","event_type":"bookTicker","event_time_ms":1788563389539,"raw_json":"{\"stream\":\"btcusdt@bookTicker\",\"data\":{\"e\":\"bookTicker\",\"u\":11478233129015,\"s\":\"BTCUSDT\",\"ps\":\"BTCUSDT\",\"b\":\"79607.10\",\"B\":\"4.483\",\"a\":\"79607.20\",\"A\":\"7.773\",\"T\":1788563389539,\"E\":1788563389539,\"st\":1}}"}
{"receive_ns":1788563389511685000,"stream":"btcusdt@bookTicker","event_type":"bookTicker","event_time_ms":1788563389542,"raw_json":"{\"stream\":\"btcusdt@bookTicker\",\"data\":{\"e\":\"bookTicker\",\"u\":11478233129374,\"s\":\"BTCUSDT\",\"ps\":\"BTCUSDT\",\"b\":\"79607.10\",\"B\":\"4.496\",\"a\":\"79607.20\",\"A\":\"7.773\",\"T\":1788563389542,\"E\":1788563389542,\"st\":1}}"}
{"receive_ns":1788563389512615000,"stream":"btcusdt@bookTicker","event_type":"bookTicker","event_time_ms":1788563389543,"raw_json":"{\"stream\":\"btcusdt@bookTicker\",\"data\":{\"e\":\"bookTicker\",\"u\":11478233129458,\"s\":\"BTCUSDT\",\"ps\":\"BTCUSDT\",\"b\":\"79607.10\",\"B\":\"4.494\",\"a\":\"79607.20\",\"A\":\"7.773\",\"T\":1788563389543,\"E\":1788563389543,\"st\":1}}"}
{"receive_ns":1788563389574450000,"stream":"btcusdt@depth@100ms","event_type":"depthUpdate","event_time_ms":1788563389613,"raw_json":"{\"stream\":\"btcusdt@depth@100ms\",\"data\":{\"e\":\"depthUpdate\",\"E\":1788563389613,\"T\":1788563389610,\"s\":\"BTCUSDT\",\"ps\":\"BTCUSDT\",\"U\":11478233127642,\"u\":11478233132476,\"pu\":11478233127509,\"b\":[[\"1000.00\",\"24.754\"],[\"29207.10\",\"0.056\"],[\"29307.10\",\"1.799\"],[\"29407.10\",\"0.245\"],[\"63685.70\",\"0.001\"],[\"63686.00\",\"0.000\"],[\"71646.30\",\"0.002\"],[\"78452.80\",\"40.346\"],[\"78811.00\",\"15.338\"],[\"79209.10\",\"4.482\"],[\"79232.90\",\"0.141\"],[\"79443.80\",\"0.816\"],[\"79483.20\",\"0.000\"],[\"79491.70\",\"0.232\"],[\"79523.50\",\"0.125\"],[\"79524.00\",\"0.002\"],[\"79583.20\",\"0.855\"],[\"79583.40\",\"0.006\"],[\"79583.80\",\"0.001\"],[\"79589.20\",\"0.470\"],[\"79602.30\",\"0.002\"],[\"79603.70\",\"0.037\"],[\"79604.20\",\"0.027\"],[\"79607.10\",\"4.494\"]],\"a\":[[\"79623.30\",\"0.458\"],[\"79728.80\",\"0.000\"],[\"79768.20\",\"0.000\"],[\"79774.40\",\"2.254\"],[\"79968.00\",\"0.867\"],[\"79969.40\",\"1.160\"],[\"79997.80\",\"0.525\"],[\"80403.30\",\"22.286\"],[\"80761.50\",\"21.520\"]],\"st\":1}}"}
{"receive_ns":1788563389593083000,"stream":"btcusdt@bookTicker","event_type":"bookTicker","event_time_ms":1788563389631,"raw_json":"{\"stream\":\"btcusdt@bookTicker\",\"data\":{\"e\":\"bookTicker\",\"u\":11478233133196,\"s\":\"BTCUSDT\",\"ps\":\"BTCUSDT\",\"b\":\"79607.10\",\"B\":\"4.494\",\"a\":\"79607.20\",\"A\":\"7.573\",\"T\":1788563389630,\"E\":1788563389631,\"st\":1}}"}
{"receive_ns":1788563389615544000,"stream":"btcusdt@bookTicker","event_type":"bookTicker","event_time_ms":1788563389653,"raw_json":"{\"stream\":\"btcusdt@bookTicker\",\"data\":{\"e\":\"bookTicker\",\"u\":11478233134138,\"s\":\"BTCUSDT\",\"ps\":\"BTCUSDT\",\"b\":\"79607.10\",\"B\":\"4.494\",\"a\":\"79607.20\",\"A\":\"7.567\",\"T\":1788563389653,\"E\":1788563389653,\"st\":1}}"}
{"receive_ns":1788563389615769000,"stream":"btcusdt@trade","event_type":"trade","event_time_ms":1788563389653,"raw_json":"{\"stream\":\"btcusdt@trade\",\"data\":{\"e\":\"trade\",\"E\":1788563389653,\"T\":1788563389653,\"s\":\"BTCUSDT\",\"t\":8054083499,\"p\":\"79607.20\",\"q\":\"0.006\",\"X\":\"MARKET\",\"m\":false,\"st\":1}}"}
{"receive_ns":1788563389677447000,"stream":"btcusdt@depth@100ms","event_type":"depthUpdate","event_time_ms":1788563389715,"raw_json":"{\"stream\":\"btcusdt@depth@100ms\",\"data\":{\"e\":\"depthUpdate\",\"E\":1788563389715,\"T\":1788563389713,\"s\":\"BTCUSDT\",\"ps\":\"BTCUSDT\",\"U\":11478233132581,\"u\":11478233136327,\"pu\":11478233132476,\"b\":[[\"29207.10\",\"0.112\"],[\"29307.10\",\"1.869\"],[\"29407.10\",\"0.119\"],[\"63686.00\",\"0.000\"],[\"71646.30\",\"0.002\"],[\"76422.80\",\"0.000\"],[\"78811.00\",\"15.338\"],[\"78970.20\",\"4.840\"],[\"79209.10\",\"4.482\"],[\"79396.00\",\"5.012\"],[\"79443.80\",\"2.433\"],[\"79454.50\",\"0.077\"],[\"79455.00\",\"2.188\"],[\"79483.20\",\"0.385\"],[\"79492.40\",\"0.099\"],[\"79515.90\",\"4.603\"],[\"79604.20\",\"0.001\"],[\"79604.30\",\"0.026\"],[\"79606.90\",\"0.198\"]],\"a\":[[\"79607.20\",\"7.567\"],[\"79697.90\",\"4.041\"],[\"79728.80\",\"0.169\"],[\"79768.20\",\"0.635\"],[\"79772.80\",\"0.013\"],[\"79815.90\",\"1.676\"],[\"79828.60\",\"7.376\"],[\"80244.10\",\"4.514\"],[\"80403.30\",\"22.286\"],[\"80602.30\",\"12.116\"]],\"st\":1}}"}
{"receive_ns":1788563389778967000,"stream":"btcusdt@depth@100ms","event_type":"depthUpdate","event_time_ms":1788563389817,"raw_json":"{\"stream\":\"btcusdt@depth@100ms\",\"data\":{\"e\":\"depthUpdate\",\"E\":1788563389817,\"T\":1788563389816,\"s\":\"BTCUSDT\",\"ps\":\"BTCUSDT\",\"U\":11478233136398,\"u\":11478233140447,\"pu\":11478233136327,\"b\":[[\"1000.00\",\"24.904\"],[\"29207.10\",\"0.182\"],[\"29307.10\",\"1.904\"],[\"29407.10\",\"0.014\"],[\"71646.30\",\"0.002\"],[\"71684.00\",\"0.000\"],[\"76422.80\",\"0.002\"],[\"78811.00\",\"15.340\"],[\"78890.50\",\"2.658\"],[\"78970.20\",\"8.000\"],[\"79010.00\",\"4.312\"],[\"79209.10\",\"4.608\"],[\"79232.90\",\"0.141\"],[\"79491.70\",\"0.000\"],[\"79492.40\",\"0.092\"],[\"79573.90\",\"0.002\"],[\"79574.70\",\"0.455\"],[\"79575.90\",\"0.001\"],[\"79581.80\",\"2.873\"],[\"79583.20\",\"1.087\"],[\"79583.80\",\"1.005\"],[\"79589.20\",\"0.470\"],[\"79593.20\",\"0.000\"],[\"79602.40\",\"0.254\"],[\"79602.50\",\"0.001\"],[\"79604.90\",\"0.001\"],[\"79605.10\",\"0.000\"]],\"a\":[[\"79611.00\",\"0.130\"],[\"79612.10\",\"0.008\"],[\"79615.00\",\"0.033\"],[\"79615.10\",\"0.000\"],[\"79616.00\",\"0.020\"],[\"79618.10\",\"0.380\"],[\"79618.30\",\"0.440\"],[\"79624.40\",\"0.000\"],[\"79625.50\",\"0.458\"],[\"79774.40\",\"2.003\"],[\"79968.00\",\"0.867\"],[\"79969.40\",\"1.367\"],[\"79995.30\",\"0.046\"],[\"79997.80\",\"0.525\"],[\"80180.10\",\"0.186\"],[\"80244.10\",\"7.624\"],[\"80320.20\",\"0.870\"],[\"80403.30\",\"22.286\"]],\"st\":1}}"}
{"receive_ns":1788563389882350000,"stream":"btcusdt@depth@100ms","event_type":"depthUpdate","event_time_ms":1788563389919,"raw_json":"{\"stream\":\"btcusdt@depth@100ms\",\"data\":{\"e\":\"depthUpdate\",\"E\":1788563389919,\"T\":1788563389918,\"s\":\"BTCUSDT\",\"ps\":\"BTCUSDT\",\"U\":11478233140451,\"u\":11478233146780,\"pu\":11478233140447,\"b\":[[\"1000.00\",\"24.754\"],[\"29207.10\",\"0.350\"],[\"29307.10\",\"1.750\"],[\"29407.10\",\"0.000\"],[\"63686.00\",\"0.000\"],[\"71646.30\",\"0.002\"],[\"76422.80\",\"0.000\"],[\"78015.00\",\"10.697\"],[\"78452.80\",\"41.237\"],[\"78568.50\",\"5.086\"],[\"78572.10\",\"2.750\"],[\"78811.00\",\"15.338\"],[\"79209.10\",\"4.598\"],[\"79455.00\",\"2.156\"],[\"79456.10\",\"0.032\"],[\"79535.40\",\"0.002\"],[\"79548.90\",\"0.000\"],[\"79567.20\",\"0.240\"],[\"79576.10\",\"0.535\"],[\"79582.70\",\"1.886\"],[\"79582.80\",\"0.001\"],[\"79583.20\",\"0.604\"],[\"79583.70\",\"0.017\"],[\"79583.80\",\"0.001\"],[\"79583.90\",\"0.688\"],[\"79602.60\",\"0.001\"],[\"79602.70\",\"0.000\"],[\"79603.30\",\"0.600\"],[\"79604.40\",\"0.026\"],[\"79604.60\",\"0.026\"],[\"79605.00\",\"0.656\"]],\"a\":[[\"79668.80\",\"25.705\"],[\"79671.50\",\"0.002\"],[\"79678.90\",\"0.015\"],[\"79682.90\",\"0.001\"],[\"80403.30\",\"22.286\"],[\"80562.50\",\"50.458\"],[\"80638.60\",\"4.769\"],[\"80761.50\",\"22.386\"]],\"st\":1}}"}
{"receive_ns":1788563389970649000,"stream":"btcusdt@bookTicker","event_type":"bookTicker","event_time_ms":1788563390008,"raw_json":"{\"stream\":\"btcusdt@bookTicker\",\"data\":{\"e\":\"bookTicker\",\"u\":11478233151393,\"s\":\"BTCUSDT\",\"ps\":\"BTCUSDT\",\"b\":\"79607.10\",\"B\":\"4.494\",\"a\":\"79607.20\",\"A\":\"7.157\",\"T\":1788563390008,\"E\":1788563390008,\"st\":1}}"}
{"receive_ns":1788563389970881000,"stream":"btcusdt@bookTicker","event_type":"bookTicker","event_time_ms":1788563390009,"raw_json":"{\"stream\":\"btcusdt@bookTicker\",\"data\":{\"e\":\"bookTicker\",\"u\":11478233151465,\"s\":\"BTCUSDT\",\"ps\":\"BTCUSDT\",\"b\":\"79607.10\",\"B\":\"4.496\",\"a\":\"79607.20\",\"A\":\"7.157\",\"T\":1788563390009,\"E\":1788563390009,\"st\":1}}"}
{"receive_ns":1788563389982377000,"stream":"btcusdt@depth@100ms","event_type":"depthUpdate","event_time_ms":1788563390021,"raw_json":"{\"stream\":\"btcusdt@depth@100ms\",\"data\":{\"e\":\"depthUpdate\",\"E\":1788563390021,\"T\":1788563390019,\"s\":\"BTCUSDT\",\"ps\":\"BTCUSDT\",\"U\":11478233146886,\"u\":11478233152073,\"pu\":11478233146780,\"b\":[[\"29207.10\",\"0.525\"],[\"29307.10\",\"1.575\"],[\"63686.00\",\"0.000\"],[\"71646.30\",\"0.002\"],[\"76422.80\",\"0.002\"],[\"78516.50\",\"2.034\"],[\"78811.00\",\"15.338\"],[\"79010.00\",\"4.944\"],[\"79232.90\",\"0.000\"],[\"79543.70\",\"0.468\"],[\"79549.90\",\"2.856\"],[\"79550.20\",\"0.033\"],[\"79563.10\",\"2.004\"],[\"79579.20\",\"0.002\"],[\"79581.80\",\"2.879\"],[\"79582.90\",\"0.000\"],[\"79583.20\",\"0.002\"],[\"79589.20\",\"0.195\"],[\"79592.40\",\"0.366\"],[\"79592.50\",\"0.001\"],[\"79593.20\",\"0.076\"],[\"79594.50\",\"0.226\"],[\"79602.80\",\"0.000\"],[\"79602.90\",\"0.002\"],[\"79605.50\",\"0.028\"],[\"79606.10\",\"0.027\"],[\"79607.10\",\"4.496\"]],\"a\":[[\"79607.20\",\"7.157\"],[\"79608.10\",\"0.027\"],[\"79609.50\",\"0.007\"],[\"79630.70\",\"0.003\"],[\"79668.10\",\"1.856\"],[\"79668.80\",\"0.317\"],[\"79676.90\",\"25.507\"],[\"79968.00\",\"0.104\"],[\"79969.40\",\"0.001\"],[\"79995.30\",\"0.002\"],[\"79997.80\",\"0.000\"],[\"80403.30\",\"22.286\"],[\"80681.90\",\"11.157\"]],\"st\":1}}"}
{"receive_ns":1788563390017331000,"stream":"btcusdt@bookTicker","event_type":"bookTicker","event_time_ms":1788563390046,"raw_json":"{\"stream\":\"btcusdt@bookTicker\",\"data\":{\"e\":\"bookTicker\",\"u\":11478233153631,\"s\":\"BTCUSDT\",\"ps\":\"BTCUSDT\",\"b\":\"79607.10\",\"B\":\"4.483\",\"a\":\"79607.20\",\"A\":\"7.157\",\"T\":1788563390046,\"E\":1788563390046,\"st\":1}}"}
{"receive_ns":1788563390017599000,"stream":"btcusdt@bookTicker","event_type":"bookTicker","event_time_ms":1788563390049,"raw_json":"{\"stream\":\"btcusdt@bookTicker\",\"data\":{\"e\":\"bookTicker\",\"u\":11478233153749,\"s\":\"BTCUSDT\",\"ps\":\"BTCUSDT\",\"b\":\"79607.10\",\"B\":\"4.496\",\"a\":\"79607.20\",\"A\":\"7.157\",\"T\":1788563390049,\"E\":1788563390049,\"st\":1}}"}
{"receive_ns":1788563390094192000,"stream":"btcusdt@depth@100ms","event_type":"depthUpdate","event_time_ms":1788563390123,"raw_json":"{\"stream\":\"btcusdt@depth@100ms\",\"data\":{\"e\":\"depthUpdate\",\"E\":1788563390123,\"T\":1788563390122,\"s\":\"BTCUSDT\",\"ps\":\"BTCUSDT\",\"U\":11478233152203,\"u\":11478233157660,\"pu\":11478233152073,\"b\":[[\"1000.00\",\"24.754\"],[\"29207.10\",\"0.707\"],[\"29307.10\",\"1.393\"],[\"63686.00\",\"0.000\"],[\"71646.30\",\"0.002\"],[\"77613.40\",\"0.194\"],[\"78015.10\",\"0.029\"],[\"78103.50\",\"0.595\"],[\"78118.40\",\"5.300\"],[\"78192.00\",\"0.028\"],[\"78280.40\",\"0.028\"],[\"78293.60\",\"4.707\"],[\"78368.90\",\"0.028\"],[\"78457.30\",\"0.028\"],[\"78473.10\",\"0.765\"],[\"78545.80\",\"1.797\"],[\"78634.20\",\"0.028\"],[\"78722.70\",\"0.029\"],[\"78811.00\",\"15.338\"],[\"78811.10\",\"0.029\"],[\"79232.90\",\"0.141\"],[\"79491.70\",\"0.583\"],[\"79557.90\",\"0.206\"],[\"79563.00\",\"0.001\"],[\"79583.20\",\"0.504\"],[\"79583.80\",\"0.001\"],[\"79589.20\",\"0.470\"],[\"79592.80\",\"0.004\"],[\"79594.50\",\"0.150\"],[\"79605.30\",\"0.000\"],[\"79605.50\",\"0.002\"],[\"79605.60\",\"0.052\"],[\"79605.90\",\"0.000\"],[\"79606.10\",\"0.001\"],[\"79607.10\",\"4.496\"]],\"a\":[[\"79616.00\",\"0.020\"],[\"79618.30\",\"0.440\"],[\"79671.50\",\"25.303\"],[\"79676.90\",\"0.206\"],[\"79774.40\",\"2.254\"],[\"79968.00\",\"0.867\"],[\"79969.40\",\"1.116\"],[\"79995.30\",\"0.046\"],[\"79997.80\",\"0.525\"],[\"80005.30\",\"0.001\"],[\"80403.30\",\"22.314\"],[\"80491.70\",\"0.028\"],[\"80580.20\",\"0.028\"],[\"80668.60\",\"0.028\"],[\"80757.10\",\"0.045\"],[\"80845.50\",\"0.028\"],[\"80920.70\",\"4.307\"],[\"80934.00\",\"0.029\"],[\"81022.40\",\"0.028\"],[\"81110.90\",\"0.028\"],[\"81199.30\",\"10.781\"]],\"st\":1}}"}
{"receive_ns":1788563390141114000,"stream":"btcusdt@bookTicker","event_type":"bookTicker","event_time_ms":1788563390179,"raw_json":"{\"stream\":\"btcusdt@bookTicker\",\"data\":{\"e\":\"bookTicker\",\"u\":11478233159988,\"s\":\"BTCUSDT\",\"ps\":\"BTCUSDT\",\"b\":\"79607.10\",\"B\":\"4.496\",\"a\":\"79607.20\",\"A\":\"7.033\",\"T\":1788563390179,\"E\":1788563390179,\"st\":1}}"}
{"receive_ns":1788563390188694000,"stream":"btcusdt@depth@100ms","event_type":"depthUpdate","event_time_ms":1788563390225,"raw_json":"{\"stream\":\"btcusdt@depth@100ms\",\"data\":{\"e\":\"depthUpdate\",\"E\":1788563390225,\"T\":1788563390221,\"s\":\"BTCUSDT\",\"ps\":\"BTCUSDT\",\"U\":11478233157719,\"u\":11478233164849,\"pu\":11478233157660,\"b\":[[\"29207.10\",\"0.882\"],[\"29307.10\",\"1.218\"],[\"71646.30\",\"0.002\"],[\"76422.80\",\"0.000\"],[\"78811.00\",\"15.338\"],[\"79209.00\",\"0.002\"],[\"79209.10\",\"4.598\"],[\"79498.80\",\"0.000\"],[\"79511.50\",\"0.024\"],[\"79528.10\",\"0.002\"],[\"79537.40\",\"0.000\"],[\"79588.80\",\"0.003\"],[\"79589.50\",\"0.063\"],[\"79592.40\",\"0.348\"],[\"79593.00\",\"0.001\"],[\"79593.20\",\"0.000\"],[\"79602.90\",\"0.028\"],[\"79603.30\",\"0.626\"],[\"79604.60\",\"0.000\"],[\"79605.00\",\"0.630\"],[\"79605.10\",\"0.000\"],[\"79605.20\",\"0.028\"],[\"79605.30\",\"0.000\"],[\"79605.60\",\"0.026\"]],\"a\":[[\"79607.20\",\"7.033\"],[\"79615.20\",\"1.216\"],[\"79668.10\",\"5.496\"],[\"79668.20\",\"2.949\"],[\"79668.80\",\"25.618\"],[\"79671.50\",\"0.002\"],[\"79702.80\",\"0.010\"],[\"79707.40\",\"0.001\"],[\"79747.40\",\"0.007\"],[\"80403.30\",\"22.314\"],[\"80598.60\",\"12.544\"],[\"81199.30\",\"10.784\"]],\"st\":1}}"}
{"receive_ns":1788563390287582000,"stream":"btcusdt@depth@100ms","event_type":"depthUpdate","event_time_ms":1788563390327,"raw_json":"{\"stream\":\"btcusdt@depth@100ms\",\"data\":{\"e\":\"depthUpdate\",\"E\":1788563390327,\"T\":1788563390325,\"s\":\"BTCUSDT\",\"ps\":\"BTCUSDT\",\"U\":11478233165025,\"u\":11478233170140,\"pu\":11478233164849,\"b\":[[\"29207.10\",\"1.064\"],[\"29307.10\",\"1.036\"],[\"63686.00\",\"0.004\"],[\"71646.30\",\"0.002\"],[\"75626.70\",\"0.019\"],[\"76422.80\",\"0.002\"],[\"78293.60\",\"5.600\"],[\"78811.00\",\"15.338\"],[\"79232.90\",\"0.141\"],[\"79483.20\",\"0.000\"],[\"79491.70\",\"0.583\"],[\"79583.20\",\"0.579\"],[\"79583.80\",\"0.001\"],[\"79589.20\",\"0.395\"],[\"79590.30\",\"0.129\"],[\"79590.60\",\"0.329\"],[\"79593.30\",\"0.077\"],[\"79605.40\",\"0.027\"]],\"a\":[[\"79615.30\",\"0.001\"],[\"79618.00\",\"0.109\"],[\"79618.10\",\"0.318\"],[\"79728.80\",\"0.000\"],[\"79774.40\",\"2.254\"],[\"79968.00\",\"0.867\"],[\"79969.40\",\"1.160\"],[\"79995.30\",\"0.002\"],[\"79997.80\",\"0.525\"],[\"80403.30\",\"22.314\"],[\"80920.70\",\"5.171\"]],\"st\":1}}"}
{"receive_ns":1788563390328645000,"stream":"btcusdt@bookTicker","event_type":"bookTicker","event_time_ms":1788563390367,"raw_json":"{\"stream\":\"btcusdt@bookTicker\",\"data\":{\"e\":\"bookTicker\",\"u\":11478233171673,\"s\":\"BTCUSDT\",\"ps\":\"BTCUSDT\",\"b\":\"79607.10\",\"B\":\"3.330\",\"a\":\"79607.20\",\"A\":\"7.033\",\"T\":1788563390367,\"E\":1788563390367,\"st\":1}}"}
{"receive_ns":1788563390330022000,"stream":"btcusdt@bookTicker","event_type":"bookTicker","event_time_ms":1788563390368,"raw_json":"{\"stream\":\"btcusdt@bookTicker\",\"data\":{\"e\":\"bookTicker\",\"u\":11478233171777,\"s\":\"BTCUSDT\",\"ps\":\"BTCUSDT\",\"b\":\"79607.10\",\"B\":\"3.427\",\"a\":\"79607.20\",\"A\":\"7.033\",\"T\":1788563390368,\"E\":1788563390368,\"st\":1}}"}
{"receive_ns":1788563390331051000,"stream":"btcusdt@bookTicker","event_type":"bookTicker","event_time_ms":1788563390369,"raw_json":"{\"stream\":\"btcusdt@bookTicker\",\"data\":{\"e\":\"bookTicker\",\"u\":11478233171855,\"s\":\"BTCUSDT\",\"ps\":\"BTCUSDT\",\"b\":\"79607.10\",\"B\":\"3.425\",\"a\":\"79607.20\",\"A\":\"7.033\",\"T\":1788563390369,\"E\":1788563390369,\"st\":1}}"}
{"receive_ns":1788563390336262000,"stream":"btcusdt@bookTicker","event_type":"bookTicker","event_time_ms":1788563390375,"raw_json":"{\"stream\":\"btcusdt@bookTicker\",\"data\":{\"e\":\"bookTicker\",\"u\":11478233172069,\"s\":\"BTCUSDT\",\"ps\":\"BTCUSDT\",\"b\":\"79607.10\",\"B\":\"4.627\",\"a\":\"79607.20\",\"A\":\"7.033\",\"T\":1788563390375,\"E\":1788563390375,\"st\":1}}"}
{"receive_ns":1788563390337403000,"stream":"btcusdt@bookTicker","event_type":"bookTicker","event_time_ms":1788563390376,"raw_json":"{\"stream\":\"btcusdt@bookTicker\",\"data\":{\"e\":\"bookTicker\",\"u\":11478233172162,\"s\":\"BTCUSDT\",\"ps\":\"BTCUSDT\",\"b\":\"79607.10\",\"B\":\"4.629\",\"a\":\"79607.20\",\"A\":\"7.033\",\"T\":1788563390376,\"E\":1788563390376,\"st\":1}}"}
{"receive_ns":1788563390337701000,"stream":"btcusdt@bookTicker","event_type":"bookTicker","event_time_ms":1788563390377,"raw_json":"{\"stream\":\"btcusdt@bookTicker\",\"data\":{\"e\":\"bookTicker\",\"u\":11478233172170,\"s\":\"BTCUSDT\",\"ps\":\"BTCUSDT\",\"b\":\"79607.10\",\"B\":\"4.628\",\"a\":\"79607.20\",\"A\":\"7.033\",\"T\":1788563390376,\"E\":1788563390377,\"st\":1}}"}
{"receive_ns":1788563390338902000,"stream":"btcusdt@bookTicker","event_type":"bookTicker","event_time_ms":1788563390377,"raw_json":"{\"stream\":\"btcusdt@bookTicker\",\"data\":{\"e\":\"bookTicker\",\"u\":11478233172208,\"s\":\"BTCUSDT\",\"ps\":\"BTCUSDT\",\"b\":\"79607.10\",\"B\":\"4.629\",\"a\":\"79607.20\",\"A\":\"7.033\",\"T\":1788563390377,\"E\":1788563390377,\"st\":1}}"}
{"receive_ns":1788563390361663000,"stream":"btcusdt@bookTicker","event_type":"bookTicker","event_time_ms":1788563390399,"raw_json":"{\"stream\":\"btcusdt@bookTicker\",\"data\":{\"e\":\"bookTicker\",\"u\":11478233172924,\"s\":\"BTCUSDT\",\"ps\":\"BTCUSDT\",\"b\":\"79607.10\",\"B\":\"4.630\",\"a\":\"79607.20\",\"A\":\"7.033\",\"T\":1788563390398,\"E\":1788563390399,\"st\":1}}"}
{"receive_ns":1788563390397862000,"stream":"btcusdt@depth@100ms","event_type":"depthUpdate","event_time_ms":1788563390429,"raw_json":"{\"stream\":\"btcusdt@depth@100ms\",\"data\":{\"e\":\"depthUpdate\",\"E\":1788563390429,\"T\":1788563390425,\"s\":\"BTCUSDT\",\"ps\":\"BTCUSDT\",\"U\":11478233170228,\"u\":11478233173955,\"pu\":11478233170140,\"b\":[[\"1000.00\",\"24.754\"],[\"29207.10\",\"1.239\"],[\"29307.10\",\"0.861\"],[\"63686.00\",\"0.000\"],[\"71202.30\",\"0.019\"],[\"71646.30\",\"0.002\"],[\"76422.80\",\"0.000\"],[\"78516.50\",\"2.542\"],[\"78522.60\",\"0.509\"],[\"78608.50\",\"11.695\"],[\"78811.00\",\"15.338\"],[\"79483.20\",\"0.500\"],[\"79492.40\",\"0.106\"],[\"79502.40\",\"0.016\"],[\"79508.30\",\"0.000\"],[\"79524.20\",\"0.039\"],[\"79533.00\",\"0.018\"],[\"79542.00\",\"0.076\"],[\"79573.90\",\"0.002\"],[\"79574.70\",\"0.003\"],[\"79574.90\",\"0.474\"],[\"79576.10\",\"0.535\"],[\"79583.20\",\"0.077\"],[\"79593.20\",\"0.076\"],[\"79593.30\",\"0.001\"],[\"79595.70\",\"0.001\"],[\"79597.20\",\"0.186\"],[\"79597.30\",\"0.054\"],[\"79597.80\",\"0.002\"],[\"79602.90\",\"0.002\"],[\"79604.00\",\"0.003\"],[\"79604.90\",\"0.000\"],[\"79605.70\",\"0.138\"],[\"79605.90\",\"0.001\"],[\"79607.10\",\"4.630\"]],\"a\":[[\"79615.30\",\"0.001\"],[\"79616.20\",\"0.082\"],[\"79618.00\",\"0.047\"],[\"79618.10\",\"0.318\"],[\"79618.30\",\"0.502\"],[\"79623.50\",\"0.001\"],[\"79624.50\",\"0.479\"],[\"79625.50\",\"0.458\"],[\"79728.80\",\"0.276\"],[\"80244.10\",\"7.375\"],[\"80403.30\",\"22.314\"],[\"81199.30\",\"10.781\"]],\"st\":1}}"}
{"receive_ns":1788563390407756000,"stream":"btcusdt@bookTicker","event_type":"bookTicker","event_time_ms":1788563390446,"raw_json":"{\"stream\":\"btcusdt@bookTicker\",\"data\":{\"e\":\"bookTicker\",\"u\":11478233174631,\"s\":\"BTCUSDT\",\"ps\":\"BTCUSDT\",\"b\":\"79607.10\",\"B\":\"3.983\",\"a\":\"79607.20\",\"A\":\"7.033\",\"T\":1788563390446,\"E\":1788563390446,\"st\":1}}"}
{"receive_ns":1788563390410550000,"stream":"btcusdt@bookTicker","event_type":"bookTicker","event_time_ms":1788563390449,"raw_json":"{\"stream\":\"btcusdt@bookTicker\",\"data\":{\"e\":\"bookTicker\",\"u\":11478233174764,\"s\":\"BTCUSDT\",\"ps\":\"BTCUSDT\",\"b\":\"79607.10\",\"B\":\"4.631\",\"a\":\"79607.20\",\"A\":\"7.033\",\"T\":1788563390449,\"E\":1788563390449,\"st\":1}}"}
{"receive_ns":1788563390412246000,"stream":"btcusdt@bookTicker","event_type":"bookTicker","event_time_ms":1788563390451,"raw_json":"{\"stream\":\"btcusdt@bookTicker\",\"data\":{\"e\":\"bookTicker\",\"u\":11478233174832,\"s\":\"BTCUSDT\",\"ps\":\"BTCUSDT\",\"b\":\"79607.10\",\"B\":\"4.629\",\"a\":\"79607.20\",\"A\":\"7.033\",\"T\":1788563390450,\"E\":1788563390451,\"st\":1}}"}
{"receive_ns":1788563390418081000,"stream":"btcusdt@bookTicker","event_type":"bookTicker","event_time_ms":1788563390457,"raw_json":"{\"stream\":\"btcusdt@bookTicker\",\"data\":{\"e\":\"bookTicker\",\"u\":11478233175039,\"s\":\"BTCUSDT\",\"ps\":\"BTCUSDT\",\"b\":\"79607.10\",\"B\":\"4.633\",\"a\":\"79607.20\",\"A\":\"7.033\",\"T\":1788563390456,\"E\":1788563390457,\"st\":1}}"}
{"receive_ns":1788563390492422000,"stream":"btcusdt@depth@100ms","event_type":"depthUpdate","event_time_ms":1788563390531,"raw_json":"{\"stream\":\"btcusdt@depth@100ms\",\"data\":{\"e\":\"depthUpdate\",\"E\":1788563390531,\"T\":1788563390529,\"s\":\"BTCUSDT\",\"ps\":\"BTCUSDT\",\"U\":11478233174075,\"u\":11478233178446,\"pu\":11478233173955,\"b\":[[\"29207.10\",\"1.421\"],[\"29307.10\",\"0.679\"],[\"71202.30\",\"0.000\"],[\"71646.30\",\"0.002\"],[\"78811.00\",\"14.704\"],[\"78970.20\",\"8.000\"],[\"79209.10\",\"4.608\"],[\"79232.90\",\"0.141\"],[\"79491.70\",\"0.583\"],[\"79583.20\",\"0.504\"],[\"79583.80\",\"2.009\"],[\"79589.20\",\"0.470\"],[\"79597.70\",\"0.002\"],[\"79598.30\",\"0.275\"],[\"79604.90\",\"0.001\"],[\"79605.50\",\"0.028\"],[\"79605.90\",\"0.000\"],[\"79607.10\",\"4.633\"]],\"a\":[[\"79615.30\",\"0.001\"],[\"79618.00\",\"0.113\"],[\"79618.10\",\"0.314\"],[\"79618.30\",\"0.440\"],[\"79630.60\",\"1.886\"],[\"79668.10\",\"1.856\"],[\"79668.80\",\"0.317\"],[\"79676.90\",\"25.507\"],[\"79774.40\",\"2.254\"],[\"79968.00\",\"0.867\"],[\"79969.40\",\"0.961\"],[\"79997.80\",\"0.525\"],[\"80403.30\",\"22.314\"]],\"st\":1}}"}
{"receive_ns":1788563390495067000,"stream":"btcusdt@bookTicker","event_type":"bookTicker","event_time_ms":1788563390535,"raw_json":"{\"stream\":\"btcusdt@bookTicker\",\"data\":{\"e\":\"bookTicker\",\"u\":11478233178792,\"s\":\"BTCUSDT\",\"ps\":\"BTCUSDT\",\"b\":\"79607.10\",\"B\":\"4.079\",\"a\":\"79607.20\",\"A\":\"7.033\",\"T\":1788563390534,\"E\":1788563390535,\"st\":1}}"}
{"receive_ns":1788563390497821000,"stream":"btcusdt@bookTicker","event_type":"bookTicker","event_time_ms":1788563390535,"raw_json":"{\"stream\":\"btcusdt@bookTicker\",\"data\":{\"e\":\"bookTicker\",\"u\":11478233178850,\"s\":\"BTCUSDT\",\"ps\":\"BTCUSDT\",\"b\":\"79607.10\",\"B\":\"4.081\",\"a\":\"79607.20\",\"A\":\"7.033\",\"T\":1788563390535,\"E\":1788563390535,\"st\":1}}"}
{"receive_ns":1788563390498983000,"stream":"btcusdt@bookTicker","event_type":"bookTicker","event_time_ms":1788563390537,"raw_json":"{\"stream\":\"btcusdt@bookTicker\",\"data\":{\"e\":\"bookTicker\",\"u\":11478233178964,\"s\":\"BTCUSDT\",\"ps\":\"BTCUSDT\",\"b\":\"79607.10\",\"B\":\"4.637\",\"a\":\"79607.20\",\"A\":\"7.033\",\"T\":1788563390537,\"E\":1788563390537,\"st\":1}}"}
{"receive_ns":1788563390595240000,"stream":"btcusdt@depth@100ms","event_type":"depthUpdate","event_time_ms":1788563390633,"raw_json":"{\"stream\":\"btcusdt@depth@100ms\",\"data\":{\"e\":\"depthUpdate\",\"E\":1788563390633,\"T\":1788563390631,\"s\":\"BTCUSDT\",\"ps\":\"BTCUSDT\",\"U\":11478233178522,\"u\":11478233182366,\"pu\":11478233178446,\"b\":[[\"29207.10\",\"1.596\"],[\"29307.10\",\"0.504\"],[\"63685.70\",\"0.001\"],[\"63686.00\",\"0.000\"],[\"71646.30\",\"0.002\"],[\"76422.80\",\"0.002\"],[\"78608.50\",\"11.479\"],[\"78811.00\",\"14.704\"],[\"79583.40\",\"0.006\"],[\"79583.80\",\"0.001\"],[\"79598.30\",\"0.273\"],[\"79598.50\",\"0.003\"],[\"79607.10\",\"4.637\"]],\"a\":[[\"79615.30\",\"0.001\"],[\"79618.00\",\"0.426\"],[\"79618.10\",\"0.001\"],[\"79623.30\",\"0.458\"],[\"79668.20\",\"2.948\"],[\"79668.90\",\"0.000\"],[\"79676.90\",\"25.450\"],[\"79969.40\",\"1.160\"],[\"80364.50\",\"0.000\"],[\"80403.30\",\"22.314\"]],\"st\":1}}"}
{"receive_ns":1788563390696971000,"stream":"btcusdt@depth@100ms","event_type":"depthUpdate","event_time_ms":1788563390735,"raw_json":"{\"stream\":\"btcusdt@depth@100ms\",\"data\":{\"e\":\"depthUpdate\",\"E\":1788563390735,\"T\":1788563390734,\"s\":\"BTCUSDT\",\"ps\":\"BTCUSDT\",\"U\":11478233182438,\"u\":11478233186225,\"pu\":11478233182366,\"b\":[[\"1000.00\",\"24.754\"],[\"29107.10\",\"0.007\"],[\"29207.10\",\"1.764\"],[\"29307.10\",\"0.329\"],[\"71646.30\",\"0.002\"],[\"76422.80\",\"0.000\"],[\"78015.00\",\"10.694\"],[\"78811.00\",\"14.704\"],[\"79606.90\",\"0.196\"]],\"a\":[[\"80403.30\",\"22.314\"]],\"st\":1}}"}
{"receive_ns":1788563390799392000,"stream":"btcusdt@depth@100ms","event_type":"depthUpdate","event_time_ms":1788563390837,"raw_json":"{\"stream\":\"btcusdt@depth@100ms\",\"data\":{\"e\":\"depthUpdate\",\"E\":1788563390837,\"T\":1788563390833,\"s\":\"BTCUSDT\",\"ps\":\"BTCUSDT\",\"U\":11478233186305,\"u\":11478233190286,\"pu\":11478233186225,\"b\":[[\"29107.10\",\"0.070\"],[\"29207.10\",\"1.813\"],[\"29307.10\",\"0.217\"],[\"71646.30\",\"0.002\"],[\"76422.80\",\"0.002\"],[\"78811.00\",\"14.704\"],[\"78887.00\",\"1.079\"],[\"79209.10\",\"4.598\"],[\"79232.90\",\"0.141\"],[\"79491.70\",\"0.232\"],[\"79583.20\",\"0.353\"],[\"79583.80\",\"0.001\"],[\"79589.20\",\"0.972\"],[\"79589.30\",\"0.001\"],[\"79589.50\",\"0.067\"],[\"79589.80\",\"0.006\"],[\"79591.30\",\"0.000\"],[\"79603.00\",\"0.003\"],[\"79605.80\",\"0.027\"]],\"a\":[[\"79671.50\",\"25.246\"],[\"79676.90\",\"0.206\"],[\"79774.40\",\"2.003\"],[\"79968.00\",\"0.867\"],[\"79969.40\",\"1.367\"],[\"79995.30\",\"0.046\"],[\"79997.80\",\"0.525\"],[\"80403.30\",\"22.314\"],[\"80950.50\",\"1.707\"]],\"st\":1}}"}
{"receive_ns":1788563390806615000,"stream":"btcusdt@bookTicker","event_type":"bookTicker","event_time_ms":1788563390843,"raw_json":"{\"stream\":\"btcusdt@bookTicker\",\"data\":{\"e\":\"bookTicker\",\"u\":11478233190723,\"s\":\"BTCUSDT\",\"ps\":\"BTCUSDT\",\"b\":\"79607.10\",\"B\":\"4.637\",\"a\":\"79607.20\",\"A\":\"7.042\",\"T\":1788563390843,\"E\":1788563390843,\"st\":1}}"}
{"receive_ns":1788563390904436000,"stream":"btcusdt@depth@100ms","event_type":"depthUpdate","event_time_ms":1788563390939,"raw_json":"{\"stream\":\"btcusdt@depth@100ms\",\"data\":{\"e\":\"depthUpdate\",\"E\":1788563390939,\"T\":1788563390937,\"s\":\"BTCUSDT\",\"ps\":\"BTCUSDT\",\"U\":11478233190493,\"u\":11478233195357,\"pu\":11478233190286,\"b\":[[\"29107.10\",\"0.126\"],[\"29207.10\",\"1.883\"],[\"29307.10\",\"0.091\"],[\"63686.00\",\"0.000\"],[\"71646.30\",\"0.002\"],[\"76422.80\",\"0.000\"],[\"78811.00\",\"14.704\"],[\"78890.60\",\"42.629\"],[\"79605.80\",\"0.001\"]],\"a\":[[\"79607.20\",\"7.042\"],[\"79630.60\",\"1.884\"],[\"80363.50\",\"15.995\"],[\"80403.30\",\"22.314\"],[\"80562.50\",\"49.963\"],[\"83587.50\",\"0.029\"]],\"st\":1}}"}
{"receive_ns":1788563390968114000,"stream":"btcusdt@bookTicker","event_type":"bookTicker","event_time_ms":1788563391008,"raw_json":"{\"stream\":\"btcusdt@bookTicker\",\"data\":{\"e\":\"bookTicker\",\"u\":11478233198907,\"s\":\"BTCUSDT\",\"ps\":\"BTCUSDT\",\"b\":\"79607.10\",\"B\":\"5.063\",\"a\":\"79607.20\",\"A\":\"7.042\",\"T\":1788563391007,\"E\":1788563391008,\"st\":1}}"}
{"receive_ns":1788563390971615000,"stream":"btcusdt@bookTicker","event_type":"bookTicker","event_time_ms":1788563391009,"raw_json":"{\"stream\":\"btcusdt@bookTicker\",\"data\":{\"e\":\"bookTicker\",\"u\":11478233199149,\"s\":\"BTCUSDT\",\"ps\":\"BTCUSDT\",\"b\":\"79607.10\",\"B\":\"5.061\",\"a\":\"79607.20\",\"A\":\"7.042\",\"T\":1788563391009,\"E\":1788563391009,\"st\":1}}"}
{"receive_ns":1788563390971835000,"stream":"btcusdt@bookTicker","event_type":"bookTicker","event_time_ms":1788563391009,"raw_json":"{\"stream\":\"btcusdt@bookTicker\",\"data\":{\"e\":\"bookTicker\",\"u\":11478233199161,\"s\":\"BTCUSDT\",\"ps\":\"BTCUSDT\",\"b\":\"79607.10\",\"B\":\"5.062\",\"a\":\"79607.20\",\"A\":\"7.042\",\"T\":1788563391009,\"E\":1788563391009,\"st\":1}}"}
{"receive_ns":1788563391001635000,"stream":"btcusdt@depth@100ms","event_type":"depthUpdate","event_time_ms":1788563391041,"raw_json":"{\"stream\":\"btcusdt@depth@100ms\",\"data\":{\"e\":\"depthUpdate\",\"E\":1788563391041,\"T\":1788563391038,\"s\":\"BTCUSDT\",\"ps\":\"BTCUSDT\",\"U\":11478233195446,\"u\":11478233201122,\"pu\":11478233195357,\"b\":[[\"1000.00\",\"24.754\"],[\"29107.10\",\"0.210\"],[\"29207.10\",\"1.890\"],[\"29307.10\",\"0.000\"],[\"63686.00\",\"0.000\"],[\"71202.30\",\"0.000\"],[\"71646.30\",\"0.002\"],[\"71684.00\",\"0.003\"],[\"78651.80\",\"52.032\"],[\"78811.00\",\"14.704\"],[\"78888.10\",\"0.000\"],[\"78890.70\",\"3.240\"],[\"79232.90\",\"0.141\"],[\"79491.70\",\"0.232\"],[\"79583.20\",\"0.353\"],[\"79589.20\",\"0.972\"],[\"79589.50\",\"0.063\"],[\"79589.80\",\"0.006\"],[\"79591.30\",\"0.004\"],[\"79592.80\",\"0.008\"],[\"79593.20\",\"0.076\"],[\"79597.80\",\"0.001\"],[\"79600.90\",\"0.002\"],[\"79603.20\",\"0.003\"],[\"79604.20\",\"0.027\"],[\"79604.60\",\"0.026\"],[\"79604.70\",\"0.027\"],[\"79604.90\",\"0.027\"],[\"79605.00\",\"0.656\"],[\"79605.20\",\"0.002\"],[\"79605.40\",\"0.001\"],[\"79605.50\",\"0.002\"],[\"79607.10\",\"5.062\"]],\"a\":[[\"79616.00\",\"0.020\"],[\"79618.00\",\"0.422\"],[\"79618.30\",\"0.444\"],[\"79968.00\",\"0.867\"],[\"79969.40\",\"1.367\"],[\"79995.30\",\"0.046\"],[\"79997.80\",\"0.525\"],[\"80403.30\",\"22.314\"]],\"st\":1}}"}
{"receive_ns":1788563391060766000,"stream":"btcusdt@bookTicker","event_type":"bookTicker","event_time_ms":1788563391092,"raw_json":"{\"stream\":\"btcusdt@bookTicker\",\"data\":{\"e\":\"bookTicker\",\"u\":11478233203798,\"s\":\"BTCUSDT\",\"ps\":\"BTCUSDT\",\"b\":\"79607.10\",\"B\":\"4.583\",\"a\":\"79607.20\",\"A\":\"7.042\",\"T\":1788563391092,\"E\":1788563391092,\"st\":1}}"}
{"receive_ns":1788563391061033000,"stream":"btcusdt@bookTicker","event_type":"bookTicker","event_time_ms":1788563391093,"raw_json":"{\"stream\":\"btcusdt@bookTicker\",\"data\":{\"e\":\"bookTicker\",\"u\":11478233203838,\"s\":\"BTCUSDT\",\"ps\":\"BTCUSDT\",\"b\":\"79607.10\",\"B\":\"4.585\",\"a\":\"79607.20\",\"A\":\"7.042\",\"T\":1788563391093,\"E\":1788563391093,\"st\":1}}"}
{"receive_ns":1788563391069478000,"stream":"btcusdt@bookTicker","event_type":"bookTicker","event_time_ms":1788563391109,"raw_json":"{\"stream\":\"btcusdt@bookTicker\",\"data\":{\"e\":\"bookTicker\",\"u\":11478233204865,\"s\":\"BTCUSDT\",\"ps\":\"BTCUSDT\",\"b\":\"79607.10\",\"B\":\"5.072\",\"a\":\"79607.20\",\"A\":\"7.042\",\"T\":1788563391108,\"E\":1788563391109,\"st\":1}}"}
{"receive_ns":1788563391070640000,"stream":"btcusdt@bookTicker","event_type":"bookTicker","event_time_ms":1788563391110,"raw_json":"{\"stream\":\"btcusdt@bookTicker\",\"data\":{\"e\":\"bookTicker\",\"u\":11478233204919,\"s\":\"BTCUSDT\",\"ps\":\"BTCUSDT\",\"b\":\"79607.10\",\"B\":\"5.070\",\"a\":\"79607.20\",\"A\":\"7.042\",\"T\":1788563391110,\"E\":1788563391110,\"st\":1}}"}
{"receive_ns":1788563391077179000,"stream":"btcusdt@bookTicker","event_type":"bookTicker","event_time_ms":1788563391116,"raw_json":"{\"stream\":\"btcusdt@bookTicker\",\"data\":{\"e\":\"bookTicker\",\"u\":11478233205240,\"s\":\"BTCUSDT\",\"ps\":\"BTCUSDT\",\"b\":\"79607.10\",\"B\":\"5.057\",\"a\":\"79607.20\",\"A\":\"7.042\",\"T\":1788563391116,\"E\":1788563391116,\"st\":1}}"}
{"receive_ns":1788563391080593000,"stream":"btcusdt@bookTicker","event_type":"bookTicker","event_time_ms":1788563391119,"raw_json":"{\"stream\":\"btcusdt@bookTicker\",\"data\":{\"e\":\"bookTicker\",\"u\":11478233205760,\"s\":\"BTCUSDT\",\"ps\":\"BTCUSDT\",\"b\":\"79607.10\",\"B\":\"5.072\",\"a\":\"79607.20\",\"A\":\"7.042\",\"T\":1788563391119,\"E\":1788563391119,\"st\":1}}"}
{"receive_ns":1788563391080852000,"stream":"btcusdt@bookTicker","event_type":"bookTicker","event_time_ms":1788563391121,"raw_json":"{\"stream\":\"btcusdt@bookTicker\",\"data\":{\"e\":\"bookTicker\",\"u\":11478233205843,\"s\":\"BTCUSDT\",\"ps\":\"BTCUSDT\",\"b\":\"79607.10\",\"B\":\"5.074\",\"a\":\"79607.20\",\"A\":\"7.042\",\"T\":1788563391120,\"E\":1788563391121,\"st\":1}}"}
{"receive_ns":1788563391104929000,"stream":"btcusdt@depth@100ms","event_type":"depthUpdate","event_time_ms":1788563391143,"raw_json":"{\"stream\":\"btcusdt@depth@100ms\",\"data\":{\"e\":\"depthUpdate\",\"E\":1788563391143,\"T\":1788563391142,\"s\":\"BTCUSDT\",\"ps\":\"BTCUSDT\",\"U\":11478233201279,\"u\":11478233206722,\"pu\":11478233201122,\"b\":[[\"29107.10\",\"0.392\"],[\"29207.10\",\"1.708\"],[\"63686.00\",\"0.000\"],[\"71646.30\",\"0.002\"],[\"71684.00\",\"0.000\"],[\"76422.80\",\"0.002\"],[\"76422.90\",\"0.001\"],[\"78811.00\",\"14.704\"],[\"78870.10\",\"0.000\"],[\"79209.10\",\"4.598\"],[\"79421.10\",\"3.140\"],[\"79519.40\",\"0.038\"],[\"79576.30\",\"0.051\"],[\"79589.50\",\"0.067\"],[\"79591.30\",\"0.000\"],[\"79592.80\",\"0.004\"],[\"79597.80\",\"0.001\"],[\"79600.90\",\"0.002\"],[\"79603.00\",\"0.003\"],[\"79603.10\",\"0.252\"],[\"79603.20\",\"0.029\"],[\"79604.40\",\"0.000\"],[\"79604.50\",\"0.026\"],[\"79604.60\",\"0.000\"],[\"79604.70\",\"0.001\"],[\"79604.90\",\"0.000\"],[\"79605.00\",\"0.630\"],[\"79605.20\",\"0.002\"],[\"79605.50\",\"0.028\"],[\"79605.60\",\"0.027\"],[\"79606.90\",\"0.198\"],[\"79607.10\",\"5.074\"]],\"a\":[[\"79616.20\",\"0.082\"],[\"79618.30\",\"0.444\"],[\"79668.10\",\"5.488\"],[\"79694.60\",\"0.039\"],[\"79748.30\",\"3.140\"],[\"80403.30\",\"22.316\"]],\"st\":1}}"}
{"receive_ns":1788563391213672000,"stream":"btcusdt@depth@100ms","event_type":"depthUpdate","event_time_ms":1788563391245,"raw_json":"{\"stream\":\"btcusdt@depth@100ms\",\"data\":{\"e\":\"depthUpdate\",\"E\":1788563391245,\"T\":1788563391242,\"s\":\"BTCUSDT\",\"ps\":\"BTCUSDT\",\"U\":11478233206750,\"u\":11478233210904,\"pu\":11478233206722,\"b\":[[\"1000.00\",\"24.754\"],[\"29107.10\",\"0.567\"],[\"29207.10\",\"1.533\"],[\"71646.30\",\"0.002\"],[\"76422.80\",\"0.000\"],[\"78364.30\",\"2.558\"],[\"78443.90\",\"1.847\"],[\"78492.60\",\"54.619\"],[\"78608.50\",\"11.194\"],[\"78651.80\",\"51.396\"],[\"78811.00\",\"14.704\"],[\"79209.00\",\"0.000\"],[\"79232.90\",\"0.000\"],[\"79491.70\",\"0.000\"],[\"79511.50\",\"0.024\"],[\"79535.40\",\"0.000\"],[\"79583.20\",\"0.002\"],[\"79589.20\",\"0.195\"],[\"79603.00\",\"0.029\"],[\"79604.50\",\"0.000\"],[\"79605.20\",\"0.028\"],[\"79605.30\",\"0.000\"],[\"79605.50\",\"0.002\"]],\"a\":[[\"79668.20\",\"2.949\"],[\"79678.90\",\"0.015\"],[\"79702.80\",\"0.001\"],[\"79707.60\",\"8.785\"],[\"79968.00\",\"0.104\"],[\"79969.40\",\"0.001\"],[\"79995.30\",\"0.002\"],[\"79997.80\",\"0.000\"],[\"80403.30\",\"22.314\"],[\"81199.30\",\"10.784\"]],\"st\":1}}"}
{"receive_ns":1788563391222659000,"stream":"btcusdt@bookTicker","event_type":"bookTicker","event_time_ms":1788563391259,"raw_json":"{\"stream\":\"btcusdt@bookTicker\",\"data\":{\"e\":\"bookTicker\",\"u\":11478233211474,\"s\":\"BTCUSDT\",\"ps\":\"BTCUSDT\",\"b\":\"79607.10\",\"B\":\"4.639\",\"a\":\"79607.20\",\"A\":\"7.042\",\"T\":1788563391259,\"E\":1788563391259,\"st\":1}}"}
{"receive_ns":1788563391223440000,"stream":"btcusdt@bookTicker","event_type":"bookTicker","event_time_ms":1788563391262,"raw_json":"{\"stream\":\"btcusdt@bookTicker\",\"data\":{\"e\":\"bookTicker\",\"u\":11478233211592,\"s\":\"BTCUSDT\",\"ps\":\"BTCUSDT\",\"b\":\"79607.10\",\"B\":\"5.080\",\"a\":\"79607.20\",\"A\":\"7.042\",\"T\":1788563391262,\"E\":1788563391262,\"st\":1}}"}
{"receive_ns":1788563391223632000,"stream":"btcusdt@bookTicker","event_type":"bookTicker","event_time_ms":1788563391263,"raw_json":"{\"stream\":\"btcusdt@bookTicker\",\"data\":{\"e\":\"bookTicker\",\"u\":11478233211625,\"s\":\"BTCUSDT\",\"ps\":\"BTCUSDT\",\"b\":\"79607.10\",\"B\":\"5.078\",\"a\":\"79607.20\",\"A\":\"7.042\",\"T\":1788563391263,\"E\":1788563391263,\"st\":1}}"}
{"receive_ns":1788563391223764000,"stream":"btcusdt@bookTicker","event_type":"bookTicker","event_time_ms":1788563391263,"raw_json":"{\"stream\":\"btcusdt@bookTicker\",\"data\":{\"e\":\"bookTicker\",\"u\":11478233211635,\"s\":\"BTCUSDT\",\"ps\":\"BTCUSDT\",\"b\":\"79607.10\",\"B\":\"5.077\",\"a\":\"79607.20\",\"A\":\"7.042\",\"T\":1788563391263,\"E\":1788563391263,\"st\":1}}"}
{"receive_ns":1788563391223884000,"stream":"btcusdt@bookTicker","event_type":"bookTicker","event_time_ms":1788563391263,"raw_json":"{\"stream\":\"btcusdt@bookTicker\",\"data\":{\"e\":\"bookTicker\",\"u\":11478233211638,\"s\":\"BTCUSDT\",\"ps\":\"BTCUSDT\",\"b\":\"79607.10\",\"B\":\"5.078\",\"a\":\"79607.20\",\"A\":\"7.042\",\"T\":1788563391263,\"E\":1788563391263,\"st\":1}}"}
{"receive_ns":1788563391309761000,"stream":"btcusdt@depth@100ms","event_type":"depthUpdate","event_time_ms":1788563391347,"raw_json":"{\"stream\":\"btcusdt@depth@100ms\",\"data\":{\"e\":\"depthUpdate\",\"E\":1788563391347,\"T\":1788563391346,\"s\":\"BTCUSDT\",\"ps\":\"BTCUSDT\",\"U\":11478233211003,\"u\":11478233214221,\"pu\":11478233210904,\"b\":[[\"1000.00\",\"24.754\"],[\"29107.10\",\"0.749\"],[\"29207.10\",\"1.351\"],[\"71646.30\",\"0.002\"],[\"76422.80\",\"0.002\"],[\"78811.00\",\"14.704\"],[\"79232.90\",\"0.141\"],[\"79491.70\",\"0.483\"],[\"79523.50\",\"0.000\"],[\"79524.30\",\"0.126\"],[\"79535.50\",\"0.100\"],[\"79557.40\",\"6.975\"],[\"79557.90\",\"0.205\"],[\"79583.20\",\"0.504\"],[\"79583.80\",\"0.001\"],[\"79589.20\",\"0.470\"],[\"79589.50\",\"0.063\"],[\"79589.80\",\"0.010\"],[\"79591.30\",\"0.000\"],[\"79597.80\",\"0.001\"],[\"79598.50\",\"0.001\"],[\"79598.70\",\"0.004\"],[\"79600.90\",\"0.002\"],[\"79605.50\",\"0.028\"],[\"79607.10\",\"5.078\"]],\"a\":[[\"79613.40\",\"0.002\"],[\"79613.70\",\"0.378\"],[\"79615.10\",\"0.000\"],[\"79615.30\",\"0.001\"],[\"79618.00\",\"0.360\"],[\"79618.10\",\"0.063\"],[\"79668.10\",\"5.489\"],[\"79668.80\",\"0.316\"],[\"79968.00\",\"0.867\"],[\"79969.40\",\"1.411\"],[\"79997.80\",\"0.525\"],[\"80005.30\",\"0.003\"],[\"80323.70\",\"23.158\"],[\"80403.30\",\"22.314\"],[\"80729.70\",\"4.329\"]],\"st\":1}}"}
{"receive_ns":1788563391408174000,"stream":"btcusdt@depth@100ms","event_type":"depthUpdate","event_time_ms":1788563391449,"raw_json":"{\"stream\":\"btcusdt@depth@100ms\",\"data\":{\"e\":\"depthUpdate\",\"E\":1788563391449,\"T\":1788563391447,\"s\":\"BTCUSDT\",\"ps\":\"BTCUSDT\",\"U\":11478233214256,\"u\":11478233217492,\"pu\":11478233214221,\"b\":[[\"29107.10\",\"0.924\"],[\"29207.10\",\"1.176\"],[\"71646.30\",\"0.002\"],[\"75626.70\",\"0.017\"],[\"75626.80\",\"0.008\"],[\"76422.80\",\"0.000\"],[\"78452.80\",\"42.128\"],[\"78811.00\",\"14.704\"],[\"79209.10\",\"4.608\"],[\"79581.80\",\"2.873\"],[\"79584.30\",\"0.006\"],[\"79597.30\",\"0.053\"]],\"a\":[[\"80403.30\",\"22.314\"],[\"80464.90\",\"1.116\"]],\"st\":1}}"}
{"receive_ns":1788563391456042000,"stream":"btcusdt@bookTicker","event_type":"bookTicker","event_time_ms":1788563391493,"raw_json":"{\"stream\":\"btcusdt@bookTicker\",\"data\":{\"e\":\"bookTicker\",\"u\":11478233218923,\"s\":\"BTCUSDT\",\"ps\":\"BTCUSDT\",\"b\":\"79607.10\",\"B\":\"4.430\",\"a\":\"79607.20\",\"A\":\"7.042\",\"T\":1788563391493,\"E\":1788563391493,\"st\":1}}"}
{"receive_ns":1788563391456401000,"stream":"btcusdt@bookTicker","event_type":"bookTicker","event_time_ms":1788563391494,"raw_json":"{\"stream\":\"btcusdt@bookTicker\",\"data\":{\"e\":\"bookTicker\",\"u\":11478233218964,\"s\":\"BTCUSDT\",\"ps\":\"BTCUSDT\",\"b\":\"79607.10\",\"B\":\"4.432\",\"a\":\"79607.20\",\"A\":\"7.042\",\"T\":1788563391494,\"E\":1788563391494,\"st\":1}}"}
{"receive_ns":1788563391457552000,"stream":"btcusdt@bookTicker","event_type":"bookTicker","event_time_ms":1788563391496,"raw_json":"{\"stream\":\"btcusdt@bookTicker\",\"data\":{\"e\":\"bookTicker\",\"u\":11478233219119,\"s\":\"BTCUSDT\",\"ps\":\"BTCUSDT\",\"b\":\"79607.10\",\"B\":\"5.085\",\"a\":\"79607.20\",\"A\":\"7.042\",\"T\":1788563391496,\"E\":1788563391496,\"st\":1}}"}
{"receive_ns":1788563391478075000,"stream":"btcusdt@bookTicker","event_type":"bookTicker","event_time_ms":1788563391517,"raw_json":"{\"stream\":\"btcusdt@bookTicker\",\"data\":{\"e\":\"bookTicker\",\"u\":11478233219980,\"s\":\"BTCUSDT\",\"ps\":\"BTCUSDT\",\"b\":\"79607.10\",\"B\":\"5.085\",\"a\":\"79607.20\",\"A\":\"7.036\",\"T\":1788563391517,\"E\":1788563391517,\"st\":1}}"}
{"receive_ns":1788563391478396000,"stream":"btcusdt@trade","event_type":"trade","event_time_ms":1788563391517,"raw_json":"{\"stream\":\"btcusdt@trade\",\"data\":{\"e\":\"trade\",\"E\":1788563391517,\"T\":1788563391517,\"s\":\"BTCUSDT\",\"t\":8054083500,\"p\":\"79607.20\",\"q\":\"0.006\",\"X\":\"MARKET\",\"m\":false,\"st\":1}}"}
{"receive_ns":1788563391501000000,"stream":"btcusdt@bookTicker","event_type":"bookTicker","event_time_ms":1788563391539,"raw_json":"{\"stream\":\"btcusdt@bookTicker\",\"data\":{\"e\":\"bookTicker\",\"u\":11478233220794,\"s\":\"BTCUSDT\",\"ps\":\"BTCUSDT\",\"b\":\"79607.10\",\"B\":\"5.078\",\"a\":\"79607.20\",\"A\":\"7.036\",\"T\":1788563391539,\"E\":1788563391539,\"st\":1}}"}
{"receive_ns":1788563391515047000,"stream":"btcusdt@depth@100ms","event_type":"depthUpdate","event_time_ms":1788563391551,"raw_json":"{\"stream\":\"btcusdt@depth@100ms\",\"data\":{\"e\":\"depthUpdate\",\"E\":1788563391551,\"T\":1788563391550,\"s\":\"BTCUSDT\",\"ps\":\"BTCUSDT\",\"U\":11478233217537,\"u\":11478233221123,\"pu\":11478233217492,\"b\":[[\"1000.00\",\"24.754\"],[\"29107.10\",\"1.106\"],[\"29207.10\",\"0.994\"],[\"71646.30\",\"0.002\"],[\"75626.70\",\"0.019\"],[\"75626.80\",\"0.006\"],[\"78572.10\",\"3.640\"],[\"78811.00\",\"14.704\"],[\"79232.90\",\"0.141\"],[\"79396.00\",\"0.000\"],[\"79396.10\",\"5.020\"],[\"79491.70\",\"0.232\"],[\"79515.90\",\"4.610\"],[\"79519.50\",\"0.000\"],[\"79524.10\",\"1.321\"],[\"79524.30\",\"0.001\"],[\"79535.50\",\"0.251\"],[\"79573.90\",\"0.454\"],[\"79574.90\",\"0.022\"],[\"79576.30\",\"0.049\"],[\"79583.20\",\"0.102\"],[\"79583.80\",\"0.001\"],[\"79589.20\",\"0.972\"],[\"79589.80\",\"0.010\"],[\"79594.40\",\"0.005\"],[\"79597.10\",\"0.033\"],[\"79598.70\",\"0.002\"],[\"79599.20\",\"0.005\"],[\"79600.90\",\"0.002\"],[\"79603.00\",\"0.003\"],[\"79603.10\",\"0.226\"],[\"79603.20\",\"0.003\"],[\"79605.10\",\"0.026\"],[\"79605.60\",\"0.026\"],[\"79605.90\",\"0.000\"],[\"79606.10\",\"0.001\"],[\"79606.40\",\"0.002\"],[\"79606.90\",\"0.199\"],[\"79607.10\",\"5.078\"]],\"a\":[[\"79607.20\",\"7.036\"],[\"79609.40\",\"0.015\"],[\"79609.50\",\"0.005\"],[\"79609.80\",\"0.090\"],[\"79610.70\",\"0.006\"],[\"79615.30\",\"0.001\"],[\"79616.20\",\"0.521\"],[\"79618.00\",\"0.047\"],[\"79618.10\",\"0.376\"],[\"79618.30\",\"0.005\"],[\"79623.50\",\"0.453\"],[\"79625.50\",\"0.006\"],[\"79697.90\",\"4.057\"],[\"79702.80\",\"0.008\"],[\"79828.60\",\"0.351\"],[\"79828.70\",\"7.979\"],[\"79968.00\",\"0.867\"],[\"79969.40\",\"1.411\"],[\"79997.80\",\"0.525\"],[\"80240.40\",\"0.250\"],[\"80403.30\",\"22.314\"],[\"80558.80\",\"6.822\"],[\"81190.20\",\"2.951\"],[\"87568.00\",\"0.000\"]],\"st\":1}}"}
{"receive_ns":1788563391603676000,"stream":"btcusdt@bookTicker","event_type":"bookTicker","event_time_ms":1788563391641,"raw_json":"{\"stream\":\"btcusdt@bookTicker\",\"data\":{\"e\":\"bookTicker\",\"u\":11478233224387,\"s\":\"BTCUSDT\",\"ps\":\"BTCUSDT\",\"b\":\"79607.10\",\"B\":\"5.063\",\"a\":\"79607.20\",\"A\":\"7.036\",\"T\":1788563391641,\"E\":1788563391641,\"st\":1}}"}
{"receive_ns":1788563391608339000,"stream":"btcusdt@bookTicker","event_type":"bookTicker","event_time_ms":1788563391646,"raw_json":"{\"stream\":\"btcusdt@bookTicker\",\"data\":{\"e\":\"bookTicker\",\"u\":11478233224600,\"s\":\"BTCUSDT\",\"ps\":\"BTCUSDT\",\"b\":\"79607.10\",\"B\":\"5.078\",\"a\":\"79607.20\",\"A\":\"7.036\",\"T\":1788563391645,\"E\":1788563391646,\"st\":1}}"}
{"receive_ns":1788563391608628000,"stream":"btcusdt@bookTicker","event_type":"bookTicker","event_time_ms":1788563391647,"raw_json":"{\"stream\":\"btcusdt@bookTicker\",\"data\":{\"e\":\"bookTicker\",\"u\":11478233224648,\"s\":\"BTCUSDT\",\"ps\":\"BTCUSDT\",\"b\":\"79607.10\",\"B\":\"5.076\",\"a\":\"79607.20\",\"A\":\"7.036\",\"T\":1788563391646,\"E\":1788563391647,\"st\":1}}"}
{"receive_ns":1788563391614824000,"stream":"btcusdt@depth@100ms","event_type":"depthUpdate","event_time_ms":1788563391653,"raw_json":"{\"stream\":\"btcusdt@depth@100ms\",\"data\":{\"e\":\"depthUpdate\",\"E\":1788563391653,\"T\":1788563391651,\"s\":\"BTCUSDT\",\"ps\":\"BTCUSDT\",\"U\":11478233221158,\"u\":11478233224785,\"pu\":11478233221123,\"b\":[[\"1000.00\",\"24.754\"],[\"29107.10\",\"1.281\"],[\"29207.10\",\"0.819\"],[\"63685.70\",\"0.001\"],[\"71646.30\",\"0.002\"],[\"76422.80\",\"0.002\"],[\"78492.60\",\"52.710\"],[\"78608.50\",\"10.909\"],[\"78811.00\",\"14.704\"],[\"79573.90\",\"0.002\"],[\"79574.90\",\"0.474\"],[\"79576.10\",\"0.535\"],[\"79583.40\",\"0.004\"],[\"79593.20\",\"0.000\"],[\"79603.80\",\"0.029\"],[\"79604.00\",\"0.029\"],[\"79604.10\",\"1.026\"],[\"79605.10\",\"0.000\"],[\"79605.20\",\"0.002\"],[\"79605.50\",\"0.002\"],[\"79607.10\",\"5.076\"]],\"a\":[[\"79609.90\",\"0.002\"],[\"79615.30\",\"0.001\"],[\"79616.20\",\"0.082\"],[\"79618.00\",\"0.109\"],[\"79618.10\",\"0.314\"],[\"79618.30\",\"0.444\"],[\"79623.30\",\"0.456\"],[\"79623.50\",\"0.001\"],[\"79624.60\",\"0.030\"],[\"79625.50\",\"0.458\"],[\"80403.30\",\"22.314\"],[\"80562.50\",\"50.335\"],[\"81199.30\",\"10.787\"]],\"st\":1}}"}
{"receive_ns":1788563391715895000,"stream":"btcusdt@depth@100ms","event_type":"depthUpdate","event_time_ms":1788563391755,"raw_json":"{\"stream\":\"btcusdt@depth@100ms\",\"data\":{\"e\":\"depthUpdate\",\"E\":1788563391755,\"T\":1788563391754,\"s\":\"BTCUSDT\",\"ps\":\"BTCUSDT\",\"U\":11478233224870,\"u\":11478233227624,\"pu\":11478233224785,\"b\":[[\"29107.10\",\"1.463\"],[\"29207.10\",\"0.637\"],[\"71646.30\",\"0.002\"],[\"76422.80\",\"0.000\"],[\"77616.90\",\"1.481\"],[\"78118.40\",\"5.938\"],[\"78811.00\",\"14.704\"],[\"79209.10\",\"4.608\"],[\"79232.90\",\"0.000\"],[\"79491.70\",\"0.000\"],[\"79535.50\",\"0.000\"],[\"79583.20\",\"0.002\"],[\"79583.40\",\"0.006\"],[\"79589.20\",\"0.195\"],[\"79604.40\",\"0.026\"],[\"79604.60\",\"0.026\"]],\"a\":[[\"79623.30\",\"0.458\"],[\"79968.00\",\"0.104\"],[\"79969.40\",\"0.001\"],[\"79997.80\",\"0.000\"],[\"80320.20\",\"0.000\"],[\"80403.30\",\"22.314\"],[\"80642.20\",\"1.738\"],[\"80678.00\",\"4.250\"]],\"st\":1}}"}
{"receive_ns":1788563391760770000,"stream":"btcusdt@bookTicker","event_type":"bookTicker","event_time_ms":1788563391795,"raw_json":"{\"stream\":\"btcusdt@bookTicker\",\"data\":{\"e\":\"bookTicker\",\"u\":11478233228925,\"s\":\"BTCUSDT\",\"ps\":\"BTCUSDT\",\"b\":\"79607.10\",\"B\":\"5.083\",\"a\":\"79607.20\",\"A\":\"7.036\",\"T\":1788563391795,\"E\":1788563391795,\"st\":1}}"}
{"receive_ns":1788563391826329000,"stream":"btcusdt@depth@100ms","event_type":"depthUpdate","event_time_ms":1788563391857,"raw_json":"{\"stream\":\"btcusdt@depth@100ms\",\"data\":{\"e\":\"depthUpdate\",\"E\":1788563391857,\"T\":1788563391855,\"s\":\"BTCUSDT\",\"ps\":\"BTCUSDT\",\"U\":11478233227681,\"u\":11478233230943,\"pu\":11478233227624,\"b\":[[\"1000.00\",\"24.754\"],[\"29107.10\",\"1.638\"],[\"29207.10\",\"0.462\"],[\"71646.30\",\"0.002\"],[\"76422.80\",\"0.002\"],[\"78253.80\",\"7.525\"],[\"78811.00\",\"14.704\"],[\"79232.90\",\"0.141\"],[\"79443.80\",\"0.816\"],[\"79483.20\",\"0.000\"],[\"79523.30\",\"0.126\"],[\"79524.10\",\"1.196\"],[\"79583.20\",\"0.234\"],[\"79589.20\",\"1.323\"],[\"79589.80\",\"0.010\"],[\"79593.30\",\"0.077\"],[\"79595.70\",\"0.001\"],[\"79603.30\",\"0.600\"],[\"79604.70\",\"0.027\"],[\"79607.10\",\"5.083\"]],\"a\":[[\"79630.60\",\"1.884\"],[\"79728.80\",\"0.000\"],[\"79768.20\",\"0.000\"],[\"79968.00\",\"0.867\"],[\"79969.40\",\"1.367\"],[\"79995.30\",\"0.046\"],[\"79997.80\",\"0.525\"],[\"80244.10\",\"8.370\"],[\"80403.30\",\"22.314\"],[\"80562.50\",\"51.821\"],[\"80602.30\",\"12.394\"],[\"81199.30\",\"12.509\"]],\"st\":1}}"}
{"receive_ns":1788563391829566000,"stream":"btcusdt@bookTicker","event_type":"bookTicker","event_time_ms":1788563391866,"raw_json":"{\"stream\":\"btcusdt@bookTicker\",\"data\":{\"e\":\"bookTicker\",\"u\":11478233231411,\"s\":\"BTCUSDT\",\"ps\":\"BTCUSDT\",\"b\":\"79607.10\",\"B\":\"4.527\",\"a\":\"79607.20\",\"A\":\"7.036\",\"T\":1788563391866,\"E\":1788563391866,\"st\":1}}"}
{"receive_ns":1788563391829814000,"stream":"btcusdt@bookTicker","event_type":"bookTicker","event_time_ms":1788563391867,"raw_json":"{\"stream\":\"btcusdt@bookTicker\",\"data\":{\"e\":\"bookTicker\",\"u\":11478233231479,\"s\":\"BTCUSDT\",\"ps\":\"BTCUSDT\",\"b\":\"79607.10\",\"B\":\"4.529\",\"a\":\"79607.20\",\"A\":\"7.036\",\"T\":1788563391867,\"E\":1788563391867,\"st\":1}}"}
{"receive_ns":1788563391830928000,"stream":"btcusdt@bookTicker","event_type":"bookTicker","event_time_ms":1788563391871,"raw_json":"{\"stream\":\"btcusdt@bookTicker\",\"data\":{\"e\":\"bookTicker\",\"u\":11478233231750,\"s\":\"BTCUSDT\",\"ps\":\"BTCUSDT\",\"b\":\"79607.10\",\"B\":\"5.086\",\"a\":\"79607.20\",\"A\":\"7.036\",\"T\":1788563391871,\"E\":1788563391871,\"st\":1}}"}
{"receive_ns":1788563391832203000,"stream":"btcusdt@bookTicker","event_type":"bookTicker","event_time_ms":1788563391872,"raw_json":"{\"stream\":\"btcusdt@bookTicker\",\"data\":{\"e\":\"bookTicker\",\"u\":11478233231900,\"s\":\"BTCUSDT\",\"ps\":\"BTCUSDT\",\"b\":\"79607.10\",\"B\":\"5.084\",\"a\":\"79607.20\",\"A\":\"7.036\",\"T\":1788563391872,\"E\":1788563391872,\"st\":1}}"}
{"receive_ns":1788563391920053000,"stream":"btcusdt@depth@100ms","event_type":"depthUpdate","event_time_ms":1788563391959,"raw_json":"{\"stream\":\"btcusdt@depth@100ms\",\"data\":{\"e\":\"depthUpdate\",\"E\":1788563391959,\"T\":1788563391957,\"s\":\"BTCUSDT\",\"ps\":\"BTCUSDT\",\"U\":11478233231011,\"u\":11478233235399,\"pu\":11478233230943,\"b\":[[\"1000.00\",\"24.754\"],[\"29107.10\",\"1.778\"],[\"29207.10\",\"0.301\"],[\"29507.10\",\"0.021\"],[\"71646.30\",\"0.002\"],[\"78476.70\",\"1.990\"],[\"78691.60\",\"10.766\"],[\"78811.00\",\"14.704\"],[\"78887.10\",\"17.659\"],[\"79396.10\",\"0.010\"],[\"79580.80\",\"0.007\"],[\"79583.20\",\"0.002\"],[\"79584.30\",\"0.000\"],[\"79587.10\",\"0.019\"],[\"79597.80\",\"0.001\"],[\"79599.20\",\"0.005\"],[\"79600.90\",\"0.002\"],[\"79605.60\",\"0.027\"],[\"79606.90\",\"0.198\"],[\"79607.10\",\"5.084\"]],\"a\":[[\"79615.30\",\"0.001\"],[\"79618.00\",\"0.422\"],[\"79618.10\",\"0.001\"],[\"79815.90\",\"0.012\"],[\"80244.10\",\"8.619\"],[\"80403.30\",\"22.314\"]],\"st\":1}}"}
{"receive_ns":1788563391992434000,"stream":"btcusdt@bookTicker","event_type":"bookTicker","event_time_ms":1788563392030,"raw_json":"{\"stream\":\"btcusdt@bookTicker\",\"data\":{\"e\":\"bookTicker\",\"u\":11478233238432,\"s\":\"BTCUSDT\",\"ps\":\"BTCUSDT\",\"b\":\"79607.10\",\"B\":\"5.122\",\"a\":\"79607.20\",\"A\":\"7.036\",\"T\":1788563392030,\"E\":1788563392030,\"st\":1}}"}
{"receive_ns":1788563391992746000,"stream":"btcusdt@bookTicker","event_type":"bookTicker","event_time_ms":1788563392032,"raw_json":"{\"stream\":\"btcusdt@bookTicker\",\"data\":{\"e\":\"bookTicker\",\"u\":11478233238514,\"s\":\"BTCUSDT\",\"ps\":\"BTCUSDT\",\"b\":\"79607.10\",\"B\":\"5.124\",\"a\":\"79607.20\",\"A\":\"7.036\",\"T\":1788563392032,\"E\":1788563392032,\"st\":1}}"}
{"receive_ns":1788563392021964000,"stream":"btcusdt@depth@100ms","event_type":"depthUpdate","event_time_ms":1788563392061,"raw_json":"{\"stream\":\"btcusdt@depth@100ms\",\"data\":{\"e\":\"depthUpdate\",\"E\":1788563392061,\"T\":1788563392057,\"s\":\"BTCUSDT\",\"ps\":\"BTCUSDT\",\"U\":11478233235687,\"u\":11478233239396,\"pu\":11478233235399,\"b\":[[\"29107.10\",\"1.827\"],[\"29207.10\",\"0.189\"],[\"29507.10\",\"0.084\"],[\"71646.30\",\"0.002\"],[\"76422.80\",\"0.000\"],[\"78015.00\",\"10.691\"],[\"78811.00\",\"14.704\"],[\"78966.70\",\"0.253\"],[\"79209.10\",\"4.608\"],[\"79232.90\",\"0.141\"],[\"79396.10\",\"5.020\"],[\"79443.90\",\"2.405\"],[\"79483.30\",\"0.501\"],[\"79491.70\",\"0.232\"],[\"79523.10\",\"0.125\"],[\"79523.30\",\"0.001\"],[\"79583.20\",\"0.353\"],[\"79588.30\",\"0.004\"],[\"79589.20\",\"0.972\"],[\"79589.60\",\"0.028\"],[\"79589.80\",\"0.006\"],[\"79591.30\",\"0.000\"],[\"79592.80\",\"0.004\"],[\"79603.50\",\"0.003\"],[\"79605.20\",\"0.028\"],[\"79606.10\",\"0.000\"],[\"79607.10\",\"5.124\"]],\"a\":[[\"79668.90\",\"25.244\"],[\"79671.50\",\"0.002\"],[\"79728.80\",\"0.276\"],[\"79768.20\",\"1.230\"],[\"79815.90\",\"3.087\"],[\"79968.00\",\"0.867\"],[\"79969.40\",\"1.367\"],[\"79995.30\",\"0.046\"],[\"79997.80\",\"0.525\"],[\"80403.30\",\"22.314\"]],\"st\":1}}"}
{"receive_ns":1788563392047400000,"stream":"btcusdt@bookTicker","event_type":"bookTicker","event_time_ms":1788563392085,"raw_json":"{\"stream\":\"btcusdt@bookTicker\",\"data\":{\"e\":\"bookTicker\",\"u\":11478233240693,\"s\":\"BTCUSDT\",\"ps\":\"BTCUSDT\",\"b\":\"79607.10\",\"B\":\"5.128\",\"a\":\"79607.20\",\"A\":\"7.036\",\"T\":1788563392085,\"E\":1788563392085,\"st\":1}}"}
{"receive_ns":1788563392047666000,"stream":"btcusdt@bookTicker","event_type":"bookTicker","event_time_ms":1788563392087,"raw_json":"{\"stream\":\"btcusdt@bookTicker\",\"data\":{\"e\":\"bookTicker\",\"u\":11478233240774,\"s\":\"BTCUSDT\",\"ps\":\"BTCUSDT\",\"b\":\"79607.10\",\"B\":\"5.129\",\"a\":\"79607.20\",\"A\":\"7.036\",\"T\":1788563392087,\"E\":1788563392087,\"st\":1}}"}
{"receive_ns":1788563392092627000,"stream":"btcusdt@bookTicker","event_type":"bookTicker","event_time_ms":1788563392132,"raw_json":"{\"stream\":\"btcusdt@bookTicker\",\"data\":{\"e\":\"bookTicker\",\"u\":11478233242381,\"s\":\"BTCUSDT\",\"ps\":\"BTCUSDT\",\"b\":\"79607.10\",\"B\":\"4.642\",\"a\":\"79607.20\",\"A\":\"7.036\",\"T\":1788563392132,\"E\":1788563392132,\"st\":1}}"}
{"receive_ns":1788563392092970000,"stream":"btcusdt@bookTicker","event_type":"bookTicker","event_time_ms":1788563392133,"raw_json":"{\"stream\":\"btcusdt@bookTicker\",\"data\":{\"e\":\"bookTicker\",\"u\":11478233242437,\"s\":\"BTCUSDT\",\"ps\":\"BTCUSDT\",\"b\":\"79607.10\",\"B\":\"4.641\",\"a\":\"79607.20\",\"A\":\"7.036\",\"T\":1788563392133,\"E\":1788563392133,\"st\":1}}"}
{"receive_ns":1788563392108097000,"stream":"btcusdt@bookTicker","event_type":"bookTicker","event_time_ms":1788563392136,"raw_json":"{\"stream\":\"btcusdt@bookTicker\",\"data\":{\"e\":\"bookTicker\",\"u\":11478233242544,\"s\":\"BTCUSDT\",\"ps\":\"BTCUSDT\",\"b\":\"79607.10\",\"B\":\"5.137\",\"a\":\"79607.20\",\"A\":\"7.036\",\"T\":1788563392136,\"E\":1788563392136,\"st\":1}}"}
{"receive_ns":1788563392108447000,"stream":"btcusdt@bookTicker","event_type":"bookTicker","event_time_ms":1788563392137,"raw_json":"{\"stream\":\"btcusdt@bookTicker\",\"data\":{\"e\":\"bookTicker\",\"u\":11478233242587,\"s\":\"BTCUSDT\",\"ps\":\"BTCUSDT\",\"b\":\"79607.10\",\"B\":\"5.135\",\"a\":\"79607.20\",\"A\":\"7.036\",\"T\":1788563392137,\"E\":1788563392137,\"st\":1}}"}
{"receive_ns":1788563392124310000,"stream":"btcusdt@depth@100ms","event_type":"depthUpdate","event_time_ms":1788563392163,"raw_json":"{\"stream\":\"btcusdt@depth@100ms\",\"data\":{\"e\":\"depthUpdate\",\"E\":1788563392163,\"T\":1788563392162,\"s\":\"BTCUSDT\",\"ps\":\"BTCUSDT\",\"U\":11478233239621,\"u\":11478233243576,\"pu\":11478233239396,\"b\":[[\"1000.00\",\"24.754\"],[\"29107.10\",\"1.897\"],[\"29207.10\",\"0.063\"],[\"29507.10\",\"0.140\"],[\"71646.30\",\"0.002\"],[\"76422.80\",\"0.002\"],[\"78489.10\",\"18.292\"],[\"78532.40\",\"11.926\"],[\"78612.00\",\"15.484\"],[\"78811.00\",\"14.704\"],[\"79557.00\",\"0.004\"],[\"79583.20\",\"0.002\"],[\"79599.20\",\"0.005\"],[\"79603.70\",\"0.011\"],[\"79605.20\",\"0.002\"],[\"79605.40\",\"0.027\"],[\"79605.60\",\"0.026\"],[\"79605.90\",\"0.026\"],[\"79606.90\",\"0.197\"],[\"79607.10\",\"5.135\"]],\"a\":[[\"79609.40\",\"0.267\"],[\"79615.30\",\"0.001\"],[\"79616.00\",\"0.020\"],[\"79618.00\",\"0.047\"],[\"79618.30\",\"0.819\"],[\"79668.10\",\"1.857\"],[\"79668.90\",\"0.000\"],[\"79676.80\",\"4.811\"],[\"79676.90\",\"25.423\"],[\"80403.30\",\"22.314\"],[\"83587.50\",\"0.033\"]],\"st\":1}}"}
{"receive_ns":1788563392218139000,"stream":"btcusdt@bookTicker","event_type":"bookTicker","event_time_ms":1788563392257,"raw_json":"{\"stream\":\"btcusdt@bookTicker\",\"data\":{\"e\":\"bookTicker\",\"u\":11478233246982,\"s\":\"BTCUSDT\",\"ps\":\"BTCUSDT\",\"b\":\"79607.10\",\"B\":\"5.120\",\"a\":\"79607.20\",\"A\":\"7.036\",\"T\":1788563392257,\"E\":1788563392257,\"st\":1}}"}
{"receive_ns":1788563392218367000,"stream":"btcusdt@bookTicker","event_type":"bookTicker","event_time_ms":1788563392258,"raw_json":"{\"stream\":\"btcusdt@bookTicker\",\"data\":{\"e\":\"bookTicker\",\"u\":11478233247042,\"s\":\"BTCUSDT\",\"ps\":\"BTCUSDT\",\"b\":\"79607.10\",\"B\":\"5.121\",\"a\":\"79607.20\",\"A\":\"7.036\",\"T\":1788563392258,\"E\":1788563392258,\"st\":1}}"}
{"receive_ns":1788563392219237000,"stream":"btcusdt@bookTicker","event_type":"bookTicker","event_time_ms":1788563392260,"raw_json":"{\"stream\":\"btcusdt@bookTicker\",\"data\":{\"e\":\"bookTicker\",\"u\":11478233247123,\"s\":\"BTCUSDT\",\"ps\":\"BTCUSDT\",\"b\":\"79607.10\",\"B\":\"5.136\",\"a\":\"79607.20\",\"A\":\"7.036\",\"T\":1788563392260,\"E\":1788563392260,\"st\":1}}"}
{"receive_ns":1788563392221974000,"stream":"btcusdt@bookTicker","event_type":"bookTicker","event_time_ms":1788563392261,"raw_json":"{\"stream\":\"btcusdt@bookTicker\",\"data\":{\"e\":\"bookTicker\",\"u\":11478233247169,\"s\":\"BTCUSDT\",\"ps\":\"BTCUSDT\",\"b\":\"79607.10\",\"B\":\"5.138\",\"a\":\"79607.20\",\"A\":\"7.036\",\"T\":1788563392261,\"E\":1788563392261,\"st\":1}}"}
{"receive_ns":1788563392225624000,"stream":"btcusdt@depth@100ms","event_type":"depthUpdate","event_time_ms":1788563392265,"raw_json":"{\"stream\":\"btcusdt@depth@100ms\",\"data\":{\"e\":\"depthUpdate\",\"E\":1788563392265,\"T\":1788563392264,\"s\":\"BTCUSDT\",\"ps\":\"BTCUSDT\",\"U\":11478233243605,\"u\":11478233247296,\"pu\":11478233243576,\"b\":[[\"1000.00\",\"24.754\"],[\"29107.10\",\"1.848\"],[\"29207.10\",\"0.000\"],[\"29507.10\",\"0.252\"],[\"71646.30\",\"0.002\"],[\"71684.00\",\"0.003\"],[\"75626.70\",\"0.021\"],[\"76422.80\",\"0.000\"],[\"78015.00\",\"10.694\"],[\"78811.00\",\"14.704\"],[\"79232.90\",\"0.141\"],[\"79491.70\",\"0.232\"],[\"79535.40\",\"0.002\"],[\"79583.20\",\"0.353\"],[\"79589.20\",\"0.972\"],[\"79589.80\",\"0.006\"],[\"79593.30\",\"0.001\"],[\"79593.40\",\"0.078\"],[\"79597.80\",\"0.003\"],[\"79599.20\",\"0.003\"],[\"79603.60\",\"1.545\"],[\"79603.70\",\"0.037\"],[\"79604.60\",\"0.000\"],[\"79604.70\",\"0.001\"],[\"79604.80\",\"0.002\"],[\"79604.90\",\"0.000\"],[\"79605.20\",\"0.002\"],[\"79605.30\",\"0.026\"],[\"79605.40\",\"0.001\"],[\"79605.90\",\"0.000\"],[\"79607.10\",\"5.138\"]],\"a\":[[\"79615.10\",\"0.004\"],[\"79618.30\",\"0.815\"],[\"79668.20\",\"2.948\"],[\"79671.50\",\"25.219\"],[\"79676.80\",\"0.076\"],[\"79676.90\",\"0.206\"],[\"79702.80\",\"0.010\"],[\"79707.60\",\"8.783\"],[\"79968.00\",\"0.867\"],[\"79969.40\",\"1.168\"],[\"79995.30\",\"0.046\"],[\"79997.80\",\"0.525\"],[\"80005.30\",\"0.001\"],[\"80403.30\",\"22.314\"]],\"st\":1}}"}
{"receive_ns":1788563392328687000,"stream":"btcusdt@depth@100ms","event_type":"depthUpdate","event_time_ms":1788563392367,"raw_json":"{\"stream\":\"btcusdt@depth@100ms\",\"data\":{\"e\":\"depthUpdate\",\"E\":1788563392367,\"T\":1788563392365,\"s\":\"BTCUSDT\",\"ps\":\"BTCUSDT\",\"U\":11478233247354,\"u\":11478233252097,\"pu\":11478233247296,\"b\":[[\"29107.10\",\"1.666\"],[\"29507.10\",\"0.434\"],[\"63686.00\",\"0.000\"],[\"71646.30\",\"0.002\"],[\"71684.00\",\"0.000\"],[\"75626.80\",\"0.002\"],[\"76422.80\",\"0.002\"],[\"76422.90\",\"0.000\"],[\"78612.00\",\"15.700\"],[\"78651.80\",\"50.761\"],[\"78811.00\",\"15.338\"],[\"78970.20\",\"9.011\"],[\"79209.00\",\"0.002\"],[\"79209.10\",\"4.608\"],[\"79573.80\",\"0.525\"],[\"79574.90\",\"0.022\"],[\"79603.60\",\"1.519\"],[\"79605.40\",\"0.027\"],[\"79605.90\",\"0.026\"]],\"a\":[[\"79615.10\",\"0.000\"],[\"79616.00\",\"0.459\"],[\"79618.10\",\"0.005\"],[\"79618.30\",\"0.376\"],[\"79623.50\",\"0.453\"],[\"79625.50\",\"0.006\"],[\"79828.70\",\"8.000\"],[\"79969.40\",\"1.367\"],[\"80403.30\",\"22.314\"],[\"80598.60\",\"12.358\"],[\"80638.60\",\"3.902\"],[\"80718.10\",\"25.798\"],[\"83587.50\",\"0.037\"]],\"st\":1}}"}
{"receive_ns":1788563392328980000,"stream":"btcusdt@bookTicker","event_type":"bookTicker","event_time_ms":1788563392367,"raw_json":"{\"stream\":\"btcusdt@bookTicker\",\"data\":{\"e\":\"bookTicker\",\"u\":11478233252124,\"s\":\"BTCUSDT\",\"ps\":\"BTCUSDT\",\"b\":\"79607.10\",\"B\":\"5.100\",\"a\":\"79607.20\",\"A\":\"7.036\",\"T\":1788563392366,\"E\":1788563392367,\"st\":1}}"}
{"receive_ns":1788563392330039000,"stream":"btcusdt@bookTicker","event_type":"bookTicker","event_time_ms":1788563392369,"raw_json":"{\"stream\":\"btcusdt@bookTicker\",\"data\":{\"e\":\"bookTicker\",\"u\":11478233252252,\"s\":\"BTCUSDT\",\"ps\":\"BTCUSDT\",\"b\":\"79607.10\",\"B\":\"5.100\",\"a\":\"79607.20\",\"A\":\"7.053\",\"T\":1788563392369,\"E\":1788563392369,\"st\":1}}"}
{"receive_ns":1788563392435308000,"stream":"btcusdt@depth@100ms","event_type":"depthUpdate","event_time_ms":1788563392469,"raw_json":"{\"stream\":\"btcusdt@depth@100ms\",\"data\":{\"e\":\"depthUpdate\",\"E\":1788563392469,\"T\":1788563392465,\"s\":\"BTCUSDT\",\"ps\":\"BTCUSDT\",\"U\":11478233252124,\"u\":11478233256275,\"pu\":11478233252097,\"b\":[[\"1000.00\",\"24.754\"],[\"29107.10\",\"1.491\"],[\"29507.10\",\"0.609\"],[\"71646.30\",\"0.002\"],[\"78373.20\",\"10.653\"],[\"78452.80\",\"41.237\"],[\"78608.50\",\"10.624\"],[\"78811.00\",\"15.338\"],[\"79232.90\",\"0.000\"],[\"79491.70\",\"0.000\"],[\"79511.50\",\"0.024\"],[\"79523.10\",\"0.000\"],[\"79523.30\",\"0.126\"],[\"79535.40\",\"0.000\"],[\"79576.00\",\"0.021\"],[\"79583.20\",\"0.002\"],[\"79589.20\",\"0.195\"],[\"79594.80\",\"0.078\"],[\"79605.90\",\"0.000\"],[\"79607.10\",\"5.100\"]],\"a\":[[\"79607.20\",\"7.053\"],[\"79608.00\",\"0.433\"],[\"79615.30\",\"0.001\"],[\"79616.00\",\"0.020\"],[\"79618.10\",\"0.005\"],[\"79618.30\",\"0.815\"],[\"79623.50\",\"0.001\"],[\"79624.50\",\"0.931\"],[\"79668.90\",\"25.217\"],[\"79671.50\",\"0.002\"],[\"79678.90\",\"0.015\"],[\"79702.80\",\"0.008\"],[\"79968.00\",\"0.104\"],[\"79969.40\",\"0.001\"],[\"79995.30\",\"0.002\"],[\"79997.80\",\"0.000\"],[\"80403.30\",\"22.314\"],[\"87568.00\",\"0.000\"]],\"st\":1}}"}
{"receive_ns":1788563392442520000,"stream":"btcusdt@bookTicker","event_type":"bookTicker","event_time_ms":1788563392480,"raw_json":"{\"stream\":\"btcusdt@bookTicker\",\"data\":{\"e\":\"bookTicker\",\"u\":11478233256941,\"s\":\"BTCUSDT\",\"ps\":\"BTCUSDT\",\"b\":\"79607.10\",\"B\":\"5.100\",\"a\":\"79607.20\",\"A\":\"7.044\",\"T\":1788563392480,\"E\":1788563392480,\"st\":1}}"}
{"receive_ns":1788563392442707000,"stream":"btcusdt@bookTicker","event_type":"bookTicker","event_time_ms":1788563392480,"raw_json":"{\"stream\":\"btcusdt@bookTicker\",\"data\":{\"e\":\"bookTicker\",\"u\":11478233256947,\"s\":\"BTCUSDT\",\"ps\":\"BTCUSDT\",\"b\":\"79607.10\",\"B\":\"5.100\",\"a\":\"79607.20\",\"A\":\"7.043\",\"T\":1788563392480,\"E\":1788563392480,\"st\":1}}"}
{"receive_ns":1788563392444471000,"stream":"btcusdt@bookTicker","event_type":"bookTicker","event_time_ms":1788563392481,"raw_json":"{\"stream\":\"btcusdt@bookTicker\",\"data\":{\"e\":\"bookTicker\",\"u\":11478233257022,\"s\":\"BTCUSDT\",\"ps\":\"BTCUSDT\",\"b\":\"79607.10\",\"B\":\"5.100\",\"a\":\"79607.20\",\"A\":\"6.602\",\"T\":1788563392481,\"E\":1788563392481,\"st\":1}}"}
{"receive_ns":1788563392532408000,"stream":"btcusdt@depth@100ms","event_type":"depthUpdate","event_time_ms":1788563392571,"raw_json":"{\"stream\":\"btcusdt@depth@100ms\",\"data\":{\"e\":\"depthUpdate\",\"E\":1788563392571,\"T\":1788563392569,\"s\":\"BTCUSDT\",\"ps\":\"BTCUSDT\",\"U\":11478233256392,\"u\":11478233261221,\"pu\":11478233256275,\"b\":[[\"1000.00\",\"24.754\"],[\"29107.10\",\"1.309\"],[\"29507.10\",\"0.791\"],[\"71646.30\",\"0.002\"],[\"76422.80\",\"0.000\"],[\"78015.00\",\"10.691\"],[\"78427.10\",\"1.972\"],[\"78651.80\",\"51.396\"],[\"78811.00\",\"15.338\"],[\"78890.60\",\"43.515\"],[\"79232.90\",\"0.141\"],[\"79491.70\",\"0.232\"],[\"79583.20\",\"0.353\"],[\"79583.80\",\"0.001\"],[\"79589.20\",\"0.972\"],[\"79589.80\",\"0.006\"],[\"79590.80\",\"0.020\"],[\"79605.50\",\"0.028\"]],\"a\":[[\"79607.20\",\"6.602\"],[\"79609.40\",\"0.015\"],[\"79615.30\",\"0.005\"],[\"79618.10\",\"0.001\"],[\"79620.40\",\"0.627\"],[\"79630.20\",\"0.235\"],[\"79968.00\",\"0.867\"],[\"79969.40\",\"1.367\"],[\"79995.30\",\"0.046\"],[\"79997.80\",\"0.525\"],[\"80403.30\",\"22.314\"],[\"80960.50\",\"12.580\"]],\"st\":1}}"}
{"receive_ns":1788563392587153000,"stream":"btcusdt@bookTicker","event_type":"bookTicker","event_time_ms":1788563392614,"raw_json":"{\"stream\":\"btcusdt@bookTicker\",\"data\":{\"e\":\"bookTicker\",\"u\":11478233263688,\"s\":\"BTCUSDT\",\"ps\":\"BTCUSDT\",\"b\":\"79607.10\",\"B\":\"5.099\",\"a\":\"79607.20\",\"A\":\"6.602\",\"T\":1788563392614,\"E\":1788563392614,\"st\":1}}"}
{"receive_ns":1788563392605349000,"stream":"btcusdt@bookTicker","event_type":"bookTicker","event_time_ms":1788563392643,"raw_json":"{\"stream\":\"btcusdt@bookTicker\",\"data\":{\"e\":\"bookTicker\",\"u\":11478233265096,\"s\":\"BTCUSDT\",\"ps\":\"BTCUSDT\",\"b\":\"79607.10\",\"B\":\"5.099\",\"a\":\"79607.20\",\"A\":\"6.601\",\"T\":1788563392643,\"E\":1788563392643,\"st\":1}}"}
{"receive_ns":1788563392605523000,"stream":"btcusdt@trade","event_type":"trade","event_time_ms":1788563392643,"raw_json":"{\"stream\":\"btcusdt@trade\",\"data\":{\"e\":\"trade\",\"E\":1788563392643,\"T\":1788563392643,\"s\":\"BTCUSDT\",\"t\":8054083501,\"p\":\"79607.20\",\"q\":\"0.001\",\"X\":\"MARKET\",\"m\":false,\"st\":1}}"}
{"receive_ns":1788563392605705000,"stream":"btcusdt@bookTicker","event_type":"bookTicker","event_time_ms":1788563392645,"raw_json":"{\"stream\":\"btcusdt@bookTicker\",\"data\":{\"e\":\"bookTicker\",\"u\":11478233265210,\"s\":\"BTCUSDT\",\"ps\":\"BTCUSDT\",\"b\":\"79607.10\",\"B\":\"5.100\",\"a\":\"79607.20\",\"A\":\"6.601\",\"T\":1788563392645,\"E\":1788563392645,\"st\":1}}"}
{"receive_ns":1788563392634838000,"stream":"btcusdt@depth@100ms","event_type":"depthUpdate","event_time_ms":1788563392673,"raw_json":"{\"stream\":\"btcusdt@depth@100ms\",\"data\":{\"e\":\"depthUpdate\",\"E\":1788563392673,\"T\":1788563392670,\"s\":\"BTCUSDT\",\"ps\":\"BTCUSDT\",\"U\":11478233261306,\"u\":11478233266452,\"pu\":11478233261221,\"b\":[[\"29107.10\",\"1.134\"],[\"29507.10\",\"0.966\"],[\"63685.70\",\"0.001\"],[\"63686.00\",\"0.000\"],[\"71646.30\",\"0.002\"],[\"75626.70\",\"0.023\"],[\"76422.80\",\"0.002\"],[\"78404.10\",\"3.822\"],[\"78648.30\",\"20.189\"],[\"78811.00\",\"15.338\"],[\"79209.10\",\"4.608\"],[\"79483.30\",\"0.520\"],[\"79533.60\",\"0.830\"],[\"79549.50\",\"0.728\"],[\"79583.40\",\"0.004\"],[\"79590.30\",\"0.112\"],[\"79590.80\",\"0.003\"],[\"79591.10\",\"0.020\"],[\"79606.90\",\"0.199\"],[\"79607.00\",\"1.485\"],[\"79607.10\",\"5.100\"]],\"a\":[[\"79607.20\",\"6.601\"],[\"79616.20\",\"0.082\"],[\"79618.30\",\"0.815\"],[\"79623.30\",\"0.456\"],[\"79668.90\",\"0.000\"],[\"79671.50\",\"25.163\"],[\"79676.90\",\"0.206\"],[\"79728.80\",\"0.294\"],[\"79841.70\",\"0.013\"],[\"79841.80\",\"0.022\"],[\"80403.30\",\"22.314\"],[\"80479.40\",\"0.002\"],[\"80562.50\",\"52.316\"],[\"80598.60\",\"12.209\"],[\"81031.00\",\"5.397\"],[\"81199.30\",\"12.512\"],[\"87567.90\",\"0.002\"]],\"st\":1}}"}
{"receive_ns":1788563392745537000,"stream":"btcusdt@depth@100ms","event_type":"depthUpdate","event_time_ms":1788563392775,"raw_json":"{\"stream\":\"btcusdt@depth@100ms\",\"data\":{\"e\":\"depthUpdate\",\"E\":1788563392775,\"T\":1788563392772,\"s\":\"BTCUSDT\",\"ps\":\"BTCUSDT\",\"U\":11478233266609,\"u\":11478233270498,\"pu\":11478233266452,\"b\":[[\"1000.00\",\"24.754\"],[\"29107.10\",\"0.959\"],[\"29507.10\",\"1.141\"],[\"63686.00\",\"0.000\"],[\"71646.30\",\"0.002\"],[\"76422.80\",\"0.000\"],[\"78811.00\",\"15.338\"],[\"79232.90\",\"0.141\"],[\"79491.70\",\"0.232\"],[\"79535.50\",\"0.351\"],[\"79573.80\",\"0.073\"],[\"79576.10\",\"0.987\"],[\"79583.20\",\"0.504\"],[\"79583.40\",\"0.006\"],[\"79583.80\",\"0.001\"],[\"79589.20\",\"0.470\"],[\"79594.80\",\"0.002\"],[\"79603.70\",\"0.011\"],[\"79604.60\",\"0.026\"],[\"79604.80\",\"0.028\"],[\"79604.90\",\"0.026\"],[\"79605.30\",\"0.000\"],[\"79605.40\",\"0.001\"],[\"79605.50\",\"0.001\"],[\"79605.90\",\"0.000\"]],\"a\":[[\"79609.90\",\"0.000\"],[\"79616.20\",\"0.082\"],[\"79618.30\",\"0.815\"],[\"79623.30\",\"0.458\"],[\"79624.50\",\"0.479\"],[\"79625.60\",\"0.475\"],[\"79774.40\",\"2.254\"],[\"79968.00\",\"0.867\"],[\"79969.40\",\"1.116\"],[\"79995.30\",\"0.046\"],[\"79997.80\",\"0.525\"],[\"80244.10\",\"8.371\"],[\"80403.30\",\"22.314\"],[\"80767.40\",\"1.482\"],[\"80960.50\",\"8.880\"],[\"81040.10\",\"4.928\"],[\"81110.60\",\"1.723\"],[\"87567.90\",\"0.000\"]],\"st\":1}}"}
{"receive_ns":1788563392745787000,"stream":"btcusdt@bookTicker","event_type":"bookTicker","event_time_ms":1788563392775,"raw_json":"{\"stream\":\"btcusdt@bookTicker\",\"data\":{\"e\":\"bookTicker\",\"u\":11478233270598,\"s\":\"BTCUSDT\",\"ps\":\"BTCUSDT\",\"b\":\"79607.10\",\"B\":\"5.085\",\"a\":\"79607.20\",\"A\":\"6.601\",\"T\":1788563392775,\"E\":1788563392775,\"st\":1}}"}
{"receive_ns":1788563392745939000,"stream":"btcusdt@bookTicker","event_type":"bookTicker","event_time_ms":1788563392778,"raw_json":"{\"stream\":\"btcusdt@bookTicker\",\"data\":{\"e\":\"bookTicker\",\"u\":11478233270748,\"s\":\"BTCUSDT\",\"ps\":\"BTCUSDT\",\"b\":\"79607.10\",\"B\":\"5.100\",\"a\":\"79607.20\",\"A\":\"6.601\",\"T\":1788563392778,\"E\":1788563392778,\"st\":1}}"}
{"receive_ns":1788563392803075000,"stream":"btcusdt@bookTicker","event_type":"bookTicker","event_time_ms":1788563392844,"raw_json":"{\"stream\":\"btcusdt@bookTicker\",\"data\":{\"e\":\"bookTicker\",\"u\":11478233274145,\"s\":\"BTCUSDT\",\"ps\":\"BTCUSDT\",\"b\":\"79607.10\",\"B\":\"5.100\",\"a\":\"79607.20\",\"A\":\"6.600\",\"T\":1788563392844,\"E\":1788563392844,\"st\":1}}"}
{"receive_ns":1788563392837208000,"stream":"btcusdt@depth@100ms","event_type":"depthUpdate","event_time_ms":1788563392877,"raw_json":"{\"stream\":\"btcusdt@depth@100ms\",\"data\":{\"e\":\"depthUpdate\",\"E\":1788563392877,\"T\":1788563392876,\"s\":\"BTCUSDT\",\"ps\":\"BTCUSDT\",\"U\":11478233270593,\"u\":11478233275718,\"pu\":11478233270498,\"b\":[[\"1000.00\",\"24.754\"],[\"29107.10\",\"0.777\"],[\"29507.10\",\"1.323\"],[\"71646.30\",\"0.002\"],[\"78436.90\",\"8.761\"],[\"78572.20\",\"29.669\"],[\"78651.80\",\"52.919\"],[\"78811.00\",\"15.338\"],[\"79523.30\",\"0.001\"],[\"79523.70\",\"0.142\"],[\"79535.40\",\"0.002\"],[\"79574.90\",\"0.474\"],[\"79576.10\",\"0.535\"],[\"79585.50\",\"0.006\"],[\"79588.30\",\"0.068\"],[\"79590.60\",\"0.314\"],[\"79591.10\",\"0.005\"],[\"79592.50\",\"0.018\"],[\"79593.00\",\"0.016\"],[\"79594.50\",\"0.226\"],[\"79603.80\",\"0.003\"],[\"79604.00\",\"0.003\"],[\"79605.00\",\"0.656\"],[\"79605.10\",\"0.026\"],[\"79605.20\",\"0.028\"],[\"79607.10\",\"5.100\"]],\"a\":[[\"79607.20\",\"6.600\"],[\"79615.30\",\"0.001\"],[\"79618.10\",\"0.005\"],[\"80403.30\",\"22.314\"],[\"80777.40\",\"11.114\"],[\"81110.60\",\"0.000\"],[\"81119.70\",\"3.445\"],[\"81179.50\",\"0.000\"]],\"st\":1}}"}
{"receive_ns":1788563392940359000,"stream":"btcusdt@depth@100ms","event_type":"depthUpdate","event_time_ms":1788563392979,"raw_json":"{\"stream\":\"btcusdt@depth@100ms\",\"data\":{\"e\":\"depthUpdate\",\"E\":1788563392979,\"T\":1788563392978,\"s\":\"BTCUSDT\",\"ps\":\"BTCUSDT\",\"U\":11478233275750,\"u\":11478233279642,\"pu\":11478233275718,\"b\":[[\"29107.10\",\"0.595\"],[\"29507.10\",\"1.505\"],[\"63686.00\",\"0.002\"],[\"71646.30\",\"0.002\"],[\"76422.80\",\"0.002\"],[\"78373.20\",\"11.545\"],[\"78413.00\",\"7.578\"],[\"78612.00\",\"15.985\"],[\"78651.80\",\"54.189\"],[\"78811.00\",\"15.338\"],[\"78874.90\",\"0.190\"],[\"79029.60\",\"0.000\"],[\"79209.10\",\"4.608\"],[\"79232.90\",\"0.141\"],[\"79491.70\",\"0.232\"],[\"79535.50\",\"0.000\"],[\"79583.20\",\"0.353\"],[\"79583.80\",\"2.009\"],[\"79589.20\",\"0.772\"],[\"79597.30\",\"0.054\"]],\"a\":[[\"79702.80\",\"0.010\"],[\"79774.40\",\"2.254\"],[\"79968.00\",\"0.867\"],[\"79969.40\",\"0.917\"],[\"79995.30\",\"0.046\"],[\"79997.80\",\"0.525\"],[\"80403.30\",\"22.314\"],[\"80960.50\",\"12.580\"],[\"81119.70\",\"5.168\"],[\"81190.20\",\"1.230\"]],\"st\":1}}"}
{"receive_ns":1788563393031429000,"stream":"btcusdt@bookTicker","event_type":"bookTicker","event_time_ms":1788563393071,"raw_json":"{\"stream\":\"btcusdt@bookTicker\",\"data\":{\"e\":\"bookTicker\",\"u\":11478233283953,\"s\":\"BTCUSDT\",\"ps\":\"BTCUSDT\",\"b\":\"79607.10\",\"B\":\"5.100\",\"a\":\"79607.20\",\"A\":\"6.520\",\"T\":1788563393071,\"E\":1788563393071,\"st\":1}}"}
{"receive_ns":1788563393038464000,"stream":"btcusdt@trade","event_type":"trade","event_time_ms":1788563393071,"raw_json":"{\"stream\":\"btcusdt@trade\",\"data\":{\"e\":\"trade\",\"E\":1788563393071,\"T\":1788563393071,\"s\":\"BTCUSDT\",\"t\":8054083502,\"p\":\"79607.20\",\"q\":\"0.080\",\"X\":\"MARKET\",\"m\":false,\"st\":1}}"}
{"receive_ns":1788563393040977000,"stream":"btcusdt@depth@100ms","event_type":"depthUpdate","event_time_ms":1788563393081,"raw_json":"{\"stream\":\"btcusdt@depth@100ms\",\"data\":{\"e\":\"depthUpdate\",\"E\":1788563393081,\"T\":1788563393080,\"s\":\"BTCUSDT\",\"ps\":\"BTCUSDT\",\"U\":11478233279663,\"u\":11478233284430,\"pu\":11478233279642,\"b\":[[\"1000.00\",\"24.754\"],[\"29107.10\",\"0.420\"],[\"29507.10\",\"1.680\"],[\"63686.00\",\"0.000\"],[\"71646.30\",\"0.002\"],[\"71646.40\",\"0.032\"],[\"76422.80\",\"0.000\"],[\"78811.00\",\"15.338\"],[\"79443.90\",\"2.477\"],[\"79483.30\",\"0.520\"],[\"79523.70\",\"0.017\"],[\"79523.80\",\"0.485\"],[\"79583.20\",\"0.002\"],[\"79583.80\",\"0.001\"],[\"79589.20\",\"0.972\"],[\"79592.80\",\"0.004\"],[\"79594.50\",\"0.150\"],[\"79594.80\",\"0.078\"],[\"79603.70\",\"0.037\"],[\"79603.80\",\"0.029\"],[\"79604.00\",\"0.029\"],[\"79604.80\",\"0.002\"],[\"79604.90\",\"0.000\"],[\"79605.00\",\"0.630\"],[\"79605.10\",\"0.000\"],[\"79605.20\",\"0.002\"],[\"79606.00\",\"0.000\"]],\"a\":[[\"79607.20\",\"6.520\"],[\"79615.30\",\"0.001\"],[\"79618.10\",\"0.005\"],[\"79728.80\",\"0.294\"],[\"79768.20\",\"1.329\"],[\"79828.70\",\"7.993\"],[\"79969.40\",\"1.116\"],[\"80403.30\",\"22.316\"],[\"80681.90\",\"10.786\"],[\"80729.70\",\"4.947\"],[\"81199.30\",\"14.234\"]],\"st\":1}}"}
{"receive_ns":1788563393142463000,"stream":"btcusdt@depth@100ms","event_type":"depthUpdate","event_time_ms":1788563393183,"raw_json":"{\"stream\":\"btcusdt@depth@100ms\",\"data\":{\"e\":\"depthUpdate\",\"E\":1788563393183,\"T\":1788563393182,\"s\":\"BTCUSDT\",\"ps\":\"BTCUSDT\",\"U\":11478233284509,\"u\":11478233290860,\"pu\":11478233284430,\"b\":[[\"1000.00\",\"24.754\"],[\"29107.10\",\"0.273\"],[\"29407.10\",\"0.035\"],[\"29507.10\",\"1.792\"],[\"63686.00\",\"0.000\"],[\"71646.30\",\"0.002\"],[\"76422.80\",\"0.002\"],[\"78811.00\",\"15.338\"],[\"79523.70\",\"0.142\"],[\"79523.80\",\"0.360\"],[\"79592.50\",\"0.001\"],[\"79593.00\",\"0.001\"],[\"79593.50\",\"0.021\"],[\"79594.00\",\"0.021\"],[\"79605.40\",\"0.027\"]],\"a\":[[\"79618.50\",\"0.004\"],[\"79620.60\",\"7.703\"],[\"79644.20\",\"1.383\"],[\"79647.10\",\"0.069\"],[\"79668.10\",\"5.476\"],[\"79668.20\",\"2.949\"],[\"79708.20\",\"2.515\"],[\"80403.30\",\"22.314\"],[\"80474.90\",\"7.374\"],[\"80562.50\",\"51.076\"],[\"80598.60\",\"12.023\"],[\"83587.50\",\"0.041\"]],\"st\":1}}"}
{"receive_ns":1788563393184938000,"stream":"btcusdt@bookTicker","event_type":"bookTicker","event_time_ms":1788563393224,"raw_json":"{\"stream\":\"btcusdt@bookTicker\",\"data\":{\"e\":\"bookTicker\",\"u\":11478233292672,\"s\":\"BTCUSDT\",\"ps\":\"BTCUSDT\",\"b\":\"79607.10\",\"B\":\"4.604\",\"a\":\"79607.20\",\"A\":\"6.520\",\"T\":1788563393223,\"E\":1788563393224,\"st\":1}}"}
{"receive_ns":1788563393185185000,"stream":"btcusdt@bookTicker","event_type":"bookTicker","event_time_ms":1788563393225,"raw_json":"{\"stream\":\"btcusdt@bookTicker\",\"data\":{\"e\":\"bookTicker\",\"u\":11478233292732,\"s\":\"BTCUSDT\",\"ps\":\"BTCUSDT\",\"b\":\"79607.10\",\"B\":\"4.603\",\"a\":\"79607.20\",\"A\":\"6.520\",\"T\":1788563393225,\"E\":1788563393225,\"st\":1}}"}
{"receive_ns":1788563393186827000,"stream":"btcusdt@bookTicker","event_type":"bookTicker","event_time_ms":1788563393226,"raw_json":"{\"stream\":\"btcusdt@bookTicker\",\"data\":{\"e\":\"bookTicker\",\"u\":11478233292802,\"s\":\"BTCUSDT\",\"ps\":\"BTCUSDT\",\"b\":\"79607.10\",\"B\":\"5.103\",\"a\":\"79607.20\",\"A\":\"6.520\",\"T\":1788563393226,\"E\":1788563393226,\"st\":1}}"}
{"receive_ns":1788563393188200000,"stream":"btcusdt@bookTicker","event_type":"bookTicker","event_time_ms":1788563393228,"raw_json":"{\"stream\":\"btcusdt@bookTicker\",\"data\":{\"e\":\"bookTicker\",\"u\":11478233292873,\"s\":\"BTCUSDT\",\"ps\":\"BTCUSDT\",\"b\":\"79607.10\",\"B\":\"5.101\",\"a\":\"79607.20\",\"A\":\"6.520\",\"T\":1788563393227,\"E\":1788563393228,\"st\":1}}"}
{"receive_ns":1788563393245537000,"stream":"btcusdt@depth@100ms","event_type":"depthUpdate","event_time_ms":1788563393285,"raw_json":"{\"stream\":\"btcusdt@depth@100ms\",\"data\":{\"e\":\"depthUpdate\",\"E\":1788563393285,\"T\":1788563393281,\"s\":\"BTCUSDT\",\"ps\":\"BTCUSDT\",\"U\":11478233290920,\"u\":11478233294694,\"pu\":11478233290860,\"b\":[[\"29107.10\",\"0.161\"],[\"29407.10\",\"0.098\"],[\"29507.10\",\"1.841\"],[\"71646.30\",\"0.002\"],[\"76422.80\",\"0.000\"],[\"78015.00\",\"10.688\"],[\"78811.00\",\"15.338\"],[\"79209.10\",\"4.608\"],[\"79232.90\",\"0.141\"],[\"79443.90\",\"0.000\"],[\"79483.30\",\"0.001\"],[\"79491.70\",\"0.232\"],[\"79533.60\",\"0.001\"],[\"79549.50\",\"0.037\"],[\"79583.20\",\"0.353\"],[\"79589.20\",\"0.972\"],[\"79589.80\",\"0.006\"],[\"79605.40\",\"0.001\"],[\"79605.50\",\"0.001\"],[\"79605.60\",\"0.053\"],[\"79606.60\",\"0.037\"],[\"79606.90\",\"0.198\"],[\"79607.10\",\"5.101\"]],\"a\":[[\"79609.20\",\"0.000\"],[\"79615.30\",\"0.005\"],[\"79618.10\",\"0.376\"],[\"79618.30\",\"0.440\"],[\"79707.40\",\"0.002\"],[\"79707.50\",\"0.126\"],[\"79709.70\",\"0.831\"],[\"79728.80\",\"0.000\"],[\"79768.20\",\"0.000\"],[\"79774.40\",\"2.003\"],[\"79968.00\",\"0.867\"],[\"79969.40\",\"1.367\"],[\"79995.30\",\"0.002\"],[\"79997.80\",\"0.525\"],[\"79999.30\",\"0.055\"],[\"80403.30\",\"22.314\"],[\"81199.30\",\"14.231\"]],\"st\":1}}"}
{"receive_ns":1788563393334395000,"stream":"btcusdt@bookTicker","event_type":"bookTicker","event_time_ms":1788563393366,"raw_json":"{\"stream\":\"btcusdt@bookTicker\",\"data\":{\"e\":\"bookTicker\",\"u\":11478233298446,\"s\":\"BTCUSDT\",\"ps\":\"BTCUSDT\",\"b\":\"79607.10\",\"B\":\"5.139\",\"a\":\"79607.20\",\"A\":\"6.520\",\"T\":1788563393366,\"E\":1788563393366,\"st\":1}}"}
{"receive_ns":1788563393334618000,"stream":"btcusdt@bookTicker","event_type":"bookTicker","event_time_ms":1788563393368,"raw_json":"{\"stream\":\"btcusdt@bookTicker\",\"data\":{\"e\":\"bookTicker\",\"u\":11478233298531,\"s\":\"BTCUSDT\",\"ps\":\"BTCUSDT\",\"b\":\"79607.10\",\"B\":\"5.140\",\"a\":\"79607.20\",\"A\":\"6.520\",\"T\":1788563393367,\"E\":1788563393368,\"st\":1}}"}
{"receive_ns":1788563393334754000,"stream":"btcusdt@bookTicker","event_type":"bookTicker","event_time_ms":1788563393368,"raw_json":"{\"stream\":\"btcusdt@bookTicker\",\"data\":{\"e\":\"bookTicker\",\"u\":11478233298534,\"s\":\"BTCUSDT\",\"ps\":\"BTCUSDT\",\"b\":\"79607.10\",\"B\":\"5.142\",\"a\":\"79607.20\",\"A\":\"6.520\",\"T\":1788563393367,\"E\":1788563393368,\"st\":1}}"}
{"receive_ns":1788563393347882000,"stream":"btcusdt@depth@100ms","event_type":"depthUpdate","event_time_ms":1788563393387,"raw_json":"{\"stream\":\"btcusdt@depth@100ms\",\"data\":{\"e\":\"depthUpdate\",\"E\":1788563393387,\"T\":1788563393385,\"s\":\"BTCUSDT\",\"ps\":\"BTCUSDT\",\"U\":11478233294869,\"u\":11478233299299,\"pu\":11478233294694,\"b\":[[\"1000.00\",\"24.754\"],[\"29107.10\",\"0.035\"],[\"29407.10\",\"0.154\"],[\"29507.10\",\"1.911\"],[\"71646.30\",\"0.002\"],[\"78811.00\",\"15.339\"],[\"79209.00\",\"0.000\"],[\"79443.90\",\"2.477\"],[\"79483.30\",\"0.520\"],[\"79573.90\",\"0.002\"],[\"79574.90\",\"0.474\"],[\"79576.10\",\"0.535\"],[\"79584.00\",\"0.015\"],[\"79588.00\",\"3.077\"],[\"79596.10\",\"0.003\"],[\"79603.70\",\"0.011\"],[\"79605.60\",\"0.052\"],[\"79606.10\",\"0.000\"],[\"79606.30\",\"0.066\"],[\"79606.90\",\"0.199\"],[\"79607.10\",\"5.142\"]],\"a\":[[\"79616.20\",\"0.082\"],[\"79618.30\",\"0.440\"],[\"79623.50\",\"0.001\"],[\"79624.50\",\"0.479\"],[\"79625.50\",\"0.458\"],[\"79625.60\",\"0.023\"],[\"79728.80\",\"0.294\"],[\"79768.20\",\"1.330\"],[\"79828.70\",\"7.896\"],[\"80323.80\",\"2.611\"],[\"80403.30\",\"22.314\"],[\"80681.90\",\"11.405\"],[\"80761.50\",\"22.262\"],[\"80951.40\",\"0.303\"],[\"87568.00\",\"0.000\"]],\"st\":1}}"}
{"receive_ns":1788563393402379000,"stream":"btcusdt@bookTicker","event_type":"bookTicker","event_time_ms":1788563393442,"raw_json":"{\"stream\":\"btcusdt@bookTicker\",\"data\":{\"e\":\"bookTicker\",\"u\":11478233301157,\"s\":\"BTCUSDT\",\"ps\":\"BTCUSDT\",\"b\":\"79607.10\",\"B\":\"4.701\",\"a\":\"79607.20\",\"A\":\"6.520\",\"T\":1788563393442,\"E\":1788563393442,\"st\":1}}"}
{"receive_ns":1788563393402611000,"stream":"btcusdt@bookTicker","event_type":"bookTicker","event_time_ms":1788563393443,"raw_json":"{\"stream\":\"btcusdt@bookTicker\",\"data\":{\"e\":\"bookTicker\",\"u\":11478233301196,\"s\":\"BTCUSDT\",\"ps\":\"BTCUSDT\",\"b\":\"79607.10\",\"B\":\"4.700\",\"a\":\"79607.20\",\"A\":\"6.520\",\"T\":1788563393443,\"E\":1788563393443,\"st\":1}}"}
{"receive_ns":1788563393405749000,"stream":"btcusdt@bookTicker","event_type":"bookTicker","event_time_ms":1788563393444,"raw_json":"{\"stream\":\"btcusdt@bookTicker\",\"data\":{\"e\":\"bookTicker\",\"u\":11478233301291,\"s\":\"BTCUSDT\",\"ps\":\"BTCUSDT\",\"b\":\"79607.10\",\"B\":\"4.701\",\"a\":\"79607.20\",\"A\":\"6.520\",\"T\":1788563393444,\"E\":1788563393444,\"st\":1}}"}
{"receive_ns":1788563393406013000,"stream":"btcusdt@bookTicker","event_type":"bookTicker","event_time_ms":1788563393445,"raw_json":"{\"stream\":\"btcusdt@bookTicker\",\"data\":{\"e\":\"bookTicker\",\"u\":11478233301331,\"s\":\"BTCUSDT\",\"ps\":\"BTCUSDT\",\"b\":\"79607.10\",\"B\":\"5.149\",\"a\":\"79607.20\",\"A\":\"6.520\",\"T\":1788563393445,\"E\":1788563393445,\"st\":1}}"}
{"receive_ns":1788563393413364000,"stream":"btcusdt@bookTicker","event_type":"bookTicker","event_time_ms":1788563393446,"raw_json":"{\"stream\":\"btcusdt@bookTicker\",\"data\":{\"e\":\"bookTicker\",\"u\":11478233301390,\"s\":\"BTCUSDT\",\"ps\":\"BTCUSDT\",\"b\":\"79607.10\",\"B\":\"5.147\",\"a\":\"79607.20\",\"A\":\"6.520\",\"T\":1788563393446,\"E\":1788563393446,\"st\":1}}"}
{"receive_ns":1788563393450614000,"stream":"btcusdt@depth@100ms","event_type":"depthUpdate","event_time_ms":1788563393489,"raw_json":"{\"stream\":\"btcusdt@depth@100ms\",\"data\":{\"e\":\"depthUpdate\",\"E\":1788563393489,\"T\":1788563393485,\"s\":\"BTCUSDT\",\"ps\":\"BTCUSDT\",\"U\":11478233299340,\"u\":11478233302839,\"pu\":11478233299299,\"b\":[[\"1000.00\",\"24.754\"],[\"29107.10\",\"0.000\"],[\"29407.10\",\"0.294\"],[\"29507.10\",\"1.806\"],[\"71646.30\",\"0.002\"],[\"71684.00\",\"0.000\"],[\"75626.70\",\"0.021\"],[\"75626.80\",\"0.004\"],[\"76422.80\",\"0.002\"],[\"78404.10\",\"2.548\"],[\"78492.60\",\"54.619\"],[\"78612.00\",\"16.270\"],[\"78811.00\",\"15.339\"],[\"79232.90\",\"0.141\"],[\"79491.70\",\"0.000\"],[\"79583.20\",\"0.353\"],[\"79589.20\",\"0.772\"],[\"79589.80\",\"0.006\"],[\"79595.70\",\"0.001\"],[\"79603.70\",\"0.037\"],[\"79605.60\",\"0.052\"],[\"79605.70\",\"0.164\"],[\"79607.10\",\"5.147\"]],\"a\":[[\"79609.40\",\"0.017\"],[\"79615.30\",\"0.005\"],[\"79618.00\",\"0.422\"],[\"79618.10\",\"0.001\"],[\"79968.00\",\"0.867\"],[\"79969.40\",\"1.367\"],[\"79997.80\",\"0.525\"],[\"79999.30\",\"0.055\"],[\"80005.30\",\"0.003\"],[\"80394.70\",\"0.000\"],[\"80403.30\",\"22.314\"]],\"st\":1}}"}
{"receive_ns":1788563393472500000,"stream":"btcusdt@bookTicker","event_type":"bookTicker","event_time_ms":1788563393511,"raw_json":"{\"stream\":\"btcusdt@bookTicker\",\"data\":{\"e\":\"bookTicker\",\"u\":11478233303777,\"s\":\"BTCUSDT\",\"ps\":\"BTCUSDT\",\"b\":\"79607.10\",\"B\":\"5.148\",\"a\":\"79607.20\",\"A\":\"6.520\",\"T\":1788563393511,\"E\":1788563393511,\"st\":1}}"}
{"receive_ns":1788563393542246000,"stream":"btcusdt@bookTicker","event_type":"bookTicker","event_time_ms":1788563393581,"raw_json":"{\"stream\":\"btcusdt@bookTicker\",\"data\":{\"e\":\"bookTicker\",\"u\":11478233306415,\"s\":\"BTCUSDT\",\"ps\":\"BTCUSDT\",\"b\":\"79607.10\",\"B\":\"5.133\",\"a\":\"79607.20\",\"A\":\"6.520\",\"T\":1788563393581,\"E\":1788563393581,\"st\":1}}"}
{"receive_ns":1788563393545220000,"stream":"btcusdt@bookTicker","event_type":"bookTicker","event_time_ms":1788563393585,"raw_json":"{\"stream\":\"btcusdt@bookTicker\",\"data\":{\"e\":\"bookTicker\",\"u\":11478233306595,\"s\":\"BTCUSDT\",\"ps\":\"BTCUSDT\",\"b\":\"79607.10\",\"B\":\"5.148\",\"a\":\"79607.20\",\"A\":\"6.520\",\"T\":1788563393585,\"E\":1788563393585,\"st\":1}}"}
{"receive_ns":1788563393545444000,"stream":"btcusdt@bookTicker","event_type":"bookTicker","event_time_ms":1788563393586,"raw_json":"{\"stream\":\"btcusdt@bookTicker\",\"data\":{\"e\":\"bookTicker\",\"u\":11478233306644,\"s\":\"BTCUSDT\",\"ps\":\"BTCUSDT\",\"b\":\"79607.10\",\"B\":\"5.150\",\"a\":\"79607.20\",\"A\":\"6.520\",\"T\":1788563393586,\"E\":1788563393586,\"st\":1}}"}
{"receive_ns":1788563393552118000,"stream":"btcusdt@depth@100ms","event_type":"depthUpdate","event_time_ms":1788563393591,"raw_json":"{\"stream\":\"btcusdt@depth@100ms\",\"data\":{\"e\":\"depthUpdate\",\"E\":1788563393591,\"T\":1788563393590,\"s\":\"BTCUSDT\",\"ps\":\"BTCUSDT\",\"U\":11478233302950,\"u\":11478233306761,\"pu\":11478233302839,\"b\":[[\"29407.10\",\"0.476\"],[\"29507.10\",\"1.624\"],[\"71646.30\",\"0.002\"],[\"76422.80\",\"0.000\"],[\"78811.00\",\"15.339\"],[\"79209.10\",\"4.608\"],[\"79443.90\",\"2.476\"],[\"79483.30\",\"0.520\"],[\"79520.50\",\"0.000\"],[\"79523.90\",\"1.619\"],[\"79548.30\",\"0.000\"],[\"79551.70\",\"0.639\"],[\"79568.20\",\"0.121\"],[\"79589.20\",\"0.972\"],[\"79596.60\",\"0.077\"],[\"79603.70\",\"0.011\"],[\"79603.80\",\"0.003\"],[\"79605.50\",\"0.002\"],[\"79606.60\",\"0.063\"],[\"79606.80\",\"0.030\"],[\"79606.90\",\"0.197\"],[\"79607.10\",\"5.150\"]],\"a\":[[\"79607.30\",\"1.351\"],[\"79607.40\",\"2.601\"],[\"79609.40\",\"0.015\"],[\"79615.30\",\"0.001\"],[\"79618.10\",\"0.005\"],[\"79626.40\",\"0.000\"],[\"79627.60\",\"0.062\"],[\"79639.10\",\"0.033\"],[\"79659.00\",\"0.001\"],[\"79685.00\",\"0.760\"],[\"79686.90\",\"0.003\"],[\"79728.80\",\"0.294\"],[\"79768.20\",\"1.330\"],[\"80204.30\",\"3.736\"],[\"80403.30\",\"21.695\"],[\"80761.50\",\"22.386\"],[\"80960.50\",\"13.814\"],[\"81031.00\",\"3.672\"]],\"st\":1}}"}
{"receive_ns":1788563393572964000,"stream":"btcusdt@bookTicker","event_type":"bookTicker","event_time_ms":1788563393612,"raw_json":"{\"stream\":\"btcusdt@bookTicker\",\"data\":{\"e\":\"bookTicker\",\"u\":11478233307495,\"s\":\"BTCUSDT\",\"ps\":\"BTCUSDT\",\"b\":\"79607.10\",\"B\":\"5.150\",\"a\":\"79607.20\",\"A\":\"6.546\",\"T\":1788563393612,\"E\":1788563393612,\"st\":1}}"}
{"receive_ns":1788563393598874000,"stream":"btcusdt@bookTicker","event_type":"bookTicker","event_time_ms":1788563393639,"raw_json":"{\"stream\":\"btcusdt@bookTicker\",\"data\":{\"e\":\"bookTicker\",\"u\":11478233308292,\"s\":\"BTCUSDT\",\"ps\":\"BTCUSDT\",\"b\":\"79607.10\",\"B\":\"4.593\",\"a\":\"79607.20\",\"A\":\"6.546\",\"T\":1788563393639,\"E\":1788563393639,\"st\":1}}"}
{"receive_ns":1788563393600892000,"stream":"btcusdt@bookTicker","event_type":"bookTicker","event_time_ms":1788563393642,"raw_json":"{\"stream\":\"btcusdt@bookTicker\",\"data\":{\"e\":\"bookTicker\",\"u\":11478233308436,\"s\":\"BTCUSDT\",\"ps\":\"BTCUSDT\",\"b\":\"79607.10\",\"B\":\"5.157\",\"a\":\"79607.20\",\"A\":\"6.546\",\"T\":1788563393642,\"E\":1788563393642,\"st\":1}}"}
{"receive_ns":1788563393602266000,"stream":"btcusdt@bookTicker","event_type":"bookTicker","event_time_ms":1788563393643,"raw_json":"{\"stream\":\"btcusdt@bookTicker\",\"data\":{\"e\":\"bookTicker\",\"u\":11478233308487,\"s\":\"BTCUSDT\",\"ps\":\"BTCUSDT\",\"b\":\"79607.10\",\"B\":\"5.155\",\"a\":\"79607.20\",\"A\":\"6.546\",\"T\":1788563393643,\"E\":1788563393643,\"st\":1}}"}
{"receive_ns":1788563393653458000,"stream":"btcusdt@depth@100ms","event_type":"depthUpdate","event_time_ms":1788563393693,"raw_json":"{\"stream\":\"btcusdt@depth@100ms\",\"data\":{\"e\":\"depthUpdate\",\"E\":1788563393693,\"T\":1788563393692,\"s\":\"BTCUSDT\",\"ps\":\"BTCUSDT\",\"U\":11478233306788,\"u\":11478233310776,\"pu\":11478233306761,\"b\":[[\"1000.00\",\"24.754\"],[\"29407.10\",\"0.651\"],[\"29507.10\",\"1.449\"],[\"63685.70\",\"0.001\"],[\"63686.00\",\"0.000\"],[\"71646.30\",\"0.002\"],[\"76422.80\",\"0.002\"],[\"78015.00\",\"10.685\"],[\"78253.80\",\"8.035\"],[\"78691.60\",\"11.528\"],[\"78711.20\",\"0.000\"],[\"78811.00\",\"15.339\"],[\"78890.60\",\"43.705\"],[\"79232.90\",\"0.000\"],[\"79480.70\",\"0.000\"],[\"79511.50\",\"0.024\"],[\"79521.50\",\"0.000\"],[\"79535.40\",\"0.000\"],[\"79537.40\",\"0.000\"],[\"79583.20\",\"0.002\"],[\"79583.40\",\"0.004\"],[\"79589.20\",\"0.195\"],[\"79596.60\",\"0.001\"],[\"79597.80\",\"0.003\"],[\"79600.90\",\"0.002\"],[\"79603.80\",\"0.029\"],[\"79605.00\",\"0.656\"],[\"79605.20\",\"0.028\"],[\"79605.60\",\"0.026\"],[\"79605.70\",\"0.138\"],[\"79606.00\",\"0.000\"],[\"79606.60\",\"0.001\"],[\"79606.80\",\"0.004\"],[\"79607.10\",\"5.155\"]],\"a\":[[\"79607.20\",\"6.546\"],[\"79608.50\",\"0.000\"],[\"79623.30\",\"0.456\"],[\"79668.90\",\"25.161\"],[\"79671.50\",\"0.002\"],[\"79678.90\",\"0.015\"],[\"79702.80\",\"0.008\"],[\"79725.00\",\"1.517\"],[\"79968.00\",\"0.104\"],[\"79969.40\",\"0.001\"],[\"79997.80\",\"0.000\"],[\"79999.30\",\"0.011\"],[\"80403.30\",\"21.693\"],[\"81031.00\",\"1.946\"]],\"st\":1}}"}
{"receive_ns":1788563393754855000,"stream":"btcusdt@depth@100ms","event_type":"depthUpdate","event_time_ms":1788563393795,"raw_json":"{\"stream\":\"btcusdt@depth@100ms\",\"data\":{\"e\":\"depthUpdate\",\"E\":1788563393795,\"T\":1788563393794,\"s\":\"BTCUSDT\",\"ps\":\"BTCUSDT\",\"U\":11478233310831,\"u\":11478233315235,\"pu\":11478233310776,\"b\":[[\"1000.00\",\"24.754\"],[\"29407.10\",\"0.833\"],[\"29507.10\",\"1.267\"],[\"71646.30\",\"0.002\"],[\"75626.70\",\"0.023\"],[\"76422.80\",\"0.000\"],[\"78244.90\",\"1.660\"],[\"78413.00\",\"8.851\"],[\"78811.00\",\"15.339\"],[\"79232.90\",\"0.141\"],[\"79482.30\",\"2.138\"],[\"79491.70\",\"0.232\"],[\"79505.60\",\"1.691\"],[\"79521.40\",\"6.000\"],[\"79523.90\",\"2.523\"],[\"79549.20\",\"3.500\"],[\"79551.70\",\"1.070\"],[\"79552.00\",\"1.628\"],[\"79568.70\",\"0.002\"],[\"79569.10\",\"0.412\"],[\"79583.20\",\"0.504\"],[\"79583.40\",\"0.006\"],[\"79583.80\",\"0.001\"],[\"79589.20\",\"0.470\"],[\"79605.30\",\"0.026\"]],\"a\":[[\"79623.30\",\"0.458\"],[\"79639.30\",\"0.428\"],[\"79659.20\",\"3.542\"],[\"79668.90\",\"0.000\"],[\"79676.90\",\"25.275\"],[\"79687.10\",\"6.000\"],[\"79724.40\",\"0.686\"],[\"79774.40\",\"2.505\"],[\"79969.40\",\"0.865\"],[\"79995.80\",\"0.863\"],[\"79997.80\",\"0.525\"],[\"79999.30\",\"0.055\"],[\"80403.30\",\"21.693\"],[\"80403.40\",\"2.734\"],[\"80464.90\",\"0.559\"],[\"81040.10\",\"6.652\"]],\"st\":1}}"}
{"receive_ns":1788563393867166000,"stream":"btcusdt@depth@100ms","event_type":"depthUpdate","event_time_ms":1788563393897,"raw_json":"{\"stream\":\"btcusdt@depth@100ms\",\"data\":{\"e\":\"depthUpdate\",\"E\":1788563393897,\"T\":1788563393894,\"s\":\"BTCUSDT\",\"ps\":\"BTCUSDT\",\"U\":11478233315295,\"u\":11478233319232,\"pu\":11478233315235,\"b\":[[\"29407.10\",\"1.008\"],[\"29507.10\",\"1.092\"],[\"63686.00\",\"0.000\"],[\"71646.30\",\"0.002\"],[\"78244.90\",\"0.383\"],[\"78492.60\",\"55.001\"],[\"78811.00\",\"15.339\"],[\"79209.10\",\"4.608\"],[\"79443.90\",\"2.476\"],[\"79483.30\",\"0.520\"],[\"79523.70\",\"0.017\"],[\"79523.80\",\"0.485\"],[\"79596.00\",\"0.333\"],[\"79603.80\",\"0.003\"],[\"79605.90\",\"0.026\"]],\"a\":[[\"79616.00\",\"0.459\"],[\"79618.30\",\"0.001\"],[\"79668.10\",\"1.857\"],[\"79668.20\",\"2.948\"],[\"79671.50\",\"25.071\"],[\"79676.90\",\"0.206\"],[\"79728.80\",\"0.294\"],[\"79768.20\",\"1.330\"],[\"80403.30\",\"21.693\"],[\"80721.70\",\"59.144\"],[\"81031.00\",\"0.222\"],[\"81040.10\",\"8.377\"]],\"st\":1}}"}
{"receive_ns":1788563393960094000,"stream":"btcusdt@depth@100ms","event_type":"depthUpdate","event_time_ms":1788563393999,"raw_json":"{\"stream\":\"btcusdt@depth@100ms\",\"data\":{\"e\":\"depthUpdate\",\"E\":1788563393999,\"T\":1788563393998,\"s\":\"BTCUSDT\",\"ps\":\"BTCUSDT\",\"U\":11478233319396,\"u\":11478233323009,\"pu\":11478233319232,\"b\":[[\"1000.00\",\"24.754\"],[\"29407.10\",\"1.190\"],[\"29507.10\",\"0.910\"],[\"63686.00\",\"0.000\"],[\"71646.30\",\"0.002\"],[\"76422.80\",\"0.002\"],[\"78324.50\",\"3.824\"],[\"78532.40\",\"12.308\"],[\"78811.00\",\"15.339\"],[\"79232.90\",\"0.141\"],[\"79481.60\",\"10.004\"],[\"79482.30\",\"3.288\"],[\"79491.70\",\"0.232\"],[\"79505.60\",\"1.340\"],[\"79578.50\",\"0.010\"],[\"79580.80\",\"0.001\"],[\"79583.20\",\"0.002\"],[\"79583.80\",\"0.001\"],[\"79589.20\",\"0.972\"],[\"79589.80\",\"0.006\"],[\"79594.80\",\"0.002\"],[\"79596.00\",\"0.257\"],[\"79605.40\",\"0.027\"],[\"79605.90\",\"0.000\"]],\"a\":[[\"79609.90\",\"0.002\"],[\"79616.00\",\"0.020\"],[\"79618.30\",\"0.440\"],[\"79724.40\",\"1.946\"],[\"79725.90\",\"10.200\"],[\"79774.40\",\"2.003\"],[\"79968.00\",\"0.867\"],[\"79969.40\",\"1.168\"],[\"79995.30\",\"0.046\"],[\"79995.80\",\"0.100\"],[\"79997.80\",\"0.525\"],[\"79999.30\",\"0.011\"],[\"80320.00\",\"5.051\"],[\"80403.30\",\"21.693\"],[\"80602.30\",\"12.580\"]],\"st\":1}}"}
{"receive_ns":1788563394050550000,"stream":"btcusdt@bookTicker","event_type":"bookTicker","event_time_ms":1788563394089,"raw_json":"{\"stream\":\"btcusdt@bookTicker\",\"data\":{\"e\":\"bookTicker\",\"u\":11478233328877,\"s\":\"BTCUSDT\",\"ps\":\"BTCUSDT\",\"b\":\"79607.10\",\"B\":\"5.155\",\"a\":\"79607.20\",\"A\":\"6.545\",\"T\":1788563394089,\"E\":1788563394089,\"st\":1}}"}
{"receive_ns":1788563394053402000,"stream":"btcusdt@bookTicker","event_type":"bookTicker","event_time_ms":1788563394093,"raw_json":"{\"stream\":\"btcusdt@bookTicker\",\"data\":{\"e\":\"bookTicker\",\"u\":11478233329189,\"s\":\"BTCUSDT\",\"ps\":\"BTCUSDT\",\"b\":\"79607.10\",\"B\":\"5.167\",\"a\":\"79607.20\",\"A\":\"6.545\",\"T\":1788563394093,\"E\":1788563394093,\"st\":1}}"}
{"receive_ns":1788563394053605000,"stream":"btcusdt@bookTicker","event_type":"bookTicker","event_time_ms":1788563394093,"raw_json":"{\"stream\":\"btcusdt@bookTicker\",\"data\":{\"e\":\"bookTicker\",\"u\":11478233329207,\"s\":\"BTCUSDT\",\"ps\":\"BTCUSDT\",\"b\":\"79607.10\",\"B\":\"5.179\",\"a\":\"79607.20\",\"A\":\"6.545\",\"T\":1788563394093,\"E\":1788563394093,\"st\":1}}"}
{"receive_ns":1788563394053777000,"stream":"btcusdt@bookTicker","event_type":"bookTicker","event_time_ms":1788563394094,"raw_json":"{\"stream\":\"btcusdt@bookTicker\",\"data\":{\"e\":\"bookTicker\",\"u\":11478233329230,\"s\":\"BTCUSDT\",\"ps\":\"BTCUSDT\",\"b\":\"79607.10\",\"B\":\"5.191\",\"a\":\"79607.20\",\"A\":\"6.545\",\"T\":1788563394093,\"E\":1788563394094,\"st\":1}}"}
{"receive_ns":1788563394053905000,"stream":"btcusdt@bookTicker","event_type":"bookTicker","event_time_ms":1788563394094,"raw_json":"{\"stream\":\"btcusdt@bookTicker\",\"data\":{\"e\":\"bookTicker\",\"u\":11478233329258,\"s\":\"BTCUSDT\",\"ps\":\"BTCUSDT\",\"b\":\"79607.10\",\"B\":\"5.193\",\"a\":\"79607.20\",\"A\":\"6.545\",\"T\":1788563394094,\"E\":1788563394094,\"st\":1}}"}
{"receive_ns":1788563394060417000,"stream":"btcusdt@depth@100ms","event_type":"depthUpdate","event_time_ms":1788563394101,"raw_json":"{\"stream\":\"btcusdt@depth@100ms\",\"data\":{\"e\":\"depthUpdate\",\"E\":1788563394101,\"T\":1788563394097,\"s\":\"BTCUSDT\",\"ps\":\"BTCUSDT\",\"U\":11478233323278,\"u\":11478233329511,\"pu\":11478233323009,\"b\":[[\"1000.00\",\"24.754\"],[\"29407.10\",\"1.365\"],[\"29507.10\",\"0.735\"],[\"63686.00\",\"0.002\"],[\"71646.30\",\"0.002\"],[\"76422.80\",\"0.000\"],[\"78006.10\",\"1.792\"],[\"78253.80\",\"9.311\"],[\"78324.50\",\"2.550\"],[\"78333.40\",\"5.276\"],[\"78811.00\",\"15.339\"],[\"79566.70\",\"0.071\"],[\"79578.40\",\"0.619\"],[\"79592.80\",\"0.004\"],[\"79606.90\",\"0.199\"],[\"79607.10\",\"5.193\"]],\"a\":[[\"79607.20\",\"6.545\"],[\"79615.30\",\"0.380\"],[\"79618.00\",\"0.047\"],[\"79618.10\",\"0.001\"],[\"79969.40\",\"1.367\"],[\"80403.30\",\"21.693\"],[\"80474.90\",\"7.931\"],[\"81040.10\",\"10.101\"]],\"st\":1}}"}
{"receive_ns":1788563394061200000,"stream":"btcusdt@bookTicker","event_type":"bookTicker","event_time_ms":1788563394101,"raw_json":"{\"stream\":\"btcusdt@bookTicker\",\"data\":{\"e\":\"bookTicker\",\"u\":11478233329755,\"s\":\"BTCUSDT\",\"ps\":\"BTCUSDT\",\"b\":\"79607.10\",\"B\":\"5.193\",\"a\":\"79607.20\",\"A\":\"6.543\",\"T\":1788563394101,\"E\":1788563394101,\"st\":1}}"}
{"receive_ns":1788563394095506000,"stream":"btcusdt@bookTicker","event_type":"bookTicker","event_time_ms":1788563394135,"raw_json":"{\"stream\":\"btcusdt@bookTicker\",\"data\":{\"e\":\"bookTicker\",\"u\":11478233331847,\"s\":\"BTCUSDT\",\"ps\":\"BTCUSDT\",\"b\":\"79607.10\",\"B\":\"5.193\",\"a\":\"79607.20\",\"A\":\"6.546\",\"T\":1788563394134,\"E\":1788563394135,\"st\":1}}"}
{"receive_ns":1788563394164022000,"stream":"btcusdt@depth@100ms","event_type":"depthUpdate","event_time_ms":1788563394203,"raw_json":"{\"stream\":\"btcusdt@depth@100ms\",\"data\":{\"e\":\"depthUpdate\",\"E\":1788563394203,\"T\":1788563394202,\"s\":\"BTCUSDT\",\"ps\":\"BTCUSDT\",\"U\":11478233329755,\"u\":11478233335376,\"pu\":11478233329511,\"b\":[[\"29407.10\",\"1.547\"],[\"29507.10\",\"0.553\"],[\"63686.00\",\"0.000\"],[\"71646.30\",\"0.002\"],[\"76422.80\",\"0.002\"],[\"78015.00\",\"10.688\"],[\"78253.80\",\"10.587\"],[\"78373.20\",\"12.437\"],[\"78452.80\",\"42.128\"],[\"78608.50\",\"10.472\"],[\"78612.00\",\"16.555\"],[\"78811.00\",\"15.339\"],[\"79209.10\",\"4.608\"],[\"79232.90\",\"0.000\"],[\"79491.70\",\"0.000\"],[\"79529.40\",\"0.003\"],[\"79568.80\",\"0.117\"],[\"79569.10\",\"0.410\"],[\"79578.40\",\"0.605\"],[\"79588.10\",\"2.363\"],[\"79589.20\",\"0.195\"],[\"79593.50\",\"0.003\"],[\"79594.00\",\"0.005\"],[\"79602.70\",\"0.002\"],[\"79603.30\",\"0.598\"]],\"a\":[[\"79607.20\",\"6.546\"],[\"79611.00\",\"0.136\"],[\"79612.10\",\"0.002\"],[\"79615.10\",\"0.004\"],[\"79615.30\",\"0.376\"],[\"79668.10\",\"5.463\"],[\"79673.90\",\"0.001\"],[\"79707.40\",\"0.003\"],[\"79708.90\",\"0.124\"],[\"79711.90\",\"0.002\"],[\"79968.00\",\"0.104\"],[\"79969.40\",\"0.001\"],[\"79995.30\",\"0.002\"],[\"79997.80\",\"0.000\"],[\"80403.30\",\"21.693\"],[\"80495.30\",\"0.000\"],[\"80642.20\",\"2.605\"]],\"st\":1}}"}
{"receive_ns":1788563394196393000,"stream":"btcusdt@bookTicker","event_type":"bookTicker","event_time_ms":1788563394231,"raw_json":"{\"stream\":\"btcusdt@bookTicker\",\"data\":{\"e\":\"bookTicker\",\"u\":11478233336719,\"s\":\"BTCUSDT\",\"ps\":\"BTCUSDT\",\"b\":\"79607.10\",\"B\":\"5.189\",\"a\":\"79607.20\",\"A\":\"6.546\",\"T\":1788563394231,\"E\":1788563394231,\"st\":1}}"}
{"receive_ns":1788563394196647000,"stream":"btcusdt@bookTicker","event_type":"bookTicker","event_time_ms":1788563394232,"raw_json":"{\"stream\":\"btcusdt@bookTicker\",\"data\":{\"e\":\"bookTicker\",\"u\":11478233336795,\"s\":\"BTCUSDT\",\"ps\":\"BTCUSDT\",\"b\":\"79607.10\",\"B\":\"5.188\",\"a\":\"79607.20\",\"A\":\"6.546\",\"T\":1788563394232,\"E\":1788563394232,\"st\":1}}"}
{"receive_ns":1788563394204011000,"stream":"btcusdt@bookTicker","event_type":"bookTicker","event_time_ms":1788563394234,"raw_json":"{\"stream\":\"btcusdt@bookTicker\",\"data\":{\"e\":\"bookTicker\",\"u\":11478233336946,\"s\":\"BTCUSDT\",\"ps\":\"BTCUSDT\",\"b\":\"79607.10\",\"B\":\"5.176\",\"a\":\"79607.20\",\"A\":\"6.546\",\"T\":1788563394234,\"E\":1788563394234,\"st\":1}}"}
{"receive_ns":1788563394204259000,"stream":"btcusdt@bookTicker","event_type":"bookTicker","event_time_ms":1788563394234,"raw_json":"{\"stream\":\"btcusdt@bookTicker\",\"data\":{\"e\":\"bookTicker\",\"u\":11478233336948,\"s\":\"BTCUSDT\",\"ps\":\"BTCUSDT\",\"b\":\"79607.10\",\"B\":\"5.164\",\"a\":\"79607.20\",\"A\":\"6.546\",\"T\":1788563394234,\"E\":1788563394234,\"st\":1}}"}
{"receive_ns":1788563394204407000,"stream":"btcusdt@bookTicker","event_type":"bookTicker","event_time_ms":1788563394234,"raw_json":"{\"stream\":\"btcusdt@bookTicker\",\"data\":{\"e\":\"bookTicker\",\"u\":11478233336952,\"s\":\"BTCUSDT\",\"ps\":\"BTCUSDT\",\"b\":\"79607.10\",\"B\":\"5.152\",\"a\":\"79607.20\",\"A\":\"6.546\",\"T\":1788563394234,\"E\":1788563394234,\"st\":1}}"}
{"receive_ns":1788563394204559000,"stream":"btcusdt@bookTicker","event_type":"bookTicker","event_time_ms":1788563394240,"raw_json":"{\"stream\":\"btcusdt@bookTicker\",\"data\":{\"e\":\"bookTicker\",\"u\":11478233337275,\"s\":\"BTCUSDT\",\"ps\":\"BTCUSDT\",\"b\":\"79607.10\",\"B\":\"5.152\",\"a\":\"79607.20\",\"A\":\"6.916\",\"T\":1788563394240,\"E\":1788563394240,\"st\":1}}"}
{"receive_ns":1788563394204728000,"stream":"btcusdt@bookTicker","event_type":"bookTicker","event_time_ms":1788563394242,"raw_json":"{\"stream\":\"btcusdt@bookTicker\",\"data\":{\"e\":\"bookTicker\",\"u\":11478233337384,\"s\":\"BTCUSDT\",\"ps\":\"BTCUSDT\",\"b\":\"79607.10\",\"B\":\"5.055\",\"a\":\"79607.20\",\"A\":\"6.916\",\"T\":1788563394241,\"E\":1788563394242,\"st\":1}}"}
{"receive_ns":1788563394209950000,"stream":"btcusdt@bookTicker","event_type":"bookTicker","event_time_ms":1788563394249,"raw_json":"{\"stream\":\"btcusdt@bookTicker\",\"data\":{\"e\":\"bookTicker\",\"u\":11478233337697,\"s\":\"BTCUSDT\",\"ps\":\"BTCUSDT\",\"b\":\"79607.10\",\"B\":\"5.059\",\"a\":\"79607.20\",\"A\":\"6.916\",\"T\":1788563394248,\"E\":1788563394249,\"st\":1}}"}
{"receive_ns":1788563394214698000,"stream":"btcusdt@bookTicker","event_type":"bookTicker","event_time_ms":1788563394254,"raw_json":"{\"stream\":\"btcusdt@bookTicker\",\"data\":{\"e\":\"bookTicker\",\"u\":11478233338128,\"s\":\"BTCUSDT\",\"ps\":\"BTCUSDT\",\"b\":\"79607.10\",\"B\":\"5.059\",\"a\":\"79607.20\",\"A\":\"7.051\",\"T\":1788563394254,\"E\":1788563394254,\"st\":1}}"}
{"receive_ns":1788563394237323000,"stream":"btcusdt@bookTicker","event_type":"bookTicker","event_time_ms":1788563394275,"raw_json":"{\"stream\":\"btcusdt@bookTicker\",\"data\":{\"e\":\"bookTicker\",\"u\":11478233338949,\"s\":\"BTCUSDT\",\"ps\":\"BTCUSDT\",\"b\":\"79607.10\",\"B\":\"4.406\",\"a\":\"79607.20\",\"A\":\"7.051\",\"T\":1788563394275,\"E\":1788563394275,\"st\":1}}"}
{"receive_ns":1788563394239788000,"stream":"btcusdt@bookTicker","event_type":"bookTicker","event_time_ms":1788563394280,"raw_json":"{\"stream\":\"btcusdt@bookTicker\",\"data\":{\"e\":\"bookTicker\",\"u\":11478233339294,\"s\":\"BTCUSDT\",\"ps\":\"BTCUSDT\",\"b\":\"79607.10\",\"B\":\"5.065\",\"a\":\"79607.20\",\"A\":\"7.051\",\"T\":1788563394280,\"E\":1788563394280,\"st\":1}}"}
{"receive_ns":1788563394241144000,"stream":"btcusdt@bookTicker","event_type":"bookTicker","event_time_ms":1788563394281,"raw_json":"{\"stream\":\"btcusdt@bookTicker\",\"data\":{\"e\":\"bookTicker\",\"u\":11478233339385,\"s\":\"BTCUSDT\",\"ps\":\"BTCUSDT\",\"b\":\"79607.10\",\"B\":\"5.063\",\"a\":\"79607.20\",\"A\":\"7.051\",\"T\":1788563394281,\"E\":1788563394281,\"st\":1}}"}
{"receive_ns":1788563394262742000,"stream":"btcusdt@bookTicker","event_type":"bookTicker","event_time_ms":1788563394304,"raw_json":"{\"stream\":\"btcusdt@bookTicker\",\"data\":{\"e\":\"bookTicker\",\"u\":11478233340734,\"s\":\"BTCUSDT\",\"ps\":\"BTCUSDT\",\"b\":\"79607.10\",\"B\":\"5.048\",\"a\":\"79607.20\",\"A\":\"7.051\",\"T\":1788563394303,\"E\":1788563394304,\"st\":1}}"}
{"receive_ns":1788563394264231000,"stream":"btcusdt@depth@100ms","event_type":"depthUpdate","event_time_ms":1788563394305,"raw_json":"{\"stream\":\"btcusdt@depth@100ms\",\"data\":{\"e\":\"depthUpdate\",\"E\":1788563394305,\"T\":1788563394303,\"s\":\"BTCUSDT\",\"ps\":\"BTCUSDT\",\"U\":11478233335480,\"u\":11478233340734,\"pu\":11478233335376,\"b\":[[\"1000.00\",\"24.754\"],[\"29407.10\",\"1.722\"],[\"29507.10\",\"0.378\"],[\"71646.30\",\"0.002\"],[\"74750.00\",\"1.430\"],[\"78015.00\",\"12.477\"],[\"78333.40\",\"6.550\"],[\"78811.00\",\"15.339\"],[\"79209.10\",\"4.608\"],[\"79232.90\",\"0.141\"],[\"79491.70\",\"0.583\"],[\"79523.80\",\"0.360\"],[\"79535.40\",\"0.002\"],[\"79559.30\",\"0.142\"],[\"79583.20\",\"0.779\"],[\"79583.80\",\"0.001\"],[\"79584.80\",\"0.256\"],[\"79588.90\",\"0.050\"],[\"79589.00\",\"0.062\"],[\"79589.50\",\"0.001\"],[\"79589.60\",\"0.024\"],[\"79597.10\",\"0.033\"],[\"79597.80\",\"0.001\"],[\"79600.90\",\"0.002\"],[\"79603.70\",\"0.037\"],[\"79603.80\",\"0.029\"],[\"79604.90\",\"0.000\"],[\"79605.00\",\"0.630\"],[\"79605.20\",\"0.002\"],[\"79605.30\",\"0.000\"],[\"79605.40\",\"0.027\"],[\"79606.60\",\"0.001\"],[\"79606.90\",\"0.235\"],[\"79607.00\",\"1.486\"],[\"79607.10\",\"5.048\"]],\"a\":[[\"79607.20\",\"7.051\"],[\"79618.90\",\"0.703\"],[\"79619.00\",\"0.194\"],[\"79619.20\",\"0.026\"],[\"79620.40\",\"0.000\"],[\"79630.50\",\"0.038\"],[\"79668.20\",\"2.949\"],[\"79670.90\",\"0.210\"],[\"79702.80\",\"0.010\"],[\"79726.70\",\"0.000\"],[\"79774.40\",\"2.254\"],[\"79968.00\",\"0.867\"],[\"79969.40\",\"1.160\"],[\"79997.80\",\"0.525\"],[\"80403.30\",\"21.693\"]],\"st\":1}}"}
{"receive_ns":1788563394266194000,"stream":"btcusdt@bookTicker","event_type":"bookTicker","event_time_ms":1788563394307,"raw_json":"{\"stream\":\"btcusdt@bookTicker\",\"data\":{\"e\":\"bookTicker\",\"u\":11478233340901,\"s\":\"BTCUSDT\",\"ps\":\"BTCUSDT\",\"b\":\"79607.10\",\"B\":\"5.063\",\"a\":\"79607.20\",\"A\":\"7.051\",\"T\":1788563394307,\"E\":1788563394307,\"st\":1}}"}
{"receive_ns":1788563394267472000,"stream":"btcusdt@bookTicker","event_type":"bookTicker","event_time_ms":1788563394308,"raw_json":"{\"stream\":\"btcusdt@bookTicker\",\"data\":{\"e\":\"bookTicker\",\"u\":11478233340954,\"s\":\"BTCUSDT\",\"ps\":\"BTCUSDT\",\"b\":\"79607.10\",\"B\":\"5.065\",\"a\":\"79607.20\",\"A\":\"7.051\",\"T\":1788563394308,\"E\":1788563394308,\"st\":1}}"}
{"receive_ns":1788563394342224000,"stream":"btcusdt@bookTicker","event_type":"bookTicker","event_time_ms":1788563394382,"raw_json":"{\"stream\":\"btcusdt@bookTicker\",\"data\":{\"e\":\"bookTicker\",\"u\":11478233344843,\"s\":\"BTCUSDT\",\"ps\":\"BTCUSDT\",\"b\":\"79607.10\",\"B\":\"3.863\",\"a\":\"79607.20\",\"A\":\"7.051\",\"T\":1788563394382,\"E\":1788563394382,\"st\":1}}"}
{"receive_ns":1788563394343307000,"stream":"btcusdt@bookTicker","event_type":"bookTicker","event_time_ms":1788563394383,"raw_json":"{\"stream\":\"btcusdt@bookTicker\",\"data\":{\"e\":\"bookTicker\",\"u\":11478233344969,\"s\":\"BTCUSDT\",\"ps\":\"BTCUSDT\",\"b\":\"79607.10\",\"B\":\"3.960\",\"a\":\"79607.20\",\"A\":\"7.051\",\"T\":1788563394383,\"E\":1788563394383,\"st\":1}}"}
{"receive_ns":1788563394344219000,"stream":"btcusdt@bookTicker","event_type":"bookTicker","event_time_ms":1788563394384,"raw_json":"{\"stream\":\"btcusdt@bookTicker\",\"data\":{\"e\":\"bookTicker\",\"u\":11478233345086,\"s\":\"BTCUSDT\",\"ps\":\"BTCUSDT\",\"b\":\"79607.10\",\"B\":\"3.958\",\"a\":\"79607.20\",\"A\":\"7.051\",\"T\":1788563394384,\"E\":1788563394384,\"st\":1}}"}
{"receive_ns":1788563394352094000,"stream":"btcusdt@bookTicker","event_type":"bookTicker","event_time_ms":1788563394391,"raw_json":"{\"stream\":\"btcusdt@bookTicker\",\"data\":{\"e\":\"bookTicker\",\"u\":11478233345468,\"s\":\"BTCUSDT\",\"ps\":\"BTCUSDT\",\"b\":\"79607.10\",\"B\":\"5.187\",\"a\":\"79607.20\",\"A\":\"7.051\",\"T\":1788563394391,\"E\":1788563394391,\"st\":1}}"}
{"receive_ns":1788563394352458000,"stream":"btcusdt@bookTicker","event_type":"bookTicker","event_time_ms":1788563394392,"raw_json":"{\"stream\":\"btcusdt@bookTicker\",\"data\":{\"e\":\"bookTicker\",\"u\":11478233345499,\"s\":\"BTCUSDT\",\"ps\":\"BTCUSDT\",\"b\":\"79607.10\",\"B\":\"5.186\",\"a\":\"79607.20\",\"A\":\"7.051\",\"T\":1788563394392,\"E\":1788563394392,\"st\":1}}"}
{"receive_ns":1788563394352608000,"stream":"btcusdt@bookTicker","event_type":"bookTicker","event_time_ms":1788563394392,"raw_json":"{\"stream\":\"btcusdt@bookTicker\",\"data\":{\"e\":\"bookTicker\",\"u\":11478233345500,\"s\":\"BTCUSDT\",\"ps\":\"BTCUSDT\",\"b\":\"79607.10\",\"B\":\"5.187\",\"a\":\"79607.20\",\"A\":\"7.051\",\"T\":1788563394392,\"E\":1788563394392,\"st\":1}}"}
{"receive_ns":1788563394352735000,"stream":"btcusdt@bookTicker","event_type":"bookTicker","event_time_ms":1788563394392,"raw_json":"{\"stream\":\"btcusdt@bookTicker\",\"data\":{\"e\":\"bookTicker\",\"u\":11478233345508,\"s\":\"BTCUSDT\",\"ps\":\"BTCUSDT\",\"b\":\"79607.10\",\"B\":\"5.189\",\"a\":\"79607.20\",\"A\":\"7.051\",\"T\":1788563394392,\"E\":1788563394392,\"st\":1}}"}
{"receive_ns":1788563394366360000,"stream":"btcusdt@bookTicker","event_type":"bookTicker","event_time_ms":1788563394406,"raw_json":"{\"stream\":\"btcusdt@bookTicker\",\"data\":{\"e\":\"bookTicker\",\"u\":11478233346109,\"s\":\"BTCUSDT\",\"ps\":\"BTCUSDT\",\"b\":\"79607.10\",\"B\":\"4.689\",\"a\":\"79607.20\",\"A\":\"7.051\",\"T\":1788563394406,\"E\":1788563394406,\"st\":1}}"}
{"receive_ns":1788563394374308000,"stream":"btcusdt@depth@100ms","event_type":"depthUpdate","event_time_ms":1788563394407,"raw_json":"{\"stream\":\"btcusdt@depth@100ms\",\"data\":{\"e\":\"depthUpdate\",\"E\":1788563394407,\"T\":1788563394406,\"s\":\"BTCUSDT\",\"ps\":\"BTCUSDT\",\"U\":11478233340810,\"u\":11478233346109,\"pu\":11478233340734,\"b\":[[\"1000.00\",\"24.754\"],[\"29307.10\",\"0.049\"],[\"29407.10\",\"1.806\"],[\"29507.10\",\"0.245\"],[\"71646.30\",\"0.002\"],[\"76422.80\",\"0.000\"],[\"77616.90\",\"1.031\"],[\"78811.00\",\"15.338\"],[\"79529.40\",\"0.001\"],[\"79565.30\",\"0.198\"],[\"79587.90\",\"0.019\"],[\"79588.10\",\"2.330\"],[\"79595.90\",\"0.004\"],[\"79600.90\",\"0.002\"],[\"79604.90\",\"0.026\"],[\"79605.40\",\"0.001\"],[\"79605.50\",\"0.002\"],[\"79605.60\",\"0.052\"],[\"79606.00\",\"0.036\"],[\"79606.30\",\"0.067\"],[\"79606.90\",\"0.199\"],[\"79607.00\",\"1.485\"],[\"79607.10\",\"4.689\"]],\"a\":[[\"79618.80\",\"0.443\"],[\"79618.90\",\"0.076\"],[\"79630.50\",\"0.665\"],[\"79669.70\",\"5.846\"],[\"79671.50\",\"25.072\"],[\"79671.80\",\"0.002\"],[\"79711.90\",\"0.000\"],[\"80403.30\",\"21.693\"],[\"80482.90\",\"20.659\"],[\"81199.30\",\"14.234\"]],\"st\":1}}"}
{"receive_ns":1788563394374989000,"stream":"btcusdt@bookTicker","event_type":"bookTicker","event_time_ms":1788563394409,"raw_json":"{\"stream\":\"btcusdt@bookTicker\",\"data\":{\"e\":\"bookTicker\",\"u\":11478233346275,\"s\":\"BTCUSDT\",\"ps\":\"BTCUSDT\",\"b\":\"79607.10\",\"B\":\"5.204\",\"a\":\"79607.20\",\"A\":\"7.051\",\"T\":1788563394409,\"E\":1788563394409,\"st\":1}}"}
{"receive_ns":1788563394375318000,"stream":"btcusdt@bookTicker","event_type":"bookTicker","event_time_ms":1788563394410,"raw_json":"{\"stream\":\"btcusdt@bookTicker\",\"data\":{\"e\":\"bookTicker\",\"u\":11478233346323,\"s\":\"BTCUSDT\",\"ps\":\"BTCUSDT\",\"b\":\"79607.10\",\"B\":\"5.202\",\"a\":\"79607.20\",\"A\":\"7.051\",\"T\":1788563394410,\"E\":1788563394410,\"st\":1}}"}
{"receive_ns":1788563394474316000,"stream":"btcusdt@depth@100ms","event_type":"depthUpdate","event_time_ms":1788563394509,"raw_json":"{\"stream\":\"btcusdt@depth@100ms\",\"data\":{\"e\":\"depthUpdate\",\"E\":1788563394509,\"T\":1788563394505,\"s\":\"BTCUSDT\",\"ps\":\"BTCUSDT\",\"U\":11478233346174,\"u\":11478233349889,\"pu\":11478233346109,\"b\":[[\"29307.10\",\"0.112\"],[\"29407.10\",\"1.855\"],[\"29507.10\",\"0.133\"],[\"71646.30\",\"0.002\"],[\"71684.00\",\"0.000\"],[\"76422.80\",\"0.002\"],[\"78811.00\",\"15.338\"],[\"79209.10\",\"4.608\"],[\"79232.90\",\"0.141\"],[\"79491.70\",\"0.583\"],[\"79524.00\",\"0.002\"],[\"79573.90\",\"0.454\"],[\"79574.90\",\"0.022\"],[\"79578.50\",\"0.004\"],[\"79581.30\",\"0.007\"],[\"79583.20\",\"0.277\"],[\"79583.80\",\"0.001\"],[\"79594.90\",\"0.170\"],[\"79598.20\",\"0.001\"],[\"79600.90\",\"0.002\"],[\"79603.70\",\"0.011\"],[\"79605.50\",\"0.028\"],[\"79605.60\",\"0.026\"],[\"79606.00\",\"0.036\"],[\"79606.20\",\"0.004\"],[\"79606.90\",\"0.198\"],[\"79607.10\",\"5.202\"]],\"a\":[[\"79616.00\",\"0.020\"],[\"79618.30\",\"0.440\"],[\"79623.50\",\"0.001\"],[\"79624.50\",\"0.931\"],[\"79625.50\",\"0.006\"],[\"79772.40\",\"0.255\"],[\"79774.40\",\"2.254\"],[\"79968.00\",\"0.867\"],[\"79969.40\",\"0.909\"],[\"79997.80\",\"0.525\"],[\"80005.30\",\"0.001\"],[\"80353.50\",\"2.046\"],[\"80403.30\",\"21.693\"],[\"80602.30\",\"12.729\"],[\"81183.40\",\"0.617\"]],\"st\":1}}"}
{"receive_ns":1788563394514817000,"stream":"btcusdt@bookTicker","event_type":"bookTicker","event_time_ms":1788563394555,"raw_json":"{\"stream\":\"btcusdt@bookTicker\",\"data\":{\"e\":\"bookTicker\",\"u\":11478233352163,\"s\":\"BTCUSDT\",\"ps\":\"BTCUSDT\",\"b\":\"79607.10\",\"B\":\"4.754\",\"a\":\"79607.20\",\"A\":\"7.051\",\"T\":1788563394554,\"E\":1788563394555,\"st\":1}}"}
{"receive_ns":1788563394515884000,"stream":"btcusdt@bookTicker","event_type":"bookTicker","event_time_ms":1788563394556,"raw_json":"{\"stream\":\"btcusdt@bookTicker\",\"data\":{\"e\":\"bookTicker\",\"u\":11478233352226,\"s\":\"BTCUSDT\",\"ps\":\"BTCUSDT\",\"b\":\"79607.10\",\"B\":\"4.756\",\"a\":\"79607.20\",\"A\":\"7.051\",\"T\":1788563394556,\"E\":1788563394556,\"st\":1}}"}
{"receive_ns":1788563394518894000,"stream":"btcusdt@bookTicker","event_type":"bookTicker","event_time_ms":1788563394559,"raw_json":"{\"stream\":\"btcusdt@bookTicker\",\"data\":{\"e\":\"bookTicker\",\"u\":11478233352415,\"s\":\"BTCUSDT\",\"ps\":\"BTCUSDT\",\"b\":\"79607.10\",\"B\":\"5.203\",\"a\":\"79607.20\",\"A\":\"7.051\",\"T\":1788563394559,\"E\":1788563394559,\"st\":1}}"}
{"receive_ns":1788563394519776000,"stream":"btcusdt@bookTicker","event_type":"bookTicker","event_time_ms":1788563394561,"raw_json":"{\"stream\":\"btcusdt@bookTicker\",\"data\":{\"e\":\"bookTicker\",\"u\":11478233352472,\"s\":\"BTCUSDT\",\"ps\":\"BTCUSDT\",\"b\":\"79607.10\",\"B\":\"5.201\",\"a\":\"79607.20\",\"A\":\"7.051\",\"T\":1788563394561,\"E\":1788563394561,\"st\":1}}"}
{"receive_ns":1788563394571797000,"stream":"btcusdt@depth@100ms","event_type":"depthUpdate","event_time_ms":1788563394611,"raw_json":"{\"stream\":\"btcusdt@depth@100ms\",\"data\":{\"e\":\"depthUpdate\",\"E\":1788563394611,\"T\":1788563394610,\"s\":\"BTCUSDT\",\"ps\":\"BTCUSDT\",\"U\":11478233350003,\"u\":11478233354239,\"pu\":11478233349889,\"b\":[[\"1000.00\",\"24.754\"],[\"29307.10\",\"0.175\"],[\"29407.10\",\"1.911\"],[\"29507.10\",\"0.014\"],[\"63686.00\",\"0.000\"],[\"71646.30\",\"0.002\"],[\"75626.70\",\"0.025\"],[\"76422.80\",\"0.000\"],[\"78500.00\",\"85.006\"],[\"78572.20\",\"31.576\"],[\"78811.00\",\"15.338\"],[\"79209.00\",\"0.002\"],[\"79523.80\",\"0.485\"],[\"79573.90\",\"0.002\"],[\"79574.70\",\"0.455\"],[\"79575.90\",\"0.001\"],[\"79587.20\",\"0.029\"],[\"79587.90\",\"0.003\"],[\"79598.20\",\"0.001\"],[\"79600.90\",\"0.002\"],[\"79605.10\",\"0.026\"],[\"79605.50\",\"0.002\"],[\"79607.10\",\"5.201\"]],\"a\":[[\"79624.50\",\"0.479\"],[\"79625.50\",\"0.458\"],[\"79680.60\",\"0.014\"],[\"79689.50\",\"0.001\"],[\"80244.10\",\"8.619\"],[\"80403.30\",\"21.693\"],[\"80598.60\",\"11.745\"]],\"st\":1}}"}
{"receive_ns":1788563394598889000,"stream":"btcusdt@bookTicker","event_type":"bookTicker","event_time_ms":1788563394638,"raw_json":"{\"stream\":\"btcusdt@bookTicker\",\"data\":{\"e\":\"bookTicker\",\"u\":11478233355308,\"s\":\"BTCUSDT\",\"ps\":\"BTCUSDT\",\"b\":\"79607.10\",\"B\":\"5.184\",\"a\":\"79607.20\",\"A\":\"7.051\",\"T\":1788563394638,\"E\":1788563394638,\"st\":1}}"}
{"receive_ns":1788563394600975000,"stream":"btcusdt@bookTicker","event_type":"bookTicker","event_time_ms":1788563394641,"raw_json":"{\"stream\":\"btcusdt@bookTicker\",\"data\":{\"e\":\"bookTicker\",\"u\":11478233355465,\"s\":\"BTCUSDT\",\"ps\":\"BTCUSDT\",\"b\":\"79607.10\",\"B\":\"5.200\",\"a\":\"79607.20\",\"A\":\"7.051\",\"T\":1788563394641,\"E\":1788563394641,\"st\":1}}"}
{"receive_ns":1788563394602185000,"stream":"btcusdt@bookTicker","event_type":"bookTicker","event_time_ms":1788563394642,"raw_json":"{\"stream\":\"btcusdt@bookTicker\",\"data\":{\"e\":\"bookTicker\",\"u\":11478233355528,\"s\":\"BTCUSDT\",\"ps\":\"BTCUSDT\",\"b\":\"79607.10\",\"B\":\"5.202\",\"a\":\"79607.20\",\"A\":\"7.051\",\"T\":1788563394642,\"E\":1788563394642,\"st\":1}}"}
{"receive_ns":1788563394672601000,"stream":"btcusdt@depth@100ms","event_type":"depthUpdate","event_time_ms":1788563394713,"raw_json":"{\"stream\":\"btcusdt@depth@100ms\",\"data\":{\"e\":\"depthUpdate\",\"E\":1788563394713,\"T\":1788563394710,\"s\":\"BTCUSDT\",\"ps\":\"BTCUSDT\",\"U\":11478233354302,\"u\":11478233358144,\"pu\":11478233354239,\"b\":[[\"1000.00\",\"24.754\"],[\"29307.10\",\"0.336\"],[\"29407.10\",\"1.764\"],[\"29507.10\",\"0.000\"],[\"63685.70\",\"0.001\"],[\"71646.30\",\"0.002\"],[\"75626.80\",\"0.002\"],[\"76422.80\",\"0.002\"],[\"78473.10\",\"0.612\"],[\"78811.00\",\"15.338\"],[\"79033.90\",\"0.190\"],[\"79232.90\",\"0.141\"],[\"79491.70\",\"0.583\"],[\"79523.80\",\"0.360\"],[\"79534.00\",\"0.948\"],[\"79549.90\",\"3.547\"],[\"79583.20\",\"0.779\"],[\"79583.80\",\"2.009\"],[\"79607.10\",\"5.202\"]],\"a\":[[\"79772.40\",\"0.255\"],[\"79774.40\",\"2.254\"],[\"79968.00\",\"0.867\"],[\"79969.40\",\"0.909\"],[\"79997.80\",\"0.525\"],[\"80100.20\",\"0.008\"],[\"80363.50\",\"16.367\"],[\"80403.30\",\"21.693\"],[\"80464.90\",\"0.002\"]],\"st\":1}}"}
{"receive_ns":1788563394776904000,"stream":"btcusdt@depth@100ms","event_type":"depthUpdate","event_time_ms":1788563394815,"raw_json":"{\"stream\":\"btcusdt@depth@100ms\",\"data\":{\"e\":\"depthUpdate\",\"E\":1788563394815,\"T\":1788563394814,\"s\":\"BTCUSDT\",\"ps\":\"BTCUSDT\",\"U\":11478233358277,\"u\":11478233362498,\"pu\":11478233358144,\"b\":[[\"29307.10\",\"0.518\"],[\"29407.10\",\"1.582\"],[\"71646.30\",\"0.002\"],[\"78811.00\",\"15.338\"],[\"79209.10\",\"4.598\"],[\"79523.80\",\"0.485\"],[\"79524.30\",\"0.001\"],[\"79583.40\",\"0.006\"],[\"79583.80\",\"0.001\"]],\"a\":[[\"79623.30\",\"0.458\"],[\"80403.30\",\"21.693\"],[\"80681.90\",\"11.776\"]],\"st\":1}}"}
{"receive_ns":1788563394788344000,"stream":"btcusdt@bookTicker","event_type":"bookTicker","event_time_ms":1788563394828,"raw_json":"{\"stream\":\"btcusdt@bookTicker\",\"data\":{\"e\":\"bookTicker\",\"u\":11478233363050,\"s\":\"BTCUSDT\",\"ps\":\"BTCUSDT\",\"b\":\"79607.10\",\"B\":\"5.202\",\"a\":\"79607.20\",\"A\":\"7.050\",\"T\":1788563394828,\"E\":1788563394828,\"st\":1}}"}
{"receive_ns":1788563394803137000,"stream":"btcusdt@bookTicker","event_type":"bookTicker","event_time_ms":1788563394843,"raw_json":"{\"stream\":\"btcusdt@bookTicker\",\"data\":{\"e\":\"bookTicker\",\"u\":11478233363960,\"s\":\"BTCUSDT\",\"ps\":\"BTCUSDT\",\"b\":\"79607.10\",\"B\":\"5.202\",\"a\":\"79607.20\",\"A\":\"7.048\",\"T\":1788563394843,\"E\":1788563394843,\"st\":1}}"}
{"receive_ns":1788563394876577000,"stream":"btcusdt@depth@100ms","event_type":"depthUpdate","event_time_ms":1788563394917,"raw_json":"{\"stream\":\"btcusdt@depth@100ms\",\"data\":{\"e\":\"depthUpdate\",\"E\":1788563394917,\"T\":1788563394916,\"s\":\"BTCUSDT\",\"ps\":\"BTCUSDT\",\"U\":11478233362605,\"u\":11478233367057,\"pu\":11478233362498,\"b\":[[\"1000.00\",\"24.754\"],[\"29307.10\",\"0.693\"],[\"29407.10\",\"1.407\"],[\"71646.30\",\"0.002\"],[\"76422.80\",\"0.000\"],[\"78324.50\",\"1.275\"],[\"78811.00\",\"15.338\"],[\"79396.10\",\"0.010\"],[\"79396.20\",\"2.784\"],[\"79443.90\",\"1.584\"],[\"79483.30\",\"0.387\"],[\"79491.70\",\"0.251\"],[\"79515.90\",\"0.001\"],[\"79516.00\",\"1.256\"]],\"a\":[[\"79607.20\",\"7.048\"],[\"79697.90\",\"0.003\"],[\"79728.80\",\"0.169\"],[\"79768.20\",\"0.650\"],[\"79772.40\",\"0.004\"],[\"79815.90\",\"1.735\"],[\"79969.40\",\"0.819\"],[\"79997.80\",\"0.000\"],[\"80403.30\",\"21.695\"],[\"80495.10\",\"0.000\"],[\"80528.60\",\"0.866\"],[\"80602.30\",\"12.915\"]],\"st\":1}}"}
{"receive_ns":1788563394936005000,"stream":"btcusdt@bookTicker","event_type":"bookTicker","event_time_ms":1788563394977,"raw_json":"{\"stream\":\"btcusdt@bookTicker\",\"data\":{\"e\":\"bookTicker\",\"u\":11478233369390,\"s\":\"BTCUSDT\",\"ps\":\"BTCUSDT\",\"b\":\"79607.10\",\"B\":\"5.187\",\"a\":\"79607.20\",\"A\":\"7.048\",\"T\":1788563394976,\"E\":1788563394977,\"st\":1}}"}
{"receive_ns":1788563394939737000,"stream":"btcusdt@bookTicker","event_type":"bookTicker","event_time_ms":1788563394980,"raw_json":"{\"stream\":\"btcusdt@bookTicker\",\"data\":{\"e\":\"bookTicker\",\"u\":11478233369520,\"s\":\"BTCUSDT\",\"ps\":\"BTCUSDT\",\"b\":\"79607.10\",\"B\":\"5.202\",\"a\":\"79607.20\",\"A\":\"7.048\",\"T\":1788563394980,\"E\":1788563394980,\"st\":1}}"}
{"receive_ns":1788563394977905000,"stream":"btcusdt@depth@100ms","event_type":"depthUpdate","event_time_ms":1788563395019,"raw_json":"{\"stream\":\"btcusdt@depth@100ms\",\"data\":{\"e\":\"depthUpdate\",\"E\":1788563395019,\"T\":1788563395017,\"s\":\"BTCUSDT\",\"ps\":\"BTCUSDT\",\"U\":11478233367061,\"u\":11478233371018,\"pu\":11478233367057,\"b\":[[\"1000.00\",\"24.754\"],[\"29307.10\",\"0.875\"],[\"29407.10\",\"1.225\"],[\"71646.30\",\"0.002\"],[\"76422.80\",\"0.002\"],[\"78811.00\",\"15.338\"],[\"79232.90\",\"0.141\"],[\"79462.10\",\"0.717\"],[\"79462.40\",\"17.618\"],[\"79464.00\",\"0.828\"],[\"79471.70\",\"0.042\"],[\"79483.30\",\"0.368\"],[\"79491.70\",\"0.583\"],[\"79511.50\",\"0.022\"],[\"79515.90\",\"4.709\"],[\"79535.40\",\"0.000\"],[\"79577.60\",\"0.006\"],[\"79581.30\",\"0.001\"],[\"79583.20\",\"0.277\"],[\"79583.80\",\"0.001\"],[\"79607.10\",\"5.202\"]],\"a\":[[\"79678.90\",\"0.015\"],[\"79697.90\",\"4.034\"],[\"79702.80\",\"0.008\"],[\"79728.80\",\"0.151\"],[\"79748.00\",\"2.506\"],[\"79751.40\",\"0.001\"],[\"79751.50\",\"17.555\"],[\"79774.40\",\"2.505\"],[\"79828.70\",\"7.905\"],[\"79968.00\",\"0.867\"],[\"79969.40\",\"0.865\"],[\"79995.30\",\"0.046\"],[\"79997.80\",\"0.525\"],[\"80403.30\",\"21.693\"],[\"80474.90\",\"8.488\"],[\"80562.50\",\"52.316\"],[\"83587.50\",\"0.045\"]],\"st\":1}}"}
{"receive_ns":1788563395021427000,"stream":"btcusdt@bookTicker","event_type":"bookTicker","event_time_ms":1788563395063,"raw_json":"{\"stream\":\"btcusdt@bookTicker\",\"data\":{\"e\":\"bookTicker\",\"u\":11478233372713,\"s\":\"BTCUSDT\",\"ps\":\"BTCUSDT\",\"b\":\"79607.10\",\"B\":\"4.755\",\"a\":\"79607.20\",\"A\":\"7.048\",\"T\":1788563395062,\"E\":1788563395063,\"st\":1}}"}
{"receive_ns":1788563395037241000,"stream":"btcusdt@bookTicker","event_type":"bookTicker","event_time_ms":1788563395070,"raw_json":"{\"stream\":\"btcusdt@bookTicker\",\"data\":{\"e\":\"bookTicker\",\"u\":11478233373508,\"s\":\"BTCUSDT\",\"ps\":\"BTCUSDT\",\"b\":\"79607.10\",\"B\":\"5.206\",\"a\":\"79607.20\",\"A\":\"7.048\",\"T\":1788563395069,\"E\":1788563395070,\"st\":1}}"}
{"receive_ns":1788563395038382000,"stream":"btcusdt@bookTicker","event_type":"bookTicker","event_time_ms":1788563395071,"raw_json":"{\"stream\":\"btcusdt@bookTicker\",\"data\":{\"e\":\"bookTicker\",\"u\":11478233373550,\"s\":\"BTCUSDT\",\"ps\":\"BTCUSDT\",\"b\":\"79607.10\",\"B\":\"5.204\",\"a\":\"79607.20\",\"A\":\"7.048\",\"T\":1788563395071,\"E\":1788563395071,\"st\":1}}"}
{"receive_ns":1788563395080015000,"stream":"btcusdt@depth@100ms","event_type":"depthUpdate","event_time_ms":1788563395121,"raw_json":"{\"stream\":\"btcusdt@depth@100ms\",\"data\":{\"e\":\"depthUpdate\",\"E\":1788563395121,\"T\":1788563395117,\"s\":\"BTCUSDT\",\"ps\":\"BTCUSDT\",\"U\":11478233371066,\"u\":11478233375579,\"pu\":11478233371018,\"b\":[[\"29307.10\",\"1.050\"],[\"29407.10\",\"1.050\"],[\"71646.30\",\"0.002\"],[\"76422.80\",\"0.000\"],[\"78015.00\",\"12.480\"],[\"78333.40\",\"7.825\"],[\"78811.00\",\"15.338\"],[\"79209.10\",\"4.608\"],[\"79396.20\",\"4.949\"],[\"79534.00\",\"0.119\"],[\"79549.90\",\"2.856\"],[\"79584.80\",\"0.277\"],[\"79587.20\",\"0.045\"],[\"79592.80\",\"0.004\"],[\"79594.70\",\"0.101\"],[\"79598.20\",\"0.001\"],[\"79600.90\",\"0.002\"],[\"79603.80\",\"0.003\"],[\"79604.00\",\"0.003\"],[\"79605.70\",\"0.164\"],[\"79606.10\",\"0.000\"],[\"79606.30\",\"0.067\"],[\"79606.90\",\"0.196\"],[\"79607.10\",\"5.204\"]],\"a\":[[\"79616.00\",\"0.020\"],[\"79618.30\",\"0.440\"],[\"79748.00\",\"5.427\"],[\"80204.30\",\"3.113\"],[\"80403.30\",\"21.693\"],[\"80538.60\",\"4.039\"],[\"80729.70\",\"4.329\"],[\"80761.50\",\"21.520\"],[\"80841.10\",\"9.516\"]],\"st\":1}}"}
{"receive_ns":1788563395135211000,"stream":"btcusdt@bookTicker","event_type":"bookTicker","event_time_ms":1788563395164,"raw_json":"{\"stream\":\"btcusdt@bookTicker\",\"data\":{\"e\":\"bookTicker\",\"u\":11478233377012,\"s\":\"BTCUSDT\",\"ps\":\"BTCUSDT\",\"b\":\"79607.10\",\"B\":\"4.640\",\"a\":\"79607.20\",\"A\":\"7.048\",\"T\":1788563395164,\"E\":1788563395164,\"st\":1}}"}
{"receive_ns":1788563395135540000,"stream":"btcusdt@bookTicker","event_type":"bookTicker","event_time_ms":1788563395165,"raw_json":"{\"stream\":\"btcusdt@bookTicker\",\"data\":{\"e\":\"bookTicker\",\"u\":11478233377084,\"s\":\"BTCUSDT\",\"ps\":\"BTCUSDT\",\"b\":\"79607.10\",\"B\":\"4.642\",\"a\":\"79607.20\",\"A\":\"7.048\",\"T\":1788563395165,\"E\":1788563395165,\"st\":1}}"}
{"receive_ns":1788563395135905000,"stream":"btcusdt@bookTicker","event_type":"bookTicker","event_time_ms":1788563395167,"raw_json":"{\"stream\":\"btcusdt@bookTicker\",\"data\":{\"e\":\"bookTicker\",\"u\":11478233377243,\"s\":\"BTCUSDT\",\"ps\":\"BTCUSDT\",\"b\":\"79607.10\",\"B\":\"5.213\",\"a\":\"79607.20\",\"A\":\"7.048\",\"T\":1788563395167,\"E\":1788563395167,\"st\":1}}"}
{"receive_ns":1788563395142085000,"stream":"btcusdt@bookTicker","event_type":"bookTicker","event_time_ms":1788563395183,"raw_json":"{\"stream\":\"btcusdt@bookTicker\",\"data\":{\"e\":\"bookTicker\",\"u\":11478233377964,\"s\":\"BTCUSDT\",\"ps\":\"BTCUSDT\",\"b\":\"79607.10\",\"B\":\"5.213\",\"a\":\"79607.20\",\"A\":\"7.022\",\"T\":1788563395183,\"E\":1788563395183,\"st\":1}}"}
{"receive_ns":1788563395183418000,"stream":"btcusdt@depth@100ms","event_type":"depthUpdate","event_time_ms":1788563395223,"raw_json":"{\"stream\":\"btcusdt@depth@100ms\",\"data\":{\"e\":\"depthUpdate\",\"E\":1788563395223,\"T\":1788563395221,\"s\":\"BTCUSDT\",\"ps\":\"BTCUSDT\",\"U\":11478233375678,\"u\":11478233379544,\"pu\":11478233375579,\"b\":[[\"1000.00\",\"24.754\"],[\"29307.10\",\"1.232\"],[\"29407.10\",\"0.868\"],[\"63686.00\",\"0.000\"],[\"71646.30\",\"0.002\"],[\"76422.80\",\"0.002\"],[\"78324.50\",\"0.000\"],[\"78552.90\",\"0.000\"],[\"78811.00\",\"15.338\"],[\"79232.90\",\"0.141\"],[\"79464.00\",\"3.482\"],[\"79476.40\",\"0.003\"],[\"79491.70\",\"0.000\"],[\"79493.70\",\"1.214\"],[\"79516.00\",\"2.539\"],[\"79583.20\",\"0.779\"],[\"79583.80\",\"0.001\"],[\"79594.90\",\"0.246\"],[\"79597.60\",\"0.002\"],[\"79600.50\",\"0.000\"],[\"79606.40\",\"0.028\"],[\"79606.70\",\"0.026\"],[\"79607.10\",\"5.213\"]],\"a\":[[\"79607.20\",\"7.022\"],[\"79616.00\",\"0.020\"],[\"79618.30\",\"0.440\"],[\"79677.70\",\"0.871\"],[\"79772.40\",\"0.506\"],[\"79774.40\",\"2.003\"],[\"79968.00\",\"0.867\"],[\"79969.40\",\"0.710\"],[\"79995.30\",\"0.002\"],[\"79997.80\",\"0.525\"],[\"80403.30\",\"21.693\"]],\"st\":1}}"}
{"receive_ns":1788563395183723000,"stream":"btcusdt@bookTicker","event_type":"bookTicker","event_time_ms":1788563395223,"raw_json":"{\"stream\":\"btcusdt@bookTicker\",\"data\":{\"e\":\"bookTicker\",\"u\":11478233379577,\"s\":\"BTCUSDT\",\"ps\":\"BTCUSDT\",\"b\":\"79607.10\",\"B\":\"5.214\",\"a\":\"79607.20\",\"A\":\"7.022\",\"T\":1788563395222,\"E\":1788563395223,\"st\":1}}"}
{"receive_ns":1788563395185212000,"stream":"btcusdt@trade","event_type":"trade","event_time_ms":1788563395227,"raw_json":"{\"stream\":\"btcusdt@trade\",\"data\":{\"e\":\"trade\",\"E\":1788563395227,\"T\":1788563395227,\"s\":\"BTCUSDT\",\"t\":8054083503,\"p\":\"79607.10\",\"q\":\"0.004\",\"X\":\"MARKET\",\"m\":true,\"st\":1}}"}
{"receive_ns":1788563395185386000,"stream":"btcusdt@trade","event_type":"trade","event_time_ms":1788563395227,"raw_json":"{\"stream\":\"btcusdt@trade\",\"data\":{\"e\":\"trade\",\"E\":1788563395227,\"T\":1788563395227,\"s\":\"BTCUSDT\",\"t\":8054083504,\"p\":\"79607.10\",\"q\":\"0.001\",\"X\":\"MARKET\",\"m\":true,\"st\":1}}"}
{"receive_ns":1788563395186572000,"stream":"btcusdt@bookTicker","event_type":"bookTicker","event_time_ms":1788563395227,"raw_json":"{\"stream\":\"btcusdt@bookTicker\",\"data\":{\"e\":\"bookTicker\",\"u\":11478233379722,\"s\":\"BTCUSDT\",\"ps\":\"BTCUSDT\",\"b\":\"79607.10\",\"B\":\"5.114\",\"a\":\"79607.20\",\"A\":\"7.022\",\"T\":1788563395227,\"E\":1788563395227,\"st\":1}}"}
{"receive_ns":1788563395186771000,"stream":"btcusdt@trade","event_type":"trade","event_time_ms":1788563395227,"raw_json":"{\"stream\":\"btcusdt@trade\",\"data\":{\"e\":\"trade\",\"E\":1788563395227,\"T\":1788563395227,\"s\":\"BTCUSDT\",\"t\":8054083505,\"p\":\"79607.10\",\"q\":\"0.004\",\"X\":\"MARKET\",\"m\":true,\"st\":1}}"}
{"receive_ns":1788563395186917000,"stream":"btcusdt@trade","event_type":"trade","event_time_ms":1788563395227,"raw_json":"{\"stream\":\"btcusdt@trade\",\"data\":{\"e\":\"trade\",\"E\":1788563395227,\"T\":1788563395227,\"s\":\"BTCUSDT\",\"t\":8054083506,\"p\":\"79607.10\",\"q\":\"0.091\",\"X\":\"MARKET\",\"m\":true,\"st\":1}}"}
{"receive_ns":1788563395187120000,"stream":"btcusdt@bookTicker","event_type":"bookTicker","event_time_ms":1788563395228,"raw_json":"{\"stream\":\"btcusdt@bookTicker\",\"data\":{\"e\":\"bookTicker\",\"u\":11478233379784,\"s\":\"BTCUSDT\",\"ps\":\"BTCUSDT\",\"b\":\"79607.10\",\"B\":\"5.114\",\"a\":\"79607.20\",\"A\":\"7.048\",\"T\":1788563395228,\"E\":1788563395228,\"st\":1}}"}
{"receive_ns":1788563395188017000,"stream":"btcusdt@bookTicker","event_type":"bookTicker","event_time_ms":1788563395229,"raw_json":"{\"stream\":\"btcusdt@bookTicker\",\"data\":{\"e\":\"bookTicker\",\"u\":11478233379904,\"s\":\"BTCUSDT\",\"ps\":\"BTCUSDT\",\"b\":\"79607.10\",\"B\":\"5.112\",\"a\":\"79607.20\",\"A\":\"7.048\",\"T\":1788563395229,\"E\":1788563395229,\"st\":1}}"}
{"receive_ns":1788563395285145000,"stream":"btcusdt@depth@100ms","event_type":"depthUpdate","event_time_ms":1788563395325,"raw_json":"{\"stream\":\"btcusdt@depth@100ms\",\"data\":{\"e\":\"depthUpdate\",\"E\":1788563395325,\"T\":1788563395322,\"s\":\"BTCUSDT\",\"ps\":\"BTCUSDT\",\"U\":11478233379577,\"u\":11478233383359,\"pu\":11478233379544,\"b\":[[\"29307.10\",\"1.407\"],[\"29407.10\",\"0.693\"],[\"71646.30\",\"0.002\"],[\"78333.40\",\"9.100\"],[\"78811.00\",\"15.338\"],[\"78887.10\",\"17.469\"],[\"79198.90\",\"0.090\"],[\"79237.10\",\"0.284\"],[\"79239.90\",\"0.350\"],[\"79285.70\",\"0.003\"],[\"79287.80\",\"0.377\"],[\"79334.30\",\"0.000\"],[\"79335.50\",\"0.481\"],[\"79382.90\",\"0.000\"],[\"79421.10\",\"3.140\"],[\"79431.50\",\"0.001\"],[\"79461.40\",\"0.000\"],[\"79461.50\",\"1.884\"],[\"79480.10\",\"0.000\"],[\"79483.50\",\"0.000\"],[\"79483.60\",\"0.003\"],[\"79519.40\",\"0.038\"],[\"79582.90\",\"0.076\"],[\"79583.20\",\"0.277\"],[\"79584.00\",\"0.091\"],[\"79592.10\",\"0.077\"],[\"79592.30\",\"0.001\"],[\"79593.40\",\"0.002\"],[\"79594.90\",\"0.170\"],[\"79597.60\",\"0.000\"],[\"79603.70\",\"0.037\"],[\"79603.80\",\"0.029\"],[\"79604.00\",\"0.029\"],[\"79604.10\",\"1.026\"],[\"79604.20\",\"0.027\"],[\"79604.90\",\"0.000\"],[\"79605.10\",\"0.000\"],[\"79605.20\",\"0.002\"],[\"79605.30\",\"0.026\"],[\"79605.50\",\"0.002\"],[\"79605.60\",\"0.026\"],[\"79605.70\",\"0.138\"],[\"79605.90\",\"0.000\"],[\"79606.40\",\"0.002\"],[\"79606.70\",\"0.000\"],[\"79607.10\",\"5.112\"]],\"a\":[[\"79607.20\",\"7.048\"],[\"79608.70\",\"0.278\"],[\"79664.20\",\"0.004\"],[\"79667.70\",\"0.000\"],[\"79694.60\",\"0.039\"],[\"79716.30\",\"0.165\"],[\"79729.80\",\"0.000\"],[\"79729.90\",\"1.884\"],[\"79748.10\",\"3.140\"],[\"79748.30\",\"0.000\"],[\"79764.90\",\"0.000\"],[\"79813.50\",\"0.503\"],[\"79860.20\",\"0.375\"],[\"79862.10\",\"0.002\"],[\"79910.70\",\"0.000\"],[\"79969.40\",\"0.909\"],[\"80403.30\",\"21.693\"],[\"80721.70\",\"57.288\"],[\"81040.10\",\"9.608\"],[\"81199.30\",\"14.231\"]],\"st\":1}}"}
{"receive_ns":1788563395373795000,"stream":"btcusdt@bookTicker","event_type":"bookTicker","event_time_ms":1788563395412,"raw_json":"{\"stream\":\"btcusdt@bookTicker\",\"data\":{\"e\":\"bookTicker\",\"u\":11478233386861,\"s\":\"BTCUSDT\",\"ps\":\"BTCUSDT\",\"b\":\"79607.10\",\"B\":\"4.597\",\"a\":\"79607.20\",\"A\":\"7.048\",\"T\":1788563395412,\"E\":1788563395412,\"st\":1}}"}
{"receive_ns":1788563395374108000,"stream":"btcusdt@bookTicker","event_type":"bookTicker","event_time_ms":1788563395414,"raw_json":"{\"stream\":\"btcusdt@bookTicker\",\"data\":{\"e\":\"bookTicker\",\"u\":11478233386966,\"s\":\"BTCUSDT\",\"ps\":\"BTCUSDT\",\"b\":\"79607.10\",\"B\":\"4.599\",\"a\":\"79607.20\",\"A\":\"7.048\",\"T\":1788563395414,\"E\":1788563395414,\"st\":1}}"}
{"receive_ns":1788563395374303000,"stream":"btcusdt@bookTicker","event_type":"bookTicker","event_time_ms":1788563395414,"raw_json":"{\"stream\":\"btcusdt@bookTicker\",\"data\":{\"e\":\"bookTicker\",\"u\":11478233386975,\"s\":\"BTCUSDT\",\"ps\":\"BTCUSDT\",\"b\":\"79607.10\",\"B\":\"4.599\",\"a\":\"79607.20\",\"A\":\"7.487\",\"T\":1788563395414,\"E\":1788563395414,\"st\":1}}"}
{"receive_ns":1788563395377024000,"stream":"btcusdt@bookTicker","event_type":"bookTicker","event_time_ms":1788563395416,"raw_json":"{\"stream\":\"btcusdt@bookTicker\",\"data\":{\"e\":\"bookTicker\",\"u\":11478233387070,\"s\":\"BTCUSDT\",\"ps\":\"BTCUSDT\",\"b\":\"79607.10\",\"B\":\"5.111\",\"a\":\"79607.20\",\"A\":\"7.487\",\"T\":1788563395416,\"E\":1788563395416,\"st\":1}}"}
{"receive_ns":1788563395393331000,"stream":"btcusdt@depth@100ms","event_type":"depthUpdate","event_time_ms":1788563395427,"raw_json":"{\"stream\":\"btcusdt@depth@100ms\",\"data\":{\"e\":\"depthUpdate\",\"E\":1788563395427,\"T\":1788563395425,\"s\":\"BTCUSDT\",\"ps\":\"BTCUSDT\",\"U\":11478233383446,\"u\":11478233387379,\"pu\":11478233383359,\"b\":[[\"29307.10\",\"1.589\"],[\"29407.10\",\"0.511\"],[\"63686.00\",\"0.000\"],[\"71646.30\",\"0.002\"],[\"75626.70\",\"0.027\"],[\"76422.80\",\"0.000\"],[\"78601.80\",\"0.044\"],[\"78715.50\",\"0.393\"],[\"78811.00\",\"15.338\"],[\"79209.10\",\"4.608\"],[\"79232.90\",\"0.000\"],[\"79483.30\",\"0.001\"],[\"79493.70\",\"0.631\"],[\"79582.90\",\"0.704\"],[\"79583.20\",\"0.002\"],[\"79583.90\",\"0.060\"],[\"79592.10\",\"0.077\"],[\"79603.60\",\"1.545\"],[\"79604.60\",\"0.000\"],[\"79605.20\",\"0.028\"],[\"79605.30\",\"0.000\"],[\"79607.10\",\"5.111\"]],\"a\":[[\"79607.20\",\"7.487\"],[\"79608.50\",\"0.002\"],[\"79610.70\",\"0.004\"],[\"79728.80\",\"0.000\"],[\"79772.40\",\"0.004\"],[\"79968.00\",\"0.104\"],[\"79969.40\",\"0.001\"],[\"79997.80\",\"0.000\"],[\"80204.30\",\"3.735\"],[\"80403.30\",\"22.314\"],[\"83486.20\",\"0.000\"],[\"87568.00\",\"0.000\"]],\"st\":1}}"}
{"receive_ns":1788563395488156000,"stream":"btcusdt@depth@100ms","event_type":"depthUpdate","event_time_ms":1788563395529,"raw_json":"{\"stream\":\"btcusdt@depth@100ms\",\"data\":{\"e\":\"depthUpdate\",\"E\":1788563395529,\"T\":1788563395526,\"s\":\"BTCUSDT\",\"ps\":\"BTCUSDT\",\"U\":11478233387455,\"u\":11478233394002,\"pu\":11478233387379,\"b\":[[\"1000.00\",\"24.754\"],[\"29207.10\",\"0.007\"],[\"29307.10\",\"1.750\"],[\"29407.10\",\"0.343\"],[\"71646.30\",\"0.002\"],[\"76422.80\",\"0.002\"],[\"78811.00\",\"15.338\"],[\"78970.20\",\"9.011\"],[\"79209.00\",\"0.000\"],[\"79232.90\",\"0.141\"],[\"79462.60\",\"0.013\"],[\"79466.20\",\"0.002\"],[\"79483.40\",\"0.000\"],[\"79491.70\",\"1.085\"],[\"79492.30\",\"2.039\"],[\"79502.40\",\"0.014\"],[\"79506.00\",\"0.003\"],[\"79523.80\",\"0.360\"],[\"79524.10\",\"1.321\"],[\"79535.50\",\"0.275\"],[\"79542.20\",\"0.002\"],[\"79545.80\",\"0.003\"],[\"79577.60\",\"0.000\"],[\"79581.90\",\"0.067\"],[\"79582.00\",\"0.004\"],[\"79585.60\",\"0.335\"],[\"79592.10\",\"0.001\"],[\"79592.30\",\"0.077\"],[\"79597.30\",\"0.053\"],[\"79605.20\",\"0.028\"],[\"79605.50\",\"0.028\"],[\"79606.90\",\"0.198\"]],\"a\":[[\"79665.00\",\"0.003\"],[\"79668.60\",\"0.605\"],[\"79704.90\",\"0.005\"],[\"79708.50\",\"0.002\"],[\"79728.80\",\"0.000\"],[\"79744.80\",\"0.000\"],[\"79748.40\",\"0.003\"],[\"79774.40\",\"2.505\"],[\"79828.70\",\"7.918\"],[\"79968.00\",\"0.867\"],[\"79969.40\",\"0.909\"],[\"79997.80\",\"0.525\"],[\"80403.30\",\"22.314\"]],\"st\":1}}"}
{"receive_ns":1788563395574091000,"stream":"btcusdt@bookTicker","event_type":"bookTicker","event_time_ms":1788563395614,"raw_json":"{\"stream\":\"btcusdt@bookTicker\",\"data\":{\"e\":\"bookTicker\",\"u\":11478233397929,\"s\":\"BTCUSDT\",\"ps\":\"BTCUSDT\",\"b\":\"79607.10\",\"B\":\"4.660\",\"a\":\"79607.20\",\"A\":\"7.487\",\"T\":1788563395613,\"E\":1788563395614,\"st\":1}}"}
{"receive_ns":1788563395574401000,"stream":"btcusdt@bookTicker","event_type":"bookTicker","event_time_ms":1788563395615,"raw_json":"{\"stream\":\"btcusdt@bookTicker\",\"data\":{\"e\":\"bookTicker\",\"u\":11478233397963,\"s\":\"BTCUSDT\",\"ps\":\"BTCUSDT\",\"b\":\"79607.10\",\"B\":\"4.659\",\"a\":\"79607.20\",\"A\":\"7.487\",\"T\":1788563395615,\"E\":1788563395615,\"st\":1}}"}
{"receive_ns":1788563395574565000,"stream":"btcusdt@bookTicker","event_type":"bookTicker","event_time_ms":1788563395615,"raw_json":"{\"stream\":\"btcusdt@bookTicker\",\"data\":{\"e\":\"bookTicker\",\"u\":11478233397990,\"s\":\"BTCUSDT\",\"ps\":\"BTCUSDT\",\"b\":\"79607.10\",\"B\":\"4.657\",\"a\":\"79607.20\",\"A\":\"7.487\",\"T\":1788563395615,\"E\":1788563395615,\"st\":1}}"}
{"receive_ns":1788563395575123000,"stream":"btcusdt@bookTicker","event_type":"bookTicker","event_time_ms":1788563395616,"raw_json":"{\"stream\":\"btcusdt@bookTicker\",\"data\":{\"e\":\"bookTicker\",\"u\":11478233398047,\"s\":\"BTCUSDT\",\"ps\":\"BTCUSDT\",\"b\":\"79607.10\",\"B\":\"4.658\",\"a\":\"79607.20\",\"A\":\"7.487\",\"T\":1788563395616,\"E\":1788563395616,\"st\":1}}"}
{"receive_ns":1788563395584298000,"stream":"btcusdt@bookTicker","event_type":"bookTicker","event_time_ms":1788563395616,"raw_json":"{\"stream\":\"btcusdt@bookTicker\",\"data\":{\"e\":\"bookTicker\",\"u\":11478233398066,\"s\":\"BTCUSDT\",\"ps\":\"BTCUSDT\",\"b\":\"79607.10\",\"B\":\"5.107\",\"a\":\"79607.20\",\"A\":\"7.487\",\"T\":1788563395616,\"E\":1788563395616,\"st\":1}}"}
{"receive_ns":1788563395584528000,"stream":"btcusdt@bookTicker","event_type":"bookTicker","event_time_ms":1788563395617,"raw_json":"{\"stream\":\"btcusdt@bookTicker\",\"data\":{\"e\":\"bookTicker\",\"u\":11478233398140,\"s\":\"BTCUSDT\",\"ps\":\"BTCUSDT\",\"b\":\"79607.10\",\"B\":\"5.109\",\"a\":\"79607.20\",\"A\":\"7.487\",\"T\":1788563395617,\"E\":1788563395617,\"st\":1}}"}
{"receive_ns":1788563395590426000,"stream":"btcusdt@depth@100ms","event_type":"depthUpdate","event_time_ms":1788563395631,"raw_json":"{\"stream\":\"btcusdt@depth@100ms\",\"data\":{\"e\":\"depthUpdate\",\"E\":1788563395631,\"T\":1788563395630,\"s\":\"BTCUSDT\",\"ps\":\"BTCUSDT\",\"U\":11478233394316,\"u\":11478233398804,\"pu\":11478233394002,\"b\":[[\"29207.10\",\"0.063\"],[\"29307.10\",\"1.820\"],[\"29407.10\",\"0.217\"],[\"63686.00\",\"0.000\"],[\"71646.30\",\"0.002\"],[\"71684.00\",\"0.003\"],[\"76422.80\",\"0.000\"],[\"78085.70\",\"0.017\"],[\"78811.00\",\"15.338\"],[\"79209.10\",\"4.598\"],[\"79443.90\",\"0.000\"],[\"79492.30\",\"1.035\"],[\"79536.70\",\"1.544\"],[\"79598.20\",\"0.001\"],[\"79600.90\",\"0.002\"],[\"79607.10\",\"5.109\"]],\"a\":[[\"79675.70\",\"1.798\"],[\"79768.20\",\"0.000\"],[\"80005.30\",\"0.003\"],[\"80403.30\",\"22.314\"],[\"81149.40\",\"0.480\"]],\"st\":1}}"}
{"receive_ns":1788563395691566000,"stream":"btcusdt@depth@100ms","event_type":"depthUpdate","event_time_ms":1788563395733,"raw_json":"{\"stream\":\"btcusdt@depth@100ms\",\"data\":{\"e\":\"depthUpdate\",\"E\":1788563395733,\"T\":1788563395731,\"s\":\"BTCUSDT\",\"ps\":\"BTCUSDT\",\"U\":11478233398848,\"u\":11478233402359,\"pu\":11478233398804,\"b\":[[\"29207.10\",\"0.126\"],[\"29307.10\",\"1.869\"],[\"29407.10\",\"0.105\"],[\"63685.70\",\"0.001\"],[\"63686.00\",\"0.000\"],[\"71646.30\",\"0.002\"],[\"71684.00\",\"0.000\"],[\"78015.00\",\"12.483\"],[\"78165.30\",\"1.013\"],[\"78729.60\",\"3.925\"],[\"78811.00\",\"15.338\"],[\"79232.90\",\"0.141\"],[\"79444.00\",\"2.770\"],[\"79461.50\",\"1.884\"],[\"79483.40\",\"0.519\"],[\"79491.70\",\"0.583\"],[\"79492.30\",\"0.031\"],[\"79515.90\",\"0.001\"],[\"79516.00\",\"5.856\"],[\"79535.50\",\"0.502\"],[\"79573.90\",\"0.002\"],[\"79574.70\",\"0.455\"],[\"79575.20\",\"0.901\"],[\"79575.90\",\"0.001\"],[\"79583.20\",\"0.277\"],[\"79583.80\",\"0.001\"],[\"79592.30\",\"0.001\"],[\"79592.50\",\"0.001\"],[\"79603.60\",\"1.519\"],[\"79604.70\",\"0.027\"],[\"79604.80\",\"0.028\"],[\"79605.20\",\"0.002\"],[\"79605.40\",\"0.001\"],[\"79605.50\",\"0.002\"]],\"a\":[[\"79616.00\",\"0.020\"],[\"79618.30\",\"0.440\"],[\"79623.50\",\"0.001\"],[\"79624.50\",\"0.479\"],[\"79625.50\",\"0.458\"],[\"79728.80\",\"0.294\"],[\"79729.90\",\"1.884\"],[\"79768.20\",\"1.329\"],[\"79774.40\",\"2.505\"],[\"79968.00\",\"0.867\"],[\"79969.40\",\"0.865\"],[\"79995.30\",\"0.046\"],[\"79997.80\",\"0.525\"],[\"80176.80\",\"0.000\"],[\"80403.30\",\"22.314\"]],\"st\":1}}"}
{"receive_ns":1788563395714859000,"stream":"btcusdt@bookTicker","event_type":"bookTicker","event_time_ms":1788563395750,"raw_json":"{\"stream\":\"btcusdt@bookTicker\",\"data\":{\"e\":\"bookTicker\",\"u\":11478233403063,\"s\":\"BTCUSDT\",\"ps\":\"BTCUSDT\",\"b\":\"79607.10\",\"B\":\"5.122\",\"a\":\"79607.20\",\"A\":\"7.487\",\"T\":1788563395750,\"E\":1788563395750,\"st\":1}}"}
{"receive_ns":1788563395801475000,"stream":"btcusdt@depth@100ms","event_type":"depthUpdate","event_time_ms":1788563395835,"raw_json":"{\"stream\":\"btcusdt@depth@100ms\",\"data\":{\"e\":\"depthUpdate\",\"E\":1788563395835,\"T\":1788563395833,\"s\":\"BTCUSDT\",\"ps\":\"BTCUSDT\",\"U\":11478233402426,\"u\":11478233405511,\"pu\":11478233402359,\"b\":[[\"1000.00\",\"24.754\"],[\"29207.10\",\"0.203\"],[\"29307.10\",\"1.897\"],[\"29407.10\",\"0.000\"],[\"71646.30\",\"0.002\"],[\"76422.80\",\"0.002\"],[\"78601.80\",\"0.794\"],[\"78811.00\",\"15.338\"],[\"79516.00\",\"5.957\"],[\"79533.90\",\"23.397\"],[\"79549.80\",\"0.691\"],[\"79583.40\",\"0.006\"],[\"79592.10\",\"0.077\"],[\"79603.70\",\"0.011\"],[\"79605.00\",\"0.656\"],[\"79605.10\",\"0.026\"],[\"79607.10\",\"5.122\"]],\"a\":[[\"79623.30\",\"0.458\"],[\"80323.70\",\"23.344\"],[\"80403.30\",\"22.314\"],[\"81500.00\",\"37.445\"],[\"83485.90\",\"0.750\"]],\"st\":1}}"}
{"receive_ns":1788563395802441000,"stream":"btcusdt@bookTicker","event_type":"bookTicker","event_time_ms":1788563395844,"raw_json":"{\"stream\":\"btcusdt@bookTicker\",\"data\":{\"e\":\"bookTicker\",\"u\":11478233405848,\"s\":\"BTCUSDT\",\"ps\":\"BTCUSDT\",\"b\":\"79607.10\",\"B\":\"5.122\",\"a\":\"79607.20\",\"A\":\"7.494\",\"T\":1788563395843,\"E\":1788563395844,\"st\":1}}"}
{"receive_ns":1788563395895975000,"stream":"btcusdt@depth@100ms","event_type":"depthUpdate","event_time_ms":1788563395937,"raw_json":"{\"stream\":\"btcusdt@depth@100ms\",\"data\":{\"e\":\"depthUpdate\",\"E\":1788563395937,\"T\":1788563395934,\"s\":\"BTCUSDT\",\"ps\":\"BTCUSDT\",\"U\":11478233405563,\"u\":11478233409212,\"pu\":11478233405511,\"b\":[[\"29207.10\",\"0.378\"],[\"29307.10\",\"1.722\"],[\"71646.30\",\"0.002\"],[\"76422.80\",\"0.000\"],[\"78094.60\",\"1.789\"],[\"78690.80\",\"5.291\"],[\"78811.00\",\"15.338\"],[\"78870.50\",\"0.018\"],[\"79209.10\",\"4.608\"],[\"79232.90\",\"0.141\"],[\"79483.40\",\"0.000\"],[\"79491.70\",\"0.583\"],[\"79535.50\",\"0.000\"],[\"79583.20\",\"0.779\"],[\"79583.80\",\"2.009\"]],\"a\":[[\"79607.20\",\"7.494\"],[\"79728.80\",\"0.000\"],[\"79774.40\",\"2.254\"],[\"79968.00\",\"0.867\"],[\"79969.40\",\"0.917\"],[\"79995.30\",\"0.046\"],[\"79997.80\",\"0.525\"],[\"80403.30\",\"22.314\"],[\"80498.30\",\"1.416\"]],\"st\":1}}"}
{"receive_ns":1788563395998655000,"stream":"btcusdt@depth@100ms","event_type":"depthUpdate","event_time_ms":1788563396039,"raw_json":"{\"stream\":\"btcusdt@depth@100ms\",\"data\":{\"e\":\"depthUpdate\",\"E\":1788563396039,\"T\":1788563396037,\"s\":\"BTCUSDT\",\"ps\":\"BTCUSDT\",\"U\":11478233409298,\"u\":11478233412643,\"pu\":11478233409212,\"b\":[[\"29207.10\",\"0.560\"],[\"29307.10\",\"1.540\"],[\"63686.00\",\"0.000\"],[\"71646.30\",\"0.002\"],[\"76422.80\",\"0.002\"],[\"78174.20\",\"1.636\"],[\"78612.00\",\"16.707\"],[\"78739.40\",\"7.283\"],[\"78811.00\",\"15.338\"],[\"79444.00\",\"2.699\"],[\"79483.40\",\"0.519\"],[\"79516.00\",\"4.573\"],[\"79522.40\",\"0.125\"],[\"79524.10\",\"1.196\"],[\"79581.90\",\"0.061\"],[\"79583.80\",\"0.001\"],[\"79592.80\",\"0.008\"]],\"a\":[[\"79674.50\",\"2.899\"],[\"79676.90\",\"0.205\"],[\"79704.20\",\"0.003\"],[\"79707.50\",\"0.001\"],[\"79728.80\",\"0.294\"],[\"79768.20\",\"1.284\"],[\"79969.40\",\"1.116\"],[\"80403.30\",\"22.314\"]],\"st\":1}}"}
{"receive_ns":1788563396005622000,"stream":"btcusdt@bookTicker","event_type":"bookTicker","event_time_ms":1788563396046,"raw_json":"{\"stream\":\"btcusdt@bookTicker\",\"data\":{\"e\":\"bookTicker\",\"u\":11478233412895,\"s\":\"BTCUSDT\",\"ps\":\"BTCUSDT\",\"b\":\"79607.10\",\"B\":\"5.107\",\"a\":\"79607.20\",\"A\":\"7.494\",\"T\":1788563396046,\"E\":1788563396046,\"st\":1}}"}
{"receive_ns":1788563396006026000,"stream":"btcusdt@bookTicker","event_type":"bookTicker","event_time_ms":1788563396046,"raw_json":"{\"stream\":\"btcusdt@bookTicker\",\"data\":{\"e\":\"bookTicker\",\"u\":11478233412912,\"s\":\"BTCUSDT\",\"ps\":\"BTCUSDT\",\"b\":\"79607.10\",\"B\":\"5.101\",\"a\":\"79607.20\",\"A\":\"7.494\",\"T\":1788563396046,\"E\":1788563396046,\"st\":1}}"}
{"receive_ns":1788563396014199000,"stream":"btcusdt@trade","event_type":"trade","event_time_ms":1788563396046,"raw_json":"{\"stream\":\"btcusdt@trade\",\"data\":{\"e\":\"trade\",\"E\":1788563396046,\"T\":1788563396046,\"s\":\"BTCUSDT\",\"t\":8054083507,\"p\":\"79607.10\",\"q\":\"0.006\",\"X\":\"MARKET\",\"m\":true,\"st\":1}}"}
{"receive_ns":1788563396014462000,"stream":"btcusdt@bookTicker","event_type":"bookTicker","event_time_ms":1788563396049,"raw_json":"{\"stream\":\"btcusdt@bookTicker\",\"data\":{\"e\":\"bookTicker\",\"u\":11478233413116,\"s\":\"BTCUSDT\",\"ps\":\"BTCUSDT\",\"b\":\"79607.10\",\"B\":\"5.116\",\"a\":\"79607.20\",\"A\":\"7.494\",\"T\":1788563396049,\"E\":1788563396049,\"st\":1}}"}
{"receive_ns":1788563396078636000,"stream":"btcusdt@bookTicker","event_type":"bookTicker","event_time_ms":1788563396119,"raw_json":"{\"stream\":\"btcusdt@bookTicker\",\"data\":{\"e\":\"bookTicker\",\"u\":11478233415350,\"s\":\"BTCUSDT\",\"ps\":\"BTCUSDT\",\"b\":\"79607.10\",\"B\":\"4.667\",\"a\":\"79607.20\",\"A\":\"7.494\",\"T\":1788563396119,\"E\":1788563396119,\"st\":1}}"}
{"receive_ns":1788563396081950000,"stream":"btcusdt@bookTicker","event_type":"bookTicker","event_time_ms":1788563396122,"raw_json":"{\"stream\":\"btcusdt@bookTicker\",\"data\":{\"e\":\"bookTicker\",\"u\":11478233415459,\"s\":\"BTCUSDT\",\"ps\":\"BTCUSDT\",\"b\":\"79607.10\",\"B\":\"5.117\",\"a\":\"79607.20\",\"A\":\"7.494\",\"T\":1788563396122,\"E\":1788563396122,\"st\":1}}"}
{"receive_ns":1788563396082253000,"stream":"btcusdt@bookTicker","event_type":"bookTicker","event_time_ms":1788563396123,"raw_json":"{\"stream\":\"btcusdt@bookTicker\",\"data\":{\"e\":\"bookTicker\",\"u\":11478233415496,\"s\":\"BTCUSDT\",\"ps\":\"BTCUSDT\",\"b\":\"79607.10\",\"B\":\"5.115\",\"a\":\"79607.20\",\"A\":\"7.494\",\"T\":1788563396123,\"E\":1788563396123,\"st\":1}}"}
{"receive_ns":1788563396100146000,"stream":"btcusdt@depth@100ms","event_type":"depthUpdate","event_time_ms":1788563396141,"raw_json":"{\"stream\":\"btcusdt@depth@100ms\",\"data\":{\"e\":\"depthUpdate\",\"E\":1788563396141,\"T\":1788563396137,\"s\":\"BTCUSDT\",\"ps\":\"BTCUSDT\",\"U\":11478233412693,\"u\":11478233415874,\"pu\":11478233412643,\"b\":[[\"1000.00\",\"24.754\"],[\"29207.10\",\"0.735\"],[\"29307.10\",\"1.365\"],[\"63686.00\",\"0.000\"],[\"71646.30\",\"0.002\"],[\"76422.80\",\"0.000\"],[\"77616.90\",\"1.481\"],[\"78404.10\",\"1.274\"],[\"78528.70\",\"4.944\"],[\"78811.00\",\"15.338\"],[\"79488.10\",\"1.545\"],[\"79533.90\",\"22.568\"],[\"79549.80\",\"0.000\"],[\"79592.80\",\"0.004\"],[\"79597.80\",\"0.001\"],[\"79600.90\",\"0.002\"],[\"79603.80\",\"0.003\"],[\"79605.60\",\"0.026\"],[\"79607.10\",\"5.115\"]],\"a\":[[\"79656.50\",\"0.059\"],[\"79656.60\",\"1.381\"],[\"79705.00\",\"0.003\"],[\"79705.30\",\"0.000\"],[\"79705.40\",\"0.001\"],[\"79705.50\",\"8.626\"],[\"79724.30\",\"1.566\"],[\"80403.30\",\"22.314\"]],\"st\":1}}"}
{"receive_ns":1788563396104115000,"stream":"btcusdt@bookTicker","event_type":"bookTicker","event_time_ms":1788563396144,"raw_json":"{\"stream\":\"btcusdt@bookTicker\",\"data\":{\"e\":\"bookTicker\",\"u\":11478233416113,\"s\":\"BTCUSDT\",\"ps\":\"BTCUSDT\",\"b\":\"79607.10\",\"B\":\"5.115\",\"a\":\"79607.20\",\"A\":\"7.495\",\"T\":1788563396144,\"E\":1788563396144,\"st\":1}}"}
{"receive_ns":1788563396202529000,"stream":"btcusdt@depth@100ms","event_type":"depthUpdate","event_time_ms":1788563396243,"raw_json":"{\"stream\":\"btcusdt@depth@100ms\",\"data\":{\"e\":\"depthUpdate\",\"E\":1788563396243,\"T\":1788563396240,\"s\":\"BTCUSDT\",\"ps\":\"BTCUSDT\",\"U\":11478233415993,\"u\":11478233419201,\"pu\":11478233415874,\"b\":[[\"29207.10\",\"0.910\"],[\"29307.10\",\"1.190\"],[\"71646.30\",\"0.002\"],[\"78811.00\",\"15.338\"],[\"79209.10\",\"4.598\"],[\"79232.90\",\"0.141\"],[\"79471.70\",\"0.040\"],[\"79491.70\",\"0.583\"],[\"79515.80\",\"0.581\"],[\"79535.40\",\"0.002\"],[\"79583.20\",\"0.779\"],[\"79583.80\",\"0.001\"]],\"a\":[[\"79607.20\",\"7.495\"],[\"79664.20\",\"0.540\"],[\"79678.90\",\"0.015\"],[\"79705.60\",\"0.140\"],[\"79774.40\",\"2.254\"],[\"79968.00\",\"0.867\"],[\"79969.40\",\"1.116\"],[\"79995.30\",\"0.046\"],[\"79997.80\",\"0.525\"],[\"80320.10\",\"8.052\"],[\"80403.30\",\"22.314\"],[\"81199.30\",\"14.228\"]],\"st\":1}}"}
{"receive_ns":1788563396204478000,"stream":"btcusdt@bookTicker","event_type":"bookTicker","event_time_ms":1788563396245,"raw_json":"{\"stream\":\"btcusdt@bookTicker\",\"data\":{\"e\":\"bookTicker\",\"u\":11478233419301,\"s\":\"BTCUSDT\",\"ps\":\"BTCUSDT\",\"b\":\"79607.10\",\"B\":\"5.115\",\"a\":\"79607.20\",\"A\":\"7.496\",\"T\":1788563396245,\"E\":1788563396245,\"st\":1}}"}
{"receive_ns":1788563396242239000,"stream":"btcusdt@bookTicker","event_type":"bookTicker","event_time_ms":1788563396272,"raw_json":"{\"stream\":\"btcusdt@bookTicker\",\"data\":{\"e\":\"bookTicker\",\"u\":11478233420160,\"s\":\"BTCUSDT\",\"ps\":\"BTCUSDT\",\"b\":\"79607.10\",\"B\":\"4.544\",\"a\":\"79607.20\",\"A\":\"7.496\",\"T\":1788563396272,\"E\":1788563396272,\"st\":1}}"}
{"receive_ns":1788563396242511000,"stream":"btcusdt@bookTicker","event_type":"bookTicker","event_time_ms":1788563396273,"raw_json":"{\"stream\":\"btcusdt@bookTicker\",\"data\":{\"e\":\"bookTicker\",\"u\":11478233420196,\"s\":\"BTCUSDT\",\"ps\":\"BTCUSDT\",\"b\":\"79607.10\",\"B\":\"4.546\",\"a\":\"79607.20\",\"A\":\"7.496\",\"T\":1788563396273,\"E\":1788563396273,\"st\":1}}"}
{"receive_ns":1788563396242795000,"stream":"btcusdt@bookTicker","event_type":"bookTicker","event_time_ms":1788563396276,"raw_json":"{\"stream\":\"btcusdt@bookTicker\",\"data\":{\"e\":\"bookTicker\",\"u\":11478233420312,\"s\":\"BTCUSDT\",\"ps\":\"BTCUSDT\",\"b\":\"79607.10\",\"B\":\"5.119\",\"a\":\"79607.20\",\"A\":\"7.496\",\"T\":1788563396275,\"E\":1788563396276,\"st\":1}}"}
{"receive_ns":1788563396313179000,"stream":"btcusdt@depth@100ms","event_type":"depthUpdate","event_time_ms":1788563396345,"raw_json":"{\"stream\":\"btcusdt@depth@100ms\",\"data\":{\"e\":\"depthUpdate\",\"E\":1788563396345,\"T\":1788563396344,\"s\":\"BTCUSDT\",\"ps\":\"BTCUSDT\",\"U\":11478233419246,\"u\":11478233422577,\"pu\":11478233419201,\"b\":[[\"29207.10\",\"1.092\"],[\"29307.10\",\"1.008\"],[\"63686.00\",\"0.000\"],[\"71646.30\",\"0.002\"],[\"76422.80\",\"0.002\"],[\"78413.00\",\"10.125\"],[\"78608.50\",\"10.187\"],[\"78811.00\",\"15.338\"],[\"78887.10\",\"17.279\"],[\"79396.20\",\"4.710\"],[\"79483.40\",\"0.386\"],[\"79516.00\",\"4.572\"],[\"79543.40\",\"0.001\"],[\"79573.80\",\"0.073\"],[\"79574.70\",\"0.455\"],[\"79575.90\",\"0.001\"],[\"79592.10\",\"0.001\"],[\"79603.30\",\"0.624\"],[\"79603.40\",\"0.026\"],[\"79603.50\",\"0.029\"],[\"79603.60\",\"1.545\"],[\"79603.70\",\"0.037\"],[\"79603.80\",\"0.029\"],[\"79604.20\",\"0.001\"],[\"79604.30\",\"0.000\"],[\"79604.40\",\"0.000\"],[\"79604.70\",\"0.001\"],[\"79604.80\",\"0.002\"],[\"79605.00\",\"0.630\"],[\"79605.10\",\"0.000\"],[\"79605.70\",\"0.138\"],[\"79607.10\",\"5.119\"]],\"a\":[[\"79607.20\",\"7.496\"],[\"79616.00\",\"0.020\"],[\"79618.30\",\"0.440\"],[\"79623.50\",\"0.001\"],[\"79624.50\",\"0.479\"],[\"79625.40\",\"0.452\"],[\"79625.50\",\"0.006\"],[\"79627.90\",\"0.045\"],[\"79628.20\",\"0.200\"],[\"79656.50\",\"0.009\"],[\"79656.60\",\"1.431\"],[\"79670.90\",\"0.212\"],[\"79705.60\",\"0.015\"],[\"79705.70\",\"0.001\"],[\"79705.80\",\"4.901\"],[\"79728.80\",\"0.169\"],[\"80019.60\",\"0.087\"],[\"80403.30\",\"22.314\"],[\"80602.30\",\"13.193\"]],\"st\":1}}"}
{"receive_ns":1788563396414884000,"stream":"btcusdt@depth@100ms","event_type":"depthUpdate","event_time_ms":1788563396447,"raw_json":"{\"stream\":\"btcusdt@depth@100ms\",\"data\":{\"e\":\"depthUpdate\",\"E\":1788563396447,\"T\":1788563396445,\"s\":\"BTCUSDT\",\"ps\":\"BTCUSDT\",\"U\":11478233422594,\"u\":11478233426739,\"pu\":11478233422577,\"b\":[[\"1000.00\",\"24.754\"],[\"29207.10\",\"1.274\"],[\"29307.10\",\"0.826\"],[\"71646.30\",\"0.002\"],[\"76422.80\",\"0.000\"],[\"78476.70\",\"2.143\"],[\"78811.00\",\"15.338\"],[\"79232.90\",\"0.141\"],[\"79491.70\",\"0.583\"],[\"79576.00\",\"0.027\"],[\"79583.20\",\"0.779\"],[\"79583.80\",\"0.001\"],[\"79604.20\",\"0.027\"]],\"a\":[[\"79774.40\",\"2.254\"],[\"79968.00\",\"0.867\"],[\"79969.40\",\"1.116\"],[\"79995.30\",\"0.046\"],[\"79997.80\",\"0.525\"],[\"80403.30\",\"22.314\"]],\"st\":1}}"}
{"receive_ns":1788563396517452000,"stream":"btcusdt@depth@100ms","event_type":"depthUpdate","event_time_ms":1788563396549,"raw_json":"{\"stream\":\"btcusdt@depth@100ms\",\"data\":{\"e\":\"depthUpdate\",\"E\":1788563396549,\"T\":1788563396547,\"s\":\"BTCUSDT\",\"ps\":\"BTCUSDT\",\"U\":11478233426820,\"u\":11478233430641,\"pu\":11478233426739,\"b\":[[\"29207.10\",\"1.449\"],[\"29307.10\",\"0.651\"],[\"71646.30\",\"0.002\"],[\"76422.80\",\"0.002\"],[\"78811.00\",\"15.338\"],[\"79209.10\",\"4.598\"],[\"79606.90\",\"0.196\"]],\"a\":[[\"79705.80\",\"4.901\"],[\"80403.30\",\"22.314\"],[\"80752.40\",\"1.732\"]],\"st\":1}}"}
{"receive_ns":1788563396517797000,"stream":"btcusdt@bookTicker","event_type":"bookTicker","event_time_ms":1788563396558,"raw_json":"{\"stream\":\"btcusdt@bookTicker\",\"data\":{\"e\":\"bookTicker\",\"u\":11478233431350,\"s\":\"BTCUSDT\",\"ps\":\"BTCUSDT\",\"b\":\"79607.10\",\"B\":\"5.104\",\"a\":\"79607.20\",\"A\":\"7.496\",\"T\":1788563396558,\"E\":1788563396558,\"st\":1}}"}
{"receive_ns":1788563396520329000,"stream":"btcusdt@bookTicker","event_type":"bookTicker","event_time_ms":1788563396561,"raw_json":"{\"stream\":\"btcusdt@bookTicker\",\"data\":{\"e\":\"bookTicker\",\"u\":11478233431566,\"s\":\"BTCUSDT\",\"ps\":\"BTCUSDT\",\"b\":\"79607.10\",\"B\":\"5.119\",\"a\":\"79607.20\",\"A\":\"7.496\",\"T\":1788563396561,\"E\":1788563396561,\"st\":1}}"}
{"receive_ns":1788563396520567000,"stream":"btcusdt@bookTicker","event_type":"bookTicker","event_time_ms":1788563396562,"raw_json":"{\"stream\":\"btcusdt@bookTicker\",\"data\":{\"e\":\"bookTicker\",\"u\":11478233431591,\"s\":\"BTCUSDT\",\"ps\":\"BTCUSDT\",\"b\":\"79607.10\",\"B\":\"5.117\",\"a\":\"79607.20\",\"A\":\"7.496\",\"T\":1788563396562,\"E\":1788563396562,\"st\":1}}"}
{"receive_ns":1788563396608437000,"stream":"btcusdt@depth@100ms","event_type":"depthUpdate","event_time_ms":1788563396651,"raw_json":"{\"stream\":\"btcusdt@depth@100ms\",\"data\":{\"e\":\"depthUpdate\",\"E\":1788563396651,\"T\":1788563396650,\"s\":\"BTCUSDT\",\"ps\":\"BTCUSDT\",\"U\":11478233430770,\"u\":11478233435143,\"pu\":11478233430641,\"b\":[[\"1000.00\",\"24.754\"],[\"29207.10\",\"1.631\"],[\"29307.10\",\"0.469\"],[\"63686.00\",\"0.000\"],[\"71646.30\",\"0.002\"],[\"76422.80\",\"0.000\"],[\"78015.00\",\"12.486\"],[\"78124.70\",\"0.002\"],[\"78489.10\",\"18.038\"],[\"78811.00\",\"15.338\"],[\"79232.90\",\"0.000\"],[\"79444.00\",\"2.402\"],[\"79483.40\",\"0.457\"],[\"79491.70\",\"0.000\"],[\"79583.20\",\"0.002\"],[\"79603.00\",\"0.029\"],[\"79603.10\",\"0.252\"],[\"79604.00\",\"0.003\"],[\"79604.10\",\"1.000\"],[\"79604.20\",\"0.001\"],[\"79607.10\",\"5.117\"]],\"a\":[[\"79728.80\",\"0.232\"],[\"79768.20\",\"0.994\"],[\"79774.40\",\"2.003\"],[\"79968.00\",\"0.104\"],[\"79969.40\",\"0.001\"],[\"79995.30\",\"0.002\"],[\"79997.80\",\"0.000\"],[\"80005.30\",\"0.001\"],[\"80403.30\",\"22.314\"],[\"80498.30\",\"1.602\"],[\"80712.60\",\"3.369\"]],\"st\":1}}"}
{"receive_ns":1788563396711549000,"stream":"btcusdt@depth@100ms","event_type":"depthUpdate","event_time_ms":1788563396753,"raw_json":"{\"stream\":\"btcusdt@depth@100ms\",\"data\":{\"e\":\"depthUpdate\",\"E\":1788563396753,\"T\":1788563396751,\"s\":\"BTCUSDT\",\"ps\":\"BTCUSDT\",\"U\":11478233435180,\"u\":11478233439635,\"pu\":11478233435143,\"b\":[[\"1000.00\",\"24.754\"],[\"29107.10\",\"0.021\"],[\"29207.10\",\"1.764\"],[\"29307.10\",\"0.315\"],[\"63685.70\",\"0.001\"],[\"71646.30\",\"0.002\"],[\"71684.00\",\"0.000\"],[\"75626.80\",\"0.000\"],[\"78811.00\",\"15.338\"],[\"79232.90\",\"0.141\"],[\"79439.50\",\"1.544\"],[\"79491.70\",\"0.583\"],[\"79565.20\",\"0.000\"],[\"79566.60\",\"0.127\"],[\"79573.00\",\"0.101\"],[\"79583.20\",\"0.779\"],[\"79583.80\",\"0.001\"],[\"79595.00\",\"0.182\"],[\"79595.30\",\"0.003\"],[\"79604.30\",\"0.026\"]],\"a\":[[\"79705.80\",\"4.901\"],[\"79772.90\",\"1.547\"],[\"79774.40\",\"2.254\"],[\"79828.70\",\"9.265\"],[\"79968.00\",\"0.867\"],[\"79969.40\",\"1.116\"],[\"79995.30\",\"0.046\"],[\"79997.80\",\"0.525\"],[\"80403.30\",\"22.314\"],[\"80761.50\",\"22.262\"],[\"81199.30\",\"14.225\"]],\"st\":1}}"}
{"receive_ns":1788563396802138000,"stream":"btcusdt@bookTicker","event_type":"bookTicker","event_time_ms":1788563396844,"raw_json":"{\"stream\":\"btcusdt@bookTicker\",\"data\":{\"e\":\"bookTicker\",\"u\":11478233443095,\"s\":\"BTCUSDT\",\"ps\":\"BTCUSDT\",\"b\":\"79607.10\",\"B\":\"5.117\",\"a\":\"79607.20\",\"A\":\"7.494\",\"T\":1788563396843,\"E\":1788563396844,\"st\":1}}"}
{"receive_ns":1788563396813388000,"stream":"btcusdt@depth@100ms","event_type":"depthUpdate","event_time_ms":1788563396855,"raw_json":"{\"stream\":\"btcusdt@depth@100ms\",\"data\":{\"e\":\"depthUpdate\",\"E\":1788563396855,\"T\":1788563396854,\"s\":\"BTCUSDT\",\"ps\":\"BTCUSDT\",\"U\":11478233439737,\"u\":11478233443431,\"pu\":11478233439635,\"b\":[[\"29107.10\",\"0.077\"],[\"29207.10\",\"1.834\"],[\"29307.10\",\"0.189\"],[\"71646.30\",\"0.002\"],[\"76422.80\",\"0.002\"],[\"78134.40\",\"3.320\"],[\"78562.90\",\"1.275\"],[\"78811.00\",\"15.338\"],[\"79209.00\",\"0.002\"],[\"79209.10\",\"4.598\"],[\"79483.40\",\"0.500\"],[\"79516.00\",\"5.957\"],[\"79533.70\",\"0.829\"],[\"79549.60\",\"0.691\"],[\"79583.40\",\"0.006\"],[\"79592.60\",\"0.080\"],[\"79596.40\",\"0.073\"],[\"79604.90\",\"0.026\"]],\"a\":[[\"79607.20\",\"7.494\"],[\"79613.40\",\"0.006\"],[\"79616.00\",\"0.459\"],[\"79618.30\",\"0.001\"],[\"79623.30\",\"0.458\"],[\"79728.80\",\"0.276\"],[\"80204.30\",\"4.358\"],[\"80403.30\",\"22.314\"],[\"80721.70\",\"57.436\"],[\"80729.70\",\"4.947\"],[\"80761.50\",\"23.128\"]],\"st\":1}}"}
{"receive_ns":1788563396917310000,"stream":"btcusdt@depth@100ms","event_type":"depthUpdate","event_time_ms":1788563396957,"raw_json":"{\"stream\":\"btcusdt@depth@100ms\",\"data\":{\"e\":\"depthUpdate\",\"E\":1788563396957,\"T\":1788563396955,\"s\":\"BTCUSDT\",\"ps\":\"BTCUSDT\",\"U\":11478233443463,\"u\":11478233446793,\"pu\":11478233443431,\"b\":[[\"1000.00\",\"24.754\"],[\"29107.10\",\"0.140\"],[\"29207.10\",\"1.883\"],[\"29307.10\",\"0.077\"],[\"63686.00\",\"0.000\"],[\"71646.30\",\"0.002\"],[\"76422.80\",\"0.000\"],[\"78811.00\",\"15.340\"],[\"79232.90\",\"0.141\"],[\"79491.70\",\"0.232\"],[\"79516.00\",\"4.572\"],[\"79531.50\",\"0.051\"],[\"79576.00\",\"0.021\"],[\"79583.20\",\"0.353\"],[\"79583.80\",\"0.001\"],[\"79589.20\",\"0.972\"],[\"79592.40\",\"0.424\"],[\"79592.60\",\"0.004\"],[\"79596.80\",\"0.100\"],[\"79604.90\",\"0.000\"],[\"79605.40\",\"0.027\"]],\"a\":[[\"79616.00\",\"0.020\"],[\"79618.30\",\"0.440\"],[\"79774.40\",\"2.003\"],[\"79968.00\",\"0.867\"],[\"79969.40\",\"1.367\"],[\"79995.30\",\"0.046\"],[\"79997.80\",\"0.525\"],[\"80176.70\",\"0.000\"],[\"80403.30\",\"22.314\"],[\"80678.00\",\"3.756\"],[\"80841.10\",\"10.381\"]],\"st\":1}}"}
{"receive_ns":1788563397022202000,"stream":"btcusdt@depth@100ms","event_type":"depthUpdate","event_time_ms":1788563397059,"raw_json":"{\"stream\":\"btcusdt@depth@100ms\",\"data\":{\"e\":\"depthUpdate\",\"E\":1788563397059,\"T\":1788563397058,\"s\":\"BTCUSDT\",\"ps\":\"BTCUSDT\",\"U\":11478233446824,\"u\":11478233450476,\"pu\":11478233446793,\"b\":[[\"1000.00\",\"24.754\"],[\"29107.10\",\"0.245\"],[\"29207.10\",\"1.855\"],[\"29307.10\",\"0.000\"],[\"63686.00\",\"0.000\"],[\"71646.30\",\"0.002\"],[\"76422.80\",\"0.002\"],[\"78682.70\",\"1.524\"],[\"78811.00\",\"15.338\"],[\"78887.10\",\"17.089\"],[\"79522.40\",\"0.000\"],[\"79592.80\",\"0.004\"],[\"79603.00\",\"0.003\"],[\"79605.50\",\"0.028\"],[\"79606.90\",\"0.198\"]],\"a\":[[\"79705.80\",\"4.776\"],[\"80320.00\",\"4.181\"],[\"80403.30\",\"22.314\"],[\"80767.40\",\"0.432\"],[\"81040.10\",\"10.101\"]],\"st\":1}}"}
{"receive_ns":1788563397058355000,"stream":"btcusdt@bookTicker","event_type":"bookTicker","event_time_ms":1788563397100,"raw_json":"{\"stream\":\"btcusdt@bookTicker\",\"data\":{\"e\":\"bookTicker\",\"u\":11478233451941,\"s\":\"BTCUSDT\",\"ps\":\"BTCUSDT\",\"b\":\"79607.10\",\"B\":\"5.102\",\"a\":\"79607.20\",\"A\":\"7.494\",\"T\":1788563397099,\"E\":1788563397100,\"st\":1}}"}
{"receive_ns":1788563397062966000,"stream":"btcusdt@bookTicker","event_type":"bookTicker","event_time_ms":1788563397103,"raw_json":"{\"stream\":\"btcusdt@bookTicker\",\"data\":{\"e\":\"bookTicker\",\"u\":11478233452118,\"s\":\"BTCUSDT\",\"ps\":\"BTCUSDT\",\"b\":\"79607.10\",\"B\":\"5.117\",\"a\":\"79607.20\",\"A\":\"7.494\",\"T\":1788563397103,\"E\":1788563397103,\"st\":1}}"}
{"receive_ns":1788563397063265000,"stream":"btcusdt@bookTicker","event_type":"bookTicker","event_time_ms":1788563397104,"raw_json":"{\"stream\":\"btcusdt@bookTicker\",\"data\":{\"e\":\"bookTicker\",\"u\":11478233452174,\"s\":\"BTCUSDT\",\"ps\":\"BTCUSDT\",\"b\":\"79607.10\",\"B\":\"5.119\",\"a\":\"79607.20\",\"A\":\"7.494\",\"T\":1788563397104,\"E\":1788563397104,\"st\":1}}"}
{"receive_ns":1788563397093405000,"stream":"btcusdt@bookTicker","event_type":"bookTicker","event_time_ms":1788563397127,"raw_json":"{\"stream\":\"btcusdt@bookTicker\",\"data\":{\"e\":\"bookTicker\",\"u\":11478233453000,\"s\":\"BTCUSDT\",\"ps\":\"BTCUSDT\",\"b\":\"79607.10\",\"B\":\"4.669\",\"a\":\"79607.20\",\"A\":\"7.494\",\"T\":1788563397127,\"E\":1788563397127,\"st\":1}}"}
{"receive_ns":1788563397093680000,"stream":"btcusdt@bookTicker","event_type":"bookTicker","event_time_ms":1788563397128,"raw_json":"{\"stream\":\"btcusdt@bookTicker\",\"data\":{\"e\":\"bookTicker\",\"u\":11478233453094,\"s\":\"BTCUSDT\",\"ps\":\"BTCUSDT\",\"b\":\"79607.10\",\"B\":\"4.669\",\"a\":\"79607.20\",\"A\":\"7.484\",\"T\":1788563397128,\"E\":1788563397128,\"st\":1}}"}
{"receive_ns":1788563397093886000,"stream":"btcusdt@trade","event_type":"trade","event_time_ms":1788563397128,"raw_json":"{\"stream\":\"btcusdt@trade\",\"data\":{\"e\":\"trade\",\"E\":1788563397128,\"T\":1788563397128,\"s\":\"BTCUSDT\",\"t\":8054083508,\"p\":\"79607.20\",\"q\":\"0.010\",\"X\":\"MARKET\",\"m\":false,\"st\":1}}"}
{"receive_ns":1788563397094093000,"stream":"btcusdt@bookTicker","event_type":"bookTicker","event_time_ms":1788563397130,"raw_json":"{\"stream\":\"btcusdt@bookTicker\",\"data\":{\"e\":\"bookTicker\",\"u\":11478233453209,\"s\":\"BTCUSDT\",\"ps\":\"BTCUSDT\",\"b\":\"79607.10\",\"B\":\"5.120\",\"a\":\"79607.20\",\"A\":\"7.484\",\"T\":1788563397130,\"E\":1788563397130,\"st\":1}}"}
{"receive_ns":1788563397094370000,"stream":"btcusdt@bookTicker","event_type":"bookTicker","event_time_ms":1788563397131,"raw_json":"{\"stream\":\"btcusdt@bookTicker\",\"data\":{\"e\":\"bookTicker\",\"u\":11478233453267,\"s\":\"BTCUSDT\",\"ps\":\"BTCUSDT\",\"b\":\"79607.10\",\"B\":\"5.118\",\"a\":\"79607.20\",\"A\":\"7.484\",\"T\":1788563397131,\"E\":1788563397131,\"st\":1}}"}
{"receive_ns":1788563397119581000,"stream":"btcusdt@depth@100ms","event_type":"depthUpdate","event_time_ms":1788563397161,"raw_json":"{\"stream\":\"btcusdt@depth@100ms\",\"data\":{\"e\":\"depthUpdate\",\"E\":1788563397161,\"T\":1788563397159,\"s\":\"BTCUSDT\",\"ps\":\"BTCUSDT\",\"U\":11478233450541,\"u\":11478233454263,\"pu\":11478233450476,\"b\":[[\"29107.10\",\"0.420\"],[\"29207.10\",\"1.680\"],[\"63686.00\",\"0.000\"],[\"71646.30\",\"0.002\"],[\"78691.60\",\"12.290\"],[\"78727.90\",\"13.193\"],[\"78811.00\",\"15.338\"],[\"78890.60\",\"43.895\"],[\"79209.10\",\"4.608\"],[\"79232.90\",\"0.141\"],[\"79421.10\",\"3.140\"],[\"79461.50\",\"1.884\"],[\"79491.70\",\"0.232\"],[\"79519.40\",\"0.038\"],[\"79523.60\",\"0.126\"],[\"79523.90\",\"2.523\"],[\"79533.70\",\"0.000\"],[\"79549.60\",\"0.000\"],[\"79575.20\",\"0.915\"],[\"79583.20\",\"0.855\"],[\"79583.80\",\"2.009\"],[\"79589.20\",\"0.470\"],[\"79592.40\",\"0.348\"],[\"79593.40\",\"0.078\"],[\"79597.80\",\"0.001\"],[\"79598.00\",\"0.006\"],[\"79600.90\",\"0.002\"],[\"79603.10\",\"0.226\"],[\"79603.30\",\"0.598\"],[\"79605.80\",\"0.027\"],[\"79605.90\",\"0.026\"],[\"79607.10\",\"5.118\"]],\"a\":[[\"79607.20\",\"7.484\"],[\"79608.70\",\"0.026\"],[\"79694.60\",\"0.039\"],[\"79705.40\",\"0.001\"],[\"79705.50\",\"8.626\"],[\"79705.70\",\"0.001\"],[\"79729.90\",\"1.884\"],[\"79748.10\",\"3.140\"],[\"79968.00\",\"0.867\"],[\"79969.40\",\"1.367\"],[\"79995.30\",\"0.046\"],[\"79997.80\",\"0.525\"],[\"80403.30\",\"22.314\"],[\"80598.60\",\"11.559\"],[\"80721.70\",\"59.292\"]],\"st\":1}}"}
{"receive_ns":1788563397222368000,"stream":"btcusdt@depth@100ms","event_type":"depthUpdate","event_time_ms":1788563397263,"raw_json":"{\"stream\":\"btcusdt@depth@100ms\",\"data\":{\"e\":\"depthUpdate\",\"E\":1788563397263,\"T\":1788563397261,\"s\":\"BTCUSDT\",\"ps\":\"BTCUSDT\",\"U\":11478233454337,\"u\":11478233457409,\"pu\":11478233454263,\"b\":[[\"1000.00\",\"24.754\"],[\"29107.10\",\"0.602\"],[\"29207.10\",\"1.498\"],[\"71646.30\",\"0.002\"],[\"76422.80\",\"0.000\"],[\"78811.00\",\"15.338\"],[\"79574.90\",\"0.092\"],[\"79583.20\",\"0.504\"],[\"79583.80\",\"0.001\"],[\"79598.00\",\"0.004\"],[\"79603.40\",\"0.000\"],[\"79604.50\",\"0.026\"],[\"79604.70\",\"0.027\"],[\"79604.80\",\"0.028\"],[\"79605.40\",\"0.001\"],[\"79605.50\",\"0.002\"],[\"79605.80\",\"0.001\"],[\"79605.90\",\"0.000\"],[\"79606.00\",\"0.062\"]],\"a\":[[\"79685.00\",\"1.558\"],[\"79705.70\",\"0.001\"],[\"79705.80\",\"4.901\"],[\"80403.30\",\"22.314\"],[\"80598.60\",\"11.348\"],[\"80777.40\",\"12.164\"],[\"80952.60\",\"0.986\"]],\"st\":1}}"}
{"receive_ns":1788563397325247000,"stream":"btcusdt@depth@100ms","event_type":"depthUpdate","event_time_ms":1788563397365,"raw_json":"{\"stream\":\"btcusdt@depth@100ms\",\"data\":{\"e\":\"depthUpdate\",\"E\":1788563397365,\"T\":1788563397364,\"s\":\"BTCUSDT\",\"ps\":\"BTCUSDT\",\"U\":11478233457470,\"u\":11478233460710,\"pu\":11478233457409,\"b\":[[\"1000.00\",\"24.754\"],[\"29107.10\",\"0.777\"],[\"29207.10\",\"1.323\"],[\"71646.30\",\"0.002\"],[\"76422.80\",\"0.002\"],[\"78484.60\",\"1.908\"],[\"78811.00\",\"15.338\"],[\"79232.90\",\"0.000\"],[\"79390.90\",\"1.544\"],[\"79491.70\",\"0.000\"],[\"79516.00\",\"4.572\"],[\"79519.90\",\"1.535\"],[\"79523.30\",\"0.126\"],[\"79523.60\",\"0.001\"],[\"79555.70\",\"0.001\"],[\"79576.00\",\"0.121\"],[\"79583.20\",\"0.002\"],[\"79589.20\",\"0.195\"],[\"79592.10\",\"0.077\"],[\"79592.40\",\"0.348\"],[\"79593.40\",\"0.002\"],[\"79603.00\",\"0.029\"],[\"79603.10\",\"0.252\"],[\"79603.30\",\"0.624\"],[\"79603.40\",\"0.026\"],[\"79604.00\",\"0.029\"],[\"79604.10\",\"1.026\"],[\"79604.30\",\"0.000\"],[\"79604.50\",\"0.000\"],[\"79604.70\",\"0.001\"],[\"79604.80\",\"0.002\"],[\"79606.00\",\"0.036\"]],\"a\":[[\"79609.30\",\"0.252\"],[\"79673.10\",\"0.103\"],[\"79697.90\",\"4.033\"],[\"79821.40\",\"0.380\"],[\"79821.50\",\"2.047\"],[\"79828.70\",\"7.906\"],[\"79968.00\",\"0.104\"],[\"79969.40\",\"0.001\"],[\"79995.30\",\"0.002\"],[\"79997.80\",\"0.000\"],[\"80403.30\",\"22.314\"],[\"81159.50\",\"1.919\"]],\"st\":1}}"}
{"receive_ns":1788563397368234000,"stream":"btcusdt@bookTicker","event_type":"bookTicker","event_time_ms":1788563397408,"raw_json":"{\"stream\":\"btcusdt@bookTicker\",\"data\":{\"e\":\"bookTicker\",\"u\":11478233463056,\"s\":\"BTCUSDT\",\"ps\":\"BTCUSDT\",\"b\":\"79607.10\",\"B\":\"3.889\",\"a\":\"79607.20\",\"A\":\"7.484\",\"T\":1788563397408,\"E\":1788563397408,\"st\":1}}"}
{"receive_ns":1788563397368436000,"stream":"btcusdt@bookTicker","event_type":"bookTicker","event_time_ms":1788563397409,"raw_json":"{\"stream\":\"btcusdt@bookTicker\",\"data\":{\"e\":\"bookTicker\",\"u\":11478233463121,\"s\":\"BTCUSDT\",\"ps\":\"BTCUSDT\",\"b\":\"79607.10\",\"B\":\"3.888\",\"a\":\"79607.20\",\"A\":\"7.484\",\"T\":1788563397409,\"E\":1788563397409,\"st\":1}}"}
{"receive_ns":1788563397368570000,"stream":"btcusdt@bookTicker","event_type":"bookTicker","event_time_ms":1788563397409,"raw_json":"{\"stream\":\"btcusdt@bookTicker\",\"data\":{\"e\":\"bookTicker\",\"u\":11478233463124,\"s\":\"BTCUSDT\",\"ps\":\"BTCUSDT\",\"b\":\"79607.10\",\"B\":\"3.890\",\"a\":\"79607.20\",\"A\":\"7.484\",\"T\":1788563397409,\"E\":1788563397409,\"st\":1}}"}
{"receive_ns":1788563397368772000,"stream":"btcusdt@bookTicker","event_type":"bookTicker","event_time_ms":1788563397409,"raw_json":"{\"stream\":\"btcusdt@bookTicker\",\"data\":{\"e\":\"bookTicker\",\"u\":11478233463189,\"s\":\"BTCUSDT\",\"ps\":\"BTCUSDT\",\"b\":\"79607.10\",\"B\":\"3.891\",\"a\":\"79607.20\",\"A\":\"7.484\",\"T\":1788563397409,\"E\":1788563397409,\"st\":1}}"}
{"receive_ns":1788563397376502000,"stream":"btcusdt@bookTicker","event_type":"bookTicker","event_time_ms":1788563397417,"raw_json":"{\"stream\":\"btcusdt@bookTicker\",\"data\":{\"e\":\"bookTicker\",\"u\":11478233463582,\"s\":\"BTCUSDT\",\"ps\":\"BTCUSDT\",\"b\":\"79607.10\",\"B\":\"5.123\",\"a\":\"79607.20\",\"A\":\"7.484\",\"T\":1788563397417,\"E\":1788563397417,\"st\":1}}"}
{"receive_ns":1788563397376743000,"stream":"btcusdt@bookTicker","event_type":"bookTicker","event_time_ms":1788563397418,"raw_json":"{\"stream\":\"btcusdt@bookTicker\",\"data\":{\"e\":\"bookTicker\",\"u\":11478233463645,\"s\":\"BTCUSDT\",\"ps\":\"BTCUSDT\",\"b\":\"79607.10\",\"B\":\"5.121\",\"a\":\"79607.20\",\"A\":\"7.484\",\"T\":1788563397418,\"E\":1788563397418,\"st\":1}}"}
{"receive_ns":1788563397399146000,"stream":"btcusdt@bookTicker","event_type":"bookTicker","event_time_ms":1788563397437,"raw_json":"{\"stream\":\"btcusdt@bookTicker\",\"data\":{\"e\":\"bookTicker\",\"u\":11478233464278,\"s\":\"BTCUSDT\",\"ps\":\"BTCUSDT\",\"b\":\"79607.10\",\"B\":\"4.548\",\"a\":\"79607.20\",\"A\":\"7.484\",\"T\":1788563397437,\"E\":1788563397437,\"st\":1}}"}
{"receive_ns":1788563397399438000,"stream":"btcusdt@bookTicker","event_type":"bookTicker","event_time_ms":1788563397439,"raw_json":"{\"stream\":\"btcusdt@bookTicker\",\"data\":{\"e\":\"bookTicker\",\"u\":11478233464372,\"s\":\"BTCUSDT\",\"ps\":\"BTCUSDT\",\"b\":\"79607.10\",\"B\":\"4.550\",\"a\":\"79607.20\",\"A\":\"7.484\",\"T\":1788563397438,\"E\":1788563397439,\"st\":1}}"}
{"receive_ns":1788563397408169000,"stream":"btcusdt@bookTicker","event_type":"bookTicker","event_time_ms":1788563397440,"raw_json":"{\"stream\":\"btcusdt@bookTicker\",\"data\":{\"e\":\"bookTicker\",\"u\":11478233464527,\"s\":\"BTCUSDT\",\"ps\":\"BTCUSDT\",\"b\":\"79607.10\",\"B\":\"5.124\",\"a\":\"79607.20\",\"A\":\"7.484\",\"T\":1788563397440,\"E\":1788563397440,\"st\":1}}"}
{"receive_ns":1788563397426662000,"stream":"btcusdt@depth@100ms","event_type":"depthUpdate","event_time_ms":1788563397467,"raw_json":"{\"stream\":\"btcusdt@depth@100ms\",\"data\":{\"e\":\"depthUpdate\",\"E\":1788563397467,\"T\":1788563397465,\"s\":\"BTCUSDT\",\"ps\":\"BTCUSDT\",\"U\":11478233460797,\"u\":11478233465403,\"pu\":11478233460710,\"b\":[[\"29107.10\",\"0.959\"],[\"29207.10\",\"1.141\"],[\"71646.30\",\"0.002\"],[\"75626.70\",\"0.029\"],[\"76422.80\",\"0.000\"],[\"78015.00\",\"12.489\"],[\"78522.60\",\"0.000\"],[\"78811.00\",\"15.338\"],[\"78970.20\",\"8.001\"],[\"79209.10\",\"4.598\"],[\"79232.90\",\"0.141\"],[\"79491.70\",\"0.232\"],[\"79516.00\",\"4.572\"],[\"79535.50\",\"0.251\"],[\"79559.10\",\"0.001\"],[\"79575.80\",\"1.734\"],[\"79583.20\",\"0.504\"],[\"79583.80\",\"0.001\"],[\"79589.20\",\"0.470\"],[\"79596.60\",\"0.001\"],[\"79597.80\",\"0.001\"],[\"79600.90\",\"0.002\"],[\"79603.00\",\"0.003\"],[\"79603.10\",\"0.226\"],[\"79603.30\",\"0.598\"],[\"79604.20\",\"0.027\"],[\"79604.30\",\"0.026\"],[\"79604.50\",\"0.026\"],[\"79604.90\",\"0.000\"],[\"79605.60\",\"0.027\"],[\"79606.20\",\"0.003\"],[\"79606.90\",\"0.198\"],[\"79607.10\",\"5.124\"]],\"a\":[[\"79613.40\",\"0.002\"],[\"79673.10\",\"0.104\"],[\"79686.90\",\"0.002\"],[\"79687.10\",\"6.001\"],[\"79968.00\",\"0.867\"],[\"79969.40\",\"1.367\"],[\"79995.30\",\"0.046\"],[\"79997.80\",\"0.525\"],[\"80179.90\",\"0.093\"],[\"80403.30\",\"22.314\"]],\"st\":1}}"}
{"receive_ns":1788563397465271000,"stream":"btcusdt@bookTicker","event_type":"bookTicker","event_time_ms":1788563397505,"raw_json":"{\"stream\":\"btcusdt@bookTicker\",\"data\":{\"e\":\"bookTicker\",\"u\":11478233467434,\"s\":\"BTCUSDT\",\"ps\":\"BTCUSDT\",\"b\":\"79607.10\",\"B\":\"5.124\",\"a\":\"79607.20\",\"A\":\"7.474\",\"T\":1788563397505,\"E\":1788563397505,\"st\":1}}"}
{"receive_ns":1788563397465502000,"stream":"btcusdt@trade","event_type":"trade","event_time_ms":1788563397505,"raw_json":"{\"stream\":\"btcusdt@trade\",\"data\":{\"e\":\"trade\",\"E\":1788563397505,\"T\":1788563397505,\"s\":\"BTCUSDT\",\"t\":8054083509,\"p\":\"79607.20\",\"q\":\"0.010\",\"X\":\"MARKET\",\"m\":false,\"st\":1}}"}
{"receive_ns":1788563397498160000,"stream":"btcusdt@bookTicker","event_type":"bookTicker","event_time_ms":1788563397539,"raw_json":"{\"stream\":\"btcusdt@bookTicker\",\"data\":{\"e\":\"bookTicker\",\"u\":11478233469024,\"s\":\"BTCUSDT\",\"ps\":\"BTCUSDT\",\"b\":\"79607.10\",\"B\":\"5.117\",\"a\":\"79607.20\",\"A\":\"7.474\",\"T\":1788563397538,\"E\":1788563397539,\"st\":1}}"}
{"receive_ns":1788563397528788000,"stream":"btcusdt@depth@100ms","event_type":"depthUpdate","event_time_ms":1788563397569,"raw_json":"{\"stream\":\"btcusdt@depth@100ms\",\"data\":{\"e\":\"depthUpdate\",\"E\":1788563397569,\"T\":1788563397565,\"s\":\"BTCUSDT\",\"ps\":\"BTCUSDT\",\"U\":11478233465468,\"u\":11478233469881,\"pu\":11478233465403,\"b\":[[\"1000.00\",\"24.754\"],[\"29107.10\",\"1.134\"],[\"29207.10\",\"0.966\"],[\"71646.30\",\"0.002\"],[\"76422.80\",\"0.002\"],[\"78492.60\",\"53.093\"],[\"78608.50\",\"10.035\"],[\"78651.80\",\"52.919\"],[\"78811.00\",\"15.338\"],[\"78874.70\",\"0.201\"],[\"79523.10\",\"0.125\"],[\"79523.30\",\"0.001\"],[\"79535.40\",\"0.002\"],[\"79573.80\",\"0.525\"],[\"79574.70\",\"0.003\"],[\"79593.50\",\"0.079\"],[\"79597.60\",\"0.002\"],[\"79603.40\",\"0.000\"],[\"79603.50\",\"0.003\"],[\"79603.60\",\"1.519\"],[\"79603.70\",\"0.011\"],[\"79604.80\",\"0.028\"],[\"79605.20\",\"0.028\"],[\"79605.60\",\"0.052\"],[\"79605.70\",\"0.164\"],[\"79606.90\",\"0.199\"],[\"79607.10\",\"5.117\"]],\"a\":[[\"79607.20\",\"7.474\"],[\"79616.00\",\"0.459\"],[\"79618.30\",\"0.001\"],[\"79620.60\",\"8.075\"],[\"79623.00\",\"0.000\"],[\"79623.20\",\"0.642\"],[\"79625.40\",\"0.000\"],[\"79678.90\",\"0.015\"],[\"80403.30\",\"22.314\"],[\"80703.70\",\"0.005\"]],\"st\":1}}"}
{"receive_ns":1788563397564793000,"stream":"btcusdt@bookTicker","event_type":"bookTicker","event_time_ms":1788563397606,"raw_json":"{\"stream\":\"btcusdt@bookTicker\",\"data\":{\"e\":\"bookTicker\",\"u\":11478233471121,\"s\":\"BTCUSDT\",\"ps\":\"BTCUSDT\",\"b\":\"79607.10\",\"B\":\"5.102\",\"a\":\"79607.20\",\"A\":\"7.474\",\"T\":1788563397606,\"E\":1788563397606,\"st\":1}}"}
{"receive_ns":1788563397570011000,"stream":"btcusdt@bookTicker","event_type":"bookTicker","event_time_ms":1788563397610,"raw_json":"{\"stream\":\"btcusdt@bookTicker\",\"data\":{\"e\":\"bookTicker\",\"u\":11478233471254,\"s\":\"BTCUSDT\",\"ps\":\"BTCUSDT\",\"b\":\"79607.10\",\"B\":\"5.117\",\"a\":\"79607.20\",\"A\":\"7.474\",\"T\":1788563397610,\"E\":1788563397610,\"st\":1}}"}
{"receive_ns":1788563397570257000,"stream":"btcusdt@bookTicker","event_type":"bookTicker","event_time_ms":1788563397611,"raw_json":"{\"stream\":\"btcusdt@bookTicker\",\"data\":{\"e\":\"bookTicker\",\"u\":11478233471328,\"s\":\"BTCUSDT\",\"ps\":\"BTCUSDT\",\"b\":\"79607.10\",\"B\":\"5.115\",\"a\":\"79607.20\",\"A\":\"7.474\",\"T\":1788563397611,\"E\":1788563397611,\"st\":1}}"}
{"receive_ns":1788563397605558000,"stream":"btcusdt@bookTicker","event_type":"bookTicker","event_time_ms":1788563397646,"raw_json":"{\"stream\":\"btcusdt@bookTicker\",\"data\":{\"e\":\"bookTicker\",\"u\":11478233472220,\"s\":\"BTCUSDT\",\"ps\":\"BTCUSDT\",\"b\":\"79607.10\",\"B\":\"5.099\",\"a\":\"79607.20\",\"A\":\"7.474\",\"T\":1788563397645,\"E\":1788563397646,\"st\":1}}"}
{"receive_ns":1788563397606637000,"stream":"btcusdt@bookTicker","event_type":"bookTicker","event_time_ms":1788563397649,"raw_json":"{\"stream\":\"btcusdt@bookTicker\",\"data\":{\"e\":\"bookTicker\",\"u\":11478233472323,\"s\":\"BTCUSDT\",\"ps\":\"BTCUSDT\",\"b\":\"79607.10\",\"B\":\"5.117\",\"a\":\"79607.20\",\"A\":\"7.474\",\"T\":1788563397649,\"E\":1788563397649,\"st\":1}}"}
{"receive_ns":1788563397607799000,"stream":"btcusdt@bookTicker","event_type":"bookTicker","event_time_ms":1788563397650,"raw_json":"{\"stream\":\"btcusdt@bookTicker\",\"data\":{\"e\":\"bookTicker\",\"u\":11478233472363,\"s\":\"BTCUSDT\",\"ps\":\"BTCUSDT\",\"b\":\"79607.10\",\"B\":\"5.119\",\"a\":\"79607.20\",\"A\":\"7.474\",\"T\":1788563397650,\"E\":1788563397650,\"st\":1}}"}
{"receive_ns":1788563397629249000,"stream":"btcusdt@depth@100ms","event_type":"depthUpdate","event_time_ms":1788563397671,"raw_json":"{\"stream\":\"btcusdt@depth@100ms\",\"data\":{\"e\":\"depthUpdate\",\"E\":1788563397671,\"T\":1788563397670,\"s\":\"BTCUSDT\",\"ps\":\"BTCUSDT\",\"U\":11478233469990,\"u\":11478233473012,\"pu\":11478233469881,\"b\":[[\"1000.00\",\"24.754\"],[\"29107.10\",\"1.309\"],[\"29207.10\",\"0.791\"],[\"71646.30\",\"0.002\"],[\"75626.70\",\"0.027\"],[\"75626.80\",\"0.002\"],[\"78690.80\",\"6.052\"],[\"78723.20\",\"0.000\"],[\"78811.00\",\"15.338\"],[\"79010.00\",\"4.312\"],[\"79232.90\",\"0.141\"],[\"79491.70\",\"0.583\"],[\"79516.00\",\"4.572\"],[\"79522.80\",\"0.125\"],[\"79523.10\",\"0.000\"],[\"79533.80\",\"3.459\"],[\"79535.50\",\"0.000\"],[\"79582.90\",\"0.628\"],[\"79583.20\",\"0.579\"],[\"79583.80\",\"0.001\"],[\"79589.20\",\"0.395\"],[\"79593.30\",\"0.077\"],[\"79593.50\",\"0.003\"],[\"79594.50\",\"0.226\"],[\"79595.10\",\"2.225\"],[\"79603.60\",\"1.519\"],[\"79603.70\",\"0.011\"],[\"79604.80\",\"0.028\"],[\"79604.90\",\"0.026\"],[\"79605.20\",\"0.002\"],[\"79605.60\",\"0.026\"],[\"79605.70\",\"0.138\"],[\"79606.30\",\"0.093\"],[\"79606.50\",\"0.026\"],[\"79607.10\",\"5.119\"]],\"a\":[[\"79616.00\",\"0.459\"],[\"79618.30\",\"0.001\"],[\"79620.60\",\"7.703\"],[\"79621.90\",\"0.372\"],[\"79623.20\",\"0.190\"],[\"79624.40\",\"0.000\"],[\"79625.40\",\"0.452\"],[\"79772.40\",\"0.255\"],[\"79968.00\",\"0.867\"],[\"79969.40\",\"1.160\"],[\"79995.30\",\"0.002\"],[\"79997.80\",\"0.525\"],[\"80204.30\",\"3.735\"],[\"80403.30\",\"22.314\"],[\"80562.50\",\"51.076\"],[\"81199.30\",\"14.222\"]],\"st\":1}}"}
{"receive_ns":1788563397694207000,"stream":"btcusdt@bookTicker","event_type":"bookTicker","event_time_ms":1788563397725,"raw_json":"{\"stream\":\"btcusdt@bookTicker\",\"data\":{\"e\":\"bookTicker\",\"u\":11478233474836,\"s\":\"BTCUSDT\",\"ps\":\"BTCUSDT\",\"b\":\"79607.10\",\"B\":\"4.460\",\"a\":\"79607.20\",\"A\":\"7.474\",\"T\":1788563397725,\"E\":1788563397725,\"st\":1}}"}
{"receive_ns":1788563397694667000,"stream":"btcusdt@bookTicker","event_type":"bookTicker","event_time_ms":1788563397728,"raw_json":"{\"stream\":\"btcusdt@bookTicker\",\"data\":{\"e\":\"bookTicker\",\"u\":11478233474997,\"s\":\"BTCUSDT\",\"ps\":\"BTCUSDT\",\"b\":\"79607.10\",\"B\":\"5.128\",\"a\":\"79607.20\",\"A\":\"7.474\",\"T\":1788563397728,\"E\":1788563397728,\"st\":1}}"}
{"receive_ns":1788563397695033000,"stream":"btcusdt@bookTicker","event_type":"bookTicker","event_time_ms":1788563397729,"raw_json":"{\"stream\":\"btcusdt@bookTicker\",\"data\":{\"e\":\"bookTicker\",\"u\":11478233475027,\"s\":\"BTCUSDT\",\"ps\":\"BTCUSDT\",\"b\":\"79607.10\",\"B\":\"5.126\",\"a\":\"79607.20\",\"A\":\"7.474\",\"T\":1788563397729,\"E\":1788563397729,\"st\":1}}"}
{"receive_ns":1788563397727983000,"stream":"btcusdt@bookTicker","event_type":"bookTicker","event_time_ms":1788563397762,"raw_json":"{\"stream\":\"btcusdt@bookTicker\",\"data\":{\"e\":\"bookTicker\",\"u\":11478233475810,\"s\":\"BTCUSDT\",\"ps\":\"BTCUSDT\",\"b\":\"79607.10\",\"B\":\"5.126\",\"a\":\"79607.20\",\"A\":\"7.467\",\"T\":1788563397761,\"E\":1788563397762,\"st\":1}}"}
{"receive_ns":1788563397728366000,"stream":"btcusdt@trade","event_type":"trade","event_time_ms":1788563397762,"raw_json":"{\"stream\":\"btcusdt@trade\",\"data\":{\"e\":\"trade\",\"E\":1788563397762,\"T\":1788563397761,\"s\":\"BTCUSDT\",\"t\":8054083510,\"p\":\"79607.20\",\"q\":\"0.007\",\"X\":\"MARKET\",\"m\":false,\"st\":1}}"}
{"receive_ns":1788563397732176000,"stream":"btcusdt@depth@100ms","event_type":"depthUpdate","event_time_ms":1788563397773,"raw_json":"{\"stream\":\"btcusdt@depth@100ms\",\"data\":{\"e\":\"depthUpdate\",\"E\":1788563397773,\"T\":1788563397772,\"s\":\"BTCUSDT\",\"ps\":\"BTCUSDT\",\"U\":11478233473043,\"u\":11478233476312,\"pu\":11478233473012,\"b\":[[\"29107.10\",\"1.491\"],[\"29207.10\",\"0.609\"],[\"63685.70\",\"0.001\"],[\"71646.30\",\"0.002\"],[\"76422.80\",\"0.000\"],[\"78492.60\",\"55.001\"],[\"78651.80\",\"54.189\"],[\"78811.00\",\"14.071\"],[\"78970.20\",\"8.759\"],[\"79058.00\",\"0.005\"],[\"79209.10\",\"4.608\"],[\"79232.30\",\"0.000\"],[\"79235.90\",\"0.285\"],[\"79351.40\",\"0.003\"],[\"79351.90\",\"1.090\"],[\"79360.00\",\"0.924\"],[\"79483.40\",\"0.500\"],[\"79550.90\",\"0.070\"],[\"79594.50\",\"0.150\"],[\"79595.00\",\"0.112\"],[\"79595.20\",\"0.149\"],[\"79596.40\",\"0.143\"],[\"79597.10\",\"0.033\"],[\"79597.60\",\"0.000\"],[\"79599.20\",\"0.005\"],[\"79600.90\",\"0.002\"],[\"79605.80\",\"0.027\"],[\"79606.30\",\"0.067\"],[\"79606.50\",\"0.000\"],[\"79607.10\",\"5.126\"]],\"a\":[[\"79607.20\",\"7.467\"],[\"79616.00\",\"0.020\"],[\"79618.30\",\"0.440\"],[\"79728.80\",\"0.276\"],[\"79848.00\",\"1.532\"],[\"79850.50\",\"0.010\"],[\"79969.30\",\"0.560\"],[\"79969.60\",\"0.000\"],[\"79970.30\",\"0.005\"],[\"80146.20\",\"0.004\"],[\"80320.10\",\"7.182\"],[\"80403.30\",\"21.072\"],[\"80638.40\",\"18.082\"]],\"st\":1}}"}
{"receive_ns":1788563397801796000,"stream":"btcusdt@bookTicker","event_type":"bookTicker","event_time_ms":1788563397843,"raw_json":"{\"stream\":\"btcusdt@bookTicker\",\"data\":{\"e\":\"bookTicker\",\"u\":11478233479310,\"s\":\"BTCUSDT\",\"ps\":\"BTCUSDT\",\"b\":\"79607.10\",\"B\":\"5.126\",\"a\":\"79607.20\",\"A\":\"7.465\",\"T\":1788563397843,\"E\":1788563397843,\"st\":1}}"}
{"receive_ns":1788563397833125000,"stream":"btcusdt@depth@100ms","event_type":"depthUpdate","event_time_ms":1788563397875,"raw_json":"{\"stream\":\"btcusdt@depth@100ms\",\"data\":{\"e\":\"depthUpdate\",\"E\":1788563397875,\"T\":1788563397874,\"s\":\"BTCUSDT\",\"ps\":\"BTCUSDT\",\"U\":11478233476355,\"u\":11478233480759,\"pu\":11478233476312,\"b\":[[\"1000.00\",\"24.754\"],[\"29107.10\",\"1.673\"],[\"29207.10\",\"0.427\"],[\"71646.30\",\"0.002\"],[\"71684.00\",\"0.000\"],[\"75626.70\",\"0.029\"],[\"76422.80\",\"0.002\"],[\"78452.80\",\"41.237\"],[\"78691.60\",\"11.528\"],[\"78727.90\",\"13.003\"],[\"78811.00\",\"14.071\"],[\"79209.00\",\"0.000\"],[\"79232.90\",\"0.000\"],[\"79342.30\",\"1.553\"],[\"79343.30\",\"0.664\"],[\"79491.70\",\"0.000\"],[\"79543.70\",\"0.572\"],[\"79559.30\",\"0.144\"],[\"79583.20\",\"0.002\"],[\"79583.40\",\"0.006\"],[\"79589.20\",\"0.195\"],[\"79594.50\",\"0.150\"],[\"79597.60\",\"0.002\"],[\"79599.20\",\"0.003\"],[\"79605.20\",\"0.028\"],[\"79605.60\",\"0.052\"],[\"79605.80\",\"0.001\"],[\"79606.10\",\"0.000\"]],\"a\":[[\"79607.20\",\"7.465\"],[\"79623.30\",\"0.458\"],[\"79772.40\",\"0.004\"],[\"79870.10\",\"1.547\"],[\"79968.00\",\"0.104\"],[\"79969.40\",\"0.001\"],[\"79997.80\",\"0.000\"],[\"80005.30\",\"0.003\"],[\"80403.30\",\"21.072\"],[\"80562.50\",\"52.316\"],[\"80713.70\",\"9.048\"]],\"st\":1}}"}
{"receive_ns":1788563397936536000,"stream":"btcusdt@depth@100ms","event_type":"depthUpdate","event_time_ms":1788563397977,"raw_json":"{\"stream\":\"btcusdt@depth@100ms\",\"data\":{\"e\":\"depthUpdate\",\"E\":1788563397977,\"T\":1788563397975,\"s\":\"BTCUSDT\",\"ps\":\"BTCUSDT\",\"U\":11478233480776,\"u\":11478233485276,\"pu\":11478233480759,\"b\":[[\"1000.00\",\"24.754\"],[\"29107.10\",\"1.778\"],[\"29207.10\",\"0.287\"],[\"29507.10\",\"0.035\"],[\"71646.30\",\"0.002\"],[\"76422.80\",\"0.000\"],[\"78532.40\",\"12.943\"],[\"78568.60\",\"0.254\"],[\"78584.40\",\"0.001\"],[\"78729.60\",\"3.419\"],[\"78811.00\",\"14.073\"],[\"78844.60\",\"0.000\"],[\"79209.10\",\"4.749\"],[\"79444.00\",\"0.294\"],[\"79483.40\",\"0.000\"],[\"79491.70\",\"0.232\"],[\"79511.50\",\"0.024\"],[\"79548.90\",\"0.032\"],[\"79551.30\",\"0.105\"],[\"79575.80\",\"1.728\"],[\"79583.20\",\"0.855\"],[\"79583.80\",\"0.001\"],[\"79589.20\",\"0.470\"],[\"79596.70\",\"0.132\"],[\"79598.00\",\"0.201\"],[\"79605.60\",\"0.026\"],[\"79606.90\",\"0.197\"]],\"a\":[[\"79702.80\",\"0.010\"],[\"79705.70\",\"0.126\"],[\"79705.80\",\"4.776\"],[\"79726.70\",\"0.002\"],[\"79728.80\",\"0.000\"],[\"79768.20\",\"0.000\"],[\"79969.30\",\"0.000\"],[\"79987.30\",\"1.210\"],[\"79997.80\",\"1.288\"],[\"79999.30\",\"0.211\"],[\"80244.10\",\"8.371\"],[\"80323.70\",\"24.214\"],[\"80362.60\",\"0.001\"],[\"80403.30\",\"21.072\"],[\"80627.80\",\"0.000\"]],\"st\":1}}"}
{"receive_ns":1788563398018819000,"stream":"btcusdt@bookTicker","event_type":"bookTicker","event_time_ms":1788563398059,"raw_json":"{\"stream\":\"btcusdt@bookTicker\",\"data\":{\"e\":\"bookTicker\",\"u\":11478233488377,\"s\":\"BTCUSDT\",\"ps\":\"BTCUSDT\",\"b\":\"79607.10\",\"B\":\"5.126\",\"a\":\"79607.20\",\"A\":\"7.467\",\"T\":1788563398058,\"E\":1788563398059,\"st\":1}}"}
{"receive_ns":1788563398038247000,"stream":"btcusdt@depth@100ms","event_type":"depthUpdate","event_time_ms":1788563398079,"raw_json":"{\"stream\":\"btcusdt@depth@100ms\",\"data\":{\"e\":\"depthUpdate\",\"E\":1788563398079,\"T\":1788563398077,\"s\":\"BTCUSDT\",\"ps\":\"BTCUSDT\",\"U\":11478233485335,\"u\":11478233489368,\"pu\":11478233485276,\"b\":[[\"29107.10\",\"1.841\"],[\"29207.10\",\"0.168\"],[\"29507.10\",\"0.091\"],[\"71646.30\",\"0.002\"],[\"76422.80\",\"0.002\"],[\"78427.10\",\"1.527\"],[\"78452.80\",\"42.128\"],[\"78612.00\",\"16.992\"],[\"78691.60\",\"12.290\"],[\"78811.00\",\"14.071\"],[\"79058.10\",\"0.000\"],[\"79058.20\",\"55.654\"],[\"79058.30\",\"0.648\"],[\"79209.10\",\"4.739\"],[\"79232.40\",\"0.000\"],[\"79232.50\",\"43.524\"],[\"79232.60\",\"0.164\"],[\"79235.90\",\"6.749\"],[\"79351.50\",\"36.296\"],[\"79444.00\",\"2.596\"],[\"79483.40\",\"0.500\"],[\"79533.60\",\"0.830\"],[\"79549.50\",\"0.728\"],[\"79592.80\",\"0.004\"]],\"a\":[[\"79607.20\",\"7.467\"],[\"79625.80\",\"0.086\"],[\"79728.80\",\"0.276\"],[\"79768.20\",\"1.216\"],[\"79848.00\",\"6.784\"],[\"79850.30\",\"36.417\"],[\"79970.00\",\"1.319\"],[\"79970.10\",\"44.257\"],[\"79970.20\",\"0.003\"],[\"80146.10\",\"56.285\"],[\"80403.30\",\"21.072\"],[\"80562.50\",\"51.076\"]],\"st\":1}}"}
{"receive_ns":1788563398112077000,"stream":"btcusdt@bookTicker","event_type":"bookTicker","event_time_ms":1788563398153,"raw_json":"{\"stream\":\"btcusdt@bookTicker\",\"data\":{\"e\":\"bookTicker\",\"u\":11478233493164,\"s\":\"BTCUSDT\",\"ps\":\"BTCUSDT\",\"b\":\"79607.10\",\"B\":\"5.111\",\"a\":\"79607.20\",\"A\":\"7.467\",\"T\":1788563398153,\"E\":1788563398153,\"st\":1}}"}
{"receive_ns":1788563398114294000,"stream":"btcusdt@bookTicker","event_type":"bookTicker","event_time_ms":1788563398156,"raw_json":"{\"stream\":\"btcusdt@bookTicker\",\"data\":{\"e\":\"bookTicker\",\"u\":11478233493349,\"s\":\"BTCUSDT\",\"ps\":\"BTCUSDT\",\"b\":\"79607.10\",\"B\":\"5.126\",\"a\":\"79607.20\",\"A\":\"7.467\",\"T\":1788563398156,\"E\":1788563398156,\"st\":1}}"}
{"receive_ns":1788563398114547000,"stream":"btcusdt@bookTicker","event_type":"bookTicker","event_time_ms":1788563398157,"raw_json":"{\"stream\":\"btcusdt@bookTicker\",\"data\":{\"e\":\"bookTicker\",\"u\":11478233493386,\"s\":\"BTCUSDT\",\"ps\":\"BTCUSDT\",\"b\":\"79607.10\",\"B\":\"5.128\",\"a\":\"79607.20\",\"A\":\"7.467\",\"T\":1788563398157,\"E\":1788563398157,\"st\":1}}"}
{"receive_ns":1788563398116932000,"stream":"btcusdt@bookTicker","event_type":"bookTicker","event_time_ms":1788563398158,"raw_json":"{\"stream\":\"btcusdt@bookTicker\",\"data\":{\"e\":\"bookTicker\",\"u\":11478233493425,\"s\":\"BTCUSDT\",\"ps\":\"BTCUSDT\",\"b\":\"79607.10\",\"B\":\"5.127\",\"a\":\"79607.20\",\"A\":\"7.467\",\"T\":1788563398158,\"E\":1788563398158,\"st\":1}}"}
{"receive_ns":1788563398117295000,"stream":"btcusdt@trade","event_type":"trade","event_time_ms":1788563398158,"raw_json":"{\"stream\":\"btcusdt@trade\",\"data\":{\"e\":\"trade\",\"E\":1788563398158,\"T\":1788563398158,\"s\":\"BTCUSDT\",\"t\":8054083511,\"p\":\"79607.10\",\"q\":\"0.001\",\"X\":\"MARKET\",\"m\":true,\"st\":1}}"}
{"receive_ns":1788563398117746000,"stream":"btcusdt@bookTicker","event_type":"bookTicker","event_time_ms":1788563398159,"raw_json":"{\"stream\":\"btcusdt@bookTicker\",\"data\":{\"e\":\"bookTicker\",\"u\":11478233493541,\"s\":\"BTCUSDT\",\"ps\":\"BTCUSDT\",\"b\":\"79607.10\",\"B\":\"5.089\",\"a\":\"79607.20\",\"A\":\"7.467\",\"T\":1788563398159,\"E\":1788563398159,\"st\":1}}"}
{"receive_ns":1788563398140497000,"stream":"btcusdt@depth@100ms","event_type":"depthUpdate","event_time_ms":1788563398181,"raw_json":"{\"stream\":\"btcusdt@depth@100ms\",\"data\":{\"e\":\"depthUpdate\",\"E\":1788563398181,\"T\":1788563398178,\"s\":\"BTCUSDT\",\"ps\":\"BTCUSDT\",\"U\":11478233489491,\"u\":11478233494191,\"pu\":11478233489368,\"b\":[[\"1000.00\",\"24.754\"],[\"29107.10\",\"1.897\"],[\"29207.10\",\"0.049\"],[\"29507.10\",\"0.154\"],[\"71646.30\",\"0.002\"],[\"77157.70\",\"0.000\"],[\"78015.00\",\"12.492\"],[\"78436.90\",\"9.206\"],[\"78492.60\",\"53.092\"],[\"78584.50\",\"85.689\"],[\"78651.80\",\"52.919\"],[\"78811.00\",\"14.071\"],[\"78844.70\",\"69.863\"],[\"78890.60\",\"44.085\"],[\"79209.10\",\"4.598\"],[\"79232.90\",\"0.141\"],[\"79491.70\",\"0.232\"],[\"79521.40\",\"0.000\"],[\"79523.90\",\"1.619\"],[\"79549.20\",\"0.000\"],[\"79550.90\",\"0.000\"],[\"79551.70\",\"0.639\"],[\"79569.10\",\"0.000\"],[\"79583.20\",\"0.855\"],[\"79583.80\",\"0.001\"],[\"79589.20\",\"0.470\"],[\"79594.50\",\"0.150\"],[\"79597.60\",\"0.000\"],[\"79605.20\",\"0.002\"],[\"79605.60\",\"0.052\"],[\"79606.20\",\"0.003\"],[\"79607.10\",\"5.089\"]],\"a\":[[\"79609.30\",\"0.000\"],[\"79616.00\",\"0.020\"],[\"79618.30\",\"0.440\"],[\"79639.30\",\"0.006\"],[\"79655.00\",\"0.002\"],[\"79659.20\",\"0.042\"],[\"79685.00\",\"0.760\"],[\"79687.10\",\"0.001\"],[\"79969.40\",\"1.211\"],[\"79987.30\",\"0.000\"],[\"79993.90\",\"0.264\"],[\"79995.30\",\"0.158\"],[\"79995.80\",\"0.863\"],[\"79997.80\",\"0.525\"],[\"79999.30\",\"0.055\"],[\"80403.30\",\"21.072\"],[\"80832.00\",\"1.732\"]],\"st\":1}}"}
{"receive_ns":1788563398242138000,"stream":"btcusdt@depth@100ms","event_type":"depthUpdate","event_time_ms":1788563398283,"raw_json":"{\"stream\":\"btcusdt@depth@100ms\",\"data\":{\"e\":\"depthUpdate\",\"E\":1788563398283,\"T\":1788563398282,\"s\":\"BTCUSDT\",\"ps\":\"BTCUSDT\",\"U\":11478233494354,\"u\":11478233498796,\"pu\":11478233494191,\"b\":[[\"1000.00\",\"24.754\"],[\"29107.10\",\"1.813\"],[\"29207.10\",\"0.000\"],[\"29507.10\",\"0.287\"],[\"63686.00\",\"0.002\"],[\"71646.30\",\"0.004\"],[\"76362.20\",\"0.000\"],[\"76422.80\",\"0.000\"],[\"77953.10\",\"0.000\"],[\"78739.40\",\"7.789\"],[\"78811.00\",\"12.804\"],[\"79010.00\",\"3.680\"],[\"79481.60\",\"0.004\"],[\"79482.30\",\"2.138\"],[\"79584.80\",\"0.256\"],[\"79593.30\",\"0.001\"],[\"79603.60\",\"1.545\"],[\"79603.70\",\"0.037\"],[\"79604.80\",\"0.002\"],[\"79604.90\",\"0.000\"],[\"79605.00\",\"0.630\"],[\"79605.10\",\"0.000\"],[\"79605.50\",\"0.028\"],[\"79605.60\",\"0.026\"],[\"79605.70\",\"0.164\"]],\"a\":[[\"79609.40\",\"0.267\"],[\"79621.90\",\"0.000\"],[\"79623.00\",\"0.372\"],[\"79639.30\",\"0.417\"],[\"79659.20\",\"3.542\"],[\"79687.10\",\"6.001\"],[\"79709.70\",\"0.830\"],[\"79724.40\",\"0.686\"],[\"79725.90\",\"0.200\"],[\"80204.30\",\"3.113\"],[\"80335.90\",\"0.197\"],[\"80403.30\",\"21.072\"],[\"80638.60\",\"3.035\"]],\"st\":1}}"}
{"receive_ns":1788563398333124000,"stream":"btcusdt@bookTicker","event_type":"bookTicker","event_time_ms":1788563398367,"raw_json":"{\"stream\":\"btcusdt@bookTicker\",\"data\":{\"e\":\"bookTicker\",\"u\":11478233502015,\"s\":\"BTCUSDT\",\"ps\":\"BTCUSDT\",\"b\":\"79607.10\",\"B\":\"5.127\",\"a\":\"79607.20\",\"A\":\"7.467\",\"T\":1788563398366,\"E\":1788563398367,\"st\":1}}"}
{"receive_ns":1788563398333458000,"stream":"btcusdt@bookTicker","event_type":"bookTicker","event_time_ms":1788563398368,"raw_json":"{\"stream\":\"btcusdt@bookTicker\",\"data\":{\"e\":\"bookTicker\",\"u\":11478233502065,\"s\":\"BTCUSDT\",\"ps\":\"BTCUSDT\",\"b\":\"79607.10\",\"B\":\"5.126\",\"a\":\"79607.20\",\"A\":\"7.467\",\"T\":1788563398368,\"E\":1788563398368,\"st\":1}}"}
{"receive_ns":1788563398333752000,"stream":"btcusdt@bookTicker","event_type":"bookTicker","event_time_ms":1788563398369,"raw_json":"{\"stream\":\"btcusdt@bookTicker\",\"data\":{\"e\":\"bookTicker\",\"u\":11478233502101,\"s\":\"BTCUSDT\",\"ps\":\"BTCUSDT\",\"b\":\"79607.10\",\"B\":\"5.127\",\"a\":\"79607.20\",\"A\":\"7.467\",\"T\":1788563398369,\"E\":1788563398369,\"st\":1}}"}
