{"receive_ns":1788563372342694000,"stream":"btcusdt@depth@100ms","event_type":"depthUpdate","event_time_ms":1788563372375,"raw_json":"{\"stream\":\"btcusdt@depth@100ms\",\"data\":{\"e\":\"depthUpdate\",\"E\":1788563372375,\"T\":1788563372373,\"s\":\"BTCUSDT\",\"ps\":\"BTCUSDT\",\"U\":11478232311672,\"u\":11478232315723,\"pu\":11478232311557,\"b\":[[\"1000.00\",\"24.754\"],[\"29207.10\",\"1.148\"],[\"29307.10\",\"0.952\"],[\"63686.00\",\"0.000\"],[\"71646.30\",\"0.002\"],[\"75626.70\",\"0.033\"],[\"75626.80\",\"0.006\"],[\"76422.80\",\"0.002\"],[\"78811.00\",\"15.338\"],[\"78850.80\",\"15.287\"],[\"78970.20\",\"7.748\"],[\"79573.00\",\"0.179\"],[\"79574.20\",\"0.003\"],[\"79583.20\",\"0.855\"],[\"79589.20\",\"0.470\"],[\"79591.80\",\"0.078\"],[\"79602.50\",\"0.027\"],[\"79602.60\",\"0.027\"]],\"a\":[[\"79842.60\",\"0.000\"],[\"79963.40\",\"0.509\"],[\"79967.40\",\"0.199\"],[\"79999.30\",\"0.211\"],[\"80244.10\",\"7.624\"],[\"80403.30\",\"22.286\"],[\"80465.80\",\"0.385\"],[\"80562.50\",\"45.812\"],[\"80721.70\",\"56.177\"]],\"st\":1}}"}
{"receive_ns":1788563372391992000,"stream":"btcusdt@bookTicker","event_type":"bookTicker","event_time_ms":1788563372429,"raw_json":"{\"stream\":\"btcusdt@bookTicker\",\"data\":{\"e\":\"bookTicker\",\"u\":11478232318329,\"s\":\"BTCUSDT\",\"ps\":\"BTCUSDT\",\"b\":\"79607.10\",\"B\":\"5.017\",\"a\":\"79607.20\",\"A\":\"7.418\",\"T\":1788563372428,\"E\":1788563372429,\"st\":1}}"}
{"receive_ns":1788563372398871000,"stream":"btcusdt@bookTicker","event_type":"bookTicker","event_time_ms":1788563372430,"raw_json":"{\"stream\":\"btcusdt@bookTicker\",\"data\":{\"e\":\"bookTicker\",\"u\":11478232318358,\"s\":\"BTCUSDT\",\"ps\":\"BTCUSDT\",\"b\":\"79607.10\",\"B\":\"5.019\",\"a\":\"79607.20\",\"A\":\"7.418\",\"T\":1788563372429,\"E\":1788563372430,\"st\":1}}"}
{"receive_ns":1788563372399510000,"stream":"btcusdt@bookTicker","event_type":"bookTicker","event_time_ms":1788563372432,"raw_json":"{\"stream\":\"btcusdt@bookTicker\",\"data\":{\"e\":\"bookTicker\",\"u\":11478232318451,\"s\":\"BTCUSDT\",\"ps\":\"BTCUSDT\",\"b\":\"79607.10\",\"B\":\"5.530\",\"a\":\"79607.20\",\"A\":\"7.418\",\"T\":1788563372431,\"E\":1788563372432,\"st\":1}}"}
{"receive_ns":1788563372447323000,"stream":"btcusdt@depth@100ms","event_type":"depthUpdate","event_time_ms":1788563372477,"raw_json":"{\"stream\":\"btcusdt@depth@100ms\",\"data\":{\"e\":\"depthUpdate\",\"E\":1788563372477,\"T\":1788563372473,\"s\":\"BTCUSDT\",\"ps\":\"BTCUSDT\",\"U\":11478232315811,\"u\":11478232320179,\"pu\":11478232315723,\"b\":[[\"1000.00\",\"24.754\"],[\"29207.10\",\"1.323\"],[\"29307.10\",\"0.777\"],[\"63685.70\",\"0.001\"],[\"71646.30\",\"0.002\"],[\"76422.80\",\"0.000\"],[\"78651.80\",\"48.159\"],[\"78811.00\",\"15.338\"],[\"79232.90\",\"0.141\"],[\"79407.80\",\"0.002\"],[\"79407.90\",\"0.408\"],[\"79491.70\",\"0.232\"],[\"79577.10\",\"0.398\"],[\"79580.50\",\"0.260\"],[\"79581.80\",\"2.873\"],[\"79583.20\",\"0.855\"],[\"79583.80\",\"2.009\"],[\"79593.10\",\"0.001\"],[\"79600.90\",\"0.001\"],[\"79602.80\",\"0.026\"],[\"79603.20\",\"0.003\"],[\"79606.60\",\"0.001\"],[\"79607.10\",\"5.530\"]],\"a\":[[\"79774.40\",\"2.003\"],[\"79840.80\",\"0.503\"],[\"79963.40\",\"0.921\"],[\"79964.00\",\"0.001\"],[\"79967.40\",\"0.289\"],[\"79995.80\",\"0.863\"],[\"79997.80\",\"0.525\"],[\"80403.30\",\"22.286\"],[\"81199.30\",\"4.472\"]],\"st\":1}}"}
{"receive_ns":1788563372528083000,"stream":"btcusdt@bookTicker","event_type":"bookTicker","event_time_ms":1788563372563,"raw_json":"{\"stream\":\"btcusdt@bookTicker\",\"data\":{\"e\":\"bookTicker\",\"u\":11478232324426,\"s\":\"BTCUSDT\",\"ps\":\"BTCUSDT\",\"b\":\"79607.10\",\"B\":\"5.448\",\"a\":\"79607.20\",\"A\":\"7.418\",\"T\":1788563372563,\"E\":1788563372563,\"st\":1}}"}
{"receive_ns":1788563372528389000,"stream":"btcusdt@trade","event_type":"trade","event_time_ms":1788563372563,"raw_json":"{\"stream\":\"btcusdt@trade\",\"data\":{\"e\":\"trade\",\"E\":1788563372563,\"T\":1788563372563,\"s\":\"BTCUSDT\",\"t\":8054083436,\"p\":\"79607.10\",\"q\":\"0.042\",\"X\":\"MARKET\",\"m\":true,\"st\":1}}"}
{"receive_ns":1788563372528537000,"stream":"btcusdt@trade","event_type":"trade","event_time_ms":1788563372563,"raw_json":"{\"stream\":\"btcusdt@trade\",\"data\":{\"e\":\"trade\",\"E\":1788563372563,\"T\":1788563372563,\"s\":\"BTCUSDT\",\"t\":8054083437,\"p\":\"79607.10\",\"q\":\"0.010\",\"X\":\"MARKET\",\"m\":true,\"st\":1}}"}
{"receive_ns":1788563372528674000,"stream":"btcusdt@trade","event_type":"trade","event_time_ms":1788563372563,"raw_json":"{\"stream\":\"btcusdt@trade\",\"data\":{\"e\":\"trade\",\"E\":1788563372563,\"T\":1788563372563,\"s\":\"BTCUSDT\",\"t\":8054083438,\"p\":\"79607.10\",\"q\":\"0.002\",\"X\":\"MARKET\",\"m\":true,\"st\":1}}"}
{"receive_ns":1788563372528819000,"stream":"btcusdt@trade","event_type":"trade","event_time_ms":1788563372563,"raw_json":"{\"stream\":\"btcusdt@trade\",\"data\":{\"e\":\"trade\",\"E\":1788563372563,\"T\":1788563372563,\"s\":\"BTCUSDT\",\"t\":8054083439,\"p\":\"79607.10\",\"q\":\"0.003\",\"X\":\"MARKET\",\"m\":true,\"st\":1}}"}
{"receive_ns":1788563372528975000,"stream":"btcusdt@trade","event_type":"trade","event_time_ms":1788563372563,"raw_json":"{\"stream\":\"btcusdt@trade\",\"data\":{\"e\":\"trade\",\"E\":1788563372563,\"T\":1788563372563,\"s\":\"BTCUSDT\",\"t\":8054083440,\"p\":\"79607.10\",\"q\":\"0.001\",\"X\":\"MARKET\",\"m\":true,\"st\":1}}"}
{"receive_ns":1788563372529154000,"stream":"btcusdt@trade","event_type":"trade","event_time_ms":1788563372563,"raw_json":"{\"stream\":\"btcusdt@trade\",\"data\":{\"e\":\"trade\",\"E\":1788563372563,\"T\":1788563372563,\"s\":\"BTCUSDT\",\"t\":8054083441,\"p\":\"79607.10\",\"q\":\"0.001\",\"X\":\"MARKET\",\"m\":true,\"st\":1}}"}
{"receive_ns":1788563372529359000,"stream":"btcusdt@trade","event_type":"trade","event_time_ms":1788563372563,"raw_json":"{\"stream\":\"btcusdt@trade\",\"data\":{\"e\":\"trade\",\"E\":1788563372563,\"T\":1788563372563,\"s\":\"BTCUSDT\",\"t\":8054083442,\"p\":\"79607.10\",\"q\":\"0.023\",\"X\":\"MARKET\",\"m\":true,\"st\":1}}"}
{"receive_ns":1788563372547630000,"stream":"btcusdt@depth@100ms","event_type":"depthUpdate","event_time_ms":1788563372579,"raw_json":"{\"stream\":\"btcusdt@depth@100ms\",\"data\":{\"e\":\"depthUpdate\",\"E\":1788563372579,\"T\":1788563372578,\"s\":\"BTCUSDT\",\"ps\":\"BTCUSDT\",\"U\":11478232320287,\"u\":11478232325173,\"pu\":11478232320179,\"b\":[[\"29207.10\",\"1.505\"],[\"29307.10\",\"0.595\"],[\"71646.30\",\"0.002\"],[\"78015.00\",\"4.417\"],[\"78730.50\",\"0.000\"],[\"78739.40\",\"6.333\"],[\"78811.00\",\"15.338\"],[\"79209.10\",\"3.977\"],[\"79482.60\",\"0.001\"],[\"79582.90\",\"0.076\"],[\"79583.20\",\"0.353\"],[\"79583.70\",\"0.644\"],[\"79583.80\",\"0.001\"],[\"79588.30\",\"0.008\"],[\"79589.20\",\"0.697\"],[\"79591.80\",\"0.002\"],[\"79602.50\",\"0.001\"],[\"79602.60\",\"0.027\"],[\"79602.80\",\"0.000\"],[\"79605.50\",\"0.002\"],[\"79606.80\",\"0.039\"],[\"79607.10\",\"5.448\"]],\"a\":[[\"79728.70\",\"0.000\"],[\"79963.40\",\"0.921\"],[\"79967.40\",\"0.090\"],[\"79999.30\",\"0.167\"],[\"80403.30\",\"22.286\"],[\"80474.90\",\"6.816\"],[\"81199.30\",\"4.475\"]],\"st\":1}}"}
{"receive_ns":1788563372552926000,"stream":"btcusdt@bookTicker","event_type":"bookTicker","event_time_ms":1788563372587,"raw_json":"{\"stream\":\"btcusdt@bookTicker\",\"data\":{\"e\":\"bookTicker\",\"u\":11478232325524,\"s\":\"BTCUSDT\",\"ps\":\"BTCUSDT\",\"b\":\"79607.10\",\"B\":\"5.453\",\"a\":\"79607.20\",\"A\":\"7.418\",\"T\":1788563372587,\"E\":1788563372587,\"st\":1}}"}
{"receive_ns":1788563372562241000,"stream":"btcusdt@bookTicker","event_type":"bookTicker","event_time_ms":1788563372594,"raw_json":"{\"stream\":\"btcusdt@bookTicker\",\"data\":{\"e\":\"bookTicker\",\"u\":11478232325872,\"s\":\"BTCUSDT\",\"ps\":\"BTCUSDT\",\"b\":\"79607.10\",\"B\":\"5.045\",\"a\":\"79607.20\",\"A\":\"7.418\",\"T\":1788563372594,\"E\":1788563372594,\"st\":1}}"}
{"receive_ns":1788563372562682000,"stream":"btcusdt@bookTicker","event_type":"bookTicker","event_time_ms":1788563372595,"raw_json":"{\"stream\":\"btcusdt@bookTicker\",\"data\":{\"e\":\"bookTicker\",\"u\":11478232325903,\"s\":\"BTCUSDT\",\"ps\":\"BTCUSDT\",\"b\":\"79607.10\",\"B\":\"5.043\",\"a\":\"79607.20\",\"A\":\"7.418\",\"T\":1788563372595,\"E\":1788563372595,\"st\":1}}"}
{"receive_ns":1788563372562925000,"stream":"btcusdt@bookTicker","event_type":"bookTicker","event_time_ms":1788563372597,"raw_json":"{\"stream\":\"btcusdt@bookTicker\",\"data\":{\"e\":\"bookTicker\",\"u\":11478232325996,\"s\":\"BTCUSDT\",\"ps\":\"BTCUSDT\",\"b\":\"79607.10\",\"B\":\"5.452\",\"a\":\"79607.20\",\"A\":\"7.418\",\"T\":1788563372597,\"E\":1788563372597,\"st\":1}}"}
{"receive_ns":1788563372563161000,"stream":"btcusdt@bookTicker","event_type":"bookTicker","event_time_ms":1788563372598,"raw_json":"{\"stream\":\"btcusdt@bookTicker\",\"data\":{\"e\":\"bookTicker\",\"u\":11478232326043,\"s\":\"BTCUSDT\",\"ps\":\"BTCUSDT\",\"b\":\"79607.10\",\"B\":\"5.454\",\"a\":\"79607.20\",\"A\":\"7.418\",\"T\":1788563372598,\"E\":1788563372598,\"st\":1}}"}
{"receive_ns":1788563372578136000,"stream":"btcusdt@bookTicker","event_type":"bookTicker","event_time_ms":1788563372614,"raw_json":"{\"stream\":\"btcusdt@bookTicker\",\"data\":{\"e\":\"bookTicker\",\"u\":11478232326664,\"s\":\"BTCUSDT\",\"ps\":\"BTCUSDT\",\"b\":\"79607.10\",\"B\":\"5.454\",\"a\":\"79607.20\",\"A\":\"7.419\",\"T\":1788563372614,\"E\":1788563372614,\"st\":1}}"}
{"receive_ns":1788563372645549000,"stream":"btcusdt@depth@100ms","event_type":"depthUpdate","event_time_ms":1788563372681,"raw_json":"{\"stream\":\"btcusdt@depth@100ms\",\"data\":{\"e\":\"depthUpdate\",\"E\":1788563372681,\"T\":1788563372680,\"s\":\"BTCUSDT\",\"ps\":\"BTCUSDT\",\"U\":11478232325206,\"u\":11478232328929,\"pu\":11478232325173,\"b\":[[\"1000.00\",\"24.754\"],[\"29207.10\",\"1.680\"],[\"29307.10\",\"0.420\"],[\"63686.00\",\"0.000\"],[\"71646.30\",\"0.002\"],[\"76422.80\",\"0.002\"],[\"78563.30\",\"0.191\"],[\"78811.00\",\"15.340\"],[\"79232.90\",\"0.000\"],[\"79443.20\",\"0.000\"],[\"79491.70\",\"0.000\"],[\"79576.20\",\"0.003\"],[\"79582.80\",\"0.629\"],[\"79583.20\",\"0.253\"],[\"79583.70\",\"0.016\"],[\"79589.20\",\"0.972\"],[\"79602.90\",\"0.028\"],[\"79606.80\",\"0.039\"],[\"79607.10\",\"5.454\"]],\"a\":[[\"79607.20\",\"7.419\"],[\"79612.50\",\"0.164\"],[\"79615.80\",\"0.980\"],[\"79768.10\",\"0.000\"],[\"79963.40\",\"0.618\"],[\"79967.40\",\"0.000\"],[\"79995.30\",\"0.046\"],[\"79995.80\",\"0.100\"],[\"80403.30\",\"22.286\"]],\"st\":1}}"}
{"receive_ns":1788563372747930000,"stream":"btcusdt@depth@100ms","event_type":"depthUpdate","event_time_ms":1788563372783,"raw_json":"{\"stream\":\"btcusdt@depth@100ms\",\"data\":{\"e\":\"depthUpdate\",\"E\":1788563372783,\"T\":1788563372781,\"s\":\"BTCUSDT\",\"ps\":\"BTCUSDT\",\"U\":11478232328944,\"u\":11478232333405,\"pu\":11478232328929,\"b\":[[\"1000.00\",\"24.754\"],[\"29107.10\",\"0.035\"],[\"29207.10\",\"1.792\"],[\"29307.10\",\"0.273\"],[\"71646.30\",\"0.002\"],[\"76422.80\",\"0.000\"],[\"78492.60\",\"53.970\"],[\"78811.00\",\"15.338\"],[\"79234.90\",\"0.141\"],[\"79491.70\",\"0.232\"],[\"79583.20\",\"0.353\"],[\"79583.80\",\"0.001\"]],\"a\":[[\"79963.40\",\"1.120\"],[\"79967.40\",\"0.090\"],[\"79995.80\",\"0.863\"],[\"79997.80\",\"0.525\"],[\"80403.30\",\"22.286\"],[\"80562.50\",\"46.431\"]],\"st\":1}}"}
{"receive_ns":1788563372830873000,"stream":"btcusdt@bookTicker","event_type":"bookTicker","event_time_ms":1788563372868,"raw_json":"{\"stream\":\"btcusdt@bookTicker\",\"data\":{\"e\":\"bookTicker\",\"u\":11478232337424,\"s\":\"BTCUSDT\",\"ps\":\"BTCUSDT\",\"b\":\"79607.10\",\"B\":\"5.438\",\"a\":\"79607.20\",\"A\":\"7.419\",\"T\":1788563372868,\"E\":1788563372868,\"st\":1}}"}
{"receive_ns":1788563372839031000,"stream":"btcusdt@bookTicker","event_type":"bookTicker","event_time_ms":1788563372877,"raw_json":"{\"stream\":\"btcusdt@bookTicker\",\"data\":{\"e\":\"bookTicker\",\"u\":11478232337758,\"s\":\"BTCUSDT\",\"ps\":\"BTCUSDT\",\"b\":\"79607.10\",\"B\":\"5.455\",\"a\":\"79607.20\",\"A\":\"7.419\",\"T\":1788563372877,\"E\":1788563372877,\"st\":1}}"}
{"receive_ns":1788563372849715000,"stream":"btcusdt@depth@100ms","event_type":"depthUpdate","event_time_ms":1788563372885,"raw_json":"{\"stream\":\"btcusdt@depth@100ms\",\"data\":{\"e\":\"depthUpdate\",\"E\":1788563372885,\"T\":1788563372881,\"s\":\"BTCUSDT\",\"ps\":\"BTCUSDT\",\"U\":11478232333530,\"u\":11478232337928,\"pu\":11478232333405,\"b\":[[\"29107.10\",\"0.098\"],[\"29207.10\",\"1.841\"],[\"29307.10\",\"0.161\"],[\"63686.00\",\"0.000\"],[\"71646.30\",\"0.002\"],[\"76422.80\",\"0.002\"],[\"77374.60\",\"1.548\"],[\"77612.20\",\"0.006\"],[\"78015.00\",\"10.572\"],[\"78233.70\",\"0.002\"],[\"78600.00\",\"26.013\"],[\"78811.00\",\"15.339\"],[\"79209.10\",\"3.967\"],[\"79234.30\",\"0.000\"],[\"79235.90\",\"0.285\"],[\"79443.20\",\"2.434\"],[\"79443.60\",\"0.916\"],[\"79482.70\",\"0.541\"],[\"79491.70\",\"0.483\"],[\"79535.40\",\"0.002\"],[\"79572.00\",\"1.809\"],[\"79573.00\",\"0.133\"],[\"79574.70\",\"0.455\"],[\"79574.90\",\"0.022\"],[\"79575.90\",\"0.001\"],[\"79579.90\",\"0.063\"],[\"79581.10\",\"0.373\"],[\"79581.80\",\"2.949\"],[\"79581.90\",\"0.500\"],[\"79582.10\",\"0.045\"],[\"79582.80\",\"0.001\"],[\"79583.20\",\"0.879\"],[\"79583.70\",\"0.644\"],[\"79589.20\",\"0.195\"],[\"79590.70\",\"0.000\"],[\"79602.90\",\"0.002\"],[\"79603.50\",\"0.004\"],[\"79606.90\",\"0.199\"],[\"79607.00\",\"0.063\"],[\"79607.10\",\"5.455\"]],\"a\":[[\"79621.00\",\"0.000\"],[\"79622.20\",\"0.003\"],[\"79623.10\",\"0.937\"],[\"79623.20\",\"0.190\"],[\"79624.40\",\"0.452\"],[\"79625.60\",\"0.023\"],[\"79678.90\",\"0.015\"],[\"79728.70\",\"0.293\"],[\"79768.10\",\"1.348\"],[\"79963.40\",\"0.921\"],[\"79967.40\",\"0.289\"],[\"79995.30\",\"0.046\"],[\"79999.30\",\"0.167\"],[\"80403.30\",\"22.286\"]],\"st\":1}}"}
{"receive_ns":1788563372951191000,"stream":"btcusdt@depth@100ms","event_type":"depthUpdate","event_time_ms":1788563372987,"raw_json":"{\"stream\":\"btcusdt@depth@100ms\",\"data\":{\"e\":\"depthUpdate\",\"E\":1788563372987,\"T\":1788563372986,\"s\":\"BTCUSDT\",\"ps\":\"BTCUSDT\",\"U\":11478232338034,\"u\":11478232342082,\"pu\":11478232337928,\"b\":[[\"1000.00\",\"24.754\"],[\"29107.10\",\"0.154\"],[\"29207.10\",\"1.911\"],[\"29307.10\",\"0.035\"],[\"63686.00\",\"0.000\"],[\"71646.30\",\"0.002\"],[\"78651.80\",\"47.778\"],[\"78811.00\",\"15.339\"],[\"78970.20\",\"8.000\"],[\"79232.90\",\"0.141\"],[\"79234.90\",\"0.000\"],[\"79491.70\",\"0.583\"],[\"79583.20\",\"0.779\"],[\"79583.70\",\"0.017\"],[\"79583.80\",\"0.001\"],[\"79588.30\",\"0.636\"],[\"79590.90\",\"0.076\"],[\"79601.40\",\"0.000\"],[\"79603.30\",\"0.625\"],[\"79603.40\",\"0.026\"],[\"79603.50\",\"0.030\"]],\"a\":[[\"79774.40\",\"2.254\"],[\"79963.40\",\"0.670\"],[\"79967.40\",\"0.289\"],[\"79969.60\",\"0.290\"],[\"79995.80\",\"0.863\"],[\"79997.80\",\"0.525\"],[\"80044.30\",\"0.456\"],[\"80046.60\",\"0.902\"],[\"80403.30\",\"22.286\"]],\"st\":1}}"}
{"receive_ns":1788563373001751000,"stream":"btcusdt@bookTicker","event_type":"bookTicker","event_time_ms":1788563373037,"raw_json":"{\"stream\":\"btcusdt@bookTicker\",\"data\":{\"e\":\"bookTicker\",\"u\":11478232345677,\"s\":\"BTCUSDT\",\"ps\":\"BTCUSDT\",\"b\":\"79607.10\",\"B\":\"5.034\",\"a\":\"79607.20\",\"A\":\"7.419\",\"T\":1788563373037,\"E\":1788563373037,\"st\":1}}"}
{"receive_ns":1788563373002386000,"stream":"btcusdt@bookTicker","event_type":"bookTicker","event_time_ms":1788563373039,"raw_json":"{\"stream\":\"btcusdt@bookTicker\",\"data\":{\"e\":\"bookTicker\",\"u\":11478232345867,\"s\":\"BTCUSDT\",\"ps\":\"BTCUSDT\",\"b\":\"79607.10\",\"B\":\"5.033\",\"a\":\"79607.20\",\"A\":\"7.419\",\"T\":1788563373039,\"E\":1788563373039,\"st\":1}}"}
{"receive_ns":1788563373006022000,"stream":"btcusdt@bookTicker","event_type":"bookTicker","event_time_ms":1788563373040,"raw_json":"{\"stream\":\"btcusdt@bookTicker\",\"data\":{\"e\":\"bookTicker\",\"u\":11478232345985,\"s\":\"BTCUSDT\",\"ps\":\"BTCUSDT\",\"b\":\"79607.10\",\"B\":\"5.034\",\"a\":\"79607.20\",\"A\":\"7.419\",\"T\":1788563373040,\"E\":1788563373040,\"st\":1}}"}
{"receive_ns":1788563373006476000,"stream":"btcusdt@bookTicker","event_type":"bookTicker","event_time_ms":1788563373040,"raw_json":"{\"stream\":\"btcusdt@bookTicker\",\"data\":{\"e\":\"bookTicker\",\"u\":11478232345999,\"s\":\"BTCUSDT\",\"ps\":\"BTCUSDT\",\"b\":\"79607.10\",\"B\":\"5.459\",\"a\":\"79607.20\",\"A\":\"7.419\",\"T\":1788563373040,\"E\":1788563373040,\"st\":1}}"}
{"receive_ns":1788563373006930000,"stream":"btcusdt@bookTicker","event_type":"bookTicker","event_time_ms":1788563373042,"raw_json":"{\"stream\":\"btcusdt@bookTicker\",\"data\":{\"e\":\"bookTicker\",\"u\":11478232346050,\"s\":\"BTCUSDT\",\"ps\":\"BTCUSDT\",\"b\":\"79607.10\",\"B\":\"5.457\",\"a\":\"79607.20\",\"A\":\"7.419\",\"T\":1788563373041,\"E\":1788563373042,\"st\":1}}"}
{"receive_ns":1788563373051940000,"stream":"btcusdt@depth@100ms","event_type":"depthUpdate","event_time_ms":1788563373089,"raw_json":"{\"stream\":\"btcusdt@depth@100ms\",\"data\":{\"e\":\"depthUpdate\",\"E\":1788563373089,\"T\":1788563373086,\"s\":\"BTCUSDT\",\"ps\":\"BTCUSDT\",\"U\":11478232342144,\"u\":11478232347928,\"pu\":11478232342082,\"b\":[[\"1000.00\",\"24.754\"],[\"29107.10\",\"0.294\"],[\"29207.10\",\"1.806\"],[\"29307.10\",\"0.000\"],[\"63686.00\",\"0.000\"],[\"71646.30\",\"0.002\"],[\"76422.80\",\"0.000\"],[\"78394.60\",\"0.029\"],[\"78484.60\",\"2.543\"],[\"78811.00\",\"15.339\"],[\"79050.00\",\"5.751\"],[\"79209.00\",\"0.002\"],[\"79491.70\",\"0.332\"],[\"79524.50\",\"0.968\"],[\"79540.40\",\"0.000\"],[\"79582.90\",\"0.704\"],[\"79583.20\",\"0.755\"],[\"79583.70\",\"0.016\"],[\"79588.30\",\"0.008\"],[\"79588.40\",\"0.004\"],[\"79592.80\",\"0.004\"],[\"79606.80\",\"0.003\"],[\"79607.10\",\"5.457\"]],\"a\":[[\"79963.40\",\"0.670\"],[\"79967.40\",\"0.090\"],[\"79995.30\",\"0.002\"],[\"79999.30\",\"0.167\"],[\"80005.30\",\"0.001\"],[\"80403.30\",\"22.286\"],[\"80492.80\",\"2.480\"],[\"80563.80\",\"0.001\"],[\"80598.60\",\"15.460\"],[\"80819.60\",\"0.028\"],[\"81199.30\",\"10.756\"]],\"st\":1}}"}
{"receive_ns":1788563373060379000,"stream":"btcusdt@bookTicker","event_type":"bookTicker","event_time_ms":1788563373097,"raw_json":"{\"stream\":\"btcusdt@bookTicker\",\"data\":{\"e\":\"bookTicker\",\"u\":11478232348378,\"s\":\"BTCUSDT\",\"ps\":\"BTCUSDT\",\"b\":\"79607.10\",\"B\":\"5.457\",\"a\":\"79607.20\",\"A\":\"7.749\",\"T\":1788563373097,\"E\":1788563373097,\"st\":1}}"}
{"receive_ns":1788563373061618000,"stream":"btcusdt@bookTicker","event_type":"bookTicker","event_time_ms":1788563373099,"raw_json":"{\"stream\":\"btcusdt@bookTicker\",\"data\":{\"e\":\"bookTicker\",\"u\":11478232348449,\"s\":\"BTCUSDT\",\"ps\":\"BTCUSDT\",\"b\":\"79607.10\",\"B\":\"5.459\",\"a\":\"79607.20\",\"A\":\"7.749\",\"T\":1788563373098,\"E\":1788563373099,\"st\":1}}"}
{"receive_ns":1788563373110497000,"stream":"btcusdt@bookTicker","event_type":"bookTicker","event_time_ms":1788563373146,"raw_json":"{\"stream\":\"btcusdt@bookTicker\",\"data\":{\"e\":\"bookTicker\",\"u\":11478232350536,\"s\":\"BTCUSDT\",\"ps\":\"BTCUSDT\",\"b\":\"79607.10\",\"B\":\"5.459\",\"a\":\"79607.20\",\"A\":\"7.349\",\"T\":1788563373146,\"E\":1788563373146,\"st\":1}}"}
{"receive_ns":1788563373156357000,"stream":"btcusdt@depth@100ms","event_type":"depthUpdate","event_time_ms":1788563373191,"raw_json":"{\"stream\":\"btcusdt@depth@100ms\",\"data\":{\"e\":\"depthUpdate\",\"E\":1788563373191,\"T\":1788563373190,\"s\":\"BTCUSDT\",\"ps\":\"BTCUSDT\",\"U\":11478232348066,\"u\":11478232352353,\"pu\":11478232347928,\"b\":[[\"29107.10\",\"0.476\"],[\"29207.10\",\"1.624\"],[\"63686.00\",\"0.000\"],[\"71646.30\",\"0.002\"],[\"76422.80\",\"0.002\"],[\"78015.00\",\"10.575\"],[\"78253.80\",\"8.035\"],[\"78394.60\",\"0.037\"],[\"78492.60\",\"52.062\"],[\"78608.50\",\"12.852\"],[\"78727.60\",\"1.098\"],[\"78811.00\",\"15.339\"],[\"79209.10\",\"3.977\"],[\"79232.90\",\"0.000\"],[\"79491.70\",\"0.000\"],[\"79583.20\",\"0.579\"],[\"79583.40\",\"0.006\"],[\"79588.60\",\"0.064\"],[\"79588.90\",\"0.046\"],[\"79589.20\",\"0.395\"],[\"79590.90\",\"0.000\"],[\"79591.10\",\"0.081\"],[\"79595.30\",\"0.354\"],[\"79595.70\",\"0.001\"],[\"79601.40\",\"0.026\"],[\"79603.30\",\"0.599\"],[\"79603.40\",\"0.026\"],[\"79603.50\",\"0.004\"],[\"79606.60\",\"0.037\"],[\"79606.90\",\"0.197\"],[\"79607.10\",\"5.459\"]],\"a\":[[\"79607.20\",\"7.349\"],[\"79608.70\",\"0.026\"],[\"79609.90\",\"0.002\"],[\"79623.30\",\"0.458\"],[\"79774.40\",\"2.003\"],[\"79963.40\",\"0.419\"],[\"79967.40\",\"0.199\"],[\"79995.80\",\"0.100\"],[\"79997.80\",\"0.000\"],[\"79999.30\",\"0.211\"],[\"80403.30\",\"22.286\"],[\"80484.30\",\"0.000\"],[\"80523.50\",\"7.440\"],[\"81597.40\",\"0.369\"]],\"st\":1}}"}
{"receive_ns":1788563373182079000,"stream":"btcusdt@bookTicker","event_type":"bookTicker","event_time_ms":1788563373214,"raw_json":"{\"stream\":\"btcusdt@bookTicker\",\"data\":{\"e\":\"bookTicker\",\"u\":11478232353431,\"s\":\"BTCUSDT\",\"ps\":\"BTCUSDT\",\"b\":\"79607.10\",\"B\":\"5.050\",\"a\":\"79607.20\",\"A\":\"7.349\",\"T\":1788563373214,\"E\":1788563373214,\"st\":1}}"}
{"receive_ns":1788563373182684000,"stream":"btcusdt@bookTicker","event_type":"bookTicker","event_time_ms":1788563373217,"raw_json":"{\"stream\":\"btcusdt@bookTicker\",\"data\":{\"e\":\"bookTicker\",\"u\":11478232353573,\"s\":\"BTCUSDT\",\"ps\":\"BTCUSDT\",\"b\":\"79607.10\",\"B\":\"5.460\",\"a\":\"79607.20\",\"A\":\"7.349\",\"T\":1788563373217,\"E\":1788563373217,\"st\":1}}"}
{"receive_ns":1788563373183087000,"stream":"btcusdt@bookTicker","event_type":"bookTicker","event_time_ms":1788563373218,"raw_json":"{\"stream\":\"btcusdt@bookTicker\",\"data\":{\"e\":\"bookTicker\",\"u\":11478232353623,\"s\":\"BTCUSDT\",\"ps\":\"BTCUSDT\",\"b\":\"79607.10\",\"B\":\"5.458\",\"a\":\"79607.20\",\"A\":\"7.349\",\"T\":1788563373218,\"E\":1788563373218,\"st\":1}}"}
{"receive_ns":1788563373233490000,"stream":"btcusdt@bookTicker","event_type":"bookTicker","event_time_ms":1788563373269,"raw_json":"{\"stream\":\"btcusdt@bookTicker\",\"data\":{\"e\":\"bookTicker\",\"u\":11478232355406,\"s\":\"BTCUSDT\",\"ps\":\"BTCUSDT\",\"b\":\"79607.10\",\"B\":\"4.880\",\"a\":\"79607.20\",\"A\":\"7.349\",\"T\":1788563373269,\"E\":1788563373269,\"st\":1}}"}
{"receive_ns":1788563373240771000,"stream":"btcusdt@bookTicker","event_type":"bookTicker","event_time_ms":1788563373271,"raw_json":"{\"stream\":\"btcusdt@bookTicker\",\"data\":{\"e\":\"bookTicker\",\"u\":11478232355487,\"s\":\"BTCUSDT\",\"ps\":\"BTCUSDT\",\"b\":\"79607.10\",\"B\":\"4.882\",\"a\":\"79607.20\",\"A\":\"7.349\",\"T\":1788563373271,\"E\":1788563373271,\"st\":1}}"}
{"receive_ns":1788563373241662000,"stream":"btcusdt@bookTicker","event_type":"bookTicker","event_time_ms":1788563373273,"raw_json":"{\"stream\":\"btcusdt@bookTicker\",\"data\":{\"e\":\"bookTicker\",\"u\":11478232355604,\"s\":\"BTCUSDT\",\"ps\":\"BTCUSDT\",\"b\":\"79607.10\",\"B\":\"5.462\",\"a\":\"79607.20\",\"A\":\"7.349\",\"T\":1788563373272,\"E\":1788563373273,\"st\":1}}"}
{"receive_ns":1788563373258479000,"stream":"btcusdt@depth@100ms","event_type":"depthUpdate","event_time_ms":1788563373293,"raw_json":"{\"stream\":\"btcusdt@depth@100ms\",\"data\":{\"e\":\"depthUpdate\",\"E\":1788563373293,\"T\":1788563373292,\"s\":\"BTCUSDT\",\"ps\":\"BTCUSDT\",\"U\":11478232352388,\"u\":11478232356377,\"pu\":11478232352353,\"b\":[[\"1000.00\",\"24.754\"],[\"29107.10\",\"0.651\"],[\"29207.10\",\"1.449\"],[\"71646.30\",\"0.002\"],[\"71684.00\",\"0.000\"],[\"75626.80\",\"0.004\"],[\"76422.80\",\"0.000\"],[\"78608.50\",\"12.700\"],[\"78811.00\",\"15.339\"],[\"79197.20\",\"0.000\"],[\"79197.30\",\"0.281\"],[\"79232.90\",\"0.141\"],[\"79482.70\",\"0.543\"],[\"79491.70\",\"0.332\"],[\"79524.50\",\"0.139\"],[\"79579.90\",\"0.063\"],[\"79581.80\",\"3.388\"],[\"79581.90\",\"0.061\"],[\"79583.80\",\"0.001\"],[\"79591.10\",\"0.005\"],[\"79601.20\",\"0.141\"],[\"79602.60\",\"0.001\"],[\"79603.40\",\"0.000\"],[\"79606.50\",\"0.036\"],[\"79606.60\",\"0.001\"],[\"79607.10\",\"5.462\"]],\"a\":[[\"79728.70\",\"0.293\"],[\"79774.40\",\"2.505\"],[\"79964.00\",\"0.764\"],[\"79967.40\",\"0.289\"],[\"79997.80\",\"0.525\"],[\"80403.30\",\"22.286\"],[\"80819.60\",\"0.036\"]],\"st\":1}}"}
{"receive_ns":1788563373358555000,"stream":"btcusdt@depth@100ms","event_type":"depthUpdate","event_time_ms":1788563373395,"raw_json":"{\"stream\":\"btcusdt@depth@100ms\",\"data\":{\"e\":\"depthUpdate\",\"E\":1788563373395,\"T\":1788563373394,\"s\":\"BTCUSDT\",\"ps\":\"BTCUSDT\",\"U\":11478232356423,\"u\":11478232366051,\"pu\":11478232356377,\"b\":[[\"1000.00\",\"24.754\"],[\"29107.10\",\"0.833\"],[\"29207.10\",\"1.267\"],[\"71646.30\",\"0.002\"],[\"76422.80\",\"0.002\"],[\"78686.90\",\"0.025\"],[\"78811.00\",\"15.339\"],[\"79491.70\",\"0.583\"],[\"79535.40\",\"0.000\"],[\"79551.30\",\"0.005\"],[\"79579.90\",\"0.502\"],[\"79581.80\",\"2.949\"],[\"79583.20\",\"0.779\"],[\"79589.20\",\"0.195\"],[\"79590.90\",\"0.076\"],[\"79592.10\",\"0.077\"],[\"79601.20\",\"0.115\"],[\"79602.40\",\"0.280\"],[\"79603.10\",\"0.226\"],[\"79603.20\",\"0.003\"],[\"79603.50\",\"0.030\"],[\"79604.10\",\"1.026\"],[\"79606.80\",\"0.004\"]],\"a\":[[\"79618.50\",\"0.006\"],[\"79620.80\",\"0.378\"],[\"79621.00\",\"0.372\"],[\"79623.10\",\"0.565\"],[\"79678.90\",\"0.015\"],[\"79690.20\",\"0.001\"],[\"79691.00\",\"0.041\"],[\"79699.90\",\"0.003\"],[\"79963.40\",\"0.618\"],[\"79967.40\",\"0.090\"],[\"79999.30\",\"0.211\"],[\"80403.30\",\"22.286\"],[\"80529.50\",\"0.433\"],[\"80752.40\",\"4.267\"],[\"87568.00\",\"0.000\"]],\"st\":1}}"}
{"receive_ns":1788563373379866000,"stream":"btcusdt@bookTicker","event_type":"bookTicker","event_time_ms":1788563373412,"raw_json":"{\"stream\":\"btcusdt@bookTicker\",\"data\":{\"e\":\"bookTicker\",\"u\":11478232368499,\"s\":\"BTCUSDT\",\"ps\":\"BTCUSDT\",\"b\":\"79607.10\",\"B\":\"5.466\",\"a\":\"79607.20\",\"A\":\"7.349\",\"T\":1788563373412,\"E\":1788563373412,\"st\":1}}"}
{"receive_ns":1788563373380541000,"stream":"btcusdt@bookTicker","event_type":"bookTicker","event_time_ms":1788563373413,"raw_json":"{\"stream\":\"btcusdt@bookTicker\",\"data\":{\"e\":\"bookTicker\",\"u\":11478232368699,\"s\":\"BTCUSDT\",\"ps\":\"BTCUSDT\",\"b\":\"79607.10\",\"B\":\"5.484\",\"a\":\"79607.20\",\"A\":\"7.349\",\"T\":1788563373413,\"E\":1788563373413,\"st\":1}}"}
{"receive_ns":1788563373381040000,"stream":"btcusdt@bookTicker","event_type":"bookTicker","event_time_ms":1788563373414,"raw_json":"{\"stream\":\"btcusdt@bookTicker\",\"data\":{\"e\":\"bookTicker\",\"u\":11478232368822,\"s\":\"BTCUSDT\",\"ps\":\"BTCUSDT\",\"b\":\"79607.10\",\"B\":\"5.482\",\"a\":\"79607.20\",\"A\":\"7.349\",\"T\":1788563373414,\"E\":1788563373414,\"st\":1}}"}
{"receive_ns":1788563373417537000,"stream":"btcusdt@bookTicker","event_type":"bookTicker","event_time_ms":1788563373450,"raw_json":"{\"stream\":\"btcusdt@bookTicker\",\"data\":{\"e\":\"bookTicker\",\"u\":11478232371032,\"s\":\"BTCUSDT\",\"ps\":\"BTCUSDT\",\"b\":\"79607.10\",\"B\":\"4.971\",\"a\":\"79607.20\",\"A\":\"7.349\",\"T\":1788563373450,\"E\":1788563373450,\"st\":1}}"}
{"receive_ns":1788563373418976000,"stream":"btcusdt@bookTicker","event_type":"bookTicker","event_time_ms":1788563373451,"raw_json":"{\"stream\":\"btcusdt@bookTicker\",\"data\":{\"e\":\"bookTicker\",\"u\":11478232371118,\"s\":\"BTCUSDT\",\"ps\":\"BTCUSDT\",\"b\":\"79607.10\",\"B\":\"4.973\",\"a\":\"79607.20\",\"A\":\"7.349\",\"T\":1788563373451,\"E\":1788563373451,\"st\":1}}"}
{"receive_ns":1788563373419942000,"stream":"btcusdt@bookTicker","event_type":"bookTicker","event_time_ms":1788563373455,"raw_json":"{\"stream\":\"btcusdt@bookTicker\",\"data\":{\"e\":\"bookTicker\",\"u\":11478232371377,\"s\":\"BTCUSDT\",\"ps\":\"BTCUSDT\",\"b\":\"79607.10\",\"B\":\"5.483\",\"a\":\"79607.20\",\"A\":\"7.349\",\"T\":1788563373455,\"E\":1788563373455,\"st\":1}}"}
{"receive_ns":1788563373420730000,"stream":"btcusdt@bookTicker","event_type":"bookTicker","event_time_ms":1788563373457,"raw_json":"{\"stream\":\"btcusdt@bookTicker\",\"data\":{\"e\":\"bookTicker\",\"u\":11478232371416,\"s\":\"BTCUSDT\",\"ps\":\"BTCUSDT\",\"b\":\"79607.10\",\"B\":\"5.481\",\"a\":\"79607.20\",\"A\":\"7.349\",\"T\":1788563373456,\"E\":1788563373457,\"st\":1}}"}
{"receive_ns":1788563373460976000,"stream":"btcusdt@depth@100ms","event_type":"depthUpdate","event_time_ms":1788563373497,"raw_json":"{\"stream\":\"btcusdt@depth@100ms\",\"data\":{\"e\":\"depthUpdate\",\"E\":1788563373497,\"T\":1788563373496,\"s\":\"BTCUSDT\",\"ps\":\"BTCUSDT\",\"U\":11478232366311,\"u\":11478232373434,\"pu\":11478232366051,\"b\":[[\"29107.10\",\"1.008\"],[\"29207.10\",\"1.092\"],[\"63685.70\",\"0.001\"],[\"71646.30\",\"0.002\"],[\"78612.00\",\"13.407\"],[\"78811.00\",\"15.339\"],[\"79209.10\",\"3.977\"],[\"79232.90\",\"0.141\"],[\"79491.70\",\"0.583\"],[\"79492.30\",\"1.035\"],[\"79579.90\",\"0.502\"],[\"79581.90\",\"0.061\"],[\"79582.90\",\"0.076\"],[\"79583.20\",\"0.202\"],[\"79583.60\",\"1.321\"],[\"79583.70\",\"0.644\"],[\"79583.80\",\"0.001\"],[\"79588.30\",\"0.008\"],[\"79588.40\",\"0.004\"],[\"79592.00\",\"0.083\"],[\"79592.10\",\"0.001\"],[\"79604.10\",\"1.026\"],[\"79606.50\",\"0.000\"],[\"79607.10\",\"5.481\"]],\"a\":[[\"79621.00\",\"0.372\"],[\"79622.10\",\"0.002\"],[\"79623.10\",\"0.565\"],[\"79623.20\",\"0.188\"],[\"79624.40\",\"0.000\"],[\"79625.50\",\"0.458\"],[\"79774.40\",\"2.505\"],[\"79828.60\",\"7.307\"],[\"79964.00\",\"0.764\"],[\"79967.40\",\"0.090\"],[\"79997.80\",\"0.525\"],[\"80354.40\",\"1.117\"],[\"80403.30\",\"22.286\"],[\"80752.40\",\"3.401\"]],\"st\":1}}"}
{"receive_ns":1788563373477085000,"stream":"btcusdt@bookTicker","event_type":"bookTicker","event_time_ms":1788563373514,"raw_json":"{\"stream\":\"btcusdt@bookTicker\",\"data\":{\"e\":\"bookTicker\",\"u\":11478232374572,\"s\":\"BTCUSDT\",\"ps\":\"BTCUSDT\",\"b\":\"79607.10\",\"B\":\"5.442\",\"a\":\"79607.20\",\"A\":\"7.349\",\"T\":1788563373513,\"E\":1788563373514,\"st\":1}}"}
{"receive_ns":1788563373477983000,"stream":"btcusdt@trade","event_type":"trade","event_time_ms":1788563373514,"raw_json":"{\"stream\":\"btcusdt@trade\",\"data\":{\"e\":\"trade\",\"E\":1788563373514,\"T\":1788563373513,\"s\":\"BTCUSDT\",\"t\":8054083443,\"p\":\"79607.10\",\"q\":\"0.002\",\"X\":\"MARKET\",\"m\":true,\"st\":1}}"}
{"receive_ns":1788563373478513000,"stream":"btcusdt@trade","event_type":"trade","event_time_ms":1788563373514,"raw_json":"{\"stream\":\"btcusdt@trade\",\"data\":{\"e\":\"trade\",\"E\":1788563373514,\"T\":1788563373513,\"s\":\"BTCUSDT\",\"t\":8054083444,\"p\":\"79607.10\",\"q\":\"0.010\",\"X\":\"MARKET\",\"m\":true,\"st\":1}}"}
{"receive_ns":1788563373479045000,"stream":"btcusdt@trade","event_type":"trade","event_time_ms":1788563373514,"raw_json":"{\"stream\":\"btcusdt@trade\",\"data\":{\"e\":\"trade\",\"E\":1788563373514,\"T\":1788563373513,\"s\":\"BTCUSDT\",\"t\":8054083445,\"p\":\"79607.10\",\"q\":\"0.027\",\"X\":\"MARKET\",\"m\":true,\"st\":1}}"}
{"receive_ns":1788563373513320000,"stream":"btcusdt@bookTicker","event_type":"bookTicker","event_time_ms":1788563373548,"raw_json":"{\"stream\":\"btcusdt@bookTicker\",\"data\":{\"e\":\"bookTicker\",\"u\":11478232376656,\"s\":\"BTCUSDT\",\"ps\":\"BTCUSDT\",\"b\":\"79607.10\",\"B\":\"5.017\",\"a\":\"79607.20\",\"A\":\"7.349\",\"T\":1788563373548,\"E\":1788563373548,\"st\":1}}"}
{"receive_ns":1788563373514223000,"stream":"btcusdt@bookTicker","event_type":"bookTicker","event_time_ms":1788563373549,"raw_json":"{\"stream\":\"btcusdt@bookTicker\",\"data\":{\"e\":\"bookTicker\",\"u\":11478232376719,\"s\":\"BTCUSDT\",\"ps\":\"BTCUSDT\",\"b\":\"79607.10\",\"B\":\"5.019\",\"a\":\"79607.20\",\"A\":\"7.349\",\"T\":1788563373549,\"E\":1788563373549,\"st\":1}}"}
{"receive_ns":1788563373514845000,"stream":"btcusdt@bookTicker","event_type":"bookTicker","event_time_ms":1788563373551,"raw_json":"{\"stream\":\"btcusdt@bookTicker\",\"data\":{\"e\":\"bookTicker\",\"u\":11478232376847,\"s\":\"BTCUSDT\",\"ps\":\"BTCUSDT\",\"b\":\"79607.10\",\"B\":\"5.019\",\"a\":\"79607.20\",\"A\":\"7.347\",\"T\":1788563373551,\"E\":1788563373551,\"st\":1}}"}
{"receive_ns":1788563373516026000,"stream":"btcusdt@bookTicker","event_type":"bookTicker","event_time_ms":1788563373551,"raw_json":"{\"stream\":\"btcusdt@bookTicker\",\"data\":{\"e\":\"bookTicker\",\"u\":11478232376858,\"s\":\"BTCUSDT\",\"ps\":\"BTCUSDT\",\"b\":\"79607.10\",\"B\":\"5.447\",\"a\":\"79607.20\",\"A\":\"7.347\",\"T\":1788563373551,\"E\":1788563373551,\"st\":1}}"}
{"receive_ns":1788563373548753000,"stream":"btcusdt@bookTicker","event_type":"bookTicker","event_time_ms":1788563373584,"raw_json":"{\"stream\":\"btcusdt@bookTicker\",\"data\":{\"e\":\"bookTicker\",\"u\":11478232378677,\"s\":\"BTCUSDT\",\"ps\":\"BTCUSDT\",\"b\":\"79607.10\",\"B\":\"5.447\",\"a\":\"79607.20\",\"A\":\"7.348\",\"T\":1788563373584,\"E\":1788563373584,\"st\":1}}"}
{"receive_ns":1788563373549360000,"stream":"btcusdt@bookTicker","event_type":"bookTicker","event_time_ms":1788563373585,"raw_json":"{\"stream\":\"btcusdt@bookTicker\",\"data\":{\"e\":\"bookTicker\",\"u\":11478232378733,\"s\":\"BTCUSDT\",\"ps\":\"BTCUSDT\",\"b\":\"79607.10\",\"B\":\"5.447\",\"a\":\"79607.20\",\"A\":\"7.350\",\"T\":1788563373585,\"E\":1788563373585,\"st\":1}}"}
{"receive_ns":1788563373563582000,"stream":"btcusdt@depth@100ms","event_type":"depthUpdate","event_time_ms":1788563373599,"raw_json":"{\"stream\":\"btcusdt@depth@100ms\",\"data\":{\"e\":\"depthUpdate\",\"E\":1788563373599,\"T\":1788563373597,\"s\":\"BTCUSDT\",\"ps\":\"BTCUSDT\",\"U\":11478232373499,\"u\":11478232379512,\"pu\":11478232373434,\"b\":[[\"1000.00\",\"24.754\"],[\"29107.10\",\"1.190\"],[\"29207.10\",\"0.910\"],[\"71646.30\",\"0.002\"],[\"76422.80\",\"0.000\"],[\"77374.60\",\"1.290\"],[\"78015.00\",\"10.578\"],[\"78691.60\",\"10.766\"],[\"78811.00\",\"15.339\"],[\"79483.20\",\"0.000\"],[\"79483.30\",\"0.004\"],[\"79491.70\",\"0.332\"],[\"79493.70\",\"0.957\"],[\"79579.90\",\"0.063\"],[\"79581.80\",\"3.388\"],[\"79581.90\",\"0.061\"],[\"79583.20\",\"0.704\"],[\"79592.00\",\"0.007\"],[\"79601.40\",\"0.000\"],[\"79601.50\",\"0.002\"],[\"79603.80\",\"0.029\"],[\"79604.10\",\"1.000\"],[\"79604.20\",\"0.027\"],[\"79604.30\",\"0.026\"],[\"79606.30\",\"0.102\"],[\"79606.90\",\"0.199\"],[\"79607.10\",\"5.447\"]],\"a\":[[\"79607.20\",\"7.350\"],[\"79621.00\",\"0.000\"],[\"79622.10\",\"0.374\"],[\"79630.90\",\"0.013\"],[\"79633.10\",\"0.000\"],[\"79841.40\",\"0.000\"],[\"79841.50\",\"0.004\"],[\"79963.40\",\"0.618\"],[\"79999.30\",\"0.211\"],[\"80403.30\",\"22.286\"],[\"80538.60\",\"2.739\"],[\"80761.50\",\"20.593\"]],\"st\":1}}"}
{"receive_ns":1788563373665097000,"stream":"btcusdt@depth@100ms","event_type":"depthUpdate","event_time_ms":1788563373701,"raw_json":"{\"stream\":\"btcusdt@depth@100ms\",\"data\":{\"e\":\"depthUpdate\",\"E\":1788563373701,\"T\":1788563373697,\"s\":\"BTCUSDT\",\"ps\":\"BTCUSDT\",\"U\":11478232379640,\"u\":11478232383889,\"pu\":11478232379512,\"b\":[[\"1000.00\",\"24.754\"],[\"29107.10\",\"1.365\"],[\"29207.10\",\"0.735\"],[\"71646.30\",\"0.002\"],[\"76422.80\",\"0.002\"],[\"78609.10\",\"0.002\"],[\"78613.90\",\"0.002\"],[\"78811.00\",\"15.339\"],[\"79209.10\",\"3.977\"],[\"79232.90\",\"0.000\"],[\"79491.70\",\"0.000\"],[\"79492.30\",\"0.031\"],[\"79579.90\",\"0.063\"],[\"79581.80\",\"2.949\"],[\"79581.90\",\"0.500\"],[\"79592.40\",\"0.348\"],[\"79601.60\",\"0.001\"],[\"79603.40\",\"0.026\"],[\"79604.20\",\"0.001\"],[\"79604.30\",\"0.000\"],[\"79604.60\",\"0.000\"]],\"a\":[[\"79774.40\",\"2.003\"],[\"79964.00\",\"0.001\"],[\"79967.40\",\"0.000\"],[\"79997.80\",\"0.000\"],[\"80403.30\",\"22.286\"],[\"80677.00\",\"1.300\"],[\"80761.50\",\"21.459\"]],\"st\":1}}"}
{"receive_ns":1788563373709552000,"stream":"btcusdt@bookTicker","event_type":"bookTicker","event_time_ms":1788563373747,"raw_json":"{\"stream\":\"btcusdt@bookTicker\",\"data\":{\"e\":\"bookTicker\",\"u\":11478232385936,\"s\":\"BTCUSDT\",\"ps\":\"BTCUSDT\",\"b\":\"79607.10\",\"B\":\"5.447\",\"a\":\"79607.20\",\"A\":\"7.415\",\"T\":1788563373747,\"E\":1788563373747,\"st\":1}}"}
{"receive_ns":1788563373710911000,"stream":"btcusdt@bookTicker","event_type":"bookTicker","event_time_ms":1788563373749,"raw_json":"{\"stream\":\"btcusdt@bookTicker\",\"data\":{\"e\":\"bookTicker\",\"u\":11478232386015,\"s\":\"BTCUSDT\",\"ps\":\"BTCUSDT\",\"b\":\"79607.10\",\"B\":\"5.445\",\"a\":\"79607.20\",\"A\":\"7.415\",\"T\":1788563373748,\"E\":1788563373749,\"st\":1}}"}
{"receive_ns":1788563373721532000,"stream":"btcusdt@bookTicker","event_type":"bookTicker","event_time_ms":1788563373759,"raw_json":"{\"stream\":\"btcusdt@bookTicker\",\"data\":{\"e\":\"bookTicker\",\"u\":11478232386505,\"s\":\"BTCUSDT\",\"ps\":\"BTCUSDT\",\"b\":\"79607.10\",\"B\":\"5.452\",\"a\":\"79607.20\",\"A\":\"7.415\",\"T\":1788563373759,\"E\":1788563373759,\"st\":1}}"}
{"receive_ns":1788563373766056000,"stream":"btcusdt@depth@100ms","event_type":"depthUpdate","event_time_ms":1788563373803,"raw_json":"{\"stream\":\"btcusdt@depth@100ms\",\"data\":{\"e\":\"depthUpdate\",\"E\":1788563373803,\"T\":1788563373802,\"s\":\"BTCUSDT\",\"ps\":\"BTCUSDT\",\"U\":11478232384132,\"u\":11478232388362,\"pu\":11478232383889,\"b\":[[\"29107.10\",\"1.547\"],[\"29207.10\",\"0.553\"],[\"71646.30\",\"0.002\"],[\"76422.80\",\"0.000\"],[\"77931.80\",\"0.004\"],[\"78811.00\",\"15.338\"],[\"79232.90\",\"0.141\"],[\"79482.70\",\"0.017\"],[\"79491.70\",\"0.332\"],[\"79493.70\",\"0.631\"],[\"79583.20\",\"0.002\"],[\"79583.70\",\"0.644\"],[\"79583.80\",\"0.001\"],[\"79584.80\",\"0.270\"],[\"79588.30\",\"0.008\"],[\"79588.40\",\"0.004\"],[\"79601.60\",\"0.027\"],[\"79603.80\",\"0.003\"],[\"79607.10\",\"5.452\"]],\"a\":[[\"79607.20\",\"7.415\"],[\"79728.70\",\"0.000\"],[\"79774.40\",\"2.505\"],[\"79963.40\",\"0.000\"],[\"79967.40\",\"0.090\"],[\"79995.80\",\"0.863\"],[\"79997.80\",\"0.525\"],[\"79999.30\",\"0.055\"],[\"80363.50\",\"10.746\"],[\"80403.30\",\"22.286\"],[\"83587.50\",\"0.019\"]],\"st\":1}}"}
{"receive_ns":1788563373806931000,"stream":"btcusdt@bookTicker","event_type":"bookTicker","event_time_ms":1788563373843,"raw_json":"{\"stream\":\"btcusdt@bookTicker\",\"data\":{\"e\":\"bookTicker\",\"u\":11478232390099,\"s\":\"BTCUSDT\",\"ps\":\"BTCUSDT\",\"b\":\"79607.10\",\"B\":\"5.452\",\"a\":\"79607.20\",\"A\":\"7.431\",\"T\":1788563373843,\"E\":1788563373843,\"st\":1}}"}
{"receive_ns":1788563373807685000,"stream":"btcusdt@bookTicker","event_type":"bookTicker","event_time_ms":1788563373844,"raw_json":"{\"stream\":\"btcusdt@bookTicker\",\"data\":{\"e\":\"bookTicker\",\"u\":11478232390148,\"s\":\"BTCUSDT\",\"ps\":\"BTCUSDT\",\"b\":\"79607.10\",\"B\":\"5.454\",\"a\":\"79607.20\",\"A\":\"7.431\",\"T\":1788563373844,\"E\":1788563373844,\"st\":1}}"}
{"receive_ns":1788563373868554000,"stream":"btcusdt@depth@100ms","event_type":"depthUpdate","event_time_ms":1788563373905,"raw_json":"{\"stream\":\"btcusdt@depth@100ms\",\"data\":{\"e\":\"depthUpdate\",\"E\":1788563373905,\"T\":1788563373902,\"s\":\"BTCUSDT\",\"ps\":\"BTCUSDT\",\"U\":11478232388425,\"u\":11478232392193,\"pu\":11478232388362,\"b\":[[\"1000.00\",\"24.754\"],[\"29107.10\",\"1.722\"],[\"29207.10\",\"0.378\"],[\"71646.30\",\"0.002\"],[\"76422.80\",\"0.002\"],[\"78015.00\",\"10.575\"],[\"78651.80\",\"49.048\"],[\"78811.00\",\"15.338\"],[\"79482.70\",\"0.543\"],[\"79579.90\",\"0.502\"],[\"79581.90\",\"0.061\"],[\"79583.20\",\"0.830\"],[\"79588.60\",\"0.002\"],[\"79589.00\",\"0.062\"],[\"79589.20\",\"0.395\"],[\"79589.30\",\"0.001\"],[\"79592.20\",\"0.022\"],[\"79603.80\",\"0.003\"],[\"79607.10\",\"5.454\"]],\"a\":[[\"79607.20\",\"7.431\"],[\"79624.40\",\"0.452\"],[\"79625.50\",\"0.006\"],[\"79728.70\",\"0.293\"],[\"79961.60\",\"0.120\"],[\"79963.40\",\"0.419\"],[\"79967.40\",\"0.289\"],[\"79999.30\",\"0.211\"],[\"80403.30\",\"22.286\"],[\"80562.50\",\"43.953\"],[\"80721.70\",\"58.033\"]],\"st\":1}}"}
{"receive_ns":1788563373873679000,"stream":"btcusdt@bookTicker","event_type":"bookTicker","event_time_ms":1788563373909,"raw_json":"{\"stream\":\"btcusdt@bookTicker\",\"data\":{\"e\":\"bookTicker\",\"u\":11478232392483,\"s\":\"BTCUSDT\",\"ps\":\"BTCUSDT\",\"b\":\"79607.10\",\"B\":\"5.491\",\"a\":\"79607.20\",\"A\":\"7.431\",\"T\":1788563373909,\"E\":1788563373909,\"st\":1}}"}
{"receive_ns":1788563373971557000,"stream":"btcusdt@depth@100ms","event_type":"depthUpdate","event_time_ms":1788563374007,"raw_json":"{\"stream\":\"btcusdt@depth@100ms\",\"data\":{\"e\":\"depthUpdate\",\"E\":1788563374007,\"T\":1788563374005,\"s\":\"BTCUSDT\",\"ps\":\"BTCUSDT\",\"U\":11478232392324,\"u\":11478232396559,\"pu\":11478232392193,\"b\":[[\"29107.10\",\"1.806\"],[\"29207.10\",\"0.245\"],[\"29507.10\",\"0.049\"],[\"71646.30\",\"0.002\"],[\"78618.00\",\"0.619\"],[\"78811.00\",\"15.338\"],[\"79209.10\",\"3.967\"],[\"79232.90\",\"0.141\"],[\"79482.70\",\"0.543\"],[\"79491.70\",\"0.232\"],[\"79492.40\",\"0.092\"],[\"79543.70\",\"0.267\"],[\"79573.90\",\"0.454\"],[\"79574.70\",\"0.003\"],[\"79575.30\",\"0.174\"],[\"79583.20\",\"0.579\"],[\"79583.70\",\"0.644\"],[\"79583.80\",\"0.001\"],[\"79588.30\",\"0.008\"],[\"79592.10\",\"0.077\"],[\"79603.70\",\"0.037\"],[\"79607.10\",\"5.491\"]],\"a\":[[\"79728.70\",\"0.293\"],[\"79740.50\",\"0.768\"],[\"79774.40\",\"2.254\"],[\"79840.70\",\"0.256\"],[\"79961.60\",\"0.205\"],[\"79963.40\",\"0.670\"],[\"79967.40\",\"0.289\"],[\"79995.80\",\"0.863\"],[\"79997.80\",\"0.525\"],[\"80403.30\",\"22.286\"]],\"st\":1}}"}
{"receive_ns":1788563374072446000,"stream":"btcusdt@depth@100ms","event_type":"depthUpdate","event_time_ms":1788563374109,"raw_json":"{\"stream\":\"btcusdt@depth@100ms\",\"data\":{\"e\":\"depthUpdate\",\"E\":1788563374109,\"T\":1788563374105,\"s\":\"BTCUSDT\",\"ps\":\"BTCUSDT\",\"U\":11478232396663,\"u\":11478232401013,\"pu\":11478232396559,\"b\":[[\"29107.10\",\"1.855\"],[\"29207.10\",\"0.133\"],[\"29507.10\",\"0.112\"],[\"71646.30\",\"0.002\"],[\"76422.80\",\"0.000\"],[\"78394.60\",\"0.030\"],[\"78474.10\",\"0.000\"],[\"78811.00\",\"15.338\"],[\"78870.00\",\"0.094\"],[\"79209.00\",\"0.000\"],[\"79492.40\",\"0.099\"],[\"79573.90\",\"0.002\"],[\"79575.10\",\"1.191\"],[\"79579.90\",\"0.502\"],[\"79581.80\",\"2.949\"],[\"79582.90\",\"0.704\"],[\"79583.20\",\"0.328\"],[\"79583.70\",\"0.016\"],[\"79589.20\",\"0.897\"],[\"79592.10\",\"0.001\"],[\"79592.80\",\"0.004\"],[\"79602.60\",\"0.027\"],[\"79602.70\",\"0.028\"],[\"79602.90\",\"0.028\"],[\"79603.00\",\"0.029\"],[\"79603.40\",\"0.000\"],[\"79603.50\",\"0.004\"],[\"79603.70\",\"0.011\"]],\"a\":[[\"79622.10\",\"0.002\"],[\"79623.10\",\"0.937\"],[\"79624.40\",\"0.000\"],[\"79625.50\",\"0.458\"],[\"79963.40\",\"0.670\"],[\"79967.40\",\"0.289\"],[\"79999.30\",\"0.211\"],[\"80005.30\",\"0.002\"],[\"80344.20\",\"0.003\"],[\"80403.30\",\"22.286\"],[\"80562.50\",\"47.671\"],[\"80677.50\",\"0.023\"],[\"80740.00\",\"5.063\"],[\"80819.60\",\"0.029\"]],\"st\":1}}"}
{"receive_ns":1788563374167087000,"stream":"btcusdt@bookTicker","event_type":"bookTicker","event_time_ms":1788563374203,"raw_json":"{\"stream\":\"btcusdt@bookTicker\",\"data\":{\"e\":\"bookTicker\",\"u\":11478232404893,\"s\":\"BTCUSDT\",\"ps\":\"BTCUSDT\",\"b\":\"79607.10\",\"B\":\"5.494\",\"a\":\"79607.20\",\"A\":\"7.431\",\"T\":1788563374203,\"E\":1788563374203,\"st\":1}}"}
{"receive_ns":1788563374173682000,"stream":"btcusdt@depth@100ms","event_type":"depthUpdate","event_time_ms":1788563374211,"raw_json":"{\"stream\":\"btcusdt@depth@100ms\",\"data\":{\"e\":\"depthUpdate\",\"E\":1788563374211,\"T\":1788563374209,\"s\":\"BTCUSDT\",\"ps\":\"BTCUSDT\",\"U\":11478232401192,\"u\":11478232405176,\"pu\":11478232401013,\"b\":[[\"1000.00\",\"24.754\"],[\"29107.10\",\"1.911\"],[\"29207.10\",\"0.014\"],[\"29507.10\",\"0.175\"],[\"71646.30\",\"0.002\"],[\"76422.80\",\"0.002\"],[\"78394.60\",\"0.037\"],[\"78474.10\",\"0.007\"],[\"78645.10\",\"1.905\"],[\"78811.00\",\"15.338\"],[\"78870.00\",\"0.099\"],[\"79232.90\",\"0.141\"],[\"79482.70\",\"0.017\"],[\"79491.70\",\"0.232\"],[\"79533.70\",\"0.829\"],[\"79549.60\",\"0.691\"],[\"79575.30\",\"0.074\"],[\"79583.20\",\"0.428\"],[\"79583.40\",\"0.006\"],[\"79583.80\",\"0.001\"],[\"79601.60\",\"0.001\"],[\"79601.70\",\"0.000\"],[\"79603.10\",\"0.252\"],[\"79603.20\",\"0.029\"],[\"79607.10\",\"5.494\"]],\"a\":[[\"79623.30\",\"0.458\"],[\"79712.30\",\"0.000\"],[\"79728.70\",\"0.000\"],[\"79774.40\",\"2.254\"],[\"79963.40\",\"0.760\"],[\"79967.40\",\"0.199\"],[\"79995.80\",\"0.863\"],[\"79997.80\",\"0.525\"],[\"80005.30\",\"0.003\"],[\"80344.20\",\"0.008\"],[\"80403.30\",\"22.286\"]],\"st\":1}}"}
{"receive_ns":1788563374181923000,"stream":"btcusdt@bookTicker","event_type":"bookTicker","event_time_ms":1788563374218,"raw_json":"{\"stream\":\"btcusdt@bookTicker\",\"data\":{\"e\":\"bookTicker\",\"u\":11478232405587,\"s\":\"BTCUSDT\",\"ps\":\"BTCUSDT\",\"b\":\"79607.10\",\"B\":\"5.495\",\"a\":\"79607.20\",\"A\":\"7.431\",\"T\":1788563374218,\"E\":1788563374218,\"st\":1}}"}
{"receive_ns":1788563374182677000,"stream":"btcusdt@bookTicker","event_type":"bookTicker","event_time_ms":1788563374219,"raw_json":"{\"stream\":\"btcusdt@bookTicker\",\"data\":{\"e\":\"bookTicker\",\"u\":11478232405676,\"s\":\"BTCUSDT\",\"ps\":\"BTCUSDT\",\"b\":\"79607.10\",\"B\":\"5.495\",\"a\":\"79607.20\",\"A\":\"7.432\",\"T\":1788563374219,\"E\":1788563374219,\"st\":1}}"}
{"receive_ns":1788563374242479000,"stream":"btcusdt@bookTicker","event_type":"bookTicker","event_time_ms":1788563374272,"raw_json":"{\"stream\":\"btcusdt@bookTicker\",\"data\":{\"e\":\"bookTicker\",\"u\":11478232408451,\"s\":\"BTCUSDT\",\"ps\":\"BTCUSDT\",\"b\":\"79607.10\",\"B\":\"4.985\",\"a\":\"79607.20\",\"A\":\"7.432\",\"T\":1788563374272,\"E\":1788563374272,\"st\":1}}"}
{"receive_ns":1788563374243392000,"stream":"btcusdt@bookTicker","event_type":"bookTicker","event_time_ms":1788563374275,"raw_json":"{\"stream\":\"btcusdt@bookTicker\",\"data\":{\"e\":\"bookTicker\",\"u\":11478232408624,\"s\":\"BTCUSDT\",\"ps\":\"BTCUSDT\",\"b\":\"79607.10\",\"B\":\"5.500\",\"a\":\"79607.20\",\"A\":\"7.432\",\"T\":1788563374274,\"E\":1788563374275,\"st\":1}}"}
{"receive_ns":1788563374244341000,"stream":"btcusdt@bookTicker","event_type":"bookTicker","event_time_ms":1788563374276,"raw_json":"{\"stream\":\"btcusdt@bookTicker\",\"data\":{\"e\":\"bookTicker\",\"u\":11478232408681,\"s\":\"BTCUSDT\",\"ps\":\"BTCUSDT\",\"b\":\"79607.10\",\"B\":\"5.498\",\"a\":\"79607.20\",\"A\":\"7.432\",\"T\":1788563374276,\"E\":1788563374276,\"st\":1}}"}
{"receive_ns":1788563374245159000,"stream":"btcusdt@bookTicker","event_type":"bookTicker","event_time_ms":1788563374276,"raw_json":"{\"stream\":\"btcusdt@bookTicker\",\"data\":{\"e\":\"bookTicker\",\"u\":11478232408682,\"s\":\"BTCUSDT\",\"ps\":\"BTCUSDT\",\"b\":\"79607.10\",\"B\":\"5.497\",\"a\":\"79607.20\",\"A\":\"7.432\",\"T\":1788563374276,\"E\":1788563374276,\"st\":1}}"}
{"receive_ns":1788563374246224000,"stream":"btcusdt@bookTicker","event_type":"bookTicker","event_time_ms":1788563374277,"raw_json":"{\"stream\":\"btcusdt@bookTicker\",\"data\":{\"e\":\"bookTicker\",\"u\":11478232408714,\"s\":\"BTCUSDT\",\"ps\":\"BTCUSDT\",\"b\":\"79607.10\",\"B\":\"5.498\",\"a\":\"79607.20\",\"A\":\"7.432\",\"T\":1788563374277,\"E\":1788563374277,\"st\":1}}"}
{"receive_ns":1788563374281659000,"stream":"btcusdt@depth@100ms","event_type":"depthUpdate","event_time_ms":1788563374313,"raw_json":"{\"stream\":\"btcusdt@depth@100ms\",\"data\":{\"e\":\"depthUpdate\",\"E\":1788563374313,\"T\":1788563374310,\"s\":\"BTCUSDT\",\"ps\":\"BTCUSDT\",\"U\":11478232405278,\"u\":11478232410317,\"pu\":11478232405176,\"b\":[[\"29107.10\",\"1.764\"],[\"29207.10\",\"0.000\"],[\"29507.10\",\"0.336\"],[\"71646.30\",\"0.002\"],[\"76422.80\",\"0.000\"],[\"78528.10\",\"0.020\"],[\"78616.30\",\"0.003\"],[\"78618.80\",\"0.000\"],[\"78811.00\",\"15.338\"],[\"79209.10\",\"3.967\"],[\"79443.20\",\"0.000\"],[\"79443.30\",\"2.511\"],[\"79443.60\",\"0.927\"],[\"79482.70\",\"0.543\"],[\"79533.70\",\"0.000\"],[\"79549.60\",\"0.000\"],[\"79583.20\",\"0.855\"],[\"79589.20\",\"0.195\"],[\"79601.90\",\"0.000\"],[\"79604.10\",\"1.026\"],[\"79607.10\",\"5.498\"]],\"a\":[[\"79607.20\",\"7.432\"],[\"79627.70\",\"0.003\"],[\"79627.80\",\"0.047\"],[\"79728.70\",\"0.293\"],[\"79768.10\",\"1.325\"],[\"79828.60\",\"7.323\"],[\"79963.40\",\"0.760\"],[\"79967.40\",\"0.199\"],[\"79999.30\",\"0.167\"],[\"80019.50\",\"0.000\"],[\"80019.60\",\"0.087\"],[\"80403.30\",\"22.286\"],[\"80734.00\",\"1.036\"],[\"80740.00\",\"5.070\"],[\"80819.60\",\"0.036\"]],\"st\":1}}"}
{"receive_ns":1788563374378802000,"stream":"btcusdt@depth@100ms","event_type":"depthUpdate","event_time_ms":1788563374415,"raw_json":"{\"stream\":\"btcusdt@depth@100ms\",\"data\":{\"e\":\"depthUpdate\",\"E\":1788563374415,\"T\":1788563374414,\"s\":\"BTCUSDT\",\"ps\":\"BTCUSDT\",\"U\":11478232410440,\"u\":11478232415304,\"pu\":11478232410317,\"b\":[[\"29107.10\",\"1.582\"],[\"29507.10\",\"0.518\"],[\"63685.70\",\"0.003\"],[\"71646.30\",\"0.002\"],[\"78015.00\",\"10.572\"],[\"78491.70\",\"0.187\"],[\"78568.50\",\"7.756\"],[\"78572.20\",\"26.045\"],[\"78811.00\",\"15.338\"],[\"79232.90\",\"0.000\"],[\"79491.70\",\"0.000\"],[\"79520.40\",\"0.019\"],[\"79523.90\",\"1.619\"],[\"79548.30\",\"0.000\"],[\"79551.70\",\"0.639\"],[\"79568.20\",\"0.001\"],[\"79583.20\",\"0.579\"],[\"79588.70\",\"0.065\"],[\"79589.00\",\"0.000\"],[\"79589.20\",\"0.395\"]],\"a\":[[\"79637.90\",\"0.002\"],[\"79657.80\",\"0.001\"],[\"79685.00\",\"0.760\"],[\"79685.70\",\"0.001\"],[\"79774.40\",\"2.003\"],[\"79963.40\",\"0.419\"],[\"79995.80\",\"0.100\"],[\"79997.80\",\"0.000\"],[\"79999.30\",\"0.211\"],[\"80403.30\",\"22.286\"],[\"80529.50\",\"0.000\"],[\"80947.70\",\"0.000\"]],\"st\":1}}"}
{"receive_ns":1788563374417935000,"stream":"btcusdt@bookTicker","event_type":"bookTicker","event_time_ms":1788563374446,"raw_json":"{\"stream\":\"btcusdt@bookTicker\",\"data\":{\"e\":\"bookTicker\",\"u\":11478232416706,\"s\":\"BTCUSDT\",\"ps\":\"BTCUSDT\",\"b\":\"79607.10\",\"B\":\"5.498\",\"a\":\"79607.20\",\"A\":\"7.102\",\"T\":1788563374446,\"E\":1788563374446,\"st\":1}}"}
{"receive_ns":1788563374418194000,"stream":"btcusdt@bookTicker","event_type":"bookTicker","event_time_ms":1788563374447,"raw_json":"{\"stream\":\"btcusdt@bookTicker\",\"data\":{\"e\":\"bookTicker\",\"u\":11478232416778,\"s\":\"BTCUSDT\",\"ps\":\"BTCUSDT\",\"b\":\"79607.10\",\"B\":\"5.500\",\"a\":\"79607.20\",\"A\":\"7.102\",\"T\":1788563374447,\"E\":1788563374447,\"st\":1}}"}
{"receive_ns":1788563374465081000,"stream":"btcusdt@bookTicker","event_type":"bookTicker","event_time_ms":1788563374503,"raw_json":"{\"stream\":\"btcusdt@bookTicker\",\"data\":{\"e\":\"bookTicker\",\"u\":11478232419156,\"s\":\"BTCUSDT\",\"ps\":\"BTCUSDT\",\"b\":\"79607.10\",\"B\":\"5.500\",\"a\":\"79607.20\",\"A\":\"7.109\",\"T\":1788563374503,\"E\":1788563374503,\"st\":1}}"}
{"receive_ns":1788563374473444000,"stream":"btcusdt@bookTicker","event_type":"bookTicker","event_time_ms":1788563374510,"raw_json":"{\"stream\":\"btcusdt@bookTicker\",\"data\":{\"e\":\"bookTicker\",\"u\":11478232419614,\"s\":\"BTCUSDT\",\"ps\":\"BTCUSDT\",\"b\":\"79607.10\",\"B\":\"4.920\",\"a\":\"79607.20\",\"A\":\"7.109\",\"T\":1788563374510,\"E\":1788563374510,\"st\":1}}"}
{"receive_ns":1788563374476094000,"stream":"btcusdt@bookTicker","event_type":"bookTicker","event_time_ms":1788563374513,"raw_json":"{\"stream\":\"btcusdt@bookTicker\",\"data\":{\"e\":\"bookTicker\",\"u\":11478232419780,\"s\":\"BTCUSDT\",\"ps\":\"BTCUSDT\",\"b\":\"79607.10\",\"B\":\"5.507\",\"a\":\"79607.20\",\"A\":\"7.109\",\"T\":1788563374513,\"E\":1788563374513,\"st\":1}}"}
{"receive_ns":1788563374476304000,"stream":"btcusdt@bookTicker","event_type":"bookTicker","event_time_ms":1788563374514,"raw_json":"{\"stream\":\"btcusdt@bookTicker\",\"data\":{\"e\":\"bookTicker\",\"u\":11478232419883,\"s\":\"BTCUSDT\",\"ps\":\"BTCUSDT\",\"b\":\"79607.10\",\"B\":\"5.505\",\"a\":\"79607.20\",\"A\":\"7.109\",\"T\":1788563374514,\"E\":1788563374514,\"st\":1}}"}
{"receive_ns":1788563374481457000,"stream":"btcusdt@depth@100ms","event_type":"depthUpdate","event_time_ms":1788563374517,"raw_json":"{\"stream\":\"btcusdt@depth@100ms\",\"data\":{\"e\":\"depthUpdate\",\"E\":1788563374517,\"T\":1788563374516,\"s\":\"BTCUSDT\",\"ps\":\"BTCUSDT\",\"U\":11478232415354,\"u\":11478232420139,\"pu\":11478232415304,\"b\":[[\"1000.00\",\"24.754\"],[\"29107.10\",\"1.407\"],[\"29507.10\",\"0.693\"],[\"63685.70\",\"0.001\"],[\"71646.30\",\"0.002\"],[\"71684.00\",\"0.000\"],[\"75626.70\",\"0.031\"],[\"75626.80\",\"0.006\"],[\"76422.80\",\"0.002\"],[\"78500.60\",\"5.806\"],[\"78727.70\",\"0.887\"],[\"78811.00\",\"15.338\"],[\"79232.90\",\"0.141\"],[\"79395.40\",\"0.000\"],[\"79395.60\",\"2.889\"],[\"79480.70\",\"0.000\"],[\"79482.30\",\"2.138\"],[\"79491.70\",\"0.232\"],[\"79505.60\",\"1.440\"],[\"79515.50\",\"0.000\"],[\"79515.60\",\"4.675\"],[\"79575.20\",\"0.901\"],[\"79580.50\",\"0.254\"],[\"79583.20\",\"0.077\"],[\"79583.80\",\"0.001\"],[\"79583.90\",\"0.066\"],[\"79589.20\",\"0.195\"],[\"79602.00\",\"0.003\"],[\"79603.40\",\"0.026\"],[\"79604.10\",\"1.000\"],[\"79604.20\",\"0.027\"],[\"79607.10\",\"5.505\"]],\"a\":[[\"79607.20\",\"7.109\"],[\"79609.90\",\"0.000\"],[\"79610.70\",\"0.008\"],[\"79697.80\",\"4.081\"],[\"79724.40\",\"0.686\"],[\"79725.50\",\"0.000\"],[\"79774.40\",\"2.505\"],[\"79963.40\",\"0.090\"],[\"79967.40\",\"0.000\"],[\"79987.90\",\"0.763\"],[\"79997.80\",\"0.525\"],[\"79999.30\",\"0.055\"],[\"80403.30\",\"22.286\"]],\"st\":1}}"}
{"receive_ns":1788563374530234000,"stream":"btcusdt@bookTicker","event_type":"bookTicker","event_time_ms":1788563374568,"raw_json":"{\"stream\":\"btcusdt@bookTicker\",\"data\":{\"e\":\"bookTicker\",\"u\":11478232422704,\"s\":\"BTCUSDT\",\"ps\":\"BTCUSDT\",\"b\":\"79607.10\",\"B\":\"5.077\",\"a\":\"79607.20\",\"A\":\"7.109\",\"T\":1788563374568,\"E\":1788563374568,\"st\":1}}"}
{"receive_ns":1788563374531290000,"stream":"btcusdt@bookTicker","event_type":"bookTicker","event_time_ms":1788563374569,"raw_json":"{\"stream\":\"btcusdt@bookTicker\",\"data\":{\"e\":\"bookTicker\",\"u\":11478232422743,\"s\":\"BTCUSDT\",\"ps\":\"BTCUSDT\",\"b\":\"79607.10\",\"B\":\"5.079\",\"a\":\"79607.20\",\"A\":\"7.109\",\"T\":1788563374569,\"E\":1788563374569,\"st\":1}}"}
{"receive_ns":1788563374534272000,"stream":"btcusdt@bookTicker","event_type":"bookTicker","event_time_ms":1788563374571,"raw_json":"{\"stream\":\"btcusdt@bookTicker\",\"data\":{\"e\":\"bookTicker\",\"u\":11478232422916,\"s\":\"BTCUSDT\",\"ps\":\"BTCUSDT\",\"b\":\"79607.10\",\"B\":\"5.514\",\"a\":\"79607.20\",\"A\":\"7.109\",\"T\":1788563374571,\"E\":1788563374571,\"st\":1}}"}
{"receive_ns":1788563374583441000,"stream":"btcusdt@depth@100ms","event_type":"depthUpdate","event_time_ms":1788563374619,"raw_json":"{\"stream\":\"btcusdt@depth@100ms\",\"data\":{\"e\":\"depthUpdate\",\"E\":1788563374619,\"T\":1788563374618,\"s\":\"BTCUSDT\",\"ps\":\"BTCUSDT\",\"U\":11478232420266,\"u\":11478232425022,\"pu\":11478232420139,\"b\":[[\"29107.10\",\"1.225\"],[\"29507.10\",\"0.875\"],[\"63686.00\",\"0.000\"],[\"71646.30\",\"0.002\"],[\"76422.80\",\"0.000\"],[\"77378.10\",\"1.031\"],[\"77616.90\",\"1.480\"],[\"78237.90\",\"2.553\"],[\"78811.00\",\"15.338\"],[\"79209.10\",\"3.977\"],[\"79395.60\",\"5.030\"],[\"79519.50\",\"6.000\"],[\"79519.90\",\"1.728\"],[\"79547.40\",\"5.100\"],[\"79567.30\",\"0.421\"],[\"79575.20\",\"0.915\"],[\"79583.20\",\"0.579\"],[\"79589.20\",\"0.395\"],[\"79592.40\",\"0.424\"],[\"79595.80\",\"0.777\"],[\"79596.30\",\"0.033\"],[\"79602.20\",\"0.020\"],[\"79604.20\",\"0.027\"],[\"79604.70\",\"0.027\"],[\"79606.90\",\"0.197\"],[\"79607.10\",\"5.514\"]],\"a\":[[\"79621.00\",\"0.000\"],[\"79622.10\",\"0.374\"],[\"79623.10\",\"0.565\"],[\"79637.90\",\"0.431\"],[\"79657.80\",\"3.501\"],[\"79685.00\",\"1.558\"],[\"79685.70\",\"6.001\"],[\"79961.60\",\"0.120\"],[\"79963.40\",\"0.708\"],[\"79995.30\",\"0.158\"],[\"79999.30\",\"0.055\"],[\"80403.30\",\"22.286\"],[\"80538.60\",\"3.172\"],[\"81199.30\",\"10.759\"]],\"st\":1}}"}
{"receive_ns":1788563374598246000,"stream":"btcusdt@bookTicker","event_type":"bookTicker","event_time_ms":1788563374635,"raw_json":"{\"stream\":\"btcusdt@bookTicker\",\"data\":{\"e\":\"bookTicker\",\"u\":11478232426747,\"s\":\"BTCUSDT\",\"ps\":\"BTCUSDT\",\"b\":\"79607.10\",\"B\":\"5.516\",\"a\":\"79607.20\",\"A\":\"7.109\",\"T\":1788563374634,\"E\":1788563374635,\"st\":1}}"}
{"receive_ns":1788563374621146000,"stream":"btcusdt@bookTicker","event_type":"bookTicker","event_time_ms":1788563374656,"raw_json":"{\"stream\":\"btcusdt@bookTicker\",\"data\":{\"e\":\"bookTicker\",\"u\":11478232428068,\"s\":\"BTCUSDT\",\"ps\":\"BTCUSDT\",\"b\":\"79607.10\",\"B\":\"5.106\",\"a\":\"79607.20\",\"A\":\"7.109\",\"T\":1788563374656,\"E\":1788563374656,\"st\":1}}"}
{"receive_ns":1788563374628016000,"stream":"btcusdt@bookTicker","event_type":"bookTicker","event_time_ms":1788563374657,"raw_json":"{\"stream\":\"btcusdt@bookTicker\",\"data\":{\"e\":\"bookTicker\",\"u\":11478232428148,\"s\":\"BTCUSDT\",\"ps\":\"BTCUSDT\",\"b\":\"79607.10\",\"B\":\"5.104\",\"a\":\"79607.20\",\"A\":\"7.109\",\"T\":1788563374657,\"E\":1788563374657,\"st\":1}}"}
{"receive_ns":1788563374636257000,"stream":"btcusdt@bookTicker","event_type":"bookTicker","event_time_ms":1788563374669,"raw_json":"{\"stream\":\"btcusdt@bookTicker\",\"data\":{\"e\":\"bookTicker\",\"u\":11478232428641,\"s\":\"BTCUSDT\",\"ps\":\"BTCUSDT\",\"b\":\"79607.10\",\"B\":\"5.517\",\"a\":\"79607.20\",\"A\":\"7.109\",\"T\":1788563374668,\"E\":1788563374669,\"st\":1}}"}
{"receive_ns":1788563374636557000,"stream":"btcusdt@bookTicker","event_type":"bookTicker","event_time_ms":1788563374670,"raw_json":"{\"stream\":\"btcusdt@bookTicker\",\"data\":{\"e\":\"bookTicker\",\"u\":11478232428708,\"s\":\"BTCUSDT\",\"ps\":\"BTCUSDT\",\"b\":\"79607.10\",\"B\":\"5.519\",\"a\":\"79607.20\",\"A\":\"7.109\",\"T\":1788563374670,\"E\":1788563374670,\"st\":1}}"}
{"receive_ns":1788563374658354000,"stream":"btcusdt@bookTicker","event_type":"bookTicker","event_time_ms":1788563374687,"raw_json":"{\"stream\":\"btcusdt@bookTicker\",\"data\":{\"e\":\"bookTicker\",\"u\":11478232431628,\"s\":\"BTCUSDT\",\"ps\":\"BTCUSDT\",\"b\":\"79607.10\",\"B\":\"5.393\",\"a\":\"79607.20\",\"A\":\"7.109\",\"T\":1788563374687,\"E\":1788563374687,\"st\":1}}"}
{"receive_ns":1788563374658678000,"stream":"btcusdt@trade","event_type":"trade","event_time_ms":1788563374687,"raw_json":"{\"stream\":\"btcusdt@trade\",\"data\":{\"e\":\"trade\",\"E\":1788563374687,\"T\":1788563374687,\"s\":\"BTCUSDT\",\"t\":8054083446,\"p\":\"79607.10\",\"q\":\"0.126\",\"X\":\"MARKET\",\"m\":true,\"st\":1}}"}
{"receive_ns":1788563374694616000,"stream":"btcusdt@depth@100ms","event_type":"depthUpdate","event_time_ms":1788563374721,"raw_json":"{\"stream\":\"btcusdt@depth@100ms\",\"data\":{\"e\":\"depthUpdate\",\"E\":1788563374721,\"T\":1788563374717,\"s\":\"BTCUSDT\",\"ps\":\"BTCUSDT\",\"U\":11478232425073,\"u\":11478232433793,\"pu\":11478232425022,\"b\":[[\"29107.10\",\"1.050\"],[\"29507.10\",\"1.050\"],[\"63686.00\",\"0.000\"],[\"71646.30\",\"0.002\"],[\"76422.80\",\"0.002\"],[\"78651.80\",\"49.429\"],[\"78811.00\",\"15.338\"],[\"79232.90\",\"0.141\"],[\"79491.70\",\"0.232\"],[\"79505.60\",\"1.340\"],[\"79551.30\",\"0.005\"],[\"79564.40\",\"0.003\"],[\"79566.70\",\"0.085\"],[\"79576.20\",\"0.001\"],[\"79577.70\",\"0.002\"],[\"79579.90\",\"0.063\"],[\"79580.30\",\"0.001\"],[\"79581.80\",\"3.388\"],[\"79583.20\",\"0.679\"],[\"79583.80\",\"0.001\"],[\"79590.90\",\"0.000\"],[\"79591.00\",\"0.328\"],[\"79592.40\",\"0.348\"],[\"79595.70\",\"0.002\"],[\"79596.30\",\"0.032\"],[\"79602.40\",\"0.254\"],[\"79603.40\",\"0.000\"],[\"79603.70\",\"0.011\"],[\"79603.80\",\"0.003\"],[\"79604.10\",\"1.026\"],[\"79604.20\",\"0.001\"],[\"79604.70\",\"0.001\"],[\"79606.80\",\"0.003\"],[\"79607.10\",\"5.393\"]],\"a\":[[\"79621.00\",\"0.000\"],[\"79622.10\",\"0.374\"],[\"79623.10\",\"0.565\"],[\"79644.20\",\"1.385\"],[\"79646.90\",\"2.114\"],[\"79678.90\",\"0.013\"],[\"79702.80\",\"0.029\"],[\"79774.40\",\"2.505\"],[\"79963.40\",\"0.708\"],[\"79987.90\",\"0.763\"],[\"79997.80\",\"0.525\"],[\"80403.30\",\"22.286\"],[\"81199.30\",\"10.756\"]],\"st\":1}}"}
{"receive_ns":1788563374793921000,"stream":"btcusdt@depth@100ms","event_type":"depthUpdate","event_time_ms":1788563374823,"raw_json":"{\"stream\":\"btcusdt@depth@100ms\",\"data\":{\"e\":\"depthUpdate\",\"E\":1788563374823,\"T\":1788563374822,\"s\":\"BTCUSDT\",\"ps\":\"BTCUSDT\",\"U\":11478232433912,\"u\":11478232439946,\"pu\":11478232433793,\"b\":[[\"1000.00\",\"24.754\"],[\"29107.10\",\"0.868\"],[\"29507.10\",\"1.232\"],[\"71646.30\",\"0.002\"],[\"75626.70\",\"0.033\"],[\"76422.80\",\"0.000\"],[\"78015.00\",\"10.569\"],[\"78612.00\",\"13.844\"],[\"78811.00\",\"15.338\"],[\"78886.80\",\"3.566\"],[\"79479.10\",\"0.000\"],[\"79479.80\",\"10.340\"],[\"79479.90\",\"2.037\"],[\"79579.90\",\"0.502\"],[\"79581.80\",\"2.949\"],[\"79581.90\",\"0.061\"],[\"79582.70\",\"1.886\"],[\"79583.20\",\"0.830\"],[\"79589.20\",\"0.395\"],[\"79606.80\",\"0.004\"]],\"a\":[[\"79622.10\",\"0.002\"],[\"79623.00\",\"0.372\"],[\"79725.10\",\"10.077\"],[\"79963.40\",\"0.708\"],[\"79995.30\",\"0.002\"],[\"79999.30\",\"0.211\"],[\"80403.30\",\"22.286\"],[\"80571.90\",\"1.860\"],[\"80602.30\",\"9.478\"]],\"st\":1}}"}
{"receive_ns":1788563374886970000,"stream":"btcusdt@depth@100ms","event_type":"depthUpdate","event_time_ms":1788563374925,"raw_json":"{\"stream\":\"btcusdt@depth@100ms\",\"data\":{\"e\":\"depthUpdate\",\"E\":1788563374925,\"T\":1788563374922,\"s\":\"BTCUSDT\",\"ps\":\"BTCUSDT\",\"U\":11478232440027,\"u\":11478232444756,\"pu\":11478232439946,\"b\":[[\"29107.10\",\"0.693\"],[\"29507.10\",\"1.407\"],[\"63686.00\",\"0.000\"],[\"71646.30\",\"0.002\"],[\"77374.60\",\"1.032\"],[\"78492.60\",\"53.970\"],[\"78568.40\",\"4.498\"],[\"78731.40\",\"7.929\"],[\"78811.00\",\"15.338\"],[\"79209.10\",\"3.967\"],[\"79232.90\",\"0.000\"],[\"79491.70\",\"0.000\"]],\"a\":[[\"79774.40\",\"2.003\"],[\"79963.40\",\"0.618\"],[\"79987.90\",\"0.000\"],[\"79997.80\",\"0.000\"],[\"80403.30\",\"22.286\"],[\"80492.20\",\"0.620\"]],\"st\":1}}"}
{"receive_ns":1788563374991114000,"stream":"btcusdt@depth@100ms","event_type":"depthUpdate","event_time_ms":1788563375027,"raw_json":"{\"stream\":\"btcusdt@depth@100ms\",\"data\":{\"e\":\"depthUpdate\",\"E\":1788563375027,\"T\":1788563375026,\"s\":\"BTCUSDT\",\"ps\":\"BTCUSDT\",\"U\":11478232444973,\"u\":11478232451151,\"pu\":11478232444756,\"b\":[[\"1000.00\",\"24.754\"],[\"29107.10\",\"0.511\"],[\"29507.10\",\"1.589\"],[\"63686.00\",\"0.000\"],[\"71646.30\",\"0.002\"],[\"76422.80\",\"0.002\"],[\"78811.00\",\"15.338\"],[\"79232.90\",\"0.141\"],[\"79491.70\",\"0.332\"],[\"79581.80\",\"2.955\"],[\"79582.90\",\"0.076\"],[\"79583.20\",\"0.077\"],[\"79583.70\",\"0.644\"],[\"79583.80\",\"0.001\"],[\"79583.90\",\"0.060\"],[\"79588.30\",\"0.008\"],[\"79588.40\",\"0.004\"],[\"79589.20\",\"0.195\"]],\"a\":[[\"79724.40\",\"1.946\"],[\"79774.40\",\"2.505\"],[\"79828.60\",\"7.319\"],[\"79961.60\",\"0.197\"],[\"79963.40\",\"0.000\"],[\"79967.40\",\"0.090\"],[\"79987.90\",\"0.763\"],[\"79997.80\",\"0.525\"],[\"79999.30\",\"0.055\"],[\"80403.30\",\"22.286\"],[\"80523.20\",\"7.380\"],[\"80704.60\",\"0.014\"]],\"st\":1}}"}
{"receive_ns":1788563375045329000,"stream":"btcusdt@bookTicker","event_type":"bookTicker","event_time_ms":1788563375081,"raw_json":"{\"stream\":\"btcusdt@bookTicker\",\"data\":{\"e\":\"bookTicker\",\"u\":11478232454274,\"s\":\"BTCUSDT\",\"ps\":\"BTCUSDT\",\"b\":\"79607.10\",\"B\":\"5.394\",\"a\":\"79607.20\",\"A\":\"7.109\",\"T\":1788563375081,\"E\":1788563375081,\"st\":1}}"}
{"receive_ns":1788563375097501000,"stream":"btcusdt@depth@100ms","event_type":"depthUpdate","event_time_ms":1788563375129,"raw_json":"{\"stream\":\"btcusdt@depth@100ms\",\"data\":{\"e\":\"depthUpdate\",\"E\":1788563375129,\"T\":1788563375125,\"s\":\"BTCUSDT\",\"ps\":\"BTCUSDT\",\"U\":11478232451253,\"u\":11478232458078,\"pu\":11478232451151,\"b\":[[\"1000.00\",\"24.754\"],[\"29107.10\",\"0.343\"],[\"29407.10\",\"0.007\"],[\"29507.10\",\"1.750\"],[\"63686.00\",\"0.000\"],[\"71646.30\",\"0.002\"],[\"76422.80\",\"0.000\"],[\"78394.60\",\"0.031\"],[\"78563.30\",\"0.000\"],[\"78811.00\",\"15.338\"],[\"79491.70\",\"0.232\"],[\"79582.90\",\"0.704\"],[\"79583.20\",\"0.253\"],[\"79583.70\",\"0.016\"],[\"79589.20\",\"0.972\"],[\"79592.80\",\"0.004\"],[\"79603.50\",\"0.030\"],[\"79603.60\",\"1.545\"],[\"79603.80\",\"0.029\"],[\"79604.10\",\"1.000\"],[\"79604.40\",\"0.000\"],[\"79606.90\",\"0.199\"],[\"79607.10\",\"5.394\"]],\"a\":[[\"79615.10\",\"0.379\"],[\"79618.30\",\"0.001\"],[\"79630.50\",\"0.038\"],[\"79715.70\",\"0.001\"],[\"79961.60\",\"0.120\"],[\"79963.40\",\"0.419\"],[\"79967.40\",\"0.289\"],[\"79999.30\",\"0.211\"],[\"80005.30\",\"0.002\"],[\"80403.30\",\"22.286\"],[\"80819.60\",\"0.030\"]],\"st\":1}}"}
{"receive_ns":1788563375152089000,"stream":"btcusdt@bookTicker","event_type":"bookTicker","event_time_ms":1788563375188,"raw_json":"{\"stream\":\"btcusdt@bookTicker\",\"data\":{\"e\":\"bookTicker\",\"u\":11478232461623,\"s\":\"BTCUSDT\",\"ps\":\"BTCUSDT\",\"b\":\"79607.10\",\"B\":\"4.959\",\"a\":\"79607.20\",\"A\":\"7.109\",\"T\":1788563375188,\"E\":1788563375188,\"st\":1}}"}
{"receive_ns":1788563375153024000,"stream":"btcusdt@bookTicker","event_type":"bookTicker","event_time_ms":1788563375191,"raw_json":"{\"stream\":\"btcusdt@bookTicker\",\"data\":{\"e\":\"bookTicker\",\"u\":11478232461805,\"s\":\"BTCUSDT\",\"ps\":\"BTCUSDT\",\"b\":\"79607.10\",\"B\":\"5.395\",\"a\":\"79607.20\",\"A\":\"7.109\",\"T\":1788563375191,\"E\":1788563375191,\"st\":1}}"}
{"receive_ns":1788563375155204000,"stream":"btcusdt@bookTicker","event_type":"bookTicker","event_time_ms":1788563375192,"raw_json":"{\"stream\":\"btcusdt@bookTicker\",\"data\":{\"e\":\"bookTicker\",\"u\":11478232461867,\"s\":\"BTCUSDT\",\"ps\":\"BTCUSDT\",\"b\":\"79607.10\",\"B\":\"5.393\",\"a\":\"79607.20\",\"A\":\"7.109\",\"T\":1788563375192,\"E\":1788563375192,\"st\":1}}"}
{"receive_ns":1788563375204339000,"stream":"btcusdt@depth@100ms","event_type":"depthUpdate","event_time_ms":1788563375231,"raw_json":"{\"stream\":\"btcusdt@depth@100ms\",\"data\":{\"e\":\"depthUpdate\",\"E\":1788563375231,\"T\":1788563375229,\"s\":\"BTCUSDT\",\"ps\":\"BTCUSDT\",\"U\":11478232458381,\"u\":11478232464286,\"pu\":11478232458078,\"b\":[[\"29107.10\",\"0.217\"],[\"29407.10\",\"0.063\"],[\"29507.10\",\"1.820\"],[\"71646.30\",\"0.002\"],[\"76422.80\",\"0.002\"],[\"77378.10\",\"1.289\"],[\"78394.60\",\"0.037\"],[\"78676.90\",\"0.443\"],[\"78811.00\",\"15.338\"],[\"79209.00\",\"0.001\"],[\"79209.10\",\"3.977\"],[\"79232.90\",\"0.141\"],[\"79443.30\",\"2.510\"],[\"79482.70\",\"0.543\"],[\"79491.70\",\"0.000\"],[\"79573.90\",\"0.454\"],[\"79575.10\",\"0.739\"],[\"79579.90\",\"0.063\"],[\"79581.80\",\"3.394\"],[\"79583.20\",\"0.353\"],[\"79583.40\",\"0.006\"],[\"79583.80\",\"0.001\"],[\"79602.30\",\"0.028\"],[\"79602.40\",\"0.280\"],[\"79602.50\",\"0.027\"],[\"79602.90\",\"0.028\"],[\"79603.00\",\"0.029\"],[\"79603.10\",\"0.226\"],[\"79603.20\",\"0.029\"],[\"79603.30\",\"0.599\"],[\"79603.40\",\"0.000\"],[\"79603.50\",\"0.004\"],[\"79603.60\",\"1.519\"],[\"79603.80\",\"0.003\"],[\"79607.10\",\"5.393\"]],\"a\":[[\"79623.30\",\"0.458\"],[\"79623.50\",\"0.001\"],[\"79624.50\",\"0.931\"],[\"79625.50\",\"0.006\"],[\"79728.70\",\"0.293\"],[\"79768.10\",\"1.325\"],[\"79774.40\",\"2.003\"],[\"79963.40\",\"1.011\"],[\"79967.40\",\"0.199\"],[\"79987.90\",\"0.000\"],[\"79995.80\",\"0.863\"],[\"79997.80\",\"0.525\"],[\"80005.30\",\"0.001\"],[\"80403.30\",\"22.286\"],[\"80523.50\",\"8.184\"],[\"80819.60\",\"0.036\"]],\"st\":1}}"}
{"receive_ns":1788563375275086000,"stream":"btcusdt@bookTicker","event_type":"bookTicker","event_time_ms":1788563375311,"raw_json":"{\"stream\":\"btcusdt@bookTicker\",\"data\":{\"e\":\"bookTicker\",\"u\":11478232468318,\"s\":\"BTCUSDT\",\"ps\":\"BTCUSDT\",\"b\":\"79607.10\",\"B\":\"4.119\",\"a\":\"79607.20\",\"A\":\"7.109\",\"T\":1788563375311,\"E\":1788563375311,\"st\":1}}"}
{"receive_ns":1788563375275363000,"stream":"btcusdt@bookTicker","event_type":"bookTicker","event_time_ms":1788563375312,"raw_json":"{\"stream\":\"btcusdt@bookTicker\",\"data\":{\"e\":\"bookTicker\",\"u\":11478232468375,\"s\":\"BTCUSDT\",\"ps\":\"BTCUSDT\",\"b\":\"79607.10\",\"B\":\"4.121\",\"a\":\"79607.20\",\"A\":\"7.109\",\"T\":1788563375312,\"E\":1788563375312,\"st\":1}}"}
{"receive_ns":1788563375275841000,"stream":"btcusdt@bookTicker","event_type":"bookTicker","event_time_ms":1788563375314,"raw_json":"{\"stream\":\"btcusdt@bookTicker\",\"data\":{\"e\":\"bookTicker\",\"u\":11478232468532,\"s\":\"BTCUSDT\",\"ps\":\"BTCUSDT\",\"b\":\"79607.10\",\"B\":\"5.397\",\"a\":\"79607.20\",\"A\":\"7.109\",\"T\":1788563375314,\"E\":1788563375314,\"st\":1}}"}
{"receive_ns":1788563375277379000,"stream":"btcusdt@bookTicker","event_type":"bookTicker","event_time_ms":1788563375315,"raw_json":"{\"stream\":\"btcusdt@bookTicker\",\"data\":{\"e\":\"bookTicker\",\"u\":11478232468614,\"s\":\"BTCUSDT\",\"ps\":\"BTCUSDT\",\"b\":\"79607.10\",\"B\":\"5.396\",\"a\":\"79607.20\",\"A\":\"7.109\",\"T\":1788563375315,\"E\":1788563375315,\"st\":1}}"}
{"receive_ns":1788563375279000000,"stream":"btcusdt@bookTicker","event_type":"bookTicker","event_time_ms":1788563375316,"raw_json":"{\"stream\":\"btcusdt@bookTicker\",\"data\":{\"e\":\"bookTicker\",\"u\":11478232468708,\"s\":\"BTCUSDT\",\"ps\":\"BTCUSDT\",\"b\":\"79607.10\",\"B\":\"5.397\",\"a\":\"79607.20\",\"A\":\"7.109\",\"T\":1788563375316,\"E\":1788563375316,\"st\":1}}"}
{"receive_ns":1788563375294521000,"stream":"btcusdt@depth@100ms","event_type":"depthUpdate","event_time_ms":1788563375333,"raw_json":"{\"stream\":\"btcusdt@depth@100ms\",\"data\":{\"e\":\"depthUpdate\",\"E\":1788563375333,\"T\":1788563375331,\"s\":\"BTCUSDT\",\"ps\":\"BTCUSDT\",\"U\":11478232464448,\"u\":11478232469459,\"pu\":11478232464286,\"b\":[[\"1000.00\",\"24.754\"],[\"29107.10\",\"0.105\"],[\"29407.10\",\"0.126\"],[\"29507.10\",\"1.869\"],[\"71646.30\",\"0.002\"],[\"76422.80\",\"0.000\"],[\"78568.40\",\"3.608\"],[\"78616.30\",\"0.000\"],[\"78618.70\",\"0.002\"],[\"78651.80\",\"48.414\"],[\"78675.70\",\"3.111\"],[\"78811.00\",\"15.338\"],[\"79209.00\",\"0.002\"],[\"79505.90\",\"0.208\"],[\"79521.90\",\"0.363\"],[\"79573.90\",\"0.002\"],[\"79574.70\",\"0.455\"],[\"79575.90\",\"0.001\"],[\"79579.90\",\"0.502\"],[\"79581.80\",\"2.955\"],[\"79583.20\",\"0.604\"],[\"79589.20\",\"0.470\"],[\"79603.50\",\"0.030\"],[\"79607.10\",\"5.397\"]],\"a\":[[\"79624.50\",\"0.479\"],[\"79625.40\",\"0.452\"],[\"79963.40\",\"1.011\"],[\"79967.40\",\"0.199\"],[\"79999.30\",\"0.211\"],[\"80403.30\",\"22.286\"],[\"80713.70\",\"7.071\"]],\"st\":1}}"}
{"receive_ns":1788563375397968000,"stream":"btcusdt@depth@100ms","event_type":"depthUpdate","event_time_ms":1788563375435,"raw_json":"{\"stream\":\"btcusdt@depth@100ms\",\"data\":{\"e\":\"depthUpdate\",\"E\":1788563375435,\"T\":1788563375434,\"s\":\"BTCUSDT\",\"ps\":\"BTCUSDT\",\"U\":11478232469586,\"u\":11478232473604,\"pu\":11478232469459,\"b\":[[\"1000.00\",\"24.754\"],[\"29107.10\",\"0.000\"],[\"29407.10\",\"0.203\"],[\"29507.10\",\"1.897\"],[\"63685.70\",\"0.001\"],[\"71646.30\",\"0.002\"],[\"78015.00\",\"10.572\"],[\"78114.70\",\"0.639\"],[\"78811.00\",\"15.338\"],[\"78970.20\",\"8.002\"],[\"79232.90\",\"0.141\"],[\"79491.70\",\"0.232\"],[\"79583.20\",\"0.604\"],[\"79583.80\",\"2.009\"]],\"a\":[[\"79774.40\",\"2.254\"],[\"79963.40\",\"0.760\"],[\"79995.80\",\"0.863\"],[\"79997.80\",\"0.525\"],[\"80403.30\",\"22.286\"],[\"80598.60\",\"15.182\"],[\"80681.90\",\"9.895\"],[\"87568.00\",\"0.000\"]],\"st\":1}}"}
{"receive_ns":1788563375440300000,"stream":"btcusdt@bookTicker","event_type":"bookTicker","event_time_ms":1788563375478,"raw_json":"{\"stream\":\"btcusdt@bookTicker\",\"data\":{\"e\":\"bookTicker\",\"u\":11478232475866,\"s\":\"BTCUSDT\",\"ps\":\"BTCUSDT\",\"b\":\"79607.10\",\"B\":\"5.397\",\"a\":\"79607.20\",\"A\":\"7.106\",\"T\":1788563375478,\"E\":1788563375478,\"st\":1}}"}
{"receive_ns":1788563375479419000,"stream":"btcusdt@bookTicker","event_type":"bookTicker","event_time_ms":1788563375516,"raw_json":"{\"stream\":\"btcusdt@bookTicker\",\"data\":{\"e\":\"bookTicker\",\"u\":11478232477886,\"s\":\"BTCUSDT\",\"ps\":\"BTCUSDT\",\"b\":\"79607.10\",\"B\":\"4.810\",\"a\":\"79607.20\",\"A\":\"7.106\",\"T\":1788563375515,\"E\":1788563375516,\"st\":1}}"}
{"receive_ns":1788563375480042000,"stream":"btcusdt@bookTicker","event_type":"bookTicker","event_time_ms":1788563375516,"raw_json":"{\"stream\":\"btcusdt@bookTicker\",\"data\":{\"e\":\"bookTicker\",\"u\":11478232477939,\"s\":\"BTCUSDT\",\"ps\":\"BTCUSDT\",\"b\":\"79607.10\",\"B\":\"4.808\",\"a\":\"79607.20\",\"A\":\"7.106\",\"T\":1788563375516,\"E\":1788563375516,\"st\":1}}"}
{"receive_ns":1788563375484001000,"stream":"btcusdt@bookTicker","event_type":"bookTicker","event_time_ms":1788563375518,"raw_json":"{\"stream\":\"btcusdt@bookTicker\",\"data\":{\"e\":\"bookTicker\",\"u\":11478232478010,\"s\":\"BTCUSDT\",\"ps\":\"BTCUSDT\",\"b\":\"79607.10\",\"B\":\"5.396\",\"a\":\"79607.20\",\"A\":\"7.106\",\"T\":1788563375518,\"E\":1788563375518,\"st\":1}}"}
{"receive_ns":1788563375484261000,"stream":"btcusdt@bookTicker","event_type":"bookTicker","event_time_ms":1788563375519,"raw_json":"{\"stream\":\"btcusdt@bookTicker\",\"data\":{\"e\":\"bookTicker\",\"u\":11478232478051,\"s\":\"BTCUSDT\",\"ps\":\"BTCUSDT\",\"b\":\"79607.10\",\"B\":\"5.398\",\"a\":\"79607.20\",\"A\":\"7.106\",\"T\":1788563375519,\"E\":1788563375519,\"st\":1}}"}
{"receive_ns":1788563375500794000,"stream":"btcusdt@bookTicker","event_type":"bookTicker","event_time_ms":1788563375536,"raw_json":"{\"stream\":\"btcusdt@bookTicker\",\"data\":{\"e\":\"bookTicker\",\"u\":11478232478748,\"s\":\"BTCUSDT\",\"ps\":\"BTCUSDT\",\"b\":\"79607.10\",\"B\":\"5.394\",\"a\":\"79607.20\",\"A\":\"7.106\",\"T\":1788563375536,\"E\":1788563375536,\"st\":1}}"}
{"receive_ns":1788563375501004000,"stream":"btcusdt@trade","event_type":"trade","event_time_ms":1788563375536,"raw_json":"{\"stream\":\"btcusdt@trade\",\"data\":{\"e\":\"trade\",\"E\":1788563375536,\"T\":1788563375536,\"s\":\"BTCUSDT\",\"t\":8054083447,\"p\":\"79607.10\",\"q\":\"0.004\",\"X\":\"MARKET\",\"m\":true,\"st\":1}}"}
{"receive_ns":1788563375501348000,"stream":"btcusdt@depth@100ms","event_type":"depthUpdate","event_time_ms":1788563375537,"raw_json":"{\"stream\":\"btcusdt@depth@100ms\",\"data\":{\"e\":\"depthUpdate\",\"E\":1788563375537,\"T\":1788563375536,\"s\":\"BTCUSDT\",\"ps\":\"BTCUSDT\",\"U\":11478232473694,\"u\":11478232478748,\"pu\":11478232473604,\"b\":[[\"29407.10\",\"0.378\"],[\"29507.10\",\"1.722\"],[\"71646.30\",\"0.002\"],[\"76422.80\",\"0.002\"],[\"78527.70\",\"2.460\"],[\"78651.80\",\"49.429\"],[\"78811.00\",\"15.338\"],[\"78970.20\",\"8.000\"],[\"79209.10\",\"3.977\"],[\"79535.40\",\"0.002\"],[\"79582.90\",\"0.076\"],[\"79583.20\",\"0.855\"],[\"79583.70\",\"0.644\"],[\"79583.80\",\"0.001\"],[\"79588.30\",\"0.008\"],[\"79588.40\",\"0.004\"],[\"79589.20\",\"0.195\"],[\"79592.60\",\"0.002\"],[\"79604.10\",\"1.000\"],[\"79607.10\",\"5.394\"]],\"a\":[[\"79607.20\",\"7.106\"],[\"79623.20\",\"0.190\"],[\"79678.90\",\"0.015\"],[\"79963.40\",\"0.760\"],[\"79967.40\",\"0.000\"],[\"79999.30\",\"0.167\"],[\"80403.30\",\"22.286\"]],\"st\":1}}"}
{"receive_ns":1788563375535812000,"stream":"btcusdt@bookTicker","event_type":"bookTicker","event_time_ms":1788563375573,"raw_json":"{\"stream\":\"btcusdt@bookTicker\",\"data\":{\"e\":\"bookTicker\",\"u\":11478232480205,\"s\":\"BTCUSDT\",\"ps\":\"BTCUSDT\",\"b\":\"79607.10\",\"B\":\"4.879\",\"a\":\"79607.20\",\"A\":\"7.106\",\"T\":1788563375573,\"E\":1788563375573,\"st\":1}}"}
{"receive_ns":1788563375537984000,"stream":"btcusdt@bookTicker","event_type":"bookTicker","event_time_ms":1788563375576,"raw_json":"{\"stream\":\"btcusdt@bookTicker\",\"data\":{\"e\":\"bookTicker\",\"u\":11478232480333,\"s\":\"BTCUSDT\",\"ps\":\"BTCUSDT\",\"b\":\"79607.10\",\"B\":\"5.403\",\"a\":\"79607.20\",\"A\":\"7.106\",\"T\":1788563375576,\"E\":1788563375576,\"st\":1}}"}
{"receive_ns":1788563375538936000,"stream":"btcusdt@bookTicker","event_type":"bookTicker","event_time_ms":1788563375577,"raw_json":"{\"stream\":\"btcusdt@bookTicker\",\"data\":{\"e\":\"bookTicker\",\"u\":11478232480376,\"s\":\"BTCUSDT\",\"ps\":\"BTCUSDT\",\"b\":\"79607.10\",\"B\":\"5.401\",\"a\":\"79607.20\",\"A\":\"7.106\",\"T\":1788563375577,\"E\":1788563375577,\"st\":1}}"}
{"receive_ns":1788563375601762000,"stream":"btcusdt@depth@100ms","event_type":"depthUpdate","event_time_ms":1788563375639,"raw_json":"{\"stream\":\"btcusdt@depth@100ms\",\"data\":{\"e\":\"depthUpdate\",\"E\":1788563375639,\"T\":1788563375637,\"s\":\"BTCUSDT\",\"ps\":\"BTCUSDT\",\"U\":11478232478787,\"u\":11478232483030,\"pu\":11478232478748,\"b\":[[\"1000.00\",\"24.754\"],[\"29407.10\",\"0.560\"],[\"29507.10\",\"1.540\"],[\"63686.00\",\"0.000\"],[\"71646.30\",\"0.002\"],[\"71684.00\",\"0.000\"],[\"75626.80\",\"0.004\"],[\"76422.80\",\"0.000\"],[\"77935.40\",\"0.258\"],[\"78015.00\",\"10.569\"],[\"78631.80\",\"0.000\"],[\"78676.90\",\"0.000\"],[\"78811.00\",\"15.338\"],[\"78970.20\",\"7.748\"],[\"79010.00\",\"4.312\"],[\"79395.60\",\"2.848\"],[\"79515.60\",\"0.060\"],[\"79515.80\",\"0.562\"],[\"79583.20\",\"0.604\"],[\"79589.20\",\"0.470\"],[\"79604.30\",\"0.026\"],[\"79607.10\",\"5.401\"]],\"a\":[[\"79697.80\",\"0.001\"],[\"79967.40\",\"0.199\"],[\"79999.30\",\"0.211\"],[\"80403.30\",\"22.286\"],[\"81199.30\",\"10.759\"]],\"st\":1}}"}
{"receive_ns":1788563375627455000,"stream":"btcusdt@bookTicker","event_type":"bookTicker","event_time_ms":1788563375665,"raw_json":"{\"stream\":\"btcusdt@bookTicker\",\"data\":{\"e\":\"bookTicker\",\"u\":11478232484284,\"s\":\"BTCUSDT\",\"ps\":\"BTCUSDT\",\"b\":\"79607.10\",\"B\":\"5.404\",\"a\":\"79607.20\",\"A\":\"7.106\",\"T\":1788563375664,\"E\":1788563375665,\"st\":1}}"}
{"receive_ns":1788563375706438000,"stream":"btcusdt@depth@100ms","event_type":"depthUpdate","event_time_ms":1788563375741,"raw_json":"{\"stream\":\"btcusdt@depth@100ms\",\"data\":{\"e\":\"depthUpdate\",\"E\":1788563375741,\"T\":1788563375739,\"s\":\"BTCUSDT\",\"ps\":\"BTCUSDT\",\"U\":11478232483142,\"u\":11478232488461,\"pu\":11478232483030,\"b\":[[\"1000.00\",\"24.754\"],[\"29407.10\",\"0.735\"],[\"29507.10\",\"1.365\"],[\"71646.30\",\"0.002\"],[\"75626.70\",\"0.031\"],[\"75626.80\",\"0.006\"],[\"76422.80\",\"0.002\"],[\"78473.10\",\"1.224\"],[\"78727.70\",\"0.697\"],[\"79232.90\",\"0.141\"],[\"79395.60\",\"5.030\"],[\"79462.00\",\"0.052\"],[\"79462.10\",\"18.335\"],[\"79464.00\",\"0.828\"],[\"79491.70\",\"0.232\"],[\"79515.70\",\"5.806\"],[\"79583.20\",\"0.604\"],[\"79583.70\",\"0.016\"],[\"79583.80\",\"0.001\"],[\"79587.90\",\"0.036\"],[\"79588.30\",\"0.008\"],[\"79588.40\",\"0.632\"],[\"79602.30\",\"0.002\"],[\"79604.50\",\"0.026\"],[\"79607.10\",\"5.404\"]],\"a\":[[\"79610.70\",\"0.006\"],[\"79630.60\",\"1.888\"],[\"79697.80\",\"4.221\"],[\"79748.00\",\"2.506\"],[\"79751.30\",\"0.000\"],[\"79751.40\",\"17.556\"],[\"79774.40\",\"2.254\"],[\"79828.60\",\"7.167\"],[\"79963.40\",\"0.670\"],[\"79967.40\",\"0.289\"],[\"79987.90\",\"0.763\"],[\"79995.80\",\"0.100\"],[\"79997.80\",\"0.525\"],[\"80403.30\",\"22.286\"],[\"80539.80\",\"1.476\"],[\"80911.60\",\"1.419\"]],\"st\":1}}"}
{"receive_ns":1788563375755325000,"stream":"btcusdt@bookTicker","event_type":"bookTicker","event_time_ms":1788563375793,"raw_json":"{\"stream\":\"btcusdt@bookTicker\",\"data\":{\"e\":\"bookTicker\",\"u\":11478232490643,\"s\":\"BTCUSDT\",\"ps\":\"BTCUSDT\",\"b\":\"79607.10\",\"B\":\"5.403\",\"a\":\"79607.20\",\"A\":\"7.106\",\"T\":1788563375793,\"E\":1788563375793,\"st\":1}}"}
{"receive_ns":1788563375806059000,"stream":"btcusdt@bookTicker","event_type":"bookTicker","event_time_ms":1788563375841,"raw_json":"{\"stream\":\"btcusdt@bookTicker\",\"data\":{\"e\":\"bookTicker\",\"u\":11478232493587,\"s\":\"BTCUSDT\",\"ps\":\"BTCUSDT\",\"b\":\"79607.10\",\"B\":\"5.404\",\"a\":\"79607.20\",\"A\":\"7.106\",\"T\":1788563375841,\"E\":1788563375841,\"st\":1}}"}
{"receive_ns":1788563375815393000,"stream":"btcusdt@depth@100ms","event_type":"depthUpdate","event_time_ms":1788563375843,"raw_json":"{\"stream\":\"btcusdt@depth@100ms\",\"data\":{\"e\":\"depthUpdate\",\"E\":1788563375843,\"T\":1788563375841,\"s\":\"BTCUSDT\",\"ps\":\"BTCUSDT\",\"U\":11478232488527,\"u\":11478232493587,\"pu\":11478232488461,\"b\":[[\"29407.10\",\"0.910\"],[\"29507.10\",\"1.190\"],[\"71646.30\",\"0.002\"],[\"78675.70\",\"3.555\"],[\"78811.00\",\"15.338\"],[\"79209.10\",\"3.967\"],[\"79422.20\",\"0.003\"],[\"79491.70\",\"0.483\"],[\"79579.90\",\"0.063\"],[\"79581.80\",\"3.394\"],[\"79583.20\",\"0.504\"],[\"79583.70\",\"0.644\"],[\"79588.40\",\"0.004\"],[\"79589.20\",\"0.470\"],[\"79592.40\",\"0.424\"],[\"79592.80\",\"0.004\"],[\"79603.70\",\"0.037\"],[\"79604.30\",\"0.000\"],[\"79604.40\",\"0.000\"],[\"79604.50\",\"0.000\"],[\"79604.80\",\"0.028\"],[\"79605.00\",\"0.630\"],[\"79606.80\",\"0.003\"],[\"79607.10\",\"5.404\"]],\"a\":[[\"79630.60\",\"1.884\"],[\"79747.90\",\"0.000\"],[\"79748.00\",\"4.958\"],[\"79749.70\",\"0.123\"],[\"79963.40\",\"0.670\"],[\"79967.40\",\"0.289\"],[\"79999.30\",\"0.211\"],[\"80403.30\",\"22.286\"]],\"st\":1}}"}
{"receive_ns":1788563375840757000,"stream":"btcusdt@bookTicker","event_type":"bookTicker","event_time_ms":1788563375878,"raw_json":"{\"stream\":\"btcusdt@bookTicker\",\"data\":{\"e\":\"bookTicker\",\"u\":11478232495310,\"s\":\"BTCUSDT\",\"ps\":\"BTCUSDT\",\"b\":\"79607.10\",\"B\":\"5.404\",\"a\":\"79607.20\",\"A\":\"7.102\",\"T\":1788563375878,\"E\":1788563375878,\"st\":1}}"}
{"receive_ns":1788563375850209000,"stream":"btcusdt@bookTicker","event_type":"bookTicker","event_time_ms":1788563375888,"raw_json":"{\"stream\":\"btcusdt@bookTicker\",\"data\":{\"e\":\"bookTicker\",\"u\":11478232495785,\"s\":\"BTCUSDT\",\"ps\":\"BTCUSDT\",\"b\":\"79607.10\",\"B\":\"5.404\",\"a\":\"79607.20\",\"A\":\"7.108\",\"T\":1788563375887,\"E\":1788563375888,\"st\":1}}"}
{"receive_ns":1788563375917109000,"stream":"btcusdt@depth@100ms","event_type":"depthUpdate","event_time_ms":1788563375945,"raw_json":"{\"stream\":\"btcusdt@depth@100ms\",\"data\":{\"e\":\"depthUpdate\",\"E\":1788563375945,\"T\":1788563375942,\"s\":\"BTCUSDT\",\"ps\":\"BTCUSDT\",\"U\":11478232493668,\"u\":11478232498232,\"pu\":11478232493587,\"b\":[[\"1000.00\",\"24.754\"],[\"29407.10\",\"1.092\"],[\"29507.10\",\"1.008\"],[\"71646.30\",\"0.002\"],[\"75626.70\",\"0.026\"],[\"75626.80\",\"0.008\"],[\"76422.80\",\"0.000\"],[\"78608.50\",\"12.484\"],[\"78811.00\",\"15.338\"],[\"79232.90\",\"0.141\"],[\"79491.70\",\"0.583\"],[\"79511.50\",\"0.024\"],[\"79531.40\",\"0.031\"],[\"79535.40\",\"0.000\"],[\"79576.70\",\"0.360\"],[\"79579.90\",\"0.502\"],[\"79581.80\",\"2.949\"],[\"79583.70\",\"0.016\"],[\"79583.80\",\"0.001\"],[\"79588.30\",\"0.636\"],[\"79592.40\",\"0.348\"],[\"79602.40\",\"0.254\"],[\"79602.50\",\"0.001\"],[\"79602.60\",\"0.001\"],[\"79603.80\",\"0.029\"],[\"79603.90\",\"0.027\"],[\"79604.00\",\"0.030\"],[\"79604.20\",\"0.027\"],[\"79604.80\",\"0.002\"]],\"a\":[[\"79607.20\",\"7.108\"],[\"79678.90\",\"0.015\"],[\"79747.90\",\"0.006\"],[\"79749.70\",\"0.117\"],[\"79774.40\",\"2.505\"],[\"79963.40\",\"0.509\"],[\"79967.40\",\"0.199\"],[\"79987.90\",\"0.000\"],[\"79995.80\",\"0.863\"],[\"79997.80\",\"0.525\"],[\"80364.70\",\"0.558\"],[\"80403.30\",\"22.286\"],[\"80479.00\",\"2.832\"],[\"80538.60\",\"3.606\"],[\"80681.90\",\"10.390\"]],\"st\":1}}"}
{"receive_ns":1788563376016913000,"stream":"btcusdt@depth@100ms","event_type":"depthUpdate","event_time_ms":1788563376047,"raw_json":"{\"stream\":\"btcusdt@depth@100ms\",\"data\":{\"e\":\"depthUpdate\",\"E\":1788563376047,\"T\":1788563376046,\"s\":\"BTCUSDT\",\"ps\":\"BTCUSDT\",\"U\":11478232498359,\"u\":11478232502592,\"pu\":11478232498232,\"b\":[[\"1000.00\",\"24.754\"],[\"29407.10\",\"1.274\"],[\"29507.10\",\"0.826\"],[\"63686.00\",\"0.000\"],[\"71646.30\",\"0.002\"],[\"76422.80\",\"0.002\"],[\"78015.00\",\"10.563\"],[\"78811.00\",\"15.338\"],[\"79464.00\",\"3.483\"],[\"79491.70\",\"0.583\"],[\"79515.80\",\"1.201\"],[\"79582.90\",\"0.704\"],[\"79583.20\",\"0.579\"],[\"79583.70\",\"0.016\"],[\"79588.30\",\"0.008\"],[\"79588.40\",\"0.004\"],[\"79589.20\",\"0.395\"],[\"79592.60\",\"0.002\"],[\"79592.80\",\"0.008\"],[\"79602.70\",\"0.002\"],[\"79604.20\",\"0.001\"],[\"79604.80\",\"0.002\"],[\"79606.90\",\"0.197\"]],\"a\":[[\"79961.60\",\"0.120\"],[\"79963.40\",\"0.509\"],[\"79967.40\",\"0.000\"],[\"79999.30\",\"0.211\"],[\"80403.30\",\"22.286\"]],\"st\":1}}"}
{"receive_ns":1788563376085127000,"stream":"btcusdt@bookTicker","event_type":"bookTicker","event_time_ms":1788563376123,"raw_json":"{\"stream\":\"btcusdt@bookTicker\",\"data\":{\"e\":\"bookTicker\",\"u\":11478232507085,\"s\":\"BTCUSDT\",\"ps\":\"BTCUSDT\",\"b\":\"79607.10\",\"B\":\"5.404\",\"a\":\"79607.20\",\"A\":\"7.104\",\"T\":1788563376123,\"E\":1788563376123,\"st\":1}}"}
{"receive_ns":1788563376085746000,"stream":"btcusdt@trade","event_type":"trade","event_time_ms":1788563376123,"raw_json":"{\"stream\":\"btcusdt@trade\",\"data\":{\"e\":\"trade\",\"E\":1788563376123,\"T\":1788563376123,\"s\":\"BTCUSDT\",\"t\":8054083448,\"p\":\"79607.20\",\"q\":\"0.004\",\"X\":\"MARKET\",\"m\":false,\"st\":1}}"}
{"receive_ns":1788563376087348000,"stream":"btcusdt@bookTicker","event_type":"bookTicker","event_time_ms":1788563376125,"raw_json":"{\"stream\":\"btcusdt@bookTicker\",\"data\":{\"e\":\"bookTicker\",\"u\":11478232507282,\"s\":\"BTCUSDT\",\"ps\":\"BTCUSDT\",\"b\":\"79607.10\",\"B\":\"5.366\",\"a\":\"79607.20\",\"A\":\"7.104\",\"T\":1788563376125,\"E\":1788563376125,\"st\":1}}"}
{"receive_ns":1788563376112045000,"stream":"btcusdt@depth@100ms","event_type":"depthUpdate","event_time_ms":1788563376149,"raw_json":"{\"stream\":\"btcusdt@depth@100ms\",\"data\":{\"e\":\"depthUpdate\",\"E\":1788563376149,\"T\":1788563376145,\"s\":\"BTCUSDT\",\"ps\":\"BTCUSDT\",\"U\":11478232502615,\"u\":11478232508231,\"pu\":11478232502592,\"b\":[[\"29407.10\",\"1.449\"],[\"29507.10\",\"0.651\"],[\"63686.00\",\"0.000\"],[\"71646.30\",\"0.002\"],[\"76422.80\",\"0.000\"],[\"78532.40\",\"8.876\"],[\"78572.20\",\"26.935\"],[\"78811.00\",\"15.338\"],[\"79209.10\",\"3.967\"],[\"79232.90\",\"0.000\"],[\"79491.70\",\"0.251\"],[\"79564.40\",\"0.002\"],[\"79566.60\",\"0.197\"],[\"79577.70\",\"0.001\"],[\"79579.80\",\"1.201\"],[\"79583.20\",\"0.002\"],[\"79592.40\",\"0.424\"],[\"79592.80\",\"0.004\"],[\"79602.60\",\"0.027\"],[\"79602.70\",\"0.028\"],[\"79602.80\",\"0.026\"],[\"79603.80\",\"0.003\"],[\"79603.90\",\"0.001\"],[\"79604.00\",\"0.004\"],[\"79605.90\",\"0.000\"],[\"79607.10\",\"5.366\"]],\"a\":[[\"79607.20\",\"7.104\"],[\"79660.00\",\"0.790\"],[\"79774.40\",\"2.003\"],[\"79963.40\",\"0.419\"],[\"79967.40\",\"0.199\"],[\"79995.80\",\"0.100\"],[\"79997.80\",\"0.000\"],[\"80005.20\",\"3.629\"],[\"80363.50\",\"11.304\"],[\"80403.30\",\"22.286\"],[\"80598.60\",\"14.996\"],[\"80737.60\",\"1.628\"]],\"st\":1}}"}
{"receive_ns":1788563376216152000,"stream":"btcusdt@depth@100ms","event_type":"depthUpdate","event_time_ms":1788563376251,"raw_json":"{\"stream\":\"btcusdt@depth@100ms\",\"data\":{\"e\":\"depthUpdate\",\"E\":1788563376251,\"T\":1788563376249,\"s\":\"BTCUSDT\",\"ps\":\"BTCUSDT\",\"U\":11478232508497,\"u\":11478232514006,\"pu\":11478232508231,\"b\":[[\"1000.00\",\"24.754\"],[\"29407.10\",\"1.631\"],[\"29507.10\",\"0.469\"],[\"71646.30\",\"0.002\"],[\"76422.80\",\"0.002\"],[\"78651.80\",\"50.762\"],[\"78731.40\",\"8.119\"],[\"78811.00\",\"15.338\"],[\"78886.80\",\"2.680\"],[\"79209.00\",\"0.001\"],[\"79232.90\",\"0.141\"],[\"79491.70\",\"0.332\"],[\"79521.80\",\"0.012\"],[\"79524.20\",\"0.164\"],[\"79582.90\",\"0.704\"],[\"79583.40\",\"0.006\"],[\"79583.80\",\"0.001\"],[\"79588.30\",\"0.008\"],[\"79589.20\",\"0.195\"],[\"79604.10\",\"1.026\"]],\"a\":[[\"79623.30\",\"0.458\"],[\"79774.40\",\"2.505\"],[\"79963.40\",\"0.090\"],[\"79964.00\",\"0.764\"],[\"79967.40\",\"0.000\"],[\"79997.80\",\"0.525\"],[\"79999.30\",\"0.055\"],[\"80005.30\",\"0.002\"],[\"80403.30\",\"22.286\"],[\"80768.30\",\"0.125\"],[\"80952.60\",\"1.479\"]],\"st\":1}}"}
{"receive_ns":1788563376222324000,"stream":"btcusdt@bookTicker","event_type":"bookTicker","event_time_ms":1788563376260,"raw_json":"{\"stream\":\"btcusdt@bookTicker\",\"data\":{\"e\":\"bookTicker\",\"u\":11478232514584,\"s\":\"BTCUSDT\",\"ps\":\"BTCUSDT\",\"b\":\"79607.10\",\"B\":\"5.373\",\"a\":\"79607.20\",\"A\":\"7.104\",\"T\":1788563376260,\"E\":1788563376260,\"st\":1}}"}
{"receive_ns":1788563376280398000,"stream":"btcusdt@bookTicker","event_type":"bookTicker","event_time_ms":1788563376316,"raw_json":"{\"stream\":\"btcusdt@bookTicker\",\"data\":{\"e\":\"bookTicker\",\"u\":11478232517584,\"s\":\"BTCUSDT\",\"ps\":\"BTCUSDT\",\"b\":\"79607.10\",\"B\":\"4.097\",\"a\":\"79607.20\",\"A\":\"7.104\",\"T\":1788563376316,\"E\":1788563376316,\"st\":1}}"}
{"receive_ns":1788563376281257000,"stream":"btcusdt@bookTicker","event_type":"bookTicker","event_time_ms":1788563376318,"raw_json":"{\"stream\":\"btcusdt@bookTicker\",\"data\":{\"e\":\"bookTicker\",\"u\":11478232517689,\"s\":\"BTCUSDT\",\"ps\":\"BTCUSDT\",\"b\":\"79607.10\",\"B\":\"4.099\",\"a\":\"79607.20\",\"A\":\"7.104\",\"T\":1788563376318,\"E\":1788563376318,\"st\":1}}"}
{"receive_ns":1788563376282080000,"stream":"btcusdt@bookTicker","event_type":"bookTicker","event_time_ms":1788563376319,"raw_json":"{\"stream\":\"btcusdt@bookTicker\",\"data\":{\"e\":\"bookTicker\",\"u\":11478232517873,\"s\":\"BTCUSDT\",\"ps\":\"BTCUSDT\",\"b\":\"79607.10\",\"B\":\"5.376\",\"a\":\"79607.20\",\"A\":\"7.104\",\"T\":1788563376319,\"E\":1788563376319,\"st\":1}}"}
{"receive_ns":1788563376317033000,"stream":"btcusdt@depth@100ms","event_type":"depthUpdate","event_time_ms":1788563376353,"raw_json":"{\"stream\":\"btcusdt@depth@100ms\",\"data\":{\"e\":\"depthUpdate\",\"E\":1788563376353,\"T\":1788563376349,\"s\":\"BTCUSDT\",\"ps\":\"BTCUSDT\",\"U\":11478232514085,\"u\":11478232519012,\"pu\":11478232514006,\"b\":[[\"1000.00\",\"24.754\"],[\"29307.10\",\"0.021\"],[\"29407.10\",\"1.764\"],[\"29507.10\",\"0.315\"],[\"71646.30\",\"0.002\"],[\"78811.00\",\"15.338\"],[\"78920.30\",\"0.000\"],[\"79209.00\",\"0.000\"],[\"79491.70\",\"0.583\"],[\"79505.90\",\"0.208\"],[\"79521.80\",\"0.012\"],[\"79522.20\",\"1.877\"],[\"79524.20\",\"0.039\"],[\"79576.00\",\"0.021\"],[\"79583.20\",\"0.579\"],[\"79589.20\",\"0.395\"],[\"79595.10\",\"2.224\"],[\"79595.20\",\"0.249\"],[\"79595.70\",\"0.001\"],[\"79596.00\",\"0.007\"],[\"79597.10\",\"0.134\"],[\"79604.10\",\"1.000\"],[\"79604.20\",\"0.001\"],[\"79604.50\",\"0.026\"],[\"79607.00\",\"0.063\"],[\"79607.10\",\"5.376\"]],\"a\":[[\"79630.60\",\"1.886\"],[\"79963.40\",\"0.509\"],[\"79967.40\",\"0.199\"],[\"79999.30\",\"0.211\"],[\"80403.30\",\"22.286\"],[\"80715.00\",\"0.047\"],[\"83587.50\",\"0.022\"]],\"st\":1}}"}
{"receive_ns":1788563376330374000,"stream":"btcusdt@bookTicker","event_type":"bookTicker","event_time_ms":1788563376367,"raw_json":"{\"stream\":\"btcusdt@bookTicker\",\"data\":{\"e\":\"bookTicker\",\"u\":11478232519539,\"s\":\"BTCUSDT\",\"ps\":\"BTCUSDT\",\"b\":\"79607.10\",\"B\":\"5.414\",\"a\":\"79607.20\",\"A\":\"7.104\",\"T\":1788563376366,\"E\":1788563376367,\"st\":1}}"}
{"receive_ns":1788563376330661000,"stream":"btcusdt@bookTicker","event_type":"bookTicker","event_time_ms":1788563376368,"raw_json":"{\"stream\":\"btcusdt@bookTicker\",\"data\":{\"e\":\"bookTicker\",\"u\":11478232519618,\"s\":\"BTCUSDT\",\"ps\":\"BTCUSDT\",\"b\":\"79607.10\",\"B\":\"5.412\",\"a\":\"79607.20\",\"A\":\"7.104\",\"T\":1788563376368,\"E\":1788563376368,\"st\":1}}"}
{"receive_ns":1788563376331545000,"stream":"btcusdt@bookTicker","event_type":"bookTicker","event_time_ms":1788563376368,"raw_json":"{\"stream\":\"btcusdt@bookTicker\",\"data\":{\"e\":\"bookTicker\",\"u\":11478232519624,\"s\":\"BTCUSDT\",\"ps\":\"BTCUSDT\",\"b\":\"79607.10\",\"B\":\"5.413\",\"a\":\"79607.20\",\"A\":\"7.104\",\"T\":1788563376368,\"E\":1788563376368,\"st\":1}}"}
{"receive_ns":1788563376417415000,"stream":"btcusdt@depth@100ms","event_type":"depthUpdate","event_time_ms":1788563376455,"raw_json":"{\"stream\":\"btcusdt@depth@100ms\",\"data\":{\"e\":\"depthUpdate\",\"E\":1788563376455,\"T\":1788563376453,\"s\":\"BTCUSDT\",\"ps\":\"BTCUSDT\",\"U\":11478232519126,\"u\":11478232523105,\"pu\":11478232519012,\"b\":[[\"29307.10\",\"0.077\"],[\"29407.10\",\"1.834\"],[\"29507.10\",\"0.189\"],[\"63685.70\",\"0.001\"],[\"71646.30\",\"0.002\"],[\"76422.80\",\"0.000\"],[\"78015.00\",\"10.560\"],[\"78608.50\",\"12.293\"],[\"78727.60\",\"0.908\"],[\"78811.00\",\"15.338\"],[\"78890.50\",\"1.772\"],[\"79209.10\",\"3.967\"],[\"79232.90\",\"0.141\"],[\"79491.70\",\"0.483\"],[\"79573.90\",\"0.002\"],[\"79574.70\",\"0.003\"],[\"79575.90\",\"0.453\"],[\"79576.70\",\"0.354\"],[\"79579.90\",\"0.063\"],[\"79581.80\",\"3.312\"],[\"79582.90\",\"0.076\"],[\"79583.10\",\"0.006\"],[\"79583.20\",\"0.002\"],[\"79583.80\",\"0.001\"],[\"79588.30\",\"0.636\"],[\"79593.80\",\"0.502\"],[\"79604.00\",\"0.030\"],[\"79604.10\",\"1.026\"],[\"79604.50\",\"0.000\"],[\"79605.10\",\"0.000\"],[\"79606.80\",\"0.004\"],[\"79607.10\",\"5.413\"]],\"a\":[[\"79623.50\",\"0.001\"],[\"79624.50\",\"0.479\"],[\"79625.40\",\"0.000\"],[\"79625.50\",\"0.458\"],[\"79774.40\",\"2.505\"],[\"79963.40\",\"0.509\"],[\"79964.00\",\"0.001\"],[\"79995.80\",\"0.863\"],[\"79997.80\",\"0.525\"],[\"80005.30\",\"0.003\"],[\"80403.30\",\"22.286\"]],\"st\":1}}"}
{"receive_ns":1788563376485093000,"stream":"btcusdt@bookTicker","event_type":"bookTicker","event_time_ms":1788563376521,"raw_json":"{\"stream\":\"btcusdt@bookTicker\",\"data\":{\"e\":\"bookTicker\",\"u\":11478232526009,\"s\":\"BTCUSDT\",\"ps\":\"BTCUSDT\",\"b\":\"79607.10\",\"B\":\"4.825\",\"a\":\"79607.20\",\"A\":\"7.104\",\"T\":1788563376521,\"E\":1788563376521,\"st\":1}}"}
{"receive_ns":1788563376492006000,"stream":"btcusdt@bookTicker","event_type":"bookTicker","event_time_ms":1788563376522,"raw_json":"{\"stream\":\"btcusdt@bookTicker\",\"data\":{\"e\":\"bookTicker\",\"u\":11478232526094,\"s\":\"BTCUSDT\",\"ps\":\"BTCUSDT\",\"b\":\"79607.10\",\"B\":\"4.827\",\"a\":\"79607.20\",\"A\":\"7.104\",\"T\":1788563376522,\"E\":1788563376522,\"st\":1}}"}
{"receive_ns":1788563376492228000,"stream":"btcusdt@bookTicker","event_type":"bookTicker","event_time_ms":1788563376522,"raw_json":"{\"stream\":\"btcusdt@bookTicker\",\"data\":{\"e\":\"bookTicker\",\"u\":11478232526100,\"s\":\"BTCUSDT\",\"ps\":\"BTCUSDT\",\"b\":\"79607.10\",\"B\":\"4.826\",\"a\":\"79607.20\",\"A\":\"7.104\",\"T\":1788563376522,\"E\":1788563376522,\"st\":1}}"}
{"receive_ns":1788563376492414000,"stream":"btcusdt@bookTicker","event_type":"bookTicker","event_time_ms":1788563376522,"raw_json":"{\"stream\":\"btcusdt@bookTicker\",\"data\":{\"e\":\"bookTicker\",\"u\":11478232526111,\"s\":\"BTCUSDT\",\"ps\":\"BTCUSDT\",\"b\":\"79607.10\",\"B\":\"4.825\",\"a\":\"79607.20\",\"A\":\"7.104\",\"T\":1788563376522,\"E\":1788563376522,\"st\":1}}"}
{"receive_ns":1788563376492635000,"stream":"btcusdt@bookTicker","event_type":"bookTicker","event_time_ms":1788563376523,"raw_json":"{\"stream\":\"btcusdt@bookTicker\",\"data\":{\"e\":\"bookTicker\",\"u\":11478232526197,\"s\":\"BTCUSDT\",\"ps\":\"BTCUSDT\",\"b\":\"79607.10\",\"B\":\"4.826\",\"a\":\"79607.20\",\"A\":\"7.104\",\"T\":1788563376523,\"E\":1788563376523,\"st\":1}}"}
{"receive_ns":1788563376492882000,"stream":"btcusdt@bookTicker","event_type":"bookTicker","event_time_ms":1788563376523,"raw_json":"{\"stream\":\"btcusdt@bookTicker\",\"data\":{\"e\":\"bookTicker\",\"u\":11478232526217,\"s\":\"BTCUSDT\",\"ps\":\"BTCUSDT\",\"b\":\"79607.10\",\"B\":\"5.420\",\"a\":\"79607.20\",\"A\":\"7.104\",\"T\":1788563376523,\"E\":1788563376523,\"st\":1}}"}
{"receive_ns":1788563376520322000,"stream":"btcusdt@depth@100ms","event_type":"depthUpdate","event_time_ms":1788563376557,"raw_json":"{\"stream\":\"btcusdt@depth@100ms\",\"data\":{\"e\":\"depthUpdate\",\"E\":1788563376557,\"T\":1788563376555,\"s\":\"BTCUSDT\",\"ps\":\"BTCUSDT\",\"U\":11478232523187,\"u\":11478232527621,\"pu\":11478232523105,\"b\":[[\"1000.00\",\"24.754\"],[\"29307.10\",\"0.140\"],[\"29407.10\",\"1.883\"],[\"29507.10\",\"0.077\"],[\"63686.00\",\"0.010\"],[\"71646.30\",\"0.002\"],[\"75626.70\",\"0.028\"],[\"76422.80\",\"0.002\"],[\"78230.00\",\"0.151\"],[\"78572.20\",\"27.825\"],[\"78811.00\",\"15.338\"],[\"78929.80\",\"0.569\"],[\"79491.70\",\"0.483\"],[\"79574.70\",\"0.455\"],[\"79575.90\",\"0.001\"],[\"79579.90\",\"0.502\"],[\"79581.80\",\"2.873\"],[\"79582.90\",\"0.704\"],[\"79583.20\",\"0.579\"],[\"79588.30\",\"0.008\"],[\"79589.20\",\"0.395\"],[\"79602.60\",\"0.001\"],[\"79602.70\",\"0.002\"],[\"79602.80\",\"0.000\"],[\"79602.90\",\"0.002\"],[\"79604.20\",\"0.027\"],[\"79604.50\",\"0.026\"],[\"79604.70\",\"0.027\"],[\"79604.80\",\"0.028\"],[\"79606.90\",\"0.199\"],[\"79607.10\",\"5.420\"]],\"a\":[[\"79963.40\",\"0.509\"],[\"79967.40\",\"0.199\"],[\"79999.30\",\"0.211\"],[\"80403.30\",\"22.288\"],[\"80598.60\",\"14.718\"],[\"80777.40\",\"8.768\"]],\"st\":1}}"}
{"receive_ns":1788563376544890000,"stream":"btcusdt@bookTicker","event_type":"bookTicker","event_time_ms":1788563376583,"raw_json":"{\"stream\":\"btcusdt@bookTicker\",\"data\":{\"e\":\"bookTicker\",\"u\":11478232528571,\"s\":\"BTCUSDT\",\"ps\":\"BTCUSDT\",\"b\":\"79607.10\",\"B\":\"5.422\",\"a\":\"79607.20\",\"A\":\"7.104\",\"T\":1788563376583,\"E\":1788563376583,\"st\":1}}"}
{"receive_ns":1788563376547314000,"stream":"btcusdt@bookTicker","event_type":"bookTicker","event_time_ms":1788563376584,"raw_json":"{\"stream\":\"btcusdt@bookTicker\",\"data\":{\"e\":\"bookTicker\",\"u\":11478232528655,\"s\":\"BTCUSDT\",\"ps\":\"BTCUSDT\",\"b\":\"79607.10\",\"B\":\"5.423\",\"a\":\"79607.20\",\"A\":\"7.104\",\"T\":1788563376584,\"E\":1788563376584,\"st\":1}}"}
{"receive_ns":1788563376621808000,"stream":"btcusdt@depth@100ms","event_type":"depthUpdate","event_time_ms":1788563376659,"raw_json":"{\"stream\":\"btcusdt@depth@100ms\",\"data\":{\"e\":\"depthUpdate\",\"E\":1788563376659,\"T\":1788563376658,\"s\":\"BTCUSDT\",\"ps\":\"BTCUSDT\",\"U\":11478232527673,\"u\":11478232531662,\"pu\":11478232527621,\"b\":[[\"1000.00\",\"24.754\"],[\"29307.10\",\"0.245\"],[\"29407.10\",\"1.855\"],[\"29507.10\",\"0.000\"],[\"63686.00\",\"0.000\"],[\"71646.30\",\"0.002\"],[\"75626.80\",\"0.006\"],[\"76422.80\",\"0.000\"],[\"77378.10\",\"1.547\"],[\"78651.80\",\"50.255\"],[\"78811.00\",\"15.338\"],[\"79232.90\",\"0.000\"],[\"79491.70\",\"0.251\"],[\"79607.10\",\"5.423\"]],\"a\":[[\"79774.40\",\"2.003\"],[\"79963.40\",\"0.419\"],[\"79995.80\",\"0.100\"],[\"79997.80\",\"0.000\"],[\"80403.30\",\"22.286\"],[\"80713.70\",\"7.812\"]],\"st\":1}}"}
{"receive_ns":1788563376723188000,"stream":"btcusdt@depth@100ms","event_type":"depthUpdate","event_time_ms":1788563376761,"raw_json":"{\"stream\":\"btcusdt@depth@100ms\",\"data\":{\"e\":\"depthUpdate\",\"E\":1788563376761,\"T\":1788563376757,\"s\":\"BTCUSDT\",\"ps\":\"BTCUSDT\",\"U\":11478232531759,\"u\":11478232535734,\"pu\":11478232531662,\"b\":[[\"29307.10\",\"0.420\"],[\"29407.10\",\"1.680\"],[\"71646.30\",\"0.002\"],[\"71684.00\",\"0.000\"],[\"76422.80\",\"0.002\"],[\"78811.00\",\"15.338\"],[\"79209.10\",\"3.977\"],[\"79232.90\",\"0.141\"],[\"79491.70\",\"0.483\"],[\"79582.90\",\"0.076\"],[\"79583.20\",\"0.504\"],[\"79583.80\",\"0.001\"],[\"79588.30\",\"0.008\"],[\"79588.40\",\"0.632\"],[\"79589.20\",\"0.395\"]],\"a\":[[\"79642.40\",\"2.947\"],[\"79774.40\",\"2.505\"],[\"79828.60\",\"7.300\"],[\"79963.40\",\"0.509\"],[\"79964.00\",\"0.764\"],[\"79967.40\",\"0.199\"],[\"79997.80\",\"0.525\"],[\"79999.30\",\"0.167\"],[\"80244.10\",\"7.375\"],[\"80403.30\",\"22.286\"]],\"st\":1}}"}
{"receive_ns":1788563376799412000,"stream":"btcusdt@bookTicker","event_type":"bookTicker","event_time_ms":1788563376828,"raw_json":"{\"stream\":\"btcusdt@bookTicker\",\"data\":{\"e\":\"bookTicker\",\"u\":11478232538608,\"s\":\"BTCUSDT\",\"ps\":\"BTCUSDT\",\"b\":\"79607.10\",\"B\":\"5.423\",\"a\":\"79607.20\",\"A\":\"7.103\",\"T\":1788563376828,\"E\":1788563376828,\"st\":1}}"}
{"receive_ns":1788563376799648000,"stream":"btcusdt@bookTicker","event_type":"bookTicker","event_time_ms":1788563376830,"raw_json":"{\"stream\":\"btcusdt@bookTicker\",\"data\":{\"e\":\"bookTicker\",\"u\":11478232538709,\"s\":\"BTCUSDT\",\"ps\":\"BTCUSDT\",\"b\":\"79607.10\",\"B\":\"5.422\",\"a\":\"79607.20\",\"A\":\"7.103\",\"T\":1788563376829,\"E\":1788563376830,\"st\":1}}"}
{"receive_ns":1788563376799856000,"stream":"btcusdt@bookTicker","event_type":"bookTicker","event_time_ms":1788563376831,"raw_json":"{\"stream\":\"btcusdt@bookTicker\",\"data\":{\"e\":\"bookTicker\",\"u\":11478232538780,\"s\":\"BTCUSDT\",\"ps\":\"BTCUSDT\",\"b\":\"79607.10\",\"B\":\"5.423\",\"a\":\"79607.20\",\"A\":\"7.103\",\"T\":1788563376831,\"E\":1788563376831,\"st\":1}}"}
{"receive_ns":1788563376801547000,"stream":"btcusdt@bookTicker","event_type":"bookTicker","event_time_ms":1788563376838,"raw_json":"{\"stream\":\"btcusdt@bookTicker\",\"data\":{\"e\":\"bookTicker\",\"u\":11478232539058,\"s\":\"BTCUSDT\",\"ps\":\"BTCUSDT\",\"b\":\"79607.10\",\"B\":\"5.406\",\"a\":\"79607.20\",\"A\":\"7.103\",\"T\":1788563376838,\"E\":1788563376838,\"st\":1}}"}
{"receive_ns":1788563376803748000,"stream":"btcusdt@bookTicker","event_type":"bookTicker","event_time_ms":1788563376841,"raw_json":"{\"stream\":\"btcusdt@bookTicker\",\"data\":{\"e\":\"bookTicker\",\"u\":11478232539146,\"s\":\"BTCUSDT\",\"ps\":\"BTCUSDT\",\"b\":\"79607.10\",\"B\":\"5.422\",\"a\":\"79607.20\",\"A\":\"7.103\",\"T\":1788563376841,\"E\":1788563376841,\"st\":1}}"}
{"receive_ns":1788563376803982000,"stream":"btcusdt@bookTicker","event_type":"bookTicker","event_time_ms":1788563376842,"raw_json":"{\"stream\":\"btcusdt@bookTicker\",\"data\":{\"e\":\"bookTicker\",\"u\":11478232539194,\"s\":\"BTCUSDT\",\"ps\":\"BTCUSDT\",\"b\":\"79607.10\",\"B\":\"5.420\",\"a\":\"79607.20\",\"A\":\"7.103\",\"T\":1788563376842,\"E\":1788563376842,\"st\":1}}"}
{"receive_ns":1788563376825306000,"stream":"btcusdt@depth@100ms","event_type":"depthUpdate","event_time_ms":1788563376863,"raw_json":"{\"stream\":\"btcusdt@depth@100ms\",\"data\":{\"e\":\"depthUpdate\",\"E\":1788563376863,\"T\":1788563376862,\"s\":\"BTCUSDT\",\"ps\":\"BTCUSDT\",\"U\":11478232535938,\"u\":11478232539882,\"pu\":11478232535734,\"b\":[[\"1000.00\",\"24.754\"],[\"29307.10\",\"0.602\"],[\"29407.10\",\"1.498\"],[\"71646.30\",\"0.002\"],[\"78645.10\",\"0.001\"],[\"78651.80\",\"49.621\"],[\"78811.00\",\"15.338\"],[\"79395.60\",\"0.000\"],[\"79443.30\",\"0.000\"],[\"79443.60\",\"0.613\"],[\"79482.70\",\"0.017\"],[\"79583.20\",\"0.579\"],[\"79583.70\",\"0.644\"],[\"79588.40\",\"0.004\"],[\"79607.10\",\"5.420\"]],\"a\":[[\"79607.20\",\"7.103\"],[\"79635.70\",\"0.352\"],[\"79683.90\",\"0.085\"],[\"79728.70\",\"0.000\"],[\"79768.10\",\"0.000\"],[\"79812.00\",\"0.607\"],[\"79815.80\",\"0.000\"],[\"79999.30\",\"0.211\"],[\"80403.30\",\"22.286\"],[\"80939.80\",\"0.000\"],[\"81199.30\",\"10.762\"]],\"st\":1}}"}
{"receive_ns":1788563376928657000,"stream":"btcusdt@depth@100ms","event_type":"depthUpdate","event_time_ms":1788563376965,"raw_json":"{\"stream\":\"btcusdt@depth@100ms\",\"data\":{\"e\":\"depthUpdate\",\"E\":1788563376965,\"T\":1788563376964,\"s\":\"BTCUSDT\",\"ps\":\"BTCUSDT\",\"U\":11478232539942,\"u\":11478232543583,\"pu\":11478232539882,\"b\":[[\"1000.00\",\"24.754\"],[\"29307.10\",\"0.777\"],[\"29407.10\",\"1.323\"],[\"71646.30\",\"0.002\"],[\"75626.70\",\"0.030\"],[\"76422.80\",\"0.000\"],[\"78572.20\",\"28.016\"],[\"78811.00\",\"15.338\"],[\"78886.90\",\"3.987\"],[\"79232.90\",\"0.141\"],[\"79491.70\",\"0.232\"],[\"79515.70\",\"1.171\"],[\"79583.20\",\"0.177\"],[\"79583.80\",\"0.001\"],[\"79587.10\",\"0.000\"]],\"a\":[[\"79697.80\",\"0.001\"],[\"79774.40\",\"2.003\"],[\"79963.40\",\"0.502\"],[\"79964.00\",\"0.001\"],[\"79967.40\",\"0.289\"],[\"79987.90\",\"0.763\"],[\"79997.80\",\"0.525\"],[\"79999.30\",\"0.055\"],[\"80244.10\",\"7.624\"],[\"80403.30\",\"22.286\"]],\"st\":1}}"}
{"receive_ns":1788563377029843000,"stream":"btcusdt@depth@100ms","event_type":"depthUpdate","event_time_ms":1788563377067,"raw_json":"{\"stream\":\"btcusdt@depth@100ms\",\"data\":{\"e\":\"depthUpdate\",\"E\":1788563377067,\"T\":1788563377066,\"s\":\"BTCUSDT\",\"ps\":\"BTCUSDT\",\"U\":11478232543634,\"u\":11478232547690,\"pu\":11478232543583,\"b\":[[\"29307.10\",\"0.959\"],[\"29407.10\",\"1.141\"],[\"71646.30\",\"0.002\"],[\"76422.80\",\"0.002\"],[\"78572.20\",\"28.906\"],[\"78811.00\",\"15.338\"],[\"79209.10\",\"3.977\"],[\"79395.70\",\"5.020\"],[\"79443.40\",\"2.535\"],[\"79443.60\",\"0.926\"],[\"79482.80\",\"0.526\"],[\"79515.70\",\"5.817\"],[\"79575.00\",\"0.007\"],[\"79575.30\",\"0.325\"],[\"79579.90\",\"0.502\"],[\"79581.80\",\"2.873\"],[\"79583.20\",\"0.604\"],[\"79583.70\",\"0.016\"],[\"79583.80\",\"0.629\"],[\"79588.30\",\"0.008\"],[\"79589.20\",\"0.470\"],[\"79592.80\",\"0.004\"],[\"79593.90\",\"0.000\"],[\"79603.00\",\"0.003\"],[\"79603.90\",\"0.027\"],[\"79604.70\",\"0.001\"],[\"79604.80\",\"0.002\"],[\"79605.20\",\"0.002\"]],\"a\":[[\"79697.80\",\"4.073\"],[\"79728.70\",\"0.293\"],[\"79768.10\",\"1.325\"],[\"79812.00\",\"1.002\"],[\"79815.90\",\"3.091\"],[\"79961.60\",\"0.242\"],[\"79963.40\",\"0.921\"],[\"79967.40\",\"0.289\"],[\"79999.30\",\"0.211\"],[\"80403.30\",\"22.286\"],[\"80602.30\",\"9.756\"]],\"st\":1}}"}
{"receive_ns":1788563377056993000,"stream":"btcusdt@bookTicker","event_type":"bookTicker","event_time_ms":1788563377093,"raw_json":"{\"stream\":\"btcusdt@bookTicker\",\"data\":{\"e\":\"bookTicker\",\"u\":11478232549126,\"s\":\"BTCUSDT\",\"ps\":\"BTCUSDT\",\"b\":\"79607.10\",\"B\":\"4.896\",\"a\":\"79607.20\",\"A\":\"7.103\",\"T\":1788563377093,\"E\":1788563377093,\"st\":1}}"}
{"receive_ns":1788563377057228000,"stream":"btcusdt@bookTicker","event_type":"bookTicker","event_time_ms":1788563377095,"raw_json":"{\"stream\":\"btcusdt@bookTicker\",\"data\":{\"e\":\"bookTicker\",\"u\":11478232549230,\"s\":\"BTCUSDT\",\"ps\":\"BTCUSDT\",\"b\":\"79607.10\",\"B\":\"4.898\",\"a\":\"79607.20\",\"A\":\"7.103\",\"T\":1788563377094,\"E\":1788563377095,\"st\":1}}"}
{"receive_ns":1788563377057368000,"stream":"btcusdt@bookTicker","event_type":"bookTicker","event_time_ms":1788563377095,"raw_json":"{\"stream\":\"btcusdt@bookTicker\",\"data\":{\"e\":\"bookTicker\",\"u\":11478232549231,\"s\":\"BTCUSDT\",\"ps\":\"BTCUSDT\",\"b\":\"79607.10\",\"B\":\"4.897\",\"a\":\"79607.20\",\"A\":\"7.103\",\"T\":1788563377094,\"E\":1788563377095,\"st\":1}}"}
{"receive_ns":1788563377058075000,"stream":"btcusdt@bookTicker","event_type":"bookTicker","event_time_ms":1788563377096,"raw_json":"{\"stream\":\"btcusdt@bookTicker\",\"data\":{\"e\":\"bookTicker\",\"u\":11478232549322,\"s\":\"BTCUSDT\",\"ps\":\"BTCUSDT\",\"b\":\"79607.10\",\"B\":\"5.425\",\"a\":\"79607.20\",\"A\":\"7.103\",\"T\":1788563377096,\"E\":1788563377096,\"st\":1}}"}
{"receive_ns":1788563377078687000,"stream":"btcusdt@bookTicker","event_type":"bookTicker","event_time_ms":1788563377111,"raw_json":"{\"stream\":\"btcusdt@bookTicker\",\"data\":{\"e\":\"bookTicker\",\"u\":11478232550032,\"s\":\"BTCUSDT\",\"ps\":\"BTCUSDT\",\"b\":\"79607.10\",\"B\":\"4.989\",\"a\":\"79607.20\",\"A\":\"7.103\",\"T\":1788563377111,\"E\":1788563377111,\"st\":1}}"}
{"receive_ns":1788563377078960000,"stream":"btcusdt@bookTicker","event_type":"bookTicker","event_time_ms":1788563377112,"raw_json":"{\"stream\":\"btcusdt@bookTicker\",\"data\":{\"e\":\"bookTicker\",\"u\":11478232550122,\"s\":\"BTCUSDT\",\"ps\":\"BTCUSDT\",\"b\":\"79607.10\",\"B\":\"4.987\",\"a\":\"79607.20\",\"A\":\"7.103\",\"T\":1788563377112,\"E\":1788563377112,\"st\":1}}"}
{"receive_ns":1788563377079393000,"stream":"btcusdt@bookTicker","event_type":"bookTicker","event_time_ms":1788563377114,"raw_json":"{\"stream\":\"btcusdt@bookTicker\",\"data\":{\"e\":\"bookTicker\",\"u\":11478232550261,\"s\":\"BTCUSDT\",\"ps\":\"BTCUSDT\",\"b\":\"79607.10\",\"B\":\"5.428\",\"a\":\"79607.20\",\"A\":\"7.103\",\"T\":1788563377114,\"E\":1788563377114,\"st\":1}}"}
{"receive_ns":1788563377080181000,"stream":"btcusdt@bookTicker","event_type":"bookTicker","event_time_ms":1788563377115,"raw_json":"{\"stream\":\"btcusdt@bookTicker\",\"data\":{\"e\":\"bookTicker\",\"u\":11478232550309,\"s\":\"BTCUSDT\",\"ps\":\"BTCUSDT\",\"b\":\"79607.10\",\"B\":\"5.430\",\"a\":\"79607.20\",\"A\":\"7.103\",\"T\":1788563377115,\"E\":1788563377115,\"st\":1}}"}
{"receive_ns":1788563377137468000,"stream":"btcusdt@depth@100ms","event_type":"depthUpdate","event_time_ms":1788563377169,"raw_json":"{\"stream\":\"btcusdt@depth@100ms\",\"data\":{\"e\":\"depthUpdate\",\"E\":1788563377169,\"T\":1788563377166,\"s\":\"BTCUSDT\",\"ps\":\"BTCUSDT\",\"U\":11478232547779,\"u\":11478232552828,\"pu\":11478232547690,\"b\":[[\"1000.00\",\"24.754\"],[\"29307.10\",\"1.134\"],[\"29407.10\",\"0.966\"],[\"71646.30\",\"0.002\"],[\"76422.80\",\"0.000\"],[\"78394.60\",\"0.037\"],[\"78811.00\",\"15.338\"],[\"79232.90\",\"0.000\"],[\"79491.70\",\"0.000\"],[\"79575.30\",\"0.074\"],[\"79583.20\",\"0.504\"],[\"79606.70\",\"0.001\"],[\"79607.10\",\"5.430\"]],\"a\":[[\"79683.90\",\"0.011\"],[\"79963.40\",\"0.419\"],[\"79967.40\",\"0.199\"],[\"79987.90\",\"0.000\"],[\"79997.80\",\"0.000\"],[\"80319.90\",\"0.000\"],[\"80403.30\",\"22.286\"],[\"80819.60\",\"0.028\"],[\"87568.00\",\"0.000\"]],\"st\":1}}"}
{"receive_ns":1788563377161134000,"stream":"btcusdt@bookTicker","event_type":"bookTicker","event_time_ms":1788563377193,"raw_json":"{\"stream\":\"btcusdt@bookTicker\",\"data\":{\"e\":\"bookTicker\",\"u\":11478232553703,\"s\":\"BTCUSDT\",\"ps\":\"BTCUSDT\",\"b\":\"79607.10\",\"B\":\"5.428\",\"a\":\"79607.20\",\"A\":\"7.103\",\"T\":1788563377192,\"E\":1788563377193,\"st\":1}}"}
{"receive_ns":1788563377161388000,"stream":"btcusdt@trade","event_type":"trade","event_time_ms":1788563377193,"raw_json":"{\"stream\":\"btcusdt@trade\",\"data\":{\"e\":\"trade\",\"E\":1788563377193,\"T\":1788563377192,\"s\":\"BTCUSDT\",\"t\":8054083449,\"p\":\"79607.10\",\"q\":\"0.002\",\"X\":\"MARKET\",\"m\":true,\"st\":1}}"}
{"receive_ns":1788563377166170000,"stream":"btcusdt@bookTicker","event_type":"bookTicker","event_time_ms":1788563377203,"raw_json":"{\"stream\":\"btcusdt@bookTicker\",\"data\":{\"e\":\"bookTicker\",\"u\":11478232554299,\"s\":\"BTCUSDT\",\"ps\":\"BTCUSDT\",\"b\":\"79607.10\",\"B\":\"5.433\",\"a\":\"79607.20\",\"A\":\"7.103\",\"T\":1788563377203,\"E\":1788563377203,\"st\":1}}"}
{"receive_ns":1788563377190147000,"stream":"btcusdt@bookTicker","event_type":"bookTicker","event_time_ms":1788563377228,"raw_json":"{\"stream\":\"btcusdt@bookTicker\",\"data\":{\"e\":\"bookTicker\",\"u\":11478232555631,\"s\":\"BTCUSDT\",\"ps\":\"BTCUSDT\",\"b\":\"79607.10\",\"B\":\"5.436\",\"a\":\"79607.20\",\"A\":\"7.103\",\"T\":1788563377228,\"E\":1788563377228,\"st\":1}}"}
{"receive_ns":1788563377204168000,"stream":"btcusdt@bookTicker","event_type":"bookTicker","event_time_ms":1788563377240,"raw_json":"{\"stream\":\"btcusdt@bookTicker\",\"data\":{\"e\":\"bookTicker\",\"u\":11478232556208,\"s\":\"BTCUSDT\",\"ps\":\"BTCUSDT\",\"b\":\"79607.10\",\"B\":\"4.330\",\"a\":\"79607.20\",\"A\":\"7.103\",\"T\":1788563377240,\"E\":1788563377240,\"st\":1}}"}
{"receive_ns":1788563377218258000,"stream":"btcusdt@bookTicker","event_type":"bookTicker","event_time_ms":1788563377249,"raw_json":"{\"stream\":\"btcusdt@bookTicker\",\"data\":{\"e\":\"bookTicker\",\"u\":11478232556525,\"s\":\"BTCUSDT\",\"ps\":\"BTCUSDT\",\"b\":\"79607.10\",\"B\":\"5.483\",\"a\":\"79607.20\",\"A\":\"7.103\",\"T\":1788563377249,\"E\":1788563377249,\"st\":1}}"}
{"receive_ns":1788563377218513000,"stream":"btcusdt@bookTicker","event_type":"bookTicker","event_time_ms":1788563377250,"raw_json":"{\"stream\":\"btcusdt@bookTicker\",\"data\":{\"e\":\"bookTicker\",\"u\":11478232556581,\"s\":\"BTCUSDT\",\"ps\":\"BTCUSDT\",\"b\":\"79607.10\",\"B\":\"5.482\",\"a\":\"79607.20\",\"A\":\"7.103\",\"T\":1788563377250,\"E\":1788563377250,\"st\":1}}"}
{"receive_ns":1788563377218702000,"stream":"btcusdt@bookTicker","event_type":"bookTicker","event_time_ms":1788563377250,"raw_json":"{\"stream\":\"btcusdt@bookTicker\",\"data\":{\"e\":\"bookTicker\",\"u\":11478232556592,\"s\":\"BTCUSDT\",\"ps\":\"BTCUSDT\",\"b\":\"79607.10\",\"B\":\"5.483\",\"a\":\"79607.20\",\"A\":\"7.103\",\"T\":1788563377250,\"E\":1788563377250,\"st\":1}}"}
{"receive_ns":1788563377218904000,"stream":"btcusdt@bookTicker","event_type":"bookTicker","event_time_ms":1788563377251,"raw_json":"{\"stream\":\"btcusdt@bookTicker\",\"data\":{\"e\":\"bookTicker\",\"u\":11478232556599,\"s\":\"BTCUSDT\",\"ps\":\"BTCUSDT\",\"b\":\"79607.10\",\"B\":\"5.481\",\"a\":\"79607.20\",\"A\":\"7.103\",\"T\":1788563377250,\"E\":1788563377251,\"st\":1}}"}
{"receive_ns":1788563377219157000,"stream":"btcusdt@bookTicker","event_type":"bookTicker","event_time_ms":1788563377251,"raw_json":"{\"stream\":\"btcusdt@bookTicker\",\"data\":{\"e\":\"bookTicker\",\"u\":11478232556638,\"s\":\"BTCUSDT\",\"ps\":\"BTCUSDT\",\"b\":\"79607.10\",\"B\":\"5.482\",\"a\":\"79607.20\",\"A\":\"7.103\",\"T\":1788563377251,\"E\":1788563377251,\"st\":1}}"}
{"receive_ns":1788563377237735000,"stream":"btcusdt@depth@100ms","event_type":"depthUpdate","event_time_ms":1788563377271,"raw_json":"{\"stream\":\"btcusdt@depth@100ms\",\"data\":{\"e\":\"depthUpdate\",\"E\":1788563377271,\"T\":1788563377270,\"s\":\"BTCUSDT\",\"ps\":\"BTCUSDT\",\"U\":11478232552952,\"u\":11478232557305,\"pu\":11478232552828,\"b\":[[\"1000.00\",\"24.754\"],[\"29307.10\",\"1.316\"],[\"29407.10\",\"0.784\"],[\"71646.30\",\"0.002\"],[\"76856.10\",\"0.000\"],[\"78118.40\",\"5.299\"],[\"78532.40\",\"9.384\"],[\"78811.00\",\"14.071\"],[\"78886.80\",\"1.794\"],[\"79010.00\",\"3.680\"],[\"79137.60\",\"0.000\"],[\"79209.00\",\"0.001\"],[\"79232.90\",\"0.141\"],[\"79395.70\",\"5.039\"],[\"79420.90\",\"2.359\"],[\"79421.00\",\"3.140\"],[\"79482.80\",\"0.393\"],[\"79491.70\",\"0.232\"],[\"79511.50\",\"0.022\"],[\"79519.20\",\"3.741\"],[\"79519.30\",\"0.038\"],[\"79535.40\",\"0.002\"],[\"79582.90\",\"0.704\"],[\"79583.20\",\"0.604\"],[\"79583.40\",\"0.006\"],[\"79583.80\",\"0.001\"],[\"79584.80\",\"0.256\"],[\"79587.30\",\"0.456\"],[\"79587.90\",\"0.019\"],[\"79588.30\",\"0.008\"],[\"79588.40\",\"0.004\"],[\"79589.20\",\"0.470\"],[\"79592.40\",\"0.348\"],[\"79595.20\",\"0.249\"],[\"79596.00\",\"0.006\"],[\"79596.30\",\"0.033\"],[\"79602.60\",\"0.027\"],[\"79602.70\",\"0.028\"],[\"79602.80\",\"0.026\"],[\"79602.90\",\"0.028\"],[\"79603.00\",\"0.029\"],[\"79603.90\",\"0.001\"],[\"79604.00\",\"0.004\"],[\"79604.10\",\"1.000\"],[\"79604.20\",\"0.001\"],[\"79604.40\",\"0.026\"],[\"79604.50\",\"0.000\"],[\"79606.70\",\"0.000\"],[\"79607.10\",\"5.482\"]],\"a\":[[\"79623.30\",\"0.458\"],[\"79678.90\",\"0.015\"],[\"79694.50\",\"0.056\"],[\"79728.70\",\"0.169\"],[\"79735.30\",\"0.088\"],[\"79740.50\",\"0.364\"],[\"79742.90\",\"0.002\"],[\"79744.20\",\"1.038\"],[\"79746.60\",\"3.142\"],[\"79774.40\",\"2.254\"],[\"79961.60\",\"0.120\"],[\"79963.40\",\"0.760\"],[\"79967.40\",\"0.199\"],[\"79979.70\",\"0.000\"],[\"79995.80\",\"0.863\"],[\"79997.80\",\"0.525\"],[\"79999.30\",\"0.211\"],[\"80005.30\",\"0.002\"],[\"80403.30\",\"22.286\"],[\"80819.70\",\"0.008\"],[\"81199.30\",\"10.759\"]],\"st\":1}}"}
{"receive_ns":1788563377238082000,"stream":"btcusdt@bookTicker","event_type":"bookTicker","event_time_ms":1788563377271,"raw_json":"{\"stream\":\"btcusdt@bookTicker\",\"data\":{\"e\":\"bookTicker\",\"u\":11478232557330,\"s\":\"BTCUSDT\",\"ps\":\"BTCUSDT\",\"b\":\"79607.10\",\"B\":\"5.483\",\"a\":\"79607.20\",\"A\":\"7.103\",\"T\":1788563377271,\"E\":1788563377271,\"st\":1}}"}
{"receive_ns":1788563377238344000,"stream":"btcusdt@bookTicker","event_type":"bookTicker","event_time_ms":1788563377272,"raw_json":"{\"stream\":\"btcusdt@bookTicker\",\"data\":{\"e\":\"bookTicker\",\"u\":11478232557365,\"s\":\"BTCUSDT\",\"ps\":\"BTCUSDT\",\"b\":\"79607.10\",\"B\":\"5.482\",\"a\":\"79607.20\",\"A\":\"7.103\",\"T\":1788563377272,\"E\":1788563377272,\"st\":1}}"}
{"receive_ns":1788563377286415000,"stream":"btcusdt@bookTicker","event_type":"bookTicker","event_time_ms":1788563377323,"raw_json":"{\"stream\":\"btcusdt@bookTicker\",\"data\":{\"e\":\"bookTicker\",\"u\":11478232559268,\"s\":\"BTCUSDT\",\"ps\":\"BTCUSDT\",\"b\":\"79607.10\",\"B\":\"4.205\",\"a\":\"79607.20\",\"A\":\"7.103\",\"T\":1788563377323,\"E\":1788563377323,\"st\":1}}"}
{"receive_ns":1788563377286726000,"stream":"btcusdt@bookTicker","event_type":"bookTicker","event_time_ms":1788563377324,"raw_json":"{\"stream\":\"btcusdt@bookTicker\",\"data\":{\"e\":\"bookTicker\",\"u\":11478232559300,\"s\":\"BTCUSDT\",\"ps\":\"BTCUSDT\",\"b\":\"79607.10\",\"B\":\"4.207\",\"a\":\"79607.20\",\"A\":\"7.103\",\"T\":1788563377324,\"E\":1788563377324,\"st\":1}}"}
{"receive_ns":1788563377297290000,"stream":"btcusdt@bookTicker","event_type":"bookTicker","event_time_ms":1788563377325,"raw_json":"{\"stream\":\"btcusdt@bookTicker\",\"data\":{\"e\":\"bookTicker\",\"u\":11478232559386,\"s\":\"BTCUSDT\",\"ps\":\"BTCUSDT\",\"b\":\"79607.10\",\"B\":\"5.482\",\"a\":\"79607.20\",\"A\":\"7.103\",\"T\":1788563377325,\"E\":1788563377325,\"st\":1}}"}
{"receive_ns":1788563377338044000,"stream":"btcusdt@depth@100ms","event_type":"depthUpdate","event_time_ms":1788563377373,"raw_json":"{\"stream\":\"btcusdt@depth@100ms\",\"data\":{\"e\":\"depthUpdate\",\"E\":1788563377373,\"T\":1788563377371,\"s\":\"BTCUSDT\",\"ps\":\"BTCUSDT\",\"U\":11478232557330,\"u\":11478232561161,\"pu\":11478232557305,\"b\":[[\"29307.10\",\"1.491\"],[\"29407.10\",\"0.609\"],[\"71646.30\",\"0.002\"],[\"76422.80\",\"0.002\"],[\"78641.90\",\"1.274\"],[\"78811.00\",\"14.071\"],[\"78938.30\",\"0.030\"],[\"78970.20\",\"8.000\"],[\"79209.10\",\"3.967\"],[\"79431.50\",\"1.545\"],[\"79505.90\",\"0.208\"],[\"79521.80\",\"0.012\"],[\"79573.70\",\"3.885\"],[\"79574.70\",\"0.003\"],[\"79576.00\",\"0.019\"],[\"79579.90\",\"0.063\"],[\"79581.80\",\"3.312\"],[\"79583.20\",\"0.504\"],[\"79583.60\",\"1.320\"],[\"79586.60\",\"0.000\"],[\"79589.20\",\"0.395\"],[\"79592.70\",\"0.237\"],[\"79595.20\",\"0.249\"],[\"79596.00\",\"0.086\"],[\"79596.30\",\"0.033\"],[\"79602.60\",\"0.001\"],[\"79604.40\",\"0.000\"],[\"79604.50\",\"0.026\"],[\"79604.90\",\"0.026\"],[\"79605.40\",\"0.001\"],[\"79605.60\",\"0.025\"],[\"79606.40\",\"0.003\"],[\"79607.10\",\"5.482\"]],\"a\":[[\"79620.70\",\"0.684\"],[\"79622.10\",\"0.374\"],[\"79623.00\",\"0.000\"],[\"79623.10\",\"0.565\"],[\"79624.50\",\"0.931\"],[\"79625.50\",\"0.006\"],[\"80005.30\",\"0.001\"],[\"80403.30\",\"22.288\"]],\"st\":1}}"}
{"receive_ns":1788563377346000000,"stream":"btcusdt@bookTicker","event_type":"bookTicker","event_time_ms":1788563377382,"raw_json":"{\"stream\":\"btcusdt@bookTicker\",\"data\":{\"e\":\"bookTicker\",\"u\":11478232561538,\"s\":\"BTCUSDT\",\"ps\":\"BTCUSDT\",\"b\":\"79607.10\",\"B\":\"5.069\",\"a\":\"79607.20\",\"A\":\"7.103\",\"T\":1788563377382,\"E\":1788563377382,\"st\":1}}"}
{"receive_ns":1788563377346296000,"stream":"btcusdt@bookTicker","event_type":"bookTicker","event_time_ms":1788563377383,"raw_json":"{\"stream\":\"btcusdt@bookTicker\",\"data\":{\"e\":\"bookTicker\",\"u\":11478232561586,\"s\":\"BTCUSDT\",\"ps\":\"BTCUSDT\",\"b\":\"79607.10\",\"B\":\"5.067\",\"a\":\"79607.20\",\"A\":\"7.103\",\"T\":1788563377383,\"E\":1788563377383,\"st\":1}}"}
{"receive_ns":1788563377348737000,"stream":"btcusdt@bookTicker","event_type":"bookTicker","event_time_ms":1788563377385,"raw_json":"{\"stream\":\"btcusdt@bookTicker\",\"data\":{\"e\":\"bookTicker\",\"u\":11478232561669,\"s\":\"BTCUSDT\",\"ps\":\"BTCUSDT\",\"b\":\"79607.10\",\"B\":\"5.486\",\"a\":\"79607.20\",\"A\":\"7.103\",\"T\":1788563377385,\"E\":1788563377385,\"st\":1}}"}
{"receive_ns":1788563377349026000,"stream":"btcusdt@bookTicker","event_type":"bookTicker","event_time_ms":1788563377387,"raw_json":"{\"stream\":\"btcusdt@bookTicker\",\"data\":{\"e\":\"bookTicker\",\"u\":11478232561704,\"s\":\"BTCUSDT\",\"ps\":\"BTCUSDT\",\"b\":\"79607.10\",\"B\":\"5.488\",\"a\":\"79607.20\",\"A\":\"7.103\",\"T\":1788563377386,\"E\":1788563377387,\"st\":1}}"}
{"receive_ns":1788563377438465000,"stream":"btcusdt@depth@100ms","event_type":"depthUpdate","event_time_ms":1788563377475,"raw_json":"{\"stream\":\"btcusdt@depth@100ms\",\"data\":{\"e\":\"depthUpdate\",\"E\":1788563377475,\"T\":1788563377474,\"s\":\"BTCUSDT\",\"ps\":\"BTCUSDT\",\"U\":11478232561238,\"u\":11478232565041,\"pu\":11478232561161,\"b\":[[\"1000.00\",\"24.754\"],[\"29307.10\",\"1.673\"],[\"29407.10\",\"0.427\"],[\"63685.70\",\"0.001\"],[\"71646.30\",\"0.002\"],[\"76422.80\",\"0.000\"],[\"78476.70\",\"1.531\"],[\"78731.40\",\"8.309\"],[\"78811.00\",\"14.071\"],[\"78938.30\",\"0.060\"],[\"79010.00\",\"4.312\"],[\"79209.00\",\"0.002\"],[\"79232.90\",\"0.141\"],[\"79488.00\",\"1.035\"],[\"79491.70\",\"0.332\"],[\"79573.80\",\"0.073\"],[\"79574.10\",\"0.006\"],[\"79579.90\",\"0.508\"],[\"79581.80\",\"2.873\"],[\"79583.10\",\"0.000\"],[\"79583.20\",\"0.002\"],[\"79583.80\",\"0.001\"],[\"79584.80\",\"0.270\"],[\"79589.20\",\"0.195\"],[\"79592.70\",\"0.161\"],[\"79592.90\",\"0.076\"],[\"79603.40\",\"0.026\"],[\"79604.50\",\"0.000\"],[\"79604.60\",\"0.026\"],[\"79604.90\",\"0.000\"],[\"79606.90\",\"0.197\"],[\"79607.10\",\"5.488\"]],\"a\":[[\"79774.40\",\"2.505\"],[\"79963.40\",\"0.090\"],[\"79964.00\",\"0.764\"],[\"79967.40\",\"0.000\"],[\"79995.80\",\"0.100\"],[\"79997.80\",\"0.525\"],[\"79999.30\",\"0.055\"],[\"80403.30\",\"22.286\"],[\"80718.10\",\"26.538\"],[\"80920.70\",\"3.752\"],[\"81199.30\",\"10.762\"]],\"st\":1}}"}
{"receive_ns":1788563377466662000,"stream":"btcusdt@bookTicker","event_type":"bookTicker","event_time_ms":1788563377503,"raw_json":"{\"stream\":\"btcusdt@bookTicker\",\"data\":{\"e\":\"bookTicker\",\"u\":11478232566272,\"s\":\"BTCUSDT\",\"ps\":\"BTCUSDT\",\"b\":\"79607.10\",\"B\":\"5.488\",\"a\":\"79607.20\",\"A\":\"7.109\",\"T\":1788563377503,\"E\":1788563377503,\"st\":1}}"}
{"receive_ns":1788563377490414000,"stream":"btcusdt@bookTicker","event_type":"bookTicker","event_time_ms":1788563377526,"raw_json":"{\"stream\":\"btcusdt@bookTicker\",\"data\":{\"e\":\"bookTicker\",\"u\":11478232567310,\"s\":\"BTCUSDT\",\"ps\":\"BTCUSDT\",\"b\":\"79607.10\",\"B\":\"4.894\",\"a\":\"79607.20\",\"A\":\"7.109\",\"T\":1788563377526,\"E\":1788563377526,\"st\":1}}"}
{"receive_ns":1788563377491777000,"stream":"btcusdt@bookTicker","event_type":"bookTicker","event_time_ms":1788563377529,"raw_json":"{\"stream\":\"btcusdt@bookTicker\",\"data\":{\"e\":\"bookTicker\",\"u\":11478232567448,\"s\":\"BTCUSDT\",\"ps\":\"BTCUSDT\",\"b\":\"79607.10\",\"B\":\"5.491\",\"a\":\"79607.20\",\"A\":\"7.109\",\"T\":1788563377529,\"E\":1788563377529,\"st\":1}}"}
{"receive_ns":1788563377493179000,"stream":"btcusdt@bookTicker","event_type":"bookTicker","event_time_ms":1788563377530,"raw_json":"{\"stream\":\"btcusdt@bookTicker\",\"data\":{\"e\":\"bookTicker\",\"u\":11478232567479,\"s\":\"BTCUSDT\",\"ps\":\"BTCUSDT\",\"b\":\"79607.10\",\"B\":\"5.489\",\"a\":\"79607.20\",\"A\":\"7.109\",\"T\":1788563377530,\"E\":1788563377530,\"st\":1}}"}
{"receive_ns":1788563377541223000,"stream":"btcusdt@depth@100ms","event_type":"depthUpdate","event_time_ms":1788563377577,"raw_json":"{\"stream\":\"btcusdt@depth@100ms\",\"data\":{\"e\":\"depthUpdate\",\"E\":1788563377577,\"T\":1788563377573,\"s\":\"BTCUSDT\",\"ps\":\"BTCUSDT\",\"U\":11478232565105,\"u\":11478232569388,\"pu\":11478232565041,\"b\":[[\"1000.00\",\"24.754\"],[\"29207.10\",\"0.035\"],[\"29307.10\",\"1.778\"],[\"29407.10\",\"0.287\"],[\"71646.30\",\"0.002\"],[\"76422.80\",\"0.002\"],[\"78811.00\",\"14.071\"],[\"79491.70\",\"0.583\"],[\"79511.50\",\"0.024\"],[\"79583.20\",\"0.277\"],[\"79592.40\",\"0.424\"],[\"79592.90\",\"0.000\"],[\"79602.60\",\"0.027\"],[\"79602.90\",\"0.002\"],[\"79603.00\",\"0.003\"],[\"79603.10\",\"0.252\"],[\"79603.20\",\"0.029\"],[\"79603.40\",\"0.026\"],[\"79603.50\",\"0.030\"],[\"79603.60\",\"1.545\"],[\"79603.70\",\"0.011\"],[\"79604.10\",\"1.026\"],[\"79604.20\",\"0.001\"],[\"79604.60\",\"0.000\"],[\"79607.10\",\"5.489\"]],\"a\":[[\"79607.20\",\"7.109\"],[\"79630.50\",\"0.038\"],[\"79702.80\",\"0.031\"],[\"79963.40\",\"0.509\"],[\"79967.40\",\"0.199\"],[\"79999.30\",\"0.211\"],[\"80403.30\",\"22.286\"],[\"81275.30\",\"1.843\"]],\"st\":1}}"}
{"receive_ns":1788563377643257000,"stream":"btcusdt@depth@100ms","event_type":"depthUpdate","event_time_ms":1788563377679,"raw_json":"{\"stream\":\"btcusdt@depth@100ms\",\"data\":{\"e\":\"depthUpdate\",\"E\":1788563377679,\"T\":1788563377678,\"s\":\"BTCUSDT\",\"ps\":\"BTCUSDT\",\"U\":11478232569643,\"u\":11478232575429,\"pu\":11478232569388,\"b\":[[\"29207.10\",\"0.091\"],[\"29307.10\",\"1.848\"],[\"29407.10\",\"0.161\"],[\"63686.00\",\"0.000\"],[\"71646.30\",\"0.002\"],[\"75626.70\",\"0.028\"],[\"75626.80\",\"0.006\"],[\"76422.80\",\"0.000\"],[\"78015.00\",\"10.563\"],[\"78608.50\",\"12.102\"],[\"78811.00\",\"14.071\"],[\"79209.10\",\"3.977\"],[\"79232.90\",\"0.141\"],[\"79453.60\",\"0.001\"],[\"79454.50\",\"0.109\"],[\"79491.70\",\"0.483\"],[\"79579.90\",\"0.508\"],[\"79581.90\",\"0.061\"],[\"79583.20\",\"0.377\"],[\"79583.80\",\"2.009\"],[\"79587.30\",\"0.440\"],[\"79587.90\",\"0.003\"],[\"79592.20\",\"0.098\"],[\"79592.40\",\"0.348\"],[\"79602.20\",\"0.046\"],[\"79602.40\",\"0.280\"],[\"79602.50\",\"0.027\"],[\"79603.40\",\"0.000\"],[\"79603.50\",\"0.004\"],[\"79603.60\",\"1.519\"],[\"79604.10\",\"1.000\"]],\"a\":[[\"79622.10\",\"0.002\"],[\"79623.10\",\"0.937\"],[\"79666.90\",\"0.000\"],[\"79774.40\",\"2.003\"],[\"79963.40\",\"0.921\"],[\"79964.00\",\"0.001\"],[\"79967.40\",\"0.289\"],[\"79995.80\",\"0.863\"],[\"79997.80\",\"0.525\"],[\"80403.30\",\"22.286\"],[\"80479.00\",\"2.646\"],[\"80638.30\",\"0.000\"],[\"80724.90\",\"0.000\"],[\"80832.00\",\"2.597\"],[\"81199.30\",\"10.759\"]],\"st\":1}}"}
{"receive_ns":1788563377674112000,"stream":"btcusdt@bookTicker","event_type":"bookTicker","event_time_ms":1788563377711,"raw_json":"{\"stream\":\"btcusdt@bookTicker\",\"data\":{\"e\":\"bookTicker\",\"u\":11478232577248,\"s\":\"BTCUSDT\",\"ps\":\"BTCUSDT\",\"b\":\"79607.10\",\"B\":\"5.491\",\"a\":\"79607.20\",\"A\":\"7.109\",\"T\":1788563377711,\"E\":1788563377711,\"st\":1}}"}
{"receive_ns":1788563377698839000,"stream":"btcusdt@bookTicker","event_type":"bookTicker","event_time_ms":1788563377736,"raw_json":"{\"stream\":\"btcusdt@bookTicker\",\"data\":{\"e\":\"bookTicker\",\"u\":11478232578412,\"s\":\"BTCUSDT\",\"ps\":\"BTCUSDT\",\"b\":\"79607.10\",\"B\":\"5.491\",\"a\":\"79607.20\",\"A\":\"6.669\",\"T\":1788563377736,\"E\":1788563377736,\"st\":1}}"}
{"receive_ns":1788563377700070000,"stream":"btcusdt@bookTicker","event_type":"bookTicker","event_time_ms":1788563377738,"raw_json":"{\"stream\":\"btcusdt@bookTicker\",\"data\":{\"e\":\"bookTicker\",\"u\":11478232578468,\"s\":\"BTCUSDT\",\"ps\":\"BTCUSDT\",\"b\":\"79607.10\",\"B\":\"5.493\",\"a\":\"79607.20\",\"A\":\"6.669\",\"T\":1788563377737,\"E\":1788563377738,\"st\":1}}"}
{"receive_ns":1788563377720208000,"stream":"btcusdt@bookTicker","event_type":"bookTicker","event_time_ms":1788563377755,"raw_json":"{\"stream\":\"btcusdt@bookTicker\",\"data\":{\"e\":\"bookTicker\",\"u\":11478232579138,\"s\":\"BTCUSDT\",\"ps\":\"BTCUSDT\",\"b\":\"79607.10\",\"B\":\"5.493\",\"a\":\"79607.20\",\"A\":\"7.109\",\"T\":1788563377755,\"E\":1788563377755,\"st\":1}}"}
{"receive_ns":1788563377743245000,"stream":"btcusdt@depth@100ms","event_type":"depthUpdate","event_time_ms":1788563377781,"raw_json":"{\"stream\":\"btcusdt@depth@100ms\",\"data\":{\"e\":\"depthUpdate\",\"E\":1788563377781,\"T\":1788563377778,\"s\":\"BTCUSDT\",\"ps\":\"BTCUSDT\",\"U\":11478232575472,\"u\":11478232580038,\"pu\":11478232575429,\"b\":[[\"1000.00\",\"24.754\"],[\"29207.10\",\"0.154\"],[\"29307.10\",\"1.897\"],[\"29407.10\",\"0.049\"],[\"63686.00\",\"0.000\"],[\"71646.30\",\"0.002\"],[\"78612.00\",\"14.060\"],[\"78711.80\",\"0.000\"],[\"78811.00\",\"14.071\"],[\"79482.80\",\"0.000\"],[\"79491.70\",\"0.232\"],[\"79583.20\",\"0.930\"],[\"79583.80\",\"0.001\"],[\"79589.20\",\"0.395\"],[\"79590.00\",\"0.022\"],[\"79603.40\",\"0.026\"],[\"79603.70\",\"0.037\"],[\"79607.10\",\"5.493\"]],\"a\":[[\"79607.20\",\"7.109\"],[\"79610.70\",\"0.004\"],[\"79611.20\",\"0.250\"],[\"79630.60\",\"1.884\"],[\"79656.80\",\"0.452\"],[\"79728.70\",\"0.000\"],[\"79963.40\",\"0.921\"],[\"79967.40\",\"0.289\"],[\"79999.30\",\"0.211\"],[\"80005.20\",\"3.255\"],[\"80204.30\",\"3.735\"],[\"80403.30\",\"21.044\"],[\"80482.90\",\"19.357\"],[\"80841.10\",\"10.381\"]],\"st\":1}}"}
{"receive_ns":1788563377845699000,"stream":"btcusdt@depth@100ms","event_type":"depthUpdate","event_time_ms":1788563377883,"raw_json":"{\"stream\":\"btcusdt@depth@100ms\",\"data\":{\"e\":\"depthUpdate\",\"E\":1788563377883,\"T\":1788563377881,\"s\":\"BTCUSDT\",\"ps\":\"BTCUSDT\",\"U\":11478232580129,\"u\":11478232583717,\"pu\":11478232580038,\"b\":[[\"1000.00\",\"24.754\"],[\"29207.10\",\"0.287\"],[\"29307.10\",\"1.813\"],[\"29407.10\",\"0.000\"],[\"63686.00\",\"0.000\"],[\"71646.30\",\"0.002\"],[\"71684.00\",\"0.000\"],[\"76422.80\",\"0.002\"],[\"78811.00\",\"14.071\"],[\"79443.40\",\"0.029\"],[\"79443.60\",\"0.613\"],[\"79471.70\",\"0.042\"]],\"a\":[[\"79706.60\",\"0.301\"],[\"79706.70\",\"0.027\"],[\"79707.30\",\"0.002\"],[\"79742.60\",\"0.002\"],[\"79768.10\",\"0.000\"],[\"80403.30\",\"21.044\"],[\"80523.10\",\"1.476\"],[\"80602.30\",\"9.942\"]],\"st\":1}}"}
{"receive_ns":1788563377845970000,"stream":"btcusdt@bookTicker","event_type":"bookTicker","event_time_ms":1788563377883,"raw_json":"{\"stream\":\"btcusdt@bookTicker\",\"data\":{\"e\":\"bookTicker\",\"u\":11478232583773,\"s\":\"BTCUSDT\",\"ps\":\"BTCUSDT\",\"b\":\"79607.10\",\"B\":\"5.494\",\"a\":\"79607.20\",\"A\":\"7.109\",\"T\":1788563377882,\"E\":1788563377883,\"st\":1}}"}
{"receive_ns":1788563377948941000,"stream":"btcusdt@depth@100ms","event_type":"depthUpdate","event_time_ms":1788563377985,"raw_json":"{\"stream\":\"btcusdt@depth@100ms\",\"data\":{\"e\":\"depthUpdate\",\"E\":1788563377985,\"T\":1788563377984,\"s\":\"BTCUSDT\",\"ps\":\"BTCUSDT\",\"U\":11478232583773,\"u\":11478232587426,\"pu\":11478232583717,\"b\":[[\"29207.10\",\"0.462\"],[\"29307.10\",\"1.638\"],[\"63686.00\",\"0.000\"],[\"71646.30\",\"0.002\"],[\"76422.80\",\"0.000\"],[\"78811.00\",\"14.071\"],[\"78890.60\",\"34.212\"],[\"79209.10\",\"3.977\"],[\"79232.90\",\"0.141\"],[\"79395.70\",\"0.000\"],[\"79491.70\",\"0.232\"],[\"79579.90\",\"0.502\"],[\"79582.50\",\"0.008\"],[\"79583.20\",\"0.855\"],[\"79583.80\",\"0.001\"],[\"79589.20\",\"0.395\"],[\"79606.90\",\"0.199\"],[\"79607.10\",\"5.494\"]],\"a\":[[\"79706.90\",\"0.000\"],[\"79707.00\",\"0.728\"],[\"79707.10\",\"0.000\"],[\"79774.40\",\"2.254\"],[\"79815.90\",\"0.012\"],[\"79963.40\",\"0.869\"],[\"79967.40\",\"0.090\"],[\"79995.80\",\"0.863\"],[\"79997.80\",\"0.525\"],[\"79999.30\",\"0.167\"],[\"80005.20\",\"3.629\"],[\"80354.40\",\"0.000\"],[\"80403.30\",\"21.045\"],[\"80523.50\",\"8.928\"]],\"st\":1}}"}
{"receive_ns":1788563378050760000,"stream":"btcusdt@depth@100ms","event_type":"depthUpdate","event_time_ms":1788563378087,"raw_json":"{\"stream\":\"btcusdt@depth@100ms\",\"data\":{\"e\":\"depthUpdate\",\"E\":1788563378087,\"T\":1788563378086,\"s\":\"BTCUSDT\",\"ps\":\"BTCUSDT\",\"U\":11478232587451,\"u\":11478232590804,\"pu\":11478232587426,\"b\":[[\"1000.00\",\"24.754\"],[\"29207.10\",\"0.644\"],[\"29307.10\",\"1.456\"],[\"71646.30\",\"0.002\"],[\"76422.80\",\"0.002\"],[\"78612.00\",\"14.251\"],[\"78811.00\",\"14.071\"],[\"79395.70\",\"5.019\"],[\"79443.50\",\"2.515\"],[\"79443.60\",\"0.926\"],[\"79482.90\",\"0.526\"],[\"79575.90\",\"0.003\"],[\"79576.20\",\"0.003\"],[\"79583.20\",\"0.930\"],[\"79592.80\",\"0.004\"]],\"a\":[[\"79707.00\",\"0.603\"],[\"79707.40\",\"0.126\"],[\"79728.70\",\"0.293\"],[\"79768.10\",\"1.320\"],[\"79812.00\",\"0.999\"],[\"79815.90\",\"3.073\"],[\"79961.60\",\"0.235\"],[\"79995.30\",\"0.046\"],[\"80403.30\",\"21.045\"]],\"st\":1}}"}
{"receive_ns":1788563378086154000,"stream":"btcusdt@bookTicker","event_type":"bookTicker","event_time_ms":1788563378123,"raw_json":"{\"stream\":\"btcusdt@bookTicker\",\"data\":{\"e\":\"bookTicker\",\"u\":11478232592268,\"s\":\"BTCUSDT\",\"ps\":\"BTCUSDT\",\"b\":\"79607.10\",\"B\":\"5.075\",\"a\":\"79607.20\",\"A\":\"7.109\",\"T\":1788563378123,\"E\":1788563378123,\"st\":1}}"}
{"receive_ns":1788563378089685000,"stream":"btcusdt@bookTicker","event_type":"bookTicker","event_time_ms":1788563378126,"raw_json":"{\"stream\":\"btcusdt@bookTicker\",\"data\":{\"e\":\"bookTicker\",\"u\":11478232592447,\"s\":\"BTCUSDT\",\"ps\":\"BTCUSDT\",\"b\":\"79607.10\",\"B\":\"5.496\",\"a\":\"79607.20\",\"A\":\"7.109\",\"T\":1788563378126,\"E\":1788563378126,\"st\":1}}"}
{"receive_ns":1788563378089995000,"stream":"btcusdt@bookTicker","event_type":"bookTicker","event_time_ms":1788563378127,"raw_json":"{\"stream\":\"btcusdt@bookTicker\",\"data\":{\"e\":\"bookTicker\",\"u\":11478232592494,\"s\":\"BTCUSDT\",\"ps\":\"BTCUSDT\",\"b\":\"79607.10\",\"B\":\"5.494\",\"a\":\"79607.20\",\"A\":\"7.109\",\"T\":1788563378127,\"E\":1788563378127,\"st\":1}}"}
{"receive_ns":1788563378120973000,"stream":"btcusdt@bookTicker","event_type":"bookTicker","event_time_ms":1788563378154,"raw_json":"{\"stream\":\"btcusdt@bookTicker\",\"data\":{\"e\":\"bookTicker\",\"u\":11478232593417,\"s\":\"BTCUSDT\",\"ps\":\"BTCUSDT\",\"b\":\"79607.10\",\"B\":\"5.492\",\"a\":\"79607.20\",\"A\":\"7.109\",\"T\":1788563378154,\"E\":1788563378154,\"st\":1}}"}
{"receive_ns":1788563378121194000,"stream":"btcusdt@trade","event_type":"trade","event_time_ms":1788563378154,"raw_json":"{\"stream\":\"btcusdt@trade\",\"data\":{\"e\":\"trade\",\"E\":1788563378154,\"T\":1788563378154,\"s\":\"BTCUSDT\",\"t\":8054083450,\"p\":\"79607.10\",\"q\":\"0.002\",\"X\":\"MARKET\",\"m\":true,\"st\":1}}"}
{"receive_ns":1788563378121389000,"stream":"btcusdt@bookTicker","event_type":"bookTicker","event_time_ms":1788563378155,"raw_json":"{\"stream\":\"btcusdt@bookTicker\",\"data\":{\"e\":\"bookTicker\",\"u\":11478232593460,\"s\":\"BTCUSDT\",\"ps\":\"BTCUSDT\",\"b\":\"79607.10\",\"B\":\"5.051\",\"a\":\"79607.20\",\"A\":\"7.109\",\"T\":1788563378155,\"E\":1788563378155,\"st\":1}}"}
{"receive_ns":1788563378128445000,"stream":"btcusdt@bookTicker","event_type":"bookTicker","event_time_ms":1788563378157,"raw_json":"{\"stream\":\"btcusdt@bookTicker\",\"data\":{\"e\":\"bookTicker\",\"u\":11478232593561,\"s\":\"BTCUSDT\",\"ps\":\"BTCUSDT\",\"b\":\"79607.10\",\"B\":\"5.050\",\"a\":\"79607.20\",\"A\":\"7.109\",\"T\":1788563378156,\"E\":1788563378157,\"st\":1}}"}
{"receive_ns":1788563378128641000,"stream":"btcusdt@bookTicker","event_type":"bookTicker","event_time_ms":1788563378157,"raw_json":"{\"stream\":\"btcusdt@bookTicker\",\"data\":{\"e\":\"bookTicker\",\"u\":11478232593579,\"s\":\"BTCUSDT\",\"ps\":\"BTCUSDT\",\"b\":\"79607.10\",\"B\":\"5.052\",\"a\":\"79607.20\",\"A\":\"7.109\",\"T\":1788563378156,\"E\":1788563378157,\"st\":1}}"}
{"receive_ns":1788563378128827000,"stream":"btcusdt@bookTicker","event_type":"bookTicker","event_time_ms":1788563378158,"raw_json":"{\"stream\":\"btcusdt@bookTicker\",\"data\":{\"e\":\"bookTicker\",\"u\":11478232593660,\"s\":\"BTCUSDT\",\"ps\":\"BTCUSDT\",\"b\":\"79607.10\",\"B\":\"5.053\",\"a\":\"79607.20\",\"A\":\"7.109\",\"T\":1788563378158,\"E\":1788563378158,\"st\":1}}"}
{"receive_ns":1788563378129055000,"stream":"btcusdt@bookTicker","event_type":"bookTicker","event_time_ms":1788563378159,"raw_json":"{\"stream\":\"btcusdt@bookTicker\",\"data\":{\"e\":\"bookTicker\",\"u\":11478232593704,\"s\":\"BTCUSDT\",\"ps\":\"BTCUSDT\",\"b\":\"79607.10\",\"B\":\"5.505\",\"a\":\"79607.20\",\"A\":\"7.109\",\"T\":1788563378159,\"E\":1788563378159,\"st\":1}}"}
{"receive_ns":1788563378139220000,"stream":"btcusdt@bookTicker","event_type":"bookTicker","event_time_ms":1788563378168,"raw_json":"{\"stream\":\"btcusdt@bookTicker\",\"data\":{\"e\":\"bookTicker\",\"u\":11478232594307,\"s\":\"BTCUSDT\",\"ps\":\"BTCUSDT\",\"b\":\"79607.10\",\"B\":\"5.508\",\"a\":\"79607.20\",\"A\":\"7.109\",\"T\":1788563378168,\"E\":1788563378168,\"st\":1}}"}
{"receive_ns":1788563378152161000,"stream":"btcusdt@depth@100ms","event_type":"depthUpdate","event_time_ms":1788563378189,"raw_json":"{\"stream\":\"btcusdt@depth@100ms\",\"data\":{\"e\":\"depthUpdate\",\"E\":1788563378189,\"T\":1788563378187,\"s\":\"BTCUSDT\",\"ps\":\"BTCUSDT\",\"U\":11478232590866,\"u\":11478232595143,\"pu\":11478232590804,\"b\":[[\"1000.00\",\"24.754\"],[\"29207.10\",\"0.819\"],[\"29307.10\",\"1.281\"],[\"63686.00\",\"0.000\"],[\"71646.30\",\"0.002\"],[\"75626.70\",\"0.026\"],[\"75626.80\",\"0.008\"],[\"76422.80\",\"0.000\"],[\"78438.10\",\"0.000\"],[\"78731.40\",\"8.499\"],[\"78811.00\",\"14.071\"],[\"78886.90\",\"3.797\"],[\"79232.90\",\"0.141\"],[\"79482.90\",\"0.526\"],[\"79491.70\",\"0.332\"],[\"79579.90\",\"0.063\"],[\"79581.90\",\"0.500\"],[\"79583.20\",\"0.077\"],[\"79583.70\",\"0.017\"],[\"79583.80\",\"0.001\"],[\"79590.30\",\"0.127\"],[\"79590.60\",\"0.314\"],[\"79593.60\",\"0.007\"],[\"79593.70\",\"0.077\"],[\"79595.70\",\"0.001\"],[\"79596.00\",\"0.006\"],[\"79596.30\",\"0.033\"],[\"79602.20\",\"0.020\"],[\"79602.40\",\"0.254\"],[\"79603.80\",\"0.029\"],[\"79604.20\",\"0.027\"],[\"79604.30\",\"0.000\"],[\"79606.30\",\"0.066\"],[\"79607.00\",\"0.099\"],[\"79607.10\",\"5.508\"]],\"a\":[[\"79728.70\",\"0.293\"],[\"79774.40\",\"2.505\"],[\"79963.40\",\"0.289\"],[\"79964.00\",\"0.764\"],[\"79967.40\",\"0.000\"],[\"79995.80\",\"0.100\"],[\"79997.80\",\"0.525\"],[\"79999.30\",\"0.011\"],[\"80403.30\",\"19.803\"],[\"80602.30\",\"10.220\"]],\"st\":1}}"}
{"receive_ns":1788563378177085000,"stream":"btcusdt@bookTicker","event_type":"bookTicker","event_time_ms":1788563378213,"raw_json":"{\"stream\":\"btcusdt@bookTicker\",\"data\":{\"e\":\"bookTicker\",\"u\":11478232596036,\"s\":\"BTCUSDT\",\"ps\":\"BTCUSDT\",\"b\":\"79607.10\",\"B\":\"4.980\",\"a\":\"79607.20\",\"A\":\"7.109\",\"T\":1788563378213,\"E\":1788563378213,\"st\":1}}"}
{"receive_ns":1788563378177328000,"stream":"btcusdt@bookTicker","event_type":"bookTicker","event_time_ms":1788563378214,"raw_json":"{\"stream\":\"btcusdt@bookTicker\",\"data\":{\"e\":\"bookTicker\",\"u\":11478232596088,\"s\":\"BTCUSDT\",\"ps\":\"BTCUSDT\",\"b\":\"79607.10\",\"B\":\"4.978\",\"a\":\"79607.20\",\"A\":\"7.109\",\"T\":1788563378214,\"E\":1788563378214,\"st\":1}}"}
{"receive_ns":1788563378179248000,"stream":"btcusdt@bookTicker","event_type":"bookTicker","event_time_ms":1788563378216,"raw_json":"{\"stream\":\"btcusdt@bookTicker\",\"data\":{\"e\":\"bookTicker\",\"u\":11478232596169,\"s\":\"BTCUSDT\",\"ps\":\"BTCUSDT\",\"b\":\"79607.10\",\"B\":\"5.509\",\"a\":\"79607.20\",\"A\":\"7.109\",\"T\":1788563378215,\"E\":1788563378216,\"st\":1}}"}
{"receive_ns":1788563378179534000,"stream":"btcusdt@bookTicker","event_type":"bookTicker","event_time_ms":1788563378217,"raw_json":"{\"stream\":\"btcusdt@bookTicker\",\"data\":{\"e\":\"bookTicker\",\"u\":11478232596223,\"s\":\"BTCUSDT\",\"ps\":\"BTCUSDT\",\"b\":\"79607.10\",\"B\":\"5.511\",\"a\":\"79607.20\",\"A\":\"7.109\",\"T\":1788563378217,\"E\":1788563378217,\"st\":1}}"}
{"receive_ns":1788563378262523000,"stream":"btcusdt@depth@100ms","event_type":"depthUpdate","event_time_ms":1788563378291,"raw_json":"{\"stream\":\"btcusdt@depth@100ms\",\"data\":{\"e\":\"depthUpdate\",\"E\":1788563378291,\"T\":1788563378289,\"s\":\"BTCUSDT\",\"ps\":\"BTCUSDT\",\"U\":11478232595222,\"u\":11478232599121,\"pu\":11478232595143,\"b\":[[\"29207.10\",\"1.001\"],[\"29307.10\",\"1.099\"],[\"71646.30\",\"0.002\"],[\"78243.90\",\"1.276\"],[\"78648.30\",\"21.712\"],[\"78811.00\",\"14.071\"],[\"79209.00\",\"0.001\"],[\"79209.10\",\"3.977\"],[\"79491.70\",\"1.085\"],[\"79573.70\",\"3.433\"],[\"79574.90\",\"0.474\"],[\"79576.10\",\"0.533\"],[\"79579.90\",\"0.502\"],[\"79581.10\",\"0.000\"],[\"79581.90\",\"0.061\"],[\"79582.10\",\"0.418\"],[\"79583.20\",\"0.277\"],[\"79583.30\",\"0.199\"],[\"79583.40\",\"0.004\"],[\"79583.70\",\"0.016\"],[\"79589.20\",\"0.195\"],[\"79590.60\",\"0.331\"],[\"79592.20\",\"0.022\"],[\"79592.30\",\"0.077\"],[\"79593.70\",\"0.001\"],[\"79595.70\",\"0.001\"],[\"79596.30\",\"0.033\"],[\"79602.10\",\"0.156\"],[\"79602.20\",\"0.046\"],[\"79602.40\",\"0.280\"],[\"79602.70\",\"0.028\"],[\"79602.80\",\"0.026\"],[\"79602.90\",\"0.028\"],[\"79603.00\",\"0.003\"],[\"79603.10\",\"0.226\"],[\"79603.20\",\"0.003\"],[\"79603.30\",\"0.599\"],[\"79603.40\",\"0.000\"],[\"79603.50\",\"0.030\"],[\"79603.70\",\"0.037\"],[\"79603.80\",\"0.003\"],[\"79604.20\",\"0.001\"],[\"79607.00\",\"0.063\"],[\"79607.10\",\"5.511\"]],\"a\":[[\"79623.30\",\"0.456\"],[\"79624.50\",\"0.479\"],[\"79625.50\",\"0.458\"],[\"79963.40\",\"0.708\"],[\"79995.30\",\"0.002\"],[\"79999.30\",\"0.211\"],[\"80001.60\",\"0.749\"],[\"80363.50\",\"11.800\"],[\"80403.30\",\"19.803\"],[\"80598.60\",\"14.532\"],[\"81199.30\",\"10.762\"]],\"st\":1}}"}
{"receive_ns":1788563378355445000,"stream":"btcusdt@depth@100ms","event_type":"depthUpdate","event_time_ms":1788563378393,"raw_json":"{\"stream\":\"btcusdt@depth@100ms\",\"data\":{\"e\":\"depthUpdate\",\"E\":1788563378393,\"T\":1788563378392,\"s\":\"BTCUSDT\",\"ps\":\"BTCUSDT\",\"U\":11478232599340,\"u\":11478232604241,\"pu\":11478232599121,\"b\":[[\"1000.00\",\"24.754\"],[\"29207.10\",\"1.176\"],[\"29307.10\",\"0.924\"],[\"63686.00\",\"0.000\"],[\"71646.30\",\"0.002\"],[\"76422.80\",\"0.002\"],[\"78651.80\",\"50.762\"],[\"78811.00\",\"14.071\"],[\"78938.30\",\"0.100\"],[\"79209.00\",\"0.000\"],[\"79232.90\",\"0.000\"],[\"79491.70\",\"0.753\"],[\"79583.40\",\"0.006\"],[\"79602.10\",\"0.130\"],[\"79603.90\",\"0.027\"]],\"a\":[[\"79623.30\",\"0.458\"],[\"79774.40\",\"2.003\"],[\"79963.40\",\"0.618\"],[\"79964.00\",\"0.001\"],[\"79997.80\",\"0.000\"],[\"80005.30\",\"0.003\"],[\"80403.30\",\"18.561\"],[\"80562.50\",\"47.052\"]],\"st\":1}}"}
{"receive_ns":1788563378384143000,"stream":"btcusdt@bookTicker","event_type":"bookTicker","event_time_ms":1788563378413,"raw_json":"{\"stream\":\"btcusdt@bookTicker\",\"data\":{\"e\":\"bookTicker\",\"u\":11478232605217,\"s\":\"BTCUSDT\",\"ps\":\"BTCUSDT\",\"b\":\"79607.10\",\"B\":\"5.512\",\"a\":\"79607.20\",\"A\":\"7.109\",\"T\":1788563378413,\"E\":1788563378413,\"st\":1}}"}
{"receive_ns":1788563378384377000,"stream":"btcusdt@bookTicker","event_type":"bookTicker","event_time_ms":1788563378416,"raw_json":"{\"stream\":\"btcusdt@bookTicker\",\"data\":{\"e\":\"bookTicker\",\"u\":11478232605408,\"s\":\"BTCUSDT\",\"ps\":\"BTCUSDT\",\"b\":\"79607.10\",\"B\":\"5.524\",\"a\":\"79607.20\",\"A\":\"7.109\",\"T\":1788563378416,\"E\":1788563378416,\"st\":1}}"}
{"receive_ns":1788563378384518000,"stream":"btcusdt@bookTicker","event_type":"bookTicker","event_time_ms":1788563378416,"raw_json":"{\"stream\":\"btcusdt@bookTicker\",\"data\":{\"e\":\"bookTicker\",\"u\":11478232605409,\"s\":\"BTCUSDT\",\"ps\":\"BTCUSDT\",\"b\":\"79607.10\",\"B\":\"5.536\",\"a\":\"79607.20\",\"A\":\"7.109\",\"T\":1788563378416,\"E\":1788563378416,\"st\":1}}"}
{"receive_ns":1788563378384643000,"stream":"btcusdt@bookTicker","event_type":"bookTicker","event_time_ms":1788563378416,"raw_json":"{\"stream\":\"btcusdt@bookTicker\",\"data\":{\"e\":\"bookTicker\",\"u\":11478232605415,\"s\":\"BTCUSDT\",\"ps\":\"BTCUSDT\",\"b\":\"79607.10\",\"B\":\"5.548\",\"a\":\"79607.20\",\"A\":\"7.109\",\"T\":1788563378416,\"E\":1788563378416,\"st\":1}}"}
{"receive_ns":1788563378458105000,"stream":"btcusdt@depth@100ms","event_type":"depthUpdate","event_time_ms":1788563378495,"raw_json":"{\"stream\":\"btcusdt@depth@100ms\",\"data\":{\"e\":\"depthUpdate\",\"E\":1788563378495,\"T\":1788563378493,\"s\":\"BTCUSDT\",\"ps\":\"BTCUSDT\",\"U\":11478232604311,\"u\":11478232608383,\"pu\":11478232604241,\"b\":[[\"1000.00\",\"24.754\"],[\"29207.10\",\"1.358\"],[\"29307.10\",\"0.742\"],[\"63685.70\",\"0.001\"],[\"71646.30\",\"0.002\"],[\"76422.80\",\"0.000\"],[\"78436.90\",\"7.235\"],[\"78811.00\",\"14.071\"],[\"78928.70\",\"0.126\"],[\"79030.30\",\"0.000\"],[\"79232.90\",\"0.141\"],[\"79463.00\",\"0.000\"],[\"79471.70\",\"0.040\"],[\"79482.90\",\"0.000\"],[\"79491.70\",\"0.483\"],[\"79493.70\",\"0.731\"],[\"79511.50\",\"0.022\"],[\"79533.70\",\"0.829\"],[\"79535.40\",\"0.002\"],[\"79549.60\",\"0.691\"],[\"79580.60\",\"0.006\"],[\"79582.50\",\"0.002\"],[\"79583.20\",\"0.704\"],[\"79583.80\",\"0.001\"],[\"79587.20\",\"0.012\"],[\"79602.10\",\"0.156\"],[\"79603.50\",\"0.004\"],[\"79603.70\",\"0.037\"],[\"79603.90\",\"0.001\"],[\"79607.10\",\"5.548\"]],\"a\":[[\"79678.90\",\"0.015\"],[\"79708.10\",\"1.072\"],[\"79728.70\",\"0.000\"],[\"79742.60\",\"0.000\"],[\"79774.40\",\"2.505\"],[\"79961.60\",\"0.120\"],[\"79963.40\",\"0.509\"],[\"79967.40\",\"0.199\"],[\"79995.80\",\"0.863\"],[\"79997.80\",\"0.525\"],[\"79999.30\",\"0.167\"],[\"80202.00\",\"0.003\"],[\"80403.30\",\"18.561\"],[\"80555.60\",\"2.974\"],[\"80562.50\",\"47.671\"]],\"st\":1}}"}
{"receive_ns":1788563378559390000,"stream":"btcusdt@depth@100ms","event_type":"depthUpdate","event_time_ms":1788563378597,"raw_json":"{\"stream\":\"btcusdt@depth@100ms\",\"data\":{\"e\":\"depthUpdate\",\"E\":1788563378597,\"T\":1788563378594,\"s\":\"BTCUSDT\",\"ps\":\"BTCUSDT\",\"U\":11478232608456,\"u\":11478232612411,\"pu\":11478232608383,\"b\":[[\"29207.10\",\"1.533\"],[\"29307.10\",\"0.567\"],[\"63686.00\",\"0.002\"],[\"71646.30\",\"0.002\"],[\"76422.80\",\"0.002\"],[\"78015.00\",\"10.560\"],[\"78603.10\",\"0.658\"],[\"78651.80\",\"52.666\"],[\"78811.00\",\"14.071\"],[\"79209.10\",\"3.977\"],[\"79583.20\",\"0.779\"]],\"a\":[[\"79999.30\",\"0.211\"],[\"80403.30\",\"18.561\"]],\"st\":1}}"}
{"receive_ns":1788563378664456000,"stream":"btcusdt@bookTicker","event_type":"bookTicker","event_time_ms":1788563378696,"raw_json":"{\"stream\":\"btcusdt@bookTicker\",\"data\":{\"e\":\"bookTicker\",\"u\":11478232616304,\"s\":\"BTCUSDT\",\"ps\":\"BTCUSDT\",\"b\":\"79607.10\",\"B\":\"5.548\",\"a\":\"79607.20\",\"A\":\"7.107\",\"T\":1788563378696,\"E\":1788563378696,\"st\":1}}"}
{"receive_ns":1788563378671999000,"stream":"btcusdt@depth@100ms","event_type":"depthUpdate","event_time_ms":1788563378699,"raw_json":"{\"stream\":\"btcusdt@depth@100ms\",\"data\":{\"e\":\"depthUpdate\",\"E\":1788563378699,\"T\":1788563378698,\"s\":\"BTCUSDT\",\"ps\":\"BTCUSDT\",\"U\":11478232612491,\"u\":11478232616401,\"pu\":11478232612411,\"b\":[[\"1000.00\",\"24.754\"],[\"29207.10\",\"1.715\"],[\"29307.10\",\"0.385\"],[\"63686.00\",\"0.000\"],[\"71646.30\",\"0.002\"],[\"75626.70\",\"0.028\"],[\"78811.00\",\"14.073\"],[\"78890.60\",\"35.288\"],[\"79232.90\",\"0.141\"],[\"79395.70\",\"0.000\"],[\"79443.50\",\"0.009\"],[\"79443.60\",\"0.613\"],[\"79491.70\",\"0.332\"],[\"79493.70\",\"0.631\"],[\"79583.20\",\"0.077\"],[\"79583.80\",\"1.005\"],[\"79590.00\",\"0.005\"],[\"79591.00\",\"0.344\"],[\"79594.10\",\"0.000\"],[\"79595.10\",\"2.225\"]],\"a\":[[\"79607.20\",\"7.107\"],[\"79668.00\",\"0.004\"],[\"79768.10\",\"0.000\"],[\"79774.40\",\"2.505\"],[\"79812.00\",\"0.607\"],[\"79815.90\",\"0.012\"],[\"79963.40\",\"0.000\"],[\"79967.40\",\"0.090\"],[\"79987.90\",\"0.763\"],[\"79995.80\",\"0.100\"],[\"79997.80\",\"0.525\"],[\"79999.30\",\"0.055\"],[\"80320.20\",\"1.243\"],[\"80403.30\",\"18.561\"],[\"80523.10\",\"0.738\"],[\"80734.00\",\"0.888\"],[\"80944.60\",\"2.465\"],[\"87567.90\",\"0.002\"]],\"st\":1}}"}
{"receive_ns":1788563378711245000,"stream":"btcusdt@bookTicker","event_type":"bookTicker","event_time_ms":1788563378748,"raw_json":"{\"stream\":\"btcusdt@bookTicker\",\"data\":{\"e\":\"bookTicker\",\"u\":11478232618117,\"s\":\"BTCUSDT\",\"ps\":\"BTCUSDT\",\"b\":\"79607.10\",\"B\":\"5.548\",\"a\":\"79607.20\",\"A\":\"6.667\",\"T\":1788563378748,\"E\":1788563378748,\"st\":1}}"}
{"receive_ns":1788563378765378000,"stream":"btcusdt@depth@100ms","event_type":"depthUpdate","event_time_ms":1788563378801,"raw_json":"{\"stream\":\"btcusdt@depth@100ms\",\"data\":{\"e\":\"depthUpdate\",\"E\":1788563378801,\"T\":1788563378797,\"s\":\"BTCUSDT\",\"ps\":\"BTCUSDT\",\"U\":11478232616419,\"u\":11478232619629,\"pu\":11478232616401,\"b\":[[\"1000.00\",\"24.754\"],[\"29107.10\",\"0.049\"],[\"29207.10\",\"1.792\"],[\"29307.10\",\"0.259\"],[\"71646.30\",\"0.002\"],[\"76422.80\",\"0.000\"],[\"78528.30\",\"1.557\"],[\"78612.00\",\"14.886\"],[\"78811.00\",\"14.071\"],[\"79209.10\",\"3.599\"],[\"79395.70\",\"5.019\"],[\"79443.50\",\"2.515\"],[\"79482.90\",\"0.526\"],[\"79491.70\",\"0.583\"],[\"79559.30\",\"0.144\"],[\"79566.50\",\"0.001\"],[\"79573.90\",\"0.454\"],[\"79574.90\",\"0.022\"],[\"79579.90\",\"0.063\"],[\"79581.00\",\"0.374\"],[\"79581.80\",\"3.312\"],[\"79582.10\",\"0.045\"],[\"79583.20\",\"0.077\"],[\"79583.80\",\"0.001\"],[\"79585.20\",\"0.580\"],[\"79589.20\",\"0.395\"],[\"79593.40\",\"0.002\"],[\"79594.20\",\"0.001\"],[\"79594.90\",\"0.240\"],[\"79599.10\",\"0.020\"],[\"79602.10\",\"0.130\"],[\"79603.90\",\"0.001\"],[\"79604.50\",\"0.000\"]],\"a\":[[\"79607.20\",\"6.667\"],[\"79728.70\",\"0.294\"],[\"79768.10\",\"1.329\"],[\"79815.90\",\"3.087\"],[\"79963.40\",\"0.618\"],[\"79995.30\",\"0.046\"],[\"79999.30\",\"0.167\"],[\"80320.10\",\"9.108\"],[\"80403.30\",\"18.561\"],[\"80734.00\",\"0.740\"],[\"87567.90\",\"0.000\"]],\"st\":1}}"}
{"receive_ns":1788563378779501000,"stream":"btcusdt@bookTicker","event_type":"bookTicker","event_time_ms":1788563378817,"raw_json":"{\"stream\":\"btcusdt@bookTicker\",\"data\":{\"e\":\"bookTicker\",\"u\":11478232620447,\"s\":\"BTCUSDT\",\"ps\":\"BTCUSDT\",\"b\":\"79607.10\",\"B\":\"5.548\",\"a\":\"79607.20\",\"A\":\"6.669\",\"T\":1788563378817,\"E\":1788563378817,\"st\":1}}"}
{"receive_ns":1788563378783167000,"stream":"btcusdt@bookTicker","event_type":"bookTicker","event_time_ms":1788563378818,"raw_json":"{\"stream\":\"btcusdt@bookTicker\",\"data\":{\"e\":\"bookTicker\",\"u\":11478232620494,\"s\":\"BTCUSDT\",\"ps\":\"BTCUSDT\",\"b\":\"79607.10\",\"B\":\"5.548\",\"a\":\"79607.20\",\"A\":\"6.671\",\"T\":1788563378818,\"E\":1788563378818,\"st\":1}}"}
{"receive_ns":1788563378783550000,"stream":"btcusdt@bookTicker","event_type":"bookTicker","event_time_ms":1788563378820,"raw_json":"{\"stream\":\"btcusdt@bookTicker\",\"data\":{\"e\":\"bookTicker\",\"u\":11478232620528,\"s\":\"BTCUSDT\",\"ps\":\"BTCUSDT\",\"b\":\"79607.10\",\"B\":\"5.536\",\"a\":\"79607.20\",\"A\":\"6.671\",\"T\":1788563378820,\"E\":1788563378820,\"st\":1}}"}
{"receive_ns":1788563378783772000,"stream":"btcusdt@bookTicker","event_type":"bookTicker","event_time_ms":1788563378820,"raw_json":"{\"stream\":\"btcusdt@bookTicker\",\"data\":{\"e\":\"bookTicker\",\"u\":11478232620532,\"s\":\"BTCUSDT\",\"ps\":\"BTCUSDT\",\"b\":\"79607.10\",\"B\":\"5.524\",\"a\":\"79607.20\",\"A\":\"6.671\",\"T\":1788563378820,\"E\":1788563378820,\"st\":1}}"}
{"receive_ns":1788563378783917000,"stream":"btcusdt@bookTicker","event_type":"bookTicker","event_time_ms":1788563378820,"raw_json":"{\"stream\":\"btcusdt@bookTicker\",\"data\":{\"e\":\"bookTicker\",\"u\":11478232620535,\"s\":\"BTCUSDT\",\"ps\":\"BTCUSDT\",\"b\":\"79607.10\",\"B\":\"5.512\",\"a\":\"79607.20\",\"A\":\"6.671\",\"T\":1788563378820,\"E\":1788563378820,\"st\":1}}"}
{"receive_ns":1788563378866233000,"stream":"btcusdt@depth@100ms","event_type":"depthUpdate","event_time_ms":1788563378903,"raw_json":"{\"stream\":\"btcusdt@depth@100ms\",\"data\":{\"e\":\"depthUpdate\",\"E\":1788563378903,\"T\":1788563378900,\"s\":\"BTCUSDT\",\"ps\":\"BTCUSDT\",\"U\":11478232619804,\"u\":11478232625141,\"pu\":11478232619629,\"b\":[[\"29107.10\",\"0.105\"],[\"29207.10\",\"1.855\"],[\"29307.10\",\"0.140\"],[\"63686.00\",\"0.002\"],[\"71646.30\",\"0.002\"],[\"76422.80\",\"0.002\"],[\"78811.00\",\"14.071\"],[\"79209.10\",\"3.589\"],[\"79232.90\",\"0.000\"],[\"79491.70\",\"0.251\"],[\"79563.30\",\"0.001\"],[\"79579.90\",\"0.502\"],[\"79581.80\",\"2.873\"],[\"79590.30\",\"0.112\"],[\"79591.20\",\"1.248\"],[\"79601.90\",\"0.000\"],[\"79602.00\",\"0.029\"],[\"79602.10\",\"0.156\"],[\"79602.80\",\"0.000\"],[\"79602.90\",\"0.002\"],[\"79603.50\",\"0.030\"],[\"79603.60\",\"1.545\"],[\"79603.70\",\"0.037\"],[\"79607.10\",\"5.512\"]],\"a\":[[\"79607.20\",\"6.671\"],[\"79657.20\",\"0.080\"],[\"79774.40\",\"2.003\"],[\"79967.40\",\"0.000\"],[\"79987.90\",\"0.000\"],[\"79997.80\",\"0.000\"],[\"80323.80\",\"0.871\"],[\"80403.30\",\"18.560\"],[\"80523.50\",\"9.672\"],[\"80734.00\",\"0.592\"]],\"st\":1}}"}
{"receive_ns":1788563378882751000,"stream":"btcusdt@bookTicker","event_type":"bookTicker","event_time_ms":1788563378919,"raw_json":"{\"stream\":\"btcusdt@bookTicker\",\"data\":{\"e\":\"bookTicker\",\"u\":11478232625913,\"s\":\"BTCUSDT\",\"ps\":\"BTCUSDT\",\"b\":\"79607.10\",\"B\":\"4.915\",\"a\":\"79607.20\",\"A\":\"6.671\",\"T\":1788563378918,\"E\":1788563378919,\"st\":1}}"}
{"receive_ns":1788563378885485000,"stream":"btcusdt@bookTicker","event_type":"bookTicker","event_time_ms":1788563378922,"raw_json":"{\"stream\":\"btcusdt@bookTicker\",\"data\":{\"e\":\"bookTicker\",\"u\":11478232626128,\"s\":\"BTCUSDT\",\"ps\":\"BTCUSDT\",\"b\":\"79607.10\",\"B\":\"5.517\",\"a\":\"79607.20\",\"A\":\"6.671\",\"T\":1788563378921,\"E\":1788563378922,\"st\":1}}"}
{"receive_ns":1788563378885710000,"stream":"btcusdt@bookTicker","event_type":"bookTicker","event_time_ms":1788563378923,"raw_json":"{\"stream\":\"btcusdt@bookTicker\",\"data\":{\"e\":\"bookTicker\",\"u\":11478232626177,\"s\":\"BTCUSDT\",\"ps\":\"BTCUSDT\",\"b\":\"79607.10\",\"B\":\"5.515\",\"a\":\"79607.20\",\"A\":\"6.671\",\"T\":1788563378922,\"E\":1788563378923,\"st\":1}}"}
{"receive_ns":1788563378931324000,"stream":"btcusdt@bookTicker","event_type":"bookTicker","event_time_ms":1788563378968,"raw_json":"{\"stream\":\"btcusdt@bookTicker\",\"data\":{\"e\":\"bookTicker\",\"u\":11478232628259,\"s\":\"BTCUSDT\",\"ps\":\"BTCUSDT\",\"b\":\"79607.10\",\"B\":\"5.518\",\"a\":\"79607.20\",\"A\":\"6.671\",\"T\":1788563378967,\"E\":1788563378968,\"st\":1}}"}
{"receive_ns":1788563378933488000,"stream":"btcusdt@bookTicker","event_type":"bookTicker","event_time_ms":1788563378971,"raw_json":"{\"stream\":\"btcusdt@bookTicker\",\"data\":{\"e\":\"bookTicker\",\"u\":11478232628414,\"s\":\"BTCUSDT\",\"ps\":\"BTCUSDT\",\"b\":\"79607.10\",\"B\":\"5.518\",\"a\":\"79607.20\",\"A\":\"6.474\",\"T\":1788563378971,\"E\":1788563378971,\"st\":1}}"}
{"receive_ns":1788563378968096000,"stream":"btcusdt@depth@100ms","event_type":"depthUpdate","event_time_ms":1788563379005,"raw_json":"{\"stream\":\"btcusdt@depth@100ms\",\"data\":{\"e\":\"depthUpdate\",\"E\":1788563379005,\"T\":1788563379004,\"s\":\"BTCUSDT\",\"ps\":\"BTCUSDT\",\"U\":11478232625263,\"u\":11478232630139,\"pu\":11478232625141,\"b\":[[\"1000.00\",\"24.904\"],[\"29107.10\",\"0.168\"],[\"29207.10\",\"1.911\"],[\"29307.10\",\"0.021\"],[\"63686.00\",\"0.000\"],[\"71646.30\",\"0.002\"],[\"71684.00\",\"0.000\"],[\"76422.80\",\"0.000\"],[\"78811.00\",\"15.338\"],[\"78890.60\",\"36.174\"],[\"79010.00\",\"4.944\"],[\"79209.10\",\"3.967\"],[\"79232.90\",\"0.141\"],[\"79491.70\",\"0.483\"],[\"79533.70\",\"0.000\"],[\"79549.60\",\"0.000\"],[\"79573.30\",\"0.712\"],[\"79583.20\",\"0.679\"],[\"79583.80\",\"0.001\"],[\"79585.20\",\"0.078\"],[\"79589.20\",\"0.395\"],[\"79591.20\",\"1.231\"],[\"79595.70\",\"0.001\"],[\"79596.30\",\"0.033\"],[\"79602.00\",\"0.003\"],[\"79602.10\",\"0.130\"],[\"79602.20\",\"0.020\"],[\"79604.60\",\"0.026\"],[\"79604.80\",\"0.028\"],[\"79605.00\",\"0.656\"],[\"79606.50\",\"0.036\"],[\"79606.90\",\"0.197\"],[\"79607.10\",\"5.518\"]],\"a\":[[\"79607.20\",\"6.474\"],[\"79774.40\",\"2.254\"],[\"79963.40\",\"0.869\"],[\"79967.40\",\"0.090\"],[\"79995.30\",\"0.046\"],[\"79995.80\",\"0.863\"],[\"79997.80\",\"0.525\"],[\"79999.30\",\"0.167\"],[\"80403.30\",\"18.560\"],[\"81199.30\",\"10.765\"],[\"83587.50\",\"0.025\"]],\"st\":1}}"}
{"receive_ns":1788563379069861000,"stream":"btcusdt@depth@100ms","event_type":"depthUpdate","event_time_ms":1788563379107,"raw_json":"{\"stream\":\"btcusdt@depth@100ms\",\"data\":{\"e\":\"depthUpdate\",\"E\":1788563379107,\"T\":1788563379105,\"s\":\"BTCUSDT\",\"ps\":\"BTCUSDT\",\"U\":11478232630199,\"u\":11478232635568,\"pu\":11478232630139,\"b\":[[\"1000.00\",\"24.754\"],[\"29107.10\",\"0.329\"],[\"29207.10\",\"1.771\"],[\"29307.10\",\"0.000\"],[\"63686.00\",\"0.000\"],[\"71646.30\",\"0.002\"],[\"76422.80\",\"0.002\"],[\"78811.00\",\"15.338\"],[\"79209.10\",\"3.967\"],[\"79443.60\",\"0.926\"],[\"79470.00\",\"0.633\"],[\"79572.70\",\"1.065\"],[\"79592.80\",\"0.004\"],[\"79595.60\",\"0.078\"],[\"79599.20\",\"0.005\"]],\"a\":[[\"79812.00\",\"1.001\"],[\"79961.60\",\"0.235\"],[\"80403.30\",\"18.560\"],[\"81279.00\",\"0.246\"]],\"st\":1}}"}
{"receive_ns":1788563379093692000,"stream":"btcusdt@bookTicker","event_type":"bookTicker","event_time_ms":1788563379130,"raw_json":"{\"stream\":\"btcusdt@bookTicker\",\"data\":{\"e\":\"bookTicker\",\"u\":11478232636549,\"s\":\"BTCUSDT\",\"ps\":\"BTCUSDT\",\"b\":\"79607.10\",\"B\":\"4.987\",\"a\":\"79607.20\",\"A\":\"6.474\",\"T\":1788563379130,\"E\":1788563379130,\"st\":1}}"}
{"receive_ns":1788563379093956000,"stream":"btcusdt@bookTicker","event_type":"bookTicker","event_time_ms":1788563379131,"raw_json":"{\"stream\":\"btcusdt@bookTicker\",\"data\":{\"e\":\"bookTicker\",\"u\":11478232636570,\"s\":\"BTCUSDT\",\"ps\":\"BTCUSDT\",\"b\":\"79607.10\",\"B\":\"4.989\",\"a\":\"79607.20\",\"A\":\"6.474\",\"T\":1788563379131,\"E\":1788563379131,\"st\":1}}"}
{"receive_ns":1788563379096058000,"stream":"btcusdt@bookTicker","event_type":"bookTicker","event_time_ms":1788563379133,"raw_json":"{\"stream\":\"btcusdt@bookTicker\",\"data\":{\"e\":\"bookTicker\",\"u\":11478232636701,\"s\":\"BTCUSDT\",\"ps\":\"BTCUSDT\",\"b\":\"79607.10\",\"B\":\"5.522\",\"a\":\"79607.20\",\"A\":\"6.474\",\"T\":1788563379133,\"E\":1788563379133,\"st\":1}}"}
{"receive_ns":1788563379135592000,"stream":"btcusdt@bookTicker","event_type":"bookTicker","event_time_ms":1788563379172,"raw_json":"{\"stream\":\"btcusdt@bookTicker\",\"data\":{\"e\":\"bookTicker\",\"u\":11478232638089,\"s\":\"BTCUSDT\",\"ps\":\"BTCUSDT\",\"b\":\"79607.10\",\"B\":\"5.522\",\"a\":\"79607.20\",\"A\":\"6.462\",\"T\":1788563379171,\"E\":1788563379172,\"st\":1}}"}
{"receive_ns":1788563379135861000,"stream":"btcusdt@trade","event_type":"trade","event_time_ms":1788563379172,"raw_json":"{\"stream\":\"btcusdt@trade\",\"data\":{\"e\":\"trade\",\"E\":1788563379172,\"T\":1788563379171,\"s\":\"BTCUSDT\",\"t\":8054083451,\"p\":\"79607.20\",\"q\":\"0.012\",\"X\":\"MARKET\",\"m\":false,\"st\":1}}"}
{"receive_ns":1788563379172194000,"stream":"btcusdt@depth@100ms","event_type":"depthUpdate","event_time_ms":1788563379209,"raw_json":"{\"stream\":\"btcusdt@depth@100ms\",\"data\":{\"e\":\"depthUpdate\",\"E\":1788563379209,\"T\":1788563379208,\"s\":\"BTCUSDT\",\"ps\":\"BTCUSDT\",\"U\":11478232635643,\"u\":11478232639499,\"pu\":11478232635568,\"b\":[[\"29107.10\",\"0.504\"],[\"29207.10\",\"1.596\"],[\"71646.30\",\"0.002\"],[\"78568.50\",\"6.866\"],[\"78811.00\",\"15.338\"],[\"78870.70\",\"0.000\"],[\"79209.10\",\"3.969\"],[\"79232.90\",\"0.141\"],[\"79461.20\",\"0.000\"],[\"79461.30\",\"1.884\"],[\"79491.70\",\"0.232\"],[\"79583.20\",\"0.177\"],[\"79583.80\",\"0.001\"],[\"79589.20\",\"0.697\"],[\"79594.10\",\"0.076\"],[\"79599.20\",\"0.003\"],[\"79599.30\",\"0.004\"],[\"79602.40\",\"0.254\"],[\"79605.60\",\"0.051\"],[\"79607.10\",\"5.522\"]],\"a\":[[\"79607.20\",\"6.462\"],[\"79609.00\",\"0.003\"],[\"79609.70\",\"0.000\"],[\"79630.20\",\"0.235\"],[\"79630.90\",\"0.640\"],[\"79729.60\",\"0.016\"],[\"79729.70\",\"4.220\"],[\"79774.40\",\"2.505\"],[\"79961.60\",\"0.120\"],[\"79963.40\",\"0.618\"],[\"79967.40\",\"0.090\"],[\"79995.80\",\"0.863\"],[\"79997.80\",\"0.525\"],[\"79999.30\",\"0.011\"],[\"80403.30\",\"18.560\"]],\"st\":1}}"}
{"receive_ns":1788563379220253000,"stream":"btcusdt@bookTicker","event_type":"bookTicker","event_time_ms":1788563379256,"raw_json":"{\"stream\":\"btcusdt@bookTicker\",\"data\":{\"e\":\"bookTicker\",\"u\":11478232641708,\"s\":\"BTCUSDT\",\"ps\":\"BTCUSDT\",\"b\":\"79607.10\",\"B\":\"4.369\",\"a\":\"79607.20\",\"A\":\"6.462\",\"T\":1788563379256,\"E\":1788563379256,\"st\":1}}"}
{"receive_ns":1788563379221101000,"stream":"btcusdt@bookTicker","event_type":"bookTicker","event_time_ms":1788563379257,"raw_json":"{\"stream\":\"btcusdt@bookTicker\",\"data\":{\"e\":\"bookTicker\",\"u\":11478232641751,\"s\":\"BTCUSDT\",\"ps\":\"BTCUSDT\",\"b\":\"79607.10\",\"B\":\"4.367\",\"a\":\"79607.20\",\"A\":\"6.462\",\"T\":1788563379257,\"E\":1788563379257,\"st\":1}}"}
{"receive_ns":1788563379229198000,"stream":"btcusdt@bookTicker","event_type":"bookTicker","event_time_ms":1788563379265,"raw_json":"{\"stream\":\"btcusdt@bookTicker\",\"data\":{\"e\":\"bookTicker\",\"u\":11478232642373,\"s\":\"BTCUSDT\",\"ps\":\"BTCUSDT\",\"b\":\"79607.10\",\"B\":\"5.525\",\"a\":\"79607.20\",\"A\":\"6.462\",\"T\":1788563379265,\"E\":1788563379265,\"st\":1}}"}
{"receive_ns":1788563379229581000,"stream":"btcusdt@bookTicker","event_type":"bookTicker","event_time_ms":1788563379267,"raw_json":"{\"stream\":\"btcusdt@bookTicker\",\"data\":{\"e\":\"bookTicker\",\"u\":11478232642486,\"s\":\"BTCUSDT\",\"ps\":\"BTCUSDT\",\"b\":\"79607.10\",\"B\":\"5.527\",\"a\":\"79607.20\",\"A\":\"6.462\",\"T\":1788563379266,\"E\":1788563379267,\"st\":1}}"}
{"receive_ns":1788563379229753000,"stream":"btcusdt@bookTicker","event_type":"bookTicker","event_time_ms":1788563379267,"raw_json":"{\"stream\":\"btcusdt@bookTicker\",\"data\":{\"e\":\"bookTicker\",\"u\":11478232642488,\"s\":\"BTCUSDT\",\"ps\":\"BTCUSDT\",\"b\":\"79607.10\",\"B\":\"5.526\",\"a\":\"79607.20\",\"A\":\"6.462\",\"T\":1788563379266,\"E\":1788563379267,\"st\":1}}"}
{"receive_ns":1788563379231414000,"stream":"btcusdt@bookTicker","event_type":"bookTicker","event_time_ms":1788563379268,"raw_json":"{\"stream\":\"btcusdt@bookTicker\",\"data\":{\"e\":\"bookTicker\",\"u\":11478232642641,\"s\":\"BTCUSDT\",\"ps\":\"BTCUSDT\",\"b\":\"79607.10\",\"B\":\"5.527\",\"a\":\"79607.20\",\"A\":\"6.462\",\"T\":1788563379267,\"E\":1788563379268,\"st\":1}}"}
{"receive_ns":1788563379273598000,"stream":"btcusdt@depth@100ms","event_type":"depthUpdate","event_time_ms":1788563379311,"raw_json":"{\"stream\":\"btcusdt@depth@100ms\",\"data\":{\"e\":\"depthUpdate\",\"E\":1788563379311,\"T\":1788563379310,\"s\":\"BTCUSDT\",\"ps\":\"BTCUSDT\",\"U\":11478232639529,\"u\":11478232644229,\"pu\":11478232639499,\"b\":[[\"1000.00\",\"24.754\"],[\"29107.10\",\"0.686\"],[\"29207.10\",\"1.414\"],[\"71646.30\",\"0.002\"],[\"76422.80\",\"0.000\"],[\"78011.40\",\"5.071\"],[\"78604.00\",\"0.032\"],[\"78811.00\",\"15.338\"],[\"78841.90\",\"0.000\"],[\"79209.10\",\"3.967\"],[\"79482.90\",\"0.526\"],[\"79583.20\",\"0.177\"],[\"79583.40\",\"0.004\"],[\"79589.20\",\"0.395\"],[\"79593.90\",\"0.076\"],[\"79594.10\",\"0.000\"],[\"79595.20\",\"0.350\"],[\"79596.30\",\"0.033\"],[\"79597.10\",\"0.033\"],[\"79598.00\",\"0.004\"],[\"79599.30\",\"0.004\"],[\"79603.40\",\"0.026\"],[\"79604.80\",\"0.002\"],[\"79605.00\",\"0.630\"],[\"79605.60\",\"0.025\"],[\"79607.10\",\"5.527\"]],\"a\":[[\"79608.20\",\"0.029\"],[\"79623.30\",\"0.456\"],[\"79728.70\",\"0.294\"],[\"79995.30\",\"0.046\"],[\"79999.30\",\"0.167\"],[\"80403.30\",\"18.560\"],[\"80517.80\",\"0.258\"],[\"80721.70\",\"58.404\"],[\"83492.00\",\"0.020\"]],\"st\":1}}"}
{"receive_ns":1788563379278649000,"stream":"btcusdt@bookTicker","event_type":"bookTicker","event_time_ms":1788563379317,"raw_json":"{\"stream\":\"btcusdt@bookTicker\",\"data\":{\"e\":\"bookTicker\",\"u\":11478232644509,\"s\":\"BTCUSDT\",\"ps\":\"BTCUSDT\",\"b\":\"79607.10\",\"B\":\"5.531\",\"a\":\"79607.20\",\"A\":\"6.462\",\"T\":1788563379317,\"E\":1788563379317,\"st\":1}}"}
{"receive_ns":1788563379378150000,"stream":"btcusdt@depth@100ms","event_type":"depthUpdate","event_time_ms":1788563379413,"raw_json":"{\"stream\":\"btcusdt@depth@100ms\",\"data\":{\"e\":\"depthUpdate\",\"E\":1788563379413,\"T\":1788563379410,\"s\":\"BTCUSDT\",\"ps\":\"BTCUSDT\",\"U\":11478232644297,\"u\":11478232647738,\"pu\":11478232644229,\"b\":[[\"29107.10\",\"0.861\"],[\"29207.10\",\"1.239\"],[\"71646.30\",\"0.002\"],[\"76422.80\",\"0.002\"],[\"78612.00\",\"15.077\"],[\"78811.00\",\"15.338\"],[\"78886.80\",\"0.908\"],[\"79209.10\",\"3.977\"],[\"79232.90\",\"0.000\"],[\"79491.70\",\"0.000\"],[\"79573.90\",\"0.002\"],[\"79575.00\",\"0.459\"],[\"79575.20\",\"0.947\"],[\"79579.90\",\"0.063\"],[\"79581.80\",\"3.312\"],[\"79583.20\",\"0.077\"],[\"79583.40\",\"0.006\"],[\"79588.70\",\"0.003\"],[\"79589.20\",\"0.195\"],[\"79589.30\",\"0.063\"],[\"79593.90\",\"0.000\"],[\"79604.00\",\"0.030\"],[\"79604.40\",\"0.000\"],[\"79604.60\",\"0.000\"],[\"79604.70\",\"0.001\"],[\"79605.00\",\"0.630\"],[\"79607.10\",\"5.531\"]],\"a\":[[\"79623.30\",\"0.458\"],[\"79624.50\",\"0.479\"],[\"79625.50\",\"0.458\"],[\"79774.40\",\"2.003\"],[\"79963.40\",\"0.000\"],[\"79967.40\",\"0.000\"],[\"79995.80\",\"0.100\"],[\"79997.80\",\"0.000\"],[\"80005.30\",\"0.001\"],[\"80204.30\",\"4.358\"],[\"80403.30\",\"18.560\"],[\"80482.90\",\"19.543\"]],\"st\":1}}"}
{"receive_ns":1788563379388048000,"stream":"btcusdt@bookTicker","event_type":"bookTicker","event_time_ms":1788563379425,"raw_json":"{\"stream\":\"btcusdt@bookTicker\",\"data\":{\"e\":\"bookTicker\",\"u\":11478232648191,\"s\":\"BTCUSDT\",\"ps\":\"BTCUSDT\",\"b\":\"79607.10\",\"B\":\"4.929\",\"a\":\"79607.20\",\"A\":\"6.462\",\"T\":1788563379424,\"E\":1788563379425,\"st\":1}}"}
{"receive_ns":1788563379391969000,"stream":"btcusdt@bookTicker","event_type":"bookTicker","event_time_ms":1788563379427,"raw_json":"{\"stream\":\"btcusdt@bookTicker\",\"data\":{\"e\":\"bookTicker\",\"u\":11478232648391,\"s\":\"BTCUSDT\",\"ps\":\"BTCUSDT\",\"b\":\"79607.10\",\"B\":\"5.532\",\"a\":\"79607.20\",\"A\":\"6.462\",\"T\":1788563379427,\"E\":1788563379427,\"st\":1}}"}
{"receive_ns":1788563379392279000,"stream":"btcusdt@bookTicker","event_type":"bookTicker","event_time_ms":1788563379429,"raw_json":"{\"stream\":\"btcusdt@bookTicker\",\"data\":{\"e\":\"bookTicker\",\"u\":11478232648442,\"s\":\"BTCUSDT\",\"ps\":\"BTCUSDT\",\"b\":\"79607.10\",\"B\":\"5.530\",\"a\":\"79607.20\",\"A\":\"6.462\",\"T\":1788563379428,\"E\":1788563379429,\"st\":1}}"}
{"receive_ns":1788563379477486000,"stream":"btcusdt@depth@100ms","event_type":"depthUpdate","event_time_ms":1788563379515,"raw_json":"{\"stream\":\"btcusdt@depth@100ms\",\"data\":{\"e\":\"depthUpdate\",\"E\":1788563379515,\"T\":1788563379513,\"s\":\"BTCUSDT\",\"ps\":\"BTCUSDT\",\"U\":11478232647812,\"u\":11478232651005,\"pu\":11478232647738,\"b\":[[\"29107.10\",\"1.043\"],[\"29207.10\",\"1.057\"],[\"63685.70\",\"0.001\"],[\"71646.30\",\"0.002\"],[\"76422.80\",\"0.000\"],[\"78716.20\",\"0.190\"],[\"78811.00\",\"15.338\"],[\"79232.90\",\"0.141\"],[\"79491.70\",\"0.558\"],[\"79520.60\",\"0.000\"],[\"79536.50\",\"0.002\"],[\"79574.00\",\"0.071\"],[\"79579.90\",\"0.502\"],[\"79580.60\",\"0.000\"],[\"79581.80\",\"2.873\"],[\"79582.90\",\"0.076\"],[\"79583.20\",\"0.002\"],[\"79583.70\",\"0.017\"],[\"79583.80\",\"0.001\"],[\"79583.90\",\"0.688\"],[\"79584.20\",\"0.010\"],[\"79585.20\",\"0.078\"],[\"79588.20\",\"0.332\"],[\"79588.30\",\"0.023\"],[\"79589.00\",\"0.062\"],[\"79589.20\",\"0.395\"],[\"79589.30\",\"0.001\"],[\"79590.60\",\"0.314\"],[\"79591.00\",\"0.328\"],[\"79598.60\",\"0.002\"],[\"79599.30\",\"0.002\"],[\"79604.10\",\"1.026\"],[\"79606.90\",\"0.199\"],[\"79607.10\",\"5.530\"]],\"a\":[[\"79607.70\",\"0.017\"],[\"79609.90\",\"0.002\"],[\"79625.30\",\"0.003\"],[\"79626.50\",\"0.709\"],[\"79774.40\",\"2.505\"],[\"79963.40\",\"0.618\"],[\"79967.40\",\"0.090\"],[\"79995.30\",\"0.046\"],[\"79995.80\",\"0.863\"],[\"79997.80\",\"0.525\"],[\"79999.30\",\"0.167\"],[\"80403.30\",\"18.560\"],[\"80522.70\",\"0.232\"],[\"80633.00\",\"13.636\"],[\"80642.20\",\"0.871\"],[\"80729.70\",\"4.947\"]],\"st\":1}}"}
{"receive_ns":1788563379479356000,"stream":"btcusdt@bookTicker","event_type":"bookTicker","event_time_ms":1788563379517,"raw_json":"{\"stream\":\"btcusdt@bookTicker\",\"data\":{\"e\":\"bookTicker\",\"u\":11478232651201,\"s\":\"BTCUSDT\",\"ps\":\"BTCUSDT\",\"b\":\"79607.10\",\"B\":\"5.530\",\"a\":\"79607.20\",\"A\":\"6.901\",\"T\":1788563379517,\"E\":1788563379517,\"st\":1}}"}
{"receive_ns":1788563379480447000,"stream":"btcusdt@bookTicker","event_type":"bookTicker","event_time_ms":1788563379519,"raw_json":"{\"stream\":\"btcusdt@bookTicker\",\"data\":{\"e\":\"bookTicker\",\"u\":11478232651237,\"s\":\"BTCUSDT\",\"ps\":\"BTCUSDT\",\"b\":\"79607.10\",\"B\":\"5.532\",\"a\":\"79607.20\",\"A\":\"6.901\",\"T\":1788563379518,\"E\":1788563379519,\"st\":1}}"}
{"receive_ns":1788563379500906000,"stream":"btcusdt@bookTicker","event_type":"bookTicker","event_time_ms":1788563379539,"raw_json":"{\"stream\":\"btcusdt@bookTicker\",\"data\":{\"e\":\"bookTicker\",\"u\":11478232652363,\"s\":\"BTCUSDT\",\"ps\":\"BTCUSDT\",\"b\":\"79607.10\",\"B\":\"5.525\",\"a\":\"79607.20\",\"A\":\"6.901\",\"T\":1788563379538,\"E\":1788563379539,\"st\":1}}"}
{"receive_ns":1788563379524824000,"stream":"btcusdt@bookTicker","event_type":"bookTicker","event_time_ms":1788563379554,"raw_json":"{\"stream\":\"btcusdt@bookTicker\",\"data\":{\"e\":\"bookTicker\",\"u\":11478232652850,\"s\":\"BTCUSDT\",\"ps\":\"BTCUSDT\",\"b\":\"79607.10\",\"B\":\"5.525\",\"a\":\"79607.20\",\"A\":\"6.462\",\"T\":1788563379554,\"E\":1788563379554,\"st\":1}}"}
{"receive_ns":1788563379571789000,"stream":"btcusdt@bookTicker","event_type":"bookTicker","event_time_ms":1788563379609,"raw_json":"{\"stream\":\"btcusdt@bookTicker\",\"data\":{\"e\":\"bookTicker\",\"u\":11478232654934,\"s\":\"BTCUSDT\",\"ps\":\"BTCUSDT\",\"b\":\"79607.10\",\"B\":\"5.528\",\"a\":\"79607.20\",\"A\":\"6.462\",\"T\":1788563379609,\"E\":1788563379609,\"st\":1}}"}
{"receive_ns":1788563379580102000,"stream":"btcusdt@depth@100ms","event_type":"depthUpdate","event_time_ms":1788563379617,"raw_json":"{\"stream\":\"btcusdt@depth@100ms\",\"data\":{\"e\":\"depthUpdate\",\"E\":1788563379617,\"T\":1788563379616,\"s\":\"BTCUSDT\",\"ps\":\"BTCUSDT\",\"U\":11478232651126,\"u\":11478232655545,\"pu\":11478232651005,\"b\":[[\"1000.00\",\"24.754\"],[\"29107.10\",\"1.218\"],[\"29207.10\",\"0.882\"],[\"71646.30\",\"0.002\"],[\"75626.70\",\"0.026\"],[\"75626.80\",\"0.010\"],[\"78811.00\",\"15.338\"],[\"79209.00\",\"0.002\"],[\"79491.70\",\"0.326\"],[\"79511.50\",\"0.024\"],[\"79559.80\",\"0.002\"],[\"79564.50\",\"2.339\"],[\"79598.50\",\"0.003\"],[\"79598.60\",\"0.000\"],[\"79607.10\",\"5.528\"]],\"a\":[[\"79607.20\",\"6.462\"],[\"79707.40\",\"0.001\"],[\"79742.60\",\"0.002\"],[\"79774.40\",\"2.254\"],[\"79967.40\",\"0.000\"],[\"79995.80\",\"0.100\"],[\"79997.80\",\"0.000\"],[\"80403.30\",\"18.562\"],[\"80642.10\",\"31.129\"]],\"st\":1}}"}
{"receive_ns":1788563379639687000,"stream":"btcusdt@bookTicker","event_type":"bookTicker","event_time_ms":1788563379676,"raw_json":"{\"stream\":\"btcusdt@bookTicker\",\"data\":{\"e\":\"bookTicker\",\"u\":11478232657484,\"s\":\"BTCUSDT\",\"ps\":\"BTCUSDT\",\"b\":\"79607.10\",\"B\":\"5.532\",\"a\":\"79607.20\",\"A\":\"6.462\",\"T\":1788563379676,\"E\":1788563379676,\"st\":1}}"}
{"receive_ns":1788563379683346000,"stream":"btcusdt@depth@100ms","event_type":"depthUpdate","event_time_ms":1788563379719,"raw_json":"{\"stream\":\"btcusdt@depth@100ms\",\"data\":{\"e\":\"depthUpdate\",\"E\":1788563379719,\"T\":1788563379717,\"s\":\"BTCUSDT\",\"ps\":\"BTCUSDT\",\"U\":11478232655562,\"u\":11478232658989,\"pu\":11478232655545,\"b\":[[\"29107.10\",\"1.400\"],[\"29207.10\",\"0.700\"],[\"71646.30\",\"0.002\"],[\"76422.80\",\"0.002\"],[\"78601.80\",\"0.794\"],[\"78811.00\",\"15.338\"],[\"79209.10\",\"3.977\"],[\"79232.90\",\"0.141\"],[\"79443.50\",\"0.009\"],[\"79443.60\",\"0.613\"],[\"79482.90\",\"0.000\"],[\"79491.70\",\"0.000\"],[\"79492.40\",\"0.099\"],[\"79493.70\",\"0.863\"],[\"79535.50\",\"0.251\"],[\"79583.20\",\"0.604\"],[\"79583.80\",\"0.001\"],[\"79589.20\",\"0.395\"],[\"79594.90\",\"0.170\"],[\"79604.90\",\"0.026\"],[\"79607.10\",\"5.532\"]],\"a\":[[\"79648.80\",\"0.327\"],[\"79706.50\",\"0.076\"],[\"79728.70\",\"0.000\"],[\"79768.10\",\"0.000\"],[\"79772.80\",\"0.007\"],[\"79774.40\",\"2.505\"],[\"79963.40\",\"0.618\"],[\"79967.40\",\"0.090\"],[\"79995.30\",\"0.002\"],[\"79995.80\",\"0.863\"],[\"79997.80\",\"0.525\"],[\"79999.30\",\"0.167\"],[\"80363.50\",\"12.420\"],[\"80403.30\",\"19.802\"],[\"80523.20\",\"6.642\"],[\"81199.30\",\"10.768\"],[\"83486.20\",\"0.750\"]],\"st\":1}}"}
{"receive_ns":1788563379710776000,"stream":"btcusdt@bookTicker","event_type":"bookTicker","event_time_ms":1788563379748,"raw_json":"{\"stream\":\"btcusdt@bookTicker\",\"data\":{\"e\":\"bookTicker\",\"u\":11478232659937,\"s\":\"BTCUSDT\",\"ps\":\"BTCUSDT\",\"b\":\"79607.10\",\"B\":\"5.539\",\"a\":\"79607.20\",\"A\":\"6.462\",\"T\":1788563379747,\"E\":1788563379748,\"st\":1}}"}
{"receive_ns":1788563379789729000,"stream":"btcusdt@depth@100ms","event_type":"depthUpdate","event_time_ms":1788563379821,"raw_json":"{\"stream\":\"btcusdt@depth@100ms\",\"data\":{\"e\":\"depthUpdate\",\"E\":1788563379821,\"T\":1788563379818,\"s\":\"BTCUSDT\",\"ps\":\"BTCUSDT\",\"U\":11478232659049,\"u\":11478232663314,\"pu\":11478232658989,\"b\":[[\"29107.10\",\"1.575\"],[\"29207.10\",\"0.525\"],[\"71646.30\",\"0.002\"],[\"76422.80\",\"0.000\"],[\"78253.80\",\"4.207\"],[\"78811.00\",\"15.338\"],[\"79395.70\",\"0.000\"],[\"79511.50\",\"0.022\"],[\"79535.40\",\"0.002\"],[\"79589.20\",\"0.470\"],[\"79598.40\",\"0.141\"],[\"79607.10\",\"5.539\"]],\"a\":[[\"79678.90\",\"0.015\"],[\"79706.60\",\"0.301\"],[\"79706.80\",\"0.000\"],[\"79742.60\",\"0.000\"],[\"79812.00\",\"0.607\"],[\"79815.90\",\"0.012\"],[\"79995.30\",\"0.046\"],[\"80403.30\",\"19.802\"],[\"80523.50\",\"10.416\"]],\"st\":1}}"}
{"receive_ns":1788563379887437000,"stream":"btcusdt@depth@100ms","event_type":"depthUpdate","event_time_ms":1788563379923,"raw_json":"{\"stream\":\"btcusdt@depth@100ms\",\"data\":{\"e\":\"depthUpdate\",\"E\":1788563379923,\"T\":1788563379922,\"s\":\"BTCUSDT\",\"ps\":\"BTCUSDT\",\"U\":11478232663472,\"u\":11478232667356,\"pu\":11478232663314,\"b\":[[\"1000.00\",\"24.754\"],[\"29107.10\",\"1.757\"],[\"29207.10\",\"0.343\"],[\"71646.30\",\"0.002\"],[\"76422.80\",\"0.002\"],[\"78811.00\",\"15.338\"],[\"78890.60\",\"36.364\"],[\"79232.90\",\"0.141\"],[\"79491.70\",\"0.232\"],[\"79493.70\",\"0.631\"],[\"79535.50\",\"0.100\"],[\"79548.20\",\"0.071\"],[\"79583.20\",\"0.504\"],[\"79583.80\",\"2.009\"],[\"79589.20\",\"0.470\"],[\"79593.70\",\"0.077\"],[\"79594.30\",\"0.297\"],[\"79595.60\",\"0.148\"],[\"79602.50\",\"0.001\"],[\"79602.60\",\"0.001\"],[\"79605.50\",\"0.028\"],[\"79605.60\",\"0.051\"]],\"a\":[[\"79638.90\",\"0.191\"],[\"79667.80\",\"0.001\"],[\"79706.90\",\"0.000\"],[\"79707.30\",\"0.002\"],[\"79774.40\",\"2.254\"],[\"79963.40\",\"0.618\"],[\"79967.40\",\"0.341\"],[\"79987.90\",\"0.763\"],[\"79995.80\",\"0.100\"],[\"79997.80\",\"0.525\"],[\"79999.30\",\"0.011\"],[\"80005.20\",\"3.753\"],[\"80320.10\",\"8.922\"],[\"80403.30\",\"19.802\"],[\"80523.50\",\"9.672\"],[\"80602.30\",\"10.406\"],[\"80734.00\",\"0.444\"]],\"st\":1}}"}
{"receive_ns":1788563379998343000,"stream":"btcusdt@depth@100ms","event_type":"depthUpdate","event_time_ms":1788563380025,"raw_json":"{\"stream\":\"btcusdt@depth@100ms\",\"data\":{\"e\":\"depthUpdate\",\"E\":1788563380025,\"T\":1788563380021,\"s\":\"BTCUSDT\",\"ps\":\"BTCUSDT\",\"U\":11478232667374,\"u\":11478232671320,\"pu\":11478232667356,\"b\":[[\"29107.10\",\"1.806\"],[\"29207.10\",\"0.231\"],[\"29507.10\",\"0.063\"],[\"71646.30\",\"0.002\"],[\"76422.80\",\"0.000\"],[\"78253.80\",\"8.035\"],[\"78811.00\",\"15.338\"],[\"79209.10\",\"3.977\"],[\"79395.70\",\"5.018\"],[\"79443.50\",\"2.514\"],[\"79482.90\",\"0.526\"],[\"79491.70\",\"0.483\"],[\"79548.20\",\"0.001\"],[\"79573.90\",\"0.002\"],[\"79574.70\",\"0.455\"],[\"79575.00\",\"0.007\"],[\"79575.90\",\"0.003\"],[\"79579.90\",\"0.502\"],[\"79580.70\",\"0.006\"],[\"79581.80\",\"2.873\"],[\"79582.00\",\"0.026\"],[\"79583.20\",\"0.077\"],[\"79583.80\",\"0.001\"],[\"79584.20\",\"0.004\"],[\"79589.20\",\"0.395\"],[\"79592.20\",\"0.098\"],[\"79592.30\",\"0.001\"],[\"79593.00\",\"0.001\"],[\"79593.70\",\"0.001\"],[\"79599.00\",\"0.006\"],[\"79602.20\",\"0.046\"],[\"79602.40\",\"0.280\"],[\"79602.50\",\"0.027\"],[\"79602.60\",\"0.027\"],[\"79602.90\",\"0.001\"],[\"79603.70\",\"0.011\"],[\"79603.90\",\"0.001\"],[\"79604.00\",\"0.004\"],[\"79604.10\",\"1.000\"],[\"79604.70\",\"0.001\"],[\"79604.90\",\"0.000\"],[\"79605.50\",\"0.002\"],[\"79605.60\",\"0.025\"],[\"79606.80\",\"0.003\"]],\"a\":[[\"79624.40\",\"0.452\"],[\"79625.50\",\"0.006\"],[\"79630.90\",\"0.638\"],[\"79632.90\",\"1.006\"],[\"79706.90\",\"0.000\"],[\"79707.20\",\"0.000\"],[\"79728.70\",\"0.294\"],[\"79768.10\",\"1.349\"],[\"79815.90\",\"3.159\"],[\"79995.30\",\"0.002\"],[\"79999.30\",\"0.211\"],[\"80364.70\",\"0.000\"],[\"80403.30\",\"21.044\"],[\"80638.70\",\"0.434\"],[\"80693.00\",\"0.000\"],[\"81199.30\",\"10.765\"]],\"st\":1}}"}
{"receive_ns":1788563380090202000,"stream":"btcusdt@depth@100ms","event_type":"depthUpdate","event_time_ms":1788563380127,"raw_json":"{\"stream\":\"btcusdt@depth@100ms\",\"data\":{\"e\":\"depthUpdate\",\"E\":1788563380127,\"T\":1788563380126,\"s\":\"BTCUSDT\",\"ps\":\"BTCUSDT\",\"U\":11478232671421,\"u\":11478232676986,\"pu\":11478232671320,\"b\":[[\"29107.10\",\"1.876\"],[\"29207.10\",\"0.105\"],[\"29507.10\",\"0.119\"],[\"71646.30\",\"0.002\"],[\"78448.10\",\"3.692\"],[\"78501.70\",\"0.000\"],[\"78651.80\",\"48.857\"],[\"78811.00\",\"15.338\"],[\"79443.60\",\"0.926\"],[\"79528.60\",\"0.000\"],[\"79529.10\",\"0.050\"],[\"79592.80\",\"0.004\"],[\"79603.70\",\"0.037\"],[\"79604.30\",\"0.026\"]],\"a\":[[\"79656.10\",\"0.200\"],[\"79656.60\",\"1.431\"],[\"79707.00\",\"0.603\"],[\"79777.00\",\"1.260\"],[\"79812.00\",\"1.012\"],[\"79961.60\",\"0.197\"],[\"79987.90\",\"0.000\"],[\"80403.30\",\"22.288\"],[\"80523.50\",\"8.928\"]],\"st\":1}}"}
{"receive_ns":1788563380090485000,"stream":"btcusdt@bookTicker","event_type":"bookTicker","event_time_ms":1788563380128,"raw_json":"{\"stream\":\"btcusdt@bookTicker\",\"data\":{\"e\":\"bookTicker\",\"u\":11478232677115,\"s\":\"BTCUSDT\",\"ps\":\"BTCUSDT\",\"b\":\"79607.10\",\"B\":\"5.543\",\"a\":\"79607.20\",\"A\":\"6.462\",\"T\":1788563380128,\"E\":1788563380128,\"st\":1}}"}
{"receive_ns":1788563380093815000,"stream":"btcusdt@bookTicker","event_type":"bookTicker","event_time_ms":1788563380130,"raw_json":"{\"stream\":\"btcusdt@bookTicker\",\"data\":{\"e\":\"bookTicker\",\"u\":11478232677244,\"s\":\"BTCUSDT\",\"ps\":\"BTCUSDT\",\"b\":\"79607.10\",\"B\":\"5.122\",\"a\":\"79607.20\",\"A\":\"6.462\",\"T\":1788563380130,\"E\":1788563380130,\"st\":1}}"}
{"receive_ns":1788563380096500000,"stream":"btcusdt@bookTicker","event_type":"bookTicker","event_time_ms":1788563380133,"raw_json":"{\"stream\":\"btcusdt@bookTicker\",\"data\":{\"e\":\"bookTicker\",\"u\":11478232677378,\"s\":\"BTCUSDT\",\"ps\":\"BTCUSDT\",\"b\":\"79607.10\",\"B\":\"5.545\",\"a\":\"79607.20\",\"A\":\"6.462\",\"T\":1788563380133,\"E\":1788563380133,\"st\":1}}"}
{"receive_ns":1788563380097765000,"stream":"btcusdt@bookTicker","event_type":"bookTicker","event_time_ms":1788563380134,"raw_json":"{\"stream\":\"btcusdt@bookTicker\",\"data\":{\"e\":\"bookTicker\",\"u\":11478232677413,\"s\":\"BTCUSDT\",\"ps\":\"BTCUSDT\",\"b\":\"79607.10\",\"B\":\"5.543\",\"a\":\"79607.20\",\"A\":\"6.462\",\"T\":1788563380134,\"E\":1788563380134,\"st\":1}}"}
{"receive_ns":1788563380107926000,"stream":"btcusdt@bookTicker","event_type":"bookTicker","event_time_ms":1788563380144,"raw_json":"{\"stream\":\"btcusdt@bookTicker\",\"data\":{\"e\":\"bookTicker\",\"u\":11478232678108,\"s\":\"BTCUSDT\",\"ps\":\"BTCUSDT\",\"b\":\"79607.10\",\"B\":\"5.543\",\"a\":\"79607.20\",\"A\":\"6.593\",\"T\":1788563380144,\"E\":1788563380144,\"st\":1}}"}
{"receive_ns":1788563380108754000,"stream":"btcusdt@bookTicker","event_type":"bookTicker","event_time_ms":1788563380145,"raw_json":"{\"stream\":\"btcusdt@bookTicker\",\"data\":{\"e\":\"bookTicker\",\"u\":11478232678233,\"s\":\"BTCUSDT\",\"ps\":\"BTCUSDT\",\"b\":\"79607.10\",\"B\":\"5.545\",\"a\":\"79607.20\",\"A\":\"6.593\",\"T\":1788563380145,\"E\":1788563380145,\"st\":1}}"}
{"receive_ns":1788563380143890000,"stream":"btcusdt@bookTicker","event_type":"bookTicker","event_time_ms":1788563380181,"raw_json":"{\"stream\":\"btcusdt@bookTicker\",\"data\":{\"e\":\"bookTicker\",\"u\":11478232680032,\"s\":\"BTCUSDT\",\"ps\":\"BTCUSDT\",\"b\":\"79607.10\",\"B\":\"5.012\",\"a\":\"79607.20\",\"A\":\"6.593\",\"T\":1788563380181,\"E\":1788563380181,\"st\":1}}"}
{"receive_ns":1788563380147276000,"stream":"btcusdt@bookTicker","event_type":"bookTicker","event_time_ms":1788563380185,"raw_json":"{\"stream\":\"btcusdt@bookTicker\",\"data\":{\"e\":\"bookTicker\",\"u\":11478232680246,\"s\":\"BTCUSDT\",\"ps\":\"BTCUSDT\",\"b\":\"79607.10\",\"B\":\"5.546\",\"a\":\"79607.20\",\"A\":\"6.593\",\"T\":1788563380184,\"E\":1788563380185,\"st\":1}}"}
{"receive_ns":1788563380155837000,"stream":"btcusdt@bookTicker","event_type":"bookTicker","event_time_ms":1788563380186,"raw_json":"{\"stream\":\"btcusdt@bookTicker\",\"data\":{\"e\":\"bookTicker\",\"u\":11478232680322,\"s\":\"BTCUSDT\",\"ps\":\"BTCUSDT\",\"b\":\"79607.10\",\"B\":\"5.544\",\"a\":\"79607.20\",\"A\":\"6.593\",\"T\":1788563380186,\"E\":1788563380186,\"st\":1}}"}
{"receive_ns":1788563380191661000,"stream":"btcusdt@depth@100ms","event_type":"depthUpdate","event_time_ms":1788563380229,"raw_json":"{\"stream\":\"btcusdt@depth@100ms\",\"data\":{\"e\":\"depthUpdate\",\"E\":1788563380229,\"T\":1788563380225,\"s\":\"BTCUSDT\",\"ps\":\"BTCUSDT\",\"U\":11478232676991,\"u\":11478232682005,\"pu\":11478232676986,\"b\":[[\"1000.00\",\"24.754\"],[\"29107.10\",\"1.897\"],[\"29207.10\",\"0.007\"],[\"29507.10\",\"0.196\"],[\"71646.30\",\"0.002\"],[\"71684.00\",\"0.000\"],[\"76422.80\",\"0.002\"],[\"78811.00\",\"15.338\"],[\"79034.60\",\"0.095\"],[\"79120.50\",\"0.313\"],[\"79209.10\",\"3.851\"],[\"79232.90\",\"0.141\"],[\"79482.90\",\"0.526\"],[\"79491.70\",\"0.332\"],[\"79492.30\",\"2.039\"],[\"79493.70\",\"0.882\"],[\"79535.50\",\"0.502\"],[\"79583.20\",\"0.202\"],[\"79589.20\",\"0.195\"],[\"79594.40\",\"0.002\"],[\"79595.70\",\"0.001\"],[\"79596.30\",\"0.033\"],[\"79598.50\",\"0.001\"],[\"79599.00\",\"0.007\"],[\"79602.10\",\"0.156\"],[\"79602.90\",\"0.002\"],[\"79603.60\",\"1.519\"],[\"79603.70\",\"0.011\"],[\"79603.90\",\"0.001\"],[\"79604.30\",\"0.000\"],[\"79606.80\",\"0.004\"],[\"79607.10\",\"5.544\"]],\"a\":[[\"79607.20\",\"6.593\"],[\"79609.30\",\"0.252\"],[\"79615.20\",\"1.341\"],[\"79626.50\",\"0.629\"],[\"79628.50\",\"0.080\"],[\"79707.00\",\"0.603\"],[\"79707.30\",\"0.002\"],[\"79728.70\",\"0.294\"],[\"79747.40\",\"0.007\"],[\"79774.40\",\"2.505\"],[\"79961.60\",\"0.120\"],[\"79963.40\",\"0.618\"],[\"79964.00\",\"0.764\"],[\"79967.40\",\"0.090\"],[\"79997.80\",\"0.525\"],[\"79999.30\",\"0.167\"],[\"80363.50\",\"12.978\"],[\"80403.30\",\"22.286\"],[\"80523.50\",\"10.416\"],[\"80562.50\",\"48.972\"],[\"81832.50\",\"0.488\"]],\"st\":1}}"}
{"receive_ns":1788563380237443000,"stream":"btcusdt@bookTicker","event_type":"bookTicker","event_time_ms":1788563380274,"raw_json":"{\"stream\":\"btcusdt@bookTicker\",\"data\":{\"e\":\"bookTicker\",\"u\":11478232683509,\"s\":\"BTCUSDT\",\"ps\":\"BTCUSDT\",\"b\":\"79607.10\",\"B\":\"4.386\",\"a\":\"79607.20\",\"A\":\"6.593\",\"T\":1788563380274,\"E\":1788563380274,\"st\":1}}"}
{"receive_ns":1788563380238419000,"stream":"btcusdt@bookTicker","event_type":"bookTicker","event_time_ms":1788563380276,"raw_json":"{\"stream\":\"btcusdt@bookTicker\",\"data\":{\"e\":\"bookTicker\",\"u\":11478232683573,\"s\":\"BTCUSDT\",\"ps\":\"BTCUSDT\",\"b\":\"79607.10\",\"B\":\"4.388\",\"a\":\"79607.20\",\"A\":\"6.593\",\"T\":1788563380275,\"E\":1788563380276,\"st\":1}}"}
{"receive_ns":1788563380246137000,"stream":"btcusdt@bookTicker","event_type":"bookTicker","event_time_ms":1788563380283,"raw_json":"{\"stream\":\"btcusdt@bookTicker\",\"data\":{\"e\":\"bookTicker\",\"u\":11478232683901,\"s\":\"BTCUSDT\",\"ps\":\"BTCUSDT\",\"b\":\"79607.10\",\"B\":\"5.547\",\"a\":\"79607.20\",\"A\":\"6.593\",\"T\":1788563380283,\"E\":1788563380283,\"st\":1}}"}
{"receive_ns":1788563380246464000,"stream":"btcusdt@bookTicker","event_type":"bookTicker","event_time_ms":1788563380284,"raw_json":"{\"stream\":\"btcusdt@bookTicker\",\"data\":{\"e\":\"bookTicker\",\"u\":11478232683946,\"s\":\"BTCUSDT\",\"ps\":\"BTCUSDT\",\"b\":\"79607.10\",\"B\":\"5.545\",\"a\":\"79607.20\",\"A\":\"6.593\",\"T\":1788563380284,\"E\":1788563380284,\"st\":1}}"}
{"receive_ns":1788563380249568000,"stream":"btcusdt@bookTicker","event_type":"bookTicker","event_time_ms":1788563380286,"raw_json":"{\"stream\":\"btcusdt@bookTicker\",\"data\":{\"e\":\"bookTicker\",\"u\":11478232684041,\"s\":\"BTCUSDT\",\"ps\":\"BTCUSDT\",\"b\":\"79607.10\",\"B\":\"5.557\",\"a\":\"79607.20\",\"A\":\"6.593\",\"T\":1788563380286,\"E\":1788563380286,\"st\":1}}"}
{"receive_ns":1788563380249760000,"stream":"btcusdt@bookTicker","event_type":"bookTicker","event_time_ms":1788563380287,"raw_json":"{\"stream\":\"btcusdt@bookTicker\",\"data\":{\"e\":\"bookTicker\",\"u\":11478232684042,\"s\":\"BTCUSDT\",\"ps\":\"BTCUSDT\",\"b\":\"79607.10\",\"B\":\"5.569\",\"a\":\"79607.20\",\"A\":\"6.593\",\"T\":1788563380286,\"E\":1788563380287,\"st\":1}}"}
{"receive_ns":1788563380249905000,"stream":"btcusdt@bookTicker","event_type":"bookTicker","event_time_ms":1788563380287,"raw_json":"{\"stream\":\"btcusdt@bookTicker\",\"data\":{\"e\":\"bookTicker\",\"u\":11478232684048,\"s\":\"BTCUSDT\",\"ps\":\"BTCUSDT\",\"b\":\"79607.10\",\"B\":\"5.581\",\"a\":\"79607.20\",\"A\":\"6.593\",\"T\":1788563380287,\"E\":1788563380287,\"st\":1}}"}
{"receive_ns":1788563380250104000,"stream":"btcusdt@bookTicker","event_type":"bookTicker","event_time_ms":1788563380288,"raw_json":"{\"stream\":\"btcusdt@bookTicker\",\"data\":{\"e\":\"bookTicker\",\"u\":11478232684085,\"s\":\"BTCUSDT\",\"ps\":\"BTCUSDT\",\"b\":\"79607.10\",\"B\":\"5.583\",\"a\":\"79607.20\",\"A\":\"6.593\",\"T\":1788563380287,\"E\":1788563380288,\"st\":1}}"}
{"receive_ns":1788563380293702000,"stream":"btcusdt@depth@100ms","event_type":"depthUpdate","event_time_ms":1788563380331,"raw_json":"{\"stream\":\"btcusdt@depth@100ms\",\"data\":{\"e\":\"depthUpdate\",\"E\":1788563380331,\"T\":1788563380329,\"s\":\"BTCUSDT\",\"ps\":\"BTCUSDT\",\"U\":11478232682129,\"u\":11478232685552,\"pu\":11478232682005,\"b\":[[\"29107.10\",\"1.729\"],[\"29207.10\",\"0.000\"],[\"29507.10\",\"0.371\"],[\"71646.30\",\"0.002\"],[\"76422.80\",\"0.000\"],[\"78651.80\",\"52.666\"],[\"78811.00\",\"15.338\"],[\"79209.10\",\"3.725\"],[\"79482.90\",\"0.526\"],[\"79535.50\",\"0.577\"],[\"79583.40\",\"0.004\"],[\"79592.10\",\"0.077\"],[\"79592.20\",\"0.022\"],[\"79595.30\",\"0.354\"],[\"79596.30\",\"0.033\"],[\"79601.90\",\"0.026\"],[\"79602.00\",\"0.029\"],[\"79603.10\",\"0.252\"],[\"79603.40\",\"0.026\"],[\"79603.50\",\"0.004\"],[\"79606.50\",\"0.000\"],[\"79607.10\",\"5.583\"]],\"a\":[[\"79623.30\",\"0.456\"],[\"79705.10\",\"0.001\"],[\"79706.40\",\"0.127\"],[\"79706.90\",\"0.000\"],[\"79728.70\",\"0.294\"],[\"79999.30\",\"0.211\"],[\"80403.30\",\"22.286\"],[\"80523.50\",\"9.672\"],[\"80562.50\",\"47.981\"],[\"80681.90\",\"9.896\"]],\"st\":1}}"}
{"receive_ns":1788563380397262000,"stream":"btcusdt@bookTicker","event_type":"bookTicker","event_time_ms":1788563380431,"raw_json":"{\"stream\":\"btcusdt@bookTicker\",\"data\":{\"e\":\"bookTicker\",\"u\":11478232688680,\"s\":\"BTCUSDT\",\"ps\":\"BTCUSDT\",\"b\":\"79607.10\",\"B\":\"4.980\",\"a\":\"79607.20\",\"A\":\"6.593\",\"T\":1788563380431,\"E\":1788563380431,\"st\":1}}"}
{"receive_ns":1788563380397632000,"stream":"btcusdt@bookTicker","event_type":"bookTicker","event_time_ms":1788563380432,"raw_json":"{\"stream\":\"btcusdt@bookTicker\",\"data\":{\"e\":\"bookTicker\",\"u\":11478232688736,\"s\":\"BTCUSDT\",\"ps\":\"BTCUSDT\",\"b\":\"79607.10\",\"B\":\"4.979\",\"a\":\"79607.20\",\"A\":\"6.593\",\"T\":1788563380432,\"E\":1788563380432,\"st\":1}}"}
{"receive_ns":1788563380398039000,"stream":"btcusdt@depth@100ms","event_type":"depthUpdate","event_time_ms":1788563380433,"raw_json":"{\"stream\":\"btcusdt@depth@100ms\",\"data\":{\"e\":\"depthUpdate\",\"E\":1788563380433,\"T\":1788563380432,\"s\":\"BTCUSDT\",\"ps\":\"BTCUSDT\",\"U\":11478232685610,\"u\":11478232688736,\"pu\":11478232685552,\"b\":[[\"1000.00\",\"24.754\"],[\"29107.10\",\"1.554\"],[\"29507.10\",\"0.546\"],[\"63686.00\",\"0.000\"],[\"71646.30\",\"0.002\"],[\"76422.80\",\"0.002\"],[\"78500.60\",\"7.077\"],[\"78811.00\",\"15.340\"],[\"78970.20\",\"8.000\"],[\"79209.10\",\"3.977\"],[\"79232.90\",\"0.141\"],[\"79491.70\",\"0.483\"],[\"79492.30\",\"0.031\"],[\"79493.70\",\"0.631\"],[\"79535.50\",\"0.075\"],[\"79583.20\",\"0.604\"],[\"79583.40\",\"0.006\"],[\"79583.80\",\"0.001\"],[\"79589.20\",\"0.395\"],[\"79606.90\",\"0.197\"],[\"79607.10\",\"4.979\"]],\"a\":[[\"79612.50\",\"0.081\"],[\"79615.80\",\"0.821\"],[\"79623.30\",\"0.458\"],[\"79637.90\",\"0.002\"],[\"79706.40\",\"0.002\"],[\"79707.20\",\"0.125\"],[\"79774.40\",\"2.254\"],[\"79963.40\",\"0.869\"],[\"79964.00\",\"0.001\"],[\"79967.40\",\"0.090\"],[\"79995.80\",\"0.863\"],[\"79997.80\",\"0.525\"],[\"79999.30\",\"0.211\"],[\"80005.20\",\"3.629\"],[\"80320.20\",\"1.056\"],[\"80403.30\",\"22.286\"],[\"80523.50\",\"8.928\"],[\"80562.50\",\"48.972\"],[\"80737.60\",\"1.924\"]],\"st\":1}}"}
{"receive_ns":1788563380398243000,"stream":"btcusdt@bookTicker","event_type":"bookTicker","event_time_ms":1788563380433,"raw_json":"{\"stream\":\"btcusdt@bookTicker\",\"data\":{\"e\":\"bookTicker\",\"u\":11478232688796,\"s\":\"BTCUSDT\",\"ps\":\"BTCUSDT\",\"b\":\"79607.10\",\"B\":\"4.980\",\"a\":\"79607.20\",\"A\":\"6.593\",\"T\":1788563380433,\"E\":1788563380433,\"st\":1}}"}
{"receive_ns":1788563380398407000,"stream":"btcusdt@bookTicker","event_type":"bookTicker","event_time_ms":1788563380434,"raw_json":"{\"stream\":\"btcusdt@bookTicker\",\"data\":{\"e\":\"bookTicker\",\"u\":11478232688843,\"s\":\"BTCUSDT\",\"ps\":\"BTCUSDT\",\"b\":\"79607.10\",\"B\":\"4.968\",\"a\":\"79607.20\",\"A\":\"6.593\",\"T\":1788563380434,\"E\":1788563380434,\"st\":1}}"}
{"receive_ns":1788563380398537000,"stream":"btcusdt@bookTicker","event_type":"bookTicker","event_time_ms":1788563380434,"raw_json":"{\"stream\":\"btcusdt@bookTicker\",\"data\":{\"e\":\"bookTicker\",\"u\":11478232688847,\"s\":\"BTCUSDT\",\"ps\":\"BTCUSDT\",\"b\":\"79607.10\",\"B\":\"5.585\",\"a\":\"79607.20\",\"A\":\"6.593\",\"T\":1788563380434,\"E\":1788563380434,\"st\":1}}"}
{"receive_ns":1788563380398670000,"stream":"btcusdt@bookTicker","event_type":"bookTicker","event_time_ms":1788563380434,"raw_json":"{\"stream\":\"btcusdt@bookTicker\",\"data\":{\"e\":\"bookTicker\",\"u\":11478232688848,\"s\":\"BTCUSDT\",\"ps\":\"BTCUSDT\",\"b\":\"79607.10\",\"B\":\"5.573\",\"a\":\"79607.20\",\"A\":\"6.593\",\"T\":1788563380434,\"E\":1788563380434,\"st\":1}}"}
{"receive_ns":1788563380398793000,"stream":"btcusdt@bookTicker","event_type":"bookTicker","event_time_ms":1788563380434,"raw_json":"{\"stream\":\"btcusdt@bookTicker\",\"data\":{\"e\":\"bookTicker\",\"u\":11478232688850,\"s\":\"BTCUSDT\",\"ps\":\"BTCUSDT\",\"b\":\"79607.10\",\"B\":\"5.561\",\"a\":\"79607.20\",\"A\":\"6.593\",\"T\":1788563380434,\"E\":1788563380434,\"st\":1}}"}
{"receive_ns":1788563380398988000,"stream":"btcusdt@bookTicker","event_type":"bookTicker","event_time_ms":1788563380435,"raw_json":"{\"stream\":\"btcusdt@bookTicker\",\"data\":{\"e\":\"bookTicker\",\"u\":11478232688872,\"s\":\"BTCUSDT\",\"ps\":\"BTCUSDT\",\"b\":\"79607.10\",\"B\":\"5.559\",\"a\":\"79607.20\",\"A\":\"6.593\",\"T\":1788563380435,\"E\":1788563380435,\"st\":1}}"}
{"receive_ns":1788563380467040000,"stream":"btcusdt@bookTicker","event_type":"bookTicker","event_time_ms":1788563380503,"raw_json":"{\"stream\":\"btcusdt@bookTicker\",\"data\":{\"e\":\"bookTicker\",\"u\":11478232691404,\"s\":\"BTCUSDT\",\"ps\":\"BTCUSDT\",\"b\":\"79607.10\",\"B\":\"5.559\",\"a\":\"79607.20\",\"A\":\"6.595\",\"T\":1788563380503,\"E\":1788563380503,\"st\":1}}"}
{"receive_ns":1788563380476071000,"stream":"btcusdt@bookTicker","event_type":"bookTicker","event_time_ms":1788563380506,"raw_json":"{\"stream\":\"btcusdt@bookTicker\",\"data\":{\"e\":\"bookTicker\",\"u\":11478232691596,\"s\":\"BTCUSDT\",\"ps\":\"BTCUSDT\",\"b\":\"79607.10\",\"B\":\"5.571\",\"a\":\"79607.20\",\"A\":\"6.595\",\"T\":1788563380506,\"E\":1788563380506,\"st\":1}}"}
{"receive_ns":1788563380476255000,"stream":"btcusdt@bookTicker","event_type":"bookTicker","event_time_ms":1788563380506,"raw_json":"{\"stream\":\"btcusdt@bookTicker\",\"data\":{\"e\":\"bookTicker\",\"u\":11478232691598,\"s\":\"BTCUSDT\",\"ps\":\"BTCUSDT\",\"b\":\"79607.10\",\"B\":\"5.583\",\"a\":\"79607.20\",\"A\":\"6.595\",\"T\":1788563380506,\"E\":1788563380506,\"st\":1}}"}
{"receive_ns":1788563380476386000,"stream":"btcusdt@bookTicker","event_type":"bookTicker","event_time_ms":1788563380506,"raw_json":"{\"stream\":\"btcusdt@bookTicker\",\"data\":{\"e\":\"bookTicker\",\"u\":11478232691613,\"s\":\"BTCUSDT\",\"ps\":\"BTCUSDT\",\"b\":\"79607.10\",\"B\":\"5.595\",\"a\":\"79607.20\",\"A\":\"6.595\",\"T\":1788563380506,\"E\":1788563380506,\"st\":1}}"}
{"receive_ns":1788563380478345000,"stream":"btcusdt@bookTicker","event_type":"bookTicker","event_time_ms":1788563380508,"raw_json":"{\"stream\":\"btcusdt@bookTicker\",\"data\":{\"e\":\"bookTicker\",\"u\":11478232691683,\"s\":\"BTCUSDT\",\"ps\":\"BTCUSDT\",\"b\":\"79607.10\",\"B\":\"5.597\",\"a\":\"79607.20\",\"A\":\"6.595\",\"T\":1788563380507,\"E\":1788563380508,\"st\":1}}"}
{"receive_ns":1788563380498099000,"stream":"btcusdt@depth@100ms","event_type":"depthUpdate","event_time_ms":1788563380535,"raw_json":"{\"stream\":\"btcusdt@depth@100ms\",\"data\":{\"e\":\"depthUpdate\",\"E\":1788563380535,\"T\":1788563380534,\"s\":\"BTCUSDT\",\"ps\":\"BTCUSDT\",\"U\":11478232688784,\"u\":11478232693064,\"pu\":11478232688736,\"b\":[[\"1000.00\",\"24.754\"],[\"29107.10\",\"1.372\"],[\"29507.10\",\"0.728\"],[\"63685.70\",\"0.001\"],[\"63686.00\",\"0.000\"],[\"71646.30\",\"0.002\"],[\"76422.80\",\"0.000\"],[\"77374.60\",\"0.774\"],[\"78015.00\",\"10.554\"],[\"78532.40\",\"9.893\"],[\"78811.00\",\"15.338\"],[\"79209.00\",\"0.000\"],[\"79520.50\",\"0.000\"],[\"79535.50\",\"0.000\"],[\"79536.50\",\"0.002\"],[\"79580.70\",\"0.000\"],[\"79582.60\",\"2.337\"],[\"79583.20\",\"0.579\"],[\"79594.40\",\"0.005\"],[\"79595.70\",\"0.001\"],[\"79596.30\",\"0.033\"],[\"79601.90\",\"0.000\"],[\"79603.50\",\"0.030\"],[\"79603.70\",\"0.011\"],[\"79607.10\",\"5.597\"]],\"a\":[[\"79607.20\",\"6.595\"],[\"79995.30\",\"0.046\"],[\"79999.30\",\"0.167\"],[\"80319.80\",\"0.250\"],[\"80323.70\",\"18.870\"],[\"80403.30\",\"22.286\"],[\"80523.50\",\"9.672\"],[\"80911.60\",\"0.864\"],[\"87568.00\",\"0.000\"]],\"st\":1}}"}
{"receive_ns":1788563380518562000,"stream":"btcusdt@bookTicker","event_type":"bookTicker","event_time_ms":1788563380554,"raw_json":"{\"stream\":\"btcusdt@bookTicker\",\"data\":{\"e\":\"bookTicker\",\"u\":11478232693801,\"s\":\"BTCUSDT\",\"ps\":\"BTCUSDT\",\"b\":\"79607.10\",\"B\":\"5.597\",\"a\":\"79607.20\",\"A\":\"7.034\",\"T\":1788563380554,\"E\":1788563380554,\"st\":1}}"}
{"receive_ns":1788563380518825000,"stream":"btcusdt@bookTicker","event_type":"bookTicker","event_time_ms":1788563380556,"raw_json":"{\"stream\":\"btcusdt@bookTicker\",\"data\":{\"e\":\"bookTicker\",\"u\":11478232693844,\"s\":\"BTCUSDT\",\"ps\":\"BTCUSDT\",\"b\":\"79607.10\",\"B\":\"5.597\",\"a\":\"79607.20\",\"A\":\"7.033\",\"T\":1788563380555,\"E\":1788563380556,\"st\":1}}"}
{"receive_ns":1788563380519193000,"stream":"btcusdt@bookTicker","event_type":"bookTicker","event_time_ms":1788563380557,"raw_json":"{\"stream\":\"btcusdt@bookTicker\",\"data\":{\"e\":\"bookTicker\",\"u\":11478232693939,\"s\":\"BTCUSDT\",\"ps\":\"BTCUSDT\",\"b\":\"79607.10\",\"B\":\"5.597\",\"a\":\"79607.20\",\"A\":\"7.034\",\"T\":1788563380557,\"E\":1788563380557,\"st\":1}}"}
{"receive_ns":1788563380521770000,"stream":"btcusdt@bookTicker","event_type":"bookTicker","event_time_ms":1788563380558,"raw_json":"{\"stream\":\"btcusdt@bookTicker\",\"data\":{\"e\":\"bookTicker\",\"u\":11478232693956,\"s\":\"BTCUSDT\",\"ps\":\"BTCUSDT\",\"b\":\"79607.10\",\"B\":\"5.585\",\"a\":\"79607.20\",\"A\":\"7.034\",\"T\":1788563380557,\"E\":1788563380558,\"st\":1}}"}
{"receive_ns":1788563380522221000,"stream":"btcusdt@bookTicker","event_type":"bookTicker","event_time_ms":1788563380558,"raw_json":"{\"stream\":\"btcusdt@bookTicker\",\"data\":{\"e\":\"bookTicker\",\"u\":11478232693965,\"s\":\"BTCUSDT\",\"ps\":\"BTCUSDT\",\"b\":\"79607.10\",\"B\":\"5.573\",\"a\":\"79607.20\",\"A\":\"7.034\",\"T\":1788563380557,\"E\":1788563380558,\"st\":1}}"}
{"receive_ns":1788563380522377000,"stream":"btcusdt@bookTicker","event_type":"bookTicker","event_time_ms":1788563380558,"raw_json":"{\"stream\":\"btcusdt@bookTicker\",\"data\":{\"e\":\"bookTicker\",\"u\":11478232693968,\"s\":\"BTCUSDT\",\"ps\":\"BTCUSDT\",\"b\":\"79607.10\",\"B\":\"5.561\",\"a\":\"79607.20\",\"A\":\"7.034\",\"T\":1788563380558,\"E\":1788563380558,\"st\":1}}"}
{"receive_ns":1788563380535641000,"stream":"btcusdt@bookTicker","event_type":"bookTicker","event_time_ms":1788563380565,"raw_json":"{\"stream\":\"btcusdt@bookTicker\",\"data\":{\"e\":\"bookTicker\",\"u\":11478232694299,\"s\":\"BTCUSDT\",\"ps\":\"BTCUSDT\",\"b\":\"79607.10\",\"B\":\"5.109\",\"a\":\"79607.20\",\"A\":\"7.034\",\"T\":1788563380564,\"E\":1788563380565,\"st\":1}}"}
{"receive_ns":1788563380535904000,"stream":"btcusdt@bookTicker","event_type":"bookTicker","event_time_ms":1788563380567,"raw_json":"{\"stream\":\"btcusdt@bookTicker\",\"data\":{\"e\":\"bookTicker\",\"u\":11478232694438,\"s\":\"BTCUSDT\",\"ps\":\"BTCUSDT\",\"b\":\"79607.10\",\"B\":\"5.562\",\"a\":\"79607.20\",\"A\":\"7.034\",\"T\":1788563380567,\"E\":1788563380567,\"st\":1}}"}
{"receive_ns":1788563380536132000,"stream":"btcusdt@bookTicker","event_type":"bookTicker","event_time_ms":1788563380568,"raw_json":"{\"stream\":\"btcusdt@bookTicker\",\"data\":{\"e\":\"bookTicker\",\"u\":11478232694464,\"s\":\"BTCUSDT\",\"ps\":\"BTCUSDT\",\"b\":\"79607.10\",\"B\":\"5.560\",\"a\":\"79607.20\",\"A\":\"7.034\",\"T\":1788563380568,\"E\":1788563380568,\"st\":1}}"}
{"receive_ns":1788563380581857000,"stream":"btcusdt@bookTicker","event_type":"bookTicker","event_time_ms":1788563380615,"raw_json":"{\"stream\":\"btcusdt@bookTicker\",\"data\":{\"e\":\"bookTicker\",\"u\":11478232696351,\"s\":\"BTCUSDT\",\"ps\":\"BTCUSDT\",\"b\":\"79607.10\",\"B\":\"5.558\",\"a\":\"79607.20\",\"A\":\"7.034\",\"T\":1788563380615,\"E\":1788563380615,\"st\":1}}"}
{"receive_ns":1788563380596557000,"stream":"btcusdt@bookTicker","event_type":"bookTicker","event_time_ms":1788563380633,"raw_json":"{\"stream\":\"btcusdt@bookTicker\",\"data\":{\"e\":\"bookTicker\",\"u\":11478232697181,\"s\":\"BTCUSDT\",\"ps\":\"BTCUSDT\",\"b\":\"79607.10\",\"B\":\"5.558\",\"a\":\"79607.20\",\"A\":\"7.032\",\"T\":1788563380633,\"E\":1788563380633,\"st\":1}}"}
{"receive_ns":1788563380596817000,"stream":"btcusdt@trade","event_type":"trade","event_time_ms":1788563380633,"raw_json":"{\"stream\":\"btcusdt@trade\",\"data\":{\"e\":\"trade\",\"E\":1788563380633,\"T\":1788563380633,\"s\":\"BTCUSDT\",\"t\":8054083452,\"p\":\"79607.20\",\"q\":\"0.002\",\"X\":\"MARKET\",\"m\":false,\"st\":1}}"}
{"receive_ns":1788563380597752000,"stream":"btcusdt@bookTicker","event_type":"bookTicker","event_time_ms":1788563380634,"raw_json":"{\"stream\":\"btcusdt@bookTicker\",\"data\":{\"e\":\"bookTicker\",\"u\":11478232697309,\"s\":\"BTCUSDT\",\"ps\":\"BTCUSDT\",\"b\":\"79607.10\",\"B\":\"5.559\",\"a\":\"79607.20\",\"A\":\"7.032\",\"T\":1788563380634,\"E\":1788563380634,\"st\":1}}"}
