{"kind": "depth", "E": 1787095366869, "U": 11316374347230, "u": 11316374353384, "recv_ms": 1787095366984, "bids": [[1000.0, 35.76], [14389.9, 0.084], [14489.9, 3.752], [14589.9, 0.364], [51752.0, 0.0], [58220.9, 0.002], [61455.4, 0.01], [62102.3, 0.833], [63689.9, 0.01], [64043.0, 0.033], [64366.4, 1.177], [64403.3, 0.026], [64548.4, 0.001], [64548.5, 4.69], [64627.0, 0.195], [64657.0, 0.005], [64657.1, 0.021], [64657.2, 0.064], [64660.5, 1.332], [64660.6, 0.028], [64660.7, 0.008], [64668.0, 0.373], [64668.1, 0.025], [64679.0, 0.961], [64679.1, 0.227], [64679.3, 2.53], [64685.5, 1.687], [64685.6, 0.243], [64687.6, 0.452], [64689.4, 0.042], [64689.9, 8.064]], "asks": [[64692.5, 0.033], [64694.0, 0.092], [64694.1, 0.452], [64694.4, 0.115], [64694.6, 1.094], [64694.8, 7.554], [64694.9, 0.164], [64713.9, 2.907], [64714.0, 0.188], [64714.2, 0.26], [64717.6, 0.001], [64717.7, 6.198], [64765.6, 1.142], [64767.9, 0.0], [64770.1, 48.937], [64778.9, 0.005], [64830.6, 3.79], [64847.5, 0.005], [64847.6, 5.527], [64886.4, 9.264], [65202.5, 0.017], [65336.9, 0.001], [65690.0, 0.413], [65983.7, 0.018]]}
{"kind": "depth", "E": 1787095366971, "U": 11316374353731, "u": 11316374360022, "recv_ms": 1787095367164, "bids": [[1000.0, 35.76], [14389.9, 0.308], [14489.9, 3.668], [14589.9, 0.224], [58220.9, 0.002], [61455.4, 0.012], [62102.3, 0.836], [63590.2, 7.224], [63649.9, 1.11], [64075.3, 7.382], [64627.3, 0.033], [64627.6, 0.032], [64628.3, 0.129], [64679.6, 0.755], [64685.5, 1.687], [64685.6, 0.005], [64687.6, 0.006], [64689.9, 8.065]], "asks": [[64692.2, 0.011], [64692.5, 0.258], [64694.0, 0.092], [64694.3, 0.24], [64694.4, 0.115], [64694.6, 1.078], [64694.7, 1.515], [64699.0, 0.107], [64713.5, 0.676], [64717.7, 6.198], [64767.9, 48.936], [64770.1, 0.001], [65336.9, 0.001], [65374.2, 3.281], [66075.6, 0.0]]}
{"kind": "depth", "E": 1787095367073, "U": 11316374360101, "u": 11316374366092, "recv_ms": 1787095367167, "bids": [[14389.9, 0.56], [14489.9, 3.528], [14589.9, 0.112], [58220.9, 0.002], [61455.4, 0.012], [62102.3, 0.833], [63287.7, 0.681], [63689.9, 0.03], [63876.5, 0.07], [63881.3, 4.679], [64043.0, 0.033], [64366.5, 0.01], [64548.5, 4.257], [64626.5, 0.396], [64628.0, 0.033], [64628.7, 0.012], [64655.7, 0.002], [64658.0, 0.028], [64659.6, 0.235], [64659.8, 0.077], [64659.9, 0.07], [64660.2, 0.301], [64660.6, 0.098], [64660.8, 1.289], [64663.1, 2.337], [64663.6, 0.382], [64665.5, 0.083], [64665.9, 2.347], [64678.3, 0.021], [64685.5, 1.687], [64685.6, 0.005], [64687.4, 0.008], [64689.8, 0.007], [64689.9, 8.063]], "asks": [[64692.2, 0.011], [64692.5, 0.033], [64694.1, 0.452], [64694.2, 0.574], [64694.7, 1.515], [64695.4, 0.314], [64699.0, 0.107], [64703.4, 2.784], [64706.2, 0.236], [64710.8, 0.393], [64717.7, 6.032], [64717.9, 0.154], [64720.0, 0.627], [64722.3, 1.498], [64724.6, 1.255], [64729.4, 0.002], [64730.3, 0.0], [64731.7, 0.331], [64732.6, 2.34], [64830.2, 1.501], [64830.6, 5.399], [64847.6, 10.409], [65207.5, 6.0], [65336.9, 0.001], [65348.3, 0.945], [65395.1, 0.691], [65591.0, 6.246], [65622.9, 1.065], [65687.6, 1.259], [65690.0, 0.433], [65708.4, 0.0]]}
{"kind": "depth", "E": 1787095367175, "U": 11316374366117, "u": 11316374371309, "recv_ms": 1787095367326, "bids": [[1000.0, 35.76], [14389.9, 0.798], [14489.9, 3.402], [14589.9, 0.0], [51752.0, 0.002], [58220.9, 0.002], [62102.3, 0.836], [63617.6, 0.002], [63654.9, 3.296], [63747.0, 3.471], [63837.2, 3.129], [63941.0, 0.158], [64043.0, 0.033], [64366.4, 1.178], [64609.3, 0.008], [64616.5, 0.012], [64621.2, 0.002], [64624.4, 0.137], [64631.6, 1.24], [64636.9, 0.001], [64637.1, 0.002], [64640.2, 0.002], [64640.3, 0.023], [64645.3, 0.003], [64645.5, 0.028], [64659.8, 0.147], [64660.1, 0.113], [64660.2, 0.358], [64660.3, 0.101], [64660.4, 4.972], [64661.3, 1.468], [64661.6, 0.128], [64662.0, 0.538], [64677.0, 3.108], [64677.7, 0.348], [64683.8, 0.236], [64684.5, 0.096], [64685.5, 1.687], [64685.6, 0.005]], "asks": [[64691.1, 0.084], [64692.5, 0.258], [64694.2, 0.455], [64695.7, 0.006], [64701.9, 0.017], [64709.4, 1.623], [64711.1, 3.303], [64713.6, 1.477], [64714.6, 0.0], [64714.7, 0.031], [64735.3, 0.267], [65013.5, 0.768], [65336.9, 0.001], [65517.1, 1.528], [65622.9, 0.0], [65752.3, 0.182]]}
{"kind": "depth", "E": 1787095367277, "U": 11316374371410, "u": 11316374376227, "recv_ms": 1787095367337, "bids": [[1000.0, 35.76], [14389.9, 1.162], [14489.9, 3.038], [51752.0, 0.0], [58220.9, 0.002], [61455.4, 0.012], [63110.6, 0.678], [63689.9, 0.01], [63755.1, 2.119], [63771.3, 0.937], [64043.0, 0.033], [64531.3, 0.0], [64531.5, 6.443], [64636.9, 0.002], [64659.7, 0.071], [64659.9, 0.14], [64660.0, 0.21], [64671.0, 0.016], [64671.3, 0.117], [64672.5, 0.038], [64673.4, 0.002], [64674.0, 2.122], [64675.0, 0.246], [64677.0, 2.649], [64677.7, 0.807], [64678.6, 0.514], [64684.3, 0.548], [64685.5, 1.806], [64685.6, 0.005], [64687.1, 0.011], [64687.9, 0.139], [64688.2, 0.001], [64689.4, 0.022], [64689.9, 8.065]], "asks": [[64692.2, 0.236], [64692.5, 0.033], [64706.2, 0.256], [64709.4, 1.164], [64710.3, 0.078], [64711.0, 3.289], [64712.5, 0.029], [64713.6, 0.806], [64714.6, 0.0], [64715.3, 0.116], [64715.5, 0.559], [64717.7, 6.032], [64717.8, 0.386], [64717.9, 0.0], [64886.4, 8.41], [65328.4, 0.111], [65336.9, 0.001], [65369.2, 0.839], [65499.2, 8.781], [65552.2, 2.877], [65587.1, 0.0], [65602.1, 2.435], [65628.0, 15.096], [65690.0, 0.413], [65692.7, 8.054], [65725.0, 3.683], [65946.3, 0.086]]}
{"kind": "depth", "E": 1787095367379, "U": 11316374376245, "u": 11316374381074, "recv_ms": 1787095367504, "bids": [[14389.9, 1.512], [14489.9, 2.688], [58220.9, 0.002], [61455.4, 0.012], [62102.3, 0.833], [63396.2, 0.011], [63881.3, 4.944], [63946.0, 10.88], [64043.0, 0.033], [64366.5, 0.0], [64548.5, 0.0], [64658.5, 0.003], [64660.4, 5.072], [64670.6, 0.478], [64671.5, 0.084], [64685.2, 2.455], [64687.1, 0.457], [64689.9, 8.064]], "asks": [[64692.2, 0.011], [64707.6, 0.011], [64717.8, 0.386], [64830.6, 0.0], [65336.9, 0.001], [65542.8, 3.054], [65720.0, 2.24]]}
{"kind": "depth", "E": 1787095367481, "U": 11316374381198, "u": 11316374385289, "recv_ms": 1787095367537, "bids": [[1000.0, 35.76], [14389.9, 1.876], [14489.9, 2.324], [51751.9, 0.0], [58220.9, 0.002], [62102.3, 0.836], [63622.5, 4.324], [63649.9, 0.012], [63689.9, 0.03], [63751.9, 12.761], [63768.1, 51.319], [63946.0, 11.817], [64043.0, 0.032], [64548.5, 4.588], [64670.7, 0.62], [64678.1, 0.84], [64687.1, 0.457], [64689.9, 8.062]], "asks": [[64691.8, 0.447], [64692.2, 0.011], [64701.6, 0.618], [64709.0, 0.629], [64718.0, 0.25], [64830.6, 5.399], [64886.4, 8.411], [64958.5, 0.125], [65336.9, 2.293], [65531.0, 3.341], [65563.3, 2.236], [65595.7, 17.546], [65628.0, 16.161], [65690.0, 0.433], [65720.0, 1.176], [65757.4, 3.19]]}
{"kind": "depth", "E": 1787095367685, "U": 11316374389218, "u": 11316374395434, "recv_ms": 1787095367750, "bids": [[14389.9, 2.576], [14489.9, 1.624], [51752.0, 0.0], [58220.9, 0.002], [61455.4, 0.012], [62102.3, 0.836], [63654.9, 4.394], [63682.3, 3.294], [63689.9, 0.01], [63747.0, 2.374], [64043.0, 0.032], [64366.5, 0.01], [64584.0, 2.915], [64584.2, 0.003], [64641.7, 0.018], [64641.8, 0.09], [64668.2, 0.155], [64685.5, 1.806], [64685.6, 0.005], [64687.1, 0.011], [64687.6, 0.006], [64689.9, 8.064]], "asks": [[64690.0, 8.814], [64692.2, 0.012], [64694.1, 0.214], [64694.2, 0.336], [64701.6, 0.0], [64875.1, 0.001], [64875.3, 2.582], [65336.9, 2.295], [65690.0, 0.413], [65725.0, 5.811]]}
{"kind": "depth", "E": 1787095367787, "U": 11316374395444, "u": 11316374405006, "recv_ms": 1787095367851, "bids": [[1000.0, 35.76], [14389.9, 2.94], [14489.9, 1.26], [51752.0, 0.0], [58220.9, 0.002], [61455.4, 0.013], [63513.7, 1.572], [63689.9, 0.03], [63784.2, 8.066], [64043.0, 0.036], [64548.5, 0.0], [64548.6, 5.109], [64657.9, 1.009], [64669.4, 2.026], [64673.5, 3.822], [64683.8, 0.004], [64684.2, 1.115], [64684.3, 0.007], [64684.5, 0.012], [64684.9, 0.322], [64685.5, 2.585], [64685.6, 0.005], [64686.1, 0.0], [64686.6, 0.247], [64687.6, 0.006], [64687.7, 0.446], [64688.4, 0.085], [64688.8, 0.087], [64689.2, 0.084], [64689.4, 0.042], [64689.7, 0.086], [64689.9, 8.713]], "asks": [[64690.0, 7.073], [64690.1, 0.01], [64691.1, 0.002], [64691.6, 0.002], [64692.3, 0.315], [64694.0, 0.092], [64694.7, 1.422], [64695.4, 0.004], [64695.7, 0.09], [64699.0, 0.2], [64706.0, 0.389], [64709.0, 0.011], [64714.4, 0.174], [64718.0, 0.096], [64723.2, 0.103], [64765.6, 8.237], [64793.0, 0.002], [64830.6, 3.857], [64847.6, 5.644], [64886.4, 9.785], [65336.9, 2.295], [65616.9, 5.38], [65646.5, 0.0], [65649.3, 5.403], [65672.1, 1.52], [65690.0, 0.433]]}
{"kind": "depth", "E": 1787095367889, "U": 11316374405119, "u": 11316374431733, "recv_ms": 1787095367947, "bids": [[14389.9, 3.29], [14489.9, 0.91], [58220.9, 0.002], [61455.4, 0.011], [61455.5, 0.004], [62102.3, 0.833], [63396.2, 0.014], [63687.2, 9.49], [63751.9, 13.858], [64043.0, 0.032], [64167.4, 0.621], [64361.5, 0.316], [64366.4, 1.177], [64512.3, 0.003], [64608.6, 0.013], [64611.6, 0.0], [64619.7, 0.001], [64620.9, 0.026], [64625.2, 0.002], [64625.7, 6.356], [64632.9, 0.0], [64637.8, 0.0], [64638.0, 0.017], [64638.1, 4.924], [64638.2, 0.427], [64643.7, 0.07], [64643.9, 0.385], [64645.2, 0.213], [64646.7, 0.025], [64650.4, 0.037], [64651.1, 0.01], [64653.4, 0.013], [64653.8, 0.435], [64654.3, 0.0], [64654.8, 0.002], [64662.8, 0.107], [64664.2, 0.02], [64664.3, 0.004], [64664.6, 0.012], [64665.1, 0.417], [64665.4, 0.039], [64665.5, 0.083], [64665.9, 2.341], [64666.3, 0.046], [64668.5, 1.004], [64669.4, 0.006], [64671.3, 0.133], [64671.8, 0.008], [64673.3, 8.119], [64676.2, 0.062], [64682.1, 2.38], [64682.3, 0.032], [64684.2, 0.883], [64684.4, 0.315], [64684.6, 0.004], [64684.7, 0.0], [64685.2, 2.687], [64685.4, 1.55], [64685.5, 0.642], [64685.6, 0.481], [64686.1, 0.001], [64686.6, 0.244], [64686.9, 0.014], [64687.1, 0.014], [64687.4, 0.005], [64687.6, 0.099], [64687.7, 0.0], [64688.9, 0.005], [64689.4, 0.022], [64689.5, 0.31], [64689.6, 0.095], [64689.7, 0.003], [64689.9, 8.808]], "asks": [[64690.0, 4.44], [64690.5, 0.002], [64691.1, 0.0], [64691.7, 0.226], [64692.2, 0.011], [64692.3, 0.001], [64692.4, 0.002], [64692.5, 0.036], [64692.7, 0.003], [64693.1, 0.367], [64693.2, 0.225], [64693.3, 0.066], [64693.8, 0.005], [64694.0, 0.33], [64694.1, 0.571], [64694.2, 0.49], [64694.4, 0.114], [64694.5, 0.257], [64694.6, 0.835], [64695.0, 0.103], [64695.1, 0.01], [64695.3, 0.001], [64695.7, 0.086], [64696.1, 0.366], [64696.4, 0.412], [64696.8, 0.086], [64697.2, 0.088], [64697.5, 0.191], [64697.9, 0.087], [64698.2, 0.247], [64699.0, 0.176], [64699.1, 0.431], [64700.7, 0.004], [64700.8, 0.009], [64701.0, 2.364], [64702.0, 0.004], [64702.9, 1.401], [64703.0, 0.047], [64704.3, 2.283], [64704.8, 0.036], [64705.1, 0.003], [64706.2, 0.256], [64706.3, 0.019], [64706.8, 0.014], [64707.2, 0.09], [64707.3, 0.061], [64708.7, 0.007], [64709.2, 0.869], [64709.7, 0.887], [64710.4, 0.169], [64712.4, 0.408], [64712.5, 0.023], [64713.5, 0.711], [64713.9, 1.747], [64716.4, 0.393], [64716.9, 0.033], [64717.8, 0.336], [64718.0, 0.096], [64721.2, 0.003], [64723.0, 0.108], [64724.4, 0.45], [64726.3, 11.324], [64727.9, 0.781], [64729.0, 0.021], [64729.3, 0.154], [64733.5, 1.501], [64735.9, 0.028], [64737.9, 0.026], [64740.0, 2.68], [64749.5, 0.017], [64752.3, 0.018], [64752.4, 2.609], [64752.5, 0.006], [64761.7, 0.033], [64762.8, 0.119], [64765.6, 1.142], [64767.9, 0.0], [64778.9, 48.941], [64830.2, 2.116], [64830.6, 3.858], [64847.6, 5.645], [65011.4, 3.228], [65205.5, 3.061], [65336.9, 2.293], [65983.7, 0.015]]}
{"kind": "depth", "E": 1787095367991, "U": 11316374431765, "u": 11316374458189, "recv_ms": 1787095368092, "bids": [[14389.9, 3.654], [14489.9, 0.546], [58220.9, 0.002], [61455.4, 0.011], [62102.3, 0.836], [63689.9, 0.01], [64043.0, 0.032], [64107.7, 17.6], [64366.5, 0.0], [64620.9, 0.0], [64623.4, 0.029], [64628.7, 0.0], [64629.9, 0.0], [64630.4, 0.046], [64638.2, 0.422], [64639.8, 1.503], [64643.7, 0.01], [64646.2, 0.444], [64646.4, 0.259], [64650.9, 0.003], [64657.8, 6.19], [64658.0, 0.01], [64658.1, 0.064], [64659.7, 0.09], [64660.2, 0.301], [64663.1, 2.322], [64663.9, 1.708], [64664.8, 0.247], [64665.1, 0.347], [64665.9, 2.321], [64666.3, 0.04], [64666.4, 1.708], [64667.6, 0.028], [64668.4, 0.169], [64668.7, 0.313], [64669.0, 0.905], [64670.4, 1.431], [64670.7, 0.002], [64671.3, 0.001], [64671.7, 1.143], [64672.1, 0.026], [64672.3, 0.005], [64672.4, 0.0], [64672.7, 2.0], [64673.1, 0.0], [64673.3, 0.121], [64673.5, 3.82], [64673.6, 1.347], [64673.7, 0.313], [64674.0, 1.565], [64674.1, 0.124], [64674.5, 0.013], [64674.9, 0.031], [64675.3, 0.002], [64676.2, 0.069], [64676.8, 0.562], [64677.4, 0.023], [64677.6, 0.052], [64677.7, 0.348], [64678.1, 0.222], [64678.2, 0.0], [64678.6, 0.534], [64679.1, 0.22], [64679.4, 0.202], [64679.5, 0.072], [64679.7, 0.927], [64679.8, 0.562], [64680.4, 0.0], [64680.7, 0.002], [64681.1, 0.034], [64681.7, 0.333], [64682.1, 2.385], [64682.3, 0.024], [64682.5, 1.565], [64682.6, 0.029], [64682.7, 0.001], [64682.8, 0.009], [64683.3, 0.534], [64683.4, 0.01], [64683.7, 0.011], [64684.0, 0.003], [64684.1, 0.025], [64684.3, 0.456], [64684.7, 0.0], [64684.9, 0.321], [64685.0, 0.168], [64685.1, 0.0], [64685.2, 2.455], [64685.3, 0.086], [64685.4, 0.005], [64685.5, 0.024], [64685.6, 0.005], [64685.7, 0.066], [64685.8, 0.086], [64685.9, 0.007], [64686.0, 0.003], [64686.1, 0.001], [64686.2, 0.003], [64686.8, 0.726], [64686.9, 0.555], [64687.0, 0.366], [64687.1, 0.011], [64687.6, 0.096], [64688.9, 0.008], [64689.7, 0.003], [64689.8, 0.008], [64689.9, 23.867]], "asks": [[64690.0, 2.214], [64690.1, 0.01], [64690.7, 0.001], [64691.2, 0.002], [64691.7, 0.0], [64691.8, 0.003], [64692.0, 0.063], [64692.1, 0.032], [64692.4, 0.003], [64692.5, 0.034], [64692.6, 0.263], [64692.9, 0.004], [64693.1, 0.367], [64693.2, 0.223], [64693.3, 0.054], [64693.7, 0.05], [64693.9, 0.131], [64694.0, 0.092], [64694.1, 0.209], [64694.2, 0.252], [64694.4, 0.116], [64694.5, 0.253], [64694.6, 0.297], [64694.7, 1.42], [64694.9, 0.169], [64695.1, 0.005], [64695.3, 0.005], [64695.5, 0.001], [64695.7, 0.002], [64695.8, 0.002], [64695.9, 0.124], [64696.1, 0.162], [64696.3, 0.084], [64696.4, 0.018], [64696.6, 0.017], [64696.8, 0.086], [64697.1, 0.308], [64697.4, 0.142], [64697.7, 0.047], [64698.0, 0.344], [64698.2, 0.247], [64698.6, 0.086], [64698.7, 0.002], [64698.8, 0.004], [64698.9, 0.599], [64699.0, 0.26], [64699.3, 10.074], [64699.4, 0.377], [64699.7, 0.005], [64699.9, 0.206], [64700.0, 2.933], [64700.1, 0.002], [64700.5, 0.001], [64700.6, 0.449], [64700.8, 2.328], [64700.9, 2.852], [64701.0, 2.361], [64701.1, 0.477], [64701.8, 0.311], [64702.1, 1.721], [64703.0, 0.947], [64703.4, 2.939], [64703.5, 0.086], [64703.6, 1.771], [64703.9, 0.035], [64706.0, 0.382], [64707.5, 0.027], [64708.7, 0.014], [64709.2, 0.251], [64709.7, 0.885], [64710.9, 0.625], [64711.0, 2.83], [64711.9, 0.165], [64712.1, 0.05], [64712.4, 0.402], [64712.7, 0.02], [64712.8, 2.726], [64712.9, 0.57], [64713.2, 0.234], [64713.3, 0.109], [64713.6, 0.807], [64714.1, 0.642], [64715.3, 0.001], [64715.5, 0.003], [64715.7, 0.048], [64715.8, 0.184], [64715.9, 0.767], [64716.6, 0.002], [64716.9, 0.116], [64717.0, 2.798], [64717.2, 0.054], [64717.6, 0.008], [64718.0, 0.003], [64718.1, 0.001], [64718.2, 0.014], [64718.4, 1.664], [64720.0, 0.615], [64721.6, 1.379], [64723.2, 0.01], [64724.4, 0.4], [64724.6, 1.237], [64726.1, 0.312], [64726.3, 1.345], [64726.4, 4.254], [64728.7, 0.025], [64731.7, 0.316], [64732.6, 2.32], [64732.7, 0.075], [64732.8, 0.215], [64732.9, 0.026], [64733.4, 0.015], [64733.9, 1.04], [64734.3, 0.276], [64735.9, 0.003], [64740.0, 2.47], [64740.4, 1.355], [64746.8, 3.093], [64752.5, 0.001], [64753.3, 1.96], [64754.1, 0.015], [64762.8, 0.093], [64765.4, 0.403], [64766.1, 0.31], [64770.1, 48.793], [64778.9, 0.005], [64794.9, 0.151], [64830.6, 3.791], [64847.6, 5.528], [65013.5, 0.769], [65336.9, 2.295], [65517.1, 1.223], [65517.2, 0.308], [65616.9, 4.315], [65628.0, 17.074], [65660.4, 3.81], [65690.0, 0.413]]}
{"kind": "depth", "E": 1787095368093, "U": 11316374458284, "u": 11316374489240, "recv_ms": 1787095368153, "bids": [[1000.0, 35.76], [14289.9, 0.126], [14389.9, 3.752], [14489.9, 0.322], [58220.9, 0.002], [61455.4, 0.01], [62102.3, 0.833], [63706.1, 0.38], [63770.9, 0.0], [63772.1, 0.0], [63837.2, 3.911], [63964.3, 4.176], [64043.0, 0.034], [64167.4, 0.31], [64172.4, 3.453], [64545.0, 0.013], [64559.1, 0.037], [64569.3, 0.0], [64584.2, 0.0], [64584.3, 0.03], [64594.3, 0.036], [64620.7, 0.028], [64623.4, 0.003], [64624.0, 2.326], [64625.1, 6.293], [64625.7, 1.682], [64629.5, 33.073], [64629.6, 6.419], [64631.8, 4.681], [64639.6, 0.09], [64639.8, 1.498], [64639.9, 0.005], [64640.2, 0.001], [64645.7, 0.032], [64646.7, 0.0], [64657.1, 0.046], [64658.1, 0.004], [64659.6, 0.235], [64662.8, 0.074], [64662.9, 0.207], [64663.0, 0.069], [64663.9, 1.651], [64665.0, 0.004], [64665.1, 0.417], [64666.1, 0.421], [64666.7, 0.051], [64667.3, 0.061], [64668.7, 0.312], [64669.3, 0.469], [64670.0, 0.696], [64671.0, 0.065], [64673.0, 0.283], [64673.3, 0.119], [64673.5, 3.822], [64673.6, 1.277], [64673.7, 0.312], [64674.1, 0.008], [64675.0, 0.253], [64675.9, 0.569], [64676.2, 0.062], [64676.5, 1.314], [64676.8, 0.005], [64677.1, 0.097], [64677.6, 0.003], [64678.2, 0.001], [64678.3, 0.021], [64678.5, 0.596], [64679.0, 1.42], [64679.4, 0.209], [64679.7, 0.309], [64679.8, 0.103], [64680.3, 0.023], [64680.8, 0.042], [64681.0, 0.904], [64681.7, 0.003], [64682.1, 2.378], [64682.6, 0.106], [64682.7, 0.001], [64682.8, 0.017], [64684.1, 0.015], [64684.2, 1.233], [64684.3, 0.02], [64684.5, 0.012], [64684.8, 0.01], [64685.3, 0.627], [64685.4, 0.006], [64685.7, 0.062], [64686.9, 0.014], [64687.3, 0.316], [64687.5, 0.382], [64687.9, 0.142], [64688.0, 0.003], [64688.3, 0.0], [64688.5, 0.0], [64688.8, 0.091], [64688.9, 0.005], [64689.5, 0.0], [64689.6, 0.0], [64689.7, 0.002], [64689.8, 0.052], [64689.9, 23.672]], "asks": [[64690.0, 4.395], [64691.5, 0.084], [64691.6, 0.117], [64692.4, 0.003], [64692.5, 0.034], [64693.0, 0.22], [64693.1, 1.334], [64693.7, 0.281], [64693.8, 0.243], [64693.9, 1.58], [64694.0, 0.094], [64694.1, 0.21], [64694.2, 0.252], [64694.3, 0.24], [64694.4, 1.753], [64694.5, 0.885], [64694.7, 1.418], [64694.9, 0.257], [64695.0, 0.103], [64695.2, 0.007], [64695.4, 0.004], [64695.6, 0.084], [64695.9, 0.124], [64696.1, 0.002], [64696.3, 0.394], [64697.1, 0.068], [64697.4, 0.14], [64697.6, 0.245], [64697.8, 0.002], [64698.0, 0.342], [64698.2, 0.163], [64698.6, 0.002], [64698.8, 0.007], [64698.9, 0.076], [64699.0, 0.176], [64699.1, 0.671], [64699.3, 9.99], [64699.7, 1.005], [64699.8, 0.007], [64700.0, 2.931], [64700.8, 2.328], [64701.2, 0.31], [64701.8, 0.002], [64702.1, 0.721], [64703.0, 0.927], [64704.3, 2.284], [64706.5, 0.001], [64707.2, 0.01], [64708.0, 1.284], [64709.2, 0.291], [64709.5, 0.002], [64710.2, 0.274], [64710.6, 0.127], [64711.0, 2.87], [64711.4, 0.482], [64712.1, 0.052], [64712.2, 0.167], [64712.6, 0.386], [64712.9, 0.111], [64716.1, 0.314], [64717.6, 0.101], [64717.7, 6.341], [64718.4, 1.355], [64720.0, 0.566], [64723.2, 0.103], [64729.5, 10.006], [64729.9, 5.24], [64732.7, 0.015], [64733.2, 0.276], [64740.7, 0.073], [64743.2, 0.004], [64754.1, 0.01], [64754.2, 0.06], [64765.4, 0.377], [64767.1, 0.027], [64788.5, 0.381], [64830.6, 3.858], [64847.6, 5.645], [64886.4, 9.786], [65011.4, 3.074], [65207.5, 6.306], [65336.9, 2.293], [65482.0, 14.578], [65498.6, 5.409], [65531.0, 3.646], [65607.8, 0.008], [65609.1, 0.001], [65664.5, 0.342], [65673.8, 0.018], [65983.7, 0.018]]}
{"kind": "depth", "E": 1787095368195, "U": 11316374489279, "u": 11316374499138, "recv_ms": 1787095368252, "bids": [[14289.9, 0.364], [14389.9, 3.64], [14489.9, 0.196], [51752.0, 0.0], [58220.9, 0.002], [61455.4, 0.01], [63689.9, 0.03], [63692.0, 0.031], [63706.1, 0.388], [63770.9, 0.008], [63772.1, 0.008], [63821.5, 0.782], [64043.0, 0.032], [64172.4, 7.342], [64366.4, 1.176], [64366.5, 0.155], [64600.4, 0.002], [64600.5, 2.359], [64609.0, 6.957], [64609.2, 0.381], [64609.3, 0.005], [64616.2, 2.323], [64620.7, 33.068], [64621.2, 0.001], [64629.5, 0.033], [64629.6, 1.166], [64636.6, 0.001], [64636.9, 0.0], [64637.8, 0.21], [64639.9, 0.006], [64640.0, 0.029], [64640.2, 0.0], [64645.1, 0.003], [64645.2, 0.003], [64645.3, 0.001], [64660.0, 0.27], [64665.0, 0.003], [64667.0, 0.35], [64667.3, 0.001], [64668.4, 8.171], [64670.3, 0.003], [64674.3, 0.326], [64674.9, 0.016], [64676.0, 1.199], [64678.6, 0.251], [64679.4, 0.202], [64681.4, 0.324], [64682.0, 0.01], [64682.6, 0.654], [64683.4, 0.456], [64686.8, 0.958], [64687.3, 0.084], [64687.4, 0.01], [64687.5, 0.385], [64687.9, 0.139], [64688.0, 0.007], [64689.7, 0.003], [64689.8, 0.053], [64689.9, 23.662]], "asks": [[64690.0, 5.593], [64691.5, 0.007], [64691.6, 0.136], [64692.3, 0.311], [64692.5, 0.034], [64692.9, 0.088], [64693.0, 0.018], [64693.1, 1.096], [64693.6, 0.084], [64693.7, 0.043], [64693.8, 0.088], [64694.1, 0.329], [64694.4, 1.754], [64695.3, 0.009], [64696.1, 0.007], [64697.5, 0.107], [64697.6, 0.246], [64697.9, 0.003], [64699.9, 0.331], [64705.4, 0.131], [64711.7, 0.063], [64712.2, 0.118], [64719.4, 0.145], [64723.0, 0.094], [64730.6, 0.04], [64805.6, 0.0], [64830.6, 5.399], [64847.6, 10.409], [64886.4, 8.413], [65013.4, 0.769], [65207.5, 6.611], [65336.9, 2.293], [65535.1, 0.916], [65628.0, 18.138], [65690.0, 0.433]]}
{"kind": "depth", "E": 1787095368297, "U": 11316374499302, "u": 11316374509655, "recv_ms": 1787095368355, "bids": [[14289.9, 0.616], [14389.9, 3.5], [14489.9, 0.084], [51752.0, 0.0], [58220.9, 0.002], [61455.4, 0.01], [62102.3, 0.836], [63881.3, 5.178], [64043.0, 0.032], [64366.5, 0.165], [64654.7, 0.001], [64656.7, 0.026], [64657.8, 6.192], [64661.0, 0.057], [64662.8, 0.017], [64667.2, 9.316], [64668.4, 0.171], [64670.7, 0.004], [64671.7, 1.141], [64671.8, 0.124], [64672.7, 0.0], [64673.0, 0.167], [64674.2, 0.557], [64675.9, 0.012], [64677.8, 0.459], [64679.0, 0.961], [64679.8, 0.11], [64680.8, 0.035], [64683.4, 0.456], [64684.8, 0.011], [64685.4, 0.003], [64687.0, 0.369], [64687.2, 0.009], [64687.4, 0.005], [64687.5, 0.382], [64687.6, 0.003], [64688.0, 0.008], [64689.2, 0.0], [64689.9, 22.078]], "asks": [[64690.0, 7.824], [64691.4, 0.0], [64691.5, 0.007], [64691.6, 0.22], [64692.0, 0.064], [64692.1, 0.116], [64692.2, 0.012], [64692.4, 0.086], [64693.1, 0.892], [64693.5, 0.02], [64693.8, 0.326], [64694.1, 0.21], [64694.2, 0.252], [64694.4, 0.114], [64694.8, 7.557], [64695.8, 0.312], [64696.1, 0.002], [64696.3, 0.31], [64696.8, 0.002], [64697.2, 0.004], [64706.3, 0.054], [64709.7, 0.887], [64712.1, 0.05], [64713.0, 0.059], [64713.5, 0.676], [64715.8, 0.127], [64716.0, 0.016], [64717.6, 0.094], [64718.6, 0.042], [64720.7, 0.07], [64723.2, 4.103], [64727.9, 0.711], [64729.5, 0.006], [64781.6, 1.279], [64830.6, 5.399], [64847.6, 10.409], [64886.4, 8.315], [65013.5, 0.924], [65205.5, 2.755], [65336.9, 2.293], [65464.3, 5.028], [65607.8, 0.016], [65609.1, 0.009], [65626.0, 2.136], [65673.8, 0.026], [65690.7, 1.064]]}
{"kind": "depth", "E": 1787095368399, "U": 11316374509811, "u": 11316374516899, "recv_ms": 1787095368456, "bids": [[1000.0, 35.76], [14289.9, 0.882], [14389.9, 3.318], [14489.9, 0.0], [58220.9, 0.002], [61455.4, 0.01], [62102.3, 0.833], [63689.9, 0.01], [63984.8, 2.502], [64043.0, 0.032], [64172.4, 7.653], [64361.5, 0.161], [64620.7, 0.028], [64625.1, 39.333], [64631.6, 1.237], [64673.9, 2.326], [64675.0, 0.246], [64682.6, 0.63], [64682.7, 0.041], [64682.8, 0.001], [64683.4, 0.01], [64685.0, 0.171], [64686.3, 0.416], [64686.8, 0.726], [64689.9, 22.183]], "asks": [[64690.0, 7.039], [64691.6, 0.136], [64693.8, 0.313], [64694.8, 7.554], [64702.0, 0.904], [64718.5, 0.59], [64719.2, 0.532], [64735.3, 0.264], [64747.0, 0.009], [64925.7, 0.0], [64990.3, 0.001], [65011.4, 2.92], [65336.9, 2.293], [65466.3, 20.111], [65517.2, 0.003], [65608.6, 0.687], [65690.0, 0.413], [65983.7, 0.021]]}
{"kind": "depth", "E": 1787095368501, "U": 11316374516936, "u": 11316374522686, "recv_ms": 1787095368558, "bids": [[14289.9, 1.246], [14389.9, 2.954], [51751.9, 0.0], [58220.9, 0.002], [61455.4, 0.01], [62102.3, 0.836], [63678.9, 0.055], [63682.3, 2.197], [64043.0, 0.032], [64167.4, 0.0], [64631.6, 1.24], [64661.0, 0.0], [64662.3, 0.563], [64663.7, 0.367], [64671.5, 0.702], [64677.8, 0.0], [64678.8, 0.62], [64680.4, 0.459], [64684.3, 0.139], [64685.3, 0.086], [64685.4, 0.449], [64686.9, 0.555], [64689.2, 0.084], [64689.7, 0.087], [64689.9, 22.194]], "asks": [[64690.0, 4.406], [64692.1, 0.032], [64692.3, 0.001], [64692.4, 0.002], [64692.9, 0.004], [64693.2, 0.307], [64693.8, 0.088], [64695.8, 0.002], [64696.3, 0.394], [64697.4, 0.125], [64700.9, 2.81], [64701.0, 2.361], [64702.0, 0.004], [64708.4, 1.008], [64711.4, 0.023], [64713.0, 0.002], [64713.8, 0.588], [64714.1, 0.642], [64714.9, 0.185], [64715.6, 2.448], [64716.0, 0.009], [64717.3, 0.007], [64728.7, 0.05], [64735.3, 0.267], [64737.9, 0.001], [65054.9, 0.0], [65336.9, 2.295], [65461.5, 0.02], [65628.0, 19.203], [65692.7, 9.118]]}
{"kind": "depth", "E": 1787095368603, "U": 11316374522697, "u": 11316374529689, "recv_ms": 1787095368661, "bids": [[14289.9, 1.596], [14389.9, 2.604], [51752.0, 0.0], [58220.9, 0.002], [61455.4, 0.01], [62102.3, 0.833], [63396.2, 0.011], [63679.0, 0.032], [63747.0, 1.278], [63749.0, 2.196], [64043.0, 0.032], [64366.5, 0.155], [64625.1, 39.333], [64627.3, 0.033], [64646.4, 0.258], [64669.0, 0.005], [64674.0, 1.58], [64674.3, 0.311], [64675.4, 0.013], [64676.0, 2.099], [64679.6, 1.214], [64680.4, 0.0], [64680.9, 0.147], [64684.3, 0.377], [64684.5, 0.131], [64685.3, 0.532], [64685.4, 0.004], [64686.3, 0.184], [64687.1, 0.243], [64689.7, 0.088], [64689.9, 22.195]], "asks": [[64690.0, 4.4], [64691.2, 0.003], [64693.0, 0.03], [64693.2, 0.223], [64693.6, 0.0], [64694.1, 0.126], [64696.7, 0.084], [64697.0, 0.102], [64697.4, 0.209], [64698.5, 0.31], [64701.6, 0.02], [64712.0, 3.521], [64712.8, 3.185], [64713.6, 0.806], [64713.8, 0.129], [64759.1, 48.812], [64770.1, 0.001], [64800.6, 0.024], [64803.0, 17.004], [64808.1, 0.023], [64810.5, 0.0], [64836.5, 0.0], [64836.6, 0.0], [64840.8, 21.247], [64874.9, 0.441], [64875.4, 0.0], [64878.8, 9.288], [64879.6, 23.834], [64989.9, 0.112], [65100.5, 0.493], [65119.5, 0.005], [65336.9, 2.293], [65626.0, 1.071]]}
{"kind": "depth", "E": 1787095368807, "U": 11316374535258, "u": 11316374544398, "recv_ms": 1787095368864, "bids": [[14289.9, 2.31], [14389.9, 1.89], [58220.9, 0.002], [62102.3, 0.836], [63396.2, 0.014], [64043.0, 0.032], [64172.4, 7.963], [64651.0, 0.046], [64664.1, 1.658], [64671.5, 0.084], [64673.5, 3.822], [64678.8, 0.002], [64684.3, 0.258], [64684.5, 0.012], [64685.3, 0.532], [64685.4, 0.004], [64689.9, 22.201]], "asks": [[64690.0, 3.917], [64691.6, 0.002], [64692.2, 0.011], [64693.0, 0.031], [64693.1, 1.117], [64693.6, 0.0], [64693.7, 0.127], [64693.8, 0.088], [64701.6, 0.0], [64701.8, 0.025], [64706.0, 0.382], [64713.1, 0.005], [64748.1, 1.001], [64759.0, 8.596], [64875.3, 2.507], [64875.4, 0.003], [64977.0, 5.977], [65011.4, 2.766], [65054.6, 1.417], [65336.9, 2.293], [66092.2, 0.95], [71159.0, 0.002]]}
{"kind": "depth", "E": 1787095368909, "U": 11316374544468, "u": 11316374550799, "recv_ms": 1787095368970, "bids": [[14289.9, 2.66], [14389.9, 1.54], [58220.9, 0.002], [61455.4, 0.008], [61455.5, 0.006], [62102.3, 0.833], [63687.2, 12.783], [63689.9, 0.01], [63751.9, 16.051], [64043.0, 0.034], [64366.4, 1.331], [64366.5, 0.31], [64548.6, 0.419], [64662.6, 0.06], [64663.7, 0.31], [64684.3, 0.02], [64685.3, 1.073], [64686.9, 0.014], [64689.9, 22.183]], "asks": [[64690.0, 5.105], [64693.0, 0.031], [64693.1, 0.976], [64697.4, 0.125], [64830.6, 0.0], [65013.5, 1.077], [65119.3, 0.112], [65336.9, 2.293], [65628.0, 20.268], [65690.0, 0.413]]}
{"kind": "depth", "E": 1787095369011, "U": 11316374550812, "u": 11316374556311, "recv_ms": 1787095369068, "bids": [[1000.0, 35.76], [14289.9, 3.024], [14389.9, 1.176], [58220.9, 0.002], [61455.4, 0.008], [62102.3, 0.836], [63126.2, 1.356], [63396.2, 0.017], [63741.1, 8.632], [63771.3, 1.171], [64043.0, 0.032], [64366.4, 1.332], [64548.7, 5.084], [64632.5, 0.319], [64641.9, 6.028], [64642.4, 2.407], [64671.8, 0.008], [64673.1, 0.116], [64674.2, 0.0], [64675.5, 0.558], [64683.1, 0.675], [64684.3, 0.466], [64685.3, 0.627], [64685.9, 0.239], [64687.1, 0.011], [64689.9, 22.184]], "asks": [[64692.8, 0.062], [64695.2, 0.0], [64699.6, 0.369], [64701.2, 0.001], [64701.7, 0.02], [64709.2, 0.909], [64710.9, 0.007], [64715.8, 0.683], [64715.9, 0.882], [64716.9, 0.001], [64717.0, 2.242], [64808.3, 0.475], [64810.7, 0.09], [64830.6, 5.399], [64886.4, 8.116], [65184.0, 0.184], [65336.9, 2.293], [65611.4, 17.085], [65687.4, 0.0]]}
{"kind": "depth", "E": 1787095369113, "U": 11316374556504, "u": 11316374562043, "recv_ms": 1787095369170, "bids": [[14289.9, 3.374], [14389.9, 0.826], [58220.9, 0.002], [62102.3, 0.833], [63619.7, 0.005], [63689.9, 0.03], [63751.9, 16.364], [64043.0, 0.032], [64054.8, 4.962], [64446.8, 0.013], [64485.8, 0.007], [64600.6, 4.107], [64609.2, 0.383], [64678.3, 0.021], [64684.3, 0.02]], "asks": [[64886.4, 8.05], [64904.7, 0.319], [65013.4, 0.923], [65207.5, 6.917], [65336.9, 2.295], [65690.0, 0.433], [65690.7, 0.0], [65723.0, 0.216], [65755.4, 0.0], [65962.8, 0.649]]}
{"kind": "depth", "E": 1787095369215, "U": 11316374562119, "u": 11316374567234, "recv_ms": 1787095369271, "bids": [[1000.0, 35.76], [14189.9, 0.014], [14289.9, 3.71], [14389.9, 0.476], [58220.9, 0.002], [61455.4, 0.008], [64043.0, 0.032], [64323.7, 0.423], [64366.5, 0.32], [64420.4, 0.003], [64421.7, 0.249], [64491.3, 0.001], [64492.6, 3.285], [64548.7, 0.394], [64609.2, 0.384], [64616.4, 0.002], [64636.8, 1.516], [64640.1, 0.007], [64645.3, 0.002], [64679.7, 0.328], [64684.3, 0.02], [64685.4, 0.004], [64689.9, 22.185]], "asks": [[64690.8, 0.023], [64690.9, 0.206], [64693.8, 0.313], [64698.8, 0.008], [64701.9, 0.016], [64830.2, 1.501], [64830.6, 0.0], [64887.9, 26.376], [64959.3, 0.077], [65013.5, 1.076], [65056.7, 0.007], [65336.9, 2.293], [65396.8, 3.056], [65526.2, 0.763]]}
{"kind": "depth", "E": 1787095369317, "U": 11316374567310, "u": 11316374575688, "recv_ms": 1787095369376, "bids": [[1000.0, 35.76], [14189.9, 0.196], [14289.9, 3.71], [14389.9, 0.294], [51752.0, 0.0], [58220.9, 0.002], [61455.4, 0.01], [62102.3, 0.836], [63622.5, 5.423], [63689.9, 0.01], [63747.0, 0.181], [63853.9, 0.782], [64043.0, 0.032], [64100.1, 4.342], [64300.1, 13.342], [64323.8, 0.021], [64324.9, 0.758], [64366.4, 1.333], [64531.5, 0.0], [64531.7, 6.645], [64548.7, 5.084], [64579.9, 0.003], [64672.1, 0.041], [64674.0, 1.565], [64680.7, 0.311], [64681.4, 0.015], [64683.7, 0.026], [64684.1, 0.0], [64684.3, 0.02], [64685.4, 0.004], [64688.2, 0.001], [64689.7, 0.004], [64689.9, 22.083]], "asks": [[64690.0, 7.174], [64692.2, 0.321], [64692.5, 0.118], [64693.0, 0.031], [64693.8, 0.23], [64694.6, 0.38], [64694.7, 1.418], [64695.8, 0.312], [64697.0, 0.018], [64703.0, 0.914], [64705.4, 0.144], [64708.4, 0.39], [64712.4, 0.39], [64715.9, 0.885], [64716.2, 0.043], [64767.7, 0.003], [64830.6, 5.399], [64847.6, 10.409], [65056.6, 0.576], [65336.9, 2.293], [65482.0, 14.32], [65607.4, 2.284], [65690.0, 0.413], [65725.0, 6.875], [65757.4, 4.253]]}
{"kind": "depth", "E": 1787095369419, "U": 11316374575706, "u": 11316374581616, "recv_ms": 1787095369479, "bids": [[14189.9, 0.42], [14289.9, 3.612], [14389.9, 0.168], [51752.0, 0.0], [58220.9, 0.002], [62102.3, 0.833], [64043.0, 0.032], [64060.9, 0.001], [64075.3, 8.082], [64208.6, 0.0], [64689.7, 0.003]], "asks": [[64693.8, 0.23], [65176.2, 0.001], [65325.6, 0.007], [65336.9, 2.293], [65692.7, 10.182]]}
{"kind": "depth", "E": 1787095369521, "U": 11316374581726, "u": 11316374586677, "recv_ms": 1787095369578, "bids": [[1000.0, 35.76], [14189.9, 0.658], [14289.9, 3.486], [14389.9, 0.056], [51751.9, 0.0], [58220.9, 0.002], [61455.4, 0.01], [62102.3, 0.836], [63689.9, 0.03], [64043.0, 0.032], [64324.9, 0.009], [64325.7, 37.743], [64325.8, 6.395], [64366.5, 0.32], [64422.4, 30.904], [64425.0, 5.921], [64493.3, 24.671], [64495.7, 4.744], [64548.7, 5.084], [64584.3, 0.027], [64584.5, 0.072], [64625.2, 0.02], [64671.5, 0.702], [64678.8, 0.62], [64681.2, 1.576], [64684.9, 0.405], [64688.8, 0.007], [64689.2, 0.0], [64689.8, 0.032], [64689.9, 22.08]], "asks": [[64690.0, 7.359], [64691.6, 0.086], [64693.8, 0.005], [64696.7, 0.0], [64701.0, 2.979], [64708.4, 1.008], [64830.6, 5.399], [64875.4, 0.0], [64875.6, 0.004], [64886.4, 8.051], [64890.5, 23.892], [64960.2, 4.609], [64961.9, 29.659], [65059.3, 37.455], [65336.9, 2.293], [65690.0, 0.433]]}
{"kind": "depth", "E": 1787095369623, "U": 11316374586753, "u": 11316374600184, "recv_ms": 1787095369681, "bids": [[1000.0, 35.76], [14189.9, 0.966], [14289.9, 3.234], [14389.9, 0.0], [58220.9, 0.002], [61455.4, 0.01], [63751.9, 17.461], [64043.0, 0.032], [64100.1, 0.022], [64209.9, 48.992], [64300.1, 16.798], [64325.8, 7.259], [64657.0, 0.003], [64657.1, 0.044], [64657.2, 0.062], [64660.5, 1.33], [64660.6, 0.096], [64660.7, 0.006], [64688.0, 0.004], [64689.9, 22.081]], "asks": [[64830.6, 3.773], [64847.6, 5.496], [65176.5, 45.249], [65336.9, 2.293]]}
{"kind": "depth", "E": 1787095369725, "U": 11316374600375, "u": 11316374605141, "recv_ms": 1787095369783, "bids": [[14189.9, 1.33], [14289.9, 2.87], [58220.9, 0.002], [61455.4, 0.01], [62102.3, 0.833], [63689.9, 0.01], [63886.2, 0.783], [64043.0, 0.032], [64548.7, 0.394], [64579.9, 0.0], [64625.2, 0.021], [64631.6, 1.24]], "asks": [[64690.0, 7.369], [64719.2, 0.378], [64735.3, 0.267], [64754.7, 6.99], [64767.7, 0.0], [64830.6, 0.0], [64878.8, 6.662], [64879.6, 0.117], [65336.9, 2.293], [65690.0, 0.413]]}
{"kind": "depth", "E": 1787095369827, "U": 11316374605212, "u": 11316374609664, "recv_ms": 1787095369889, "bids": [[1000.0, 35.76], [14189.9, 1.68], [14289.9, 2.52], [51752.0, 0.0], [58220.9, 0.002], [61455.4, 0.01], [62102.3, 0.836], [63707.6, 0.8], [64043.0, 0.032], [64064.5, 3.317], [64366.5, 0.32], [64531.7, 6.644], [64548.7, 5.084], [64625.7, 6.395], [64647.5, 0.013], [64650.7, 0.102], [64668.8, 3.039], [64673.5, 3.82], [64689.9, 22.081]], "asks": [[64706.0, 0.38], [64718.7, 2.323], [64810.6, 0.1], [64830.6, 5.399], [64839.9, 4.49], [64847.6, 10.409], [64890.3, 4.404], [65100.0, 51.416], [65205.5, 2.449], [65336.9, 2.293]]}
{"kind": "depth", "E": 1787095369929, "U": 11316374609820, "u": 11316374618966, "recv_ms": 1787095369987, "bids": [[1000.0, 35.76], [14189.9, 2.03], [14289.9, 2.17], [58220.9, 0.002], [61455.4, 0.011], [62102.3, 0.833], [63689.9, 0.03], [63837.2, 4.693], [64043.0, 0.032], [64361.6, 0.055], [64366.4, 1.332], [64403.3, 0.079], [64555.4, 0.0], [64560.1, 0.609], [64574.6, 3.867], [64574.7, 1.264], [64618.9, 0.06], [64649.3, 0.003], [64673.5, 3.822], [64685.4, 0.004], [64689.3, 0.112], [64689.9, 22.206]], "asks": [[64690.0, 6.733], [64691.6, 0.002], [64693.8, 0.23], [64701.0, 2.361], [64706.0, 0.382], [64708.4, 0.39], [64718.8, 0.039], [64719.0, 0.156], [64761.3, 0.048], [64825.6, 4.36], [65336.9, 2.293], [65498.6, 5.751], [65690.0, 0.433], [65833.3, 0.866], [65983.7, 0.024]]}
{"kind": "depth", "E": 1787095370133, "U": 11316374624643, "u": 11316374630587, "recv_ms": 1787095370192, "bids": [[1000.0, 35.76], [14189.9, 2.744], [14289.9, 1.456], [51752.0, 0.0], [58220.9, 0.002], [61455.4, 0.008], [61455.5, 0.008], [63689.9, 0.01], [63696.8, 0.39], [63963.3, 0.0], [64043.0, 0.032], [64366.5, 0.31], [64560.1, 1.615], [64600.6, 4.106], [64600.7, 0.276], [64609.2, 0.385], [64616.4, 0.003], [64636.8, 1.517], [64641.8, 0.029], [64642.4, 2.468], [64645.3, 0.003], [64678.3, 0.021], [64684.5, 0.012], [64686.9, 0.572], [64689.9, 22.206]], "asks": [[64693.1, 0.892], [64696.7, 0.084], [64745.4, 0.004], [64746.0, 0.07], [65013.5, 1.077], [65336.9, 2.293], [65660.3, 1.368], [65683.2, 0.0], [65690.0, 0.413]]}
{"kind": "depth", "E": 1787095370235, "U": 11316374630806, "u": 11316374635191, "recv_ms": 1787095370294, "bids": [[1000.0, 35.76], [14189.9, 3.108], [14289.9, 1.092], [51752.0, 0.0], [58220.9, 0.002], [61455.4, 0.008], [62102.3, 0.833], [63689.9, 0.03], [63696.6, 0.016], [64043.0, 0.032], [64061.4, 59.668], [64366.4, 1.486], [64579.9, 0.003], [64625.2, 0.003], [64636.8, 1.518], [64640.1, 0.009], [64645.3, 0.004], [64687.2, 0.004], [64687.6, 0.009], [64689.9, 22.206]], "asks": [[64693.8, 0.088], [64698.8, 0.007], [64736.9, 0.06], [64738.7, 0.0], [64767.7, 0.003], [65326.4, 58.217], [65336.9, 2.293], [65348.3, 0.182], [65464.3, 2.589], [65683.1, 0.011], [65690.0, 0.433]]}
{"kind": "depth", "E": 1787095370337, "U": 11316374635257, "u": 11316374641067, "recv_ms": 1787095370398, "bids": [[14189.9, 3.472], [14289.9, 0.728], [51752.0, 0.0], [58220.9, 0.002], [61455.4, 0.008], [62102.3, 0.836], [63718.6, 4.231], [63973.0, 0.242], [64043.0, 0.032], [64366.5, 0.31], [64685.3, 0.627], [64686.9, 0.031], [64689.9, 22.207]], "asks": [[64693.8, 0.313], [64830.6, 3.792], [64847.6, 5.528], [65011.4, 2.612], [65013.4, 1.077], [65013.5, 1.078], [65205.5, 1.53], [65336.9, 2.293], [65466.3, 20.72], [65478.1, 5.341], [65482.0, 14.092]]}
{"kind": "depth", "E": 1787095370439, "U": 11316374641106, "u": 11316374646166, "recv_ms": 1787095370499, "bids": [[1000.0, 35.76], [14189.9, 3.738], [14289.9, 0.42], [14589.9, 0.042], [58220.9, 0.002], [61455.4, 0.008], [62102.3, 0.833], [63689.9, 0.01], [64032.2, 0.0], [64043.0, 0.032], [64158.8, 0.311], [64671.5, 0.084], [64678.8, 0.002], [64689.9, 22.207]], "asks": [[64690.0, 5.322], [64693.3, 0.138], [64693.8, 0.088], [64728.7, 0.053], [64739.2, 0.009], [64830.6, 5.399], [64847.6, 10.409], [65205.5, 1.225], [65336.9, 2.295], [65369.2, 1.602], [65690.0, 0.413]]}
{"kind": "depth", "E": 1787095370541, "U": 11316374646249, "u": 11316374651400, "recv_ms": 1787095370603, "bids": [[1000.0, 35.76], [14189.9, 3.682], [14289.9, 0.266], [14589.9, 0.252], [51751.9, 0.0], [58220.9, 0.002], [61455.4, 0.009], [62102.3, 0.836], [63396.2, 0.017], [63490.9, 0.005], [63505.2, 4.614], [63739.0, 1.885], [64043.0, 0.032], [64657.0, 0.005], [64657.1, 0.046], [64657.2, 0.064], [64660.5, 1.332], [64660.6, 0.098], [64660.7, 0.008], [64671.5, 0.084], [64678.9, 2.104], [64679.6, 0.755], [64683.1, 0.628], [64684.3, 0.02], [64689.9, 22.208]], "asks": [[64690.0, 5.474], [64690.4, 0.011], [64693.0, 0.031], [64701.1, 1.095], [64708.5, 0.618], [64830.6, 5.399], [64847.6, 10.409], [65207.5, 8.142], [65336.9, 2.293], [65466.3, 22.55]]}
{"kind": "depth", "E": 1787095370745, "U": 11316374657660, "u": 11316374662348, "recv_ms": 1787095370807, "bids": [[1000.0, 35.76], [14189.9, 3.458], [14289.9, 0.028], [14589.9, 0.714], [58220.9, 0.002], [61455.4, 0.008], [62102.3, 0.833], [64043.0, 0.034], [64548.7, 0.394], [64689.9, 22.206]], "asks": [[64830.6, 0.0], [65336.9, 2.293], [65628.0, 21.028], [65703.9, 1.953]]}
{"kind": "depth", "E": 1787095370847, "U": 11316374662394, "u": 11316374667188, "recv_ms": 1787095370909, "bids": [[1000.0, 35.76], [14189.9, 3.15], [14289.9, 0.0], [14589.9, 1.05], [58220.9, 0.002], [61455.5, 0.006], [62102.3, 0.836], [63768.1, 50.85], [63911.6, 4.207], [64043.0, 0.032], [64170.4, 1.242], [64364.5, 2.641], [64387.0, 0.0], [64548.8, 5.935], [64657.9, 1.501], [64673.5, 3.82], [64689.9, 22.205]], "asks": [[64690.0, 5.321], [64692.3, 0.311], [64693.3, 0.054], [64701.1, 0.477], [64706.0, 0.38], [64708.5, 0.0], [64830.2, 2.116], [64830.6, 5.399], [64886.4, 8.119], [65059.2, 5.891], [65059.9, 0.0], [65336.9, 2.293], [65413.4, 1.526]]}
{"kind": "depth", "E": 1787095370949, "U": 11316374667309, "u": 11316374671941, "recv_ms": 1787095371007, "bids": [[14189.9, 2.786], [14589.9, 1.414], [58220.9, 0.002], [62102.3, 0.833], [63689.9, 0.01], [64043.0, 0.032], [64366.5, 0.32], [64579.9, 0.0], [64631.6, 1.24], [64673.5, 3.822]], "asks": [[64693.0, 0.256], [64693.3, 0.138], [64706.0, 0.382], [64725.7, 0.042], [64735.3, 0.267], [64736.9, 0.021], [64767.7, 0.0], [65336.9, 2.293], [65396.8, 2.292], [65542.8, 3.816], [65690.0, 0.413], [65983.7, 0.024]]}
{"kind": "depth", "E": 1787095371051, "U": 11316374671981, "u": 11316374677468, "recv_ms": 1787095371114, "bids": [[1000.0, 35.76], [14189.9, 2.436], [14589.9, 1.764], [58220.9, 0.002], [61455.4, 0.008], [64043.0, 0.032], [64172.4, 7.963], [64366.5, 0.475], [64492.5, 0.06], [64492.6, 1.547], [64493.0, 11.747], [64531.7, 0.004], [64531.8, 7.42], [64548.8, 5.738], [64628.1, 0.0], [64628.6, 3.789], [64678.3, 0.026], [64689.9, 22.206]], "asks": [[64693.0, 0.031], [64752.7, 0.018], [64754.3, 3.261], [64878.9, 35.01], [64886.4, 0.033], [64886.5, 8.216], [65013.5, 1.077], [65193.7, 0.331], [65336.9, 2.293], [65498.6, 6.009], [65983.7, 0.021]]}
{"kind": "depth", "E": 1787095371153, "U": 11316374677634, "u": 11316374682592, "recv_ms": 1787095371212, "bids": [[1000.0, 35.76], [14189.9, 2.086], [14589.9, 2.114], [58220.9, 0.002], [61455.4, 0.01], [62102.3, 0.836], [63689.9, 0.03], [63706.1, 0.388], [63869.5, 2.355], [63913.6, 35.858], [64043.0, 0.032], [64172.4, 8.897], [64366.4, 1.487], [64548.8, 1.245], [64609.2, 0.381], [64616.4, 0.004], [64636.8, 1.519], [64639.7, 2.323], [64640.1, 0.01], [64645.3, 0.005], [64648.2, 0.465], [64678.3, 0.021], [64689.9, 22.208]], "asks": [[64690.0, 5.336], [64700.1, 0.003], [64830.2, 1.501], [64830.6, 0.0], [65336.9, 2.297], [65673.7, 0.019], [65673.8, 0.016], [65690.0, 0.433], [65784.9, 0.0]]}
{"kind": "depth", "E": 1787095371357, "U": 11316374688253, "u": 11316374692759, "recv_ms": 1787095371415, "bids": [[1000.0, 35.76], [14189.9, 1.372], [14589.9, 2.828], [58220.9, 0.002], [62102.3, 0.836], [63689.9, 0.01], [63918.6, 0.0], [64043.0, 0.032], [64075.3, 11.199], [64366.4, 1.488], [64548.8, 1.245]], "asks": [[64692.3, 0.001], [64707.6, 0.01], [64708.0, 1.286], [64830.7, 0.001], [65013.5, 1.076], [65336.9, 2.293], [65482.0, 13.834], [65690.0, 0.413]]}
{"kind": "depth", "E": 1787095371459, "U": 11316374693010, "u": 11316374697819, "recv_ms": 1787095371516, "bids": [[1000.0, 35.76], [14189.9, 1.008], [14589.9, 3.192], [58220.9, 0.002], [61455.4, 0.008], [61455.5, 0.008], [62102.3, 0.833], [63396.2, 0.014], [63901.8, 3.151], [64043.0, 0.032], [64548.8, 5.635], [64579.9, 0.003], [64685.3, 0.627], [64686.9, 0.031], [64689.7, 0.012], [64689.9, 22.211]], "asks": [[64767.7, 0.003], [64830.7, 5.4], [64886.5, 8.743], [65011.4, 2.458], [65336.9, 2.293], [65983.7, 0.015], [66237.1, 0.0]]}
{"kind": "depth", "E": 1787095371561, "U": 11316374697903, "u": 11316374702638, "recv_ms": 1787095371620, "bids": [[14189.9, 0.658], [14589.9, 3.542], [51751.9, 0.0], [58220.9, 0.002], [61455.4, 0.009], [63689.9, 0.03], [63870.4, 4.77], [63886.1, 0.0], [64043.0, 0.034], [64170.4, 0.931], [64366.5, 0.465], [64584.5, 0.069], [64584.6, 0.036], [64639.7, 2.319], [64647.9, 0.315], [64671.5, 0.702], [64678.9, 2.722], [64685.3, 0.086], [64686.9, 0.572], [64689.7, 0.013], [64689.9, 22.209]], "asks": [[64690.0, 5.322], [64692.1, 0.342], [64692.5, 0.118], [64692.9, 0.088], [64696.7, 0.0], [64701.1, 1.095], [64708.5, 0.618], [64878.8, 7.525], [65336.9, 2.294], [65374.2, 2.594], [65449.7, 24.997], [65690.0, 0.433], [65983.7, 0.018]]}
{"kind": "depth", "E": 1787095371765, "U": 11316374708633, "u": 11316374712899, "recv_ms": 1787095371821, "bids": [[1000.0, 35.76], [14189.9, 0.238], [14489.9, 0.294], [14589.9, 3.668], [58220.9, 0.002], [61455.4, 0.008], [62102.3, 0.833], [63689.9, 0.01], [64043.0, 0.032], [64172.4, 9.208], [64548.8, 1.245], [64548.9, 4.99], [64625.2, 0.021], [64680.4, 0.01], [64684.3, 0.02], [64685.3, 0.086], [64686.9, 0.572], [64688.8, 0.091], [64689.3, 0.028], [64689.8, 0.032], [64689.9, 22.197]], "asks": [[64690.0, 4.094], [64692.0, 0.148], [64694.7, 1.42], [64696.3, 0.31], [64701.1, 0.477], [64708.5, 0.0], [64721.1, 0.388], [64830.7, 5.4], [64878.8, 6.662], [64886.5, 8.549], [65013.4, 1.231], [65336.9, 2.294], [65690.0, 0.413]]}
{"kind": "depth", "E": 1787095371867, "U": 11316374713032, "u": 11316374718132, "recv_ms": 1787095371924, "bids": [[14189.9, 0.112], [14489.9, 0.532], [14589.9, 3.556], [58220.9, 0.002], [62102.3, 0.836], [63881.3, 5.295], [64043.0, 0.034], [64170.4, 0.62], [64366.5, 0.465], [64673.5, 3.82], [64678.2, 0.281], [64680.8, 0.395], [64684.5, 0.012], [64684.9, 0.321], [64687.4, 0.005], [64688.0, 0.007], [64689.3, 0.112], [64689.8, 0.055], [64689.9, 22.295]], "asks": [[64690.0, 3.876], [64692.0, 0.064], [64692.1, 0.032], [64692.5, 0.034], [64706.0, 0.38], [64723.2, 0.103], [64755.9, 8.494], [64756.9, 47.963], [64759.0, 1.487], [64759.1, 0.02], [64830.2, 2.116], [65013.4, 1.385], [65336.9, 2.294], [65395.1, 1.377], [65466.3, 23.008], [65602.1, 3.349], [65647.9, 0.0], [65983.7, 0.015]]}
{"kind": "depth", "E": 1787095371969, "U": 11316374718166, "u": 11316374722816, "recv_ms": 1787095372026, "bids": [[1000.0, 35.76], [14189.9, 0.0], [14489.9, 0.784], [14589.9, 3.416], [58220.9, 0.002], [61455.4, 0.008], [63689.9, 0.03], [64043.0, 0.032], [64493.0, 0.043], [64493.1, 4.141], [64531.8, 0.781], [64531.9, 2.866], [64548.9, 2.415], [64628.6, 3.802], [64673.5, 3.822], [64684.5, 0.458], [64689.9, 22.305]], "asks": [[64706.0, 0.382], [64725.3, 10.027], [64754.2, 3.142], [64754.3, 0.002], [64830.7, 1.817], [64844.9, 1.542], [64847.6, 3.287], [64878.8, 6.662], [64886.5, 1.117], [65336.9, 2.294], [65396.8, 1.528], [65690.0, 0.433], [65983.7, 0.018]]}
{"kind": "depth", "E": 1787095372071, "U": 11316374722859, "u": 11316374727124, "recv_ms": 1787095372128, "bids": [[1000.0, 35.76], [14489.9, 1.134], [14589.9, 3.066], [58220.9, 0.002], [61455.5, 0.006], [62102.3, 0.833], [63272.3, 0.678], [64043.0, 0.032], [64493.1, 11.566], [64531.9, 5.867], [64548.9, 4.66], [64678.3, 0.021], [64684.5, 0.012], [64685.3, 0.627], [64686.9, 0.031], [64689.9, 22.304]], "asks": [[64830.7, 5.4], [64847.6, 10.409], [64878.7, 0.901], [64886.5, 9.527], [65336.9, 2.294], [65442.3, 0.0], [65457.8, 1.83], [65482.0, 13.606], [65498.6, 6.237], [65846.3, 0.0]]}
{"kind": "depth", "E": 1787095372173, "U": 11316374727206, "u": 11316374732430, "recv_ms": 1787095372237, "bids": [[14489.9, 1.484], [14589.9, 2.716], [58220.9, 0.002], [61455.4, 0.008], [62102.3, 0.836], [63689.9, 0.01], [64043.0, 1.591], [64169.3, 0.703], [64172.4, 9.519], [64366.4, 1.487], [64366.5, 0.465], [64609.1, 0.003], [64616.4, 0.005], [64636.8, 1.52], [64645.3, 0.006], [64678.9, 2.104], [64689.9, 22.217]], "asks": [[64691.5, 0.026], [64692.1, 0.017], [64692.5, 0.118], [64755.9, 1.445], [64756.9, 0.0], [64761.3, 47.711], [64878.7, 0.001], [65013.5, 1.077], [65336.9, 2.294], [65668.7, 0.266], [65690.0, 0.413]]}
{"kind": "depth", "E": 1787095372275, "U": 11316374732517, "u": 11316374737385, "recv_ms": 1787095372336, "bids": [[1000.0, 35.76], [14489.9, 1.848], [14589.9, 2.352], [51752.0, 0.0], [58220.9, 0.002], [61455.4, 0.008], [62102.3, 0.833], [63525.5, 0.808], [64043.0, 1.591], [64158.8, 0.0], [64579.9, 0.0], [64631.6, 1.24], [64640.1, 0.011], [64671.5, 0.084], [64685.3, 0.627], [64686.9, 0.031], [64689.9, 22.304]], "asks": [[64690.0, 5.062], [64692.1, 0.017], [64692.5, 0.034], [64694.8, 7.557], [64701.6, 0.022], [64721.1, 0.388], [64735.3, 0.264], [64759.1, 47.683], [64761.3, 0.048], [64767.7, 0.003], [64875.6, 0.001], [64875.7, 0.003], [64878.7, 0.001], [65336.9, 2.294], [65459.8, 6.412], [65537.1, 1.983], [66782.4, 0.0]]}
{"kind": "depth", "E": 1787095372377, "U": 11316374737444, "u": 11316374742117, "recv_ms": 1787095372436, "bids": [[1000.0, 35.76], [14489.9, 2.198], [14589.9, 2.002], [51752.0, 0.0], [58220.9, 0.002], [61455.4, 0.008], [62102.3, 0.836], [63511.2, 0.845], [63638.7, 4.058], [63689.9, 0.03], [64043.0, 1.591], [64366.4, 1.486], [64547.7, 0.121], [64574.6, 3.867], [64612.9, 0.789], [64618.9, 0.06], [64648.7, 0.001], [64689.9, 22.3]], "asks": [[64694.2, 0.477], [64721.1, 0.374], [64724.9, 0.004], [64755.7, 0.221], [64758.4, 0.001], [64761.3, 0.048], [64817.2, 0.0], [64825.5, 3.865], [64825.6, 0.495], [65336.9, 2.294], [65546.7, 15.602], [65690.0, 0.433], [66799.8, 0.136]]}
{"kind": "depth", "E": 1787095372479, "U": 11316374742239, "u": 11316374745720, "recv_ms": 1787095372539, "bids": [[14489.9, 2.562], [14589.9, 1.638], [51751.9, 0.0], [58220.9, 0.002], [61455.4, 0.008], [63654.9, 4.833], [63706.0, 1.004], [64043.0, 1.591], [64366.5, 0.475], [64366.7, 0.115], [64548.9, 0.6], [64689.9, 22.305]], "asks": [[64692.0, 0.374], [64792.1, 0.506], [64830.7, 0.001], [65013.5, 1.078], [65016.1, 0.002], [65020.1, 0.108], [65336.9, 2.294], [65623.1, 0.0]]}
{"kind": "depth", "E": 1787095372581, "U": 11316374745729, "u": 11316374752226, "recv_ms": 1787095372639, "bids": [[1000.0, 35.76], [14489.9, 2.912], [14589.9, 1.288], [58220.9, 0.002], [61455.4, 0.008], [61455.5, 0.008], [62102.3, 0.833], [63689.9, 0.01], [64043.0, 1.591], [64170.4, 0.31], [64364.5, 2.486], [64548.9, 4.99], [64558.7, 0.121], [64616.2, 2.395], [64650.7, 0.133], [64671.5, 0.702], [64678.9, 2.104], [64685.3, 0.627], [64685.5, 0.256], [64685.9, 0.007], [64686.9, 0.031], [64687.4, 0.008], [64687.6, 0.003], [64689.9, 22.223]], "asks": [[64690.0, 5.09], [64690.4, 0.019], [64692.4, 0.086], [64694.2, 0.252], [64695.9, 0.434], [64701.1, 1.095], [64708.5, 0.618], [64711.2, 0.91], [64712.8, 2.726], [64724.0, 0.191], [64747.0, 0.0], [64761.4, 2.718], [64805.2, 0.001], [64823.7, 0.143], [64830.2, 1.501], [64830.7, 3.248], [64847.6, 0.0], [64847.7, 4.43], [64886.5, 8.736], [65336.9, 2.293], [65563.3, 2.844], [65690.0, 0.413]]}
{"kind": "depth", "E": 1787095372683, "U": 11316374752304, "u": 11316374756775, "recv_ms": 1787095372740, "bids": [[1000.0, 35.76], [14489.9, 3.276], [14589.9, 0.924], [58220.9, 0.002], [61455.4, 0.008], [62102.3, 0.836], [63396.2, 0.017], [63784.2, 8.535], [63853.9, 0.0], [64043.0, 1.591], [64548.9, 4.99], [64689.9, 22.222]], "asks": [[64694.1, 0.21], [64718.1, 0.155], [64719.1, 0.019], [64830.7, 5.4], [64847.7, 10.41], [64886.5, 8.551], [65336.9, 2.293]]}
{"kind": "depth", "E": 1787095372785, "U": 11316374756826, "u": 11316374761237, "recv_ms": 1787095372843, "bids": [[14489.9, 3.626], [14589.9, 0.574], [51752.0, 0.0], [58220.9, 0.002], [62102.3, 0.833], [63279.9, 0.0], [63280.6, 0.012], [63689.9, 0.03], [63719.6, 1.493], [63805.7, 4.22], [64043.0, 1.591], [64172.4, 9.829], [64325.7, 0.003], [64325.8, 1.626], [64366.5, 0.62], [64422.4, 0.007], [64425.0, 1.549], [64493.3, 0.285], [64495.7, 1.265], [64671.5, 0.084], [64673.2, 1.462], [64676.6, 4.037], [64689.9, 22.299]], "asks": [[64690.0, 5.089], [64694.2, 0.252], [64701.1, 0.477], [64708.5, 0.0], [64890.3, 0.992], [64890.5, 0.182], [64960.2, 0.263], [64961.9, 0.324], [65059.2, 0.301], [65059.3, 0.002], [65241.7, 0.168], [65336.9, 2.293], [65413.4, 2.289], [65628.0, 22.093], [65690.0, 0.433], [65801.5, 3.037]]}
{"kind": "depth", "E": 1787095372989, "U": 11316374766461, "u": 11316374771160, "recv_ms": 1787095373061, "bids": [[1000.0, 35.76], [14389.9, 0.35], [14489.9, 3.64], [14589.9, 0.21], [58220.9, 0.002], [61455.4, 0.008], [63689.9, 0.01], [63751.9, 17.618], [63816.6, 6.601], [64043.0, 1.591], [64061.4, 0.0], [64209.9, 0.062], [64531.9, 6.448], [64534.1, 2.053], [64548.9, 4.99], [64627.0, 0.163], [64627.3, 0.001], [64627.6, 0.0], [64628.0, 0.001], [64628.3, 0.097], [64644.7, 0.0], [64645.0, 0.121], [64645.4, 0.072], [64645.7, 0.0], [64646.0, 0.202], [64659.6, 0.165], [64659.7, 0.02], [64659.8, 0.007], [64659.9, 0.0], [64660.0, 0.17], [64660.1, 0.013], [64660.2, 0.131], [64660.3, 0.001], [64660.4, 4.902], [64660.6, 0.028], [64661.6, 0.028], [64662.0, 0.438], [64668.2, 0.155], [64673.5, 3.822], [64678.9, 2.034], [64679.0, 0.821], [64679.1, 0.08], [64679.2, 0.0], [64679.3, 2.33], [64679.4, 0.002], [64679.5, 0.002], [64679.6, 0.555], [64679.7, 0.328], [64679.8, 0.01], [64679.9, 0.002], [64680.2, 0.415], [64680.5, 0.215], [64680.8, 0.363], [64681.1, 0.002], [64681.5, 0.049], [64684.3, 0.02], [64685.3, 0.086], [64686.9, 0.572], [64687.2, 0.007], [64687.4, 0.005], [64689.9, 22.382]], "asks": [[64690.0, 6.026], [64692.0, 0.064], [64692.4, 0.002], [64692.5, 0.002], [64692.8, 0.027], [64692.9, 0.004], [64693.1, 0.854], [64693.3, 0.054], [64693.4, 0.001], [64693.7, 0.085], [64694.0, 0.003], [64694.1, 0.09], [64694.2, 0.161], [64694.3, 0.0], [64694.4, 0.044], [64694.5, 0.635], [64694.6, 0.007], [64694.7, 1.35], [64694.8, 7.4], [64694.9, 0.096], [64695.0, 0.026], [64695.9, 0.124], [64696.2, 0.071], [64696.3, 0.394], [64696.7, 0.084], [64701.1, 0.64], [64706.0, 0.382], [64710.2, 0.242], [64710.5, 0.001], [64710.8, 0.355], [64711.1, 3.261], [64711.2, 0.451], [64711.5, 0.031], [64711.9, 0.045], [64712.1, 0.509], [64712.3, 0.466], [64713.3, 0.018], [64713.5, 0.465], [64713.6, 0.686], [64713.7, 0.001], [64713.8, 0.009], [64713.9, 1.597], [64714.0, 0.034], [64714.1, 0.502], [64714.2, 0.169], [64714.3, 0.015], [64715.5, 0.073], [64727.9, 0.679], [64728.2, 0.007], [64728.5, 0.071], [64728.9, 0.002], [64729.2, 0.013], [64830.7, 5.4], [64847.7, 10.41], [65176.5, 0.0], [65326.4, 0.0], [65336.9, 2.293], [65690.0, 0.413]]}
{"kind": "depth", "E": 1787095373091, "U": 11316374771280, "u": 11316374777027, "recv_ms": 1787095373153, "bids": [[14389.9, 0.588], [14489.9, 3.528], [14589.9, 0.084], [58220.9, 0.002], [61455.4, 0.008], [62102.3, 0.833], [63706.1, 0.38], [63934.2, 3.905], [64043.0, 1.591], [64100.1, 4.342], [64300.1, 13.342], [64325.8, 39.005], [64366.5, 0.62], [64422.4, 29.519], [64425.0, 5.714], [64493.3, 24.347], [64625.1, 6.293], [64625.2, 0.003], [64625.7, 1.682], [64627.3, 34.279], [64629.6, 6.543], [64640.1, 0.012], [64645.3, 0.007], [64645.9, 0.037], [64678.3, 0.021], [64679.1, 0.15], [64679.3, 2.47], [64679.4, 0.072], [64679.7, 0.428], [64680.1, 0.074], [64681.4, 0.047], [64689.9, 22.378]], "asks": [[64690.0, 5.09], [64693.1, 0.68], [64694.4, 0.044], [64694.6, 0.042], [64695.9, 0.215], [64696.3, 0.524], [64696.5, 0.072], [64696.6, 0.087], [64696.7, 0.154], [64696.8, 0.079], [64712.3, 0.501], [64715.1, 0.453], [64715.6, 2.578], [64715.8, 0.197], [64715.9, 0.84], [64716.0, 0.079], [64716.1, 0.391], [64717.8, 0.336], [64717.9, 0.0], [64718.1, 0.001], [64718.2, 0.168], [64730.1, 0.039], [64739.2, 0.0], [64890.3, 4.424], [64890.5, 24.023], [64960.2, 4.559], [64961.9, 29.33], [65011.4, 0.154], [65059.3, 38.101], [65205.5, 0.92], [65252.8, 1.394], [65336.9, 2.293], [65498.6, 6.495], [65673.8, 0.027], [65983.7, 0.015], [71159.0, 0.002]]}
{"kind": "depth", "E": 1787095373193, "U": 11316374777135, "u": 11316374783035, "recv_ms": 1787095373251, "bids": [[1000.0, 35.76], [14389.9, 0.854], [14489.9, 3.346], [14589.9, 0.0], [51752.0, 0.0], [58206.2, 0.0], [58220.9, 0.002], [61455.5, 0.006], [62102.3, 0.836], [63396.2, 0.02], [63689.9, 0.03], [63706.1, 0.388], [64043.0, 1.591], [64609.2, 0.383], [64616.4, 0.006], [64622.9, 0.027], [64627.3, 34.653], [64629.6, 1.166], [64636.8, 1.521], [64644.9, 0.033], [64645.3, 0.008], [64679.6, 0.755], [64679.8, 0.11], [64679.9, 0.072], [64680.0, 0.231], [64680.4, 0.042], [64689.9, 22.38]], "asks": [[64690.0, 5.071], [64691.4, 0.019], [64694.4, 0.044], [64695.6, 0.126], [64696.0, 0.304], [64696.2, 0.191], [64696.4, 0.278], [64713.3, 0.06], [64713.7, 0.121], [64714.1, 0.642], [64715.3, 0.092], [64715.4, 0.122], [64715.6, 2.698], [64731.0, 0.049], [64830.7, 5.4], [64847.7, 10.41], [65013.4, 3.689], [65013.5, 1.077], [65336.9, 2.293], [65690.0, 0.433], [65830.5, 0.903]]}
{"kind": "depth", "E": 1787095373295, "U": 11316374783087, "u": 11316374788004, "recv_ms": 1787095373352, "bids": [[14389.9, 1.218], [14489.9, 2.982], [58220.9, 0.002], [61455.4, 0.008], [62102.3, 0.833], [63913.6, 36.639], [64043.0, 1.591], [64210.0, 47.932], [64366.4, 1.487], [64620.4, 0.013], [64639.8, 1.5], [64645.3, 0.04], [64645.6, 0.032], [64646.2, 0.476], [64656.0, 0.015], [64672.2, 0.007], [64679.2, 0.07], [64679.4, 0.142], [64679.5, 0.102], [64679.9, 0.172], [64680.7, 0.343], [64681.0, 0.936], [64681.7, 0.035], [64687.1, 0.011], [64689.9, 22.381]], "asks": [[64690.0, 3.883], [64693.7, 0.001], [64693.8, 0.088], [64694.1, 0.006], [64694.3, 0.032], [64694.4, 0.044], [64694.9, 0.134], [64695.3, 0.051], [64696.1, 0.122], [64696.5, 0.222], [64696.6, 0.171], [64696.8, 0.17], [64697.0, 0.102], [64697.4, 0.209], [64707.7, 0.007], [64712.0, 3.553], [64712.7, 0.058], [64713.0, 0.044], [64715.4, 0.242], [64715.7, 0.198], [64715.9, 0.924], [64716.0, 0.17], [64723.9, 0.017], [64729.7, 2.366], [64730.4, 0.154], [64730.7, 0.044], [64740.1, 0.002], [64759.5, 0.462], [65176.4, 48.363], [65336.9, 2.293], [65647.2, 0.0], [65673.8, 0.035], [66253.7, 1.292]]}
{"kind": "depth", "E": 1787095373499, "U": 11316374794726, "u": 11316374800977, "recv_ms": 1787095373558, "bids": [[1000.0, 35.76], [14389.9, 1.932], [14489.9, 2.268], [51751.9, 0.0], [58220.9, 0.002], [62102.3, 0.836], [63689.9, 0.01], [64043.0, 1.591], [64366.4, 1.488], [64579.9, 0.0], [64627.2, 0.045], [64631.6, 1.237], [64659.9, 0.07], [64660.0, 0.31], [64660.2, 0.201], [64660.4, 5.002], [64660.8, 1.359], [64664.6, 0.012], [64671.1, 2.003], [64685.3, 0.627], [64686.9, 0.031], [64689.9, 22.398]], "asks": [[64692.8, 0.02], [64693.4, 0.008], [64693.8, 0.088], [64694.5, 0.551], [64697.8, 0.086], [64735.3, 0.264], [64767.7, 0.0], [65013.5, 1.076], [65280.0, 9.419], [65336.9, 2.295], [65690.0, 0.413], [66880.0, 0.265]]}
{"kind": "depth", "E": 1787095373601, "U": 11316374801023, "u": 11316374806049, "recv_ms": 1787095373660, "bids": [[14389.9, 2.296], [14489.9, 1.904], [34000.0, 1.146], [51752.0, 0.0], [58220.9, 0.002], [61455.4, 0.008], [62102.3, 0.833], [63498.2, 0.674], [63773.6, 0.001], [63911.6, 3.582], [64043.0, 1.591], [64569.9, 0.6], [64622.9, 34.679], [64627.3, 0.001], [64627.5, 0.342], [64627.9, 0.032], [64628.5, 0.038], [64660.2, 0.301], [64660.3, 0.101], [64660.5, 1.502], [64660.7, 0.078], [64661.8, 0.1], [64662.3, 0.663], [64667.2, 1.316], [64668.8, 1.957], [64671.5, 0.702], [64678.6, 0.037], [64678.9, 2.652], [64680.2, 0.179], [64680.5, 0.427], [64682.1, 2.612], [64689.9, 22.384]], "asks": [[64690.0, 3.884], [64693.8, 0.313], [64694.5, 0.635], [64697.6, 0.011], [64699.3, 9.776], [64701.1, 1.258], [64708.5, 0.618], [64741.8, 0.003], [64932.7, 0.001], [64971.8, 0.079], [65329.4, 0.0], [65336.9, 2.293], [65668.9, 0.266]]}
{"kind": "depth", "E": 1787095373703, "U": 11316374806116, "u": 11316374811166, "recv_ms": 1787095373760, "bids": [[14389.9, 2.646], [14489.9, 1.554], [51752.0, 0.0], [58220.9, 0.004], [62102.3, 0.836], [63654.9, 5.931], [63689.9, 0.03], [63784.2, 10.884], [63835.4, 5.396], [63865.1, 16.044], [63913.6, 37.264], [64043.0, 1.591], [64364.5, 0.159], [64364.6, 0.256], [64366.5, 0.63], [64622.9, 0.027], [64629.5, 34.685], [64631.6, 1.24], [64659.9, 0.14], [64660.1, 0.083], [64660.6, 0.128], [64665.1, 0.418], [64689.9, 22.383]], "asks": [[64690.9, 0.014], [64693.8, 0.088], [64704.3, 2.324], [64711.0, 2.83], [64735.3, 0.267], [65336.9, 2.293], [65690.0, 0.433]]}
{"kind": "depth", "E": 1787095373805, "U": 11316374811347, "u": 11316374815718, "recv_ms": 1787095373865, "bids": [[1000.0, 35.76], [14389.9, 3.01], [14489.9, 1.19], [51752.0, 0.0], [58220.9, 0.002], [61455.4, 0.008], [62102.3, 0.833], [63110.6, 0.0], [63287.9, 0.678], [63396.2, 0.023], [64043.0, 1.591], [64061.4, 56.758], [64493.1, 0.0], [64493.2, 4.181], [64531.9, 0.001], [64532.0, 4.076], [64548.9, 0.6], [64549.0, 2.745], [64628.6, 1.306], [64665.1, 0.417], [64687.1, 0.011], [64688.4, 0.124], [64689.9, 22.752]], "asks": [[64690.0, 4.102], [64693.7, 0.085], [64693.8, 0.088], [64694.4, 0.044], [64700.1, 0.002], [64701.1, 0.64], [64708.5, 0.0], [64754.2, 0.06], [64830.7, 5.4], [64847.7, 10.41], [64878.6, 5.655], [64886.5, 15.414], [65328.0, 59.998], [65336.9, 2.293], [65341.1, 1.299], [65413.4, 3.052], [65498.6, 6.723], [65590.8, 0.0], [65867.4, 0.835], [71159.0, 0.002]]}
{"kind": "depth", "E": 1787095374009, "U": 11316374819086, "u": 11316374822630, "recv_ms": 1787095374068, "bids": [[14289.9, 0.014], [14389.9, 3.696], [14489.9, 0.49], [58220.9, 0.002], [62102.3, 0.836], [63396.2, 0.023], [63706.0, 0.651], [64043.0, 1.591], [64366.5, 2.957], [64622.9, 0.027], [64627.3, 35.436], [64629.5, 0.033], [64672.4, 0.116], [64673.1, 0.0], [64673.5, 3.822], [64674.6, 0.562], [64675.5, 0.001]], "asks": [[64693.0, 0.031], [64706.0, 0.382], [64735.1, 0.03], [64736.3, 0.208], [64744.0, 1.262], [65261.2, 0.374], [65336.9, 2.293], [65983.7, 0.012]]}
{"kind": "depth", "E": 1787095374111, "U": 11316374822683, "u": 11316374826949, "recv_ms": 1787095374172, "bids": [[1000.0, 35.76], [14289.9, 0.168], [14389.9, 3.738], [14489.9, 0.294], [58220.9, 0.002], [62102.3, 0.833], [63689.9, 0.03], [64043.0, 1.591], [64170.4, 0.0], [64172.4, 10.139], [64364.5, 0.004], [64627.3, 0.001], [64629.5, 35.468], [64636.8, 1.519], [64640.1, 0.007], [64678.3, 0.021], [64685.3, 0.086], [64686.9, 0.572], [64687.1, 0.011]], "asks": [[64692.1, 0.017], [64704.3, 2.324], [65011.4, 0.0], [65207.5, 9.976], [65336.9, 2.293], [65589.2, 0.923], [65690.0, 0.433]]}
{"kind": "depth", "E": 1787095374213, "U": 11316374827011, "u": 11316374830715, "recv_ms": 1787095374272, "bids": [[14289.9, 0.406], [14389.9, 3.612], [14489.9, 0.182], [58220.9, 0.002], [61455.4, 0.006], [62102.3, 0.836], [63719.6, 1.846], [64043.0, 1.591], [64549.0, 0.0], [64636.8, 1.515], [64640.1, 0.005], [64665.0, 0.004], [64671.1, 0.003], [64685.3, 0.627], [64686.9, 0.031], [64689.9, 22.751]], "asks": [[64700.7, 0.005], [64830.7, 0.001], [65336.9, 2.293], [65773.1, 13.492]]}
{"kind": "depth", "E": 1787095374315, "U": 11316374830876, "u": 11316374834632, "recv_ms": 1787095374372, "bids": [[1000.0, 35.91], [14289.9, 0.644], [14389.9, 3.5], [14489.9, 0.056], [51752.0, 0.0], [58220.9, 0.002], [62102.3, 0.833], [63689.9, 0.01], [64043.0, 1.591], [64366.4, 1.487], [64366.5, 2.947], [64665.0, 0.003]], "asks": [[64701.1, 0.66], [64701.8, 0.002], [64788.1, 0.028], [64830.2, 1.501], [64867.5, 0.0], [65272.2, 4.588], [65336.9, 2.293], [65396.8, 0.764], [65690.0, 0.413], [65789.7, 8.947]]}
{"kind": "depth", "E": 1787095374417, "U": 11316374834669, "u": 11316374839893, "recv_ms": 1787095374475, "bids": [[1000.0, 35.76], [14289.9, 0.938], [14389.9, 3.262], [14489.9, 0.0], [58220.9, 0.002], [63869.5, 3.137], [63911.6, 3.113], [64043.0, 1.591], [64172.4, 10.449], [64366.5, 3.102], [64634.2, 0.002], [64647.7, 0.165], [64647.9, 0.311], [64664.1, 1.659], [64687.1, 0.011]], "asks": [[64693.8, 0.313], [64727.9, 4.544], [64747.3, 5.332], [64766.8, 3.864], [64786.2, 3.871], [65013.4, 3.843]]}
{"kind": "depth", "E": 1787095374519, "U": 11316374840811, "u": 11316374846054, "recv_ms": 1787095374576, "bids": [[14289.9, 1.302], [14389.9, 2.898], [51751.9, 0.0], [58220.9, 0.002], [62102.3, 0.836], [63689.9, 0.03], [64043.0, 1.591], [64366.4, 1.486], [64664.1, 1.658], [64675.1, 0.0], [64679.1, 0.168]], "asks": [[64690.4, 0.026], [64693.8, 0.313], [64726.6, 1.645], [64735.1, 0.026], [64744.0, 1.266], [64999.7, 0.003], [65013.5, 1.077], [65336.9, 2.293], [65584.6, 5.482], [65616.8, 5.898], [65646.4, 0.342], [65690.0, 0.433]]}
{"kind": "depth", "E": 1787095374621, "U": 11316374846137, "u": 11316374851479, "recv_ms": 1787095374680, "bids": [[1000.0, 35.76], [14289.9, 1.666], [14389.9, 2.534], [58220.9, 0.002], [61455.4, 0.006], [62102.3, 0.833], [63547.1, 0.002], [63689.9, 0.01], [63865.1, 15.809], [63913.6, 37.733], [64043.0, 1.591], [64100.1, 4.342], [64300.1, 13.342], [64325.8, 0.003], [64325.9, 0.0], [64366.5, 3.112], [64422.4, 0.007], [64425.0, 1.549], [64493.2, 11.511], [64493.3, 0.285], [64495.7, 0.009], [64532.0, 5.858], [64549.0, 4.257], [64622.9, 0.027], [64625.1, 41.728], [64629.5, 0.033], [64668.0, 8.219], [64668.2, 0.001], [64668.3, 0.155], [64668.4, 0.171], [64668.8, 3.016], [64689.9, 22.751]], "asks": [[64690.0, 3.884], [64693.8, 0.088], [64830.7, 5.4], [64847.7, 10.41], [64886.5, 9.362], [64890.3, 0.992], [64890.5, 0.182], [64960.2, 0.263], [64961.9, 0.324], [65013.5, 1.078], [65059.2, 0.301], [65059.3, 0.002], [65336.9, 2.295], [65690.0, 0.413]]}
{"kind": "depth", "E": 1787095374723, "U": 11316374851549, "u": 11316374862901, "recv_ms": 1787095374780, "bids": [[1000.0, 35.76], [14289.9, 2.016], [14389.9, 2.184], [58220.9, 0.002], [62102.3, 0.836], [63396.2, 0.017], [63718.6, 3.682], [63902.9, 3.126], [64043.0, 1.591], [64532.0, 6.46], [64624.3, 0.0], [64637.2, 0.0], [64672.2, 0.008], [64672.4, 0.0], [64674.1, 0.124], [64674.6, 0.005], [64676.6, 4.594], [64685.5, 0.024], [64686.0, 0.235], [64687.1, 0.011]], "asks": [[64693.7, 0.085], [64693.8, 0.313], [64694.1, 0.09], [64701.1, 1.278], [64706.7, 0.003], [64708.5, 0.618], [64709.1, 0.018], [64735.1, 0.03], [64744.0, 1.262], [64886.5, 8.314], [65336.9, 2.293], [65628.0, 22.397]]}
{"kind": "depth", "E": 1787095374825, "U": 11316374863007, "u": 11316374868653, "recv_ms": 1787095374883, "bids": [[14289.9, 2.366], [14389.9, 1.834], [58220.9, 0.002], [61455.4, 0.006], [63739.0, 2.433], [64043.0, 1.591], [64061.4, 0.0], [64210.0, 0.039], [64505.6, 0.018], [64508.6, 0.01], [64514.3, 0.0], [64515.0, 5.726], [64515.1, 2.634], [64583.2, 4.021], [64625.2, 0.002], [64631.6, 1.24], [64638.1, 1.269], [64651.4, 4.024], [64667.5, 0.017], [64668.0, 8.373], [64668.3, 0.001], [64672.2, 0.007], [64673.1, 0.116], [64674.1, 0.008], [64675.5, 0.558], [64676.6, 4.037], [64685.3, 0.627], [64686.9, 0.031], [64689.9, 22.75]], "asks": [[64693.8, 0.088], [64701.1, 1.3], [64735.3, 0.267], [64754.7, 6.989], [64878.6, 0.01], [65176.4, 0.002], [65328.0, 2.871], [65336.9, 2.293], [65663.4, 0.347]]}
{"kind": "depth", "E": 1787095374927, "U": 11316374868905, "u": 11316374875269, "recv_ms": 1787095374986, "bids": [[1000.0, 35.76], [14289.9, 2.73], [14389.9, 1.47], [58220.9, 0.002], [61455.4, 0.004], [61455.5, 0.008], [62102.3, 0.833], [63557.8, 3.771], [63689.9, 0.03], [64043.0, 1.591], [64100.1, 0.022], [64300.1, 16.798], [64324.9, 37.26], [64325.0, 0.887], [64366.5, 3.102], [64367.7, 1.076], [64421.5, 30.247], [64421.7, 4.729], [64492.4, 23.931], [64507.6, 0.755], [64620.1, 0.032], [64620.2, 2.604], [64625.7, 6.749], [64628.4, 0.004], [64628.6, 5.767], [64636.8, 1.385], [64636.9, 0.128], [64668.0, 8.375], [64668.4, 0.169], [64683.4, 0.012], [64685.3, 0.532], [64686.9, 0.572], [64687.1, 0.011], [64689.9, 22.751]], "asks": [[64690.0, 3.679], [64693.7, 0.001], [64693.8, 0.088], [64694.1, 0.006], [64701.1, 0.682], [64703.6, 0.123], [64703.7, 1.651], [64704.3, 2.324], [64708.5, 0.0], [64712.0, 1.578], [64712.1, 2.485], [64720.3, 0.011], [64720.4, 5.238], [64724.8, 1.287], [64725.3, 10.029], [64830.2, 2.116], [64890.3, 4.417], [64890.5, 23.982], [64960.2, 4.59], [64961.9, 29.532], [65059.2, 5.679], [65059.3, 36.291], [65336.9, 2.293], [65655.5, 0.001], [65690.0, 0.433]]}
{"kind": "depth", "E": 1787095375029, "U": 11316374875404, "u": 11316374879620, "recv_ms": 1787095375086, "bids": [[1000.0, 35.76], [14289.9, 3.094], [14389.9, 1.106], [58220.9, 0.002], [61455.4, 0.004], [62102.3, 0.836], [63897.4, 44.894], [64043.0, 1.591], [64061.4, 59.131], [64209.1, 47.843], [64630.3, 0.0], [64645.3, 0.267], [64667.5, 0.016], [64671.2, 0.004], [64673.5, 3.822], [64684.5, 0.458], [64685.3, 0.627], [64686.9, 0.031], [64689.9, 22.753]], "asks": [[64690.0, 3.678], [64692.5, 0.002], [64694.1, 0.09], [64706.0, 0.382], [65336.9, 2.293], [65983.7, 0.015]]}
{"kind": "depth", "E": 1787095375131, "U": 11316374879686, "u": 11316374884472, "recv_ms": 1787095375189, "bids": [[14289.9, 3.444], [14389.9, 0.756], [58220.9, 0.002], [62102.3, 0.833], [63592.3, 0.0], [63689.9, 0.01], [63706.1, 0.38], [63770.9, 0.0], [63772.1, 0.0], [63865.1, 15.458], [64043.0, 1.591], [64636.8, 1.386], [64640.0, 0.03], [64662.0, 0.322], [64668.3, 0.002], [64671.2, 0.003], [64678.3, 0.021], [64684.5, 0.012], [64685.3, 0.627], [64686.9, 0.031], [64687.0, 0.366], [64687.1, 0.011], [64687.6, 0.006], [64689.9, 22.766]], "asks": [[64690.0, 3.529], [64693.1, 0.68], [64694.1, 0.006], [64698.4, 0.006], [64700.7, 0.004], [64886.5, 7.982], [65178.1, 47.747], [65336.9, 2.293], [65425.9, 1.224], [65429.2, 0.772], [65607.8, 0.008], [65609.1, 0.001], [65673.8, 0.027], [65690.0, 0.413]]}
{"kind": "depth", "E": 1787095375233, "U": 11316374884565, "u": 11316374897625, "recv_ms": 1787095375296, "bids": [[1000.0, 35.76], [14189.9, 0.042], [14289.9, 3.71], [14389.9, 0.448], [51752.0, 0.0], [58220.9, 0.002], [61455.4, 0.006], [62102.3, 0.836], [63689.9, 0.03], [63706.1, 0.388], [63770.9, 0.008], [63772.1, 0.008], [63800.4, 12.969], [64043.0, 1.593], [64321.6, 0.0], [64323.0, 0.013], [64328.4, 0.0], [64351.3, 0.066], [64352.8, 0.0], [64353.0, 0.29], [64359.8, 0.123], [64366.5, 3.112], [64483.4, 0.07], [64507.9, 0.536], [64562.6, 0.556], [64579.9, 0.003], [64589.6, 0.0], [64590.8, 2.484], [64591.5, 0.0], [64602.8, 0.043], [64604.2, 3.094], [64610.3, 0.0], [64624.3, 1.546], [64625.1, 6.293], [64625.7, 1.682], [64627.3, 0.001], [64629.5, 36.174], [64633.9, 0.001], [64638.1, 1.272], [64639.6, 0.01], [64641.9, 6.03], [64642.3, 2.319], [64649.5, 1.367], [64650.9, 0.001], [64651.4, 4.026], [64658.5, 0.073], [64661.3, 1.479], [64663.9, 1.7], [64665.1, 0.347], [64666.8, 0.052], [64668.0, 0.375], [64668.3, 0.001], [64668.8, 1.957], [64670.6, 0.001], [64671.0, 0.016], [64671.4, 0.0], [64671.5, 0.084], [64672.0, 0.028], [64672.3, 2.005], [64673.1, 0.0], [64674.2, 0.116], [64674.9, 0.016], [64675.3, 0.002], [64675.4, 0.001], [64675.5, 0.001], [64675.9, 0.005], [64676.3, 1.0], [64676.8, 0.562], [64677.4, 0.033], [64677.8, 0.007], [64678.2, 0.28], [64678.9, 1.576], [64679.5, 0.103], [64679.8, 0.103], [64680.0, 1.131], [64680.1, 0.078], [64680.6, 0.017], [64680.7, 0.034], [64680.9, 0.606], [64681.0, 0.943], [64681.6, 0.129], [64681.7, 0.035], [64681.9, 0.83], [64682.4, 0.093], [64682.6, 0.939], [64683.6, 0.466], [64684.0, 0.043], [64685.3, 0.086], [64685.4, 0.004], [64685.9, 0.004], [64686.0, 0.003], [64686.5, 0.002], [64686.9, 0.572], [64687.0, 0.598], [64687.6, 0.003], [64688.0, 0.007], [64688.4, 0.085], [64688.5, 0.049], [64689.2, 0.0], [64689.4, 0.022], [64689.8, 0.106], [64689.9, 22.766]], "asks": [[64690.0, 3.385], [64690.1, 0.01], [64691.2, 0.002], [64691.5, 0.257], [64691.6, 0.213], [64692.4, 0.003], [64692.5, 1.651], [64692.6, 0.101], [64692.9, 0.229], [64693.0, 0.003], [64693.1, 0.329], [64693.4, 0.001], [64693.5, 0.017], [64693.7, 0.009], [64693.8, 0.085], [64693.9, 1.794], [64694.0, 0.001], [64694.3, 0.0], [64694.4, 1.791], [64694.5, 0.003], [64694.6, 0.004], [64694.7, 1.357], [64694.9, 0.1], [64695.3, 0.009], [64695.6, 0.084], [64695.9, 0.124], [64696.0, 0.093], [64696.1, 0.002], [64696.2, 0.001], [64696.3, 0.394], [64696.5, 0.222], [64696.6, 0.174], [64697.1, 0.026], [64697.4, 0.086], [64697.6, 0.011], [64697.8, 0.086], [64698.2, 0.163], [64698.3, 0.003], [64698.4, 0.005], [64698.8, 0.004], [64698.9, 0.62], [64699.0, 0.635], [64699.1, 0.252], [64699.2, 2.183], [64699.3, 9.776], [64699.6, 0.002], [64699.7, 0.002], [64699.9, 0.206], [64700.3, 0.002], [64700.6, 1.449], [64700.8, 0.009], [64700.9, 2.066], [64701.3, 0.314], [64701.7, 0.023], [64702.1, 0.732], [64702.6, 0.238], [64702.8, 2.326], [64703.0, 0.014], [64703.1, 0.004], [64703.4, 0.623], [64703.5, 0.006], [64704.0, 1.429], [64704.2, 1.001], [64704.3, 1.656], [64704.4, 0.413], [64705.6, 0.083], [64705.9, 2.319], [64706.0, 1.282], [64706.2, 0.256], [64706.9, 0.005], [64707.3, 0.689], [64708.0, 0.046], [64708.3, 0.002], [64708.4, 0.39], [64708.5, 2.319], [64709.1, 0.0], [64709.2, 0.131], [64709.7, 0.885], [64710.0, 0.14], [64710.2, 0.382], [64710.4, 0.189], [64710.6, 0.167], [64710.8, 0.973], [64710.9, 1.244], [64711.0, 0.502], [64711.1, 0.314], [64711.4, 0.025], [64711.9, 2.364], [64712.1, 2.026], [64712.7, 0.518], [64712.8, 2.726], [64713.5, 0.002], [64713.6, 0.687], [64713.8, 0.637], [64714.5, 0.002], [64714.6, 0.0], [64715.1, 2.772], [64715.6, 0.322], [64716.3, 0.002], [64716.5, 0.17], [64717.0, 2.357], [64717.1, 1.866], [64717.3, 0.057], [64717.6, 1.331], [64718.1, 0.001], [64718.6, 0.505], [64719.0, 0.002], [64719.1, 0.019], [64719.4, 0.042], [64719.7, 1.481], [64720.4, 4.446], [64721.1, 0.392], [64721.9, 3.094], [64722.6, 0.002], [64725.3, 0.029], [64727.2, 10.009], [64729.5, 0.004], [64729.9, 5.242], [64730.7, 0.044], [64736.1, 1.843], [64754.0, 0.041], [64759.0, 1.487], [64759.1, 5.789], [64763.8, 0.002], [64765.6, 1.142], [64765.7, 0.002], [64767.7, 0.003], [64767.9, 46.701], [64781.1, 0.0], [64781.5, 1.3], [64784.4, 0.663], [64793.1, 0.003], [64803.0, 0.477], [64806.5, 3.077], [64807.0, 15.401], [64808.3, 0.408], [64810.7, 0.0], [64839.9, 1.514], [64840.8, 0.0], [64844.8, 19.762], [64844.9, 1.542], [64878.5, 3.247], [64883.6, 8.222], [64883.7, 0.014], [64996.2, 0.0], [65025.9, 0.034], [65258.3, 1.301], [65336.9, 2.293], [65607.8, 0.016], [65609.1, 0.009], [65673.8, 0.035], [65690.0, 0.433], [65983.7, 0.012]]}
{"kind": "depth", "E": 1787095375335, "U": 11316374897628, "u": 11316374904727, "recv_ms": 1787095375393, "bids": [[1000.0, 35.76], [14189.9, 0.224], [14289.9, 3.71], [14389.9, 0.266], [58220.9, 0.002], [61455.4, 0.006], [63513.7, 2.358], [63881.3, 5.56], [64043.0, 1.591], [64116.2, 1.168], [64650.7, 0.033], [64677.2, 0.001], [64677.4, 0.013], [64678.6, 0.017], [64678.7, 0.016], [64678.9, 1.575], [64679.6, 0.627], [64680.2, 0.638], [64680.9, 0.147], [64682.8, 0.021], [64684.5, 0.012], [64687.2, 0.004], [64687.6, 0.006], [64688.0, 0.007], [64689.8, 0.066], [64689.9, 24.259]], "asks": [[64690.0, 3.368], [64691.5, 0.103], [64692.9, 0.004], [64693.0, 0.003], [64693.8, 0.31], [64694.6, 0.004], [64698.3, 0.035], [64698.9, 0.658], [64699.3, 9.818], [64699.4, 0.378], [64699.6, 0.043], [64700.1, 0.122], [64701.0, 1.461], [64704.1, 1.242], [64705.0, 0.101], [64705.4, 0.051], [64712.7, 0.48], [64713.0, 0.002], [64713.3, 0.018], [64727.7, 0.104], [64734.7, 0.12], [64747.5, 0.0], [64748.1, 1.039], [64748.4, 0.434], [64748.8, 0.048], [64763.5, 46.714], [64767.9, 0.0], [64798.2, 0.352], [64959.6, 0.095], [65297.1, 1.312], [65336.9, 2.293], [65434.4, 1.526], [65434.5, 18.665], [65446.9, 1.068], [65592.0, 3.008]]}
{"kind": "depth", "E": 1787095375437, "U": 11316374904916, "u": 11316374911203, "recv_ms": 1787095375496, "bids": [[14189.9, 0.476], [14289.9, 3.57], [14389.9, 0.154], [51752.0, 0.0], [58220.9, 0.002], [61455.4, 0.006], [62102.3, 0.833], [63816.6, 7.226], [64043.0, 1.591], [64593.8, 0.009], [64595.7, 0.068], [64598.4, 0.796], [64600.2, 0.038], [64603.0, 0.002], [64607.6, 0.003], [64612.2, 0.002], [64616.8, 0.0], [64621.4, 0.43], [64626.0, 0.001], [64630.6, 0.0], [64635.2, 2.353], [64639.8, 1.485], [64644.4, 0.311], [64649.0, 0.356], [64653.6, 0.009], [64657.0, 0.003], [64657.1, 0.044], [64657.2, 0.062], [64658.2, 0.009], [64660.5, 1.5], [64660.6, 0.126], [64660.7, 0.076], [64662.8, 0.002], [64667.4, 0.0], [64672.0, 0.013], [64675.5, 0.002], [64676.6, 4.022], [64677.2, 0.0], [64681.7, 0.344], [64682.6, 0.63], [64684.3, 0.02], [64684.5, 0.012], [64687.9, 0.142], [64688.5, 0.046], [64689.9, 24.21]], "asks": [[64691.5, 0.103], [64691.6, 0.22], [64692.9, 0.088], [64693.1, 0.554], [64693.7, 0.093], [64693.8, 0.085], [64694.3, 0.548], [64694.9, 0.103], [64696.6, 0.171], [64697.8, 0.002], [64698.6, 0.037], [64698.9, 0.11], [64699.9, 2.525], [64700.2, 0.071], [64700.3, 0.132], [64700.5, 0.033], [64707.5, 0.03], [64708.4, 0.39], [64710.5, 0.619], [64710.8, 0.355], [64712.0, 1.546], [64712.2, 0.309], [64715.4, 0.122], [64718.2, 0.014], [64718.3, 0.425], [64731.0, 0.049], [64734.8, 3.574], [64734.9, 0.133], [64747.8, 1.275], [64750.4, 3.542], [64750.5, 0.0], [64754.9, 0.252], [64755.1, 0.0], [64759.7, 0.008], [64764.3, 0.0], [64768.9, 0.001], [64773.5, 0.01], [64778.1, 0.016], [64809.0, 0.067], [65013.4, 3.228], [65013.5, 1.077], [65308.7, 1.437], [65336.9, 2.293], [65434.5, 16.849], [65607.4, 3.045]]}
{"kind": "depth", "E": 1787095375539, "U": 11316374911262, "u": 11316374915989, "recv_ms": 1787095375598, "bids": [[1000.0, 35.76], [14189.9, 0.7], [14289.9, 3.472], [14389.9, 0.028], [51751.9, 0.0], [58220.9, 0.002], [61455.4, 0.006], [62102.3, 0.836], [63126.2, 2.034], [63396.2, 0.014], [63685.2, 0.706], [63689.9, 0.01], [64043.0, 1.591], [64366.4, 1.487], [64366.5, 3.102], [64597.0, 2.775], [64601.5, 0.001], [64602.7, 0.005], [64604.7, 0.015], [64606.0, 0.001], [64606.9, 0.094], [64610.5, 0.148], [64615.0, 0.177], [64624.0, 2.321], [64625.2, 0.005], [64627.2, 0.043], [64628.5, 0.033], [64628.6, 5.769], [64633.0, 0.003], [64637.5, 0.915], [64642.0, 0.016], [64646.5, 0.001], [64651.0, 0.041], [64655.5, 0.053], [64660.0, 0.305], [64664.5, 0.003], [64669.0, 0.0], [64672.5, 0.039], [64673.5, 3.817], [64675.5, 0.001], [64678.0, 0.004], [64684.5, 0.012], [64687.2, 0.004], [64689.9, 24.124]], "asks": [[64690.0, 3.399], [64691.5, 0.103], [64692.4, 0.003], [64692.5, 1.735], [64693.1, 0.329], [64693.7, 0.085], [64693.8, 0.093], [64697.4, 0.002], [64698.4, 0.01], [64698.5, 0.305], [64699.1, 0.255], [64699.9, 2.616], [64700.1, 0.242], [64701.7, 0.02], [64702.8, 2.321], [64705.0, 1.001], [64707.1, 0.072], [64711.4, 0.02], [64715.4, 0.002], [64715.5, 0.003], [64715.7, 0.193], [64718.3, 0.579], [64720.0, 0.561], [64723.7, 3.695], [64724.3, 0.116], [64725.3, 0.027], [64728.6, 0.0], [64732.9, 0.021], [64734.4, 1.347], [64734.7, 0.24], [64737.2, 1.485], [64741.7, 0.0], [64746.2, 0.001], [64747.8, 1.24], [64750.7, 1.469], [64755.2, 0.007], [64759.4, 0.02], [64759.7, 0.003], [64764.2, 0.0], [64768.7, 0.389], [64773.2, 0.001], [64777.7, 0.1], [64800.0, 21.198], [65013.5, 1.692], [65336.9, 2.293], [65434.5, 15.941], [65434.6, 0.916], [65690.0, 0.413]]}
{"kind": "depth", "E": 1787095375641, "U": 11316374916092, "u": 11316374920809, "recv_ms": 1787095375700, "bids": [[1000.0, 35.76], [14189.9, 1.022], [14289.9, 3.178], [14389.9, 0.0], [58220.9, 0.002], [62102.3, 0.833], [64043.0, 1.591], [64127.1, 1.256], [64366.4, 1.488], [64584.6, 0.033], [64584.7, 0.004], [64609.2, 0.398], [64611.1, 2.164], [64613.7, 1.803], [64671.6, 0.712], [64678.9, 2.193], [64683.3, 0.55], [64683.7, 0.249], [64684.3, 0.02], [64685.0, 0.168], [64685.3, 0.532], [64686.0, 0.006], [64688.5, 0.043], [64689.9, 23.94]], "asks": [[64691.5, 0.257], [64692.0, 0.064], [64692.2, 0.321], [64692.4, 0.228], [64695.4, 0.314], [64697.0, 0.018], [64700.0, 3.142], [64701.1, 1.3], [64702.6, 0.243], [64708.5, 2.937], [64708.8, 1.372], [64712.3, 0.466], [64712.7, 0.479], [64713.7, 0.001], [64715.1, 2.681], [64715.3, 0.001], [64715.6, 0.192], [64721.1, 0.406], [64731.4, 0.121], [64734.6, 0.248], [64747.0, 0.0], [64747.5, 0.032], [64763.9, 0.015], [64768.4, 1.178], [64875.7, 0.0], [64875.8, 0.011], [64883.6, 0.0], [65013.5, 1.691], [65328.6, 58.807], [65336.9, 2.293], [65434.6, 4.579]]}
{"kind": "depth", "E": 1787095375743, "U": 11316374920934, "u": 11316374925385, "recv_ms": 1787095375801, "bids": [[14189.9, 1.386], [14289.9, 2.814], [32345.0, 0.032], [58220.9, 0.002], [61455.4, 0.006], [62102.3, 0.836], [63396.2, 0.017], [63687.2, 13.881], [63689.9, 0.03], [64043.0, 1.591], [64330.3, 0.0], [64366.5, 3.112], [64549.0, 0.0], [64549.1, 4.588], [64615.3, 0.007], [64616.6, 0.359], [64618.2, 0.015], [64623.7, 0.005], [64669.0, 8.0], [64669.9, 0.003], [64671.6, 0.094], [64672.3, 0.005], [64672.5, 0.038], [64677.3, 2.009], [64678.9, 1.575], [64679.5, 0.562], [64680.2, 0.179], [64680.3, 0.03], [64681.0, 0.936], [64682.8, 0.001], [64683.7, 0.011], [64684.3, 0.496], [64684.5, 0.369], [64685.0, 0.287], [64685.3, 0.532], [64686.0, 0.238], [64687.0, 0.366], [64687.2, 0.004], [64687.4, 0.008], [64687.9, 0.139], [64689.9, 22.722]], "asks": [[64690.0, 4.682], [64691.5, 0.103], [64692.0, 0.064], [64692.4, 0.003], [64692.5, 1.651], [64693.1, 0.329], [64693.8, 0.093], [64699.5, 1.002], [64700.6, 0.449], [64701.1, 0.682], [64706.8, 0.019], [64708.5, 2.319], [64711.0, 0.507], [64721.1, 0.392], [64723.1, 4.001], [64727.2, 0.009], [64747.0, 0.009], [64747.8, 1.275], [64772.9, 0.037], [64811.3, 0.212], [64830.7, 5.4], [64886.5, 8.316], [64958.9, 2.617], [65336.9, 2.293], [65434.6, 5.495], [65690.0, 0.433]]}
{"kind": "depth", "E": 1787095375845, "U": 11316374925396, "u": 11316374930340, "recv_ms": 1787095375903, "bids": [[1000.0, 35.76], [14189.9, 1.736], [14289.9, 2.464], [32345.0, 0.03], [51752.0, 0.0], [58220.9, 0.002], [61455.5, 0.006], [63689.9, 0.01], [63800.4, 12.344], [63897.4, 43.956], [64043.0, 1.593], [64324.9, 36.511], [64325.0, 7.086], [64366.5, 3.102], [64492.6, 4.922], [64622.7, 0.016], [64627.2, 0.058], [64627.9, 0.037], [64629.6, 6.846], [64668.3, 0.001], [64669.9, 0.002], [64670.8, 0.12], [64671.7, 2.073], [64673.5, 3.818], [64675.9, 0.085], [64682.6, 0.546], [64682.7, 0.086], [64684.3, 0.02], [64684.5, 0.012], [64685.0, 0.168], [64685.3, 0.086], [64685.4, 0.043], [64689.9, 22.723]], "asks": [[64691.5, 0.103], [64711.1, 2.271], [64715.2, 2.017], [64721.1, 0.392], [64777.4, 0.015], [64842.0, 6.063], [65336.9, 2.293], [65565.1, 0.002], [65643.7, 11.631], [65690.0, 0.413]]}
{"kind": "depth", "E": 1787095376049, "U": 11316374937855, "u": 11316374944546, "recv_ms": 1787095376109, "bids": [[14189.9, 2.464], [14289.9, 1.736], [58220.9, 0.002], [61455.4, 0.006], [62102.3, 0.836], [63865.1, 15.107], [64043.0, 1.591], [64172.4, 10.449], [64366.5, 3.102], [64579.9, 0.0], [64631.6, 1.24], [64636.2, 0.397], [64640.5, 0.005], [64640.7, 0.016], [64650.7, 0.133], [64673.5, 3.818], [64675.3, 0.559], [64676.8, 0.005], [64678.3, 0.026], [64682.7, 0.125], [64684.3, 0.258], [64684.5, 0.012], [64685.2, 2.458], [64685.3, 0.627], [64685.4, 0.45], [64686.1, 0.001], [64686.9, 0.031], [64689.9, 22.725]], "asks": [[64690.0, 4.722], [64691.5, 0.103], [64692.2, 0.011], [64692.4, 0.228], [64692.9, 0.004], [64693.7, 0.001], [64694.0, 0.085], [64695.4, 0.004], [64697.0, 0.102], [64699.9, 2.619], [64703.4, 0.62], [64706.0, 1.282], [64714.1, 0.699], [64717.3, 0.0], [64727.8, 0.006], [64735.3, 0.264], [64767.7, 0.0], [64800.0, 21.198], [65325.9, 0.0], [65336.9, 2.293], [65390.6, 5.306], [65413.4, 3.816], [65591.0, 4.419], [65646.4, 0.0], [65681.6, 0.001], [65833.3, 0.108]]}
{"kind": "depth", "E": 1787095376151, "U": 11316374944607, "u": 11316374953065, "recv_ms": 1787095376216, "bids": [[1000.0, 35.76], [14189.9, 2.814], [14289.9, 1.386], [51752.0, 0.0], [58220.9, 0.002], [61455.4, 0.006], [62102.3, 0.833], [63689.9, 0.03], [63816.6, 7.851], [63913.6, 38.669], [63950.9, 1.563], [64043.0, 1.591], [64100.1, 4.342], [64300.1, 13.342], [64325.0, 6.222], [64616.4, 0.0], [64636.7, 2.344], [64636.8, 1.385], [64640.0, 0.031], [64644.7, 0.005], [64645.2, 0.018], [64645.3, 0.26], [64648.9, 0.545], [64668.0, 0.373], [64669.0, 8.002], [64673.6, 1.393], [64674.2, 0.0], [64675.3, 0.002], [64676.3, 1.557], [64678.3, 0.021], [64684.3, 0.02], [64685.0, 0.492], [64685.3, 0.086], [64685.4, 0.004], [64686.9, 0.572], [64689.9, 22.724]], "asks": [[64690.0, 5.451], [64691.5, 0.103], [64692.2, 0.321], [64692.4, 0.003], [64693.0, 0.003], [64693.2, 0.307], [64693.8, 0.093], [64694.4, 0.128], [64695.5, 0.311], [64698.0, 0.343], [64699.8, 0.1], [64708.4, 1.008], [64710.5, 0.001], [64717.5, 0.008], [64719.7, 1.474], [64732.0, 0.006], [64736.2, 0.015], [64881.7, 0.0], [64883.2, 3.915], [64901.6, 0.004], [65336.9, 2.293], [65401.6, 1.816], [65589.2, 1.683], [65649.3, 3.822], [65690.0, 0.433], [66625.2, 0.0]]}
{"kind": "depth", "E": 1787095376253, "U": 11316374953233, "u": 11316374958705, "recv_ms": 1787095376311, "bids": [[1000.0, 35.76], [14189.9, 3.178], [14289.9, 1.022], [51752.0, 0.004], [58220.9, 0.002], [61455.4, 0.006], [63719.6, 2.199], [64043.0, 1.593], [64549.1, 0.001], [64615.9, 1.96], [64622.9, 36.168], [64629.5, 0.033], [64638.5, 0.0], [64649.7, 0.018], [64653.1, 0.123], [64654.2, 0.021], [64662.3, 0.11], [64672.2, 0.008], [64673.5, 3.817], [64684.5, 0.012], [64687.2, 0.004], [64689.9, 22.721]], "asks": [[64690.0, 5.471], [64691.5, 0.103], [64692.2, 0.011], [64692.4, 0.003], [64693.8, 0.093], [64704.0, 0.131], [64740.4, 1.36], [64746.0, 0.009], [64746.2, 0.062], [64830.2, 1.501], [64830.7, 0.001], [65013.4, 3.382], [65336.9, 2.293], [65595.7, 19.83], [65660.3, 1.71], [65692.7, 11.246]]}
{"kind": "depth", "E": 1787095376355, "U": 11316374958710, "u": 11316374963151, "recv_ms": 1787095376412, "bids": [[14189.9, 3.528], [14289.9, 0.672], [51752.0, 0.0], [58220.9, 0.002], [62102.3, 0.836], [63689.9, 0.01], [63881.3, 5.794], [63911.6, 2.489], [64043.0, 1.591], [64366.5, 3.112], [64532.0, 0.014], [64532.1, 6.795], [64549.1, 4.691], [64617.4, 1.424], [64622.9, 0.027], [64625.1, 43.189], [64629.6, 1.166], [64630.2, 0.017], [64639.8, 1.07], [64657.3, 0.006], [64658.7, 0.015], [64661.5, 1.303], [64667.7, 0.006], [64672.2, 0.007], [64689.9, 22.723]], "asks": [[64690.0, 5.471], [64690.6, 0.039], [64691.5, 0.026], [64693.8, 0.318], [64702.6, 1.541], [64704.0, 1.031], [64706.0, 0.382], [64718.5, 0.014], [64734.8, 0.074], [64739.7, 0.97], [64739.8, 0.006], [64744.6, 0.098], [64748.8, 0.053], [64761.3, 46.441], [64763.5, 0.013], [64830.8, 5.399], [64847.7, 10.41], [64886.5, 0.002], [64886.6, 7.451], [65336.9, 2.293], [65482.0, 13.347], [65519.9, 3.201], [65592.0, 2.552], [65690.0, 0.413], [71159.0, 0.002]]}
{"kind": "depth", "E": 1787095376457, "U": 11316374963258, "u": 11316374970366, "recv_ms": 1787095376517, "bids": [[1000.0, 35.76], [14189.9, 3.752], [14289.9, 0.378], [14589.9, 0.07], [58220.9, 0.002], [61455.5, 0.004], [62102.3, 0.833], [63689.9, 0.03], [63913.6, 40.232], [64043.0, 1.591], [64366.4, 1.487], [64549.1, 0.001], [64583.6, 0.0], [64623.6, 6.026], [64646.2, 3.976], [64662.4, 0.707], [64663.2, 0.017], [64665.7, 0.006], [64666.3, 0.041], [64667.7, 0.02], [64668.0, 0.219], [64687.2, 0.006]], "asks": [[64690.0, 5.318], [64691.5, 0.026], [64718.5, 0.578], [64734.7, 3.74], [64753.0, 0.066], [64772.2, 0.019], [64787.4, 2.769], [64789.7, 10.0], [64830.8, 0.0], [65013.5, 1.692], [65336.9, 2.293], [65531.0, 4.56], [65552.2, 2.116], [65660.4, 5.391], [65690.0, 0.433]]}
{"kind": "depth", "E": 1787095376559, "U": 11316374970396, "u": 11316374975367, "recv_ms": 1787095376616, "bids": [[1000.0, 35.76], [14189.9, 3.682], [14289.9, 0.238], [14589.9, 0.28], [51751.9, 0.0], [58220.9, 0.002], [61455.4, 0.006], [62102.3, 0.836], [63913.6, 40.857], [64043.0, 1.591], [64549.1, 4.588], [64668.5, 1.158], [64669.9, 0.007], [64672.2, 0.022], [64674.1, 0.013], [64687.2, 0.004], [64689.9, 22.722]], "asks": [[64693.8, 0.093], [64698.0, 0.342], [64746.0, 0.07], [64746.2, 0.001], [64757.2, 0.005], [64761.4, 2.723], [64830.8, 3.918], [64847.7, 5.847], [64886.6, 9.415], [65336.9, 2.293], [65531.0, 6.464], [65983.7, 0.018]]}
{"kind": "depth", "E": 1787095376661, "U": 11316374975439, "u": 11316374979941, "recv_ms": 1787095376720, "bids": [[14189.9, 3.542], [14289.9, 0.126], [14589.9, 0.532], [58220.9, 0.002], [61455.4, 0.008], [62102.3, 0.833], [64043.0, 1.592], [64366.4, 1.486], [64366.5, 3.112], [64591.3, 10.0], [64657.0, 0.005], [64657.1, 0.046], [64657.2, 0.064], [64660.5, 1.502], [64660.6, 0.128], [64660.7, 0.078], [64668.5, 1.158], [64671.5, 0.702], [64672.9, 0.535], [64673.6, 1.277], [64675.3, 0.559], [64676.3, 1.0], [64676.7, 0.18], [64678.3, 0.026], [64678.9, 2.193], [64680.9, 0.456], [64681.7, 0.035], [64684.5, 0.458], [64685.3, 0.086], [64685.4, 0.545], [64686.0, 0.006], [64686.7, 0.236], [64686.9, 0.031], [64687.1, 0.011], [64687.4, 0.008], [64688.1, 0.005], [64689.9, 22.907]], "asks": [[64690.0, 4.17], [64691.5, 0.103], [64693.1, 0.332], [64693.2, 0.223], [64693.7, 0.001], [64693.8, 0.318], [64694.0, 0.001], [64694.3, 0.0], [64694.4, 0.043], [64694.9, 0.016], [64695.5, 0.001], [64697.4, 0.086], [64697.6, 0.01], [64697.8, 0.086], [64698.1, 0.303], [64698.9, 0.658], [64699.5, 1.002], [64700.9, 2.375], [64701.1, 0.64], [64701.3, 0.005], [64701.6, 0.08], [64701.7, 0.001], [64701.9, 0.059], [64704.0, 0.131], [64705.6, 0.003], [64708.0, 0.061], [64708.4, 0.39], [64708.5, 2.319], [64709.5, 0.002], [64710.8, 0.973], [64711.4, 0.005], [64712.1, 1.986], [64715.6, 0.192], [64715.7, 0.193], [64716.6, 0.673], [64717.0, 2.242], [64717.1, 1.31], [64718.3, 0.425], [64718.5, 0.014], [64718.6, 0.659], [64756.3, 6.099], [64765.6, 1.147], [64830.8, 5.399], [64847.7, 10.41], [64886.6, 13.589], [65013.5, 1.693], [65336.9, 2.293], [65563.3, 3.604], [65672.1, 2.28]]}
{"kind": "depth", "E": 1787095376763, "U": 11316374979949, "u": 11316374986838, "recv_ms": 1787095376823, "bids": [[1000.0, 35.76], [14189.9, 3.444], [14289.9, 0.0], [14589.9, 0.756], [58220.9, 0.002], [62086.8, 0.0], [63603.1, 1.887], [63689.9, 0.01], [63870.5, 0.784], [63913.6, 41.076], [64043.0, 1.592], [64532.1, 6.464], [64662.1, 3.532], [64663.4, 0.001], [64666.3, 0.04], [64675.7, 0.004], [64684.5, 0.012], [64685.3, 0.532], [64685.4, 0.004], [64686.2, 0.235], [64686.7, 0.004], [64686.9, 0.572], [64687.2, 0.004], [64689.9, 22.908]], "asks": [[64691.5, 0.18], [64693.0, 0.003], [64693.8, 0.093], [64694.2, 0.245], [64694.6, 0.088], [64694.7, 1.905], [64695.0, 0.11], [64698.1, 0.219], [64698.9, 0.11], [64701.6, 0.0], [64704.0, 1.031], [64705.6, 0.083], [64712.8, 0.003], [64712.9, 1.212], [64714.1, 0.642], [64715.3, 0.058], [64718.1, 0.576], [64769.8, 0.006], [64886.6, 8.269], [65336.9, 2.293], [65445.7, 1.526], [65690.0, 0.413], [65983.7, 0.018]]}
{"kind": "depth", "E": 1787095376865, "U": 11316374986973, "u": 11316374993201, "recv_ms": 1787095376925, "bids": [[1000.0, 35.76], [14189.9, 3.094], [14589.9, 1.106], [58220.9, 0.002], [61455.4, 0.008], [62086.6, 0.695], [62102.3, 0.836], [63881.3, 6.145], [63950.9, 0.782], [64043.0, 1.592], [64494.5, 2.415], [64574.6, 3.867], [64584.7, 0.001], [64584.8, 0.003], [64603.7, 0.0], [64604.3, 1.523], [64618.9, 0.06], [64625.7, 7.197], [64661.3, 0.012], [64662.2, 2.249], [64672.9, 0.536], [64675.7, 0.003], [64684.5, 0.012], [64685.3, 0.532], [64689.9, 22.909]], "asks": [[64690.0, 4.15], [64691.5, 0.026], [64693.8, 0.177], [64694.4, 0.044], [64697.6, 0.011], [64697.8, 0.002], [64728.7, 0.028], [64740.2, 0.029], [64759.0, 9.11], [64761.3, 46.441], [64825.5, 3.865], [64830.2, 2.116], [64875.8, 0.008], [64875.9, 0.003], [64880.8, 0.748], [65336.9, 2.293], [65592.0, 2.325]]}
{"kind": "depth", "E": 1787095376967, "U": 11316374993357, "u": 11316374997597, "recv_ms": 1787095377025, "bids": [[14189.9, 2.73], [14589.9, 1.47], [58220.9, 0.002], [61455.4, 0.008], [62102.3, 0.833], [63689.9, 0.03], [64043.0, 1.592], [64366.5, 3.112], [64549.1, 0.001], [64685.3, 0.086], [64687.2, 0.004], [64689.9, 22.907]], "asks": [[64691.5, 0.18], [64693.1, 0.332], [64693.8, 0.177], [64718.5, 0.168], [64718.6, 0.505], [64721.1, 0.406], [64830.2, 1.501], [64830.8, 0.0], [64880.8, 0.197], [64883.2, 0.031], [65273.2, 1.192], [65336.9, 2.293], [65690.0, 0.433]]}
{"kind": "depth", "E": 1787095377171, "U": 11316375002886, "u": 11316375009425, "recv_ms": 1787095377229, "bids": [[1000.0, 35.76], [14189.9, 2.016], [14589.9, 2.184], [51752.0, 0.0], [58220.9, 0.002], [61455.4, 0.008], [62102.3, 0.833], [63689.9, 0.01], [64043.0, 1.592], [64584.8, 0.0], [64584.9, 0.004], [64609.2, 0.396], [64616.3, 0.103], [64636.6, 0.002], [64636.7, 2.343], [64639.9, 0.007], [64640.0, 0.029], [64645.2, 0.02], [64658.7, 0.04], [64665.3, 0.025], [64675.3, 0.002], [64676.3, 1.557], [64685.3, 0.086], [64687.2, 0.004], [64689.9, 23.943]], "asks": [[64690.0, 4.15], [64691.5, 0.084], [64693.5, 0.017], [64693.8, 0.402], [64697.4, 0.002], [64700.9, 2.376], [64732.8, 0.24], [64740.2, 0.004], [65336.9, 2.293], [65608.6, 0.914], [65690.0, 0.413], [65772.1, 1.37]]}
{"kind": "depth", "E": 1787095377375, "U": 11316375015303, "u": 11316375020479, "recv_ms": 1787095377432, "bids": [[1000.0, 35.76], [14189.9, 1.302], [14589.9, 2.898], [58220.9, 0.002], [61455.4, 0.008], [62102.3, 0.836], [63689.9, 0.03], [63865.1, 14.873], [64043.0, 1.592], [64549.1, 0.001], [64579.9, 0.003], [64631.6, 1.237], [64676.8, 0.006], [64680.2, 0.179], [64687.2, 0.004], [64689.9, 23.942]], "asks": [[64690.0, 4.152], [64691.5, 0.007], [64692.4, 0.011], [64693.8, 0.093], [64698.9, 0.11], [64706.2, 0.256], [64707.4, 1.633], [64718.5, 0.0], [64725.7, 0.003], [64726.6, 0.189], [64727.4, 0.168], [64735.3, 0.267], [64800.0, 21.195], [64830.8, 0.0], [65283.7, 6.091], [65336.9, 2.293], [65690.0, 0.433], [65783.3, 0.608], [65983.7, 0.021]]}
{"kind": "depth", "E": 1787095377579, "U": 11316375025867, "u": 11316375031392, "recv_ms": 1787095377639, "bids": [[14189.9, 0.588], [14589.9, 3.612], [51751.9, 0.0], [51752.0, 0.0], [58220.9, 0.002], [61455.4, 0.008], [62102.3, 0.836], [63689.9, 0.01], [63865.1, 14.638], [64043.0, 1.592], [64061.0, 0.0], [64365.5, 0.0], [64366.4, 1.487], [64366.5, 3.267], [64579.0, 0.017], [64591.4, 0.035], [64592.7, 0.04], [64592.8, 0.0], [64611.4, 0.961], [64612.1, 0.002], [64613.7, 0.015], [64625.1, 6.293], [64625.7, 1.682], [64627.3, 37.009], [64631.5, 2.324], [64632.6, 0.004], [64657.8, 2.323], [64657.9, 1.009], [64664.3, 0.001], [64670.8, 0.117], [64687.2, 0.004], [64689.9, 23.941]], "asks": [[64694.4, 0.044], [64697.6, 0.011], [64717.4, 0.166], [64718.7, 2.477], [64727.9, 0.679], [64728.0, 1.834], [64747.3, 1.468], [64766.8, 0.002], [64786.2, 0.01], [65297.1, 0.012], [65336.9, 2.293], [65595.7, 20.469], [65660.3, 2.09], [65690.0, 0.413], [65983.7, 0.018]]}
{"kind": "depth", "E": 1787095377681, "U": 11316375031467, "u": 11316375041250, "recv_ms": 1787095377739, "bids": [[1000.0, 35.76], [14189.9, 0.336], [14489.9, 0.098], [14589.9, 3.766], [58220.9, 0.002], [64043.0, 1.591], [64366.4, 2.108], [64689.9, 23.944]], "asks": [[64718.7, 2.323], [65013.5, 1.691], [65304.6, 5.478], [65336.9, 2.293], [65461.4, 0.0]]}
{"kind": "depth", "E": 1787095377783, "U": 11316375041347, "u": 11316375046829, "recv_ms": 1787095377840, "bids": [[1000.0, 35.76], [14189.9, 0.21], [14489.9, 0.336], [14589.9, 3.654], [58220.9, 0.002], [61455.4, 0.008], [62102.3, 0.833], [63689.9, 0.03], [63913.6, 40.607], [63966.5, 3.92], [64043.0, 1.591], [64071.1, 1.325], [64366.4, 2.109], [64672.9, 0.419], [64673.6, 1.393], [64674.6, 0.005], [64676.8, 0.012], [64677.8, 0.0], [64683.4, 0.018], [64683.8, 0.005], [64687.2, 0.004], [64689.9, 23.932]], "asks": [[64691.5, 0.084], [64693.7, 0.085], [64694.6, 0.636], [64698.9, 0.11], [64701.1, 1.258], [64708.5, 2.937], [64716.6, 0.002], [64717.3, 0.556], [64717.4, 0.281], [64718.8, 0.193], [65308.8, 1.31], [65336.9, 3.821], [65396.8, 0.0], [65425.9, 0.69], [65563.3, 4.212], [65690.0, 0.433]]}
{"kind": "depth", "E": 1787095377987, "U": 11316375053905, "u": 11316375060909, "recv_ms": 1787095378044, "bids": [[1000.0, 35.76], [14189.9, 0.0], [14489.9, 0.84], [14589.9, 3.36], [58220.9, 0.002], [61455.4, 0.008], [62102.3, 0.833], [63396.2, 0.017], [63579.4, 2.045], [63689.9, 0.01], [63865.1, 14.287], [64043.0, 1.591], [64532.1, 0.0], [64532.2, 6.562], [64534.1, 1.252], [64549.2, 4.834], [64591.4, 3.98], [64591.5, 0.008], [64671.5, 0.084], [64672.8, 0.39], [64678.7, 0.016], [64678.9, 1.575], [64687.2, 0.006], [64689.9, 23.972]], "asks": [[64690.0, 5.349], [64691.5, 0.084], [64692.7, 0.087], [64693.7, 0.168], [64693.8, 0.01], [64697.4, 0.002], [64701.1, 0.64], [64706.2, 0.256], [64708.4, 1.008], [64710.8, 0.355], [64718.5, 0.014], [64718.7, 2.323], [64718.8, 0.039], [64718.9, 0.159], [64723.3, 5.914], [64830.2, 1.501], [64830.8, 5.399], [64847.7, 0.001], [64847.8, 10.409], [64886.6, 8.261], [65336.9, 3.821], [65446.9, 1.602], [65619.9, 2.892], [65690.0, 0.413], [65700.0, 31.31], [66641.9, 0.642]]}
{"kind": "depth", "E": 1787095378191, "U": 11316375065850, "u": 11316375070701, "recv_ms": 1787095378248, "bids": [[14489.9, 1.554], [14589.9, 2.646], [58220.9, 0.002], [61455.4, 0.01], [61982.3, 0.0], [63273.6, 0.0], [63590.2, 7.773], [63689.9, 0.03], [64043.0, 1.591], [64172.4, 9.515], [64366.5, 3.267], [64525.1, 0.003], [64526.1, 0.043], [64609.0, 6.959], [64616.2, 2.397], [64636.5, 0.075], [64636.6, 0.0], [64639.7, 2.321], [64645.1, 0.005], [64672.8, 0.389], [64672.9, 0.535], [64673.5, 2.817], [64673.6, 1.277], [64674.3, 0.312], [64675.3, 0.002], [64676.3, 1.557], [64685.3, 0.086], [64686.9, 0.572]], "asks": [[64691.5, 0.007], [64706.0, 0.382], [64708.4, 1.008], [64710.7, 0.031], [64715.6, 0.192], [64715.7, 0.193], [64716.6, 0.673], [64717.3, 0.0], [64717.4, 0.166], [65336.9, 3.821], [65498.6, 6.982], [65591.0, 3.658], [65690.0, 0.433], [67169.9, 0.0]]}
{"kind": "depth", "E": 1787095378293, "U": 11316375070827, "u": 11316375074835, "recv_ms": 1787095378352, "bids": [[1000.0, 35.76], [14489.9, 1.904], [14589.9, 2.296], [51752.0, 0.0], [58220.9, 0.002], [61336.7, 0.012], [61455.4, 0.01], [62102.3, 0.833], [63396.2, 0.02], [64043.0, 1.591], [64674.3, 0.311], [64676.8, 0.013], [64687.2, 0.004]], "asks": [[64690.0, 5.348], [64703.0, 0.914], [64704.0, 1.031], [65336.9, 3.821], [65616.9, 3.249], [65640.9, 4.259]]}
{"kind": "depth", "E": 1787095378395, "U": 11316375074965, "u": 11316375079134, "recv_ms": 1787095378452, "bids": [[1000.0, 35.76], [14489.9, 2.268], [14589.9, 1.932], [51752.0, 0.0], [58220.9, 0.002], [60691.0, 0.0], [61455.4, 0.008], [61455.5, 0.006], [62102.3, 0.836], [62369.8, 0.002], [62628.0, 0.348], [63689.9, 0.01], [63865.1, 14.053], [64043.0, 1.591], [64172.4, 10.449], [64210.9, 9.344], [64525.9, 0.04], [64526.1, 0.004], [64532.2, 0.093], [64534.1, 1.252], [64549.2, 0.243], [64569.0, 0.071], [64569.2, 0.008], [64627.3, 37.009], [64629.5, 0.033], [64672.7, 0.001], [64676.8, 0.012], [64684.5, 0.458], [64689.9, 23.972]], "asks": [[64691.5, 0.007], [64693.0, 0.228], [64809.0, 0.0], [64809.2, 0.066], [64830.8, 0.0], [64847.8, 0.0], [65336.9, 3.821], [65628.0, 23.462], [65690.0, 0.413]]}
{"kind": "depth", "E": 1787095378497, "U": 11316375079520, "u": 11316375083235, "recv_ms": 1787095378556, "bids": [[14489.9, 2.618], [14589.9, 1.582], [58220.9, 0.002], [62102.3, 1.522], [63886.3, 0.0], [63966.5, 4.701], [64043.0, 1.591], [64366.5, 3.267], [64493.2, 0.001], [64494.5, 0.0], [64495.7, 1.265], [64525.9, 0.001], [64526.8, 0.039], [64670.4, 1.432], [64672.7, 0.0], [64684.5, 0.012], [64687.2, 0.004]], "asks": [[64691.5, 0.084], [64693.0, 0.003], [64693.1, 0.557], [64693.7, 0.168], [64703.0, 0.014], [64704.0, 1.931], [64708.3, 0.002], [64708.4, 0.39], [64710.7, 0.649], [64886.6, 0.019], [64979.5, 1.691], [64979.6, 0.003], [65336.9, 3.823], [65608.6, 1.141], [66873.2, 8.972], [67187.5, 0.157]]}
{"kind": "depth", "E": 1787095378599, "U": 11316375083240, "u": 11316375086653, "recv_ms": 1787095378658, "bids": [[1000.0, 35.76], [14489.9, 2.982], [14589.9, 1.218], [51751.9, 0.0], [51752.0, 0.0], [58220.9, 0.002], [61455.4, 0.008], [63689.9, 0.03], [64043.0, 1.591], [64366.4, 2.108], [64493.4, 11.724], [64532.2, 6.736], [64549.2, 4.933], [64579.9, 0.0], [64606.1, 0.029], [64666.6, 8.002], [64666.8, 0.053], [64668.8, 3.038], [64669.0, 0.002], [64670.4, 1.431], [64671.7, 1.141], [64684.5, 0.012], [64689.9, 23.585]], "asks": [[64690.0, 5.535], [64691.5, 0.161], [64693.1, 0.64], [64693.7, 0.085], [64699.6, 0.277], [64701.3, 0.217], [64704.5, 0.004], [64708.5, 2.319], [64830.8, 5.399], [64847.8, 10.409], [64886.6, 7.969], [65013.5, 1.692], [65336.9, 3.821], [65690.0, 0.433]]}
{"kind": "depth", "E": 1787095378701, "U": 11316375086735, "u": 11316375090926, "recv_ms": 1787095378759, "bids": [[14489.9, 3.346], [14589.9, 0.854], [51752.0, 0.0], [58220.9, 0.002], [61455.4, 0.008], [62102.3, 1.525], [63705.2, 0.035], [63912.6, 2.736], [64029.1, 0.0], [64043.0, 1.591], [64189.6, 0.001], [64350.5, 0.015], [64511.8, 0.022], [64666.8, 0.052], [64684.5, 0.012], [64687.2, 0.004], [64689.9, 23.584]], "asks": [[64691.5, 0.084], [64693.0, 0.311], [64693.1, 0.332], [64701.9, 0.016], [64735.1, 0.026], [64744.0, 1.266], [64841.0, 0.008], [65003.2, 1.453], [65165.8, 0.001], [65328.8, 0.058], [65336.9, 3.821], [65390.6, 3.78], [65591.0, 3.049], [65649.3, 0.78]]}
{"kind": "depth", "E": 1787095378803, "U": 11316375090981, "u": 11316375096875, "recv_ms": 1787095378867, "bids": [[14489.9, 3.696], [14589.9, 0.504], [51752.0, 0.0], [58220.9, 0.002], [61455.4, 0.008], [62102.3, 1.522], [63689.9, 0.01], [64043.0, 1.591], [64366.4, 2.107], [64366.5, 3.267], [64366.7, 0.118], [64528.1, 0.411], [64627.3, 37.303], [64629.5, 0.033], [64671.5, 0.702], [64678.9, 2.193], [64684.5, 0.458], [64689.9, 23.584]], "asks": [[64690.0, 5.378], [64691.5, 0.084], [64693.0, 0.311], [64693.8, 0.01], [64701.1, 0.64], [64708.5, 2.319], [64857.5, 0.036], [64875.9, 0.0], [64876.0, 0.012], [64886.6, 8.337], [65013.5, 1.693], [65019.7, 0.009], [65182.3, 0.131], [65336.9, 3.821], [65345.3, 0.008], [65690.0, 0.413]]}
{"kind": "depth", "E": 1787095379109, "U": 11316375104795, "u": 11316375110377, "recv_ms": 1787095379167, "bids": [[14389.9, 0.644], [14489.9, 3.486], [14589.9, 0.07], [51752.0, 0.0], [58220.9, 0.002], [61455.4, 0.008], [63396.2, 0.011], [63706.1, 0.378], [63751.9, 16.521], [63881.3, 7.511], [64043.0, 1.591], [64366.5, 3.267], [64609.1, 0.002], [64616.2, 2.398], [64623.6, 0.026], [64645.1, 0.006], [64646.2, 0.032], [64662.2, 4.249], [64662.4, 0.141], [64665.7, 0.006], [64669.2, 0.323], [64669.3, 0.469], [64671.5, 0.084], [64675.3, 0.559], [64676.3, 1.0], [64678.3, 0.026], [64678.8, 0.461], [64679.5, 0.103], [64685.3, 0.532], [64686.9, 0.572], [64687.2, 0.004], [64687.3, 0.087], [64687.4, 0.005]], "asks": [[64690.0, 6.538], [64691.5, 0.238], [64693.0, 0.003], [64693.5, 0.019], [64694.7, 1.44], [64695.3, 0.005], [64707.3, 0.728], [64707.4, 1.594], [64717.7, 16.341], [64718.5, 0.0], [64723.0, 0.119], [64732.8, 0.215], [65336.9, 3.821], [65673.8, 0.025]]}
{"kind": "depth", "E": 1787095379211, "U": 11316375110437, "u": 11316375114296, "recv_ms": 1787095379269, "bids": [[1000.0, 35.76], [14389.9, 0.924], [14489.9, 3.276], [14589.9, 0.0], [51752.0, 0.0], [58220.9, 0.002], [61455.4, 0.01], [62102.3, 1.525], [63689.9, 0.01], [63706.1, 0.388], [64043.0, 1.591], [64609.1, 0.003], [64616.2, 2.399], [64621.6, 0.0], [64622.9, 37.813], [64623.7, 0.005], [64627.3, 0.001], [64629.5, 0.033], [64636.5, 0.077], [64639.7, 2.323], [64645.1, 0.007], [64646.3, 0.002], [64647.5, 0.012], [64662.2, 2.249], [64668.9, 2.48], [64669.1, 0.003], [64673.5, 2.817], [64685.3, 0.532], [64687.3, 0.09], [64687.7, 0.003], [64688.1, 0.002], [64689.9, 23.572]], "asks": [[64690.0, 6.539], [64691.5, 0.007], [64694.5, 0.003], [64697.2, 0.004], [64700.9, 2.375], [64702.0, 0.947], [64704.0, 1.031], [64706.0, 0.382], [64708.4, 1.008], [64710.7, 0.031], [64718.1, 0.001], [64723.1, 0.001], [64725.3, 0.026], [64734.7, 0.24], [64755.9, 1.445], [64756.3, 0.099], [65336.9, 3.821], [65690.0, 0.413]]}
{"kind": "depth", "E": 1787095379313, "U": 11316375114370, "u": 11316375118822, "recv_ms": 1787095379374, "bids": [[14389.9, 1.274], [14489.9, 2.926], [58220.9, 0.002], [61455.4, 0.01], [62102.3, 1.522], [63843.2, 0.274], [63870.5, 0.002], [63881.3, 7.745], [64043.0, 1.591], [64590.8, 0.039], [64591.3, 0.0], [64591.4, 2.488], [64591.5, 0.0], [64620.2, 0.628], [64620.4, 1.99], [64622.9, 0.027], [64625.2, 0.023], [64625.4, 6.002], [64627.3, 37.787], [64628.6, 3.793], [64628.7, 1.977], [64629.6, 1.166], [64636.9, 0.0], [64637.0, 0.131], [64648.0, 4.926], [64664.2, 0.572], [64684.9, 0.405], [64685.3, 0.086], [64685.6, 0.237], [64686.2, 0.003], [64686.7, 0.004], [64687.3, 0.09], [64688.5, 0.0], [64688.8, 0.051], [64689.2, 0.0], [64689.3, 0.028], [64689.8, 0.04], [64689.9, 23.557]], "asks": [[64690.0, 6.921], [64691.3, 0.086], [64691.5, 0.315], [64691.6, 0.136], [64691.8, 0.003], [64691.9, 0.097], [64692.0, 0.064], [64692.1, 0.017], [64692.2, 0.321], [64692.3, 0.085], [64693.0, 0.003], [64693.9, 1.666], [64694.5, 0.003], [64695.5, 0.001], [64695.7, 0.002], [64695.8, 0.312], [64696.2, 0.001], [64696.3, 0.31], [64696.7, 0.07], [64698.2, 0.166], [64698.3, 0.032], [64702.1, 0.535], [64703.7, 0.0], [64703.8, 1.822], [64706.2, 0.257], [64712.0, 1.447], [64712.1, 0.01], [64712.2, 2.286], [64713.1, 0.001], [64713.3, 0.022], [64715.9, 0.938], [64717.5, 0.572], [64720.4, 2.471], [64720.5, 1.993], [64733.6, 3.5], [64755.9, 2.22], [64756.3, 6.099], [64759.1, 5.789], [64761.3, 45.932], [64787.4, 1.959], [64789.7, 0.0], [65336.9, 3.88], [65568.2, 3.962], [65673.8, 0.035]]}
{"kind": "depth", "E": 1787095379415, "U": 11316375118922, "u": 11316375123091, "recv_ms": 1787095379474, "bids": [[14389.9, 1.638], [14489.9, 2.562], [51752.0, 0.0], [58220.9, 0.002], [62102.3, 1.525], [63396.2, 0.014], [63689.9, 0.03], [63751.9, 17.618], [63865.1, 13.788], [64043.0, 1.591], [64366.5, 3.257], [64627.2, 0.026], [64627.5, 0.31], [64627.7, 0.018], [64627.9, 0.005], [64628.2, 0.003], [64628.5, 0.001], [64644.9, 0.001], [64645.3, 0.228], [64645.6, 0.0], [64645.9, 0.005], [64646.2, 0.0], [64659.9, 0.0], [64660.0, 0.165], [64660.1, 0.013], [64660.2, 0.131], [64660.3, 0.001], [64660.4, 4.902], [64660.5, 1.332], [64660.6, 0.028], [64660.7, 0.008], [64660.8, 1.289], [64661.8, 0.0], [64662.3, 0.01], [64668.9, 2.326], [64669.1, 0.157], [64669.2, 0.323], [64679.1, 0.098], [64679.2, 0.0], [64679.3, 2.33], [64679.4, 0.002], [64679.5, 0.003], [64679.6, 0.427], [64679.7, 0.258], [64679.8, 0.003], [64679.9, 0.002], [64680.0, 1.031], [64680.1, 0.078], [64680.4, 0.01], [64680.7, 0.002], [64681.0, 0.904], [64681.4, 0.015], [64681.7, 0.003], [64684.5, 0.012], [64687.3, 0.087]], "asks": [[64691.5, 0.007], [64693.0, 0.003], [64693.8, 0.01], [64696.2, 0.001], [64696.4, 0.018], [64696.5, 0.002], [64696.6, 0.017], [64696.7, 0.0], [64696.8, 0.002], [64698.3, 0.0], [64698.6, 0.002], [64698.9, 0.072], [64699.3, 9.776], [64699.6, 0.235], [64699.9, 2.528], [64700.0, 2.931], [64700.1, 0.072], [64700.2, 0.001], [64700.3, 0.002], [64714.1, 0.502], [64715.6, 0.072], [64715.7, 0.043], [64715.8, 0.127], [64715.9, 0.784], [64716.0, 0.009], [64716.1, 0.314], [64719.1, 0.019], [64719.3, 0.075], [64729.7, 2.334], [64730.1, 0.004], [64730.4, 0.116], [64730.7, 0.002], [64731.0, 0.007], [64731.4, 0.001], [64734.6, 0.157], [64734.7, 0.0], [64734.8, 0.004], [64734.9, 0.003], [64747.5, 0.0], [64747.8, 1.24], [64748.1, 1.001], [64748.4, 0.392], [64748.8, 0.011], [65478.1, 6.104], [65608.6, 1.597], [65690.0, 0.433]]}
{"kind": "depth", "E": 1787095379517, "U": 11316375123245, "u": 11316375128258, "recv_ms": 1787095379575, "bids": [[1000.0, 35.76], [14389.9, 1.988], [14489.9, 2.212], [58220.9, 0.002], [61455.4, 0.01], [62102.3, 1.522], [63772.5, 0.944], [64043.0, 1.591], [64532.2, 0.093], [64549.2, 0.243], [64590.8, 0.031], [64592.4, 10.0], [64592.5, 0.01], [64597.9, 3.873], [64617.3, 3.875], [64625.2, 0.005], [64636.7, 6.213], [64645.3, 0.26], [64656.1, 3.871], [64657.9, 1.498], [64679.5, 0.073], [64679.7, 0.398], [64679.8, 0.073], [64680.1, 0.178], [64680.2, 0.279], [64680.5, 0.497], [64680.8, 0.395], [64687.2, 0.004], [64689.9, 23.556]], "asks": [[64699.4, 0.419], [64699.7, 0.093], [64700.0, 3.051], [64700.1, 0.202], [64700.3, 0.072], [64700.5, 0.173], [64700.7, 0.081], [64717.1, 1.352], [64719.0, 0.093], [64719.3, 0.195], [64719.4, 0.177], [64719.6, 0.071], [64719.7, 1.544], [64719.8, 0.089], [64719.9, 0.079], [64734.9, 0.045], [64759.1, 51.673], [64761.3, 0.048], [64787.4, 2.769], [64788.6, 0.223], [64788.7, 10.027], [64830.2, 1.501], [64830.8, 0.0], [64847.8, 0.0], [65336.9, 3.88], [65413.4, 4.579], [65589.2, 3.205]]}
{"kind": "depth", "E": 1787095379619, "U": 11316375128296, "u": 11316375132849, "recv_ms": 1787095379678, "bids": [[14389.9, 2.352], [14489.9, 1.848], [51751.9, 0.0], [58220.9, 0.002], [61455.4, 0.01], [63689.9, 0.01], [63881.3, 8.527], [63913.6, 39.827], [64043.0, 1.591], [64366.4, 2.108], [64493.4, 11.06], [64532.3, 5.615], [64549.2, 4.338], [64620.7, 0.028], [64622.6, 0.395], [64625.1, 44.079], [64627.3, 0.001], [64645.7, 0.032], [64646.0, 0.234], [64646.3, 0.034], [64646.6, 0.034], [64668.8, 3.192], [64669.1, 0.003], [64670.4, 1.434], [64676.9, 0.006], [64679.9, 0.102], [64680.0, 1.231], [64680.3, 0.1], [64680.4, 0.11], [64681.1, 0.034], [64681.4, 0.047], [64681.8, 0.034], [64682.1, 2.644], [64688.8, 0.007]], "asks": [[64690.0, 6.924], [64691.6, 0.002], [64693.2, 0.3], [64698.1, 0.251], [64698.4, 0.045], [64698.8, 0.042], [64699.1, 0.297], [64699.8, 0.311], [64700.2, 0.261], [64700.3, 0.222], [64709.5, 0.005], [64715.8, 0.159], [64716.1, 0.349], [64716.5, 0.208], [64716.8, 0.059], [64717.5, 0.692], [64717.9, 0.14], [64719.1, 0.11], [64719.5, 0.153], [64719.6, 0.221], [64728.9, 0.005], [64733.6, 3.532], [64733.9, 1.075], [64734.2, 0.041], [64734.5, 0.045], [64759.1, 5.789], [64761.3, 45.932], [64830.8, 5.399], [64847.8, 10.409], [64886.6, 10.198], [65013.5, 1.692], [65336.9, 3.88], [65690.0, 0.413], [65946.1, 0.006], [66881.6, 0.0]]}
{"kind": "depth", "E": 1787095379823, "U": 11316375136915, "u": 11316375141520, "recv_ms": 1787095379881, "bids": [[1000.0, 35.76], [14389.9, 3.066], [14489.9, 1.134], [51752.0, 0.0], [58220.9, 0.002], [61455.4, 0.008], [62102.3, 1.522], [63396.2, 0.017], [63741.1, 8.318], [63881.3, 8.878], [64043.0, 1.591], [64584.9, 0.001], [64585.2, 0.027], [64627.6, 0.032], [64628.3, 0.129], [64660.9, 0.075], [64662.0, 0.337], [64665.8, 8.061], [64666.6, 0.002], [64689.9, 23.646]], "asks": [[64690.0, 6.748], [64691.9, 0.013], [64692.3, 0.001], [64693.6, 0.061], [64693.8, 0.235], [64694.1, 0.09], [64701.0, 1.461], [64702.1, 0.474], [64705.6, 0.137], [64708.4, 1.008], [64712.0, 1.393], [64715.0, 0.131], [64721.6, 1.379], [64735.1, 0.026], [64738.9, 0.008], [64876.0, 0.009], [64876.3, 0.003], [65013.5, 1.691], [65336.9, 3.821], [65482.0, 13.119]]}
{"kind": "depth", "E": 1787095380027, "U": 11316375148303, "u": 11316375156202, "recv_ms": 1787095380086, "bids": [[1000.0, 35.76], [14289.9, 0.028], [14389.9, 3.724], [14489.9, 0.448], [58220.9, 0.002], [63689.9, 0.01], [63741.2, 3.291], [63796.2, 2.773], [63920.1, 4.687], [64043.0, 1.591], [64366.5, 3.257], [64660.3, 0.071], [64660.6, 0.198], [64660.7, 0.108], [64661.1, 0.102], [64662.2, 2.349], [64662.6, 0.003], [64662.7, 1.747], [64662.8, 0.059], [64666.5, 0.015], [64668.8, 3.038], [64669.0, 0.156], [64670.7, 0.002], [64671.5, 0.086], [64673.5, 2.929], [64675.8, 0.002], [64676.8, 0.005], [64677.2, 0.007], [64677.4, 0.013], [64677.8, 0.154], [64678.9, 1.421], [64680.1, 0.178], [64680.9, 0.147], [64681.3, 0.157], [64681.7, 0.312], [64681.9, 0.676], [64682.3, 1.57], [64682.4, 0.17], [64682.5, 0.019], [64682.7, 0.048], [64684.5, 0.166], [64685.3, 0.086], [64687.3, 0.084], [64688.0, 0.004], [64688.4, 0.085], [64689.9, 23.562]], "asks": [[64693.8, 0.39], [64695.3, 0.003], [64698.9, 0.227], [64699.1, 0.607], [64700.3, 0.531], [64700.9, 2.066], [64707.2, 0.017], [64708.3, 0.157], [64708.7, 0.007], [64710.5, 0.003], [64711.4, 0.003], [64712.0, 1.393], [64712.1, 0.469], [64712.7, 0.02], [64714.6, 0.057], [64715.3, 0.001], [64716.9, 0.156], [64717.0, 4.474], [64717.7, 16.032], [64720.2, 0.158], [64721.5, 0.001], [64722.1, 0.026], [64726.7, 2.474], [64729.3, 0.0], [65336.9, 3.821], [65552.3, 0.0], [65602.1, 5.632], [65690.0, 0.413], [65934.7, 1.363], [65983.7, 0.015], [71159.0, 0.002]]}
{"kind": "depth", "E": 1787095380129, "U": 11316375156366, "u": 11316375165714, "recv_ms": 1787095380186, "bids": [[1000.0, 35.76], [14289.9, 0.21], [14389.9, 3.71], [14489.9, 0.28], [51752.0, 0.0], [58220.9, 0.002], [61455.4, 0.008], [62102.3, 1.522], [62541.2, 0.001], [63706.1, 0.379], [63933.0, 2.841], [64010.7, 1.568], [64043.0, 1.591], [64625.1, 37.814], [64635.5, 0.0], [64642.4, 2.407], [64643.6, 0.063], [64646.9, 0.061], [64660.5, 1.402], [64661.0, 0.1], [64668.6, 0.157], [64669.0, 0.002], [64669.1, 0.003], [64678.3, 0.026], [64679.6, 0.497], [64679.7, 0.857], [64682.4, 0.711], [64682.6, 0.005], [64689.9, 23.561]], "asks": [[64693.8, 0.165], [64699.9, 2.649], [64746.0, 0.009], [64747.3, 1.529], [64752.0, 0.061], [64763.4, 0.044], [65336.9, 3.821], [65459.8, 5.496], [65673.8, 0.026]]}
{"kind": "depth", "E": 1787095380231, "U": 11316375166277, "u": 11316375172390, "recv_ms": 1787095380289, "bids": [[14289.9, 0.448], [14389.9, 3.598], [14489.9, 0.154], [51752.0, 0.0], [58220.9, 0.002], [58221.0, 0.051], [61455.4, 0.009], [62102.3, 1.525], [63689.9, 0.03], [63706.1, 0.388], [63881.3, 9.112], [63901.8, 4.713], [64043.0, 1.591], [64528.1, 0.414], [64616.4, 0.002], [64631.6, 1.24], [64636.6, 0.001], [64639.9, 0.007], [64645.2, 0.02], [64673.5, 2.929], [64682.3, 0.024], [64682.5, 1.565], [64687.2, 0.004], [64687.6, 0.006], [64687.7, 0.0], [64689.9, 23.568]], "asks": [[64690.0, 6.758], [64691.5, 0.007], [64691.6, 0.117], [64693.5, 0.026], [64693.8, 0.165], [64694.7, 1.433], [64706.0, 0.382], [64716.3, 0.673], [64717.1, 1.352], [64717.3, 0.0], [64722.4, 0.003], [64886.6, 13.617], [65336.9, 3.821], [65673.8, 0.035], [65690.0, 0.433], [65951.5, 0.757], [65983.7, 0.012]]}
{"kind": "depth", "E": 1787095380333, "U": 11316375172483, "u": 11316375178128, "recv_ms": 1787095380395, "bids": [[1000.0, 35.76], [14289.9, 0.686], [14389.9, 3.472], [14489.9, 0.042], [51752.0, 0.0], [58220.9, 0.002], [61455.4, 0.008], [62102.3, 1.522], [63272.3, 0.002], [63741.2, 2.194], [63751.9, 19.654], [63805.7, 3.439], [63838.2, 0.808], [64043.0, 1.591], [64366.5, 3.267], [64525.9, 0.04], [64526.8, 0.0], [64532.3, 6.308], [64636.6, 0.002], [64666.5, 0.015], [64669.0, 0.002], [64677.4, 0.013], [64680.1, 0.178], [64682.6, 0.005], [64685.3, 0.086], [64689.9, 23.57]], "asks": [[64693.8, 0.165], [64698.9, 0.227], [64699.1, 0.607], [64708.3, 0.157], [64716.9, 0.156], [64759.1, 51.578], [64761.3, 0.048], [64886.6, 8.824], [65336.9, 3.821], [65459.8, 6.412], [65519.9, 2.286], [65563.3, 6.007]]}
{"kind": "depth", "E": 1787095380435, "U": 11316375178220, "u": 11316375186653, "recv_ms": 1787095380491, "bids": [[1000.0, 35.76], [14289.9, 1.008], [14389.9, 3.192], [14489.9, 0.0], [58220.9, 0.002], [61455.4, 0.008], [62102.3, 1.525], [63689.9, 0.01], [63816.6, 8.632], [64043.0, 1.591], [64549.2, 0.243], [64549.3, 4.176], [64662.1, 3.589], [64662.8, 0.002], [64666.5, 0.17], [64669.0, 0.157], [64672.6, 0.116], [64673.5, 2.813], [64675.1, 0.557], [64676.0, 2.099], [64677.4, 0.013], [64678.9, 1.88], [64679.6, 0.497], [64679.7, 0.398], [64680.1, 0.333], [64682.6, 0.2], [64682.7, 0.008], [64685.3, 0.782], [64686.9, 0.031], [64687.2, 0.004], [64689.7, 0.097], [64689.9, 23.569]], "asks": [[64690.0, 6.753], [64692.3, 0.001], [64692.7, 0.003], [64693.7, 0.093], [64693.8, 0.002], [64696.3, 0.394], [64698.9, 0.072], [64699.1, 0.297], [64707.3, 0.689], [64707.4, 1.633], [64708.3, 0.002], [64711.3, 0.563], [64712.1, 0.01], [64715.5, 0.559], [64716.3, 0.117], [64716.9, 0.001], [64717.5, 0.685], [64717.7, 16.039], [64830.8, 5.399], [64886.6, 9.621], [65336.9, 3.821], [65429.2, 0.009], [65690.0, 0.413], [65789.7, 4.393]]}
{"kind": "depth", "E": 1787095380639, "U": 11316375203779, "u": 11316375214707, "recv_ms": 1787095380696, "bids": [[1000.0, 35.76], [14289.9, 1.722], [14389.9, 2.478], [51751.9, 0.0], [51752.0, 0.0], [58220.9, 0.002], [61455.4, 0.008], [62102.3, 1.522], [63689.9, 0.03], [63848.9, 2.58], [64043.0, 1.591], [64366.4, 2.108], [64366.5, 3.267], [64549.3, 0.0], [64684.9, 0.113], [64687.2, 0.004], [64689.9, 23.57]], "asks": [[64693.7, 0.085], [64693.8, 0.165], [64694.5, 0.003], [64830.2, 1.501], [64830.8, 0.0], [65336.9, 3.821], [65500.0, 342.417], [65531.0, 7.683], [65690.0, 0.433], [65789.7, 8.947], [71159.0, 0.004]]}
{"kind": "depth", "E": 1787095380741, "U": 11316375214962, "u": 11316375222541, "recv_ms": 1787095380798, "bids": [[1000.0, 35.76], [14289.9, 2.086], [14389.9, 2.114], [58220.9, 0.002], [61088.0, 1.208], [61455.4, 0.008], [62102.3, 1.525], [63707.8, 2.354], [64043.0, 1.591], [64493.4, 0.0], [64495.7, 1.265], [64532.3, 0.0], [64534.1, 1.252], [64678.8, 0.62], [64689.9, 23.569]], "asks": [[64690.0, 6.759], [64694.5, 0.003], [64701.0, 2.079], [64708.4, 1.626], [64715.9, 0.798], [64847.8, 0.0], [64886.6, 0.019], [65013.5, 1.692], [65336.9, 3.821], [65452.3, 6.867], [65466.3, 18.432], [65487.5, 0.116], [65514.4, 11.733], [71159.0, 0.002]]}
{"kind": "depth", "E": 1787095380843, "U": 11316375222585, "u": 11316375228876, "recv_ms": 1787095380901, "bids": [[14289.9, 2.436], [14389.9, 1.764], [58220.9, 0.002], [61455.4, 0.008], [62102.3, 1.522], [63689.9, 0.01], [63706.1, 0.035], [63773.5, 2.371], [64043.0, 1.591], [64493.5, 11.412], [64532.3, 5.774], [64549.3, 4.176], [64627.7, 0.0], [64641.5, 5.013], [64687.2, 0.004], [64689.7, 0.013], [64689.9, 23.652]], "asks": [[64690.0, 6.606], [64691.6, 0.079], [64692.2, 0.011], [64692.3, 0.001], [64692.4, 0.011], [64692.8, 0.02], [64693.2, 0.223], [64693.8, 0.165], [64694.5, 0.228], [64695.8, 0.002], [64698.9, 0.227], [64701.0, 1.461], [64708.4, 1.008], [64830.8, 5.399], [64847.8, 10.409], [64886.6, 13.618], [65336.9, 3.821], [65690.0, 0.413]]}
{"kind": "depth", "E": 1787095381047, "U": 11316375236317, "u": 11316375242135, "recv_ms": 1787095381104, "bids": [[1000.0, 35.76], [14289.9, 3.15], [14389.9, 1.05], [58220.9, 0.002], [61455.4, 0.006], [61455.5, 0.012], [62102.3, 1.525], [63689.9, 0.03], [63719.6, 2.552], [64043.0, 1.591], [64172.4, 10.449], [64662.1, 3.532], [64663.1, 2.379], [64664.3, 0.156], [64676.7, 0.335], [64677.4, 0.168], [64678.3, 0.031], [64679.8, 0.143], [64680.0, 1.69], [64680.1, 0.333], [64682.4, 0.17], [64682.6, 0.57], [64682.7, 0.179], [64684.3, 0.02], [64684.5, 0.166], [64685.3, 0.241], [64687.1, 0.013], [64687.2, 0.004], [64689.9, 23.691]], "asks": [[64690.0, 4.528], [64693.1, 0.332], [64693.2, 0.139], [64693.7, 0.084], [64693.8, 0.002], [64696.2, 0.226], [64697.0, 0.102], [64698.9, 0.072], [64699.1, 0.297], [64702.0, 0.047], [64708.3, 0.002], [64712.2, 2.286], [64712.5, 0.482], [64714.6, 0.0], [64714.9, 0.185], [64715.1, 2.738], [64716.9, 0.001], [64738.5, 1.881], [64752.4, 2.609], [64754.7, 6.99], [64759.0, 1.487], [64759.1, 5.789], [64761.3, 45.802], [64798.3, 0.023], [64798.4, 0.593], [64830.8, 3.464], [64847.8, 6.639], [64886.6, 8.275], [65013.5, 1.693], [65336.9, 3.821], [65466.3, 23.008], [65467.3, 1.251], [65498.6, 7.287], [65579.0, 51.027], [65690.0, 0.433]]}
{"kind": "depth", "E": 1787095381149, "U": 11316375242263, "u": 11316375249118, "recv_ms": 1787095381206, "bids": [[14289.9, 3.5], [14389.9, 0.7], [58220.9, 0.002], [61455.4, 0.006], [62102.3, 1.522], [63696.6, 0.005], [63703.4, 18.398], [63784.2, 13.233], [63913.6, 40.296], [64043.0, 1.591], [64116.2, 0.0], [64631.6, 1.237], [64636.8, 1.386], [64640.0, 0.03], [64641.5, 7.519], [64645.4, 0.496], [64652.5, 0.001], [64662.9, 0.264], [64663.1, 2.322], [64664.3, 0.156], [64671.3, 0.003], [64671.4, 0.0], [64671.5, 0.084], [64676.4, 1.041], [64676.7, 0.335], [64677.4, 0.168], [64678.3, 0.026], [64678.8, 0.002], [64679.8, 0.602], [64680.0, 1.231], [64680.1, 0.333], [64681.1, 0.034], [64682.7, 0.179], [64684.0, 0.003], [64684.5, 0.166], [64685.3, 0.241]], "asks": [[64690.0, 6.248], [64692.4, 0.011], [64693.2, 0.223], [64693.6, 0.063], [64693.7, 0.168], [64693.8, 0.002], [64694.5, 0.228], [64695.7, 0.003], [64696.2, 0.001], [64698.9, 0.072], [64699.1, 0.297], [64699.9, 2.648], [64703.0, 0.914], [64708.3, 0.002], [64712.1, 0.469], [64712.5, 0.023], [64714.7, 0.088], [64715.1, 2.681], [64716.9, 0.001], [64735.3, 0.267], [64756.9, 45.754], [64759.1, 5.789], [64761.3, 0.048], [65336.9, 3.823], [65519.9, 0.0], [65584.6, 3.198], [65683.1, 0.0]]}
{"kind": "depth", "E": 1787095381251, "U": 11316375249125, "u": 11316375255191, "recv_ms": 1787095381310, "bids": [[1000.0, 35.76], [14189.9, 0.056], [14289.9, 3.752], [14389.9, 0.392], [51752.0, 0.0], [58220.9, 0.002], [61455.4, 0.006], [62102.3, 1.525], [62628.0, 1.348], [63061.9, 0.002], [63273.6, 0.3], [63396.2, 0.023], [63689.9, 0.01], [63699.3, 0.025], [63821.5, 0.0], [63881.3, 9.377], [64043.0, 1.591], [64366.5, 3.267], [64664.3, 0.001], [64673.5, 2.813], [64675.1, 0.0], [64676.1, 1.033], [64676.7, 0.18], [64677.4, 0.013], [64680.1, 0.178], [64682.3, 1.57], [64682.4, 0.735], [64682.5, 0.035], [64682.6, 0.005], [64682.7, 0.008], [64682.8, 0.001], [64684.5, 0.612], [64685.3, 0.086], [64687.2, 0.004], [64687.6, 0.003], [64687.7, 0.003], [64687.9, 0.139], [64689.9, 23.688]], "asks": [[64690.0, 5.618], [64693.6, 0.071], [64693.8, 0.157], [64694.5, 0.003], [64695.7, 0.002], [64698.9, 0.227], [64699.1, 0.607], [64701.1, 0.477], [64702.0, 0.947], [64703.0, 0.014], [64706.0, 0.382], [64708.3, 0.157], [64708.4, 0.39], [64710.5, 0.621], [64716.9, 0.156], [65336.9, 3.821], [65563.3, 6.615], [65680.7, 0.011], [65690.0, 0.413], [65773.1, 13.188]]}
{"kind": "depth", "E": 1787095381353, "U": 11316375255350, "u": 11316375270686, "recv_ms": 1787095381417, "bids": [[1000.0, 35.76], [14189.9, 0.28], [14289.9, 3.668], [14389.9, 0.252], [58220.9, 0.002], [61336.7, 3.012], [61455.4, 0.006], [61982.3, 2.0], [62102.3, 1.522], [63719.5, 0.313], [63865.1, 13.437], [63913.6, 41.076], [64043.0, 1.591], [64127.1, 2.424], [64549.3, 0.0], [64672.6, 0.0], [64673.7, 0.428], [64678.2, 0.281], [64684.5, 0.612], [64689.9, 23.87]], "asks": [[64690.0, 5.636], [64693.8, 0.157], [64698.9, 0.228], [64754.7, 52.744], [64756.9, 0.0], [64798.7, 0.018], [64798.8, 0.024], [64830.8, 0.0], [65336.9, 3.821], [65595.7, 22.753], [65789.7, 9.251], [65962.6, 0.649]]}
{"kind": "depth", "E": 1787095381455, "U": 11316375270794, "u": 11316375281261, "recv_ms": 1787095381513, "bids": [[14189.9, 0.504], [14289.9, 3.57], [14389.9, 0.126], [51752.0, 0.0], [58220.9, 0.002], [60691.0, 4.0], [61455.4, 0.006], [63689.9, 0.03], [63800.4, 11.954], [63865.1, 13.202], [64043.0, 1.591], [64366.5, 3.257], [64366.6, 1.485], [64549.3, 4.587], [64569.0, 0.002], [64595.7, 0.053], [64597.6, 0.015], [64600.2, 0.023], [64602.0, 0.04], [64604.7, 0.0], [64609.2, 0.381], [64613.7, 1.198], [64618.2, 0.0], [64622.7, 0.001], [64627.2, 0.011], [64631.7, 0.004], [64636.2, 0.382], [64640.7, 0.001], [64645.2, 0.005], [64649.7, 0.003], [64654.2, 0.006], [64658.7, 0.025], [64663.2, 0.002], [64667.7, 0.005], [64671.3, 0.001], [64671.7, 1.143], [64672.2, 0.007], [64676.7, 0.165], [64682.4, 0.711], [64682.5, 0.059], [64684.5, 0.166], [64687.3, 0.084], [64689.9, 23.873]], "asks": [[64690.0, 5.636], [64692.3, 0.311], [64692.9, 0.088], [64693.2, 0.216], [64693.3, 0.138], [64693.8, 0.157], [64694.5, 0.003], [64697.0, 0.018], [64710.5, 0.619], [64710.7, 0.033], [64719.3, 0.209], [64730.6, 0.026], [64750.3, 0.049], [64750.4, 3.527], [64754.7, 52.759], [64754.9, 0.237], [64759.4, 0.005], [64763.9, 0.0], [64768.4, 1.163], [64772.9, 0.022], [64777.4, 0.0], [64830.2, 1.501], [64830.8, 5.399], [64886.6, 8.276], [65336.9, 3.821], [65531.0, 10.273], [65690.0, 0.433]]}
{"kind": "depth", "E": 1787095381659, "U": 11316375287905, "u": 11316375293973, "recv_ms": 1787095381718, "bids": [[1000.0, 35.76], [14189.9, 1.078], [14289.9, 3.122], [14389.9, 0.0], [51751.9, 0.0], [58220.9, 0.002], [61455.4, 0.006], [62102.3, 1.522], [63689.9, 0.01], [63816.6, 9.022], [63832.8, 0.0], [63860.8, 2.359], [63912.6, 1.642], [64043.0, 1.591], [64495.8, 0.004], [64525.9, 0.04], [64526.7, 0.0], [64610.8, 0.036], [64615.2, 0.015], [64657.0, 0.005], [64657.1, 0.021], [64657.2, 0.064], [64657.5, 0.007], [64660.5, 1.402], [64660.6, 0.198], [64660.7, 0.108], [64662.2, 2.406], [64662.9, 0.207], [64664.3, 0.001], [64672.6, 0.116], [64673.7, 0.312], [64675.3, 0.559], [64676.1, 0.476], [64676.7, 0.165], [64677.4, 0.013], [64679.0, 1.28], [64679.8, 0.143], [64680.1, 0.178], [64682.5, 0.059], [64685.3, 0.627], [64686.9, 0.031], [64687.3, 0.084], [64689.9, 23.873]], "asks": [[64690.0, 5.621], [64693.2, 0.12], [64693.8, 0.39], [64698.9, 0.228], [64699.1, 0.607], [64708.3, 0.157], [64711.4, 0.462], [64712.1, 0.01], [64716.9, 0.156], [64763.5, 0.028], [64767.7, 0.003], [64767.9, 0.015], [65251.7, 0.352], [65336.9, 3.821], [65498.6, 7.515], [65628.0, 22.398], [65690.0, 0.413]]}
{"kind": "depth", "E": 1787095381761, "U": 11316375294168, "u": 11316375298870, "recv_ms": 1787095381819, "bids": [[14189.9, 1.456], [14289.9, 2.744], [58220.9, 0.002], [61455.4, 0.007], [61455.5, 0.01], [62102.3, 1.525], [63803.6, 2.5], [64028.7, 0.0], [64043.0, 1.591], [64366.4, 2.108], [64366.5, 3.267], [64619.6, 0.133], [64671.9, 0.681], [64679.0, 0.821], [64679.3, 2.948], [64679.9, 0.561], [64685.3, 0.086], [64686.9, 0.572], [64689.9, 23.873]], "asks": [[64693.8, 0.39], [64700.6, 1.158], [64708.0, 0.679], [64711.4, 0.003], [64712.3, 0.925], [64772.3, 7.423], [65013.5, 1.692], [65336.9, 3.822], [65591.0, 2.289], [65983.7, 0.012]]}
{"kind": "depth", "E": 1787095381863, "U": 11316375298911, "u": 11316375305533, "recv_ms": 1787095381922, "bids": [[1000.0, 35.76], [14189.9, 1.806], [14289.9, 2.394], [51752.0, 0.0], [58220.9, 0.002], [61455.4, 0.006], [61845.0, 0.129], [61954.1, 0.001], [62063.5, 0.0], [62102.3, 1.522], [62173.1, 0.0], [62282.8, 0.0], [62392.8, 0.0], [62502.9, 0.0], [62613.3, 0.016], [62723.8, 0.0], [62834.5, 0.003], [62945.5, 0.002], [63056.6, 0.01], [63167.9, 0.0], [63279.4, 0.044], [63391.1, 0.0], [63472.8, 3.814], [63503.0, 0.008], [63615.1, 0.003], [63689.9, 0.03], [63727.4, 0.0], [63816.6, 9.803], [63839.9, 0.0], [63952.6, 0.0], [64043.0, 1.593], [64065.5, 0.0], [64178.6, 0.0], [64291.9, 0.002], [64405.4, 0.112], [64519.1, 0.02], [64525.9, 0.001], [64526.7, 0.039], [64549.3, 4.686], [64582.6, 0.775], [64585.6, 1.232], [64587.4, 3.346], [64624.0, 2.336], [64628.4, 0.019], [64664.3, 0.001], [64671.3, 0.003], [64671.7, 1.141], [64676.7, 0.165], [64677.4, 0.013], [64680.1, 0.178], [64682.5, 0.059], [64685.3, 0.086], [64687.3, 0.084], [64689.9, 23.87]], "asks": [[64690.0, 4.531], [64692.2, 0.011], [64692.3, 0.001], [64692.4, 0.011], [64692.9, 0.004], [64693.1, 0.178], [64693.2, 0.005], [64693.3, 0.054], [64693.7, 0.001], [64693.8, 0.39], [64697.0, 0.102], [64698.0, 0.342], [64698.1, 0.244], [64698.9, 0.228], [64699.1, 0.607], [64700.6, 0.54], [64708.0, 0.061], [64708.3, 0.157], [64716.9, 0.156], [64747.1, 0.005], [64776.7, 0.039], [64796.4, 0.0], [64798.3, 0.177], [64798.4, 0.811], [64801.2, 2.319], [64830.8, 5.399], [64861.4, 0.0], [64886.6, 8.087], [64975.9, 0.0], [65090.6, 0.001], [65205.5, 0.0], [65320.7, 0.002], [65336.9, 3.822], [65436.0, 0.032], [65526.2, 0.001], [65546.7, 14.567], [65551.5, 0.0], [65602.1, 6.392], [65628.0, 23.462], [65667.2, 0.001], [65690.0, 0.433], [65776.8, 1.838], [65783.1, 0.003], [65899.3, 0.022], [65951.3, 0.0], [65983.7, 0.009], [66015.6, 0.004], [66132.1, 0.0], [66248.9, 0.0], [66365.9, 0.002], [66483.0, 0.0], [66600.4, 0.001], [66718.0, 0.009]]}
{"kind": "depth", "E": 1787095382067, "U": 11316375312694, "u": 11316375323780, "recv_ms": 1787095382128, "bids": [[14189.9, 2.52], [14289.9, 1.68], [58220.9, 0.002], [61455.4, 0.008], [62102.3, 1.525], [63287.9, 1.354], [63396.2, 0.026], [63493.1, 1.03], [63689.9, 0.01], [63770.9, 0.0], [63800.4, 11.329], [63831.8, 0.274], [63902.9, 1.563], [63918.1, 3.752], [64043.0, 1.591], [64366.4, 2.109], [64366.5, 3.257], [64637.2, 0.015], [64641.6, 2.055], [64662.8, 0.059], [64663.1, 2.322], [64663.3, 0.007], [64664.3, 0.001], [64665.9, 2.321], [64671.9, 0.063], [64673.5, 2.811], [64676.7, 0.165], [64677.4, 0.013], [64678.3, 0.026], [64679.3, 2.33], [64679.6, 0.956], [64679.8, 0.143], [64679.9, 0.102], [64680.1, 0.178], [64682.5, 0.059], [64684.3, 0.02], [64685.3, 0.086], [64687.3, 0.084], [64689.9, 23.885]], "asks": [[64690.0, 4.683], [64690.7, 0.001], [64690.9, 0.039], [64693.1, 0.101], [64693.3, 0.138], [64693.8, 0.166], [64698.0, 0.342], [64698.1, 0.251], [64698.9, 0.228], [64699.1, 0.607], [64708.3, 0.157], [64708.4, 1.008], [64710.5, 0.001], [64712.0, 1.852], [64712.3, 0.466], [64714.6, 0.057], [64715.2, 2.017], [64716.9, 0.156], [64798.3, 0.254], [65336.9, 3.824], [65452.3, 6.104], [65482.0, 12.374], [65510.4, 3.048], [65609.1, 0.001], [65639.7, 0.001], [65690.0, 0.413]]}
{"kind": "depth", "E": 1787095382169, "U": 11316375323842, "u": 11316375333994, "recv_ms": 1787095382228, "bids": [[1000.0, 35.76], [14189.9, 2.87], [14289.9, 1.33], [51752.0, 0.002], [58220.9, 0.002], [61455.4, 0.006], [61455.5, 0.012], [62102.3, 1.522], [63706.1, 0.035], [63770.9, 0.008], [63772.1, 0.008], [63902.9, 0.0], [64043.0, 1.591], [64640.0, 0.031], [64646.0, 0.249], [64655.0, 0.003], [64656.1, 3.873], [64662.5, 0.404], [64662.8, 0.002], [64667.2, 9.316], [64667.3, 0.001], [64668.8, 3.036], [64669.0, 0.002], [64670.3, 0.003], [64676.8, 0.012], [64677.2, 0.0], [64677.4, 0.013], [64679.2, 0.459], [64679.4, 0.002], [64679.6, 0.497], [64682.5, 0.059], [64685.3, 0.627], [64685.4, 0.004], [64686.9, 0.031], [64689.9, 23.806]], "asks": [[64690.0, 6.8], [64692.2, 0.321], [64692.3, 0.085], [64692.4, 0.011], [64692.9, 0.088], [64693.6, 0.061], [64693.7, 0.001], [64693.8, 0.166], [64694.5, 0.005], [64694.7, 1.433], [64695.9, 0.434], [64697.0, 0.018], [64697.6, 0.012], [64698.0, 0.265], [64698.1, 0.148], [64698.9, 0.228], [64699.1, 0.607], [64702.0, 0.904], [64703.0, 0.014], [64708.3, 0.157], [64716.9, 0.156], [64718.5, 0.014], [64720.4, 3.697], [64722.1, 10.026], [64726.3, 1.345], [64754.7, 52.759], [64755.9, 2.218], [64756.3, 6.101], [64847.8, 10.409], [64880.8, 1.114], [64880.9, 6.722], [64886.6, 10.246], [65336.9, 3.822], [65445.7, 2.289], [65498.6, 7.773], [65563.3, 6.92], [65607.8, 0.008], [65673.8, 0.027]]}
{"kind": "depth", "E": 1787095382271, "U": 11316375334105, "u": 11316375340380, "recv_ms": 1787095382328, "bids": [[1000.0, 35.76], [14189.9, 3.234], [14289.9, 0.966], [51752.0, 0.0], [58220.9, 0.002], [61455.4, 0.006], [61455.5, 0.01], [62102.3, 1.525], [63689.9, 0.03], [63719.5, 1.88], [63816.6, 10.428], [63843.2, 0.548], [64043.0, 1.591], [64650.4, 0.052], [64654.8, 0.017], [64673.5, 2.811], [64684.3, 0.02], [64685.3, 0.086], [64686.9, 0.572], [64688.8, 0.007], [64688.9, 0.046], [64689.5, 0.084], [64689.9, 23.807]], "asks": [[64693.8, 0.391], [64696.2, 0.001], [64697.6, 0.011], [64698.0, 0.188], [64698.1, 0.148], [64706.0, 0.382], [64717.1, 1.359], [64717.7, 6.032], [64754.7, 7.005], [64765.7, 45.6], [64798.3, 0.331], [64830.8, 3.933], [64847.8, 7.542], [64886.6, 8.276], [65336.9, 3.822], [65531.0, 11.187], [65563.3, 7.681], [65607.8, 0.016], [65609.1, 0.009], [65617.8, 0.715], [65673.8, 0.035], [65690.0, 0.433]]}
{"kind": "depth", "E": 1787095382373, "U": 11316375340533, "u": 11316375347290, "recv_ms": 1787095382439, "bids": [[14189.9, 3.584], [14289.9, 0.616], [58220.9, 0.002], [61455.4, 0.006], [63741.1, 8.161], [63913.6, 42.639], [63920.1, 5.624], [64043.0, 1.591], [64366.5, 3.267], [64567.5, 0.0], [64631.6, 1.24], [64659.2, 0.022], [64684.3, 0.02], [64687.4, 0.005], [64689.9, 23.885]], "asks": [[64690.0, 6.801], [64692.6, 0.103], [64693.8, 0.391], [64694.5, 0.003], [64698.0, 0.342], [64698.1, 0.174], [64710.3, 0.078], [64710.7, 0.033], [64735.3, 0.267], [64767.7, 0.0], [65336.9, 3.822], [65466.3, 23.161], [65660.3, 4.371]]}
{"kind": "depth", "E": 1787095382475, "U": 11316375347432, "u": 11316375352875, "recv_ms": 1787095382535, "bids": [[1000.0, 35.76], [14189.9, 3.78], [14289.9, 0.336], [14589.9, 0.084], [58220.9, 0.002], [62102.3, 1.522], [63396.2, 0.029], [63689.9, 0.01], [63692.2, 0.009], [63708.8, 0.0], [64043.0, 1.591], [64663.6, 0.397], [64668.0, 0.234], [64689.9, 23.889]], "asks": [[64693.8, 0.391], [65336.9, 3.822], [65634.5, 0.686], [65690.0, 0.413]]}
{"kind": "depth", "E": 1787095382577, "U": 11316375352950, "u": 11316375358840, "recv_ms": 1787095382635, "bids": [[1000.0, 35.76], [14189.9, 3.654], [14289.9, 0.224], [14589.9, 0.322], [58220.9, 0.002], [61455.4, 0.006], [62102.3, 1.525], [63689.9, 0.03], [64043.0, 1.591], [64549.3, 0.0], [64549.4, 4.593], [64672.4, 0.015], [64687.4, 0.005], [64689.9, 23.888]], "asks": [[64693.8, 0.166], [64698.0, 0.265], [64698.1, 0.148], [64830.2, 1.501], [64830.8, 0.0], [64830.9, 3.994], [64847.8, 7.543], [64886.6, 0.019], [64886.7, 10.533], [65336.9, 3.822], [65690.0, 0.433]]}
{"kind": "depth", "E": 1787095382679, "U": 11316375358870, "u": 11316375364596, "recv_ms": 1787095382737, "bids": [[14189.9, 3.542], [14289.9, 0.098], [14589.9, 0.56], [51751.9, 0.0], [58220.9, 0.002], [61455.4, 0.006], [61455.5, 0.008], [62102.3, 1.522], [63380.0, 0.329], [63451.9, 0.009], [63523.7, 0.854], [63595.6, 0.009], [63667.5, 0.0], [63739.3, 0.0], [63755.1, 1.885], [63811.2, 0.0], [63883.0, 0.156], [63954.9, 0.001], [64026.8, 4.496], [64043.0, 1.591], [64366.5, 3.267], [64549.4, 4.593], [64667.3, 0.001], [64669.0, 0.002], [64676.8, 0.027], [64677.4, 0.013], [64679.4, 0.002], [64682.5, 0.059], [64685.3, 0.086], [64689.9, 23.886]], "asks": [[64690.0, 6.291], [64692.3, 0.001], [64692.4, 0.003], [64693.1, 0.024], [64693.2, 0.088], [64693.8, 0.174], [64694.5, 0.003], [64694.7, 1.35], [64695.9, 0.124], [64698.0, 0.265], [64698.1, 0.148], [64698.9, 0.228], [64699.1, 0.607], [64702.1, 0.515], [64708.2, 0.215], [64708.3, 0.002], [64708.4, 0.39], [64710.5, 0.619], [64716.9, 0.156], [64830.9, 3.994], [64886.7, 1.941], [65320.2, 1.215], [65336.9, 3.822], [65392.1, 0.01], [65464.0, 1.56], [65535.8, 0.0], [65607.7, 0.001], [65679.5, 0.001], [65751.4, 0.004], [65823.3, 0.0], [65895.1, 0.017], [65967.0, 0.001]]}
{"kind": "depth", "E": 1787095382781, "U": 11316375364687, "u": 11316375369882, "recv_ms": 1787095382842, "bids": [[1000.0, 35.76], [14189.9, 3.374], [14289.9, 0.0], [14589.9, 0.826], [58220.9, 0.002], [61455.4, 0.006], [62102.3, 1.525], [63719.5, 3.29], [63865.1, 12.936], [64043.0, 1.591], [64366.4, 2.108], [64662.5, 0.347], [64663.0, 0.126], [64687.4, 0.005], [64689.9, 23.888]], "asks": [[64690.0, 6.668], [64692.4, 0.011], [64693.8, 0.166], [64698.0, 0.265], [64698.1, 0.148], [64708.3, 0.002], [64708.4, 0.39], [64710.5, 0.619], [64714.6, 0.0], [64714.8, 0.062], [64726.0, 0.253], [64886.7, 8.661], [65013.5, 1.692], [65336.9, 3.821], [65595.7, 22.936]]}
{"kind": "depth", "E": 1787095382883, "U": 11316375369922, "u": 11316375388348, "recv_ms": 1787095382943, "bids": [[1000.0, 35.76], [14189.9, 3.024], [14589.9, 1.176], [58220.9, 0.002], [61455.4, 0.006], [62731.9, 0.0], [63396.2, 0.026], [63689.9, 0.01], [64043.0, 1.591], [64667.3, 0.156], [64669.0, 0.157], [64672.1, 0.041], [64677.4, 0.168], [64679.4, 0.002], [64679.5, 0.228], [64682.5, 0.214], [64685.3, 0.241], [64689.9, 23.883]], "asks": [[64690.0, 7.177], [64692.4, 0.669], [64692.5, 1.727], [64693.8, 0.011], [64695.8, 0.312], [64698.0, 0.342], [64698.1, 0.174], [64698.9, 0.073], [64699.1, 0.297], [64700.5, 0.791], [64707.9, 0.622], [64708.0, 0.059], [64708.2, 0.06], [64716.9, 0.001], [64721.7, 4.148], [64826.0, 0.0], [65336.9, 3.821], [65690.0, 0.413]]}
{"kind": "depth", "E": 1787095382985, "U": 11316375388954, "u": 11316375423366, "recv_ms": 1787095383048, "bids": [[14189.9, 2.66], [14589.9, 1.54], [58220.9, 0.002], [61455.4, 0.006], [61455.5, 0.006], [62102.3, 1.522], [63072.6, 1.108], [63396.2, 0.029], [63837.1, 1.567], [63920.1, 4.687], [64043.0, 1.591], [64366.4, 2.107], [64366.5, 3.257], [64525.9, 0.04], [64526.7, 0.0], [64547.3, 0.016], [64627.7, 0.018], [64629.7, 0.312], [64637.8, 0.0], [64643.3, 0.072], [64644.6, 0.069], [64651.1, 0.035], [64651.3, 0.002], [64653.3, 0.43], [64657.9, 0.312], [64658.4, 8.001], [64658.5, 2.594], [64658.7, 0.0], [64659.9, 0.05], [64660.2, 0.081], [64661.0, 0.1], [64661.4, 0.057], [64662.4, 0.141], [64663.0, 0.069], [64664.3, 0.156], [64666.8, 0.002], [64667.2, 1.318], [64667.3, 0.001], [64667.6, 0.026], [64667.7, 0.003], [64668.3, 0.001], [64668.4, 0.169], [64668.8, 1.957], [64669.0, 0.0], [64669.2, 0.477], [64670.1, 0.002], [64670.5, 0.001], [64670.6, 0.017], [64671.3, 0.117], [64672.0, 0.013], [64672.1, 0.026], [64672.6, 0.0], [64673.0, 0.174], [64673.9, 2.319], [64674.0, 2.122], [64674.6, 0.005], [64675.3, 0.002], [64675.4, 0.008], [64675.9, 0.085], [64676.2, 0.062], [64676.7, 0.162], [64676.8, 0.02], [64677.0, 2.803], [64677.1, 0.252], [64677.4, 0.168], [64677.6, 0.462], [64677.8, 0.0], [64678.2, 0.301], [64678.3, 0.074], [64678.4, 0.011], [64678.8, 0.003], [64679.0, 0.828], [64679.2, 0.0], [64679.4, 0.421], [64679.5, 0.227], [64679.6, 0.078], [64679.7, 0.398], [64680.1, 1.415], [64680.2, 0.588], [64680.3, 0.327], [64680.9, 0.127], [64681.3, 0.003], [64681.4, 0.063], [64681.7, 0.003], [64682.0, 0.243], [64682.2, 0.307], [64682.3, 0.025], [64682.4, 0.17], [64682.5, 0.019], [64682.7, 0.001], [64683.0, 0.603], [64683.3, 0.151], [64683.5, 0.001], [64683.8, 0.088], [64684.1, 0.001], [64684.2, 0.96], [64684.3, 0.02], [64684.4, 0.001], [64684.5, 0.012], [64684.6, 0.088], [64684.8, 0.011], [64684.9, 0.115], [64685.0, 0.488], [64685.2, 0.136], [64685.3, 4.5], [64685.4, 0.724], [64685.5, 0.016], [64685.6, 0.005], [64685.7, 0.0], [64686.2, 0.006], [64686.8, 0.989], [64686.9, 0.085], [64687.0, 0.056], [64687.1, 0.0], [64687.3, 0.0], [64687.4, 0.005], [64687.5, 0.382], [64687.7, 0.0], [64687.8, 0.054], [64687.9, 0.055], [64688.0, 0.043], [64688.4, 0.001], [64688.8, 0.007], [64688.9, 0.005], [64689.1, 0.0], [64689.5, 0.002], [64689.7, 0.012], [64689.8, 0.025], [64689.9, 7.712]], "asks": [[64690.0, 9.361], [64690.1, 0.018], [64690.6, 0.123], [64691.2, 0.003], [64691.3, 0.086], [64691.5, 0.007], [64691.6, 0.136], [64692.0, 0.155], [64692.1, 0.027], [64692.4, 0.66], [64692.5, 0.085], [64692.6, 0.101], [64693.0, 0.002], [64693.1, 0.332], [64693.2, 0.223], [64693.5, 0.022], [64693.7, 0.017], [64693.8, 0.663], [64693.9, 0.003], [64694.4, 0.044], [64694.5, 0.003], [64694.6, 0.271], [64694.7, 1.35], [64694.8, 7.404], [64694.9, 0.007], [64695.6, 0.0], [64695.9, 0.04], [64696.3, 0.31], [64696.6, 0.017], [64696.7, 0.0], [64696.8, 0.005], [64698.1, 0.251], [64698.9, 0.057], [64699.0, 0.558], [64699.1, 0.294], [64699.7, 0.152], [64700.5, 0.173], [64702.2, 0.044], [64703.2, 0.026], [64704.0, 1.035], [64704.5, 0.004], [64705.4, 0.038], [64705.6, 0.137], [64707.5, 0.027], [64707.9, 0.004], [64708.3, 0.002], [64708.4, 0.39], [64708.9, 0.003], [64709.2, 0.294], [64709.6, 0.001], [64710.4, 0.169], [64710.7, 0.031], [64710.9, 1.703], [64711.7, 0.063], [64712.0, 1.393], [64713.0, 0.084], [64713.2, 4.236], [64713.3, 0.079], [64713.6, 0.686], [64714.4, 0.172], [64714.8, 0.005], [64715.0, 0.687], [64715.1, 2.796], [64715.8, 0.249], [64715.9, 0.77], [64716.2, 0.03], [64716.3, 0.002], [64716.9, 0.001], [64717.5, 0.685], [64718.5, 0.0], [64719.3, 0.195], [64720.4, 2.471], [64720.7, 0.0], [64721.1, 0.336], [64721.7, 0.148], [64722.1, 0.026], [64723.0, 0.029], [64726.1, 0.326], [64744.4, 0.396], [64747.0, 0.018], [64761.3, 45.646], [64765.6, 7.796], [64765.7, 0.002], [64798.3, 0.023], [64798.4, 0.593], [64844.9, 2.47], [64886.7, 8.629], [65336.9, 3.821], [65459.8, 5.497], [65482.0, 12.032], [65983.7, 0.003], [66894.4, 1.346]]}
{"kind": "depth", "E": 1787095383087, "U": 11316375423424, "u": 11316375435871, "recv_ms": 1787095383145, "bids": [[1000.0, 35.76], [14189.9, 2.31], [14589.9, 1.89], [58220.9, 0.002], [61455.4, 0.006], [62102.3, 1.525], [63689.9, 0.03], [63706.1, 0.027], [63741.2, 1.097], [63881.3, 10.314], [63920.1, 3.749], [64043.0, 1.591], [64547.3, 0.015], [64659.9, 0.0], [64664.3, 0.001], [64667.1, 1.343], [64669.1, 0.003], [64669.2, 0.323], [64674.7, 0.021], [64676.2, 0.042], [64677.1, 0.097], [64677.4, 0.013], [64677.6, 0.003], [64678.3, 0.074], [64678.7, 0.474], [64680.3, 0.172], [64682.2, 0.144], [64682.3, 0.033], [64683.0, 0.157], [64683.2, 0.001], [64683.7, 0.457], [64684.2, 0.959], [64684.9, 0.115], [64685.1, 0.001], [64685.3, 3.959], [64685.4, 0.553], [64685.5, 0.016], [64685.6, 0.005], [64685.7, 0.541], [64685.8, 0.086], [64685.9, 0.02], [64686.9, 0.093], [64687.2, 0.088], [64688.8, 0.055], [64689.9, 7.717]], "asks": [[64691.9, 0.344], [64692.1, 0.017], [64692.4, 0.002], [64693.0, 0.227], [64693.7, 0.001], [64693.8, 0.003], [64694.4, 0.318], [64694.5, 0.567], [64694.6, 0.171], [64694.7, 1.35], [64696.2, 0.001], [64698.9, 0.305], [64699.1, 0.604], [64699.8, 0.314], [64701.0, 2.361], [64702.0, 0.004], [64702.9, 1.404], [64703.0, 0.011], [64703.2, 0.006], [64705.4, 0.058], [64708.3, 0.157], [64708.9, 0.001], [64709.3, 2.753], [64710.9, 1.244], [64711.1, 2.73], [64713.0, 0.014], [64713.3, 0.022], [64713.6, 0.743], [64716.9, 0.156], [64717.6, 1.331], [64718.6, 0.505], [64718.7, 2.477], [64718.9, 0.005], [64720.1, 0.07], [64736.2, 0.016], [64765.6, 1.147], [64781.6, 1.278], [64810.6, 0.0], [64886.7, 1.965], [65013.5, 1.693], [65336.9, 3.821], [65673.8, 0.027], [65690.0, 0.433]]}
{"kind": "depth", "E": 1787095383189, "U": 11316375436001, "u": 11316375447530, "recv_ms": 1787095383247, "bids": [[1000.0, 35.76], [14189.9, 1.946], [14589.9, 2.254], [58220.9, 0.002], [61455.4, 0.006], [62102.3, 1.522], [62743.8, 2.308], [63706.1, 0.035], [63749.9, 2.061], [63751.9, 20.908], [63881.3, 10.665], [63886.2, 0.001], [64043.0, 1.591], [64525.9, 0.001], [64526.7, 0.0], [64537.4, 0.132], [64621.2, 0.0], [64625.2, 0.015], [64638.1, 1.286], [64658.4, 0.001], [64658.5, 0.073], [64661.4, 0.0], [64662.1, 3.591], [64662.3, 2.01], [64665.0, 0.004], [64668.9, 2.48], [64669.0, 0.0], [64670.3, 0.002], [64670.4, 1.45], [64670.6, 0.001], [64671.3, 0.001], [64672.9, 0.535], [64674.0, 1.565], [64675.3, 0.559], [64682.2, 0.7], [64682.3, 0.025], [64683.2, 0.001], [64683.7, 0.457], [64684.9, 0.115], [64685.1, 0.001], [64685.3, 2.407], [64685.4, 0.012], [64685.5, 0.557], [64685.6, 0.005], [64685.7, 0.0], [64685.8, 0.086], [64685.9, 0.004], [64686.0, 0.006], [64686.9, 0.047], [64687.0, 1.663], [64687.6, 0.087], [64689.9, 7.721]], "asks": [[64690.0, 9.277], [64693.0, 0.002], [64694.2, 0.28], [64694.3, 0.008], [64694.4, 0.199], [64694.5, 0.559], [64694.7, 1.35], [64696.2, 0.239], [64698.8, 0.043], [64698.9, 0.305], [64699.1, 0.913], [64700.3, 0.222], [64707.4, 1.594], [64708.4, 1.008], [64710.5, 0.001], [64711.1, 2.271], [64711.3, 0.104], [64711.5, 0.49], [64713.6, 0.686], [64713.9, 1.654], [64715.0, 0.131], [64715.1, 2.681], [64715.6, 0.628], [64715.7, 0.158], [64716.3, 0.009], [64717.1, 1.352], [64718.4, 1.509], [64718.7, 2.323], [64736.2, 0.015], [64738.7, 0.039], [64782.3, 0.005], [64886.7, 8.529], [65336.9, 3.821], [65457.8, 0.915], [65498.6, 8.002], [65983.7, 0.006]]}
{"kind": "depth", "E": 1787095383291, "U": 11316375447610, "u": 11316375456083, "recv_ms": 1787095383351, "bids": [[14189.9, 1.596], [14589.9, 2.604], [58220.9, 0.002], [62102.3, 1.525], [63396.2, 0.026], [63689.9, 0.01], [63920.1, 5.624], [64043.0, 1.591], [64366.5, 3.257], [64537.4, 0.093], [64538.2, 2.777], [64574.6, 3.867], [64585.2, 0.024], [64585.3, 0.003], [64587.2, 3.713], [64587.4, 1.027], [64618.8, 0.046], [64629.7, 0.102], [64636.9, 0.21], [64637.0, 0.132], [64653.3, 0.31], [64656.2, 0.068], [64658.0, 8.01], [64660.9, 0.295], [64662.3, 0.01], [64668.9, 2.326], [64673.5, 2.811], [64677.1, 0.1], [64680.5, 0.513], [64681.4, 0.047], [64682.2, 0.7], [64682.3, 0.025], [64683.7, 0.011], [64684.3, 0.466], [64684.8, 0.011], [64684.9, 0.116], [64685.1, 0.0], [64685.2, 0.136], [64685.3, 2.469], [64685.6, 0.005], [64685.7, 0.0], [64685.8, 0.086], [64685.9, 1.549], [64686.9, 0.031], [64687.0, 0.056], [64687.1, 0.002], [64687.2, 0.004], [64687.3, 0.0], [64687.6, 0.003], [64687.7, 0.0], [64687.8, 0.07], [64689.9, 7.647]], "asks": [[64690.0, 9.363], [64691.8, 0.004], [64692.1, 0.018], [64693.0, 0.002], [64693.8, 0.002], [64694.1, 0.09], [64694.2, 0.161], [64694.4, 0.199], [64694.7, 1.35], [64696.1, 0.002], [64696.2, 0.001], [64697.1, 0.027], [64698.8, 0.136], [64698.9, 0.212], [64701.0, 2.361], [64702.0, 0.904], [64702.9, 3.258], [64704.0, 0.135], [64706.0, 0.382], [64713.2, 0.236], [64713.9, 1.597], [64714.3, 0.072], [64714.6, 10.0], [64718.4, 1.355], [64736.1, 1.842], [64761.3, 45.646], [64801.0, 27.352], [64801.2, 0.0], [64825.5, 3.865], [65336.9, 3.821], [65459.8, 6.412], [65482.0, 11.804], [65673.8, 0.035], [65690.0, 0.413]]}
{"kind": "depth", "E": 1787095383393, "U": 11316375456126, "u": 11316375465951, "recv_ms": 1787095383450, "bids": [[1000.0, 35.76], [14189.9, 1.232], [14589.9, 2.968], [58220.9, 0.002], [61455.4, 0.006], [63751.9, 22.005], [63865.1, 12.701], [64043.0, 1.591], [64527.5, 0.039], [64538.2, 2.738], [64651.9, 0.178], [64657.0, 0.003], [64657.1, 0.019], [64657.2, 0.062], [64660.0, 0.105], [64660.5, 1.4], [64660.6, 0.196], [64660.7, 0.106], [64682.2, 0.152], [64682.3, 0.025], [64683.2, 0.447], [64684.2, 0.959], [64684.3, 0.02], [64684.9, 0.116], [64685.5, 0.016], [64686.0, 1.095], [64686.9, 0.047], [64687.1, 0.002], [64687.8, 0.054], [64689.9, 7.644]], "asks": [[64691.8, 0.004], [64692.1, 0.018], [64693.1, 0.332], [64694.3, 0.246], [64694.4, 0.199], [64694.6, 0.171], [64696.2, 0.001], [64712.1, 0.01], [64718.5, 0.0], [64761.3, 0.048], [64767.9, 45.496], [65283.7, 5.404], [65336.9, 3.823], [65459.8, 7.327], [65482.0, 11.546], [65714.0, 0.0]]}
{"kind": "depth", "E": 1787095383495, "U": 11316375465980, "u": 11316375476056, "recv_ms": 1787095383559, "bids": [[1000.0, 35.76], [14189.9, 0.896], [14589.9, 3.304], [58220.9, 0.002], [61455.4, 0.006], [62102.3, 1.522], [63689.9, 0.03], [64043.0, 1.591], [64366.7, 0.01], [64367.7, 1.184], [64638.1, 1.286], [64664.3, 0.001], [64677.1, 0.1], [64677.4, 0.013], [64680.3, 0.172], [64682.2, 0.152], [64683.2, 0.001], [64683.5, 0.085], [64683.7, 0.011], [64685.9, 1.553], [64686.1, 0.001], [64686.8, 0.905], [64689.9, 7.645]], "asks": [[64693.0, 0.002], [64694.1, 0.09], [64694.2, 0.161], [64694.3, 0.127], [64694.4, 0.199], [64694.5, 0.56], [64694.7, 1.366], [64696.2, 0.001], [64698.8, 0.043], [64698.9, 0.289], [64699.1, 0.913], [64708.3, 0.157], [64711.5, 0.031], [64711.8, 0.782], [64712.5, 0.003], [64713.9, 1.617], [64714.5, 0.157], [64716.9, 0.001], [64728.9, 0.085], [64886.7, 1.976], [65020.1, 0.0], [65021.1, 0.109], [65336.9, 3.821], [65390.6, 0.726], [65628.0, 22.397], [65690.0, 0.433]]}
{"kind": "depth", "E": 1787095383597, "U": 11316375476486, "u": 11316375489308, "recv_ms": 1787095383656, "bids": [[14189.9, 0.532], [14589.9, 3.668], [51752.0, 0.0], [58220.9, 0.002], [61455.4, 0.006], [62102.3, 1.525], [64043.0, 1.591], [64366.5, 3.267], [64527.5, 0.0], [64528.2, 0.04], [64622.5, 0.192], [64625.1, 37.788], [64638.1, 1.286], [64650.7, 0.033], [64664.3, 0.001], [64676.2, 0.062], [64677.1, 0.1], [64677.3, 1.989], [64677.4, 0.013], [64680.3, 0.172], [64681.0, 0.004], [64682.2, 0.152], [64682.4, 0.077], [64683.2, 0.001], [64683.7, 0.011], [64685.3, 2.407], [64686.1, 0.447], [64686.7, 0.088], [64686.9, 0.109], [64687.1, 0.086], [64689.9, 7.646]], "asks": [[64693.0, 0.227], [64694.3, 0.163], [64694.4, 0.282], [64694.7, 1.35], [64694.8, 7.4], [64695.7, 0.121], [64695.9, 0.044], [64696.2, 0.358], [64697.1, 0.028], [64698.8, 0.043], [64698.9, 0.305], [64699.1, 0.913], [64708.3, 0.157], [64708.8, 1.371], [64714.5, 0.157], [64718.4, 1.509], [64744.9, 0.036], [64745.0, 0.0], [64761.3, 45.529], [64764.5, 0.036], [64767.1, 0.001], [64767.9, 0.015], [64886.7, 8.309], [65304.6, 6.165], [65336.9, 3.821], [65518.1, 0.0], [65542.8, 4.578], [65628.0, 23.462], [65962.6, 1.298]]}
{"kind": "depth", "E": 1787095383699, "U": 11316375489706, "u": 11316375497840, "recv_ms": 1787095383758, "bids": [[1000.0, 35.91], [14189.9, 0.308], [14489.9, 0.14], [14589.9, 3.752], [51751.9, 0.0], [58220.9, 0.002], [61455.4, 0.004], [61455.5, 0.008], [62102.3, 1.522], [62550.2, 1.598], [63689.9, 0.01], [64043.0, 1.591], [64549.4, 0.006], [64631.6, 1.237], [64639.6, 0.007], [64664.3, 0.001], [64677.1, 0.007], [64677.4, 0.106], [64680.3, 0.172], [64682.2, 0.152], [64683.2, 0.477], [64684.3, 0.466], [64686.0, 1.095], [64686.1, 0.001], [64689.9, 7.647]], "asks": [[64691.8, 0.006], [64692.0, 0.148], [64692.6, 0.108], [64692.7, 0.005], [64693.0, 0.002], [64694.3, 0.163], [64694.4, 0.044], [64694.7, 1.35], [64694.9, 0.005], [64695.3, 0.001], [64695.7, 0.002], [64696.2, 0.001], [64698.6, 0.082], [64698.9, 0.305], [64699.1, 0.913], [64705.6, 0.057], [64708.3, 0.157], [64712.2, 2.095], [64714.5, 0.157], [64718.4, 1.355], [64735.3, 0.267], [64830.9, 0.06], [65336.9, 3.821], [65466.3, 23.924], [65690.0, 0.413], [66630.5, 0.003]]}
{"kind": "depth", "E": 1787095383801, "U": 11316375497958, "u": 11316375505325, "recv_ms": 1787095383860, "bids": [[1000.0, 35.76], [14189.9, 0.196], [14489.9, 0.378], [14589.9, 3.626], [58220.9, 0.002], [61455.4, 0.004], [63689.9, 0.03], [63913.6, 44.202], [64043.0, 1.591], [64497.9, 0.0], [64549.4, 4.692], [64587.8, 0.0], [64625.3, 0.002], [64644.6, 0.072], [64664.3, 0.001], [64671.8, 0.626], [64677.1, 0.007], [64677.4, 0.106], [64679.2, 0.618], [64680.3, 0.172], [64682.2, 0.152], [64683.2, 0.358], [64684.3, 0.02], [64686.0, 1.541], [64686.1, 0.001], [64687.1, 0.086], [64689.9, 7.647]], "asks": [[64692.1, 0.243], [64692.7, 0.166], [64693.0, 0.002], [64694.3, 0.163], [64694.4, 0.401], [64694.6, 0.409], [64696.2, 0.358], [64696.3, 0.325], [64698.6, 0.002], [64698.9, 0.305], [64699.1, 0.913], [64700.0, 3.982], [64700.3, 0.84], [64700.8, 0.089], [64701.0, 1.461], [64707.6, 0.628], [64708.3, 0.157], [64714.5, 0.157], [64714.9, 0.17], [64752.7, 0.015], [64767.7, 0.003], [64785.1, 2.46], [64830.9, 5.459], [65013.5, 1.692], [65336.9, 3.821], [65498.6, 8.26], [65536.6, 0.267], [65690.0, 0.433], [65778.5, 1.548]]}
{"kind": "depth", "E": 1787095383903, "U": 11316375505544, "u": 11316375515713, "recv_ms": 1787095383967, "bids": [[14189.9, 0.07], [14489.9, 0.616], [14589.9, 3.514], [58220.9, 0.002], [62091.9, 0.001], [62102.3, 1.525], [63380.1, 0.059], [63452.0, 0.284], [63523.8, 0.058], [63595.7, 0.061], [63667.6, 0.88], [63739.4, 0.073], [63811.3, 0.06], [63883.1, 0.058], [63913.6, 39.515], [63955.0, 0.451], [64026.9, 0.06], [64043.0, 1.591], [64366.4, 2.108], [64366.5, 3.257], [64549.4, 0.006], [64638.1, 1.286], [64664.3, 0.001], [64675.4, 0.001], [64676.4, 1.048], [64677.1, 0.007], [64677.4, 0.106], [64680.3, 0.172], [64682.2, 0.152], [64683.2, 0.477], [64683.7, 0.011], [64686.0, 1.095], [64686.1, 0.447], [64686.2, 0.003], [64686.7, 0.091], [64687.1, 0.002], [64687.3, 0.084], [64689.9, 7.644]], "asks": [[64692.1, 0.018], [64693.0, 0.002], [64694.3, 0.008], [64694.4, 0.318], [64694.6, 0.171], [64696.2, 0.001], [64698.9, 0.305], [64699.1, 0.913], [64708.3, 0.157], [64713.9, 2.66], [64714.5, 0.157], [64718.6, 0.505], [64759.0, 8.974], [64788.1, 0.0], [64830.9, 0.06], [64837.9, 0.778], [65320.3, 4.367], [65336.9, 3.821], [65392.2, 0.067], [65464.1, 0.067], [65535.9, 0.06], [65607.8, 0.074], [65628.0, 22.397], [65679.6, 0.437]]}
{"kind": "depth", "E": 1787095384005, "U": 11316375515855, "u": 11316375522988, "recv_ms": 1787095384063, "bids": [[1000.0, 35.76], [14189.9, 0.0], [14489.9, 0.896], [14589.9, 3.304], [58220.9, 0.002], [61455.4, 0.004], [62102.3, 1.522], [63689.9, 0.01], [63729.3, 1.003], [63865.1, 12.35], [64043.0, 1.591], [64493.5, 0.0], [64493.6, 11.692], [64532.3, 0.0], [64532.4, 6.623], [64534.1, 2.08], [64549.4, 4.495], [64562.1, 0.0], [64565.8, 0.018], [64638.1, 1.272], [64669.1, 0.157], [64683.2, 0.001], [64683.7, 0.13], [64684.9, 0.115], [64685.2, 0.137], [64686.1, 0.001], [64687.2, 0.004], [64689.9, 7.636]], "asks": [[64693.0, 0.227], [64696.2, 0.12], [64712.1, 0.014], [64718.6, 0.659], [64830.9, 5.459], [64844.9, 1.542], [64847.8, 0.0], [64847.9, 10.792], [64886.7, 8.501], [65336.9, 3.821], [65690.0, 0.413], [65751.5, 0.058], [65789.7, 9.857], [65823.4, 0.058], [65895.2, 0.058], [65967.1, 3.994]]}
{"kind": "depth", "E": 1787095384107, "U": 11316375523140, "u": 11316375530771, "recv_ms": 1787095384165, "bids": [[14489.9, 1.26], [14589.9, 2.94], [58220.9, 0.002], [61455.4, 0.004], [62102.3, 1.525], [63751.9, 22.162], [63913.6, 44.202], [64043.0, 1.591], [64574.6, 3.867], [64618.8, 0.046], [64638.1, 1.272], [64664.3, 0.001], [64669.1, 0.003], [64669.3, 0.469], [64677.1, 0.007], [64677.4, 0.106], [64678.3, 0.074], [64678.7, 0.015], [64679.3, 2.789], [64680.3, 0.172], [64682.2, 0.152], [64683.2, 0.001], [64683.7, 0.011], [64684.9, 0.115], [64685.2, 0.137], [64686.1, 0.001], [64687.3, 0.0], [64689.4, 0.019], [64689.9, 7.641]], "asks": [[64693.0, 0.227], [64694.4, 0.318], [64696.2, 0.001], [64698.9, 0.305], [64699.1, 0.913], [64700.8, 0.009], [64701.0, 1.541], [64708.3, 0.157], [64709.5, 0.005], [64714.5, 0.157], [64715.6, 0.653], [64718.6, 0.505], [64718.7, 2.323], [64718.8, 0.193], [64723.0, 0.004], [64761.3, 45.529], [64825.5, 3.865], [65013.5, 1.691], [65336.9, 3.821], [65628.0, 23.462], [65643.7, 11.252], [65983.7, 0.009]]}
{"kind": "depth", "E": 1787095384209, "U": 11316375530912, "u": 11316375537528, "recv_ms": 1787095384268, "bids": [[14489.9, 1.61], [14589.9, 2.59], [58220.9, 0.002], [61455.4, 0.004], [62102.3, 1.522], [62102.4, 0.027], [63707.8, 3.138], [63745.4, 1.128], [63805.7, 2.813], [63897.4, 43.737], [64022.3, 0.589], [64043.0, 1.591], [64366.4, 2.109], [64366.5, 3.257], [64497.7, 0.002], [64549.4, 4.495], [64582.0, 0.025], [64638.1, 1.272], [64645.7, 0.132], [64664.3, 0.001], [64668.7, 0.466], [64677.1, 0.007], [64677.4, 0.106], [64680.3, 0.172], [64682.2, 0.152], [64683.5, 0.001], [64683.7, 0.011], [64684.0, 0.313], [64684.9, 0.115], [64685.2, 0.137], [64685.9, 0.008], [64686.1, 0.001], [64686.9, 1.654], [64687.1, 0.0], [64687.3, 0.084], [64687.7, 0.084], [64689.9, 7.64]], "asks": [[64690.0, 9.279], [64691.6, 0.117], [64693.0, 0.227], [64694.4, 0.318], [64696.2, 0.239], [64698.9, 0.305], [64699.1, 0.913], [64699.8, 0.221], [64700.3, 0.222], [64703.7, 0.04], [64708.3, 0.157], [64710.6, 0.127], [64714.5, 0.157], [64715.6, 0.628], [64716.3, 0.002], [64716.9, 0.008], [64726.9, 0.052], [64759.0, 1.487], [64761.3, 0.048], [64767.9, 45.496], [64805.6, 0.1], [64830.9, 5.459], [64876.3, 0.0], [64876.4, 0.021], [64886.7, 8.424], [65336.9, 3.821]]}
{"kind": "depth", "E": 1787095384311, "U": 11316375537637, "u": 11316375544197, "recv_ms": 1787095384368, "bids": [[1000.0, 35.76], [14489.9, 1.974], [14589.9, 2.226], [51752.0, 0.0], [58220.9, 0.002], [63689.9, 0.03], [63831.8, 0.0], [63913.6, 44.202], [64043.0, 1.591], [64531.4, 0.883], [64622.2, 0.333], [64638.1, 1.272], [64656.2, 0.026], [64664.3, 0.001], [64673.5, 2.811], [64677.1, 0.007], [64677.4, 0.106], [64680.3, 0.172], [64682.0, 0.011], [64682.2, 0.152], [64682.8, 0.233], [64684.3, 0.02], [64684.4, 0.001], [64684.5, 0.012], [64684.9, 0.115], [64685.0, 0.488], [64685.2, 0.137], [64685.4, 0.081], [64685.5, 0.016], [64685.6, 1.55], [64685.7, 1.098], [64686.0, 0.006], [64686.1, 0.001], [64686.2, 0.003], [64686.3, 0.184], [64686.8, 0.005], [64686.9, 0.031], [64687.0, 0.056], [64687.1, 0.011], [64687.2, 0.984], [64687.6, 0.003], [64688.8, 0.007], [64689.9, 7.647]], "asks": [[64693.0, 0.227], [64694.4, 0.318], [64696.2, 0.001], [64698.9, 0.305], [64699.1, 0.913], [64699.8, 0.314], [64706.0, 0.382], [64708.3, 0.157], [64712.1, 0.01], [64714.5, 0.157], [64718.8, 0.193], [64761.3, 45.443], [64767.9, 0.015], [65336.9, 3.821], [65660.4, 8.811], [65690.0, 0.433]]}
{"kind": "depth", "E": 1787095384413, "U": 11316375544339, "u": 11316375548825, "recv_ms": 1787095384475, "bids": [[14489.9, 2.338], [14589.9, 1.862], [51752.0, 0.0], [58220.9, 0.002], [61455.4, 0.004], [62102.3, 1.525], [63396.2, 0.023], [63741.2, 0.0], [63771.3, 1.405], [63964.3, 3.474], [64043.0, 1.591], [64364.3, 0.0], [64684.1, 0.001], [64684.3, 0.02], [64684.9, 0.116], [64685.2, 0.136], [64685.7, 0.008], [64685.8, 0.627], [64685.9, 0.008], [64686.0, 0.547], [64686.1, 0.009], [64686.4, 0.003], [64687.3, 0.084], [64689.9, 7.649]], "asks": [[64690.0, 9.282], [64693.0, 0.002], [64694.3, 0.233], [64696.2, 0.239], [64886.7, 8.415], [65336.9, 3.821], [65584.6, 0.914]]}
{"kind": "depth", "E": 1787095384515, "U": 11316375548903, "u": 11316375557705, "recv_ms": 1787095384581, "bids": [[14489.9, 2.688], [14589.9, 1.512], [58220.9, 0.002], [61455.4, 0.004], [62102.3, 1.522], [63396.2, 0.026], [63689.9, 0.01], [63751.9, 21.065], [63755.1, 1.651], [63881.3, 10.931], [64043.0, 1.591], [64366.5, 3.257], [64658.0, 0.01], [64658.5, 0.003], [64662.0, 2.337], [64662.1, 3.534], [64662.9, 0.264], [64663.9, 1.651], [64664.3, 0.156], [64665.8, 0.131], [64667.8, 0.002], [64667.9, 0.004], [64671.1, 0.052], [64677.1, 0.162], [64677.4, 0.261], [64678.2, 0.021], [64678.9, 1.421], [64679.3, 2.33], [64679.8, 0.602], [64680.3, 0.327], [64680.8, 0.035], [64682.2, 0.855], [64682.3, 0.025], [64683.8, 0.004], [64684.2, 0.875], [64684.3, 0.466], [64684.6, 0.004], [64685.1, 0.003], [64685.4, 0.074], [64685.6, 0.005], [64685.7, 0.0], [64686.0, 0.006], [64686.1, 0.001], [64686.2, 0.003], [64687.2, 1.294], [64687.3, 0.094], [64687.4, 0.16], [64687.6, 1.556], [64687.8, 0.053], [64688.0, 0.004], [64688.1, 0.086], [64688.5, 0.084], [64689.0, 0.086], [64689.4, 0.058], [64689.8, 0.06], [64689.9, 8.406]], "asks": [[64690.0, 9.309], [64690.1, 0.018], [64690.6, 0.039], [64691.3, 0.002], [64691.8, 0.004], [64692.8, 0.022], [64693.5, 0.019], [64693.7, 0.085], [64694.2, 0.161], [64694.3, 0.0], [64694.4, 0.044], [64694.5, 0.011], [64694.6, 0.728], [64694.9, 0.005], [64696.2, 0.001], [64698.8, 0.067], [64698.9, 0.126], [64699.1, 0.603], [64699.6, 0.237], [64699.8, 0.312], [64707.6, 0.01], [64708.3, 0.002], [64709.3, 2.751], [64709.9, 0.003], [64711.2, 0.453], [64711.3, 0.104], [64711.7, 0.014], [64711.8, 0.323], [64712.1, 0.008], [64712.2, 2.554], [64713.9, 1.617], [64714.3, 0.015], [64714.5, 0.002], [64714.6, 0.0], [64714.7, 0.031], [64714.8, 0.062], [64715.6, 0.072], [64715.7, 0.043], [64716.3, 0.673], [64718.5, 0.049], [64718.8, 0.039], [64718.9, 0.159], [64720.1, 0.0], [64720.5, 5.993], [64721.1, 0.392], [64726.8, 0.071], [64886.7, 8.159], [65336.9, 3.823], [65531.4, 2.274], [65690.0, 0.413]]}
{"kind": "depth", "E": 1787095384617, "U": 11316375557737, "u": 11316375563897, "recv_ms": 1787095384675, "bids": [[1000.0, 35.76], [14489.9, 3.038], [14589.9, 1.162], [58220.9, 0.002], [61455.4, 0.004], [62102.3, 1.525], [63751.9, 22.162], [63832.7, 22.25], [63843.6, 0.274], [64043.0, 1.591], [64518.8, 0.024], [64643.3, 0.044], [64645.7, 0.032], [64657.1, 0.004], [64662.1, 3.549], [64664.3, 0.001], [64671.8, 0.008], [64676.2, 0.042], [64676.4, 1.008], [64677.1, 0.007], [64677.4, 0.106], [64679.2, 0.0], [64679.9, 0.122], [64680.3, 0.172], [64681.2, 1.596], [64682.2, 0.7], [64682.3, 0.024], [64682.8, 0.001], [64682.9, 0.35], [64683.1, 0.86], [64684.3, 0.258], [64684.9, 0.115], [64685.1, 0.0], [64685.4, 0.646], [64685.5, 0.016], [64685.6, 0.005], [64685.7, 0.0], [64685.8, 0.532], [64685.9, 0.008], [64686.2, 0.003], [64686.6, 0.245], [64686.7, 0.15], [64687.2, 0.317], [64687.3, 0.086], [64687.4, 0.005], [64687.5, 0.383], [64687.6, 0.003], [64687.7, 0.084], [64687.8, 0.053], [64687.9, 3.928], [64688.0, 1.599], [64689.0, 0.002], [64689.5, 0.086], [64689.9, 8.456]], "asks": [[64690.0, 8.971], [64690.1, 0.012], [64691.5, 0.013], [64691.6, 0.117], [64692.0, 0.064], [64694.2, 0.162], [64694.4, 0.044], [64694.5, 0.011], [64695.3, 0.085], [64698.9, 0.281], [64699.1, 0.913], [64699.8, 0.219], [64702.0, 0.004], [64704.0, 0.131], [64705.0, 0.008], [64706.6, 0.096], [64708.3, 0.157], [64709.2, 0.286], [64710.0, 0.14], [64710.6, 0.034], [64711.8, 0.416], [64716.0, 0.009], [64716.9, 0.163], [64717.5, 0.778], [64717.6, 1.238], [64718.5, 0.063], [64718.8, 0.193], [64718.9, 0.005], [64886.7, 1.96], [65336.9, 3.821], [65596.0, 0.0]]}
{"kind": "depth", "E": 1787095384719, "U": 11316375563898, "u": 11316375568126, "recv_ms": 1787095384777, "bids": [[14489.9, 3.402], [14589.9, 0.798], [51751.9, 0.0], [58220.9, 0.002], [61455.4, 0.006], [62298.0, 0.263], [63689.9, 0.03], [63751.9, 23.259], [63984.8, 3.203], [64043.0, 1.591], [64664.3, 0.001], [64677.1, 0.007], [64677.4, 0.106], [64680.1, 1.416], [64680.3, 0.172], [64681.0, 0.904], [64682.3, 0.024], [64682.4, 0.077], [64683.1, 0.628], [64683.5, 0.233], [64684.1, 0.001], [64684.3, 0.02], [64685.4, 0.553], [64685.5, 0.016], [64685.8, 0.086], [64686.7, 0.088], [64686.8, 0.067], [64689.9, 8.562]], "asks": [[64690.0, 8.522], [64694.4, 0.269], [64694.5, 0.166], [64695.7, 0.002], [64696.2, 0.001], [64698.9, 0.281], [64699.1, 0.913], [64699.8, 0.312], [64701.0, 1.461], [64702.9, 3.255], [64703.0, 0.014], [64703.6, 0.203], [64704.0, 1.035], [64708.3, 0.157], [64716.9, 0.163], [64886.7, 8.028], [65336.9, 3.821], [65466.6, 2.144], [65499.2, 8.025], [65595.7, 25.22], [65690.0, 0.433]]}
{"kind": "depth", "E": 1787095384821, "U": 11316375568197, "u": 11316375571871, "recv_ms": 1787095384881, "bids": [[14389.9, 0.028], [14489.9, 3.696], [14589.9, 0.476], [51752.0, 0.0], [58220.9, 0.002], [61455.4, 0.007], [62102.3, 1.522], [63848.9, 2.893], [64043.0, 1.591], [64366.4, 2.108], [64366.5, 3.257], [64528.2, 0.001], [64528.9, 0.071], [64621.9, 0.12], [64625.4, 0.002], [64648.0, 1.426], [64664.2, 0.02], [64664.3, 0.001], [64671.7, 1.759], [64677.1, 0.007], [64677.4, 0.106], [64679.1, 0.716], [64680.3, 0.172], [64682.3, 0.024], [64682.4, 0.078], [64684.3, 0.02], [64685.5, 0.016], [64687.4, 0.005], [64689.9, 8.561]], "asks": [[64692.7, 0.005], [64693.0, 0.227], [64694.4, 0.044], [64694.5, 0.285], [64698.9, 0.281], [64699.1, 0.913], [64700.6, 1.158], [64704.1, 1.25], [64708.0, 0.677], [64708.3, 0.157], [64716.9, 0.163], [64717.5, 0.214], [64719.5, 0.223], [64726.8, 0.001], [64733.6, 0.034], [64755.9, 1.443], [64756.3, 0.101], [64805.6, 0.0], [65336.9, 3.821], [65498.6, 8.602], [65983.7, 0.012]]}
{"kind": "depth", "E": 1787095384923, "U": 11316375571980, "u": 11316375575717, "recv_ms": 1787095384980, "bids": [[1000.0, 35.76], [14389.9, 0.196], [14489.9, 3.724], [14589.9, 0.28], [58220.9, 0.002], [61455.4, 0.007], [62102.3, 1.525], [63689.9, 0.01], [63901.8, 5.494], [63964.3, 2.772], [63984.8, 3.904], [64043.0, 1.591], [64569.6, 0.021], [64576.7, 0.023], [64592.4, 0.0], [64594.4, 1.532], [64636.6, 0.022], [64644.6, 0.072], [64657.9, 1.585], [64682.4, 0.078], [64685.5, 0.016], [64689.9, 8.564]], "asks": [[64693.0, 0.002], [64693.1, 0.557], [64694.1, 0.093], [64694.5, 0.285], [64696.2, 0.239], [64735.3, 0.267], [64759.0, 8.962], [64767.7, 0.0], [64787.4, 1.959], [64788.7, 0.027], [64830.2, 2.116], [65013.5, 1.692], [65336.9, 3.821], [65499.3, 2.286], [65690.0, 0.413], [65895.4, 0.005], [71159.0, 0.002]]}
{"kind": "depth", "E": 1787095385025, "U": 11316375575787, "u": 11316375579944, "recv_ms": 1787095385087, "bids": [[14389.9, 0.434], [14489.9, 3.598], [14589.9, 0.168], [58220.9, 0.002], [61455.4, 0.006], [62102.3, 1.522], [63396.2, 0.023], [64043.0, 1.593], [64493.6, 0.0], [64493.7, 11.621], [64532.4, 0.0], [64532.5, 7.171], [64549.4, 4.498], [64590.8, 0.039], [64592.5, 0.002], [64622.6, 0.377], [64623.6, 6.026], [64623.7, 1.761], [64625.2, 0.014], [64646.2, 3.5], [64649.3, 0.001], [64662.0, 0.337], [64662.4, 0.698], [64665.8, 8.131], [64679.5, 0.686], [64679.8, 0.143], [64682.4, 0.077], [64684.1, 0.001], [64685.5, 0.016], [64686.6, 0.244], [64686.8, 0.005], [64687.4, 0.006], [64687.6, 0.065], [64689.9, 9.223]], "asks": [[64692.8, 0.02], [64693.1, 0.332], [64694.5, 0.391], [64694.6, 0.728], [64695.1, 0.007], [64696.2, 0.001], [64698.8, 0.066], [64700.6, 0.54], [64708.0, 0.059], [64716.6, 0.575], [64718.6, 0.659], [64718.8, 0.039], [64732.7, 3.515], [64754.7, 7.004], [64755.4, 6.03], [64788.6, 0.215], [64788.7, 0.035], [64886.7, 8.253], [65306.0, 0.137], [65336.9, 3.821], [65498.6, 9.088], [65900.0, 13.865]]}
{"kind": "depth", "E": 1787095385127, "U": 11316375579965, "u": 11316375585008, "recv_ms": 1787095385186, "bids": [[1000.0, 35.76], [14389.9, 0.672], [14489.9, 3.486], [14589.9, 0.042], [51752.0, 0.0], [58220.9, 0.002], [61455.4, 0.006], [62102.3, 1.525], [63689.9, 0.03], [63881.3, 11.165], [64043.0, 1.591], [64366.5, 3.267], [64526.9, 0.039], [64528.9, 0.032], [64587.0, 2.383], [64587.2, 1.394], [64591.3, 10.0], [64591.4, 3.667], [64653.3, 0.312], [64657.0, 0.005], [64657.1, 0.006], [64657.2, 0.064], [64660.5, 1.402], [64660.6, 0.198], [64660.7, 0.108], [64678.3, 0.074], [64683.7, 0.007], [64684.1, 0.12], [64685.5, 0.462], [64689.9, 9.221]], "asks": [[64690.0, 8.524], [64694.4, 0.044], [64694.5, 0.166], [64696.2, 0.001], [64699.2, 2.184], [64718.6, 0.659], [64787.4, 2.765], [64787.8, 10.004], [64800.8, 2.32], [64801.0, 25.033], [65336.9, 3.821], [65401.6, 6.396], [65407.1, 0.357], [65660.6, 0.0], [65690.0, 0.433], [65725.0, 10.673]]}
{"kind": "depth", "E": 1787095385229, "U": 11316375585123, "u": 11316375589832, "recv_ms": 1787095385286, "bids": [[1000.0, 35.76], [14389.9, 0.994], [14489.9, 3.206], [14589.9, 0.0], [51752.0, 0.0], [58220.9, 0.002], [64043.0, 1.591], [64366.4, 2.107], [64590.8, 0.031], [64591.5, 0.008], [64592.8, 0.003], [64631.6, 1.24], [64684.1, 0.001], [64684.3, 0.02], [64685.5, 0.016], [64687.4, 0.008]], "asks": [[64694.1, 0.09], [64694.5, 0.166], [64718.6, 0.505], [64718.7, 2.477], [64754.7, 7.007], [64767.7, 0.003], [64787.7, 0.011], [64788.7, 0.027], [65013.5, 1.693], [65336.9, 3.821], [65916.5, 8.182]]}
{"kind": "depth", "E": 1787095385331, "U": 11316375589847, "u": 11316375595963, "recv_ms": 1787095385391, "bids": [[14389.9, 1.344], [14489.9, 2.856], [58220.9, 0.002], [61455.4, 0.006], [61455.5, 0.006], [62102.3, 1.522], [63503.6, 9.164], [63689.9, 0.01], [64043.0, 1.591], [64526.9, 0.0], [64530.8, 0.039], [64668.7, 0.312], [64668.9, 2.48], [64673.5, 2.809], [64684.3, 0.466], [64685.5, 0.462], [64687.4, 0.006], [64689.9, 9.226]], "asks": [[64694.4, 0.269], [64694.5, 0.391], [64696.2, 0.12], [64706.0, 0.38], [64706.2, 0.257], [65336.9, 3.821], [65690.0, 0.413]]}
{"kind": "depth", "E": 1787095385433, "U": 11316375596019, "u": 11316375600671, "recv_ms": 1787095385496, "bids": [[1000.0, 35.76], [14389.9, 1.694], [14489.9, 2.506], [58220.9, 0.002], [61455.4, 0.006], [62102.3, 1.525], [63821.6, 0.782], [64043.0, 1.591], [64366.5, 3.257], [64526.9, 0.039], [64530.8, 0.0], [64549.4, 0.006], [64549.5, 4.515], [64673.5, 2.811], [64684.1, 0.001], [64684.3, 0.466], [64685.5, 0.016], [64687.4, 0.005], [64687.6, 0.003], [64687.8, 0.116], [64689.9, 9.532]], "asks": [[64694.4, 0.044], [64694.5, 0.166], [64694.6, 0.728], [64696.2, 0.001], [64699.2, 2.183], [64706.0, 0.382], [64718.7, 2.477], [64830.2, 1.501], [64830.9, 5.459], [64886.7, 8.669], [64961.0, 0.086], [65336.9, 3.821], [65446.2, 0.001], [65482.0, 11.318], [65725.0, 9.609]]}
{"kind": "depth", "E": 1787095385535, "U": 11316375600822, "u": 11316375605497, "recv_ms": 1787095385600, "bids": [[1000.0, 35.76], [14389.9, 2.058], [14489.9, 2.142], [51752.0, 0.0], [58220.9, 0.002], [61455.4, 0.006], [62102.3, 1.522], [63689.9, 0.03], [64043.0, 1.593], [64493.7, 6.585], [64532.5, 4.609], [64549.5, 2.672], [64679.1, 0.698], [64680.1, 1.434], [64684.3, 0.466], [64687.4, 0.005], [64689.9, 9.53]], "asks": [[64694.5, 0.166], [64699.6, 0.428], [64708.6, 0.024], [64718.7, 2.323], [64718.8, 0.193], [64721.1, 0.374], [64886.7, 15.716], [65336.9, 3.821], [65616.8, 5.784], [65690.0, 0.433]]}
{"kind": "depth", "E": 1787095385637, "U": 11316375605565, "u": 11316375609229, "recv_ms": 1787095385694, "bids": [[14389.9, 2.408], [14489.9, 1.792], [58220.9, 0.002], [61455.4, 0.006], [62102.3, 1.525], [63396.2, 0.026], [63881.3, 11.516], [64043.0, 1.591], [64493.7, 11.555], [64526.9, 0.0], [64532.5, 6.982], [64538.2, 2.777], [64549.5, 4.515], [64668.9, 2.326], [64669.2, 0.477], [64684.3, 0.02], [64689.9, 9.529]], "asks": [[64694.5, 0.391], [64718.8, 0.193], [64886.7, 8.596], [65336.9, 3.821], [65568.2, 2.44]]}
{"kind": "depth", "E": 1787095385739, "U": 11316375609436, "u": 11316375613365, "recv_ms": 1787095385797, "bids": [[1000.0, 35.76], [14389.9, 2.772], [14489.9, 1.428], [51751.9, 0.0], [51752.0, 0.0], [58220.9, 0.002], [63396.2, 0.023], [63689.9, 0.01], [64043.0, 1.591], [64366.5, 3.267], [64669.1, 0.157], [64669.2, 0.323], [64684.3, 0.466], [64685.4, 0.553], [64687.4, 0.007], [64689.9, 9.522]], "asks": [[64694.5, 0.391], [65336.9, 3.821], [65466.3, 25.449], [65531.3, 3.048], [65628.0, 23.576], [65690.0, 0.413], [65725.0, 10.673], [65889.3, 0.009]]}
{"kind": "depth", "E": 1787095385841, "U": 11316375613576, "u": 11316375617905, "recv_ms": 1787095385901, "bids": [[1000.0, 35.76], [14389.9, 3.122], [14489.9, 1.078], [58220.9, 0.002], [61455.4, 0.006], [62102.3, 1.522], [63920.1, 4.687], [64043.0, 1.591], [64538.2, 2.738], [64538.9, 0.043], [64549.5, 0.121], [64666.5, 0.015], [64669.4, 0.006], [64672.9, 0.419], [64673.3, 0.235], [64676.4, 1.001], [64676.9, 0.013], [64677.4, 0.106], [64678.6, 0.297], [64679.0, 0.821], [64679.9, 0.129], [64680.2, 0.279], [64680.3, 0.172], [64681.1, 0.343], [64681.2, 1.855], [64682.3, 0.101], [64682.4, 0.0], [64684.1, 0.358], [64684.3, 0.377], [64685.5, 0.462], [64687.1, 0.014], [64687.2, 0.314], [64687.4, 0.005], [64687.6, 0.066], [64687.7, 0.084], [64687.8, 0.053], [64687.9, 2.383], [64688.1, 1.631], [64689.5, 0.002], [64689.9, 9.526]], "asks": [[64691.9, 0.428], [64692.6, 0.101], [64692.9, 0.095], [64693.7, 0.088], [64694.5, 0.391], [64696.2, 0.239], [64698.9, 0.281], [64699.1, 0.604], [64699.6, 0.737], [64702.1, 0.474], [64708.3, 0.157], [64716.3, 0.982], [64716.9, 0.156], [64717.0, 2.242], [64717.1, 1.359], [64718.8, 0.193], [64830.9, 0.06], [65336.9, 3.821], [65568.2, 0.918], [65637.1, 14.711]]}
{"kind": "depth", "E": 1787095385943, "U": 11316375618069, "u": 11316375622273, "recv_ms": 1787095386022, "bids": [[14389.9, 3.486], [14489.9, 0.714], [58220.9, 0.002], [61455.4, 0.006], [62102.3, 1.525], [63689.9, 0.03], [63751.9, 22.162], [63816.6, 11.054], [63913.6, 44.421], [64043.0, 1.591], [64075.1, 0.937], [64366.4, 2.108], [64493.7, 11.62], [64495.7, 2.838], [64532.5, 7.007], [64534.1, 2.126], [64549.5, 4.515], [64612.2, 0.005], [64627.6, 0.0], [64627.9, 0.005], [64628.3, 0.097], [64628.6, 3.793], [64628.9, 2.319], [64645.3, 0.228], [64645.4, 0.073], [64645.7, 0.0], [64646.0, 0.217], [64646.3, 1.035], [64646.6, 0.002], [64660.2, 0.011], [64660.3, 0.001], [64660.4, 4.902], [64660.5, 1.332], [64660.6, 0.028], [64660.7, 0.008], [64660.8, 1.289], [64660.9, 0.125], [64661.0, 0.0], [64661.1, 0.032], [64661.2, 0.034], [64661.8, 0.0], [64662.2, 2.249], [64662.7, 1.647], [64662.8, 0.059], [64662.9, 0.207], [64666.5, 0.015], [64668.8, 3.026], [64669.4, 0.006], [64672.6, 0.116], [64673.3, 0.119], [64675.1, 0.557], [64675.3, 0.002], [64677.4, 0.106], [64678.7, 0.015], [64679.5, 0.157], [64679.6, 0.467], [64679.7, 0.258], [64679.8, 0.003], [64679.9, 0.029], [64680.0, 1.031], [64680.1, 1.264], [64680.2, 0.179], [64680.3, 0.002], [64680.4, 0.11], [64680.5, 0.443], [64680.8, 0.003], [64681.1, 0.311], [64681.4, 0.015], [64681.8, 0.002], [64682.1, 2.612], [64682.2, 0.7], [64682.3, 0.101], [64684.1, 0.001], [64684.3, 0.02], [64685.5, 0.016], [64685.6, 0.005], [64685.7, 0.446], [64687.5, 0.384], [64687.6, 0.065], [64687.8, 0.053], [64687.9, 2.374], [64688.0, 1.181], [64688.2, 0.009], [64689.1, 0.084], [64689.8, 0.289], [64689.9, 9.525]], "asks": [[64694.5, 0.391], [64696.2, 0.001], [64698.1, 0.219], [64698.4, 0.01], [64698.8, 0.028], [64698.9, 0.281], [64699.1, 0.562], [64699.4, 0.377], [64699.7, 0.181], [64699.8, 0.101], [64699.9, 2.528], [64700.0, 3.862], [64700.1, 0.002], [64700.2, 0.001], [64700.3, 0.002], [64700.4, 0.392], [64700.5, 0.033], [64700.6, 0.449], [64700.7, 0.004], [64701.0, 2.079], [64708.3, 0.157], [64708.4, 1.626], [64711.2, 0.453], [64712.1, 0.467], [64712.2, 2.095], [64713.8, 0.637], [64714.6, 0.057], [64714.8, 0.005], [64715.4, 0.002], [64715.5, 0.003], [64715.8, 0.217], [64716.1, 0.314], [64716.2, 0.586], [64716.3, 0.426], [64716.5, 0.17], [64716.8, 0.017], [64716.9, 0.156], [64717.1, 1.317], [64717.5, 0.094], [64717.9, 0.0], [64718.8, 0.039], [64718.9, 0.159], [64719.0, 0.122], [64719.1, 0.019], [64719.2, 0.378], [64719.3, 0.005], [64719.4, 0.047], [64719.5, 0.103], [64719.6, 0.001], [64719.7, 1.474], [64719.8, 0.019], [64719.9, 0.002], [64733.6, 0.002], [64733.9, 1.04], [64734.2, 0.003], [64734.5, 0.003], [64734.9, 0.003], [64755.3, 2.345], [64755.9, 0.2], [64787.1, 0.015], [64800.0, 21.198], [64806.2, 0.08], [64830.2, 2.116], [64830.9, 5.459], [64847.9, 10.792], [64886.7, 8.508], [65013.5, 1.692], [65191.0, 0.0], [65336.9, 3.821], [65507.8, 2.897], [65531.3, 2.286], [65589.2, 4.727], [65637.1, 12.429], [65660.3, 6.651], [65690.0, 0.433]]}
{"kind": "depth", "E": 1787095386045, "U": 11316375622433, "u": 11316375626550, "recv_ms": 1787095386104, "bids": [[1000.0, 35.76], [14289.9, 0.056], [14389.9, 3.724], [14489.9, 0.42], [58220.9, 0.002], [61455.4, 0.008], [62102.3, 1.522], [64043.0, 1.591], [64172.4, 10.449], [64366.5, 3.267], [64678.3, 0.079], [64679.8, 0.073], [64680.1, 1.364], [64680.2, 0.379], [64680.6, 0.187], [64682.3, 1.647], [64684.3, 0.139], [64685.5, 0.462], [64685.7, 0.0], [64687.5, 0.384], [64688.0, 1.173], [64688.1, 0.086], [64688.2, 0.009], [64688.3, 0.0], [64688.4, 0.009], [64689.9, 9.516]], "asks": [[64691.8, 0.004], [64693.0, 0.002], [64693.1, 0.332], [64694.5, 0.166], [64694.6, 0.728], [64694.7, 1.35], [64695.7, 0.002], [64696.2, 0.001], [64699.5, 1.122], [64699.6, 0.828], [64699.9, 2.788], [64700.0, 4.012], [64700.3, 0.093], [64717.2, 0.174], [64717.7, 6.172], [64718.9, 0.096], [64719.0, 0.276], [64719.2, 0.498], [64719.3, 0.155], [64719.6, 0.092], [64830.9, 3.533], [64847.9, 7.044], [64886.7, 8.67], [65336.9, 3.821], [65388.4, 1.264], [65466.3, 24.687], [65637.1, 10.148], [65778.5, 0.942], [65912.6, 0.456]]}
{"kind": "depth", "E": 1787095386147, "U": 11316375626586, "u": 11316375630551, "recv_ms": 1787095386206, "bids": [[1000.0, 35.76], [14289.9, 0.252], [14389.9, 3.696], [14489.9, 0.252], [58220.9, 0.002], [63689.9, 0.01], [63751.9, 23.259], [63768.1, 50.662], [63920.1, 5.624], [64043.0, 1.591], [64645.6, 0.032], [64645.9, 0.037], [64646.2, 3.532], [64678.3, 0.074], [64680.0, 1.101], [64680.5, 0.543], [64681.0, 0.936], [64681.3, 0.035], [64681.7, 0.035], [64682.2, 0.7], [64682.3, 0.101], [64682.4, 0.0], [64684.3, 0.02], [64685.4, 0.553], [64685.5, 0.016], [64685.6, 0.005], [64687.5, 0.384], [64688.1, 0.094], [64688.2, 0.009], [64688.3, 1.545], [64688.4, 0.001], [64689.9, 9.519]], "asks": [[64693.0, 0.227], [64694.5, 0.404], [64696.2, 0.001], [64698.5, 0.343], [64698.8, 0.07], [64699.0, 0.559], [64699.1, 0.604], [64699.6, 0.948], [64700.1, 0.086], [64716.2, 0.624], [64716.5, 0.212], [64716.8, 0.059], [64718.9, 0.216], [64719.0, 0.122], [64719.4, 0.131], [64733.9, 1.078], [64734.2, 0.045], [64734.6, 0.199], [64748.3, 0.016], [64782.3, 0.004], [65336.9, 3.821], [65531.0, 14.234], [65546.7, 13.425], [65589.2, 6.248], [65637.1, 8.323], [65690.0, 0.413]]}
{"kind": "depth", "E": 1787095386249, "U": 11316375630662, "u": 11316375635663, "recv_ms": 1787095386307, "bids": [[14289.9, 0.49], [14389.9, 3.57], [14489.9, 0.14], [58220.9, 0.002], [61455.4, 0.008], [62102.3, 1.525], [63396.2, 0.02], [63689.9, 0.03], [63771.3, 1.639], [64043.0, 1.593], [64549.5, 0.121], [64644.6, 0.072], [64646.5, 0.033], [64646.9, 0.093], [64650.7, 0.133], [64657.5, 0.003], [64657.6, 1.304], [64672.6, 0.0], [64673.3, 0.235], [64675.1, 0.0], [64675.3, 0.559], [64680.3, 0.102], [64680.4, 0.18], [64682.0, 0.043], [64682.3, 0.133], [64685.4, 0.553], [64687.0, 0.059], [64687.1, 0.011], [64687.4, 0.006], [64687.5, 0.383], [64688.1, 0.086], [64688.2, 0.001], [64688.3, 0.0], [64688.4, 0.002], [64688.5, 0.1], [64688.6, 1.545], [64689.1, 0.0], [64689.9, 9.523]], "asks": [[64693.0, 0.227], [64694.5, 0.404], [64697.8, 0.034], [64698.1, 0.254], [64699.8, 0.301], [64715.5, 0.035], [64715.9, 0.805], [64716.0, 0.565], [64716.1, 0.429], [64716.2, 0.068], [64716.3, 0.311], [64719.0, 0.346], [64719.1, 0.149], [64733.3, 1.724], [64733.6, 0.037], [64735.3, 0.267], [64767.7, 0.0], [64800.0, 21.195], [64810.6, 0.1], [64830.9, 0.06], [65013.5, 1.691], [65336.9, 3.821], [65408.6, 0.553], [65482.0, 11.059], [65507.8, 1.982], [65542.7, 2.287], [65572.4, 5.786], [65607.4, 3.806], [65628.0, 21.446], [65637.1, 6.041], [65660.3, 8.932], [65690.0, 0.433], [65692.7, 10.182], [65789.7, 10.463], [65854.3, 0.0], [66296.0, 0.377]]}
{"kind": "depth", "E": 1787095386351, "U": 11316375635724, "u": 11316375640996, "recv_ms": 1787095386409, "bids": [[1000.0, 35.76], [14289.9, 0.728], [14389.9, 3.458], [14489.9, 0.014], [51752.0, 0.0], [58220.9, 0.002], [61455.4, 0.008], [62102.3, 1.522], [63732.2, 0.0], [63912.6, 1.095], [64043.0, 1.591], [64366.4, 2.109], [64366.5, 3.257], [64532.5, 6.415], [64534.1, 1.252], [64549.5, 4.184], [64661.2, 0.134], [64666.5, 0.17], [64669.4, 0.161], [64673.5, 2.809], [64677.4, 0.261], [64679.8, 0.143], [64679.9, 0.099], [64680.0, 1.171], [64680.1, 1.434], [64680.2, 0.534], [64680.7, 0.072], [64682.2, 0.777], [64682.3, 0.211], [64682.4, 0.0], [64684.3, 0.02], [64684.9, 0.031], [64685.4, 0.553], [64685.5, 0.171], [64687.4, 0.006], [64687.6, 0.065], [64688.1, 0.102], [64688.2, 1.546], [64688.4, 0.001], [64688.5, 0.084], [64688.6, 0.0], [64688.9, 0.089], [64689.3, 0.112], [64689.8, 0.289], [64689.9, 9.529]], "asks": [[64690.0, 8.523], [64693.0, 0.002], [64694.4, 0.044], [64694.5, 0.236], [64698.9, 0.126], [64699.1, 0.294], [64699.4, 0.468], [64700.1, 0.156], [64700.2, 0.141], [64700.4, 0.469], [64702.2, 0.086], [64706.0, 0.38], [64708.3, 0.002], [64716.9, 0.001], [64718.5, 0.063], [64718.7, 2.414], [64718.8, 0.039], [64718.9, 0.216], [64719.0, 0.192], [64719.3, 0.225], [64719.4, 0.201], [64719.5, 0.173], [64719.6, 0.169], [64830.2, 1.501], [64830.9, 5.459], [64847.9, 10.792], [64886.7, 9.524], [65336.9, 3.821], [65402.0, 1.527], [65443.1, 7.718], [65466.3, 25.449], [65563.3, 8.061], [65628.0, 22.511], [65660.3, 11.212]]}
{"kind": "depth", "E": 1787095386453, "U": 11316375641031, "u": 11316375645479, "recv_ms": 1787095386513, "bids": [[1000.0, 35.76], [14289.9, 1.064], [14389.9, 3.136], [14489.9, 0.0], [58220.9, 0.002], [61455.4, 0.008], [62102.3, 1.525], [63773.5, 0.022], [63923.6, 2.343], [64043.0, 1.591], [64378.8, 0.0], [64532.5, 7.035], [64627.8, 0.343], [64628.2, 0.035], [64628.5, 0.033], [64629.1, 0.036], [64660.5, 1.402], [64660.7, 0.078], [64660.9, 0.225], [64661.0, 0.1], [64661.3, 0.082], [64661.8, 0.0], [64662.5, 0.447], [64662.8, 0.059], [64662.9, 0.307], [64666.5, 0.015], [64669.4, 0.006], [64672.5, 0.154], [64673.3, 0.119], [64673.5, 2.811], [64677.4, 0.106], [64678.7, 0.015], [64679.6, 0.467], [64680.2, 0.379], [64682.3, 0.056], [64685.3, 2.323], [64685.5, 0.016], [64687.4, 0.005], [64687.5, 0.383], [64687.7, 0.085], [64688.1, 0.094], [64688.2, 1.554], [64688.3, 0.0], [64688.4, 0.001], [64689.7, 0.096], [64689.9, 9.53]], "asks": [[64690.0, 8.524], [64691.9, 0.344], [64693.0, 0.227], [64693.7, 0.085], [64694.4, 0.199], [64694.5, 0.13], [64696.2, 0.12], [64698.9, 0.281], [64699.1, 0.604], [64706.0, 0.382], [64708.3, 0.157], [64711.1, 2.271], [64712.0, 1.852], [64712.1, 0.008], [64713.7, 0.001], [64714.6, 0.057], [64715.3, 0.001], [64716.1, 0.314], [64716.2, 0.183], [64716.9, 0.156], [64717.1, 1.31], [64717.5, 0.101], [64718.9, 0.37], [64886.7, 8.219], [65336.9, 3.821], [65478.1, 6.867], [65531.0, 15.149], [65595.7, 26.134], [65628.0, 23.576], [65637.1, 3.759], [65660.3, 15.317], [65692.7, 11.246]]}
{"kind": "depth", "E": 1787095386555, "U": 11316375645502, "u": 11316375649599, "recv_ms": 1787095386613, "bids": [[14289.9, 1.428], [14389.9, 2.772], [51752.0, 0.0], [58220.9, 0.002], [62102.3, 1.522], [63689.9, 0.01], [63703.4, 18.007], [63933.0, 3.935], [64043.0, 1.591], [64628.8, 1.06], [64661.2, 0.234], [64665.6, 0.009], [64665.8, 8.133], [64671.5, 0.082], [64679.1, 0.08], [64682.3, 0.056], [64684.3, 0.466], [64685.4, 0.553], [64688.1, 0.086], [64688.2, 0.001], [64688.3, 0.0], [64688.4, 0.001], [64688.5, 0.1], [64688.6, 1.545], [64689.9, 9.532]], "asks": [[64690.0, 8.522], [64692.5, 0.001], [64693.0, 0.227], [64695.7, 0.086], [64696.2, 0.001], [64701.0, 1.461], [64718.9, 0.216], [64719.0, 0.346], [64720.5, 5.995], [64721.4, 2.339], [64733.9, 0.112], [64740.4, 0.394], [64746.8, 2.127], [64753.3, 0.029], [64981.1, 0.346], [65336.9, 3.821], [65378.4, 0.0], [65572.4, 4.872], [65660.3, 17.598], [65690.0, 0.413], [65701.8, 0.001], [65983.7, 0.015]]}
{"kind": "depth", "E": 1787095386657, "U": 11316375649684, "u": 11316375654022, "recv_ms": 1787095386717, "bids": [[1000.0, 35.76], [14289.9, 1.778], [14389.9, 2.422], [51752.0, 0.0], [58220.9, 0.002], [61455.4, 0.008], [61455.5, 0.004], [63689.9, 0.03], [63751.9, 24.199], [64043.0, 1.591], [64350.1, 0.0], [64366.5, 3.257], [64549.5, 4.712], [64657.0, 0.003], [64657.1, 0.004], [64657.2, 0.062], [64660.5, 1.4], [64660.6, 0.026], [64660.7, 0.146], [64661.0, 0.2], [64661.1, 0.102], [64666.5, 0.015], [64669.4, 0.006], [64677.4, 0.106], [64680.2, 0.379], [64682.3, 0.056], [64684.3, 0.466], [64685.5, 0.016], [64687.4, 0.005], [64688.1, 0.087], [64688.2, 0.016], [64688.3, 1.545], [64688.5, 0.084], [64688.6, 0.0], [64689.9, 9.531]], "asks": [[64690.0, 8.051], [64693.0, 0.227], [64694.4, 0.044], [64694.5, 0.285], [64698.9, 0.281], [64699.1, 0.604], [64708.3, 0.157], [64716.9, 0.156], [64830.9, 5.459], [64886.7, 8.185], [65336.9, 3.823], [65466.3, 27.279], [65572.4, 3.044], [65690.0, 0.433]]}
{"kind": "depth", "E": 1787095386759, "U": 11316375654088, "u": 11316375658931, "recv_ms": 1787095386818, "bids": [[1000.0, 35.76], [14289.9, 2.142], [14389.9, 2.058], [51751.9, 0.0], [58220.9, 0.002], [61455.4, 0.008], [62102.3, 1.525], [63718.6, 3.133], [63784.2, 15.582], [64043.0, 1.591], [64660.5, 1.47], [64660.6, 0.096], [64660.8, 1.359], [64661.5, 1.373], [64661.8, 0.0], [64662.8, 0.002], [64662.9, 0.364], [64668.9, 2.48], [64669.1, 0.003], [64678.8, 0.003], [64679.6, 0.467], [64682.3, 1.602], [64684.3, 0.466], [64685.2, 0.139], [64685.4, 0.553], [64688.2, 0.008], [64688.3, 0.0], [64688.4, 0.001], [64688.5, 0.092], [64689.9, 9.528]], "asks": [[64690.0, 8.053], [64693.0, 0.227], [64694.5, 0.285], [64708.4, 1.008], [64711.2, 0.453], [64712.0, 1.393], [64712.1, 0.467], [64749.6, 0.012], [65316.9, 2.675], [65336.9, 3.821], [65401.6, 6.854], [65466.3, 26.059], [65595.7, 27.048], [65704.7, 4.562], [65725.0, 13.711]]}
{"kind": "depth", "E": 1787095386861, "U": 11316375659019, "u": 11316375662769, "recv_ms": 1787095386918, "bids": [[14289.9, 2.506], [14389.9, 1.694], [58220.9, 0.002], [61455.4, 0.008], [62102.3, 1.522], [63719.6, 2.943], [63751.9, 22.005], [64043.0, 1.592], [64366.5, 3.257], [64623.9, 0.0], [64668.9, 2.48], [64682.2, 0.769], [64682.3, 0.064], [64682.4, 0.0], [64684.3, 0.02], [64686.2, 0.003], [64687.4, 0.005], [64687.7, 0.085], [64688.1, 0.087], [64688.2, 0.008], [64688.3, 0.0], [64688.4, 1.554], [64688.5, 0.084], [64689.9, 9.528]], "asks": [[64691.5, 0.013], [64691.8, 0.004], [64692.1, 0.018], [64693.0, 0.002], [64693.1, 0.332], [64694.5, 0.391], [64694.6, 0.728], [64694.7, 1.35], [64696.2, 0.001], [65283.7, 4.717], [65316.9, 1.605], [65336.9, 3.821], [65443.1, 6.802], [65459.8, 6.411], [65507.8, 0.152], [65510.9, 1.603], [65595.7, 28.875], [65616.9, 2.184], [65628.0, 22.511], [65672.1, 3.04], [65824.6, 0.0], [65983.7, 0.018]]}
{"kind": "depth", "E": 1787095386963, "U": 11316375662805, "u": 11316375666267, "recv_ms": 1787095387066, "bids": [[1000.0, 35.76], [14289.9, 2.856], [14389.9, 1.344], [58220.9, 0.002], [62102.3, 1.525], [63689.9, 0.01], [64043.0, 1.592], [64366.4, 2.108], [64534.1, 2.13], [64549.5, 4.381], [64644.6, 0.257], [64678.9, 2.039], [64682.3, 1.626], [64684.3, 0.466], [64688.2, 0.0], [64688.4, 0.001], [64688.5, 0.084], [64688.6, 0.0], [64688.7, 0.0], [64689.9, 9.53]], "asks": [[64694.5, 0.166], [64701.0, 2.079], [64708.4, 1.626], [64830.2, 2.116], [64830.9, 5.459], [64886.7, 9.08], [65316.9, 1.07], [65336.9, 3.821], [65337.1, 0.537], [65443.1, 5.886], [65572.4, 0.761], [65690.0, 0.413], [65704.7, 3.042], [65725.0, 15.231], [66080.6, 1.301]]}
{"kind": "depth", "E": 1787095387065, "U": 11316375666415, "u": 11316375673489, "recv_ms": 1787095387124, "bids": [[1000.0, 35.76], [14289.9, 3.206], [14389.9, 0.994], [58220.9, 0.002], [61455.4, 0.008], [62102.3, 1.522], [63380.0, 0.321], [63396.2, 0.017], [63514.3, 0.679], [63739.0, 2.981], [63751.9, 23.102], [64026.8, 4.488], [64043.0, 1.592], [64054.8, 4.184], [64625.2, 0.005], [64627.7, 0.0], [64634.6, 0.284], [64647.0, 0.004], [64647.7, 0.161], [64668.9, 2.326], [64678.3, 0.074], [64679.2, 0.459], [64679.6, 0.008], [64682.3, 0.064], [64684.3, 0.02], [64686.2, 0.003], [64687.3, 0.086], [64687.7, 0.085], [64688.1, 0.095], [64688.2, 0.0], [64688.3, 0.0], [64688.4, 1.554], [64689.9, 9.535]], "asks": [[64690.7, 0.025], [64690.9, 0.014], [64691.8, 0.004], [64693.1, 0.332], [64694.5, 0.166], [64694.6, 0.728], [64696.2, 0.001], [64719.0, 0.192], [64886.7, 9.144], [65013.5, 1.692], [65304.6, 6.852], [65316.9, 0.535], [65321.4, 0.01], [65336.9, 3.821], [65337.1, 1.607], [65459.8, 6.412], [65466.3, 28.194], [65531.0, 16.977], [65628.0, 24.641], [65637.1, 2.237], [65640.0, 3.166], [65769.4, 0.073]]}
{"kind": "depth", "E": 1787095387167, "U": 11316375673579, "u": 11316375679333, "recv_ms": 1787095387227, "bids": [[14289.9, 3.57], [14389.9, 0.63], [58220.9, 0.002], [61455.4, 0.008], [63689.9, 0.03], [63706.1, 0.035], [63751.9, 24.199], [63837.1, 2.349], [63859.0, 0.0], [64043.0, 1.592], [64366.5, 3.267], [64549.5, 0.121], [64682.3, 0.064], [64682.4, 0.0], [64684.3, 0.466], [64685.2, 0.136], [64685.3, 2.323], [64685.4, 0.553], [64685.5, 0.016], [64686.2, 0.003], [64687.4, 0.006], [64687.6, 0.065], [64687.7, 0.084], [64688.1, 0.103], [64688.2, 1.545], [64688.4, 0.001], [64688.5, 0.084], [64689.8, 0.314], [64689.9, 9.531]], "asks": [[64690.0, 8.055], [64691.5, 0.013], [64691.8, 0.004], [64692.1, 0.018], [64693.0, 0.002], [64693.1, 0.332], [64694.0, 0.004], [64694.5, 0.166], [64694.6, 0.728], [64694.7, 1.35], [64696.2, 0.001], [64702.0, 0.904], [64704.0, 0.135], [64729.9, 2.094], [64732.1, 4.174], [64830.9, 0.06], [64862.1, 0.711], [64862.2, 0.002], [64865.2, 2.931], [65336.9, 3.821], [65337.1, 2.142], [65466.3, 29.109], [65498.6, 9.316], [65531.2, 1.599], [65660.3, 19.119], [65673.8, 0.025], [65690.0, 0.433], [65789.7, 11.981], [65848.0, 0.516]]}
{"kind": "depth", "E": 1787095387269, "U": 11316375679447, "u": 11316375683942, "recv_ms": 1787095387328, "bids": [[1000.0, 35.76], [14189.9, 0.084], [14289.9, 3.766], [14389.9, 0.35], [51752.0, 0.0], [58220.9, 0.002], [61455.4, 0.006], [61455.5, 0.006], [62102.3, 1.525], [64043.0, 1.592], [64366.4, 2.107], [64493.7, 11.692], [64495.7, 2.849], [64532.5, 7.035], [64549.5, 4.515], [64628.3, 2.974], [64628.6, 1.308], [64672.5, 0.038], [64673.3, 0.235], [64676.8, 0.027], [64676.9, 0.006], [64681.0, 1.245], [64681.1, 0.002], [64682.3, 1.61], [64684.3, 0.466], [64686.9, 0.034], [64687.0, 0.056], [64687.4, 0.005], [64687.6, 0.003], [64687.8, 0.116], [64688.1, 0.087], [64688.2, 0.0], [64688.3, 0.0], [64688.4, 0.009], [64688.5, 0.092], [64689.9, 9.527]], "asks": [[64694.5, 0.166], [64699.4, 0.777], [64699.6, 0.639], [64717.0, 2.249], [64717.5, 0.094], [64755.1, 3.277], [64759.1, 0.035], [64830.2, 1.501], [64830.9, 5.459], [64886.7, 8.412], [65336.9, 3.821], [65459.8, 7.327], [65595.7, 31.158], [65640.0, 0.123], [65660.3, 20.64], [65673.8, 0.035], [65704.7, 1.522], [65725.0, 16.751]]}
{"kind": "depth", "E": 1787095387371, "U": 11316375684000, "u": 11316375687927, "recv_ms": 1787095387436, "bids": [[1000.0, 35.76], [14189.9, 0.308], [14289.9, 3.668], [14389.9, 0.224], [51752.0, 0.0], [58220.9, 0.002], [61455.4, 0.005], [61455.5, 0.008], [62102.3, 1.522], [63464.1, 2.938], [63689.9, 0.01], [63763.8, 18.01], [64043.0, 1.592], [64075.3, 11.977], [64549.5, 4.184], [64666.5, 0.015], [64669.4, 0.006], [64673.3, 0.119], [64674.1, 0.129], [64675.3, 0.002], [64676.6, 4.579], [64677.4, 0.106], [64679.2, 0.0], [64680.2, 0.838], [64682.2, 0.692], [64682.3, 0.141], [64682.4, 0.0], [64684.3, 0.02], [64685.5, 0.016], [64686.2, 0.003], [64687.3, 0.086], [64687.8, 0.116], [64688.1, 1.632], [64688.2, 0.0], [64688.3, 0.0], [64688.4, 0.009], [64688.5, 0.092], [64689.7, 0.012], [64689.9, 9.526]], "asks": [[64690.0, 8.06], [64691.8, 0.229], [64692.0, 0.148], [64692.1, 0.137], [64693.0, 0.478], [64693.1, 0.808], [64694.5, 0.642], [64694.6, 0.966], [64694.7, 1.588], [64696.2, 0.477], [64698.9, 0.281], [64699.1, 0.604], [64706.2, 0.237], [64708.3, 0.157], [64712.1, 0.008], [64712.6, 0.845], [64714.6, 0.0], [64715.2, 2.074], [64716.0, 0.009], [64716.2, 0.068], [64716.8, 0.615], [64716.9, 0.271], [64830.9, 5.459], [64886.7, 9.368], [65013.5, 1.693], [65316.9, 0.0], [65336.9, 3.821], [65337.1, 2.677], [65510.9, 1.069], [65592.0, 2.098], [65660.3, 22.161], [65690.0, 0.413], [65704.7, 0.002], [65725.0, 18.271]]}
{"kind": "depth", "E": 1787095387473, "U": 11316375687945, "u": 11316375692408, "recv_ms": 1787095387530, "bids": [[14189.9, 0.546], [14289.9, 3.542], [14389.9, 0.112], [58220.9, 0.002], [61455.4, 0.005], [62102.3, 1.525], [63654.9, 4.833], [63951.0, 0.0], [64043.0, 1.592], [64366.5, 3.267], [64625.2, 0.032], [64644.6, 0.257], [64666.5, 0.015], [64669.4, 0.006], [64673.1, 0.116], [64673.5, 2.811], [64674.1, 0.013], [64675.3, 0.559], [64676.6, 4.022], [64677.4, 0.106], [64679.2, 0.459], [64680.2, 0.379], [64680.3, 0.102], [64682.3, 0.141], [64685.5, 0.462], [64687.6, 0.065], [64687.7, 0.085], [64687.8, 0.053], [64688.1, 0.087], [64688.2, 1.561], [64688.4, 0.001], [64688.5, 0.084], [64689.9, 9.533]], "asks": [[64691.5, 0.013], [64691.6, 0.136], [64691.8, 0.004], [64692.1, 0.018], [64693.0, 0.227], [64693.1, 0.332], [64694.4, 0.199], [64694.5, 0.13], [64694.6, 0.728], [64694.7, 1.35], [64696.2, 0.001], [64698.9, 0.281], [64699.1, 0.604], [64706.0, 0.382], [64706.2, 0.257], [64708.3, 0.157], [64711.7, 0.473], [64712.6, 0.386], [64716.9, 0.271], [64735.3, 0.267], [64830.9, 5.459], [64847.9, 10.792], [64886.7, 8.22], [65336.9, 3.821], [65542.7, 3.049], [65660.3, 23.681], [65983.7, 0.021]]}
{"kind": "depth", "E": 1787095387575, "U": 11316375692522, "u": 11316375696398, "recv_ms": 1787095387634, "bids": [[1000.0, 35.76], [14189.9, 0.798], [14289.9, 3.402], [14389.9, 0.0], [58220.9, 0.002], [61455.4, 0.004], [63689.9, 0.03], [63703.4, 17.999], [63784.2, 17.931], [63845.7, 0.048], [64043.0, 1.592], [64661.8, 0.057], [64662.9, 0.307], [64666.5, 0.015], [64669.4, 0.006], [64677.4, 0.106], [64678.6, 0.297], [64678.9, 1.421], [64679.2, 0.0], [64679.5, 0.616], [64680.2, 0.379], [64682.3, 0.141], [64685.5, 0.016], [64685.6, 0.005], [64687.4, 0.005], [64687.6, 0.003], [64687.8, 0.115], [64688.2, 0.016], [64688.3, 0.0], [64688.4, 1.546], [64689.7, 0.096], [64689.9, 9.534]], "asks": [[64690.0, 8.084], [64691.8, 0.229], [64692.0, 0.064], [64692.1, 0.375], [64692.5, 0.085], [64693.0, 0.478], [64693.1, 0.808], [64694.4, 0.044], [64694.5, 0.642], [64694.6, 1.204], [64694.7, 1.707], [64695.7, 0.324], [64696.2, 0.12], [64698.9, 0.281], [64699.1, 0.604], [64701.0, 1.461], [64708.3, 0.157], [64713.6, 0.686], [64714.6, 0.057], [64715.1, 2.681], [64715.2, 2.017], [64716.1, 0.87], [64716.8, 0.059], [64716.9, 0.271], [65336.9, 3.821], [65482.0, 10.831], [65502.3, 0.003], [65510.9, 0.535], [65546.7, 12.664], [65592.0, 1.871], [65644.5, 0.0], [65690.0, 0.433], [65725.0, 19.791], [65967.9, 0.0]]}
{"kind": "depth", "E": 1787095387677, "U": 11316375696485, "u": 11316375700492, "recv_ms": 1787095387735, "bids": [[1000.0, 35.76], [14189.9, 1.162], [14289.9, 3.038], [51751.9, 0.0], [58220.9, 0.004], [61455.4, 0.004], [62102.3, 1.522], [64043.0, 1.592], [64623.6, 0.026], [64623.7, 0.865], [64646.2, 0.032], [64646.3, 0.555], [64659.1, 0.192], [64662.4, 0.141], [64665.8, 0.133], [64666.5, 0.015], [64669.4, 0.006], [64671.7, 1.141], [64677.4, 0.106], [64678.7, 0.474], [64679.5, 0.157], [64680.2, 0.379], [64682.3, 0.141], [64682.4, 0.0], [64682.5, 0.019], [64684.3, 0.02], [64685.3, 2.324], [64685.5, 0.016], [64685.8, 0.148], [64686.2, 0.003], [64687.7, 0.084], [64687.8, 0.053], [64688.1, 1.648], [64688.2, 0.0], [64688.4, 0.001], [64688.5, 0.084], [64688.6, 0.0], [64689.8, 0.064], [64689.9, 9.533]], "asks": [[64690.0, 8.384], [64691.5, 0.013], [64691.6, 0.214], [64691.7, 0.283], [64691.8, 0.003], [64691.9, 0.013], [64692.1, 0.018], [64693.0, 0.002], [64693.1, 0.332], [64694.5, 0.166], [64694.6, 0.728], [64694.7, 1.35], [64695.7, 0.086], [64696.2, 0.001], [64698.9, 0.281], [64699.1, 0.604], [64702.0, 0.004], [64708.3, 0.157], [64716.6, 0.002], [64716.9, 0.271], [64728.6, 0.0], [64732.7, 0.015], [64749.6, 0.021], [64755.3, 1.449], [64755.4, 0.03], [64847.9, 10.792], [64886.7, 8.286], [65336.9, 3.821], [65337.1, 3.212], [65531.2, 2.132]]}
{"kind": "depth", "E": 1787095387779, "U": 11316375700514, "u": 11316375707395, "recv_ms": 1787095387838, "bids": [[14189.9, 1.512], [14289.9, 2.688], [58220.9, 0.002], [61455.4, 0.004], [62102.3, 1.525], [63396.2, 0.02], [63654.9, 5.931], [63689.9, 0.01], [63865.1, 12.116], [64043.0, 1.592], [64366.5, 3.257], [64591.3, 0.0], [64591.4, 2.488], [64659.1, 0.038], [64662.5, 0.447], [64664.1, 1.658], [64664.2, 0.02], [64666.3, 2.04], [64668.8, 1.957], [64669.4, 0.006], [64677.4, 0.106], [64678.7, 0.015], [64679.7, 0.717], [64680.2, 0.379], [64682.3, 0.141], [64682.4, 0.0], [64684.3, 0.02], [64685.1, 0.003], [64685.3, 2.323], [64685.5, 0.462], [64685.8, 0.086], [64687.3, 0.086], [64687.4, 0.005], [64687.6, 0.003], [64687.8, 0.116], [64688.1, 0.103], [64688.2, 0.0], [64688.3, 0.0], [64688.4, 0.001], [64688.5, 1.629], [64689.4, 0.019], [64689.7, 0.012], [64689.8, 0.314], [64689.9, 9.65]], "asks": [[64690.0, 8.084], [64692.5, 0.001], [64692.9, 0.004], [64693.0, 0.002], [64693.2, 0.23], [64694.0, 0.001], [64694.5, 0.285], [64696.0, 0.177], [64696.2, 0.001], [64698.9, 0.281], [64699.1, 0.604], [64703.0, 0.914], [64708.3, 0.157], [64708.4, 1.008], [64716.3, 0.002], [64716.7, 0.317], [64716.9, 0.271], [64728.5, 0.225], [64787.4, 1.959], [64787.7, 0.003], [64787.8, 0.004], [64788.7, 0.035], [65336.9, 3.821], [65510.9, 0.001], [65531.2, 2.665], [65542.7, 3.811], [65563.3, 8.822], [65690.0, 0.413]]}
{"kind": "depth", "E": 1787095387881, "U": 11316375707595, "u": 11316375713987, "recv_ms": 1787095387938, "bids": [[1000.0, 35.76], [14189.9, 1.876], [14289.9, 2.324], [51752.0, 0.0], [58220.9, 0.002], [61455.4, 0.004], [62102.3, 1.522], [63784.2, 18.119], [63865.1, 11.531], [64043.0, 1.591], [64590.8, 0.039], [64591.5, 0.0], [64601.4, 0.017], [64608.4, 0.008], [64620.7, 0.028], [64623.6, 6.026], [64625.1, 0.002], [64625.7, 0.003], [64627.3, 37.844], [64646.2, 3.532], [64659.1, 0.192], [64662.4, 0.69], [64667.3, 0.001], [64672.6, 0.001], [64677.1, 0.007], [64677.4, 0.106], [64680.1, 1.433], [64680.2, 0.379], [64682.0, 0.042], [64682.3, 0.141], [64682.4, 0.001], [64684.3, 0.466], [64685.3, 2.323], [64685.5, 0.016], [64685.6, 0.005], [64685.8, 0.086], [64686.2, 0.003], [64687.4, 0.006], [64687.6, 0.065], [64687.8, 0.053], [64688.1, 0.103], [64688.2, 1.545], [64688.4, 0.001], [64688.5, 0.084], [64688.6, 0.0], [64689.8, 0.295], [64689.9, 9.659]], "asks": [[64693.0, 0.002], [64694.5, 0.391], [64696.2, 0.001], [64698.9, 0.281], [64699.1, 0.604], [64703.0, 0.014], [64704.0, 1.035], [64708.3, 0.157], [64716.6, 0.56], [64716.9, 0.271], [64728.5, 0.071], [64728.6, 0.154], [64732.7, 3.515], [64735.5, 0.003], [64755.4, 6.03], [65336.9, 3.821], [67924.5, 0.027]]}
{"kind": "depth", "E": 1787095387983, "U": 11316375714045, "u": 11316375718742, "recv_ms": 1787095388041, "bids": [[1000.0, 35.76], [14189.9, 2.226], [14289.9, 1.974], [58220.9, 0.002], [61455.4, 0.002], [61455.5, 0.01], [62102.3, 1.525], [63689.9, 0.03], [63897.4, 43.518], [64043.0, 1.591], [64054.8, 3.483], [64558.5, 0.001], [64579.9, 0.003], [64591.3, 10.0], [64591.4, 3.667], [64600.0, 3.738], [64659.1, 0.038], [64671.5, 0.7], [64678.9, 2.039], [64682.3, 1.687], [64684.3, 0.02], [64685.4, 0.999], [64685.5, 0.016], [64687.4, 0.005], [64687.6, 0.003], [64687.8, 0.116], [64688.2, 0.0], [64688.3, 0.0], [64689.9, 9.664]], "asks": [[64692.9, 0.088], [64694.5, 0.391], [64701.0, 2.079], [64706.2, 0.257], [64708.4, 1.626], [64728.6, 0.0], [64749.6, 0.012], [64767.7, 0.003], [64787.4, 2.765], [64787.8, 10.004], [64817.4, 0.0], [64830.2, 2.116], [64849.8, 0.001], [65013.5, 1.692], [65207.5, 10.282], [65336.9, 3.821], [65498.6, 9.575], [65531.2, 3.198], [65690.0, 0.433], [66307.3, 0.602]]}
{"kind": "depth", "E": 1787095388085, "U": 11316375718799, "u": 11316375722938, "recv_ms": 1787095388146, "bids": [[14189.9, 2.576], [14289.9, 1.624], [51752.0, 0.0], [58220.9, 0.002], [61455.4, 0.002], [63689.9, 0.01], [64043.0, 1.591], [64366.4, 2.108], [64366.5, 3.267], [64590.8, 0.031], [64591.5, 0.008], [64622.9, 37.87], [64627.3, 0.001], [64659.1, 0.192], [64678.3, 0.074], [64682.3, 1.687], [64682.4, 0.017], [64684.3, 0.466], [64685.4, 0.553], [64685.6, 0.067], [64686.2, 0.004], [64687.8, 0.053], [64688.1, 0.087], [64688.2, 0.0], [64689.8, 0.064], [64689.9, 9.693]], "asks": [[64691.5, 0.013], [64694.2, 0.703], [64694.3, 0.0], [64694.4, 0.282], [64694.5, 0.166], [64694.6, 0.187], [64728.7, 0.182], [64787.7, 0.011], [64788.7, 0.027], [65336.9, 3.823], [65401.9, 0.765], [65690.0, 0.413], [65865.6, 1.3]]}
{"kind": "depth", "E": 1787095388187, "U": 11316375722950, "u": 11316375728012, "recv_ms": 1787095388248, "bids": [[1000.0, 35.76], [14189.9, 2.94], [14289.9, 1.26], [51752.0, 0.0], [58220.9, 0.002], [61455.4, 0.003], [62102.3, 1.522], [63396.2, 0.014], [63492.2, 0.716], [63934.2, 4.686], [64043.0, 1.593], [64075.3, 12.677], [64586.6, 2.325], [64587.0, 0.064], [64682.3, 0.141], [64682.4, 0.001], [64684.3, 0.02], [64685.3, 2.323], [64685.5, 0.462], [64685.6, 0.005], [64686.2, 0.003], [64687.3, 0.086], [64687.4, 0.005], [64687.6, 0.003], [64687.8, 0.116], [64688.1, 0.103], [64688.2, 0.0], [64688.3, 1.545], [64689.8, 0.295], [64689.9, 9.687]], "asks": [[64694.0, 0.001], [64694.1, 0.09], [64694.2, 0.162], [64694.4, 0.044], [64694.5, 0.707], [64728.7, 0.028], [64800.5, 2.321], [64800.8, 0.001], [65336.9, 3.821], [65413.4, 5.343]]}
{"kind": "depth", "E": 1787095388289, "U": 11316375728108, "u": 11316375734099, "recv_ms": 1787095388346, "bids": [[1000.0, 35.76], [14189.9, 3.29], [14289.9, 0.91], [51752.0, 0.0], [58220.9, 0.002], [61455.4, 0.002], [62102.3, 1.525], [63689.9, 0.03], [64043.0, 1.591], [64659.1, 0.038], [64681.0, 0.936], [64681.5, 0.358], [64682.3, 0.141], [64682.4, 0.0], [64685.5, 0.016], [64686.9, 0.031], [64687.4, 0.008], [64688.1, 0.087], [64688.3, 0.0], [64688.4, 0.001], [64688.5, 1.629], [64688.6, 0.016], [64689.9, 9.69]], "asks": [[64694.4, 0.044], [64699.4, 0.468], [64699.9, 3.097], [64716.1, 0.985], [64716.9, 0.156], [64717.0, 2.242], [64717.1, 1.317], [65336.9, 3.821], [65690.0, 0.433]]}
{"kind": "depth", "E": 1787095388391, "U": 11316375734235, "u": 11316375741218, "recv_ms": 1787095388458, "bids": [[14189.9, 3.654], [14289.9, 0.546], [58220.9, 0.002], [61455.4, 0.002], [62102.3, 1.522], [63923.6, 1.562], [64043.0, 1.591], [64258.4, 0.076], [64264.8, 0.443], [64366.4, 2.109], [64366.5, 3.257], [64549.5, 0.121], [64622.9, 0.027], [64625.1, 37.845], [64633.2, 0.001], [64634.6, 0.284], [64647.0, 0.0], [64667.3, 0.001], [64677.1, 0.007], [64677.4, 0.106], [64680.2, 0.379], [64682.3, 1.703], [64682.4, 0.001], [64682.5, 0.019], [64685.3, 2.324], [64685.5, 0.016], [64685.6, 0.067], [64686.2, 0.003], [64687.3, 0.086], [64687.8, 0.053], [64688.5, 0.084], [64688.6, 0.0], [64689.8, 0.064], [64689.9, 9.688]], "asks": [[64694.4, 0.424], [64694.5, 0.552], [64698.9, 0.281], [64699.1, 0.604], [64708.3, 0.157], [64716.9, 0.156], [64738.9, 0.004], [64741.4, 0.103], [64746.5, 0.032], [64830.2, 1.501], [64830.9, 0.06], [65013.5, 1.691], [65336.9, 3.821], [65449.7, 24.783], [65533.4, 3.025], [65539.9, 0.077]]}
{"kind": "depth", "E": 1787095388493, "U": 11316375741319, "u": 11316375745621, "recv_ms": 1787095388553, "bids": [[1000.0, 35.76], [14189.9, 3.752], [14289.9, 0.322], [14589.9, 0.126], [58220.9, 0.002], [61455.4, 0.002], [62102.3, 1.525], [63396.2, 0.011], [63858.9, 0.782], [64043.0, 1.591], [64258.4, 0.0], [64264.8, 0.439], [64549.5, 4.378], [64640.6, 0.465], [64647.0, 0.004], [64673.5, 2.811], [64682.2, 0.777], [64682.3, 0.056], [64682.4, 0.0], [64684.3, 0.02], [64684.4, 0.001], [64685.3, 2.323], [64685.5, 0.016], [64685.6, 0.005], [64685.7, 0.446], [64687.4, 0.008], [64687.6, 0.003], [64687.8, 0.116], [64688.1, 1.648], [64689.8, 0.295], [64689.9, 9.692]], "asks": [[64694.4, 0.424], [64706.0, 0.382], [64739.4, 0.007], [64745.8, 0.076], [64830.9, 5.459], [64886.7, 9.344], [65336.9, 3.821], [65533.4, 3.021], [65539.9, 0.0], [65983.7, 0.015]]}
{"kind": "depth", "E": 1787095388595, "U": 11316375745789, "u": 11316375751187, "recv_ms": 1787095388654, "bids": [[1000.0, 35.76], [14189.9, 3.64], [14289.9, 0.196], [14589.9, 0.364], [58220.9, 0.002], [61455.4, 0.004], [63689.9, 0.01], [64043.0, 1.591], [64667.3, 0.156], [64677.1, 0.162], [64677.4, 0.261], [64680.2, 0.534], [64682.3, 0.211], [64682.4, 0.001], [64684.3, 0.02], [64685.5, 0.171], [64685.7, 0.0], [64688.1, 0.103], [64688.2, 0.0], [64688.3, 1.545], [64689.9, 9.691]], "asks": [[64691.5, 0.013], [64691.6, 0.214], [64691.7, 0.283], [64693.0, 0.002], [64693.1, 0.332], [64694.4, 0.269], [64694.6, 0.187], [64694.7, 1.35], [64696.2, 0.001], [64698.9, 0.126], [64699.1, 0.294], [64708.3, 0.002], [64716.9, 0.001], [64886.7, 9.345], [65336.9, 3.821], [65619.9, 1.599], [65690.0, 0.413], [65983.7, 0.018]]}
