{"kind": "depth", "E": 1787095345551, "U": 11316372537992, "u": 11316372548055, "recv_ms": 1787095345639, "bids": [[1000.0, 35.76], [14189.9, 0.728], [14287.9, 2.646], [14288.0, 0.014], [14288.3, 0.028], [14289.9, 0.728], [14387.9, 0.014], [58220.9, 0.002], [62102.3, 0.144], [63689.9, 0.01], [63749.9, 3.158], [63801.4, 0.0], [63918.1, 5.313], [64043.0, 0.032], [64220.2, 0.122], [64230.2, 0.239], [64545.3, 3.412], [64545.6, 4.132], [64577.9, 1.187], [64588.7, 0.006], [64625.7, 7.289], [64629.6, 1.173], [64645.5, 0.03], [64645.8, 0.283], [64650.0, 3.371], [64661.8, 0.057], [64662.5, 0.347], [64670.5, 0.001], [64674.1, 0.003], [64677.4, 0.151], [64678.7, 0.506], [64679.4, 0.512], [64679.8, 0.0], [64682.6, 0.036], [64682.7, 0.001], [64685.2, 0.003], [64685.7, 0.004], [64688.1, 0.355], [64689.9, 34.646]], "asks": [[64690.0, 5.291], [64692.9, 0.758], [64693.1, 0.462], [64693.3, 0.22], [64693.5, 0.087], [64693.7, 0.084], [64693.8, 0.396], [64694.5, 0.0], [64694.6, 0.163], [64694.7, 1.432], [64696.5, 0.086], [64696.9, 0.088], [64698.9, 0.366], [64699.0, 0.647], [64699.1, 0.714], [64700.4, 0.392], [64704.0, 2.329], [64706.0, 0.382], [64709.2, 0.321], [64713.8, 0.066], [64715.6, 2.443], [64716.9, 0.311], [64719.6, 0.37], [64723.9, 0.015], [64729.3, 0.154], [64733.5, 1.501], [64735.1, 0.026], [64747.0, 0.009], [64768.4, 8.16], [64770.1, 45.839], [64781.1, 0.0], [64810.5, 0.09], [64830.1, 5.399], [64847.1, 10.41], [64885.9, 8.677], [65011.5, 0.008], [65336.9, 0.001], [65690.0, 0.413]]}
{"kind": "depth", "E": 1787095345653, "U": 11316372548296, "u": 11316372555756, "recv_ms": 1787095345709, "bids": [[1000.0, 35.76], [14189.9, 1.064], [14287.9, 2.492], [14288.0, 0.0], [14288.3, 0.014], [14288.9, 0.014], [14289.9, 0.602], [14387.9, 0.0], [58220.9, 0.004], [61455.4, 0.0], [62102.3, 0.147], [63396.2, 0.014], [63514.7, 2.205], [63897.4, 56.326], [63903.9, 3.752], [64043.0, 0.032], [64366.4, 0.013], [64656.5, 0.0], [64656.7, 0.036], [64659.5, 0.002], [64666.3, 0.04], [64673.4, 0.003], [64675.3, 0.002], [64675.9, 0.562], [64678.8, 0.002], [64679.8, 0.108], [64680.0, 0.151], [64682.6, 0.005], [64685.7, 0.004], [64687.7, 0.001], [64687.8, 0.137], [64687.9, 0.014], [64688.2, 0.236], [64688.6, 0.0], [64689.7, 0.005], [64689.8, 1.319], [64689.9, 34.65]], "asks": [[64693.4, 0.239], [64694.1, 0.018], [64694.6, 0.163], [64694.7, 1.439], [64694.9, 0.007], [64696.3, 0.0], [64698.8, 0.081], [64699.0, 0.64], [64699.1, 0.648], [64699.3, 9.99], [64701.1, 0.633], [64702.4, 0.004], [64703.3, 0.0], [64713.8, 0.009], [64714.7, 0.088], [64715.5, 0.003], [64716.3, 0.673], [64716.7, 0.065], [64717.3, 0.0], [64717.5, 0.31], [64717.6, 0.001], [64718.4, 1.353], [64718.5, 0.014], [64719.6, 0.061], [64720.1, 0.0], [64733.3, 1.099], [64743.8, 7.269], [64744.1, 0.01], [64749.7, 0.075], [64823.3, 0.478], [65336.9, 0.001], [65619.9, 5.934], [65776.8, 0.626]]}
{"kind": "depth", "E": 1787095345755, "U": 11316372556045, "u": 11316372563572, "recv_ms": 1787095345812, "bids": [[14189.9, 1.428], [14287.9, 2.254], [14289.9, 0.476], [58220.9, 0.002], [61455.4, 0.0], [62102.3, 0.144], [63214.1, 0.001], [63689.9, 0.03], [63912.6, 4.377], [64043.0, 0.032], [64091.3, 2.182], [64231.9, 0.119], [64366.5, 0.01], [64618.5, 38.834], [64625.1, 6.267], [64625.7, 1.714], [64630.6, 0.0], [64670.5, 0.001], [64674.1, 0.003], [64675.3, 0.559], [64675.9, 0.005], [64677.4, 0.167], [64678.5, 0.583], [64679.8, 0.092], [64680.5, 0.218], [64682.6, 0.005], [64685.2, 0.003], [64685.6, 0.172], [64689.9, 34.651]], "asks": [[64693.8, 0.086], [64694.6, 0.473], [64694.7, 1.98], [64698.8, 0.004], [64698.9, 0.366], [64699.0, 0.099], [64699.1, 0.725], [64709.2, 0.321], [64716.9, 0.311], [64885.9, 8.789], [65336.9, 0.001], [65477.7, 4.502], [65690.0, 0.433], [65866.1, 0.759]]}
{"kind": "depth", "E": 1787095345857, "U": 11316372563813, "u": 11316372570607, "recv_ms": 1787095345914, "bids": [[1000.0, 35.76], [14189.9, 1.792], [14287.9, 2.002], [14289.9, 0.364], [51752.0, 0.0], [58220.9, 0.002], [61455.4, 0.0], [63232.4, 0.632], [63523.5, 0.628], [63796.9, 0.005], [63832.7, 23.657], [63879.3, 1.17], [63918.1, 6.251], [64043.0, 0.032], [64545.3, 0.001], [64545.4, 3.433], [64618.5, 0.001], [64625.1, 44.338], [64644.8, 1.038], [64656.7, 0.026], [64656.9, 0.638], [64670.5, 0.001], [64674.1, 0.003], [64677.4, 0.151], [64679.8, 0.0], [64682.6, 0.113], [64685.2, 0.003], [64685.6, 0.172], [64687.9, 0.018], [64688.5, 0.005], [64689.0, 0.004], [64689.6, 0.0], [64689.9, 34.666]], "asks": [[64690.0, 6.569], [64693.7, 0.001], [64693.8, 0.396], [64694.1, 0.015], [64694.5, 0.0], [64694.6, 0.163], [64694.7, 2.063], [64694.9, 0.01], [64695.6, 0.004], [64696.5, 0.091], [64698.9, 0.056], [64699.1, 1.035], [64709.2, 0.321], [64716.9, 0.311], [64718.3, 0.425], [64718.6, 0.196], [64744.1, 0.0], [64744.2, 0.01], [64830.1, 5.399], [64885.9, 8.678], [65200.0, 135.287], [65336.9, 0.001], [65461.5, 3.835], [65484.8, 2.095], [65785.3, 1.969]]}
{"kind": "depth", "E": 1787095345959, "U": 11316372570674, "u": 11316372579627, "recv_ms": 1787095346015, "bids": [[1000.0, 35.76], [14189.9, 2.128], [14287.9, 1.778], [14289.9, 0.252], [58220.9, 0.002], [61455.4, 0.0], [62102.3, 0.147], [63689.9, 0.01], [63911.6, 6.082], [63931.1, 0.547], [64043.0, 0.032], [64103.8, 1.095], [64172.4, 0.032], [64342.6, 0.505], [64346.8, 0.0], [64365.0, 0.069], [64417.6, 0.004], [64418.9, 0.014], [64566.2, 0.858], [64652.5, 0.004], [64677.4, 0.167], [64679.8, 0.092], [64682.6, 0.005], [64685.3, 0.0], [64688.2, 0.004], [64688.9, 0.407], [64689.1, 0.086], [64689.6, 0.0], [64689.9, 35.052]], "asks": [[64690.0, 6.572], [64692.8, 0.232], [64693.0, 0.279], [64693.8, 0.396], [64694.1, 0.015], [64694.6, 0.246], [64694.7, 1.98], [64699.0, 0.099], [64718.4, 1.353], [64718.5, 0.014], [64718.6, 0.042], [64721.3, 0.159], [65336.9, 0.001], [65494.2, 0.005], [65640.9, 1.218], [65690.0, 0.413]]}
{"kind": "depth", "E": 1787095346061, "U": 11316372579814, "u": 11316372590429, "recv_ms": 1787095346118, "bids": [[14189.9, 2.506], [14287.9, 1.526], [14289.9, 0.126], [58220.9, 0.002], [61455.4, 0.001], [62102.3, 0.144], [62736.2, 0.682], [63394.2, 0.009], [64043.0, 0.032], [64062.2, 59.696], [64109.0, 0.0], [64111.0, 2.963], [64269.3, 0.031], [64271.2, 0.008], [64288.4, 0.002], [64366.5, 0.0], [64429.9, 0.011], [64431.9, 0.009], [64545.4, 3.531], [64567.6, 0.01], [64568.5, 0.07], [64579.5, 0.001], [64581.8, 2.352], [64582.3, 0.001], [64582.4, 0.008], [64591.0, 0.0], [64593.0, 0.021], [64640.3, 0.023], [64656.9, 0.628], [64657.0, 0.013], [64662.5, 0.347], [64664.2, 0.17], [64667.0, 8.357], [64670.3, 0.002], [64670.5, 0.001], [64670.8, 0.738], [64674.1, 0.003], [64677.4, 0.306], [64677.6, 0.358], [64678.2, 0.621], [64678.3, 0.242], [64679.8, 0.108], [64682.6, 0.005], [64682.7, 0.001], [64685.2, 0.003], [64685.4, 0.003], [64685.7, 0.004], [64687.6, 0.006], [64687.9, 0.014], [64688.5, 0.004], [64688.8, 0.087], [64689.9, 35.836]], "asks": [[64690.0, 6.415], [64691.3, 0.002], [64691.6, 0.117], [64692.6, 0.163], [64693.0, 0.195], [64693.2, 0.568], [64693.4, 0.155], [64693.8, 0.311], [64694.6, 0.401], [64694.7, 1.439], [64696.9, 0.088], [64698.7, 0.126], [64699.1, 1.266], [64701.7, 0.619], [64703.2, 0.064], [64704.6, 0.0], [64707.6, 1.65], [64708.5, 0.035], [64709.1, 0.618], [64709.2, 0.321], [64711.8, 0.414], [64712.1, 0.318], [64712.2, 0.268], [64713.1, 0.068], [64715.6, 2.391], [64716.9, 0.311], [64718.4, 1.355], [64718.5, 0.014], [64718.6, 0.042], [64718.7, 2.323], [64718.9, 0.159], [64719.7, 1.472], [64722.0, 11.547], [64744.2, 0.0], [64744.4, 0.397], [64763.5, 0.013], [64763.7, 0.029], [64770.5, 0.014], [64770.8, 0.013], [64777.6, 0.013], [64777.8, 0.0], [64784.6, 2.332], [64784.9, 0.004], [64786.9, 1.005], [64791.7, 0.013], [64792.0, 0.023], [64795.2, 4.84], [64795.7, 2.319], [64798.7, 0.018], [64799.0, 0.454], [64805.8, 0.051], [64806.1, 0.013], [64808.0, 5.245], [64808.1, 0.091], [64812.9, 0.016], [64813.1, 0.0], [64830.1, 5.399], [64885.9, 8.602], [64946.9, 0.005], [64948.9, 0.004], [65013.5, 0.001], [65109.2, 0.002], [65111.2, 0.601], [65272.0, 0.019], [65274.0, 0.061], [65326.4, 57.616], [65334.9, 1.668], [65336.9, 0.001], [65466.3, 0.772], [65498.6, 0.57], [65526.6, 2.287], [65983.7, 0.003], [66016.2, 2.269]]}
{"kind": "depth", "E": 1787095346163, "U": 11316372590520, "u": 11316372598409, "recv_ms": 1787095346220, "bids": [[1000.0, 35.76], [14189.9, 2.856], [14287.9, 1.302], [14289.9, 0.0], [51750.0, 0.064], [51751.9, 0.0], [51752.0, 0.0], [58220.9, 0.002], [61455.4, 0.001], [62102.3, 0.147], [63569.8, 8.01], [63689.9, 0.03], [63848.9, 0.313], [64043.0, 0.032], [64547.3, 0.015], [64618.5, 38.072], [64625.1, 6.267], [64640.0, 0.028], [64657.0, 0.003], [64657.1, 0.029], [64663.2, 0.002], [64667.5, 0.016], [64670.8, 0.12], [64673.5, 2.424], [64674.1, 0.003], [64677.4, 0.151], [64677.6, 0.203], [64678.2, 0.003], [64679.8, 0.108], [64682.6, 0.005], [64685.1, 0.0], [64685.2, 0.003], [64688.0, 2.857], [64688.2, 0.001], [64688.9, 0.175], [64689.4, 0.232], [64689.9, 35.727]], "asks": [[64690.0, 8.586], [64690.1, 0.011], [64692.2, 0.086], [64692.7, 0.186], [64693.7, 0.156], [64693.8, 0.086], [64694.4, 0.127], [64694.6, 0.704], [64694.9, 0.008], [64695.9, 0.35], [64696.9, 0.004], [64697.3, 0.071], [64699.0, 0.409], [64699.1, 0.26], [64701.7, 0.001], [64704.0, 2.333], [64706.0, 0.382], [64708.7, 0.197], [64709.2, 0.011], [64716.9, 0.156], [64718.9, 0.005], [64719.1, 0.201], [64744.4, 0.387], [64744.5, 0.011], [64747.0, 0.0], [65336.9, 0.001], [65690.0, 0.433]]}
{"kind": "depth", "E": 1787095346265, "U": 11316372598797, "u": 11316372608365, "recv_ms": 1787095346323, "bids": [[1000.0, 35.76], [14189.9, 3.206], [14287.9, 0.994], [14288.3, 0.0], [14288.5, 0.0], [14288.9, 0.0], [51750.0, 0.064], [51752.0, 0.002], [58220.9, 0.002], [61455.4, 0.001], [62102.3, 0.144], [63396.2, 0.017], [63674.1, 0.673], [64043.0, 0.032], [64054.8, 8.933], [64547.3, 0.015], [64590.1, 0.002], [64617.3, 0.004], [64618.5, 0.001], [64620.0, 0.022], [64622.9, 0.027], [64625.1, 6.267], [64625.2, 0.02], [64629.5, 38.106], [64642.3, 2.321], [64643.2, 0.037], [64652.1, 0.076], [64656.0, 0.013], [64657.9, 0.312], [64658.9, 2.604], [64661.8, 0.106], [64664.0, 1.446], [64664.5, 0.038], [64667.0, 0.36], [64667.1, 1.293], [64668.7, 0.312], [64671.2, 0.003], [64671.6, 0.003], [64672.6, 0.137], [64673.1, 0.0], [64673.4, 0.002], [64676.1, 0.02], [64676.8, 0.005], [64677.1, 0.081], [64677.4, 0.151], [64679.4, 0.093], [64679.6, 0.555], [64679.7, 0.271], [64679.8, 0.003], [64680.6, 0.026], [64680.9, 0.003], [64681.0, 0.904], [64682.1, 2.474], [64682.2, 1.549], [64682.3, 0.041], [64682.4, 0.0], [64682.5, 0.022], [64682.6, 0.63], [64682.7, 0.017], [64683.0, 0.023], [64684.0, 1.286], [64684.1, 0.0], [64684.4, 0.155], [64684.5, 0.096], [64684.6, 0.002], [64685.0, 0.229], [64685.6, 0.018], [64686.3, 0.084], [64687.6, 0.005], [64687.7, 0.004], [64687.9, 0.013], [64688.0, 0.318], [64688.1, 0.004], [64688.2, 0.005], [64688.3, 0.006], [64688.4, 0.001], [64688.5, 0.002], [64688.7, 0.232], [64688.8, 0.003], [64689.0, 0.067], [64689.1, 0.002], [64689.4, 0.0], [64689.5, 0.0], [64689.8, 0.688], [64689.9, 18.682]], "asks": [[64690.0, 9.102], [64690.9, 0.088], [64691.2, 0.003], [64691.4, 0.035], [64691.5, 0.232], [64691.6, 0.22], [64691.8, 0.087], [64691.9, 0.323], [64692.5, 0.479], [64692.6, 0.163], [64692.7, 0.178], [64692.9, 0.122], [64693.1, 0.454], [64693.3, 0.22], [64693.4, 0.155], [64693.5, 0.094], [64693.7, 0.001], [64693.8, 0.086], [64693.9, 0.003], [64694.0, 0.001], [64694.1, 0.24], [64694.4, 0.127], [64694.5, 0.016], [64694.8, 7.402], [64694.9, 0.009], [64696.1, 0.002], [64696.5, 0.007], [64696.9, 0.001], [64697.3, 0.07], [64699.0, 0.099], [64699.1, 0.105], [64703.1, 0.008], [64706.3, 0.103], [64708.7, 0.042], [64709.1, 0.0], [64709.2, 0.629], [64710.3, 0.121], [64713.6, 0.705], [64716.3, 0.743], [64716.5, 0.198], [64716.6, 4.002], [64716.9, 0.001], [64719.1, 0.047], [64719.2, 0.532], [64722.0, 1.547], [64723.6, 0.006], [64725.8, 4.263], [64745.2, 3.866], [64764.6, 3.863], [64784.1, 5.144], [64830.1, 5.399], [64847.1, 10.41], [64885.9, 8.98], [64899.0, 3.577], [64919.5, 0.004], [65336.9, 0.001], [65498.6, 0.799], [65579.3, 3.125]]}
{"kind": "depth", "E": 1787095346367, "U": 11316372608379, "u": 11316372636353, "recv_ms": 1787095346424, "bids": [[14189.9, 3.57], [14287.9, 0.63], [51752.0, 0.0], [58220.9, 0.002], [61455.4, 0.0], [63689.9, 0.01], [63880.8, 16.845], [63913.1, 3.098], [63913.6, 3.098], [63945.5, 0.0], [63946.0, 3.1], [63950.5, 5.474], [63978.3, 3.095], [64043.0, 0.033], [64366.5, 0.01], [64575.2, 0.005], [64607.6, 0.003], [64622.9, 38.098], [64629.5, 0.035], [64632.9, 0.018], [64640.0, 0.03], [64650.4, 0.037], [64657.1, 0.019], [64657.2, 0.072], [64664.2, 0.17], [64677.4, 0.151], [64679.7, 0.271], [64680.9, 0.015], [64682.1, 2.475], [64682.3, 0.04], [64682.7, 0.017], [64683.2, 0.001], [64684.0, 0.854], [64684.9, 0.429], [64685.2, 0.003], [64685.3, 0.002], [64686.6, 0.244], [64687.7, 0.236], [64687.9, 0.011], [64688.7, 0.0], [64689.0, 0.032], [64689.9, 18.151]], "asks": [[64690.0, 9.103], [64691.5, 0.232], [64692.8, 0.231], [64694.1, 0.24], [64694.4, 0.127], [64694.5, 0.171], [64695.0, 0.106], [64698.5, 0.322], [64699.1, 0.57], [64700.4, 0.433], [64701.8, 0.002], [64704.2, 1.086], [64707.5, 0.12], [64708.7, 0.197], [64716.5, 0.339], [64719.2, 0.378], [64719.4, 0.299], [64739.9, 0.033], [64744.5, 0.001], [64744.6, 0.103], [64772.3, 7.408], [64804.7, 0.007], [64810.6, 0.0], [65336.9, 0.001], [65595.7, 2.742], [65690.0, 0.413]]}
{"kind": "depth", "E": 1787095346469, "U": 11316372636771, "u": 11316372670732, "recv_ms": 1787095346528, "bids": [[1000.0, 35.76], [14189.9, 3.752], [14287.9, 0.364], [14589.9, 0.084], [58220.9, 0.002], [61455.4, 0.0], [62102.3, 0.147], [63832.7, 22.563], [63912.6, 3.83], [64042.5, 0.0], [64043.0, 0.035], [64075.3, 4.114], [64547.3, 0.016], [64616.9, 0.012], [64620.8, 0.801], [64622.9, 0.027], [64626.5, 0.408], [64627.0, 0.195], [64627.3, 38.072], [64627.7, 1.988], [64629.4, 0.0], [64631.0, 0.905], [64632.9, 0.046], [64633.6, 0.635], [64636.5, 0.283], [64643.1, 0.06], [64646.2, 0.469], [64650.3, 0.074], [64652.1, 0.016], [64653.4, 0.013], [64654.5, 8.005], [64655.3, 2.442], [64655.7, 0.019], [64658.7, 0.102], [64658.9, 0.604], [64659.7, 0.007], [64659.9, 0.0], [64660.3, 0.001], [64660.8, 1.303], [64661.0, 0.057], [64661.8, 0.049], [64663.0, 0.001], [64663.6, 0.397], [64663.8, 0.073], [64664.2, 0.325], [64664.8, 0.232], [64666.6, 0.002], [64668.1, 0.025], [64670.1, 0.02], [64670.2, 0.314], [64670.9, 0.005], [64671.6, 0.001], [64671.7, 1.257], [64671.8, 0.001], [64672.6, 0.021], [64673.6, 1.264], [64674.1, 0.56], [64675.0, 0.466], [64675.3, 0.009], [64676.1, 0.013], [64676.5, 1.408], [64676.8, 0.005], [64677.4, 0.461], [64677.8, 0.901], [64678.4, 0.062], [64678.7, 0.047], [64679.2, 0.007], [64679.7, 0.426], [64679.9, 0.002], [64680.0, 0.131], [64680.2, 0.547], [64680.5, 0.372], [64680.6, 0.019], [64680.9, 0.014], [64681.0, 0.004], [64681.2, 1.496], [64681.5, 0.069], [64682.1, 2.321], [64682.2, 0.166], [64682.3, 0.024], [64682.5, 0.017], [64682.6, 0.005], [64682.7, 0.001], [64682.8, 0.001], [64683.0, 0.088], [64683.2, 0.155], [64683.3, 0.213], [64683.4, 0.092], [64683.8, 0.102], [64683.9, 0.003], [64684.0, 0.544], [64684.1, 2.286], [64684.2, 1.346], [64684.4, 0.001], [64684.5, 0.085], [64684.6, 0.002], [64684.8, 0.011], [64685.0, 0.225], [64685.2, 0.003], [64685.7, 0.164], [64685.8, 0.318], [64686.2, 0.003], [64686.3, 0.184], [64686.5, 0.008], [64686.7, 0.004], [64687.0, 0.056], [64687.1, 0.0], [64687.2, 0.004], [64687.3, 0.12], [64687.4, 0.001], [64687.6, 0.001], [64687.7, 0.001], [64687.8, 0.055], [64688.0, 0.23], [64688.1, 0.002], [64688.2, 0.001], [64688.3, 0.006], [64688.5, 0.0], [64688.8, 0.004], [64689.1, 0.0], [64689.7, 0.003], [64689.8, 0.04], [64689.9, 7.802]], "asks": [[64690.0, 9.466], [64690.4, 0.087], [64691.5, 0.078], [64691.8, 0.088], [64692.4, 0.07], [64692.5, 0.78], [64692.9, 0.663], [64693.0, 0.624], [64693.1, 0.464], [64693.2, 0.651], [64693.3, 0.607], [64693.4, 0.158], [64693.5, 0.094], [64693.6, 0.17], [64693.7, 0.001], [64693.8, 0.086], [64693.9, 0.003], [64694.1, 0.015], [64694.4, 0.044], [64694.5, 0.093], [64694.6, 0.163], [64694.7, 1.432], [64694.8, 7.4], [64694.9, 0.006], [64695.0, 0.026], [64695.7, 0.006], [64695.8, 0.039], [64696.1, 0.282], [64697.1, 0.028], [64697.5, 0.161], [64697.8, 0.111], [64699.0, 0.099], [64699.1, 0.012], [64700.4, 0.392], [64700.8, 2.409], [64702.4, 0.004], [64702.6, 0.115], [64702.9, 2.21], [64703.2, 0.067], [64704.8, 0.076], [64706.0, 0.389], [64706.8, 0.014], [64707.2, 0.01], [64707.3, 0.034], [64708.7, 0.041], [64708.8, 1.373], [64708.9, 0.001], [64709.3, 2.869], [64710.7, 3.721], [64710.9, 0.466], [64711.2, 0.451], [64711.8, 10.414], [64712.0, 1.463], [64712.8, 2.88], [64714.4, 0.728], [64714.7, 0.031], [64715.4, 0.072], [64716.3, 0.117], [64716.5, 0.17], [64716.6, 0.002], [64716.9, 0.001], [64717.7, 6.044], [64718.2, 0.02], [64718.5, 0.0], [64718.8, 0.301], [64719.1, 0.019], [64719.2, 0.532], [64719.4, 0.145], [64720.7, 0.0], [64722.3, 1.515], [64723.3, 5.914], [64724.5, 0.019], [64724.9, 0.036], [64725.3, 0.027], [64725.6, 0.007], [64726.6, 1.204], [64729.4, 0.016], [64729.6, 0.008], [64730.3, 0.015], [64732.4, 0.765], [64733.3, 1.099], [64736.8, 2.328], [64737.6, 1.265], [64744.4, 0.396], [64745.0, 0.0], [64830.1, 3.99], [64847.1, 5.933], [64878.1, 0.078], [64883.3, 0.002], [64885.9, 1.652], [65336.9, 0.001], [65981.7, 0.009], [65983.7, 0.009]]}
{"kind": "depth", "E": 1787095346571, "U": 11316372670735, "u": 11316372688660, "recv_ms": 1787095346628, "bids": [[14189.9, 3.668], [14287.9, 0.224], [14589.9, 0.308], [58220.9, 0.002], [61455.4, 0.002], [62102.3, 0.144], [63394.9, 0.0], [63525.3, 1.248], [63582.8, 0.007], [63689.9, 0.03], [63768.4, 0.941], [63783.8, 0.0], [63816.6, 1.096], [64043.0, 0.033], [64418.9, 0.495], [64492.8, 6.672], [64547.3, 0.015], [64620.7, 0.028], [64622.6, 0.397], [64625.1, 44.338], [64627.3, 0.001], [64629.6, 1.173], [64642.5, 0.018], [64654.5, 0.005], [64655.0, 0.003], [64655.1, 1.0], [64655.2, 2.483], [64655.3, 1.415], [64657.0, 0.005], [64657.1, 0.021], [64657.2, 0.064], [64657.3, 0.011], [64658.4, 2.141], [64658.5, 0.187], [64658.6, 1.521], [64658.7, 0.1], [64660.5, 1.242], [64660.6, 0.028], [64660.7, 0.101], [64664.2, 0.17], [64666.2, 0.0], [64672.4, 0.1], [64673.7, 0.332], [64676.7, 0.165], [64677.4, 0.151], [64679.7, 0.271], [64681.3, 0.046], [64681.9, 0.665], [64682.2, 0.003], [64682.3, 0.032], [64683.3, 0.151], [64683.5, 0.063], [64684.1, 2.254], [64684.2, 1.191], [64684.3, 0.034], [64685.8, 0.086], [64685.9, 0.004], [64686.3, 0.084], [64686.4, 0.235], [64686.8, 0.089], [64687.0, 0.002], [64689.9, 7.965]], "asks": [[64690.9, 0.09], [64691.5, 0.38], [64692.5, 0.479], [64692.7, 0.178], [64692.9, 0.122], [64693.0, 0.617], [64693.1, 0.459], [64693.2, 0.798], [64693.6, 0.168], [64693.9, 0.086], [64694.0, 0.001], [64694.1, 0.245], [64694.4, 0.044], [64694.5, 0.387], [64694.6, 0.711], [64698.8, 0.046], [64698.9, 0.056], [64699.1, 0.457], [64700.8, 2.329], [64701.0, 1.478], [64702.9, 2.215], [64703.0, 1.635], [64706.8, 0.169], [64707.4, 0.093], [64709.2, 0.784], [64712.4, 0.546], [64712.5, 0.078], [64716.9, 0.156], [64763.0, 1.57], [64784.0, 1.994], [64784.1, 3.861], [64836.5, 3.07], [64847.1, 10.41], [64885.9, 9.508], [64890.3, 4.552], [64960.2, 4.823], [65336.9, 0.001], [65690.0, 0.433], [65768.7, 0.911]]}
{"kind": "depth", "E": 1787095346673, "U": 11316372689089, "u": 11316372701086, "recv_ms": 1787095346731, "bids": [[14189.9, 3.542], [14287.9, 0.112], [14589.9, 0.546], [58220.9, 0.002], [61455.4, 0.004], [62102.3, 0.147], [63689.9, 0.01], [63719.2, 2.331], [63751.9, 1.087], [63845.1, 1.102], [63880.8, 13.745], [63913.1, 0.0], [63913.6, 6.196], [63946.0, 6.196], [64043.0, 0.033], [64366.4, 0.012], [64366.5, 0.01], [64625.1, 6.267], [64627.3, 38.072], [64657.3, 0.001], [64657.4, 0.073], [64671.3, 0.117], [64671.7, 1.141], [64673.8, 0.558], [64674.1, 0.003], [64676.0, 1.199], [64682.2, 0.003], [64685.0, 0.385], [64685.7, 0.004], [64688.8, 0.003], [64689.8, 0.041], [64689.9, 7.967]], "asks": [[64690.0, 9.506], [64691.4, 0.043], [64691.5, 0.38], [64691.7, 0.038], [64691.8, 0.82], [64692.4, 0.061], [64692.5, 0.009], [64692.6, 0.273], [64693.1, 0.459], [64693.2, 0.881], [64693.3, 0.607], [64693.6, 0.17], [64693.8, 0.166], [64693.9, 0.003], [64694.0, 0.231], [64694.1, 0.123], [64694.5, 0.155], [64699.4, 0.686], [64701.1, 0.324], [64707.4, 0.013], [64714.2, 0.747], [64715.5, 0.01], [64715.7, 0.357], [64716.3, 0.002], [64716.7, 0.058], [64717.5, 0.001], [64719.7, 1.474], [64744.6, 0.093], [64744.7, 0.015], [64830.1, 4.02], [64847.1, 10.41], [64885.9, 8.983], [65336.9, 0.001], [65484.8, 1.753], [65510.4, 1.677], [65690.0, 0.413]]}
{"kind": "depth", "E": 1787095346775, "U": 11316372701435, "u": 11316372712057, "recv_ms": 1787095346831, "bids": [[1000.0, 35.76], [14189.9, 3.402], [14287.9, 0.0], [14589.9, 0.798], [58220.9, 0.002], [61455.4, 0.004], [62102.3, 0.144], [63705.8, 0.785], [63783.3, 2.349], [63880.8, 10.645], [63913.6, 9.294], [63933.0, 1.2], [64043.0, 0.033], [64090.9, 0.265], [64091.3, 1.091], [64545.4, 0.022], [64664.2, 0.17], [64676.5, 1.409], [64677.4, 0.461], [64679.7, 0.426], [64682.2, 0.003], [64682.3, 0.187], [64685.2, 0.158], [64689.9, 7.968]], "asks": [[64691.4, 0.035], [64691.5, 0.155], [64692.5, 0.017], [64693.1, 0.469], [64693.2, 0.651], [64693.8, 0.086], [64694.0, 0.001], [64694.1, 0.008], [64694.4, 0.044], [64694.5, 0.0], [64697.2, 0.005], [64699.1, 0.147], [64699.6, 0.14], [64703.0, 2.535], [64704.0, 1.433], [64706.8, 0.014], [64709.2, 0.629], [64716.9, 0.001], [64830.1, 0.0], [65013.5, 0.002], [65336.9, 0.001], [65789.7, 0.606]]}
{"kind": "depth", "E": 1787095346877, "U": 11316372712156, "u": 11316372726649, "recv_ms": 1787095346934, "bids": [[14189.9, 3.052], [14589.9, 1.148], [58220.9, 0.002], [61442.4, 0.001], [61455.4, 0.004], [63603.1, 0.632], [63689.9, 0.03], [63880.8, 7.545], [63913.6, 12.392], [64043.0, 0.033], [64102.6, 0.247], [64350.1, 1.319], [64528.7, 6.787], [64545.7, 3.395], [64627.3, 0.001], [64629.5, 38.106], [64629.6, 1.173], [64664.2, 0.015], [64670.5, 0.117], [64671.3, 0.001], [64673.1, 0.557], [64673.8, 0.001], [64676.7, 0.624], [64677.4, 0.151], [64677.8, 0.442], [64679.7, 0.271], [64682.2, 0.003], [64682.3, 0.125], [64685.2, 0.003], [64689.9, 7.965]], "asks": [[64691.4, 0.043], [64691.5, 0.155], [64692.4, 0.051], [64692.5, 0.009], [64693.1, 0.459], [64693.2, 0.651], [64693.6, 0.168], [64694.1, 0.008], [64694.3, 0.002], [64694.4, 0.199], [64694.5, 0.0], [64697.4, 0.128], [64699.1, 0.457], [64701.2, 1.51], [64702.1, 0.625], [64706.2, 0.045], [64706.8, 0.169], [64708.7, 0.041], [64709.2, 0.784], [64710.1, 0.462], [64710.9, 0.007], [64713.3, 0.018], [64714.2, 1.303], [64714.4, 0.172], [64716.9, 0.156], [64733.3, 1.099], [64830.1, 5.399], [64847.1, 10.41], [65336.9, 0.001], [65690.0, 0.433], [65981.7, 0.006]]}
{"kind": "depth", "E": 1787095346979, "U": 11316372726838, "u": 11316372739038, "recv_ms": 1787095347038, "bids": [[14189.9, 2.688], [14589.9, 1.512], [58220.9, 0.002], [62102.3, 0.147], [63396.2, 0.02], [63671.6, 0.011], [64043.0, 0.035], [64342.6, 0.013], [64345.2, 0.492], [64366.5, 0.0], [64391.1, 0.002], [64664.2, 0.015], [64666.1, 0.421], [64676.5, 1.408], [64677.4, 0.151], [64679.7, 0.271], [64679.8, 0.023], [64680.6, 0.017], [64681.5, 0.049], [64682.2, 0.003], [64682.3, 0.125], [64682.4, 0.0], [64685.2, 0.003], [64689.9, 7.958]], "asks": [[64691.4, 0.043], [64691.5, 0.232], [64692.5, 0.009], [64694.1, 0.008], [64694.4, 0.199], [64694.5, 0.0], [64697.2, 0.004], [64697.4, 0.143], [64698.8, 0.004], [64699.1, 0.415], [64699.6, 0.06], [64700.3, 0.082], [64706.2, 0.055], [64706.8, 0.169], [64709.2, 0.784], [64714.5, 1.239], [64716.9, 0.156], [64721.1, 0.374], [64744.7, 0.005], [64744.8, 0.195], [65336.9, 0.001]]}
{"kind": "depth", "E": 1787095347081, "U": 11316372739049, "u": 11316372750615, "recv_ms": 1787095347139, "bids": [[1000.0, 35.76], [14189.9, 2.338], [14589.9, 1.862], [58220.9, 0.002], [61453.6, 0.0], [61455.4, 0.004], [62102.3, 0.144], [63396.1, 0.158], [63689.9, 0.01], [63704.5, 0.012], [63769.1, 0.0], [63770.5, 0.0], [64043.0, 0.033], [64103.2, 1.09], [64536.2, 0.002], [64549.1, 0.001], [64656.9, 0.73], [64664.2, 0.015], [64670.8, 0.738], [64677.4, 0.151], [64678.1, 0.69], [64678.3, 0.242], [64679.7, 0.271], [64682.2, 0.003], [64685.2, 0.003], [64688.4, 0.003], [64689.9, 7.964]], "asks": [[64690.0, 9.51], [64691.3, 0.01], [64691.4, 0.26], [64691.5, 0.347], [64692.5, 0.019], [64693.1, 0.574], [64694.4, 0.199], [64699.1, 0.415], [64701.7, 0.619], [64706.8, 0.169], [64709.0, 0.664], [64709.2, 0.784], [64714.2, 0.747], [64715.0, 0.629], [64716.9, 0.156], [65013.5, 0.001], [65336.9, 0.001], [65605.3, 0.761], [65606.6, 2.72], [65671.3, 0.009], [65690.0, 0.413]]}
{"kind": "depth", "E": 1787095347183, "U": 11316372750721, "u": 11316372764024, "recv_ms": 1787095347242, "bids": [[14189.9, 1.974], [14589.9, 2.226], [51751.9, 0.0], [58220.9, 0.002], [61455.4, 0.005], [62102.3, 0.147], [63706.1, 0.762], [63770.9, 0.008], [63772.1, 0.008], [64043.0, 0.033], [64365.5, 0.621], [64366.4, 0.013], [64547.3, 0.016], [64645.7, 0.1], [64653.7, 0.42], [64657.4, 0.063], [64657.5, 0.014], [64664.2, 0.015], [64670.8, 0.12], [64673.5, 2.424], [64674.6, 0.005], [64676.5, 1.288], [64677.4, 0.151], [64678.1, 0.072], [64679.7, 0.271], [64681.6, 0.128], [64682.2, 0.004], [64682.3, 0.117], [64682.4, 0.0], [64682.7, 0.085], [64683.0, 0.087], [64683.8, 0.088], [64684.1, 1.713], [64684.3, 0.002], [64684.8, 0.01], [64685.2, 0.003], [64685.8, 0.002], [64686.1, 0.003], [64686.3, 0.0], [64686.5, 0.005], [64686.8, 0.005], [64687.2, 0.005], [64688.0, 0.229], [64689.7, 0.002], [64689.8, 0.04], [64689.9, 6.953]], "asks": [[64690.0, 10.208], [64691.3, 0.002], [64691.4, 0.26], [64691.5, 0.078], [64692.5, 0.027], [64692.8, 0.231], [64692.9, 0.129], [64693.1, 0.459], [64693.2, 0.661], [64694.4, 0.044], [64694.5, 0.634], [64694.6, 0.318], [64696.6, 0.017], [64698.5, 0.322], [64699.0, 0.099], [64699.1, 0.322], [64699.7, 0.022], [64699.8, 0.027], [64701.7, 0.001], [64705.6, 0.023], [64706.0, 0.389], [64706.7, 0.003], [64706.8, 0.787], [64707.4, 4.013], [64708.7, 0.196], [64709.2, 0.011], [64711.8, 0.414], [64712.1, 0.298], [64712.4, 0.606], [64716.9, 0.156], [64719.6, 0.001], [64744.4, 0.387], [64805.6, 0.1], [65336.9, 0.001], [65671.7, 6.568]]}
{"kind": "depth", "E": 1787095347285, "U": 11316372764100, "u": 11316372792750, "recv_ms": 1787095347348, "bids": [[14189.9, 1.61], [14589.9, 2.59], [58220.9, 0.002], [61455.4, 0.006], [63687.2, 0.706], [63816.6, 1.487], [63880.8, 4.445], [63897.4, 55.857], [63913.6, 15.959], [64043.0, 0.033], [64366.5, 0.01], [64590.9, 0.0], [64592.7, 3.901], [64592.8, 0.008], [64608.8, 0.027], [64610.2, 0.013], [64612.1, 3.874], [64620.7, 0.028], [64621.7, 0.0], [64622.9, 0.027], [64625.1, 43.719], [64626.4, 0.005], [64629.5, 0.037], [64629.8, 1.667], [64630.0, 0.014], [64631.5, 6.194], [64636.5, 0.073], [64638.8, 0.001], [64641.2, 0.016], [64643.1, 0.0], [64646.2, 0.444], [64648.5, 0.0], [64650.4, 0.097], [64650.8, 0.16], [64650.9, 3.872], [64651.0, 0.015], [64652.6, 2.347], [64652.9, 0.001], [64653.4, 0.038], [64655.1, 1.04], [64655.6, 0.07], [64656.7, 8.026], [64658.4, 0.141], [64658.6, 0.41], [64659.1, 0.108], [64659.5, 0.059], [64659.6, 0.215], [64660.2, 0.131], [64661.0, 0.0], [64662.1, 0.003], [64663.0, 0.002], [64664.6, 0.011], [64665.6, 0.012], [64666.3, 0.0], [64666.8, 0.016], [64666.9, 0.38], [64667.0, 0.359], [64667.3, 0.001], [64668.3, 0.038], [64669.0, 0.902], [64669.4, 0.026], [64670.1, 0.0], [64670.2, 0.312], [64671.4, 0.001], [64672.1, 0.033], [64672.4, 0.02], [64672.6, 0.0], [64672.7, 0.02], [64673.6, 1.257], [64673.9, 2.399], [64674.0, 1.11], [64674.5, 0.007], [64674.8, 1.046], [64675.3, 0.002], [64676.1, 0.476], [64676.5, 1.088], [64677.1, 0.073], [64677.4, 0.154], [64678.1, 0.079], [64678.5, 0.583], [64679.2, 0.309], [64679.4, 0.037], [64679.5, 0.002], [64679.6, 1.555], [64679.8, 0.023], [64680.2, 0.238], [64680.3, 0.002], [64680.8, 0.0], [64681.1, 0.017], [64681.2, 1.496], [64681.3, 0.043], [64681.4, 0.015], [64681.6, 0.128], [64681.8, 0.003], [64681.9, 0.819], [64682.0, 0.01], [64682.2, 0.214], [64682.3, 0.124], [64682.5, 0.016], [64682.9, 0.31], [64683.1, 0.628], [64683.2, 0.542], [64683.4, 0.089], [64683.5, 0.001], [64683.8, 0.004], [64683.9, 0.397], [64684.0, 0.003], [64684.1, 0.007], [64684.2, 1.192], [64684.3, 1.749], [64684.4, 0.009], [64684.5, 0.012], [64684.7, 0.0], [64684.8, 0.242], [64684.9, 0.429], [64685.0, 0.168], [64685.1, 2.153], [64685.2, 2.882], [64685.4, 0.087], [64685.5, 0.001], [64685.9, 0.086], [64686.1, 0.0], [64686.3, 0.084], [64686.4, 0.003], [64686.5, 0.002], [64687.2, 0.004], [64687.3, 0.0], [64687.5, 0.0], [64687.7, 0.0], [64688.0, 0.526], [64688.9, 0.002], [64689.0, 0.001], [64689.8, 0.038], [64689.9, 5.724]], "asks": [[64690.0, 11.214], [64690.1, 0.018], [64690.8, 0.003], [64691.1, 0.039], [64691.2, 0.003], [64691.3, 0.002], [64691.4, 0.26], [64691.5, 0.078], [64692.0, 0.084], [64692.4, 0.044], [64692.5, 0.011], [64692.9, 0.205], [64693.0, 0.676], [64693.1, 0.574], [64693.2, 0.567], [64693.3, 0.609], [64693.5, 0.087], [64694.3, 0.0], [64694.4, 0.067], [64694.6, 0.163], [64694.7, 1.525], [64696.5, 0.002], [64696.6, 0.018], [64699.1, 0.012], [64699.9, 0.778], [64700.0, 3.841], [64700.8, 2.328], [64701.1, 0.787], [64702.4, 0.084], [64702.8, 0.007], [64703.4, 2.782], [64704.3, 2.287], [64705.6, 0.003], [64706.0, 0.438], [64706.3, 0.054], [64706.7, 0.003], [64706.8, 0.632], [64708.7, 0.041], [64708.8, 1.832], [64709.0, 0.046], [64709.3, 2.789], [64709.4, 1.285], [64710.1, 0.003], [64710.7, 0.033], [64711.1, 3.259], [64711.4, 1.978], [64711.8, 0.416], [64712.7, 0.034], [64714.2, 0.284], [64714.3, 0.015], [64715.6, 2.416], [64716.7, 0.008], [64716.9, 0.001], [64722.8, 0.005], [64725.8, 0.398], [64740.6, 0.01], [64740.7, 0.073], [64742.4, 0.012], [64744.4, 0.405], [64745.2, 0.002], [64747.0, 0.018], [64750.8, 0.026], [64752.2, 0.378], [64753.1, 0.005], [64763.0, 1.084], [64763.7, 0.003], [64764.6, 0.0], [64766.1, 0.0], [64767.9, 46.319], [64768.4, 1.163], [64770.1, 0.006], [64784.0, 0.0], [64784.1, 0.0], [64830.1, 4.039], [64847.1, 10.41], [64885.9, 9.349], [65336.9, 0.001], [65607.8, 0.074], [65609.1, 0.009], [65673.8, 0.018]]}
{"kind": "depth", "E": 1787095347387, "U": 11316372792881, "u": 11316372816077, "recv_ms": 1787095347444, "bids": [[1000.0, 35.76], [14189.9, 1.26], [14589.9, 2.94], [58220.9, 0.002], [60535.2, 0.004], [61455.4, 0.006], [62102.3, 0.144], [63396.2, 0.023], [63689.9, 0.03], [64043.0, 0.032], [64156.1, 1.866], [64608.6, 0.039], [64608.8, 0.001], [64609.9, 0.002], [64618.5, 0.001], [64622.9, 37.479], [64625.1, 6.267], [64625.7, 1.719], [64626.4, 0.0], [64629.9, 0.02], [64651.9, 0.133], [64653.6, 0.045], [64655.3, 1.415], [64655.5, 8.053], [64656.7, 0.028], [64658.3, 0.072], [64660.5, 1.335], [64660.7, 0.008], [64663.0, 0.07], [64666.0, 0.437], [64671.6, 0.094], [64674.7, 0.001], [64676.0, 1.658], [64676.7, 0.165], [64677.1, 0.166], [64678.3, 0.021], [64678.5, 0.583], [64678.9, 1.09], [64679.5, 1.002], [64679.6, 0.555], [64679.8, 0.023], [64680.2, 0.415], [64680.5, 0.218], [64681.3, 0.003], [64681.6, 0.129], [64681.9, 0.903], [64682.0, 0.01], [64682.2, 0.23], [64682.3, 0.108], [64683.3, 0.151], [64683.9, 0.087], [64684.1, 0.007], [64684.2, 0.884], [64684.3, 0.086], [64684.4, 0.001], [64684.7, 0.084], [64684.8, 0.243], [64684.9, 0.345], [64685.1, 2.091], [64685.2, 2.526], [64685.3, 0.879], [64685.4, 0.081], [64685.6, 0.102], [64685.9, 0.002], [64686.3, 0.0], [64688.0, 0.004], [64689.9, 4.889]], "asks": [[64690.0, 11.902], [64690.7, 0.001], [64691.3, 0.002], [64691.4, 0.035], [64691.5, 0.457], [64692.5, 0.011], [64692.7, 0.261], [64692.9, 0.122], [64693.0, 0.676], [64693.1, 0.459], [64693.2, 0.682], [64694.4, 0.067], [64694.7, 1.432], [64703.7, 0.16], [64704.1, 0.005], [64705.6, 0.023], [64706.0, 0.389], [64707.4, 0.013], [64707.5, 10.12], [64708.2, 0.06], [64710.2, 0.222], [64710.8, 0.542], [64711.4, 1.978], [64712.4, 0.546], [64712.6, 0.574], [64712.7, 0.134], [64715.4, 0.072], [64715.6, 2.391], [64719.2, 0.592], [64720.3, 0.011], [64722.1, 1.304], [64726.9, 0.065], [64733.5, 1.711], [64734.9, 0.003], [64740.0, 2.475], [64740.6, 0.005], [64747.0, 0.0], [64749.5, 0.043], [64750.8, 0.0], [64805.6, 0.0], [65336.9, 0.001], [65690.0, 0.433], [65692.7, 1.671], [65983.7, 0.012]]}
{"kind": "depth", "E": 1787095347489, "U": 11316372816432, "u": 11316372830703, "recv_ms": 1787095347548, "bids": [[14189.9, 0.896], [14589.9, 3.304], [58220.9, 0.002], [61455.4, 0.006], [62102.3, 0.147], [64043.0, 0.032], [64547.3, 0.015], [64591.2, 0.024], [64622.6, 0.395], [64625.7, 1.687], [64626.0, 0.001], [64626.3, 0.006], [64626.6, 0.033], [64627.0, 0.163], [64643.2, 0.005], [64643.6, 0.002], [64643.9, 0.385], [64644.2, 0.018], [64644.5, 0.003], [64654.4, 1.293], [64655.5, 8.055], [64658.2, 0.009], [64658.3, 0.002], [64658.4, 0.001], [64658.5, 0.017], [64658.6, 0.31], [64658.7, 0.0], [64658.8, 0.003], [64658.9, 0.504], [64659.0, 0.097], [64659.1, 0.038], [64660.0, 0.105], [64660.4, 4.902], [64664.1, 1.463], [64664.5, 0.003], [64672.5, 0.038], [64674.0, 1.102], [64677.1, 0.096], [64677.2, 0.0], [64677.3, 1.989], [64677.4, 0.014], [64677.5, 0.384], [64677.6, 0.003], [64677.7, 0.348], [64677.8, 0.272], [64677.9, 0.0], [64678.0, 0.009], [64678.1, 0.009], [64678.4, 0.03], [64678.7, 0.015], [64678.8, 0.102], [64679.0, 0.487], [64679.4, 0.005], [64679.7, 0.239], [64682.0, 0.009], [64682.2, 0.23], [64682.3, 0.108], [64683.0, 0.088], [64683.2, 0.542], [64683.3, 0.151], [64684.6, 0.004], [64684.8, 0.011], [64685.1, 2.089], [64685.2, 2.758], [64685.4, 1.601], [64685.5, 0.155], [64685.6, 0.018], [64688.0, 0.004], [64689.9, 5.673]], "asks": [[64690.0, 11.265], [64691.1, 0.007], [64691.4, 0.0], [64691.5, 0.078], [64691.7, 0.0], [64691.8, 0.543], [64692.1, 0.006], [64692.4, 0.002], [64692.5, 0.011], [64692.7, 0.087], [64692.8, 0.02], [64692.9, 0.002], [64693.0, 0.486], [64693.1, 0.412], [64693.2, 0.317], [64693.3, 0.389], [64693.4, 0.004], [64693.5, 0.017], [64693.6, 0.0], [64694.0, 0.121], [64694.2, 0.365], [64694.4, 0.067], [64700.0, 4.741], [64703.0, 1.635], [64705.6, 0.003], [64707.5, 10.122], [64708.7, 0.009], [64708.8, 1.83], [64709.0, 0.011], [64709.3, 2.751], [64709.6, 0.001], [64710.0, 0.136], [64710.3, 0.001], [64710.8, 0.402], [64711.6, 0.002], [64711.8, 0.325], [64711.9, 0.045], [64712.0, 1.393], [64712.1, 0.068], [64712.2, 0.118], [64712.3, 0.493], [64712.4, 0.392], [64712.5, 0.008], [64712.6, 0.406], [64713.3, 0.138], [64713.5, 0.122], [64726.2, 0.002], [64726.6, 1.169], [64726.9, 0.027], [64727.2, 0.009], [64727.5, 0.001], [64747.0, 0.009], [65336.9, 0.001], [65478.1, 0.763]]}
{"kind": "depth", "E": 1787095347591, "U": 11316372830843, "u": 11316372841448, "recv_ms": 1787095347648, "bids": [[1000.0, 35.91], [14189.9, 0.546], [14589.9, 3.654], [51750.0, 0.064], [58220.9, 0.002], [62102.3, 0.144], [63689.9, 0.01], [63897.7, 3.171], [64043.0, 0.032], [64366.5, 0.01], [64622.9, 0.027], [64623.0, 0.033], [64625.1, 43.719], [64655.3, 0.164], [64655.6, 2.556], [64659.6, 0.165], [64666.8, 0.066], [64670.1, 0.116], [64670.5, 0.001], [64678.4, 0.1], [64678.7, 0.215], [64679.1, 0.171], [64679.2, 0.409], [64679.7, 0.247], [64682.2, 0.222], [64687.2, 0.002], [64688.4, 0.001]], "asks": [[64691.4, 0.0], [64691.5, 0.001], [64692.2, 0.088], [64692.9, 0.551], [64693.2, 0.547], [64693.3, 0.387], [64693.7, 0.001], [64693.8, 0.206], [64693.9, 0.094], [64694.1, 0.008], [64694.3, 0.29], [64694.4, 0.059], [64694.5, 0.095], [64694.6, 0.254], [64698.3, 0.309], [64699.4, 0.377], [64701.5, 0.02], [64707.4, 2.974], [64707.6, 0.253], [64708.5, 0.015], [64711.6, 0.122], [64712.0, 1.533], [64712.9, 0.226], [64713.2, 0.325], [64713.6, 0.855], [64713.9, 2.623], [64714.2, 0.169], [64744.8, 0.185], [64744.9, 0.036], [64747.0, 0.0], [64765.6, 7.786], [64784.5, 1.413], [64844.9, 2.898], [65191.0, 0.612], [65336.9, 0.001], [65498.6, 1.141], [65690.0, 0.413], [65801.5, 0.76]]}
{"kind": "depth", "E": 1787095347693, "U": 11316372841523, "u": 11316372850049, "recv_ms": 1787095347749, "bids": [[1000.0, 35.76], [14189.9, 0.322], [14489.9, 0.126], [14589.9, 3.752], [58220.9, 0.002], [62102.3, 0.147], [63816.6, 2.113], [64043.0, 0.032], [64172.4, 0.966], [64506.3, 0.003], [64644.1, 0.152], [64644.4, 0.343], [64644.7, 0.093], [64645.4, 0.104], [64670.0, 0.696], [64672.6, 0.557], [64672.7, 0.0], [64673.1, 0.0], [64677.5, 0.424], [64678.5, 0.653], [64679.0, 0.587], [64679.5, 1.034], [64679.9, 0.034], [64680.2, 0.447], [64680.8, 0.032], [64680.9, 0.034], [64682.2, 0.763], [64682.3, 0.201], [64684.1, 0.0], [64685.1, 0.0], [64685.2, 2.526], [64685.3, 0.009], [64685.4, 1.604], [64685.6, 1.563], [64685.7, 1.303]], "asks": [[64691.4, 0.016], [64691.5, 0.303], [64691.8, 1.078], [64692.2, 0.12], [64692.5, 0.011], [64692.8, 0.599], [64692.9, 0.085], [64693.0, 0.716], [64693.1, 0.601], [64693.2, 0.317], [64693.4, 0.046], [64693.6, 0.0], [64693.7, 0.001], [64694.0, 0.241], [64694.1, 0.008], [64694.2, 0.367], [64694.4, 0.051], [64694.5, 0.177], [64698.1, 0.227], [64698.2, 2.536], [64698.9, 0.048], [64703.6, 0.16], [64709.9, 0.033], [64710.5, 0.039], [64710.6, 0.034], [64710.8, 0.444], [64711.2, 0.493], [64712.9, 0.782], [64713.3, 0.258], [64713.7, 0.085], [64715.0, 0.073], [64727.6, 0.033], [64728.3, 0.252], [64728.6, 0.047], [64728.9, 0.044], [65336.9, 0.001], [65510.4, 2.439]]}
{"kind": "depth", "E": 1787095347795, "U": 11316372850355, "u": 11316372858033, "recv_ms": 1787095347852, "bids": [[14189.9, 0.196], [14489.9, 0.364], [14589.9, 3.64], [58220.9, 0.002], [61455.4, 0.008], [63590.2, 0.944], [63689.9, 0.03], [64043.0, 0.032], [64366.4, 0.014], [64489.8, 0.011], [64528.7, 0.001], [64531.2, 1.926], [64545.7, 0.0], [64618.5, 37.453], [64625.1, 6.267], [64645.1, 0.039], [64678.8, 0.202], [64678.9, 1.16], [64680.5, 0.25], [64682.2, 0.222], [64683.0, 0.087], [64683.8, 0.005], [64685.3, 0.55], [64685.6, 1.565], [64685.8, 0.004], [64689.9, 5.689]], "asks": [[64690.0, 11.235], [64690.1, 0.011], [64690.8, 0.01], [64691.4, 0.225], [64691.5, 0.232], [64691.8, 0.766], [64692.5, 0.046], [64692.8, 0.058], [64692.9, 0.093], [64693.0, 0.486], [64693.1, 0.371], [64693.2, 0.432], [64693.4, 0.043], [64693.7, 0.231], [64693.9, 0.171], [64694.1, 0.619], [64694.2, 0.497], [64694.5, 0.108], [64701.0, 1.464], [64704.2, 1.0], [64706.2, 0.141], [64709.4, 1.214], [64710.2, 0.257], [64713.4, 0.462], [64715.4, 0.002], [64722.0, 1.617], [64727.9, 0.714], [64830.1, 0.0], [64844.9, 1.542], [64847.1, 0.001], [64873.4, 0.0], [64873.5, 0.004], [64885.9, 0.001], [65013.5, 0.0], [65336.9, 0.001], [65542.8, 0.768], [65690.0, 0.433]]}
{"kind": "depth", "E": 1787095347897, "U": 11316372858134, "u": 11316372869613, "recv_ms": 1787095347957, "bids": [[1000.0, 35.76], [14189.9, 0.084], [14489.9, 0.602], [14589.9, 3.514], [58220.9, 0.002], [62102.3, 0.144], [63913.6, 17.522], [64043.0, 0.032], [64366.5, 0.01], [64397.6, 0.0], [64618.5, 36.31], [64625.1, 6.267], [64659.5, 0.159], [64659.7, 0.107], [64678.3, 0.091], [64678.4, 0.17], [64678.5, 0.723], [64678.6, 0.301], [64679.3, 2.432], [64681.9, 0.819], [64684.3, 0.091], [64685.5, 0.093], [64685.7, 1.365], [64686.1, 0.084], [64687.0, 0.021], [64689.9, 5.69]], "asks": [[64691.4, 0.0], [64691.5, 0.226], [64693.6, 0.0], [64693.7, 0.322], [64693.9, 0.524], [64694.4, 0.121], [64694.5, 0.17], [64694.6, 0.324], [64694.7, 1.509], [64699.7, 0.002], [64713.0, 0.105], [64713.7, 0.155], [64713.8, 0.079], [64713.9, 2.693], [64714.0, 0.113], [64798.7, 0.005], [64798.8, 11.701], [65207.5, 1.224], [65336.9, 0.001], [65455.1, 22.456], [65595.7, 5.026]]}
{"kind": "depth", "E": 1787095347999, "U": 11316372870148, "u": 11316372880662, "recv_ms": 1787095348056, "bids": [[1000.0, 35.76], [14189.9, 0.0], [14489.9, 0.882], [14589.9, 3.318], [58220.9, 0.002], [61455.4, 0.008], [62102.3, 0.147], [63689.9, 0.01], [64043.0, 0.032], [64345.2, 0.0], [64346.8, 0.492], [64490.1, 12.496], [64528.9, 7.013], [64531.2, 2.723], [64545.9, 3.3], [64618.5, 0.001], [64622.9, 36.336], [64626.4, 0.032], [64626.7, 0.66], [64627.0, 0.195], [64627.6, 0.032], [64659.1, 0.108], [64659.2, 0.082], [64659.4, 0.103], [64659.8, 0.077], [64661.0, 0.1], [64661.4, 0.1], [64685.7, 1.133], [64686.5, 0.234], [64686.9, 0.003], [64689.9, 5.694]], "asks": [[64691.5, 0.001], [64693.1, 0.371], [64693.2, 0.317], [64693.7, 0.092], [64693.9, 0.179], [64699.1, 0.015], [64703.1, 0.005], [64830.1, 5.399], [64847.1, 10.41], [64885.9, 8.838], [65336.9, 0.001], [65690.0, 0.413]]}
{"kind": "depth", "E": 1787095348101, "U": 11316372880751, "u": 11316372891509, "recv_ms": 1787095348158, "bids": [[14489.9, 1.246], [14589.9, 2.954], [58220.9, 0.002], [62102.3, 0.144], [63394.2, 0.006], [63692.1, 0.0], [63964.6, 1.957], [64043.0, 0.032], [64090.9, 0.031], [64627.3, 0.033], [64629.6, 1.173], [64653.6, 0.003], [64657.5, 0.004], [64657.6, 1.3], [64659.7, 0.207], [64678.3, 0.091], [64678.9, 1.035], [64680.9, 0.159], [64682.2, 0.206], [64682.3, 0.117], [64683.3, 0.151], [64683.4, 0.105], [64685.9, 0.004], [64686.5, 0.318]], "asks": [[64691.5, 0.155], [64692.8, 0.599], [64692.9, 0.093], [64693.7, 0.317], [64694.1, 0.078], [64715.9, 0.767], [64728.8, 0.004], [64733.3, 1.099], [65336.9, 0.001], [65677.8, 0.0]]}
{"kind": "depth", "E": 1787095348203, "U": 11316372891640, "u": 11316372899353, "recv_ms": 1787095348262, "bids": [[1000.0, 35.76], [14489.9, 1.596], [14589.9, 2.604], [51751.9, 0.0], [58220.9, 0.002], [61455.4, 0.008], [62102.3, 0.147], [63576.3, 0.003], [63689.9, 0.03], [63696.8, 0.401], [63736.0, 0.871], [64043.0, 0.032], [64366.4, 0.013], [64366.5, 0.0], [64641.2, 0.002], [64651.3, 0.016], [64659.2, 0.152], [64659.6, 0.335], [64660.4, 4.904], [64660.7, 0.006], [64668.3, 0.001], [64670.7, 0.62], [64673.5, 2.424], [64675.3, 0.039], [64678.1, 0.627], [64682.2, 0.222], [64683.3, 0.583], [64683.4, 0.089], [64684.8, 0.015], [64685.7, 1.137], [64686.9, 0.006], [64687.1, 0.002], [64687.9, 0.009], [64689.9, 5.695]], "asks": [[64690.1, 0.012], [64691.4, 0.002], [64691.5, 0.001], [64691.6, 0.117], [64691.7, 0.225], [64691.8, 0.769], [64692.5, 0.053], [64692.7, 0.087], [64692.8, 0.058], [64692.9, 0.638], [64693.2, 0.432], [64693.7, 0.322], [64693.9, 0.524], [64694.1, 0.078], [64694.4, 0.114], [64694.9, 0.003], [64695.6, 0.0], [64698.5, 0.323], [64701.6, 0.618], [64706.0, 0.389], [64709.0, 0.629], [65336.9, 0.001], [65466.3, 2.298], [65690.0, 0.433]]}
{"kind": "depth", "E": 1787095348305, "U": 11316372899468, "u": 11316372907218, "recv_ms": 1787095348362, "bids": [[1000.0, 35.76], [14489.9, 1.946], [14589.9, 2.254], [51752.0, 0.0], [58220.9, 0.002], [61455.4, 0.008], [63396.2, 0.026], [63867.7, 3.478], [64043.0, 0.032], [64547.3, 0.015], [64579.9, 0.003], [64581.8, 0.033], [64581.9, 2.319], [64600.0, 1.842], [64654.5, 8.005], [64655.5, 0.055], [64659.0, 0.167], [64659.1, 0.178], [64659.3, 0.462], [64660.0, 0.175], [64670.7, 0.002], [64678.1, 0.009], [64682.2, 0.229], [64682.3, 0.658], [64683.1, 0.629], [64683.3, 0.583], [64683.8, 0.004], [64685.1, 0.003], [64685.3, 0.002], [64685.4, 1.601], [64686.1, 0.0], [64686.5, 0.234], [64688.7, 0.009], [64689.9, 5.054]], "asks": [[64691.5, 0.078], [64691.6, 0.136], [64691.7, 0.0], [64692.6, 0.276], [64692.7, 0.628], [64692.8, 0.058], [64692.9, 0.097], [64693.2, 0.317], [64693.7, 0.317], [64693.9, 0.179], [64694.1, 0.078], [64698.5, 0.322], [64699.8, 0.004], [64701.6, 0.0], [64707.5, 0.122], [64708.9, 10.001], [64709.0, 0.011], [64738.3, 0.002], [64767.7, 0.003], [64795.7, 2.319], [64867.7, 0.415], [65013.5, 0.001], [65336.9, 0.001], [65449.7, 32.976], [65683.2, 0.011]]}
{"kind": "depth", "E": 1787095348407, "U": 11316372907247, "u": 11316372914845, "recv_ms": 1787095348464, "bids": [[14489.9, 2.31], [14589.9, 1.89], [51752.0, 0.0], [58220.9, 0.002], [61455.4, 0.01], [62102.3, 0.144], [63689.9, 0.01], [63706.1, 0.371], [63751.9, 2.184], [64043.0, 0.032], [64102.9, 4.917], [64682.2, 0.136], [64682.3, 0.117], [64683.3, 0.583], [64683.4, 0.723], [64683.5, 0.001], [64686.0, 0.087], [64689.9, 5.053]], "asks": [[64690.0, 11.234], [64691.5, 0.001], [64692.5, 0.053], [64692.6, 0.276], [64692.7, 0.087], [64692.8, 0.283], [64692.9, 0.097], [64693.7, 0.092], [64693.9, 0.294], [64694.1, 0.619], [64696.7, 0.019], [64847.1, 6.239], [64885.9, 0.001], [64886.0, 1.64], [65336.9, 0.001], [65498.6, 1.483], [65690.0, 0.413], [65847.6, 0.004]]}
{"kind": "depth", "E": 1787095348509, "U": 11316372915013, "u": 11316372923504, "recv_ms": 1787095348567, "bids": [[1000.0, 35.76], [14489.9, 2.66], [14589.9, 1.54], [58220.9, 0.002], [61455.4, 0.01], [62102.3, 0.147], [63596.6, 0.663], [64043.0, 0.032], [64366.5, 0.01], [64622.9, 0.027], [64625.1, 42.576], [64682.2, 0.77], [64683.3, 0.583], [64683.4, 0.089], [64683.5, 0.001], [64683.6, 0.003], [64685.3, 0.002], [64685.7, 1.075], [64685.8, 0.066], [64686.0, 0.003], [64689.9, 4.899]], "asks": [[64690.0, 11.259], [64691.5, 0.001], [64692.5, 0.046], [64692.6, 0.276], [64692.7, 0.087], [64692.8, 0.058], [64692.9, 0.314], [64693.9, 0.179], [64694.1, 0.634], [64721.1, 0.318], [64728.9, 0.124], [64730.8, 0.284], [64737.3, 0.005], [64743.8, 6.303], [64750.2, 0.0], [64847.1, 10.41], [64886.0, 8.921], [65336.9, 0.001]]}
{"kind": "depth", "E": 1787095348611, "U": 11316372923663, "u": 11316372930659, "recv_ms": 1787095348670, "bids": [[1000.0, 35.76], [14489.9, 3.024], [14589.9, 1.176], [58220.9, 0.002], [62102.3, 0.144], [63576.7, 1.525], [63689.9, 0.03], [63719.6, 0.396], [63735.7, 15.985], [64043.0, 0.032], [64156.1, 0.622], [64350.1, 0.543], [64485.5, 0.6], [64524.7, 0.039], [64524.9, 0.007], [64595.0, 0.028], [64618.5, 36.31], [64625.1, 6.267], [64625.7, 1.687], [64656.2, 0.068], [64658.0, 0.753], [64676.0, 1.199], [64676.3, 1.474], [64677.2, 0.0], [64679.3, 2.4], [64681.2, 1.524], [64682.2, 0.222], [64682.3, 0.201], [64683.1, 0.628], [64683.2, 0.001], [64683.3, 0.692], [64683.4, 0.089], [64684.1, 0.001], [64684.3, 0.091], [64685.3, 0.55], [64685.5, 0.009], [64685.6, 0.02], [64685.8, 0.498], [64685.9, 1.549]], "asks": [[64690.0, 11.289], [64691.5, 0.309], [64691.8, 0.994], [64692.9, 0.089], [64693.7, 0.207], [64693.9, 0.409], [64694.0, 0.241], [64708.8, 1.371], [64709.7, 1.344], [64711.0, 2.797], [64712.9, 0.667], [64713.0, 0.22], [64713.8, 0.079], [64713.9, 2.693], [64781.6, 1.278], [64830.0, 2.454], [64830.3, 0.0], [64997.0, 0.2], [65336.9, 0.001], [65594.7, 0.159], [65690.0, 0.433]]}
{"kind": "depth", "E": 1787095348713, "U": 11316372930779, "u": 11316372940662, "recv_ms": 1787095348771, "bids": [[14489.9, 3.374], [14589.9, 0.826], [58220.9, 0.002], [61455.4, 0.01], [62102.3, 0.147], [63689.9, 0.01], [64043.0, 0.032], [64366.5, 0.0], [64618.5, 0.001], [64622.9, 0.027], [64625.1, 42.082], [64651.7, 8.001], [64653.6, 0.017], [64654.5, 0.005], [64655.6, 0.07], [64669.5, 0.116], [64670.1, 0.0], [64672.0, 1.47], [64672.6, 0.0], [64675.6, 0.46], [64676.3, 1.015], [64682.2, 0.763], [64683.2, 0.002], [64683.3, 0.151], [64684.1, 0.0], [64685.7, 0.79], [64685.8, 1.549], [64685.9, 0.066], [64689.9, 4.9]], "asks": [[64691.5, 0.534], [64691.6, 0.213], [64691.8, 0.769], [64692.9, 0.091], [64693.0, 0.716], [64693.2, 0.537], [64693.7, 0.552], [64693.8, 0.206], [64693.9, 0.639], [64708.1, 0.464], [64709.7, 0.885], [64710.7, 0.09], [64712.2, 0.674], [64712.3, 0.608], [64712.8, 2.823], [64712.9, 0.111], [64713.0, 0.105], [65255.7, 6.889], [65336.9, 0.001], [65619.9, 4.717], [65690.0, 0.413]]}
{"kind": "depth", "E": 1787095348815, "U": 11316372940910, "u": 11316372948919, "recv_ms": 1787095348872, "bids": [[1000.0, 35.76], [14389.9, 0.014], [14489.9, 3.71], [14589.9, 0.476], [51752.0, 0.0], [58220.9, 0.002], [63751.9, 3.281], [64043.0, 0.032], [64172.4, 2.21], [64366.4, 0.788], [64367.7, 0.518], [64524.7, 0.0], [64524.9, 0.046], [64668.5, 1.023], [64673.6, 1.24], [64682.2, 0.222], [64682.3, 0.201], [64682.8, 0.002], [64683.2, 0.542], [64685.3, 0.55], [64685.9, 0.066], [64686.6, 0.676]], "asks": [[64691.5, 0.001], [64691.6, 0.22], [64693.0, 0.486], [64693.2, 0.422], [64693.7, 0.092], [64693.9, 0.179], [64696.7, 0.041], [64708.1, 0.005], [64709.1, 0.459], [64710.7, 0.033], [64711.6, 0.179], [64712.2, 0.118], [64712.3, 0.493], [64713.1, 0.624], [64713.2, 0.44], [65013.5, 0.77], [65336.9, 0.001]]}
{"kind": "depth", "E": 1787095348917, "U": 11316372949291, "u": 11316372959881, "recv_ms": 1787095348974, "bids": [[1000.0, 35.76], [14389.9, 0.196], [14489.9, 3.71], [14589.9, 0.294], [58220.9, 0.002], [61455.4, 0.01], [62102.3, 0.144], [63590.2, 1.336], [63853.4, 2.395], [64043.0, 0.032], [64346.8, 0.0], [64347.8, 0.497], [64545.9, 0.0], [64546.2, 3.401], [64642.0, 0.03], [64651.3, 0.002], [64682.2, 0.129], [64682.3, 0.208], [64683.3, 0.151], [64683.4, 0.723], [64685.3, 0.002], [64685.7, 0.874], [64685.8, 1.549], [64685.9, 0.498], [64686.2, 0.087], [64686.6, 0.244], [64686.8, 0.006], [64689.9, 4.901]], "asks": [[64691.5, 0.226], [64692.6, 0.273], [64692.9, 0.107], [64693.2, 0.547], [64693.7, 0.322], [64693.9, 0.532], [64694.1, 0.626], [64694.5, 0.154], [64698.1, 0.227], [64731.5, 0.0], [64732.9, 0.026], [64740.8, 1.34], [64747.3, 1.546], [64830.0, 0.159], [64830.1, 0.0], [64830.2, 5.413], [64886.0, 9.511], [65272.6, 1.471], [65336.9, 0.001], [65581.8, 0.61], [65676.3, 0.912]]}
{"kind": "depth", "E": 1787095349019, "U": 11316372959967, "u": 11316372967609, "recv_ms": 1787095349076, "bids": [[14389.9, 0.42], [14489.9, 3.612], [14589.9, 0.168], [58220.9, 0.002], [61455.4, 0.01], [62102.3, 0.147], [63396.2, 0.029], [63689.9, 0.03], [63897.4, 54.607], [63918.1, 5.47], [63962.3, 0.0], [64043.0, 0.032], [64366.5, 0.0], [64620.7, 35.843], [64625.1, 6.267], [64651.7, 0.001], [64655.6, 2.07], [64656.2, 0.026], [64675.6, 0.001], [64676.7, 0.624], [64678.2, 0.004], [64682.2, 0.129], [64682.3, 0.294], [64683.4, 0.089], [64685.1, 0.0], [64685.3, 0.55], [64685.4, 1.604], [64685.9, 0.066], [64689.9, 5.685]], "asks": [[64691.4, 0.227], [64691.5, 0.38], [64692.9, 0.648], [64693.1, 0.486], [64693.2, 0.309], [64693.4, 0.043], [64693.7, 0.092], [64693.9, 0.11], [64694.1, 0.162], [64694.2, 0.495], [64698.9, 0.049], [64721.1, 0.374], [65336.9, 0.001], [65640.9, 2.434], [65690.0, 0.433]]}
{"kind": "depth", "E": 1787095349223, "U": 11316372974631, "u": 11316372981440, "recv_ms": 1787095349283, "bids": [[1000.0, 35.76], [14389.9, 0.966], [14489.9, 3.234], [14589.9, 0.0], [51751.9, 0.0], [51752.0, 0.0], [58220.9, 0.002], [61455.4, 0.01], [63394.2, 0.003], [63689.9, 0.01], [63867.7, 3.244], [63913.6, 18.771], [64043.0, 0.032], [64546.2, 3.07], [64670.7, 0.002], [64673.5, 2.422], [64678.0, 0.009], [64682.2, 0.129], [64682.3, 0.209], [64683.2, 0.542], [64683.3, 0.777], [64683.4, 0.096], [64685.1, 0.003], [64685.3, 0.002], [64685.4, 1.601], [64686.2, 0.003], [64688.0, 0.003], [64689.9, 4.902]], "asks": [[64690.0, 11.309], [64691.4, 0.227], [64691.5, 0.001], [64692.0, 0.078], [64692.8, 0.058], [64692.9, 0.091], [64693.1, 0.371], [64693.2, 0.312], [64693.7, 0.207], [64693.9, 0.126], [64694.1, 0.703], [64701.5, 0.02], [64706.0, 0.387], [64708.9, 10.619], [64718.5, 0.576], [64830.2, 5.413], [64886.0, 10.378], [65336.9, 0.001], [65690.0, 0.413], [65692.7, 2.735], [68495.1, 1.458]]}
{"kind": "depth", "E": 1787095349325, "U": 11316372981591, "u": 11316372987648, "recv_ms": 1787095349381, "bids": [[14389.9, 1.316], [14489.9, 2.884], [58220.9, 0.002], [62102.3, 0.147], [63865.1, 18.63], [64043.0, 0.032], [64366.5, 0.0], [64625.2, 0.021], [64669.5, 0.0], [64671.3, 0.117], [64673.5, 2.424], [64682.2, 0.755], [64683.2, 0.001], [64683.3, 0.151], [64683.4, 0.089], [64683.5, 0.542], [64684.3, 0.091], [64685.3, 0.009]], "asks": [[64691.0, 0.027], [64691.4, 0.002], [64691.5, 0.161], [64692.7, 0.628], [64692.8, 0.058], [64692.9, 0.091], [64693.0, 0.711], [64693.2, 0.32], [64693.6, 0.002], [64693.7, 0.092], [64694.1, 0.162], [64701.5, 0.0], [64703.0, 1.655], [64706.0, 0.389], [64709.1, 0.0], [64709.9, 0.492], [64711.6, 0.122], [64712.5, 0.065], [64713.1, 0.068], [64713.2, 0.325], [64714.0, 0.669], [64714.1, 0.617], [64732.9, 0.03], [64740.8, 1.336], [64754.7, 6.99], [65013.5, 0.769], [65336.9, 0.001], [65466.3, 3.061], [65514.9, 0.0]]}
{"kind": "depth", "E": 1787095349427, "U": 11316372987812, "u": 11316372994047, "recv_ms": 1787095349485, "bids": [[1000.0, 35.76], [14389.9, 1.68], [14489.9, 2.52], [58220.9, 0.002], [61455.4, 0.01], [62102.3, 0.144], [63689.9, 0.03], [63903.9, 2.814], [64043.0, 0.032], [64366.4, 0.789], [64579.9, 0.003], [64629.6, 1.17], [64648.9, 0.54], [64651.0, 0.043], [64663.9, 1.656], [64669.8, 0.131], [64671.3, 0.001], [64675.9, 0.464], [64676.7, 0.165], [64679.7, 0.247], [64682.2, 0.754], [64682.3, 0.217], [64683.5, 0.001], [64684.3, 0.632], [64685.3, 0.002], [64685.4, 1.585], [64685.9, 0.514], [64689.9, 4.901]], "asks": [[64691.5, 0.386], [64692.5, 0.054], [64692.7, 0.087], [64692.9, 0.632], [64693.0, 0.486], [64693.2, 0.425], [64693.7, 0.322], [64693.9, 0.118], [64694.1, 0.162], [64708.3, 0.002], [64709.3, 3.21], [64709.9, 0.033], [64733.3, 1.096], [64735.3, 0.005], [64767.7, 0.0], [64847.1, 0.001], [64847.2, 10.436], [64886.0, 8.843], [65336.9, 0.001], [65690.0, 0.433], [68506.7, 2.186]]}
{"kind": "depth", "E": 1787095349529, "U": 11316372994213, "u": 11316373007399, "recv_ms": 1787095349585, "bids": [[1000.0, 35.76], [14389.9, 2.03], [14489.9, 2.17], [51752.0, 0.0], [58220.9, 0.002], [62102.3, 0.147], [64043.0, 0.032], [64403.3, 0.054], [64625.7, 6.814], [64655.6, 3.358], [64666.6, 0.039], [64675.3, 0.002], [64679.7, 0.247], [64682.2, 0.222], [64682.3, 0.201], [64685.3, 0.55], [64685.7, 0.79], [64685.9, 0.066], [64686.0, 0.019], [64686.7, 0.436], [64689.9, 4.9]], "asks": [[64691.5, 0.386], [64692.8, 0.599], [64692.9, 0.091], [64693.2, 0.31], [64693.7, 0.322], [64694.1, 0.162], [64695.8, 0.059], [64696.2, 0.043], [64696.7, 0.0], [64714.6, 0.07], [64722.0, 1.547], [64729.7, 3.3], [64736.2, 0.976], [64742.6, 3.301], [64744.4, 0.387], [64749.1, 1.931], [64830.1, 2.295], [65283.7, 10.954], [65304.6, 0.616], [65336.9, 0.001], [65579.3, 0.841]]}
{"kind": "depth", "E": 1787095349733, "U": 11316373014867, "u": 11316373021254, "recv_ms": 1787095349791, "bids": [[1000.0, 35.76], [14389.9, 2.744], [14489.9, 1.456], [51752.0, 0.0], [58220.9, 0.002], [61455.4, 0.008], [61455.5, 0.002], [63885.8, 1.566], [63920.1, 0.937], [64041.9, 0.0], [64043.0, 0.032], [64062.4, 0.865], [64528.9, 0.032], [64546.2, 0.002], [64666.6, 0.002], [64673.6, 1.277], [64686.7, 0.436], [64687.9, 0.055], [64689.9, 4.901]], "asks": [[64691.5, 0.007], [64693.6, 0.002], [64693.7, 0.092], [64693.9, 0.195], [64694.1, 0.634], [64698.5, 0.343], [64698.8, 0.026], [64741.8, 0.018], [64744.4, 0.387], [64830.1, 0.0], [64830.2, 0.014], [64847.2, 0.027], [65336.9, 0.001], [65595.7, 7.31], [65981.7, 0.0]]}
{"kind": "depth", "E": 1787095349835, "U": 11316373021530, "u": 11316373030035, "recv_ms": 1787095349892, "bids": [[1000.0, 35.76], [14389.9, 3.108], [14489.9, 1.092], [58220.9, 0.002], [61455.4, 0.008], [62102.3, 0.147], [63689.9, 0.03], [63865.1, 18.365], [64043.0, 0.032], [64490.1, 0.003], [64490.5, 12.543], [64529.3, 6.844], [64531.2, 2.7], [64546.3, 3.399], [64598.4, 0.796], [64609.0, 6.956], [64651.0, 0.015], [64653.6, 0.003], [64677.4, 0.006], [64679.7, 0.239], [64682.2, 0.23], [64682.8, 0.001], [64683.9, 0.397], [64684.1, 0.001], [64685.1, 0.0], [64685.3, 0.553], [64685.5, 0.012], [64685.6, 0.104], [64685.9, 0.066], [64686.2, 0.087], [64686.7, 0.436], [64686.8, 0.014], [64689.9, 5.532]], "asks": [[64690.0, 11.114], [64690.8, 0.003], [64691.0, 0.034], [64691.1, 0.0], [64691.5, 0.393], [64692.5, 0.036], [64693.2, 0.307], [64693.7, 0.322], [64693.9, 0.425], [64700.0, 3.841], [64703.7, 0.0], [64704.8, 0.236], [64708.9, 10.001], [64744.4, 0.405], [64830.2, 4.224], [64847.2, 6.33], [64886.0, 1.641], [65013.5, 0.768], [65336.9, 0.001], [65443.2, 2.748], [65449.7, 28.399], [65690.0, 0.433], [65773.1, 13.871]]}
{"kind": "depth", "E": 1787095349937, "U": 11316373030336, "u": 11316373040495, "recv_ms": 1787095349993, "bids": [[14389.9, 3.458], [14489.9, 0.742], [58220.9, 0.002], [61453.5, 2.441], [61453.6, 0.002], [62102.3, 0.144], [63676.4, 9.412], [64043.0, 0.032], [64347.8, 0.005], [64348.4, 0.493], [64366.4, 0.79], [64366.5, 0.01], [64675.9, 0.005], [64676.3, 1.055], [64677.0, 3.037], [64677.5, 0.384], [64685.5, 0.009], [64686.0, 0.022], [64686.5, 0.002], [64686.7, 0.004], [64687.3, 0.232], [64689.9, 5.532]], "asks": [[64691.5, 0.232], [64692.0, 0.085], [64693.2, 0.422], [64693.7, 0.322], [64693.9, 0.332], [64694.1, 0.634], [64694.5, 0.247], [64698.3, 0.0], [64699.1, 0.324], [64701.0, 2.364], [64702.4, 0.004], [64704.8, 0.156], [64706.8, 0.174], [64708.3, 0.62], [64709.3, 2.751], [64709.8, 0.787], [64713.4, 0.462], [64714.0, 0.669], [64744.4, 0.396], [64847.2, 10.436], [64886.0, 8.461], [65336.9, 0.001], [65785.3, 1.21]]}
{"kind": "depth", "E": 1787095350039, "U": 11316373040612, "u": 11316373049748, "recv_ms": 1787095350098, "bids": [[1000.0, 35.76], [14289.9, 0.042], [14389.9, 3.738], [14489.9, 0.42], [58220.9, 0.002], [61455.4, 0.008], [62102.3, 0.147], [63689.9, 0.01], [63867.7, 3.009], [63881.3, 0.402], [64040.4, 0.0], [64042.4, 0.528], [64043.0, 0.032], [64172.4, 2.521], [64609.9, 0.001], [64678.3, 0.096], [64681.7, 0.003], [64682.8, 0.002], [64683.7, 0.011], [64684.1, 0.0], [64684.9, 0.321], [64685.3, 0.55], [64685.4, 0.003], [64685.7, 0.563], [64686.2, 0.003], [64686.9, 0.012]], "asks": [[64690.0, 11.116], [64691.5, 0.616], [64692.9, 0.632], [64693.0, 0.601], [64693.6, 0.232], [64693.7, 0.092], [64693.9, 0.102], [64694.0, 0.396], [64694.1, 0.093], [64699.1, 0.634], [64706.8, 0.329], [64708.7, 0.164], [64716.9, 0.156], [64744.4, 0.387], [65336.9, 0.001], [65459.8, 0.919], [65466.3, 7.637], [65607.0, 8.675], [65690.0, 0.413]]}
{"kind": "depth", "E": 1787095350141, "U": 11316373050018, "u": 11316373058644, "recv_ms": 1787095350197, "bids": [[1000.0, 35.76], [14289.9, 0.238], [14389.9, 3.696], [14489.9, 0.266], [58220.9, 0.002], [61455.4, 0.008], [62102.3, 0.144], [63394.2, 0.0], [63396.2, 0.023], [63687.2, 1.804], [63805.7, 7.3], [64043.0, 0.032], [64616.8, 0.001], [64643.2, 0.066], [64644.7, 0.032], [64678.3, 0.091], [64684.6, 0.007], [64689.9, 5.531]], "asks": [[64691.4, 0.227], [64691.5, 0.232], [64692.5, 0.046], [64692.7, 0.095], [64692.8, 0.599], [64692.9, 0.091], [64693.0, 0.601], [64693.2, 0.422], [64693.6, 0.002], [64693.9, 0.102], [64694.1, 0.085], [64746.8, 2.188], [64748.3, 0.015], [65336.9, 0.001], [65789.7, 5.16], [65868.7, 0.76]]}
{"kind": "depth", "E": 1787095350243, "U": 11316373058738, "u": 11316373066293, "recv_ms": 1787095350300, "bids": [[14289.9, 0.476], [14389.9, 3.584], [14489.9, 0.14], [51751.9, 0.0], [58220.9, 0.002], [63689.9, 0.03], [63816.6, 2.738], [63912.6, 3.283], [64043.0, 0.032], [64366.5, 0.01], [64629.8, 1.457], [64631.6, 1.24], [64637.1, 0.212], [64655.1, 1.0], [64655.6, 3.288], [64660.5, 1.332], [64661.8, 0.0], [64663.9, 1.726], [64664.2, 0.015], [64665.7, 0.041], [64670.4, 1.48], [64673.5, 2.422], [64677.1, 0.096], [64677.4, 0.006], [64679.7, 0.239], [64682.3, 0.117], [64682.7, 0.001], [64685.3, 0.009], [64685.9, 0.066], [64686.0, 0.647], [64686.6, 0.328], [64687.1, 0.312], [64687.2, 0.086]], "asks": [[64691.4, 0.002], [64691.5, 0.007], [64692.6, 0.273], [64692.7, 0.095], [64692.8, 0.058], [64692.9, 0.632], [64693.0, 0.486], [64693.2, 0.537], [64693.7, 0.092], [64693.9, 0.109], [64694.0, 0.241], [64694.1, 0.233], [64699.1, 0.634], [64703.0, 1.658], [64704.8, 0.076], [64706.0, 0.387], [64706.8, 0.409], [64708.7, 0.164], [64716.9, 0.156], [64744.4, 0.387], [64767.7, 0.003], [65336.9, 0.001], [65484.8, 1.525], [65608.6, 0.233], [65690.0, 0.433], [65983.7, 0.015]]}
{"kind": "depth", "E": 1787095350345, "U": 11316373066387, "u": 11316373073089, "recv_ms": 1787095350402, "bids": [[1000.0, 35.76], [14289.9, 0.714], [14389.9, 3.458], [14489.9, 0.028], [51752.0, 0.0], [58220.9, 0.002], [61455.4, 0.012], [62102.3, 0.147], [63110.6, 1.356], [63469.4, 0.002], [63741.1, 10.042], [64043.0, 0.032], [64054.8, 8.232], [64366.4, 0.789], [64546.3, 0.0], [64664.0, 1.449], [64664.2, 0.015], [64668.4, 0.169], [64670.7, 0.736], [64673.5, 2.424], [64677.1, 0.096], [64677.4, 0.006], [64678.0, 0.627], [64679.7, 0.239], [64682.3, 0.117], [64685.3, 0.55], [64686.0, 0.106], [64686.2, 0.003], [64687.1, 0.002], [64687.2, 0.002], [64689.9, 5.532]], "asks": [[64691.5, 0.007], [64692.4, 0.012], [64692.5, 0.036], [64692.8, 0.599], [64692.9, 0.091], [64693.1, 0.381], [64693.2, 0.307], [64693.7, 0.092], [64693.9, 0.109], [64694.1, 0.233], [64699.1, 0.634], [64701.6, 0.618], [64706.0, 0.389], [64706.8, 0.409], [64708.7, 0.164], [64708.9, 10.619], [64716.9, 0.156], [64767.9, 0.0], [64774.5, 52.67], [64830.2, 0.014], [65336.9, 0.001], [65482.0, 17.636]]}
{"kind": "depth", "E": 1787095350447, "U": 11316373073102, "u": 11316373084584, "recv_ms": 1787095350505, "bids": [[1000.0, 35.76], [14289.9, 1.05], [14389.9, 3.15], [14489.9, 0.0], [58220.9, 0.002], [62102.3, 0.144], [63689.9, 0.01], [63718.6, 4.78], [63897.4, 53.046], [64043.0, 0.032], [64323.6, 0.0], [64324.9, 0.758], [64364.2, 0.0], [64366.7, 0.115], [64420.3, 0.0], [64421.7, 0.249], [64491.2, 1.18], [64492.8, 3.477], [64546.4, 3.562], [64659.5, 0.199], [64665.7, 0.001], [64670.7, 0.118], [64678.0, 0.009], [64682.0, 0.01], [64682.7, 0.085], [64682.8, 0.001], [64683.1, 0.663], [64683.2, 0.433], [64683.9, 0.087], [64684.6, 0.004], [64685.7, 0.566], [64686.0, 0.019], [64686.6, 0.244], [64687.2, 0.004], [64689.9, 4.902]], "asks": [[64691.5, 0.007], [64692.5, 0.044], [64692.7, 0.095], [64692.8, 0.058], [64692.9, 0.632], [64693.0, 0.711], [64693.7, 0.092], [64693.9, 0.101], [64698.5, 0.342], [64701.6, 0.0], [64765.6, 1.142], [64767.9, 46.863], [64770.1, 0.006], [64774.4, 2.592], [64774.5, 5.807], [64830.2, 5.413], [64886.0, 8.649], [64890.3, 0.992], [64891.5, 0.013], [64960.2, 0.263], [64962.9, 0.013], [65013.5, 0.769], [65018.8, 0.03], [65018.9, 0.108], [65059.9, 0.293], [65060.4, 0.125], [65336.9, 0.001], [65595.7, 7.318], [65690.0, 0.413]]}
{"kind": "depth", "E": 1787095350549, "U": 11316373084753, "u": 11316373091658, "recv_ms": 1787095350605, "bids": [[14289.9, 1.4], [14389.9, 2.8], [58220.9, 0.002], [61453.5, 2.439], [61453.6, 0.004], [61455.4, 0.012], [62102.3, 0.147], [63739.0, 1.337], [63751.9, 4.377], [63933.0, 1.747], [64043.0, 0.032], [64075.3, 4.814], [64366.5, 0.01], [64524.7, 0.039], [64524.9, 0.007], [64582.4, 0.005], [64582.5, 0.003], [64613.7, 1.788], [64642.4, 1.616], [64683.2, 0.433], [64689.9, 4.903]], "asks": [[64690.0, 11.11], [64691.5, 0.386], [64692.5, 0.585], [64692.7, 0.095], [64692.8, 0.058], [64692.9, 0.091], [64693.0, 0.486], [64693.9, 0.101], [64830.1, 2.295], [65336.9, 0.001], [65591.0, 7.767], [65982.6, 0.0]]}
{"kind": "depth", "E": 1787095350651, "U": 11316373091784, "u": 11316373097788, "recv_ms": 1787095350708, "bids": [[1000.0, 35.76], [14289.9, 1.764], [14389.9, 2.436], [58220.9, 0.002], [61455.4, 0.012], [63480.2, 0.786], [63689.9, 0.03], [63821.5, 5.475], [63867.6, 4.185], [63913.6, 19.551], [63975.9, 0.156], [64043.0, 0.032], [64062.2, 0.009], [64207.8, 0.0], [64579.9, 0.0], [64631.6, 1.24], [64677.5, 0.002], [64683.2, 0.001], [64686.1, 0.084], [64687.5, 0.382], [64689.9, 4.901]], "asks": [[64691.4, 0.002], [64691.5, 0.161], [64692.4, 0.012], [64692.5, 0.036], [64692.7, 0.087], [64692.9, 0.64], [64693.1, 0.371], [64693.8, 0.291], [64693.9, 0.109], [64694.5, 0.162], [64706.8, 1.027], [64708.3, 0.002], [64721.1, 0.318], [64735.3, 0.002], [64767.7, 0.003], [64805.6, 0.0], [65177.5, 0.009], [65326.4, 0.0], [65336.9, 0.001], [65510.4, 3.201], [65690.0, 0.433], [65983.7, 0.018]]}
{"kind": "depth", "E": 1787095350753, "U": 11316373097864, "u": 11316373103603, "recv_ms": 1787095350810, "bids": [[1000.0, 35.76], [14289.9, 2.128], [14389.9, 2.072], [58220.9, 0.002], [62102.3, 0.144], [63689.9, 0.01], [64043.0, 0.032], [64321.6, 38.318], [64321.7, 0.864], [64322.7, 6.122], [64323.7, 0.423], [64418.3, 30.383], [64418.9, 4.95], [64489.2, 24.573], [64524.7, 0.0], [64524.9, 0.046], [64686.9, 0.244], [64687.3, 0.0], [64689.9, 4.902]], "asks": [[64691.4, 0.227], [64691.5, 0.539], [64692.5, 0.266], [64692.8, 0.288], [64692.9, 0.87], [64693.0, 0.601], [64693.1, 0.486], [64693.7, 0.092], [64709.4, 1.409], [64732.9, 0.026], [64740.8, 1.34], [64888.1, 24.786], [64959.4, 30.337], [65056.8, 6.157], [65056.9, 37.409], [65336.9, 0.001], [65670.4, 0.153], [65690.0, 0.413]]}
{"kind": "depth", "E": 1787095350855, "U": 11316373103665, "u": 11316373110041, "recv_ms": 1787095350912, "bids": [[14289.9, 2.478], [14389.9, 1.722], [58220.9, 0.002], [61455.4, 0.012], [62102.3, 0.147], [63805.7, 6.518], [63934.2, 0.781], [64043.0, 0.032], [64366.5, 0.0], [64490.5, 0.003], [64490.7, 4.543], [64529.3, 0.018], [64529.6, 4.347], [64546.4, 0.06], [64546.5, 4.506], [64623.8, 0.001], [64651.0, 0.057]], "asks": [[64690.0, 11.834], [64691.3, 0.002], [64691.4, 0.243], [64691.5, 0.238], [64692.3, 0.001], [64692.4, 0.242], [64692.5, 0.266], [64692.7, 0.17], [64692.8, 0.058], [64692.9, 0.008], [64693.0, 0.486], [64693.1, 0.371], [64693.3, 0.39], [64693.9, 0.642], [64706.7, 0.621], [64706.8, 0.409], [64708.3, 0.002], [64750.5, 0.0], [64886.0, 15.412], [65174.0, 47.945], [65323.9, 60.177], [65336.9, 0.001], [71159.0, 0.003]]}
{"kind": "depth", "E": 1787095350957, "U": 11316373110140, "u": 11316373116965, "recv_ms": 1787095351014, "bids": [[1000.0, 35.76], [14289.9, 2.842], [14389.9, 1.358], [58220.9, 0.002], [61455.4, 0.012], [62102.3, 0.144], [63396.2, 0.023], [63689.9, 0.03], [63860.8, 3.062], [63865.2, 0.22], [63881.3, 0.636], [64043.0, 0.032], [64172.4, 2.521], [64205.9, 47.13], [64348.4, 0.001], [64348.8, 1.015], [64366.4, 0.788], [64490.7, 12.208], [64492.8, 0.06], [64529.6, 7.96], [64546.5, 6.88], [64585.0, 0.015], [64618.5, 35.578], [64625.1, 6.267], [64625.7, 1.687], [64627.1, 2.731], [64651.0, 0.057], [64655.5, 0.053], [64655.6, 3.29], [64664.2, 0.015], [64670.1, 0.116], [64670.7, 0.002], [64672.6, 0.557], [64673.1, 0.0], [64676.3, 1.514], [64677.0, 2.578], [64677.1, 0.096], [64677.4, 0.006], [64678.7, 0.524], [64679.2, 0.1], [64679.7, 0.247], [64681.1, 0.002], [64682.2, 0.129], [64682.3, 0.665], [64683.2, 0.542], [64683.3, 0.151], [64683.4, 0.166], [64684.3, 0.091], [64684.5, 0.016], [64685.1, 0.003], [64685.3, 0.002], [64685.5, 0.009], [64685.7, 0.563], [64685.9, 0.066], [64686.1, 0.0], [64686.9, 0.241], [64689.9, 3.931]], "asks": [[64690.0, 11.834], [64691.4, 0.002], [64691.5, 0.161], [64692.4, 0.012], [64692.5, 0.036], [64693.1, 0.381], [64693.2, 0.307], [64693.6, 0.157], [64693.7, 0.108], [64694.1, 0.078], [64699.1, 0.634], [64706.7, 0.158], [64706.8, 0.872], [64707.5, 0.12], [64708.3, 0.002], [64708.7, 0.164], [64708.9, 10.003], [64713.1, 0.624], [64714.0, 0.113], [64716.9, 0.156], [64749.0, 2.216], [64749.9, 0.0], [64752.6, 3.446], [64847.2, 10.436], [64886.0, 8.687], [65013.5, 0.77], [65336.9, 0.001], [65690.0, 0.433], [65691.4, 4.128], [65755.7, 0.0], [71159.0, 0.002]]}
{"kind": "depth", "E": 1787095351161, "U": 11316373124242, "u": 11316373134405, "recv_ms": 1787095351218, "bids": [[14289.9, 3.556], [14389.9, 0.644], [58220.9, 0.002], [61455.4, 0.011], [61455.5, 0.004], [63816.6, 3.52], [63881.3, 0.987], [64043.0, 0.032], [64366.5, 0.0], [64620.7, 0.028], [64625.1, 41.589], [64651.0, 0.015], [64654.0, 8.047], [64655.6, 1.29], [64656.2, 0.04], [64682.4, 0.0], [64683.2, 0.542], [64683.3, 0.236], [64683.4, 0.097], [64685.9, 0.066], [64689.9, 3.95]], "asks": [[64690.0, 11.83], [64691.5, 0.232], [64692.9, 0.549], [64693.0, 0.483], [64693.2, 0.307], [64693.7, 0.338], [64698.6, 0.003], [64702.1, 0.463], [64709.4, 1.338], [64800.6, 0.124], [64873.5, 0.001], [64873.6, 0.004], [65336.9, 0.001], [65591.3, 0.02]]}
{"kind": "depth", "E": 1787095351263, "U": 11316373134476, "u": 11316373142400, "recv_ms": 1787095351321, "bids": [[1000.0, 35.76], [14189.9, 0.07], [14289.9, 3.766], [14389.9, 0.364], [51751.9, 0.0], [51752.0, 0.0], [58220.9, 0.002], [61455.4, 0.01], [62102.3, 0.144], [63557.8, 1.257], [63689.9, 0.01], [64043.0, 0.032], [64667.3, 0.156], [64673.5, 2.422], [64677.1, 0.251], [64677.4, 0.161], [64677.8, 0.0], [64679.7, 0.402], [64680.4, 0.0], [64682.2, 0.284], [64682.3, 0.117], [64682.4, 0.093], [64682.5, 0.016], [64683.2, 0.001], [64683.3, 0.151], [64683.4, 0.089], [64684.3, 0.632], [64685.3, 0.55], [64685.9, 0.221], [64689.9, 3.951]], "asks": [[64691.4, 0.232], [64691.5, 0.462], [64691.8, 0.884], [64692.5, 0.266], [64692.7, 0.087], [64692.8, 0.074], [64692.9, 0.779], [64693.0, 0.681], [64693.6, 0.002], [64693.7, 0.092], [64693.8, 0.214], [64693.9, 0.101], [64694.1, 0.155], [64699.1, 0.015], [64706.0, 0.387], [64706.7, 0.003], [64708.7, 0.009], [64716.9, 0.001], [65336.9, 0.001], [65425.9, 1.758], [65611.4, 24.238], [65690.0, 0.413], [65775.8, 0.379], [65776.8, 1.232], [66975.8, 0.01]]}
{"kind": "depth", "E": 1787095351365, "U": 11316373142626, "u": 11316373150030, "recv_ms": 1787095351424, "bids": [[1000.0, 35.76], [14189.9, 0.308], [14289.9, 3.654], [14389.9, 0.238], [51752.0, 0.0], [58220.9, 0.002], [61455.4, 0.011], [62102.3, 0.147], [63901.8, 0.808], [64043.0, 0.032], [64667.3, 0.001], [64668.9, 2.341], [64670.6, 1.082], [64673.5, 2.424], [64677.1, 0.096], [64677.4, 0.006], [64678.0, 0.627], [64679.7, 0.247], [64682.2, 0.129], [64685.6, 0.089], [64685.9, 0.066], [64689.9, 3.95]], "asks": [[64691.3, 0.002], [64691.4, 0.002], [64691.5, 0.232], [64691.8, 0.769], [64692.4, 0.012], [64692.5, 0.036], [64692.6, 0.356], [64692.7, 0.644], [64692.8, 0.058], [64692.9, 0.008], [64693.0, 0.483], [64693.1, 0.381], [64693.2, 0.537], [64693.7, 0.322], [64693.9, 0.101], [64694.1, 0.31], [64699.1, 0.325], [64701.5, 0.618], [64706.0, 0.389], [64706.7, 0.158], [64708.7, 0.164], [64708.9, 10.621], [64716.9, 0.156], [65336.9, 0.002], [65542.3, 0.001], [65565.1, 0.61]]}
{"kind": "depth", "E": 1787095351569, "U": 11316373157444, "u": 11316373163510, "recv_ms": 1787095351626, "bids": [[1000.0, 35.76], [14189.9, 0.77], [14289.9, 3.43], [14389.9, 0.0], [58220.9, 0.002], [61455.4, 0.01], [63692.2, 2.361], [63881.3, 1.252], [64043.0, 0.032], [64365.0, 0.038], [64366.4, 0.789], [64488.9, 0.015], [64489.3, 4.726], [64490.7, 0.001], [64490.9, 7.16], [64529.6, 1.282], [64529.7, 4.11], [64546.5, 2.501], [64546.7, 2.739], [64585.0, 0.0], [64625.7, 6.741], [64655.6, 2.311], [64657.0, 0.005], [64657.1, 0.021], [64657.2, 0.064], [64660.5, 1.332], [64660.6, 0.028], [64681.2, 1.539]], "asks": [[64690.0, 11.855], [64691.4, 0.002], [64691.5, 0.007], [64692.5, 0.044], [64692.8, 0.599], [64692.9, 0.016], [64693.7, 0.092], [64693.9, 0.101], [64765.6, 7.868], [64844.9, 2.898], [64886.0, 15.412], [65336.9, 0.002], [65446.9, 0.534], [65563.3, 0.805], [65628.0, 1.365]]}
{"kind": "depth", "E": 1787095351671, "U": 11316373163649, "u": 11316373169908, "recv_ms": 1787095351727, "bids": [[1000.0, 35.76], [14189.9, 1.134], [14289.9, 3.066], [58220.9, 0.002], [61455.4, 0.01], [62102.3, 0.147], [63396.2, 0.026], [63689.9, 0.01], [63702.9, 0.0], [64043.0, 0.032], [64490.9, 12.214], [64529.7, 6.516], [64546.7, 4.381], [64684.5, 0.019], [64685.9, 0.498], [64686.0, 0.103], [64689.9, 3.95]], "asks": [[64690.0, 10.438], [64691.5, 0.007], [64692.5, 0.044], [64692.6, 0.273], [64692.8, 0.599], [64692.9, 0.099], [64693.3, 0.387], [64693.7, 0.092], [64693.9, 0.101], [64699.7, 0.005], [64701.5, 0.0], [64703.2, 0.064], [64708.9, 10.003], [64713.1, 0.068], [64713.6, 1.411], [64765.6, 1.142], [64767.9, 0.0], [64772.4, 47.069], [64886.0, 8.923], [65336.9, 0.002], [65655.9, 0.762], [65690.0, 0.413], [65801.5, 1.519]]}
{"kind": "depth", "E": 1787095351773, "U": 11316373170078, "u": 11316373176289, "recv_ms": 1787095351832, "bids": [[14189.9, 1.498], [14289.9, 2.702], [58220.9, 0.002], [61455.4, 0.01], [62102.3, 0.144], [63881.3, 1.486], [63897.4, 52.827], [63918.1, 4.689], [64043.0, 0.032], [64220.2, 0.005], [64366.5, 0.01], [64546.7, 0.003], [64664.2, 0.015], [64670.6, 0.464], [64677.1, 0.096], [64677.4, 0.006], [64678.0, 0.009], [64679.7, 0.247], [64682.2, 0.129], [64684.5, 0.016], [64685.4, 0.003], [64685.7, 0.008], [64685.8, 0.004], [64685.9, 0.004], [64686.0, 0.664], [64686.1, 0.0], [64686.2, 1.548], [64686.3, 0.232], [64686.4, 0.065], [64686.9, 0.009]], "asks": [[64690.0, 11.29], [64691.4, 0.002], [64691.5, 0.007], [64692.5, 0.044], [64692.7, 0.087], [64692.8, 0.599], [64692.9, 0.099], [64693.1, 0.381], [64693.6, 0.0], [64693.7, 0.092], [64693.9, 0.101], [64694.1, 0.312], [64699.1, 0.325], [64706.7, 0.158], [64708.7, 0.164], [64716.9, 0.156], [64744.4, 0.387], [64767.9, 47.257], [64770.1, 0.006], [64772.4, 0.0], [64830.1, 0.0], [64830.2, 0.014], [65336.9, 0.002], [65450.0, 25.299], [65499.2, 9.537], [65628.0, 1.517]]}
{"kind": "depth", "E": 1787095351875, "U": 11316373176312, "u": 11316373183538, "recv_ms": 1787095351931, "bids": [[1000.0, 35.76], [14189.9, 1.848], [14289.9, 2.352], [51752.0, 0.0], [58220.9, 0.002], [61455.4, 0.008], [61455.5, 0.006], [62102.3, 0.147], [63676.4, 8.314], [63689.9, 0.03], [64043.0, 0.032], [64524.7, 0.039], [64524.9, 0.007], [64685.3, 0.612], [64685.4, 0.011], [64686.0, 0.087], [64686.2, 0.003], [64686.4, 0.003], [64686.5, 0.002], [64686.7, 0.012], [64686.8, 0.651], [64686.9, 1.554]], "asks": [[64691.3, 0.227], [64691.4, 0.002], [64691.5, 0.315], [64691.7, 0.016], [64692.4, 0.325], [64692.5, 0.807], [64692.6, 0.273], [64692.7, 0.087], [64692.8, 0.06], [64692.9, 0.238], [64693.0, 0.483], [64693.2, 0.307], [64693.9, 0.101], [64694.1, 0.31], [65336.9, 0.002], [65466.3, 9.163], [65499.3, 0.762], [65690.0, 0.433], [66290.4, 1.075]]}
{"kind": "depth", "E": 1787095351977, "U": 11316373183624, "u": 11316373189475, "recv_ms": 1787095352036, "bids": [[14189.9, 2.198], [14289.9, 2.002], [58220.9, 0.002], [61455.4, 0.008], [62102.3, 0.144], [63714.9, 0.274], [64043.0, 0.032], [64366.4, 0.79], [64490.9, 0.424], [64491.0, 11.782], [64529.7, 0.0], [64529.8, 6.363], [64531.2, 1.926], [64546.7, 4.05], [64579.9, 0.003], [64631.6, 1.237], [64685.4, 1.556], [64685.5, 0.017], [64686.7, 0.004], [64686.9, 0.009], [64689.9, 3.957]], "asks": [[64690.0, 11.292], [64691.3, 0.002], [64691.4, 0.002], [64691.5, 0.007], [64691.7, 0.0], [64692.2, 0.12], [64692.3, 0.001], [64692.4, 0.012], [64692.5, 0.036], [64692.8, 0.141], [64692.9, 0.016], [64693.1, 0.371], [64693.2, 0.307], [64693.3, 0.387], [64693.9, 0.652], [64735.3, 0.005], [64767.7, 0.0], [64830.2, 5.413], [64844.9, 1.542], [64847.2, 10.436], [64886.0, 9.852], [65013.5, 0.768], [65336.9, 0.002], [65461.5, 3.072], [65482.0, 17.407], [65514.4, 12.343]]}
{"kind": "depth", "E": 1787095352079, "U": 11316373189692, "u": 11316373196163, "recv_ms": 1787095352136, "bids": [[14189.9, 2.562], [14289.9, 1.638], [58220.9, 0.002], [63126.2, 0.678], [63687.2, 2.902], [63689.9, 0.01], [64043.0, 0.032], [64232.5, 0.12], [64366.5, 0.0], [64524.7, 0.0], [64524.9, 0.046], [64664.2, 0.015], [64677.1, 0.096], [64677.4, 0.006], [64678.3, 0.091], [64679.7, 0.247], [64682.2, 0.129], [64683.2, 0.001], [64684.3, 0.632], [64685.5, 0.017], [64688.3, 0.007], [64689.9, 3.959]], "asks": [[64691.5, 0.084], [64692.8, 0.599], [64692.9, 0.099], [64693.0, 0.483], [64693.1, 0.381], [64693.2, 0.422], [64693.7, 0.092], [64693.8, 0.369], [64693.9, 0.111], [64694.1, 0.155], [64699.1, 0.325], [64706.7, 0.158], [64708.6, 0.024], [64708.7, 0.164], [64709.4, 1.214], [64709.5, 0.461], [64709.8, 0.328], [64712.8, 2.823], [64713.7, 0.27], [64714.1, 0.502], [64716.9, 0.156], [64886.0, 0.0], [64886.1, 9.347], [65336.9, 0.002], [65498.6, 2.054], [65690.0, 0.413], [66307.2, 0.075]]}
{"kind": "depth", "E": 1787095352181, "U": 11316373196333, "u": 11316373203857, "recv_ms": 1787095352239, "bids": [[1000.0, 35.76], [14189.9, 2.912], [14289.9, 1.288], [51752.0, 0.0], [58220.9, 0.002], [62102.3, 0.147], [64043.0, 0.032], [64600.4, 0.003], [64651.9, 0.118], [64657.1, 0.036], [64669.8, 0.004], [64673.2, 1.468], [64685.4, 1.555], [64689.9, 3.958]], "asks": [[64691.4, 0.002], [64691.5, 0.084], [64693.2, 0.307], [64847.2, 6.467], [64886.1, 1.645], [65336.9, 0.002], [65531.2, 1.066], [65983.7, 0.012]]}
{"kind": "depth", "E": 1787095352283, "U": 11316373203910, "u": 11316373213982, "recv_ms": 1787095352340, "bids": [[14189.9, 3.276], [14289.9, 0.924], [51751.9, 0.0], [51752.0, 0.0], [58220.9, 0.002], [61455.4, 0.008], [62102.3, 0.144], [63689.9, 0.03], [64043.0, 0.032], [64091.6, 0.001], [64479.5, 0.017], [64673.5, 3.813], [64673.7, 0.333], [64686.5, 0.086]], "asks": [[64691.4, 0.002], [64691.5, 0.084], [64706.0, 0.387], [64847.2, 10.436], [64886.1, 8.179], [65300.0, 128.151], [65336.9, 0.002], [65526.6, 1.525], [65602.1, 0.914], [65690.0, 0.433]]}
{"kind": "depth", "E": 1787095352691, "U": 11316373234467, "u": 11316373240524, "recv_ms": 1787095352748, "bids": [[14189.9, 3.528], [14289.9, 0.084], [14589.9, 0.588], [58220.9, 0.002], [61455.4, 0.009], [62102.3, 0.147], [63689.9, 0.03], [63903.9, 0.938], [63920.1, 1.874], [64043.0, 0.032], [64366.5, 0.0], [64546.7, 0.003], [64631.6, 1.24], [64668.9, 2.326], [64670.7, 0.62], [64678.1, 0.783], [64682.0, 0.025], [64685.8, 0.002], [64686.5, 0.002], [64689.9, 3.959]], "asks": [[64691.5, 0.309], [64692.4, 0.002], [64693.3, 0.39], [64693.7, 0.322], [64701.6, 0.618], [64708.9, 10.621], [64741.8, 0.021], [64767.7, 0.003], [64830.1, 0.0], [64830.2, 0.014], [65013.5, 0.769], [65336.9, 0.001], [65443.2, 1.832], [65449.7, 28.185], [65690.0, 0.433], [71159.0, 0.004]]}
{"kind": "depth", "E": 1787095352793, "U": 11316373240684, "u": 11316373246629, "recv_ms": 1787095352852, "bids": [[1000.0, 35.76], [14189.9, 3.346], [14289.9, 0.0], [14589.9, 0.854], [58220.9, 0.002], [61455.4, 0.008], [62102.3, 0.144], [63275.3, 0.002], [63278.0, 0.005], [63881.3, 1.877], [64043.0, 0.032], [64529.8, 0.419], [64529.9, 8.831], [64546.9, 4.263], [64689.9, 3.958]], "asks": [[64691.5, 0.007], [64692.5, 0.036], [64693.7, 0.092], [64765.6, 1.142], [64767.9, 47.367], [64770.1, 0.006], [64772.4, 0.0], [64830.3, 5.399], [64847.2, 10.436], [64886.1, 9.057], [65207.5, 1.53], [65336.9, 0.003], [71159.0, 0.002]]}
{"kind": "depth", "E": 1787095352895, "U": 11316373246674, "u": 11316373252307, "recv_ms": 1787095352951, "bids": [[14189.9, 2.996], [14589.9, 1.204], [58220.9, 0.002], [61455.5, 0.004], [62102.3, 0.147], [63689.9, 0.01], [63783.2, 0.0], [63920.1, 2.812], [64043.0, 0.032], [64546.9, 4.594]], "asks": [[64691.5, 0.161], [64692.5, 0.046], [64693.7, 0.092], [64830.3, 5.399], [64886.1, 8.11], [65336.9, 0.001], [65459.8, 1.834], [65690.0, 0.413], [65708.4, 0.426], [65725.0, 2.193]]}
{"kind": "depth", "E": 1787095352997, "U": 11316373252792, "u": 11316373276294, "recv_ms": 1787095353053, "bids": [[1000.0, 35.76], [14189.9, 2.632], [14589.9, 1.568], [58220.9, 0.002], [61455.4, 0.008], [64043.0, 0.032], [64366.4, 0.788], [64366.5, 0.01], [64619.3, 0.388], [64619.4, 1.972], [64627.7, 0.018], [64627.8, 2.282], [64636.0, 0.033], [64636.2, 0.524], [64656.2, 0.026], [64679.7, 0.239], [64682.2, 0.137], [64684.4, 0.311], [64686.7, 0.088], [64687.6, 0.003]], "asks": [[64690.0, 11.153], [64690.9, 0.09], [64691.4, 0.009], [64691.5, 0.161], [64693.2, 0.537], [64693.3, 0.387], [64693.7, 0.092], [64701.6, 0.0], [64702.7, 0.541], [64703.0, 0.033], [64703.1, 1.637], [64708.9, 10.003], [64711.4, 0.008], [64711.5, 2.002], [64714.6, 0.0], [64719.8, 0.019], [64719.9, 1.973], [64721.1, 0.374], [64721.2, 0.073], [64800.6, 0.024], [64886.1, 11.457], [65013.5, 0.77], [65336.9, 0.001], [65607.4, 0.762]]}
{"kind": "depth", "E": 1787095353099, "U": 11316373276361, "u": 11316373286755, "recv_ms": 1787095353157, "bids": [[1000.0, 35.76], [14189.9, 2.268], [14589.9, 1.932], [51752.0, 0.002], [58220.9, 0.002], [62102.3, 0.144], [63396.2, 0.017], [63689.9, 0.03], [63704.5, 0.003], [63704.6, 1.088], [63803.6, 0.625], [64043.0, 0.032], [64582.5, 0.0], [64582.6, 0.778], [64656.2, 0.068], [64670.7, 0.002], [64673.3, 0.351], [64673.5, 3.817], [64678.1, 0.165], [64678.2, 0.004], [64679.7, 0.239], [64682.2, 0.137], [64682.3, 0.201], [64684.4, 0.001], [64684.7, 0.087], [64685.1, 0.0], [64685.6, 0.008], [64686.0, 0.003], [64686.7, 0.004], [64689.9, 4.833]], "asks": [[64690.0, 11.154], [64691.4, 0.025], [64691.5, 0.539], [64691.8, 1.258], [64692.5, 0.496], [64692.6, 0.356], [64692.7, 0.317], [64692.9, 0.01], [64693.0, 0.483], [64693.1, 0.371], [64693.2, 0.307], [64693.4, 0.043], [64693.7, 0.092], [64693.9, 0.101], [64694.7, 1.511], [64698.6, 0.002], [64700.9, 1.46], [64709.3, 2.753], [64721.1, 0.318], [64741.8, 0.021], [64767.9, 0.0], [64772.4, 47.367], [65336.9, 0.001], [65671.3, 0.0], [65671.4, 0.002], [65690.0, 0.433], [65983.7, 0.006]]}
{"kind": "depth", "E": 1787095353201, "U": 11316373286801, "u": 11316373295378, "recv_ms": 1787095353257, "bids": [[14189.9, 1.918], [14589.9, 2.282], [51752.0, 0.0], [58220.9, 0.002], [61455.4, 0.008], [62102.3, 0.147], [63706.1, 0.388], [63881.3, 2.228], [64043.0, 0.034], [64524.7, 0.039], [64524.9, 0.007], [64579.9, 0.003], [64593.2, 2.482], [64617.1, 0.002], [64631.6, 1.237], [64660.4, 4.904], [64664.2, 0.015], [64670.1, 0.0], [64671.8, 0.117], [64672.6, 0.0], [64674.1, 0.56], [64674.5, 0.0], [64675.9, 0.012], [64676.3, 1.055], [64677.1, 0.096], [64677.4, 0.006], [64677.8, 0.459], [64679.7, 0.239], [64682.2, 0.137], [64684.3, 0.091], [64684.4, 0.542], [64685.3, 0.55], [64685.4, 1.555], [64685.5, 0.511], [64685.6, 0.005], [64685.9, 0.088], [64686.1, 0.003], [64689.9, 5.462]], "asks": [[64690.0, 11.153], [64691.4, 0.002], [64691.5, 0.386], [64691.8, 0.769], [64692.0, 0.085], [64692.4, 0.002], [64692.5, 0.036], [64692.6, 0.273], [64692.7, 0.087], [64692.8, 0.058], [64692.9, 0.557], [64693.1, 0.454], [64693.4, 0.043], [64693.7, 0.092], [64693.8, 0.208], [64693.9, 0.109], [64694.0, 0.396], [64694.1, 0.078], [64694.5, 0.247], [64697.9, 0.003], [64698.1, 0.382], [64698.3, 0.02], [64698.5, 0.365], [64698.9, 0.358], [64699.1, 0.17], [64699.9, 0.78], [64700.0, 2.931], [64700.4, 0.393], [64701.0, 2.364], [64706.7, 0.003], [64706.8, 0.409], [64708.4, 1.085], [64708.7, 0.164], [64709.5, 0.002], [64710.4, 0.468], [64713.6, 0.855], [64713.7, 0.155], [64714.6, 0.671], [64715.5, 0.003], [64716.3, 0.009], [64716.9, 0.156], [64735.3, 0.005], [64740.8, 1.336], [64744.4, 0.387], [64767.7, 0.0], [64768.0, 47.393], [64772.4, 0.0], [64805.6, 0.1], [64847.2, 0.027], [64847.3, 10.436], [64886.1, 8.112], [65336.9, 0.001], [65611.4, 23.173]]}
{"kind": "depth", "E": 1787095353303, "U": 11316373295406, "u": 11316373302370, "recv_ms": 1787095353361, "bids": [[1000.0, 35.76], [14189.9, 1.554], [14589.9, 2.646], [51751.9, 0.0], [58220.9, 0.002], [62102.3, 0.144], [63396.2, 0.014], [63689.9, 0.01], [64043.0, 0.032], [64366.5, 0.0], [64671.2, 0.119], [64671.8, 0.001], [64673.5, 3.815], [64677.2, 0.459], [64677.8, 0.0], [64682.0, 0.024], [64683.0, 0.088], [64685.5, 0.079], [64689.9, 5.465]], "asks": [[64690.0, 11.156], [64691.5, 0.161], [64692.9, 0.87], [64693.0, 0.483], [64693.1, 0.371], [64693.2, 0.307], [64693.7, 0.092], [64706.0, 0.387], [64708.9, 0.003], [64711.7, 10.014], [64732.9, 0.03], [65336.9, 0.003], [65620.6, 0.0], [65673.8, 0.035], [65690.0, 0.413], [71159.0, 0.002]]}
{"kind": "depth", "E": 1787095353405, "U": 11316373302379, "u": 11316373324164, "recv_ms": 1787095353463, "bids": [[1000.0, 35.76], [14189.9, 1.204], [14589.9, 2.996], [58220.9, 0.002], [61439.8, 0.002], [61455.4, 0.008], [62102.3, 0.147], [63707.8, 0.786], [63805.7, 5.783], [63897.4, 48.139], [63934.2, 1.562], [64043.0, 0.032], [64459.3, 0.108], [64486.7, 0.003], [64519.7, 0.0], [64551.2, 0.0], [64566.4, 0.412], [64632.9, 0.018], [64656.2, 0.026], [64664.2, 0.015], [64664.6, 0.012], [64665.6, 0.011], [64670.0, 0.812], [64671.2, 0.003], [64672.6, 0.557], [64673.4, 0.002], [64673.5, 3.817], [64674.1, 0.003], [64676.3, 1.514], [64677.2, 0.0], [64677.4, 0.006], [64679.7, 0.239], [64682.2, 0.137], [64682.3, 0.117], [64682.7, 0.001], [64683.2, 0.001], [64684.2, 0.883], [64684.3, 0.632], [64684.4, 0.001], [64685.5, 0.525], [64685.6, 0.005], [64686.3, 0.0], [64686.4, 0.087], [64686.5, 0.003], [64686.9, 0.319], [64687.0, 0.253], [64687.1, 0.013], [64687.3, 0.084], [64687.8, 0.139], [64688.0, 0.004], [64689.9, 5.616]], "asks": [[64690.0, 11.15], [64690.4, 0.003], [64691.5, 0.007], [64692.8, 0.066], [64692.9, 0.099], [64693.0, 0.424], [64693.2, 0.307], [64693.7, 0.092], [64693.9, 0.101], [64694.0, 0.241], [64694.1, 0.774], [64695.8, 0.002], [64698.1, 0.382], [64698.3, 0.0], [64698.5, 0.322], [64698.8, 0.004], [64698.9, 0.513], [64699.1, 0.015], [64700.4, 0.392], [64700.6, 0.486], [64703.6, 0.12], [64706.0, 0.389], [64706.5, 0.041], [64706.8, 0.249], [64707.4, 1.594], [64708.7, 0.164], [64708.8, 1.371], [64709.2, 0.171], [64709.3, 2.751], [64709.7, 1.344], [64710.4, 0.009], [64710.8, 0.458], [64712.8, 2.823], [64713.9, 2.808], [64714.6, 0.556], [64716.9, 0.156], [64721.1, 0.374], [64728.8, 0.01], [64744.4, 0.396], [64768.0, 0.026], [64772.4, 47.367], [64830.3, 5.399], [64847.3, 10.436], [64886.1, 9.561], [65336.9, 0.001], [65628.0, 2.582], [65672.1, 0.76], [65983.7, 0.009]]}
{"kind": "depth", "E": 1787095353507, "U": 11316373325272, "u": 11316373338069, "recv_ms": 1787095353564, "bids": [[14189.9, 0.84], [14589.9, 3.36], [58220.9, 0.002], [61455.4, 0.006], [61455.5, 0.006], [63689.9, 0.03], [63964.3, 5.658], [64043.0, 0.032], [64676.3, 1.055], [64677.5, 0.461], [64678.1, 0.158], [64679.4, 0.012], [64683.0, 0.088], [64684.1, 0.0], [64685.5, 0.525], [64687.0, 0.002], [64687.5, 0.614], [64689.9, 5.87]], "asks": [[64690.0, 11.148], [64691.5, 0.232], [64691.8, 0.803], [64691.9, 0.326], [64692.0, 0.078], [64692.5, 0.053], [64692.6, 0.163], [64692.8, 0.058], [64692.9, 0.024], [64693.2, 0.307], [64693.5, 0.1], [64693.6, 0.119], [64693.7, 0.33], [64693.8, 0.446], [64693.9, 0.101], [64694.4, 0.114], [64694.5, 0.154], [64694.7, 1.604], [64697.6, 0.247], [64697.9, 0.003], [64699.6, 0.14], [64700.3, 0.002], [64700.6, 0.449], [64700.8, 2.369], [64707.5, 0.12], [64770.1, 47.373], [64772.4, 0.0], [64830.3, 3.469], [64847.3, 10.436], [64876.3, 0.11], [64886.1, 8.147], [65336.9, 0.001], [65478.1, 1.526], [65498.6, 2.283], [65611.4, 22.108], [65690.0, 0.433]]}
{"kind": "depth", "E": 1787095353609, "U": 11316373338354, "u": 11316373346652, "recv_ms": 1787095353668, "bids": [[1000.0, 35.76], [14189.9, 0.504], [14489.9, 0.014], [14589.9, 3.682], [51752.0, 0.0], [58220.9, 0.002], [62102.3, 0.144], [63913.6, 19.77], [64043.0, 0.032], [64156.1, 0.0], [64350.1, 0.155], [64366.5, 0.0], [64524.7, 0.0], [64528.1, 0.448], [64683.0, 0.088], [64684.1, 0.0], [64684.5, 0.012], [64685.5, 0.525], [64686.5, 0.006]], "asks": [[64691.5, 0.161], [64691.6, 0.213], [64691.7, 0.0], [64691.8, 0.803], [64692.9, 0.024], [64693.0, 0.507], [64693.1, 0.371], [64693.2, 0.307], [64693.5, 0.017], [64693.6, 0.779], [64693.7, 0.092], [64693.8, 0.208], [64693.9, 0.101], [64694.0, 0.241], [64694.1, 0.233], [64744.4, 0.387], [64765.6, 7.943], [64767.9, 47.367], [64770.1, 0.006], [64830.2, 2.018], [65336.9, 0.001], [65628.0, 3.647], [65888.5, 1.518]]}
{"kind": "depth", "E": 1787095353711, "U": 11316373346762, "u": 11316373355129, "recv_ms": 1787095353768, "bids": [[1000.0, 35.76], [14189.9, 0.294], [14489.9, 0.168], [14589.9, 3.738], [58220.9, 0.002], [61455.4, 0.006], [62102.3, 0.147], [63689.9, 0.01], [63816.6, 4.255], [63913.6, 24.457], [63984.8, 1.022], [64043.0, 0.032], [64172.4, 3.142], [64366.4, 1.176], [64546.6, 0.0], [64546.9, 0.015], [64547.1, 4.752], [64547.2, 4.472], [64620.0, 0.004], [64658.1, 2.004], [64667.0, 0.353], [64671.6, 0.712], [64675.3, 0.009], [64675.9, 0.005], [64679.0, 1.205], [64683.0, 0.088], [64684.0, 0.313], [64684.1, 0.0], [64685.5, 0.525], [64689.9, 5.872]], "asks": [[64690.0, 11.095], [64691.4, 0.018], [64691.5, 0.463], [64691.6, 0.22], [64691.8, 1.154], [64692.5, 0.043], [64692.9, 0.091], [64693.0, 0.424], [64693.1, 0.371], [64693.2, 0.307], [64693.5, 0.017], [64693.6, 0.541], [64693.7, 0.092], [64693.9, 0.101], [64702.5, 0.845], [64707.6, 0.062], [64709.9, 0.651], [64744.4, 0.387], [64765.6, 1.142], [64767.9, 0.0], [64770.1, 47.698], [64779.0, 0.603], [64830.2, 0.014], [64830.3, 4.098], [64847.3, 6.117], [64873.6, 0.001], [64873.7, 0.004], [64886.1, 1.651], [65013.5, 0.769], [65336.9, 0.001], [65690.0, 0.413]]}
{"kind": "depth", "E": 1787095353813, "U": 11316373355332, "u": 11316373361532, "recv_ms": 1787095353872, "bids": [[14189.9, 0.182], [14489.9, 0.406], [14589.9, 3.612], [58220.9, 0.002], [62102.3, 0.144], [64043.0, 0.032], [64568.5, 0.001], [64626.4, 0.0], [64626.7, 0.628], [64627.0, 0.163], [64627.3, 0.001], [64627.6, 0.0], [64644.1, 0.12], [64644.4, 0.311], [64644.7, 0.0], [64645.1, 0.007], [64645.4, 0.072], [64654.0, 0.047], [64655.6, 1.29], [64659.0, 0.097], [64659.1, 0.038], [64659.2, 0.012], [64659.3, 0.392], [64659.4, 0.003], [64659.5, 0.099], [64659.6, 0.165], [64659.7, 0.007], [64659.8, 0.007], [64660.0, 0.105], [64661.0, 0.0], [64661.4, 0.0], [64678.3, 0.021], [64678.4, 0.03], [64678.5, 0.583], [64678.6, 0.301], [64678.7, 0.324], [64678.8, 0.002], [64678.9, 0.965], [64679.0, 1.005], [64679.1, 0.101], [64679.2, 0.0], [64679.3, 2.33], [64679.5, 1.002], [64679.9, 0.002], [64680.2, 0.415], [64680.5, 0.218], [64680.8, 0.0], [64683.0, 0.087], [64683.3, 0.151], [64683.8, 0.004], [64684.1, 0.001], [64685.5, 0.079], [64687.8, 0.055], [64688.3, 0.054], [64689.9, 5.853]], "asks": [[64690.4, 0.087], [64691.4, 0.002], [64691.5, 0.007], [64691.8, 0.803], [64692.2, 0.088], [64692.5, 0.008], [64692.8, 0.02], [64692.9, 0.107], [64693.1, 0.329], [64693.4, 0.001], [64693.5, 0.255], [64693.7, 0.001], [64693.8, 0.088], [64693.9, 0.01], [64694.0, 0.001], [64694.1, 0.163], [64694.2, 0.245], [64694.3, 0.0], [64694.4, 0.044], [64694.5, 0.0], [64694.6, 0.233], [64694.7, 1.527], [64709.9, 0.619], [64710.2, 0.222], [64710.5, 0.001], [64710.8, 0.416], [64711.2, 0.451], [64711.6, 0.002], [64712.0, 1.393], [64713.0, 0.014], [64713.2, 0.234], [64713.3, 0.018], [64713.4, 0.262], [64713.5, 0.002], [64713.6, 0.705], [64713.7, 0.001], [64713.8, 0.079], [64713.9, 2.647], [64714.0, 0.036], [64727.6, 0.001], [64727.9, 0.679], [64728.3, 0.214], [64728.6, 0.005], [64728.9, 0.082], [64744.4, 0.387], [64767.9, 47.692], [64770.1, 0.006], [64847.3, 10.436], [64886.1, 8.078], [65336.9, 0.001]]}
{"kind": "depth", "E": 1787095353915, "U": 11316373361709, "u": 11316373366814, "recv_ms": 1787095353972, "bids": [[1000.0, 35.76], [14189.9, 0.056], [14489.9, 0.644], [14589.9, 3.5], [58220.9, 0.002], [61455.4, 0.006], [62102.3, 0.147], [63689.9, 0.03], [64043.0, 0.032], [64366.4, 1.177], [64366.5, 0.0], [64495.8, 0.001], [64528.1, 0.409], [64528.6, 0.039], [64634.6, 0.284], [64664.2, 0.015], [64670.0, 0.696], [64671.7, 1.257], [64672.6, 0.0], [64674.1, 0.56], [64677.1, 0.096], [64677.4, 0.006], [64678.4, 0.1], [64678.6, 0.371], [64678.7, 0.394], [64678.9, 1.165], [64679.1, 0.201], [64679.2, 0.07], [64679.4, 0.082], [64679.7, 0.239], [64682.2, 0.137], [64683.6, 0.004], [64684.1, 0.0], [64685.5, 0.079], [64687.3, 0.0], [64689.9, 5.855]], "asks": [[64691.4, 0.227], [64691.5, 0.54], [64692.8, 0.02], [64692.9, 0.448], [64693.0, 0.662], [64693.1, 0.329], [64693.2, 0.307], [64693.4, 0.001], [64693.5, 0.017], [64693.6, 0.0], [64693.8, 0.179], [64694.0, 0.33], [64694.1, 0.128], [64694.3, 0.26], [64694.5, 0.782], [64694.6, 0.303], [64694.8, 7.477], [64698.1, 0.382], [64698.9, 0.513], [64706.8, 0.249], [64708.7, 0.009], [64709.2, 0.326], [64709.7, 0.885], [64710.3, 0.46], [64712.0, 1.533], [64713.1, 0.159], [64713.2, 0.325], [64713.4, 0.382], [64713.6, 0.825], [64713.7, 0.071], [64713.9, 2.717], [64714.0, 0.113], [64716.9, 0.156], [64717.6, 0.155], [64719.2, 0.438], [64744.4, 0.396], [64886.1, 8.079], [65336.9, 0.001], [65690.0, 0.433]]}
{"kind": "depth", "E": 1787095354017, "U": 11316373366920, "u": 11316373372413, "recv_ms": 1787095354075, "bids": [[1000.0, 35.76], [14189.9, 0.0], [14489.9, 0.938], [14589.9, 3.262], [58220.9, 0.002], [61455.4, 0.006], [63396.2, 0.017], [63897.4, 47.437], [64043.0, 0.032], [64105.3, 0.157], [64528.1, 0.448], [64528.6, 0.0], [64632.9, 0.046], [64644.2, 0.05], [64644.6, 0.087], [64644.9, 0.033], [64645.5, 0.062], [64667.0, 0.352], [64670.8, 0.236], [64671.7, 1.141], [64673.3, 0.908], [64674.1, 0.003], [64676.9, 0.462], [64677.5, 0.002], [64678.5, 0.653], [64678.7, 0.464], [64678.8, 0.102], [64679.3, 2.43], [64679.7, 0.271], [64680.0, 0.163], [64680.3, 0.034], [64681.0, 0.036], [64683.3, 0.152], [64683.6, 0.003], [64684.0, 0.003], [64685.5, 0.079], [64685.6, 0.089], [64686.4, 0.003], [64689.9, 5.854]], "asks": [[64690.0, 11.096], [64691.4, 0.225], [64691.5, 0.232], [64691.9, 0.329], [64692.2, 0.12], [64692.8, 0.036], [64692.9, 0.367], [64693.0, 0.424], [64693.2, 0.468], [64693.5, 0.059], [64693.9, 0.13], [64694.0, 0.092], [64694.1, 0.128], [64694.4, 0.194], [64694.5, 0.85], [64694.7, 1.618], [64709.9, 0.651], [64710.6, 0.072], [64710.8, 0.402], [64710.9, 0.049], [64711.2, 0.493], [64711.6, 0.122], [64713.7, 0.221], [64713.8, 0.163], [64714.0, 0.204], [64717.6, 0.155], [64717.7, 6.044], [64727.7, 0.037], [64728.3, 0.252], [64728.6, 0.047], [64729.0, 0.088], [64732.9, 0.026], [64740.8, 1.34], [64767.9, 0.0], [64779.0, 48.295], [65013.5, 0.768], [65336.9, 0.001], [65542.8, 1.53], [66037.3, 0.0]]}
{"kind": "depth", "E": 1787095354119, "U": 11316373372579, "u": 11316373378426, "recv_ms": 1787095354176, "bids": [[14489.9, 1.302], [14589.9, 2.898], [58220.9, 0.002], [62102.3, 0.144], [63689.9, 0.01], [63706.1, 0.38], [63770.9, 0.0], [63772.1, 0.0], [63913.6, 25.159], [63950.8, 0.0], [64043.0, 0.032], [64366.5, 0.01], [64617.1, 0.001], [64645.2, 0.035], [64659.5, 0.059], [64666.3, 0.04], [64678.3, 0.021], [64679.2, 0.17], [64680.7, 0.135], [64685.5, 0.079]], "asks": [[64691.4, 0.0], [64691.6, 0.136], [64692.5, 0.053], [64692.8, 0.02], [64693.2, 0.468], [64693.9, 0.13], [64694.0, 0.212], [64694.1, 0.144], [64698.2, 2.537], [64710.3, 0.495], [64713.3, 0.138], [64717.6, 0.001], [64717.7, 6.044], [64717.8, 0.49], [64728.0, 1.872], [64744.4, 0.396], [64770.1, 47.698], [64779.0, 0.603], [65336.9, 0.001], [65484.8, 1.267], [65607.8, 0.066], [65609.1, 0.001], [65673.8, 0.027], [65690.0, 0.413]]}
{"kind": "depth", "E": 1787095354221, "U": 11316373378523, "u": 11316373384224, "recv_ms": 1787095354278, "bids": [[1000.0, 35.76], [14489.9, 1.652], [14589.9, 2.548], [58220.9, 0.002], [61455.4, 0.006], [62102.3, 0.147], [63706.1, 0.388], [63735.7, 14.888], [63770.9, 0.008], [63772.1, 0.008], [64043.0, 0.032], [64366.4, 1.178], [64491.0, 0.041], [64491.4, 7.154], [64529.9, 2.728], [64530.2, 4.29], [64547.1, 0.135], [64547.2, 7.348], [64617.0, 0.027], [64657.0, 0.003], [64657.1, 0.034], [64657.2, 0.062], [64659.4, 0.073], [64660.1, 0.083], [64660.5, 1.33], [64660.6, 0.026], [64679.0, 1.105], [64679.1, 0.271], [64685.5, 0.525]], "asks": [[64690.0, 11.097], [64691.5, 0.007], [64691.6, 0.117], [64691.7, 0.0], [64692.8, 0.02], [64692.9, 0.595], [64693.0, 0.662], [64693.2, 0.432], [64693.7, 0.001], [64693.9, 0.614], [64694.0, 0.45], [64694.1, 0.128], [64694.2, 0.445], [64694.5, 0.309], [64697.6, 0.246], [64713.4, 0.452], [64713.5, 0.132], [64717.8, 0.49], [64744.4, 0.387], [64886.1, 15.412], [65336.9, 0.001], [65461.5, 2.309], [65607.8, 0.074], [65609.1, 0.009], [65849.1, 0.0]]}
{"kind": "depth", "E": 1787095354323, "U": 11316373384321, "u": 11316373390004, "recv_ms": 1787095354379, "bids": [[1000.0, 35.76], [14489.9, 2.016], [14589.9, 2.184], [51751.9, 0.0], [51752.0, 0.0], [58220.9, 0.002], [61455.5, 0.004], [62086.6, 0.695], [62102.3, 0.144], [63689.9, 0.03], [64043.0, 0.032], [64491.3, 0.001], [64491.4, 12.205], [64491.5, 2.13], [64530.2, 6.693], [64547.2, 6.838], [64569.2, 0.076], [64626.5, 0.44], [64626.8, 0.032], [64627.2, 0.043], [64627.8, 2.314], [64659.2, 0.082], [64659.3, 0.462], [64659.5, 0.129], [64659.6, 0.265], [64659.8, 0.107], [64660.0, 0.175], [64661.1, 0.212], [64661.6, 0.128], [64685.5, 0.525], [64689.9, 5.855]], "asks": [[64690.0, 11.096], [64691.7, 0.0], [64691.9, 0.326], [64692.1, 0.017], [64692.2, 0.127], [64692.7, 0.095], [64692.8, 0.02], [64692.9, 0.595], [64693.0, 0.424], [64693.1, 0.416], [64693.2, 0.359], [64693.7, 0.001], [64693.8, 0.179], [64693.9, 0.13], [64694.0, 0.212], [64694.1, 0.128], [64697.6, 0.247], [64699.6, 0.14], [64707.4, 1.594], [64717.8, 0.49], [64744.4, 0.387], [64886.1, 8.595], [65336.9, 0.001], [65673.8, 0.035], [65690.0, 0.433]]}
{"kind": "depth", "E": 1787095354425, "U": 11316373390176, "u": 11316373396033, "recv_ms": 1787095354481, "bids": [[14489.9, 2.366], [14589.9, 1.834], [51752.0, 0.0], [58220.9, 0.002], [61455.4, 0.006], [63751.9, 5.474], [64043.0, 0.032], [64366.5, 0.0], [64547.2, 6.507], [64625.2, 0.02], [64627.5, 0.342], [64659.2, 0.152], [64659.4, 0.143], [64659.5, 0.229], [64664.2, 0.015], [64673.5, 3.817], [64677.1, 0.096], [64677.4, 0.006], [64679.7, 0.271], [64682.2, 0.137], [64683.0, 0.088], [64683.3, 0.151], [64684.1, 0.0], [64685.5, 0.525], [64689.9, 5.854]], "asks": [[64690.0, 11.096], [64691.7, 0.225], [64692.7, 0.087], [64692.9, 0.595], [64693.0, 0.424], [64693.1, 0.416], [64693.2, 0.359], [64693.7, 0.001], [64693.8, 0.572], [64693.9, 0.376], [64694.0, 0.212], [64694.1, 0.128], [64694.2, 0.445], [64694.5, 0.154], [64697.6, 0.247], [64698.1, 0.382], [64698.9, 0.513], [64700.8, 2.328], [64706.0, 0.389], [64706.8, 0.249], [64709.2, 0.326], [64716.9, 0.156], [64717.8, 0.336], [64717.9, 0.0], [64718.0, 0.25], [64744.4, 0.387], [64754.7, 6.989], [64767.9, 47.692], [64770.1, 0.006], [64830.3, 5.399], [64886.1, 9.494], [65336.9, 0.001], [65466.3, 9.377]]}
{"kind": "depth", "E": 1787095354527, "U": 11316373396361, "u": 11316373415146, "recv_ms": 1787095354584, "bids": [[1000.0, 35.76], [14489.9, 2.73], [14589.9, 1.47], [58220.9, 0.002], [61455.4, 0.008], [62102.3, 0.147], [63396.2, 0.02], [63689.9, 0.01], [64043.0, 0.032], [64393.3, 0.001], [64579.9, 0.0], [64625.1, 6.267], [64625.2, 0.002], [64625.7, 1.687], [64627.3, 33.747], [64629.6, 6.113], [64631.6, 1.24], [64659.9, 0.1], [64679.0, 0.487], [64682.7, 0.085], [64683.0, 0.088], [64683.8, 0.004], [64685.3, 0.551], [64685.5, 0.079], [64685.9, 0.004], [64686.5, 0.005], [64686.9, 0.009], [64689.9, 5.886]], "asks": [[64690.0, 11.125], [64691.5, 0.007], [64691.6, 0.136], [64691.7, 0.0], [64691.8, 0.766], [64692.9, 0.595], [64693.0, 0.507], [64693.1, 0.333], [64693.2, 0.359], [64693.7, 0.239], [64693.8, 0.334], [64693.9, 0.138], [64694.1, 0.128], [64696.5, 0.039], [64699.6, 0.14], [64707.4, 1.594], [64717.9, 0.154], [64718.0, 0.096], [64735.3, 0.005], [64744.4, 0.387], [65336.9, 0.001], [65443.2, 0.916], [65690.0, 0.413], [65775.8, 0.0]]}
{"kind": "depth", "E": 1787095354629, "U": 11316373415545, "u": 11316373430396, "recv_ms": 1787095354692, "bids": [[1000.0, 35.76], [14489.9, 3.08], [14589.9, 1.12], [51752.0, 0.0], [58220.9, 0.002], [62102.3, 0.144], [63865.1, 18.014], [64043.0, 0.034], [64054.8, 7.765], [64620.7, 0.028], [64625.1, 40.013], [64625.2, 0.02], [64627.3, 0.001], [64629.6, 1.17], [64659.7, 0.107], [64659.8, 0.177], [64664.2, 0.015], [64677.1, 0.096], [64677.4, 0.006], [64678.9, 1.172], [64679.4, 0.075], [64679.7, 0.271], [64682.2, 0.137], [64682.3, 0.201], [64683.2, 0.001], [64685.5, 0.079], [64685.6, 0.005]], "asks": [[64691.6, 0.002], [64691.7, 0.0], [64692.6, 0.273], [64692.8, 0.028], [64692.9, 0.375], [64693.0, 0.424], [64693.2, 0.246], [64693.7, 0.001], [64693.8, 0.179], [64693.9, 0.671], [64694.0, 0.367], [64694.1, 0.128], [64698.1, 0.382], [64698.9, 0.513], [64706.8, 0.249], [64708.4, 0.467], [64709.2, 0.944], [64711.0, 3.874], [64716.9, 0.156], [64717.9, 0.154], [64718.0, 0.096], [64744.4, 0.387], [64765.6, 1.142], [64767.6, 0.706], [64767.9, 0.0], [64768.5, 2.391], [64779.0, 48.295], [64785.7, 0.444], [64830.2, 2.306], [64847.3, 10.436], [64876.3, 0.0], [64886.1, 8.965], [65336.9, 0.001]]}
{"kind": "depth", "E": 1787095354731, "U": 11316373430455, "u": 11316373442333, "recv_ms": 1787095354790, "bids": [[14489.9, 3.444], [14589.9, 0.756], [58220.9, 0.002], [62102.3, 0.147], [63689.9, 0.03], [64043.0, 0.032], [64366.5, 0.01], [64645.5, 0.06], [64671.5, 0.02], [64683.2, 0.001], [64685.6, 0.089], [64686.1, 0.0], [64686.7, 0.007]], "asks": [[64691.6, 0.121], [64691.7, 0.0], [64692.8, 0.028], [64692.9, 0.367], [64693.0, 0.662], [64693.2, 0.26], [64693.7, 0.001], [64693.8, 0.425], [64698.1, 0.298], [64706.5, 0.001], [64707.2, 0.05], [64717.8, 0.336], [64717.9, 0.154], [64767.5, 0.141], [64767.6, 0.802], [64767.9, 48.066], [64779.0, 0.603], [64798.4, 0.6], [65336.9, 0.001], [65459.8, 2.75], [65690.0, 0.433], [65789.7, 5.917], [66307.2, 1.581]]}
{"kind": "depth", "E": 1787095354833, "U": 11316373442808, "u": 11316373454472, "recv_ms": 1787095354890, "bids": [[1000.0, 35.76], [14389.9, 0.042], [14489.9, 3.71], [14589.9, 0.448], [51752.0, 0.0], [58220.9, 0.002], [61455.4, 0.008], [62102.3, 0.144], [64043.0, 0.032], [64366.4, 1.177], [64579.9, 0.003], [64625.1, 6.267], [64627.3, 33.228], [64647.5, 0.03], [64660.4, 4.902], [64664.2, 0.17], [64677.1, 0.251], [64677.4, 0.161], [64678.1, 0.776], [64679.7, 0.426], [64682.2, 0.292], [64685.5, 0.68], [64689.9, 5.887]], "asks": [[64690.0, 11.035], [64691.6, 0.002], [64691.7, 0.225], [64692.8, 0.02], [64692.9, 0.054], [64693.0, 0.424], [64693.2, 0.256], [64693.5, 0.142], [64693.7, 0.239], [64693.8, 0.428], [64693.9, 0.671], [64694.0, 0.212], [64694.1, 0.128], [64698.1, 0.227], [64698.9, 0.358], [64706.8, 0.094], [64709.2, 0.789], [64716.9, 0.001], [64717.9, 0.0], [64767.6, 0.725], [64767.7, 0.003], [64792.6, 0.0], [64884.1, 0.003], [65277.2, 0.0], [65336.9, 0.001], [65449.7, 26.355], [65482.0, 17.065]]}
{"kind": "depth", "E": 1787095354935, "U": 11316373454504, "u": 11316373468170, "recv_ms": 1787095354994, "bids": [[1000.0, 35.76], [14389.9, 0.224], [14489.9, 3.71], [14589.9, 0.266], [58220.9, 0.002], [61455.4, 0.009], [63396.2, 0.017], [63689.9, 0.01], [64043.0, 0.032], [64075.3, 5.281], [64547.2, 2.32], [64547.3, 4.43], [64582.6, 0.775], [64582.7, 1.24], [64622.1, 0.0], [64622.6, 0.377], [64627.3, 33.23], [64627.4, 0.007], [64632.9, 0.018], [64664.2, 0.17], [64671.6, 0.094], [64677.0, 2.649], [64677.1, 0.251], [64677.4, 0.161], [64678.1, 0.158], [64678.7, 0.155], [64678.9, 1.165], [64679.7, 0.426], [64680.1, 0.011], [64680.8, 0.309], [64682.2, 1.529], [64682.3, 0.117], [64682.4, 0.0], [64683.0, 0.087], [64683.2, 0.001], [64684.4, 0.001], [64685.0, 0.478], [64685.1, 0.001], [64685.3, 0.55], [64685.5, 0.327], [64685.9, 0.002], [64686.7, 0.004], [64687.3, 0.003], [64687.5, 0.698], [64687.8, 0.365], [64688.3, 0.138], [64688.4, 0.023], [64688.9, 0.005], [64689.0, 0.002], [64689.1, 0.0], [64689.8, 0.039], [64689.9, 8.284]], "asks": [[64690.0, 8.959], [64690.4, 0.003], [64690.8, 0.003], [64690.9, 0.006], [64691.0, 0.027], [64691.4, 0.084], [64691.5, 0.315], [64691.6, 0.117], [64691.7, 0.225], [64692.0, 0.085], [64692.5, 0.039], [64692.6, 0.163], [64692.9, 0.419], [64693.0, 0.005], [64693.1, 0.34], [64693.2, 0.33], [64693.5, 0.142], [64693.6, 0.0], [64693.7, 0.001], [64693.8, 0.18], [64693.9, 0.671], [64694.7, 1.527], [64697.4, 0.14], [64697.9, 0.019], [64698.1, 0.304], [64698.4, 0.005], [64698.9, 0.049], [64699.6, 0.06], [64700.1, 1.311], [64700.9, 1.502], [64702.5, 0.227], [64706.8, 0.094], [64707.4, 1.674], [64708.7, 0.009], [64709.9, 0.033], [64710.7, 0.031], [64710.8, 0.416], [64711.0, 3.876], [64712.4, 0.39], [64712.5, 0.063], [64712.8, 2.819], [64713.0, 0.002], [64715.0, 0.085], [64716.4, 0.483], [64716.9, 0.001], [64717.9, 0.154], [64744.4, 0.387], [64767.5, 0.064], [64767.6, 0.648], [64767.9, 0.0], [64772.4, 0.0], [64774.5, 53.873], [64798.4, 0.593], [64830.3, 5.399], [64847.3, 6.084], [64886.1, 8.865], [65013.5, 0.769], [65336.9, 0.005], [65690.0, 0.413]]}
{"kind": "depth", "E": 1787095355037, "U": 11316373468222, "u": 11316373478268, "recv_ms": 1787095355094, "bids": [[14389.9, 0.462], [14489.9, 3.584], [14589.9, 0.154], [58220.9, 0.002], [61455.4, 0.007], [61455.5, 0.006], [62102.3, 0.147], [63676.4, 7.216], [64043.0, 0.032], [64366.5, 0.01], [64592.7, 3.913], [64619.4, 0.0], [64619.6, 2.091], [64620.7, 33.255], [64627.3, 0.003], [64627.7, 0.0], [64627.8, 0.343], [64628.0, 1.973], [64632.9, 0.027], [64636.2, 0.382], [64636.3, 0.142], [64664.2, 0.015], [64677.1, 0.096], [64677.4, 0.006], [64678.3, 0.026], [64679.6, 0.562], [64679.7, 0.271], [64680.1, 0.004], [64682.2, 1.374], [64682.3, 0.21], [64684.2, 0.884], [64684.8, 0.015], [64685.0, 0.168], [64685.1, 0.232], [64685.5, 0.079], [64686.8, 0.735], [64687.0, 0.006], [64687.3, 0.0], [64687.5, 0.382], [64687.8, 0.365], [64688.3, 0.054], [64688.4, 0.001], [64688.9, 0.002], [64689.8, 0.038], [64689.9, 6.874]], "asks": [[64690.0, 9.097], [64690.2, 0.086], [64690.6, 0.086], [64691.1, 0.084], [64691.5, 0.007], [64691.6, 0.136], [64691.7, 0.225], [64691.8, 1.287], [64692.8, 0.02], [64692.9, 0.054], [64693.0, 0.481], [64693.1, 0.816], [64693.2, 0.587], [64693.5, 0.059], [64693.7, 0.239], [64693.8, 0.426], [64693.9, 0.671], [64694.1, 0.128], [64694.2, 0.445], [64694.3, 0.26], [64694.7, 1.443], [64695.4, 0.004], [64697.8, 0.113], [64698.2, 2.536], [64698.8, 0.007], [64698.9, 0.359], [64699.6, 0.14], [64703.1, 0.005], [64703.3, 1.636], [64706.8, 0.249], [64707.4, 1.594], [64708.7, 0.164], [64711.5, 0.031], [64711.6, 2.094], [64712.9, 0.115], [64713.5, 0.595], [64716.9, 0.156], [64717.9, 0.0], [64718.0, 0.25], [64719.9, 0.002], [64720.0, 2.538], [64767.6, 0.629], [64770.1, 48.072], [64774.5, 5.807], [64847.3, 10.436], [64876.3, 0.11], [64886.1, 8.9], [65298.1, 0.614], [65336.9, 0.001], [65466.3, 11.206], [65983.7, 0.012]]}
{"kind": "depth", "E": 1787095355139, "U": 11316373478331, "u": 11316373488897, "recv_ms": 1787095355198, "bids": [[1000.0, 35.76], [14389.9, 0.7], [14489.9, 3.472], [14589.9, 0.028], [51752.0, 0.0], [58220.9, 0.002], [61455.4, 0.006], [62102.3, 0.144], [63547.0, 3.774], [63689.9, 0.03], [63706.1, 0.378], [63950.5, 4.693], [64043.0, 0.032], [64582.7, 1.237], [64582.8, 0.003], [64620.7, 0.028], [64622.6, 0.404], [64625.1, 39.494], [64645.7, 0.0], [64678.3, 0.021], [64679.1, 0.269], [64682.7, 0.001], [64684.1, 0.31], [64685.5, 0.017], [64685.6, 0.151], [64685.9, 0.003], [64686.7, 0.007], [64687.0, 0.002], [64687.3, 0.31], [64687.6, 0.003], [64687.8, 0.055], [64688.0, 0.004], [64689.9, 5.938]], "asks": [[64690.0, 9.156], [64690.1, 0.096], [64690.2, 0.002], [64690.6, 0.002], [64690.7, 0.085], [64691.5, 0.007], [64691.6, 0.117], [64691.7, 0.225], [64691.8, 0.766], [64692.8, 0.028], [64692.9, 0.046], [64693.0, 0.013], [64693.1, 0.34], [64693.2, 0.349], [64693.7, 0.239], [64693.8, 0.418], [64693.9, 0.909], [64694.2, 0.802], [64696.5, 0.002], [64698.1, 0.285], [64698.7, 0.248], [64699.6, 0.06], [64703.2, 0.134], [64703.5, 0.086], [64706.2, 0.141], [64707.6, 0.268], [64711.7, 0.016], [64711.8, 0.323], [64712.9, 10.115], [64713.1, 0.207], [64718.0, 0.096], [64718.1, 0.005], [64744.4, 0.396], [64767.5, 0.064], [64767.6, 0.629], [64767.9, 48.066], [64769.2, 0.019], [64770.1, 0.006], [64873.7, 0.001], [64873.9, 0.008], [65336.9, 0.154], [65526.6, 0.763], [65634.5, 0.382], [65673.8, 0.025], [65690.0, 0.433], [65711.0, 5.271], [65983.7, 0.015], [67277.5, 0.015]]}
{"kind": "depth", "E": 1787095355241, "U": 11316373489014, "u": 11316373505212, "recv_ms": 1787095355298, "bids": [[1000.0, 35.76], [14389.9, 1.022], [14489.9, 3.178], [14589.9, 0.0], [51752.0, 0.004], [58220.9, 0.002], [61442.2, 0.018], [61455.4, 0.006], [62102.3, 0.147], [63706.1, 0.388], [64043.0, 0.032], [64366.4, 1.176], [64524.7, 0.039], [64528.1, 0.409], [64664.2, 0.015], [64677.1, 0.096], [64677.4, 0.006], [64679.7, 0.271], [64682.3, 0.117], [64682.7, 0.085], [64683.6, 0.004], [64684.2, 0.883], [64684.3, 0.091], [64684.4, 0.542], [64685.3, 0.643], [64685.5, 0.017], [64685.9, 0.087], [64686.3, 0.084], [64686.8, 0.902], [64689.9, 6.87]], "asks": [[64691.7, 0.225], [64692.8, 0.02], [64693.0, 0.005], [64693.1, 0.578], [64693.2, 0.468], [64693.6, 0.476], [64693.7, 0.731], [64693.8, 0.656], [64693.9, 0.671], [64694.1, 0.247], [64694.2, 0.445], [64698.1, 0.44], [64698.9, 0.204], [64699.0, 1.154], [64706.8, 0.094], [64708.7, 0.164], [64712.7, 0.289], [64715.1, 0.362], [64715.6, 2.398], [64716.3, 0.002], [64716.9, 0.001], [64718.1, 0.005], [64718.2, 0.02], [64718.3, 0.579], [64767.9, 0.0], [64779.0, 48.669], [64800.0, 21.198], [65336.9, 0.154], [65673.7, 0.029]]}
{"kind": "depth", "E": 1787095355343, "U": 11316373505539, "u": 11316373515317, "recv_ms": 1787095355400, "bids": [[14389.9, 1.386], [14489.9, 2.814], [51751.9, 0.0], [51752.0, 0.0], [58220.9, 0.002], [62102.3, 0.144], [63666.5, 0.0], [63687.2, 4.0], [63689.9, 0.01], [63755.1, 3.055], [64043.0, 0.032], [64366.5, 0.01], [64645.7, 0.1], [64682.3, 0.21], [64683.6, 0.003], [64684.3, 0.092], [64685.3, 0.55], [64685.5, 0.017]], "asks": [[64691.4, 0.085], [64691.7, 0.0], [64693.1, 0.34], [64693.2, 0.349], [64693.6, 0.238], [64693.7, 0.255], [64693.8, 0.418], [64693.9, 0.671], [64694.1, 0.128], [64718.3, 0.425], [64767.9, 48.066], [64770.1, 0.006], [64779.0, 0.603], [65013.5, 0.77], [65336.9, 0.154], [65482.0, 16.836], [65526.2, 2.287], [65690.0, 0.413], [65725.0, 3.257], [65899.7, 0.909]]}
{"kind": "depth", "E": 1787095355445, "U": 11316373515537, "u": 11316373521534, "recv_ms": 1787095355502, "bids": [[1000.0, 35.76], [14389.9, 1.736], [14489.9, 2.464], [58220.9, 0.002], [61455.4, 0.006], [63557.8, 2.514], [63735.7, 13.791], [63763.8, 20.36], [63903.9, 0.0], [64043.0, 0.032], [64524.7, 0.0], [64528.1, 0.448], [64530.2, 0.0], [64530.3, 6.097], [64547.3, 3.97], [64657.0, 0.005], [64657.1, 0.036], [64657.2, 0.064], [64660.5, 1.332], [64660.6, 0.028], [64660.7, 0.008], [64664.2, 0.015], [64667.5, 0.018], [64673.5, 3.817], [64677.1, 0.096], [64677.4, 0.006], [64679.7, 0.271], [64682.3, 0.21], [64683.1, 0.628], [64685.5, 0.017], [64685.6, 0.151], [64685.9, 0.089], [64689.9, 6.871]], "asks": [[64690.0, 9.251], [64691.6, 0.04], [64691.7, 0.0], [64693.5, 0.571], [64693.6, 0.0], [64693.7, 0.1], [64693.8, 0.18], [64693.9, 0.79], [64698.1, 0.44], [64698.9, 0.204], [64699.0, 1.154], [64706.0, 0.389], [64706.7, 0.021], [64708.6, 0.006], [64708.7, 0.164], [64712.0, 1.533], [64712.7, 0.289], [64713.8, 0.719], [64714.6, 0.0], [64718.1, 0.005], [64718.2, 0.174], [64721.7, 0.22], [64728.9, 0.002], [64830.2, 0.014], [64830.3, 5.399], [64847.3, 10.436], [64886.1, 10.597], [65336.9, 0.154], [65452.3, 11.091]]}
{"kind": "depth", "E": 1787095355547, "U": 11316373521693, "u": 11316373526849, "recv_ms": 1787095355606, "bids": [[1000.0, 35.76], [14389.9, 2.1], [14489.9, 2.1], [58220.9, 0.002], [62102.3, 0.147], [63689.9, 0.03], [64043.0, 0.032], [64677.4, 0.003], [64680.7, 0.138], [64682.7, 0.001], [64685.5, 0.463], [64686.7, 0.091]], "asks": [[64691.7, 0.0], [64693.1, 0.459], [64693.5, 0.214], [64693.8, 0.656], [64693.9, 1.028], [64694.1, 0.128], [64694.2, 0.445], [64698.1, 0.459], [64718.2, 0.02], [65336.9, 0.154], [65614.0, 5.287], [65690.0, 0.433]]}
{"kind": "depth", "E": 1787095355649, "U": 11316373526965, "u": 11316373532475, "recv_ms": 1787095355706, "bids": [[14389.9, 2.464], [14489.9, 1.736], [51752.0, 0.0], [58220.9, 0.002], [61455.4, 0.004], [61455.5, 0.008], [62102.3, 0.144], [63465.9, 0.014], [63751.9, 6.571], [63784.2, 0.552], [63920.1, 3.749], [64043.0, 0.032], [64366.5, 0.01], [64524.7, 0.039], [64528.1, 0.409], [64546.6, 1.435], [64547.3, 0.015], [64625.7, 6.428], [64627.1, 0.097], [64627.5, 2.948], [64667.5, 0.016], [64683.4, 0.09], [64685.5, 0.463], [64685.6, 0.089], [64685.7, 0.07], [64689.9, 6.871]], "asks": [[64691.6, 0.002], [64691.7, 0.225], [64693.1, 0.34], [64693.2, 0.265], [64693.7, 0.1], [64693.8, 0.418], [64693.9, 1.028], [64694.2, 0.802], [64718.1, 0.005], [64718.2, 0.02], [64718.3, 0.579], [64752.6, 3.025], [64765.6, 8.048], [64767.9, 0.0], [64772.4, 48.066], [64830.2, 2.306], [64830.3, 0.0], [64886.1, 9.765], [65336.9, 0.154], [65466.3, 11.968], [65549.4, 1.618], [65584.5, 32.913], [65983.7, 0.012]]}
{"kind": "depth", "E": 1787095355751, "U": 11316373532496, "u": 11316373542055, "recv_ms": 1787095355809, "bids": [[1000.0, 35.76], [14389.9, 2.814], [14489.9, 1.386], [51752.0, 0.0], [58220.9, 0.002], [61455.4, 0.004], [62102.3, 0.147], [63689.9, 0.01], [64043.0, 0.032], [64547.3, 4.429], [64579.9, 0.003], [64631.6, 1.237], [64664.2, 0.015], [64670.3, 0.002], [64670.8, 0.12], [64671.2, 0.119], [64672.6, 0.0], [64673.3, 0.351], [64673.7, 0.89], [64677.1, 0.096], [64677.4, 0.003], [64679.7, 0.271], [64682.3, 0.21], [64683.0, 0.003], [64683.2, 0.001], [64684.3, 0.633], [64684.4, 0.001], [64685.5, 0.463], [64685.6, 0.089], [64685.7, 0.008], [64686.7, 0.153], [64687.1, 0.097], [64689.9, 6.868]], "asks": [[64691.7, 0.0], [64691.8, 0.766], [64693.2, 0.349], [64693.5, 0.059], [64693.7, 0.374], [64693.8, 0.537], [64693.9, 0.909], [64694.2, 0.445], [64698.1, 0.459], [64698.9, 0.204], [64699.0, 1.154], [64708.7, 0.164], [64708.9, 0.003], [64709.8, 0.787], [64710.3, 0.036], [64712.7, 0.289], [64718.3, 0.425], [64735.3, 0.005], [64765.6, 1.142], [64767.7, 0.0], [64767.9, 48.18], [64770.1, 0.006], [64772.4, 0.0], [64800.0, 21.195], [64830.3, 5.399], [64886.1, 8.905], [65336.9, 0.154], [65595.7, 7.501], [65614.0, 4.221], [65678.7, 3.045], [65690.0, 0.413], [66048.5, 1.285]]}
{"kind": "depth", "E": 1787095355853, "U": 11316373542482, "u": 11316373559044, "recv_ms": 1787095355910, "bids": [[1000.0, 35.76], [14389.9, 3.164], [14489.9, 1.036], [58220.9, 0.002], [61442.2, 0.012], [63966.5, 0.796], [64043.0, 0.034], [64524.7, 0.0], [64528.3, 0.041], [64653.9, 1.618], [64685.5, 0.017], [64687.4, 0.447]], "asks": [[64690.1, 0.012], [64691.7, 0.0], [64693.2, 0.169], [64693.6, 0.0], [64693.7, 0.172], [64693.8, 0.18], [64693.9, 0.671], [64694.5, 0.237], [64718.4, 1.509], [64767.6, 0.732], [64830.3, 4.016], [64847.3, 5.971], [64886.1, 1.675], [65498.6, 2.541], [65628.0, 4.712]]}
{"kind": "depth", "E": 1787095355955, "U": 11316373559070, "u": 11316373565470, "recv_ms": 1787095356012, "bids": [[14389.9, 3.528], [14489.9, 0.672], [58220.9, 0.002], [61455.4, 0.004], [62102.3, 0.144], [63396.2, 0.014], [63689.9, 0.03], [64043.0, 0.032], [64172.4, 3.146], [64366.5, 0.0], [64644.0, 0.384], [64670.7, 0.62], [64678.1, 0.776], [64685.4, 1.555], [64685.5, 0.463], [64686.7, 0.091], [64686.9, 0.071], [64687.4, 0.001], [64689.9, 6.869]], "asks": [[64691.7, 0.0], [64693.0, 0.005], [64693.2, 0.349], [64693.8, 0.418], [64693.9, 0.909], [64694.0, 0.295], [64694.1, 0.128], [64694.2, 0.445], [64694.4, 0.194], [64694.5, 0.154], [64701.6, 0.618], [64709.0, 0.629], [64712.1, 0.068], [64712.2, 0.12], [64718.4, 1.355], [64744.4, 0.387], [64767.6, 0.713], [64830.3, 5.399], [64847.3, 10.436], [64886.1, 8.906], [65013.5, 0.769], [65336.9, 0.154], [65443.2, 0.0], [65478.1, 2.289], [65690.0, 0.433], [65865.6, 0.65]]}
{"kind": "depth", "E": 1787095356057, "U": 11316373565623, "u": 11316373578616, "recv_ms": 1787095356114, "bids": [[1000.0, 35.76], [14289.9, 0.07], [14389.9, 3.738], [14489.9, 0.392], [58220.9, 0.002], [61455.4, 0.006], [62102.3, 0.147], [63061.9, 1.664], [63741.1, 8.945], [64043.0, 0.032], [64172.4, 3.142], [64366.4, 1.177], [64650.5, 0.007], [64653.1, 8.118], [64655.6, 2.321], [64658.1, 0.004], [64664.2, 0.015], [64670.7, 0.002], [64670.8, 0.236], [64671.2, 0.003], [64671.5, 0.019], [64673.3, 0.908], [64673.7, 0.333], [64677.1, 0.096], [64677.4, 0.003], [64678.1, 0.158], [64678.3, 0.021], [64679.7, 0.271], [64680.2, 0.724], [64680.8, 0.0], [64682.3, 0.21], [64683.0, 0.088], [64684.0, 0.003], [64684.1, 0.0], [64684.3, 0.632], [64684.6, 0.236], [64685.1, 0.0], [64685.5, 0.079], [64686.3, 0.003], [64686.5, 0.005], [64686.7, 0.004], [64686.9, 0.009], [64687.1, 0.013], [64687.2, 0.004], [64687.3, 0.0], [64689.8, 0.006], [64689.9, 5.761]], "asks": [[64690.0, 9.497], [64690.3, 0.095], [64691.7, 0.0], [64692.9, 0.465], [64693.0, 0.546], [64693.2, 0.349], [64693.6, 0.238], [64693.7, 0.648], [64693.8, 0.263], [64693.9, 0.258], [64694.0, 0.212], [64694.6, 0.306], [64694.7, 1.536], [64697.9, 0.003], [64698.1, 0.382], [64698.7, 0.002], [64698.9, 0.204], [64699.0, 1.154], [64701.6, 0.0], [64702.1, 0.721], [64703.2, 0.006], [64706.2, 0.256], [64707.6, 0.01], [64708.7, 4.164], [64711.0, 2.799], [64712.0, 1.686], [64712.7, 0.289], [64712.9, 0.115], [64713.1, 0.092], [64718.7, 2.323], [64718.8, 0.455], [64744.4, 0.396], [64767.6, 0.629], [65336.9, 0.001], [65628.0, 5.777], [65692.7, 3.799], [65983.7, 0.009]]}
{"kind": "depth", "E": 1787095356159, "U": 11316373578941, "u": 11316373586655, "recv_ms": 1787095356216, "bids": [[1000.0, 35.76], [14289.9, 0.28], [14389.9, 3.682], [14489.9, 0.238], [51752.0, 0.03], [58220.9, 0.002], [61455.4, 0.006], [62102.3, 0.144], [63689.9, 0.01], [64043.0, 0.032], [64685.5, 0.079], [64686.9, 0.009], [64689.9, 5.762]], "asks": [[64692.8, 0.028], [64693.0, 0.005], [64693.1, 0.263], [64693.2, 0.246], [64693.5, 0.6], [64693.6, 0.0], [64693.7, 0.164], [64694.7, 1.443], [64697.8, 0.112], [64697.9, 0.096], [64698.1, 0.382], [64699.0, 0.254], [64699.5, 0.003], [64711.0, 3.979], [64713.0, 10.002], [64744.4, 0.387], [64767.5, 0.218], [64767.6, 0.847], [65336.9, 0.001], [65459.8, 3.666], [65526.6, 0.001], [65690.0, 0.413]]}
{"kind": "depth", "E": 1787095356261, "U": 11316373586658, "u": 11316373595491, "recv_ms": 1787095356318, "bids": [[14289.9, 0.532], [14389.9, 3.542], [14489.9, 0.126], [51752.0, 0.006], [58220.9, 0.002], [62086.6, 0.694], [62102.3, 0.147], [63569.8, 7.226], [63751.9, 7.668], [63961.5, 0.0], [63973.7, 0.983], [64043.0, 0.032], [64366.5, 0.01], [64653.1, 0.118], [64655.6, 1.29], [64656.9, 2.73], [64685.5, 0.525], [64689.9, 5.76]], "asks": [[64690.0, 9.498], [64691.7, 0.0], [64691.8, 0.769], [64693.1, 0.186], [64693.2, 0.131], [64693.6, 0.0], [64693.7, 0.247], [64693.8, 0.18], [64694.1, 0.126], [64694.7, 1.443], [64697.6, 0.247], [64697.9, 0.096], [64698.1, 0.279], [64705.0, 0.908], [64711.0, 2.799], [64711.7, 0.028], [64713.0, 0.002], [64715.0, 0.073], [64744.4, 0.396], [65336.9, 0.001], [65452.3, 9.871], [65484.8, 1.038]]}
{"kind": "depth", "E": 1787095356363, "U": 11316373595582, "u": 11316373609020, "recv_ms": 1787095356421, "bids": [[1000.0, 35.76], [14289.9, 0.756], [14389.9, 3.444], [14489.9, 0.0], [51751.9, 0.0], [51752.0, 0.0], [58220.9, 0.002], [61455.4, 0.006], [63689.9, 0.03], [64043.0, 0.032], [64366.4, 1.178], [64574.7, 5.129], [64575.4, 0.0], [64581.9, 0.0], [64582.3, 2.32], [64582.8, 0.0], [64583.0, 0.003], [64619.0, 0.059], [64619.7, 0.001], [64632.9, 0.041], [64654.6, 8.035], [64656.9, 0.73], [64664.2, 0.015], [64677.1, 0.096], [64677.4, 0.003], [64679.1, 0.276], [64679.6, 0.555], [64679.7, 0.271], [64681.9, 0.903], [64682.2, 1.375], [64682.3, 0.294], [64682.7, 0.085], [64683.0, 0.087], [64684.7, 0.084], [64685.2, 2.442], [64685.5, 0.525], [64685.6, 0.005], [64685.9, 0.005], [64689.9, 5.127]], "asks": [[64690.0, 9.5], [64691.7, 0.017], [64691.8, 0.769], [64692.5, 0.049], [64692.6, 0.273], [64692.8, 0.02], [64693.0, 0.004], [64693.1, 0.34], [64693.2, 0.265], [64693.7, 0.084], [64693.9, 0.496], [64694.0, 0.212], [64694.1, 0.281], [64694.7, 1.536], [64697.8, 0.111], [64697.9, 0.003], [64698.1, 0.227], [64698.9, 0.049], [64699.0, 0.564], [64708.6, 0.161], [64708.7, 4.009], [64709.0, 0.629], [64710.8, 0.402], [64712.7, 0.134], [64716.9, 0.156], [64721.1, 0.318], [64744.4, 0.405], [64757.3, 0.001], [64761.4, 2.691], [64767.5, 0.064], [64767.6, 0.636], [64795.7, 0.0], [64796.1, 2.321], [64825.6, 4.36], [64825.7, 2.527], [64826.9, 0.0], [64873.9, 0.005], [64874.0, 0.018], [64876.3, 0.0], [65013.5, 0.768], [65336.9, 0.001], [65461.6, 0.0], [65690.0, 0.433]]}
{"kind": "depth", "E": 1787095356465, "U": 11316373609278, "u": 11316373619307, "recv_ms": 1787095356521, "bids": [[1000.0, 35.76], [14289.9, 1.12], [14389.9, 3.08], [58220.9, 0.002], [61455.4, 0.004], [61455.5, 0.01], [62102.3, 0.144], [63881.3, 2.579], [64043.0, 0.033], [64673.5, 3.817], [64677.9, 0.018], [64679.1, 0.257], [64685.5, 0.079], [64686.0, 0.006], [64686.3, 0.0], [64689.9, 5.127]], "asks": [[64691.7, 0.017], [64691.9, 0.333], [64692.5, 0.049], [64692.8, 0.02], [64693.1, 0.333], [64693.2, 0.342], [64693.4, 0.239], [64693.8, 0.18], [64693.9, 0.258], [64700.9, 3.779], [64701.2, 0.001], [64703.0, 0.933], [64705.0, 0.008], [64706.0, 0.389], [64712.5, 0.065], [65283.7, 10.267], [65336.9, 0.001], [65611.4, 21.043], [65983.7, 0.012]]}
{"kind": "depth", "E": 1787095356669, "U": 11316373630332, "u": 11316373641673, "recv_ms": 1787095356726, "bids": [[1000.0, 35.76], [14289.9, 1.82], [14389.9, 2.38], [51752.0, 0.0], [58220.9, 0.002], [61442.2, 0.006], [61455.4, 0.004], [61455.5, 0.008], [62102.3, 0.144], [63738.3, 7.935], [64043.0, 0.033], [64527.5, 0.039], [64528.3, 0.002], [64547.3, 0.015], [64547.5, 4.642], [64683.6, 0.235], [64684.6, 0.004], [64685.1, 0.084], [64686.1, 0.084], [64689.9, 5.127]], "asks": [[64690.0, 9.53], [64691.6, 0.137], [64691.7, 0.001], [64691.8, 0.769], [64692.4, 0.359], [64692.5, 0.277], [64692.7, 0.206], [64692.8, 0.258], [64693.0, 0.123], [64693.1, 0.571], [64693.2, 0.169], [64693.3, 0.387], [64693.4, 0.084], [64693.8, 0.18], [64694.0, 0.214], [64711.7, 0.016], [64712.4, 0.402], [64718.6, 0.196], [64721.1, 0.374], [64765.6, 8.065], [64767.6, 0.713], [64830.2, 1.501], [64830.3, 0.0], [64830.4, 5.399], [64886.1, 0.0], [64886.2, 9.722], [65000.0, 122.884], [65304.6, 1.303], [65336.9, 0.001], [65445.8, 0.919], [65614.0, 3.155]]}
{"kind": "depth", "E": 1787095356771, "U": 11316373641783, "u": 11316373650017, "recv_ms": 1787095356827, "bids": [[1000.0, 35.76], [14289.9, 2.184], [14389.9, 2.016], [58220.9, 0.002], [61455.4, 0.004], [62102.3, 0.147], [63689.9, 0.03], [63751.9, 9.862], [64043.0, 0.033], [64524.7, 0.039], [64527.5, 0.0], [64588.7, 0.001], [64656.2, 0.068], [64681.9, 0.819], [64682.7, 0.09], [64683.6, 0.003], [64684.2, 1.115], [64685.5, 0.079], [64686.6, 0.244], [64689.9, 5.141]], "asks": [[64691.6, 0.002], [64691.7, 0.226], [64692.3, 0.011], [64692.4, 0.002], [64692.5, 0.039], [64692.7, 0.087], [64692.8, 0.036], [64693.0, 0.004], [64693.1, 0.333], [64693.2, 0.349], [64693.4, 0.239], [64693.7, 0.239], [64693.8, 0.62], [64693.9, 0.258], [64694.0, 0.212], [64694.1, 0.281], [64694.5, 0.156], [64708.7, 0.009], [64712.1, 10.068], [64744.4, 0.387], [64767.9, 0.0], [64772.4, 48.18], [65336.9, 0.001], [65350.0, 80.781], [65445.8, 0.003], [65459.8, 4.582], [65584.5, 30.629], [65628.0, 7.907], [65690.0, 0.433]]}
{"kind": "depth", "E": 1787095356873, "U": 11316373650163, "u": 11316373655439, "recv_ms": 1787095356931, "bids": [[14289.9, 2.548], [14389.9, 1.652], [58220.9, 0.002], [61455.4, 0.004], [63966.5, 1.577], [64043.0, 0.033], [64107.7, 0.469], [64366.5, 0.01], [64547.5, 0.027], [64547.6, 4.615], [64631.6, 1.24], [64685.5, 0.163], [64686.1, 0.0], [64689.9, 5.142]], "asks": [[64691.5, 0.007], [64691.6, 0.002], [64691.7, 0.001], [64692.8, 0.274], [64693.0, 0.014], [64693.1, 0.333], [64693.2, 0.265], [64693.4, 0.084], [64693.7, 0.001], [64693.8, 0.18], [64741.3, 0.045], [64741.5, 0.045], [64744.4, 0.387], [64765.6, 1.142], [64767.6, 0.629], [64767.7, 0.003], [64767.9, 48.318], [64770.1, 0.006], [64772.4, 0.0], [64830.4, 5.399], [64886.2, 9.657], [65336.9, 0.001]]}
{"kind": "depth", "E": 1787095356975, "U": 11316373655482, "u": 11316373671202, "recv_ms": 1787095357031, "bids": [[1000.0, 35.91], [14289.9, 2.898], [14389.9, 1.302], [58220.9, 0.002], [62102.3, 0.158], [62296.4, 0.016], [63638.7, 4.497], [63641.3, 0.006], [63689.9, 0.01], [64043.0, 0.033], [64524.7, 0.0], [64525.1, 0.042], [64579.9, 0.003], [64631.6, 1.237], [64670.7, 0.62], [64678.1, 0.776], [64689.9, 5.141]], "asks": [[64691.6, 0.018], [64691.7, 0.001], [64691.8, 1.048], [64692.3, 0.001], [64692.5, 0.049], [64692.6, 0.273], [64692.7, 0.087], [64692.8, 0.02], [64693.0, 0.004], [64693.1, 0.654], [64693.2, 0.265], [64693.3, 0.387], [64693.4, 0.001], [64693.8, 0.18], [64699.6, 0.14], [64701.6, 0.618], [64703.5, 0.006], [64706.2, 0.236], [64707.4, 1.594], [64735.3, 0.002], [64744.4, 0.387], [64767.7, 0.0], [65336.9, 0.003], [65459.8, 5.497], [65542.7, 0.763], [65595.7, 9.785], [65690.0, 0.413]]}
{"kind": "depth", "E": 1787095357281, "U": 11316373686089, "u": 11316373698468, "recv_ms": 1787095357339, "bids": [[1000.0, 35.76], [14189.9, 0.098], [14289.9, 3.766], [14389.9, 0.336], [51752.0, 0.0], [58220.9, 0.002], [61455.4, 0.005], [61455.5, 0.006], [63689.9, 0.01], [64043.0, 0.033], [64366.4, 1.176], [64657.0, 0.005], [64657.1, 0.036], [64657.2, 0.064], [64660.4, 4.904], [64660.5, 1.332], [64660.6, 0.028], [64678.1, 0.158], [64685.5, 0.079]], "asks": [[64690.0, 9.529], [64691.7, 0.001], [64692.9, 0.465], [64693.0, 0.004], [64693.3, 0.387], [64693.4, 0.084], [64693.6, 0.119], [64693.7, 0.001], [64693.8, 0.18], [64694.1, 0.281], [64694.5, 0.233], [64694.7, 1.457], [64701.6, 0.0], [64847.3, 0.027], [64847.4, 6.229], [64886.2, 2.599], [65336.9, 0.001], [65482.0, 16.607], [65690.0, 0.413], [65899.7, 1.515]]}
{"kind": "depth", "E": 1787095357383, "U": 11316373698519, "u": 11316373707179, "recv_ms": 1787095357440, "bids": [[14189.9, 0.336], [14289.9, 3.654], [14389.9, 0.21], [51751.9, 0.0], [51752.0, 0.0], [58220.9, 0.002], [61455.4, 0.004], [62102.3, 0.147], [63315.4, 0.0], [63480.2, 1.729], [64043.0, 0.033], [64471.0, 0.154], [64654.6, 8.037], [64655.6, 1.288], [64679.6, 0.864], [64680.2, 0.415], [64685.5, 0.079], [64689.9, 5.151]], "asks": [[64690.0, 9.532], [64691.7, 0.001], [64693.4, 0.203], [64693.6, 0.0], [64693.8, 0.18], [64693.9, 0.258], [64694.1, 0.358], [64694.5, 0.156], [64698.8, 0.316], [64700.1, 1.002], [64711.7, 0.014], [64712.1, 10.07], [64744.4, 0.387], [64767.6, 0.706], [64798.4, 0.593], [64847.4, 10.621], [64886.2, 8.838], [65013.5, 0.77], [65336.9, 0.001], [65584.5, 29.868], [65687.4, 1.304], [71159.0, 0.002]]}
{"kind": "depth", "E": 1787095357485, "U": 11316373707287, "u": 11316373713698, "recv_ms": 1787095357543, "bids": [[14189.9, 0.574], [14289.9, 3.528], [14389.9, 0.098], [58220.9, 0.002], [61455.4, 0.006], [62102.3, 0.144], [63497.7, 0.0], [63668.1, 0.0], [63885.8, 0.784], [64043.0, 0.032], [64366.5, 0.0], [64616.1, 1.46], [64629.1, 0.004], [64664.2, 0.015], [64673.5, 3.817], [64677.1, 0.096], [64677.4, 0.003], [64679.7, 0.271], [64682.3, 0.294], [64685.5, 0.079], [64685.6, 0.089]], "asks": [[64691.7, 0.001], [64693.1, 0.333], [64693.3, 0.625], [64693.8, 0.18], [64694.1, 0.281], [64694.5, 0.233], [64699.0, 0.409], [64706.0, 0.389], [64706.8, 0.249], [64708.7, 0.164], [64716.9, 0.156], [64744.4, 0.387], [65336.9, 0.003], [65590.8, 1.522]]}
{"kind": "depth", "E": 1787095357587, "U": 11316373713714, "u": 11316373720447, "recv_ms": 1787095357644, "bids": [[1000.0, 35.76], [14189.9, 0.84], [14289.9, 3.36], [14389.9, 0.0], [58220.9, 0.002], [61442.2, 0.0], [61455.4, 0.006], [62102.3, 0.147], [63396.2, 0.02], [63689.9, 0.03], [64043.0, 0.032], [64547.6, 4.717], [64682.2, 1.367], [64682.3, 0.278], [64682.4, 0.024], [64683.2, 0.447], [64685.4, 1.547], [64685.5, 0.087], [64685.8, 0.005], [64686.0, 0.003]], "asks": [[64690.0, 9.558], [64691.8, 1.273], [64693.2, 0.349], [64693.3, 0.387], [64693.4, 0.084], [64693.8, 0.299], [64693.9, 0.258], [64694.0, 0.289], [64694.5, 0.156], [64718.0, 0.096], [64718.1, 0.159], [64718.6, 0.042], [64721.1, 0.318], [64744.4, 0.405], [64767.6, 0.629], [64830.4, 5.399], [64886.2, 8.767], [65336.9, 0.001], [65690.0, 0.433]]}
{"kind": "depth", "E": 1787095357689, "U": 11316373720817, "u": 11316373728608, "recv_ms": 1787095357747, "bids": [[14189.9, 1.204], [14289.9, 2.996], [58220.9, 0.002], [62102.3, 0.144], [63331.4, 0.316], [63438.9, 0.006], [64043.0, 0.032], [64655.6, 2.32], [64683.2, 0.447], [64689.9, 5.15]], "asks": [[64691.8, 1.048], [64692.5, 0.049], [64693.7, 0.12], [64693.8, 0.18], [64711.0, 4.041], [64718.1, 0.005], [64718.2, 0.02], [64744.4, 0.387], [64765.6, 1.142], [64767.9, 0.0], [64770.1, 48.396], [64779.0, 0.603], [64830.2, 2.116], [65336.9, 0.001], [65687.4, 0.652]]}
{"kind": "depth", "E": 1787095357791, "U": 11316373728754, "u": 11316373736912, "recv_ms": 1787095357849, "bids": [[14189.9, 1.554], [14289.9, 2.646], [51752.0, 0.0], [58220.9, 0.002], [63688.5, 4.242], [63689.9, 0.01], [64043.0, 0.032], [64366.5, 0.0], [64530.3, 0.0], [64530.7, 6.188], [64547.6, 0.0], [64547.7, 4.526], [64683.2, 0.447], [64689.9, 5.148]], "asks": [[64692.5, 0.264], [64693.7, 0.001], [64693.8, 0.418], [64693.9, 0.496], [64706.2, 0.17], [64713.7, 0.336], [64714.6, 0.0], [64718.1, 0.005], [64718.2, 0.174], [64767.9, 48.39], [64770.1, 0.006], [64830.2, 1.501], [64830.4, 5.399], [64847.4, 10.621], [64874.0, 0.015], [64874.1, 0.004], [64886.2, 9.986], [65336.9, 0.001], [65690.0, 0.413], [67924.5, 0.027]]}
{"kind": "depth", "E": 1787095358097, "U": 11316373750825, "u": 11316373756862, "recv_ms": 1787095358153, "bids": [[14189.9, 2.618], [14289.9, 1.582], [51752.0, 0.0], [58220.9, 0.002], [61455.4, 0.006], [62102.3, 0.153], [63865.1, 17.544], [63902.8, 18.352], [64043.0, 0.032], [64288.6, 0.513], [64366.5, 0.01], [64678.1, 0.776], [64678.3, 0.021], [64683.2, 0.001], [64684.4, 0.447], [64689.9, 5.15]], "asks": [[64691.5, 0.007], [64692.5, 0.264], [64693.4, 0.322], [64693.8, 0.418], [64693.9, 0.258], [64694.0, 0.212], [64694.5, 0.241], [64701.6, 0.618], [64739.4, 0.003], [64886.2, 9.111], [65283.7, 8.905], [65336.9, 0.001]]}
{"kind": "depth", "E": 1787095358199, "U": 11316373757067, "u": 11316373763313, "recv_ms": 1787095358266, "bids": [[1000.0, 35.76], [14189.9, 2.982], [14289.9, 1.218], [51752.0, 0.0], [58220.9, 0.002], [63374.2, 0.0], [63689.9, 0.01], [63761.6, 7.2], [64043.0, 0.032], [64366.4, 1.177], [64664.2, 0.015], [64677.1, 0.096], [64677.4, 0.003], [64679.7, 0.271], [64682.3, 0.194], [64682.7, 0.006], [64684.4, 0.001], [64685.5, 0.087], [64685.9, 0.005], [64687.0, 0.086]], "asks": [[64692.5, 0.039], [64693.8, 0.18], [64694.1, 0.281], [64699.0, 0.409], [64706.8, 0.249], [64708.7, 0.164], [64716.9, 0.156], [65304.6, 1.978], [65336.9, 0.001], [65449.7, 25.669], [65690.0, 0.413]]}
{"kind": "depth", "E": 1787095358301, "U": 11316373763536, "u": 11316373769314, "recv_ms": 1787095358358, "bids": [[14189.9, 3.332], [14289.9, 0.868], [51752.0, 0.0], [58220.9, 0.002], [62102.3, 0.15], [62296.4, 0.002], [63061.9, 1.189], [63673.6, 2.196], [63913.6, 26.721], [64043.0, 0.032], [64579.9, 0.0], [64631.6, 1.24], [64683.2, 0.001], [64684.3, 1.078]], "asks": [[64692.5, 0.039], [64693.3, 0.387], [64693.8, 0.18], [64718.3, 0.579], [64718.4, 1.355], [64735.3, 0.005], [64886.2, 8.839], [65304.6, 2.665], [65336.9, 0.001]]}
{"kind": "depth", "E": 1787095358403, "U": 11316373769732, "u": 11316373774867, "recv_ms": 1787095358461, "bids": [[1000.0, 35.76], [14189.9, 3.696], [14289.9, 0.504], [34000.0, 1.146], [51751.9, 0.0], [58220.9, 0.002], [61455.4, 0.006], [62102.3, 0.153], [63394.5, 0.566], [63396.2, 0.023], [63660.1, 0.0], [63689.9, 0.03], [64043.0, 0.032], [64366.5, 0.0], [64547.7, 4.629], [64683.2, 0.447], [64684.3, 0.632], [64689.9, 5.148]], "asks": [[64691.5, 0.007], [64692.5, 0.039], [64693.8, 0.18], [64718.3, 0.425], [64718.5, 0.73], [64830.4, 5.399], [64886.2, 10.257], [65013.5, 0.768], [65336.9, 0.001], [65690.0, 0.433], [65983.7, 0.009]]}
{"kind": "depth", "E": 1787095358709, "U": 11316373786319, "u": 11316373791532, "recv_ms": 1787095358767, "bids": [[1000.0, 35.76], [14189.9, 3.5], [14289.9, 0.07], [14589.9, 0.63], [51752.0, 0.0], [58220.9, 0.002], [64043.0, 0.032], [64052.4, 0.0], [64366.5, 0.0], [64530.7, 0.094], [64530.8, 6.452], [64579.9, 0.003], [64683.2, 0.001]], "asks": [[64692.5, 0.264], [64693.8, 0.418], [64693.9, 0.496], [64712.3, 0.466], [64713.6, 0.806], [64765.6, 1.142], [64767.7, 0.003], [64767.9, 0.0], [64778.9, 48.395], [64886.2, 9.851], [65336.9, 0.001]]}
{"kind": "depth", "E": 1787095358811, "U": 11316373791727, "u": 11316373797958, "recv_ms": 1787095358867, "bids": [[1000.0, 35.76], [14189.9, 3.276], [14289.9, 0.0], [14589.9, 0.924], [58220.9, 0.0], [62102.3, 0.15], [63689.9, 0.03], [63881.3, 2.813], [64043.0, 0.032], [64055.9, 0.623], [64683.2, 0.001]], "asks": [[64692.5, 0.264], [64693.8, 0.418], [64693.9, 0.496], [64767.9, 48.437], [64778.9, 0.005], [65336.9, 0.001], [65514.4, 12.038], [65690.0, 0.433]]}
{"kind": "depth", "E": 1787095358913, "U": 11316373797968, "u": 11316373804681, "recv_ms": 1787095358969, "bids": [[14189.9, 2.926], [14589.9, 1.274], [58220.9, 0.002], [61455.4, 0.006], [62102.3, 0.153], [63773.4, 14.5], [64043.0, 0.032], [64328.1, 0.0], [64530.8, 6.424], [64547.7, 0.242], [64547.8, 4.589], [64583.0, 0.0], [64583.1, 0.018], [64619.6, 0.118], [64619.8, 1.974], [64627.5, 0.342], [64627.8, 3.044], [64628.0, 0.001], [64628.1, 1.973], [64632.9, 0.027], [64636.3, 0.003], [64636.5, 0.209], [64654.6, 0.037], [64655.6, 1.288], [64658.7, 2.0], [64670.7, 0.002], [64678.1, 0.378], [64682.2, 1.366], [64683.0, 0.003], [64683.2, 0.001], [64683.3, 0.151], [64684.1, 0.001], [64684.2, 1.425], [64684.4, 0.001], [64684.5, 0.015], [64685.8, 0.002], [64686.0, 0.006], [64686.2, 0.003], [64686.4, 0.003], [64687.1, 0.323], [64687.4, 0.085], [64687.5, 0.382], [64688.1, 0.002], [64688.4, 0.001], [64689.9, 5.152]], "asks": [[64690.0, 9.15], [64690.3, 0.011], [64690.7, 0.085], [64691.5, 0.161], [64691.6, 0.229], [64692.5, 0.039], [64693.4, 0.084], [64693.8, 0.18], [64693.9, 0.258], [64694.6, 0.303], [64697.6, 0.247], [64701.6, 0.0], [64703.3, 0.0], [64703.4, 4.422], [64709.0, 0.011], [64710.8, 0.416], [64711.6, 0.122], [64711.7, 1.987], [64715.9, 0.767], [64720.0, 0.566], [64720.1, 1.973], [64744.4, 0.396], [64752.6, 0.02], [64752.7, 3.024], [64767.9, 0.0], [64778.9, 48.442], [64800.0, 21.198], [64830.4, 5.399], [64847.4, 10.621], [64886.2, 9.389], [65336.9, 0.001], [65452.3, 9.261], [65555.3, 0.001]]}
{"kind": "depth", "E": 1787095359015, "U": 11316373804824, "u": 11316373811649, "recv_ms": 1787095359072, "bids": [[1000.0, 35.76], [14189.9, 2.562], [14589.9, 1.638], [58220.9, 0.002], [61453.6, 0.0], [62102.3, 0.15], [63396.2, 0.02], [63513.7, 0.786], [63689.9, 0.01], [64043.0, 0.032], [64140.0, 5.008], [64366.5, 0.01], [64395.2, 0.0], [64683.0, 0.004], [64684.1, 0.0], [64689.9, 5.151]], "asks": [[64690.0, 9.152], [64691.4, 0.31], [64691.5, 0.322], [64691.6, 0.236], [64692.7, 0.325], [64692.8, 0.377], [64693.0, 0.004], [64693.1, 0.69], [64693.2, 0.468], [64693.4, 0.084], [64693.8, 0.18], [64694.7, 1.452], [64744.4, 0.387], [64767.9, 48.437], [64778.9, 0.005], [65336.9, 0.001], [65498.6, 3.57], [65531.0, 0.751], [65619.9, 3.425], [65640.9, 3.726], [65690.0, 0.413]]}
{"kind": "depth", "E": 1787095359117, "U": 11316373811902, "u": 11316373818265, "recv_ms": 1787095359173, "bids": [[1000.0, 35.76], [14189.9, 2.212], [14589.9, 1.988], [58220.9, 0.002], [62102.3, 0.153], [63696.8, 0.39], [63703.5, 0.0], [63784.2, 2.9], [63901.8, 1.589], [63902.8, 16.789], [64617.0, 0.026], [64678.3, 0.021]], "asks": [[64691.4, 0.084], [64691.5, 0.553], [64692.6, 0.273], [64692.7, 0.087], [64692.8, 0.799], [64693.0, 0.004], [64693.1, 0.416], [64693.2, 0.349], [64693.4, 0.001], [64693.5, 0.059], [64693.7, 0.001], [64693.8, 0.18], [64694.3, 0.262], [64694.5, 0.239], [65336.9, 0.001], [65452.3, 8.575], [65466.3, 13.798], [65485.8, 0.763], [65576.3, 1.218], [65595.7, 10.546], [65683.2, 0.0], [65703.9, 0.651]]}
{"kind": "depth", "E": 1787095359321, "U": 11316373824214, "u": 11316373829687, "recv_ms": 1787095359389, "bids": [[1000.0, 35.76], [14189.9, 1.484], [14589.9, 2.716], [51751.9, 0.0], [58220.9, 0.002], [61455.4, 0.004], [61455.5, 0.008], [62102.3, 0.15], [63396.2, 0.023], [63719.6, 0.787], [64043.0, 0.032], [64366.5, 0.0], [64625.1, 38.932], [64627.2, 0.043], [64629.6, 1.17]], "asks": [[64690.8, 0.019], [64691.4, 0.084], [64691.5, 0.238], [64691.6, 0.236], [64691.7, 0.003], [64693.1, 0.333], [64693.5, 0.142], [64693.7, 0.001], [64693.8, 0.18], [64718.3, 0.425], [64718.6, 0.042], [64718.7, 2.477], [65336.9, 0.001], [65466.3, 14.483], [65683.2, 0.011]]}
{"kind": "depth", "E": 1787095359423, "U": 11316373829742, "u": 11316373834336, "recv_ms": 1787095359481, "bids": [[1000.0, 35.76], [14189.9, 1.134], [14589.9, 3.066], [51752.0, 0.0], [58220.9, 0.002], [60808.5, 0.091], [61455.4, 0.004], [62102.3, 0.153], [63689.9, 0.01], [63703.4, 18.711], [63844.0, 0.411], [63913.6, 28.284], [64043.0, 0.032], [64102.7, 0.473], [64491.4, 0.395], [64491.5, 0.001], [64492.0, 13.717], [64492.1, 3.193], [64530.8, 6.07], [64531.2, 1.926], [64547.8, 4.36], [64566.7, 0.0], [64577.5, 0.442], [64625.1, 6.267], [64627.2, 32.708], [64630.7, 0.032], [64689.9, 5.152]], "asks": [[64691.5, 0.084], [64693.1, 0.333], [64693.2, 0.349], [64693.8, 0.18], [64830.2, 1.501], [64830.4, 5.399], [64847.4, 10.621], [64886.2, 14.459], [65013.5, 0.769], [65270.2, 1.837], [65336.9, 0.001], [65528.9, 1.058], [65690.0, 0.413], [65703.9, 1.302]]}
{"kind": "depth", "E": 1787095359525, "U": 11316373834494, "u": 11316373840195, "recv_ms": 1787095359582, "bids": [[14189.9, 0.77], [14589.9, 3.43], [58220.9, 0.002], [61455.4, 0.004], [62102.3, 0.15], [63396.2, 0.02], [64043.0, 0.032], [64366.5, 0.01], [64530.8, 6.504], [64579.9, 0.0], [64625.2, 0.021], [64631.6, 1.24], [64673.5, 3.817], [64688.7, 0.0], [64689.9, 5.162]], "asks": [[64690.0, 9.161], [64690.2, 0.002], [64691.5, 0.007], [64691.6, 0.22], [64692.6, 0.273], [64692.7, 0.087], [64692.8, 0.02], [64693.7, 0.017], [64693.8, 0.721], [64693.9, 0.258], [64701.0, 3.264], [64703.0, 0.033], [64706.0, 0.389], [64735.3, 0.002], [64744.4, 0.387], [64754.7, 6.99], [64767.7, 0.0], [64800.0, 21.198], [64886.2, 9.103], [65336.9, 0.001], [65849.5, 0.758]]}
{"kind": "depth", "E": 1787095359627, "U": 11316373840269, "u": 11316373846178, "recv_ms": 1787095359684, "bids": [[1000.0, 35.76], [14189.9, 0.448], [14489.9, 0.028], [14589.9, 3.724], [51752.0, 0.0], [58220.9, 0.004], [62102.3, 0.153], [63689.9, 0.03], [63719.6, 1.14], [63755.1, 2.821], [63784.2, 5.249], [64043.0, 0.032], [64366.4, 1.176], [64530.8, 0.0], [64547.8, 0.005], [64593.4, 0.016], [64684.2, 1.115], [64684.5, 0.012], [64687.0, 0.312], [64687.1, 0.097], [64687.4, 0.001], [64688.2, 0.043], [64688.3, 0.007], [64689.9, 5.16]], "asks": [[64690.1, 0.096], [64691.5, 0.007], [64691.6, 0.136], [64691.7, 0.019], [64692.8, 0.68], [64693.0, 0.004], [64693.1, 0.809], [64693.2, 0.349], [64693.7, 0.001], [64693.8, 0.418], [64712.1, 0.07], [64718.7, 2.323], [64718.8, 0.455], [64765.6, 8.102], [64822.4, 1.839], [64830.4, 0.0], [64844.9, 2.898], [64847.4, 0.212], [65013.5, 0.77], [65336.9, 0.001], [65462.1, 0.003], [65690.0, 0.433]]}
{"kind": "depth", "E": 1787095359729, "U": 11316373846308, "u": 11316373857686, "recv_ms": 1787095359787, "bids": [[1000.0, 35.76], [14189.9, 0.28], [14489.9, 0.21], [14589.9, 3.71], [58220.9, 0.002], [61455.4, 0.006], [63396.2, 0.017], [64043.0, 0.032], [64492.0, 13.826], [64492.1, 0.001], [64530.8, 6.504], [64547.8, 4.62], [64582.3, 0.001], [64582.4, 2.324], [64625.1, 39.046], [64627.2, 0.045], [64627.3, 0.001], [64632.9, 0.041], [64641.3, 0.004], [64653.6, 0.003], [64654.6, 8.037], [64655.6, 2.326], [64658.7, 0.0], [64664.2, 0.17], [64670.7, 0.002], [64673.1, 0.557], [64673.4, 0.002], [64673.9, 2.319], [64675.9, 0.085], [64677.1, 0.251], [64677.4, 0.158], [64678.1, 0.378], [64679.7, 0.426], [64681.9, 0.903], [64682.2, 1.367], [64682.3, 0.433], [64682.7, 0.09], [64683.0, 0.087], [64685.1, 0.0], [64685.5, 0.242], [64685.6, 0.005], [64686.1, 0.0], [64686.6, 0.244], [64687.0, 0.002], [64687.1, 0.013], [64689.8, 0.017], [64689.9, 4.57]], "asks": [[64690.0, 9.164], [64690.5, 0.005], [64690.8, 0.329], [64691.5, 0.238], [64691.6, 0.201], [64691.7, 0.019], [64692.5, 0.043], [64692.6, 0.273], [64692.7, 0.087], [64692.8, 0.561], [64693.0, 0.087], [64693.1, 0.333], [64693.2, 0.349], [64693.5, 0.059], [64693.7, 0.001], [64693.8, 0.18], [64693.9, 0.251], [64694.1, 0.203], [64694.5, 0.162], [64698.1, 0.427], [64699.0, 0.099], [64701.6, 0.0], [64703.0, 0.031], [64703.4, 4.424], [64706.8, 0.094], [64708.0, 5.279], [64708.7, 0.009], [64708.9, 0.003], [64710.8, 0.402], [64711.0, 2.799], [64713.1, 0.092], [64715.9, 0.767], [64716.9, 0.001], [64721.1, 0.318], [64744.4, 0.387], [64765.6, 1.142], [64767.9, 48.506], [64771.2, 1.237], [64778.9, 0.005], [64791.5, 0.0], [64796.1, 0.002], [64796.3, 2.357], [64830.4, 4.018], [64844.9, 1.542], [64847.4, 6.159], [64874.1, 0.001], [64874.2, 0.016], [64886.2, 2.603], [65336.9, 0.001]]}
{"kind": "depth", "E": 1787095359831, "U": 11316373857717, "u": 11316373869482, "recv_ms": 1787095359890, "bids": [[14189.9, 0.154], [14489.9, 0.448], [14589.9, 3.598], [58220.9, 0.002], [61455.4, 0.006], [62102.3, 0.15], [63396.2, 0.02], [64043.0, 0.032], [64366.5, 0.01], [64509.0, 1.217], [64547.3, 0.015], [64569.3, 0.003], [64611.6, 0.31], [64618.5, 0.001], [64619.8, 0.0], [64619.9, 1.975], [64620.7, 32.807], [64625.1, 6.267], [64628.1, 0.0], [64628.3, 2.086], [64636.5, 0.073], [64636.6, 0.133], [64644.3, 0.007], [64649.8, 1.21], [64654.6, 0.035], [64655.0, 8.005], [64656.2, 0.068], [64657.0, 0.003], [64657.1, 0.034], [64657.2, 0.062], [64658.4, 0.058], [64659.5, 0.172], [64660.4, 4.902], [64660.5, 1.33], [64660.6, 0.026], [64664.2, 0.015], [64664.6, 0.011], [64665.6, 0.012], [64666.9, 0.46], [64669.1, 0.003], [64670.0, 0.812], [64670.9, 0.005], [64671.0, 0.005], [64672.2, 0.562], [64672.5, 0.038], [64673.1, 0.0], [64674.4, 0.539], [64675.0, 0.246], [64675.3, 0.002], [64675.9, 0.005], [64676.3, 1.514], [64676.8, 0.026], [64676.9, 0.003], [64677.1, 0.096], [64677.2, 0.007], [64677.4, 0.003], [64677.5, 0.002], [64678.1, 0.687], [64678.2, 0.003], [64678.4, 0.081], [64678.6, 0.371], [64678.9, 1.775], [64679.0, 0.797], [64679.4, 0.083], [64679.5, 0.002], [64679.6, 0.555], [64679.7, 0.271], [64679.8, 0.023], [64680.5, 0.215], [64680.8, 0.003], [64681.2, 1.539], [64681.6, 0.129], [64681.9, 0.819], [64682.2, 0.13], [64682.3, 0.108], [64682.4, 0.641], [64682.5, 0.024], [64682.9, 0.31], [64683.2, 0.542], [64683.3, 0.236], [64683.8, 0.088], [64683.9, 0.003], [64684.2, 1.199], [64684.3, 0.007], [64684.5, 0.096], [64684.7, 0.0], [64684.9, 0.405], [64685.0, 0.171], [64685.1, 0.001], [64685.3, 0.088], [64685.4, 1.547], [64685.5, 0.009], [64685.6, 0.005], [64685.7, 0.082], [64685.9, 0.004], [64686.0, 0.087], [64686.3, 0.1], [64686.5, 0.002], [64686.8, 0.894], [64687.0, 0.056], [64687.1, 0.011], [64687.8, 0.053], [64688.0, 0.003], [64688.3, 0.006], [64689.3, 0.011], [64689.8, 0.006], [64689.9, 4.606]], "asks": [[64690.0, 23.573], [64690.1, 0.105], [64690.2, 0.004], [64690.3, 0.011], [64690.7, 0.085], [64690.9, 0.013], [64691.3, 0.002], [64691.5, 0.007], [64691.6, 0.002], [64691.7, 0.001], [64691.8, 0.766], [64691.9, 0.323], [64692.0, 0.078], [64692.5, 0.036], [64692.6, 0.263], [64692.7, 0.087], [64692.8, 0.02], [64693.0, 0.087], [64693.1, 0.329], [64693.2, 0.169], [64693.3, 0.441], [64693.8, 0.239], [64694.1, 0.126], [64694.3, 0.26], [64694.4, 0.195], [64694.5, 0.27], [64694.7, 1.444], [64694.9, 0.003], [64695.5, 0.004], [64696.1, 0.282], [64696.8, 0.002], [64697.2, 0.004], [64697.5, 0.107], [64697.6, 0.246], [64697.9, 0.312], [64698.1, 0.219], [64698.2, 2.482], [64698.7, 0.005], [64698.8, 0.007], [64698.9, 0.048], [64699.0, 0.099], [64699.1, 0.561], [64699.8, 0.016], [64700.0, 3.831], [64701.0, 2.364], [64701.3, 0.005], [64702.2, 0.032], [64702.9, 3.258], [64703.4, 2.784], [64703.5, 1.65], [64704.0, 1.433], [64705.6, 0.003], [64706.7, 0.021], [64706.8, 0.094], [64707.3, 0.034], [64707.4, 1.594], [64707.9, 0.622], [64708.0, 1.281], [64708.1, 0.005], [64708.7, 0.468], [64708.9, 0.001], [64709.2, 0.171], [64710.1, 0.023], [64710.2, 0.222], [64710.4, 0.009], [64710.7, 4.003], [64710.8, 10.404], [64711.0, 0.502], [64711.1, 3.316], [64711.7, 0.014], [64711.8, 2.297], [64711.9, 0.045], [64712.1, 0.05], [64712.5, 0.008], [64712.7, 0.134], [64713.0, 0.673], [64713.7, 0.221], [64713.9, 1.559], [64714.4, 0.179], [64715.6, 2.391], [64716.9, 0.001], [64720.1, 0.0], [64720.2, 1.978], [64741.8, 0.003], [64767.6, 1.132], [64767.9, 0.0], [64770.0, 0.134], [64770.1, 48.512], [64770.9, 0.204], [64778.9, 0.005], [64794.9, 0.148], [64830.4, 5.399], [64847.4, 10.621], [64886.2, 10.212], [65336.9, 0.001], [65983.7, 0.012]]}
{"kind": "depth", "E": 1787095359933, "U": 11316373869630, "u": 11316373878489, "recv_ms": 1787095359990, "bids": [[1000.0, 35.76], [14189.9, 0.042], [14489.9, 0.686], [14589.9, 3.472], [58220.9, 0.002], [61455.4, 0.006], [62102.3, 0.153], [63689.9, 0.01], [63777.8, 0.94], [63881.3, 3.047], [64043.0, 0.032], [64620.7, 0.028], [64625.1, 39.046], [64666.9, 0.38], [64675.9, 0.085], [64677.6, 0.003], [64682.2, 0.13], [64682.4, 0.093], [64683.3, 0.151], [64683.4, 0.09], [64683.5, 0.086], [64685.3, 0.636], [64688.2, 0.001], [64688.3, 0.048], [64689.9, 4.613]], "asks": [[64690.0, 22.844], [64692.5, 0.046], [64694.0, 0.289], [64694.1, 0.667], [64694.5, 0.193], [64698.3, 0.0], [64699.1, 0.02], [64710.7, 0.031], [64710.8, 0.404], [64714.4, 10.179], [64769.2, 0.045], [64805.6, 0.0], [64873.7, 0.111], [65336.9, 0.001], [65466.3, 15.168], [65690.0, 0.413]]}
{"kind": "depth", "E": 1787095360035, "U": 11316373878531, "u": 11316373884939, "recv_ms": 1787095360091, "bids": [[1000.0, 35.76], [14189.9, 0.0], [14489.9, 1.008], [14589.9, 3.192], [58220.9, 0.002], [61455.4, 0.006], [62102.3, 0.15], [63072.6, 0.475], [64043.0, 0.032], [64678.3, 0.026], [64679.4, 0.075], [64682.2, 0.223], [64683.2, 0.001], [64683.3, 0.151], [64683.4, 0.09], [64683.5, 0.001], [64684.3, 0.548], [64689.3, 0.033], [64689.4, 0.019], [64689.9, 4.611]], "asks": [[64692.5, 0.036], [64708.7, 0.009], [64709.3, 3.21], [64713.0, 0.002], [64713.5, 1.151], [64713.6, 0.921], [64714.4, 10.172], [64715.0, 0.08], [64769.2, 0.122], [65336.9, 0.001], [65482.0, 16.379], [65549.4, 1.237]]}
{"kind": "depth", "E": 1787095360137, "U": 11316373885053, "u": 11316373890465, "recv_ms": 1787095360195, "bids": [[14489.9, 1.358], [14589.9, 2.842], [58220.9, 0.002], [63675.9, 0.673], [63689.9, 0.03], [64043.0, 0.032], [64366.5, 0.01], [64616.8, 0.002], [64641.7, 0.079], [64643.2, 0.005], [64678.2, 0.004], [64678.3, 0.021], [64679.4, 0.075], [64682.2, 0.223], [64683.2, 0.001], [64685.0, 0.168], [64685.5, 0.012]], "asks": [[64697.5, 0.108], [64698.9, 0.049], [64699.5, 0.002], [64711.1, 3.259], [64712.0, 1.743], [64745.4, 0.065], [64746.8, 2.127], [65202.4, 0.408], [65283.7, 8.218], [65336.9, 0.001], [65452.3, 8.117], [65690.0, 0.433], [65849.5, 0.0]]}
{"kind": "depth", "E": 1787095360239, "U": 11316373890641, "u": 11316373898299, "recv_ms": 1787095360296, "bids": [[1000.0, 35.76], [14489.9, 1.722], [14589.9, 2.478], [58220.9, 0.002], [61455.4, 0.006], [62102.3, 0.153], [63821.5, 4.693], [64043.0, 0.034], [64579.9, 0.003], [64626.5, 0.408], [64626.8, 0.0], [64627.2, 0.013], [64627.5, 0.31], [64627.8, 3.012], [64644.2, 0.018], [64644.5, 0.035], [64644.6, 0.055], [64644.9, 0.001], [64645.2, 0.003], [64645.5, 0.028], [64659.2, 0.012], [64659.3, 0.392], [64659.4, 0.003], [64659.5, 0.002], [64659.6, 0.165], [64659.7, 0.007], [64659.8, 0.007], [64659.9, 0.0], [64660.0, 0.105], [64660.1, 0.013], [64661.1, 0.112], [64661.6, 0.028], [64668.2, 0.016], [64670.6, 1.082], [64678.0, 0.009], [64678.4, 0.011], [64678.5, 0.583], [64678.6, 0.231], [64678.7, 0.015], [64678.8, 0.002], [64678.9, 1.645], [64679.0, 0.697], [64679.1, 0.08], [64679.2, 0.1], [64679.3, 2.4], [64679.4, 0.106], [64679.6, 0.625], [64679.7, 0.239], [64679.9, 0.034], [64680.0, 0.131], [64680.3, 0.002], [64680.7, 0.005], [64681.0, 0.004], [64681.2, 1.144], [64682.0, 0.009], [64682.2, 0.13], [64682.5, 0.016], [64683.2, 0.001], [64684.1, 0.005], [64685.0, 0.172], [64685.7, 0.166], [64686.0, 0.003], [64686.2, 0.006], [64686.9, 0.017], [64688.3, 0.006], [64688.4, 0.04], [64689.9, 4.611]], "asks": [[64690.0, 22.939], [64691.7, 0.004], [64691.8, 0.536], [64692.2, 0.095], [64692.5, 0.001], [64692.9, 0.427], [64693.2, 0.127], [64693.5, 0.017], [64693.6, 0.042], [64693.8, 0.148], [64693.9, 0.222], [64694.0, 0.016], [64694.1, 0.006], [64694.2, 0.245], [64694.3, 0.2], [64694.4, 0.045], [64694.5, 0.039], [64694.6, 0.781], [64694.7, 1.423], [64694.8, 7.4], [64694.9, 0.001], [64697.7, 0.049], [64701.5, 0.618], [64708.5, 0.0], [64708.9, 0.619], [64709.9, 0.001], [64710.3, 0.001], [64710.6, 0.034], [64710.9, 0.007], [64711.2, 0.451], [64711.4, 0.05], [64711.6, 0.002], [64712.0, 1.603], [64713.1, 0.001], [64713.2, 0.325], [64713.3, 0.018], [64713.4, 0.262], [64713.5, 1.091], [64713.6, 0.931], [64713.7, 0.001], [64713.8, 0.009], [64713.9, 1.489], [64714.0, 0.106], [64718.8, 0.457], [64718.9, 0.007], [64719.0, 0.004], [64721.8, 0.453], [64721.9, 5.712], [64722.0, 1.549], [64722.8, 0.007], [64722.9, 0.007], [64723.0, 0.02], [64724.9, 0.038], [64725.0, 0.066], [64725.1, 0.002], [64727.7, 0.005], [64728.0, 1.837], [64728.3, 0.214], [64728.6, 0.005], [64729.0, 0.046], [64729.1, 0.432], [64735.3, 0.005], [65336.9, 0.001], [65584.5, 27.584]]}
{"kind": "depth", "E": 1787095360341, "U": 11316373898378, "u": 11316373910467, "recv_ms": 1787095360398, "bids": [[1000.0, 35.76], [14489.9, 2.072], [14589.9, 2.128], [51751.9, 0.0], [51752.0, 0.0], [58220.9, 0.002], [61455.4, 0.006], [62102.3, 0.15], [63689.9, 0.01], [64035.4, 0.0], [64043.0, 0.032], [64489.9, 0.48], [64644.8, 1.07], [64645.1, 0.039], [64645.8, 0.315], [64658.4, 0.001], [64659.1, 2.038], [64660.5, 1.387], [64677.2, 0.0], [64678.1, 0.378], [64678.4, 0.018], [64678.7, 0.085], [64678.8, 0.072], [64679.0, 0.767], [64679.1, 0.28], [64679.3, 2.5], [64679.4, 0.082], [64679.5, 0.481], [64680.3, 0.034], [64680.6, 0.049], [64681.2, 1.176], [64682.2, 0.154], [64682.3, 0.024], [64686.1, 0.084], [64689.9, 5.243]], "asks": [[64690.9, 0.006], [64691.4, 0.091], [64692.3, 0.033], [64693.0, 0.125], [64693.3, 0.483], [64694.0, 0.136], [64694.1, 0.097], [64694.2, 0.365], [64694.4, 0.305], [64694.6, 0.921], [64694.9, 0.078], [64697.5, 0.107], [64697.9, 0.003], [64698.6, 0.311], [64700.0, 2.931], [64701.5, 0.0], [64708.9, 0.001], [64710.1, 0.055], [64710.7, 0.069], [64711.0, 0.544], [64711.7, 0.134], [64712.2, 0.26], [64713.4, 0.353], [64713.5, 1.211], [64713.7, 0.121], [64713.9, 1.629], [64714.2, 0.246], [64727.8, 0.033], [64728.4, 0.428], [64728.8, 0.052], [65013.5, 0.769], [65304.6, 3.352], [65336.9, 0.001], [65542.9, 0.774], [65690.0, 0.413], [65865.7, 0.985], [65983.7, 0.009]]}
{"kind": "depth", "E": 1787095360443, "U": 11316373910757, "u": 11316373917065, "recv_ms": 1787095360499, "bids": [[14489.9, 2.436], [14589.9, 1.764], [51752.0, 0.0], [58220.9, 0.002], [62102.3, 0.153], [64043.0, 0.032], [64366.4, 1.177], [64366.5, 0.0], [64645.5, 0.06], [64678.7, 0.155], [64678.9, 1.715], [64679.0, 0.867], [64679.7, 0.263], [64680.9, 0.191], [64682.2, 0.13]], "asks": [[64692.7, 0.122], [64693.2, 0.204], [64694.5, 0.189], [64694.6, 1.005], [64694.8, 7.491], [64701.0, 3.264], [64710.4, 0.044], [64713.8, 0.159], [64713.9, 1.713], [64714.1, 0.593], [64728.1, 0.037], [64847.4, 6.265], [64886.2, 2.596], [65336.9, 0.001], [65466.3, 15.84], [65595.7, 12.829]]}
{"kind": "depth", "E": 1787095360545, "U": 11316373917174, "u": 11316373922314, "recv_ms": 1787095360602, "bids": [[1000.0, 35.76], [14489.9, 2.786], [14589.9, 1.414], [58220.9, 0.002], [61455.4, 0.006], [62102.3, 0.15], [63689.9, 0.03], [64043.0, 0.032], [64055.9, 1.635], [64626.8, 0.032], [64653.6, 0.017], [64655.0, 0.005], [64655.6, 1.288], [64673.5, 3.815], [64676.0, 1.479], [64679.4, 0.182], [64689.9, 5.249]], "asks": [[64690.0, 22.962], [64694.1, 0.217], [64706.0, 0.387], [64713.4, 0.473], [64830.4, 0.0], [64830.5, 4.011], [64847.4, 6.144], [64886.2, 0.943], [64886.3, 2.595], [65230.8, 0.0], [65261.3, 0.003], [65336.9, 0.001], [65690.0, 0.433], [65886.8, 0.984]]}
{"kind": "depth", "E": 1787095360749, "U": 11316373933232, "u": 11316373940675, "recv_ms": 1787095360807, "bids": [[14489.9, 3.514], [14589.9, 0.686], [58220.9, 0.002], [61455.4, 0.004], [62102.3, 0.153], [63576.6, 1.413], [63689.9, 0.01], [64043.0, 0.032], [64366.4, 1.178], [64366.5, 0.0], [64583.1, 0.015], [64583.8, 0.003], [64588.7, 0.006], [64627.7, 0.032], [64645.8, 0.237], [64645.9, 0.083], [64659.4, 0.073], [64659.5, 0.072], [64659.7, 0.077], [64659.9, 0.2], [64660.1, 0.113], [64660.2, 0.201], [64661.4, 0.1], [64661.8, 0.1], [64682.7, 0.001], [64683.2, 0.001], [64687.2, 0.088]], "asks": [[64690.0, 22.856], [64690.1, 0.021], [64707.9, 0.004], [64708.6, 0.624], [64718.0, 0.096], [64718.8, 0.303], [64741.8, 0.012], [64830.5, 5.4], [64847.4, 10.621], [64874.2, 0.013], [64874.9, 2.756], [64886.3, 10.338], [65336.9, 0.001], [65494.3, 0.0], [65690.0, 0.413]]}
{"kind": "depth", "E": 1787095360851, "U": 11316373940685, "u": 11316373945722, "recv_ms": 1787095360909, "bids": [[1000.0, 35.76], [14389.9, 0.056], [14489.9, 3.752], [14589.9, 0.392], [51752.0, 0.0], [58220.9, 0.002], [62102.3, 0.15], [63396.2, 0.023], [64043.0, 0.032], [64342.4, 0.007], [64547.8, 0.005], [64548.0, 28.409], [64579.9, 0.0], [64588.7, 0.001], [64631.6, 1.24], [64651.0, 0.015], [64659.5, 0.142], [64659.6, 0.305], [64659.8, 0.107], [64670.0, 0.696], [64671.0, 0.121], [64672.2, 0.005], [64673.4, 0.559], [64682.7, 0.006], [64683.2, 0.447], [64689.9, 5.248]], "asks": [[64718.0, 0.25], [64729.7, 2.334], [64735.3, 0.005], [64736.2, 0.01], [64742.6, 2.335], [64749.1, 0.0], [64800.0, 21.195], [64830.5, 5.4], [64886.3, 11.261], [65336.9, 0.001], [65455.1, 20.93], [65461.5, 1.546], [65498.6, 3.722], [65635.1, 4.107], [68228.8, 0.0]]}
{"kind": "depth", "E": 1787095361157, "U": 11316373958752, "u": 11316373965760, "recv_ms": 1787095361215, "bids": [[1000.0, 35.76], [14389.9, 0.756], [14489.9, 3.43], [14589.9, 0.014], [51752.0, 0.0], [58220.9, 0.002], [63689.9, 0.01], [63706.1, 0.388], [63770.9, 0.008], [63796.2, 3.555], [64043.0, 0.032], [64629.5, 0.036], [64683.2, 0.447]], "asks": [[64697.8, 0.112], [64702.7, 0.377], [64718.1, 0.159], [64718.2, 0.02], [65336.9, 0.003], [65466.3, 17.366], [65609.1, 0.001], [65673.8, 0.017], [65690.0, 0.413]]}
{"kind": "depth", "E": 1787095361259, "U": 11316373965799, "u": 11316373978788, "recv_ms": 1787095361315, "bids": [[1000.0, 35.76], [14389.9, 1.092], [14489.9, 3.108], [14589.9, 0.0], [51752.0, 0.0], [58220.9, 0.002], [61455.4, 0.004], [62102.3, 0.147], [63772.1, 0.0], [64043.0, 0.032], [64054.8, 6.441], [64075.3, 6.059], [64548.0, 28.872], [64656.2, 0.026], [64678.6, 0.849], [64683.2, 0.447], [64683.4, 0.091], [64683.7, 0.021], [64689.9, 5.249]], "asks": [[64690.0, 22.821], [64690.2, 0.088], [64693.2, 0.089], [64694.0, 0.121], [64699.8, 0.004], [64699.9, 0.793], [64700.8, 2.343], [64702.1, 1.339], [64704.5, 0.009], [64709.5, 0.62], [64714.0, 0.104], [64718.1, 0.005], [64767.5, 0.141], [64830.5, 5.4], [64886.3, 9.26], [65207.5, 1.867], [65336.9, 0.001], [65400.0, 116.125], [65461.5, 0.783], [65607.8, 0.066], [65609.1, 0.009], [65673.8, 0.025], [65866.2, 0.759], [65888.5, 0.002], [65983.7, 0.006], [66031.7, 0.0]]}
{"kind": "depth", "E": 1787095361361, "U": 11316373979005, "u": 11316373986445, "recv_ms": 1787095361417, "bids": [[14389.9, 1.442], [14489.9, 2.758], [51751.9, 0.0], [58220.9, 0.002], [61455.4, 0.004], [62102.3, 0.144], [63562.8, 0.0], [63689.9, 0.03], [63771.3, 0.469], [63772.1, 0.008], [64043.0, 0.032], [64366.5, 0.01], [64403.3, 0.054], [64670.8, 0.2], [64675.9, 0.005], [64683.2, 0.447], [64685.5, 0.009], [64686.0, 0.006], [64689.9, 5.4]], "asks": [[64690.0, 22.814], [64690.8, 0.019], [64702.1, 0.721], [64718.0, 0.096], [64718.1, 0.159], [65336.9, 0.001], [65592.0, 3.462], [65690.0, 0.433]]}
{"kind": "depth", "E": 1787095361463, "U": 11316373986623, "u": 11316373993794, "recv_ms": 1787095361520, "bids": [[1000.0, 35.76], [14389.9, 1.806], [14489.9, 2.394], [58220.9, 0.002], [62102.3, 0.147], [63787.5, 3.137], [63950.9, 2.344], [64043.0, 0.032], [64075.3, 6.604], [64366.4, 1.177], [64366.7, 0.115], [64627.8, 0.311], [64642.0, 0.016], [64651.3, 0.016], [64668.3, 0.001], [64668.6, 0.008], [64683.2, 0.447]], "asks": [[64718.1, 0.005], [64718.8, 0.041], [64735.3, 0.267], [64752.7, 0.018], [65016.1, 0.11], [65018.9, 0.0], [65336.9, 0.002], [65478.2, 0.767], [65607.8, 0.074], [66048.5, 1.587]]}
{"kind": "depth", "E": 1787095361565, "U": 11316373993950, "u": 11316373999567, "recv_ms": 1787095361622, "bids": [[1000.0, 35.76], [14389.9, 2.17], [14489.9, 2.03], [51752.0, 0.0], [58220.9, 0.002], [61455.4, 0.004], [63396.2, 0.026], [63689.9, 0.01], [63731.9, 0.0], [64043.0, 0.032], [64492.0, 2.054], [64492.1, 0.001], [64492.2, 12.202], [64530.8, 0.0], [64531.0, 0.001], [64531.1, 11.247], [64531.2, 2.669], [64548.0, 28.773], [64588.7, 0.006], [64627.9, 2.678], [64670.6, 0.464], [64673.5, 3.815], [64678.6, 0.231], [64682.7, 0.001], [64683.2, 0.447], [64689.9, 5.403]], "asks": [[64706.0, 0.387], [64711.1, 3.261], [64712.1, 0.048], [64752.7, 3.049], [64830.5, 5.4], [64847.4, 10.621], [64886.3, 9.223], [65013.5, 0.769], [65336.9, 0.002], [65690.0, 0.413], [65768.7, 0.0], [65983.7, 0.003], [67277.5, 0.015]]}
{"kind": "depth", "E": 1787095361667, "U": 11316373999633, "u": 11316374005194, "recv_ms": 1787095361724, "bids": [[14389.9, 2.52], [14489.9, 1.68], [51752.0, 0.0], [58220.9, 0.002], [61455.4, 0.004], [62102.3, 0.144], [63396.2, 0.029], [64043.0, 0.032], [64366.5, 0.0], [64531.1, 11.051], [64588.7, 0.001], [64668.3, 0.155], [64673.5, 3.817], [64682.7, 0.006], [64683.2, 0.001]], "asks": [[64690.0, 22.774], [64693.1, 0.098], [64698.1, 0.116], [64706.0, 0.389], [64717.9, 0.0], [64767.5, 0.295], [64767.6, 1.247], [64805.6, 0.1], [64886.3, 9.578], [65336.9, 0.002], [65563.3, 1.475]]}
{"kind": "depth", "E": 1787095361769, "U": 11316374005352, "u": 11316374013760, "recv_ms": 1787095361826, "bids": [[1000.0, 35.76], [14389.9, 2.87], [14489.9, 1.33], [51752.0, 0.0], [58220.9, 0.002], [61455.4, 0.004], [62102.3, 0.147], [63689.9, 0.03], [63803.6, 1.25], [63805.7, 5.001], [63870.4, 4.887], [64043.0, 0.032], [64366.4, 1.176], [64492.3, 3.281], [64650.0, 3.621], [64651.0, 0.015], [64658.0, 0.01], [64659.2, 1.204], [64668.1, 0.179], [64668.3, 0.001], [64683.2, 0.001], [64686.1, 0.0], [64687.2, 0.004], [64689.9, 5.399]], "asks": [[64694.3, 0.425], [64698.1, 0.219], [64713.9, 2.976], [64718.1, 0.159], [64718.8, 0.039], [64718.9, 0.005], [64719.0, 0.002], [64721.8, 0.451], [64721.9, 5.71], [64722.0, 1.547], [64722.8, 0.005], [64722.9, 0.005], [64723.0, 0.018], [64724.9, 0.036], [64725.0, 0.064], [64725.1, 0.0], [64765.6, 1.142], [64767.9, 0.0], [64778.9, 48.586], [64830.2, 2.116], [64886.3, 10.498], [65013.5, 0.77], [65336.9, 0.002], [65498.6, 3.95], [65690.0, 0.433]]}
{"kind": "depth", "E": 1787095361871, "U": 11316374013884, "u": 11316374021048, "recv_ms": 1787095361928, "bids": [[1000.0, 35.76], [14389.9, 3.234], [14489.9, 0.966], [58220.9, 0.002], [61455.4, 0.004], [62102.3, 0.144], [63606.4, 1.099], [63745.4, 0.783], [63816.6, 5.037], [64043.0, 0.032], [64492.2, 0.556], [64492.3, 11.03], [64531.1, 10.784], [64548.0, 24.271], [64548.1, 4.277], [64651.0, 0.043], [64668.1, 0.025], [64672.6, 0.0], [64673.4, 0.559], [64679.4, 0.105], [64679.8, 0.1], [64682.2, 0.129], [64682.8, 0.02], [64683.2, 0.001], [64689.9, 5.243]], "asks": [[64690.0, 22.773], [64694.3, 0.2], [64767.9, 48.597], [64770.9, 0.223], [64778.9, 0.005], [64830.5, 5.4], [64886.3, 10.539], [65336.9, 0.002], [65643.8, 0.54]]}
{"kind": "depth", "E": 1787095361973, "U": 11316374021128, "u": 11316374027282, "recv_ms": 1787095362031, "bids": [[14389.9, 3.584], [14489.9, 0.616], [58220.9, 0.0], [62102.3, 0.147], [63380.1, 0.001], [63452.0, 0.226], [63523.8, 0.0], [63595.7, 0.003], [63667.6, 0.822], [63689.9, 0.01], [63739.4, 0.015], [63811.3, 0.002], [63837.2, 1.565], [63881.3, 3.164], [63883.1, 0.0], [63955.0, 0.393], [64026.9, 0.002], [64043.0, 0.032], [64366.5, 0.01], [64651.0, 0.015], [64668.3, 0.155], [64672.6, 0.0], [64673.4, 0.002], [64673.6, 1.834], [64679.7, 0.34], [64679.8, 0.023], [64682.2, 0.129], [64683.2, 0.001], [64683.3, 0.151], [64684.3, 0.548], [64686.3, 0.184], [64689.9, 5.244]], "asks": [[64690.0, 22.773], [65320.3, 4.309], [65336.9, 0.002], [65392.2, 0.009], [65464.1, 0.009], [65535.9, 0.002], [65607.8, 0.016], [65679.6, 0.379], [65690.0, 0.413], [65751.5, 0.0], [65823.4, 0.0], [65866.2, 1.517], [65895.2, 0.0], [65967.1, 3.936], [66024.8, 0.001]]}
{"kind": "depth", "E": 1787095362075, "U": 11316374027287, "u": 11316374033969, "recv_ms": 1787095362132, "bids": [[1000.0, 35.76], [14289.9, 0.084], [14389.9, 3.78], [14489.9, 0.336], [58220.9, 0.002], [61455.4, 0.004], [63706.1, 0.379], [63900.1, 2.265], [64043.0, 0.032], [64579.9, 0.0], [64631.6, 1.24], [64651.0, 0.015], [64668.2, 0.17], [64668.3, 0.001], [64678.3, 0.021], [64683.2, 0.447], [64689.9, 5.247]], "asks": [[64691.8, 0.532], [64692.3, 0.037], [64735.3, 0.267], [64741.8, 0.003], [64767.7, 0.0], [65336.9, 0.002], [65482.0, 16.121], [65660.3, 0.342], [65673.8, 0.016]]}
{"kind": "depth", "E": 1787095362279, "U": 11316374046593, "u": 11316374056359, "recv_ms": 1787095362336, "bids": [[14289.9, 0.56], [14389.9, 3.542], [14489.9, 0.098], [51752.0, 0.0], [58220.9, 0.002], [61455.4, 0.004], [62102.3, 0.147], [63914.7, 0.0], [64043.0, 0.032], [64366.5, 0.0], [64531.1, 4.627], [64531.2, 1.926], [64548.1, 0.038], [64621.1, 0.001], [64637.3, 0.001], [64651.0, 0.015], [64668.1, 0.179], [64668.2, 0.016], [64670.6, 1.082], [64676.0, 1.479], [64678.0, 0.627], [64678.6, 0.514], [64679.7, 0.34], [64682.2, 0.129], [64683.2, 0.001], [64686.3, 0.1], [64689.9, 5.248]], "asks": [[64698.1, 0.116], [64701.5, 0.618], [64830.2, 1.501], [64830.5, 0.001], [64844.9, 1.542], [64847.4, 0.212], [65336.9, 0.002], [65579.0, 52.305], [65643.8, 0.198], [65673.7, 0.038]]}
{"kind": "depth", "E": 1787095362381, "U": 11316374056557, "u": 11316374062484, "recv_ms": 1787095362441, "bids": [[1000.0, 35.91], [14289.9, 0.812], [14389.9, 3.388], [14489.9, 0.0], [51751.9, 0.0], [58220.9, 0.002], [61455.4, 0.004], [62102.3, 0.144], [63061.9, 0.635], [63689.9, 0.01], [63920.1, 4.687], [64043.0, 0.032], [64492.3, 4.161], [64531.1, 6.957], [64548.1, 1.535], [64583.8, 0.0], [64583.9, 0.003], [64668.0, 0.373], [64668.1, 0.025], [64679.7, 0.34], [64682.2, 0.129], [64683.2, 0.001], [64686.4, 0.087], [64689.9, 5.25]], "asks": [[64690.0, 22.772], [64698.1, 0.219], [64718.9, 0.007], [64719.0, 0.004], [64719.1, 0.021], [64721.8, 0.453], [64721.9, 5.712], [64722.0, 1.549], [64722.8, 0.007], [64722.9, 0.007], [64723.0, 0.02], [64724.9, 0.038], [64725.0, 0.066], [64725.1, 0.002], [64741.8, 0.012], [64830.5, 5.4], [64847.5, 10.414], [64886.3, 13.295], [65283.7, 7.531], [65336.9, 0.002], [65611.4, 19.977], [65663.9, 0.342], [65690.0, 0.413]]}
{"kind": "depth", "E": 1787095362483, "U": 11316374062555, "u": 11316374068369, "recv_ms": 1787095362554, "bids": [[1000.0, 35.76], [14289.9, 1.176], [14389.9, 3.024], [58220.9, 0.002], [61455.4, 0.004], [61455.5, 0.006], [62102.3, 0.147], [63901.8, 2.37], [64043.0, 0.032], [64122.1, 0.0], [64140.4, 0.0], [64384.2, 0.004], [64541.4, 0.029], [64575.9, 0.0], [64576.0, 2.007], [64588.7, 0.006], [64609.6, 1.367], [64627.9, 0.0], [64635.8, 0.0], [64670.6, 0.464], [64678.0, 0.009], [64682.7, 0.001], [64683.2, 0.447], [64689.9, 5.248]], "asks": [[64697.8, 0.111], [64701.5, 0.0], [64727.0, 0.336], [64752.7, 0.018], [64752.9, 0.058], [64798.8, 0.037], [64820.3, 0.003], [64975.6, 0.003], [65013.5, 0.769], [65234.6, 0.002], [65336.9, 0.001], [65510.4, 3.963], [65595.7, 13.285], [65643.7, 12.011], [65646.4, 1.368]]}
{"kind": "depth", "E": 1787095362585, "U": 11316374068560, "u": 11316374073538, "recv_ms": 1787095362642, "bids": [[14289.9, 1.526], [14389.9, 2.674], [51752.0, 0.0], [58220.9, 0.002], [61455.4, 0.006], [63072.7, 2.138], [63396.2, 0.023], [63689.9, 0.03], [63821.5, 3.911], [63961.3, 0.0], [64043.0, 0.032], [64366.4, 1.177], [64366.5, 0.01], [64492.3, 11.588], [64531.1, 11.05], [64548.1, 4.441], [64580.1, 16.333], [64591.7, 0.171], [64598.2, 0.004], [64627.9, 2.696], [64637.6, 0.0], [64639.7, 2.319], [64647.7, 0.161], [64673.5, 3.815], [64679.0, 0.991], [64683.2, 0.001], [64689.9, 5.403]], "asks": [[64698.1, 0.116], [64706.0, 0.387], [64740.8, 1.336], [64747.3, 1.468], [64752.7, 3.026], [64800.6, 10.475], [64886.3, 9.576], [65336.9, 0.001], [65628.0, 8.972], [65660.3, 0.684], [65690.0, 0.433], [65778.5, 3.29]]}
{"kind": "depth", "E": 1787095362687, "U": 11316374073694, "u": 11316374088321, "recv_ms": 1787095362744, "bids": [[1000.0, 35.76], [14289.9, 1.89], [14389.9, 2.31], [58220.9, 0.002], [61455.4, 0.006], [62102.3, 0.144], [64043.0, 0.032], [64492.4, 3.266], [64588.7, 0.001], [64591.7, 0.095], [64598.2, 0.0], [64633.2, 0.077], [64639.7, 2.323], [64653.6, 0.003], [64668.0, 0.373], [64672.6, 0.557], [64673.5, 3.817], [64673.6, 1.277], [64682.7, 0.006], [64683.2, 0.001], [64683.3, 0.151], [64684.2, 0.967], [64684.3, 0.548], [64684.8, 0.247], [64689.9, 5.402]], "asks": [[64691.4, 0.084], [64691.9, 0.33], [64699.6, 0.14], [64706.0, 0.389], [64707.4, 1.594], [64711.0, 2.872], [64712.2, 0.258], [64712.5, 0.006], [64734.9, 0.007], [64741.4, 0.221], [64765.6, 8.253], [64767.9, 0.0], [64775.0, 0.25], [64778.9, 48.602], [64781.4, 0.0], [64830.2, 2.116], [64886.3, 9.577], [65304.6, 4.039], [65336.9, 0.001], [65478.1, 3.815], [65660.4, 0.769], [65778.5, 2.684]]}
{"kind": "depth", "E": 1787095362789, "U": 11316374088699, "u": 11316374097590, "recv_ms": 1787095362846, "bids": [[14289.9, 2.24], [14389.9, 1.96], [58220.9, 0.002], [62102.3, 0.147], [63278.0, 0.003], [63279.9, 0.002], [63689.9, 0.01], [63816.6, 5.82], [63973.3, 0.473], [64043.0, 0.032], [64156.3, 0.893], [64588.7, 0.006], [64670.1, 0.0], [64671.0, 0.121], [64671.8, 0.001], [64676.3, 1.055], [64677.1, 0.555], [64678.1, 0.222], [64682.7, 0.001], [64683.2, 0.001], [64684.3, 0.548], [64685.4, 1.547]], "asks": [[64698.1, 0.193], [64709.3, 2.751], [64710.5, 0.46], [64712.0, 1.546], [64713.1, 0.058], [64713.5, 0.655], [64713.6, 0.816], [64714.6, 0.556], [64714.7, 0.146], [64765.6, 1.142], [64767.9, 48.657], [64770.8, 0.09], [64770.9, 0.307], [64778.9, 0.005], [64882.6, 0.0], [65013.5, 0.768], [65336.9, 0.003], [65690.0, 0.413], [65789.7, 6.523], [65801.5, 2.278], [65983.7, 0.006], [71159.0, 0.002]]}
{"kind": "depth", "E": 1787095362891, "U": 11316374097638, "u": 11316374108028, "recv_ms": 1787095362948, "bids": [[14289.9, 2.604], [14389.9, 1.596], [58220.9, 0.002], [61455.4, 0.005], [61455.5, 0.008], [62102.3, 0.144], [63671.1, 14.26], [63743.6, 0.0], [64043.0, 0.032], [64366.4, 1.178], [64366.5, 0.0], [64548.1, 0.038], [64548.2, 4.403], [64574.7, 5.129], [64588.7, 0.001], [64618.9, 0.06], [64619.0, 0.013], [64667.9, 0.156], [64668.0, 0.219], [64670.1, 0.116], [64671.0, 0.005], [64676.3, 1.514], [64677.1, 0.096], [64682.7, 0.006], [64683.0, 0.004], [64683.1, 0.639], [64683.2, 0.542], [64683.4, 0.007], [64684.3, 0.007], [64685.1, 0.004], [64686.9, 0.101], [64687.3, 0.084], [64687.8, 0.053], [64689.3, 0.039], [64689.9, 5.247]], "asks": [[64690.2, 0.004], [64694.7, 1.42], [64698.1, 0.2], [64708.8, 1.83], [64710.5, 0.001], [64713.0, 0.673], [64714.6, 0.0], [64714.7, 0.031], [64727.0, 0.333], [64739.2, 0.003], [64761.3, 0.048], [64761.4, 2.645], [64825.6, 4.36], [64830.5, 5.4], [64886.3, 9.457], [65336.9, 0.001], [65623.1, 2.13], [65789.7, 7.129]]}
{"kind": "depth", "E": 1787095362993, "U": 11316374108117, "u": 11316374114422, "recv_ms": 1787095363052, "bids": [[1000.0, 35.76], [14289.9, 2.954], [14389.9, 1.246], [58220.9, 0.002], [60425.2, 0.004], [61455.4, 0.002], [61455.5, 0.01], [62086.8, 0.689], [63578.4, 0.792], [63689.9, 0.03], [64043.0, 0.032], [64679.7, 0.34], [64682.2, 0.129], [64683.2, 0.001], [64684.3, 0.548], [64685.1, 0.001], [64685.5, 0.009], [64687.3, 0.0], [64689.9, 5.25]], "asks": [[64690.3, 0.095], [64692.5, 0.001], [64694.1, 0.294], [64694.3, 0.2], [64694.6, 0.931], [64698.1, 0.219], [64708.8, 1.371], [64709.7, 1.344], [64713.0, 0.002], [64713.8, 0.715], [64713.9, 3.091], [64727.0, 0.496], [65336.9, 0.001], [65478.1, 4.578], [65690.0, 0.433], [65899.7, 2.423]]}
{"kind": "depth", "E": 1787095363197, "U": 11316374123703, "u": 11316374134247, "recv_ms": 1787095363258, "bids": [[14289.9, 3.668], [14389.9, 0.532], [58220.9, 0.002], [61455.4, 0.002], [61455.5, 0.008], [62102.3, 0.144], [63380.0, 0.387], [63385.4, 0.0], [63451.9, 0.067], [63523.7, 0.912], [63595.6, 0.067], [63667.5, 0.058], [63689.9, 0.01], [63706.1, 0.388], [63739.3, 0.058], [63751.9, 10.567], [63811.2, 0.058], [63883.0, 0.214], [63900.1, 1.563], [63954.9, 0.059], [63966.5, 2.358], [64026.8, 4.554], [64043.0, 0.034], [64366.5, 0.01], [64609.3, 0.007], [64637.4, 0.001], [64640.6, 0.387], [64667.8, 0.0], [64671.8, 0.008], [64679.7, 0.239], [64682.2, 0.206], [64689.9, 5.246]], "asks": [[64692.5, 0.011], [64693.2, 0.099], [64695.3, 0.001], [64712.1, 0.05], [64730.4, 1.082], [64736.8, 3.294], [64743.3, 0.97], [64749.8, 1.935], [65320.2, 1.273], [65336.9, 0.001], [65392.1, 0.068], [65464.0, 1.618], [65535.8, 0.058], [65607.7, 0.059], [65608.6, 0.46], [65628.0, 9.657], [65679.5, 0.059], [65690.0, 0.413], [65751.4, 0.062], [65823.3, 0.058], [65895.1, 0.075], [65967.0, 0.059], [66237.1, 0.646], [68571.3, 0.0]]}
{"kind": "depth", "E": 1787095363299, "U": 11316374134329, "u": 11316374140302, "recv_ms": 1787095363356, "bids": [[1000.0, 35.76], [14189.9, 0.14], [14289.9, 3.752], [14389.9, 0.308], [51752.0, 0.0], [58220.9, 0.002], [62102.3, 0.147], [63790.7, 1.567], [64043.0, 0.032], [64218.8, 0.0], [64531.1, 4.627], [64548.2, 0.0], [64588.7, 0.006], [64679.7, 0.239], [64682.2, 0.23], [64682.7, 0.001]], "asks": [[64767.9, 0.0], [64778.9, 48.662], [64830.2, 1.501], [64830.5, 0.001], [64847.5, 0.005], [65336.9, 0.001], [65673.8, 0.026], [65789.7, 8.039], [65895.4, 4.097]]}
{"kind": "depth", "E": 1787095363401, "U": 11316374140521, "u": 11316374150452, "recv_ms": 1787095363457, "bids": [[14189.9, 0.392], [14289.9, 3.612], [14389.9, 0.196], [51751.9, 0.0], [51752.0, 0.0], [58220.9, 0.002], [60808.5, 0.087], [61455.4, 0.002], [62102.3, 0.144], [63689.9, 0.03], [63950.5, 3.912], [64043.0, 0.032], [64219.2, 0.002], [64492.3, 0.008], [64492.4, 11.525], [64531.2, 7.779], [64534.1, 1.965], [64548.2, 4.072], [64579.9, 0.0], [64588.7, 0.001], [64631.6, 1.24], [64670.7, 0.62], [64678.0, 0.627], [64679.4, 0.121], [64679.7, 0.316], [64679.8, 0.003], [64682.2, 0.153], [64682.7, 0.006], [64686.8, 0.893], [64689.9, 5.249]], "asks": [[64693.0, 0.123], [64693.2, 0.089], [64698.1, 0.193], [64701.6, 0.618], [64735.3, 0.267], [64767.7, 0.0], [64769.1, 0.158], [64769.2, 0.199], [64770.1, 48.663], [64778.9, 0.005], [64830.5, 5.4], [64847.5, 10.414], [64886.3, 10.507], [65336.9, 0.001], [65690.0, 0.433], [65740.7, 4.054], [65778.5, 2.154], [67924.5, 0.032]]}
{"kind": "depth", "E": 1787095363503, "U": 11316374150542, "u": 11316374160594, "recv_ms": 1787095363560, "bids": [[14189.9, 0.616], [14289.9, 3.514], [14389.9, 0.07], [58220.9, 0.002], [61455.4, 0.002], [64043.0, 0.032], [64366.5, 0.0], [64588.7, 0.006], [64622.6, 0.377], [64675.1, 0.018], [64677.9, 0.0], [64679.8, 0.027], [64682.2, 0.129], [64682.7, 0.001], [64685.5, 0.009], [64686.7, 0.088]], "asks": [[64690.0, 22.726], [64690.8, 0.019], [64692.5, 0.001], [64693.1, 0.175], [64693.2, 0.127], [64698.1, 0.219], [64770.9, 0.223], [65336.9, 0.001], [65789.7, 8.569], [65916.5, 4.092]]}
{"kind": "depth", "E": 1787095363605, "U": 11316374160832, "u": 11316374166933, "recv_ms": 1787095363661, "bids": [[1000.0, 35.76], [14189.9, 0.896], [14289.9, 3.304], [14389.9, 0.0], [58220.9, 0.002], [61455.4, 0.002], [62102.3, 0.147], [63689.9, 0.01], [63792.8, 1.876], [64043.0, 0.032], [64366.4, 1.177], [64548.2, 4.076], [64679.8, 0.027], [64682.2, 0.129], [64686.4, 0.087], [64686.7, 0.004], [64689.9, 5.248]], "asks": [[64690.0, 22.752], [64692.5, 0.011], [64693.2, 0.137], [64694.3, 0.2], [64697.8, 0.001], [64830.5, 5.4], [64884.1, 0.113], [64886.3, 10.34], [65013.5, 0.769], [65283.7, 6.767], [65336.9, 0.001], [65482.0, 15.779], [65611.4, 18.911], [65676.0, 11.688], [65690.0, 0.413], [65757.4, 1.064], [71159.0, 0.002]]}
{"kind": "depth", "E": 1787095363809, "U": 11316374172814, "u": 11316374182041, "recv_ms": 1787095363866, "bids": [[1000.0, 35.76], [14189.9, 1.624], [14289.9, 2.576], [51752.0, 0.0], [58220.9, 0.002], [62102.3, 0.147], [63689.9, 0.03], [63784.2, 7.597], [63869.5, 0.791], [64043.0, 0.032], [64161.6, 0.0], [64290.9, 0.008], [64366.4, 1.176], [64366.5, 0.01], [64492.5, 3.316]], "asks": [[64712.2, 0.26], [64768.4, 8.552], [64830.2, 2.116], [65267.4, 0.26], [65304.6, 4.802], [65336.9, 0.001], [65414.5, 0.008], [65526.1, 0.762], [65646.4, 1.026], [65690.0, 0.433]]}
{"kind": "depth", "E": 1787095363911, "U": 11316374182106, "u": 11316374190969, "recv_ms": 1787095363967, "bids": [[1000.0, 35.76], [14189.9, 1.974], [14289.9, 2.226], [58220.9, 0.002], [61455.5, 0.006], [62102.3, 0.144], [63803.6, 1.875], [63865.1, 17.279], [64043.0, 0.032], [64492.4, 0.001], [64492.5, 0.06], [64531.2, 1.926], [64534.1, 1.252], [64536.2, 0.001], [64548.2, 0.0], [64555.5, 0.008], [64683.6, 0.235], [64684.8, 0.015]], "asks": [[64734.9, 0.003], [64744.7, 0.009], [64830.2, 1.501], [64830.5, 0.001], [64847.5, 0.005], [64886.3, 0.942], [65013.5, 0.77], [65336.9, 0.001], [65498.6, 4.208], [65628.0, 10.722], [65692.7, 4.863]]}
{"kind": "depth", "E": 1787095364013, "U": 11316374190986, "u": 11316374198384, "recv_ms": 1787095364070, "bids": [[14189.9, 2.324], [14289.9, 1.876], [58220.9, 0.002], [61455.4, 0.002], [63689.9, 0.01], [63934.2, 2.343], [64043.0, 0.032], [64492.5, 11.702], [64531.3, 5.902], [64548.2, 4.076], [64582.4, 0.005], [64582.6, 3.094], [64599.7, 0.059], [64600.0, 3.727]], "asks": [[64690.0, 22.747], [64718.9, 0.005], [64719.0, 0.002], [64719.1, 0.019], [64721.8, 0.451], [64721.9, 5.71], [64722.0, 1.547], [64722.8, 0.005], [64722.9, 0.005], [64723.0, 0.018], [64724.9, 0.036], [64725.0, 0.064], [64725.1, 0.0], [64796.3, 0.038], [64796.4, 2.319], [64830.5, 5.4], [64847.5, 10.414], [64874.9, 2.753], [64875.0, 0.35], [64886.3, 10.341], [65272.2, 2.294], [65336.9, 0.001], [65455.1, 19.404], [65531.0, 3.036], [65535.1, 0.306], [65660.3, 1.026], [65690.0, 0.413], [67919.2, 0.0]]}
{"kind": "depth", "E": 1787095364115, "U": 11316374198577, "u": 11316374204330, "recv_ms": 1787095364177, "bids": [[1000.0, 35.76], [14189.9, 2.688], [14289.9, 1.512], [51752.0, 0.0], [58220.9, 0.002], [61455.5, 0.004], [62102.3, 0.147], [64043.0, 0.032], [64366.5, 0.01], [64593.1, 1.352], [64609.2, 0.382], [64609.3, 0.005], [64624.4, 0.141], [64629.6, 1.169], [64637.4, 0.0], [64640.5, 0.001], [64640.6, 0.386], [64645.7, 0.103], [64645.8, 0.237], [64678.3, 0.021], [64685.5, 0.009]], "asks": [[64694.3, 0.2], [64694.7, 1.421], [64717.6, 0.155], [64718.1, 0.005], [65336.9, 0.001], [65387.7, 0.229], [65983.7, 0.009], [66413.0, 0.302], [67277.5, 0.002]]}
{"kind": "depth", "E": 1787095364217, "U": 11316374204433, "u": 11316374210557, "recv_ms": 1787095364275, "bids": [[1000.0, 35.76], [14189.9, 3.052], [14289.9, 1.148], [51752.0, 0.0], [58220.9, 0.002], [61455.4, 0.002], [62102.3, 0.144], [63689.9, 0.03], [63766.9, 0.557], [64043.0, 0.032], [64496.6, 0.0], [64506.2, 0.579], [64653.6, 0.003], [64670.7, 0.002], [64678.0, 0.009], [64685.5, 0.009], [64689.9, 5.24]], "asks": [[64694.7, 1.42], [64701.6, 0.0], [64717.6, 0.155], [64886.3, 14.85], [65336.9, 0.001], [65690.0, 0.433]]}
{"kind": "depth", "E": 1787095364319, "U": 11316374210597, "u": 11316374216716, "recv_ms": 1787095364376, "bids": [[14189.9, 3.402], [14289.9, 0.798], [51752.0, 0.0], [58220.9, 0.002], [62102.3, 0.147], [63396.2, 0.02], [63837.2, 2.347], [63865.1, 16.809], [64043.0, 0.032], [64531.3, 6.452], [64638.2, 0.422], [64674.1, 0.008], [64685.5, 0.455]], "asks": [[64717.6, 0.001], [64717.8, 0.336], [64767.9, 48.657], [64768.4, 1.163], [64769.2, 0.122], [64770.1, 0.006], [64886.3, 9.482], [65336.9, 0.001], [65466.3, 18.891], [66436.6, 0.903]]}
{"kind": "depth", "E": 1787095364421, "U": 11316374216869, "u": 11316374222113, "recv_ms": 1787095364479, "bids": [[1000.0, 35.76], [14189.9, 3.696], [14289.9, 0.476], [14589.9, 0.028], [51751.9, 0.0], [58220.9, 0.002], [61455.4, 0.002], [63689.9, 0.01], [63918.5, 0.0], [64043.0, 0.032], [64261.0, 5.006], [64356.3, 0.005], [64366.5, 0.0], [64548.2, 0.0], [64548.3, 4.076], [64589.9, 0.0], [64593.8, 0.024], [64594.7, 0.02], [64598.4, 0.811], [64599.5, 0.0], [64604.3, 0.0], [64609.1, 0.001], [64613.9, 0.0], [64618.7, 0.147], [64623.5, 0.311], [64628.3, 2.071], [64633.1, 0.001], [64637.9, 0.076], [64642.7, 0.001], [64647.5, 0.015], [64652.3, 0.049], [64657.1, 0.019], [64661.9, 0.002], [64666.7, 0.049], [64670.7, 0.62], [64671.5, 0.002], [64676.3, 1.499], [64678.0, 0.627], [64678.5, 0.595], [64685.5, 0.455], [64689.9, 5.395]], "asks": [[64690.0, 22.746], [64692.5, 0.001], [64693.2, 0.127], [64701.5, 0.618], [64717.8, 0.49], [64718.1, 0.001], [64733.3, 1.692], [64735.6, 1.309], [64739.2, 0.012], [64741.8, 0.003], [64748.1, 1.0], [64750.5, 0.015], [64750.7, 1.469], [64755.1, 0.015], [64755.5, 0.393], [64760.3, 0.0], [64765.1, 0.0], [64767.9, 0.0], [64769.9, 0.019], [64774.7, 1.083], [64778.9, 48.817], [64779.5, 0.027], [64797.3, 0.005], [64830.5, 5.4], [64847.7, 0.001], [64875.5, 0.003], [64886.3, 10.5], [64888.5, 0.004], [64965.5, 0.084], [65336.9, 0.001], [65401.6, 0.229], [65616.8, 6.202], [65690.0, 0.413]]}
{"kind": "depth", "E": 1787095364523, "U": 11316374222317, "u": 11316374227963, "recv_ms": 1787095364615, "bids": [[1000.0, 35.76], [14189.9, 3.724], [14289.9, 0.28], [14589.9, 0.196], [58220.9, 0.002], [62102.3, 0.144], [63895.1, 0.0], [64043.0, 0.032], [64135.3, 0.109], [64396.1, 0.07], [64552.6, 0.523], [64588.7, 0.001], [64593.4, 0.011], [64597.0, 2.78], [64598.1, 0.001], [64601.5, 0.006], [64602.8, 0.002], [64603.0, 0.017], [64607.5, 0.0], [64612.2, 0.002], [64616.9, 0.007], [64620.4, 0.011], [64621.6, 0.001], [64646.4, 0.181], [64668.6, 0.003], [64673.3, 0.119], [64685.5, 0.455]], "asks": [[64693.2, 0.089], [64730.4, 0.116], [64736.7, 0.124], [64736.8, 2.328], [64738.7, 0.039], [64741.4, 0.182], [64741.7, 0.005], [64741.8, 0.012], [64741.9, 0.0], [64743.3, 0.004], [64746.2, 0.006], [64746.6, 0.002], [64749.8, 0.004], [64751.3, 0.001], [64756.0, 1.298], [64759.7, 0.018], [64762.5, 0.014], [64770.1, 48.818], [64770.9, 0.307], [64774.8, 0.012], [64778.9, 0.005], [64779.5, 0.022], [64829.5, 0.029], [64949.9, 0.417], [64969.6, 5.375], [64984.0, 0.065], [65241.7, 0.398], [65336.9, 0.001], [65518.1, 0.267]]}
{"kind": "depth", "E": 1787095364625, "U": 11316374227965, "u": 11316374232944, "recv_ms": 1787095364682, "bids": [[14189.9, 3.598], [14289.9, 0.168], [14589.9, 0.434], [58220.9, 0.002], [61455.4, 0.002], [62102.3, 0.147], [63396.2, 0.017], [63689.9, 0.03], [64043.0, 0.032], [64531.3, 5.858], [64548.3, 4.274], [64579.9, 0.003], [64606.0, 0.006], [64607.6, 0.018], [64612.2, 0.017], [64625.2, 0.02], [64626.3, 0.001], [64631.0, 0.9], [64631.6, 1.237], [64635.7, 0.008], [64640.4, 0.313], [64645.1, 0.034], [64649.8, 1.205], [64654.5, 0.0], [64659.2, 1.199], [64663.9, 1.721], [64670.7, 0.002], [64678.0, 0.009], [64685.5, 0.455], [64686.8, 0.893], [64688.4, 0.001], [64689.9, 5.261]], "asks": [[64692.5, 0.001], [64693.2, 0.127], [64712.2, 0.258], [64735.3, 0.267], [64750.7, 1.474], [64754.7, 6.989], [64760.7, 0.061], [64764.3, 0.015], [64765.4, 0.377], [64767.9, 48.812], [64768.9, 0.016], [64770.1, 0.001], [64770.9, 0.223], [64830.5, 5.4], [64847.5, 10.414], [64886.3, 10.308], [64967.9, 0.984], [65013.5, 0.769], [65336.9, 0.001], [65482.0, 15.262], [65579.0, 51.849], [65623.1, 1.065], [65690.0, 0.433]]}
{"kind": "depth", "E": 1787095364727, "U": 11316374233377, "u": 11316374239235, "recv_ms": 1787095364783, "bids": [[1000.0, 35.76], [14189.9, 3.486], [14289.9, 0.042], [14589.9, 0.672], [58220.9, 0.002], [62102.3, 0.833], [63755.1, 2.587], [64043.0, 0.032], [64366.5, 0.01], [64511.9, 0.0], [64527.1, 0.002], [64610.5, 0.153], [64615.0, 0.182], [64616.8, 0.017], [64673.5, 3.817], [64685.5, 0.009]], "asks": [[64706.0, 0.389], [64755.2, 0.012], [64759.7, 0.023], [64773.5, 0.025], [65336.9, 0.001], [65429.2, 1.535], [65628.0, 10.836]]}
{"kind": "depth", "E": 1787095364829, "U": 11316374239372, "u": 11316374244953, "recv_ms": 1787095364887, "bids": [[1000.0, 35.76], [14189.9, 3.22], [14289.9, 0.0], [14589.9, 0.98], [58220.9, 0.002], [61455.4, 0.002], [62102.3, 0.836], [63396.2, 0.014], [63689.9, 0.01], [63821.5, 3.129], [64043.0, 0.032], [64366.4, 1.177], [64492.6, 3.285], [64534.1, 1.966], [64548.3, 0.0], [64619.5, 0.007], [64621.4, 0.445], [64626.0, 0.016], [64632.9, 0.014], [64653.6, 0.045], [64657.0, 0.005], [64657.1, 0.021], [64657.2, 0.064], [64660.4, 4.974], [64660.5, 1.332], [64660.6, 0.028], [64667.9, 0.156], [64674.5, 0.013], [64679.7, 0.34], [64679.8, 0.003], [64682.2, 0.129], [64682.7, 0.085], [64684.8, 0.015], [64685.5, 0.009], [64685.7, 0.082], [64686.4, 0.003], [64689.9, 5.176]], "asks": [[64690.0, 22.684], [64692.5, 0.001], [64693.1, 0.329], [64693.2, 0.204], [64712.0, 1.548], [64721.1, 0.318], [64764.2, 0.005], [64765.6, 1.142], [64767.5, 0.141], [64767.6, 1.209], [64767.9, 0.0], [64769.2, 0.019], [64770.2, 0.0], [64770.8, 0.013], [64770.9, 0.204], [64778.1, 0.031], [64778.9, 48.817], [64830.5, 0.001], [64844.9, 2.898], [65336.9, 0.001], [65540.2, 0.267], [65628.0, 11.901], [65690.0, 0.413], [65782.9, 0.0], [66253.7, 0.646]]}
{"kind": "depth", "E": 1787095364931, "U": 11316374245111, "u": 11316374250023, "recv_ms": 1787095364987, "bids": [[14189.9, 2.856], [14589.9, 1.344], [58220.9, 0.002], [61455.4, 0.002], [63913.6, 30.86], [64043.0, 0.032], [64172.3, 0.342], [64301.8, 0.344], [64366.5, 0.0], [64531.3, 5.858], [64534.1, 1.252], [64548.3, 4.274], [64624.0, 2.354], [64628.5, 0.006], [64630.6, 0.015], [64679.7, 0.34], [64682.2, 0.129], [64685.5, 0.009], [64689.9, 5.176]], "asks": [[64692.5, 0.001], [64736.3, 0.212], [64744.7, 0.005], [64767.9, 48.968], [64768.7, 0.394], [64770.1, 0.001], [64773.2, 0.006], [64778.9, 0.005], [64830.5, 5.4], [64844.9, 1.542], [64847.5, 10.414], [64886.3, 10.309], [65013.5, 0.768], [65142.7, 0.0], [65336.9, 0.001], [65595.7, 13.741]]}
{"kind": "depth", "E": 1787095365033, "U": 11316374250132, "u": 11316374255969, "recv_ms": 1787095365091, "bids": [[1000.0, 35.76], [14189.9, 2.506], [14589.9, 1.694], [58220.9, 0.002], [61455.4, 0.002], [62102.3, 0.833], [63396.2, 0.017], [63689.9, 0.03], [63966.5, 3.139], [64043.0, 0.034], [64366.4, 1.178], [64492.5, 11.631], [64531.3, 5.892], [64548.3, 4.072], [64626.6, 0.059], [64627.9, 0.0], [64628.0, 2.813], [64633.0, 0.008], [64635.2, 2.368], [64639.8, 1.478], [64678.3, 0.026], [64679.7, 0.34], [64682.2, 0.129], [64685.5, 0.009], [64689.9, 5.553]], "asks": [[64692.5, 0.001], [64701.5, 0.0], [64709.5, 0.002], [64752.7, 3.003], [64777.7, 0.105], [64830.5, 5.4], [64886.3, 10.424], [65160.6, 0.081], [65336.9, 0.001], [65690.0, 0.433], [65804.0, 4.107]]}
{"kind": "depth", "E": 1787095365135, "U": 11316374256016, "u": 11316374262338, "recv_ms": 1787095365198, "bids": [[1000.0, 35.76], [14189.9, 2.142], [14589.9, 2.058], [51752.0, 0.0], [58220.9, 0.002], [62102.3, 0.836], [63908.7, 3.345], [64043.0, 0.032], [64609.2, 0.383], [64616.8, 0.015], [64624.4, 0.14], [64631.6, 1.24], [64637.1, 0.213], [64637.3, 0.0], [64637.5, 0.92], [64639.7, 2.319], [64640.3, 0.024], [64640.5, 0.0], [64642.0, 0.021], [64644.4, 0.326], [64645.7, 0.1], [64648.2, 0.469], [64651.0, 0.018], [64678.3, 0.021], [64683.1, 0.686], [64685.5, 0.455], [64686.2, 0.09], [64689.9, 5.554]], "asks": [[64693.2, 0.127], [64697.8, 0.002], [64712.0, 1.546], [64712.1, 0.048], [64767.7, 0.003], [65336.9, 0.001], [65498.6, 4.55]]}
{"kind": "depth", "E": 1787095365237, "U": 11316374262391, "u": 11316374268720, "recv_ms": 1787095365293, "bids": [[14189.9, 1.778], [14589.9, 2.422], [58220.9, 0.002], [61455.4, 0.002], [62102.3, 0.833], [63272.1, 0.023], [63576.7, 1.132], [63689.9, 0.01], [64043.0, 0.032], [64366.5, 0.0], [64548.3, 4.403], [64583.9, 0.0], [64584.0, 2.918], [64621.1, 0.0], [64632.9, 0.027], [64645.5, 0.061], [64646.5, 0.006], [64649.0, 0.374], [64653.6, 0.018], [64667.8, 0.154], [64667.9, 0.002], [64683.6, 0.003], [64684.0, 0.235], [64684.1, 0.0], [64685.5, 0.455], [64685.7, 0.085], [64686.0, 0.006], [64686.2, 0.006], [64686.7, 0.088], [64687.1, 0.011], [64687.5, 0.382], [64689.9, 5.553]], "asks": [[64690.0, 22.184], [64693.1, 0.175], [64693.2, 0.089], [64694.6, 0.928], [64698.1, 0.219], [64706.2, 0.256], [64712.9, 0.111], [64713.1, 0.062], [64713.3, 0.032], [64721.1, 0.374], [64800.0, 21.198], [64830.5, 5.4], [64886.3, 9.576], [65336.9, 0.001], [65690.0, 0.413]]}
{"kind": "depth", "E": 1787095365339, "U": 11316374268790, "u": 11316374274353, "recv_ms": 1787095365396, "bids": [[1000.0, 35.76], [14189.9, 1.428], [14589.9, 2.772], [58220.9, 0.002], [61455.4, 0.002], [62687.9, 0.036], [64043.0, 0.032], [64548.3, 0.0], [64632.9, 0.055], [64651.0, 0.023], [64655.5, 0.058], [64658.2, 0.024], [64667.6, 0.005], [64667.7, 0.005], [64667.8, 0.0], [64668.0, 0.373], [64668.2, 0.016], [64685.5, 0.009], [64685.7, 0.082], [64685.8, 0.089], [64686.7, 0.004], [64689.9, 5.553]], "asks": [[64690.0, 22.684], [64692.5, 0.001], [64693.1, 0.329], [64693.2, 0.204], [64694.4, 0.308], [64713.3, 0.018], [64717.8, 0.336], [64830.5, 0.001], [65336.9, 0.001], [65983.7, 0.006]]}
{"kind": "depth", "E": 1787095365441, "U": 11316374274395, "u": 11316374279057, "recv_ms": 1787095365498, "bids": [[1000.0, 35.76], [14189.9, 1.078], [14589.9, 3.122], [51751.9, 0.0], [58220.9, 0.002], [61455.4, 0.002], [62102.3, 0.836], [63689.9, 0.03], [63821.5, 2.346], [63869.5, 1.573], [63913.6, 31.64], [64043.0, 0.032], [64548.4, 4.404], [64660.0, 0.18], [64662.8, 0.108], [64667.4, 0.015], [64668.2, 0.001], [64670.7, 0.62], [64675.3, 0.017], [64678.0, 0.627], [64685.5, 0.455], [64689.9, 5.553]], "asks": [[64690.9, 0.198], [64692.5, 0.011], [64700.8, 2.328], [64701.5, 0.618], [64707.7, 0.1], [64708.9, 0.619], [64718.0, 0.25], [64830.5, 5.4], [64886.3, 9.577], [65336.9, 0.001], [65690.0, 0.433]]}
{"kind": "depth", "E": 1787095365543, "U": 11316374279173, "u": 11316374283628, "recv_ms": 1787095365600, "bids": [[14189.9, 0.714], [14589.9, 3.486], [58220.9, 0.002], [61455.4, 0.004], [62102.3, 0.833], [63396.2, 0.02], [63682.3, 4.392], [63747.0, 4.568], [63755.1, 2.353], [63941.0, 4.842], [63964.3, 4.956], [64043.0, 0.032], [64366.5, 0.01], [64548.4, 0.001], [64664.5, 0.008], [64669.0, 0.907], [64670.1, 0.0], [64670.3, 0.118], [64671.1, 0.003], [64672.0, 0.928], [64672.6, 0.0], [64673.6, 1.834], [64678.0, 0.009], [64683.2, 0.542], [64684.3, 0.007], [64685.5, 0.009], [64687.4, 0.005], [64689.9, 5.555]], "asks": [[64690.0, 22.709], [64692.5, 0.001], [64693.1, 0.252], [64693.2, 0.089], [64701.5, 0.0], [64830.5, 0.001], [65336.9, 0.001], [65740.7, 2.991]]}
{"kind": "depth", "E": 1787095365645, "U": 11316374283681, "u": 11316374290464, "recv_ms": 1787095365702, "bids": [[1000.0, 35.76], [14189.9, 0.42], [14489.9, 0.056], [14589.9, 3.724], [51752.0, 0.0], [58220.9, 0.002], [61455.4, 0.004], [62102.3, 0.836], [63689.9, 0.01], [63865.1, 16.544], [64043.0, 0.032], [64321.6, 0.065], [64322.7, 0.414], [64418.3, 0.123], [64418.9, 0.495], [64489.2, 0.008], [64489.3, 0.009], [64548.4, 4.404], [64672.6, 0.557], [64673.5, 3.822], [64673.6, 1.277], [64674.4, 0.532], [64675.9, 0.012], [64676.6, 4.026], [64683.2, 0.001], [64684.3, 0.548], [64685.5, 0.009], [64686.3, 0.184], [64689.9, 5.556]], "asks": [[64713.0, 0.002], [64713.8, 0.159], [64713.9, 3.647], [64830.5, 5.4], [64886.3, 9.457], [64888.1, 0.176], [64959.4, 0.0], [65056.8, 0.573], [65056.9, 0.0], [65336.9, 0.001], [65526.2, 1.525], [65690.0, 0.413]]}
{"kind": "depth", "E": 1787095365849, "U": 11316374296764, "u": 11316374304153, "recv_ms": 1787095365908, "bids": [[14189.9, 0.14], [14489.9, 0.49], [14589.9, 3.57], [58220.9, 0.002], [61455.4, 0.004], [63396.2, 0.017], [63689.9, 0.03], [64043.0, 0.032], [64091.4, 29.065], [64100.1, 4.342], [64205.9, 0.086], [64300.1, 13.342], [64321.7, 0.0], [64366.5, 0.01], [64488.1, 1.308], [64534.1, 1.971], [64628.0, 0.033], [64628.1, 2.769], [64630.6, 0.015], [64632.9, 0.027], [64637.1, 0.003], [64637.8, 0.21], [64655.6, 1.288], [64656.6, 0.0], [64659.1, 0.038], [64659.6, 0.305], [64661.1, 0.032], [64662.3, 0.067], [64662.8, 0.108], [64663.9, 1.651], [64664.1, 0.061], [64664.2, 8.017], [64664.3, 2.8], [64664.6, 0.082], [64665.6, 0.011], [64670.3, 0.002], [64671.5, 0.082], [64672.4, 0.136], [64672.6, 0.0], [64675.1, 0.575], [64676.3, 1.04], [64678.4, 0.011], [64678.7, 0.614], [64679.1, 0.287], [64679.6, 0.625], [64679.7, 0.239], [64679.8, 0.003], [64682.2, 1.366], [64682.3, 0.125], [64683.0, 0.003], [64683.4, 0.007], [64683.8, 0.004], [64684.0, 0.003], [64684.1, 0.0], [64684.3, 0.007], [64684.4, 0.311], [64684.5, 0.328], [64684.8, 0.011], [64684.9, 0.406], [64685.0, 0.168], [64685.1, 0.0], [64685.3, 0.634], [64685.4, 1.547], [64685.5, 2.213], [64685.6, 0.005], [64685.8, 0.086], [64686.1, 0.003], [64686.8, 0.98], [64687.0, 0.368], [64687.3, 0.084], [64687.4, 0.008], [64687.6, 0.006], [64688.0, 0.088], [64689.0, 0.086], [64689.3, 0.028], [64689.4, 0.051], [64689.8, 0.007], [64689.9, 8.675]], "asks": [[64690.0, 9.65], [64690.1, 0.012], [64690.2, 0.002], [64690.3, 0.011], [64690.7, 0.025], [64691.1, 0.0], [64691.3, 0.002], [64691.4, 0.0], [64691.7, 0.001], [64691.8, 0.448], [64691.9, 0.323], [64692.5, 0.001], [64692.6, 0.27], [64692.9, 0.008], [64693.0, 0.04], [64693.1, 0.329], [64693.2, 0.307], [64693.8, 0.089], [64694.1, 0.222], [64694.2, 0.365], [64694.4, 0.393], [64694.5, 0.25], [64694.6, 1.028], [64694.7, 1.422], [64694.9, 0.08], [64695.0, 0.11], [64695.3, 0.085], [64697.7, 0.05], [64697.8, 0.002], [64698.0, 0.342], [64698.1, 0.219], [64698.2, 0.163], [64698.6, 0.002], [64699.0, 0.107], [64699.1, 2.75], [64699.4, 0.686], [64699.6, 0.06], [64699.9, 0.374], [64700.8, 1.326], [64700.9, 2.542], [64701.0, 2.364], [64704.5, 0.007], [64704.8, 0.076], [64707.7, 0.02], [64708.6, 0.006], [64708.9, 0.001], [64709.2, 0.789], [64709.4, 1.164], [64709.5, 0.004], [64709.7, 0.885], [64710.8, 0.355], [64711.1, 3.72], [64711.6, 0.082], [64712.7, 0.014], [64713.1, 0.005], [64713.9, 2.976], [64714.1, 0.65], [64714.4, 10.174], [64715.2, 2.012], [64715.3, 0.116], [64715.5, 0.559], [64715.9, 0.767], [64716.6, 0.009], [64717.6, 0.001], [64717.7, 6.044], [64717.8, 0.386], [64718.0, 0.096], [64718.8, 0.039], [64719.2, 0.378], [64720.0, 0.615], [64721.1, 0.374], [64721.7, 0.148], [64722.1, 1.279], [64726.1, 0.372], [64729.3, 0.179], [64744.4, 0.387], [64752.7, 3.481], [64765.6, 8.28], [64767.5, 0.064], [64767.6, 1.029], [64769.1, 0.004], [64798.4, 0.593], [64830.2, 2.116], [64830.5, 0.001], [64830.6, 5.399], [64847.5, 10.414], [64875.0, 0.347], [64875.1, 0.004], [64886.3, 0.942], [64886.4, 9.416], [65013.5, 0.769], [65174.0, 0.047], [65323.9, 0.132], [65336.9, 0.001], [65396.9, 0.024], [65591.0, 7.007], [65622.9, 2.13], [65690.0, 0.433], [65983.7, 0.009]]}
{"kind": "depth", "E": 1787095365951, "U": 11316374304298, "u": 11316374308992, "recv_ms": 1787095366008, "bids": [[1000.0, 35.76], [14189.9, 0.014], [14489.9, 0.728], [14589.9, 3.458], [58220.9, 0.002], [61455.4, 0.004], [62102.3, 0.836], [63777.8, 1.88], [63881.3, 3.663], [64043.0, 0.032], [64107.7, 2.805], [64172.4, 3.146], [64323.7, 37.885], [64324.9, 6.254], [64420.4, 29.907], [64421.7, 4.68], [64491.3, 24.157], [64579.9, 0.0], [64631.6, 1.24], [64672.0, 1.044], [64672.4, 0.02], [64674.6, 0.562], [64675.1, 0.018], [64685.6, 0.005], [64686.6, 0.247], [64686.8, 0.977], [64689.9, 8.676]], "asks": [[64690.7, 0.017], [64693.0, 0.265], [64693.3, 0.491], [64694.2, 0.365], [64718.0, 0.25], [64735.3, 0.267], [64767.7, 0.0], [64800.0, 21.195], [64887.9, 51.028], [64959.3, 30.014], [65056.7, 37.655], [65336.9, 0.001], [65387.8, 0.001], [65628.0, 12.966], [65983.7, 0.012]]}
{"kind": "depth", "E": 1787095366053, "U": 11316374309112, "u": 11316374314731, "recv_ms": 1787095366111, "bids": [[1000.0, 35.76], [14189.9, 0.0], [14489.9, 1.064], [14589.9, 3.136], [58220.9, 0.002], [62102.3, 0.833], [63498.2, 1.46], [63603.1, 1.259], [63689.9, 0.01], [63881.3, 3.897], [64043.0, 0.032], [64172.4, 3.142], [64366.4, 1.176], [64646.1, 0.025], [64646.2, 0.522], [64661.3, 1.525], [64662.3, 0.01], [64671.0, 0.121], [64672.0, 0.928], [64673.4, 0.559], [64674.2, 0.0], [64674.6, 0.005], [64677.2, 0.459], [64678.1, 0.222], [64678.3, 0.026], [64678.7, 0.155], [64681.8, 0.002], [64684.2, 0.883], [64684.3, 0.007], [64685.1, 0.001], [64685.4, 2.088], [64685.5, 1.672], [64685.6, 0.005], [64689.6, 0.084], [64689.9, 8.677]], "asks": [[64692.2, 0.011], [64693.0, 0.265], [64694.1, 0.222], [64694.2, 0.484], [64694.5, 0.173], [64694.6, 1.012], [64694.7, 1.438], [64695.7, 0.09], [64699.0, 0.184], [64708.4, 0.39], [64709.6, 0.001], [64710.5, 0.46], [64711.1, 3.261], [64713.7, 0.121], [64713.8, 0.159], [64714.6, 0.556], [64714.7, 0.146], [64715.3, 0.001], [64715.5, 0.003], [64718.0, 0.096], [65202.5, 3.845], [65336.9, 0.001], [65461.2, 11.445], [65602.1, 1.674], [65655.9, 0.001], [65690.0, 0.413]]}
{"kind": "depth", "E": 1787095366155, "U": 11316374314743, "u": 11316374319564, "recv_ms": 1787095366213, "bids": [[14489.9, 1.428], [14589.9, 2.772], [58220.9, 0.002], [61455.4, 0.006], [61455.5, 0.002], [62102.3, 0.836], [63396.1, 1.103], [63941.0, 3.905], [64043.0, 0.032], [64091.4, 24.431], [64100.1, 0.022], [64107.7, 11.371], [64208.6, 46.119], [64300.1, 16.798], [64323.8, 0.885], [64366.5, 0.0], [64609.3, 0.007], [64616.5, 0.013], [64621.2, 0.004], [64624.4, 0.138], [64629.6, 1.167], [64640.3, 0.025], [64645.5, 0.063], [64658.9, 0.041], [64659.2, 0.007], [64674.0, 1.565], [64677.2, 0.0], [64677.7, 0.807], [64678.3, 0.021], [64678.7, 0.155], [64679.4, 0.118], [64682.7, 0.004], [64684.3, 0.548], [64685.4, 1.547], [64685.5, 2.118], [64685.6, 0.005], [64689.6, 0.0]], "asks": [[64692.2, 0.095], [64693.0, 0.04], [64693.2, 0.307], [64694.2, 0.365], [64694.7, 1.422], [64698.9, 0.05], [64699.0, 0.2], [64710.3, 0.078], [64710.5, 0.001], [64711.1, 3.72], [64718.1, 0.001], [64718.2, 0.174], [64767.6, 1.029], [65013.5, 0.77], [65176.2, 47.147], [65336.9, 0.001], [65405.7, 0.629], [65517.2, 0.613]]}
{"kind": "depth", "E": 1787095366359, "U": 11316374325453, "u": 11316374329216, "recv_ms": 1787095366417, "bids": [[1000.0, 35.76], [14489.9, 2.142], [14589.9, 2.058], [51752.0, 0.002], [58220.9, 0.002], [61455.4, 0.008], [63946.0, 8.07], [64043.0, 0.032], [64616.9, 0.001], [64649.0, 0.371], [64653.6, 0.024], [64657.0, 0.003], [64657.1, 0.019], [64657.2, 0.062], [64659.7, 0.071], [64660.4, 4.972], [64660.5, 1.33], [64660.6, 0.026], [64664.2, 8.02], [64665.5, 0.089], [64684.2, 0.967], [64685.6, 0.451], [64686.1, 0.003], [64686.4, 0.003], [64687.4, 0.009], [64688.0, 0.004], [64689.4, 0.019], [64689.8, 0.006], [64689.9, 7.207]], "asks": [[64690.3, 0.095], [64691.8, 0.74], [64692.5, 0.226], [64693.2, 0.307], [64693.3, 0.495], [64693.8, 0.208], [64693.9, 0.222], [64694.0, 0.359], [64694.1, 0.305], [64694.3, 0.2], [64694.4, 0.305], [64694.7, 1.425], [64695.3, 0.001], [64701.0, 3.264], [64707.0, 0.015], [64707.3, 0.029], [64712.5, 0.012], [64713.3, 0.032], [64713.9, 2.981], [64718.2, 0.014], [64723.4, 25.013], [64725.6, 0.001], [64830.6, 5.399], [64847.5, 10.414], [64922.5, 0.0], [64987.1, 0.001], [64989.8, 0.634], [65051.7, 0.0], [65054.5, 0.635], [65116.3, 0.003], [65207.5, 2.173], [65336.9, 0.001], [65466.3, 19.653], [65482.0, 14.92], [65700.0, 31.294]]}
{"kind": "depth", "E": 1787095366461, "U": 11316374329243, "u": 11316374333661, "recv_ms": 1787095366520, "bids": [[14489.9, 2.492], [14589.9, 1.708], [51751.9, 0.0], [51752.0, 0.002], [58220.9, 0.002], [61455.4, 0.008], [62102.3, 0.836], [63555.6, 0.0], [63689.9, 0.01], [63771.3, 0.703], [63941.0, 2.969], [64043.0, 0.032], [64366.5, 0.0], [64619.9, 0.0], [64620.1, 2.008], [64628.3, 0.097], [64628.4, 1.979], [64632.9, 0.027], [64636.6, 0.0], [64636.8, 1.515], [64672.5, 0.038], [64675.3, 0.002], [64679.9, 0.034], [64684.3, 0.007], [64685.1, 0.001], [64685.3, 1.175], [64685.4, 1.55], [64685.5, 1.925], [64685.6, 0.005], [64686.9, 0.463], [64687.4, 0.008], [64689.0, 0.086], [64689.4, 0.039], [64689.8, 0.007], [64689.9, 8.066]], "asks": [[64690.0, 8.738], [64690.3, 0.011], [64690.9, 0.198], [64691.8, 0.656], [64691.9, 0.013], [64692.2, 0.011], [64692.3, 0.431], [64692.4, 0.002], [64692.5, 0.001], [64692.7, 0.122], [64693.1, 0.413], [64693.2, 0.223], [64693.8, 0.089], [64694.0, 0.121], [64694.5, 0.181], [64694.6, 1.097], [64694.7, 1.422], [64695.3, 0.085], [64695.7, 0.09], [64695.9, 0.04], [64696.1, 0.366], [64700.8, 1.246], [64701.0, 2.364], [64702.9, 1.404], [64703.0, 0.031], [64703.4, 3.402], [64703.5, 0.006], [64703.6, 1.768], [64706.7, 0.021], [64707.4, 1.674], [64707.7, 0.005], [64710.8, 0.973], [64711.4, 0.065], [64711.8, 0.323], [64712.0, 3.521], [64713.1, 0.001], [64718.1, 0.001], [64720.2, 0.004], [64720.3, 1.985], [65119.2, 0.636], [65183.9, 0.637], [65336.9, 0.001], [65498.6, 5.067], [65535.1, 0.611], [65611.4, 17.845], [65676.0, 10.623], [65687.6, 2.323], [65690.0, 0.413], [65983.7, 0.015]]}
{"kind": "depth", "E": 1787095366563, "U": 11316374333701, "u": 11316374337053, "recv_ms": 1787095366622, "bids": [[1000.0, 35.76], [14489.9, 2.856], [14589.9, 1.344], [51752.0, 0.0], [58220.9, 0.002], [61455.4, 0.008], [62102.3, 0.833], [63770.3, 3.136], [63837.1, 0.785], [63865.1, 16.309], [63913.6, 33.983], [63941.0, 2.032], [63946.0, 9.006], [64043.0, 0.033], [64107.7, 16.043], [64626.8, 0.0], [64627.1, 0.097], [64627.4, 0.007], [64627.7, 0.0], [64628.0, 0.001], [64644.5, 0.003], [64644.7, 0.032], [64644.8, 1.038], [64645.1, 0.002], [64645.5, 0.031], [64645.8, 0.205], [64659.4, 0.003], [64659.5, 0.002], [64659.6, 0.165], [64659.7, 0.001], [64659.8, 0.007], [64659.9, 0.0], [64660.0, 0.11], [64660.1, 0.013], [64660.2, 0.131], [64660.4, 4.902], [64661.4, 0.0], [64661.8, 0.0], [64678.7, 0.015], [64678.8, 0.002], [64678.9, 1.575], [64679.0, 0.821], [64679.1, 0.087], [64679.2, 0.0], [64679.3, 2.33], [64679.4, 0.002], [64679.5, 0.311], [64679.6, 0.555], [64679.9, 0.002], [64680.2, 0.447], [64680.3, 0.002], [64680.6, 0.017], [64680.9, 0.159], [64681.1, 0.018], [64681.2, 1.144], [64684.3, 0.548], [64685.3, 0.634], [64685.5, 1.687], [64685.6, 0.005], [64686.9, 0.017], [64688.2, 0.085], [64689.0, 0.002], [64689.9, 8.066]], "asks": [[64690.0, 8.766], [64691.6, 0.086], [64691.8, 0.448], [64692.3, 0.399], [64692.5, 0.001], [64692.7, 0.087], [64693.0, 0.227], [64693.3, 0.453], [64693.6, 0.0], [64693.7, 0.043], [64693.9, 0.131], [64694.0, 0.001], [64694.1, 0.094], [64694.2, 0.245], [64694.3, 0.0], [64694.4, 0.045], [64694.5, 0.261], [64694.6, 0.804], [64694.7, 1.429], [64694.8, 7.4], [64694.9, 0.003], [64696.1, 0.282], [64699.0, 0.107], [64700.6, 0.529], [64707.4, 1.594], [64710.1, 0.003], [64710.4, 0.009], [64710.7, 0.031], [64711.0, 2.83], [64711.4, 0.023], [64711.5, 0.073], [64711.7, 0.014], [64712.2, 0.118], [64712.5, 0.032], [64713.1, 0.005], [64713.2, 0.234], [64713.4, 0.262], [64713.5, 0.465], [64713.6, 0.686], [64713.7, 0.001], [64713.8, 0.009], [64713.9, 2.757], [64714.0, 0.034], [64714.1, 0.559], [64714.2, 0.169], [64727.8, 0.001], [64728.1, 0.002], [64728.4, 0.39], [64728.8, 0.01], [64729.1, 0.39], [64729.2, 0.055], [64830.6, 5.399], [64847.5, 10.414], [65336.9, 0.001], [65445.7, 0.763], [65692.7, 5.926]]}
{"kind": "depth", "E": 1787095366665, "U": 11316374337087, "u": 11316374343084, "recv_ms": 1787095366815, "bids": [[1000.0, 35.76], [14489.9, 3.206], [14589.9, 0.994], [51752.0, 0.0], [58220.9, 0.002], [61455.4, 0.01], [62102.3, 0.836], [63396.2, 0.014], [63575.9, 4.243], [63689.9, 0.03], [64043.0, 0.033], [64054.8, 5.663], [64060.9, 60.234], [64645.0, 0.153], [64645.4, 0.104], [64646.0, 0.234], [64679.1, 0.157], [64679.4, 0.102], [64679.5, 0.381], [64679.9, 0.072], [64680.5, 0.247], [64680.8, 0.035], [64681.5, 0.081], [64685.6, 0.005]], "asks": [[64690.0, 8.914], [64692.5, 0.033], [64693.0, 0.002], [64693.1, 0.676], [64693.4, 0.043], [64694.0, 0.092], [64694.4, 0.115], [64694.5, 0.153], [64694.8, 7.47], [64701.0, 3.264], [64710.2, 0.254], [64710.8, 1.011], [64711.1, 3.762], [64713.3, 0.123], [64713.7, 0.201], [64714.1, 0.629], [64727.9, 0.711], [64728.5, 0.109], [64728.9, 0.044], [64732.6, 2.32], [64733.2, 0.216], [64767.9, 0.0], [64776.7, 49.105], [65325.6, 56.66], [65336.9, 0.001], [65592.0, 3.235], [65690.0, 0.433], [71159.0, 0.004]]}
