{"receive_ns":1788782255544781000,"stream":"btcusdt@depth@100ms","event_type":"depthUpdate","event_time_ms":1788782255630,"raw_json":"{\"stream\":\"btcusdt@depth@100ms\",\"data\":{\"e\":\"depthUpdate\",\"E\":1788782255630,\"T\":1788782255629,\"s\":\"BTCUSDT\",\"ps\":\"BTCUSDT\",\"U\":11496347670990,\"u\":11496347675688,\"pu\":11496347670861,\"b\":[[\"1000.00\",\"24.754\"],[\"28966.00\",\"0.539\"],[\"29066.00\",\"1.561\"],[\"63493.00\",\"0.010\"],[\"71429.40\",\"0.048\"],[\"76191.30\",\"0.000\"],[\"78056.50\",\"3.264\"],[\"78413.60\",\"38.342\"],[\"78453.30\",\"6.377\"],[\"78572.30\",\"12.650\"],[\"78969.10\",\"0.002\"],[\"78969.20\",\"4.114\"],[\"79123.90\",\"3.282\"],[\"79124.70\",\"0.010\"],[\"79143.50\",\"2.137\"],[\"79143.70\",\"0.015\"],[\"79143.80\",\"0.464\"],[\"79171.80\",\"3.719\"],[\"79181.80\",\"0.024\"],[\"79189.30\",\"2.009\"],[\"79189.60\",\"0.004\"],[\"79189.70\",\"0.050\"],[\"79220.50\",\"0.745\"],[\"79220.70\",\"0.005\"],[\"79273.80\",\"0.133\"],[\"79274.10\",\"0.008\"],[\"79347.50\",\"0.138\"],[\"79350.10\",\"3.801\"],[\"79350.30\",\"0.000\"]],\"a\":[[\"79370.00\",\"0.002\"],[\"79370.10\",\"0.103\"],[\"79370.40\",\"0.022\"],[\"79372.10\",\"0.086\"],[\"79374.50\",\"0.005\"],[\"79380.00\",\"0.023\"],[\"79561.70\",\"0.126\"],[\"79733.20\",\"0.836\"],[\"79762.90\",\"4.628\"],[\"79763.00\",\"0.000\"],[\"80080.40\",\"4.925\"],[\"80080.50\",\"2.620\"],[\"80159.80\",\"12.336\"],[\"80345.30\",\"0.000\"],[\"80371.50\",\"2.414\"],[\"80575.50\",\"16.911\"]],\"st\":1}}"}
{"receive_ns":1788782255671395000,"stream":"btcusdt@depth@100ms","event_type":"depthUpdate","event_time_ms":1788782255732,"raw_json":"{\"stream\":\"btcusdt@depth@100ms\",\"data\":{\"e\":\"depthUpdate\",\"E\":1788782255732,\"T\":1788782255731,\"s\":\"BTCUSDT\",\"ps\":\"BTCUSDT\",\"U\":11496347675721,\"u\":11496347681730,\"pu\":11496347675688,\"b\":[[\"28966.00\",\"0.721\"],[\"29066.00\",\"1.379\"],[\"71429.40\",\"0.048\"],[\"76191.30\",\"0.002\"],[\"78175.70\",\"0.382\"],[\"78254.90\",\"38.028\"],[\"78521.20\",\"0.000\"],[\"78572.30\",\"12.650\"],[\"78731.10\",\"4.821\"],[\"78969.10\",\"0.001\"],[\"79124.70\",\"0.000\"],[\"79143.50\",\"0.000\"],[\"79143.70\",\"35.394\"],[\"79143.80\",\"0.377\"],[\"79143.90\",\"0.063\"],[\"79145.80\",\"0.000\"],[\"79181.80\",\"0.005\"],[\"79189.30\",\"0.512\"],[\"79189.60\",\"26.523\"],[\"79220.50\",\"0.000\"],[\"79220.70\",\"17.677\"],[\"79273.80\",\"0.000\"],[\"79274.10\",\"8.838\"],[\"79284.40\",\"0.000\"],[\"79292.30\",\"0.001\"],[\"79300.20\",\"0.354\"],[\"79308.10\",\"0.000\"],[\"79316.00\",\"0.002\"],[\"79323.90\",\"0.033\"],[\"79342.90\",\"0.000\"],[\"79343.00\",\"0.000\"],[\"79343.10\",\"0.632\"],[\"79347.50\",\"0.579\"],[\"79347.60\",\"0.313\"],[\"79347.80\",\"0.143\"],[\"79350.10\",\"3.360\"],[\"79351.00\",\"0.113\"],[\"79351.80\",\"0.013\"],[\"79358.50\",\"0.082\"],[\"79358.60\",\"0.064\"],[\"79358.80\",\"0.017\"],[\"79359.00\",\"0.022\"],[\"79366.00\",\"7.066\"]],\"a\":[[\"79366.10\",\"5.099\"],[\"79367.60\",\"0.154\"],[\"79368.70\",\"0.000\"],[\"79369.10\",\"0.008\"],[\"79369.70\",\"0.002\"],[\"79370.10\",\"0.027\"],[\"79370.50\",\"0.005\"],[\"79370.70\",\"0.076\"],[\"79371.50\",\"0.000\"],[\"79372.00\",\"0.006\"],[\"79372.60\",\"1.004\"],[\"79372.90\",\"1.087\"],[\"79389.30\",\"0.001\"],[\"79389.40\",\"0.082\"],[\"79390.00\",\"0.006\"],[\"79390.40\",\"0.454\"],[\"79390.60\",\"0.000\"],[\"79395.00\",\"1.194\"],[\"79400.70\",\"6.831\"],[\"79410.80\",\"0.114\"],[\"79418.70\",\"0.002\"],[\"79426.60\",\"0.001\"],[\"79434.50\",\"0.000\"],[\"79442.40\",\"0.001\"],[\"79450.30\",\"0.000\"],[\"79733.20\",\"0.502\"],[\"79733.30\",\"0.062\"],[\"79763.00\",\"0.001\"],[\"80159.80\",\"11.090\"],[\"80301.40\",\"0.124\"],[\"80397.90\",\"10.235\"]],\"st\":1}}"}
{"receive_ns":1788782255749184000,"stream":"btcusdt@depth@100ms","event_type":"depthUpdate","event_time_ms":1788782255834,"raw_json":"{\"stream\":\"btcusdt@depth@100ms\",\"data\":{\"e\":\"depthUpdate\",\"E\":1788782255834,\"T\":1788782255830,\"s\":\"BTCUSDT\",\"ps\":\"BTCUSDT\",\"U\":11496347681769,\"u\":11496347687314,\"pu\":11496347681730,\"b\":[[\"1000.00\",\"24.754\"],[\"28966.00\",\"0.896\"],[\"29066.00\",\"1.204\"],[\"71429.40\",\"0.048\"],[\"75746.90\",\"0.003\"],[\"76191.30\",\"0.000\"],[\"77156.60\",\"0.000\"],[\"78254.90\",\"36.113\"],[\"78413.60\",\"37.068\"],[\"78572.30\",\"12.650\"],[\"79002.00\",\"0.353\"],[\"79041.60\",\"0.363\"],[\"79081.20\",\"0.001\"],[\"79116.10\",\"0.000\"],[\"79120.80\",\"0.001\"],[\"79123.90\",\"2.680\"],[\"79143.80\",\"1.020\"],[\"79160.40\",\"0.001\"],[\"79171.80\",\"3.701\"],[\"79189.70\",\"0.068\"],[\"79200.00\",\"6.378\"],[\"79239.60\",\"0.010\"],[\"79279.20\",\"0.002\"],[\"79318.80\",\"0.002\"],[\"79338.30\",\"0.021\"],[\"79341.60\",\"0.003\"],[\"79345.50\",\"0.057\"],[\"79347.80\",\"0.123\"],[\"79349.40\",\"0.437\"],[\"79351.00\",\"0.113\"],[\"79353.30\",\"0.003\"],[\"79355.20\",\"0.252\"],[\"79355.80\",\"0.136\"],[\"79357.20\",\"0.253\"],[\"79358.40\",\"1.352\"],[\"79358.50\",\"0.145\"],[\"79358.60\",\"0.001\"],[\"79361.10\",\"0.002\"],[\"79365.00\",\"0.001\"]],\"a\":[[\"79366.10\",\"4.760\"],[\"79368.90\",\"0.238\"],[\"79369.10\",\"0.006\"],[\"79370.60\",\"0.000\"],[\"79370.80\",\"0.002\"],[\"79370.90\",\"0.002\"],[\"79371.20\",\"0.255\"],[\"79371.70\",\"0.305\"],[\"79372.10\",\"0.106\"],[\"79372.80\",\"0.023\"],[\"79374.10\",\"0.233\"],[\"79376.30\",\"0.235\"],[\"79376.70\",\"0.103\"],[\"79380.60\",\"0.003\"],[\"79384.50\",\"0.004\"],[\"79388.40\",\"0.259\"],[\"79392.30\",\"0.438\"],[\"79398.00\",\"0.008\"],[\"79404.90\",\"1.136\"],[\"79405.60\",\"0.275\"],[\"79420.50\",\"0.081\"],[\"79420.60\",\"0.052\"],[\"79437.60\",\"0.015\"],[\"79477.20\",\"0.003\"],[\"79516.80\",\"0.015\"],[\"79556.40\",\"0.002\"],[\"79596.00\",\"0.003\"],[\"79635.60\",\"0.002\"],[\"79675.20\",\"0.029\"],[\"79714.80\",\"0.002\"],[\"79733.20\",\"0.478\"],[\"79754.40\",\"0.001\"],[\"80080.40\",\"5.798\"],[\"80159.80\",\"11.090\"],[\"80437.50\",\"5.657\"],[\"80477.20\",\"35.545\"]],\"st\":1}}"}
{"receive_ns":1788782255850589000,"stream":"btcusdt@depth@100ms","event_type":"depthUpdate","event_time_ms":1788782255936,"raw_json":"{\"stream\":\"btcusdt@depth@100ms\",\"data\":{\"e\":\"depthUpdate\",\"E\":1788782255936,\"T\":1788782255934,\"s\":\"BTCUSDT\",\"ps\":\"BTCUSDT\",\"U\":11496347687542,\"u\":11496347692533,\"pu\":11496347687314,\"b\":[[\"1000.00\",\"24.754\"],[\"28966.00\",\"1.078\"],[\"29066.00\",\"1.022\"],[\"63493.00\",\"0.010\"],[\"71429.40\",\"0.048\"],[\"77540.60\",\"1.807\"],[\"78254.90\",\"34.199\"],[\"78516.80\",\"10.787\"],[\"78572.30\",\"12.650\"],[\"78969.20\",\"4.104\"],[\"79145.80\",\"0.540\"],[\"79340.00\",\"0.450\"],[\"79340.90\",\"0.453\"],[\"79342.00\",\"0.098\"],[\"79366.00\",\"7.034\"]],\"a\":[[\"79366.10\",\"4.760\"],[\"79368.50\",\"0.076\"],[\"79368.80\",\"0.033\"],[\"79370.40\",\"0.098\"],[\"79370.70\",\"0.000\"],[\"79372.10\",\"0.086\"],[\"79372.80\",\"0.015\"],[\"79373.80\",\"0.008\"],[\"79374.10\",\"0.231\"],[\"79374.60\",\"0.029\"],[\"79390.40\",\"0.001\"],[\"79391.70\",\"0.454\"],[\"79429.60\",\"0.349\"],[\"79733.20\",\"0.789\"],[\"79762.90\",\"4.753\"],[\"79767.30\",\"0.056\"],[\"79767.40\",\"0.088\"],[\"80128.70\",\"0.000\"],[\"80159.80\",\"11.090\"],[\"80516.90\",\"11.433\"]],\"st\":1}}"}
{"receive_ns":1788782255952521000,"stream":"btcusdt@depth@100ms","event_type":"depthUpdate","event_time_ms":1788782256038,"raw_json":"{\"stream\":\"btcusdt@depth@100ms\",\"data\":{\"e\":\"depthUpdate\",\"E\":1788782256038,\"T\":1788782256036,\"s\":\"BTCUSDT\",\"ps\":\"BTCUSDT\",\"U\":11496347692670,\"u\":11496347699019,\"pu\":11496347692533,\"b\":[[\"28966.00\",\"1.253\"],[\"29066.00\",\"0.847\"],[\"63493.00\",\"0.010\"],[\"71429.40\",\"0.048\"],[\"76191.30\",\"0.002\"],[\"78135.80\",\"7.160\"],[\"78215.20\",\"12.473\"],[\"78254.90\",\"36.114\"],[\"78413.60\",\"38.342\"],[\"78453.30\",\"5.613\"],[\"78572.30\",\"12.650\"],[\"78731.10\",\"7.991\"],[\"79143.80\",\"0.833\"],[\"79143.90\",\"0.063\"],[\"79343.10\",\"0.002\"],[\"79344.90\",\"0.002\"],[\"79347.50\",\"0.138\"],[\"79350.10\",\"3.801\"],[\"79351.00\",\"0.743\"]],\"a\":[[\"79366.10\",\"4.763\"],[\"79368.50\",\"0.000\"],[\"79369.10\",\"0.082\"],[\"79369.70\",\"0.000\"],[\"79371.90\",\"0.008\"],[\"79372.10\",\"0.001\"],[\"79380.40\",\"4.497\"],[\"79384.70\",\"0.008\"],[\"79733.20\",\"0.800\"],[\"79733.30\",\"0.062\"],[\"80120.10\",\"6.943\"],[\"80159.80\",\"11.090\"],[\"80278.80\",\"0.149\"],[\"80318.50\",\"41.419\"],[\"80371.50\",\"2.134\"],[\"80490.60\",\"8.683\"],[\"80675.60\",\"2.222\"]],\"st\":1}}"}
{"receive_ns":1788782256053079000,"stream":"btcusdt@depth@100ms","event_type":"depthUpdate","event_time_ms":1788782256140,"raw_json":"{\"stream\":\"btcusdt@depth@100ms\",\"data\":{\"e\":\"depthUpdate\",\"E\":1788782256140,\"T\":1788782256138,\"s\":\"BTCUSDT\",\"ps\":\"BTCUSDT\",\"U\":11496347699071,\"u\":11496347704584,\"pu\":11496347699019,\"b\":[[\"1000.00\",\"24.754\"],[\"28966.00\",\"1.435\"],[\"29066.00\",\"0.665\"],[\"63493.00\",\"0.010\"],[\"71429.40\",\"0.048\"],[\"76191.30\",\"0.000\"],[\"78135.80\",\"8.055\"],[\"78215.20\",\"13.367\"],[\"78254.90\",\"38.028\"],[\"78453.30\",\"6.377\"],[\"78572.30\",\"12.650\"],[\"79143.70\",\"35.379\"],[\"79143.80\",\"1.560\"],[\"79145.80\",\"0.000\"],[\"79191.30\",\"0.010\"],[\"79325.40\",\"1.169\"],[\"79341.30\",\"1.115\"],[\"79347.50\",\"0.138\"],[\"79350.10\",\"3.801\"],[\"79356.70\",\"0.026\"],[\"79358.40\",\"1.348\"],[\"79358.80\",\"0.021\"]],\"a\":[[\"79366.10\",\"4.764\"],[\"79367.90\",\"0.001\"],[\"79369.10\",\"0.006\"],[\"79372.10\",\"0.086\"],[\"79374.30\",\"0.113\"],[\"79380.40\",\"4.493\"],[\"79380.90\",\"0.004\"],[\"79392.40\",\"1.086\"],[\"79408.30\",\"1.290\"],[\"79574.30\",\"3.061\"],[\"79575.10\",\"0.001\"],[\"79733.20\",\"0.836\"],[\"80159.80\",\"11.090\"],[\"80318.50\",\"40.176\"],[\"80516.90\",\"12.301\"]],\"st\":1}}"}
{"receive_ns":1788782256157184000,"stream":"btcusdt@depth@100ms","event_type":"depthUpdate","event_time_ms":1788782256242,"raw_json":"{\"stream\":\"btcusdt@depth@100ms\",\"data\":{\"e\":\"depthUpdate\",\"E\":1788782256242,\"T\":1788782256240,\"s\":\"BTCUSDT\",\"ps\":\"BTCUSDT\",\"U\":11496347704848,\"u\":11496347709336,\"pu\":11496347704584,\"b\":[[\"1000.00\",\"24.754\"],[\"28966.00\",\"1.610\"],[\"29066.00\",\"0.490\"],[\"71429.40\",\"0.048\"],[\"75397.70\",\"0.021\"],[\"76191.30\",\"0.002\"],[\"77881.90\",\"3.944\"],[\"78254.90\",\"36.113\"],[\"78318.00\",\"1.277\"],[\"78413.60\",\"37.068\"],[\"78477.10\",\"8.205\"],[\"78572.30\",\"12.650\"],[\"78969.20\",\"4.114\"],[\"79116.10\",\"0.054\"],[\"79123.90\",\"2.931\"],[\"79124.10\",\"0.063\"],[\"79124.70\",\"0.005\"],[\"79143.50\",\"2.163\"],[\"79143.70\",\"0.000\"],[\"79143.80\",\"0.778\"],[\"79143.90\",\"0.765\"],[\"79181.80\",\"0.011\"],[\"79189.30\",\"2.028\"],[\"79189.60\",\"0.004\"],[\"79220.50\",\"0.754\"],[\"79220.70\",\"0.005\"],[\"79236.90\",\"1.179\"],[\"79258.00\",\"17.489\"],[\"79273.90\",\"0.375\"],[\"79274.10\",\"0.008\"],[\"79277.40\",\"1.052\"]],\"a\":[[\"79366.10\",\"4.764\"],[\"79369.20\",\"0.005\"],[\"79484.20\",\"0.002\"],[\"79533.40\",\"0.001\"],[\"79574.30\",\"5.106\"],[\"79733.20\",\"0.529\"],[\"79733.30\",\"0.062\"],[\"80159.80\",\"11.090\"],[\"80318.50\",\"38.932\"],[\"80477.20\",\"33.683\"]],\"st\":1}}"}
{"receive_ns":1788782256260129000,"stream":"btcusdt@depth@100ms","event_type":"depthUpdate","event_time_ms":1788782256344,"raw_json":"{\"stream\":\"btcusdt@depth@100ms\",\"data\":{\"e\":\"depthUpdate\",\"E\":1788782256344,\"T\":1788782256342,\"s\":\"BTCUSDT\",\"ps\":\"BTCUSDT\",\"U\":11496347709405,\"u\":11496347715573,\"pu\":11496347709336,\"b\":[[\"28866.00\",\"0.014\"],[\"28966.00\",\"1.764\"],[\"29066.00\",\"0.322\"],[\"63492.80\",\"0.000\"],[\"71429.40\",\"0.048\"],[\"75632.90\",\"0.002\"],[\"76191.30\",\"0.000\"],[\"78215.20\",\"14.261\"],[\"78453.30\",\"6.377\"],[\"78572.30\",\"12.650\"],[\"78696.30\",\"0.000\"],[\"79123.90\",\"3.408\"],[\"79124.70\",\"0.000\"],[\"79143.50\",\"0.000\"],[\"79143.70\",\"35.379\"],[\"79143.80\",\"0.678\"],[\"79146.90\",\"0.000\"],[\"79181.80\",\"0.005\"],[\"79189.30\",\"0.512\"],[\"79189.60\",\"26.523\"],[\"79190.30\",\"4.755\"],[\"79190.40\",\"0.076\"],[\"79194.50\",\"0.000\"],[\"79220.50\",\"0.000\"],[\"79220.70\",\"17.677\"],[\"79258.00\",\"17.501\"],[\"79273.90\",\"0.241\"],[\"79274.10\",\"8.838\"]],\"a\":[[\"79369.20\",\"0.081\"],[\"79372.10\",\"0.001\"],[\"79372.20\",\"0.014\"],[\"79372.70\",\"0.102\"],[\"79372.80\",\"0.009\"],[\"79372.90\",\"0.741\"],[\"79373.80\",\"0.000\"],[\"79373.90\",\"0.079\"],[\"79374.00\",\"0.173\"],[\"79374.60\",\"0.027\"],[\"79375.00\",\"0.020\"],[\"79375.20\",\"1.321\"],[\"79375.50\",\"0.556\"],[\"79380.00\",\"0.108\"],[\"79574.30\",\"3.061\"],[\"79733.20\",\"0.836\"],[\"79947.00\",\"1.039\"],[\"80239.50\",\"0.188\"],[\"80257.90\",\"5.537\"],[\"80318.50\",\"40.175\"],[\"80516.90\",\"11.433\"],[\"80596.30\",\"6.939\"],[\"80675.60\",\"3.088\"],[\"81601.90\",\"0.000\"]],\"st\":1}}"}
{"receive_ns":1788782256360985000,"stream":"btcusdt@depth@100ms","event_type":"depthUpdate","event_time_ms":1788782256446,"raw_json":"{\"stream\":\"btcusdt@depth@100ms\",\"data\":{\"e\":\"depthUpdate\",\"E\":1788782256446,\"T\":1788782256442,\"s\":\"BTCUSDT\",\"ps\":\"BTCUSDT\",\"U\":11496347715659,\"u\":11496347721219,\"pu\":11496347715573,\"b\":[[\"1000.00\",\"24.754\"],[\"28866.00\",\"0.070\"],[\"28966.00\",\"1.827\"],[\"29066.00\",\"0.203\"],[\"71429.40\",\"0.048\"],[\"77778.70\",\"1.448\"],[\"78254.90\",\"38.028\"],[\"78413.60\",\"38.342\"],[\"78572.30\",\"12.650\"],[\"78969.20\",\"4.104\"],[\"79123.90\",\"3.157\"],[\"79124.10\",\"0.000\"],[\"79124.70\",\"0.005\"],[\"79143.50\",\"2.162\"],[\"79143.70\",\"0.000\"],[\"79143.80\",\"0.778\"],[\"79171.80\",\"3.719\"],[\"79181.80\",\"0.017\"],[\"79189.30\",\"2.027\"],[\"79189.60\",\"0.004\"],[\"79189.70\",\"0.050\"],[\"79190.30\",\"0.902\"],[\"79220.50\",\"0.754\"],[\"79220.70\",\"0.005\"],[\"79244.00\",\"1.657\"],[\"79273.90\",\"0.375\"],[\"79274.10\",\"0.008\"],[\"79294.50\",\"0.000\"],[\"79310.40\",\"0.010\"]],\"a\":[[\"79366.10\",\"4.764\"],[\"79421.70\",\"0.144\"],[\"79487.30\",\"0.451\"],[\"79487.40\",\"0.003\"],[\"79733.20\",\"0.692\"],[\"79733.30\",\"0.028\"],[\"80001.00\",\"8.639\"],[\"80159.80\",\"11.090\"],[\"80239.50\",\"0.375\"],[\"80257.90\",\"5.350\"],[\"80318.50\",\"40.175\"],[\"80397.90\",\"11.105\"],[\"80398.00\",\"1.989\"],[\"80477.20\",\"33.684\"]],\"st\":1}}"}
{"receive_ns":1788782256463465000,"stream":"btcusdt@depth@100ms","event_type":"depthUpdate","event_time_ms":1788782256548,"raw_json":"{\"stream\":\"btcusdt@depth@100ms\",\"data\":{\"e\":\"depthUpdate\",\"E\":1788782256548,\"T\":1788782256547,\"s\":\"BTCUSDT\",\"ps\":\"BTCUSDT\",\"U\":11496347721410,\"u\":11496347726933,\"pu\":11496347721219,\"b\":[[\"1000.00\",\"24.754\"],[\"28866.00\",\"0.133\"],[\"28966.00\",\"1.883\"],[\"29066.00\",\"0.084\"],[\"71429.40\",\"0.048\"],[\"75397.70\",\"0.023\"],[\"76191.30\",\"0.002\"],[\"78254.90\",\"38.282\"],[\"78329.00\",\"0.001\"],[\"78349.20\",\"0.000\"],[\"78366.90\",\"0.286\"],[\"78572.30\",\"12.650\"],[\"78690.20\",\"0.679\"],[\"79123.90\",\"3.408\"],[\"79124.10\",\"0.063\"],[\"79124.70\",\"0.000\"],[\"79143.50\",\"0.000\"],[\"79143.70\",\"35.379\"],[\"79143.80\",\"0.151\"],[\"79181.80\",\"0.005\"],[\"79189.30\",\"0.512\"],[\"79189.60\",\"26.523\"],[\"79220.50\",\"0.000\"],[\"79220.70\",\"17.677\"],[\"79273.90\",\"0.241\"],[\"79274.10\",\"8.838\"],[\"79347.50\",\"0.138\"],[\"79347.60\",\"0.754\"],[\"79350.10\",\"3.360\"],[\"79350.30\",\"0.000\"]],\"a\":[[\"79368.70\",\"0.000\"],[\"79368.90\",\"0.314\"],[\"79369.20\",\"0.005\"],[\"79380.00\",\"0.070\"],[\"79733.20\",\"0.507\"],[\"79733.30\",\"0.062\"],[\"80159.80\",\"11.090\"],[\"80477.20\",\"33.932\"],[\"80516.90\",\"10.565\"],[\"80596.30\",\"6.072\"]],\"st\":1}}"}
{"receive_ns":1788782256565230000,"stream":"btcusdt@depth@100ms","event_type":"depthUpdate","event_time_ms":1788782256650,"raw_json":"{\"stream\":\"btcusdt@depth@100ms\",\"data\":{\"e\":\"depthUpdate\",\"E\":1788782256650,\"T\":1788782256646,\"s\":\"BTCUSDT\",\"ps\":\"BTCUSDT\",\"U\":11496347726942,\"u\":11496347733406,\"pu\":11496347726933,\"b\":[[\"28866.00\",\"0.224\"],[\"28966.00\",\"1.876\"],[\"29066.00\",\"0.000\"],[\"63493.00\",\"0.010\"],[\"71429.40\",\"0.048\"],[\"76191.30\",\"0.000\"],[\"78318.40\",\"0.643\"],[\"78572.30\",\"12.650\"],[\"78969.10\",\"0.000\"],[\"79143.80\",\"0.778\"],[\"79171.80\",\"3.701\"],[\"79189.70\",\"0.068\"],[\"79214.60\",\"0.100\"],[\"79347.60\",\"0.313\"],[\"79350.30\",\"0.441\"],[\"79356.70\",\"0.000\"],[\"79366.00\",\"7.023\"]],\"a\":[[\"79374.00\",\"0.258\"],[\"79380.00\",\"0.059\"],[\"79420.50\",\"0.131\"],[\"79420.60\",\"0.002\"],[\"79437.00\",\"0.201\"],[\"79442.60\",\"0.149\"],[\"79445.00\",\"0.844\"],[\"79450.60\",\"0.001\"],[\"79462.40\",\"0.485\"],[\"79733.20\",\"0.753\"],[\"79763.00\",\"0.002\"],[\"79786.20\",\"0.222\"],[\"79791.80\",\"0.001\"],[\"80159.80\",\"11.090\"],[\"80318.50\",\"41.419\"],[\"80477.20\",\"33.932\"],[\"80516.90\",\"11.433\"],[\"80596.30\",\"6.940\"]],\"st\":1}}"}
{"receive_ns":1788782256667447000,"stream":"btcusdt@depth@100ms","event_type":"depthUpdate","event_time_ms":1788782256752,"raw_json":"{\"stream\":\"btcusdt@depth@100ms\",\"data\":{\"e\":\"depthUpdate\",\"E\":1788782256752,\"T\":1788782256750,\"s\":\"BTCUSDT\",\"ps\":\"BTCUSDT\",\"U\":11496347733620,\"u\":11496347739998,\"pu\":11496347733406,\"b\":[[\"1000.00\",\"24.754\"],[\"28866.00\",\"0.406\"],[\"28966.00\",\"1.694\"],[\"71429.40\",\"0.048\"],[\"75397.70\",\"0.025\"],[\"76191.30\",\"0.002\"],[\"77778.70\",\"1.454\"],[\"78215.20\",\"13.367\"],[\"78387.00\",\"2.666\"],[\"78572.30\",\"12.650\"],[\"78969.20\",\"4.104\"],[\"79116.10\",\"0.000\"],[\"79123.90\",\"3.371\"],[\"79124.10\",\"0.063\"],[\"79124.70\",\"0.010\"],[\"79143.50\",\"2.145\"],[\"79143.70\",\"0.000\"],[\"79143.80\",\"0.782\"],[\"79181.80\",\"0.011\"],[\"79189.30\",\"2.015\"],[\"79189.60\",\"0.004\"],[\"79220.50\",\"0.748\"],[\"79220.70\",\"0.005\"],[\"79250.30\",\"0.001\"],[\"79273.90\",\"0.374\"],[\"79274.10\",\"0.008\"],[\"79275.30\",\"0.067\"],[\"79356.70\",\"0.026\"],[\"79358.50\",\"0.082\"],[\"79358.80\",\"0.084\"],[\"79366.00\",\"7.023\"]],\"a\":[[\"79366.10\",\"3.212\"],[\"79367.60\",\"0.001\"],[\"79368.70\",\"0.153\"],[\"79368.90\",\"0.238\"],[\"79370.50\",\"0.003\"],[\"79370.80\",\"0.000\"],[\"79372.50\",\"0.010\"],[\"79372.70\",\"0.104\"],[\"79375.00\",\"0.010\"],[\"79375.50\",\"0.554\"],[\"79376.50\",\"0.265\"],[\"79387.40\",\"0.441\"],[\"79390.40\",\"0.001\"],[\"79390.90\",\"0.461\"],[\"79391.70\",\"0.001\"],[\"79392.40\",\"0.115\"],[\"79400.70\",\"4.831\"],[\"79403.30\",\"0.013\"],[\"79403.40\",\"0.001\"],[\"79404.90\",\"2.418\"],[\"79405.40\",\"10.484\"],[\"79407.50\",\"0.591\"],[\"79408.30\",\"0.125\"],[\"79428.30\",\"0.040\"],[\"79500.00\",\"8.018\"],[\"79574.20\",\"5.124\"],[\"79574.30\",\"0.000\"],[\"79660.00\",\"1.109\"],[\"79733.20\",\"0.753\"],[\"79733.30\",\"0.062\"],[\"79763.00\",\"0.001\"],[\"80080.80\",\"0.187\"],[\"80159.80\",\"11.090\"],[\"80477.90\",\"0.000\"],[\"80516.90\",\"10.565\"]],\"st\":1}}"}
{"receive_ns":1788782256768496000,"stream":"btcusdt@depth@100ms","event_type":"depthUpdate","event_time_ms":1788782256854,"raw_json":"{\"stream\":\"btcusdt@depth@100ms\",\"data\":{\"e\":\"depthUpdate\",\"E\":1788782256854,\"T\":1788782256850,\"s\":\"BTCUSDT\",\"ps\":\"BTCUSDT\",\"U\":11496347740133,\"u\":11496347750149,\"pu\":11496347739998,\"b\":[[\"1000.00\",\"24.754\"],[\"28866.00\",\"0.581\"],[\"28966.00\",\"1.519\"],[\"71429.40\",\"0.048\"],[\"76191.30\",\"0.000\"],[\"78016.80\",\"4.348\"],[\"78387.00\",\"2.475\"],[\"78412.10\",\"0.713\"],[\"78491.50\",\"0.921\"],[\"78572.30\",\"12.650\"],[\"78969.10\",\"0.001\"],[\"79123.90\",\"3.458\"],[\"79124.70\",\"0.000\"],[\"79143.50\",\"0.000\"],[\"79143.70\",\"35.379\"],[\"79143.80\",\"0.782\"],[\"79171.80\",\"3.719\"],[\"79181.80\",\"0.005\"],[\"79189.30\",\"0.512\"],[\"79189.60\",\"26.523\"],[\"79189.70\",\"0.050\"],[\"79214.60\",\"0.000\"],[\"79220.50\",\"0.000\"],[\"79220.70\",\"17.677\"],[\"79273.90\",\"0.241\"],[\"79274.10\",\"8.838\"],[\"79340.30\",\"0.453\"],[\"79340.90\",\"0.000\"],[\"79347.20\",\"0.000\"],[\"79347.50\",\"0.705\"],[\"79347.60\",\"0.313\"],[\"79348.60\",\"0.001\"],[\"79349.60\",\"0.756\"],[\"79350.30\",\"0.441\"],[\"79366.00\",\"7.029\"]],\"a\":[[\"79366.10\",\"2.674\"],[\"79370.40\",\"0.022\"],[\"79371.20\",\"0.331\"],[\"79371.70\",\"0.053\"],[\"79372.50\",\"0.000\"],[\"79372.60\",\"0.004\"],[\"79372.70\",\"0.102\"],[\"79374.00\",\"0.173\"],[\"79375.00\",\"0.020\"],[\"79375.10\",\"0.503\"],[\"79375.90\",\"0.009\"],[\"79376.50\",\"0.263\"],[\"79377.60\",\"0.309\"],[\"79379.40\",\"0.006\"],[\"79380.00\",\"0.108\"],[\"79389.70\",\"1.297\"],[\"79390.80\",\"0.478\"],[\"79390.90\",\"0.008\"],[\"79405.40\",\"10.485\"],[\"79405.60\",\"0.274\"],[\"79420.50\",\"0.081\"],[\"79420.60\",\"0.052\"],[\"79561.70\",\"0.000\"],[\"79574.20\",\"3.079\"],[\"79733.20\",\"0.800\"],[\"80159.80\",\"11.090\"],[\"80516.90\",\"11.433\"],[\"80596.30\",\"7.807\"]],\"st\":1}}"}
{"receive_ns":1788782256877916000,"stream":"btcusdt@depth@100ms","event_type":"depthUpdate","event_time_ms":1788782256956,"raw_json":"{\"stream\":\"btcusdt@depth@100ms\",\"data\":{\"e\":\"depthUpdate\",\"E\":1788782256956,\"T\":1788782256954,\"s\":\"BTCUSDT\",\"ps\":\"BTCUSDT\",\"U\":11496347750386,\"u\":11496347757450,\"pu\":11496347750149,\"b\":[[\"28866.00\",\"0.763\"],[\"28966.00\",\"1.337\"],[\"71429.40\",\"0.048\"],[\"75397.70\",\"0.023\"],[\"75397.80\",\"0.008\"],[\"78572.30\",\"12.650\"],[\"79123.90\",\"2.730\"],[\"79124.10\",\"0.000\"],[\"79143.50\",\"2.127\"],[\"79143.70\",\"0.000\"],[\"79143.80\",\"1.033\"],[\"79143.90\",\"0.828\"],[\"79171.80\",\"3.701\"],[\"79189.40\",\"1.492\"],[\"79189.60\",\"0.004\"],[\"79189.70\",\"0.068\"],[\"79220.50\",\"0.742\"],[\"79220.70\",\"0.005\"],[\"79273.90\",\"0.373\"],[\"79274.10\",\"0.008\"],[\"79335.00\",\"0.649\"],[\"79340.80\",\"5.163\"],[\"79359.40\",\"0.030\"],[\"79362.40\",\"0.252\"],[\"79366.00\",\"7.029\"]],\"a\":[[\"79366.10\",\"2.171\"],[\"79366.40\",\"0.000\"],[\"79367.20\",\"0.002\"],[\"79371.20\",\"0.255\"],[\"79377.60\",\"0.307\"],[\"79378.20\",\"0.003\"],[\"79380.90\",\"0.080\"],[\"79389.90\",\"0.172\"],[\"79405.40\",\"2.228\"],[\"79408.90\",\"0.265\"],[\"79429.60\",\"0.249\"],[\"79560.80\",\"0.000\"],[\"79561.00\",\"0.145\"],[\"79574.20\",\"3.079\"],[\"79733.20\",\"0.493\"],[\"79733.30\",\"0.062\"],[\"80080.50\",\"3.493\"],[\"80159.80\",\"11.090\"],[\"80477.20\",\"35.793\"],[\"80497.20\",\"0.743\"],[\"80675.60\",\"2.221\"],[\"80953.40\",\"0.009\"]],\"st\":1}}"}
{"receive_ns":1788782256973011000,"stream":"btcusdt@depth@100ms","event_type":"depthUpdate","event_time_ms":1788782257058,"raw_json":"{\"stream\":\"btcusdt@depth@100ms\",\"data\":{\"e\":\"depthUpdate\",\"E\":1788782257058,\"T\":1788782257057,\"s\":\"BTCUSDT\",\"ps\":\"BTCUSDT\",\"U\":11496347757528,\"u\":11496347763487,\"pu\":11496347757450,\"b\":[[\"1000.00\",\"24.754\"],[\"28866.00\",\"0.945\"],[\"28966.00\",\"1.155\"],[\"71429.40\",\"0.048\"],[\"76191.30\",\"0.002\"],[\"78215.20\",\"14.261\"],[\"78334.20\",\"2.542\"],[\"78373.90\",\"10.153\"],[\"78572.30\",\"12.650\"],[\"78969.20\",\"4.104\"],[\"79123.90\",\"2.717\"],[\"79124.70\",\"0.000\"],[\"79125.90\",\"0.441\"],[\"79143.50\",\"0.000\"],[\"79143.80\",\"35.685\"],[\"79145.80\",\"0.237\"],[\"79146.90\",\"0.020\"],[\"79150.10\",\"0.000\"],[\"79181.80\",\"0.005\"],[\"79189.40\",\"0.001\"],[\"79189.60\",\"26.523\"],[\"79191.30\",\"0.030\"],[\"79220.50\",\"0.000\"],[\"79220.70\",\"17.677\"],[\"79273.90\",\"0.241\"],[\"79274.10\",\"8.838\"],[\"79335.80\",\"1.003\"],[\"79342.80\",\"1.565\"],[\"79343.20\",\"0.632\"],[\"79344.90\",\"0.002\"],[\"79351.00\",\"0.113\"],[\"79351.10\",\"0.172\"],[\"79351.20\",\"0.102\"],[\"79366.00\",\"7.029\"]],\"a\":[[\"79366.10\",\"1.754\"],[\"79366.30\",\"0.000\"],[\"79366.40\",\"0.002\"],[\"79371.10\",\"0.001\"],[\"79371.20\",\"0.003\"],[\"79371.90\",\"0.006\"],[\"79372.70\",\"0.102\"],[\"79372.80\",\"0.007\"],[\"79373.00\",\"0.004\"],[\"79374.00\",\"0.341\"],[\"79378.20\",\"0.001\"],[\"79378.90\",\"0.002\"],[\"79380.00\",\"0.023\"],[\"79380.40\",\"4.493\"],[\"79382.00\",\"0.267\"],[\"79384.70\",\"0.008\"],[\"79386.00\",\"0.663\"],[\"79388.50\",\"0.003\"],[\"79404.90\",\"1.136\"],[\"79409.60\",\"8.257\"],[\"79496.30\",\"0.000\"],[\"79560.80\",\"0.000\"],[\"79560.90\",\"0.002\"],[\"79561.50\",\"0.191\"],[\"79578.90\",\"2.815\"],[\"79733.20\",\"0.442\"],[\"80159.80\",\"11.090\"],[\"80371.50\",\"1.923\"],[\"80516.90\",\"11.433\"]],\"st\":1}}"}
{"receive_ns":1788782257073780000,"stream":"btcusdt@depth@100ms","event_type":"depthUpdate","event_time_ms":1788782257160,"raw_json":"{\"stream\":\"btcusdt@depth@100ms\",\"data\":{\"e\":\"depthUpdate\",\"E\":1788782257160,\"T\":1788782257158,\"s\":\"BTCUSDT\",\"ps\":\"BTCUSDT\",\"U\":11496347763504,\"u\":11496347769357,\"pu\":11496347763487,\"b\":[[\"1000.00\",\"24.754\"],[\"28866.00\",\"1.120\"],[\"28966.00\",\"0.980\"],[\"71429.40\",\"0.048\"],[\"75518.90\",\"0.002\"],[\"76191.30\",\"0.000\"],[\"78016.80\",\"8.188\"],[\"78572.30\",\"12.650\"],[\"79116.10\",\"0.054\"],[\"79123.90\",\"2.817\"],[\"79124.70\",\"0.000\"],[\"79125.90\",\"0.881\"],[\"79143.50\",\"2.168\"],[\"79143.80\",\"0.252\"],[\"79171.80\",\"3.719\"],[\"79181.80\",\"0.005\"],[\"79189.40\",\"1.520\"],[\"79189.60\",\"0.004\"],[\"79189.70\",\"0.050\"],[\"79220.50\",\"0.756\"],[\"79220.70\",\"0.005\"],[\"79273.90\",\"0.376\"],[\"79274.10\",\"0.008\"],[\"79290.00\",\"0.258\"],[\"79293.50\",\"0.111\"],[\"79343.20\",\"0.002\"],[\"79347.60\",\"0.313\"],[\"79350.30\",\"0.441\"],[\"79351.00\",\"0.743\"],[\"79351.30\",\"0.120\"],[\"79351.40\",\"0.071\"],[\"79351.50\",\"0.100\"]],\"a\":[[\"79371.20\",\"0.255\"],[\"79372.00\",\"0.006\"],[\"79372.30\",\"0.000\"],[\"79372.40\",\"0.076\"],[\"79372.70\",\"0.026\"],[\"79388.80\",\"0.007\"],[\"79574.20\",\"5.124\"],[\"79733.20\",\"0.753\"],[\"80099.20\",\"9.534\"],[\"80106.70\",\"0.000\"],[\"80159.80\",\"11.090\"],[\"80318.50\",\"41.977\"]],\"st\":1}}"}
{"receive_ns":1788782257177165000,"stream":"btcusdt@depth@100ms","event_type":"depthUpdate","event_time_ms":1788782257262,"raw_json":"{\"stream\":\"btcusdt@depth@100ms\",\"data\":{\"e\":\"depthUpdate\",\"E\":1788782257262,\"T\":1788782257261,\"s\":\"BTCUSDT\",\"ps\":\"BTCUSDT\",\"U\":11496347769455,\"u\":11496347774598,\"pu\":11496347769357,\"b\":[[\"28866.00\",\"1.295\"],[\"28966.00\",\"0.805\"],[\"63493.00\",\"0.012\"],[\"71429.40\",\"0.048\"],[\"76191.30\",\"0.002\"],[\"78011.50\",\"0.001\"],[\"78572.30\",\"12.650\"],[\"79123.90\",\"2.817\"],[\"79124.70\",\"0.020\"],[\"79125.90\",\"0.881\"],[\"79143.50\",\"2.168\"],[\"79143.80\",\"0.001\"],[\"79143.90\",\"0.634\"],[\"79145.80\",\"0.251\"],[\"79181.80\",\"0.024\"],[\"79189.40\",\"1.520\"],[\"79189.60\",\"0.004\"],[\"79220.50\",\"0.756\"],[\"79220.70\",\"0.005\"],[\"79244.00\",\"1.261\"],[\"79273.90\",\"0.376\"],[\"79274.10\",\"0.008\"],[\"79283.60\",\"1.552\"],[\"79343.20\",\"0.002\"],[\"79351.00\",\"0.113\"],[\"79351.10\",\"0.172\"],[\"79351.20\",\"0.102\"],[\"79351.30\",\"0.120\"],[\"79351.40\",\"0.071\"],[\"79351.50\",\"0.730\"]],\"a\":[[\"79366.10\",\"1.755\"],[\"79374.00\",\"0.193\"],[\"79380.00\",\"0.167\"],[\"79380.10\",\"0.035\"],[\"79487.30\",\"0.000\"],[\"79733.20\",\"0.609\"],[\"79733.30\",\"0.028\"],[\"80159.80\",\"11.091\"],[\"80371.50\",\"1.737\"],[\"80675.60\",\"3.088\"]],\"st\":1}}"}
{"receive_ns":1788782257281139000,"stream":"btcusdt@depth@100ms","event_type":"depthUpdate","event_time_ms":1788782257364,"raw_json":"{\"stream\":\"btcusdt@depth@100ms\",\"data\":{\"e\":\"depthUpdate\",\"E\":1788782257364,\"T\":1788782257361,\"s\":\"BTCUSDT\",\"ps\":\"BTCUSDT\",\"U\":11496347774619,\"u\":11496347782430,\"pu\":11496347774598,\"b\":[[\"1000.00\",\"24.754\"],[\"28866.00\",\"1.477\"],[\"28966.00\",\"0.623\"],[\"63492.80\",\"0.000\"],[\"63493.00\",\"0.012\"],[\"71429.40\",\"0.048\"],[\"78572.30\",\"12.650\"],[\"78969.20\",\"4.114\"],[\"79116.10\",\"0.000\"],[\"79123.90\",\"2.817\"],[\"79124.70\",\"0.020\"],[\"79125.90\",\"0.881\"],[\"79143.50\",\"2.141\"],[\"79143.80\",\"0.001\"],[\"79143.90\",\"0.688\"],[\"79145.80\",\"0.488\"],[\"79181.80\",\"0.024\"],[\"79189.40\",\"1.502\"],[\"79189.60\",\"0.004\"],[\"79220.50\",\"0.747\"],[\"79220.70\",\"0.005\"],[\"79223.80\",\"1.476\"],[\"79244.00\",\"1.657\"],[\"79273.90\",\"0.374\"],[\"79274.10\",\"0.008\"],[\"79343.20\",\"0.632\"],[\"79351.50\",\"0.100\"],[\"79358.50\",\"0.149\"],[\"79358.80\",\"0.017\"]],\"a\":[[\"79366.10\",\"1.754\"],[\"79374.00\",\"0.341\"],[\"79392.70\",\"1.454\"],[\"79408.60\",\"1.614\"],[\"79435.90\",\"0.022\"],[\"79484.20\",\"0.001\"],[\"79487.30\",\"0.451\"],[\"79574.20\",\"3.079\"],[\"79733.20\",\"0.609\"],[\"80159.80\",\"11.091\"],[\"80257.90\",\"5.163\"],[\"80334.40\",\"0.624\"],[\"80358.20\",\"6.496\"],[\"80516.90\",\"12.301\"],[\"80556.60\",\"3.706\"]],\"st\":1}}"}
{"receive_ns":1788782257382111000,"stream":"btcusdt@depth@100ms","event_type":"depthUpdate","event_time_ms":1788782257466,"raw_json":"{\"stream\":\"btcusdt@depth@100ms\",\"data\":{\"e\":\"depthUpdate\",\"E\":1788782257466,\"T\":1788782257465,\"s\":\"BTCUSDT\",\"ps\":\"BTCUSDT\",\"U\":11496347782674,\"u\":11496347789222,\"pu\":11496347782430,\"b\":[[\"1000.00\",\"24.754\"],[\"28866.00\",\"1.652\"],[\"28966.00\",\"0.448\"],[\"71429.40\",\"0.048\"],[\"76191.30\",\"0.000\"],[\"78572.30\",\"12.650\"],[\"78731.10\",\"7.993\"],[\"79123.90\",\"3.068\"],[\"79124.10\",\"0.063\"],[\"79125.90\",\"0.441\"],[\"79143.50\",\"0.000\"],[\"79143.80\",\"35.380\"],[\"79143.90\",\"0.625\"],[\"79145.80\",\"0.237\"],[\"79189.40\",\"0.001\"],[\"79189.60\",\"26.523\"],[\"79220.50\",\"0.000\"],[\"79220.70\",\"17.677\"],[\"79273.90\",\"0.241\"],[\"79274.10\",\"8.838\"],[\"79294.50\",\"0.002\"]],\"a\":[[\"79366.10\",\"1.754\"],[\"79372.40\",\"0.076\"],[\"79372.70\",\"0.026\"],[\"79374.00\",\"0.485\"],[\"79380.00\",\"0.023\"],[\"79380.10\",\"0.035\"],[\"79437.60\",\"0.017\"],[\"79733.20\",\"0.322\"],[\"80159.80\",\"12.337\"]],\"st\":1}}"}
{"receive_ns":1788782257488271000,"stream":"btcusdt@depth@100ms","event_type":"depthUpdate","event_time_ms":1788782257568,"raw_json":"{\"stream\":\"btcusdt@depth@100ms\",\"data\":{\"e\":\"depthUpdate\",\"E\":1788782257568,\"T\":1788782257567,\"s\":\"BTCUSDT\",\"ps\":\"BTCUSDT\",\"U\":11496347789263,\"u\":11496347796254,\"pu\":11496347789222,\"b\":[[\"28866.00\",\"1.778\"],[\"28966.00\",\"0.294\"],[\"29266.00\",\"0.028\"],[\"71429.40\",\"0.048\"],[\"76191.30\",\"0.002\"],[\"77143.80\",\"1.093\"],[\"77778.70\",\"1.451\"],[\"78159.70\",\"1.278\"],[\"78387.00\",\"2.322\"],[\"78572.30\",\"12.652\"],[\"78731.10\",\"7.991\"],[\"79123.90\",\"2.931\"],[\"79124.70\",\"0.000\"],[\"79125.90\",\"0.001\"],[\"79145.80\",\"0.714\"],[\"79171.80\",\"3.701\"],[\"79181.80\",\"0.005\"],[\"79189.70\",\"0.068\"],[\"79347.60\",\"0.313\"],[\"79350.20\",\"0.950\"],[\"79350.30\",\"0.000\"],[\"79359.40\",\"0.004\"],[\"79366.00\",\"7.035\"]],\"a\":[[\"79370.90\",\"0.078\"],[\"79371.20\",\"0.003\"],[\"79371.30\",\"0.253\"],[\"79372.30\",\"0.076\"],[\"79372.40\",\"0.000\"],[\"79372.80\",\"0.008\"],[\"79374.00\",\"0.485\"],[\"79379.00\",\"0.300\"],[\"79381.30\",\"0.002\"],[\"79607.10\",\"2.646\"],[\"79733.20\",\"0.298\"],[\"80159.80\",\"12.337\"]],\"st\":1}}"}
{"receive_ns":1788782257585482000,"stream":"btcusdt@depth@100ms","event_type":"depthUpdate","event_time_ms":1788782257670,"raw_json":"{\"stream\":\"btcusdt@depth@100ms\",\"data\":{\"e\":\"depthUpdate\",\"E\":1788782257670,\"T\":1788782257668,\"s\":\"BTCUSDT\",\"ps\":\"BTCUSDT\",\"U\":11496347796268,\"u\":11496347801185,\"pu\":11496347796254,\"b\":[[\"1000.00\",\"24.754\"],[\"28866.00\",\"1.841\"],[\"28966.00\",\"0.175\"],[\"29266.00\",\"0.084\"],[\"63493.00\",\"0.012\"],[\"71429.40\",\"0.048\"],[\"76191.30\",\"0.000\"],[\"78511.40\",\"4.019\"],[\"78572.30\",\"12.652\"],[\"78969.20\",\"4.104\"],[\"79124.70\",\"0.000\"],[\"79125.90\",\"0.541\"],[\"79143.50\",\"0.000\"],[\"79143.80\",\"35.380\"],[\"79181.80\",\"0.005\"],[\"79189.40\",\"0.001\"],[\"79189.60\",\"26.523\"],[\"79220.50\",\"0.000\"],[\"79220.70\",\"17.677\"],[\"79253.70\",\"0.001\"],[\"79253.80\",\"0.031\"],[\"79273.90\",\"0.241\"],[\"79274.10\",\"8.838\"],[\"79280.00\",\"1.051\"],[\"79283.60\",\"0.868\"],[\"79294.50\",\"0.002\"],[\"79307.80\",\"0.013\"],[\"79310.40\",\"0.008\"],[\"79327.60\",\"0.000\"],[\"79358.90\",\"0.086\"]],\"a\":[[\"79370.90\",\"0.002\"],[\"79374.30\",\"0.049\"],[\"79404.60\",\"0.003\"],[\"79421.70\",\"0.144\"],[\"79424.00\",\"0.841\"],[\"79424.40\",\"0.009\"],[\"79437.60\",\"0.015\"],[\"79452.10\",\"1.266\"],[\"79452.20\",\"0.000\"],[\"79496.30\",\"0.036\"],[\"79578.90\",\"2.840\"],[\"79607.00\",\"0.004\"],[\"79733.20\",\"0.609\"],[\"79763.00\",\"0.000\"],[\"80013.10\",\"0.000\"],[\"80159.80\",\"12.337\"],[\"80170.60\",\"0.609\"],[\"80327.80\",\"4.695\"]],\"st\":1}}"}
{"receive_ns":1788782257687897000,"stream":"btcusdt@depth@100ms","event_type":"depthUpdate","event_time_ms":1788782257772,"raw_json":"{\"stream\":\"btcusdt@depth@100ms\",\"data\":{\"e\":\"depthUpdate\",\"E\":1788782257772,\"T\":1788782257770,\"s\":\"BTCUSDT\",\"ps\":\"BTCUSDT\",\"U\":11496347801219,\"u\":11496347807325,\"pu\":11496347801185,\"b\":[[\"1000.00\",\"24.754\"],[\"28866.00\",\"1.897\"],[\"28966.00\",\"0.056\"],[\"29266.00\",\"0.147\"],[\"63493.00\",\"0.012\"],[\"71429.40\",\"0.048\"],[\"75397.70\",\"0.025\"],[\"75404.90\",\"0.003\"],[\"76191.30\",\"0.002\"],[\"78572.30\",\"12.650\"],[\"78969.10\",\"0.002\"],[\"78987.70\",\"0.000\"],[\"78987.80\",\"0.144\"],[\"79123.90\",\"2.931\"],[\"79124.10\",\"0.063\"],[\"79124.70\",\"0.000\"],[\"79143.50\",\"0.000\"],[\"79143.80\",\"35.380\"],[\"79145.80\",\"0.477\"],[\"79189.40\",\"0.001\"],[\"79189.60\",\"26.523\"],[\"79197.50\",\"0.000\"],[\"79204.70\",\"2.092\"],[\"79220.50\",\"0.000\"],[\"79220.70\",\"17.677\"],[\"79240.40\",\"0.394\"],[\"79242.30\",\"0.412\"],[\"79244.00\",\"1.657\"],[\"79273.90\",\"0.241\"],[\"79274.10\",\"8.838\"],[\"79277.10\",\"1.611\"],[\"79340.30\",\"0.000\"],[\"79341.20\",\"0.454\"],[\"79342.10\",\"0.003\"],[\"79347.60\",\"0.313\"],[\"79350.20\",\"0.509\"],[\"79350.30\",\"0.441\"],[\"79358.50\",\"0.086\"],[\"79358.80\",\"0.080\"],[\"79366.00\",\"7.029\"]],\"a\":[[\"79371.20\",\"0.079\"],[\"79374.00\",\"0.193\"],[\"79380.00\",\"0.167\"],[\"79380.10\",\"0.035\"],[\"79380.40\",\"1.896\"],[\"79390.80\",\"0.025\"],[\"79391.70\",\"0.454\"],[\"79420.50\",\"0.131\"],[\"79420.60\",\"0.002\"],[\"79487.30\",\"0.451\"],[\"79491.90\",\"2.401\"],[\"79499.50\",\"0.068\"],[\"79519.90\",\"0.000\"],[\"79526.60\",\"2.253\"],[\"79733.20\",\"0.609\"],[\"80105.40\",\"0.001\"],[\"80159.80\",\"12.337\"],[\"80263.70\",\"0.000\"],[\"80318.50\",\"40.733\"],[\"80358.20\",\"6.776\"],[\"80477.20\",\"36.040\"],[\"80953.40\",\"0.012\"]],\"st\":1}}"}
{"receive_ns":1788782257788875000,"stream":"btcusdt@depth@100ms","event_type":"depthUpdate","event_time_ms":1788782257874,"raw_json":"{\"stream\":\"btcusdt@depth@100ms\",\"data\":{\"e\":\"depthUpdate\",\"E\":1788782257874,\"T\":1788782257873,\"s\":\"BTCUSDT\",\"ps\":\"BTCUSDT\",\"U\":11496347807476,\"u\":11496347813835,\"pu\":11496347807325,\"b\":[[\"28866.00\",\"1.827\"],[\"28966.00\",\"0.000\"],[\"29266.00\",\"0.273\"],[\"71429.40\",\"0.048\"],[\"78352.60\",\"18.544\"],[\"78572.30\",\"12.650\"],[\"78668.40\",\"0.000\"],[\"78969.10\",\"0.001\"],[\"79123.90\",\"3.471\"],[\"79124.70\",\"0.015\"],[\"79125.90\",\"0.001\"],[\"79143.50\",\"2.151\"],[\"79143.80\",\"0.001\"],[\"79145.80\",\"0.714\"],[\"79189.40\",\"1.508\"],[\"79189.60\",\"0.004\"],[\"79190.10\",\"0.001\"],[\"79220.50\",\"0.750\"],[\"79220.70\",\"0.005\"],[\"79231.60\",\"0.006\"],[\"79240.50\",\"0.000\"],[\"79273.90\",\"0.375\"],[\"79274.10\",\"0.008\"]],\"a\":[[\"79366.10\",\"1.756\"],[\"79374.00\",\"0.341\"],[\"79489.10\",\"0.718\"],[\"79491.80\",\"0.000\"],[\"79499.90\",\"0.915\"],[\"79733.20\",\"0.544\"],[\"80002.10\",\"0.562\"],[\"80159.80\",\"12.337\"],[\"80318.50\",\"41.354\"],[\"80423.10\",\"1.243\"],[\"80477.20\",\"34.178\"],[\"80507.80\",\"1.116\"]],\"st\":1}}"}
{"receive_ns":1788782257896636000,"stream":"btcusdt@depth@100ms","event_type":"depthUpdate","event_time_ms":1788782257976,"raw_json":"{\"stream\":\"btcusdt@depth@100ms\",\"data\":{\"e\":\"depthUpdate\",\"E\":1788782257976,\"T\":1788782257975,\"s\":\"BTCUSDT\",\"ps\":\"BTCUSDT\",\"U\":11496347813881,\"u\":11496347819351,\"pu\":11496347813835,\"b\":[[\"1000.00\",\"24.754\"],[\"28866.00\",\"1.652\"],[\"29266.00\",\"0.448\"],[\"63493.00\",\"0.014\"],[\"71429.40\",\"0.048\"],[\"76191.30\",\"0.000\"],[\"78248.30\",\"0.000\"],[\"78572.30\",\"12.650\"],[\"78968.20\",\"0.088\"],[\"78969.20\",\"4.736\"],[\"79002.00\",\"0.352\"],[\"79041.60\",\"0.362\"],[\"79081.20\",\"0.000\"],[\"79100.00\",\"49.124\"],[\"79102.40\",\"0.026\"],[\"79116.10\",\"0.054\"],[\"79120.80\",\"0.000\"],[\"79123.90\",\"3.471\"],[\"79124.10\",\"0.063\"],[\"79143.90\",\"0.571\"],[\"79145.80\",\"0.237\"],[\"79160.40\",\"0.000\"],[\"79171.80\",\"3.719\"],[\"79189.70\",\"0.050\"],[\"79200.00\",\"6.365\"],[\"79239.60\",\"0.009\"],[\"79279.20\",\"0.001\"],[\"79291.10\",\"0.002\"],[\"79293.50\",\"0.110\"],[\"79318.80\",\"0.001\"],[\"79325.40\",\"0.005\"],[\"79327.70\",\"1.106\"],[\"79340.10\",\"0.455\"],[\"79341.20\",\"0.001\"],[\"79341.30\",\"0.145\"],[\"79341.60\",\"0.002\"],[\"79345.50\",\"0.056\"],[\"79347.60\",\"0.313\"],[\"79349.40\",\"0.436\"],[\"79350.30\",\"0.441\"],[\"79353.30\",\"0.002\"],[\"79357.20\",\"0.252\"],[\"79361.10\",\"0.001\"],[\"79365.00\",\"0.000\"],[\"79366.00\",\"7.029\"]],\"a\":[[\"79366.10\",\"2.177\"],[\"79368.90\",\"0.237\"],[\"79371.20\",\"0.079\"],[\"79372.60\",\"0.006\"],[\"79372.70\",\"0.127\"],[\"79372.80\",\"0.007\"],[\"79373.00\",\"0.002\"],[\"79374.00\",\"0.364\"],[\"79376.70\",\"0.102\"],[\"79380.00\",\"0.023\"],[\"79380.10\",\"0.035\"],[\"79380.60\",\"0.002\"],[\"79384.50\",\"0.003\"],[\"79388.40\",\"0.258\"],[\"79389.50\",\"0.312\"],[\"79390.70\",\"0.466\"],[\"79391.70\",\"0.001\"],[\"79392.30\",\"0.437\"],[\"79398.00\",\"0.007\"],[\"79404.50\",\"1.711\"],[\"79437.60\",\"0.014\"],[\"79477.20\",\"0.002\"],[\"79509.00\",\"0.002\"],[\"79516.80\",\"0.014\"],[\"79556.40\",\"0.001\"],[\"79596.00\",\"0.002\"],[\"79635.60\",\"0.001\"],[\"79675.20\",\"0.028\"],[\"79714.80\",\"0.001\"],[\"79733.20\",\"0.322\"],[\"79754.40\",\"0.000\"],[\"79763.00\",\"0.001\"],[\"80159.80\",\"12.337\"],[\"80239.10\",\"5.975\"],[\"80420.50\",\"0.003\"]],\"st\":1}}"}
{"receive_ns":1788782257993263000,"stream":"btcusdt@depth@100ms","event_type":"depthUpdate","event_time_ms":1788782258078,"raw_json":"{\"stream\":\"btcusdt@depth@100ms\",\"data\":{\"e\":\"depthUpdate\",\"E\":1788782258078,\"T\":1788782258076,\"s\":\"BTCUSDT\",\"ps\":\"BTCUSDT\",\"U\":11496347819373,\"u\":11496347825878,\"pu\":11496347819351,\"b\":[[\"1000.00\",\"24.754\"],[\"28866.00\",\"1.477\"],[\"29266.00\",\"0.623\"],[\"63493.00\",\"0.012\"],[\"71429.40\",\"0.048\"],[\"76191.30\",\"0.002\"],[\"78572.30\",\"12.650\"],[\"79123.90\",\"3.408\"],[\"79124.70\",\"0.000\"],[\"79143.50\",\"0.000\"],[\"79143.80\",\"35.380\"],[\"79145.80\",\"0.237\"],[\"79171.80\",\"3.701\"],[\"79189.40\",\"0.001\"],[\"79189.60\",\"26.523\"],[\"79189.70\",\"0.068\"],[\"79220.50\",\"0.000\"],[\"79220.80\",\"17.748\"],[\"79273.90\",\"0.241\"],[\"79274.10\",\"8.838\"],[\"79342.90\",\"0.000\"],[\"79343.20\",\"0.002\"],[\"79344.90\",\"0.002\"],[\"79347.60\",\"0.754\"],[\"79350.30\",\"0.000\"],[\"79351.00\",\"0.743\"],[\"79356.70\",\"0.000\"],[\"79358.50\",\"0.149\"],[\"79358.80\",\"0.017\"],[\"79358.90\",\"0.060\"],[\"79362.40\",\"0.000\"],[\"79366.00\",\"7.029\"]],\"a\":[[\"79366.10\",\"2.671\"],[\"79367.30\",\"0.707\"],[\"79367.40\",\"2.526\"],[\"79367.50\",\"0.020\"],[\"79368.40\",\"0.077\"],[\"79368.50\",\"0.000\"],[\"79368.90\",\"0.001\"],[\"79369.10\",\"0.008\"],[\"79369.70\",\"0.076\"],[\"79371.20\",\"0.080\"],[\"79371.80\",\"0.252\"],[\"79372.70\",\"0.026\"],[\"79372.80\",\"0.008\"],[\"79373.30\",\"0.153\"],[\"79373.40\",\"1.000\"],[\"79373.50\",\"0.002\"],[\"79373.90\",\"0.079\"],[\"79374.00\",\"0.157\"],[\"79375.10\",\"0.501\"],[\"79376.30\",\"0.237\"],[\"79378.90\",\"0.000\"],[\"79379.50\",\"0.630\"],[\"79379.60\",\"0.002\"],[\"79379.70\",\"0.020\"],[\"79380.00\",\"0.059\"],[\"79380.40\",\"1.896\"],[\"79380.90\",\"0.004\"],[\"79382.00\",\"0.191\"],[\"79384.70\",\"0.008\"],[\"79385.60\",\"0.002\"],[\"79420.50\",\"0.081\"],[\"79420.60\",\"0.052\"],[\"79733.20\",\"0.325\"],[\"80159.80\",\"12.337\"],[\"80239.10\",\"6.162\"],[\"80318.50\",\"42.598\"],[\"80477.20\",\"36.040\"],[\"81588.40\",\"1.220\"]],\"st\":1}}"}
{"receive_ns":1788782258103240000,"stream":"btcusdt@depth@100ms","event_type":"depthUpdate","event_time_ms":1788782258180,"raw_json":"{\"stream\":\"btcusdt@depth@100ms\",\"data\":{\"e\":\"depthUpdate\",\"E\":1788782258180,\"T\":1788782258178,\"s\":\"BTCUSDT\",\"ps\":\"BTCUSDT\",\"U\":11496347825963,\"u\":11496347831662,\"pu\":11496347825878,\"b\":[[\"28866.00\",\"1.295\"],[\"29266.00\",\"0.805\"],[\"71429.40\",\"0.048\"],[\"76191.30\",\"0.000\"],[\"77778.70\",\"1.454\"],[\"78572.30\",\"12.650\"],[\"79116.10\",\"0.000\"],[\"79123.90\",\"3.157\"],[\"79124.10\",\"0.000\"],[\"79143.90\",\"0.625\"],[\"79145.80\",\"0.777\"],[\"79336.30\",\"11.253\"],[\"79340.80\",\"1.420\"],[\"79342.80\",\"0.803\"],[\"79343.00\",\"0.000\"],[\"79347.60\",\"0.313\"],[\"79350.90\",\"0.739\"],[\"79351.00\",\"0.113\"],[\"79351.10\",\"0.802\"],[\"79358.10\",\"1.002\"],[\"79366.00\",\"6.993\"]],\"a\":[[\"79366.10\",\"2.764\"],[\"79367.20\",\"0.002\"],[\"79368.00\",\"0.006\"],[\"79368.40\",\"0.001\"],[\"79370.40\",\"0.008\"],[\"79370.60\",\"0.002\"],[\"79371.40\",\"0.002\"],[\"79372.60\",\"0.004\"],[\"79379.50\",\"0.001\"],[\"79380.10\",\"0.001\"],[\"79385.60\",\"0.631\"],[\"79574.20\",\"3.079\"],[\"79733.20\",\"0.636\"],[\"79926.80\",\"0.094\"],[\"80159.80\",\"12.337\"],[\"80343.00\",\"0.001\"]],\"st\":1}}"}
{"receive_ns":1788782258196288000,"stream":"btcusdt@depth@100ms","event_type":"depthUpdate","event_time_ms":1788782258282,"raw_json":"{\"stream\":\"btcusdt@depth@100ms\",\"data\":{\"e\":\"depthUpdate\",\"E\":1788782258282,\"T\":1788782258281,\"s\":\"BTCUSDT\",\"ps\":\"BTCUSDT\",\"U\":11496347831773,\"u\":11496347836183,\"pu\":11496347831662,\"b\":[[\"1000.00\",\"24.754\"],[\"28866.00\",\"1.120\"],[\"29266.00\",\"0.980\"],[\"63493.00\",\"0.014\"],[\"71429.40\",\"0.048\"],[\"75290.90\",\"0.002\"],[\"76191.30\",\"0.002\"],[\"78317.80\",\"1.918\"],[\"78334.20\",\"3.434\"],[\"78572.30\",\"12.652\"],[\"78969.20\",\"4.746\"],[\"79123.90\",\"3.408\"],[\"79124.10\",\"0.063\"],[\"79124.70\",\"0.010\"],[\"79143.60\",\"0.001\"],[\"79143.80\",\"35.380\"],[\"79145.80\",\"0.540\"],[\"79147.30\",\"0.750\"],[\"79171.80\",\"3.719\"],[\"79189.40\",\"0.001\"],[\"79189.60\",\"26.523\"],[\"79189.70\",\"0.050\"],[\"79206.90\",\"0.673\"],[\"79220.60\",\"0.000\"],[\"79220.80\",\"17.748\"],[\"79232.60\",\"0.008\"],[\"79273.90\",\"0.241\"],[\"79274.10\",\"8.838\"],[\"79275.60\",\"2.134\"],[\"79325.70\",\"1.177\"],[\"79339.00\",\"2.383\"],[\"79341.50\",\"0.970\"],[\"79349.70\",\"0.441\"],[\"79350.90\",\"0.298\"]],\"a\":[[\"79366.10\",\"2.651\"],[\"79367.20\",\"0.002\"],[\"79371.40\",\"0.000\"],[\"79374.00\",\"0.072\"],[\"79380.00\",\"0.023\"],[\"79409.50\",\"2.793\"],[\"79410.30\",\"0.309\"],[\"79733.20\",\"0.773\"],[\"79733.30\",\"0.062\"],[\"80001.00\",\"8.888\"],[\"80159.80\",\"12.336\"],[\"80264.50\",\"0.000\"],[\"80279.60\",\"13.879\"]],\"st\":1}}"}
{"receive_ns":1788782258299216000,"stream":"btcusdt@depth@100ms","event_type":"depthUpdate","event_time_ms":1788782258384,"raw_json":"{\"stream\":\"btcusdt@depth@100ms\",\"data\":{\"e\":\"depthUpdate\",\"E\":1788782258384,\"T\":1788782258383,\"s\":\"BTCUSDT\",\"ps\":\"BTCUSDT\",\"U\":11496347836220,\"u\":11496347841770,\"pu\":11496347836183,\"b\":[[\"1000.00\",\"24.754\"],[\"28866.00\",\"0.938\"],[\"29266.00\",\"1.162\"],[\"63492.80\",\"0.000\"],[\"63493.00\",\"0.012\"],[\"71429.40\",\"0.048\"],[\"75397.70\",\"0.023\"],[\"75397.80\",\"0.010\"],[\"77778.70\",\"1.457\"],[\"78487.90\",\"0.479\"],[\"78572.30\",\"12.650\"],[\"78668.90\",\"0.000\"],[\"79124.70\",\"0.000\"],[\"79145.80\",\"0.777\"],[\"79171.80\",\"3.701\"],[\"79189.70\",\"0.068\"],[\"79335.00\",\"0.648\"],[\"79336.30\",\"11.254\"],[\"79347.60\",\"0.313\"],[\"79349.70\",\"0.000\"],[\"79350.10\",\"3.801\"],[\"79357.20\",\"0.278\"]],\"a\":[[\"79366.10\",\"2.652\"],[\"79367.20\",\"0.002\"],[\"79369.50\",\"0.000\"],[\"79369.60\",\"0.082\"],[\"79369.70\",\"0.000\"],[\"79371.40\",\"0.000\"],[\"79380.00\",\"0.108\"],[\"79409.60\",\"8.258\"],[\"79410.40\",\"3.333\"],[\"79574.20\",\"5.123\"],[\"79733.20\",\"0.800\"],[\"80159.80\",\"12.336\"],[\"80279.60\",\"14.625\"],[\"80953.40\",\"0.009\"]],\"st\":1}}"}
{"receive_ns":1788782258400246000,"stream":"btcusdt@depth@100ms","event_type":"depthUpdate","event_time_ms":1788782258486,"raw_json":"{\"stream\":\"btcusdt@depth@100ms\",\"data\":{\"e\":\"depthUpdate\",\"E\":1788782258486,\"T\":1788782258481,\"s\":\"BTCUSDT\",\"ps\":\"BTCUSDT\",\"U\":11496347841779,\"u\":11496347846709,\"pu\":11496347841770,\"b\":[[\"28866.00\",\"0.763\"],[\"29266.00\",\"1.337\"],[\"71429.40\",\"0.048\"],[\"76191.30\",\"0.000\"],[\"78352.90\",\"0.004\"],[\"78373.90\",\"10.630\"],[\"78383.10\",\"0.174\"],[\"78413.80\",\"0.637\"],[\"79123.90\",\"2.931\"],[\"79124.10\",\"0.063\"],[\"79124.70\",\"0.010\"],[\"79143.60\",\"2.171\"],[\"79143.80\",\"0.001\"],[\"79189.40\",\"1.521\"],[\"79189.60\",\"0.004\"],[\"79220.60\",\"0.756\"],[\"79220.80\",\"0.076\"],[\"79273.90\",\"0.376\"],[\"79274.10\",\"0.008\"],[\"79275.60\",\"0.914\"]],\"a\":[[\"79389.70\",\"1.626\"],[\"79561.50\",\"0.065\"],[\"79733.20\",\"0.493\"],[\"79733.30\",\"0.062\"],[\"80159.80\",\"12.336\"]],\"st\":1}}"}
{"receive_ns":1788782258501153000,"stream":"btcusdt@depth@100ms","event_type":"depthUpdate","event_time_ms":1788782258588,"raw_json":"{\"stream\":\"btcusdt@depth@100ms\",\"data\":{\"e\":\"depthUpdate\",\"E\":1788782258588,\"T\":1788782258585,\"s\":\"BTCUSDT\",\"ps\":\"BTCUSDT\",\"U\":11496347847199,\"u\":11496347852705,\"pu\":11496347846709,\"b\":[[\"1000.00\",\"24.754\"],[\"28866.00\",\"0.588\"],[\"29266.00\",\"1.512\"],[\"63493.00\",\"0.014\"],[\"71429.40\",\"0.048\"],[\"76191.30\",\"0.002\"],[\"78245.10\",\"0.000\"],[\"78445.80\",\"0.000\"],[\"78572.30\",\"12.650\"],[\"78968.60\",\"0.000\"],[\"78969.20\",\"4.736\"],[\"79116.10\",\"0.054\"],[\"79123.90\",\"3.168\"],[\"79125.90\",\"0.478\"],[\"79143.90\",\"0.571\"],[\"79145.80\",\"0.000\"],[\"79171.80\",\"3.719\"],[\"79189.70\",\"0.050\"],[\"79244.00\",\"1.657\"],[\"79310.40\",\"0.010\"],[\"79350.10\",\"3.799\"]],\"a\":[[\"79366.10\",\"2.652\"],[\"79367.20\",\"0.002\"],[\"79380.00\",\"0.108\"],[\"79437.60\",\"0.016\"],[\"79487.30\",\"0.451\"],[\"79604.20\",\"0.001\"],[\"79733.20\",\"0.525\"],[\"80105.20\",\"0.004\"],[\"80159.80\",\"12.336\"],[\"80318.50\",\"42.102\"],[\"80543.70\",\"0.000\"],[\"80556.50\",\"0.000\"]],\"st\":1}}"}
{"receive_ns":1788782258579768000,"stream":"btcusdt@bookTicker","event_type":"bookTicker","event_time_ms":1788782258666,"raw_json":"{\"stream\":\"btcusdt@bookTicker\",\"data\":{\"e\":\"bookTicker\",\"u\":11496347857908,\"s\":\"BTCUSDT\",\"ps\":\"BTCUSDT\",\"b\":\"79366.00\",\"B\":\"6.994\",\"a\":\"79366.10\",\"A\":\"2.652\",\"T\":1788782258666,\"E\":1788782258666,\"st\":1}}"}
{"receive_ns":1788782258591551000,"stream":"btcusdt@bookTicker","event_type":"bookTicker","event_time_ms":1788782258676,"raw_json":"{\"stream\":\"btcusdt@bookTicker\",\"data\":{\"e\":\"bookTicker\",\"u\":11496347858299,\"s\":\"BTCUSDT\",\"ps\":\"BTCUSDT\",\"b\":\"79366.00\",\"B\":\"6.994\",\"a\":\"79366.10\",\"A\":\"2.571\",\"T\":1788782258675,\"E\":1788782258676,\"st\":1}}"}
{"receive_ns":1788782258592504000,"stream":"btcusdt@bookTicker","event_type":"bookTicker","event_time_ms":1788782258678,"raw_json":"{\"stream\":\"btcusdt@bookTicker\",\"data\":{\"e\":\"bookTicker\",\"u\":11496347858394,\"s\":\"BTCUSDT\",\"ps\":\"BTCUSDT\",\"b\":\"79366.00\",\"B\":\"6.994\",\"a\":\"79366.10\",\"A\":\"2.653\",\"T\":1788782258678,\"E\":1788782258678,\"st\":1}}"}
{"receive_ns":1788782258604792000,"stream":"btcusdt@depth@100ms","event_type":"depthUpdate","event_time_ms":1788782258690,"raw_json":"{\"stream\":\"btcusdt@depth@100ms\",\"data\":{\"e\":\"depthUpdate\",\"E\":1788782258690,\"T\":1788782258689,\"s\":\"BTCUSDT\",\"ps\":\"BTCUSDT\",\"U\":11496347852810,\"u\":11496347858957,\"pu\":11496347852705,\"b\":[[\"1000.00\",\"24.754\"],[\"28866.00\",\"0.406\"],[\"29266.00\",\"1.694\"],[\"63493.00\",\"0.012\"],[\"71429.40\",\"0.048\"],[\"76191.30\",\"0.000\"],[\"77778.70\",\"1.460\"],[\"78387.00\",\"2.169\"],[\"78572.30\",\"12.650\"],[\"78968.60\",\"0.002\"],[\"78969.10\",\"0.000\"],[\"79123.90\",\"2.917\"],[\"79124.10\",\"0.000\"],[\"79124.70\",\"0.000\"],[\"79125.90\",\"1.018\"],[\"79143.60\",\"0.001\"],[\"79143.80\",\"35.380\"],[\"79171.80\",\"3.701\"],[\"79189.40\",\"0.001\"],[\"79189.60\",\"26.523\"],[\"79189.70\",\"0.068\"],[\"79220.60\",\"0.000\"],[\"79220.80\",\"17.748\"],[\"79224.60\",\"0.101\"],[\"79273.90\",\"0.241\"],[\"79274.10\",\"8.838\"],[\"79347.60\",\"0.313\"],[\"79350.10\",\"3.358\"],[\"79350.20\",\"0.950\"],[\"79357.20\",\"0.252\"],[\"79357.40\",\"0.030\"],[\"79358.00\",\"1.103\"],[\"79366.00\",\"6.994\"]],\"a\":[[\"79366.10\",\"2.653\"],[\"79367.20\",\"0.102\"],[\"79368.70\",\"0.153\"],[\"79369.20\",\"0.081\"],[\"79369.60\",\"0.006\"],[\"79370.10\",\"0.027\"],[\"79429.60\",\"0.349\"],[\"79560.00\",\"0.574\"],[\"79733.20\",\"0.692\"],[\"79733.30\",\"0.028\"],[\"79961.30\",\"3.746\"],[\"80080.40\",\"5.985\"],[\"80159.80\",\"12.336\"],[\"80416.80\",\"0.539\"]],\"st\":1}}"}
{"receive_ns":1788782258672437000,"stream":"btcusdt@bookTicker","event_type":"bookTicker","event_time_ms":1788782258757,"raw_json":"{\"stream\":\"btcusdt@bookTicker\",\"data\":{\"e\":\"bookTicker\",\"u\":11496347862646,\"s\":\"BTCUSDT\",\"ps\":\"BTCUSDT\",\"b\":\"79366.00\",\"B\":\"7.000\",\"a\":\"79366.10\",\"A\":\"2.653\",\"T\":1788782258757,\"E\":1788782258757,\"st\":1}}"}
{"receive_ns":1788782258673439000,"stream":"btcusdt@bookTicker","event_type":"bookTicker","event_time_ms":1788782258758,"raw_json":"{\"stream\":\"btcusdt@bookTicker\",\"data\":{\"e\":\"bookTicker\",\"u\":11496347862726,\"s\":\"BTCUSDT\",\"ps\":\"BTCUSDT\",\"b\":\"79366.00\",\"B\":\"6.994\",\"a\":\"79366.10\",\"A\":\"2.653\",\"T\":1788782258757,\"E\":1788782258758,\"st\":1}}"}
{"receive_ns":1788782258674516000,"stream":"btcusdt@bookTicker","event_type":"bookTicker","event_time_ms":1788782258758,"raw_json":"{\"stream\":\"btcusdt@bookTicker\",\"data\":{\"e\":\"bookTicker\",\"u\":11496347862776,\"s\":\"BTCUSDT\",\"ps\":\"BTCUSDT\",\"b\":\"79366.00\",\"B\":\"6.994\",\"a\":\"79366.10\",\"A\":\"2.934\",\"T\":1788782258758,\"E\":1788782258758,\"st\":1}}"}
{"receive_ns":1788782258675120000,"stream":"btcusdt@bookTicker","event_type":"bookTicker","event_time_ms":1788782258759,"raw_json":"{\"stream\":\"btcusdt@bookTicker\",\"data\":{\"e\":\"bookTicker\",\"u\":11496347862875,\"s\":\"BTCUSDT\",\"ps\":\"BTCUSDT\",\"b\":\"79366.00\",\"B\":\"6.994\",\"a\":\"79366.10\",\"A\":\"2.932\",\"T\":1788782258759,\"E\":1788782258759,\"st\":1}}"}
{"receive_ns":1788782258675358000,"stream":"btcusdt@bookTicker","event_type":"bookTicker","event_time_ms":1788782258760,"raw_json":"{\"stream\":\"btcusdt@bookTicker\",\"data\":{\"e\":\"bookTicker\",\"u\":11496347862886,\"s\":\"BTCUSDT\",\"ps\":\"BTCUSDT\",\"b\":\"79366.00\",\"B\":\"7.000\",\"a\":\"79366.10\",\"A\":\"2.932\",\"T\":1788782258759,\"E\":1788782258760,\"st\":1}}"}
{"receive_ns":1788782258675774000,"stream":"btcusdt@bookTicker","event_type":"bookTicker","event_time_ms":1788782258760,"raw_json":"{\"stream\":\"btcusdt@bookTicker\",\"data\":{\"e\":\"bookTicker\",\"u\":11496347862918,\"s\":\"BTCUSDT\",\"ps\":\"BTCUSDT\",\"b\":\"79366.00\",\"B\":\"6.994\",\"a\":\"79366.10\",\"A\":\"2.932\",\"T\":1788782258760,\"E\":1788782258760,\"st\":1}}"}
{"receive_ns":1788782258708075000,"stream":"btcusdt@depth@100ms","event_type":"depthUpdate","event_time_ms":1788782258792,"raw_json":"{\"stream\":\"btcusdt@depth@100ms\",\"data\":{\"e\":\"depthUpdate\",\"E\":1788782258792,\"T\":1788782258789,\"s\":\"BTCUSDT\",\"ps\":\"BTCUSDT\",\"U\":11496347858966,\"u\":11496347864598,\"pu\":11496347858957,\"b\":[[\"28866.00\",\"0.266\"],[\"29166.00\",\"0.042\"],[\"29266.00\",\"1.792\"],[\"71429.40\",\"0.048\"],[\"75176.90\",\"0.002\"],[\"78000.40\",\"1.280\"],[\"78437.40\",\"1.973\"],[\"78572.30\",\"12.650\"],[\"79123.90\",\"2.917\"],[\"79124.70\",\"0.010\"],[\"79125.90\",\"0.541\"],[\"79143.60\",\"2.170\"],[\"79143.80\",\"0.001\"],[\"79143.90\",\"0.634\"],[\"79145.80\",\"0.728\"],[\"79150.10\",\"0.005\"],[\"79189.40\",\"1.521\"],[\"79189.60\",\"0.004\"],[\"79191.30\",\"0.010\"],[\"79194.50\",\"0.012\"],[\"79220.40\",\"0.000\"],[\"79220.60\",\"2.646\"],[\"79220.80\",\"0.076\"],[\"79232.60\",\"0.001\"],[\"79240.50\",\"10.000\"],[\"79273.90\",\"0.376\"],[\"79274.10\",\"0.008\"],[\"79280.10\",\"6.016\"],[\"79307.90\",\"3.572\"],[\"79341.50\",\"0.000\"],[\"79358.50\",\"0.086\"],[\"79358.80\",\"0.080\"],[\"79366.00\",\"6.994\"]],\"a\":[[\"79366.10\",\"2.932\"],[\"79367.20\",\"0.002\"],[\"79369.20\",\"0.005\"],[\"79369.90\",\"0.076\"],[\"79371.40\",\"0.002\"],[\"79380.00\",\"0.108\"],[\"79424.30\",\"3.500\"],[\"79452.00\",\"2.170\"],[\"79452.10\",\"6.002\"],[\"79489.10\",\"2.119\"],[\"79489.70\",\"0.000\"],[\"79491.80\",\"10.000\"],[\"79493.00\",\"1.906\"],[\"79496.30\",\"0.000\"],[\"79499.50\",\"0.032\"],[\"79560.40\",\"0.001\"],[\"79560.50\",\"0.000\"],[\"79560.80\",\"0.000\"],[\"79578.90\",\"2.815\"],[\"79733.20\",\"0.836\"],[\"79733.30\",\"0.062\"],[\"80080.90\",\"0.873\"],[\"80159.80\",\"12.336\"],[\"80358.20\",\"6.987\"],[\"80953.40\",\"0.006\"]],\"st\":1}}"}
{"receive_ns":1788782258808758000,"stream":"btcusdt@depth@100ms","event_type":"depthUpdate","event_time_ms":1788782258894,"raw_json":"{\"stream\":\"btcusdt@depth@100ms\",\"data\":{\"e\":\"depthUpdate\",\"E\":1788782258894,\"T\":1788782258893,\"s\":\"BTCUSDT\",\"ps\":\"BTCUSDT\",\"U\":11496347864736,\"u\":11496347871760,\"pu\":11496347864598,\"b\":[[\"1000.00\",\"24.754\"],[\"28866.00\",\"0.147\"],[\"29166.00\",\"0.105\"],[\"29266.00\",\"1.848\"],[\"63493.00\",\"0.012\"],[\"71429.40\",\"0.048\"],[\"76191.30\",\"0.002\"],[\"78038.70\",\"2.021\"],[\"78271.20\",\"0.000\"],[\"78348.30\",\"0.130\"],[\"78427.70\",\"3.786\"],[\"78572.30\",\"12.650\"],[\"78969.20\",\"4.746\"],[\"79123.90\",\"3.457\"],[\"79125.90\",\"0.001\"],[\"79171.80\",\"3.719\"],[\"79181.80\",\"0.013\"],[\"79189.70\",\"0.050\"],[\"79231.60\",\"0.000\"],[\"79240.60\",\"0.006\"]],\"a\":[[\"79367.20\",\"0.102\"],[\"79491.70\",\"0.007\"],[\"79499.90\",\"0.909\"],[\"79560.30\",\"0.045\"],[\"79560.40\",\"0.001\"],[\"79560.70\",\"0.000\"],[\"79733.20\",\"0.836\"],[\"79763.00\",\"0.000\"],[\"80159.80\",\"12.336\"],[\"80271.30\",\"0.000\"],[\"80575.50\",\"16.632\"],[\"80843.00\",\"0.009\"]],\"st\":1}}"}
{"receive_ns":1788782258817815000,"stream":"btcusdt@bookTicker","event_type":"bookTicker","event_time_ms":1788782258904,"raw_json":"{\"stream\":\"btcusdt@bookTicker\",\"data\":{\"e\":\"bookTicker\",\"u\":11496347872435,\"s\":\"BTCUSDT\",\"ps\":\"BTCUSDT\",\"b\":\"79366.00\",\"B\":\"6.994\",\"a\":\"79366.10\",\"A\":\"2.850\",\"T\":1788782258903,\"E\":1788782258904,\"st\":1}}"}
{"receive_ns":1788782258821987000,"stream":"btcusdt@bookTicker","event_type":"bookTicker","event_time_ms":1788782258907,"raw_json":"{\"stream\":\"btcusdt@bookTicker\",\"data\":{\"e\":\"bookTicker\",\"u\":11496347872638,\"s\":\"BTCUSDT\",\"ps\":\"BTCUSDT\",\"b\":\"79366.00\",\"B\":\"6.994\",\"a\":\"79366.10\",\"A\":\"2.931\",\"T\":1788782258907,\"E\":1788782258907,\"st\":1}}"}
{"receive_ns":1788782258822645000,"stream":"btcusdt@bookTicker","event_type":"bookTicker","event_time_ms":1788782258908,"raw_json":"{\"stream\":\"btcusdt@bookTicker\",\"data\":{\"e\":\"bookTicker\",\"u\":11496347872731,\"s\":\"BTCUSDT\",\"ps\":\"BTCUSDT\",\"b\":\"79366.00\",\"B\":\"6.994\",\"a\":\"79366.10\",\"A\":\"2.933\",\"T\":1788782258908,\"E\":1788782258908,\"st\":1}}"}
{"receive_ns":1788782258823246000,"stream":"btcusdt@bookTicker","event_type":"bookTicker","event_time_ms":1788782258908,"raw_json":"{\"stream\":\"btcusdt@bookTicker\",\"data\":{\"e\":\"bookTicker\",\"u\":11496347872735,\"s\":\"BTCUSDT\",\"ps\":\"BTCUSDT\",\"b\":\"79366.00\",\"B\":\"6.994\",\"a\":\"79366.10\",\"A\":\"2.966\",\"T\":1788782258908,\"E\":1788782258908,\"st\":1}}"}
{"receive_ns":1788782258823692000,"stream":"btcusdt@bookTicker","event_type":"bookTicker","event_time_ms":1788782258909,"raw_json":"{\"stream\":\"btcusdt@bookTicker\",\"data\":{\"e\":\"bookTicker\",\"u\":11496347872808,\"s\":\"BTCUSDT\",\"ps\":\"BTCUSDT\",\"b\":\"79366.00\",\"B\":\"6.994\",\"a\":\"79366.10\",\"A\":\"2.970\",\"T\":1788782258909,\"E\":1788782258909,\"st\":1}}"}
{"receive_ns":1788782258825020000,"stream":"btcusdt@bookTicker","event_type":"bookTicker","event_time_ms":1788782258910,"raw_json":"{\"stream\":\"btcusdt@bookTicker\",\"data\":{\"e\":\"bookTicker\",\"u\":11496347872874,\"s\":\"BTCUSDT\",\"ps\":\"BTCUSDT\",\"b\":\"79366.00\",\"B\":\"6.994\",\"a\":\"79366.10\",\"A\":\"2.980\",\"T\":1788782258910,\"E\":1788782258910,\"st\":1}}"}
{"receive_ns":1788782258884385000,"stream":"btcusdt@bookTicker","event_type":"bookTicker","event_time_ms":1788782258969,"raw_json":"{\"stream\":\"btcusdt@bookTicker\",\"data\":{\"e\":\"bookTicker\",\"u\":11496347875819,\"s\":\"BTCUSDT\",\"ps\":\"BTCUSDT\",\"b\":\"79366.00\",\"B\":\"6.994\",\"a\":\"79366.10\",\"A\":\"2.976\",\"T\":1788782258969,\"E\":1788782258969,\"st\":1}}"}
{"receive_ns":1788782258884789000,"stream":"btcusdt@bookTicker","event_type":"bookTicker","event_time_ms":1788782258969,"raw_json":"{\"stream\":\"btcusdt@bookTicker\",\"data\":{\"e\":\"bookTicker\",\"u\":11496347875827,\"s\":\"BTCUSDT\",\"ps\":\"BTCUSDT\",\"b\":\"79366.00\",\"B\":\"6.994\",\"a\":\"79366.10\",\"A\":\"2.943\",\"T\":1788782258969,\"E\":1788782258969,\"st\":1}}"}
{"receive_ns":1788782258885046000,"stream":"btcusdt@bookTicker","event_type":"bookTicker","event_time_ms":1788782258969,"raw_json":"{\"stream\":\"btcusdt@bookTicker\",\"data\":{\"e\":\"bookTicker\",\"u\":11496347875834,\"s\":\"BTCUSDT\",\"ps\":\"BTCUSDT\",\"b\":\"79366.00\",\"B\":\"6.994\",\"a\":\"79366.10\",\"A\":\"2.933\",\"T\":1788782258969,\"E\":1788782258969,\"st\":1}}"}
{"receive_ns":1788782258911491000,"stream":"btcusdt@depth@100ms","event_type":"depthUpdate","event_time_ms":1788782258996,"raw_json":"{\"stream\":\"btcusdt@depth@100ms\",\"data\":{\"e\":\"depthUpdate\",\"E\":1788782258996,\"T\":1788782258993,\"s\":\"BTCUSDT\",\"ps\":\"BTCUSDT\",\"U\":11496347871836,\"u\":11496347877474,\"pu\":11496347871760,\"b\":[[\"1000.00\",\"24.754\"],[\"28866.00\",\"0.028\"],[\"29166.00\",\"0.161\"],[\"29266.00\",\"1.911\"],[\"63493.00\",\"0.012\"],[\"71429.40\",\"0.048\"],[\"76191.30\",\"0.000\"],[\"78572.30\",\"12.650\"],[\"78969.10\",\"0.001\"],[\"79123.90\",\"3.471\"],[\"79124.10\",\"0.063\"],[\"79124.70\",\"0.000\"],[\"79143.60\",\"0.001\"],[\"79143.80\",\"35.380\"],[\"79143.90\",\"0.571\"],[\"79145.80\",\"0.440\"],[\"79181.80\",\"0.005\"],[\"79189.40\",\"0.001\"],[\"79189.60\",\"26.523\"],[\"79204.70\",\"2.092\"],[\"79220.60\",\"1.890\"],[\"79220.80\",\"17.748\"],[\"79244.00\",\"1.657\"],[\"79273.90\",\"0.241\"],[\"79274.10\",\"8.838\"],[\"79294.50\",\"0.000\"],[\"79310.40\",\"0.010\"],[\"79340.10\",\"0.002\"],[\"79340.90\",\"0.453\"],[\"79341.80\",\"0.001\"],[\"79343.20\",\"0.002\"],[\"79343.80\",\"0.000\"],[\"79343.90\",\"0.045\"],[\"79351.10\",\"0.172\"],[\"79351.20\",\"0.732\"],[\"79353.10\",\"0.297\"],[\"79356.20\",\"0.043\"],[\"79358.50\",\"0.149\"],[\"79358.80\",\"0.017\"]],\"a\":[[\"79366.10\",\"2.933\"],[\"79367.20\",\"0.002\"],[\"79368.80\",\"0.002\"],[\"79369.10\",\"0.084\"],[\"79369.20\",\"0.005\"],[\"79369.90\",\"0.000\"],[\"79380.00\",\"0.023\"],[\"79421.70\",\"0.144\"],[\"79437.60\",\"0.014\"],[\"79487.30\",\"0.451\"],[\"79526.60\",\"2.788\"],[\"79560.30\",\"0.045\"],[\"79733.20\",\"0.753\"],[\"79733.30\",\"0.062\"],[\"79763.00\",\"0.001\"],[\"80159.80\",\"12.336\"],[\"80350.70\",\"0.001\"],[\"80358.20\",\"7.173\"]],\"st\":1}}"}
{"receive_ns":1788782258950444000,"stream":"btcusdt@bookTicker","event_type":"bookTicker","event_time_ms":1788782259037,"raw_json":"{\"stream\":\"btcusdt@bookTicker\",\"data\":{\"e\":\"bookTicker\",\"u\":11496347880403,\"s\":\"BTCUSDT\",\"ps\":\"BTCUSDT\",\"b\":\"79366.00\",\"B\":\"6.994\",\"a\":\"79366.10\",\"A\":\"2.932\",\"T\":1788782259037,\"E\":1788782259037,\"st\":1}}"}
{"receive_ns":1788782258953272000,"stream":"btcusdt@bookTicker","event_type":"bookTicker","event_time_ms":1788782259039,"raw_json":"{\"stream\":\"btcusdt@bookTicker\",\"data\":{\"e\":\"bookTicker\",\"u\":11496347880573,\"s\":\"BTCUSDT\",\"ps\":\"BTCUSDT\",\"b\":\"79366.00\",\"B\":\"6.994\",\"a\":\"79366.10\",\"A\":\"2.933\",\"T\":1788782259039,\"E\":1788782259039,\"st\":1}}"}
{"receive_ns":1788782259013376000,"stream":"btcusdt@depth@100ms","event_type":"depthUpdate","event_time_ms":1788782259098,"raw_json":"{\"stream\":\"btcusdt@depth@100ms\",\"data\":{\"e\":\"depthUpdate\",\"E\":1788782259098,\"T\":1788782259097,\"s\":\"BTCUSDT\",\"ps\":\"BTCUSDT\",\"U\":11496347877652,\"u\":11496347883703,\"pu\":11496347877474,\"b\":[[\"28866.00\",\"0.000\"],[\"29166.00\",\"0.308\"],[\"29266.00\",\"1.792\"],[\"63493.00\",\"0.014\"],[\"71429.40\",\"0.048\"],[\"76191.30\",\"0.002\"],[\"78262.80\",\"3.518\"],[\"78572.30\",\"12.650\"],[\"78667.80\",\"0.129\"],[\"79116.10\",\"0.000\"],[\"79123.90\",\"3.371\"],[\"79124.70\",\"0.005\"],[\"79143.60\",\"2.169\"],[\"79143.80\",\"0.001\"],[\"79143.90\",\"0.625\"],[\"79145.80\",\"0.714\"],[\"79171.80\",\"3.701\"],[\"79181.80\",\"0.013\"],[\"79189.40\",\"1.520\"],[\"79189.60\",\"0.004\"],[\"79189.70\",\"0.068\"],[\"79220.60\",\"2.646\"],[\"79220.80\",\"0.076\"],[\"79274.00\",\"0.135\"],[\"79274.10\",\"0.008\"],[\"79277.10\",\"1.597\"],[\"79343.20\",\"0.632\"],[\"79344.90\",\"0.000\"],[\"79351.20\",\"0.102\"],[\"79351.30\",\"0.120\"],[\"79351.40\",\"0.071\"],[\"79351.50\",\"0.100\"]],\"a\":[[\"79366.10\",\"2.933\"],[\"79367.20\",\"0.002\"],[\"79380.00\",\"0.108\"],[\"79380.40\",\"1.896\"],[\"79384.70\",\"0.006\"],[\"79390.70\",\"0.013\"],[\"79391.70\",\"0.454\"],[\"79560.20\",\"0.000\"],[\"79560.30\",\"0.045\"],[\"79733.20\",\"0.771\"],[\"80159.80\",\"12.336\"],[\"80219.90\",\"0.000\"],[\"80239.10\",\"6.349\"],[\"80862.10\",\"0.806\"]],\"st\":1}}"}
{"receive_ns":1788782259018195000,"stream":"btcusdt@bookTicker","event_type":"bookTicker","event_time_ms":1788782259103,"raw_json":"{\"stream\":\"btcusdt@bookTicker\",\"data\":{\"e\":\"bookTicker\",\"u\":11496347883991,\"s\":\"BTCUSDT\",\"ps\":\"BTCUSDT\",\"b\":\"79366.00\",\"B\":\"6.994\",\"a\":\"79366.10\",\"A\":\"2.906\",\"T\":1788782259103,\"E\":1788782259103,\"st\":1}}"}
{"receive_ns":1788782259021578000,"stream":"btcusdt@bookTicker","event_type":"bookTicker","event_time_ms":1788782259107,"raw_json":"{\"stream\":\"btcusdt@bookTicker\",\"data\":{\"e\":\"bookTicker\",\"u\":11496347884340,\"s\":\"BTCUSDT\",\"ps\":\"BTCUSDT\",\"b\":\"79366.00\",\"B\":\"6.994\",\"a\":\"79366.10\",\"A\":\"2.926\",\"T\":1788782259107,\"E\":1788782259107,\"st\":1}}"}
{"receive_ns":1788782259022142000,"stream":"btcusdt@bookTicker","event_type":"bookTicker","event_time_ms":1788782259108,"raw_json":"{\"stream\":\"btcusdt@bookTicker\",\"data\":{\"e\":\"bookTicker\",\"u\":11496347884452,\"s\":\"BTCUSDT\",\"ps\":\"BTCUSDT\",\"b\":\"79366.00\",\"B\":\"6.994\",\"a\":\"79366.10\",\"A\":\"2.924\",\"T\":1788782259108,\"E\":1788782259108,\"st\":1}}"}
{"receive_ns":1788782259032250000,"stream":"btcusdt@bookTicker","event_type":"bookTicker","event_time_ms":1788782259119,"raw_json":"{\"stream\":\"btcusdt@bookTicker\",\"data\":{\"e\":\"bookTicker\",\"u\":11496347885428,\"s\":\"BTCUSDT\",\"ps\":\"BTCUSDT\",\"b\":\"79366.00\",\"B\":\"6.994\",\"a\":\"79366.10\",\"A\":\"2.925\",\"T\":1788782259119,\"E\":1788782259119,\"st\":1}}"}
{"receive_ns":1788782259084282000,"stream":"btcusdt@bookTicker","event_type":"bookTicker","event_time_ms":1788782259170,"raw_json":"{\"stream\":\"btcusdt@bookTicker\",\"data\":{\"e\":\"bookTicker\",\"u\":11496347888696,\"s\":\"BTCUSDT\",\"ps\":\"BTCUSDT\",\"b\":\"79366.00\",\"B\":\"6.993\",\"a\":\"79366.10\",\"A\":\"2.925\",\"T\":1788782259170,\"E\":1788782259170,\"st\":1}}"}
{"receive_ns":1788782259114976000,"stream":"btcusdt@depth@100ms","event_type":"depthUpdate","event_time_ms":1788782259200,"raw_json":"{\"stream\":\"btcusdt@depth@100ms\",\"data\":{\"e\":\"depthUpdate\",\"E\":1788782259200,\"T\":1788782259199,\"s\":\"BTCUSDT\",\"ps\":\"BTCUSDT\",\"U\":11496347883724,\"u\":11496347890452,\"pu\":11496347883703,\"b\":[[\"1000.00\",\"24.754\"],[\"29166.00\",\"0.490\"],[\"29266.00\",\"1.610\"],[\"63493.00\",\"0.012\"],[\"71429.40\",\"0.048\"],[\"76191.30\",\"0.000\"],[\"77778.70\",\"1.457\"],[\"78193.80\",\"10.366\"],[\"78572.30\",\"12.650\"],[\"78969.20\",\"4.746\"],[\"79123.90\",\"3.471\"],[\"79124.10\",\"0.063\"],[\"79124.70\",\"0.000\"],[\"79143.60\",\"0.001\"],[\"79143.80\",\"35.380\"],[\"79171.80\",\"3.719\"],[\"79181.80\",\"0.005\"],[\"79189.40\",\"0.001\"],[\"79189.60\",\"26.523\"],[\"79189.70\",\"0.050\"],[\"79220.60\",\"1.890\"],[\"79220.80\",\"17.748\"],[\"79244.00\",\"1.657\"],[\"79274.00\",\"0.000\"],[\"79274.10\",\"8.838\"],[\"79277.10\",\"1.604\"],[\"79344.90\",\"0.002\"],[\"79356.90\",\"0.028\"],[\"79357.40\",\"0.004\"],[\"79357.60\",\"0.030\"],[\"79366.00\",\"6.993\"]],\"a\":[[\"79366.10\",\"2.925\"],[\"79367.20\",\"0.101\"],[\"79379.10\",\"0.006\"],[\"79380.20\",\"0.080\"],[\"79381.30\",\"0.001\"],[\"79384.70\",\"0.008\"],[\"79487.30\",\"0.451\"],[\"79560.10\",\"0.000\"],[\"79560.20\",\"0.000\"],[\"79560.30\",\"0.171\"],[\"79560.60\",\"0.001\"],[\"79733.20\",\"0.836\"],[\"79733.30\",\"0.062\"],[\"80159.80\",\"12.338\"],[\"80534.90\",\"0.008\"],[\"87302.80\",\"0.000\"]],\"st\":1}}"}
{"receive_ns":1788782259115461000,"stream":"btcusdt@bookTicker","event_type":"bookTicker","event_time_ms":1788782259200,"raw_json":"{\"stream\":\"btcusdt@bookTicker\",\"data\":{\"e\":\"bookTicker\",\"u\":11496347890497,\"s\":\"BTCUSDT\",\"ps\":\"BTCUSDT\",\"b\":\"79366.00\",\"B\":\"6.993\",\"a\":\"79366.10\",\"A\":\"3.037\",\"T\":1788782259200,\"E\":1788782259200,\"st\":1}}"}
{"receive_ns":1788782259115829000,"stream":"btcusdt@bookTicker","event_type":"bookTicker","event_time_ms":1788782259201,"raw_json":"{\"stream\":\"btcusdt@bookTicker\",\"data\":{\"e\":\"bookTicker\",\"u\":11496347890613,\"s\":\"BTCUSDT\",\"ps\":\"BTCUSDT\",\"b\":\"79366.00\",\"B\":\"6.993\",\"a\":\"79366.10\",\"A\":\"3.039\",\"T\":1788782259201,\"E\":1788782259201,\"st\":1}}"}
{"receive_ns":1788782259119171000,"stream":"btcusdt@bookTicker","event_type":"bookTicker","event_time_ms":1788782259204,"raw_json":"{\"stream\":\"btcusdt@bookTicker\",\"data\":{\"e\":\"bookTicker\",\"u\":11496347890733,\"s\":\"BTCUSDT\",\"ps\":\"BTCUSDT\",\"b\":\"79366.00\",\"B\":\"6.993\",\"a\":\"79366.10\",\"A\":\"3.121\",\"T\":1788782259204,\"E\":1788782259204,\"st\":1}}"}
{"receive_ns":1788782259138472000,"stream":"btcusdt@bookTicker","event_type":"bookTicker","event_time_ms":1788782259223,"raw_json":"{\"stream\":\"btcusdt@bookTicker\",\"data\":{\"e\":\"bookTicker\",\"u\":11496347892078,\"s\":\"BTCUSDT\",\"ps\":\"BTCUSDT\",\"b\":\"79366.00\",\"B\":\"6.993\",\"a\":\"79366.10\",\"A\":\"3.040\",\"T\":1788782259223,\"E\":1788782259223,\"st\":1}}"}
{"receive_ns":1788782259163133000,"stream":"btcusdt@bookTicker","event_type":"bookTicker","event_time_ms":1788782259249,"raw_json":"{\"stream\":\"btcusdt@bookTicker\",\"data\":{\"e\":\"bookTicker\",\"u\":11496347894311,\"s\":\"BTCUSDT\",\"ps\":\"BTCUSDT\",\"b\":\"79366.00\",\"B\":\"6.993\",\"a\":\"79366.10\",\"A\":\"3.028\",\"T\":1788782259248,\"E\":1788782259249,\"st\":1}}"}
{"receive_ns":1788782259163980000,"stream":"btcusdt@trade","event_type":"trade","event_time_ms":1788782259249,"raw_json":"{\"stream\":\"btcusdt@trade\",\"data\":{\"e\":\"trade\",\"E\":1788782259249,\"T\":1788782259248,\"s\":\"BTCUSDT\",\"t\":8057739779,\"p\":\"79366.10\",\"q\":\"0.012\",\"X\":\"MARKET\",\"m\":false,\"st\":1}}"}
{"receive_ns":1788782259164360000,"stream":"btcusdt@bookTicker","event_type":"bookTicker","event_time_ms":1788782259250,"raw_json":"{\"stream\":\"btcusdt@bookTicker\",\"data\":{\"e\":\"bookTicker\",\"u\":11496347894438,\"s\":\"BTCUSDT\",\"ps\":\"BTCUSDT\",\"b\":\"79366.00\",\"B\":\"6.999\",\"a\":\"79366.10\",\"A\":\"3.028\",\"T\":1788782259250,\"E\":1788782259250,\"st\":1}}"}
{"receive_ns":1788782259164785000,"stream":"btcusdt@bookTicker","event_type":"bookTicker","event_time_ms":1788782259251,"raw_json":"{\"stream\":\"btcusdt@bookTicker\",\"data\":{\"e\":\"bookTicker\",\"u\":11496347894538,\"s\":\"BTCUSDT\",\"ps\":\"BTCUSDT\",\"b\":\"79366.00\",\"B\":\"6.993\",\"a\":\"79366.10\",\"A\":\"3.028\",\"T\":1788782259251,\"E\":1788782259251,\"st\":1}}"}
{"receive_ns":1788782259216640000,"stream":"btcusdt@depth@100ms","event_type":"depthUpdate","event_time_ms":1788782259302,"raw_json":"{\"stream\":\"btcusdt@depth@100ms\",\"data\":{\"e\":\"depthUpdate\",\"E\":1788782259302,\"T\":1788782259300,\"s\":\"BTCUSDT\",\"ps\":\"BTCUSDT\",\"U\":11496347890468,\"u\":11496347897864,\"pu\":11496347890452,\"b\":[[\"29166.00\",\"0.665\"],[\"29266.00\",\"1.435\"],[\"71429.40\",\"0.048\"],[\"75062.90\",\"0.002\"],[\"78373.90\",\"10.783\"],[\"78572.30\",\"12.650\"],[\"79143.90\",\"5.508\"],[\"79145.80\",\"0.714\"],[\"79181.30\",\"0.000\"],[\"79181.40\",\"0.001\"],[\"79182.30\",\"3.150\"],[\"79190.30\",\"4.752\"],[\"79220.60\",\"1.890\"],[\"79242.30\",\"1.851\"],[\"79279.40\",\"0.388\"],[\"79279.70\",\"0.023\"],[\"79340.00\",\"0.903\"],[\"79340.90\",\"0.000\"],[\"79366.00\",\"6.993\"]],\"a\":[[\"79366.10\",\"3.028\"],[\"79367.20\",\"0.001\"],[\"79369.10\",\"0.008\"],[\"79369.70\",\"0.000\"],[\"79373.30\",\"0.052\"],[\"79380.00\",\"0.023\"],[\"79383.20\",\"0.103\"],[\"79384.00\",\"0.618\"],[\"79389.30\",\"0.001\"],[\"79390.40\",\"0.454\"],[\"79391.70\",\"0.001\"],[\"79404.30\",\"2.009\"],[\"79408.90\",\"1.825\"],[\"79409.50\",\"0.058\"],[\"79409.60\",\"0.001\"],[\"79454.10\",\"0.102\"],[\"79454.40\",\"1.599\"],[\"79492.90\",\"1.890\"],[\"79493.00\",\"0.016\"],[\"79501.60\",\"3.627\"],[\"79501.80\",\"0.000\"],[\"79560.20\",\"0.000\"],[\"79560.30\",\"0.045\"],[\"79560.60\",\"0.001\"],[\"79733.20\",\"0.836\"],[\"80090.00\",\"0.003\"],[\"80159.80\",\"13.270\"]],\"st\":1}}"}
{"receive_ns":1788782259318805000,"stream":"btcusdt@depth@100ms","event_type":"depthUpdate","event_time_ms":1788782259404,"raw_json":"{\"stream\":\"btcusdt@depth@100ms\",\"data\":{\"e\":\"depthUpdate\",\"E\":1788782259404,\"T\":1788782259401,\"s\":\"BTCUSDT\",\"ps\":\"BTCUSDT\",\"U\":11496347897950,\"u\":11496347904098,\"pu\":11496347897864,\"b\":[[\"29166.00\",\"0.847\"],[\"29266.00\",\"1.253\"],[\"63492.80\",\"0.000\"],[\"71429.40\",\"0.048\"],[\"76191.30\",\"0.002\"],[\"78193.80\",\"10.079\"],[\"78217.50\",\"0.153\"],[\"78572.30\",\"12.650\"],[\"78666.50\",\"0.001\"],[\"79123.90\",\"2.680\"],[\"79124.10\",\"0.000\"],[\"79145.80\",\"1.254\"],[\"79146.90\",\"0.000\"],[\"79171.80\",\"3.701\"],[\"79189.70\",\"0.068\"],[\"79194.50\",\"0.000\"],[\"79347.60\",\"0.313\"],[\"79348.80\",\"0.004\"],[\"79350.20\",\"0.950\"]],\"a\":[[\"79367.20\",\"0.101\"],[\"79378.00\",\"0.002\"],[\"79384.00\",\"0.620\"],[\"79733.20\",\"0.692\"],[\"79733.30\",\"0.028\"],[\"79772.40\",\"0.110\"],[\"79851.80\",\"0.115\"],[\"80010.60\",\"0.136\"],[\"80159.80\",\"13.270\"],[\"80215.30\",\"0.684\"],[\"80248.80\",\"0.000\"],[\"80358.20\",\"8.105\"],[\"80407.60\",\"0.000\"]],\"st\":1}}"}
{"receive_ns":1788782259339449000,"stream":"btcusdt@bookTicker","event_type":"bookTicker","event_time_ms":1788782259425,"raw_json":"{\"stream\":\"btcusdt@bookTicker\",\"data\":{\"e\":\"bookTicker\",\"u\":11496347905534,\"s\":\"BTCUSDT\",\"ps\":\"BTCUSDT\",\"b\":\"79366.00\",\"B\":\"6.993\",\"a\":\"79366.10\",\"A\":\"2.916\",\"T\":1788782259424,\"E\":1788782259425,\"st\":1}}"}
{"receive_ns":1788782259339989000,"stream":"btcusdt@bookTicker","event_type":"bookTicker","event_time_ms":1788782259426,"raw_json":"{\"stream\":\"btcusdt@bookTicker\",\"data\":{\"e\":\"bookTicker\",\"u\":11496347905629,\"s\":\"BTCUSDT\",\"ps\":\"BTCUSDT\",\"b\":\"79366.00\",\"B\":\"6.993\",\"a\":\"79366.10\",\"A\":\"2.914\",\"T\":1788782259426,\"E\":1788782259426,\"st\":1}}"}
{"receive_ns":1788782259406522000,"stream":"btcusdt@bookTicker","event_type":"bookTicker","event_time_ms":1788782259492,"raw_json":"{\"stream\":\"btcusdt@bookTicker\",\"data\":{\"e\":\"bookTicker\",\"u\":11496347908452,\"s\":\"BTCUSDT\",\"ps\":\"BTCUSDT\",\"b\":\"79366.00\",\"B\":\"6.993\",\"a\":\"79366.10\",\"A\":\"2.974\",\"T\":1788782259492,\"E\":1788782259492,\"st\":1}}"}
{"receive_ns":1788782259407110000,"stream":"btcusdt@bookTicker","event_type":"bookTicker","event_time_ms":1788782259493,"raw_json":"{\"stream\":\"btcusdt@bookTicker\",\"data\":{\"e\":\"bookTicker\",\"u\":11496347908502,\"s\":\"BTCUSDT\",\"ps\":\"BTCUSDT\",\"b\":\"79366.00\",\"B\":\"6.993\",\"a\":\"79366.10\",\"A\":\"2.976\",\"T\":1788782259493,\"E\":1788782259493,\"st\":1}}"}
{"receive_ns":1788782259417278000,"stream":"btcusdt@bookTicker","event_type":"bookTicker","event_time_ms":1788782259504,"raw_json":"{\"stream\":\"btcusdt@bookTicker\",\"data\":{\"e\":\"bookTicker\",\"u\":11496347909140,\"s\":\"BTCUSDT\",\"ps\":\"BTCUSDT\",\"b\":\"79366.00\",\"B\":\"6.993\",\"a\":\"79366.10\",\"A\":\"3.025\",\"T\":1788782259504,\"E\":1788782259504,\"st\":1}}"}
{"receive_ns":1788782259418003000,"stream":"btcusdt@bookTicker","event_type":"bookTicker","event_time_ms":1788782259505,"raw_json":"{\"stream\":\"btcusdt@bookTicker\",\"data\":{\"e\":\"bookTicker\",\"u\":11496347909200,\"s\":\"BTCUSDT\",\"ps\":\"BTCUSDT\",\"b\":\"79366.00\",\"B\":\"6.993\",\"a\":\"79366.10\",\"A\":\"3.023\",\"T\":1788782259505,\"E\":1788782259505,\"st\":1}}"}
{"receive_ns":1788782259421114000,"stream":"btcusdt@depth@100ms","event_type":"depthUpdate","event_time_ms":1788782259506,"raw_json":"{\"stream\":\"btcusdt@depth@100ms\",\"data\":{\"e\":\"depthUpdate\",\"E\":1788782259506,\"T\":1788782259505,\"s\":\"BTCUSDT\",\"ps\":\"BTCUSDT\",\"U\":11496347904461,\"u\":11496347909225,\"pu\":11496347904098,\"b\":[[\"1000.00\",\"24.754\"],[\"29166.00\",\"1.022\"],[\"29266.00\",\"1.078\"],[\"71429.40\",\"0.048\"],[\"75397.70\",\"0.025\"],[\"76191.30\",\"0.000\"],[\"78038.70\",\"1.509\"],[\"78493.00\",\"8.460\"],[\"78507.10\",\"1.263\"],[\"78572.30\",\"12.652\"],[\"78969.20\",\"4.736\"],[\"79123.90\",\"3.157\"],[\"79124.70\",\"0.000\"],[\"79143.60\",\"0.001\"],[\"79143.80\",\"35.380\"],[\"79143.90\",\"0.625\"],[\"79145.80\",\"0.791\"],[\"79145.90\",\"0.063\"],[\"79171.80\",\"3.719\"],[\"79181.80\",\"0.005\"],[\"79189.40\",\"0.001\"],[\"79189.60\",\"26.523\"],[\"79189.70\",\"0.050\"],[\"79190.30\",\"0.902\"],[\"79220.60\",\"1.890\"],[\"79220.80\",\"17.748\"],[\"79244.00\",\"1.657\"],[\"79274.00\",\"0.000\"],[\"79274.10\",\"8.838\"],[\"79343.20\",\"0.002\"],[\"79343.80\",\"0.000\"],[\"79351.00\",\"0.113\"],[\"79351.10\",\"0.802\"],[\"79357.00\",\"0.003\"]],\"a\":[[\"79366.10\",\"3.086\"],[\"79367.20\",\"0.001\"],[\"79369.50\",\"0.076\"],[\"79369.60\",\"0.006\"],[\"79369.80\",\"0.001\"],[\"79384.00\",\"0.535\"],[\"79387.30\",\"0.045\"],[\"79487.30\",\"0.451\"],[\"79561.10\",\"0.001\"],[\"79733.20\",\"0.773\"],[\"79733.30\",\"0.062\"],[\"80085.00\",\"0.197\"],[\"80159.80\",\"13.270\"],[\"80240.50\",\"0.697\"],[\"80318.50\",\"40.610\"],[\"80329.30\",\"4.931\"],[\"80350.60\",\"1.242\"],[\"80476.00\",\"0.990\"]],\"st\":1}}"}
{"receive_ns":1788782259421757000,"stream":"btcusdt@bookTicker","event_type":"bookTicker","event_time_ms":1788782259505,"raw_json":"{\"stream\":\"btcusdt@bookTicker\",\"data\":{\"e\":\"bookTicker\",\"u\":11496347909225,\"s\":\"BTCUSDT\",\"ps\":\"BTCUSDT\",\"b\":\"79366.00\",\"B\":\"6.993\",\"a\":\"79366.10\",\"A\":\"3.086\",\"T\":1788782259505,\"E\":1788782259505,\"st\":1}}"}
{"receive_ns":1788782259422109000,"stream":"btcusdt@bookTicker","event_type":"bookTicker","event_time_ms":1788782259506,"raw_json":"{\"stream\":\"btcusdt@bookTicker\",\"data\":{\"e\":\"bookTicker\",\"u\":11496347909282,\"s\":\"BTCUSDT\",\"ps\":\"BTCUSDT\",\"b\":\"79366.00\",\"B\":\"6.993\",\"a\":\"79366.10\",\"A\":\"3.088\",\"T\":1788782259506,\"E\":1788782259506,\"st\":1}}"}
{"receive_ns":1788782259462897000,"stream":"btcusdt@bookTicker","event_type":"bookTicker","event_time_ms":1788782259549,"raw_json":"{\"stream\":\"btcusdt@bookTicker\",\"data\":{\"e\":\"bookTicker\",\"u\":11496347911770,\"s\":\"BTCUSDT\",\"ps\":\"BTCUSDT\",\"b\":\"79366.00\",\"B\":\"6.993\",\"a\":\"79366.10\",\"A\":\"3.087\",\"T\":1788782259549,\"E\":1788782259549,\"st\":1}}"}
{"receive_ns":1788782259463787000,"stream":"btcusdt@bookTicker","event_type":"bookTicker","event_time_ms":1788782259551,"raw_json":"{\"stream\":\"btcusdt@bookTicker\",\"data\":{\"e\":\"bookTicker\",\"u\":11496347911890,\"s\":\"BTCUSDT\",\"ps\":\"BTCUSDT\",\"b\":\"79366.00\",\"B\":\"6.993\",\"a\":\"79366.10\",\"A\":\"3.088\",\"T\":1788782259551,\"E\":1788782259551,\"st\":1}}"}
{"receive_ns":1788782259522959000,"stream":"btcusdt@depth@100ms","event_type":"depthUpdate","event_time_ms":1788782259608,"raw_json":"{\"stream\":\"btcusdt@depth@100ms\",\"data\":{\"e\":\"depthUpdate\",\"E\":1788782259608,\"T\":1788782259606,\"s\":\"BTCUSDT\",\"ps\":\"BTCUSDT\",\"U\":11496347909242,\"u\":11496347914899,\"pu\":11496347909225,\"b\":[[\"29166.00\",\"1.204\"],[\"29266.00\",\"0.896\"],[\"63493.00\",\"0.012\"],[\"71429.40\",\"0.048\"],[\"76191.30\",\"0.002\"],[\"77778.70\",\"1.460\"],[\"78413.90\",\"0.000\"],[\"78572.30\",\"12.650\"],[\"78651.70\",\"6.981\"],[\"78666.10\",\"0.000\"],[\"79123.90\",\"3.834\"],[\"79124.70\",\"0.010\"],[\"79143.60\",\"2.165\"],[\"79143.80\",\"0.001\"],[\"79145.80\",\"0.251\"],[\"79181.80\",\"0.017\"],[\"79189.40\",\"1.518\"],[\"79189.60\",\"0.004\"],[\"79220.60\",\"2.645\"],[\"79220.80\",\"0.076\"],[\"79274.00\",\"0.134\"],[\"79274.10\",\"0.008\"],[\"79327.70\",\"0.101\"],[\"79343.20\",\"0.632\"],[\"79347.60\",\"0.313\"],[\"79350.10\",\"3.358\"],[\"79350.20\",\"0.509\"],[\"79350.30\",\"0.441\"],[\"79351.10\",\"0.172\"],[\"79351.20\",\"0.102\"],[\"79351.30\",\"0.120\"],[\"79351.40\",\"0.071\"],[\"79351.50\",\"0.100\"],[\"79353.10\",\"0.034\"],[\"79356.20\",\"0.001\"]],\"a\":[[\"79366.10\",\"3.088\"],[\"79369.40\",\"0.076\"],[\"79369.50\",\"0.000\"],[\"79380.00\",\"0.108\"],[\"79384.10\",\"0.001\"],[\"79390.40\",\"0.001\"],[\"79391.70\",\"0.454\"],[\"79407.20\",\"2.598\"],[\"79572.50\",\"0.025\"],[\"79733.20\",\"0.771\"],[\"80159.80\",\"13.270\"],[\"80371.50\",\"1.551\"],[\"80398.30\",\"0.870\"],[\"80430.90\",\"0.621\"],[\"80485.20\",\"1.243\"]],\"st\":1}}"}
{"receive_ns":1788782259599231000,"stream":"btcusdt@bookTicker","event_type":"bookTicker","event_time_ms":1788782259685,"raw_json":"{\"stream\":\"btcusdt@bookTicker\",\"data\":{\"e\":\"bookTicker\",\"u\":11496347919221,\"s\":\"BTCUSDT\",\"ps\":\"BTCUSDT\",\"b\":\"79366.00\",\"B\":\"6.993\",\"a\":\"79366.10\",\"A\":\"3.006\",\"T\":1788782259685,\"E\":1788782259685,\"st\":1}}"}
{"receive_ns":1788782259599808000,"stream":"btcusdt@bookTicker","event_type":"bookTicker","event_time_ms":1788782259686,"raw_json":"{\"stream\":\"btcusdt@bookTicker\",\"data\":{\"e\":\"bookTicker\",\"u\":11496347919280,\"s\":\"BTCUSDT\",\"ps\":\"BTCUSDT\",\"b\":\"79366.00\",\"B\":\"6.993\",\"a\":\"79366.10\",\"A\":\"2.943\",\"T\":1788782259686,\"E\":1788782259686,\"st\":1}}"}
{"receive_ns":1788782259600148000,"stream":"btcusdt@bookTicker","event_type":"bookTicker","event_time_ms":1788782259686,"raw_json":"{\"stream\":\"btcusdt@bookTicker\",\"data\":{\"e\":\"bookTicker\",\"u\":11496347919286,\"s\":\"BTCUSDT\",\"ps\":\"BTCUSDT\",\"b\":\"79366.00\",\"B\":\"6.993\",\"a\":\"79366.10\",\"A\":\"2.894\",\"T\":1788782259686,\"E\":1788782259686,\"st\":1}}"}
{"receive_ns":1788782259603434000,"stream":"btcusdt@bookTicker","event_type":"bookTicker","event_time_ms":1788782259688,"raw_json":"{\"stream\":\"btcusdt@bookTicker\",\"data\":{\"e\":\"bookTicker\",\"u\":11496347919380,\"s\":\"BTCUSDT\",\"ps\":\"BTCUSDT\",\"b\":\"79366.00\",\"B\":\"6.993\",\"a\":\"79366.10\",\"A\":\"2.947\",\"T\":1788782259688,\"E\":1788782259688,\"st\":1}}"}
{"receive_ns":1788782259604082000,"stream":"btcusdt@bookTicker","event_type":"bookTicker","event_time_ms":1788782259689,"raw_json":"{\"stream\":\"btcusdt@bookTicker\",\"data\":{\"e\":\"bookTicker\",\"u\":11496347919454,\"s\":\"BTCUSDT\",\"ps\":\"BTCUSDT\",\"b\":\"79366.00\",\"B\":\"6.993\",\"a\":\"79366.10\",\"A\":\"2.945\",\"T\":1788782259689,\"E\":1788782259689,\"st\":1}}"}
{"receive_ns":1788782259605283000,"stream":"btcusdt@bookTicker","event_type":"bookTicker","event_time_ms":1788782259691,"raw_json":"{\"stream\":\"btcusdt@bookTicker\",\"data\":{\"e\":\"bookTicker\",\"u\":11496347919540,\"s\":\"BTCUSDT\",\"ps\":\"BTCUSDT\",\"b\":\"79366.00\",\"B\":\"6.993\",\"a\":\"79366.10\",\"A\":\"3.026\",\"T\":1788782259691,\"E\":1788782259691,\"st\":1}}"}
{"receive_ns":1788782259606255000,"stream":"btcusdt@bookTicker","event_type":"bookTicker","event_time_ms":1788782259692,"raw_json":"{\"stream\":\"btcusdt@bookTicker\",\"data\":{\"e\":\"bookTicker\",\"u\":11496347919581,\"s\":\"BTCUSDT\",\"ps\":\"BTCUSDT\",\"b\":\"79366.00\",\"B\":\"6.993\",\"a\":\"79366.10\",\"A\":\"3.028\",\"T\":1788782259692,\"E\":1788782259692,\"st\":1}}"}
{"receive_ns":1788782259607019000,"stream":"btcusdt@bookTicker","event_type":"bookTicker","event_time_ms":1788782259693,"raw_json":"{\"stream\":\"btcusdt@bookTicker\",\"data\":{\"e\":\"bookTicker\",\"u\":11496347919648,\"s\":\"BTCUSDT\",\"ps\":\"BTCUSDT\",\"b\":\"79366.00\",\"B\":\"6.993\",\"a\":\"79366.10\",\"A\":\"3.039\",\"T\":1788782259693,\"E\":1788782259693,\"st\":1}}"}
{"receive_ns":1788782259623715000,"stream":"btcusdt@depth@100ms","event_type":"depthUpdate","event_time_ms":1788782259710,"raw_json":"{\"stream\":\"btcusdt@depth@100ms\",\"data\":{\"e\":\"depthUpdate\",\"E\":1788782259710,\"T\":1788782259709,\"s\":\"BTCUSDT\",\"ps\":\"BTCUSDT\",\"U\":11496347915050,\"u\":11496347920508,\"pu\":11496347914899,\"b\":[[\"29166.00\",\"1.379\"],[\"29266.00\",\"0.721\"],[\"71429.40\",\"0.048\"],[\"75397.80\",\"0.008\"],[\"76191.30\",\"0.000\"],[\"77778.70\",\"1.463\"],[\"78239.00\",\"1.071\"],[\"78334.20\",\"3.689\"],[\"78349.30\",\"0.000\"],[\"78387.00\",\"1.978\"],[\"78572.30\",\"12.652\"],[\"79123.90\",\"3.457\"],[\"79124.70\",\"0.000\"],[\"79143.60\",\"2.129\"],[\"79143.80\",\"0.001\"],[\"79143.90\",\"0.688\"],[\"79144.70\",\"0.000\"],[\"79145.80\",\"0.251\"],[\"79145.90\",\"0.000\"],[\"79147.30\",\"0.303\"],[\"79171.80\",\"3.701\"],[\"79181.80\",\"0.005\"],[\"79189.40\",\"1.492\"],[\"79189.60\",\"0.004\"],[\"79189.70\",\"0.068\"],[\"79194.50\",\"0.012\"],[\"79220.60\",\"2.632\"],[\"79220.80\",\"0.076\"],[\"79228.30\",\"0.631\"],[\"79274.00\",\"0.132\"],[\"79274.10\",\"0.008\"],[\"79312.10\",\"0.001\"],[\"79324.70\",\"0.000\"],[\"79327.40\",\"0.562\"],[\"79327.70\",\"1.057\"],[\"79335.90\",\"0.000\"],[\"79343.20\",\"0.002\"],[\"79351.00\",\"0.743\"]],\"a\":[[\"79366.10\",\"3.039\"],[\"79367.20\",\"0.001\"],[\"79369.40\",\"0.000\"],[\"79387.50\",\"0.255\"],[\"79398.80\",\"0.001\"],[\"79408.90\",\"0.265\"],[\"79411.30\",\"1.454\"],[\"79573.70\",\"0.000\"],[\"79733.20\",\"0.529\"],[\"79733.30\",\"0.062\"],[\"80099.20\",\"9.347\"],[\"80151.90\",\"2.180\"],[\"80159.80\",\"13.270\"],[\"80398.30\",\"1.740\"]],\"st\":1}}"}
{"receive_ns":1788782259700246000,"stream":"btcusdt@bookTicker","event_type":"bookTicker","event_time_ms":1788782259778,"raw_json":"{\"stream\":\"btcusdt@bookTicker\",\"data\":{\"e\":\"bookTicker\",\"u\":11496347924599,\"s\":\"BTCUSDT\",\"ps\":\"BTCUSDT\",\"b\":\"79366.00\",\"B\":\"7.003\",\"a\":\"79366.10\",\"A\":\"3.039\",\"T\":1788782259778,\"E\":1788782259778,\"st\":1}}"}
{"receive_ns":1788782259700834000,"stream":"btcusdt@bookTicker","event_type":"bookTicker","event_time_ms":1788782259780,"raw_json":"{\"stream\":\"btcusdt@bookTicker\",\"data\":{\"e\":\"bookTicker\",\"u\":11496347924686,\"s\":\"BTCUSDT\",\"ps\":\"BTCUSDT\",\"b\":\"79366.00\",\"B\":\"7.003\",\"a\":\"79366.10\",\"A\":\"3.087\",\"T\":1788782259779,\"E\":1788782259780,\"st\":1}}"}
{"receive_ns":1788782259701353000,"stream":"btcusdt@bookTicker","event_type":"bookTicker","event_time_ms":1788782259781,"raw_json":"{\"stream\":\"btcusdt@bookTicker\",\"data\":{\"e\":\"bookTicker\",\"u\":11496347924756,\"s\":\"BTCUSDT\",\"ps\":\"BTCUSDT\",\"b\":\"79366.00\",\"B\":\"7.003\",\"a\":\"79366.10\",\"A\":\"3.085\",\"T\":1788782259781,\"E\":1788782259781,\"st\":1}}"}
{"receive_ns":1788782259702179000,"stream":"btcusdt@bookTicker","event_type":"bookTicker","event_time_ms":1788782259787,"raw_json":"{\"stream\":\"btcusdt@bookTicker\",\"data\":{\"e\":\"bookTicker\",\"u\":11496347925096,\"s\":\"BTCUSDT\",\"ps\":\"BTCUSDT\",\"b\":\"79366.00\",\"B\":\"7.003\",\"a\":\"79366.10\",\"A\":\"3.086\",\"T\":1788782259786,\"E\":1788782259787,\"st\":1}}"}
{"receive_ns":1788782259703295000,"stream":"btcusdt@bookTicker","event_type":"bookTicker","event_time_ms":1788782259788,"raw_json":"{\"stream\":\"btcusdt@bookTicker\",\"data\":{\"e\":\"bookTicker\",\"u\":11496347925173,\"s\":\"BTCUSDT\",\"ps\":\"BTCUSDT\",\"b\":\"79366.00\",\"B\":\"7.003\",\"a\":\"79366.10\",\"A\":\"3.063\",\"T\":1788782259788,\"E\":1788782259788,\"st\":1}}"}
{"receive_ns":1788782259727549000,"stream":"btcusdt@depth@100ms","event_type":"depthUpdate","event_time_ms":1788782259812,"raw_json":"{\"stream\":\"btcusdt@depth@100ms\",\"data\":{\"e\":\"depthUpdate\",\"E\":1788782259812,\"T\":1788782259809,\"s\":\"BTCUSDT\",\"ps\":\"BTCUSDT\",\"U\":11496347920564,\"u\":11496347926293,\"pu\":11496347920508,\"b\":[[\"1000.00\",\"24.754\"],[\"29166.00\",\"1.561\"],[\"29266.00\",\"0.539\"],[\"71429.40\",\"0.048\"],[\"75397.70\",\"0.023\"],[\"75397.80\",\"0.010\"],[\"78413.80\",\"0.000\"],[\"78572.30\",\"12.650\"],[\"78969.20\",\"4.746\"],[\"79123.90\",\"3.220\"],[\"79124.70\",\"0.000\"],[\"79125.90\",\"0.478\"],[\"79143.60\",\"2.083\"],[\"79143.80\",\"0.001\"],[\"79145.80\",\"0.488\"],[\"79146.90\",\"0.010\"],[\"79181.80\",\"0.005\"],[\"79189.40\",\"1.460\"],[\"79189.60\",\"0.004\"],[\"79191.30\",\"0.018\"],[\"79220.60\",\"2.616\"],[\"79220.80\",\"0.076\"],[\"79274.00\",\"0.129\"],[\"79274.10\",\"0.008\"],[\"79335.80\",\"1.002\"],[\"79340.00\",\"0.450\"],[\"79342.00\",\"0.551\"],[\"79358.50\",\"0.086\"],[\"79358.80\",\"0.080\"],[\"79366.00\",\"7.003\"]],\"a\":[[\"79366.10\",\"3.063\"],[\"79367.20\",\"0.001\"],[\"79369.80\",\"0.001\"],[\"79380.00\",\"0.108\"],[\"79387.40\",\"0.001\"],[\"79387.60\",\"0.002\"],[\"79388.50\",\"0.443\"],[\"79405.40\",\"0.001\"],[\"79496.30\",\"0.036\"],[\"79559.20\",\"0.001\"],[\"79559.60\",\"0.127\"],[\"79578.90\",\"2.840\"],[\"79733.20\",\"0.836\"],[\"80159.80\",\"13.270\"],[\"80319.90\",\"0.696\"]],\"st\":1}}"}
{"receive_ns":1788782259825005000,"stream":"btcusdt@bookTicker","event_type":"bookTicker","event_time_ms":1788782259909,"raw_json":"{\"stream\":\"btcusdt@bookTicker\",\"data\":{\"e\":\"bookTicker\",\"u\":11496347931727,\"s\":\"BTCUSDT\",\"ps\":\"BTCUSDT\",\"b\":\"79366.00\",\"B\":\"7.003\",\"a\":\"79366.10\",\"A\":\"2.982\",\"T\":1788782259909,\"E\":1788782259909,\"st\":1}}"}
{"receive_ns":1788782259828847000,"stream":"btcusdt@depth@100ms","event_type":"depthUpdate","event_time_ms":1788782259914,"raw_json":"{\"stream\":\"btcusdt@depth@100ms\",\"data\":{\"e\":\"depthUpdate\",\"E\":1788782259914,\"T\":1788782259912,\"s\":\"BTCUSDT\",\"ps\":\"BTCUSDT\",\"U\":11496347926344,\"u\":11496347932027,\"pu\":11496347926293,\"b\":[[\"29166.00\",\"1.736\"],[\"29266.00\",\"0.364\"],[\"71429.40\",\"0.048\"],[\"76191.30\",\"0.002\"],[\"78572.30\",\"12.650\"],[\"78969.10\",\"0.001\"],[\"79116.10\",\"0.054\"],[\"79123.90\",\"3.220\"],[\"79124.10\",\"0.063\"],[\"79124.70\",\"0.010\"],[\"79125.90\",\"0.729\"],[\"79143.60\",\"0.001\"],[\"79143.80\",\"35.380\"],[\"79143.90\",\"0.571\"],[\"79145.80\",\"0.237\"],[\"79171.80\",\"3.719\"],[\"79189.40\",\"0.001\"],[\"79189.60\",\"26.523\"],[\"79189.70\",\"0.050\"],[\"79220.60\",\"1.890\"],[\"79220.80\",\"17.748\"],[\"79274.00\",\"0.000\"],[\"79274.10\",\"8.838\"],[\"79340.90\",\"0.453\"],[\"79342.00\",\"0.098\"]],\"a\":[[\"79366.10\",\"2.982\"],[\"79367.20\",\"0.001\"],[\"79370.00\",\"0.002\"],[\"79385.90\",\"1.797\"],[\"79388.50\",\"0.003\"],[\"79388.60\",\"0.868\"],[\"79559.20\",\"0.127\"],[\"79559.60\",\"0.001\"],[\"79706.90\",\"0.000\"],[\"79733.20\",\"0.836\"],[\"79733.30\",\"0.062\"],[\"79763.00\",\"0.001\"],[\"80159.80\",\"13.270\"]],\"st\":1}}"}
{"receive_ns":1788782259831345000,"stream":"btcusdt@bookTicker","event_type":"bookTicker","event_time_ms":1788782259918,"raw_json":"{\"stream\":\"btcusdt@bookTicker\",\"data\":{\"e\":\"bookTicker\",\"u\":11496347932458,\"s\":\"BTCUSDT\",\"ps\":\"BTCUSDT\",\"b\":\"79366.00\",\"B\":\"7.003\",\"a\":\"79366.10\",\"A\":\"3.064\",\"T\":1788782259917,\"E\":1788782259918,\"st\":1}}"}
{"receive_ns":1788782259831805000,"stream":"btcusdt@bookTicker","event_type":"bookTicker","event_time_ms":1788782259919,"raw_json":"{\"stream\":\"btcusdt@bookTicker\",\"data\":{\"e\":\"bookTicker\",\"u\":11496347932518,\"s\":\"BTCUSDT\",\"ps\":\"BTCUSDT\",\"b\":\"79366.00\",\"B\":\"7.003\",\"a\":\"79366.10\",\"A\":\"3.066\",\"T\":1788782259918,\"E\":1788782259919,\"st\":1}}"}
{"receive_ns":1788782259931038000,"stream":"btcusdt@depth@100ms","event_type":"depthUpdate","event_time_ms":1788782260016,"raw_json":"{\"stream\":\"btcusdt@depth@100ms\",\"data\":{\"e\":\"depthUpdate\",\"E\":1788782260016,\"T\":1788782260013,\"s\":\"BTCUSDT\",\"ps\":\"BTCUSDT\",\"U\":11496347932152,\"u\":11496347939598,\"pu\":11496347932027,\"b\":[[\"29066.00\",\"0.056\"],[\"29166.00\",\"1.806\"],[\"29266.00\",\"0.238\"],[\"71429.40\",\"0.048\"],[\"75397.80\",\"0.008\"],[\"76191.30\",\"0.000\"],[\"78572.30\",\"12.650\"],[\"78651.70\",\"7.870\"],[\"79124.70\",\"0.000\"],[\"79125.90\",\"0.252\"],[\"79145.80\",\"0.477\"],[\"79171.80\",\"3.701\"],[\"79189.70\",\"0.068\"]],\"a\":[[\"79366.10\",\"3.066\"],[\"79367.20\",\"0.001\"],[\"79370.10\",\"0.103\"],[\"79380.00\",\"0.023\"],[\"79559.20\",\"0.001\"],[\"79733.20\",\"0.773\"],[\"80159.80\",\"13.270\"],[\"80953.40\",\"0.003\"]],\"st\":1}}"}
{"receive_ns":1788782260033415000,"stream":"btcusdt@depth@100ms","event_type":"depthUpdate","event_time_ms":1788782260118,"raw_json":"{\"stream\":\"btcusdt@depth@100ms\",\"data\":{\"e\":\"depthUpdate\",\"E\":1788782260118,\"T\":1788782260117,\"s\":\"BTCUSDT\",\"ps\":\"BTCUSDT\",\"U\":11496347939879,\"u\":11496347945702,\"pu\":11496347939598,\"b\":[[\"1000.00\",\"24.754\"],[\"29066.00\",\"0.119\"],[\"29166.00\",\"1.862\"],[\"29266.00\",\"0.119\"],[\"71429.40\",\"0.048\"],[\"74948.90\",\"0.002\"],[\"75397.80\",\"0.006\"],[\"76191.30\",\"0.002\"],[\"78397.70\",\"0.643\"],[\"78434.00\",\"0.000\"],[\"78572.30\",\"12.650\"],[\"78969.20\",\"4.736\"],[\"79116.10\",\"0.000\"],[\"79123.90\",\"2.680\"],[\"79127.90\",\"0.019\"],[\"79143.90\",\"0.625\"],[\"79145.80\",\"0.714\"],[\"79220.80\",\"0.076\"],[\"79274.10\",\"0.008\"],[\"79293.50\",\"0.060\"],[\"79293.80\",\"0.108\"],[\"79339.90\",\"0.485\"],[\"79340.90\",\"0.000\"],[\"79344.90\",\"0.000\"],[\"79347.60\",\"0.754\"],[\"79350.30\",\"0.000\"]],\"a\":[[\"79367.20\",\"0.101\"],[\"79370.00\",\"0.078\"],[\"79370.10\",\"0.027\"],[\"79380.00\",\"0.108\"],[\"79380.40\",\"1.896\"],[\"79384.70\",\"0.006\"],[\"79385.80\",\"0.450\"],[\"79385.90\",\"1.357\"],[\"79388.50\",\"0.003\"],[\"79389.30\",\"0.001\"],[\"79390.40\",\"0.454\"],[\"79391.70\",\"0.001\"],[\"79420.60\",\"0.002\"],[\"79420.80\",\"0.090\"],[\"79456.20\",\"0.010\"],[\"79509.60\",\"0.000\"],[\"79559.10\",\"0.000\"],[\"79559.20\",\"0.001\"],[\"79604.20\",\"0.000\"],[\"79733.20\",\"0.525\"],[\"80159.80\",\"13.270\"],[\"80229.80\",\"0.000\"],[\"80231.20\",\"9.578\"],[\"80239.80\",\"0.003\"],[\"80244.30\",\"0.586\"]],\"st\":1}}"}
{"receive_ns":1788782260049536000,"stream":"btcusdt@bookTicker","event_type":"bookTicker","event_time_ms":1788782260134,"raw_json":"{\"stream\":\"btcusdt@bookTicker\",\"data\":{\"e\":\"bookTicker\",\"u\":11496347946711,\"s\":\"BTCUSDT\",\"ps\":\"BTCUSDT\",\"b\":\"79366.00\",\"B\":\"7.003\",\"a\":\"79366.10\",\"A\":\"2.984\",\"T\":1788782260134,\"E\":1788782260134,\"st\":1}}"}
{"receive_ns":1788782260053034000,"stream":"btcusdt@bookTicker","event_type":"bookTicker","event_time_ms":1788782260139,"raw_json":"{\"stream\":\"btcusdt@bookTicker\",\"data\":{\"e\":\"bookTicker\",\"u\":11496347946900,\"s\":\"BTCUSDT\",\"ps\":\"BTCUSDT\",\"b\":\"79366.00\",\"B\":\"7.003\",\"a\":\"79366.10\",\"A\":\"2.983\",\"T\":1788782260139,\"E\":1788782260139,\"st\":1}}"}
{"receive_ns":1788782260054794000,"stream":"btcusdt@bookTicker","event_type":"bookTicker","event_time_ms":1788782260141,"raw_json":"{\"stream\":\"btcusdt@bookTicker\",\"data\":{\"e\":\"bookTicker\",\"u\":11496347947003,\"s\":\"BTCUSDT\",\"ps\":\"BTCUSDT\",\"b\":\"79366.00\",\"B\":\"7.003\",\"a\":\"79366.10\",\"A\":\"2.984\",\"T\":1788782260141,\"E\":1788782260141,\"st\":1}}"}
{"receive_ns":1788782260056207000,"stream":"btcusdt@bookTicker","event_type":"bookTicker","event_time_ms":1788782260142,"raw_json":"{\"stream\":\"btcusdt@bookTicker\",\"data\":{\"e\":\"bookTicker\",\"u\":11496347947047,\"s\":\"BTCUSDT\",\"ps\":\"BTCUSDT\",\"b\":\"79366.00\",\"B\":\"7.003\",\"a\":\"79366.10\",\"A\":\"3.065\",\"T\":1788782260142,\"E\":1788782260142,\"st\":1}}"}
{"receive_ns":1788782260136972000,"stream":"btcusdt@depth@100ms","event_type":"depthUpdate","event_time_ms":1788782260220,"raw_json":"{\"stream\":\"btcusdt@depth@100ms\",\"data\":{\"e\":\"depthUpdate\",\"E\":1788782260220,\"T\":1788782260218,\"s\":\"BTCUSDT\",\"ps\":\"BTCUSDT\",\"U\":11496347945788,\"u\":11496347950716,\"pu\":11496347945702,\"b\":[[\"29066.00\",\"0.189\"],[\"29166.00\",\"1.897\"],[\"29266.00\",\"0.014\"],[\"71429.40\",\"0.048\"],[\"75397.80\",\"0.004\"],[\"78223.60\",\"0.639\"],[\"78352.60\",\"18.289\"],[\"78373.90\",\"11.070\"],[\"78427.70\",\"2.524\"],[\"78477.00\",\"1.422\"],[\"78572.30\",\"12.650\"],[\"79124.10\",\"0.000\"],[\"79125.90\",\"0.001\"],[\"79143.90\",\"0.688\"],[\"79145.80\",\"1.028\"],[\"79310.40\",\"0.010\"],[\"79339.90\",\"0.032\"],[\"79340.00\",\"0.903\"],[\"79342.00\",\"0.098\"],[\"79344.90\",\"0.002\"],[\"79347.60\",\"0.313\"],[\"79349.70\",\"0.441\"],[\"79350.90\",\"0.298\"]],\"a\":[[\"79366.10\",\"3.065\"],[\"79367.20\",\"0.001\"],[\"79370.00\",\"0.002\"],[\"79384.70\",\"0.008\"],[\"79385.80\",\"0.450\"],[\"79388.50\",\"0.003\"],[\"79390.40\",\"0.001\"],[\"79391.70\",\"0.454\"],[\"79421.70\",\"0.144\"],[\"79499.50\",\"0.068\"],[\"79508.10\",\"0.907\"],[\"79534.40\",\"0.033\"],[\"79559.20\",\"0.001\"],[\"79559.80\",\"0.000\"],[\"79559.90\",\"0.000\"],[\"79561.30\",\"0.126\"],[\"79733.20\",\"0.529\"],[\"79733.30\",\"0.028\"],[\"79735.30\",\"0.337\"],[\"80159.80\",\"13.270\"],[\"80318.50\",\"41.106\"],[\"80524.80\",\"0.619\"]],\"st\":1}}"}
{"receive_ns":1788782260184240000,"stream":"btcusdt@bookTicker","event_type":"bookTicker","event_time_ms":1788782260268,"raw_json":"{\"stream\":\"btcusdt@bookTicker\",\"data\":{\"e\":\"bookTicker\",\"u\":11496347952994,\"s\":\"BTCUSDT\",\"ps\":\"BTCUSDT\",\"b\":\"79366.00\",\"B\":\"7.009\",\"a\":\"79366.10\",\"A\":\"3.065\",\"T\":1788782260268,\"E\":1788782260268,\"st\":1}}"}
{"receive_ns":1788782260184630000,"stream":"btcusdt@bookTicker","event_type":"bookTicker","event_time_ms":1788782260269,"raw_json":"{\"stream\":\"btcusdt@bookTicker\",\"data\":{\"e\":\"bookTicker\",\"u\":11496347953076,\"s\":\"BTCUSDT\",\"ps\":\"BTCUSDT\",\"b\":\"79366.00\",\"B\":\"7.003\",\"a\":\"79366.10\",\"A\":\"3.065\",\"T\":1788782260269,\"E\":1788782260269,\"st\":1}}"}
{"receive_ns":1788782260237096000,"stream":"btcusdt@depth@100ms","event_type":"depthUpdate","event_time_ms":1788782260322,"raw_json":"{\"stream\":\"btcusdt@depth@100ms\",\"data\":{\"e\":\"depthUpdate\",\"E\":1788782260322,\"T\":1788782260321,\"s\":\"BTCUSDT\",\"ps\":\"BTCUSDT\",\"U\":11496347950845,\"u\":11496347955662,\"pu\":11496347950716,\"b\":[[\"29066.00\",\"0.350\"],[\"29166.00\",\"1.750\"],[\"29266.00\",\"0.000\"],[\"71429.40\",\"0.048\"],[\"76191.30\",\"0.000\"],[\"78254.90\",\"40.197\"],[\"78300.70\",\"2.037\"],[\"78370.40\",\"0.286\"],[\"78373.90\",\"11.223\"],[\"78572.30\",\"12.652\"],[\"79143.80\",\"0.001\"],[\"79143.90\",\"0.117\"],[\"79145.80\",\"1.065\"],[\"79171.80\",\"3.719\"],[\"79182.40\",\"0.785\"],[\"79189.60\",\"0.004\"],[\"79189.70\",\"0.050\"],[\"79283.60\",\"1.552\"],[\"79366.00\",\"7.003\"]],\"a\":[[\"79367.20\",\"0.001\"],[\"79380.00\",\"0.023\"],[\"79408.50\",\"1.462\"],[\"79492.00\",\"0.586\"],[\"79532.20\",\"0.755\"],[\"79535.10\",\"0.287\"],[\"79535.20\",\"1.195\"],[\"79543.90\",\"0.033\"],[\"79580.00\",\"3.773\"],[\"79581.00\",\"0.073\"],[\"79581.10\",\"0.001\"],[\"79733.20\",\"0.590\"],[\"80159.80\",\"13.270\"],[\"80318.50\",\"40.733\"],[\"80830.40\",\"0.000\"],[\"80953.40\",\"0.006\"]],\"st\":1}}"}
{"receive_ns":1788782260340882000,"stream":"btcusdt@depth@100ms","event_type":"depthUpdate","event_time_ms":1788782260424,"raw_json":"{\"stream\":\"btcusdt@depth@100ms\",\"data\":{\"e\":\"depthUpdate\",\"E\":1788782260424,\"T\":1788782260422,\"s\":\"BTCUSDT\",\"ps\":\"BTCUSDT\",\"U\":11496347955668,\"u\":11496347959892,\"pu\":11496347955662,\"b\":[[\"1000.00\",\"24.754\"],[\"29066.00\",\"0.532\"],[\"29166.00\",\"1.568\"],[\"63492.80\",\"0.000\"],[\"71429.40\",\"0.048\"],[\"76191.30\",\"0.002\"],[\"78572.30\",\"12.650\"],[\"78969.20\",\"4.736\"],[\"79123.90\",\"3.471\"],[\"79124.10\",\"0.063\"],[\"79124.70\",\"0.010\"],[\"79143.90\",\"0.054\"],[\"79145.80\",\"0.714\"],[\"79356.90\",\"0.002\"]],\"a\":[[\"79368.40\",\"0.001\"],[\"79369.60\",\"0.082\"],[\"79385.80\",\"0.010\"],[\"79385.90\",\"1.797\"],[\"79388.50\",\"0.003\"],[\"79547.10\",\"0.032\"],[\"79561.30\",\"0.000\"],[\"79574.20\",\"3.079\"],[\"79594.70\",\"0.025\"],[\"79733.20\",\"0.590\"],[\"79735.30\",\"0.303\"],[\"79755.10\",\"0.040\"],[\"79757.00\",\"0.246\"],[\"79961.30\",\"4.371\"],[\"80080.90\",\"1.746\"],[\"80159.80\",\"13.270\"],[\"80215.30\",\"1.430\"],[\"80494.00\",\"0.011\"]],\"st\":1}}"}
{"receive_ns":1788782260395241000,"stream":"btcusdt@bookTicker","event_type":"bookTicker","event_time_ms":1788782260459,"raw_json":"{\"stream\":\"btcusdt@bookTicker\",\"data\":{\"e\":\"bookTicker\",\"u\":11496347962039,\"s\":\"BTCUSDT\",\"ps\":\"BTCUSDT\",\"b\":\"79366.00\",\"B\":\"7.003\",\"a\":\"79366.10\",\"A\":\"3.037\",\"T\":1788782260459,\"E\":1788782260459,\"st\":1}}"}
{"receive_ns":1788782260395613000,"stream":"btcusdt@bookTicker","event_type":"bookTicker","event_time_ms":1788782260462,"raw_json":"{\"stream\":\"btcusdt@bookTicker\",\"data\":{\"e\":\"bookTicker\",\"u\":11496347962304,\"s\":\"BTCUSDT\",\"ps\":\"BTCUSDT\",\"b\":\"79366.00\",\"B\":\"7.003\",\"a\":\"79366.10\",\"A\":\"3.067\",\"T\":1788782260462,\"E\":1788782260462,\"st\":1}}"}
{"receive_ns":1788782260419112000,"stream":"btcusdt@bookTicker","event_type":"bookTicker","event_time_ms":1788782260504,"raw_json":"{\"stream\":\"btcusdt@bookTicker\",\"data\":{\"e\":\"bookTicker\",\"u\":11496347965061,\"s\":\"BTCUSDT\",\"ps\":\"BTCUSDT\",\"b\":\"79366.00\",\"B\":\"7.010\",\"a\":\"79366.10\",\"A\":\"3.067\",\"T\":1788782260504,\"E\":1788782260504,\"st\":1}}"}
{"receive_ns":1788782260440862000,"stream":"btcusdt@depth@100ms","event_type":"depthUpdate","event_time_ms":1788782260526,"raw_json":"{\"stream\":\"btcusdt@depth@100ms\",\"data\":{\"e\":\"depthUpdate\",\"E\":1788782260526,\"T\":1788782260525,\"s\":\"BTCUSDT\",\"ps\":\"BTCUSDT\",\"U\":11496347960241,\"u\":11496347966222,\"pu\":11496347959892,\"b\":[[\"29066.00\",\"0.707\"],[\"29166.00\",\"1.393\"],[\"71429.40\",\"0.048\"],[\"76191.30\",\"0.000\"],[\"78413.60\",\"39.616\"],[\"78572.30\",\"12.650\"],[\"79124.70\",\"0.000\"],[\"79143.80\",\"35.380\"],[\"79145.80\",\"0.477\"],[\"79189.60\",\"26.523\"],[\"79220.60\",\"1.890\"],[\"79220.80\",\"17.748\"],[\"79274.00\",\"0.000\"],[\"79274.20\",\"8.830\"],[\"79342.00\",\"1.068\"],[\"79347.60\",\"0.313\"],[\"79349.70\",\"0.000\"],[\"79350.30\",\"0.441\"],[\"79356.80\",\"0.280\"],[\"79366.00\",\"7.010\"]],\"a\":[[\"79366.10\",\"3.067\"],[\"79369.60\",\"0.006\"],[\"79369.90\",\"0.000\"],[\"79432.80\",\"0.037\"],[\"79456.20\",\"2.376\"],[\"79499.50\",\"0.032\"],[\"79509.60\",\"13.349\"],[\"79540.60\",\"5.049\"],[\"79540.70\",\"26.942\"],[\"79543.90\",\"0.001\"],[\"79547.10\",\"0.000\"],[\"79574.20\",\"3.079\"],[\"79581.00\",\"0.001\"],[\"79582.90\",\"0.095\"],[\"79584.00\",\"5.548\"],[\"79586.50\",\"0.055\"],[\"79586.60\",\"35.411\"],[\"79594.70\",\"0.000\"],[\"79733.20\",\"0.527\"],[\"80159.80\",\"13.270\"],[\"80398.20\",\"0.918\"],[\"80476.00\",\"0.495\"]],\"st\":1}}"}
{"receive_ns":1788782260530584000,"stream":"btcusdt@bookTicker","event_type":"bookTicker","event_time_ms":1788782260615,"raw_json":"{\"stream\":\"btcusdt@bookTicker\",\"data\":{\"e\":\"bookTicker\",\"u\":11496347971788,\"s\":\"BTCUSDT\",\"ps\":\"BTCUSDT\",\"b\":\"79366.00\",\"B\":\"7.010\",\"a\":\"79366.10\",\"A\":\"3.066\",\"T\":1788782260615,\"E\":1788782260615,\"st\":1}}"}
{"receive_ns":1788782260531182000,"stream":"btcusdt@bookTicker","event_type":"bookTicker","event_time_ms":1788782260617,"raw_json":"{\"stream\":\"btcusdt@bookTicker\",\"data\":{\"e\":\"bookTicker\",\"u\":11496347971921,\"s\":\"BTCUSDT\",\"ps\":\"BTCUSDT\",\"b\":\"79366.00\",\"B\":\"7.010\",\"a\":\"79366.10\",\"A\":\"3.067\",\"T\":1788782260617,\"E\":1788782260617,\"st\":1}}"}
{"receive_ns":1788782260533517000,"stream":"btcusdt@bookTicker","event_type":"bookTicker","event_time_ms":1788782260618,"raw_json":"{\"stream\":\"btcusdt@bookTicker\",\"data\":{\"e\":\"bookTicker\",\"u\":11496347972013,\"s\":\"BTCUSDT\",\"ps\":\"BTCUSDT\",\"b\":\"79366.00\",\"B\":\"7.010\",\"a\":\"79366.10\",\"A\":\"3.019\",\"T\":1788782260618,\"E\":1788782260618,\"st\":1}}"}
{"receive_ns":1788782260533796000,"stream":"btcusdt@bookTicker","event_type":"bookTicker","event_time_ms":1788782260618,"raw_json":"{\"stream\":\"btcusdt@bookTicker\",\"data\":{\"e\":\"bookTicker\",\"u\":11496347972014,\"s\":\"BTCUSDT\",\"ps\":\"BTCUSDT\",\"b\":\"79366.00\",\"B\":\"7.010\",\"a\":\"79366.10\",\"A\":\"2.966\",\"T\":1788782260618,\"E\":1788782260618,\"st\":1}}"}
{"receive_ns":1788782260533979000,"stream":"btcusdt@bookTicker","event_type":"bookTicker","event_time_ms":1788782260618,"raw_json":"{\"stream\":\"btcusdt@bookTicker\",\"data\":{\"e\":\"bookTicker\",\"u\":11496347972015,\"s\":\"BTCUSDT\",\"ps\":\"BTCUSDT\",\"b\":\"79366.00\",\"B\":\"7.010\",\"a\":\"79366.10\",\"A\":\"2.955\",\"T\":1788782260618,\"E\":1788782260618,\"st\":1}}"}
{"receive_ns":1788782260543109000,"stream":"btcusdt@depth@100ms","event_type":"depthUpdate","event_time_ms":1788782260628,"raw_json":"{\"stream\":\"btcusdt@depth@100ms\",\"data\":{\"e\":\"depthUpdate\",\"E\":1788782260628,\"T\":1788782260624,\"s\":\"BTCUSDT\",\"ps\":\"BTCUSDT\",\"U\":11496347966229,\"u\":11496347972645,\"pu\":11496347966222,\"b\":[[\"1000.00\",\"24.754\"],[\"29066.00\",\"0.882\"],[\"29166.00\",\"1.218\"],[\"63493.00\",\"0.012\"],[\"71429.40\",\"0.048\"],[\"76191.30\",\"0.002\"],[\"78334.10\",\"2.297\"],[\"78572.30\",\"12.650\"],[\"78955.00\",\"5.035\"],[\"79123.90\",\"2.680\"],[\"79124.10\",\"0.000\"],[\"79124.70\",\"0.000\"],[\"79143.60\",\"0.001\"],[\"79143.80\",\"35.380\"],[\"79145.80\",\"1.254\"],[\"79171.80\",\"3.701\"],[\"79189.50\",\"0.000\"],[\"79189.60\",\"26.523\"],[\"79189.70\",\"0.068\"],[\"79220.60\",\"1.890\"],[\"79220.80\",\"17.748\"],[\"79223.80\",\"1.476\"],[\"79274.00\",\"0.000\"],[\"79274.20\",\"8.830\"],[\"79294.50\",\"0.002\"],[\"79347.60\",\"0.754\"],[\"79350.10\",\"3.360\"],[\"79350.30\",\"0.000\"]],\"a\":[[\"79366.10\",\"2.955\"],[\"79431.60\",\"0.085\"],[\"79437.60\",\"0.016\"],[\"79540.60\",\"5.067\"],[\"79574.20\",\"5.123\"],[\"79582.90\",\"0.077\"],[\"79604.20\",\"0.002\"],[\"79733.20\",\"0.692\"],[\"79755.10\",\"0.006\"],[\"79757.00\",\"0.000\"],[\"80159.80\",\"13.270\"],[\"80255.20\",\"0.622\"],[\"80477.20\",\"36.660\"],[\"80575.50\",\"16.353\"]],\"st\":1}}"}
{"receive_ns":1788782260643990000,"stream":"btcusdt@depth@100ms","event_type":"depthUpdate","event_time_ms":1788782260730,"raw_json":"{\"stream\":\"btcusdt@depth@100ms\",\"data\":{\"e\":\"depthUpdate\",\"E\":1788782260730,\"T\":1788782260729,\"s\":\"BTCUSDT\",\"ps\":\"BTCUSDT\",\"U\":11496347972880,\"u\":11496347979463,\"pu\":11496347972645,\"b\":[[\"1000.00\",\"24.754\"],[\"29066.00\",\"1.071\"],[\"29166.00\",\"1.029\"],[\"63493.00\",\"0.012\"],[\"71429.40\",\"0.048\"],[\"74834.90\",\"0.002\"],[\"78016.80\",\"8.828\"],[\"78572.30\",\"12.650\"],[\"78691.40\",\"3.758\"],[\"78968.60\",\"0.000\"],[\"78968.70\",\"0.002\"],[\"78969.20\",\"4.746\"],[\"79123.90\",\"3.157\"],[\"79124.70\",\"0.015\"],[\"79143.60\",\"2.056\"],[\"79143.80\",\"0.001\"],[\"79143.90\",\"0.117\"],[\"79145.80\",\"1.028\"],[\"79189.50\",\"1.440\"],[\"79189.60\",\"0.004\"],[\"79220.60\",\"2.606\"],[\"79220.80\",\"0.076\"],[\"79274.00\",\"0.128\"],[\"79274.20\",\"0.000\"],[\"79284.30\",\"0.014\"],[\"79284.60\",\"0.000\"],[\"79284.70\",\"0.000\"],[\"79293.50\",\"0.060\"],[\"79293.80\",\"0.108\"],[\"79347.60\",\"0.313\"],[\"79347.70\",\"0.000\"],[\"79350.30\",\"0.441\"]],\"a\":[[\"79370.00\",\"0.078\"],[\"79385.90\",\"1.357\"],[\"79388.50\",\"0.443\"],[\"79391.00\",\"0.003\"],[\"79437.10\",\"0.001\"],[\"79447.90\",\"0.015\"],[\"79574.20\",\"3.079\"],[\"79733.20\",\"0.836\"],[\"79733.30\",\"0.062\"],[\"80040.70\",\"1.847\"],[\"80159.80\",\"13.270\"],[\"80334.30\",\"1.295\"],[\"80556.60\",\"3.985\"]],\"st\":1}}"}
{"receive_ns":1788782260666497000,"stream":"btcusdt@bookTicker","event_type":"bookTicker","event_time_ms":1788782260752,"raw_json":"{\"stream\":\"btcusdt@bookTicker\",\"data\":{\"e\":\"bookTicker\",\"u\":11496347980693,\"s\":\"BTCUSDT\",\"ps\":\"BTCUSDT\",\"b\":\"79366.00\",\"B\":\"7.010\",\"a\":\"79366.10\",\"A\":\"2.956\",\"T\":1788782260752,\"E\":1788782260752,\"st\":1}}"}
{"receive_ns":1788782260667130000,"stream":"btcusdt@bookTicker","event_type":"bookTicker","event_time_ms":1788782260753,"raw_json":"{\"stream\":\"btcusdt@bookTicker\",\"data\":{\"e\":\"bookTicker\",\"u\":11496347980779,\"s\":\"BTCUSDT\",\"ps\":\"BTCUSDT\",\"b\":\"79366.00\",\"B\":\"7.010\",\"a\":\"79366.10\",\"A\":\"2.955\",\"T\":1788782260753,\"E\":1788782260753,\"st\":1}}"}
{"receive_ns":1788782260703945000,"stream":"btcusdt@bookTicker","event_type":"bookTicker","event_time_ms":1788782260789,"raw_json":"{\"stream\":\"btcusdt@bookTicker\",\"data\":{\"e\":\"bookTicker\",\"u\":11496347982385,\"s\":\"BTCUSDT\",\"ps\":\"BTCUSDT\",\"b\":\"79366.00\",\"B\":\"7.003\",\"a\":\"79366.10\",\"A\":\"2.955\",\"T\":1788782260789,\"E\":1788782260789,\"st\":1}}"}
{"receive_ns":1788782260704470000,"stream":"btcusdt@trade","event_type":"trade","event_time_ms":1788782260789,"raw_json":"{\"stream\":\"btcusdt@trade\",\"data\":{\"e\":\"trade\",\"E\":1788782260789,\"T\":1788782260789,\"s\":\"BTCUSDT\",\"t\":8057739780,\"p\":\"79366.00\",\"q\":\"0.007\",\"X\":\"MARKET\",\"m\":true,\"st\":1}}"}
{"receive_ns":1788782260705037000,"stream":"btcusdt@bookTicker","event_type":"bookTicker","event_time_ms":1788782260791,"raw_json":"{\"stream\":\"btcusdt@bookTicker\",\"data\":{\"e\":\"bookTicker\",\"u\":11496347982499,\"s\":\"BTCUSDT\",\"ps\":\"BTCUSDT\",\"b\":\"79366.00\",\"B\":\"7.009\",\"a\":\"79366.10\",\"A\":\"2.955\",\"T\":1788782260791,\"E\":1788782260791,\"st\":1}}"}
{"receive_ns":1788782260705396000,"stream":"btcusdt@bookTicker","event_type":"bookTicker","event_time_ms":1788782260791,"raw_json":"{\"stream\":\"btcusdt@bookTicker\",\"data\":{\"e\":\"bookTicker\",\"u\":11496347982600,\"s\":\"BTCUSDT\",\"ps\":\"BTCUSDT\",\"b\":\"79366.00\",\"B\":\"7.003\",\"a\":\"79366.10\",\"A\":\"2.955\",\"T\":1788782260791,\"E\":1788782260791,\"st\":1}}"}
{"receive_ns":1788782260705760000,"stream":"btcusdt@bookTicker","event_type":"bookTicker","event_time_ms":1788782260792,"raw_json":"{\"stream\":\"btcusdt@bookTicker\",\"data\":{\"e\":\"bookTicker\",\"u\":11496347982603,\"s\":\"BTCUSDT\",\"ps\":\"BTCUSDT\",\"b\":\"79366.00\",\"B\":\"7.003\",\"a\":\"79366.10\",\"A\":\"3.067\",\"T\":1788782260791,\"E\":1788782260792,\"st\":1}}"}
{"receive_ns":1788782260723880000,"stream":"btcusdt@bookTicker","event_type":"bookTicker","event_time_ms":1788782260806,"raw_json":"{\"stream\":\"btcusdt@bookTicker\",\"data\":{\"e\":\"bookTicker\",\"u\":11496347983266,\"s\":\"BTCUSDT\",\"ps\":\"BTCUSDT\",\"b\":\"79366.00\",\"B\":\"7.003\",\"a\":\"79366.10\",\"A\":\"2.986\",\"T\":1788782260806,\"E\":1788782260806,\"st\":1}}"}
{"receive_ns":1788782260728903000,"stream":"btcusdt@bookTicker","event_type":"bookTicker","event_time_ms":1788782260814,"raw_json":"{\"stream\":\"btcusdt@bookTicker\",\"data\":{\"e\":\"bookTicker\",\"u\":11496347983882,\"s\":\"BTCUSDT\",\"ps\":\"BTCUSDT\",\"b\":\"79366.00\",\"B\":\"7.003\",\"a\":\"79366.10\",\"A\":\"3.068\",\"T\":1788782260813,\"E\":1788782260814,\"st\":1}}"}
{"receive_ns":1788782260741476000,"stream":"btcusdt@bookTicker","event_type":"bookTicker","event_time_ms":1788782260823,"raw_json":"{\"stream\":\"btcusdt@bookTicker\",\"data\":{\"e\":\"bookTicker\",\"u\":11496347984248,\"s\":\"BTCUSDT\",\"ps\":\"BTCUSDT\",\"b\":\"79366.00\",\"B\":\"7.003\",\"a\":\"79366.10\",\"A\":\"2.787\",\"T\":1788782260823,\"E\":1788782260823,\"st\":1}}"}
{"receive_ns":1788782260741860000,"stream":"btcusdt@bookTicker","event_type":"bookTicker","event_time_ms":1788782260824,"raw_json":"{\"stream\":\"btcusdt@bookTicker\",\"data\":{\"e\":\"bookTicker\",\"u\":11496347984250,\"s\":\"BTCUSDT\",\"ps\":\"BTCUSDT\",\"b\":\"79366.00\",\"B\":\"7.003\",\"a\":\"79366.10\",\"A\":\"2.731\",\"T\":1788782260823,\"E\":1788782260824,\"st\":1}}"}
{"receive_ns":1788782260742094000,"stream":"btcusdt@bookTicker","event_type":"bookTicker","event_time_ms":1788782260825,"raw_json":"{\"stream\":\"btcusdt@bookTicker\",\"data\":{\"e\":\"bookTicker\",\"u\":11496347984304,\"s\":\"BTCUSDT\",\"ps\":\"BTCUSDT\",\"b\":\"79366.00\",\"B\":\"7.003\",\"a\":\"79366.10\",\"A\":\"2.732\",\"T\":1788782260825,\"E\":1788782260825,\"st\":1}}"}
{"receive_ns":1788782260742271000,"stream":"btcusdt@bookTicker","event_type":"bookTicker","event_time_ms":1788782260825,"raw_json":"{\"stream\":\"btcusdt@bookTicker\",\"data\":{\"e\":\"bookTicker\",\"u\":11496347984305,\"s\":\"BTCUSDT\",\"ps\":\"BTCUSDT\",\"b\":\"79366.00\",\"B\":\"7.003\",\"a\":\"79366.10\",\"A\":\"2.731\",\"T\":1788782260825,\"E\":1788782260825,\"st\":1}}"}
{"receive_ns":1788782260742632000,"stream":"btcusdt@bookTicker","event_type":"bookTicker","event_time_ms":1788782260825,"raw_json":"{\"stream\":\"btcusdt@bookTicker\",\"data\":{\"e\":\"bookTicker\",\"u\":11496347984307,\"s\":\"BTCUSDT\",\"ps\":\"BTCUSDT\",\"b\":\"79366.00\",\"B\":\"7.009\",\"a\":\"79366.10\",\"A\":\"2.731\",\"T\":1788782260825,\"E\":1788782260825,\"st\":1}}"}
{"receive_ns":1788782260742920000,"stream":"btcusdt@bookTicker","event_type":"bookTicker","event_time_ms":1788782260826,"raw_json":"{\"stream\":\"btcusdt@bookTicker\",\"data\":{\"e\":\"bookTicker\",\"u\":11496347984361,\"s\":\"BTCUSDT\",\"ps\":\"BTCUSDT\",\"b\":\"79366.00\",\"B\":\"7.003\",\"a\":\"79366.10\",\"A\":\"2.731\",\"T\":1788782260826,\"E\":1788782260826,\"st\":1}}"}
{"receive_ns":1788782260748219000,"stream":"btcusdt@depth@100ms","event_type":"depthUpdate","event_time_ms":1788782260832,"raw_json":"{\"stream\":\"btcusdt@depth@100ms\",\"data\":{\"e\":\"depthUpdate\",\"E\":1788782260832,\"T\":1788782260830,\"s\":\"BTCUSDT\",\"ps\":\"BTCUSDT\",\"U\":11496347979540,\"u\":11496347984583,\"pu\":11496347979463,\"b\":[[\"29066.00\",\"1.246\"],[\"29166.00\",\"0.854\"],[\"71429.40\",\"0.048\"],[\"76191.30\",\"0.000\"],[\"77778.70\",\"1.460\"],[\"78175.50\",\"1.518\"],[\"78572.30\",\"12.650\"],[\"78651.70\",\"8.759\"],[\"78670.10\",\"10.724\"],[\"79123.90\",\"3.394\"],[\"79143.60\",\"2.056\"],[\"79143.80\",\"0.001\"],[\"79145.80\",\"0.251\"],[\"79171.80\",\"3.719\"],[\"79182.10\",\"3.150\"],[\"79182.30\",\"0.000\"],[\"79189.50\",\"1.440\"],[\"79189.60\",\"0.004\"],[\"79189.70\",\"0.050\"],[\"79220.60\",\"2.606\"],[\"79220.80\",\"0.076\"],[\"79274.00\",\"0.128\"],[\"79274.20\",\"0.000\"],[\"79279.40\",\"0.388\"],[\"79340.00\",\"0.450\"],[\"79341.10\",\"0.530\"],[\"79342.10\",\"0.003\"],[\"79366.00\",\"7.003\"]],\"a\":[[\"79366.10\",\"2.731\"],[\"79369.10\",\"0.084\"],[\"79369.50\",\"0.000\"],[\"79370.00\",\"0.002\"],[\"79385.90\",\"1.797\"],[\"79388.50\",\"0.003\"],[\"79392.70\",\"0.484\"],[\"79431.60\",\"0.085\"],[\"79438.20\",\"0.014\"],[\"79447.90\",\"0.001\"],[\"79454.10\",\"0.102\"],[\"79492.70\",\"1.890\"],[\"79492.90\",\"0.000\"],[\"79501.60\",\"3.627\"],[\"79733.20\",\"0.525\"],[\"80159.80\",\"13.270\"],[\"80329.30\",\"3.699\"]],\"st\":1}}"}
{"receive_ns":1788782260798601000,"stream":"btcusdt@bookTicker","event_type":"bookTicker","event_time_ms":1788782260884,"raw_json":"{\"stream\":\"btcusdt@bookTicker\",\"data\":{\"e\":\"bookTicker\",\"u\":11496347987414,\"s\":\"BTCUSDT\",\"ps\":\"BTCUSDT\",\"b\":\"79366.00\",\"B\":\"7.003\",\"a\":\"79366.10\",\"A\":\"2.716\",\"T\":1788782260884,\"E\":1788782260884,\"st\":1}}"}
{"receive_ns":1788782260798900000,"stream":"btcusdt@bookTicker","event_type":"bookTicker","event_time_ms":1788782260885,"raw_json":"{\"stream\":\"btcusdt@bookTicker\",\"data\":{\"e\":\"bookTicker\",\"u\":11496347987494,\"s\":\"BTCUSDT\",\"ps\":\"BTCUSDT\",\"b\":\"79366.00\",\"B\":\"7.003\",\"a\":\"79366.10\",\"A\":\"2.604\",\"T\":1788782260885,\"E\":1788782260885,\"st\":1}}"}
{"receive_ns":1788782260849555000,"stream":"btcusdt@depth@100ms","event_type":"depthUpdate","event_time_ms":1788782260934,"raw_json":"{\"stream\":\"btcusdt@depth@100ms\",\"data\":{\"e\":\"depthUpdate\",\"E\":1788782260934,\"T\":1788782260929,\"s\":\"BTCUSDT\",\"ps\":\"BTCUSDT\",\"U\":11496347984680,\"u\":11496347989481,\"pu\":11496347984583,\"b\":[[\"1000.00\",\"24.754\"],[\"29066.00\",\"1.421\"],[\"29166.00\",\"0.679\"],[\"63493.00\",\"0.012\"],[\"71429.40\",\"0.048\"],[\"76191.30\",\"0.002\"],[\"78572.30\",\"12.650\"],[\"78969.10\",\"0.000\"],[\"79116.10\",\"0.054\"],[\"79123.90\",\"3.934\"],[\"79124.10\",\"0.063\"],[\"79125.90\",\"0.252\"],[\"79143.90\",\"0.000\"],[\"79145.80\",\"0.000\"],[\"79334.10\",\"0.941\"]],\"a\":[[\"79366.10\",\"2.604\"],[\"79367.30\",\"0.741\"],[\"79369.10\",\"0.008\"],[\"79369.70\",\"0.076\"],[\"79371.40\",\"0.000\"],[\"79438.20\",\"0.000\"],[\"79446.70\",\"0.014\"],[\"79537.60\",\"0.064\"],[\"79559.90\",\"0.000\"],[\"79560.00\",\"0.574\"],[\"79706.90\",\"0.031\"],[\"79733.20\",\"0.836\"],[\"79733.30\",\"0.062\"],[\"79763.00\",\"0.000\"],[\"79947.10\",\"0.094\"],[\"80159.80\",\"13.270\"],[\"80494.90\",\"0.149\"]],\"st\":1}}"}
{"receive_ns":1788782260969878000,"stream":"btcusdt@bookTicker","event_type":"bookTicker","event_time_ms":1788782261022,"raw_json":"{\"stream\":\"btcusdt@bookTicker\",\"data\":{\"e\":\"bookTicker\",\"u\":11496347997406,\"s\":\"BTCUSDT\",\"ps\":\"BTCUSDT\",\"b\":\"79366.00\",\"B\":\"7.003\",\"a\":\"79366.10\",\"A\":\"2.618\",\"T\":1788782261022,\"E\":1788782261022,\"st\":1}}"}
{"receive_ns":1788782260970198000,"stream":"btcusdt@bookTicker","event_type":"bookTicker","event_time_ms":1788782261023,"raw_json":"{\"stream\":\"btcusdt@bookTicker\",\"data\":{\"e\":\"bookTicker\",\"u\":11496347997509,\"s\":\"BTCUSDT\",\"ps\":\"BTCUSDT\",\"b\":\"79366.00\",\"B\":\"7.003\",\"a\":\"79366.10\",\"A\":\"2.604\",\"T\":1788782261023,\"E\":1788782261023,\"st\":1}}"}
{"receive_ns":1788782260970705000,"stream":"btcusdt@depth@100ms","event_type":"depthUpdate","event_time_ms":1788782261036,"raw_json":"{\"stream\":\"btcusdt@depth@100ms\",\"data\":{\"e\":\"depthUpdate\",\"E\":1788782261036,\"T\":1788782261034,\"s\":\"BTCUSDT\",\"ps\":\"BTCUSDT\",\"U\":11496347989625,\"u\":11496347998297,\"pu\":11496347989481,\"b\":[[\"1000.00\",\"24.754\"],[\"29066.00\",\"1.603\"],[\"29166.00\",\"0.497\"],[\"63493.00\",\"0.012\"],[\"71429.40\",\"0.048\"],[\"75397.70\",\"0.021\"],[\"75397.80\",\"0.006\"],[\"76191.30\",\"0.000\"],[\"78572.30\",\"12.650\"],[\"78969.10\",\"0.001\"],[\"78969.20\",\"4.736\"],[\"79123.90\",\"3.257\"],[\"79124.70\",\"0.000\"],[\"79125.90\",\"0.692\"],[\"79143.60\",\"2.055\"],[\"79143.80\",\"0.001\"],[\"79145.80\",\"0.237\"],[\"79157.10\",\"4.910\"],[\"79189.50\",\"1.440\"],[\"79189.60\",\"0.004\"],[\"79220.60\",\"2.606\"],[\"79220.80\",\"0.076\"],[\"79274.00\",\"0.128\"],[\"79274.20\",\"0.000\"],[\"79347.60\",\"0.313\"],[\"79350.30\",\"0.441\"],[\"79364.20\",\"0.002\"]],\"a\":[[\"79366.10\",\"2.604\"],[\"79369.30\",\"0.002\"],[\"79369.70\",\"0.000\"],[\"79371.40\",\"0.002\"],[\"79375.10\",\"0.497\"],[\"79380.40\",\"1.900\"],[\"79385.50\",\"0.006\"],[\"79399.90\",\"1.424\"],[\"79431.60\",\"0.085\"],[\"79559.80\",\"0.000\"],[\"79706.90\",\"0.000\"],[\"79733.20\",\"0.836\"],[\"79763.00\",\"0.001\"],[\"80159.80\",\"13.270\"]],\"st\":1}}"}
{"receive_ns":1788782260971075000,"stream":"btcusdt@bookTicker","event_type":"bookTicker","event_time_ms":1788782261036,"raw_json":"{\"stream\":\"btcusdt@bookTicker\",\"data\":{\"e\":\"bookTicker\",\"u\":11496347998396,\"s\":\"BTCUSDT\",\"ps\":\"BTCUSDT\",\"b\":\"79366.00\",\"B\":\"7.003\",\"a\":\"79366.10\",\"A\":\"2.603\",\"T\":1788782261035,\"E\":1788782261036,\"st\":1}}"}
{"receive_ns":1788782260971296000,"stream":"btcusdt@bookTicker","event_type":"bookTicker","event_time_ms":1788782261038,"raw_json":"{\"stream\":\"btcusdt@bookTicker\",\"data\":{\"e\":\"bookTicker\",\"u\":11496347998566,\"s\":\"BTCUSDT\",\"ps\":\"BTCUSDT\",\"b\":\"79366.00\",\"B\":\"7.003\",\"a\":\"79366.10\",\"A\":\"2.604\",\"T\":1788782261038,\"E\":1788782261038,\"st\":1}}"}
{"receive_ns":1788782260971520000,"stream":"btcusdt@bookTicker","event_type":"bookTicker","event_time_ms":1788782261041,"raw_json":"{\"stream\":\"btcusdt@bookTicker\",\"data\":{\"e\":\"bookTicker\",\"u\":11496347998758,\"s\":\"BTCUSDT\",\"ps\":\"BTCUSDT\",\"b\":\"79366.00\",\"B\":\"7.003\",\"a\":\"79366.10\",\"A\":\"2.522\",\"T\":1788782261041,\"E\":1788782261041,\"st\":1}}"}
{"receive_ns":1788782260971736000,"stream":"btcusdt@bookTicker","event_type":"bookTicker","event_time_ms":1788782261042,"raw_json":"{\"stream\":\"btcusdt@bookTicker\",\"data\":{\"e\":\"bookTicker\",\"u\":11496347998836,\"s\":\"BTCUSDT\",\"ps\":\"BTCUSDT\",\"b\":\"79366.00\",\"B\":\"7.003\",\"a\":\"79366.10\",\"A\":\"2.603\",\"T\":1788782261042,\"E\":1788782261042,\"st\":1}}"}
{"receive_ns":1788782260971971000,"stream":"btcusdt@bookTicker","event_type":"bookTicker","event_time_ms":1788782261043,"raw_json":"{\"stream\":\"btcusdt@bookTicker\",\"data\":{\"e\":\"bookTicker\",\"u\":11496347998882,\"s\":\"BTCUSDT\",\"ps\":\"BTCUSDT\",\"b\":\"79366.00\",\"B\":\"7.003\",\"a\":\"79366.10\",\"A\":\"2.601\",\"T\":1788782261043,\"E\":1788782261043,\"st\":1}}"}
{"receive_ns":1788782260972184000,"stream":"btcusdt@bookTicker","event_type":"bookTicker","event_time_ms":1788782261056,"raw_json":"{\"stream\":\"btcusdt@bookTicker\",\"data\":{\"e\":\"bookTicker\",\"u\":11496347999645,\"s\":\"BTCUSDT\",\"ps\":\"BTCUSDT\",\"b\":\"79366.00\",\"B\":\"7.003\",\"a\":\"79366.10\",\"A\":\"2.596\",\"T\":1788782261056,\"E\":1788782261056,\"st\":1}}"}
{"receive_ns":1788782260972381000,"stream":"btcusdt@trade","event_type":"trade","event_time_ms":1788782261056,"raw_json":"{\"stream\":\"btcusdt@trade\",\"data\":{\"e\":\"trade\",\"E\":1788782261056,\"T\":1788782261056,\"s\":\"BTCUSDT\",\"t\":8057739781,\"p\":\"79366.10\",\"q\":\"0.005\",\"X\":\"MARKET\",\"m\":false,\"st\":1}}"}
{"receive_ns":1788782260972605000,"stream":"btcusdt@bookTicker","event_type":"bookTicker","event_time_ms":1788782261057,"raw_json":"{\"stream\":\"btcusdt@bookTicker\",\"data\":{\"e\":\"bookTicker\",\"u\":11496347999766,\"s\":\"BTCUSDT\",\"ps\":\"BTCUSDT\",\"b\":\"79366.00\",\"B\":\"7.009\",\"a\":\"79366.10\",\"A\":\"2.596\",\"T\":1788782261057,\"E\":1788782261057,\"st\":1}}"}
{"receive_ns":1788782260973171000,"stream":"btcusdt@bookTicker","event_type":"bookTicker","event_time_ms":1788782261058,"raw_json":"{\"stream\":\"btcusdt@bookTicker\",\"data\":{\"e\":\"bookTicker\",\"u\":11496347999866,\"s\":\"BTCUSDT\",\"ps\":\"BTCUSDT\",\"b\":\"79366.00\",\"B\":\"7.003\",\"a\":\"79366.10\",\"A\":\"2.596\",\"T\":1788782261058,\"E\":1788782261058,\"st\":1}}"}
{"receive_ns":1788782261052657000,"stream":"btcusdt@depth@100ms","event_type":"depthUpdate","event_time_ms":1788782261138,"raw_json":"{\"stream\":\"btcusdt@depth@100ms\",\"data\":{\"e\":\"depthUpdate\",\"E\":1788782261138,\"T\":1788782261137,\"s\":\"BTCUSDT\",\"ps\":\"BTCUSDT\",\"U\":11496347998396,\"u\":11496348005922,\"pu\":11496347998297,\"b\":[[\"28966.00\",\"0.007\"],[\"29066.00\",\"1.764\"],[\"29166.00\",\"0.329\"],[\"71429.40\",\"0.048\"],[\"76191.30\",\"0.002\"],[\"77431.90\",\"0.000\"],[\"78175.50\",\"1.805\"],[\"78397.80\",\"16.960\"],[\"78572.30\",\"12.650\"],[\"78651.60\",\"0.889\"],[\"78823.50\",\"0.522\"],[\"78997.30\",\"0.000\"],[\"78999.80\",\"0.121\"],[\"79104.10\",\"0.541\"],[\"79112.00\",\"0.013\"],[\"79116.00\",\"1.196\"],[\"79116.10\",\"0.000\"],[\"79119.00\",\"0.816\"],[\"79123.90\",\"2.717\"],[\"79124.10\",\"0.000\"],[\"79124.70\",\"0.000\"],[\"79125.90\",\"0.441\"],[\"79143.60\",\"0.001\"],[\"79143.80\",\"35.380\"],[\"79143.90\",\"0.054\"],[\"79189.50\",\"0.000\"],[\"79189.60\",\"26.523\"],[\"79220.60\",\"1.890\"],[\"79220.80\",\"17.748\"],[\"79274.00\",\"0.000\"],[\"79274.20\",\"8.830\"],[\"79284.30\",\"0.000\"],[\"79294.60\",\"0.057\"],[\"79308.60\",\"1.315\"],[\"79340.30\",\"0.453\"],[\"79341.10\",\"0.077\"],[\"79347.60\",\"0.313\"],[\"79350.30\",\"0.441\"],[\"79359.00\",\"0.048\"],[\"79366.00\",\"7.003\"]],\"a\":[[\"79366.10\",\"2.596\"],[\"79371.20\",\"0.004\"],[\"79371.40\",\"0.002\"],[\"79375.10\",\"0.501\"],[\"79380.40\",\"1.896\"],[\"79380.90\",\"0.080\"],[\"79385.50\",\"0.002\"],[\"79389.60\",\"0.571\"],[\"79390.60\",\"0.453\"],[\"79391.70\",\"0.001\"],[\"79391.90\",\"2.291\"],[\"79560.10\",\"0.126\"],[\"79560.50\",\"0.000\"],[\"79574.20\",\"5.123\"],[\"79616.40\",\"0.984\"],[\"79616.50\",\"0.000\"],[\"79733.20\",\"0.381\"],[\"79733.30\",\"0.028\"],[\"79733.80\",\"0.405\"],[\"79735.90\",\"0.260\"],[\"79757.00\",\"0.246\"],[\"79911.30\",\"0.000\"],[\"80159.80\",\"13.270\"],[\"80605.50\",\"0.000\"]],\"st\":1}}"}
{"receive_ns":1788782261155051000,"stream":"btcusdt@depth@100ms","event_type":"depthUpdate","event_time_ms":1788782261240,"raw_json":"{\"stream\":\"btcusdt@depth@100ms\",\"data\":{\"e\":\"depthUpdate\",\"E\":1788782261240,\"T\":1788782261238,\"s\":\"BTCUSDT\",\"ps\":\"BTCUSDT\",\"U\":11496348005931,\"u\":11496348014599,\"pu\":11496348005922,\"b\":[[\"1000.00\",\"24.754\"],[\"28966.00\",\"0.070\"],[\"29066.00\",\"1.820\"],[\"29166.00\",\"0.210\"],[\"71429.40\",\"0.048\"],[\"75397.70\",\"0.019\"],[\"75397.80\",\"0.008\"],[\"78016.80\",\"9.340\"],[\"78237.20\",\"5.653\"],[\"78352.70\",\"0.000\"],[\"78493.00\",\"9.732\"],[\"78572.30\",\"12.650\"],[\"78610.70\",\"0.001\"],[\"79104.10\",\"1.269\"],[\"79104.30\",\"0.063\"],[\"79123.90\",\"2.680\"],[\"79125.90\",\"0.001\"],[\"79344.90\",\"0.002\"]],\"a\":[[\"79384.70\",\"0.008\"],[\"79559.80\",\"0.000\"],[\"79560.00\",\"0.574\"],[\"79560.10\",\"0.000\"],[\"79733.20\",\"0.074\"],[\"79755.00\",\"0.292\"],[\"79755.10\",\"0.040\"],[\"79757.00\",\"0.475\"],[\"80159.80\",\"13.345\"],[\"80318.50\",\"43.469\"],[\"80348.70\",\"0.631\"],[\"80453.40\",\"1.490\"]],\"st\":1}}"}
{"receive_ns":1788782261219315000,"stream":"btcusdt@bookTicker","event_type":"bookTicker","event_time_ms":1788782261306,"raw_json":"{\"stream\":\"btcusdt@bookTicker\",\"data\":{\"e\":\"bookTicker\",\"u\":11496348019874,\"s\":\"BTCUSDT\",\"ps\":\"BTCUSDT\",\"b\":\"79366.00\",\"B\":\"7.003\",\"a\":\"79366.10\",\"A\":\"2.585\",\"T\":1788782261306,\"E\":1788782261306,\"st\":1}}"}
{"receive_ns":1788782261222295000,"stream":"btcusdt@bookTicker","event_type":"bookTicker","event_time_ms":1788782261308,"raw_json":"{\"stream\":\"btcusdt@bookTicker\",\"data\":{\"e\":\"bookTicker\",\"u\":11496348020231,\"s\":\"BTCUSDT\",\"ps\":\"BTCUSDT\",\"b\":\"79366.00\",\"B\":\"7.003\",\"a\":\"79366.10\",\"A\":\"2.598\",\"T\":1788782261308,\"E\":1788782261308,\"st\":1}}"}
{"receive_ns":1788782261224944000,"stream":"btcusdt@bookTicker","event_type":"bookTicker","event_time_ms":1788782261310,"raw_json":"{\"stream\":\"btcusdt@bookTicker\",\"data\":{\"e\":\"bookTicker\",\"u\":11496348020355,\"s\":\"BTCUSDT\",\"ps\":\"BTCUSDT\",\"b\":\"79366.00\",\"B\":\"7.003\",\"a\":\"79366.10\",\"A\":\"2.600\",\"T\":1788782261309,\"E\":1788782261310,\"st\":1}}"}
{"receive_ns":1788782261257405000,"stream":"btcusdt@depth@100ms","event_type":"depthUpdate","event_time_ms":1788782261342,"raw_json":"{\"stream\":\"btcusdt@depth@100ms\",\"data\":{\"e\":\"depthUpdate\",\"E\":1788782261342,\"T\":1788782261341,\"s\":\"BTCUSDT\",\"ps\":\"BTCUSDT\",\"U\":11496348014759,\"u\":11496348022287,\"pu\":11496348014599,\"b\":[[\"1000.00\",\"24.754\"],[\"28966.00\",\"0.133\"],[\"29066.00\",\"1.876\"],[\"29166.00\",\"0.091\"],[\"71429.40\",\"0.048\"],[\"76191.30\",\"0.000\"],[\"77778.70\",\"1.463\"],[\"78572.30\",\"12.650\"],[\"78826.00\",\"56.518\"],[\"78827.90\",\"8.723\"],[\"78969.20\",\"4.736\"],[\"78999.80\",\"44.945\"],[\"78999.90\",\"6.855\"],[\"79104.10\",\"1.506\"],[\"79108.00\",\"0.574\"],[\"79118.50\",\"35.219\"],[\"79143.90\",\"5.581\"],[\"79145.80\",\"0.000\"],[\"79171.80\",\"3.701\"],[\"79189.70\",\"0.068\"],[\"79190.30\",\"4.755\"],[\"79236.70\",\"0.000\"],[\"79275.60\",\"2.134\"],[\"79300.30\",\"1.202\"],[\"79308.60\",\"1.301\"],[\"79347.60\",\"0.313\"],[\"79350.30\",\"0.441\"],[\"79355.80\",\"0.138\"]],\"a\":[[\"79366.10\",\"2.600\"],[\"79370.80\",\"0.000\"],[\"79371.00\",\"0.197\"],[\"79404.30\",\"0.009\"],[\"79407.50\",\"8.848\"],[\"79424.00\",\"1.236\"],[\"79431.60\",\"0.000\"],[\"79437.90\",\"0.022\"],[\"79446.70\",\"0.000\"],[\"79496.30\",\"0.000\"],[\"79508.10\",\"2.765\"],[\"79531.20\",\"0.032\"],[\"79534.40\",\"0.001\"],[\"79537.60\",\"0.032\"],[\"79559.90\",\"0.000\"],[\"79560.20\",\"0.000\"],[\"79574.20\",\"3.079\"],[\"79617.50\",\"36.542\"],[\"79733.20\",\"0.011\"],[\"79736.60\",\"9.028\"],[\"79737.00\",\"47.324\"],[\"79757.00\",\"0.623\"],[\"79912.40\",\"57.158\"],[\"80001.00\",\"8.638\"],[\"80127.10\",\"0.498\"],[\"80159.80\",\"13.345\"],[\"80358.20\",\"8.291\"],[\"80391.60\",\"0.003\"],[\"80413.80\",\"1.246\"],[\"80430.90\",\"0.000\"]],\"st\":1}}"}
{"receive_ns":1788782261302130000,"stream":"btcusdt@bookTicker","event_type":"bookTicker","event_time_ms":1788782261387,"raw_json":"{\"stream\":\"btcusdt@bookTicker\",\"data\":{\"e\":\"bookTicker\",\"u\":11496348024225,\"s\":\"BTCUSDT\",\"ps\":\"BTCUSDT\",\"b\":\"79366.00\",\"B\":\"7.000\",\"a\":\"79366.10\",\"A\":\"2.600\",\"T\":1788782261387,\"E\":1788782261387,\"st\":1}}"}
{"receive_ns":1788782261303148000,"stream":"btcusdt@bookTicker","event_type":"bookTicker","event_time_ms":1788782261390,"raw_json":"{\"stream\":\"btcusdt@bookTicker\",\"data\":{\"e\":\"bookTicker\",\"u\":11496348024372,\"s\":\"BTCUSDT\",\"ps\":\"BTCUSDT\",\"b\":\"79366.00\",\"B\":\"7.002\",\"a\":\"79366.10\",\"A\":\"2.600\",\"T\":1788782261389,\"E\":1788782261390,\"st\":1}}"}
{"receive_ns":1788782261360412000,"stream":"btcusdt@depth@100ms","event_type":"depthUpdate","event_time_ms":1788782261444,"raw_json":"{\"stream\":\"btcusdt@depth@100ms\",\"data\":{\"e\":\"depthUpdate\",\"E\":1788782261444,\"T\":1788782261441,\"s\":\"BTCUSDT\",\"ps\":\"BTCUSDT\",\"U\":11496348022316,\"u\":11496348027617,\"pu\":11496348022287,\"b\":[[\"28966.00\",\"0.217\"],[\"29066.00\",\"1.883\"],[\"29166.00\",\"0.000\"],[\"63492.80\",\"0.000\"],[\"71429.40\",\"0.048\"],[\"76191.30\",\"0.002\"],[\"78353.80\",\"87.499\"],[\"78373.90\",\"11.414\"],[\"78507.10\",\"0.002\"],[\"78572.30\",\"12.650\"],[\"78613.20\",\"68.052\"],[\"78651.60\",\"1.778\"],[\"78823.60\",\"0.000\"],[\"78826.10\",\"3.246\"],[\"79104.10\",\"0.238\"],[\"79104.30\",\"0.000\"],[\"79123.90\",\"2.931\"],[\"79124.10\",\"0.063\"],[\"79124.70\",\"0.015\"],[\"79143.60\",\"2.081\"],[\"79143.80\",\"0.001\"],[\"79143.90\",\"0.054\"],[\"79145.80\",\"0.100\"],[\"79171.80\",\"3.719\"],[\"79189.50\",\"1.458\"],[\"79189.60\",\"0.004\"],[\"79189.70\",\"0.050\"],[\"79190.30\",\"0.902\"],[\"79220.60\",\"2.615\"],[\"79220.80\",\"0.076\"],[\"79244.00\",\"1.651\"],[\"79274.00\",\"0.129\"],[\"79274.20\",\"0.000\"],[\"79275.60\",\"0.914\"],[\"79300.50\",\"0.473\"],[\"79366.00\",\"7.002\"]],\"a\":[[\"79370.70\",\"0.000\"],[\"79370.90\",\"0.002\"],[\"79371.00\",\"0.121\"],[\"79371.10\",\"0.001\"],[\"79462.40\",\"0.651\"],[\"79487.30\",\"0.451\"],[\"79560.10\",\"0.000\"],[\"79560.40\",\"0.001\"],[\"79735.20\",\"0.488\"],[\"79735.30\",\"0.337\"],[\"79735.80\",\"0.000\"],[\"79736.90\",\"0.648\"],[\"79755.00\",\"0.005\"],[\"79755.10\",\"0.006\"],[\"79757.00\",\"0.148\"],[\"79911.20\",\"0.000\"],[\"79912.30\",\"3.240\"],[\"80080.70\",\"0.191\"],[\"80159.80\",\"13.345\"],[\"80350.60\",\"0.621\"],[\"80744.10\",\"0.000\"],[\"82298.60\",\"0.100\"]],\"st\":1}}"}
{"receive_ns":1788782261416406000,"stream":"btcusdt@bookTicker","event_type":"bookTicker","event_time_ms":1788782261501,"raw_json":"{\"stream\":\"btcusdt@bookTicker\",\"data\":{\"e\":\"bookTicker\",\"u\":11496348033806,\"s\":\"BTCUSDT\",\"ps\":\"BTCUSDT\",\"b\":\"79366.00\",\"B\":\"7.002\",\"a\":\"79366.10\",\"A\":\"2.599\",\"T\":1788782261501,\"E\":1788782261501,\"st\":1}}"}
{"receive_ns":1788782261416994000,"stream":"btcusdt@bookTicker","event_type":"bookTicker","event_time_ms":1788782261503,"raw_json":"{\"stream\":\"btcusdt@bookTicker\",\"data\":{\"e\":\"bookTicker\",\"u\":11496348034117,\"s\":\"BTCUSDT\",\"ps\":\"BTCUSDT\",\"b\":\"79366.00\",\"B\":\"7.002\",\"a\":\"79366.10\",\"A\":\"2.600\",\"T\":1788782261503,\"E\":1788782261503,\"st\":1}}"}
{"receive_ns":1788782261424488000,"stream":"btcusdt@bookTicker","event_type":"bookTicker","event_time_ms":1788782261510,"raw_json":"{\"stream\":\"btcusdt@bookTicker\",\"data\":{\"e\":\"bookTicker\",\"u\":11496348034949,\"s\":\"BTCUSDT\",\"ps\":\"BTCUSDT\",\"b\":\"79366.00\",\"B\":\"7.002\",\"a\":\"79366.10\",\"A\":\"2.580\",\"T\":1788782261509,\"E\":1788782261510,\"st\":1}}"}
{"receive_ns":1788782261426138000,"stream":"btcusdt@bookTicker","event_type":"bookTicker","event_time_ms":1788782261512,"raw_json":"{\"stream\":\"btcusdt@bookTicker\",\"data\":{\"e\":\"bookTicker\",\"u\":11496348035158,\"s\":\"BTCUSDT\",\"ps\":\"BTCUSDT\",\"b\":\"79366.00\",\"B\":\"7.002\",\"a\":\"79366.10\",\"A\":\"2.604\",\"T\":1788782261512,\"E\":1788782261512,\"st\":1}}"}
{"receive_ns":1788782261459901000,"stream":"btcusdt@depth@100ms","event_type":"depthUpdate","event_time_ms":1788782261546,"raw_json":"{\"stream\":\"btcusdt@depth@100ms\",\"data\":{\"e\":\"depthUpdate\",\"E\":1788782261546,\"T\":1788782261542,\"s\":\"BTCUSDT\",\"ps\":\"BTCUSDT\",\"U\":11496348027812,\"u\":11496348037496,\"pu\":11496348027617,\"b\":[[\"1000.00\",\"24.754\"],[\"28966.00\",\"0.392\"],[\"29066.00\",\"1.708\"],[\"71429.40\",\"0.048\"],[\"76191.30\",\"0.000\"],[\"77932.30\",\"0.000\"],[\"78334.20\",\"4.582\"],[\"78397.70\",\"1.280\"],[\"78572.30\",\"12.650\"],[\"79104.10\",\"0.001\"],[\"79108.00\",\"0.428\"],[\"79123.90\",\"3.408\"],[\"79125.90\",\"0.238\"],[\"79294.50\",\"0.000\"],[\"79310.40\",\"0.008\"],[\"79326.30\",\"0.321\"],[\"79342.10\",\"0.001\"]],\"a\":[[\"79366.10\",\"2.604\"],[\"79370.70\",\"0.000\"],[\"79390.00\",\"0.004\"],[\"79392.50\",\"1.223\"],[\"79405.80\",\"0.032\"],[\"79421.70\",\"0.142\"],[\"79429.60\",\"0.249\"],[\"79437.60\",\"0.014\"],[\"79559.90\",\"0.000\"],[\"79574.20\",\"5.123\"],[\"79735.20\",\"0.943\"],[\"79757.00\",\"0.000\"],[\"80159.80\",\"13.345\"]],\"st\":1}}"}
{"receive_ns":1788782261563506000,"stream":"btcusdt@depth@100ms","event_type":"depthUpdate","event_time_ms":1788782261648,"raw_json":"{\"stream\":\"btcusdt@depth@100ms\",\"data\":{\"e\":\"depthUpdate\",\"E\":1788782261648,\"T\":1788782261646,\"s\":\"BTCUSDT\",\"ps\":\"BTCUSDT\",\"U\":11496348037771,\"u\":11496348044476,\"pu\":11496348037496,\"b\":[[\"1000.00\",\"24.754\"],[\"28966.00\",\"0.574\"],[\"29066.00\",\"1.526\"],[\"63493.00\",\"0.012\"],[\"71429.40\",\"0.050\"],[\"78511.40\",\"3.828\"],[\"78572.30\",\"12.650\"],[\"78969.20\",\"4.746\"],[\"79123.90\",\"3.697\"],[\"79124.10\",\"0.000\"],[\"79124.70\",\"0.015\"],[\"79143.60\",\"0.001\"],[\"79143.70\",\"0.000\"],[\"79143.80\",\"35.380\"],[\"79145.80\",\"0.000\"],[\"79157.10\",\"4.901\"],[\"79189.50\",\"0.000\"],[\"79189.70\",\"26.569\"],[\"79220.60\",\"1.890\"],[\"79220.80\",\"17.748\"],[\"79274.00\",\"0.000\"],[\"79274.20\",\"8.830\"],[\"79300.30\",\"1.188\"],[\"79300.50\",\"0.033\"],[\"79312.80\",\"0.015\"]],\"a\":[[\"79370.90\",\"0.000\"],[\"79371.00\",\"0.197\"],[\"79371.20\",\"0.006\"],[\"79375.10\",\"0.501\"],[\"79379.60\",\"0.002\"],[\"79379.70\",\"0.020\"],[\"79384.30\",\"0.976\"],[\"79385.60\",\"0.631\"],[\"79385.90\",\"1.797\"],[\"79388.50\",\"0.003\"],[\"79390.60\",\"0.000\"],[\"79391.70\",\"0.454\"],[\"79400.60\",\"3.527\"],[\"79574.20\",\"3.085\"],[\"79578.90\",\"2.840\"],[\"79735.20\",\"0.734\"],[\"79735.30\",\"0.303\"],[\"80350.60\",\"0.000\"]],\"st\":1}}"}
{"receive_ns":1788782261673169000,"stream":"btcusdt@depth@100ms","event_type":"depthUpdate","event_time_ms":1788782261750,"raw_json":"{\"stream\":\"btcusdt@depth@100ms\",\"data\":{\"e\":\"depthUpdate\",\"E\":1788782261750,\"T\":1788782261746,\"s\":\"BTCUSDT\",\"ps\":\"BTCUSDT\",\"U\":11496348044598,\"u\":11496348049377,\"pu\":11496348044476,\"b\":[[\"28966.00\",\"0.749\"],[\"29066.00\",\"1.351\"],[\"71429.40\",\"0.048\"],[\"74720.90\",\"0.002\"],[\"76191.30\",\"0.002\"],[\"77778.70\",\"1.460\"],[\"78413.60\",\"38.980\"],[\"78572.30\",\"12.650\"],[\"79123.90\",\"3.697\"],[\"79124.70\",\"0.015\"],[\"79125.90\",\"0.001\"],[\"79143.70\",\"2.090\"],[\"79143.80\",\"0.001\"],[\"79143.90\",\"0.117\"],[\"79145.80\",\"0.251\"],[\"79189.50\",\"1.464\"],[\"79189.70\",\"0.050\"],[\"79220.60\",\"2.619\"],[\"79220.80\",\"0.076\"],[\"79274.00\",\"0.130\"],[\"79274.20\",\"0.000\"]],\"a\":[[\"79366.60\",\"0.021\"],[\"79371.00\",\"0.121\"],[\"79371.10\",\"0.077\"],[\"79385.90\",\"1.797\"],[\"79388.50\",\"0.003\"],[\"79558.90\",\"0.000\"],[\"79735.20\",\"0.795\"],[\"79735.30\",\"0.337\"],[\"80159.80\",\"13.345\"],[\"80399.50\",\"0.001\"]],\"st\":1}}"}
{"receive_ns":1788782261689973000,"stream":"btcusdt@bookTicker","event_type":"bookTicker","event_time_ms":1788782261775,"raw_json":"{\"stream\":\"btcusdt@bookTicker\",\"data\":{\"e\":\"bookTicker\",\"u\":11496348051224,\"s\":\"BTCUSDT\",\"ps\":\"BTCUSDT\",\"b\":\"79366.00\",\"B\":\"7.008\",\"a\":\"79366.10\",\"A\":\"2.604\",\"T\":1788782261775,\"E\":1788782261775,\"st\":1}}"}
{"receive_ns":1788782261690615000,"stream":"btcusdt@bookTicker","event_type":"bookTicker","event_time_ms":1788782261775,"raw_json":"{\"stream\":\"btcusdt@bookTicker\",\"data\":{\"e\":\"bookTicker\",\"u\":11496348051271,\"s\":\"BTCUSDT\",\"ps\":\"BTCUSDT\",\"b\":\"79366.00\",\"B\":\"7.002\",\"a\":\"79366.10\",\"A\":\"2.604\",\"T\":1788782261775,\"E\":1788782261775,\"st\":1}}"}
{"receive_ns":1788782261765250000,"stream":"btcusdt@bookTicker","event_type":"bookTicker","event_time_ms":1788782261843,"raw_json":"{\"stream\":\"btcusdt@bookTicker\",\"data\":{\"e\":\"bookTicker\",\"u\":11496348054345,\"s\":\"BTCUSDT\",\"ps\":\"BTCUSDT\",\"b\":\"79366.00\",\"B\":\"7.000\",\"a\":\"79366.10\",\"A\":\"2.604\",\"T\":1788782261842,\"E\":1788782261843,\"st\":1}}"}
{"receive_ns":1788782261767146000,"stream":"btcusdt@depth@100ms","event_type":"depthUpdate","event_time_ms":1788782261852,"raw_json":"{\"stream\":\"btcusdt@depth@100ms\",\"data\":{\"e\":\"depthUpdate\",\"E\":1788782261852,\"T\":1788782261851,\"s\":\"BTCUSDT\",\"ps\":\"BTCUSDT\",\"U\":11496348049566,\"u\":11496348054781,\"pu\":11496348049377,\"b\":[[\"1000.00\",\"24.754\"],[\"28966.00\",\"0.931\"],[\"29066.00\",\"1.169\"],[\"71429.40\",\"0.048\"],[\"75397.70\",\"0.017\"],[\"75397.80\",\"0.010\"],[\"76191.30\",\"0.000\"],[\"78413.60\",\"39.617\"],[\"78572.30\",\"12.652\"],[\"78670.10\",\"10.534\"],[\"78737.00\",\"0.093\"],[\"79118.60\",\"0.054\"],[\"79123.90\",\"3.157\"],[\"79124.70\",\"0.000\"],[\"79125.90\",\"0.238\"],[\"79143.70\",\"0.000\"],[\"79143.80\",\"35.380\"],[\"79143.90\",\"0.063\"],[\"79189.50\",\"0.000\"],[\"79189.70\",\"26.569\"],[\"79220.60\",\"1.890\"],[\"79220.80\",\"17.748\"],[\"79274.00\",\"0.000\"],[\"79274.20\",\"8.830\"],[\"79366.00\",\"7.000\"]],\"a\":[[\"79437.90\",\"0.008\"],[\"79446.60\",\"0.016\"],[\"79735.20\",\"0.632\"],[\"80159.80\",\"13.345\"]],\"st\":1}}"}
{"receive_ns":1788782261782744000,"stream":"btcusdt@bookTicker","event_type":"bookTicker","event_time_ms":1788782261867,"raw_json":"{\"stream\":\"btcusdt@bookTicker\",\"data\":{\"e\":\"bookTicker\",\"u\":11496348055794,\"s\":\"BTCUSDT\",\"ps\":\"BTCUSDT\",\"b\":\"79366.00\",\"B\":\"7.000\",\"a\":\"79366.10\",\"A\":\"2.619\",\"T\":1788782261867,\"E\":1788782261867,\"st\":1}}"}
{"receive_ns":1788782261783985000,"stream":"btcusdt@bookTicker","event_type":"bookTicker","event_time_ms":1788782261869,"raw_json":"{\"stream\":\"btcusdt@bookTicker\",\"data\":{\"e\":\"bookTicker\",\"u\":11496348055916,\"s\":\"BTCUSDT\",\"ps\":\"BTCUSDT\",\"b\":\"79366.00\",\"B\":\"7.000\",\"a\":\"79366.10\",\"A\":\"2.622\",\"T\":1788782261868,\"E\":1788782261869,\"st\":1}}"}
{"receive_ns":1788782261793612000,"stream":"btcusdt@bookTicker","event_type":"bookTicker","event_time_ms":1788782261880,"raw_json":"{\"stream\":\"btcusdt@bookTicker\",\"data\":{\"e\":\"bookTicker\",\"u\":11496348056807,\"s\":\"BTCUSDT\",\"ps\":\"BTCUSDT\",\"b\":\"79366.00\",\"B\":\"7.000\",\"a\":\"79366.10\",\"A\":\"2.704\",\"T\":1788782261879,\"E\":1788782261880,\"st\":1}}"}
{"receive_ns":1788782261794279000,"stream":"btcusdt@bookTicker","event_type":"bookTicker","event_time_ms":1788782261881,"raw_json":"{\"stream\":\"btcusdt@bookTicker\",\"data\":{\"e\":\"bookTicker\",\"u\":11496348056860,\"s\":\"BTCUSDT\",\"ps\":\"BTCUSDT\",\"b\":\"79366.00\",\"B\":\"7.000\",\"a\":\"79366.10\",\"A\":\"2.702\",\"T\":1788782261881,\"E\":1788782261881,\"st\":1}}"}
{"receive_ns":1788782261794592000,"stream":"btcusdt@bookTicker","event_type":"bookTicker","event_time_ms":1788782261881,"raw_json":"{\"stream\":\"btcusdt@bookTicker\",\"data\":{\"e\":\"bookTicker\",\"u\":11496348056887,\"s\":\"BTCUSDT\",\"ps\":\"BTCUSDT\",\"b\":\"79366.00\",\"B\":\"7.000\",\"a\":\"79366.10\",\"A\":\"2.687\",\"T\":1788782261881,\"E\":1788782261881,\"st\":1}}"}
{"receive_ns":1788782261794805000,"stream":"btcusdt@bookTicker","event_type":"bookTicker","event_time_ms":1788782261881,"raw_json":"{\"stream\":\"btcusdt@bookTicker\",\"data\":{\"e\":\"bookTicker\",\"u\":11496348056893,\"s\":\"BTCUSDT\",\"ps\":\"BTCUSDT\",\"b\":\"79366.00\",\"B\":\"7.000\",\"a\":\"79366.10\",\"A\":\"2.684\",\"T\":1788782261881,\"E\":1788782261881,\"st\":1}}"}
{"receive_ns":1788782261794989000,"stream":"btcusdt@bookTicker","event_type":"bookTicker","event_time_ms":1788782261881,"raw_json":"{\"stream\":\"btcusdt@bookTicker\",\"data\":{\"e\":\"bookTicker\",\"u\":11496348056912,\"s\":\"BTCUSDT\",\"ps\":\"BTCUSDT\",\"b\":\"79366.00\",\"B\":\"7.000\",\"a\":\"79366.10\",\"A\":\"2.603\",\"T\":1788782261881,\"E\":1788782261881,\"st\":1}}"}
{"receive_ns":1788782261840587000,"stream":"btcusdt@bookTicker","event_type":"bookTicker","event_time_ms":1788782261926,"raw_json":"{\"stream\":\"btcusdt@bookTicker\",\"data\":{\"e\":\"bookTicker\",\"u\":11496348058864,\"s\":\"BTCUSDT\",\"ps\":\"BTCUSDT\",\"b\":\"79366.00\",\"B\":\"7.000\",\"a\":\"79366.10\",\"A\":\"2.602\",\"T\":1788782261925,\"E\":1788782261926,\"st\":1}}"}
{"receive_ns":1788782261841086000,"stream":"btcusdt@bookTicker","event_type":"bookTicker","event_time_ms":1788782261928,"raw_json":"{\"stream\":\"btcusdt@bookTicker\",\"data\":{\"e\":\"bookTicker\",\"u\":11496348058971,\"s\":\"BTCUSDT\",\"ps\":\"BTCUSDT\",\"b\":\"79366.00\",\"B\":\"7.000\",\"a\":\"79366.10\",\"A\":\"2.603\",\"T\":1788782261927,\"E\":1788782261928,\"st\":1}}"}
{"receive_ns":1788782261841335000,"stream":"btcusdt@bookTicker","event_type":"bookTicker","event_time_ms":1788782261928,"raw_json":"{\"stream\":\"btcusdt@bookTicker\",\"data\":{\"e\":\"bookTicker\",\"u\":11496348059000,\"s\":\"BTCUSDT\",\"ps\":\"BTCUSDT\",\"b\":\"79366.00\",\"B\":\"6.982\",\"a\":\"79366.10\",\"A\":\"2.603\",\"T\":1788782261928,\"E\":1788782261928,\"st\":1}}"}
{"receive_ns":1788782261841594000,"stream":"btcusdt@trade","event_type":"trade","event_time_ms":1788782261928,"raw_json":"{\"stream\":\"btcusdt@trade\",\"data\":{\"e\":\"trade\",\"E\":1788782261928,\"T\":1788782261928,\"s\":\"BTCUSDT\",\"t\":8057739782,\"p\":\"79366.00\",\"q\":\"0.018\",\"X\":\"MARKET\",\"m\":true,\"st\":1}}"}
{"receive_ns":1788782261843186000,"stream":"btcusdt@bookTicker","event_type":"bookTicker","event_time_ms":1788782261929,"raw_json":"{\"stream\":\"btcusdt@bookTicker\",\"data\":{\"e\":\"bookTicker\",\"u\":11496348059080,\"s\":\"BTCUSDT\",\"ps\":\"BTCUSDT\",\"b\":\"79366.00\",\"B\":\"6.988\",\"a\":\"79366.10\",\"A\":\"2.603\",\"T\":1788782261929,\"E\":1788782261929,\"st\":1}}"}
{"receive_ns":1788782261843852000,"stream":"btcusdt@bookTicker","event_type":"bookTicker","event_time_ms":1788782261930,"raw_json":"{\"stream\":\"btcusdt@bookTicker\",\"data\":{\"e\":\"bookTicker\",\"u\":11496348059238,\"s\":\"BTCUSDT\",\"ps\":\"BTCUSDT\",\"b\":\"79366.00\",\"B\":\"6.982\",\"a\":\"79366.10\",\"A\":\"2.603\",\"T\":1788782261930,\"E\":1788782261930,\"st\":1}}"}
{"receive_ns":1788782261868956000,"stream":"btcusdt@depth@100ms","event_type":"depthUpdate","event_time_ms":1788782261954,"raw_json":"{\"stream\":\"btcusdt@depth@100ms\",\"data\":{\"e\":\"depthUpdate\",\"E\":1788782261954,\"T\":1788782261951,\"s\":\"BTCUSDT\",\"ps\":\"BTCUSDT\",\"U\":11496348054805,\"u\":11496348060279,\"pu\":11496348054781,\"b\":[[\"1000.00\",\"24.754\"],[\"28966.00\",\"1.106\"],[\"29066.00\",\"0.994\"],[\"71429.40\",\"0.048\"],[\"76191.30\",\"0.002\"],[\"77771.00\",\"5.519\"],[\"77778.70\",\"1.460\"],[\"77859.20\",\"0.000\"],[\"77937.50\",\"0.008\"],[\"77947.40\",\"0.000\"],[\"78035.60\",\"0.361\"],[\"78123.70\",\"0.000\"],[\"78211.90\",\"0.446\"],[\"78238.60\",\"0.791\"],[\"78300.10\",\"0.014\"],[\"78334.20\",\"4.837\"],[\"78388.30\",\"0.000\"],[\"78413.60\",\"40.891\"],[\"78476.40\",\"0.011\"],[\"78564.60\",\"4.385\"],[\"78572.30\",\"12.650\"],[\"78969.20\",\"4.746\"],[\"79143.90\",\"0.063\"],[\"79145.80\",\"0.351\"],[\"79171.80\",\"3.701\"],[\"79189.80\",\"0.018\"],[\"79300.50\",\"0.473\"],[\"79303.90\",\"0.023\"],[\"79312.80\",\"0.001\"],[\"79347.60\",\"0.313\"],[\"79350.20\",\"0.950\"],[\"79350.30\",\"0.000\"],[\"79359.00\",\"0.022\"],[\"79366.00\",\"6.982\"]],\"a\":[[\"79366.10\",\"2.603\"],[\"79367.80\",\"0.077\"],[\"79368.50\",\"0.000\"],[\"79370.00\",\"0.078\"],[\"79380.90\",\"0.004\"],[\"79559.40\",\"0.011\"],[\"79706.90\",\"0.000\"],[\"79735.20\",\"0.943\"],[\"79735.30\",\"0.337\"],[\"79961.30\",\"3.747\"],[\"80099.20\",\"9.160\"],[\"80151.80\",\"1.124\"],[\"80159.80\",\"13.345\"],[\"80240.00\",\"0.131\"],[\"80328.10\",\"0.000\"],[\"80416.30\",\"0.000\"],[\"80504.50\",\"0.000\"],[\"80592.70\",\"0.009\"],[\"80680.80\",\"0.000\"],[\"80769.00\",\"0.001\"],[\"80857.20\",\"0.000\"],[\"80945.40\",\"0.000\"]],\"st\":1}}"}
{"receive_ns":1788782261872130000,"stream":"btcusdt@bookTicker","event_type":"bookTicker","event_time_ms":1788782261959,"raw_json":"{\"stream\":\"btcusdt@bookTicker\",\"data\":{\"e\":\"bookTicker\",\"u\":11496348060615,\"s\":\"BTCUSDT\",\"ps\":\"BTCUSDT\",\"b\":\"79366.00\",\"B\":\"6.982\",\"a\":\"79366.10\",\"A\":\"2.602\",\"T\":1788782261958,\"E\":1788782261959,\"st\":1}}"}
{"receive_ns":1788782261970485000,"stream":"btcusdt@depth@100ms","event_type":"depthUpdate","event_time_ms":1788782262056,"raw_json":"{\"stream\":\"btcusdt@depth@100ms\",\"data\":{\"e\":\"depthUpdate\",\"E\":1788782262056,\"T\":1788782262055,\"s\":\"BTCUSDT\",\"ps\":\"BTCUSDT\",\"U\":11496348060369,\"u\":11496348065441,\"pu\":11496348060279,\"b\":[[\"28966.00\",\"1.288\"],[\"29066.00\",\"0.812\"],[\"63493.00\",\"0.012\"],[\"71429.40\",\"0.048\"],[\"76191.30\",\"0.000\"],[\"76191.40\",\"0.004\"],[\"77778.70\",\"1.463\"],[\"78572.30\",\"12.650\"],[\"78969.10\",\"0.000\"],[\"79118.60\",\"0.000\"],[\"79123.90\",\"3.394\"],[\"79124.70\",\"0.010\"],[\"79125.90\",\"0.001\"],[\"79143.70\",\"0.000\"],[\"79143.80\",\"35.380\"],[\"79143.90\",\"0.117\"],[\"79189.50\",\"0.000\"],[\"79189.70\",\"26.569\"],[\"79220.70\",\"0.005\"],[\"79220.80\",\"17.748\"],[\"79274.00\",\"0.000\"],[\"79274.20\",\"8.830\"]],\"a\":[[\"79366.10\",\"2.602\"],[\"79367.80\",\"0.001\"],[\"79368.50\",\"0.000\"],[\"79372.80\",\"0.008\"],[\"79380.40\",\"1.896\"],[\"79385.90\",\"1.357\"],[\"79388.50\",\"0.443\"],[\"79437.80\",\"1.215\"],[\"79446.60\",\"0.002\"],[\"79559.30\",\"0.042\"],[\"79735.20\",\"0.943\"],[\"79763.00\",\"0.001\"],[\"80099.40\",\"0.114\"],[\"80126.80\",\"69.078\"],[\"80159.80\",\"13.345\"],[\"80391.30\",\"85.211\"]],\"st\":1}}"}
{"receive_ns":1788782262071957000,"stream":"btcusdt@depth@100ms","event_type":"depthUpdate","event_time_ms":1788782262158,"raw_json":"{\"stream\":\"btcusdt@depth@100ms\",\"data\":{\"e\":\"depthUpdate\",\"E\":1788782262158,\"T\":1788782262155,\"s\":\"BTCUSDT\",\"ps\":\"BTCUSDT\",\"U\":11496348065469,\"u\":11496348070285,\"pu\":11496348065441,\"b\":[[\"1000.00\",\"24.754\"],[\"28966.00\",\"1.463\"],[\"29066.00\",\"0.637\"],[\"63493.00\",\"0.012\"],[\"71429.40\",\"0.048\"],[\"76191.40\",\"0.005\"],[\"78278.70\",\"1.222\"],[\"78350.50\",\"0.000\"],[\"78572.30\",\"12.650\"],[\"78969.10\",\"0.001\"],[\"78969.20\",\"4.746\"],[\"79123.90\",\"3.645\"],[\"79124.10\",\"0.063\"],[\"79124.70\",\"0.010\"],[\"79125.90\",\"0.441\"],[\"79143.70\",\"0.000\"],[\"79143.80\",\"35.380\"],[\"79143.90\",\"0.054\"],[\"79145.80\",\"0.000\"],[\"79189.50\",\"0.000\"],[\"79189.70\",\"26.569\"],[\"79220.70\",\"0.005\"],[\"79220.80\",\"17.748\"],[\"79274.00\",\"0.000\"],[\"79274.20\",\"8.830\"],[\"79300.50\",\"0.033\"]],\"a\":[[\"79385.80\",\"0.450\"],[\"79388.50\",\"0.003\"],[\"79470.70\",\"0.000\"],[\"79559.20\",\"0.127\"],[\"79574.20\",\"3.281\"],[\"79578.90\",\"2.840\"],[\"79735.20\",\"0.943\"],[\"79735.30\",\"0.337\"],[\"80159.80\",\"13.345\"],[\"80318.50\",\"43.842\"],[\"80453.40\",\"1.986\"],[\"80810.50\",\"0.618\"]],\"st\":1}}"}
{"receive_ns":1788782262173840000,"stream":"btcusdt@depth@100ms","event_type":"depthUpdate","event_time_ms":1788782262260,"raw_json":"{\"stream\":\"btcusdt@depth@100ms\",\"data\":{\"e\":\"depthUpdate\",\"E\":1788782262260,\"T\":1788782262257,\"s\":\"BTCUSDT\",\"ps\":\"BTCUSDT\",\"U\":11496348070445,\"u\":11496348076235,\"pu\":11496348070285,\"b\":[[\"1000.00\",\"24.754\"],[\"28966.00\",\"1.645\"],[\"29066.00\",\"0.455\"],[\"71429.40\",\"0.048\"],[\"74606.90\",\"0.002\"],[\"76191.30\",\"0.002\"],[\"78572.30\",\"12.650\"],[\"79123.90\",\"2.931\"],[\"79124.70\",\"0.000\"],[\"79125.90\",\"0.541\"],[\"79145.80\",\"0.477\"],[\"79344.90\",\"0.002\"]],\"a\":[[\"79369.50\",\"0.076\"],[\"79370.00\",\"0.002\"],[\"79384.70\",\"0.008\"],[\"79559.20\",\"0.001\"],[\"79559.60\",\"0.001\"],[\"79574.20\",\"5.123\"],[\"79735.20\",\"0.795\"],[\"79961.30\",\"3.122\"],[\"80159.80\",\"13.345\"]],\"st\":1}}"}
{"receive_ns":1788782262179315000,"stream":"btcusdt@bookTicker","event_type":"bookTicker","event_time_ms":1788782262265,"raw_json":"{\"stream\":\"btcusdt@bookTicker\",\"data\":{\"e\":\"bookTicker\",\"u\":11496348076578,\"s\":\"BTCUSDT\",\"ps\":\"BTCUSDT\",\"b\":\"79366.00\",\"B\":\"6.982\",\"a\":\"79366.10\",\"A\":\"2.520\",\"T\":1788782262264,\"E\":1788782262265,\"st\":1}}"}
{"receive_ns":1788782262179932000,"stream":"btcusdt@bookTicker","event_type":"bookTicker","event_time_ms":1788782262266,"raw_json":"{\"stream\":\"btcusdt@bookTicker\",\"data\":{\"e\":\"bookTicker\",\"u\":11496348076666,\"s\":\"BTCUSDT\",\"ps\":\"BTCUSDT\",\"b\":\"79366.00\",\"B\":\"6.982\",\"a\":\"79366.10\",\"A\":\"2.522\",\"T\":1788782262266,\"E\":1788782262266,\"st\":1}}"}
{"receive_ns":1788782262202304000,"stream":"btcusdt@bookTicker","event_type":"bookTicker","event_time_ms":1788782262287,"raw_json":"{\"stream\":\"btcusdt@bookTicker\",\"data\":{\"e\":\"bookTicker\",\"u\":11496348077439,\"s\":\"BTCUSDT\",\"ps\":\"BTCUSDT\",\"b\":\"79366.00\",\"B\":\"6.982\",\"a\":\"79366.10\",\"A\":\"2.603\",\"T\":1788782262286,\"E\":1788782262287,\"st\":1}}"}
{"receive_ns":1788782262202879000,"stream":"btcusdt@bookTicker","event_type":"bookTicker","event_time_ms":1788782262288,"raw_json":"{\"stream\":\"btcusdt@bookTicker\",\"data\":{\"e\":\"bookTicker\",\"u\":11496348077479,\"s\":\"BTCUSDT\",\"ps\":\"BTCUSDT\",\"b\":\"79366.00\",\"B\":\"6.982\",\"a\":\"79366.10\",\"A\":\"2.601\",\"T\":1788782262288,\"E\":1788782262288,\"st\":1}}"}
{"receive_ns":1788782262217277000,"stream":"btcusdt@bookTicker","event_type":"bookTicker","event_time_ms":1788782262303,"raw_json":"{\"stream\":\"btcusdt@bookTicker\",\"data\":{\"e\":\"bookTicker\",\"u\":11496348078615,\"s\":\"BTCUSDT\",\"ps\":\"BTCUSDT\",\"b\":\"79366.00\",\"B\":\"6.982\",\"a\":\"79366.10\",\"A\":\"2.603\",\"T\":1788782262303,\"E\":1788782262303,\"st\":1}}"}
{"receive_ns":1788782262276439000,"stream":"btcusdt@depth@100ms","event_type":"depthUpdate","event_time_ms":1788782262362,"raw_json":"{\"stream\":\"btcusdt@depth@100ms\",\"data\":{\"e\":\"depthUpdate\",\"E\":1788782262362,\"T\":1788782262361,\"s\":\"BTCUSDT\",\"ps\":\"BTCUSDT\",\"U\":11496348076362,\"u\":11496348082234,\"pu\":11496348076235,\"b\":[[\"28866.00\",\"0.028\"],[\"28966.00\",\"1.771\"],[\"29066.00\",\"0.301\"],[\"71429.40\",\"0.048\"],[\"76191.30\",\"0.000\"],[\"77778.70\",\"1.460\"],[\"78193.80\",\"9.792\"],[\"78572.30\",\"12.650\"],[\"79119.00\",\"5.831\"],[\"79123.90\",\"2.680\"],[\"79124.10\",\"0.000\"],[\"79125.90\",\"0.001\"],[\"79143.90\",\"5.581\"],[\"79145.80\",\"0.714\"],[\"79190.30\",\"4.755\"],[\"79223.80\",\"4.207\"],[\"79275.60\",\"2.134\"]],\"a\":[[\"79366.10\",\"2.603\"],[\"79369.40\",\"0.076\"],[\"79369.50\",\"0.000\"],[\"79371.40\",\"0.002\"],[\"79404.90\",\"2.473\"],[\"79559.30\",\"0.168\"],[\"79559.80\",\"0.000\"],[\"79560.10\",\"0.000\"],[\"79578.90\",\"2.815\"],[\"79616.40\",\"6.312\"],[\"79735.20\",\"0.488\"],[\"79735.30\",\"0.303\"],[\"80001.00\",\"8.388\"],[\"80159.80\",\"13.345\"],[\"80329.30\",\"2.467\"],[\"80509.50\",\"0.000\"],[\"80547.30\",\"0.160\"]],\"st\":1}}"}
{"receive_ns":1788782262317224000,"stream":"btcusdt@bookTicker","event_type":"bookTicker","event_time_ms":1788782262402,"raw_json":"{\"stream\":\"btcusdt@bookTicker\",\"data\":{\"e\":\"bookTicker\",\"u\":11496348084793,\"s\":\"BTCUSDT\",\"ps\":\"BTCUSDT\",\"b\":\"79366.00\",\"B\":\"6.980\",\"a\":\"79366.10\",\"A\":\"2.603\",\"T\":1788782262401,\"E\":1788782262402,\"st\":1}}"}
{"receive_ns":1788782262318201000,"stream":"btcusdt@bookTicker","event_type":"bookTicker","event_time_ms":1788782262403,"raw_json":"{\"stream\":\"btcusdt@bookTicker\",\"data\":{\"e\":\"bookTicker\",\"u\":11496348084913,\"s\":\"BTCUSDT\",\"ps\":\"BTCUSDT\",\"b\":\"79366.00\",\"B\":\"6.980\",\"a\":\"79366.10\",\"A\":\"3.066\",\"T\":1788782262403,\"E\":1788782262403,\"st\":1}}"}
{"receive_ns":1788782262319239000,"stream":"btcusdt@bookTicker","event_type":"bookTicker","event_time_ms":1788782262404,"raw_json":"{\"stream\":\"btcusdt@bookTicker\",\"data\":{\"e\":\"bookTicker\",\"u\":11496348084968,\"s\":\"BTCUSDT\",\"ps\":\"BTCUSDT\",\"b\":\"79366.00\",\"B\":\"6.981\",\"a\":\"79366.10\",\"A\":\"3.066\",\"T\":1788782262404,\"E\":1788782262404,\"st\":1}}"}
{"receive_ns":1788782262319502000,"stream":"btcusdt@bookTicker","event_type":"bookTicker","event_time_ms":1788782262405,"raw_json":"{\"stream\":\"btcusdt@bookTicker\",\"data\":{\"e\":\"bookTicker\",\"u\":11496348084980,\"s\":\"BTCUSDT\",\"ps\":\"BTCUSDT\",\"b\":\"79366.00\",\"B\":\"6.981\",\"a\":\"79366.10\",\"A\":\"3.068\",\"T\":1788782262404,\"E\":1788782262405,\"st\":1}}"}
{"receive_ns":1788782262319709000,"stream":"btcusdt@bookTicker","event_type":"bookTicker","event_time_ms":1788782262405,"raw_json":"{\"stream\":\"btcusdt@bookTicker\",\"data\":{\"e\":\"bookTicker\",\"u\":11496348084990,\"s\":\"BTCUSDT\",\"ps\":\"BTCUSDT\",\"b\":\"79366.00\",\"B\":\"6.987\",\"a\":\"79366.10\",\"A\":\"3.068\",\"T\":1788782262404,\"E\":1788782262405,\"st\":1}}"}
{"receive_ns":1788782262319975000,"stream":"btcusdt@bookTicker","event_type":"bookTicker","event_time_ms":1788782262406,"raw_json":"{\"stream\":\"btcusdt@bookTicker\",\"data\":{\"e\":\"bookTicker\",\"u\":11496348085049,\"s\":\"BTCUSDT\",\"ps\":\"BTCUSDT\",\"b\":\"79366.00\",\"B\":\"6.981\",\"a\":\"79366.10\",\"A\":\"3.068\",\"T\":1788782262406,\"E\":1788782262406,\"st\":1}}"}
{"receive_ns":1788782262378949000,"stream":"btcusdt@depth@100ms","event_type":"depthUpdate","event_time_ms":1788782262464,"raw_json":"{\"stream\":\"btcusdt@depth@100ms\",\"data\":{\"e\":\"depthUpdate\",\"E\":1788782262464,\"T\":1788782262461,\"s\":\"BTCUSDT\",\"ps\":\"BTCUSDT\",\"U\":11496348082251,\"u\":11496348087640,\"pu\":11496348082234,\"b\":[[\"1000.00\",\"24.754\"],[\"28866.00\",\"0.084\"],[\"28966.00\",\"1.834\"],[\"29066.00\",\"0.182\"],[\"34000.00\",\"0.968\"],[\"63492.80\",\"0.000\"],[\"71429.40\",\"0.048\"],[\"76191.30\",\"0.002\"],[\"78572.30\",\"12.651\"],[\"78969.20\",\"4.746\"],[\"79118.60\",\"0.054\"],[\"79123.90\",\"3.471\"],[\"79124.10\",\"0.063\"],[\"79124.70\",\"0.000\"],[\"79143.70\",\"0.000\"],[\"79143.80\",\"35.380\"],[\"79143.90\",\"0.000\"],[\"79148.90\",\"2.553\"],[\"79171.80\",\"3.719\"],[\"79189.50\",\"0.000\"],[\"79189.70\",\"26.569\"],[\"79189.80\",\"0.000\"],[\"79190.30\",\"0.902\"],[\"79220.70\",\"0.005\"],[\"79220.80\",\"17.748\"],[\"79223.80\",\"1.476\"],[\"79274.00\",\"0.000\"],[\"79274.20\",\"8.830\"],[\"79275.60\",\"0.914\"],[\"79311.80\",\"2.554\"],[\"79312.10\",\"0.000\"],[\"79325.70\",\"0.013\"],[\"79327.40\",\"0.403\"],[\"79335.60\",\"0.986\"],[\"79342.00\",\"0.098\"],[\"79366.00\",\"6.981\"]],\"a\":[[\"79366.10\",\"3.068\"],[\"79387.20\",\"0.615\"],[\"79389.60\",\"0.844\"],[\"79392.50\",\"0.253\"],[\"79398.60\",\"4.888\"],[\"79404.90\",\"2.474\"],[\"79405.40\",\"0.000\"],[\"79411.00\",\"3.630\"],[\"79492.00\",\"1.059\"],[\"79495.30\",\"3.376\"],[\"79531.20\",\"0.000\"],[\"79559.20\",\"0.001\"],[\"79559.30\",\"0.042\"],[\"79576.90\",\"1.168\"],[\"79579.80\",\"3.375\"],[\"79735.20\",\"0.943\"],[\"79735.30\",\"0.337\"],[\"80159.80\",\"13.345\"],[\"80318.50\",\"45.085\"],[\"80556.70\",\"0.279\"],[\"87302.80\",\"0.000\"]],\"st\":1}}"}
{"receive_ns":1788782262410191000,"stream":"btcusdt@bookTicker","event_type":"bookTicker","event_time_ms":1788782262496,"raw_json":"{\"stream\":\"btcusdt@bookTicker\",\"data\":{\"e\":\"bookTicker\",\"u\":11496348090611,\"s\":\"BTCUSDT\",\"ps\":\"BTCUSDT\",\"b\":\"79366.00\",\"B\":\"6.981\",\"a\":\"79366.10\",\"A\":\"3.073\",\"T\":1788782262495,\"E\":1788782262496,\"st\":1}}"}
{"receive_ns":1788782262410453000,"stream":"btcusdt@bookTicker","event_type":"bookTicker","event_time_ms":1788782262496,"raw_json":"{\"stream\":\"btcusdt@bookTicker\",\"data\":{\"e\":\"bookTicker\",\"u\":11496348090612,\"s\":\"BTCUSDT\",\"ps\":\"BTCUSDT\",\"b\":\"79366.00\",\"B\":\"6.981\",\"a\":\"79366.10\",\"A\":\"3.086\",\"T\":1788782262495,\"E\":1788782262496,\"st\":1}}"}
{"receive_ns":1788782262410637000,"stream":"btcusdt@bookTicker","event_type":"bookTicker","event_time_ms":1788782262496,"raw_json":"{\"stream\":\"btcusdt@bookTicker\",\"data\":{\"e\":\"bookTicker\",\"u\":11496348090624,\"s\":\"BTCUSDT\",\"ps\":\"BTCUSDT\",\"b\":\"79366.00\",\"B\":\"6.981\",\"a\":\"79366.10\",\"A\":\"3.098\",\"T\":1788782262496,\"E\":1788782262496,\"st\":1}}"}
{"receive_ns":1788782262410805000,"stream":"btcusdt@bookTicker","event_type":"bookTicker","event_time_ms":1788782262496,"raw_json":"{\"stream\":\"btcusdt@bookTicker\",\"data\":{\"e\":\"bookTicker\",\"u\":11496348090667,\"s\":\"BTCUSDT\",\"ps\":\"BTCUSDT\",\"b\":\"79366.00\",\"B\":\"6.981\",\"a\":\"79366.10\",\"A\":\"3.101\",\"T\":1788782262496,\"E\":1788782262496,\"st\":1}}"}
{"receive_ns":1788782262410968000,"stream":"btcusdt@bookTicker","event_type":"bookTicker","event_time_ms":1788782262496,"raw_json":"{\"stream\":\"btcusdt@bookTicker\",\"data\":{\"e\":\"bookTicker\",\"u\":11496348090670,\"s\":\"BTCUSDT\",\"ps\":\"BTCUSDT\",\"b\":\"79366.00\",\"B\":\"6.981\",\"a\":\"79366.10\",\"A\":\"3.177\",\"T\":1788782262496,\"E\":1788782262496,\"st\":1}}"}
{"receive_ns":1788782262411211000,"stream":"btcusdt@bookTicker","event_type":"bookTicker","event_time_ms":1788782262497,"raw_json":"{\"stream\":\"btcusdt@bookTicker\",\"data\":{\"e\":\"bookTicker\",\"u\":11496348090749,\"s\":\"BTCUSDT\",\"ps\":\"BTCUSDT\",\"b\":\"79366.00\",\"B\":\"6.981\",\"a\":\"79366.10\",\"A\":\"4.617\",\"T\":1788782262496,\"E\":1788782262497,\"st\":1}}"}
{"receive_ns":1788782262411393000,"stream":"btcusdt@bookTicker","event_type":"bookTicker","event_time_ms":1788782262497,"raw_json":"{\"stream\":\"btcusdt@bookTicker\",\"data\":{\"e\":\"bookTicker\",\"u\":11496348090815,\"s\":\"BTCUSDT\",\"ps\":\"BTCUSDT\",\"b\":\"79366.00\",\"B\":\"6.981\",\"a\":\"79366.10\",\"A\":\"4.615\",\"T\":1788782262497,\"E\":1788782262497,\"st\":1}}"}
{"receive_ns":1788782262412870000,"stream":"btcusdt@bookTicker","event_type":"bookTicker","event_time_ms":1788782262497,"raw_json":"{\"stream\":\"btcusdt@bookTicker\",\"data\":{\"e\":\"bookTicker\",\"u\":11496348090830,\"s\":\"BTCUSDT\",\"ps\":\"BTCUSDT\",\"b\":\"79366.00\",\"B\":\"6.981\",\"a\":\"79366.10\",\"A\":\"4.617\",\"T\":1788782262497,\"E\":1788782262497,\"st\":1}}"}
{"receive_ns":1788782262413082000,"stream":"btcusdt@bookTicker","event_type":"bookTicker","event_time_ms":1788782262497,"raw_json":"{\"stream\":\"btcusdt@bookTicker\",\"data\":{\"e\":\"bookTicker\",\"u\":11496348090846,\"s\":\"BTCUSDT\",\"ps\":\"BTCUSDT\",\"b\":\"79366.00\",\"B\":\"6.981\",\"a\":\"79366.10\",\"A\":\"4.696\",\"T\":1788782262497,\"E\":1788782262497,\"st\":1}}"}
{"receive_ns":1788782262413278000,"stream":"btcusdt@bookTicker","event_type":"bookTicker","event_time_ms":1788782262498,"raw_json":"{\"stream\":\"btcusdt@bookTicker\",\"data\":{\"e\":\"bookTicker\",\"u\":11496348090950,\"s\":\"BTCUSDT\",\"ps\":\"BTCUSDT\",\"b\":\"79366.00\",\"B\":\"6.981\",\"a\":\"79366.10\",\"A\":\"4.695\",\"T\":1788782262498,\"E\":1788782262498,\"st\":1}}"}
{"receive_ns":1788782262413445000,"stream":"btcusdt@bookTicker","event_type":"bookTicker","event_time_ms":1788782262498,"raw_json":"{\"stream\":\"btcusdt@bookTicker\",\"data\":{\"e\":\"bookTicker\",\"u\":11496348090962,\"s\":\"BTCUSDT\",\"ps\":\"BTCUSDT\",\"b\":\"79366.00\",\"B\":\"6.981\",\"a\":\"79366.10\",\"A\":\"4.697\",\"T\":1788782262498,\"E\":1788782262498,\"st\":1}}"}
{"receive_ns":1788782262413705000,"stream":"btcusdt@bookTicker","event_type":"bookTicker","event_time_ms":1788782262498,"raw_json":"{\"stream\":\"btcusdt@bookTicker\",\"data\":{\"e\":\"bookTicker\",\"u\":11496348090963,\"s\":\"BTCUSDT\",\"ps\":\"BTCUSDT\",\"b\":\"79366.00\",\"B\":\"6.981\",\"a\":\"79366.10\",\"A\":\"4.698\",\"T\":1788782262498,\"E\":1788782262498,\"st\":1}}"}
{"receive_ns":1788782262416363000,"stream":"btcusdt@bookTicker","event_type":"bookTicker","event_time_ms":1788782262501,"raw_json":"{\"stream\":\"btcusdt@bookTicker\",\"data\":{\"e\":\"bookTicker\",\"u\":11496348091418,\"s\":\"BTCUSDT\",\"ps\":\"BTCUSDT\",\"b\":\"79366.00\",\"B\":\"6.981\",\"a\":\"79366.10\",\"A\":\"4.617\",\"T\":1788782262501,\"E\":1788782262501,\"st\":1}}"}
{"receive_ns":1788782262419799000,"stream":"btcusdt@bookTicker","event_type":"bookTicker","event_time_ms":1788782262504,"raw_json":"{\"stream\":\"btcusdt@bookTicker\",\"data\":{\"e\":\"bookTicker\",\"u\":11496348091705,\"s\":\"BTCUSDT\",\"ps\":\"BTCUSDT\",\"b\":\"79366.00\",\"B\":\"6.981\",\"a\":\"79366.10\",\"A\":\"4.699\",\"T\":1788782262504,\"E\":1788782262504,\"st\":1}}"}
{"receive_ns":1788782262420269000,"stream":"btcusdt@bookTicker","event_type":"bookTicker","event_time_ms":1788782262505,"raw_json":"{\"stream\":\"btcusdt@bookTicker\",\"data\":{\"e\":\"bookTicker\",\"u\":11496348091829,\"s\":\"BTCUSDT\",\"ps\":\"BTCUSDT\",\"b\":\"79366.00\",\"B\":\"6.981\",\"a\":\"79366.10\",\"A\":\"4.697\",\"T\":1788782262505,\"E\":1788782262505,\"st\":1}}"}
{"receive_ns":1788782262420933000,"stream":"btcusdt@bookTicker","event_type":"bookTicker","event_time_ms":1788782262507,"raw_json":"{\"stream\":\"btcusdt@bookTicker\",\"data\":{\"e\":\"bookTicker\",\"u\":11496348092075,\"s\":\"BTCUSDT\",\"ps\":\"BTCUSDT\",\"b\":\"79366.00\",\"B\":\"6.981\",\"a\":\"79366.10\",\"A\":\"4.698\",\"T\":1788782262507,\"E\":1788782262507,\"st\":1}}"}
{"receive_ns":1788782262421183000,"stream":"btcusdt@bookTicker","event_type":"bookTicker","event_time_ms":1788782262507,"raw_json":"{\"stream\":\"btcusdt@bookTicker\",\"data\":{\"e\":\"bookTicker\",\"u\":11496348092078,\"s\":\"BTCUSDT\",\"ps\":\"BTCUSDT\",\"b\":\"79366.00\",\"B\":\"6.980\",\"a\":\"79366.10\",\"A\":\"4.698\",\"T\":1788782262507,\"E\":1788782262507,\"st\":1}}"}
{"receive_ns":1788782262421393000,"stream":"btcusdt@bookTicker","event_type":"bookTicker","event_time_ms":1788782262507,"raw_json":"{\"stream\":\"btcusdt@bookTicker\",\"data\":{\"e\":\"bookTicker\",\"u\":11496348092118,\"s\":\"BTCUSDT\",\"ps\":\"BTCUSDT\",\"b\":\"79366.00\",\"B\":\"6.980\",\"a\":\"79366.10\",\"A\":\"4.738\",\"T\":1788782262507,\"E\":1788782262507,\"st\":1}}"}
{"receive_ns":1788782262422254000,"stream":"btcusdt@bookTicker","event_type":"bookTicker","event_time_ms":1788782262508,"raw_json":"{\"stream\":\"btcusdt@bookTicker\",\"data\":{\"e\":\"bookTicker\",\"u\":11496348092227,\"s\":\"BTCUSDT\",\"ps\":\"BTCUSDT\",\"b\":\"79366.00\",\"B\":\"6.979\",\"a\":\"79366.10\",\"A\":\"4.738\",\"T\":1788782262508,\"E\":1788782262508,\"st\":1}}"}
{"receive_ns":1788782262422605000,"stream":"btcusdt@bookTicker","event_type":"bookTicker","event_time_ms":1788782262509,"raw_json":"{\"stream\":\"btcusdt@bookTicker\",\"data\":{\"e\":\"bookTicker\",\"u\":11496348092271,\"s\":\"BTCUSDT\",\"ps\":\"BTCUSDT\",\"b\":\"79366.00\",\"B\":\"6.979\",\"a\":\"79366.10\",\"A\":\"4.740\",\"T\":1788782262508,\"E\":1788782262509,\"st\":1}}"}
{"receive_ns":1788782262428453000,"stream":"btcusdt@bookTicker","event_type":"bookTicker","event_time_ms":1788782262514,"raw_json":"{\"stream\":\"btcusdt@bookTicker\",\"data\":{\"e\":\"bookTicker\",\"u\":11496348092870,\"s\":\"BTCUSDT\",\"ps\":\"BTCUSDT\",\"b\":\"79366.00\",\"B\":\"6.979\",\"a\":\"79366.10\",\"A\":\"4.893\",\"T\":1788782262514,\"E\":1788782262514,\"st\":1}}"}
{"receive_ns":1788782262429092000,"stream":"btcusdt@bookTicker","event_type":"bookTicker","event_time_ms":1788782262515,"raw_json":"{\"stream\":\"btcusdt@bookTicker\",\"data\":{\"e\":\"bookTicker\",\"u\":11496348093022,\"s\":\"BTCUSDT\",\"ps\":\"BTCUSDT\",\"b\":\"79366.00\",\"B\":\"6.979\",\"a\":\"79366.10\",\"A\":\"4.891\",\"T\":1788782262515,\"E\":1788782262515,\"st\":1}}"}
{"receive_ns":1788782262432841000,"stream":"btcusdt@bookTicker","event_type":"bookTicker","event_time_ms":1788782262519,"raw_json":"{\"stream\":\"btcusdt@bookTicker\",\"data\":{\"e\":\"bookTicker\",\"u\":11496348093321,\"s\":\"BTCUSDT\",\"ps\":\"BTCUSDT\",\"b\":\"79366.00\",\"B\":\"6.979\",\"a\":\"79366.10\",\"A\":\"4.890\",\"T\":1788782262519,\"E\":1788782262519,\"st\":1}}"}
{"receive_ns":1788782262439178000,"stream":"btcusdt@bookTicker","event_type":"bookTicker","event_time_ms":1788782262521,"raw_json":"{\"stream\":\"btcusdt@bookTicker\",\"data\":{\"e\":\"bookTicker\",\"u\":11496348093409,\"s\":\"BTCUSDT\",\"ps\":\"BTCUSDT\",\"b\":\"79366.00\",\"B\":\"6.979\",\"a\":\"79366.10\",\"A\":\"4.891\",\"T\":1788782262521,\"E\":1788782262521,\"st\":1}}"}
{"receive_ns":1788782262439782000,"stream":"btcusdt@bookTicker","event_type":"bookTicker","event_time_ms":1788782262522,"raw_json":"{\"stream\":\"btcusdt@bookTicker\",\"data\":{\"e\":\"bookTicker\",\"u\":11496348093480,\"s\":\"BTCUSDT\",\"ps\":\"BTCUSDT\",\"b\":\"79366.00\",\"B\":\"6.978\",\"a\":\"79366.10\",\"A\":\"4.891\",\"T\":1788782262522,\"E\":1788782262522,\"st\":1}}"}
{"receive_ns":1788782262482587000,"stream":"btcusdt@depth@100ms","event_type":"depthUpdate","event_time_ms":1788782262566,"raw_json":"{\"stream\":\"btcusdt@depth@100ms\",\"data\":{\"e\":\"depthUpdate\",\"E\":1788782262566,\"T\":1788782262561,\"s\":\"BTCUSDT\",\"ps\":\"BTCUSDT\",\"U\":11496348087766,\"u\":11496348096633,\"pu\":11496348087640,\"b\":[[\"1000.00\",\"24.754\"],[\"28866.00\",\"0.140\"],[\"28966.00\",\"1.897\"],[\"29066.00\",\"0.063\"],[\"63493.00\",\"0.022\"],[\"71429.40\",\"0.048\"],[\"75397.70\",\"0.012\"],[\"78572.30\",\"12.651\"],[\"78651.70\",\"8.949\"],[\"78669.50\",\"0.000\"],[\"78731.10\",\"7.991\"],[\"79123.90\",\"3.596\"],[\"79125.90\",\"0.113\"],[\"79143.70\",\"2.163\"],[\"79143.80\",\"0.001\"],[\"79145.80\",\"0.000\"],[\"79151.70\",\"0.478\"],[\"79189.50\",\"1.515\"],[\"79189.70\",\"0.050\"],[\"79220.70\",\"0.759\"],[\"79220.80\",\"0.076\"],[\"79274.00\",\"0.134\"],[\"79274.20\",\"0.000\"],[\"79280.20\",\"0.000\"],[\"79286.90\",\"0.001\"],[\"79291.10\",\"0.001\"],[\"79326.50\",\"1.165\"],[\"79328.50\",\"3.745\"],[\"79332.00\",\"1.110\"],[\"79334.10\",\"0.967\"],[\"79334.30\",\"0.006\"],[\"79336.00\",\"0.031\"],[\"79336.30\",\"1.254\"],[\"79336.40\",\"0.002\"],[\"79337.20\",\"0.630\"],[\"79337.90\",\"0.357\"],[\"79338.60\",\"0.000\"],[\"79338.80\",\"0.457\"],[\"79339.00\",\"1.018\"],[\"79340.30\",\"0.000\"],[\"79340.90\",\"0.630\"],[\"79341.20\",\"0.631\"],[\"79342.30\",\"0.970\"],[\"79342.90\",\"0.000\"],[\"79343.80\",\"0.006\"],[\"79345.20\",\"0.631\"],[\"79346.00\",\"0.572\"],[\"79346.10\",\"0.000\"],[\"79346.40\",\"0.011\"],[\"79347.50\",\"0.138\"],[\"79347.60\",\"0.754\"],[\"79350.20\",\"0.509\"],[\"79350.30\",\"0.026\"],[\"79350.90\",\"0.272\"],[\"79351.00\",\"0.113\"],[\"79351.10\",\"0.554\"],[\"79351.20\",\"0.102\"],[\"79351.30\",\"0.196\"],[\"79352.80\",\"0.506\"],[\"79354.40\",\"0.001\"],[\"79354.80\",\"0.077\"],[\"79355.20\",\"0.000\"],[\"79356.10\",\"0.003\"],[\"79356.80\",\"0.254\"],[\"79357.00\",\"0.000\"],[\"79357.20\",\"0.000\"],[\"79358.00\",\"1.101\"],[\"79358.40\",\"1.033\"],[\"79358.50\",\"0.090\"],[\"79358.80\",\"0.009\"],[\"79362.50\",\"0.000\"],[\"79362.80\",\"0.076\"],[\"79363.90\",\"0.002\"],[\"79364.00\",\"0.076\"],[\"79365.20\",\"0.000\"],[\"79366.00\",\"6.978\"]],\"a\":[[\"79366.10\",\"4.891\"],[\"79366.30\",\"0.002\"],[\"79366.40\",\"0.252\"],[\"79366.50\",\"0.254\"],[\"79366.90\",\"0.004\"],[\"79367.20\",\"0.041\"],[\"79367.30\",\"0.783\"],[\"79367.40\",\"2.528\"],[\"79368.50\",\"0.002\"],[\"79368.70\",\"0.000\"],[\"79369.00\",\"1.002\"],[\"79369.10\",\"0.010\"],[\"79369.20\",\"0.002\"],[\"79369.40\",\"0.078\"],[\"79369.90\",\"0.000\"],[\"79370.60\",\"0.000\"],[\"79371.20\",\"0.004\"],[\"79371.40\",\"0.000\"],[\"79374.80\",\"0.003\"],[\"79374.90\",\"0.007\"],[\"79375.00\",\"0.331\"],[\"79375.10\",\"0.186\"],[\"79376.30\",\"0.235\"],[\"79376.80\",\"0.413\"],[\"79377.00\",\"0.107\"],[\"79378.80\",\"0.000\"],[\"79379.70\",\"0.329\"],[\"79379.80\",\"1.266\"],[\"79382.80\",\"0.112\"],[\"79383.20\",\"0.002\"],[\"79384.00\",\"0.620\"],[\"79384.20\",\"0.000\"],[\"79384.30\",\"1.351\"],[\"79385.10\",\"0.631\"],[\"79385.20\",\"0.010\"],[\"79385.80\",\"1.016\"],[\"79386.60\",\"0.002\"],[\"79387.10\",\"0.006\"],[\"79387.30\",\"0.042\"],[\"79387.80\",\"0.973\"],[\"79387.90\",\"0.170\"],[\"79388.20\",\"0.455\"],[\"79388.90\",\"0.003\"],[\"79391.30\",\"0.149\"],[\"79391.70\",\"0.001\"],[\"79392.90\",\"1.409\"],[\"79393.90\",\"0.004\"],[\"79395.70\",\"0.004\"],[\"79397.80\",\"2.315\"],[\"79404.90\",\"1.137\"],[\"79407.50\",\"0.592\"],[\"79409.10\",\"0.002\"],[\"79445.30\",\"0.027\"],[\"79448.20\",\"1.926\"],[\"79515.40\",\"0.032\"],[\"79521.20\",\"0.008\"],[\"79522.90\",\"0.000\"],[\"79583.40\",\"0.259\"],[\"79584.90\",\"0.006\"],[\"79735.20\",\"0.858\"],[\"80159.80\",\"13.345\"],[\"80371.50\",\"1.272\"],[\"80561.70\",\"0.433\"],[\"87302.80\",\"0.000\"]],\"st\":1}}"}
{"receive_ns":1788782262500996000,"stream":"btcusdt@bookTicker","event_type":"bookTicker","event_time_ms":1788782262586,"raw_json":"{\"stream\":\"btcusdt@bookTicker\",\"data\":{\"e\":\"bookTicker\",\"u\":11496348100399,\"s\":\"BTCUSDT\",\"ps\":\"BTCUSDT\",\"b\":\"79366.00\",\"B\":\"5.878\",\"a\":\"79366.10\",\"A\":\"4.891\",\"T\":1788782262586,\"E\":1788782262586,\"st\":1}}"}
{"receive_ns":1788782262501520000,"stream":"btcusdt@bookTicker","event_type":"bookTicker","event_time_ms":1788782262588,"raw_json":"{\"stream\":\"btcusdt@bookTicker\",\"data\":{\"e\":\"bookTicker\",\"u\":11496348100738,\"s\":\"BTCUSDT\",\"ps\":\"BTCUSDT\",\"b\":\"79366.00\",\"B\":\"5.878\",\"a\":\"79366.10\",\"A\":\"4.893\",\"T\":1788782262587,\"E\":1788782262588,\"st\":1}}"}
{"receive_ns":1788782262515753000,"stream":"btcusdt@bookTicker","event_type":"bookTicker","event_time_ms":1788782262601,"raw_json":"{\"stream\":\"btcusdt@bookTicker\",\"data\":{\"e\":\"bookTicker\",\"u\":11496348103108,\"s\":\"BTCUSDT\",\"ps\":\"BTCUSDT\",\"b\":\"79366.00\",\"B\":\"5.876\",\"a\":\"79366.10\",\"A\":\"4.893\",\"T\":1788782262601,\"E\":1788782262601,\"st\":1}}"}
{"receive_ns":1788782262516350000,"stream":"btcusdt@trade","event_type":"trade","event_time_ms":1788782262601,"raw_json":"{\"stream\":\"btcusdt@trade\",\"data\":{\"e\":\"trade\",\"E\":1788782262601,\"T\":1788782262601,\"s\":\"BTCUSDT\",\"t\":8057739783,\"p\":\"79366.00\",\"q\":\"0.002\",\"X\":\"MARKET\",\"m\":true,\"st\":1}}"}
{"receive_ns":1788782262535937000,"stream":"btcusdt@bookTicker","event_type":"bookTicker","event_time_ms":1788782262622,"raw_json":"{\"stream\":\"btcusdt@bookTicker\",\"data\":{\"e\":\"bookTicker\",\"u\":11496348105801,\"s\":\"BTCUSDT\",\"ps\":\"BTCUSDT\",\"b\":\"79366.00\",\"B\":\"5.876\",\"a\":\"79366.10\",\"A\":\"4.943\",\"T\":1788782262622,\"E\":1788782262622,\"st\":1}}"}
{"receive_ns":1788782262536868000,"stream":"btcusdt@bookTicker","event_type":"bookTicker","event_time_ms":1788782262622,"raw_json":"{\"stream\":\"btcusdt@bookTicker\",\"data\":{\"e\":\"bookTicker\",\"u\":11496348105839,\"s\":\"BTCUSDT\",\"ps\":\"BTCUSDT\",\"b\":\"79366.00\",\"B\":\"5.166\",\"a\":\"79366.10\",\"A\":\"4.943\",\"T\":1788782262622,\"E\":1788782262622,\"st\":1}}"}
{"receive_ns":1788782262539971000,"stream":"btcusdt@bookTicker","event_type":"bookTicker","event_time_ms":1788782262623,"raw_json":"{\"stream\":\"btcusdt@bookTicker\",\"data\":{\"e\":\"bookTicker\",\"u\":11496348105908,\"s\":\"BTCUSDT\",\"ps\":\"BTCUSDT\",\"b\":\"79366.00\",\"B\":\"5.166\",\"a\":\"79366.10\",\"A\":\"5.653\",\"T\":1788782262623,\"E\":1788782262623,\"st\":1}}"}
{"receive_ns":1788782262540395000,"stream":"btcusdt@bookTicker","event_type":"bookTicker","event_time_ms":1788782262623,"raw_json":"{\"stream\":\"btcusdt@bookTicker\",\"data\":{\"e\":\"bookTicker\",\"u\":11496348105981,\"s\":\"BTCUSDT\",\"ps\":\"BTCUSDT\",\"b\":\"79366.00\",\"B\":\"5.166\",\"a\":\"79366.10\",\"A\":\"5.651\",\"T\":1788782262623,\"E\":1788782262623,\"st\":1}}"}
{"receive_ns":1788782262540674000,"stream":"btcusdt@bookTicker","event_type":"bookTicker","event_time_ms":1788782262623,"raw_json":"{\"stream\":\"btcusdt@bookTicker\",\"data\":{\"e\":\"bookTicker\",\"u\":11496348105987,\"s\":\"BTCUSDT\",\"ps\":\"BTCUSDT\",\"b\":\"79366.00\",\"B\":\"5.165\",\"a\":\"79366.10\",\"A\":\"5.651\",\"T\":1788782262623,\"E\":1788782262623,\"st\":1}}"}
{"receive_ns":1788782262540877000,"stream":"btcusdt@bookTicker","event_type":"bookTicker","event_time_ms":1788782262623,"raw_json":"{\"stream\":\"btcusdt@bookTicker\",\"data\":{\"e\":\"bookTicker\",\"u\":11496348105993,\"s\":\"BTCUSDT\",\"ps\":\"BTCUSDT\",\"b\":\"79366.00\",\"B\":\"4.925\",\"a\":\"79366.10\",\"A\":\"5.651\",\"T\":1788782262623,\"E\":1788782262623,\"st\":1}}"}
{"receive_ns":1788782262541061000,"stream":"btcusdt@bookTicker","event_type":"bookTicker","event_time_ms":1788782262623,"raw_json":"{\"stream\":\"btcusdt@bookTicker\",\"data\":{\"e\":\"bookTicker\",\"u\":11496348106006,\"s\":\"BTCUSDT\",\"ps\":\"BTCUSDT\",\"b\":\"79366.00\",\"B\":\"4.519\",\"a\":\"79366.10\",\"A\":\"5.651\",\"T\":1788782262623,\"E\":1788782262623,\"st\":1}}"}
{"receive_ns":1788782262541334000,"stream":"btcusdt@bookTicker","event_type":"bookTicker","event_time_ms":1788782262624,"raw_json":"{\"stream\":\"btcusdt@bookTicker\",\"data\":{\"e\":\"bookTicker\",\"u\":11496348106142,\"s\":\"BTCUSDT\",\"ps\":\"BTCUSDT\",\"b\":\"79366.00\",\"B\":\"4.520\",\"a\":\"79366.10\",\"A\":\"5.651\",\"T\":1788782262623,\"E\":1788782262624,\"st\":1}}"}
{"receive_ns":1788782262541535000,"stream":"btcusdt@bookTicker","event_type":"bookTicker","event_time_ms":1788782262624,"raw_json":"{\"stream\":\"btcusdt@bookTicker\",\"data\":{\"e\":\"bookTicker\",\"u\":11496348106143,\"s\":\"BTCUSDT\",\"ps\":\"BTCUSDT\",\"b\":\"79366.00\",\"B\":\"4.519\",\"a\":\"79366.10\",\"A\":\"5.651\",\"T\":1788782262623,\"E\":1788782262624,\"st\":1}}"}
{"receive_ns":1788782262541720000,"stream":"btcusdt@bookTicker","event_type":"bookTicker","event_time_ms":1788782262624,"raw_json":"{\"stream\":\"btcusdt@bookTicker\",\"data\":{\"e\":\"bookTicker\",\"u\":11496348106171,\"s\":\"BTCUSDT\",\"ps\":\"BTCUSDT\",\"b\":\"79366.00\",\"B\":\"4.132\",\"a\":\"79366.10\",\"A\":\"5.651\",\"T\":1788782262624,\"E\":1788782262624,\"st\":1}}"}
{"receive_ns":1788782262542031000,"stream":"btcusdt@bookTicker","event_type":"bookTicker","event_time_ms":1788782262624,"raw_json":"{\"stream\":\"btcusdt@bookTicker\",\"data\":{\"e\":\"bookTicker\",\"u\":11496348106196,\"s\":\"BTCUSDT\",\"ps\":\"BTCUSDT\",\"b\":\"79366.00\",\"B\":\"3.753\",\"a\":\"79366.10\",\"A\":\"5.651\",\"T\":1788782262624,\"E\":1788782262624,\"st\":1}}"}
{"receive_ns":1788782262542268000,"stream":"btcusdt@bookTicker","event_type":"bookTicker","event_time_ms":1788782262624,"raw_json":"{\"stream\":\"btcusdt@bookTicker\",\"data\":{\"e\":\"bookTicker\",\"u\":11496348106199,\"s\":\"BTCUSDT\",\"ps\":\"BTCUSDT\",\"b\":\"79366.00\",\"B\":\"3.327\",\"a\":\"79366.10\",\"A\":\"5.651\",\"T\":1788782262624,\"E\":1788782262624,\"st\":1}}"}
{"receive_ns":1788782262542490000,"stream":"btcusdt@bookTicker","event_type":"bookTicker","event_time_ms":1788782262624,"raw_json":"{\"stream\":\"btcusdt@bookTicker\",\"data\":{\"e\":\"bookTicker\",\"u\":11496348106282,\"s\":\"BTCUSDT\",\"ps\":\"BTCUSDT\",\"b\":\"79366.00\",\"B\":\"3.327\",\"a\":\"79366.10\",\"A\":\"5.653\",\"T\":1788782262624,\"E\":1788782262624,\"st\":1}}"}
{"receive_ns":1788782262542667000,"stream":"btcusdt@bookTicker","event_type":"bookTicker","event_time_ms":1788782262624,"raw_json":"{\"stream\":\"btcusdt@bookTicker\",\"data\":{\"e\":\"bookTicker\",\"u\":11496348106321,\"s\":\"BTCUSDT\",\"ps\":\"BTCUSDT\",\"b\":\"79366.00\",\"B\":\"3.327\",\"a\":\"79366.10\",\"A\":\"5.654\",\"T\":1788782262624,\"E\":1788782262624,\"st\":1}}"}
{"receive_ns":1788782262542859000,"stream":"btcusdt@bookTicker","event_type":"bookTicker","event_time_ms":1788782262627,"raw_json":"{\"stream\":\"btcusdt@bookTicker\",\"data\":{\"e\":\"bookTicker\",\"u\":11496348107905,\"s\":\"BTCUSDT\",\"ps\":\"BTCUSDT\",\"b\":\"79366.00\",\"B\":\"3.327\",\"a\":\"79366.10\",\"A\":\"6.754\",\"T\":1788782262626,\"E\":1788782262627,\"st\":1}}"}
{"receive_ns":1788782262543053000,"stream":"btcusdt@bookTicker","event_type":"bookTicker","event_time_ms":1788782262627,"raw_json":"{\"stream\":\"btcusdt@bookTicker\",\"data\":{\"e\":\"bookTicker\",\"u\":11496348108235,\"s\":\"BTCUSDT\",\"ps\":\"BTCUSDT\",\"b\":\"79366.00\",\"B\":\"3.289\",\"a\":\"79366.10\",\"A\":\"6.754\",\"T\":1788782262627,\"E\":1788782262627,\"st\":1}}"}
{"receive_ns":1788782262543255000,"stream":"btcusdt@bookTicker","event_type":"bookTicker","event_time_ms":1788782262628,"raw_json":"{\"stream\":\"btcusdt@bookTicker\",\"data\":{\"e\":\"bookTicker\",\"u\":11496348109370,\"s\":\"BTCUSDT\",\"ps\":\"BTCUSDT\",\"b\":\"79366.00\",\"B\":\"3.289\",\"a\":\"79366.10\",\"A\":\"6.758\",\"T\":1788782262628,\"E\":1788782262628,\"st\":1}}"}
{"receive_ns":1788782262543447000,"stream":"btcusdt@bookTicker","event_type":"bookTicker","event_time_ms":1788782262628,"raw_json":"{\"stream\":\"btcusdt@bookTicker\",\"data\":{\"e\":\"bookTicker\",\"u\":11496348109590,\"s\":\"BTCUSDT\",\"ps\":\"BTCUSDT\",\"b\":\"79366.00\",\"B\":\"3.289\",\"a\":\"79366.10\",\"A\":\"6.759\",\"T\":1788782262628,\"E\":1788782262628,\"st\":1}}"}
{"receive_ns":1788782262543635000,"stream":"btcusdt@bookTicker","event_type":"bookTicker","event_time_ms":1788782262629,"raw_json":"{\"stream\":\"btcusdt@bookTicker\",\"data\":{\"e\":\"bookTicker\",\"u\":11496348110665,\"s\":\"BTCUSDT\",\"ps\":\"BTCUSDT\",\"b\":\"79366.00\",\"B\":\"3.289\",\"a\":\"79366.10\",\"A\":\"6.763\",\"T\":1788782262629,\"E\":1788782262629,\"st\":1}}"}
{"receive_ns":1788782262543887000,"stream":"btcusdt@bookTicker","event_type":"bookTicker","event_time_ms":1788782262630,"raw_json":"{\"stream\":\"btcusdt@bookTicker\",\"data\":{\"e\":\"bookTicker\",\"u\":11496348111514,\"s\":\"BTCUSDT\",\"ps\":\"BTCUSDT\",\"b\":\"79366.00\",\"B\":\"3.289\",\"a\":\"79366.10\",\"A\":\"6.759\",\"T\":1788782262630,\"E\":1788782262630,\"st\":1}}"}
{"receive_ns":1788782262544610000,"stream":"btcusdt@bookTicker","event_type":"bookTicker","event_time_ms":1788782262630,"raw_json":"{\"stream\":\"btcusdt@bookTicker\",\"data\":{\"e\":\"bookTicker\",\"u\":11496348111790,\"s\":\"BTCUSDT\",\"ps\":\"BTCUSDT\",\"b\":\"79366.00\",\"B\":\"3.289\",\"a\":\"79366.10\",\"A\":\"6.761\",\"T\":1788782262630,\"E\":1788782262630,\"st\":1}}"}
{"receive_ns":1788782262545678000,"stream":"btcusdt@bookTicker","event_type":"bookTicker","event_time_ms":1788782262630,"raw_json":"{\"stream\":\"btcusdt@bookTicker\",\"data\":{\"e\":\"bookTicker\",\"u\":11496348112042,\"s\":\"BTCUSDT\",\"ps\":\"BTCUSDT\",\"b\":\"79366.00\",\"B\":\"3.289\",\"a\":\"79366.10\",\"A\":\"7.078\",\"T\":1788782262630,\"E\":1788782262630,\"st\":1}}"}
{"receive_ns":1788782262545889000,"stream":"btcusdt@bookTicker","event_type":"bookTicker","event_time_ms":1788782262630,"raw_json":"{\"stream\":\"btcusdt@bookTicker\",\"data\":{\"e\":\"bookTicker\",\"u\":11496348112048,\"s\":\"BTCUSDT\",\"ps\":\"BTCUSDT\",\"b\":\"79366.00\",\"B\":\"3.289\",\"a\":\"79366.10\",\"A\":\"7.318\",\"T\":1788782262630,\"E\":1788782262630,\"st\":1}}"}
{"receive_ns":1788782262546088000,"stream":"btcusdt@bookTicker","event_type":"bookTicker","event_time_ms":1788782262631,"raw_json":"{\"stream\":\"btcusdt@bookTicker\",\"data\":{\"e\":\"bookTicker\",\"u\":11496348112263,\"s\":\"BTCUSDT\",\"ps\":\"BTCUSDT\",\"b\":\"79366.00\",\"B\":\"3.289\",\"a\":\"79366.10\",\"A\":\"7.322\",\"T\":1788782262630,\"E\":1788782262631,\"st\":1}}"}
{"receive_ns":1788782262546260000,"stream":"btcusdt@bookTicker","event_type":"bookTicker","event_time_ms":1788782262631,"raw_json":"{\"stream\":\"btcusdt@bookTicker\",\"data\":{\"e\":\"bookTicker\",\"u\":11496348112365,\"s\":\"BTCUSDT\",\"ps\":\"BTCUSDT\",\"b\":\"79366.00\",\"B\":\"3.289\",\"a\":\"79366.10\",\"A\":\"7.561\",\"T\":1788782262631,\"E\":1788782262631,\"st\":1}}"}
{"receive_ns":1788782262546503000,"stream":"btcusdt@bookTicker","event_type":"bookTicker","event_time_ms":1788782262632,"raw_json":"{\"stream\":\"btcusdt@bookTicker\",\"data\":{\"e\":\"bookTicker\",\"u\":11496348113058,\"s\":\"BTCUSDT\",\"ps\":\"BTCUSDT\",\"b\":\"79366.00\",\"B\":\"3.289\",\"a\":\"79366.10\",\"A\":\"7.570\",\"T\":1788782262631,\"E\":1788782262632,\"st\":1}}"}
{"receive_ns":1788782262547178000,"stream":"btcusdt@bookTicker","event_type":"bookTicker","event_time_ms":1788782262633,"raw_json":"{\"stream\":\"btcusdt@bookTicker\",\"data\":{\"e\":\"bookTicker\",\"u\":11496348114282,\"s\":\"BTCUSDT\",\"ps\":\"BTCUSDT\",\"b\":\"79366.00\",\"B\":\"3.289\",\"a\":\"79366.10\",\"A\":\"7.566\",\"T\":1788782262632,\"E\":1788782262633,\"st\":1}}"}
{"receive_ns":1788782262548324000,"stream":"btcusdt@bookTicker","event_type":"bookTicker","event_time_ms":1788782262633,"raw_json":"{\"stream\":\"btcusdt@bookTicker\",\"data\":{\"e\":\"bookTicker\",\"u\":11496348114511,\"s\":\"BTCUSDT\",\"ps\":\"BTCUSDT\",\"b\":\"79366.00\",\"B\":\"3.289\",\"a\":\"79366.10\",\"A\":\"7.570\",\"T\":1788782262633,\"E\":1788782262633,\"st\":1}}"}
{"receive_ns":1788782262548541000,"stream":"btcusdt@bookTicker","event_type":"bookTicker","event_time_ms":1788782262633,"raw_json":"{\"stream\":\"btcusdt@bookTicker\",\"data\":{\"e\":\"bookTicker\",\"u\":11496348114544,\"s\":\"BTCUSDT\",\"ps\":\"BTCUSDT\",\"b\":\"79366.00\",\"B\":\"3.289\",\"a\":\"79366.10\",\"A\":\"7.999\",\"T\":1788782262633,\"E\":1788782262633,\"st\":1}}"}
{"receive_ns":1788782262548723000,"stream":"btcusdt@bookTicker","event_type":"bookTicker","event_time_ms":1788782262633,"raw_json":"{\"stream\":\"btcusdt@bookTicker\",\"data\":{\"e\":\"bookTicker\",\"u\":11496348114621,\"s\":\"BTCUSDT\",\"ps\":\"BTCUSDT\",\"b\":\"79366.00\",\"B\":\"3.289\",\"a\":\"79366.10\",\"A\":\"8.003\",\"T\":1788782262633,\"E\":1788782262633,\"st\":1}}"}
{"receive_ns":1788782262562129000,"stream":"btcusdt@bookTicker","event_type":"bookTicker","event_time_ms":1788782262633,"raw_json":"{\"stream\":\"btcusdt@bookTicker\",\"data\":{\"e\":\"bookTicker\",\"u\":11496348114673,\"s\":\"BTCUSDT\",\"ps\":\"BTCUSDT\",\"b\":\"79366.00\",\"B\":\"3.289\",\"a\":\"79366.10\",\"A\":\"8.419\",\"T\":1788782262633,\"E\":1788782262633,\"st\":1}}"}
{"receive_ns":1788782262562369000,"stream":"btcusdt@bookTicker","event_type":"bookTicker","event_time_ms":1788782262633,"raw_json":"{\"stream\":\"btcusdt@bookTicker\",\"data\":{\"e\":\"bookTicker\",\"u\":11496348114676,\"s\":\"BTCUSDT\",\"ps\":\"BTCUSDT\",\"b\":\"79366.00\",\"B\":\"3.289\",\"a\":\"79366.10\",\"A\":\"8.825\",\"T\":1788782262633,\"E\":1788782262633,\"st\":1}}"}
{"receive_ns":1788782262562548000,"stream":"btcusdt@bookTicker","event_type":"bookTicker","event_time_ms":1788782262633,"raw_json":"{\"stream\":\"btcusdt@bookTicker\",\"data\":{\"e\":\"bookTicker\",\"u\":11496348114688,\"s\":\"BTCUSDT\",\"ps\":\"BTCUSDT\",\"b\":\"79366.00\",\"B\":\"3.058\",\"a\":\"79366.10\",\"A\":\"8.825\",\"T\":1788782262633,\"E\":1788782262633,\"st\":1}}"}
{"receive_ns":1788782262562715000,"stream":"btcusdt@bookTicker","event_type":"bookTicker","event_time_ms":1788782262633,"raw_json":"{\"stream\":\"btcusdt@bookTicker\",\"data\":{\"e\":\"bookTicker\",\"u\":11496348114875,\"s\":\"BTCUSDT\",\"ps\":\"BTCUSDT\",\"b\":\"79366.00\",\"B\":\"3.058\",\"a\":\"79366.10\",\"A\":\"9.220\",\"T\":1788782262633,\"E\":1788782262633,\"st\":1}}"}
{"receive_ns":1788782262562880000,"stream":"btcusdt@bookTicker","event_type":"bookTicker","event_time_ms":1788782262633,"raw_json":"{\"stream\":\"btcusdt@bookTicker\",\"data\":{\"e\":\"bookTicker\",\"u\":11496348114887,\"s\":\"BTCUSDT\",\"ps\":\"BTCUSDT\",\"b\":\"79366.00\",\"B\":\"3.058\",\"a\":\"79366.10\",\"A\":\"9.604\",\"T\":1788782262633,\"E\":1788782262633,\"st\":1}}"}
{"receive_ns":1788782262572356000,"stream":"btcusdt@trade","event_type":"trade","event_time_ms":1788782262633,"raw_json":"{\"stream\":\"btcusdt@trade\",\"data\":{\"e\":\"trade\",\"E\":1788782262633,\"T\":1788782262633,\"s\":\"BTCUSDT\",\"t\":8057739784,\"p\":\"79366.00\",\"q\":\"0.231\",\"X\":\"MARKET\",\"m\":true,\"st\":1}}"}
{"receive_ns":1788782262572750000,"stream":"btcusdt@bookTicker","event_type":"bookTicker","event_time_ms":1788782262634,"raw_json":"{\"stream\":\"btcusdt@bookTicker\",\"data\":{\"e\":\"bookTicker\",\"u\":11496348115200,\"s\":\"BTCUSDT\",\"ps\":\"BTCUSDT\",\"b\":\"79366.00\",\"B\":\"3.058\",\"a\":\"79366.10\",\"A\":\"10.684\",\"T\":1788782262633,\"E\":1788782262634,\"st\":1}}"}
{"receive_ns":1788782262572967000,"stream":"btcusdt@bookTicker","event_type":"bookTicker","event_time_ms":1788782262634,"raw_json":"{\"stream\":\"btcusdt@bookTicker\",\"data\":{\"e\":\"bookTicker\",\"u\":11496348115215,\"s\":\"BTCUSDT\",\"ps\":\"BTCUSDT\",\"b\":\"79366.00\",\"B\":\"3.058\",\"a\":\"79366.10\",\"A\":\"11.764\",\"T\":1788782262633,\"E\":1788782262634,\"st\":1}}"}
{"receive_ns":1788782262573164000,"stream":"btcusdt@bookTicker","event_type":"bookTicker","event_time_ms":1788782262634,"raw_json":"{\"stream\":\"btcusdt@bookTicker\",\"data\":{\"e\":\"bookTicker\",\"u\":11496348115221,\"s\":\"BTCUSDT\",\"ps\":\"BTCUSDT\",\"b\":\"79366.00\",\"B\":\"3.058\",\"a\":\"79366.10\",\"A\":\"10.684\",\"T\":1788782262633,\"E\":1788782262634,\"st\":1}}"}
{"receive_ns":1788782262573348000,"stream":"btcusdt@bookTicker","event_type":"bookTicker","event_time_ms":1788782262634,"raw_json":"{\"stream\":\"btcusdt@bookTicker\",\"data\":{\"e\":\"bookTicker\",\"u\":11496348115392,\"s\":\"BTCUSDT\",\"ps\":\"BTCUSDT\",\"b\":\"79366.00\",\"B\":\"3.058\",\"a\":\"79366.10\",\"A\":\"10.685\",\"T\":1788782262633,\"E\":1788782262634,\"st\":1}}"}
{"receive_ns":1788782262573533000,"stream":"btcusdt@bookTicker","event_type":"bookTicker","event_time_ms":1788782262634,"raw_json":"{\"stream\":\"btcusdt@bookTicker\",\"data\":{\"e\":\"bookTicker\",\"u\":11496348115481,\"s\":\"BTCUSDT\",\"ps\":\"BTCUSDT\",\"b\":\"79366.00\",\"B\":\"2.295\",\"a\":\"79366.10\",\"A\":\"10.685\",\"T\":1788782262634,\"E\":1788782262634,\"st\":1}}"}
{"receive_ns":1788782262573712000,"stream":"btcusdt@bookTicker","event_type":"bookTicker","event_time_ms":1788782262634,"raw_json":"{\"stream\":\"btcusdt@bookTicker\",\"data\":{\"e\":\"bookTicker\",\"u\":11496348115524,\"s\":\"BTCUSDT\",\"ps\":\"BTCUSDT\",\"b\":\"79366.00\",\"B\":\"1.686\",\"a\":\"79366.10\",\"A\":\"10.685\",\"T\":1788782262634,\"E\":1788782262634,\"st\":1}}"}
{"receive_ns":1788782262573913000,"stream":"btcusdt@bookTicker","event_type":"bookTicker","event_time_ms":1788782262634,"raw_json":"{\"stream\":\"btcusdt@bookTicker\",\"data\":{\"e\":\"bookTicker\",\"u\":11496348115560,\"s\":\"BTCUSDT\",\"ps\":\"BTCUSDT\",\"b\":\"79366.00\",\"B\":\"1.686\",\"a\":\"79366.10\",\"A\":\"11.069\",\"T\":1788782262634,\"E\":1788782262634,\"st\":1}}"}
{"receive_ns":1788782262574084000,"stream":"btcusdt@bookTicker","event_type":"bookTicker","event_time_ms":1788782262634,"raw_json":"{\"stream\":\"btcusdt@bookTicker\",\"data\":{\"e\":\"bookTicker\",\"u\":11496348115597,\"s\":\"BTCUSDT\",\"ps\":\"BTCUSDT\",\"b\":\"79366.00\",\"B\":\"1.686\",\"a\":\"79366.10\",\"A\":\"11.067\",\"T\":1788782262634,\"E\":1788782262634,\"st\":1}}"}
{"receive_ns":1788782262574251000,"stream":"btcusdt@bookTicker","event_type":"bookTicker","event_time_ms":1788782262634,"raw_json":"{\"stream\":\"btcusdt@bookTicker\",\"data\":{\"e\":\"bookTicker\",\"u\":11496348115600,\"s\":\"BTCUSDT\",\"ps\":\"BTCUSDT\",\"b\":\"79366.00\",\"B\":\"1.686\",\"a\":\"79366.10\",\"A\":\"11.497\",\"T\":1788782262634,\"E\":1788782262634,\"st\":1}}"}
{"receive_ns":1788782262574414000,"stream":"btcusdt@trade","event_type":"trade","event_time_ms":1788782262634,"raw_json":"{\"stream\":\"btcusdt@trade\",\"data\":{\"e\":\"trade\",\"E\":1788782262634,\"T\":1788782262634,\"s\":\"BTCUSDT\",\"t\":8057739785,\"p\":\"79366.00\",\"q\":\"0.763\",\"X\":\"MARKET\",\"m\":true,\"st\":1}}"}
{"receive_ns":1788782262574601000,"stream":"btcusdt@trade","event_type":"trade","event_time_ms":1788782262634,"raw_json":"{\"stream\":\"btcusdt@trade\",\"data\":{\"e\":\"trade\",\"E\":1788782262634,\"T\":1788782262634,\"s\":\"BTCUSDT\",\"t\":8057739786,\"p\":\"79366.00\",\"q\":\"0.609\",\"X\":\"MARKET\",\"m\":true,\"st\":1}}"}
{"receive_ns":1788782262574827000,"stream":"btcusdt@bookTicker","event_type":"bookTicker","event_time_ms":1788782262634,"raw_json":"{\"stream\":\"btcusdt@bookTicker\",\"data\":{\"e\":\"bookTicker\",\"u\":11496348116091,\"s\":\"BTCUSDT\",\"ps\":\"BTCUSDT\",\"b\":\"79366.00\",\"B\":\"1.686\",\"a\":\"79366.10\",\"A\":\"11.855\",\"T\":1788782262634,\"E\":1788782262634,\"st\":1}}"}
{"receive_ns":1788782262575051000,"stream":"btcusdt@bookTicker","event_type":"bookTicker","event_time_ms":1788782262634,"raw_json":"{\"stream\":\"btcusdt@bookTicker\",\"data\":{\"e\":\"bookTicker\",\"u\":11496348116101,\"s\":\"BTCUSDT\",\"ps\":\"BTCUSDT\",\"b\":\"79366.00\",\"B\":\"1.686\",\"a\":\"79366.10\",\"A\":\"11.851\",\"T\":1788782262634,\"E\":1788782262634,\"st\":1}}"}
{"receive_ns":1788782262575246000,"stream":"btcusdt@bookTicker","event_type":"bookTicker","event_time_ms":1788782262635,"raw_json":"{\"stream\":\"btcusdt@bookTicker\",\"data\":{\"e\":\"bookTicker\",\"u\":11496348116236,\"s\":\"BTCUSDT\",\"ps\":\"BTCUSDT\",\"b\":\"79366.00\",\"B\":\"1.686\",\"a\":\"79366.10\",\"A\":\"11.847\",\"T\":1788782262634,\"E\":1788782262635,\"st\":1}}"}
{"receive_ns":1788782262575418000,"stream":"btcusdt@bookTicker","event_type":"bookTicker","event_time_ms":1788782262635,"raw_json":"{\"stream\":\"btcusdt@bookTicker\",\"data\":{\"e\":\"bookTicker\",\"u\":11496348116267,\"s\":\"BTCUSDT\",\"ps\":\"BTCUSDT\",\"b\":\"79366.00\",\"B\":\"1.686\",\"a\":\"79366.10\",\"A\":\"12.201\",\"T\":1788782262634,\"E\":1788782262635,\"st\":1}}"}
{"receive_ns":1788782262575589000,"stream":"btcusdt@bookTicker","event_type":"bookTicker","event_time_ms":1788782262635,"raw_json":"{\"stream\":\"btcusdt@bookTicker\",\"data\":{\"e\":\"bookTicker\",\"u\":11496348116516,\"s\":\"BTCUSDT\",\"ps\":\"BTCUSDT\",\"b\":\"79366.00\",\"B\":\"1.686\",\"a\":\"79366.10\",\"A\":\"12.197\",\"T\":1788782262635,\"E\":1788782262635,\"st\":1}}"}
{"receive_ns":1788782262575762000,"stream":"btcusdt@bookTicker","event_type":"bookTicker","event_time_ms":1788782262635,"raw_json":"{\"stream\":\"btcusdt@bookTicker\",\"data\":{\"e\":\"bookTicker\",\"u\":11496348116693,\"s\":\"BTCUSDT\",\"ps\":\"BTCUSDT\",\"b\":\"79366.00\",\"B\":\"1.686\",\"a\":\"79366.10\",\"A\":\"12.201\",\"T\":1788782262635,\"E\":1788782262635,\"st\":1}}"}
{"receive_ns":1788782262575935000,"stream":"btcusdt@bookTicker","event_type":"bookTicker","event_time_ms":1788782262635,"raw_json":"{\"stream\":\"btcusdt@bookTicker\",\"data\":{\"e\":\"bookTicker\",\"u\":11496348116871,\"s\":\"BTCUSDT\",\"ps\":\"BTCUSDT\",\"b\":\"79366.00\",\"B\":\"1.686\",\"a\":\"79366.10\",\"A\":\"12.435\",\"T\":1788782262635,\"E\":1788782262635,\"st\":1}}"}
{"receive_ns":1788782262576112000,"stream":"btcusdt@bookTicker","event_type":"bookTicker","event_time_ms":1788782262635,"raw_json":"{\"stream\":\"btcusdt@bookTicker\",\"data\":{\"e\":\"bookTicker\",\"u\":11496348116903,\"s\":\"BTCUSDT\",\"ps\":\"BTCUSDT\",\"b\":\"79366.00\",\"B\":\"1.686\",\"a\":\"79366.10\",\"A\":\"12.849\",\"T\":1788782262635,\"E\":1788782262635,\"st\":1}}"}
{"receive_ns":1788782262576311000,"stream":"btcusdt@bookTicker","event_type":"bookTicker","event_time_ms":1788782262635,"raw_json":"{\"stream\":\"btcusdt@bookTicker\",\"data\":{\"e\":\"bookTicker\",\"u\":11496348116908,\"s\":\"BTCUSDT\",\"ps\":\"BTCUSDT\",\"b\":\"79366.00\",\"B\":\"1.686\",\"a\":\"79366.10\",\"A\":\"13.256\",\"T\":1788782262635,\"E\":1788782262635,\"st\":1}}"}
{"receive_ns":1788782262576564000,"stream":"btcusdt@bookTicker","event_type":"bookTicker","event_time_ms":1788782262635,"raw_json":"{\"stream\":\"btcusdt@bookTicker\",\"data\":{\"e\":\"bookTicker\",\"u\":11496348116913,\"s\":\"BTCUSDT\",\"ps\":\"BTCUSDT\",\"b\":\"79366.00\",\"B\":\"0.740\",\"a\":\"79366.10\",\"A\":\"13.256\",\"T\":1788782262635,\"E\":1788782262635,\"st\":1}}"}
{"receive_ns":1788782262576763000,"stream":"btcusdt@bookTicker","event_type":"bookTicker","event_time_ms":1788782262635,"raw_json":"{\"stream\":\"btcusdt@bookTicker\",\"data\":{\"e\":\"bookTicker\",\"u\":11496348116917,\"s\":\"BTCUSDT\",\"ps\":\"BTCUSDT\",\"b\":\"79366.00\",\"B\":\"0.740\",\"a\":\"79366.10\",\"A\":\"13.384\",\"T\":1788782262635,\"E\":1788782262635,\"st\":1}}"}
{"receive_ns":1788782262576929000,"stream":"btcusdt@trade","event_type":"trade","event_time_ms":1788782262635,"raw_json":"{\"stream\":\"btcusdt@trade\",\"data\":{\"e\":\"trade\",\"E\":1788782262635,\"T\":1788782262635,\"s\":\"BTCUSDT\",\"t\":8057739787,\"p\":\"79366.00\",\"q\":\"0.946\",\"X\":\"MARKET\",\"m\":true,\"st\":1}}"}
{"receive_ns":1788782262577162000,"stream":"btcusdt@bookTicker","event_type":"bookTicker","event_time_ms":1788782262635,"raw_json":"{\"stream\":\"btcusdt@bookTicker\",\"data\":{\"e\":\"bookTicker\",\"u\":11496348117044,\"s\":\"BTCUSDT\",\"ps\":\"BTCUSDT\",\"b\":\"79366.00\",\"B\":\"0.740\",\"a\":\"79366.10\",\"A\":\"13.793\",\"T\":1788782262635,\"E\":1788782262635,\"st\":1}}"}
{"receive_ns":1788782262577356000,"stream":"btcusdt@bookTicker","event_type":"bookTicker","event_time_ms":1788782262635,"raw_json":"{\"stream\":\"btcusdt@bookTicker\",\"data\":{\"e\":\"bookTicker\",\"u\":11496348117114,\"s\":\"BTCUSDT\",\"ps\":\"BTCUSDT\",\"b\":\"79366.00\",\"B\":\"0.740\",\"a\":\"79366.10\",\"A\":\"13.794\",\"T\":1788782262635,\"E\":1788782262635,\"st\":1}}"}
{"receive_ns":1788782262577526000,"stream":"btcusdt@bookTicker","event_type":"bookTicker","event_time_ms":1788782262635,"raw_json":"{\"stream\":\"btcusdt@bookTicker\",\"data\":{\"e\":\"bookTicker\",\"u\":11496348117116,\"s\":\"BTCUSDT\",\"ps\":\"BTCUSDT\",\"b\":\"79366.00\",\"B\":\"0.740\",\"a\":\"79366.10\",\"A\":\"14.034\",\"T\":1788782262635,\"E\":1788782262635,\"st\":1}}"}
{"receive_ns":1788782262577742000,"stream":"btcusdt@bookTicker","event_type":"bookTicker","event_time_ms":1788782262636,"raw_json":"{\"stream\":\"btcusdt@bookTicker\",\"data\":{\"e\":\"bookTicker\",\"u\":11496348117207,\"s\":\"BTCUSDT\",\"ps\":\"BTCUSDT\",\"b\":\"79366.00\",\"B\":\"0.740\",\"a\":\"79366.10\",\"A\":\"14.399\",\"T\":1788782262635,\"E\":1788782262636,\"st\":1}}"}
{"receive_ns":1788782262577928000,"stream":"btcusdt@bookTicker","event_type":"bookTicker","event_time_ms":1788782262636,"raw_json":"{\"stream\":\"btcusdt@bookTicker\",\"data\":{\"e\":\"bookTicker\",\"u\":11496348117227,\"s\":\"BTCUSDT\",\"ps\":\"BTCUSDT\",\"b\":\"79366.00\",\"B\":\"0.740\",\"a\":\"79366.10\",\"A\":\"14.159\",\"T\":1788782262635,\"E\":1788782262636,\"st\":1}}"}
{"receive_ns":1788782262578102000,"stream":"btcusdt@bookTicker","event_type":"bookTicker","event_time_ms":1788782262636,"raw_json":"{\"stream\":\"btcusdt@bookTicker\",\"data\":{\"e\":\"bookTicker\",\"u\":11496348117232,\"s\":\"BTCUSDT\",\"ps\":\"BTCUSDT\",\"b\":\"79366.00\",\"B\":\"0.740\",\"a\":\"79366.10\",\"A\":\"14.399\",\"T\":1788782262635,\"E\":1788782262636,\"st\":1}}"}
{"receive_ns":1788782262578274000,"stream":"btcusdt@bookTicker","event_type":"bookTicker","event_time_ms":1788782262636,"raw_json":"{\"stream\":\"btcusdt@bookTicker\",\"data\":{\"e\":\"bookTicker\",\"u\":11496348117353,\"s\":\"BTCUSDT\",\"ps\":\"BTCUSDT\",\"b\":\"79366.00\",\"B\":\"0.740\",\"a\":\"79366.10\",\"A\":\"13.319\",\"T\":1788782262636,\"E\":1788782262636,\"st\":1}}"}
{"receive_ns":1788782262578451000,"stream":"btcusdt@bookTicker","event_type":"bookTicker","event_time_ms":1788782262636,"raw_json":"{\"stream\":\"btcusdt@bookTicker\",\"data\":{\"e\":\"bookTicker\",\"u\":11496348117447,\"s\":\"BTCUSDT\",\"ps\":\"BTCUSDT\",\"b\":\"79366.00\",\"B\":\"0.740\",\"a\":\"79366.10\",\"A\":\"13.321\",\"T\":1788782262636,\"E\":1788782262636,\"st\":1}}"}
{"receive_ns":1788782262578622000,"stream":"btcusdt@bookTicker","event_type":"bookTicker","event_time_ms":1788782262636,"raw_json":"{\"stream\":\"btcusdt@bookTicker\",\"data\":{\"e\":\"bookTicker\",\"u\":11496348117503,\"s\":\"BTCUSDT\",\"ps\":\"BTCUSDT\",\"b\":\"79366.00\",\"B\":\"0.740\",\"a\":\"79366.10\",\"A\":\"13.325\",\"T\":1788782262636,\"E\":1788782262636,\"st\":1}}"}
{"receive_ns":1788782262578788000,"stream":"btcusdt@trade","event_type":"trade","event_time_ms":1788782262636,"raw_json":"{\"stream\":\"btcusdt@trade\",\"data\":{\"e\":\"trade\",\"E\":1788782262636,\"T\":1788782262636,\"s\":\"BTCUSDT\",\"t\":8057739788,\"p\":\"79366.00\",\"q\":\"0.286\",\"X\":\"MARKET\",\"m\":true,\"st\":1}}"}
{"receive_ns":1788782262578970000,"stream":"btcusdt@trade","event_type":"trade","event_time_ms":1788782262636,"raw_json":"{\"stream\":\"btcusdt@trade\",\"data\":{\"e\":\"trade\",\"E\":1788782262636,\"T\":1788782262636,\"s\":\"BTCUSDT\",\"t\":8057739789,\"p\":\"79366.00\",\"q\":\"0.010\",\"X\":\"MARKET\",\"m\":true,\"st\":1}}"}
{"receive_ns":1788782262579122000,"stream":"btcusdt@trade","event_type":"trade","event_time_ms":1788782262636,"raw_json":"{\"stream\":\"btcusdt@trade\",\"data\":{\"e\":\"trade\",\"E\":1788782262636,\"T\":1788782262636,\"s\":\"BTCUSDT\",\"t\":8057739790,\"p\":\"79366.00\",\"q\":\"0.023\",\"X\":\"MARKET\",\"m\":true,\"st\":1}}"}
{"receive_ns":1788782262579275000,"stream":"btcusdt@trade","event_type":"trade","event_time_ms":1788782262636,"raw_json":"{\"stream\":\"btcusdt@trade\",\"data\":{\"e\":\"trade\",\"E\":1788782262636,\"T\":1788782262636,\"s\":\"BTCUSDT\",\"t\":8057739791,\"p\":\"79366.00\",\"q\":\"0.012\",\"X\":\"MARKET\",\"m\":true,\"st\":1}}"}
{"receive_ns":1788782262579421000,"stream":"btcusdt@trade","event_type":"trade","event_time_ms":1788782262636,"raw_json":"{\"stream\":\"btcusdt@trade\",\"data\":{\"e\":\"trade\",\"E\":1788782262636,\"T\":1788782262636,\"s\":\"BTCUSDT\",\"t\":8057739792,\"p\":\"79366.00\",\"q\":\"0.002\",\"X\":\"MARKET\",\"m\":true,\"st\":1}}"}
{"receive_ns":1788782262579576000,"stream":"btcusdt@trade","event_type":"trade","event_time_ms":1788782262636,"raw_json":"{\"stream\":\"btcusdt@trade\",\"data\":{\"e\":\"trade\",\"E\":1788782262636,\"T\":1788782262636,\"s\":\"BTCUSDT\",\"t\":8057739793,\"p\":\"79366.00\",\"q\":\"0.002\",\"X\":\"MARKET\",\"m\":true,\"st\":1}}"}
{"receive_ns":1788782262579731000,"stream":"btcusdt@trade","event_type":"trade","event_time_ms":1788782262636,"raw_json":"{\"stream\":\"btcusdt@trade\",\"data\":{\"e\":\"trade\",\"E\":1788782262636,\"T\":1788782262636,\"s\":\"BTCUSDT\",\"t\":8057739794,\"p\":\"79366.00\",\"q\":\"0.013\",\"X\":\"MARKET\",\"m\":true,\"st\":1}}"}
{"receive_ns":1788782262579916000,"stream":"btcusdt@trade","event_type":"trade","event_time_ms":1788782262636,"raw_json":"{\"stream\":\"btcusdt@trade\",\"data\":{\"e\":\"trade\",\"E\":1788782262636,\"T\":1788782262636,\"s\":\"BTCUSDT\",\"t\":8057739795,\"p\":\"79366.00\",\"q\":\"0.002\",\"X\":\"MARKET\",\"m\":true,\"st\":1}}"}
{"receive_ns":1788782262580241000,"stream":"btcusdt@trade","event_type":"trade","event_time_ms":1788782262636,"raw_json":"{\"stream\":\"btcusdt@trade\",\"data\":{\"e\":\"trade\",\"E\":1788782262636,\"T\":1788782262636,\"s\":\"BTCUSDT\",\"t\":8057739796,\"p\":\"79366.00\",\"q\":\"0.002\",\"X\":\"MARKET\",\"m\":true,\"st\":1}}"}
{"receive_ns":1788782262580458000,"stream":"btcusdt@trade","event_type":"trade","event_time_ms":1788782262636,"raw_json":"{\"stream\":\"btcusdt@trade\",\"data\":{\"e\":\"trade\",\"E\":1788782262636,\"T\":1788782262636,\"s\":\"BTCUSDT\",\"t\":8057739797,\"p\":\"79366.00\",\"q\":\"0.002\",\"X\":\"MARKET\",\"m\":true,\"st\":1}}"}
{"receive_ns":1788782262580765000,"stream":"btcusdt@trade","event_type":"trade","event_time_ms":1788782262636,"raw_json":"{\"stream\":\"btcusdt@trade\",\"data\":{\"e\":\"trade\",\"E\":1788782262636,\"T\":1788782262636,\"s\":\"BTCUSDT\",\"t\":8057739798,\"p\":\"79366.00\",\"q\":\"0.002\",\"X\":\"MARKET\",\"m\":true,\"st\":1}}"}
{"receive_ns":1788782262581039000,"stream":"btcusdt@trade","event_type":"trade","event_time_ms":1788782262636,"raw_json":"{\"stream\":\"btcusdt@trade\",\"data\":{\"e\":\"trade\",\"E\":1788782262636,\"T\":1788782262636,\"s\":\"BTCUSDT\",\"t\":8057739799,\"p\":\"79366.00\",\"q\":\"0.002\",\"X\":\"MARKET\",\"m\":true,\"st\":1}}"}
{"receive_ns":1788782262581288000,"stream":"btcusdt@trade","event_type":"trade","event_time_ms":1788782262636,"raw_json":"{\"stream\":\"btcusdt@trade\",\"data\":{\"e\":\"trade\",\"E\":1788782262636,\"T\":1788782262636,\"s\":\"BTCUSDT\",\"t\":8057739800,\"p\":\"79366.00\",\"q\":\"0.004\",\"X\":\"MARKET\",\"m\":true,\"st\":1}}"}
{"receive_ns":1788782262581474000,"stream":"btcusdt@bookTicker","event_type":"bookTicker","event_time_ms":1788782262636,"raw_json":"{\"stream\":\"btcusdt@bookTicker\",\"data\":{\"e\":\"bookTicker\",\"u\":11496348117667,\"s\":\"BTCUSDT\",\"ps\":\"BTCUSDT\",\"b\":\"79365.90\",\"B\":\"0.004\",\"a\":\"79366.00\",\"A\":\"0.428\",\"T\":1788782262636,\"E\":1788782262636,\"st\":1}}"}
{"receive_ns":1788782262581648000,"stream":"btcusdt@bookTicker","event_type":"bookTicker","event_time_ms":1788782262636,"raw_json":"{\"stream\":\"btcusdt@bookTicker\",\"data\":{\"e\":\"bookTicker\",\"u\":11496348117771,\"s\":\"BTCUSDT\",\"ps\":\"BTCUSDT\",\"b\":\"79365.90\",\"B\":\"0.004\",\"a\":\"79366.00\",\"A\":\"0.748\",\"T\":1788782262636,\"E\":1788782262636,\"st\":1}}"}
{"receive_ns":1788782262581814000,"stream":"btcusdt@bookTicker","event_type":"bookTicker","event_time_ms":1788782262636,"raw_json":"{\"stream\":\"btcusdt@bookTicker\",\"data\":{\"e\":\"bookTicker\",\"u\":11496348117773,\"s\":\"BTCUSDT\",\"ps\":\"BTCUSDT\",\"b\":\"79365.90\",\"B\":\"0.004\",\"a\":\"79366.00\",\"A\":\"0.985\",\"T\":1788782262636,\"E\":1788782262636,\"st\":1}}"}
{"receive_ns":1788782262581965000,"stream":"btcusdt@trade","event_type":"trade","event_time_ms":1788782262636,"raw_json":"{\"stream\":\"btcusdt@trade\",\"data\":{\"e\":\"trade\",\"E\":1788782262636,\"T\":1788782262636,\"s\":\"BTCUSDT\",\"t\":8057739801,\"p\":\"79366.00\",\"q\":\"0.001\",\"X\":\"MARKET\",\"m\":true,\"st\":1}}"}
