{"kind": "depth", "E": 1787080346675, "U": 11315348013983, "u": 11315348019731, "recv_ms": 1787080346629, "bids": [[1000.0, 35.81], [14196.8, 0.112], [14496.8, 0.56], [14596.8, 3.528], [58227.1, 0.002], [61461.9, 0.0], [61462.0, 0.006], [61462.1, 0.004], [62108.9, 0.003], [63720.7, 8.01], [63913.8, 0.001], [63913.9, 0.004], [63920.4, 7.171], [64049.8, 0.0], [64666.7, 1.611], [64670.6, 0.162], [64674.5, 0.157], [64680.6, 0.698], [64681.9, 0.216], [64683.6, 0.0], [64689.3, 0.333], [64690.0, 0.008], [64690.2, 0.134], [64691.3, 0.311], [64696.8, 10.351]], "asks": [[64696.9, 15.682], [64697.0, 0.068], [64698.1, 0.0], [64699.0, 0.022], [64699.1, 1.727], [64699.3, 0.002], [64700.5, 0.069], [64701.2, 0.001], [64702.0, 0.085], [64705.6, 0.476], [64705.7, 0.644], [64706.9, 0.334], [64711.6, 0.043], [64712.1, 0.002], [64713.5, 0.31], [64720.0, 3.672], [64720.8, 0.003], [64722.0, 10.496], [64726.6, 0.001], [64726.7, 0.038], [64826.8, 0.045], [64890.5, 0.859], [64892.7, 5.848], [64895.0, 50.853], [65343.9, 0.0], [65441.6, 13.622]]}
{"kind": "depth", "E": 1787080346777, "U": 11315348019798, "u": 11315348025275, "recv_ms": 1787080346729, "bids": [[14196.8, 0.0], [14496.8, 0.812], [14596.8, 3.388], [58227.1, 0.002], [63618.6, 4.244], [63850.1, 10.657], [64049.8, 0.0], [64691.3, 0.101]], "asks": [[64702.0, 0.1], [64705.5, 0.0], [64705.6, 0.006], [64705.7, 0.567], [64706.8, 0.496], [64706.9, 0.418], [64712.1, 0.002], [64826.8, 0.03], [65343.9, 0.0], [65797.3, 1.32], [65862.0, 1.639]]}
{"kind": "depth", "E": 1787080346879, "U": 11315348025331, "u": 11315348033898, "recv_ms": 1787080346832, "bids": [[1000.0, 35.81], [14496.8, 1.162], [14596.8, 3.038], [58227.1, 0.002], [61461.9, 0.0], [61464.9, 0.0], [62108.9, 0.006], [63612.1, 9.419], [63696.8, 0.0], [64049.8, 0.0], [64064.6, 65.509], [64212.3, 54.933], [64373.3, 2.64], [64592.6, 2.32], [64593.4, 0.0], [64621.7, 0.018], [64674.5, 0.775], [64674.6, 0.002], [64675.5, 0.562], [64677.2, 2.319], [64681.8, 0.798], [64690.0, 0.162], [64690.1, 1.999], [64691.3, 0.206], [64696.8, 10.347]], "asks": [[64699.0, 0.022], [64702.0, 0.085], [64705.4, 0.004], [64705.5, 0.0], [64705.6, 0.006], [64705.7, 0.002], [64706.8, 0.504], [64706.9, 0.975], [64711.6, 0.043], [64712.1, 0.002], [64713.4, 0.784], [64720.8, 0.621], [64806.5, 2.319], [64807.3, 0.0], [64826.8, 0.045], [64892.7, 4.033], [64895.0, 50.853], [65343.9, 0.0], [65596.9, 6.244], [65696.9, 0.01], [65990.8, 0.012]]}
{"kind": "depth", "E": 1787080346981, "U": 11315348034115, "u": 11315348041037, "recv_ms": 1787080346936, "bids": [[14496.8, 1.512], [14596.8, 2.688], [58227.1, 0.002], [62108.9, 0.003], [63599.9, 7.548], [63726.3, 0.391], [63855.7, 0.313], [63923.4, 37.5], [64049.8, 0.0], [64620.7, 0.122], [64620.8, 1.242], [64621.7, 0.009], [64622.9, 37.1], [64647.6, 0.681], [64691.3, 0.101], [64696.8, 10.348]], "asks": [[64699.0, 0.022], [64705.5, 0.0], [64705.6, 0.006], [64705.7, 0.002], [64706.7, 0.014], [64706.8, 0.604], [64706.9, 0.875], [64711.6, 0.043], [64712.1, 0.002], [65343.9, 0.0], [65441.6, 14.538], [65799.8, 6.764], [71166.6, 0.013]]}
{"kind": "depth", "E": 1787080347083, "U": 11315348041304, "u": 11315348047913, "recv_ms": 1787080347035, "bids": [[14496.8, 1.876], [14596.8, 2.324], [58227.1, 0.002], [61461.9, 0.0], [61462.0, 0.008], [62108.9, 0.006], [63596.9, 0.784], [63597.0, 4.711], [63603.4, 0.628], [63696.8, 0.02], [63706.5, 0.155], [64049.8, 0.0], [64108.9, 7.944], [64179.2, 4.518], [64373.3, 2.639], [64539.8, 7.903], [64556.8, 4.747], [64685.2, 0.464], [64690.0, 0.162], [64690.2, 0.19], [64690.8, 0.134], [64691.3, 0.101], [64696.7, 0.042], [64696.8, 10.341]], "asks": [[64696.9, 15.575], [64699.0, 0.022], [64705.5, 0.007], [64705.6, 0.469], [64705.7, 0.103], [64706.7, 0.014], [64706.8, 0.033], [64706.9, 0.875], [64711.6, 0.043], [64712.1, 0.002], [64713.4, 0.166], [64835.2, 2.703], [64836.9, 5.398], [64853.9, 10.778], [65343.9, 0.0], [65693.3, 0.77], [65696.9, 0.03], [65796.7, 4.556], [65990.8, 0.009]]}
{"kind": "depth", "E": 1787080347185, "U": 11315348048235, "u": 11315348053721, "recv_ms": 1787080347136, "bids": [[1000.0, 35.81], [14496.8, 2.226], [14596.8, 1.974], [58227.1, 0.002], [61461.9, 0.001], [62108.9, 0.003], [63703.6, 0.011], [63710.4, 0.008], [63791.0, 0.666], [63923.4, 36.876], [64049.8, 0.0], [64373.3, 2.639], [64376.3, 4.158], [64539.8, 7.903], [64556.8, 4.747], [64617.6, 0.011], [64624.5, 0.161], [64644.6, 0.005], [64647.7, 0.004], [64654.1, 0.067], [64681.8, 0.18], [64685.8, 0.649], [64686.9, 0.002], [64690.2, 0.134], [64691.3, 0.101], [64695.9, 0.002], [64696.8, 10.616]], "asks": [[64696.9, 15.577], [64698.7, 0.084], [64699.0, 0.177], [64703.1, 0.303], [64703.5, 0.006], [64705.4, 0.159], [64705.5, 0.548], [64705.6, 0.624], [64705.7, 0.103], [64705.9, 0.041], [64706.8, 0.033], [64706.9, 0.644], [64711.6, 0.198], [64720.8, 0.003], [64836.9, 5.398], [64853.9, 10.778], [65020.4, 2.92], [65343.9, 0.0]]}
{"kind": "depth", "E": 1787080347287, "U": 11315348053775, "u": 11315348059629, "recv_ms": 1787080347243, "bids": [[14496.8, 2.59], [14596.8, 1.61], [58227.1, 0.002], [61461.9, 0.0], [63696.8, 0.0], [63791.0, 1.135], [63920.4, 7.951], [63955.6, 0.782], [64049.8, 0.0], [64114.5, 2.182], [64663.9, 0.003], [64664.6, 0.059], [64665.5, 0.001], [64675.3, 0.561], [64675.5, 0.005], [64676.2, 0.083], [64676.4, 0.486], [64676.9, 0.427], [64677.9, 0.231], [64690.0, 0.008], [64690.1, 1.999], [64690.2, 0.19], [64691.3, 0.101], [64696.8, 10.617]], "asks": [[64699.0, 0.022], [64704.0, 0.931], [64705.3, 0.015], [64705.4, 0.004], [64705.5, 0.0], [64705.6, 0.013], [64705.7, 0.644], [64706.8, 0.033], [64706.9, 0.334], [64710.3, 0.145], [64711.6, 0.043], [64712.1, 0.465], [64713.0, 0.003], [64713.9, 0.963], [64715.9, 0.021], [64716.4, 6.674], [64716.6, 0.008], [64717.3, 0.06], [64718.3, 0.675], [64719.4, 0.004], [64720.1, 2.328], [64720.7, 0.214], [65343.9, 0.0], [65521.2, 5.993], [65690.2, 0.012], [65696.9, 0.01]]}
{"kind": "depth", "E": 1787080347389, "U": 11315348059790, "u": 11315348065006, "recv_ms": 1787080347345, "bids": [[14496.8, 2.94], [14596.8, 1.26], [51757.4, 0.0], [58227.1, 0.002], [62108.9, 0.006], [63697.0, 17.252], [63761.7, 32.346], [64049.8, 0.0], [64403.3, 0.001], [64651.5, 0.189], [64685.9, 0.125], [64690.0, 0.162], [64691.3, 0.101]], "asks": [[64705.5, 0.0], [64705.6, 0.006], [64705.7, 0.002], [64706.8, 1.145], [64706.9, 0.334], [64712.1, 0.002], [64755.2, 0.319], [64826.3, 0.0], [64892.7, 4.084], [65343.9, 0.0], [65505.6, 2.527]]}
{"kind": "depth", "E": 1787080347491, "U": 11315348065188, "u": 11315348070849, "recv_ms": 1787080347450, "bids": [[1000.0, 35.81], [14496.8, 3.304], [14596.8, 0.896], [58227.1, 0.002], [62108.9, 0.003], [63402.9, 0.91], [63695.3, 5.329], [63696.8, 0.02], [63920.4, 8.575], [64049.8, 0.0], [64373.3, 2.794], [64626.9, 0.814], [64663.9, 0.06], [64664.6, 0.002], [64674.6, 0.559], [64675.3, 0.004], [64676.3, 0.12], [64676.9, 0.311], [64679.9, 0.943], [64680.8, 0.003], [64680.9, 0.313], [64687.1, 0.005], [64688.0, 2.692], [64691.3, 0.101]], "asks": [[64703.2, 0.396], [64704.0, 0.031], [64705.7, 0.567], [64706.8, 0.58], [64712.3, 1.435], [64713.3, 0.927], [64713.9, 0.038], [64715.8, 0.001], [64716.7, 0.072], [64717.3, 0.003], [64718.3, 0.675], [64719.1, 0.152], [64720.7, 0.099], [64765.2, 1.225], [65343.9, 0.0], [65598.9, 0.609], [65696.9, 0.03], [65750.0, 6.845]]}
{"kind": "depth", "E": 1787080347593, "U": 11315348070977, "u": 11315348075959, "recv_ms": 1787080347544, "bids": [[14496.8, 3.654], [14596.8, 0.546], [51758.0, 0.0], [58227.1, 0.002], [61461.9, 0.0], [62108.9, 0.006], [63402.9, 0.907], [63547.5, 0.0], [63694.0, 5.414], [63696.8, 0.0], [63758.7, 1.096], [63888.1, 2.003], [64049.8, 0.002], [64373.3, 2.793], [64495.7, 26.258], [64495.8, 5.528], [64623.0, 6.565], [64663.9, 0.003], [64665.6, 0.064], [64677.3, 0.007], [64679.9, 0.017], [64681.5, 2.174], [64688.5, 0.0], [64691.3, 0.101], [64694.2, 0.011], [64696.8, 10.655]], "asks": [[64696.9, 15.576], [64699.0, 0.177], [64704.0, 0.931], [64705.6, 0.006], [64706.7, 0.324], [64706.8, 0.117], [64710.3, 0.3], [64712.1, 0.465], [64713.3, 0.002], [64714.0, 0.947], [64716.7, 0.015], [64717.4, 1.6], [64718.3, 0.134], [64719.1, 0.037], [64719.4, 0.545], [64720.0, 2.17], [64720.8, 0.118], [64722.0, 0.496], [64723.9, 2.661], [64725.3, 10.347], [64746.1, 0.041], [64769.4, 0.0], [64835.2, 3.46], [64890.5, 1.381], [64963.6, 5.245], [65020.4, 2.921], [65343.9, 0.0], [65583.2, 0.608], [65696.9, 0.01], [66259.7, 0.646]]}
{"kind": "depth", "E": 1787080347695, "U": 11315348075964, "u": 11315348081969, "recv_ms": 1787080347653, "bids": [[14396.8, 0.14], [14496.8, 3.738], [14596.8, 0.322], [58227.1, 0.002], [61461.9, 0.0], [62108.9, 0.003], [64049.8, 0.0], [64630.7, 0.14], [64638.5, 0.008], [64657.9, 0.006], [64659.4, 0.403], [64664.5, 0.068], [64665.6, 0.007], [64680.4, 1.05], [64681.5, 1.248], [64690.2, 0.134], [64691.2, 0.395], [64691.3, 0.101], [64694.2, 0.095], [64696.8, 10.665]], "asks": [[64696.9, 15.58], [64698.7, 0.0], [64699.0, 0.022], [64705.4, 0.004], [64705.6, 0.469], [64705.7, 1.804], [64706.7, 0.014], [64706.9, 0.334], [64709.6, 0.001], [64710.3, 0.145], [64711.6, 0.043], [64712.1, 0.002], [64712.9, 0.93], [64714.0, 0.022], [64717.7, 0.233], [64718.3, 0.675], [64719.4, 0.004], [64738.8, 3.61], [64785.6, 1.355], [64790.6, 0.0], [64806.9, 0.006], [65217.5, 9.062], [65343.9, 0.002], [65367.9, 0.0], [65476.3, 28.444], [65505.5, 1.6], [65626.8, 0.025], [65691.5, 7.706], [66127.6, 0.669]]}
{"kind": "depth", "E": 1787080347797, "U": 11315348081993, "u": 11315348087209, "recv_ms": 1787080347749, "bids": [[1000.0, 35.81], [14396.8, 0.378], [14496.8, 3.626], [14596.8, 0.196], [58227.1, 0.002], [61462.1, 0.002], [64049.8, 0.001], [64373.3, 2.803], [64663.9, 0.06], [64664.5, 0.011], [64679.7, 0.926], [64680.4, 0.124], [64687.1, 0.005], [64688.0, 2.692], [64688.3, 2.323], [64689.9, 0.696], [64690.0, 0.008], [64690.1, 1.999], [64690.2, 0.19], [64690.3, 0.016], [64691.2, 0.29], [64691.3, 0.101], [64694.8, 0.084]], "asks": [[64699.1, 1.643], [64715.7, 0.131], [64716.7, 0.072], [64717.3, 0.003], [64717.4, 1.543], [64718.3, 0.675], [65343.9, 0.0], [65602.7, 9.013], [65618.6, 3.872]]}
{"kind": "depth", "E": 1787080348001, "U": 11315348094174, "u": 11315348102720, "recv_ms": 1787080347953, "bids": [[1000.0, 35.81], [14396.8, 0.896], [14496.8, 3.304], [14596.8, 0.0], [58227.1, 0.002], [62108.9, 0.003], [63696.8, 0.0], [63720.7, 7.619], [64049.8, 0.001], [64556.8, 4.737], [64667.3, 3.097], [64677.3, 0.025], [64682.1, 1.395], [64691.3, 0.101]], "asks": [[64696.9, 15.581], [64699.3, 0.157], [64705.5, 0.387], [64706.9, 0.644], [64709.0, 1.149], [64711.6, 0.198], [64713.7, 0.627], [64721.1, 1.12], [64743.5, 0.002], [64836.9, 5.398], [64892.7, 4.115], [65214.5, 1.221], [65343.9, 2.294], [65473.3, 10.002], [65667.4, 3.05], [65696.9, 0.01], [71166.6, 0.013]]}
{"kind": "depth", "E": 1787080348103, "U": 11315348102798, "u": 11315348115324, "recv_ms": 1787080348056, "bids": [[1000.0, 35.81], [14396.8, 1.246], [14496.8, 2.954], [58227.1, 0.002], [61461.9, 0.0], [62108.9, 0.006], [63629.3, 1.101], [63710.5, 4.25], [63775.1, 0.014], [63776.6, 0.0], [64049.8, 0.001], [64373.3, 2.793], [64624.6, 0.012], [64639.4, 0.212], [64646.7, 0.0], [64647.9, 0.027], [64654.3, 0.061], [64660.5, 0.017], [64663.4, 0.12], [64670.0, 1.404], [64685.2, 0.464], [64685.9, 0.001], [64690.2, 0.134], [64690.6, 0.319], [64691.1, 0.216], [64691.3, 0.101], [64693.3, 0.106], [64693.5, 0.001], [64693.6, 0.001], [64693.8, 0.087], [64694.2, 0.011], [64694.8, 0.0], [64695.2, 0.003], [64696.8, 10.653]], "asks": [[64698.7, 0.084], [64699.1, 1.727], [64699.3, 0.002], [64700.3, 1.053], [64700.7, 0.022], [64705.4, 0.011], [64705.5, 0.077], [64706.8, 0.033], [64706.9, 0.334], [64711.4, 0.074], [64711.6, 0.043], [64715.3, 0.384], [64715.5, 0.62], [64716.4, 6.118], [64718.7, 0.003], [64721.4, 10.06], [64722.7, 2.823], [64766.8, 0.442], [65343.9, 2.292], [65562.1, 5.11], [65617.1, 0.0], [65618.6, 3.864], [65683.3, 0.026], [65690.8, 0.0]]}
{"kind": "depth", "E": 1787080348205, "U": 11315348115659, "u": 11315348138624, "recv_ms": 1787080348159, "bids": [[14396.8, 1.596], [14496.8, 2.604], [58227.1, 0.002], [61461.9, 0.0], [63402.9, 0.91], [63696.8, 0.02], [63710.5, 4.258], [63775.1, 0.022], [63776.6, 0.008], [64049.8, 0.001], [64373.3, 2.794], [64599.0, 0.606], [64599.1, 0.02], [64599.3, 0.004], [64618.5, 33.322], [64621.0, 0.041], [64622.4, 3.407], [64622.9, 3.939], [64623.0, 1.798], [64624.6, 0.013], [64627.2, 0.033], [64634.3, 0.031], [64640.5, 0.0], [64644.8, 1.19], [64654.2, 0.001], [64654.3, 0.062], [64656.8, 0.099], [64657.2, 0.001], [64657.5, 0.005], [64657.9, 0.02], [64661.3, 0.002], [64663.9, 0.003], [64665.0, 1.307], [64666.6, 0.046], [64666.7, 1.275], [64667.2, 1.153], [64667.9, 0.0], [64668.6, 0.031], [64669.6, 0.171], [64670.0, 1.401], [64670.8, 0.02], [64672.9, 0.002], [64673.9, 0.273], [64674.4, 0.006], [64674.5, 0.003], [64674.7, 0.009], [64675.0, 0.085], [64675.1, 0.034], [64675.2, 0.047], [64675.5, 0.005], [64675.9, 0.095], [64676.3, 0.004], [64676.6, 0.003], [64676.9, 0.311], [64677.0, 0.98], [64677.1, 0.155], [64677.3, 0.025], [64677.7, 0.004], [64677.8, 0.122], [64678.8, 0.447], [64678.9, 0.003], [64679.3, 0.005], [64679.7, 0.0], [64680.0, 1.782], [64680.1, 0.131], [64680.4, 0.0], [64681.0, 0.077], [64681.2, 0.001], [64681.4, 1.287], [64682.1, 0.777], [64682.3, 0.019], [64683.8, 0.032], [64684.3, 0.005], [64685.0, 0.022], [64685.7, 0.166], [64685.8, 0.208], [64685.9, 0.001], [64686.1, 2.559], [64688.0, 0.914], [64688.1, 0.046], [64688.2, 0.001], [64688.3, 0.0], [64688.6, 0.004], [64688.8, 0.085], [64688.9, 0.312], [64689.0, 0.001], [64689.1, 0.232], [64689.2, 0.091], [64689.6, 0.101], [64689.7, 0.0], [64689.9, 0.085], [64690.0, 0.005], [64690.1, 0.639], [64690.2, 0.018], [64690.3, 0.084], [64690.6, 0.087], [64690.7, 0.142], [64691.2, 0.231], [64691.3, 1.7], [64691.4, 0.186], [64691.5, 0.315], [64691.6, 0.07], [64691.7, 0.459], [64691.8, 0.0], [64691.9, 0.119], [64692.0, 0.011], [64692.3, 0.086], [64692.4, 0.005], [64692.6, 2.051], [64692.7, 0.121], [64692.8, 0.002], [64692.9, 0.032], [64693.0, 0.002], [64693.1, 0.005], [64693.2, 0.032], [64693.4, 0.005], [64693.5, 0.001], [64693.8, 0.003], [64695.0, 0.001], [64695.2, 0.039], [64695.8, 0.002], [64696.5, 0.0], [64696.7, 0.008], [64696.8, 4.728]], "asks": [[64696.9, 15.731], [64697.0, 0.152], [64697.2, 0.002], [64697.3, 0.084], [64697.4, 0.0], [64697.5, 0.311], [64697.8, 0.087], [64697.9, 0.0], [64698.3, 0.108], [64698.4, 0.003], [64699.0, 0.725], [64699.1, 1.73], [64699.3, 0.009], [64699.5, 0.37], [64699.9, 0.675], [64700.0, 1.734], [64700.2, 0.066], [64700.3, 1.05], [64700.5, 0.0], [64700.6, 0.091], [64700.7, 0.0], [64701.6, 0.018], [64702.0, 0.001], [64702.4, 0.008], [64702.7, 0.001], [64704.7, 0.002], [64705.4, 0.004], [64705.5, 0.387], [64705.7, 1.263], [64706.9, 0.644], [64708.1, 0.251], [64709.5, 0.254], [64709.8, 0.16], [64709.9, 2.38], [64710.3, 0.225], [64710.7, 0.007], [64711.6, 0.043], [64712.8, 1.337], [64712.9, 0.93], [64713.2, 0.227], [64713.3, 0.002], [64713.6, 0.069], [64713.7, 0.009], [64714.4, 0.443], [64715.5, 0.627], [64715.8, 0.066], [64715.9, 0.023], [64716.4, 6.133], [64716.6, 0.006], [64716.7, 0.059], [64716.8, 0.455], [64717.3, 0.544], [64717.8, 11.391], [64718.0, 0.001], [64718.3, 0.134], [64719.0, 0.01], [64719.6, 0.116], [64719.7, 0.002], [64720.8, 0.003], [64721.1, 0.502], [64721.4, 0.062], [64721.5, 0.31], [64723.2, 0.007], [64723.4, 0.021], [64723.9, 1.251], [64725.3, 0.347], [64736.8, 0.211], [64744.1, 0.119], [64751.6, 0.07], [64763.0, 0.423], [64764.4, 0.034], [64775.4, 0.127], [64785.6, 1.255], [64791.8, 0.001], [64812.6, 0.001], [64892.7, 7.199], [65020.4, 2.92], [65303.2, 2.296], [65343.9, 2.294], [65696.9, 0.03]]}
{"kind": "depth", "E": 1787080348307, "U": 11315348138734, "u": 11315348154930, "recv_ms": 1787080348258, "bids": [[1000.0, 35.81], [14396.8, 1.96], [14496.8, 2.24], [51758.0, 0.0], [58227.1, 0.002], [61461.9, 0.0], [62108.9, 0.003], [63402.9, 0.913], [63726.3, 0.782], [63858.7, 5.335], [64049.8, 0.001], [64182.2, 5.941], [64618.5, 0.005], [64620.7, 33.465], [64621.7, 0.018], [64655.3, 0.112], [64662.2, 0.346], [64664.1, 0.07], [64665.0, 1.31], [64666.6, 0.201], [64670.0, 1.404], [64673.1, 0.174], [64675.0, 0.645], [64675.5, 0.012], [64676.5, 0.117], [64679.6, 0.173], [64679.7, 0.926], [64680.0, 1.785], [64680.3, 2.321], [64680.5, 0.003], [64683.2, 0.008], [64685.0, 0.025], [64686.8, 0.456], [64687.0, 0.001], [64687.1, 0.005], [64687.8, 0.324], [64688.0, 1.455], [64688.1, 0.578], [64688.2, 0.025], [64688.8, 0.001], [64689.2, 0.007], [64689.7, 0.001], [64689.9, 0.085], [64690.0, 0.279], [64690.1, 0.639], [64690.2, 0.002], [64691.8, 0.549], [64692.1, 0.044], [64692.7, 0.084], [64692.8, 0.018], [64693.1, 0.089], [64695.0, 0.004], [64696.5, 0.001], [64696.8, 5.062]], "asks": [[64696.9, 15.732], [64697.0, 0.068], [64697.1, 0.0], [64697.2, 0.0], [64697.3, 0.0], [64697.4, 0.002], [64697.6, 0.004], [64698.8, 0.08], [64698.9, 0.066], [64699.0, 0.177], [64699.2, 0.829], [64699.3, 0.009], [64705.3, 0.015], [64705.4, 0.004], [64705.5, 0.387], [64706.9, 0.644], [64707.1, 0.48], [64709.2, 0.023], [64709.8, 0.16], [64710.3, 0.145], [64715.2, 3.653], [64716.4, 6.135], [64716.8, 0.453], [64717.3, 0.003], [64717.7, 0.774], [64718.4, 1.287], [64724.3, 0.024], [64724.4, 0.158], [64724.7, 0.121], [64892.7, 4.115], [65343.9, 2.292], [65420.8, 0.002], [65538.0, 3.534], [65617.1, 0.008], [65618.6, 3.872], [65683.3, 0.034], [65699.7, 2.583]]}
{"kind": "depth", "E": 1787080348409, "U": 11315348155075, "u": 11315348163408, "recv_ms": 1787080348360, "bids": [[1000.0, 35.81], [14396.8, 2.31], [14496.8, 1.89], [51757.4, 0.0], [51758.0, 0.0], [58227.1, 0.002], [61461.9, 0.0], [62108.9, 0.006], [63784.5, 0.0], [63920.4, 10.138], [64049.8, 0.001], [64373.3, 2.804], [64571.3, 0.002], [64690.0, 0.279], [64690.1, 0.639], [64691.8, 0.549], [64692.7, 0.084], [64696.8, 5.035]], "asks": [[64696.9, 15.731], [64698.8, 0.0], [64698.9, 0.056], [64699.0, 0.177], [64699.1, 1.737], [64699.2, 0.822], [64699.9, 0.656], [64700.0, 0.856], [64703.0, 0.914], [64705.4, 0.004], [64705.5, 0.387], [64706.9, 0.644], [64708.0, 0.321], [64709.4, 0.163], [64709.8, 0.16], [64716.0, 1.04], [64717.8, 11.393], [64719.0, 0.008], [64720.0, 2.169], [64724.4, 0.004], [64826.3, 0.0], [65279.2, 4.817], [65343.9, 2.292], [65562.9, 0.001], [65638.0, 35.075], [65702.7, 18.087]]}
{"kind": "depth", "E": 1787080348511, "U": 11315348163530, "u": 11315348173091, "recv_ms": 1787080348462, "bids": [[14396.8, 2.674], [14496.8, 1.526], [58227.1, 0.002], [61461.9, 0.0], [62108.9, 0.003], [63515.4, 0.0], [63696.8, 0.0], [63855.7, 0.626], [64049.8, 0.001], [64376.3, 4.003], [64663.9, 0.001], [64664.0, 1.223], [64664.1, 0.068], [64667.3, 3.095], [64667.4, 0.004], [64667.5, 0.014], [64680.8, 0.003], [64688.1, 0.501], [64688.2, 0.009], [64689.2, 0.008], [64689.7, 0.0], [64690.0, 0.279], [64690.2, 0.305], [64691.3, 1.699], [64692.7, 0.085], [64696.8, 4.426]], "asks": [[64696.9, 15.779], [64699.0, 0.177], [64700.2, 0.004], [64701.0, 0.067], [64702.7, 0.02], [64702.8, 2.354], [64705.5, 0.387], [64706.9, 0.644], [64709.8, 0.16], [64713.3, 0.002], [64724.4, 0.004], [64724.5, 0.155], [65217.5, 8.756], [65343.9, 2.292], [65532.5, 0.006], [65538.4, 1.08], [65696.9, 0.01], [65990.8, 0.006]]}
{"kind": "depth", "E": 1787080348613, "U": 11315348173189, "u": 11315348181410, "recv_ms": 1787080348569, "bids": [[1000.0, 35.81], [14396.8, 3.024], [14496.8, 1.176], [58227.1, 0.002], [61461.9, 0.0], [62108.9, 0.006], [63402.9, 0.916], [63478.3, 0.0], [63791.0, 3.484], [64049.8, 0.001], [64153.3, 0.043], [64179.2, 4.828], [64373.3, 2.805], [64620.8, 8.603], [64638.5, 0.008], [64651.5, 0.186], [64688.2, 0.102], [64690.2, 0.002], [64693.1, 0.005], [64696.8, 4.448]], "asks": [[64696.9, 15.784], [64697.3, 0.084], [64698.9, 0.056], [64699.0, 0.874], [64700.2, 0.066], [64700.4, 0.001], [64701.0, 0.005], [64703.0, 0.014], [64704.0, 1.047], [64705.5, 0.077], [64706.9, 0.334], [64709.8, 0.005], [64717.4, 2.735], [64717.7, 0.233], [64718.3, 0.675], [64719.1, 0.041], [64755.2, 0.319], [64765.2, 6.837], [64767.9, 38.718], [64768.3, 0.893], [64770.2, 0.628], [64806.9, 0.003], [64851.9, 2.673], [65020.4, 2.919], [65343.9, 2.292], [65402.1, 0.704], [65508.6, 17.024], [65638.0, 34.01]]}
{"kind": "depth", "E": 1787080348715, "U": 11315348181495, "u": 11315348188068, "recv_ms": 1787080348675, "bids": [[1000.0, 35.81], [14396.8, 3.388], [14496.8, 0.812], [58227.1, 0.002], [61461.9, 0.0], [63696.8, 0.02], [63923.4, 36.251], [64049.8, 0.001], [64373.3, 2.805], [64376.3, 3.848], [64679.7, 0.0], [64680.4, 0.926], [64681.4, 1.287], [64688.2, 0.009], [64689.1, 0.0], [64689.5, 0.236], [64690.0, 0.433], [64690.1, 0.639], [64690.2, 0.305], [64692.7, 0.085], [64696.5, 0.0], [64696.6, 0.017], [64696.7, 0.009], [64696.8, 4.454]], "asks": [[64697.2, 0.002], [64697.4, 0.0], [64698.9, 0.211], [64699.1, 1.73], [64699.9, 0.623], [64705.4, 0.011], [64705.5, 0.387], [64706.9, 0.644], [64709.8, 0.16], [64712.9, 0.005], [64713.8, 3.636], [64717.7, 0.774], [64718.3, 0.134], [64719.4, 0.004], [64719.6, 0.001], [64720.6, 0.196], [65023.4, 2.003], [65343.9, 2.292], [65602.7, 9.021], [65635.0, 1.827], [65696.9, 0.03], [65699.7, 3.647]]}
{"kind": "depth", "E": 1787080348817, "U": 11315348188294, "u": 11315348199376, "recv_ms": 1787080348775, "bids": [[14296.8, 0.014], [14396.8, 3.71], [14496.8, 0.476], [58227.1, 0.002], [62108.9, 0.003], [63499.9, 4.946], [63812.7, 15.857], [63920.4, 11.543], [64049.8, 0.0], [64100.5, 0.002], [64179.2, 5.139], [64182.2, 5.63], [64373.3, 3.115], [64688.2, 0.102], [64690.0, 0.279], [64690.2, 0.212], [64691.8, 0.549], [64692.7, 0.085], [64696.6, 0.018], [64696.8, 5.629]], "asks": [[64698.9, 0.056], [64699.2, 0.281], [64700.0, 0.85], [64705.3, 0.015], [64705.4, 0.552], [64705.5, 0.077], [64706.9, 0.334], [64709.4, 0.083], [64709.8, 0.005], [64710.3, 0.225], [64715.5, 0.62], [64716.3, 0.171], [64717.7, 0.233], [64718.3, 0.675], [64724.4, 0.158], [64724.5, 0.001], [65020.4, 3.073], [65214.5, 1.527], [65343.9, 2.292], [65635.0, 2.892]]}
{"kind": "depth", "E": 1787080348919, "U": 11315348199474, "u": 11315348207798, "recv_ms": 1787080348870, "bids": [[1000.0, 35.81], [14296.8, 0.196], [14396.8, 3.71], [14496.8, 0.294], [58227.1, 0.002], [61461.9, 0.0], [62108.9, 0.006], [63232.0, 0.055], [63696.8, 0.0], [63920.4, 12.168], [64049.8, 0.0], [64108.8, 2.413], [64556.2, 0.001], [64556.7, 4.657], [64556.8, 1.593], [64571.2, 3.743], [64688.4, 0.005], [64690.0, 0.433], [64690.1, 0.849], [64690.2, 0.002], [64691.6, 0.161], [64696.8, 5.592]], "asks": [[64698.9, 0.211], [64705.0, 0.172], [64705.1, 0.855], [64705.3, 0.015], [64705.5, 0.232], [64706.9, 0.335], [64709.8, 0.16], [64713.6, 0.029], [64717.3, 5.003], [64724.4, 0.004], [64724.5, 0.155], [64836.9, 5.398], [64892.7, 4.902], [65275.3, 0.0], [65303.2, 0.003], [65343.9, 2.292], [65505.6, 2.679], [65696.9, 0.01]]}
{"kind": "depth", "E": 1787080349021, "U": 11315348207866, "u": 11315348215315, "recv_ms": 1787080348972, "bids": [[1000.0, 35.81], [14296.8, 0.42], [14396.8, 3.612], [14496.8, 0.168], [58227.1, 0.002], [61461.9, 0.0], [62108.9, 0.003], [62871.3, 0.0], [63797.5, 0.907], [63882.5, 2.741], [64049.8, 0.0], [64082.2, 1.641], [64373.3, 3.105], [64688.2, 0.009], [64689.5, 0.004], [64689.9, 0.317], [64690.1, 0.744], [64690.2, 0.095], [64692.1, 0.024], [64692.7, 0.107], [64692.8, 0.037], [64696.8, 5.587]], "asks": [[64696.9, 15.84], [64698.9, 0.056], [64705.0, 0.017], [64705.5, 0.077], [64706.9, 0.025], [64709.8, 0.005], [64724.5, 0.001], [64765.2, 1.225], [64767.9, 0.009], [64768.0, 38.631], [64770.1, 0.001], [64772.3, 1.251], [65022.1, 0.022], [65022.2, 0.13], [65343.9, 2.292]]}
{"kind": "depth", "E": 1787080349123, "U": 11315348215573, "u": 11315348223341, "recv_ms": 1787080349079, "bids": [[14296.8, 0.672], [14396.8, 3.472], [14496.8, 0.056], [51758.0, 0.002], [58227.1, 0.002], [61461.9, 0.0], [61462.0, 0.01], [62108.9, 0.006], [63402.9, 0.913], [63696.8, 0.02], [63710.5, 4.248], [63909.3, 6.173], [64049.8, 0.0], [64114.4, 1.09], [64153.3, 0.006], [64624.7, 0.001], [64639.3, 0.015], [64644.8, 1.191], [64645.0, 6.128], [64647.9, 0.029], [64655.3, 0.098], [64664.1, 0.011], [64665.5, 0.058], [64675.0, 0.088], [64675.3, 0.561], [64676.2, 0.701], [64676.5, 0.001], [64677.0, 1.096], [64677.9, 0.231], [64680.4, 0.0], [64681.5, 2.174], [64683.5, 0.06], [64685.2, 0.464], [64686.9, 0.001], [64687.9, 1.113], [64688.2, 0.102], [64690.0, 0.279], [64690.1, 0.639], [64690.2, 0.002], [64692.1, 0.002], [64692.7, 0.107], [64692.8, 0.142], [64692.9, 0.054], [64693.3, 0.106], [64696.8, 5.569]], "asks": [[64696.9, 15.745], [64697.1, 0.0], [64697.2, 0.0], [64697.3, 0.0], [64697.4, 0.002], [64698.9, 0.056], [64699.0, 1.422], [64699.2, 0.303], [64699.5, 0.389], [64699.8, 2.528], [64702.7, 0.001], [64702.8, 2.332], [64704.5, 1.191], [64705.0, 0.017], [64705.4, 0.004], [64705.5, 0.077], [64706.9, 0.025], [64709.8, 0.005], [64715.1, 0.66], [64715.5, 0.064], [64716.4, 6.691], [64716.7, 0.002], [64717.3, 5.06], [64718.3, 0.675], [64719.4, 0.004], [64722.5, 1.621], [64724.5, 0.155], [64764.2, 0.024], [64892.7, 4.809], [65259.8, 0.231], [65343.9, 2.292], [65683.3, 0.024], [65696.9, 0.03]]}
{"kind": "depth", "E": 1787080349225, "U": 11315348223365, "u": 11315348232156, "recv_ms": 1787080349175, "bids": [[1000.0, 35.81], [14296.8, 0.98], [14396.8, 3.22], [14496.8, 0.0], [51758.0, 0.0], [58227.1, 0.002], [61462.0, 0.008], [61462.1, 0.004], [62820.6, 0.477], [63283.7, 0.155], [63402.9, 0.916], [63710.4, 0.018], [63850.0, 10.931], [64049.8, 0.0], [64373.3, 3.104], [64664.6, 0.059], [64665.5, 0.001], [64680.4, 0.926], [64681.5, 1.248], [64690.0, 0.433], [64690.1, 0.639], [64692.7, 0.107], [64692.8, 0.037]], "asks": [[64696.9, 15.746], [64697.0, 0.07], [64697.1, 0.0], [64697.2, 0.0], [64697.3, 0.0], [64697.4, 0.0], [64698.9, 0.075], [64700.3, 1.004], [64701.0, 0.051], [64720.0, 2.17], [64724.4, 0.158], [64724.5, 0.001], [65020.4, 3.074], [65343.9, 2.294], [65683.2, 0.018]]}
{"kind": "depth", "E": 1787080349327, "U": 11315348232184, "u": 11315348241395, "recv_ms": 1787080349283, "bids": [[1000.0, 35.81], [14296.8, 1.33], [14396.8, 2.87], [51757.4, 0.0], [58227.1, 0.002], [61461.9, 0.0], [62108.9, 0.003], [63522.3, 1.415], [63696.8, 0.0], [63920.4, 13.731], [64049.8, 0.0], [64373.3, 3.104], [64680.6, 0.692], [64688.2, 0.009], [64688.4, 0.002], [64688.8, 0.085], [64689.2, 0.092], [64690.2, 0.095], [64691.9, 0.14], [64692.1, 0.086], [64692.3, 0.002], [64692.7, 0.023], [64692.8, 0.037]], "asks": [[64697.0, 0.068], [64697.2, 0.002], [64697.3, 0.084], [64697.4, 0.0], [64697.5, 0.314], [64698.9, 0.056], [64699.2, 0.281], [64705.5, 0.077], [64706.9, 0.025], [64709.8, 0.005], [64724.4, 0.004], [64724.6, 0.387], [64806.4, 0.031], [65343.9, 2.292], [65432.6, 3.112], [65684.1, 0.001], [65696.9, 0.01]]}
{"kind": "depth", "E": 1787080349429, "U": 11315348241592, "u": 11315348249569, "recv_ms": 1787080349380, "bids": [[14296.8, 1.68], [14396.8, 2.52], [51757.0, 0.0], [58227.1, 0.002], [61461.9, 0.0], [62108.9, 0.006], [63870.5, 0.002], [64049.8, 0.0], [64680.6, 0.698], [64688.2, 0.102], [64689.7, 0.154], [64690.0, 0.279], [64690.1, 0.695], [64690.2, 0.002], [64691.9, 0.035], [64692.5, 0.119], [64692.7, 0.233], [64696.8, 5.591]], "asks": [[64697.5, 0.311], [64698.9, 0.056], [64705.5, 0.077], [64706.9, 0.025], [64709.8, 0.005], [64826.3, 0.0], [64892.7, 4.9], [65343.9, 2.292], [65435.1, 0.011], [65508.4, 0.011], [65642.9, 0.737], [66097.3, 0.648]]}
{"kind": "depth", "E": 1787080349531, "U": 11315348249618, "u": 11315348256227, "recv_ms": 1787080349483, "bids": [[1000.0, 35.81], [14296.8, 2.044], [14396.8, 2.156], [51758.0, 0.0], [58227.1, 0.002], [61461.9, 0.0], [61462.0, 0.01], [62108.9, 0.003], [63696.8, 0.02], [63720.7, 7.266], [63855.5, 7.318], [64006.8, 9.97], [64049.8, 0.0], [64182.2, 5.319], [64589.3, 2.322], [64592.6, 0.001], [64663.9, 0.003], [64664.0, 1.225], [64664.1, 0.013], [64666.8, 0.2], [64667.3, 3.097], [64667.4, 0.006], [64667.5, 0.016], [64680.8, 0.001], [64688.2, 0.102], [64688.8, 0.001], [64690.1, 0.639], [64690.2, 0.002], [64692.7, 0.023], [64693.5, 0.085], [64696.8, 5.605]], "asks": [[64696.9, 15.738], [64697.0, 0.07], [64697.1, 0.0], [64697.2, 0.0], [64697.3, 0.0], [64697.4, 0.0], [64697.8, 0.003], [64698.9, 0.056], [64701.5, 0.091], [64705.5, 0.077], [64706.9, 0.025], [64709.8, 0.005], [64713.3, 0.0], [64806.3, 2.562], [64806.5, 0.0], [65343.9, 2.292], [65473.3, 10.155], [65615.6, 0.469], [65667.4, 6.091], [65667.8, 1.324], [65696.9, 0.03]]}
{"kind": "depth", "E": 1787080349633, "U": 11315348256328, "u": 11315348263215, "recv_ms": 1787080349586, "bids": [[1000.0, 35.81], [14296.8, 2.394], [14396.8, 1.806], [58227.1, 0.002], [61461.9, 0.0], [61462.0, 0.008], [61462.1, 0.006], [62108.9, 0.006], [63991.6, 3.589], [64049.8, 0.0], [64332.3, 0.057], [64373.3, 3.103], [64556.7, 4.084], [64616.3, 33.187], [64620.7, 0.122], [64620.8, 1.242], [64621.7, 0.009], [64622.9, 3.939], [64625.7, 1.786], [64655.3, 0.112], [64680.8, 0.003], [64683.2, 0.572], [64686.0, 0.012], [64688.1, 0.038], [64688.2, 0.001], [64690.1, 0.639], [64696.8, 5.65]], "asks": [[64697.0, 0.068], [64697.4, 0.002], [64698.9, 0.056], [64705.5, 0.077], [64706.9, 0.025], [64709.8, 0.005], [64713.3, 0.002], [64727.9, 0.972], [64765.2, 6.824], [64768.0, 0.012], [64772.3, 39.87], [64836.9, 5.398], [64842.0, 0.634], [64892.7, 7.14], [65020.4, 3.075], [65343.9, 2.294]]}
{"kind": "depth", "E": 1787080349735, "U": 11315348263229, "u": 11315348268847, "recv_ms": 1787080349687, "bids": [[14296.8, 2.758], [14396.8, 1.442], [51758.0, 0.0], [58227.1, 0.002], [63696.8, 0.0], [63903.3, 4.022], [64049.8, 0.0], [64621.7, 0.018], [64626.9, 0.823], [64689.7, 0.0], [64689.9, 0.471], [64691.6, 0.07]], "asks": [[64699.2, 0.301], [64699.5, 0.411], [64717.7, 0.233], [64718.3, 0.675], [64719.4, 0.004], [64765.2, 1.225], [64780.6, 0.434], [64892.7, 4.806], [65273.6, 1.147], [65343.9, 2.292], [65432.6, 1.525], [65471.7, 0.0], [65561.4, 3.179], [65696.9, 0.01], [65800.7, 0.001]]}
{"kind": "depth", "E": 1787080349837, "U": 11315348268999, "u": 11315348274892, "recv_ms": 1787080349788, "bids": [[1000.0, 35.81], [14296.8, 3.108], [14396.8, 1.092], [58227.1, 0.004], [61461.9, 0.0], [62108.9, 0.003], [63726.3, 1.135], [64049.8, 0.0], [64179.2, 5.45], [64373.3, 3.113], [64556.7, 0.0], [64556.8, 0.002], [64616.3, 0.0], [64621.7, 0.009], [64622.9, 37.126], [64651.5, 0.189], [64696.8, 5.649]], "asks": [[64698.9, 0.056], [64705.5, 0.077], [64706.9, 0.025], [64709.8, 0.005], [64751.7, 0.168], [64767.9, 38.628], [64772.3, 1.251], [64806.9, 0.006], [64835.2, 2.703], [64836.9, 0.0], [65023.4, 1.849], [65343.9, 2.292], [65469.8, 6.405], [65473.3, 11.681], [65476.3, 27.986], [65537.7, 0.001], [65626.1, 3.168], [65809.7, 0.606]]}
{"kind": "depth", "E": 1787080349939, "U": 11315348274901, "u": 11315348280867, "recv_ms": 1787080349890, "bids": [[1000.0, 35.81], [14296.8, 3.472], [14396.8, 0.728], [58227.1, 0.002], [62108.9, 0.006], [63696.8, 0.02], [64049.8, 0.0], [64308.6, 0.048], [64373.3, 3.103], [64556.7, 4.658], [64638.5, 0.005], [64651.5, 0.186], [64695.3, 0.173]], "asks": [[64755.2, 0.316], [64806.9, 0.003], [64836.9, 5.398], [64892.7, 4.9], [65020.4, 3.229], [65279.4, 1.071], [65343.9, 2.292], [65473.3, 12.139], [65545.8, 0.01], [65570.3, 0.771], [65696.9, 0.03], [65990.8, 0.009]]}
{"kind": "depth", "E": 1787080350143, "U": 11315348287670, "u": 11315348295032, "recv_ms": 1787080350093, "bids": [[1000.0, 35.81], [14196.8, 0.252], [14296.8, 3.682], [14396.8, 0.266], [58227.1, 0.002], [61461.9, 0.0], [63696.8, 0.0], [64049.8, 0.0], [64373.3, 3.103], [64655.3, 0.051], [64655.6, 0.062], [64656.8, 0.085], [64667.5, 0.03], [64682.2, 1.103], [64685.2, 0.464], [64689.9, 0.471], [64690.0, 0.279], [64696.8, 5.655]], "asks": [[64696.9, 15.717], [64698.9, 0.056], [64705.5, 0.077], [64706.9, 0.025], [64709.8, 0.005], [64758.9, 0.022], [64759.3, 0.061], [64800.0, 11.032], [65343.9, 2.292], [65539.8, 1.532], [65696.9, 0.01], [65826.7, 2.206]]}
{"kind": "depth", "E": 1787080350245, "U": 11315348295213, "u": 11315348301210, "recv_ms": 1787080350196, "bids": [[1000.0, 35.81], [14196.8, 0.49], [14296.8, 3.57], [14396.8, 0.14], [58227.1, 0.002], [62108.9, 0.006], [63850.1, 9.563], [64049.8, 0.0], [64373.3, 3.104], [64556.7, 0.0], [64632.1, 0.004], [64662.6, 0.0], [64689.7, 0.154], [64689.9, 0.317], [64691.5, 0.407], [64692.9, 0.032]], "asks": [[64705.0, 0.019], [64761.6, 1.612], [64836.9, 0.0], [65020.4, 3.228], [65343.9, 2.292], [65368.8, 0.0], [65811.0, 4.112]]}
{"kind": "depth", "E": 1787080350347, "U": 11315348301288, "u": 11315348308097, "recv_ms": 1787080350297, "bids": [[14196.8, 0.728], [14296.8, 3.444], [14396.8, 0.028], [51757.4, 0.0], [51758.0, 0.0], [58227.1, 0.002], [61461.9, 0.0], [62108.9, 0.003], [63487.0, 0.943], [63625.0, 0.699], [63696.8, 0.02], [63758.7, 2.192], [64539.7, 7.742], [64539.8, 0.0], [64540.7, 1.236], [64556.7, 4.666], [64655.3, 0.037], [64680.6, 0.689], [64685.3, 0.261], [64689.2, 0.008], [64693.4, 0.315], [64693.9, 0.084], [64696.8, 5.676]], "asks": [[64697.6, 0.003], [64698.3, 0.024], [64698.9, 0.056], [64701.9, 0.119], [64705.5, 0.077], [64706.9, 0.025], [64709.8, 0.005], [64736.8, 0.001], [64743.7, 0.216], [64836.9, 5.398], [64851.9, 1.277], [64853.8, 10.408], [64853.9, 0.37], [64892.7, 4.806], [65217.5, 8.45], [65273.4, 3.068], [65343.9, 2.292], [65505.6, 2.907], [65508.6, 16.795], [65696.9, 0.03], [65990.8, 0.006]]}
{"kind": "depth", "E": 1787080350449, "U": 11315348308257, "u": 11315348314293, "recv_ms": 1787080350398, "bids": [[1000.0, 35.81], [14196.8, 1.064], [14296.8, 3.136], [14396.8, 0.0], [58227.1, 0.002], [62108.9, 0.006], [63855.6, 1.486], [64049.8, 0.0], [64373.3, 3.114], [64669.6, 0.122], [64677.0, 1.145], [64680.6, 0.699], [64696.8, 5.675]], "asks": [[64698.9, 0.056], [64705.5, 0.077], [64706.9, 0.025], [64709.8, 0.005], [64826.3, 0.0], [65273.4, 2.838], [65343.9, 2.294], [65345.6, 1.302], [65638.0, 32.945], [65661.6, 6.082]]}
{"kind": "depth", "E": 1787080350551, "U": 11315348314369, "u": 11315348319824, "recv_ms": 1787080350512, "bids": [[1000.0, 35.81], [14196.8, 1.414], [14296.8, 2.786], [58227.1, 0.002], [62108.9, 0.003], [63696.8, 0.0], [63923.4, 35.782], [64049.8, 0.0], [64556.7, 0.0], [64680.8, 0.001]], "asks": [[64713.3, 0.0], [64836.9, 0.0], [65214.5, 1.833], [65279.2, 5.046], [65343.9, 2.292], [65562.1, 4.196], [65635.0, 3.957], [65696.9, 0.01]]}
{"kind": "depth", "E": 1787080350653, "U": 11315348320113, "u": 11315348328032, "recv_ms": 1787080350609, "bids": [[14196.8, 1.764], [14296.8, 2.436], [51758.0, 0.0], [58227.1, 0.002], [63518.1, 0.01], [63609.9, 1.3], [63696.8, 0.02], [64049.8, 0.002], [64501.0, 0.408], [64539.7, 0.0], [64556.2, 0.732], [64623.0, 6.569], [64680.8, 0.003], [64690.2, 0.212], [64696.8, 5.661]], "asks": [[64698.9, 0.211], [64705.5, 0.387], [64706.9, 0.335], [64709.8, 0.16], [64713.3, 0.002], [64765.2, 6.824], [64767.9, 0.009], [64772.3, 39.87], [64851.9, 2.673], [64853.8, 0.0], [64892.7, 0.007], [65020.4, 3.227], [65279.2, 7.34], [65343.9, 2.292], [65618.6, 3.645], [65696.9, 0.03]]}
{"kind": "depth", "E": 1787080350755, "U": 11315348328057, "u": 11315348334518, "recv_ms": 1787080350713, "bids": [[1000.0, 35.81], [14196.8, 2.128], [14296.8, 2.072], [58227.1, 0.002], [61461.9, 0.0], [62108.9, 0.006], [63920.4, 14.2], [64049.8, 0.0], [64373.3, 3.105], [64500.9, 12.638], [64539.7, 6.392], [64556.7, 3.645], [64599.8, 6.671], [64676.2, 0.083], [64682.2, 0.485], [64682.8, 0.009], [64683.2, 0.565], [64685.3, 0.137], [64686.1, 2.868], [64686.8, 0.147], [64690.2, 0.002], [64693.0, 0.025], [64693.4, 0.005], [64693.5, 0.001], [64693.9, 0.0], [64696.8, 5.306]], "asks": [[64697.0, 0.07], [64697.1, 0.003], [64697.3, 0.084], [64697.4, 0.0], [64697.7, 0.084], [64698.2, 0.086], [64698.3, 0.031], [64698.9, 0.056], [64699.3, 0.002], [64699.9, 0.562], [64701.9, 0.035], [64704.5, 1.19], [64705.5, 0.077], [64706.9, 0.025], [64709.8, 0.005], [64715.1, 0.042], [64717.7, 0.774], [64718.3, 0.134], [64719.4, 0.004], [64764.2, 0.006], [64765.2, 1.225], [64768.0, 38.548], [64770.1, 0.001], [64772.3, 1.251], [64836.8, 6.589], [64853.8, 10.408], [64890.5, 0.18], [64892.7, 5.095], [65273.8, 0.006], [65279.2, 7.57], [65343.9, 2.292], [65538.0, 4.448], [65667.4, 6.47]]}
{"kind": "depth", "E": 1787080350857, "U": 11315348334727, "u": 11315348340582, "recv_ms": 1787080350809, "bids": [[1000.0, 35.81], [14196.8, 2.478], [14296.8, 1.722], [58227.1, 0.002], [61461.9, 0.0], [62108.9, 0.003], [63402.9, 0.919], [63499.9, 5.967], [63888.1, 2.237], [64049.8, 0.0], [64685.3, 0.261], [64690.2, 0.002], [64696.8, 5.243]], "asks": [[64698.6, 0.003], [64698.9, 0.056], [64699.1, 1.727], [64705.5, 0.077], [64706.9, 0.025], [64709.8, 0.005], [64717.7, 0.233], [64718.3, 0.675], [64761.7, 0.0], [64762.1, 6.051], [64892.7, 4.804], [65343.9, 2.292], [65638.0, 31.88]]}
{"kind": "depth", "E": 1787080350959, "U": 11315348340736, "u": 11315348346381, "recv_ms": 1787080350909, "bids": [[14196.8, 2.842], [14296.8, 1.358], [58227.1, 0.002], [61461.9, 0.0], [61462.0, 0.01], [62108.9, 0.006], [63402.9, 0.916], [63696.8, 0.0], [64049.8, 0.0], [64052.8, 1.995], [64556.7, 4.658], [64690.1, 0.639], [64692.7, 0.233], [64693.0, 0.109], [64696.8, 5.257]], "asks": [[64698.6, 0.0], [64698.8, 0.003], [64698.9, 0.056], [64705.5, 0.077], [64706.9, 0.025], [64709.8, 0.005], [64712.2, 2.651], [64712.5, 1.247], [64836.8, 6.589], [64892.7, 4.897], [65343.9, 2.292], [65532.4, 2.135], [65635.0, 5.022], [65696.9, 0.01]]}
{"kind": "depth", "E": 1787080351061, "U": 11315348346579, "u": 11315348355027, "recv_ms": 1787080351013, "bids": [[1000.0, 35.81], [14196.8, 3.192], [14296.8, 1.008], [58227.1, 0.002], [61461.9, 0.0], [62108.9, 0.003], [63208.8, 0.316], [64049.8, 0.0], [64373.3, 3.105], [64645.1, 2.183], [64645.2, 0.003], [64653.5, 2.205], [64655.3, 0.051], [64658.3, 0.252], [64661.8, 3.821], [64667.5, 0.016], [64685.2, 0.464], [64692.7, 0.023], [64693.8, 0.087], [64696.8, 5.376]], "asks": [[64696.9, 15.607], [64697.0, 0.068], [64697.1, 0.0], [64697.3, 0.0], [64697.4, 0.002], [64697.7, 0.0], [64698.9, 0.056], [64705.5, 0.077], [64706.9, 0.025], [64709.8, 0.005], [64795.0, 2.157], [64795.1, 0.0], [64803.4, 2.128], [64803.5, 0.008], [64811.7, 2.15], [64811.8, 0.41], [64828.9, 0.094], [65281.6, 1.083], [65343.9, 2.292], [65408.6, 4.964], [65505.6, 3.249]]}
{"kind": "depth", "E": 1787080351163, "U": 11315348355090, "u": 11315348367450, "recv_ms": 1787080351117, "bids": [[1000.0, 35.81], [14196.8, 3.556], [14296.8, 0.644], [58227.1, 0.002], [61461.9, 0.0], [63696.8, 0.02], [64049.8, 0.0], [64658.3, 0.238], [64667.4, 0.02], [64674.1, 0.621], [64681.5, 1.866], [64685.6, 0.003], [64687.9, 1.112], [64690.1, 0.744], [64696.8, 5.399]], "asks": [[64696.9, 15.628], [64698.9, 0.056], [64700.0, 0.845], [64702.1, 0.001], [64705.5, 0.077], [64706.9, 0.025], [64709.8, 0.005], [64712.2, 2.651], [64713.1, 0.743], [65343.9, 2.292], [65696.9, 0.03]]}
{"kind": "depth", "E": 1787080351265, "U": 11315348367701, "u": 11315348376631, "recv_ms": 1787080351222, "bids": [[14196.8, 3.766], [14296.8, 0.364], [14596.8, 0.07], [51758.0, 0.0], [58227.1, 0.002], [61461.9, 0.0], [62108.9, 0.006], [63845.2, 0.782], [63891.1, 20.279], [64049.8, 0.156], [64373.3, 3.104], [64539.7, 0.0], [64556.7, 0.0], [64599.8, 6.679], [64690.1, 0.639], [64693.1, 0.025], [64693.8, 0.003], [64696.8, 5.363]], "asks": [[64697.3, 0.002], [64697.4, 0.084], [64698.9, 0.056], [64699.1, 1.729], [64702.1, 0.0], [64705.5, 0.077], [64706.9, 0.025], [64709.8, 0.005], [64836.8, 1.191], [64851.9, 1.277], [64853.8, 0.0], [65343.9, 2.292], [65402.8, 0.682], [65440.9, 0.67], [65540.3, 1.068], [65613.3, 0.764]]}
{"kind": "depth", "E": 1787080351367, "U": 11315348376929, "u": 11315348383698, "recv_ms": 1787080351317, "bids": [[1000.0, 35.81], [14196.8, 3.654], [14296.8, 0.238], [14596.8, 0.308], [51757.0, 0.0], [51757.4, 0.0], [58227.1, 0.002], [62108.9, 0.003], [63696.8, 0.0], [63955.8, 8.587], [64049.8, 0.156], [64373.3, 3.114], [64500.9, 0.013], [64501.2, 4.902], [64696.8, 5.37]], "asks": [[64698.9, 0.056], [64705.5, 0.077], [64706.9, 0.025], [64709.8, 0.005], [64724.6, 0.233], [64724.7, 0.275], [64826.3, 0.001], [64892.7, 0.007], [65020.4, 3.228], [65343.9, 2.292], [65464.4, 10.356], [65691.5, 3.086], [65696.9, 0.01]]}
{"kind": "depth", "E": 1787080351469, "U": 11315348383867, "u": 11315348390289, "recv_ms": 1787080351421, "bids": [[1000.0, 35.81], [14196.8, 3.542], [14296.8, 0.112], [14596.8, 0.546], [58227.1, 0.002], [61461.9, 0.0], [62108.9, 0.006], [63850.1, 8.468], [63888.1, 2.393], [64049.8, 0.156], [64500.9, 15.017], [64539.7, 7.743], [64556.7, 4.666], [64663.9, 0.001], [64664.0, 1.223], [64664.1, 0.011], [64667.3, 3.095], [64667.4, 0.018], [64667.5, 0.014], [64696.8, 5.346]], "asks": [[64698.9, 0.056], [64705.5, 0.077], [64706.9, 0.025], [64709.8, 0.005], [64826.3, 0.0], [64836.8, 6.589], [64853.8, 10.408], [64892.7, 4.804], [65343.9, 2.292]]}
{"kind": "depth", "E": 1787080351571, "U": 11315348390364, "u": 11315348396134, "recv_ms": 1787080351524, "bids": [[14196.8, 3.416], [14296.8, 0.0], [14596.8, 0.784], [58227.1, 0.002], [61461.9, 0.0], [63664.6, 4.392], [63696.8, 0.02], [63761.7, 30.153], [63955.8, 7.65], [64049.8, 0.156], [64663.9, 0.001], [64664.6, 0.059], [64665.5, 0.001], [64674.5, 0.56], [64675.3, 0.004], [64675.5, 0.005], [64676.3, 0.004], [64676.5, 0.008], [64677.0, 1.145], [64677.9, 0.231], [64679.9, 0.017], [64680.4, 0.463], [64680.6, 1.625], [64681.4, 1.287], [64686.8, 0.147], [64688.0, 0.914], [64688.1, 0.579], [64689.2, 0.007], [64689.7, 0.155], [64690.1, 0.639], [64691.9, 0.035], [64692.7, 0.001], [64692.8, 0.018], [64693.4, 0.089], [64693.5, 0.024], [64693.6, 0.02], [64696.8, 5.294]], "asks": [[64696.9, 15.736], [64697.1, 0.002], [64697.2, 0.0], [64697.3, 0.0], [64697.4, 0.0], [64698.2, 0.085], [64698.3, 0.024], [64698.7, 0.091], [64698.8, 0.0], [64698.9, 0.056], [64699.0, 1.425], [64705.5, 0.077], [64706.9, 0.025], [64709.8, 0.005], [64712.3, 1.435], [64713.1, 0.743], [64713.8, 2.711], [64713.9, 0.963], [64714.8, 0.118], [64715.7, 0.687], [64715.8, 0.066], [64716.3, 0.164], [64716.4, 6.135], [64716.6, 0.006], [64716.9, 0.008], [64717.2, 0.001], [64717.3, 5.06], [64718.1, 0.546], [64718.2, 0.014], [64718.3, 0.134], [64719.1, 0.041], [64719.4, 0.004], [64719.9, 0.154], [64720.6, 0.081], [64720.7, 0.214], [65343.9, 2.294], [65402.8, 0.453], [65408.6, 5.193], [65473.3, 13.665], [65508.6, 16.566], [65635.0, 5.782], [65638.0, 30.815], [65667.4, 8.051], [65696.9, 0.03]]}
{"kind": "depth", "E": 1787080351673, "U": 11315348396331, "u": 11315348404244, "recv_ms": 1787080351632, "bids": [[1000.0, 35.81], [14196.8, 3.066], [14596.8, 1.134], [58227.1, 0.004], [61461.9, 0.0], [62108.9, 0.003], [63761.7, 29.058], [63817.8, 7.744], [63850.1, 8.155], [63952.8, 1.874], [63955.8, 6.714], [64049.8, 0.156], [64373.3, 3.114], [64376.3, 3.693], [64556.2, 0.001], [64556.8, 1.594], [64620.6, 2.395], [64674.1, 0.003], [64680.8, 0.003], [64681.5, 1.248], [64685.6, 0.002], [64689.7, 0.001], [64689.9, 0.085], [64690.1, 0.793], [64690.2, 0.002], [64693.0, 0.002], [64693.1, 0.005], [64693.4, 0.005], [64693.5, 0.001], [64693.6, 0.001], [64696.8, 5.295]], "asks": [[64696.9, 14.932], [64697.0, 0.067], [64697.1, 0.002], [64697.2, 0.084], [64697.4, 0.0], [64697.6, 0.087], [64697.7, 0.001], [64698.9, 0.075], [64699.0, 0.877], [64699.2, 0.324], [64699.5, 0.392], [64699.8, 2.505], [64699.9, 0.529], [64700.2, 0.004], [64701.2, 0.063], [64705.5, 0.625], [64706.9, 0.025], [64709.8, 0.005], [64713.1, 0.125], [64713.3, 0.002], [64722.5, 1.003], [64765.2, 6.812], [64835.2, 3.46], [65023.4, 1.695], [65217.5, 8.144], [65343.9, 2.292], [65476.3, 27.224]]}
{"kind": "depth", "E": 1787080351775, "U": 11315348404282, "u": 11315348410492, "recv_ms": 1787080351726, "bids": [[1000.0, 35.81], [14196.8, 2.702], [14596.8, 1.498], [51757.0, 0.0], [58227.1, 0.002], [61461.9, 0.0], [62108.9, 0.006], [63661.7, 1.539], [63696.8, 0.0], [63758.7, 3.289], [63779.9, 6.984], [63855.7, 1.721], [63891.1, 20.014], [63955.8, 5.777], [64049.8, 0.158], [64373.3, 3.113], [64539.7, 5.298], [64556.7, 3.09], [64556.8, 0.002], [64690.1, 0.793], [64696.8, 5.341]], "asks": [[64696.9, 14.934], [64698.9, 0.23], [64699.0, 1.425], [64699.9, 0.527], [64700.4, 0.063], [64701.0, 0.051], [64701.2, 0.001], [64705.4, 0.004], [64705.5, 0.387], [64706.9, 0.335], [64709.8, 0.16], [64710.3, 0.161], [64835.2, 2.703], [64836.8, 6.589], [65327.1, 9.127], [65343.9, 2.292], [65517.4, 1.524], [65635.0, 6.847], [65696.9, 0.01]]}
{"kind": "depth", "E": 1787080351877, "U": 11315348410559, "u": 11315348417407, "recv_ms": 1787080351829, "bids": [[14196.8, 2.352], [14596.8, 1.848], [51757.0, 0.0], [58227.1, 0.002], [62108.9, 0.003], [63402.9, 0.919], [63823.4, 0.313], [63952.8, 2.811], [64049.8, 0.156], [64635.0, 0.041], [64635.3, 0.409], [64635.6, 0.234], [64635.9, 0.022], [64636.3, 0.005], [64653.9, 0.015], [64654.3, 0.03], [64654.6, 0.002], [64654.9, 2.319], [64655.2, 0.0], [64668.9, 0.003], [64669.0, 0.001], [64669.1, 0.086], [64669.2, 0.124], [64669.3, 0.0], [64669.4, 0.002], [64669.5, 0.003], [64669.6, 0.022], [64669.7, 0.056], [64669.8, 0.003], [64671.7, 0.95], [64672.1, 0.037], [64672.5, 0.002], [64683.3, 0.657], [64688.8, 0.002], [64689.7, 0.0], [64690.1, 0.793], [64690.7, 0.002], [64690.8, 0.064], [64690.9, 0.0], [64691.0, 0.257], [64691.1, 0.086], [64691.2, 0.061], [64691.3, 1.599], [64691.4, 0.016], [64691.5, 0.307], [64691.6, 0.0], [64691.7, 0.002], [64691.8, 0.008], [64691.9, 0.003], [64692.2, 0.002], [64692.5, 0.087], [64692.9, 0.084], [64693.2, 0.0]], "asks": [[64698.9, 0.075], [64705.5, 0.077], [64706.5, 0.001], [64706.8, 0.001], [64706.9, 0.025], [64707.1, 0.442], [64707.4, 1.467], [64707.8, 0.524], [64708.0, 0.223], [64708.1, 0.111], [64708.2, 0.005], [64708.3, 0.258], [64708.4, 0.001], [64708.5, 0.536], [64708.6, 2.742], [64708.7, 0.003], [64708.8, 0.006], [64708.9, 0.234], [64709.0, 1.079], [64709.8, 0.005], [64725.4, 0.022], [64725.8, 1.418], [64726.1, 0.216], [64726.4, 0.007], [64726.7, 0.0], [64727.1, 0.0], [64727.5, 0.001], [64729.8, 0.005], [64730.0, 0.019], [64730.1, 0.033], [64730.2, 0.0], [64730.3, 0.174], [64730.4, 0.22], [64730.5, 0.964], [64730.6, 0.404], [64730.7, 0.001], [64730.8, 0.002], [64744.4, 0.0], [64744.7, 0.067], [64745.1, 1.004], [64745.4, 0.316], [64745.7, 0.0], [65020.4, 3.229], [65214.5, 2.139], [65343.9, 2.292], [65408.6, 5.422], [65473.3, 14.427], [65831.8, 0.0]]}
{"kind": "depth", "E": 1787080351979, "U": 11315348417521, "u": 11315348423879, "recv_ms": 1787080351930, "bids": [[1000.0, 35.96], [14196.8, 1.988], [14596.8, 2.212], [58227.1, 0.002], [61461.9, 0.0], [61462.1, 0.004], [62108.9, 0.006], [63696.8, 0.02], [63758.7, 4.384], [63850.1, 7.061], [63855.7, 2.034], [63952.8, 3.747], [63999.2, 0.0], [64049.8, 0.156], [64373.3, 3.268], [64651.5, 0.189], [64654.1, 0.099], [64654.7, 0.157], [64655.0, 0.057], [64683.3, 0.116], [64683.4, 0.245], [64686.5, 0.171], [64686.8, 0.144], [64687.9, 1.113], [64688.8, 0.001], [64689.0, 0.001], [64691.4, 0.086], [64691.6, 0.548], [64691.8, 0.001], [64691.9, 0.003], [64692.0, 0.043], [64692.7, 0.033], [64693.0, 0.034], [64696.8, 5.34]], "asks": [[64697.0, 0.069], [64697.1, 0.0], [64697.2, 0.0], [64697.4, 0.0], [64697.7, 0.0], [64698.1, 0.001], [64698.9, 0.075], [64704.4, 0.044], [64705.5, 0.077], [64706.5, 0.033], [64706.9, 0.063], [64707.5, 0.038], [64708.2, 0.082], [64709.8, 0.005], [64712.3, 1.435], [64717.5, 2.536], [64722.8, 0.006], [64725.5, 0.032], [64725.6, 0.003], [64725.9, 0.047], [64726.5, 0.053], [64730.0, 0.096], [64744.5, 0.033], [64744.8, 0.347], [64745.5, 0.046], [64755.2, 0.319], [64892.6, 5.115], [64892.7, 0.007], [65020.4, 3.383], [65311.5, 2.672], [65336.4, 0.001], [65343.9, 2.292], [65696.9, 0.03], [65816.2, 0.758]]}
{"kind": "depth", "E": 1787080352183, "U": 11315348430690, "u": 11315348442405, "recv_ms": 1787080352134, "bids": [[14196.8, 1.274], [14596.8, 2.926], [51757.0, 0.0], [58227.1, 0.002], [61461.9, 0.0], [61462.0, 0.01], [61462.1, 0.006], [62108.9, 0.003], [63696.8, 0.0], [63710.4, 0.027], [63758.7, 5.48], [64049.8, 0.156], [64182.2, 4.075], [64635.7, 0.191], [64679.2, 1.002], [64680.2, 0.037], [64681.9, 0.216], [64687.8, 0.324], [64688.3, 0.077], [64689.2, 0.008], [64689.3, 0.333], [64690.2, 0.018], [64690.9, 0.07], [64691.1, 0.186], [64691.3, 1.699], [64691.4, 0.186], [64691.5, 0.407], [64691.6, 0.718], [64691.8, 0.071], [64692.2, 0.044], [64696.8, 5.367]], "asks": [[64698.9, 1.23], [64699.0, 0.877], [64699.1, 1.188], [64699.2, 0.323], [64699.4, 2.323], [64699.8, 2.503], [64700.3, 0.004], [64700.4, 0.001], [64702.5, 0.071], [64705.0, 0.174], [64705.4, 0.552], [64705.5, 0.232], [64706.9, 0.373], [64707.7, 0.63], [64707.8, 0.622], [64708.0, 0.427], [64708.1, 0.231], [64708.3, 0.368], [64708.4, 0.101], [64708.6, 2.819], [64709.8, 0.16], [64718.8, 0.022], [64723.7, 0.164], [64729.6, 0.125], [64729.8, 0.209], [64729.9, 0.121], [64730.1, 0.143], [64730.2, 0.1], [64730.4, 0.297], [64731.1, 1.084], [65217.5, 7.225], [65343.9, 2.292], [65696.9, 0.01], [65939.3, 0.757]]}
{"kind": "depth", "E": 1787080352285, "U": 11315348442626, "u": 11315348450942, "recv_ms": 1787080352237, "bids": [[1000.0, 35.81], [14196.8, 0.924], [14596.8, 3.276], [51757.0, 0.0], [51758.0, 0.0], [58227.1, 0.002], [61461.9, 0.0], [62108.9, 0.006], [63855.7, 3.128], [64049.8, 0.156], [64179.2, 6.383], [64373.3, 3.258], [64635.1, 0.377], [64636.1, 0.038], [64664.0, 1.28], [64664.6, 0.002], [64669.3, 0.07], [64674.5, 0.56], [64675.3, 0.004], [64676.3, 0.12], [64677.0, 1.029], [64679.9, 0.943], [64680.6, 0.699], [64688.3, 0.093], [64689.6, 0.017], [64690.2, 0.002], [64690.9, 0.14], [64691.0, 0.397], [64691.2, 0.161], [64691.3, 1.799], [64693.6, 0.085], [64696.8, 5.325]], "asks": [[64697.6, 0.003], [64698.9, 1.075], [64701.3, 0.608], [64701.4, 0.004], [64702.5, 0.071], [64703.1, 0.008], [64704.9, 0.014], [64705.0, 0.919], [64705.4, 0.545], [64705.5, 0.084], [64705.7, 1.255], [64705.8, 2.393], [64706.9, 0.063], [64708.2, 0.192], [64708.3, 0.498], [64708.6, 2.91], [64708.7, 0.08], [64709.8, 0.005], [64712.4, 0.001], [64713.3, 0.927], [64713.9, 0.038], [64715.9, 0.023], [64716.8, 0.51], [64717.3, 5.003], [64723.3, 0.311], [64727.3, 0.502], [64730.0, 0.206], [64730.3, 0.349], [64730.5, 1.111], [64765.2, 1.225], [64768.0, 0.012], [64772.3, 1.251], [65214.5, 3.058], [65313.1, 1.3], [65343.9, 2.292], [65402.9, 9.557], [65473.3, 17.782], [65540.2, 1.066], [65683.2, 0.027], [66480.3, 0.0]]}
{"kind": "depth", "E": 1787080352387, "U": 11315348450954, "u": 11315348457115, "recv_ms": 1787080352339, "bids": [[14196.8, 0.56], [14596.8, 3.64], [51757.4, 0.0], [58227.1, 0.002], [62108.9, 0.003], [63494.3, 1.343], [63696.8, 0.02], [63772.5, 0.006], [63782.2, 4.096], [63891.1, 19.78], [64044.3, 6.507], [64044.5, 0.001], [64049.8, 0.156], [64319.3, 0.315], [64319.7, 0.001], [64594.9, 0.094], [64635.4, 2.355], [64636.4, 0.032], [64669.6, 0.092], [64690.1, 0.639], [64696.8, 5.303]], "asks": [[64698.9, 1.075], [64704.3, 0.012], [64704.4, 0.044], [64704.9, 0.006], [64705.4, 0.004], [64705.5, 0.0], [64705.6, 0.64], [64705.7, 1.239], [64706.9, 0.533], [64709.8, 0.005], [64768.0, 38.596], [64770.1, 0.001], [64826.3, 0.0], [65020.4, 3.382], [65343.9, 2.292], [65696.9, 0.03], [65923.6, 4.09], [65990.8, 0.006]]}
{"kind": "depth", "E": 1787080352489, "U": 11315348457295, "u": 11315348462782, "recv_ms": 1787080352442, "bids": [[14196.8, 0.322], [14496.8, 0.112], [14596.8, 3.766], [58227.1, 0.002], [61461.9, 0.0], [63610.9, 0.0], [63760.9, 7.672], [64049.8, 0.156], [64179.2, 6.694], [64373.3, 3.259], [64500.9, 0.013], [64539.7, 0.0], [64556.7, 0.0], [64595.8, 5.213], [64628.1, 0.027], [64650.7, 0.473], [64651.5, 0.189], [64666.9, 0.325], [64669.0, 0.071], [64669.2, 0.194], [64672.7, 0.124], [64689.4, 0.156], [64690.0, 0.279], [64696.8, 5.289]], "asks": [[64698.9, 1.075], [64704.4, 0.044], [64705.6, 0.64], [64706.8, 0.001], [64709.4, 0.104], [64709.8, 0.005], [64712.2, 2.651], [64739.3, 0.889], [64739.4, 0.0], [64755.2, 0.319], [64761.6, 0.815], [64762.1, 0.051], [64794.5, 0.002], [64836.8, 1.191], [64853.8, 0.0], [64892.6, 0.023], [65343.9, 2.292], [65410.6, 0.233], [65615.6, 0.696], [65990.8, 0.009]]}
{"kind": "depth", "E": 1787080352591, "U": 11315348462811, "u": 11315348468778, "recv_ms": 1787080352543, "bids": [[1000.0, 35.81], [14196.8, 0.21], [14496.8, 0.364], [14596.8, 3.626], [58227.1, 0.002], [62108.9, 0.006], [63661.7, 2.637], [63664.6, 3.294], [63696.8, 0.0], [63850.1, 6.748], [63909.3, 4.624], [63911.6, 2.343], [64049.8, 0.156], [64373.3, 3.259], [64626.6, 6.006], [64649.2, 3.507], [64665.4, 1.261], [64669.1, 0.156], [64669.4, 0.102], [64669.5, 0.103], [64669.7, 0.256], [64669.8, 0.073], [64670.0, 1.474], [64680.6, 0.351], [64696.8, 5.332]], "asks": [[64698.9, 1.075], [64703.1, 0.35], [64704.3, 0.012], [64704.4, 0.044], [64704.5, 1.627], [64705.6, 0.655], [64705.8, 2.918], [64706.8, 0.001], [64706.9, 0.518], [64709.8, 0.005], [64722.0, 1.469], [64738.2, 3.5], [64760.9, 6.0], [65278.7, 0.0], [65343.9, 2.292], [65469.8, 5.49], [65696.9, 0.01], [65732.1, 1.064], [65735.1, 7.414], [66443.7, 0.902]]}
{"kind": "depth", "E": 1787080352693, "U": 11315348468886, "u": 11315348474828, "recv_ms": 1787080352645, "bids": [[14196.8, 0.084], [14496.8, 0.588], [14596.8, 3.528], [58227.1, 0.002], [61461.9, 0.0], [62108.9, 0.003], [63696.8, 0.02], [63758.7, 6.42], [64049.8, 0.156], [64556.2, 0.732], [64575.8, 3.869], [64579.9, 0.0], [64625.7, 0.023], [64626.6, 6.052], [64626.7, 2.831], [64628.3, 0.0], [64638.5, 0.008], [64669.1, 0.226], [64669.2, 0.264], [64669.5, 0.203], [64672.2, 0.106], [64680.6, 0.355], [64680.8, 0.003], [64683.8, 0.035], [64689.4, 0.366], [64691.6, 0.17], [64692.7, 0.581], [64693.6, 0.001], [64696.8, 5.346]], "asks": [[64696.9, 14.935], [64697.6, 0.003], [64698.9, 1.23], [64704.3, 0.175], [64704.4, 0.601], [64704.6, 0.266], [64705.6, 0.245], [64706.8, 0.311], [64707.8, 0.606], [64709.8, 0.16], [64713.3, 0.927], [64717.8, 1.393], [64720.7, 10.099], [64731.1, 0.466], [64735.8, 0.003], [64758.4, 1.908], [64769.0, 0.311], [64770.8, 0.014], [64806.9, 0.006], [64833.3, 3.937], [64835.0, 2.617], [64891.1, 0.676], [65343.9, 2.292], [65466.8, 3.667], [65696.9, 0.03]]}
{"kind": "depth", "E": 1787080352795, "U": 11315348474869, "u": 11315348480979, "recv_ms": 1787080352747, "bids": [[14196.8, 0.0], [14496.8, 0.868], [14596.8, 3.332], [58227.1, 0.002], [61461.9, 0.0], [61462.0, 0.008], [61462.1, 0.008], [62108.9, 0.006], [63745.8, 1.878], [63855.7, 3.441], [63888.1, 3.174], [63920.4, 14.98], [63923.4, 35.002], [64049.8, 0.156], [64500.9, 12.459], [64539.7, 6.983], [64556.7, 4.283], [64594.3, 10.002], [64595.2, 2.586], [64688.3, 0.093], [64689.4, 0.156], [64690.2, 0.002], [64695.8, 0.045], [64696.8, 5.275]], "asks": [[64698.9, 1.075], [64704.3, 0.02], [64705.6, 0.09], [64706.8, 0.001], [64709.8, 0.005], [64711.4, 0.109], [64717.4, 1.543], [64719.1, 0.037], [64720.0, 3.829], [64790.7, 3.408], [64793.3, 10.093], [64835.2, 3.46], [64836.8, 6.589], [64853.8, 10.408], [64892.6, 8.433], [65343.9, 2.293], [65663.6, 9.5]]}
{"kind": "depth", "E": 1787080352897, "U": 11315348481140, "u": 11315348486656, "recv_ms": 1787080352850, "bids": [[1000.0, 35.81], [14496.8, 1.218], [14596.8, 2.982], [58227.1, 0.002], [61462.1, 0.006], [62108.9, 0.003], [63664.6, 2.196], [63761.7, 26.866], [63909.3, 3.075], [63920.4, 16.543], [64049.8, 0.156], [64202.7, 0.0], [64373.3, 3.269], [64690.2, 0.212], [64691.7, 0.543], [64692.7, 0.04], [64696.8, 5.254]], "asks": [[64698.9, 1.075], [64704.3, 0.02], [64705.6, 0.09], [64706.8, 0.001], [64709.8, 0.005], [65020.4, 3.381], [65285.5, 0.229], [65343.9, 2.293], [65732.1, 2.127], [65735.1, 6.351]]}
{"kind": "depth", "E": 1787080352999, "U": 11315348486913, "u": 11315348493041, "recv_ms": 1787080352951, "bids": [[14496.8, 1.582], [14596.8, 2.618], [58227.1, 0.002], [63696.8, 0.0], [63888.1, 3.525], [63952.8, 4.136], [64049.8, 0.156], [64182.2, 3.764], [64373.3, 3.27], [64376.3, 3.538], [64674.5, 0.003], [64674.8, 1.197], [64675.3, 0.561], [64676.3, 0.004], [64677.1, 0.271], [64690.2, 0.212], [64691.8, 0.078], [64692.7, 0.033], [64696.8, 5.257]], "asks": [[64698.9, 1.23], [64699.0, 0.874], [64699.2, 0.326], [64704.1, 1.186], [64704.2, 0.002], [64704.3, 0.097], [64704.4, 0.06], [64705.6, 0.168], [64706.9, 0.365], [64709.8, 0.16], [65273.4, 2.609], [65343.9, 2.293], [65464.4, 7.332], [65562.1, 2.293], [65647.9, 1.292], [65696.9, 0.01]]}
{"kind": "depth", "E": 1787080353101, "U": 11315348493129, "u": 11315348500525, "recv_ms": 1787080353052, "bids": [[14496.8, 1.932], [14596.8, 2.268], [51758.0, 0.008], [58227.1, 0.002], [61461.9, 0.0], [62108.9, 0.006], [63402.9, 0.922], [63661.7, 3.735], [63758.7, 7.516], [63817.8, 7.353], [63923.4, 33.128], [64049.8, 0.156], [64575.8, 0.005], [64575.9, 3.864], [64588.6, 4.583], [64589.3, 0.003], [64617.6, 0.01], [64626.5, 0.146], [64626.6, 6.006], [64654.3, 0.028], [64682.8, 0.002], [64683.8, 0.042], [64685.2, 0.464], [64686.1, 2.559], [64687.2, 0.353], [64688.3, 0.0], [64688.6, 0.007], [64690.1, 0.849], [64690.2, 0.002], [64691.5, 0.5], [64691.7, 0.002], [64691.8, 0.071], [64692.7, 0.574], [64692.8, 0.025], [64693.4, 0.315], [64694.6, 0.084], [64695.2, 0.003], [64695.8, 0.002], [64696.3, 0.048], [64696.8, 5.314]], "asks": [[64696.9, 14.797], [64697.3, 0.002], [64697.4, 0.043], [64698.2, 0.001], [64698.7, 0.084], [64698.9, 1.075], [64699.2, 0.323], [64699.3, 0.164], [64699.5, 0.395], [64701.9, 0.119], [64702.7, 0.001], [64704.1, 0.027], [64704.2, 0.002], [64704.3, 0.012], [64704.4, 0.848], [64705.1, 0.546], [64705.4, 0.159], [64705.5, 0.463], [64705.6, 0.315], [64706.9, 0.365], [64709.8, 0.16], [64711.7, 1.057], [64712.7, 0.172], [64721.5, 0.001], [64722.3, 1.349], [64764.2, 0.024], [64769.0, 0.311], [64806.1, 2.557], [64806.3, 0.243], [64833.2, 3.969], [64833.3, 0.073], [65343.9, 2.293], [65441.6, 13.63], [65464.4, 5.82], [65715.3, 4.164], [65732.1, 3.19]]}
{"kind": "depth", "E": 1787080353203, "U": 11315348500571, "u": 11315348506696, "recv_ms": 1787080353154, "bids": [[1000.0, 35.81], [14496.8, 2.296], [14596.8, 1.904], [51758.0, 0.0], [58227.1, 0.002], [61461.9, 0.0], [62108.9, 0.003], [63696.8, 0.02], [63761.7, 25.77], [63955.8, 4.84], [64049.8, 0.156], [64097.4, 16.144], [64373.3, 3.415], [64655.3, 0.037], [64674.5, 0.621], [64681.9, 0.834], [64688.0, 0.915], [64689.9, 0.085], [64690.1, 0.639], [64691.0, 0.225], [64696.8, 5.301]], "asks": [[64698.9, 1.075], [64699.3, 0.009], [64704.3, 0.012], [64704.4, 0.693], [64704.5, 1.628], [64705.4, 0.004], [64706.9, 0.055], [64707.7, 0.629], [64709.8, 0.005], [64713.5, 0.928], [64720.8, 0.621], [65343.9, 2.293], [65473.3, 20.834], [65696.9, 0.03], [65699.7, 4.254]]}
{"kind": "depth", "E": 1787080353305, "U": 11315348506881, "u": 11315348512063, "recv_ms": 1787080353348, "bids": [[14496.8, 2.646], [14596.8, 1.554], [58227.1, 0.002], [61461.9, 0.0], [62108.9, 0.006], [63697.0, 16.154], [63761.7, 24.673], [64049.8, 0.156], [64179.2, 7.005], [64689.9, 0.085], [64690.1, 0.849], [64691.1, 0.185], [64696.8, 5.314]], "asks": [[64696.9, 14.798], [64698.9, 1.075], [64704.3, 0.012], [64705.4, 0.004], [64706.9, 0.055], [64709.8, 0.005], [64747.0, 0.0], [64817.4, 24.222], [65281.2, 0.31], [65343.9, 2.293], [65441.6, 14.546], [65538.0, 6.352], [65748.8, 0.001]]}
{"kind": "depth", "E": 1787080353407, "U": 11315348512235, "u": 11315348517794, "recv_ms": 1787080353365, "bids": [[1000.0, 35.81], [14496.8, 3.01], [14596.8, 1.19], [51757.4, 0.0], [58227.1, 0.002], [61461.9, 0.0], [61462.0, 0.01], [62108.9, 0.003], [63696.8, 0.0], [63758.7, 8.612], [63920.4, 18.418], [63952.8, 5.073], [63955.8, 3.903], [64082.2, 2.186], [64645.0, 6.114], [64674.6, 0.559], [64675.3, 0.004], [64676.2, 0.199], [64677.1, 0.155], [64688.6, 0.004], [64690.1, 0.639], [64695.9, 0.044], [64696.8, 5.308]], "asks": [[64698.9, 1.211], [64699.2, 0.28], [64699.3, 0.028], [64699.5, 0.392], [64699.8, 2.506], [64704.3, 0.167], [64705.4, 0.159], [64706.9, 0.365], [64709.8, 0.16], [64714.8, 0.118], [64715.7, 0.687], [64719.0, 0.008], [64719.9, 0.154], [64720.0, 3.944], [64826.3, 0.0], [65343.9, 2.293], [65432.6, 0.0], [65505.6, 3.707], [65691.5, 0.046], [65696.9, 0.01]]}
{"kind": "depth", "E": 1787080353509, "U": 11315348517927, "u": 11315348523366, "recv_ms": 1787080353463, "bids": [[1000.0, 35.81], [14496.8, 3.374], [14596.8, 0.826], [58227.1, 0.002], [61461.9, 0.0], [63923.4, 32.659], [63929.9, 4.685], [64049.8, 0.156], [64373.3, 3.414], [64689.4, 0.002], [64690.1, 0.793], [64690.2, 0.002], [64696.8, 5.307]], "asks": [[64698.9, 1.056], [64704.3, 0.012], [64705.4, 0.004], [64706.9, 0.055], [64709.8, 0.005], [65020.4, 3.382], [65343.9, 2.293]]}
{"kind": "depth", "E": 1787080353611, "U": 11315348523430, "u": 11315348530902, "recv_ms": 1787080353563, "bids": [[14396.8, 0.014], [14496.8, 3.696], [14596.8, 0.49], [51757.0, 0.0], [58227.1, 0.002], [61461.9, 0.0], [62108.9, 0.006], [63402.9, 0.919], [63694.0, 6.512], [63696.8, 0.02], [63758.7, 9.709], [63806.2, 44.46], [63888.1, 3.79], [63926.9, 4.685], [63952.8, 6.01], [64049.8, 0.156], [64556.7, 0.0], [64655.3, 0.051], [64658.4, 0.0], [64662.2, 0.01], [64663.9, 0.003], [64664.0, 1.282], [64664.1, 0.013], [64666.1, 0.336], [64667.3, 3.097], [64667.4, 0.02], [64667.5, 0.016], [64674.5, 0.003], [64681.9, 0.216], [64688.3, 0.0], [64690.1, 0.793], [64692.8, 0.026], [64693.4, 0.005], [64694.6, 0.0], [64696.8, 5.327]], "asks": [[64697.9, 0.084], [64698.2, 0.002], [64698.9, 1.056], [64704.3, 0.012], [64704.5, 1.627], [64705.4, 0.004], [64706.9, 0.055], [64709.8, 0.005], [64713.5, 0.31], [64719.0, 0.012], [64720.8, 0.003], [64835.2, 2.703], [64836.8, 1.191], [65273.5, 5.817], [65343.9, 2.293], [65408.6, 6.948], [65667.4, 11.092], [65696.9, 0.03], [65732.5, 1.543]]}
{"kind": "depth", "E": 1787080353713, "U": 11315348531155, "u": 11315348539255, "recv_ms": 1787080353666, "bids": [[1000.0, 35.81], [14396.8, 0.182], [14496.8, 3.724], [14596.8, 0.294], [58227.1, 0.002], [62108.9, 0.003], [63405.9, 0.001], [63477.8, 0.003], [63549.7, 0.0], [63621.6, 0.001], [63693.5, 0.042], [63765.3, 0.027], [63791.0, 6.381], [63837.2, 0.001], [63909.1, 3.907], [63974.6, 0.781], [63981.0, 0.015], [64049.8, 0.156], [64052.9, 3.954], [64539.7, 0.0], [64638.5, 0.005], [64651.5, 0.189], [64671.7, 0.0], [64672.0, 1.589], [64680.8, 0.003], [64693.6, 0.085], [64696.8, 5.316]], "asks": [[64696.9, 14.76], [64698.9, 1.211], [64704.0, 1.047], [64704.3, 0.167], [64705.4, 0.159], [64706.9, 0.365], [64709.8, 0.16], [64713.3, 0.927], [64717.3, 0.003], [64719.0, 0.008], [64755.2, 0.319], [64765.2, 1.225], [64768.0, 0.012], [64772.3, 39.946], [64806.9, 0.003], [64853.8, 0.0], [64891.1, 1.845], [65343.9, 2.293], [65346.9, 4.434], [65418.8, 0.0], [65490.7, 0.0], [65562.6, 0.328], [65605.7, 45.065], [65634.5, 0.002], [65706.3, 0.0], [65778.2, 0.005], [65850.1, 0.001], [65922.0, 0.025], [65993.9, 0.024]]}
{"kind": "depth", "E": 1787080353815, "U": 11315348539288, "u": 11315348549902, "recv_ms": 1787080353768, "bids": [[1000.0, 35.81], [14396.8, 0.42], [14496.8, 3.598], [14596.8, 0.182], [58227.1, 0.002], [61461.9, 0.0], [62108.9, 0.006], [63696.8, 0.0], [63920.4, 18.887], [64049.8, 0.156], [64108.8, 1.323], [64373.3, 3.414], [64500.9, 14.123], [64539.7, 7.445], [64556.7, 4.517], [64575.8, 3.869], [64575.9, 0.0], [64626.5, 0.146], [64689.9, 0.155], [64690.1, 0.639], [64694.0, 0.086], [64696.8, 5.317]], "asks": [[64698.9, 1.056], [64699.3, 0.183], [64702.5, 0.612], [64702.6, 0.124], [64702.7, 0.101], [64703.9, 0.003], [64704.3, 0.012], [64704.4, 0.207], [64705.4, 0.159], [64706.9, 0.365], [64709.8, 0.16], [64734.6, 0.0], [64751.6, 0.001], [64766.8, 0.46], [64767.9, 38.704], [64769.0, 0.311], [64772.3, 1.251], [64785.6, 1.355], [64833.2, 3.969], [64836.8, 6.589], [64853.8, 10.408], [64892.6, 6.134], [65273.4, 2.379], [65281.3, 1.08], [65343.9, 2.292], [65696.9, 0.01], [67931.7, 0.038]]}
{"kind": "depth", "E": 1787080353917, "U": 11315348550093, "u": 11315348558788, "recv_ms": 1787080353875, "bids": [[14396.8, 0.644], [14496.8, 3.5], [14596.8, 0.056], [58227.1, 0.002], [61461.9, 0.0], [63605.6, 0.0], [64049.8, 0.156], [64556.2, 0.001], [64556.8, 1.572], [64696.8, 5.254]], "asks": [[64699.3, 0.028], [64702.4, 0.07], [64702.5, 0.009], [64702.7, 0.565], [64704.4, 0.129], [64705.4, 0.004], [64706.9, 0.055], [64709.8, 0.005], [64729.1, 0.028], [64748.6, 7.04], [65343.9, 2.292]]}
{"kind": "depth", "E": 1787080354019, "U": 11315348559195, "u": 11315348567742, "recv_ms": 1787080353972, "bids": [[1000.0, 35.81], [14396.8, 0.952], [14496.8, 3.248], [14596.8, 0.0], [58227.1, 0.004], [61461.9, 0.0], [61462.0, 0.008], [61462.1, 0.008], [62108.9, 0.003], [63402.9, 0.919], [63696.8, 0.02], [63761.7, 23.576], [63782.2, 3.156], [63979.5, 4.759], [64000.5, 0.016], [64049.8, 0.156], [64114.5, 3.272], [64373.3, 3.413], [64374.0, 0.165], [64638.5, 0.008], [64648.0, 1.287], [64674.6, 0.002], [64675.3, 0.561], [64676.2, 0.083], [64677.0, 1.145], [64683.3, 0.123], [64683.8, 0.035], [64686.6, 0.689], [64687.2, 0.044], [64688.0, 0.914], [64688.3, 0.0], [64691.4, 0.279], [64691.5, 0.407], [64691.7, 0.002], [64691.8, 0.072], [64692.7, 0.581], [64692.8, 0.018], [64696.8, 5.265]], "asks": [[64696.9, 14.76], [64697.0, 0.069], [64697.1, 0.0], [64697.2, 0.0], [64697.3, 0.0], [64697.4, 0.043], [64698.9, 1.211], [64699.2, 0.28], [64699.3, 0.028], [64699.5, 0.395], [64699.8, 2.503], [64701.2, 0.063], [64701.3, 0.883], [64702.3, 0.007], [64702.4, 0.008], [64702.5, 0.009], [64702.6, 0.124], [64702.7, 0.001], [64704.4, 0.199], [64705.4, 0.004], [64705.5, 0.0], [64705.6, 1.582], [64706.9, 0.365], [64709.8, 0.16], [64748.7, 0.03], [64806.9, 0.006], [65020.4, 3.383], [65281.2, 0.54], [65343.9, 2.292], [65598.9, 0.001], [65638.0, 28.685], [65696.9, 0.03]]}
{"kind": "depth", "E": 1787080354223, "U": 11315348577066, "u": 11315348584630, "recv_ms": 1787080354174, "bids": [[14396.8, 1.666], [14496.8, 2.534], [58227.1, 0.002], [61461.9, 0.0], [62108.9, 0.003], [63402.9, 0.916], [63632.3, 3.297], [63696.8, 0.0], [63697.0, 15.057], [63758.7, 11.746], [63888.1, 4.024], [64049.8, 0.156], [64460.8, 0.005], [64488.4, 0.0], [64539.7, 5.097], [64556.7, 2.99], [64654.2, 0.003], [64674.2, 0.619], [64674.4, 0.01], [64681.5, 1.866], [64696.8, 5.164]], "asks": [[64698.9, 1.056], [64699.3, 0.028], [64702.7, 0.642], [64703.6, 0.004], [64703.9, 0.003], [64704.3, 0.012], [64704.4, 0.044], [64705.4, 0.004], [64705.5, 0.0], [64705.6, 0.786], [64706.9, 0.055], [64709.8, 0.005], [64713.1, 0.743], [64720.5, 0.654], [64766.8, 0.442], [64871.3, 0.003], [64892.6, 8.021], [65343.9, 2.292], [65469.8, 4.575], [65583.3, 0.619], [65635.0, 7.912], [65696.9, 0.01], [65767.4, 5.315], [65825.4, 0.606]]}
{"kind": "depth", "E": 1787080354325, "U": 11315348584841, "u": 11315348592461, "recv_ms": 1787080354279, "bids": [[1000.0, 35.81], [14396.8, 2.03], [14496.8, 2.17], [51757.0, 0.0], [51758.0, 0.0], [58227.1, 0.002], [62108.9, 0.006], [63661.7, 4.833], [63758.7, 12.842], [63779.9, 4.656], [63985.1, 0.234], [64049.8, 0.156]], "asks": [[64702.6, 0.124], [64702.7, 0.642], [64704.4, 0.515], [64705.5, 0.0], [64705.6, 0.315], [65313.2, 2.095], [65343.9, 2.294], [65635.0, 8.977], [65732.1, 4.253], [67931.7, 0.043]]}
{"kind": "depth", "E": 1787080354427, "U": 11315348592524, "u": 11315348601747, "recv_ms": 1787080354378, "bids": [[1000.0, 35.81], [14396.8, 2.38], [14496.8, 1.82], [51757.0, 0.0], [51757.4, 0.0], [58227.1, 0.002], [61461.9, 0.0], [63256.2, 0.053], [63402.9, 0.91], [63694.0, 7.61], [63696.8, 0.02], [63911.6, 1.562], [64049.8, 0.156], [64373.3, 3.413], [64659.6, 0.339], [64666.1, 0.0], [64676.0, 0.026], [64676.6, 0.001], [64681.5, 1.248], [64688.3, 0.093], [64691.4, 0.186], [64691.7, 0.55], [64692.7, 0.033], [64696.8, 5.071]], "asks": [[64696.9, 14.811], [64697.2, 0.0], [64697.3, 0.0], [64697.4, 0.002], [64698.9, 1.056], [64699.0, 1.422], [64699.3, 0.028], [64701.2, 0.063], [64702.3, 0.007], [64702.6, 0.124], [64702.7, 0.102], [64704.3, 0.012], [64704.4, 0.044], [64705.5, 0.463], [64705.6, 0.315], [64706.9, 0.055], [64709.8, 0.005], [64714.9, 2.529], [64715.9, 0.021], [64716.2, 10.021], [64716.4, 11.135], [64720.0, 2.285], [64720.7, 0.099], [64764.2, 0.006], [64767.9, 0.009], [64772.3, 39.946], [64826.3, 0.0], [65343.9, 2.292], [65466.8, 4.582], [65696.9, 0.03], [65809.7, 1.212]]}
{"kind": "depth", "E": 1787080354529, "U": 11315348601945, "u": 11315348609162, "recv_ms": 1787080354479, "bids": [[14396.8, 2.73], [14496.8, 1.47], [34000.0, 1.146], [58227.1, 0.002], [61461.9, 0.0], [62108.9, 0.003], [63629.3, 2.2], [64049.8, 0.156], [64373.3, 3.414], [64624.3, 0.025]], "asks": [[64696.9, 14.85], [64698.9, 1.056], [64702.7, 0.565], [64704.4, 0.044], [64705.4, 0.004], [64705.5, 0.0], [64706.9, 0.055], [64709.8, 0.005], [64767.9, 38.639], [64772.3, 1.251], [65020.4, 3.382], [65343.9, 2.292], [65508.6, 16.223], [65764.4, 1.697], [67931.7, 0.048]]}
{"kind": "depth", "E": 1787080354631, "U": 11315348609290, "u": 11315348615978, "recv_ms": 1787080354585, "bids": [[1000.0, 35.81], [14396.8, 3.094], [14496.8, 1.106], [51758.0, 0.0], [58227.1, 0.002], [62108.9, 0.006], [62109.0, 0.007], [63241.1, 0.631], [63449.7, 0.004], [63696.8, 0.0], [63920.4, 20.45], [64049.8, 0.156], [64099.6, 0.008], [64663.6, 0.337], [64674.2, 0.001], [64690.3, 0.316], [64691.7, 0.002], [64692.7, 0.581], [64693.0, 0.056], [64693.1, 0.024], [64696.8, 5.164]], "asks": [[64696.9, 14.845], [64698.9, 1.056], [64699.0, 0.874], [64699.9, 0.497], [64701.2, 0.001], [64702.6, 0.186], [64702.7, 1.113], [64704.4, 0.044], [64705.4, 0.004], [64705.5, 0.0], [64705.6, 0.315], [64706.9, 0.055], [64709.8, 0.005], [64713.1, 0.125], [64714.9, 2.527], [64715.3, 0.386], [64716.2, 0.021], [64720.5, 0.036], [64892.6, 6.415], [65343.9, 2.292], [65532.2, 4.257], [65696.9, 0.01], [65990.8, 0.012]]}
{"kind": "depth", "E": 1787080354835, "U": 11315348622260, "u": 11315348633679, "recv_ms": 1787080354790, "bids": [[14296.8, 0.042], [14396.8, 3.724], [14496.8, 0.434], [58227.1, 0.002], [61462.0, 0.006], [61462.1, 0.01], [62108.9, 0.006], [63405.8, 1.032], [63696.8, 0.02], [63715.6, 0.274], [63823.4, 0.704], [63891.1, 19.429], [64049.8, 0.156], [64674.5, 0.56], [64675.3, 0.004], [64676.3, 0.12], [64677.0, 1.029], [64690.2, 0.212], [64691.8, 0.071]], "asks": [[64697.9, 0.0], [64702.7, 0.642], [64705.6, 0.786], [64714.8, 0.674], [64715.7, 0.131], [64892.6, 5.312], [65273.4, 2.149], [65343.9, 2.292], [65532.2, 3.19], [65532.4, 0.001], [65635.0, 10.042], [65696.9, 0.03], [71166.6, 0.013]]}
{"kind": "depth", "E": 1787080354937, "U": 11315348634039, "u": 11315348646380, "recv_ms": 1787080354889, "bids": [[1000.0, 35.81], [14296.8, 0.238], [14396.8, 3.696], [14496.8, 0.266], [58227.1, 0.002], [63477.7, 0.058], [63549.6, 0.058], [63621.5, 2.179], [63693.4, 0.058], [63765.2, 0.059], [63837.1, 0.061], [63909.0, 1.097], [63980.9, 0.058], [64049.8, 0.156], [64052.8, 2.053], [64080.5, 1.327], [64690.2, 0.002], [64692.2, 0.002], [64693.3, 0.244]], "asks": [[64702.5, 0.071], [64702.6, 0.665], [64702.7, 0.024], [64704.4, 0.121], [64705.5, 0.0], [64705.6, 0.786], [64714.8, 0.118], [64715.8, 0.622], [65343.9, 2.292], [65346.8, 0.405], [65418.7, 0.058], [65490.6, 0.089], [65562.5, 0.063], [65577.4, 0.001], [65634.4, 0.058], [65706.2, 0.831], [65778.1, 0.058], [65850.0, 10.466], [65921.9, 0.058], [65993.8, 0.099]]}
{"kind": "depth", "E": 1787080355039, "U": 11315348646494, "u": 11315348655392, "recv_ms": 1787080354996, "bids": [[1000.0, 35.81], [14296.8, 0.476], [14396.8, 3.57], [14496.8, 0.154], [58227.1, 0.002], [61461.9, 0.0], [62108.9, 0.003], [63664.6, 0.0], [63696.8, 0.0], [63720.0, 2.267], [64049.8, 0.156], [64373.3, 3.415], [64588.6, 2.264], [64589.7, 2.322], [64619.1, 0.004], [64638.5, 0.005], [64651.5, 0.186], [64659.6, 0.003], [64674.5, 0.003], [64675.5, 0.562], [64676.3, 0.004], [64677.1, 0.271], [64685.2, 0.469], [64688.3, 0.0], [64688.7, 0.003], [64690.3, 0.232], [64691.5, 0.5], [64692.8, 0.018], [64693.4, 0.315], [64694.5, 0.085], [64696.7, 0.182], [64696.8, 5.39]], "asks": [[64696.9, 14.668], [64697.3, 0.002], [64697.4, 0.043], [64698.9, 1.056], [64699.3, 0.183], [64699.5, 0.392], [64699.7, 0.005], [64702.6, 0.124], [64702.7, 0.642], [64703.9, 0.629], [64704.3, 0.012], [64704.4, 0.044], [64705.5, 0.0], [64705.6, 0.47], [64706.9, 0.365], [64709.8, 0.16], [64717.4, 2.729], [64719.1, 10.037], [64755.2, 0.319], [64764.2, 0.024], [64806.0, 2.362], [64806.1, 0.238], [64806.9, 0.003], [64892.6, 6.413], [65020.4, 3.381], [65273.4, 1.078], [65279.2, 7.8], [65343.9, 2.294], [65466.8, 5.497], [65505.6, 4.392], [65538.0, 8.637], [65540.0, 2.215], [65696.9, 0.01], [65735.1, 4.224], [65990.8, 0.009]]}
{"kind": "depth", "E": 1787080355141, "U": 11315348655613, "u": 11315348664028, "recv_ms": 1787080355092, "bids": [[14296.8, 0.7], [14396.8, 3.472], [14496.8, 0.028], [51757.0, 0.0], [58227.1, 0.002], [62108.9, 0.006], [63710.4, 0.019], [63710.5, 4.239], [63775.1, 0.014], [63776.6, 0.0], [63929.9, 3.748], [64049.8, 0.156], [64657.9, 0.006], [64660.5, 0.003], [64685.2, 0.464], [64687.0, 0.001], [64688.9, 0.313], [64690.6, 0.003], [64693.5, 0.002], [64695.1, 0.084], [64696.8, 5.391]], "asks": [[64696.9, 14.456], [64698.1, 0.0], [64698.7, 0.0], [64698.8, 0.0], [64699.0, 0.875], [64699.3, 0.028], [64702.2, 0.09], [64703.9, 0.003], [64704.3, 0.012], [64704.4, 0.044], [64705.4, 0.004], [64705.5, 0.001], [64705.6, 0.786], [64706.9, 0.055], [64709.8, 0.005], [64765.2, 1.225], [64767.9, 0.009], [64770.1, 38.574], [64772.3, 1.251], [65273.5, 4.747], [65343.9, 2.292], [65540.2, 2.133], [65617.1, 0.0], [65618.6, 3.637], [65683.2, 0.019], [65683.3, 0.007], [65990.8, 0.012], [71166.6, 0.013]]}
{"kind": "depth", "E": 1787080355243, "U": 11315348664202, "u": 11315348671447, "recv_ms": 1787080355194, "bids": [[1000.0, 35.81], [14296.8, 1.036], [14396.8, 3.164], [14496.8, 0.0], [51757.0, 0.0], [58227.1, 0.002], [61461.9, 0.0], [62108.9, 0.003], [63661.7, 5.931], [63696.8, 0.02], [63710.5, 4.247], [63775.1, 0.022], [63776.6, 0.008], [64049.8, 0.156], [64373.3, 3.415], [64696.8, 5.392]], "asks": [[64699.3, 0.028], [64702.4, 0.07], [64702.5, 0.009], [64702.6, 0.124], [64702.7, 0.001], [64703.9, 0.003], [64704.4, 0.678], [64705.5, 0.016], [64705.6, 0.778], [64706.9, 0.055], [64709.8, 0.005], [64767.9, 38.582], [64770.1, 0.001], [65281.2, 1.611], [65343.9, 2.292], [65417.7, 8.919], [65602.7, 9.477], [65617.1, 0.008], [65618.6, 3.645], [65683.3, 0.023], [65696.9, 0.03], [65702.7, 17.023], [65732.1, 5.317], [65895.0, 0.001]]}
{"kind": "depth", "E": 1787080355345, "U": 11315348671541, "u": 11315348678833, "recv_ms": 1787080355296, "bids": [[1000.0, 35.81], [14296.8, 1.372], [14396.8, 2.828], [58227.1, 0.002], [61461.9, 0.0], [63591.4, 2.511], [63696.8, 0.0], [63720.7, 6.913], [63779.9, 2.328], [64049.8, 0.156], [64500.8, 19.074], [64500.9, 0.013], [64539.7, 7.446], [64556.6, 4.319], [64556.7, 0.0], [64586.3, 0.031], [64586.7, 0.019], [64632.1, 0.005], [64634.0, 0.001], [64655.3, 0.037], [64674.5, 0.621], [64681.8, 0.18], [64683.2, 0.472], [64688.2, 0.001], [64688.9, 0.312], [64689.2, 0.007], [64689.8, 0.051], [64690.1, 0.004], [64690.3, 0.233], [64690.4, 2.006], [64690.5, 1.112], [64695.1, 0.0], [64696.8, 5.405]], "asks": [[64696.9, 14.558], [64698.5, 0.085], [64698.6, 0.001], [64699.0, 0.874], [64699.3, 0.183], [64702.5, 0.009], [64702.6, 0.124], [64702.7, 0.001], [64704.4, 0.199], [64705.5, 0.805], [64706.9, 0.365], [64709.8, 0.16], [64713.4, 0.784], [64716.4, 6.135], [64720.8, 0.621], [64761.6, 0.816], [64765.3, 0.002], [64766.8, 0.46], [64812.9, 0.001], [64891.1, 0.0], [64892.6, 6.413], [65343.9, 2.292], [65571.6, 0.003], [65696.9, 0.01], [67931.7, 0.053]]}
{"kind": "depth", "E": 1787080355447, "U": 11315348679031, "u": 11315348691342, "recv_ms": 1787080355407, "bids": [[14296.8, 1.75], [14396.8, 2.45], [51757.4, 0.0], [58227.1, 0.002], [61461.9, 0.0], [62108.9, 0.006], [63926.9, 5.622], [64049.8, 0.156], [64467.6, 0.019], [64548.4, 0.002], [64550.1, 2.049], [64588.6, 1.217], [64663.6, 0.001], [64667.8, 0.347], [64674.5, 0.003], [64676.0, 0.024], [64677.0, 1.031], [64679.9, 0.017], [64681.2, 0.927], [64683.2, 0.001], [64683.3, 0.116], [64684.3, 0.012], [64685.3, 0.702], [64688.1, 1.816], [64688.2, 0.472], [64690.5, 0.806], [64693.4, 0.334], [64695.2, 0.087], [64696.8, 6.855]], "asks": [[64696.9, 14.457], [64697.2, 0.002], [64697.3, 0.0], [64697.4, 0.0], [64697.9, 0.043], [64698.5, 0.001], [64698.6, 0.0], [64698.9, 1.056], [64699.0, 0.875], [64699.1, 1.104], [64699.3, 0.027], [64699.7, 0.002], [64699.8, 2.51], [64700.0, 0.845], [64700.5, 0.003], [64702.6, 0.208], [64702.7, 0.001], [64704.0, 0.147], [64704.4, 0.044], [64705.0, 0.019], [64705.1, 0.506], [64705.4, 0.004], [64705.5, 0.65], [64706.9, 0.055], [64709.1, 0.041], [64709.8, 0.005], [64713.4, 0.166], [64715.3, 0.384], [64715.8, 0.068], [64716.1, 0.996], [64717.8, 1.391], [64718.1, 0.005], [64719.0, 0.549], [64719.1, 10.039], [64720.0, 2.169], [64720.3, 0.22], [64720.8, 0.003], [64723.0, 0.003], [64766.8, 0.451], [64826.3, 0.0], [64850.4, 0.002], [65281.3, 2.15], [65343.9, 2.292], [65402.1, 1.466]]}
{"kind": "depth", "E": 1787080355549, "U": 11315348691743, "u": 11315348701134, "recv_ms": 1787080355501, "bids": [[1000.0, 35.81], [14296.8, 2.1], [14396.8, 2.1], [58227.1, 0.002], [62108.9, 0.003], [63596.9, 1.176], [63726.3, 1.488], [64035.8, 0.0], [64049.8, 0.156], [64373.3, 3.414], [64457.1, 0.006], [64521.9, 0.002]], "asks": [[64697.0, 0.067], [64697.1, 0.0], [64697.2, 0.0], [64697.4, 0.002], [64697.5, 0.001], [64697.6, 0.002], [64697.9, 0.353], [64699.2, 0.364], [64699.3, 0.027], [64705.4, 0.004], [64705.5, 0.649], [64706.9, 0.055], [64709.8, 0.005], [65343.9, 2.292], [65402.9, 9.328], [65583.3, 1.227], [65699.7, 5.318], [65906.7, 0.763]]}
{"kind": "depth", "E": 1787080355651, "U": 11315348701361, "u": 11315348710755, "recv_ms": 1787080355604, "bids": [[1000.0, 35.81], [14296.8, 2.464], [14396.8, 1.736], [51758.0, 0.0], [58227.1, 0.002], [61461.9, 0.0], [62108.9, 0.006], [62109.0, 0.006], [63402.9, 0.913], [63590.5, 0.946], [63696.8, 0.02], [63697.0, 13.961], [63760.9, 7.124], [63761.7, 21.383], [63791.0, 8.73], [64049.8, 0.156], [64543.8, 4.457], [64545.7, 11.373], [64548.5, 0.0], [64583.1, 8.801], [64630.6, 2.656], [64657.9, 0.02], [64676.5, 0.117], [64676.8, 8.162], [64677.1, 0.155], [64680.2, 0.963], [64680.7, 0.614], [64681.2, 0.001], [64683.8, 0.042], [64684.3, 0.005], [64688.6, 0.632], [64690.6, 0.087], [64694.0, 0.002], [64694.5, 0.001], [64695.2, 0.003], [64696.8, 5.18]], "asks": [[64696.9, 14.564], [64697.4, 0.086], [64698.0, 0.525], [64698.4, 0.087], [64698.8, 0.239], [64699.3, 0.002], [64699.5, 0.37], [64701.2, 0.021], [64701.5, 0.114], [64701.9, 0.035], [64702.2, 0.006], [64702.6, 0.124], [64704.3, 0.167], [64704.4, 0.601], [64705.0, 0.919], [64705.5, 0.247], [64706.9, 0.365], [64709.8, 0.16], [64717.7, 0.774], [64719.0, 0.008], [64743.5, 0.044], [64763.3, 2.78], [64810.8, 2.695], [64810.9, 10.576], [64811.1, 0.001], [64848.3, 13.72], [65020.4, 3.382], [65343.9, 2.292], [65638.0, 26.556], [65696.9, 0.03], [65702.7, 15.96]]}
{"kind": "depth", "E": 1787080355753, "U": 11315348711172, "u": 11315348719195, "recv_ms": 1787080355709, "bids": [[14296.8, 2.814], [14396.8, 1.386], [51758.0, 0.0], [58227.1, 0.002], [62108.9, 0.003], [63975.1, 3.728], [64017.5, 2.488], [64049.8, 0.156], [64543.8, 4.433], [64545.8, 2.348], [64547.2, 2.981], [64616.1, 0.016], [64616.3, 0.0], [64616.4, 0.001], [64620.7, 32.406], [64622.9, 3.939], [64623.0, 1.798], [64645.1, 2.158], [64654.3, 0.053], [64673.5, 0.014], [64675.8, 0.128], [64680.8, 0.003]], "asks": [[64696.9, 14.566], [64697.3, 0.002], [64697.4, 0.084], [64698.1, 0.001], [64698.8, 0.084], [64699.0, 0.874], [64699.9, 0.495], [64702.6, 0.665], [64702.7, 0.101], [64703.9, 0.003], [64704.0, 1.047], [64704.3, 0.012], [64704.4, 0.044], [64704.6, 0.249], [64705.5, 0.008], [64706.2, 0.374], [64706.4, 0.025], [64706.9, 0.055], [64707.4, 1.364], [64709.1, 0.001], [64709.8, 0.005], [64713.3, 0.927], [64713.6, 0.069], [64743.5, 0.002], [64765.2, 6.418], [64766.8, 0.442], [64848.2, 0.024], [64849.9, 0.002], [64851.9, 2.673], [65343.9, 2.292], [65410.6, 0.462]]}
{"kind": "depth", "E": 1787080355855, "U": 11315348719491, "u": 11315348727117, "recv_ms": 1787080355808, "bids": [[1000.0, 35.81], [14296.8, 3.178], [14396.8, 1.022], [58227.1, 0.002], [63694.0, 8.707], [63696.8, 0.0], [63758.7, 13.939], [63891.1, 19.195], [64049.8, 0.156], [64373.3, 3.424], [64392.3, 0.0], [64393.4, 0.161], [64691.5, 0.408]], "asks": [[64702.6, 0.124], [64702.7, 0.001], [64704.4, 0.052], [64705.5, 0.641], [64717.7, 0.233], [64718.3, 0.675], [65343.9, 2.292], [65635.0, 11.106], [65696.9, 0.01], [65699.7, 6.381]]}
{"kind": "depth", "E": 1787080356059, "U": 11315348734725, "u": 11315348741516, "recv_ms": 1787080356009, "bids": [[14196.8, 0.07], [14296.8, 3.752], [14396.8, 0.378], [58227.1, 0.002], [61462.0, 0.008], [61462.1, 0.008], [62108.9, 0.003], [63696.8, 0.02], [63791.0, 11.079], [64049.8, 0.156], [64373.3, 3.423], [64455.6, 0.076], [64674.5, 0.003], [64675.5, 0.562], [64679.7, 0.926], [64680.2, 0.037], [64685.2, 0.464], [64694.1, 0.084]], "asks": [[64697.0, 0.069], [64697.1, 0.0], [64697.2, 0.0], [64697.3, 0.0], [64697.4, 0.0], [64700.0, 0.848], [64700.5, 0.0], [64703.4, 0.33], [64712.1, 0.013], [64714.9, 2.527], [64715.7, 0.687], [64716.1, 0.44], [64717.3, 0.003], [64718.3, 0.675], [64719.2, 0.056], [64720.0, 2.284], [64720.3, 0.105], [65343.9, 2.292], [65585.9, 2.89], [65638.0, 25.491], [65696.9, 0.03]]}
{"kind": "depth", "E": 1787080356161, "U": 11315348741757, "u": 11315348751002, "recv_ms": 1787080356121, "bids": [[1000.0, 35.81], [14196.8, 0.28], [14296.8, 3.682], [14396.8, 0.238], [51758.0, 0.05], [58227.1, 0.0], [61461.9, 0.0], [62108.9, 0.006], [64049.8, 0.156], [64373.3, 3.413], [64390.9, 0.126], [64467.6, 0.0], [64523.8, 0.019], [64602.7, 0.0], [64610.5, 0.003], [64617.5, 0.0], [64620.7, 0.122], [64622.9, 36.223], [64624.7, 0.0], [64651.5, 0.189], [64654.2, 0.001], [64664.0, 1.225], [64664.4, 0.337], [64664.7, 0.057], [64665.7, 0.161], [64667.8, 0.011], [64676.5, 0.001], [64676.8, 3.162], [64677.2, 2.435], [64678.1, 0.002], [64679.7, 0.0], [64680.9, 1.239], [64685.3, 0.703], [64688.7, 0.0], [64693.1, 0.005], [64694.1, 0.0], [64696.8, 5.415]], "asks": [[64696.9, 14.537], [64697.0, 0.067], [64697.3, 0.002], [64697.4, 0.084], [64698.1, 0.0], [64698.3, 0.025], [64698.8, 0.239], [64701.9, 0.035], [64704.3, 0.167], [64704.4, 0.044], [64705.0, 0.019], [64705.4, 0.004], [64705.5, 0.015], [64705.6, 1.567], [64706.9, 0.365], [64709.8, 0.16], [64713.3, 0.002], [64714.1, 0.985], [64715.7, 0.131], [64715.9, 0.002], [64716.7, 0.558], [64716.8, 0.453], [64717.6, 0.058], [64718.3, 0.134], [64719.0, 0.549], [64720.0, 2.169], [64720.9, 0.118], [64733.9, 0.115], [64758.8, 0.045], [64780.5, 0.035], [64806.9, 0.006], [64827.1, 0.0], [64873.8, 0.008], [65020.4, 3.383], [65273.6, 0.076], [65343.9, 2.292], [65508.7, 0.518]]}
{"kind": "depth", "E": 1787080356263, "U": 11315348751122, "u": 11315348757369, "recv_ms": 1787080356218, "bids": [[1000.0, 35.81], [14196.8, 0.532], [14296.8, 3.542], [14396.8, 0.126], [51758.0, 0.002], [58227.1, 0.002], [62108.9, 0.003], [63424.6, 0.675], [63696.8, 0.0], [63874.0, 2.97], [63891.1, 18.961], [64049.8, 0.156], [64619.1, 0.001], [64638.5, 0.008], [64651.5, 0.186], [64689.6, 0.017], [64689.9, 0.155], [64693.0, 0.034]], "asks": [[64698.7, 0.008], [64698.8, 0.084], [64699.0, 0.866], [64704.0, 1.047], [64704.3, 0.012], [64705.6, 1.412], [64706.9, 0.055], [64709.8, 0.005], [64755.2, 0.319], [64806.9, 0.003], [65343.9, 2.292], [65505.6, 4.735], [65696.9, 0.01]]}
{"kind": "depth", "E": 1787080356365, "U": 11315348757385, "u": 11315348762377, "recv_ms": 1787080356316, "bids": [[14196.8, 0.756], [14296.8, 3.444], [14396.8, 0.0], [51758.0, 0.0], [58227.1, 0.002], [61461.9, 0.0], [63402.9, 0.91], [64049.8, 0.156], [64326.2, 0.076], [64556.6, 0.092], [64691.4, 0.281]], "asks": [[64696.9, 14.538], [64698.8, 0.084], [64704.0, 0.147], [64705.5, 0.015], [64706.9, 0.055], [64709.8, 0.005], [64826.3, 0.001], [64836.8, 1.191], [65343.9, 2.292], [65532.2, 2.123], [65570.3, 1.532], [65635.0, 12.171], [67284.8, 0.013]]}
{"kind": "depth", "E": 1787080356467, "U": 11315348762556, "u": 11315348767929, "recv_ms": 1787080356423, "bids": [[1000.0, 35.81], [14196.8, 1.12], [14296.8, 3.08], [51757.4, 0.0], [58227.1, 0.002], [61461.9, 0.0], [62108.9, 0.006], [63696.8, 0.02], [63855.7, 5.395], [64049.8, 0.156], [64373.3, 3.423], [64500.8, 19.983], [64539.6, 6.703], [64539.7, 0.0], [64556.6, 3.91], [64681.9, 0.216], [64686.6, 0.38], [64687.7, 2.483], [64688.8, 0.004], [64689.3, 0.333], [64689.8, 0.205], [64689.9, 0.001], [64694.0, 0.086], [64696.8, 6.823]], "asks": [[64697.1, 0.002], [64697.2, 0.0], [64697.3, 0.0], [64697.4, 0.0], [64698.8, 0.084], [64699.0, 0.866], [64699.1, 1.11], [64705.5, 0.015], [64706.9, 0.055], [64709.8, 0.005], [64716.5, 0.006], [64720.0, 2.17], [64723.4, 0.021], [64730.8, 0.002], [64826.3, 0.0], [64836.8, 6.589], [64853.8, 10.408], [64892.6, 6.721], [65280.7, 1.071], [65343.9, 2.292], [65476.3, 24.785], [65532.3, 8.48], [65618.6, 2.962], [65696.9, 0.03]]}
{"kind": "depth", "E": 1787080356569, "U": 11315348768027, "u": 11315348774810, "recv_ms": 1787080356526, "bids": [[1000.0, 35.81], [14196.8, 1.47], [14296.8, 2.73], [58227.1, 0.002], [61461.9, 0.0], [62108.9, 0.003], [63752.2, 0.414], [63766.4, 0.0], [63888.1, 5.158], [63909.3, 1.526], [64049.8, 0.156], [64693.5, 0.024], [64693.6, 0.104]], "asks": [[64696.9, 14.537], [64697.0, 0.067], [64697.1, 0.0], [64697.4, 0.002], [64698.8, 0.084], [64705.5, 0.015], [64706.0, 0.906], [64709.8, 0.005], [65343.9, 2.292], [65538.0, 9.704], [65539.4, 1.407]]}
{"kind": "depth", "E": 1787080356671, "U": 11315348774895, "u": 11315348783236, "recv_ms": 1787080356628, "bids": [[14196.8, 1.834], [14296.8, 2.366], [51758.0, 0.0], [58227.1, 0.002], [62108.9, 0.006], [63696.8, 0.0], [64049.8, 0.156], [64373.3, 3.424], [64618.5, 0.005], [64622.9, 36.102], [64675.8, 0.13], [64676.3, 0.004], [64677.0, 1.029], [64680.6, 0.355], [64683.2, 0.008], [64683.8, 0.035], [64686.6, 0.689], [64687.7, 2.174], [64687.8, 0.324], [64688.3, 0.0], [64688.5, 0.0], [64688.8, 0.001], [64689.2, 0.091], [64689.6, 0.101], [64689.8, 0.051], [64689.9, 0.085], [64690.3, 0.317], [64690.6, 0.18], [64691.2, 0.16], [64691.4, 0.365], [64691.5, 0.231], [64691.6, 0.718], [64691.8, 0.155], [64692.1, 0.086], [64692.5, 0.087], [64692.7, 0.033], [64692.9, 0.0], [64693.3, 0.16], [64693.4, 0.024], [64693.5, 0.023], [64693.6, 0.02], [64694.0, 0.002], [64694.4, 0.003], [64696.8, 6.73]], "asks": [[64696.9, 15.36], [64697.3, 0.002], [64697.4, 0.084], [64697.5, 0.002], [64697.9, 0.31], [64698.3, 0.024], [64698.7, 0.015], [64698.8, 0.084], [64699.3, 0.005], [64699.8, 2.503], [64699.9, 0.515], [64700.0, 0.867], [64701.2, 0.063], [64701.3, 0.608], [64701.5, 0.007], [64701.6, 0.003], [64702.4, 0.008], [64705.5, 0.015], [64706.0, 0.006], [64706.9, 0.055], [64707.0, 1.362], [64708.7, 0.095], [64709.0, 1.979], [64709.8, 0.005], [64714.7, 0.176], [64715.8, 0.066], [64717.8, 11.391], [64719.1, 0.039], [64722.3, 1.04], [64723.2, 0.316], [64785.6, 1.255], [64892.6, 4.669], [64893.9, 9.043], [65020.4, 3.382], [65343.9, 2.292], [65548.5, 0.769], [65696.9, 0.01]]}
{"kind": "depth", "E": 1787080356773, "U": 11315348783427, "u": 11315348791616, "recv_ms": 1787080356730, "bids": [[1000.0, 35.81], [14196.8, 2.198], [14296.8, 2.002], [58227.1, 0.002], [61461.9, 0.0], [63402.9, 0.913], [63920.4, 22.012], [64049.8, 0.156], [64373.3, 3.424], [64556.7, 1.466], [64623.0, 6.416], [64651.5, 0.189], [64680.8, 0.003], [64687.9, 1.266], [64688.3, 0.0], [64689.2, 0.007], [64689.6, 0.017], [64689.9, 0.001], [64690.3, 0.233], [64690.6, 0.087], [64691.2, 0.161], [64691.4, 0.458], [64691.6, 0.177], [64692.7, 0.574], [64693.1, 0.089], [64693.3, 0.138], [64693.4, 0.005], [64693.5, 0.085], [64693.6, 0.311], [64693.7, 0.003], [64693.9, 0.084], [64694.4, 0.004], [64694.5, 0.085], [64696.8, 6.731]], "asks": [[64696.9, 15.231], [64697.2, 0.0], [64697.3, 0.0], [64697.4, 0.002], [64697.5, 0.001], [64697.8, 0.046], [64698.0, 0.442], [64698.7, 0.008], [64698.8, 0.084], [64699.2, 0.371], [64701.5, 0.091], [64705.5, 0.015], [64706.9, 0.055], [64709.8, 0.005], [64713.3, 0.002], [64714.7, 0.174], [64715.4, 0.534], [64717.4, 1.543], [64717.8, 1.391], [64761.6, 1.135], [64766.8, 0.46], [64806.9, 0.006], [64835.2, 3.46], [64891.1, 1.37], [65343.9, 2.292], [65404.7, 0.015], [65469.4, 2.67], [65473.3, 21.443]]}
{"kind": "depth", "E": 1787080356875, "U": 11315348791666, "u": 11315348798588, "recv_ms": 1787080356827, "bids": [[1000.0, 35.81], [14196.8, 2.548], [14296.8, 1.652], [58227.1, 0.002], [61461.9, 0.0], [62108.9, 0.003], [63696.8, 0.02], [64049.8, 0.158], [64556.6, 0.092], [64556.7, 0.0], [64647.6, 0.667], [64687.9, 1.112], [64688.3, 0.003], [64691.6, 0.282], [64693.2, 0.022], [64693.3, 0.158], [64696.8, 6.838]], "asks": [[64696.9, 15.233], [64697.0, 0.069], [64697.1, 0.0], [64697.2, 0.0], [64697.3, 0.0], [64697.4, 0.0], [64698.8, 0.084], [64701.2, 0.001], [64701.4, 0.004], [64702.5, 0.071], [64705.5, 0.015], [64706.0, 0.906], [64709.8, 0.005], [64720.0, 3.846], [64721.5, 10.001], [64765.2, 0.0], [64766.8, 0.442], [64767.9, 0.009], [64772.3, 39.984], [64835.2, 2.703], [64836.8, 1.191], [65343.9, 2.292], [65453.9, 1.071], [65696.9, 0.03], [67284.8, 0.0]]}
{"kind": "depth", "E": 1787080357079, "U": 11315348805355, "u": 11315348811345, "recv_ms": 1787080357037, "bids": [[1000.0, 35.81], [14196.8, 3.262], [14296.8, 0.938], [58227.1, 0.002], [61461.9, 0.0], [61462.0, 0.008], [61462.1, 0.01], [62108.9, 0.003], [63632.3, 2.198], [63696.8, 0.0], [63710.4, 0.009], [63761.7, 20.286], [64049.8, 0.156], [64179.2, 7.005], [64328.1, 0.0], [64329.1, 0.856], [64373.3, 3.414], [64424.7, 0.006], [64425.6, 0.368], [64495.7, 0.001], [64495.8, 1.609], [64500.8, 19.148], [64539.6, 6.52], [64556.6, 3.824], [64618.5, 0.005], [64620.7, 32.085], [64622.9, 3.939], [64623.0, 1.798], [64630.6, 2.635], [64677.4, 5.343], [64685.1, 0.485], [64691.6, 0.177], [64694.5, 0.001], [64695.2, 0.087], [64696.8, 6.822]], "asks": [[64696.9, 15.134], [64697.7, 0.0], [64698.4, 0.003], [64698.8, 0.084], [64699.3, 0.002], [64699.7, 0.005], [64699.9, 0.567], [64701.4, 0.066], [64701.9, 0.119], [64702.5, 0.009], [64705.5, 0.015], [64709.8, 0.005], [64715.7, 0.687], [64716.7, 0.002], [64719.9, 0.269], [64720.9, 0.003], [64752.7, 0.021], [64761.6, 0.816], [64763.2, 3.929], [64763.3, 0.002], [64764.2, 0.006], [64851.9, 1.277], [64853.8, 0.0], [64854.8, 1.771], [64855.0, 8.353], [64891.1, 0.0], [64892.6, 0.023], [64893.6, 0.006], [64893.9, 17.305], [64963.6, 0.35], [64965.0, 0.001], [65020.4, 3.381], [65059.8, 0.963], [65062.4, 0.16], [65343.9, 2.292], [65593.7, 2.264], [65683.2, 0.009], [65696.9, 0.01], [65767.4, 4.252], [65799.5, 0.606], [65990.8, 0.009]]}
{"kind": "depth", "E": 1787080357181, "U": 11315348811440, "u": 11315348816387, "recv_ms": 1787080357133, "bids": [[1000.0, 35.81], [14196.8, 3.612], [14296.8, 0.588], [58227.1, 0.002], [61461.9, 0.0], [61462.0, 0.006], [61462.1, 0.01], [62108.9, 0.006], [63502.1, 0.002], [63710.5, 4.257], [64049.8, 0.156], [64153.3, 0.068], [64373.3, 3.415], [64610.4, 0.017], [64617.3, 0.002], [64624.6, 0.014], [64654.2, 0.002], [64696.8, 6.823]], "asks": [[64696.9, 15.133], [64698.8, 0.084], [64701.4, 0.004], [64701.8, 0.072], [64702.5, 0.009], [64703.0, 0.014], [64705.5, 0.015], [64709.8, 0.005], [64853.8, 10.408], [64854.8, 0.719], [64855.0, 0.688], [65343.9, 2.292]]}
{"kind": "depth", "E": 1787080357283, "U": 11315348816598, "u": 11315348822160, "recv_ms": 1787080357235, "bids": [[14196.8, 3.752], [14296.8, 0.336], [14596.8, 0.112], [51758.0, 0.0], [58227.1, 0.002], [61462.1, 0.008], [63629.3, 3.299], [63696.8, 0.02], [63758.7, 15.036], [63929.9, 2.811], [64049.8, 0.156], [64064.6, 0.109], [64212.3, 0.014], [64560.9, 0.079], [64565.4, 1.041]], "asks": [[64892.6, 6.719], [64893.9, 9.043], [65179.6, 0.001], [65329.5, 0.043], [65343.9, 2.292], [65683.3, 0.033], [65696.9, 0.03], [65783.8, 2.556], [65818.9, 0.0]]}
{"kind": "depth", "E": 1787080357385, "U": 11315348822239, "u": 11315348827004, "recv_ms": 1787080357339, "bids": [[1000.0, 35.96], [14196.8, 3.654], [14296.8, 0.21], [14596.8, 0.336], [51758.0, 0.0], [58227.1, 0.002], [61461.9, 0.0], [62108.9, 0.003], [63487.0, 1.728], [64049.8, 0.156], [64327.8, 42.077], [64329.1, 7.084], [64373.3, 3.425], [64424.5, 34.98], [64425.6, 5.543], [64473.2, 6.294], [64495.4, 27.511], [64495.8, 1.393], [64556.6, 0.092], [64696.8, 6.833]], "asks": [[64696.9, 15.134], [64697.6, 0.001], [64698.8, 0.239], [64705.5, 0.635], [64709.8, 0.16], [64826.3, 0.0], [64836.8, 1.191], [64892.1, 26.548], [64893.5, 0.001], [64894.9, 1.763], [64963.4, 5.236], [64963.5, 32.771], [64963.6, 0.005], [65059.8, 6.951], [65060.9, 41.176], [65273.5, 3.677], [65343.9, 2.292], [65602.7, 11.761], [65764.4, 2.76]]}
{"kind": "depth", "E": 1787080357487, "U": 11315348827121, "u": 11315348831756, "recv_ms": 1787080357442, "bids": [[1000.0, 35.81], [14196.8, 3.514], [14296.8, 0.098], [14596.8, 0.588], [51757.4, 0.0], [58227.1, 0.002], [62108.9, 0.006], [63696.8, 0.0], [64049.8, 0.156], [64212.0, 54.102], [64500.8, 4.962], [64539.6, 0.002], [64638.5, 0.005], [64651.5, 0.186], [64687.5, 0.0], [64687.6, 0.157]], "asks": [[64698.8, 0.084], [64705.5, 0.015], [64709.8, 0.005], [64755.2, 0.316], [64806.9, 0.003], [64853.8, 0.0], [64892.6, 0.023], [65343.9, 2.292], [65696.9, 0.01], [65990.8, 0.009]]}
{"kind": "depth", "E": 1787080357589, "U": 11315348831832, "u": 11315348837679, "recv_ms": 1787080357540, "bids": [[14196.8, 3.36], [14296.8, 0.0], [14596.8, 0.84], [58227.1, 0.002], [60608.2, 0.004], [61461.9, 0.0], [62108.9, 0.003], [63402.9, 0.916], [63888.1, 5.392], [63926.9, 6.559], [64049.8, 0.156], [64373.3, 3.424], [64500.8, 19.985], [64539.6, 6.703], [64556.6, 3.91], [64651.5, 0.189], [64673.8, 1.661], [64677.4, 0.343], [64681.2, 0.619], [64688.3, 0.003], [64691.4, 0.458], [64696.8, 6.824]], "asks": [[64696.9, 15.17], [64697.7, 0.043], [64697.8, 0.003], [64698.8, 0.239], [64705.5, 0.635], [64706.9, 0.055], [64709.8, 0.16], [64712.8, 1.337], [64720.2, 0.659], [64755.2, 0.319], [64836.8, 6.589], [64853.8, 10.408], [64892.6, 6.719], [65280.6, 1.07], [65343.9, 2.292], [65615.6, 1.152]]}
{"kind": "depth", "E": 1787080357691, "U": 11315348837717, "u": 11315348844670, "recv_ms": 1787080357642, "bids": [[1000.0, 35.81], [14196.8, 2.996], [14596.8, 1.204], [58227.1, 0.002], [61461.9, 0.0], [62108.9, 0.006], [63546.2, 0.003], [63611.0, 0.209], [63696.8, 0.02], [63744.6, 0.989], [63779.9, 0.0], [64049.8, 0.156], [64373.3, 3.414], [64473.2, 6.078], [64495.5, 0.216], [64565.4, 1.748], [64620.7, 0.122], [64622.9, 35.902], [64638.5, 0.008], [64645.0, 6.117], [64666.8, 0.016], [64673.8, 1.043], [64681.2, 0.001], [64688.3, 0.096], [64691.4, 0.365], [64693.4, 0.315], [64693.6, 0.001], [64693.9, 0.0], [64695.2, 0.003], [64696.8, 6.635]], "asks": [[64696.9, 15.214], [64697.0, 0.151], [64697.7, 0.0], [64698.4, 0.087], [64698.8, 0.084], [64699.5, 0.37], [64699.6, 0.19], [64699.9, 0.532], [64701.4, 0.066], [64701.7, 0.002], [64701.8, 0.01], [64701.9, 0.134], [64705.5, 0.015], [64708.7, 0.08], [64709.8, 0.005], [64722.1, 0.159], [64724.7, 0.121], [64806.9, 0.006], [64853.8, 10.408], [64855.0, 0.688], [64892.0, 0.216], [64892.6, 5.16], [64893.8, 0.0], [64894.9, 1.547], [65020.4, 3.382], [65343.9, 2.292], [65696.9, 0.03]]}
{"kind": "depth", "E": 1787080357793, "U": 11315348844757, "u": 11315348854797, "recv_ms": 1787080357744, "bids": [[14196.8, 2.646], [14596.8, 1.554], [51757.0, 0.0], [58227.1, 0.002], [61461.9, 0.0], [64049.8, 0.156], [64495.7, 0.02], [64523.8, 0.0], [64556.7, 1.466], [64599.7, 0.005], [64623.0, 6.387], [64660.1, 4.652], [64663.9, 0.058], [64664.0, 1.223], [64664.1, 0.011], [64664.7, 0.0], [64667.3, 3.095], [64667.4, 0.018], [64667.5, 0.014], [64674.5, 0.003], [64675.3, 0.561], [64675.5, 0.005], [64676.2, 0.083], [64676.3, 0.12], [64677.2, 2.319], [64678.7, 0.377], [64679.6, 0.166], [64679.9, 0.017], [64680.2, 0.963], [64680.7, 0.614], [64680.8, 0.001], [64680.9, 0.313], [64681.5, 1.248], [64682.4, 0.008], [64683.2, 0.001], [64688.3, 0.093], [64688.9, 0.544], [64690.0, 0.279], [64690.3, 0.085], [64690.7, 0.002], [64691.7, 0.543], [64692.1, 0.128], [64692.7, 0.033], [64693.2, 0.0], [64693.3, 0.138], [64693.4, 0.005], [64693.5, 0.001], [64693.7, 0.002], [64696.8, 4.894]], "asks": [[64696.9, 15.316], [64697.5, 0.002], [64697.9, 0.317], [64698.0, 0.441], [64698.4, 0.09], [64698.7, 0.556], [64698.8, 0.239], [64699.1, 1.104], [64699.2, 0.364], [64699.7, 0.022], [64701.2, 0.063], [64701.4, 0.004], [64705.5, 0.628], [64705.6, 0.871], [64709.8, 0.16], [64712.3, 1.435], [64712.7, 1.097], [64713.1, 0.125], [64713.3, 0.0], [64713.9, 0.038], [64714.1, 0.06], [64715.7, 0.131], [64716.4, 6.691], [64716.5, 0.006], [64717.3, 0.06], [64717.5, 12.536], [64717.6, 0.001], [64718.3, 0.675], [64719.0, 0.008], [64719.4, 0.004], [64719.9, 0.154], [64720.2, 0.041], [64720.7, 0.214], [64721.5, 0.001], [64722.1, 0.005], [64722.2, 0.167], [64730.8, 0.021], [64758.8, 0.026], [64766.8, 0.442], [64767.8, 5.785], [64785.6, 1.355], [64835.2, 3.46], [64850.0, 29.286], [64853.8, 10.408], [64855.0, 0.688], [64892.0, 4.95], [64892.6, 4.963], [64893.8, 0.0], [65343.9, 2.292]]}
{"kind": "depth", "E": 1787080357895, "U": 11315348855109, "u": 11315348864546, "recv_ms": 1787080357845, "bids": [[14196.8, 2.282], [14596.8, 1.918], [58227.1, 0.002], [62108.9, 0.003], [63531.8, 1.372], [63596.5, 1.368], [63696.8, 0.0], [63726.3, 3.054], [64049.8, 0.157], [64680.8, 0.003], [64687.4, 0.155], [64687.6, 0.003], [64688.9, 0.312], [64689.6, 0.017], [64689.7, 0.0], [64689.9, 0.002], [64690.1, 0.004], [64690.3, 0.084], [64690.4, 2.238]], "asks": [[64698.8, 0.084], [64701.1, 0.212], [64701.2, 0.001], [64704.0, 1.047], [64705.5, 0.008], [64709.8, 0.005], [64713.3, 0.002], [64720.0, 2.17], [64722.2, 0.013], [64722.4, 1.786], [64853.8, 0.0], [64855.0, 8.366], [64892.6, 0.023], [64893.8, 9.073], [65343.9, 2.292], [65505.6, 4.993], [65696.9, 0.01]]}
{"kind": "depth", "E": 1787080357997, "U": 11315348864799, "u": 11315348871286, "recv_ms": 1787080357949, "bids": [[1000.0, 35.81], [14196.8, 1.932], [14596.8, 2.268], [58227.1, 0.002], [61461.9, 0.0], [62108.9, 0.006], [63781.1, 3.984], [63838.6, 5.472], [64049.8, 0.157], [64373.3, 3.414], [64691.8, 0.156]], "asks": [[64696.9, 15.323], [64697.0, 0.153], [64697.1, 0.001], [64697.4, 0.0], [64697.5, 0.001], [64698.8, 0.104], [64699.0, 0.888], [64699.7, 0.002], [64699.9, 0.512], [64705.5, 0.008], [64705.6, 0.892], [64706.9, 0.055], [64709.8, 0.005], [64752.7, 0.0], [64853.8, 10.408], [64855.0, 0.688], [64892.6, 6.269], [64893.8, 0.0], [65343.9, 2.292], [65391.8, 5.345], [65638.0, 24.426], [65702.7, 14.896], [67934.8, 0.025]]}
{"kind": "depth", "E": 1787080358099, "U": 11315348871394, "u": 11315348877368, "recv_ms": 1787080358050, "bids": [[14196.8, 1.568], [14596.8, 2.632], [51758.0, 0.0], [58227.1, 0.002], [62108.9, 0.003], [63590.1, 0.0], [63696.8, 0.02], [63703.6, 0.0], [63888.1, 5.626], [64049.8, 0.159], [64064.1, 64.842], [64610.4, 0.018], [64617.3, 0.003], [64654.2, 0.003], [64685.2, 0.464], [64686.0, 0.321], [64686.6, 0.38], [64689.4, 0.212]], "asks": [[64697.6, 0.002], [64704.4, 0.353], [64704.5, 1.535], [64705.6, 0.583], [64720.0, 2.169], [65178.0, 52.73], [65327.9, 65.829], [65343.9, 2.292], [65690.2, 0.001], [65696.9, 0.03]]}
{"kind": "depth", "E": 1787080358201, "U": 11315348877443, "u": 11315348884955, "recv_ms": 1787080358152, "bids": [[14196.8, 1.218], [14596.8, 2.982], [51757.0, 0.0], [58227.1, 0.002], [63564.6, 4.637], [63703.5, 0.011], [64049.8, 0.157], [64373.3, 3.413], [64635.1, 0.345], [64635.4, 2.323], [64635.7, 0.159], [64636.1, 0.006], [64636.4, 0.0], [64654.1, 0.067], [64654.4, 1.164], [64654.7, 0.125], [64654.9, 2.351], [64655.0, 0.025], [64655.4, 0.005], [64669.0, 0.001], [64669.1, 0.086], [64669.2, 0.124], [64669.3, 0.0], [64669.4, 0.002], [64669.5, 0.003], [64669.6, 0.022], [64669.7, 0.056], [64669.8, 0.003], [64670.0, 1.404], [64672.2, 0.006], [64672.7, 0.024], [64688.5, 0.001], [64689.4, 0.002], [64689.9, 0.001], [64690.8, 0.064], [64690.9, 0.0], [64691.0, 0.085], [64691.1, 0.085], [64691.2, 0.061], [64691.3, 1.599], [64691.4, 0.295], [64691.5, 0.231], [64691.6, 0.007], [64691.7, 0.643], [64691.8, 0.156], [64692.0, 0.081], [64692.4, 0.005], [64692.7, 0.001], [64692.9, 0.032], [64693.0, 0.002], [64693.3, 0.106], [64695.3, 0.003]], "asks": [[64703.0, 0.015], [64706.2, 0.342], [64706.5, 0.001], [64706.6, 0.042], [64706.9, 0.017], [64707.2, 0.009], [64707.5, 0.0], [64707.6, 0.216], [64707.8, 0.712], [64707.9, 0.014], [64708.0, 0.223], [64708.1, 0.221], [64708.2, 0.105], [64708.3, 0.258], [64708.4, 0.078], [64708.5, 0.466], [64708.6, 2.742], [64708.7, 0.003], [64708.8, 0.006], [64712.2, 2.651], [64725.2, 0.137], [64725.5, 0.0], [64725.6, 0.041], [64725.9, 0.009], [64726.2, 1.243], [64726.5, 0.015], [64726.9, 0.002], [64727.3, 0.372], [64729.3, 1.069], [64729.5, 0.086], [64729.6, 0.147], [64729.8, 0.005], [64729.9, 0.111], [64730.0, 0.119], [64730.1, 0.033], [64730.2, 0.077], [64730.3, 0.104], [64730.4, 0.22], [64730.5, 0.964], [64744.2, 0.0], [64744.5, 0.001], [64744.6, 0.062], [64744.8, 0.309], [64745.1, 1.004], [64745.5, 0.008], [65020.4, 3.383], [65343.9, 2.292], [65376.2, 2.261], [65605.7, 44.882], [65635.0, 13.236], [65699.7, 7.445], [71166.6, 0.013]]}
{"kind": "depth", "E": 1787080358303, "U": 11315348885398, "u": 11315348892568, "recv_ms": 1787080358254, "bids": [[1000.0, 35.81], [14196.8, 0.854], [14596.8, 3.346], [51757.0, 0.0], [51758.0, 0.0], [58227.1, 0.002], [62108.9, 0.006], [63696.8, 0.0], [63754.0, 0.094], [63823.4, 1.329], [64049.8, 0.157], [64373.3, 3.413], [64654.3, 0.085], [64655.3, 0.069], [64678.0, 0.002], [64688.5, 0.0], [64689.2, 0.008], [64689.4, 0.002], [64691.1, 0.155], [64691.2, 0.131], [64691.3, 1.669], [64691.4, 0.395], [64691.5, 0.331], [64692.3, 0.034], [64692.7, 0.001], [64693.2, 0.032]], "asks": [[64698.4, 0.087], [64698.7, 0.559], [64706.3, 0.036], [64707.3, 0.04], [64708.0, 0.333], [64708.1, 0.351], [64708.2, 0.175], [64708.3, 0.349], [64708.5, 0.543], [64716.5, 5.006], [64725.3, 0.379], [64726.3, 0.353], [64727.1, 0.13], [64729.8, 0.115], [64730.0, 0.189], [64730.1, 0.124], [64730.2, 0.154], [64744.3, 4.317], [64745.3, 0.078], [64767.9, 0.009], [64772.3, 40.051], [64892.6, 4.95], [65343.9, 2.292], [65615.6, 1.379], [65690.1, 0.016], [65696.9, 0.01]]}
{"kind": "depth", "E": 1787080358405, "U": 11315348892702, "u": 11315348897853, "recv_ms": 1787080358355, "bids": [[14196.8, 0.504], [14596.8, 3.696], [58227.1, 0.002], [62108.9, 0.003], [64049.8, 0.157], [64074.1, 1.056], [64654.6, 0.034], [64655.6, 0.094], [64689.4, 0.002], [64689.9, 0.085], [64691.2, 0.201], [64691.6, 0.077], [64692.6, 2.083], [64693.1, 0.005], [64693.6, 0.033]], "asks": [[64706.0, 0.938], [64707.0, 1.4], [64707.9, 0.091], [64708.3, 0.433], [64725.0, 0.036], [64725.9, 0.047], [64729.7, 0.079], [64730.1, 0.208], [64744.0, 1.377], [64744.9, 0.062], [64767.8, 0.001], [64770.1, 38.899], [64772.3, 1.251], [64826.3, 0.0], [65343.9, 2.292]]}
{"kind": "depth", "E": 1787080358507, "U": 11315348897990, "u": 11315348903388, "recv_ms": 1787080358458, "bids": [[14196.8, 0.308], [14496.8, 0.168], [14596.8, 3.724], [51757.4, 0.0], [58227.1, 0.002], [62108.9, 0.006], [63696.8, 0.02], [64049.8, 0.157], [64556.6, 4.716], [64556.7, 0.0], [64636.0, 0.066], [64676.8, 1.252], [64678.3, 2.861], [64691.0, 0.155], [64691.7, 0.743], [64691.9, 0.103]], "asks": [[64707.7, 0.769], [64707.9, 0.211], [64708.5, 0.613], [64726.7, 0.14], [64729.7, 0.199], [64730.3, 0.174], [64835.2, 2.703], [64836.8, 6.589], [65343.9, 2.294], [65389.2, 0.839], [65696.9, 0.03]]}
{"kind": "depth", "E": 1787080358711, "U": 11315348909220, "u": 11315348915290, "recv_ms": 1787080358662, "bids": [[14196.8, 0.07], [14496.8, 0.644], [14596.8, 3.486], [51757.0, 0.0], [58227.1, 0.002], [63532.3, 1.573], [63696.8, 0.0], [63888.1, 5.86], [64049.8, 0.157], [64495.8, 5.356], [64556.7, 1.586], [64616.1, 1.115], [64635.7, 0.191], [64669.3, 0.14], [64669.4, 0.072], [64669.5, 0.073], [64669.7, 0.256], [64689.4, 0.212], [64695.9, 0.05], [64696.2, 0.07]], "asks": [[64717.4, 2.712], [64768.3, 6.663], [64835.2, 3.46], [65020.4, 3.382], [65343.9, 2.292], [65696.9, 0.01], [71166.6, 0.015]]}
{"kind": "depth", "E": 1787080358813, "U": 11315348915427, "u": 11315348922214, "recv_ms": 1787080358764, "bids": [[1000.0, 35.81], [14196.8, 0.0], [14496.8, 0.924], [14596.8, 3.276], [58227.1, 0.002], [62108.9, 0.006], [64049.8, 0.156], [64373.3, 3.414], [64630.6, 0.001], [64638.5, 0.005], [64651.5, 0.189], [64669.5, 0.143], [64669.8, 0.073], [64680.8, 0.001], [64689.4, 0.212]], "asks": [[64713.3, 0.0], [64755.2, 0.319], [64763.2, 1.153], [64806.9, 0.003], [65343.9, 2.292], [71166.6, 0.013]]}
{"kind": "depth", "E": 1787080358915, "U": 11315348922371, "u": 11315348929148, "recv_ms": 1787080358868, "bids": [[1000.0, 35.81], [14496.8, 1.288], [14596.8, 2.912], [58227.1, 0.002], [62108.9, 0.003], [63402.9, 0.913], [63572.7, 0.0], [63696.8, 0.02], [64049.8, 0.156], [64373.3, 3.424], [64495.7, 0.001], [64500.8, 4.962], [64539.6, 0.002], [64556.6, 0.092], [64556.7, 0.0], [64630.6, 2.626], [64638.5, 0.008], [64669.2, 0.194], [64669.9, 0.802], [64671.6, 0.619], [64672.9, 0.102], [64674.4, 0.008], [64678.1, 1.002], [64679.2, 0.002], [64680.8, 0.003], [64689.4, 0.002], [64689.6, 0.101], [64692.5, 0.003], [64692.7, 0.211], [64696.3, 0.001], [64696.8, 3.707]], "asks": [[64696.9, 15.321], [64698.3, 0.334], [64698.8, 0.104], [64699.9, 0.52], [64701.0, 0.113], [64701.1, 0.15], [64701.8, 0.002], [64703.0, 0.014], [64704.7, 0.62], [64705.5, 0.008], [64706.9, 0.017], [64709.8, 0.005], [64712.1, 0.631], [64713.3, 0.002], [64717.5, 12.538], [64719.1, 0.037], [64730.8, 0.002], [64758.6, 0.0], [64763.1, 2.823], [64768.0, 0.012], [64768.3, 0.893], [64770.1, 0.001], [64772.3, 40.149], [64806.9, 0.006], [64835.2, 2.703], [64836.8, 1.191], [64853.8, 0.0], [64892.6, 0.023], [65327.1, 8.44], [65343.9, 2.292], [65696.9, 0.03], [65803.2, 0.911], [65990.8, 0.012]]}
{"kind": "depth", "E": 1787080359017, "U": 11315348929151, "u": 11315348935011, "recv_ms": 1787080358969, "bids": [[14496.8, 1.638], [14596.8, 2.562], [58227.1, 0.002], [61461.9, 0.0], [62108.9, 0.006], [63584.0, 0.634], [63696.8, 0.0], [64049.8, 0.156], [64500.8, 20.21], [64539.6, 7.753], [64556.6, 4.742], [64664.2, 0.693], [64671.6, 0.001], [64677.3, 0.025], [64688.5, 0.001], [64689.9, 0.085], [64692.7, 0.001], [64695.8, 0.065], [64696.8, 5.028]], "asks": [[64696.9, 15.371], [64698.8, 0.259], [64700.9, 0.126], [64701.0, 0.051], [64704.7, 0.002], [64704.8, 0.028], [64705.5, 0.318], [64705.6, 0.562], [64706.9, 0.327], [64709.8, 0.16], [64712.1, 0.013], [64770.1, 38.899], [64772.3, 1.251], [64836.8, 6.589], [64853.8, 10.408], [64892.6, 4.654], [65343.9, 2.296], [65464.4, 4.308], [65696.9, 0.01]]}
{"kind": "depth", "E": 1787080359119, "U": 11315348935030, "u": 11315348942773, "recv_ms": 1787080359072, "bids": [[1000.0, 35.81], [14496.8, 2.002], [14596.8, 2.198], [58227.1, 0.002], [61461.9, 0.0], [63891.1, 18.495], [64049.8, 0.156], [64108.9, 7.71], [64575.8, 0.005], [64576.1, 3.864], [64588.5, 2.324], [64589.7, 0.003], [64610.4, 0.016], [64617.3, 0.005], [64626.4, 0.199], [64626.5, 0.1], [64654.2, 0.001], [64655.3, 0.083], [64664.4, 0.001], [64678.1, 0.002], [64679.2, 1.002], [64685.2, 0.464], [64688.3, 0.003], [64688.5, 0.0], [64689.4, 0.002], [64689.6, 0.017], [64689.9, 0.002], [64690.1, 0.004], [64690.2, 0.002], [64690.6, 0.18], [64692.8, 0.102], [64693.2, 0.116], [64693.6, 0.343], [64694.5, 0.085], [64694.9, 0.084], [64695.8, 0.101], [64695.9, 0.008], [64696.3, 0.0], [64696.8, 5.121]], "asks": [[64696.9, 15.244], [64697.0, 0.067], [64697.1, 0.0], [64697.4, 0.002], [64697.9, 0.31], [64698.0, 0.442], [64698.3, 0.024], [64698.5, 0.02], [64698.6, 0.007], [64698.8, 0.259], [64700.0, 0.845], [64700.9, 0.064], [64701.0, 0.113], [64703.5, 0.007], [64705.5, 0.318], [64706.9, 0.327], [64709.8, 0.16], [64712.7, 0.172], [64713.3, 0.927], [64764.2, 0.024], [64768.8, 0.046], [64769.0, 0.265], [64805.7, 2.321], [64806.0, 0.043], [64833.1, 4.266], [64833.2, 0.105], [65311.5, 3.359], [65343.9, 2.292], [65990.8, 0.015]]}
{"kind": "depth", "E": 1787080359221, "U": 11315348942968, "u": 11315348950200, "recv_ms": 1787080359173, "bids": [[1000.0, 35.81], [14496.8, 2.352], [14596.8, 1.848], [58227.1, 0.002], [61462.0, 0.008], [62108.9, 0.003], [63744.7, 0.003], [63929.9, 1.874], [64049.8, 0.156], [64373.3, 3.414], [64688.3, 0.08], [64690.6, 0.103], [64694.9, 0.0]], "asks": [[64698.0, 0.526], [64698.8, 0.104], [64705.5, 0.008], [64706.9, 0.017], [64709.8, 0.005], [64767.9, 39.045], [64770.1, 0.001], [65020.4, 3.381], [65343.9, 2.292], [65638.0, 23.361], [71166.6, 0.013]]}
{"kind": "depth", "E": 1787080359323, "U": 11315348950531, "u": 11315348957315, "recv_ms": 1787080359335, "bids": [[14496.8, 2.716], [14596.8, 1.484], [58227.1, 0.002], [61461.9, 0.001], [61462.0, 0.006], [61462.1, 0.01], [62108.9, 0.006], [63696.8, 0.02], [63726.3, 4.464], [63999.5, 0.001], [64049.8, 0.156], [64114.5, 3.506], [64373.3, 3.415], [64539.6, 0.002], [64556.6, 0.092], [64662.7, 0.425], [64674.8, 1.199], [64684.4, 0.081], [64685.3, 0.703], [64690.5, 0.86], [64691.2, 0.301], [64692.6, 2.075], [64693.3, 0.006], [64694.7, 0.003]], "asks": [[64696.9, 15.298], [64697.5, 0.101], [64697.7, 0.001], [64698.0, 0.525], [64698.2, 0.048], [64698.5, 0.001], [64698.8, 0.084], [64698.9, 1.002], [64699.0, 0.866], [64699.6, 0.09], [64700.3, 0.004], [64701.0, 0.067], [64705.1, 0.505], [64705.5, 0.008], [64706.9, 0.017], [64709.8, 0.005], [64836.8, 1.191], [64853.8, 0.0], [65278.3, 0.0], [65343.9, 2.292], [65473.3, 22.969], [65696.9, 0.03]]}
{"kind": "depth", "E": 1787080359425, "U": 11315348957346, "u": 11315348964481, "recv_ms": 1787080359376, "bids": [[1000.0, 35.81], [14496.8, 3.08], [14596.8, 1.12], [58227.1, 0.002], [61461.9, 0.0], [62108.9, 0.003], [64049.8, 0.156], [64539.6, 7.718], [64556.6, 4.725], [64659.1, 0.33]], "asks": [[64704.0, 0.147], [64706.0, 0.038], [64708.0, 1.233], [64730.8, 0.0], [64744.5, 0.326], [64750.0, 1.881], [64766.8, 0.442], [64768.4, 2.322], [64826.3, 0.0], [64836.8, 6.589], [64853.8, 10.408], [64892.6, 4.853], [65343.9, 2.292], [65635.0, 14.301]]}
{"kind": "depth", "E": 1787080359527, "U": 11315348964574, "u": 11315348970854, "recv_ms": 1787080359517, "bids": [[1000.0, 35.81], [14496.8, 3.43], [14596.8, 0.77], [51757.4, 0.0], [58227.1, 0.002], [61461.9, 0.0], [62108.9, 0.006], [63696.8, 0.0], [63926.9, 7.496], [63929.9, 0.937], [64049.8, 0.156], [64373.3, 3.425], [64500.8, 13.823], [64539.6, 5.117], [64556.6, 3.071], [64630.6, 2.608], [64659.1, 0.332], [64664.2, 0.075], [64670.1, 0.189], [64680.6, 0.355], [64684.4, 0.082], [64693.6, 0.427], [64694.5, 0.001], [64696.8, 5.12]], "asks": [[64696.9, 15.297], [64697.5, 0.185], [64698.8, 0.084], [64701.9, 0.05], [64705.1, 0.506], [64705.5, 0.008], [64706.9, 0.017], [64707.4, 1.914], [64709.8, 0.005], [64728.5, 0.002], [64763.1, 2.836], [64766.8, 0.46], [64892.6, 15.074], [65343.9, 2.292], [65696.9, 0.01]]}
{"kind": "depth", "E": 1787080359629, "U": 11315348970968, "u": 11315348977980, "recv_ms": 1787080359700, "bids": [[14396.8, 0.028], [14496.8, 3.724], [14596.8, 0.448], [51758.0, 0.0], [58227.1, 0.002], [61461.9, 0.0], [63812.7, 14.293], [63838.6, 4.691], [64049.8, 0.156], [64500.8, 19.987], [64539.6, 7.701], [64556.6, 4.418], [64588.5, 0.005], [64588.9, 2.875], [64659.1, 0.33], [64687.7, 0.238], [64688.3, 0.003], [64690.6, 0.18], [64693.6, 0.117]], "asks": [[64696.9, 15.381], [64698.7, 0.552], [64698.8, 0.091], [64701.5, 0.007], [64704.0, 1.047], [64705.5, 0.008], [64706.9, 0.017], [64709.8, 0.005], [64728.5, 0.0], [64766.8, 0.442], [64805.7, 2.321], [64892.6, 5.238], [65287.0, 0.288], [65343.9, 2.292]]}
{"kind": "depth", "E": 1787080359731, "U": 11315348978225, "u": 11315348985235, "recv_ms": 1787080359702, "bids": [[1000.0, 35.81], [14396.8, 0.224], [14496.8, 3.696], [14596.8, 0.28], [58227.1, 0.002], [62108.9, 0.003], [63696.8, 0.02], [63778.1, 0.555], [63791.0, 13.428], [63850.1, 6.435], [63926.9, 8.433], [64049.8, 0.156], [64474.8, 0.019], [64539.6, 0.002], [64556.2, 0.732], [64556.6, 0.092], [64626.9, 0.823]], "asks": [[64716.5, 5.025], [64767.8, 5.83], [64836.8, 1.191], [64853.8, 0.0], [65273.5, 3.447], [65343.9, 2.292], [65508.6, 15.994], [65661.3, 0.0], [65696.9, 0.03], [65990.8, 0.012]]}
{"kind": "depth", "E": 1787080359833, "U": 11315348985479, "u": 11315348991650, "recv_ms": 1787080359786, "bids": [[1000.0, 35.81], [14396.8, 0.448], [14496.8, 3.598], [14596.8, 0.154], [58227.1, 0.002], [61461.9, 0.0], [62108.9, 0.006], [63685.4, 0.315], [63797.5, 2.471], [63823.4, 2.11], [63855.7, 5.708], [64049.8, 0.156], [64373.3, 3.414], [64500.8, 4.962], [64680.8, 0.001], [64692.7, 0.211]], "asks": [[64696.9, 15.395], [64697.6, 0.004], [64698.8, 0.091], [64699.4, 2.342], [64699.6, 0.113], [64705.5, 0.008], [64706.9, 0.017], [64709.8, 0.005], [64713.3, 0.925], [64892.6, 0.023], [65020.4, 3.382], [65343.9, 2.292], [65864.5, 1.726], [66637.7, 0.001]]}
{"kind": "depth", "E": 1787080359935, "U": 11315348991679, "u": 11315348997414, "recv_ms": 1787080359887, "bids": [[14396.8, 0.7], [14496.8, 3.458], [14596.8, 0.042], [58227.1, 0.002], [61462.1, 0.008], [62108.9, 0.003], [63696.8, 0.0], [64006.8, 9.269], [64049.8, 0.156], [64680.8, 0.003], [64687.4, 0.001], [64687.8, 0.478], [64692.7, 0.211], [64693.6, 0.117]], "asks": [[64713.3, 0.927], [65280.5, 0.236], [65343.9, 2.292], [65602.7, 11.944], [65696.9, 0.01]]}
{"kind": "depth", "E": 1787080360037, "U": 11315348997629, "u": 11315349002300, "recv_ms": 1787080359988, "bids": [[1000.0, 35.81], [14396.8, 1.008], [14496.8, 3.192], [14596.8, 0.0], [58227.1, 0.002], [62108.9, 0.006], [63694.0, 9.805], [63747.6, 0.0], [64049.8, 0.156], [64500.8, 19.987], [64539.6, 7.701], [64556.6, 4.418], [64638.5, 0.005], [64651.5, 0.189], [64679.6, 0.336], [64683.2, 0.001], [64685.2, 0.469], [64687.7, 0.392], [64687.8, 0.324], [64688.2, 0.009], [64688.3, 0.466], [64692.7, 0.001]], "asks": [[64698.7, 0.008], [64698.8, 0.632], [64699.0, 0.869], [64699.9, 0.512], [64700.2, 0.027], [64701.3, 0.615], [64704.4, 0.044], [64704.8, 0.007], [64705.0, 0.328], [64705.5, 0.008], [64710.2, 0.024], [64719.4, 0.001], [64755.2, 0.316], [64806.9, 0.003], [64836.8, 6.589], [64853.8, 10.408], [64892.6, 5.238], [65022.2, 0.13], [65149.0, 1.036], [65343.9, 2.292], [65635.0, 15.214]]}
{"kind": "depth", "E": 1787080360139, "U": 11315349002365, "u": 11315349008819, "recv_ms": 1787080360090, "bids": [[1000.0, 35.81], [14396.8, 1.372], [14496.8, 2.828], [58227.1, 0.002], [61462.0, 0.008], [63696.8, 0.02], [63746.6, 0.0], [63777.0, 3.409], [64049.8, 0.156], [64373.3, 3.414], [64610.2, 0.145], [64617.2, 0.017], [64617.3, 0.001], [64647.9, 0.026], [64654.1, 0.068], [64655.3, 0.144], [64655.6, 0.033], [64685.2, 0.464], [64692.7, 0.001]], "asks": [[64758.9, 0.083], [64759.3, 0.0], [64835.2, 3.46], [65343.9, 2.292], [65650.6, 15.914], [65696.9, 0.03]]}
{"kind": "depth", "E": 1787080360241, "U": 11315349009017, "u": 11315349015599, "recv_ms": 1787080360195, "bids": [[14396.8, 1.722], [14496.8, 2.478], [58227.1, 0.002], [61461.9, 0.001], [62108.9, 0.003], [63535.2, 2.92], [63758.7, 16.132], [63991.6, 4.29], [64049.8, 0.156], [64556.6, 3.911], [64674.5, 0.621], [64681.8, 0.798], [64683.2, 0.464], [64686.5, 0.0], [64687.7, 0.238], [64687.8, 0.478], [64688.2, 0.102], [64688.3, 0.003], [64690.6, 0.087], [64692.7, 0.001], [64694.3, 0.086]], "asks": [[64696.9, 15.31], [64698.8, 0.632], [64705.5, 0.008], [64706.9, 0.017], [64709.8, 0.005], [64713.4, 0.166], [64720.8, 0.621], [64836.8, 6.589], [64892.6, 6.703], [65327.1, 7.753], [65343.9, 2.292], [65626.1, 2.112]]}
{"kind": "depth", "E": 1787080360343, "U": 11315349015765, "u": 11315349022168, "recv_ms": 1787080360306, "bids": [[1000.0, 35.81], [14396.8, 2.086], [14496.8, 2.114], [51757.0, 0.0], [51758.0, 0.0], [58227.1, 0.002], [61461.9, 0.0], [62108.9, 0.006], [63696.8, 0.0], [64049.8, 0.156], [64373.3, 3.413], [64676.3, 0.004], [64677.0, 1.145], [64677.9, 0.231], [64680.2, 0.037], [64680.6, 1.281], [64681.5, 1.248], [64681.8, 0.18], [64683.2, 0.001], [64687.6, 0.157], [64687.7, 0.238], [64687.8, 0.324], [64688.2, 0.472], [64688.3, 0.0], [64690.6, 0.18], [64696.8, 5.12]], "asks": [[64696.9, 15.304], [64698.8, 0.787], [64703.5, 0.006], [64705.5, 0.318], [64706.9, 0.327], [64709.8, 0.16], [64713.3, 0.002], [64713.9, 0.963], [64717.4, 1.543], [64717.5, 2.538], [64718.3, 0.675], [64719.4, 0.001], [64720.7, 10.214], [65157.6, 0.115], [65343.9, 2.292], [65469.8, 2.745], [65508.6, 15.736], [65696.9, 0.01]]}
{"kind": "depth", "E": 1787080360445, "U": 11315349022257, "u": 11315349027897, "recv_ms": 1787080360396, "bids": [[1000.0, 35.81], [14396.8, 2.436], [14496.8, 1.764], [51758.0, 0.0], [58227.1, 0.002], [62108.9, 0.003], [63532.3, 1.95], [63752.2, 0.805], [64049.8, 0.156], [64161.7, 2.292], [64373.3, 3.413], [64632.1, 0.004], [64674.6, 0.559], [64675.3, 0.004], [64676.3, 0.12], [64677.0, 1.029], [64679.7, 0.926], [64680.6, 0.355], [64683.2, 0.009], [64686.8, 0.144], [64687.5, 0.154], [64687.6, 0.003], [64688.0, 1.455], [64688.1, 1.275], [64688.2, 0.001], [64688.3, 0.463], [64689.0, 0.004], [64690.1, 0.214], [64690.3, 0.0], [64695.0, 0.088]], "asks": [[64697.5, 0.101], [64698.0, 0.441], [64698.8, 0.632], [64701.5, 0.091], [64705.5, 0.008], [64706.9, 0.017], [64709.8, 0.005], [64712.3, 1.435], [64713.2, 1.152], [64713.9, 0.038], [64714.8, 0.118], [64715.7, 0.687], [64716.4, 6.135], [64719.1, 0.152], [64720.0, 3.96], [64720.7, 10.099], [64761.6, 0.815], [64826.3, 0.0], [65020.4, 3.383], [65217.5, 6.306], [65311.5, 4.046], [65343.9, 2.292]]}
{"kind": "depth", "E": 1787080360547, "U": 11315349028004, "u": 11315349033879, "recv_ms": 1787080360499, "bids": [[14396.8, 2.8], [14496.8, 1.4], [51757.4, 0.0], [58227.1, 0.002], [61461.9, 0.0], [63402.9, 0.916], [63696.8, 0.02], [63850.0, 9.836], [64049.8, 0.156], [64680.6, 0.355], [64683.2, 0.464], [64688.2, 0.009], [64688.3, 0.0], [64688.6, 0.635], [64689.0, 0.001], [64690.1, 0.004], [64690.6, 0.18]], "asks": [[64696.9, 15.34], [64698.8, 0.632], [64705.5, 0.008], [64706.9, 0.017], [64709.8, 0.005], [65217.5, 6.0], [65343.9, 2.292], [65464.4, 2.796], [65476.3, 24.327], [65635.0, 16.279], [65696.9, 0.03]]}
{"kind": "depth", "E": 1787080360649, "U": 11315349033955, "u": 11315349040478, "recv_ms": 1787080360602, "bids": [[1000.0, 35.81], [14396.8, 3.15], [14496.8, 1.05], [58227.1, 0.002], [62108.9, 0.006], [64049.8, 0.156], [64556.6, 0.092], [64683.2, 0.464], [64688.2, 0.009], [64688.3, 0.0], [64688.6, 0.632], [64689.4, 0.002], [64690.6, 0.18], [64692.7, 0.001], [64694.1, 0.084], [64694.3, 0.002], [64695.0, 0.004]], "asks": [[64696.9, 15.342], [64697.5, 0.185], [64698.7, 0.018], [64698.8, 0.632], [64699.9, 0.478], [64705.5, 0.008], [64706.9, 0.017], [64709.8, 0.005], [64835.2, 2.703], [64836.8, 1.191], [65343.9, 2.292], [65466.8, 6.412], [65812.4, 1.22]]}
{"kind": "depth", "E": 1787080360751, "U": 11315349040650, "u": 11315349047398, "recv_ms": 1787080360704, "bids": [[1000.0, 35.81], [14396.8, 3.514], [14496.8, 0.686], [58227.1, 0.002], [61461.9, 0.0], [62108.9, 0.003], [63696.8, 0.0], [63715.6, 0.0], [63888.1, 6.094], [64049.8, 0.156], [64373.3, 3.413], [64539.6, 0.002], [64683.2, 0.464], [64688.2, 0.102], [64688.3, 0.0], [64688.5, 0.003], [64690.6, 0.087], [64691.5, 0.331], [64693.7, 0.312], [64694.7, 0.087]], "asks": [[64696.9, 15.277], [64697.5, 0.101], [64697.7, 0.0], [64698.0, 0.442], [64698.8, 0.632], [64703.1, 0.008], [64705.5, 0.008], [64705.8, 2.393], [64706.9, 0.017], [64709.8, 0.005], [64761.6, 1.142], [64853.8, 0.0], [65214.5, 3.977], [65343.9, 2.294], [65473.3, 23.427], [65696.9, 0.01]]}
{"kind": "depth", "E": 1787080360955, "U": 11315349054867, "u": 11315349060810, "recv_ms": 1787080360906, "bids": [[1000.0, 35.81], [14296.8, 0.28], [14396.8, 3.668], [14496.8, 0.252], [58227.1, 0.002], [62108.9, 0.003], [63696.8, 0.02], [63720.0, 2.541], [63912.6, 0.001], [64049.8, 0.156], [64373.3, 3.414], [64377.0, 0.459], [64599.8, 6.671], [64680.8, 0.003], [64683.2, 0.464], [64687.3, 0.155], [64687.5, 0.0], [64688.2, 0.102], [64688.3, 0.0], [64688.4, 0.002], [64689.4, 0.002], [64693.3, 0.316]], "asks": [[64698.8, 0.084], [64701.0, 0.005], [64702.5, 0.071], [64705.5, 0.556], [64713.3, 0.002], [65343.9, 2.292], [65611.8, 9.307], [65696.9, 0.03], [65943.0, 0.076], [66007.7, 0.0], [66315.5, 0.005]]}
{"kind": "depth", "E": 1787080361057, "U": 11315349061049, "u": 11315349068574, "recv_ms": 1787080361009, "bids": [[1000.0, 35.81], [14296.8, 0.518], [14396.8, 3.556], [14496.8, 0.126], [58227.1, 0.002], [61461.9, 0.0], [63402.9, 0.91], [63923.4, 31.723], [63984.7, 0.874], [64049.8, 0.156], [64182.2, 3.143], [64376.3, 1.707], [64638.5, 0.008], [64663.9, 0.06], [64664.0, 1.225], [64664.1, 0.013], [64667.3, 3.097], [64667.4, 0.02], [64667.5, 0.016], [64682.4, 0.001], [64683.6, 0.007], [64685.1, 0.485], [64690.6, 0.003], [64691.7, 0.202], [64691.8, 0.155], [64692.7, 0.542], [64693.4, 0.006], [64695.4, 0.084], [64696.8, 5.078]], "asks": [[64696.9, 15.269], [64697.0, 0.067], [64697.1, 0.0], [64697.4, 0.002], [64697.6, 0.004], [64698.0, 0.442], [64698.8, 0.239], [64700.2, 0.006], [64701.2, 0.063], [64702.5, 0.009], [64704.4, 0.199], [64705.4, 0.159], [64706.9, 0.327], [64709.8, 0.16], [64732.3, 0.001], [64764.2, 0.024], [64892.6, 7.485], [65343.9, 2.292], [65990.8, 0.009]]}
{"kind": "depth", "E": 1787080361159, "U": 11315349068670, "u": 11315349075150, "recv_ms": 1787080361109, "bids": [[14296.8, 0.756], [14396.8, 3.43], [14496.8, 0.014], [51757.0, 0.0], [51758.0, 0.0], [58227.1, 0.002], [61461.9, 0.0], [62108.9, 0.006], [63402.9, 0.913], [63696.8, 0.0], [63710.4, 0.0], [63710.5, 4.266], [63823.4, 2.891], [63920.4, 23.575], [64049.8, 0.156], [64153.3, 0.105], [64610.3, 1.963], [64617.3, 0.003], [64647.9, 0.028], [64654.1, 0.069], [64691.4, 0.395], [64692.7, 0.542], [64695.4, 0.0]], "asks": [[64696.9, 15.29], [64698.8, 0.084], [64701.2, 0.001], [64701.8, 0.064], [64702.0, 0.002], [64702.7, 0.001], [64704.4, 0.044], [64705.4, 0.004], [64706.9, 0.017], [64709.8, 0.005], [64719.1, 0.037], [64719.9, 0.269], [65343.9, 2.292], [65402.1, 2.152], [65596.2, 0.921], [65683.2, 0.0], [65696.9, 0.01], [65926.6, 4.396], [65991.3, 0.303]]}
{"kind": "depth", "E": 1787080361261, "U": 11315349075340, "u": 11315349080981, "recv_ms": 1787080361212, "bids": [[1000.0, 35.81], [14296.8, 1.106], [14396.8, 3.094], [14496.8, 0.0], [51757.0, 0.0], [58227.1, 0.002], [62108.9, 0.003], [63697.0, 12.863], [63920.4, 24.511], [64049.8, 0.156], [64179.2, 7.626], [64373.3, 3.812]], "asks": [[64704.0, 0.147], [64892.6, 4.218], [65343.9, 2.292], [65683.3, 0.042], [66320.2, 2.188]]}
{"kind": "depth", "E": 1787080361465, "U": 11315349087413, "u": 11315349093304, "recv_ms": 1787080361416, "bids": [[14296.8, 1.792], [14396.8, 2.408], [58227.1, 0.002], [62108.9, 0.003], [63694.0, 10.903], [64006.8, 7.945], [64049.8, 0.156], [64556.6, 0.092], [64556.7, 0.0], [64663.5, 1.935], [64683.2, 0.001], [64688.2, 0.565], [64694.7, 0.003]], "asks": [[64697.2, 0.002], [64697.3, 0.084], [64697.4, 0.0], [64697.6, 0.005], [64697.8, 0.087], [64698.0, 0.441], [64704.0, 1.047], [64709.0, 1.079], [64826.3, 0.0], [64836.8, 1.191], [65020.4, 3.381], [65343.9, 2.292], [65402.9, 9.099], [65505.6, 5.222], [65595.8, 0.002]]}
{"kind": "depth", "E": 1787080361567, "U": 11315349093399, "u": 11315349100138, "recv_ms": 1787080361523, "bids": [[1000.0, 35.81], [14296.8, 2.17], [14396.8, 2.03], [51757.4, 0.0], [51758.0, 0.0], [58227.1, 0.002], [63696.8, 0.0], [63991.6, 4.835], [64049.8, 0.156], [64082.2, 2.886], [64373.3, 3.803], [64539.6, 7.861], [64556.6, 4.795], [64576.0, 3.871], [64576.1, 0.0], [64626.3, 0.413], [64626.4, 0.153], [64691.6, 0.618], [64692.1, 0.086], [64692.3, 0.057], [64692.7, 0.001]], "asks": [[64768.8, 0.046], [64833.0, 4.039], [64833.1, 0.402], [64836.8, 6.589], [64853.8, 10.408], [64892.6, 4.248], [65343.9, 2.292], [65696.9, 0.01], [65798.0, 0.037], [65861.4, 0.008]]}
{"kind": "depth", "E": 1787080361669, "U": 11315349100346, "u": 11315349107382, "recv_ms": 1787080361620, "bids": [[1000.0, 35.81], [14296.8, 2.52], [14396.8, 1.68], [51758.0, 0.0], [58227.1, 0.002], [62108.9, 0.006], [63696.8, 0.02], [63891.1, 18.262], [63991.6, 5.614], [64049.8, 0.156], [64556.6, 4.208], [64674.5, 0.003], [64681.9, 0.834], [64682.9, 0.261], [64683.2, 0.001], [64683.6, 0.0], [64684.8, 0.049], [64685.8, 0.168], [64686.8, 0.144], [64688.0, 1.455], [64688.2, 0.001], [64688.3, 0.466], [64688.5, 0.0], [64689.3, 0.951], [64690.6, 0.096], [64694.6, 0.084]], "asks": [[64696.9, 14.486], [64697.3, 0.0], [64697.6, 0.004], [64698.1, 0.001], [64698.7, 0.008], [64698.8, 0.632], [64704.4, 0.044], [64705.4, 0.004], [64705.5, 0.008], [64706.9, 0.017], [64709.8, 0.005], [64720.8, 0.003], [64727.6, 0.618], [64735.0, 0.621], [64836.8, 6.589], [64892.6, 6.432], [65343.9, 2.294], [65409.9, 0.229], [65696.9, 0.03]]}
{"kind": "depth", "E": 1787080361771, "U": 11315349107400, "u": 11315349115065, "recv_ms": 1787080361723, "bids": [[14296.8, 2.884], [14396.8, 1.316], [51758.0, 0.0], [58227.1, 0.002], [62108.9, 0.003], [63402.9, 0.913], [63729.3, 3.276], [64049.8, 0.156], [64683.2, 0.464], [64688.2, 0.009], [64688.3, 0.003]], "asks": [[64697.0, 0.067], [64697.1, 0.0], [64697.2, 0.0], [64697.4, 0.002], [64733.3, 1.676], [64835.2, 3.46], [65343.9, 2.292], [65635.0, 16.431], [65702.7, 13.832], [65809.7, 1.818]]}
{"kind": "depth", "E": 1787080361873, "U": 11315349115172, "u": 11315349121280, "recv_ms": 1787080361827, "bids": [[1000.0, 35.81], [14296.8, 3.234], [14396.8, 0.966], [58227.1, 0.002], [61461.9, 0.001], [61462.0, 0.006], [61462.1, 0.01], [62108.9, 0.006], [64049.8, 0.156], [64108.8, 1.089], [64188.9, 0.0], [64373.3, 3.803], [64674.6, 0.002], [64676.3, 0.677], [64679.7, 0.0], [64681.5, 2.174], [64681.9, 0.216], [64683.3, 0.124], [64688.0, 0.914], [64688.2, 0.001], [64689.3, 0.333], [64689.4, 0.543], [64691.3, 1.973], [64694.6, 0.0], [64696.8, 5.084]], "asks": [[64697.1, 0.002], [64697.2, 0.084], [64697.4, 0.0], [64698.7, 0.018], [64698.8, 0.787], [64702.0, 0.001], [64705.5, 0.318], [64706.9, 0.327], [64709.8, 0.16], [64713.2, 0.227], [64713.9, 0.963], [64715.7, 0.131], [64716.5, 5.581], [64718.3, 0.134], [64719.4, 0.542], [64719.9, 0.154], [64720.7, 10.214], [64727.6, 0.0], [64735.0, 0.003], [64817.4, 24.22], [65343.9, 2.292]]}
{"kind": "depth", "E": 1787080361975, "U": 11315349121514, "u": 11315349129809, "recv_ms": 1787080361925, "bids": [[1000.0, 35.81], [14296.8, 3.598], [14396.8, 0.602], [58227.1, 0.002], [61461.9, 0.0], [63696.8, 0.0], [64049.8, 0.156], [64108.9, 7.476], [64114.5, 3.74], [64373.3, 3.802], [64675.3, 0.561], [64676.3, 0.12], [64680.5, 0.929], [64680.8, 0.003], [64681.5, 1.248], [64683.3, 0.116], [64687.9, 1.282], [64688.2, 0.542], [64688.3, 0.088], [64689.4, 0.002], [64690.5, 0.86], [64690.6, 0.019], [64691.3, 1.763]], "asks": [[64698.7, 0.566], [64698.8, 0.084], [64705.5, 0.008], [64706.9, 0.017], [64709.8, 0.005], [64713.3, 0.002], [64718.3, 0.675], [64719.4, 0.001], [64892.6, 0.023], [64893.6, 7.521], [65020.4, 3.382], [65149.1, 0.0], [65343.9, 2.292], [65505.6, 5.48], [65696.9, 0.01]]}
{"kind": "depth", "E": 1787080362077, "U": 11315349129962, "u": 11315349136623, "recv_ms": 1787080362027, "bids": [[14196.8, 0.084], [14296.8, 3.78], [14396.8, 0.336], [58227.1, 0.002], [61462.0, 0.004], [61462.1, 0.012], [62108.9, 0.003], [63710.5, 4.258], [63776.6, 0.0], [63891.1, 18.029], [64049.8, 0.156], [64165.7, 0.083], [64179.2, 7.626], [64685.2, 0.464], [64688.3, 0.104], [64690.5, 0.86], [64690.6, 0.003], [64693.2, 0.138], [64693.4, 0.026]], "asks": [[64892.6, 4.902], [64893.6, 0.006], [65343.9, 2.292], [65532.3, 7.413], [65617.1, 0.0], [65683.3, 0.034], [65699.7, 8.509]]}
{"kind": "depth", "E": 1787080362179, "U": 11315349136816, "u": 11315349143732, "recv_ms": 1787080362131, "bids": [[1000.0, 35.81], [14196.8, 0.336], [14296.8, 3.64], [14396.8, 0.224], [58227.1, 0.002], [62108.9, 0.006], [63696.8, 0.02], [63710.5, 4.266], [63775.1, 0.022], [63776.6, 0.008], [64006.8, 7.244], [64049.8, 0.156], [64114.5, 3.974], [64373.3, 3.812], [64575.8, 3.869], [64576.0, 0.007], [64588.7, 2.322], [64588.9, 0.556], [64617.3, 0.005], [64626.3, 0.413], [64667.7, 0.001], [64674.9, 0.207], [64685.3, 0.702], [64688.4, 0.003], [64694.1, 0.0], [64696.8, 5.083]], "asks": [[64698.8, 0.084], [64705.0, 0.329], [64705.5, 0.008], [64706.9, 0.017], [64709.8, 0.005], [64715.6, 0.926], [64716.5, 5.025], [64719.8, 0.996], [64720.7, 10.099], [64764.2, 0.006], [64768.7, 0.14], [64768.8, 0.0], [64805.6, 2.348], [64805.7, 0.002], [64833.0, 4.039], [65157.3, 0.119], [65273.4, 0.007], [65343.9, 2.292], [65618.6, 2.954], [65696.9, 0.03]]}
{"kind": "depth", "E": 1787080362281, "U": 11315349143876, "u": 11315349150001, "recv_ms": 1787080362233, "bids": [[1000.0, 35.81], [14196.8, 0.56], [14296.8, 3.542], [14396.8, 0.098], [51757.0, 0.0], [51758.0, 0.0], [58227.1, 0.002], [61461.9, 0.0], [61462.1, 0.01], [62108.9, 0.003], [64647.9, 0.029]], "asks": [[65343.9, 2.292], [65538.0, 10.771], [65617.1, 0.008], [65618.6, 2.962], [65683.3, 0.042]]}
{"kind": "depth", "E": 1787080362383, "U": 11315349150204, "u": 11315349155871, "recv_ms": 1787080362335, "bids": [[14196.8, 0.826], [14296.8, 3.374], [14396.8, 0.0], [58227.1, 0.002], [61462.0, 0.002], [61462.1, 0.01], [62108.9, 0.006], [63696.8, 0.0], [63955.1, 2.735], [64049.8, 0.156], [64108.7, 0.03], [64153.3, 0.178], [64159.1, 0.0], [64392.6, 0.0], [64539.6, 0.002], [64556.5, 0.972], [64556.6, 0.092], [64624.6, 0.003], [64650.8, 0.0], [64676.3, 0.004], [64677.1, 0.271], [64690.6, 0.087], [64696.8, 5.08]], "asks": [[64698.7, 0.556], [64698.8, 0.239], [64705.5, 0.318], [64706.9, 0.327], [64709.8, 0.16], [64720.7, 10.101], [64721.4, 0.06], [64743.9, 0.0], [64766.6, 0.002], [64826.3, 0.0], [64832.7, 0.0], [64835.2, 2.703], [64836.8, 1.191], [64853.8, 0.0], [65011.4, 0.111], [65012.3, 0.0], [65100.0, 56.701], [65269.6, 0.0], [65279.2, 8.871], [65343.9, 2.292], [65696.9, 0.01], [66127.6, 0.022]]}
{"kind": "depth", "E": 1787080362485, "U": 11315349155971, "u": 11315349160904, "recv_ms": 1787080362454, "bids": [[1000.0, 35.81], [14196.8, 1.19], [14296.8, 3.01], [58227.1, 0.002], [61461.9, 0.0], [63755.2, 1.348], [63812.7, 12.729], [63923.4, 30.473], [63991.6, 6.315], [64049.8, 0.156], [64373.3, 3.812], [64539.6, 6.72], [64556.6, 4.217], [64688.3, 0.104], [64689.5, 0.001], [64690.6, 0.087], [64691.2, 0.304], [64691.3, 1.868], [64695.8, 0.106], [64695.9, 0.002]], "asks": [[64698.8, 0.084], [64705.5, 0.008], [64706.9, 0.017], [64709.8, 0.005], [64836.8, 6.589], [64853.8, 0.0], [64854.6, 1.809], [64854.7, 7.296], [64854.8, 0.0], [64892.6, 0.023], [64893.6, 7.458], [65023.4, 1.081], [65343.9, 2.292], [65706.2, 0.071], [65990.8, 0.006], [66621.8, 0.0]]}
{"kind": "depth", "E": 1787080362587, "U": 11315349160976, "u": 11315349166351, "recv_ms": 1787080362537, "bids": [[1000.0, 35.81], [14196.8, 1.54], [14296.8, 2.66], [51757.4, 0.0], [51758.0, 0.0], [58227.1, 0.002], [62108.9, 0.003], [63797.5, 4.036], [63935.3, 3.9], [63939.8, 0.547], [64049.8, 0.156], [64114.4, 2.181], [64373.3, 3.811], [64638.5, 0.005], [64651.5, 0.189], [64688.3, 0.088], [64690.6, 0.103], [64691.3, 1.763], [64692.3, 0.034], [64693.8, 0.022]], "asks": [[64729.3, 1.074], [65020.4, 3.383], [65343.9, 2.292], [65441.6, 13.638]]}
{"kind": "depth", "E": 1787080362791, "U": 11315349172185, "u": 11315349177818, "recv_ms": 1787080362743, "bids": [[1000.0, 35.81], [14196.8, 2.254], [14296.8, 1.946], [58227.1, 0.002], [62108.9, 0.003], [63515.0, 2.17], [63920.4, 25.76], [64049.8, 0.156], [64373.3, 3.811], [64556.7, 1.507], [64688.3, 0.085], [64690.6, 0.103], [64691.3, 1.763], [64691.4, 0.3], [64693.6, 0.117]], "asks": [[64697.3, 0.0], [64835.2, 3.46], [65343.9, 2.292], [65441.6, 14.554], [65812.4, 0.614], [66611.5, 0.127]]}
{"kind": "depth", "E": 1787080362893, "U": 11315349177880, "u": 11315349183901, "recv_ms": 1787080362845, "bids": [[14196.8, 2.604], [14296.8, 1.596], [58227.1, 0.002], [62108.9, 0.006], [63696.8, 0.0], [64049.8, 0.156], [64097.4, 14.666], [64688.3, 0.101], [64690.6, 0.087], [64696.2, 0.088]], "asks": [[65343.9, 2.293], [65585.9, 2.282], [65696.9, 0.01]]}
{"kind": "depth", "E": 1787080362995, "U": 11315349184034, "u": 11315349189511, "recv_ms": 1787080362946, "bids": [[14196.8, 2.968], [14296.8, 1.232], [58227.1, 0.002], [61461.9, 0.0], [63402.9, 0.91], [63499.9, 6.988], [64049.8, 0.156], [64500.7, 15.115], [64500.8, 4.962], [64539.6, 6.721], [64556.5, 4.799], [64556.6, 0.092], [64556.7, 0.0], [64630.5, 2.588], [64630.6, 0.001], [64663.9, 0.058], [64664.0, 1.223], [64664.1, 0.011], [64667.3, 3.095], [64667.4, 0.018], [64667.5, 0.014], [64669.6, 0.122], [64676.9, 0.311], [64680.6, 0.355], [64680.8, 0.003], [64687.3, 0.001], [64687.4, 0.155], [64688.3, 0.085], [64690.6, 0.103], [64691.3, 1.763], [64696.8, 5.079]], "asks": [[64698.8, 0.084], [64700.0, 1.325], [64701.2, 0.063], [64701.8, 0.002], [64705.0, 0.328], [64705.5, 0.008], [64706.9, 0.017], [64708.5, 0.631], [64709.8, 0.005], [64710.0, 0.128], [64712.3, 1.417], [64713.3, 0.927], [64715.9, 0.002], [64762.9, 2.743], [64763.1, 0.002], [64835.2, 2.703], [64836.8, 6.589], [64853.8, 10.408], [64854.6, 0.001], [64854.7, 0.0], [64892.6, 6.661], [65020.4, 3.996], [65343.9, 2.293], [65570.3, 2.14]]}
{"kind": "depth", "E": 1787080363097, "U": 11315349189654, "u": 11315349200825, "recv_ms": 1787080363048, "bids": [[1000.0, 35.81], [14196.8, 3.318], [14296.8, 0.882], [58227.1, 0.002], [61461.9, 0.0], [62108.9, 0.003], [63402.9, 0.913], [63696.8, 0.02], [64049.8, 0.158], [64082.2, 3.664], [64373.3, 3.812], [64638.5, 0.008], [64685.2, 0.464], [64688.3, 0.101], [64688.4, 0.002], [64689.0, 0.004], [64690.6, 0.087], [64691.3, 1.763], [64693.6, 0.139], [64694.9, 0.084], [64695.8, 0.007], [64695.9, 0.045], [64696.2, 0.07], [64696.3, 0.093], [64696.8, 5.079]], "asks": [[64696.9, 14.391], [64697.0, 0.069], [64697.1, 0.0], [64697.2, 0.0], [64697.4, 0.0], [64698.1, 0.0], [64698.4, 0.088], [64698.8, 0.084], [64705.5, 0.008], [64706.9, 0.017], [64709.8, 0.005], [64721.7, 0.012], [64721.8, 2.072], [64722.4, 1.632], [64755.2, 0.319], [64764.2, 0.024], [64800.0, 11.024], [65343.9, 2.293], [65696.9, 0.03], [65796.8, 1.212]]}
{"kind": "depth", "E": 1787080363301, "U": 11315349212320, "u": 11315349218948, "recv_ms": 1787080363255, "bids": [[14196.8, 3.738], [14296.8, 0.308], [14596.8, 0.154], [51758.0, 0.0], [58227.1, 0.002], [61461.9, 0.0], [61462.1, 0.008], [62108.9, 0.003], [63696.8, 0.0], [64049.8, 0.156], [64556.5, 4.792], [64689.0, 0.001], [64694.9, 0.0], [64696.8, 5.033]], "asks": [[64697.2, 0.002], [64697.3, 0.084], [64697.4, 0.0], [64698.1, 0.001], [64698.4, 0.087], [64698.8, 0.084], [64702.6, 0.124], [64705.5, 0.008], [64706.9, 0.017], [64709.8, 0.005], [64721.8, 2.072], [64836.8, 6.589], [64892.6, 6.751], [65273.5, 2.376], [65343.9, 2.293], [65400.0, 96.774], [65407.9, 0.0], [65564.5, 4.257], [65696.9, 0.01]]}
{"kind": "depth", "E": 1787080363403, "U": 11315349219040, "u": 11315349226394, "recv_ms": 1787080363356, "bids": [[1000.0, 35.81], [14196.8, 3.612], [14296.8, 0.196], [14596.8, 0.392], [51757.0, 0.0], [58227.1, 0.002], [63825.6, 0.625], [63888.1, 6.328], [64049.8, 0.156], [64373.3, 3.802], [64556.5, 0.972], [64645.0, 6.103]], "asks": [[64721.8, 2.072], [64826.3, 0.001], [64836.8, 1.191], [65694.0, 0.019], [65796.8, 1.818]]}
{"kind": "depth", "E": 1787080363505, "U": 11315349226547, "u": 11315349232401, "recv_ms": 1787080363457, "bids": [[14196.8, 3.5], [14296.8, 0.07], [14596.8, 0.63], [58227.1, 0.002], [61462.0, 0.0], [61462.1, 0.01], [62108.9, 0.006], [62134.9, 0.0], [63696.8, 0.02], [63726.3, 4.762], [64049.8, 0.156], [64153.3, 0.215], [64376.3, 1.086], [64377.0, 0.327], [64672.3, 1.91], [64687.4, 0.001]], "asks": [[65343.9, 2.293], [65415.4, 0.229], [65469.8, 1.83], [65570.3, 2.87], [65696.9, 0.03]]}
{"kind": "depth", "E": 1787080363607, "U": 11315349232475, "u": 11315349238359, "recv_ms": 1787080363562, "bids": [[14196.8, 3.29], [14296.8, 0.0], [14596.8, 0.91], [51757.4, 0.0], [58227.1, 0.002], [61461.9, 0.0], [62108.9, 0.003], [63810.4, 1.25], [63902.0, 0.002], [63955.6, 0.001], [64049.8, 0.156], [64500.7, 15.043], [64539.6, 7.703], [64556.5, 5.299], [64630.5, 2.553], [64683.2, 0.001], [64683.9, 0.326], [64687.3, 0.001], [64688.1, 1.276], [64688.3, 0.487], [64688.7, 0.077], [64689.9, 0.001], [64690.3, 0.084], [64690.4, 0.241], [64690.6, 0.087], [64691.6, 0.077], [64691.8, 0.696], [64693.6, 0.055], [64693.7, 0.086], [64696.8, 5.034]], "asks": [[64696.9, 14.433], [64698.8, 0.084], [64705.5, 0.008], [64706.9, 0.017], [64709.8, 0.005], [64761.6, 1.132], [64762.9, 2.767], [64826.3, 0.0], [64836.8, 6.589], [64853.8, 10.408], [64892.6, 5.286], [65020.4, 3.995], [65273.5, 1.305], [65279.3, 1.071], [65343.9, 2.293], [65699.7, 9.573]]}
{"kind": "depth", "E": 1787080363709, "U": 11315349238516, "u": 11315349244978, "recv_ms": 1787080363673, "bids": [[1000.0, 35.81], [14196.8, 2.94], [14596.8, 1.26], [58227.1, 0.002], [62108.9, 0.006], [63696.8, 0.0], [64049.8, 0.156], [64373.3, 4.424], [64556.5, 0.972], [64645.0, 6.117], [64687.3, 0.001], [64688.3, 0.49], [64688.4, 0.079], [64688.7, 0.0], [64689.2, 0.005], [64690.6, 0.087], [64694.2, 0.095]], "asks": [[64698.7, 0.008], [64699.9, 0.443], [64701.2, 0.001], [64702.7, 0.063], [64705.5, 0.556], [64721.6, 1.408], [64721.7, 0.012], [64721.8, 1.918], [64836.8, 1.191], [65343.9, 2.295], [65611.8, 7.786], [65696.9, 0.01]]}
{"kind": "depth", "E": 1787080363811, "U": 11315349245015, "u": 11315349250403, "recv_ms": 1787080363783, "bids": [[14196.8, 2.576], [14596.8, 1.624], [51757.0, 0.0], [58227.1, 0.002], [62108.9, 0.003], [63888.1, 6.562], [64049.8, 0.156], [64539.5, 7.719], [64539.6, 0.002], [64556.5, 5.307], [64556.6, 1.617], [64674.5, 0.56], [64675.5, 0.005], [64676.3, 0.12], [64677.1, 0.155], [64686.8, 0.144], [64687.3, 0.155], [64688.2, 0.001], [64688.7, 0.541]], "asks": [[64697.1, 0.002], [64697.2, 0.0], [64697.3, 0.0], [64697.4, 0.0], [64698.1, 0.0], [64698.3, 0.025], [64714.8, 0.118], [64715.6, 0.926], [64715.9, 0.002], [64721.6, 1.254], [64721.8, 2.072], [64767.7, 0.002], [64835.2, 3.46], [64836.8, 6.589], [64853.8, 10.408], [64854.8, 0.719], [64892.6, 5.19], [65017.6, 1.465], [65343.9, 2.293], [65466.8, 7.327]]}
{"kind": "depth", "E": 1787080363913, "U": 11315349250586, "u": 11315349255004, "recv_ms": 1787080363892, "bids": [[14196.8, 2.226], [14596.8, 1.974], [58227.1, 0.002], [63696.8, 0.02], [64049.8, 0.156], [64638.5, 0.008], [64651.5, 0.186], [64679.9, 0.017], [64680.6, 1.281], [64681.4, 1.287], [64688.3, 0.482], [64688.4, 0.002], [64688.8, 0.086], [64690.5, 0.86], [64690.6, 0.297]], "asks": [[64697.0, 0.067], [64697.1, 0.0], [64697.4, 0.002], [64698.2, 0.047], [64713.3, 0.002], [64713.9, 0.963], [64715.6, 0.37], [64716.4, 6.694], [64718.2, 0.555], [64718.3, 0.134], [64719.4, 0.001], [64719.8, 0.881], [64720.7, 10.216], [64729.3, 1.074], [64755.2, 0.316], [65279.3, 2.142], [65343.9, 2.292], [65466.4, 0.0], [65596.2, 2.443], [65696.9, 0.03], [65714.1, 0.0], [65990.8, 0.003]]}
{"kind": "depth", "E": 1787080364117, "U": 11315349259709, "u": 11315349266038, "recv_ms": 1787080364089, "bids": [[14196.8, 1.512], [14596.8, 2.688], [51757.0, 0.002], [51758.0, 0.0], [58227.1, 0.002], [61461.9, 0.0], [62108.9, 0.003], [64049.8, 0.156], [64373.3, 4.423], [64663.9, 0.06], [64664.0, 1.225], [64664.1, 0.013], [64667.3, 3.097], [64667.4, 0.02], [64667.5, 0.016], [64671.0, 0.622], [64678.3, 2.861], [64682.3, 0.026], [64682.9, 0.254], [64683.2, 0.001], [64685.2, 0.464], [64687.3, 0.155], [64688.2, 0.627], [64688.3, 0.016], [64688.4, 0.003], [64688.7, 0.0], [64688.8, 0.464], [64691.5, 0.872], [64691.6, 0.078], [64691.8, 0.155], [64693.4, 0.025], [64693.6, 0.033], [64693.8, 0.003], [64696.0, 0.003], [64696.8, 4.802]], "asks": [[64697.3, 0.002], [64697.4, 0.084], [64697.5, 0.104], [64698.3, 0.028], [64698.8, 0.632], [64699.0, 0.866], [64701.2, 0.063], [64702.7, 0.001], [64704.4, 0.044], [64705.0, 0.329], [64705.4, 0.004], [64705.5, 0.008], [64706.9, 0.017], [64708.7, 0.003], [64709.8, 0.005], [64716.1, 0.44], [64892.6, 4.989], [65020.4, 3.996], [65343.9, 2.292], [65473.3, 26.479], [66097.3, 1.295]]}
{"kind": "depth", "E": 1787080364219, "U": 11315349266202, "u": 11315349271680, "recv_ms": 1787080364180, "bids": [[1000.0, 35.81], [14196.8, 1.148], [14596.8, 3.052], [51757.0, 0.0], [58227.1, 0.002], [62108.9, 0.006], [63696.8, 0.0], [63979.5, 4.525], [64049.8, 0.156], [64179.3, 0.0], [64674.5, 0.003], [64675.3, 0.561], [64688.2, 0.55], [64688.3, 0.479], [64688.7, 0.077], [64688.8, 0.001], [64691.6, 0.078], [64693.4, 0.005], [64695.5, 0.005], [64695.8, 0.002]], "asks": [[64715.6, 0.926], [64716.4, 6.138], [64719.8, 0.996], [64720.7, 10.101], [64721.8, 1.918], [64721.9, 0.157], [64743.7, 0.329], [65343.9, 2.292], [65677.3, 2.209], [65696.9, 0.01], [65882.9, 4.098]]}
{"kind": "depth", "E": 1787080364321, "U": 11315349271834, "u": 11315349277093, "recv_ms": 1787080364274, "bids": [[1000.0, 35.81], [14196.8, 0.798], [14596.8, 3.402], [51757.0, 0.0], [58227.1, 0.002], [61461.9, 0.0], [62108.9, 0.003], [63729.3, 2.963], [64049.8, 0.156], [64108.9, 7.242], [64153.3, 0.22], [64373.3, 4.423], [64671.0, 0.004], [64676.3, 0.004], [64677.1, 0.271], [64688.2, 0.542], [64688.4, 0.011], [64688.7, 0.077], [64691.6, 0.078], [64691.8, 0.155], [64694.1, 0.084], [64696.7, 0.118], [64696.8, 5.141]], "asks": [[64697.5, 0.101], [64698.3, 0.025], [64698.5, 0.004], [64698.8, 0.632], [64705.5, 0.008], [64706.9, 0.017], [64709.8, 0.005], [64892.6, 5.283], [65343.9, 2.292]]}
{"kind": "depth", "E": 1787080364423, "U": 11315349277230, "u": 11315349285120, "recv_ms": 1787080364374, "bids": [[14196.8, 0.462], [14496.8, 0.028], [14596.8, 3.71], [58227.1, 0.002], [61461.9, 0.001], [63696.8, 0.02], [63910.4, 0.781], [63934.5, 0.781], [64049.8, 0.156], [64143.9, 0.11], [64405.0, 0.187], [64556.5, 0.972], [64561.6, 1.21], [64629.5, 0.045], [64655.6, 0.037], [64691.6, 0.288], [64696.8, 5.137]], "asks": [[64698.8, 0.787], [64705.5, 0.318], [64706.9, 0.327], [64709.8, 0.16], [64745.2, 0.009], [64770.8, 0.025], [64826.3, 0.0], [64836.8, 1.191], [64837.2, 0.044], [64990.5, 0.066], [65246.1, 0.422], [65343.9, 2.292], [65696.9, 0.03], [65990.8, 0.0]]}
{"kind": "depth", "E": 1787080364525, "U": 11315349285199, "u": 11315349291584, "recv_ms": 1787080364476, "bids": [[1000.0, 35.81], [14196.8, 0.28], [14496.8, 0.21], [14596.8, 3.71], [51757.4, 0.0], [58227.1, 0.002], [61461.9, 0.0], [62108.9, 0.006], [63865.2, 0.22], [63888.1, 6.913], [63985.1, 0.468], [64049.8, 0.156], [64114.5, 4.208], [64539.5, 7.702], [64556.5, 5.3], [64556.6, 0.092], [64635.3, 0.409], [64635.7, 0.159], [64636.0, 0.034], [64636.3, 0.005], [64636.6, 0.001], [64654.3, 0.053], [64654.6, 0.002], [64654.9, 2.319], [64655.3, 0.112], [64655.6, 0.005], [64669.2, 0.124], [64669.3, 0.0], [64669.4, 0.002], [64669.5, 0.003], [64669.6, 0.022], [64669.7, 0.056], [64669.8, 0.003], [64669.9, 0.602], [64670.0, 1.404], [64670.2, 0.308], [64672.4, 0.0], [64672.9, 0.002], [64688.4, 0.01], [64690.3, 0.0], [64691.0, 0.085], [64691.1, 0.015], [64691.2, 0.164], [64691.3, 1.693], [64691.4, 0.1], [64691.5, 0.672], [64691.6, 0.008], [64691.7, 0.002], [64691.8, 0.295], [64691.9, 0.003], [64692.0, 0.011], [64692.3, 0.002], [64692.6, 2.043], [64692.9, 0.0], [64693.2, 0.106], [64693.6, 0.001], [64694.8, 0.084], [64696.8, 5.147]], "asks": [[64696.9, 14.387], [64697.0, 0.067], [64697.3, 0.0], [64697.4, 0.002], [64698.8, 0.632], [64701.2, 0.001], [64702.5, 0.071], [64705.5, 0.008], [64706.0, 0.006], [64706.3, 0.004], [64706.6, 0.004], [64706.9, 0.017], [64707.0, 2.262], [64707.3, 0.002], [64707.6, 0.118], [64707.7, 0.629], [64707.8, 0.508], [64707.9, 0.014], [64708.0, 1.123], [64708.1, 0.111], [64708.2, 0.005], [64708.3, 0.258], [64708.4, 0.001], [64708.5, 0.484], [64709.8, 0.005], [64716.5, 0.025], [64725.0, 0.004], [64725.3, 0.347], [64725.6, 0.003], [64725.9, 0.009], [64726.3, 0.315], [64726.7, 0.0], [64727.1, 0.0], [64729.3, 0.976], [64729.5, 0.002], [64729.6, 0.027], [64729.7, 0.002], [64729.8, 0.005], [64729.9, 0.001], [64730.0, 0.019], [64730.1, 0.033], [64730.2, 0.0], [64730.3, 0.104], [64744.0, 1.345], [64744.3, 4.285], [64744.6, 0.024], [64744.9, 0.024], [64745.3, 0.04], [64764.2, 0.024], [64766.8, 0.46], [64835.2, 2.703], [64836.8, 6.589], [64853.8, 10.408], [65343.9, 2.292]]}
{"kind": "depth", "E": 1787080364627, "U": 11315349291605, "u": 11315349297992, "recv_ms": 1787080364579, "bids": [[1000.0, 35.81], [14196.8, 0.168], [14496.8, 0.448], [14596.8, 3.584], [58227.1, 0.002], [61461.9, 0.0], [62108.9, 0.003], [63696.8, 0.0], [63726.3, 5.075], [64049.8, 0.156], [64078.0, 0.087], [64373.3, 4.422], [64556.5, 0.972], [64655.9, 0.032], [64656.8, 0.117], [64657.2, 0.033], [64680.6, 1.622], [64688.7, 2.467], [64690.1, 0.004], [64690.6, 0.087], [64691.5, 0.131], [64691.6, 0.07], [64691.8, 0.185], [64691.9, 0.203], [64692.2, 0.102], [64692.3, 0.072], [64692.4, 0.075], [64692.7, 0.033], [64693.3, 0.026], [64693.4, 0.315], [64693.5, 0.002], [64693.7, 0.118], [64694.0, 0.034], [64694.8, 0.0], [64696.8, 5.138]], "asks": [[64697.2, 0.002], [64697.3, 0.084], [64697.4, 0.0], [64698.8, 0.632], [64701.2, 0.063], [64702.3, 0.007], [64702.4, 0.381], [64702.5, 0.009], [64704.4, 0.044], [64705.0, 0.854], [64705.5, 0.008], [64705.6, 0.594], [64705.9, 0.073], [64706.9, 0.055], [64707.1, 0.54], [64707.3, 0.086], [64707.4, 2.034], [64707.6, 0.228], [64707.7, 0.859], [64708.0, 1.2], [64709.8, 0.005], [64724.0, 0.159], [64724.3, 0.056], [64725.3, 0.385], [64726.1, 0.346], [64727.8, 0.099], [64728.0, 1.444], [64728.3, 0.113], [64728.4, 0.109], [64728.6, 0.1], [64742.4, 0.04], [64742.7, 0.033], [64743.7, 0.367], [64836.8, 1.191], [65343.9, 2.292], [65508.7, 0.0], [65696.9, 0.01]]}
{"kind": "depth", "E": 1787080364729, "U": 11315349298166, "u": 11315349303302, "recv_ms": 1787080364684, "bids": [[14196.8, 0.042], [14496.8, 0.686], [14596.8, 3.472], [58227.1, 0.002], [62108.9, 0.006], [63720.7, 6.56], [63794.0, 37.589], [64049.8, 0.156], [64161.7, 0.008], [64500.7, 0.015], [64539.5, 0.0], [64656.2, 0.033], [64691.5, 0.201], [64691.7, 0.072], [64691.8, 0.255], [64692.0, 0.111], [64693.1, 0.037]], "asks": [[64706.5, 0.039], [64707.6, 0.338], [64707.8, 0.578], [64707.9, 0.105], [64708.0, 1.277], [64724.9, 0.04], [64728.2, 0.147], [64728.5, 0.07], [64728.6, 0.191], [64728.7, 0.385], [64743.4, 2.039], [64853.8, 0.0], [64892.6, 0.023], [65343.9, 2.292], [65650.6, 15.762]]}
{"kind": "depth", "E": 1787080364831, "U": 11315349303343, "u": 11315349308268, "recv_ms": 1787080364806, "bids": [[1000.0, 35.81], [14196.8, 0.0], [14496.8, 0.994], [14596.8, 3.206], [58227.1, 0.002], [63696.8, 0.02], [64049.8, 0.156], [64062.8, 0.631], [64373.4, 0.787], [64500.7, 15.044], [64539.5, 7.702], [64556.5, 5.3], [64556.6, 1.616], [64624.3, 0.034], [64626.6, 0.006], [64626.7, 1.94], [64649.2, 0.007], [64656.5, 0.277], [64665.4, 0.307], [64674.5, 0.56], [64675.3, 0.004], [64676.3, 0.12], [64677.1, 0.155], [64679.9, 0.943], [64680.6, 0.696], [64688.6, 0.635], [64689.4, 0.002], [64691.7, 0.142], [64692.1, 0.156], [64693.4, 0.347], [64694.7, 0.087]], "asks": [[64697.1, 0.002], [64697.2, 0.0], [64697.3, 0.0], [64697.4, 0.0], [64698.2, 0.048], [64701.2, 0.001], [64702.3, 0.069], [64706.2, 0.38], [64707.5, 0.077], [64707.9, 0.189], [64712.4, 0.001], [64713.3, 0.927], [64713.9, 0.038], [64722.0, 0.496], [64724.6, 0.271], [64728.2, 0.224], [64728.5, 0.154], [64738.2, 0.0], [64743.0, 0.039], [64758.4, 1.192], [64760.9, 0.0], [64835.2, 3.464], [64836.8, 6.589], [64853.8, 10.408], [64892.6, 5.283], [65020.4, 3.997], [65343.9, 2.292], [65585.9, 1.522], [65696.9, 0.03]]}
{"kind": "depth", "E": 1787080364933, "U": 11315349308347, "u": 11315349313956, "recv_ms": 1787080364886, "bids": [[1000.0, 35.81], [14496.8, 1.358], [14596.8, 2.842], [58227.1, 0.002], [62108.9, 0.003], [63781.1, 3.515], [63791.0, 13.897], [64049.8, 0.156], [64373.3, 4.422], [64594.3, 0.002], [64595.2, 1.545], [64637.4, 0.032], [64638.4, 1.099], [64638.8, 0.06], [64691.5, 0.271], [64692.1, 0.256], [64692.3, 0.172]], "asks": [[64697.0, 0.067], [64697.1, 0.0], [64697.4, 0.002], [64698.5, 0.001], [64698.8, 0.635], [64707.2, 0.149], [64707.4, 2.154], [64708.1, 0.181], [64720.6, 1.059], [64721.9, 0.003], [64725.7, 0.149], [64728.1, 0.69], [64728.8, 0.427], [64790.7, 2.442], [64793.3, 0.093], [64892.6, 6.094], [64970.0, 0.341], [65343.9, 2.292], [65350.0, 152.556], [65505.6, 5.709], [65710.0, 0.511], [66280.0, 0.186], [66710.0, 0.034], [66925.0, 0.541]]}
{"kind": "depth", "E": 1787080365035, "U": 11315349313990, "u": 11315349319236, "recv_ms": 1787080364986, "bids": [[14496.8, 1.708], [14596.8, 2.492], [58227.1, 0.002], [61462.0, 0.002], [62108.9, 0.006], [63402.9, 0.916], [63696.8, 0.0], [63726.3, 5.428], [63920.4, 25.979], [64049.8, 0.156], [64374.0, 0.165], [64626.7, 7.94], [64637.8, 0.033], [64649.3, 3.515], [64655.3, 0.098], [64665.5, 0.994], [64670.9, 0.116], [64671.0, 0.074], [64671.1, 0.411], [64671.3, 0.113], [64671.5, 0.106], [64671.6, 0.071], [64671.8, 0.544], [64672.0, 1.762], [64673.5, 0.114], [64676.8, 6.252], [64678.3, 3.379], [64680.8, 0.003], [64685.2, 0.469], [64690.1, 0.004]], "asks": [[64713.3, 0.927], [64721.9, 0.003], [64722.0, 0.65], [64736.7, 3.502], [64758.4, 1.908], [64759.4, 6.03], [64785.6, 1.255], [65343.9, 2.292], [65585.9, 0.762], [65696.9, 0.01]]}
{"kind": "depth", "E": 1787080365137, "U": 11315349319498, "u": 11315349326498, "recv_ms": 1787080365087, "bids": [[1000.0, 35.81], [14496.8, 2.058], [14596.8, 2.142], [51758.0, 0.0], [58227.1, 0.002], [61461.9, 0.0], [62108.9, 0.003], [63710.5, 4.248], [63812.7, 11.165], [63934.5, 0.0], [64049.8, 0.156], [64570.4, 0.001], [64587.9, 2.538], [64588.7, 0.003], [64594.4, 10.067], [64595.2, 2.586], [64618.5, 0.005], [64620.7, 31.63], [64622.9, 3.939], [64623.0, 1.798], [64638.1, 0.034], [64638.5, 0.005], [64651.5, 0.186], [64657.9, 0.006], [64670.9, 0.186], [64671.1, 0.481], [64671.3, 0.213], [64676.9, 0.929], [64684.3, 0.623], [64685.2, 0.464], [64686.0, 0.322], [64690.6, 0.003], [64695.5, 0.089]], "asks": [[64696.9, 14.283], [64697.8, 0.003], [64698.3, 0.024], [64698.6, 0.027], [64698.8, 0.659], [64702.6, 0.125], [64704.4, 0.044], [64705.0, 0.853], [64705.5, 0.008], [64706.9, 0.055], [64709.8, 0.005], [64714.6, 0.618], [64722.0, 1.268], [64729.3, 0.973], [64755.2, 0.316], [64764.6, 0.001], [64790.7, 3.408], [64791.8, 10.001], [64805.5, 2.413], [64805.6, 0.029], [65020.4, 3.996], [65343.9, 2.292], [65570.3, 3.63], [65683.3, 0.024], [67934.8, 0.015]]}
{"kind": "depth", "E": 1787080365239, "U": 11315349326685, "u": 11315349336248, "recv_ms": 1787080365190, "bids": [[1000.0, 35.81], [14496.8, 2.422], [14596.8, 1.778], [58227.1, 0.002], [61461.9, 0.0], [62108.9, 0.006], [63696.8, 0.02], [63710.5, 4.266], [63891.1, 17.413], [64049.8, 0.156], [64373.3, 4.433], [64556.5, 5.625], [64575.6, 3.864], [64575.8, 0.005], [64626.2, 0.053], [64626.3, 0.367], [64657.9, 0.02], [64660.5, 0.017], [64671.0, 0.144], [64671.4, 0.533], [64674.5, 0.56], [64675.3, 0.004], [64676.3, 0.12], [64677.1, 0.155], [64684.3, 0.005], [64686.8, 0.144], [64688.0, 1.455], [64688.2, 0.001], [64690.4, 0.009], [64690.8, 0.296], [64696.8, 5.136]], "asks": [[64696.9, 14.286], [64698.8, 0.659], [64701.5, 0.091], [64701.8, 0.064], [64702.3, 0.007], [64702.6, 0.124], [64704.4, 0.044], [64705.5, 0.008], [64706.9, 0.055], [64709.8, 0.005], [64714.9, 2.527], [64715.6, 0.37], [64715.9, 0.558], [64722.0, 1.268], [64766.8, 0.46], [64768.7, 0.14], [64832.9, 4.442], [64833.0, 0.175], [64836.8, 6.589], [64892.6, 4.694], [65343.9, 2.292], [65683.3, 0.042], [65696.9, 0.03]]}
{"kind": "depth", "E": 1787080365341, "U": 11315349336339, "u": 11315349344874, "recv_ms": 1787080365292, "bids": [[14496.8, 2.772], [14596.8, 1.428], [58227.1, 0.002], [61462.1, 0.008], [62108.9, 0.695], [63402.9, 0.919], [63797.5, 5.6], [63877.7, 0.782], [63920.4, 26.76], [64049.8, 0.156], [64556.5, 0.972], [64667.1, 2.316], [64670.8, 0.09], [64671.5, 0.206], [64673.9, 1.61], [64687.3, 0.001], [64687.4, 0.155]], "asks": [[64698.8, 0.659], [64704.4, 0.044], [64705.5, 0.008], [64706.9, 0.055], [64709.8, 0.005], [64721.5, 0.001], [64722.0, 1.114], [64722.1, 0.159], [64836.8, 1.191], [65343.9, 2.292], [65570.3, 4.39], [65593.7, 0.0], [71166.6, 0.013]]}
{"kind": "depth", "E": 1787080365443, "U": 11315349345187, "u": 11315349353655, "recv_ms": 1787080365394, "bids": [[1000.0, 35.81], [14496.8, 3.136], [14596.8, 1.064], [58227.1, 0.002], [61462.0, 0.004], [61462.1, 0.006], [62108.9, 0.692], [63696.8, 0.0], [64049.8, 0.156], [64153.3, 0.155], [64539.5, 0.0], [64556.6, 0.092], [64657.9, 0.006]], "asks": [[64704.0, 0.147], [64722.1, 0.159], [64722.2, 0.013], [64826.3, 0.0], [64835.2, 2.703], [64853.8, 0.0], [65343.9, 2.292], [65476.3, 24.113], [65696.9, 0.01], [71166.6, 0.013]]}
{"kind": "depth", "E": 1787080365545, "U": 11315349353900, "u": 11315349363015, "recv_ms": 1787080365496, "bids": [[1000.0, 35.81], [14496.8, 3.486], [14596.8, 0.714], [51757.4, 0.0], [58227.1, 0.002], [62108.9, 0.695], [63773.9, 32.721], [63874.0, 2.032], [64049.8, 0.156], [64373.3, 4.423], [64632.1, 0.005], [64683.0, 0.001], [64690.6, 0.213], [64695.5, 0.005]], "asks": [[64698.6, 0.007], [64698.8, 0.636], [64707.0, 1.362], [64718.2, 0.014], [64719.4, 0.542], [64719.8, 0.881], [64720.7, 10.216], [64722.1, 0.005], [64722.2, 0.013], [64761.6, 1.133], [65343.9, 2.292], [65602.7, 16.511], [67934.8, 0.01]]}
{"kind": "depth", "E": 1787080365647, "U": 11315349363100, "u": 11315349370178, "recv_ms": 1787080365597, "bids": [[14396.8, 0.056], [14496.8, 3.738], [14596.8, 0.406], [58227.1, 0.004], [62108.9, 0.692], [63696.8, 0.02], [64049.8, 0.156], [64539.5, 7.702], [64556.5, 5.599], [64679.7, 0.926], [64679.9, 0.017], [64680.5, 0.003], [64681.5, 1.248], [64682.0, 1.275], [64686.8, 0.685], [64688.0, 0.914], [64688.6, 0.632], [64688.7, 1.919], [64689.0, 0.004], [64690.6, 0.213], [64692.7, 0.581], [64694.6, 0.084], [64694.7, 0.003]], "asks": [[64697.1, 0.002], [64697.2, 0.0], [64697.4, 0.0], [64697.6, 0.004], [64697.7, 0.0], [64698.8, 0.085], [64699.1, 1.107], [64703.0, 0.914], [64705.5, 0.556], [64707.0, 2.262], [64712.3, 2.342], [64713.3, 0.002], [64713.9, 0.038], [64717.3, 0.601], [64719.4, 0.001], [64836.8, 6.589], [64853.8, 10.408], [64892.6, 4.99], [65343.9, 2.292], [65505.6, 5.968], [65696.9, 0.03]]}
{"kind": "depth", "E": 1787080365749, "U": 11315349370276, "u": 11315349378026, "recv_ms": 1787080365702, "bids": [[1000.0, 35.81], [14396.8, 0.252], [14496.8, 3.696], [14596.8, 0.252], [58227.1, 0.002], [63850.1, 5.34], [63855.7, 6.646], [64049.8, 0.156], [64065.9, 0.001], [64679.7, 0.0], [64680.6, 1.622], [64681.5, 1.248], [64686.8, 0.144], [64687.4, 0.001], [64688.0, 1.455], [64688.3, 0.016], [64688.4, 0.002], [64688.7, 1.842], [64688.8, 0.549], [64689.0, 0.475], [64689.1, 0.077], [64690.6, 0.213], [64692.7, 0.033], [64694.6, 0.0]], "asks": [[64697.0, 0.067], [64697.1, 0.0], [64697.4, 0.002], [64697.5, 0.185], [64698.0, 0.525], [64698.5, 0.002], [64698.8, 0.084], [64699.0, 0.866], [64703.0, 0.014], [64704.4, 0.592], [64705.5, 0.556], [64705.6, 0.046], [64707.0, 0.462], [64708.0, 0.377], [64711.6, 0.043], [64712.3, 1.417], [64713.2, 0.227], [64714.0, 0.947], [64717.3, 0.06], [64718.3, 0.134], [64719.4, 0.542], [65343.9, 2.292]]}
{"kind": "depth", "E": 1787080365851, "U": 11315349378415, "u": 11315349387988, "recv_ms": 1787080365804, "bids": [[1000.0, 35.81], [14396.8, 0.504], [14496.8, 3.556], [14596.8, 0.14], [58227.1, 0.002], [61461.9, 0.0], [62108.9, 0.695], [63696.8, 0.0], [63758.7, 16.249], [63998.4, 0.0], [64049.8, 0.156], [64153.3, 0.15], [64373.3, 4.433], [64556.6, 1.66], [64620.6, 0.034], [64620.8, 8.329], [64682.0, 0.375], [64683.0, 0.901], [64687.7, 0.392], [64690.6, 0.003], [64692.7, 0.243]], "asks": [[64696.9, 14.291], [64698.8, 0.084], [64699.0, 1.414], [64701.2, 0.063], [64701.8, 0.002], [64702.7, 0.001], [64703.9, 0.003], [64704.0, 1.047], [64704.3, 0.012], [64704.4, 0.044], [64705.5, 0.0], [64705.6, 0.602], [64706.9, 0.055], [64707.0, 1.362], [64709.8, 0.005], [64711.6, 0.043], [64722.2, 0.167], [64835.2, 3.464], [65020.4, 3.995], [65343.9, 2.292], [65696.9, 0.01], [65864.5, 1.362]]}
{"kind": "depth", "E": 1787080365953, "U": 11315349388360, "u": 11315349394520, "recv_ms": 1787080365903, "bids": [[14396.8, 0.742], [14496.8, 3.444], [14596.8, 0.014], [58227.1, 0.002], [62108.9, 0.692], [63402.9, 0.922], [63855.7, 7.741], [63929.9, 0.0], [64049.8, 0.156], [64075.7, 0.188], [64153.3, 0.119], [64373.3, 4.434], [64682.3, 0.019], [64683.5, 0.067], [64688.1, 1.275], [64688.8, 0.002], [64689.1, 0.077], [64692.7, 0.574], [64692.8, 0.109], [64692.9, 0.0], [64694.8, 0.084], [64695.2, 0.087]], "asks": [[64697.5, 0.101], [64698.0, 0.441], [64698.5, 0.001], [64698.7, 0.008], [64698.9, 1.003], [64699.0, 0.866], [64701.2, 0.001], [64702.7, 0.063], [64704.3, 0.012], [64704.4, 0.044], [64705.5, 0.625], [64705.6, 0.517], [64712.1, 0.013], [64722.2, 0.013], [64722.3, 1.194], [65343.9, 2.292], [65867.3, 4.093], [67934.8, 0.005]]}
{"kind": "depth", "E": 1787080366055, "U": 11315349394546, "u": 11315349400601, "recv_ms": 1787080366006, "bids": [[1000.0, 35.81], [14396.8, 1.078], [14496.8, 3.122], [14596.8, 0.0], [58227.1, 0.002], [62108.9, 0.695], [63696.8, 0.02], [64049.8, 0.156], [64153.3, 0.088], [64680.8, 0.001], [64685.2, 0.469], [64689.1, 0.077], [64690.6, 0.108], [64692.7, 0.581], [64692.8, 0.102]], "asks": [[64704.4, 0.044], [64705.5, 0.548], [64705.6, 0.131], [64712.1, 0.476], [64713.3, 0.0], [64892.6, 4.279], [65343.9, 2.292], [65621.4, 20.731], [65696.9, 0.03], [65861.4, 0.372]]}
{"kind": "depth", "E": 1787080366157, "U": 11315349400615, "u": 11315349406506, "recv_ms": 1787080366108, "bids": [[1000.0, 35.81], [14396.8, 1.428], [14496.8, 2.772], [58227.1, 0.002], [61461.9, 0.0], [62108.9, 0.692], [63402.9, 0.919], [63548.6, 0.002], [63910.1, 0.782], [63982.8, 0.885], [64049.8, 0.156], [64373.3, 4.423], [64662.7, 0.089], [64666.6, 0.537], [64680.8, 0.003], [64682.4, 0.619], [64685.2, 0.464], [64690.6, 0.003], [64690.9, 0.0], [64696.8, 5.136]], "asks": [[64696.9, 14.298], [64698.8, 0.084], [64699.4, 2.323], [64699.6, 0.09], [64700.0, 1.344], [64700.3, 0.027], [64702.2, 0.007], [64704.0, 0.147], [64704.4, 0.515], [64705.6, 0.131], [64706.9, 0.055], [64709.8, 0.005], [64712.1, 0.013], [64713.3, 0.002], [64717.7, 0.774], [64719.4, 0.001], [65343.9, 2.292]]}
{"kind": "depth", "E": 1787080366259, "U": 11315349406704, "u": 11315349414049, "recv_ms": 1787080366211, "bids": [[14396.8, 1.792], [14496.8, 2.408], [51757.0, 0.004], [51758.0, 0.002], [58227.1, 0.002], [63402.9, 0.916], [63696.8, 0.0], [63926.9, 9.37], [64049.8, 0.156], [64674.5, 0.003], [64675.8, 0.687], [64676.3, 0.004], [64677.1, 0.271], [64677.5, 0.002], [64690.6, 0.213], [64693.5, 0.021]], "asks": [[64704.3, 0.089], [64705.6, 0.054], [64709.0, 1.979], [64717.7, 0.233], [64718.3, 0.675], [64790.6, 0.1], [65020.4, 3.996], [65343.9, 2.292], [65696.9, 0.01]]}
{"kind": "depth", "E": 1787080366361, "U": 11315349414296, "u": 11315349421060, "recv_ms": 1787080366312, "bids": [[1000.0, 35.81], [14396.8, 2.142], [14496.8, 2.058], [51757.0, 0.002], [51758.0, 0.0], [58227.1, 0.002], [61461.9, 0.0], [62108.9, 0.695], [63862.2, 0.316], [64049.8, 0.156], [64104.2, 0.0], [64676.8, 1.252], [64678.3, 2.861], [64682.4, 0.001], [64683.0, 0.001], [64690.6, 0.003], [64696.8, 5.363]], "asks": [[64697.6, 0.003], [64698.8, 0.084], [64699.3, 0.55], [64699.8, 0.003], [64702.2, 0.006], [64704.0, 1.047], [64704.3, 0.089], [64704.4, 0.044], [64704.5, 1.098], [64705.5, 0.0], [64705.6, 0.054], [64707.0, 0.462], [64707.3, 0.086], [64709.8, 0.005], [64712.1, 0.476], [64714.6, 0.0], [64720.0, 3.961], [64826.3, 0.0], [65343.9, 2.294], [65505.6, 6.227], [65532.2, 1.057], [65602.7, 18.795]]}
{"kind": "depth", "E": 1787080366463, "U": 11315349421084, "u": 11315349426746, "recv_ms": 1787080366414, "bids": [[1000.0, 35.81], [14396.8, 2.506], [14496.8, 1.694], [51757.0, 0.0], [51758.0, 0.002], [58227.1, 0.002], [62108.9, 0.692], [63696.8, 0.02], [64049.8, 0.156], [64146.9, 2.317], [64373.3, 4.423], [64620.7, 0.122], [64620.8, 1.242], [64622.9, 35.447], [64675.3, 0.561], [64675.8, 0.13], [64682.0, 1.275], [64696.8, 5.365]], "asks": [[64698.7, 0.0], [64698.8, 0.1], [64699.0, 0.858], [64699.1, 0.785], [64699.3, 0.002], [64699.5, 0.389], [64699.7, 0.024], [64701.3, 0.862], [64702.7, 1.175], [64703.0, 0.914], [64704.3, 0.012], [64704.4, 0.044], [64705.4, 0.004], [64705.6, 0.038], [64706.9, 0.055], [64707.0, 1.362], [64709.8, 0.005], [64712.1, 0.013], [65343.9, 2.292], [65538.0, 11.837], [65696.9, 0.03]]}
{"kind": "depth", "E": 1787080366565, "U": 11315349427038, "u": 11315349433242, "recv_ms": 1787080366519, "bids": [[14396.8, 2.856], [14496.8, 1.344], [51757.4, 0.0], [51758.0, 0.0], [58227.1, 0.002], [61461.9, 0.0], [62108.9, 0.695], [64049.8, 0.156], [64556.5, 0.972], [64556.6, 0.092], [64575.6, 0.0], [64576.3, 3.868], [64587.9, 0.219], [64588.4, 2.32], [64626.2, 0.053], [64657.9, 0.02], [64676.9, 0.311], [64687.7, 0.238], [64687.8, 0.478], [64687.9, 1.282], [64695.2, 0.003], [64695.9, 0.002], [64696.8, 5.387]], "asks": [[64696.9, 14.341], [64698.0, 0.525], [64698.5, 0.002], [64698.9, 1.002], [64702.3, 0.162], [64702.6, 0.279], [64705.6, 0.193], [64706.9, 0.365], [64709.8, 0.16], [64768.7, 0.14], [64805.4, 2.356], [64805.5, 0.094], [64832.9, 4.442], [64835.2, 2.703], [64836.8, 1.191], [65343.9, 2.292], [65469.8, 0.915], [65479.6, 0.017], [65635.0, 16.583], [67931.7, 0.058]]}
{"kind": "depth", "E": 1787080366667, "U": 11315349433393, "u": 11315349438966, "recv_ms": 1787080366617, "bids": [[1000.0, 35.81], [14396.8, 3.22], [14496.8, 0.98], [51757.0, 0.0], [58227.1, 0.002], [61461.9, 0.0], [62108.9, 0.692], [63402.9, 0.919], [63696.8, 0.0], [63825.6, 0.0], [63909.7, 0.786], [64049.8, 0.156], [64108.4, 0.234], [64539.5, 6.843], [64556.5, 5.161], [64663.9, 0.058], [64664.0, 1.223], [64664.1, 0.011], [64667.3, 3.095], [64667.4, 0.018], [64667.5, 0.014], [64687.7, 0.392], [64687.8, 0.324], [64689.0, 0.472], [64689.1, 0.625], [64692.7, 0.033], [64694.8, 0.0], [64696.8, 5.161]], "asks": [[64696.9, 15.143], [64697.1, 0.002], [64697.2, 0.084], [64697.4, 0.0], [64698.0, 0.526], [64698.5, 0.001], [64699.9, 0.41], [64702.3, 0.007], [64702.6, 0.124], [64705.6, 0.038], [64706.9, 0.055], [64709.8, 0.005], [64722.0, 0.496], [64722.2, 0.167], [64722.3, 1.04], [64764.2, 0.006], [64790.6, 0.0], [64836.8, 6.589], [64853.8, 10.408], [64892.6, 5.775], [65343.9, 2.292], [65696.9, 0.01]]}
{"kind": "depth", "E": 1787080366769, "U": 11315349439031, "u": 11315349443954, "recv_ms": 1787080366720, "bids": [[1000.0, 35.81], [14396.8, 3.57], [14496.8, 0.63], [58227.1, 0.002], [61461.9, 0.0], [61462.1, 0.004], [63402.9, 0.916], [63891.1, 17.148], [64049.8, 0.156], [64153.3, 0.162], [64373.3, 4.433], [64680.6, 1.609], [64688.3, 0.019], [64689.1, 0.077], [64692.7, 0.581], [64693.3, 0.006], [64693.6, 0.023], [64696.8, 5.146]], "asks": [[64722.2, 0.013], [64722.3, 1.194], [65343.9, 2.292]]}
{"kind": "depth", "E": 1787080366871, "U": 11315349444067, "u": 11315349449469, "recv_ms": 1787080366822, "bids": [[14296.8, 0.084], [14396.8, 3.766], [14496.8, 0.35], [58227.1, 0.002], [62108.9, 0.695], [63696.8, 0.02], [63810.4, 1.875], [64049.8, 0.156], [64373.3, 4.432], [64556.6, 1.595], [64623.0, 6.319], [64686.0, 0.013], [64687.2, 0.353], [64689.1, 0.077], [64692.7, 0.581], [64693.8, 0.022]], "asks": [[64698.6, 0.0], [64699.1, 0.782], [64699.2, 0.371], [64699.5, 0.392], [64702.7, 0.704], [64705.0, 0.544], [64705.5, 0.309], [64705.6, 0.509], [64835.2, 3.464], [64892.6, 4.674], [65466.8, 8.242], [65696.9, 0.03]]}
{"kind": "depth", "E": 1787080366973, "U": 11315349449597, "u": 11315349454646, "recv_ms": 1787080366929, "bids": [[1000.0, 35.81], [14296.8, 0.308], [14396.8, 3.668], [14496.8, 0.224], [58227.1, 0.002], [62108.9, 0.692], [64049.8, 0.156], [64373.3, 4.432], [64687.5, 0.154], [64687.6, 0.003], [64687.7, 0.238], [64688.3, 0.003], [64689.0, 0.464], [64689.1, 0.101], [64690.6, 0.003], [64692.8, 0.102], [64693.5, 0.002]], "asks": [[64697.2, 0.085], [64698.8, 0.084], [64702.5, 0.009], [64702.6, 0.124], [64702.7, 0.063], [64703.0, 0.014], [64704.0, 0.147], [64705.4, 0.545], [64705.5, 0.425], [64706.0, 0.906], [64766.8, 0.442], [64892.6, 4.278], [65020.4, 3.997], [65343.9, 2.292], [65508.6, 15.165], [67934.8, 0.0]]}
{"kind": "depth", "E": 1787080367075, "U": 11315349454887, "u": 11315349461589, "recv_ms": 1787080367033, "bids": [[1000.0, 35.81], [14296.8, 0.56], [14396.8, 3.528], [14496.8, 0.112], [58227.1, 0.002], [61461.9, 0.0], [62108.9, 0.695], [63599.9, 7.157], [63696.8, 0.0], [63888.1, 7.178], [64049.8, 0.156], [64153.3, 0.158], [64179.2, 7.626], [64567.4, 0.025], [64651.5, 0.189], [64677.1, 0.271], [64680.6, 1.622], [64680.8, 0.001], [64685.2, 0.464], [64690.6, 0.003], [64694.8, 0.084], [64696.6, 0.019]], "asks": [[64696.9, 15.002], [64697.2, 0.001], [64697.4, 0.043], [64713.3, 0.0], [64729.3, 0.976], [64766.8, 0.46], [64797.0, 0.0], [65343.9, 2.292], [65696.9, 0.01]]}
{"kind": "depth", "E": 1787080367177, "U": 11315349461657, "u": 11315349468009, "recv_ms": 1787080367129, "bids": [[14296.8, 0.798], [14396.8, 3.402], [14496.8, 0.0], [51757.0, 0.0], [58227.1, 0.002], [64049.8, 0.156], [64153.3, 0.154], [64588.4, 0.001], [64588.8, 2.326], [64674.5, 0.56], [64674.7, 0.627], [64674.8, 1.634], [64675.3, 0.004], [64676.3, 0.12], [64677.1, 0.155], [64679.9, 0.943], [64680.6, 0.696], [64680.8, 0.003], [64682.1, 1.395], [64686.8, 0.144], [64687.4, 0.155], [64687.5, 0.0], [64688.0, 1.455], [64694.0, 0.053], [64695.1, 0.084], [64696.8, 5.156]], "asks": [[64696.9, 15.025], [64701.8, 0.003], [64703.0, 0.914], [64712.3, 1.417], [64712.4, 0.619], [64713.2, 1.152], [64713.3, 0.002], [64714.0, 0.022], [64719.1, 0.152], [64719.8, 1.499], [64720.7, 10.101], [64805.4, 2.356], [65343.9, 2.292], [65473.3, 26.693], [66330.1, 1.509]]}
{"kind": "depth", "E": 1787080367279, "U": 11315349468081, "u": 11315349473691, "recv_ms": 1787080367230, "bids": [[1000.0, 35.81], [14296.8, 1.162], [14396.8, 3.038], [58227.1, 0.002], [61461.9, 0.0], [62108.9, 0.692], [63596.9, 1.568], [63696.8, 0.02], [63891.1, 16.882], [64049.8, 0.156], [64373.3, 4.433], [64663.9, 0.06], [64664.0, 1.225], [64664.1, 0.013], [64667.3, 3.097], [64667.4, 0.02], [64667.5, 0.016], [64674.5, 0.003], [64675.5, 0.562], [64676.3, 0.004], [64677.2, 2.435], [64682.1, 0.777], [64691.3, 1.599], [64693.2, 0.084], [64693.8, 0.044], [64696.8, 5.371]], "asks": [[64696.9, 15.068], [64697.4, 0.0], [64701.8, 0.002], [64709.4, 0.144], [64712.4, 0.001], [64713.6, 0.029], [64719.1, 0.037], [64719.8, 0.881], [64720.0, 4.076], [65020.4, 3.996], [65343.9, 2.292], [65696.9, 0.03]]}
{"kind": "depth", "E": 1787080367381, "U": 11315349473838, "u": 11315349479378, "recv_ms": 1787080367345, "bids": [[1000.0, 35.81], [14296.8, 1.512], [14396.8, 2.688], [58227.1, 0.002], [62108.9, 0.695], [64049.8, 0.156], [64576.3, 3.868], [64626.2, 0.053], [64683.5, 0.137], [64684.2, 0.043], [64684.8, 0.009], [64685.4, 0.004], [64686.5, 0.309], [64686.7, 1.044], [64687.2, 0.044], [64689.1, 0.649], [64692.7, 0.033], [64695.1, 0.0]], "asks": [[64697.6, 0.087], [64703.0, 0.014], [64768.6, 0.086], [64768.7, 0.094], [64826.3, 0.0], [64832.9, 4.442], [65343.9, 2.292], [66200.7, 1.056]]}
{"kind": "depth", "E": 1787080367483, "U": 11315349479537, "u": 11315349484704, "recv_ms": 1787080367460, "bids": [[14296.8, 1.876], [14396.8, 2.324], [58227.1, 0.002], [61461.9, 0.0], [61462.1, 0.002], [62108.9, 0.692], [63402.9, 0.919], [63696.8, 0.0], [64049.8, 0.156], [64556.5, 5.115], [64674.7, 0.009], [64680.6, 0.376], [64682.0, 0.695], [64682.3, 0.019], [64682.8, 0.009], [64683.0, 0.901], [64683.5, 0.13], [64685.8, 0.477], [64686.5, 0.0], [64688.2, 0.001], [64688.3, 0.0], [64688.8, 0.473], [64689.0, 0.001], [64689.1, 0.641], [64696.8, 5.143]], "asks": [[64697.8, 0.01], [64698.7, 0.003], [64699.2, 0.364], [64699.5, 0.389], [64704.1, 0.336], [64705.5, 0.116], [64706.0, 0.006], [64707.0, 1.362], [64709.0, 1.079], [64836.8, 6.589], [64892.6, 6.149], [65343.9, 2.292], [65696.9, 0.01]]}
{"kind": "depth", "E": 1787080367585, "U": 11315349484864, "u": 11315349492350, "recv_ms": 1787080367557, "bids": [[1000.0, 35.81], [14296.8, 2.226], [14396.8, 1.974], [51757.4, 0.0], [58227.1, 0.002], [61461.9, 0.0], [61462.0, 0.006], [62108.9, 0.695], [63781.1, 3.281], [63826.4, 13.454], [64049.8, 0.156], [64108.9, 7.008], [64373.3, 4.433], [64556.5, 0.972], [64556.6, 0.092], [64694.8, 0.0], [64696.8, 5.144]], "asks": [[64696.9, 15.067], [64697.8, 0.003], [64698.3, 0.031], [64704.9, 0.091], [64705.0, 1.444], [64705.5, 0.039], [64705.6, 0.501], [64766.8, 0.442], [64835.2, 2.703], [64836.8, 1.191], [65343.9, 2.292], [65402.8, 0.224], [65532.3, 6.346], [65739.3, 0.006], [67931.7, 0.053]]}
{"kind": "depth", "E": 1787080367687, "U": 11315349492592, "u": 11315349502202, "recv_ms": 1787080367648, "bids": [[1000.0, 35.81], [14296.8, 2.59], [14396.8, 1.61], [51757.0, 0.0], [58227.1, 0.002], [63696.8, 0.02], [63826.4, 13.064], [64049.8, 0.156], [64182.2, 2.209], [64500.7, 15.519], [64539.5, 6.844], [64556.5, 4.857], [64651.5, 0.189], [64662.1, 0.344], [64666.6, 0.201], [64670.1, 0.004], [64676.8, 1.368], [64677.2, 2.319], [64687.4, 0.001], [64687.5, 0.154], [64690.3, 0.084], [64690.6, 0.087], [64693.6, 0.001], [64693.7, 0.034], [64693.8, 0.003], [64694.0, 0.034], [64694.1, 0.0], [64696.8, 5.145]], "asks": [[64696.9, 15.151], [64701.5, 0.007], [64704.0, 1.047], [64709.8, 0.337], [64713.8, 4.057], [64716.4, 16.138], [64729.3, 0.976], [64761.6, 1.136], [64775.7, 0.0], [64836.8, 6.589], [64892.6, 6.071], [65343.9, 2.292], [65696.9, 0.03]]}
{"kind": "depth", "E": 1787080367789, "U": 11315349502337, "u": 11315349507990, "recv_ms": 1787080367773, "bids": [[14296.8, 2.94], [14396.8, 1.26], [51757.0, 0.0], [58227.1, 0.002], [62108.9, 0.692], [63014.6, 0.001], [63920.4, 26.058], [63979.5, 4.291], [64049.8, 0.156], [64691.2, 0.258]], "asks": [[64892.6, 4.874], [65343.9, 2.292], [65408.6, 7.177], [65508.6, 14.907]]}
{"kind": "depth", "E": 1787080367891, "U": 11315349508025, "u": 11315349515693, "recv_ms": 1787080367870, "bids": [[1000.0, 35.81], [14296.8, 3.304], [14396.8, 0.896], [58227.1, 0.002], [62108.9, 0.695], [63696.8, 0.0], [63823.4, 3.281], [64049.8, 0.157], [64114.5, 4.442], [64179.2, 8.56], [64373.3, 4.433], [64556.6, 1.55], [64620.6, 2.395], [64687.3, 0.155], [64687.5, 0.0], [64689.1, 0.634], [64690.6, 0.087], [64692.0, 0.118], [64693.9, 0.084]], "asks": [[64835.2, 3.464], [65343.9, 2.292], [65538.1, 2.591], [65696.9, 0.01]]}
{"kind": "depth", "E": 1787080367993, "U": 11315349515808, "u": 11315349525563, "recv_ms": 1787080367962, "bids": [[1000.0, 35.81], [14296.8, 3.654], [14396.8, 0.546], [58227.1, 0.002], [62108.9, 0.692], [63014.6, 0.0], [63920.4, 26.76], [64049.8, 0.157], [64153.3, 0.117], [64689.2, 0.012], [64690.6, 0.087], [64692.0, 0.111], [64696.6, 0.02]], "asks": [[65020.4, 3.995], [65343.9, 2.292], [65618.6, 2.735], [65670.4, 7.651], [65799.8, 6.476]]}
{"kind": "depth", "E": 1787080368095, "U": 11315349525931, "u": 11315349538991, "recv_ms": 1787080368064, "bids": [[14196.8, 0.14], [14296.8, 3.738], [14396.8, 0.322], [51757.0, 0.002], [58227.1, 0.002], [61461.9, 0.0], [62108.9, 0.695], [63402.9, 0.916], [63696.8, 0.02], [63985.1, 0.702], [64049.8, 0.157], [64108.9, 6.774], [64373.3, 4.434], [64556.5, 5.09], [64674.8, 1.632], [64680.8, 0.001], [64685.2, 0.464], [64687.3, 0.001], [64687.4, 0.155], [64693.5, 0.025], [64693.7, 0.054], [64696.8, 5.37]], "asks": [[64696.9, 15.095], [64698.8, 0.084], [64702.6, 0.124], [64702.7, 0.063], [64704.0, 0.147], [64704.9, 0.014], [64705.0, 0.544], [64705.4, 0.004], [64705.5, 0.549], [64705.6, 0.609], [64712.2, 2.651], [64713.3, 0.0], [64716.4, 6.138], [64716.6, 5.006], [64720.0, 2.285], [64720.7, 0.101], [64721.7, 0.012], [64721.8, 2.072], [64722.3, 1.04], [64836.8, 6.589], [64892.6, 6.456], [65217.5, 2.173], [65273.5, 0.235], [65343.9, 2.292], [65407.3, 0.006], [65666.7, 0.032], [65696.9, 0.03]]}
{"kind": "depth", "E": 1787080368197, "U": 11315349539055, "u": 11315349549365, "recv_ms": 1787080368155, "bids": [[1000.0, 35.81], [14196.8, 0.364], [14296.8, 3.64], [14396.8, 0.196], [51757.0, 0.0], [58227.1, 0.002], [64049.8, 0.157], [64153.3, 0.08], [64373.3, 4.424], [64618.5, 0.005], [64620.7, 31.782], [64622.9, 3.939], [64623.0, 1.798], [64679.6, 0.166], [64680.8, 0.003], [64687.2, 0.198], [64687.4, 0.001], [64690.8, 0.064], [64691.2, 0.49]], "asks": [[64699.0, 0.006], [64703.7, 0.001], [64709.0, 1.979], [64713.3, 0.002], [64721.8, 1.918], [65262.4, 0.0], [65343.9, 2.292]]}
{"kind": "depth", "E": 1787080368299, "U": 11315349549433, "u": 11315349556683, "recv_ms": 1787080368252, "bids": [[14196.8, 0.616], [14296.8, 3.5], [14396.8, 0.084], [51757.0, 0.0], [51758.0, 0.0], [58227.1, 0.002], [62108.9, 0.692], [63696.8, 0.0], [63755.2, 0.957], [63888.1, 7.443], [64049.8, 0.157], [64114.5, 4.676], [64373.3, 4.423], [64648.5, 0.061], [64689.2, 0.012], [64690.6, 0.297], [64691.6, 0.07]], "asks": [[64704.1, 0.027], [64704.4, 0.592], [64704.6, 0.558], [64705.0, 1.444], [64705.6, 0.061], [64721.8, 1.918], [64721.9, 0.157], [65343.9, 2.292], [65414.8, 0.229], [65441.6, 13.646], [65450.9, 0.793], [65647.9, 2.508], [65696.9, 0.01]]}
{"kind": "depth", "E": 1787080368401, "U": 11315349557046, "u": 11315349566536, "recv_ms": 1787080368353, "bids": [[14196.8, 0.896], [14296.8, 3.304], [14396.8, 0.0], [58227.1, 0.002], [61461.9, 0.0], [61462.0, 0.008], [62108.9, 0.695], [63402.9, 0.919], [63955.1, 2.188], [64049.8, 0.159], [64063.4, 0.0], [64618.5, 0.005], [64620.7, 0.122], [64622.9, 35.599], [64674.6, 0.004], [64676.5, 0.001], [64683.9, 0.326], [64689.2, 0.012], [64690.1, 0.004], [64690.6, 0.087], [64692.2, 0.102], [64693.7, 0.034], [64693.8, 0.026], [64694.0, 0.053], [64694.4, 0.088], [64696.3, 0.108], [64696.8, 5.167]], "asks": [[64696.9, 15.011], [64699.3, 0.005], [64703.7, 0.0], [64714.3, 0.0], [64719.7, 10.002], [64721.7, 0.63], [64826.3, 0.0], [64826.7, 0.044], [64826.8, 0.03], [64892.6, 4.872], [65020.4, 3.996], [65214.5, 8.11], [65279.2, 9.941], [65343.9, 2.292], [67931.7, 0.058]]}
{"kind": "depth", "E": 1787080368605, "U": 11315349572761, "u": 11315349580402, "recv_ms": 1787080368556, "bids": [[14196.8, 1.596], [14296.8, 2.604], [51757.4, 0.0], [58227.1, 0.002], [61462.0, 0.01], [64049.8, 0.157], [64618.5, 0.005], [64620.7, 31.782], [64689.2, 0.012], [64690.1, 0.214], [64692.0, 0.111], [64693.5, 0.002], [64693.8, 0.003], [64694.0, 0.034], [64694.2, 0.011], [64694.4, 0.004]], "asks": [[64697.0, 0.151], [64892.6, 4.277], [65343.9, 2.292], [65407.5, 0.002], [65441.6, 13.654], [67931.7, 0.053]]}
{"kind": "depth", "E": 1787080368707, "U": 11315349580540, "u": 11315349587144, "recv_ms": 1787080368658, "bids": [[14196.8, 1.96], [14296.8, 2.24], [58227.1, 0.002], [61461.9, 0.0], [61462.0, 0.008], [61462.1, 0.004], [62108.9, 0.695], [63696.8, 0.0], [63939.8, 1.094], [64047.9, 0.873], [64049.8, 0.157], [64576.0, 3.871], [64576.3, 0.004], [64588.7, 2.322], [64588.8, 0.007], [64620.7, 0.122], [64622.9, 35.599], [64626.2, 0.053], [64688.4, 0.005], [64689.2, 0.012], [64690.1, 0.004], [64692.0, 0.111], [64693.7, 0.057], [64693.9, 0.103], [64695.3, 0.087], [64696.8, 5.188]], "asks": [[64696.9, 14.934], [64697.0, 0.067], [64697.6, 0.003], [64698.0, 0.442], [64701.5, 0.091], [64709.4, 0.131], [64768.6, 0.086], [64805.4, 2.356], [64832.9, 4.442], [65343.9, 2.292], [65508.6, 14.649], [65696.9, 0.01]]}
{"kind": "depth", "E": 1787080368911, "U": 11315349593624, "u": 11315349599629, "recv_ms": 1787080368862, "bids": [[14196.8, 2.674], [14296.8, 1.526], [58227.1, 0.002], [62108.9, 0.695], [63696.8, 0.02], [63778.1, 1.024], [63999.6, 0.0], [64049.8, 0.156], [64153.3, 0.006], [64540.7, 2.101], [64556.5, 0.972], [64556.6, 0.092], [64623.0, 6.341], [64638.5, 0.008], [64651.5, 0.186], [64696.6, 0.019]], "asks": [[64717.4, 2.729], [64729.3, 0.973], [64835.2, 2.703], [64836.8, 1.191], [64851.9, 2.673], [65343.9, 2.292], [65414.7, 0.305], [65696.9, 0.03]]}
{"kind": "depth", "E": 1787080369013, "U": 11315349599782, "u": 11315349606478, "recv_ms": 1787080368964, "bids": [[14196.8, 3.024], [14296.8, 1.176], [58227.1, 0.002], [61461.9, 0.001], [62108.9, 0.692], [63863.2, 0.0], [63888.1, 7.709], [63999.7, 0.001], [64044.3, 6.499], [64049.8, 0.156], [64114.5, 4.91], [64373.3, 4.432], [64500.7, 15.273], [64539.5, 6.753], [64556.5, 5.115], [64663.9, 0.058], [64664.0, 1.223], [64664.1, 0.011], [64667.3, 3.095], [64667.4, 0.018], [64667.5, 0.014], [64696.8, 5.187]], "asks": [[64706.9, 0.066], [64729.3, 0.976], [64836.8, 6.589], [64853.8, 10.408], [64892.6, 6.147], [65311.5, 4.58], [65343.9, 2.292], [65355.4, 0.306], [65508.6, 14.162], [67931.7, 0.058]]}
{"kind": "depth", "E": 1787080369115, "U": 11315349606592, "u": 11315349613472, "recv_ms": 1787080369066, "bids": [[1000.0, 35.81], [14196.8, 3.388], [14296.8, 0.812], [58227.1, 0.002], [61461.9, 0.0], [63696.8, 0.0], [63703.5, 0.0], [63710.5, 4.258], [63775.1, 0.014], [63776.6, 0.0], [63984.7, 1.748], [64049.8, 0.156], [64373.3, 4.432], [64645.1, 2.159], [64651.5, 0.189], [64653.4, 2.145], [64653.5, 0.074], [64661.7, 2.157], [64661.8, 1.69], [64666.7, 1.611], [64683.0, 0.001], [64685.2, 0.464], [64689.1, 0.093], [64689.2, 0.005], [64690.3, 0.0], [64692.7, 0.581], [64695.8, 0.086], [64696.0, 0.002], [64696.8, 5.197]], "asks": [[64696.9, 14.814], [64698.3, 0.024], [64698.4, 0.003], [64698.7, 0.0], [64698.8, 0.091], [64699.1, 0.785], [64701.9, 0.134], [64702.9, 0.312], [64705.7, 1.238], [64707.0, 0.462], [64707.5, 0.078], [64755.2, 0.319], [64766.8, 0.46], [64794.0, 0.069], [64794.9, 2.127], [64795.0, 0.031], [64803.3, 2.13], [64803.4, 0.002], [64811.6, 2.127], [64811.7, 0.024], [65343.9, 2.292], [65441.6, 14.577], [65617.1, 0.0], [65618.6, 2.727], [65683.3, 0.034], [65690.1, 0.005], [65696.9, 0.01]]}
{"kind": "depth", "E": 1787080369217, "U": 11315349613603, "u": 11315349620077, "recv_ms": 1787080369169, "bids": [[14196.8, 3.71], [14296.8, 0.476], [14596.8, 0.014], [58227.1, 0.002], [62108.9, 0.695], [63703.6, 0.011], [63710.5, 4.266], [63775.1, 0.022], [63776.6, 0.008], [63984.7, 2.622], [64049.8, 0.156], [64680.8, 0.003], [64682.0, 1.595]], "asks": [[64701.3, 0.853], [64702.6, 1.128], [64702.7, 0.187], [64704.0, 1.047], [64704.4, 0.044], [64704.9, 0.006], [64705.5, 0.0], [64705.6, 0.038], [64707.0, 1.362], [64709.4, 0.131], [64713.3, 0.002], [64764.2, 0.024], [64766.8, 0.442], [65020.4, 3.997], [65343.9, 2.292], [65441.6, 13.669], [65683.3, 0.042], [66184.9, 0.755], [67931.7, 0.053]]}
{"kind": "depth", "E": 1787080369319, "U": 11315349620258, "u": 11315349628612, "recv_ms": 1787080369279, "bids": [[1000.0, 35.96], [14196.8, 3.71], [14296.8, 0.294], [14596.8, 0.196], [51758.0, 0.0], [58227.1, 0.002], [62108.9, 0.692], [63402.9, 0.922], [63696.8, 0.02], [63778.1, 1.258], [63823.4, 3.436], [63979.5, 4.057], [64049.8, 0.156], [64687.1, 0.005]], "asks": [[64702.5, 0.009], [64702.6, 0.124], [64702.7, 0.063], [64705.6, 1.166], [65020.4, 3.996], [65148.3, 0.0], [65343.9, 2.292], [65448.7, 0.763], [65617.1, 0.008], [65618.6, 2.735], [65690.2, 0.012], [65696.9, 0.03]]}
{"kind": "depth", "E": 1787080369421, "U": 11315349628625, "u": 11315349640957, "recv_ms": 1787080369372, "bids": [[1000.0, 35.81], [14196.8, 3.598], [14296.8, 0.168], [14596.8, 0.434], [51758.0, 0.0], [58227.1, 0.002], [61461.9, 0.0], [62108.9, 0.695], [63812.7, 9.601], [64049.8, 0.156], [64373.3, 4.433], [64539.5, 6.845], [64540.7, 1.236], [64556.5, 5.162], [64603.4, 0.093], [64603.5, 2.656], [64657.9, 0.006], [64660.5, 0.003], [64662.1, 0.008], [64663.9, 0.06], [64664.0, 1.225], [64664.1, 0.013], [64667.3, 3.097], [64667.4, 0.02], [64667.5, 0.016], [64679.0, 0.003], [64686.4, 0.001], [64686.8, 0.298], [64689.0, 0.001], [64692.7, 0.581], [64692.8, 0.312], [64696.6, 0.022], [64696.8, 5.438]], "asks": [[64702.7, 0.18], [64702.9, 0.311], [64703.0, 0.914], [64705.6, 1.049], [64709.0, 1.079], [64716.8, 0.453], [64721.7, 0.012], [64724.2, 0.619], [64826.3, 0.0], [64826.6, 0.015], [64826.7, 0.029], [64836.8, 6.589], [64851.9, 1.277], [64853.7, 11.873], [64853.8, 0.0], [64892.6, 5.773], [65343.9, 2.292], [65441.6, 14.585], [65709.1, 0.651]]}
{"kind": "depth", "E": 1787080369523, "U": 11315349641066, "u": 11315349647013, "recv_ms": 1787080369475, "bids": [[14196.8, 3.472], [14296.8, 0.056], [14596.8, 0.672], [58227.1, 0.002], [61461.9, 0.0], [61462.1, 0.002], [62108.9, 0.692], [63397.4, 0.0], [63696.8, 0.0], [63720.8, 0.469], [64049.8, 0.156], [64676.8, 1.553], [64680.6, 0.37]], "asks": [[64696.9, 14.854], [64702.7, 0.063], [64703.0, 0.014], [64704.0, 0.147], [64705.0, 0.019], [64705.6, 1.166], [64766.8, 0.451], [65156.0, 0.585], [65343.9, 2.292], [65536.6, 0.0], [65678.9, 0.305], [65696.9, 0.01], [66002.5, 0.0]]}
{"kind": "depth", "E": 1787080369625, "U": 11315349647047, "u": 11315349652254, "recv_ms": 1787080369576, "bids": [[1000.0, 35.81], [14196.8, 3.234], [14296.8, 0.0], [14596.8, 0.966], [51757.4, 0.0], [58227.1, 0.002], [63985.1, 0.936], [64049.8, 0.156], [64663.5, 0.001], [64690.6, 0.297], [64692.8, 0.102], [64694.3, 0.024], [64694.5, 0.021], [64695.8, 0.002]], "asks": [[64698.4, 0.087], [64699.9, 0.38], [64701.3, 0.615], [64706.0, 0.906], [64892.6, 4.245], [65343.9, 2.292], [65492.0, 7.692], [65505.6, 6.827]]}
{"kind": "depth", "E": 1787080369727, "U": 11315349652437, "u": 11315349658081, "recv_ms": 1787080369686, "bids": [[1000.0, 35.81], [14196.8, 2.87], [14596.8, 1.33], [34000.0, 1.146], [58227.1, 0.002], [61461.9, 0.0], [61462.0, 0.01], [62108.9, 0.695], [63696.8, 0.02], [63797.5, 7.165], [64049.8, 0.156], [64373.3, 4.423], [64626.9, 0.832], [64676.8, 1.437], [64677.0, 1.145], [64677.9, 0.231], [64679.9, 0.017], [64680.5, 0.929], [64680.6, 0.377], [64681.5, 1.248], [64689.0, 0.549], [64690.6, 0.087], [64692.7, 0.033], [64692.8, 0.102], [64693.5, 0.212], [64694.4, 0.088], [64695.3, 0.003], [64696.8, 5.437]], "asks": [[64696.9, 14.856], [64697.8, 0.087], [64704.0, 1.047], [64713.2, 0.227], [64713.9, 0.963], [64715.9, 0.002], [64716.4, 6.694], [64718.3, 0.134], [64719.4, 0.542], [64720.0, 2.17], [64720.7, 0.216], [65214.5, 7.805], [65343.9, 2.292], [65667.4, 11.381], [65696.9, 0.03], [65796.8, 2.106]]}
{"kind": "depth", "E": 1787080369829, "U": 11315349658232, "u": 11315349663482, "recv_ms": 1787080369785, "bids": [[14196.8, 2.52], [14596.8, 1.68], [51758.0, 0.0], [58227.1, 0.002], [62108.9, 0.692], [63082.3, 1.744], [64049.8, 0.156], [64664.8, 3.019], [64665.1, 1.335], [64667.3, 0.112], [64674.0, 1.32], [64689.0, 0.008], [64689.1, 0.634], [64690.1, 0.004], [64692.7, 0.243], [64693.5, 0.002], [64694.8, 0.084]], "asks": [[64699.1, 0.782], [64699.5, 0.392], [64704.6, 0.249], [64705.5, 0.309], [64715.5, 1.353], [64717.8, 0.002], [64724.7, 3.344], [64766.8, 0.442], [65343.9, 2.292], [65441.6, 13.677], [65473.3, 28.219], [65615.6, 1.606], [67931.7, 0.058]]}
{"kind": "depth", "E": 1787080369931, "U": 11315349663487, "u": 11315349669556, "recv_ms": 1787080369882, "bids": [[1000.0, 35.81], [14196.8, 2.156], [14596.8, 2.044], [58227.1, 0.002], [62108.9, 0.695], [63696.8, 0.0], [63979.5, 3.823], [64049.8, 0.156], [64097.4, 13.266], [64505.7, 0.0], [64556.6, 1.595], [64689.0, 0.001], [64689.1, 0.093], [64692.7, 0.574], [64692.8, 0.109], [64696.7, 0.119]], "asks": [[64696.9, 14.813], [64697.4, 0.043], [64717.4, 1.543], [64719.7, 0.002], [64723.9, 1.764], [64766.8, 0.46], [64835.2, 3.464], [64892.6, 4.276], [65214.5, 8.11], [65278.1, 0.003], [65343.9, 2.292], [65556.7, 4.721], [65696.9, 0.01]]}
{"kind": "depth", "E": 1787080370033, "U": 11315349669756, "u": 11315349676124, "recv_ms": 1787080369985, "bids": [[1000.0, 35.81], [14196.8, 1.806], [14596.8, 2.394], [58227.1, 0.002], [61461.9, 0.0], [63079.4, 0.101], [63696.8, 0.02], [63794.0, 37.401], [64049.8, 0.156], [64373.3, 4.423], [64599.8, 6.671], [64677.3, 0.025], [64680.2, 0.208], [64690.4, 0.007]], "asks": [[64696.9, 14.735], [64699.5, 0.373], [64699.7, 0.002], [64722.8, 10.006], [64766.8, 0.442], [65343.9, 2.294], [65441.6, 14.593], [65696.9, 0.03], [66635.1, 0.003], [67931.7, 0.053]]}
