{"kind": "depth", "E": 1787080321889, "U": 11315345965564, "u": 11315345972679, "recv_ms": 1787080321839, "bids": [[1000.0, 35.81], [14199.8, 2.31], [14599.8, 1.89], [51760.0, 0.004], [58229.8, 0.053], [61464.8, 2.445], [62111.8, 1.898], [62987.3, 0.0], [63405.9, 0.013], [63699.8, 0.011], [64052.8, 1.808], [64685.7, 0.162], [64686.5, 0.002], [64688.3, 0.56], [64688.5, 0.024], [64693.3, 0.107], [64697.1, 0.002], [64699.8, 5.104]], "asks": [[64699.9, 23.325], [64700.2, 0.086], [64702.7, 0.003], [64704.6, 0.003], [64707.2, 0.163], [64710.4, 0.163], [64712.1, 0.002], [65346.9, 4.434], [65699.9, 0.931]]}
{"kind": "depth", "E": 1787080321991, "U": 11315345972857, "u": 11315345978617, "recv_ms": 1787080322003, "bids": [[1000.0, 35.81], [14199.8, 1.946], [14599.8, 2.254], [51759.8, 0.0], [58229.8, 0.053], [62111.8, 1.895], [63664.6, 4.831], [63858.6, 1.175], [63914.8, 9.031], [63923.4, 38.059], [63947.3, 3.12], [64052.8, 1.81], [64182.2, 10.145], [64376.3, 6.795], [64559.8, 4.145], [64622.1, 0.021], [64622.9, 37.318], [64624.7, 0.018], [64625.0, 1.59], [64641.5, 0.009], [64654.5, 0.001], [64660.9, 0.023], [64677.6, 0.173], [64678.0, 0.135], [64678.6, 5.001], [64686.2, 0.157], [64686.4, 0.001], [64691.5, 0.101], [64692.3, 0.002], [64692.7, 0.033], [64693.2, 0.315], [64693.9, 0.085], [64697.3, 0.085], [64699.8, 7.276]], "asks": [[64701.9, 0.005], [64702.6, 0.192], [64702.7, 0.003], [64707.2, 0.163], [64707.7, 0.667], [64710.4, 0.163], [64712.1, 0.002], [64716.7, 0.005], [64716.9, 0.003], [64741.4, 0.57], [64745.2, 0.037], [64809.9, 0.001], [64839.9, 6.863], [64895.7, 5.555], [65346.9, 4.434], [65521.2, 6.297], [65702.7, 17.023], [65735.1, 8.477]]}
{"kind": "depth", "E": 1787080322093, "U": 11315345978626, "u": 11315345984379, "recv_ms": 1787080322045, "bids": [[14199.8, 1.582], [14599.8, 2.618], [58229.8, 0.053], [61464.8, 2.445], [62111.8, 1.898], [63699.8, 0.031], [63955.8, 9.913], [64052.8, 1.808], [64376.3, 6.794], [64622.9, 3.939], [64625.0, 34.794], [64660.9, 0.037], [64667.6, 0.851], [64681.0, 0.077], [64681.5, 0.936], [64688.0, 2.379], [64688.2, 0.573], [64688.3, 0.004], [64688.4, 0.542], [64688.5, 0.016], [64688.6, 0.001], [64689.0, 0.001], [64689.1, 0.0], [64689.2, 0.315], [64689.3, 0.564], [64692.3, 0.002], [64693.8, 0.004], [64693.9, 0.084], [64695.4, 0.023], [64696.8, 0.004], [64697.3, 0.001], [64699.8, 7.274]], "asks": [[64699.9, 23.233], [64700.2, 0.086], [64702.7, 0.158], [64704.7, 0.094], [64706.8, 0.172], [64706.9, 0.585], [64707.3, 0.549], [64708.0, 1.044], [64708.4, 0.296], [64710.4, 0.473], [64712.1, 0.157], [65023.4, 4.924], [65346.9, 4.434], [65699.9, 0.951], [65993.8, 0.053], [104929.0, 0.0]]}
{"kind": "depth", "E": 1787080322195, "U": 11315345984471, "u": 11315345990116, "recv_ms": 1787080322150, "bids": [[1000.0, 35.81], [14199.8, 1.246], [14599.8, 2.954], [51760.0, 0.004], [58229.8, 0.053], [61464.8, 2.447], [62952.9, 0.952], [63405.9, 0.016], [63664.6, 5.929], [63761.7, 25.924], [63891.1, 17.907], [63923.4, 38.839], [63958.1, 1.641], [64052.8, 1.808], [64182.2, 10.456], [64559.8, 0.0], [64624.7, 0.0], [64660.9, 0.023], [64688.0, 3.279], [64689.0, 0.542], [64689.3, 0.023], [64689.4, 0.002], [64690.3, 0.0], [64692.3, 0.002], [64693.4, 0.247], [64693.8, 0.003], [64699.8, 7.275]], "asks": [[64699.9, 23.294], [64702.7, 0.003], [64706.8, 0.017], [64706.9, 0.586], [64707.0, 1.394], [64708.0, 1.944], [64708.4, 0.141], [64710.4, 0.163], [64711.0, 0.312], [64712.1, 0.002], [64839.9, 1.465], [65023.4, 4.923], [65346.9, 4.434], [65508.6, 13.605], [65735.1, 7.414]]}
{"kind": "depth", "E": 1787080322297, "U": 11315345990388, "u": 11315345996986, "recv_ms": 1787080322248, "bids": [[1000.0, 35.81], [14199.8, 0.882], [14599.8, 3.318], [51760.0, 0.004], [58229.8, 0.053], [61464.8, 2.447], [62111.8, 1.895], [63699.8, 0.011], [64052.8, 1.808], [64182.2, 10.145], [64376.3, 6.639], [64559.8, 4.677], [64625.1, 6.206], [64660.9, 0.037], [64664.9, 2.819], [64665.3, 0.047], [64665.8, 2.161], [64666.1, 0.0], [64670.1, 0.004], [64677.2, 0.002], [64677.5, 0.002], [64677.6, 0.173], [64678.0, 0.133], [64680.9, 2.214], [64681.5, 0.01], [64681.7, 0.016], [64682.1, 0.016], [64684.3, 0.012], [64684.7, 0.003], [64688.2, 0.016], [64688.5, 0.557], [64688.6, 0.558], [64689.0, 0.001], [64691.5, 0.102], [64692.3, 0.19], [64692.7, 0.117], [64693.2, 0.312], [64693.4, 0.246], [64695.9, 1.926], [64699.8, 4.886]], "asks": [[64701.4, 0.009], [64701.6, 0.109], [64701.9, 0.0], [64702.7, 0.003], [64706.8, 0.017], [64706.9, 0.585], [64708.0, 1.944], [64710.4, 0.163], [64712.1, 0.002], [64713.4, 0.943], [64714.0, 0.102], [64714.6, 0.249], [64715.3, 0.354], [64716.4, 6.118], [64716.8, 0.181], [64717.3, 0.559], [64717.5, 2.532], [64717.6, 2.774], [64718.0, 0.001], [64718.3, 0.675], [64719.2, 0.017], [64720.7, 0.009], [64721.3, 2.082], [64741.4, 0.528], [64758.4, 1.888], [64767.2, 0.5], [64839.9, 6.863], [64895.7, 3.804], [65346.9, 4.434], [65476.5, 2.289], [65699.9, 0.931], [65735.1, 8.478]]}
{"kind": "depth", "E": 1787080322399, "U": 11315345997041, "u": 11315346003673, "recv_ms": 1787080322350, "bids": [[14199.8, 0.518], [14599.8, 3.682], [58229.8, 0.053], [61464.8, 2.447], [62111.8, 1.898], [62738.9, 0.002], [63752.2, 0.022], [63923.4, 36.965], [63942.8, 4.928], [64052.8, 1.81], [64376.3, 6.64], [64656.8, 0.085], [64664.9, 2.819], [64665.7, 0.161], [64677.7, 0.12], [64680.5, 0.009], [64680.9, 2.214], [64681.1, 0.002], [64681.3, 1.239], [64681.7, 0.016], [64683.6, 0.362], [64685.4, 0.086], [64687.4, 0.31], [64687.9, 1.761], [64688.2, 0.008], [64688.5, 0.541], [64688.7, 0.024], [64695.4, 0.0], [64699.8, 4.895]], "asks": [[64699.9, 23.308], [64700.7, 0.0], [64701.2, 0.022], [64702.7, 0.003], [64705.7, 0.002], [64706.5, 0.005], [64706.8, 0.017], [64706.9, 0.585], [64710.4, 0.163], [64712.1, 0.002], [64713.0, 0.009], [64713.3, 0.925], [64713.4, 0.018], [64714.1, 0.06], [64714.3, 0.0], [64715.9, 0.023], [64716.3, 0.167], [64716.8, 0.124], [64716.9, 0.001], [64717.6, 2.831], [64718.3, 0.675], [64719.2, 0.017], [64829.3, 2.322], [65023.4, 5.077], [65346.9, 4.434], [65598.9, 1.217], [65628.1, 3.178], [104929.0, 0.236]]}
{"kind": "depth", "E": 1787080322501, "U": 11315346003719, "u": 11315346014236, "recv_ms": 1787080322451, "bids": [[1000.0, 35.81], [14199.8, 0.308], [14499.8, 0.14], [14599.8, 3.752], [58229.8, 0.053], [62111.8, 1.895], [63697.0, 16.153], [63699.8, 0.031], [63761.7, 25.923], [64052.8, 1.808], [64182.2, 10.456], [64376.3, 6.805], [64675.5, 0.559], [64675.8, 0.128], [64676.5, 0.001], [64677.4, 0.459], [64677.7, 0.004], [64678.2, 0.192], [64678.3, 3.356], [64678.5, 0.002], [64688.2, 0.001], [64688.4, 0.002], [64688.6, 0.009], [64688.7, 0.093], [64689.0, 0.016], [64689.1, 1.012], [64692.3, 0.002], [64693.3, 0.107]], "asks": [[64699.9, 23.393], [64700.1, 0.009], [64700.3, 0.06], [64700.6, 0.085], [64702.7, 0.003], [64704.7, 0.002], [64706.6, 0.009], [64706.8, 0.557], [64706.9, 0.577], [64707.3, 0.009], [64709.0, 0.896], [64710.4, 0.163], [64712.1, 0.002], [64713.3, 0.0], [64714.3, 0.925], [64716.0, 1.029], [64716.9, 0.557], [64717.3, 0.003], [64718.3, 0.675], [64718.7, 0.01], [64718.9, 0.073], [64719.2, 0.017], [64720.2, 0.001], [64721.0, 0.132], [64721.3, 1.967], [65346.9, 4.434], [65586.3, 2.437], [65638.0, 31.804], [65650.6, 16.18], [65699.9, 0.951], [65735.1, 9.541]]}
{"kind": "depth", "E": 1787080322603, "U": 11315346014275, "u": 11315346025007, "recv_ms": 1787080322554, "bids": [[1000.0, 35.81], [14199.8, 0.196], [14499.8, 0.392], [14599.8, 3.612], [58229.8, 0.053], [61464.8, 2.447], [62111.8, 1.898], [63017.6, 0.0], [63761.7, 27.018], [63923.4, 38.839], [64052.8, 1.808], [64678.6, 0.001], [64683.6, 0.029], [64684.1, 0.863], [64688.0, 2.379], [64688.2, 1.129], [64688.6, 0.001], [64688.7, 0.0], [64689.0, 0.001], [64689.1, 0.0], [64693.3, 0.295], [64699.8, 4.899]], "asks": [[64702.7, 0.003], [64706.6, 0.001], [64706.7, 0.344], [64706.8, 0.094], [64707.3, 0.009], [64708.0, 1.044], [64710.4, 0.163], [64712.1, 0.473], [64718.3, 0.134], [64719.2, 0.558], [64895.7, 4.005], [65346.9, 4.435]]}
{"kind": "depth", "E": 1787080322705, "U": 11315346025210, "u": 11315346031633, "recv_ms": 1787080322658, "bids": [[14199.8, 0.07], [14499.8, 0.616], [14599.8, 3.514], [58229.8, 0.053], [61464.8, 2.449], [62752.8, 2.308], [63428.3, 2.61], [63699.8, 0.011], [63761.7, 25.922], [63955.8, 8.976], [64052.8, 1.808], [64625.0, 1.59], [64625.1, 0.0], [64627.2, 33.237], [64683.8, 0.022], [64687.0, 0.936], [64693.3, 0.295]], "asks": [[64704.5, 1.064], [64705.6, 0.547], [64705.7, 0.589], [64706.0, 0.904], [64706.8, 0.001], [64706.9, 0.02], [64707.3, 0.002], [64708.0, 1.944], [64712.1, 0.002], [64716.3, 0.165], [65346.9, 4.435], [65638.0, 31.918], [65699.9, 0.931], [65993.8, 0.05], [66650.3, 0.644]]}
{"kind": "depth", "E": 1787080322807, "U": 11315346031862, "u": 11315346038054, "recv_ms": 1787080322757, "bids": [[1000.0, 35.81], [14199.8, 0.0], [14499.8, 0.91], [14599.8, 3.29], [58229.8, 0.053], [61464.8, 2.449], [62111.8, 1.895], [63664.6, 4.831], [63697.0, 17.251], [63761.7, 27.019], [63923.4, 38.37], [63955.8, 9.913], [64052.8, 1.808], [64376.3, 6.795], [64542.8, 6.594], [64559.8, 4.077], [64666.9, 1.312], [64667.0, 0.004], [64667.1, 0.309], [64670.3, 0.347], [64670.4, 1.242], [64670.5, 0.71], [64683.8, 0.024], [64693.3, 0.201], [64696.3, 0.085]], "asks": [[64699.9, 23.392], [64700.3, 0.057], [64700.5, 0.003], [64702.7, 0.003], [64705.7, 0.126], [64706.8, 0.001], [64706.9, 0.483], [64707.3, 0.002], [64710.4, 0.163], [64712.1, 0.002], [64716.3, 0.167], [64839.9, 6.863], [64854.8, 2.18], [64856.9, 10.408], [64895.7, 6.336], [65346.9, 4.435], [65578.2, 1.522], [65791.0, 28.968], [66058.6, 2.268]]}
{"kind": "depth", "E": 1787080322909, "U": 11315346038357, "u": 11315346048777, "recv_ms": 1787080322860, "bids": [[1000.0, 35.81], [14499.8, 1.274], [14599.8, 2.926], [58229.8, 0.053], [61774.8, 0.0], [62111.8, 1.898], [63664.6, 5.929], [63699.8, 0.031], [63761.7, 28.115], [63955.8, 8.976], [64009.9, 2.193], [64052.8, 1.808], [64693.3, 0.295]], "asks": [[65159.6, 0.0], [65346.9, 4.435], [65699.9, 0.951]]}
{"kind": "depth", "E": 1787080323011, "U": 11315346048927, "u": 11315346055557, "recv_ms": 1787080322963, "bids": [[14499.8, 1.624], [14599.8, 2.576], [51759.8, 0.0], [58229.8, 0.053], [61464.8, 2.449], [62111.8, 1.895], [63226.5, 0.0], [63882.5, 7.076], [63929.9, 8.433], [63955.8, 9.913], [64052.8, 1.808], [64559.8, 0.0], [64605.2, 0.029], [64688.5, 0.0], [64689.0, 0.542], [64693.3, 0.295]], "asks": [[64699.9, 23.367], [64702.7, 0.003], [64706.8, 0.001], [64707.3, 0.002], [64710.4, 0.163], [64712.1, 0.002], [64764.6, 0.022], [64839.9, 1.465], [65134.2, 0.012], [65346.9, 4.435], [65799.8, 10.181]]}
{"kind": "depth", "E": 1787080323113, "U": 11315346055788, "u": 11315346062130, "recv_ms": 1787080323066, "bids": [[1000.0, 35.81], [14499.8, 1.988], [14599.8, 2.212], [58229.8, 0.053], [61464.8, 2.449], [62111.8, 1.898], [63699.8, 0.011], [63923.4, 38.839], [63994.6, 5.92], [64052.8, 1.808], [64376.3, 6.805], [64559.8, 4.65], [64645.3, 3.601], [64653.6, 2.249], [64654.5, 0.004], [64661.9, 3.051], [64664.9, 2.762], [64665.5, 0.058], [64680.9, 1.288], [64681.5, 0.936], [64686.1, 0.358], [64686.2, 0.003], [64688.2, 1.129], [64692.7, 0.033], [64693.3, 0.295], [64693.4, 0.246], [64696.7, 0.086], [64697.3, 0.001], [64699.8, 4.899]], "asks": [[64699.9, 23.26], [64700.2, 0.086], [64701.6, 0.106], [64702.5, 0.015], [64702.7, 0.158], [64706.8, 0.156], [64707.3, 0.157], [64710.4, 0.473], [64712.1, 0.157], [64713.0, 0.002], [64713.5, 0.317], [64713.7, 0.947], [64714.3, 0.0], [64795.2, 6.265], [64795.3, 0.442], [64803.5, 2.134], [64803.6, 0.001], [64809.9, 0.004], [64811.8, 2.536], [64811.9, 0.018], [64839.9, 6.863], [64895.7, 4.098], [65023.4, 5.076], [65346.9, 4.435], [65699.9, 0.931], [66058.6, 2.57]]}
{"kind": "depth", "E": 1787080323215, "U": 11315346062181, "u": 11315346069471, "recv_ms": 1787080323175, "bids": [[1000.0, 35.81], [14499.8, 2.338], [14599.8, 1.862], [58229.8, 0.053], [63929.9, 9.37], [64052.8, 1.808], [64182.2, 10.767], [64376.3, 6.806], [64575.8, 0.005], [64641.5, 0.009], [64654.5, 0.001], [64681.2, 0.93], [64681.5, 0.01], [64688.6, 0.002], [64692.3, 0.19], [64693.3, 0.107], [64696.4, 0.0]], "asks": [[64699.9, 23.259], [64702.5, 0.005], [64702.7, 0.003], [64705.2, 0.002], [64706.8, 0.001], [64707.3, 0.002], [64710.4, 0.163], [64712.1, 0.002], [64717.7, 0.233], [64745.2, 0.037], [64767.2, 0.518], [64809.9, 0.001], [65346.9, 4.435]]}
{"kind": "depth", "E": 1787080323419, "U": 11315346079552, "u": 11315346085527, "recv_ms": 1787080323368, "bids": [[1000.0, 35.81], [14499.8, 3.052], [14599.8, 1.148], [58229.8, 0.053], [62111.8, 1.898], [63214.3, 0.006], [64052.8, 1.808], [64182.2, 10.76], [64376.3, 6.805], [64672.1, 0.0], [64681.0, 0.977], [64685.4, 0.116], [64686.1, 0.328], [64688.2, 0.541], [64688.3, 1.846], [64688.4, 0.002], [64688.7, 0.565], [64689.0, 0.557], [64691.2, 1.9], [64692.3, 0.002], [64693.5, 0.234], [64697.1, 0.01]], "asks": [[64701.6, 0.084], [64703.0, 0.014], [64705.6, 0.006], [64705.7, 0.049], [64706.9, 0.638], [64707.1, 0.463], [64708.0, 1.044], [64712.1, 0.465], [64713.7, 0.927], [64772.3, 40.837], [64774.5, 0.062], [64790.6, 0.0], [64829.3, 2.322], [65023.4, 5.077], [65346.9, 4.435], [65643.0, 0.304]]}
{"kind": "depth", "E": 1787080323521, "U": 11315346085611, "u": 11315346092612, "recv_ms": 1787080323473, "bids": [[1000.0, 35.81], [14499.8, 3.402], [14599.8, 0.798], [58229.8, 0.053], [61464.8, 2.449], [61762.8, 0.346], [62111.8, 1.895], [63664.6, 4.831], [63699.8, 0.011], [63761.7, 25.922], [63764.0, 1.152], [64052.8, 1.808], [64666.9, 1.314], [64667.0, 0.006], [64667.1, 0.311], [64670.3, 0.349], [64670.4, 1.244], [64670.5, 0.712], [64674.5, 0.56], [64675.3, 0.004], [64675.5, 0.002], [64676.2, 0.199], [64677.1, 2.461], [64677.4, 0.343], [64678.1, 0.009], [64678.3, 3.349], [64687.4, 0.001], [64687.8, 0.315], [64688.2, 0.001], [64688.4, 0.543], [64688.7, 0.463], [64689.0, 0.001], [64689.1, 0.0], [64689.3, 0.023], [64691.7, 0.751], [64692.7, 0.117], [64693.5, 0.046], [64695.9, 2.01], [64696.3, 0.001], [64699.8, 4.28]], "asks": [[64699.9, 23.258], [64700.1, 0.002], [64700.5, 0.007], [64700.7, 0.003], [64702.7, 0.003], [64705.6, 0.547], [64705.7, 0.086], [64706.8, 0.001], [64706.9, 0.02], [64710.4, 0.163], [64712.0, 0.003], [64712.1, 0.473], [64713.0, 0.927], [64713.6, 0.01], [64713.7, 0.002], [64715.4, 0.551], [64715.6, 0.975], [64716.3, 0.165], [64716.9, 0.003], [64718.3, 0.682], [64718.7, 0.003], [64719.9, 0.115], [64721.0, 0.017], [64731.2, 3.109], [65346.9, 4.437], [65421.9, 0.863], [65638.0, 30.853], [65699.9, 0.931], [65735.1, 8.478], [65814.0, 4.097]]}
{"kind": "depth", "E": 1787080323725, "U": 11315346101302, "u": 11315346106979, "recv_ms": 1787080323676, "bids": [[1000.0, 35.81], [14399.8, 0.196], [14499.8, 3.724], [14599.8, 0.28], [58229.8, 0.053], [61464.8, 2.449], [62111.8, 1.898], [63632.3, 3.297], [63699.8, 0.031], [63923.4, 39.058], [64052.8, 1.808], [64156.3, 0.915], [64376.3, 6.805], [64575.7, 0.114], [64627.3, 0.012], [64689.1, 0.077], [64691.2, 1.9], [64691.5, 0.102], [64691.7, 0.133], [64696.2, 0.154], [64699.8, 4.281]], "asks": [[64702.7, 0.003], [64703.0, 0.014], [64704.8, 0.01], [64705.6, 0.006], [64705.7, 0.583], [64706.8, 0.001], [64706.9, 0.104], [64707.5, 0.0], [64708.4, 0.141], [64710.4, 0.163], [64711.9, 0.002], [64712.1, 0.465], [64731.2, 2.955], [64731.3, 0.322], [65346.9, 4.434], [65699.9, 0.951], [65767.4, 5.315]]}
{"kind": "depth", "E": 1787080323827, "U": 11315346107029, "u": 11315346122848, "recv_ms": 1787080323779, "bids": [[1000.0, 35.81], [14399.8, 0.448], [14499.8, 3.584], [14599.8, 0.168], [58229.8, 0.053], [62111.8, 1.895], [63664.6, 5.929], [63697.0, 16.154], [63761.7, 28.115], [64052.8, 1.808], [64639.0, 0.0], [64640.0, 0.997], [64645.5, 0.001], [64646.5, 0.579], [64658.4, 0.151], [64659.4, 0.403], [64679.7, 0.0], [64680.9, 2.214], [64683.8, 0.024], [64689.1, 0.108], [64691.7, 0.102], [64692.8, 0.005], [64693.3, 0.107], [64696.6, 0.087], [64699.8, 4.973]], "asks": [[64701.0, 0.073], [64701.1, 0.109], [64701.4, 0.009], [64702.7, 0.003], [64705.5, 0.0], [64705.6, 0.006], [64705.7, 0.026], [64706.8, 0.001], [64706.9, 0.645], [64708.4, 0.141], [64710.4, 0.163], [64712.0, 0.003], [64712.1, 0.481], [64716.3, 0.165], [64731.3, 0.168], [64731.5, 0.182], [64764.6, 0.022], [64891.3, 0.0], [64891.4, 0.003], [65346.9, 4.434], [65469.8, 8.235], [65638.0, 31.918], [65735.1, 9.541]]}
{"kind": "depth", "E": 1787080323929, "U": 11315346123250, "u": 11315346130665, "recv_ms": 1787080323879, "bids": [[14399.8, 0.672], [14499.8, 3.486], [14599.8, 0.042], [58229.8, 0.053], [62111.8, 1.898], [63405.9, 0.01], [63573.3, 0.0], [63699.8, 0.011], [64052.8, 1.808], [64674.5, 0.003], [64676.3, 0.559], [64692.3, 0.002]], "asks": [[64705.0, 0.917], [64713.1, 0.13], [64714.1, 0.985], [64715.6, 0.419], [64716.6, 0.025], [64716.7, 0.561], [64717.5, 2.589], [64718.3, 0.141], [64718.9, 0.614], [64719.9, 0.0], [64720.8, 0.118], [64731.3, 0.322], [64731.5, 0.028], [64895.7, 3.251], [65346.9, 4.434], [65420.8, 3.432], [65699.9, 0.931]]}
{"kind": "depth", "E": 1787080324031, "U": 11315346130886, "u": 11315346136864, "recv_ms": 1787080323988, "bids": [[1000.0, 35.81], [14399.8, 0.994], [14499.8, 3.206], [14599.8, 0.0], [51759.8, 0.0], [58229.8, 0.053], [62111.8, 1.895], [63632.3, 4.396], [63947.2, 4.215], [64052.8, 1.808], [64076.7, 0.0], [64376.3, 6.805], [64597.9, 0.026], [64601.1, 1.716], [64675.1, 0.671], [64676.3, 0.002], [64680.5, 0.935], [64680.9, 1.288], [64688.4, 0.543], [64688.7, 0.463], [64693.5, 0.234]], "asks": [[64705.7, 0.033], [64706.9, 0.638], [64712.9, 3.053], [64714.1, 0.06], [64716.2, 0.078], [64717.5, 2.532], [64718.3, 0.682], [64718.9, 0.073], [65346.9, 4.434], [65767.4, 6.378], [71169.9, 0.0]]}
{"kind": "depth", "E": 1787080324133, "U": 11315346136866, "u": 11315346143428, "recv_ms": 1787080324085, "bids": [[1000.0, 35.81], [14399.8, 1.344], [14499.8, 2.856], [58229.8, 0.053], [61464.8, 2.449], [63405.9, 0.013], [63561.1, 0.802], [63697.0, 17.251], [63699.8, 0.031], [64052.8, 1.808], [64667.2, 1.153], [64688.2, 0.001], [64699.8, 5.004]], "asks": [[64699.9, 23.237], [64702.7, 0.003], [64705.7, 0.574], [64706.1, 0.065], [64706.8, 0.001], [64706.9, 0.097], [64708.4, 0.141], [64710.4, 0.163], [64712.0, 0.019], [64712.1, 0.465], [64712.9, 2.128], [64713.3, 0.925], [64716.2, 0.021], [64716.7, 0.618], [65346.9, 4.434], [65405.1, 3.888], [65469.8, 9.15], [65699.9, 0.951], [67934.8, 0.0]]}
{"kind": "depth", "E": 1787080324745, "U": 11315346176887, "u": 11315346181937, "recv_ms": 1787080324696, "bids": [[1000.0, 35.81], [14399.8, 3.486], [14499.8, 0.714], [58229.8, 0.053], [61464.8, 2.447], [62111.8, 1.898], [63405.9, 0.01], [63699.8, 0.011], [64052.8, 1.808], [64100.5, 2.778], [64635.1, 0.346], [64664.7, 0.057], [64665.6, 0.007], [64675.1, 0.114], [64675.5, 0.559], [64676.3, 0.002], [64680.5, 0.009], [64680.7, 1.094], [64681.6, 0.016], [64686.0, 0.125], [64692.3, 0.102], [64693.5, 0.234], [64699.8, 4.945]], "asks": [[64702.7, 0.003], [64706.8, 0.032], [64708.4, 0.141], [64710.4, 0.163], [64712.1, 0.465], [64713.3, 0.0], [64714.0, 1.027], [64716.0, 1.029], [64716.6, 0.638], [64716.7, 0.005], [64717.5, 2.532], [64718.3, 0.675], [64718.9, 0.073], [64720.2, 0.001], [64720.8, 0.118], [64725.2, 0.137], [64764.6, 0.023], [64780.5, 0.035], [64827.1, 0.0], [64873.8, 0.008], [65346.9, 4.434], [65405.1, 4.574], [65699.9, 0.931], [65799.5, 1.818]]}
{"kind": "depth", "E": 1787080324949, "U": 11315346187954, "u": 11315346194172, "recv_ms": 1787080324899, "bids": [[1000.0, 36.01], [14299.8, 0.252], [14399.8, 3.696], [14499.8, 0.252], [58229.8, 0.053], [61464.8, 2.449], [62111.8, 1.898], [63699.8, 0.031], [64052.8, 1.808], [64376.3, 6.795], [64559.8, 0.0], [64671.2, 0.175], [64693.5, 0.046]], "asks": [[64703.0, 0.014], [64705.0, 0.017], [64705.7, 0.103], [64706.0, 0.904], [64706.8, 0.008], [64706.9, 0.561], [64731.0, 0.242], [64735.7, 0.036], [64839.9, 1.465], [65699.9, 0.951], [65735.1, 9.541]]}
{"kind": "depth", "E": 1787080325051, "U": 11315346194200, "u": 11315346201887, "recv_ms": 1787080325002, "bids": [[1000.0, 36.01], [14299.8, 0.504], [14399.8, 3.556], [14499.8, 0.14], [51759.8, 0.0], [58229.8, 0.053], [61464.8, 2.449], [63923.4, 39.402], [64052.8, 2.151], [64542.8, 6.862], [64559.8, 4.213], [64622.1, 0.024], [64628.2, 0.251], [64650.8, 0.005], [64660.9, 0.023], [64664.7, 0.0], [64664.9, 2.819], [64665.8, 2.161], [64666.9, 0.325], [64667.0, 0.004], [64667.1, 0.309], [64670.3, 0.347], [64670.4, 1.242], [64670.5, 0.71], [64680.7, 0.168], [64680.9, 2.214], [64681.8, 0.02], [64688.2, 0.006], [64692.3, 0.002], [64693.5, 0.046], [64696.6, 0.087], [64699.3, 0.008], [64699.8, 4.944]], "asks": [[64699.9, 23.118], [64700.8, 0.032], [64702.7, 0.158], [64705.6, 0.547], [64705.7, 0.103], [64706.8, 0.163], [64706.9, 0.02], [64708.4, 0.296], [64710.4, 0.163], [64712.0, 0.011], [64712.1, 0.938], [64712.5, 1.243], [64713.6, 0.09], [64714.0, 0.947], [64716.6, 0.581], [64716.8, 0.181], [64717.7, 0.233], [64718.3, 0.675], [64719.2, 0.017], [64720.7, 0.009], [64723.7, 0.164], [64731.0, 0.396], [64741.4, 0.57], [64829.3, 2.322], [64839.9, 6.863], [64856.9, 10.408], [64895.7, 5.094], [65346.9, 4.434], [65596.9, 6.891]]}
{"kind": "depth", "E": 1787080325255, "U": 11315346208963, "u": 11315346215619, "recv_ms": 1787080325207, "bids": [[1000.0, 36.16], [14299.8, 1.078], [14399.8, 3.122], [14499.8, 0.0], [51760.0, 0.004], [58229.8, 0.053], [61464.8, 2.449], [62111.8, 1.898], [63710.3, 0.03], [63906.4, 3.221], [64052.8, 2.151], [64376.3, 6.805], [64559.8, 4.658], [64595.8, 5.213], [64600.0, 14.492], [64601.2, 5.984], [64627.8, 6.026], [64650.0, 2.792], [64650.4, 3.501], [64666.6, 1.043], [64686.0, 0.279], [64692.7, 0.033], [64693.5, 0.234], [64697.1, 0.094], [64699.8, 4.945]], "asks": [[64702.7, 0.003], [64704.6, 0.003], [64705.7, 0.103], [64706.8, 0.008], [64708.4, 0.141], [64710.4, 0.163], [64712.0, 0.019], [64712.1, 0.465], [64721.7, 1.013], [64737.9, 3.523], [64760.6, 6.013], [64767.2, 0.5], [64769.8, 0.0], [64770.1, 0.001], [64774.5, 39.648], [64790.7, 2.439], [64792.9, 0.171], [64839.9, 6.863], [64895.7, 4.376], [65346.9, 4.434], [65617.5, 1.522], [65689.3, 0.027], [65693.2, 0.771], [65993.8, 0.059]]}
{"kind": "depth", "E": 1787080325561, "U": 11315346228677, "u": 11315346233443, "recv_ms": 1787080325510, "bids": [[1000.0, 36.21], [14299.8, 2.142], [14399.8, 2.058], [51760.0, 0.004], [58229.8, 0.053], [63699.8, 0.011], [63891.1, 18.961], [64052.8, 2.151], [64216.8, 0.0], [64376.3, 6.795], [64559.8, 0.0], [64693.3, 0.295], [64693.5, 0.046]], "asks": [[64839.9, 1.465], [65346.9, 4.434], [65699.9, 0.931]]}
{"kind": "depth", "E": 1787080326071, "U": 11315346257029, "u": 11315346264624, "recv_ms": 1787080326020, "bids": [[14199.8, 0.084], [14299.8, 3.766], [14399.8, 0.35], [51759.8, 0.0], [58229.8, 0.053], [61464.8, 2.445], [61464.9, 0.008], [62111.8, 1.898], [64052.8, 2.151], [64100.5, 2.09], [64686.5, 0.002], [64688.1, 2.357], [64688.4, 0.002], [64689.0, 0.009], [64689.1, 0.541], [64689.3, 0.023], [64691.2, 2.054], [64691.7, 0.751], [64693.3, 0.107], [64693.5, 0.234], [64697.1, 0.01], [64697.7, 0.018], [64698.6, 0.007], [64699.3, 0.0], [64699.7, 0.314], [64699.8, 4.941]], "asks": [[64700.2, 0.086], [64701.4, 0.004], [64702.7, 0.003], [64705.7, 0.103], [64706.8, 0.008], [64708.4, 0.141], [64710.4, 0.163], [64712.1, 0.473], [64725.7, 0.009], [64731.2, 2.955], [64764.6, 0.005], [64890.5, 0.859], [64891.8, 0.0], [65346.9, 4.434], [65476.3, 34.372], [65618.6, 3.41], [65786.9, 1.818]]}
{"kind": "depth", "E": 1787080326173, "U": 11315346264778, "u": 11315346270517, "recv_ms": 1787080326123, "bids": [[1000.0, 36.21], [14199.8, 0.322], [14299.8, 3.654], [14399.8, 0.224], [58229.8, 0.053], [62111.8, 1.895], [63699.8, 0.031], [63826.4, 12.094], [64052.8, 2.151], [64376.3, 6.795], [64534.8, 0.141], [64536.7, 0.405], [64664.3, 0.149], [64665.1, 0.962], [64675.0, 0.769], [64676.6, 0.001], [64680.3, 0.931], [64681.1, 0.002], [64684.5, 0.083], [64685.4, 0.036], [64688.2, 0.542], [64688.6, 1.843], [64689.1, 0.0], [64689.3, 0.023], [64690.9, 0.142], [64691.2, 1.9], [64691.7, 0.21], [64691.8, 0.07], [64691.9, 0.544], [64693.5, 0.046]], "asks": [[64707.5, 0.001], [64712.7, 1.089], [64714.4, 0.515], [64716.2, 0.078], [64717.5, 3.073], [64717.8, 1.392], [64718.9, 0.073], [64723.6, 0.439], [64726.1, 0.402], [64895.7, 4.377], [65217.5, 10.283], [65346.9, 4.434], [65469.8, 9.15], [65694.0, 1.978], [65699.9, 0.951]]}
{"kind": "depth", "E": 1787080326377, "U": 11315346276072, "u": 11315346282934, "recv_ms": 1787080326329, "bids": [[14199.8, 0.798], [14299.8, 3.402], [14399.8, 0.0], [58229.8, 0.053], [62111.8, 1.895], [63405.9, 3.256], [63699.8, 0.011], [64052.8, 2.153], [64085.2, 12.843], [64376.3, 6.794], [64580.1, 0.0], [64580.6, 3.865], [64628.5, 0.019], [64628.6, 1.813], [64634.9, 0.043], [64635.2, 1.102], [64635.5, 0.001], [64635.9, 0.022], [64636.2, 0.0], [64654.0, 0.004], [64654.1, 0.097], [64654.3, 0.001], [64654.6, 0.002], [64654.9, 2.319], [64655.3, 0.152], [64668.9, 0.003], [64669.0, 0.001], [64669.1, 0.176], [64669.2, 0.124], [64669.3, 0.0], [64669.4, 0.002], [64669.5, 0.003], [64669.6, 0.022], [64669.7, 0.056], [64669.9, 0.602], [64672.2, 0.006], [64672.6, 0.498], [64683.6, 0.016], [64689.1, 0.008], [64690.9, 0.002], [64691.0, 0.272], [64691.1, 0.015], [64691.2, 1.73], [64691.3, 0.071], [64691.4, 0.019], [64691.5, 0.002], [64691.6, 1.695], [64691.7, 0.156], [64691.8, 0.0], [64692.1, 0.0], [64692.3, 0.034], [64692.4, 0.003], [64692.7, 0.001], [64693.1, 0.001], [64693.4, 0.214], [64693.5, 0.046], [64697.1, 0.002], [64699.8, 4.941]], "asks": [[64702.7, 0.003], [64705.7, 0.095], [64706.7, 0.312], [64706.8, 0.008], [64707.0, 1.887], [64707.4, 1.466], [64707.7, 0.629], [64708.0, 1.044], [64708.3, 0.258], [64708.4, 0.001], [64708.5, 0.466], [64708.6, 2.702], [64708.7, 0.005], [64708.8, 0.121], [64708.9, 0.234], [64709.0, 0.805], [64709.1, 0.001], [64709.2, 0.003], [64710.4, 0.163], [64711.6, 0.092], [64712.1, 0.473], [64717.7, 0.233], [64718.9, 0.614], [64725.8, 1.421], [64726.1, 0.216], [64726.4, 0.007], [64726.8, 0.001], [64727.1, 0.243], [64727.5, 0.002], [64727.9, 0.001], [64730.2, 0.0], [64730.4, 0.22], [64730.5, 0.964], [64730.6, 0.404], [64730.7, 0.001], [64730.8, 0.058], [64730.9, 0.009], [64731.0, 0.151], [64731.1, 0.466], [64731.2, 2.885], [64744.9, 0.024], [64745.2, 0.005], [64745.5, 0.008], [64745.8, 0.036], [64746.1, 0.079], [64771.0, 0.049], [64772.2, 6.928], [64829.3, 2.322], [64835.2, 3.28], [64835.3, 3.864], [64835.4, 0.001], [65023.4, 5.078], [65346.9, 4.434], [65699.9, 0.931], [65993.8, 3.302]]}
{"kind": "depth", "E": 1787080326581, "U": 11315346289483, "u": 11315346297334, "recv_ms": 1787080326532, "bids": [[14199.8, 1.512], [14299.8, 2.688], [51760.0, 0.004], [58229.8, 0.053], [61464.8, 2.445], [62111.8, 1.898], [63405.9, 9.287], [63699.8, 0.031], [63761.7, 28.115], [63999.1, 0.601], [64052.8, 2.151], [64452.5, 0.0], [64454.2, 1.666], [64654.5, 0.033], [64676.5, 0.001], [64677.6, 0.289], [64691.2, 1.87], [64691.4, 0.119], [64691.5, 0.202], [64691.7, 0.202], [64691.8, 0.07], [64692.0, 0.081], [64692.3, 0.222], [64692.6, 0.033]], "asks": [[64699.9, 23.138], [64702.7, 0.003], [64705.7, 0.111], [64706.8, 0.008], [64707.7, 0.667], [64708.2, 0.103], [64708.4, 0.225], [64708.5, 0.586], [64708.8, 0.361], [64708.9, 0.334], [64709.0, 0.896], [64709.1, 0.078], [64710.4, 0.163], [64711.6, 0.084], [64712.1, 0.465], [64720.3, 0.2], [64721.2, 0.116], [64726.7, 0.038], [64727.9, 0.131], [64730.2, 0.098], [64730.4, 0.304], [64730.5, 1.204], [64730.7, 0.111], [64730.8, 0.158], [64731.0, 0.242], [64731.1, 0.543], [64745.8, 0.074], [65346.9, 4.434], [65564.5, 4.987], [65666.7, 1.779], [65699.9, 0.951], [65993.8, 9.327]]}
{"kind": "depth", "E": 1787080326683, "U": 11315346298158, "u": 11315346304321, "recv_ms": 1787080326634, "bids": [[1000.0, 36.21], [14199.8, 1.876], [14299.8, 2.324], [58229.8, 0.053], [62111.8, 1.895], [63813.4, 3.127], [63882.5, 6.725], [64052.8, 2.151], [64376.3, 6.805], [64635.1, 0.378], [64654.8, 1.944], [64674.6, 0.002], [64676.5, 0.117], [64677.6, 0.173], [64682.0, 0.375], [64690.9, 0.001], [64691.1, 0.085], [64691.3, 0.141], [64691.6, 1.795], [64692.3, 0.034], [64692.4, 0.0], [64692.7, 0.085], [64692.9, 0.034], [64696.2, 0.07], [64696.8, 0.004]], "asks": [[64699.9, 23.94], [64701.5, 0.87], [64702.3, 0.069], [64702.6, 0.13], [64702.7, 0.003], [64705.7, 0.103], [64706.8, 0.008], [64707.3, 0.04], [64708.4, 0.225], [64708.7, 0.115], [64708.9, 0.404], [64709.2, 0.15], [64710.4, 0.163], [64711.9, 0.002], [64712.0, 0.011], [64712.1, 0.465], [64712.8, 1.339], [64715.3, 0.354], [64716.0, 1.585], [64716.9, 0.06], [64717.1, 0.001], [64717.4, 0.016], [64718.3, 0.675], [64718.9, 0.073], [64719.9, 0.0], [64726.4, 0.045], [64730.7, 0.221], [64730.9, 0.079], [64731.1, 0.62], [64745.5, 0.046], [65023.4, 5.077], [65346.9, 4.434], [65650.6, 16.066]]}
{"kind": "depth", "E": 1787080326887, "U": 11315346309999, "u": 11315346315977, "recv_ms": 1787080326837, "bids": [[14199.8, 2.59], [14299.8, 1.61], [58229.8, 0.053], [61464.8, 2.445], [62111.8, 1.895], [63923.4, 40.104], [64052.8, 2.151], [64542.8, 0.002], [64559.8, 0.0], [64635.4, 2.355], [64669.7, 0.156], [64672.8, 0.484], [64674.9, 0.631], [64682.3, 0.646], [64683.8, 0.024], [64689.1, 0.0], [64691.8, 0.07], [64692.3, 0.034], [64696.2, 0.154], [64697.1, 0.01], [64699.8, 4.943]], "asks": [[64702.7, 0.003], [64705.0, 0.017], [64705.7, 0.103], [64706.0, 0.004], [64706.8, 0.008], [64708.4, 0.225], [64710.4, 0.163], [64712.0, 0.011], [64712.1, 0.465], [64712.8, 1.957], [64716.3, 0.165], [64720.2, 0.619], [64726.1, 0.402], [64839.9, 1.465], [64856.9, 0.0], [65346.9, 4.434], [65651.0, 10.189], [71169.9, 0.0]]}
{"kind": "depth", "E": 1787080326989, "U": 11315346316073, "u": 11315346321098, "recv_ms": 1787080326940, "bids": [[1000.0, 36.21], [14199.8, 2.954], [14299.8, 1.246], [58229.8, 0.053], [63699.8, 0.031], [63929.9, 8.433], [64052.8, 2.151], [64085.2, 13.543], [64182.2, 10.764], [64361.9, 0.037], [64635.7, 0.191], [64669.2, 0.194], [64669.3, 0.14], [64669.4, 0.102], [64669.5, 0.103], [64669.8, 0.173], [64670.0, 1.474], [64672.4, 0.1], [64688.3, 0.004], [64689.1, 0.0], [64691.6, 2.019], [64692.3, 0.222], [64697.1, 0.01]], "asks": [[64705.6, 0.006], [64705.7, 0.002], [64706.8, 0.125], [64712.0, 0.003], [64854.8, 0.719], [65022.1, 0.13], [65022.8, 0.0], [65346.9, 4.434], [65699.9, 0.951], [67934.8, 0.005]]}
{"kind": "depth", "E": 1787080327091, "U": 11315346321192, "u": 11315346326625, "recv_ms": 1787080327041, "bids": [[1000.0, 36.21], [14199.8, 3.304], [14299.8, 0.896], [51759.8, 0.0], [58229.8, 0.053], [61464.8, 2.445], [62111.8, 1.898], [62744.7, 1.001], [63708.8, 0.0], [63773.5, 0.022], [63775.5, 0.12], [64052.8, 2.151], [64156.3, 0.952], [64182.2, 10.76], [64376.3, 6.805], [64504.0, 12.031], [64542.8, 5.282], [64559.8, 3.08], [64580.6, 0.001], [64580.8, 5.181], [64589.8, 0.0], [64591.6, 2.319], [64628.6, 1.813], [64667.4, 0.007], [64669.1, 0.316], [64669.4, 0.172], [64669.6, 0.122], [64674.9, 0.013], [64682.3, 0.028], [64688.2, 0.001], [64691.5, 0.356], [64691.6, 1.865], [64692.3, 0.034], [64693.3, 0.295], [64697.3, 0.001], [64699.8, 4.683]], "asks": [[64699.9, 23.839], [64702.7, 0.003], [64705.0, 0.917], [64706.8, 0.117], [64708.4, 0.225], [64710.4, 0.163], [64712.0, 0.003], [64712.1, 0.473], [64712.8, 1.339], [64715.5, 0.063], [64745.2, 0.037], [64771.0, 0.049], [64807.2, 2.34], [64835.2, 2.319], [64835.3, 3.864], [64839.9, 6.863], [64854.8, 2.18], [64856.9, 10.408], [64861.7, 4.655], [64895.7, 6.13], [65346.9, 4.434], [65624.1, 0.0], [65626.1, 3.928], [65690.8, 1.055], [65739.3, 0.657]]}
{"kind": "depth", "E": 1787080327193, "U": 11315346326785, "u": 11315346332580, "recv_ms": 1787080327143, "bids": [[14199.8, 3.654], [14299.8, 0.546], [58229.8, 0.053], [62111.8, 1.895], [63699.8, 0.011], [63713.3, 0.015], [63778.0, 0.15], [63779.6, 0.012], [63882.5, 6.491], [63929.9, 9.37], [64035.8, 1.559], [64052.8, 2.153], [64559.8, 0.0], [64669.7, 0.226], [64688.4, 0.544], [64693.3, 0.107], [64693.5, 0.046]], "asks": [[64705.0, 0.918], [64707.5, 0.0], [64726.0, 2.325], [64726.1, 0.402], [64839.9, 1.465], [65346.9, 4.436], [65699.9, 0.931]]}
{"kind": "depth", "E": 1787080327499, "U": 11315346345295, "u": 11315346352536, "recv_ms": 1787080327449, "bids": [[14199.8, 3.5], [14299.8, 0.084], [14599.8, 0.616], [58229.8, 0.053], [61464.8, 2.447], [61464.9, 0.006], [62111.8, 1.895], [64052.8, 2.151], [64542.8, 7.767], [64559.8, 4.676], [64681.0, 0.077], [64682.0, 1.275]], "asks": [[64704.5, 0.725], [64705.7, 0.086], [64706.0, 0.904], [64706.9, 0.577], [64708.0, 1.044], [64708.4, 0.225], [64726.2, 1.243], [64839.9, 6.863], [64854.8, 0.719], [64856.9, 10.408], [64895.7, 4.18], [65346.9, 4.434], [65638.0, 32.032], [66091.8, 0.0]]}
{"kind": "depth", "E": 1787080327601, "U": 11315346352668, "u": 11315346361755, "recv_ms": 1787080327550, "bids": [[1000.0, 36.21], [14199.8, 3.318], [14299.8, 0.0], [14599.8, 0.882], [58229.8, 0.053], [61464.8, 2.447], [62111.8, 1.898], [62111.9, 0.603], [63405.9, 9.284], [63699.8, 0.011], [64052.8, 2.152], [64156.3, 0.915], [64559.8, 4.141], [64666.9, 0.327], [64667.0, 0.006], [64667.1, 0.311], [64670.3, 0.349], [64670.4, 1.244], [64670.5, 0.712], [64677.6, 0.222], [64677.7, 0.091], [64684.1, 0.814], [64684.3, 0.012], [64684.5, 0.003], [64684.9, 0.212], [64688.0, 2.92], [64688.4, 0.003], [64689.1, 0.008], [64695.0, 0.004], [64695.1, 0.086], [64696.2, 0.07], [64697.1, 0.002], [64699.8, 3.987]], "asks": [[64699.9, 23.866], [64700.2, 0.089], [64700.7, 0.0], [64701.3, 0.866], [64702.7, 0.158], [64704.6, 0.0], [64705.7, 0.094], [64706.8, 0.164], [64708.4, 0.38], [64710.4, 0.473], [64711.6, 0.084], [64712.1, 0.62], [64712.4, 0.926], [64713.6, 0.09], [64714.6, 10.249], [64717.4, 0.557], [64718.1, 0.012], [64718.3, 0.134], [64719.0, 10.008], [64719.2, 0.132], [64720.2, 0.001], [64720.3, 0.085], [64839.9, 6.863], [64856.9, 7.694], [64895.7, 8.352], [65346.9, 4.434], [65699.9, 0.931], [65702.7, 18.087]]}
{"kind": "depth", "E": 1787080327703, "U": 11315346361873, "u": 11315346372029, "recv_ms": 1787080327657, "bids": [[1000.0, 36.21], [14199.8, 2.954], [14599.8, 1.246], [58229.8, 0.053], [61464.8, 2.447], [62111.8, 1.895], [63090.5, 0.0], [64052.8, 2.152], [64376.3, 6.795], [64400.0, 23.182], [64651.1, 0.391], [64655.4, 0.037], [64658.1, 0.04], [64659.5, 0.004], [64668.2, 2.28], [64675.4, 0.16], [64683.7, 0.011], [64684.3, 0.005], [64686.7, 1.086], [64686.9, 0.31], [64687.0, 0.936], [64687.7, 0.358], [64687.8, 0.006], [64688.0, 2.02], [64689.1, 0.0], [64689.9, 0.272], [64691.0, 0.071], [64691.2, 1.871], [64691.4, 0.119], [64691.5, 0.355], [64693.2, 0.034], [64696.0, 0.01], [64699.8, 3.891]], "asks": [[64699.9, 25.274], [64700.2, 0.086], [64700.5, 0.0], [64702.2, 0.06], [64702.7, 0.003], [64706.8, 0.009], [64708.4, 0.225], [64710.4, 0.163], [64712.0, 0.011], [64712.1, 0.465], [64713.7, 0.002], [64717.6, 1.82], [64719.0, 0.008], [64719.3, 1.047], [64772.2, 1.099], [64772.3, 40.942], [64774.4, 1.129], [64774.5, 0.062], [64777.1, 0.003], [64839.9, 6.863], [64856.9, 10.408], [64895.7, 7.452], [65346.9, 4.434], [65993.8, 9.333], [66065.0, 0.159]]}
{"kind": "depth", "E": 1787080328111, "U": 11315346399808, "u": 11315346409806, "recv_ms": 1787080328064, "bids": [[14199.8, 1.526], [14599.8, 2.674], [51759.8, 0.0], [51760.0, 0.004], [58229.8, 0.053], [61464.8, 2.447], [62111.8, 1.898], [63405.9, 9.281], [63794.0, 34.865], [64052.8, 2.152], [64559.8, 4.724], [64600.2, 0.0], [64600.3, 0.215], [64674.4, 1.861], [64681.8, 0.02], [64685.6, 0.13], [64688.2, 0.001], [64689.0, 0.117], [64689.2, 0.318], [64691.2, 1.87], [64691.4, 0.116], [64691.5, 0.356], [64691.6, 0.17], [64691.7, 1.869], [64691.8, 0.07], [64691.9, 0.103], [64692.0, 0.622], [64692.3, 0.118], [64694.5, 0.044], [64695.5, 0.155], [64698.0, 0.17], [64698.6, 0.0], [64699.8, 3.336]], "asks": [[64699.9, 25.292], [64701.1, 0.089], [64702.0, 0.095], [64702.7, 0.003], [64704.0, 1.085], [64706.8, 0.101], [64707.8, 0.274], [64709.9, 0.012], [64712.0, 0.011], [64712.3, 1.417], [64713.7, 0.002], [64714.5, 0.871], [64719.7, 0.117], [64726.2, 1.397], [64830.8, 0.0], [64839.9, 6.863], [64895.7, 3.581], [65346.9, 4.434], [65499.8, 6.44], [65638.0, 30.967], [65993.8, 9.33]]}
{"kind": "depth", "E": 1787080328213, "U": 11315346409934, "u": 11315346424931, "recv_ms": 1787080328165, "bids": [[1000.0, 36.21], [14199.8, 1.162], [14599.8, 3.038], [51760.0, 0.004], [58229.8, 0.053], [61464.8, 2.447], [62111.8, 1.895], [63699.8, 0.031], [64052.8, 2.152], [64156.3, 0.956], [64376.3, 6.805], [64598.9, 0.023], [64604.8, 0.821], [64619.0, 0.169], [64624.0, 0.254], [64627.5, 0.028], [64639.4, 0.212], [64644.1, 0.03], [64647.6, 0.665], [64654.9, 2.319], [64662.7, 0.209], [64662.8, 0.011], [64668.3, 0.092], [64670.7, 0.196], [64672.1, 0.037], [64676.8, 3.16], [64678.2, 0.022], [64678.4, 0.452], [64681.5, 0.01], [64683.0, 1.001], [64683.1, 0.002], [64683.4, 0.245], [64684.8, 0.169], [64685.6, 0.13], [64686.1, 0.014], [64687.8, 1.243], [64688.0, 0.783], [64688.1, 2.357], [64688.7, 1.035], [64689.0, 0.078], [64689.1, 0.008], [64691.1, 0.085], [64691.2, 0.975], [64691.5, 0.356], [64691.6, 0.254], [64691.7, 1.869], [64691.8, 0.07], [64691.9, 0.187], [64692.0, 0.081], [64694.5, 0.002], [64694.7, 0.049], [64694.9, 0.093], [64695.1, 0.002], [64696.0, 0.01], [64698.4, 0.0], [64699.8, 3.336]], "asks": [[64700.4, 0.02], [64701.2, 0.0], [64702.0, 0.085], [64702.7, 0.284], [64704.5, 1.083], [64705.7, 1.239], [64706.0, 0.005], [64706.8, 0.156], [64706.9, 0.561], [64710.5, 12.146], [64712.0, 0.476], [64713.1, 0.125], [64713.7, 0.157], [64719.0, 0.013], [64727.5, 0.002], [64744.9, 0.234], [64754.6, 0.375], [64761.0, 0.002], [64769.5, 0.026], [64785.8, 0.028], [64839.9, 6.863], [64856.9, 10.408], [64895.7, 5.65], [65346.9, 4.434], [65508.6, 13.834], [65597.0, 17.535], [65605.7, 38.488], [65699.9, 0.951]]}
{"kind": "depth", "E": 1787080328315, "U": 11315346425061, "u": 11315346436561, "recv_ms": 1787080328267, "bids": [[1000.0, 36.21], [14199.8, 0.812], [14599.8, 3.388], [51760.0, 0.004], [58229.8, 0.053], [62000.0, 122.285], [62111.8, 1.898], [63518.1, 1.031], [63891.1, 19.312], [64052.8, 2.152], [64156.3, 0.96], [64622.8, 0.372], [64623.0, 6.461], [64625.0, 34.053], [64625.1, 0.0], [64654.5, 0.036], [64688.7, 1.011], [64689.0, 0.118], [64689.1, 0.001], [64690.9, 0.0], [64691.1, 0.085], [64691.2, 1.293], [64691.5, 0.356], [64691.8, 0.258], [64692.3, 0.118], [64693.0, 0.108], [64693.1, 0.02], [64693.2, 0.344], [64694.9, 0.093], [64696.0, 0.002], [64699.8, 3.861]], "asks": [[64699.9, 25.285], [64700.5, 0.022], [64702.0, 0.085], [64702.6, 0.13], [64702.7, 0.003], [64704.0, 0.185], [64705.0, 0.017], [64705.5, 0.0], [64705.6, 0.648], [64706.0, 0.004], [64706.8, 0.001], [64706.9, 0.506], [64707.3, 0.04], [64708.0, 1.044], [64710.3, 0.013], [64710.4, 3.797], [64710.5, 10.024], [64712.0, 0.003], [64712.1, 0.002], [64712.9, 3.055], [64713.0, 0.0], [64713.7, 0.002], [64714.6, 0.249], [64717.4, 0.016], [64718.3, 0.675], [64726.2, 1.397], [64745.2, 0.037], [64772.3, 40.927], [64774.5, 0.062], [65346.9, 4.434], [65508.6, 14.176], [65573.3, 9.174], [65638.0, 32.032]]}
{"kind": "depth", "E": 1787080328417, "U": 11315346436784, "u": 11315346453332, "recv_ms": 1787080328369, "bids": [[14199.8, 0.476], [14499.8, 0.014], [14599.8, 3.71], [58229.8, 0.053], [61464.8, 2.447], [63405.9, 9.284], [63699.8, 0.011], [63977.3, 0.781], [64052.8, 2.152], [64156.3, 0.923], [64376.3, 6.804], [64604.5, 3.787], [64604.7, 0.06], [64604.8, 0.816], [64617.6, 0.01], [64623.0, 1.798], [64624.0, 0.225], [64630.5, 0.0], [64651.1, 0.416], [64662.9, 0.003], [64664.3, 0.092], [64665.2, 0.074], [64665.3, 0.022], [64665.8, 2.161], [64674.5, 0.127], [64675.0, 0.088], [64676.5, 0.558], [64678.2, 0.138], [64680.2, 0.01], [64680.3, 0.005], [64681.3, 2.165], [64681.8, 0.02], [64682.3, 0.025], [64685.6, 0.006], [64688.0, 1.142], [64689.0, 0.619], [64689.1, 0.033], [64691.1, 0.086], [64691.2, 1.377], [64691.5, 0.355], [64691.7, 1.969], [64691.8, 0.17], [64691.9, 0.187], [64692.0, 0.081], [64692.3, 0.218], [64692.4, 0.1], [64693.0, 0.086], [64693.1, 0.001], [64693.2, 0.034], [64693.5, 0.096], [64693.6, 0.033], [64694.2, 0.001], [64694.5, 0.19], [64694.9, 0.009], [64695.5, 0.155], [64695.6, 1.561], [64696.0, 0.01], [64699.7, 0.314], [64699.8, 3.335]], "asks": [[64701.4, 0.007], [64701.5, 0.867], [64702.7, 0.003], [64705.0, 0.917], [64705.5, 0.0], [64705.6, 0.022], [64706.8, 0.643], [64706.9, 0.49], [64707.3, 0.04], [64710.3, 0.323], [64712.1, 0.157], [64712.9, 2.13], [64714.3, 0.925], [64715.6, 0.37], [64715.9, 0.021], [64716.0, 1.029], [64716.8, 0.68], [64716.9, 0.003], [64717.6, 1.877], [64718.1, 0.005], [64718.3, 0.134], [64718.8, 0.067], [64719.0, 0.008], [64719.2, 0.565], [64719.3, 0.976], [64719.5, 1.255], [64719.7, 0.002], [64721.0, 0.132], [64722.2, 0.062], [64726.1, 0.318], [64726.2, 1.243], [64726.3, 0.315], [64829.3, 2.322], [64835.2, 3.28], [64854.8, 0.719], [64856.9, 10.408], [64895.7, 3.543], [65346.9, 4.434], [65605.7, 40.77], [65699.9, 0.931]]}
{"kind": "depth", "E": 1787080328621, "U": 11315346467021, "u": 11315346476224, "recv_ms": 1787080328572, "bids": [[1000.0, 36.21], [14199.8, 0.168], [14499.8, 0.42], [14599.8, 3.612], [58229.8, 0.053], [61464.8, 2.447], [61464.9, 0.006], [62111.8, 1.898], [63699.8, 0.031], [63923.4, 40.323], [64052.8, 2.151], [64573.1, 1.237], [64651.1, 0.391], [64658.3, 0.025], [64677.2, 0.118], [64678.2, 0.022], [64691.5, 0.201], [64692.4, 0.0], [64693.5, 0.046], [64694.5, 0.002]], "asks": [[64699.9, 25.285], [64701.8, 0.002], [64702.6, 0.13], [64705.6, 0.006], [64706.8, 0.009], [64707.3, 0.04], [64710.3, 0.323], [64712.1, 0.157], [64713.1, 1.05], [64714.3, 0.0], [64719.7, 0.082], [64726.1, 0.318], [65346.9, 4.434], [65476.3, 34.8], [65638.0, 30.967], [65699.9, 0.951]]}
{"kind": "depth", "E": 1787080328825, "U": 11315346487366, "u": 11315346499707, "recv_ms": 1787080328777, "bids": [[1000.0, 35.81], [14199.8, 0.0], [14499.8, 0.98], [14599.8, 3.22], [58229.8, 0.053], [61464.8, 2.447], [63699.8, 0.011], [64052.8, 2.151], [64156.3, 0.919], [64328.9, 0.0], [64376.3, 6.95], [64425.5, 0.556], [64496.5, 0.08], [64663.8, 0.059], [64664.6, 0.002], [64674.6, 0.559], [64675.5, 0.002], [64676.2, 0.199], [64677.2, 0.002], [64679.7, 0.926], [64680.8, 0.469], [64687.1, 0.005], [64688.2, 0.001], [64688.7, 1.552], [64689.0, 0.086], [64689.1, 0.033], [64691.7, 1.869], [64691.8, 0.145], [64692.3, 0.234], [64693.5, 0.234], [64694.8, 0.084], [64696.0, 0.002], [64699.8, 3.335]], "asks": [[64702.6, 0.13], [64707.3, 0.04], [64710.3, 0.403], [64712.1, 0.157], [64714.8, 0.377], [64715.7, 0.687], [64716.6, 0.082], [64716.8, 0.124], [64717.4, 0.016], [64717.6, 1.82], [64718.3, 0.675], [64719.0, 0.008], [64719.9, 0.115], [64721.0, 0.017], [64895.2, 0.001], [64966.6, 0.03], [65064.0, 0.024], [65346.9, 4.434], [65638.0, 32.032], [65699.9, 0.931], [65713.4, 0.727]]}
{"kind": "depth", "E": 1787080328927, "U": 11315346500024, "u": 11315346509236, "recv_ms": 1787080328878, "bids": [[1000.0, 35.81], [14499.8, 1.33], [14599.8, 2.87], [58229.8, 0.053], [62111.8, 1.898], [62111.9, 0.602], [63891.1, 19.546], [64052.8, 2.151], [64329.1, 0.856], [64425.6, 0.368], [64473.2, 6.294], [64496.6, 0.0], [64499.0, 1.036], [64683.8, 0.022], [64688.2, 0.542], [64688.7, 1.011], [64689.0, 0.078], [64691.8, 0.07], [64692.4, 0.1], [64693.5, 0.234], [64696.0, 0.01], [64699.8, 3.334]], "asks": [[64701.0, 0.05], [64702.6, 0.13], [64707.3, 0.04], [64708.5, 0.586], [64709.7, 0.293], [64710.3, 0.403], [64712.1, 0.157], [64716.3, 0.163], [64966.5, 0.568], [65062.8, 0.94], [65346.9, 4.434], [65512.8, 0.0], [65638.0, 33.097]]}
{"kind": "depth", "E": 1787080329029, "U": 11315346509523, "u": 11315346517707, "recv_ms": 1787080328982, "bids": [[14499.8, 1.68], [14599.8, 2.52], [58229.8, 0.053], [61464.8, 2.447], [62111.8, 1.895], [63699.8, 0.031], [63882.5, 5.875], [63929.9, 8.433], [64020.5, 0.86], [64052.8, 2.151], [64065.0, 2.36], [64213.1, 0.0], [64683.8, 0.024], [64691.2, 1.293], [64692.3, 0.159], [64692.4, 0.0], [64693.5, 0.046], [64695.3, 0.086]], "asks": [[64699.9, 25.306], [64702.6, 0.13], [64707.3, 0.04], [64710.3, 0.403], [64712.1, 0.157], [64716.3, 0.165], [64895.7, 4.379], [65181.2, 0.074], [65329.9, 0.002], [65346.9, 4.434], [65638.0, 32.032], [65699.9, 0.951]]}
{"kind": "depth", "E": 1787080329131, "U": 11315346517959, "u": 11315346537170, "recv_ms": 1787080329088, "bids": [[1000.0, 35.81], [14499.8, 2.044], [14599.8, 2.156], [51759.8, 0.0], [51760.0, 0.004], [58229.8, 0.053], [61464.8, 2.447], [62111.8, 1.898], [63405.9, 9.284], [63752.1, 5.59], [64052.8, 2.151], [64156.3, 0.915], [64327.9, 43.395], [64329.1, 7.281], [64376.3, 6.96], [64424.5, 34.631], [64425.6, 5.49], [64495.5, 27.512], [64495.7, 5.658], [64520.5, 0.001], [64525.6, 2.834], [64573.0, 2.758], [64578.6, 3.864], [64580.8, 1.317], [64588.6, 2.264], [64591.6, 0.001], [64592.3, 2.318], [64628.6, 1.813], [64635.1, 0.378], [64641.5, 0.009], [64648.2, 0.001], [64648.3, 0.006], [64651.2, 1.193], [64666.9, 0.325], [64667.0, 0.004], [64667.1, 0.309], [64670.3, 0.347], [64670.4, 1.242], [64670.5, 0.696], [64683.6, 0.029], [64684.1, 0.814], [64688.2, 0.542], [64689.0, 0.078], [64691.1, 0.085], [64691.4, 0.117], [64691.5, 0.355], [64691.6, 0.17], [64692.3, 0.259], [64692.4, 0.1], [64692.8, 0.005], [64693.5, 0.046], [64693.7, 0.315], [64693.8, 0.003], [64694.5, 0.19], [64694.6, 0.006], [64695.7, 0.003], [64696.0, 0.01], [64696.1, 0.085], [64697.1, 0.002], [64699.8, 3.333]], "asks": [[64699.9, 25.226], [64701.4, 0.004], [64701.9, 0.006], [64702.6, 0.13], [64704.1, 0.089], [64704.5, 1.084], [64707.3, 0.04], [64710.3, 0.323], [64712.1, 0.157], [64713.6, 0.09], [64714.6, 0.867], [64722.0, 1.116], [64725.9, 0.0], [64726.1, 0.472], [64771.0, 0.049], [64777.6, 0.004], [64807.3, 2.318], [64835.2, 2.319], [64835.3, 3.864], [64890.5, 4.865], [64892.3, 27.421], [64963.7, 33.848], [65346.9, 4.434], [65638.0, 33.097], [65767.4, 5.315]]}
{"kind": "depth", "E": 1787080329335, "U": 11315346547707, "u": 11315346557648, "recv_ms": 1787080329286, "bids": [[14499.8, 2.758], [14599.8, 1.442], [58229.8, 0.053], [63276.4, 0.01], [63697.0, 16.153], [63761.7, 29.211], [64052.8, 2.151], [64212.0, 52.513], [64659.1, 0.332], [64674.4, 1.243], [64688.4, 0.002], [64689.0, 0.078], [64691.1, 0.086], [64691.4, 0.116], [64691.5, 0.355], [64691.6, 0.17], [64691.8, 0.07], [64692.3, 0.159], [64692.4, 0.0], [64692.8, 0.002], [64693.6, 0.041], [64693.7, 0.005], [64694.5, 0.002], [64694.9, 0.0], [64696.0, 0.01], [64699.8, 3.309]], "asks": [[64699.9, 29.137], [64700.1, 0.022], [64701.5, 0.867], [64702.6, 0.13], [64702.7, 0.003], [64702.8, 2.419], [64705.5, 0.309], [64705.6, 0.014], [64706.7, 0.035], [64706.8, 0.634], [64706.9, 0.507], [64707.3, 0.04], [64710.2, 0.026], [64710.3, 0.013], [64710.4, 3.799], [64712.1, 0.002], [64714.6, 0.249], [64722.0, 0.498], [64730.8, 0.158], [64777.1, 0.003], [65061.2, 41.739], [65330.2, 13.208], [65346.9, 4.434], [65578.2, 0.761], [65993.8, 9.33]]}
{"kind": "depth", "E": 1787080329437, "U": 11315346557959, "u": 11315346568189, "recv_ms": 1787080329391, "bids": [[1000.0, 35.81], [14499.8, 3.108], [14599.8, 1.092], [51760.0, 0.004], [58229.8, 0.053], [61464.8, 2.447], [62111.8, 1.898], [63094.4, 1.583], [63699.8, 0.031], [63761.7, 28.114], [64052.8, 2.151], [64376.3, 6.96], [64559.8, 4.657], [64622.8, 0.372], [64625.0, 33.963], [64625.1, 0.0], [64689.0, 0.078], [64691.3, 0.295], [64691.5, 0.201], [64691.8, 0.145], [64692.3, 0.347], [64693.5, 0.234], [64696.0, 0.01], [64699.8, 3.309]], "asks": [[64699.9, 29.14], [64700.8, 0.009], [64702.0, 0.085], [64702.7, 0.003], [64704.5, 1.083], [64706.8, 0.626], [64706.9, 0.036], [64707.3, 0.04], [64710.2, 0.026], [64710.3, 0.492], [64712.1, 0.002], [64772.2, 6.942], [64829.3, 2.322], [64835.2, 3.28], [64839.9, 6.863], [64847.8, 0.972], [64854.8, 2.18], [65059.8, 7.034], [65346.9, 4.434], [65512.0, 0.077], [65512.1, 0.0], [65699.9, 0.951], [65767.4, 6.378]]}
{"kind": "depth", "E": 1787080329641, "U": 11315346576196, "u": 11315346588803, "recv_ms": 1787080329594, "bids": [[14399.8, 0.042], [14499.8, 3.738], [14599.8, 0.42], [51760.0, 0.004], [58229.8, 0.053], [61464.8, 2.447], [62111.8, 1.898], [63699.8, 0.011], [63761.7, 28.115], [63891.1, 19.811], [64052.8, 2.151], [64542.9, 8.974], [64559.8, 4.657], [64604.1, 0.011], [64604.5, 3.782], [64625.9, 0.027], [64627.5, 0.002], [64633.9, 2.446], [64641.5, 0.006], [64654.5, 0.036], [64683.6, 0.021], [64688.7, 0.463], [64689.0, 0.078], [64689.1, 0.001], [64690.0, 1.654], [64690.4, 0.001], [64691.1, 0.086], [64692.3, 0.159], [64692.4, 0.0], [64692.8, 1.844], [64692.9, 0.582], [64693.5, 0.234], [64694.3, 0.087], [64695.3, 0.002], [64695.7, 0.003], [64695.8, 0.003], [64695.9, 0.001], [64696.0, 0.002], [64699.8, 3.308]], "asks": [[64702.7, 0.003], [64707.3, 0.04], [64710.2, 0.026], [64710.3, 0.492], [64712.1, 0.002], [64718.3, 0.68], [64718.8, 0.062], [64737.6, 1.464], [64744.9, 0.024], [64745.2, 0.037], [64765.2, 0.002], [64765.3, 2.646], [64767.9, 0.035], [64769.5, 0.0], [64839.9, 6.863], [64856.9, 10.408], [65314.5, 9.824], [65330.2, 12.521], [65346.9, 4.434], [65699.9, 0.931], [65702.7, 17.023]]}
{"kind": "depth", "E": 1787080329743, "U": 11315346589154, "u": 11315346604472, "recv_ms": 1787080329696, "bids": [[1000.0, 35.81], [14399.8, 0.252], [14499.8, 3.682], [14599.8, 0.266], [58229.8, 0.053], [62111.8, 1.895], [63761.7, 29.211], [63913.8, 3.099], [64052.8, 2.151], [64376.3, 6.96], [64663.8, 0.002], [64664.4, 0.058], [64665.3, 0.022], [64676.2, 0.083], [64676.8, 3.276], [64677.7, 0.091], [64679.7, 0.0], [64680.4, 0.946], [64681.3, 1.239], [64689.0, 0.102], [64691.1, 0.085], [64691.5, 0.202], [64691.8, 0.17], [64692.3, 0.159], [64692.9, 0.582], [64693.5, 0.046], [64694.5, 0.198], [64695.7, 0.011]], "asks": [[64713.1, 0.125], [64713.7, 0.927], [64716.6, 0.025], [64717.2, 0.058], [64717.7, 0.774], [64718.3, 0.139], [64719.2, 0.024], [64719.9, 0.0], [64720.5, 0.151], [64726.2, 1.397], [65346.9, 4.434], [65469.8, 8.235], [65508.6, 14.663], [65661.6, 6.461], [65702.7, 18.087]]}
{"kind": "depth", "E": 1787080329947, "U": 11315346613659, "u": 11315346626174, "recv_ms": 1787080329902, "bids": [[14399.8, 0.728], [14499.8, 3.444], [14599.8, 0.028], [58229.8, 0.053], [61464.8, 2.447], [62111.8, 1.898], [63752.1, 4.503], [63923.4, 41.886], [64052.8, 2.151], [64622.8, 0.372], [64625.0, 33.963], [64683.6, 0.029], [64683.8, 0.022], [64688.3, 0.105], [64688.6, 0.001], [64689.0, 0.001], [64691.6, 0.254], [64691.8, 0.668], [64692.9, 0.042], [64693.0, 0.094], [64693.5, 0.234], [64694.5, 0.002], [64694.8, 0.0], [64695.7, 0.003], [64699.8, 3.306]], "asks": [[64701.5, 0.87], [64701.9, 0.006], [64702.7, 0.003], [64706.9, 0.036], [64707.3, 0.04], [64709.7, 0.253], [64710.2, 0.026], [64710.3, 0.492], [64712.1, 0.002], [64712.2, 2.571], [64712.3, 1.435], [64713.7, 0.967], [64716.3, 0.163], [64717.7, 0.233], [64718.3, 0.68], [64854.8, 0.719], [64856.9, 10.408], [64893.9, 9.042], [64895.7, 3.544], [65023.4, 5.077], [65217.5, 10.283], [65346.9, 4.434], [65508.6, 14.892], [65670.4, 7.94], [65825.4, 1.212]]}
{"kind": "depth", "E": 1787080330049, "U": 11315346626460, "u": 11315346643501, "recv_ms": 1787080330010, "bids": [[1000.0, 35.81], [14399.8, 1.05], [14499.8, 3.15], [14599.8, 0.0], [58229.8, 0.053], [61464.8, 2.447], [62111.8, 1.895], [63405.9, 9.287], [63699.8, 0.011], [64052.8, 2.151], [64376.3, 6.95], [64661.9, 3.051], [64673.4, 0.154], [64674.1, 0.003], [64683.8, 0.024], [64688.2, 0.547], [64688.3, 0.105], [64691.5, 0.201], [64691.7, 1.869], [64691.8, 0.078], [64691.9, 0.187], [64692.9, 0.583], [64693.5, 0.234], [64694.7, 0.133], [64695.1, 0.086], [64695.7, 0.172], [64699.8, 3.831]], "asks": [[64702.7, 0.157], [64704.0, 0.931], [64705.9, 0.223], [64706.9, 0.036], [64707.2, 0.009], [64707.3, 0.04], [64709.2, 0.304], [64710.2, 0.026], [64710.3, 0.021], [64710.4, 1.898], [64710.5, 0.024], [64712.1, 0.473], [64713.1, 1.05], [64713.7, 0.042], [64714.4, 10.515], [64716.3, 0.165], [64716.5, 0.063], [64717.2, 0.001], [65346.9, 4.434], [65469.8, 9.15], [65699.9, 0.931], [65805.9, 0.61]]}
{"kind": "depth", "E": 1787080330151, "U": 11315346643685, "u": 11315346660893, "recv_ms": 1787080330145, "bids": [[1000.0, 35.81], [14399.8, 1.414], [14499.8, 2.786], [51759.8, 0.0], [58229.8, 0.053], [61464.8, 2.447], [62111.8, 1.912], [63697.0, 16.153], [63699.8, 0.031], [63752.1, 3.416], [63761.7, 28.114], [63785.4, 12.72], [63955.8, 9.913], [64052.8, 2.155], [64648.3, 0.006], [64651.3, 0.007], [64658.6, 0.738], [64661.2, 0.0], [64670.4, 1.256], [64675.0, 0.706], [64682.4, 0.001], [64685.6, 0.571], [64688.2, 0.542], [64688.3, 0.105], [64688.4, 0.003], [64691.6, 0.17], [64691.8, 0.07], [64691.9, 0.103], [64692.1, 0.0], [64692.3, 0.078], [64692.7, 0.086], [64692.9, 0.582], [64693.0, 0.282], [64693.3, 0.417], [64693.5, 0.046], [64694.3, 0.086], [64695.7, 0.256], [64696.1, 0.085], [64696.6, 0.087], [64696.7, 0.004], [64696.8, 1.691], [64696.9, 0.001], [64697.1, 0.01], [64699.2, 0.002], [64699.3, 0.087], [64699.8, 4.487]], "asks": [[64699.9, 27.419], [64700.1, 0.025], [64701.5, 0.867], [64702.7, 0.003], [64703.0, 0.014], [64703.4, 0.154], [64704.0, 0.031], [64705.0, 0.017], [64705.5, 0.0], [64705.6, 0.006], [64705.7, 0.002], [64705.9, 0.069], [64706.0, 0.313], [64706.3, 0.004], [64706.7, 0.197], [64706.8, 0.549], [64706.9, 0.028], [64709.2, 0.15], [64709.7, 0.407], [64710.2, 0.103], [64710.3, 0.013], [64711.0, 0.31], [64711.5, 0.012], [64712.0, 0.003], [64712.8, 1.339], [64713.1, 0.125], [64713.3, 0.925], [64713.7, 0.042], [64719.1, 10.052], [64720.2, 0.001], [65346.9, 4.436], [65638.0, 32.032], [65699.9, 0.951], [65702.7, 18.087], [65767.4, 6.378], [65812.7, 1.364], [65993.8, 9.327], [66641.3, 2.173]]}
{"kind": "depth", "E": 1787080330253, "U": 11315346660909, "u": 11315346674163, "recv_ms": 1787080330225, "bids": [[14399.8, 1.764], [14499.8, 2.436], [51760.0, 0.008], [58229.8, 0.053], [63761.7, 29.211], [64052.8, 2.151], [64622.8, 0.372], [64624.7, 0.0], [64625.0, 33.954], [64639.4, 0.002], [64646.6, 0.222], [64658.6, 0.402], [64662.6, 0.336], [64664.4, 0.001], [64664.9, 2.819], [64677.6, 0.052], [64680.4, 0.02], [64680.7, 1.094], [64680.9, 1.288], [64683.7, 0.004], [64684.5, 0.01], [64685.0, 0.015], [64688.3, 0.653], [64688.4, 0.011], [64692.9, 0.034], [64693.0, 0.086], [64693.1, 0.001], [64693.5, 0.046], [64693.6, 0.041], [64694.5, 0.002], [64695.8, 0.003], [64696.9, 0.001], [64697.1, 0.01], [64699.8, 4.483]], "asks": [[64699.9, 27.412], [64700.1, 0.002], [64700.4, 0.03], [64702.7, 0.003], [64703.4, 0.0], [64703.9, 0.29], [64705.6, 0.006], [64706.9, 0.113], [64707.0, 1.919], [64709.7, 0.253], [64710.2, 0.026], [64710.4, 2.052], [64712.0, 0.003], [64713.7, 0.042], [64714.8, 0.328], [64716.5, 0.006], [64716.8, 0.181], [64719.1, 0.052], [64721.3, 2.016], [64737.6, 1.254], [64745.0, 2.531], [65346.9, 4.434], [65520.5, 3.048], [65993.8, 9.324]]}
{"kind": "depth", "E": 1787080330355, "U": 11315346674279, "u": 11315346684775, "recv_ms": 1787080330306, "bids": [[1000.0, 35.81], [14399.8, 2.114], [14499.8, 2.086], [51760.0, 0.006], [58229.8, 0.053], [61464.8, 2.445], [61464.9, 0.008], [62111.8, 1.909], [64052.8, 2.151], [64156.3, 0.878], [64376.3, 6.96], [64645.4, 0.029], [64664.6, 0.059], [64664.9, 2.762], [64688.3, 0.646], [64688.4, 0.003], [64689.2, 0.315], [64691.2, 1.296], [64691.8, 0.07], [64692.9, 0.049], [64693.5, 0.046], [64699.7, 0.315]], "asks": [[64700.4, 0.027], [64701.0, 0.053], [64703.3, 0.0], [64704.2, 0.071], [64705.0, 0.917], [64706.7, 0.043], [64707.5, 0.154], [65346.9, 4.434], [65448.8, 0.778], [65533.0, 0.099]]}
{"kind": "depth", "E": 1787080330457, "U": 11315346685078, "u": 11315346693945, "recv_ms": 1787080330407, "bids": [[1000.0, 35.81], [14399.8, 2.478], [14499.8, 1.722], [51760.0, 0.004], [58229.8, 0.053], [61464.8, 2.445], [62111.8, 1.912], [63697.0, 16.153], [63699.8, 0.011], [63761.7, 31.405], [63771.3, 0.001], [64052.8, 2.151], [64156.3, 0.816], [64602.8, 0.121], [64611.5, 0.001], [64625.1, 6.08], [64688.3, 0.553], [64688.4, 0.096], [64691.8, 0.07], [64692.3, 0.078], [64692.9, 0.041], [64693.0, 0.094], [64693.4, 0.214], [64694.5, 0.002], [64695.8, 0.003]], "asks": [[64699.9, 27.411], [64702.7, 0.003], [64706.0, 0.004], [64706.9, 0.113], [64707.1, 0.772], [64711.5, 0.004], [64712.0, 0.011], [64713.7, 0.042], [64726.2, 1.397], [64765.2, 1.221], [64819.8, 2.419], [64829.3, 2.322], [64854.8, 2.18], [64910.6, 0.0], [64963.6, 5.401], [64965.2, 0.0], [65346.9, 4.434], [65638.0, 33.097], [65699.9, 0.931]]}
{"kind": "depth", "E": 1787080330559, "U": 11315346694189, "u": 11315346701090, "recv_ms": 1787080330517, "bids": [[14399.8, 2.842], [14499.8, 1.358], [58229.8, 0.053], [61464.8, 2.447], [62111.8, 1.909], [64052.8, 2.151], [64376.3, 6.959], [64578.4, 3.868], [64578.6, 0.0], [64628.6, 1.813], [64639.9, 2.225], [64680.5, 2.923], [64680.7, 0.168], [64688.4, 0.096], [64691.8, 0.07], [64692.5, 0.011], [64692.9, 0.049], [64693.0, 0.086], [64693.5, 0.234], [64694.5, 0.002], [64695.8, 0.003], [64699.8, 4.483]], "asks": [[64699.9, 27.429], [64702.7, 0.158], [64706.9, 0.268], [64712.0, 0.476], [64713.7, 0.197], [64716.3, 0.222], [64716.8, 0.124], [64717.7, 0.774], [64718.3, 0.139], [64726.2, 1.243], [64726.3, 0.315], [64771.0, 0.049], [64785.6, 1.255], [64835.3, 3.864], [64895.7, 3.711], [65023.4, 5.078], [65097.9, 0.007], [65346.9, 4.434], [65508.6, 15.654]]}
{"kind": "depth", "E": 1787080330661, "U": 11315346701185, "u": 11315346709493, "recv_ms": 1787080330612, "bids": [[1000.0, 35.81], [14399.8, 3.192], [14499.8, 1.008], [51760.0, 0.004], [58229.8, 0.053], [61464.8, 2.445], [61464.9, 0.01], [62111.8, 1.912], [63699.8, 0.031], [63761.7, 30.308], [64052.8, 2.151], [64376.3, 6.959], [64659.3, 0.839], [64662.6, 0.0], [64664.3, 0.149], [64664.6, 0.002], [64675.0, 0.088], [64680.2, 1.06], [64680.5, 1.997], [64686.9, 0.001], [64688.3, 0.321], [64688.4, 0.096], [64691.6, 0.171], [64691.8, 0.07], [64691.9, 0.187], [64692.3, 0.159], [64692.7, 0.085], [64692.9, 0.582], [64693.0, 0.086], [64693.1, 0.009], [64693.3, 0.107], [64693.5, 0.046], [64694.5, 0.002], [64695.1, 0.002], [64695.5, 0.156], [64695.7, 0.172], [64695.8, 0.003], [64696.1, 0.001], [64696.6, 0.003], [64696.7, 0.003], [64699.8, 3.3]], "asks": [[64699.9, 27.397], [64701.2, 0.003], [64702.7, 0.158], [64704.0, 0.931], [64706.9, 0.268], [64712.0, 0.476], [64712.7, 1.089], [64713.3, 0.0], [64713.7, 0.197], [64714.4, 0.515], [64714.5, 10.871], [64719.3, 1.047], [65111.2, 0.6], [65330.2, 11.834], [65346.9, 4.434], [65486.9, 3.177], [65699.9, 0.951], [71169.9, 0.002]]}
{"kind": "depth", "E": 1787080330763, "U": 11315346709524, "u": 11315346718186, "recv_ms": 1787080330714, "bids": [[14399.8, 3.542], [14499.8, 0.658], [58229.8, 0.053], [61464.8, 2.445], [63697.0, 17.251], [63891.1, 20.162], [64052.8, 2.151], [64688.4, 0.003], [64691.8, 0.163], [64692.3, 0.137], [64693.0, 0.086], [64693.1, 0.001], [64693.2, 0.344], [64693.5, 0.234], [64694.5, 0.01], [64696.9, 0.009], [64697.1, 0.002], [64699.8, 2.523]], "asks": [[64700.4, 0.03], [64701.0, 0.05], [64701.4, 0.009], [64701.9, 0.0], [64702.7, 0.003], [64706.9, 0.113], [64712.0, 0.011], [64712.7, 0.164], [64713.0, 0.925], [64713.7, 0.042], [64713.8, 2.711], [64714.5, 10.873], [65233.8, 0.007], [65346.9, 4.434], [65585.9, 3.65], [71169.9, 0.0]]}
{"kind": "depth", "E": 1787080330865, "U": 11315346718689, "u": 11315346729135, "recv_ms": 1787080330816, "bids": [[14299.8, 0.07], [14399.8, 3.766], [14499.8, 0.364], [58229.8, 0.053], [61464.8, 2.443], [61464.9, 0.012], [62111.8, 1.909], [63632.3, 3.297], [63699.8, 0.011], [63761.7, 31.405], [63817.8, 8.447], [64052.8, 2.151], [64559.8, 0.0], [64641.5, 0.006], [64654.5, 0.036], [64693.5, 0.046], [64699.8, 2.529]], "asks": [[64702.7, 0.003], [64706.9, 0.113], [64712.0, 0.011], [64713.7, 0.042], [64745.2, 0.037], [64809.9, 0.001], [64839.9, 1.465], [64893.9, 9.043], [65023.4, 5.077], [65314.5, 10.511], [65346.9, 4.436], [65573.3, 9.782], [65699.9, 0.931]]}
{"kind": "depth", "E": 1787080331069, "U": 11315346741866, "u": 11315346753915, "recv_ms": 1787080331028, "bids": [[14299.8, 0.532], [14399.8, 3.556], [14499.8, 0.112], [58229.8, 0.053], [61464.8, 2.443], [62111.8, 1.909], [63632.3, 4.396], [63699.8, 0.031], [64052.8, 2.151], [64578.3, 5.229], [64578.4, 0.004], [64592.3, 0.0], [64593.2, 2.333], [64628.6, 1.813], [64654.8, 1.944], [64683.8, 0.031], [64684.5, 0.003], [64688.2, 0.542], [64692.9, 0.632], [64693.0, 0.094], [64693.5, 0.046], [64694.5, 0.002], [64694.8, 0.084], [64695.5, 0.24], [64695.8, 0.011], [64697.1, 0.19]], "asks": [[64699.9, 28.619], [64700.4, 0.02], [64701.8, 0.012], [64702.5, 0.015], [64702.7, 0.003], [64706.2, 0.156], [64706.9, 0.121], [64707.5, 0.0], [64712.0, 0.003], [64713.7, 0.042], [64716.3, 0.224], [64716.9, 0.001], [64717.7, 0.233], [64718.3, 0.68], [64771.0, 0.049], [64807.3, 2.318], [64835.2, 2.703], [64835.3, 3.864], [65314.5, 11.167], [65346.9, 4.434], [65476.5, 4.195], [65486.5, 2.289], [65699.9, 0.951], [65702.7, 17.023]]}
{"kind": "depth", "E": 1787080331171, "U": 11315346754311, "u": 11315346764022, "recv_ms": 1787080331123, "bids": [[14299.8, 0.784], [14399.8, 3.416], [14499.8, 0.0], [51759.8, 0.0], [51760.0, 0.006], [58229.8, 0.053], [61464.8, 2.443], [63405.9, 9.29], [64052.8, 2.151], [64641.5, 0.009], [64648.2, 0.002], [64648.3, 0.005], [64651.3, 0.006], [64674.9, 0.631], [64682.3, 0.643], [64688.3, 0.106], [64692.9, 0.582], [64694.5, 0.19], [64697.1, 0.002], [64699.8, 2.529]], "asks": [[64699.9, 28.643], [64701.8, 0.002], [64702.5, 0.005], [64702.7, 0.003], [64704.9, 0.007], [64706.9, 0.121], [64712.0, 0.003], [64712.8, 1.957], [64713.7, 0.042], [64720.1, 2.946], [64809.9, 0.004], [65346.9, 4.434], [65551.6, 2.286]]}
{"kind": "depth", "E": 1787080331375, "U": 11315346773647, "u": 11315346781716, "recv_ms": 1787080331328, "bids": [[14299.8, 1.498], [14399.8, 2.702], [58229.8, 0.053], [61464.8, 2.443], [62111.8, 1.909], [63405.9, 9.293], [63699.8, 0.031], [63882.5, 5.641], [64052.8, 2.151], [64625.0, 1.59], [64625.1, 0.0], [64627.2, 32.397], [64663.9, 0.058], [64664.3, 0.092], [64679.9, 0.932], [64680.7, 0.168], [64687.2, 0.002], [64687.9, 2.29], [64688.0, 1.074], [64688.2, 0.001], [64688.3, 0.106], [64689.8, 0.093], [64690.0, 0.011], [64690.4, 0.069], [64691.6, 0.17], [64692.6, 0.034], [64692.7, 2.005], [64692.8, 1.869], [64692.9, 0.607], [64693.0, 0.094], [64694.5, 0.19], [64695.8, 0.003], [64695.9, 0.085], [64696.9, 0.009], [64699.8, 3.062]], "asks": [[64701.2, 0.0], [64701.4, 0.004], [64701.9, 0.005], [64702.7, 0.003], [64706.9, 0.113], [64708.8, 0.246], [64710.1, 0.116], [64712.0, 0.003], [64712.3, 2.36], [64713.0, 0.0], [64713.7, 0.042], [64715.8, 0.064], [64716.6, 0.025], [64717.4, 0.557], [64718.3, 0.139], [64829.3, 2.322], [65346.9, 4.434], [65699.9, 0.951]]}
{"kind": "depth", "E": 1787080331681, "U": 11315346801501, "u": 11315346810242, "recv_ms": 1787080331633, "bids": [[14299.8, 2.576], [14399.8, 1.624], [51760.0, 0.004], [58229.8, 0.053], [61464.8, 2.443], [63632.3, 3.297], [63699.8, 0.011], [63923.4, 41.887], [64052.8, 2.151], [64376.3, 6.951], [64403.4, 0.001], [64438.5, 2.387], [64452.1, 0.001], [64487.1, 0.001], [64559.8, 4.727], [64594.2, 10.001], [64595.2, 2.981], [64629.5, 0.032], [64636.0, 0.064], [64642.5, 0.034], [64649.0, 0.263], [64655.5, 0.063], [64662.0, 0.032], [64668.5, 0.034], [64674.6, 0.002], [64675.3, 0.561], [64676.2, 0.083], [64676.8, 3.16], [64676.9, 0.427], [64677.7, 0.091], [64680.4, 0.018], [64687.9, 1.749], [64688.2, 1.082], [64688.3, 0.029], [64688.7, 0.0], [64689.0, 0.001], [64693.0, 0.102], [64694.5, 0.022], [64695.5, 0.156], [64695.8, 0.003], [64695.9, 0.277], [64696.0, 0.002], [64696.1, 0.001], [64696.9, 0.001], [64697.1, 0.002], [64699.8, 2.763]], "asks": [[64699.9, 27.83], [64700.2, 0.089], [64702.7, 0.011], [64704.1, 0.09], [64706.2, 0.465], [64706.6, 0.001], [64706.7, 0.112], [64706.9, 0.036], [64707.1, 0.462], [64707.9, 0.014], [64712.0, 0.003], [64713.0, 0.925], [64713.3, 0.0], [64713.7, 0.042], [64713.9, 0.042], [64714.0, 0.02], [64715.5, 0.619], [64715.7, 0.131], [64716.4, 6.118], [64716.7, 0.005], [64717.3, 0.06], [64717.7, 0.774], [64718.2, 0.014], [64718.3, 0.139], [64718.7, 0.01], [64719.2, 0.017], [64720.5, 0.149], [64727.0, 3.755], [64733.5, 0.028], [64740.0, 0.836], [64746.5, 0.062], [64753.0, 0.032], [64790.7, 3.406], [64792.9, 10.171], [64839.9, 6.863], [64895.7, 3.613], [64967.6, 0.001], [65003.0, 0.103], [65023.4, 5.076], [65108.0, 0.002], [65143.5, 0.0], [65346.9, 4.434], [65635.7, 0.016], [65699.9, 0.931], [65702.7, 18.087]]}
{"kind": "depth", "E": 1787080331783, "U": 11315346810300, "u": 11315346818872, "recv_ms": 1787080331735, "bids": [[14299.8, 2.926], [14399.8, 1.274], [51760.0, 0.004], [58229.8, 0.053], [62111.8, 1.912], [63794.0, 35.241], [64052.8, 2.151], [64680.4, 0.944], [64680.8, 0.469], [64693.0, 0.094], [64695.7, 0.36], [64695.8, 0.003], [64696.0, 0.01]], "asks": [[64713.0, 0.0], [64713.7, 0.967], [64715.5, 0.063], [64716.3, 0.78], [64717.3, 0.003], [64717.7, 0.774], [64718.3, 0.139], [64719.2, 0.017], [64719.3, 0.976], [65346.9, 4.434], [65605.7, 43.237], [65644.5, 2.445], [65793.3, 1.972], [65812.4, 1.826]]}
{"kind": "depth", "E": 1787080331885, "U": 11315346819109, "u": 11315346829190, "recv_ms": 1787080331838, "bids": [[1000.0, 35.81], [14299.8, 3.276], [14399.8, 0.924], [58229.8, 0.053], [61464.8, 2.445], [62111.8, 1.909], [63632.3, 4.396], [63699.8, 0.031], [64052.8, 2.151], [64376.3, 6.951], [64655.2, 0.336], [64659.1, 0.332], [64692.2, 0.25], [64692.6, 0.034], [64695.2, 0.086], [64695.7, 0.172], [64695.8, 0.003], [64696.0, 0.01], [64696.9, 0.189], [64699.8, 2.238]], "asks": [[64701.4, 0.004], [64701.9, 0.0], [64702.7, 0.011], [64706.9, 0.036], [64710.3, 0.492], [64710.4, 3.587], [64710.6, 10.003], [64711.4, 0.023], [64712.0, 0.003], [64712.1, 0.002], [64712.7, 1.089], [64713.6, 0.09], [64713.7, 0.042], [64714.5, 0.873], [65346.9, 4.434], [65420.8, 2.06], [65699.9, 0.951], [65993.8, 9.327]]}
{"kind": "depth", "E": 1787080331987, "U": 11315346829448, "u": 11315346841776, "recv_ms": 1787080331937, "bids": [[14299.8, 3.64], [14399.8, 0.56], [58229.8, 0.053], [61464.8, 2.445], [62111.8, 1.912], [63934.4, 0.781], [64052.8, 2.151], [64182.2, 10.764], [64374.0, 0.165], [64376.3, 6.95], [64559.8, 0.0], [64559.9, 4.737], [64683.8, 0.029], [64687.0, 1.105], [64696.0, 0.19], [64696.1, 0.009], [64696.9, 0.001]], "asks": [[64699.9, 27.833], [64700.2, 0.086], [64701.4, 0.009], [64702.7, 0.011], [64706.9, 0.036], [64708.4, 0.225], [64710.2, 0.026], [64710.3, 0.492], [64712.1, 0.002], [64716.3, 0.778], [64839.9, 6.863], [64895.7, 3.544], [65094.9, 0.0], [65346.9, 4.434], [65799.8, 10.94]]}
{"kind": "depth", "E": 1787080332089, "U": 11315346842006, "u": 11315346851410, "recv_ms": 1787080332039, "bids": [[1000.0, 35.81], [14199.8, 0.112], [14299.8, 3.766], [14399.8, 0.322], [58229.8, 0.053], [62111.8, 1.909], [63699.8, 0.011], [63757.2, 0.096], [64052.8, 2.151], [64182.2, 10.76], [64683.8, 0.031], [64688.2, 1.082], [64696.0, 0.19], [64696.1, 0.001]], "asks": [[64712.7, 0.164], [64713.0, 0.925], [64716.3, 0.78], [64717.7, 0.233], [64718.3, 0.68], [65069.4, 0.002], [65346.9, 4.436], [65405.1, 5.26], [65421.8, 3.052], [65699.9, 0.931], [65942.4, 0.0]]}
{"kind": "depth", "E": 1787080332191, "U": 11315346851420, "u": 11315346868526, "recv_ms": 1787080332143, "bids": [[1000.0, 35.81], [14199.8, 0.364], [14299.8, 3.626], [14399.8, 0.21], [51759.8, 0.0], [51760.0, 0.004], [58229.8, 0.053], [63405.9, 9.29], [63699.8, 0.031], [63834.6, 5.945], [64376.3, 6.96], [64641.5, 0.006], [64648.2, 0.003], [64651.2, 1.194], [64654.5, 0.036], [64681.9, 0.643], [64689.3, 0.023], [64696.0, 0.002], [64696.1, 0.009], [64698.3, 0.0], [64699.8, 2.763]], "asks": [[64700.8, 0.009], [64701.3, 0.869], [64702.7, 0.166], [64705.0, 0.917], [64707.3, 0.195], [64710.2, 0.181], [64710.3, 0.802], [64710.6, 0.003], [64712.1, 0.157], [64713.0, 0.0], [64713.3, 0.925], [64716.3, 0.723], [64716.6, 0.082], [64722.1, 0.623], [64745.2, 0.037], [64809.9, 0.001], [65023.4, 5.077], [65346.9, 4.434], [65699.9, 0.951]]}
{"kind": "depth", "E": 1787080332395, "U": 11315346882412, "u": 11315346899063, "recv_ms": 1787080332350, "bids": [[1000.0, 35.81], [14199.8, 0.868], [14299.8, 3.332], [14399.8, 0.0], [58229.8, 0.053], [61464.8, 2.445], [62111.8, 1.909], [63699.8, 0.011], [63772.5, 0.474], [63826.4, 13.219], [63913.8, 1.55], [64052.8, 2.153], [64559.9, 4.727], [64625.6, 7.539], [64642.6, 0.073], [64649.6, 0.131], [64652.4, 0.411], [64657.5, 0.004], [64658.3, 0.0], [64659.9, 0.126], [64660.7, 0.24], [64670.4, 1.242], [64671.1, 0.311], [64671.2, 0.174], [64683.6, 0.029], [64684.0, 0.008], [64688.7, 0.0], [64689.1, 0.0], [64690.6, 0.003], [64692.2, 0.251], [64692.6, 0.033], [64693.0, 0.094], [64694.4, 1.655], [64694.5, 0.002], [64695.2, 0.002], [64695.5, 0.155], [64696.0, 0.01], [64696.9, 0.001], [64699.8, 2.221]], "asks": [[64700.8, 0.012], [64701.3, 0.866], [64701.9, 0.0], [64702.7, 0.166], [64706.9, 0.191], [64710.0, 10.623], [64712.0, 0.468], [64713.7, 0.197], [64716.4, 6.118], [64717.7, 0.774], [64718.3, 0.139], [64724.7, 0.061], [64732.1, 0.003], [64736.7, 0.027], [64739.2, 1.668], [64743.3, 2.12], [64746.8, 0.001], [64829.3, 2.322], [64835.2, 3.231], [64839.9, 5.595], [64856.9, 6.037], [64895.7, 6.485], [65346.9, 4.434], [65609.8, 0.455], [65699.9, 0.931], [65993.8, 9.324]]}
{"kind": "depth", "E": 1787080332497, "U": 11315346899445, "u": 11315346925884, "recv_ms": 1787080332450, "bids": [[1000.0, 35.81], [14199.8, 1.218], [14299.8, 2.982], [58229.8, 0.053], [62111.8, 1.912], [64052.8, 2.151], [64102.8, 0.0], [64376.3, 6.96], [64491.2, 0.0], [64532.3, 0.006], [64598.6, 10.66], [64630.0, 3.081], [64637.9, 0.093], [64639.5, 0.236], [64642.6, 0.013], [64645.0, 6.031], [64646.6, 0.012], [64648.6, 0.124], [64649.6, 0.106], [64653.0, 0.059], [64654.8, 2.004], [64657.3, 0.03], [64663.8, 0.002], [64664.6, 0.059], [64664.7, 0.0], [64665.3, 0.022], [64670.9, 0.209], [64671.2, 0.174], [64676.1, 0.151], [64676.9, 0.311], [64679.7, 0.0], [64680.4, 0.018], [64680.5, 2.923], [64681.3, 1.239], [64683.9, 0.631], [64684.0, 0.008], [64684.9, 0.212], [64688.3, 0.029], [64689.8, 0.325], [64691.2, 1.38], [64691.6, 0.254], [64692.1, 0.042], [64692.2, 0.251], [64692.6, 0.033], [64693.0, 0.086], [64693.5, 0.046], [64694.3, 0.002], [64694.5, 0.01], [64694.8, 0.0], [64695.5, 0.155], [64695.7, 0.19], [64696.0, 0.01]], "asks": [[64701.4, 0.009], [64702.7, 0.119], [64706.7, 0.498], [64706.8, 0.542], [64706.9, 0.028], [64707.4, 2.937], [64711.2, 0.001], [64712.0, 0.003], [64712.1, 0.002], [64712.2, 2.571], [64713.0, 0.0], [64713.3, 0.0], [64713.7, 0.042], [64713.8, 3.636], [64715.6, 0.37], [64716.3, 0.721], [64716.4, 6.118], [64716.6, 0.027], [64717.2, 0.058], [64717.7, 0.233], [64718.3, 0.68], [64724.7, 0.001], [64727.9, 2.016], [64731.4, 0.0], [64736.7, 0.002], [64737.0, 0.004], [64742.2, 0.217], [64744.2, 0.025], [64745.9, 0.0], [64817.8, 0.003], [64856.9, 8.393], [65346.9, 4.434], [65499.8, 6.098]]}
{"kind": "depth", "E": 1787080332599, "U": 11315346926303, "u": 11315346947912, "recv_ms": 1787080332550, "bids": [[14199.8, 1.582], [14299.8, 2.618], [51760.0, 0.004], [58229.8, 0.053], [63276.4, 0.007], [63687.4, 2.176], [63761.7, 32.502], [64052.8, 2.151], [64376.3, 6.959], [64453.1, 0.019], [64481.3, 0.012], [64603.7, 0.087], [64604.1, 0.006], [64607.9, 1.599], [64614.3, 0.019], [64620.8, 1.242], [64624.6, 0.037], [64625.9, 0.001], [64629.5, 0.034], [64632.5, 0.01], [64636.0, 0.066], [64642.5, 0.036], [64649.0, 0.265], [64655.5, 0.065], [64662.0, 0.034], [64668.5, 0.036], [64671.2, 0.175], [64672.6, 0.495], [64677.5, 0.004], [64684.0, 0.009], [64685.6, 0.13], [64688.3, 0.005], [64691.6, 0.255], [64693.0, 0.086], [64693.5, 0.234], [64694.5, 0.002], [64695.5, 0.156], [64696.0, 0.002]], "asks": [[64709.9, 0.014], [64714.0, 0.022], [64717.8, 1.391], [64717.9, 0.099], [64718.3, 0.675], [64720.5, 0.151], [64727.0, 3.757], [64727.5, 0.001], [64733.5, 0.03], [64736.6, 0.1], [64740.0, 0.838], [64744.2, 0.0], [64746.5, 0.064], [64753.0, 0.034], [64766.6, 0.039], [64767.9, 0.009], [64776.0, 3.971], [64785.8, 0.0], [65346.9, 4.434], [65499.8, 5.87], [65666.7, 1.247], [65993.8, 9.327], [66626.0, 0.131]]}
{"kind": "depth", "E": 1787080332701, "U": 11315346948369, "u": 11315346961029, "recv_ms": 1787080332654, "bids": [[1000.0, 35.81], [14199.8, 1.932], [14299.8, 2.268], [58229.8, 0.053], [61464.8, 2.445], [62111.8, 1.909], [63697.0, 16.154], [63699.8, 0.031], [63923.4, 43.45], [63958.1, 1.094], [64052.8, 2.151], [64311.6, 0.345], [64344.0, 5.004], [64613.7, 0.027], [64620.2, 0.029], [64626.7, 0.03], [64635.1, 0.345], [64635.4, 2.323], [64635.7, 0.159], [64636.0, 0.034], [64636.3, 0.005], [64654.1, 0.065], [64654.5, 0.004], [64654.8, 1.972], [64655.1, 0.359], [64655.3, 0.184], [64655.4, 0.005], [64669.1, 0.176], [64669.2, 0.124], [64669.3, 0.0], [64669.4, 0.002], [64669.5, 0.003], [64669.6, 0.022], [64669.7, 0.056], [64669.8, 0.003], [64670.0, 1.404], [64672.4, 0.0], [64672.8, 0.384], [64676.1, 0.035], [64677.0, 1.096], [64677.7, 0.084], [64678.4, 0.462], [64688.3, 0.029], [64689.8, 0.093], [64690.2, 0.234], [64691.0, 0.001], [64691.1, 0.169], [64691.2, 1.24], [64691.3, 0.001], [64691.4, 0.016], [64691.5, 0.001], [64691.6, 0.085], [64691.7, 1.669], [64691.8, 0.0], [64691.9, 0.087], [64692.0, 0.011], [64692.3, 0.086], [64692.6, 0.001], [64692.9, 0.009], [64693.0, 0.643], [64693.2, 0.002], [64693.4, 0.246], [64693.5, 0.046], [64693.6, 0.009], [64694.5, 0.002], [64696.0, 0.002], [64696.9, 0.001], [64699.8, 2.22]], "asks": [[64701.3, 1.199], [64701.4, 0.004], [64702.7, 0.011], [64705.1, 0.506], [64706.7, 0.574], [64706.9, 0.025], [64707.0, 1.019], [64707.3, 0.002], [64707.7, 0.629], [64708.0, 1.006], [64708.2, 0.005], [64708.4, 0.001], [64708.5, 0.466], [64708.6, 2.702], [64708.7, 0.005], [64708.8, 0.006], [64708.9, 0.234], [64709.0, 0.721], [64709.1, 0.001], [64709.2, 0.003], [64709.9, 0.014], [64712.8, 1.34], [64713.7, 0.042], [64714.6, 0.249], [64715.5, 0.619], [64716.3, 0.165], [64719.9, 0.115], [64720.5, 0.036], [64722.5, 1.003], [64725.8, 1.421], [64726.1, 0.318], [64726.4, 0.007], [64726.7, 0.0], [64727.1, 0.205], [64727.4, 0.332], [64727.9, 1.886], [64730.2, 0.0], [64730.4, 0.22], [64730.5, 0.964], [64730.6, 0.404], [64730.7, 0.001], [64730.8, 0.058], [64730.9, 0.009], [64731.0, 0.067], [64731.1, 0.466], [64731.2, 2.885], [64744.8, 0.309], [64745.1, 1.036], [64745.2, 0.005], [64745.5, 0.008], [64745.8, 0.036], [64746.1, 0.041], [64771.1, 0.11], [64780.8, 0.035], [65023.4, 5.078], [65088.1, 0.074], [65120.9, 0.036], [65346.9, 4.435], [65499.8, 5.641], [65699.9, 0.951], [65993.8, 9.324], [71169.9, 0.0]]}
{"kind": "depth", "E": 1787080332803, "U": 11315346961320, "u": 11315346970710, "recv_ms": 1787080332753, "bids": [[1000.0, 35.81], [14199.8, 2.296], [14299.8, 1.904], [58229.8, 0.053], [61464.8, 2.445], [62111.8, 1.912], [62134.9, 0.689], [63697.0, 17.252], [64052.8, 2.151], [64117.4, 2.261], [64376.3, 6.949], [64655.6, 0.033], [64688.3, 0.029], [64691.1, 0.015], [64691.2, 1.31], [64691.4, 0.086], [64691.6, 0.086], [64691.8, 0.07], [64692.2, 0.25], [64692.8, 1.944], [64692.9, 0.55], [64693.0, 0.102], [64693.7, 0.037], [64695.7, 0.19], [64696.9, 0.189], [64699.8, 2.22]], "asks": [[64701.4, 0.004], [64702.7, 0.119], [64706.7, 0.498], [64706.9, 0.025], [64707.3, 0.002], [64708.6, 2.779], [64709.0, 0.805], [64709.2, 0.073], [64709.9, 0.014], [64712.1, 0.002], [64725.7, 0.041], [64730.6, 0.481], [64730.9, 0.093], [64731.2, 2.955], [64744.8, 0.341], [64780.6, 0.434], [65346.9, 4.435], [65469.8, 8.235], [65651.0, 10.722], [65692.8, 0.0]]}
{"kind": "depth", "E": 1787080332905, "U": 11315346970998, "u": 11315346978923, "recv_ms": 1787080332857, "bids": [[14199.8, 2.646], [14299.8, 1.554], [58229.8, 0.053], [62111.8, 1.895], [63397.4, 0.008], [63469.3, 0.0], [63541.1, 0.0], [63613.0, 0.001], [63684.9, 0.0], [63697.0, 18.349], [63699.8, 0.011], [63756.8, 0.049], [63828.7, 0.047], [63900.5, 0.024], [63942.8, 5.475], [63972.4, 0.126], [64044.3, 6.192], [64052.8, 2.151], [64134.5, 0.0], [64559.9, 4.675], [64654.6, 0.034], [64654.8, 1.912], [64662.0, 0.094], [64688.3, 0.029], [64691.1, 0.169], [64691.6, 0.085], [64691.7, 1.669], [64691.8, 0.17], [64692.0, 0.111], [64692.1, 0.043], [64692.4, 0.0], [64692.6, 0.001], [64692.8, 1.876], [64692.9, 0.009], [64693.0, 0.627], [64693.1, 0.189], [64694.5, 0.01], [64696.0, 0.01], [64696.9, 0.001]], "asks": [[64701.4, 0.009], [64707.6, 0.303], [64708.4, 0.141], [64708.6, 2.899], [64726.7, 0.038], [64727.4, 0.472], [64730.5, 1.084], [64745.8, 0.074], [64839.9, 6.863], [64895.7, 4.185], [65338.1, 0.035], [65346.9, 4.435], [65410.0, 0.521], [65481.9, 0.019], [65553.7, 0.001], [65625.6, 0.001], [65697.5, 0.0], [65699.9, 0.931], [65769.4, 0.075], [65841.3, 0.0], [65913.1, 0.0], [65985.0, 6.143], [66640.9, 2.173]]}
{"kind": "depth", "E": 1787080333109, "U": 11315346987719, "u": 11315346997247, "recv_ms": 1787080333062, "bids": [[1000.0, 35.81], [14199.8, 3.374], [14299.8, 0.826], [58229.8, 0.053], [61464.8, 2.443], [61464.9, 0.012], [63699.8, 0.031], [63710.3, 0.02], [63891.1, 20.396], [64052.8, 2.151], [64376.3, 6.328], [64571.2, 3.627], [64578.1, 6.184], [64578.3, 1.365], [64586.0, 0.501], [64593.2, 0.015], [64593.4, 2.318], [64628.6, 1.813], [64636.5, 0.032], [64641.5, 0.009], [64683.8, 0.031], [64688.2, 1.082], [64690.2, 0.002], [64690.6, 0.235], [64691.3, 0.141], [64691.5, 0.071], [64691.7, 1.869], [64692.1, 0.042], [64692.4, 0.032], [64692.6, 0.002], [64692.8, 1.976], [64692.9, 0.6], [64693.0, 0.237], [64693.1, 0.133], [64694.3, 0.086], [64694.5, 0.002], [64695.3, 0.086], [64696.0, 0.01], [64697.1, 0.19], [64699.8, 2.22]], "asks": [[64699.9, 27.753], [64700.8, 0.009], [64701.4, 0.004], [64702.7, 0.274], [64703.4, 0.003], [64704.8, 0.007], [64707.3, 0.195], [64708.7, 0.225], [64708.9, 0.304], [64709.1, 0.155], [64709.9, 0.479], [64712.1, 0.157], [64713.0, 0.925], [64713.8, 2.711], [64716.3, 0.165], [64730.6, 0.591], [64730.9, 0.163], [64731.1, 0.543], [64771.0, 0.049], [64807.3, 2.318], [64809.9, 0.004], [64830.0, 0.203], [64835.2, 2.703], [64835.3, 3.864], [64844.8, 0.005], [64891.4, 0.0], [64891.5, 0.016], [64894.0, 0.002], [65023.4, 5.077], [65346.9, 4.435], [65689.3, 0.017], [65699.9, 0.951]]}
{"kind": "depth", "E": 1787080333211, "U": 11315346997334, "u": 11315347006413, "recv_ms": 1787080333164, "bids": [[14199.8, 3.696], [14299.8, 0.49], [14599.8, 0.014], [51759.8, 0.0], [58229.8, 0.053], [61464.8, 2.443], [62111.8, 1.895], [63297.4, 0.002], [63298.7, 0.0], [63713.3, 0.025], [63975.2, 0.245], [64052.8, 2.151], [64376.3, 6.95], [64635.5, 0.033], [64648.2, 0.004], [64669.2, 0.194], [64669.5, 0.073], [64669.8, 0.073], [64671.2, 0.003], [64688.3, 0.028], [64690.8, 0.064], [64692.6, 0.056], [64692.8, 1.876], [64693.0, 0.229], [64693.1, 0.041], [64693.3, 0.053], [64694.5, 0.002], [64695.7, 0.19], [64697.1, 0.002], [64699.7, 0.318]], "asks": [[64699.9, 27.754], [64702.7, 0.119], [64707.3, 0.04], [64707.4, 2.938], [64709.9, 0.014], [64712.1, 0.002], [64938.1, 0.0], [65120.9, 0.034], [65346.9, 4.435], [65476.3, 35.014]]}
{"kind": "depth", "E": 1787080333313, "U": 11315347006736, "u": 11315347014877, "recv_ms": 1787080333266, "bids": [[1000.0, 35.81], [14199.8, 3.738], [14299.8, 0.294], [14599.8, 0.168], [51760.0, 0.004], [58229.8, 0.053], [62111.8, 1.898], [63158.5, 0.0], [63699.8, 0.011], [63761.7, 32.659], [64052.8, 2.151], [64635.2, 1.134], [64635.9, 0.054], [64669.9, 0.702], [64673.0, 0.569], [64674.9, 0.631], [64682.3, 0.643], [64692.9, 0.55], [64696.0, 0.19], [64696.1, 0.009], [64699.8, 2.22]], "asks": [[64702.7, 0.119], [64707.3, 0.04], [64709.9, 0.014], [64712.1, 0.002], [64712.8, 1.958], [64720.1, 2.946], [65088.1, 0.076], [65346.9, 4.435], [65686.3, 0.018], [65699.9, 0.931]]}
{"kind": "depth", "E": 1787080333415, "U": 11315347015320, "u": 11315347023463, "recv_ms": 1787080333367, "bids": [[1000.0, 35.81], [14199.8, 3.598], [14299.8, 0.182], [14599.8, 0.42], [51760.0, 0.004], [58229.8, 0.053], [61464.8, 2.443], [61464.9, 0.01], [62111.8, 1.895], [63405.9, 9.287], [64052.8, 2.151], [64376.3, 6.96], [64504.0, 0.022], [64504.1, 15.531], [64542.9, 9.136], [64559.9, 4.433], [64633.9, 0.0], [64634.0, 2.437], [64641.5, 0.009], [64654.5, 0.001], [64669.3, 0.07], [64669.4, 0.142], [64669.6, 0.122], [64669.7, 0.156], [64669.8, 0.173], [64669.9, 0.802], [64670.0, 1.474], [64670.2, 0.483], [64672.5, 0.103], [64683.8, 0.035], [64695.7, 0.19], [64696.0, 0.01], [64696.1, 0.001], [64699.8, 2.221]], "asks": [[64702.7, 0.119], [64707.3, 0.04], [64709.9, 0.014], [64712.1, 0.002], [64745.2, 0.005], [64765.2, 1.227], [64765.3, 2.687], [64809.9, 0.001], [64829.3, 2.322], [64835.2, 3.231], [64895.7, 3.842], [65346.9, 4.435]]}
{"kind": "depth", "E": 1787080333517, "U": 11315347023647, "u": 11315347033250, "recv_ms": 1787080333467, "bids": [[14199.8, 3.5], [14299.8, 0.056], [14599.8, 0.644], [58229.8, 0.053], [61464.8, 2.443], [62111.8, 1.898], [63699.8, 0.031], [64052.8, 2.153], [64559.9, 0.0], [64669.5, 0.143], [64693.0, 0.129], [64695.7, 0.19], [64696.0, 0.002], [64696.1, 0.009]], "asks": [[64699.9, 27.804], [64702.7, 0.119], [64707.3, 0.04], [64709.9, 0.014], [64712.1, 0.002], [64839.9, 1.465], [65346.9, 4.435], [65597.0, 13.007], [65699.9, 0.951]]}
{"kind": "depth", "E": 1787080333619, "U": 11315347033265, "u": 11315347059707, "recv_ms": 1787080333570, "bids": [[1000.0, 35.81], [14199.8, 3.248], [14299.8, 0.0], [14599.8, 0.952], [58229.8, 0.053], [61464.8, 2.441], [61464.9, 0.012], [63699.8, 0.011], [64052.8, 2.151], [64376.3, 6.951], [64504.1, 15.492], [64542.9, 9.114], [64559.9, 3.701], [64680.5, 0.935], [64692.4, 0.033], [64692.6, 0.055], [64692.9, 0.55], [64694.5, 0.002], [64694.7, 0.133], [64695.3, 0.002], [64696.0, 0.01], [64696.1, 0.001]], "asks": [[64699.9, 27.771], [64702.7, 0.274], [64707.3, 0.195], [64709.9, 0.479], [64712.1, 0.157], [64839.9, 6.863], [64895.7, 3.615], [65023.4, 5.076], [65346.9, 4.434], [65699.9, 0.931], [71169.9, 0.0]]}
{"kind": "depth", "E": 1787080333721, "U": 11315347060006, "u": 11315347070239, "recv_ms": 1787080333679, "bids": [[1000.0, 35.81], [14199.8, 2.898], [14599.8, 1.302], [58229.8, 0.053], [61464.8, 2.441], [62111.8, 1.895], [63752.1, 1.553], [63844.4, 3.067], [64052.8, 2.151], [64627.3, 0.012], [64666.8, 0.018], [64666.9, 0.327], [64667.0, 0.006], [64670.3, 0.349], [64670.4, 1.244], [64670.5, 0.698], [64690.6, 0.003], [64691.0, 0.233], [64692.1, 0.0], [64693.5, 0.088], [64694.5, 0.002], [64699.8, 2.221]], "asks": [[64702.7, 0.011], [64706.7, 0.143], [64706.9, 0.488], [64707.3, 0.04], [64709.9, 0.014], [64712.1, 0.002], [64715.5, 0.063], [64715.6, 0.926], [64719.3, 1.047], [64722.4, 1.937], [64723.9, 1.251], [65346.9, 4.434], [65581.9, 3.934], [65605.7, 45.521], [65735.1, 9.116], [67287.8, 0.291]]}
{"kind": "depth", "E": 1787080333823, "U": 11315347070446, "u": 11315347079535, "recv_ms": 1787080333775, "bids": [[14199.8, 2.534], [14599.8, 1.666], [51760.0, 0.004], [58229.8, 0.053], [62111.8, 1.898], [63405.9, 9.29], [63913.2, 0.782], [64052.8, 2.151], [64663.8, 0.002], [64664.6, 0.002], [64664.7, 0.057], [64674.6, 0.559], [64675.3, 0.004], [64676.2, 0.199], [64677.0, 0.98], [64679.7, 0.0], [64680.5, 0.009], [64680.7, 1.094], [64687.4, 0.001], [64687.9, 2.29], [64688.2, 0.541], [64693.1, 0.033], [64693.5, 0.088], [64694.5, 0.01]], "asks": [[64712.2, 2.571], [64713.0, 0.0], [64713.3, 0.925], [64714.8, 0.328], [64715.6, 0.37], [64715.7, 0.687], [64716.4, 6.118], [64716.6, 0.084], [64717.4, 0.016], [64718.3, 0.675], [64718.7, 0.003], [64719.0, 0.015], [64719.9, 0.115], [64895.7, 4.186], [65346.9, 4.434], [65609.8, 0.228]]}
{"kind": "depth", "E": 1787080334129, "U": 11315347096920, "u": 11315347106282, "recv_ms": 1787080334080, "bids": [[14199.8, 1.47], [14599.8, 2.73], [51759.8, 0.002], [51760.0, 0.004], [58229.8, 0.053], [61464.8, 2.441], [62111.8, 1.898], [63405.9, 9.345], [63477.8, 0.061], [63549.7, 0.058], [63621.6, 0.059], [63693.5, 0.1], [63699.8, 0.011], [63710.3, 0.011], [63713.3, 0.017], [63765.3, 0.085], [63778.0, 0.142], [63779.6, 0.004], [63781.1, 3.984], [63837.2, 0.059], [64052.8, 2.151], [64657.5, 0.004], [64682.3, 0.025], [64683.8, 0.035], [64687.9, 1.749], [64688.2, 0.541], [64688.3, 0.584], [64688.4, 0.551], [64690.7, 0.003], [64691.6, 0.201], [64691.7, 0.202], [64692.3, 0.089], [64692.9, 0.19], [64693.3, 0.363], [64693.5, 0.088], [64694.5, 0.002], [64695.9, 0.361], [64696.0, 0.002], [64698.3, 0.001], [64699.8, 2.746]], "asks": [[64701.4, 0.009], [64702.7, 0.011], [64707.3, 0.04], [64709.9, 0.014], [64712.1, 0.002], [64712.8, 1.34], [64713.7, 0.042], [64714.8, 0.328], [64716.3, 0.165], [64720.1, 2.328], [65346.9, 4.434], [65620.0, 0.075], [65621.6, 0.0], [65686.3, 0.01], [65689.3, 0.008], [65699.9, 0.931]]}
{"kind": "depth", "E": 1787080334231, "U": 11315347106396, "u": 11315347113462, "recv_ms": 1787080334183, "bids": [[1000.0, 35.81], [14199.8, 1.106], [14599.8, 3.094], [51759.8, 0.0], [51760.0, 0.004], [58229.8, 0.053], [62111.8, 1.895], [63713.4, 0.018], [63778.1, 0.095], [63779.6, 0.012], [63909.1, 3.965], [63981.0, 0.073], [64052.8, 2.151], [64052.9, 4.012], [64376.3, 6.95], [64648.2, 0.005], [64688.4, 0.543], [64688.5, 0.0], [64691.0, 0.001], [64691.3, 0.373], [64693.5, 0.046], [64696.0, 0.01]], "asks": [[65346.9, 4.492], [65418.8, 0.058], [65490.7, 0.058], [65508.6, 15.996], [65562.6, 0.386], [65618.6, 3.864], [65620.1, 0.008], [65621.7, 0.008], [65634.5, 0.06], [65686.4, 0.019], [65706.3, 0.058], [65778.2, 0.063], [65850.1, 0.059], [65922.0, 0.083], [65993.9, 0.082]]}
{"kind": "depth", "E": 1787080334333, "U": 11315347113626, "u": 11315347122929, "recv_ms": 1787080334283, "bids": [[1000.0, 35.81], [14199.8, 0.756], [14599.8, 3.444], [51760.0, 0.004], [58229.8, 0.053], [61464.8, 2.441], [62111.8, 1.898], [63591.4, 3.296], [63699.8, 0.031], [63794.0, 37.589], [64052.8, 2.151], [64625.1, 0.0], [64625.6, 1.114], [64627.2, 32.437], [64630.1, 6.278], [64682.4, 0.619], [64688.5, 0.008], [64690.7, 0.002], [64692.3, 0.086], [64696.0, 0.002], [64699.8, 2.748]], "asks": [[64699.9, 27.769], [64702.7, 0.011], [64707.3, 0.04], [64709.9, 0.014], [64712.1, 0.002], [64712.9, 2.787], [64720.2, 0.619], [64895.7, 3.615], [65023.4, 5.077], [65346.9, 4.494], [65699.9, 0.951], [71169.9, 0.0]]}
{"kind": "depth", "E": 1787080334537, "U": 11315347133054, "u": 11315347141691, "recv_ms": 1787080334487, "bids": [[1000.0, 35.81], [14199.8, 0.266], [14499.8, 0.224], [14599.8, 3.71], [58229.8, 0.053], [61464.8, 2.441], [62111.8, 2.584], [63699.8, 0.011], [64052.8, 2.151], [64376.3, 6.96], [64692.9, 0.002], [64699.8, 2.747]], "asks": [[64702.7, 0.011], [64707.3, 0.04], [64709.9, 0.014], [64712.1, 0.002], [65346.9, 4.492], [65699.9, 0.931], [65891.4, 0.0]]}
{"kind": "depth", "E": 1787080334843, "U": 11315347159216, "u": 11315347169643, "recv_ms": 1787080334793, "bids": [[1000.0, 35.81], [14199.8, 0.0], [14499.8, 1.036], [14599.8, 3.164], [58229.8, 0.053], [62111.8, 2.587], [63891.1, 20.63], [64052.8, 2.151], [64376.3, 6.959], [64538.0, 2.689], [64641.5, 0.009]], "asks": [[64699.9, 27.77], [64702.7, 0.166], [64707.3, 0.195], [64709.9, 0.479], [64712.1, 0.157], [64809.9, 0.004], [64894.0, 0.005], [64978.4, 6.05], [65346.9, 4.492]]}
{"kind": "depth", "E": 1787080334945, "U": 11315347169808, "u": 11315347179214, "recv_ms": 1787080334896, "bids": [[1000.0, 35.81], [14499.8, 1.386], [14599.8, 2.814], [58229.8, 0.053], [61464.8, 2.441], [63699.8, 0.011], [63794.0, 38.058], [63817.8, 8.057], [64052.8, 2.151], [64635.1, 0.346], [64663.9, 0.001], [64664.0, 1.193], [64664.7, 0.0], [64664.9, 2.819], [64674.6, 0.559], [64675.3, 0.004], [64676.2, 0.199], [64676.9, 0.311], [64679.7, 0.0], [64680.0, 2.533], [64680.7, 0.168], [64680.9, 2.214], [64687.9, 1.749], [64688.4, 1.006], [64688.5, 0.085], [64691.0, 0.155], [64691.1, 0.015], [64692.9, 0.19], [64694.5, 0.002]], "asks": [[64702.7, 0.011], [64707.3, 0.04], [64709.9, 0.014], [64712.1, 0.002], [64712.3, 1.435], [64712.4, 0.001], [64713.3, 0.925], [64714.8, 0.328], [64715.7, 0.687], [64716.6, 0.084], [64717.4, 0.016], [64718.2, 0.014], [64718.3, 0.675], [64719.0, 0.015], [64719.9, 0.0], [64720.0, 2.306], [64764.6, 0.005], [65314.5, 11.854], [65346.9, 4.492], [65699.9, 0.931]]}
{"kind": "depth", "E": 1787080335047, "U": 11315347179529, "u": 11315347188372, "recv_ms": 1787080334997, "bids": [[14499.8, 1.75], [14599.8, 2.45], [58229.8, 0.053], [61464.8, 2.441], [62111.8, 2.584], [63136.4, 1.356], [63405.9, 9.345], [64052.8, 2.151], [64663.1, 0.481], [64664.1, 0.011], [64664.9, 2.819], [64680.0, 2.533], [64680.8, 1.395], [64680.9, 1.288], [64688.1, 2.898], [64688.2, 0.006], [64688.4, 0.465], [64688.5, 0.085], [64692.1, 0.001], [64692.2, 0.32], [64692.3, 0.086], [64692.6, 0.055], [64692.9, 0.002], [64693.0, 0.086], [64693.5, 0.234], [64694.5, 0.002], [64699.1, 0.103], [64699.3, 0.0], [64699.8, 2.222]], "asks": [[64699.9, 27.686], [64702.7, 0.166], [64707.3, 0.195], [64709.9, 0.479], [64712.1, 0.157], [64717.4, 0.016], [64718.3, 0.675], [64785.6, 1.355], [65346.9, 4.492], [65791.0, 28.589]]}
{"kind": "depth", "E": 1787080335149, "U": 11315347188440, "u": 11315347209055, "recv_ms": 1787080335103, "bids": [[1000.0, 35.81], [14499.8, 2.1], [14599.8, 2.1], [51759.8, 0.0], [58229.8, 0.053], [61464.8, 2.439], [61464.9, 0.012], [62111.8, 2.587], [63699.8, 0.031], [63710.3, 0.003], [63713.4, 0.026], [64052.8, 2.153], [64152.5, 0.157], [64376.3, 6.959], [64648.3, 0.006], [64657.5, 0.005], [64683.8, 0.035], [64688.1, 2.357], [64688.2, 0.001], [64688.4, 1.006], [64688.5, 0.085], [64689.0, 0.001], [64691.2, 1.224], [64692.1, 0.0], [64692.5, 0.01], [64692.9, 0.005], [64693.5, 0.046], [64694.5, 0.002], [64695.9, 0.361], [64696.0, 0.002], [64698.3, 0.001], [64699.8, 2.747]], "asks": [[64701.4, 0.009], [64701.5, 0.867], [64702.7, 0.003], [64705.0, 0.017], [64705.7, 0.01], [64707.3, 0.04], [64709.9, 0.014], [64712.1, 0.002], [64716.3, 0.165], [65346.9, 4.492], [65499.8, 5.413], [65689.3, 0.0], [65699.9, 0.951], [67934.8, 0.02]]}
{"kind": "depth", "E": 1787080335251, "U": 11315347209142, "u": 11315347217773, "recv_ms": 1787080335201, "bids": [[1000.0, 35.81], [14499.8, 2.464], [14599.8, 1.736], [58229.8, 0.053], [61464.8, 2.439], [62111.8, 2.584], [63826.4, 13.609], [64052.8, 2.151], [64538.0, 2.692], [64559.9, 0.0], [64622.1, 0.024], [64657.5, 0.004], [64659.7, 0.337], [64660.9, 0.023], [64688.5, 0.093], [64691.2, 1.223]], "asks": [[64699.9, 27.681], [64702.7, 0.158], [64707.3, 0.195], [64709.9, 0.479], [64712.1, 0.157], [64764.6, 0.014], [64839.9, 1.465], [65346.9, 4.492], [65686.4, 0.027], [65799.8, 11.318]]}
{"kind": "depth", "E": 1787080335353, "U": 11315347218053, "u": 11315347226453, "recv_ms": 1787080335303, "bids": [[14499.8, 2.814], [14599.8, 1.386], [58229.8, 0.053], [62111.8, 2.587], [63591.4, 2.903], [63699.8, 0.011], [64052.8, 2.151], [64677.7, 0.004], [64678.7, 2.368], [64684.8, 0.249], [64692.8, 1.876]], "asks": [[64702.7, 0.003], [64707.3, 0.04], [64709.9, 0.014], [64712.1, 0.002], [64762.1, 0.058], [64764.6, 0.014], [65023.4, 5.077], [65346.9, 4.492], [65699.9, 0.931], [71169.9, 0.0]]}
{"kind": "depth", "E": 1787080335455, "U": 11315347226738, "u": 11315347234071, "recv_ms": 1787080335406, "bids": [[1000.0, 35.81], [14499.8, 3.178], [14599.8, 1.022], [58229.8, 0.053], [64052.8, 2.151], [64117.5, 3.815], [64376.3, 6.96], [64504.1, 0.028], [64542.9, 1.246], [64625.1, 32.405], [64627.2, 0.033], [64630.1, 6.279], [64655.2, 0.0], [64660.9, 0.037], [64674.9, 0.631], [64682.3, 0.643], [64699.8, 2.747]], "asks": [[64702.7, 0.158], [64707.3, 0.195], [64709.9, 0.479], [64712.1, 0.157], [64712.8, 1.958], [64829.3, 2.322], [64856.9, 0.0], [64895.7, 0.001], [65346.9, 4.492], [65618.6, 4.091], [65993.8, 9.327]]}
{"kind": "depth", "E": 1787080335557, "U": 11315347234101, "u": 11315347241955, "recv_ms": 1787080335509, "bids": [[1000.0, 35.81], [14499.8, 3.542], [14599.8, 0.658], [58229.8, 0.053], [61464.8, 2.439], [62111.8, 2.584], [63699.8, 0.031], [64052.8, 2.151], [64504.1, 15.062], [64542.9, 9.009], [64559.9, 4.674], [64630.1, 1.811], [64664.0, 1.25], [64664.9, 2.762], [64679.9, 0.932], [64680.8, 0.469], [64688.0, 1.615], [64688.4, 0.465]], "asks": [[64702.7, 0.003], [64707.3, 0.04], [64709.9, 0.014], [64712.1, 0.002], [64712.4, 0.926], [64713.3, 0.0], [64715.8, 0.064], [64716.6, 0.027], [64717.4, 0.557], [64718.3, 0.134], [64720.2, 0.619], [64764.6, 0.005], [64839.9, 6.863], [64854.8, 2.18], [64856.9, 10.408], [64895.7, 4.187], [65346.9, 4.492], [65448.8, 0.015], [65699.9, 0.951], [67934.8, 0.025]]}
{"kind": "depth", "E": 1787080335659, "U": 11315347242083, "u": 11315347249887, "recv_ms": 1787080335610, "bids": [[14399.8, 0.07], [14499.8, 3.752], [14599.8, 0.378], [51760.0, 0.004], [58229.8, 0.053], [61464.8, 2.439], [62111.8, 2.587], [63772.5, 0.24], [63923.4, 43.669], [64052.8, 2.151], [64664.0, 1.193], [64664.9, 2.819], [64674.6, 0.002], [64674.9, 0.013], [64675.5, 0.559], [64676.2, 0.083], [64677.2, 0.118], [64679.9, 0.006], [64680.9, 2.214], [64682.3, 0.025], [64684.0, 0.089], [64684.8, 0.169], [64688.5, 0.093], [64691.0, 0.001], [64691.6, 0.355], [64692.1, 0.0], [64692.5, 0.009], [64692.6, 0.056], [64692.9, 0.002], [64695.9, 0.277], [64696.0, 0.002], [64699.8, 2.747]], "asks": [[64699.9, 27.682], [64701.2, 0.003], [64701.4, 0.009], [64702.7, 0.003], [64707.3, 0.04], [64707.4, 2.937], [64709.9, 0.014], [64712.1, 0.002], [64712.4, 0.001], [64712.8, 1.34], [64713.3, 0.925], [64715.8, 0.007], [64716.7, 0.062], [64717.4, 0.016], [64718.3, 0.675], [64720.2, 0.001], [65346.9, 4.492], [65476.3, 35.228], [65993.8, 9.324]]}
{"kind": "depth", "E": 1787080335761, "U": 11315347250051, "u": 11315347258188, "recv_ms": 1787080335712, "bids": [[1000.0, 35.81], [14399.8, 0.28], [14499.8, 3.682], [14599.8, 0.238], [58229.8, 0.053], [62111.8, 2.584], [63699.8, 0.011], [64052.8, 2.153], [64376.3, 6.95], [64662.0, 0.034], [64670.4, 1.304], [64691.5, 0.225], [64691.6, 0.201]], "asks": [[64701.2, 0.0], [64895.7, 4.188], [65023.4, 5.076], [65346.9, 4.492], [65699.9, 0.931]]}
{"kind": "depth", "E": 1787080335863, "U": 11315347258243, "u": 11315347266140, "recv_ms": 1787080335812, "bids": [[1000.0, 35.81], [14399.8, 0.532], [14499.8, 3.542], [14599.8, 0.126], [58229.8, 0.053], [61464.9, 0.01], [62111.8, 2.587], [63405.9, 9.348], [64052.8, 2.151], [64376.3, 6.951], [64559.9, 0.0], [64691.5, 0.071], [64691.6, 0.355]], "asks": [[64839.9, 1.465], [65346.9, 4.492]]}
{"kind": "depth", "E": 1787080335965, "U": 11315347266367, "u": 11315347274469, "recv_ms": 1787080335915, "bids": [[14399.8, 0.756], [14499.8, 3.444], [14599.8, 0.0], [58229.8, 0.053], [61464.8, 2.439], [63699.8, 0.031], [63958.1, 0.547], [64052.8, 2.151], [64542.9, 1.246], [64589.8, 0.003], [64622.1, 0.021], [64641.5, 0.006], [64654.5, 0.001], [64691.3, 0.527], [64691.6, 0.201], [64695.7, 0.172], [64698.0, 0.212], [64699.3, 0.035], [64699.8, 2.747]], "asks": [[64702.7, 0.003], [64707.3, 0.04], [64709.9, 0.014], [64712.1, 0.002], [64745.2, 0.005], [64809.9, 0.001], [64854.8, 0.719], [64856.9, 0.0], [65330.2, 9.85], [65346.9, 4.492], [65699.9, 0.951], [67934.8, 0.03]]}
{"kind": "depth", "E": 1787080336067, "U": 11315347274753, "u": 11315347283644, "recv_ms": 1787080336024, "bids": [[1000.0, 35.81], [14399.8, 1.12], [14499.8, 3.08], [58229.8, 0.053], [62111.8, 2.584], [62500.0, 153.796], [62681.8, 0.014], [62863.6, 0.003], [63045.4, 0.026], [63227.2, 0.006], [63409.0, 0.007], [63590.9, 0.022], [63772.7, 0.011], [63954.5, 0.38], [64052.8, 2.151], [64136.3, 0.022], [64318.1, 0.015], [64376.3, 6.951], [64500.0, 25.273], [64504.1, 14.844], [64542.9, 7.967], [64559.9, 3.845], [64600.3, 0.212], [64600.4, 0.006], [64634.0, 2.446], [64639.2, 0.022], [64642.2, 0.001], [64645.9, 0.014], [64647.9, 0.022], [64662.0, 0.094], [64664.0, 1.193], [64664.9, 2.819], [64670.4, 1.244], [64674.6, 0.559], [64675.5, 0.002], [64676.3, 0.118], [64677.2, 0.002], [64679.9, 0.006], [64680.8, 1.395], [64680.9, 1.288], [64688.2, 0.001], [64691.9, 0.103], [64692.6, 0.059], [64695.8, 0.087], [64696.2, 0.154]], "asks": [[64699.9, 27.647], [64700.0, 1.409], [64702.7, 0.003], [64707.1, 0.502], [64707.3, 0.04], [64709.9, 0.014], [64712.1, 0.002], [64712.4, 0.001], [64713.3, 0.925], [64713.7, 0.002], [64715.8, 0.007], [64716.7, 0.062], [64717.4, 0.016], [64718.3, 0.675], [64719.1, 0.052], [64719.3, 0.976], [64720.0, 2.306], [64765.3, 2.687], [64839.9, 6.863], [64856.9, 10.408], [64863.6, 0.009], [64895.7, 4.385], [65045.4, 0.0], [65227.2, 0.025], [65346.9, 4.492], [65409.0, 0.247], [65581.9, 3.173], [65590.9, 0.001], [65628.1, 1.066], [65772.7, 0.021], [65954.5, 0.012], [66136.3, 0.001], [66318.1, 0.021], [66500.0, 72.43]]}
{"kind": "depth", "E": 1787080336169, "U": 11315347283782, "u": 11315347292590, "recv_ms": 1787080336126, "bids": [[14399.8, 1.484], [14499.8, 2.716], [51759.8, 0.0], [58229.8, 0.053], [61464.8, 2.439], [62111.8, 2.587], [63405.9, 9.345], [63699.8, 0.011], [63706.4, 0.0], [63706.5, 0.166], [63942.8, 6.022], [64052.8, 2.151], [64648.2, 0.006], [64648.3, 0.005], [64650.9, 0.029], [64683.8, 0.035], [64687.5, 0.001], [64694.3, 0.108], [64694.4, 1.674], [64699.8, 2.748]], "asks": [[64699.9, 27.668], [64702.7, 0.003], [64704.1, 0.091], [64707.3, 0.04], [64709.9, 0.014], [64712.1, 0.002], [64716.3, 0.165], [64764.6, 0.014], [65346.9, 4.492], [65693.2, 0.76], [65699.9, 0.931], [65918.3, 0.0]]}
{"kind": "depth", "E": 1787080336373, "U": 11315347300808, "u": 11315347307430, "recv_ms": 1787080336324, "bids": [[1000.0, 35.81], [14399.8, 2.184], [14499.8, 2.016], [51760.0, 0.004], [58229.8, 0.053], [61464.8, 2.439], [63699.8, 0.031], [64052.8, 2.151], [64376.3, 6.961], [64639.5, 0.026], [64646.7, 0.21], [64663.8, 0.338], [64677.2, 0.0], [64677.9, 0.233], [64688.0, 1.074], [64688.4, 1.006], [64688.5, 0.093], [64689.0, 0.001], [64691.3, 0.295], [64691.9, 0.335], [64692.7, 1.921], [64692.9, 0.002], [64694.3, 0.086], [64694.4, 1.655], [64696.9, 0.001], [64697.3, 0.085]], "asks": [[64699.9, 26.325], [64700.2, 0.002], [64702.7, 0.003], [64703.5, 1.006], [64706.7, 0.058], [64706.9, 0.094], [64707.3, 0.04], [64707.4, 1.466], [64709.5, 0.044], [64709.9, 0.014], [64711.4, 0.031], [64712.1, 0.473], [64717.6, 2.549], [64829.3, 2.322], [65346.9, 4.492], [65500.6, 0.024], [65699.9, 0.951], [65878.7, 0.809], [65909.8, 5.418]]}
{"kind": "depth", "E": 1787080336679, "U": 11315347319934, "u": 11315347328622, "recv_ms": 1787080336629, "bids": [[1000.0, 35.81], [14399.8, 3.262], [14499.8, 0.938], [58229.8, 0.053], [61464.8, 2.441], [62111.8, 2.587], [63882.5, 5.056], [64052.8, 2.151], [64376.3, 6.96], [64559.9, 4.14], [64663.7, 0.001], [64664.5, 0.001], [64664.7, 0.057], [64664.9, 2.762], [64674.1, 0.003], [64677.6, 0.054], [64677.9, 0.231], [64679.7, 0.0], [64680.4, 0.018], [64680.6, 0.928], [64680.8, 0.469], [64681.5, 0.01], [64687.4, 0.001], [64687.9, 2.29], [64688.4, 0.465], [64692.3, 0.005], [64692.6, 0.056], [64694.5, 0.022], [64697.3, 0.001], [64699.8, 2.748]], "asks": [[64699.9, 27.141], [64700.1, 0.022], [64700.2, 0.109], [64702.7, 0.003], [64704.3, 0.004], [64704.5, 0.725], [64706.7, 0.043], [64706.8, 0.001], [64706.9, 0.094], [64707.0, 0.494], [64707.2, 0.009], [64707.3, 0.596], [64708.4, 0.225], [64711.3, 0.413], [64711.4, 0.023], [64711.6, 0.084], [64712.0, 0.003], [64712.1, 0.473], [64712.2, 2.571], [64713.1, 1.05], [64713.3, 0.0], [64715.6, 0.37], [64716.5, 0.063], [64716.7, 0.005], [64717.7, 0.233], [64718.3, 0.675], [64719.3, 0.976], [64839.9, 6.863], [64895.7, 5.958], [65346.9, 4.494], [65614.9, 0.001], [65662.5, 0.77], [67287.8, 0.278]]}
{"kind": "depth", "E": 1787080336781, "U": 11315347328804, "u": 11315347338000, "recv_ms": 1787080336732, "bids": [[14399.8, 3.612], [14499.8, 0.588], [58229.8, 0.053], [61464.8, 2.439], [61464.9, 0.01], [62111.8, 2.584], [63699.8, 0.031], [63882.5, 4.822], [63994.6, 6.699], [64052.8, 2.151], [64663.9, 0.058], [64664.7, 0.0], [64676.3, 0.002], [64677.2, 0.116], [64680.0, 3.459], [64680.6, 0.002], [64688.5, 0.085], [64692.9, 0.19], [64696.9, 0.009], [64697.3, 0.085], [64699.8, 3.408]], "asks": [[64699.9, 27.143], [64700.0, 1.406], [64700.2, 0.028], [64702.7, 0.003], [64706.9, 0.017], [64707.2, 0.086], [64708.4, 0.225], [64712.0, 0.003], [64712.1, 0.473], [64717.4, 0.557], [64718.3, 0.134], [64719.1, 0.052], [64720.0, 2.191], [64720.2, 0.116], [65346.9, 4.492], [65499.8, 5.071], [65699.9, 0.951]]}
{"kind": "depth", "E": 1787080336883, "U": 11315347338174, "u": 11315347347810, "recv_ms": 1787080336833, "bids": [[14299.8, 0.112], [14399.8, 3.752], [14499.8, 0.336], [58229.8, 0.053], [61464.9, 0.008], [63815.8, 0.002], [64052.8, 2.151], [64376.3, 6.959], [64663.9, 0.001], [64664.1, 0.068], [64665.0, 1.31], [64674.6, 0.002], [64674.8, 2.159], [64675.5, 0.002], [64676.4, 1.753], [64677.2, 0.0], [64680.0, 3.459], [64680.9, 1.288], [64692.9, 0.002]], "asks": [[64717.4, 0.557], [64718.3, 0.134], [65023.4, 5.078], [65346.9, 4.492], [65638.0, 35.075]]}
{"kind": "depth", "E": 1787080337189, "U": 11315347360486, "u": 11315347368313, "recv_ms": 1787080337142, "bids": [[14299.8, 0.84], [14399.8, 3.36], [14499.8, 0.0], [51759.8, 0.0], [51760.0, 0.004], [58229.8, 0.053], [61464.8, 2.441], [62111.8, 2.587], [63699.8, 0.031], [64052.8, 2.151], [64100.5, 0.702], [64589.8, 0.0], [64648.3, 0.006], [64654.5, 0.004], [64683.8, 0.035], [64688.0, 1.615], [64688.4, 0.465], [64694.0, 0.079], [64694.4, 1.677]], "asks": [[64699.9, 28.22], [64702.7, 0.003], [64702.9, 0.312], [64706.9, 0.017], [64708.4, 0.225], [64712.0, 0.003], [64712.1, 0.473], [64716.3, 0.165], [64717.4, 0.557], [64718.3, 0.134], [64745.2, 0.005], [65346.9, 4.492], [65699.9, 0.951]]}
{"kind": "depth", "E": 1787080337393, "U": 11315347378911, "u": 11315347395543, "recv_ms": 1787080337345, "bids": [[14299.8, 1.554], [14399.8, 2.646], [58229.8, 0.053], [61464.8, 2.441], [63699.8, 0.011], [63781.1, 4.218], [63882.5, 4.557], [63923.4, 42.967], [64000.6, 0.009], [64052.8, 2.153], [64085.2, 14.232], [64182.2, 10.76], [64649.2, 3.507], [64650.1, 0.011], [64657.3, 0.005], [64660.9, 0.023], [64662.0, 0.034], [64664.1, 0.011], [64664.4, 0.058], [64665.1, 0.962], [64665.4, 1.338], [64666.8, 0.016], [64667.1, 0.311], [64676.4, 1.813], [64678.4, 0.455], [64679.2, 0.007], [64680.0, 2.533], [64680.4, 0.944], [64681.0, 0.077], [64682.0, 1.275], [64688.0, 1.074], [64688.4, 1.006], [64688.5, 0.093], [64689.0, 0.001], [64692.9, 0.002], [64693.0, 0.002], [64694.0, 0.056], [64694.6, 0.028], [64694.7, 0.153], [64696.9, 0.001], [64697.7, 0.102], [64699.8, 5.473]], "asks": [[64699.9, 28.2], [64700.1, 0.002], [64700.2, 0.025], [64700.5, 0.0], [64700.6, 0.001], [64702.7, 0.003], [64704.0, 0.931], [64706.9, 0.025], [64707.2, 0.017], [64707.3, 0.581], [64708.0, 1.044], [64708.2, 0.111], [64708.3, 0.342], [64708.4, 0.225], [64711.6, 0.084], [64712.1, 0.473], [64713.1, 0.125], [64713.5, 1.242], [64716.0, 1.025], [64716.5, 0.006], [64717.0, 0.52], [64717.4, 0.014], [64717.7, 0.774], [64718.3, 0.134], [64718.9, 0.073], [64719.0, 10.01], [64719.4, 0.012], [64719.5, 1.253], [64719.7, 5.004], [64736.6, 0.075], [64742.2, 0.157], [64743.2, 1.561], [64749.0, 0.071], [64829.3, 2.322], [65346.9, 4.492], [65596.9, 6.708], [65699.9, 0.931]]}
{"kind": "depth", "E": 1787080337495, "U": 11315347395677, "u": 11315347420762, "recv_ms": 1787080337607, "bids": [[1000.0, 35.81], [14296.8, 0.126], [14299.8, 1.792], [14399.8, 2.282], [58227.1, 0.002], [58229.8, 0.051], [61085.2, 0.0], [61247.7, 0.002], [61461.9, 0.0], [62111.8, 2.587], [62305.8, 0.014], [63405.9, 0.074], [63882.5, 4.292], [64049.8, 0.0], [64052.8, 2.151], [64155.6, 0.362], [64373.9, 0.16], [64463.4, 0.0], [64463.9, 6.641], [64464.0, 3.248], [64505.6, 0.017], [64519.9, 0.377], [64535.1, 3.375], [64536.7, 0.837], [64560.3, 0.006], [64568.6, 0.0], [64573.0, 2.644], [64575.7, 0.028], [64587.7, 32.302], [64591.3, 0.004], [64600.9, 0.343], [64601.1, 1.714], [64601.2, 10.601], [64602.4, 0.562], [64602.5, 0.001], [64603.7, 0.082], [64614.0, 0.762], [64620.7, 0.123], [64622.3, 1.944], [64622.4, 3.407], [64624.1, 0.0], [64624.6, 0.011], [64624.8, 6.368], [64625.0, 1.59], [64625.1, 0.0], [64625.6, 1.114], [64626.5, 0.1], [64626.7, 2.831], [64626.9, 0.823], [64627.2, 0.042], [64631.1, 0.311], [64632.1, 0.004], [64633.7, 0.63], [64635.2, 1.169], [64635.5, 0.033], [64636.9, 0.756], [64637.1, 0.0], [64637.5, 0.023], [64638.4, 1.067], [64639.3, 0.084], [64639.9, 2.221], [64640.5, 0.022], [64640.6, 0.001], [64641.4, 0.006], [64642.8, 0.212], [64644.4, 0.001], [64645.0, 6.045], [64645.1, 0.052], [64646.1, 0.019], [64646.7, 0.0], [64648.0, 1.293], [64648.2, 0.005], [64648.3, 0.008], [64648.5, 1.946], [64648.9, 0.004], [64649.3, 0.015], [64650.9, 0.025], [64653.6, 2.134], [64653.8, 0.033], [64654.0, 0.002], [64654.2, 0.0], [64655.3, 0.083], [64656.4, 0.0], [64657.5, 0.01], [64658.2, 0.001], [64658.4, 0.0], [64658.6, 0.377], [64659.3, 0.503], [64659.4, 0.403], [64660.4, 0.0], [64660.9, 0.037], [64661.0, 0.117], [64661.1, 0.107], [64661.8, 1.69], [64662.0, 0.034], [64662.6, 0.12], [64663.3, 0.075], [64663.8, 0.002], [64664.0, 1.193], [64664.2, 0.075], [64664.3, 0.04], [64664.4, 0.001], [64665.4, 1.313], [64665.8, 2.497], [64666.2, 0.329], [64666.6, 0.06], [64666.9, 0.325], [64667.0, 0.004], [64667.3, 3.07], [64667.5, 0.024], [64667.6, 0.683], [64667.7, 0.071], [64668.2, 2.21], [64669.1, 0.086], [64669.5, 0.143], [64669.9, 0.851], [64670.2, 0.378], [64670.3, 0.347], [64670.4, 1.242], [64670.5, 0.696], [64670.7, 0.164], [64670.8, 0.02], [64671.2, 0.052], [64671.3, 0.013], [64671.8, 0.474], [64671.9, 2.628], [64672.2, 0.006], [64672.5, 0.102], [64672.7, 0.024], [64672.8, 0.375], [64672.9, 0.017], [64673.0, 0.684], [64673.2, 0.116], [64673.4, 0.0], [64674.0, 0.127], [64674.2, 0.001], [64674.4, 0.006], [64674.5, 0.003], [64674.8, 1.197], [64674.9, 0.137], [64675.1, 0.114], [64675.2, 0.053], [64675.4, 0.16], [64675.5, 0.005], [64675.9, 0.195], [64676.1, 0.022], [64676.4, 1.637], [64676.7, 0.002], [64676.9, 0.311], [64677.1, 0.142], [64677.2, 2.326], [64677.4, 0.342], [64677.5, 0.002], [64677.6, 0.004], [64677.8, 0.042], [64678.0, 0.133], [64678.1, 0.009], [64678.2, 0.022], [64678.4, 0.014], [64678.8, 0.441], [64679.0, 0.003], [64679.2, 0.0], [64679.3, 0.085], [64679.4, 0.946], [64679.9, 0.017], [64680.0, 1.785], [64680.1, 0.007], [64680.2, 1.169], [64680.4, 0.002], [64680.5, 0.002], [64680.6, 0.322], [64680.9, 0.313], [64681.0, 0.077], [64681.1, 0.349], [64681.2, 0.004], [64681.3, 0.002], [64681.4, 1.287], [64681.5, 1.247], [64681.6, 0.015], [64681.8, 0.187], [64681.9, 0.005], [64682.1, 0.777], [64682.3, 0.119], [64682.9, 0.002], [64683.0, 0.001], [64683.1, 2.321], [64683.2, 0.01], [64683.3, 0.116], [64683.4, 0.245], [64683.5, 0.06], [64683.8, 0.03], [64683.9, 0.311], [64684.0, 0.008], [64684.2, 0.005], [64684.3, 0.009], [64684.4, 0.101], [64684.6, 0.002], [64684.8, 0.008], [64685.0, 0.015], [64685.1, 0.485], [64685.4, 0.036], [64685.5, 0.005], [64685.6, 0.002], [64685.7, 2.605], [64685.8, 0.208], [64686.0, 0.009], [64686.1, 0.003], [64686.4, 0.001], [64686.8, 0.149], [64687.0, 1.07], [64687.2, 0.044], [64687.3, 0.001], [64687.4, 0.542], [64687.5, 0.0], [64687.6, 0.005], [64687.7, 0.238], [64687.8, 0.074], [64687.9, 1.126], [64688.0, 2.15], [64688.1, 1.896], [64688.3, 0.0], [64688.4, 0.002], [64688.5, 0.084], [64688.6, 0.004], [64688.8, 0.004], [64688.9, 0.002], [64689.0, 0.311], [64689.1, 0.084], [64689.2, 0.005], [64689.3, 0.333], [64689.5, 0.085], [64689.6, 0.241], [64689.8, 0.051], [64689.9, 0.317], [64690.0, 0.008], [64690.1, 0.158], [64690.3, 0.002], [64690.4, 0.002], [64690.5, 0.003], [64690.8, 0.062], [64691.0, 0.085], [64691.2, 0.448], [64691.3, 0.141], [64691.4, 0.156], [64691.5, 0.155], [64691.6, 0.2], [64691.7, 0.39], [64691.9, 0.103], [64692.0, 0.265], [64692.1, 0.041], [64692.2, 0.07], [64692.3, 0.002], [64692.4, 0.116], [64692.5, 0.003], [64692.6, 0.055], [64692.7, 1.92], [64692.8, 0.119], [64692.9, 0.0], [64693.2, 0.001], [64693.3, 0.106], [64693.4, 0.121], [64693.5, 0.356], [64693.6, 0.001], [64693.7, 0.034], [64693.8, 0.003], [64693.9, 0.0], [64694.0, 0.002], [64694.1, 0.0], [64694.3, 0.002], [64694.4, 0.003], [64694.5, 0.002], [64694.6, 0.0], [64694.7, 0.049], [64694.8, 0.001], [64695.1, 0.004], [64695.3, 0.001], [64695.5, 0.156], [64695.6, 0.0], [64695.7, 0.17], [64695.8, 0.001], [64695.9, 0.276], [64696.2, 0.076], [64696.3, 0.0], [64696.5, 0.0], [64696.6, 0.002], [64696.7, 0.003], [64696.8, 8.77], [64696.9, 0.0], [64697.0, 0.0], [64697.1, 0.0], [64697.2, 0.0], [64697.3, 0.0], [64697.4, 0.0], [64697.5, 0.0], [64697.6, 0.0], [64697.7, 0.0], [64697.9, 0.0], [64698.0, 0.0], [64698.3, 0.0], [64698.7, 0.0], [64699.1, 0.0], [64699.2, 0.0], [64699.3, 0.0], [64699.4, 0.0], [64699.6, 0.0], [64699.7, 0.0], [64699.8, 0.0]], "asks": [[64696.9, 13.363], [64697.0, 0.005], [64697.1, 0.02], [64697.2, 0.0], [64697.3, 0.0], [64697.4, 0.0], [64697.5, 0.001], [64697.6, 0.001], [64697.7, 0.0], [64697.8, 0.001], [64697.9, 0.0], [64698.0, 0.441], [64698.1, 0.0], [64698.2, 0.001], [64698.3, 0.001], [64698.4, 0.001], [64698.5, 0.001], [64698.8, 0.0], [64698.9, 0.054], [64699.0, 0.002], [64699.1, 2.351], [64699.2, 0.28], [64699.3, 0.095], [64699.4, 2.319], [64699.5, 0.37], [64699.6, 0.101], [64699.7, 0.157], [64699.8, 2.52], [64699.9, 4.875], [64700.0, 0.942], [64700.2, 0.026], [64700.3, 1.049], [64700.6, 0.085], [64700.7, 0.0], [64700.9, 0.01], [64701.0, 0.004], [64701.2, 0.629], [64701.3, 1.179], [64701.4, 0.314], [64701.5, 0.005], [64701.6, 0.084], [64701.8, 0.156], [64701.9, 0.035], [64702.2, 0.043], [64702.5, 0.009], [64702.6, 0.124], [64702.7, 0.001], [64702.8, 2.418], [64703.1, 0.088], [64703.4, 0.007], [64703.5, 0.006], [64703.7, 0.0], [64703.8, 0.213], [64703.9, 0.137], [64704.1, 0.028], [64704.2, 0.063], [64704.3, 0.008], [64704.5, 0.817], [64704.6, 0.249], [64704.8, 0.007], [64705.1, 0.505], [64705.6, 0.316], [64705.7, 1.238], [64705.8, 2.321], [64705.9, 0.041], [64706.1, 0.211], [64706.2, 0.702], [64706.4, 0.004], [64706.5, 0.001], [64706.9, 0.017], [64707.2, 0.086], [64707.3, 0.35], [64707.4, 1.467], [64707.6, 0.156], [64707.8, 0.524], [64708.0, 1.159], [64708.2, 0.103], [64708.3, 0.258], [64708.4, 0.233], [64708.7, 0.225], [64709.5, 0.254], [64709.6, 0.155], [64709.7, 0.004], [64709.9, 0.485], [64710.0, 0.608], [64710.1, 0.001], [64710.2, 0.026], [64710.3, 0.168], [64710.5, 0.024], [64710.6, 0.01], [64710.8, 0.327], [64710.9, 0.002], [64711.2, 0.464], [64711.3, 0.168], [64711.6, 0.092], [64711.8, 0.0], [64711.9, 0.002], [64712.1, 0.002], [64712.4, 0.001], [64712.5, 1.247], [64712.6, 0.004], [64712.7, 1.204], [64712.8, 1.337], [64712.9, 1.92], [64713.4, 0.012], [64713.5, 0.31], [64713.6, 0.149], [64713.9, 0.038], [64714.1, 0.06], [64714.3, 0.556], [64714.4, 0.537], [64714.6, 0.0], [64714.7, 0.174], [64715.1, 0.044], [64715.2, 2.653], [64715.4, 0.532], [64715.5, 0.064], [64715.7, 0.131], [64715.8, 0.001], [64715.9, 0.021], [64716.0, 1.082], [64716.3, 0.26], [64716.4, 6.118], [64716.6, 0.011], [64716.7, 0.011], [64716.8, 0.459], [64716.9, 0.001], [64717.0, 0.578], [64717.1, 0.331], [64717.4, 0.014], [64717.6, 1.82], [64717.7, 0.233], [64717.9, 0.094], [64718.0, 0.001], [64718.1, 0.005], [64718.3, 0.675], [64718.4, 1.287], [64718.9, 0.073], [64719.0, 0.025], [64719.1, 0.037], [64719.2, 0.002], [64719.3, 0.316], [64719.4, 0.004], [64719.5, 1.238], [64719.6, 0.116], [64720.0, 2.19], [64720.2, 0.001], [64720.7, 0.099], [64721.2, 0.026], [64721.3, 0.17], [64721.7, 11.015], [64722.2, 0.013], [64722.4, 1.632], [64723.2, 0.06], [64723.5, 0.0], [64723.6, 0.435], [64725.0, 0.004], [64725.1, 0.635], [64725.5, 0.0], [64725.9, 0.009], [64726.1, 0.248], [64726.3, 0.364], [64727.3, 0.372], [64727.9, 0.001], [64728.1, 0.57], [64728.3, 0.003], [64728.5, 0.0], [64728.8, 0.357], [64729.6, 0.027], [64730.0, 0.019], [64730.1, 0.103], [64732.0, 0.144], [64732.6, 0.093], [64732.7, 1.561], [64733.1, 0.001], [64733.5, 0.03], [64737.1, 0.25], [64737.4, 3.547], [64739.0, 0.932], [64739.2, 1.553], [64740.3, 0.049], [64740.9, 0.0], [64741.4, 0.5], [64741.5, 0.025], [64742.2, 0.001], [64743.2, 1.596], [64743.7, 0.031], [64748.4, 3.742], [64748.5, 0.0], [64749.0, 0.011], [64750.1, 0.026], [64750.3, 0.002], [64750.4, 1.376], [64750.9, 0.001], [64752.8, 0.002], [64754.2, 0.002], [64756.0, 1.472], [64756.1, 3.814], [64756.3, 0.166], [64756.4, 0.0], [64757.9, 0.094], [64758.8, 0.236], [64759.2, 1.237], [64760.5, 6.228], [64760.8, 0.5], [64762.1, 0.049], [64762.5, 0.003], [64764.6, 0.005], [64765.7, 1.237], [64766.6, 0.013], [64767.9, 0.009], [64768.5, 0.032], [64768.9, 0.102], [64770.6, 0.391], [64771.3, 0.2], [64772.2, 1.099], [64772.3, 1.251], [64773.2, 0.003], [64773.7, 0.503], [64775.4, 0.437], [64776.0, 3.771], [64777.1, 0.002], [64778.6, 0.211], [64780.0, 0.042], [64781.0, 9.711], [64781.1, 40.987], [64781.7, 0.026], [64788.4, 0.026], [64798.9, 0.0], [64799.1, 0.003], [64809.9, 0.004], [64812.5, 0.004], [64836.4, 0.0], [64854.8, 2.18], [64893.2, 6.492], [64895.7, 0.001], [64899.7, 3.248], [64983.4, 1.64], [64983.8, 6.059], [65029.1, 0.115], [65038.2, 0.001], [65217.5, 6.456], [65343.9, 0.0], [65346.9, 4.492], [65476.2, 0.335], [65993.8, 0.05]]}
{"kind": "depth", "E": 1787080337597, "U": 11315347420967, "u": 11315347436570, "recv_ms": 1787080337618, "bids": [[1000.0, 35.81], [14296.8, 0.476], [14399.8, 1.932], [51758.0, 0.0], [58227.1, 0.002], [61461.9, 0.0], [62111.8, 2.584], [63402.9, 0.901], [63696.8, 0.02], [63920.4, 0.702], [64049.8, 0.0], [64149.2, 0.001], [64179.3, 0.007], [64373.3, 0.003], [64376.3, 6.959], [64513.3, 0.001], [64514.9, 1.356], [64517.6, 0.001], [64520.8, 0.001], [64563.4, 4.723], [64565.7, 2.438], [64573.4, 2.32], [64578.5, 0.802], [64583.9, 0.006], [64587.7, 0.016], [64592.0, 33.549], [64598.6, 10.659], [64599.9, 0.01], [64601.2, 0.079], [64601.4, 2.32], [64603.4, 0.108], [64616.0, 3.437], [64621.1, 0.046], [64621.2, 0.282], [64622.7, 0.001], [64624.8, 6.342], [64628.8, 1.119], [64630.8, 0.263], [64631.4, 1.485], [64631.5, 0.112], [64635.6, 0.234], [64637.2, 0.024], [64637.4, 0.0], [64638.5, 0.005], [64641.8, 0.027], [64642.8, 0.002], [64645.2, 2.133], [64645.3, 1.47], [64647.5, 0.041], [64648.7, 0.04], [64649.4, 1.716], [64649.8, 0.004], [64650.3, 0.0], [64651.1, 0.351], [64651.2, 1.198], [64652.9, 0.167], [64653.5, 2.204], [64653.6, 0.213], [64654.3, 0.06], [64654.5, 0.005], [64655.1, 0.36], [64655.3, 0.069], [64655.7, 0.17], [64655.8, 0.029], [64656.3, 0.003], [64656.9, 0.389], [64657.5, 0.011], [64657.6, 1.439], [64657.9, 0.017], [64660.0, 0.315], [64660.1, 4.649], [64660.2, 0.006], [64660.5, 0.017], [64660.8, 1.182], [64661.8, 3.819], [64661.9, 0.92], [64662.6, 0.0], [64664.0, 1.223], [64666.4, 0.196], [64667.2, 1.154], [64667.3, 3.123], [64667.5, 0.014], [64669.9, 0.802], [64670.0, 1.594], [64670.4, 1.77], [64670.5, 0.248], [64670.6, 0.162], [64672.9, 0.171], [64673.3, 0.503], [64674.0, 0.131], [64674.5, 0.56], [64675.1, 0.034], [64676.1, 0.024], [64676.8, 3.78], [64677.1, 0.189], [64678.4, 0.014], [64678.6, 0.002], [64678.7, 2.358], [64680.2, 1.037], [64680.3, 2.324], [64680.4, 0.124], [64680.6, 0.666], [64680.7, 0.616], [64680.8, 0.021], [64681.4, 1.288], [64681.6, 0.016], [64681.9, 0.216], [64682.0, 0.375], [64682.2, 0.485], [64682.3, 0.019], [64683.0, 0.901], [64683.2, 0.001], [64684.1, 0.814], [64684.2, 0.003], [64684.4, 0.081], [64684.8, 0.009], [64684.9, 0.001], [64685.5, 0.003], [64685.7, 2.481], [64686.0, 0.005], [64686.2, 0.312], [64686.8, 0.147], [64687.6, 0.003], [64688.0, 2.151], [64688.1, 0.046], [64688.2, 0.085], [64688.3, 2.32], [64688.4, 1.844], [64688.5, 0.471], [64688.6, 0.632], [64688.9, 0.002], [64689.1, 1.34], [64689.2, 0.562], [64689.4, 0.01], [64689.5, 0.085], [64689.6, 0.412], [64689.7, 0.188], [64689.8, 0.052], [64689.9, 0.085], [64690.0, 0.007], [64690.3, 0.0], [64690.4, 0.001], [64691.1, 0.247], [64691.2, 0.131], [64691.7, 0.202], [64693.5, 0.311], [64693.8, 0.087], [64694.2, 0.011], [64694.3, 0.003], [64694.4, 0.004], [64694.8, 0.0], [64696.7, 0.006], [64696.8, 9.385]], "asks": [[64696.9, 14.905], [64697.0, 0.004], [64697.1, 0.0], [64697.4, 0.002], [64697.6, 0.001], [64698.6, 0.084], [64698.9, 0.054], [64699.0, 0.258], [64699.1, 2.201], [64699.2, 0.281], [64699.6, 0.102], [64699.7, 0.002], [64699.8, 2.508], [64699.9, 4.045], [64700.0, 1.798], [64700.2, 0.027], [64700.4, 0.001], [64700.8, 0.01], [64701.0, 0.005], [64701.2, 0.001], [64701.3, 0.831], [64702.3, 0.007], [64702.8, 2.416], [64703.1, 0.004], [64703.4, 0.009], [64703.8, 0.129], [64703.9, 0.136], [64704.5, 1.121], [64704.8, 0.007], [64705.3, 0.015], [64705.6, 0.332], [64706.4, 0.002], [64706.9, 0.327], [64707.0, 1.394], [64707.3, 0.04], [64708.4, 0.225], [64709.8, 0.005], [64709.9, 0.477], [64710.1, 0.003], [64710.3, 0.013], [64710.6, 0.003], [64711.2, 0.001], [64711.5, 0.179], [64711.6, 0.555], [64711.8, 0.217], [64712.1, 0.002], [64712.7, 1.203], [64714.8, 0.118], [64715.1, 0.042], [64715.5, 0.066], [64715.7, 0.131], [64716.3, 0.189], [64717.4, 0.015], [64718.4, 2.281], [64719.3, 0.314], [64719.5, 1.242], [64720.0, 3.803], [64720.2, 0.041], [64721.7, 10.012], [64722.8, 0.003], [64723.1, 0.642], [64728.2, 0.037], [64730.9, 0.161], [64732.0, 0.174], [64732.2, 0.004], [64735.0, 0.003], [64736.0, 2.676], [64736.5, 0.025], [64737.9, 0.023], [64741.6, 0.002], [64742.2, 0.0], [64743.2, 1.536], [64743.7, 0.006], [64744.3, 4.285], [64744.4, 0.0], [64748.7, 0.027], [64751.6, 0.28], [64755.1, 0.047], [64755.9, 0.077], [64756.5, 0.089], [64758.3, 0.0], [64758.4, 1.192], [64758.8, 0.026], [64759.5, 0.038], [64760.5, 0.228], [64761.1, 0.011], [64761.3, 0.005], [64761.6, 0.815], [64763.2, 1.179], [64764.8, 0.251], [64768.5, 0.006], [64771.3, 0.229], [64772.3, 42.234], [64774.5, 0.091], [64781.0, 0.204], [64781.1, 0.004], [64784.2, 0.027], [64785.6, 1.255], [64790.7, 2.439], [64792.9, 0.171], [64795.1, 2.133], [64795.2, 4.139], [64799.9, 2.413], [64803.5, 2.133], [64804.2, 0.452], [64804.3, 0.025], [64811.8, 2.535], [64814.5, 0.448], [64814.6, 0.003], [64817.8, 1.888], [64822.0, 4.642], [64824.8, 0.824], [64824.9, 0.0], [64825.9, 1.466], [64826.0, 0.029], [64839.8, 3.784], [64839.9, 5.398], [64853.7, 1.465], [64853.8, 0.0], [64875.3, 0.0], [65023.4, 5.077], [65343.9, 0.0], [65696.9, 0.03], [67931.7, 0.005]]}
{"kind": "depth", "E": 1787080337699, "U": 11315347436802, "u": 11315347446921, "recv_ms": 1787080337651, "bids": [[14296.8, 0.84], [14399.8, 1.568], [51758.0, 0.0], [58227.1, 0.004], [61461.9, 0.0], [62108.9, 0.006], [63903.3, 4.178], [64049.2, 0.39], [64049.8, 0.001], [64052.2, 0.054], [64572.6, 0.086], [64592.0, 1.263], [64600.3, 0.215], [64600.4, 0.003], [64618.5, 32.291], [64619.1, 0.004], [64634.1, 0.001], [64647.9, 0.026], [64648.9, 0.0], [64650.6, 0.117], [64652.5, 1.982], [64654.5, 0.004], [64660.3, 0.004], [64666.8, 0.026], [64667.3, 3.113], [64670.9, 0.026], [64673.0, 0.569], [64673.2, 0.0], [64674.0, 0.127], [64674.3, 0.631], [64675.9, 0.08], [64676.3, 0.12], [64677.4, 0.343], [64679.4, 0.02], [64679.5, 0.025], [64679.9, 0.943], [64680.7, 0.616], [64681.8, 0.18], [64683.5, 0.067], [64684.1, 0.812], [64684.4, 0.082], [64685.4, 0.034], [64685.8, 0.332], [64686.2, 0.314], [64686.7, 1.084], [64688.2, 0.008], [64688.5, 0.0], [64688.9, 0.004], [64689.2, 0.562], [64689.3, 0.333], [64689.4, 0.55], [64689.5, 0.093], [64689.7, 0.0], [64694.2, 0.095], [64696.8, 9.5]], "asks": [[64696.9, 15.139], [64698.1, 0.001], [64698.6, 0.0], [64699.0, 0.255], [64699.2, 0.284], [64699.3, 0.114], [64699.5, 0.392], [64699.8, 2.505], [64699.9, 4.035], [64700.0, 1.779], [64700.2, 0.004], [64702.2, 0.006], [64703.0, 0.014], [64703.1, 0.008], [64704.3, 0.004], [64705.1, 0.506], [64705.6, 0.409], [64705.8, 2.393], [64706.9, 0.327], [64707.2, 0.009], [64708.0, 0.259], [64710.1, 0.095], [64710.8, 0.133], [64711.5, 0.179], [64711.6, 0.084], [64712.1, 0.473], [64712.7, 1.088], [64714.3, 0.0], [64714.4, 0.465], [64714.9, 2.527], [64715.8, 0.557], [64716.3, 0.183], [64717.0, 0.463], [64717.9, 0.002], [64718.1, 0.012], [64721.9, 0.003], [64722.0, 0.496], [64727.1, 0.0], [64730.8, 0.156], [64732.1, 0.001], [64734.0, 0.006], [64737.0, 0.0], [64737.7, 0.117], [64738.8, 3.613], [64739.8, 0.005], [64740.4, 0.002], [64741.0, 0.001], [64760.6, 0.023], [64761.1, 0.001], [64891.4, 0.003], [64891.5, 0.013], [65217.5, 10.283], [65343.9, 0.0], [65444.3, 5.519], [65444.5, 2.457], [65444.6, 7.326], [65509.0, 6.989], [65509.2, 1.518]]}
{"kind": "depth", "E": 1787080337801, "U": 11315347447082, "u": 11315347464886, "recv_ms": 1787080337753, "bids": [[1000.0, 35.81], [14296.8, 1.19], [14399.8, 1.218], [51758.0, 0.0], [58227.1, 0.002], [61461.9, 0.0], [63696.8, 0.0], [64049.8, 0.001], [64618.5, 0.005], [64620.6, 34.656], [64673.9, 0.278], [64676.1, 0.022], [64677.7, 0.006], [64685.8, 0.773], [64688.2, 0.001], [64689.4, 0.55], [64689.5, 0.009], [64689.6, 0.288], [64689.7, 0.131], [64689.8, 0.051], [64690.0, 0.008], [64690.1, 0.004], [64690.9, 0.001], [64691.2, 0.131], [64694.5, 0.001], [64694.6, 0.084], [64696.4, 0.002], [64696.8, 9.516]], "asks": [[64696.9, 15.097], [64697.9, 0.043], [64699.0, 0.002], [64699.1, 1.68], [64699.2, 0.281], [64699.3, 0.03], [64699.7, 0.002], [64699.8, 2.515], [64699.9, 4.034], [64700.3, 1.052], [64701.8, 0.002], [64703.1, 0.246], [64704.1, 0.027], [64705.5, 0.008], [64705.6, 0.639], [64705.7, 1.239], [64706.9, 0.017], [64710.6, 0.001], [64711.0, 0.31], [64711.3, 0.166], [64711.5, 0.024], [64711.6, 0.084], [64711.8, 0.21], [64711.9, 0.0], [64712.6, 0.002], [64712.7, 0.163], [64713.0, 0.007], [64713.3, 0.925], [64715.5, 0.064], [64716.6, 0.013], [64720.0, 2.19], [64721.7, 0.012], [64723.3, 1.279], [64724.4, 10.004], [64739.5, 3.801], [64762.1, 6.049], [64766.8, 0.442], [64794.4, 0.013], [64794.5, 10.002], [64795.1, 2.125], [64892.2, 0.216], [64894.9, 1.547], [65343.9, 0.0], [65420.8, 1.298], [65444.5, 3.365], [65444.6, 6.41], [65513.4, 2.288], [65696.9, 0.01]]}
{"kind": "depth", "E": 1787080337903, "U": 11315347464965, "u": 11315347474017, "recv_ms": 1787080337853, "bids": [[1000.0, 35.81], [14296.8, 1.554], [14399.8, 0.854], [58227.1, 0.002], [62108.9, 0.003], [64049.8, 0.001], [64133.9, 4.436], [64373.3, 0.004], [64376.3, 6.949], [64666.4, 0.206], [64666.8, 0.016], [64674.4, 0.008], [64674.7, 0.011], [64677.6, 0.003], [64678.4, 0.022], [64681.5, 1.248], [64689.5, 0.009], [64689.7, 0.341], [64689.8, 0.052], [64690.2, 0.156], [64690.3, 0.0], [64690.4, 0.009], [64690.9, 0.0], [64691.5, 0.161], [64692.4, 0.121], [64693.1, 0.037]], "asks": [[64696.9, 15.1], [64699.0, 0.006], [64699.1, 1.679], [64699.3, 0.19], [64699.8, 2.514], [64699.9, 4.029], [64700.6, 0.091], [64701.8, 0.01], [64705.4, 0.159], [64705.5, 0.0], [64705.6, 0.794], [64706.9, 0.327], [64711.3, 0.174], [64711.6, 0.239], [64760.2, 0.07], [64760.6, 0.013], [64764.2, 0.024], [64915.1, 0.014], [64933.9, 0.0], [65023.4, 5.076], [65343.9, 0.0], [65441.6, 2.726], [65444.5, 0.641], [65506.3, 0.806], [65509.2, 0.762]]}
{"kind": "depth", "E": 1787080338005, "U": 11315347474237, "u": 11315347481611, "recv_ms": 1787080337957, "bids": [[14296.8, 1.904], [14399.8, 0.504], [58227.1, 0.002], [61461.9, 0.0], [62108.9, 0.006], [63696.8, 0.02], [64049.8, 0.001], [64155.6, 0.325], [64571.3, 0.115], [64663.3, 0.018], [64664.7, 0.057], [64666.0, 3.113], [64666.4, 0.196], [64667.0, 0.002], [64689.7, 0.341], [64693.6, 0.002], [64695.9, 0.278], [64696.5, 0.001], [64696.6, 0.0], [64696.7, 0.005], [64696.8, 9.536]], "asks": [[64696.9, 15.102], [64698.3, 0.02], [64699.3, 0.035], [64699.9, 4.026], [64703.9, 0.003], [64705.4, 0.004], [64705.6, 0.639], [64706.9, 0.017], [64711.6, 0.084], [64716.0, 1.025], [64716.6, 0.07], [64717.6, 0.001], [64719.7, 0.004], [64738.4, 0.004], [64759.8, 2.334], [64760.2, 0.06], [64766.8, 0.46], [65022.1, 0.13], [65343.9, 0.0], [65441.6, 4.542], [65444.3, 3.703], [65506.3, 1.562], [65509.0, 6.233], [65696.9, 0.03]]}
{"kind": "depth", "E": 1787080338107, "U": 11315347481701, "u": 11315347488732, "recv_ms": 1787080338059, "bids": [[1000.0, 35.81], [14196.8, 0.168], [14296.8, 2.1], [14299.8, 1.624], [14399.8, 0.308], [58227.1, 0.002], [61461.9, 0.0], [62108.9, 0.003], [64049.8, 0.001], [64099.6, 1.333], [64613.6, 1.537], [64620.3, 2.32], [64620.5, 6.962], [64620.7, 0.122], [64627.5, 0.0], [64627.6, 0.035], [64627.7, 0.001], [64648.3, 0.009], [64657.1, 0.442], [64657.2, 0.001], [64657.3, 0.003], [64657.4, 0.001], [64685.2, 0.464], [64687.4, 0.001], [64688.7, 0.541], [64689.7, 0.341], [64690.2, 0.002], [64691.1, 0.015], [64691.7, 0.434], [64692.6, 0.209], [64695.5, 0.002]], "asks": [[64696.9, 15.105], [64699.3, 0.035], [64699.9, 4.004], [64700.0, 1.757], [64701.1, 0.15], [64704.2, 0.002], [64705.4, 0.004], [64705.6, 0.639], [64706.9, 0.017], [64711.6, 0.084], [64716.0, 1.029], [65343.9, 0.0], [65405.1, 6.022], [65441.6, 5.45], [65444.6, 5.494], [65990.8, 0.003]]}
{"kind": "depth", "E": 1787080338209, "U": 11315347488828, "u": 11315347495788, "recv_ms": 1787080338160, "bids": [[1000.0, 35.81], [14196.8, 0.406], [14296.8, 2.226], [14299.8, 1.386], [14399.8, 0.182], [51757.4, 0.0], [58227.1, 0.002], [61461.9, 0.0], [62108.9, 0.006], [63696.8, 0.0], [64049.8, 0.001], [64373.3, 0.014], [64576.5, 1.016], [64579.5, 0.556], [64583.6, 0.021], [64586.6, 0.006], [64590.6, 0.225], [64593.6, 1.259], [64597.7, 0.423], [64600.7, 0.579], [64604.7, 0.073], [64607.7, 0.0], [64611.8, 0.028], [64614.8, 0.0], [64618.8, 0.013], [64620.3, 2.319], [64621.8, 0.146], [64625.9, 0.014], [64628.9, 2.66], [64664.0, 1.28], [64664.7, 0.0], [64665.7, 0.171], [64665.8, 2.161], [64666.0, 3.103], [64670.6, 0.498], [64676.5, 0.008], [64676.8, 3.162], [64677.2, 2.319], [64682.9, 0.004], [64683.8, 0.028], [64687.1, 0.006], [64688.0, 2.692], [64688.7, 0.0], [64689.7, 0.131], [64689.8, 0.052], [64690.3, 0.0], [64690.4, 0.163], [64695.7, 0.001], [64696.8, 9.537]], "asks": [[64696.9, 16.318], [64697.0, 0.005], [64698.1, 0.0], [64699.3, 0.035], [64699.9, 2.733], [64703.7, 0.001], [64705.4, 0.004], [64705.5, 0.0], [64705.6, 0.639], [64706.9, 0.017], [64711.3, 0.166], [64711.5, 0.032], [64711.6, 0.084], [64716.3, 0.181], [64717.3, 0.003], [64717.4, 0.015], [64718.3, 0.675], [64723.1, 0.024], [64737.3, 0.006], [64759.6, 0.01], [64759.8, 2.324], [65343.9, 0.0], [65405.1, 6.708], [65420.8, 0.612], [65441.6, 6.358], [65444.6, 4.578], [65696.9, 0.01]]}
{"kind": "depth", "E": 1787080338311, "U": 11315347495801, "u": 11315347502303, "recv_ms": 1787080338262, "bids": [[14196.8, 0.644], [14296.8, 2.338], [14299.8, 1.148], [14399.8, 0.07], [51758.0, 0.0], [51760.0, 0.004], [58227.1, 0.002], [61464.9, 0.006], [63958.1, 0.0], [64049.8, 0.001], [64112.9, 1.331], [64673.7, 0.003], [64680.8, 0.023], [64690.2, 0.156], [64690.4, 0.009], [64695.8, 0.003]], "asks": [[64699.6, 0.104], [64699.8, 2.511], [64700.3, 1.055], [64703.1, 0.572], [64705.8, 2.918], [64713.3, 0.927], [64722.7, 2.823], [64729.2, 0.019], [65343.9, 0.0]]}
{"kind": "depth", "E": 1787080338413, "U": 11315347502424, "u": 11315347514282, "recv_ms": 1787080338370, "bids": [[1000.0, 35.81], [14196.8, 0.938], [14296.8, 2.408], [14299.8, 0.854], [14399.8, 0.0], [58227.1, 0.002], [62108.9, 0.003], [63625.0, 1.326], [63696.8, 0.02], [63888.2, 0.351], [64049.8, 0.001], [64599.3, 0.009], [64602.4, 0.557], [64621.2, 0.256], [64622.4, 3.433], [64665.5, 0.011], [64665.7, 0.161], [64678.1, 0.002], [64681.2, 0.011], [64689.7, 0.131], [64689.9, 0.001], [64693.5, 0.314], [64695.1, 0.004]], "asks": [[64699.0, 0.014], [64699.1, 1.663], [64699.3, 0.043], [64699.8, 2.504], [64700.5, 0.007], [64705.5, 0.008], [64705.6, 0.631], [64711.5, 0.024], [64711.6, 0.092], [64712.0, 0.011], [64712.1, 0.465], [64713.6, 0.154], [64716.6, 0.065], [64717.4, 0.015], [64718.3, 0.675], [64724.7, 0.121], [64732.0, 0.054], [64759.3, 0.01], [64759.6, 0.0], [64763.2, 1.153], [64764.4, 0.06], [64770.2, 0.628], [64772.3, 42.101], [64826.3, 0.0], [65343.9, 0.0], [65506.3, 2.318], [65509.3, 1.1], [65696.9, 0.03]]}
{"kind": "depth", "E": 1787080338515, "U": 11315347514406, "u": 11315347521175, "recv_ms": 1787080338465, "bids": [[1000.0, 35.81], [14196.8, 1.288], [14299.8, 0.504], [58227.1, 0.002], [61461.9, 0.0], [62108.9, 0.006], [63888.2, 0.585], [63939.9, 2.112], [64049.8, 0.001], [64373.3, 0.014], [64586.8, 0.007], [64601.1, 1.716], [64619.1, 0.001], [64641.4, 0.003], [64654.5, 0.001], [64657.9, 0.003], [64670.9, 0.043], [64677.1, 0.204], [64679.9, 0.017], [64680.8, 0.641], [64681.1, 1.275], [64683.8, 0.032], [64684.3, 0.005], [64686.0, 0.009], [64686.2, 0.005], [64688.4, 2.153], [64689.8, 0.051], [64691.2, 0.19], [64691.9, 0.104], [64695.3, 0.003], [64696.8, 11.471]], "asks": [[64696.9, 16.381], [64698.3, 0.022], [64699.3, 0.193], [64699.6, 0.188], [64699.8, 2.505], [64699.9, 2.732], [64700.9, 0.07], [64703.7, 0.0], [64705.5, 0.318], [64706.9, 0.327], [64709.5, 0.269], [64711.6, 0.247], [64716.0, 1.044], [64716.6, 5.065], [64717.4, 0.015], [64718.3, 0.675], [64719.4, 0.004], [64719.6, 0.001], [64720.3, 0.2], [64746.2, 1.564], [64758.2, 0.018], [64766.8, 0.442], [64809.9, 0.001], [64966.5, 0.004], [64968.0, 0.84], [65343.9, 0.0], [65441.6, 7.266], [65444.6, 3.662], [65508.6, 17.023], [65993.8, 0.047], [67931.7, 0.01]]}
{"kind": "depth", "E": 1787080338617, "U": 11315347521290, "u": 11315347527179, "recv_ms": 1787080338570, "bids": [[14196.8, 1.638], [14299.8, 0.154], [51758.0, 0.0], [58227.1, 0.002], [62108.9, 0.003], [63609.9, 0.673], [63696.8, 0.0], [64049.8, 0.001], [64373.3, 0.013], [64665.3, 0.032], [64665.5, 0.001], [64673.5, 0.622], [64690.2, 0.002], [64694.3, 0.002]], "asks": [[64697.9, 0.0], [64698.8, 0.043], [64699.2, 0.304], [64699.3, 0.038], [64700.0, 1.756], [64705.5, 0.008], [64706.9, 0.017], [64711.6, 0.092], [64712.4, 0.619], [64719.8, 1.499], [64757.9, 0.096], [64759.1, 0.01], [64759.3, 0.0], [65020.4, 0.001], [65343.9, 0.0], [65441.6, 8.174], [65444.6, 2.747], [65696.9, 0.01]]}
{"kind": "depth", "E": 1787080338719, "U": 11315347527487, "u": 11315347534831, "recv_ms": 1787080338670, "bids": [[1000.0, 35.81], [14196.8, 2.002], [14296.8, 2.198], [14299.8, 0.0], [51758.0, 0.0], [58227.1, 0.002], [63826.1, 0.0], [64049.8, 0.0], [64665.2, 0.012], [64665.3, 0.022], [64681.6, 0.018], [64683.5, 0.06], [64684.7, 0.01], [64690.4, 0.163]], "asks": [[64700.3, 1.052], [64700.7, 0.003], [64759.0, 0.385], [64759.1, 0.0], [64814.9, 0.003], [65343.9, 0.0], [65467.6, 14.001], [65521.2, 6.145], [65990.8, 0.006]]}
{"kind": "depth", "E": 1787080338821, "U": 11315347535128, "u": 11315347543727, "recv_ms": 1787080338772, "bids": [[1000.0, 35.81], [14196.8, 2.352], [14296.8, 1.848], [58227.1, 0.002], [62108.9, 0.006], [63405.9, 0.071], [63696.8, 0.02], [64049.8, 0.0], [64373.3, 0.013], [64665.1, 0.972], [64665.2, 0.002], [64683.8, 0.032], [64690.4, 0.009]], "asks": [[64711.3, 0.168], [64758.9, 0.032], [64759.0, 0.375], [64892.7, 3.808], [64893.2, 0.004], [65343.9, 0.0], [65469.8, 8.235], [65696.9, 0.03]]}
{"kind": "depth", "E": 1787080338923, "U": 11315347543809, "u": 11315347550812, "recv_ms": 1787080338876, "bids": [[14196.8, 2.716], [14296.8, 1.484], [58227.1, 0.002], [61461.9, 0.0], [62108.9, 0.003], [63807.9, 4.225], [64049.8, 0.0], [64373.3, 0.012], [64639.3, 0.038], [64645.4, 0.015], [64660.5, 0.003], [64660.9, 0.023], [64665.0, 1.32], [64665.1, 0.962], [64667.1, 0.309], [64689.5, 0.012], [64690.2, 0.156], [64691.7, 0.202], [64692.1, 0.022], [64692.3, 0.045], [64696.8, 11.473]], "asks": [[64696.9, 16.329], [64697.0, 0.007], [64699.3, 0.038], [64700.0, 1.757], [64705.5, 0.008], [64706.2, 0.393], [64706.9, 0.326], [64711.6, 0.092], [64712.4, 0.001], [64716.6, 0.065], [64758.8, 0.036], [64758.9, 0.022], [64766.8, 0.451], [65343.9, 0.0], [65506.3, 3.83], [65509.0, 4.721]]}
{"kind": "depth", "E": 1787080339025, "U": 11315347550857, "u": 11315347556145, "recv_ms": 1787080338977, "bids": [[1000.0, 35.81], [14196.8, 3.08], [14296.8, 1.12], [58227.1, 0.002], [62108.9, 0.006], [63294.6, 0.002], [63297.4, 0.0], [63696.8, 0.0], [63975.1, 2.947], [64049.8, 0.0], [64117.8, 0.016], [64120.8, 0.0], [64278.1, 2.529], [64281.1, 2.596], [64373.3, 0.012], [64438.8, 0.148], [64441.8, 0.001], [64453.1, 0.0], [64488.4, 0.019], [64599.9, 0.012], [64602.9, 0.001], [64645.0, 6.091], [64682.3, 0.02], [64692.1, 0.0], [64693.0, 0.022]], "asks": [[64696.9, 16.328], [64697.8, 0.003], [64699.3, 0.038], [64705.5, 0.008], [64706.9, 0.326], [64711.6, 0.092], [64712.5, 1.567], [64715.0, 0.494], [64716.3, 0.164], [64718.0, 0.018], [64793.8, 1.086], [64796.8, 2.47], [64955.8, 0.015], [64958.8, 0.0], [65020.4, 0.002], [65118.2, 0.008], [65121.2, 0.001], [65281.0, 0.018], [65284.0, 2.299], [65343.9, 0.0], [65441.6, 9.082], [65444.6, 1.831], [65469.8, 9.15], [65476.3, 36.753], [65499.8, 4.842], [65506.3, 4.586], [65509.0, 3.965], [65696.9, 0.01]]}
{"kind": "depth", "E": 1787080339127, "U": 11315347556282, "u": 11315347569634, "recv_ms": 1787080339113, "bids": [[1000.0, 35.81], [14196.8, 3.43], [14296.8, 0.77], [58227.1, 0.002], [61461.9, 0.0], [62108.9, 0.003], [64049.8, 0.0], [64610.8, 0.007], [64617.6, 0.011], [64635.2, 1.137], [64635.5, 0.001], [64635.9, 0.022], [64636.2, 0.0], [64636.5, 0.0], [64648.2, 0.004], [64650.8, 0.004], [64650.9, 0.022], [64651.1, 0.349], [64654.3, 0.028], [64654.5, 0.004], [64654.6, 0.002], [64654.9, 2.319], [64655.0, 0.057], [64655.3, 0.037], [64655.6, 0.001], [64664.9, 2.772], [64665.0, 1.31], [64669.2, 0.124], [64669.3, 0.0], [64669.4, 0.002], [64669.5, 0.003], [64669.6, 0.022], [64669.7, 0.056], [64669.8, 0.003], [64669.9, 0.602], [64670.0, 1.524], [64670.2, 0.308], [64672.5, 0.002], [64673.0, 0.469], [64673.5, 0.004], [64677.1, 5.204], [64680.0, 2.711], [64680.8, 0.023], [64681.1, 0.349], [64683.6, 0.024], [64684.6, 0.003], [64685.2, 0.464], [64687.1, 0.005], [64690.1, 0.158], [64690.2, 0.002], [64690.9, 0.071], [64691.2, 0.12], [64691.3, 0.001], [64691.4, 0.016], [64691.5, 0.091], [64691.6, 0.0], [64691.7, 0.002], [64691.8, 0.0], [64691.9, 0.003], [64692.0, 0.095], [64692.2, 0.0], [64692.3, 0.002], [64692.4, 0.089], [64692.8, 0.087], [64692.9, 0.022], [64693.1, 0.037], [64693.4, 0.089], [64693.5, 0.333], [64693.7, 0.002], [64696.8, 11.474]], "asks": [[64696.9, 14.966], [64697.0, 0.006], [64697.5, 0.311], [64698.1, 0.001], [64699.1, 1.643], [64699.2, 0.281], [64699.3, 0.01], [64699.5, 0.37], [64699.8, 2.524], [64699.9, 2.693], [64700.1, 0.064], [64700.2, 0.004], [64700.7, 0.0], [64701.0, 0.008], [64701.2, 0.002], [64703.1, 0.418], [64704.0, 0.031], [64704.2, 0.156], [64705.5, 0.0], [64705.6, 0.106], [64706.6, 0.033], [64706.7, 0.003], [64706.9, 0.326], [64707.0, 1.362], [64707.3, 0.002], [64707.6, 0.118], [64708.0, 0.221], [64708.2, 0.005], [64708.4, 0.001], [64708.5, 0.466], [64708.6, 2.702], [64708.7, 0.005], [64708.8, 0.076], [64708.9, 0.234], [64709.0, 0.721], [64709.1, 0.001], [64709.2, 0.003], [64710.2, 0.026], [64710.3, 0.554], [64711.6, 0.092], [64712.9, 0.066], [64717.4, 0.015], [64718.2, 0.555], [64718.3, 0.134], [64719.8, 0.881], [64725.7, 0.041], [64726.1, 0.216], [64726.4, 0.007], [64726.7, 0.0], [64727.0, 3.757], [64727.4, 0.332], [64727.8, 0.001], [64729.1, 0.013], [64730.2, 0.0], [64730.4, 0.22], [64730.5, 0.964], [64730.6, 0.404], [64730.7, 0.001], [64730.8, 0.126], [64730.9, 0.007], [64731.0, 0.067], [64731.1, 0.466], [64731.2, 2.885], [64740.9, 0.042], [64743.5, 0.002], [64744.7, 0.099], [64744.8, 0.309], [64745.1, 1.004], [64745.5, 0.008], [64745.8, 0.036], [64746.1, 0.041], [64758.7, 0.034], [64758.8, 0.026], [64766.8, 0.442], [64769.4, 0.0], [64770.2, 0.628], [64772.3, 1.251], [64774.5, 40.769], [64790.6, 0.1], [64809.9, 0.004], [65343.1, 0.0], [65343.9, 0.002], [65441.6, 9.99], [65444.3, 2.795], [65467.6, 12.489], [65499.8, 4.613], [65602.7, 0.184], [65990.8, 0.009], [67931.7, 0.015]]}
{"kind": "depth", "E": 1787080339229, "U": 11315347569688, "u": 11315347576552, "recv_ms": 1787080339220, "bids": [[14196.8, 3.724], [14296.8, 0.448], [14596.8, 0.028], [51757.4, 0.0], [51758.0, 0.0], [58227.1, 0.002], [61461.9, 0.0], [63696.8, 0.02], [63888.1, 0.53], [64049.8, 0.0], [64472.4, 0.6], [64578.1, 2.32], [64578.2, 4.325], [64610.8, 0.008], [64624.6, 0.012], [64628.4, 0.046], [64628.6, 1.767], [64648.2, 0.0], [64648.3, 0.006], [64651.1, 0.348], [64651.2, 1.197], [64654.0, 0.034], [64654.2, 0.002], [64670.5, 0.378], [64680.6, 0.672], [64680.8, 0.021], [64689.7, 0.007], [64689.9, 0.125], [64690.1, 0.004], [64690.6, 0.073], [64690.8, 0.132], [64691.2, 0.19], [64692.2, 0.032], [64696.8, 11.472]], "asks": [[64696.9, 15.114], [64699.3, 0.01], [64699.9, 2.755], [64700.1, 0.002], [64701.2, 0.001], [64705.4, 0.004], [64705.5, 0.008], [64705.6, 0.639], [64706.9, 0.326], [64707.0, 2.262], [64707.6, 0.156], [64708.5, 0.543], [64708.9, 0.318], [64709.1, 0.071], [64710.2, 0.026], [64710.3, 0.013], [64711.4, 0.025], [64711.6, 0.092], [64713.3, 0.925], [64714.1, 0.08], [64716.7, 0.018], [64718.1, 0.005], [64720.0, 2.17], [64722.4, 1.632], [64726.6, 0.039], [64730.5, 1.041], [64730.9, 0.091], [64731.1, 0.536], [64740.8, 1.257], [64743.5, 0.016], [64745.7, 0.038], [64769.4, 0.009], [64770.1, 40.679], [64770.9, 0.048], [64771.0, 0.003], [64774.5, 0.091], [64813.3, 0.087], [64835.1, 8.092], [64835.2, 2.703], [64835.3, 0.0], [65343.9, 0.0], [65696.9, 0.03]]}
{"kind": "depth", "E": 1787080339331, "U": 11315347576678, "u": 11315347582030, "recv_ms": 1787080339283, "bids": [[1000.0, 35.81], [14196.8, 3.696], [14296.8, 0.28], [14596.8, 0.224], [58227.1, 0.002], [62108.9, 0.006], [62305.8, 0.0], [64049.8, 0.0], [64373.3, 0.002], [64653.7, 0.055], [64654.4, 1.199], [64654.7, 0.157], [64664.8, 0.048], [64664.9, 2.762], [64678.2, 0.04], [64680.8, 0.023], [64686.2, 0.003], [64689.2, 0.564], [64689.8, 0.205], [64689.9, 0.001], [64690.1, 0.004], [64690.2, 0.126], [64691.3, 0.201], [64691.5, 0.191], [64691.8, 0.032], [64692.5, 0.035], [64692.8, 0.119]], "asks": [[64699.7, 0.01], [64699.9, 2.693], [64700.1, 0.064], [64700.2, 0.004], [64705.0, 0.917], [64705.5, 0.0], [64706.9, 0.358], [64707.2, 0.047], [64707.9, 0.052], [64708.3, 0.398], [64708.4, 0.121], [64708.5, 0.663], [64713.3, 0.927], [64726.0, 2.357], [64726.3, 0.402], [64727.0, 3.795], [64727.4, 0.472], [64730.4, 0.46], [64745.1, 1.036], [64745.4, 0.351], [64746.0, 0.667], [64758.6, 0.01], [64758.7, 0.024], [64766.8, 0.451], [64769.4, 0.0], [64835.0, 0.025], [64849.9, 0.002], [64892.7, 3.654], [65327.5, 2.367], [65343.9, 0.0], [65441.6, 10.898], [65444.3, 1.887], [65506.3, 5.342], [65509.0, 3.209]]}
{"kind": "depth", "E": 1787080339433, "U": 11315347582101, "u": 11315347586221, "recv_ms": 1787080339384, "bids": [[1000.0, 35.81], [14196.8, 3.598], [14296.8, 0.154], [14596.8, 0.448], [34000.0, 1.146], [51758.0, 0.0], [58227.1, 0.002], [61464.9, 0.004], [62108.9, 0.003], [63696.8, 0.0], [63845.4, 0.0], [63882.5, 3.793], [63888.1, 0.686], [64049.8, 0.0], [64635.9, 0.054], [64664.7, 0.01], [64664.8, 0.038], [64678.4, 0.032], [64690.7, 0.142], [64690.8, 0.202], [64691.0, 0.285], [64691.1, 0.215], [64691.4, 0.086], [64691.6, 0.07]], "asks": [[64697.6, 0.003], [64708.2, 0.103], [64708.3, 0.482], [64708.6, 2.812], [64708.7, 0.245], [64708.8, 0.176], [64708.9, 0.409], [64709.0, 0.798], [64709.1, 0.148], [64712.6, 0.004], [64727.8, 0.131], [64730.1, 0.201], [64730.3, 0.108], [64730.6, 0.624], [64730.7, 0.101], [64730.9, 0.182], [64731.0, 0.221], [64743.5, 0.002], [64826.3, 0.0], [65217.5, 9.978], [65343.9, 0.0], [65473.3, 1.692], [65696.9, 0.01]]}
{"kind": "depth", "E": 1787080339535, "U": 11315347586356, "u": 11315347590776, "recv_ms": 1787080339486, "bids": [[14196.8, 3.458], [14296.8, 0.042], [14596.8, 0.7], [58227.1, 0.002], [61461.9, 0.0], [62108.9, 0.006], [64049.8, 0.0], [64559.9, 0.0], [64600.9, 6.469], [64620.6, 32.32], [64620.7, 7.28], [64635.0, 0.076], [64659.4, 0.587], [64668.9, 0.073], [64674.5, 1.178], [64677.1, 0.204], [64681.9, 0.834], [64695.8, 0.047]], "asks": [[64696.9, 15.158], [64697.6, 0.004], [64698.1, 0.0], [64698.4, 0.003], [64699.3, 0.01], [64699.9, 2.755], [64700.1, 0.002], [64704.4, 0.044], [64704.5, 1.575], [64705.5, 0.016], [64705.6, 0.639], [64706.9, 0.358], [64711.6, 0.084], [64712.0, 0.003], [64713.5, 0.928], [64717.4, 1.545], [64720.8, 0.621], [64724.9, 10.002], [64739.4, 1.415], [64740.0, 0.039], [64740.9, 0.0], [64766.8, 0.442], [64768.3, 6.93], [64793.8, 1.094], [64793.9, 3.575], [64794.4, 0.005], [64839.9, 0.0], [64967.9, 0.266], [65020.4, 0.001], [65343.9, 0.0], [65486.9, 3.94], [65506.3, 6.854], [65509.0, 1.697]]}
{"kind": "depth", "E": 1787080339637, "U": 11315347590880, "u": 11315347595715, "recv_ms": 1787080339588, "bids": [[1000.0, 35.81], [14196.8, 3.192], [14296.8, 0.0], [14596.8, 1.008], [58227.1, 0.002], [62108.9, 0.003], [63696.8, 0.02], [63785.4, 11.782], [64049.8, 0.0], [64182.2, 6.871], [64373.3, 0.003], [64634.6, 0.034], [64635.3, 0.441], [64635.6, 0.266], [64647.6, 0.693], [64668.7, 0.07], [64668.9, 0.143], [64669.2, 0.194], [64689.7, 0.008], [64690.9, 0.07], [64692.7, 0.0], [64693.4, 0.111], [64694.6, 0.0]], "asks": [[64699.9, 2.719], [64705.5, 0.0], [64706.7, 0.014], [64709.9, 0.466], [64712.0, 0.019], [64724.7, 0.275], [64726.3, 0.248], [64758.5, 0.015], [64758.6, 0.0], [64768.3, 0.893], [64770.1, 0.001], [64772.3, 41.929], [64774.5, 0.091], [65214.5, 0.305], [65343.9, 0.0], [65441.6, 10.898], [65444.6, 1.823], [65696.9, 0.03]]}
{"kind": "depth", "E": 1787080339739, "U": 11315347595783, "u": 11315347599702, "recv_ms": 1787080339690, "bids": [[1000.0, 35.81], [14196.8, 2.828], [14596.8, 1.372], [58227.1, 0.002], [63402.9, 0.904], [63853.4, 3.49], [64049.8, 0.0], [64179.2, 3.898], [64500.6, 0.204], [64501.1, 15.504], [64501.2, 7.216], [64504.1, 0.028], [64539.9, 7.921], [64540.7, 2.262], [64542.9, 1.246], [64556.9, 5.207], [64586.8, 0.004], [64641.5, 0.009], [64654.5, 0.001], [64668.8, 0.077], [64669.1, 0.186], [64669.3, 0.1], [64669.4, 0.172], [64672.4, 0.1]], "asks": [[64699.0, 0.098], [64724.7, 0.275], [64758.2, 0.018], [64809.9, 0.001], [64835.2, 3.46], [64836.9, 5.398], [64853.9, 10.778], [64854.8, 0.719], [64856.9, 0.0], [64892.7, 3.702], [65343.9, 0.0], [65441.6, 9.99], [65444.6, 2.731]]}
{"kind": "depth", "E": 1787080339841, "U": 11315347599763, "u": 11315347605864, "recv_ms": 1787080339791, "bids": [[14196.8, 2.478], [14596.8, 1.722], [51758.0, 0.0], [58227.1, 0.002], [61461.9, 0.0], [62108.9, 0.006], [63696.8, 0.0], [64049.8, 0.0], [64556.9, 4.677], [64668.7, 0.14], [64668.8, 0.147], [64669.0, 0.101], [64669.2, 0.294], [64669.6, 0.092], [64672.0, 0.108], [64696.8, 11.473]], "asks": [[64699.3, 0.01], [64699.9, 2.658], [64704.4, 0.044], [64705.6, 0.639], [64706.9, 0.358], [64711.6, 0.084], [64712.7, 0.165], [64716.5, 0.006], [64724.7, 0.121], [64724.8, 1.396], [64724.9, 0.002], [64766.8, 0.451], [64770.2, 41.306], [64772.3, 1.251], [64813.3, 0.001], [64835.2, 2.703], [64836.9, 5.398], [64892.7, 5.277], [65343.9, 0.0], [65696.9, 0.01]]}
{"kind": "depth", "E": 1787080339943, "U": 11315347606152, "u": 11315347610790, "recv_ms": 1787080339893, "bids": [[1000.0, 35.81], [14196.8, 2.114], [14596.8, 2.086], [58227.1, 0.002], [62108.9, 0.003], [63687.4, 1.088], [64049.8, 0.0], [64376.3, 6.949], [64664.6, 0.012], [64664.7, 0.0], [64683.8, 0.031]], "asks": [[64717.3, 0.003], [64718.2, 0.014], [64718.3, 0.675], [64758.4, 1.202], [64758.5, 0.005], [64770.2, 0.628], [64772.3, 41.929], [64774.5, 0.091], [65023.4, 4.922], [65343.9, 0.0], [66330.1, 2.111], [67931.7, 0.02]]}
{"kind": "depth", "E": 1787080340045, "U": 11315347610826, "u": 11315347616267, "recv_ms": 1787080339995, "bids": [[1000.0, 35.81], [14196.8, 1.764], [14596.8, 2.436], [58227.1, 0.002], [61464.8, 2.443], [62108.9, 0.006], [63696.8, 0.02], [64049.8, 0.0], [64635.1, 0.345], [64670.8, 0.189], [64680.0, 1.785], [64680.8, 0.949], [64683.8, 0.032], [64685.2, 0.469], [64688.0, 2.151], [64688.7, 0.541]], "asks": [[64698.3, 0.024], [64700.1, 0.006], [64706.2, 0.239], [64707.5, 0.154], [64708.6, 2.852], [64709.0, 1.002], [64711.6, 0.043], [64712.2, 2.331], [64764.6, 0.004], [64892.7, 3.778], [65020.4, 0.154], [65343.9, 0.0], [65441.6, 8.174], [65444.6, 4.547], [65506.3, 6.098], [65509.3, 1.856], [65696.9, 0.03]]}
{"kind": "depth", "E": 1787080340147, "U": 11315347616462, "u": 11315347622311, "recv_ms": 1787080340097, "bids": [[14196.8, 1.4], [14596.8, 2.8], [51758.0, 0.0], [58227.1, 0.002], [61461.9, 0.0], [61464.8, 2.441], [61464.9, 0.006], [63694.0, 3.218], [63799.8, 1.733], [64049.8, 0.0], [64373.3, 0.004], [64556.9, 0.475], [64617.7, 2.336], [64624.6, 0.013], [64644.7, 0.248], [64647.8, 0.035], [64652.9, 0.106], [64654.2, 0.003], [64655.3, 0.098], [64683.6, 0.016], [64684.6, 0.002], [64685.2, 0.464], [64688.8, 0.005], [64696.8, 11.474]], "asks": [[64699.3, 0.01], [64699.5, 0.374], [64699.9, 2.719], [64700.9, 0.064], [64704.0, 0.931], [64704.4, 0.044], [64705.4, 0.005], [64705.5, 0.0], [64705.6, 0.639], [64706.9, 0.358], [64711.6, 0.043], [64712.0, 0.019], [64756.5, 0.028], [64758.9, 0.083], [64766.8, 0.451], [64836.9, 0.0], [65343.9, 0.0], [65441.6, 9.082], [65444.3, 0.979], [67931.7, 0.025]]}
{"kind": "depth", "E": 1787080340249, "U": 11315347622557, "u": 11315347628061, "recv_ms": 1787080340201, "bids": [[1000.0, 35.81], [14196.8, 1.05], [14596.8, 3.15], [51757.4, 0.0], [51758.0, 0.0], [58227.1, 0.002], [62108.9, 0.003], [63696.8, 0.0], [63740.3, 1.245], [63882.5, 3.56], [64049.8, 0.0], [64376.3, 6.949], [64539.9, 0.0], [64617.7, 2.337], [64624.6, 0.014], [64644.7, 0.249], [64654.2, 0.004], [64680.6, 0.681], [64680.8, 0.947], [64683.8, 0.031], [64687.0, 0.901], [64689.5, 0.013], [64689.7, 0.007], [64693.0, 0.002], [64693.4, 0.089], [64696.8, 11.47]], "asks": [[64696.9, 15.159], [64699.3, 0.165], [64699.8, 2.505], [64699.9, 2.696], [64704.4, 0.199], [64705.6, 0.794], [64706.9, 0.668], [64711.6, 0.198], [64713.3, 0.925], [64766.8, 0.442], [64853.9, 0.37], [65343.9, 0.0], [65476.3, 35.534], [65505.6, 0.153], [65629.3, 11.329], [65696.9, 0.01], [66314.3, 0.527]]}
{"kind": "depth", "E": 1787080340351, "U": 11315347628177, "u": 11315347634694, "recv_ms": 1787080340301, "bids": [[1000.0, 35.81], [14196.8, 0.686], [14596.8, 3.514], [51758.0, 0.0], [58227.1, 0.002], [61461.9, 0.0], [62108.9, 0.006], [63405.9, 0.068], [63449.7, 0.678], [63725.8, 1.365], [64049.8, 0.0], [64540.7, 1.236], [64596.2, 0.0], [64602.7, 0.011], [64609.2, 0.0], [64615.6, 0.025], [64622.1, 0.018], [64628.6, 1.764], [64635.0, 0.073], [64641.5, 0.006], [64648.0, 1.29], [64654.4, 1.196], [64660.9, 0.02], [64667.4, 0.004], [64673.9, 0.275], [64680.8, 0.949], [64681.2, 0.008], [64683.8, 0.032], [64687.9, 1.123]], "asks": [[64699.3, 0.01], [64699.9, 2.693], [64703.8, 0.126], [64704.4, 0.044], [64705.6, 0.639], [64706.9, 0.358], [64710.3, 0.01], [64711.6, 0.043], [64713.3, 0.927], [64716.7, 0.015], [64723.2, 0.057], [64729.7, 0.002], [64736.1, 0.002], [64742.6, 0.101], [64749.1, 0.026], [64755.5, 0.0], [64768.5, 0.003], [64774.9, 0.032], [64781.4, 2.319], [64787.9, 0.001], [64792.4, 0.0], [64812.6, 0.086], [65311.5, 0.687], [65330.2, 9.163], [65343.9, 0.0]]}
{"kind": "depth", "E": 1787080340453, "U": 11315347634700, "u": 11315347640641, "recv_ms": 1787080340405, "bids": [[14196.8, 0.392], [14496.8, 0.056], [14596.8, 3.752], [58227.1, 0.002], [61461.9, 0.0], [62108.9, 0.003], [63696.8, 0.02], [64049.8, 0.0], [64501.1, 15.504], [64539.9, 6.888], [64556.9, 4.398], [64578.2, 0.461], [64579.9, 3.864], [64628.3, 0.046], [64628.4, 0.0], [64664.0, 1.223], [64664.6, 0.069], [64665.5, 0.001], [64674.5, 0.621], [64675.3, 0.561], [64676.3, 0.004], [64677.0, 1.096], [64677.9, 0.231], [64688.1, 0.038], [64688.5, 0.541], [64688.7, 0.0], [64689.2, 0.023], [64689.5, 0.005], [64689.7, 0.556], [64689.8, 0.213], [64696.8, 11.471]], "asks": [[64699.3, 0.018], [64699.7, 0.002], [64700.7, 0.003], [64704.4, 0.044], [64705.6, 0.639], [64706.9, 0.358], [64711.6, 0.043], [64713.0, 0.932], [64713.3, 0.002], [64713.9, 0.038], [64715.8, 0.001], [64716.4, 6.118], [64716.5, 0.562], [64716.6, 0.008], [64717.4, 1.602], [64718.3, 0.675], [64719.4, 0.004], [64724.8, 1.396], [64762.0, 0.078], [64770.2, 0.628], [64770.8, 0.06], [64770.9, 0.002], [64772.3, 1.251], [64774.5, 40.626], [64826.3, 0.0], [64835.0, 3.865], [64835.1, 4.228], [64836.9, 5.398], [64849.9, 0.026], [64853.9, 10.778], [64892.7, 5.498], [65343.9, 0.0], [65469.8, 8.235], [65473.3, 2.911], [65696.9, 0.03], [65993.8, 0.044]]}
{"kind": "depth", "E": 1787080340555, "U": 11315347640717, "u": 11315347645882, "recv_ms": 1787080340509, "bids": [[1000.0, 35.81], [14196.8, 0.252], [14496.8, 0.28], [14596.8, 3.668], [58227.1, 0.002], [62108.9, 0.006], [63764.0, 0.604], [63914.8, 8.593], [64049.8, 0.0], [64373.3, 0.004], [64602.7, 0.003], [64660.5, 0.017], [64689.2, 0.007], [64689.9, 0.017], [64692.8, 0.118]], "asks": [[64699.0, 0.116], [64699.3, 0.01], [64723.9, 2.639], [64724.8, 1.242], [64724.9, 0.156], [64768.3, 6.908], [64770.2, 41.163], [64774.5, 0.091], [65023.4, 2.619], [65343.9, 0.0], [65597.0, 10.743], [65638.0, 36.14]]}
{"kind": "depth", "E": 1787080340657, "U": 11315347646001, "u": 11315347650953, "recv_ms": 1787080340607, "bids": [[1000.0, 35.81], [14196.8, 0.126], [14496.8, 0.518], [14596.8, 3.556], [58227.1, 0.002], [61461.9, 0.001], [63696.8, 0.0], [64049.8, 0.0], [64373.3, 0.003], [64645.8, 0.003], [64664.5, 0.011], [64664.6, 0.059], [64683.8, 0.032], [64690.6, 0.157], [64694.2, 0.011], [64696.8, 11.475]], "asks": [[64696.9, 15.166], [64698.9, 0.056], [64699.3, 0.165], [64699.9, 2.688], [64700.4, 0.004], [64701.0, 0.005], [64704.4, 0.199], [64705.5, 0.0], [64705.6, 0.794], [64706.9, 0.668], [64711.6, 0.206], [64712.0, 0.011], [64750.0, 1.88], [64768.3, 0.893], [64770.2, 0.628], [64772.3, 41.786], [64774.5, 0.091], [65343.9, 0.0], [65466.8, 0.922], [65696.9, 0.01]]}
{"kind": "depth", "E": 1787080340759, "U": 11315347651020, "u": 11315347657224, "recv_ms": 1787080340709, "bids": [[14196.8, 0.014], [14496.8, 0.756], [14596.8, 3.43], [58227.1, 0.002], [61461.9, 0.001], [62108.9, 0.003], [63675.6, 0.002], [64049.8, 0.0], [64519.9, 0.12], [64556.9, 5.21], [64574.8, 0.095], [64651.5, 0.186], [64693.5, 0.356], [64693.7, 0.021]], "asks": [[64696.9, 15.165], [64699.3, 0.01], [64700.0, 1.776], [64700.1, 0.028], [64704.4, 0.044], [64705.5, 0.008], [64705.6, 0.639], [64706.9, 0.358], [64711.6, 0.043], [64724.8, 1.396], [64724.9, 0.002], [64730.8, 0.072], [64750.5, 0.0], [64770.2, 41.163], [64772.3, 1.251], [64816.3, 0.002], [64836.9, 0.0], [64840.1, 5.4], [64892.7, 0.007], [64895.9, 5.585], [65020.4, 0.155], [65343.9, 0.0], [65505.6, 0.382], [65513.4, 1.526]]}
{"kind": "depth", "E": 1787080340861, "U": 11315347657507, "u": 11315347664375, "recv_ms": 1787080340810, "bids": [[1000.0, 35.81], [14196.8, 0.0], [14496.8, 1.092], [14596.8, 3.108], [58227.1, 0.002], [61461.9, 0.0], [62108.9, 0.006], [63696.8, 0.02], [63745.9, 0.562], [64049.8, 0.0], [64105.4, 0.0], [64373.3, 0.003], [64664.0, 1.28], [64664.6, 0.002], [64674.6, 0.559], [64675.3, 0.004], [64676.3, 0.12], [64677.0, 0.98], [64679.9, 0.017], [64680.8, 0.949], [64688.0, 2.692], [64688.5, 0.0]], "asks": [[64703.1, 0.092], [64705.5, 0.0], [64705.8, 2.393], [64711.6, 0.051], [64714.9, 2.527], [64715.8, 0.557], [64716.5, 0.006], [64716.7, 0.072], [64717.3, 0.003], [64717.4, 1.545], [64718.3, 0.675], [64724.8, 1.396], [64758.3, 0.01], [64758.4, 1.192], [64770.2, 0.628], [64772.3, 41.786], [64774.5, 0.091], [65020.4, 2.458], [65343.9, 0.0], [65508.6, 17.252], [65602.7, 2.468], [65696.9, 0.03]]}
{"kind": "depth", "E": 1787080340963, "U": 11315347664574, "u": 11315347669849, "recv_ms": 1787080340915, "bids": [[1000.0, 35.81], [14496.8, 1.456], [14596.8, 2.744], [58227.1, 0.002], [62108.9, 0.003], [63882.5, 3.209], [64049.8, 0.0], [64376.3, 6.794], [64595.4, 0.031], [64601.9, 0.017], [64608.3, 0.004], [64614.8, 0.003], [64621.3, 0.005], [64627.7, 0.004], [64634.2, 0.136], [64640.7, 0.165], [64647.1, 0.314], [64653.6, 0.216], [64660.1, 4.652], [64666.5, 0.399], [64673.0, 0.472], [64679.5, 0.028], [64680.0, 2.711], [64680.8, 0.023], [64686.0, 0.012]], "asks": [[64700.1, 0.031], [64706.6, 0.036], [64712.3, 1.435], [64713.0, 0.935], [64717.3, 0.003], [64718.3, 0.675], [64719.5, 1.245], [64726.0, 2.36], [64770.1, 40.536], [64772.3, 1.251], [65343.9, 0.0], [65476.3, 34.849]]}
{"kind": "depth", "E": 1787080341065, "U": 11315347669934, "u": 11315347674796, "recv_ms": 1787080341015, "bids": [[14496.8, 1.806], [14596.8, 2.394], [58227.1, 0.002], [61461.9, 0.0], [61646.4, 0.014], [61649.3, 0.0], [62108.9, 0.006], [63661.1, 1.417], [63696.8, 0.0], [63888.1, 0.951], [64049.8, 0.0], [64182.2, 6.561], [64641.5, 0.003], [64654.5, 0.004], [64677.4, 0.343], [64680.0, 1.785], [64681.0, 1.003], [64683.8, 0.032], [64683.9, 0.311], [64685.2, 0.464], [64688.0, 2.151], [64688.7, 0.541], [64688.8, 0.004], [64689.9, 0.017], [64691.1, 0.216]], "asks": [[64696.9, 15.073], [64697.6, 0.003], [64698.1, 0.001], [64698.9, 0.066], [64699.0, 0.106], [64699.3, 0.01], [64704.4, 0.044], [64705.6, 0.639], [64706.9, 0.358], [64709.9, 0.523], [64710.3, 0.01], [64712.9, 0.008], [64713.0, 0.01], [64713.4, 0.937], [64713.5, 0.31], [64715.1, 0.66], [64732.5, 0.079], [64738.9, 0.004], [64745.4, 0.354], [64751.9, 0.228], [64758.2, 0.018], [64758.3, 0.013], [64764.8, 0.254], [64770.1, 0.001], [64771.3, 0.232], [64774.5, 40.626], [64777.7, 0.171], [64784.2, 0.03], [64790.7, 2.442], [64797.2, 0.003], [65343.9, 0.002], [65469.8, 7.32], [65696.9, 0.01], [67727.9, 0.04], [67731.0, 0.0]]}
{"kind": "depth", "E": 1787080341167, "U": 11315347674816, "u": 11315347679697, "recv_ms": 1787080341117, "bids": [[1000.0, 35.81], [14496.8, 2.17], [14596.8, 2.03], [51758.0, 0.0], [58227.1, 0.002], [61462.0, 0.002], [61464.9, 0.004], [63710.5, 4.249], [63713.3, 0.007], [63713.4, 0.018], [63764.0, 0.056], [63775.1, 0.022], [63778.1, 0.087], [63888.1, 1.185], [64049.8, 0.0], [64112.9, 2.42], [64373.3, 0.012], [64376.3, 4.468], [64599.8, 6.679], [64617.6, 0.012], [64617.7, 2.335], [64624.6, 0.016], [64644.7, 0.25], [64647.8, 0.036], [64654.2, 0.005]], "asks": [[64698.9, 0.056], [64699.6, 0.19], [64702.4, 0.097], [64705.4, 0.004], [64770.2, 0.628], [64774.5, 40.417], [65020.4, 2.459], [65343.9, 0.0], [65466.8, 1.837], [65621.7, 0.0], [65686.3, 0.0], [65686.4, 0.019]]}
{"kind": "depth", "E": 1787080341269, "U": 11315347679835, "u": 11315347684816, "recv_ms": 1787080341221, "bids": [[1000.0, 35.81], [14496.8, 2.52], [14596.8, 1.68], [51757.4, 0.0], [58227.1, 0.002], [61461.9, 0.0], [62108.9, 0.003], [63293.9, 0.002], [63294.6, 0.0], [63402.9, 0.907], [63405.9, 0.065], [63484.1, 0.0], [63696.8, 0.02], [63779.6, 0.004], [63791.0, 0.478], [64049.8, 0.0], [64179.2, 4.208], [64373.3, 0.167], [64556.9, 4.648], [64680.8, 0.021], [64689.7, 0.556], [64689.9, 0.017], [64693.5, 0.333], [64693.7, 0.002], [64696.8, 11.476]], "asks": [[64699.3, 0.01], [64702.4, 0.096], [64704.4, 0.044], [64705.6, 0.639], [64706.9, 0.358], [64710.3, 0.145], [64713.2, 0.216], [64713.3, 0.0], [64733.9, 0.116], [64770.2, 40.954], [64774.5, 0.091], [64780.5, 0.036], [64790.6, 0.0], [64827.1, 0.001], [64836.9, 5.398], [64840.1, 0.002], [64873.8, 0.009], [64892.7, 0.007], [64895.8, 5.887], [64895.9, 0.028], [65343.9, 0.0], [65473.3, 3.596], [65476.3, 34.087], [65506.3, 7.61], [65509.0, 0.941], [65509.3, 1.094], [65618.6, 4.099], [65620.1, 0.0], [65683.3, 0.025], [65696.9, 0.03], [65901.8, 0.0], [66075.3, 0.002]]}
{"kind": "depth", "E": 1787080341371, "U": 11315347684981, "u": 11315347690211, "recv_ms": 1787080341322, "bids": [[14496.8, 2.884], [14596.8, 1.316], [58227.1, 0.002], [62108.9, 0.006], [63745.8, 0.548], [63776.6, 0.008], [64049.8, 0.0], [64373.1, 0.003], [64373.3, 2.493], [64373.4, 0.569], [64680.8, 0.023], [64683.8, 0.031], [64686.0, 1.946], [64689.5, 0.004], [64689.7, 0.556], [64689.8, 0.213], [64689.9, 0.017], [64690.1, 0.005], [64691.2, 0.19], [64694.5, 0.085]], "asks": [[64696.9, 15.074], [64699.0, 0.022], [64699.3, 0.01], [64704.4, 0.044], [64705.5, 0.0], [64705.6, 0.639], [64706.0, 0.006], [64706.9, 0.358], [64710.3, 0.145], [64711.6, 0.051], [64713.3, 0.002], [64812.6, 0.002], [64826.3, 0.0], [65343.9, 0.0], [65344.5, 0.381], [65347.3, 1.605], [65441.6, 10.898], [65444.3, 0.071], [65444.6, 3.632], [65513.4, 0.764]]}
{"kind": "depth", "E": 1787080341473, "U": 11315347690291, "u": 11315347696177, "recv_ms": 1787080341425, "bids": [[1000.0, 35.81], [14496.8, 3.234], [14596.8, 0.966], [58227.1, 0.002], [61461.9, 0.0], [61462.0, 0.006], [62108.9, 0.003], [63696.8, 0.0], [64049.8, 0.0], [64373.3, 2.483], [64539.9, 7.904], [64556.9, 5.219], [64680.0, 2.711], [64681.0, 0.077], [64683.8, 0.032], [64688.0, 2.692], [64688.7, 0.0], [64689.7, 0.557], [64689.9, 0.017], [64690.1, 0.004], [64692.9, 0.0], [64693.7, 0.025], [64693.9, 0.019], [64695.3, 0.087]], "asks": [[64696.9, 15.049], [64699.0, 0.014], [64699.3, 0.018], [64699.6, 0.106], [64699.9, 2.604], [64700.0, 1.757], [64700.1, 0.009], [64700.4, 0.001], [64700.6, 0.111], [64700.7, 0.028], [64701.4, 0.004], [64704.4, 0.044], [64705.6, 0.639], [64706.9, 0.358], [64710.3, 0.145], [64711.6, 0.043], [64712.0, 0.019], [64712.4, 0.926], [64713.4, 0.012], [64717.3, 0.544], [64718.3, 0.134], [64836.9, 5.398], [64853.9, 10.778], [64892.7, 4.032], [64895.8, 0.0], [65343.9, 0.0], [65499.8, 4.384], [65696.9, 0.01]]}
{"kind": "depth", "E": 1787080341575, "U": 11315347696243, "u": 11315347700957, "recv_ms": 1787080341527, "bids": [[14496.8, 3.598], [14596.8, 0.602], [51758.0, 0.004], [58227.1, 0.002], [63066.8, 0.002], [64049.8, 0.0], [64540.7, 2.259], [64638.5, 0.008], [64660.5, 0.003], [64680.0, 1.785], [64680.9, 1.239], [64683.8, 0.032], [64688.0, 2.151], [64688.7, 0.541], [64689.9, 0.017]], "asks": [[64696.9, 15.048], [64699.3, 0.018], [64703.4, 0.319], [64703.5, 0.09], [64704.4, 0.044], [64705.6, 0.639], [64706.9, 0.358], [64710.3, 0.145], [64712.4, 0.001], [64713.4, 0.937], [64717.3, 0.003], [64718.3, 0.675], [64768.3, 6.877], [64806.9, 0.006], [64835.2, 3.46], [65343.9, 0.0], [65473.3, 4.358], [65617.1, 0.008]]}
{"kind": "depth", "E": 1787080341677, "U": 11315347701013, "u": 11315347706081, "recv_ms": 1787080341627, "bids": [[14396.8, 0.084], [14496.8, 3.78], [14596.8, 0.336], [51758.0, 0.0], [58227.1, 0.002], [62108.9, 0.006], [63696.8, 0.02], [64049.8, 0.0], [64688.8, 0.001], [64689.9, 0.227], [64694.5, 0.001], [64695.3, 0.003]], "asks": [[64699.0, 0.106], [64699.3, 0.01], [64699.5, 0.458], [64699.9, 1.8], [64700.1, 0.093], [64703.5, 0.006], [65343.9, 0.0], [65441.6, 11.806], [65444.6, 2.724], [65476.3, 29.512], [65696.9, 0.03]]}
{"kind": "depth", "E": 1787080341779, "U": 11315347706204, "u": 11315347711923, "recv_ms": 1787080341730, "bids": [[1000.0, 35.81], [14396.8, 0.336], [14496.8, 3.64], [14596.8, 0.224], [58227.1, 0.002], [61461.9, 0.0], [61464.8, 2.439], [61464.9, 0.006], [62108.9, 0.003], [63405.9, 0.062], [64049.8, 0.0], [64373.3, 2.484], [64556.9, 4.162], [64619.1, 0.004], [64688.4, 2.156], [64689.9, 0.227], [64696.8, 11.477]], "asks": [[64698.9, 0.056], [64699.3, 0.01], [64704.4, 0.044], [64705.5, 0.0], [64705.6, 0.639], [64706.9, 0.358], [64710.3, 0.145], [64711.9, 0.008], [64712.0, 0.011], [64836.9, 5.398], [64892.7, 8.791], [65020.4, 2.458], [65343.9, 0.0], [65441.6, 12.714], [65444.6, 1.816], [67931.7, 0.029]]}
{"kind": "depth", "E": 1787080341881, "U": 11315347712116, "u": 11315347717893, "recv_ms": 1787080341831, "bids": [[14396.8, 0.574], [14496.8, 3.528], [14596.8, 0.098], [58227.1, 0.002], [62108.9, 0.006], [63073.4, 2.299], [63696.8, 0.0], [63784.6, 0.625], [63929.9, 8.433], [64049.8, 0.0], [64674.6, 0.002], [64675.5, 0.562], [64676.3, 0.004], [64677.2, 2.435], [64688.1, 0.347], [64688.4, 1.847], [64689.4, 0.473], [64689.8, 0.136], [64689.9, 0.017], [64690.2, 0.28], [64690.3, 0.21]], "asks": [[64811.5, 0.125], [64892.7, 4.332], [65343.9, 0.0], [65473.3, 8.934], [65696.9, 0.01]]}
{"kind": "depth", "E": 1787080341983, "U": 11315347717966, "u": 11315347725921, "recv_ms": 1787080341933, "bids": [[14396.8, 0.826], [14496.8, 3.374], [14596.8, 0.0], [58227.1, 0.002], [61461.9, 0.0], [62108.9, 0.003], [63425.1, 0.675], [63888.1, 1.418], [63929.9, 7.496], [64049.8, 0.0], [64539.9, 6.84], [64540.7, 1.236], [64556.8, 4.205], [64556.9, 0.475], [64662.6, 0.17], [64677.2, 7.435], [64689.7, 0.557], [64689.8, 0.346], [64690.1, 0.158], [64690.2, 0.126], [64690.3, 0.0], [64696.8, 11.495]], "asks": [[64696.9, 14.992], [64699.3, 0.01], [64704.4, 0.044], [64705.5, 0.008], [64705.6, 0.639], [64706.9, 0.358], [64710.3, 0.145], [64711.9, 0.0], [64835.2, 2.703], [64836.9, 5.398], [64853.9, 10.778], [64892.7, 5.596], [65343.9, 0.0]]}
{"kind": "depth", "E": 1787080342085, "U": 11315347726062, "u": 11315347732197, "recv_ms": 1787080342035, "bids": [[1000.0, 35.81], [14396.8, 1.176], [14496.8, 3.024], [58227.1, 0.002], [60719.2, 0.028], [63696.8, 0.02], [63926.9, 0.937], [64049.8, 0.0], [64179.2, 4.208], [64373.3, 2.494], [64683.8, 0.032], [64685.2, 0.464], [64688.4, 1.849], [64689.8, 0.136], [64694.5, 0.085], [64695.1, 0.0], [64695.5, 0.0], [64696.7, 0.009], [64696.8, 11.511]], "asks": [[64696.9, 14.98], [64699.0, 0.022], [64699.3, 0.01], [64704.4, 0.044], [64705.5, 0.008], [64705.6, 0.639], [64706.9, 0.358], [64710.3, 0.145], [64711.9, 0.0], [65343.9, 0.0], [65441.6, 14.53], [65444.6, 0.0], [65506.3, 8.366], [65509.3, 0.338], [65696.9, 0.03], [65990.8, 0.012]]}
{"kind": "depth", "E": 1787080342187, "U": 11315347732250, "u": 11315347737177, "recv_ms": 1787080342140, "bids": [[14396.8, 1.54], [14496.8, 2.66], [58227.1, 0.002], [61461.9, 0.0], [62108.9, 0.006], [63934.4, 0.0], [64049.8, 0.0], [64617.7, 2.337], [64624.6, 0.017], [64644.7, 0.251], [64647.8, 0.037], [64654.2, 0.006], [64687.7, 0.239]], "asks": [[64704.3, 0.005], [64705.5, 0.0], [64711.6, 0.051], [65020.4, 2.457], [65499.8, 4.156], [67931.7, 0.033]]}
{"kind": "depth", "E": 1787080342289, "U": 11315347737367, "u": 11315347742479, "recv_ms": 1787080342242, "bids": [[14396.8, 1.89], [14496.8, 2.31], [51757.4, 0.0], [51758.0, 0.0], [58227.1, 0.002], [61461.9, 0.0], [62108.9, 0.003], [63405.9, 0.059], [63696.8, 0.0], [63926.9, 1.874], [64049.8, 0.0], [64373.3, 2.495], [64539.9, 0.0], [64556.8, 0.002], [64586.8, 0.007], [64619.1, 0.001], [64638.5, 0.005], [64654.5, 0.001], [64683.8, 0.031], [64689.8, 0.29], [64690.1, 0.004], [64696.8, 11.523]], "asks": [[64699.3, 0.01], [64704.3, 0.004], [64704.4, 0.044], [64705.5, 0.008], [64705.6, 0.639], [64706.9, 0.358], [64710.3, 0.145], [64711.6, 0.043], [64718.7, 0.052], [64726.3, 0.199], [64755.2, 0.319], [64758.2, 0.015], [64806.9, 0.003], [64836.9, 0.0], [64853.9, 0.37], [65343.9, 0.0], [65486.4, 0.763], [65696.9, 0.01], [65989.5, 0.0]]}
{"kind": "depth", "E": 1787080342391, "U": 11315347742602, "u": 11315347754585, "recv_ms": 1787080342342, "bids": [[1000.0, 35.81], [14396.8, 2.254], [14496.8, 1.946], [51758.0, 0.0], [58227.1, 0.002], [62108.9, 0.006], [63920.4, 0.921], [64049.8, 0.0], [64373.3, 2.495], [64539.9, 7.855], [64556.8, 4.721], [64646.7, 0.21], [64653.6, 0.006], [64680.8, 0.023], [64683.8, 0.032]], "asks": [[64697.9, 0.043], [64698.8, 0.0], [64699.3, 0.002], [64700.4, 0.004], [64700.7, 0.025], [64705.5, 0.008], [64706.9, 0.366], [64711.6, 0.043], [64713.3, 0.002], [64826.3, 0.0], [64839.8, 9.182], [64854.8, 1.901], [64856.8, 8.538], [64892.7, 0.007], [64895.6, 8.52], [65343.9, 0.0]]}
{"kind": "depth", "E": 1787080342493, "U": 11315347754790, "u": 11315347765104, "recv_ms": 1787080342444, "bids": [[14396.8, 2.604], [14496.8, 1.596], [58227.1, 0.002], [61461.9, 0.0], [62108.9, 0.003], [63664.6, 5.49], [63696.8, 0.02], [63799.8, 0.951], [64049.8, 0.0], [64680.3, 2.942], [64681.9, 0.216], [64683.6, 0.013], [64684.3, 0.012], [64684.7, 0.003], [64689.9, 0.227], [64696.8, 11.43]], "asks": [[64699.3, 0.002], [64704.4, 0.044], [64705.5, 0.008], [64706.9, 0.366], [64710.3, 0.145], [64768.3, 0.893], [64770.2, 40.738], [64774.5, 0.091], [64892.7, 4.034], [64895.6, 0.0], [65343.9, 0.0], [65499.8, 3.814], [65696.9, 0.03]]}
{"kind": "depth", "E": 1787080342595, "U": 11315347765154, "u": 11315347773396, "recv_ms": 1787080342547, "bids": [[1000.0, 35.96], [14396.8, 2.968], [14496.8, 1.232], [51758.0, 0.0], [58227.1, 0.002], [63402.9, 0.907], [64009.9, 0.791], [64049.8, 0.0], [64540.7, 2.252], [64680.6, 0.685], [64688.4, 1.846], [64689.9, 0.227], [64696.8, 11.525]], "asks": [[64696.9, 15.028], [64699.3, 0.002], [64702.7, 0.001], [64703.0, 0.014], [64704.4, 0.044], [64705.5, 0.0], [64705.6, 0.639], [64706.9, 0.366], [64707.0, 1.362], [64710.3, 0.145], [64711.4, 0.033], [64766.8, 0.46], [64768.3, 6.844], [64839.7, 0.096], [64849.9, 0.002], [65343.9, 0.0], [65548.3, 0.0], [65578.2, 0.0]]}
{"kind": "depth", "E": 1787080342697, "U": 11315347773913, "u": 11315347782014, "recv_ms": 1787080342647, "bids": [[1000.0, 35.81], [14396.8, 3.318], [14496.8, 0.882], [58227.1, 0.002], [62108.9, 0.006], [63696.8, 0.0], [63784.6, 1.407], [63888.1, 1.769], [64049.8, 0.0], [64373.3, 2.495], [64556.8, 4.721], [64651.5, 0.189], [64689.9, 0.227], [64694.5, 0.001]], "asks": [[64699.2, 0.365], [64699.9, 1.766], [64806.9, 0.006], [64835.2, 3.46], [64836.9, 5.398], [64839.7, 0.072], [64839.8, 3.784], [64849.9, 0.026], [64892.7, 4.106], [65343.9, 0.001], [65499.8, 3.585], [65696.9, 0.01], [65993.8, 0.041]]}
{"kind": "depth", "E": 1787080342799, "U": 11315347782132, "u": 11315347789834, "recv_ms": 1787080342750, "bids": [[14396.8, 3.682], [14496.8, 0.518], [58227.1, 0.002], [62108.9, 0.003], [63661.7, 0.441], [63991.6, 2.187], [64049.8, 0.0], [64373.3, 2.494], [64673.9, 0.272], [64689.2, 0.47], [64689.4, 0.01], [64689.7, 0.016], [64689.8, 0.213], [64689.9, 0.017], [64690.0, 0.626]], "asks": [[64700.3, 1.05], [64700.4, 0.001], [64700.5, 0.01], [64712.9, 0.005], [64747.0, 0.002], [64856.7, 8.538], [64856.8, 0.0], [64892.7, 0.007], [64895.6, 5.861], [65330.2, 8.476], [65343.9, 0.001], [65499.8, 3.327], [65529.6, 4.114], [65595.8, 2.266]]}
{"kind": "depth", "E": 1787080342901, "U": 11315347789982, "u": 11315347795990, "recv_ms": 1787080342851, "bids": [[1000.0, 35.81], [14296.8, 0.14], [14396.8, 3.752], [14496.8, 0.308], [58227.1, 0.002], [62108.9, 0.006], [63696.8, 0.02], [64049.8, 0.0], [64683.8, 0.032], [64689.2, 0.007], [64689.4, 0.567], [64689.5, 0.467], [64689.7, 0.101], [64689.8, 0.205], [64689.9, 0.001], [64690.0, 0.008], [64690.1, 0.004]], "asks": [[64719.9, 0.115], [64720.3, 0.085], [64892.7, 4.037], [64895.6, 0.0], [65020.4, 2.458], [65273.4, 3.297], [65343.9, 0.001], [65602.7, 4.752], [65696.9, 0.03], [65875.1, 1.408]]}
{"kind": "depth", "E": 1787080343003, "U": 11315347796248, "u": 11315347800768, "recv_ms": 1787080342954, "bids": [[1000.0, 35.81], [14296.8, 0.392], [14396.8, 3.612], [14496.8, 0.196], [58227.1, 0.002], [61461.9, 0.0], [64049.8, 0.0], [64373.3, 2.494], [64374.0, 0.165], [64454.5, 0.437], [64494.0, 0.051], [64533.5, 0.0], [64533.9, 0.061], [64539.9, 5.432], [64556.8, 3.154], [64573.0, 0.028], [64612.5, 0.014], [64652.0, 0.011], [64689.9, 0.001], [64696.8, 11.513]], "asks": [[64698.2, 0.002], [64699.3, 0.002], [64704.4, 0.044], [64705.6, 0.639], [64706.9, 0.366], [64710.3, 0.145], [64766.8, 0.451], [64804.6, 2.319], [64835.2, 2.703], [64836.9, 5.398], [64842.9, 0.0], [64844.1, 0.002], [64883.6, 0.11], [64923.0, 0.867], [64923.1, 0.643], [64962.6, 0.002], [65002.1, 0.001], [65279.2, 0.229], [65311.5, 1.374], [65343.9, 0.001], [65791.9, 0.0]]}
{"kind": "depth", "E": 1787080343105, "U": 11315347800939, "u": 11315347805560, "recv_ms": 1787080343056, "bids": [[14296.8, 0.616], [14396.8, 3.514], [14496.8, 0.07], [58227.1, 0.002], [62108.9, 0.003], [63696.8, 0.0], [63713.4, 0.009], [64049.8, 0.0], [64556.8, 3.922], [64645.0, 6.077], [64683.8, 0.031], [64685.2, 0.464], [64688.6, 0.635], [64689.9, 0.001]], "asks": [[64696.9, 14.925], [64699.3, 0.002], [64703.1, 0.387], [64704.4, 0.044], [64705.6, 0.639], [64705.8, 2.918], [64706.9, 0.366], [64710.3, 0.145], [64740.9, 0.042], [64766.8, 0.442], [64768.3, 0.893], [64770.2, 40.44], [64774.5, 0.091], [64776.3, 0.002], [64836.9, 0.0], [64839.7, 4.034], [64856.7, 6.083], [64892.7, 0.007], [64895.5, 10.038], [65343.9, 0.001], [65485.1, 0.763], [65686.4, 0.01], [65696.9, 0.01], [65990.8, 0.009]]}
{"kind": "depth", "E": 1787080343207, "U": 11315347805630, "u": 11315347811595, "recv_ms": 1787080343159, "bids": [[1000.0, 35.81], [14296.8, 0.882], [14396.8, 3.318], [14496.8, 0.0], [51758.0, 0.0], [58227.1, 0.002], [61461.9, 0.001], [62108.9, 0.006], [63696.8, 0.02], [63710.5, 4.258], [64049.8, 0.0], [64373.3, 2.493], [64617.7, 2.338], [64624.7, 0.001], [64644.8, 1.19], [64647.8, 0.038], [64654.2, 0.007], [64663.1, 0.311], [64663.9, 0.003], [64664.0, 1.282], [64664.1, 0.013], [64667.4, 0.006], [64667.5, 0.016], [64667.6, 0.685], [64689.9, 0.211], [64696.8, 11.514]], "asks": [[64699.3, 0.157], [64703.3, 0.001], [64704.4, 0.199], [64705.6, 0.794], [64706.9, 0.676], [64710.3, 0.3], [64735.3, 4.149], [64737.4, 0.004], [64836.9, 5.398], [64839.7, 0.072], [64853.9, 10.778], [64854.8, 0.719], [64856.7, 0.001], [64892.7, 4.403], [64895.5, 0.0], [65343.9, 0.001], [65545.8, 0.772], [65696.9, 0.03], [65764.4, 0.634]]}
{"kind": "depth", "E": 1787080343309, "U": 11315347811706, "u": 11315347816567, "recv_ms": 1787080343261, "bids": [[1000.0, 35.81], [14296.8, 1.26], [14396.8, 2.94], [51757.4, 0.0], [58227.1, 0.002], [61461.9, 0.0], [61464.8, 2.437], [61464.9, 0.006], [62108.9, 0.003], [64049.8, 0.0], [64373.3, 2.493], [64403.3, 0.054], [64581.8, 0.301], [64619.3, 0.184], [64683.8, 0.032], [64689.9, 0.211]], "asks": [[64699.3, 0.002], [64704.4, 0.044], [64705.6, 0.639], [64706.9, 0.366], [64710.3, 0.145], [64719.2, 0.056], [64730.3, 0.188], [64736.0, 1.781], [64772.0, 0.365], [64868.0, 4.511], [64871.3, 0.018], [64871.4, 0.002], [65020.4, 2.459], [65023.4, 2.465], [65217.5, 9.673], [65343.9, 0.001], [65505.6, 0.611], [65683.3, 0.034], [65990.8, 0.012]]}
{"kind": "depth", "E": 1787080343411, "U": 11315347816709, "u": 11315347821200, "recv_ms": 1787080343361, "bids": [[14296.8, 1.624], [14396.8, 2.576], [58227.1, 0.002], [61461.9, 0.0], [62108.9, 0.006], [64049.8, 0.0], [64556.8, 0.002], [64645.0, 6.105], [64680.8, 0.023], [64689.9, 0.211], [64696.8, 11.515]], "asks": [[64696.9, 14.936], [64699.3, 0.002], [64699.9, 1.765], [64704.4, 0.044], [64705.6, 0.639], [64706.9, 0.366], [64710.3, 0.145], [64713.3, 0.002], [64785.6, 1.355], [64826.3, 0.0], [64836.9, 0.0], [65343.9, 0.001], [65510.1, 0.001]]}
{"kind": "depth", "E": 1787080343513, "U": 11315347821292, "u": 11315347827236, "recv_ms": 1787080343465, "bids": [[1000.0, 35.81], [14296.8, 1.974], [14396.8, 2.226], [58227.1, 0.002], [61461.9, 0.0], [63696.8, 0.0], [63929.9, 6.559], [64049.8, 0.0], [64501.0, 15.912], [64501.1, 0.0], [64533.9, 2.051], [64539.8, 7.901], [64539.9, 0.0], [64556.8, 4.441], [64643.0, 2.616], [64660.5, 0.017], [64662.9, 0.005], [64666.4, 0.196], [64670.2, 0.308], [64674.5, 0.003], [64675.3, 0.561], [64675.5, 0.005], [64677.0, 1.096], [64677.2, 7.319], [64680.3, 2.324], [64682.9, 0.254], [64684.5, 0.253], [64686.1, 0.24], [64687.8, 0.323], [64689.3, 0.334], [64689.4, 0.01], [64689.7, 0.092], [64689.9, 0.001], [64690.0, 0.669], [64690.1, 0.02], [64690.3, 0.084], [64691.4, 0.086], [64693.8, 0.003], [64693.9, 0.0], [64696.8, 10.214]], "asks": [[64696.9, 14.935], [64698.3, 0.108], [64698.6, 0.084], [64699.3, 0.002], [64702.8, 2.332], [64703.1, 0.303], [64703.3, 0.0], [64704.4, 0.044], [64704.7, 0.002], [64705.6, 0.639], [64706.9, 0.366], [64710.3, 0.145], [64712.1, 0.465], [64715.1, 0.042], [64720.8, 0.003], [64740.9, 0.0], [64756.0, 4.088], [64764.2, 0.006], [64770.2, 0.628], [64774.4, 6.966], [64774.5, 39.903], [64836.9, 5.398], [64871.9, 0.592], [64892.7, 4.333], [65020.4, 2.613], [65214.5, 0.61], [65343.9, 0.001], [65696.9, 0.01]]}
{"kind": "depth", "E": 1787080343615, "U": 11315347827248, "u": 11315347832210, "recv_ms": 1787080343568, "bids": [[1000.0, 35.81], [14296.8, 2.338], [14396.8, 1.862], [58227.1, 0.002], [61461.9, 0.0], [62108.9, 0.003], [64049.8, 0.0], [64373.3, 2.483], [64556.8, 4.441], [64571.3, 0.002], [64586.8, 0.004], [64651.5, 0.189], [64670.9, 0.046], [64678.7, 0.37], [64688.6, 0.632], [64689.7, 0.633], [64689.8, 0.317], [64689.9, 0.197], [64690.0, 0.016], [64691.4, 0.086], [64691.5, 0.296], [64693.4, 0.005], [64693.5, 0.314], [64693.7, 0.002], [64696.8, 10.204]], "asks": [[64699.3, 0.157], [64704.4, 0.199], [64705.6, 0.794], [64706.4, 0.008], [64706.9, 0.676], [64709.9, 0.526], [64710.3, 0.3], [64719.9, 10.115], [64755.2, 0.319], [64770.2, 40.44], [64772.3, 1.251], [64774.4, 1.129], [64774.5, 0.091], [64806.9, 0.003], [64813.8, 0.0], [64836.9, 0.0], [64839.6, 5.11], [64853.9, 0.37], [64856.6, 7.823], [64892.7, 0.007], [64895.4, 9.733], [65343.9, 0.001], [65474.7, 0.914]]}
{"kind": "depth", "E": 1787080343717, "U": 11315347832358, "u": 11315347836621, "recv_ms": 1787080343669, "bids": [[14296.8, 2.688], [14396.8, 1.512], [51757.0, 0.002], [58227.1, 0.002], [61461.9, 0.001], [62108.9, 0.006], [63273.5, 0.003], [63696.8, 0.02], [63926.9, 2.811], [64049.8, 0.0], [64657.9, 0.017], [64677.2, 2.319], [64689.7, 0.633], [64689.8, 0.205], [64689.9, 0.085], [64690.9, 0.07], [64691.5, 0.191], [64693.5, 0.004], [64696.8, 10.229]], "asks": [[64699.3, 0.157], [64704.4, 0.199], [64705.6, 0.794], [64706.9, 0.676], [64710.3, 0.3], [64717.4, 2.875], [64719.9, 0.115], [64723.9, 1.251], [64724.4, 0.004], [64770.2, 0.628], [64774.5, 39.903], [64892.7, 5.851], [64895.4, 0.008], [65343.9, 0.0], [65505.6, 0.839], [65696.9, 0.03], [65990.8, 0.009]]}
{"kind": "depth", "E": 1787080343819, "U": 11315347836742, "u": 11315347845568, "recv_ms": 1787080343770, "bids": [[1000.0, 35.81], [14296.8, 3.052], [14396.8, 1.148], [51757.0, 0.0], [58227.1, 0.002], [61461.9, 0.0], [62108.9, 0.003], [63929.9, 5.622], [64049.8, 0.0], [64556.8, 0.002], [64620.6, 0.034], [64620.7, 0.122], [64622.8, 33.216], [64623.0, 6.518], [64689.5, 0.004], [64689.6, 0.288], [64689.7, 0.668], [64689.8, 0.163], [64689.9, 0.625], [64690.0, 0.17], [64691.4, 0.086], [64696.8, 10.227]], "asks": [[64699.3, 0.002], [64704.4, 0.044], [64705.6, 0.639], [64706.9, 0.366], [64710.3, 0.145], [64717.4, 1.545], [64722.6, 11.001], [64770.2, 40.44], [64774.5, 0.091], [64839.6, 0.0], [65330.2, 7.866], [65343.9, 0.0]]}
{"kind": "depth", "E": 1787080343921, "U": 11315347845790, "u": 11315347856197, "recv_ms": 1787080343872, "bids": [[1000.0, 35.81], [14296.8, 3.416], [14396.8, 0.784], [58227.1, 0.002], [61461.9, 0.0], [62108.9, 0.006], [63696.8, 0.0], [63910.0, 1.416], [64049.8, 0.002], [64373.3, 2.493], [64539.8, 6.776], [64556.8, 4.173], [64618.5, 32.849], [64622.8, 0.372], [64623.0, 1.798], [64683.8, 0.031], [64689.1, 1.341], [64689.2, 0.548], [64689.3, 0.445], [64689.4, 0.686], [64689.5, 0.116], [64689.7, 0.127], [64689.8, 0.051], [64689.9, 0.085], [64690.0, 0.162], [64690.1, 0.004], [64690.9, 0.182], [64691.4, 0.296], [64696.8, 10.226]], "asks": [[64699.3, 0.002], [64704.4, 0.044], [64705.6, 0.639], [64706.9, 0.366], [64710.3, 0.145], [64770.2, 0.628], [64772.3, 41.063], [64774.5, 0.091], [64836.9, 5.398], [64853.9, 10.778], [64856.6, 0.001], [64892.7, 6.038], [65020.4, 2.612], [65343.9, 0.0], [65499.8, 3.069], [65696.9, 0.01]]}
{"kind": "depth", "E": 1787080344023, "U": 11315347856233, "u": 11315347862295, "recv_ms": 1787080343975, "bids": [[14196.8, 0.028], [14296.8, 3.71], [14396.8, 0.462], [58227.1, 0.002], [64049.8, 0.0], [64373.3, 2.494], [64618.5, 0.005], [64620.6, 32.878], [64627.3, 0.003], [64660.0, 0.161], [64666.4, 0.042], [64667.9, 0.154], [64672.9, 0.017], [64674.5, 0.157], [64681.0, 0.231], [64683.8, 0.032], [64689.3, 0.333], [64691.4, 0.086]], "asks": [[64699.9, 0.703], [64701.2, 0.063], [64704.2, 0.002], [64707.5, 0.0], [64710.4, 1.898], [64713.4, 1.091], [64719.9, 0.269], [64726.3, 0.353], [64892.7, 4.035], [65203.8, 0.0], [65311.5, 1.985], [65343.9, 0.0], [65361.5, 0.161], [65426.2, 0.0], [65609.8, 0.001], [65977.9, 0.606]]}
{"kind": "depth", "E": 1787080344125, "U": 11315347862406, "u": 11315347868607, "recv_ms": 1787080344079, "bids": [[1000.0, 35.81], [14196.8, 0.196], [14296.8, 3.724], [14396.8, 0.28], [51757.0, 0.0], [58227.1, 0.002], [61461.9, 0.0], [62108.9, 0.003], [63402.9, 0.91], [63588.0, 4.435], [63696.8, 0.02], [63926.9, 3.748], [64049.8, 0.0], [64582.0, 0.303], [64585.1, 0.002], [64603.5, 2.641], [64610.8, 0.006], [64614.4, 0.009], [64617.5, 0.0], [64617.6, 0.01], [64617.7, 2.335], [64620.6, 0.034], [64622.8, 33.341], [64624.6, 0.013], [64624.7, 0.0], [64646.8, 0.005], [64647.8, 0.033], [64649.9, 0.001], [64654.2, 0.001], [64679.2, 0.002], [64680.7, 0.614], [64685.2, 0.464], [64685.7, 2.483], [64686.5, 0.0], [64689.3, 0.333], [64691.4, 0.086], [64692.2, 0.034], [64693.2, 0.024], [64693.4, 0.025], [64695.2, 0.0]], "asks": [[64696.9, 14.914], [64699.0, 0.022], [64701.5, 0.007], [64702.4, 0.094], [64703.9, 0.004], [64704.4, 0.044], [64705.6, 0.639], [64706.9, 0.366], [64708.0, 0.223], [64708.7, 0.243], [64710.3, 0.145], [64716.4, 6.118], [64717.4, 1.543], [64749.8, 0.002], [64770.1, 39.676], [64772.3, 1.251], [64782.2, 0.0], [64795.5, 2.617], [64814.6, 0.001], [65209.5, 4.595], [65343.9, 0.0], [65696.9, 0.03]]}
{"kind": "depth", "E": 1787080344227, "U": 11315347868780, "u": 11315347873369, "recv_ms": 1787080344179, "bids": [[1000.0, 35.81], [14196.8, 0.448], [14296.8, 3.584], [14396.8, 0.168], [51757.0, 0.0], [58227.1, 0.002], [62108.9, 0.006], [64049.8, 0.0], [64373.3, 2.484], [64604.5, 4.557], [64617.5, 0.001], [64624.4, 0.001], [64624.6, 0.011], [64644.6, 0.003], [64644.7, 0.247], [64644.8, 1.189], [64647.7, 0.003], [64654.0, 0.035], [64654.2, 0.0], [64680.8, 0.003], [64689.3, 0.445], [64689.5, 0.004], [64689.7, 0.015], [64690.9, 0.07], [64691.4, 0.296]], "asks": [[65343.9, 0.0], [65472.6, 0.763], [65499.8, 2.81], [65505.6, 1.181], [65548.8, 0.762]]}
{"kind": "depth", "E": 1787080344329, "U": 11315347873526, "u": 11315347879947, "recv_ms": 1787080344280, "bids": [[14196.8, 0.672], [14296.8, 3.486], [14396.8, 0.042], [51757.0, 0.0], [51757.4, 0.0], [51758.0, 0.0], [58227.1, 0.002], [62108.9, 0.003], [63696.8, 0.0], [64049.8, 0.0], [64659.1, 0.33], [64683.8, 0.032], [64689.3, 0.389], [64691.4, 0.296]], "asks": [[64714.5, 0.875], [64730.8, 0.07], [64746.9, 0.003], [64779.3, 0.029], [64811.7, 0.024], [64892.7, 4.104], [65020.4, 2.611], [65343.9, 0.0], [65346.3, 0.856], [65411.0, 1.558], [65505.6, 1.41], [65696.9, 0.01]]}
{"kind": "depth", "E": 1787080344431, "U": 11315347880910, "u": 11315347891794, "recv_ms": 1787080344383, "bids": [[1000.0, 35.81], [14196.8, 0.994], [14296.8, 3.206], [14396.8, 0.0], [58227.1, 0.002], [61461.9, 0.0], [61462.0, 0.008], [63564.6, 3.38], [64049.8, 0.0], [64373.3, 2.495], [64659.1, 0.332], [64680.8, 0.003], [64689.3, 0.333], [64689.4, 0.574], [64689.5, 0.06], [64691.4, 0.191], [64693.2, 0.108], [64693.3, 0.416], [64696.8, 10.219]], "asks": [[64699.0, 0.022], [64699.4, 2.321], [64699.9, 0.698], [64702.4, 0.092], [64703.9, 0.003], [64704.4, 0.044], [64705.6, 0.639], [64706.9, 0.366], [64710.3, 0.145], [64713.3, 0.002], [64730.8, 0.072], [64826.3, 0.0], [65343.9, 0.0], [65453.9, 0.537], [65505.6, 1.668]]}
{"kind": "depth", "E": 1787080344533, "U": 11315347891939, "u": 11315347898596, "recv_ms": 1787080344483, "bids": [[1000.0, 35.81], [14196.8, 1.344], [14296.8, 2.856], [58227.1, 0.002], [62108.9, 0.006], [63273.5, 0.0], [63696.8, 0.02], [64049.8, 0.0], [64689.4, 0.574], [64689.7, 0.127], [64690.9, 0.07], [64691.4, 0.086]], "asks": [[64720.0, 3.641], [64768.3, 6.779], [64835.2, 3.46], [65343.9, 0.0], [65696.9, 0.03], [71166.6, 0.014]]}
{"kind": "depth", "E": 1787080344635, "U": 11315347898824, "u": 11315347906556, "recv_ms": 1787080344588, "bids": [[14196.8, 1.708], [14296.8, 2.492], [58227.1, 0.002], [61461.9, 0.0], [61462.0, 0.006], [61462.1, 0.002], [62108.9, 0.003], [64049.8, 0.0], [64674.5, 0.775], [64674.6, 0.559], [64675.3, 0.004], [64676.3, 0.12], [64677.0, 0.98], [64679.9, 0.017], [64680.9, 1.239], [64681.8, 0.798], [64683.8, 0.032], [64687.1, 0.005], [64688.0, 2.692], [64688.7, 0.0], [64689.4, 0.686], [64689.5, 0.116], [64689.7, 0.043], [64690.0, 0.008], [64691.4, 0.296], [64693.6, 0.001]], "asks": [[64696.9, 14.919], [64699.0, 0.022], [64704.4, 0.044], [64705.6, 0.639], [64706.9, 0.366], [64711.6, 0.043], [64712.3, 1.435], [64713.3, 0.927], [64713.4, 0.784], [64714.9, 2.527], [64715.8, 0.557], [64717.3, 0.003], [64718.2, 0.555], [64718.3, 0.134], [64719.1, 0.037], [64719.9, 0.154], [64720.1, 2.443], [64720.8, 0.621], [64853.9, 0.37], [64854.8, 1.792], [64856.4, 7.806], [64892.7, 0.007], [64895.3, 8.39], [65343.9, 0.0], [71166.6, 0.015]]}
{"kind": "depth", "E": 1787080344737, "U": 11315347906696, "u": 11315347913351, "recv_ms": 1787080344688, "bids": [[1000.0, 35.81], [14196.8, 2.072], [14296.8, 2.128], [58227.1, 0.002], [62108.9, 0.006], [63402.9, 0.91], [63696.8, 0.0], [64049.8, 0.0], [64373.3, 2.495], [64564.0, 2.619], [64657.9, 0.017], [64664.0, 1.282], [64664.7, 0.0], [64665.5, 0.001], [64675.9, 0.087], [64676.5, 0.001], [64679.9, 0.943], [64680.9, 0.313], [64688.0, 2.692], [64688.4, 1.844], [64688.7, 0.0], [64689.4, 0.686], [64689.5, 0.116], [64689.7, 0.099], [64690.1, 0.004], [64691.4, 0.296]], "asks": [[64696.9, 14.921], [64699.0, 0.022], [64699.9, 0.696], [64704.4, 0.044], [64705.6, 0.639], [64706.9, 0.366], [64710.3, 0.145], [64712.4, 0.001], [64713.2, 1.141], [64713.3, 0.002], [64713.9, 0.038], [64715.8, 0.557], [64716.6, 0.065], [64716.7, 0.015], [64717.3, 0.003], [64717.4, 1.543], [64718.0, 0.559], [64718.1, 0.005], [64718.2, 0.014], [64719.4, 0.004], [64722.7, 2.893], [64730.1, 0.131], [64835.0, 6.481], [64853.9, 10.778], [64854.8, 0.719], [64856.4, 0.001], [64892.7, 4.035], [64895.3, 0.003], [65343.9, 0.0], [65696.9, 0.01], [66637.7, 0.004], [71166.6, 0.013]]}
{"kind": "depth", "E": 1787080344839, "U": 11315347913401, "u": 11315347920271, "recv_ms": 1787080344790, "bids": [[1000.0, 35.81], [14196.8, 2.422], [14296.8, 1.778], [58227.1, 0.002], [61461.9, 0.0], [62108.9, 0.003], [64049.8, 0.0], [64376.3, 4.313], [64622.8, 33.341], [64625.0, 1.59], [64626.6, 0.006], [64626.7, 0.03], [64649.2, 0.007], [64651.5, 0.186], [64657.9, 0.017], [64663.9, 0.001], [64664.0, 1.28], [64664.1, 0.011], [64665.4, 0.307], [64667.4, 0.004], [64667.5, 0.014], [64667.6, 0.683], [64674.6, 0.002], [64675.5, 0.562], [64676.3, 0.004], [64676.4, 0.502], [64677.1, 0.32], [64680.3, 2.321], [64689.4, 0.574], [64689.5, 0.004], [64690.2, 0.28], [64690.3, 0.196], [64691.4, 0.086], [64696.8, 10.231]], "asks": [[64699.0, 0.022], [64704.4, 0.044], [64705.6, 0.639], [64706.9, 0.366], [64710.3, 0.145], [64723.3, 0.311], [64726.9, 0.002], [64727.0, 0.111], [64739.4, 0.886], [64739.5, 0.301], [64755.2, 0.319], [64762.1, 0.049], [64892.7, 4.105], [65343.9, 0.0], [65694.0, 1.074], [71166.6, 0.013]]}
{"kind": "depth", "E": 1787080344941, "U": 11315347920480, "u": 11315347925518, "recv_ms": 1787080344892, "bids": [[14196.8, 2.786], [14296.8, 1.414], [58227.1, 0.002], [63696.8, 0.02], [64049.8, 0.0], [64594.2, 0.001], [64595.2, 1.545], [64624.3, 0.034], [64628.1, 6.027], [64650.7, 3.973], [64666.9, 1.327], [64689.4, 0.574], [64689.5, 0.116], [64690.1, 0.158], [64690.2, 0.126], [64690.3, 0.084], [64691.4, 0.086]], "asks": [[64723.3, 1.291], [64739.4, 4.386], [64762.1, 6.049], [64794.5, 0.002], [65343.9, 0.0], [65517.4, 0.762], [65696.9, 0.03]]}
{"kind": "depth", "E": 1787080345043, "U": 11315347925566, "u": 11315347932697, "recv_ms": 1787080344994, "bids": [[1000.0, 35.81], [14196.8, 3.136], [14296.8, 1.064], [58227.1, 0.002], [61461.9, 0.0], [62108.9, 0.006], [64049.8, 0.0], [64178.5, 0.433], [64373.3, 2.484], [64539.8, 5.459], [64556.8, 3.925], [64679.9, 0.017], [64680.8, 0.929], [64685.2, 0.469], [64688.5, 0.003], [64689.4, 0.574], [64691.0, 0.457], [64691.4, 0.086], [64693.4, 0.026], [64693.8, 0.087], [64696.8, 10.23]], "asks": [[64696.9, 14.922], [64697.0, 0.067], [64698.3, 0.024], [64699.0, 0.022], [64699.9, 0.691], [64700.0, 1.712], [64704.4, 0.044], [64705.6, 0.639], [64706.9, 0.366], [64710.3, 0.145], [64716.7, 0.015], [64768.3, 0.893], [64770.1, 0.001], [64770.2, 40.044], [64774.5, 0.091], [64853.9, 10.778], [64856.4, 0.001], [64892.7, 5.554], [64895.2, 0.001], [65020.4, 2.612], [65343.9, 0.0], [65699.7, 0.912]]}
{"kind": "depth", "E": 1787080345145, "U": 11315347932860, "u": 11315347939151, "recv_ms": 1787080345096, "bids": [[1000.0, 35.81], [14196.8, 3.486], [14296.8, 0.714], [58227.1, 0.002], [61461.9, 0.0], [61464.9, 0.004], [62108.9, 0.003], [63687.4, 0.0], [63696.8, 0.0], [63710.4, 4.239], [63713.4, 0.001], [63849.5, 3.136], [64049.8, 0.0], [64373.3, 2.639], [64595.8, 15.213], [64610.5, 0.004], [64617.5, 0.003], [64618.5, 0.005], [64620.6, 33.123], [64621.7, 0.018], [64622.8, 0.372], [64624.4, 0.002], [64632.1, 0.005], [64644.5, 0.017], [64644.6, 0.001], [64647.6, 0.695], [64647.7, 0.001], [64654.0, 0.037], [64660.5, 0.003], [64670.3, 0.347], [64685.2, 0.464], [64685.7, 2.485], [64689.4, 0.686], [64689.7, 0.015], [64689.9, 0.001], [64691.4, 0.296], [64695.0, 0.088], [64696.8, 10.24]], "asks": [[64696.9, 14.68], [64698.6, 0.0], [64699.0, 0.022], [64699.2, 0.281], [64699.3, 0.002], [64699.5, 0.374], [64702.7, 0.085], [64702.9, 0.312], [64703.1, 0.387], [64704.4, 0.044], [64705.5, 0.0], [64705.6, 0.006], [64705.7, 0.087], [64706.8, 0.549], [64706.9, 0.366], [64710.3, 0.145], [64711.4, 0.025], [64711.6, 0.051], [64713.4, 0.166], [64720.0, 2.17], [64720.8, 0.003], [64722.6, 1.001], [64726.7, 10.0], [64761.6, 0.816], [64766.8, 0.451], [64769.4, 0.018], [64785.6, 1.255], [64794.5, 10.002], [65000.0, 117.689], [65343.9, 0.0], [65686.4, 0.002], [65696.9, 0.01], [65990.8, 0.006]]}
{"kind": "depth", "E": 1787080345247, "U": 11315347939414, "u": 11315347944334, "recv_ms": 1787080345198, "bids": [[14196.8, 3.738], [14296.8, 0.406], [14596.8, 0.056], [51758.0, 0.0], [58227.1, 0.002], [62108.9, 0.006], [64009.9, 0.09], [64049.8, 0.0], [64524.2, 0.001], [64524.5, 2.618], [64524.7, 3.444], [64610.5, 0.005], [64644.5, 0.018], [64664.0, 1.223], [64664.7, 0.057], [64665.6, 0.007], [64674.5, 0.157], [64674.8, 1.754], [64675.5, 0.005], [64675.8, 0.138], [64676.4, 0.602], [64677.1, 0.204], [64680.0, 1.785], [64680.8, 0.929], [64681.6, 0.018], [64681.8, 0.18], [64688.0, 2.151], [64688.7, 0.541], [64689.4, 0.686], [64689.5, 0.116], [64689.7, 0.127], [64691.4, 0.296], [64696.8, 10.248]], "asks": [[64696.9, 14.83], [64699.0, 0.014], [64699.3, 0.01], [64699.9, 0.689], [64700.5, 0.007], [64700.7, 0.025], [64702.9, 0.311], [64704.4, 0.044], [64705.6, 0.006], [64705.7, 0.087], [64706.7, 0.014], [64706.8, 0.549], [64711.6, 0.051], [64713.2, 0.216], [64714.0, 0.947], [64714.1, 0.06], [64715.0, 0.494], [64715.8, 0.001], [64716.6, 0.564], [64717.5, 2.589], [64718.0, 0.018], [64718.3, 0.675], [64719.4, 0.004], [64720.3, 0.105], [64874.4, 1.232], [64874.5, 2.616], [65306.4, 0.0], [65343.9, 0.0], [65565.3, 0.002], [65683.2, 0.008]]}
{"kind": "depth", "E": 1787080345349, "U": 11315347944410, "u": 11315347949524, "recv_ms": 1787080345299, "bids": [[1000.0, 35.81], [14196.8, 3.696], [14296.8, 0.252], [14596.8, 0.252], [51757.4, 0.0], [58227.1, 0.002], [61461.9, 0.0], [63696.8, 0.02], [64184.2, 4.666], [64373.3, 2.638], [64556.8, 0.002], [64657.9, 0.003], [64658.4, 2.002], [64689.4, 0.574], [64690.0, 0.162], [64690.1, 0.004], [64691.4, 0.086], [64696.8, 10.249]], "asks": [[64699.3, 0.01], [64701.6, 0.087], [64704.4, 0.044], [64705.7, 0.628], [64706.7, 0.014], [64706.8, 0.008], [64710.3, 0.145], [64713.0, 0.003], [64713.7, 0.009], [64836.9, 0.0], [65343.9, 0.0], [65696.9, 0.03], [65990.8, 0.009], [71166.6, 0.013]]}
{"kind": "depth", "E": 1787080345451, "U": 11315347949685, "u": 11315347955671, "recv_ms": 1787080345402, "bids": [[1000.0, 35.81], [14196.8, 3.556], [14296.8, 0.14], [14596.8, 0.504], [51758.0, 0.0], [58227.1, 0.002], [62108.9, 0.003], [63694.0, 4.316], [63785.4, 11.125], [63854.9, 1.1], [63991.6, 2.888], [64049.8, 0.0], [64556.8, 4.764], [64634.6, 0.002], [64635.0, 0.041], [64635.3, 0.409], [64635.6, 0.234], [64635.9, 0.022], [64653.7, 0.023], [64654.0, 0.005], [64654.4, 1.164], [64654.7, 0.125], [64655.0, 0.025], [64668.7, 0.0], [64668.8, 0.007], [64668.9, 0.003], [64669.0, 0.001], [64669.1, 0.086], [64669.2, 0.124], [64669.3, 0.0], [64669.4, 0.002], [64669.6, 0.022], [64672.0, 0.008], [64672.4, 0.0], [64680.8, 0.929], [64685.0, 0.025], [64687.9, 1.112], [64688.5, 0.544], [64688.7, 0.0], [64688.9, 0.002], [64689.4, 0.566], [64689.5, 0.004], [64689.6, 0.288], [64689.7, 0.135], [64689.8, 1.893], [64690.6, 0.087], [64690.7, 0.002], [64690.8, 0.062], [64690.9, 0.0], [64691.0, 0.257], [64691.1, 0.016], [64691.2, 0.12], [64691.3, 0.001], [64691.4, 0.016], [64691.5, 0.091], [64691.6, 0.0], [64691.8, 0.0], [64692.1, 0.002], [64692.2, 0.002], [64692.5, 0.003], [64692.8, 0.086], [64693.1, 0.005]], "asks": [[64705.6, 0.006], [64705.7, 0.002], [64706.6, 0.004], [64706.8, 0.001], [64706.9, 0.334], [64707.2, 0.009], [64707.6, 0.118], [64707.9, 0.014], [64708.2, 0.005], [64708.3, 0.258], [64708.4, 0.001], [64708.5, 0.466], [64708.6, 2.742], [64708.7, 0.003], [64708.8, 0.006], [64708.9, 0.234], [64709.0, 0.925], [64709.1, 0.001], [64710.3, 0.778], [64713.0, 0.928], [64713.3, 0.002], [64714.0, 0.022], [64718.3, 0.675], [64719.4, 0.004], [64724.8, 1.242], [64725.7, 0.009], [64726.0, 2.328], [64726.3, 0.315], [64726.6, 0.001], [64727.0, 0.073], [64727.4, 0.332], [64727.8, 0.001], [64730.1, 0.033], [64730.3, 0.104], [64730.4, 0.22], [64730.5, 0.964], [64730.6, 0.404], [64730.7, 0.001], [64730.8, 0.002], [64730.9, 0.007], [64731.0, 0.067], [64731.1, 0.466], [64744.7, 0.067], [64745.1, 1.004], [64745.4, 0.316], [64745.7, 0.0], [64746.0, 0.629], [64790.6, 0.1], [64826.3, 0.0], [64835.2, 2.703], [64836.9, 5.398], [64892.7, 3.977], [65279.2, 2.523], [65343.9, 0.0], [65538.0, 2.315]]}
{"kind": "depth", "E": 1787080345553, "U": 11315347955753, "u": 11315347961291, "recv_ms": 1787080345505, "bids": [[14196.8, 3.458], [14296.8, 0.014], [14596.8, 0.728], [58227.1, 0.002], [61461.9, 0.0], [62108.9, 0.006], [63696.8, 0.0], [64049.8, 0.0], [64620.7, 7.426], [64654.3, 0.06], [64663.9, 0.003], [64664.0, 1.225], [64664.1, 0.013], [64667.3, 3.115], [64667.4, 0.006], [64667.5, 0.016], [64677.1, 0.204], [64689.1, 1.34], [64689.2, 0.007], [64689.4, 0.586], [64689.7, 0.016], [64689.9, 0.542], [64690.0, 0.226], [64690.1, 0.012], [64691.0, 0.327], [64691.1, 0.121], [64691.2, 0.19], [64692.2, 0.034], [64695.8, 0.003], [64696.8, 10.267]], "asks": [[64696.9, 14.878], [64699.0, 0.022], [64699.3, 0.002], [64699.6, 0.19], [64704.4, 0.044], [64704.5, 1.19], [64705.7, 0.002], [64706.9, 0.334], [64707.4, 1.505], [64708.4, 0.078], [64708.7, 0.073], [64710.2, 0.026], [64724.6, 0.387], [64726.4, 0.045], [64726.6, 2.587], [64730.2, 0.077], [64730.5, 1.034], [64745.4, 0.354], [64768.3, 6.743], [64769.4, 0.0], [64835.2, 3.46], [65020.4, 2.613], [65343.9, 0.0], [65696.9, 0.01]]}
{"kind": "depth", "E": 1787080345655, "U": 11315347961415, "u": 11315347968875, "recv_ms": 1787080345607, "bids": [[1000.0, 35.81], [14196.8, 3.122], [14296.8, 0.0], [14596.8, 1.078], [58227.1, 0.002], [62108.9, 0.003], [64049.8, 0.0], [64373.3, 2.638], [64620.6, 0.034], [64622.8, 33.461], [64653.9, 0.047], [64654.6, 0.034], [64654.9, 2.351], [64660.9, 0.017], [64663.9, 0.06], [64664.7, 0.0], [64674.5, 0.775], [64677.3, 0.007], [64679.9, 0.943], [64680.8, 0.003], [64681.9, 0.834], [64687.1, 0.546], [64688.5, 0.003], [64689.2, 0.007], [64689.4, 0.558], [64690.0, 0.282], [64690.7, 0.072], [64690.9, 0.07], [64691.1, 0.248], [64691.9, 0.035], [64692.5, 0.035], [64692.9, 0.032], [64694.2, 0.095], [64695.0, 0.004]], "asks": [[64696.9, 14.88], [64699.0, 0.106], [64699.3, 0.157], [64699.9, 0.656], [64704.4, 0.199], [64705.7, 0.157], [64706.8, 0.033], [64706.9, 0.644], [64707.1, 0.5], [64707.8, 0.562], [64708.8, 0.09], [64709.0, 0.995], [64710.2, 0.181], [64713.5, 0.928], [64715.8, 0.058], [64717.3, 0.544], [64717.5, 2.532], [64718.3, 0.134], [64720.8, 0.621], [64724.6, 0.387], [64725.8, 1.45], [64726.1, 0.254], [64726.7, 10.038], [64730.5, 1.118], [64730.8, 0.072], [64744.7, 0.099], [64745.1, 1.042], [64745.7, 0.038], [64806.9, 0.006], [64892.7, 3.514], [65343.9, 0.0], [65499.8, 2.468], [65505.6, 1.926]]}
{"kind": "depth", "E": 1787080345757, "U": 11315347969015, "u": 11315347974022, "recv_ms": 1787080345712, "bids": [[1000.0, 35.81], [14196.8, 2.772], [14596.8, 1.428], [58227.1, 0.002], [61461.9, 0.0], [62108.9, 0.006], [63696.8, 0.02], [64049.8, 0.0], [64327.9, 0.0], [64424.5, 0.0], [64485.0, 2.794], [64485.3, 1.221], [64495.5, 0.0], [64620.7, 0.122], [64621.7, 0.009], [64630.7, 0.04], [64635.3, 0.441], [64655.2, 0.032], [64687.1, 0.005], [64688.0, 2.692], [64689.4, 0.614], [64689.9, 0.598], [64690.0, 0.282], [64690.1, 0.012], [64690.8, 0.132], [64691.0, 0.427], [64691.1, 0.348], [64691.2, 0.4], [64691.3, 0.101], [64691.4, 0.186], [64691.5, 0.191], [64693.2, 0.14], [64696.8, 10.282]], "asks": [[64699.0, 0.098], [64699.3, 0.002], [64704.0, 0.031], [64704.4, 0.044], [64705.0, 0.017], [64705.7, 0.559], [64706.5, 0.033], [64706.8, 0.117], [64706.9, 0.334], [64708.0, 1.123], [64708.1, 0.221], [64708.2, 0.089], [64708.3, 0.498], [64708.5, 0.576], [64708.6, 2.842], [64708.8, 0.167], [64710.2, 0.026], [64710.3, 0.145], [64715.8, 0.001], [64716.6, 0.621], [64717.3, 0.003], [64718.3, 0.675], [64724.6, 0.387], [64725.4, 0.054], [64727.1, 0.14], [64730.0, 0.223], [64730.1, 0.153], [64730.3, 0.214], [64730.4, 0.32], [64730.6, 0.481], [64744.4, 0.032], [64892.3, 0.001], [64912.0, 1.797], [64914.0, 3.047], [64963.7, 0.0], [65061.2, 0.013], [65343.9, 0.0], [65541.0, 2.251], [65596.9, 6.252], [65615.6, 0.242], [65696.9, 0.03], [68228.8, 0.0]]}
{"kind": "depth", "E": 1787080345859, "U": 11315347974025, "u": 11315347979530, "recv_ms": 1787080345812, "bids": [[14196.8, 2.408], [14596.8, 1.792], [51758.0, 0.0], [58227.1, 0.002], [61461.9, 0.0], [63882.5, 2.975], [63955.8, 8.976], [64049.8, 0.0], [64329.1, 0.856], [64425.6, 0.368], [64495.7, 1.816], [64556.8, 0.002], [64618.5, 0.005], [64620.6, 33.123], [64621.7, 0.027], [64622.8, 0.372], [64674.8, 1.197], [64675.5, 0.562], [64676.4, 0.486], [64677.2, 2.435], [64688.4, 0.002], [64689.1, 0.0], [64689.4, 0.01], [64689.5, 0.004], [64689.9, 0.542], [64690.1, 2.111], [64690.2, 0.134], [64690.7, 0.142], [64690.9, 0.14], [64691.1, 0.448], [64691.2, 0.29], [64691.3, 0.311], [64691.6, 0.07], [64696.8, 10.295]], "asks": [[64699.3, 0.002], [64705.6, 0.006], [64705.7, 0.002], [64706.8, 0.048], [64706.9, 0.968], [64708.0, 1.221], [64708.5, 0.686], [64708.6, 2.972], [64708.8, 0.258], [64708.9, 0.311], [64711.6, 0.043], [64712.0, 0.003], [64715.8, 0.557], [64716.6, 0.065], [64724.6, 0.233], [64727.5, 0.131], [64729.8, 0.103], [64730.2, 0.187], [64730.6, 0.572], [64730.7, 0.078], [64743.5, 0.044], [64835.2, 2.703], [64836.9, 0.0], [64890.5, 0.859], [64963.6, 0.35], [65059.8, 0.963], [65343.9, 0.0], [66289.4, 0.002]]}
{"kind": "depth", "E": 1787080345961, "U": 11315347979537, "u": 11315347984378, "recv_ms": 1787080345918, "bids": [[1000.0, 35.81], [14196.8, 2.058], [14596.8, 2.142], [58227.1, 0.002], [62108.9, 0.003], [63696.8, 0.0], [63952.8, 0.937], [64049.8, 0.0], [64064.3, 0.0], [64108.5, 0.004], [64182.2, 6.251], [64212.0, 0.0], [64373.3, 2.638], [64473.2, 6.294], [64495.6, 3.006], [64556.8, 4.764], [64635.0, 0.073], [64635.6, 0.266], [64635.9, 0.054], [64669.2, 0.194], [64669.5, 0.073], [64689.4, 0.002], [64690.0, 0.162], [64690.1, 1.999], [64690.2, 0.344], [64690.3, 0.1], [64691.3, 0.101]], "asks": [[64699.0, 0.106], [64705.6, 0.469], [64705.7, 0.644], [64706.8, 0.04], [64706.9, 0.334], [64707.0, 2.262], [64712.1, 0.002], [64724.6, 0.233], [64724.7, 0.275], [64836.9, 5.398], [64892.2, 0.0], [64892.7, 3.978], [64894.9, 1.763], [65178.3, 0.004], [65328.2, 0.0], [65343.9, 0.0], [65476.3, 29.054], [65505.6, 2.185], [65602.7, 5.208], [65696.9, 0.01], [66315.6, 0.0], [68228.8, 0.076]]}
{"kind": "depth", "E": 1787080346063, "U": 11315347984459, "u": 11315347989456, "recv_ms": 1787080346013, "bids": [[1000.0, 35.81], [14196.8, 1.694], [14596.8, 2.506], [58227.1, 0.002], [62108.9, 0.006], [64049.8, 0.0], [64114.0, 5.124], [64179.2, 4.518], [64328.1, 40.48], [64329.1, 6.846], [64373.3, 2.639], [64424.7, 32.256], [64425.6, 5.135], [64495.7, 28.073], [64636.3, 0.037], [64651.5, 0.189], [64668.9, 0.073], [64669.1, 0.156], [64685.2, 0.464], [64690.2, 0.239]], "asks": [[64699.0, 0.014], [64705.4, 0.004], [64705.5, 0.0], [64705.6, 0.013], [64705.7, 1.115], [64706.8, 0.033], [64706.9, 0.334], [64712.1, 0.002], [64755.2, 0.319], [64806.9, 0.003], [64893.6, 26.352], [64965.0, 33.099], [65020.4, 2.612], [65021.5, 0.33], [65023.4, 2.311], [65059.8, 6.948], [65062.4, 41.309], [65343.9, 0.002], [65538.0, 2.62]]}
{"kind": "depth", "E": 1787080346165, "U": 11315347989457, "u": 11315347993753, "recv_ms": 1787080346117, "bids": [[14196.8, 1.344], [14596.8, 2.856], [51758.0, 0.0], [58227.1, 0.002], [62108.9, 0.003], [63696.8, 0.02], [64049.8, 0.0], [64617.5, 0.005], [64620.6, 0.034], [64621.7, 0.009], [64622.8, 33.461], [64624.4, 0.003], [64644.6, 0.003], [64647.7, 0.002], [64654.0, 0.006], [64669.0, 0.071], [64669.2, 0.294], [64669.3, 0.1], [64669.5, 0.173], [64669.6, 0.122], [64669.7, 0.126], [64672.5, 0.102], [64674.6, 0.559], [64675.5, 0.005], [64676.4, 0.602], [64677.2, 2.319], [64679.9, 0.017], [64680.9, 1.239], [64687.7, 0.238], [64689.3, 0.334], [64690.2, 0.19], [64691.3, 0.101]], "asks": [[64705.9, 0.042], [64714.9, 2.527], [64715.8, 0.001], [64715.9, 0.577], [64717.3, 0.003], [64718.3, 0.675], [64719.2, 0.056], [64720.1, 2.443], [65023.4, 2.157], [65179.6, 51.641], [65217.5, 9.368], [65329.5, 63.113], [65343.9, 0.0], [65696.9, 0.03], [66323.0, 2.214]]}
{"kind": "depth", "E": 1787080346267, "U": 11315347993865, "u": 11315347997837, "recv_ms": 1787080346219, "bids": [[1000.0, 35.81], [14196.8, 0.98], [14596.8, 3.22], [51757.0, 0.002], [51758.0, 0.0], [58227.1, 0.002], [61461.9, 0.0], [62108.9, 0.006], [64049.8, 0.0], [64373.3, 2.639], [64445.5, 2.616], [64447.0, 1.754], [64473.2, 6.078], [64495.8, 0.216], [64618.5, 33.166], [64622.8, 0.372], [64668.9, 0.143], [64669.1, 0.226], [64669.4, 0.102], [64669.8, 0.073], [64672.1, 0.137], [64677.2, 7.319], [64690.2, 0.134], [64691.3, 0.101], [64691.4, 0.186], [64691.5, 0.191], [64691.6, 0.175], [64696.8, 10.344]], "asks": [[64699.3, 0.002], [64702.0, 0.1], [64705.6, 0.013], [64706.9, 0.334], [64711.6, 0.043], [64826.5, 0.004], [64892.7, 0.007], [64893.5, 0.217], [64894.9, 1.547], [64895.0, 57.535], [64953.5, 2.616], [65020.4, 2.766], [65343.9, 0.0], [65473.3, 9.392], [65715.3, 4.771]]}
{"kind": "depth", "E": 1787080346369, "U": 11315347997913, "u": 11315348004092, "recv_ms": 1787080346320, "bids": [[1000.0, 35.81], [14196.8, 0.63], [14596.8, 3.57], [51757.0, 0.0], [51757.4, 0.0], [58227.1, 0.002], [61461.9, 0.0], [61462.0, 0.008], [63402.9, 0.907], [63696.8, 0.0], [63825.6, 1.25], [63923.4, 38.28], [64049.8, 0.0], [64108.9, 9.035], [64556.8, 0.002], [64618.5, 0.005], [64620.7, 33.283], [64691.3, 0.101], [64691.4, 0.186], [64691.5, 0.191], [64691.6, 0.175], [64696.8, 10.365]], "asks": [[64699.3, 0.002], [64705.6, 0.013], [64706.9, 0.334], [64711.6, 0.043], [64826.3, 0.0], [64836.9, 0.0], [64892.7, 4.359], [64895.0, 50.853], [65020.4, 2.92], [65214.5, 0.915], [65343.9, 0.0], [65696.9, 0.01]]}
{"kind": "depth", "E": 1787080346471, "U": 11315348004216, "u": 11315348008717, "recv_ms": 1787080346423, "bids": [[14196.8, 0.35], [14496.8, 0.084], [14596.8, 3.766], [58227.1, 0.002], [61464.9, 0.002], [62108.9, 0.003], [64049.8, 0.0], [64556.8, 4.433], [64647.6, 0.667], [64680.8, 0.003], [64691.3, 0.101], [64691.4, 0.186], [64691.5, 0.191], [64691.6, 0.175]], "asks": [[64713.3, 0.002], [64836.9, 5.398], [65020.4, 2.919], [65343.9, 0.0], [65699.7, 1.519], [65813.6, 0.0], [65878.3, 0.0]]}
{"kind": "depth", "E": 1787080346573, "U": 11315348008873, "u": 11315348013979, "recv_ms": 1787080346525, "bids": [[1000.0, 35.81], [14196.8, 0.224], [14496.8, 0.308], [14596.8, 3.668], [58227.1, 0.002], [62108.9, 0.006], [63696.8, 0.02], [63810.4, 0.625], [63920.4, 5.608], [64049.8, 0.0], [64114.5, 1.091], [64373.3, 2.65], [64620.8, 8.575], [64691.3, 0.206], [64691.4, 0.186], [64691.5, 0.191], [64691.6, 0.07], [64693.6, 0.023], [64693.8, 0.106]], "asks": [[64699.0, 0.014], [64705.6, 0.021], [64705.7, 1.107], [64739.3, 1.412], [64739.4, 3.5], [64761.6, 1.613], [64782.3, 2.887], [64835.2, 3.46], [64890.5, 1.417], [64892.7, 0.007], [64895.0, 59.877], [65343.9, 0.002], [65696.9, 0.03]]}
