{"kind": "depth", "E": 1787080291595, "U": 11315344028097, "u": 11315344039152, "recv_ms": 1787080291557, "bids": [[1000.0, 35.81], [14199.8, 3.332], [14299.8, 0.0], [14599.8, 0.868], [51759.8, 0.0], [58229.8, 0.002], [61464.8, 0.004], [62111.8, 0.517], [62748.7, 0.682], [63405.9, 0.019], [63664.6, 4.831], [63923.4, 23.903], [64052.8, 1.739], [64376.3, 4.043], [64595.2, 11.545], [64599.5, 0.003], [64599.6, 0.004], [64658.5, 0.615], [64659.6, 0.339], [64666.6, 0.046], [64675.6, 0.0], [64676.5, 0.133], [64676.6, 0.001], [64683.0, 0.002], [64691.7, 0.086], [64692.1, 0.084], [64692.4, 0.0], [64693.3, 0.417], [64693.9, 0.007], [64694.9, 0.0], [64695.3, 0.002], [64695.9, 0.001], [64699.8, 3.381]], "asks": [[64699.9, 26.314], [64700.0, 1.201], [64700.2, 0.002], [64700.3, 0.008], [64704.6, 0.003], [64704.7, 0.002], [64704.8, 0.482], [64705.6, 0.656], [64707.6, 0.303], [64710.4, 0.009], [64710.5, 3.482], [64711.6, 0.043], [64712.0, 0.003], [64712.1, 0.002], [64713.0, 10.04], [64719.3, 1.047], [64719.5, 6.325], [64720.6, 0.095], [64725.8, 3.118], [64727.8, 0.001], [64727.9, 1.886], [64733.2, 0.003], [64764.6, 0.004], [64772.3, 1.251], [64774.5, 0.054], [64776.7, 40.114], [64793.9, 3.878], [64794.0, 10.066], [64794.2, 0.529], [64817.8, 0.003], [65023.4, 4.001], [65346.9, 3.625], [65735.1, 7.414], [65909.8, 3.33], [71169.9, 0.0]]}
{"kind": "depth", "E": 1787080291799, "U": 11315344047195, "u": 11315344053861, "recv_ms": 1787080291815, "bids": [[14199.8, 2.618], [14599.8, 1.582], [51760.0, 0.004], [58229.8, 0.002], [62111.8, 0.517], [63664.6, 5.929], [64052.8, 1.739], [64622.9, 3.939], [64625.0, 34.202], [64681.9, 0.026], [64683.6, 0.353], [64683.8, 0.022], [64688.0, 2.218], [64689.2, 0.315], [64689.3, 0.564]], "asks": [[64699.9, 25.571], [64700.0, 1.198], [64700.3, 0.011], [64704.8, 0.019], [64705.0, 0.485], [64707.6, 0.303], [64710.4, 0.009], [64712.1, 0.002], [64712.7, 0.011], [64716.3, 0.163], [64718.3, 0.134], [64719.1, 0.578], [64719.2, 0.004], [64726.3, 0.201], [64733.7, 0.0], [64772.3, 41.343], [64774.5, 0.054], [65346.9, 3.625], [65735.1, 9.541], [66100.0, 33.81]]}
{"kind": "depth", "E": 1787080291901, "U": 11315344054363, "u": 11315344066102, "recv_ms": 1787080291853, "bids": [[1000.0, 35.81], [14199.8, 2.268], [14599.8, 1.932], [58229.8, 0.002], [61464.8, 0.004], [63699.8, 0.031], [63876.7, 4.331], [63976.3, 1.572], [64052.8, 1.739], [64182.2, 7.968], [64376.3, 3.888], [64622.9, 3.939], [64624.7, 0.0], [64625.0, 34.202], [64625.1, 6.116], [64662.1, 0.344], [64663.4, 0.0], [64680.2, 0.134], [64681.5, 0.976], [64683.6, 0.355], [64683.8, 0.024], [64691.1, 0.018], [64691.5, 0.017], [64691.7, 0.002], [64692.0, 0.012], [64692.8, 0.089], [64695.0, 0.088], [64695.4, 0.084], [64695.8, 0.087], [64699.8, 4.748]], "asks": [[64699.9, 25.51], [64701.4, 0.004], [64704.8, 0.019], [64704.9, 1.412], [64707.6, 0.303], [64710.4, 0.009], [64712.1, 0.002], [64712.7, 0.011], [64713.3, 0.0], [64713.9, 0.932], [64716.3, 0.165], [64716.9, 0.003], [64717.5, 2.589], [64717.9, 0.094], [64758.4, 1.906], [65346.9, 3.625], [65699.9, 0.951]]}
{"kind": "depth", "E": 1787080292105, "U": 11315344074989, "u": 11315344082841, "recv_ms": 1787080292056, "bids": [[14199.8, 1.554], [14599.8, 2.646], [51760.0, 0.004], [58229.8, 0.002], [62111.8, 0.517], [63405.9, 0.022], [63706.4, 0.027], [63748.7, 6.26], [63771.1, 0.0], [63773.4, 0.001], [63923.4, 22.029], [64052.8, 1.739], [64182.2, 8.279], [64376.3, 4.043], [64503.6, 8.766], [64559.4, 3.164], [64613.4, 0.094], [64688.2, 0.001], [64692.0, 0.011], [64692.1, 0.085], [64693.2, 0.085], [64699.8, 5.612]], "asks": [[64699.9, 25.525], [64701.8, 0.002], [64702.3, 0.012], [64704.5, 0.012], [64706.2, 0.002], [64706.6, 1.021], [64707.6, 0.303], [64710.4, 0.009], [64712.1, 0.002], [64712.7, 0.011], [64719.5, 1.325], [64764.6, 0.022], [64895.6, 8.942], [65346.9, 3.625], [65626.2, 0.0], [65628.5, 0.763], [65693.2, 0.787], [65993.8, 0.056]]}
{"kind": "depth", "E": 1787080292207, "U": 11315344083320, "u": 11315344090639, "recv_ms": 1787080292158, "bids": [[1000.0, 35.81], [14199.8, 1.19], [14599.8, 3.01], [51760.0, 0.004], [58229.8, 0.002], [61464.8, 0.004], [62111.8, 0.52], [63697.0, 14.115], [63706.4, 0.046], [63761.7, 19.579], [63771.1, 0.008], [63773.4, 0.009], [63876.7, 3.98], [63955.8, 6.165], [64052.8, 1.739], [64376.3, 4.033], [64542.4, 7.859], [64559.4, 3.913], [64620.3, 2.323], [64627.6, 0.029], [64639.0, 0.55], [64648.4, 0.002], [64650.9, 0.012], [64657.3, 0.005], [64688.0, 2.217], [64691.8, 0.0]], "asks": [[64699.9, 25.527], [64704.5, 0.012], [64707.6, 0.303], [64708.3, 0.479], [64710.4, 0.009], [64712.1, 0.002], [64712.7, 0.011], [64893.9, 12.842], [64895.6, 8.301], [65346.9, 3.626], [65469.8, 8.235], [65670.4, 4.113]]}
{"kind": "depth", "E": 1787080292309, "U": 11315344090774, "u": 11315344103170, "recv_ms": 1787080292266, "bids": [[1000.0, 35.81], [14199.8, 0.826], [14599.8, 3.374], [51760.0, 0.004], [58229.8, 0.002], [62111.8, 0.517], [63699.8, 0.031], [63761.7, 20.675], [63858.7, 4.162], [63955.8, 7.102], [64052.8, 1.739]], "asks": [[64700.9, 0.026], [64701.1, 0.005], [65314.5, 5.561], [65346.9, 3.626], [65508.6, 7.399], [65575.1, 0.0], [65626.2, 0.008], [65628.5, 0.771], [65693.2, 0.806], [65699.9, 0.951]]}
{"kind": "depth", "E": 1787080292411, "U": 11315344103261, "u": 11315344110291, "recv_ms": 1787080292363, "bids": [[14199.8, 0.49], [14499.8, 0.014], [14599.8, 3.696], [58229.8, 0.002], [61464.8, 0.008], [63697.0, 15.213], [63761.7, 21.772], [63923.4, 23.434], [64052.8, 1.739], [64376.3, 4.032], [64664.4, 0.001], [64665.8, 2.218], [64675.5, 0.559], [64676.3, 0.002], [64677.1, 2.577], [64677.7, 0.004], [64677.9, 0.231], [64678.7, 0.387], [64680.7, 0.168], [64681.5, 0.05], [64681.6, 0.516], [64681.8, 0.926], [64683.4, 0.72], [64684.4, 0.028], [64688.4, 0.002], [64689.3, 0.023], [64689.6, 0.158], [64689.7, 0.611], [64689.8, 0.209], [64691.5, 0.017], [64692.1, 0.0], [64692.5, 0.005], [64694.1, 0.085], [64695.6, 1.572], [64696.1, 0.001], [64696.3, 0.543], [64696.7, 1.691], [64697.9, 0.005], [64699.8, 7.785]], "asks": [[64699.9, 25.487], [64700.3, 0.008], [64700.5, 0.006], [64701.4, 0.004], [64701.9, 0.004], [64702.6, 0.31], [64703.4, 0.471], [64704.5, 0.012], [64704.6, 0.003], [64704.8, 0.088], [64707.6, 0.303], [64708.3, 0.478], [64710.4, 0.009], [64710.5, 2.146], [64711.2, 0.001], [64712.1, 0.473], [64712.7, 0.011], [64713.0, 0.042], [64769.8, 0.009], [64770.1, 40.093], [64772.3, 1.251], [64829.3, 2.322], [65338.9, 0.033], [65346.9, 3.626], [65993.8, 0.059]]}
{"kind": "depth", "E": 1787080292513, "U": 11315344110474, "u": 11315344115891, "recv_ms": 1787080292464, "bids": [[1000.0, 35.81], [14199.8, 0.294], [14499.8, 0.168], [14599.8, 3.738], [58229.8, 0.002], [61464.8, 0.006], [61464.9, 0.006], [62111.8, 0.52], [63699.8, 0.011], [63848.5, 0.784], [63955.8, 8.039], [64052.8, 1.739], [64376.3, 4.032], [64660.9, 0.02], [64678.1, 0.012], [64678.7, 0.38], [64681.6, 0.053], [64689.8, 0.672], [64691.5, 0.141], [64692.1, 0.0], [64692.5, 0.005], [64692.8, 0.09], [64692.9, 0.468], [64694.1, 0.084], [64694.2, 0.004], [64694.3, 0.003]], "asks": [[64700.5, 0.025], [65023.4, 4.0], [65346.9, 3.626], [65478.8, 0.791], [65585.9, 7.298], [65699.9, 0.931]]}
{"kind": "depth", "E": 1787080292615, "U": 11315344116123, "u": 11315344122459, "recv_ms": 1787080292566, "bids": [[1000.0, 35.81], [14199.8, 0.182], [14499.8, 0.42], [14599.8, 3.598], [51759.8, 0.0], [58229.8, 0.002], [61464.8, 0.006], [62111.8, 0.517], [63405.9, 0.019], [63664.6, 5.929], [63737.9, 0.0], [63761.7, 20.675], [63776.9, 3.93], [63923.4, 23.903], [64052.8, 1.739], [64376.3, 4.033], [64578.2, 0.461], [64578.9, 3.866], [64591.3, 0.001], [64628.4, 0.046], [64629.9, 0.027], [64645.3, 3.597], [64645.4, 0.015], [64653.7, 2.15], [64654.2, 0.004], [64660.3, 0.002], [64662.0, 2.16], [64662.1, 0.008], [64666.3, 1.289], [64677.0, 0.98], [64678.2, 0.024], [64678.5, 5.005], [64689.0, 0.542], [64689.7, 0.07], [64691.3, 0.599], [64692.1, 0.001], [64692.5, 0.003], [64692.8, 0.005], [64693.2, 0.086], [64694.3, 0.002], [64695.0, 0.398], [64695.6, 0.004], [64696.8, 0.083], [64697.3, 0.085], [64697.9, 0.004], [64698.4, 0.0], [64699.7, 0.046], [64699.8, 8.443]], "asks": [[64699.9, 25.213], [64700.4, 0.001], [64700.5, 0.003], [64700.7, 0.003], [64700.8, 0.012], [64700.9, 0.006], [64701.0, 0.05], [64701.2, 0.0], [64703.4, 0.161], [64704.6, 0.087], [64704.8, 0.166], [64705.0, 0.106], [64705.5, 0.0], [64705.6, 0.011], [64705.7, 1.061], [64707.5, 0.649], [64707.6, 0.613], [64710.4, 0.319], [64711.1, 0.467], [64712.1, 0.628], [64712.7, 0.004], [64713.6, 0.097], [64722.2, 10.969], [64725.4, 0.024], [64738.1, 0.002], [64743.9, 0.004], [64767.2, 0.509], [64769.8, 0.0], [64770.9, 0.048], [64795.5, 2.123], [64795.6, 3.812], [64803.9, 2.238], [64804.0, 0.003], [64812.2, 2.749], [64812.3, 2.319], [64835.1, 8.092], [65023.4, 4.001], [65346.9, 3.626], [65602.0, 0.611], [65638.0, 24.615], [65993.8, 0.056]]}
{"kind": "depth", "E": 1787080292717, "U": 11315344122515, "u": 11315344129345, "recv_ms": 1787080292669, "bids": [[14199.8, 0.056], [14499.8, 0.658], [14599.8, 3.486], [58229.8, 0.002], [62111.8, 0.52], [63397.4, 0.066], [63469.3, 0.058], [63541.1, 0.058], [63613.0, 0.059], [63684.9, 0.058], [63699.8, 0.031], [63756.8, 0.107], [63828.7, 0.105], [63900.5, 0.082], [63929.9, 8.433], [63972.4, 0.184], [64044.3, 6.25], [64052.8, 1.739], [64618.5, 32.741], [64625.0, 1.59], [64625.1, 0.0], [64663.4, 0.0], [64670.8, 0.006], [64691.3, 0.6], [64692.1, 0.0], [64692.3, 0.002], [64695.0, 0.088], [64695.1, 0.045], [64697.3, 0.001], [64697.9, 0.005], [64699.7, 0.045], [64699.8, 7.786]], "asks": [[64700.0, 1.282], [64700.4, 0.085], [64700.8, 0.096], [64701.2, 0.104], [64701.3, 0.9], [64702.8, 0.097], [64703.1, 0.416], [64704.6, 0.003], [64704.8, 0.011], [64704.9, 1.005], [64705.0, 0.022], [64705.7, 1.064], [64705.8, 2.32], [64707.4, 0.134], [64707.6, 0.303], [64710.4, 0.009], [64712.0, 0.003], [64712.1, 0.473], [64720.0, 3.938], [64725.4, 0.028], [64741.4, 0.545], [64767.2, 0.5], [64770.1, 0.001], [64772.3, 41.523], [64774.5, 0.054], [65314.5, 6.324], [65338.1, 0.246], [65346.9, 3.626], [65410.0, 0.579], [65481.9, 0.077], [65553.7, 0.059], [65573.3, 4.691], [65625.6, 0.059], [65697.5, 0.058], [65699.9, 0.951], [65769.4, 0.133], [65841.3, 0.058], [65913.1, 0.058], [65985.0, 6.201]]}
{"kind": "depth", "E": 1787080292819, "U": 11315344129382, "u": 11315344136157, "recv_ms": 1787080292769, "bids": [[1000.0, 35.81], [14199.8, 0.0], [14499.8, 0.952], [14599.8, 3.248], [58229.8, 0.002], [64052.8, 1.739], [64109.0, 7.72], [64376.3, 4.043], [64618.5, 0.005], [64622.1, 0.021], [64622.9, 36.675], [64625.0, 1.59], [64654.5, 0.004], [64693.0, 0.19], [64696.7, 1.775]], "asks": [[64745.2, 0.005], [65346.9, 3.626], [65638.0, 25.68]]}
{"kind": "depth", "E": 1787080292921, "U": 11315344136221, "u": 11315344141316, "recv_ms": 1787080292871, "bids": [[1000.0, 35.81], [14499.8, 1.302], [14599.8, 2.898], [58229.8, 0.002], [62111.8, 0.517], [63699.8, 0.011], [63761.7, 21.772], [63929.9, 9.37], [64052.8, 1.739], [64085.2, 8.608], [64559.4, 0.154], [64622.9, 36.675], [64625.0, 1.59], [64625.1, 0.0], [64681.4, 1.754], [64683.8, 0.024], [64685.0, 0.015], [64686.8, 0.031], [64687.9, 2.052], [64692.3, 0.19], [64693.0, 0.002]], "asks": [[64707.4, 0.142], [64707.5, 0.641], [64712.0, 0.003], [64716.3, 0.165], [64772.2, 7.032], [64839.8, 2.319], [65346.9, 3.626], [65586.3, 0.613], [65699.9, 0.931]]}
{"kind": "depth", "E": 1787080293125, "U": 11315344147009, "u": 11315344154449, "recv_ms": 1787080293080, "bids": [[1000.0, 35.96], [14499.8, 2.03], [14599.8, 2.17], [51760.0, 0.004], [58229.8, 0.002], [61464.8, 0.006], [62111.8, 0.517], [63699.8, 0.031], [63706.4, 0.036], [64052.8, 1.739], [64376.3, 4.033], [64613.6, 1.546], [64620.5, 6.963], [64622.1, 0.024], [64627.7, 0.003], [64651.0, 0.013], [64657.4, 0.002], [64666.9, 0.327], [64667.0, 0.009], [64667.1, 0.311], [64670.3, 0.349], [64670.4, 1.324], [64670.5, 0.738], [64687.5, 0.309], [64687.9, 1.743], [64688.2, 0.001], [64688.5, 0.004], [64692.3, 0.002], [64696.6, 0.003], [64698.8, 0.0], [64699.3, 0.003], [64699.8, 7.787]], "asks": [[64699.9, 25.301], [64700.3, 0.001], [64700.7, 0.007], [64702.8, 0.097], [64705.1, 0.503], [64707.4, 0.142], [64707.6, 0.303], [64710.4, 0.009], [64712.1, 0.473], [64719.3, 0.976], [64809.9, 0.004], [65346.9, 3.626], [65508.6, 7.627], [65564.6, 8.485], [65693.2, 0.796], [65699.9, 0.951]]}
{"kind": "depth", "E": 1787080293227, "U": 11315344154517, "u": 11315344160654, "recv_ms": 1787080293179, "bids": [[1000.0, 35.81], [14499.8, 2.38], [14599.8, 1.82], [58229.8, 0.002], [61464.8, 0.008], [61464.9, 0.004], [62111.8, 0.52], [63427.5, 0.675], [63664.6, 4.831], [63706.5, 0.165], [63761.7, 20.676], [63976.3, 2.353], [64052.8, 1.739], [64373.9, 0.158], [64432.6, 0.009], [64613.6, 1.547], [64645.4, 0.043], [64648.5, 0.102], [64651.0, 0.014], [64657.4, 0.003], [64662.5, 0.337], [64665.2, 0.077], [64665.8, 2.161], [64666.3, 0.953], [64675.2, 0.045], [64675.9, 0.637], [64676.2, 0.083], [64676.7, 0.002], [64677.6, 0.168], [64677.9, 0.231], [64681.2, 0.93], [64681.8, 0.0], [64689.9, 0.203], [64691.4, 1.686], [64693.0, 1.844], [64696.6, 0.004], [64696.7, 1.691], [64697.6, 0.008], [64697.9, 0.004], [64699.8, 5.617]], "asks": [[64699.9, 25.303], [64702.8, 0.252], [64705.1, 0.502], [64707.3, 0.312], [64707.4, 0.297], [64707.6, 0.303], [64710.4, 0.474], [64712.1, 0.628], [64718.4, 12.283], [64895.6, 9.791], [65346.9, 3.625], [65638.0, 24.615], [65693.3, 0.78], [65735.1, 8.478], [65993.8, 0.059]]}
{"kind": "depth", "E": 1787080293329, "U": 11315344160734, "u": 11315344166304, "recv_ms": 1787080293279, "bids": [[14499.8, 2.73], [14599.8, 1.47], [58229.8, 0.002], [63632.3, 4.396], [63699.8, 0.011], [64052.8, 1.739], [64685.7, 0.316], [64691.3, 0.052], [64691.5, 0.001], [64692.9, 0.0], [64693.1, 0.734], [64693.4, 0.16], [64693.5, 0.587]], "asks": [[64702.8, 0.097], [64705.6, 0.011], [64707.3, 0.041], [64707.4, 0.366], [64707.5, 0.541], [64710.4, 0.164], [64712.1, 0.465], [64741.4, 0.503], [65346.9, 3.625], [65469.8, 7.32], [65573.3, 5.071], [65699.9, 0.931], [65767.4, 5.315]]}
{"kind": "depth", "E": 1787080293635, "U": 11315344179118, "u": 11315344186588, "recv_ms": 1787080293590, "bids": [[14399.8, 0.042], [14499.8, 3.724], [14599.8, 0.434], [51759.8, 0.0], [51760.0, 0.004], [58229.8, 0.002], [62111.8, 0.517], [63697.0, 15.213], [64052.8, 1.739], [64376.3, 4.042], [64627.3, 0.003], [64688.4, 0.465], [64688.5, 0.661], [64689.1, 0.008], [64689.5, 0.141], [64689.8, 0.201], [64691.2, 1.208], [64691.3, 0.036], [64691.4, 1.609], [64691.5, 0.001], [64693.2, 0.086], [64693.4, 0.137], [64693.5, 0.046], [64699.8, 5.609]], "asks": [[64702.8, 0.097], [64705.6, 0.011], [64707.3, 0.002], [64707.4, 0.242], [64707.6, 0.303], [64710.4, 0.009], [64712.1, 0.473], [65023.4, 4.0], [65346.9, 3.627], [65469.8, 8.235]]}
{"kind": "depth", "E": 1787080294043, "U": 11315344212664, "u": 11315344219465, "recv_ms": 1787080293994, "bids": [[1000.0, 35.81], [14399.8, 1.036], [14499.8, 3.164], [14599.8, 0.0], [58229.8, 0.002], [61464.8, 0.008], [62111.8, 0.52], [64052.8, 1.739], [64376.3, 4.033], [64559.5, 3.787], [64589.8, 0.003], [64622.1, 0.021], [64633.4, 0.579], [64633.8, 0.001], [64634.1, 0.0], [64634.4, 0.03], [64634.7, 0.051], [64652.5, 1.867], [64652.8, 0.394], [64653.2, 0.0], [64653.5, 0.074], [64653.8, 0.011], [64654.5, 0.001], [64667.5, 0.071], [64667.6, 0.697], [64667.7, 0.156], [64667.8, 0.011], [64667.9, 0.0], [64668.0, 0.005], [64668.1, 2.321], [64668.2, 2.21], [64668.4, 0.161], [64670.7, 0.316], [64671.2, 0.002], [64678.8, 0.0], [64686.2, 0.061], [64688.2, 0.006], [64688.4, 0.002], [64688.5, 0.012], [64689.1, 0.548], [64689.3, 1.858], [64689.4, 0.543], [64689.5, 0.009], [64689.6, 0.018], [64689.7, 0.0], [64689.8, 0.001], [64689.9, 0.003], [64690.0, 0.008], [64690.1, 0.004], [64690.2, 0.002], [64690.3, 0.271], [64690.4, 0.001], [64690.5, 0.339], [64690.7, 0.002], [64691.0, 0.001], [64691.3, 0.004], [64691.6, 0.0], [64691.9, 0.003], [64693.2, 0.086], [64693.4, 0.137], [64695.2, 0.025], [64699.8, 5.608]], "asks": [[64702.8, 0.097], [64706.3, 0.004], [64706.6, 0.989], [64706.9, 0.02], [64707.2, 0.009], [64707.3, 0.635], [64707.4, 0.142], [64707.5, 0.0], [64707.6, 0.265], [64707.8, 0.262], [64707.9, 1.155], [64708.0, 0.906], [64708.1, 0.093], [64708.2, 0.148], [64708.3, 0.258], [64708.4, 0.001], [64708.5, 0.466], [64708.6, 2.772], [64708.7, 0.045], [64708.8, 0.121], [64710.2, 0.026], [64710.4, 0.009], [64711.9, 0.01], [64712.1, 0.473], [64716.7, 0.005], [64724.1, 0.001], [64725.3, 0.347], [64725.7, 0.009], [64726.0, 2.325], [64726.3, 0.163], [64726.6, 0.001], [64727.0, 0.073], [64727.4, 0.338], [64729.8, 0.003], [64730.0, 0.02], [64730.1, 0.033], [64730.2, 0.12], [64730.3, 0.024], [64730.4, 0.22], [64730.5, 0.007], [64730.6, 0.404], [64730.7, 0.001], [64730.8, 0.058], [64741.0, 0.002], [64744.4, 0.002], [64744.7, 0.067], [64745.0, 2.321], [64745.2, 0.005], [64745.4, 0.313], [64745.7, 0.0], [64809.9, 0.001], [64839.8, 7.717], [64895.6, 8.132], [65022.2, 0.13], [65346.9, 3.625], [65551.2, 0.769], [65629.3, 14.497], [66640.7, 0.043]]}
{"kind": "depth", "E": 1787080294247, "U": 11315344227328, "u": 11315344241314, "recv_ms": 1787080294198, "bids": [[14399.8, 1.75], [14499.8, 2.45], [58229.8, 0.002], [63929.9, 9.37], [64052.8, 1.739], [64648.6, 0.126], [64652.9, 0.138], [64653.6, 0.15], [64653.9, 0.047], [64688.5, 0.003], [64689.1, 0.471], [64689.3, 1.835], [64689.5, 0.001], [64689.9, 0.073], [64690.1, 0.074], [64690.4, 0.101], [64691.1, 0.048], [64691.5, 0.094], [64691.7, 0.034], [64692.1, 0.032], [64693.4, 0.16]], "asks": [[64699.9, 25.312], [64702.8, 0.097], [64706.7, 0.035], [64707.0, 0.5], [64707.5, 0.0], [64707.6, 0.303], [64707.8, 0.262], [64708.3, 0.368], [64708.6, 2.842], [64708.8, 0.198], [64710.4, 0.009], [64711.6, 0.051], [64712.1, 0.473], [64712.6, 0.004], [64725.7, 0.041], [64726.1, 0.254], [64726.7, 0.038], [64730.3, 0.134], [64730.5, 0.177], [64730.8, 0.135], [64744.8, 0.341], [64745.1, 1.042], [64745.8, 0.284], [65346.9, 3.627], [65461.0, 0.039], [65533.0, 1.623], [65638.0, 26.745], [65735.1, 8.477]]}
{"kind": "depth", "E": 1787080294451, "U": 11315344248845, "u": 11315344255238, "recv_ms": 1787080294405, "bids": [[14399.8, 2.464], [14499.8, 1.736], [51760.0, 0.004], [58229.8, 0.002], [62111.8, 0.517], [63405.9, 0.025], [63824.2, 0.0], [64052.8, 1.739], [64634.2, 0.165], [64668.5, 0.136], [64689.4, 0.095], [64690.7, 0.102], [64691.3, 0.003], [64691.5, 0.001], [64692.1, 0.033], [64693.2, 0.086], [64693.4, 0.16], [64693.5, 0.587]], "asks": [[64708.0, 1.046], [64727.1, 0.345], [64829.3, 2.322], [65346.9, 3.625], [65469.8, 9.15]]}
{"kind": "depth", "E": 1787080294655, "U": 11315344261382, "u": 11315344265998, "recv_ms": 1787080294611, "bids": [[1000.0, 35.81], [14399.8, 3.178], [14499.8, 1.022], [51759.8, 0.0], [51760.0, 0.004], [58229.8, 0.002], [61464.8, 0.008], [61464.9, 0.006], [62111.8, 0.517], [64052.8, 1.739], [64376.3, 4.033], [64635.2, 1.134], [64668.2, 2.38], [64668.4, 0.261], [64689.5, 0.001], [64691.5, 0.04], [64693.2, 0.086]], "asks": [[64707.6, 0.311], [64712.0, 0.011], [64895.6, 2.751], [65023.4, 4.001], [65346.9, 3.625]]}
{"kind": "depth", "E": 1787080294757, "U": 11315344266106, "u": 11315344271482, "recv_ms": 1787080294709, "bids": [[14399.8, 3.542], [14499.8, 0.658], [58229.8, 0.002], [63697.0, 14.117], [63699.8, 0.031], [63761.7, 20.832], [63800.5, 5.888], [63966.6, 0.031], [64052.8, 1.739], [64667.9, 0.14], [64668.1, 2.461], [64668.5, 0.206], [64675.5, 0.559], [64676.5, 0.001], [64677.1, 2.577], [64677.6, 0.067], [64680.7, 1.094], [64681.2, 0.004], [64688.4, 0.543], [64689.0, 0.001], [64696.6, 0.003], [64697.9, 0.005]], "asks": [[64715.8, 0.557], [64716.5, 0.006], [64719.9, 0.115], [64720.7, 0.009], [64895.6, 7.823], [65346.9, 3.625], [65591.0, 9.725], [65638.0, 25.681], [65653.0, 0.0], [65699.9, 0.951], [65702.7, 11.705], [66062.3, 0.007], [67934.8, 0.01]]}
{"kind": "depth", "E": 1787080294859, "U": 11315344271531, "u": 11315344277208, "recv_ms": 1787080294810, "bids": [[1000.0, 35.81], [14299.8, 0.07], [14399.8, 3.752], [14499.8, 0.378], [58229.8, 0.002], [61464.8, 0.008], [62111.8, 0.52], [63405.9, 0.025], [63942.8, 2.193], [64052.8, 1.739], [64654.5, 0.004], [64666.9, 0.325], [64667.0, 0.007], [64667.1, 0.309], [64670.3, 0.347], [64670.4, 1.322], [64670.5, 0.736], [64671.6, 0.101], [64681.5, 0.521], [64688.4, 0.002], [64689.1, 0.0], [64689.4, 0.079], [64689.5, 0.542], [64689.6, 0.018], [64691.5, 0.558], [64693.2, 0.086], [64693.4, 0.16]], "asks": [[64699.9, 25.349], [64702.8, 0.097], [64706.9, 0.028], [64707.8, 0.262], [64710.4, 0.009], [64712.1, 0.465], [64715.8, 0.001], [64716.7, 0.561], [64719.8, 0.001], [64719.9, 0.0], [64720.8, 0.118], [64809.9, 0.004], [64895.6, 4.42], [65346.9, 3.625], [65496.7, 3.757], [65638.0, 24.616], [71169.9, 0.0]]}
{"kind": "depth", "E": 1787080294961, "U": 11315344277641, "u": 11315344296870, "recv_ms": 1787080294912, "bids": [[1000.0, 35.81], [14299.8, 0.28], [14399.8, 3.682], [14499.8, 0.238], [58229.8, 0.002], [62111.8, 0.517], [62584.3, 0.0], [63405.9, 0.022], [63699.8, 0.011], [64052.8, 1.739], [64376.3, 4.033], [64632.4, 1.131], [64652.2, 2.872], [64683.6, 0.025], [64683.8, 0.024], [64691.6, 0.0], [64693.2, 0.086], [64693.4, 0.16], [64697.9, 0.177]], "asks": [[64707.6, 0.303], [64712.0, 0.019], [64716.3, 0.165], [64718.8, 0.062], [64730.5, 1.139], [65346.9, 3.625], [65591.0, 9.542], [65638.0, 25.68], [65644.5, 1.048], [65699.9, 0.931]]}
{"kind": "depth", "E": 1787080295165, "U": 11315344304833, "u": 11315344312105, "recv_ms": 1787080295117, "bids": [[1000.0, 35.81], [14299.8, 0.756], [14399.8, 3.444], [14499.8, 0.0], [51760.0, 0.004], [58229.8, 0.002], [62111.8, 0.517], [63699.8, 0.031], [63706.4, 0.028], [63707.5, 0.011], [63802.6, 0.001], [64052.8, 1.739], [64376.3, 4.033], [64648.7, 0.001], [64651.3, 0.008], [64676.2, 0.083], [64676.5, 0.558], [64677.0, 0.98], [64677.7, 0.12], [64677.9, 0.231], [64678.7, 0.38], [64680.7, 0.168], [64681.3, 2.245], [64681.5, 0.05], [64682.2, 0.465], [64686.0, 0.588], [64689.0, 0.542], [64689.5, 0.001], [64689.6, 0.49], [64691.6, 0.077], [64692.8, 0.089], [64693.4, 0.348], [64696.3, 0.459]], "asks": [[64706.2, 0.003], [64707.6, 0.303], [64709.7, 0.253], [64712.0, 0.019], [64713.9, 0.007], [64714.7, 1.081], [64716.7, 0.005], [64717.3, 0.559], [64719.1, 0.037], [64719.9, 0.541], [64720.8, 0.003], [64721.5, 0.116], [65346.9, 3.627], [65638.0, 26.745], [65693.2, 0.788], [65699.9, 0.951]]}
{"kind": "depth", "E": 1787080295267, "U": 11315344312147, "u": 11315344318072, "recv_ms": 1787080295219, "bids": [[1000.0, 35.81], [14299.8, 1.12], [14399.8, 3.08], [51760.0, 0.004], [58229.8, 0.002], [62560.4, 1.436], [63699.8, 0.011], [64052.8, 1.739], [64089.6, 0.0], [64589.8, 0.0], [64622.1, 0.024], [64654.5, 0.001], [64675.3, 0.561], [64676.5, 0.001], [64677.0, 1.096], [64677.7, 0.004], [64679.8, 5.002], [64680.6, 0.928], [64681.3, 1.319], [64688.4, 0.002], [64689.0, 0.001], [64689.4, 0.543], [64693.4, 0.16], [64696.8, 0.167], [64699.8, 7.749]], "asks": [[64702.8, 0.252], [64706.9, 0.183], [64707.6, 0.303], [64707.8, 0.417], [64710.4, 0.319], [64712.0, 0.011], [64712.1, 0.62], [64713.0, 0.042], [64714.0, 0.947], [64714.7, 0.156], [64715.6, 0.975], [64717.3, 0.003], [64718.3, 0.134], [64719.2, 0.545], [64719.8, 0.116], [64719.9, 0.0], [64721.5, 0.001], [64745.2, 0.002], [64809.9, 0.001], [64895.6, 2.242], [65346.9, 3.627], [65692.1, 0.009], [65699.9, 0.931], [71169.9, 0.0]]}
{"kind": "depth", "E": 1787080295369, "U": 11315344318103, "u": 11315344324289, "recv_ms": 1787080295320, "bids": [[14299.8, 1.47], [14399.8, 2.73], [58229.8, 0.002], [61464.8, 0.008], [62111.8, 0.52], [63876.7, 3.247], [64052.8, 1.739], [64618.5, 32.913], [64625.0, 1.59], [64625.1, 0.0], [64645.4, 0.015], [64648.0, 1.307], [64660.9, 0.02], [64674.2, 3.092], [64681.5, 0.668], [64681.6, 0.524], [64688.4, 0.002], [64689.3, 0.023], [64689.5, 0.001], [64689.6, 0.019], [64691.4, 0.048], [64691.5, 0.017], [64691.6, 1.984], [64691.7, 0.111], [64693.4, 0.16], [64693.5, 0.587], [64693.6, 0.088], [64699.8, 8.468]], "asks": [[64702.8, 0.252], [64704.0, 0.031], [64705.6, 0.003], [64706.2, 0.002], [64706.6, 0.155], [64706.9, 0.183], [64707.3, 0.665], [64707.4, 0.134], [64707.6, 0.319], [64707.8, 0.417], [64710.4, 0.319], [64712.0, 0.019], [64712.1, 0.62], [64718.4, 2.283], [64719.4, 0.623], [64745.2, 0.005], [64767.2, 0.518], [64829.3, 2.322], [65346.9, 3.627], [65675.4, 1.293]]}
{"kind": "depth", "E": 1787080295471, "U": 11315344324330, "u": 11315344329776, "recv_ms": 1787080295423, "bids": [[1000.0, 35.81], [14299.8, 1.834], [14399.8, 2.366], [58229.8, 0.002], [61464.8, 0.006], [61464.9, 0.008], [62111.8, 0.517], [63906.4, 4.04], [64052.8, 1.739], [64376.3, 4.033], [64599.6, 0.001], [64599.7, 0.005], [64618.5, 0.005], [64620.7, 0.122], [64624.7, 0.0], [64625.0, 34.516], [64645.4, 0.043], [64674.2, 2.474], [64681.5, 0.05], [64681.6, 0.053], [64688.4, 0.667], [64688.5, 0.466], [64691.5, 0.001], [64691.7, 0.034], [64693.2, 0.086], [64693.4, 0.137], [64693.5, 0.046], [64697.9, 0.176], [64699.7, 0.046], [64699.8, 8.407]], "asks": [[64702.8, 0.097], [64706.9, 0.028], [64707.6, 0.319], [64707.8, 0.262], [64710.4, 0.009], [64712.0, 0.019], [64712.1, 0.465], [64717.2, 1.863], [64719.4, 0.005], [64719.8, 0.001], [64720.8, 0.118], [64721.4, 10.06], [64769.8, 0.0], [65346.9, 3.625], [65508.6, 8.731]]}
{"kind": "depth", "E": 1787080295675, "U": 11315344335190, "u": 11315344345345, "recv_ms": 1787080295638, "bids": [[14299.8, 2.548], [14399.8, 1.652], [51759.8, 0.0], [51760.0, 0.004], [58229.8, 0.004], [61464.8, 0.006], [63891.1, 10.739], [64052.8, 1.739], [64376.3, 4.032], [64622.9, 36.865], [64625.0, 1.59], [64645.4, 0.015], [64662.5, 0.001], [64665.2, 0.02], [64667.0, 0.064], [64670.4, 1.242], [64672.2, 0.006], [64674.9, 0.349], [64678.1, 0.005], [64678.2, 0.022], [64679.2, 0.007], [64679.7, 0.0], [64679.8, 5.084], [64680.0, 2.553], [64680.3, 0.002], [64680.6, 0.002], [64682.3, 0.029], [64682.4, 0.927], [64684.4, 0.021], [64685.4, 0.016], [64687.5, 0.0], [64688.4, 0.002], [64688.5, 0.0], [64689.0, 0.542], [64689.4, 0.002], [64689.9, 0.141], [64690.1, 0.453], [64690.3, 0.2], [64691.2, 1.211], [64691.3, 0.003], [64691.7, 2.353], [64691.8, 0.008], [64691.9, 0.466], [64692.7, 0.272], [64692.8, 0.005], [64692.9, 0.0], [64693.1, 1.157], [64693.2, 0.002], [64693.4, 0.005], [64693.5, 0.827], [64693.6, 0.001], [64693.9, 0.0], [64694.3, 0.312], [64694.9, 0.001], [64695.2, 0.006], [64695.4, 0.087], [64696.1, 0.007], [64696.2, 0.07], [64696.6, 0.003], [64696.8, 0.17], [64697.1, 0.086], [64697.2, 0.009], [64697.4, 0.311], [64698.0, 0.262], [64698.4, 0.001], [64698.5, 0.084], [64699.1, 0.084], [64699.8, 10.796]], "asks": [[64699.9, 9.543], [64700.0, 1.197], [64700.1, 0.001], [64700.3, 0.001], [64700.4, 0.001], [64700.7, 0.0], [64700.8, 0.012], [64700.9, 0.049], [64701.0, 0.05], [64701.2, 0.0], [64701.3, 0.877], [64701.4, 0.004], [64701.6, 0.003], [64701.7, 0.002], [64701.9, 0.0], [64702.0, 0.001], [64702.1, 0.0], [64702.2, 0.042], [64702.3, 0.007], [64702.4, 0.014], [64702.8, 2.416], [64702.9, 0.001], [64703.0, 0.014], [64703.1, 0.106], [64703.2, 0.402], [64703.3, 0.16], [64703.4, 0.0], [64703.5, 0.011], [64703.8, 0.218], [64704.3, 0.088], [64704.4, 0.051], [64704.5, 0.004], [64704.6, 0.087], [64704.7, 0.002], [64704.8, 0.669], [64705.0, 0.103], [64705.4, 0.088], [64705.5, 0.07], [64705.6, 0.01], [64705.7, 1.086], [64705.9, 0.195], [64706.6, 0.001], [64706.9, 0.02], [64707.1, 0.442], [64707.3, 0.04], [64707.6, 0.311], [64707.7, 0.629], [64707.8, 0.733], [64708.0, 1.046], [64708.7, 0.173], [64709.1, 0.464], [64709.4, 0.243], [64709.8, 0.001], [64710.2, 0.026], [64710.4, 0.009], [64710.6, 0.004], [64711.2, 0.155], [64711.5, 0.004], [64712.0, 0.003], [64712.1, 0.002], [64713.2, 0.216], [64713.6, 0.01], [64713.9, 0.042], [64714.0, 0.022], [64714.8, 0.328], [64714.9, 2.642], [64715.5, 0.925], [64715.6, 0.37], [64715.7, 0.022], [64715.8, 0.008], [64716.4, 6.118], [64716.7, 0.005], [64716.8, 0.124], [64716.9, 0.001], [64717.5, 2.532], [64717.8, 0.003], [64718.1, 0.561], [64718.4, 2.285], [64718.5, 0.35], [64718.7, 0.003], [64719.1, 0.094], [64719.2, 0.004], [64719.5, 1.255], [64719.7, 0.082], [64719.9, 0.007], [64720.0, 2.211], [64720.2, 0.001], [64720.8, 0.003], [64720.9, 0.544], [64721.1, 0.502], [64721.4, 0.06], [64722.2, 1.084], [64722.7, 2.807], [64722.8, 0.052], [64723.2, 0.026], [64725.2, 0.312], [64725.8, 3.138], [64726.7, 0.108], [64727.1, 0.345], [64728.4, 0.023], [64729.8, 10.101], [64735.1, 0.034], [64739.7, 0.443], [64744.4, 0.027], [64745.8, 0.074], [64746.5, 0.106], [64747.3, 0.025], [64749.1, 0.029], [64754.6, 0.585], [64769.8, 0.009], [64895.6, 2.283], [65023.4, 4.0], [65346.9, 3.625], [65993.8, 0.059]]}
{"kind": "depth", "E": 1787080295777, "U": 11315344345372, "u": 11315344353345, "recv_ms": 1787080295745, "bids": [[1000.0, 35.81], [14299.8, 2.898], [14399.8, 1.302], [51760.0, 0.004], [58229.8, 0.002], [61464.8, 0.006], [62111.8, 0.517], [63699.8, 0.011], [63806.2, 45.008], [64052.8, 1.739], [64376.3, 4.033], [64622.9, 3.939], [64625.1, 32.926], [64665.5, 0.058], [64667.0, 0.007], [64677.8, 0.006], [64679.4, 0.002], [64680.0, 2.551], [64681.0, 0.08], [64681.4, 2.68], [64682.4, 0.001], [64686.2, 0.0], [64688.4, 0.002], [64689.9, 0.506], [64690.8, 0.134], [64691.8, 0.008], [64693.1, 1.107], [64693.6, 0.189], [64694.8, 0.019], [64695.3, 0.025], [64695.4, 0.106], [64695.7, 0.025], [64699.8, 10.795]], "asks": [[64699.9, 9.591], [64700.5, 0.0], [64700.9, 0.006], [64702.9, 0.02], [64703.0, 0.036], [64704.7, 0.002], [64704.8, 0.128], [64705.6, 0.551], [64705.9, 0.199], [64707.6, 0.311], [64708.1, 0.285], [64708.6, 2.906], [64709.7, 0.268], [64710.4, 0.009], [64712.1, 0.002], [64712.8, 1.334], [64712.9, 2.108], [64713.9, 0.967], [64715.3, 0.334], [64715.5, 0.0], [64718.5, 0.31], [64719.5, 1.295], [64719.9, 0.548], [64720.9, 0.003], [64725.8, 3.118], [64730.0, 0.124], [64895.6, 4.687], [64967.9, 0.942], [64968.0, 5.802], [65023.4, 4.001], [65346.9, 3.625], [65446.6, 0.002], [65586.3, 1.221], [65693.9, 4.256], [65699.9, 0.931]]}
{"kind": "depth", "E": 1787080295879, "U": 11315344353397, "u": 11315344365777, "recv_ms": 1787080295831, "bids": [[1000.0, 35.81], [14299.8, 3.262], [14399.8, 0.938], [58229.8, 0.002], [61464.8, 0.006], [61464.9, 0.006], [62111.8, 0.52], [63405.9, 0.025], [63632.3, 3.297], [64052.8, 1.739], [64647.2, 0.0], [64648.0, 1.293], [64648.5, 0.062], [64654.7, 0.165], [64656.0, 1.88], [64665.9, 0.003], [64668.4, 0.171], [64673.2, 0.0], [64674.9, 0.013], [64675.6, 0.09], [64676.0, 0.36], [64677.6, 0.003], [64679.4, 0.0], [64679.6, 0.012], [64680.6, 0.004], [64681.5, 0.12], [64683.6, 0.012], [64684.8, 0.058], [64685.4, 0.009], [64687.0, 0.001], [64687.5, 0.007], [64688.0, 3.117], [64689.6, 0.018], [64690.0, 0.151], [64691.8, 0.665], [64692.6, 0.114], [64693.0, 0.002], [64693.1, 1.057], [64693.2, 0.002], [64693.3, 0.418], [64693.4, 0.004], [64693.5, 0.046], [64693.6, 0.001], [64693.7, 0.126], [64694.1, 0.0], [64694.3, 0.312], [64694.4, 0.632], [64694.8, 0.0], [64695.3, 0.002], [64695.4, 0.087], [64695.9, 0.02], [64696.2, 0.093], [64696.3, 0.172], [64696.6, 0.003], [64696.8, 0.69], [64697.2, 0.008], [64697.5, 0.005], [64699.6, 0.001], [64699.8, 11.934]], "asks": [[64699.9, 9.379], [64700.8, 0.011], [64700.9, 0.049], [64701.3, 0.558], [64701.6, 0.0], [64702.3, 0.007], [64702.4, 0.007], [64702.6, 0.12], [64702.9, 0.311], [64703.0, 0.014], [64703.2, 0.023], [64703.4, 0.042], [64703.5, 0.018], [64703.9, 0.137], [64704.2, 0.066], [64704.6, 0.087], [64704.7, 0.018], [64704.8, 0.56], [64705.0, 0.103], [64705.5, 0.147], [64705.6, 0.026], [64705.9, 0.045], [64706.8, 0.155], [64707.4, 0.137], [64707.5, 0.008], [64707.6, 0.311], [64707.8, 0.725], [64708.0, 0.146], [64709.0, 0.901], [64709.4, 0.083], [64710.4, 0.009], [64711.2, 0.001], [64712.1, 0.002], [64712.7, 0.164], [64713.1, 0.284], [64713.9, 0.042], [64714.6, 1.174], [64718.4, 2.283], [64719.6, 0.003], [64729.0, 3.204], [64729.8, 0.103], [64730.0, 0.104], [64731.1, 0.466], [64731.2, 3.037], [64731.5, 0.048], [64735.0, 10.003], [65346.9, 3.625], [65476.3, 21.394], [65511.2, 0.764], [65702.7, 13.831], [65767.4, 4.252], [65993.8, 0.062]]}
{"kind": "depth", "E": 1787080296083, "U": 11315344371326, "u": 11315344378388, "recv_ms": 1787080296035, "bids": [[1000.0, 35.81], [14199.8, 0.112], [14299.8, 3.752], [14399.8, 0.336], [58229.8, 0.002], [61464.8, 0.006], [62111.8, 0.52], [63794.0, 19.553], [63891.1, 10.973], [64052.8, 1.739], [64376.3, 4.043], [64675.0, 0.282], [64675.3, 0.004], [64677.0, 0.98], [64677.5, 0.559], [64679.2, 0.123], [64681.4, 1.754], [64681.5, 0.05], [64682.9, 3.247], [64688.2, 0.001]], "asks": [[64699.9, 9.415], [64704.7, 0.018], [64705.6, 0.026], [64707.5, 0.008], [64707.6, 0.311], [64709.1, 0.155], [64709.6, 0.311], [64710.4, 0.009], [64712.1, 0.002], [64720.0, 2.211], [64725.2, 0.003], [64726.0, 2.634], [64731.2, 12.883], [64731.4, 0.0], [64731.5, 0.048], [64735.0, 0.003], [64746.5, 0.078], [65346.9, 3.625], [65605.7, 22.201]]}
{"kind": "depth", "E": 1787080296185, "U": 11315344378548, "u": 11315344385313, "recv_ms": 1787080296174, "bids": [[1000.0, 35.81], [14199.8, 0.336], [14299.8, 3.654], [14399.8, 0.21], [51760.0, 0.004], [58229.8, 0.002], [63405.9, 0.025], [63632.3, 4.396], [63699.8, 0.011], [63761.7, 21.929], [64052.8, 1.739], [64627.9, 0.0], [64651.0, 0.015], [64651.2, 1.193], [64651.3, 0.006], [64657.3, 0.003], [64657.4, 0.001], [64657.5, 0.004], [64678.7, 0.387], [64679.2, 0.116], [64683.4, 0.565], [64689.2, 0.47], [64689.8, 0.002], [64692.8, 0.03], [64693.4, 0.004], [64694.4, 0.726]], "asks": [[64699.9, 9.394], [64704.7, 0.018], [64706.4, 0.041], [64707.5, 0.008], [64707.6, 0.311], [64710.4, 0.009], [64712.1, 0.002], [64790.6, 0.0], [65346.9, 3.625], [65488.8, 35.389], [65699.9, 0.931], [65767.4, 5.315]]}
{"kind": "depth", "E": 1787080296287, "U": 11315344385660, "u": 11315344392638, "recv_ms": 1787080296240, "bids": [[14199.8, 0.588], [14299.8, 3.514], [14399.8, 0.098], [51760.0, 0.004], [58229.8, 0.002], [62111.8, 0.517], [63017.6, 0.0], [63405.9, 0.022], [63935.7, 31.085], [64052.8, 1.739], [64689.6, 0.017], [64692.8, 0.005], [64693.4, 0.192], [64693.6, 0.002], [64694.4, 0.632]], "asks": [[64709.7, 0.253], [64709.9, 0.896], [64718.8, 0.069], [64719.9, 0.0], [65346.9, 3.625]]}
{"kind": "depth", "E": 1787080296389, "U": 11315344392883, "u": 11315344401068, "recv_ms": 1787080296352, "bids": [[1000.0, 35.81], [14199.8, 0.84], [14299.8, 3.36], [14399.8, 0.0], [58229.8, 0.002], [61464.8, 0.008], [62111.8, 0.52], [63276.4, 0.007], [63591.2, 2.516], [63699.8, 0.031], [64052.8, 1.739], [64376.3, 4.033], [64559.5, 0.022], [64675.1, 0.668], [64682.4, 0.619], [64693.4, 0.004], [64694.4, 0.82], [64699.8, 11.933]], "asks": [[64699.9, 9.359], [64701.3, 0.572], [64702.4, 0.093], [64704.7, 0.018], [64706.4, 0.04], [64707.5, 0.008], [64707.6, 0.311], [64710.4, 0.009], [64712.1, 0.002], [64712.9, 2.726], [64720.3, 0.723], [64731.5, 0.028], [64829.3, 2.322], [64839.8, 2.319], [65346.9, 3.627], [65476.3, 22.919], [65552.8, 1.524], [65699.9, 0.951], [65993.8, 0.068]]}
{"kind": "depth", "E": 1787080296593, "U": 11315344406772, "u": 11315344412346, "recv_ms": 1787080296566, "bids": [[14199.8, 1.554], [14299.8, 2.646], [51760.0, 0.004], [58229.8, 0.002], [62111.8, 0.52], [63567.6, 2.514], [63699.8, 0.011], [63923.4, 25.466], [64052.8, 1.739], [64622.1, 0.021], [64654.5, 0.004], [64684.1, 0.814], [64690.6, 0.453], [64692.3, 0.002], [64692.8, 0.005], [64694.4, 0.632], [64699.1, 0.0]], "asks": [[64703.2, 0.042], [64704.7, 0.018], [64707.5, 0.008], [64707.6, 0.311], [64710.4, 0.009], [64711.9, 0.042], [64712.1, 0.002], [64719.5, 1.255], [64719.9, 0.541], [64720.9, 0.003], [64731.3, 0.168], [64745.2, 0.005], [65346.9, 3.625], [65466.4, 1.512], [65699.9, 0.931], [66026.2, 2.269]]}
{"kind": "depth", "E": 1787080296695, "U": 11315344412451, "u": 11315344417322, "recv_ms": 1787080296646, "bids": [[1000.0, 35.81], [14199.8, 1.918], [14299.8, 2.282], [51759.8, 0.0], [58229.8, 0.002], [61464.8, 0.008], [64052.8, 1.739], [64210.3, 0.0], [64376.3, 4.033], [64675.1, 0.034], [64675.4, 0.16], [64682.4, 0.927], [64682.9, 2.321], [64689.8, 0.001], [64691.6, 1.984], [64692.3, 0.102], [64693.4, 0.192], [64695.6, 0.019], [64699.8, 11.928]], "asks": [[64699.9, 10.161], [64702.9, 0.312], [64703.1, 0.091], [64703.9, 0.136], [64704.7, 0.018], [64705.0, 0.168], [64705.5, 0.085], [64707.5, 0.008], [64707.6, 0.311], [64710.4, 0.009], [64712.1, 0.002], [64712.9, 2.108], [64720.3, 0.105], [64721.5, 0.016], [65346.9, 3.625], [65508.6, 8.96], [65603.9, 0.683], [65605.7, 22.84]]}
{"kind": "depth", "E": 1787080296797, "U": 11315344417459, "u": 11315344421675, "recv_ms": 1787080296747, "bids": [[1000.0, 35.81], [14199.8, 2.268], [14299.8, 1.932], [58229.8, 0.002], [61464.8, 0.008], [62111.8, 0.517], [63699.8, 0.031], [63929.9, 9.37], [64052.8, 1.739], [64376.3, 4.033], [64430.4, 1.998], [64431.4, 0.62], [64622.1, 0.024], [64627.7, 0.005], [64648.4, 0.0], [64648.5, 0.06], [64648.6, 0.124], [64648.7, 0.0], [64657.3, 0.005], [64692.8, 0.03], [64693.4, 0.004], [64694.4, 0.82], [64695.7, 0.002], [64695.9, 0.001], [64696.5, 0.002], [64696.7, 1.691], [64696.8, 0.707]], "asks": [[64699.9, 10.163], [64702.0, 0.085], [64704.7, 0.018], [64707.5, 0.008], [64707.6, 0.311], [64710.4, 0.009], [64712.1, 0.002], [64719.5, 1.325], [64726.7, 0.038], [64731.1, 0.466], [64731.5, 0.182], [64809.9, 0.004], [65023.4, 4.001], [65346.9, 3.625], [65461.6, 7.34], [65476.3, 24.444], [65494.0, 2.747], [65699.9, 0.951]]}
{"kind": "depth", "E": 1787080296899, "U": 11315344421750, "u": 11315344426928, "recv_ms": 1787080296852, "bids": [[14199.8, 2.632], [14299.8, 1.568], [58229.8, 0.002], [61464.9, 0.004], [62111.8, 0.52], [63609.4, 0.144], [63782.2, 5.035], [63876.7, 2.981], [64052.8, 1.739], [64079.9, 0.0], [64182.2, 8.283], [64651.0, 0.017], [64677.0, 1.537], [64677.5, 0.002], [64678.6, 1.27], [64679.2, 0.0], [64692.8, 0.005], [64693.4, 0.192], [64694.4, 0.632]], "asks": [[64715.6, 0.419], [64722.8, 0.003], [64731.3, 0.322], [64731.5, 0.028], [65346.9, 3.625], [65638.0, 25.68], [65702.7, 12.767]]}
{"kind": "depth", "E": 1787080297001, "U": 11315344427044, "u": 11315344432951, "recv_ms": 1787080296952, "bids": [[1000.0, 35.81], [14199.8, 2.996], [14299.8, 1.204], [58229.8, 0.002], [61464.8, 0.008], [62111.8, 0.517], [63699.8, 0.011], [64052.8, 1.739], [64182.2, 8.279], [64376.3, 4.033], [64384.7, 0.002], [64677.8, 0.004], [64683.8, 0.024], [64694.1, 0.084], [64696.4, 0.103], [64698.0, 0.178], [64698.5, 0.0], [64699.8, 11.908]], "asks": [[64700.9, 0.133], [64701.3, 0.574], [64701.5, 0.928], [64704.6, 0.628], [64704.7, 0.018], [64704.8, 0.019], [64705.4, 0.004], [64705.6, 0.026], [64705.7, 1.002], [64707.5, 0.008], [64707.6, 0.311], [64710.4, 0.009], [64712.1, 0.002], [64712.3, 1.417], [64713.3, 0.018], [64716.3, 0.165], [64728.4, 0.009], [64895.6, 2.254], [65340.7, 0.001], [65346.9, 3.625], [65638.0, 26.745], [65699.9, 0.931], [65702.7, 13.831]]}
{"kind": "depth", "E": 1787080297205, "U": 11315344438326, "u": 11315344443523, "recv_ms": 1787080297155, "bids": [[14199.8, 3.696], [14299.8, 0.504], [58229.8, 0.002], [61464.8, 0.008], [62111.8, 0.52], [63699.8, 0.031], [63891.1, 11.363], [64052.8, 1.74], [64059.3, 0.7], [64190.5, 0.0], [64648.0, 1.321], [64648.3, 0.007], [64651.0, 0.018], [64657.3, 0.007], [64671.6, 0.437], [64676.0, 0.024], [64676.5, 0.558], [64677.0, 0.98], [64677.5, 0.009], [64677.8, 0.002], [64678.1, 0.121], [64678.6, 1.154], [64679.7, 0.002], [64680.6, 0.002], [64681.7, 0.942], [64682.4, 0.001], [64686.5, 0.044], [64687.5, 0.0], [64689.7, 0.309], [64690.1, 0.144], [64690.4, 0.171], [64692.3, 0.002], [64693.8, 0.087], [64695.5, 0.156], [64696.0, 0.002], [64696.2, 0.07], [64696.4, 0.084], [64696.6, 0.003], [64696.8, 0.687], [64697.1, 0.002], [64699.8, 11.804]], "asks": [[64699.9, 12.351], [64702.7, 0.002], [64703.4, 0.352], [64704.5, 0.004], [64704.7, 0.002], [64704.8, 0.019], [64705.0, 0.022], [64705.5, 0.008], [64705.6, 0.003], [64707.0, 0.501], [64707.5, 0.665], [64707.6, 0.373], [64708.0, 1.046], [64709.0, 0.001], [64710.4, 0.009], [64711.9, 0.002], [64712.1, 0.002], [64712.8, 1.336], [64712.9, 2.106], [64714.1, 0.985], [64715.3, 0.334], [64715.4, 0.572], [64716.7, 0.561], [64717.5, 2.589], [64718.1, 0.005], [64719.1, 0.037], [64720.9, 0.118], [64722.2, 0.969], [64726.8, 4.06], [64726.9, 10.002], [64728.0, 1.24], [64730.5, 1.139], [64731.2, 2.883], [64731.3, 0.322], [64746.5, 0.064], [64856.8, 7.301], [64895.6, 2.285], [65217.5, 9.365], [65226.0, 3.03], [65335.5, 0.81], [65346.9, 3.625], [65484.8, 3.058], [65699.9, 0.951]]}
{"kind": "depth", "E": 1787080297511, "U": 11315344453068, "u": 11315344457611, "recv_ms": 1787080297462, "bids": [[14199.8, 3.486], [14299.8, 0.07], [14599.8, 0.644], [58229.8, 0.002], [61464.8, 0.006], [62111.8, 0.517], [63405.9, 0.019], [63699.8, 0.031], [63766.8, 5.398], [63826.4, 6.844], [64052.8, 1.74], [64182.2, 9.523], [64627.5, 0.002], [64650.1, 0.013], [64660.9, 0.1], [64666.3, 0.002], [64675.0, 0.9], [64682.4, 0.619], [64695.7, 0.025], [64695.8, 0.106]], "asks": [[64699.9, 12.383], [64702.7, 0.157], [64703.0, 0.014], [64707.0, 0.5], [64707.4, 0.292], [64707.6, 0.528], [64710.4, 0.319], [64712.1, 0.157], [64712.9, 2.724], [64720.3, 0.723], [64722.2, 0.013], [64731.4, 0.0], [64731.5, 0.182], [64738.4, 0.002], [64758.4, 1.167], [64761.0, 0.028], [65346.9, 3.625], [65471.7, 3.024], [65699.9, 0.951], [65993.8, 0.062]]}
{"kind": "depth", "E": 1787080297613, "U": 11315344457726, "u": 11315344461736, "recv_ms": 1787080297564, "bids": [[1000.0, 35.81], [14199.8, 3.276], [14299.8, 0.0], [14599.8, 0.924], [58229.8, 0.002], [61464.8, 0.006], [63899.8, 0.146], [64052.8, 1.74], [64376.3, 4.819], [64595.2, 1.545], [64635.7, 0.259], [64692.3, 0.052], [64694.6, 0.001], [64695.5, 0.155], [64697.4, 0.001]], "asks": [[64702.3, 0.011], [64702.7, 0.002], [64704.4, 0.044], [64707.4, 0.137], [64707.6, 0.373], [64710.4, 0.009], [64712.1, 0.002], [64790.6, 0.1], [64793.9, 2.386], [64794.0, 0.066], [65346.9, 3.625], [65486.5, 1.526], [65864.5, 1.37]]}
{"kind": "depth", "E": 1787080297715, "U": 11315344461854, "u": 11315344465414, "recv_ms": 1787080297666, "bids": [[1000.0, 35.81], [14199.8, 2.912], [14599.8, 1.288], [51759.8, 0.0], [58229.8, 0.002], [62111.8, 0.52], [63923.4, 29.683], [63931.7, 4.691], [63964.5, 2.343], [64052.8, 1.74], [64628.9, 8.673], [64651.5, 3.501], [64667.7, 1.159], [64692.2, 0.25]], "asks": [[64704.6, 0.312], [64705.6, 0.66], [64707.3, 0.517], [64707.5, 0.008], [64721.0, 0.017], [64725.3, 1.304], [64741.5, 3.638], [64763.1, 1.41], [64764.2, 6.004], [65031.8, 0.0], [65346.9, 3.625], [65508.6, 9.722]]}
{"kind": "depth", "E": 1787080297817, "U": 11315344465488, "u": 11315344470195, "recv_ms": 1787080297768, "bids": [[14199.8, 2.562], [14599.8, 1.638], [51760.0, 0.004], [58229.8, 0.002], [62111.8, 0.517], [63699.8, 0.011], [63876.7, 2.716], [64052.8, 1.74], [64376.3, 4.819], [64589.8, 0.0], [64596.6, 10.016], [64622.1, 0.021], [64654.5, 0.004], [64673.9, 0.297]], "asks": [[64712.9, 2.727], [64745.2, 0.005], [64796.5, 10.211], [64809.9, 0.001], [65023.4, 4.001], [65346.9, 3.627], [65476.3, 27.798], [65699.9, 0.931], [65993.8, 0.065]]}
{"kind": "depth", "E": 1787080297919, "U": 11315344470236, "u": 11315344474793, "recv_ms": 1787080297872, "bids": [[1000.0, 35.81], [14199.8, 2.198], [14599.8, 2.002], [58229.8, 0.002], [61052.2, 0.004], [61464.8, 0.008], [62111.8, 0.52], [63929.9, 8.433], [64052.8, 1.74], [64376.3, 4.809], [64503.6, 0.0], [64503.7, 15.006], [64542.4, 1.21], [64542.5, 7.797], [64559.5, 4.377], [64633.6, 0.193], [64633.7, 3.219], [64663.5, 0.015], [64666.1, 0.014], [64671.6, 0.101], [64675.0, 0.282], [64679.1, 0.258], [64679.7, 0.0], [64682.4, 0.001], [64686.0, 0.595], [64686.5, 0.037], [64692.3, 0.002], [64692.8, 0.002], [64693.0, 0.086], [64693.4, 0.088], [64694.3, 0.003], [64694.6, 0.0], [64696.4, 0.0], [64696.8, 0.603], [64697.5, 0.004], [64699.8, 11.576]], "asks": [[64699.9, 12.427], [64700.9, 0.09], [64702.0, 0.095], [64702.1, 0.007], [64702.4, 0.094], [64702.7, 0.002], [64702.9, 0.33], [64703.5, 0.011], [64705.5, 0.471], [64705.6, 0.668], [64707.2, 0.071], [64707.5, 0.0], [64707.6, 0.311], [64707.8, 0.262], [64710.4, 0.009], [64712.1, 0.002], [64712.9, 2.109], [64714.1, 0.06], [64715.1, 0.967], [64716.7, 0.005], [64717.5, 2.532], [64717.8, 0.559], [64718.2, 0.016], [64718.5, 0.367], [64719.6, 0.001], [64720.9, 0.003], [64721.9, 0.12], [64722.9, 10.463], [64725.8, 3.116], [64726.9, 10.004], [64765.4, 2.9], [64769.8, 0.0], [64839.8, 7.717], [64856.8, 10.408], [64895.6, 3.29], [65346.9, 3.625]]}
{"kind": "depth", "E": 1787080298123, "U": 11315344479860, "u": 11315344485038, "recv_ms": 1787080298076, "bids": [[14199.8, 1.484], [14599.8, 2.716], [51760.0, 0.004], [58229.8, 0.002], [63405.9, 0.022], [63706.4, 0.019], [63766.8, 5.164], [63929.9, 9.37], [64052.8, 1.74], [64657.3, 0.009], [64683.8, 0.024], [64688.2, 0.001], [64689.1, 0.309], [64689.7, 0.0], [64691.8, 0.666], [64692.3, 0.19], [64693.0, 0.088], [64693.4, 0.088], [64693.6, 0.001], [64694.3, 0.002], [64694.5, 0.094], [64696.7, 0.002], [64696.8, 0.082], [64699.3, 0.0], [64699.8, 11.636]], "asks": [[64704.5, 0.004], [64704.8, 0.096], [64705.6, 0.591], [64707.6, 0.311], [64707.8, 0.262], [64708.2, 0.457], [64708.6, 2.856], [64709.6, 0.003], [64710.4, 0.009], [64712.1, 0.002], [64716.3, 0.165], [64716.5, 0.562], [64717.8, 0.003], [64720.8, 0.118], [64721.9, 0.005], [65346.9, 3.625], [65693.2, 0.779]]}
{"kind": "depth", "E": 1787080298633, "U": 11315344513646, "u": 11315344519315, "recv_ms": 1787080298584, "bids": [[1000.0, 35.81], [14199.8, 0.154], [14499.8, 0.462], [14599.8, 3.584], [51760.0, 0.008], [58229.8, 0.002], [61464.8, 0.006], [61464.9, 0.008], [62111.8, 0.517], [63699.8, 0.011], [63891.1, 11.746], [64052.8, 1.739], [64578.9, 0.002], [64584.0, 6.805], [64628.4, 0.0], [64628.5, 0.065], [64693.4, 0.276]], "asks": [[64702.7, 0.002], [64702.9, 0.333], [64703.4, 0.31], [64770.9, 0.048], [64835.0, 0.001], [64835.1, 4.228], [64835.4, 0.962], [64835.5, 3.864], [64836.3, 0.002], [64839.7, 0.096], [65346.9, 3.625], [65461.6, 7.126], [65508.6, 9.98], [65638.0, 26.745], [65699.9, 0.931]]}
{"kind": "depth", "E": 1787080298735, "U": 11315344519341, "u": 11315344524216, "recv_ms": 1787080298695, "bids": [[14199.8, 0.042], [14499.8, 0.7], [14599.8, 3.458], [51759.8, 0.0], [51760.0, 0.004], [58229.8, 0.002], [61464.8, 0.006], [61464.9, 0.006], [62111.8, 0.52], [63405.9, 0.019], [63794.0, 21.902], [63929.9, 8.433], [64052.8, 1.739], [64509.4, 0.02], [64537.1, 0.001], [64559.5, 3.798], [64645.4, 0.029], [64660.9, 0.114], [64664.0, 1.193], [64675.1, 0.034], [64675.9, 0.637], [64676.5, 0.001], [64679.8, 0.084], [64682.1, 0.016], [64682.4, 0.001], [64685.5, 2.331], [64686.0, 0.588], [64688.4, 0.465], [64688.5, 0.0], [64691.7, 2.354], [64691.8, 0.094], [64691.9, 0.003], [64692.0, 1.853], [64693.0, 0.087], [64693.2, 0.004], [64693.4, 0.088], [64693.5, 1.888], [64693.6, 0.565], [64694.2, 1.604], [64694.7, 0.092], [64695.7, 0.002], [64695.8, 0.087], [64699.8, 8.103]], "asks": [[64702.0, 0.095], [64702.3, 0.03], [64702.4, 0.117], [64702.7, 0.002], [64703.2, 0.023], [64704.5, 0.004], [64704.8, 0.104], [64705.6, 0.583], [64707.6, 0.311], [64707.8, 0.262], [64709.6, 0.157], [64710.4, 0.009], [64712.1, 0.002], [64712.9, 2.109], [64713.6, 0.935], [64715.1, 0.042], [64718.0, 10.006], [64720.3, 0.105], [64722.9, 10.465], [64723.3, 0.311], [64771.9, 0.001], [64839.8, 7.717], [64895.6, 5.642], [65346.9, 3.625]]}
{"kind": "depth", "E": 1787080298837, "U": 11315344524305, "u": 11315344533222, "recv_ms": 1787080298819, "bids": [[1000.0, 35.81], [14199.8, 0.0], [14499.8, 1.022], [14599.8, 3.178], [58229.8, 0.002], [61257.2, 0.004], [62111.8, 0.517], [63699.8, 0.031], [64052.8, 1.739], [64376.3, 4.818], [64659.8, 0.002], [64664.7, 0.057], [64665.5, 0.001], [64667.2, 3.908], [64675.0, 0.212], [64675.3, 0.561], [64675.9, 0.08], [64677.2, 0.116], [64678.1, 0.002], [64678.5, 0.007], [64679.1, 0.256], [64680.7, 1.094], [64681.2, 0.011], [64681.5, 0.05], [64681.7, 0.016], [64681.8, 0.463], [64682.3, 0.022], [64683.6, 0.025], [64685.0, 0.022], [64685.5, 2.324], [64687.8, 0.312], [64688.4, 0.543], [64688.5, 0.008], [64689.0, 0.001], [64689.1, 0.0], [64691.3, 0.274], [64691.7, 2.353], [64691.8, 0.078], [64692.1, 0.049], [64692.3, 0.102], [64692.6, 0.055], [64692.7, 0.085], [64693.0, 0.087], [64693.6, 0.008], [64694.3, 0.543], [64694.4, 0.192], [64694.5, 0.093], [64694.6, 0.018], [64695.8, 0.003], [64697.0, 0.005], [64697.2, 0.004], [64699.7, 0.045], [64699.8, 6.571]], "asks": [[64700.3, 0.004], [64701.0, 0.057], [64701.3, 0.858], [64702.1, 0.0], [64702.3, 0.053], [64702.4, 0.094], [64702.6, 0.399], [64702.7, 0.035], [64703.2, 0.394], [64704.1, 0.159], [64704.5, 0.004], [64704.8, 0.019], [64705.6, 0.544], [64706.8, 0.001], [64707.1, 0.504], [64707.2, 0.009], [64707.5, 0.101], [64707.6, 0.466], [64707.8, 0.417], [64710.4, 0.319], [64712.1, 0.157], [64716.6, 0.063], [64718.0, 10.008], [64718.3, 0.675], [64718.5, 0.31], [64719.2, 0.002], [64719.9, 0.0], [64722.9, 0.465], [64764.6, 0.005], [64895.6, 3.384], [64967.9, 0.532], [64968.0, 2.825], [65023.4, 4.769], [65346.9, 3.625], [65699.9, 0.951]]}
{"kind": "depth", "E": 1787080298939, "U": 11315344533258, "u": 11315344539868, "recv_ms": 1787080298932, "bids": [[14499.8, 1.372], [14599.8, 2.828], [58229.8, 0.002], [61464.8, 0.008], [62111.8, 0.52], [63752.1, 7.764], [63761.7, 23.025], [63929.9, 9.37], [64052.8, 1.739], [64374.0, 0.165], [64376.3, 4.819], [64659.1, 0.33], [64681.8, 0.0], [64688.5, 0.471], [64693.3, 0.417], [64694.3, 0.543], [64696.3, 0.176], [64697.0, 0.001]], "asks": [[64701.6, 0.001], [64702.0, 0.085], [64702.4, 0.093], [64702.5, 0.005], [64702.6, 0.244], [64702.7, 0.002], [64704.7, 0.002], [64704.8, 0.019], [64705.5, 0.008], [64705.6, 1.131], [64707.0, 0.562], [64707.1, 0.442], [64707.5, 0.0], [64707.6, 0.311], [64707.8, 0.262], [64710.4, 0.009], [64712.1, 0.002], [64714.9, 2.642], [64730.8, 0.203], [64770.1, 39.307], [64772.2, 1.099], [64772.3, 1.251], [65346.9, 3.625], [65650.6, 16.293]]}
{"kind": "depth", "E": 1787080299041, "U": 11315344539951, "u": 11315344546115, "recv_ms": 1787080299036, "bids": [[14499.8, 1.736], [14599.8, 2.464], [58229.8, 0.002], [62132.7, 0.0], [63699.8, 0.011], [64052.8, 1.739], [64659.1, 0.332], [64683.8, 0.022], [64688.2, 0.006], [64692.3, 0.052]], "asks": [[64716.3, 0.163], [64727.8, 1.752], [64730.8, 0.205], [64770.1, 0.001], [64774.4, 6.932], [64774.5, 39.36], [64793.9, 3.573], [65346.9, 3.625], [65699.9, 0.931]]}
{"kind": "depth", "E": 1787080299143, "U": 11315344546152, "u": 11315344552641, "recv_ms": 1787080299137, "bids": [[1000.0, 35.81], [14499.8, 2.086], [14599.8, 2.114], [58229.8, 0.002], [61464.8, 0.008], [62111.8, 0.517], [63429.4, 0.0], [63706.4, 0.011], [63707.5, 0.028], [63771.1, 0.0], [63773.4, 0.001], [63880.4, 2.362], [64015.1, 1.013], [64052.8, 1.739], [64376.3, 4.809], [64654.5, 0.001], [64665.3, 0.022], [64678.5, 0.004], [64683.6, 0.026], [64683.8, 0.024], [64688.2, 0.001], [64688.5, 0.463], [64688.6, 0.001], [64691.8, 0.086], [64692.3, 0.067], [64693.0, 0.086], [64694.4, 0.193], [64694.6, 0.017], [64695.6, 0.002], [64699.8, 7.218]], "asks": [[64699.9, 12.425], [64700.3, 0.001], [64701.0, 0.05], [64701.5, 0.935], [64702.7, 0.002], [64705.3, 0.015], [64707.6, 0.311], [64707.8, 0.262], [64710.4, 0.009], [64712.1, 0.002], [64716.3, 0.165], [64719.4, 5.005], [64721.5, 0.001], [64722.3, 1.04], [64745.2, 0.005], [64767.2, 0.5], [64769.8, 0.009], [64772.3, 40.218], [64772.4, 0.0], [64774.4, 1.137], [64774.5, 0.054], [65217.5, 8.446], [65346.9, 3.625], [65626.2, 0.0], [65628.5, 0.763], [65693.2, 0.771], [66431.4, 0.0]]}
{"kind": "depth", "E": 1787080299347, "U": 11315344559195, "u": 11315344565120, "recv_ms": 1787080299339, "bids": [[14499.8, 2.8], [14599.8, 1.4], [58229.8, 0.002], [61464.8, 0.008], [62111.8, 0.517], [63526.7, 2.209], [64052.8, 1.739], [64663.5, 0.001], [64666.1, 0.0], [64688.5, 0.0], [64688.6, 0.001], [64691.8, 0.549], [64692.1, 0.048], [64692.3, 0.017], [64693.0, 0.087], [64694.3, 0.544], [64694.4, 0.005], [64694.6, 0.016], [64699.7, 0.046], [64699.8, 8.807]], "asks": [[64700.9, 0.09], [64702.7, 0.002], [64707.6, 0.311], [64707.8, 0.262], [64710.4, 0.009], [64712.1, 0.002], [64716.6, 0.006], [64717.8, 0.06], [64719.4, 0.005], [64725.8, 3.118], [64726.9, 0.002], [64743.9, 0.046], [64744.0, 1.364], [65346.9, 3.625], [65469.8, 8.235], [65675.4, 0.002]]}
{"kind": "depth", "E": 1787080299449, "U": 11315344565245, "u": 11315344570178, "recv_ms": 1787080299458, "bids": [[1000.0, 35.81], [14499.8, 3.164], [14599.8, 1.036], [58229.8, 0.002], [61464.8, 0.008], [63630.0, 1.316], [63699.8, 0.011], [63891.1, 12.011], [63994.6, 3.116], [64052.8, 1.739], [64105.8, 1.277], [64376.3, 4.809], [64559.5, 0.022], [64665.2, 0.017], [64680.3, 0.005], [64692.3, 0.067], [64694.4, 0.193], [64699.8, 8.797]], "asks": [[64702.7, 0.157], [64707.6, 0.466], [64707.8, 0.417], [64710.4, 0.319], [64712.1, 0.157], [64725.5, 0.0], [64733.1, 0.001], [64809.9, 0.004], [64829.3, 2.322], [64839.8, 2.319], [65217.5, 9.365], [65346.9, 3.625], [65651.0, 8.44], [65699.9, 0.931]]}
{"kind": "depth", "E": 1787080299653, "U": 11315344574741, "u": 11315344578765, "recv_ms": 1787080299653, "bids": [[14399.8, 0.056], [14499.8, 3.752], [14599.8, 0.392], [58229.8, 0.002], [61464.8, 0.008], [62111.8, 0.517], [63461.8, 0.005], [63535.2, 1.248], [63699.8, 0.031], [64052.8, 1.739], [64688.5, 0.0], [64691.8, 0.472], [64692.1, 0.032], [64692.3, 0.017], [64693.6, 0.101], [64694.4, 0.005], [64699.8, 8.797]], "asks": [[64702.7, 0.002], [64707.6, 0.311], [64707.8, 0.262], [64710.4, 0.009], [64712.1, 0.002], [64713.0, 0.967], [64714.3, 0.0], [64715.4, 0.532], [64717.9, 0.635], [64718.2, 0.056], [64719.2, 0.002], [64770.1, 0.001], [64772.3, 40.218], [65346.9, 3.625], [65469.8, 9.15], [65699.9, 0.951], [65824.3, 1.061]]}
{"kind": "depth", "E": 1787080299755, "U": 11315344578931, "u": 11315344583390, "recv_ms": 1787080299757, "bids": [[1000.0, 35.81], [14399.8, 0.28], [14499.8, 3.668], [14599.8, 0.252], [51759.8, 0.0], [58229.8, 0.002], [62111.8, 0.52], [63405.9, 0.016], [64052.8, 1.739], [64376.3, 4.819]], "asks": [[64701.3, 0.842], [64701.5, 0.955], [64701.6, 0.024], [64713.0, 0.042], [64713.9, 0.967], [64717.9, 0.094], [64719.2, 0.543], [64770.1, 38.968], [64772.3, 1.251], [65993.8, 0.062]]}
{"kind": "depth", "E": 1787080299959, "U": 11315344587866, "u": 11315344593062, "recv_ms": 1787080299963, "bids": [[1000.0, 35.81], [14399.8, 0.756], [14499.8, 3.43], [14599.8, 0.014], [58229.8, 0.002], [61464.8, 0.008], [63699.8, 0.031], [63779.7, 5.074], [63799.8, 2.358], [63977.9, 1.64], [64052.8, 1.741], [64063.7, 0.0], [64376.3, 4.819], [64503.7, 0.02], [64542.6, 0.0], [64663.5, 0.001], [64697.1, 0.086]], "asks": [[64699.9, 12.341], [64701.9, 0.003], [64702.7, 0.157], [64707.6, 0.466], [64707.8, 0.417], [64710.4, 0.319], [64712.1, 0.157], [64746.5, 0.106], [64772.3, 40.218], [64772.4, 0.0], [64774.5, 0.054], [64839.7, 0.072], [64849.9, 0.026], [64856.8, 0.0], [64895.6, 0.0], [65023.4, 4.769], [65346.9, 3.625], [65603.9, 0.456], [65699.9, 0.951]]}
{"kind": "depth", "E": 1787080300061, "U": 11315344593158, "u": 11315344598457, "recv_ms": 1787080300065, "bids": [[1000.0, 35.81], [14399.8, 1.106], [14499.8, 3.094], [14599.8, 0.0], [58229.8, 0.002], [61464.8, 0.008], [61464.9, 0.004], [62111.8, 0.52], [64052.8, 1.739], [64376.3, 4.809], [64503.8, 15.503], [64542.6, 6.846], [64559.6, 6.267], [64672.5, 0.174], [64683.8, 0.022], [64688.2, 0.001], [64692.3, 0.02], [64699.8, 8.782]], "asks": [[64699.9, 12.356], [64702.7, 0.002], [64707.6, 0.311], [64707.8, 0.262], [64710.4, 0.009], [64712.1, 0.002], [64712.6, 0.004], [64712.8, 1.34], [64716.3, 0.163], [64726.9, 2.028], [64743.9, 0.018], [64746.5, 0.064], [64772.2, 6.837], [64839.8, 7.717], [64854.8, 2.184], [64856.8, 10.408], [64895.6, 3.779], [65208.7, 0.004], [65346.9, 3.625], [65467.5, 11.475], [65476.3, 29.536], [65552.8, 2.286]]}
{"kind": "depth", "E": 1787080300163, "U": 11315344598632, "u": 11315344603976, "recv_ms": 1787080300165, "bids": [[14399.8, 1.456], [14499.8, 2.744], [58229.8, 0.002], [62111.8, 0.517], [63454.9, 0.001], [63697.0, 15.213], [63761.7, 24.121], [64052.8, 1.739], [64072.2, 3.1], [64618.5, 0.005], [64620.6, 7.107], [64625.1, 33.875], [64625.2, 0.001], [64648.3, 0.011], [64648.4, 0.0], [64651.0, 0.012], [64657.3, 0.003], [64683.8, 0.024], [64685.9, 0.155], [64686.1, 0.204], [64687.8, 0.003], [64689.1, 0.309], [64690.1, 0.145], [64692.3, 0.12], [64693.6, 0.126]], "asks": [[64706.7, 0.036], [64709.6, 0.156], [64716.3, 0.165], [64746.5, 0.092], [64839.7, 0.096], [64849.9, 0.002], [64895.6, 2.26], [65461.6, 6.912]]}
{"kind": "depth", "E": 1787080300265, "U": 11315344604170, "u": 11315344611211, "recv_ms": 1787080300263, "bids": [[1000.0, 35.81], [14399.8, 1.806], [14499.8, 2.394], [51760.0, 0.004], [58229.8, 0.002], [61464.8, 0.008], [62111.8, 1.209], [63699.8, 0.011], [64052.8, 1.739], [64620.6, 2.368], [64648.0, 1.293], [64668.6, 0.195], [64668.8, 0.117], [64669.4, 0.338], [64670.5, 0.696], [64687.3, 0.251], [64688.9, 0.577], [64692.7, 0.001], [64693.2, 0.027], [64693.4, 0.09], [64693.6, 0.126], [64694.2, 1.914], [64694.6, 0.142], [64694.9, 0.043], [64696.3, 0.005], [64698.1, 0.084]], "asks": [[64699.9, 12.25], [64700.9, 0.006], [64701.5, 0.935], [64701.6, 0.0], [64702.1, 0.001], [64702.7, 0.157], [64707.6, 0.466], [64707.8, 0.417], [64710.4, 0.319], [64712.1, 0.157], [64714.9, 2.322], [64715.0, 1.294], [64746.5, 0.064], [65346.9, 3.625], [65476.3, 29.994], [65699.9, 0.931]]}
{"kind": "depth", "E": 1787080300367, "U": 11315344611219, "u": 11315344617797, "recv_ms": 1787080300425, "bids": [[1000.0, 35.81], [14399.8, 2.17], [14499.8, 2.03], [51760.0, 0.004], [58229.8, 0.002], [61464.8, 0.008], [61464.9, 0.002], [62111.8, 1.206], [63405.9, 0.016], [63996.9, 0.0], [64052.8, 1.739], [64376.3, 4.819], [64403.3, 0.054], [64638.3, 0.002], [64645.4, 0.043], [64654.5, 0.004], [64654.7, 0.125], [64656.0, 1.84], [64660.9, 0.103], [64663.5, 0.015], [64664.3, 0.428], [64669.4, 0.002], [64674.7, 0.009], [64679.8, 0.082], [64680.1, 2.344], [64681.5, 0.05], [64682.1, 0.016], [64684.4, 0.028], [64684.8, 1.009], [64685.0, 0.015], [64685.6, 0.447], [64685.7, 0.286], [64685.8, 0.133], [64687.1, 0.02], [64687.8, 0.312], [64688.5, 1.105], [64688.9, 0.562], [64689.1, 0.0], [64689.3, 0.063], [64689.9, 0.141], [64690.6, 0.173], [64691.6, 1.985], [64691.7, 0.034], [64691.8, 0.001], [64691.9, 0.003], [64692.3, 0.017], [64693.0, 0.086], [64693.1, 0.324], [64693.2, 0.002], [64693.6, 0.008], [64694.2, 1.605], [64694.3, 0.003], [64694.4, 0.004], [64694.5, 0.151], [64694.6, 0.126], [64694.7, 0.049], [64694.9, 0.001], [64696.6, 0.003], [64696.8, 0.002], [64697.1, 0.002], [64698.1, 0.0], [64699.7, 0.045], [64699.8, 5.266]], "asks": [[64699.9, 12.295], [64700.0, 1.281], [64700.3, 0.008], [64700.5, 0.087], [64701.1, 0.089], [64701.5, 0.928], [64701.6, 0.001], [64701.9, 0.019], [64702.1, 0.023], [64702.5, 0.005], [64702.6, 0.244], [64702.7, 0.157], [64702.8, 2.425], [64703.8, 0.213], [64704.5, 0.99], [64704.6, 1.228], [64704.9, 0.068], [64705.6, 0.003], [64705.7, 0.002], [64706.5, 0.31], [64706.7, 0.035], [64706.8, 0.156], [64706.9, 0.677], [64707.5, 0.471], [64707.6, 0.311], [64707.8, 0.417], [64708.2, 0.148], [64710.4, 0.319], [64712.1, 0.157], [64713.3, 0.025], [64715.3, 0.314], [64715.8, 0.001], [64717.6, 10.019], [64718.0, 0.008], [64718.2, 0.076], [64720.0, 2.211], [64723.2, 0.334], [64725.8, 3.121], [64726.0, 2.325], [64737.4, 3.547], [64737.5, 0.0], [64743.9, 0.004], [64745.2, 0.005], [64746.5, 0.064], [64777.1, 0.003], [64809.9, 0.001], [64829.3, 2.322], [64895.6, 8.667], [65217.5, 9.671], [65346.9, 3.625], [65476.3, 30.208], [65702.7, 12.767]]}
{"kind": "depth", "E": 1787080300469, "U": 11315344617932, "u": 11315344623210, "recv_ms": 1787080300449, "bids": [[14399.8, 2.534], [14499.8, 1.666], [58229.8, 0.002], [61464.8, 0.008], [63405.9, 0.019], [63699.8, 0.031], [63766.8, 4.929], [64052.8, 1.741], [64649.8, 0.042], [64651.1, 0.427], [64660.9, 0.117], [64675.1, 0.114], [64676.4, 1.753], [64677.2, 0.0], [64679.8, 0.002], [64680.0, 3.459], [64680.7, 0.168], [64685.7, 0.286], [64688.5, 0.471], [64688.6, 0.001], [64691.1, 0.049], [64691.6, 1.984], [64691.7, 1.876], [64691.8, 0.094], [64692.3, 0.117], [64693.1, 0.001], [64693.6, 1.066], [64693.7, 0.55], [64694.3, 0.191], [64696.5, 0.003], [64699.8, 4.731]], "asks": [[64699.9, 12.297], [64702.6, 0.244], [64702.7, 0.659], [64704.4, 0.515], [64704.8, 0.018], [64705.0, 0.922], [64705.7, 0.064], [64706.8, 0.001], [64706.9, 0.02], [64707.0, 0.5], [64707.5, 0.0], [64707.6, 0.311], [64707.8, 0.262], [64710.3, 0.093], [64710.4, 0.009], [64712.1, 0.002], [64712.5, 1.243], [64712.8, 1.34], [64713.3, 0.95], [64713.9, 0.042], [64715.0, 1.294], [64715.8, 0.557], [64715.9, 0.019], [64716.5, 0.006], [64716.7, 0.062], [64717.4, 0.014], [64717.8, 0.003], [64718.3, 0.675], [64719.2, 0.002], [64719.7, 0.002], [64720.0, 2.326], [64720.8, 0.003], [64790.6, 0.0], [64895.6, 5.335], [65346.9, 3.625], [65699.9, 0.951]]}
{"kind": "depth", "E": 1787080300571, "U": 11315344623249, "u": 11315344627747, "recv_ms": 1787080300533, "bids": [[1000.0, 35.81], [14399.8, 2.884], [14499.8, 1.316], [58229.8, 0.002], [61464.8, 0.006], [61464.9, 0.004], [62111.8, 1.209], [63729.4, 0.0], [63909.1, 5.609], [63914.8, 9.907], [63964.4, 0.004], [64052.8, 1.739], [64173.6, 0.002], [64367.6, 0.047], [64633.9, 0.0], [64634.2, 0.133], [64634.5, 0.0], [64634.9, 0.043], [64635.2, 1.102], [64652.9, 0.106], [64653.3, 0.245], [64653.4, 0.045], [64653.6, 0.118], [64653.9, 0.015], [64654.3, 0.001], [64654.4, 1.199], [64667.9, 0.0], [64668.0, 0.005], [64668.1, 2.321], [64668.2, 2.21], [64668.3, 0.06], [64668.4, 0.071], [64668.5, 0.036], [64668.6, 0.025], [64668.8, 0.047], [64671.2, 0.002], [64671.6, 0.001], [64680.0, 2.533], [64680.7, 1.094], [64681.6, 0.238], [64688.6, 0.001], [64689.9, 0.001], [64690.0, 0.011], [64690.1, 0.005], [64690.2, 0.002], [64690.3, 0.07], [64690.4, 0.001], [64690.5, 0.309], [64690.6, 0.103], [64690.7, 0.102], [64690.8, 0.164], [64691.1, 0.017], [64691.2, 1.281], [64691.4, 0.016], [64691.5, 0.033], [64691.7, 1.844], [64691.8, 0.094], [64692.1, 0.0], [64692.3, 0.067], [64692.4, 0.0], [64692.5, 0.035], [64699.8, 4.737]], "asks": [[64699.9, 12.332], [64700.3, 0.001], [64700.8, 0.019], [64702.6, 0.244], [64704.3, 0.088], [64704.4, 0.052], [64706.4, 0.008], [64706.7, 0.003], [64707.0, 0.494], [64707.3, 0.479], [64707.5, 0.463], [64707.6, 0.273], [64707.8, 0.262], [64707.9, 1.193], [64708.0, 0.906], [64708.1, 0.081], [64708.2, 0.126], [64708.3, 0.258], [64708.4, 0.001], [64708.5, 0.466], [64708.6, 2.812], [64708.7, 0.135], [64708.8, 0.221], [64708.9, 0.234], [64709.0, 0.092], [64709.1, 0.232], [64710.4, 0.009], [64712.1, 0.002], [64712.8, 1.339], [64713.3, 0.025], [64714.0, 0.947], [64715.8, 0.001], [64716.6, 0.562], [64718.3, 0.134], [64719.2, 0.543], [64720.0, 2.211], [64720.8, 0.118], [64725.4, 0.028], [64725.7, 0.009], [64726.1, 0.248], [64726.4, 0.887], [64726.7, 0.0], [64727.0, 3.795], [64727.1, 0.205], [64727.5, 0.002], [64727.8, 0.131], [64729.8, 0.005], [64730.0, 0.02], [64730.1, 0.033], [64730.2, 0.098], [64730.3, 0.024], [64730.4, 0.22], [64730.5, 0.969], [64730.6, 0.514], [64730.7, 0.001], [64730.8, 0.158], [64730.9, 0.1], [64731.1, 0.543], [64744.5, 0.001], [64744.8, 0.309], [64745.1, 1.036], [64745.5, 0.008], [64745.8, 0.036], [64746.1, 0.079], [64895.6, 3.096], [65346.9, 3.625], [65585.9, 6.69]]}
{"kind": "depth", "E": 1787080300775, "U": 11315344635136, "u": 11315344639254, "recv_ms": 1787080300741, "bids": [[14399.8, 3.598], [14499.8, 0.602], [51759.8, 0.0], [58229.8, 0.002], [62111.8, 1.898], [63923.4, 31.244], [64052.8, 1.739], [64182.2, 10.144], [64376.3, 5.197], [64690.3, 0.14], [64690.5, 0.379], [64690.9, 0.07]], "asks": [[64708.6, 2.889], [64708.9, 0.388], [64709.2, 0.073], [64712.8, 1.34], [64730.6, 0.591], [64730.9, 0.184], [64731.1, 0.613], [65346.9, 3.625], [65494.0, 2.405], [65573.3, 5.679]]}
{"kind": "depth", "E": 1787080300877, "U": 11315344639364, "u": 11315344644437, "recv_ms": 1787080300854, "bids": [[1000.0, 35.81], [14299.8, 0.084], [14399.8, 3.78], [14499.8, 0.336], [58229.8, 0.002], [61464.8, 0.006], [63405.9, 0.022], [63699.8, 0.031], [63876.7, 1.835], [63891.1, 12.276], [64052.8, 1.739], [64376.3, 5.206], [64376.4, 0.0], [64634.3, 0.033], [64635.3, 0.441], [64654.0, 0.036], [64666.9, 0.327], [64667.0, 0.009], [64667.1, 0.311], [64670.3, 0.349], [64670.4, 1.244], [64670.5, 0.698], [64676.8, 3.778], [64684.2, 0.006], [64690.9, 0.17], [64691.0, 0.101], [64691.1, 0.187], [64692.2, 0.282], [64699.8, 5.366]], "asks": [[64700.5, 0.084], [64700.9, 0.009], [64701.7, 0.025], [64702.6, 0.245], [64704.4, 0.515], [64707.2, 0.009], [64707.3, 0.517], [64707.5, 0.0], [64707.8, 0.262], [64708.3, 0.398], [64708.4, 0.085], [64708.5, 0.706], [64710.4, 0.009], [64712.1, 0.002], [64712.8, 1.339], [64713.6, 0.09], [64714.0, 0.022], [64714.7, 0.774], [64717.5, 2.532], [64717.6, 0.019], [64718.3, 0.675], [64719.7, 5.002], [64720.0, 12.211], [64720.7, 0.009], [64722.0, 1.114], [64726.4, 0.925], [64727.4, 0.478], [64730.4, 0.424], [64730.5, 1.089], [64745.5, 0.046], [65023.4, 4.769], [65346.9, 3.625], [65699.9, 0.951]]}
{"kind": "depth", "E": 1787080301081, "U": 11315344648617, "u": 11315344652571, "recv_ms": 1787080301044, "bids": [[14299.8, 0.56], [14399.8, 3.542], [14499.8, 0.098], [58229.8, 0.002], [62111.8, 1.898], [63699.8, 0.011], [63706.5, 0.155], [64052.8, 1.739], [64376.3, 5.197], [64668.6, 0.095], [64688.2, 0.001], [64694.5, 0.151]], "asks": [[64706.5, 0.001], [64707.2, 0.318], [64717.2, 3.552], [64730.7, 0.111], [64730.8, 0.228], [64730.9, 0.338], [64740.0, 1.262], [64743.9, 0.046], [64767.2, 0.509], [64769.8, 0.0], [65346.9, 3.625], [65693.3, 0.77], [65699.9, 0.931]]}
{"kind": "depth", "E": 1787080301183, "U": 11315344652703, "u": 11315344657469, "recv_ms": 1787080301151, "bids": [[1000.0, 35.81], [14299.8, 0.826], [14399.8, 3.374], [14499.8, 0.0], [51760.0, 0.004], [58229.8, 0.002], [61464.8, 0.006], [62111.8, 1.895], [63708.8, 0.01], [63784.4, 9.325], [64052.8, 1.739], [64376.3, 5.197], [64635.0, 0.076], [64648.3, 0.012], [64650.9, 0.014], [64657.3, 0.005], [64668.3, 0.13], [64668.6, 0.165], [64668.9, 0.079], [64676.8, 3.16], [64683.8, 0.024], [64690.1, 0.004], [64692.3, 0.205], [64692.9, 0.0], [64694.5, 0.151], [64699.8, 5.365]], "asks": [[64699.9, 12.279], [64700.3, 0.055], [64702.6, 0.245], [64704.4, 0.044], [64706.9, 0.028], [64707.2, 0.318], [64707.8, 0.262], [64709.5, 0.005], [64710.4, 0.009], [64712.1, 0.002], [64716.3, 0.165], [64743.9, 0.004], [65346.9, 3.625], [65446.4, 0.0]]}
{"kind": "depth", "E": 1787080301285, "U": 11315344657649, "u": 11315344661152, "recv_ms": 1787080301249, "bids": [[1000.0, 35.81], [14299.8, 1.176], [14399.8, 3.024], [58229.8, 0.002], [61464.8, 0.006], [62111.8, 1.898], [63405.9, 0.019], [63699.8, 0.031], [64052.8, 1.739], [64660.9, 0.103], [64663.5, 0.001], [64668.5, 0.176], [64669.0, 0.101], [64669.1, 0.256], [64672.1, 0.2], [64674.5, 0.003], [64675.3, 0.004], [64676.0, 0.581], [64676.4, 1.637], [64677.7, 0.12], [64679.9, 0.006], [64680.7, 0.168], [64681.2, 0.937], [64684.4, 0.021], [64685.7, 0.293], [64685.9, 0.155], [64686.0, 0.588], [64687.8, 0.003], [64688.5, 0.0], [64688.9, 0.871], [64691.1, 0.186], [64691.8, 0.565], [64692.3, 0.017], [64692.4, 0.003], [64693.0, 0.002], [64693.2, 0.003], [64693.4, 0.006], [64694.0, 0.312], [64694.2, 1.604], [64694.5, 0.151], [64696.3, 0.005], [64697.5, 0.088], [64697.8, 0.001], [64697.9, 0.26], [64698.4, 0.085], [64699.8, 7.51]], "asks": [[64700.0, 1.197], [64700.5, 0.0], [64700.8, 0.012], [64700.9, 0.006], [64701.1, 0.005], [64701.2, 0.0], [64701.6, 0.01], [64701.7, 0.044], [64702.1, 0.024], [64702.6, 0.245], [64702.7, 0.566], [64704.4, 0.06], [64704.6, 1.312], [64706.9, 0.105], [64707.2, 0.009], [64707.8, 0.262], [64707.9, 1.502], [64709.5, 0.004], [64710.4, 0.009], [64712.1, 0.002], [64712.6, 0.324], [64712.7, 0.164], [64713.3, 0.018], [64713.6, 0.01], [64713.7, 0.927], [64714.0, 0.102], [64714.3, 0.007], [64714.7, 0.156], [64714.9, 2.322], [64715.0, 0.974], [64715.5, 0.0], [64716.2, 0.557], [64716.6, 0.006], [64718.3, 0.134], [64719.2, 0.543], [64719.5, 1.323], [64719.6, 0.001], [64720.0, 12.213], [64720.5, 0.151], [64720.7, 0.009], [64720.8, 0.003], [64722.0, 0.496], [64723.2, 0.025], [64724.5, 0.31], [64743.9, 0.046], [64769.8, 0.009], [64895.6, 0.0], [64895.7, 2.804], [65346.9, 3.625], [65690.8, 1.065], [65699.9, 0.951], [65993.8, 0.053]]}
{"kind": "depth", "E": 1787080301489, "U": 11315344665860, "u": 11315344670200, "recv_ms": 1787080301439, "bids": [[1000.0, 35.81], [14299.8, 1.904], [14399.8, 2.296], [58229.8, 0.002], [62111.8, 1.895], [63699.8, 0.011], [63787.5, 5.02], [63794.0, 24.251], [64052.8, 1.739], [64376.3, 5.207], [64470.0, 0.288], [64618.5, 0.005], [64622.1, 0.021], [64625.1, 33.869], [64681.7, 0.479], [64681.8, 0.008], [64685.2, 0.471], [64685.7, 0.286], [64688.5, 0.0], [64688.6, 0.001], [64691.8, 0.658], [64693.2, 0.002], [64693.5, 0.047], [64693.6, 0.796], [64693.7, 0.002], [64693.9, 0.0], [64694.3, 0.191], [64694.4, 0.004], [64694.5, 0.135]], "asks": [[64704.4, 0.06], [64706.9, 0.105], [65346.9, 3.625], [65597.0, 26.591], [65655.7, 0.0], [65699.9, 0.931]]}
{"kind": "depth", "E": 1787080301591, "U": 11315344670247, "u": 11315344677158, "recv_ms": 1787080301564, "bids": [[1000.0, 35.81], [14299.8, 2.254], [14399.8, 1.946], [51760.0, 0.004], [58229.8, 0.002], [61464.8, 0.008], [62111.8, 1.898], [63729.4, 0.008], [64052.8, 1.739], [64542.6, 7.7], [64559.6, 6.704], [64618.5, 33.874], [64625.1, 0.0], [64641.5, 0.009], [64679.5, 5.026], [64681.7, 0.016], [64681.8, 0.0], [64688.5, 0.0], [64691.8, 1.121], [64691.9, 0.043], [64697.9, 0.176], [64698.2, 0.001], [64698.4, 0.001], [64699.8, 7.559]], "asks": [[64699.9, 12.278], [64700.9, 0.09], [64702.6, 0.245], [64704.4, 0.044], [64706.9, 0.121], [64707.2, 0.009], [64707.8, 0.262], [64710.4, 0.009], [64712.1, 0.002], [64738.8, 3.498], [64758.2, 0.018], [64839.7, 0.072], [64839.8, 7.717], [64849.9, 0.026], [64854.8, 0.687], [64856.8, 10.408], [64895.7, 3.097], [65346.9, 3.625], [66317.4, 0.68]]}
{"kind": "depth", "E": 1787080301795, "U": 11315344683669, "u": 11315344688318, "recv_ms": 1787080301746, "bids": [[1000.0, 35.81], [14299.8, 2.968], [14399.8, 1.232], [51759.8, 0.0], [51760.0, 0.004], [58229.8, 0.002], [62111.8, 1.898], [63942.8, 3.287], [64052.8, 1.739], [64156.3, 0.824], [64376.3, 5.207], [64685.9, 0.001], [64694.5, 0.128], [64697.3, 0.007]], "asks": [[64699.9, 11.085], [64702.3, 0.007], [64702.6, 0.245], [64702.8, 2.417], [64703.6, 0.013], [64705.7, 0.016], [64707.2, 0.009], [64707.3, 0.579], [64707.8, 0.262], [64710.4, 0.009], [64712.1, 0.002], [65346.9, 3.625], [65476.3, 30.422], [65670.4, 5.252]]}
{"kind": "depth", "E": 1787080302101, "U": 11315344697720, "u": 11315344704979, "recv_ms": 1787080302053, "bids": [[1000.0, 35.81], [14199.8, 0.14], [14299.8, 3.752], [14399.8, 0.308], [58229.8, 0.002], [61464.8, 0.008], [61464.9, 0.006], [62111.8, 1.898], [63599.1, 0.63], [63699.8, 0.031], [64052.8, 1.741], [64156.3, 0.816], [64376.3, 5.197], [64542.6, 7.695], [64559.6, 6.701], [64623.0, 6.671], [64657.4, 0.002], [64660.9, 0.117], [64661.9, 1.256], [64669.2, 0.124], [64675.0, 0.83], [64675.5, 0.559], [64675.9, 0.08], [64676.5, 0.001], [64676.6, 0.117], [64677.5, 0.002], [64677.6, 0.003], [64678.6, 0.001], [64679.5, 0.028], [64680.2, 0.134], [64681.5, 0.058], [64681.6, 0.201], [64686.1, 0.358], [64686.2, 0.0], [64688.2, 0.001], [64691.8, 0.658], [64691.9, 0.035], [64692.4, 0.0], [64692.7, 0.085], [64693.0, 0.086], [64693.4, 0.09], [64693.7, 0.002], [64694.0, 0.002], [64694.3, 0.003], [64695.0, 0.097], [64696.2, 0.07], [64696.9, 0.001], [64697.3, 0.001], [64697.5, 0.004], [64699.8, 3.713]], "asks": [[64699.9, 11.558], [64700.5, 0.084], [64702.5, 0.021], [64702.6, 0.407], [64704.4, 0.052], [64704.6, 1.228], [64706.9, 0.252], [64707.8, 0.417], [64710.4, 0.319], [64712.1, 0.157], [64719.6, 0.116], [64719.9, 10.0], [64720.5, 0.036], [64741.5, 3.64], [64742.3, 0.0], [64743.9, 0.004], [64839.7, 0.072], [64839.8, 7.717], [64849.9, 0.026], [64854.8, 0.687], [64856.8, 10.408], [64895.7, 3.121], [65023.4, 4.769], [65346.9, 3.633], [65469.8, 8.235], [65511.2, 0.002], [65699.9, 0.951], [65993.8, 0.047]]}
{"kind": "depth", "E": 1787080302203, "U": 11315344705021, "u": 11315344727966, "recv_ms": 1787080302155, "bids": [[1000.0, 35.81], [14199.8, 0.392], [14299.8, 3.612], [14399.8, 0.196], [58229.8, 0.002], [61464.8, 0.008], [62111.8, 1.895], [63405.8, 0.974], [63405.9, 0.019], [63699.8, 0.011], [63769.2, 0.002], [63781.1, 2.11], [63976.3, 3.134], [64052.8, 1.739], [64376.3, 4.576], [64618.5, 0.005], [64622.9, 37.884], [64623.0, 1.798], [64651.1, 0.429], [64657.4, 0.003], [64658.3, 0.0], [64661.2, 0.0], [64661.4, 0.154], [64664.6, 0.059], [64664.7, 0.0], [64665.0, 1.312], [64667.7, 1.005], [64667.9, 0.154], [64668.1, 2.32], [64669.1, 0.346], [64669.6, 0.023], [64670.0, 1.404], [64674.2, 2.32], [64674.4, 1.397], [64675.0, 0.212], [64675.3, 0.561], [64675.5, 0.002], [64675.6, 0.0], [64676.6, 0.001], [64676.8, 3.197], [64677.0, 1.096], [64677.5, 0.009], [64680.0, 2.533], [64680.6, 0.928], [64680.7, 0.175], [64681.2, 0.004], [64681.5, 0.05], [64681.9, 0.025], [64682.4, 0.001], [64683.8, 0.025], [64684.2, 0.013], [64685.0, 0.015], [64685.2, 0.464], [64685.6, 0.571], [64685.7, 0.162], [64685.9, 0.001], [64686.1, 0.204], [64686.2, 0.0], [64686.3, 0.001], [64686.4, 0.001], [64687.4, 0.31], [64688.1, 2.357], [64688.2, 1.013], [64688.3, 0.004], [64688.4, 0.002], [64688.5, 0.0], [64688.9, 0.562], [64690.0, 0.011], [64691.2, 1.552], [64691.3, 0.004], [64691.5, 0.034], [64691.6, 1.985], [64691.8, 0.657], [64692.6, 0.055], [64692.9, 0.003], [64693.5, 0.046], [64693.7, 0.002], [64695.0, 0.097], [64695.8, 0.087], [64696.2, 0.154], [64696.3, 0.006], [64697.8, 0.0], [64699.7, 0.045], [64699.8, 5.738]], "asks": [[64699.9, 11.548], [64700.2, 0.002], [64700.5, 0.087], [64701.3, 0.884], [64701.6, 0.0], [64701.9, 0.0], [64702.0, 0.088], [64702.1, 0.0], [64702.5, 0.098], [64702.6, 0.252], [64702.7, 0.567], [64702.8, 2.416], [64704.2, 0.526], [64704.3, 0.088], [64704.4, 0.052], [64705.7, 0.064], [64706.3, 0.313], [64706.9, 0.02], [64707.0, 0.494], [64707.5, 0.0], [64707.6, 0.311], [64707.8, 0.262], [64707.9, 1.193], [64710.4, 0.009], [64712.1, 0.002], [64712.8, 1.41], [64712.9, 2.109], [64715.0, 0.974], [64716.0, 1.585], [64716.2, 0.001], [64716.3, 0.165], [64717.6, 0.019], [64718.3, 0.675], [64719.2, 0.002], [64719.6, 0.001], [64719.9, 10.002], [64720.0, 2.211], [64720.2, 0.116], [64720.3, 0.105], [64729.3, 0.971], [64730.9, 0.184], [64769.8, 0.0], [64777.1, 0.003], [64839.7, 0.096], [64849.9, 0.002], [64895.7, 9.134], [65346.9, 3.625], [65699.9, 0.931], [65993.8, 0.05]]}
{"kind": "depth", "E": 1787080302305, "U": 11315344728210, "u": 11315344736260, "recv_ms": 1787080302257, "bids": [[14199.8, 0.616], [14299.8, 3.514], [14399.8, 0.07], [51760.0, 0.004], [58229.8, 0.002], [61464.8, 0.008], [63587.0, 1.535], [63709.2, 7.774], [63945.1, 1.562], [64052.8, 1.739], [64622.9, 3.939], [64625.1, 33.945], [64645.3, 3.598], [64653.6, 2.246], [64653.7, 0.055], [64660.9, 0.103], [64661.9, 0.92], [64662.0, 2.161], [64666.0, 3.439], [64667.2, 3.838], [64675.3, 0.631], [64686.0, 0.742], [64686.1, 0.204], [64686.2, 0.0], [64687.1, 0.005], [64688.2, 1.005], [64688.3, 0.661], [64688.8, 0.151], [64691.3, 0.003], [64691.6, 1.984], [64691.8, 0.008], [64691.9, 0.035], [64692.7, 0.001], [64692.9, 0.003], [64693.5, 0.046], [64693.6, 0.001], [64694.1, 0.395], [64694.3, 1.222], [64694.4, 0.192], [64697.4, 0.311], [64697.5, 0.004], [64698.9, 0.084], [64699.8, 7.237]], "asks": [[64699.9, 10.309], [64700.5, 0.0], [64700.9, 0.006], [64701.3, 0.842], [64701.4, 0.014], [64701.5, 0.844], [64702.5, 0.021], [64702.6, 0.252], [64702.7, 0.551], [64703.4, 0.0], [64703.6, 0.004], [64704.2, 0.063], [64704.4, 0.137], [64704.6, 1.312], [64705.0, 1.003], [64705.6, 0.006], [64705.7, 0.016], [64706.3, 0.004], [64706.9, 0.491], [64707.5, 0.0], [64707.6, 0.373], [64707.8, 0.571], [64710.4, 0.009], [64712.1, 0.002], [64712.6, 0.004], [64712.7, 0.484], [64714.0, 0.102], [64717.2, 1.863], [64718.3, 0.134], [64719.2, 0.543], [64719.9, 0.002], [64720.0, 3.703], [64720.7, 0.009], [64723.1, 10.024], [64725.4, 0.024], [64725.5, 0.004], [64725.8, 3.135], [64730.8, 0.382], [64735.9, 2.001], [64738.7, 0.092], [64743.9, 0.046], [64746.5, 0.078], [64764.2, 6.006], [64765.0, 1.231], [64769.8, 0.009], [64795.4, 2.139], [64795.5, 0.001], [64803.8, 2.505], [64803.9, 0.116], [64812.1, 2.122], [64812.2, 0.628], [64890.8, 0.002], [64890.9, 0.003], [65346.9, 3.626], [65469.8, 9.15]]}
{"kind": "depth", "E": 1787080302407, "U": 11315344736400, "u": 11315344741734, "recv_ms": 1787080302356, "bids": [[1000.0, 35.81], [14199.8, 0.91], [14299.8, 3.29], [14399.8, 0.0], [58229.8, 0.002], [62111.8, 1.898], [63748.7, 7.591], [63891.1, 12.541], [63923.4, 32.712], [64052.8, 1.739], [64376.3, 4.586], [64624.7, 0.0]], "asks": [[64730.8, 0.382], [64785.6, 1.255], [64829.3, 2.323], [65346.9, 3.626]]}
{"kind": "depth", "E": 1787080302713, "U": 11315344752273, "u": 11315344757194, "recv_ms": 1787080302669, "bids": [[1000.0, 35.81], [14199.8, 1.974], [14299.8, 2.226], [51759.8, 0.0], [58229.8, 0.002], [62111.8, 1.895], [63699.8, 0.011], [63740.9, 0.658], [64052.8, 1.739], [64376.3, 5.207], [64559.6, 6.792], [64685.8, 0.287], [64694.8, 0.019]], "asks": [[64708.2, 0.146], [64710.1, 0.041], [64718.2, 0.016], [64829.3, 2.322], [64839.9, 6.863], [64895.7, 2.263], [65346.9, 3.626], [65699.9, 0.931], [71169.9, 0.002]]}
{"kind": "depth", "E": 1787080302815, "U": 11315344757315, "u": 11315344762639, "recv_ms": 1787080302765, "bids": [[1000.0, 35.81], [14199.8, 2.338], [14299.8, 1.862], [58229.8, 0.002], [63794.0, 26.788], [64052.8, 1.739], [64679.4, 5.0], [64694.8, 0.041]], "asks": [[65346.9, 3.626], [65605.7, 25.578], [71169.9, 0.0]]}
{"kind": "depth", "E": 1787080302917, "U": 11315344762841, "u": 11315344768731, "recv_ms": 1787080302868, "bids": [[14199.8, 2.702], [14299.8, 1.498], [58229.8, 0.002], [61464.8, 0.008], [62111.8, 1.898], [63699.8, 0.031], [64052.8, 1.739], [64503.8, 15.503], [64542.6, 7.878], [64559.6, 6.792], [64641.5, 0.006], [64654.5, 0.004], [64666.0, 3.103], [64670.2, 0.629], [64693.9, 0.0], [64694.4, 0.004], [64697.5, 0.01], [64699.8, 7.239]], "asks": [[64699.9, 10.215], [64702.6, 0.252], [64707.4, 0.199], [64707.6, 0.311], [64710.4, 0.009], [64712.1, 0.002], [64745.2, 0.005], [64746.5, 0.078], [64839.9, 6.863], [64856.8, 10.408], [64895.7, 2.263], [65346.9, 3.626], [65422.2, 6.403], [65699.9, 0.951], [65799.8, 8.36], [65824.3, 0.303]]}
{"kind": "depth", "E": 1787080303121, "U": 11315344776995, "u": 11315344785968, "recv_ms": 1787080303072, "bids": [[1000.0, 35.81], [14199.8, 3.402], [14299.8, 0.798], [58229.8, 0.002], [61464.8, 0.008], [62111.8, 1.898], [63699.8, 0.011], [63706.4, 0.0], [63750.0, 13.873], [63876.7, 1.601], [64052.8, 1.739], [64376.3, 5.197], [64500.0, 25.274], [64599.7, 0.002], [64599.8, 6.674], [64618.5, 33.95], [64625.1, 0.0], [64625.2, 0.001], [64645.4, 0.043], [64648.0, 1.307], [64651.1, 0.43], [64657.4, 0.004], [64675.3, 0.692], [64676.2, 0.64], [64677.0, 0.98], [64677.9, 0.347], [64682.7, 0.005], [64684.2, 0.006], [64685.9, 0.008], [64687.4, 0.001], [64688.2, 1.005], [64689.0, 0.31], [64690.1, 0.005], [64693.3, 0.363], [64694.0, 0.056], [64694.5, 0.108], [64696.3, 0.005], [64697.3, 0.085], [64698.2, 0.002], [64698.9, 0.0], [64699.3, 0.0], [64699.7, 0.06], [64699.8, 7.193]], "asks": [[64699.9, 10.377], [64700.0, 1.197], [64701.0, 0.134], [64701.4, 0.004], [64701.9, 0.01], [64702.5, 0.57], [64702.6, 0.251], [64702.7, 0.157], [64702.9, 0.312], [64703.4, 0.001], [64704.4, 0.044], [64705.0, 0.102], [64705.2, 0.155], [64706.7, 0.036], [64706.8, 0.156], [64706.9, 0.584], [64707.6, 0.311], [64707.8, 0.417], [64708.2, 0.455], [64708.3, 0.552], [64709.1, 0.078], [64710.0, 0.143], [64710.4, 0.319], [64710.6, 0.003], [64710.9, 0.004], [64711.6, 0.197], [64712.1, 0.157], [64713.1, 0.13], [64713.2, 0.834], [64713.7, 0.002], [64713.9, 0.967], [64714.3, 0.0], [64714.8, 0.335], [64715.0, 0.974], [64716.0, 1.029], [64716.5, 0.562], [64716.7, 0.005], [64717.4, 0.071], [64718.5, 0.317], [64718.8, 0.062], [64719.2, 0.543], [64720.0, 3.703], [64720.2, 0.001], [64720.5, 0.654], [64720.7, 0.124], [64724.5, 0.31], [64725.0, 0.054], [64725.8, 3.121], [64730.0, 0.02], [64730.4, 0.578], [64730.7, 0.111], [64731.1, 0.613], [64746.5, 0.064], [64854.8, 2.184], [64856.8, 7.716], [64895.7, 5.63], [65023.4, 4.769], [65346.9, 3.626], [65693.2, 0.76], [65699.9, 0.931], [65993.8, 0.05]]}
{"kind": "depth", "E": 1787080303223, "U": 11315344786009, "u": 11315344791934, "recv_ms": 1787080303175, "bids": [[14199.8, 3.71], [14299.8, 0.462], [14599.8, 0.028], [51760.0, 0.006], [58229.8, 0.002], [62111.8, 1.895], [63706.5, 0.166], [64052.8, 1.739], [64580.4, 3.864], [64584.0, 2.941], [64618.5, 0.005], [64624.7, 0.0], [64625.1, 33.868], [64628.5, 0.065], [64628.9, 2.673], [64651.5, 0.001], [64667.7, 0.002], [64683.8, 0.025], [64688.2, 0.542], [64688.3, 0.004], [64691.8, 0.587], [64691.9, 0.576], [64693.4, 0.09], [64693.7, 0.003], [64694.1, 0.394], [64694.4, 0.192], [64694.5, 0.086], [64695.0, 0.116], [64697.4, 0.001], [64697.9, 0.004]], "asks": [[64702.7, 0.002], [64706.8, 0.001], [64707.8, 0.262], [64710.4, 0.009], [64712.1, 0.002], [64716.3, 0.165], [64725.3, 0.347], [64730.4, 0.424], [64730.9, 0.184], [64731.0, 0.298], [64740.0, 0.838], [64741.5, 0.14], [64763.1, 0.587], [64764.2, 0.006], [64770.9, 0.048], [64835.2, 6.183], [64835.4, 0.385], [64835.5, 0.0], [64842.3, 0.0], [65346.9, 3.626], [65693.3, 0.781]]}
{"kind": "depth", "E": 1787080303325, "U": 11315344792023, "u": 11315344795885, "recv_ms": 1787080303277, "bids": [[1000.0, 35.81], [14199.8, 3.71], [14299.8, 0.28], [14599.8, 0.21], [51760.0, 0.004], [58229.8, 0.002], [61464.8, 0.008], [63699.8, 0.031], [63913.8, 7.746], [64052.8, 1.739], [64376.3, 5.207], [64559.6, 6.792], [64596.6, 0.016], [64666.9, 0.325], [64667.0, 0.007], [64667.1, 0.309], [64670.3, 0.347], [64670.4, 1.242], [64670.5, 0.696], [64694.3, 1.41], [64694.4, 0.004], [64699.8, 7.191]], "asks": [[64702.7, 0.002], [64707.6, 0.311], [64707.8, 0.262], [64710.4, 0.009], [64712.1, 0.002], [64718.6, 0.0], [64721.7, 0.05], [64770.1, 37.781], [64772.3, 1.251], [64793.9, 2.386], [64796.5, 0.211], [64839.9, 6.863], [64895.7, 2.264], [65346.9, 3.625], [65699.9, 0.951]]}
{"kind": "depth", "E": 1787080303529, "U": 11315344799875, "u": 11315344805245, "recv_ms": 1787080303481, "bids": [[14199.8, 3.486], [14299.8, 0.042], [14599.8, 0.672], [58229.8, 0.002], [61464.8, 0.01], [62111.8, 1.895], [63405.9, 0.013], [63699.8, 0.011], [64052.8, 1.739], [64596.6, 10.016], [64641.5, 0.009]], "asks": [[64699.9, 10.41], [64700.6, 0.085], [64702.7, 0.002], [64707.6, 0.311], [64707.8, 0.262], [64710.4, 0.009], [64712.1, 0.002], [64731.0, 0.144], [64731.1, 0.767], [64751.7, 0.097], [64770.1, 0.001], [64772.3, 39.031], [64772.4, 0.0], [64774.5, 0.054], [64794.1, 10.379], [64809.9, 0.004], [64829.3, 2.322], [64895.7, 4.465], [65346.9, 3.625], [65699.9, 0.931]]}
{"kind": "depth", "E": 1787080303631, "U": 11315344805441, "u": 11315344811109, "recv_ms": 1787080303583, "bids": [[1000.0, 35.81], [14199.8, 3.206], [14299.8, 0.0], [14599.8, 0.994], [58229.8, 0.002], [62111.8, 1.898], [63405.9, 0.016], [63923.4, 34.275], [64052.8, 1.739], [64376.3, 5.207], [64559.6, 2.059], [64633.7, 3.198], [64688.3, 1.124], [64689.1, 0.008], [64691.6, 0.0], [64691.8, 0.0], [64691.9, 0.035], [64693.2, 0.003], [64693.7, 0.002], [64694.3, 0.825]], "asks": [[64701.3, 0.861], [64765.4, 2.854], [64790.6, 0.1], [64793.9, 3.573], [64839.9, 1.465], [65346.9, 3.625], [66317.4, 1.057], [71169.9, 0.0]]}
{"kind": "depth", "E": 1787080303733, "U": 11315344811215, "u": 11315344815515, "recv_ms": 1787080303685, "bids": [[1000.0, 35.81], [14199.8, 2.856], [14599.8, 1.344], [51759.8, 0.0], [58229.8, 0.002], [63699.8, 0.031], [64052.8, 1.739], [64542.6, 0.0], [64627.3, 0.012], [64691.3, 0.001], [64695.0, 0.139]], "asks": [[64854.8, 0.687], [64856.8, 0.0], [65346.9, 3.627], [65699.9, 0.951]]}
{"kind": "depth", "E": 1787080303835, "U": 11315344815566, "u": 11315344819443, "recv_ms": 1787080303787, "bids": [[14199.8, 2.492], [14599.8, 1.708], [51760.0, 0.004], [58229.8, 0.002], [62111.8, 1.895], [64052.8, 1.739], [64503.8, 0.0], [64685.8, 0.133], [64685.9, 0.162]], "asks": [[64895.7, 0.001], [65346.9, 3.625], [65488.1, 1.526], [65612.2, 3.499]]}
{"kind": "depth", "E": 1787080304039, "U": 11315344823093, "u": 11315344826867, "recv_ms": 1787080303993, "bids": [[14199.8, 1.778], [14599.8, 2.422], [58229.8, 0.002], [62111.8, 1.895], [63699.8, 0.031], [63784.4, 4.669], [64052.8, 1.739], [64376.3, 5.198], [64559.6, 6.802], [64670.2, 0.293], [64680.9, 1.906], [64688.2, 0.547], [64692.9, 0.0], [64694.1, 0.084], [64697.3, 0.001], [64699.8, 7.19]], "asks": [[64699.9, 10.492], [64702.7, 0.467], [64705.0, 0.018], [64707.6, 0.466], [64707.8, 0.417], [64710.4, 0.319], [64712.1, 0.157], [64839.9, 6.863], [64895.7, 2.105], [65023.4, 4.768], [65346.9, 3.625], [65699.9, 0.951]]}
{"kind": "depth", "E": 1787080304141, "U": 11315344826972, "u": 11315344834922, "recv_ms": 1787080304095, "bids": [[14199.8, 1.414], [14599.8, 2.786], [51760.0, 0.004], [58229.8, 0.002], [61464.8, 0.008], [61464.9, 0.006], [62111.8, 1.898], [64052.8, 1.739], [64376.3, 5.197], [64625.2, 6.303], [64651.2, 1.194], [64657.5, 0.005], [64660.9, 0.037], [64661.4, 0.0], [64664.6, 0.002], [64665.0, 1.309], [64667.2, 4.174], [64667.9, 0.0], [64669.6, 0.022], [64670.0, 1.401], [64674.4, 1.243], [64675.0, 0.209], [64676.2, 0.083], [64677.5, 0.002], [64677.9, 0.231], [64680.0, 2.53], [64680.6, 0.002], [64680.7, 0.168], [64683.8, 0.024], [64685.0, 0.012], [64685.9, 0.155], [64688.2, 0.001], [64688.3, 0.004], [64689.0, 0.001], [64690.0, 0.008], [64691.2, 1.281], [64691.5, 0.033], [64692.1, 0.0], [64692.3, 0.205], [64692.4, 0.1], [64693.2, 0.002], [64694.3, 1.013], [64695.0, 0.136], [64698.2, 0.001], [64699.7, 0.058]], "asks": [[64701.3, 0.863], [64702.7, 0.312], [64707.6, 0.311], [64707.8, 0.262], [64710.4, 0.009], [64712.1, 0.002], [64736.0, 2.616], [64743.9, 0.004], [64854.8, 2.184], [64895.7, 6.328], [65346.9, 3.625], [65367.9, 2.291], [65812.7, 0.758], [65825.4, 1.818], [65909.8, 3.936]]}
{"kind": "depth", "E": 1787080304243, "U": 11315344835108, "u": 11315344840733, "recv_ms": 1787080304194, "bids": [[1000.0, 35.81], [14199.8, 1.064], [14599.8, 3.136], [51760.0, 0.004], [58229.8, 0.002], [61464.8, 0.008], [63405.9, 0.019], [63699.8, 0.011], [64052.8, 1.739], [64376.3, 5.207], [64618.5, 33.873], [64625.1, 0.0], [64625.2, 0.001], [64641.5, 0.006], [64654.5, 0.004], [64660.9, 0.023], [64662.8, 0.164], [64665.0, 1.312], [64665.3, 0.079], [64669.3, 0.224], [64670.0, 1.404], [64671.2, 0.003], [64675.0, 0.212], [64675.6, 0.154], [64676.0, 0.581], [64677.5, 0.009], [64677.7, 0.12], [64680.0, 2.533], [64681.3, 2.245], [64682.2, 0.472], [64683.8, 0.024], [64684.0, 0.013], [64685.0, 0.015], [64685.7, 0.169], [64685.9, 0.155], [64688.2, 1.089], [64688.9, 0.871], [64689.0, 0.542], [64689.2, 0.472], [64690.0, 0.011], [64691.6, 0.001], [64692.3, 0.117], [64692.4, 0.0], [64692.5, 0.309], [64692.6, 0.155], [64693.2, 0.003], [64694.3, 0.825], [64694.4, 0.004], [64695.0, 0.139], [64696.9, 0.085], [64698.0, 0.163], [64698.2, 0.002], [64699.7, 0.07], [64699.8, 7.29]], "asks": [[64699.9, 10.464], [64702.4, 0.093], [64707.6, 0.311], [64707.8, 0.262], [64710.4, 0.009], [64712.1, 0.002], [64713.2, 0.216], [64716.3, 0.165], [64733.5, 0.055], [64743.9, 0.046], [64744.4, 0.002], [64745.2, 0.005], [64809.9, 0.001], [64828.9, 0.093], [64895.7, 2.651], [65023.4, 4.769], [65346.9, 3.625], [65699.9, 0.931]]}
{"kind": "depth", "E": 1787080304345, "U": 11315344840808, "u": 11315344844730, "recv_ms": 1787080304303, "bids": [[14199.8, 0.714], [14599.8, 3.486], [51760.0, 0.004], [58229.8, 0.002], [62111.8, 1.895], [63068.2, 0.554], [63543.8, 0.0], [63766.8, 4.695], [63794.0, 29.136], [64052.8, 1.739], [64635.1, 0.346], [64692.3, 0.017], [64692.9, 0.001], [64693.2, 0.002], [64696.2, 0.161], [64697.5, 0.004]], "asks": [[64699.9, 10.38], [64702.4, 0.093], [64707.6, 0.311], [64707.8, 0.262], [64710.4, 0.009], [64712.1, 0.002], [64764.6, 0.005], [65346.9, 3.625], [65821.0, 0.0]]}
{"kind": "depth", "E": 1787080304447, "U": 11315344844840, "u": 11315344849828, "recv_ms": 1787080304402, "bids": [[14199.8, 0.406], [14499.8, 0.056], [14599.8, 3.738], [58229.8, 0.002], [61464.8, 0.008], [62111.8, 1.898], [63547.4, 9.788], [63755.2, 1.081], [64052.8, 1.739], [64692.6, 0.055], [64694.8, 0.0], [64699.8, 7.289]], "asks": [[64702.4, 0.093], [64707.6, 0.311], [64707.8, 0.262], [64710.0, 0.143], [64710.4, 0.009], [64712.1, 0.002], [64721.7, 0.05], [64728.3, 0.017], [64729.0, 0.035], [64829.3, 2.322], [64895.7, 2.652], [65346.9, 3.625]]}
{"kind": "depth", "E": 1787080304549, "U": 11315344849892, "u": 11315344854367, "recv_ms": 1787080304500, "bids": [[1000.0, 35.81], [14199.8, 0.252], [14499.8, 0.252], [14599.8, 3.696], [58229.8, 0.002], [61464.8, 0.008], [62111.8, 1.895], [63082.3, 0.003], [63699.8, 0.031], [64052.8, 1.739], [64376.3, 5.207], [64559.6, 2.059], [64618.5, 0.005], [64625.1, 33.949], [64685.9, 0.155], [64692.3, 0.205], [64699.8, 7.287]], "asks": [[64702.4, 0.093], [64706.7, 0.035], [64707.6, 0.311], [64707.8, 0.262], [64710.4, 0.009], [64712.1, 0.002], [64839.9, 1.465], [65346.9, 3.627], [65699.9, 0.951], [71169.9, 0.0]]}
{"kind": "depth", "E": 1787080304753, "U": 11315344858135, "u": 11315344862402, "recv_ms": 1787080304704, "bids": [[14199.8, 0.014], [14499.8, 0.728], [14599.8, 3.458], [51759.8, 0.0], [58229.8, 0.002], [63699.8, 0.011], [64052.8, 1.739], [64580.4, 0.0], [64582.0, 4.165], [64628.5, 0.065], [64692.3, 0.017]], "asks": [[64770.9, 0.048], [64835.2, 6.183], [65346.9, 3.625], [65699.9, 0.931]]}
{"kind": "depth", "E": 1787080304855, "U": 11315344862629, "u": 11315344866235, "recv_ms": 1787080304805, "bids": [[1000.0, 35.81], [14199.8, 0.0], [14499.8, 1.078], [14599.8, 3.122], [58229.8, 0.002], [62111.8, 1.895], [63963.4, 0.55], [64052.8, 1.739], [64376.3, 5.207], [64641.5, 0.009], [64648.0, 1.304], [64672.7, 1.067], [64686.7, 0.107], [64686.8, 0.028], [64692.3, 0.205]], "asks": [[64751.7, 0.1], [64809.9, 0.004], [65346.9, 3.625], [65644.5, 1.352]]}
{"kind": "depth", "E": 1787080305161, "U": 11315344876327, "u": 11315344882255, "recv_ms": 1787080305130, "bids": [[1000.0, 35.81], [14499.8, 2.142], [14599.8, 2.058], [51760.0, 0.004], [58229.8, 0.002], [61464.8, 0.01], [61464.9, 0.008], [63699.8, 0.011], [63707.5, 0.02], [63708.9, 0.008], [64052.8, 1.739], [64376.3, 5.206], [64625.2, 6.315], [64675.3, 0.074], [64675.5, 0.002], [64676.3, 0.559], [64680.9, 1.288], [64690.1, 0.004], [64692.3, 0.117], [64692.4, 0.0], [64692.5, 0.309], [64692.6, 0.155], [64692.9, 0.0], [64693.2, 0.003], [64694.3, 0.825], [64694.4, 0.192], [64694.6, 0.127], [64696.2, 0.154], [64697.3, 0.007], [64699.8, 7.261]], "asks": [[64700.0, 1.381], [64702.4, 0.093], [64704.3, 0.099], [64705.7, 0.002], [64707.6, 0.311], [64707.8, 0.262], [64710.4, 0.009], [64711.2, 0.002], [64712.1, 0.002], [64712.9, 2.128], [64720.5, 0.036], [64770.1, 37.383], [64772.3, 1.251], [64772.4, 0.0], [64774.4, 1.137], [64774.5, 0.054], [65023.4, 4.77], [65346.9, 3.625], [65692.1, 0.018], [65699.9, 0.931], [65993.8, 0.05], [71169.9, 0.0]]}
{"kind": "depth", "E": 1787080305263, "U": 11315344882403, "u": 11315344888044, "recv_ms": 1787080305239, "bids": [[14499.8, 2.506], [14599.8, 1.694], [58229.8, 0.002], [61464.8, 0.01], [61464.9, 0.006], [62111.8, 1.898], [63779.7, 4.886], [63876.7, 1.367], [64052.8, 1.739], [64679.4, 0.0], [64683.8, 0.024], [64690.5, 0.381], [64692.3, 0.017], [64692.4, 0.001], [64692.6, 0.055], [64693.2, 0.002], [64694.4, 0.004], [64694.6, 0.126], [64699.8, 7.259]], "asks": [[64702.4, 0.248], [64702.5, 0.029], [64706.8, 0.542], [64707.6, 0.466], [64707.8, 0.417], [64710.0, 1.043], [64710.4, 0.319], [64712.1, 0.157], [64716.3, 0.165], [64770.1, 0.001], [64774.5, 37.436], [65023.4, 4.769], [65346.9, 3.625], [65690.9, 0.008]]}
{"kind": "depth", "E": 1787080305365, "U": 11315344888173, "u": 11315344892723, "recv_ms": 1787080305337, "bids": [[1000.0, 35.81], [14499.8, 2.87], [14599.8, 1.33], [58229.8, 0.002], [61464.8, 0.01], [62111.8, 1.895], [63405.9, 0.016], [63699.8, 0.031], [64052.8, 1.739], [64376.3, 5.207], [64685.3, 2.125], [64691.6, 0.002], [64692.3, 0.117], [64692.4, 0.0], [64692.6, 0.105], [64694.4, 0.192], [64699.8, 6.422]], "asks": [[64702.4, 0.093], [64702.5, 0.029], [64706.8, 0.542], [64707.6, 0.311], [64707.8, 0.262], [64710.0, 0.143], [64710.4, 0.009], [64712.1, 0.002], [64772.3, 38.633], [64772.4, 0.0], [64774.5, 0.054], [64829.3, 2.322], [64895.7, 2.108], [65346.9, 3.625], [65699.9, 0.951], [65855.6, 10.69], [65961.5, 2.571]]}
{"kind": "depth", "E": 1787080305467, "U": 11315344892823, "u": 11315344897730, "recv_ms": 1787080305441, "bids": [[1000.0, 35.81], [14499.8, 3.22], [14599.8, 0.98], [58229.8, 0.002], [62111.8, 1.898], [63838.6, 9.019], [64052.8, 1.739], [64173.5, 0.0], [64376.3, 5.207], [64622.1, 0.024], [64641.5, 0.006], [64654.5, 0.001], [64693.8, 0.099], [64695.2, 0.029], [64697.0, 0.085], [64697.3, 0.001]], "asks": [[64699.9, 10.394], [64702.2, 0.05], [64702.3, 0.548], [64702.4, 0.093], [64702.5, 0.006], [64704.8, 0.01], [64706.8, 0.024], [64707.6, 0.303], [64707.8, 0.262], [64710.4, 0.009], [64712.1, 0.002], [64745.2, 0.005], [64770.1, 37.383], [64772.3, 1.251], [64809.9, 0.001], [65208.8, 0.767], [65346.9, 3.625], [65471.7, 1.512], [65624.7, 0.609]]}
{"kind": "depth", "E": 1787080305773, "U": 11315344906042, "u": 11315344909362, "recv_ms": 1787080305769, "bids": [[1000.0, 35.81], [14399.8, 0.322], [14499.8, 3.654], [14599.8, 0.224], [51759.8, 0.0], [58229.8, 0.002], [61464.8, 0.01], [62111.8, 1.898], [63699.8, 0.031], [63812.0, 4.112], [63826.4, 7.469], [64052.8, 1.739], [64376.3, 5.197], [64692.7, 0.002], [64693.2, 0.002], [64693.4, 0.278]], "asks": [[64702.3, 0.007], [64702.5, 0.029], [64702.7, 0.002], [64706.8, 0.542], [64707.6, 0.303], [64707.8, 0.262], [64710.4, 0.009], [64712.1, 0.002], [64743.9, 0.046], [64746.5, 0.078], [65346.9, 3.625], [65699.9, 0.951]]}
{"kind": "depth", "E": 1787080305875, "U": 11315344909418, "u": 11315344913273, "recv_ms": 1787080305884, "bids": [[14399.8, 0.56], [14499.8, 3.528], [14599.8, 0.112], [58229.8, 0.002], [61464.8, 0.01], [62111.8, 1.895], [63963.4, 0.003], [64052.8, 1.739], [64686.1, 0.358], [64686.2, 0.0], [64692.3, 0.017], [64693.4, 0.09], [64694.2, 1.914]], "asks": [[64699.9, 10.002], [64702.7, 0.543], [64706.7, 0.035], [64706.8, 0.001], [64707.8, 0.262], [64710.4, 0.009], [64712.1, 0.002], [64746.5, 0.064], [65314.5, 7.774], [65346.9, 4.283], [65426.2, 0.855]]}
{"kind": "depth", "E": 1787080305977, "U": 11315344913286, "u": 11315344916332, "recv_ms": 1787080305994, "bids": [[1000.0, 35.81], [14399.8, 0.812], [14499.8, 3.388], [14599.8, 0.0], [58229.8, 0.002], [61464.8, 0.008], [61464.9, 0.008], [62111.8, 1.898], [63699.8, 0.011], [63882.5, 10.267], [64052.8, 1.739], [64695.3, 0.021]], "asks": [[64746.5, 0.078], [65101.7, 0.006], [65346.9, 4.281], [65699.9, 0.931], [65993.8, 0.053]]}
{"kind": "depth", "E": 1787080306079, "U": 11315344916373, "u": 11315344920323, "recv_ms": 1787080306099, "bids": [[1000.0, 35.81], [14399.8, 1.162], [14499.8, 3.038], [58229.8, 0.002], [61464.8, 0.008], [63225.8, 0.0], [63525.1, 0.786], [63707.5, 0.012], [63772.1, 0.0], [63774.3, 0.019], [63909.1, 5.39], [63942.8, 4.381], [64052.8, 1.739], [64376.3, 5.197], [64675.3, 0.692], [64682.7, 0.623], [64683.6, 0.027], [64688.2, 1.089], [64692.3, 0.067], [64692.6, 0.243]], "asks": [[64699.9, 9.986], [64702.6, 0.406], [64707.6, 0.458], [64707.8, 0.417], [64710.4, 0.319], [64712.1, 0.157], [64713.2, 0.834], [64720.5, 0.654], [64746.5, 0.064], [65023.4, 4.768], [65346.9, 4.281], [65405.1, 3.202], [65625.3, 1.522], [65627.4, 0.0], [65692.1, 0.01]]}
{"kind": "depth", "E": 1787080306181, "U": 11315344920419, "u": 11315344925388, "recv_ms": 1787080306193, "bids": [[14399.8, 1.512], [14499.8, 2.688], [58229.8, 0.002], [62111.8, 1.895], [63225.8, 0.052], [63405.9, 0.01], [63625.0, 2.58], [63699.8, 0.031], [63708.9, 0.016], [63773.6, 1.575], [63775.6, 0.008], [63781.1, 2.344], [64052.8, 1.739], [64376.3, 5.198], [64645.3, 3.599], [64645.4, 0.015], [64648.0, 1.29], [64653.6, 2.247], [64661.9, 3.048], [64662.0, 0.034], [64675.3, 0.074], [64675.4, 0.16], [64676.3, 0.559], [64677.1, 2.461], [64678.0, 0.249], [64682.7, 0.005], [64686.1, 0.204], [64687.1, 0.006], [64692.6, 0.055], [64692.7, 0.001], [64693.4, 0.006], [64694.1, 0.085], [64694.4, 0.004], [64695.0, 0.088], [64695.5, 0.178], [64695.6, 0.021], [64697.1, 0.008], [64697.5, 0.314], [64697.9, 0.088], [64698.4, 0.085], [64699.2, 0.002], [64699.8, 7.262]], "asks": [[64699.9, 9.169], [64701.0, 0.05], [64701.4, 0.024], [64701.5, 0.866], [64701.6, 0.084], [64702.0, 0.088], [64702.6, 0.251], [64703.7, 0.001], [64705.0, 0.102], [64705.4, 0.088], [64705.6, 0.006], [64707.6, 0.303], [64707.8, 0.262], [64710.4, 0.009], [64711.2, 0.001], [64712.1, 0.002], [64713.2, 0.216], [64719.9, 0.0], [64720.0, 3.705], [64720.5, 0.036], [64725.5, 0.004], [64725.8, 3.135], [64727.1, 0.205], [64746.5, 0.078], [64768.3, 6.438], [64795.4, 2.14], [64803.7, 2.132], [64803.8, 0.382], [64812.0, 2.126], [64812.1, 0.0], [64895.7, 2.139], [65346.9, 4.281], [65699.9, 0.951], [65799.8, 9.877], [65993.8, 0.056]]}
{"kind": "depth", "E": 1787080306487, "U": 11315344934018, "u": 11315344937675, "recv_ms": 1787080306438, "bids": [[14399.8, 2.59], [14499.8, 1.61], [51760.0, 0.004], [58229.8, 0.002], [61464.8, 0.008], [62111.8, 1.898], [64052.8, 1.741], [64692.6, 0.243], [64694.3, 0.825], [64698.4, 0.001]], "asks": [[64699.9, 9.365], [64702.6, 0.251], [64703.7, 0.0], [64707.6, 0.303], [64707.8, 0.262], [64710.4, 0.009], [64712.1, 0.002], [64715.9, 0.004], [64719.2, 0.558], [64720.0, 2.213], [64723.1, 0.026], [64728.4, 0.023], [64749.1, 0.043], [64829.3, 2.322], [65023.4, 4.769], [65346.9, 4.281]]}
{"kind": "depth", "E": 1787080306691, "U": 11315344942382, "u": 11315344945886, "recv_ms": 1787080306662, "bids": [[1000.0, 35.81], [14399.8, 3.304], [14499.8, 0.896], [58229.8, 0.002], [61464.8, 0.006], [62111.8, 1.895], [63405.9, 0.007], [63699.8, 0.011], [63755.2, 1.394], [64052.8, 1.739], [64503.8, 15.503], [64542.6, 0.0], [64542.7, 7.877], [64559.6, 6.487], [64692.3, 0.017], [64692.6, 0.055], [64693.4, 0.006]], "asks": [[64699.9, 10.197], [64701.7, 0.021], [64702.6, 0.251], [64703.4, 0.311], [64707.6, 0.303], [64707.8, 0.262], [64710.4, 0.009], [64712.1, 0.002], [64817.8, 1.888], [64839.9, 6.863], [64895.7, 2.435], [65346.9, 4.281], [65699.9, 0.931]]}
{"kind": "depth", "E": 1787080306793, "U": 11315344945995, "u": 11315344951128, "recv_ms": 1787080306780, "bids": [[14399.8, 3.654], [14499.8, 0.546], [51759.8, 0.0], [58229.8, 0.002], [61464.8, 0.006], [62111.8, 1.898], [63867.4, 0.0], [63913.8, 6.197], [64052.8, 1.739], [64622.1, 0.021], [64634.3, 0.001], [64634.6, 0.002], [64635.0, 0.044], [64635.3, 0.409], [64635.6, 0.233], [64653.4, 0.013], [64653.7, 0.023], [64654.0, 0.004], [64654.4, 1.167], [64654.5, 0.004], [64654.7, 0.125], [64668.3, 0.06], [64668.4, 0.071], [64668.5, 0.036], [64668.6, 0.025], [64668.7, 0.0], [64668.8, 0.047], [64668.9, 0.009], [64669.0, 0.001], [64669.1, 0.176], [64669.3, 0.154], [64671.6, 0.001], [64672.1, 0.1], [64688.4, 1.787], [64690.3, 0.0], [64690.4, 0.001], [64690.5, 0.311], [64690.6, 0.003], [64690.7, 0.002], [64690.8, 0.064], [64690.9, 0.0], [64691.0, 0.001], [64691.1, 0.016], [64691.2, 1.211], [64691.5, 0.001], [64691.9, 0.003], [64692.2, 0.25], [64692.3, 0.017], [64692.4, 0.001], [64692.5, 0.277], [64692.6, 0.243], [64692.8, 0.002], [64693.2, 0.002], [64694.2, 1.604]], "asks": [[64699.9, 10.194], [64700.3, 0.139], [64702.6, 0.251], [64705.0, 0.018], [64706.7, 0.003], [64706.9, 0.121], [64707.0, 0.462], [64707.3, 0.479], [64707.5, 0.463], [64707.6, 0.265], [64707.8, 0.262], [64707.9, 1.155], [64708.2, 0.357], [64708.3, 0.412], [64708.4, 0.001], [64708.5, 0.466], [64708.6, 2.703], [64708.7, 0.005], [64708.8, 0.121], [64708.9, 0.234], [64709.0, 0.001], [64709.1, 0.001], [64709.2, 0.003], [64709.3, 0.235], [64710.4, 0.009], [64712.1, 0.002], [64725.7, 0.009], [64726.1, 0.216], [64726.4, 0.887], [64726.7, 0.0], [64727.0, 3.757], [64727.4, 0.338], [64727.8, 0.001], [64730.2, 0.0], [64730.4, 0.22], [64730.5, 0.969], [64730.6, 0.404], [64730.7, 0.001], [64730.8, 0.058], [64730.9, 0.009], [64731.0, 0.067], [64731.1, 0.62], [64731.2, 2.953], [64744.8, 0.309], [64745.1, 1.004], [64745.2, 0.005], [64745.5, 0.008], [64745.8, 0.036], [64746.1, 0.041], [64809.9, 0.001], [65346.9, 4.281], [65371.2, 0.384], [65620.3, 1.521]]}
{"kind": "depth", "E": 1787080306895, "U": 11315344951163, "u": 11315344956038, "recv_ms": 1787080306863, "bids": [[1000.0, 35.81], [14299.8, 0.14], [14399.8, 3.738], [14499.8, 0.322], [58229.8, 0.002], [62111.8, 1.895], [63502.1, 0.787], [63964.5, 1.562], [64052.8, 1.739], [64182.2, 9.21], [64376.3, 5.207], [64645.4, 0.043], [64653.6, 2.279], [64654.3, 0.033], [64654.6, 0.048], [64675.4, 0.717], [64676.3, 0.002], [64677.0, 1.096], [64678.0, 0.133], [64690.7, 0.072], [64691.0, 0.101], [64691.2, 1.311], [64691.3, 0.171], [64691.4, 0.116], [64691.8, 0.032], [64692.4, 0.033], [64692.6, 0.243], [64692.7, 0.033]], "asks": [[64707.1, 0.474], [64707.4, 0.237], [64708.0, 0.944], [64708.4, 0.141], [64708.5, 0.55], [64708.6, 2.943], [64708.8, 0.231], [64709.2, 0.08], [64715.6, 0.975], [64716.7, 0.005], [64719.9, 0.0], [64720.6, 0.196], [64721.0, 0.017], [64726.1, 0.248], [64726.5, 0.053], [64727.1, 0.243], [64727.5, 0.142], [64730.5, 1.173], [64730.6, 0.524], [64730.8, 0.168], [64731.1, 0.697], [64745.2, 0.037], [64745.5, 0.046], [64746.2, 1.601], [65346.9, 4.281], [65834.8, 0.042], [66677.8, 0.642]]}
{"kind": "depth", "E": 1787080307201, "U": 11315344963826, "u": 11315344968620, "recv_ms": 1787080307152, "bids": [[1000.0, 35.81], [14299.8, 0.882], [14399.8, 3.318], [14499.8, 0.0], [51760.0, 0.004], [58229.8, 0.002], [62111.8, 1.895], [63489.9, 2.152], [63699.8, 0.011], [63708.9, 0.025], [63923.4, 35.838], [64052.8, 1.739], [64376.3, 5.196], [64634.6, 0.034], [64635.5, 0.033], [64639.1, 0.526], [64648.1, 0.485], [64668.6, 0.095], [64676.2, 0.64], [64677.0, 1.096], [64685.8, 0.287], [64685.9, 0.001], [64687.1, 0.005], [64689.6, 0.018], [64690.8, 0.204], [64692.5, 0.277], [64693.2, 0.003], [64694.0, 0.068], [64694.3, 0.825], [64694.4, 0.192], [64695.2, 0.025]], "asks": [[64701.2, 0.023], [64701.7, 0.002], [64706.2, 0.003], [64709.0, 0.155], [64731.0, 0.221], [65023.4, 4.77], [65217.5, 5.844], [65346.9, 4.283], [65612.2, 4.411], [65699.9, 0.931], [65898.7, 0.0]]}
{"kind": "depth", "E": 1787080307303, "U": 11315344968654, "u": 11315344972194, "recv_ms": 1787080307254, "bids": [[1000.0, 35.81], [14299.8, 1.246], [14399.8, 2.954], [58229.8, 0.002], [62111.8, 1.898], [63772.5, 0.942], [63781.1, 2.578], [63858.7, 4.631], [64052.8, 1.739], [64542.7, 7.899], [64559.6, 2.059], [64559.7, 4.75], [64634.9, 0.075], [64635.9, 0.13], [64668.7, 0.07], [64668.9, 0.109], [64669.0, 0.101], [64669.2, 0.224], [64669.3, 0.254], [64669.4, 0.072], [64672.3, 0.1], [64683.8, 0.024]], "asks": [[64699.9, 10.195], [64706.7, 0.001], [64709.0, 1.055], [64716.3, 0.165], [64839.9, 6.863], [64854.8, 0.687], [64856.8, 10.408], [64895.7, 2.108], [65346.9, 4.281], [65525.7, 0.0], [65690.9, 0.025]]}
{"kind": "depth", "E": 1787080307405, "U": 11315344972240, "u": 11315344979333, "recv_ms": 1787080307355, "bids": [[14299.8, 1.596], [14399.8, 2.604], [58229.8, 0.002], [61464.8, 0.006], [62111.8, 1.895], [63158.5, 0.678], [63699.8, 0.031], [63794.0, 31.672], [63826.4, 8.203], [63848.1, 1.564], [63964.5, 0.781], [64052.8, 1.74], [64618.5, 33.817], [64625.1, 0.0], [64639.1, 0.522], [64645.4, 0.015], [64647.8, 0.037], [64648.0, 1.318], [64668.6, 0.165], [64668.8, 0.117], [64669.1, 0.276], [64669.5, 0.073], [64671.9, 0.409], [64675.0, 0.83], [64677.0, 0.98], [64677.7, 0.12], [64678.6, 0.001], [64682.4, 0.619]], "asks": [[64702.6, 0.251], [64707.2, 0.009], [64707.8, 0.262], [64709.0, 0.155], [64710.4, 0.009], [64712.1, 0.002], [64712.9, 2.746], [64720.3, 0.723], [64725.8, 3.153], [64746.5, 0.078], [64829.3, 2.322], [64854.8, 2.184], [64895.7, 2.405], [65023.4, 4.769], [65217.5, 9.671], [65346.9, 4.281], [65508.6, 10.55], [65629.3, 13.441], [65699.9, 0.951]]}
{"kind": "depth", "E": 1787080307507, "U": 11315344979575, "u": 11315344984537, "recv_ms": 1787080307457, "bids": [[1000.0, 35.81], [14299.8, 1.96], [14399.8, 2.24], [58229.8, 0.002], [63826.4, 8.5], [64052.8, 1.74], [64348.4, 0.001], [64376.3, 5.197], [64618.5, 0.005], [64620.6, 2.368], [64620.7, 33.863], [64625.2, 0.001], [64668.9, 0.179], [64669.2, 0.294]], "asks": [[64701.1, 0.025], [64702.5, 0.006], [64702.7, 0.002], [64704.6, 1.087], [64706.9, 0.044], [64707.3, 0.566], [64707.4, 0.314], [64710.0, 1.043], [65346.9, 4.281], [65603.9, 0.0], [65638.0, 27.924]]}
{"kind": "depth", "E": 1787080307609, "U": 11315344984779, "u": 11315344988794, "recv_ms": 1787080307560, "bids": [[1000.0, 35.81], [14299.8, 2.31], [14399.8, 1.89], [58229.8, 0.002], [61464.8, 0.006], [62111.8, 1.898], [63405.9, 0.01], [63699.8, 0.011], [64052.8, 1.74], [64582.0, 0.301], [64582.1, 3.864], [64591.4, 0.0], [64593.3, 2.414], [64599.8, 6.671], [64599.9, 0.005], [64620.7, 0.122], [64622.9, 37.68], [64624.7, 0.009], [64628.5, 0.065], [64645.4, 0.043], [64668.8, 0.187], [64675.0, 0.212], [64681.5, 0.668], [64682.4, 0.001], [64683.6, 0.36], [64688.2, 0.626], [64691.7, 1.845], [64692.6, 0.155], [64693.2, 0.002], [64693.4, 0.09], [64694.4, 0.192], [64694.9, 0.01], [64695.5, 0.155], [64695.6, 0.024], [64696.1, 0.001], [64697.0, 0.001], [64699.8, 6.421]], "asks": [[64699.9, 10.281], [64701.4, 0.025], [64702.5, 0.006], [64702.6, 0.251], [64702.7, 0.566], [64704.6, 1.003], [64705.0, 0.017], [64706.2, 0.002], [64706.8, 0.033], [64706.9, 0.036], [64707.3, 0.002], [64707.4, 0.237], [64707.5, 0.0], [64707.6, 1.895], [64707.8, 0.262], [64710.4, 0.009], [64712.1, 0.002], [64712.9, 2.128], [64720.3, 0.105], [64746.5, 0.064], [64761.7, 6.002], [64762.2, 0.001], [64768.3, 0.893], [64770.1, 0.001], [64770.9, 0.002], [64771.0, 0.049], [64774.4, 6.677], [64774.5, 37.652], [64807.1, 0.494], [64807.2, 2.34], [64835.2, 6.183], [64890.9, 0.0], [64891.0, 0.018], [64895.7, 2.476], [65346.9, 4.281], [65699.9, 0.931]]}
{"kind": "depth", "E": 1787080307711, "U": 11315344988806, "u": 11315344992519, "recv_ms": 1787080307662, "bids": [[14299.8, 2.674], [14399.8, 1.526], [51760.0, 0.004], [58229.8, 0.002], [61464.8, 0.006], [62111.8, 1.895], [63547.4, 9.003], [63891.1, 14.406], [64052.8, 1.74], [64076.7, 0.343], [64641.5, 0.009], [64648.0, 1.321], [64663.5, 0.015], [64664.4, 0.337], [64666.9, 0.325], [64667.0, 0.007], [64667.1, 0.309], [64667.2, 3.838], [64670.3, 0.347], [64670.4, 1.242], [64670.5, 0.696], [64681.6, 0.016], [64699.8, 5.893]], "asks": [[64702.4, 0.093], [64702.7, 0.002], [64702.8, 2.418], [64707.4, 2.086], [64707.5, 2.109], [64707.6, 0.35], [64707.9, 0.016], [64710.0, 0.143], [64710.4, 0.009], [64712.1, 0.002], [64743.9, 0.004], [64770.1, 37.599], [64772.3, 1.251], [64772.4, 0.0], [64774.4, 1.137], [64774.5, 0.054], [64809.9, 0.004], [65346.9, 4.281]]}
{"kind": "depth", "E": 1787080307813, "U": 11315344992658, "u": 11315344996737, "recv_ms": 1787080307764, "bids": [[1000.0, 35.81], [14299.8, 3.038], [14399.8, 1.162], [51759.8, 0.0], [51760.0, 0.004], [58229.8, 0.002], [62111.8, 1.898], [63353.8, 0.008], [63699.8, 0.031], [63867.3, 0.002], [64052.8, 1.74], [64330.4, 0.002], [64376.3, 5.207], [64497.0, 0.18]], "asks": [[65346.9, 4.281], [65699.9, 0.951]]}
{"kind": "depth", "E": 1787080307915, "U": 11315344996767, "u": 11315345000406, "recv_ms": 1787080307868, "bids": [[1000.0, 35.81], [14299.8, 3.388], [14399.8, 0.812], [58229.8, 0.002], [62111.8, 1.895], [63535.2, 2.661], [63766.8, 4.227], [63923.4, 36.057], [64052.8, 1.809], [64580.0, 1.644], [64622.9, 3.939], [64624.7, 0.0], [64625.1, 33.741]], "asks": [[64710.0, 1.043], [64895.7, 2.406], [65346.9, 4.281]]}
{"kind": "depth", "E": 1787080308017, "U": 11315345000533, "u": 11315345005019, "recv_ms": 1787080307969, "bids": [[14199.8, 0.014], [14299.8, 3.71], [14399.8, 0.476], [58229.8, 0.002], [61464.8, 0.006], [63333.5, 0.166], [63699.8, 0.011], [64052.8, 1.809], [64542.7, 5.217], [64559.7, 3.921], [64618.5, 33.746], [64622.1, 0.024], [64624.7, 0.018], [64625.1, 0.0], [64641.5, 0.006], [64654.5, 0.001], [64658.2, 0.001], [64658.3, 0.061], [64680.2, 0.134], [64697.1, 0.092], [64699.8, 5.997]], "asks": [[64699.9, 10.183], [64702.7, 0.002], [64706.9, 0.113], [64707.3, 0.002], [64707.6, 0.273], [64710.4, 0.009], [64712.1, 0.002], [64712.2, 2.589], [64713.3, 0.0], [64743.9, 0.046], [64745.2, 0.037], [64770.1, 0.001], [64772.4, 0.009], [64774.5, 37.652], [64809.9, 0.001], [64839.9, 6.863], [64895.7, 3.924], [65346.9, 4.281], [65699.9, 0.931]]}
{"kind": "depth", "E": 1787080308119, "U": 11315345005162, "u": 11315345010670, "recv_ms": 1787080308071, "bids": [[1000.0, 35.81], [14199.8, 0.196], [14299.8, 3.71], [14399.8, 0.294], [51760.0, 0.004], [58229.8, 0.002], [61464.8, 0.006], [62111.8, 1.898], [64052.8, 1.809], [64376.3, 5.197], [64618.5, 0.005], [64624.7, 0.0], [64625.1, 33.675], [64660.9, 0.037], [64688.2, 0.078], [64688.4, 1.779], [64689.1, 0.0], [64691.3, 0.171], [64691.7, 1.844], [64692.1, 0.033], [64692.6, 0.055], [64692.8, 1.796], [64692.9, 0.002], [64694.4, 0.568], [64695.7, 0.022], [64696.4, 0.0], [64696.5, 0.002], [64699.2, 0.032], [64699.7, 0.055], [64699.8, 5.976]], "asks": [[64699.9, 10.169], [64700.3, 0.055], [64702.7, 0.157], [64706.6, 0.002], [64706.9, 0.036], [64707.3, 0.389], [64710.4, 0.319], [64712.1, 0.157], [64746.5, 0.064], [64772.3, 38.83], [64772.4, 0.0], [64773.4, 0.037], [64773.5, 0.0], [64774.5, 0.054], [65346.9, 4.281], [65993.8, 0.053], [67287.8, 0.291]]}
{"kind": "depth", "E": 1787080308221, "U": 11315345010726, "u": 11315345015011, "recv_ms": 1787080308171, "bids": [[1000.0, 35.81], [14199.8, 0.42], [14299.8, 3.612], [14399.8, 0.168], [51760.0, 0.004], [58229.8, 0.002], [62111.8, 1.895], [63405.9, 0.013], [63699.8, 0.031], [63882.5, 9.564], [63997.0, 0.0], [64052.8, 1.809], [64156.3, 0.878], [64376.3, 5.198], [64559.7, 4.583], [64618.5, 33.68], [64624.7, 0.018], [64625.1, 0.0], [64660.9, 0.023], [64663.5, 0.001], [64667.7, 0.002], [64672.5, 0.003], [64688.5, 0.541], [64692.9, 0.096], [64693.4, 0.184], [64694.1, 0.394], [64694.4, 0.027], [64694.5, 0.087], [64697.6, 0.092], [64699.8, 7.506]], "asks": [[64702.7, 0.002], [64706.6, 0.001], [64707.3, 0.079], [64710.4, 0.009], [64712.1, 0.002], [64725.8, 3.167], [64746.5, 0.078], [64839.9, 6.863], [64895.7, 4.138], [65023.4, 4.768], [65346.9, 4.281], [65699.9, 0.951]]}
{"kind": "depth", "E": 1787080308323, "U": 11315345015166, "u": 11315345019344, "recv_ms": 1787080308275, "bids": [[14199.8, 0.672], [14299.8, 3.472], [14399.8, 0.056], [51760.0, 0.004], [58229.8, 0.002], [61464.8, 0.006], [62111.8, 1.898], [64052.8, 1.808], [64618.5, 0.005], [64622.9, 3.939], [64624.7, 0.0], [64625.1, 33.675], [64666.9, 0.327], [64667.0, 0.009], [64667.1, 0.311], [64668.4, 0.407], [64670.4, 1.244], [64670.5, 0.698], [64670.6, 0.006], [64683.8, 0.024], [64688.5, 0.548], [64692.1, 0.032], [64692.9, 0.146], [64693.4, 0.091], [64694.4, 0.02], [64694.6, 0.126], [64694.7, 0.049], [64698.2, 0.001], [64699.7, 0.056], [64699.8, 8.345]], "asks": [[64700.7, 0.0], [64702.7, 0.157], [64703.4, 0.001], [64704.6, 1.087], [64707.3, 0.389], [64710.4, 0.319], [64712.1, 0.157], [64716.3, 0.165], [65346.9, 4.281], [65455.0, 2.55]]}
{"kind": "depth", "E": 1787080308425, "U": 11315345019432, "u": 11315345022691, "recv_ms": 1787080308376, "bids": [[1000.0, 35.81], [14199.8, 0.98], [14299.8, 3.22], [14399.8, 0.0], [58229.8, 0.002], [61464.9, 0.008], [62111.8, 1.895], [63699.8, 0.011], [64052.8, 1.808], [64376.3, 5.197], [64618.5, 0.005], [64625.1, 33.675], [64667.7, 0.957], [64688.4, 0.026], [64688.6, 0.009], [64692.6, 0.155], [64692.7, 0.034], [64693.4, 0.09], [64694.4, 0.012]], "asks": [[64702.7, 0.002], [64707.3, 0.079], [64710.4, 0.009], [64712.1, 0.002], [64746.5, 0.078], [64770.1, 0.001], [64772.3, 1.251], [64772.4, 0.009], [64774.5, 37.633], [64829.3, 2.322], [65346.9, 4.281], [65596.8, 0.066], [65699.9, 0.931]]}
{"kind": "depth", "E": 1787080308527, "U": 11315345022709, "u": 11315345026036, "recv_ms": 1787080308484, "bids": [[1000.0, 35.81], [14199.8, 1.33], [14299.8, 2.87], [58229.8, 0.002], [61464.8, 0.008], [61464.9, 0.006], [63699.8, 0.031], [64688.6, 0.009], [64692.6, 0.055], [64692.9, 0.077], [64693.4, 0.006], [64694.4, 0.2], [64697.5, 0.314], [64698.0, 0.247]], "asks": [[64772.3, 38.83], [64772.4, 0.0], [64774.5, 0.054], [65023.4, 4.769], [65346.9, 4.281], [65699.9, 0.951]]}
{"kind": "depth", "E": 1787080308731, "U": 11315345029086, "u": 11315345037730, "recv_ms": 1787080308696, "bids": [[1000.0, 35.81], [14199.8, 2.044], [14299.8, 2.156], [58229.8, 0.002], [62111.8, 1.895], [63826.4, 8.734], [63964.5, 0.0], [64052.8, 1.808], [64376.3, 5.207], [64695.6, 0.002]], "asks": [[65346.9, 4.281]]}
{"kind": "depth", "E": 1787080308833, "U": 11315345037835, "u": 11315345043096, "recv_ms": 1787080308783, "bids": [[1000.0, 35.81], [14199.8, 2.408], [14299.8, 1.792], [51759.8, 0.0], [58229.8, 0.002], [62111.8, 1.898], [63699.8, 0.011], [63914.8, 9.688], [64052.8, 1.808], [64505.7, 0.004], [64559.7, 4.739], [64618.5, 33.68], [64625.1, 0.0], [64645.4, 0.015], [64678.5, 5.004]], "asks": [[64839.9, 6.863], [64895.7, 2.497], [65346.9, 4.281], [65586.3, 1.829], [65699.9, 0.931]]}
{"kind": "depth", "E": 1787080308935, "U": 11315345043123, "u": 11315345051059, "recv_ms": 1787080308886, "bids": [[14199.8, 2.758], [14299.8, 1.442], [58229.8, 0.002], [61464.8, 0.008], [64052.8, 1.808], [64618.5, 0.005], [64622.9, 37.614], [64648.0, 1.293], [64664.4, 0.001], [64681.9, 0.643], [64683.6, 0.356], [64689.3, 0.071], [64692.7, 0.033], [64692.9, 0.19], [64693.8, 0.003], [64694.0, 0.069], [64694.4, 0.004], [64694.5, 0.086], [64695.7, 0.045], [64698.5, 0.084], [64699.8, 8.955]], "asks": [[64701.2, 0.0], [64702.7, 0.002], [64707.3, 0.079], [64709.0, 1.055], [64710.4, 0.009], [64712.1, 0.002], [64712.7, 0.164], [64713.1, 0.45], [64723.7, 0.0], [64731.0, 0.221], [64746.5, 0.064], [65346.9, 4.281], [65873.9, 0.65]]}
{"kind": "depth", "E": 1787080309037, "U": 11315345051279, "u": 11315345062791, "recv_ms": 1787080308988, "bids": [[1000.0, 35.81], [14199.8, 3.108], [14299.8, 1.092], [58229.8, 0.002], [61464.8, 0.008], [62111.8, 1.895], [62767.0, 0.039], [63699.8, 0.031], [63781.1, 2.812], [64052.8, 1.808], [64376.3, 5.197], [64672.4, 0.336], [64683.6, 0.36], [64688.2, 0.083], [64692.9, 0.002], [64699.8, 8.96]], "asks": [[64701.6, 0.0], [64702.7, 0.157], [64705.0, 0.101], [64707.3, 0.389], [64710.4, 0.319], [64712.1, 0.157], [64723.1, 0.026], [65217.5, 9.366], [65346.9, 4.281], [65534.5, 0.309], [65699.9, 0.951], [65805.9, 1.369]]}
{"kind": "depth", "E": 1787080309139, "U": 11315345062829, "u": 11315345073583, "recv_ms": 1787080309090, "bids": [[1000.0, 35.81], [14199.8, 3.472], [14299.8, 0.728], [34000.0, 1.146], [58229.8, 0.002], [62111.8, 1.898], [62758.8, 4.354], [63073.8, 0.941], [63138.0, 0.678], [63708.8, 0.0], [63945.1, 2.343], [64052.8, 1.808], [64107.8, 0.001], [64156.3, 0.816], [64623.0, 6.643], [64668.4, 0.071], [64688.2, 0.078], [64692.9, 0.002], [64693.4, 0.1], [64699.8, 8.963]], "asks": [[64699.9, 10.18], [64702.7, 0.002], [64706.9, 0.037], [64707.3, 0.079], [64709.0, 0.155], [64710.0, 0.143], [64710.4, 0.009], [64712.1, 0.002], [64720.0, 2.213], [64721.9, 0.003], [64726.9, 2.977], [64727.9, 10.131], [64728.4, 0.009], [64746.5, 0.078], [64770.1, 0.001], [64772.3, 1.251], [64772.4, 0.009], [64774.4, 6.674], [64774.5, 37.633], [65346.9, 4.281], [65690.8, 1.055], [65993.8, 0.056]]}
{"kind": "depth", "E": 1787080309241, "U": 11315345073697, "u": 11315345086319, "recv_ms": 1787080309195, "bids": [[14199.8, 3.738], [14299.8, 0.42], [14599.8, 0.042], [51760.0, 0.004], [58229.8, 0.002], [61464.8, 0.008], [62111.8, 1.895], [63591.2, 1.259], [63699.8, 0.011], [63708.9, 0.035], [64052.8, 1.81], [64376.3, 5.196], [64622.1, 0.021], [64654.5, 0.004], [64681.8, 0.02], [64683.6, 0.353], [64693.4, 0.006], [64694.3, 0.919], [64695.7, 0.025], [64699.8, 8.966]], "asks": [[64702.7, 0.157], [64706.9, 0.036], [64707.3, 0.389], [64710.4, 0.319], [64712.1, 0.157], [64745.2, 0.037], [64772.3, 38.879], [64772.4, 0.0], [64774.4, 1.137], [64774.5, 0.054], [64856.8, 0.0], [64856.9, 7.25], [64895.7, 7.556], [65346.9, 4.281], [65690.9, 0.035], [65699.9, 0.931], [66640.7, 0.04]]}
{"kind": "depth", "E": 1787080309343, "U": 11315345086472, "u": 11315345098065, "recv_ms": 1787080309296, "bids": [[1000.0, 35.81], [14199.8, 3.682], [14299.8, 0.266], [14599.8, 0.252], [58229.8, 0.002], [61464.8, 0.008], [61464.9, 0.008], [62111.8, 1.898], [63876.7, 1.016], [63937.0, 0.063], [64052.8, 1.808], [64085.2, 10.086], [64182.2, 6.255], [64376.3, 5.206], [64581.9, 3.865], [64582.1, 0.0], [64593.3, 2.414], [64628.5, 0.065], [64648.0, 1.307], [64677.8, 0.002], [64683.6, 0.36], [64683.8, 0.022], [64694.3, 1.013], [64695.3, 0.002], [64695.7, 0.002], [64695.8, 0.109], [64696.0, 0.021], [64697.6, 0.093], [64699.8, 8.965]], "asks": [[64699.9, 10.181], [64701.1, 0.005], [64701.4, 0.005], [64701.5, 0.844], [64701.6, 0.084], [64701.9, 0.026], [64702.1, 0.023], [64702.3, 0.01], [64702.7, 0.157], [64707.3, 0.389], [64710.4, 0.319], [64712.1, 0.157], [64716.3, 0.163], [64725.8, 3.153], [64770.1, 37.629], [64771.0, 0.049], [64772.3, 1.251], [64807.2, 2.34], [64835.2, 6.183], [64856.9, 10.408], [64891.0, 0.015], [64891.1, 0.003], [64895.7, 4.875], [64967.9, 0.942], [64968.0, 5.797], [65023.4, 4.77], [65217.5, 9.671], [65346.9, 4.281], [65793.3, 1.213], [67287.8, 0.278]]}
{"kind": "depth", "E": 1787080309445, "U": 11315345098182, "u": 11315345103270, "recv_ms": 1787080309399, "bids": [[14199.8, 3.57], [14299.8, 0.14], [14599.8, 0.49], [51760.0, 0.004], [58229.8, 0.002], [61464.8, 0.008], [63082.3, 0.082], [63567.6, 3.771], [63699.8, 0.031], [64052.8, 1.81], [64635.1, 0.345], [64681.9, 0.025], [64683.8, 0.024], [64689.3, 0.063], [64689.4, 0.09], [64694.3, 0.825], [64694.4, 0.098]], "asks": [[64699.9, 10.18], [64702.7, 0.002], [64707.3, 0.079], [64710.4, 0.009], [64712.1, 0.002], [64716.3, 0.165], [64720.3, 0.085], [64725.3, 0.367], [64730.8, 0.168], [64730.9, 0.263], [64731.1, 0.634], [64764.6, 0.004], [64770.1, 0.001], [64772.3, 38.879], [64772.4, 0.0], [64774.5, 0.054], [64829.3, 2.322], [65023.4, 4.769], [65346.9, 4.281], [65699.9, 0.951]]}
{"kind": "depth", "E": 1787080309547, "U": 11315345103296, "u": 11315345107936, "recv_ms": 1787080309500, "bids": [[14199.8, 3.444], [14299.8, 0.028], [14599.8, 0.728], [58229.8, 0.002], [61464.8, 0.008], [62111.8, 1.895], [63017.6, 0.001], [63846.9, 3.128], [64052.8, 1.808], [64182.2, 10.144], [64376.3, 5.207], [64559.7, 0.008], [64688.2, 0.263], [64691.1, 0.185], [64694.4, 0.192], [64698.3, 0.001], [64698.5, 0.0], [64699.8, 8.964]], "asks": [[64699.9, 10.209], [64702.7, 0.002], [64707.3, 0.079], [64710.4, 0.009], [64712.1, 0.002], [64718.1, 0.025], [64725.3, 0.347], [64733.9, 0.116], [64780.5, 0.036], [64827.1, 0.001], [64839.9, 1.465], [64873.8, 0.009], [65023.4, 4.615], [65346.9, 4.281]]}
{"kind": "depth", "E": 1787080309649, "U": 11315345108026, "u": 11315345111373, "recv_ms": 1787080309601, "bids": [[1000.0, 35.81], [14199.8, 3.15], [14299.8, 0.0], [14599.8, 1.05], [58229.8, 0.004], [61464.9, 0.006], [62111.8, 1.898], [63405.9, 0.01], [63699.8, 0.011], [63781.1, 3.046], [64052.8, 1.808], [64376.3, 5.207], [64622.9, 3.939], [64623.0, 1.798], [64624.7, 0.0], [64625.1, 33.612], [64645.4, 0.043], [64675.4, 0.717], [64676.2, 0.083], [64677.1, 2.577], [64677.7, 0.004], [64680.7, 1.094], [64681.4, 1.754], [64688.5, 0.541], [64688.6, 0.001], [64689.4, 0.082], [64692.7, 0.034], [64693.8, 0.087], [64694.0, 0.068], [64694.4, 0.019], [64694.5, 0.094], [64694.6, 0.124], [64695.4, 0.095], [64697.5, 0.004], [64697.6, 0.009], [64698.0, 0.163]], "asks": [[64700.4, 0.085], [64700.7, 0.084], [64703.2, 0.704], [64705.0, 0.017], [64713.1, 1.375], [64714.7, 0.156], [64715.6, 0.975], [64717.3, 0.003], [64718.1, 0.005], [64719.9, 0.115], [64721.5, 0.001], [64725.3, 0.367], [65318.8, 0.067], [65346.9, 4.281], [65499.8, 10.408], [65699.9, 0.931]]}
{"kind": "depth", "E": 1787080309751, "U": 11315345111512, "u": 11315345116029, "recv_ms": 1787080309703, "bids": [[14199.8, 2.786], [14599.8, 1.414], [58229.8, 0.002], [62111.8, 1.895], [63547.4, 8.375], [63740.9, 0.0], [63977.5, 2.341], [64052.8, 1.808], [64559.7, 4.923], [64613.6, 1.539], [64688.4, 0.567], [64688.5, 0.0], [64694.3, 0.825], [64694.4, 0.019], [64694.5, 0.094]], "asks": [[64702.7, 2.111], [64704.8, 0.295], [64707.3, 0.141], [64707.4, 2.024], [64707.5, 0.465], [64713.1, 0.45], [64714.0, 1.027], [64715.6, 0.419], [64716.7, 0.561], [64718.1, 0.025], [64719.9, 0.0], [64720.8, 0.118], [64725.3, 0.347], [64839.9, 6.863], [64895.7, 1.946], [65023.4, 4.769], [65346.9, 4.281], [65993.8, 0.059]]}
{"kind": "depth", "E": 1787080309853, "U": 11315345116087, "u": 11315345120735, "recv_ms": 1787080309806, "bids": [[14199.8, 2.422], [14599.8, 1.778], [51759.8, 0.0], [51760.0, 0.004], [58229.8, 0.002], [62111.8, 1.898], [63699.8, 0.031], [63891.1, 14.64], [64052.8, 1.808], [64602.7, 0.003], [64617.9, 0.008], [64641.5, 0.009], [64645.4, 0.015], [64682.4, 1.697], [64688.4, 0.026], [64692.9, 0.096], [64694.4, 0.56], [64694.5, 0.188], [64694.6, 0.124]], "asks": [[64709.0, 1.055], [64746.5, 0.064], [64809.9, 0.004], [64967.9, 0.532], [64968.0, 2.825], [65346.9, 4.281], [65662.5, 1.682], [65694.9, 0.762], [65699.9, 0.951], [65901.8, 0.758]]}
{"kind": "depth", "E": 1787080309955, "U": 11315345120773, "u": 11315345124400, "recv_ms": 1787080309907, "bids": [[1000.0, 35.81], [14199.8, 2.072], [14599.8, 2.128], [58229.8, 0.002], [63625.0, 1.953], [63755.2, 1.739], [64052.8, 1.808], [64158.9, 0.0], [64374.0, 0.165], [64376.3, 5.197], [64688.4, 0.567], [64692.9, 0.077], [64694.4, 0.019], [64694.5, 0.094], [64694.6, 0.124], [64694.7, 0.049], [64694.8, 0.0], [64695.8, 0.087]], "asks": [[64705.0, 0.917], [64709.0, 0.155], [64722.0, 0.498], [64785.6, 1.355], [64790.6, 0.0], [65346.9, 4.281], [65476.3, 30.728], [66070.0, 0.229]]}
{"kind": "depth", "E": 1787080310159, "U": 11315345128372, "u": 11315345132333, "recv_ms": 1787080310112, "bids": [[14199.8, 1.358], [14599.8, 2.842], [51760.0, 0.004], [58229.8, 0.002], [61464.8, 0.008], [62111.8, 1.898], [63017.6, 0.0], [63612.8, 4.456], [63729.4, 0.0], [63770.7, 0.002], [64052.8, 1.808], [64602.7, 0.006], [64618.5, 0.005], [64620.6, 2.368], [64622.1, 0.024], [64625.1, 33.655], [64657.6, 1.45], [64658.3, 0.0], [64666.9, 0.325], [64667.0, 0.007], [64667.1, 0.309], [64670.4, 1.242], [64670.5, 0.696], [64670.6, 0.004], [64675.0, 0.83], [64681.5, 0.05], [64682.4, 2.315], [64685.7, 0.787], [64689.6, 0.017], [64692.1, 0.033], [64692.9, 0.052], [64694.4, 0.207], [64697.6, 0.008], [64698.2, 0.0], [64699.8, 8.963]], "asks": [[64702.6, 0.251], [64706.9, 0.098], [64707.0, 0.462], [64707.3, 0.079], [64708.7, 0.083], [64710.4, 0.009], [64712.1, 0.002], [64712.9, 2.746], [64720.3, 0.703], [64761.3, 0.076], [64761.8, 0.023], [64772.2, 6.637], [65023.4, 4.769], [65346.9, 4.281], [65499.8, 10.066], [65596.9, 7.44], [65638.0, 28.609]]}
{"kind": "depth", "E": 1787080310261, "U": 11315345132438, "u": 11315345136767, "recv_ms": 1787080310212, "bids": [[1000.0, 35.81], [14199.8, 0.994], [14599.8, 3.206], [51760.0, 0.01], [58229.8, 0.002], [62111.8, 1.895], [63618.6, 4.871], [63699.8, 0.031], [63964.8, 1.042], [64042.8, 0.063], [64052.8, 1.808], [64145.0, 0.234], [64376.3, 5.197], [64618.5, 0.005], [64622.9, 37.594], [64625.1, 0.0], [64675.4, 0.16], [64676.9, 0.917], [64677.1, 2.461], [64678.5, 5.12], [64679.1, 0.256], [64680.7, 0.168], [64681.3, 2.245], [64682.2, 0.472], [64688.4, 0.026], [64693.4, 0.09], [64694.4, 0.019], [64694.5, 0.094], [64694.6, 0.665], [64695.4, 0.118], [64696.0, 0.002], [64697.1, 0.008]], "asks": [[64700.0, 1.465], [64704.6, 1.003], [64714.0, 0.102], [64714.6, 1.174], [64743.9, 0.004], [64759.4, 0.03], [64895.7, 2.505], [65346.9, 4.283], [65476.3, 31.947], [65699.9, 0.951], [66450.7, 0.015]]}
{"kind": "depth", "E": 1787080310363, "U": 11315345136768, "u": 11315345140887, "recv_ms": 1787080310315, "bids": [[14199.8, 0.644], [14599.8, 3.556], [51760.0, 0.004], [58229.8, 0.002], [61464.8, 0.008], [63606.4, 2.666], [63752.1, 6.677], [63757.0, 9.334], [64052.8, 1.808], [64622.9, 3.939], [64624.7, 0.0], [64625.1, 33.655], [64645.4, 0.029], [64663.5, 0.015], [64667.4, 0.343], [64672.4, 0.0], [64675.0, 0.212], [64675.9, 0.637], [64676.9, 0.36], [64677.5, 0.125], [64678.5, 5.004], [64681.5, 0.668], [64682.4, 1.697], [64683.8, 0.022], [64685.7, 0.169], [64692.1, 0.034], [64692.7, 0.033], [64692.9, 0.002], [64694.1, 0.084], [64694.4, 0.207], [64694.7, 0.05], [64695.5, 0.175], [64699.3, 0.0], [64699.8, 8.123]], "asks": [[64699.9, 10.211], [64702.6, 0.251], [64707.3, 0.079], [64708.7, 0.082], [64710.4, 0.009], [64712.1, 0.002], [64712.9, 2.128], [64716.3, 0.163], [64720.0, 3.848], [64720.3, 0.085], [64722.8, 10.003], [64739.0, 0.932], [64739.5, 0.301], [64761.7, 0.002], [64767.2, 0.5], [64769.8, 0.0], [64829.3, 2.322], [65023.4, 4.768], [65346.9, 4.281], [65469.8, 8.235], [65509.3, 1.862], [65670.4, 6.544]]}
{"kind": "depth", "E": 1787080310465, "U": 11315345140950, "u": 11315345146951, "recv_ms": 1787080310419, "bids": [[1000.0, 35.96], [14199.8, 0.364], [14499.8, 0.084], [14599.8, 3.752], [58229.8, 0.002], [61464.8, 0.006], [61464.9, 0.008], [62111.8, 1.898], [63699.8, 0.011], [63944.7, 0.785], [63951.0, 0.086], [63964.7, 0.002], [64017.9, 1.171], [64052.8, 1.808], [64376.3, 5.197], [64628.9, 2.673], [64651.5, 0.001], [64660.9, 0.037], [64667.7, 0.002], [64683.8, 0.024], [64688.4, 0.582], [64692.3, 0.117], [64692.6, 0.105], [64692.9, 0.102], [64694.4, 0.004], [64694.6, 0.124], [64694.7, 0.05], [64694.8, 0.0], [64694.9, 0.198], [64696.7, 0.086]], "asks": [[64716.3, 0.165], [64720.0, 3.808], [64761.6, 0.007], [65346.9, 4.281], [65575.9, 0.0], [65699.9, 0.931], [65900.0, 13.016], [66414.4, 0.902]]}
{"kind": "depth", "E": 1787080310567, "U": 11315345146969, "u": 11315345154045, "recv_ms": 1787080310521, "bids": [[1000.0, 35.81], [14199.8, 0.238], [14499.8, 0.308], [14599.8, 3.654], [58229.8, 0.002], [61464.8, 0.006], [62111.8, 1.895], [63761.7, 25.218], [63923.4, 36.276], [63950.9, 0.087], [64052.8, 1.808], [64376.3, 2.871], [64377.0, 0.459], [64596.6, 0.016], [64622.1, 0.024], [64629.4, 6.212], [64641.5, 0.006], [64652.0, 6.127], [64654.5, 0.001], [64660.9, 0.037], [64668.2, 3.178], [64678.5, 0.004], [64688.4, 0.026], [64691.6, 0.002], [64692.1, 0.033], [64692.3, 0.042], [64692.5, 0.274], [64692.6, 0.055], [64692.9, 0.102], [64694.4, 0.56], [64694.5, 0.282], [64694.7, 0.049], [64694.9, 0.01], [64695.1, 0.003], [64696.6, 0.003], [64699.7, 0.055], [64699.8, 6.935]], "asks": [[64701.3, 0.842], [64701.6, 0.087], [64701.8, 0.005], [64702.3, 0.007], [64702.6, 0.251], [64707.3, 0.079], [64710.4, 0.009], [64712.1, 0.002], [64722.6, 1.041], [64722.8, 11.008], [64726.9, 2.028], [64727.9, 0.131], [64739.0, 4.432], [64745.2, 0.037], [64761.7, 6.002], [64769.8, 0.018], [64770.1, 0.001], [64772.2, 1.099], [64772.3, 1.251], [64774.5, 37.687], [64793.9, 2.386], [64794.1, 0.379], [64809.9, 0.001], [65023.4, 4.769], [65346.9, 4.281], [65476.3, 31.262], [65620.3, 0.0], [66094.6, 0.004]]}
{"kind": "depth", "E": 1787080310669, "U": 11315345154262, "u": 11315345163986, "recv_ms": 1787080310621, "bids": [[14199.8, 0.112], [14499.8, 0.532], [14599.8, 3.556], [58229.8, 0.002], [61464.8, 0.006], [62111.8, 1.898], [63405.9, 0.013], [63699.8, 0.031], [63729.3, 3.191], [64052.8, 1.808], [64182.2, 9.834], [64376.3, 2.716], [64481.3, 0.031], [64509.4, 0.001], [64590.0, 0.382], [64663.2, 0.122], [64664.3, 0.149], [64665.3, 0.022], [64675.0, 0.769], [64675.9, 0.08], [64676.6, 0.117], [64676.9, 0.362], [64677.5, 0.009], [64678.5, 0.002], [64680.3, 0.931], [64681.0, 0.077], [64681.3, 1.319], [64685.8, 0.442], [64688.2, 0.186], [64688.4, 0.223], [64689.2, 0.317], [64689.3, 0.023], [64689.4, 0.002], [64691.1, 0.186], [64691.6, 0.001], [64692.1, 0.032], [64692.3, 0.101], [64692.7, 0.117], [64692.9, 0.002], [64693.0, 0.086], [64694.4, 0.552], [64694.5, 0.094], [64694.6, 0.125], [64694.8, 0.019], [64695.2, 0.002], [64695.4, 0.011], [64695.5, 0.155], [64695.6, 1.558], [64695.7, 0.009], [64695.8, 0.003], [64696.2, 0.07], [64696.7, 0.002], [64697.1, 0.002], [64699.2, 0.002], [64699.8, 5.045]], "asks": [[64699.9, 11.984], [64701.5, 0.864], [64701.6, 0.109], [64702.5, 0.107], [64702.6, 0.406], [64706.9, 0.082], [64707.3, 0.312], [64707.6, 0.265], [64710.4, 0.319], [64712.1, 0.157], [64712.7, 1.089], [64714.6, 0.249], [64715.2, 0.559], [64716.7, 0.005], [64717.3, 10.003], [64717.6, 0.56], [64718.2, 0.014], [64719.2, 0.017], [64722.8, 1.01], [64723.1, 0.024], [64744.0, 1.345], [64772.3, 38.884], [64772.4, 0.0], [64774.5, 0.054], [64777.1, 0.002], [64856.9, 5.82], [64895.7, 8.174], [65346.9, 4.281], [65469.8, 9.15], [65476.3, 30.5], [65699.9, 0.951], [65993.8, 0.056]]}
{"kind": "depth", "E": 1787080310771, "U": 11315345164008, "u": 11315345182200, "recv_ms": 1787080310725, "bids": [[1000.0, 35.81], [14199.8, 0.0], [14499.8, 0.784], [14599.8, 3.416], [58229.8, 0.002], [62111.8, 1.895], [63405.9, 0.01], [63882.5, 9.299], [64052.8, 1.808], [64376.3, 5.042], [64596.6, 10.016], [64618.5, 33.66], [64624.1, 0.019], [64625.1, 0.0], [64626.3, 0.367], [64636.9, 0.782], [64637.1, 0.037], [64639.3, 0.108], [64639.4, 0.002], [64641.6, 1.064], [64648.0, 1.326], [64649.3, 0.015], [64650.3, 0.001], [64650.6, 0.002], [64653.0, 0.059], [64656.3, 0.002], [64660.2, 0.787], [64663.2, 0.179], [64664.3, 0.092], [64667.0, 0.004], [64667.4, 0.007], [64668.0, 0.075], [64668.9, 0.173], [64671.1, 0.315], [64672.7, 1.07], [64673.5, 0.004], [64673.9, 0.854], [64675.0, 0.212], [64675.3, 0.004], [64675.5, 0.118], [64676.2, 0.085], [64676.6, 0.001], [64676.7, 0.024], [64676.9, 0.36], [64677.2, 0.618], [64677.5, 0.002], [64679.2, 0.926], [64679.4, 0.04], [64679.7, 0.007], [64679.8, 0.037], [64680.3, 0.005], [64681.4, 1.757], [64681.5, 0.01], [64682.2, 0.465], [64682.3, 0.035], [64682.6, 0.003], [64683.3, 0.116], [64683.7, 0.005], [64683.8, 1.024], [64684.2, 0.005], [64684.8, 0.009], [64685.5, 2.633], [64685.6, 0.13], [64685.7, 0.162], [64686.0, 0.125], [64686.1, 0.745], [64686.5, 0.002], [64686.7, 0.107], [64687.7, 0.358], [64687.9, 1.749], [64688.3, 0.005], [64688.4, 0.659], [64688.5, 0.008], [64688.6, 1.843], [64688.9, 0.562], [64689.2, 0.317], [64689.3, 0.297], [64690.4, 0.002], [64691.1, 0.185], [64691.2, 1.768], [64691.6, 0.084], [64691.7, 0.002], [64691.9, 0.087], [64692.5, 0.003], [64693.3, 0.053], [64693.7, 0.005], [64694.2, 1.601], [64694.3, 0.004], [64694.4, 0.004], [64694.5, 0.128], [64694.6, 0.132], [64694.8, 0.0], [64694.9, 0.009], [64695.0, 0.004], [64695.1, 0.002], [64695.4, 0.008], [64695.6, 1.556], [64696.3, 0.001], [64696.8, 0.004], [64697.9, 0.013], [64698.4, 0.033], [64698.7, 0.001], [64699.7, 0.045], [64699.8, 5.289]], "asks": [[64699.9, 25.336], [64700.0, 1.469], [64701.5, 0.844], [64701.6, 0.087], [64701.8, 0.002], [64701.9, 0.028], [64702.0, 0.085], [64702.3, 0.017], [64702.5, 0.006], [64702.6, 0.131], [64702.7, 0.01], [64702.8, 2.418], [64702.9, 0.311], [64703.3, 0.0], [64703.5, 1.011], [64703.7, 0.037], [64704.3, 0.088], [64704.4, 1.59], [64704.6, 0.003], [64704.9, 0.067], [64705.5, 0.0], [64705.6, 0.315], [64705.7, 0.064], [64705.9, 0.069], [64706.0, 0.004], [64706.1, 0.064], [64706.6, 0.009], [64706.7, 0.001], [64706.9, 0.02], [64707.2, 0.033], [64707.3, 0.627], [64707.4, 2.021], [64708.2, 0.065], [64710.1, 0.001], [64710.4, 0.009], [64710.5, 3.474], [64710.8, 0.357], [64712.1, 0.009], [64713.2, 10.216], [64713.3, 0.0], [64713.4, 0.018], [64714.2, 0.633], [64714.8, 0.328], [64715.1, 0.099], [64715.3, 0.314], [64715.4, 0.551], [64715.8, 0.009], [64716.6, 0.025], [64717.3, 0.003], [64717.4, 0.014], [64717.6, 0.542], [64718.0, 0.003], [64718.3, 0.249], [64718.9, 0.073], [64719.1, 0.052], [64719.3, 1.047], [64720.0, 2.173], [64720.8, 0.003], [64721.7, 0.319], [64723.2, 0.01], [64723.8, 0.098], [64724.5, 0.001], [64727.4, 0.332], [64730.5, 1.168], [64745.3, 0.04], [64747.6, 0.224], [64747.7, 0.008], [64769.8, 0.0], [64785.6, 1.255], [64793.9, 3.574], [64794.1, 10.379], [64854.8, 1.5], [64856.9, 10.408], [64895.7, 3.215], [65346.9, 4.281], [65599.2, 6.394], [65694.0, 5.143], [65993.8, 0.053]]}
{"kind": "depth", "E": 1787080310873, "U": 11315345182343, "u": 11315345190245, "recv_ms": 1787080310823, "bids": [[1000.0, 35.81], [14499.8, 1.134], [14599.8, 3.066], [51759.8, 0.0], [58229.8, 0.002], [61464.8, 0.006], [63699.8, 0.011], [63785.4, 14.881], [64052.8, 1.808], [64182.2, 10.144], [64376.3, 5.207], [64377.0, 0.872], [64618.5, 0.005], [64622.9, 37.594], [64683.7, 0.004], [64686.1, 0.204], [64688.0, 3.818], [64692.5, 0.015], [64694.0, 0.056], [64694.9, 0.093], [64699.7, 0.027], [64699.8, 5.308]], "asks": [[64699.9, 25.399], [64701.2, 0.003], [64701.4, 0.025], [64701.5, 0.866], [64701.9, 0.009], [64702.1, 0.0], [64704.4, 1.589], [64704.9, 0.006], [64707.2, 0.025], [64710.5, 2.146], [64712.1, 0.017], [64712.4, 0.321], [64713.1, 0.13], [64713.2, 0.216], [64770.1, 0.001], [64772.3, 38.884], [65346.9, 4.281], [65476.3, 31.947], [65699.9, 0.931], [65702.7, 14.895]]}
{"kind": "depth", "E": 1787080310975, "U": 11315345190401, "u": 11315345199600, "recv_ms": 1787080310925, "bids": [[14499.8, 1.498], [14599.8, 2.702], [58229.8, 0.002], [62111.8, 1.898], [63761.7, 25.923], [63891.1, 14.991], [64052.8, 1.808], [64464.3, 0.004], [64485.0, 0.178], [64618.5, 0.005], [64620.7, 33.777], [64622.9, 3.939], [64691.6, 0.0], [64693.2, 0.312], [64695.4, 0.092], [64699.8, 5.951]], "asks": [[64702.3, 0.007], [64702.5, 0.005], [64715.1, 0.042], [64716.1, 0.497], [64717.0, 10.463], [64718.3, 0.134], [64719.4, 0.12], [64929.4, 0.004], [64949.5, 0.003], [65346.9, 4.281], [65444.3, 7.335]]}
{"kind": "depth", "E": 1787080311077, "U": 11315345199809, "u": 11315345207946, "recv_ms": 1787080311034, "bids": [[1000.0, 35.81], [14499.8, 1.848], [14599.8, 2.352], [58229.8, 0.002], [62111.8, 1.895], [63699.8, 0.031], [63708.6, 0.0], [63882.5, 8.948], [64052.8, 1.808], [64688.2, 0.186], [64691.9, 0.003], [64695.8, 0.087]], "asks": [[64706.7, 0.003], [64719.3, 0.976], [64852.5, 0.004], [64873.2, 0.004], [64895.7, 2.536], [65346.9, 4.283], [65558.7, 2.812], [65699.9, 0.951]]}
{"kind": "depth", "E": 1787080311281, "U": 11315345213963, "u": 11315345219247, "recv_ms": 1787080311232, "bids": [[14499.8, 2.562], [14599.8, 1.638], [58229.8, 0.002], [62111.8, 1.895], [63405.9, 0.013], [63664.6, 4.831], [63699.8, 0.011], [64052.8, 1.808], [64540.6, 0.008], [64560.0, 0.44], [64618.5, 0.005], [64620.7, 33.841], [64622.9, 3.939], [64679.8, 0.002], [64687.0, 0.036], [64688.4, 0.582], [64689.0, 0.078]], "asks": [[64700.1, 0.002], [64702.6, 1.676], [64702.7, 0.01], [64703.4, 0.0], [64704.4, 0.044], [64705.2, 0.156], [64705.7, 0.064], [64710.9, 0.003], [64715.9, 0.023], [65346.9, 4.281], [65444.6, 7.326], [65476.3, 27.372], [65573.3, 6.592], [65638.0, 27.544], [65699.9, 0.931]]}
{"kind": "depth", "E": 1787080311383, "U": 11315345219383, "u": 11315345236506, "recv_ms": 1787080311338, "bids": [[1000.0, 35.81], [14499.8, 2.926], [14599.8, 1.274], [58229.8, 0.002], [61464.8, 0.006], [63794.0, 34.02], [64052.8, 1.808], [64624.7, 0.009], [64660.2, 0.451], [64663.2, 0.122], [64664.8, 0.374], [64665.5, 0.058], [64673.9, 0.297], [64675.5, 0.002], [64675.7, 0.752], [64676.1, 1.963], [64676.2, 0.083], [64676.7, 0.017], [64677.2, 0.0], [64677.3, 0.12], [64677.7, 0.006], [64678.5, 0.009], [64679.2, 0.0], [64680.9, 2.214], [64681.9, 0.643], [64682.3, 0.028], [64683.0, 0.002], [64683.1, 0.62], [64683.7, 0.011], [64683.8, 1.022], [64684.1, 1.198], [64685.4, 0.451], [64685.5, 2.324], [64687.0, 0.345], [64688.0, 3.82], [64688.7, 0.077], [64689.0, 0.001], [64689.2, 0.315], [64689.3, 0.297], [64690.4, 0.001], [64692.1, 0.033], [64692.3, 0.002], [64692.5, 0.018], [64692.7, 0.033], [64692.9, 0.002], [64693.0, 0.002], [64693.3, 0.053], [64694.3, 0.003], [64694.6, 0.131], [64695.7, 0.01], [64696.4, 0.084], [64696.8, 0.088], [64697.2, 0.088], [64697.4, 0.311], [64699.7, 0.028], [64699.8, 8.139]], "asks": [[64699.9, 23.921], [64700.0, 1.385], [64700.1, 0.021], [64700.2, 0.024], [64700.3, 0.055], [64700.4, 0.001], [64700.5, 0.02], [64700.6, 0.011], [64700.7, 0.107], [64701.4, 0.005], [64701.5, 0.844], [64701.6, 0.084], [64702.4, 0.094], [64702.5, 0.005], [64702.6, 0.131], [64702.7, 0.064], [64704.6, 0.064], [64705.0, 0.017], [64705.6, 0.006], [64705.7, 0.002], [64706.4, 0.317], [64706.6, 0.102], [64706.7, 1.548], [64707.2, 0.025], [64707.3, 0.55], [64708.6, 2.942], [64712.0, 0.003], [64712.1, 0.002], [64712.7, 0.164], [64713.1, 0.137], [64713.3, 0.0], [64713.9, 0.967], [64715.2, 0.003], [64715.8, 0.007], [64715.9, 0.023], [64716.1, 0.44], [64716.3, 0.163], [64716.4, 6.116], [64716.5, 0.564], [64717.0, 10.465], [64717.4, 0.071], [64717.6, 0.001], [64718.3, 0.134], [64719.2, 0.558], [64719.4, 5.005], [64720.2, 0.001], [64720.7, 0.124], [64721.1, 0.502], [64721.7, 0.01], [64722.8, 1.319], [64724.5, 0.619], [64731.8, 0.641], [64739.8, 0.031], [64747.3, 0.0], [64777.1, 0.003], [64829.3, 2.322], [65327.5, 1.692], [65346.9, 4.281], [65508.6, 10.808], [65638.0, 28.609], [65874.6, 0.758], [65993.8, 0.053], [71169.9, 0.0]]}
{"kind": "depth", "E": 1787080311689, "U": 11315345256221, "u": 11315345265325, "recv_ms": 1787080311641, "bids": [[1000.0, 35.81], [14399.8, 0.112], [14499.8, 3.766], [14599.8, 0.322], [58229.8, 0.002], [61464.8, 0.006], [61464.9, 0.01], [62111.8, 1.898], [63699.8, 0.011], [64015.1, 0.39], [64052.8, 1.808], [64158.7, 0.0], [64376.3, 5.197], [64685.6, 0.284], [64685.8, 0.288], [64692.3, 0.052], [64694.9, 0.093], [64695.4, 0.084]], "asks": [[64699.9, 23.51], [64701.4, 0.012], [64701.9, 0.009], [64702.7, 0.064], [64713.1, 0.13], [64714.1, 0.067], [64719.4, 0.005], [64730.7, 0.342], [64730.9, 0.109], [64732.6, 0.118], [64739.8, 0.006], [65346.9, 4.281], [65699.9, 0.931], [66654.9, 0.005]]}
{"kind": "depth", "E": 1787080311791, "U": 11315345265539, "u": 11315345274642, "recv_ms": 1787080311745, "bids": [[1000.0, 35.81], [14399.8, 0.364], [14499.8, 3.626], [14599.8, 0.21], [58229.8, 0.002], [63761.7, 24.827], [63770.5, 0.0], [63785.4, 14.693], [64052.8, 1.808], [64145.0, 0.312], [64620.7, 0.122], [64622.1, 0.021], [64622.9, 37.658], [64654.5, 0.001], [64693.3, 0.241]], "asks": [[64716.5, 0.562], [64717.2, 1.865], [64722.8, 1.01], [64723.9, 1.558], [64730.7, 0.188], [64730.8, 0.322], [64745.2, 0.034], [64809.9, 0.001], [64895.7, 2.54], [65346.9, 4.281], [65508.6, 11.15], [65621.4, 23.014]]}
{"kind": "depth", "E": 1787080311893, "U": 11315345274844, "u": 11315345281270, "recv_ms": 1787080311845, "bids": [[14399.8, 0.602], [14499.8, 3.514], [14599.8, 0.084], [51759.8, 0.0], [58229.8, 0.002], [62111.8, 1.895], [63699.8, 0.031], [63994.6, 3.739], [64052.8, 1.808], [64618.5, 33.724], [64620.8, 1.271], [64622.9, 3.939], [64693.3, 0.241]], "asks": [[64730.8, 0.322], [65699.9, 0.951]]}
{"kind": "depth", "E": 1787080311995, "U": 11315345281331, "u": 11315345287160, "recv_ms": 1787080311947, "bids": [[1000.0, 35.81], [14399.8, 0.868], [14499.8, 3.332], [14599.8, 0.0], [58229.8, 0.002], [61464.8, 0.006], [62111.8, 1.898], [64052.8, 1.808], [64182.2, 10.144], [64376.3, 5.207], [64618.5, 0.005], [64620.7, 0.122], [64622.9, 37.651], [64633.7, 0.654], [64633.8, 2.432], [64678.5, 0.009], [64680.3, 0.005], [64683.6, 0.357], [64689.0, 0.464], [64692.3, 0.002], [64693.3, 0.241], [64695.0, 0.046]], "asks": [[64699.9, 23.142], [64700.0, 1.382], [64700.1, 0.002], [64701.9, 0.012], [64702.4, 0.093], [64703.5, 1.006], [64704.4, 0.058], [64706.7, 0.003], [64706.9, 0.483], [64708.2, 0.025], [64709.1, 0.132], [64724.5, 0.001], [64730.7, 0.188], [64730.8, 0.322], [64765.3, 2.543], [64765.4, 0.337], [65346.9, 4.281], [65499.8, 9.724], [65605.7, 25.944], [66646.9, 2.173]]}
{"kind": "depth", "E": 1787080312199, "U": 11315345292242, "u": 11315345302428, "recv_ms": 1787080312156, "bids": [[14399.8, 1.582], [14499.8, 2.618], [58229.8, 0.002], [61464.9, 0.008], [62111.8, 1.898], [63397.4, 0.008], [63469.3, 0.0], [63541.1, 0.0], [63613.0, 0.001], [63684.9, 0.0], [63756.8, 0.049], [63828.7, 0.047], [63900.5, 0.024], [63972.4, 0.126], [64044.3, 6.192], [64052.8, 1.808], [64618.5, 33.717], [64622.9, 3.939], [64624.7, 0.009], [64625.1, 0.0], [64625.2, 0.001], [64657.4, 0.005], [64688.2, 0.187]], "asks": [[64704.8, 0.296], [64709.9, 0.896], [64716.9, 3.102], [64717.2, 0.003], [64772.2, 6.638], [64854.8, 2.08], [65338.1, 0.188], [65346.9, 4.281], [65410.0, 0.521], [65481.9, 0.019], [65552.0, 0.764], [65553.7, 0.001], [65597.0, 24.327], [65625.6, 0.001], [65697.5, 0.0], [65769.4, 0.075], [65841.3, 0.0], [65913.1, 0.0], [65985.0, 6.143]]}
{"kind": "depth", "E": 1787080312403, "U": 11315345306966, "u": 11315345311800, "recv_ms": 1787080312401, "bids": [[1000.0, 35.81], [14399.8, 2.296], [14499.8, 1.904], [51760.0, 0.004], [58229.8, 0.002], [61464.8, 0.006], [62111.8, 1.895], [64052.8, 1.808], [64606.8, 0.022], [64660.9, 0.023], [64675.0, 0.83], [64682.3, 0.646], [64683.8, 1.022], [64692.3, 0.373], [64692.9, 0.002], [64693.3, 0.053]], "asks": [[64699.9, 23.145], [64712.8, 1.957], [64716.3, 0.163], [64716.9, 0.001], [64720.2, 0.619], [64724.0, 10.125], [64730.8, 0.168], [64730.9, 0.263], [64731.8, 0.023], [64751.7, 0.171], [64770.1, 37.835], [64772.2, 1.099], [64772.3, 1.251], [64784.2, 0.0], [64829.3, 2.322], [64895.7, 7.244], [65346.9, 4.282], [65605.7, 28.227], [65735.1, 8.478]]}
{"kind": "depth", "E": 1787080312505, "U": 11315345311940, "u": 11315345316409, "recv_ms": 1787080312457, "bids": [[14399.8, 2.66], [14499.8, 1.54], [58229.8, 0.002], [61464.8, 0.006], [62111.8, 1.898], [63699.8, 0.011], [63891.1, 15.256], [63914.8, 9.469], [64052.8, 1.808], [64629.9, 0.0], [64683.8, 1.024], [64692.3, 0.273], [64692.9, 0.19], [64699.8, 8.119]], "asks": [[64699.9, 23.144], [64716.3, 0.165], [64770.1, 0.001], [64772.3, 39.085], [64774.5, 0.054], [64895.7, 2.764], [65023.4, 4.768], [65346.9, 4.284], [65699.9, 0.931]]}
{"kind": "depth", "E": 1787080312607, "U": 11315345316434, "u": 11315345321888, "recv_ms": 1787080312564, "bids": [[1000.0, 35.81], [14399.8, 3.01], [14499.8, 1.19], [58229.8, 0.002], [61464.8, 0.006], [62111.8, 1.895], [63781.1, 3.516], [63785.4, 14.505], [64052.8, 1.808], [64376.3, 5.198], [64559.7, 0.008], [64622.9, 3.939], [64624.7, 0.0], [64625.1, 33.712], [64695.1, 0.022]], "asks": [[64699.9, 23.17], [64719.5, 6.323], [64730.9, 0.109], [64839.9, 1.465], [65346.9, 4.282], [65467.5, 11.261], [65596.9, 7.257], [65735.1, 9.541]]}
{"kind": "depth", "E": 1787080312709, "U": 11315345321990, "u": 11315345325867, "recv_ms": 1787080312660, "bids": [[1000.0, 35.81], [14399.8, 3.36], [14499.8, 0.84], [58229.8, 0.002], [61464.8, 0.004], [61464.9, 0.01], [63699.8, 0.031], [64052.8, 1.808], [64376.3, 5.197], [64542.7, 0.001]], "asks": [[64699.9, 23.179], [64730.9, 0.109], [64731.0, 0.375], [64854.8, 0.58], [64856.9, 0.0], [65023.4, 4.769], [65217.5, 9.366], [65346.9, 4.282], [65618.6, 2.502], [65699.9, 0.951], [65830.0, 1.4], [66135.0, 0.038]]}
{"kind": "depth", "E": 1787080312811, "U": 11315345325935, "u": 11315345331619, "recv_ms": 1787080312767, "bids": [[14299.8, 0.014], [14399.8, 3.696], [14499.8, 0.49], [58229.8, 0.002], [61464.8, 0.006], [62111.8, 1.898], [63405.9, 0.019], [63891.1, 15.607], [64052.8, 1.808], [64403.3, 0.026], [64503.8, 0.0], [64503.9, 15.505], [64542.7, 6.882], [64559.7, 4.233], [64581.0, 0.121], [64581.8, 3.893], [64593.1, 3.401], [64593.3, 0.096], [64628.5, 0.065], [64692.9, 0.002], [64693.3, 0.053], [64695.0, 0.004], [64695.1, 0.044]], "asks": [[64699.9, 23.179], [64702.7, 0.065], [64707.0, 0.462], [64708.0, 0.944], [64731.0, 0.221], [64731.1, 0.788], [64764.6, 0.022], [64767.2, 0.518], [64771.0, 0.049], [64807.2, 2.34], [64835.2, 6.183], [64839.9, 6.863], [64856.9, 10.408], [64895.7, 3.959], [65023.4, 4.615], [65338.1, 0.035], [65346.9, 4.282], [71169.9, 0.0]]}
{"kind": "depth", "E": 1787080312913, "U": 11315345331814, "u": 11315345336126, "recv_ms": 1787080312864, "bids": [[1000.0, 35.81], [14299.8, 0.168], [14399.8, 3.724], [14499.8, 0.308], [51759.8, 0.0], [58229.8, 0.002], [60941.2, 0.004], [62111.8, 1.895], [63687.5, 0.858], [63699.8, 0.011], [64052.8, 1.808], [64376.3, 5.207], [64675.3, 0.004], [64675.7, 0.195], [64676.3, 0.559], [64677.3, 0.004], [64678.6, 0.117], [64693.3, 0.241], [64693.8, 0.003], [64695.1, 0.024], [64698.2, 0.084]], "asks": [[64701.2, 0.01], [64701.9, 0.003], [64702.4, 0.102], [64713.9, 0.042], [64714.7, 1.081], [64716.5, 0.006], [64717.3, 0.559], [64719.2, 0.017], [64719.9, 0.541], [64720.7, 0.009], [64721.5, 0.116], [65346.9, 4.282], [65699.9, 0.931]]}
{"kind": "depth", "E": 1787080313117, "U": 11315345340981, "u": 11315345346374, "recv_ms": 1787080313072, "bids": [[14299.8, 0.658], [14399.8, 3.486], [14499.8, 0.056], [51760.0, 0.006], [58229.8, 0.002], [61464.8, 0.006], [62111.8, 1.895], [63699.8, 0.031], [63708.9, 0.027], [63773.6, 1.567], [63775.6, 0.0], [64052.8, 1.808], [64634.6, 0.002], [64634.9, 0.043], [64635.2, 1.102], [64635.5, 0.001], [64635.9, 0.098], [64653.6, 2.247], [64654.0, 0.004], [64654.3, 0.001], [64654.4, 1.199], [64654.5, 0.004], [64654.6, 0.016], [64654.9, 2.319], [64668.6, 0.025], [64668.7, 0.0], [64668.8, 0.007], [64668.9, 0.003], [64669.0, 0.001], [64669.1, 0.176], [64669.2, 0.124], [64669.3, 0.154], [64669.4, 0.002], [64669.5, 0.003], [64671.9, 0.309], [64672.3, 0.0], [64688.0, 3.82], [64688.2, 0.187], [64690.5, 0.241], [64690.6, 0.003], [64690.7, 0.002], [64690.8, 0.064], [64690.9, 0.0], [64691.0, 0.001], [64691.1, 0.015], [64691.2, 1.668], [64691.3, 0.071], [64691.4, 0.019], [64691.5, 0.001], [64691.8, 0.0], [64692.1, 0.001], [64692.4, 0.0], [64692.6, 0.087], [64692.7, 0.001], [64693.1, 0.001], [64693.3, 0.053], [64694.3, 0.829], [64699.8, 8.12]], "asks": [[64699.9, 23.158], [64701.3, 0.864], [64706.2, 0.003], [64706.8, 0.001], [64707.1, 0.443], [64707.4, 2.021], [64707.7, 0.629], [64708.0, 0.906], [64708.3, 0.412], [64708.4, 0.001], [64708.5, 0.466], [64708.6, 2.702], [64708.7, 0.082], [64708.8, 0.121], [64708.9, 0.234], [64709.0, 0.901], [64709.1, 0.041], [64709.2, 0.003], [64709.3, 0.165], [64725.8, 3.121], [64726.1, 0.216], [64726.4, 0.925], [64726.5, 0.015], [64726.8, 0.001], [64727.1, 0.205], [64727.5, 0.002], [64727.9, 0.001], [64730.3, 0.024], [64730.5, 0.964], [64730.6, 0.481], [64730.7, 0.001], [64730.8, 0.058], [64730.9, 0.009], [64731.0, 0.067], [64731.1, 0.62], [64731.2, 2.883], [64732.3, 0.001], [64744.9, 0.024], [64745.2, 0.002], [64745.5, 0.046], [64745.9, 0.0], [64746.2, 1.563], [64767.2, 0.518], [65346.9, 4.435], [65624.2, 0.0], [65626.2, 0.0], [65670.4, 7.531], [65690.9, 0.027], [65699.9, 0.951]]}
{"kind": "depth", "E": 1787080313219, "U": 11315345346430, "u": 11315345353548, "recv_ms": 1787080313170, "bids": [[1000.0, 35.81], [14299.8, 0.952], [14399.8, 3.248], [14499.8, 0.0], [51760.0, 0.004], [58229.8, 0.002], [58229.9, 0.0], [63405.9, 0.013], [63708.9, 0.035], [63773.6, 1.575], [63775.6, 0.008], [63902.0, 0.783], [64052.8, 1.808], [64376.3, 5.207], [64625.2, 6.283], [64653.8, 0.043], [64654.8, 1.944], [64676.5, 0.001], [64690.7, 0.072], [64690.9, 0.07], [64691.5, 0.101], [64691.9, 0.035], [64692.3, 0.273], [64692.4, 0.0], [64692.9, 0.034]], "asks": [[64707.1, 0.475], [64708.0, 0.944], [64708.4, 0.141], [64709.0, 0.985], [64709.3, 0.235], [64717.4, 2.345], [64726.1, 0.248], [64727.1, 0.243], [64727.5, 0.142], [64731.0, 0.151], [64731.2, 2.953], [64745.2, 0.034], [64746.2, 1.601], [64767.2, 0.5], [64772.2, 6.668], [64854.8, 2.198], [65346.9, 4.435]]}
{"kind": "depth", "E": 1787080313321, "U": 11315345353766, "u": 11315345358824, "recv_ms": 1787080313275, "bids": [[1000.0, 35.81], [14299.8, 1.302], [14399.8, 2.898], [58229.8, 0.002], [61464.8, 0.006], [62111.8, 1.898], [63699.8, 0.011], [64052.8, 1.808], [64625.1, 0.0], [64625.2, 0.001], [64654.1, 0.097], [64655.1, 0.391], [64660.9, 0.037], [64666.9, 0.327], [64667.0, 0.006], [64667.1, 0.311], [64670.3, 0.349], [64670.4, 1.244], [64670.5, 0.698], [64675.9, 0.637], [64676.3, 0.002], [64690.8, 0.134], [64691.1, 0.115], [64691.2, 1.768], [64691.3, 0.171], [64691.4, 0.119], [64691.5, 0.171], [64691.7, 0.072], [64692.3, 0.305], [64692.9, 0.034], [64693.2, 0.344], [64695.1, 0.022]], "asks": [[64699.9, 23.165], [64701.5, 0.005], [64706.7, 0.035], [64707.7, 0.667], [64708.3, 0.51], [64708.5, 0.67], [64708.6, 2.822], [64708.8, 0.231], [64708.9, 0.334], [64709.1, 0.118], [64716.2, 0.557], [64717.3, 0.003], [64718.3, 0.134], [64719.2, 0.558], [64719.9, 0.0], [64720.4, 0.117], [64721.5, 0.001], [64725.8, 3.153], [64726.8, 0.039], [64730.2, 0.098], [64730.4, 0.304], [64730.5, 1.084], [64730.6, 0.601], [64730.8, 0.168], [64730.9, 0.109], [64731.0, 0.305], [64731.1, 0.543], [64744.9, 0.056], [64745.8, 0.074], [65314.5, 8.45], [65346.9, 4.435], [65601.1, 2.266], [65624.2, 0.008], [65626.2, 0.008], [65690.9, 0.035], [65699.9, 0.931], [65720.3, 0.003]]}
{"kind": "depth", "E": 1787080313423, "U": 11315345358894, "u": 11315345364243, "recv_ms": 1787080313399, "bids": [[14299.8, 1.666], [14399.8, 2.534], [58229.8, 0.002], [62111.8, 1.895], [63397.4, 0.066], [63469.3, 0.058], [63541.1, 0.058], [63613.0, 0.059], [63684.9, 0.058], [63756.8, 0.107], [63828.7, 0.105], [63882.5, 8.48], [63900.5, 0.082], [63972.4, 0.184], [64044.3, 6.25], [64052.8, 1.808], [64620.7, 33.909], [64635.4, 2.355], [64664.5, 0.058], [64665.5, 0.001], [64675.3, 0.561], [64675.9, 0.08], [64676.9, 0.311], [64677.8, 0.002], [64677.9, 0.347], [64690.8, 0.204], [64690.9, 0.14], [64691.0, 0.071], [64691.1, 0.215], [64691.2, 1.868], [64692.4, 0.0], [64692.9, 0.222], [64695.0, 0.026]], "asks": [[64708.7, 0.192], [64708.8, 0.361], [64709.0, 1.055], [64709.1, 0.209], [64709.2, 0.08], [64713.0, 0.002], [64713.9, 0.967], [64714.7, 0.156], [64727.9, 0.131], [64730.7, 0.111], [64730.9, 0.179], [64731.0, 0.396], [64731.2, 3.03], [64829.3, 2.322], [65338.1, 0.093], [65346.9, 4.434], [65410.0, 0.579], [65481.9, 0.077], [65553.7, 0.059], [65625.6, 0.059], [65697.5, 0.058]]}
{"kind": "depth", "E": 1787080313525, "U": 11315345364340, "u": 11315345368783, "recv_ms": 1787080313478, "bids": [[1000.0, 35.81], [14299.8, 2.016], [14399.8, 2.184], [51760.0, 0.004], [58229.8, 0.002], [62111.8, 1.898], [63699.8, 0.031], [63794.0, 34.208], [64052.8, 1.808], [64376.3, 5.196], [64559.7, 0.008], [64624.7, 0.009], [64634.7, 0.083], [64635.7, 0.291], [64636.0, 0.066], [64669.3, 0.224], [64671.6, 0.041], [64676.1, 1.963], [64683.8, 1.024], [64692.4, 0.0], [64692.9, 0.034], [64697.4, 0.001]], "asks": [[64709.0, 0.155], [64716.3, 0.165], [64839.9, 1.465], [65346.9, 4.434], [65605.7, 30.511], [65694.0, 4.088], [65699.9, 0.951], [65769.4, 0.133], [65841.3, 0.058], [65913.1, 0.058], [65985.0, 6.201]]}
{"kind": "depth", "E": 1787080313627, "U": 11315345368817, "u": 11315345377998, "recv_ms": 1787080313589, "bids": [[1000.0, 35.81], [14299.8, 2.38], [14399.8, 1.82], [58229.8, 0.002], [61464.8, 0.006], [62111.8, 1.895], [63526.7, 2.201], [63699.8, 0.011], [64052.8, 1.808], [64182.2, 10.145], [64559.7, 4.749], [64620.7, 0.122], [64622.9, 37.726], [64623.4, 0.002], [64635.0, 0.076], [64668.7, 0.07], [64669.0, 0.071], [64672.5, 0.103], [64685.3, 0.137], [64692.4, 0.0], [64692.9, 0.034], [64695.6, 1.561], [64698.2, 0.0], [64699.8, 8.123]], "asks": [[64699.9, 23.158], [64701.1, 0.089], [64701.3, 0.866], [64701.4, 0.011], [64706.2, 0.002], [64716.2, 0.577], [64716.4, 6.118], [64717.0, 0.463], [64719.5, 6.325], [64720.0, 2.191], [64775.5, 0.009], [64839.9, 6.863], [64895.7, 2.468], [65023.4, 4.77], [65346.9, 4.434], [65605.7, 31.272], [65670.4, 7.561], [65699.9, 0.931], [65702.7, 15.959]]}
{"kind": "depth", "E": 1787080313729, "U": 11315345378306, "u": 11315345386812, "recv_ms": 1787080313681, "bids": [[14299.8, 2.73], [14399.8, 1.47], [51760.0, 0.004], [58229.8, 0.002], [64052.8, 1.808], [64376.3, 5.197], [64578.4, 0.004], [64581.0, 0.129], [64622.9, 3.939], [64624.7, 0.0], [64625.1, 33.787], [64627.3, 0.012], [64627.6, 0.037], [64668.9, 0.073], [64669.1, 0.276], [64669.2, 0.224], [64669.4, 0.202], [64669.5, 0.073], [64669.7, 0.126], [64692.3, 0.305]], "asks": [[64709.0, 1.055], [64724.0, 10.127], [64725.4, 0.022], [64774.4, 1.129], [64774.5, 0.062], [65023.4, 4.769], [65346.9, 4.434], [65508.6, 11.492], [65596.9, 7.074]]}
{"kind": "depth", "E": 1787080313933, "U": 11315345396899, "u": 11315345411966, "recv_ms": 1787080313884, "bids": [[1000.0, 35.81], [14299.8, 3.444], [14399.8, 0.756], [51759.8, 0.0], [58229.8, 0.002], [62111.8, 1.895], [63320.3, 0.001], [63405.9, 0.016], [63699.8, 0.031], [63881.5, 0.009], [64052.8, 1.808], [64654.6, 0.002], [64656.9, 3.536], [64666.6, 0.071], [64668.0, 0.005], [64670.5, 0.712], [64675.4, 0.23], [64692.3, 0.493], [64699.7, 0.031]], "asks": [[64733.5, 0.03], [64741.4, 0.528], [65265.7, 0.0], [65346.9, 4.434], [65699.9, 0.951]]}
{"kind": "depth", "E": 1787080314035, "U": 11315345414880, "u": 11315345434621, "recv_ms": 1787080313986, "bids": [[14199.8, 0.042], [14299.8, 3.724], [14399.8, 0.434], [58229.8, 0.002], [61464.8, 0.006], [62111.8, 1.898], [63825.6, 3.75], [63869.7, 0.014], [63891.1, 16.622], [64052.8, 1.808], [64409.0, 3.736], [64659.1, 0.33], [64664.8, 0.038], [64668.9, 0.479], [64675.0, 0.212], [64682.3, 0.028], [64685.6, 0.284], [64688.0, 3.279], [64688.2, 0.186], [64688.4, 0.574], [64688.7, 0.0], [64689.2, 0.933], [64689.3, 0.649], [64692.3, 0.305], [64692.9, 0.222], [64694.4, 0.314], [64699.8, 8.216]], "asks": [[64699.9, 23.065], [64700.5, 0.0], [64700.7, 0.0], [64701.2, 0.027], [64701.3, 0.888], [64702.8, 2.419], [64703.2, 0.394], [64708.0, 1.844], [64709.1, 0.169], [64711.0, 0.312], [64712.4, 0.001], [64712.5, 1.243], [64712.8, 1.339], [64713.7, 0.042], [64715.0, 1.294], [64719.7, 0.002], [64720.2, 0.001], [64727.1, 0.243], [64730.8, 0.166], [65346.9, 4.434], [65499.8, 9.466]]}
{"kind": "depth", "E": 1787080314443, "U": 11315345458477, "u": 11315345466488, "recv_ms": 1787080314396, "bids": [[1000.0, 35.81], [14199.8, 1.036], [14299.8, 3.164], [14399.8, 0.0], [58229.8, 0.002], [61464.9, 0.008], [62111.8, 1.895], [63882.5, 8.013], [64100.5, 4.178], [64156.3, 0.935], [64376.3, 5.207], [64686.3, 0.014], [64688.8, 0.137], [64693.3, 0.053]], "asks": [[64700.7, 0.087], [64701.3, 0.885], [64702.4, 0.105], [64811.1, 1.276], [64811.4, 0.369], [64829.3, 2.322], [64895.7, 2.543], [65346.9, 4.434], [65444.6, 5.494], [65499.8, 9.237], [65993.8, 0.053]]}
{"kind": "depth", "E": 1787080314545, "U": 11315345466615, "u": 11315345475314, "recv_ms": 1787080314501, "bids": [[1000.0, 35.81], [14199.8, 1.386], [14299.8, 2.814], [58229.8, 0.002], [61464.8, 0.006], [62111.8, 1.898], [63699.8, 0.011], [64052.8, 1.81], [64635.1, 0.346], [64641.5, 0.009], [64664.4, 0.337], [64668.9, 0.143], [64675.7, 0.752], [64676.2, 0.083], [64677.4, 0.459], [64677.5, 0.009], [64677.9, 0.231], [64678.5, 0.002], [64683.8, 1.024], [64684.5, 0.01], [64685.0, 0.015], [64687.9, 2.058], [64688.5, 0.008], [64688.7, 0.541], [64689.2, 0.316], [64689.3, 0.108], [64691.2, 1.869], [64691.3, 0.442], [64692.1, 0.0], [64692.3, 0.034], [64692.9, 0.034], [64693.3, 0.053], [64695.5, 0.156], [64699.7, 0.03], [64699.8, 6.56]], "asks": [[64699.9, 23.271], [64701.4, 0.007], [64716.3, 0.165], [64719.4, 0.005], [64719.9, 10.0], [64730.9, 0.179], [64731.0, 0.396], [64732.6, 0.093], [64739.2, 1.693], [64764.6, 0.005], [64777.1, 0.002], [65346.9, 4.434], [65444.6, 5.495], [65699.9, 0.931], [65993.8, 0.05]]}
{"kind": "depth", "E": 1787080314749, "U": 11315345482485, "u": 11315345488310, "recv_ms": 1787080314701, "bids": [[1000.0, 35.81], [14199.8, 2.1], [14299.8, 2.1], [58229.8, 0.002], [61464.8, 0.002], [61464.9, 0.012], [62111.8, 1.895], [63699.8, 0.031], [64052.8, 1.808], [64376.3, 5.197], [64693.0, 0.086], [64693.3, 0.241], [64696.4, 0.0], [64699.8, 6.57]], "asks": [[64699.9, 23.281], [64787.2, 2.818], [64787.7, 10.84], [65011.5, 0.002], [65346.9, 4.434], [65699.9, 0.951], [65993.8, 0.047]]}
{"kind": "depth", "E": 1787080314953, "U": 11315345495088, "u": 11315345504041, "recv_ms": 1787080314903, "bids": [[14199.8, 2.828], [14299.8, 1.372], [51759.8, 0.0], [58229.8, 0.002], [61464.8, 0.002], [62111.8, 1.895], [63699.8, 0.011], [63880.0, 2.755], [64052.8, 1.81], [64156.3, 0.898], [64503.9, 15.129], [64542.7, 7.769], [64559.7, 4.386], [64666.9, 0.325], [64667.0, 0.004], [64667.1, 0.309], [64670.3, 0.347], [64670.4, 1.242], [64670.5, 0.71], [64676.8, 3.313], [64677.4, 0.343], [64692.9, 0.034], [64693.3, 0.147], [64696.4, 0.173], [64699.8, 5.91]], "asks": [[64701.8, 0.012], [64702.5, 0.015], [64717.6, 0.001], [64718.3, 0.134], [64719.2, 0.558], [64854.8, 1.54], [64856.9, 10.408], [64895.7, 4.144], [65346.9, 4.434], [65444.6, 7.326], [65513.5, 0.001], [65699.9, 0.931]]}
{"kind": "depth", "E": 1787080315055, "U": 11315345504058, "u": 11315345514151, "recv_ms": 1787080315010, "bids": [[1000.0, 35.81], [14199.8, 3.178], [14299.8, 1.022], [58229.8, 0.002], [61464.8, 0.002], [62111.8, 1.898], [63882.5, 7.778], [64052.8, 1.808], [64376.3, 5.207], [64663.6, 0.619], [64664.4, 0.001], [64671.0, 0.004], [64683.3, 0.579], [64685.3, 0.291], [64685.6, 0.13], [64688.2, 0.186], [64688.5, 0.0], [64693.3, 0.053], [64694.5, 0.129], [64695.5, 0.155], [64695.7, 0.018], [64698.4, 0.0], [64699.8, 5.163]], "asks": [[64701.8, 0.012], [64704.7, 0.002], [64712.0, 0.003], [65346.9, 4.434], [65367.3, 0.025]]}
{"kind": "depth", "E": 1787080315259, "U": 11315345522211, "u": 11315345528521, "recv_ms": 1787080315211, "bids": [[14199.8, 3.752], [14299.8, 0.378], [14599.8, 0.07], [51760.0, 0.004], [58229.8, 0.002], [61464.8, 0.002], [62111.8, 1.895], [63094.4, 2.216], [63649.3, 0.15], [63891.1, 16.856], [64052.8, 1.808], [64559.7, 4.66], [64620.6, 2.37], [64685.3, 0.137], [64685.6, 0.284], [64692.9, 0.034], [64699.8, 5.161]], "asks": [[64699.9, 23.28], [64700.0, 1.397], [64701.1, 0.111], [64717.4, 3.547], [64772.2, 6.735], [64839.9, 6.863], [64895.7, 3.313], [65346.9, 4.434], [65690.8, 1.063], [67223.2, 1.336], [71169.9, 0.0]]}
{"kind": "depth", "E": 1787080315565, "U": 11315345539364, "u": 11315345544845, "recv_ms": 1787080315516, "bids": [[14199.8, 3.444], [14299.8, 0.0], [14599.8, 0.756], [58229.8, 0.002], [61464.8, 0.002], [61464.9, 0.008], [63697.0, 17.251], [63699.8, 0.031], [63826.4, 9.516], [64052.8, 1.808], [64182.2, 10.145], [64362.0, 5.241], [64503.9, 8.459], [64542.7, 5.057], [64559.7, 2.973], [64580.1, 3.864], [64581.9, 0.001], [64628.5, 0.065], [64633.8, 0.001], [64663.6, 0.001], [64683.8, 1.024], [64691.0, 0.071], [64692.9, 0.222], [64693.3, 0.107], [64699.8, 5.159]], "asks": [[64699.9, 23.296], [64716.3, 0.165], [64765.2, 0.002], [64765.3, 0.002], [64771.0, 0.049], [64835.2, 6.183], [64839.9, 6.863], [64856.9, 10.408], [65346.9, 4.434], [65454.6, 2.289], [65605.7, 31.455], [65609.8, 1.363], [65699.9, 0.951], [65901.1, 0.124]]}
{"kind": "depth", "E": 1787080315667, "U": 11315345545080, "u": 11315345555274, "recv_ms": 1787080315619, "bids": [[1000.0, 35.81], [14199.8, 3.08], [14599.8, 1.12], [58229.8, 0.002], [62111.8, 1.898], [63785.4, 14.317], [64052.8, 1.808], [64156.3, 0.885], [64376.3, 5.196], [64585.8, 0.001], [64588.6, 4.365], [64622.1, 0.021], [64641.5, 0.006], [64654.5, 0.004], [64692.9, 0.222]], "asks": [[64725.8, 1.453], [64732.3, 0.006], [64813.0, 0.002], [64839.9, 6.863], [64856.9, 10.408], [64894.0, 0.005], [64895.7, 14.316], [64965.4, 0.0], [65023.4, 4.77], [65062.9, 0.0], [65346.9, 4.434], [65476.3, 31.947], [65558.7, 2.432]]}
{"kind": "depth", "E": 1787080315769, "U": 11315345555445, "u": 11315345564880, "recv_ms": 1787080315720, "bids": [[14199.8, 2.716], [14599.8, 1.484], [51760.0, 0.008], [58229.8, 0.002], [62111.8, 1.895], [63298.9, 0.676], [63699.8, 0.011], [63846.9, 3.91], [63955.8, 8.039], [64328.5, 0.0], [64329.1, 0.856], [64425.1, 0.038], [64425.6, 0.368], [64496.1, 0.0], [64499.0, 1.036], [64503.9, 14.907], [64542.7, 7.716], [64559.7, 4.362], [64586.3, 9.342], [64588.6, 5.412], [64633.8, 2.441], [64692.9, 0.034]], "asks": [[64726.3, 0.161], [64765.3, 2.498], [64812.9, 10.222], [64893.9, 9.259], [64895.7, 3.604], [64965.2, 0.33], [65023.4, 4.77], [65062.8, 0.94], [65205.6, 0.095], [65217.5, 9.367], [65346.9, 4.434], [65508.6, 11.75], [65573.3, 6.972], [65699.9, 0.931], [66289.4, 0.648], [66317.4, 1.057]]}
{"kind": "depth", "E": 1787080315871, "U": 11315345564963, "u": 11315345573594, "recv_ms": 1787080315824, "bids": [[1000.0, 35.96], [14199.8, 2.366], [14599.8, 1.834], [51760.0, 0.004], [58229.8, 0.002], [61464.8, 0.0], [61464.9, 0.01], [62111.8, 1.898], [64052.8, 1.808], [64065.0, 2.36], [64212.7, 0.007], [64376.3, 5.197], [64684.2, 0.006], [64694.5, 0.087], [64695.4, 0.107]], "asks": [[64704.9, 0.007], [65023.4, 4.769], [65180.0, 1.631], [65329.9, 0.002], [65346.9, 4.434], [65551.6, 1.524], [65564.5, 5.138]]}
{"kind": "depth", "E": 1787080315973, "U": 11315345573653, "u": 11315345580646, "recv_ms": 1787080315927, "bids": [[1000.0, 35.81], [14199.8, 2.016], [14599.8, 2.184], [51759.8, 0.0], [58229.8, 0.002], [61464.8, 0.0], [62111.8, 1.895], [63405.9, 0.016], [63699.8, 0.031], [63923.4, 31.589], [64052.8, 1.808], [64328.9, 43.393], [64329.1, 7.281], [64376.3, 5.352], [64425.5, 35.99], [64425.6, 5.61], [64496.2, 0.079], [64496.5, 27.622], [64496.6, 0.216], [64499.0, 5.061], [64616.3, 33.736], [64618.5, 0.005], [64625.1, 0.0], [64625.2, 0.001], [64645.3, 3.6], [64653.6, 2.248], [64654.2, 0.0], [64659.6, 0.339], [64661.9, 3.05], [64662.8, 0.164], [64674.9, 0.57], [64675.7, 0.195], [64680.2, 1.06], [64680.9, 1.288], [64682.0, 1.375], [64683.8, 0.024], [64683.9, 0.318], [64684.5, 0.003], [64685.4, 0.007], [64687.2, 0.353], [64687.9, 1.749], [64688.3, 0.006], [64688.4, 0.002], [64689.1, 0.548], [64690.4, 0.001], [64690.8, 0.288], [64691.2, 1.952], [64691.3, 2.285], [64691.4, 1.763], [64691.5, 0.295], [64691.6, 0.084], [64691.9, 0.119], [64692.3, 0.218], [64692.7, 0.085], [64692.8, 1.844], [64693.2, 0.034], [64693.3, 0.107], [64693.4, 0.278], [64693.8, 0.003], [64693.9, 0.084], [64694.1, 0.0], [64694.2, 0.001], [64694.3, 0.003], [64694.4, 1.655], [64694.5, 0.002], [64694.6, 0.007], [64694.8, 0.023], [64694.9, 0.009], [64695.1, 0.002], [64695.4, 0.0], [64695.7, 0.01], [64695.8, 0.003], [64696.8, 0.013], [64697.1, 0.001], [64697.7, 0.019], [64697.9, 0.004], [64699.8, 2.883]], "asks": [[64699.9, 23.306], [64700.7, 0.084], [64701.2, 0.02], [64701.8, 0.012], [64702.5, 0.015], [64704.1, 0.019], [64704.4, 0.044], [64706.0, 0.313], [64707.5, 0.465], [64707.6, 0.265], [64710.5, 3.119], [64713.4, 0.018], [64715.2, 0.559], [64716.2, 0.021], [64717.4, 4.09], [64718.0, 0.001], [64719.2, 0.017], [64719.3, 1.047], [64719.4, 0.12], [64719.9, 0.0], [64720.4, 0.002], [64721.8, 1.918], [64772.3, 1.251], [64774.5, 38.569], [64777.1, 0.003], [64795.3, 2.567], [64795.4, 0.016], [64803.6, 2.126], [64803.7, 0.008], [64811.9, 2.143], [64812.0, 0.002], [64839.9, 5.402], [64856.9, 6.065], [64893.9, 9.043], [64894.9, 1.763], [64895.2, 26.285], [64895.7, 9.195], [64966.5, 5.33], [64966.6, 31.94], [64967.9, 0.027], [65022.1, 0.022], [65022.8, 0.108], [65062.8, 6.825], [65064.0, 40.255], [65346.9, 4.434], [65585.9, 5.474], [65699.9, 0.951], [65993.8, 0.05]]}
{"kind": "depth", "E": 1787080316075, "U": 11315345580785, "u": 11315345586084, "recv_ms": 1787080316027, "bids": [[14199.8, 1.652], [14599.8, 2.548], [51760.0, 0.008], [58229.8, 0.002], [61464.8, 0.0], [63708.9, 0.018], [63994.6, 4.44], [64009.9, 2.972], [64052.8, 1.808], [64085.2, 10.755], [64213.1, 54.42], [64616.3, 0.0], [64618.5, 33.783], [64654.2, 0.004], [64675.0, 0.83], [64682.4, 1.697], [64688.2, 0.186], [64688.3, 0.005], [64689.1, 0.0], [64689.3, 0.031], [64690.8, 0.204], [64691.1, 0.216], [64691.2, 1.868], [64691.4, 1.747], [64691.5, 0.171], [64691.6, 0.077], [64692.3, 0.118], [64692.9, 1.687], [64693.0, 0.21], [64693.1, 0.189], [64693.4, 0.09], [64693.7, 0.005], [64694.2, 0.085], [64694.3, 0.002], [64694.5, 0.01], [64694.7, 0.133], [64694.8, 0.042], [64695.1, 0.086], [64695.4, 0.084], [64695.6, 1.558], [64695.7, 0.018], [64697.2, 0.005], [64697.7, 0.018], [64699.8, 3.452]], "asks": [[64699.9, 23.382], [64700.0, 1.4], [64701.8, 0.002], [64701.9, 0.0], [64702.5, 0.005], [64704.6, 0.003], [64710.5, 2.146], [64712.9, 2.128], [64717.9, 10.094], [64719.4, 0.005], [64719.9, 0.115], [64720.3, 0.703], [64772.2, 1.099], [64772.3, 39.977], [64774.5, 0.062], [64839.9, 6.863], [64856.9, 10.408], [64895.7, 2.796], [65023.4, 4.923], [65181.2, 51.83], [65217.5, 9.672], [65346.9, 4.434], [65690.9, 0.018], [65993.8, 0.053]]}
{"kind": "depth", "E": 1787080316177, "U": 11315345586145, "u": 11315345591473, "recv_ms": 1787080316129, "bids": [[1000.0, 35.81], [14199.8, 1.302], [14599.8, 2.898], [51760.0, 0.006], [58229.8, 0.002], [62111.8, 1.898], [63699.8, 0.011], [63708.8, 0.017], [63891.1, 17.09], [63923.4, 36.276], [64052.8, 1.808], [64596.6, 0.016], [64618.5, 0.005], [64620.7, 0.122], [64625.1, 33.778], [64629.4, 0.212], [64652.0, 2.627], [64668.2, 2.21], [64683.6, 0.36], [64689.3, 0.032], [64699.8, 3.452]], "asks": [[64699.9, 23.383], [64703.0, 0.914], [64705.9, 0.07], [64709.0, 0.155], [64722.8, 0.005], [64739.0, 0.932], [64761.6, 0.007], [64761.7, 0.002], [64790.6, 0.0], [64793.9, 2.386], [64794.1, 0.379], [65346.9, 4.434], [65629.3, 12.385], [65699.9, 0.931]]}
{"kind": "depth", "E": 1787080316279, "U": 11315345591551, "u": 11315345597027, "recv_ms": 1787080316262, "bids": [[1000.0, 35.81], [14199.8, 0.938], [14599.8, 3.262], [51760.0, 0.004], [58229.8, 0.002], [61464.8, 0.0], [62111.8, 1.895], [63064.5, 0.0], [63699.8, 0.031], [63891.1, 17.323], [64052.8, 1.808], [64376.3, 5.352], [64599.9, 0.002], [64600.1, 0.153], [64601.7, 0.001], [64625.2, 6.293], [64685.6, 0.13], [64686.1, 0.358], [64686.2, 0.003], [64688.2, 0.75], [64688.6, 0.001], [64689.0, 0.001], [64689.3, 0.024], [64691.3, 0.443], [64691.4, 1.731], [64691.6, 0.0], [64691.9, 0.037], [64692.3, 0.034], [64692.9, 1.339], [64693.1, 0.001], [64693.7, 0.315], [64694.5, 0.01], [64695.8, 0.087], [64697.0, 1.648], [64697.1, 0.002]], "asks": [[64699.9, 23.186], [64708.0, 1.944], [64717.4, 3.549], [64718.3, 0.675], [64762.9, 0.646], [64791.0, 5.945], [64839.9, 5.367], [64856.9, 6.001], [64891.1, 0.0], [64891.2, 4.481], [64895.7, 8.281], [65346.9, 4.434], [65508.6, 11.979], [65512.0, 4.268], [65573.3, 7.58], [65690.8, 1.072], [65699.9, 0.951]]}
{"kind": "depth", "E": 1787080316483, "U": 11315345602811, "u": 11315345609405, "recv_ms": 1787080316433, "bids": [[1000.0, 35.81], [14199.8, 0.336], [14499.8, 0.112], [14599.8, 3.752], [58229.8, 0.002], [62111.8, 1.895], [63405.9, 0.013], [63923.4, 35.496], [64052.8, 1.808], [64596.6, 10.016], [64618.5, 33.783], [64624.7, 0.009], [64625.1, 0.0], [64625.2, 0.001], [64628.9, 8.673], [64674.9, 0.013], [64676.1, 2.52], [64686.0, 0.279], [64686.1, 0.204], [64692.9, 1.339], [64693.1, 0.189], [64699.8, 3.453]], "asks": [[64715.2, 0.003], [64716.3, 0.721], [64718.3, 0.134], [64719.2, 0.558], [64719.9, 0.0], [64720.5, 0.151], [64793.9, 3.574], [64794.1, 10.379], [65346.9, 4.434], [65638.0, 29.674]]}
{"kind": "depth", "E": 1787080316585, "U": 11315345609601, "u": 11315345614933, "recv_ms": 1787080316539, "bids": [[1000.0, 35.81], [14199.8, 0.21], [14499.8, 0.336], [14599.8, 3.654], [58229.8, 0.002], [63076.7, 2.296], [63699.8, 0.011], [63923.4, 37.839], [63999.1, 1.381], [64052.8, 1.808], [64376.3, 5.352], [64618.5, 0.005], [64620.7, 33.9], [64675.1, 0.671], [64676.1, 1.963], [64683.8, 0.024]], "asks": [[64715.3, 0.87], [64716.3, 0.165], [64717.6, 0.542], [64719.2, 0.017], [65346.9, 4.434], [65699.9, 0.931], [65758.7, 0.0]]}
{"kind": "depth", "E": 1787080316789, "U": 11315345620016, "u": 11315345624049, "recv_ms": 1787080316781, "bids": [[1000.0, 35.81], [14199.8, 0.0], [14499.8, 0.84], [14599.8, 3.36], [58229.8, 0.002], [62111.8, 1.895], [63699.8, 0.031], [63825.6, 3.125], [63923.4, 37.215], [64052.8, 1.808], [64167.9, 0.0], [64376.3, 5.198], [64685.9, 0.155], [64686.0, 0.125], [64693.1, 0.189], [64693.4, 0.09]], "asks": [[64705.6, 0.477], [64705.7, 0.079], [64706.0, 1.213], [64706.6, 0.017], [64706.9, 0.561], [64707.3, 0.009], [65150.4, 2.6], [65329.9, 65.945], [65346.9, 4.434], [65699.9, 0.951], [71169.9, 0.0]]}
{"kind": "depth", "E": 1787080316891, "U": 11315345624194, "u": 11315345628668, "recv_ms": 1787080316854, "bids": [[1000.0, 35.81], [14499.8, 1.204], [14599.8, 2.996], [51759.8, 0.0], [58229.8, 0.002], [62111.8, 1.898], [63891.1, 17.556], [64052.8, 1.808], [64376.3, 5.197], [64542.7, 0.001], [64559.7, 0.008], [64633.8, 0.001], [64633.9, 2.431], [64641.5, 0.006], [64654.5, 0.004], [64682.0, 0.375], [64683.0, 1.002], [64699.8, 4.111]], "asks": [[64699.9, 24.077], [64701.2, 0.02], [64701.4, 0.004], [64705.9, 0.069], [64732.3, 0.004], [64745.2, 0.037], [64765.3, 2.562], [64839.9, 1.465], [64856.9, 0.0], [65023.4, 4.923], [65346.9, 4.434], [65767.4, 6.378]]}
{"kind": "depth", "E": 1787080317197, "U": 11315345642233, "u": 11315345649315, "recv_ms": 1787080317151, "bids": [[1000.0, 35.81], [14499.8, 2.282], [14599.8, 1.918], [51760.0, 0.004], [58229.8, 0.002], [61464.8, 0.002], [61464.9, 0.008], [61487.7, 0.002], [62111.8, 1.898], [63697.0, 17.251], [63699.8, 0.031], [63708.8, 0.027], [64052.8, 1.808], [64559.7, 4.737], [64620.7, 0.122], [64622.9, 37.717], [64674.3, 0.628], [64677.2, 0.0], [64684.5, 0.003], [64688.3, 0.005], [64690.4, 0.002], [64692.4, 0.003], [64693.1, 0.73], [64693.4, 0.097], [64695.0, 0.045], [64699.8, 3.496]], "asks": [[64707.0, 1.362], [64715.0, 1.294], [64722.4, 1.628], [64839.9, 6.863], [64895.7, 2.501], [65346.9, 4.434], [65699.9, 0.951], [65915.5, 1.202]]}
{"kind": "depth", "E": 1787080317299, "U": 11315345649386, "u": 11315345655368, "recv_ms": 1787080317251, "bids": [[14499.8, 2.632], [14599.8, 1.568], [58229.8, 0.002], [62111.8, 1.895], [63405.9, 0.01], [63966.8, 0.016], [64052.8, 1.808], [64623.0, 6.658], [64692.4, 0.0], [64693.1, 0.542], [64696.5, 0.086], [64697.2, 0.005], [64699.8, 3.497]], "asks": [[64701.5, 0.867], [64702.5, 0.067], [64702.7, 0.003], [64761.6, 1.679], [64762.9, 0.002], [65346.9, 4.434], [65618.6, 2.956], [65690.8, 1.082], [65874.5, 0.76], [65896.8, 1.968]]}
{"kind": "depth", "E": 1787080317401, "U": 11315345656184, "u": 11315345663705, "recv_ms": 1787080317351, "bids": [[1000.0, 35.81], [14499.8, 2.982], [14599.8, 1.218], [58229.8, 0.002], [61464.8, 2.439], [62111.8, 1.898], [63699.8, 0.011], [63720.7, 8.401], [64052.8, 1.808], [64376.3, 5.352], [64559.7, 0.008], [64559.8, 4.74], [64678.3, 3.347], [64688.1, 2.898], [64688.3, 0.553], [64688.7, 0.0], [64690.4, 0.001], [64693.1, 0.001], [64693.3, 0.107], [64693.4, 0.09]], "asks": [[64699.9, 23.951], [64702.3, 0.069], [64702.5, 0.005], [64719.3, 1.091], [64720.5, 0.036], [64829.3, 2.322], [64839.9, 6.863], [64895.7, 2.47], [65217.5, 9.366], [65346.9, 4.434], [65476.3, 31.337], [65609.8, 1.136], [65699.9, 0.931], [65912.6, 0.001], [66634.5, 0.001]]}
{"kind": "depth", "E": 1787080317605, "U": 11315345674554, "u": 11315345681985, "recv_ms": 1787080317582, "bids": [[14499.8, 3.696], [14599.8, 0.504], [51760.0, 0.004], [58229.8, 0.002], [61464.8, 2.439], [62111.8, 1.895], [63405.9, 0.013], [63622.4, 0.0], [63699.8, 0.031], [63773.9, 32.995], [64017.2, 0.39], [64052.8, 1.809], [64620.0, 1.789], [64655.5, 0.401], [64663.4, 0.057], [64664.5, 0.001], [64674.3, 1.185], [64675.1, 0.114], [64675.9, 0.196], [64676.8, 3.197], [64679.5, 0.954], [64680.2, 0.134], [64683.8, 0.024], [64685.7, 0.316], [64685.9, 0.001], [64687.1, 0.546], [64688.0, 1.479], [64688.1, 2.357], [64688.4, 0.002], [64693.3, 0.115], [64694.5, 0.002], [64695.8, 0.003], [64696.5, 0.002], [64699.8, 2.866]], "asks": [[64699.9, 23.957], [64711.9, 0.927], [64713.9, 0.042], [64716.3, 0.165], [64717.4, 2.347], [64717.9, 0.094], [64772.3, 40.253], [64774.5, 0.062], [64856.9, 6.002], [64895.7, 8.058], [65112.3, 0.0], [65346.9, 4.434], [65573.3, 7.807], [65674.2, 0.027], [65699.9, 0.951], [65896.8, 2.952], [66646.8, 2.173]]}
{"kind": "depth", "E": 1787080317707, "U": 11315345682115, "u": 11315345687966, "recv_ms": 1787080317684, "bids": [[1000.0, 35.81], [14399.8, 0.168], [14499.8, 3.724], [14599.8, 0.308], [58229.8, 0.002], [61464.8, 2.439], [62111.8, 1.898], [63729.3, 3.582], [63994.6, 5.141], [64052.8, 1.809], [64376.3, 5.352], [64571.9, 0.032], [64620.7, 33.859], [64622.9, 3.939], [64655.5, 0.065], [64673.4, 0.557], [64674.3, 0.628], [64675.2, 0.161], [64675.9, 0.08], [64678.8, 0.926], [64679.5, 0.028], [64685.6, 0.13], [64687.0, 1.836], [64687.1, 0.546], [64688.2, 0.565], [64688.4, 0.002], [64691.2, 1.408], [64692.3, 0.118], [64693.3, 0.107], [64694.5, 0.01], [64695.4, 0.0], [64695.5, 0.239]], "asks": [[64699.9, 25.254], [64713.8, 2.713], [64714.7, 0.156], [64714.8, 0.884], [64715.3, 0.314], [64715.8, 0.064], [64716.3, 0.165], [64717.3, 0.544], [64717.4, 2.29], [64717.6, 0.001], [64718.0, 0.001], [64719.0, 0.123], [64719.3, 0.976], [64813.8, 0.0], [64856.9, 10.408], [64895.7, 4.684], [65217.5, 9.672], [65346.9, 4.434], [65476.3, 31.947], [65993.8, 0.056]]}
{"kind": "depth", "E": 1787080317911, "U": 11315345694754, "u": 11315345699195, "recv_ms": 1787080317900, "bids": [[14399.8, 0.644], [14499.8, 3.486], [14599.8, 0.07], [51759.8, 0.0], [58229.8, 0.002], [61464.8, 2.441], [62111.8, 1.898], [62111.9, 0.603], [64052.8, 1.809]], "asks": [[64707.3, 0.102], [64712.1, 0.465], [65023.4, 4.923], [65088.1, 0.073], [65346.9, 4.434], [65461.6, 6.149], [65476.3, 32.161]]}
{"kind": "depth", "E": 1787080318013, "U": 11315345699256, "u": 11315345704565, "recv_ms": 1787080318006, "bids": [[1000.0, 35.81], [14399.8, 0.924], [14499.8, 3.276], [14599.8, 0.0], [58229.8, 0.002], [61464.9, 0.006], [63699.8, 0.031], [64052.8, 1.809], [64376.3, 5.197], [64559.8, 0.0], [64680.0, 2.533], [64680.6, 0.02], [64696.0, 0.086]], "asks": [[64839.9, 1.465], [65217.5, 9.366], [65346.9, 4.434], [65476.3, 32.924], [65499.8, 8.667], [65638.0, 28.609], [65699.9, 0.951]]}
{"kind": "depth", "E": 1787080318115, "U": 11315345704651, "u": 11315345713616, "recv_ms": 1787080318116, "bids": [[1000.0, 35.81], [14399.8, 1.288], [14499.8, 2.912], [58229.8, 0.002], [61464.8, 2.441], [62111.8, 1.895], [63785.4, 13.377], [64052.8, 1.809], [64156.3, 0.816], [64182.2, 10.145], [64559.8, 4.66], [64622.1, 0.03], [64659.4, 0.003], [64674.9, 0.631], [64678.8, 0.0], [64680.5, 0.928], [64682.3, 0.028], [64682.4, 0.001], [64687.1, 0.005], [64688.2, 0.565], [64688.4, 0.543], [64688.5, 0.016], [64690.6, 0.004], [64692.3, 0.037], [64692.7, 0.001], [64694.5, 0.002], [64695.7, 0.01], [64696.5, 0.086], [64697.4, 0.085], [64699.8, 4.169]], "asks": [[64699.9, 25.165], [64700.3, 0.057], [64701.6, 0.084], [64702.2, 0.05], [64707.2, 0.026], [64707.3, 0.565], [64710.0, 0.623], [64710.5, 2.146], [64712.1, 0.002], [64712.7, 0.164], [64713.2, 0.301], [64713.5, 0.31], [64713.6, 0.01], [64715.0, 0.814], [64717.3, 0.003], [64717.4, 3.509], [64718.2, 10.014], [64718.3, 0.675], [64720.1, 2.328], [64839.9, 6.863], [64856.9, 6.065], [64895.7, 7.958], [65346.9, 4.434], [65638.0, 27.544], [65702.7, 14.895]]}
{"kind": "depth", "E": 1787080318421, "U": 11315345722313, "u": 11315345726906, "recv_ms": 1787080318407, "bids": [[1000.0, 35.81], [14399.8, 2.366], [14499.8, 1.834], [51760.0, 0.004], [58229.8, 0.002], [61464.8, 2.441], [63391.6, 1.891], [63699.8, 0.031], [63909.1, 4.609], [64052.8, 1.809], [64559.8, 4.168], [64591.4, 2.318], [64593.3, 0.096], [64673.4, 0.0], [64675.1, 0.671], [64675.2, 0.045], [64676.5, 0.117], [64699.8, 4.155]], "asks": [[64705.0, 0.917], [64708.0, 1.044], [64807.2, 2.34], [64829.3, 2.322], [64839.9, 6.863], [64895.7, 4.492], [65346.9, 4.434], [65614.9, 0.913], [65699.9, 0.951]]}
{"kind": "depth", "E": 1787080318523, "U": 11315345726942, "u": 11315345731974, "recv_ms": 1787080318501, "bids": [[14399.8, 2.716], [14499.8, 1.484], [58229.8, 0.002], [61464.8, 2.441], [62111.8, 1.898], [63276.4, 0.01], [63826.4, 10.141], [63923.4, 37.214], [64052.8, 1.808], [64055.0, 0.15], [64182.2, 9.834], [64215.6, 0.0], [64376.3, 5.197], [64376.6, 0.002], [64538.0, 2.69], [64674.9, 0.013], [64692.9, 0.979], [64693.3, 0.107], [64699.8, 3.629]], "asks": [[64699.9, 25.184], [64707.2, 0.025], [64867.4, 0.227], [65023.4, 4.769], [65029.6, 2.385], [65192.2, 0.001], [65346.9, 4.434], [65355.2, 1.0], [65499.8, 8.067], [65508.6, 12.207], [65601.1, 0.002]]}
{"kind": "depth", "E": 1787080318727, "U": 11315345738879, "u": 11315345751270, "recv_ms": 1787080318683, "bids": [[1000.0, 35.81], [14399.8, 3.43], [14499.8, 0.77], [51760.0, 0.004], [58229.8, 0.002], [61464.8, 2.441], [62111.8, 1.898], [63826.4, 10.923], [63947.3, 4.049], [64052.8, 1.808], [64570.4, 0.004], [64641.5, 0.009], [64690.6, 0.003], [64692.4, 0.003], [64692.7, 0.085], [64693.3, 0.295], [64695.8, 0.087], [64699.8, 4.039]], "asks": [[64699.9, 25.197], [64701.6, 0.084], [64715.8, 0.007], [64716.9, 0.058], [64785.6, 1.255], [64797.0, 0.0], [64809.9, 0.004], [65346.9, 4.434], [65597.0, 22.063], [65599.2, 7.915], [67934.8, 0.005]]}
{"kind": "depth", "E": 1787080318931, "U": 11315345761814, "u": 11315345767883, "recv_ms": 1787080318882, "bids": [[1000.0, 35.81], [14299.8, 0.224], [14399.8, 3.696], [14499.8, 0.28], [51759.8, 0.0], [58229.8, 0.002], [61464.8, 2.441], [62111.9, 0.602], [63405.9, 0.013], [63699.8, 0.011], [64052.8, 1.808], [64376.3, 5.363], [64687.0, 0.036], [64688.0, 3.279], [64699.8, 4.153]], "asks": [[65023.4, 4.922], [65330.2, 13.864], [65346.9, 4.436], [65605.7, 36.022], [65699.9, 0.931]]}
{"kind": "depth", "E": 1787080319135, "U": 11315345772522, "u": 11315345779029, "recv_ms": 1787080319088, "bids": [[14299.8, 0.7], [14399.8, 3.458], [14499.8, 0.042], [51760.0, 0.004], [58229.8, 0.002], [61464.8, 2.441], [62111.8, 1.895], [64052.8, 1.81], [64620.7, 33.765], [64622.9, 3.939], [64648.0, 1.312], [64674.9, 0.631], [64682.3, 0.028], [64685.4, 0.006], [64688.2, 0.565], [64688.5, 0.016], [64688.9, 0.563], [64693.0, 0.126], [64693.3, 0.295], [64693.4, 0.09], [64697.1, 0.002], [64698.1, 0.084], [64699.8, 4.822]], "asks": [[64699.9, 23.645], [64700.2, 0.002], [64700.7, 0.0], [64701.4, 0.011], [64702.3, 0.007], [64702.7, 0.065], [64704.1, 0.103], [64705.5, 0.001], [64712.7, 0.164], [64719.5, 1.325], [64720.1, 2.946], [64764.6, 0.02], [64767.2, 0.518], [64856.9, 6.1], [64891.2, 4.478], [64891.3, 0.003], [64895.7, 7.906], [65023.4, 4.923], [65346.9, 4.434], [65618.6, 3.183]]}
{"kind": "depth", "E": 1787080319237, "U": 11315345779122, "u": 11315345783830, "recv_ms": 1787080319189, "bids": [[1000.0, 35.81], [14299.8, 1.008], [14399.8, 3.192], [14499.8, 0.0], [51760.0, 0.004], [58229.8, 0.002], [61464.8, 2.441], [62111.8, 1.898], [63599.9, 11.474], [63699.8, 0.031], [63761.7, 27.02], [63923.4, 38.62], [64052.8, 1.808], [64182.2, 10.145], [64376.3, 5.352], [64507.2, 4.745], [64620.8, 8.652], [64660.9, 0.037], [64674.5, 0.56], [64675.1, 0.114], [64679.8, 0.002], [64680.5, 0.002], [64680.6, 0.946], [64681.6, 0.016], [64685.6, 0.13], [64686.5, 0.002], [64688.0, 3.588], [64688.1, 2.898], [64688.4, 0.002]], "asks": [[64699.9, 23.638], [64700.5, 0.01], [64700.7, 0.0], [64701.3, 0.863], [64713.4, 0.018], [64714.1, 0.992], [64715.9, 0.023], [64716.7, 0.561], [64718.3, 0.134], [64718.5, 0.31], [64719.2, 0.558], [64719.4, 0.012], [64765.2, 1.207], [64856.9, 10.408], [64895.7, 2.502], [65346.9, 4.434], [65628.1, 4.234], [65699.9, 0.951]]}
{"kind": "depth", "E": 1787080319441, "U": 11315345789394, "u": 11315345794006, "recv_ms": 1787080319392, "bids": [[14299.8, 1.722], [14399.8, 2.478], [58229.8, 0.002], [61464.8, 2.441], [62111.8, 1.895], [63699.8, 0.011], [64052.8, 1.808], [64641.5, 0.009], [64654.5, 0.001], [64680.3, 0.005], [64683.6, 0.354], [64699.8, 4.822]], "asks": [[64705.5, 0.0], [64715.3, 0.87], [64716.7, 0.005], [64745.2, 0.037], [64809.9, 0.001], [64829.3, 2.322], [64991.1, 35.338], [65346.8, 0.347], [65346.9, 4.434], [65699.9, 0.931], [65993.8, 0.053]]}
{"kind": "depth", "E": 1787080319543, "U": 11315345794457, "u": 11315345800049, "recv_ms": 1787080319496, "bids": [[1000.0, 35.81], [14299.8, 2.086], [14399.8, 2.114], [58229.8, 0.002], [61464.8, 2.441], [62111.8, 1.898], [64052.8, 1.808], [64376.3, 5.352], [64542.8, 7.769], [64559.8, 4.677], [64672.7, 0.027], [64683.6, 0.362], [64687.7, 0.542], [64693.3, 0.107], [64698.1, 0.0], [64699.8, 4.821]], "asks": [[64699.9, 23.638], [64700.6, 0.128], [64839.9, 6.863], [64854.8, 0.719], [64856.9, 10.408], [64895.7, 3.025], [65346.9, 4.434], [65638.0, 30.739]]}
{"kind": "depth", "E": 1787080319645, "U": 11315345800148, "u": 11315345805006, "recv_ms": 1787080319596, "bids": [[1000.0, 35.81], [14299.8, 2.436], [14399.8, 1.764], [51760.0, 0.006], [58229.8, 0.002], [61464.8, 2.441], [62111.8, 1.895], [63699.8, 0.031], [63761.7, 27.02], [64573.1, 1.351], [64620.7, 0.122], [64620.8, 1.271], [64624.7, 0.0], [64625.0, 35.188], [64634.7, 0.051], [64635.0, 0.044], [64635.1, 0.345], [64635.4, 2.323], [64635.7, 0.259], [64636.0, 0.034], [64653.8, 0.008], [64654.1, 0.065], [64654.3, 0.033], [64654.4, 1.167], [64654.8, 1.912], [64655.1, 0.359], [64668.7, 0.0], [64668.8, 0.007], [64668.9, 0.003], [64669.0, 0.001], [64669.1, 0.176], [64669.2, 0.124], [64669.3, 2.145], [64669.4, 0.002], [64669.5, 0.003], [64669.7, 0.056], [64672.0, 0.008], [64672.5, 0.003], [64673.7, 0.558], [64674.5, 0.003], [64674.9, 0.013], [64675.4, 0.346], [64676.1, 0.035], [64676.5, 0.001], [64679.6, 0.938], [64680.6, 0.02], [64683.8, 0.024], [64686.7, 1.15], [64686.8, 0.572], [64687.3, 0.56], [64688.0, 2.379], [64688.1, 2.357], [64690.7, 0.002], [64690.8, 0.064], [64690.9, 0.0], [64691.0, 0.001], [64691.1, 0.016], [64691.2, 1.208], [64691.3, 0.001], [64691.4, 1.631], [64691.5, 0.001], [64691.7, 0.102], [64691.9, 0.005], [64692.3, 0.002], [64692.4, 0.032], [64692.6, 0.001], [64692.9, 0.759], [64693.0, 0.21], [64693.1, 0.189], [64693.2, 0.312], [64696.3, 0.001], [64696.8, 0.013], [64699.8, 4.147]], "asks": [[64699.9, 23.729], [64700.5, 0.003], [64701.4, 0.004], [64706.7, 0.003], [64707.1, 0.443], [64707.3, 0.086], [64707.4, 1.466], [64707.7, 0.667], [64708.0, 1.006], [64708.3, 0.412], [64708.4, 0.141], [64708.5, 0.466], [64708.6, 2.702], [64708.7, 0.005], [64708.8, 0.121], [64708.9, 0.234], [64709.0, 0.001], [64709.1, 0.001], [64709.2, 0.003], [64709.3, 0.165], [64711.6, 0.223], [64712.0, 0.928], [64714.1, 0.067], [64716.3, 0.706], [64717.6, 0.001], [64718.2, 10.129], [64720.1, 2.328], [64720.2, 0.001], [64725.8, 1.421], [64726.1, 0.216], [64726.4, 0.887], [64726.8, 0.039], [64727.1, 0.205], [64727.5, 0.142], [64727.9, 0.001], [64730.2, 0.0], [64730.4, 0.22], [64730.5, 0.964], [64730.6, 0.404], [64730.7, 0.001], [64730.8, 0.058], [64730.9, 0.009], [64731.0, 0.067], [64731.1, 0.62], [64731.2, 2.883], [64744.9, 0.024], [64745.2, 0.005], [64745.5, 0.008], [64745.8, 0.074], [64746.2, 1.563], [64764.6, 0.019], [64813.8, 0.115], [65346.9, 4.434], [65379.2, 5.442], [65699.9, 0.951]]}
{"kind": "depth", "E": 1787080319849, "U": 11315345810523, "u": 11315345815462, "recv_ms": 1787080319799, "bids": [[1000.0, 35.96], [14299.8, 3.15], [14399.8, 1.05], [58229.8, 0.002], [61464.9, 0.002], [63699.8, 0.011], [64052.8, 1.808], [64376.3, 5.362], [64620.7, 0.122], [64622.1, 0.021], [64622.9, 37.537], [64624.7, 0.009], [64654.0, 0.036], [64654.5, 0.004], [64654.9, 2.351], [64655.3, 0.184], [64688.3, 0.005], [64688.5, 0.0], [64690.9, 0.07], [64691.1, 0.086], [64691.2, 1.378], [64691.3, 0.201], [64691.4, 1.731], [64691.6, 1.865], [64692.1, 0.032], [64693.1, 0.033], [64693.3, 0.295], [64693.4, 0.67], [64694.5, 0.01], [64695.7, 0.018], [64698.4, 0.001]], "asks": [[64706.7, 0.035], [64707.0, 0.494], [64707.3, 0.094], [64708.0, 1.044], [64708.7, 0.115], [64708.8, 0.361], [64708.9, 0.404], [64709.0, 0.092], [64709.2, 0.08], [64711.6, 0.215], [64725.8, 1.453], [64726.1, 0.248], [64727.1, 0.243], [64727.9, 0.131], [64730.7, 0.221], [64730.9, 0.079], [64731.0, 0.158], [64731.1, 0.774], [64744.9, 0.056], [64745.2, 0.037], [64746.1, 0.079], [64764.6, 0.022], [64809.9, 0.004], [65346.9, 4.434], [65508.6, 12.549], [65699.9, 0.931]]}
{"kind": "depth", "E": 1787080319951, "U": 11315345815491, "u": 11315345820098, "recv_ms": 1787080319903, "bids": [[1000.0, 35.81], [14299.8, 3.514], [14399.8, 0.686], [51759.8, 0.0], [58229.8, 0.002], [61464.8, 2.441], [62111.8, 1.895], [64052.8, 1.81], [64376.3, 5.361], [64635.2, 1.134], [64678.2, 0.192], [64691.1, 0.156], [64691.4, 1.801], [64693.3, 0.107], [64699.8, 4.149]], "asks": [[64708.7, 0.192], [64709.0, 0.176], [64730.6, 0.601], [64731.0, 0.242], [65346.9, 4.434], [65461.6, 5.464], [65638.0, 29.674]]}
{"kind": "depth", "E": 1787080320053, "U": 11315345820132, "u": 11315345828274, "recv_ms": 1787080320007, "bids": [[14199.8, 0.056], [14299.8, 3.752], [14399.8, 0.392], [58229.8, 0.002], [61464.8, 2.442], [62111.8, 1.898], [63699.8, 0.031], [63781.1, 3.75], [64052.8, 1.808], [64635.5, 0.033], [64651.4, 0.004], [64661.1, 0.261], [64661.3, 0.016], [64662.8, 0.01], [64663.4, 0.0], [64664.4, 0.058], [64667.6, 0.851], [64669.3, 1.991], [64669.5, 0.103], [64670.5, 0.696], [64672.6, 0.598], [64674.1, 0.157], [64675.6, 0.0], [64679.6, 0.012], [64680.4, 0.946], [64688.1, 2.357], [64688.2, 0.565], [64688.3, 0.546], [64689.3, 0.023], [64689.8, 0.051], [64690.9, 0.14], [64691.0, 0.342], [64691.1, 0.155], [64691.5, 0.102], [64692.5, 0.013], [64693.1, 0.574], [64693.4, 0.129], [64693.5, 0.046], [64694.6, 0.0], [64695.6, 1.563], [64698.9, 0.0], [64699.3, 0.06], [64699.8, 4.153]], "asks": [[64699.9, 23.73], [64702.4, 0.102], [64702.6, 0.186], [64702.7, 0.003], [64703.3, 0.008], [64703.4, 0.154], [64704.1, 0.099], [64705.2, 0.001], [64706.5, 0.159], [64706.9, 0.02], [64707.2, 0.025], [64707.3, 0.635], [64707.8, 0.258], [64708.3, 0.356], [64708.4, 0.141], [64709.2, 0.15], [64709.8, 0.155], [64710.4, 0.009], [64711.6, 0.061], [64712.0, 0.011], [64712.1, 0.465], [64716.3, 0.222], [64716.9, 0.001], [64731.2, 2.953], [64748.4, 0.001], [65023.4, 4.923], [65346.9, 4.434], [65508.6, 12.807], [65635.7, 0.396], [65699.9, 0.951]]}
{"kind": "depth", "E": 1787080320155, "U": 11315345828326, "u": 11315345835371, "recv_ms": 1787080320107, "bids": [[1000.0, 35.81], [14199.8, 0.28], [14299.8, 3.668], [14399.8, 0.252], [51760.0, 0.054], [58229.8, 0.002], [61464.8, 2.442], [62111.8, 1.895], [63708.8, 0.035], [63708.9, 0.0], [63773.5, 0.03], [63773.6, 1.567], [63775.5, 0.128], [63775.6, 0.0], [63923.4, 38.151], [64052.8, 1.808], [64376.3, 5.362], [64542.8, 5.427], [64559.8, 3.149], [64615.4, 0.094], [64622.9, 3.939], [64624.7, 0.0], [64625.0, 35.188], [64634.9, 0.075], [64635.9, 0.13], [64636.2, 0.032], [64655.8, 0.09], [64657.6, 1.389], [64669.0, 0.071], [64669.3, 2.191], [64669.6, 0.122], [64669.7, 0.126], [64669.9, 0.672], [64672.2, 0.106], [64675.0, 0.83], [64682.4, 0.619], [64688.9, 0.562], [64690.6, 0.004], [64699.8, 4.163]], "asks": [[64701.4, 0.009], [64702.7, 0.158], [64706.9, 0.028], [64707.2, 0.181], [64708.4, 0.296], [64711.6, 0.061], [64712.0, 0.313], [64712.1, 0.62], [64712.9, 3.671], [64719.5, 6.325], [64720.3, 0.703], [64735.0, 0.033], [64759.5, 0.099], [64761.3, 0.015], [64767.2, 0.5], [64771.8, 0.002], [64839.9, 6.863], [64895.7, 9.082], [65217.5, 9.672], [65346.9, 4.434], [65624.2, 0.0], [65626.2, 0.0], [65690.9, 0.0]]}
{"kind": "depth", "E": 1787080320359, "U": 11315345840714, "u": 11315345852760, "recv_ms": 1787080320310, "bids": [[14199.8, 0.742], [14299.8, 3.444], [14399.8, 0.014], [51760.0, 0.004], [58229.8, 0.053], [61464.8, 2.443], [63838.6, 6.097], [63923.4, 38.62], [64052.8, 1.808], [64645.4, 0.043], [64664.0, 1.193], [64665.0, 1.369], [64669.1, 0.316], [64669.5, 0.173], [64673.7, 0.001], [64676.2, 0.64], [64679.9, 0.006], [64680.9, 2.214], [64682.4, 0.001], [64685.6, 0.571], [64687.0, 0.036], [64688.0, 3.279], [64688.3, 0.546], [64689.0, 0.001], [64691.5, 0.101], [64692.0, 0.012], [64692.9, 0.762], [64693.0, 0.086], [64693.1, 0.033], [64693.2, 0.436], [64693.3, 0.648], [64695.0, 0.026], [64697.2, 0.005], [64699.8, 4.812]], "asks": [[64699.9, 23.637], [64700.0, 1.484], [64700.1, 0.005], [64700.3, 0.076], [64700.4, 0.024], [64700.5, 0.0], [64701.1, 0.089], [64701.2, 0.0], [64702.7, 0.003], [64704.5, 0.725], [64705.0, 0.017], [64706.9, 0.02], [64707.2, 0.496], [64708.0, 1.944], [64708.4, 0.141], [64712.0, 0.003], [64712.1, 0.002], [64712.9, 2.128], [64713.3, 0.0], [64713.8, 3.638], [64715.3, 0.314], [64716.4, 6.674], [64716.9, 0.058], [64717.4, 2.29], [64718.1, 0.005], [64718.2, 0.014], [64719.2, 0.558], [64720.0, 4.08], [64720.2, 0.116], [64720.3, 0.085], [64721.4, 10.06], [64829.3, 2.323], [64856.9, 10.408], [64895.7, 3.225], [65217.5, 9.978], [65300.0, 133.792], [65346.9, 4.434], [65350.0, 152.571], [65499.8, 7.725], [65508.6, 13.149], [65638.0, 30.739], [65644.5, 2.066], [71169.9, 0.0]]}
{"kind": "depth", "E": 1787080320461, "U": 11315345852901, "u": 11315345861720, "recv_ms": 1787080320414, "bids": [[1000.0, 35.81], [14199.8, 1.092], [14299.8, 3.108], [14399.8, 0.0], [58229.8, 0.053], [61464.8, 2.443], [62111.8, 1.895], [63699.8, 0.031], [64052.8, 1.81], [64092.6, 0.0], [64376.3, 5.362], [64663.9, 0.394], [64665.0, 1.312], [64668.9, 0.073], [64674.5, 0.56], [64675.4, 0.23], [64676.2, 0.083], [64677.2, 0.116], [64677.5, 0.002], [64678.3, 3.349], [64678.8, 0.007], [64679.5, 0.026], [64679.9, 0.932], [64680.9, 1.288], [64683.9, 0.631], [64685.0, 0.022], [64687.3, 0.251], [64687.8, 0.547], [64688.2, 0.866], [64688.3, 0.013], [64692.9, 0.762], [64693.0, 0.627], [64693.3, 0.107], [64693.4, 0.129], [64693.5, 0.046], [64694.5, 0.002], [64695.1, 0.106], [64695.7, 0.018], [64697.1, 0.01], [64699.8, 4.807]], "asks": [[64699.9, 23.63], [64700.1, 0.002], [64700.3, 0.057], [64700.7, 0.01], [64702.7, 0.158], [64703.4, 0.0], [64704.0, 0.185], [64706.5, 0.005], [64706.6, 0.001], [64706.8, 0.009], [64706.9, 0.362], [64707.0, 0.803], [64707.2, 0.626], [64707.3, 0.627], [64709.8, 0.001], [64710.4, 0.163], [64712.1, 0.467], [64712.3, 1.417], [64713.3, 0.925], [64713.8, 2.713], [64717.3, 0.003], [64717.4, 0.016], [64718.3, 0.675], [64719.2, 0.024], [64719.5, 1.323], [64721.4, 10.062], [64731.0, 0.396], [64731.1, 0.62], [64767.2, 0.518], [64829.3, 2.322], [65346.9, 4.434], [65512.0, 1.982], [65699.9, 0.951], [65993.8, 0.056]]}
{"kind": "depth", "E": 1787080320563, "U": 11315345861729, "u": 11315345879260, "recv_ms": 1787080320513, "bids": [[14199.8, 1.456], [14299.8, 2.744], [58229.8, 0.053], [61464.8, 2.443], [61464.9, 0.0], [62111.8, 1.898], [63813.4, 2.502], [64052.8, 1.808], [64559.8, 0.0], [64684.2, 0.005], [64693.0, 0.627], [64693.3, 0.107], [64693.6, 0.001], [64699.8, 4.804]], "asks": [[64700.4, 0.044], [64702.7, 0.003], [64704.9, 0.006], [64706.8, 0.009], [64706.9, 0.052], [64712.1, 0.002], [64730.7, 0.221], [64731.0, 0.242], [64731.1, 0.62], [64839.9, 1.465], [65346.9, 4.434]]}
{"kind": "depth", "E": 1787080320665, "U": 11315345879533, "u": 11315345888290, "recv_ms": 1787080320619, "bids": [[14199.8, 1.806], [14299.8, 2.394], [58229.8, 0.053], [61464.8, 2.443], [62111.8, 1.895], [63522.3, 0.629], [63699.8, 0.011], [63826.4, 11.704], [63882.5, 7.427], [64052.8, 1.808], [64559.8, 4.659], [64622.1, 0.024], [64641.5, 0.006], [64654.5, 0.001], [64680.2, 0.134], [64683.8, 0.024], [64692.9, 0.759], [64699.8, 4.796]], "asks": [[64702.7, 0.003], [64706.8, 0.009], [64706.9, 0.052], [64712.1, 0.002], [64716.3, 0.165], [64731.2, 3.107], [64745.2, 0.037], [64809.9, 0.001], [64839.9, 6.863], [64856.9, 6.032], [64895.7, 9.511], [65008.8, 0.078], [65346.9, 4.434], [65638.0, 29.674], [65699.9, 0.931], [65909.8, 4.662], [65922.4, 0.0]]}
{"kind": "depth", "E": 1787080320869, "U": 11315345898912, "u": 11315345906371, "recv_ms": 1787080320819, "bids": [[14199.8, 2.534], [14299.8, 1.666], [58229.8, 0.053], [62111.8, 1.898], [63405.9, 0.013], [63449.7, 1.352], [63699.8, 0.031], [64052.8, 1.808], [64602.8, 0.129], [64628.9, 2.673], [64635.9, 0.054], [64651.5, 0.001], [64652.2, 1.796], [64667.7, 0.002], [64687.8, 0.006], [64689.0, 0.542]], "asks": [[64722.8, 0.005], [64739.0, 0.932], [64761.6, 0.786], [64761.7, 0.002], [64770.1, 39.68], [64772.2, 1.099], [64772.3, 1.251], [65346.9, 4.434], [65699.9, 0.951], [65993.8, 0.059], [66677.8, 0.0]]}
{"kind": "depth", "E": 1787080320971, "U": 11315345906434, "u": 11315345912768, "recv_ms": 1787080320922, "bids": [[14199.8, 2.884], [14299.8, 1.316], [51759.8, 0.0], [58229.8, 0.053], [62111.8, 1.895], [63761.7, 25.923], [63955.8, 8.039], [64052.8, 1.81], [64100.5, 3.478], [64374.0, 0.165], [64596.6, 0.016], [64651.4, 1.257], [64688.2, 0.85], [64688.3, 0.029], [64692.3, 0.005], [64695.7, 0.018], [64697.1, 0.01]], "asks": [[64708.2, 0.005], [64709.8, 0.001], [64713.7, 0.022], [64715.3, 0.354], [64793.9, 2.386], [64794.1, 0.379], [65001.9, 0.075], [65346.9, 4.434], [65585.9, 4.866]]}
{"kind": "depth", "E": 1787080321073, "U": 11315345912844, "u": 11315345919227, "recv_ms": 1787080321025, "bids": [[1000.0, 35.81], [14199.8, 3.234], [14299.8, 0.966], [58229.8, 0.053], [61464.8, 2.445], [62111.8, 1.898], [63699.8, 0.011], [64052.8, 1.808], [64376.3, 5.363], [64503.9, 0.002], [64504.0, 14.995], [64542.8, 6.74], [64559.8, 4.152], [64628.2, 6.251], [64650.8, 3.505], [64654.5, 0.004], [64661.3, 0.002], [64663.9, 0.337], [64665.0, 1.312], [64665.3, 0.079], [64666.9, 1.312], [64670.5, 0.71], [64674.5, 0.003], [64676.3, 0.559], [64677.0, 0.98], [64677.8, 0.004], [64679.9, 0.006], [64681.0, 0.077], [64681.3, 2.245], [64686.3, 0.001], [64687.9, 1.761], [64688.2, 0.85], [64688.3, 0.592], [64690.6, 0.003], [64691.4, 0.189], [64692.0, 0.011], [64692.1, 0.033], [64692.8, 1.845], [64693.0, 0.086], [64693.2, 0.312], [64693.3, 0.107], [64693.4, 0.246], [64694.3, 0.002], [64694.8, 0.023], [64695.7, 0.01], [64696.8, 0.004], [64696.9, 0.002], [64697.1, 0.002], [64697.2, 0.089], [64699.7, 0.039], [64699.8, 7.141]], "asks": [[64699.9, 23.522], [64700.0, 1.4], [64701.4, 0.004], [64701.9, 0.005], [64702.7, 0.158], [64706.8, 0.164], [64706.9, 0.593], [64707.3, 0.241], [64712.1, 0.467], [64713.3, 0.0], [64713.5, 0.31], [64713.7, 0.022], [64714.0, 1.027], [64716.7, 0.005], [64716.9, 0.003], [64717.1, 0.001], [64717.2, 0.001], [64717.5, 2.589], [64718.3, 0.134], [64719.2, 0.565], [64721.7, 0.977], [64731.2, 3.109], [64731.7, 0.022], [64737.9, 3.523], [64748.4, 3.743], [64760.5, 6.226], [64770.1, 0.001], [64774.5, 39.741], [64797.0, 0.003], [64809.9, 0.004], [64839.9, 6.863], [64856.9, 10.408], [64895.7, 5.464], [65023.4, 4.922], [65346.9, 4.434], [65699.9, 0.931]]}
{"kind": "depth", "E": 1787080321277, "U": 11315345924068, "u": 11315345929118, "recv_ms": 1787080321227, "bids": [[1000.0, 35.81], [14199.8, 3.78], [14299.8, 0.336], [14599.8, 0.084], [51760.0, 0.004], [58229.8, 0.053], [61464.8, 2.445], [62097.9, 2.017], [63699.8, 0.031], [63761.7, 27.02], [63955.8, 8.039], [64052.8, 1.808], [64085.2, 11.455], [64559.8, 0.0], [64595.8, 15.213], [64620.6, 2.37], [64666.9, 1.314], [64667.0, 0.006], [64667.1, 0.311], [64670.3, 0.349], [64670.4, 1.244], [64670.5, 0.712], [64683.4, 0.863], [64699.8, 7.146]], "asks": [[64699.9, 23.461], [64702.7, 0.003], [64704.6, 0.095], [64706.5, 0.005], [64706.6, 0.001], [64706.7, 0.112], [64706.8, 0.001], [64706.9, 0.593], [64707.3, 0.009], [64708.4, 0.141], [64710.4, 0.163], [64712.1, 0.473], [64713.9, 0.66], [64719.6, 0.001], [64721.3, 2.585], [64790.7, 3.406], [64792.9, 10.171], [64839.9, 1.465], [64854.8, 2.18], [65023.4, 4.923], [65346.9, 4.434], [65585.9, 4.258], [65699.9, 0.951], [65993.8, 0.056]]}
{"kind": "depth", "E": 1787080321379, "U": 11315345929154, "u": 11315345936094, "recv_ms": 1787080321332, "bids": [[1000.0, 35.81], [14199.8, 3.64], [14299.8, 0.224], [14599.8, 0.336], [51760.0, 0.004], [58229.8, 0.053], [60804.2, 4.001], [61451.0, 3.227], [61464.8, 2.445], [62111.8, 1.898], [63955.8, 8.976], [64052.8, 1.808], [64182.2, 9.523], [64376.3, 6.65], [64559.8, 4.677], [64622.8, 33.751], [64625.0, 1.59], [64660.9, 0.023], [64692.7, 0.033], [64692.8, 0.002], [64693.8, 0.004], [64694.8, 0.0], [64695.5, 0.261], [64695.9, 1.926]], "asks": [[64699.9, 23.462], [64702.7, 0.003], [64706.7, 0.144], [64706.8, 0.472], [64706.9, 0.561], [64708.4, 0.141], [64709.0, 1.076], [64710.4, 0.163], [64712.1, 0.002], [64767.2, 0.5], [64829.3, 2.322], [64839.9, 6.863], [64895.7, 3.804], [65023.4, 4.769], [65217.5, 8.753], [65346.9, 4.434], [65476.3, 31.095], [65573.3, 9.023]]}
{"kind": "depth", "E": 1787080321481, "U": 11315345936212, "u": 11315345943968, "recv_ms": 1787080321432, "bids": [[14199.8, 3.542], [14299.8, 0.098], [14599.8, 0.56], [58229.8, 0.053], [61464.8, 2.445], [62111.8, 1.895], [63699.8, 0.011], [63761.7, 25.925], [63955.8, 8.04], [64052.8, 1.808], [64167.8, 0.0], [64559.8, 4.142], [64622.8, 0.372], [64624.7, 0.0], [64625.0, 34.969], [64625.1, 0.0], [64660.9, 0.037], [64683.4, 0.245], [64691.9, 0.003], [64692.3, 0.005], [64692.9, 0.002], [64693.3, 0.107], [64693.4, 0.247], [64693.8, 0.003], [64697.2, 0.005], [64699.8, 7.174]], "asks": [[64700.1, 0.086], [64702.7, 0.003], [64706.7, 0.144], [64708.4, 0.141], [64710.4, 0.163], [64712.1, 0.002], [64749.7, 0.03], [64767.2, 0.5], [64839.9, 6.863], [64895.7, 5.578], [65346.9, 4.434], [65699.9, 0.931], [65993.8, 0.059]]}
{"kind": "depth", "E": 1787080321583, "U": 11315345944193, "u": 11315345950845, "recv_ms": 1787080321537, "bids": [[1000.0, 35.81], [14199.8, 3.374], [14299.8, 0.0], [14599.8, 0.826], [58229.8, 0.053], [62111.8, 1.898], [64052.8, 1.81], [64591.4, 0.0], [64591.6, 2.319], [64600.1, 0.15], [64600.2, 0.003], [64676.2, 0.64], [64676.3, 0.002], [64677.2, 0.0], [64677.7, 0.12], [64677.9, 0.231], [64678.5, 0.009], [64678.8, 0.0], [64679.7, 0.0], [64681.1, 0.009], [64683.8, 0.025], [64684.7, 0.01], [64685.0, 0.015], [64687.9, 2.07], [64688.2, 0.001], [64688.3, 0.568], [64688.4, 0.55], [64688.5, 0.016], [64693.3, 0.108], [64693.4, 0.246], [64696.7, 0.002], [64699.3, 0.068], [64699.7, 0.031], [64699.8, 7.172]], "asks": [[64699.9, 23.541], [64700.6, 0.088], [64700.7, 0.007], [64702.7, 0.003], [64704.5, 0.726], [64706.5, 1.086], [64706.6, 0.008], [64706.7, 0.344], [64706.8, 0.001], [64706.9, 0.02], [64707.0, 0.494], [64707.3, 0.002], [64708.4, 0.141], [64710.4, 0.163], [64712.1, 0.002], [64718.9, 0.08], [64719.2, 0.558], [64720.2, 0.001], [64720.7, 0.124], [64807.2, 2.34], [65217.5, 9.978], [65346.9, 4.434], [65476.3, 33.687]]}
{"kind": "depth", "E": 1787080321685, "U": 11315345950854, "u": 11315345957225, "recv_ms": 1787080321635, "bids": [[1000.0, 35.81], [14199.8, 3.024], [14599.8, 1.176], [58229.8, 0.053], [61464.8, 2.445], [62111.8, 1.895], [63017.6, 0.001], [63405.9, 0.01], [63699.8, 0.031], [63761.7, 27.02], [63955.8, 8.976], [64052.8, 1.808], [64182.2, 10.456], [64376.3, 6.795], [64665.3, 0.104], [64671.8, 0.524], [64675.0, 0.212], [64675.8, 0.685], [64676.2, 0.083], [64677.6, 0.005], [64677.8, 0.002], [64681.0, 1.003], [64681.3, 1.319], [64683.8, 0.023], [64691.5, 0.102], [64692.3, 0.002], [64692.7, 0.117], [64693.3, 0.107], [64695.5, 0.239], [64695.6, 1.563], [64695.8, 0.004], [64695.9, 2.01], [64696.9, 0.001], [64699.8, 4.828]], "asks": [[64699.9, 23.604], [64700.9, 0.025], [64701.0, 0.072], [64701.6, 0.087], [64701.9, 0.011], [64702.4, 0.096], [64702.7, 0.158], [64705.7, 0.002], [64706.5, 0.005], [64706.6, 0.001], [64706.8, 0.009], [64706.9, 0.199], [64707.2, 0.318], [64707.3, 1.098], [64708.4, 0.141], [64709.0, 1.796], [64709.9, 0.027], [64710.4, 0.473], [64712.1, 0.157], [64713.9, 0.042], [64714.4, 0.515], [64716.3, 0.163], [64716.5, 0.008], [64716.9, 0.001], [64717.0, 0.463], [64718.3, 0.134], [64719.2, 0.558], [64719.5, 11.323], [64719.8, 0.881], [64720.0, 2.191], [64721.3, 1.967], [64721.4, 0.062], [64726.4, 0.045], [64731.8, 0.647], [64738.3, 0.0], [64764.6, 0.004], [64770.1, 39.808], [64772.3, 1.251], [65023.4, 4.923], [65346.9, 4.434], [65447.9, 0.013], [65694.0, 3.033], [65699.9, 0.951], [65993.8, 0.056]]}
