{"kind": "depth", "E": 1787080467547, "U": 11315356488502, "u": 11315356496744, "recv_ms": 1787080467508, "bids": [[1000.0, 35.81], [14492.6, 3.5], [14592.6, 0.7], [58223.3, 0.055], [61457.9, 0.067], [62104.8, 0.015], [62760.2, 0.002], [63068.9, 4.592], [63398.8, 0.642], [64045.7, 4.688], [64175.1, 9.803], [64552.3, 1.237], [64552.4, 6.247], [64614.1, 0.003], [64616.3, 36.413], [64627.9, 0.036], [64628.6, 1.796], [64640.1, 0.03], [64663.1, 0.311], [64666.5, 0.447], [64671.0, 0.095], [64671.9, 0.336], [64676.2, 0.003], [64679.1, 0.073], [64682.3, 0.407], [64682.6, 0.227], [64682.7, 0.776], [64682.8, 0.484], [64682.9, 0.101], [64683.0, 0.17], [64684.5, 0.514], [64687.3, 1.188], [64687.4, 0.008], [64689.0, 0.0], [64689.4, 0.027], [64689.9, 0.001], [64692.6, 8.757]], "asks": [[64692.7, 25.881], [64695.0, 0.007], [64695.1, 0.012], [64695.7, 0.006], [64696.0, 0.851], [64697.4, 0.011], [64697.5, 0.124], [64697.9, 0.307], [64698.0, 0.81], [64698.1, 1.261], [64699.7, 0.011], [64700.0, 1.753], [64700.7, 0.256], [64700.8, 0.409], [64700.9, 0.218], [64701.1, 0.902], [64701.2, 0.197], [64701.4, 1.174], [64706.1, 0.003], [64707.9, 0.002], [64708.1, 0.008], [64708.7, 0.023], [64709.2, 0.322], [64709.3, 0.556], [64713.9, 0.004], [64721.3, 0.257], [64721.4, 0.253], [64721.5, 1.834], [64721.6, 1.729], [64721.7, 0.123], [64721.8, 0.282], [64722.0, 0.64], [64724.6, 0.0], [64724.7, 0.001], [64724.8, 1.242], [64725.4, 0.006], [64725.5, 0.0], [64727.6, 0.0], [64727.7, 0.026], [64727.8, 0.001], [64736.7, 0.043], [64757.4, 0.411], [64833.6, 9.218], [64889.4, 3.472], [64889.9, 6.037], [65339.6, 5.533]]}
{"kind": "depth", "E": 1787080467649, "U": 11315356496973, "u": 11315356504718, "recv_ms": 1787080467601, "bids": [[1000.0, 35.81], [14392.6, 0.056], [14492.6, 3.738], [14592.6, 0.406], [51754.0, 0.0], [58223.3, 0.055], [61457.9, 0.067], [63692.6, 0.002], [63858.1, 0.313], [63916.3, 21.047], [64045.7, 4.688], [64369.1, 4.731], [64614.2, 0.629], [64614.9, 0.138], [64628.3, 0.032], [64628.9, 0.034], [64641.3, 0.016], [64661.6, 1.071], [64661.8, 0.07], [64662.1, 0.178], [64662.5, 0.191], [64664.2, 0.115], [64684.0, 0.005], [64689.3, 0.087], [64689.6, 0.021]], "asks": [[64692.7, 25.891], [64696.0, 0.388], [64697.6, 0.03], [64697.8, 0.006], [64697.9, 0.275], [64698.0, 0.842], [64699.6, 0.047], [64699.7, 0.474], [64700.0, 2.637], [64701.4, 1.19], [64708.3, 0.13], [64711.4, 0.374], [64712.1, 1.504], [64736.4, 0.052], [64737.1, 1.108], [64889.4, 3.334], [65339.6, 5.533], [65501.4, 11.11], [65533.7, 13.864], [65692.7, 0.006]]}
{"kind": "depth", "E": 1787080467751, "U": 11315356504834, "u": 11315356511443, "recv_ms": 1787080467703, "bids": [[14392.6, 0.266], [14492.6, 3.682], [14592.6, 0.252], [58223.3, 0.055], [62104.8, 0.018], [63791.0, 42.397], [63883.9, 10.472], [63916.3, 25.734], [64045.7, 4.688], [64175.1, 10.113], [64369.1, 4.732], [64609.7, 36.531], [64612.3, 0.227], [64616.3, 0.0], [64629.2, 0.037], [64629.6, 0.032], [64633.0, 0.065], [64651.1, 0.318], [64661.8, 0.14], [64662.1, 0.108], [64662.2, 0.07], [64663.6, 0.001], [64669.3, 0.07], [64672.8, 5.379], [64675.1, 2.026], [64680.2, 0.47], [64680.3, 0.628], [64681.5, 0.586], [64681.6, 0.024], [64689.3, 0.003], [64692.6, 8.756]], "asks": [[64692.9, 0.097], [64701.2, 0.66], [64708.1, 0.001], [64708.9, 0.221], [64735.8, 0.035], [64736.1, 0.036], [65016.2, 4.487], [65339.6, 5.533], [71162.0, 0.0]]}
{"kind": "depth", "E": 1787080467853, "U": 11315356511596, "u": 11315356551023, "recv_ms": 1787080467886, "bids": [[1000.0, 35.81], [14392.6, 0.504], [14492.6, 3.57], [14592.6, 0.126], [51754.1, 0.0], [58223.3, 0.055], [61457.9, 0.073], [61458.0, 0.074], [61458.1, 0.007], [62104.8, 0.015], [63398.8, 0.645], [63692.6, 0.022], [63923.9, 0.783], [64045.7, 4.688], [64582.6, 0.005], [64583.3, 0.085], [64609.7, 0.118], [64612.3, 0.209], [64614.1, 36.416], [64614.9, 0.156], [64631.6, 6.031], [64632.8, 2.107], [64646.4, 0.009], [64657.7, 0.003], [64659.3, 0.693], [64661.4, 0.124], [64661.6, 1.141], [64661.8, 0.21], [64664.5, 0.117], [64664.7, 0.102], [64666.2, 3.164], [64667.5, 0.35], [64668.8, 0.359], [64670.1, 1.472], [64671.0, 0.005], [64672.1, 0.619], [64673.1, 0.003], [64674.3, 0.002], [64674.7, 1.146], [64675.4, 3.716], [64675.9, 0.052], [64677.5, 0.007], [64680.4, 0.324], [64680.5, 0.064], [64680.9, 0.0], [64681.5, 0.045], [64682.8, 1.022], [64683.2, 0.011], [64684.4, 0.032], [64684.6, 0.005], [64684.8, 0.044], [64685.4, 0.009], [64686.5, 0.003], [64686.7, 1.822], [64687.1, 0.001], [64687.3, 1.126], [64687.4, 0.188], [64687.9, 0.05], [64689.2, 0.001], [64689.4, 0.005], [64689.5, 0.085], [64689.9, 0.007], [64690.2, 0.086], [64690.6, 0.084], [64690.7, 0.48], [64690.8, 0.126], [64691.2, 0.05], [64691.9, 0.002], [64692.6, 10.303]], "asks": [[64692.7, 9.307], [64692.8, 0.205], [64692.9, 0.012], [64693.3, 0.004], [64693.9, 0.002], [64694.0, 0.002], [64694.1, 0.001], [64694.5, 0.005], [64695.1, 0.002], [64695.6, 0.003], [64695.7, 0.003], [64695.9, 0.021], [64696.0, 0.381], [64696.3, 0.012], [64696.4, 0.184], [64696.6, 0.037], [64696.8, 0.001], [64697.0, 0.016], [64697.2, 0.018], [64697.6, 0.033], [64697.7, 0.084], [64697.9, 0.004], [64698.0, 0.815], [64698.1, 0.024], [64698.2, 0.441], [64699.4, 0.001], [64699.6, 0.151], [64699.7, 0.003], [64700.0, 1.737], [64700.1, 0.003], [64700.4, 0.287], [64701.1, 0.274], [64701.4, 1.174], [64701.6, 0.021], [64702.2, 0.466], [64702.8, 0.023], [64702.9, 0.327], [64703.0, 0.009], [64703.1, 0.469], [64703.4, 0.968], [64704.0, 1.953], [64705.0, 0.018], [64705.8, 0.005], [64706.4, 0.025], [64706.5, 0.003], [64707.2, 0.936], [64707.8, 0.002], [64708.3, 0.385], [64708.8, 0.026], [64708.9, 0.214], [64709.2, 0.002], [64709.6, 0.0], [64709.9, 0.45], [64710.0, 0.285], [64710.3, 0.134], [64711.1, 0.059], [64711.6, 0.083], [64711.9, 0.541], [64712.1, 1.389], [64712.8, 0.237], [64712.9, 0.003], [64713.4, 0.212], [64713.8, 0.008], [64714.3, 0.0], [64714.8, 3.517], [64715.2, 1.247], [64717.1, 0.154], [64719.1, 0.037], [64719.7, 0.05], [64721.2, 0.065], [64721.6, 1.609], [64723.3, 0.313], [64723.4, 0.021], [64723.5, 10.44], [64731.1, 0.122], [64738.0, 0.007], [64741.9, 0.042], [64747.2, 1.396], [64755.9, 2.259], [64770.6, 0.376], [64822.1, 0.0], [64854.5, 0.006], [65339.6, 5.533], [65396.3, 3.43], [65598.4, 14.898], [65692.7, 0.026]]}
{"kind": "depth", "E": 1787080467955, "U": 11315356551215, "u": 11315356564458, "recv_ms": 1787080467948, "bids": [[1000.0, 35.81], [14392.6, 0.742], [14492.6, 3.444], [14592.6, 0.014], [58223.3, 0.055], [61457.9, 0.073], [62104.8, 0.018], [63692.6, 0.002], [63948.6, 3.747], [64045.7, 4.688], [64351.7, 0.017], [64351.8, 0.611], [64369.1, 4.732], [64582.6, 0.002], [64614.1, 0.003], [64614.9, 0.138], [64616.3, 36.413], [64635.6, 1.663], [64646.0, 3.044], [64661.7, 0.07], [64662.0, 0.383], [64662.1, 0.208], [64662.2, 0.17], [64662.3, 2.261], [64662.4, 0.08], [64665.0, 1.177], [64668.3, 0.311], [64669.2, 0.001], [64671.5, 0.585], [64678.8, 0.001], [64679.6, 0.394], [64679.7, 0.007], [64680.3, 0.551], [64680.4, 0.015], [64680.5, 0.018], [64681.0, 0.063], [64681.4, 0.992], [64681.5, 0.663], [64681.6, 0.008], [64682.8, 0.481], [64684.6, 0.314], [64685.9, 0.001], [64686.7, 1.821], [64686.8, 0.004], [64687.4, 0.189], [64689.3, 0.01], [64690.5, 0.024], [64690.6, 0.0], [64691.0, 0.008], [64692.6, 10.284]], "asks": [[64692.7, 9.407], [64693.3, 0.003], [64694.4, 0.094], [64694.6, 0.317], [64696.8, 0.0], [64697.2, 0.011], [64697.3, 0.088], [64697.6, 0.013], [64698.0, 0.822], [64698.5, 0.002], [64698.8, 0.454], [64699.6, 0.14], [64700.1, 0.014], [64701.1, 0.377], [64702.0, 0.903], [64703.0, 0.001], [64703.4, 0.659], [64704.3, 0.467], [64707.0, 1.383], [64708.3, 0.29], [64709.3, 0.0], [64709.9, 0.13], [64710.2, 0.584], [64710.6, 0.32], [64713.4, 0.097], [64714.3, 0.115], [64723.7, 0.122], [64731.1, 0.002], [64738.0, 0.004], [64744.5, 0.018], [64748.7, 0.237], [64755.9, 2.049], [64756.9, 0.001], [64759.1, 0.021], [64760.0, 1.359], [64761.3, 36.815], [64770.4, 0.022], [64770.6, 0.375], [64785.6, 1.255], [64889.4, 2.928], [64961.6, 4.97], [65339.6, 5.535], [65508.6, 3.437], [65692.7, 0.006]]}
{"kind": "depth", "E": 1787080468057, "U": 11315356564556, "u": 11315356572068, "recv_ms": 1787080468007, "bids": [[14392.6, 1.092], [14492.6, 3.108], [14592.6, 0.0], [58223.3, 0.055], [61457.9, 0.073], [61458.0, 0.074], [61458.1, 0.009], [64045.7, 4.692], [64630.7, 0.04], [64632.9, 0.005], [64640.3, 0.032], [64657.9, 0.06], [64658.6, 0.377], [64659.3, 0.636], [64668.6, 0.558], [64669.4, 0.002], [64670.1, 1.031], [64670.9, 0.022], [64671.5, 0.469], [64673.6, 1.682], [64673.7, 0.019], [64674.7, 0.22], [64679.6, 0.396], [64679.7, 0.005], [64680.3, 0.01], [64680.9, 0.548], [64681.0, 0.063], [64681.4, 0.985], [64681.5, 0.122], [64681.6, 0.549], [64685.4, 0.01], [64686.7, 0.034], [64686.9, 0.008], [64687.1, 0.0], [64687.3, 0.847], [64687.4, 0.009], [64690.2, 0.002]], "asks": [[64692.7, 11.648], [64694.0, 0.086], [64696.8, 0.002], [64697.9, 0.004], [64698.0, 0.82], [64698.9, 0.095], [64699.0, 1.286], [64699.6, 0.047], [64700.1, 0.109], [64701.0, 0.125], [64701.1, 0.274], [64703.0, 0.009], [64705.0, 0.918], [64705.3, 0.0], [64706.0, 0.214], [64706.9, 0.021], [64707.1, 1.388], [64707.2, 0.011], [64708.8, 0.026], [64709.9, 0.686], [64710.2, 0.028], [64714.0, 0.083], [64721.2, 0.015], [64738.0, 0.007], [64744.5, 0.004], [64759.1, 36.831], [64760.0, 1.35], [64761.3, 0.005], [65339.6, 5.535], [65505.6, 8.069], [65986.5, 0.024]]}
{"kind": "depth", "E": 1787080468261, "U": 11315356580220, "u": 11315356587597, "recv_ms": 1787080468213, "bids": [[1000.0, 35.81], [14392.6, 1.792], [14492.6, 2.408], [51754.0, 0.006], [58223.3, 0.055], [62104.8, 0.018], [63692.6, 0.022], [63722.2, 19.338], [63791.0, 42.209], [63888.1, 13.45], [63948.6, 4.684], [64045.7, 4.692], [64149.1, 0.212], [64369.1, 4.742], [64657.9, 0.003], [64659.5, 0.061], [64668.6, 0.001], [64671.0, 0.562], [64674.8, 0.024], [64675.2, 1.028], [64676.0, 0.041], [64680.9, 0.64], [64683.2, 0.011], [64683.3, 0.001], [64684.5, 0.73], [64690.7, 0.312]], "asks": [[64704.0, 2.853], [64707.1, 0.463], [64707.6, 0.661], [64708.5, 1.236], [64709.9, 0.13], [64711.1, 0.002], [64711.3, 0.724], [64711.9, 0.0], [64712.2, 2.39], [64714.1, 0.601], [64714.3, 0.0], [64714.8, 3.519], [64715.4, 0.115], [65339.6, 5.535], [65679.7, 0.019], [65692.7, 0.026]]}
{"kind": "depth", "E": 1787080468363, "U": 11315356587753, "u": 11315356593822, "recv_ms": 1787080468315, "bids": [[14392.6, 2.156], [14492.6, 2.044], [51754.0, 0.0], [58223.3, 0.055], [62104.8, 0.015], [64045.7, 4.692], [64149.1, 0.188], [64563.2, 0.005], [64616.3, 0.0], [64616.4, 0.003], [64617.5, 0.0], [64618.5, 35.658], [64668.8, 0.36], [64684.7, 0.042], [64687.3, 0.937], [64687.4, 0.091]], "asks": [[64697.0, 0.019], [64697.6, 0.01], [64703.0, 0.001], [64703.1, 0.006], [64704.0, 1.953], [64705.0, 0.018], [64707.0, 0.483], [64709.9, 0.601], [64712.5, 0.059], [64719.7, 0.001], [65016.2, 4.179], [65210.2, 8.424], [65339.6, 5.535], [65469.0, 25.951], [65505.6, 7.727], [65566.1, 3.876]]}
{"kind": "depth", "E": 1787080468567, "U": 11315356598192, "u": 11315356602778, "recv_ms": 1787080468518, "bids": [[1000.0, 35.81], [14392.6, 2.87], [14492.6, 1.33], [58223.3, 0.057], [61457.9, 0.073], [61458.0, 0.072], [61458.1, 0.011], [63752.2, 1.415], [63906.7, 0.781], [64045.7, 4.692], [64369.1, 4.742], [64633.0, 0.079], [64658.6, 0.434], [64659.5, 0.004], [64669.1, 0.559], [64671.0, 0.005], [64672.8, 0.379], [64674.3, 0.928], [64675.1, 0.006], [64675.2, 0.102], [64676.2, 0.003], [64680.1, 0.02], [64680.5, 0.01], [64681.5, 0.045], [64681.6, 0.008], [64682.8, 1.022], [64684.7, 0.042], [64686.8, 0.0], [64687.3, 0.937], [64687.4, 0.001]], "asks": [[64692.7, 11.756], [64698.3, 0.004], [64702.5, 0.005], [64705.0, 0.918], [64706.7, 0.002], [64707.6, 1.586], [64708.5, 0.311], [64708.7, 0.023], [64710.5, 1.89], [64711.3, 0.781], [64712.1, 1.265], [64712.2, 2.333], [64714.1, 0.601], [64721.2, 0.001], [64721.6, 1.611], [64721.7, 0.125], [64721.8, 0.284], [64724.6, 0.002], [64724.7, 0.003], [64724.8, 1.244], [64725.4, 0.008], [64725.5, 0.002], [64727.6, 0.002], [64727.7, 0.028], [64727.8, 0.003], [65016.2, 4.487], [65210.2, 8.729], [65339.6, 5.535], [65469.0, 26.409], [67280.3, 0.006]]}
{"kind": "depth", "E": 1787080468669, "U": 11315356602781, "u": 11315356608063, "recv_ms": 1787080468628, "bids": [[14392.6, 3.22], [14492.6, 0.98], [58223.3, 0.055], [62104.8, 0.015], [63692.6, 0.022], [63819.2, 9.098], [63924.5, 0.0], [64045.7, 4.692], [64552.4, 1.26], [64609.7, 35.771], [64618.5, 0.005], [64670.5, 0.252], [64679.6, 0.242], [64679.7, 0.159], [64684.7, 0.034], [64687.3, 1.027], [64687.4, 0.009], [64687.5, 0.085], [64689.5, 0.001], [64690.7, 0.002], [64690.8, 0.001]], "asks": [[64693.2, 0.084], [64696.9, 0.342], [64698.0, 0.214], [64698.3, 0.545], [64833.5, 0.103], [64833.6, 3.82], [64843.6, 0.024], [64882.6, 2.591], [65339.6, 5.535], [65405.4, 0.0], [65692.7, 0.026], [65986.5, 0.021]]}
{"kind": "depth", "E": 1787080468771, "U": 11315356608145, "u": 11315356615264, "recv_ms": 1787080468724, "bids": [[1000.0, 35.81], [14392.6, 3.584], [14492.6, 0.616], [58223.3, 0.055], [62104.8, 0.018], [63748.1, 8.17], [64045.7, 4.692], [64369.1, 4.741], [64535.3, 0.002], [64536.7, 0.404], [64612.3, 0.218], [64637.2, 0.004], [64643.9, 0.073], [64684.5, 0.731], [64684.7, 0.042], [64686.5, 0.003], [64687.3, 0.847], [64687.4, 0.001]], "asks": [[64693.7, 0.003], [64851.2, 1.319], [64851.3, 0.0], [65016.2, 4.486], [65274.9, 0.688], [65339.6, 5.535], [65501.4, 11.339], [71162.0, 0.0]]}
{"kind": "depth", "E": 1787080468873, "U": 11315356615382, "u": 11315356623621, "recv_ms": 1787080468825, "bids": [[1000.0, 35.81], [14292.6, 0.084], [14392.6, 3.766], [14492.6, 0.35], [51754.1, 0.0], [58223.3, 0.055], [61457.9, 0.073], [62104.8, 0.015], [63398.8, 0.648], [63692.6, 0.002], [64369.1, 4.742], [64489.5, 0.0], [64489.6, 1.287], [64496.6, 15.505], [64535.4, 8.685], [64536.7, 1.634], [64552.4, 6.437]], "asks": [[64692.7, 11.757], [64833.6, 9.218], [64850.6, 10.412], [64889.4, 2.905], [65016.2, 4.487], [65339.6, 5.535], [65692.7, 0.006]]}
{"kind": "depth", "E": 1787080468975, "U": 11315356623962, "u": 11315356629755, "recv_ms": 1787080468928, "bids": [[14292.6, 0.322], [14392.6, 3.654], [14492.6, 0.224], [58223.3, 0.055], [62104.8, 0.018], [63692.6, 0.022], [63916.3, 24.954], [64045.7, 4.692], [64351.7, 0.509], [64351.8, 0.119], [64552.4, 1.26], [64669.1, 0.002], [64670.1, 0.915], [64670.6, 0.557], [64672.0, 3.487], [64683.9, 0.316], [64684.6, 0.005]], "asks": [[64692.7, 11.756], [64708.8, 0.006], [64709.7, 0.026], [64721.2, 0.015], [64721.8, 0.284], [64721.9, 0.421], [64722.8, 0.003], [64833.5, 0.127], [64833.6, 3.82], [64843.6, 0.0], [65339.6, 5.537], [65501.4, 11.681], [65692.7, 0.026]]}
{"kind": "depth", "E": 1787080469077, "U": 11315356629785, "u": 11315356641356, "recv_ms": 1787080469028, "bids": [[1000.0, 35.81], [14292.6, 0.56], [14392.6, 3.528], [14492.6, 0.112], [51754.0, 0.004], [58223.3, 0.055], [61457.9, 0.073], [63398.8, 0.645], [63705.6, 0.027], [64045.7, 4.692], [64552.4, 5.876], [64620.4, 1.695], [64633.0, 0.065], [64653.6, 0.016], [64653.7, 0.472], [64669.2, 0.619], [64673.0, 5.447], [64673.7, 1.799], [64676.6, 0.236], [64681.0, 0.063], [64689.4, 0.089], [64692.6, 10.386]], "asks": [[64692.7, 11.349], [64693.2, 0.0], [64696.9, 0.339], [64699.2, 0.002], [64702.9, 0.311], [64703.2, 0.412], [64705.4, 0.006], [64712.8, 0.237], [64714.7, 2.222], [64721.9, 0.267], [64722.1, 0.082], [64722.3, 1.273], [64833.6, 9.218], [64883.4, 2.576], [64889.4, 4.537], [65339.6, 5.535], [65435.2, 3.523], [65505.6, 7.469], [65679.6, 0.008]]}
{"kind": "depth", "E": 1787080469179, "U": 11315356641508, "u": 11315356648909, "recv_ms": 1787080469130, "bids": [[1000.0, 35.81], [14292.6, 0.812], [14392.6, 3.388], [14492.6, 0.0], [51754.0, 0.0], [58223.3, 0.055], [61457.9, 0.073], [62104.8, 0.015], [63398.8, 0.642], [63592.8, 13.653], [63705.6, 0.046], [63916.3, 25.734], [64045.6, 0.001], [64045.7, 4.692], [64369.1, 4.732], [64609.7, 0.118], [64614.1, 35.656], [64666.7, 0.668], [64669.2, 0.001], [64674.3, 0.002], [64675.6, 0.926], [64680.1, 0.012], [64681.0, 2.382], [64681.4, 1.396], [64684.8, 0.042], [64686.5, 0.002], [64687.1, 0.001], [64688.4, 0.156], [64689.1, 0.054], [64689.6, 0.001], [64690.0, 0.087], [64690.8, 0.02], [64691.2, 0.36], [64691.3, 0.023], [64692.0, 0.232], [64692.1, 0.002], [64692.6, 10.621]], "asks": [[64692.7, 8.584], [64694.0, 0.002], [64696.4, 0.168], [64696.5, 0.087], [64696.6, 0.053], [64696.8, 0.0], [64697.0, 0.016], [64697.2, 0.011], [64697.4, 0.014], [64698.0, 0.195], [64698.1, 0.001], [64698.4, 1.218], [64698.5, 0.004], [64698.6, 0.464], [64698.9, 0.079], [64699.7, 0.019], [64700.6, 0.002], [64701.1, 0.745], [64702.5, 0.497], [64703.1, 0.006], [64703.4, 0.312], [64708.9, 0.561], [64714.8, 3.517], [64715.2, 1.245], [64723.3, 0.311], [64723.4, 0.021], [64723.5, 0.442], [64725.6, 0.047], [65339.6, 5.537], [65792.5, 3.109]]}
{"kind": "depth", "E": 1787080469281, "U": 11315356648944, "u": 11315356653957, "recv_ms": 1787080469231, "bids": [[14292.6, 1.162], [14392.6, 3.038], [58223.3, 0.055], [61457.9, 0.073], [62104.8, 0.018], [62742.8, 0.686], [63692.6, 0.002], [63888.1, 13.216], [64045.7, 4.692], [64149.1, 0.179], [64582.6, 0.005], [64612.3, 0.209], [64614.9, 0.162], [64670.0, 1.42], [64679.6, 0.24], [64679.7, 0.161], [64681.0, 2.32], [64681.2, 0.224], [64681.5, 0.053], [64686.5, 0.003], [64687.1, 0.0], [64687.3, 0.847], [64692.6, 10.257]], "asks": [[64698.9, 0.095], [64699.7, 0.003], [64700.6, 0.001], [64724.0, 10.002], [64738.0, 0.007], [64883.4, 1.945], [65339.6, 5.535], [65679.6, 0.027], [65692.7, 0.006], [66350.0, 5.199]]}
{"kind": "depth", "E": 1787080469485, "U": 11315356659143, "u": 11315356663144, "recv_ms": 1787080469436, "bids": [[1000.0, 35.81], [14292.6, 1.876], [14392.6, 2.324], [51754.0, 0.0], [58223.3, 0.055], [61457.9, 0.067], [63592.8, 18.364], [63692.6, 0.022], [63754.6, 8.419], [63855.7, 15.715], [64045.7, 4.692], [64369.1, 4.732], [64661.8, 0.393], [64666.7, 0.698], [64679.4, 0.538], [64679.7, 0.007], [64682.7, 0.761]], "asks": [[64883.2, 0.397], [65210.2, 8.423], [65339.6, 5.535], [65469.0, 25.799], [65692.7, 0.026], [65986.5, 0.024]]}
{"kind": "depth", "E": 1787080469587, "U": 11315356663269, "u": 11315356667418, "recv_ms": 1787080469539, "bids": [[14292.6, 2.24], [14392.6, 1.96], [51754.0, 0.0], [58223.3, 0.055], [61457.9, 0.067], [62104.8, 0.004], [64045.7, 4.692], [64149.1, 0.148], [64496.6, 0.0], [64535.4, 0.003], [64536.7, 0.404], [64552.4, 1.26], [64635.6, 1.635], [64655.4, 0.005], [64656.0, 1.191], [64670.8, 0.014], [64673.6, 0.746], [64676.2, 0.003], [64681.6, 0.02], [64684.8, 0.031], [64687.4, 0.181], [64692.6, 10.258]], "asks": [[64692.7, 8.809], [64708.7, 0.023], [64723.8, 0.016], [64833.6, 3.82], [64850.6, 0.003], [64889.4, 0.01], [65339.6, 5.535], [65473.3, 41.984], [65501.9, 3.781], [65986.5, 0.021]]}
{"kind": "depth", "E": 1787080469689, "U": 11315356667542, "u": 11315356672597, "recv_ms": 1787080469640, "bids": [[1000.0, 35.96], [14292.6, 2.59], [14392.6, 1.61], [51754.0, 0.0], [58223.3, 0.055], [61458.0, 0.076], [62104.8, 0.001], [63692.6, 0.002], [63906.5, 11.33], [64045.7, 4.694], [64496.6, 15.505], [64535.4, 8.816], [64552.4, 6.5], [64589.6, 0.0], [64589.7, 0.006], [64658.6, 0.377], [64659.5, 0.061], [64660.3, 0.012], [64682.6, 0.202], [64682.7, 0.736], [64690.0, 0.003], [64690.5, 0.001], [64691.5, 0.02], [64692.5, 0.618], [64692.6, 10.276]], "asks": [[64692.7, 8.804], [64693.7, 0.087], [64707.6, 0.661], [64708.5, 1.236], [64711.3, 0.724], [64712.2, 2.39], [64833.5, 0.103], [64833.6, 9.218], [64843.6, 0.024], [64850.6, 10.412], [64880.7, 0.093], [64880.8, 0.019], [64889.4, 2.716], [65210.2, 8.729], [65339.6, 5.535], [65469.0, 26.409], [65488.8, 11.45], [65692.7, 0.006]]}
{"kind": "depth", "E": 1787080469791, "U": 11315356672617, "u": 11315356676594, "recv_ms": 1787080469741, "bids": [[1000.0, 35.81], [14292.6, 2.954], [14392.6, 1.246], [51754.0, 0.0], [58223.3, 0.055], [62104.8, 0.004], [63754.6, 9.515], [63851.6, 4.85], [64045.7, 4.692], [64369.1, 4.741]], "asks": [[64833.5, 0.127], [64843.6, 0.0], [65016.2, 4.486], [65339.6, 5.535], [65448.1, 2.15], [65501.4, 12.091]]}
{"kind": "depth", "E": 1787080469893, "U": 11315356676666, "u": 11315356681542, "recv_ms": 1787080469844, "bids": [[14292.6, 3.304], [14392.6, 0.896], [51754.1, 0.0], [58223.3, 0.055], [61457.9, 0.067], [62104.8, 0.001], [63147.1, 0.0], [63692.6, 0.022], [63761.7, 14.646], [63826.4, 6.019], [63883.9, 11.088], [63916.3, 25.11], [64045.7, 4.692], [64369.1, 4.431], [64424.0, 2.158], [64614.9, 0.165], [64669.8, 0.56], [64670.6, 0.0], [64671.1, 0.116], [64672.0, 3.371], [64675.0, 1.844], [64675.6, 0.0], [64681.5, 0.594], [64682.8, 0.481]], "asks": [[64692.7, 9.103], [64704.6, 0.305], [64707.2, 0.936], [64708.5, 0.311], [64712.1, 1.806], [64714.1, 0.06], [64770.4, 0.025], [64789.8, 0.007], [65210.2, 8.423], [65339.6, 5.535], [65502.0, 3.051], [65692.7, 0.026], [66155.6, 0.0]]}
{"kind": "depth", "E": 1787080469995, "U": 11315356681566, "u": 11315356686035, "recv_ms": 1787080469946, "bids": [[1000.0, 35.81], [14292.6, 3.668], [14392.6, 0.532], [58223.3, 0.055], [63689.9, 2.039], [63786.9, 26.315], [64045.7, 4.692], [64351.7, 0.017], [64351.8, 0.611], [64369.1, 4.432], [64658.8, 1.534], [64659.5, 0.004], [64674.4, 0.926], [64674.6, 0.323], [64675.0, 0.918], [64680.2, 0.0], [64681.5, 0.053], [64681.6, 0.483], [64682.8, 1.022]], "asks": [[64694.5, 0.015], [64709.7, 0.026], [64710.4, 1.2], [64710.5, 1.89], [64711.3, 0.225], [64712.2, 2.333], [64713.9, 0.119], [64715.4, 0.0], [65015.2, 0.11], [65016.2, 4.487], [65018.9, 0.0], [65339.6, 5.535], [65449.6, 2.137], [65469.0, 27.934], [66148.3, 1.206]]}
{"kind": "depth", "E": 1787080470097, "U": 11315356686094, "u": 11315356690810, "recv_ms": 1787080470049, "bids": [[14192.6, 0.14], [14292.6, 3.738], [14392.6, 0.322], [58223.3, 0.055], [61457.9, 0.067], [62104.8, 0.004], [63692.6, 0.002], [63722.2, 19.33], [63752.2, 1.024], [64045.7, 4.692], [64369.1, 4.577], [64499.0, 2.824], [64536.7, 1.654], [64614.2, 7.364], [64652.7, 0.101], [64653.7, 0.411], [64668.4, 0.62], [64669.1, 0.559], [64669.8, 0.003], [64675.8, 0.621], [64676.7, 0.786], [64680.5, 0.002], [64680.9, 0.007], [64681.0, 2.32], [64681.5, 0.586], [64681.6, 1.132], [64682.8, 0.481], [64683.2, 0.011], [64683.3, 0.001], [64686.5, 0.003], [64686.9, 0.007], [64690.9, 0.0], [64692.6, 10.384]], "asks": [[64692.7, 10.368], [64694.5, 0.005], [64695.9, 0.021], [64704.0, 1.955], [64704.7, 0.001], [64712.0, 3.516], [64712.1, 1.877], [64717.7, 0.088], [64721.6, 1.609], [64721.7, 0.123], [64721.8, 0.282], [64723.9, 2.597], [64724.6, 0.0], [64724.7, 0.001], [64724.8, 1.242], [64725.4, 0.006], [64725.5, 0.0], [64727.6, 0.0], [64727.7, 0.026], [64727.8, 0.001], [64756.3, 0.227], [64757.3, 0.0], [65210.2, 8.729], [65339.6, 5.535], [65692.7, 0.006], [65986.5, 0.018]]}
{"kind": "depth", "E": 1787080470199, "U": 11315356690845, "u": 11315356700600, "recv_ms": 1787080470150, "bids": [[14192.6, 0.378], [14292.6, 3.626], [14392.6, 0.196], [58223.3, 0.055], [62104.8, 0.001], [63398.8, 0.645], [63819.2, 9.723], [63916.3, 25.734], [64045.6, 0.0], [64045.7, 4.692], [64369.1, 4.732], [64424.0, 5.131], [64438.0, 0.408], [64467.6, 0.0], [64565.0, 1.079], [64567.6, 0.0], [64570.7, 0.0], [64625.0, 1.603], [64627.9, 0.033], [64635.6, 1.649], [64657.5, 0.008], [64666.6, 1.563], [64668.4, 0.002], [64673.0, 5.444], [64675.8, 0.003], [64677.4, 0.372], [64679.5, 0.464], [64690.6, 0.31], [64690.8, 0.001], [64691.2, 0.05], [64692.6, 10.421]], "asks": [[64692.7, 10.363], [64694.5, 0.015], [64695.9, 0.031], [64696.9, 0.342], [64697.0, 0.018], [64697.4, 0.011], [64698.5, 0.002], [64698.8, 0.454], [64700.1, 0.014], [64701.1, 0.282], [64703.1, 0.469], [64721.2, 0.001], [64723.8, 0.002], [64730.0, 1.261], [64767.7, 0.002], [64822.1, 0.003], [64830.6, 0.0], [65339.6, 5.533], [65501.4, 12.433], [65566.0, 1.942], [65986.5, 0.015]]}
{"kind": "depth", "E": 1787080470301, "U": 11315356700748, "u": 11315356706142, "recv_ms": 1787080470250, "bids": [[1000.0, 35.81], [14192.6, 0.616], [14292.6, 3.514], [14392.6, 0.07], [51754.0, 0.0], [58223.3, 0.055], [62104.8, 0.004], [63689.9, 3.137], [63692.6, 0.022], [63748.1, 8.561], [64045.7, 4.692], [64063.6, 0.001], [64552.4, 1.26], [64687.4, 0.001], [64689.4, 0.005]], "asks": [[64693.1, 0.086], [64833.6, 3.82], [65339.6, 5.533], [65692.7, 0.026]]}
{"kind": "depth", "E": 1787080470403, "U": 11315356706220, "u": 11315356709632, "recv_ms": 1787080470353, "bids": [[14192.6, 0.896], [14292.6, 3.304], [14392.6, 0.0], [58223.3, 0.055], [62104.8, 0.001], [62299.0, 0.677], [63726.3, 6.591], [64045.7, 4.692], [64149.1, 0.153], [64175.1, 9.803], [64369.1, 4.742], [64563.2, 0.005], [64667.4, 0.001], [64675.1, 0.046], [64689.6, 0.002]], "asks": [[64693.7, 0.086], [64694.4, 0.098], [65339.6, 5.533], [65780.1, 0.019], [67280.4, 1.272]]}
{"kind": "depth", "E": 1787080470607, "U": 11315356715949, "u": 11315356720277, "recv_ms": 1787080470556, "bids": [[1000.0, 35.81], [14192.6, 1.61], [14292.6, 2.59], [51754.0, 0.0], [58223.3, 0.055], [61457.9, 0.062], [62104.8, 0.004], [63692.6, 0.002], [64045.7, 4.692], [64562.2, 1.028], [64653.7, 0.425], [64668.2, 1.658], [64670.0, 1.416], [64673.4, 0.328], [64676.2, 0.003], [64686.7, 0.118], [64688.9, 0.001], [64692.6, 10.281]], "asks": [[64700.1, 0.022], [64701.1, 0.274], [64704.0, 2.855], [64708.7, 0.023], [64741.9, 0.0], [64790.6, 0.0], [64806.8, 0.001], [65339.6, 5.533], [65630.7, 11.871], [65692.7, 0.006], [65695.4, 1.066]]}
{"kind": "depth", "E": 1787080470811, "U": 11315356724571, "u": 11315356728789, "recv_ms": 1787080470764, "bids": [[14192.6, 2.324], [14292.6, 1.876], [58223.3, 0.055], [61457.9, 0.061], [62104.8, 0.004], [63692.6, 0.022], [63916.3, 25.734], [64045.7, 4.692], [64175.1, 10.113], [64369.1, 4.732], [64643.1, 4.124], [64643.3, 10.226], [64658.1, 0.062], [64658.8, 1.477], [64667.3, 0.332], [64667.5, 0.014], [64668.3, 0.002], [64670.3, 0.581], [64671.1, 0.0], [64673.7, 2.725], [64674.4, 0.0], [64680.2, 0.007], [64680.9, 0.0], [64691.2, 0.049]], "asks": [[64692.7, 12.758], [64696.6, 0.037], [64696.9, 0.349], [64698.0, 0.188], [64698.1, 0.017], [64698.2, 0.534], [64698.9, 0.002], [64700.0, 1.745], [64701.0, 1.025], [64701.1, 0.274], [64702.0, 0.003], [64703.1, 0.006], [64719.3, 10.313], [64724.0, 10.004], [64725.6, 0.045], [64759.0, 0.375], [64759.1, 0.021], [64764.9, 6.299], [64767.9, 36.833], [64889.4, 2.906], [65016.2, 4.487], [65339.6, 5.533], [65414.0, 2.548], [65630.7, 14.001], [65692.7, 0.026], [65695.4, 2.13], [65986.5, 0.012], [71162.0, 0.0]]}
{"kind": "depth", "E": 1787080470913, "U": 11315356728939, "u": 11315356733067, "recv_ms": 1787080470863, "bids": [[1000.0, 35.81], [14192.6, 2.674], [14292.6, 1.526], [51754.1, 0.0], [58223.3, 0.055], [61457.9, 0.061], [63692.6, 0.002], [63883.9, 11.322], [63888.1, 12.982], [64045.7, 4.694], [64351.7, 0.509], [64351.8, 0.119], [64552.4, 6.437], [64664.7, 0.438], [64670.9, 0.022], [64673.0, 0.444], [64673.7, 1.962], [64675.7, 0.164], [64679.4, 0.384], [64679.5, 0.618], [64680.5, 0.082], [64690.6, 0.0], [64691.2, 0.281], [64691.6, 0.024], [64691.8, 0.02], [64691.9, 0.002], [64692.0, 0.002], [64692.1, 0.0], [64692.3, 0.0], [64692.4, 0.0], [64692.5, 0.618], [64692.6, 8.881]], "asks": [[64692.7, 12.765], [64701.1, 0.902], [64723.9, 0.007], [64724.0, 0.004], [64733.9, 0.013], [64759.1, 36.845], [64760.0, 1.35], [64762.6, 0.003], [64764.9, 0.677], [64767.9, 0.009], [64780.5, 0.022], [64827.1, 3.864], [64833.6, 9.218], [64873.8, 0.008], [65339.6, 5.533], [65501.4, 12.691], [65590.4, 4.868], [65598.4, 15.431], [65692.7, 0.006]]}
{"kind": "depth", "E": 1787080471015, "U": 11315356733243, "u": 11315356738309, "recv_ms": 1787080470965, "bids": [[14192.6, 3.038], [14292.6, 1.162], [58223.3, 0.055], [61457.9, 0.055], [62104.8, 0.001], [64045.7, 4.692], [64149.1, 0.116], [64369.1, 4.742], [64570.6, 0.0], [64624.9, 0.0], [64657.4, 0.04]], "asks": [[64729.9, 0.002], [64767.6, 0.015], [64830.5, 0.001], [65016.2, 4.487], [65339.6, 5.533], [65591.9, 4.323]]}
{"kind": "depth", "E": 1787080471117, "U": 11315356738430, "u": 11315356742826, "recv_ms": 1787080471068, "bids": [[1000.0, 35.81], [14192.6, 3.388], [14292.6, 0.812], [58223.3, 0.055], [61457.9, 0.055], [62104.8, 0.004], [63398.8, 0.645], [63722.3, 0.023], [63854.9, 0.006], [64045.7, 4.692], [64110.4, 8.768], [64149.1, 0.079], [64458.4, 0.024], [64552.4, 6.436], [64620.4, 6.607], [64644.0, 2.133], [64652.3, 2.13], [64652.4, 0.397], [64660.6, 2.13], [64660.7, 0.227], [64666.7, 0.668], [64668.8, 0.36], [64676.2, 0.003], [64681.0, 2.32], [64681.6, 0.027], [64683.2, 1.824], [64683.3, 1.106], [64684.4, 0.032], [64684.5, 1.006], [64686.0, 0.016], [64686.5, 0.003], [64687.3, 1.027], [64689.9, 0.001], [64692.6, 8.787]], "asks": [[64692.7, 12.468], [64693.0, 0.02], [64704.0, 2.856], [64705.1, 0.775], [64712.0, 2.898], [64712.3, 5.119], [64714.9, 2.325], [64717.4, 2.684], [64718.1, 0.005], [64719.3, 10.315], [64741.9, 0.0], [64793.9, 4.511], [64794.0, 0.066], [64802.2, 2.128], [64802.3, 0.018], [64807.3, 0.0], [64810.5, 2.124], [64810.7, 0.219], [64833.6, 9.218], [64889.4, 2.907], [65200.0, 136.8], [65339.6, 5.533], [65501.4, 12.919]]}
{"kind": "depth", "E": 1787080471321, "U": 11315356747472, "u": 11315356751383, "recv_ms": 1787080471272, "bids": [[14192.6, 3.71], [14292.6, 0.294], [14592.6, 0.196], [51754.0, 0.0], [58223.3, 0.055], [61457.9, 0.055], [62104.8, 0.004], [64045.7, 4.692], [64369.1, 4.742], [64570.6, 0.0], [64624.9, 0.0], [64657.4, 0.04], [64692.5, 0.62]], "asks": [[64692.7, 12.565], [64698.2, 0.518], [64698.5, 0.018], [64707.0, 1.383], [64721.8, 0.436], [64721.9, 0.267], [64729.9, 0.002], [64739.3, 1.376], [64767.6, 0.015], [64830.5, 0.001], [65339.6, 5.533], [65383.4, 0.002]]}
{"kind": "depth", "E": 1787080471423, "U": 11315356751515, "u": 11315356754857, "recv_ms": 1787080471373, "bids": [[1000.0, 35.81], [14192.6, 3.598], [14292.6, 0.168], [14592.6, 0.434], [51754.0, 0.0], [58223.3, 0.055], [63692.6, 0.002], [63748.1, 8.952], [63787.5, 3.143], [63851.5, 1.876], [64045.7, 4.692], [64114.0, 4.034], [64136.9, 0.081], [64552.4, 6.5], [64563.2, 0.005], [64612.3, 0.227], [64618.5, 0.005], [64620.4, 1.695], [64666.7, 0.698], [64681.2, 0.162], [64682.3, 2.377], [64687.3, 0.909]], "asks": [[64705.0, 0.918], [64833.6, 9.218], [64889.4, 2.717], [65339.6, 5.533], [65469.0, 28.148], [65692.7, 0.006], [65986.5, 0.009]]}
{"kind": "depth", "E": 1787080471525, "U": 11315356754965, "u": 11315356760521, "recv_ms": 1787080471476, "bids": [[1000.0, 35.81], [14192.6, 3.486], [14292.6, 0.042], [14592.6, 0.672], [58223.3, 0.055], [61457.9, 0.055], [62104.8, 0.001], [64045.7, 4.692], [64175.1, 9.802], [64570.6, 0.0], [64624.9, 0.0], [64625.3, 0.006], [64657.4, 0.04], [64659.7, 0.03], [64659.8, 0.453], [64659.9, 0.005], [64663.2, 0.006], [64663.3, 0.011], [64663.4, 0.002], [64687.4, 0.189], [64692.6, 8.786]], "asks": [[64692.7, 12.634], [64698.2, 0.441], [64698.5, 0.095], [64712.3, 0.119], [64721.8, 0.282], [64721.9, 0.421], [64729.9, 0.002], [64741.9, 0.014], [64767.6, 0.015], [64830.5, 0.001], [65339.6, 5.533], [65715.3, 0.06], [66323.0, 0.03]]}
{"kind": "depth", "E": 1787080471627, "U": 11315356760544, "u": 11315356765222, "recv_ms": 1787080471579, "bids": [[14192.6, 3.22], [14292.6, 0.0], [14592.6, 0.98], [58223.3, 0.055], [62104.8, 0.004], [63398.8, 0.651], [63612.8, 3.829], [63692.6, 0.022], [63754.6, 9.672], [64045.7, 4.692], [64369.1, 4.742], [64552.4, 6.497], [64676.2, 0.003], [64684.9, 0.084], [64687.3, 0.909], [64687.4, 0.009], [64688.4, 0.072], [64688.8, 0.004]], "asks": [[64696.9, 0.283], [64708.7, 0.023], [64742.1, 0.492], [64806.4, 0.115], [64833.6, 9.218], [64889.4, 2.726], [65339.6, 5.533], [65384.9, 0.92], [65566.1, 4.484], [65573.3, 4.568], [65692.7, 0.026], [65986.5, 0.006]]}
{"kind": "depth", "E": 1787080471729, "U": 11315356765343, "u": 11315356769669, "recv_ms": 1787080471685, "bids": [[1000.0, 35.81], [14192.6, 2.87], [14592.6, 1.33], [58223.3, 0.055], [61457.9, 0.055], [62104.8, 0.001], [63010.5, 0.032], [63131.0, 1.356], [63754.6, 8.576], [64045.7, 4.692], [64110.3, 1.093], [64129.8, 18.763], [64149.1, 0.074], [64175.1, 10.113], [64328.0, 0.077], [64329.2, 1.014], [64424.7, 0.006], [64425.6, 1.029], [64475.0, 0.356], [64495.6, 3.006], [64495.7, 0.001], [64495.8, 1.393], [64612.3, 0.209], [64614.1, 33.59], [64614.9, 0.147], [64673.1, 5.003], [64679.7, 0.005]], "asks": [[64692.7, 11.83], [64737.9, 0.185], [64889.9, 0.836], [64891.7, 0.0], [64960.6, 1.061], [64963.1, 0.0], [65059.8, 0.963], [65060.6, 0.065], [65339.6, 5.533], [65462.5, 2.751], [65573.3, 3.96], [66316.3, 2.184], [67280.3, 0.001], [71162.0, 0.0]]}
{"kind": "depth", "E": 1787080471831, "U": 11315356769699, "u": 11315356772965, "recv_ms": 1787080471781, "bids": [[1000.0, 35.81], [14192.6, 2.506], [14592.6, 1.694], [51754.0, 0.0], [58223.3, 0.055], [61458.0, 0.074], [61458.1, 0.009], [62104.8, 0.004], [63692.6, 0.002], [64045.7, 4.692], [64064.6, 0.109], [64114.5, 6.233], [64212.2, 0.775], [64369.1, 4.732], [64552.4, 5.869], [64582.6, 0.005], [64614.9, 0.144], [64679.3, 0.158]], "asks": [[64692.7, 11.837], [64721.9, 0.421], [64738.0, 0.007], [64833.6, 9.218], [64889.4, 4.557], [65177.7, 0.881], [65327.6, 0.001], [65339.6, 5.533], [65692.7, 0.006], [65695.4, 3.042]]}
{"kind": "depth", "E": 1787080471933, "U": 11315356772972, "u": 11315356776941, "recv_ms": 1787080471884, "bids": [[14192.6, 2.142], [14592.6, 2.058], [51754.1, 0.0], [58223.3, 0.055], [61457.9, 0.055], [63605.8, 0.627], [64045.7, 4.692], [64323.9, 42.681], [64351.7, 0.017], [64351.9, 0.492], [64369.1, 4.742], [64420.6, 34.558], [64491.5, 27.276], [64627.9, 0.036], [64664.7, 0.102], [64683.6, 0.0], [64687.4, 0.009], [64688.5, 0.084], [64692.6, 8.678]], "asks": [[64692.7, 12.861], [64712.1, 2.001], [64888.7, 27.041], [64960.1, 33.382], [65016.2, 4.333], [65056.9, 8.197], [65057.5, 43.324], [65339.6, 5.533], [65462.5, 3.666], [65469.0, 27.69], [65543.3, 1.524], [65566.1, 5.092], [65986.5, 0.003]]}
{"kind": "depth", "E": 1787080472137, "U": 11315356781407, "u": 11315356787107, "recv_ms": 1787080472088, "bids": [[1000.0, 35.81], [14192.6, 1.442], [14592.6, 2.758], [51754.0, 0.0], [58223.3, 0.055], [61457.9, 0.055], [62104.8, 0.004], [64045.7, 4.692], [64110.4, 9.859], [64208.1, 54.778], [64369.1, 4.732], [64475.0, 0.14], [64491.6, 0.259], [64552.4, 1.26], [64570.6, 0.28], [64614.1, 0.003], [64614.2, 0.629], [64614.9, 0.135], [64616.3, 33.587], [64617.5, 0.009], [64624.9, 0.168], [64635.6, 1.635], [64638.2, 0.014], [64657.4, 0.113], [64668.8, 0.978], [64673.7, 2.578], [64676.2, 0.621], [64681.0, 2.32]], "asks": [[64692.7, 12.842], [64699.4, 0.002], [64704.0, 1.955], [64705.0, 1.536], [64712.4, 0.619], [64721.9, 0.267], [64724.7, 1.09], [64729.9, 0.075], [64741.9, 0.0], [64759.0, 8.528], [64767.6, 0.184], [64830.5, 0.283], [64833.5, 0.103], [64834.0, 0.029], [64843.6, 0.024], [65016.2, 4.333], [65174.6, 52.634], [65339.6, 5.533], [65570.3, 11.739], [65630.7, 14.001], [65694.1, 0.76], [71162.0, 0.0]]}
{"kind": "depth", "E": 1787080472239, "U": 11315356787284, "u": 11315356794783, "recv_ms": 1787080472191, "bids": [[14192.6, 1.078], [14592.6, 3.122], [51754.0, 0.0], [58223.3, 0.055], [61458.0, 0.072], [61458.1, 0.011], [62104.8, 0.001], [63692.6, 0.002], [63916.3, 25.734], [64045.7, 4.692], [64049.8, 3.253], [64460.0, 1.07], [64552.4, 6.428], [64570.6, 0.0], [64624.9, 0.0], [64657.4, 0.04], [64683.2, 1.816], [64683.3, 1.082], [64683.4, 0.072], [64687.3, 0.909], [64687.4, 0.009]], "asks": [[64699.9, 0.147], [64704.0, 2.855], [64705.5, 1.762], [64721.9, 0.421], [64729.9, 0.002], [64767.6, 0.015], [64785.6, 1.355], [64830.5, 0.001], [64833.5, 0.127], [64833.6, 9.218], [64843.6, 0.0], [64889.4, 2.931], [64889.8, 0.0], [65016.2, 4.487], [65339.6, 5.533], [65469.0, 28.148], [65630.7, 14.153], [65692.7, 0.006]]}
{"kind": "depth", "E": 1787080472341, "U": 11315356794973, "u": 11315356800226, "recv_ms": 1787080472292, "bids": [[1000.0, 35.81], [14192.6, 0.728], [14592.6, 3.472], [51754.0, 0.0], [58223.3, 0.055], [61457.9, 0.055], [63010.5, 0.031], [63855.7, 15.402], [64045.7, 4.694], [64175.1, 10.113], [64563.2, 0.005], [64612.3, 0.218], [64616.3, 0.0], [64635.6, 1.649], [64673.2, 0.003], [64674.3, 0.0], [64679.3, 0.004], [64683.1, 1.008], [64683.4, 0.08], [64683.9, 0.007], [64687.4, 0.001], [64688.5, 0.0], [64692.6, 8.672]], "asks": [[64692.7, 12.848], [64699.4, 0.001], [64882.9, 0.43], [65339.6, 5.533], [65566.1, 5.472], [71162.0, 0.0]]}
{"kind": "depth", "E": 1787080472443, "U": 11315356800296, "u": 11315356804257, "recv_ms": 1787080472395, "bids": [[1000.0, 35.81], [14192.6, 0.42], [14492.6, 0.056], [14592.6, 3.724], [58223.3, 0.055], [61457.9, 0.055], [62104.8, 0.004], [63692.6, 0.022], [64045.7, 4.692], [64070.1, 1.033], [64369.1, 4.742], [64552.4, 1.26], [64570.6, 0.0], [64624.8, 0.0], [64635.6, 1.649], [64657.4, 0.04], [64661.0, 0.359], [64664.1, 0.011], [64672.8, 0.381], [64679.7, 0.159], [64679.8, 0.0], [64679.9, 0.002], [64692.6, 8.671]], "asks": [[64696.2, 0.004], [64696.9, 0.28], [64699.0, 1.493], [64701.6, 0.372], [64729.9, 0.002], [64767.6, 0.015], [64830.4, 1.208], [64833.6, 3.82], [64882.9, 0.0], [65210.2, 8.423], [65339.6, 5.533], [65667.4, 17.363], [65692.7, 0.026], [65802.1, 0.759]]}
{"kind": "depth", "E": 1787080472545, "U": 11315356804290, "u": 11315356808593, "recv_ms": 1787080472497, "bids": [[14192.6, 0.266], [14492.6, 0.252], [14592.6, 3.682], [58223.3, 0.055], [62104.8, 0.001], [63398.8, 0.648], [63851.6, 5.163], [63883.9, 11.556], [64045.7, 4.848], [64114.5, 5.142], [64552.4, 6.436], [64668.3, 0.559], [64669.1, 0.002], [64676.4, 0.031], [64679.7, 0.166], [64680.2, 0.0]], "asks": [[64705.9, 0.948], [64707.2, 0.011], [64708.7, 0.579], [64709.6, 0.057], [64710.4, 0.644], [64711.3, 0.168], [64833.6, 9.218], [64889.4, 2.908], [65339.6, 5.533], [65630.7, 13.088]]}
{"kind": "depth", "E": 1787080472749, "U": 11315356812944, "u": 11315356818089, "recv_ms": 1787080472700, "bids": [[1000.0, 35.81], [14192.6, 0.028], [14492.6, 0.728], [14592.6, 3.444], [58223.3, 0.055], [62104.8, 0.001], [63867.2, 0.0], [64045.7, 4.848], [64060.5, 67.295], [64071.6, 1.374], [64369.1, 4.742], [64535.4, 0.003], [64536.7, 0.404], [64552.4, 1.26], [64570.5, 0.245], [64614.1, 0.003], [64614.9, 0.135], [64616.3, 32.845], [64624.8, 0.0], [64657.3, 0.0], [64676.2, 0.621]], "asks": [[64703.0, 0.901], [64707.0, 0.483], [64708.7, 0.579], [64718.0, 0.059], [64721.9, 0.421], [64729.8, 0.006], [64733.0, 0.018], [64759.1, 36.771], [64767.5, 0.017], [64830.4, 1.208], [64833.5, 0.103], [64833.6, 3.82], [64843.6, 0.024], [64850.6, 0.003], [65210.2, 8.729], [65324.6, 68.187], [65339.6, 5.533], [65630.7, 12.023]]}
{"kind": "depth", "E": 1787080472851, "U": 11315356818387, "u": 11315356823859, "recv_ms": 1787080472802, "bids": [[14192.6, 0.0], [14492.6, 1.064], [14592.6, 3.136], [58223.3, 0.055], [61458.0, 0.07], [61458.1, 0.013], [62299.0, 0.663], [63692.6, 0.022], [63813.4, 2.502], [63924.6, 1.562], [64045.7, 4.848], [64110.4, 10.95], [64496.6, 0.0], [64499.0, 0.568], [64612.3, 0.218], [64616.3, 0.0]], "asks": [[64703.0, 0.001], [64721.9, 0.267], [64722.0, 0.64], [64889.4, 0.01], [65305.8, 9.11], [65339.6, 5.533], [65521.2, 3.022], [65630.7, 13.088], [65692.7, 0.026]]}
{"kind": "depth", "E": 1787080472953, "U": 11315356823974, "u": 11315356828904, "recv_ms": 1787080472902, "bids": [[1000.0, 35.81], [14492.6, 1.414], [14592.6, 2.786], [51754.1, 0.0], [58223.3, 0.055], [62104.8, 0.004], [64045.7, 4.848], [64622.7, 0.001], [64668.4, 0.009], [64669.0, 0.001], [64679.4, 0.538], [64679.7, 0.012]], "asks": [[64697.9, 0.027], [64702.6, 0.361], [64704.3, 0.158], [64722.0, 0.64], [64722.1, 0.236], [65339.6, 5.533]]}
{"kind": "depth", "E": 1787080473055, "U": 11315356829213, "u": 11315356833928, "recv_ms": 1787080473006, "bids": [[1000.0, 35.81], [14492.6, 1.778], [14592.6, 2.422], [58223.3, 0.055], [62104.8, 0.001], [63398.8, 0.648], [63657.5, 6.297], [63692.6, 0.002], [63754.6, 8.576], [63806.3, 1.875], [63851.6, 6.101], [63980.6, 0.485], [64045.7, 4.846], [64369.1, 4.731], [64496.6, 15.505], [64535.4, 8.667], [64536.7, 1.632], [64552.4, 6.428], [64570.5, 0.525], [64582.6, 0.002], [64614.9, 0.138], [64624.8, 0.168], [64657.3, 0.073], [64681.0, 2.325]], "asks": [[64729.8, 0.078], [64738.0, 0.007], [64767.5, 0.184], [64830.4, 1.486], [64833.5, 0.127], [64833.6, 9.218], [64843.6, 0.0], [64850.6, 10.412], [64889.4, 2.931], [65016.2, 4.486], [65307.3, 3.206], [65339.6, 5.533], [65501.4, 13.681], [65630.7, 14.153], [65692.7, 0.006], [65868.6, 1.202]]}
{"kind": "depth", "E": 1787080473157, "U": 11315356833952, "u": 11315356838957, "recv_ms": 1787080473108, "bids": [[14492.6, 2.128], [14592.6, 2.072], [51754.0, 0.0], [58223.3, 0.055], [61457.9, 0.055], [62104.8, 0.004], [63657.5, 7.395], [63754.6, 7.479], [63780.4, 2.849], [63888.1, 12.748], [64045.7, 4.844], [64369.1, 4.732], [64420.1, 0.005], [64420.7, 5.722], [64499.0, 2.824], [64570.5, 0.245], [64573.3, 0.003], [64576.3, 3.868], [64582.7, 2.319], [64584.4, 0.001], [64612.3, 0.209], [64616.3, 0.0], [64616.4, 6.359], [64620.4, 1.649], [64620.6, 0.083], [64624.8, 0.0], [64635.6, 1.635], [64653.7, 0.411], [64657.3, 0.0], [64659.7, 0.028], [64659.8, 0.451], [64659.9, 0.003], [64663.2, 0.004], [64663.3, 0.009], [64663.4, 0.0], [64666.7, 0.668], [64668.1, 0.619], [64668.8, 0.36], [64675.5, 1.082], [64676.2, 0.003], [64681.0, 2.32], [64682.4, 1.377], [64684.4, 0.032], [64684.5, 1.45], [64686.5, 0.003], [64687.3, 0.909], [64688.6, 0.131], [64692.6, 8.496]], "asks": [[64692.7, 12.606], [64697.8, 0.025], [64703.4, 0.313], [64704.3, 0.776], [64705.0, 0.918], [64711.7, 0.632], [64712.1, 1.806], [64712.4, 0.001], [64714.8, 3.517], [64722.1, 0.082], [64722.3, 1.273], [64727.9, 1.475], [64729.8, 0.006], [64736.7, 0.085], [64759.0, 8.517], [64762.8, 0.004], [64763.0, 0.443], [64767.5, 0.017], [64798.4, 3.472], [64801.2, 0.0], [64827.1, 0.0], [64828.7, 3.874], [64830.4, 1.208], [64960.0, 10.854], [64960.6, 0.0], [65016.2, 4.487], [65339.6, 5.533]]}
{"kind": "depth", "E": 1787080473565, "U": 11315356858080, "u": 11315356866423, "recv_ms": 1787080473521, "bids": [[1000.0, 35.81], [14492.6, 3.57], [14592.6, 0.63], [58223.3, 0.055], [61457.9, 0.055], [61458.0, 0.074], [62104.8, 0.001], [63140.0, 4.83], [64045.7, 4.844], [64369.1, 4.587], [64684.6, 1.818], [64685.6, 0.002], [64686.5, 0.002], [64686.6, 0.31], [64687.3, 0.629], [64687.4, 0.001], [64691.2, 0.049], [64691.5, 0.0], [64691.6, 0.233], [64691.7, 0.025]], "asks": [[64692.7, 12.596], [64697.8, 0.006], [64697.9, 0.004], [64726.3, 0.176], [65016.2, 4.333], [65210.2, 8.423], [65339.6, 5.535], [65360.5, 0.006], [65469.0, 27.386]]}
{"kind": "depth", "E": 1787080473667, "U": 11315356866433, "u": 11315356874750, "recv_ms": 1787080473618, "bids": [[1000.0, 35.81], [14392.6, 0.084], [14492.6, 3.752], [14592.6, 0.364], [51754.0, 0.0], [58223.3, 0.055], [62104.8, 0.004], [63601.0, 4.522], [63754.6, 9.672], [63780.4, 3.475], [63948.6, 3.747], [64045.7, 4.844], [64369.1, 4.587], [64628.3, 0.0], [64628.6, 1.764], [64628.9, 0.002], [64629.2, 0.005], [64629.6, 0.0], [64635.6, 1.635], [64646.7, 0.0], [64647.0, 0.005], [64647.3, 0.207], [64647.6, 0.202], [64647.9, 0.022], [64648.5, 0.173], [64661.6, 1.001], [64661.7, 0.0], [64661.8, 0.183], [64662.0, 0.283], [64662.1, 0.008], [64662.2, 0.0], [64662.3, 2.161], [64662.4, 0.01], [64662.5, 0.121], [64664.2, 0.015], [64664.7, 0.002], [64676.2, 0.008], [64677.5, 0.0], [64682.2, 0.003], [64682.3, 2.307], [64682.4, 1.237], [64682.5, 0.0], [64682.6, 0.002], [64682.7, 0.536], [64682.8, 0.311], [64682.9, 0.001], [64683.0, 0.0], [64683.1, 0.938], [64683.3, 0.001], [64683.4, 0.008], [64683.7, 0.002], [64684.1, 0.0], [64684.4, 0.001], [64684.7, 1.115], [64684.8, 0.071], [64685.6, 0.001]], "asks": [[64692.7, 12.606], [64699.0, 1.458], [64699.3, 0.413], [64699.6, 0.005], [64699.9, 0.105], [64700.3, 0.46], [64700.5, 0.003], [64700.7, 0.005], [64700.8, 0.279], [64700.9, 0.004], [64701.0, 0.905], [64701.1, 0.632], [64701.2, 0.463], [64701.3, 1.319], [64701.4, 1.006], [64701.5, 0.01], [64708.7, 0.577], [64717.4, 2.681], [64717.7, 0.056], [64718.0, 0.017], [64718.3, 0.002], [64718.7, 0.006], [64719.0, 0.007], [64719.5, 1.242], [64721.1, 4.008], [64721.3, 0.166], [64721.4, 0.123], [64721.5, 1.62], [64721.6, 1.359], [64721.7, 0.003], [64721.9, 0.001], [64722.0, 0.472], [64722.1, 0.005], [64735.5, 0.032], [64735.8, 0.0], [64736.1, 0.004], [64736.4, 0.01], [64736.7, 0.043], [64737.1, 1.066], [65339.6, 5.533], [65462.5, 4.582], [65909.8, 0.756]]}
{"kind": "depth", "E": 1787080473871, "U": 11315356883340, "u": 11315356889301, "recv_ms": 1787080473823, "bids": [[1000.0, 35.81], [14392.6, 0.546], [14492.6, 3.542], [14592.6, 0.112], [58223.3, 0.055], [62104.8, 0.001], [63398.8, 0.648], [63948.6, 3.747], [64045.7, 4.844], [64552.4, 1.26], [64614.1, 0.003], [64614.9, 0.138], [64617.5, 0.0], [64618.5, 32.199], [64648.0, 1.308], [64682.6, 0.072], [64682.8, 0.451], [64683.4, 0.108], [64684.1, 0.032]], "asks": [[64696.9, 0.273], [64699.9, 0.147], [64700.6, 0.161], [64701.3, 1.41], [64701.5, 0.087], [64718.0, 0.059], [64718.7, 0.166], [64721.3, 0.334], [64721.5, 1.697], [64736.1, 0.046], [64833.5, 0.103], [64833.6, 3.82], [64843.6, 0.024], [65339.6, 5.533], [65538.4, 0.014]]}
{"kind": "depth", "E": 1787080473973, "U": 11315356889415, "u": 11315356895147, "recv_ms": 1787080473928, "bids": [[1000.0, 35.81], [14392.6, 0.784], [14492.6, 3.416], [14592.6, 0.0], [51754.1, 0.0], [58223.3, 0.055], [62104.8, 0.004], [63692.6, 0.002], [63948.6, 4.684], [64045.7, 4.844], [64351.9, 0.0], [64352.0, 11.492], [64369.1, 4.742], [64535.4, 8.667], [64552.4, 6.428], [64609.7, 0.118], [64612.3, 0.209], [64618.5, 32.199], [64620.1, 0.013], [64630.4, 2.382], [64647.6, 0.234], [64648.3, 0.038], [64669.4, 0.002], [64670.3, 0.581], [64682.7, 0.606], [64682.9, 0.101], [64683.0, 0.1], [64683.2, 1.986], [64683.3, 0.101], [64683.4, 0.171], [64683.5, 0.073], [64683.8, 0.033], [64684.5, 1.482], [64684.8, 0.078]], "asks": [[64698.1, 0.094], [64698.5, 0.018], [64699.6, 0.047], [64699.7, 0.466], [64700.1, 0.014], [64700.3, 0.502], [64700.5, 0.108], [64700.7, 0.096], [64700.8, 0.539], [64701.0, 1.035], [64701.1, 0.752], [64701.4, 1.09], [64705.2, 0.174], [64708.7, 0.023], [64709.3, 0.556], [64713.1, 0.116], [64713.9, 0.004], [64717.7, 0.098], [64718.3, 0.044], [64720.5, 0.211], [64720.7, 0.1], [64720.8, 0.261], [64721.0, 0.132], [64721.1, 4.128], [64721.4, 0.207], [64735.8, 0.042], [64736.4, 0.052], [64834.0, 5.427], [64850.6, 0.003], [64850.9, 8.406], [64889.4, 0.01], [64889.7, 1.497], [64889.8, 4.426], [64889.9, 0.0], [65339.6, 5.533], [65692.7, 0.006], [65902.5, 3.755]]}
{"kind": "depth", "E": 1787080474075, "U": 11315356895639, "u": 11315356901757, "recv_ms": 1787080474026, "bids": [[14392.6, 1.148], [14492.6, 3.052], [58223.3, 0.055], [61457.9, 0.055], [62104.8, 0.001], [63705.6, 0.038], [63770.3, 0.006], [64045.7, 4.844], [64218.8, 0.0], [64369.1, 4.741], [64582.6, 0.005], [64630.8, 0.265], [64659.2, 1.02], [64662.8, 0.114], [64675.5, 0.464], [64681.0, 2.32], [64682.6, 0.142], [64682.8, 0.521], [64683.0, 0.2], [64683.1, 1.038], [64692.0, 0.02], [64692.1, 0.002]], "asks": [[64692.7, 12.764], [64696.4, 0.008], [64697.7, 0.104], [64697.8, 0.029], [64698.3, 0.819], [64701.0, 1.155], [64701.1, 0.892], [64701.3, 1.508], [64701.4, 1.174], [64705.1, 0.501], [64716.9, 1.288], [64719.2, 1.113], [64721.0, 0.252], [64721.3, 0.432], [64721.4, 0.291], [64721.5, 3.397], [64723.5, 0.225], [64770.4, 0.025], [65016.2, 4.486], [65339.6, 5.533], [65614.9, 0.001], [65679.6, 0.019]]}
{"kind": "depth", "E": 1787080474177, "U": 11315356901904, "u": 11315356906952, "recv_ms": 1787080474132, "bids": [[1000.0, 35.81], [14392.6, 1.498], [14492.6, 2.702], [58223.3, 0.055], [61457.9, 0.055], [62104.8, 0.004], [63657.5, 6.297], [63692.6, 0.022], [63705.6, 0.046], [63770.3, 0.014], [63771.9, 0.008], [63791.0, 42.021], [64045.7, 4.844], [64175.1, 9.802], [64369.1, 4.742], [64570.6, 0.0], [64620.4, 6.252], [64622.7, 0.01], [64624.8, 0.0], [64629.9, 0.032], [64657.4, 0.04], [64662.8, 0.184], [64663.2, 0.076], [64669.5, 0.12], [64670.3, 0.465], [64679.4, 0.384], [64680.0, 1.848], [64680.1, 0.012], [64681.5, 0.586]], "asks": [[64692.7, 12.765], [64697.9, 0.004], [64703.4, 0.312], [64708.3, 0.29], [64709.3, 0.556], [64712.4, 0.001], [64713.1, 0.001], [64713.3, 0.346], [64720.0, 3.152], [64729.9, 0.002], [64754.9, 0.113], [64757.4, 0.392], [64767.6, 0.015], [64830.5, 0.001], [65016.2, 4.487], [65033.7, 0.0], [65339.6, 5.533], [65533.8, 1.066], [65613.3, 0.764], [65663.1, 9.064], [65692.7, 0.026], [65727.8, 6.388]]}
{"kind": "depth", "E": 1787080474279, "U": 11315356907040, "u": 11315356912046, "recv_ms": 1787080474229, "bids": [[1000.0, 35.81], [14392.6, 1.862], [14492.6, 2.338], [51754.0, 0.0], [58223.3, 0.055], [61458.0, 0.076], [63596.9, 0.784], [63657.5, 7.395], [64045.7, 4.844], [64369.1, 4.742], [64609.7, 32.056], [64612.3, 0.218], [64618.5, 0.005], [64620.4, 1.649], [64629.5, 0.077], [64630.2, 0.044], [64662.6, 0.418], [64663.2, 0.176], [64665.3, 0.122], [64676.2, 0.628], [64679.9, 0.156], [64680.0, 1.694], [64692.5, 0.621], [64692.6, 8.432]], "asks": [[64692.7, 12.766], [65339.6, 5.533], [65339.7, 0.009], [65613.3, 0.772], [65614.9, 0.009], [65679.6, 0.027], [65727.8, 7.452]]}
{"kind": "depth", "E": 1787080474381, "U": 11315356912115, "u": 11315356917362, "recv_ms": 1787080474333, "bids": [[14392.6, 2.212], [14492.6, 1.988], [51754.0, 0.0], [58223.3, 0.055], [61457.9, 0.055], [62104.8, 0.001], [63592.8, 18.756], [63692.6, 0.002], [64045.7, 4.844], [64175.1, 9.179], [64563.2, 0.006], [64582.6, 0.002], [64609.7, 0.118], [64612.3, 0.209], [64614.1, 31.941], [64614.9, 0.147], [64662.7, 0.071], [64662.9, 0.241], [64663.0, 0.111], [64663.3, 0.111], [64663.4, 0.072], [64663.5, 0.073], [64664.9, 0.813]], "asks": [[64738.0, 0.007], [64770.4, 0.022], [65098.5, 0.0], [65210.2, 7.81], [65339.6, 5.533], [65469.0, 26.318], [65692.7, 0.006]]}
{"kind": "depth", "E": 1787080474585, "U": 11315356923035, "u": 11315356930130, "recv_ms": 1787080474538, "bids": [[1000.0, 35.81], [14392.6, 2.94], [14492.6, 1.26], [51754.0, 0.016], [58223.3, 0.055], [61457.9, 0.055], [62104.8, 0.001], [63692.6, 0.022], [63906.4, 1.565], [64045.7, 4.844], [64369.1, 4.742], [64496.6, 15.505], [64499.0, 2.824], [64535.4, 7.679], [64536.7, 1.484], [64552.4, 5.928], [64635.6, 1.635], [64664.0, 2.934], [64664.9, 1.146], [64692.6, 8.432]], "asks": [[64692.7, 12.84], [64698.4, 1.198], [64757.4, 0.419], [64833.6, 9.218], [64850.6, 10.412], [64850.9, 0.05], [64889.4, 3.875], [64889.7, 0.0], [64889.8, 0.0], [65163.3, 0.076], [65210.2, 8.729], [65339.6, 5.533], [65469.0, 28.148], [65533.7, 13.102], [65692.7, 0.026], [65986.5, 0.006]]}
{"kind": "depth", "E": 1787080474687, "U": 11315356930172, "u": 11315356935046, "recv_ms": 1787080474639, "bids": [[14392.6, 3.29], [14492.6, 0.91], [51754.0, 0.0], [58223.3, 0.055], [63592.8, 19.383], [64045.7, 4.844], [64175.1, 10.113], [64614.1, 0.003], [64614.9, 0.138], [64616.3, 31.938], [64617.5, 0.009], [64683.9, 0.004], [64688.2, 0.085], [64690.8, 0.233], [64691.6, 0.001], [64691.7, 0.002], [64691.8, 0.0], [64692.0, 0.0], [64692.1, 0.0], [64692.2, 0.0], [64692.3, 0.0], [64692.4, 0.002]], "asks": [[64696.9, 0.207], [64698.1, 0.094], [64698.2, 0.441], [64698.3, 0.819], [64806.4, 0.031], [64833.5, 0.127], [64843.6, 0.0], [65339.6, 5.533], [66568.8, 0.453]]}
{"kind": "depth", "E": 1787080474789, "U": 11315356935168, "u": 11315356939839, "recv_ms": 1787080474741, "bids": [[1000.0, 35.81], [14392.6, 3.64], [14492.6, 0.56], [58223.3, 0.055], [62104.8, 0.004], [63671.2, 0.0], [63692.6, 0.002], [63735.8, 1.087], [63754.6, 10.769], [63855.5, 6.224], [64045.7, 4.844], [64552.4, 1.26], [64612.3, 0.218], [64616.3, 0.0], [64676.2, 0.628], [64692.0, 0.002], [64692.4, 0.0]], "asks": [[64698.2, 0.441], [64698.3, 0.819], [64708.7, 0.023], [64833.6, 3.82], [65228.1, 0.003], [65305.8, 7.278], [65307.3, 4.58], [65339.6, 5.533], [65692.7, 0.006], [65870.1, 0.758]]}
{"kind": "depth", "E": 1787080474891, "U": 11315356940034, "u": 11315356945048, "recv_ms": 1787080474847, "bids": [[1000.0, 35.81], [14292.6, 0.126], [14392.6, 3.752], [14492.6, 0.322], [58223.3, 0.055], [61457.9, 0.055], [62104.8, 0.001], [63754.6, 11.866], [63883.9, 11.79], [63904.0, 0.118], [64045.7, 4.844], [64369.1, 4.742], [64535.4, 8.962], [64536.7, 0.404], [64552.4, 6.566], [64570.6, 0.0], [64612.3, 0.209], [64614.1, 31.941], [64614.9, 0.147], [64624.8, 0.0], [64635.6, 1.635], [64657.4, 0.04], [64675.1, 0.043], [64676.2, 0.01], [64679.1, 0.076], [64679.9, 0.002], [64680.0, 1.848], [64680.1, 0.012], [64683.7, 0.005], [64688.7, 0.086]], "asks": [[64692.7, 12.539], [64704.3, 0.158], [64711.7, 0.014], [64719.5, 11.242], [64729.9, 0.002], [64754.9, 0.131], [64767.6, 0.015], [64830.5, 0.001], [64833.5, 0.103], [64833.9, 5.399], [64843.6, 0.024], [64850.6, 0.003], [64850.9, 8.438], [64889.4, 0.01], [64889.7, 3.973], [64967.2, 0.08], [65305.8, 6.264], [65339.6, 5.533], [65711.3, 1.064], [66115.7, 0.0]]}
{"kind": "depth", "E": 1787080474993, "U": 11315356945081, "u": 11315356949434, "recv_ms": 1787080474945, "bids": [[14292.6, 0.364], [14392.6, 3.626], [14492.6, 0.21], [51754.1, 0.0], [58223.3, 0.055], [62104.8, 0.004], [63689.9, 4.235], [63692.6, 0.022], [63851.6, 7.195], [63939.0, 0.81], [64045.7, 4.844], [64367.4, 0.292], [64614.1, 0.003], [64614.9, 0.138], [64616.3, 31.938], [64635.6, 1.635], [64657.8, 0.174], [64668.3, 0.002], [64668.9, 4.116], [64669.5, 0.004], [64670.4, 2.518], [64679.8, 0.154], [64680.0, 1.694], [64684.9, 0.0], [64689.1, 0.138], [64691.7, 0.022]], "asks": [[64697.5, 0.147], [64697.6, 0.033], [64697.8, 0.006], [65339.6, 5.533], [65505.6, 6.899], [65692.7, 0.026]]}
{"kind": "depth", "E": 1787080475095, "U": 11315356949549, "u": 11315356954658, "recv_ms": 1787080475045, "bids": [[1000.0, 35.96], [14292.6, 0.602], [14392.6, 3.514], [14492.6, 0.084], [51754.0, 0.0], [58223.3, 0.055], [62104.8, 0.001], [63536.3, 0.795], [63606.4, 2.039], [63705.6, 0.038], [63744.8, 16.539], [63777.0, 5.758], [63859.9, 2.346], [63888.1, 12.397], [64045.7, 4.844], [64175.1, 9.802], [64369.1, 4.587], [64403.3, 0.079], [64681.0, 2.32]], "asks": [[64698.4, 1.175], [64705.9, 0.023], [64706.5, 0.928], [64889.4, 2.02], [64889.7, 0.0], [65031.9, 0.076], [65307.3, 6.052], [65339.6, 5.533], [65469.0, 27.385], [65679.7, 0.011], [65695.4, 4.105]]}
{"kind": "depth", "E": 1787080475197, "U": 11315356954773, "u": 11315356959724, "recv_ms": 1787080475148, "bids": [[1000.0, 35.81], [14292.6, 0.882], [14392.6, 3.318], [14492.6, 0.0], [51754.0, 0.0], [58223.3, 0.055], [61457.9, 0.055], [63692.6, 0.002], [63705.6, 0.046], [63726.3, 6.238], [63922.8, 4.688], [63938.8, 3.827], [64045.7, 4.844], [64114.4, 3.27], [64369.1, 4.587], [64576.3, 0.004], [64576.4, 3.866], [64582.6, 0.005], [64582.7, 0.0], [64582.9, 2.321], [64589.8, 0.0], [64589.9, 0.004], [64609.7, 32.063], [64616.3, 0.0], [64617.5, 0.018], [64618.5, 0.005], [64620.4, 1.649], [64620.6, 0.037], [64620.7, 0.169], [64635.6, 1.663], [64653.7, 0.411], [64666.7, 0.668], [64668.1, 0.001], [64668.6, 0.558], [64668.9, 3.559], [64676.4, 0.031], [64679.4, 0.538], [64679.8, 0.0], [64684.8, 0.174], [64685.3, 0.0], [64687.4, 0.001], [64690.3, 0.085], [64690.8, 0.001], [64691.2, 0.359], [64691.3, 0.255], [64692.6, 8.349]], "asks": [[64692.7, 12.323], [64693.1, 0.002], [64693.7, 0.002], [64696.2, 0.001], [64696.4, 0.011], [64697.5, 0.127], [64697.6, 0.01], [64697.7, 0.084], [64697.9, 0.023], [64698.0, 0.211], [64701.6, 0.373], [64703.3, 1.529], [64708.0, 0.141], [64716.5, 0.011], [64719.5, 1.242], [64736.7, 0.043], [64739.3, 1.348], [64763.0, 0.397], [64763.1, 0.046], [64770.4, 0.025], [64798.4, 1.153], [64800.5, 2.321], [64801.0, 0.09], [64828.6, 3.864], [64828.7, 0.01], [64880.9, 0.88], [64881.0, 4.394], [64891.1, 0.676], [65016.2, 4.486], [65096.6, 0.547], [65279.4, 0.001], [65339.6, 5.533], [65692.7, 0.006], [65986.5, 0.003]]}
{"kind": "depth", "E": 1787080475299, "U": 11315356959794, "u": 11315356964881, "recv_ms": 1787080475249, "bids": [[14292.6, 1.232], [14392.6, 2.968], [58223.3, 0.055], [61457.9, 0.055], [62104.8, 0.004], [63778.1, 2.663], [63935.7, 5.63], [64045.7, 4.844], [64369.1, 4.742], [64552.4, 6.435], [64570.6, 0.0], [64576.4, 3.866], [64609.7, 0.118], [64612.3, 0.209], [64616.3, 31.945], [64620.7, 0.169], [64624.8, 0.0], [64635.6, 1.649], [64653.7, 0.425], [64657.4, 0.04], [64669.0, 0.619], [64676.4, 0.649], [64684.8, 0.078], [64687.4, 0.181], [64689.5, 0.085], [64690.3, 0.001], [64690.6, 0.31], [64691.2, 0.049], [64692.6, 8.348]], "asks": [[64693.8, 0.086], [64705.3, 0.618], [64712.7, 0.714], [64729.9, 0.002], [64763.1, 0.046], [64767.6, 0.015], [64828.6, 3.864], [64830.5, 0.001], [64833.6, 9.218], [64833.9, 0.001], [64889.4, 2.404], [65016.2, 4.487], [65043.5, 0.003], [65339.6, 5.533], [65339.7, 0.008], [65342.6, 1.147], [65679.6, 0.035]]}
{"kind": "depth", "E": 1787080475401, "U": 11315356965078, "u": 11315356969295, "recv_ms": 1787080475352, "bids": [[1000.0, 35.81], [14292.6, 1.582], [14392.6, 2.618], [58223.3, 0.055], [62104.8, 0.001], [63583.2, 0.785], [63599.3, 1.278], [63647.8, 5.379], [63692.6, 0.022], [63722.2, 19.996], [63744.8, 15.442], [63754.6, 12.962], [63916.3, 27.296], [63948.6, 6.558], [64045.7, 4.844], [64110.3, 2.183], [64175.1, 10.113], [64563.2, 0.006], [64609.7, 32.063], [64614.9, 0.147], [64616.3, 0.0], [64617.5, 0.0], [64618.5, 0.005], [64635.6, 1.635], [64638.2, 0.0], [64643.4, 0.264], [64679.4, 2.418], [64679.9, 0.156]], "asks": [[64833.5, 0.127], [64843.6, 0.0], [65022.6, 0.13], [65161.3, 0.101], [65275.0, 1.554], [65339.6, 5.533], [65692.7, 0.026], [65727.8, 7.452]]}
{"kind": "depth", "E": 1787080475503, "U": 11315356969453, "u": 11315356974852, "recv_ms": 1787080475454, "bids": [[14292.6, 1.946], [14392.6, 2.254], [58223.3, 0.055], [62104.8, 0.004], [63657.5, 8.493], [63754.6, 14.058], [63900.8, 0.0], [64045.7, 4.844], [64149.1, 0.163], [64369.1, 4.742], [64496.6, 0.0], [64535.4, 0.003], [64552.4, 1.26], [64563.2, 0.005], [64609.7, 0.118], [64614.1, 31.948], [64652.6, 0.036], [64653.7, 0.411], [64656.3, 0.017], [64664.4, 1.323], [64666.7, 0.699], [64679.7, 0.166], [64679.9, 0.002]], "asks": [[64833.5, 0.103], [64833.6, 3.82], [64843.6, 0.024], [64850.9, 0.05], [64889.4, 0.01], [65339.6, 5.533], [65466.8, 0.007], [65484.8, 1.533], [65547.3, 4.229], [65727.8, 8.516]]}
{"kind": "depth", "E": 1787080475605, "U": 11315356975083, "u": 11315356979650, "recv_ms": 1787080475557, "bids": [[14292.6, 2.296], [14392.6, 1.904], [58223.3, 0.055], [61457.9, 0.055], [61458.0, 0.074], [61458.1, 0.013], [62104.8, 0.001], [63398.8, 0.645], [63692.6, 0.002], [63761.7, 14.529], [63904.7, 0.0], [64045.7, 4.844], [64496.6, 15.505], [64499.0, 0.568], [64535.4, 8.814], [64552.4, 6.499], [64582.6, 0.002], [64614.9, 0.147], [64687.4, 0.001]], "asks": [[64692.7, 12.333], [64693.2, 0.084], [64736.7, 0.001], [64738.0, 0.007], [64739.3, 1.334], [64770.4, 0.022], [64833.6, 9.218], [64850.6, 0.003], [64850.9, 7.689], [64889.4, 0.01], [64889.7, 6.898], [65305.8, 5.806], [65339.6, 5.533], [65692.7, 0.006]]}
{"kind": "depth", "E": 1787080475707, "U": 11315356979883, "u": 11315356983244, "recv_ms": 1787080475659, "bids": [[1000.0, 35.81], [14292.6, 2.66], [14392.6, 1.54], [51754.0, 0.0], [58223.3, 0.055], [63754.6, 14.175], [63897.5, 11.156], [63916.3, 29.171], [64045.7, 4.844], [64686.7, 0.298]], "asks": [[64833.5, 0.127], [64843.6, 0.0], [64850.6, 10.412], [64850.9, 0.05], [64889.4, 2.02], [64889.7, 0.0], [65339.6, 5.533], [65840.7, 1.214]]}
{"kind": "depth", "E": 1787080475809, "U": 11315356983369, "u": 11315356986489, "recv_ms": 1787080475760, "bids": [[14292.6, 3.01], [14392.6, 1.19], [34000.0, 1.146], [51754.0, 0.0], [58223.3, 0.055], [62104.8, 0.004], [63633.4, 0.0], [63644.4, 0.004], [63692.6, 0.022], [63786.9, 26.503], [63916.3, 29.64], [64045.7, 4.844], [64369.1, 4.742], [64676.2, 0.01], [64691.5, 0.023]], "asks": [[64708.7, 0.023], [64889.4, 0.01], [64889.7, 6.907], [65339.6, 5.533], [65462.5, 5.498], [65539.9, 0.267], [65692.7, 0.026]]}
{"kind": "depth", "E": 1787080475911, "U": 11315356986618, "u": 11315356990061, "recv_ms": 1787080475861, "bids": [[14292.6, 3.374], [14392.6, 0.826], [58223.3, 0.055], [61457.9, 0.055], [62104.8, 0.001], [63279.7, 0.001], [63289.4, 0.01], [63855.6, 2.582], [63916.3, 30.42], [64045.7, 4.844], [64552.4, 1.26], [64638.2, 0.014], [64653.7, 0.425], [64663.1, 0.413], [64663.4, 0.07], [64669.0, 0.001], [64676.4, 0.031], [64686.7, 0.118]], "asks": [[64692.7, 12.632], [64696.9, 0.204], [64705.3, 0.0], [64833.6, 3.82], [64889.4, 3.867], [64889.7, 0.0], [65307.3, 6.51], [65339.6, 5.533], [65824.8, 4.99]]}
{"kind": "depth", "E": 1787080476013, "U": 11315356990174, "u": 11315356994731, "recv_ms": 1787080475963, "bids": [[1000.0, 35.81], [14192.6, 0.014], [14292.6, 3.696], [14392.6, 0.49], [51754.1, 0.0], [58223.3, 0.055], [61458.1, 0.011], [62104.8, 0.004], [63625.2, 0.894], [63692.6, 0.002], [63744.8, 14.345], [63791.0, 41.833], [64045.7, 4.844], [64609.7, 32.14], [64612.3, 0.218], [64614.1, 0.003], [64614.9, 0.138], [64618.5, 0.005], [64689.5, 0.001]], "asks": [[64703.3, 1.449], [64708.0, 0.221], [64833.5, 0.103], [64843.6, 0.024], [65339.6, 5.533], [65630.7, 13.088], [65692.7, 0.006]]}
{"kind": "depth", "E": 1787080476115, "U": 11315356994812, "u": 11315357000820, "recv_ms": 1787080476131, "bids": [[14192.6, 0.182], [14292.6, 3.724], [14392.6, 0.294], [51754.0, 0.002], [58223.3, 0.055], [63615.4, 4.709], [63634.9, 4.236], [63754.6, 15.272], [63851.6, 8.289], [64045.7, 4.844], [64369.1, 4.732], [64535.4, 7.786], [64552.4, 5.979], [64609.7, 32.14], [64612.3, 0.218], [64616.3, 0.0], [64617.5, 0.009], [64670.0, 1.413], [64681.0, 2.32], [64691.5, 0.0], [64691.9, 0.102]], "asks": [[64697.6, 0.011], [64701.6, 0.372], [64833.5, 0.127], [64833.6, 9.218], [64843.6, 0.0], [64850.6, 10.412], [64889.4, 3.722], [65339.6, 5.533], [65396.3, 2.439], [65630.7, 14.153]]}
{"kind": "depth", "E": 1787080476217, "U": 11315357000901, "u": 11315357005920, "recv_ms": 1787080476168, "bids": [[14192.6, 0.406], [14292.6, 3.612], [14392.6, 0.182], [51754.0, 0.0], [58223.3, 0.055], [61457.9, 0.055], [61458.1, 0.009], [62104.8, 0.001], [63583.2, 1.57], [63692.6, 0.022], [64045.7, 4.844], [64369.1, 4.731], [64499.0, 2.824], [64535.4, 7.793], [64536.7, 0.404], [64552.4, 5.982], [64582.6, 0.005], [64609.7, 0.118], [64612.3, 0.209], [64614.1, 32.025], [64616.1, 1.455], [64691.6, 0.023], [64691.9, 0.021]], "asks": [[64692.7, 12.633], [64697.6, 0.01], [64770.4, 0.025], [64833.6, 9.218], [64850.6, 10.412], [64886.8, 0.014], [64889.4, 3.711], [65016.2, 4.487], [65279.2, 17.588], [65339.6, 5.533], [65618.3, 0.086], [65692.7, 0.026], [65750.1, 3.191], [65888.0, 8.101]]}
{"kind": "depth", "E": 1787080476319, "U": 11315357005945, "u": 11315357010613, "recv_ms": 1787080476272, "bids": [[1000.0, 35.81], [14192.6, 0.658], [14292.6, 3.486], [14392.6, 0.056], [51754.0, 0.0], [58223.3, 0.055], [62104.8, 0.004], [64045.7, 4.844], [64369.1, 4.732], [64552.4, 1.26], [64614.1, 0.003], [64616.3, 32.022], [64668.4, 0.002], [64669.7, 0.081]], "asks": [[64833.6, 3.82], [65274.9, 0.918], [65339.6, 5.535], [65511.3, 1.081]]}
{"kind": "depth", "E": 1787080476421, "U": 11315357010651, "u": 11315357014662, "recv_ms": 1787080476372, "bids": [[14192.6, 0.966], [14292.6, 3.234], [14392.6, 0.0], [58223.3, 0.055], [61457.9, 0.055], [62104.8, 0.001], [63398.8, 0.648], [63625.2, 1.993], [63647.8, 4.281], [63680.1, 5.489], [63692.6, 0.002], [63744.8, 13.248], [64045.7, 4.844], [64369.1, 4.732], [64552.4, 5.928], [64563.2, 0.005], [64635.7, 0.292], [64638.2, 0.0], [64653.7, 0.411], [64667.9, 0.557], [64668.6, 0.001], [64669.0, 0.619], [64669.4, 0.118], [64670.4, 2.402], [64676.3, 1.249], [64679.7, 0.012], [64680.1, 0.012], [64681.5, 0.586], [64687.3, 0.809], [64689.7, 0.084], [64692.0, 0.0], [64692.1, 0.096], [64692.2, 0.002], [64692.6, 8.333]], "asks": [[64692.7, 12.623], [64693.2, 0.0], [64693.4, 0.084], [64705.2, 0.792], [64708.1, 0.001], [64709.3, 0.556], [64709.4, 0.915], [64709.8, 0.009], [64710.3, 0.141], [64710.6, 0.0], [64712.2, 2.333], [64713.1, 0.116], [64713.3, 0.231], [64833.6, 9.218], [64889.4, 3.877], [65279.2, 17.359], [65339.6, 5.533], [65397.9, 5.489], [65452.5, 2.779], [65598.4, 17.715], [65630.7, 13.088], [65692.7, 0.006], [65727.8, 7.452], [65760.1, 1.745]]}
{"kind": "depth", "E": 1787080476523, "U": 11315357014685, "u": 11315357022130, "recv_ms": 1787080476476, "bids": [[1000.0, 35.81], [14192.6, 1.316], [14292.6, 2.884], [58223.3, 0.055], [61457.9, 0.055], [62104.8, 0.004], [63398.8, 0.645], [63692.6, 0.022], [64045.7, 4.844], [64653.7, 0.425], [64676.3, 0.631], [64678.1, 0.381], [64678.4, 0.137], [64679.7, 0.166], [64687.3, 0.629], [64689.1, 0.054], [64689.7, 0.0], [64692.6, 8.202]], "asks": [[64692.7, 12.635], [64693.0, 0.104], [64696.4, 0.008], [64697.7, 0.0], [64699.0, 1.286], [64701.6, 0.021], [64703.0, 0.901], [65339.6, 5.533], [65692.7, 0.026], [65889.5, 2.952]]}
{"kind": "depth", "E": 1787080476625, "U": 11315357022292, "u": 11315357028963, "recv_ms": 1787080476575, "bids": [[1000.0, 35.81], [14192.6, 1.666], [14292.6, 2.534], [51754.0, 0.0], [58223.3, 0.055], [61458.0, 0.072], [61458.1, 0.011], [63657.5, 9.591], [63754.6, 16.368], [64045.7, 4.844], [64616.3, 0.0], [64618.5, 32.027], [64638.2, 0.014], [64690.6, 0.0]], "asks": [[64785.6, 1.255], [65274.9, 1.147], [65281.6, 0.012], [65339.6, 5.533], [65505.6, 6.671], [65630.7, 14.153]]}
{"kind": "depth", "E": 1787080476727, "U": 11315357029006, "u": 11315357038004, "recv_ms": 1787080476678, "bids": [[14192.6, 2.03], [14292.6, 2.17], [58223.3, 0.055], [61457.9, 0.055], [62104.8, 0.001], [63689.9, 5.333], [63883.9, 12.142], [64045.7, 4.844], [64369.1, 4.742], [64609.7, 0.118], [64612.3, 0.209], [64617.5, 0.0], [64618.5, 32.027], [64669.0, 0.001], [64687.9, 0.002], [64688.6, 0.002], [64691.5, 0.047], [64692.2, 0.047], [64692.3, 0.002]], "asks": [[64692.7, 13.437], [64696.1, 0.102], [64697.0, 0.016], [64705.2, 0.174], [64712.7, 0.096], [64714.7, 3.414], [64715.7, 10.226], [64801.0, 0.004], [64889.4, 3.712], [65339.6, 5.533], [65462.5, 6.413], [65501.4, 14.024], [65727.8, 8.516], [65888.2, 1.963], [66093.0, 1.296]]}
{"kind": "depth", "E": 1787080476829, "U": 11315357038204, "u": 11315357049303, "recv_ms": 1787080476779, "bids": [[1000.0, 35.81], [14192.6, 2.38], [14292.6, 1.82], [58223.3, 0.055], [62104.8, 0.004], [63518.5, 0.788], [63692.6, 0.002], [63841.7, 1.564], [63867.0, 0.052], [63913.0, 3.92], [64045.7, 4.844], [64142.7, 1.323], [64562.1, 1.092], [64570.6, 0.0], [64609.7, 0.118], [64612.3, 0.218], [64616.3, 32.022], [64618.5, 0.005], [64624.8, 0.0], [64657.4, 0.04], [64676.2, 0.01], [64685.4, 0.094], [64688.7, 0.002]], "asks": [[64708.7, 0.023], [64729.8, 0.006], [64767.6, 0.015], [64806.4, 0.146], [64830.4, 1.208], [64889.4, 3.608], [64889.6, 1.869], [64889.7, 0.0], [64891.1, 0.0], [65275.0, 2.625], [65339.6, 5.533], [65446.3, 0.854], [65692.7, 0.006]]}
{"kind": "depth", "E": 1787080476931, "U": 11315357049685, "u": 11315357058260, "recv_ms": 1787080476882, "bids": [[1000.0, 35.81], [14192.6, 2.744], [14292.6, 1.456], [58223.3, 0.055], [62104.8, 0.001], [62104.9, 0.001], [63398.8, 0.642], [63587.0, 1.066], [63774.0, 2.142], [64045.7, 4.844], [64582.6, 0.002], [64609.7, 32.14], [64612.3, 0.218], [64614.9, 0.138], [64616.3, 0.0], [64617.5, 0.009]], "asks": [[64738.0, 0.007], [64770.4, 0.022], [64889.6, 0.019], [65339.6, 5.533], [65408.6, 7.406], [65505.6, 6.442], [65620.7, 10.655], [65685.4, 7.452]]}
{"kind": "depth", "E": 1787080477033, "U": 11315357058459, "u": 11315357065689, "recv_ms": 1787080476984, "bids": [[14192.6, 3.108], [14292.6, 1.092], [51754.1, 0.0], [58223.3, 0.055], [62104.8, 0.004], [63647.8, 3.182], [63692.6, 0.022], [63705.2, 0.035], [63922.8, 5.626], [64045.7, 4.844], [64369.1, 4.732], [64458.4, 0.005], [64486.5, 0.177], [64570.5, 0.525], [64609.7, 0.118], [64612.3, 0.209], [64616.3, 32.022], [64624.8, 0.168], [64657.4, 0.113], [64660.8, 1.152], [64667.9, 0.0], [64668.6, 0.558], [64669.4, 0.002], [64670.1, 1.031], [64674.6, 0.341]], "asks": [[64693.0, 0.085], [64705.8, 0.023], [64706.4, 0.007], [64728.3, 0.02], [64729.8, 0.078], [64767.6, 0.182], [64830.4, 1.486], [64889.4, 0.01], [64889.7, 6.87], [65339.6, 5.533], [65404.3, 3.515], [65540.3, 0.003], [65692.7, 0.026], [65717.7, 0.426]]}
{"kind": "depth", "E": 1787080477135, "U": 11315357065773, "u": 11315357071683, "recv_ms": 1787080477088, "bids": [[1000.0, 35.81], [14192.6, 3.458], [14292.6, 0.742], [58223.3, 0.055], [61457.9, 0.055], [63398.8, 0.642], [63579.9, 1.881], [63705.6, 0.036], [63851.6, 9.227], [64045.7, 4.844], [64570.5, 0.245], [64576.4, 0.002], [64576.5, 4.867], [64582.9, 0.002], [64583.1, 2.319], [64620.7, 0.169], [64624.8, 0.0], [64657.4, 0.04], [64666.7, 0.668], [64676.4, 0.032], [64679.6, 0.396], [64679.7, 0.012], [64681.0, 2.32], [64687.4, 0.181], [64689.5, 0.085], [64690.6, 0.31], [64692.6, 8.166]], "asks": [[64692.7, 13.705], [64699.9, 0.052], [64700.6, 0.162], [64705.4, 0.101], [64717.4, 1.231], [64719.3, 0.315], [64729.8, 0.006], [64763.1, 0.046], [64767.6, 0.015], [64800.5, 0.002], [64801.3, 2.532], [64828.4, 3.866], [64828.6, 0.0], [64830.4, 1.208], [64889.4, 1.763], [64889.7, 0.0], [65339.6, 5.533], [65408.6, 7.177], [65469.0, 28.911], [65630.7, 15.218], [65679.6, 0.025], [65695.4, 5.169]]}
{"kind": "depth", "E": 1787080477237, "U": 11315357071749, "u": 11315357076504, "recv_ms": 1787080477188, "bids": [[1000.0, 35.81], [14192.6, 3.724], [14292.6, 0.434], [14592.6, 0.042], [51754.0, 0.0], [58223.3, 0.055], [61458.1, 0.009], [62104.8, 0.001], [63657.5, 10.689], [63692.6, 0.002], [63705.6, 0.046], [63986.0, 0.701], [64045.7, 4.844], [64536.7, 1.501], [64552.4, 1.26], [64616.1, 0.001], [64616.4, 6.236]], "asks": [[64692.7, 13.658], [64806.3, 0.329], [64833.6, 3.82], [65016.2, 4.486], [65339.6, 5.533], [65533.8, 2.132], [65679.6, 0.035], [65692.7, 0.006], [65727.8, 9.58]]}
{"kind": "depth", "E": 1787080477339, "U": 11315357076616, "u": 11315357081295, "recv_ms": 1787080477290, "bids": [[14192.6, 3.696], [14292.6, 0.266], [14592.6, 0.238], [58223.3, 0.055], [61457.9, 0.055], [62104.8, 0.004], [63308.8, 0.0], [64045.7, 4.844], [64175.1, 10.113], [64369.1, 4.742], [64535.4, 0.003], [64536.7, 0.404], [64563.2, 0.006], [64687.4, 0.001], [64690.6, 0.0], [64692.6, 8.18]], "asks": [[64698.2, 0.465], [64833.5, 0.103], [64843.6, 0.024], [64850.6, 0.003], [65339.6, 5.533], [65404.3, 3.744]]}
{"kind": "depth", "E": 1787080477441, "U": 11315357081393, "u": 11315357085552, "recv_ms": 1787080477391, "bids": [[1000.0, 35.81], [14192.6, 3.57], [14292.6, 0.154], [14592.6, 0.476], [51754.0, 0.0], [58223.3, 0.055], [61457.9, 0.055], [61458.0, 0.07], [61458.1, 0.011], [62104.8, 0.001], [63692.6, 0.022], [63855.7, 14.307], [63987.5, 7.093], [64045.7, 4.844], [64496.6, 15.505], [64535.4, 9.13], [64552.4, 6.644], [64563.2, 0.005], [64635.6, 1.649], [64666.7, 0.698], [64669.1, 0.62], [64670.4, 2.417], [64673.1, 0.003], [64673.7, 1.036], [64676.5, 0.618], [64679.5, 0.618], [64679.6, 0.242], [64680.0, 1.679], [64687.3, 0.629], [64692.6, 8.19]], "asks": [[64698.2, 0.441], [64705.4, 0.719], [64712.7, 0.714], [64721.9, 0.155], [64722.3, 1.119], [64833.9, 5.356], [64850.9, 8.233], [64889.4, 0.01], [64889.7, 6.921], [65016.2, 4.487], [65339.6, 5.533], [65692.7, 0.026], [65888.2, 1.205]]}
{"kind": "depth", "E": 1787080477543, "U": 11315357085672, "u": 11315357089846, "recv_ms": 1787080477494, "bids": [[1000.0, 35.81], [14192.6, 3.458], [14292.6, 0.028], [14592.6, 0.714], [58223.3, 0.055], [61457.9, 0.055], [63680.1, 4.392], [63855.7, 13.994], [64045.7, 4.844], [64369.1, 4.732], [64666.5, 0.756], [64667.3, 0.023], [64676.5, 0.0], [64679.4, 2.572], [64679.5, 0.464], [64689.6, 0.001], [64690.1, 0.004], [64692.6, 8.22]], "asks": [[64692.7, 13.74], [64705.2, 0.269], [64705.4, 0.624], [64712.2, 2.376], [64850.6, 10.412], [64850.9, 0.05], [64883.0, 0.391], [64889.4, 2.006], [64889.7, 0.0], [65339.6, 5.533], [65620.7, 9.591], [65685.4, 6.389]]}
{"kind": "depth", "E": 1787080477645, "U": 11315357089962, "u": 11315357094498, "recv_ms": 1787080477596, "bids": [[14192.6, 3.164], [14292.6, 0.0], [14592.6, 1.036], [58223.3, 0.057], [61448.5, 0.056], [61457.9, 0.055], [62104.8, 0.004], [63398.8, 0.639], [63786.9, 26.691], [63851.5, 2.971], [63855.7, 12.9], [64045.7, 4.844], [64609.7, 32.195], [64612.3, 0.218], [64616.3, 0.0], [64616.4, 0.003], [64617.5, 0.0], [64618.5, 0.005], [64692.6, 8.22]], "asks": [[64696.9, 0.14], [64698.9, 0.01], [64700.0, 1.737], [64883.0, 0.067], [64889.4, 2.022], [65339.6, 5.533]]}
{"kind": "depth", "E": 1787080477747, "U": 11315357094535, "u": 11315357098615, "recv_ms": 1787080477698, "bids": [[1000.0, 35.81], [14192.6, 2.8], [14592.6, 1.4], [58223.3, 0.055], [62104.8, 0.001], [63398.8, 0.642], [63689.9, 6.43], [63692.6, 0.002], [63744.8, 12.151], [64045.7, 4.844], [64149.1, 0.098], [64552.4, 1.26], [64570.5, 0.245], [64624.8, 0.0], [64627.9, 0.036], [64657.4, 0.04], [64661.8, 0.0]], "asks": [[64692.7, 13.747], [64729.8, 0.006], [64757.4, 0.42], [64767.6, 0.015], [64830.4, 1.208], [64833.9, 0.001], [65339.6, 5.533], [65630.7, 16.282], [65692.7, 0.006], [65695.4, 6.232]]}
{"kind": "depth", "E": 1787080477849, "U": 11315357098755, "u": 11315357102484, "recv_ms": 1787080477802, "bids": [[1000.0, 35.81], [14192.6, 2.45], [14592.6, 1.75], [51754.0, 0.0], [58223.3, 0.055], [61457.9, 0.055], [62104.8, 0.004], [63851.5, 4.378], [64045.7, 4.844], [64369.1, 4.742], [64530.8, 0.003], [64552.4, 6.56], [64676.2, 0.01]], "asks": [[64692.7, 13.691], [64693.0, 0.001], [64698.9, 0.002], [64699.6, 0.055], [64708.7, 0.023], [64833.9, 5.397], [64854.5, 0.009], [64883.0, 0.472], [64889.4, 0.01], [64889.7, 4.125], [65339.6, 5.533], [65410.6, 0.233], [65540.2, 1.067], [65570.3, 11.404]]}
{"kind": "depth", "E": 1787080477951, "U": 11315357102652, "u": 11315357107131, "recv_ms": 1787080477901, "bids": [[14192.6, 2.086], [14592.6, 2.114], [58223.3, 0.055], [62104.8, 0.001], [62104.9, 0.0], [63692.6, 0.022], [64045.7, 4.844], [64552.4, 1.26], [64679.2, 0.154], [64679.4, 2.418]], "asks": [[64833.9, 0.001], [65339.6, 5.533], [65566.1, 5.807], [65692.7, 0.026]]}
{"kind": "depth", "E": 1787080478053, "U": 11315357107191, "u": 11315357112338, "recv_ms": 1787080478005, "bids": [[1000.0, 35.81], [14192.6, 1.736], [14592.6, 2.464], [51754.1, 0.0], [58223.3, 0.055], [61448.5, 0.05], [63402.9, 2.559], [63474.7, 0.0], [63546.6, 0.036], [63618.5, 0.5], [63690.4, 0.0], [63754.6, 17.465], [63762.3, 0.0], [63834.2, 0.0], [63859.2, 0.783], [63906.1, 0.0], [63977.9, 1.64], [64045.7, 4.844], [64049.8, 3.195], [64183.0, 0.02], [64552.4, 6.565], [64668.3, 0.559], [64668.6, 0.001], [64672.8, 0.381], [64673.5, 0.931], [64674.3, 0.0], [64681.0, 2.32], [64687.3, 0.809]], "asks": [[64696.9, 0.135], [64709.6, 0.0], [64710.7, 0.057], [64711.1, 0.002], [64711.9, 0.541], [64712.8, 0.352], [64713.1, 0.001], [64713.7, 0.011], [64833.6, 9.218], [64883.0, 0.067], [64889.4, 2.006], [64889.7, 0.0], [65339.6, 5.533], [65343.8, 0.0], [65404.3, 3.973], [65415.7, 0.006], [65487.5, 0.002], [65533.8, 3.199], [65559.4, 1.524], [65631.3, 0.0], [65703.2, 0.0], [65775.1, 0.0], [65847.0, 0.0], [65864.5, 0.0], [65918.9, 0.641], [65990.7, 0.0]]}
{"kind": "depth", "E": 1787080478155, "U": 11315357112348, "u": 11315357118059, "recv_ms": 1787080478106, "bids": [[1000.0, 35.81], [14192.6, 1.372], [14592.6, 2.828], [51754.0, 0.0], [58223.3, 0.055], [61457.9, 0.055], [61458.0, 0.068], [61458.1, 0.013], [62104.8, 0.004], [63692.6, 0.002], [63705.6, 0.046], [64045.7, 4.844], [64369.1, 4.732], [64614.9, 0.138], [64635.6, 1.635], [64673.0, 5.444], [64673.7, 1.791], [64686.7, 0.118], [64687.3, 0.629], [64691.5, 0.089], [64692.6, 8.2]], "asks": [[64698.3, 0.819], [64700.6, 0.161], [64712.8, 0.237], [64713.1, 0.116], [64738.0, 0.007], [64833.5, 0.127], [64843.6, 0.0], [65339.6, 5.533], [65679.6, 0.026], [65692.7, 0.006]]}
{"kind": "depth", "E": 1787080478257, "U": 11315357118081, "u": 11315357123000, "recv_ms": 1787080478208, "bids": [[14192.6, 1.022], [14592.6, 3.178], [51754.0, 0.006], [58223.3, 0.055], [62104.8, 0.001], [63855.7, 12.587], [64045.7, 4.844], [64536.7, 1.701], [64609.7, 0.118], [64612.3, 0.209], [64618.5, 32.082], [64620.4, 6.235], [64638.2, 0.0], [64674.6, 0.173], [64687.4, 0.181], [64690.6, 0.31], [64692.6, 8.256]], "asks": [[64692.9, 0.001], [64694.6, 0.311], [64727.9, 0.944], [64729.5, 0.003], [64730.2, 3.457], [64861.8, 29.414], [64862.0, 0.25], [64891.1, 0.676], [65339.6, 5.533], [65679.7, 0.02]]}
{"kind": "depth", "E": 1787080478359, "U": 11315357123131, "u": 11315357128296, "recv_ms": 1787080478312, "bids": [[1000.0, 35.81], [14192.6, 0.658], [14592.6, 3.542], [51754.0, 0.0], [58223.3, 0.055], [61457.9, 0.055], [62104.8, 0.004], [63692.6, 0.022], [63858.7, 3.692], [64045.7, 4.844], [64369.1, 4.731], [64498.5, 0.005], [64552.4, 1.26], [64563.2, 0.006], [64570.5, 0.245], [64582.6, 0.005], [64624.8, 0.0], [64657.4, 0.04], [64659.7, 0.03], [64659.8, 0.453], [64659.9, 0.005], [64663.2, 0.176], [64663.3, 0.111], [64692.6, 8.253]], "asks": [[64729.8, 0.006], [64767.6, 0.015], [64770.4, 0.025], [64830.4, 1.208], [64833.6, 3.82], [65285.5, 0.0], [65339.6, 5.533], [65501.4, 14.252], [65620.7, 8.525], [65692.7, 0.026], [65857.2, 6.305]]}
{"kind": "depth", "E": 1787080478563, "U": 11315357134009, "u": 11315357138952, "recv_ms": 1787080478520, "bids": [[14192.6, 0.238], [14492.6, 0.294], [14592.6, 3.668], [58223.3, 0.055], [61458.0, 0.07], [63692.6, 0.002], [63851.6, 10.244], [64045.7, 4.844], [64552.4, 1.26], [64656.3, 0.003], [64679.2, 0.0], [64679.6, 0.242], [64687.4, 0.001]], "asks": [[64721.6, 1.359], [64721.7, 0.157], [64833.6, 3.82], [65312.2, 0.686], [65339.6, 5.533], [65692.7, 0.006]]}
{"kind": "depth", "E": 1787080478665, "U": 11315357139043, "u": 11315357143058, "recv_ms": 1787080478618, "bids": [[1000.0, 35.81], [14192.6, 0.112], [14492.6, 0.532], [14592.6, 3.556], [51754.0, 0.0], [58223.3, 0.055], [62104.8, 0.004], [64045.7, 4.844], [64535.4, 0.003], [64535.5, 8.875], [64536.7, 0.404], [64552.4, 6.565], [64612.3, 0.218], [64614.9, 0.147], [64616.3, 32.169], [64618.5, 0.005], [64620.4, 1.649], [64679.5, 0.618], [64679.6, 0.242]], "asks": [[64693.0, 0.085], [64833.6, 9.218], [64850.6, 10.412], [64889.4, 2.088], [65280.9, 0.498], [65281.2, 1.382], [65339.6, 5.533], [65459.0, 1.587], [65501.4, 14.481], [65630.7, 17.347]]}
{"kind": "depth", "E": 1787080478767, "U": 11315357143095, "u": 11315357147687, "recv_ms": 1787080478717, "bids": [[1000.0, 35.81], [14192.6, 0.0], [14492.6, 0.77], [14592.6, 3.43], [58223.3, 0.055], [61457.9, 0.055], [62104.8, 0.001], [63692.6, 0.022], [63986.0, 0.0], [64045.7, 4.844], [64369.1, 4.732], [64612.3, 0.209], [64614.9, 0.138], [64616.3, 0.0], [64617.5, 0.0], [64618.5, 32.174], [64692.6, 8.254]], "asks": [[64721.7, 0.003], [64833.5, 0.127], [64843.6, 0.0], [65275.0, 2.854], [65313.7, 1.013], [65339.6, 5.533], [65692.7, 0.026]]}
{"kind": "depth", "E": 1787080478869, "U": 11315357147864, "u": 11315357152129, "recv_ms": 1787080478819, "bids": [[14492.6, 1.12], [14592.6, 3.08], [58223.3, 0.055], [62104.8, 0.004], [63615.4, 3.61], [63744.8, 11.054], [63945.5, 0.469], [64045.7, 4.844], [64612.3, 0.209], [64614.1, 32.172], [64614.9, 0.147], [64618.5, 0.005], [64653.7, 0.411], [64669.2, 0.001], [64670.1, 0.915], [64671.0, 0.121], [64672.8, 0.381], [64673.5, 0.005], [64673.6, 1.672], [64674.3, 0.0], [64676.2, 0.01], [64680.1, 0.012], [64681.5, 0.586], [64687.4, 0.181], [64690.6, 0.0]], "asks": [[64698.9, 0.465], [64699.7, 0.003], [64708.1, 0.001], [64708.7, 0.023], [64709.3, 0.556], [64710.3, 0.141], [64711.1, 0.002], [64711.9, 0.541], [64713.1, 0.001], [64713.8, 0.123], [64721.8, 0.282], [65339.6, 5.533], [65469.0, 29.52], [65750.1, 2.128]]}
{"kind": "depth", "E": 1787080479073, "U": 11315357156698, "u": 11315357161243, "recv_ms": 1787080479026, "bids": [[1000.0, 35.81], [14492.6, 1.834], [14592.6, 2.366], [51754.1, 0.0], [58223.3, 0.055], [61457.9, 0.061], [62104.8, 0.001], [63292.7, 1.352], [63625.2, 3.092], [63754.6, 18.562], [63987.5, 7.794], [64045.7, 4.844], [64149.1, 0.074], [64369.1, 4.742], [64614.1, 0.003], [64614.9, 0.138], [64618.5, 32.174], [64670.2, 0.119], [64671.0, 0.005], [64681.0, 2.32]], "asks": [[64721.8, 0.436], [64721.9, 0.001], [65281.3, 1.08], [65339.6, 5.533], [65638.0, 17.732], [65760.1, 2.808], [65866.8, 1.518]]}
{"kind": "depth", "E": 1787080479175, "U": 11315357161359, "u": 11315357166138, "recv_ms": 1787080479127, "bids": [[14492.6, 2.198], [14592.6, 2.002], [58223.3, 0.055], [61457.9, 0.061], [61458.0, 0.072], [62104.8, 0.004], [63438.3, 0.004], [63692.6, 0.022], [63705.6, 0.046], [64045.7, 4.844], [64552.4, 6.565], [64614.1, 0.003], [64614.9, 0.147], [64618.5, 32.359], [64638.2, 0.028], [64644.0, 2.134], [64652.3, 2.132], [64660.6, 2.131], [64666.7, 0.668], [64669.1, 0.002], [64676.6, 0.236], [64684.8, 0.092], [64687.3, 0.629], [64690.9, 0.0], [64691.6, 0.001], [64691.7, 0.045], [64691.9, 0.002], [64692.6, 8.136]], "asks": [[64692.7, 13.447], [64694.5, 0.005], [64695.9, 0.021], [64697.9, 0.004], [64698.0, 0.188], [64698.3, 0.86], [64698.9, 0.002], [64699.6, 0.055], [64700.9, 0.089], [64705.4, 0.006], [64712.7, 0.096], [64721.8, 0.282], [64721.9, 0.001], [64722.0, 0.626], [64739.3, 1.376], [64793.8, 3.21], [64793.9, 2.386], [64802.1, 2.142], [64802.2, 0.003], [64810.4, 2.125], [64810.5, 0.0], [64833.6, 9.218], [65339.6, 5.533], [65679.7, 0.009], [65692.7, 0.026], [65986.5, 0.006]]}
{"kind": "depth", "E": 1787080479379, "U": 11315357171230, "u": 11315357176897, "recv_ms": 1787080479329, "bids": [[1000.0, 35.81], [14492.6, 2.912], [14592.6, 1.288], [58223.3, 0.055], [62104.8, 0.004], [63398.8, 0.645], [63692.6, 0.002], [63899.3, 0.0], [64045.6, 0.001], [64045.7, 4.844], [64114.5, 4.052], [64369.1, 4.742], [64552.4, 1.26], [64563.2, 0.005], [64582.6, 0.005], [64614.9, 0.135], [64687.4, 0.001], [64688.6, 0.086], [64689.5, 0.001], [64689.9, 0.001], [64690.6, 0.0]], "asks": [[64692.7, 13.54], [64698.2, 0.441], [64738.0, 0.007], [64770.4, 0.022], [64833.5, 0.103], [64833.6, 3.82], [64843.6, 0.024], [65275.0, 3.924], [65339.6, 5.533], [65602.7, 57.884], [65692.7, 0.006], [66418.9, 0.007]]}
{"kind": "depth", "E": 1787080479481, "U": 11315357177013, "u": 11315357183124, "recv_ms": 1787080479432, "bids": [[14492.6, 3.262], [14592.6, 0.938], [58223.3, 0.055], [61448.5, 0.038], [61457.9, 0.061], [63900.9, 0.059], [64045.7, 4.846], [64369.1, 4.742], [64496.6, 0.0], [64499.0, 0.568], [64535.5, 0.001], [64536.7, 0.404], [64611.9, 0.004], [64612.0, 0.374], [64612.3, 0.218], [64618.5, 0.005], [64638.2, 0.0], [64654.6, 0.245], [64666.7, 0.699], [64669.1, 0.62], [64676.4, 0.65], [64679.5, 0.464], [64679.6, 0.396], [64689.4, 0.005], [64692.6, 8.144]], "asks": [[64705.3, 0.618], [64712.7, 0.714], [64850.6, 0.003], [64883.0, 0.386], [64889.4, 0.01], [65016.2, 4.487], [65281.2, 1.152], [65339.6, 5.533]]}
{"kind": "depth", "E": 1787080479583, "U": 11315357183133, "u": 11315357189714, "recv_ms": 1787080479537, "bids": [[1000.0, 35.81], [14492.6, 3.626], [14592.6, 0.574], [58223.3, 0.055], [62104.8, 0.001], [63692.6, 0.022], [63735.9, 1.556], [63795.2, 0.79], [63913.0, 2.983], [64045.7, 4.844], [64496.6, 15.505], [64499.0, 2.824], [64535.5, 8.596], [64552.4, 6.432], [64616.3, 32.354], [64638.2, 0.014], [64667.9, 0.557], [64668.3, 0.002], [64669.4, 0.118], [64670.2, 0.003], [64672.8, 1.307], [64673.6, 0.746], [64679.2, 0.154], [64679.6, 0.242], [64680.1, 0.012], [64681.5, 0.586], [64682.3, 0.337]], "asks": [[64698.9, 0.473], [64699.6, 0.047], [64699.7, 0.003], [64708.1, 0.001], [64709.3, 0.556], [64710.3, 0.141], [64711.1, 0.543], [64711.9, 0.0], [64712.2, 2.376], [64713.1, 0.116], [64713.8, 0.008], [64833.6, 9.218], [64850.6, 10.412], [64889.4, 2.489], [65339.6, 5.533], [65692.7, 0.026], [65694.1, 0.0], [65796.8, 1.818]]}
{"kind": "depth", "E": 1787080479685, "U": 11315357189832, "u": 11315357195200, "recv_ms": 1787080479636, "bids": [[1000.0, 35.81], [14392.6, 0.112], [14492.6, 3.752], [14592.6, 0.336], [58223.3, 0.055], [62104.8, 0.004], [63826.4, 5.394], [63883.9, 12.924], [64045.7, 4.844], [64110.3, 3.273], [64369.1, 4.742], [64612.3, 0.209], [64617.5, 0.009], [64671.0, 0.005], [64680.5, 0.002], [64680.6, 0.081], [64685.0, 0.007], [64688.6, 0.002], [64691.0, 0.03], [64691.2, 0.069], [64691.3, 0.232], [64691.7, 0.002], [64692.0, 0.0]], "asks": [[64698.9, 0.473], [64699.7, 0.003], [64707.8, 0.042], [64717.7, 0.058], [64883.0, 0.067], [65339.6, 5.533], [66412.0, 0.137]]}
{"kind": "depth", "E": 1787080479787, "U": 11315357195345, "u": 11315357200282, "recv_ms": 1787080479738, "bids": [[14392.6, 0.35], [14492.6, 3.64], [14592.6, 0.21], [58223.3, 0.055], [61458.1, 0.009], [62104.8, 0.001], [63692.6, 0.002], [63754.6, 19.658], [63841.8, 3.917], [63922.8, 6.563], [63985.1, 1.638], [64045.7, 4.844], [64057.1, 0.006], [64059.2, 2.009], [64616.3, 0.0], [64618.5, 32.359]], "asks": [[64698.9, 0.465], [64699.7, 0.011], [64833.5, 0.127], [64843.6, 0.0], [65275.0, 4.154], [65339.6, 5.533], [65505.6, 5.872], [65692.7, 0.006]]}
{"kind": "depth", "E": 1787080479889, "U": 11315357200407, "u": 11315357206489, "recv_ms": 1787080479841, "bids": [[1000.0, 35.81], [14392.6, 0.588], [14492.6, 3.514], [14592.6, 0.098], [58223.3, 0.055], [64058.6, 2.689], [64552.4, 1.26], [64617.5, 0.0], [64629.5, 0.045], [64629.9, 0.0], [64630.2, 0.012], [64630.4, 2.35], [64630.8, 0.233], [64635.6, 1.649], [64647.6, 0.202], [64648.0, 1.276], [64648.3, 0.006], [64648.5, 0.141], [64648.9, 0.0], [64662.6, 0.348], [64662.7, 0.001], [64662.8, 0.044], [64662.9, 0.141], [64663.0, 0.011], [64663.1, 0.313], [64663.2, 0.006], [64663.3, 0.011], [64663.4, 0.0], [64663.5, 0.003], [64664.9, 1.046], [64665.3, 0.022], [64676.2, 0.01], [64682.6, 0.002], [64682.7, 0.536], [64682.8, 0.311], [64682.9, 0.001], [64683.0, 0.0], [64683.1, 0.938], [64683.2, 1.816], [64683.3, 0.001], [64683.4, 0.001], [64683.5, 0.103], [64683.7, 0.105], [64683.8, 0.001], [64684.1, 0.0], [64684.5, 0.896], [64684.8, 0.046], [64685.1, 0.002]], "asks": [[64698.9, 0.01], [64699.0, 1.251], [64699.3, 0.381], [64699.6, 0.005], [64699.7, 0.466], [64699.9, 0.01], [64700.3, 0.46], [64700.5, 0.003], [64700.6, 0.001], [64700.7, 0.165], [64700.8, 0.279], [64700.9, 0.135], [64701.0, 0.905], [64701.1, 0.632], [64701.2, 0.463], [64701.3, 1.319], [64701.4, 1.006], [64701.5, 0.01], [64708.7, 0.023], [64717.1, 0.154], [64717.4, 1.199], [64717.7, 0.001], [64718.0, 0.017], [64718.3, 0.002], [64718.7, 0.006], [64718.8, 0.201], [64719.2, 0.973], [64720.5, 0.106], [64720.7, 0.009], [64720.8, 0.001], [64720.9, 0.132], [64721.0, 0.002], [64721.1, 4.008], [64721.3, 0.166], [64721.4, 0.123], [64721.5, 3.32], [64735.1, 0.001], [64735.5, 0.0], [64735.8, 0.0], [64736.1, 0.004], [64736.4, 0.01], [64833.5, 0.103], [64833.6, 3.82], [64843.6, 0.024], [65339.6, 5.533], [65793.3, 1.366]]}
{"kind": "depth", "E": 1787080479991, "U": 11315357206743, "u": 11315357211895, "recv_ms": 1787080479942, "bids": [[1000.0, 35.81], [14392.6, 0.854], [14492.6, 3.346], [14592.6, 0.0], [51754.1, 0.002], [58223.3, 0.055], [62104.8, 0.004], [63692.6, 0.022], [63819.2, 10.348], [64045.7, 4.844], [64078.0, 9.16], [64369.1, 4.742], [64535.5, 0.001], [64647.9, 0.054], [64648.5, 0.173], [64648.9, 0.032], [64680.8, 1.171], [64683.0, 0.07], [64683.2, 1.916], [64683.3, 0.201], [64683.6, 0.17], [64683.8, 0.071], [64684.1, 0.032], [64684.7, 1.147], [64685.0, 0.039]], "asks": [[64698.9, 0.465], [64699.4, 0.033], [64699.7, 0.053], [64700.4, 0.329], [64700.6, 0.106], [64700.8, 0.37], [64700.9, 0.265], [64701.1, 0.762], [64701.2, 0.723], [64701.5, 0.094], [64717.5, 2.564], [64717.8, 0.044], [64718.4, 1.322], [64719.3, 0.455], [64720.6, 0.208], [64720.8, 0.092], [64720.9, 0.262], [64721.1, 4.138], [64721.2, 0.121], [64721.5, 3.404], [64735.6, 0.035], [64735.9, 0.042], [64736.5, 0.042], [64850.6, 0.003], [65339.6, 5.533], [65602.7, 57.701], [65620.7, 7.459], [65692.7, 0.026]]}
{"kind": "depth", "E": 1787080480093, "U": 11315357212004, "u": 11315357217468, "recv_ms": 1787080480044, "bids": [[14392.6, 1.204], [14492.6, 2.996], [51754.1, 0.0], [58223.3, 0.055], [61448.5, 0.032], [61457.9, 0.061], [62104.8, 0.001], [63398.8, 0.642], [63689.9, 6.9], [63761.7, 14.372], [63883.9, 13.158], [63981.0, 6.553], [63988.6, 0.0], [64045.7, 4.844], [64535.5, 8.58], [64552.4, 6.424], [64611.9, 0.004], [64612.3, 0.209], [64614.1, 0.003], [64616.3, 32.404], [64617.5, 0.009], [64618.5, 0.005], [64649.2, 0.037], [64651.9, 0.382], [64652.7, 0.04], [64669.0, 0.008], [64669.7, 0.074], [64676.4, 0.032], [64681.0, 2.32], [64682.9, 0.071], [64683.0, 0.14], [64683.1, 1.008], [64683.4, 0.101], [64685.4, 0.126], [64690.8, 0.233], [64691.0, 0.022], [64691.3, 0.0], [64692.6, 8.404]], "asks": [[64692.7, 13.555], [64698.9, 0.465], [64699.1, 0.32], [64699.7, 0.053], [64700.9, 0.264], [64701.1, 0.882], [64701.3, 1.396], [64701.4, 1.104], [64701.5, 0.178], [64705.3, 0.0], [64712.7, 0.096], [64717.1, 0.189], [64721.1, 4.258], [64721.4, 0.298], [64721.5, 3.488], [64735.2, 0.037], [64739.3, 1.334], [64755.5, 0.064], [64756.3, 0.166], [64833.5, 0.127], [64833.6, 9.218], [64843.6, 0.0], [64850.6, 10.412], [64880.9, 1.241], [64883.0, 0.647], [64889.4, 2.513], [65304.8, 4.28], [65339.6, 5.533], [65786.0, 0.828], [65986.5, 0.003]]}
{"kind": "depth", "E": 1787080480195, "U": 11315357217554, "u": 11315357224138, "recv_ms": 1787080480146, "bids": [[1000.0, 35.81], [14392.6, 1.568], [14492.6, 2.632], [58223.3, 0.055], [61457.9, 0.061], [62104.8, 0.004], [63692.6, 0.002], [63722.3, 0.015], [63730.4, 1.58], [64045.7, 4.844], [64595.5, 0.003], [64614.9, 0.138], [64648.2, 0.032], [64657.9, 0.339], [64661.0, 0.023], [64662.3, 1.6], [64679.1, 0.23], [64679.2, 0.0], [64683.1, 1.078], [64683.4, 0.171], [64684.4, 0.033], [64684.5, 0.018], [64684.7, 2.468], [64692.6, 8.348]], "asks": [[64692.7, 13.556], [64700.0, 1.779], [64701.0, 0.989], [64701.4, 1.195], [64702.7, 0.002], [64718.1, 0.047], [64721.0, 0.086], [64721.4, 0.389], [64736.2, 0.042], [64770.4, 0.025], [65339.6, 5.533], [65501.4, 14.709], [65540.0, 1.149], [65630.7, 18.412], [65692.7, 0.006]]}
{"kind": "depth", "E": 1787080480297, "U": 11315357224264, "u": 11315357230030, "recv_ms": 1787080480248, "bids": [[1000.0, 35.81], [14392.6, 1.932], [14492.6, 2.268], [51754.0, 0.0], [58223.3, 0.055], [62104.8, 0.001], [63842.0, 0.828], [63888.1, 11.929], [64045.7, 4.844], [64369.1, 4.742], [64369.2, 0.0], [64536.7, 1.619], [64589.9, 0.001], [64590.0, 0.385], [64616.4, 6.293], [64629.8, 0.036], [64630.5, 0.032], [64630.8, 0.265], [64653.7, 0.411], [64663.5, 0.103], [64665.6, 0.147], [64682.8, 0.381], [64688.7, 0.086]], "asks": [[64692.7, 13.24], [64698.9, 0.473], [64699.7, 0.045], [64701.6, 0.098], [64721.6, 1.436], [64730.0, 1.926], [64739.3, 1.376], [64881.0, 4.391], [64881.1, 0.005], [64883.0, 0.067], [65274.9, 2.064], [65339.6, 5.533], [65505.6, 5.643]]}
{"kind": "depth", "E": 1787080480399, "U": 11315357230087, "u": 11315357235424, "recv_ms": 1787080480351, "bids": [[14392.6, 2.282], [14492.6, 1.918], [51754.0, 0.0], [58223.3, 0.055], [61457.9, 0.061], [63692.6, 0.022], [63859.9, 0.782], [64045.6, 0.0], [64045.7, 4.844], [64563.2, 0.008], [64631.1, 1.812], [64663.0, 0.151], [64663.2, 0.106], [64663.3, 0.111], [64663.6, 0.171], [64663.8, 0.072], [64665.2, 0.11], [64689.3, 0.094], [64692.6, 8.346]], "asks": [[64692.7, 13.243], [64699.1, 0.635], [64701.8, 0.526], [65339.6, 5.533], [65692.7, 0.026]]}
{"kind": "depth", "E": 1787080480501, "U": 11315357235490, "u": 11315357240707, "recv_ms": 1787080480451, "bids": [[1000.0, 35.81], [14392.6, 2.632], [14492.6, 1.568], [58223.3, 0.055], [61458.1, 0.007], [62104.8, 0.004], [63826.4, 4.613], [63916.3, 31.606], [64045.7, 4.844], [64165.3, 0.009], [64369.1, 4.741], [64552.4, 1.26], [64630.1, 0.495], [64662.9, 0.211], [64663.1, 0.383], [64663.4, 0.1]], "asks": [[64833.6, 3.82], [65016.2, 4.486], [65279.2, 17.129], [65339.6, 5.533], [65533.7, 14.168], [65540.2, 0.0], [65685.4, 5.325], [65986.5, 0.006]]}
{"kind": "depth", "E": 1787080480603, "U": 11315357240788, "u": 11315357246115, "recv_ms": 1787080480556, "bids": [[14392.6, 2.996], [14492.6, 1.204], [58223.3, 0.055], [61457.9, 0.061], [62104.8, 0.001], [63692.6, 0.002], [63720.0, 2.267], [63740.1, 5.638], [63741.6, 5.95], [64045.7, 4.844], [64369.1, 4.742], [64535.5, 8.602], [64536.7, 0.404], [64552.4, 6.434], [64616.3, 0.0], [64616.4, 0.003], [64617.5, 0.0], [64618.5, 32.409], [64635.6, 1.635], [64663.1, 0.453], [64663.4, 0.17], [64668.3, 0.009], [64669.0, 0.001], [64671.0, 0.085], [64675.1, 0.661], [64680.6, 0.001], [64688.7, 0.086], [64689.3, 0.01], [64692.6, 8.345]], "asks": [[64692.7, 13.318], [64698.0, 0.207], [64699.9, 0.105], [64704.0, 3.473], [64705.2, 0.174], [64708.8, 0.013], [64710.3, 0.134], [64711.4, 0.992], [64833.5, 0.103], [64833.6, 9.218], [64843.6, 0.024], [64850.6, 10.412], [64889.4, 2.481], [65016.2, 4.487], [65339.6, 5.533], [65667.4, 17.059], [65692.7, 0.006]]}
{"kind": "depth", "E": 1787080480705, "U": 11315357246279, "u": 11315357249919, "recv_ms": 1787080480656, "bids": [[14392.6, 3.346], [14492.6, 0.854], [58223.3, 0.055], [62104.8, 0.004], [63819.2, 11.13], [64045.7, 4.844], [64582.6, 0.005], [64614.9, 0.135], [64662.8, 0.114], [64671.0, 0.005], [64680.6, 0.081], [64686.7, 0.298], [64692.6, 8.35]], "asks": [[64704.0, 2.855], [64738.0, 0.007], [64770.4, 0.022], [64833.5, 0.127], [64843.6, 0.0], [65339.6, 5.533], [65533.9, 1.067], [65695.4, 7.296]]}
{"kind": "depth", "E": 1787080481011, "U": 11315357260140, "u": 11315357264469, "recv_ms": 1787080480962, "bids": [[14292.6, 0.406], [14392.6, 3.612], [14492.6, 0.182], [51754.1, 0.0], [58223.3, 0.055], [61448.5, 0.026], [61457.9, 0.067], [62104.8, 0.004], [63692.6, 0.002], [63726.3, 5.885], [63859.9, 0.0], [63920.4, 27.768], [64045.7, 4.844], [64552.4, 1.26], [64663.1, 0.453]], "asks": [[64692.7, 13.538], [64833.5, 0.103], [64833.6, 3.82], [64843.6, 0.024], [65015.2, 0.11], [65281.2, 0.081], [65339.6, 5.533], [65533.7, 15.235], [65549.5, 0.914], [65598.4, 17.898], [65630.0, 0.193], [65692.7, 0.006]]}
{"kind": "depth", "E": 1787080481113, "U": 11315357264578, "u": 11315357268823, "recv_ms": 1787080481065, "bids": [[1000.0, 35.81], [14292.6, 0.644], [14392.6, 3.5], [14492.6, 0.056], [51754.0, 0.002], [58223.3, 0.055], [61457.9, 0.067], [61458.0, 0.07], [61458.1, 0.009], [62104.8, 0.001], [63705.6, 0.038], [63770.3, 0.006], [63771.9, 0.0], [64045.7, 4.844], [64552.4, 6.434], [64653.7, 0.425], [64666.7, 0.668], [64679.2, 0.007], [64679.7, 0.005], [64681.0, 2.32], [64685.7, 0.003], [64686.7, 0.118], [64690.5, 0.085], [64690.8, 0.001], [64691.3, 0.232], [64692.1, 0.0], [64692.6, 8.233]], "asks": [[64692.7, 13.872], [64693.4, 0.0], [64699.7, 0.14], [64705.4, 0.006], [64714.9, 2.327], [64739.3, 1.334], [64754.9, 0.113], [64757.4, 0.402], [64833.6, 3.82], [64833.8, 5.398], [64883.1, 0.39], [64889.4, 0.01], [64889.6, 4.503], [65275.0, 5.224], [65339.6, 5.533], [65505.6, 5.301], [65613.3, 0.764], [65614.9, 0.001], [65679.6, 0.018], [65792.5, 7.95], [65986.5, 0.009], [66180.6, 1.902]]}
{"kind": "depth", "E": 1787080481215, "U": 11315357268850, "u": 11315357272668, "recv_ms": 1787080481168, "bids": [[14292.6, 0.924], [14392.6, 3.276], [14492.6, 0.0], [51754.0, 0.0], [58223.3, 0.055], [62104.8, 0.004], [63692.6, 0.022], [63722.2, 20.357], [63777.3, 1.57], [63913.0, 2.045], [64045.7, 4.844], [64369.1, 4.742], [64562.2, 0.942], [64679.1, 0.076], [64679.7, 0.159], [64679.8, 0.0], [64680.1, 0.012], [64681.5, 0.586], [64686.7, 0.118], [64687.4, 0.001], [64691.4, 0.047], [64691.5, 0.047]], "asks": [[64700.3, 0.461], [64702.7, 0.001], [64706.0, 0.223], [64708.1, 0.001], [64709.2, 0.558], [64709.3, 0.0], [65325.2, 0.0], [65339.6, 5.533], [65672.7, 0.77], [65692.7, 0.026]]}
{"kind": "depth", "E": 1787080481419, "U": 11315357277459, "u": 11315357281953, "recv_ms": 1787080481371, "bids": [[1000.0, 35.81], [14292.6, 1.652], [14392.6, 2.548], [58223.3, 0.055], [61457.9, 0.073], [62104.8, 0.001], [63692.6, 0.002], [63922.8, 7.501], [64138.4, 0.0], [64552.4, 6.426], [64563.2, 0.008], [64666.7, 0.699], [64673.2, 1.968], [64679.6, 0.396], [64679.7, 0.005], [64680.1, 0.012], [64681.5, 0.586], [64686.7, 0.118], [64692.6, 8.222]], "asks": [[64833.6, 9.218], [64833.8, 0.0], [64889.4, 2.505], [64889.6, 0.019], [65210.2, 8.423], [65339.6, 5.533], [65469.0, 29.062], [65620.7, 6.393], [65692.7, 0.006], [65855.6, 9.327]]}
{"kind": "depth", "E": 1787080481521, "U": 11315357282071, "u": 11315357289117, "recv_ms": 1787080481473, "bids": [[14292.6, 2.002], [14392.6, 2.198], [51754.0, 0.002], [58223.3, 0.055], [61457.9, 0.073], [62104.8, 0.004], [63398.8, 0.645], [63528.1, 7.919], [63858.5, 5.318], [64045.7, 4.844], [64149.1, 0.148], [64369.1, 4.732], [64669.0, 0.619], [64676.4, 0.65], [64682.5, 0.309], [64683.1, 0.769], [64691.4, 0.002], [64691.5, 0.089], [64692.6, 8.12]], "asks": [[64692.7, 13.872], [64693.4, 0.084], [64700.3, 0.46], [64705.2, 0.792], [64712.6, 0.62], [64833.5, 0.127], [64843.6, 0.0], [65210.2, 8.729], [65339.6, 5.533], [65469.0, 29.52], [65501.4, 15.051], [65602.7, 57.245]]}
{"kind": "depth", "E": 1787080481623, "U": 11315357289206, "u": 11315357297073, "recv_ms": 1787080481577, "bids": [[1000.0, 35.96], [14292.6, 2.366], [14392.6, 1.834], [51754.0, 0.0], [58223.3, 0.055], [61448.5, 0.02], [61457.9, 0.073], [62104.8, 0.001], [63692.6, 0.022], [63913.0, 1.108], [64045.7, 4.844], [64140.7, 0.728], [64369.1, 4.732], [64570.5, 0.245], [64624.7, 0.0], [64657.3, 0.0], [64659.7, 0.028], [64659.8, 0.451], [64659.9, 0.003], [64663.2, 0.104], [64663.3, 0.109], [64676.4, 0.032], [64687.4, 0.001], [64689.6, 0.001], [64690.6, 0.0], [64691.6, 0.024]], "asks": [[64692.7, 13.956], [64695.3, 0.002], [64696.1, 0.1], [64729.8, 0.006], [64767.5, 0.017], [64830.4, 1.208], [65016.2, 4.487], [65339.6, 5.533], [65630.7, 19.629], [65692.7, 0.026]]}
{"kind": "depth", "E": 1787080481725, "U": 11315357297145, "u": 11315357302196, "recv_ms": 1787080481676, "bids": [[1000.0, 35.81], [14292.6, 2.716], [14392.6, 1.484], [51754.0, 0.0], [58223.3, 0.055], [62104.8, 0.004], [63528.1, 8.296], [63712.6, 1.597], [63922.8, 8.438], [63923.2, 0.071], [64045.7, 4.844], [64070.1, 0.0], [64567.5, 0.087], [64680.9, 0.541], [64681.5, 0.045], [64684.7, 2.436], [64684.8, 0.078]], "asks": [[64692.7, 13.165], [64695.3, 0.0], [64696.4, 0.01], [64705.2, 0.174], [64712.6, 0.002], [64883.1, 0.0], [65280.7, 0.0], [65339.6, 5.533], [65598.4, 18.537]]}
{"kind": "depth", "E": 1787080482031, "U": 11315357311719, "u": 11315357317661, "recv_ms": 1787080481995, "bids": [[1000.0, 35.81], [14192.6, 0.042], [14292.6, 3.71], [14392.6, 0.448], [51754.1, 0.0], [58223.3, 0.055], [62104.8, 0.004], [63692.6, 0.022], [63883.9, 13.392], [64045.7, 4.844], [64570.5, 0.245], [64624.7, 0.0], [64657.3, 0.0], [64676.2, 0.01], [64687.3, 0.629]], "asks": [[64708.7, 0.023], [64729.7, 0.014], [64767.5, 0.017], [64830.3, 0.0], [64889.4, 2.752], [65275.1, 1.071], [65339.6, 5.533], [65404.4, 0.229], [65452.5, 1.863], [65692.7, 0.026], [66665.7, 0.0], [71162.0, 0.0]]}
{"kind": "depth", "E": 1787080482235, "U": 11315357322578, "u": 11315357327509, "recv_ms": 1787080482189, "bids": [[1000.0, 35.81], [14192.6, 0.462], [14292.6, 3.584], [14392.6, 0.154], [58223.3, 0.055], [61457.9, 0.079], [61458.0, 0.068], [61458.1, 0.011], [62104.8, 0.004], [63692.6, 0.002], [63916.3, 33.169], [64175.1, 10.113], [64369.1, 4.732], [64535.5, 8.585], [64552.4, 1.26], [64552.5, 5.166], [64570.4, 0.001], [64624.7, 2.85], [64625.3, 0.015], [64626.5, 0.115], [64627.1, 0.318], [64657.3, 0.0]], "asks": [[64729.7, 0.014], [64759.4, 2.865], [64759.7, 0.001], [64767.5, 0.017], [64830.3, 0.0], [64833.6, 9.218], [64850.6, 10.412], [64889.4, 2.506], [65339.6, 5.533], [65449.6, 2.671], [65692.7, 0.006]]}
{"kind": "depth", "E": 1787080482337, "U": 11315357327615, "u": 11315357332469, "recv_ms": 1787080482290, "bids": [[1000.0, 35.81], [14192.6, 0.7], [14292.6, 3.472], [14392.6, 0.028], [51754.0, 0.0], [58223.3, 0.055], [61457.9, 0.079], [63931.7, 1.568], [64045.7, 4.844], [64175.1, 10.113], [64563.2, 0.009], [64570.5, 0.525], [64609.7, 0.118], [64612.3, 0.218], [64614.1, 32.495], [64618.5, 0.005], [64620.4, 1.649], [64624.7, 3.018], [64627.1, 2.375], [64657.3, 0.073], [64667.9, 0.0], [64668.4, 0.559], [64669.1, 0.002], [64691.9, 0.021], [64692.6, 8.118]], "asks": [[64692.7, 13.067], [64696.4, 0.008], [64696.7, 2.322], [64698.1, 0.116], [64700.2, 1.301], [64729.7, 0.087], [64767.5, 0.186], [64830.3, 0.282], [65339.6, 5.533], [65462.5, 7.329], [65502.0, 3.057], [65538.0, 21.893], [65986.5, 0.012]]}
{"kind": "depth", "E": 1787080482439, "U": 11315357332504, "u": 11315357359271, "recv_ms": 1787080482391, "bids": [[14192.6, 1.022], [14292.6, 3.178], [14392.6, 0.0], [58223.3, 0.055], [61448.5, 0.014], [61457.9, 0.079], [62104.8, 0.001], [63692.6, 0.022], [64045.7, 4.844], [64369.1, 4.732], [64563.2, 0.008], [64570.5, 0.245], [64582.6, 0.005], [64612.3, 0.209], [64614.1, 0.003], [64614.9, 0.138], [64616.3, 32.492], [64617.5, 0.009], [64624.7, 2.85], [64635.6, 1.635], [64638.2, 0.0], [64657.3, 0.0], [64673.1, 5.003], [64673.7, 2.084], [64687.4, 0.001], [64690.8, 0.001], [64691.2, 0.049], [64691.6, 0.001], [64692.6, 8.125]], "asks": [[64692.7, 13.054], [64698.0, 0.188], [64698.9, 0.002], [64699.0, 0.014], [64699.7, 0.611], [64703.0, 0.001], [64714.7, 2.222], [64715.7, 0.226], [64717.3, 2.755], [64717.4, 10.062], [64729.7, 0.014], [64767.5, 0.017], [64770.4, 0.025], [64830.3, 0.0], [65339.6, 5.533], [65533.8, 4.265], [65539.4, 0.341], [65692.7, 0.026], [71162.0, 0.0]]}
{"kind": "depth", "E": 1787080482541, "U": 11315357359503, "u": 11315357370874, "recv_ms": 1787080482495, "bids": [[1000.0, 35.81], [14192.6, 1.386], [14292.6, 2.814], [58223.3, 0.055], [62104.8, 0.004], [63888.1, 11.227], [63916.3, 34.731], [64045.7, 4.844], [64486.5, 0.158], [64552.5, 5.174], [64638.2, 0.014], [64664.6, 0.004], [64687.4, 0.181], [64690.6, 0.31], [64691.0, 0.0]], "asks": [[64700.0, 1.798], [64728.3, 0.001], [64833.6, 3.82], [64833.8, 5.398], [64889.4, 0.01], [64889.6, 4.325], [65339.6, 5.533], [65533.7, 17.216], [65646.6, 2.107]]}
{"kind": "depth", "E": 1787080482643, "U": 11315357371007, "u": 11315357377957, "recv_ms": 1787080482596, "bids": [[1000.0, 35.81], [14192.6, 1.736], [14292.6, 2.464], [51754.0, 0.0], [58223.3, 0.055], [61448.5, 0.008], [61457.9, 0.079], [61458.0, 0.07], [62104.8, 0.015], [63010.5, 0.032], [63398.8, 0.642], [63612.8, 2.575], [63692.6, 0.002], [63769.9, 0.628], [63883.9, 13.743], [64045.7, 4.844], [64369.1, 4.732], [64638.2, 0.0], [64663.1, 0.451], [64676.6, 0.854], [64692.6, 8.124]], "asks": [[64692.7, 13.044], [64705.5, 2.38], [64712.8, 0.855], [64833.5, 0.103], [64843.6, 0.024], [64889.4, 2.483], [64889.6, 0.019], [65016.2, 4.487], [65339.6, 5.533], [65573.3, 3.351], [65692.7, 0.006], [65711.3, 0.0]]}
{"kind": "depth", "E": 1787080482847, "U": 11315357384138, "u": 11315357391676, "recv_ms": 1787080482800, "bids": [[1000.0, 35.81], [14192.6, 2.45], [14292.6, 1.75], [58223.3, 0.055], [61458.0, 0.072], [62104.8, 0.018], [63605.8, 1.881], [63692.6, 0.022], [63708.0, 0.067], [64045.7, 4.844], [64559.5, 0.023], [64570.5, 0.245], [64624.8, 0.0], [64627.9, 0.035], [64657.3, 0.0]], "asks": [[64729.8, 0.006], [64757.4, 0.401], [64767.5, 0.017], [64830.4, 1.208], [64889.4, 0.01], [64889.6, 4.442], [65339.6, 5.533], [65566.1, 6.416], [65608.2, 0.761], [65692.7, 0.026]]}
{"kind": "depth", "E": 1787080482949, "U": 11315357391943, "u": 11315357397036, "recv_ms": 1787080482902, "bids": [[1000.0, 35.81], [14192.6, 2.8], [14292.6, 1.4], [58223.3, 0.055], [62104.8, 0.015], [63754.6, 20.912], [63888.1, 10.876], [64045.7, 4.844], [64369.1, 4.732], [64676.2, 0.008]], "asks": [[64698.1, 0.136], [64708.7, 0.021], [64722.0, 0.472], [64722.1, 0.159], [65280.6, 0.0], [65305.8, 5.195], [65339.6, 5.533], [65695.4, 8.36]]}
{"kind": "depth", "E": 1787080483051, "U": 11315357397125, "u": 11315357402564, "recv_ms": 1787080483003, "bids": [[14192.6, 3.164], [14292.6, 1.036], [51754.1, 0.0], [58223.3, 0.055], [61457.9, 0.085], [62104.8, 0.018], [63692.6, 0.002], [63780.4, 4.258], [63833.4, 0.782], [63931.8, 0.105], [64045.7, 4.844], [64535.5, 0.001], [64536.7, 0.404], [64552.5, 0.0], [64676.2, 0.01], [64679.3, 0.004], [64681.0, 2.325], [64692.2, 0.069], [64692.6, 8.12]], "asks": [[64708.7, 0.023], [64722.1, 0.005], [64833.8, 0.0], [64850.6, 0.003], [65210.2, 9.648], [65339.6, 5.533], [65692.7, 0.006]]}
{"kind": "depth", "E": 1787080483153, "U": 11315357402807, "u": 11315357410902, "recv_ms": 1787080483105, "bids": [[1000.0, 35.81], [14192.6, 3.514], [14292.6, 0.686], [58223.3, 0.055], [61457.9, 0.085], [62104.8, 0.015], [64045.7, 4.844], [64496.6, 0.0], [64496.7, 15.505], [64499.0, 2.824], [64535.5, 8.601], [64536.7, 1.622], [64552.5, 5.114], [64638.2, 0.0], [64643.4, 0.278], [64653.7, 0.411], [64666.7, 0.668], [64669.0, 0.001], [64676.6, 0.236], [64679.8, 0.154], [64680.0, 1.679], [64681.0, 2.32], [64686.3, 0.001], [64690.9, 0.084], [64692.6, 8.029]], "asks": [[64692.7, 12.845], [64693.4, 0.0], [64693.8, 0.002], [64697.7, 0.084], [64700.0, 1.799], [64705.5, 1.762], [64712.8, 0.237], [64722.1, 0.159], [64739.3, 1.376], [64833.8, 5.398], [64850.8, 8.479], [64889.6, 4.442], [64961.6, 4.904], [65307.3, 7.121], [65339.6, 5.533], [65857.2, 7.063]]}
{"kind": "depth", "E": 1787080483255, "U": 11315357411165, "u": 11315357415859, "recv_ms": 1787080483207, "bids": [[1000.0, 35.81], [14192.6, 3.738], [14292.6, 0.392], [14592.6, 0.07], [51754.0, 0.0], [58223.3, 0.055], [61457.9, 0.085], [63010.5, 0.031], [63692.6, 0.022], [63816.7, 1.956], [63842.0, 3.174], [63916.3, 36.513], [64045.7, 4.844], [64369.1, 4.742], [64465.3, 0.019], [64570.5, 0.245], [64582.6, 0.002], [64614.9, 0.135], [64624.8, 0.0], [64638.2, 0.028], [64657.3, 0.0], [64657.8, 0.002], [64667.9, 0.557], [64668.4, 0.002], [64673.1, 5.0], [64680.1, 0.012], [64680.9, 0.0], [64681.5, 0.586]], "asks": [[64692.7, 12.844], [64694.0, 0.086], [64708.8, 0.006], [64709.4, 0.915], [64709.7, 0.033], [64729.8, 0.006], [64738.0, 0.004], [64767.5, 0.017], [64770.4, 0.025], [64830.4, 1.208], [65275.0, 7.365], [65339.6, 5.533], [65692.7, 0.026], [65695.5, 0.022]]}
{"kind": "depth", "E": 1787080483357, "U": 11315357415951, "u": 11315357419698, "recv_ms": 1787080483309, "bids": [[14192.6, 3.668], [14292.6, 0.252], [14592.6, 0.28], [51754.0, 0.002], [58223.3, 0.055], [62104.8, 0.018], [64045.7, 4.844], [64061.1, 0.029], [64552.5, 5.175], [64563.2, 0.008], [64616.3, 0.0], [64616.4, 0.003], [64617.5, 0.0], [64618.5, 32.497]], "asks": [[64717.4, 10.064], [64719.3, 0.453], [64833.6, 9.218], [64833.8, 0.0], [64889.4, 2.356], [64889.6, 0.019], [65339.6, 5.533], [65638.0, 17.618], [65851.6, 0.0], [67086.3, 0.013], [67280.4, 1.285]]}
{"kind": "depth", "E": 1787080483459, "U": 11315357419737, "u": 11315357424758, "recv_ms": 1787080483411, "bids": [[1000.0, 35.81], [14192.6, 3.556], [14292.6, 0.126], [14592.6, 0.518], [51754.0, 0.0], [58223.3, 0.055], [61457.9, 0.085], [62104.8, 0.015], [63398.8, 0.636], [63599.9, 1.919], [63680.1, 3.294], [63692.6, 0.002], [63906.7, 2.344], [64045.7, 4.844], [64076.5, 5.933], [64622.8, 0.372], [64635.6, 1.663], [64645.4, 0.017], [64661.6, 0.001], [64666.7, 0.699], [64679.8, 0.0], [64679.9, 0.156], [64680.0, 1.679], [64680.1, 0.012], [64687.4, 0.181]], "asks": [[64692.7, 12.844], [64719.2, 0.002], [64722.1, 0.159], [64733.3, 0.909], [64735.4, 0.368], [64741.9, 0.014], [64758.1, 0.0], [64833.5, 0.127], [64843.6, 0.0], [64883.1, 0.457], [65339.6, 5.533], [65630.7, 20.808], [65692.7, 0.006]]}
{"kind": "depth", "E": 1787080483561, "U": 11315357425010, "u": 11315357432458, "recv_ms": 1787080483514, "bids": [[1000.0, 35.81], [14192.6, 3.43], [14292.6, 0.014], [14592.6, 0.756], [58223.3, 0.055], [61457.9, 0.085], [61458.0, 0.07], [61458.1, 0.013], [62104.8, 0.018], [64045.7, 4.913], [64369.1, 4.742], [64590.5, 0.012], [64592.0, 1.263], [64679.4, 0.384], [64679.9, 0.156], [64687.4, 0.001], [64690.9, 0.0]], "asks": [[64692.7, 12.859], [64698.1, 0.136], [64698.2, 0.441], [64698.3, 0.86], [64698.7, 0.248], [64790.4, 2.216], [64790.5, 0.0], [65339.6, 5.533], [65844.2, 1.515]]}
{"kind": "depth", "E": 1787080483663, "U": 11315357432704, "u": 11315357438171, "recv_ms": 1787080483615, "bids": [[14192.6, 3.094], [14292.6, 0.0], [14592.6, 1.106], [58223.3, 0.055], [61458.0, 0.072], [63592.8, 20.168], [63689.9, 7.998], [63692.6, 0.022], [63722.2, 20.749], [63841.8, 4.699], [64045.7, 4.913], [64078.0, 9.86], [64369.1, 4.742], [64552.5, 4.564], [64586.0, 0.509], [64590.6, 0.212], [64621.6, 6.001], [64635.6, 1.635], [64644.2, 3.535], [64660.4, 0.976], [64668.9, 4.177], [64676.3, 1.249], [64679.3, 0.158], [64679.9, 0.002], [64687.4, 0.001]], "asks": [[64692.7, 12.869], [64693.4, 0.084], [64705.1, 1.119], [64712.5, 0.677], [64719.5, 2.25], [64735.6, 3.535], [64741.9, 0.0], [64758.3, 6.025], [64790.3, 0.0], [64790.9, 0.008], [64833.6, 9.218], [64889.4, 4.157], [65016.2, 4.487], [65339.6, 5.535], [65414.0, 3.311], [65692.7, 0.026]]}
{"kind": "depth", "E": 1787080483765, "U": 11315357438236, "u": 11315357443762, "recv_ms": 1787080483717, "bids": [[1000.0, 35.81], [14192.6, 2.744], [14592.6, 1.456], [51754.0, 0.0], [58223.3, 0.055], [61457.9, 0.085], [62104.8, 0.015], [63537.3, 0.013], [64045.7, 4.913], [64588.6, 11.217], [64590.0, 0.382], [64590.1, 0.005], [64653.7, 0.425], [64659.7, 0.03], [64659.8, 0.453], [64659.9, 0.005], [64663.1, 0.453], [64663.2, 0.106], [64663.3, 0.111], [64687.3, 0.629], [64692.6, 8.059]], "asks": [[64692.7, 12.86], [64700.0, 1.798], [64790.7, 10.004], [65339.6, 5.533], [66642.9, 0.642]]}
{"kind": "depth", "E": 1787080483867, "U": 11315357443835, "u": 11315357450700, "recv_ms": 1787080483819, "bids": [[1000.0, 35.81], [14192.6, 2.38], [14592.6, 1.82], [51754.0, 0.0], [58223.3, 0.055], [62104.8, 0.018], [63692.6, 0.002], [64045.7, 4.913], [64369.1, 4.732], [64535.5, 0.001], [64536.7, 0.404], [64552.5, 0.0], [64570.5, 0.245], [64586.0, 0.501], [64588.6, 10.013], [64588.7, 2.512], [64624.8, 0.0], [64657.3, 0.0], [64686.7, 0.118], [64690.0, 0.003]], "asks": [[64693.0, 0.085], [64697.7, 0.0], [64729.8, 0.006], [64767.5, 0.017], [64790.6, 0.008], [64790.9, 0.0], [64830.4, 1.208], [64833.6, 3.82], [64850.8, 0.002], [65692.7, 0.006]]}
{"kind": "depth", "E": 1787080483969, "U": 11315357450894, "u": 11315357457290, "recv_ms": 1787080483920, "bids": [[14192.6, 2.016], [14592.6, 2.184], [58223.3, 0.055], [61458.0, 0.074], [62104.8, 0.015], [64045.7, 4.913], [64149.1, 0.153], [64496.7, 0.0], [64499.0, 0.568], [64620.1, 0.004], [64651.5, 0.001], [64651.7, 0.04], [64690.1, 0.088]], "asks": [[64693.0, 0.001], [64833.5, 0.103], [64843.6, 0.024], [64889.4, 0.01], [65339.6, 5.533], [65685.4, 4.261]]}
{"kind": "depth", "E": 1787080484071, "U": 11315357457364, "u": 11315357463841, "recv_ms": 1787080484022, "bids": [[1000.0, 35.81], [14192.6, 1.666], [14592.6, 2.534], [51754.0, 0.004], [51754.1, 0.0], [58223.3, 0.055], [61458.1, 0.011], [62104.8, 0.018], [63597.0, 5.004], [64045.7, 4.913], [64496.7, 15.505], [64535.5, 8.862], [64552.5, 5.234], [64669.4, 0.002], [64670.2, 0.119], [64676.2, 0.01], [64681.0, 2.32], [64687.3, 0.809]], "asks": [[64708.7, 0.023], [64833.5, 0.127], [64833.6, 9.218], [64843.6, 0.0], [64850.6, 10.412], [64889.4, 2.169], [65339.6, 5.533], [65505.6, 5.073]]}
{"kind": "depth", "E": 1787080484173, "U": 11315357463929, "u": 11315357468521, "recv_ms": 1787080484127, "bids": [[1000.0, 35.81], [14192.6, 1.316], [14592.6, 2.884], [51754.0, 0.0], [58223.3, 0.055], [63692.6, 0.022], [64369.1, 4.732], [64552.5, 0.0], [64570.5, 0.245], [64622.7, 0.01], [64624.8, 0.0], [64657.3, 0.0], [64687.3, 0.629]], "asks": [[64700.3, 0.461], [64729.8, 0.006], [64767.5, 0.017], [64830.4, 1.208], [64833.6, 3.82], [65339.6, 5.533], [65533.7, 16.454], [65692.7, 0.026], [65695.4, 9.424], [65986.5, 0.012]]}
{"kind": "depth", "E": 1787080484275, "U": 11315357468588, "u": 11315357472503, "recv_ms": 1787080484228, "bids": [[14192.6, 0.952], [14592.6, 3.248], [51754.0, 0.0], [58223.3, 0.055], [61448.5, 0.004], [61457.9, 0.085], [62104.8, 0.015], [63592.8, 20.482], [63883.9, 14.094], [63888.1, 10.525], [63906.5, 10.08], [64045.7, 4.913], [64535.5, 7.605], [64552.5, 4.618], [64690.1, 0.004], [64692.5, 0.648]], "asks": [[64692.7, 12.865], [64739.3, 1.334], [64833.6, 9.218], [64850.6, 10.412], [64889.4, 3.97], [65006.2, 2.605], [65339.6, 5.533], [65505.6, 4.845]]}
{"kind": "depth", "E": 1787080484377, "U": 11315357472783, "u": 11315357476869, "recv_ms": 1787080484332, "bids": [[1000.0, 35.81], [14192.6, 0.588], [14592.6, 3.612], [58223.3, 0.055], [62104.8, 0.018], [63692.6, 0.002], [64045.7, 4.913], [64499.0, 2.824], [64536.7, 1.473], [64552.5, 0.0], [64563.2, 0.009], [64620.4, 6.295]], "asks": [[64733.3, 1.373], [64833.6, 3.82], [65339.6, 5.533], [65692.7, 0.006]]}
{"kind": "depth", "E": 1787080484581, "U": 11315357483060, "u": 11315357487441, "recv_ms": 1787080484532, "bids": [[14192.6, 0.224], [14492.6, 0.336], [14592.6, 3.64], [58223.3, 0.055], [61457.9, 0.085], [62104.8, 0.018], [63398.8, 0.639], [63692.6, 0.022], [63916.3, 37.762], [64045.7, 4.913], [64552.5, 4.618], [64635.6, 1.649], [64668.3, 0.002], [64669.8, 0.01], [64679.7, 0.005], [64679.8, 0.0], [64686.7, 0.298], [64687.4, 0.001], [64692.6, 8.058]], "asks": [[64692.7, 12.864], [64833.5, 0.127], [64833.6, 9.218], [64843.6, 0.0], [64881.1, 0.002], [64881.2, 0.005], [64889.4, 3.97], [65339.6, 5.533], [65692.7, 0.026]]}
{"kind": "depth", "E": 1787080484683, "U": 11315357487461, "u": 11315357491980, "recv_ms": 1787080484634, "bids": [[1000.0, 35.81], [14192.6, 0.098], [14492.6, 0.574], [14592.6, 3.528], [58223.3, 0.055], [61448.5, 0.0], [61457.9, 0.085], [63883.9, 14.445], [64045.7, 4.913], [64369.1, 4.732], [64635.6, 1.635], [64679.7, 0.159], [64686.3, 0.085], [64686.7, 0.118], [64687.4, 0.181], [64689.6, 0.001], [64690.0, 0.003], [64692.5, 0.643], [64692.6, 8.036]], "asks": [[64692.7, 12.867], [64692.8, 0.205], [64693.0, 0.085], [64739.3, 1.376], [65016.2, 5.102], [65339.6, 5.533], [65396.3, 1.753], [67086.3, 0.0], [71162.0, 0.002]]}
{"kind": "depth", "E": 1787080484785, "U": 11315357492115, "u": 11315357496414, "recv_ms": 1787080484738, "bids": [[1000.0, 35.81], [14192.6, 0.0], [14492.6, 0.826], [14592.6, 3.374], [58223.3, 0.055], [62104.8, 0.001], [63591.4, 0.0], [63692.6, 0.002], [64045.7, 4.913], [64110.4, 11.184], [64114.5, 3.818], [64369.1, 4.742], [64679.5, 0.618], [64679.7, 0.005]], "asks": [[65211.5, 0.0], [65339.6, 5.533], [65602.7, 56.789], [65692.7, 0.006], [65796.7, 3.793], [71162.0, 0.0]]}
{"kind": "depth", "E": 1787080484887, "U": 11315357496480, "u": 11315357500600, "recv_ms": 1787080484840, "bids": [[14492.6, 1.19], [14592.6, 3.01], [58223.3, 0.055], [62104.8, 0.004], [63761.7, 14.215], [64045.7, 4.913], [64535.5, 8.6], [64536.7, 0.404], [64552.5, 5.114], [64570.5, 0.245], [64624.8, 0.0], [64657.3, 0.0]], "asks": [[64729.8, 0.006], [64767.5, 0.017], [64830.4, 1.208], [64833.6, 9.218], [64850.6, 10.412], [64889.4, 2.517], [65212.2, 0.689], [65339.6, 5.533], [65397.9, 6.175], [65672.7, 1.53]]}
{"kind": "depth", "E": 1787080484989, "U": 11315357500770, "u": 11315357505126, "recv_ms": 1787080484940, "bids": [[1000.0, 35.81], [14492.6, 1.54], [14592.6, 2.66], [58223.3, 0.055], [62104.8, 0.001], [63692.6, 0.022], [64045.7, 4.913], [64149.1, 0.177], [64552.5, 0.0], [64689.8, 0.273]], "asks": [[64833.6, 3.82], [65339.6, 5.533], [65692.7, 0.026], [65792.5, 8.329]]}
{"kind": "depth", "E": 1787080485091, "U": 11315357505225, "u": 11315357509204, "recv_ms": 1787080485044, "bids": [[1000.0, 35.81], [14492.6, 1.904], [14592.6, 2.296], [51754.1, 0.0], [58223.3, 0.055], [63705.6, 0.02], [64045.7, 4.913], [64369.1, 4.732], [64552.5, 5.106], [64611.9, 32.543], [64618.5, 0.005], [64676.2, 0.01], [64681.0, 2.32]], "asks": [[64708.7, 0.023], [64833.6, 9.218], [64883.1, 0.0], [64889.4, 2.539], [65339.6, 5.533], [65679.6, 0.0]]}
{"kind": "depth", "E": 1787080485193, "U": 11315357509353, "u": 11315357513201, "recv_ms": 1787080485145, "bids": [[14492.6, 2.254], [14592.6, 1.946], [51754.0, 0.0], [58223.3, 0.055], [61457.9, 0.085], [62104.8, 0.004], [63692.6, 0.002], [63791.9, 2.783], [64045.7, 4.913], [64612.3, 0.227], [64614.9, 0.138], [64617.5, 0.009], [64620.4, 1.649], [64626.3, 0.367], [64627.3, 0.553], [64632.8, 1.158], [64633.8, 0.2], [64635.6, 1.663], [64645.7, 0.19], [64646.7, 0.4], [64653.7, 0.411], [64666.7, 0.668], [64668.9, 3.559], [64676.3, 0.631], [64676.4, 0.022], [64679.4, 0.538], [64679.5, 0.464], [64681.1, 0.618], [64690.1, 0.088], [64692.6, 7.893]], "asks": [[64692.7, 12.299], [64693.0, 0.001], [64698.1, 0.094], [64705.1, 0.501], [64710.0, 0.285], [64712.5, 0.059], [64714.9, 2.323], [64717.4, 10.064], [64755.5, 0.003], [64755.7, 0.061], [64770.4, 0.025], [65287.0, 0.059], [65339.6, 5.533], [65452.5, 0.948], [65598.4, 18.993], [65692.7, 0.006]]}
{"kind": "depth", "E": 1787080485295, "U": 11315357513309, "u": 11315357517324, "recv_ms": 1787080485248, "bids": [[1000.0, 35.81], [14492.6, 2.618], [14592.6, 1.582], [58223.3, 0.055], [62104.8, 0.001], [63398.8, 0.642], [63813.4, 1.877], [64045.7, 4.913], [64076.5, 5.311], [64359.3, 0.157], [64552.5, 5.113], [64611.9, 0.004], [64612.3, 0.209], [64617.5, 0.0], [64618.5, 32.542], [64667.9, 0.0], [64668.1, 0.558], [64669.0, 0.001], [64669.4, 0.002], [64669.6, 0.138], [64670.2, 0.003], [64672.8, 0.381], [64673.2, 2.894], [64674.3, 0.0], [64679.1, 0.23], [64679.4, 0.384], [64680.1, 0.553], [64681.5, 0.045], [64689.7, 0.084], [64690.1, 0.004]], "asks": [[64692.9, 0.085], [64708.3, 0.846], [64709.2, 0.002], [64709.6, 0.0], [64710.3, 0.675], [64711.1, 0.002], [64711.9, 0.0], [64712.4, 0.116], [64713.1, 0.001], [64713.7, 0.011], [64833.5, 0.103], [64833.6, 9.218], [64843.6, 0.024], [64889.4, 2.517], [65339.6, 5.533]]}
{"kind": "depth", "E": 1787080485397, "U": 11315357517461, "u": 11315357523139, "recv_ms": 1787080485348, "bids": [[1000.0, 35.81], [14492.6, 2.968], [14592.6, 1.232], [58223.3, 0.055], [61457.9, 0.085], [62104.8, 0.004], [63519.1, 1.348], [63536.3, 0.009], [63692.6, 0.022], [63806.3, 2.5], [63855.7, 12.274], [64045.7, 4.913], [64369.1, 4.732], [64536.7, 1.622], [64563.2, 0.008], [64618.5, 0.005], [64620.4, 1.649], [64635.6, 1.635], [64670.6, 0.002], [64674.8, 2.058], [64676.4, 0.032], [64692.6, 7.894]], "asks": [[64710.3, 0.134], [64711.1, 0.543], [64714.7, 2.222], [64755.5, 0.064], [64755.7, 0.0], [64790.4, 3.427], [64833.5, 0.127], [64843.6, 0.0], [64889.4, 0.01], [64889.6, 4.944], [65339.6, 5.533], [65437.2, 9.08], [65573.3, 2.743], [65692.7, 0.026]]}
{"kind": "depth", "E": 1787080485499, "U": 11315357523149, "u": 11315357527083, "recv_ms": 1787080485453, "bids": [[14492.6, 3.332], [14592.6, 0.868], [58223.3, 0.055], [61458.1, 0.009], [62104.8, 0.001], [63793.4, 8.484], [64045.7, 4.913], [64078.0, 10.482], [64612.3, 0.227], [64666.7, 0.698], [64669.0, 0.008], [64669.8, 0.003]], "asks": [[64790.3, 0.008], [64790.6, 0.0], [65280.8, 0.261], [65339.6, 5.533], [65339.7, 0.008], [65437.2, 6.356], [65462.5, 8.244], [65986.5, 0.009]]}
{"kind": "depth", "E": 1787080485601, "U": 11315357527199, "u": 11315357531261, "recv_ms": 1787080485553, "bids": [[1000.0, 35.81], [14492.6, 3.682], [14592.6, 0.518], [51754.0, 0.0], [58223.3, 0.055], [61457.9, 0.085], [63692.6, 0.002], [63851.6, 10.557], [64045.7, 4.913], [64369.1, 5.353], [64679.7, 1.005], [64680.8, 0.171], [64690.1, 0.004], [64690.6, 0.31], [64692.6, 7.895]], "asks": [[64692.7, 12.3], [64692.8, 0.289], [64692.9, 0.001], [64699.6, 1.005], [64701.4, 0.195], [64708.3, 0.29], [64709.3, 0.556], [64712.4, 0.001], [64713.1, 0.116], [64780.6, 0.002], [64889.4, 0.01], [64889.6, 5.083], [65280.5, 0.006], [65339.6, 5.535], [65437.2, 5.448], [65566.1, 7.024], [65692.7, 0.006], [67280.4, 1.272], [71162.0, 0.0]]}
{"kind": "depth", "E": 1787080485805, "U": 11315357536732, "u": 11315357542678, "recv_ms": 1787080485757, "bids": [[14392.6, 0.392], [14492.6, 3.612], [14592.6, 0.196], [58223.3, 0.055], [62104.8, 0.001], [62758.8, 0.0], [63692.6, 0.022], [63931.7, 0.006], [64045.7, 4.913], [64369.1, 5.363], [64552.5, 5.106], [64582.6, 0.005], [64614.9, 0.135]], "asks": [[64694.5, 0.005], [64695.7, 0.003], [64738.0, 0.007], [64770.4, 0.022], [64833.6, 9.218], [65016.2, 5.102], [65274.9, 2.524], [65339.6, 5.533], [65437.3, 6.437], [65501.4, 15.85], [65692.7, 0.026], [66633.3, 0.013]]}
{"kind": "depth", "E": 1787080485907, "U": 11315357542898, "u": 11315357548431, "recv_ms": 1787080485859, "bids": [[1000.0, 35.81], [14392.6, 0.63], [14492.6, 3.5], [14592.6, 0.07], [58223.3, 0.055], [61457.9, 0.085], [62104.8, 0.004], [63888.1, 10.259], [64045.7, 4.913], [64668.3, 0.009], [64669.0, 0.001], [64670.6, 0.0], [64680.1, 0.012], [64681.1, 0.0], [64681.5, 0.586], [64686.7, 0.118], [64687.3, 0.629]], "asks": [[64692.7, 12.599], [64694.5, 0.015], [64695.7, 0.013], [64711.1, 0.002], [64711.9, 0.541], [64715.0, 0.006], [65339.6, 5.533], [65396.3, 0.991], [65437.3, 7.353], [65511.4, 0.769], [65779.5, 1.844]]}
{"kind": "depth", "E": 1787080486009, "U": 11315357548531, "u": 11315357553572, "recv_ms": 1787080485964, "bids": [[14392.6, 0.91], [14492.6, 3.29], [14592.6, 0.0], [58223.3, 0.055], [63692.6, 0.002], [63916.3, 39.325], [64045.7, 4.913], [64367.4, 0.292], [64369.1, 5.353], [64587.6, 0.002], [64616.3, 0.0], [64617.5, 0.0], [64618.5, 32.542], [64621.4, 0.019], [64623.2, 0.0], [64625.0, 1.588], [64634.2, 0.06], [64636.0, 0.034], [64636.6, 0.026], [64637.9, 0.0], [64638.5, 0.002], [64640.0, 0.389], [64640.3, 0.012], [64644.5, 0.008], [64645.1, 0.044], [64646.9, 0.342], [64648.8, 0.213], [64657.2, 0.061], [64662.4, 0.016], [64662.8, 0.108], [64666.5, 0.771], [64667.3, 0.008], [64680.6, 0.081], [64682.7, 0.535], [64692.2, 0.047], [64692.5, 0.624]], "asks": [[64700.8, 0.398], [64702.7, 0.001], [64703.2, 0.434], [64703.4, 0.311], [64704.5, 2.32], [64705.1, 0.501], [64706.9, 0.001], [64712.6, 0.019], [64713.6, 0.058], [64714.4, 0.443], [64715.5, 0.018], [64716.3, 0.163], [64716.8, 0.021], [64717.3, 2.739], [64717.6, 0.002], [64720.9, 0.268], [64721.3, 0.16], [64726.4, 0.01], [64744.8, 0.309], [64760.1, 0.001], [64889.4, 0.01], [64889.6, 5.268], [65157.6, 0.0], [65339.6, 5.533], [65437.3, 6.445], [65532.9, 0.001], [65692.7, 0.006]]}
{"kind": "depth", "E": 1787080486111, "U": 11315357553803, "u": 11315357559343, "recv_ms": 1787080486063, "bids": [[14392.6, 1.274], [14492.6, 2.926], [51754.1, 0.0], [58223.3, 0.055], [61458.0, 0.072], [61458.1, 0.009], [62104.8, 0.001], [63883.9, 14.796], [64045.7, 4.913], [64676.2, 0.01], [64681.0, 2.32], [64682.2, 0.004], [64691.6, 0.023]], "asks": [[64702.9, 0.312], [64708.7, 0.023], [64889.4, 2.678], [64889.6, 0.019], [65339.6, 5.533], [65501.4, 16.078], [65505.6, 4.616]]}
{"kind": "depth", "E": 1787080486213, "U": 11315357559477, "u": 11315357564181, "recv_ms": 1787080486166, "bids": [[1000.0, 35.81], [14392.6, 1.638], [14492.6, 2.562], [58223.3, 0.055], [61457.9, 0.085], [62104.8, 0.004], [63605.8, 2.508], [63692.6, 0.022], [64045.7, 4.913], [64575.0, 4.497], [64576.5, 1.003], [64583.1, 0.0], [64583.9, 2.325], [64620.7, 0.123], [64620.9, 0.046], [64653.7, 0.425], [64668.7, 0.618], [64676.1, 1.21], [64679.1, 0.076], [64679.2, 0.007], [64682.2, 0.003], [64691.4, 0.045], [64691.5, 0.047], [64692.1, 0.0], [64692.6, 7.875]], "asks": [[64697.5, 0.127], [64700.3, 0.46], [64702.9, 0.311], [64704.9, 0.671], [64712.3, 0.737], [64739.3, 1.334], [64763.1, 0.0], [64763.3, 0.046], [64799.7, 2.524], [64801.3, 0.213], [64827.6, 3.865], [64828.4, 0.002], [64889.4, 2.517], [65151.4, 0.116], [65339.6, 5.533], [65397.9, 6.937], [65437.3, 7.361], [65498.7, 7.898], [65573.3, 1.982], [65692.7, 0.026], [65986.5, 0.006]]}
{"kind": "depth", "E": 1787080486315, "U": 11315357564251, "u": 11315357569520, "recv_ms": 1787080486271, "bids": [[14392.6, 1.988], [14492.6, 2.212], [51754.0, 0.0], [58223.3, 0.055], [62104.8, 0.001], [63398.8, 0.645], [64045.7, 4.913], [64369.1, 5.363], [64629.8, 0.004], [64630.1, 0.463], [64630.5, 0.0], [64630.8, 0.233], [64631.1, 1.78], [64635.6, 1.649], [64638.2, 0.0], [64647.9, 0.022], [64648.2, 0.0], [64648.5, 0.141], [64648.9, 0.0], [64649.2, 0.005], [64662.8, 0.038], [64662.9, 0.141], [64663.0, 0.011], [64663.1, 0.313], [64663.2, 0.006], [64663.3, 0.011], [64663.4, 0.0], [64663.5, 0.003], [64663.6, 0.001], [64663.8, 0.002], [64665.2, 0.01], [64665.6, 0.047], [64679.2, 0.161], [64682.7, 0.536], [64682.8, 0.311], [64682.9, 0.001], [64683.0, 0.0], [64683.1, 0.629], [64683.2, 1.816], [64683.3, 0.001], [64683.4, 0.001], [64683.5, 0.003], [64683.6, 0.0], [64683.7, 0.005], [64683.8, 0.001], [64684.1, 0.0], [64684.4, 0.001], [64684.7, 2.404], [64685.0, 0.007], [64685.4, 0.01]], "asks": [[64699.1, 0.6], [64699.4, 0.001], [64699.7, 0.569], [64700.0, 1.756], [64700.4, 0.287], [64700.6, 0.001], [64700.7, 0.005], [64700.8, 0.307], [64700.9, 0.004], [64701.0, 0.905], [64701.1, 0.632], [64701.2, 0.463], [64701.3, 1.319], [64701.4, 0.006], [64701.5, 0.01], [64701.6, 0.021], [64703.4, 0.312], [64717.1, 0.154], [64717.5, 2.532], [64717.8, 0.002], [64718.1, 0.005], [64718.4, 1.28], [64718.8, 0.041], [64719.3, 0.313], [64720.6, 0.103], [64720.8, 0.001], [64720.9, 0.008], [64721.0, 0.002], [64721.1, 4.008], [64721.2, 0.001], [64721.4, 0.123], [64721.5, 3.32], [64721.6, 1.359], [64735.2, 0.002], [64735.6, 3.503], [64735.9, 0.0], [64736.2, 0.0], [64736.5, 0.0], [64889.4, 2.332], [64889.6, 0.019], [65339.6, 5.533], [66188.0, 13.233]]}
{"kind": "depth", "E": 1787080486417, "U": 11315357569712, "u": 11315357575881, "recv_ms": 1787080486371, "bids": [[14392.6, 2.338], [14492.6, 1.862], [51754.0, 0.0], [58223.3, 0.055], [61457.9, 0.085], [62104.8, 0.004], [63692.6, 0.002], [63778.1, 2.195], [63826.4, 3.832], [64045.7, 4.913], [64149.1, 0.244], [64563.2, 0.008], [64620.4, 6.302], [64635.6, 1.635], [64638.2, 0.014], [64649.5, 0.034], [64651.5, 0.04], [64651.7, 0.001], [64659.7, 0.028], [64659.8, 0.451], [64659.9, 0.003], [64663.1, 0.311], [64663.2, 0.004], [64663.3, 0.009], [64679.2, 0.161], [64683.2, 1.886], [64683.3, 0.071], [64683.4, 0.101], [64683.5, 0.103], [64683.6, 0.1], [64683.8, 0.101], [64683.9, 0.074], [64684.1, 0.07], [64685.6, 0.033], [64687.4, 0.181], [64692.6, 7.998]], "asks": [[64692.7, 12.604], [64699.2, 0.037], [64700.7, 0.11], [64700.9, 0.095], [64701.0, 1.035], [64701.2, 0.593], [64701.3, 1.579], [64701.5, 0.108], [64701.6, 0.105], [64717.3, 1.216], [64717.4, 0.064], [64719.4, 0.141], [64720.7, 0.114], [64720.9, 0.099], [64721.0, 0.132], [64721.2, 0.131], [64721.3, 0.28], [64721.5, 3.418], [64721.6, 1.443], [64733.9, 0.014], [64735.3, 0.108], [64780.5, 0.023], [64827.1, 0.001], [64873.8, 0.009], [65339.6, 5.533], [65484.8, 0.008], [65692.7, 0.006], [66180.6, 2.655]]}
{"kind": "depth", "E": 1787080486519, "U": 11315357576176, "u": 11315357586615, "recv_ms": 1787080486472, "bids": [[1000.0, 35.81], [14392.6, 2.702], [14492.6, 1.498], [51754.0, 0.0], [58223.3, 0.055], [61457.9, 0.086], [63720.0, 1.993], [63855.6, 1.487], [64045.7, 4.913], [64614.9, 0.138], [64648.5, 0.173], [64679.2, 0.007], [64679.3, 0.158], [64683.2, 1.956], [64683.4, 0.171], [64683.6, 0.2], [64684.7, 2.436], [64687.3, 0.629], [64687.4, 0.001], [64692.6, 8.0]], "asks": [[64692.7, 12.615], [64693.4, 0.0], [64700.1, 0.056], [64701.2, 0.713], [64701.4, 0.083], [64701.6, 0.189], [64705.7, 0.289], [64715.0, 0.002], [64718.2, 0.06], [64720.6, 10.103], [64721.2, 0.251], [64721.5, 3.495], [64721.6, 1.527], [64736.3, 0.223], [64770.4, 0.025], [65339.6, 5.533], [65469.0, 31.046], [65566.1, 7.785]]}
{"kind": "depth", "E": 1787080486621, "U": 11315357587227, "u": 11315357593396, "recv_ms": 1787080486574, "bids": [[14392.6, 3.052], [14492.6, 1.148], [51754.0, 0.0], [58223.3, 0.055], [61457.9, 0.086], [62104.8, 0.001], [63398.8, 0.642], [63592.8, 21.423], [63692.6, 0.022], [63716.5, 0.274], [63754.6, 21.069], [63819.2, 11.912], [64045.7, 4.913], [64369.1, 5.353], [64552.5, 0.0], [64648.2, 0.032], [64648.8, 0.245], [64649.1, 0.033], [64676.4, 0.471], [64683.3, 0.141], [64683.7, 0.075], [64684.3, 0.497], [64685.0, 0.039], [64685.3, 0.032], [64687.4, 0.181], [64690.3, 0.001], [64690.8, 0.233], [64691.3, 0.0], [64692.6, 8.001]], "asks": [[64692.7, 12.605], [64693.2, 0.084], [64693.6, 0.164], [64699.5, 0.172], [64699.8, 2.363], [64700.5, 0.045], [64701.1, 0.716], [64701.5, 0.199], [64717.6, 0.034], [64717.9, 0.044], [64718.6, 0.045], [64721.1, 4.092], [64721.5, 3.586], [64735.7, 0.069], [64736.0, 0.084], [64736.6, 0.047], [64833.6, 3.82], [65339.6, 5.533], [65692.7, 0.026]]}
{"kind": "depth", "E": 1787080486723, "U": 11315357593524, "u": 11315357598351, "recv_ms": 1787080486677, "bids": [[14392.6, 3.416], [14492.6, 0.784], [58223.3, 0.055], [61457.9, 0.085], [62104.8, 0.004], [63913.0, 0.171], [64045.7, 4.913], [64535.5, 8.584], [64536.7, 1.62], [64552.5, 5.106], [64631.4, 0.047], [64662.1, 0.008], [64666.6, 1.899], [64668.7, 0.0], [64676.1, 0.592], [64679.3, 0.004], [64679.4, 0.538], [64683.1, 0.699], [64683.8, 0.201], [64684.0, 0.105], [64690.1, 0.088]], "asks": [[64692.7, 11.007], [64700.8, 0.467], [64701.0, 1.165], [64701.7, 0.078], [64704.9, 0.053], [64712.3, 0.119], [64718.9, 0.163], [64721.0, 0.262], [64721.7, 0.08], [64785.6, 1.355], [64833.6, 9.218], [64850.6, 10.412], [64889.4, 2.541], [65339.6, 5.533]]}
{"kind": "depth", "E": 1787080486825, "U": 11315357598518, "u": 11315357602971, "recv_ms": 1787080486779, "bids": [[1000.0, 35.81], [14292.6, 0.028], [14392.6, 3.724], [14492.6, 0.448], [58223.3, 0.055], [61457.9, 0.085], [62104.8, 0.001], [63692.6, 0.002], [63761.7, 14.098], [63851.4, 1.095], [64045.7, 4.913], [64369.1, 5.353], [64552.5, 0.0], [64630.4, 2.382], [64630.7, 0.172], [64663.2, 0.074], [64663.3, 0.079], [64663.4, 0.1], [64663.6, 0.101], [64663.8, 0.102], [64663.9, 0.071], [64664.1, 0.081], [64665.4, 0.112], [64692.6, 8.003]], "asks": [[64694.5, 0.005], [64695.7, 0.003], [64698.1, 0.117], [64833.6, 3.82], [65016.2, 5.102], [65339.6, 5.533], [65434.4, 0.763], [65692.7, 0.006]]}
{"kind": "depth", "E": 1787080487029, "U": 11315357606892, "u": 11315357610751, "recv_ms": 1787080486984, "bids": [[1000.0, 35.96], [14292.6, 0.448], [14392.6, 3.584], [14492.6, 0.168], [58223.3, 0.055], [61457.9, 0.085], [63398.8, 0.639], [63536.7, 0.685], [63692.6, 0.022], [63754.6, 21.186], [63888.1, 10.026], [63922.8, 9.375], [64045.7, 4.913], [64582.6, 0.002], [64611.9, 32.524], [64614.9, 0.138], [64618.5, 0.005], [64620.4, 1.649], [64663.1, 0.381], [64663.3, 0.219], [64663.7, 0.071]], "asks": [[64692.8, 0.125], [64693.6, 0.084], [64694.4, 0.098], [64695.2, 0.638], [64698.3, 0.86], [64699.5, 0.18], [64699.7, 0.561], [64705.7, 0.135], [64738.0, 0.007], [64741.9, 0.042], [64770.4, 0.022], [64833.5, 0.127], [64843.6, 0.0], [64889.4, 0.01], [64889.6, 4.923], [65339.6, 5.533], [65602.7, 56.333], [65692.7, 0.026], [65857.2, 7.063]]}
{"kind": "depth", "E": 1787080487131, "U": 11315357610767, "u": 11315357615463, "recv_ms": 1787080487086, "bids": [[1000.0, 35.81], [14292.6, 0.686], [14392.6, 3.472], [14492.6, 0.042], [51754.0, 0.0], [51754.1, 0.0], [58223.3, 0.055], [61457.9, 0.085], [62104.8, 0.001], [63398.8, 0.642], [63518.5, 1.574], [63705.6, 0.011], [63730.4, 0.796], [63989.3, 4.681], [64045.7, 4.915], [64611.9, 0.004], [64612.3, 0.218], [64616.3, 32.504], [64653.7, 0.411], [64663.8, 0.202], [64665.9, 0.157], [64666.6, 1.563], [64666.7, 0.668], [64670.5, 0.252], [64676.2, 0.01], [64676.4, 0.471], [64680.1, 0.012], [64681.0, 2.32], [64681.5, 0.586], [64686.3, 0.001], [64691.1, 0.001], [64692.6, 7.901]], "asks": [[64692.7, 13.505], [64693.2, 0.0], [64693.6, 0.0], [64694.5, 0.015], [64695.9, 0.031], [64698.3, 0.868], [64699.5, 0.172], [64699.6, 1.006], [64708.1, 0.001], [64708.7, 0.023], [64709.3, 0.556], [64710.3, 0.134], [64711.1, 0.543], [64711.9, 0.0], [64712.2, 2.376], [64713.0, 0.115], [64713.1, 0.001], [64718.6, 0.045], [64741.9, 0.0], [64889.4, 2.518], [64889.6, 0.019], [65339.6, 5.533], [65409.9, 0.0], [65499.0, 2.099], [65679.7, 0.011]]}
{"kind": "depth", "E": 1787080487233, "U": 11315357615510, "u": 11315357620923, "recv_ms": 1787080487190, "bids": [[14292.6, 0.994], [14392.6, 3.206], [14492.6, 0.0], [51754.0, 0.0], [58223.3, 0.055], [62104.8, 0.004], [63692.6, 0.002], [64045.7, 4.913], [64323.9, 0.012], [64325.9, 0.677], [64369.1, 5.363], [64420.6, 0.01], [64420.7, 0.566], [64475.0, 0.356], [64491.5, 0.001], [64491.6, 0.043], [64491.9, 0.437], [64612.3, 0.209], [64617.5, 0.009], [64644.0, 2.135], [64652.3, 2.133], [64653.7, 0.425], [64660.6, 2.132]], "asks": [[64692.7, 13.7], [64693.6, 0.084], [64698.3, 0.86], [64699.5, 0.18], [64706.7, 0.156], [64793.7, 2.155], [64793.8, 1.084], [64802.0, 2.128], [64802.1, 0.016], [64810.3, 2.126], [64810.4, 0.0], [64888.7, 0.0], [64958.5, 0.122], [64960.0, 5.862], [64960.1, 0.0], [65056.9, 1.943], [65057.5, 0.001], [65339.6, 5.533], [65692.7, 0.006], [65792.5, 8.935], [66316.3, 4.368]]}
{"kind": "depth", "E": 1787080487335, "U": 11315357621065, "u": 11315357625607, "recv_ms": 1787080487287, "bids": [[1000.0, 35.81], [14292.6, 1.358], [14392.6, 2.842], [58223.3, 0.055], [62104.8, 0.001], [64045.7, 4.913], [64060.5, 0.004], [64175.1, 10.113], [64208.1, 0.0], [64563.2, 0.009]], "asks": [[65174.6, 0.003], [65324.6, 0.0], [65339.6, 5.533], [65615.6, 1.38]]}
{"kind": "depth", "E": 1787080487437, "U": 11315357625693, "u": 11315357630098, "recv_ms": 1787080487394, "bids": [[1000.0, 35.81], [14292.6, 1.708], [14392.6, 2.492], [58223.3, 0.055], [61458.0, 0.072], [63289.4, 0.008], [63692.6, 0.022], [64045.7, 4.915], [64323.4, 42.457], [64325.9, 6.926], [64420.0, 36.598], [64491.0, 27.115], [64491.9, 4.422], [64552.5, 5.113], [64563.2, 0.008], [64616.4, 6.308], [64666.7, 0.699], [64669.6, 0.022], [64670.1, 1.031], [64670.9, 0.022], [64673.1, 0.003], [64679.6, 0.242], [64679.7, 1.005]], "asks": [[64692.7, 13.686], [64698.1, 0.137], [64713.0, 0.0], [64713.7, 0.126], [64714.9, 2.327], [64720.0, 4.521], [64833.6, 9.218], [64887.7, 27.797], [64959.1, 34.59], [65056.4, 8.461], [65056.5, 42.662], [65056.9, 0.0], [65339.6, 5.533], [65404.6, 0.586], [65692.7, 0.026], [65986.5, 0.003]]}
{"kind": "depth", "E": 1787080487641, "U": 11315357634351, "u": 11315357640047, "recv_ms": 1787080487594, "bids": [[1000.0, 35.81], [14292.6, 2.436], [14392.6, 1.764], [58223.3, 0.055], [61457.9, 0.085], [62104.8, 0.001], [63692.6, 0.002], [63883.9, 15.062], [64045.7, 4.913], [64114.5, 3.35], [64552.5, 4.56], [64570.5, 0.245], [64624.7, 2.85], [64657.3, 0.0], [64676.5, 0.0], [64687.4, 0.001], [64690.1, 0.004], [64692.6, 7.763]], "asks": [[64692.7, 13.715], [64692.8, 0.209], [64693.3, 0.087], [64695.9, 0.033], [64696.7, 2.32], [64697.3, 0.004], [64698.2, 0.513], [64698.3, 0.86], [64698.7, 0.248], [64716.8, 10.021], [64720.0, 0.157], [64720.6, 0.103], [64729.8, 0.006], [64754.9, 0.131], [64767.5, 0.017], [64830.3, 0.0], [64833.6, 9.218], [64889.4, 4.144], [65339.6, 5.533], [65581.6, 4.218], [65692.7, 0.006], [65986.5, 0.006]]}
{"kind": "depth", "E": 1787080487743, "U": 11315357640099, "u": 11315357644512, "recv_ms": 1787080487695, "bids": [[1000.0, 35.81], [14292.6, 2.786], [14392.6, 1.414], [51754.0, 0.0], [58223.3, 0.055], [62104.8, 0.004], [63599.9, 1.292], [64045.7, 4.913], [64654.6, 0.062]], "asks": [[64692.8, 0.125], [64698.1, 0.137], [64698.2, 0.441], [64698.7, 0.248], [64755.5, 0.064], [64755.7, 0.0], [64889.4, 0.01], [64889.6, 5.206], [65157.3, 0.004], [65339.6, 5.533], [65448.1, 1.082]]}
{"kind": "depth", "E": 1787080487845, "U": 11315357644609, "u": 11315357650097, "recv_ms": 1787080487797, "bids": [[14292.6, 3.136], [14392.6, 1.064], [58223.3, 0.055], [61457.9, 0.085], [62104.8, 0.001], [63692.6, 0.022], [64045.7, 4.913], [64110.4, 11.652], [64369.1, 5.363], [64690.0, 0.087]], "asks": [[64692.7, 13.714], [64889.4, 2.518], [64889.6, 0.019], [65016.2, 5.102], [65305.8, 4.508], [65307.3, 7.808], [65339.6, 5.533], [65396.3, 0.0], [65501.4, 16.307], [65511.2, 1.526], [65538.0, 20.826], [65590.4, 3.955], [65692.7, 0.026], [71162.0, 0.0]]}
{"kind": "depth", "E": 1787080487947, "U": 11315357650323, "u": 11315357656297, "recv_ms": 1787080487898, "bids": [[1000.0, 35.81], [14292.6, 3.5], [14392.6, 0.7], [58223.3, 0.055], [63592.8, 22.05], [64045.7, 4.913], [64552.5, 0.0], [64627.9, 0.036], [64674.4, 0.018], [64674.6, 0.155]], "asks": [[64705.4, 0.642], [64705.8, 0.005], [64757.4, 0.402], [64833.6, 3.82], [65279.2, 16.058], [65339.6, 5.533], [65449.6, 3.205], [65478.6, 1.527]]}
{"kind": "depth", "E": 1787080488049, "U": 11315357656367, "u": 11315357660819, "recv_ms": 1787080488001, "bids": [[1000.0, 35.81], [14192.6, 0.056], [14292.6, 3.738], [14392.6, 0.406], [58223.3, 0.055], [61457.9, 0.085], [61458.0, 0.07], [61458.1, 0.013], [62104.8, 0.004], [63692.6, 0.002], [64045.7, 4.913], [64552.5, 4.56], [64590.1, 0.002], [64590.2, 0.016], [64616.3, 0.0], [64616.4, 0.003], [64617.5, 0.0], [64618.5, 32.509], [64681.0, 2.325], [64686.3, 0.085], [64687.4, 0.001], [64689.7, 0.0], [64690.0, 0.003], [64690.6, 0.0], [64692.6, 7.686]], "asks": [[64692.7, 13.798], [64699.6, 1.005], [64712.2, 7.376], [64729.0, 0.034], [64729.2, 0.019], [64757.4, 0.393], [64833.5, 0.103], [64833.6, 9.218], [64843.6, 0.024], [64850.6, 0.003], [64850.7, 7.185], [64881.2, 0.002], [64881.3, 0.005], [64889.4, 0.01], [64889.6, 7.867], [65151.6, 0.115], [65339.6, 5.533], [65692.7, 0.006]]}
{"kind": "depth", "E": 1787080488151, "U": 11315357660962, "u": 11315357664872, "recv_ms": 1787080488107, "bids": [[14192.6, 0.266], [14292.6, 3.682], [14392.6, 0.252], [51754.0, 0.048], [51754.1, 0.0], [58223.3, 0.055], [61457.9, 0.085], [62104.8, 0.001], [63082.3, 1.267], [63612.8, 1.321], [64045.7, 4.913], [64149.1, 0.268], [64369.1, 5.363], [64672.3, 0.007], [64673.2, 2.892], [64676.2, 0.01], [64679.4, 0.384], [64679.5, 0.618], [64681.0, 2.32], [64687.4, 0.001], [64691.4, 0.002], [64691.5, 0.089], [64692.0, 0.022]], "asks": [[64692.7, 13.784], [64699.5, 0.181], [64708.7, 0.023], [64833.5, 0.127], [64843.6, 0.0], [64850.7, 8.286], [64889.6, 4.771], [65339.6, 5.533], [65397.9, 7.928], [65505.6, 4.388], [65533.8, 5.332], [65591.9, 5.236]]}
{"kind": "depth", "E": 1787080488253, "U": 11315357664942, "u": 11315357669523, "recv_ms": 1787080488206, "bids": [[1000.0, 35.81], [14192.6, 0.504], [14292.6, 3.556], [14392.6, 0.14], [51754.0, 0.002], [58223.3, 0.055], [62104.8, 0.004], [63692.6, 0.022], [63698.5, 0.0], [63740.1, 4.385], [63774.0, 2.61], [64045.7, 4.913], [64059.5, 64.778], [64114.4, 2.179], [64149.1, 0.44], [64660.4, 0.002], [64679.5, 0.618], [64680.8, 0.003], [64689.6, 0.085], [64692.6, 7.784]], "asks": [[64699.5, 0.18], [64705.4, 0.024], [64712.7, 0.829], [64713.7, 0.011], [64729.0, 0.004], [64729.2, 0.049], [64757.4, 0.411], [65274.9, 3.595], [65323.9, 63.948], [65339.6, 5.533], [65452.5, 0.033], [65692.7, 0.026]]}
{"kind": "depth", "E": 1787080488355, "U": 11315357669552, "u": 11315357673827, "recv_ms": 1787080488306, "bids": [[1000.0, 35.81], [14192.6, 0.742], [14292.6, 3.444], [14392.6, 0.014], [51754.0, 0.0], [58223.3, 0.055], [62104.8, 0.001], [63605.8, 3.135], [64045.7, 4.913], [64110.2, 1.094], [64563.2, 0.009], [64611.9, 32.512], [64614.9, 0.138], [64618.5, 0.005], [64687.4, 0.181]], "asks": [[64699.1, 0.285], [64701.8, 0.001], [64712.7, 0.714], [64713.1, 0.116], [64738.0, 0.007], [65339.6, 5.533], [65824.1, 0.0], [65986.5, 0.009]]}
{"kind": "depth", "E": 1787080488457, "U": 11315357673948, "u": 11315357677796, "recv_ms": 1787080488409, "bids": [[14192.6, 1.078], [14292.6, 3.122], [14392.6, 0.0], [58223.3, 0.055], [61457.9, 0.085], [63692.6, 0.002], [64045.7, 4.913], [64369.1, 5.363], [64420.7, 5.535], [64552.5, 5.113], [64563.2, 0.008], [64612.0, 5.944], [64612.3, 0.218], [64660.4, 0.988], [64687.4, 0.001], [64690.0, 0.087], [64692.6, 7.785]], "asks": [[64692.7, 13.7], [64707.5, 0.006], [64712.2, 2.376], [64721.0, 3.038], [64782.8, 0.101], [64833.6, 9.218], [64889.4, 2.519], [64889.6, 0.019], [64959.0, 8.959], [65339.6, 5.533], [65414.1, 0.993], [65549.5, 0.0], [65692.7, 0.006]]}
{"kind": "depth", "E": 1787080488559, "U": 11315357677994, "u": 11315357682613, "recv_ms": 1787080488514, "bids": [[1000.0, 35.81], [14192.6, 1.442], [14292.6, 2.758], [58223.3, 0.057], [61457.9, 0.085], [61458.0, 0.072], [62104.8, 0.004], [63692.6, 0.022], [63741.6, 7.203], [64045.7, 4.913], [64149.1, 0.416], [64552.5, 0.0], [64582.6, 0.005], [64666.7, 0.696], [64676.5, 0.618], [64686.3, 0.001], [64690.4, 0.085], [64690.7, 0.312], [64692.6, 7.8]], "asks": [[64693.3, 0.003], [64705.4, 0.642], [64705.7, 0.138], [64760.3, 0.024], [64770.4, 0.025], [64833.6, 3.82], [65339.6, 5.533], [65462.5, 9.159], [65692.7, 0.026]]}
{"kind": "depth", "E": 1787080488661, "U": 11315357682619, "u": 11315357686662, "recv_ms": 1787080488615, "bids": [[1000.0, 35.81], [14192.6, 1.792], [14292.6, 2.408], [51754.0, 0.0], [58223.3, 0.055], [62104.8, 0.001], [63883.9, 15.296], [64045.7, 4.915], [64369.1, 5.363], [64552.5, 4.559], [64611.9, 0.004], [64612.0, 0.374], [64616.3, 32.508], [64635.6, 1.635], [64673.1, 5.003], [64676.5, 0.0], [64686.7, 0.034], [64687.3, 0.629], [64690.8, 0.233], [64692.6, 7.825]], "asks": [[64692.7, 11.45], [64693.5, 0.086], [64693.6, 0.0], [64694.5, 0.005], [64695.9, 0.021], [64696.8, 0.002], [64697.2, 0.095], [64705.4, 0.024], [64712.7, 0.096], [64721.3, 0.28], [64833.6, 9.218], [64889.4, 4.145], [65339.6, 5.535]]}
{"kind": "depth", "E": 1787080488763, "U": 11315357686669, "u": 11315357691230, "recv_ms": 1787080488716, "bids": [[14192.6, 2.156], [14292.6, 2.044], [58223.3, 0.055], [61457.9, 0.085], [62104.8, 0.004], [63519.1, 2.022], [63787.5, 0.951], [63791.0, 41.645], [64045.7, 4.913], [64612.3, 0.209], [64617.5, 0.009], [64686.7, 0.214]], "asks": [[65339.6, 5.533], [65533.7, 17.368], [65598.4, 19.449], [65679.1, 0.0], [65823.5, 1.518]]}
{"kind": "depth", "E": 1787080489069, "U": 11315357700304, "u": 11315357706366, "recv_ms": 1787080489021, "bids": [[14192.6, 3.22], [14292.6, 0.98], [58223.3, 0.055], [62104.8, 0.01], [63692.6, 0.022], [63780.4, 5.041], [64045.7, 4.913], [64552.5, 5.105], [64575.0, 0.633], [64575.1, 3.868], [64620.9, 0.0], [64621.0, 0.061], [64681.0, 2.32], [64687.3, 0.809]], "asks": [[64695.1, 0.002], [64763.3, 0.0], [64763.4, 0.152], [64827.6, 3.865], [64833.6, 9.218], [65339.6, 5.533], [65415.4, 0.0], [65692.7, 0.026]]}
{"kind": "depth", "E": 1787080489171, "U": 11315357706452, "u": 11315357711425, "recv_ms": 1787080489124, "bids": [[1000.0, 35.81], [14192.6, 3.584], [14292.6, 0.616], [51754.1, 0.0], [58223.3, 0.055], [61457.9, 0.085], [62104.8, 0.007], [63289.4, 0.01], [63888.1, 9.441], [63892.2, 0.782], [64045.7, 4.913], [64149.1, 0.407], [64552.5, 5.105], [64575.1, 0.004], [64575.3, 3.868], [64584.1, 0.077], [64584.2, 2.697], [64621.0, 0.061], [64638.2, 0.0], [64643.4, 0.25], [64644.2, 3.537], [64645.4, 0.015], [64653.7, 0.411], [64659.7, 0.028], [64659.8, 0.451], [64659.9, 0.003], [64662.0, 0.283], [64663.1, 0.381], [64663.2, 0.144], [64663.3, 0.219], [64665.8, 0.389], [64666.7, 0.665], [64668.1, 0.001], [64669.0, 0.558], [64669.1, 0.002], [64673.2, 1.966], [64674.6, 1.081], [64676.2, 0.01], [64687.0, 0.003], [64687.3, 0.629], [64687.4, 0.181], [64688.2, 0.395], [64690.8, 0.317], [64691.5, 0.047], [64691.6, 0.067], [64691.9, 0.021], [64692.3, 0.019], [64692.4, 0.002], [64692.6, 9.036]], "asks": [[64692.7, 11.255], [64693.5, 0.002], [64694.0, 0.002], [64694.4, 0.014], [64694.5, 0.089], [64696.6, 0.601], [64697.6, 0.094], [64698.0, 0.265], [64698.1, 0.121], [64698.3, 0.319], [64700.2, 1.302], [64701.0, 0.265], [64708.7, 0.023], [64709.4, 0.915], [64711.1, 0.002], [64711.9, 0.541], [64713.1, 0.001], [64713.7, 0.126], [64716.0, 0.023], [64716.4, 6.029], [64716.8, 10.023], [64741.9, 0.042], [64763.4, 0.152], [64801.5, 2.49], [64801.7, 2.331], [64827.6, 3.865], [64833.6, 9.218], [65339.6, 5.533], [65611.3, 2.046], [65986.5, 0.009]]}
{"kind": "depth", "E": 1787080489273, "U": 11315357711554, "u": 11315357715452, "recv_ms": 1787080489224, "bids": [[1000.0, 35.81], [14192.6, 3.766], [14292.6, 0.35], [14592.6, 0.084], [51754.0, 0.0], [58223.3, 0.055], [62104.8, 0.01], [63601.0, 2.952], [63692.6, 0.002], [63794.5, 0.783], [64045.7, 4.913], [64369.1, 5.353], [64668.4, 0.559], [64669.0, 0.001], [64673.5, 0.931], [64674.6, 0.155], [64691.2, 0.133], [64692.5, 0.623]], "asks": [[64692.7, 11.26], [64694.5, 0.099], [64702.0, 0.903], [64712.8, 0.352], [64713.7, 0.011], [65339.6, 5.533], [65692.7, 0.006]]}
{"kind": "depth", "E": 1787080489375, "U": 11315357715550, "u": 11315357721013, "recv_ms": 1787080489327, "bids": [[14192.6, 3.654], [14292.6, 0.224], [14592.6, 0.322], [51754.0, 0.0], [58223.3, 0.055], [61457.9, 0.085], [63606.4, 1.254], [63920.4, 27.549], [64045.7, 4.913], [64552.5, 0.0], [64563.2, 0.009], [64652.8, 0.377], [64656.0, 0.776], [64660.3, 2.763]], "asks": [[64694.5, 0.089], [64695.9, 0.031], [64703.3, 0.059], [64710.8, 1.53], [64833.6, 3.82], [65339.6, 5.533], [65410.3, 0.561], [65614.2, 0.019], [65646.6, 1.194], [66196.6, 0.001]]}
{"kind": "depth", "E": 1787080489477, "U": 11315357721191, "u": 11315357724834, "recv_ms": 1787080489432, "bids": [[1000.0, 35.81], [14192.6, 3.528], [14292.6, 0.112], [14592.6, 0.56], [51754.0, 0.0], [58223.3, 0.055], [61458.1, 0.009], [62104.8, 0.007], [63692.6, 0.022], [64045.7, 4.913], [64535.5, 8.583], [64552.5, 5.105], [64563.2, 0.008], [64616.4, 6.309], [64666.7, 0.696], [64675.8, 0.187], [64679.0, 1.275], [64679.5, 0.464], [64687.4, 0.181], [64688.2, 0.085]], "asks": [[64694.2, 0.085], [64694.5, 0.099], [64695.9, 0.021], [64712.8, 0.237], [64713.2, 0.332], [64714.7, 3.418], [64833.5, 0.103], [64833.6, 9.218], [64843.6, 0.024], [64850.6, 10.412], [64850.7, 0.003], [65279.3, 1.109], [65339.6, 5.533], [65630.7, 21.721], [65692.7, 0.026], [65986.5, 0.012]]}
{"kind": "depth", "E": 1787080489579, "U": 11315357724960, "u": 11315357728499, "recv_ms": 1787080489533, "bids": [[1000.0, 35.81], [14192.6, 3.388], [14292.6, 0.0], [14592.6, 0.812], [58223.3, 0.055], [61457.9, 0.085], [62104.8, 0.01], [63897.6, 2.98], [64045.6, 0.001], [64045.7, 4.913], [64369.1, 5.363], [64570.6, 0.0], [64582.6, 0.002], [64614.9, 0.138], [64624.8, 0.0], [64635.6, 1.649], [64643.4, 0.278], [64653.7, 0.425], [64656.3, 0.017], [64657.4, 0.04], [64669.1, 0.002], [64669.7, 0.19], [64670.1, 0.915], [64670.3, 0.469], [64673.2, 0.001], [64676.5, 0.0], [64680.1, 0.553], [64681.5, 0.045], [64686.7, 0.034], [64687.1, 0.084], [64687.4, 0.181], [64690.4, 0.001], [64690.8, 0.233], [64691.2, 0.049], [64692.6, 8.935]], "asks": [[64692.7, 13.614], [64693.1, 0.086], [64693.8, 0.086], [64695.9, 0.031], [64696.5, 0.087], [64696.6, 0.037], [64697.6, 0.01], [64698.0, 0.181], [64698.1, 0.685], [64702.3, 0.013], [64705.3, 0.0], [64708.5, 0.867], [64709.3, 0.0], [64710.3, 0.675], [64711.9, 0.0], [64712.7, 0.096], [64714.9, 2.323], [64716.0, 0.009], [64729.9, 0.002], [64738.0, 0.004], [64739.3, 1.348], [64741.9, 0.0], [64767.6, 0.015], [64770.4, 0.022], [64830.5, 0.001], [65339.6, 5.533], [65598.4, 21.732], [65615.6, 1.153]]}
{"kind": "depth", "E": 1787080489681, "U": 11315357728560, "u": 11315357732303, "recv_ms": 1787080489636, "bids": [[14192.6, 3.024], [14592.6, 1.176], [58223.3, 0.055], [61457.9, 0.085], [61458.1, 0.007], [62104.8, 0.007], [63692.6, 0.002], [64045.7, 4.915], [64552.5, 5.112], [64616.3, 0.0], [64616.4, 0.003], [64618.5, 32.498], [64621.6, 0.001], [64644.2, 0.037], [64660.4, 0.002], [64665.8, 0.053], [64686.4, 0.086], [64686.7, 0.118], [64689.6, 0.001], [64690.0, 0.003], [64690.7, 0.002], [64692.5, 0.675], [64692.6, 8.937]], "asks": [[64692.7, 13.628], [64693.7, 0.0], [64701.0, 1.165], [64701.3, 1.215], [64701.5, 0.508], [64702.0, 0.003], [64702.6, 0.052], [64717.5, 12.532], [64719.5, 1.242], [64733.3, 0.909], [64735.6, 0.003], [64758.3, 0.025], [64833.5, 0.127], [64833.6, 3.82], [64833.7, 5.398], [64843.6, 0.0], [64889.4, 0.01], [64889.5, 4.09], [65275.0, 8.436], [65279.3, 0.038], [65339.6, 5.533], [65597.0, 9.83], [65598.4, 22.645], [65692.7, 0.006], [66180.6, 3.259], [67927.3, 0.006]]}
{"kind": "depth", "E": 1787080489783, "U": 11315357732304, "u": 11315357736032, "recv_ms": 1787080489735, "bids": [[1000.0, 35.81], [14192.6, 2.674], [14592.6, 1.526], [51754.0, 0.006], [58223.3, 0.055], [61457.9, 0.085], [62104.8, 0.01], [64045.7, 4.913], [64149.1, 0.431], [64588.6, 0.013], [64588.7, 1.017], [64617.5, 0.0], [64620.1, 0.013], [64661.9, 1.271], [64670.3, 0.465]], "asks": [[64692.7, 13.634], [64717.5, 2.532], [64790.4, 2.216], [64790.7, 0.004], [64833.5, 0.103], [64843.6, 0.024], [65275.0, 9.507], [65339.6, 5.533], [66276.0, 0.0]]}
{"kind": "depth", "E": 1787080489885, "U": 11315357736123, "u": 11315357740091, "recv_ms": 1787080489836, "bids": [[1000.0, 35.81], [14192.6, 2.31], [14592.6, 1.89], [51754.0, 0.0], [58223.3, 0.055], [62104.8, 0.004], [63398.8, 0.639], [63692.6, 0.022], [63916.3, 40.888], [63985.1, 1.404], [64045.7, 4.913], [64369.1, 5.352], [64552.5, 5.105], [64586.0, 0.509], [64588.7, 1.009], [64622.3, 7.91], [64635.6, 1.635], [64638.2, 0.028], [64644.9, 4.975], [64661.1, 1.087], [64679.6, 0.242], [64679.7, 1.005], [64689.8, 0.357], [64690.6, 0.31]], "asks": [[64692.7, 13.633], [64708.5, 0.311], [64709.3, 0.556], [64719.6, 1.448], [64733.3, 1.373], [64735.7, 3.569], [64741.9, 0.0], [64758.4, 6.001], [64759.0, 0.375], [64759.1, 0.021], [64764.9, 6.265], [64765.7, 37.978], [64790.3, 0.0], [64790.9, 0.008], [64833.6, 9.218], [64833.7, 0.0], [64889.4, 2.542], [64889.5, 0.012], [65016.2, 5.101], [65339.6, 5.533], [65692.7, 0.026], [71162.0, 0.0]]}
{"kind": "depth", "E": 1787080489987, "U": 11315357740164, "u": 11315357745604, "recv_ms": 1787080489939, "bids": [[14192.6, 1.96], [14592.6, 2.24], [58223.3, 0.055], [61457.9, 0.085], [61458.1, 0.005], [62104.8, 0.001], [63075.3, 1.584], [63398.8, 0.642], [63680.9, 1.345], [63726.3, 5.102], [63768.3, 0.0], [64045.7, 4.913], [64175.1, 9.179], [64369.1, 5.353], [64589.4, 10.0], [64635.6, 1.663], [64674.0, 0.295], [64687.4, 0.181], [64689.8, 0.273], [64690.6, 0.0], [64692.6, 9.035]], "asks": [[64692.7, 13.638], [64762.6, 0.012], [64787.2, 4.088], [64790.0, 10.008], [64833.5, 0.127], [64843.6, 0.0], [64889.4, 0.01], [64889.5, 4.305], [65016.2, 5.102], [65339.6, 5.533], [65501.4, 16.535], [65508.6, 3.323]]}
{"kind": "depth", "E": 1787080490089, "U": 11315357745721, "u": 11315357750652, "recv_ms": 1787080490045, "bids": [[1000.0, 35.81], [14192.6, 1.61], [14592.6, 2.59], [51754.0, 0.0], [58223.3, 0.055], [61457.9, 0.085], [62104.8, 0.004], [63692.6, 0.002], [63705.6, 0.0], [63981.0, 6.787], [64045.7, 4.913], [64586.0, 0.501], [64589.5, 0.009], [64681.0, 2.32], [64689.4, 0.003]], "asks": [[64692.7, 13.639], [64714.8, 3.519], [64714.9, 2.325], [64760.0, 1.368], [64761.3, 36.602], [64762.6, 0.003], [64764.9, 0.677], [64765.7, 1.381], [64789.9, 0.105], [64790.9, 0.0], [64889.4, 2.681], [64889.5, 0.012], [65339.6, 5.533], [65642.2, 1.599], [65679.7, 0.0], [65692.7, 0.006], [65802.3, 1.542], [65840.7, 0.0]]}
{"kind": "depth", "E": 1787080490191, "U": 11315357750824, "u": 11315357756712, "recv_ms": 1787080490145, "bids": [[1000.0, 35.81], [14192.6, 1.246], [14592.6, 2.954], [51754.0, 0.0], [51754.1, 0.0], [58223.3, 0.055], [62104.8, 0.001], [62223.8, 0.003], [63692.6, 0.022], [63730.4, 0.012], [64045.7, 4.913], [64114.5, 3.116], [64145.0, 0.234], [64149.1, 0.407], [64175.1, 10.113], [64369.1, 5.353], [64582.6, 0.005], [64635.6, 1.635], [64636.6, 0.023], [64653.7, 0.422], [64667.7, 0.558], [64668.4, 0.002], [64672.4, 0.0], [64672.7, 0.937], [64673.5, 0.005], [64676.2, 0.008], [64677.3, 0.007], [64680.1, 0.012], [64681.5, 0.586], [64692.6, 9.091]], "asks": [[64700.2, 1.301], [64701.0, 2.382], [64701.3, 0.428], [64703.0, 0.901], [64705.0, 0.018], [64708.7, 0.021], [64710.3, 0.134], [64711.1, 0.543], [64718.6, 0.042], [64738.0, 0.007], [65339.6, 5.533], [65692.7, 0.026]]}
{"kind": "depth", "E": 1787080490293, "U": 11315357756790, "u": 11315357760970, "recv_ms": 1787080490248, "bids": [[14192.6, 0.896], [14592.6, 3.304], [51754.0, 0.0], [58223.3, 0.055], [61457.9, 0.085], [63722.2, 21.14], [63914.9, 13.477], [64045.7, 4.913], [64584.2, 2.697], [64653.7, 0.408], [64667.7, 0.001], [64668.6, 0.558], [64676.2, 0.01], [64687.3, 0.809], [64687.4, 0.001], [64689.6, 0.085], [64689.9, 0.085], [64691.0, 0.31], [64692.6, 9.036]], "asks": [[64692.7, 13.646], [64696.0, 0.383], [64696.8, 0.0], [64708.7, 0.023], [64800.3, 2.714], [64801.7, 0.012], [65339.6, 5.533], [65501.4, 16.649], [65643.7, 5.701], [65824.8, 6.204]]}
{"kind": "depth", "E": 1787080490497, "U": 11315357765019, "u": 11315357768920, "recv_ms": 1787080490449, "bids": [[1000.0, 35.81], [14192.6, 0.322], [14492.6, 0.14], [14592.6, 3.738], [58223.3, 0.055], [61457.9, 0.085], [62104.8, 0.001], [63692.6, 0.002], [63794.5, 0.0], [63883.9, 15.53], [63916.3, 40.186], [63923.9, 0.002], [64045.6, 0.0], [64045.7, 4.913], [64110.4, 11.886], [64369.1, 5.363], [64570.5, 0.245], [64620.4, 6.297], [64624.7, 2.85], [64635.6, 1.649], [64644.2, 0.035], [64644.9, 4.977], [64653.7, 0.422], [64657.3, 0.0], [64687.4, 0.001], [64692.6, 7.736]], "asks": [[64705.0, 0.918], [64720.0, 0.155], [64721.1, 4.094], [64722.1, 0.159], [64729.8, 0.006], [64760.4, 6.555], [64767.5, 0.017], [64830.4, 1.208], [65339.6, 5.533], [65692.7, 0.006], [65802.1, 1.518]]}
{"kind": "depth", "E": 1787080490599, "U": 11315357769049, "u": 11315357773145, "recv_ms": 1787080490558, "bids": [[14192.6, 0.196], [14492.6, 0.378], [14592.6, 3.626], [58223.3, 0.055], [61457.9, 0.085], [62104.8, 0.004], [63757.0, 8.786], [63786.9, 26.879], [63916.3, 41.749], [63950.9, 0.001], [64045.7, 4.913], [64552.5, 5.105], [64634.7, 0.015], [64666.7, 0.699], [64669.0, 0.619], [64676.4, 1.089], [64689.6, 0.001], [64689.9, 0.001], [64690.6, 0.0], [64691.0, 0.0]], "asks": [[64692.7, 13.345], [64704.0, 2.855], [64705.3, 0.618], [64712.6, 0.637], [64718.6, 0.045], [64770.4, 0.025], [64833.6, 3.82], [64833.7, 5.386], [64889.4, 0.01], [64889.5, 4.726], [65210.2, 5.821], [65339.6, 5.533], [65663.8, 0.077], [65909.8, 0.0]]}
{"kind": "depth", "E": 1787080490701, "U": 11315357773254, "u": 11315357777070, "recv_ms": 1787080490654, "bids": [[1000.0, 35.81], [14192.6, 0.084], [14492.6, 0.616], [14592.6, 3.5], [58223.3, 0.055], [62104.8, 0.001], [63075.3, 1.505], [63692.6, 0.022], [63791.9, 1.876], [63916.3, 42.451], [63951.0, 0.0], [64045.7, 4.913], [64149.1, 0.402], [64609.7, 32.543], [64614.9, 0.147], [64618.5, 0.005], [64620.4, 1.649], [64690.8, 0.245], [64691.4, 0.05], [64691.5, 0.0], [64691.6, 0.023], [64692.2, 0.0], [64692.5, 0.623]], "asks": [[64692.7, 13.346], [64707.0, 0.318], [65339.6, 5.533], [65581.9, 2.686], [65642.2, 1.066], [65692.7, 0.026], [65902.5, 4.512]]}
{"kind": "depth", "E": 1787080490803, "U": 11315357777161, "u": 11315357781620, "recv_ms": 1787080490756, "bids": [[1000.0, 35.81], [14192.6, 0.0], [14492.6, 0.896], [14592.6, 3.304], [58223.3, 0.055], [63536.7, 0.011], [63943.0, 0.157], [64045.7, 4.913], [64149.1, 0.397], [64369.1, 5.363], [64612.3, 0.218]], "asks": [[64833.5, 0.103], [64843.6, 0.024], [65312.2, 0.014], [65339.6, 5.533], [65590.4, 2.434], [65986.5, 0.015]]}
{"kind": "depth", "E": 1787080490905, "U": 11315357781814, "u": 11315357785945, "recv_ms": 1787080490859, "bids": [[14492.6, 1.246], [14592.6, 2.954], [58223.3, 0.055], [61457.9, 0.085], [62104.8, 0.004], [63692.6, 0.002], [63722.2, 21.132], [63726.3, 4.749], [63749.1, 0.094], [63777.1, 7.829], [63793.4, 9.391], [63874.3, 0.782], [63883.9, 15.881], [63942.4, 0.912], [63989.3, 3.901], [64045.7, 4.913], [64369.1, 5.362], [64535.5, 0.001], [64536.7, 0.404], [64552.5, 0.0], [64582.6, 0.002], [64614.9, 0.144], [64634.3, 0.004], [64669.0, 0.001], [64673.1, 0.003], [64676.4, 0.471]], "asks": [[64692.7, 13.645], [64705.3, 0.0], [64738.0, 0.007], [64770.4, 0.022], [64833.7, 0.0], [64850.6, 0.003], [65210.2, 9.343], [65339.6, 5.533], [65591.9, 6.757], [65667.4, 16.679], [65692.7, 0.006]]}
{"kind": "depth", "E": 1787080491007, "U": 11315357786022, "u": 11315357789451, "recv_ms": 1787080490961, "bids": [[1000.0, 35.81], [14492.6, 1.61], [14592.6, 2.59], [34000.0, 1.146], [58223.3, 0.055], [62104.8, 0.001], [63075.3, 1.584], [63583.2, 2.355], [64045.7, 4.913], [64369.1, 5.363], [64496.7, 15.505], [64499.0, 2.824], [64535.5, 8.413], [64536.7, 1.594], [64552.5, 5.024], [64609.7, 0.118], [64618.5, 32.43], [64625.3, 0.006], [64669.7, 0.074], [64669.9, 0.37], [64670.8, 0.014], [64672.7, 0.011], [64673.3, 0.931], [64674.2, 0.08], [64679.0, 1.121], [64679.9, 0.156]], "asks": [[64710.4, 1.185], [64711.1, 0.002], [64711.9, 0.0], [64713.2, 0.217], [64713.6, 0.173], [64833.6, 9.218], [64850.6, 10.412], [64889.4, 2.787], [64889.5, 0.012], [65016.2, 5.102], [65313.7, 1.685], [65339.6, 5.535], [65643.7, 6.234]]}
{"kind": "depth", "E": 1787080491109, "U": 11315357789491, "u": 11315357795315, "recv_ms": 1787080491068, "bids": [[1000.0, 35.81], [14492.6, 1.974], [14592.6, 2.226], [58223.3, 0.055], [62104.8, 0.004], [63599.3, 2.063], [63692.6, 0.022], [63722.2, 21.485], [63916.3, 42.67], [64045.7, 4.915], [64369.1, 5.353], [64570.4, 0.001], [64612.3, 0.209], [64614.9, 0.135], [64624.7, 2.85], [64657.2, 0.061], [64666.7, 0.668], [64670.4, 2.417], [64677.0, 0.901], [64681.0, 2.32], [64689.7, 0.084], [64692.5, 0.675], [64692.6, 7.503]], "asks": [[64692.7, 13.414], [64712.6, 0.019], [64729.7, 0.014], [64739.3, 1.376], [64767.4, 0.002], [64830.3, 0.0], [64833.5, 0.127], [64843.6, 0.0], [65339.6, 5.533], [65692.7, 0.026]]}
{"kind": "depth", "E": 1787080491211, "U": 11315357795327, "u": 11315357801143, "recv_ms": 1787080491164, "bids": [[14492.6, 2.324], [14592.6, 1.876], [51754.1, 0.0], [58223.3, 0.055], [61457.9, 0.085], [62104.8, 0.001], [63535.3, 0.0], [63537.1, 0.002], [64045.7, 4.913], [64552.5, 0.0], [64676.2, 0.008], [64687.3, 0.629]], "asks": [[64699.3, 0.382], [64708.7, 0.021], [64722.1, 0.005], [64833.6, 3.82], [65210.2, 9.648], [65339.6, 5.533], [65602.7, 56.15], [65986.5, 0.018]]}
{"kind": "depth", "E": 1787080491415, "U": 11315357806406, "u": 11315357811902, "recv_ms": 1787080491369, "bids": [[14492.6, 3.038], [14592.6, 1.162], [58223.3, 0.055], [61457.9, 0.085], [62104.8, 0.004], [63601.0, 2.167], [63722.3, 0.023], [63989.3, 3.121], [64045.7, 4.913], [64149.1, 0.332], [64369.1, 5.363], [64496.7, 0.0], [64499.0, 0.568], [64563.2, 0.008], [64656.5, 1.976], [64666.7, 0.698], [64680.0, 1.833], [64680.1, 0.012]], "asks": [[64889.4, 0.01], [65339.6, 5.533]]}
{"kind": "depth", "E": 1787080491517, "U": 11315357812002, "u": 11315357818387, "recv_ms": 1787080491470, "bids": [[14492.6, 3.388], [14592.6, 0.812], [58223.3, 0.055], [62104.8, 0.001], [63466.2, 0.0], [63855.7, 11.179], [64045.7, 4.913], [64149.1, 0.308], [64496.7, 15.505], [64535.5, 8.486], [64552.5, 5.059], [64592.0, 2.591], [64620.4, 6.286], [64679.7, 1.159], [64680.0, 1.679]], "asks": [[64722.2, 0.167], [64833.6, 9.218], [64850.6, 10.412], [64883.2, 0.324], [64889.4, 2.681], [65339.6, 5.533], [65615.6, 0.926], [66254.3, 1.293]]}
{"kind": "depth", "E": 1787080491619, "U": 11315357818417, "u": 11315357825796, "recv_ms": 1787080491575, "bids": [[1000.0, 35.81], [14392.6, 0.028], [14492.6, 3.696], [14592.6, 0.476], [51754.0, 0.0], [58223.3, 0.055], [62104.8, 0.004], [63692.6, 0.022], [64045.7, 4.913], [64552.5, 5.112], [64656.3, 0.003], [64667.7, 0.558], [64668.6, 0.001], [64669.2, 0.117], [64669.9, 0.254], [64672.7, 0.937], [64673.3, 0.005], [64680.1, 0.012], [64681.5, 0.586], [64690.1, 0.088]], "asks": [[64695.9, 0.021], [64706.0, 0.232], [64708.1, 0.001], [64709.3, 0.556], [64712.1, 1.265], [64713.1, 0.116], [64713.6, 0.058], [64722.2, 0.013], [64722.3, 1.273], [64833.6, 9.218], [64889.4, 2.52], [65339.6, 5.533], [65692.7, 0.026]]}
{"kind": "depth", "E": 1787080491721, "U": 11315357826014, "u": 11315357831875, "recv_ms": 1787080491673, "bids": [[14392.6, 0.196], [14492.6, 3.71], [14592.6, 0.294], [58223.3, 0.057], [61457.9, 0.085], [61458.0, 0.072], [61458.1, 0.007], [63712.6, 3.165], [63778.1, 1.961], [63786.9, 29.228], [63891.1, 5.68], [64045.7, 4.913], [64369.1, 5.363], [64541.9, 0.735], [64652.0, 1.739], [64653.7, 0.408], [64659.7, 0.03], [64659.8, 0.453], [64659.9, 0.005], [64663.1, 0.383], [64663.2, 0.146], [64663.3, 0.221], [64675.1, 0.043], [64682.5, 0.309]], "asks": [[64692.7, 12.61], [64694.5, 0.089], [64695.3, 0.486], [64696.0, 0.381], [64696.8, 0.002], [64712.2, 2.376], [64719.5, 1.242], [64726.9, 0.0], [64741.9, 0.0], [64806.3, 0.086], [64833.5, 0.127], [64843.6, 0.0], [64883.2, 0.006], [65339.6, 5.533]]}
{"kind": "depth", "E": 1787080491925, "U": 11315357838009, "u": 11315357843320, "recv_ms": 1787080491882, "bids": [[1000.0, 35.81], [14392.6, 0.672], [14492.6, 3.486], [14592.6, 0.042], [58223.3, 0.055], [61457.9, 0.085], [62104.8, 0.004], [63692.6, 0.022], [64045.7, 4.913], [64149.1, 0.284], [64570.4, 0.001], [64624.7, 2.85], [64657.2, 0.061], [64669.2, 0.001], [64670.0, 1.529], [64671.0, 0.005], [64672.7, 0.011], [64673.5, 0.931], [64674.3, 0.0], [64680.1, 0.553], [64681.5, 0.045], [64690.1, 0.004], [64692.6, 7.523]], "asks": [[64692.7, 12.617], [64707.9, 0.009], [64709.7, 0.026], [64710.4, 0.644], [64711.9, 0.541], [64713.1, 0.001], [64713.8, 0.123], [64722.4, 1.628], [64729.7, 0.014], [64767.4, 0.002], [64830.3, 0.0], [65339.6, 5.535], [65692.7, 0.026]]}
{"kind": "depth", "E": 1787080492027, "U": 11315357843347, "u": 11315357848370, "recv_ms": 1787080491981, "bids": [[14392.6, 0.98], [14492.6, 3.22], [14592.6, 0.0], [58223.3, 0.055], [62104.8, 0.001], [63599.3, 2.69], [63776.9, 1.737], [63883.9, 16.194], [64045.7, 4.913], [64369.1, 5.363], [64552.5, 5.013], [64690.7, 0.312]], "asks": [[64692.7, 12.635], [64722.5, 1.155], [64833.6, 9.218], [65015.2, 0.002], [65015.8, 0.109], [65016.2, 5.101], [65339.6, 5.533]]}
{"kind": "depth", "E": 1787080492129, "U": 11315357848418, "u": 11315357854153, "recv_ms": 1787080492088, "bids": [[14392.6, 1.33], [14492.6, 2.87], [58223.3, 0.055], [61457.9, 0.085], [62104.8, 0.004], [64045.7, 4.913], [64108.4, 0.0], [64660.2, 0.647], [64681.0, 2.32], [64692.5, 0.623]], "asks": [[64698.2, 0.442], [64722.0, 0.472], [64722.5, 1.001], [64738.0, 0.007], [64770.4, 0.022], [65339.6, 5.535]]}
{"kind": "depth", "E": 1787080492231, "U": 11315357854233, "u": 11315357858911, "recv_ms": 1787080492185, "bids": [[1000.0, 35.81], [14392.6, 1.694], [14492.6, 2.506], [51754.1, 0.0], [58223.3, 0.055], [63692.6, 0.002], [63906.3, 0.781], [64045.7, 4.913], [64104.7, 0.236], [64145.0, 0.156], [64149.1, 0.21], [64175.1, 6.224], [64552.5, 0.0], [64670.4, 2.402], [64673.7, 0.004], [64684.5, 0.003]], "asks": [[64695.9, 0.006], [64703.5, 0.259], [64709.5, 0.464], [64722.7, 2.978], [64833.5, 0.103], [64833.6, 3.82], [64843.6, 0.024], [65016.2, 5.102], [65339.6, 5.533], [65538.0, 19.76], [65692.7, 0.006]]}
{"kind": "depth", "E": 1787080492333, "U": 11315357859068, "u": 11315357865534, "recv_ms": 1787080492285, "bids": [[14392.6, 2.058], [14492.6, 2.142], [51754.0, 0.0], [58223.3, 0.055], [61457.9, 0.085], [62104.8, 0.001], [64045.7, 4.913], [64175.1, 10.117], [64369.1, 5.363], [64496.7, 0.0], [64535.5, 0.001], [64635.6, 1.635], [64670.7, 0.176], [64672.8, 5.381], [64676.2, 0.01], [64677.2, 0.016], [64683.6, 0.215]], "asks": [[64692.7, 12.666], [64696.6, 0.052], [64698.3, 0.591], [64700.9, 0.494], [64703.0, 0.016], [64708.7, 0.023], [64709.5, 0.479], [64850.6, 0.003], [64889.4, 0.01], [65339.6, 5.533], [65533.7, 18.434], [65570.3, 11.023], [71162.0, 0.0]]}
{"kind": "depth", "E": 1787080492435, "U": 11315357865604, "u": 11315357871734, "recv_ms": 1787080492388, "bids": [[1000.0, 35.81], [14392.6, 2.408], [14492.6, 1.792], [51754.0, 0.0], [58223.3, 0.055], [61457.9, 0.085], [61458.0, 0.07], [61458.1, 0.009], [62104.8, 0.004], [63692.6, 0.022], [63757.0, 8.692], [64045.7, 4.913], [64137.1, 0.106], [64175.1, 10.113], [64563.2, 0.008], [64575.3, 0.004], [64576.0, 3.871], [64584.2, 0.378], [64584.4, 2.32], [64621.0, 0.061], [64653.7, 0.422], [64656.3, 0.017], [64686.7, 0.118], [64687.4, 0.001], [64689.1, 0.138], [64689.2, 0.001], [64689.7, 0.0], [64690.7, 0.002], [64692.6, 7.396]], "asks": [[64695.1, 0.012], [64698.2, 0.441], [64710.4, 1.185], [64711.9, 0.0], [64712.1, 1.389], [64722.7, 2.978], [64763.4, 0.152], [64798.6, 2.343], [64800.3, 0.395], [64827.6, 0.001], [64827.7, 3.864], [65339.6, 5.533], [65566.1, 9.307], [65692.7, 0.026]]}
{"kind": "depth", "E": 1787080492639, "U": 11315357876306, "u": 11315357881041, "recv_ms": 1787080492593, "bids": [[14392.6, 3.122], [14492.6, 1.078], [58223.3, 0.055], [63519.1, 2.696], [63692.6, 0.002], [63826.4, 3.206], [63888.1, 9.176], [64045.7, 4.913], [64149.1, 0.179], [64369.1, 5.363], [64552.5, 0.0], [64609.7, 0.118], [64612.3, 0.209], [64617.5, 0.0], [64618.5, 32.423], [64620.4, 1.649], [64692.5, 0.675]], "asks": [[64694.5, 0.099], [64695.2, 0.648], [64722.7, 2.978], [64722.8, 0.003], [64833.5, 0.127], [64833.6, 3.82], [64843.6, 0.0], [65339.6, 5.533], [65663.1, 9.748], [65692.7, 0.006], [66314.3, 1.807]]}
{"kind": "depth", "E": 1787080492741, "U": 11315357881201, "u": 11315357888642, "recv_ms": 1787080492698, "bids": [[1000.0, 35.81], [14392.6, 3.486], [14492.6, 0.714], [58223.3, 0.055], [61457.9, 0.085], [62104.8, 0.004], [63398.8, 0.639], [63749.2, 0.094], [63782.4, 0.0], [63847.1, 0.002], [63971.3, 0.794], [64045.7, 4.913], [64541.9, 0.491], [64552.5, 4.928], [64605.3, 0.015], [64609.7, 32.536], [64612.3, 0.218], [64614.2, 0.629], [64614.9, 0.138], [64618.5, 0.005], [64620.4, 2.267], [64627.8, 0.026], [64630.1, 0.463], [64630.4, 2.35], [64630.7, 0.14], [64631.1, 1.78], [64631.4, 0.015], [64635.6, 1.649], [64643.9, 2.206], [64644.0, 0.003], [64647.0, 0.005], [64648.2, 0.0], [64648.5, 0.141], [64648.8, 0.213], [64649.1, 0.001], [64649.5, 0.002], [64650.3, 0.036], [64651.1, 0.332], [64652.2, 2.134], [64652.3, 0.001], [64653.7, 0.425], [64655.4, 0.005], [64659.4, 0.34], [64660.5, 2.248], [64660.6, 0.001], [64661.9, 0.935], [64663.1, 0.313], [64663.2, 0.006], [64663.3, 0.011], [64663.4, 0.0], [64663.6, 0.001], [64663.7, 0.001], [64663.8, 0.002], [64663.9, 0.001], [64664.1, 0.011], [64665.4, 0.012], [64665.9, 0.057], [64667.9, 0.0], [64668.8, 0.397], [64671.0, 0.085], [64672.8, 0.381], [64675.0, 0.958], [64675.1, 0.003], [64675.2, 0.065], [64675.3, 0.009], [64676.2, 0.003], [64678.5, 0.007], [64679.2, 0.0], [64679.5, 0.023], [64680.1, 0.994], [64680.2, 1.112], [64680.6, 0.009], [64681.0, 0.001], [64681.4, 0.985], [64682.0, 0.011], [64682.4, 0.0], [64682.8, 0.001], [64682.9, 0.311], [64683.1, 0.629], [64683.2, 0.003], [64683.3, 0.001], [64683.4, 0.001], [64683.5, 0.006], [64683.6, 0.015], [64683.7, 0.002], [64683.8, 0.001], [64683.9, 0.004], [64684.0, 0.005], [64684.1, 0.0], [64684.3, 0.565], [64684.4, 0.001], [64684.7, 0.677], [64684.8, 0.163], [64685.0, 0.007], [64685.2, 0.118], [64685.3, 0.0], [64685.5, 0.084], [64685.6, 1.814], [64685.7, 0.183], [64685.9, 0.085], [64686.3, 0.085], [64686.4, 0.312], [64686.6, 0.0], [64686.7, 0.034], [64686.9, 0.091], [64687.1, 0.0], [64687.3, 0.953], [64687.4, 0.001], [64687.5, 0.001], [64687.6, 0.085], [64687.8, 0.002], [64688.0, 0.091], [64688.2, 0.001], [64688.3, 0.007], [64688.4, 0.156], [64688.7, 0.002], [64689.1, 0.054], [64689.5, 0.023], [64689.6, 0.02], [64689.8, 0.272], [64690.0, 0.004], [64690.1, 0.236], [64690.4, 0.002], [64690.8, 0.013], [64691.1, 0.001], [64691.6, 0.001], [64691.9, 0.002], [64692.0, 0.135], [64692.1, 0.002], [64692.3, 0.0], [64692.4, 0.0], [64692.5, 0.681], [64692.6, 6.964]], "asks": [[64692.7, 12.898], [64693.1, 0.089], [64695.3, 0.243], [64695.7, 0.004], [64696.6, 0.168], [64697.4, 0.282], [64697.6, 0.02], [64697.9, 0.004], [64698.0, 0.181], [64698.1, 0.585], [64698.3, 0.591], [64698.4, 1.646], [64698.5, 1.239], [64699.2, 0.005], [64699.5, 0.14], [64699.7, 0.098], [64699.8, 2.321], [64699.9, 0.052], [64700.1, 0.003], [64700.4, 0.016], [64700.5, 0.003], [64700.7, 0.005], [64700.8, 0.437], [64700.9, 0.403], [64701.0, 2.122], [64701.1, 0.632], [64701.2, 0.463], [64701.3, 0.168], [64701.4, 0.006], [64701.5, 0.319], [64701.6, 0.021], [64701.7, 0.001], [64705.3, 0.0], [64706.2, 0.023], [64711.2, 2.652], [64712.1, 1.46], [64712.4, 0.116], [64713.3, 10.233], [64713.8, 0.008], [64714.7, 2.222], [64714.8, 3.517], [64716.8, 0.023], [64717.3, 1.181], [64717.4, 0.106], [64717.6, 0.002], [64717.9, 0.002], [64718.2, 0.018], [64718.6, 0.003], [64718.9, 0.003], [64719.4, 0.001], [64719.6, 1.578], [64720.7, 0.009], [64720.9, 0.008], [64721.0, 2.778], [64721.1, 4.01], [64721.2, 0.001], [64721.3, 0.16], [64721.5, 3.32], [64721.6, 1.359], [64721.7, 0.003], [64722.7, 2.824], [64722.8, 0.157], [64734.9, 0.544], [64735.3, 0.073], [64735.4, 0.366], [64735.7, 3.539], [64736.0, 0.042], [64736.3, 0.181], [64736.6, 0.005], [64754.9, 0.113], [64757.4, 0.393], [64760.0, 1.35], [64770.4, 0.025], [64793.6, 2.174], [64793.7, 0.028], [64801.9, 2.133], [64802.0, 0.001], [64810.2, 2.127], [64810.3, 0.0], [64833.6, 9.218], [64883.2, 0.006], [64889.4, 3.075], [65339.6, 5.533], [65642.2, 0.533], [65986.5, 0.015]]}
{"kind": "depth", "E": 1787080492945, "U": 11315357895921, "u": 11315357901998, "recv_ms": 1787080492897, "bids": [[14292.6, 0.238], [14392.6, 3.696], [14492.6, 0.266], [58223.3, 0.055], [61457.9, 0.085], [62104.8, 0.004], [63518.5, 2.36], [63520.0, 0.993], [64045.7, 4.913], [64369.1, 5.363], [64616.3, 0.0], [64617.5, 0.0], [64618.5, 32.423], [64650.0, 3.114], [64651.0, 0.044], [64669.5, 0.12], [64670.0, 1.413], [64683.7, 0.072], [64683.9, 0.074], [64684.2, 0.102], [64684.7, 0.677], [64684.8, 0.127], [64684.9, 0.032], [64685.7, 0.099], [64685.9, 0.117], [64687.4, 0.189], [64688.8, 0.088], [64692.6, 6.966]], "asks": [[64699.3, 0.413], [64700.3, 0.502], [64701.0, 2.372], [64701.2, 0.54], [64701.5, 0.403], [64708.2, 0.667], [64709.3, 0.0], [64713.1, 5.001], [64716.8, 0.055], [64717.7, 0.043], [64719.7, 0.121], [64720.0, 0.232], [64720.2, 0.116], [64721.6, 1.361], [64721.7, 0.005], [64721.8, 0.284], [64724.6, 0.002], [64724.7, 1.092], [64724.8, 1.244], [64725.4, 0.008], [64725.5, 0.002], [64725.6, 0.047], [64727.6, 0.002], [64727.7, 0.028], [64727.8, 0.003], [64734.2, 0.345], [64735.2, 0.044], [64759.2, 1.237], [64763.5, 36.613], [64889.4, 2.94], [64960.0, 5.426], [64961.6, 4.863], [65339.6, 5.533], [65643.7, 6.767], [66310.0, 0.657], [71162.0, 0.0]]}
{"kind": "depth", "E": 1787080493047, "U": 11315357902077, "u": 11315357908444, "recv_ms": 1787080493001, "bids": [[1000.0, 35.81], [14292.6, 0.49], [14392.6, 3.57], [14492.6, 0.14], [58223.3, 0.055], [62104.8, 0.001], [63692.6, 0.002], [63740.1, 3.132], [63851.6, 12.59], [64045.7, 4.913], [64369.1, 5.362], [64552.5, 4.973], [64627.9, 0.035], [64632.9, 0.037], [64651.3, 0.107], [64672.9, 0.928], [64673.5, 0.005], [64681.0, 0.006], [64683.7, 0.142], [64683.9, 0.144], [64684.3, 0.635], [64685.7, 0.003], [64686.2, 0.033]], "asks": [[64692.7, 12.896], [64699.0, 0.049], [64700.9, 0.487], [64701.3, 0.357], [64701.5, 0.48], [64703.0, 0.916], [64716.3, 1.141], [64716.4, 6.064], [64719.6, 0.678], [64720.0, 0.323], [64720.3, 0.192], [64732.4, 3.501], [64733.9, 0.049], [64755.1, 6.047], [64757.4, 0.392], [64761.3, 36.662], [64763.5, 0.0], [64787.2, 4.088], [64787.5, 10.374], [64833.6, 9.218], [65014.6, 0.48], [65016.2, 2.799], [65339.6, 5.533], [65469.0, 29.826], [65598.4, 22.828], [65611.3, 2.5], [65692.7, 0.006]]}
{"kind": "depth", "E": 1787080493149, "U": 11315357908487, "u": 11315357913702, "recv_ms": 1787080493109, "bids": [[1000.0, 35.81], [14292.6, 0.728], [14392.6, 3.458], [14492.6, 0.014], [51754.0, 0.0], [58223.3, 0.004], [61457.9, 0.085], [63583.2, 3.14], [63971.2, 1.562], [64045.7, 4.913], [64114.5, 2.882], [64552.5, 0.0], [64590.3, 0.002], [64590.5, 0.015], [64633.2, 0.033], [64665.6, 0.147], [64666.7, 0.668], [64681.0, 0.001], [64684.5, 0.103], [64685.2, 0.034], [64685.7, 0.099], [64689.4, 0.087], [64692.6, 6.994]], "asks": [[64692.7, 13.007], [64698.0, 0.182], [64700.6, 0.161], [64713.1, 0.001], [64718.1, 0.165], [64760.0, 1.359], [64833.6, 3.82], [64881.4, 0.002], [64881.6, 1.256], [65016.2, 2.799], [65339.6, 5.533], [65408.6, 6.948]]}
{"kind": "depth", "E": 1787080493251, "U": 11315357913755, "u": 11315357918894, "recv_ms": 1787080493206, "bids": [[14292.6, 1.064], [14392.6, 3.136], [14492.6, 0.0], [51754.0, 0.0], [51754.1, 0.0], [58223.3, 0.004], [61458.0, 0.074], [61458.1, 0.007], [62104.8, 0.004], [63398.8, 0.642], [63494.3, 0.322], [63692.6, 0.022], [63741.6, 8.456], [64045.7, 4.913], [64369.1, 5.363], [64535.5, 0.001], [64536.7, 0.404], [64570.4, 0.283], [64624.6, 0.169], [64632.5, 0.042], [64633.5, 0.67], [64657.2, 0.134], [64665.0, 1.247], [64665.1, 0.141], [64665.3, 0.122], [64665.4, 0.112], [64665.6, 0.247], [64665.7, 0.231], [64665.9, 0.127], [64666.6, 1.663], [64671.0, 0.005], [64678.3, 1.866], [64685.5, 0.032], [64685.7, 0.003], [64689.8, 0.101], [64689.9, 0.086]], "asks": [[64698.1, 0.542], [64729.6, 0.083], [64767.4, 0.171], [64830.2, 0.298], [64833.5, 0.103], [64843.6, 0.024], [64850.6, 0.003], [65016.2, 5.102], [65339.6, 5.533], [65462.5, 8.244], [65469.0, 31.046], [65538.1, 1.524], [65692.7, 0.026]]}
{"kind": "depth", "E": 1787080493353, "U": 11315357919030, "u": 11315357923585, "recv_ms": 1787080493308, "bids": [[1000.0, 35.81], [14292.6, 1.428], [14392.6, 2.772], [58223.3, 0.004], [62104.8, 0.001], [63449.8, 0.172], [64045.7, 4.913], [64496.7, 0.0], [64499.0, 0.568], [64563.2, 0.009], [64570.4, 0.001], [64614.9, 0.135], [64624.6, 0.0], [64633.8, 0.232], [64657.2, 0.061], [64660.2, 0.647], [64665.0, 1.317], [64665.1, 0.211], [64665.5, 0.101], [64676.2, 0.003], [64689.9, 0.002]], "asks": [[64708.7, 0.023], [64729.6, 0.01], [64738.0, 0.007], [64767.4, 0.002], [64770.4, 0.022], [64830.2, 0.016], [64889.4, 0.01], [65339.6, 5.533]]}
{"kind": "depth", "E": 1787080493557, "U": 11315357927628, "u": 11315357931418, "recv_ms": 1787080493508, "bids": [[14292.6, 2.142], [14392.6, 2.058], [51754.0, 0.0], [58223.3, 0.004], [62104.8, 0.001], [63269.4, 0.003], [63791.9, 0.938], [64045.7, 4.913], [64369.1, 2.881], [64496.7, 15.505], [64535.5, 8.389], [64552.5, 5.012], [64620.4, 6.285], [64667.1, 0.409], [64674.8, 0.024], [64687.4, 0.009], [64692.5, 0.629]], "asks": [[64696.6, 0.075], [64698.0, 0.274], [64833.5, 0.127], [64833.6, 9.218], [64843.6, 0.0], [64850.5, 10.437], [64889.4, 2.821], [65016.2, 4.948], [65339.6, 5.533], [65462.5, 9.159], [65469.0, 25.785], [65533.8, 6.399]]}
{"kind": "depth", "E": 1787080493659, "U": 11315357931500, "u": 11315357937607, "recv_ms": 1787080493612, "bids": [[1000.0, 35.81], [14292.6, 2.492], [14392.6, 1.708], [51754.0, 0.0], [58223.3, 0.004], [61457.9, 0.085], [63692.6, 0.022], [63981.0, 7.021], [64045.7, 4.913], [64076.5, 4.611], [64369.1, 5.208], [64672.7, 5.011], [64674.9, 1.293], [64684.8, 0.031], [64685.7, 0.183], [64686.5, 0.002], [64689.4, 0.003]], "asks": [[64692.7, 13.007], [64697.3, 0.024], [64697.4, 0.366], [64698.3, 0.55], [65339.6, 5.533], [65692.7, 0.026], [65986.5, 0.018]]}
{"kind": "depth", "E": 1787080493761, "U": 11315357937719, "u": 11315357942526, "recv_ms": 1787080493715, "bids": [[1000.0, 35.81], [14292.6, 2.842], [14392.6, 1.358], [51754.0, 0.0], [58223.3, 0.004], [62104.8, 0.004], [64045.7, 4.913], [64498.5, 0.004], [64552.5, 0.0], [64620.0, 2.789], [64679.7, 1.005], [64679.9, 0.156], [64689.2, 0.085]], "asks": [[64708.2, 0.111], [64708.7, 0.579], [64767.5, 0.025], [64768.6, 0.048], [64770.3, 0.0], [64771.4, 0.062], [64833.6, 3.82], [65339.6, 5.533], [65469.0, 31.046], [67300.8, 0.738]]}
{"kind": "depth", "E": 1787080493965, "U": 11315357948244, "u": 11315357952203, "recv_ms": 1787080493918, "bids": [[1000.0, 35.81], [14292.6, 3.556], [14392.6, 0.644], [58223.3, 0.004], [62104.8, 0.004], [64045.7, 4.913], [64078.0, 11.182], [64552.5, 5.023]], "asks": [[64833.6, 9.218], [64889.4, 2.788], [65279.2, 14.988], [65339.6, 5.533], [65414.8, 0.0]]}
{"kind": "depth", "E": 1787080494067, "U": 11315357952303, "u": 11315357956908, "recv_ms": 1787080494025, "bids": [[1000.0, 35.81], [14192.6, 0.084], [14292.6, 3.752], [14392.6, 0.364], [58223.3, 0.004], [61457.9, 0.085], [61458.0, 0.076], [63692.6, 0.022], [64045.7, 4.913], [64114.5, 2.648], [64175.1, 9.803], [64369.1, 5.363], [64552.5, 4.973], [64651.1, 0.318], [64667.4, 0.008], [64667.7, 0.001], [64668.3, 0.559], [64669.0, 0.619], [64669.1, 0.002], [64676.4, 1.089], [64681.0, 0.001], [64684.8, 0.079], [64692.5, 0.681], [64692.6, 6.996]], "asks": [[64694.1, 0.019], [64705.3, 0.618], [64708.7, 0.023], [64709.4, 1.471], [64710.3, 0.675], [64710.4, 0.644], [64711.9, 0.0], [64712.4, 0.001], [64712.6, 0.637], [64713.5, 0.425], [64833.5, 0.127], [64833.6, 9.218], [64843.6, 0.0], [64889.4, 2.941], [65016.2, 5.101], [65339.6, 5.533], [65469.0, 31.046], [65566.1, 9.688], [65692.7, 0.026]]}
{"kind": "depth", "E": 1787080494271, "U": 11315357961293, "u": 11315357965639, "recv_ms": 1787080494224, "bids": [[1000.0, 35.81], [14192.6, 0.546], [14292.6, 3.542], [14392.6, 0.112], [51754.0, 0.0], [51754.1, 0.0], [58223.3, 0.004], [62104.8, 0.004], [63888.1, 8.91], [64045.7, 4.913], [64110.4, 12.354], [64175.1, 10.113], [64369.1, 5.363], [64552.5, 0.0], [64679.9, 0.002], [64680.3, 0.156], [64692.6, 6.964]], "asks": [[64699.5, 0.14], [64711.2, 1.395], [64716.4, 16.064], [64833.6, 3.82], [65339.6, 5.533], [65505.6, 4.046], [65986.5, 0.015]]}
{"kind": "depth", "E": 1787080494373, "U": 11315357965697, "u": 11315357970366, "recv_ms": 1787080494328, "bids": [[1000.0, 35.81], [14192.6, 0.798], [14292.6, 3.402], [14392.6, 0.0], [58223.3, 0.004], [62104.8, 0.001], [63819.2, 12.538], [63858.5, 4.536], [64045.7, 4.913], [64369.1, 5.353], [64498.5, 0.005], [64535.5, 0.001], [64563.2, 0.008], [64667.7, 0.558], [64668.3, 0.002], [64676.2, 0.003], [64685.9, 0.033], [64690.2, 0.086]], "asks": [[64707.9, 0.565], [64708.7, 0.023], [64709.4, 0.915], [64712.0, 3.013], [64713.5, 0.31], [64833.5, 0.103], [64843.6, 0.024], [64850.5, 0.028], [65016.2, 5.102], [65339.6, 5.38], [65469.0, 31.26]]}
{"kind": "depth", "E": 1787080494577, "U": 11315357974771, "u": 11315357980708, "recv_ms": 1787080494531, "bids": [[1000.0, 35.81], [14192.6, 1.498], [14292.6, 2.702], [51754.0, 0.0], [58223.3, 0.004], [63692.6, 0.002], [63888.1, 8.676], [64045.7, 4.913], [64499.0, 2.824], [64536.7, 1.619], [64613.6, 1.549], [64680.3, 0.002], [64680.6, 0.163], [64692.6, 6.964]], "asks": [[64695.2, 0.638], [64714.7, 3.571], [64721.6, 1.359], [64721.7, 0.003], [64721.8, 0.282], [64724.6, 0.0], [64724.7, 1.09], [64724.8, 1.242], [64725.4, 0.006], [64725.5, 0.0], [64725.6, 0.045], [64727.6, 0.0], [64727.7, 0.026], [64727.8, 0.001], [64753.2, 1.67], [64833.5, 0.127], [64843.6, 0.0], [64960.0, 5.777], [65014.6, 0.797], [65255.3, 0.0], [65339.6, 5.38], [65339.7, 0.009], [65692.7, 0.006], [65796.7, 3.413]]}
{"kind": "depth", "E": 1787080494781, "U": 11315357988220, "u": 11315357993775, "recv_ms": 1787080494734, "bids": [[14192.6, 2.212], [14292.6, 1.988], [58223.3, 0.004], [61457.9, 0.085], [62104.8, 0.004], [64045.7, 4.913], [64552.5, 0.0], [64660.2, 0.647], [64666.7, 0.687], [64692.6, 6.973]], "asks": [[64695.8, 0.093], [64698.4, 2.083], [64699.5, 0.148], [64722.7, 2.978], [64722.8, 0.003], [64770.4, 0.025], [64833.6, 3.82], [65248.4, 0.08], [65339.6, 5.533], [65505.6, 3.788], [65986.5, 0.009]]}
{"kind": "depth", "E": 1787080494883, "U": 11315357994060, "u": 11315357999442, "recv_ms": 1787080494836, "bids": [[1000.0, 35.81], [14192.6, 2.576], [14292.6, 1.624], [58223.3, 0.004], [61457.9, 0.085], [61458.1, 0.005], [62104.8, 0.001], [63692.6, 0.022], [63888.1, 8.411], [64045.7, 4.913], [64496.7, 0.0], [64499.0, 0.568], [64535.5, 0.001], [64536.7, 0.404], [64570.4, 0.001], [64590.5, 0.012], [64590.6, 0.215], [64624.7, 2.85], [64657.2, 0.061], [64689.6, 0.001]], "asks": [[64692.7, 12.99], [64694.5, 0.089], [64722.7, 2.978], [64729.7, 0.014], [64767.4, 0.002], [64830.3, 0.0], [64833.5, 0.103], [64843.6, 0.024], [64850.5, 0.028], [64889.4, 0.01], [65339.6, 5.533], [65414.7, 0.076], [65663.1, 10.127], [65692.7, 0.026]]}
{"kind": "depth", "E": 1787080495189, "U": 11315358008567, "u": 11315358013839, "recv_ms": 1787080495141, "bids": [[1000.0, 35.81], [14192.6, 3.64], [14292.6, 0.56], [51754.1, 0.0], [58223.3, 0.004], [62104.8, 0.001], [64045.7, 4.913], [64369.1, 5.362], [64570.4, 0.001], [64624.6, 0.0], [64647.3, 0.21], [64653.7, 0.411], [64656.3, 0.003], [64657.2, 0.061], [64666.7, 0.668], [64676.4, 0.471], [64680.1, 1.148], [64680.2, 1.112], [64681.8, 0.0], [64685.7, 0.003], [64686.5, 0.002], [64687.4, 0.009], [64689.5, 0.001], [64692.6, 6.952]], "asks": [[64692.7, 12.628], [64694.5, 0.089], [64696.6, 0.616], [64698.1, 0.001], [64698.2, 0.442], [64698.4, 1.62], [64699.5, 0.611], [64705.3, 0.0], [64710.6, 0.618], [64712.6, 0.019], [64718.0, 0.635], [64722.6, 1.279], [64729.7, 0.014], [64739.3, 1.376], [64767.4, 0.002], [64802.7, 0.027], [64830.3, 0.0], [64833.5, 0.127], [64843.6, 0.0], [64881.6, 1.253], [64881.7, 0.003], [64886.8, 0.017], [65016.2, 5.103], [65156.0, 0.47], [65339.6, 5.533], [65986.5, 0.012], [66310.0, 1.259]]}
{"kind": "depth", "E": 1787080495291, "U": 11315358013865, "u": 11315358022150, "recv_ms": 1787080495245, "bids": [[1000.0, 35.81], [14192.6, 3.752], [14292.6, 0.322], [14592.6, 0.126], [51754.0, 0.0], [58223.3, 0.004], [62104.8, 0.004], [63075.3, 1.586], [63692.6, 0.022], [63985.1, 0.936], [63987.9, 0.0], [64045.7, 4.913], [64369.1, 5.362], [64552.5, 0.0], [64685.7, 0.003], [64687.3, 1.133]], "asks": [[64694.5, 0.099], [64695.2, 0.648], [64698.4, 2.083], [64699.4, 0.001], [64699.5, 0.148], [64722.6, 1.125], [64722.9, 0.154], [64833.6, 3.82], [64883.2, 0.006], [65339.6, 5.533], [65434.0, 0.259], [65692.7, 0.026]]}
{"kind": "depth", "E": 1787080495393, "U": 11315358022350, "u": 11315358027033, "recv_ms": 1787080495345, "bids": [[14192.6, 3.626], [14292.6, 0.21], [14592.6, 0.364], [51754.0, 0.0], [58223.3, 0.004], [61457.9, 0.085], [62104.8, 0.001], [64045.7, 4.913], [64369.1, 5.363], [64535.5, 0.001], [64563.2, 0.008], [64653.7, 0.425], [64661.8, 2.038], [64676.2, 0.003], [64685.7, 0.051], [64687.3, 0.953], [64687.4, 0.189], [64689.9, 0.002], [64690.1, 0.004], [64692.6, 6.95]], "asks": [[64692.8, 0.14], [64698.2, 0.441], [64708.7, 0.023], [64833.5, 0.103], [64843.6, 0.024], [64850.5, 0.028], [65016.2, 5.102], [65339.6, 5.533]]}
{"kind": "depth", "E": 1787080495495, "U": 11315358027164, "u": 11315358035108, "recv_ms": 1787080495449, "bids": [[1000.0, 35.81], [14192.6, 3.514], [14292.6, 0.084], [14592.6, 0.602], [58223.3, 0.004], [61457.9, 0.085], [61458.0, 0.076], [61458.1, 0.007], [63692.6, 0.002], [63888.1, 8.146], [64045.7, 4.913], [64496.7, 15.505], [64535.6, 8.387], [64552.5, 5.012], [64676.4, 0.471], [64685.7, 0.003], [64692.5, 0.681]], "asks": [[64692.7, 12.63], [64698.4, 2.091], [64699.5, 0.14], [64721.5, 1.62], [64833.5, 0.127], [64833.6, 9.218], [64843.6, 0.0], [64850.5, 10.437], [64889.4, 2.822], [65151.1, 0.158], [65339.6, 5.533], [65692.7, 0.006], [67280.4, 1.908]]}
{"kind": "depth", "E": 1787080495597, "U": 11315358035209, "u": 11315358040902, "recv_ms": 1787080495558, "bids": [[1000.0, 35.81], [14192.6, 3.332], [14292.6, 0.0], [14592.6, 0.868], [58223.3, 0.004], [61457.9, 0.085], [62104.8, 0.004], [63692.6, 0.022], [63981.0, 7.255], [64045.7, 4.913], [64076.5, 3.833], [64369.1, 5.363], [64499.0, 2.824], [64536.7, 1.59], [64552.5, 0.0], [64623.4, 2.017], [64674.9, 1.876], [64687.4, 0.009], [64689.7, 0.0], [64690.9, 0.0], [64692.6, 6.95]], "asks": [[64692.7, 12.64], [64712.1, 1.389], [64721.6, 1.361], [64721.7, 0.005], [64721.8, 0.284], [64724.6, 0.002], [64724.7, 1.092], [64724.8, 1.244], [64725.4, 0.008], [64725.5, 0.002], [64725.6, 0.047], [64727.6, 0.002], [64727.7, 0.028], [64727.8, 0.003], [64760.4, 6.564], [64833.6, 3.82], [65285.1, 0.0], [65339.6, 5.533], [65339.7, 0.008], [65566.1, 9.977], [65646.6, 0.129], [65692.7, 0.026], [65802.1, 2.277]]}
{"kind": "depth", "E": 1787080495699, "U": 11315358040951, "u": 11315358045641, "recv_ms": 1787080495651, "bids": [[14192.6, 2.968], [14592.6, 1.232], [58223.3, 0.004], [62104.8, 0.001], [63892.2, 0.0], [64045.7, 4.913], [64535.6, 8.387], [64536.7, 0.404], [64552.5, 5.012], [64689.8, 0.101]], "asks": [[64698.1, 0.001], [64698.2, 0.441], [64833.5, 0.103], [64833.6, 9.218], [64843.6, 0.024], [64850.5, 10.437], [65280.6, 0.229], [65339.6, 5.533], [65866.6, 0.675]]}
{"kind": "depth", "E": 1787080495801, "U": 11315358045740, "u": 11315358049646, "recv_ms": 1787080495754, "bids": [[1000.0, 35.81], [14192.6, 2.604], [14592.6, 1.596], [51754.0, 0.0], [58223.3, 0.004], [61458.0, 0.074], [61458.1, 0.009], [62104.8, 0.004], [64078.0, 11.96], [64227.9, 0.0], [64552.5, 0.0], [64622.3, 1.91], [64623.4, 1.323], [64644.9, 1.477], [64659.1, 0.312], [64661.1, 0.107]], "asks": [[64716.3, 0.163], [64727.9, 0.944], [64732.4, 0.001], [64753.2, 0.884], [64755.1, 0.047], [64833.6, 3.82], [65339.6, 5.533], [65630.7, 22.786]]}
{"kind": "depth", "E": 1787080495903, "U": 11315358049728, "u": 11315358053884, "recv_ms": 1787080495856, "bids": [[1000.0, 35.81], [14192.6, 2.268], [14592.6, 1.932], [58223.3, 0.006], [61457.9, 0.085], [62104.8, 0.001], [63692.6, 0.002], [63985.1, 0.702], [64045.7, 4.913], [64369.1, 5.363], [64535.6, 8.387], [64552.5, 5.012], [64589.4, 0.0], [64614.9, 0.138], [64647.3, 0.207], [64651.1, 0.332], [64659.1, 0.314], [64664.0, 1.232], [64669.0, 0.001], [64691.1, 0.021]], "asks": [[64692.7, 12.939], [64696.3, 0.012], [64696.4, 0.008], [64696.5, 0.087], [64696.6, 0.052], [64698.1, 0.565], [64710.6, 0.0], [64717.2, 1.701], [64718.0, 0.017], [64727.9, 0.946], [64738.0, 0.007], [64739.3, 1.334], [64757.4, 0.41], [64759.1, 37.023], [64760.0, 1.35], [64760.4, 0.382], [64761.3, 0.005], [64770.4, 0.022], [64802.7, 0.024], [64833.6, 9.218], [64850.5, 10.437], [65339.6, 5.533], [65692.7, 0.006], [65986.5, 0.015], [66633.3, 0.016]]}
{"kind": "depth", "E": 1787080496005, "U": 11315358053888, "u": 11315358058305, "recv_ms": 1787080495960, "bids": [[14192.6, 1.904], [14592.6, 2.296], [58223.3, 0.004], [61457.9, 0.085], [63842.9, 2.733], [63883.9, 16.725], [64045.7, 4.913], [64552.5, 5.012], [64586.0, 0.509], [64589.5, 0.001], [64592.0, 1.263], [64621.0, 6.061], [64643.6, 3.945], [64651.1, 0.318], [64659.8, 1.416], [64685.7, 0.183], [64692.6, 6.95]], "asks": [[64696.3, 0.553], [64696.4, 0.008], [64696.5, 0.087], [64696.6, 0.075], [64698.1, 0.001], [64698.4, 2.083], [64699.5, 0.148], [64717.5, 3.515], [64733.3, 1.386], [64733.6, 3.511], [64756.3, 6.166], [64787.2, 2.96], [64787.5, 0.374], [64833.5, 0.127], [64833.6, 3.82], [64833.7, 5.398], [64843.6, 0.0], [64889.4, 0.01], [64889.5, 7.596], [65339.6, 5.533], [65501.4, 16.991]]}
{"kind": "depth", "E": 1787080496107, "U": 11315358058371, "u": 11315358064160, "recv_ms": 1787080496068, "bids": [[1000.0, 35.81], [14192.6, 1.54], [14592.6, 2.66], [51754.0, 0.0], [58223.3, 0.004], [62104.8, 0.004], [63692.6, 0.022], [64045.7, 4.913], [64681.0, 0.001], [64685.7, 0.003]], "asks": [[64696.3, 0.553], [64696.4, 0.008], [64696.5, 0.087], [64696.6, 0.075], [64698.1, 0.001], [64698.4, 2.083], [64699.5, 0.148], [64889.4, 4.268], [64889.5, 0.012], [65339.6, 5.533], [65692.7, 0.026]]}
{"kind": "depth", "E": 1787080496209, "U": 11315358064332, "u": 11315358070098, "recv_ms": 1787080496167, "bids": [[1000.0, 35.81], [14192.6, 1.19], [14592.6, 3.01], [51754.0, 0.0], [51754.1, 0.0], [58223.3, 0.004], [62104.8, 0.001], [63981.0, 7.489], [64045.7, 4.913], [64369.1, 5.364], [64586.0, 0.501], [64588.7, 10.0], [64588.8, 2.518], [64680.1, 0.994], [64680.6, 0.163], [64685.7, 0.183], [64690.9, 0.023]], "asks": [[64696.3, 0.012], [64696.4, 0.008], [64696.5, 0.087], [64696.6, 0.075], [64698.1, 0.542], [64700.8, 0.568], [64759.1, 0.021], [64763.6, 37.003], [64790.3, 0.008], [64790.4, 3.745], [64790.7, 10.004], [64790.9, 0.0], [64833.5, 0.103], [64843.6, 0.024], [65016.2, 5.101], [65339.6, 5.533], [65573.3, 1.221], [65597.0, 7.546]]}
{"kind": "depth", "E": 1787080496311, "U": 11315358070306, "u": 11315358075581, "recv_ms": 1787080496264, "bids": [[14192.6, 0.826], [14592.6, 3.374], [51754.0, 0.0], [58223.3, 0.004], [61457.9, 0.079], [61458.0, 0.072], [61458.1, 0.011], [62104.8, 0.004], [63692.6, 0.002], [63883.9, 16.959], [63888.1, 7.795], [64045.7, 4.913], [64242.0, 0.0], [64535.6, 7.314], [64552.5, 4.476], [64668.3, 1.703], [64669.1, 0.62], [64676.5, 0.618], [64680.6, 0.009], [64685.7, 0.183], [64689.7, 0.084], [64691.1, 0.044], [64692.0, 0.0], [64692.1, 0.15], [64692.2, 0.002]], "asks": [[64692.7, 12.936], [64698.4, 2.083], [64699.5, 0.148], [64705.4, 0.642], [64712.7, 0.714], [64739.3, 1.376], [64760.0, 1.377], [64761.3, 37.191], [64762.6, 0.003], [64763.6, 0.001], [64833.5, 0.127], [64833.6, 9.218], [64833.7, 0.0], [64843.6, 0.0], [64850.5, 10.437], [64889.4, 0.01], [64889.5, 5.131], [65339.6, 5.535], [65473.3, 41.556], [65499.9, 2.293], [65692.7, 0.006], [65792.5, 9.315], [65986.5, 0.018]]}
{"kind": "depth", "E": 1787080496413, "U": 11315358075631, "u": 11315358080205, "recv_ms": 1787080496366, "bids": [[1000.0, 35.96], [14192.6, 0.49], [14492.6, 0.014], [14592.6, 3.696], [58223.3, 0.004], [62104.8, 0.001], [63730.5, 0.0], [63985.1, 0.468], [64045.7, 4.913], [64369.1, 5.363], [64552.5, 0.0], [64563.2, 0.008], [64676.2, 0.003], [64680.4, 0.169]], "asks": [[64698.4, 2.091], [64699.5, 0.14], [64708.7, 0.023], [64833.6, 3.82], [65016.2, 4.948], [65210.2, 9.343], [65339.6, 5.533], [65436.6, 0.779], [65564.6, 6.199], [65566.1, 10.738], [65598.4, 25.112]]}
{"kind": "depth", "E": 1787080496617, "U": 11315358084752, "u": 11315358087978, "recv_ms": 1787080496618, "bids": [[14192.6, 0.182], [14492.6, 0.42], [14592.6, 3.598], [58223.3, 0.004], [61457.9, 0.079], [62104.8, 0.004], [63791.9, 0.0], [64045.7, 4.913], [64226.9, 0.104], [64536.7, 1.43], [64623.4, 2.017], [64692.6, 6.95]], "asks": [[64760.4, 6.643], [64889.4, 4.362], [65016.2, 5.102], [65339.6, 5.533], [66180.6, 3.862]]}
{"kind": "depth", "E": 1787080496719, "U": 11315358088116, "u": 11315358092843, "recv_ms": 1787080496673, "bids": [[1000.0, 35.81], [14192.6, 0.056], [14492.6, 0.658], [14592.6, 3.486], [58223.3, 0.004], [62104.8, 0.001], [63692.6, 0.002], [63795.2, 0.007], [63981.0, 7.723], [64045.7, 4.913], [64667.5, 0.571], [64668.6, 0.001], [64669.0, 0.117], [64669.1, 0.002], [64669.5, 0.004], [64669.7, 0.074], [64670.6, 0.0], [64675.9, 0.132], [64676.5, 0.0], [64678.3, 1.786], [64685.7, 0.003]], "asks": [[64692.7, 13.744], [64695.4, 0.141], [64696.8, 0.0], [64699.7, 0.003], [64704.9, 0.053], [64705.4, 0.119], [64705.7, 0.138], [64706.5, 0.928], [64707.7, 0.002], [64708.5, 0.867], [64708.6, 2.702], [64708.8, 0.006], [64709.4, 0.915], [64710.2, 0.085], [64710.3, 0.134], [64710.7, 0.0], [64711.1, 0.543], [64711.9, 0.0], [64712.7, 0.096], [64713.1, 0.001], [64713.4, 0.212], [65280.5, 0.236], [65339.6, 5.533], [65692.7, 0.006]]}
{"kind": "depth", "E": 1787080496821, "U": 11315358092968, "u": 11315358099317, "recv_ms": 1787080496774, "bids": [[14192.6, 0.0], [14492.6, 0.952], [14592.6, 3.248], [58223.3, 0.004], [61457.9, 0.073], [62104.8, 0.004], [63761.7, 13.864], [63793.4, 11.267], [64045.7, 4.915], [64369.1, 5.363], [64680.4, 0.169], [64685.7, 0.183], [64691.1, 0.021], [64691.3, 0.0], [64691.4, 0.033]], "asks": [[64697.1, 0.004], [64697.2, 0.095], [64697.3, 0.004], [64697.4, 0.343], [64697.7, 0.042], [65339.6, 5.533], [65414.0, 4.075], [65448.1, 0.548], [65478.8, 0.791], [65598.4, 27.395]]}
{"kind": "depth", "E": 1787080496923, "U": 11315358099584, "u": 11315358104892, "recv_ms": 1787080496874, "bids": [[14492.6, 1.316], [14592.6, 2.884], [58223.3, 0.004], [63692.6, 0.022], [63778.1, 1.727], [64045.7, 4.913], [64243.9, 0.011], [64535.6, 0.0], [64552.5, 0.0], [64680.3, 0.156], [64680.4, 0.015], [64685.7, 0.003], [64690.9, 0.0], [64691.1, 0.001], [64691.4, 0.014], [64692.5, 0.681]], "asks": [[64833.6, 3.82], [64850.5, 0.028], [65339.6, 5.533], [65692.7, 0.026], [65986.5, 0.015]]}
{"kind": "depth", "E": 1787080497127, "U": 11315358109901, "u": 11315358114843, "recv_ms": 1787080497085, "bids": [[14492.6, 2.03], [14592.6, 2.17], [51754.0, 0.0], [58223.3, 0.004], [61457.9, 0.067], [62104.8, 0.004], [63692.6, 0.002], [63754.6, 21.42], [64045.7, 4.913], [64114.5, 2.18], [64369.1, 5.353], [64676.4, 0.469], [64680.3, 0.002], [64680.4, 0.169], [64681.0, 0.001], [64685.7, 0.003], [64687.3, 1.133], [64692.6, 6.95]], "asks": [[64721.6, 1.359], [64721.7, 0.003], [64721.8, 0.282], [64724.6, 0.0], [64724.7, 1.09], [64724.8, 1.242], [64725.4, 0.006], [64725.5, 0.0], [64725.6, 0.045], [64727.6, 0.0], [64727.7, 0.026], [64727.8, 0.001], [64833.5, 0.127], [64843.6, 0.0], [65339.6, 5.533], [65692.7, 0.006]]}
{"kind": "depth", "E": 1787080497229, "U": 11315358114974, "u": 11315358119327, "recv_ms": 1787080497182, "bids": [[14492.6, 2.394], [14592.6, 1.806], [51754.1, 0.0], [58223.3, 0.004], [61458.0, 0.074], [62104.8, 0.001], [63888.1, 7.53], [63979.1, 0.009], [64045.7, 4.913], [64369.1, 5.352], [64552.5, 0.0], [64582.6, 0.005], [64614.9, 0.135], [64647.3, 0.207], [64680.4, 0.015], [64685.7, 0.183], [64687.3, 0.953]], "asks": [[64692.7, 13.735], [64697.5, 0.108], [64738.0, 0.007], [64770.4, 0.022], [64833.6, 3.82], [65339.6, 5.537]]}
{"kind": "depth", "E": 1787080497331, "U": 11315358119331, "u": 11315358126188, "recv_ms": 1787080497286, "bids": [[1000.0, 35.81], [14492.6, 2.744], [14592.6, 1.456], [58223.3, 0.004], [61457.9, 0.067], [62104.8, 0.004], [63398.8, 0.642], [63692.6, 0.022], [63874.3, 1.564], [63883.9, 17.49], [64045.7, 4.913], [64552.5, 4.486], [64609.7, 0.118], [64611.9, 32.066], [64614.2, 0.629], [64618.5, 0.005], [64620.4, 1.649], [64643.9, 2.207], [64647.0, 0.005], [64651.1, 0.371], [64652.2, 2.135], [64658.4, 0.336], [64659.4, 0.004], [64660.5, 2.249], [64669.1, 0.002], [64669.7, 0.537], [64671.5, 0.006], [64674.9, 1.373], [64675.9, 0.052], [64676.4, 0.472], [64677.8, 0.007], [64678.5, 0.0], [64679.8, 0.441], [64680.1, 0.707], [64680.2, 0.564], [64680.3, 2.235], [64680.5, 0.01], [64680.6, 0.001], [64681.6, 0.33], [64682.5, 0.0], [64682.9, 0.001], [64683.4, 0.004], [64683.5, 0.003], [64683.8, 0.141], [64684.1, 0.284], [64684.4, 0.17], [64684.5, 0.187], [64684.9, 0.116], [64685.2, 0.118], [64685.6, 1.898], [64685.7, 0.051], [64686.0, 0.1], [64686.3, 0.085], [64686.4, 0.002], [64686.5, 0.312], [64686.7, 0.118], [64686.8, 0.009], [64686.9, 0.007], [64687.1, 0.085], [64687.3, 0.869], [64687.4, 0.181], [64687.5, 0.085], [64687.6, 0.001], [64688.0, 0.007], [64688.4, 1.885], [64688.5, 0.008], [64688.8, 0.004], [64689.2, 0.001], [64689.3, 0.003], [64689.4, 0.047], [64689.7, 0.0], [64689.9, 0.001], [64690.0, 0.235], [64690.5, 0.002], [64690.8, 0.013], [64691.0, 0.0], [64691.3, 0.153], [64692.0, 0.0], [64692.1, 0.0], [64692.2, 0.0], [64692.3, 0.0], [64692.4, 0.002], [64692.5, 0.68], [64692.6, 5.745]], "asks": [[64692.7, 14.897], [64693.5, 0.005], [64693.7, 0.003], [64694.3, 0.008], [64695.3, 0.246], [64695.5, 0.007], [64695.8, 0.086], [64696.6, 0.709], [64697.2, 0.092], [64697.9, 0.467], [64698.0, 0.181], [64698.1, 0.001], [64698.3, 0.558], [64698.4, 1.62], [64698.8, 0.442], [64699.5, 0.14], [64700.2, 1.61], [64700.8, 0.567], [64701.5, 0.171], [64704.9, 0.054], [64705.0, 1.843], [64705.3, 0.0], [64706.5, 0.003], [64707.1, 0.47], [64708.8, 0.005], [64709.9, 0.123], [64710.3, 0.675], [64711.1, 0.002], [64711.2, 2.068], [64711.6, 0.083], [64711.9, 0.0], [64712.4, 5.001], [64712.7, 0.096], [64713.3, 0.231], [64714.3, 10.0], [64714.7, 2.224], [64716.4, 6.064], [64739.3, 1.334], [64793.5, 2.131], [64793.6, 0.046], [64801.8, 2.264], [64801.9, 0.005], [64810.1, 2.129], [64810.2, 0.0], [64833.6, 9.218], [64889.3, 2.927], [64889.4, 0.01], [64889.5, 0.012], [65016.2, 5.103], [65339.6, 5.533], [65692.7, 0.026], [65986.5, 0.012]]}
{"kind": "depth", "E": 1787080497433, "U": 11315358126375, "u": 11315358132149, "recv_ms": 1787080497388, "bids": [[14492.6, 3.094], [14592.6, 1.106], [58223.3, 0.004], [61457.9, 0.067], [63975.4, 0.263], [64045.7, 4.913], [64110.4, 12.822], [64175.1, 10.113], [64369.1, 5.352], [64563.2, 0.008], [64665.2, 0.319], [64666.5, 0.462], [64676.2, 0.003], [64682.5, 0.31], [64684.1, 0.2], [64684.5, 0.103], [64685.7, 0.099], [64687.4, 0.001], [64688.1, 0.085], [64688.5, 0.272], [64690.0, 0.236], [64690.5, 0.001], [64692.0, 0.002], [64692.4, 0.0], [64692.5, 0.681]], "asks": [[64692.7, 14.958], [64693.5, 0.002], [64694.6, 0.313], [64695.4, 0.139], [64696.5, 0.087], [64696.6, 0.052], [64697.4, 0.282], [64697.9, 0.12], [64698.0, 0.722], [64698.1, 0.464], [64700.0, 2.656], [64701.0, 1.472], [64705.0, 1.938], [64705.4, 0.024], [64708.7, 0.023], [64710.7, 0.002], [64711.9, 0.115], [64712.8, 0.235], [64713.4, 0.097], [64714.3, 10.002], [64714.7, 2.222], [64757.4, 0.392], [65016.2, 5.102], [65339.6, 5.533]]}
{"kind": "depth", "E": 1787080497637, "U": 11315358137644, "u": 11315358143436, "recv_ms": 1787080497590, "bids": [[1000.0, 35.81], [14392.6, 0.042], [14492.6, 3.724], [14592.6, 0.434], [51754.0, 0.0], [58223.3, 0.004], [61457.9, 0.067], [62104.8, 0.004], [64045.7, 4.913], [64536.7, 1.42], [64570.3, 0.282], [64611.9, 0.004], [64613.6, 1.549], [64618.5, 32.067], [64624.6, 0.169], [64657.1, 0.515], [64684.5, 0.102], [64684.9, 0.032], [64685.5, 0.033], [64686.0, 0.089], [64687.1, 0.084], [64687.4, 0.181], [64688.1, 0.092], [64689.1, 0.138], [64689.9, 0.002], [64692.6, 6.586]], "asks": [[64692.7, 14.648], [64697.6, 0.01], [64698.9, 0.014], [64729.6, 0.084], [64767.3, 0.693], [64830.2, 0.3], [65073.5, 0.0], [65339.6, 5.533], [65586.3, 1.221], [71162.0, 0.0]]}
{"kind": "depth", "E": 1787080497739, "U": 11315358143594, "u": 11315358150572, "recv_ms": 1787080497691, "bids": [[14392.6, 0.238], [14492.6, 3.696], [14592.6, 0.266], [58223.3, 0.004], [61457.9, 0.067], [62104.8, 0.001], [63761.7, 13.707], [64045.7, 4.913], [64369.1, 5.353], [64570.3, 0.0], [64624.6, 0.0], [64651.1, 0.371], [64655.9, 0.058], [64657.1, 0.442], [64657.2, 0.004], [64666.6, 2.22], [64667.5, 0.014], [64668.1, 0.117], [64669.0, 0.001], [64671.6, 0.929], [64672.9, 0.002], [64675.8, 0.003], [64679.1, 0.617], [64680.1, 0.166], [64681.5, 0.053], [64685.2, 0.034], [64687.4, 0.001], [64688.5, 0.264], [64689.7, 0.084], [64692.6, 6.681]], "asks": [[64706.9, 0.001], [64707.8, 0.598], [64708.5, 0.311], [64708.7, 0.08], [64708.8, 0.005], [64710.2, 0.028], [64710.3, 0.675], [64710.9, 0.002], [64711.9, 0.115], [64729.6, 0.01], [64767.3, 0.522], [64830.2, 0.016], [64889.3, 3.065], [64889.5, 0.012], [65339.6, 5.533], [65986.5, 0.015]]}
{"kind": "depth", "E": 1787080497841, "U": 11315358150705, "u": 11315358155615, "recv_ms": 1787080497796, "bids": [[1000.0, 35.81], [14392.6, 0.476], [14492.6, 3.57], [14592.6, 0.154], [58223.3, 0.004], [61457.9, 0.061], [63692.6, 0.022], [64045.7, 4.913], [64323.4, 0.005], [64325.9, 0.677], [64420.0, 3.682], [64420.7, 0.566], [64491.0, 0.041], [64491.9, 0.437], [64685.7, 0.003], [64688.5, 0.084], [64689.7, 0.0]], "asks": [[64696.5, 0.164], [64696.6, 0.091], [64697.9, 0.004], [64698.0, 0.722], [64698.1, 0.488], [64698.2, 0.489], [64887.7, 0.015], [64958.4, 1.263], [64959.0, 3.001], [64959.1, 0.0], [65056.4, 2.098], [65056.5, 0.026], [65339.6, 5.533], [65579.0, 3.12], [65692.7, 0.026], [71162.0, 0.0]]}
{"kind": "depth", "E": 1787080497943, "U": 11315358155698, "u": 11315358159840, "recv_ms": 1787080497896, "bids": [[1000.0, 35.81], [14392.6, 0.714], [14492.6, 3.458], [14592.6, 0.028], [58223.3, 0.004], [61458.0, 0.076], [62104.8, 0.004], [64045.7, 4.913], [64059.5, 0.029], [64207.6, 0.001], [64300.1, 15.43], [64360.1, 14.639], [64420.1, 0.005], [64475.0, 0.356], [64491.1, 0.001], [64552.5, 0.0], [64689.5, 0.085], [64692.5, 0.629]], "asks": [[64696.5, 0.087], [64696.6, 0.052], [64697.9, 0.12], [64698.0, 0.722], [64698.1, 0.464], [64698.2, 0.441], [64712.1, 1.584], [64833.5, 0.103], [64833.6, 3.82], [64843.6, 0.024], [64887.6, 0.007], [64887.8, 0.765], [65279.2, 14.759], [65339.6, 5.533], [65469.0, 31.474], [66310.0, 1.259]]}
{"kind": "depth", "E": 1787080498045, "U": 11315358160067, "u": 11315358164261, "recv_ms": 1787080497998, "bids": [[14392.6, 1.036], [14492.6, 3.164], [14592.6, 0.0], [58223.3, 0.004], [62104.8, 0.001], [63692.6, 0.002], [63883.9, 17.841], [64045.7, 4.913], [64175.1, 9.803], [64323.7, 40.718], [64325.9, 6.668], [64369.1, 5.208], [64420.4, 33.417], [64420.7, 5.481], [64491.3, 26.626], [64491.9, 4.356], [64552.5, 5.103], [64681.0, 0.006]], "asks": [[64696.4, 0.008], [64696.5, 0.087], [64696.6, 0.052], [64697.9, 0.004], [64698.0, 0.838], [64833.6, 9.218], [64887.1, 27.061], [64889.3, 2.927], [64958.5, 34.791], [65055.9, 42.084], [65173.6, 0.001], [65323.9, 0.132], [65339.6, 5.533], [65478.6, 2.29], [65692.7, 0.006]]}
