{"kind": "depth", "E": 1787080498147, "U": 11315358164266, "u": 11315358170189, "recv_ms": 1787080498108, "bids": [[1000.0, 35.81], [14392.6, 1.4], [14492.6, 2.8], [58223.3, 0.004], [61457.9, 0.061], [62104.8, 0.004], [62744.7, 0.001], [63712.6, 3.949], [63750.0, 12.619], [63946.2, 0.025], [64045.7, 4.913], [64060.3, 64.615], [64208.0, 51.405], [64627.9, 0.036], [64681.0, 0.001], [64689.2, 0.233], [64690.0, 0.004], [64692.6, 6.586]], "asks": [[64692.7, 14.635], [64697.1, 0.024], [64697.7, 0.023], [64701.1, 0.893], [64708.0, 0.141], [64711.2, 1.395], [64712.1, 1.513], [64712.4, 0.001], [64713.6, 0.138], [64721.6, 1.361], [64721.7, 0.005], [64721.8, 0.284], [64724.6, 0.002], [64724.7, 1.092], [64724.8, 1.244], [64725.4, 0.008], [64725.5, 0.002], [64725.6, 0.047], [64727.6, 0.002], [64727.7, 0.028], [64727.8, 0.003], [64757.4, 0.393], [64833.5, 0.127], [64843.6, 0.0], [65339.6, 5.533], [65413.1, 1.364]]}
{"kind": "depth", "E": 1787080498249, "U": 11315358170339, "u": 11315358175166, "recv_ms": 1787080498200, "bids": [[1000.0, 35.81], [14392.6, 1.75], [14492.6, 2.45], [51754.1, 0.0], [58223.3, 0.004], [61457.9, 0.062], [62097.9, 0.017], [62104.8, 0.001], [63391.6, 1.891], [63692.6, 0.022], [63916.3, 37.983], [64045.7, 4.913], [64076.5, 3.133], [64175.1, 10.113], [64369.1, 5.363], [64475.0, 0.14], [64491.4, 0.437], [64651.1, 0.357], [64669.1, 0.62], [64674.0, 0.125], [64676.5, 0.618], [64681.5, 0.053], [64685.7, 0.183], [64688.5, 0.084], [64689.1, 0.139], [64689.9, 0.001], [64692.6, 6.587]], "asks": [[64697.7, 0.0], [64701.9, 0.273], [64702.8, 0.103], [64705.3, 0.618], [64712.7, 0.714], [64713.6, 0.058], [64822.3, 0.061], [64887.0, 0.288], [64887.8, 0.549], [65016.2, 5.101], [65275.0, 10.806], [65305.8, 3.821], [65339.6, 5.533], [65543.3, 2.286], [65692.7, 0.026]]}
{"kind": "depth", "E": 1787080498453, "U": 11315358182051, "u": 11315358187436, "recv_ms": 1787080498418, "bids": [[1000.0, 35.81], [14392.6, 2.464], [14492.6, 1.736], [51754.0, 0.0], [58223.3, 0.004], [61451.0, 0.227], [61458.0, 0.078], [62104.8, 0.004], [63692.6, 0.002], [63754.6, 22.517], [63777.3, 2.353], [63916.3, 42.67], [63948.6, 7.495], [64047.8, 0.0], [64078.0, 12.66], [64208.4, 0.003], [64369.4, 0.001], [64530.8, 0.004], [64582.6, 0.002], [64647.3, 0.21], [64668.1, 0.001], [64669.6, 0.138], [64676.2, 0.001], [64681.5, 0.045], [64688.5, 0.092], [64689.5, 0.001], [64692.5, 0.681]], "asks": [[64697.2, 0.114], [64708.7, 0.078], [64738.0, 0.007], [64860.2, 0.0], [65022.4, 0.003], [65185.0, 0.228], [65307.3, 8.495], [65339.6, 5.533], [65348.0, 1.968], [65473.3, 41.342], [65531.5, 3.6], [65692.7, 0.006]]}
{"kind": "depth", "E": 1787080498555, "U": 11315358187437, "u": 11315358191956, "recv_ms": 1787080498508, "bids": [[1000.0, 35.81], [14392.6, 2.828], [14492.6, 1.372], [58223.3, 0.004], [61457.9, 0.061], [62104.8, 0.001], [63786.9, 32.047], [63948.6, 6.558], [64045.7, 4.913], [64369.1, 5.363], [64570.3, 0.0], [64620.4, 6.382], [64624.6, 0.0], [64657.1, 0.442], [64666.6, 1.663], [64667.2, 1.798], [64668.1, 0.001], [64668.6, 0.117], [64669.6, 0.022], [64676.2, 0.003], [64680.0, 1.833], [64680.1, 0.012], [64681.7, 0.173], [64685.7, 0.183], [64687.4, 0.001], [64688.5, 0.084], [64689.4, 0.045], [64692.6, 6.582]], "asks": [[64692.7, 14.644], [64707.8, 0.042], [64708.3, 0.846], [64708.7, 0.08], [64711.9, 0.0], [64712.4, 0.116], [64714.2, 4.547], [64714.7, 0.011], [64729.6, 0.01], [64767.3, 0.522], [64830.2, 0.016], [65016.2, 5.102], [65339.6, 5.533], [66237.8, 0.005]]}
{"kind": "depth", "E": 1787080498657, "U": 11315358192073, "u": 11315358197684, "recv_ms": 1787080498611, "bids": [[14392.6, 3.178], [14492.6, 1.022], [51754.0, 0.0], [58223.3, 0.004], [61457.9, 0.061], [62104.8, 0.004], [63692.6, 0.022], [63774.0, 3.078], [64045.7, 4.913], [64047.8, 0.008], [64208.4, 0.008], [64239.8, 0.103], [64369.1, 5.363], [64369.4, 0.004], [64530.8, 0.006], [64570.3, 0.0], [64624.6, 0.0], [64657.1, 0.442], [64681.7, 0.165], [64685.7, 0.003], [64688.5, 0.084], [64689.0, 0.084], [64689.1, 0.055], [64692.6, 6.551]], "asks": [[64729.6, 0.01], [64767.3, 0.522], [64830.2, 0.016], [64860.2, 0.002], [65022.4, 0.006], [65185.0, 0.233], [65339.6, 5.535], [65348.0, 1.976], [65692.7, 0.026], [65986.5, 0.012], [71162.0, 0.002]]}
{"kind": "depth", "E": 1787080498759, "U": 11315358197699, "u": 11315358202197, "recv_ms": 1787080498712, "bids": [[1000.0, 35.81], [14392.6, 3.542], [14492.6, 0.658], [58223.3, 0.004], [61457.9, 0.061], [62104.8, 0.001], [63403.0, 0.002], [63474.8, 0.102], [63546.7, 0.0], [63618.6, 4.244], [63690.5, 0.007], [63762.4, 0.029], [63834.3, 0.001], [63906.2, 0.001], [63978.0, 0.08], [63985.1, 0.234], [64045.7, 4.913], [64049.9, 0.0], [64574.1, 3.866], [64576.0, 0.007], [64584.4, 0.001], [64584.7, 2.466], [64621.0, 6.015], [64621.1, 0.092], [64667.9, 0.116], [64668.6, 0.001], [64672.4, 5.0], [64681.7, 0.165], [64687.3, 0.869], [64688.5, 0.092], [64689.6, 0.085], [64692.6, 6.546]], "asks": [[64692.7, 14.642], [64710.8, 1.645], [64712.4, 0.001], [64760.0, 1.368], [64763.4, 0.106], [64763.5, 0.046], [64798.6, 2.343], [64827.7, 0.0], [64827.8, 3.891], [65324.5, 67.014], [65339.6, 5.533], [65343.9, 2.3], [65415.8, 0.0], [65487.6, 0.001], [65559.5, 0.0], [65631.4, 0.0], [65703.3, 0.651], [65775.2, 0.002], [65847.1, 0.606], [65919.0, 0.128], [65990.8, 1.589], [71162.0, 0.0]]}
{"kind": "depth", "E": 1787080498861, "U": 11315358202237, "u": 11315358208195, "recv_ms": 1787080498816, "bids": [[1000.0, 35.81], [14292.6, 0.07], [14392.6, 3.752], [14492.6, 0.378], [58223.3, 0.004], [63692.6, 0.002], [63948.6, 7.495], [64045.7, 4.913], [64552.5, 0.0], [64552.6, 5.034], [64653.7, 0.411], [64666.5, 1.019], [64667.2, 1.241], [64681.7, 0.165], [64685.6, 1.814], [64685.7, 0.003], [64687.4, 0.001], [64688.5, 0.092], [64689.4, 0.003], [64689.6, 0.085], [64689.7, 0.0], [64690.0, 0.088], [64690.3, 0.023], [64690.4, 0.02], [64692.6, 6.641]], "asks": [[64692.7, 14.643], [64694.3, 0.001], [64694.9, 0.093], [64697.1, 0.004], [64697.2, 0.092], [64697.5, 0.066], [64697.7, 0.042], [64699.9, 0.051], [64700.2, 1.301], [64700.8, 0.876], [64702.8, 0.023], [64708.5, 0.311], [64710.3, 0.675], [64710.8, 1.53], [64711.7, 0.129], [64712.1, 1.584], [64713.6, 0.138], [64754.9, 0.131], [64833.5, 5.525], [64833.6, 3.82], [64889.3, 3.172], [65339.6, 5.533], [65692.7, 0.006], [66188.0, 12.026]]}
{"kind": "depth", "E": 1787080498963, "U": 11315358208374, "u": 11315358212889, "recv_ms": 1787080498916, "bids": [[14292.6, 0.294], [14392.6, 3.668], [14492.6, 0.238], [58223.3, 0.004], [62104.8, 0.004], [63883.9, 18.106], [63981.0, 7.957], [64045.7, 4.913], [64369.1, 5.353], [64570.3, 0.0], [64624.6, 0.0], [64638.2, 0.0], [64657.2, 0.004], [64674.4, 0.0], [64674.5, 0.02], [64685.7, 0.183], [64686.0, 0.005], [64690.3, 0.107]], "asks": [[64703.0, 0.916], [64703.3, 0.139], [64704.9, 0.149], [64705.0, 1.843], [64705.3, 0.636], [64705.4, 0.006], [64708.8, 0.005], [64710.3, 0.675], [64713.6, 0.058], [64729.6, 0.01], [64767.4, 0.002], [64830.2, 0.016], [64833.5, 5.501], [64843.6, 0.024], [65016.2, 4.948], [65080.9, 0.813], [65210.2, 9.343], [65339.6, 5.533], [65986.5, 0.015]]}
{"kind": "depth", "E": 1787080499065, "U": 11315358213084, "u": 11315358217012, "recv_ms": 1787080499026, "bids": [[1000.0, 35.81], [14292.6, 0.532], [14392.6, 3.542], [14492.6, 0.126], [58223.3, 0.004], [61458.1, 0.009], [62104.8, 0.001], [63003.5, 0.0], [63439.7, 0.676], [63692.6, 0.022], [63817.8, 2.039], [64045.7, 4.913], [64681.0, 0.001]], "asks": [[64693.1, 0.002], [64694.6, 0.311], [64695.0, 0.009], [65016.2, 4.948], [65210.2, 9.648], [65339.6, 5.533], [65469.0, 31.016], [65692.7, 0.026]]}
{"kind": "depth", "E": 1787080499167, "U": 11315358217040, "u": 11315358228249, "recv_ms": 1787080499122, "bids": [[1000.0, 35.81], [14292.6, 0.77], [14392.6, 3.43], [14492.6, 0.0], [51754.0, 0.002], [58223.3, 0.004], [60386.2, 0.0], [61457.9, 0.061], [62104.8, 0.004], [63398.8, 0.636], [63916.3, 41.89], [64045.7, 4.913], [64614.2, 0.629], [64614.9, 0.138], [64632.5, 0.01], [64632.9, 0.005], [64633.0, 0.079], [64633.2, 0.001], [64633.5, 0.638], [64633.8, 0.2], [64643.8, 0.022], [64648.4, 0.462], [64648.8, 0.212], [64649.4, 0.021], [64650.0, 3.082], [64650.3, 0.001], [64650.6, 0.003], [64651.0, 0.012], [64651.3, 0.075], [64651.6, 0.001], [64652.3, 0.337], [64653.7, 0.425], [64654.3, 0.059], [64655.9, 0.001], [64658.4, 0.0], [64663.2, 0.313], [64664.9, 1.046], [64665.0, 1.177], [64665.1, 0.071], [64665.2, 0.05], [64665.3, 0.022], [64665.4, 0.012], [64665.5, 0.558], [64665.6, 0.047], [64665.7, 0.161], [64665.9, 0.057], [64666.3, 0.009], [64666.5, 0.462], [64666.6, 1.679], [64667.1, 0.309], [64667.4, 0.001], [64667.9, 0.0], [64669.1, 0.002], [64669.3, 0.07], [64670.0, 2.339], [64670.8, 0.014], [64671.0, 0.007], [64671.4, 0.47], [64671.6, 0.003], [64672.3, 0.005], [64672.4, 0.0], [64672.8, 0.388], [64675.0, 0.918], [64675.1, 0.603], [64675.3, 0.002], [64676.0, 1.001], [64676.5, 0.0], [64676.7, 0.003], [64676.8, 0.003], [64677.0, 0.908], [64677.1, 0.542], [64677.3, 0.007], [64677.8, 0.0], [64677.9, 0.009], [64678.4, 0.136], [64678.7, 0.001], [64678.8, 0.241], [64679.1, 0.076], [64679.7, 0.005], [64679.8, 0.0], [64680.0, 1.717], [64680.2, 0.0], [64680.3, 1.687], [64680.4, 0.015], [64680.5, 0.311], [64681.2, 0.002], [64681.3, 0.236], [64681.5, 1.928], [64681.6, 0.009], [64681.8, 0.1], [64682.0, 0.003], [64682.1, 0.124], [64682.2, 0.073], [64682.8, 1.814], [64683.2, 1.115], [64683.3, 0.033], [64683.4, 0.001], [64683.6, 0.018], [64683.7, 0.002], [64683.8, 0.001], [64683.9, 0.004], [64684.0, 0.005], [64684.1, 0.0], [64684.2, 0.002], [64684.3, 0.465], [64684.4, 0.0], [64684.5, 0.013], [64684.6, 0.105], [64684.7, 0.782], [64684.8, 0.13], [64684.9, 0.0], [64685.1, 0.002], [64685.2, 0.086], [64685.5, 0.001], [64685.6, 1.898], [64685.7, 0.003], [64685.9, 0.001], [64686.0, 0.089], [64686.2, 0.001], [64686.4, 0.011], [64686.5, 0.002], [64686.8, 0.0], [64686.9, 0.014], [64687.3, 0.807], [64687.4, 0.009], [64688.0, 0.006], [64688.1, 0.085], [64688.3, 0.001], [64688.5, 0.154], [64688.6, 0.002], [64689.0, 0.042], [64689.1, 0.286], [64689.2, 0.001], [64689.3, 0.087], [64689.6, 0.001], [64690.0, 0.004], [64690.1, 0.16], [64690.2, 0.008], [64690.3, 0.001], [64690.4, 0.001], [64691.3, 0.0], [64691.7, 0.0], [64692.5, 0.08], [64692.6, 0.97]], "asks": [[64692.7, 15.05], [64693.1, 0.086], [64693.2, 0.007], [64693.3, 0.004], [64693.4, 0.003], [64694.3, 0.003], [64694.4, 0.012], [64694.8, 0.001], [64694.9, 0.086], [64695.0, 0.007], [64695.5, 0.009], [64697.0, 0.975], [64697.2, 0.008], [64697.5, 0.108], [64697.7, 0.082], [64698.6, 0.685], [64698.9, 0.132], [64699.0, 0.014], [64699.1, 0.594], [64699.2, 0.089], [64699.3, 0.461], [64699.6, 1.005], [64699.9, 0.009], [64700.0, 1.756], [64700.3, 0.46], [64700.5, 0.003], [64700.6, 0.001], [64700.7, 0.005], [64700.8, 0.597], [64700.9, 0.403], [64701.0, 1.222], [64701.1, 0.632], [64701.2, 0.463], [64701.3, 0.168], [64701.4, 0.006], [64701.5, 0.01], [64702.9, 0.631], [64703.2, 1.359], [64703.3, 0.14], [64705.0, 0.918], [64705.3, 0.018], [64705.8, 0.561], [64706.1, 0.06], [64707.5, 0.543], [64707.7, 0.0], [64708.2, 0.031], [64708.3, 0.25], [64708.4, 2.274], [64708.7, 0.023], [64708.9, 10.563], [64709.4, 0.595], [64710.3, 0.134], [64712.7, 0.096], [64714.2, 0.632], [64714.3, 0.002], [64714.9, 2.367], [64716.4, 6.031], [64716.8, 0.021], [64717.1, 0.154], [64717.3, 1.272], [64717.4, 0.194], [64717.6, 0.132], [64717.7, 0.001], [64718.0, 0.101], [64718.1, 0.005], [64718.2, 0.178], [64718.5, 0.682], [64719.3, 0.313], [64719.4, 0.001], [64719.5, 1.242], [64719.6, 0.594], [64719.7, 0.001], [64719.8, 0.001], [64719.9, 0.0], [64720.0, 0.155], [64720.1, 2.344], [64720.2, 0.032], [64720.3, 0.115], [64731.6, 0.019], [64732.4, 0.199], [64733.9, 0.014], [64734.2, 0.313], [64734.5, 0.071], [64734.6, 0.0], [64734.9, 0.502], [64735.2, 0.002], [64759.2, 1.237], [64761.3, 37.728], [64770.4, 0.025], [65339.6, 5.533], [65986.5, 0.018], [66664.3, 0.0]]}
{"kind": "depth", "E": 1787080499269, "U": 11315358228408, "u": 11315358239174, "recv_ms": 1787080499223, "bids": [[14292.6, 1.134], [14392.6, 3.066], [51754.0, 0.0], [51754.1, 0.0], [58223.3, 0.004], [61457.9, 0.061], [63692.6, 0.002], [63802.2, 0.001], [64045.7, 4.913], [64369.1, 5.363], [64569.8, 0.0], [64624.1, 0.0], [64647.7, 0.033], [64648.7, 0.032], [64651.1, 0.371], [64651.6, 0.101], [64656.6, 0.002], [64665.2, 0.01], [64666.7, 0.677], [64669.6, 0.64], [64670.8, 0.002], [64671.0, 0.087], [64672.1, 0.659], [64674.9, 1.293], [64676.0, 0.001], [64677.0, 2.526], [64678.4, 0.137], [64679.5, 0.464], [64680.3, 0.002], [64681.3, 0.235], [64681.4, 0.774], [64681.6, 0.08], [64681.7, 0.266], [64681.8, 0.2], [64682.2, 0.073], [64682.3, 0.407], [64682.5, 0.0], [64682.6, 0.034], [64683.6, 0.05], [64684.8, 0.131], [64686.4, 0.011], [64686.5, 0.312], [64687.4, 0.001], [64687.5, 0.085], [64688.0, 0.007], [64688.5, 0.113], [64688.6, 0.01], [64689.0, 0.0], [64689.1, 0.054], [64689.3, 0.003], [64689.7, 0.232], [64691.9, 0.001], [64692.5, 0.08], [64692.6, 0.969]], "asks": [[64692.7, 28.68], [64692.8, 0.142], [64693.4, 0.003], [64694.3, 0.001], [64694.4, 0.02], [64696.0, 1.281], [64696.3, 0.006], [64696.5, 0.089], [64696.6, 0.052], [64697.0, 0.075], [64697.1, 0.036], [64697.3, 0.023], [64697.4, 0.304], [64697.7, 0.04], [64697.9, 0.004], [64698.0, 0.225], [64698.1, 1.131], [64698.3, 0.55], [64698.4, 1.725], [64698.9, 0.272], [64699.0, 0.134], [64699.2, 0.187], [64699.3, 0.705], [64700.1, 0.017], [64701.0, 1.317], [64701.2, 0.463], [64702.9, 0.311], [64703.1, 0.004], [64703.2, 1.343], [64704.6, 0.923], [64704.9, 0.054], [64706.6, 0.558], [64707.5, 0.002], [64708.3, 0.631], [64711.9, 0.618], [64714.3, 0.0], [64714.6, 0.495], [64714.8, 3.519], [64715.6, 0.536], [64716.4, 6.171], [64717.1, 0.259], [64717.7, 0.121], [64717.9, 0.1], [64718.0, 0.185], [64729.1, 0.013], [64732.1, 0.033], [64733.0, 0.06], [64759.1, 0.021], [64759.2, 1.237], [64760.0, 1.35], [64760.4, 0.382], [64761.3, 38.001], [64765.8, 0.0], [64766.8, 0.455], [64829.7, 0.0], [65339.6, 5.533], [65692.7, 0.006], [65986.5, 0.021]]}
{"kind": "depth", "E": 1787080499371, "U": 11315358239277, "u": 11315358251046, "recv_ms": 1787080499325, "bids": [[1000.0, 35.81], [14292.6, 1.484], [14392.6, 2.716], [58223.3, 0.004], [61457.9, 0.061], [61458.1, 0.007], [62104.8, 0.001], [63916.3, 42.67], [64045.7, 4.913], [64369.1, 5.362], [64563.2, 0.008], [64569.7, 0.124], [64624.0, 0.225], [64648.1, 0.055], [64649.0, 0.281], [64656.6, 0.002], [64660.0, 0.173], [64669.6, 0.022], [64670.0, 1.413], [64671.5, 0.932], [64675.5, 1.464], [64677.0, 0.908], [64677.1, 0.001], [64679.1, 0.617], [64681.4, 0.072], [64681.6, 1.136], [64681.7, 0.336], [64681.9, 0.101], [64682.0, 0.073], [64683.0, 0.032], [64683.9, 0.036], [64684.9, 0.084], [64686.5, 0.002], [64688.1, 0.001], [64688.5, 0.105], [64689.1, 0.286], [64689.2, 0.181], [64689.3, 0.011], [64689.7, 0.0], [64692.5, 0.028], [64692.6, 0.397]], "asks": [[64692.7, 28.739], [64695.9, 0.008], [64696.8, 0.035], [64697.8, 0.048], [64698.8, 0.646], [64699.1, 0.671], [64699.5, 0.138], [64700.9, 0.498], [64701.0, 1.222], [64703.2, 0.418], [64704.0, 3.78], [64704.6, 0.305], [64706.1, 0.003], [64707.1, 0.527], [64714.3, 0.035], [64715.3, 0.481], [64717.4, 0.192], [64717.5, 3.601], [64717.6, 0.252], [64717.9, 0.177], [64729.0, 0.004], [64731.7, 0.056], [64732.7, 1.589], [64766.7, 0.0], [64829.6, 0.004], [64889.3, 0.391], [64889.4, 7.552], [65016.2, 5.103], [65339.6, 5.533], [65469.0, 31.474]]}
{"kind": "depth", "E": 1787080499473, "U": 11315358251162, "u": 11315358263767, "recv_ms": 1787080499426, "bids": [[1000.0, 35.81], [14292.6, 1.834], [14392.6, 2.366], [58223.3, 0.004], [60497.2, 0.002], [61457.9, 0.061], [62104.8, 0.004], [63692.6, 0.022], [63754.6, 22.674], [63924.6, 0.781], [64045.7, 4.913], [64630.9, 0.033], [64661.4, 0.308], [64666.6, 1.563], [64667.7, 0.117], [64670.8, 0.928], [64671.5, 0.006], [64673.7, 0.005], [64676.2, 0.001], [64678.4, 0.678], [64679.1, 0.076], [64681.4, 0.142], [64681.6, 1.206], [64685.4, 0.009], [64692.6, 0.376]], "asks": [[64692.7, 28.74], [64692.9, 0.002], [64693.2, 0.0], [64693.8, 0.093], [64697.0, 0.094], [64697.1, 0.059], [64698.5, 1.238], [64699.1, 0.453], [64699.4, 0.078], [64699.7, 0.312], [64705.8, 0.005], [64706.3, 0.725], [64708.7, 0.021], [64708.9, 10.565], [64710.2, 0.143], [64711.7, 0.014], [64712.4, 5.001], [64717.9, 0.268], [64718.1, 0.082], [64754.9, 0.113], [64889.3, 4.088], [64889.4, 0.01], [65339.6, 5.533], [65498.7, 7.135], [65692.7, 0.026]]}
{"kind": "depth", "E": 1787080499575, "U": 11315358263966, "u": 11315358277102, "recv_ms": 1787080499530, "bids": [[14292.6, 2.198], [14392.6, 2.002], [58223.3, 0.004], [61457.9, 0.061], [62104.8, 0.001], [63803.7, 4.225], [64045.7, 4.913], [64369.1, 5.363], [64569.7, 0.124], [64620.1, 0.004], [64624.0, 0.225], [64630.3, 1.529], [64631.2, 0.032], [64648.9, 0.336], [64652.3, 0.001], [64656.5, 0.002], [64662.8, 0.108], [64663.1, 0.411], [64663.3, 0.109], [64663.4, 0.17], [64664.8, 2.018], [64676.2, 0.003], [64682.7, 0.165], [64683.2, 0.543], [64683.3, 0.057], [64685.7, 0.551], [64688.1, 0.233], [64688.6, 0.018], [64689.1, 0.054], [64689.2, 0.001], [64689.3, 0.003], [64690.1, 0.158], [64692.6, 0.38]], "asks": [[64692.7, 28.748], [64697.0, 0.075], [64697.1, 0.036], [64697.3, 0.004], [64697.4, 0.282], [64700.8, 0.692], [64700.9, 0.403], [64701.0, 0.9], [64704.0, 5.207], [64705.0, 10.92], [64706.3, 0.169], [64706.7, 0.154], [64706.9, 0.557], [64708.4, 0.891], [64708.7, 0.023], [64708.9, 0.565], [64710.2, 0.028], [64710.7, 0.117], [64711.9, 0.0], [64714.7, 2.245], [64722.2, 0.167], [64722.9, 0.0], [64729.0, 0.004], [64766.7, 0.0], [64829.6, 0.004], [64958.4, 6.276], [65016.2, 5.102], [65053.4, 7.132], [65339.6, 5.533], [65623.3, 0.914]]}
{"kind": "depth", "E": 1787080499677, "U": 11315358277274, "u": 11315358287340, "recv_ms": 1787080499630, "bids": [[1000.0, 35.81], [14292.6, 2.562], [14392.6, 1.638], [51754.0, 0.0], [58223.3, 0.004], [61457.9, 0.061], [61458.0, 0.076], [61458.1, 0.009], [62104.8, 0.004], [63592.8, 17.339], [63692.6, 0.002], [64045.6, 0.001], [64045.7, 4.913], [64630.6, 0.033], [64631.6, 0.035], [64662.7, 0.071], [64662.8, 0.178], [64663.0, 0.111], [64663.2, 0.413], [64663.6, 0.071], [64664.3, 0.4], [64665.4, 0.027], [64666.5, 0.414], [64675.2, 0.033], [64683.2, 0.466], [64683.3, 0.041], [64683.6, 0.032], [64684.5, 0.097], [64684.8, 1.944], [64684.9, 0.177], [64685.7, 0.551], [64687.3, 0.157], [64687.4, 0.015], [64687.5, 0.001], [64688.5, 0.285], [64692.5, 0.027], [64692.6, 0.379]], "asks": [[64692.7, 28.743], [64708.9, 0.563], [64722.1, 0.005], [64722.2, 0.013], [64722.3, 1.273], [64740.1, 0.269], [64748.7, 0.027], [65318.7, 1.016], [65339.6, 5.533], [65692.7, 0.006], [65792.5, 4.762]]}
{"kind": "depth", "E": 1787080499779, "U": 11315358287425, "u": 11315358296247, "recv_ms": 1787080499731, "bids": [[1000.0, 35.81], [14292.6, 2.912], [14392.6, 1.288], [51754.0, 0.0], [58223.3, 0.004], [60608.2, 0.0], [64045.7, 4.913], [64369.1, 5.363], [64569.7, 0.124], [64569.8, 0.281], [64614.9, 0.138], [64624.0, 0.225], [64624.1, 0.169], [64647.3, 0.207], [64656.5, 0.002], [64656.6, 0.075], [64662.9, 0.211], [64663.3, 0.179], [64665.5, 0.001], [64666.7, 1.234], [64680.1, 0.483], [64681.5, 0.115], [64681.7, 0.335], [64682.7, 0.166], [64683.2, 0.003], [64683.3, 0.033], [64687.4, 0.0], [64687.5, 0.085], [64688.1, 0.001], [64688.5, 0.105], [64688.6, 0.01], [64689.0, 0.232], [64689.8, 1.757], [64690.2, 0.016], [64692.6, 0.394]], "asks": [[64693.6, 0.042], [64694.4, 0.012], [64696.2, 0.011], [64729.0, 0.004], [64729.1, 0.086], [64738.0, 0.007], [64754.1, 0.012], [64764.3, 0.067], [64766.7, 0.0], [64766.8, 0.624], [64770.4, 0.022], [64829.6, 0.004], [64829.7, 0.282], [65318.7, 0.002], [65339.6, 5.533], [65630.7, 23.851]]}
{"kind": "depth", "E": 1787080499881, "U": 11315358296476, "u": 11315358306080, "recv_ms": 1787080499833, "bids": [[14292.6, 3.262], [14392.6, 0.938], [58223.3, 0.004], [61458.0, 0.074], [61458.1, 0.011], [62104.8, 0.001], [63592.8, 22.051], [63692.6, 0.022], [64045.7, 4.913], [64569.8, 0.0], [64624.1, 0.0], [64656.6, 0.002], [64662.6, 0.418], [64662.9, 0.281], [64680.2, 0.016], [64684.9, 0.161], [64692.5, 0.073]], "asks": [[64729.1, 0.013], [64732.6, 0.094], [64733.6, 3.513], [64766.8, 0.455], [64829.7, 0.0], [64960.0, 5.426], [64961.6, 1.988], [65210.2, 9.342], [65339.6, 5.533], [65469.0, 30.864], [65692.7, 0.026], [65792.5, 9.316]]}
{"kind": "depth", "E": 1787080499983, "U": 11315358306493, "u": 11315358315573, "recv_ms": 1787080499935, "bids": [[1000.0, 35.81], [14292.6, 3.626], [14392.6, 0.574], [58223.3, 0.004], [60719.2, 0.024], [61457.9, 0.061], [62104.8, 0.004], [63398.7, 2.263], [63470.6, 0.058], [63542.5, 0.066], [63614.4, 0.058], [63686.3, 0.73], [63758.2, 2.387], [63830.0, 0.248], [63901.9, 0.058], [63973.8, 3.18], [64045.7, 4.971], [64108.3, 0.468], [64569.8, 0.28], [64624.1, 0.168], [64655.1, 0.43], [64656.6, 0.002], [64656.7, 0.102], [64664.6, 0.034], [64671.7, 0.17], [64680.2, 0.0], [64684.9, 0.177], [64692.6, 0.414]], "asks": [[64702.9, 0.631], [64706.6, 0.238], [64721.5, 1.622], [64721.8, 0.282], [64724.5, 0.003], [64724.8, 1.242], [64725.3, 0.002], [64725.6, 0.045], [64729.1, 0.085], [64766.8, 0.455], [64766.9, 0.169], [64829.7, 0.278], [65210.2, 9.648], [65320.2, 1.933], [65339.5, 0.058], [65339.6, 5.533], [65411.4, 0.058], [65469.0, 31.474], [65483.3, 0.067], [65527.2, 0.305], [65555.2, 0.065], [65627.0, 0.116], [65698.9, 0.06], [65770.8, 0.44], [65842.7, 0.058], [65914.6, 0.058], [65986.5, 0.079]]}
{"kind": "depth", "E": 1787080500085, "U": 11315358315821, "u": 11315358328300, "recv_ms": 1787080500039, "bids": [[1000.0, 35.81], [14192.6, 0.112], [14292.6, 3.752], [14392.6, 0.336], [58223.3, 0.004], [61457.9, 0.061], [62104.8, 0.001], [63692.6, 0.002], [63754.6, 21.578], [63971.3, 2.356], [64045.7, 4.971], [64369.1, 5.363], [64492.8, 13.813], [64495.8, 3.262], [64496.7, 0.0], [64499.0, 0.568], [64569.8, 0.0], [64624.1, 0.0], [64633.0, 0.079], [64633.4, 0.582], [64635.0, 0.038], [64644.1, 0.0], [64648.9, 0.0], [64653.9, 0.336], [64654.3, 0.002], [64656.0, 0.776], [64656.7, 0.029], [64656.9, 0.406], [64657.3, 0.0], [64661.2, 0.154], [64662.6, 0.264], [64664.8, 1.986], [64666.3, 0.002], [64667.0, 0.124], [64667.7, 0.001], [64669.2, 0.117], [64670.8, 0.002], [64671.7, 0.17], [64672.4, 0.926], [64672.7, 0.011], [64672.8, 0.381], [64672.9, 0.002], [64673.1, 0.003], [64674.3, 0.154], [64674.6, 0.008], [64675.5, 0.464], [64677.0, 0.901], [64677.8, 1.007], [64678.4, 0.137], [64679.1, 0.076], [64680.1, 1.024], [64680.2, 0.093], [64681.0, 0.001], [64682.7, 0.165], [64682.8, 2.124], [64683.0, 0.032], [64683.7, 0.005], [64684.2, 0.002], [64684.5, 0.013], [64684.6, 0.106], [64684.9, 0.0], [64685.2, 0.002], [64685.5, 0.0], [64685.7, 0.003], [64685.8, 0.001], [64686.4, 0.312], [64687.4, 0.548], [64687.6, 0.006], [64687.9, 0.086], [64688.2, 0.002], [64688.3, 0.085], [64688.9, 0.085], [64689.0, 0.0], [64689.3, 0.003], [64689.5, 0.233], [64689.7, 0.001], [64689.9, 0.01], [64690.2, 0.008], [64690.5, 0.001], [64691.1, 0.001], [64692.5, 0.075], [64692.6, 3.257]], "asks": [[64692.7, 28.984], [64693.4, 0.0], [64693.7, 0.005], [64693.8, 0.086], [64694.3, 0.008], [64695.5, 0.007], [64696.2, 0.009], [64696.3, 0.006], [64698.0, 0.766], [64698.1, 0.59], [64704.0, 3.032], [64705.0, 0.92], [64705.1, 1.426], [64705.2, 0.174], [64705.5, 1.762], [64706.8, 0.155], [64706.9, 0.001], [64707.1, 0.47], [64707.3, 0.009], [64707.9, 0.002], [64708.1, 0.557], [64708.3, 2.527], [64708.4, 10.001], [64708.8, 0.005], [64709.3, 0.057], [64710.0, 0.131], [64710.3, 0.675], [64710.7, 0.002], [64712.1, 1.699], [64713.2, 0.371], [64717.1, 0.105], [64718.4, 1.295], [64719.6, 0.748], [64724.7, 0.003], [64725.1, 0.03], [64729.1, 0.013], [64739.3, 0.886], [64740.7, 0.0], [64741.1, 0.312], [64754.4, 0.583], [64754.9, 0.131], [64755.0, 0.1], [64755.5, 0.003], [64766.9, 0.002], [64829.7, 0.0], [64889.3, 8.236], [65339.6, 5.533], [65469.0, 31.688], [65692.7, 0.006], [65888.0, 7.117]]}
{"kind": "depth", "E": 1787080500187, "U": 11315358328373, "u": 11315358337313, "recv_ms": 1787080500145, "bids": [[14192.6, 0.35], [14292.6, 3.64], [14392.6, 0.21], [51754.0, 0.0], [58223.3, 0.004], [61457.9, 0.061], [64045.7, 4.971], [64492.8, 2.887], [64492.9, 10.901], [64570.1, 0.0], [64618.0, 0.001], [64624.4, 0.0], [64647.3, 0.21], [64650.8, 3.631], [64651.9, 0.321], [64656.4, 0.057], [64656.9, 0.349], [64661.1, 0.139], [64679.1, 0.617], [64680.1, 0.483], [64680.2, 0.541], [64684.9, 0.18], [64685.7, 0.103], [64687.0, 0.005], [64687.4, 0.0], [64689.3, 0.087], [64692.6, 3.274]], "asks": [[64692.7, 28.996], [64703.0, 0.016], [64708.4, 10.06], [64708.9, 0.561], [64709.3, 0.541], [64710.3, 0.134], [64728.9, 0.158], [64729.2, 0.019], [64729.4, 2.761], [64767.1, 0.002], [64770.4, 0.025], [64830.0, 0.203], [64889.3, 6.34], [65339.6, 5.533]]}
{"kind": "depth", "E": 1787080500289, "U": 11315358337531, "u": 11315358347664, "recv_ms": 1787080500242, "bids": [[1000.0, 35.81], [14192.6, 0.588], [14292.6, 3.514], [14392.6, 0.098], [51754.0, 0.0], [51754.1, 0.0], [58223.3, 0.055], [60830.2, 0.0], [61457.9, 0.061], [62104.8, 0.004], [63398.8, 0.639], [63692.6, 0.022], [63754.6, 22.674], [63985.1, 0.0], [64045.7, 4.971], [64104.6, 0.234], [64492.9, 10.901], [64663.6, 0.108], [64668.8, 0.36], [64672.1, 1.585], [64672.4, 0.0], [64678.3, 1.806], [64682.1, 0.104], [64689.3, 0.003], [64692.6, 3.274]], "asks": [[64692.7, 28.985], [64889.3, 6.339], [65339.6, 5.533], [65692.7, 0.026]]}
{"kind": "depth", "E": 1787080500391, "U": 11315358347819, "u": 11315358358000, "recv_ms": 1787080500342, "bids": [[1000.0, 35.81], [14192.6, 0.854], [14292.6, 3.346], [14392.6, 0.0], [58223.3, 0.055], [61457.9, 0.061], [62104.8, 0.001], [64045.7, 4.971], [64563.2, 0.008], [64570.2, 0.001], [64624.4, 0.0], [64633.0, 0.065], [64657.0, 0.0], [64669.9, 0.872], [64677.3, 0.007], [64677.8, 0.007], [64679.1, 1.076], [64679.2, 0.541], [64680.0, 1.717], [64680.1, 0.483], [64680.3, 0.095], [64684.9, 0.0], [64685.7, 0.01], [64689.3, 0.087], [64692.6, 3.954]], "asks": [[64692.7, 29.051], [64694.5, 0.099], [64704.8, 0.209], [64708.3, 1.043], [64708.4, 0.003], [64708.8, 0.546], [64709.0, 0.058], [64709.3, 0.0], [64710.3, 0.134], [64710.9, 10.002], [64712.2, 2.376], [64729.4, 2.761], [64737.0, 0.002], [64760.0, 1.35], [64767.2, 0.0], [64830.0, 0.203], [65016.2, 5.101], [65339.6, 5.533], [65889.5, 3.936]]}
{"kind": "depth", "E": 1787080500493, "U": 11315358358183, "u": 11315358367672, "recv_ms": 1787080500448, "bids": [[14192.6, 1.204], [14292.6, 2.996], [58223.3, 0.055], [60941.2, 0.0], [61457.9, 0.061], [62104.8, 0.004], [63692.6, 0.002], [63981.0, 8.191], [64045.7, 4.971], [64363.5, 0.003], [64369.1, 5.364], [64655.4, 0.062], [64656.4, 0.0], [64666.1, 0.567], [64666.7, 0.677], [64667.0, 0.117], [64667.6, 0.387], [64667.7, 0.008], [64668.4, 0.002], [64669.2, 0.001], [64671.0, 1.013], [64672.1, 0.659], [64678.4, 0.678], [64679.2, 0.0], [64680.1, 0.475], [64680.3, 0.11], [64680.5, 0.002], [64681.4, 0.451], [64684.5, 0.011], [64684.9, 0.18], [64685.7, 0.003], [64688.5, 0.113], [64688.6, 0.002]], "asks": [[64692.7, 29.059], [64695.4, 0.143], [64696.3, 0.002], [64697.0, 0.016], [64697.9, 0.012], [64698.0, 0.758], [64699.7, 0.003], [64700.0, 2.065], [64703.5, 0.259], [64704.4, 1.402], [64705.1, 0.501], [64706.3, 0.169], [64707.2, 0.011], [64707.3, 0.558], [64708.0, 0.148], [64708.1, 0.001], [64708.2, 0.088], [64708.8, 0.005], [64709.0, 0.001], [64709.3, 0.541], [64710.4, 0.644], [64711.3, 0.283], [64712.1, 1.584], [65339.6, 5.533], [65692.7, 0.006], [65796.7, 3.035]]}
{"kind": "depth", "E": 1787080500595, "U": 11315358367746, "u": 11315358381221, "recv_ms": 1787080500555, "bids": [[1000.0, 35.81], [14192.6, 1.568], [14292.6, 2.632], [51754.0, 0.0], [58223.3, 0.055], [61457.9, 0.061], [63398.8, 0.642], [63778.1, 1.493], [64045.7, 4.971], [64369.1, 5.053], [64570.1, 0.0], [64580.7, 0.004], [64624.4, 0.0], [64650.7, 3.269], [64653.9, 0.0], [64656.9, 0.349], [64666.7, 0.697], [64669.9, 0.254], [64673.3, 0.012], [64673.5, 0.159], [64674.3, 0.0], [64674.6, 0.001], [64676.2, 0.003], [64676.7, 0.01], [64676.9, 1.003], [64677.4, 0.372], [64677.8, 0.0], [64678.0, 2.557], [64678.9, 0.003], [64679.1, 0.076], [64680.1, 0.476], [64680.2, 0.309], [64680.3, 2.472], [64680.9, 0.0], [64681.4, 0.142], [64681.8, 2.013], [64682.7, 0.165], [64682.8, 1.61], [64683.7, 0.002], [64684.2, 0.002], [64684.6, 0.105], [64684.7, 0.398], [64684.8, 0.131], [64684.9, 0.084], [64685.2, 0.086], [64685.5, 0.001], [64685.7, 0.003], [64686.4, 0.002], [64687.1, 0.084], [64687.9, 0.002], [64688.2, 0.001], [64688.3, 0.001], [64688.5, 0.105], [64688.6, 0.01], [64688.8, 0.236], [64688.9, 0.001], [64689.3, 0.003], [64689.5, 0.001], [64689.8, 0.101], [64689.9, 0.002], [64692.6, 1.663]], "asks": [[64692.7, 28.775], [64692.9, 0.009], [64693.6, 0.055], [64694.3, 0.001], [64694.8, 0.002], [64695.3, 0.517], [64697.4, 0.011], [64703.9, 0.006], [64704.0, 4.308], [64707.0, 0.495], [64707.1, 10.472], [64708.4, 0.001], [64708.7, 0.023], [64710.8, 1.532], [64710.9, 0.002], [64711.2, 0.001], [64722.3, 1.273], [64729.4, 2.761], [64731.5, 0.05], [64740.1, 0.059], [64747.4, 0.21], [64754.1, 0.052], [64754.9, 0.113], [64760.4, 6.764], [64764.3, 0.027], [64767.1, 0.002], [64830.0, 0.203], [65210.2, 9.342], [65339.6, 5.533], [65986.5, 0.076]]}
{"kind": "depth", "E": 1787080500697, "U": 11315358381477, "u": 11315358395226, "recv_ms": 1787080500651, "bids": [[1000.0, 35.81], [14192.6, 1.932], [14292.6, 2.268], [58223.3, 0.055], [61457.9, 0.061], [62104.8, 0.001], [63334.1, 0.003], [63422.1, 0.675], [63689.9, 6.9], [63692.6, 0.022], [63916.3, 42.046], [64045.6, 0.0], [64045.7, 4.971], [64369.1, 5.043], [64492.9, 0.0], [64493.0, 15.579], [64609.7, 32.02], [64611.1, 7.295], [64618.5, 0.005], [64620.4, 1.649], [64676.9, 0.003], [64678.0, 3.557], [64678.5, 0.008], [64680.1, 0.012], [64680.3, 0.002], [64681.7, 0.335], [64681.8, 0.2], [64681.9, 1.338], [64682.4, 0.31], [64682.7, 0.165], [64682.9, 0.001], [64683.2, 0.003], [64683.3, 0.496], [64683.5, 0.006], [64684.2, 0.003], [64684.4, 1.61], [64684.7, 0.997], [64684.8, 0.224], [64684.9, 0.0], [64685.7, 0.551], [64685.8, 0.181], [64685.9, 0.063], [64686.5, 0.312], [64687.4, 0.0], [64687.9, 0.086], [64688.3, 0.085], [64688.5, 0.051], [64688.6, 0.002], [64688.7, 0.109], [64688.8, 0.255], [64689.8, 1.914], [64689.9, 0.01], [64691.1, 0.0], [64692.6, 2.893]], "asks": [[64692.7, 28.659], [64692.9, 0.002], [64693.7, 0.012], [64695.3, 0.246], [64696.4, 0.279], [64722.3, 1.119], [64722.4, 1.782], [64770.6, 0.376], [64889.3, 0.391], [64889.4, 1.743], [65016.2, 5.102], [65339.6, 5.533], [65692.7, 0.026], [65792.5, 9.694], [65986.5, 0.079], [66180.6, 4.466], [66642.5, 1.926]]}
{"kind": "depth", "E": 1787080500799, "U": 11315358395244, "u": 11315358402747, "recv_ms": 1787080500758, "bids": [[14192.6, 2.282], [14292.6, 1.918], [58223.3, 0.055], [61458.1, 0.009], [62104.8, 0.004], [63819.2, 13.319], [64045.7, 4.971], [64149.1, 0.196], [64570.1, 0.0], [64609.7, 0.118], [64611.1, 3.315], [64618.5, 31.74], [64624.4, 0.0], [64649.7, 0.017], [64650.7, 2.933], [64654.8, 0.339], [64656.9, 0.349], [64678.5, 0.463], [64680.1, 0.113], [64683.3, 0.033], [64684.8, 0.131], [64685.5, 0.0], [64685.7, 0.003], [64685.8, 0.549], [64687.3, 0.157], [64688.3, 0.086], [64691.1, 0.001], [64692.6, 3.487]], "asks": [[64694.8, 0.003], [64704.0, 3.032], [64707.1, 0.472], [64708.3, 2.405], [64710.3, 10.134], [64717.5, 2.618], [64721.8, 0.298], [64722.4, 1.782], [64729.4, 2.761], [64733.3, 0.909], [64733.6, 0.013], [64756.3, 0.166], [64759.2, 39.703], [64760.4, 0.382], [64761.3, 0.005], [64767.1, 0.002], [64770.6, 0.375], [64790.3, 0.0], [64790.4, 2.216], [64790.7, 0.004], [64790.9, 0.008], [64830.0, 0.203], [65016.2, 4.948], [65210.2, 9.648], [65339.6, 5.533], [65984.8, 0.75]]}
{"kind": "depth", "E": 1787080500901, "U": 11315358402881, "u": 11315358409734, "recv_ms": 1787080500855, "bids": [[1000.0, 35.81], [14192.6, 2.632], [14292.6, 1.568], [58223.3, 0.055], [61457.9, 0.061], [62104.8, 0.001], [63689.9, 7.998], [63692.6, 0.002], [63791.0, 41.457], [63916.3, 42.67], [64045.7, 4.971], [64175.1, 9.802], [64369.1, 5.353], [64535.6, 0.0], [64536.7, 0.404], [64552.6, 0.012], [64684.8, 0.131], [64692.6, 3.576]], "asks": [[64692.7, 29.065], [64694.8, 0.004], [64702.3, 0.033], [64709.7, 0.006], [64715.8, 1.051], [64718.5, 0.698], [64722.4, 1.628], [64722.5, 1.155], [64732.0, 3.585], [64754.6, 6.375], [64759.2, 1.237], [64763.6, 38.467], [64784.0, 2.191], [64787.0, 10.0], [64833.5, 0.103], [64850.5, 0.028], [65339.6, 5.533], [65692.7, 0.006]]}
{"kind": "depth", "E": 1787080501003, "U": 11315358409995, "u": 11315358417208, "recv_ms": 1787080500956, "bids": [[1000.0, 35.81], [14192.6, 2.996], [14292.6, 1.204], [58223.3, 0.055], [61052.2, 0.0], [62104.8, 0.004], [63334.1, 0.318], [63487.0, 4.055], [63722.3, 0.015], [63859.2, 0.001], [64045.7, 4.971], [64369.1, 5.208], [64531.9, 9.883], [64548.9, 5.346], [64550.1, 2.743], [64582.6, 0.005], [64614.9, 0.135], [64671.0, 1.011], [64671.5, 0.008], [64685.7, 0.544], [64685.8, 0.008]], "asks": [[64694.8, 0.008], [64710.4, 0.646], [64710.7, 0.0], [64721.8, 0.314], [64725.0, 0.019], [64725.1, 0.027], [64728.2, 0.027], [64731.5, 0.078], [64738.0, 0.004], [64739.3, 1.375], [64741.1, 4.054], [64749.5, 0.002], [64761.3, 38.471], [64763.6, 0.001], [64770.4, 0.022], [64833.5, 0.127], [64833.6, 9.218], [64843.6, 0.0], [64850.5, 8.31], [64889.4, 3.867], [65339.6, 5.533], [65630.7, 22.786], [65986.5, 0.076]]}
{"kind": "depth", "E": 1787080501105, "U": 11315358417405, "u": 11315358428357, "recv_ms": 1787080501059, "bids": [[14192.6, 3.346], [14292.6, 0.854], [58223.3, 0.055], [61457.9, 0.061], [61458.0, 0.072], [61458.1, 0.011], [63398.8, 0.645], [63692.6, 0.022], [63823.4, 10.3], [63916.3, 42.045], [64045.7, 4.971], [64369.1, 5.363], [64595.6, 0.0], [64596.8, 3.352], [64615.1, 2.333], [64619.6, 0.028], [64620.1, 0.013], [64647.3, 0.207], [64651.7, 0.337], [64654.8, 0.003], [64655.4, 0.005], [64656.1, 0.057], [64662.7, 0.141], [64669.3, 0.0], [64671.0, 0.085], [64671.1, 0.002], [64671.5, 0.006], [64671.7, 1.096], [64671.8, 0.001], [64678.4, 0.137], [64678.5, 0.0], [64679.1, 0.617], [64680.1, 0.56], [64680.3, 0.543], [64680.4, 0.031], [64681.0, 0.001], [64681.9, 0.101], [64682.4, 0.31], [64684.2, 0.002], [64684.3, 0.466], [64684.5, 0.095], [64684.8, 0.131], [64684.9, 0.084], [64685.7, 0.01], [64685.8, 0.001], [64687.5, 0.085], [64687.9, 0.002], [64688.3, 0.002], [64688.7, 0.025], [64692.6, 3.575]], "asks": [[64692.7, 29.077], [64694.8, 0.009], [64704.2, 0.927], [64704.4, 0.477], [64708.0, 0.205], [64708.2, 0.031], [64708.8, 0.546], [64709.3, 0.0], [64709.9, 0.118], [64710.1, 0.005], [64710.4, 0.644], [64711.0, 0.315], [64718.5, 0.712], [64722.5, 1.001], [64722.7, 2.978], [64725.1, 0.03], [64732.0, 3.586], [64737.9, 0.395], [64745.0, 2.322], [64745.5, 0.008], [64747.4, 0.0], [64757.0, 0.346], [64758.5, 0.002], [64761.6, 0.062], [65016.2, 5.102], [65339.6, 5.533], [65478.6, 3.053], [65692.7, 0.026]]}
{"kind": "depth", "E": 1787080501207, "U": 11315358428414, "u": 11315358436815, "recv_ms": 1787080501159, "bids": [[1000.0, 35.81], [14192.6, 3.682], [14292.6, 0.504], [14592.6, 0.014], [58223.3, 0.055], [62104.8, 0.001], [63906.7, 3.125], [64045.7, 4.971], [64175.1, 9.803], [64590.6, 0.212], [64591.0, 0.003], [64640.8, 0.049], [64647.3, 0.21], [64680.4, 0.038], [64685.7, 0.183], [64688.0, 0.091], [64688.5, 0.008], [64692.6, 3.572]], "asks": [[64692.7, 29.079], [64697.3, 0.005], [64703.3, 0.139], [64710.1, 0.003], [64710.3, 10.136], [64881.7, 0.0], [64882.1, 0.008], [65339.6, 5.533], [65505.6, 3.53], [65630.7, 22.786], [65695.4, 8.36]]}
{"kind": "depth", "E": 1787080501309, "U": 11315358437033, "u": 11315358444104, "recv_ms": 1787080501261, "bids": [[1000.0, 35.81], [14192.6, 3.724], [14292.6, 0.308], [14592.6, 0.168], [51754.1, 0.0], [58223.3, 0.055], [61163.2, 0.021], [61457.9, 0.061], [62104.8, 0.004], [63692.6, 0.002], [63916.3, 42.67], [64045.7, 4.971], [64149.1, 0.172], [64369.1, 5.353], [64403.3, 0.026], [64548.9, 0.002], [64570.1, 0.0], [64624.4, 0.0], [64656.9, 0.349], [64671.1, 0.0], [64671.5, 0.008], [64679.9, 0.156], [64680.0, 1.563], [64680.4, 0.031], [64684.8, 0.227], [64684.9, 0.132], [64685.7, 0.003], [64685.8, 0.008], [64692.5, 0.029], [64692.6, 3.573]], "asks": [[64697.3, 0.004], [64729.4, 2.761], [64767.1, 0.002], [64830.0, 0.203], [64833.5, 0.103], [64833.6, 3.82], [64843.6, 0.024], [65339.6, 5.533], [65630.7, 23.851], [65692.7, 0.006]]}
{"kind": "depth", "E": 1787080501411, "U": 11315358444322, "u": 11315358453353, "recv_ms": 1787080501363, "bids": [[14192.6, 3.612], [14292.6, 0.182], [14592.6, 0.406], [51754.0, 0.0], [58223.3, 0.055], [61457.9, 0.061], [62104.8, 0.001], [63778.1, 1.259], [64045.7, 4.971], [64076.5, 1.733], [64531.9, 0.776], [64532.0, 9.09], [64549.0, 8.56], [64563.2, 0.008], [64656.1, 0.0], [64656.4, 0.057], [64669.7, 1.155], [64671.7, 0.17], [64672.0, 4.297], [64677.1, 0.001], [64677.9, 0.0], [64678.0, 2.557], [64679.3, 1.004], [64679.5, 0.473], [64679.9, 0.002], [64680.0, 1.717], [64680.4, 0.038], [64684.3, 0.465], [64684.5, 0.011], [64684.6, 0.106], [64684.8, 0.131], [64684.9, 0.0], [64685.7, 0.003], [64685.8, 0.001], [64688.6, 0.086], [64689.0, 0.084], [64692.5, 0.034], [64692.6, 4.889]], "asks": [[64692.7, 29.078], [64695.8, 0.092], [64704.2, 0.002], [64704.4, 1.402], [64704.6, 0.305], [64708.0, 0.148], [64708.2, 0.088], [64708.8, 0.005], [64709.3, 0.541], [64710.2, 0.026], [64710.3, 10.136], [64710.7, 0.002], [64712.0, 2.898], [64754.9, 0.131], [64833.6, 9.218], [64850.5, 0.028], [64850.6, 8.279], [64889.4, 3.916], [65304.8, 2.293], [65320.2, 2.589], [65339.6, 5.533], [65501.3, 0.001], [65673.5, 0.0], [65695.4, 9.424], [67300.8, 0.102]]}
{"kind": "depth", "E": 1787080501513, "U": 11315358453799, "u": 11315358463570, "recv_ms": 1787080501470, "bids": [[1000.0, 35.81], [14192.6, 3.486], [14292.6, 0.07], [14592.6, 0.644], [58223.3, 0.055], [61274.2, 0.0], [62104.8, 0.004], [63380.1, 2.507], [63692.6, 0.022], [63722.2, 21.493], [63920.4, 27.33], [63934.2, 0.0], [64045.7, 4.971], [64078.0, 13.36], [64175.1, 10.113], [64369.1, 5.352], [64493.0, 0.073], [64493.2, 15.509], [64570.2, 0.001], [64570.3, 0.0], [64624.4, 0.0], [64624.5, 2.071], [64651.7, 0.001], [64655.8, 0.029], [64656.4, 0.0], [64656.6, 0.059], [64656.8, 0.361], [64657.0, 0.0], [64657.1, 0.442], [64667.6, 0.271], [64668.1, 0.117], [64669.0, 0.001], [64671.5, 0.006], [64671.8, 0.003], [64672.0, 3.371], [64672.3, 0.931], [64676.7, 0.003], [64677.7, 0.012], [64679.1, 0.076], [64679.4, 0.384], [64679.5, 0.535], [64680.1, 1.101], [64680.2, 0.0], [64680.4, 0.046], [64681.3, 0.544], [64681.8, 0.208], [64682.8, 0.001], [64684.4, 0.0], [64684.6, 0.105], [64684.7, 0.398], [64684.8, 0.131], [64684.9, 0.0], [64685.2, 0.002], [64685.5, 0.001], [64685.6, 1.814], [64685.7, 0.183], [64685.9, 0.001], [64686.9, 0.007], [64687.7, 0.001], [64688.3, 0.001], [64688.5, 0.0], [64688.6, 0.091], [64688.7, 0.002], [64688.8, 0.004], [64688.9, 0.023], [64689.0, 0.104], [64689.5, 0.233], [64689.6, 0.104], [64689.7, 0.002], [64689.9, 0.002], [64690.1, 0.242], [64692.6, 7.063]], "asks": [[64692.7, 25.331], [64693.6, 0.013], [64693.7, 0.005], [64694.4, 0.019], [64696.0, 0.381], [64696.2, 0.001], [64697.0, 0.916], [64698.6, 0.695], [64699.3, 0.545], [64700.0, 1.756], [64700.3, 0.769], [64702.8, 0.183], [64702.9, 0.311], [64703.0, 0.916], [64703.9, 0.006], [64704.4, 0.477], [64704.8, 1.134], [64706.6, 0.558], [64707.7, 0.0], [64708.0, 0.141], [64708.2, 0.031], [64708.3, 1.043], [64708.4, 0.001], [64708.5, 0.368], [64708.8, 0.012], [64709.3, 0.541], [64710.3, 0.136], [64710.7, 0.0], [64710.9, 0.004], [64711.3, 0.168], [64711.9, 0.115], [64712.4, 0.001], [64714.3, 10.035], [64729.5, 0.003], [64729.6, 0.01], [64753.3, 2.321], [64754.6, 6.377], [64757.4, 0.411], [64760.0, 1.359], [64767.2, 0.0], [64767.3, 0.522], [64770.6, 0.375], [64830.1, 0.745], [64830.2, 0.016], [64833.5, 0.127], [64843.6, 0.0], [64889.4, 1.581], [65016.2, 5.103], [65339.6, 5.533], [65692.7, 0.026], [65986.5, 0.073]]}
{"kind": "depth", "E": 1787080501615, "U": 11315358463752, "u": 11315358470890, "recv_ms": 1787080501568, "bids": [[1000.0, 35.81], [14192.6, 3.262], [14292.6, 0.0], [14592.6, 0.938], [50000.0, 233.322], [58223.3, 0.055], [61457.9, 0.061], [62733.4, 1.001], [63398.8, 0.648], [64045.7, 4.971], [64369.1, 5.362], [64676.2, 0.003], [64679.4, 0.925], [64679.5, 0.473], [64680.1, 0.622], [64680.2, 0.016], [64680.4, 0.03], [64684.8, 0.131], [64684.9, 0.0], [64685.2, 1.973], [64685.7, 0.093], [64690.1, 0.158], [64692.6, 7.063]], "asks": [[64692.7, 25.342], [64703.0, 0.016], [64708.7, 0.023], [64714.2, 4.73], [64714.7, 0.011], [64721.5, 1.62], [64721.6, 1.359], [64721.7, 0.003], [64724.5, 0.001], [64724.6, 0.0], [64724.7, 0.001], [64725.3, 0.0], [64725.4, 0.006], [64725.5, 0.0], [64727.6, 0.0], [64727.7, 0.026], [64727.8, 0.001], [64753.2, 1.68], [64759.2, 1.237], [64760.0, 1.35], [64761.3, 0.005], [64763.6, 38.76], [65339.6, 5.533], [65668.9, 0.266], [65984.8, 0.101], [66114.3, 0.001]]}
{"kind": "depth", "E": 1787080501819, "U": 11315358477389, "u": 11315358484330, "recv_ms": 1787080501772, "bids": [[1000.0, 35.96], [14192.6, 2.548], [14592.6, 1.652], [51754.0, 0.0], [58223.3, 0.055], [61457.9, 0.061], [62104.8, 0.004], [63779.7, 2.349], [64045.7, 4.971], [64653.7, 0.411], [64666.1, 0.01], [64666.8, 0.573], [64667.7, 0.008], [64671.8, 0.927], [64672.3, 0.005], [64675.6, 0.0], [64679.4, 0.925], [64680.1, 0.552], [64680.2, 0.062], [64680.3, 0.002], [64680.4, 0.022], [64680.5, 0.002], [64680.6, 2.32], [64680.7, 0.739], [64684.8, 0.131], [64685.3, 0.096], [64687.3, 0.337], [64688.9, 0.107], [64692.5, 0.081], [64692.6, 7.078]], "asks": [[64707.3, 0.002], [64708.1, 0.557], [64708.8, 0.553], [64709.3, 0.0], [64710.3, 0.136], [65339.6, 5.533]]}
{"kind": "depth", "E": 1787080501921, "U": 11315358484485, "u": 11315358491214, "recv_ms": 1787080501879, "bids": [[1000.0, 35.81], [14192.6, 2.198], [14592.6, 2.002], [58223.3, 0.055], [61385.2, 0.0], [62086.7, 2.006], [62104.8, 0.001], [63214.3, 0.005], [63692.6, 0.022], [63888.1, 7.296], [63891.1, 5.563], [64045.7, 4.971], [64369.1, 6.796], [64548.3, 0.16], [64549.0, 3.23], [64680.2, 0.0], [64680.7, 0.801], [64684.8, 0.311], [64685.3, 0.0], [64685.7, 0.003], [64687.3, 0.157]], "asks": [[64833.6, 3.82], [65307.3, 9.258], [65339.6, 5.533], [65692.7, 0.026]]}
{"kind": "depth", "E": 1787080502023, "U": 11315358491257, "u": 11315358500037, "recv_ms": 1787080501976, "bids": [[14192.6, 1.834], [14592.6, 2.366], [58223.3, 0.055], [61457.9, 0.061], [61762.8, 0.345], [64045.7, 4.971], [64549.2, 5.381], [64570.3, 0.0], [64624.5, 2.071], [64651.1, 0.357], [64657.1, 0.442], [64667.3, 0.006], [64672.5, 5.001], [64679.9, 0.0], [64684.8, 0.131], [64685.3, 0.096], [64685.7, 0.183], [64687.3, 0.337], [64688.9, 0.085], [64689.6, 0.024], [64689.7, 0.022], [64692.6, 7.098]], "asks": [[64693.7, 0.047], [64704.2, 0.927], [64704.8, 0.209], [64707.9, 0.059], [64708.5, 0.311], [64729.6, 0.01], [64759.2, 39.996], [64760.0, 1.35], [64761.3, 0.005], [64767.3, 0.522], [64830.2, 0.016], [64833.5, 0.103], [64833.6, 9.194], [64843.6, 0.024], [64889.4, 6.486], [65339.6, 5.533], [65641.5, 2.2], [65792.5, 10.072], [65977.9, 0.606]]}
{"kind": "depth", "E": 1787080502125, "U": 11315358500277, "u": 11315358507921, "recv_ms": 1787080502082, "bids": [[1000.0, 35.81], [14192.6, 1.484], [14592.6, 2.716], [51754.0, 0.002], [58223.3, 0.055], [61458.0, 0.074], [62104.8, 0.004], [62104.9, 0.001], [63692.6, 0.002], [63786.9, 32.235], [63883.9, 18.223], [64045.7, 4.971], [64175.1, 9.802], [64570.3, 0.0], [64611.9, 0.004], [64612.3, 0.209], [64618.5, 31.445], [64621.0, 0.015], [64623.4, 1.323], [64624.5, 2.071], [64643.6, 0.445], [64657.1, 0.442], [64659.8, 0.451], [64681.0, 0.001], [64687.3, 0.157]], "asks": [[64715.8, 0.09], [64729.6, 0.01], [64732.0, 0.086], [64753.2, 0.884], [64754.6, 0.377], [64767.3, 0.522], [64830.2, 0.016], [64833.5, 0.127], [64843.6, 0.0], [64850.6, 10.412], [64889.4, 3.925], [65155.9, 0.211], [65339.6, 5.535], [65692.7, 0.006]]}
{"kind": "depth", "E": 1787080502227, "U": 11315358507964, "u": 11315358516374, "recv_ms": 1787080502180, "bids": [[14192.6, 1.12], [14592.6, 3.08], [51754.0, 0.0], [58223.3, 0.055], [62104.8, 0.001], [63754.6, 21.578], [64045.7, 4.971], [64369.1, 6.806], [64549.2, 0.0], [64588.7, 0.0], [64588.8, 1.024], [64620.6, 6.037], [64643.3, 13.726], [64659.4, 0.969], [64687.3, 0.337], [64692.6, 7.099]], "asks": [[64700.9, 0.404], [64715.8, 1.066], [64732.0, 3.586], [64754.7, 6.0], [64784.0, 0.697], [64787.0, 0.0], [64833.6, 3.82], [65339.6, 5.533]]}
{"kind": "depth", "E": 1787080502329, "U": 11315358516452, "u": 11315358523759, "recv_ms": 1787080502283, "bids": [[14192.6, 0.756], [14592.6, 3.444], [51754.0, 0.0], [51754.1, 0.0], [58223.3, 0.055], [61457.9, 0.061], [62104.8, 0.004], [63398.8, 0.648], [63692.6, 0.022], [63774.0, 3.312], [64045.7, 4.971], [64450.5, 0.007], [64496.9, 0.002], [64532.0, 0.013], [64532.2, 9.287], [64549.2, 5.061], [64561.1, 0.374], [64570.3, 0.281], [64582.6, 0.002], [64586.0, 0.509], [64588.8, 1.016], [64607.5, 0.0], [64624.5, 2.24], [64647.3, 0.21], [64653.7, 0.425], [64657.1, 0.515], [64680.0, 1.563], [64680.1, 0.706], [64687.3, 0.337], [64692.6, 7.063]], "asks": [[64692.7, 24.628], [64712.2, 2.373], [64729.6, 0.083], [64733.9, 0.013], [64754.2, 0.004], [64759.2, 1.237], [64760.0, 1.359], [64761.3, 39.029], [64763.6, 0.001], [64767.3, 0.691], [64780.5, 0.022], [64827.1, 0.0], [64830.1, 1.027], [64833.5, 0.103], [64833.6, 8.996], [64843.6, 0.024], [64850.6, 8.256], [64873.8, 0.008], [64889.4, 4.225], [65000.0, 117.622], [65016.2, 4.948], [65151.4, 0.231], [65339.6, 5.533], [65469.0, 31.23], [65692.7, 0.026]]}
{"kind": "depth", "E": 1787080502431, "U": 11315358523842, "u": 11315358530257, "recv_ms": 1787080502389, "bids": [[1000.0, 35.81], [14192.6, 0.448], [14492.6, 0.042], [14592.6, 3.71], [58223.3, 0.055], [61439.9, 3.0], [61457.9, 0.061], [62104.8, 0.001], [63754.6, 22.674], [63808.6, 0.007], [64045.7, 4.971], [64175.1, 10.113], [64403.3, 0.001], [64495.3, 0.007], [64563.2, 0.008], [64570.3, 0.0], [64588.3, 10.004], [64605.8, 0.028], [64624.5, 2.071], [64657.1, 0.442], [64669.7, 1.155], [64677.0, 1.519], [64680.1, 0.552], [64680.2, 0.154], [64687.3, 0.337], [64692.6, 7.061]], "asks": [[64704.6, 0.923], [64711.9, 0.733], [64729.6, 0.01], [64767.3, 0.522], [64787.0, 10.0], [64830.1, 0.745], [64833.5, 0.127], [64843.6, 0.0], [64889.4, 4.224], [65339.6, 5.533], [65462.5, 8.244]]}
{"kind": "depth", "E": 1787080502533, "U": 11315358530371, "u": 11315358536878, "recv_ms": 1787080502489, "bids": [[14192.6, 0.28], [14492.6, 0.224], [14592.6, 3.696], [58223.3, 0.055], [60793.2, 4.0], [61457.9, 0.061], [61458.0, 0.072], [61458.1, 0.013], [61496.2, 0.0], [63398.8, 0.651], [63692.6, 0.002], [64045.7, 4.971], [64369.1, 6.807], [64549.2, 0.0], [64549.3, 5.087], [64570.3, 0.0], [64586.0, 0.501], [64588.4, 0.009], [64624.5, 2.071], [64655.8, 0.086], [64656.1, 0.0], [64657.1, 0.442], [64667.3, 0.013], [64667.7, 0.001], [64669.7, 0.537], [64671.1, 0.002], [64671.4, 1.396], [64671.6, 0.003], [64671.8, 0.001], [64677.0, 0.901], [64679.1, 0.617], [64679.4, 0.384], [64680.1, 0.012], [64680.2, 0.0], [64680.7, 0.228], [64680.8, 0.466], [64680.9, 0.309], [64681.3, 0.235], [64681.6, 1.205], [64681.8, 0.858], [64685.1, 0.004], [64685.5, 0.0], [64685.7, 0.003], [64687.3, 0.157], [64688.3, 0.002], [64688.9, 0.001], [64689.0, 0.274], [64689.5, 0.001], [64689.6, 0.001], [64689.7, 0.001], [64692.6, 4.792]], "asks": [[64692.7, 24.935], [64695.8, 0.086], [64696.1, 0.106], [64703.8, 1.516], [64704.2, 0.002], [64704.6, 0.305], [64708.0, 0.148], [64708.8, 0.546], [64729.6, 0.01], [64767.3, 0.522], [64830.1, 0.745], [64833.6, 8.997], [64889.4, 4.226], [65016.2, 5.101], [65339.6, 5.533], [65469.0, 31.688], [65692.7, 0.006], [65963.2, 0.649]]}
{"kind": "depth", "E": 1787080502635, "U": 11315358537065, "u": 11315358544227, "recv_ms": 1787080502588, "bids": [[14192.6, 0.154], [14492.6, 0.462], [14592.6, 3.584], [58223.3, 0.055], [61457.9, 0.061], [61458.0, 0.074], [62104.8, 0.004], [63439.7, 0.001], [63817.0, 1.973], [64045.7, 4.971], [64570.2, 0.283], [64620.4, 6.292], [64624.4, 0.169], [64657.0, 0.073], [64676.2, 0.003], [64680.2, 0.154], [64680.8, 0.003], [64681.8, 0.293], [64681.9, 0.579], [64682.0, 0.63], [64682.1, 0.104], [64684.7, 0.616], [64684.8, 0.131], [64685.2, 2.057], [64685.3, 0.0], [64685.7, 0.183], [64687.3, 0.157], [64688.6, 0.007], [64689.9, 0.01], [64692.6, 4.886]], "asks": [[64692.7, 24.95], [64708.7, 0.023], [64710.7, 1.746], [64729.5, 0.076], [64753.2, 1.677], [64754.9, 0.113], [64767.2, 0.169], [64784.0, 2.191], [64830.1, 1.027], [65339.6, 5.533], [65462.5, 9.159], [65630.7, 22.786]]}
{"kind": "depth", "E": 1787080502737, "U": 11315358544364, "u": 11315358550866, "recv_ms": 1787080502692, "bids": [[1000.0, 35.81], [14192.6, 0.042], [14492.6, 0.7], [14592.6, 3.458], [58223.3, 0.055], [62104.8, 0.001], [63207.2, 0.01], [63482.8, 2.399], [63692.6, 0.022], [63786.9, 32.423], [63916.3, 42.201], [64045.7, 4.971], [64149.1, 0.246], [64369.1, 6.806], [64570.2, 0.281], [64624.4, 0.168], [64635.6, 1.635], [64657.0, 0.073], [64684.8, 0.131], [64688.4, 1.969]], "asks": [[64703.8, 0.591], [64704.0, 3.957], [64729.5, 0.076], [64767.2, 0.169], [64830.1, 1.027], [64889.4, 2.019], [65339.6, 5.533], [65580.1, 0.0], [65642.2, 0.0], [65692.7, 0.026]]}
{"kind": "depth", "E": 1787080502839, "U": 11315358551088, "u": 11315358557910, "recv_ms": 1787080502794, "bids": [[14192.6, 0.0], [14492.6, 1.022], [14592.6, 3.178], [58223.3, 0.055], [61457.9, 0.061], [61756.0, 0.043], [62104.8, 0.004], [63819.2, 13.553], [63841.6, 0.784], [64045.7, 4.971], [64237.8, 0.127], [64369.1, 6.806], [64570.2, 0.001], [64624.4, 0.0], [64635.6, 1.649], [64651.1, 0.371], [64655.2, 0.0], [64655.8, 0.029], [64656.0, 0.833], [64657.0, 0.0], [64665.9, 0.614], [64666.8, 0.016], [64667.4, 0.117], [64668.1, 0.001], [64670.8, 0.002], [64671.4, 0.47], [64671.7, 1.096], [64672.5, 0.001], [64678.4, 0.137], [64679.1, 0.076], [64679.4, 0.925], [64680.1, 0.012], [64680.2, 0.0], [64680.3, 0.156], [64685.7, 0.003], [64689.1, 0.138], [64692.6, 4.885]], "asks": [[64703.3, 0.139], [64704.0, 3.032], [64704.1, 0.019], [64704.9, 0.979], [64706.1, 0.003], [64706.9, 0.001], [64707.0, 0.495], [64707.7, 0.556], [64707.8, 0.042], [64707.9, 0.002], [64708.0, 0.148], [64708.1, 0.001], [64708.6, 3.3], [64708.7, 0.023], [64708.8, 0.005], [64710.2, 0.026], [64710.3, 0.136], [64711.0, 0.315], [64711.8, 0.126], [64711.9, 0.618], [64721.5, 1.622], [64721.6, 1.361], [64721.7, 0.005], [64722.5, 1.155], [64722.7, 2.824], [64724.5, 0.003], [64724.6, 0.002], [64724.7, 0.003], [64725.3, 0.002], [64725.4, 0.008], [64725.5, 0.002], [64727.6, 0.002], [64727.7, 0.028], [64727.8, 0.003], [64729.5, 0.003], [64757.4, 0.393], [64767.2, 0.0], [64830.1, 0.745], [64889.4, 4.696], [65016.2, 5.102], [65339.6, 5.533]]}
{"kind": "depth", "E": 1787080502941, "U": 11315358558082, "u": 11315358564845, "recv_ms": 1787080502895, "bids": [[14492.6, 1.372], [14592.6, 2.828], [58223.3, 0.055], [61457.9, 0.061], [61607.2, 0.0], [62104.8, 0.001], [63692.6, 0.002], [63778.1, 1.025], [63855.7, 10.866], [63916.3, 42.67], [64045.7, 4.971], [64549.3, 0.027], [64570.2, 0.001], [64624.4, 0.0], [64652.0, 2.075], [64657.0, 0.0], [64671.2, 0.926], [64671.7, 0.17], [64678.2, 1.338], [64679.3, 0.004], [64680.1, 0.166], [64680.3, 0.002], [64682.6, 0.035], [64684.7, 0.617], [64685.1, 0.002], [64689.1, 0.054], [64692.6, 3.66]], "asks": [[64692.7, 25.041], [64696.1, 0.1], [64703.7, 0.926], [64704.9, 0.054], [64707.5, 0.059], [64708.6, 3.243], [64709.7, 10.006], [64712.2, 2.33], [64714.3, 10.037], [64714.8, 3.517], [64729.5, 0.003], [64767.2, 0.0], [64830.1, 0.745], [64833.6, 3.82], [65339.6, 5.533], [65501.4, 17.508], [65630.7, 23.851], [65643.7, 7.3], [65692.7, 0.006]]}
{"kind": "depth", "E": 1787080503043, "U": 11315358564912, "u": 11315358581220, "recv_ms": 1787080502999, "bids": [[1000.0, 35.81], [14492.6, 1.736], [14592.6, 2.464], [58223.3, 0.055], [63692.6, 0.022], [64045.7, 4.977], [64549.4, 4.982], [64652.0, 1.739], [64655.7, 0.227], [64656.0, 0.776], [64656.8, 0.025], [64668.9, 3.639], [64671.0, 0.005], [64671.1, 0.0], [64679.1, 0.617], [64679.4, 0.384], [64680.3, 0.042], [64680.4, 0.015], [64680.7, 0.166], [64681.0, 0.006], [64681.5, 0.075], [64681.8, 0.277], [64682.0, 0.614], [64682.4, 0.0], [64683.5, 0.003], [64683.8, 0.085], [64684.2, 0.086], [64684.5, 0.095], [64684.6, 0.106], [64684.7, 0.616], [64684.8, 0.131], [64684.9, 0.084], [64685.6, 0.085], [64685.7, 0.065], [64686.5, 0.002], [64686.7, 0.034], [64687.1, 0.0], [64687.2, 0.0], [64687.5, 0.001], [64688.0, 0.007], [64688.4, 0.072], [64688.5, 0.0], [64689.0, 0.022], [64689.8, 0.101], [64689.9, 0.002], [64692.6, 1.661]], "asks": [[64692.7, 28.22], [64693.3, 0.007], [64705.6, 12.965], [64708.3, 2.401], [64709.7, 10.01], [64710.3, 0.134], [64710.9, 0.002], [64712.9, 0.073], [64713.0, 5.0], [64714.2, 0.632], [64714.3, 0.037], [64720.5, 0.036], [64760.0, 1.35], [64833.6, 9.218], [64889.4, 2.24], [65015.8, 0.109], [65339.6, 5.537], [65436.6, 0.016], [65477.4, 0.764], [65581.6, 8.328], [65692.7, 0.026]]}
{"kind": "depth", "E": 1787080503145, "U": 11315358581282, "u": 11315358608770, "recv_ms": 1787080503098, "bids": [[14492.6, 2.086], [14592.6, 2.114], [58223.3, 0.055], [61457.9, 0.061], [62104.8, 0.004], [63740.1, 1.801], [63916.3, 42.889], [64045.7, 4.971], [64233.9, 0.388], [64369.1, 6.806], [64498.5, 0.008], [64569.8, 0.0], [64596.5, 0.036], [64596.8, 3.347], [64614.9, 0.138], [64617.2, 1.587], [64618.4, 0.0], [64619.6, 0.002], [64624.1, 0.0], [64635.1, 0.521], [64641.7, 0.224], [64646.2, 2.328], [64646.7, 0.425], [64647.3, 0.21], [64651.6, 0.437], [64654.4, 1.222], [64655.1, 0.405], [64655.7, 0.17], [64655.9, 0.121], [64656.7, 0.029], [64662.5, 0.001], [64664.6, 0.083], [64670.4, 2.404], [64670.5, 0.252], [64671.1, 0.926], [64671.2, 0.0], [64672.0, 3.322], [64675.1, 0.603], [64675.6, 0.04], [64676.5, 1.007], [64676.9, 0.003], [64677.7, 0.005], [64678.2, 0.338], [64678.3, 2.327], [64678.4, 0.137], [64679.0, 1.122], [64679.1, 0.076], [64679.9, 0.0], [64680.2, 0.309], [64680.3, 0.143], [64680.4, 0.478], [64680.6, 0.001], [64680.7, 0.166], [64680.9, 0.0], [64681.0, 0.001], [64681.3, 0.236], [64681.8, 0.2], [64681.9, 0.116], [64682.0, 0.073], [64682.1, 0.104], [64682.2, 0.074], [64682.4, 0.0], [64682.6, 0.034], [64682.7, 0.164], [64682.8, 0.001], [64682.9, 0.001], [64683.0, 0.033], [64683.1, 0.629], [64683.2, 0.003], [64683.4, 0.085], [64683.7, 0.002], [64683.9, 0.036], [64684.1, 0.0], [64684.2, 0.086], [64684.6, 0.105], [64684.7, 0.583], [64685.1, 0.002], [64685.3, 1.813], [64685.6, 1.898], [64685.7, 0.544], [64685.8, 0.188], [64686.0, 0.089], [64686.3, 0.001], [64686.4, 0.086], [64686.7, 0.032], [64686.8, 0.0], [64687.0, 1.818], [64687.1, 0.093], [64687.3, 0.218], [64687.6, 0.238], [64688.2, 0.023], [64688.3, 0.02], [64688.4, 1.885], [64688.5, 0.009], [64688.6, 0.002], [64689.0, 0.0], [64689.2, 0.02], [64689.6, 0.007], [64689.9, 0.001], [64690.2, 0.002], [64692.6, 1.641]], "asks": [[64692.7, 27.967], [64692.8, 0.149], [64693.5, 0.044], [64694.4, 0.012], [64696.0, 1.281], [64697.0, 0.075], [64699.3, 0.854], [64700.3, 0.46], [64702.0, 0.004], [64703.0, 0.016], [64703.3, 0.139], [64703.4, 0.311], [64703.7, 0.926], [64704.0, 4.309], [64704.2, 0.042], [64705.8, 0.561], [64706.2, 0.023], [64706.5, 0.003], [64706.9, 0.058], [64707.5, 0.002], [64707.7, 0.0], [64708.2, 0.572], [64708.3, 1.043], [64708.6, 2.702], [64709.7, 0.01], [64710.7, 1.751], [64711.0, 0.31], [64711.6, 0.043], [64711.9, 0.0], [64712.0, 2.898], [64712.2, 2.333], [64712.9, 0.003], [64719.5, 1.242], [64720.9, 0.078], [64729.1, 0.013], [64759.2, 1.263], [64760.3, 0.024], [64761.6, 0.036], [64766.9, 0.002], [64829.7, 0.0], [65275.0, 12.794], [65339.6, 5.533], [65986.5, 0.073], [67280.4, 2.544]]}
{"kind": "depth", "E": 1787080503247, "U": 11315358608974, "u": 11315358658228, "recv_ms": 1787080503377, "bids": [[14485.4, 0.112], [14488.8, 0.056], [14488.9, 0.042], [14489.1, 0.028], [14489.6, 0.014], [14492.6, 2.198], [14592.6, 1.75], [58216.8, 0.002], [58219.9, 0.0], [58223.3, 0.053], [61457.9, 0.061], [61718.2, 0.001], [61735.1, 0.0], [61897.5, 0.0], [62104.8, 0.001], [63770.6, 0.234], [63851.6, 12.903], [64038.3, 0.001], [64038.5, 0.008], [64041.9, 0.0], [64042.0, 0.002], [64045.7, 4.971], [64232.8, 0.004], [64239.7, 0.0], [64272.0, 5.002], [64343.7, 0.115], [64352.7, 0.0], [64439.0, 0.415], [64490.3, 5.609], [64491.5, 0.002], [64493.2, 0.004], [64498.4, 0.414], [64502.5, 0.003], [64505.7, 0.001], [64522.7, 0.228], [64549.2, 0.001], [64553.2, 0.001], [64560.0, 0.554], [64560.8, 0.236], [64562.1, 0.978], [64564.9, 0.001], [64567.5, 0.001], [64567.8, 0.0], [64569.8, 0.0], [64578.8, 0.159], [64580.4, 0.0], [64581.1, 33.672], [64583.3, 0.088], [64584.5, 0.031], [64588.2, 0.014], [64588.5, 0.005], [64589.0, 2.364], [64589.1, 0.831], [64589.9, 0.001], [64591.0, 0.004], [64592.1, 0.041], [64595.3, 0.003], [64596.5, 0.001], [64598.2, 0.026], [64599.8, 6.671], [64601.1, 1.714], [64603.4, 0.093], [64604.7, 0.031], [64605.3, 0.015], [64605.5, 0.022], [64606.4, 1.235], [64607.5, 0.0], [64609.0, 6.466], [64609.2, 0.0], [64609.7, 0.118], [64610.2, 0.144], [64611.0, 7.334], [64611.1, 3.315], [64611.9, 0.314], [64612.2, 0.282], [64614.0, 0.763], [64614.2, 0.63], [64616.0, 3.437], [64616.1, 1.455], [64616.4, 0.001], [64616.5, 0.328], [64617.2, 1.561], [64617.7, 2.335], [64617.8, 0.005], [64617.9, 0.048], [64618.5, 0.007], [64618.8, 0.0], [64619.1, 0.311], [64619.4, 0.015], [64620.4, 1.579], [64620.5, 0.531], [64620.9, 0.371], [64621.4, 0.002], [64621.5, 0.167], [64622.5, 0.002], [64622.7, 0.001], [64622.8, 0.372], [64623.0, 0.052], [64623.1, 0.314], [64623.2, 0.0], [64624.0, 0.201], [64624.1, 0.0], [64624.4, 0.0], [64624.7, 2.89], [64625.3, 0.006], [64625.7, 0.029], [64626.1, 0.047], [64627.9, 0.004], [64628.0, 0.03], [64628.2, 0.461], [64628.5, 0.024], [64629.2, 0.005], [64629.5, 0.063], [64629.6, 0.0], [64630.5, 0.004], [64630.7, 0.15], [64631.0, 1.528], [64631.1, 0.31], [64632.0, 1.563], [64632.1, 0.004], [64632.5, 0.017], [64632.7, 0.028], [64632.9, 0.001], [64633.3, 0.008], [64633.6, 0.031], [64633.7, 0.03], [64634.1, 0.001], [64634.2, 0.032], [64635.0, 0.038], [64635.1, 0.311], [64635.7, 0.159], [64635.8, 0.001], [64636.1, 0.024], [64636.6, 0.001], [64636.7, 0.467], [64637.0, 0.07], [64637.6, 0.336], [64638.0, 0.014], [64639.4, 0.0], [64639.8, 0.026], [64640.0, 0.383], [64640.1, 0.013], [64640.2, 0.115], [64640.7, 0.162], [64641.0, 0.111], [64641.4, 0.002], [64641.5, 0.34], [64642.0, 0.152], [64642.5, 0.038], [64642.7, 0.005], [64643.4, 0.25], [64643.5, 0.066], [64643.6, 0.441], [64643.7, 2.13], [64643.9, 0.067], [64644.3, 0.002], [64644.5, 0.002], [64645.0, 0.012], [64645.1, 0.027], [64645.3, 0.004], [64645.7, 0.161], [64646.2, 2.418], [64646.7, 1.468], [64646.9, 0.31], [64647.0, 0.001], [64647.1, 0.311], [64647.3, 0.007], [64647.5, 0.001], [64647.8, 0.0], [64648.4, 0.519], [64648.8, 0.212], [64649.2, 0.006], [64649.9, 3.031], [64650.0, 3.084], [64650.1, 0.028], [64650.5, 0.034], [64650.8, 3.556], [64650.9, 0.007], [64651.2, 1.175], [64651.3, 0.107], [64651.4, 0.012], [64651.6, 0.141], [64651.7, 0.003], [64652.0, 3.869], [64652.2, 0.001], [64652.3, 0.125], [64653.4, 1.415], [64653.7, 0.054], [64653.8, 1.624], [64653.9, 2.319], [64654.0, 0.042], [64654.4, 1.165], [64654.6, 0.07], [64654.7, 0.31], [64654.9, 0.0], [64655.0, 0.027], [64655.2, 0.006], [64655.3, 0.019], [64655.4, 0.159], [64655.5, 0.051], [64655.6, 0.076], [64655.9, 0.121], [64656.0, 0.795], [64656.2, 0.001], [64656.6, 0.016], [64656.7, 0.029], [64656.8, 0.0], [64657.0, 0.001], [64657.1, 0.449], [64657.2, 0.001], [64657.4, 0.0], [64657.5, 0.055], [64657.6, 1.389], [64658.1, 0.005], [64658.4, 0.009], [64658.5, 0.216], [64658.6, 0.457], [64658.7, 0.609], [64658.8, 1.477], [64658.9, 0.335], [64659.0, 0.004], [64659.1, 0.312], [64659.2, 1.021], [64659.4, 0.984], [64659.6, 0.495], [64659.7, 0.485], [64659.8, 0.002], [64659.9, 0.003], [64660.0, 0.183], [64660.1, 0.131], [64660.3, 4.882], [64660.4, 0.002], [64660.5, 0.116], [64660.8, 1.159], [64660.9, 2.337], [64661.2, 0.0], [64661.3, 0.149], [64661.4, 0.184], [64661.6, 0.001], [64661.9, 0.936], [64662.1, 0.008], [64662.4, 0.016], [64662.6, 0.184], [64662.7, 0.071], [64662.8, 0.188], [64662.9, 0.741], [64663.0, 0.111], [64663.2, 0.104], [64663.5, 0.003], [64663.6, 0.071], [64663.7, 0.001], [64663.8, 0.003], [64664.1, 0.011], [64664.4, 0.025], [64664.5, 0.946], [64664.6, 0.081], [64664.7, 0.002], [64665.0, 0.149], [64665.1, 0.512], [64665.2, 0.002], [64665.3, 0.042], [64665.5, 0.001], [64665.6, 0.075], [64665.8, 0.0], [64665.9, 0.138], [64666.1, 0.003], [64666.2, 2.558], [64666.4, 0.503], [64666.5, 0.395], [64666.6, 0.049], [64666.7, 0.667], [64666.8, 0.017], [64666.9, 0.31], [64667.2, 1.241], [64667.3, 0.006], [64667.4, 0.001], [64667.6, 0.117], [64667.8, 0.051], [64667.9, 0.001], [64668.0, 0.121], [64668.1, 0.008], [64668.2, 1.654], [64668.3, 0.002], [64668.5, 0.003], [64668.6, 1.001], [64668.7, 0.32], [64668.8, 0.356], [64668.9, 3.906], [64669.0, 0.004], [64669.3, 0.002], [64669.7, 0.054], [64669.9, 0.255], [64670.0, 1.86], [64670.1, 0.467], [64670.3, 0.002], [64670.4, 1.166], [64670.5, 0.322], [64670.6, 0.463], [64670.7, 0.173], [64670.8, 0.162], [64670.9, 0.021], [64671.0, 0.001], [64671.1, 0.0], [64671.4, 0.004], [64671.5, 0.006], [64671.6, 0.312], [64671.8, 0.001], [64671.9, 0.325], [64672.0, 1.521], [64672.1, 2.319], [64672.2, 0.009], [64672.3, 0.171], [64672.4, 0.0], [64672.5, 1.892], [64672.7, 0.01], [64672.8, 0.001], [64672.9, 2.055], [64673.0, 0.003], [64673.1, 0.003], [64673.2, 0.0], [64673.3, 0.003], [64673.4, 0.313], [64673.5, 0.005], [64673.6, 0.048], [64673.7, 0.005], [64673.8, 0.004], [64673.9, 0.041], [64674.0, 0.057], [64674.1, 0.056], [64674.3, 0.001], [64674.4, 0.0], [64674.5, 0.001], [64674.7, 0.312], [64674.8, 0.022], [64674.9, 0.807], [64675.0, 1.796], [64675.1, 0.003], [64675.2, 0.032], [64675.3, 0.086], [64675.4, 0.16], [64675.5, 0.464], [64675.6, 1.813], [64675.7, 0.248], [64675.8, 0.003], [64675.9, 0.226], [64676.1, 0.086], [64676.2, 0.001], [64676.4, 0.117], [64676.5, 0.001], [64676.6, 0.002], [64676.7, 0.002], [64676.8, 1.9], [64676.9, 0.002], [64677.0, 0.001], [64677.1, 0.001], [64677.2, 0.085], [64677.3, 0.026], [64677.4, 0.001], [64677.5, 0.084], [64677.6, 0.005], [64677.8, 0.001], [64677.9, 0.108], [64678.0, 0.003], [64678.1, 0.023], [64678.2, 1.922], [64678.3, 0.09], [64678.4, 0.011], [64678.6, 0.047], [64678.7, 0.001], [64678.8, 0.001], [64679.0, 0.004], [64679.1, 0.017], [64679.3, 0.05], [64679.4, 0.002], [64679.5, 0.002], [64679.6, 0.006], [64679.7, 0.005], [64679.9, 0.0], [64680.0, 1.511], [64680.1, 0.008], [64680.2, 0.001], [64680.3, 0.001], [64680.4, 0.017], [64680.5, 0.002], [64680.7, 0.0], [64680.8, 0.001], [64681.0, 0.002], [64681.2, 0.002], [64681.3, 0.001], [64681.4, 0.141], [64681.5, 0.072], [64681.6, 0.148], [64681.7, 0.171], [64681.9, 0.101], [64682.0, 0.072], [64682.1, 0.103], [64682.2, 0.073], [64682.3, 0.083], [64682.4, 0.085], [64682.7, 0.101], [64683.0, 0.033], [64683.1, 0.001], [64683.2, 0.003], [64683.4, 0.0], [64683.5, 0.001], [64683.8, 0.0], [64683.9, 0.035], [64684.0, 0.002], [64684.2, 0.0], [64684.3, 0.001], [64684.5, 0.001], [64684.6, 0.1], [64684.7, 0.0], [64684.8, 0.108], [64684.9, 0.0], [64685.0, 0.005], [64685.1, 0.001], [64685.2, 2.27], [64685.3, 0.0], [64685.4, 0.0], [64685.6, 0.0], [64685.7, 0.0], [64685.8, 0.0], [64685.9, 0.0], [64686.0, 0.0], [64686.1, 0.0], [64686.2, 0.0], [64686.3, 0.0], [64686.4, 0.0], [64686.5, 0.0], [64686.7, 0.0], [64686.9, 0.0], [64687.0, 0.0], [64687.1, 0.0], [64687.3, 0.0], [64687.5, 0.0], [64687.6, 0.0], [64687.7, 0.0], [64687.8, 0.0], [64687.9, 0.0], [64688.0, 0.0], [64688.1, 0.0], [64688.2, 0.0], [64688.3, 0.0], [64688.4, 0.0], [64688.5, 0.0], [64688.6, 0.0], [64688.7, 0.0], [64688.8, 0.0], [64688.9, 0.0], [64689.1, 0.0], [64689.2, 0.0], [64689.3, 0.0], [64689.4, 0.0], [64689.5, 0.0], [64689.6, 0.0], [64689.7, 0.0], [64689.8, 0.0], [64689.9, 0.0], [64690.0, 0.0], [64690.1, 0.0], [64690.2, 0.0], [64690.3, 0.0], [64690.4, 0.0], [64690.5, 0.0], [64690.6, 0.0], [64690.7, 0.0], [64690.8, 0.0], [64691.1, 0.0], [64691.2, 0.0], [64691.4, 0.0], [64691.6, 0.0], [64691.9, 0.0], [64692.0, 0.0], [64692.5, 0.0], [64692.6, 0.0]], "asks": [[64685.3, 33.916], [64685.4, 15.73], [64685.5, 26.573], [64685.6, 3.749], [64685.7, 2.828], [64685.8, 0.014], [64685.9, 0.08], [64686.0, 0.0], [64686.1, 2.605], [64686.2, 0.001], [64686.3, 0.0], [64686.4, 0.001], [64686.5, 0.0], [64686.6, 0.381], [64686.7, 0.002], [64686.8, 0.039], [64687.0, 0.001], [64687.1, 0.01], [64687.2, 0.101], [64687.3, 0.0], [64687.4, 0.004], [64687.5, 0.086], [64687.6, 0.001], [64687.7, 0.0], [64687.8, 0.0], [64687.9, 0.001], [64688.0, 0.002], [64688.1, 0.077], [64688.2, 2.423], [64688.3, 0.0], [64688.4, 2.262], [64688.5, 2.868], [64688.6, 2.176], [64688.7, 0.001], [64688.8, 0.278], [64688.9, 7.14], [64689.0, 0.154], [64689.1, 0.002], [64689.2, 2.385], [64689.3, 0.002], [64689.4, 2.168], [64689.5, 2.176], [64689.6, 2.251], [64689.7, 3.839], [64689.8, 0.003], [64689.9, 0.0], [64690.0, 0.004], [64690.1, 0.002], [64690.2, 0.001], [64690.3, 0.002], [64690.4, 2.248], [64690.5, 2.172], [64690.6, 0.001], [64690.7, 2.169], [64690.8, 3.17], [64690.9, 2.172], [64691.0, 0.0], [64691.1, 0.007], [64691.2, 2.17], [64691.3, 0.276], [64691.4, 0.092], [64691.5, 2.774], [64691.6, 0.0], [64691.7, 0.001], [64691.8, 0.001], [64691.9, 1.238], [64692.0, 10.632], [64692.1, 2.168], [64692.2, 0.001], [64692.3, 0.0], [64692.4, 0.001], [64692.5, 0.628], [64692.6, 4.153], [64692.7, 6.719], [64692.8, 1.157], [64692.9, 1.003], [64693.0, 0.002], [64693.2, 0.003], [64693.3, 0.025], [64693.4, 0.002], [64693.5, 0.003], [64693.6, 0.263], [64693.7, 0.002], [64693.8, 0.336], [64693.9, 0.003], [64694.0, 0.026], [64694.1, 0.001], [64694.3, 0.002], [64694.4, 0.012], [64694.5, 0.086], [64694.7, 0.001], [64694.9, 0.008], [64695.0, 1.446], [64695.1, 0.001], [64695.2, 1.105], [64695.3, 0.292], [64695.4, 0.002], [64695.5, 0.001], [64695.6, 0.003], [64695.7, 0.004], [64695.8, 0.002], [64695.9, 0.003], [64696.1, 0.011], [64696.2, 0.002], [64696.3, 0.002], [64696.4, 0.002], [64696.5, 0.003], [64696.6, 0.043], [64696.7, 2.319], [64696.8, 0.285], [64696.9, 0.044], [64697.0, 0.095], [64697.3, 0.005], [64697.4, 0.0], [64697.5, 0.061], [64697.6, 0.01], [64697.7, 1.143], [64697.8, 0.137], [64697.9, 0.003], [64698.0, 0.185], [64698.1, 0.043], [64698.2, 0.448], [64698.3, 0.275], [64698.4, 1.972], [64698.5, 1.76], [64698.6, 0.843], [64698.7, 0.134], [64698.8, 0.647], [64699.0, 0.133], [64699.1, 0.173], [64699.3, 0.864], [64699.4, 0.078], [64699.6, 0.005], [64699.7, 0.001], [64699.8, 2.323], [64700.0, 1.756], [64700.1, 0.003], [64700.3, 0.281], [64700.4, 0.001], [64700.5, 0.081], [64700.6, 1.283], [64700.7, 0.005], [64700.8, 0.395], [64700.9, 0.405], [64701.0, 2.481], [64701.1, 0.647], [64701.3, 0.168], [64701.4, 0.006], [64701.5, 0.566], [64701.6, 0.021], [64701.7, 10.003], [64701.9, 0.038], [64702.0, 0.003], [64702.2, 0.466], [64702.3, 0.032], [64702.4, 0.319], [64702.5, 0.501], [64702.6, 0.0], [64702.7, 0.001], [64702.8, 0.183], [64702.9, 0.316], [64703.1, 0.007], [64703.2, 0.396], [64703.4, 0.557], [64703.5, 0.009], [64703.6, 0.543], [64703.7, 0.001], [64703.9, 0.131], [64704.0, 2.936], [64704.1, 0.005], [64704.2, 0.156], [64704.4, 0.519], [64704.6, 0.241], [64704.7, 0.125], [64704.8, 0.209], [64704.9, 0.124], [64705.0, 0.918], [64705.1, 1.161], [64705.2, 0.012], [64705.3, 1.947], [64705.4, 0.005], [64705.5, 1.239], [64705.6, 2.967], [64705.7, 0.294], [64705.8, 0.004], [64706.0, 0.022], [64706.3, 0.163], [64706.5, 0.051], [64706.6, 0.238], [64706.7, 0.0], [64706.8, 0.001], [64706.9, 0.001], [64707.1, 0.464], [64707.2, 0.009], [64707.3, 0.389], [64707.4, 0.015], [64707.6, 0.662], [64708.0, 0.141], [64708.2, 0.03], [64708.3, 1.094], [64708.7, 0.203], [64708.8, 0.715], [64708.9, 0.213], [64709.1, 0.001], [64709.2, 0.062], [64709.3, 0.115], [64709.4, 0.352], [64709.5, 0.464], [64709.6, 0.001], [64709.7, 0.022], [64709.9, 0.335], [64710.0, 0.129], [64710.4, 0.642], [64710.5, 0.022], [64710.7, 1.766], [64711.0, 0.314], [64711.1, 0.002], [64711.2, 0.091], [64711.6, 0.042], [64711.8, 0.001], [64712.0, 1.248], [64712.1, 1.318], [64712.5, 0.01], [64712.6, 0.002], [64712.7, 0.006], [64712.8, 0.001], [64712.9, 0.012], [64713.0, 5.0], [64713.1, 0.001], [64713.2, 0.231], [64713.4, 0.089], [64713.6, 0.039], [64713.7, 0.025], [64713.8, 0.014], [64714.0, 0.016], [64714.1, 0.109], [64714.3, 0.035], [64714.5, 0.541], [64714.8, 3.519], [64715.1, 0.017], [64715.2, 1.245], [64715.3, 0.479], [64715.5, 0.012], [64715.6, 0.561], [64715.7, 0.025], [64715.9, 0.002], [64716.0, 0.023], [64716.2, 0.151], [64716.4, 6.171], [64716.5, 0.234], [64716.8, 0.006], [64716.9, 1.071], [64717.1, 0.105], [64717.2, 0.001], [64717.3, 1.272], [64717.4, 0.192], [64717.6, 0.251], [64717.8, 0.072], [64717.9, 0.268], [64718.0, 0.171], [64718.2, 0.174], [64718.5, 0.341], [64718.6, 0.003], [64718.8, 0.029], [64719.0, 0.007], [64719.5, 1.242], [64720.0, 0.154], [64720.1, 2.321], [64720.3, 0.1], [64720.9, 0.002], [64721.0, 2.962], [64721.2, 0.001], [64721.3, 0.16], [64721.5, 1.622], [64721.7, 0.004], [64721.8, 0.344], [64722.1, 0.009], [64722.5, 0.155], [64722.6, 0.125], [64722.9, 0.004], [64723.5, 0.002], [64723.7, 0.0], [64724.4, 0.004], [64725.4, 0.008], [64725.8, 0.002], [64725.9, 0.0], [64726.0, 2.322], [64726.4, 0.005], [64726.6, 0.001], [64727.2, 0.078], [64727.5, 0.001], [64727.7, 0.184], [64727.9, 0.944], [64728.4, 0.001], [64728.9, 0.128], [64729.0, 0.004], [64729.1, 0.018], [64729.8, 0.002], [64730.1, 0.017], [64730.5, 0.213], [64731.0, 0.074], [64731.3, 0.168], [64732.0, 3.526], [64732.2, 0.018], [64732.4, 0.043], [64733.0, 0.042], [64733.2, 0.002], [64733.3, 0.794], [64733.6, 0.009], [64734.8, 0.0], [64736.4, 0.009], [64736.6, 0.013], [64736.8, 0.003], [64737.3, 0.004], [64737.7, 0.01], [64737.9, 0.185], [64738.0, 0.002], [64738.5, 0.002], [64739.0, 0.852], [64739.6, 0.0], [64739.7, 0.442], [64740.3, 0.022], [64740.4, 0.005], [64740.6, 2.34], [64742.1, 0.491], [64744.1, 0.001], [64744.4, 0.069], [64747.1, 0.004], [64747.6, 0.222], [64749.2, 0.028], [64751.1, 0.0], [64751.4, 0.066], [64752.0, 0.005], [64753.1, 0.028], [64753.8, 0.01], [64754.0, 0.002], [64754.1, 0.042], [64757.1, 0.0], [64757.4, 0.392], [64757.7, 0.001], [64758.0, 0.002], [64758.3, 0.0], [64759.2, 1.237], [64759.5, 0.038], [64760.1, 0.001], [64760.8, 0.0], [64761.3, 0.005], [64762.8, 0.001], [64764.1, 0.001], [64764.8, 0.251], [64765.4, 0.027], [64765.9, 0.074], [64766.6, 0.002], [64766.9, 0.002], [64767.3, 0.022], [64767.9, 0.009], [64768.0, 0.011], [64770.0, 0.122], [64770.1, 0.001], [64771.1, 0.082], [64771.3, 0.0], [64772.0, 0.183], [64776.1, 2.322], [64776.7, 0.021], [64778.9, 0.002], [64779.3, 2.803], [64780.0, 0.072], [64780.9, 1.083], [64781.1, 39.035], [64784.2, 0.189], [64785.6, 1.255], [64785.8, 0.2], [64786.3, 0.027], [64786.7, 0.0], [64786.9, 0.008], [64789.3, 0.006], [64790.9, 0.0], [64792.5, 0.023], [64792.6, 0.0], [64793.5, 2.127], [64794.4, 0.005], [64794.7, 0.013], [64798.4, 1.15], [64799.6, 0.0], [64799.7, 0.005], [64801.8, 2.26], [64803.6, 0.084], [64804.9, 0.004], [64805.2, 0.0], [64805.3, 0.0], [64806.3, 4.639], [64806.8, 0.0], [64810.1, 0.0], [64810.2, 2.124], [64814.2, 0.448], [64814.3, 0.163], [64815.1, 0.389], [64819.9, 0.024], [64821.1, 0.001], [64825.2, 0.0], [64825.9, 0.001], [64826.5, 0.003], [64827.4, 0.0], [64828.2, 0.458], [64829.7, 0.0], [64833.5, 0.103], [64856.9, 0.003], [64867.4, 0.015], [64869.4, 0.0], [64874.3, 0.003], [64880.9, 0.88], [64882.6, 0.0], [64883.4, 3.479], [64883.6, 14.103], [64884.6, 0.199], [64889.4, 5.73], [65045.1, 0.316], [65332.2, 0.01], [65332.4, 1.213], [65335.8, 0.0], [65339.6, 5.533], [65688.1, 0.002], [65688.9, 0.005], [65689.0, 10.021], [65689.2, 0.002], [65689.7, 0.002], [65692.7, 0.022], [66092.6, 1.296]]}
{"kind": "depth", "E": 1787080503349, "U": 11315358658255, "u": 11315358709531, "recv_ms": 1787080503774, "bids": [[1000.0, 35.81], [14481.4, 0.014], [14482.1, 0.028], [14482.4, 0.042], [14482.7, 0.014], [14483.2, 0.014], [14483.9, 0.014], [14484.8, 0.042], [14485.2, 0.182], [14592.6, 1.4], [51748.2, 0.0], [58214.1, 0.002], [58216.3, 0.0], [58216.6, 6.787], [58216.8, 0.0], [61450.9, 0.0], [62095.8, 0.003], [63391.5, 0.006], [63597.0, 4.706], [63692.6, 0.002], [63734.8, 1.397], [63855.7, 9.772], [63920.4, 27.111], [64034.6, 0.005], [64034.8, 0.002], [64035.3, 0.0], [64035.6, 1.2], [64036.8, 0.011], [64037.1, 0.002], [64038.0, 100.0], [64038.3, 0.001], [64038.5, 0.0], [64165.2, 0.312], [64171.8, 0.002], [64294.6, 0.001], [64301.2, 0.0], [64338.3, 0.072], [64341.5, 0.015], [64341.6, 0.0], [64343.7, 0.0], [64345.1, 0.001], [64348.4, 0.002], [64351.6, 0.002], [64354.4, 0.002], [64369.6, 0.001], [64371.0, 2.629], [64417.6, 4.732], [64424.0, 5.132], [64437.2, 0.022], [64465.3, 0.0], [64475.0, 0.356], [64487.3, 0.016], [64487.4, 1.268], [64489.6, 3.205], [64490.3, 0.001], [64491.4, 0.221], [64495.8, 1.393], [64499.6, 0.007], [64502.5, 0.002], [64513.0, 0.228], [64518.0, 0.318], [64529.1, 0.0], [64531.3, 0.017], [64542.1, 0.216], [64546.8, 0.002], [64548.3, 4.799], [64552.7, 0.02], [64553.0, 0.019], [64556.1, 0.834], [64556.5, 5.183], [64557.9, 0.085], [64558.7, 0.436], [64559.0, 0.127], [64559.3, 0.002], [64559.4, 0.154], [64559.8, 0.0], [64560.0, 0.44], [64560.8, 0.151], [64562.0, 0.013], [64562.3, 0.28], [64562.4, 0.138], [64564.4, 4.248], [64566.3, 0.015], [64566.6, 0.115], [64570.5, 0.003], [64573.9, 0.009], [64574.1, 0.002], [64574.4, 1.398], [64574.7, 0.001], [64576.4, 0.002], [64577.1, 0.008], [64578.0, 0.0], [64578.3, 4.064], [64578.9, 0.002], [64579.3, 0.018], [64581.1, 33.672], [64584.5, 0.045], [64585.3, 0.926], [64587.2, 1.446], [64588.0, 0.231], [64588.2, 0.009], [64592.2, 0.163], [64592.4, 0.03], [64596.6, 0.002], [64597.4, 0.379], [64597.9, 3.22], [64598.4, 0.001], [64598.8, 0.0], [64599.9, 0.002], [64600.8, 4.481], [64601.1, 1.736], [64601.3, 3.143], [64601.7, 0.025], [64602.1, 0.03], [64603.2, 3.265], [64603.6, 4.106], [64604.0, 0.379], [64604.9, 0.031], [64605.5, 0.0], [64606.6, 0.024], [64606.9, 0.317], [64607.6, 0.046], [64607.8, 0.002], [64608.0, 0.171], [64608.3, 0.074], [64609.5, 0.049], [64609.7, 0.118], [64609.9, 0.0], [64610.0, 1.073], [64611.0, 7.334], [64611.1, 3.289], [64612.1, 0.001], [64612.3, 0.211], [64612.6, 0.037], [64613.3, 0.098], [64613.7, 0.001], [64614.0, 1.263], [64614.1, 0.029], [64614.8, 0.0], [64615.5, 0.1], [64616.0, 3.463], [64616.5, 0.514], [64616.7, 0.166], [64617.7, 2.336], [64617.9, 0.0], [64618.3, 0.646], [64618.6, 1.338], [64619.1, 0.311], [64619.3, 0.003], [64619.4, 0.024], [64620.1, 0.013], [64620.4, 1.577], [64620.5, 0.536], [64620.6, 6.039], [64620.7, 0.222], [64620.9, 0.0], [64621.1, 0.232], [64621.5, 0.133], [64621.8, 0.0], [64622.6, 0.0], [64622.9, 0.003], [64623.3, 2.351], [64623.8, 0.02], [64624.3, 0.025], [64626.6, 0.006], [64627.2, 0.037], [64627.3, 0.556], [64628.2, 0.251], [64628.5, 0.004], [64628.8, 1.123], [64629.3, 0.011], [64629.8, 0.004], [64630.5, 2.086], [64630.7, 0.04], [64630.9, 1.503], [64631.0, 0.058], [64631.8, 0.681], [64632.0, 1.557], [64632.5, 0.01], [64633.3, 0.022], [64634.1, 0.002], [64634.4, 0.37], [64635.3, 0.417], [64636.7, 0.463], [64637.2, 0.022], [64637.6, 0.001], [64638.0, 0.014], [64638.1, 0.004], [64638.3, 0.196], [64638.4, 1.067], [64638.5, 0.002], [64638.6, 0.375], [64638.7, 0.011], [64639.2, 0.022], [64639.3, 0.282], [64639.8, 0.022], [64639.9, 0.925], [64640.3, 0.01], [64640.8, 0.003], [64641.0, 0.068], [64641.3, 0.001], [64641.4, 0.0], [64641.5, 0.065], [64641.8, 0.058], [64642.0, 0.144], [64642.5, 0.038], [64642.7, 0.002], [64642.8, 1.945], [64643.1, 4.193], [64643.6, 2.571], [64643.7, 0.0], [64644.4, 0.064], [64644.8, 2.634], [64644.9, 0.145], [64646.4, 0.01], [64646.7, 0.425], [64646.8, 0.06], [64646.9, 0.311], [64647.0, 0.002], [64647.3, 0.007], [64647.5, 0.016], [64647.8, 0.001], [64648.0, 2.246], [64648.4, 0.462], [64648.5, 0.061], [64648.6, 0.001], [64649.1, 0.074], [64649.2, 0.126], [64649.6, 0.007], [64650.0, 3.086], [64650.1, 0.029], [64650.2, 0.635], [64651.2, 1.484], [64651.4, 0.002], [64651.6, 0.101], [64651.9, 2.451], [64652.0, 1.739], [64652.2, 0.007], [64652.5, 0.002], [64652.6, 0.005], [64652.7, 0.0], [64652.8, 0.378], [64653.0, 0.051], [64653.4, 1.383], [64653.7, 0.057], [64653.8, 0.004], [64654.0, 0.002], [64654.2, 0.038], [64654.5, 0.081], [64654.6, 0.0], [64654.7, 0.001], [64654.9, 0.0], [64655.1, 0.414], [64655.2, 0.0], [64655.3, 0.022], [64655.4, 0.005], [64655.6, 0.015], [64655.7, 0.17], [64655.8, 0.029], [64655.9, 0.032], [64656.0, 0.797], [64656.2, 0.005], [64656.3, 0.005], [64656.5, 0.01], [64656.6, 0.066], [64656.7, 0.029], [64656.8, 0.127], [64656.9, 0.349], [64657.0, 0.558], [64657.1, 0.566], [64657.4, 0.0], [64657.5, 0.055], [64657.6, 1.508], [64657.7, 0.006], [64657.8, 0.018], [64657.9, 0.157], [64658.0, 1.309], [64658.1, 0.008], [64658.3, 0.004], [64658.4, 0.0], [64658.6, 0.377], [64658.7, 1.521], [64658.8, 0.008], [64658.9, 0.351], [64659.1, 0.314], [64659.2, 1.022], [64659.3, 0.966], [64659.4, 0.969], [64659.6, 0.452], [64659.7, 0.036], [64659.8, 0.003], [64659.9, 0.003], [64660.1, 0.015], [64660.3, 4.885], [64660.4, 0.928], [64660.5, 0.001], [64660.6, 0.041], [64660.8, 1.152], [64660.9, 2.334], [64661.1, 0.293], [64661.2, 0.02], [64661.3, 0.117], [64661.7, 0.463], [64661.9, 0.934], [64662.0, 0.137], [64662.1, 0.008], [64662.2, 0.007], [64662.3, 2.217], [64662.4, 0.017], [64662.6, 0.177], [64662.8, 0.148], [64662.9, 0.287], [64663.1, 0.412], [64663.7, 0.001], [64663.8, 0.004], [64664.3, 0.4], [64664.5, 0.013], [64664.6, 0.032], [64664.7, 0.236], [64664.8, 0.581], [64665.0, 2.046], [64665.3, 0.022], [64665.5, 0.002], [64665.6, 0.176], [64665.8, 0.002], [64665.9, 0.136], [64666.0, 3.103], [64666.1, 0.158], [64666.3, 0.583], [64666.4, 0.002], [64666.5, 0.395], [64666.6, 0.129], [64666.8, 0.096], [64667.0, 0.002], [64667.2, 0.005], [64667.6, 0.118], [64667.7, 0.348], [64667.8, 0.401], [64667.9, 0.698], [64668.0, 0.006], [64668.1, 0.001], [64668.2, 1.659], [64668.4, 0.213], [64668.6, 0.003], [64668.7, 0.071], [64668.8, 0.01], [64668.9, 0.003], [64669.0, 0.545], [64669.1, 0.094], [64669.2, 0.001], [64669.3, 0.0], [64669.4, 0.002], [64669.5, 0.06], [64669.6, 0.256], [64669.7, 0.052], [64669.8, 0.164], [64669.9, 0.703], [64670.0, 1.353], [64670.1, 0.003], [64670.3, 0.001], [64670.4, 0.003], [64670.5, 0.262], [64670.6, 0.0], [64670.7, 1.986], [64670.8, 0.046], [64670.9, 0.098], [64671.0, 0.002], [64671.2, 0.165], [64671.3, 0.085], [64671.4, 0.056], [64671.5, 0.006], [64671.6, 0.123], [64671.7, 0.171], [64671.8, 0.001], [64671.9, 0.02], [64672.0, 0.533], [64672.1, 0.084], [64672.2, 0.555], [64672.3, 0.005], [64672.4, 0.084], [64672.5, 0.003], [64672.6, 0.003], [64672.7, 0.325], [64672.8, 0.085], [64672.9, 1.816], [64673.0, 0.003], [64673.2, 0.085], [64673.4, 0.003], [64673.5, 0.089], [64673.6, 0.004], [64673.7, 0.005], [64673.8, 0.001], [64673.9, 0.185], [64674.0, 0.005], [64674.1, 0.016], [64674.2, 0.081], [64674.3, 0.001], [64674.5, 0.001], [64674.6, 0.001], [64674.7, 0.22], [64674.8, 0.023], [64674.9, 0.013], [64675.0, 0.017], [64675.1, 0.347], [64675.2, 0.033], [64675.3, 0.0], [64675.4, 0.002], [64675.5, 0.001], [64675.6, 0.0], [64675.7, 0.165], [64675.8, 0.004], [64675.9, 0.0], [64676.0, 0.011], [64676.1, 0.002], [64676.2, 0.001], [64676.3, 0.003], [64676.4, 0.032], [64676.5, 0.054], [64676.6, 0.006], [64676.7, 0.001], [64676.8, 0.003], [64676.9, 0.064], [64677.2, 0.055], [64677.3, 0.043], [64677.5, 0.045], [64677.6, 0.003], [64677.8, 0.001], [64677.9, 0.046], [64678.1, 0.003], [64678.2, 0.003], [64678.3, 0.0], [64678.4, 0.009], [64678.6, 0.001], [64678.7, 0.001], [64679.0, 0.006], [64679.1, 0.015], [64679.3, 0.004], [64679.5, 0.0], [64680.0, 1.507], [64680.1, 0.001], [64680.2, 0.0], [64680.4, 0.015], [64680.5, 0.0], [64680.8, 0.0], [64681.0, 0.001], [64681.2, 0.001], [64681.3, 0.0], [64681.4, 0.003], [64681.5, 0.0], [64681.6, 0.0], [64681.7, 0.0], [64681.8, 0.0], [64681.9, 0.0], [64682.0, 0.0], [64682.1, 0.0], [64682.2, 0.0], [64682.3, 0.0], [64682.4, 0.0], [64682.6, 0.0], [64682.7, 0.0], [64682.8, 0.0], [64682.9, 0.0], [64683.0, 0.0], [64683.1, 0.0], [64683.2, 0.0], [64683.3, 0.0], [64683.5, 0.0], [64683.6, 0.0], [64683.7, 0.0], [64683.9, 0.0], [64684.0, 0.0], [64684.3, 0.0], [64684.5, 0.0], [64684.6, 0.0], [64684.8, 0.0], [64685.0, 0.0], [64685.1, 0.0], [64685.2, 0.0]], "asks": [[64681.5, 35.108], [64681.6, 4.645], [64681.7, 16.782], [64681.8, 1.054], [64681.9, 0.261], [64682.0, 4.89], [64682.1, 5.619], [64682.2, 2.926], [64682.3, 0.981], [64682.4, 1.099], [64682.5, 2.306], [64682.6, 0.003], [64682.7, 3.888], [64682.8, 15.52], [64682.9, 0.003], [64683.0, 0.032], [64683.1, 0.037], [64683.2, 0.0], [64683.3, 4.316], [64683.4, 0.457], [64683.5, 1.0], [64683.6, 0.019], [64683.7, 4.193], [64683.8, 0.0], [64683.9, 0.002], [64684.0, 2.556], [64684.1, 2.87], [64684.2, 0.001], [64684.3, 0.0], [64684.4, 0.001], [64684.5, 0.0], [64684.6, 0.001], [64684.7, 0.999], [64684.8, 0.103], [64684.9, 3.341], [64685.0, 0.002], [64685.1, 0.004], [64685.2, 2.508], [64685.3, 3.845], [64685.4, 5.773], [64685.5, 0.472], [64685.6, 0.126], [64685.7, 0.881], [64685.8, 0.014], [64685.9, 0.0], [64686.0, 0.634], [64686.1, 2.332], [64686.3, 0.016], [64686.4, 0.119], [64686.5, 0.015], [64686.6, 0.382], [64686.7, 0.004], [64686.8, 0.0], [64686.9, 0.003], [64687.0, 0.002], [64687.1, 0.0], [64687.2, 0.001], [64687.3, 0.006], [64687.4, 0.002], [64687.5, 0.087], [64687.7, 0.0], [64687.8, 0.002], [64688.0, 0.005], [64688.1, 0.006], [64688.2, 0.271], [64688.3, 0.0], [64688.4, 0.003], [64688.5, 4.613], [64688.6, 0.002], [64688.7, 0.001], [64688.8, 0.136], [64688.9, 4.64], [64689.0, 0.132], [64689.2, 2.303], [64689.3, 0.003], [64689.4, 2.168], [64689.5, 2.168], [64689.6, 2.184], [64689.7, 3.756], [64689.8, 0.004], [64690.0, 0.004], [64690.1, 0.241], [64690.4, 12.168], [64690.5, 2.173], [64690.6, 0.0], [64690.8, 2.249], [64690.9, 2.17], [64691.1, 0.001], [64691.2, 2.178], [64691.3, 0.738], [64691.4, 0.059], [64691.5, 2.772], [64691.6, 0.156], [64691.7, 0.25], [64691.8, 0.003], [64691.9, 1.237], [64692.0, 2.569], [64692.1, 0.5], [64692.2, 0.003], [64692.3, 0.02], [64692.4, 0.022], [64692.5, 0.628], [64692.6, 1.604], [64692.7, 6.563], [64692.8, 1.161], [64692.9, 1.002], [64693.1, 0.002], [64693.2, 0.003], [64693.3, 0.272], [64693.4, 0.003], [64693.5, 0.002], [64693.6, 0.093], [64693.7, 0.002], [64693.8, 0.251], [64694.0, 0.004], [64694.1, 0.161], [64694.2, 0.001], [64694.3, 0.927], [64694.5, 2.552], [64694.6, 0.313], [64694.9, 0.001], [64695.1, 0.001], [64695.2, 0.327], [64695.3, 0.243], [64695.4, 0.001], [64695.5, 0.0], [64695.6, 0.001], [64695.9, 0.002], [64696.1, 0.0], [64696.3, 0.054], [64696.4, 0.015], [64696.5, 1.099], [64696.7, 2.319], [64696.8, 0.035], [64696.9, 0.042], [64697.0, 0.075], [64697.1, 0.035], [64697.2, 0.008], [64697.3, 0.027], [64697.4, 0.556], [64697.5, 0.046], [64697.6, 0.088], [64697.7, 0.04], [64697.8, 0.046], [64697.9, 0.006], [64698.0, 0.181], [64698.2, 0.451], [64698.3, 0.315], [64698.4, 1.761], [64698.5, 1.763], [64698.6, 0.85], [64698.8, 0.649], [64698.9, 0.276], [64699.1, 0.171], [64699.5, 0.012], [64699.6, 0.01], [64699.7, 0.541], [64699.9, 0.086], [64700.0, 1.619], [64700.2, 3.228], [64700.3, 0.224], [64700.4, 0.117], [64700.5, 0.0], [64700.6, 1.283], [64700.7, 0.002], [64701.0, 0.928], [64701.1, 0.645], [64701.2, 0.463], [64701.3, 0.167], [64701.4, 0.005], [64701.5, 0.01], [64701.7, 0.004], [64701.8, 0.021], [64701.9, 0.698], [64702.0, 0.001], [64702.1, 0.234], [64702.2, 0.466], [64702.3, 0.0], [64702.4, 0.313], [64702.5, 0.004], [64702.7, 0.002], [64702.8, 0.023], [64702.9, 0.31], [64703.0, 0.002], [64703.1, 0.026], [64703.2, 0.395], [64703.3, 0.059], [64703.4, 0.557], [64703.5, 0.046], [64703.6, 0.002], [64703.9, 0.211], [64704.2, 0.155], [64704.4, 0.014], [64704.5, 2.319], [64704.6, 0.242], [64704.7, 0.005], [64704.9, 0.054], [64705.0, 0.919], [64705.1, 0.501], [64705.2, 0.015], [64705.3, 0.024], [64705.6, 3.677], [64705.7, 0.009], [64705.9, 0.024], [64706.0, 0.072], [64706.3, 0.626], [64706.7, 0.0], [64707.0, 0.503], [64707.1, 0.464], [64707.2, 0.007], [64707.3, 0.156], [64707.7, 0.0], [64707.8, 0.001], [64708.1, 0.002], [64708.5, 0.311], [64708.7, 0.326], [64708.8, 1.187], [64709.2, 0.002], [64709.5, 0.001], [64709.6, 0.01], [64709.7, 0.006], [64709.8, 0.005], [64710.0, 0.021], [64710.2, 0.026], [64710.6, 0.0], [64710.8, 1.421], [64710.9, 0.0], [64711.1, 0.002], [64711.2, 1.671], [64711.3, 0.168], [64711.4, 0.027], [64711.6, 0.111], [64712.0, 1.248], [64712.1, 1.247], [64712.3, 0.119], [64712.4, 0.001], [64712.5, 0.002], [64712.8, 0.001], [64712.9, 0.003], [64713.3, 0.0], [64713.5, 0.31], [64713.7, 0.0], [64713.8, 0.004], [64714.1, 0.059], [64714.2, 0.631], [64714.5, 0.537], [64715.0, 0.001], [64715.1, 0.002], [64715.2, 1.254], [64715.3, 0.358], [64715.6, 2.421], [64715.8, 1.221], [64715.9, 0.001], [64717.8, 0.002], [64718.5, 0.34], [64718.8, 0.029], [64719.5, 1.241], [64719.6, 0.285], [64720.3, 0.002], [64720.4, 0.055], [64720.6, 0.001], [64721.0, 0.002], [64721.1, 4.013], [64721.5, 0.003], [64721.7, 0.375], [64722.2, 2.015], [64722.4, 0.628], [64723.8, 0.02], [64723.9, 0.002], [64724.5, 0.028], [64725.2, 0.004], [64725.7, 0.003], [64726.5, 0.017], [64727.7, 0.028], [64728.3, 0.0], [64728.6, 0.022], [64728.7, 0.308], [64729.5, 0.002], [64729.9, 0.049], [64730.5, 0.212], [64730.7, 0.031], [64731.0, 0.067], [64731.6, 0.018], [64732.0, 3.525], [64732.2, 0.017], [64732.3, 0.019], [64732.5, 0.076], [64732.6, 0.093], [64733.0, 0.042], [64733.1, 0.001], [64733.2, 0.01], [64733.6, 0.002], [64733.7, 0.003], [64733.8, 0.004], [64734.0, 0.001], [64734.2, 0.312], [64734.6, 0.006], [64735.1, 0.0], [64735.2, 0.002], [64735.9, 0.0], [64736.6, 0.005], [64737.2, 2.367], [64737.7, 0.008], [64738.7, 0.081], [64739.9, 0.041], [64740.0, 0.036], [64740.8, 1.257], [64742.0, 0.537], [64742.1, 0.024], [64742.2, 0.0], [64742.7, 0.001], [64743.2, 1.507], [64743.3, 2.124], [64743.5, 0.026], [64743.7, 0.005], [64744.0, 1.36], [64744.4, 0.121], [64746.5, 0.031], [64747.0, 0.027], [64747.1, 0.0], [64747.3, 0.061], [64747.5, 0.002], [64747.7, 0.0], [64748.7, 0.023], [64749.1, 0.0], [64749.7, 0.002], [64750.0, 1.928], [64751.8, 0.001], [64753.1, 0.002], [64753.7, 0.002], [64754.1, 0.187], [64754.4, 0.522], [64755.1, 0.023], [64755.7, 0.046], [64757.7, 0.0], [64759.3, 0.243], [64760.1, 0.0], [64760.4, 0.31], [64760.8, 0.0], [64761.6, 0.007], [64761.8, 0.029], [64762.9, 0.031], [64763.5, 0.0], [64764.0, 0.035], [64764.1, 0.0], [64765.7, 1.237], [64766.0, 0.016], [64768.0, 0.011], [64771.3, 0.029], [64774.5, 0.054], [64775.6, 0.126], [64776.0, 3.77], [64776.1, 2.32], [64776.7, 0.021], [64778.9, 0.002], [64779.6, 0.014], [64780.7, 0.402], [64781.1, 0.011], [64782.0, 0.781], [64782.2, 0.0], [64782.3, 2.893], [64783.3, 0.0], [64784.1, 2.341], [64785.5, 39.337], [64786.9, 0.0], [64789.3, 0.0], [64791.8, 0.001], [64793.4, 2.149], [64793.5, 0.002], [64794.4, 0.002], [64797.3, 0.09], [64798.4, 1.482], [64798.6, 2.675], [64799.3, 0.123], [64800.8, 0.015], [64801.7, 2.137], [64801.8, 0.135], [64803.0, 0.017], [64803.6, 0.0], [64803.8, 0.83], [64803.9, 0.116], [64805.7, 0.01], [64806.4, 0.031], [64810.0, 2.922], [64810.2, 0.0], [64811.9, 0.019], [64812.2, 0.0], [64812.7, 0.002], [64815.6, 0.013], [64817.8, 0.003], [64818.5, 0.02], [64821.1, 0.0], [64822.1, 0.285], [64823.0, 0.005], [64824.8, 0.376], [64825.5, 1.466], [64825.6, 1.926], [64827.1, 3.783], [64828.5, 0.001], [64833.6, 3.82], [64839.4, 1.465], [64839.5, 0.0], [64844.0, 0.034], [64849.9, 5.678], [64853.3, 1.467], [64853.4, 0.124], [64857.4, 0.0], [64858.1, 0.002], [64860.0, 0.248], [64861.3, 0.001], [64861.7, 4.583], [64861.8, 29.413], [64864.9, 0.0], [64866.2, 0.0], [64867.7, 3.109], [64868.0, 0.4], [64869.4, 0.003], [64876.5, 0.021], [64879.3, 0.005], [64882.9, 13.868], [64887.0, 0.287], [64889.4, 0.01], [64941.2, 0.002], [64947.9, 0.094], [65005.9, 0.003], [65012.5, 0.001], [65013.7, 0.115], [65022.6, 0.015], [65135.3, 0.005], [65141.9, 0.0], [65200.0, 136.801], [65206.6, 0.001], [65328.3, 0.007], [65328.5, 0.002], [65329.0, 0.265], [65329.3, 0.0], [65329.6, 0.008], [65331.7, 0.116], [65332.2, 0.006], [65332.4, 1.213], [65682.2, 0.771], [65682.8, 0.004], [65683.3, 0.011], [65683.4, 0.006], [65685.7, 0.008], [65689.2, 0.0], [65689.7, 0.0], [65692.7, 0.0], [65693.5, 0.003], [65693.8, 0.0], [65963.2, 1.298], [65979.0, 0.314]]}
{"kind": "depth", "E": 1787080503451, "U": 11315358709536, "u": 11315358741905, "recv_ms": 1787080503915, "bids": [[14480.0, 0.35], [14481.4, 0.028], [14592.6, 1.036], [58212.0, 0.514], [58213.2, 0.0], [58214.1, 0.0], [61446.0, 0.066], [63386.4, 0.006], [63989.3, 0.78], [64033.2, 0.002], [64034.6, 0.001], [64034.8, 0.0], [64035.5, 1.041], [64036.8, 0.009], [64045.0, 0.095], [64237.7, 0.122], [64337.0, 5.406], [64338.6, 0.115], [64340.8, 0.033], [64359.0, 5.003], [64365.8, 0.0], [64368.0, 0.025], [64369.1, 6.796], [64384.1, 4.962], [64384.9, 1.843], [64411.2, 4.734], [64414.0, 0.548], [64415.6, 0.0], [64418.8, 2.397], [64430.5, 0.001], [64489.6, 1.287], [64494.3, 0.002], [64497.5, 0.001], [64502.8, 0.09], [64513.6, 4.555], [64515.5, 0.068], [64524.8, 0.689], [64532.3, 0.03], [64539.4, 0.0], [64543.6, 0.396], [64543.8, 0.037], [64543.9, 0.838], [64545.4, 0.287], [64547.0, 0.108], [64547.1, 0.071], [64554.2, 2.322], [64554.3, 0.001], [64555.3, 0.0], [64556.4, 0.24], [64557.9, 0.0], [64558.8, 0.031], [64559.0, 0.006], [64559.1, 0.0], [64559.2, 0.015], [64559.4, 0.033], [64559.6, 1.464], [64560.0, 0.44], [64562.3, 0.0], [64565.4, 0.002], [64572.2, 0.005], [64573.9, 0.004], [64575.3, 0.007], [64576.5, 1.374], [64577.1, 0.002], [64577.9, 0.0], [64578.4, 1.756], [64580.7, 0.013], [64580.9, 0.596], [64581.1, 2.32], [64581.4, 0.006], [64584.9, 3.231], [64585.5, 0.001], [64585.9, 2.743], [64588.4, 0.001], [64592.9, 1.321], [64595.4, 0.212], [64596.5, 0.001], [64597.7, 0.412], [64597.9, 0.102], [64598.1, 3.21], [64599.7, 0.028], [64600.0, 14.559], [64600.9, 37.821], [64601.1, 1.714], [64602.0, 0.291], [64602.1, 0.269], [64603.1, 1.552], [64603.6, 4.271], [64606.0, 0.043], [64607.3, 2.401], [64608.4, 0.005], [64610.3, 0.002], [64612.7, 0.142], [64612.8, 1.191], [64612.9, 0.001], [64613.2, 0.025], [64613.3, 0.05], [64613.4, 0.032], [64613.8, 0.036], [64614.2, 0.63], [64614.3, 0.02], [64614.9, 0.065], [64615.3, 1.427], [64615.9, 0.001], [64616.0, 3.477], [64616.2, 0.001], [64616.4, 0.003], [64616.5, 0.346], [64617.2, 0.015], [64618.7, 0.024], [64619.5, 0.381], [64620.1, 0.017], [64620.2, 0.015], [64620.4, 1.579], [64620.5, 0.505], [64620.8, 0.006], [64621.2, 4.512], [64621.3, 0.006], [64621.6, 0.03], [64622.4, 1.195], [64622.6, 0.002], [64623.4, 1.323], [64623.8, 0.008], [64624.5, 2.07], [64624.6, 0.008], [64624.7, 2.879], [64625.7, 0.025], [64626.5, 0.134], [64627.2, 0.033], [64628.3, 0.046], [64630.1, 0.165], [64630.3, 1.569], [64630.5, 1.043], [64631.0, 0.173], [64631.1, 0.314], [64631.6, 0.075], [64633.7, 0.027], [64634.4, 0.03], [64634.6, 0.004], [64634.7, 0.2], [64634.9, 0.046], [64635.5, 3.674], [64635.6, 1.124], [64635.7, 0.174], [64636.0, 0.038], [64636.1, 0.019], [64636.3, 0.007], [64636.4, 0.0], [64637.1, 0.124], [64638.1, 0.002], [64638.3, 0.205], [64638.8, 0.364], [64639.3, 0.03], [64639.4, 0.1], [64639.9, 0.74], [64640.2, 0.113], [64641.2, 0.005], [64642.7, 0.0], [64643.2, 2.698], [64643.5, 0.136], [64644.1, 0.14], [64644.3, 0.137], [64644.7, 1.705], [64644.8, 1.164], [64644.9, 0.008], [64645.0, 0.014], [64645.5, 0.003], [64646.0, 3.045], [64646.6, 0.006], [64646.7, 0.465], [64646.8, 0.06], [64647.6, 0.002], [64648.0, 2.247], [64649.1, 0.001], [64649.3, 0.449], [64649.8, 0.004], [64650.2, 0.595], [64650.7, 2.934], [64651.1, 0.377], [64651.2, 1.481], [64651.3, 0.185], [64651.7, 1.705], [64651.8, 0.009], [64652.0, 1.836], [64652.1, 0.013], [64652.2, 0.001], [64652.5, 0.349], [64652.7, 0.029], [64652.8, 0.378], [64652.9, 0.013], [64653.1, 0.159], [64653.3, 0.258], [64653.6, 0.02], [64654.0, 0.006], [64654.1, 0.032], [64654.2, 0.062], [64654.4, 1.174], [64655.1, 0.414], [64655.6, 0.175], [64655.9, 0.047], [64656.0, 0.919], [64656.3, 0.005], [64656.4, 0.0], [64656.6, 0.051], [64656.7, 0.162], [64656.8, 0.619], [64657.0, 0.558], [64657.3, 0.463], [64657.4, 0.115], [64657.5, 0.053], [64657.6, 1.506], [64657.8, 0.02], [64657.9, 0.003], [64658.1, 0.012], [64658.2, 0.233], [64658.3, 0.01], [64658.5, 0.256], [64658.6, 1.846], [64658.7, 0.052], [64659.2, 1.027], [64659.3, 0.506], [64659.5, 0.009], [64659.6, 0.462], [64659.7, 0.028], [64660.0, 0.173], [64660.3, 4.892], [64660.4, 1.052], [64660.6, 0.001], [64661.1, 0.304], [64661.3, 0.002], [64661.6, 0.002], [64662.0, 0.138], [64662.2, 0.0], [64662.3, 2.297], [64662.4, 0.011], [64662.5, 0.003], [64662.7, 0.078], [64663.3, 0.109], [64663.8, 0.002], [64664.0, 0.049], [64664.3, 0.103], [64664.4, 0.001], [64664.5, 0.001], [64664.9, 0.0], [64665.1, 1.491], [64665.4, 0.011], [64665.6, 0.169], [64665.7, 0.161], [64665.8, 0.001], [64665.9, 0.056], [64666.0, 3.105], [64666.1, 0.157], [64666.7, 0.659], [64666.8, 0.006], [64667.0, 0.004], [64667.1, 0.42], [64667.3, 0.066], [64667.6, 0.025], [64667.8, 0.361], [64668.3, 0.079], [64668.4, 0.002], [64668.6, 0.001], [64668.7, 0.0], [64668.8, 0.009], [64668.9, 0.047], [64669.1, 0.26], [64669.5, 0.004], [64669.6, 0.259], [64669.9, 0.705], [64670.0, 1.405], [64670.5, 0.262], [64670.6, 0.0], [64670.7, 0.173], [64670.8, 0.002], [64670.9, 0.021], [64671.0, 0.002], [64671.2, 0.0], [64671.3, 0.001], [64671.4, 0.004], [64671.7, 0.171], [64671.9, 0.017], [64672.0, 1.525], [64672.1, 0.001], [64672.2, 0.006], [64672.7, 0.247], [64672.8, 0.086], [64673.0, 1.685], [64673.1, 0.723], [64673.2, 0.085], [64673.3, 0.551], [64673.5, 0.005], [64673.6, 0.088], [64673.7, 0.004], [64673.9, 0.101], [64674.0, 0.099], [64674.1, 0.017], [64674.3, 0.001], [64674.4, 1.817], [64674.5, 0.093], [64674.8, 0.095], [64675.0, 0.103], [64675.1, 0.001], [64675.2, 0.013], [64675.4, 0.156], [64675.7, 0.005], [64675.8, 1.816], [64675.9, 0.001], [64676.0, 0.001], [64676.1, 0.311], [64676.2, 0.0], [64676.3, 0.035], [64676.4, 0.114], [64676.6, 0.076], [64676.7, 0.002], [64676.8, 0.002], [64676.9, 0.085], [64677.3, 0.001], [64677.4, 0.033], [64677.5, 0.0], [64677.7, 0.003], [64677.8, 0.0], [64677.9, 0.078], [64678.0, 0.001], [64678.2, 0.002], [64678.7, 0.0], [64679.0, 0.002], [64679.3, 0.0], [64679.4, 0.0], [64679.5, 0.002], [64679.6, 0.004], [64679.7, 0.004], [64679.8, 0.001], [64679.9, 0.001], [64680.0, 3.025], [64680.1, 0.0], [64680.3, 0.0], [64680.4, 0.0], [64680.6, 0.0], [64681.0, 0.0], [64681.2, 0.0], [64681.3, 0.0], [64681.4, 0.0]], "asks": [[64680.1, 37.763], [64680.2, 0.007], [64680.3, 0.001], [64680.4, 0.0], [64680.5, 0.0], [64680.7, 0.0], [64680.8, 0.08], [64680.9, 0.0], [64681.0, 0.0], [64681.1, 0.0], [64681.3, 0.008], [64681.4, 2.502], [64681.5, 0.566], [64681.6, 0.133], [64681.7, 0.396], [64681.8, 1.0], [64681.9, 0.001], [64682.0, 0.002], [64682.1, 2.5], [64682.2, 0.11], [64682.3, 0.001], [64682.4, 0.085], [64682.5, 0.362], [64682.6, 0.011], [64682.7, 2.791], [64682.8, 0.186], [64682.9, 0.001], [64683.0, 0.001], [64683.1, 0.04], [64683.2, 0.0], [64683.3, 2.415], [64683.4, 0.317], [64683.5, 0.0], [64683.6, 0.001], [64683.7, 0.0], [64683.8, 0.001], [64684.0, 0.365], [64684.1, 0.444], [64684.3, 0.0], [64684.7, 0.002], [64684.8, 0.099], [64684.9, 0.248], [64685.1, 0.004], [64685.2, 0.0], [64685.3, 1.663], [64685.4, 0.001], [64685.6, 0.719], [64685.7, 0.879], [64685.8, 0.362], [64686.0, 0.75], [64686.4, 0.045], [64686.5, 0.016], [64686.6, 0.384], [64686.7, 0.005], [64687.0, 0.002], [64687.3, 0.007], [64687.8, 0.01], [64688.0, 0.91], [64688.1, 0.016], [64688.3, 0.633], [64688.4, 0.019], [64688.5, 2.943], [64688.7, 0.001], [64688.8, 0.269], [64688.9, 2.47], [64689.2, 0.134], [64689.3, 0.117], [64689.4, 0.155], [64689.5, 0.0], [64689.6, 0.016], [64689.7, 1.588], [64689.8, 0.005], [64689.9, 0.032], [64690.0, 0.903], [64690.2, 0.002], [64690.4, 10.072], [64690.5, 0.005], [64690.6, 0.002], [64690.7, 0.001], [64690.8, 0.081], [64690.9, 0.16], [64691.0, 0.9], [64691.2, 0.093], [64691.3, 0.898], [64691.4, 2.449], [64691.5, 3.172], [64691.6, 0.001], [64691.8, 0.349], [64691.9, 1.328], [64692.0, 1.035], [64692.2, 0.002], [64692.3, 0.077], [64692.4, 0.052], [64692.5, 0.712], [64692.6, 1.833], [64692.7, 6.566], [64692.8, 1.163], [64693.0, 0.004], [64693.1, 0.003], [64693.2, 0.005], [64693.7, 0.0], [64693.9, 0.043], [64694.4, 0.01], [64694.5, 1.268], [64694.6, 0.313], [64694.9, 0.031], [64695.0, 1.655], [64695.1, 0.024], [64695.2, 0.327], [64695.3, 0.0], [64695.5, 0.0], [64695.6, 0.001], [64695.7, 0.002], [64695.8, 0.002], [64695.9, 0.001], [64696.0, 0.591], [64696.2, 0.0], [64696.3, 0.18], [64696.5, 1.097], [64696.6, 0.032], [64696.9, 0.111], [64697.0, 0.073], [64697.6, 0.086], [64697.7, 0.014], [64698.1, 0.001], [64698.2, 0.444], [64698.3, 0.313], [64698.4, 1.763], [64698.6, 0.811], [64698.7, 0.133], [64698.8, 0.565], [64698.9, 0.3], [64699.1, 0.169], [64699.3, 0.464], [64699.4, 0.168], [64699.5, 0.66], [64699.6, 0.003], [64700.0, 1.459], [64700.2, 3.226], [64700.6, 1.283], [64700.7, 0.001], [64700.8, 0.3], [64700.9, 0.403], [64701.0, 0.93], [64701.1, 0.631], [64701.5, 0.008], [64701.7, 0.004], [64701.8, 0.001], [64701.9, 0.039], [64702.2, 0.464], [64702.4, 1.495], [64702.7, 0.001], [64702.8, 0.021], [64702.9, 0.31], [64703.5, 0.002], [64703.8, 0.589], [64704.0, 2.934], [64704.1, 0.003], [64704.6, 0.281], [64704.8, 0.207], [64705.0, 0.018], [64705.4, 0.003], [64705.6, 3.106], [64706.2, 0.038], [64707.0, 0.488], [64707.5, 0.011], [64707.6, 0.629], [64708.0, 0.106], [64708.3, 0.963], [64708.5, 2.011], [64708.6, 2.701], [64708.8, 1.307], [64708.9, 0.213], [64709.6, 0.001], [64709.7, 0.012], [64710.0, 1.906], [64710.2, 0.024], [64710.3, 0.134], [64710.4, 0.007], [64710.8, 1.415], [64712.0, 1.246], [64712.5, 0.004], [64713.0, 5.002], [64713.2, 0.239], [64714.0, 0.014], [64714.3, 0.04], [64714.5, 0.543], [64714.9, 2.369], [64715.1, 0.027], [64715.3, 0.354], [64715.6, 0.536], [64716.0, 0.101], [64716.2, 0.031], [64716.6, 0.004], [64717.7, 0.128], [64717.9, 0.266], [64718.0, 0.169], [64718.8, 0.021], [64719.0, 1.05], [64719.2, 0.0], [64719.5, 1.259], [64720.4, 0.042], [64720.5, 0.034], [64721.0, 0.011], [64721.6, 1.401], [64721.8, 0.278], [64722.1, 0.061], [64722.3, 1.088], [64723.1, 0.021], [64723.3, 0.521], [64723.6, 0.311], [64723.8, 0.176], [64724.0, 0.004], [64724.2, 0.003], [64724.4, 0.002], [64724.5, 0.003], [64725.6, 0.005], [64725.8, 0.001], [64726.0, 2.32], [64726.2, 1.241], [64726.8, 0.0], [64727.1, 0.0], [64727.2, 0.0], [64727.4, 0.362], [64727.7, 0.027], [64728.2, 0.026], [64728.8, 0.355], [64729.2, 0.018], [64730.1, 0.02], [64730.5, 0.002], [64730.7, 0.064], [64731.0, 0.066], [64732.6, 0.024], [64732.9, 0.029], [64733.0, 0.0], [64734.2, 0.312], [64734.6, 0.0], [64735.6, 0.001], [64735.7, 0.037], [64738.4, 0.006], [64738.9, 0.005], [64739.9, 0.015], [64740.5, 0.068], [64741.6, 0.028], [64741.8, 0.0], [64741.9, 0.448], [64742.0, 0.084], [64742.6, 0.101], [64743.3, 2.12], [64744.4, 0.069], [64745.0, 2.324], [64745.5, 0.007], [64751.9, 0.223], [64752.1, 0.025], [64753.7, 0.001], [64753.8, 0.0], [64754.4, 0.522], [64755.2, 0.007], [64756.8, 1.252], [64757.0, 0.346], [64759.1, 39.331], [64759.3, 0.074], [64760.2, 0.1], [64760.4, 0.001], [64761.5, 0.055], [64762.0, 0.0], [64768.0, 0.011], [64768.9, 0.243], [64769.8, 0.041], [64771.4, 0.022], [64772.1, 0.003], [64772.7, 2.502], [64774.8, 0.0], [64775.0, 0.0], [64776.3, 0.006], [64776.5, 0.004], [64778.0, 0.023], [64785.0, 0.102], [64785.5, 0.027], [64787.6, 0.0], [64788.3, 0.0], [64789.8, 0.003], [64790.4, 2.213], [64801.1, 0.002], [64802.1, 0.028], [64802.7, 0.025], [64807.4, 0.004], [64809.3, 0.0], [64811.5, 0.279], [64811.6, 0.0], [64813.5, 3.385], [64814.1, 0.447], [64814.2, 0.001], [64814.3, 0.408], [64818.0, 3.893], [64819.0, 0.0], [64819.8, 2.412], [64819.9, 0.0], [64822.1, 0.003], [64823.1, 0.411], [64825.4, 1.466], [64825.5, 0.001], [64826.4, 1.207], [64827.8, 0.027], [64838.7, 0.013], [64845.8, 0.039], [64846.8, 0.016], [64849.7, 0.001], [64851.6, 0.127], [64851.7, 0.069], [64854.4, 0.0], [64856.1, 0.005], [64858.1, 0.001], [64861.3, 0.0], [64862.2, 0.0], [64866.3, 0.0], [64875.5, 0.074], [64881.9, 0.11], [64882.9, 0.0], [64883.2, 0.005], [64883.4, 1.945], [64883.6, 9.519], [65011.4, 0.235], [65028.9, 0.048], [65030.0, 0.711], [65035.4, 0.977], [65041.5, 0.095], [65042.2, 0.002], [65062.6, 0.0], [65070.6, 0.004], [65077.2, 0.002], [65210.2, 9.342], [65326.9, 0.0], [65328.3, 0.003], [65328.5, 0.0], [65329.0, 0.263], [65448.1, 0.014], [65493.7, 0.756], [65498.4, 6.397], [65501.7, 0.756], [65502.0, 2.295], [65628.5, 0.002], [65973.7, 0.003]]}
{"kind": "depth", "E": 1787080503553, "U": 11315358741982, "u": 11315358760191, "recv_ms": 1787080503990, "bids": [[1000.0, 35.81], [14480.0, 0.7], [14592.6, 0.686], [58212.0, 0.514], [61446.0, 0.066], [61829.2, 0.0], [62095.8, 0.0], [63386.4, 0.009], [63601.0, 1.382], [63680.0, 1.779], [63837.0, 1.138], [63888.1, 7.062], [63924.6, 0.0], [64033.2, 0.0], [64035.5, 1.043], [64097.9, 0.203], [64149.1, 0.148], [64162.7, 0.0], [64369.1, 6.795], [64494.3, 0.001], [64497.5, 0.0], [64552.8, 1.679], [64555.1, 0.639], [64559.7, 0.021], [64565.8, 0.0], [64565.9, 0.671], [64566.8, 0.215], [64571.3, 0.581], [64572.3, 0.898], [64572.9, 0.0], [64573.4, 2.321], [64573.8, 0.014], [64579.4, 0.052], [64579.6, 5.531], [64580.9, 0.609], [64586.4, 0.001], [64587.9, 0.232], [64593.5, 0.679], [64595.0, 0.537], [64596.4, 1.517], [64599.8, 1.183], [64600.5, 0.152], [64600.9, 6.469], [64602.0, 0.304], [64603.1, 1.552], [64603.9, 0.479], [64605.0, 0.876], [64605.3, 31.367], [64607.6, 0.033], [64608.5, 0.306], [64609.1, 0.013], [64613.7, 0.0], [64613.9, 0.069], [64614.6, 0.01], [64614.9, 0.062], [64618.4, 0.011], [64621.2, 4.513], [64621.7, 0.011], [64626.9, 1.067], [64627.3, 0.553], [64627.6, 0.002], [64630.2, 0.215], [64634.4, 0.034], [64636.0, 0.034], [64639.7, 0.006], [64641.0, 0.046], [64641.3, 0.002], [64641.9, 0.33], [64642.5, 0.039], [64643.1, 4.194], [64643.7, 0.001], [64644.2, 0.135], [64644.3, 0.138], [64647.1, 0.411], [64647.3, 0.004], [64647.8, 0.012], [64650.6, 0.004], [64654.2, 0.063], [64654.4, 1.264], [64655.6, 0.171], [64656.7, 0.169], [64657.6, 1.39], [64657.7, 0.018], [64658.0, 1.311], [64658.1, 0.005], [64659.8, 0.119], [64659.9, 0.042], [64660.4, 0.126], [64660.6, 0.082], [64660.7, 0.226], [64661.8, 0.0], [64662.2, 0.001], [64662.3, 2.217], [64662.5, 0.004], [64662.6, 0.107], [64662.7, 0.071], [64662.9, 1.213], [64663.0, 1.011], [64664.3, 0.11], [64664.8, 0.481], [64665.0, 2.946], [64666.1, 0.281], [64667.1, 0.729], [64667.2, 0.003], [64667.8, 0.052], [64668.3, 0.566], [64668.5, 0.001], [64668.8, 0.008], [64669.1, 0.319], [64669.9, 0.705], [64670.2, 0.003], [64670.6, 0.001], [64671.9, 0.017], [64672.0, 1.276], [64672.7, 0.015], [64673.1, 0.723], [64673.2, 0.085], [64673.5, 0.006], [64673.6, 0.32], [64673.7, 0.002], [64674.3, 0.002], [64674.5, 0.093], [64674.8, 0.247], [64675.0, 0.101], [64675.3, 0.043], [64675.4, 0.256], [64675.5, 0.001], [64675.6, 0.1], [64675.9, 0.009], [64676.1, 0.001], [64676.2, 0.0], [64676.3, 0.033], [64676.8, 0.004], [64676.9, 0.001], [64677.3, 0.033], [64677.6, 0.001], [64678.9, 0.001], [64680.0, 3.026]], "asks": [[64680.1, 37.882], [64680.2, 0.008], [64680.3, 0.002], [64680.7, 0.007], [64681.3, 0.019], [64681.5, 0.447], [64681.7, 0.439], [64682.0, 0.012], [64682.1, 3.375], [64682.2, 0.109], [64682.4, 0.086], [64682.6, 0.012], [64682.7, 2.795], [64682.8, 0.145], [64683.3, 2.417], [64684.0, 0.46], [64684.8, 0.004], [64685.3, 1.662], [64685.4, 0.002], [64685.5, 0.47], [64685.8, 0.351], [64685.9, 0.309], [64686.6, 0.385], [64688.1, 0.001], [64688.4, 0.49], [64688.7, 0.016], [64688.8, 0.265], [64689.1, 0.001], [64689.2, 0.133], [64689.6, 0.015], [64689.7, 1.621], [64690.1, 0.24], [64690.3, 0.001], [64691.2, 0.128], [64691.4, 2.609], [64691.6, 0.151], [64692.6, 1.369], [64692.7, 6.543], [64692.9, 1.0], [64693.1, 0.004], [64693.8, 0.252], [64693.9, 0.003], [64694.3, 0.002], [64694.4, 0.012], [64695.2, 0.018], [64695.3, 0.925], [64696.9, 0.118], [64697.3, 0.029], [64697.4, 0.0], [64697.5, 0.004], [64697.6, 0.029], [64698.4, 2.324], [64698.6, 0.804], [64699.4, 0.148], [64699.5, 0.661], [64700.4, 0.001], [64700.8, 0.14], [64702.0, 0.117], [64702.4, 2.441], [64703.4, 0.556], [64705.2, 0.003], [64705.6, 3.11], [64705.9, 0.025], [64708.7, 0.34], [64709.1, 0.136], [64711.0, 0.31], [64713.2, 0.264], [64713.9, 0.002], [64714.8, 3.517], [64714.9, 2.367], [64715.2, 1.252], [64715.8, 0.245], [64716.0, 0.087], [64716.3, 0.193], [64716.5, 0.232], [64717.2, 0.005], [64717.8, 0.0], [64718.1, 0.081], [64719.1, 0.035], [64720.4, 0.015], [64721.0, 0.167], [64721.7, 0.373], [64721.8, 0.248], [64722.9, 0.0], [64723.0, 0.001], [64723.8, 0.02], [64724.3, 0.022], [64724.4, 0.001], [64724.7, 0.002], [64725.0, 0.018], [64725.4, 0.009], [64729.5, 0.256], [64730.1, 0.022], [64740.5, 0.071], [64741.5, 0.023], [64741.8, 0.061], [64744.8, 0.38], [64747.3, 0.0], [64751.4, 0.064], [64756.9, 39.311], [64759.1, 0.021], [64759.5, 0.051], [64762.5, 0.005], [64766.5, 0.176], [64766.8, 0.442], [64773.6, 0.014], [64773.8, 0.222], [64775.2, 0.014], [64780.6, 0.015], [64780.9, 1.07], [64784.7, 0.607], [64787.7, 10.853], [64788.0, 0.048], [64794.5, 0.001], [64794.8, 0.013], [64794.9, 0.002], [64795.0, 0.031], [64799.0, 0.076], [64801.8, 0.148], [64802.1, 0.015], [64808.9, 0.029], [64809.1, 0.0], [64810.1, 0.015], [64816.2, 0.0], [64821.0, 5.401], [64825.6, 1.094], [64827.1, 0.0], [64835.2, 2.703], [64838.0, 0.212], [64843.8, 6.842], [64850.6, 0.003], [64874.1, 0.111], [64876.8, 0.231], [64882.6, 9.437], [64883.6, 0.0], [64887.8, 0.524], [64955.2, 2.976], [64960.0, 5.132], [64961.5, 0.023], [64961.6, 0.016], [65002.0, 0.009], [65326.9, 0.0], [65427.1, 0.757], [65429.0, 0.91], [65437.3, 6.445], [65493.7, 1.512], [65494.5, 0.768], [65498.4, 5.641], [65502.0, 1.539], [65521.9, 0.764], [65630.7, 23.851], [65680.1, 0.02]]}
{"kind": "depth", "E": 1787080503655, "U": 11315358760392, "u": 11315358780542, "recv_ms": 1787080503998, "bids": [[1000.0, 35.81], [14380.0, 0.07], [14480.0, 0.994], [14492.6, 2.128], [14592.6, 0.392], [58212.0, 0.514], [61446.0, 0.066], [62092.8, 0.003], [63386.4, 0.012], [63680.0, 1.759], [64032.7, 1.935], [64033.2, 0.004], [64035.5, 0.656], [64393.4, 0.165], [64412.8, 1.688], [64484.2, 1.842], [64487.4, 0.0], [64541.8, 0.12], [64542.1, 0.216], [64555.1, 0.552], [64558.6, 2.319], [64572.0, 0.041], [64572.2, 0.0], [64578.4, 1.748], [64579.7, 0.012], [64588.8, 2.294], [64597.9, 0.112], [64598.6, 0.017], [64600.9, 0.343], [64612.8, 1.191], [64612.9, 0.033], [64613.9, 0.037], [64614.6, 0.0], [64615.3, 1.498], [64620.4, 0.009], [64620.7, 2.972], [64637.0, 0.074], [64638.2, 0.061], [64638.9, 0.003], [64639.5, 0.028], [64640.1, 0.014], [64640.7, 0.163], [64641.5, 0.004], [64643.6, 2.641], [64643.7, 0.071], [64643.9, 0.167], [64644.0, 0.103], [64644.2, 0.135], [64644.3, 0.138], [64644.5, 0.072], [64645.4, 0.015], [64646.7, 0.565], [64652.8, 0.377], [64653.2, 0.012], [64653.8, 0.007], [64655.1, 0.405], [64657.0, 0.559], [64658.0, 1.315], [64658.1, 0.001], [64659.5, 0.009], [64662.9, 1.143], [64663.3, 0.009], [64667.0, 0.012], [64667.1, 0.658], [64668.3, 0.542], [64668.4, 0.026], [64671.9, 0.017], [64672.0, 0.966], [64672.5, 0.003], [64672.9, 0.003], [64673.3, 0.551], [64673.4, 0.002], [64673.6, 0.088], [64674.5, 0.085], [64674.6, 0.009], [64674.8, 0.095], [64674.9, 0.083], [64675.0, 0.171], [64675.1, 0.101], [64675.2, 0.212], [64675.3, 0.076], [64675.5, 0.101], [64675.6, 0.17], [64675.7, 0.075], [64675.8, 1.9], [64675.9, 0.009], [64676.3, 0.065], [64676.4, 0.03], [64677.7, 0.023], [64680.0, 2.206]], "asks": [[64680.1, 37.724], [64680.7, 0.317], [64681.3, 2.009], [64681.5, 0.447], [64681.7, 0.396], [64682.0, 0.012], [64682.1, 3.375], [64682.2, 0.109], [64682.3, 0.001], [64682.5, 0.34], [64683.1, 0.155], [64683.3, 2.44], [64683.6, 0.001], [64683.7, 0.0], [64684.0, 0.365], [64684.8, 0.004], [64685.2, 1.238], [64685.3, 1.662], [64685.6, 0.046], [64686.2, 0.006], [64686.4, 0.041], [64690.7, 0.046], [64691.3, 1.003], [64691.5, 3.393], [64691.7, 0.267], [64691.8, 0.619], [64691.9, 1.448], [64692.1, 0.682], [64692.7, 6.52], [64696.8, 0.0], [64697.1, 0.003], [64697.8, 0.004], [64698.3, 0.041], [64699.1, 0.078], [64700.8, 0.01], [64700.9, 0.004], [64701.4, 0.019], [64704.3, 0.126], [64708.3, 0.01], [64708.4, 1.435], [64708.7, 0.326], [64713.2, 0.239], [64717.3, 1.181], [64717.4, 0.062], [64720.1, 2.346], [64728.2, 0.034], [64737.7, 0.0], [64754.8, 39.31], [64755.6, 0.001], [64755.9, 2.049], [64756.9, 0.001], [64777.8, 1.135], [64781.4, 2.323], [64797.3, 0.005], [64799.3, 0.008], [64800.9, 0.0], [64806.9, 0.118], [64818.4, 0.213], [64838.0, 0.212], [64843.0, 9.259], [64843.8, 0.0], [64845.8, 0.0], [64847.2, 0.811], [64876.8, 9.357], [64882.6, 0.0], [64910.0, 1.168], [65003.5, 0.031], [65210.2, 9.648], [65326.9, 0.002], [65429.0, 1.818], [65429.8, 0.908], [65437.2, 4.54], [65437.3, 5.529], [65449.6, 4.273], [65489.2, 1.925], [65493.7, 0.756], [65586.3, 0.613], [65637.2, 1.475], [65680.1, 0.0], [65983.6, 0.005]]}
{"kind": "depth", "E": 1787080503757, "U": 11315358780568, "u": 11315358796545, "recv_ms": 1787080504001, "bids": [[14380.0, 0.28], [14480.0, 1.134], [14492.6, 1.918], [14592.6, 0.252], [58212.0, 0.514], [61446.0, 0.066], [61458.0, 0.072], [61458.1, 0.015], [61940.2, 0.003], [62092.8, 0.0], [63754.6, 20.482], [63871.5, 0.234], [63891.1, 5.407], [63948.6, 6.559], [64033.2, 0.0], [64221.3, 0.117], [64356.6, 0.0], [64558.3, 0.366], [64568.3, 10.648], [64590.6, 0.215], [64591.0, 0.001], [64601.5, 0.002], [64607.4, 1.69], [64612.6, 0.206], [64613.4, 0.0], [64620.7, 2.872], [64635.1, 0.336], [64638.1, 0.003], [64639.5, 0.004], [64643.6, 2.641], [64643.7, 0.071], [64644.0, 0.203], [64645.1, 0.1], [64646.7, 0.54], [64648.3, 0.007], [64652.3, 0.192], [64654.8, 0.013], [64656.3, 0.005], [64658.3, 0.0], [64659.2, 1.055], [64659.4, 0.004], [64662.8, 0.078], [64663.0, 0.911], [64663.1, 0.312], [64663.4, 0.0], [64663.6, 0.001], [64664.3, 0.01], [64665.5, 0.003], [64667.4, 0.002], [64668.3, 0.543], [64668.4, 0.009], [64670.1, 0.003], [64670.2, 0.567], [64670.3, 1.62], [64672.4, 0.127], [64673.1, 0.065], [64673.3, 0.003], [64674.6, 0.001], [64674.8, 0.165], [64675.1, 0.171], [64675.3, 0.252], [64675.5, 0.102], [64675.9, 0.017], [64679.0, 0.004], [64679.1, 0.032], [64679.8, 0.017], [64679.9, 0.012], [64680.0, 2.19]], "asks": [[64680.1, 37.946], [64681.2, 0.015], [64681.4, 2.503], [64682.0, 0.002], [64682.1, 3.375], [64682.5, 0.34], [64682.7, 2.795], [64683.1, 0.04], [64683.2, 0.115], [64683.3, 2.417], [64683.4, 0.339], [64684.0, 0.365], [64684.9, 0.088], [64685.7, 0.983], [64687.8, 0.002], [64688.1, 0.002], [64688.2, 0.52], [64688.3, 0.626], [64688.9, 2.468], [64691.3, 0.729], [64691.7, 0.387], [64691.9, 1.525], [64692.2, 0.086], [64693.0, 0.166], [64693.8, 0.003], [64693.9, 0.001], [64694.5, 1.266], [64695.2, 0.016], [64695.8, 0.0], [64696.5, 1.095], [64696.8, 0.242], [64696.9, 0.111], [64697.1, 0.001], [64697.3, 0.027], [64697.7, 0.016], [64697.8, 0.002], [64697.9, 0.013], [64698.4, 2.217], [64698.6, 0.421], [64698.9, 0.03], [64699.0, 0.013], [64699.2, 0.103], [64702.4, 2.199], [64702.5, 0.004], [64703.1, 0.226], [64704.3, 0.343], [64707.3, 1.164], [64708.7, 0.126], [64709.1, 0.196], [64709.9, 0.118], [64710.9, 0.223], [64715.8, 0.185], [64716.5, 0.009], [64717.9, 0.168], [64718.0, 0.085], [64733.2, 0.052], [64748.6, 6.982], [64750.1, 0.026], [64752.1, 0.015], [64755.3, 0.17], [64774.6, 0.021], [64775.6, 0.026], [64818.2, 0.283], [64838.0, 0.212], [64842.5, 6.922], [64843.0, 2.368], [64844.6, 0.052], [64847.2, 0.772], [64876.8, 0.231], [64881.3, 9.604], [64881.7, 0.003], [64882.1, 0.005], [65016.2, 5.101], [65326.9, 0.0], [65424.6, 2.725], [65429.0, 0.002], [65437.2, 3.632], [65456.3, 3.025], [65488.8, 8.427], [65489.2, 2.681], [65493.7, 0.0], [65499.1, 0.0], [65618.0, 2.291], [65650.6, 4.524], [65973.6, 0.606], [65973.7, 0.006]]}
{"kind": "depth", "E": 1787080503859, "U": 11315358796811, "u": 11315358811079, "recv_ms": 1787080504003, "bids": [[1000.0, 35.81], [14380.0, 0.518], [14480.0, 1.26], [14492.6, 1.68], [14592.6, 0.126], [58212.0, 0.514], [61446.0, 0.066], [62092.8, 0.003], [63742.1, 1.158], [64033.2, 0.0], [64220.9, 0.017], [64239.8, 0.087], [64558.3, 0.084], [64612.6, 0.037], [64612.9, 0.001], [64613.8, 0.004], [64615.3, 1.499], [64627.9, 0.003], [64633.3, 0.008], [64638.8, 0.337], [64640.5, 0.015], [64645.1, 0.027], [64652.8, 0.378], [64653.5, 0.012], [64654.8, 0.003], [64658.0, 1.313], [64659.0, 0.006], [64659.2, 1.027], [64662.7, 0.001], [64662.8, 0.008], [64662.9, 1.073], [64663.2, 0.004], [64675.2, 0.211], [64675.3, 0.1], [64679.8, 0.018], [64680.0, 2.192]], "asks": [[64680.1, 37.978], [64682.1, 2.5], [64682.2, 0.109], [64683.1, 0.135], [64683.2, 0.0], [64683.3, 2.436], [64683.4, 0.317], [64683.5, 0.022], [64685.3, 1.63], [64685.9, 0.0], [64687.4, 0.311], [64688.0, 0.911], [64691.2, 0.282], [64698.8, 0.445], [64699.1, 0.001], [64699.2, 0.005], [64699.3, 0.38], [64740.0, 0.136], [64744.8, 0.381], [64747.3, 0.01], [64748.4, 0.017], [64748.6, 6.972], [64755.3, 0.001], [64757.4, 0.391], [64815.0, 0.325], [64818.2, 0.001], [64844.6, 0.013], [64845.9, 0.084], [65326.9, 0.0], [65424.6, 5.449], [65437.2, 1.816], [65437.3, 4.613], [65571.5, 0.608]]}
{"kind": "depth", "E": 1787080503961, "U": 11315358811584, "u": 11315358824959, "recv_ms": 1787080504005, "bids": [[1000.0, 35.81], [14380.0, 0.756], [14480.0, 1.372], [14492.6, 1.442], [14592.6, 0.014], [58212.0, 0.514], [61446.0, 0.066], [61458.1, 0.013], [62998.3, 0.001], [63257.0, 0.006], [63680.0, 1.779], [64033.2, 0.0], [64114.4, 1.09], [64139.4, 0.072], [64298.3, 0.646], [64352.0, 11.0], [64356.6, 0.001], [64558.5, 0.286], [64606.4, 1.238], [64607.4, 1.687], [64612.7, 0.31], [64645.3, 0.077], [64647.8, 1.004], [64652.4, 0.407], [64653.5, 0.002], [64659.4, 0.032], [64666.0, 3.107], [64671.1, 0.009], [64672.4, 0.135], [64673.4, 0.24], [64674.2, 0.086], [64675.3, 0.1], [64678.9, 0.003], [64680.0, 2.74]], "asks": [[64680.1, 42.299], [64680.7, 0.31], [64681.2, 0.008], [64681.3, 2.878], [64681.4, 2.51], [64681.5, 0.449], [64682.0, 0.008], [64682.3, 0.009], [64683.0, 0.0], [64684.0, 0.374], [64684.1, 0.802], [64686.3, 0.0], [64687.9, 0.008], [64688.3, 0.626], [64692.7, 3.475], [64697.2, 0.001], [64697.7, 0.014], [64698.1, 0.003], [64699.7, 0.0], [64700.9, 0.545], [64702.0, 0.001], [64702.9, 0.426], [64724.3, 0.024], [64746.2, 2.304], [64747.3, 0.0], [64755.4, 0.17], [64818.3, 0.282], [64838.0, 10.623], [64842.5, 0.005], [64843.5, 0.039], [64845.9, 0.045], [64876.8, 15.645], [64881.3, 0.002], [64954.8, 0.54], [64955.2, 0.002], [65250.0, 30.971], [65326.9, 0.008], [65424.6, 6.357], [65437.3, 3.705], [65573.3, 0.613], [65680.1, 0.02]]}
{"kind": "depth", "E": 1787080504063, "U": 11315358825036, "u": 11315358838088, "recv_ms": 1787080504015, "bids": [[14380.0, 1.106], [14480.0, 1.386], [14492.6, 1.092], [14592.6, 0.0], [58212.0, 0.514], [62051.2, 0.0], [62092.8, 0.0], [62104.9, 0.0], [63742.1, 2.254], [63808.3, 0.004], [63936.2, 0.936], [64033.2, 0.0], [64044.2, 1.728], [64149.1, 0.111], [64356.6, 0.001], [64558.5, 0.006], [64612.7, 0.142], [64645.3, 0.004], [64646.4, 0.042], [64646.8, 0.003], [64648.1, 0.112], [64655.8, 0.099], [64656.4, 0.17], [64659.4, 0.004], [64666.8, 0.006], [64667.4, 0.001], [64668.1, 0.001], [64668.3, 0.002], [64668.4, 0.009], [64669.0, 0.004], [64670.1, 0.004], [64670.2, 0.559], [64670.4, 1.085], [64670.6, 0.008], [64672.0, 1.29], [64674.3, 0.156], [64675.3, 0.252], [64680.0, 2.756]], "asks": [[64680.1, 42.557], [64681.2, 0.0], [64682.4, 0.086], [64682.5, 0.34], [64682.7, 2.505], [64683.0, 0.001], [64683.3, 2.417], [64683.5, 0.0], [64683.6, 0.02], [64683.7, 0.022], [64683.9, 0.292], [64685.8, 0.412], [64686.0, 1.027], [64687.9, 0.016], [64688.1, 0.001], [64688.7, 0.432], [64691.2, 0.283], [64692.7, 3.464], [64694.2, 0.008], [64695.3, 0.0], [64696.2, 0.925], [64698.0, 0.12], [64699.4, 0.091], [64699.9, 0.143], [64702.6, 0.002], [64702.7, 0.003], [64710.6, 0.091], [64710.7, 1.896], [64711.2, 1.769], [64724.8, 1.241], [64745.6, 0.0], [64755.4, 0.001], [64755.5, 0.003], [64818.3, 0.0], [64818.4, 0.213], [64838.0, 10.623], [64842.4, 0.001], [64843.2, 1.246], [64843.5, 0.0], [64876.8, 15.645], [64881.2, 0.002], [65008.2, 0.001], [65047.5, 0.003], [65326.9, 0.0], [65855.6, 8.493], [66245.3, 1.286]]}
{"kind": "depth", "E": 1787080504165, "U": 11315358838405, "u": 11315358849903, "recv_ms": 1787080504117, "bids": [[1000.0, 35.81], [14380.0, 1.456], [14492.6, 0.742], [58212.0, 0.514], [61446.0, 0.066], [62092.8, 0.003], [63386.4, 0.015], [63680.0, 1.759], [63858.5, 0.315], [64033.2, 0.0], [64149.1, 0.074], [64237.7, 0.005], [64542.9, 1.33], [64604.6, 0.029], [64639.7, 0.005], [64651.6, 0.111], [64652.4, 0.397], [64655.7, 0.24], [64662.0, 0.14], [64666.8, 0.16], [64668.0, 0.015], [64675.3, 0.1]], "asks": [[64680.1, 42.562], [64684.2, 0.002], [64686.6, 0.004], [64688.5, 2.562], [64692.7, 3.45], [64700.9, 0.544], [64708.9, 0.367], [64711.3, 0.252], [64722.5, 0.001], [64745.3, 0.01], [64746.2, 2.294], [64752.4, 0.027], [64763.3, 0.002], [64781.9, 0.287], [64805.9, 0.112], [65326.9, 0.0], [65424.6, 7.265], [65437.2, 0.908], [65489.2, 3.437], [65501.9, 3.025], [65680.1, 0.0], [65986.5, 0.07]]}
{"kind": "depth", "E": 1787080504267, "U": 11315358850033, "u": 11315358861900, "recv_ms": 1787080504220, "bids": [[1000.0, 35.81], [14380.0, 1.82], [14492.6, 0.378], [51744.0, 0.0], [51754.0, 0.0], [58212.0, 0.514], [61446.0, 0.066], [62092.8, 0.0], [63709.3, 0.008], [63851.6, 12.911], [63948.6, 5.622], [64032.7, 1.943], [64033.2, 0.0], [64083.7, 1.09], [64139.4, 0.068], [64484.2, 8.107], [64540.0, 4.07], [64549.4, 0.0], [64556.2, 0.004], [64596.1, 0.0], [64603.2, 3.263], [64603.3, 1.26], [64604.4, 2.703], [64606.4, 1.235], [64610.3, 0.0], [64610.4, 0.016], [64633.4, 0.579], [64633.5, 0.635], [64633.6, 0.029], [64639.6, 0.546], [64639.7, 0.001], [64647.6, 0.005], [64652.9, 0.039], [64654.0, 0.024], [64662.9, 0.147], [64663.6, 0.003], [64663.8, 0.928], [64666.8, 0.006], [64667.0, 0.166], [64668.4, 0.002], [64669.0, 0.002], [64670.4, 0.544], [64671.6, 0.231], [64672.3, 0.051], [64672.4, 0.115], [64673.0, 1.707], [64673.1, 0.084], [64673.4, 0.008], [64673.7, 0.048], [64673.8, 0.233], [64674.5, 0.633], [64675.8, 1.816], [64676.5, 0.0], [64677.2, 0.001], [64677.7, 0.003], [64677.9, 0.032], [64680.0, 2.845]], "asks": [[64680.1, 42.763], [64681.3, 2.87], [64682.5, 0.34], [64682.8, 0.146], [64683.6, 0.001], [64683.7, 0.0], [64684.2, 0.043], [64685.3, 1.521], [64685.6, 0.0], [64687.7, 0.008], [64687.9, 0.001], [64688.3, 0.0], [64688.4, 0.019], [64688.5, 2.563], [64689.7, 0.443], [64690.1, 0.241], [64690.3, 1.113], [64692.7, 3.148], [64696.1, 0.002], [64696.9, 0.224], [64701.5, 0.006], [64707.5, 0.026], [64708.9, 0.213], [64709.1, 0.196], [64709.2, 0.156], [64752.5, 39.31], [64754.8, 0.0], [64759.9, 0.59], [64821.0, 5.401], [64838.0, 0.212], [64842.3, 6.915], [64842.6, 0.039], [64843.2, 1.207], [64876.8, 9.85], [64881.6, 1.256], [64881.7, 0.0], [65326.9, 0.0], [65339.6, 5.541], [65434.4, 0.0], [65520.8, 0.041], [65553.3, 2.069], [65641.5, 1.911], [65663.1, 10.135], [65986.5, 0.064]]}
{"kind": "depth", "E": 1787080504369, "U": 11315358862039, "u": 11315358873789, "recv_ms": 1787080504321, "bids": [[14380.0, 2.17], [14492.6, 0.028], [51744.0, 0.0], [51754.0, 0.0], [58212.0, 0.514], [61446.0, 0.066], [61458.1, 0.011], [62162.2, 0.001], [63385.9, 0.008], [63409.7, 0.678], [63597.0, 4.314], [63680.0, 1.779], [63804.2, 1.957], [63847.6, 4.226], [63948.6, 4.685], [64033.2, 0.627], [64139.4, 0.006], [64221.2, 0.317], [64356.6, 0.011], [64369.1, 6.64], [64473.1, 0.0], [64473.2, 0.001], [64484.2, 7.917], [64498.0, 0.658], [64549.0, 0.73], [64550.6, 0.0], [64602.2, 0.031], [64602.7, 0.024], [64615.3, 1.53], [64630.3, 1.567], [64630.4, 2.344], [64650.8, 3.566], [64651.6, 0.101], [64652.8, 0.377], [64653.1, 0.174], [64657.0, 0.002], [64658.8, 0.565], [64659.6, 0.477], [64665.0, 2.946], [64666.0, 4.007], [64668.1, 0.001], [64672.4, 0.092], [64673.3, 0.026], [64673.4, 0.028], [64673.5, 0.006], [64673.8, 0.066], [64674.4, 2.049], [64675.2, 0.212], [64675.8, 1.9], [64678.4, 0.011], [64680.0, 2.849]], "asks": [[64680.1, 42.796], [64682.6, 0.012], [64682.8, 0.145], [64684.2, 0.02], [64684.3, 0.022], [64689.8, 0.02], [64695.0, 1.855], [64697.9, 0.006], [64698.4, 1.661], [64699.1, 0.557], [64699.2, 0.012], [64708.9, 0.215], [64709.0, 0.003], [64709.1, 0.198], [64711.9, 0.002], [64712.0, 1.248], [64712.1, 1.249], [64712.7, 0.008], [64712.8, 0.003], [64712.9, 0.005], [64715.0, 0.003], [64715.1, 0.029], [64715.2, 1.254], [64721.5, 0.001], [64721.6, 1.399], [64721.7, 0.371], [64724.5, 0.001], [64724.6, 0.0], [64724.7, 0.0], [64725.3, 0.0], [64725.4, 0.007], [64725.5, 0.0], [64727.6, 0.0], [64727.7, 0.025], [64727.8, 0.001], [64744.6, 0.034], [64745.3, 0.0], [64838.0, 10.623], [64842.3, 0.0], [64876.8, 10.057], [64909.1, 0.0], [65016.2, 4.947], [65210.2, 9.342], [65326.9, 0.0], [65469.0, 30.926], [65680.1, 0.02], [65986.6, 0.046]]}
{"kind": "depth", "E": 1787080504471, "U": 11315358873875, "u": 11315358884334, "recv_ms": 1787080504424, "bids": [[1000.0, 35.81], [14380.0, 2.534], [14485.2, 0.098], [14485.4, 0.0], [14488.8, 0.0], [14488.9, 0.0], [14489.1, 0.0], [14489.6, 0.0], [14492.6, 0.0], [58212.0, 0.514], [62092.8, 0.003], [63386.4, 0.018], [64033.2, 0.623], [64484.2, 1.625], [64603.0, 0.041], [64603.9, 0.029], [64604.4, 2.7], [64631.7, 0.014], [64650.3, 0.011], [64650.8, 3.556], [64659.4, 0.622], [64662.0, 0.144], [64666.8, 0.624], [64667.0, 0.166], [64674.8, 0.144], [64677.6, 0.003], [64680.0, 2.847]], "asks": [[64680.1, 42.788], [64681.2, 0.008], [64681.5, 0.463], [64682.7, 2.509], [64682.8, 0.145], [64684.2, 0.001], [64684.3, 0.0], [64685.5, 0.49], [64685.7, 1.005], [64687.7, 0.0], [64692.7, 3.139], [64700.0, 2.077], [64700.1, 0.544], [64700.9, 0.003], [64707.4, 0.633], [64744.1, 0.011], [64744.6, 0.024], [64876.8, 15.645], [65326.9, 0.0], [65424.6, 8.173], [65437.3, 2.789]]}
{"kind": "depth", "E": 1787080504573, "U": 11315358884364, "u": 11315358897043, "recv_ms": 1787080504528, "bids": [[1000.0, 35.81], [14380.0, 2.884], [14480.0, 1.316], [14481.4, 0.0], [14482.1, 0.0], [14482.4, 0.0], [14482.7, 0.0], [14483.2, 0.0], [14483.9, 0.0], [14484.8, 0.0], [14485.2, 0.0], [58212.0, 0.514], [61446.0, 0.066], [62092.8, 0.0], [62273.2, 0.0], [63385.9, 0.016], [63398.8, 0.648], [63553.3, 1.259], [63580.4, 0.392], [63680.0, 1.759], [63709.3, 0.016], [63761.5, 0.248], [63851.6, 12.919], [63936.2, 1.873], [64032.7, 1.951], [64033.2, 0.623], [64356.6, 0.166], [64569.7, 0.58], [64625.7, 0.103], [64640.2, 0.038], [64656.7, 0.162], [64657.9, 0.003], [64658.1, 0.558], [64658.8, 0.008], [64659.3, 0.513], [64659.4, 0.004], [64659.6, 0.593], [64659.8, 0.003], [64663.0, 0.911], [64663.8, 0.002], [64663.9, 0.927], [64664.3, 0.003], [64664.7, 0.238], [64665.1, 1.498], [64666.8, 0.006], [64667.0, 0.166], [64667.1, 0.349], [64668.2, 1.968], [64670.2, 0.019], [64670.6, 0.548], [64675.8, 1.9], [64680.0, 2.847]], "asks": [[64680.1, 42.727], [64680.4, 0.001], [64681.2, 0.0], [64681.5, 0.462], [64682.7, 2.509], [64686.0, 1.031], [64687.4, 0.002], [64687.7, 0.309], [64687.8, 0.01], [64688.1, 0.016], [64694.2, 0.029], [64698.3, 0.041], [64698.9, 0.586], [64699.1, 0.001], [64699.2, 0.005], [64699.5, 0.732], [64699.7, 0.007], [64700.0, 1.459], [64700.1, 0.003], [64700.9, 0.544], [64702.4, 2.199], [64702.9, 0.31], [64703.0, 0.118], [64707.4, 0.015], [64707.9, 0.004], [64719.5, 1.257], [64730.0, 1.93], [64750.1, 0.022], [64759.7, 0.03], [64771.3, 0.0], [64772.6, 0.032], [64784.2, 0.162], [64810.1, 0.0], [64851.8, 0.025], [65003.5, 0.185], [65197.5, 0.317], [65326.9, 0.008], [65424.6, 9.081], [65437.3, 1.874], [65456.3, 3.787], [65489.2, 4.949], [65501.9, 2.269], [65502.0, 0.777], [65505.6, 3.188], [65508.0, 0.552], [65650.3, 0.008], [65680.1, 0.0], [65973.7, 0.014], [71148.2, 0.0]]}
{"kind": "depth", "E": 1787080504675, "U": 11315358897341, "u": 11315358912459, "recv_ms": 1787080504630, "bids": [[14380.0, 3.248], [14480.0, 0.952], [58212.0, 0.514], [61446.0, 0.066], [62092.8, 0.003], [62998.3, 1.269], [63936.2, 2.81], [64033.2, 0.623], [64052.9, 0.016], [64356.6, 0.166], [64412.8, 2.302], [64472.0, 1.138], [64582.4, 2.281], [64607.4, 5.953], [64623.1, 6.341], [64632.1, 0.018], [64640.5, 0.001], [64643.3, 7.698], [64648.8, 0.249], [64649.8, 0.014], [64650.3, 0.001], [64652.0, 2.918], [64654.2, 0.026], [64663.0, 1.837], [64663.9, 0.001], [64670.2, 0.003], [64670.6, 0.54], [64670.7, 0.197], [64675.8, 1.816], [64675.9, 0.017], [64680.0, 2.84]], "asks": [[64680.1, 42.735], [64680.7, 0.0], [64682.7, 2.505], [64682.8, 0.145], [64693.0, 0.167], [64697.9, 0.005], [64698.6, 0.47], [64700.1, 0.003], [64700.9, 0.544], [64706.5, 0.002], [64714.7, 2.228], [64743.6, 0.01], [64744.1, 0.001], [64751.2, 0.03], [64752.4, 7.627], [64753.2, 0.022], [64756.1, 3.814], [64835.2, 4.172], [64874.4, 3.385], [65003.5, 0.184], [65326.9, 0.009], [65461.6, 3.938], [65489.2, 5.705], [65501.7, 0.0], [65877.1, 0.0]]}
{"kind": "depth", "E": 1787080504777, "U": 11315358912740, "u": 11315358922077, "recv_ms": 1787080504729, "bids": [[1000.0, 35.81], [14380.0, 3.598], [14480.0, 0.602], [58212.0, 0.514], [61446.0, 0.066], [62092.8, 0.0], [63274.6, 0.002], [63289.4, 0.008], [63385.9, 0.024], [63386.4, 0.026], [63657.5, 9.591], [63680.0, 1.779], [63709.3, 0.024], [63709.8, 0.008], [63851.6, 12.927], [63852.1, 0.008], [64032.7, 1.959], [64033.2, 0.631], [64356.6, 0.167], [64590.5, 0.015], [64590.6, 0.212], [64602.7, 0.027], [64603.0, 0.038], [64649.4, 0.031], [64649.8, 0.004], [64660.7, 0.228], [64668.1, 0.002], [64680.0, 2.825]], "asks": [[64680.1, 43.916], [64680.6, 0.31], [64682.8, 0.145], [64692.6, 1.37], [64743.2, 1.517], [64743.6, 0.0], [64830.0, 0.165], [65326.9, 0.009], [65329.0, 0.271], [65339.6, 5.549], [65469.0, 32.452], [65500.0, 330.114], [65510.1, 0.009], [65520.8, 0.049], [65520.9, 6.044], [65553.6, 26.444], [65652.4, 0.478], [65663.1, 10.143], [65680.1, 0.02], [65727.8, 8.516], [65975.8, 0.008], [65986.6, 0.054]]}
{"kind": "depth", "E": 1787080504879, "U": 11315358922498, "u": 11315358932195, "recv_ms": 1787080504836, "bids": [[1000.0, 35.81], [14280.0, 0.098], [14380.0, 3.766], [14480.0, 0.336], [58212.0, 0.514], [61446.0, 0.066], [62384.2, 0.014], [63386.4, 0.029], [63548.1, 1.258], [64033.2, 0.631], [64108.3, 0.234], [64175.1, 9.802], [64356.6, 0.166], [64373.2, 35.018], [64373.4, 5.393], [64561.4, 2.507], [64603.9, 0.026], [64621.7, 0.014], [64624.5, 2.291], [64637.0, 0.014], [64641.7, 0.002], [64649.1, 0.011], [64649.4, 0.021], [64650.4, 0.715], [64660.2, 0.644], [64663.0, 0.911], [64664.5, 0.927], [64667.0, 0.012], [64668.3, 0.079], [64670.4, 0.003], [64670.6, 0.0], [64670.7, 0.66], [64672.1, 0.542], [64680.0, 2.811]], "asks": [[64680.1, 44.215], [64680.9, 0.002], [64682.8, 0.145], [64688.1, 0.001], [64692.7, 3.14], [64696.2, 0.0], [64696.9, 1.149], [64698.9, 0.03], [64699.7, 0.563], [64700.9, 0.003], [64702.3, 0.541], [64703.0, 0.002], [64703.8, 0.705], [64721.1, 0.507], [64740.5, 0.071], [64742.9, 0.01], [64743.2, 1.507], [64759.9, 0.587], [64800.1, 0.018], [64810.1, 0.015], [64830.0, 0.203], [64872.0, 3.91], [65326.9, 0.009], [65412.9, 0.763], [65424.6, 9.989], [65437.0, 0.985], [65521.4, 3.036], [65587.9, 0.0], [65844.3, 0.126]]}
{"kind": "depth", "E": 1787080504981, "U": 11315358932356, "u": 11315358941062, "recv_ms": 1787080504933, "bids": [[14280.0, 0.336], [14380.0, 3.64], [14480.0, 0.224], [58212.0, 0.514], [58420.5, 0.071], [58582.4, 0.071], [58744.2, 0.072], [58906.0, 0.071], [59067.9, 0.071], [59229.7, 0.071], [59391.5, 0.078], [59553.3, 0.071], [59715.2, 0.071], [59877.0, 0.071], [60038.8, 0.071], [60200.7, 0.071], [60362.5, 0.073], [60524.3, 0.071], [60686.2, 0.071], [60848.0, 0.074], [61009.8, 0.071], [61171.6, 0.072], [61333.5, 0.071], [61446.0, 0.066], [61495.3, 0.072], [62092.8, 0.003], [63645.1, 1.099], [63680.0, 1.759], [63689.9, 6.9], [63754.6, 19.385], [63903.8, 0.219], [63989.3, 0.0], [64033.2, 0.631], [64136.6, 0.062], [64298.3, 0.154], [64313.9, 0.493], [64356.6, 0.166], [64532.3, 0.006], [64550.1, 11.245], [64550.2, 3.882], [64573.5, 0.0], [64575.2, 1.167], [64656.2, 0.176], [64663.6, 0.929], [64664.5, 0.001], [64668.3, 0.002], [64670.4, 0.544], [64670.6, 0.564], [64670.7, 0.173], [64672.1, 0.001], [64676.9, 0.003]], "asks": [[64680.1, 44.36], [64681.5, 0.464], [64682.9, 0.005], [64691.1, 0.004], [64700.9, 0.544], [64702.3, 0.0], [65003.5, 0.185], [65326.9, 0.009], [65488.6, 3.033], [65521.2, 0.0], [65615.6, 0.699], [65680.1, 0.0], [65720.3, 1.067], [65973.7, 0.017]]}
{"kind": "depth", "E": 1787080505083, "U": 11315358941133, "u": 11315358959343, "recv_ms": 1787080505035, "bids": [[1000.0, 35.81], [14280.0, 0.574], [14380.0, 3.528], [14480.0, 0.098], [51744.0, 0.0], [58212.0, 0.514], [61446.0, 0.066], [62092.8, 0.0], [63580.4, 0.69], [63742.1, 3.351], [64033.2, 0.631], [64091.9, 0.234], [64162.6, 2.696], [64175.1, 8.868], [64540.0, 3.988], [64560.0, 4.305], [64564.4, 0.383], [64609.4, 0.047], [64613.3, 0.004], [64648.8, 0.259], [64649.1, 0.001], [64666.5, 0.549], [64668.4, 0.002], [64680.0, 2.798]], "asks": [[64680.1, 44.361], [64682.9, 0.001], [64695.8, 0.925], [64696.9, 0.224], [64742.6, 0.111], [64742.9, 0.0], [64751.8, 0.047], [64755.7, 0.0], [64756.0, 2.835], [64773.8, 0.221], [64816.0, 6.306], [64818.0, 0.028], [64821.0, 5.401], [65210.2, 8.423], [65326.9, 0.009], [65424.6, 12.713], [65437.0, 0.077], [65437.2, 0.0], [65437.3, 0.958], [65456.3, 6.812], [65469.0, 30.622], [65488.9, 0.002], [65489.2, 6.461], [65501.9, 1.513], [65505.6, 2.959], [65809.7, 1.818], [66051.2, 0.011]]}
{"kind": "depth", "E": 1787080505185, "U": 11315358959426, "u": 11315358971900, "recv_ms": 1787080505139, "bids": [[1000.0, 35.81], [14280.0, 0.826], [14380.0, 3.374], [14480.0, 0.0], [51754.0, 0.0], [58212.0, 0.514], [61446.0, 0.067], [61630.4, 0.019], [61642.4, 0.0], [62092.8, 0.003], [62495.2, 0.007], [63677.5, 1.098], [63680.0, 1.779], [63778.1, 0.791], [63958.9, 0.781], [64033.2, 0.631], [64356.6, 0.166], [64601.3, 3.145], [64605.3, 0.015], [64607.4, 1.687], [64607.5, 31.443], [64608.5, 0.307], [64626.1, 0.051], [64631.9, 0.313], [64637.2, 0.018], [64637.7, 0.008], [64641.5, 0.001], [64648.6, 0.011], [64648.8, 0.249], [64666.5, 0.395], [64666.6, 0.283], [64676.4, 0.015]], "asks": [[64680.1, 44.376], [64683.0, 0.001], [64688.1, 0.002], [64694.5, 1.268], [64709.9, 0.009], [64742.4, 0.018], [64742.6, 0.101], [65326.9, 0.009], [65423.9, 0.762], [65424.6, 13.621], [65437.3, 0.042], [65489.2, 7.217], [65502.0, 0.015], [65520.9, 24.176], [65521.9, 0.009], [65553.6, 8.324], [65608.0, 2.303], [65680.1, 0.02], [67710.3, 0.04], [67723.5, 0.003]]}
{"kind": "depth", "E": 1787080505287, "U": 11315358972027, "u": 11315358980070, "recv_ms": 1787080505243, "bids": [[14280.0, 1.19], [14380.0, 3.01], [58212.0, 0.514], [61446.0, 0.066], [61458.1, 0.009], [62092.8, 0.0], [63570.8, 0.79], [63855.6, 0.392], [63894.2, 0.782], [64033.2, 0.631], [64108.3, 0.0], [64594.1, 0.38], [64628.5, 0.005], [64631.9, 0.314], [64659.4, 0.006], [64663.6, 0.929], [64663.8, 0.005], [64666.4, 0.156], [64666.6, 0.129], [64673.3, 0.003]], "asks": [[64680.1, 44.421], [64683.0, 0.001], [64685.3, 1.477], [64686.9, 0.004], [64696.1, 0.002], [65264.0, 0.664], [65276.7, 0.001], [65326.9, 0.009], [65391.6, 3.029], [65424.1, 0.458], [65489.2, 7.973], [65501.9, 0.757], [65520.9, 32.486], [65553.6, 0.0], [65792.6, 0.626], [66038.4, 0.302]]}
{"kind": "depth", "E": 1787080505389, "U": 11315358980377, "u": 11315358994223, "recv_ms": 1787080505343, "bids": [[1000.0, 35.81], [14280.0, 1.554], [14380.0, 2.646], [51744.0, 0.0], [58212.0, 0.514], [61446.0, 0.066], [61458.0, 0.07], [61458.1, 0.011], [62606.2, 0.0], [63398.8, 0.645], [63680.0, 1.759], [63871.5, 0.468], [63922.8, 8.438], [64033.2, 0.631], [64101.1, 1.415], [64113.6, 0.0], [64162.6, 3.63], [64261.4, 0.008], [64273.9, 0.016], [64422.0, 0.015], [64434.6, 3.498], [64540.0, 3.976], [64550.6, 0.0], [64583.1, 0.002], [64595.7, 0.007], [64628.5, 0.006], [64632.1, 0.004], [64641.5, 0.015], [64648.4, 0.472], [64648.6, 0.001], [64654.2, 1.998], [64680.0, 2.293]], "asks": [[64680.1, 44.422], [64681.5, 0.466], [64683.0, 0.005], [64699.9, 0.066], [64742.2, 0.01], [64742.4, 0.008], [64777.0, 0.042], [64782.8, 0.201], [64789.6, 0.0], [64821.0, 5.401], [64938.9, 0.004], [64951.6, 0.0], [65101.3, 0.021], [65114.0, 0.191], [65197.5, 1.236], [65326.9, 0.009], [65456.3, 8.643], [65489.2, 8.729], [65501.9, 0.001], [65680.1, 0.0], [65950.4, 0.649]]}
{"kind": "depth", "E": 1787080505491, "U": 11315358994378, "u": 11315359023760, "recv_ms": 1787080505446, "bids": [[1000.0, 35.81], [14280.0, 1.904], [14380.0, 2.296], [58212.0, 0.514], [61446.0, 0.066], [61458.0, 0.068], [61458.1, 0.013], [62092.8, 0.003], [63680.0, 1.779], [63778.1, 0.321], [63824.2, 1.095], [63871.5, 0.624], [63910.3, 0.938], [64033.2, 0.631], [64091.2, 0.234], [64175.1, 8.557], [64227.2, 0.019], [64356.6, 0.156], [64369.1, 6.485], [64603.1, 1.552], [64605.3, 31.558], [64607.5, 0.0], [64615.7, 0.101], [64660.8, 2.152], [64663.8, 0.015], [64667.8, 0.052], [64673.0, 1.685], [64673.1, 0.065], [64673.4, 0.008], [64673.5, 0.025], [64674.5, 0.653], [64675.2, 0.212], [64675.8, 1.9], [64676.2, 0.084], [64676.4, 0.005], [64680.0, 2.81]], "asks": [[64680.1, 44.177], [64680.6, 0.0], [64681.4, 0.01], [64681.5, 0.465], [64683.0, 0.001], [64688.1, 0.001], [64688.5, 1.472], [64690.3, 0.008], [64690.4, 0.072], [64691.1, 0.63], [64691.2, 0.762], [64695.8, 0.0], [64696.4, 0.94], [64709.4, 0.352], [64716.7, 0.001], [64770.6, 0.475], [65326.9, 0.009], [65359.2, 3.092], [65391.8, 0.076], [65456.3, 11.668], [65478.6, 3.816], [65488.8, 5.404], [65489.2, 9.485], [65494.5, 0.012], [65573.3, 0.005], [65618.0, 4.554], [65650.6, 2.262], [65680.1, 0.02]]}
{"kind": "depth", "E": 1787080505593, "U": 11315359023936, "u": 11315359043926, "recv_ms": 1787080505548, "bids": [[14280.0, 2.254], [14380.0, 1.946], [51744.0, 0.0], [58212.0, 0.514], [61446.0, 0.066], [62092.8, 0.0], [63657.5, 8.493], [63754.6, 17.193], [63948.6, 3.748], [64033.2, 0.631], [64607.5, 0.009], [64621.2, 4.515], [64622.4, 1.193], [64625.6, 1.128], [64638.8, 0.001], [64643.5, 0.472], [64643.7, 0.085], [64648.3, 0.017], [64648.4, 0.462], [64648.8, 0.212], [64651.2, 1.172], [64652.1, 0.322], [64653.2, 0.003], [64654.9, 0.009], [64655.9, 0.049], [64658.1, 0.001], [64658.8, 0.565], [64659.3, 0.506], [64659.5, 0.046], [64659.6, 0.477], [64659.7, 0.035], [64659.9, 0.044], [64660.2, 0.76], [64660.5, 0.004], [64662.9, 0.138], [64665.7, 0.17], [64666.0, 3.107], [64666.8, 0.006], [64667.0, 0.912], [64670.1, 0.003], [64670.4, 0.544], [64670.6, 0.564], [64670.7, 0.173], [64670.8, 0.002], [64671.5, 0.007], [64672.1, 0.001], [64672.4, 0.008], [64673.4, 0.008], [64674.5, 0.112], [64674.6, 0.542], [64674.8, 0.144], [64675.8, 1.9], [64675.9, 0.017], [64676.3, 0.067], [64676.7, 0.086], [64677.2, 0.001], [64678.2, 0.002], [64679.6, 0.001], [64680.0, 4.317]], "asks": [[64680.1, 43.74], [64681.0, 0.084], [64682.3, 0.001], [64682.4, 0.094], [64683.1, 0.135], [64683.3, 2.417], [64685.1, 0.001], [64687.5, 0.003], [64687.7, 0.0], [64688.1, 0.31], [64689.8, 0.019], [64690.4, 0.07], [64690.8, 0.158], [64690.9, 0.623], [64691.1, 0.553], [64691.2, 0.297], [64691.5, 3.395], [64692.2, 0.087], [64692.6, 1.359], [64697.8, 0.013], [64698.5, 11.763], [64699.2, 0.005], [64699.6, 0.559], [64699.7, 0.0], [64700.1, 0.01], [64700.9, 0.003], [64702.3, 0.541], [64702.7, 0.003], [64703.0, 0.002], [64703.7, 0.117], [64703.8, 0.589], [64742.1, 0.034], [64742.2, 0.0], [64750.3, 39.68], [64752.4, 0.027], [64752.5, 0.0], [64759.9, 0.59], [65326.9, 0.009], [65424.6, 14.529], [65429.8, 0.0], [65544.2, 0.0], [65553.3, 2.677], [65727.8, 7.452], [65973.7, 0.02]]}
{"kind": "depth", "E": 1787080505695, "U": 11315359044200, "u": 11315359057071, "recv_ms": 1787080505648, "bids": [[1000.0, 35.81], [14280.0, 2.618], [14380.0, 1.582], [51744.0, 0.0], [58212.0, 0.516], [61200.4, 0.0], [61205.8, 0.123], [61446.0, 0.066], [61779.4, 0.0], [61783.7, 0.019], [62092.8, 0.003], [62717.2, 0.002], [63257.0, 0.003], [63645.1, 2.197], [63742.1, 4.448], [63888.1, 6.797], [63948.6, 2.811], [64033.2, 0.631], [64136.6, 0.031], [64356.6, 0.311], [64415.1, 0.537], [64601.2, 4.058], [64602.5, 0.004], [64602.7, 0.024], [64623.4, 2.513], [64648.2, 0.01], [64648.3, 0.007], [64656.0, 1.441], [64661.7, 0.464], [64670.6, 0.565], [64670.7, 0.721], [64671.5, 0.006], [64674.5, 0.105], [64674.6, 0.001], [64676.6, 0.16], [64676.7, 0.002], [64680.0, 4.379]], "asks": [[64683.3, 2.417], [64685.2, 1.241], [64698.4, 3.309], [64701.0, 1.471], [64702.3, 0.0], [64720.9, 1.528], [64742.0, 0.094], [64742.1, 0.024], [64749.3, 1.807], [64750.3, 0.002], [64752.5, 39.678], [64754.7, 6.0], [64756.9, 0.001], [65326.9, 0.008], [65435.2, 1.997], [65456.3, 14.693], [65488.8, 2.381], [65505.6, 2.731], [65618.0, 6.817], [65629.3, 9.807], [65650.6, 0.0], [65688.0, 12.696], [65715.0, 1.064], [65986.5, 0.061]]}
{"kind": "depth", "E": 1787080505797, "U": 11315359057332, "u": 11315359069793, "recv_ms": 1787080505751, "bids": [[1000.0, 35.81], [14280.0, 2.968], [14380.0, 1.232], [51744.0, 0.0], [54135.0, 0.0], [54140.3, 0.001], [58212.0, 0.514], [59330.3, 0.0], [59337.5, 0.017], [61446.0, 0.066], [61458.0, 0.066], [61458.1, 0.015], [61507.5, 0.285], [62092.8, 0.0], [63528.1, 8.288], [63680.0, 1.759], [63936.2, 3.747], [64033.2, 0.631], [64136.6, 0.0], [64162.6, 3.941], [64356.6, 0.32], [64540.0, 4.039], [64628.6, 0.003], [64630.3, 0.063], [64630.6, 0.001], [64630.9, 1.471], [64631.2, 0.0], [64631.6, 0.043], [64639.7, 0.337], [64641.4, 0.032], [64643.5, 0.402], [64643.6, 2.571], [64643.7, 0.015], [64643.9, 0.067], [64644.0, 0.003], [64644.1, 0.0], [64644.2, 0.035], [64644.5, 0.002], [64646.0, 0.025], [64646.7, 0.44], [64647.1, 0.311], [64647.7, 0.001], [64648.1, 0.08], [64648.4, 0.43], [64648.7, 0.0], [64649.0, 0.249], [64655.7, 0.17], [64655.8, 0.029], [64656.4, 0.0], [64658.0, 1.278], [64660.8, 1.152], [64660.9, 3.334], [64662.1, 0.008], [64665.2, 0.037], [64668.1, 0.001], [64670.4, 0.545], [64670.6, 0.564], [64670.7, 0.173], [64671.6, 0.231], [64672.0, 1.29], [64672.4, 0.092], [64673.5, 0.006], [64674.5, 0.653], [64674.6, 0.002], [64674.8, 0.004], [64674.9, 0.013], [64675.0, 0.101], [64675.1, 0.001], [64675.2, 0.012], [64675.3, 0.0], [64675.4, 0.156], [64675.5, 0.001], [64675.6, 0.0], [64675.7, 0.005], [64675.8, 1.816], [64676.2, 0.0], [64676.3, 0.003], [64676.4, 0.028], [64676.6, 0.006], [64676.7, 0.034], [64677.3, 0.001], [64677.4, 0.001], [64677.9, 0.0], [64680.0, 2.937]], "asks": [[64680.1, 43.689], [64682.4, 0.086], [64682.6, 0.107], [64683.1, 0.048], [64683.4, 0.317], [64685.7, 0.983], [64688.4, 0.011], [64689.6, 0.023], [64689.7, 0.408], [64689.9, 0.0], [64690.3, 0.05], [64690.7, 0.001], [64690.9, 0.581], [64691.2, 0.255], [64691.3, 0.624], [64691.4, 2.449], [64691.5, 3.174], [64691.6, 0.085], [64691.7, 0.267], [64691.8, 0.349], [64691.9, 1.237], [64692.1, 0.5], [64692.2, 0.003], [64692.3, 0.0], [64692.5, 0.628], [64695.7, 0.004], [64695.8, 0.002], [64698.5, 11.765], [64698.8, 0.443], [64701.4, 0.005], [64704.0, 2.934], [64704.7, 0.025], [64707.9, 0.046], [64708.0, 0.12], [64710.6, 0.0], [64710.7, 1.83], [64711.2, 1.671], [64711.3, 0.168], [64714.3, 0.005], [64714.6, 0.463], [64714.9, 2.325], [64715.3, 0.312], [64715.6, 0.494], [64716.4, 6.031], [64717.1, 0.0], [64717.5, 2.534], [64717.6, 0.001], [64717.7, 0.008], [64717.9, 0.0], [64718.0, 0.001], [64718.1, 0.004], [64718.2, 0.014], [64719.6, 0.155], [64725.6, 0.047], [64731.7, 0.021], [64732.1, 0.001], [64732.4, 0.001], [64732.7, 1.547], [64733.2, 0.01], [64800.7, 0.001], [64821.0, 5.401], [64827.6, 0.0], [65003.5, 0.186], [65326.9, 0.008], [65590.4, 0.913], [65680.1, 0.0], [65844.3, 0.96]]}
{"kind": "depth", "E": 1787080505899, "U": 11315359069950, "u": 11315359086192, "recv_ms": 1787080505856, "bids": [[14280.0, 3.332], [14380.0, 0.868], [58212.0, 0.514], [61446.0, 0.066], [62828.2, 0.002], [62998.3, 1.268], [63742.1, 5.545], [63916.3, 42.109], [63936.2, 4.684], [64033.2, 0.631], [64605.3, 0.015], [64607.5, 31.552], [64609.5, 1.799], [64639.7, 0.001], [64640.7, 0.195], [64641.7, 0.034], [64642.0, 0.176], [64648.1, 0.09], [64648.2, 0.0], [64674.8, 0.074], [64675.0, 0.171], [64675.7, 0.105], [64676.0, 0.033], [64677.0, 0.033], [64677.3, 0.033], [64680.0, 2.922]], "asks": [[64680.1, 43.69], [64682.2, 0.187], [64682.6, 0.109], [64683.1, 0.048], [64689.6, 0.058], [64690.0, 0.935], [64690.9, 0.623], [64691.3, 0.784], [64691.9, 1.328], [64692.2, 0.08], [64707.3, 1.199], [64707.6, 0.661], [64708.6, 2.743], [64708.9, 0.213], [64709.0, 0.161], [64709.1, 0.196], [64711.1, 0.093], [64711.3, 0.245], [64711.9, 0.0], [64712.0, 1.246], [64712.1, 1.247], [64712.7, 0.006], [64712.8, 0.001], [64712.9, 0.003], [64715.0, 0.001], [64715.1, 0.027], [64715.2, 1.252], [64724.9, 0.092], [64725.3, 0.032], [64726.2, 1.283], [64741.9, 0.458], [64742.0, 0.084], [64750.3, 39.68], [64752.5, 0.0], [65326.9, 0.008], [65413.9, 0.77], [65527.6, 0.268], [65682.6, 1.14], [71148.2, 0.0]]}
{"kind": "depth", "E": 1787080506001, "U": 11315359086489, "u": 11315359095908, "recv_ms": 1787080505954, "bids": [[1000.0, 35.81], [14280.0, 3.682], [14380.0, 0.518], [58212.0, 0.514], [58420.5, 0.0], [58582.4, 0.0], [58744.2, 0.001], [58906.0, 0.0], [59067.9, 0.0], [59229.7, 0.0], [59391.5, 0.007], [59553.3, 0.0], [59715.2, 0.0], [59877.0, 0.0], [60038.8, 0.0], [60200.7, 0.0], [60362.5, 0.002], [60524.3, 0.0], [60686.2, 0.0], [60848.0, 0.003], [61009.8, 0.0], [61171.6, 0.001], [61333.5, 0.0], [61446.0, 0.066], [61495.3, 0.001], [62092.8, 0.003], [63680.0, 1.779], [63699.7, 0.005], [63916.3, 41.64], [64033.2, 0.631], [64076.5, 0.7], [64237.8, 0.01], [64313.9, 0.001], [64323.6, 0.497], [64356.6, 0.321], [64437.2, 0.003], [64641.1, 0.032], [64648.0, 2.257], [64648.1, 0.08], [64667.4, 0.002], [64674.9, 0.083], [64675.3, 0.1], [64675.5, 0.201], [64675.6, 0.07], [64676.4, 0.06], [64678.9, 0.045], [64680.0, 2.883]], "asks": [[64683.2, 0.0], [64690.6, 0.047], [64691.4, 2.67], [64691.5, 3.324], [64691.7, 0.397], [64692.1, 0.584], [64693.0, 0.24], [64700.0, 1.44], [64705.6, 3.048], [64708.3, 0.055], [64710.5, 0.113], [64710.6, 0.13], [64710.7, 1.98], [64710.8, 1.545], [64711.2, 1.755], [64725.9, 0.045], [64741.8, 0.071], [64741.9, 0.448], [64750.3, 0.002], [64752.5, 39.86], [64754.7, 6.0], [65003.5, 0.185], [65326.9, 0.008], [65615.6, 0.242], [65624.4, 0.67], [65680.1, 0.02], [65823.4, 0.0]]}
{"kind": "depth", "E": 1787080506103, "U": 11315359096256, "u": 11315359105457, "recv_ms": 1787080506057, "bids": [[1000.0, 35.81], [14180.0, 0.154], [14280.0, 3.738], [14380.0, 0.308], [58212.0, 0.514], [62092.8, 0.0], [63903.8, 0.999], [64033.2, 0.631], [64060.0, 5.831], [64356.6, 0.321], [64590.4, 2.975], [64590.5, 0.012], [64602.3, 0.004], [64603.1, 1.552], [64604.9, 0.04], [64605.3, 31.72], [64607.5, 0.009], [64610.1, 0.01], [64621.7, 0.011], [64623.1, 6.373], [64623.7, 0.052], [64661.7, 0.463], [64662.6, 0.109], [64668.4, 0.002], [64673.1, 0.065], [64674.5, 0.633], [64674.9, 0.153], [64675.0, 0.241], [64675.2, 0.212], [64675.3, 0.2], [64675.8, 1.886], [64675.9, 0.101], [64676.2, 0.084], [64676.6, 0.026], [64680.0, 3.43]], "asks": [[64680.1, 43.673], [64683.2, 0.0], [64683.3, 2.421], [64683.5, 0.019], [64683.7, 0.023], [64685.5, 0.47], [64690.4, 0.082], [64691.2, 0.36], [64691.6, 0.205], [64691.8, 0.609], [64692.0, 1.133], [64692.1, 0.668], [64709.4, 0.492], [64710.4, 0.112], [64710.8, 1.665], [64711.0, 0.43], [64711.1, 0.191], [64711.3, 0.329], [64740.5, 0.071], [64759.9, 0.587], [64875.4, 2.954], [64881.5, 0.003], [64881.6, 1.253], [65326.9, 0.008], [65579.2, 2.779], [65590.4, 0.0], [65823.5, 0.759], [65973.7, 0.023]]}
{"kind": "depth", "E": 1787080506205, "U": 11315359105743, "u": 11315359114703, "recv_ms": 1787080506158, "bids": [[14180.0, 0.392], [14280.0, 3.626], [14380.0, 0.182], [34000.0, 1.146], [58212.0, 0.514], [61446.0, 0.066], [62092.8, 0.003], [62939.2, 0.0], [63680.0, 1.759], [63903.8, 1.468], [63916.3, 39.765], [64033.2, 0.631], [64065.5, 1.033], [64220.6, 0.123], [64601.4, 2.35], [64604.9, 0.031], [64608.5, 0.309], [64624.1, 0.032], [64624.4, 0.032], [64628.8, 1.124], [64632.1, 0.006], [64637.8, 0.003], [64656.3, 0.075], [64675.1, 0.071], [64677.6, 0.001], [64680.0, 3.431]], "asks": [[64680.1, 43.678], [64680.7, 0.002], [64683.3, 2.421], [64683.7, 0.024], [64687.2, 0.002], [64691.8, 0.61], [64691.9, 1.405], [64711.0, 0.507], [64741.7, 0.01], [64741.8, 0.061], [65326.9, 0.008], [65579.2, 3.692], [65680.1, 0.0]]}
{"kind": "depth", "E": 1787080506307, "U": 11315359114776, "u": 11315359122908, "recv_ms": 1787080506261, "bids": [[1000.0, 35.81], [14180.0, 0.63], [14280.0, 3.5], [14380.0, 0.07], [51744.0, 0.0], [58212.0, 0.514], [61446.0, 0.066], [64033.2, 0.631], [64612.7, 0.151], [64623.4, 2.545], [64647.9, 0.032], [64648.0, 2.247], [64655.6, 0.241], [64655.9, 0.119], [64658.0, 1.378], [64658.1, 0.003], [64663.6, 0.927], [64680.0, 3.41]], "asks": [[64683.3, 2.417], [64696.1, 0.0], [64697.1, 0.003], [64708.9, 0.215], [64709.0, 0.163], [64709.1, 0.198], [64711.9, 0.002], [64712.0, 1.248], [64712.1, 1.249], [64712.7, 0.008], [64712.8, 0.003], [64712.9, 0.005], [64715.0, 0.003], [64715.1, 0.029], [64715.2, 1.254], [64837.2, 0.801], [64868.3, 0.002], [65326.9, 0.008], [65488.6, 3.375]]}
{"kind": "depth", "E": 1787080506409, "U": 11315359123136, "u": 11315359132288, "recv_ms": 1787080506362, "bids": [[1000.0, 35.81], [14180.0, 0.91], [14280.0, 3.29], [14380.0, 0.0], [51744.0, 0.0], [58212.0, 0.514], [61446.0, 0.067], [62092.8, 0.0], [63398.8, 0.642], [63680.0, 1.779], [64033.2, 0.631], [64356.6, 0.311], [64550.6, 0.0], [64628.8, 1.125], [64655.8, 0.099], [64656.0, 1.541], [64656.1, 0.1], [64656.3, 0.175], [64656.4, 0.17], [64656.6, 0.121], [64660.9, 2.334], [64663.1, 1.238], [64663.6, 0.003], [64665.6, 0.178], [64665.7, 0.161], [64673.1, 0.003], [64675.9, 0.163], [64676.2, 0.0], [64680.0, 2.045]], "asks": [[64680.1, 43.695], [64680.7, 0.312], [64682.0, 0.002], [64682.8, 0.147], [64683.1, 0.048], [64683.3, 2.417], [64683.6, 0.004], [64687.2, 0.001], [64696.1, 0.002], [64700.1, 0.01], [64700.5, 0.541], [64701.0, 0.93], [64709.9, 1.894], [64710.0, 0.021], [64741.6, 0.038], [64741.7, 0.0], [64775.5, 0.001], [65326.9, 0.008], [65478.6, 4.579], [65505.6, 2.389], [65680.1, 0.02], [65693.2, 0.0]]}
{"kind": "depth", "E": 1787080506511, "U": 11315359132344, "u": 11315359141159, "recv_ms": 1787080506466, "bids": [[14180.0, 1.274], [14280.0, 2.926], [51744.0, 0.0], [58212.0, 0.514], [61446.0, 0.066], [62092.8, 0.003], [63050.2, 0.001], [63903.8, 3.343], [64033.2, 0.631], [64638.1, 0.002], [64638.5, 0.003], [64651.7, 2.014], [64652.1, 0.013], [64655.7, 0.24], [64655.8, 0.169], [64656.2, 0.276], [64657.6, 1.49], [64658.3, 0.557], [64658.8, 0.008], [64659.2, 1.645], [64659.3, 0.513], [64659.7, 0.028], [64664.1, 0.331], [64664.7, 0.245], [64665.0, 2.626], [64665.1, 1.491], [64666.5, 1.013], [64667.6, 0.334], [64668.2, 1.659], [64670.7, 0.721], [64673.3, 0.002], [64674.5, 0.085], [64675.0, 0.157], [64675.4, 0.072], [64675.9, 0.079], [64680.0, 2.03]], "asks": [[64683.1, 0.052], [64691.4, 3.854], [64693.8, 10.003], [64698.7, 0.689], [64699.5, 0.739], [64699.6, 0.003], [64699.8, 2.941], [64700.1, 0.003], [64707.2, 0.625], [65326.9, 0.008], [65489.2, 8.729], [65638.0, 17.504]]}
{"kind": "depth", "E": 1787080506613, "U": 11315359141288, "u": 11315359154442, "recv_ms": 1787080506594, "bids": [[1000.0, 35.81], [14180.0, 1.624], [14280.0, 2.576], [51744.0, 0.0], [58212.0, 0.514], [61446.0, 0.066], [62092.8, 0.0], [63386.4, 0.032], [63680.0, 1.759], [63754.6, 16.096], [64033.2, 0.631], [64443.6, 0.019], [64592.9, 1.32], [64615.1, 2.643], [64647.8, 1.014], [64647.9, 0.022], [64654.5, 0.09], [64654.9, 0.0], [64655.5, 0.052], [64656.0, 1.611], [64659.2, 1.027], [64660.0, 0.289], [64660.2, 0.644], [64666.5, 0.395], [64669.9, 0.706], [64670.4, 0.544], [64671.3, 0.085], [64671.4, 0.001], [64671.7, 0.255], [64672.0, 0.98], [64672.1, 0.085], [64672.9, 0.004], [64674.3, 0.155], [64674.5, 0.01], [64674.6, 0.001], [64674.7, 0.001], [64675.9, 0.071], [64679.9, 0.011], [64680.0, 1.358]], "asks": [[64680.1, 43.696], [64680.7, 0.319], [64681.2, 0.008], [64681.4, 0.003], [64682.0, 0.012], [64683.1, 0.048], [64683.2, 0.004], [64685.2, 1.26], [64687.8, 0.002], [64690.2, 0.079], [64690.8, 0.081], [64692.7, 3.138], [64693.8, 10.005], [64698.4, 1.661], [64698.5, 1.765], [64699.8, 2.323], [64702.8, 0.137], [64703.7, 0.001], [64707.2, 0.007], [64777.1, 0.003], [64791.9, 0.0], [64809.5, 0.007], [65326.9, 0.008], [65489.2, 9.492], [65618.0, 6.931], [65630.7, 22.786], [65680.1, 0.0]]}
{"kind": "depth", "E": 1787080506715, "U": 11315359154711, "u": 11315359167960, "recv_ms": 1787080506667, "bids": [[1000.0, 35.81], [14180.0, 1.988], [14280.0, 2.212], [58212.0, 0.514], [61446.0, 0.066], [62092.8, 0.003], [63161.2, 0.001], [63398.8, 0.636], [63625.2, 1.993], [63689.9, 5.802], [63958.9, 1.562], [64033.2, 0.631], [64356.6, 0.311], [64560.0, 0.44], [64560.2, 3.865], [64562.8, 1.828], [64585.3, 1.616], [64607.4, 6.006], [64609.4, 0.047], [64621.8, 0.002], [64635.8, 0.337], [64641.6, 1.062], [64643.5, 0.066], [64644.9, 2.187], [64648.8, 0.252], [64658.9, 0.312], [64660.6, 0.213], [64664.8, 0.49], [64665.6, 0.169], [64671.0, 0.086], [64674.0, 0.015], [64680.0, 1.248]], "asks": [[64680.1, 44.816], [64681.2, 0.0], [64681.4, 0.005], [64683.1, 0.048], [64683.2, 0.0], [64685.1, 0.009], [64724.7, 0.834], [64751.8, 0.047], [64752.4, 7.709], [64816.0, 6.306], [65304.8, 0.0], [65326.9, 0.008], [65327.5, 2.746], [65340.3, 0.087], [65462.5, 8.244], [65598.6, 0.227], [65760.1, 1.745]]}
{"kind": "depth", "E": 1787080506919, "U": 11315359180159, "u": 11315359193109, "recv_ms": 1787080506872, "bids": [[1000.0, 35.81], [14180.0, 2.702], [14280.0, 1.498], [58212.0, 0.514], [61345.6, 0.285], [62092.8, 0.0], [63386.4, 0.035], [63612.8, 2.42], [63657.5, 7.395], [63754.6, 15.0], [63761.5, 0.482], [63858.7, 2.988], [64011.8, 0.0], [64033.2, 0.631], [64323.6, 0.005], [64329.7, 0.492], [64645.1, 0.094], [64680.0, 1.253]], "asks": [[64682.0, 0.012], [64697.0, 0.075], [64700.2, 3.226], [64700.5, 0.0], [64700.9, 0.544], [64709.3, 0.129], [64763.2, 2.559], [64948.8, 1.832], [65326.9, 0.008], [65435.2, 1.234], [65630.7, 21.721], [65727.8, 6.388], [65747.3, 1.073]]}
{"kind": "depth", "E": 1787080507021, "U": 11315359193278, "u": 11315359204556, "recv_ms": 1787080506973, "bids": [[1000.0, 35.81], [14180.0, 3.052], [14280.0, 1.148], [58212.0, 0.514], [61446.0, 0.066], [62092.8, 0.003], [63272.2, 0.0], [63677.5, 2.196], [63680.0, 1.759], [64033.2, 0.631], [64356.6, 0.321], [64411.8, 0.005], [64431.3, 1.002], [64540.0, 4.27], [64576.5, 1.003], [64582.8, 0.001], [64615.3, 1.901], [64622.2, 0.0], [64680.0, 1.251]], "asks": [[64680.4, 0.002], [64682.0, 0.012], [64683.1, 0.048], [64683.5, 0.021], [64821.0, 5.401], [64929.4, 0.008], [64948.9, 0.0], [64970.9, 0.002], [65010.5, 0.0], [65326.9, 0.008], [65449.8, 0.925], [65570.3, 10.354], [65624.4, 0.974], [65680.1, 0.0]]}
{"kind": "depth", "E": 1787080507123, "U": 11315359204764, "u": 11315359214901, "recv_ms": 1787080507081, "bids": [[14180.0, 3.416], [14280.0, 0.784], [58212.0, 0.514], [61446.0, 0.066], [62092.8, 0.0], [64000.9, 0.869], [64033.2, 0.631], [64542.9, 1.246], [64553.8, 0.09], [64601.3, 3.143], [64601.4, 2.348], [64608.5, 0.306], [64631.9, 0.312], [64632.1, 0.004], [64637.7, 0.007], [64637.8, 0.001], [64668.4, 0.002], [64670.7, 0.173], [64671.2, 0.31], [64673.1, 0.551], [64680.0, 1.253]], "asks": [[64680.1, 44.561], [64682.4, 0.181], [64682.6, 0.014], [64683.2, 0.0], [64685.3, 1.478], [64741.5, 0.033], [64741.6, 0.028], [64793.8, 1.084], [64800.1, 0.105], [64805.9, 0.026], [65003.5, 0.185], [65326.9, 0.008], [65435.9, 0.0], [65602.7, 55.967], [65635.0, 7.684], [65688.0, 11.632]]}
{"kind": "depth", "E": 1787080507225, "U": 11315359215326, "u": 11315359225331, "recv_ms": 1787080507181, "bids": [[1000.0, 35.81], [14180.0, 3.724], [14280.0, 0.448], [14580.0, 0.028], [51744.0, 0.002], [58212.0, 0.514], [61446.0, 0.066], [62092.8, 0.003], [63680.0, 1.779], [63747.4, 0.002], [63839.2, 0.711], [64033.2, 0.631], [64523.0, 7.646], [64532.2, 0.012], [64540.0, 4.307], [64553.8, 0.006], [64601.1, 1.715], [64608.3, 0.075], [64628.4, 0.001], [64628.5, 0.004], [64628.8, 1.123], [64631.8, 0.682], [64633.7, 0.028], [64637.6, 0.003], [64647.2, 0.198], [64647.7, 0.011], [64647.8, 1.004], [64648.1, 0.023], [64659.4, 0.122], [64660.0, 0.173], [64674.2, 0.17], [64675.9, 0.063], [64677.2, 1.811], [64677.3, 0.041], [64680.0, 1.231]], "asks": [[64680.1, 44.544], [64682.0, 0.018], [64683.2, 0.004], [64684.7, 0.061], [64684.9, 0.088], [64692.6, 6.239], [64695.3, 0.0], [64696.2, 0.925], [64696.4, 0.015], [64699.9, 0.607], [64700.9, 0.003], [64701.1, 0.711], [64713.4, 0.011], [64716.4, 0.003], [64729.9, 0.05], [64821.0, 5.401], [64835.2, 4.285], [64838.0, 10.623], [65326.9, 0.008], [65489.2, 8.736], [65553.3, 3.057], [65630.7, 20.656], [65680.1, 0.02], [65695.4, 8.36]]}
{"kind": "depth", "E": 1787080507327, "U": 11315359225349, "u": 11315359233562, "recv_ms": 1787080507285, "bids": [[14180.0, 3.71], [14280.0, 0.28], [14580.0, 0.21], [45284.9, 0.002], [51744.0, 0.0], [58212.0, 0.514], [63383.2, 0.0], [63398.8, 0.633], [63645.1, 3.295], [63742.1, 7.739], [63855.7, 8.678], [63922.8, 7.5], [64033.2, 0.631], [64356.6, 0.311], [64554.8, 0.1], [64578.8, 0.156], [64591.3, 0.007], [64657.7, 0.575], [64658.3, 0.0], [64662.6, 1.035], [64663.1, 0.312], [64663.6, 0.001], [64665.0, 3.526], [64667.0, 0.012], [64670.7, 0.721], [64673.1, 0.003], [64673.2, 0.085], [64673.3, 0.002], [64674.5, 0.01], [64675.9, 0.071], [64676.4, 0.057], [64676.8, 0.002], [64677.3, 0.033]], "asks": [[64680.1, 44.561], [64682.0, 0.02], [64683.2, 0.0], [64685.1, 0.009], [64687.1, 0.0], [64689.9, 0.541], [64691.1, 0.012], [64695.0, 2.78], [64696.1, 0.0], [64696.2, 0.0], [64696.3, 0.165], [64697.9, 0.022], [64699.2, 1.668], [64699.7, 0.541], [64699.9, 0.066], [64700.9, 0.003], [64701.0, 1.991], [64703.5, 6.03], [64714.7, 0.011], [65279.2, 13.689], [65326.9, 0.008], [65618.0, 9.062], [65715.0, 2.128]]}
{"kind": "depth", "E": 1787080507429, "U": 11315359233708, "u": 11315359243143, "recv_ms": 1787080507382, "bids": [[14180.0, 3.584], [14280.0, 0.168], [14580.0, 0.448], [51744.0, 0.0], [58212.0, 0.514], [61446.0, 0.066], [62092.8, 0.0], [63680.0, 1.759], [63697.0, 8.944], [63720.4, 0.0], [63740.1, 1.253], [63742.1, 8.679], [63828.0, 1.897], [64033.2, 0.631], [64136.6, 0.065], [64162.6, 3.941], [64453.2, 0.0], [64479.0, 0.007], [64504.9, 0.003], [64530.8, 0.005], [64564.5, 0.04], [64600.9, 0.343], [64602.3, 0.001], [64603.1, 1.552], [64605.3, 31.726], [64607.4, 1.687], [64615.3, 1.904], [64634.3, 0.001], [64634.7, 0.203], [64652.9, 0.048], [64654.5, 0.081], [64658.3, 0.007], [64659.3, 0.506], [64663.3, 0.329], [64663.6, 0.003], [64663.8, 0.019], [64664.1, 0.011], [64664.3, 0.01], [64664.7, 0.238], [64668.7, 0.02], [64670.5, 0.242], [64672.0, 0.979], [64674.5, 0.01], [64675.2, 0.211], [64675.7, 0.128], [64675.8, 1.906], [64675.9, 0.071], [64676.4, 0.034], [64676.6, 0.006], [64677.3, 0.033], [64680.0, 1.231]], "asks": [[64680.1, 44.562], [64680.8, 0.936], [64681.3, 2.001], [64682.2, 0.184], [64683.2, 0.004], [64684.5, 0.059], [64684.7, 0.002], [64685.1, 0.009], [64687.3, 0.007], [64689.9, 0.0], [64690.5, 0.546], [64696.1, 0.002], [64698.3, 0.043], [64699.7, 0.543], [64702.4, 1.253], [64740.5, 0.071], [64744.5, 0.001], [64759.9, 0.587], [65326.9, 0.008], [65401.2, 0.764], [65488.6, 3.831], [65489.2, 9.498], [65618.0, 10.127], [65680.1, 0.0], [65682.6, 3.268], [65973.7, 0.029]]}
{"kind": "depth", "E": 1787080507531, "U": 11315359243343, "u": 11315359253173, "recv_ms": 1787080507483, "bids": [[1000.0, 35.81], [14180.0, 3.472], [14280.0, 0.042], [14580.0, 0.686], [58212.0, 0.514], [61446.0, 0.068], [62092.8, 0.003], [63494.2, 0.013], [63871.5, 0.889], [64033.2, 0.631], [64427.3, 0.0], [64511.9, 0.684], [64590.6, 0.23], [64592.3, 0.0], [64642.6, 0.014], [64651.3, 0.494], [64651.7, 1.705], [64658.4, 0.618], [64663.8, 0.46], [64665.7, 0.779], [64667.3, 0.375], [64667.6, 0.025], [64679.9, 0.001], [64680.0, 1.292]], "asks": [[64680.1, 44.626], [64683.2, 0.0], [64684.1, 0.804], [64687.2, 0.31], [64688.1, 0.001], [64690.9, 0.16], [64691.2, 0.823], [64698.1, 0.559], [64698.7, 0.133], [64698.8, 0.45], [64699.0, 0.631], [64699.5, 0.732], [64702.0, 0.117], [64702.8, 0.021], [64706.4, 0.625], [64809.5, 0.008], [64821.0, 3.986], [64838.0, 6.786], [64876.8, 9.304], [65326.9, 0.008], [65595.3, 0.763]]}
{"kind": "depth", "E": 1787080507633, "U": 11315359253340, "u": 11315359273228, "recv_ms": 1787080507609, "bids": [[14180.0, 3.22], [14280.0, 0.0], [14579.1, 0.014], [14579.9, 0.014], [14580.0, 0.952], [58212.0, 0.514], [61446.0, 0.068], [62092.8, 0.0], [63515.8, 0.009], [63618.0, 0.594], [63657.5, 6.297], [63668.5, 0.672], [63680.0, 1.779], [63778.1, 0.087], [63910.3, 1.876], [64032.3, 3.096], [64033.2, 0.645], [64224.6, 0.011], [64232.8, 0.003], [64356.6, 0.311], [64362.1, 0.005], [64373.8, 0.012], [64382.5, 0.0], [64394.2, 0.001], [64435.7, 0.371], [64540.8, 0.009], [64544.2, 0.126], [64554.8, 0.013], [64557.5, 0.0], [64570.1, 0.001], [64571.3, 0.584], [64571.9, 0.032], [64572.0, 0.036], [64572.8, 0.006], [64575.0, 0.633], [64579.5, 0.0], [64581.3, 0.022], [64583.1, 0.002], [64583.4, 0.002], [64583.9, 0.005], [64586.4, 0.289], [64592.1, 31.752], [64596.5, 0.001], [64598.5, 0.003], [64599.0, 0.591], [64599.2, 0.002], [64599.5, 0.003], [64599.7, 0.002], [64600.6, 0.325], [64600.7, 0.582], [64600.9, 0.343], [64601.9, 0.324], [64602.1, 0.239], [64603.6, 4.251], [64605.3, 0.015], [64608.9, 0.005], [64609.0, 6.468], [64609.1, 0.039], [64609.6, 3.374], [64610.8, 0.051], [64611.0, 0.38], [64611.1, 5.844], [64611.2, 0.045], [64611.8, 1.252], [64611.9, 2.25], [64612.3, 0.416], [64612.6, 0.0], [64612.8, 1.192], [64612.9, 0.001], [64613.2, 0.019], [64614.0, 1.288], [64614.5, 0.0], [64615.6, 0.025], [64616.0, 3.437], [64617.3, 0.005], [64618.4, 0.978], [64618.7, 0.0], [64619.2, 1.201], [64619.4, 0.015], [64619.6, 0.002], [64620.1, 0.013], [64621.1, 0.022], [64621.4, 0.009], [64621.8, 0.003], [64622.2, 0.0], [64622.3, 0.0], [64622.7, 0.0], [64623.1, 6.382], [64623.3, 2.358], [64623.4, 2.57], [64623.5, 0.014], [64623.7, 0.057], [64624.8, 0.967], [64625.5, 0.001], [64626.3, 0.392], [64626.5, 0.115], [64626.8, 0.005], [64627.4, 0.006], [64628.0, 0.002], [64629.3, 0.012], [64629.9, 0.002], [64630.1, 1.049], [64630.4, 2.352], [64630.6, 0.337], [64631.3, 1.025], [64633.1, 0.023], [64633.7, 0.003], [64634.4, 0.001], [64634.8, 0.121], [64635.1, 0.311], [64635.3, 0.409], [64635.6, 1.123], [64635.8, 0.001], [64635.9, 0.032], [64637.3, 0.336], [64639.4, 0.19], [64640.9, 1.674], [64641.0, 1.315], [64641.5, 0.001], [64642.2, 0.061], [64643.3, 7.7], [64644.2, 0.031], [64646.2, 2.328], [64646.9, 0.326], [64648.1, 0.029], [64648.3, 0.044], [64648.4, 0.43], [64649.2, 0.006], [64649.6, 0.008], [64649.7, 0.017], [64650.0, 3.086], [64650.3, 0.001], [64650.6, 0.004], [64650.9, 0.057], [64651.1, 0.371], [64651.9, 2.441], [64652.8, 0.378], [64652.9, 0.057], [64653.4, 0.085], [64654.4, 1.255], [64654.6, 0.002], [64654.7, 0.016], [64655.5, 0.02], [64655.9, 0.104], [64657.0, 0.013], [64657.2, 0.002], [64657.5, 0.01], [64658.0, 1.443], [64658.2, 0.268], [64658.4, 0.0], [64658.5, 0.216], [64658.8, 0.009], [64659.0, 0.12], [64659.4, 0.006], [64659.5, 0.009], [64660.3, 4.885], [64660.4, 0.002], [64660.6, 0.132], [64660.7, 0.229], [64661.2, 0.0], [64662.7, 0.002], [64663.1, 0.323], [64665.0, 1.389], [64665.1, 1.05], [64665.2, 0.002], [64665.4, 0.065], [64665.6, 0.009], [64665.7, 0.161], [64666.0, 3.261], [64666.1, 0.157], [64666.2, 0.241], [64666.4, 0.002], [64666.5, 0.026], [64666.6, 0.049], [64666.7, 0.658], [64666.8, 0.467], [64666.9, 0.045], [64667.0, 0.002], [64667.1, 0.04], [64667.2, 0.313], [64667.3, 0.33], [64667.4, 0.001], [64667.6, 0.028], [64667.7, 0.53], [64667.9, 0.701], [64668.1, 0.085], [64668.8, 0.323], [64668.9, 0.003], [64669.1, 0.179], [64669.5, 0.088], [64669.7, 0.053], [64669.8, 0.004], [64669.9, 0.79], [64670.1, 0.002], [64670.2, 0.003], [64670.3, 0.001], [64670.6, 0.077], [64670.7, 0.321], [64671.0, 0.002], [64671.1, 0.049], [64671.2, 0.0], [64671.3, 0.001], [64671.6, 0.111], [64671.7, 0.172], [64672.0, 0.656], [64672.1, 0.001], [64672.2, 0.005], [64672.4, 0.008], [64672.7, 0.001], [64672.8, 0.002], [64673.0, 0.003], [64673.1, 0.551], [64673.2, 0.001], [64673.5, 0.005], [64673.6, 0.004], [64673.7, 0.048], [64673.9, 0.02], [64674.0, 0.005], [64674.2, 0.006], [64674.4, 0.006], [64674.5, 0.001], [64675.1, 0.07], [64675.2, 0.211], [64675.3, 0.201], [64675.7, 0.104], [64675.8, 0.072], [64675.9, 0.0], [64676.1, 0.0], [64676.6, 0.006], [64676.7, 0.033], [64676.8, 0.001], [64677.1, 0.0], [64677.2, 1.141], [64677.3, 0.0], [64677.4, 0.0], [64677.6, 0.0], [64677.7, 0.0], [64678.0, 0.0], [64678.1, 0.0], [64678.2, 0.0], [64678.4, 0.0], [64678.6, 0.0], [64678.8, 0.0], [64678.9, 0.0], [64679.0, 0.0], [64679.1, 0.0], [64679.5, 0.0], [64679.6, 0.0], [64679.7, 0.0], [64679.8, 0.0], [64679.9, 0.0], [64680.0, 0.0]], "asks": [[64677.3, 29.322], [64677.4, 7.847], [64677.5, 0.103], [64677.6, 0.001], [64677.8, 0.045], [64678.2, 1.047], [64678.3, 0.0], [64678.5, 1.418], [64678.7, 1.929], [64678.8, 0.001], [64678.9, 0.0], [64679.0, 1.421], [64679.1, 6.253], [64679.2, 20.523], [64679.3, 0.003], [64679.6, 0.987], [64679.7, 0.156], [64679.8, 3.267], [64679.9, 4.866], [64680.0, 27.496], [64680.1, 17.996], [64680.2, 0.005], [64680.4, 0.005], [64680.6, 0.025], [64681.0, 0.085], [64681.1, 0.0], [64681.3, 1.358], [64681.5, 0.084], [64681.6, 0.084], [64682.0, 0.009], [64682.2, 0.184], [64682.6, 0.006], [64682.8, 0.138], [64683.2, 0.016], [64683.7, 0.025], [64683.8, 0.008], [64683.9, 0.001], [64684.0, 0.086], [64684.1, 0.863], [64684.5, 0.001], [64684.6, 0.037], [64684.7, 0.002], [64685.1, 0.001], [64685.3, 1.453], [64685.7, 0.895], [64686.0, 1.03], [64686.1, 2.332], [64686.2, 0.001], [64686.4, 0.004], [64687.2, 0.001], [64687.3, 0.001], [64688.2, 0.398], [64688.4, 0.01], [64688.5, 2.887], [64688.6, 0.363], [64689.2, 0.133], [64689.5, 10.077], [64689.6, 0.059], [64689.8, 0.003], [64690.2, 0.023], [64690.3, 0.122], [64690.7, 0.001], [64690.8, 0.081], [64691.2, 0.78], [64691.5, 3.313], [64691.7, 0.606], [64691.8, 0.61], [64691.9, 1.405], [64692.0, 1.119], [64692.1, 0.671], [64692.2, 0.085], [64692.3, 0.0], [64692.4, 0.0], [64692.6, 6.043], [64693.0, 0.332], [64693.3, 0.6], [64693.6, 0.324], [64694.4, 0.016], [64694.9, 0.011], [64695.1, 0.005], [64695.5, 0.005], [64696.3, 0.174], [64696.4, 0.002], [64696.7, 2.649], [64696.8, 0.247], [64696.9, 0.226], [64697.3, 0.026], [64697.8, 0.02], [64697.9, 0.018], [64698.1, 0.557], [64698.5, 1.764], [64698.8, 0.443], [64699.0, 0.013], [64699.1, 0.002], [64699.5, 0.603], [64700.0, 1.439], [64700.4, 0.001], [64701.9, 0.038], [64702.8, 0.036], [64703.5, 6.032], [64703.8, 0.126], [64703.9, 0.281], [64704.0, 2.932], [64704.2, 0.155], [64705.0, 0.018], [64705.6, 1.194], [64705.7, 0.003], [64706.2, 0.023], [64706.4, 0.007], [64706.6, 0.258], [64706.9, 0.001], [64707.4, 0.024], [64707.5, 0.017], [64707.8, 0.001], [64707.9, 0.044], [64708.0, 0.106], [64708.9, 0.215], [64709.1, 0.138], [64709.7, 0.006], [64711.6, 0.041], [64715.1, 0.029], [64716.0, 0.147], [64716.3, 0.197], [64717.2, 0.001], [64719.5, 1.256], [64720.1, 2.321], [64722.8, 0.013], [64725.0, 0.026], [64727.6, 0.025], [64730.0, 1.936], [64730.1, 0.026], [64732.3, 0.019], [64732.9, 0.023], [64738.8, 0.003], [64739.1, 0.366], [64740.4, 0.005], [64741.6, 0.002], [64742.0, 0.086], [64751.1, 0.026], [64752.5, 0.0], [64754.4, 0.022], [64759.1, 0.021], [64759.3, 1.806], [64759.7, 0.001], [64760.0, 1.349], [64761.3, 0.005], [64763.5, 40.034], [64764.8, 0.226], [64772.1, 0.001], [64772.5, 0.015], [64772.6, 0.005], [64773.8, 0.22], [64781.0, 0.004], [64785.0, 0.1], [64794.7, 0.01], [64809.5, 0.007], [64815.8, 0.002], [64821.0, 3.48], [64821.4, 0.411], [64835.2, 2.703], [64838.0, 6.073], [64847.2, 0.772], [64856.9, 0.0], [64857.6, 1.255], [64858.8, 0.001], [64876.8, 6.988], [64877.5, 0.003], [64909.6, 0.003], [65264.8, 1.075], [65326.9, 0.012], [65473.3, 41.128], [65677.3, 2.971], [65679.2, 0.002], [65680.1, 0.02], [65683.4, 0.004], [65688.9, 0.001], [65689.0, 10.015]]}
{"kind": "depth", "E": 1787080507735, "U": 11315359273240, "u": 11315359308417, "recv_ms": 1787080507860, "bids": [[14180.0, 2.842], [14575.5, 0.182], [14575.7, 0.042], [14577.2, 0.126], [14579.1, 0.028], [14579.9, 0.028], [58207.9, 0.002], [58208.2, 0.0], [58209.4, 0.0], [58212.0, 0.512], [61441.7, 0.0], [61507.5, 0.356], [62060.0, 1.17], [62222.5, 0.804], [62384.9, 0.0], [62547.4, 0.001], [63382.0, 0.003], [63398.8, 0.63], [63473.1, 0.031], [63608.8, 0.188], [63673.8, 1.496], [63674.9, 0.626], [63680.0, 1.759], [63700.4, 0.301], [63709.2, 0.94], [63726.6, 0.674], [63737.9, 0.777], [63738.2, 3.107], [63738.5, 3.106], [63739.6, 11.497], [63773.9, 0.0], [63844.4, 0.017], [63899.6, 4.185], [63931.9, 3.149], [63935.3, 0.803], [63968.0, 0.033], [63998.3, 3.111], [64028.7, 0.0], [64028.9, 0.0], [64029.2, 1.855], [64030.4, 0.0], [64032.3, 0.002], [64033.2, 0.631], [64061.9, 5.1], [64065.1, 1.968], [64093.6, 4.635], [64093.9, 2.317], [64095.3, 4.647], [64097.4, 0.0], [64103.1, 2.338], [64129.8, 4.752], [64158.4, 0.001], [64165.2, 0.311], [64254.2, 0.259], [64258.4, 0.226], [64287.7, 0.002], [64294.6, 0.0], [64333.7, 0.116], [64336.7, 2.502], [64338.6, 0.0], [64352.4, 0.002], [64359.0, 5.002], [64371.0, 0.133], [64417.1, 0.007], [64424.0, 5.131], [64477.4, 0.005], [64478.2, 0.004], [64478.3, 2.146], [64479.3, 0.739], [64483.3, 0.001], [64484.2, 0.01], [64491.5, 0.001], [64492.9, 0.001], [64496.1, 0.001], [64516.3, 0.0], [64517.0, 0.135], [64517.2, 5.935], [64518.4, 2.805], [64523.0, 0.496], [64533.2, 0.418], [64534.0, 0.422], [64534.1, 3.692], [64536.7, 0.96], [64538.6, 0.032], [64540.0, 0.224], [64541.8, 0.003], [64545.4, 0.307], [64546.4, 0.015], [64549.8, 0.002], [64550.3, 0.065], [64550.6, 0.086], [64551.3, 0.0], [64552.3, 1.237], [64553.0, 0.018], [64561.6, 1.181], [64566.8, 1.297], [64568.6, 2.319], [64572.8, 0.0], [64573.0, 0.047], [64573.7, 0.017], [64576.3, 0.01], [64578.4, 1.756], [64579.6, 5.532], [64579.7, 0.004], [64581.3, 0.017], [64581.5, 0.001], [64582.7, 0.03], [64583.3, 0.093], [64584.7, 0.147], [64585.3, 0.018], [64585.5, 31.712], [64585.6, 6.109], [64586.1, 0.005], [64587.3, 6.958], [64587.7, 0.016], [64587.8, 0.2], [64588.8, 3.209], [64590.3, 0.005], [64590.4, 2.972], [64591.1, 0.02], [64591.7, 0.677], [64592.1, 0.041], [64593.1, 0.001], [64594.4, 0.072], [64595.1, 0.023], [64595.2, 1.545], [64599.0, 0.57], [64599.1, 0.028], [64599.5, 0.374], [64600.1, 0.17], [64600.7, 0.682], [64600.9, 0.343], [64601.2, 4.058], [64601.3, 3.144], [64606.5, 0.032], [64607.2, 1.913], [64607.5, 0.509], [64607.7, 0.014], [64607.8, 0.003], [64608.6, 0.041], [64609.0, 6.476], [64609.1, 0.013], [64610.8, 0.074], [64611.1, 2.559], [64611.2, 0.0], [64611.4, 0.0], [64612.3, 0.206], [64612.7, 0.177], [64612.8, 1.193], [64613.6, 1.349], [64613.8, 0.04], [64614.0, 1.263], [64614.1, 0.003], [64615.0, 2.367], [64615.3, 1.502], [64615.5, 0.095], [64615.9, 0.025], [64616.2, 0.005], [64616.6, 0.027], [64616.9, 0.329], [64617.0, 0.033], [64617.4, 0.005], [64617.7, 2.335], [64618.7, 0.0], [64619.0, 0.175], [64619.1, 0.318], [64619.4, 0.033], [64619.5, 0.591], [64620.0, 2.791], [64620.1, 0.015], [64620.6, 6.031], [64621.3, 0.002], [64621.5, 0.134], [64621.6, 0.059], [64621.7, 0.014], [64623.1, 6.373], [64623.3, 2.338], [64623.5, 0.0], [64623.7, 0.037], [64623.8, 0.077], [64624.0, 1.258], [64624.3, 0.047], [64625.1, 0.008], [64625.9, 0.003], [64626.3, 0.385], [64626.4, 0.02], [64626.5, 0.015], [64626.6, 0.007], [64626.8, 0.009], [64627.1, 2.39], [64628.3, 0.0], [64628.4, 0.028], [64628.5, 0.467], [64628.8, 1.117], [64629.3, 0.006], [64629.5, 0.034], [64629.9, 1.918], [64630.5, 0.01], [64630.6, 0.001], [64630.8, 1.704], [64630.9, 0.001], [64631.0, 0.035], [64631.1, 0.31], [64632.6, 0.0], [64632.7, 0.003], [64633.7, 0.014], [64634.1, 0.062], [64634.8, 0.001], [64635.1, 0.311], [64635.5, 3.56], [64635.7, 0.159], [64635.9, 0.101], [64636.1, 0.001], [64636.2, 0.001], [64636.3, 0.016], [64636.5, 0.001], [64636.7, 0.336], [64636.8, 0.003], [64636.9, 0.824], [64637.1, 0.149], [64637.2, 0.019], [64637.3, 0.0], [64637.5, 0.03], [64637.8, 0.002], [64638.4, 1.093], [64639.1, 0.522], [64639.3, 0.003], [64639.4, 0.1], [64639.8, 0.003], [64640.0, 0.417], [64640.1, 0.004], [64640.2, 0.082], [64640.4, 0.161], [64641.7, 0.071], [64641.8, 0.031], [64642.2, 0.001], [64642.3, 0.002], [64642.4, 1.628], [64642.8, 0.034], [64643.2, 2.818], [64643.3, 9.932], [64643.4, 0.307], [64643.5, 0.067], [64643.6, 0.441], [64643.7, 0.065], [64643.9, 0.015], [64644.0, 0.157], [64644.1, 0.0], [64644.7, 1.762], [64645.7, 0.161], [64645.8, 0.001], [64645.9, 0.0], [64646.1, 0.125], [64646.4, 0.091], [64646.6, 0.018], [64646.7, 0.444], [64646.8, 0.005], [64647.2, 0.101], [64647.3, 0.005], [64647.4, 0.032], [64647.6, 0.036], [64647.7, 0.036], [64647.9, 0.029], [64648.0, 2.177], [64648.1, 0.023], [64648.2, 0.347], [64648.3, 0.007], [64648.4, 0.709], [64648.5, 0.07], [64648.8, 0.332], [64648.9, 0.309], [64649.2, 0.467], [64649.3, 0.0], [64649.4, 0.036], [64649.7, 0.002], [64649.9, 3.169], [64650.0, 3.203], [64650.1, 0.018], [64650.2, 0.45], [64650.4, 0.629], [64650.7, 2.935], [64650.9, 0.255], [64651.3, 0.186], [64651.6, 2.242], [64651.7, 0.003], [64651.9, 2.517], [64652.2, 0.003], [64652.3, 0.192], [64652.4, 0.396], [64652.5, 0.054], [64652.6, 0.12], [64652.7, 0.0], [64652.8, 0.392], [64652.9, 0.039], [64653.1, 0.192], [64653.2, 0.791], [64653.4, 0.089], [64653.6, 0.007], [64653.7, 0.044], [64653.8, 0.004], [64653.9, 2.811], [64654.0, 0.006], [64654.2, 1.999], [64654.3, 0.009], [64654.5, 0.001], [64654.6, 0.002], [64654.7, 0.117], [64655.1, 0.405], [64655.2, 0.463], [64655.6, 0.239], [64656.0, 1.614], [64656.1, 0.101], [64656.2, 0.275], [64656.3, 0.18], [64656.4, 0.17], [64656.5, 0.002], [64656.6, 0.072], [64656.7, 0.182], [64656.8, 0.0], [64656.9, 0.312], [64657.1, 0.444], [64657.3, 0.0], [64657.4, 0.0], [64657.5, 0.003], [64657.6, 1.619], [64657.7, 0.142], [64657.9, 0.466], [64658.2, 0.037], [64658.3, 0.463], [64658.7, 0.053], [64658.9, 0.017], [64659.0, 0.004], [64659.2, 1.432], [64659.3, 0.007], [64659.5, 0.465], [64659.6, 0.013], [64659.7, 0.039], [64659.8, 0.466], [64659.9, 2.169], [64660.0, 0.173], [64660.3, 2.755], [64660.5, 0.932], [64660.6, 0.343], [64660.7, 0.384], [64660.8, 0.002], [64660.9, 2.335], [64661.0, 0.923], [64661.1, 0.152], [64661.4, 0.321], [64661.5, 0.083], [64661.7, 0.0], [64661.8, 0.0], [64662.0, 0.024], [64662.3, 2.218], [64662.4, 0.679], [64662.5, 0.006], [64662.6, 0.109], [64662.8, 0.008], [64662.9, 0.199], [64663.2, 0.002], [64663.3, 0.597], [64663.4, 0.0], [64663.5, 0.001], [64663.6, 0.126], [64664.0, 0.118], [64664.2, 0.015], [64664.3, 0.005], [64664.4, 0.001], [64664.6, 0.197], [64664.7, 0.313], [64664.8, 0.004], [64665.0, 0.911], [64665.1, 0.77], [64665.4, 0.0], [64665.5, 0.047], [64665.6, 0.009], [64665.7, 0.161], [64665.8, 0.0], [64665.9, 0.058], [64666.0, 3.103], [64666.1, 0.005], [64666.2, 0.24], [64666.3, 0.643], [64666.4, 0.002], [64666.5, 0.027], [64666.6, 0.049], [64666.7, 0.66], [64666.8, 0.004], [64666.9, 0.001], [64667.0, 0.086], [64667.1, 0.0], [64667.2, 0.313], [64667.3, 0.127], [64667.6, 0.025], [64667.7, 0.151], [64667.8, 0.051], [64667.9, 0.001], [64668.0, 0.085], [64668.1, 0.085], [64668.2, 1.091], [64668.3, 0.542], [64668.4, 0.086], [64668.6, 0.002], [64668.8, 0.324], [64669.0, 0.002], [64669.1, 0.087], [64669.2, 0.002], [64669.5, 0.004], [64669.6, 0.022], [64669.7, 0.137], [64669.8, 0.453], [64669.9, 0.255], [64670.0, 1.355], [64670.1, 0.156], [64670.2, 1.813], [64670.3, 0.009], [64670.4, 0.004], [64670.6, 0.0], [64670.7, 0.002], [64670.8, 0.064], [64670.9, 0.0], [64671.0, 0.001], [64671.1, 0.009], [64671.2, 0.001], [64671.3, 1.728], [64671.4, 0.009], [64671.7, 0.178], [64671.8, 0.007], [64671.9, 0.015], [64672.0, 0.036], [64672.1, 0.02], [64672.2, 0.005], [64672.5, 0.002], [64672.7, 0.0], [64672.9, 0.002], [64673.1, 0.003], [64673.2, 0.002], [64673.3, 0.013], [64673.4, 0.008], [64673.5, 0.007], [64673.6, 0.033], [64673.7, 0.047], [64674.0, 0.002], [64674.1, 0.016], [64674.2, 0.0], [64674.3, 0.154], [64674.4, 0.0], [64674.5, 0.0], [64674.6, 0.002], [64674.8, 0.072], [64675.0, 0.153], [64675.2, 0.21], [64675.3, 0.201], [64675.4, 0.072], [64675.5, 2.643], [64675.6, 0.0], [64675.7, 0.0], [64675.8, 0.0], [64676.0, 0.0], [64676.3, 0.0], [64676.4, 0.0], [64676.6, 0.0], [64676.7, 0.0], [64676.8, 0.0], [64676.9, 0.0], [64677.0, 0.0], [64677.2, 0.0]], "asks": [[64675.6, 36.56], [64675.7, 0.007], [64675.8, 1.07], [64675.9, 0.477], [64676.0, 0.083], [64676.1, 0.0], [64676.2, 0.492], [64676.3, 0.0], [64676.4, 0.0], [64676.5, 0.001], [64676.7, 0.007], [64676.8, 0.08], [64676.9, 0.0], [64677.0, 0.0], [64677.1, 0.024], [64677.2, 2.5], [64677.3, 6.893], [64677.4, 2.772], [64677.5, 1.002], [64677.6, 0.001], [64677.8, 0.0], [64677.9, 0.109], [64678.0, 0.002], [64678.1, 0.0], [64678.2, 0.0], [64678.3, 0.002], [64678.4, 0.002], [64678.5, 0.0], [64678.6, 0.104], [64678.7, 0.451], [64678.8, 1.999], [64678.9, 0.001], [64679.0, 0.003], [64679.1, 2.517], [64679.2, 0.822], [64679.4, 0.0], [64679.5, 0.001], [64679.6, 0.001], [64679.7, 0.237], [64679.8, 0.0], [64679.9, 0.004], [64680.0, 4.296], [64680.1, 9.216], [64680.2, 0.002], [64680.3, 0.001], [64680.4, 0.041], [64680.6, 0.001], [64680.7, 0.313], [64680.8, 0.856], [64680.9, 0.003], [64681.1, 0.001], [64681.3, 0.011], [64681.5, 0.072], [64681.6, 0.005], [64681.7, 0.394], [64681.8, 0.0], [64682.0, 0.895], [64682.1, 0.0], [64682.2, 0.201], [64682.3, 0.002], [64682.4, 0.643], [64682.5, 0.342], [64682.6, 0.005], [64682.7, 0.003], [64682.8, 0.145], [64683.0, 0.155], [64683.1, 0.049], [64683.2, 0.024], [64683.3, 2.415], [64683.5, 0.002], [64683.7, 0.004], [64683.8, 0.023], [64684.0, 0.087], [64684.1, 1.399], [64684.2, 0.251], [64684.3, 0.001], [64684.5, 0.001], [64684.6, 0.345], [64684.7, 0.002], [64684.8, 0.009], [64684.9, 0.005], [64685.0, 0.001], [64685.1, 0.5], [64685.3, 1.381], [64685.4, 0.004], [64685.6, 0.001], [64685.7, 0.895], [64685.8, 0.303], [64686.4, 0.136], [64686.5, 0.016], [64686.6, 0.003], [64687.0, 0.002], [64687.2, 0.004], [64687.3, 0.154], [64687.4, 0.26], [64687.7, 0.001], [64687.8, 0.001], [64687.9, 0.078], [64688.0, 0.909], [64688.1, 0.016], [64688.2, 0.598], [64688.3, 0.0], [64688.4, 0.01], [64688.5, 2.615], [64688.6, 0.002], [64688.7, 0.417], [64689.0, 0.382], [64689.1, 0.053], [64689.4, 0.0], [64689.5, 0.002], [64689.6, 0.054], [64689.9, 0.007], [64690.1, 0.002], [64690.2, 0.156], [64690.3, 1.897], [64690.5, 0.005], [64690.8, 0.081], [64690.9, 0.045], [64691.0, 10.902], [64691.1, 0.004], [64691.2, 0.772], [64691.3, 0.805], [64691.5, 3.313], [64691.7, 0.356], [64691.8, 0.263], [64691.9, 1.405], [64692.2, 0.085], [64692.4, 0.003], [64692.6, 6.043], [64692.7, 3.206], [64692.8, 1.165], [64692.9, 1.96], [64693.0, 0.261], [64693.1, 0.007], [64693.2, 0.004], [64693.3, 0.025], [64693.5, 0.004], [64693.8, 0.002], [64694.2, 0.022], [64694.9, 0.001], [64695.0, 1.109], [64695.3, 0.66], [64695.4, 0.001], [64695.5, 0.0], [64695.7, 0.003], [64695.9, 0.001], [64696.0, 1.36], [64696.3, 0.165], [64696.4, 0.092], [64696.6, 0.573], [64696.7, 2.32], [64696.9, 0.224], [64697.5, 0.009], [64697.7, 0.024], [64697.9, 0.001], [64698.0, 0.138], [64698.1, 0.0], [64698.2, 0.446], [64698.3, 0.584], [64698.4, 1.661], [64698.5, 1.761], [64698.7, 0.0], [64698.9, 0.146], [64699.2, 2.149], [64699.3, 0.38], [64699.4, 0.091], [64699.5, 0.131], [64699.7, 0.002], [64699.9, 0.009], [64700.4, 0.041], [64700.8, 0.008], [64701.1, 0.714], [64701.8, 0.124], [64701.9, 0.053], [64702.0, 0.001], [64702.3, 0.002], [64702.5, 0.004], [64702.8, 0.021], [64703.0, 0.011], [64703.3, 0.059], [64703.4, 0.402], [64703.9, 0.121], [64704.0, 2.158], [64704.2, 0.001], [64704.6, 0.241], [64705.4, 0.073], [64705.5, 1.264], [64705.6, 1.19], [64705.7, 0.009], [64706.0, 0.054], [64706.1, 0.002], [64706.6, 0.252], [64707.4, 0.015], [64707.9, 0.047], [64708.1, 0.062], [64708.7, 0.003], [64709.2, 0.002], [64709.4, 0.143], [64709.5, 1.886], [64709.9, 0.009], [64710.0, 0.02], [64712.1, 1.249], [64712.3, 0.121], [64713.2, 0.224], [64713.4, 0.001], [64714.4, 0.457], [64714.5, 1.903], [64714.6, 0.464], [64714.7, 0.001], [64714.8, 3.541], [64715.1, 0.002], [64715.5, 0.038], [64716.0, 0.087], [64716.5, 0.034], [64716.6, 0.003], [64717.2, 0.041], [64717.9, 0.002], [64719.1, 0.191], [64720.2, 0.0], [64720.5, 0.033], [64720.6, 0.001], [64720.9, 1.529], [64721.0, 0.011], [64721.1, 0.508], [64721.4, 0.06], [64721.5, 0.0], [64721.6, 1.359], [64722.1, 0.056], [64722.7, 2.823], [64723.3, 0.52], [64723.8, 0.019], [64723.9, 0.0], [64724.4, 0.0], [64725.9, 0.049], [64727.5, 0.0], [64727.6, 0.0], [64728.1, 0.501], [64728.9, 2.13], [64729.0, 0.004], [64729.1, 0.024], [64729.9, 0.041], [64730.0, 1.933], [64730.1, 0.007], [64730.6, 0.486], [64731.5, 0.056], [64734.3, 0.005], [64735.7, 0.033], [64735.9, 0.295], [64736.6, 0.003], [64737.0, 0.002], [64737.4, 0.0], [64738.9, 0.001], [64740.4, 0.002], [64740.5, 0.171], [64740.6, 2.341], [64742.8, 0.001], [64743.0, 0.002], [64743.1, 0.01], [64743.4, 0.002], [64744.7, 0.069], [64745.0, 2.353], [64745.1, 1.003], [64745.2, 0.002], [64745.5, 0.242], [64746.1, 0.023], [64747.3, 0.072], [64747.5, 0.001], [64747.6, 0.367], [64748.0, 0.458], [64751.1, 0.0], [64751.2, 0.03], [64751.7, 0.297], [64752.4, 1.685], [64753.2, 0.047], [64753.3, 2.421], [64753.5, 0.121], [64753.7, 0.0], [64754.4, 0.022], [64754.6, 0.403], [64756.0, 2.735], [64757.0, 0.317], [64757.4, 0.152], [64757.8, 0.025], [64758.0, 0.001], [64758.2, 0.0], [64759.3, 1.732], [64759.7, 0.03], [64759.9, 0.442], [64760.0, 1.277], [64761.4, 0.541], [64762.2, 7.659], [64763.0, 0.597], [64763.1, 0.2], [64763.2, 3.538], [64764.8, 0.22], [64764.9, 1.081], [64767.6, 2.803], [64768.8, 0.003], [64769.0, 0.065], [64769.1, 0.216], [64769.9, 0.001], [64770.6, 0.375], [64771.4, 0.021], [64772.6, 0.032], [64772.7, 2.322], [64775.9, 0.011], [64777.8, 0.778], [64779.3, 0.027], [64780.7, 0.002], [64780.9, 0.87], [64782.3, 2.885], [64785.5, 2.346], [64785.8, 0.0], [64786.1, 0.022], [64793.3, 2.214], [64793.4, 0.023], [64793.6, 0.13], [64795.2, 4.251], [64798.6, 0.356], [64799.2, 0.0], [64800.1, 0.018], [64801.6, 6.539], [64801.7, 0.012], [64803.7, 0.458], [64803.8, 0.382], [64805.3, 0.001], [64806.9, 0.003], [64807.2, 0.02], [64808.4, 2.319], [64810.0, 2.917], [64810.1, 0.0], [64811.9, 0.018], [64819.7, 2.807], [64835.2, 4.161], [64836.4, 4.496], [64839.3, 1.465], [64839.4, 0.0], [64845.2, 0.003], [64845.4, 0.0], [64848.3, 0.003], [64851.5, 0.003], [64853.2, 1.465], [64853.3, 0.002], [64856.1, 0.004], [64869.5, 4.437], [64869.9, 0.019], [64871.9, 1.47], [64872.8, 8.848], [64874.0, 0.0], [64874.4, 1.209], [64875.4, 0.0], [64876.5, 0.02], [64876.8, 0.016], [64877.7, 3.251], [64881.4, 0.005], [64881.5, 0.0], [64883.4, 0.904], [64883.5, 0.0], [64899.7, 0.002], [64934.6, 0.002], [64941.2, 0.001], [64972.7, 0.0], [64973.0, 0.111], [64976.0, 0.016], [64979.3, 3.692], [64999.3, 0.002], [65005.9, 0.002], [65032.2, 0.001], [65064.0, 0.025], [65070.6, 0.003], [65128.6, 0.001], [65135.3, 0.004], [65193.3, 0.001], [65200.0, 136.8], [65322.4, 0.006], [65322.6, 0.0], [65322.7, 0.0], [65324.1, 0.012], [65326.9, 0.008], [65675.6, 0.006], [65675.8, 0.008], [65675.9, 0.004], [65677.3, 2.973], [65679.2, 0.004], [65680.1, 0.0], [65682.2, 0.769], [65683.3, 0.007], [65683.4, 0.0], [65727.8, 5.324], [65969.1, 0.008]]}
{"kind": "depth", "E": 1787080507837, "U": 11315359308595, "u": 11315359328788, "recv_ms": 1787080507879, "bids": [[1000.0, 35.81], [14180.0, 2.492], [14575.5, 0.532], [51740.0, 0.0], [58207.9, 0.002], [61441.7, 0.0], [62088.4, 0.003], [63605.2, 0.0], [63640.9, 1.099], [63689.9, 4.705], [63757.3, 0.48], [63980.4, 4.366], [64028.3, 0.387], [64028.7, 0.002], [64032.7, 1.572], [64062.3, 0.0], [64093.6, 6.952], [64093.9, 4.634], [64129.8, 2.417], [64356.6, 0.31], [64474.4, 2.25], [64478.3, 0.144], [64479.3, 0.501], [64492.9, 0.0], [64513.2, 6.476], [64517.2, 0.077], [64518.4, 1.161], [64530.2, 6.364], [64531.9, 0.8], [64534.1, 0.0], [64549.0, 0.843], [64549.4, 0.0], [64550.2, 3.858], [64564.1, 6.84], [64575.4, 0.0], [64579.3, 0.849], [64584.5, 0.014], [64585.5, 0.001], [64585.6, 1.374], [64589.1, 0.001], [64592.1, 31.752], [64595.2, 5.699], [64596.0, 0.077], [64598.0, 11.212], [64602.6, 0.046], [64605.4, 0.035], [64609.4, 0.001], [64610.2, 0.146], [64625.9, 0.118], [64628.1, 0.107], [64630.1, 1.164], [64630.2, 0.585], [64632.2, 0.503], [64632.9, 0.064], [64633.6, 0.03], [64633.7, 0.073], [64634.2, 0.033], [64634.7, 0.018], [64634.8, 0.002], [64635.4, 0.01], [64637.2, 0.001], [64637.4, 0.094], [64638.2, 0.0], [64638.3, 0.125], [64643.4, 0.364], [64643.5, 0.005], [64644.7, 1.705], [64644.8, 1.165], [64646.0, 0.006], [64646.3, 0.843], [64646.4, 0.042], [64646.6, 0.028], [64647.4, 0.006], [64647.7, 0.026], [64648.9, 0.0], [64649.9, 3.178], [64650.2, 0.441], [64650.9, 0.14], [64651.1, 0.531], [64653.2, 0.793], [64653.6, 0.056], [64654.6, 0.0], [64655.6, 0.079], [64655.9, 0.536], [64657.6, 1.504], [64659.2, 2.358], [64660.5, 0.006], [64660.9, 2.682], [64661.0, 0.023], [64661.4, 0.32], [64662.0, 0.924], [64662.4, 0.208], [64662.5, 0.469], [64662.6, 0.117], [64663.0, 0.011], [64663.1, 0.447], [64663.4, 0.0], [64665.6, 0.008], [64666.1, 0.005], [64666.2, 0.24], [64666.3, 0.094], [64666.5, 0.047], [64666.8, 0.545], [64666.9, 0.55], [64668.3, 0.001], [64668.7, 0.0], [64668.8, 0.097], [64669.2, 0.234], [64669.6, 0.027], [64670.2, 1.812], [64670.3, 0.001], [64670.4, 0.088], [64671.1, 0.0], [64671.4, 0.017], [64671.5, 0.012], [64671.8, 0.001], [64672.0, 0.013], [64672.1, 0.001], [64672.4, 0.0], [64672.5, 0.034], [64673.4, 0.002], [64675.5, 1.861]], "asks": [[64675.6, 38.129], [64675.7, 0.008], [64675.8, 0.158], [64675.9, 0.105], [64676.1, 0.835], [64676.2, 0.494], [64677.1, 0.565], [64677.2, 2.5], [64677.3, 1.074], [64678.1, 0.019], [64678.2, 0.023], [64678.6, 0.104], [64678.7, 0.451], [64678.8, 1.999], [64679.0, 0.098], [64679.2, 0.408], [64679.5, 0.002], [64680.0, 4.413], [64680.1, 9.051], [64680.3, 0.001], [64680.8, 0.0], [64681.0, 0.985], [64682.1, 0.002], [64682.4, 0.548], [64682.6, 0.003], [64683.1, 0.396], [64684.9, 0.002], [64685.0, 0.001], [64685.3, 1.401], [64685.8, 0.323], [64686.0, 1.93], [64686.2, 0.349], [64686.7, 0.05], [64686.8, 0.16], [64687.0, 0.465], [64687.1, 0.0], [64687.4, 0.252], [64687.5, 0.011], [64687.7, 0.085], [64688.0, 1.0], [64689.3, 0.25], [64689.7, 0.448], [64690.3, 1.898], [64690.4, 0.092], [64690.5, 0.216], [64690.6, 0.002], [64691.6, 0.121], [64691.9, 1.328], [64692.8, 1.145], [64693.1, 0.005], [64694.9, 0.002], [64695.0, 0.206], [64695.4, 0.234], [64696.0, 2.31], [64696.4, 0.633], [64696.7, 2.319], [64698.0, 0.118], [64698.3, 0.043], [64698.4, 1.621], [64698.7, 0.05], [64701.2, 0.0], [64701.6, 0.141], [64702.1, 0.001], [64704.0, 1.258], [64706.0, 0.004], [64708.8, 1.187], [64709.3, 0.154], [64710.0, 0.204], [64710.8, 1.764], [64711.8, 0.031], [64713.5, 0.314], [64715.8, 0.001], [64716.0, 0.297], [64716.3, 0.167], [64716.5, 0.009], [64718.9, 0.159], [64719.1, 0.035], [64721.6, 1.358], [64723.3, 0.31], [64737.3, 0.065], [64740.4, 0.012], [64741.2, 0.013], [64741.5, 0.023], [64741.8, 0.0], [64745.0, 2.399], [64749.3, 1.807], [64750.3, 0.002], [64751.8, 0.001], [64752.4, 7.486], [64754.7, 46.034], [64759.1, 0.021], [64762.2, 1.691], [64763.5, 0.0], [64795.2, 4.139], [64804.9, 0.028], [64809.4, 0.121], [64813.5, 3.361], [64816.5, 4.679], [64817.0, 3.269], [64821.0, 0.002], [64824.0, 1.192], [64833.5, 0.103], [64834.0, 5.504], [64835.2, 3.451], [64838.0, 0.212], [64839.1, 0.308], [64842.3, 0.039], [64842.6, 0.0], [64848.4, 0.001], [64851.6, 0.128], [64852.7, 0.0], [64869.5, 0.008], [64872.3, 0.001], [64872.8, 6.131], [64973.0, 0.768], [64974.6, 4.55], [65030.0, 0.712], [65062.8, 0.27], [65064.1, 0.003], [65069.5, 0.0], [65098.2, 0.008], [65322.4, 0.006], [65424.5, 1.817], [65424.6, 12.713], [65630.7, 19.592], [65695.4, 7.297], [65715.0, 3.192], [65802.0, 1.528], [65969.1, 0.011]]}
{"kind": "depth", "E": 1787080507939, "U": 11315359328831, "u": 11315359342021, "recv_ms": 1787080507895, "bids": [[14180.0, 2.128], [14575.5, 0.896], [58207.9, 0.002], [61441.7, 0.0], [62088.4, 0.0], [63382.0, 0.009], [63449.3, 4.25], [63675.5, 0.02], [63809.4, 0.0], [64028.7, 0.004], [64314.3, 0.492], [64329.7, 0.0], [64356.6, 0.31], [64377.8, 0.133], [64407.7, 0.0], [64474.4, 0.0], [64474.8, 12.982], [64558.9, 0.01], [64565.9, 0.663], [64572.8, 0.03], [64592.1, 0.041], [64595.2, 1.545], [64596.0, 0.05], [64600.9, 0.343], [64601.2, 4.058], [64603.1, 33.263], [64604.4, 7.535], [64605.1, 0.0], [64605.4, 0.003], [64605.7, 0.132], [64606.1, 3.585], [64613.9, 0.039], [64614.7, 0.016], [64627.4, 0.024], [64631.6, 0.045], [64632.2, 0.501], [64633.6, 0.029], [64636.5, 0.101], [64640.0, 0.517], [64643.7, 0.015], [64643.8, 1.724], [64646.0, 0.016], [64646.4, 0.04], [64646.6, 0.018], [64648.8, 0.335], [64650.9, 0.19], [64658.2, 0.357], [64658.4, 0.926], [64659.2, 1.432], [64661.4, 0.0], [64662.4, 0.362], [64662.6, 0.109], [64662.7, 0.002], [64663.3, 0.595], [64664.6, 0.195], [64664.7, 0.311], [64665.2, 0.543], [64665.6, 0.009], [64665.9, 0.056], [64666.0, 3.101], [64666.1, 0.005], [64666.3, 0.095], [64666.4, 0.55], [64666.8, 0.012], [64666.9, 0.001], [64667.0, 0.086], [64667.4, 0.002], [64668.8, 0.098], [64670.3, 0.001], [64671.2, 0.024], [64671.4, 0.037], [64671.6, 0.211], [64671.8, 0.101], [64672.1, 0.0], [64672.2, 0.037], [64672.9, 0.034], [64673.2, 0.033], [64675.5, 1.878]], "asks": [[64675.6, 38.06], [64676.7, 0.0], [64676.8, 0.081], [64677.0, 0.007], [64677.5, 1.002], [64678.1, 0.0], [64678.2, 0.0], [64678.6, 0.119], [64678.7, 0.366], [64679.9, 0.081], [64680.1, 9.037], [64680.2, 0.005], [64683.1, 0.359], [64684.1, 1.041], [64686.1, 2.367], [64686.4, 0.178], [64687.0, 0.507], [64687.3, 0.0], [64687.4, 0.412], [64687.5, 0.003], [64687.6, 0.151], [64688.3, 0.077], [64688.4, 0.018], [64689.2, 0.135], [64689.3, 0.252], [64689.9, 0.007], [64690.3, 1.856], [64690.9, 0.97], [64692.2, 0.008], [64692.9, 1.035], [64699.2, 1.199], [64704.4, 0.016], [64704.5, 2.321], [64704.6, 0.243], [64707.4, 0.017], [64707.5, 0.019], [64707.6, 0.663], [64708.2, 0.032], [64708.3, 0.057], [64708.4, 1.437], [64708.9, 0.213], [64709.0, 0.161], [64709.1, 0.136], [64709.4, 2.028], [64709.5, 0.001], [64710.0, 0.202], [64710.1, 0.001], [64710.5, 0.115], [64710.6, 0.132], [64710.7, 1.982], [64711.3, 0.327], [64711.4, 0.025], [64711.9, 0.0], [64712.0, 1.246], [64712.1, 1.247], [64712.6, 0.0], [64712.7, 0.004], [64712.8, 0.001], [64712.9, 0.003], [64715.0, 0.001], [64715.1, 0.0], [64715.2, 1.252], [64720.0, 0.153], [64720.6, 0.0], [64720.9, 1.528], [64726.2, 1.241], [64739.8, 0.015], [64740.4, 0.002], [64749.3, 7.158], [64750.3, 40.034], [64752.4, 1.685], [64754.7, 6.0], [64787.0, 0.0], [64816.5, 8.238], [64817.0, 0.015], [64832.5, 3.133], [64833.5, 6.24], [64834.0, 0.029], [64851.6, 0.127], [64999.0, 3.667], [65322.4, 0.004], [65421.6, 0.908], [65421.7, 0.909], [65424.5, 0.001], [65641.5, 1.228], [65675.6, 0.026], [71143.2, 0.008]]}
{"kind": "depth", "E": 1787080508041, "U": 11315359342034, "u": 11315359352659, "recv_ms": 1787080507993, "bids": [[14180.0, 1.778], [14575.5, 1.246], [58207.9, 0.002], [61441.7, 0.0], [62088.4, 0.003], [63673.0, 1.099], [63716.2, 0.784], [63787.5, 0.012], [64028.7, 0.002], [64353.8, 0.13], [64367.4, 0.184], [64589.1, 0.004], [64590.3, 0.002], [64596.5, 31.838], [64603.1, 1.552], [64607.4, 1.685], [64636.6, 0.171], [64636.8, 0.073], [64643.2, 2.819], [64653.7, 0.045], [64656.3, 0.08], [64658.0, 1.343], [64663.9, 0.006], [64665.2, 1.78], [64666.4, 0.543], [64667.0, 0.002], [64667.3, 0.043], [64667.5, 0.014], [64669.2, 0.002], [64669.8, 0.607], [64670.0, 1.355], [64670.3, 0.009], [64670.4, 0.32], [64670.8, 0.148], [64671.4, 0.106], [64671.7, 0.278], [64671.8, 0.179], [64671.9, 0.093], [64674.3, 0.0], [64675.4, 0.079], [64675.5, 2.663]], "asks": [[64675.6, 38.161], [64676.0, 0.936], [64676.1, 0.0], [64677.3, 1.073], [64678.2, 0.0], [64678.4, 0.002], [64678.6, 0.118], [64678.7, 0.001], [64678.8, 1.998], [64679.0, 0.003], [64679.1, 2.535], [64679.2, 0.431], [64679.6, 0.096], [64679.9, 0.08], [64680.0, 4.412], [64680.1, 8.7], [64681.3, 0.072], [64681.6, 0.006], [64685.7, 0.933], [64685.8, 0.262], [64687.3, 0.105], [64687.5, 0.094], [64687.6, 0.281], [64687.8, 0.271], [64687.9, 0.198], [64688.1, 0.114], [64688.2, 0.682], [64688.4, 0.01], [64688.5, 1.2], [64689.7, 0.416], [64690.0, 0.903], [64690.5, 0.256], [64691.0, 0.902], [64691.3, 0.645], [64691.5, 3.163], [64691.9, 1.237], [64694.5, 2.7], [64694.9, 10.002], [64695.2, 0.557], [64696.4, 0.092], [64705.6, 1.19], [64716.9, 0.028], [64718.9, 0.161], [64720.0, 0.152], [64727.7, 1.068], [64746.2, 8.079], [64748.1, 40.111], [64749.3, 1.807], [64750.3, 0.0], [64784.0, 1.082], [64816.5, 8.29], [64833.5, 6.338], [64880.2, 0.007], [64881.4, 0.002], [65322.4, 0.004], [65421.0, 0.772], [65421.6, 1.816], [65424.6, 11.805], [65519.6, 0.001], [65564.7, 0.0], [65598.6, 0.683], [65618.0, 11.192], [65672.7, 2.29], [65682.6, 4.332], [65969.1, 0.014]]}
{"kind": "depth", "E": 1787080508143, "U": 11315359352705, "u": 11315359363398, "recv_ms": 1787080508096, "bids": [[1000.0, 35.81], [14180.0, 1.414], [14575.5, 1.61], [51740.0, 0.0], [51744.0, 0.0], [58207.9, 0.002], [61183.7, 0.285], [62088.4, 0.0], [63799.8, 1.577], [64028.7, 0.0], [64114.4, 0.0], [64352.1, 0.002], [64474.8, 0.0], [64476.1, 21.195], [64519.9, 0.124], [64541.2, 0.0], [64587.9, 0.219], [64590.5, 0.025], [64594.1, 0.378], [64595.0, 0.524], [64596.5, 0.001], [64597.5, 0.013], [64598.1, 3.21], [64600.9, 0.343], [64601.1, 1.714], [64601.2, 4.058], [64602.0, 0.291], [64603.1, 33.389], [64604.4, 7.553], [64604.6, 0.042], [64606.5, 0.0], [64608.3, 0.074], [64631.7, 0.013], [64631.8, 0.681], [64636.6, 0.071], [64636.8, 0.003], [64637.6, 0.001], [64642.5, 0.096], [64643.3, 6.432], [64643.4, 0.307], [64645.5, 0.013], [64646.0, 0.006], [64649.6, 0.007], [64650.4, 0.63], [64656.4, 0.1], [64656.6, 0.002], [64663.9, 0.001], [64666.1, 0.013], [64666.4, 0.002], [64666.8, 0.004], [64667.7, 0.067], [64670.3, 0.702], [64671.2, 0.001], [64671.8, 0.201], [64672.0, 0.118], [64672.8, 0.016], [64673.4, 0.016], [64674.5, 0.002], [64675.5, 2.662]], "asks": [[64675.6, 38.785], [64678.9, 0.001], [64679.0, 0.099], [64679.1, 2.535], [64679.2, 0.432], [64679.6, 0.001], [64680.1, 8.675], [64685.3, 1.4], [64687.6, 0.451], [64687.7, 0.205], [64688.2, 0.766], [64688.3, 0.079], [64688.7, 0.001], [64689.7, 0.414], [64690.9, 0.928], [64691.2, 0.667], [64691.4, 3.763], [64691.7, 0.226], [64691.8, 0.003], [64692.1, 0.587], [64692.8, 1.143], [64700.9, 0.005], [64704.8, 0.004], [64705.4, 0.071], [64705.7, 0.163], [64710.4, 0.007], [64710.6, 0.002], [64717.4, 3.562], [64724.9, 0.057], [64739.3, 1.385], [64739.8, 0.005], [64755.5, 0.016], [64759.5, 0.038], [64762.5, 0.018], [64766.5, 0.163], [64816.5, 8.18], [64833.5, 6.121], [64871.9, 1.833], [64872.3, 7.962], [64872.8, 0.001], [65003.5, 0.184], [65037.4, 0.004], [65058.8, 0.01], [65322.4, 0.004], [65322.6, 2.728], [65387.9, 17.135], [65420.0, 4.683], [65421.6, 0.0], [65484.7, 0.756], [65489.2, 8.742]]}
{"kind": "depth", "E": 1787080508245, "U": 11315359363661, "u": 11315359374183, "recv_ms": 1787080508198, "bids": [[14180.0, 1.064], [14575.5, 1.96], [51740.0, 0.0], [58207.9, 0.002], [61441.7, 0.0], [61458.1, 0.013], [63675.5, 0.0], [64028.7, 0.0], [64356.6, 0.31], [64516.4, 2.332], [64521.0, 1.14], [64522.2, 0.009], [64555.2, 1.201], [64559.7, 0.008], [64562.3, 0.013], [64566.8, 1.284], [64569.3, 2.332], [64573.8, 0.001], [64576.4, 0.015], [64580.9, 0.596], [64583.4, 0.015], [64596.6, 0.003], [64603.8, 0.189], [64605.7, 0.1], [64608.2, 0.001], [64609.1, 0.0], [64627.4, 0.025], [64628.4, 0.027], [64633.1, 0.024], [64645.1, 0.104], [64645.5, 0.003], [64656.4, 0.0], [64662.4, 0.208], [64666.1, 0.02], [64670.3, 0.543], [64671.4, 0.086], [64671.7, 0.108], [64672.5, 0.056], [64675.5, 2.724]], "asks": [[64675.6, 38.819], [64678.6, 0.064], [64678.8, 1.999], [64678.9, 0.001], [64679.2, 0.431], [64680.1, 8.643], [64680.4, 0.042], [64681.5, 0.054], [64689.6, 0.019], [64691.4, 3.633], [64692.0, 1.021], [64705.7, 0.009], [64711.1, 0.093], [64711.3, 0.243], [64726.6, 0.043], [64738.8, 0.013], [64739.3, 1.375], [64769.6, 3.755], [64773.6, 0.001], [64776.6, 0.023], [64780.6, 0.002], [64783.7, 0.045], [64787.7, 10.84], [64790.8, 2.72], [64794.8, 0.0], [64797.8, 0.015], [64801.8, 0.135], [64804.9, 0.041], [64808.9, 0.016], [64816.5, 10.079], [64833.5, 10.514], [65322.4, 0.004], [65488.6, 4.173], [65624.4, 1.353], [65675.6, 0.006], [65812.7, 0.606], [65986.5, 0.058]]}
{"kind": "depth", "E": 1787080508347, "U": 11315359374269, "u": 11315359383377, "recv_ms": 1787080508300, "bids": [[14180.0, 0.7], [14575.5, 2.324], [51740.0, 0.0], [51744.0, 0.0], [58207.9, 0.002], [61441.7, 0.0], [62088.4, 0.003], [63754.6, 13.903], [63827.2, 0.0], [64028.7, 0.0], [64404.1, 0.02], [64476.1, 8.242], [64476.4, 1.826], [64543.5, 0.017], [64606.1, 3.553], [64610.8, 0.075], [64611.7, 2.346], [64623.9, 0.629], [64626.1, 3.551], [64656.0, 1.618], [64662.4, 0.362], [64663.6, 0.124], [64671.8, 0.179], [64672.6, 0.022], [64675.0, 0.155], [64675.5, 2.717]], "asks": [[64675.6, 38.818], [64677.3, 1.072], [64691.6, 0.001], [64692.1, 0.503], [64696.1, 0.0], [64725.3, 0.07], [64740.3, 0.023], [64745.8, 8.701], [64745.9, 41.451], [64746.2, 0.001], [64748.1, 0.077], [64791.1, 0.12], [64816.5, 10.079], [64833.5, 10.514], [64871.9, 2.712], [64872.3, 15.416], [65264.8, 3.369], [65322.4, 0.004], [65420.0, 5.591], [65424.6, 10.897]]}
{"kind": "depth", "E": 1787080508449, "U": 11315359383524, "u": 11315359392211, "recv_ms": 1787080508402, "bids": [[1000.0, 35.81], [14180.0, 0.406], [14475.5, 0.056], [14575.5, 2.618], [14580.0, 0.896], [51744.0, 0.0], [58207.9, 0.002], [61441.7, 0.0], [62088.4, 0.0], [63382.0, 0.012], [63675.5, 0.02], [63737.7, 5.364], [63923.2, 0.117], [64028.7, 0.0], [64033.7, 0.186], [64072.9, 1.091], [64354.4, 0.029], [64476.4, 14.143], [64636.7, 0.0], [64641.2, 0.341], [64644.7, 1.715], [64645.1, 0.094], [64651.9, 2.617], [64652.1, 0.083], [64656.6, 1.002], [64658.0, 1.345], [64659.1, 0.316], [64665.9, 0.055], [64666.1, 0.561], [64666.6, 0.05], [64667.1, 0.0], [64667.7, 0.07], [64668.1, 0.001], [64670.3, 0.002], [64671.4, 0.102], [64671.8, 0.171], [64671.9, 0.085], [64672.3, 0.073], [64672.5, 0.137], [64672.6, 0.003], [64675.5, 3.87]], "asks": [[64675.6, 38.83], [64678.9, 0.001], [64679.6, 0.359], [64680.0, 4.416], [64680.2, 0.007], [64691.6, 0.003], [64694.6, 0.311], [64694.9, 10.004], [64697.3, 0.024], [64705.7, 0.009], [64707.1, 0.569], [64707.4, 0.147], [64707.9, 0.145], [64725.5, 0.002], [64730.1, 0.005], [64738.5, 0.012], [64738.8, 0.003], [64757.9, 0.096], [64762.5, 0.016], [64790.3, 0.002], [64794.9, 0.0], [64871.9, 1.833], [64872.3, 5.565], [65322.4, 0.004], [65675.6, 0.026], [65792.6, 1.384], [65973.7, 0.026]]}
