{"kind": "depth", "E": 1787089922949, "U": 11316020672453, "u": 11316020678519, "recv_ms": 1787089922919, "bids": [[14080.5, 2.8], [14480.5, 1.4], [58122.4, 0.004], [61351.4, 0.024], [61997.2, 0.0], [63934.7, 3.972], [64257.6, 4.168], [64439.4, 4.332], [64440.1, 1.023], [64515.9, 0.02], [64539.8, 0.034], [64540.1, 0.415], [64541.1, 0.126], [64541.9, 10.003], [64547.1, 0.0], [64551.1, 0.057], [64552.2, 0.406], [64555.9, 0.002], [64557.8, 0.001], [64558.3, 0.116], [64559.1, 0.559], [64559.7, 0.0], [64560.1, 0.001], [64560.6, 0.002], [64561.4, 0.012], [64562.1, 0.011], [64563.6, 0.001], [64563.7, 0.001], [64564.4, 0.943], [64565.3, 0.0], [64565.4, 0.544], [64566.5, 0.001], [64570.3, 0.154], [64573.9, 0.073], [64574.3, 0.1], [64574.4, 0.187], [64574.6, 0.102], [64574.7, 0.071], [64575.2, 0.033], [64575.5, 0.033], [64576.4, 0.126], [64580.5, 4.303]], "asks": [[64580.6, 28.584], [64583.9, 0.011], [64586.9, 0.074], [64587.5, 0.115], [64587.9, 0.309], [64588.2, 0.379], [64588.7, 0.211], [64588.8, 1.317], [64589.0, 0.522], [64589.5, 0.311], [64590.5, 0.545], [64594.6, 0.028], [64595.6, 0.543], [64595.7, 0.312], [64596.1, 0.0], [64596.8, 0.932], [64597.8, 0.56], [64598.5, 2.002], [64599.6, 0.652], [64601.0, 0.116], [64601.5, 1.241], [64602.4, 10.008], [64603.1, 0.0], [64603.4, 0.002], [64603.8, 0.078], [64604.6, 0.172], [64605.6, 0.109], [64605.9, 2.389], [64606.7, 0.278], [64607.9, 0.151], [64608.0, 0.709], [64608.2, 0.47], [64608.7, 0.171], [64622.3, 1.692], [64623.2, 0.079], [64623.6, 0.083], [64645.2, 0.363], [64720.5, 0.015], [64721.1, 8.178], [64721.2, 0.002], [64722.3, 0.47], [64737.5, 0.001], [64738.0, 6.901], [65161.9, 11.266], [65226.4, 1.36], [65478.3, 21.279], [65872.2, 7.651]]}
{"kind": "depth", "E": 1787089923051, "U": 11316020678549, "u": 11316020685034, "recv_ms": 1787089923016, "bids": [[1000.0, 35.76], [14080.5, 2.436], [14480.5, 1.764], [58122.4, 0.004], [61351.5, 0.008], [61351.6, 0.008], [61997.2, 0.003], [63469.7, 2.514], [63580.5, 0.006], [63604.4, 1.571], [63934.7, 3.972], [64534.0, 0.001], [64540.4, 2.358], [64540.8, 0.039], [64551.8, 0.31], [64552.2, 0.096], [64557.8, 0.0], [64559.2, 0.014], [64559.7, 0.001], [64561.4, 0.003], [64561.8, 0.009], [64563.2, 0.041], [64563.7, 0.011], [64564.5, 0.544], [64565.4, 0.002], [64568.5, 0.312], [64568.8, 0.155], [64568.9, 0.005], [64569.8, 0.414], [64570.2, 0.161], [64572.7, 0.929], [64572.9, 1.746], [64573.1, 1.558], [64574.0, 0.089], [64574.1, 0.28], [64574.2, 0.152], [64574.3, 0.2], [64574.7, 0.074], [64574.8, 0.198], [64575.8, 0.034], [64576.1, 0.034], [64576.4, 0.126], [64576.7, 0.127], [64576.8, 0.018]], "asks": [[64580.6, 29.462], [64587.2, 0.111], [64587.5, 0.74], [64588.3, 0.068], [64588.6, 0.275], [64588.7, 0.149], [64589.1, 0.271], [64589.2, 0.288], [64589.3, 0.213], [64589.4, 0.206], [64590.5, 0.003], [64594.6, 0.028], [64595.6, 0.001], [64595.7, 0.854], [64595.8, 0.621], [64596.1, 0.002], [64596.8, 0.005], [64597.0, 0.927], [64597.4, 0.005], [64602.4, 0.008], [64603.1, 0.057], [64603.9, 0.003], [64604.9, 0.074], [64605.2, 0.246], [64606.3, 0.263], [64608.3, 0.27], [64608.4, 1.526], [64608.6, 0.293], [64622.6, 0.077], [64622.9, 0.102], [64653.5, 37.558], [64655.7, 2.321], [64720.5, 5.423], [64721.1, 3.879], [64722.3, 1.47], [64737.5, 10.428], [64738.0, 0.005], [65226.4, 1.36], [65497.7, 0.0], [65580.6, 0.01]]}
{"kind": "depth", "E": 1787089923153, "U": 11316020685237, "u": 11316020693335, "recv_ms": 1787089923117, "bids": [[1000.0, 35.76], [14080.5, 2.086], [14480.5, 2.114], [58122.4, 0.004], [61351.4, 0.024], [63495.5, 4.399], [63599.4, 0.01], [63599.5, 5.552], [63798.3, 0.783], [63934.6, 0.005], [63934.7, 3.972], [64257.0, 0.07], [64450.5, 0.01], [64504.1, 0.035], [64508.5, 34.815], [64508.8, 1.73], [64538.1, 0.442], [64541.9, 0.003], [64549.2, 0.127], [64551.1, 0.0], [64556.2, 0.004], [64556.8, 0.124], [64557.7, 0.576], [64558.3, 0.0], [64558.8, 0.001], [64559.1, 0.001], [64559.2, 0.0], [64559.7, 0.0], [64561.8, 0.001], [64562.4, 0.002], [64562.7, 0.002], [64563.0, 1.017], [64563.1, 3.687], [64563.2, 0.583], [64563.3, 0.252], [64563.7, 0.003], [64564.4, 0.016], [64564.5, 0.002], [64564.8, 0.791], [64564.9, 0.001], [64565.9, 0.039], [64566.0, 0.125], [64566.7, 0.007], [64567.3, 0.004], [64568.6, 0.094], [64568.9, 0.0], [64570.1, 0.052], [64572.9, 1.738], [64573.0, 0.097], [64573.1, 0.002], [64574.1, 0.35], [64574.5, 0.103], [64574.6, 0.202], [64574.7, 0.071], [64574.9, 0.072], [64575.8, 0.037], [64576.0, 1.635], [64576.1, 0.034], [64576.3, 0.003], [64576.8, 0.018], [64578.0, 0.01], [64578.1, 0.609], [64580.5, 2.364]], "asks": [[64580.6, 42.524], [64580.9, 0.033], [64581.4, 0.002], [64582.6, 0.002], [64583.4, 0.254], [64583.9, 0.001], [64585.5, 0.003], [64587.4, 0.31], [64587.5, 0.198], [64587.7, 2.322], [64588.5, 0.17], [64588.6, 0.274], [64588.7, 0.429], [64589.3, 0.367], [64589.4, 0.226], [64590.5, 0.545], [64592.1, 0.009], [64592.7, 0.627], [64592.8, 0.487], [64592.9, 2.527], [64593.1, 0.545], [64593.4, 2.32], [64594.2, 1.302], [64594.5, 10.015], [64594.8, 0.0], [64595.1, 0.0], [64595.4, 0.933], [64595.7, 0.312], [64595.8, 0.002], [64596.1, 0.003], [64597.0, 0.0], [64597.2, 0.362], [64598.5, 0.002], [64601.0, 0.116], [64601.1, 0.38], [64601.3, 5.071], [64602.8, 0.0], [64603.1, 0.0], [64607.7, 0.185], [64607.9, 0.431], [64608.5, 0.259], [64640.3, 0.224], [64650.4, 0.027], [64653.5, 0.629], [64657.9, 36.972], [64660.1, 0.013], [65226.4, 1.36], [65298.3, 3.827], [65561.7, 0.03], [65872.2, 7.654]]}
{"kind": "depth", "E": 1787089923255, "U": 11316020693448, "u": 11316020703520, "recv_ms": 1787089923220, "bids": [[14080.5, 1.722], [14480.5, 2.478], [58122.4, 0.004], [61351.4, 0.024], [61997.2, 0.0], [63580.5, 0.026], [63934.7, 3.972], [64257.6, 4.178], [64495.3, 0.01], [64505.5, 0.313], [64506.2, 33.014], [64508.5, 1.806], [64522.1, 0.034], [64522.3, 0.003], [64522.4, 0.237], [64523.1, 0.114], [64523.4, 0.046], [64534.9, 0.0], [64537.2, 0.001], [64539.5, 10.001], [64549.2, 0.07], [64549.9, 0.367], [64555.0, 0.073], [64555.2, 1.211], [64556.2, 0.003], [64559.9, 0.003], [64563.2, 0.041], [64564.8, 0.241], [64564.9, 0.543], [64565.9, 0.589], [64567.3, 0.004], [64570.0, 0.004], [64574.5, 0.173], [64576.2, 0.314], [64576.8, 0.018], [64580.5, 2.252]], "asks": [[64580.6, 42.524], [64580.8, 0.039], [64584.0, 0.354], [64588.9, 0.348], [64593.1, 0.003], [64593.6, 0.007], [64594.1, 0.577], [64595.4, 0.006], [64595.7, 0.311], [64595.8, 0.002], [64596.4, 0.927], [64598.8, 0.661], [64601.3, 5.014], [64601.6, 0.011], [64602.0, 0.197], [64606.1, 0.933], [64608.1, 0.187], [64638.8, 0.003], [65226.4, 1.36], [65561.6, 0.016], [65580.6, 0.03], [67163.8, 1.911]]}
{"kind": "depth", "E": 1787089923357, "U": 11316020703611, "u": 11316020712313, "recv_ms": 1787089923321, "bids": [[1000.0, 35.76], [14080.5, 1.358], [14480.5, 2.842], [58122.4, 0.004], [61997.2, 0.003], [63208.4, 0.0], [63934.7, 3.972], [64522.7, 0.088], [64554.7, 0.117], [64555.2, 1.311], [64555.4, 0.101], [64555.5, 1.372], [64556.7, 0.103], [64561.7, 0.108], [64563.0, 0.09], [64563.2, 0.041], [64563.3, 0.244], [64564.1, 0.927], [64564.2, 0.543], [64564.9, 0.001], [64569.0, 0.637], [64571.6, 0.237], [64572.0, 0.004], [64572.3, 0.004]], "asks": [[64580.8, 0.041], [64594.1, 0.035], [64594.6, 0.028], [64595.8, 0.544], [64596.4, 0.0], [64597.0, 0.927], [64602.0, 0.14], [64602.5, 0.003], [64603.1, 0.057], [64606.1, 0.314], [64903.6, 0.0], [65226.4, 1.36]]}
{"kind": "depth", "E": 1787089923459, "U": 11316020712413, "u": 11316020721267, "recv_ms": 1787089923427, "bids": [[1000.0, 35.76], [14080.5, 1.008], [14480.5, 3.192], [51664.4, 0.0], [58122.4, 0.004], [61351.4, 0.025], [61997.2, 0.0], [63314.6, 2.028], [63580.5, 0.006], [63870.1, 6.723], [63934.7, 3.972], [63999.3, 10.721], [64257.5, 0.468], [64257.6, 6.509], [64503.0, 0.023], [64528.8, 0.092], [64539.5, 0.001], [64540.1, 2.415], [64554.8, 0.143], [64554.9, 0.073], [64555.1, 0.1], [64557.1, 0.122], [64580.5, 2.252]], "asks": [[64580.6, 42.911], [64594.1, 0.577], [64595.8, 0.002], [64619.4, 0.003], [64658.1, 0.018], [65226.4, 1.36], [65580.6, 0.01]]}
{"kind": "depth", "E": 1787089923561, "U": 11316020721472, "u": 11316020729914, "recv_ms": 1787089923525, "bids": [[14080.5, 0.644], [14480.5, 3.556], [58122.4, 0.004], [61351.4, 0.024], [61997.2, 0.003], [63934.7, 3.972], [63997.8, 0.0], [64257.6, 6.499], [64462.4, 4.504], [64506.2, 0.005], [64508.5, 34.815], [64549.9, 0.31], [64551.5, 0.299], [64554.9, 0.143], [64555.4, 0.201], [64555.6, 0.21], [64565.5, 0.0], [64569.0, 0.6], [64576.0, 1.627], [64576.3, 0.011], [64578.9, 0.003], [64580.5, 2.253]], "asks": [[64584.6, 0.007], [64586.2, 0.004], [64590.4, 0.308], [64594.1, 0.035], [64595.8, 0.544], [65226.4, 1.36], [65387.9, 17.279], [65517.3, 1.828]]}
{"kind": "depth", "E": 1787089923663, "U": 11316020730019, "u": 11316020737036, "recv_ms": 1787089923628, "bids": [[1000.0, 35.76], [14080.5, 0.364], [14380.5, 0.07], [14480.5, 3.766], [51664.0, 0.0], [58122.4, 0.004], [61351.4, 0.024], [63580.5, 0.026], [63870.1, 6.958], [63934.7, 3.972], [63999.3, 10.955], [64117.8, 0.0], [64127.8, 0.101], [64440.1, 1.539], [64464.2, 1.199], [64508.7, 7.225], [64512.6, 6.002], [64512.8, 2.348], [64533.6, 0.007], [64544.1, 0.311], [64555.3, 0.07], [64557.7, 0.018], [64560.6, 0.56], [64564.1, 0.0], [64564.2, 0.001], [64564.6, 0.929], [64564.7, 0.543], [64565.5, 0.0], [64565.6, 0.213], [64566.5, 0.001], [64568.8, 0.192], [64576.8, 0.008], [64580.5, 2.253]], "asks": [[64580.6, 42.911], [64583.9, 0.011], [64594.5, 10.017], [64594.9, 0.181], [64597.0, 0.0], [64597.9, 0.928], [64599.6, 0.095], [64600.7, 0.577], [64601.0, 0.0], [64602.2, 0.942], [64603.1, 0.0], [64604.1, 0.057], [64657.5, 5.863], [64720.4, 2.05], [64902.8, 0.86], [65226.4, 1.36], [65549.3, 19.351], [65580.6, 0.03]]}
{"kind": "depth", "E": 1787089923765, "U": 11316020737233, "u": 11316020743018, "recv_ms": 1787089923730, "bids": [[1000.0, 35.76], [14080.5, 0.238], [14380.5, 0.294], [14480.5, 3.668], [58122.4, 0.004], [61351.3, 0.056], [61997.2, 0.0], [63934.7, 3.972], [63999.1, 2.94]], "asks": [[64583.9, 0.001], [65484.7, 78.52], [65529.9, 17.208], [65872.2, 7.657]]}
{"kind": "depth", "E": 1787089923867, "U": 11316020743417, "u": 11316020749882, "recv_ms": 1787089923831, "bids": [[14080.5, 0.112], [14380.5, 0.532], [14480.5, 3.556], [58122.4, 0.004], [61351.5, 0.008], [61351.6, 0.01], [61997.2, 0.003], [63372.8, 3.275], [63580.5, 0.006], [63773.2, 23.344], [64257.6, 6.509], [64571.6, 0.005], [64572.7, 1.161]], "asks": [[64583.9, 0.011], [64776.2, 11.519], [64776.9, 0.0], [65162.0, 4.024], [65226.4, 1.36], [65465.6, 0.003], [65580.6, 0.01]]}
{"kind": "depth", "E": 1787089923969, "U": 11316020750076, "u": 11316020757580, "recv_ms": 1787089923933, "bids": [[1000.0, 35.76], [14080.5, 0.0], [14380.5, 0.77], [14480.5, 3.43], [58122.4, 0.004], [61997.2, 0.0], [63724.8, 0.0], [63798.2, 3.915], [63934.7, 3.972], [64556.8, 0.008], [64558.6, 0.118], [64559.6, 0.562], [64560.6, 0.002], [64564.8, 0.164], [64566.0, 0.202], [64574.5, 0.17], [64574.7, 0.074], [64576.0, 0.079], [64576.3, 1.559]], "asks": [[64583.9, 0.001], [64599.9, 0.562], [64600.7, 0.02], [64601.3, 5.13], [64602.2, 0.826], [64602.8, 0.007], [64603.8, 0.071], [65200.9, 0.039], [65226.4, 1.36], [65846.5, 2.605]]}
{"kind": "depth", "E": 1787089924071, "U": 11316020757729, "u": 11316020767657, "recv_ms": 1787089924035, "bids": [[1000.0, 35.76], [14380.5, 1.134], [14480.5, 3.066], [58122.4, 0.004], [61997.2, 0.003], [63418.0, 0.952], [63580.5, 0.026], [63934.7, 3.972], [64257.6, 6.509], [64563.7, 0.003], [64568.9, 0.0], [64576.0, 0.079], [64576.3, 1.559], [64576.8, 0.018]], "asks": [[64596.1, 0.003], [64597.1, 1.244], [64597.9, 0.001], [64603.2, 1.182], [64604.1, 0.0], [64776.2, 11.378], [65161.9, 12.338], [65226.4, 1.36], [65452.4, 17.796], [65478.3, 22.193], [65580.6, 0.03]]}
{"kind": "depth", "E": 1787089924173, "U": 11316020767828, "u": 11316020775908, "recv_ms": 1787089924136, "bids": [[14380.5, 1.484], [14480.5, 2.716], [58122.4, 0.004], [61351.4, 0.024], [63418.1, 3.829], [63805.5, 57.036], [63934.6, 0.004], [63934.7, 3.972], [64063.9, 4.365], [64257.6, 6.121], [64470.7, 0.007], [64508.9, 0.036], [64561.1, 1.495], [64566.7, 0.015], [64570.0, 1.552], [64576.0, 0.079], [64576.3, 0.003], [64577.9, 1.533], [64580.5, 2.254]], "asks": [[64580.6, 42.91], [64580.8, 0.039], [64592.7, 0.0], [64592.9, 1.195], [64593.1, 0.011], [64594.4, 0.003], [64594.5, 0.017], [64595.7, 0.93], [64595.9, 2.487], [64597.0, 10.0], [64690.4, 0.036], [65194.4, 0.001], [65226.4, 1.36], [65355.6, 56.786]]}
{"kind": "depth", "E": 1787089924275, "U": 11316020776172, "u": 11316020783288, "recv_ms": 1787089924240, "bids": [[1000.0, 35.76], [14380.5, 1.848], [14480.5, 2.352], [51664.0, 0.0], [58122.4, 0.004], [61351.4, 0.024], [61997.2, 0.0], [63580.5, 0.006], [63741.0, 17.351], [63821.5, 0.782], [63934.7, 3.972], [64259.3, 0.108], [64422.4, 4.699], [64439.4, 3.58], [64440.1, 1.023], [64475.7, 0.109], [64534.0, 0.015], [64559.7, 0.619], [64564.8, 0.157], [64565.9, 0.039], [64566.0, 0.125], [64566.7, 0.007], [64567.0, 1.015], [64570.0, 0.004], [64573.0, 0.731], [64575.5, 0.033], [64576.0, 1.635], [64576.2, 0.314], [64576.3, 0.003], [64576.8, 0.008], [64580.5, 2.253]], "asks": [[64580.6, 42.911], [64584.6, 0.03], [64602.2, 0.808], [64602.3, 1.291], [64605.8, 0.62], [64628.2, 0.085], [64634.9, 0.213], [64690.6, 0.1], [64720.4, 0.0], [64720.5, 5.423], [64737.5, 10.428], [64911.0, 0.308], [65213.5, 68.468], [65226.4, 1.36], [65580.6, 0.01]]}
{"kind": "depth", "E": 1787089924377, "U": 11316020783372, "u": 11316020792314, "recv_ms": 1787089924341, "bids": [[1000.0, 35.76], [14380.5, 2.198], [14480.5, 2.002], [51664.0, 0.0], [51664.4, 0.002], [58122.4, 0.004], [61351.3, 0.05], [61351.5, 0.008], [61351.6, 0.012], [61997.2, 0.003], [63288.9, 4.267], [63934.7, 3.972], [64257.6, 6.121], [64565.4, 0.003], [64565.9, 0.673], [64573.0, 0.097], [64576.0, 1.627], [64576.3, 0.011]], "asks": [[64586.1, 0.062], [64587.5, 0.106], [64587.8, 0.0], [64590.4, 0.107], [64619.2, 2.647], [64632.7, 0.0], [65162.6, 0.008], [65207.0, 3.377], [65226.4, 1.36], [65532.9, 0.001], [65548.7, 0.228]]}
{"kind": "depth", "E": 1787089924479, "U": 11316020792592, "u": 11316020801054, "recv_ms": 1787089924443, "bids": [[14380.5, 2.562], [14480.5, 1.638], [51664.4, 0.0], [58122.4, 0.004], [61997.2, 0.0], [63580.5, 0.026], [63741.0, 18.448], [63805.0, 1.833], [63805.5, 57.974], [63934.7, 3.972], [64063.9, 4.987], [64257.5, 0.466], [64257.6, 6.509], [64308.4, 0.004], [64314.5, 0.0], [64439.4, 4.25], [64470.7, 0.004], [64503.0, 0.02], [64522.3, 0.003]], "asks": [[64638.8, 0.003], [64658.1, 0.015], [64690.4, 0.033], [64720.5, 5.423], [65161.9, 13.411], [65323.9, 2.883], [65355.6, 57.244], [65580.6, 0.03]]}
{"kind": "depth", "E": 1787089924683, "U": 11316020808606, "u": 11316020819179, "recv_ms": 1787089924649, "bids": [[1000.0, 35.96], [14380.5, 3.276], [14480.5, 0.924], [58122.4, 0.004], [61351.4, 0.024], [61997.2, 0.003], [63482.6, 11.53], [63580.5, 0.006], [63805.5, 62.669], [63934.7, 3.972], [64257.6, 6.499], [64308.4, 0.0], [64314.9, 0.924], [64495.3, 32.678], [64501.0, 4.911], [64508.5, 1.806], [64534.0, 0.001], [64540.1, 0.415], [64544.1, 10.311], [64546.0, 2.476], [64561.7, 0.1], [64563.2, 0.049], [64564.6, 0.002], [64564.7, 0.928], [64565.5, 0.0], [64565.6, 0.755], [64566.5, 0.001], [64566.7, 0.0], [64567.0, 0.396], [64567.4, 0.317], [64576.8, 0.0], [64577.6, 0.001], [64578.2, 0.01], [64578.3, 0.02], [64580.2, 0.002], [64580.5, 2.564]], "asks": [[64580.6, 42.915], [64580.8, 0.041], [64580.9, 0.04], [64587.5, 0.74], [64590.4, 0.015], [64590.5, 0.003], [64591.1, 0.0], [64592.1, 0.001], [64592.7, 0.008], [64597.0, 10.927], [64597.1, 0.317], [64598.0, 0.006], [64598.8, 0.042], [64599.9, 0.005], [64601.0, 0.557], [64601.3, 5.014], [64602.2, 0.924], [64603.2, 1.182], [64604.1, 0.0], [64605.8, 0.001], [64720.4, 2.05], [65161.9, 13.449], [65226.4, 1.36], [65387.8, 2.006], [65387.9, 17.02], [65465.4, 3.654], [65580.6, 0.01], [65872.2, 7.66]]}
{"kind": "depth", "E": 1787089924785, "U": 11316020819489, "u": 11316020826622, "recv_ms": 1787089924750, "bids": [[14380.5, 3.64], [14480.5, 0.56], [51664.0, 0.0], [58122.4, 0.004], [61351.3, 0.044], [61997.2, 0.0], [63669.9, 4.742], [63934.7, 3.972], [64495.3, 0.01], [64503.0, 0.02], [64504.1, 0.035], [64505.5, 0.313], [64506.2, 32.234], [64508.7, 2.439], [64518.1, 0.036], [64519.8, 0.001], [64522.6, 0.116], [64533.9, 0.075], [64535.7, 0.0], [64536.5, 0.695], [64538.5, 0.015], [64545.8, 0.019], [64547.5, 0.003], [64550.4, 0.009], [64551.4, 1.019], [64553.1, 0.001], [64556.0, 0.001], [64558.9, 0.036], [64559.7, 0.0], [64560.4, 0.448], [64561.8, 0.009], [64563.2, 0.041], [64563.3, 0.238], [64564.8, 0.699], [64565.1, 0.017], [64565.4, 0.002], [64565.6, 0.213], [64565.8, 2.338], [64567.7, 0.011], [64568.7, 0.003], [64569.4, 0.0], [64576.8, 0.008], [64578.2, 0.002], [64580.5, 2.255]], "asks": [[64580.6, 42.922], [64580.8, 0.039], [64580.9, 0.033], [64584.6, 0.007], [64585.6, 0.925], [64586.1, 0.061], [64586.5, 0.098], [64587.5, 0.106], [64589.9, 0.004], [64590.1, 0.174], [64590.7, 0.043], [64591.1, 0.634], [64591.8, 0.003], [64592.2, 0.57], [64592.8, 0.493], [64595.8, 0.559], [64596.0, 2.445], [64602.4, 0.022], [64604.1, 0.0], [64607.0, 0.006], [64609.3, 0.012], [64610.9, 0.008], [64612.3, 0.024], [64613.7, 0.001], [64614.0, 0.029], [64616.9, 0.002], [64618.0, 0.018], [64619.7, 0.002], [64622.5, 0.002], [65226.4, 1.36], [65323.9, 3.8], [65452.4, 17.796], [65497.6, 2.509]]}
{"kind": "depth", "E": 1787089924989, "U": 11316020833423, "u": 11316020840275, "recv_ms": 1787089924952, "bids": [[1000.0, 35.96], [14280.5, 0.35], [14380.5, 3.64], [14480.5, 0.21], [58122.4, 0.004], [61351.6, 0.01], [61997.2, 0.0], [63224.3, 2.375], [63676.3, 6.963], [63999.3, 10.721], [64257.6, 6.509], [64555.4, 0.201], [64561.8, 0.001], [64565.4, 0.003], [64566.7, 0.008], [64574.6, 0.205], [64574.7, 0.071], [64576.0, 1.627], [64576.1, 0.034], [64576.3, 0.003]], "asks": [[64586.1, 0.062], [64599.9, 0.562], [64601.0, 0.0], [64601.3, 5.13], [64602.2, 0.808], [64602.8, 0.0], [64603.1, 0.007], [65226.4, 1.36], [65465.4, 4.263], [65872.2, 7.663]]}
{"kind": "depth", "E": 1787089925091, "U": 11316020840323, "u": 11316020849127, "recv_ms": 1787089925055, "bids": [[14280.5, 0.588], [14380.5, 3.528], [14480.5, 0.084], [51664.0, 0.0], [58122.4, 0.004], [63580.5, 0.006], [63934.7, 3.972], [64308.4, 0.004], [64314.9, 0.92], [64561.4, 0.011], [64563.7, 0.003], [64564.8, 0.157], [64564.9, 0.635], [64565.9, 0.581], [64566.0, 0.125], [64566.5, 0.001], [64566.7, 0.007], [64567.4, 0.31], [64568.1, 0.619], [64568.5, 0.003], [64568.9, 0.0], [64570.0, 0.004], [64570.1, 0.052], [64573.0, 0.097], [64576.0, 1.627], [64576.1, 0.042], [64576.3, 0.003]], "asks": [[64587.5, 0.121], [64590.4, 0.557], [64590.5, 0.08], [64591.1, 0.0], [64592.0, 0.088], [64592.7, 0.0], [64596.1, 0.003], [65226.4, 1.36], [65290.2, 0.765], [65580.6, 0.01], [65678.5, 22.662], [65872.2, 7.66]]}
{"kind": "depth", "E": 1787089925193, "U": 11316020849245, "u": 11316020856718, "recv_ms": 1787089925157, "bids": [[1000.0, 36.16], [14280.5, 0.854], [14380.5, 3.346], [14480.5, 0.0], [51664.0, 0.0], [58122.4, 0.004], [61351.4, 0.024], [61997.2, 0.003], [63676.4, 59.089], [63934.7, 3.972], [64551.5, 0.242], [64551.6, 0.164], [64552.5, 0.081], [64558.6, 0.002], [64558.7, 0.116], [64559.6, 0.004], [64559.7, 0.0], [64559.8, 0.558], [64560.6, 0.002], [64564.7, 0.001], [64564.9, 0.943], [64565.7, 0.005], [64565.9, 0.581], [64566.0, 0.744], [64566.5, 0.001], [64576.8, 0.018], [64578.1, 0.0]], "asks": [[64580.6, 42.922], [64597.0, 10.0], [64597.3, 1.028], [64598.1, 0.029], [64599.9, 0.005], [64601.0, 0.557], [64601.3, 5.014], [64602.4, 0.138], [64603.2, 1.125], [64604.2, 0.066], [64622.6, 0.077], [65226.4, 1.36], [65323.9, 5.633], [65349.0, 5.725]]}
{"kind": "depth", "E": 1787089925295, "U": 11316020857022, "u": 11316020863743, "recv_ms": 1787089925259, "bids": [[1000.0, 36.16], [14280.5, 1.218], [14380.5, 2.982], [58122.4, 0.004], [61351.4, 0.024], [61997.2, 0.0], [63288.9, 4.264], [63580.5, 0.026], [63934.7, 3.972], [63999.2, 6.852], [64257.6, 6.499], [64403.3, 0.027], [64559.9, 0.622], [64567.2, 0.621], [64577.4, 0.003], [64578.0, 0.854], [64578.1, 0.002], [64578.2, 0.001], [64580.2, 0.0], [64580.5, 2.253]], "asks": [[64580.6, 42.922], [64582.9, 0.294], [64583.1, 0.031], [64587.1, 0.195], [64587.5, 0.198], [64589.7, 0.509], [64590.5, 0.003], [64598.7, 3.189], [64606.0, 0.629], [64622.6, 0.231], [65181.5, 1.148], [65226.4, 1.36], [65290.5, 0.161], [65323.8, 3.668], [65387.9, 18.127], [65580.6, 0.03], [65678.5, 22.966], [71038.7, 0.002]]}
{"kind": "depth", "E": 1787089925397, "U": 11316020863805, "u": 11316020871883, "recv_ms": 1787089925361, "bids": [[14280.5, 1.568], [14380.5, 2.632], [51664.4, 0.0], [58122.4, 0.004], [61997.2, 0.003], [63605.7, 0.035], [63725.0, 0.129], [63934.7, 3.972], [64562.1, 0.004], [64563.1, 3.694], [64571.9, 0.234], [64572.7, 0.929], [64576.8, 0.008]], "asks": [[64586.5, 0.018], [64587.0, 0.549], [64596.0, 2.445], [64622.6, 0.231], [65194.1, 24.023], [65323.8, 2.751], [65349.1, 6.419]]}
{"kind": "depth", "E": 1787089925601, "U": 11316020879974, "u": 11316020886429, "recv_ms": 1787089925566, "bids": [[14280.5, 2.282], [14380.5, 1.918], [51664.0, 0.0], [58122.4, 0.004], [61351.4, 0.03], [61997.2, 0.0], [63372.8, 4.062], [63580.5, 0.006], [63663.5, 3.306], [63934.7, 3.972], [64257.5, 0.467], [64257.6, 6.509]], "asks": [[64580.6, 42.932], [64593.3, 0.006], [64597.2, 0.361], [64903.6, 0.0], [65097.2, 9.662], [65226.4, 1.36], [65323.9, 7.467], [65355.5, 8.296], [65484.2, 0.0], [65580.6, 0.01]]}
{"kind": "depth", "E": 1787089925703, "U": 11316020886502, "u": 11316020892519, "recv_ms": 1787089925668, "bids": [[14280.5, 2.646], [14380.5, 1.554], [51664.0, 0.0], [58122.4, 0.004], [61351.5, 0.01], [61997.2, 0.003], [63403.2, 0.0], [63611.8, 14.304], [63773.2, 23.11], [63863.9, 0.01], [63934.7, 3.972], [64257.5, 0.468], [64504.8, 5.881]], "asks": [[64580.6, 42.932], [64731.1, 1.148], [65226.4, 1.36], [65323.8, 0.917], [65355.6, 58.466]]}
{"kind": "depth", "E": 1787089925805, "U": 11316020892675, "u": 11316020899744, "recv_ms": 1787089925771, "bids": [[1000.0, 36.16], [14280.5, 2.996], [14380.5, 1.204], [51664.0, 0.0], [58122.4, 0.004], [60609.2, 0.004], [61351.3, 0.038], [61997.2, 0.0], [63760.9, 1.568], [63934.7, 3.972], [64112.6, 0.0], [64439.3, 5.562], [64439.4, 0.003], [64522.3, 0.003]], "asks": [[64638.8, 0.003], [64720.5, 5.423], [65226.4, 1.36], [65568.9, 5.781]]}
{"kind": "depth", "E": 1787089926111, "U": 11316020914741, "u": 11316020923021, "recv_ms": 1787089926085, "bids": [[1000.0, 36.16], [14180.5, 0.168], [14280.5, 3.738], [14380.5, 0.294], [58122.4, 0.004], [61351.5, 0.008], [61351.6, 0.012], [61997.2, 0.0], [63580.5, 0.006], [63773.2, 23.893], [63805.4, 1.783], [63934.7, 3.972], [64383.6, 9.042], [64422.4, 5.593], [64439.3, 5.597], [64512.6, 0.002], [64535.2, 0.061], [64537.1, 0.014], [64551.4, 0.018], [64563.7, 0.003], [64568.9, 0.0], [64575.3, 1.811], [64576.1, 0.352]], "asks": [[64596.1, 0.003], [64607.4, 0.092], [64623.5, 0.025], [64646.2, 6.303], [65226.4, 1.36], [65426.7, 0.267], [65549.3, 20.113], [65556.5, 1.029], [65580.6, 0.01]]}
{"kind": "depth", "E": 1787089926213, "U": 11316020923254, "u": 11316020932137, "recv_ms": 1787089926177, "bids": [[14180.5, 0.42], [14280.5, 3.598], [14380.5, 0.182], [58122.4, 0.004], [61351.3, 0.032], [61351.4, 0.03], [61997.2, 0.003], [63482.6, 11.766], [63773.2, 23.659], [63934.7, 3.972], [64063.9, 4.991], [64257.6, 6.509], [64308.4, 0.0], [64503.0, 0.023], [64505.5, 0.322], [64508.8, 1.727], [64508.9, 0.035], [64529.0, 0.09], [64531.9, 0.094], [64534.0, 0.015], [64536.7, 0.983], [64566.9, 0.462], [64571.9, 0.002], [64572.3, 0.236], [64575.7, 0.084], [64576.0, 0.079], [64576.3, 1.551], [64576.8, 0.008], [64577.4, 0.001], [64578.1, 0.001], [64579.1, 0.002], [64580.2, 0.002], [64580.5, 2.246]], "asks": [[64580.6, 42.931], [64603.1, 0.0], [64603.5, 0.021], [64622.7, 0.0], [64622.8, 0.0], [64631.7, 0.0], [64658.1, 0.018], [65226.4, 1.36], [65291.0, 9.367]]}
{"kind": "depth", "E": 1787089926315, "U": 11316020932196, "u": 11316020941503, "recv_ms": 1787089926279, "bids": [[14180.5, 0.644], [14280.5, 3.5], [14380.5, 0.056], [51664.0, 0.0], [58122.4, 0.004], [61351.4, 0.03], [61997.2, 0.0], [63934.7, 3.972], [64063.9, 4.987], [64314.8, 0.36], [64440.7, 0.0], [64480.4, 0.653], [64504.1, 0.035], [64504.8, 1.191], [64505.5, 0.313], [64506.9, 6.032], [64508.5, 34.035], [64529.4, 3.502], [64541.7, 0.032], [64545.6, 2.101], [64576.8, 0.018], [64579.9, 0.171]], "asks": [[64580.6, 42.921], [64583.8, 0.101], [64596.9, 0.003], [64601.3, 5.094], [64609.0, 3.311], [64622.7, 0.0], [64622.8, 0.154], [64625.0, 1.489], [64625.1, 3.888], [64625.5, 0.001], [64640.1, 0.009], [64647.0, 1.548], [64647.8, 6.468], [64679.1, 0.317], [64679.2, 0.001], [64679.8, 0.008], [64903.5, 4.77], [65226.4, 1.36], [65355.6, 59.153], [65413.7, 2.452], [65517.0, 28.487], [65613.8, 3.198]]}
{"kind": "depth", "E": 1787089926417, "U": 11316020941706, "u": 11316020950409, "recv_ms": 1787089926385, "bids": [[1000.0, 36.16], [14180.5, 0.952], [14280.5, 3.248], [14380.5, 0.0], [51664.4, 0.0], [58122.4, 0.004], [61351.4, 0.03], [61997.2, 0.003], [63288.9, 4.261], [63482.6, 12.158], [63580.5, 0.026], [63610.1, 0.013], [63669.9, 5.682], [63934.7, 3.974], [64487.5, 0.486], [64561.4, 0.003], [64563.2, 0.049], [64568.1, 0.31], [64568.9, 0.309], [64572.2, 0.002], [64574.6, 0.202], [64574.9, 0.075], [64575.4, 0.007], [64576.3, 1.635], [64576.8, 0.01], [64578.1, 0.009], [64580.5, 2.246]], "asks": [[64580.6, 42.822], [64585.5, 0.002], [64587.5, 0.74], [64589.4, 0.206], [64589.6, 0.257], [64590.4, 0.015], [64591.1, 0.0], [64592.0, 0.08], [64592.7, 0.008], [64597.2, 0.361], [64597.3, 0.101], [64597.7, 0.929], [64598.7, 2.57], [64600.4, 0.623], [64601.1, 0.38], [65226.4, 1.36], [65288.1, 0.03], [65387.9, 18.158], [65420.2, 7.558], [65580.6, 0.03], [65613.9, 9.101], [65993.9, 0.0]]}
{"kind": "depth", "E": 1787089926519, "U": 11316020950435, "u": 11316020958432, "recv_ms": 1787089926483, "bids": [[14180.5, 1.302], [14280.5, 2.898], [51664.0, 0.0], [58122.4, 0.004], [61351.4, 0.03], [63811.9, 8.143], [63934.7, 3.972], [64257.6, 6.509], [64474.6, 10.001], [64495.3, 31.907], [64508.5, 1.806], [64539.1, 0.08], [64546.0, 3.069], [64558.7, 0.0], [64559.6, 0.12], [64567.2, 0.002], [64577.5, 0.003], [64578.1, 0.011], [64580.2, 0.0], [64580.5, 2.552]], "asks": [[64580.6, 42.93], [64587.4, 0.001], [64587.5, 0.106], [64587.8, 0.309], [64591.1, 0.634], [64597.7, 0.002], [64598.1, 0.956], [64600.4, 0.004], [64606.0, 0.01], [64680.1, 10.002], [65226.4, 1.36], [65291.0, 9.596], [65491.2, 7.173], [66515.1, 0.003]]}
{"kind": "depth", "E": 1787089926621, "U": 11316020958609, "u": 11316020965159, "recv_ms": 1787089926590, "bids": [[1000.0, 36.31], [14180.5, 1.652], [14280.5, 2.548], [58122.4, 0.004], [61997.2, 0.0], [63580.5, 0.006], [63812.0, 3.957], [63934.7, 3.972], [64257.5, 0.312], [64305.0, 0.161], [64314.8, 0.356], [64495.3, 0.01], [64503.0, 0.023], [64508.5, 33.703], [64534.0, 0.001], [64541.5, 0.026], [64544.3, 0.001], [64564.9, 0.016], [64565.8, 3.265], [64580.5, 2.553]], "asks": [[64580.6, 42.93], [64587.5, 0.74], [64591.1, 0.0], [64595.8, 0.017], [64596.5, 0.578], [64622.7, 0.154], [64622.8, 0.0], [64774.2, 1.044], [65226.4, 1.36], [65580.6, 0.01]]}
{"kind": "depth", "E": 1787089926723, "U": 11316020965194, "u": 11316020971637, "recv_ms": 1787089926688, "bids": [[1000.0, 36.16], [14180.5, 2.016], [14280.5, 2.184], [58122.4, 0.004], [61997.2, 0.003], [63934.7, 3.972], [64257.5, 0.311], [64508.7, 7.954], [64546.0, 2.155], [64546.1, 1.427]], "asks": [[64603.5, 0.014], [64604.1, 0.007], [64622.7, 0.0], [64622.8, 0.0], [65226.4, 1.36], [65296.3, 0.458], [65888.0, 7.167], [66066.0, 4.317]]}
{"kind": "depth", "E": 1787089926825, "U": 11316020971810, "u": 11316020978791, "recv_ms": 1787089926789, "bids": [[14180.5, 2.366], [14280.5, 1.834], [58122.4, 0.004], [61351.4, 0.03], [61351.5, 0.006], [61351.6, 0.014], [61997.2, 0.0], [63580.5, 0.026], [63887.6, 0.002], [63926.3, 0.027], [63932.7, 0.0], [63934.7, 3.972], [63954.6, 1.56], [63988.6, 0.234], [64257.6, 6.664], [64294.1, 0.159], [64298.5, 0.109], [64304.9, 0.003], [64305.0, 0.157], [64383.6, 2.565], [64422.4, 2.053], [64424.2, 1.285], [64439.3, 3.705], [64517.5, 0.003], [64517.6, 0.994], [64547.6, 0.024], [64547.7, 0.006], [64547.8, 0.003], [64551.1, 0.002], [64551.2, 0.005], [64551.3, 2.322]], "asks": [[64580.6, 42.93], [64622.8, 0.0], [64622.9, 0.256], [64643.6, 0.0], [64720.4, 1.243], [64720.5, 5.423], [64737.4, 0.002], [64737.5, 10.428], [64903.6, 0.002], [65226.4, 1.36], [65298.0, 2.055], [65387.9, 17.815], [65516.9, 10.799], [65580.6, 0.03], [65872.2, 7.666]]}
{"kind": "depth", "E": 1787089927029, "U": 11316020985553, "u": 11316020991897, "recv_ms": 1787089926993, "bids": [[1000.0, 36.16], [14180.5, 3.094], [14280.5, 1.106], [58122.4, 0.004], [61997.2, 0.003], [63580.5, 0.006], [63859.5, 8.052], [63902.0, 1.174], [63934.7, 3.972], [63967.0, 20.009], [63999.3, 10.955], [64304.9, 0.007], [64312.1, 0.0], [64424.2, 1.96], [64503.0, 0.02], [64522.3, 0.0], [64534.0, 0.015], [64534.6, 2.514], [64571.8, 0.292], [64572.3, 0.004], [64576.3, 1.551], [64580.5, 2.552]], "asks": [[64582.2, 0.021], [64582.5, 0.024], [64582.9, 0.274], [64638.8, 0.0], [64658.1, 0.018], [65226.4, 1.36], [65298.3, 4.592], [65580.6, 0.01], [66066.0, 5.073]]}
{"kind": "depth", "E": 1787089927131, "U": 11316020991956, "u": 11316020998106, "recv_ms": 1787089927094, "bids": [[14180.5, 3.444], [14280.5, 0.756], [58122.4, 0.004], [61351.4, 0.03], [61997.2, 0.0], [63599.5, 5.544], [63664.1, 0.0], [63665.3, 0.188], [63733.9, 1.111], [63773.2, 23.394], [63811.9, 6.265], [63812.0, 4.896], [63870.1, 7.428], [63934.7, 3.972], [64257.6, 6.664], [64383.6, 9.178], [64422.4, 5.641], [64439.3, 5.62], [64508.8, 1.728], [64531.9, 0.095], [64537.1, 0.015], [64563.7, 0.003], [64568.8, 0.192]], "asks": [[64587.0, 0.47], [64589.9, 0.084], [64596.1, 0.003], [65226.4, 1.362], [65495.9, 0.002], [65497.1, 0.004], [65516.9, 9.732], [65517.0, 29.554], [65561.7, 0.022], [65788.3, 4.777]]}
{"kind": "depth", "E": 1787089927233, "U": 11316020998191, "u": 11316021004013, "recv_ms": 1787089927197, "bids": [[1000.0, 36.16], [14080.5, 0.042], [14180.5, 3.71], [14280.5, 0.448], [51664.0, 0.0], [58122.4, 0.004], [61351.4, 0.036], [61997.2, 0.003], [63580.5, 0.026], [63599.5, 5.552], [63664.1, 0.008], [63665.3, 0.196], [63812.0, 5.835], [63934.7, 3.972], [63977.1, 0.0], [64517.5, 0.003], [64529.0, 0.091], [64577.5, 0.001], [64578.1, 0.009], [64580.1, 0.002], [64580.5, 2.554]], "asks": [[64643.5, 0.013], [65000.0, 116.945], [65226.4, 1.36], [65497.1, 0.012], [65517.0, 30.621], [65561.7, 0.03], [65580.6, 0.03], [65581.5, 4.272], [65581.6, 26.603]]}
{"kind": "depth", "E": 1787089927335, "U": 11316021004324, "u": 11316021011679, "recv_ms": 1787089927299, "bids": [[1000.0, 36.16], [14080.5, 0.224], [14180.5, 3.71], [14280.5, 0.266], [58122.4, 0.004], [61351.4, 0.036], [61997.2, 0.0], [63663.5, 3.54], [63934.7, 3.972], [64383.6, 9.14], [64422.4, 5.631], [64439.3, 5.616], [64517.6, 5.945]], "asks": [[64580.6, 42.93], [64643.5, 2.22], [65226.4, 1.36], [65495.9, 0.01], [65517.3, 0.534], [65788.3, 5.383], [65888.0, 7.217]]}
{"kind": "depth", "E": 1787089927437, "U": 11316021011887, "u": 11316021018293, "recv_ms": 1787089927402, "bids": [[14080.5, 0.462], [14180.5, 3.584], [14280.5, 0.154], [51664.0, 0.0], [51664.4, 0.0], [58122.4, 0.004], [61351.3, 0.026], [63411.4, 2.702], [63580.5, 0.006], [63773.2, 23.628], [63934.7, 3.972], [63994.1, 3.328], [64257.6, 6.664], [64403.3, 0.001]], "asks": [[64622.8, 0.154], [64622.9, 0.102], [65226.4, 1.36], [65387.9, 17.587], [65492.1, 1.526], [65580.6, 0.01]]}
{"kind": "depth", "E": 1787089927539, "U": 11316021018513, "u": 11316021025259, "recv_ms": 1787089927503, "bids": [[1000.0, 36.16], [14080.5, 0.7], [14180.5, 3.472], [14280.5, 0.028], [58122.4, 0.004], [61351.4, 0.036], [61351.5, 0.004], [61351.6, 0.016], [61997.2, 0.003], [63859.5, 7.817], [63934.7, 3.972], [63983.2, 0.0], [64115.5, 0.312], [64304.9, 0.003], [64312.1, 0.004], [64383.6, 9.14], [64422.4, 5.631], [64439.3, 5.616], [64517.6, 5.945], [64566.1, 0.619], [64573.0, 0.221], [64576.1, 0.344], [64576.3, 0.003], [64576.7, 1.559]], "asks": [[64580.6, 42.995], [64580.9, 0.049], [64597.6, 0.627], [64604.9, 0.693], [64622.8, 0.154], [64643.5, 2.226], [64720.5, 5.423], [64737.5, 10.428], [65226.4, 1.36]]}
{"kind": "depth", "E": 1787089927641, "U": 11316021025476, "u": 11316021031568, "recv_ms": 1787089927604, "bids": [[1000.0, 36.16], [14080.5, 1.022], [14180.5, 3.178], [14280.5, 0.0], [58122.4, 0.006], [61351.4, 0.036], [61351.6, 0.014], [61997.2, 0.0], [63401.9, 0.004], [63580.5, 0.026], [63934.7, 3.972], [64304.9, 0.007], [64312.1, 0.0]], "asks": [[64580.6, 42.96], [64597.6, 0.008], [64609.4, 0.003], [64609.5, 0.014], [64609.6, 7.132], [64612.4, 0.003], [64612.5, 0.002], [64612.6, 0.002], [64613.3, 0.002], [64613.4, 0.095], [64613.5, 0.007], [64615.4, 0.031], [64615.5, 0.003], [64615.6, 0.003], [64774.2, 1.045], [65226.4, 1.36], [65355.8, 2.716], [65529.9, 18.502], [65580.6, 0.03]]}
{"kind": "depth", "E": 1787089927743, "U": 11316021031618, "u": 11316021038049, "recv_ms": 1787089927708, "bids": [[14080.5, 1.386], [14180.5, 2.814], [58122.4, 0.004], [61997.2, 0.003], [63595.5, 1.553], [63663.5, 3.07], [63934.7, 3.972], [64063.8, 1.558], [64257.6, 6.664], [64517.6, 4.958], [64517.7, 1.741]], "asks": [[64622.8, 0.154], [64640.3, 0.205], [65029.9, 0.191], [65226.4, 1.36], [65290.2, 0.0], [65387.9, 17.815], [65517.3, 0.0], [71038.7, 0.003]]}
{"kind": "depth", "E": 1787089927845, "U": 11316021038098, "u": 11316021045131, "recv_ms": 1787089927810, "bids": [[1000.0, 36.16], [14080.5, 1.736], [14180.5, 2.464], [51664.0, 0.0], [58122.4, 0.004], [61351.4, 0.042], [61997.2, 0.0], [63580.5, 0.006], [63805.5, 64.233], [63870.1, 7.663], [63934.7, 3.972], [64016.3, 0.932], [64257.5, 0.313], [64304.9, 0.003], [64311.8, 0.006], [64315.6, 0.025], [64341.4, 0.002], [64367.2, 2.617], [64393.1, 0.0], [64418.9, 0.017], [64471.1, 2.323], [64474.0, 2.43], [64551.6, 0.107], [64552.9, 0.057], [64559.8, 0.0], [64561.3, 0.567], [64563.1, 3.687], [64563.6, 0.008], [64564.1, 0.0], [64580.5, 2.556]], "asks": [[64580.6, 42.958], [64598.1, 0.029], [64598.6, 2.737], [64601.0, 0.0], [64601.5, 1.798], [64602.4, 0.022], [64603.1, 0.116], [64604.2, 0.009], [64604.7, 0.065], [64622.7, 0.154], [64622.8, 0.0], [64687.7, 2.323], [64737.5, 10.428], [64737.9, 0.0], [64903.6, 0.0], [65038.0, 0.821], [65181.5, 0.459], [65226.4, 1.36], [65440.5, 0.633], [65580.6, 0.01], [65872.2, 7.663], [71038.7, 0.002]]}
{"kind": "depth", "E": 1787089927947, "U": 11316021045472, "u": 11316021051707, "recv_ms": 1787089927911, "bids": [[1000.0, 36.16], [14080.5, 2.1], [14180.5, 2.1], [58122.4, 0.004], [61351.4, 0.042], [61351.6, 0.012], [63934.7, 3.972], [64063.9, 8.883], [64475.7, 0.009], [64560.6, 0.56], [64561.3, 0.009], [64575.3, 1.813], [64576.1, 0.428], [64576.7, 1.561], [64577.4, 0.003], [64578.1, 0.011], [64580.1, 0.0], [64580.5, 2.55]], "asks": [[64580.6, 42.947], [64622.7, 0.154], [65226.4, 1.36], [65529.9, 19.035]]}
{"kind": "depth", "E": 1787089928151, "U": 11316021058320, "u": 11316021064509, "recv_ms": 1787089928115, "bids": [[1000.0, 36.16], [14080.5, 2.814], [14180.5, 1.386], [51664.0, 0.0], [58122.4, 0.004], [61351.4, 0.042], [61997.2, 0.0], [63580.5, 0.026], [63599.4, 0.02], [63599.5, 5.542], [63611.4, 2.355], [63934.7, 3.972], [64063.8, 1.247], [64508.7, 7.956], [64508.8, 1.727], [64529.0, 0.09], [64531.9, 0.094], [64536.5, 0.681], [64537.1, 0.014], [64563.7, 0.003], [64568.9, 0.309], [64573.6, 0.003], [64574.7, 0.071], [64575.3, 0.086], [64578.9, 0.002]], "asks": [[64580.6, 42.932], [64596.1, 0.003], [64622.7, 0.154], [65226.4, 1.36], [65452.4, 18.405], [65561.7, 0.02], [65580.6, 0.03]]}
{"kind": "depth", "E": 1787089928253, "U": 11316021064750, "u": 11316021073038, "recv_ms": 1787089928217, "bids": [[1000.0, 36.16], [14080.5, 3.164], [14180.5, 1.036], [51664.0, 0.004], [58122.4, 0.004], [61997.2, 0.003], [63870.1, 7.898], [63934.7, 3.972], [64030.0, 1.45], [64519.1, 0.021]], "asks": [[64622.7, 0.0], [64622.8, 0.154], [64658.1, 0.015], [65226.4, 1.36], [65355.5, 6.998], [65491.2, 8.087], [65516.9, 8.665], [65561.6, 0.026], [65872.2, 7.666]]}
{"kind": "depth", "E": 1787089928355, "U": 11316021073120, "u": 11316021082052, "recv_ms": 1787089928324, "bids": [[14080.5, 3.528], [14180.5, 0.672], [51664.0, 0.0], [58122.4, 0.004], [61351.4, 0.042], [63580.5, 0.006], [63934.7, 3.972], [64063.9, 9.194], [64257.6, 6.664], [64304.8, 0.003], [64311.8, 0.002], [64311.9, 0.088], [64422.4, 0.007], [64424.2, 1.285], [64439.3, 2.319], [64527.2, 0.065], [64527.7, 0.363], [64535.2, 0.064], [64567.5, 0.053]], "asks": [[64580.6, 42.932], [64618.4, 0.02], [64619.2, 2.633], [64626.6, 2.637], [64632.3, 0.006], [64638.8, 0.003], [64659.0, 0.0], [64659.9, 2.332], [64660.7, 0.07], [64661.8, 0.063], [64720.5, 0.015], [64737.5, 0.001], [64903.5, 4.924], [65226.4, 1.36], [65226.5, 0.004], [65516.9, 7.598], [65580.6, 0.01], [65904.5, 5.758]]}
{"kind": "depth", "E": 1787089928457, "U": 11316021082211, "u": 11316021090082, "recv_ms": 1787089928421, "bids": [[1000.0, 36.16], [14080.5, 3.738], [14180.5, 0.392], [14480.5, 0.07], [51664.4, 0.0], [58122.4, 0.004], [61997.2, 0.0], [63934.7, 3.972], [64422.4, 5.607], [64439.3, 5.602], [64485.7, 0.108], [64522.3, 0.003], [64572.6, 0.002], [64576.6, 1.813]], "asks": [[64622.8, 0.154], [64658.1, 0.018], [64709.2, 0.243], [64720.5, 5.423], [64737.5, 10.428], [65226.4, 1.36], [65355.6, 59.764], [65517.0, 32.755]]}
{"kind": "depth", "E": 1787089928559, "U": 11316021090377, "u": 11316021097867, "recv_ms": 1787089928524, "bids": [[1000.0, 36.16], [14080.5, 3.682], [14180.5, 0.238], [14480.5, 0.28], [58122.4, 0.004], [61351.3, 0.014], [61351.4, 0.042], [61997.2, 0.003], [63580.5, 0.026], [63934.7, 3.972], [64422.3, 4.791], [64422.4, 0.007], [64439.3, 5.177], [64565.6, 0.216], [64568.2, 0.305], [64570.4, 0.004], [64570.9, 0.003], [64571.6, 0.002], [64573.2, 0.002], [64573.6, 0.006], [64575.8, 0.034], [64576.8, 0.0]], "asks": [[64580.6, 42.978], [64582.6, 0.005], [64585.1, 0.091], [64586.5, 0.021], [64588.4, 1.962], [64593.1, 0.008], [64597.9, 0.62], [64720.5, 5.423], [64737.5, 10.428], [65226.4, 1.36], [65349.0, 4.808], [65387.9, 18.158], [65516.9, 6.531], [65580.6, 0.03], [65613.8, 2.132]]}
{"kind": "depth", "E": 1787089928661, "U": 11316021098031, "u": 11316021104406, "recv_ms": 1787089928625, "bids": [[1000.0, 35.76], [14080.5, 3.542], [14180.5, 0.126], [14480.5, 0.532], [58122.4, 0.002], [61351.4, 0.048], [61997.2, 0.0], [63934.7, 3.972], [64257.6, 6.654], [64304.8, 0.007], [64311.9, 0.084], [64576.9, 0.011]], "asks": [[64622.6, 0.077], [64622.7, 0.154], [64622.8, 0.0], [65226.4, 1.36]]}
{"kind": "depth", "E": 1787089928763, "U": 11316021104414, "u": 11316021110269, "recv_ms": 1787089928728, "bids": [[1000.0, 35.76], [14080.5, 3.444], [14180.5, 0.0], [14480.5, 0.756], [58122.4, 0.004], [61351.4, 0.048], [61351.5, 0.002], [61351.6, 0.014], [61997.2, 0.003], [63547.1, 1.102], [63580.5, 0.006], [63644.0, 3.368], [63697.0, 3.294], [63773.2, 24.128], [63934.7, 3.972], [64420.3, 0.0], [64422.4, 0.965], [64439.3, 5.384], [64530.9, 1.261], [64576.9, 0.001]], "asks": [[64580.6, 42.978], [64622.6, 0.231], [64622.7, 0.0], [64720.4, 1.891], [64720.5, 5.423], [65226.4, 1.36], [65349.1, 7.336], [65517.0, 33.822], [65580.6, 0.01], [65613.9, 10.167], [66487.1, 0.0]]}
{"kind": "depth", "E": 1787089928967, "U": 11316021116696, "u": 11316021123434, "recv_ms": 1787089928948, "bids": [[14080.5, 2.73], [14480.5, 1.47], [58122.4, 0.004], [61351.3, 0.008], [61351.6, 0.012], [61997.2, 0.0], [63580.5, 0.026], [63708.7, 16.036], [63773.2, 23.426], [63934.7, 3.972], [64257.6, 6.664], [64576.9, 0.001]], "asks": [[64622.6, 0.231], [65226.4, 1.36], [65580.6, 0.03], [65613.8, 1.067]]}
{"kind": "depth", "E": 1787089929069, "U": 11316021123617, "u": 11316021130456, "recv_ms": 1787089929033, "bids": [[1000.0, 35.76], [14080.5, 2.366], [14480.5, 1.834], [58122.4, 0.004], [61997.2, 0.003], [63547.2, 8.773], [63644.1, 34.601], [63663.5, 3.54], [63916.5, 0.0], [63934.7, 3.972], [64568.9, 0.309], [64576.9, 0.011]], "asks": [[64622.6, 0.231], [65226.4, 1.36], [65298.5, 0.818], [65581.5, 3.207], [65581.6, 27.668]]}
{"kind": "depth", "E": 1787089929171, "U": 11316021130551, "u": 11316021138548, "recv_ms": 1787089929135, "bids": [[1000.0, 35.76], [14080.5, 2.016], [14480.5, 2.184], [51664.0, 0.0], [58122.4, 0.004], [61997.2, 0.0], [63580.5, 0.006], [63924.8, 0.003], [63934.7, 3.972], [64508.8, 1.728], [64537.1, 0.015], [64563.7, 0.001], [64576.9, 0.001]], "asks": [[64584.8, 0.313], [64587.0, 0.469], [64596.1, 0.001], [64622.6, 0.077], [64622.7, 0.154], [65226.4, 1.36], [65323.6, 5.56], [65362.8, 2.311], [65387.9, 18.158], [65580.6, 0.01], [65613.9, 11.232], [65646.2, 3.378], [65872.2, 7.669]]}
{"kind": "depth", "E": 1787089929273, "U": 11316021138740, "u": 11316021145509, "recv_ms": 1787089929236, "bids": [[14080.5, 1.666], [14480.5, 2.534], [58122.4, 0.004], [61351.4, 0.048], [61997.2, 0.003], [63934.7, 3.972], [64257.6, 6.654], [64383.6, 4.746], [64422.3, 3.082], [64422.4, 0.007], [64439.3, 4.509], [64529.1, 0.001], [64531.9, 0.095], [64563.7, 0.003], [64576.9, 0.001]], "asks": [[64580.6, 42.978], [64596.1, 0.003], [64609.4, 0.001], [64609.5, 0.012], [64609.6, 7.13], [64612.4, 0.001], [64612.5, 0.0], [64612.6, 0.0], [64613.3, 0.0], [64613.4, 0.093], [64613.5, 0.005], [64615.4, 0.029], [64615.5, 0.001], [64615.6, 0.001], [64622.7, 0.154], [64720.4, 1.243], [64720.5, 5.423], [64737.5, 10.428], [64903.6, 0.002], [65226.4, 1.36], [65226.5, 0.003], [65296.2, 0.229], [65581.5, 2.141], [65613.8, 0.001]]}
{"kind": "depth", "E": 1787089929375, "U": 11316021145618, "u": 11316021153193, "recv_ms": 1787089929339, "bids": [[1000.0, 35.76], [14080.5, 1.302], [14480.5, 2.898], [58122.4, 0.004], [63579.4, 0.949], [63580.5, 0.026], [63644.0, 2.27], [63644.1, 34.719], [63934.7, 3.972], [63988.6, 0.0], [63999.3, 13.295], [64451.3, 0.011], [64465.3, 0.613], [64467.9, 0.008], [64576.9, 0.001]], "asks": [[64580.6, 43.016], [64712.1, 0.012], [65226.4, 1.36], [65336.2, 5.885], [65580.6, 0.03], [65581.6, 28.734]]}
{"kind": "depth", "E": 1787089929477, "U": 11316021153407, "u": 11316021161333, "recv_ms": 1787089929442, "bids": [[1000.0, 35.76], [14080.5, 0.952], [14480.5, 3.248], [34000.0, 1.146], [51664.4, 0.0], [58122.4, 0.004], [61351.4, 0.048], [61997.2, 0.0], [63410.8, 1.576], [63934.7, 3.972], [63965.3, 0.937], [63999.3, 13.529], [64257.6, 6.664], [64383.6, 9.18], [64422.3, 5.637], [64439.3, 5.614], [64451.0, 2.497], [64461.6, 3.872], [64463.8, 0.009], [64471.1, 0.0], [64472.1, 3.154], [64480.6, 1.331], [64480.7, 0.096], [64509.3, 0.06], [64552.4, 0.064], [64552.9, 0.0], [64559.9, 0.003], [64561.9, 0.009], [64563.2, 0.041], [64564.9, 0.008], [64566.1, 0.0], [64566.2, 0.01], [64572.6, 0.086], [64572.8, 2.34], [64573.6, 0.004], [64574.7, 0.074], [64574.9, 0.072], [64575.4, 2.323], [64575.7, 0.0], [64576.1, 0.344], [64576.3, 1.559], [64576.6, 1.729], [64576.7, 0.013], [64578.0, 0.854], [64578.1, 0.003], [64580.5, 2.236]], "asks": [[64580.6, 43.017], [64584.1, 0.315], [64584.8, 0.312], [64595.8, 0.559], [64596.5, 0.036], [64596.9, 0.003], [64597.9, 0.001], [64622.7, 0.0], [64622.8, 0.154], [64640.1, 0.0], [64651.4, 0.022], [64651.5, 0.046], [64687.7, 2.323], [64710.2, 0.989], [64717.3, 3.871], [64721.1, 0.008], [64722.3, 1.47], [64771.2, 0.0], [64771.3, 0.003], [65226.4, 1.36], [65298.0, 2.82], [65872.2, 7.66], [65967.9, 0.0]]}
{"kind": "depth", "E": 1787089929579, "U": 11316021161390, "u": 11316021168658, "recv_ms": 1787089929543, "bids": [[14080.5, 0.588], [14480.5, 3.612], [58122.4, 0.004], [61997.2, 0.003], [63579.5, 29.529], [63580.5, 0.006], [63604.5, 2.36], [63644.1, 35.817], [63773.2, 23.161], [63789.4, 0.006], [63934.7, 3.972], [64304.8, 0.003], [64314.6, 0.004], [64522.1, 0.002], [64522.3, 0.0], [64522.4, 0.205], [64522.7, 0.056], [64523.1, 0.082], [64523.4, 0.014], [64535.2, 0.064], [64539.8, 0.034], [64540.1, 0.415], [64540.4, 2.326], [64540.8, 0.039], [64541.1, 0.126], [64554.7, 0.047], [64554.8, 0.003], [64554.9, 0.003], [64555.0, 0.003], [64555.1, 0.0], [64555.2, 1.111], [64555.3, 0.0], [64555.4, 0.001], [64555.5, 1.302], [64555.6, 0.14], [64556.7, 0.003], [64557.1, 0.022], [64564.9, 0.001], [64566.0, 0.21], [64566.2, 0.002], [64566.7, 0.007], [64570.0, 0.004], [64573.0, 0.646], [64573.1, 0.01], [64573.9, 0.003], [64574.0, 0.019], [64574.1, 0.28], [64574.2, 0.012], [64574.3, 0.0], [64574.4, 0.087], [64574.5, 0.0], [64574.6, 0.002], [64574.7, 0.004], [64574.8, 0.098], [64574.9, 0.072], [64575.2, 0.033], [64575.5, 0.033], [64575.8, 0.002], [64576.1, 0.344], [64576.3, 1.551], [64576.4, 0.126], [64578.0, 0.639]], "asks": [[64583.9, 0.011], [64586.9, 0.074], [64587.2, 0.111], [64587.5, 0.023], [64587.8, 0.383], [64587.9, 0.235], [64588.2, 0.379], [64588.4, 2.123], [64588.5, 0.009], [64588.6, 0.014], [64588.7, 0.002], [64588.8, 1.067], [64588.9, 0.002], [64589.0, 0.002], [64589.1, 0.001], [64589.2, 0.155], [64589.3, 0.08], [64589.4, 0.059], [64589.5, 0.164], [64590.5, 0.637], [64604.5, 0.074], [64604.6, 0.098], [64604.9, 0.693], [64605.2, 0.163], [64605.5, 0.089], [64605.6, 0.035], [64605.9, 2.389], [64606.3, 0.003], [64606.7, 0.008], [64607.7, 0.185], [64607.9, 0.004], [64608.0, 0.459], [64608.1, 0.061], [64608.2, 0.0], [64608.3, 0.0], [64608.4, 1.393], [64608.5, 0.105], [64608.6, 0.013], [64608.7, 0.024], [64622.2, 0.115], [64622.3, 1.618], [64622.6, 0.077], [64622.8, 0.0], [64622.9, 0.173], [64623.2, 0.079], [64623.5, 0.089], [64623.6, 0.019], [64638.8, 0.003], [64656.5, 0.019], [64658.1, 0.015], [64773.8, 0.012], [65169.8, 0.0], [65226.4, 1.36], [65580.6, 0.01]]}
{"kind": "depth", "E": 1787089929681, "U": 11316021168752, "u": 11316021176445, "recv_ms": 1787089929646, "bids": [[1000.0, 35.76], [14080.5, 0.336], [14380.5, 0.098], [14480.5, 3.766], [58122.4, 0.004], [61351.4, 0.054], [61997.2, 0.0], [63611.0, 1.512], [63934.7, 3.972], [64257.5, 0.156], [64540.4, 2.358], [64560.6, 1.179], [64566.0, 0.759], [64566.7, 0.015], [64568.0, 0.006], [64573.0, 0.097], [64573.1, 0.002], [64574.2, 0.082], [64574.5, 0.17], [64575.8, 0.034], [64580.5, 2.236]], "asks": [[64580.6, 43.646], [64583.3, 0.002], [64583.9, 0.001], [64587.5, 0.106], [64588.8, 1.193], [64588.9, 0.222], [64589.1, 0.141], [64599.4, 0.637], [64605.2, 0.246], [64608.0, 0.585], [64608.1, 0.281], [64608.3, 0.15], [64622.9, 0.102], [64623.1, 0.213], [65226.4, 1.36], [65355.5, 6.54], [65355.6, 59.0]]}
{"kind": "depth", "E": 1787089929885, "U": 11316021183742, "u": 11316021192937, "recv_ms": 1787089929850, "bids": [[14080.5, 0.098], [14380.5, 0.588], [14480.5, 3.514], [58122.4, 0.004], [61351.4, 0.054], [61997.2, 0.003], [63580.5, 0.006], [63934.7, 3.972], [64050.2, 0.006], [64304.7, 0.011], [64314.6, 0.0], [64383.6, 0.99], [64422.3, 1.559], [64422.4, 0.007], [64439.3, 3.448], [64508.1, 0.041], [64517.6, 0.007], [64517.7, 1.002], [64522.1, 0.034], [64522.4, 0.237], [64522.7, 0.088], [64523.1, 0.114], [64523.4, 0.046], [64543.1, 14.016], [64543.2, 2.421], [64546.0, 0.155], [64574.0, 0.089], [64574.3, 0.2], [64574.6, 0.202], [64575.8, 0.118], [64580.5, 2.238]], "asks": [[64580.6, 43.646], [64587.5, 0.198], [64588.7, 0.282], [64589.0, 0.792], [64589.4, 0.353], [64590.5, 0.545], [64607.9, 0.284], [64608.3, 0.42], [64608.6, 0.307], [64643.5, 0.002], [64655.6, 0.012], [64720.4, 0.0], [64720.5, 5.423], [64737.4, 10.429], [64737.5, 0.001], [65226.4, 1.36], [65355.0, 7.452], [65516.9, 4.397], [65580.6, 0.01]]}
{"kind": "depth", "E": 1787089929987, "U": 11316021193004, "u": 11316021199627, "recv_ms": 1787089929951, "bids": [[1000.0, 35.76], [14080.5, 0.0], [14380.5, 0.84], [14480.5, 3.36], [58122.4, 0.004], [61351.4, 0.054], [61997.2, 0.0], [63547.1, 0.002], [63644.0, 1.172], [63644.1, 35.66], [63811.9, 5.326], [63934.7, 3.972], [64383.6, 9.112], [64422.3, 4.851], [64439.3, 5.203], [64469.0, 0.092], [64469.1, 12.758], [64470.2, 4.409], [64517.6, 4.939], [64554.9, 0.073], [64555.6, 0.21], [64561.8, 0.009], [64561.9, 0.001], [64563.3, 0.23], [64563.4, 0.231], [64566.1, 0.0], [64576.7, 0.013], [64580.5, 2.237]], "asks": [[64580.9, 0.058], [64587.4, 0.551], [64587.5, 0.19], [64590.5, 0.003], [64592.1, 0.001], [64593.1, 0.008], [64595.8, 0.017], [64596.9, 0.545], [64643.5, 2.215], [64691.8, 1.049], [64691.9, 11.746], [64692.0, 0.062], [64720.5, 5.423], [65226.4, 1.36], [65355.6, 59.458]]}
{"kind": "depth", "E": 1787089930089, "U": 11316021199801, "u": 11316021208381, "recv_ms": 1787089930055, "bids": [[1000.0, 35.76], [14380.5, 1.19], [14480.5, 3.01], [58122.4, 0.004], [61997.2, 0.003], [63288.9, 4.264], [63599.5, 5.534], [63934.7, 3.972], [64257.6, 6.809], [64304.7, 0.007], [64312.2, 1.782], [64470.2, 6.141], [64526.2, 0.029], [64533.1, 0.081], [64533.9, 0.014], [64534.0, 0.001], [64544.3, 0.015], [64554.8, 0.073], [64555.0, 0.103], [64555.1, 0.07], [64565.5, 0.927], [64565.8, 2.338], [64565.9, 0.039], [64566.5, 0.543], [64568.9, 0.309], [64580.5, 2.232]], "asks": [[64580.6, 43.647], [64595.8, 0.559], [64596.9, 0.003], [64598.0, 0.933], [64598.6, 1.81], [64600.6, 0.186], [64604.1, 0.064], [64604.3, 0.442], [64604.7, 0.008], [64607.1, 0.154], [64610.7, 0.001], [64613.5, 0.159], [64617.4, 0.0], [64636.5, 0.062], [64637.3, 1.191], [64691.8, 2.322], [64697.4, 0.165], [65226.4, 1.36], [65517.0, 34.737], [65561.7, 0.012], [65613.3, 0.003]]}
{"kind": "depth", "E": 1787089930191, "U": 11316021208676, "u": 11316021217594, "recv_ms": 1787089930155, "bids": [[14380.5, 1.554], [14480.5, 2.646], [58122.4, 0.004], [61351.4, 0.054], [61997.2, 0.0], [63547.2, 9.873], [63580.5, 0.026], [63599.5, 5.542], [63644.1, 36.758], [63793.2, 12.993], [63812.0, 6.774], [63934.7, 3.972], [63954.6, 0.858], [63967.0, 20.711], [64063.8, 0.936], [64410.0, 1.146], [64508.8, 1.729], [64529.1, 0.0], [64531.9, 0.094], [64537.1, 0.014], [64554.5, 0.382], [64554.6, 1.322], [64554.7, 0.117], [64554.9, 0.173], [64555.1, 0.17], [64555.3, 0.07], [64556.4, 0.1], [64556.9, 0.102], [64563.7, 0.001], [64580.5, 2.233]], "asks": [[64580.6, 43.649], [64586.8, 0.003], [64596.1, 0.001], [65226.4, 1.36], [65517.0, 35.804], [65580.6, 0.03], [65872.2, 7.657]]}
{"kind": "depth", "E": 1787089930293, "U": 11316021217757, "u": 11316021224918, "recv_ms": 1787089930257, "bids": [[1000.0, 35.76], [14380.5, 1.904], [14480.5, 2.296], [51664.0, 0.0], [58122.4, 0.004], [63805.5, 65.798], [63934.7, 3.972], [64554.5, 0.452], [64554.8, 0.173], [64555.2, 1.211], [64563.7, 0.003]], "asks": [[64596.1, 0.003], [64903.6, 0.0], [65175.1, 0.003], [65226.4, 1.36], [65355.8, 1.952], [65388.1, 0.765], [65484.1, 6.506], [65561.7, 0.02], [65613.9, 13.363]]}
{"kind": "depth", "E": 1787089930395, "U": 11316021225154, "u": 11316021232852, "recv_ms": 1787089930360, "bids": [[1000.0, 35.76], [14380.5, 2.268], [14480.5, 1.932], [51664.0, 0.0], [58122.4, 0.004], [61351.3, 0.004], [61351.4, 0.054], [61997.2, 0.003], [63580.5, 0.006], [63805.5, 65.016], [63934.7, 3.972], [64063.9, 9.505], [64257.5, 0.158], [64257.6, 6.819], [64312.2, 1.778], [64383.6, 2.58], [64422.3, 1.774], [64439.3, 3.476], [64517.6, 4.952], [64522.3, 0.003], [64580.5, 2.231]], "asks": [[64580.6, 43.646], [64595.7, 0.311], [64595.9, 1.037], [64597.0, 0.0], [64597.2, 0.98], [64598.4, 4.218], [64598.5, 10.002], [64598.6, 0.002], [64624.9, 0.254], [64643.5, 2.215], [64658.1, 0.018], [64709.8, 0.009], [64720.5, 5.423], [65226.4, 1.362], [65580.6, 0.01], [65838.7, 0.021]]}
{"kind": "depth", "E": 1787089930497, "U": 11316021232890, "u": 11316021240633, "recv_ms": 1787089930460, "bids": [[14380.5, 2.632], [14480.5, 1.568], [51664.4, 0.0], [58122.4, 0.004], [61997.2, 0.0], [63934.7, 3.972], [64304.7, 0.011], [64383.6, 7.806], [64422.3, 5.083], [64439.3, 5.323]], "asks": [[64580.6, 43.649], [64595.6, 0.001], [64597.1, 0.936], [64597.2, 0.361], [64608.3, 0.427], [64780.8, 3.138], [64780.9, 0.473], [64781.0, 16.692], [65167.2, 0.231], [65226.4, 1.36], [65743.1, 11.955]]}
{"kind": "depth", "E": 1787089930599, "U": 11316021240689, "u": 11316021246140, "recv_ms": 1787089930564, "bids": [[1000.0, 35.76], [14380.5, 2.982], [14480.5, 1.218], [51664.0, 0.0], [58122.4, 0.004], [61351.4, 0.054], [61997.2, 0.003], [63580.5, 0.026], [63934.7, 3.972], [64213.8, 1.802], [64214.1, 0.498], [64310.2, 0.0], [64310.3, 0.738], [64381.0, 0.0], [64381.1, 0.293], [64383.7, 1.884], [64561.8, 0.001], [64563.2, 0.049], [64563.4, 0.223], [64563.7, 0.011], [64563.9, 0.004], [64576.3, 1.551], [64576.4, 0.134], [64576.7, 0.005], [64578.1, 0.011]], "asks": [[64580.6, 43.71], [64587.4, 0.543], [64587.5, 0.198], [64591.1, 0.0], [64595.8, 0.017], [64596.5, 0.578], [64598.0, 0.006], [64598.3, 0.927], [64604.1, 0.007], [64604.3, 0.499], [64697.5, 0.208], [64778.4, 0.072], [64778.5, 0.001], [64849.6, 3.915], [64849.7, 0.0], [64944.9, 0.455], [64947.0, 0.015], [65226.4, 1.36], [65291.3, 1.622], [65387.9, 18.386], [65580.6, 0.03], [65872.2, 7.657], [66516.8, 0.644]]}
{"kind": "depth", "E": 1787089930701, "U": 11316021246326, "u": 11316021253107, "recv_ms": 1787089930664, "bids": [[1000.0, 35.76], [14380.5, 3.332], [14480.5, 0.868], [58122.4, 0.004], [61351.4, 0.054], [61351.6, 0.01], [61997.2, 0.0], [63773.2, 23.863], [63934.7, 3.972], [63947.8, 0.011], [63954.6, 0.156], [64098.2, 0.0], [64257.6, 6.819], [64304.7, 0.007], [64312.3, 0.468], [64561.9, 0.009], [64562.0, 0.311], [64563.2, 0.041], [64567.1, 0.635], [64577.4, 0.001], [64578.0, 0.647], [64578.1, 0.004], [64580.5, 2.236]], "asks": [[64580.6, 43.679], [64595.9, 1.579], [64596.5, 0.036], [64778.4, 0.0], [64780.8, 0.008], [64780.9, 0.545], [64781.0, 8.509], [65226.4, 1.36], [65355.6, 60.222], [65872.2, 7.66]]}
{"kind": "depth", "E": 1787089930803, "U": 11316021253134, "u": 11316021259616, "recv_ms": 1787089930767, "bids": [[14380.5, 3.696], [14480.5, 0.504], [51664.0, 0.0], [58122.4, 0.004], [63580.5, 0.006], [63934.7, 3.972], [64304.9, 34.156], [64363.0, 5.331], [64375.8, 27.162], [64381.1, 0.077], [64422.4, 1.009], [64503.0, 0.023], [64522.3, 0.0], [64535.2, 0.061], [64563.5, 0.069], [64563.7, 0.003], [64576.3, 1.559], [64576.4, 0.126], [64576.7, 0.023], [64578.0, 0.639]], "asks": [[64595.9, 1.037], [64596.5, 0.578], [64623.0, 0.187], [64623.1, 0.059], [64638.8, 0.003], [64658.1, 0.015], [64720.4, 1.472], [64780.2, 27.044], [64851.4, 35.392], [64948.7, 41.354], [65063.9, 0.0], [65213.5, 2.626], [65226.4, 1.36], [65580.6, 0.01]]}
{"kind": "depth", "E": 1787089930905, "U": 11316021259733, "u": 11316021267451, "recv_ms": 1787089930869, "bids": [[1000.0, 35.76], [14280.5, 0.154], [14380.5, 3.738], [14480.5, 0.308], [58122.4, 0.004], [61351.5, 0.004], [61997.2, 0.003], [63482.5, 0.0], [63611.7, 0.689], [63859.4, 0.781], [63934.7, 3.974], [63967.0, 21.413], [64576.7, 0.013]], "asks": [[64622.7, 0.154], [64623.0, 0.033], [64780.1, 0.072], [64780.9, 0.473], [64851.3, 5.274], [64947.6, 10.665], [65226.4, 1.36]]}
{"kind": "depth", "E": 1787089931007, "U": 11316021267529, "u": 11316021275120, "recv_ms": 1787089930971, "bids": [[14280.5, 0.392], [14380.5, 3.626], [14480.5, 0.182], [58122.4, 0.004], [61351.3, 0.0], [61351.4, 0.054], [61997.2, 0.0], [63580.5, 0.026], [63934.7, 3.972], [63945.5, 66.961], [64257.6, 6.819], [64383.6, 2.939], [64383.7, 0.415], [64422.3, 2.534], [64422.4, 0.007], [64439.3, 3.876], [64461.6, 0.001], [64472.1, 0.831], [64472.3, 2.323], [64506.9, 0.032], [64509.3, 0.014], [64517.6, 0.007], [64529.4, 0.002], [64530.9, 0.77], [64545.6, 1.14], [64546.1, 0.016], [64568.6, 0.403], [64568.9, 0.0], [64574.6, 0.205], [64574.7, 0.071], [64576.7, 0.013], [64580.5, 2.234]], "asks": [[64580.6, 43.679], [64587.2, 0.42], [64587.4, 0.001], [64587.5, 0.106], [64587.8, 0.074], [64590.5, 0.637], [64595.8, 0.636], [64597.1, 0.317], [64601.0, 0.557], [64601.5, 1.241], [64609.0, 2.319], [64622.7, 0.0], [64625.1, 0.388], [64643.5, 0.002], [64647.8, 0.468], [64651.5, 0.0], [64687.7, 2.323], [64717.3, 0.0], [64720.5, 5.423], [64737.4, 10.429], [64776.2, 15.438], [65065.6, 51.717], [65145.5, 0.503], [65226.4, 1.36], [65580.6, 0.03], [65872.2, 7.657]]}
{"kind": "depth", "E": 1787089931109, "U": 11316021275350, "u": 11316021284445, "recv_ms": 1787089931074, "bids": [[14280.5, 0.63], [14380.5, 3.5], [14480.5, 0.07], [51664.0, 0.0], [58122.4, 0.004], [61997.2, 0.003], [63482.6, 16.877], [63934.7, 3.972], [64383.6, 9.028], [64422.3, 4.817], [64439.3, 5.185], [64461.6, 3.872], [64474.6, 0.001], [64501.3, 0.004], [64508.8, 1.727], [64509.3, 0.06], [64510.7, 0.0], [64517.6, 4.938], [64568.9, 0.0], [64574.6, 0.202], [64574.7, 0.074]], "asks": [[64581.3, 0.024], [64583.1, 0.009], [64587.5, 0.198], [64590.5, 0.545], [64595.8, 0.017], [64596.1, 0.002], [64597.4, 0.624], [64598.5, 10.003], [64602.4, 0.022], [64602.5, 0.119], [64603.1, 0.0], [64622.6, 0.077], [64622.7, 0.154], [64625.0, 0.967], [64643.5, 2.214], [64647.0, 0.684], [64651.5, 0.046], [64655.7, 41.885], [64657.9, 0.029], [64680.1, 0.002], [64717.4, 3.871], [64776.1, 0.074], [64780.1, 0.0], [65226.4, 1.36], [65291.3, 0.857], [65975.7, 3.247]]}
{"kind": "depth", "E": 1787089931211, "U": 11316021284762, "u": 11316021293941, "recv_ms": 1787089931176, "bids": [[1000.0, 35.76], [14280.5, 0.924], [14380.5, 3.276], [14480.5, 0.0], [51664.0, 0.0], [58122.4, 0.004], [61351.4, 0.054], [63580.5, 0.006], [63798.3, 1.566], [63870.1, 8.133], [63934.7, 3.972], [63966.6, 0.803], [64063.9, 9.505], [64363.0, 5.115], [64375.9, 0.217], [64506.9, 6.032], [64528.9, 0.06], [64529.5, 3.501], [64531.6, 0.753], [64536.7, 0.984], [64545.7, 1.136], [64547.6, 0.022], [64547.7, 0.004], [64547.8, 0.001], [64551.1, 0.0], [64551.2, 0.003], [64551.3, 2.32], [64552.4, 0.064], [64553.3, 0.0], [64559.6, 0.12], [64560.5, 0.311], [64560.6, 0.621], [64560.7, 0.56], [64561.7, 0.1], [64563.7, 0.001], [64565.5, 0.0], [64565.7, 0.932], [64565.9, 0.673], [64566.0, 0.125], [64566.5, 0.543], [64566.6, 0.218], [64566.7, 0.007], [64567.2, 0.002], [64570.0, 0.004], [64576.7, 0.013], [64576.8, 0.04], [64578.3, 0.0], [64580.5, 2.233]], "asks": [[64580.6, 43.678], [64595.9, 1.579], [64596.1, 0.0], [64596.5, 0.036], [64597.3, 0.101], [64598.1, 0.956], [64598.3, 0.0], [64599.0, 0.029], [64601.0, 0.0], [64601.1, 0.38], [64601.9, 0.558], [64602.5, 0.003], [64603.3, 0.132], [64604.2, 0.066], [64604.3, 0.442], [64605.1, 0.311], [64609.4, 0.963], [64622.6, 0.231], [64622.7, 0.0], [64625.5, 3.501], [64648.1, 6.348], [64653.5, 0.629], [64655.7, 2.321], [64656.5, 0.0], [64657.5, 0.442], [64660.1, 39.577], [64780.1, 0.216], [64803.7, 8.39], [65226.4, 1.36], [65580.6, 0.01], [65665.8, 0.006]]}
{"kind": "depth", "E": 1787089931313, "U": 11316021294069, "u": 11316021301996, "recv_ms": 1787089931278, "bids": [[14280.5, 1.288], [14380.5, 2.912], [58122.4, 0.004], [61997.2, 0.0], [63289.0, 0.015], [63306.3, 0.006], [63360.7, 0.063], [63432.5, 0.0], [63504.3, 0.0], [63576.0, 0.0], [63647.8, 0.0], [63719.5, 0.0], [63773.2, 24.128], [63791.3, 0.0], [63805.5, 64.797], [63863.0, 1.344], [63934.7, 3.972], [63934.8, 0.046], [64257.6, 6.819], [64563.7, 0.003], [64569.2, 0.018]], "asks": [[64595.9, 1.037], [64596.1, 0.002], [64596.5, 0.578], [64622.6, 0.077], [64622.7, 0.154], [64657.9, 39.593], [64660.1, 0.013], [65226.4, 1.301], [65298.2, 2.295], [65369.9, 0.02], [65441.7, 0.024], [65513.4, 0.002], [65585.2, 0.008], [65656.9, 0.0], [65728.7, 0.002], [65800.5, 0.312], [65872.2, 7.598]]}
{"kind": "depth", "E": 1787089931517, "U": 11316021309614, "u": 11316021319125, "recv_ms": 1787089931483, "bids": [[1000.0, 35.76], [14280.5, 1.988], [14380.5, 2.212], [51664.4, 0.0], [58122.4, 0.004], [61351.4, 0.054], [61351.6, 0.006], [61997.2, 0.0], [62821.1, 0.004], [63288.9, 4.267], [63805.5, 65.579], [63934.7, 3.972], [64438.1, 1.036], [64472.3, 2.323], [64494.5, 0.0], [64495.3, 30.084], [64495.4, 6.692], [64506.5, 2.139], [64508.5, 1.806], [64508.7, 2.441], [64510.7, 0.009], [64514.7, 1.991], [64522.8, 0.018], [64527.9, 1.327], [64529.5, 3.503], [64529.8, 0.702], [64532.6, 10.001], [64534.0, 0.029], [64536.4, 2.074], [64536.6, 0.025], [64543.1, 4.016], [64543.2, 1.084], [64551.5, 0.299], [64552.4, 0.007], [64558.3, 0.116], [64559.4, 0.002], [64559.6, 0.002], [64559.7, 0.558], [64560.6, 0.002], [64560.7, 0.002], [64561.7, 0.108], [64561.9, 0.001], [64563.1, 3.694], [64563.4, 0.099], [64563.6, 0.001], [64564.8, 1.084], [64565.2, 0.002], [64565.7, 0.005], [64565.8, 2.882], [64565.9, 0.589], [64566.0, 0.209], [64566.5, 0.001], [64567.1, 0.016], [64567.8, 0.005], [64570.0, 0.004], [64570.4, 0.001], [64571.3, 0.004], [64571.5, 0.09], [64571.7, 0.233], [64571.9, 0.086], [64572.2, 0.086], [64574.4, 0.103], [64574.5, 0.254], [64574.8, 0.114], [64575.3, 0.002], [64575.8, 0.034], [64576.0, 1.635], [64576.1, 0.034], [64576.2, 0.314], [64576.3, 0.003], [64576.4, 0.124], [64576.7, 0.137], [64577.7, 0.0], [64578.0, 0.642], [64578.3, 0.001], [64579.3, 0.021], [64579.9, 0.136], [64580.4, 0.019], [64580.5, 1.875]], "asks": [[64580.6, 57.098], [64581.4, 0.0], [64581.5, 0.038], [64585.6, 2.644], [64587.5, 0.756], [64588.3, 2.028], [64588.4, 0.162], [64588.5, 0.011], [64588.7, 0.291], [64590.4, 0.015], [64590.5, 0.003], [64592.5, 2.003], [64592.6, 0.003], [64592.7, 0.0], [64593.1, 0.0], [64594.6, 0.017], [64595.8, 0.559], [64596.5, 2.012], [64596.6, 0.138], [64597.2, 0.361], [64597.8, 1.487], [64598.1, 0.029], [64598.4, 0.041], [64598.5, 0.005], [64599.4, 0.018], [64599.6, 0.093], [64600.0, 3.744], [64601.1, 0.496], [64601.9, 0.001], [64603.2, 1.132], [64603.3, 0.016], [64603.9, 0.06], [64604.1, 0.0], [64604.2, 0.009], [64604.9, 0.074], [64609.4, 0.965], [64609.5, 0.014], [64609.6, 7.132], [64612.4, 0.003], [64612.5, 0.002], [64612.6, 0.002], [64613.3, 0.002], [64613.4, 0.095], [64613.5, 0.161], [64615.4, 0.031], [64615.5, 0.003], [64615.6, 0.003], [64622.7, 0.154], [64645.9, 0.0], [64657.9, 0.029], [64660.1, 0.013], [64662.1, 2.401], [64662.2, 0.0], [64664.5, 43.372], [64687.7, 2.323], [64722.3, 0.47], [65226.4, 1.301], [65291.2, 1.166], [65516.9, 3.33], [65646.1, 0.0], [65872.2, 7.601]]}
{"kind": "depth", "E": 1787089931619, "U": 11316021319220, "u": 11316021325861, "recv_ms": 1787089931583, "bids": [[14280.5, 2.352], [14380.5, 1.848], [58122.4, 0.004], [61351.4, 0.054], [61997.2, 0.003], [63514.9, 7.504], [63580.5, 0.006], [63670.5, 0.94], [63773.2, 23.894], [63934.7, 3.972], [64031.6, 1.325], [64091.9, 51.399], [64207.4, 41.786], [64208.0, 7.423], [64257.6, 6.819], [64438.1, 0.036], [64503.0, 0.032], [64532.6, 0.001], [64536.5, 0.685], [64560.0, 4.027], [64561.7, 0.1], [64563.2, 0.049], [64565.8, 2.34], [64566.5, 0.543], [64567.3, 0.623], [64571.7, 0.001], [64572.1, 0.544], [64576.0, 1.627], [64576.3, 0.011], [64576.7, 0.129], [64576.8, 0.04], [64578.0, 0.642], [64578.1, 0.012], [64580.5, 1.877]], "asks": [[64581.6, 0.115], [64582.2, 0.001], [64585.6, 0.925], [64587.5, 0.106], [64590.5, 0.637], [64592.4, 0.02], [64598.7, 3.189], [64606.1, 0.933], [64622.7, 0.0], [64622.8, 0.154], [64630.6, 1.875], [65215.3, 64.914], [65349.0, 3.891], [65362.9, 3.82], [65580.6, 0.01], [65678.5, 22.966], [67086.3, 0.0]]}
{"kind": "depth", "E": 1787089931721, "U": 11316021326076, "u": 11316021334564, "recv_ms": 1787089931685, "bids": [[14280.5, 2.716], [14380.5, 1.484], [51664.0, 0.002], [58122.4, 0.004], [62836.8, 0.954], [63682.8, 21.937], [63862.1, 4.169], [63934.7, 3.972], [64422.3, 0.001], [64439.3, 2.319], [64480.7, 0.093], [64480.8, 0.023], [64521.0, 0.387], [64561.8, 0.009], [64563.2, 0.041], [64565.9, 0.581], [64566.0, 0.202], [64570.0, 0.019], [64571.5, 0.09], [64572.1, 0.312], [64575.0, 0.242], [64576.1, 0.042], [64576.3, 0.003], [64576.8, 0.048], [64577.7, 0.001], [64578.1, 0.004], [64578.3, 0.0]], "asks": [[64580.6, 57.071], [64581.3, 0.004], [64581.4, 0.019], [64581.6, 0.092], [64581.7, 0.024], [64587.9, 0.237], [64593.3, 0.004], [64622.8, 0.0], [64720.4, 0.0], [64720.5, 0.015], [64737.4, 0.002], [64771.3, 0.0], [64771.4, 0.01], [65226.4, 1.301], [65349.1, 8.253], [65517.0, 35.956]]}
{"kind": "depth", "E": 1787089931823, "U": 11316021334619, "u": 11316021343112, "recv_ms": 1787089931788, "bids": [[1000.0, 35.76], [14280.5, 3.066], [14380.5, 1.134], [51664.0, 0.0], [58122.4, 0.004], [61997.2, 0.0], [63580.5, 0.026], [63644.1, 36.915], [63934.7, 3.972], [64307.0, 5.512], [64377.5, 4.516], [64420.3, 0.197], [64422.3, 5.545], [64439.3, 5.591], [64517.7, 1.612], [64546.0, 1.248], [64576.1, 0.034], [64576.3, 0.011], [64576.8, 0.058], [64578.1, 0.001], [64578.8, 0.002]], "asks": [[64599.5, 2.168], [64622.7, 0.0], [64622.9, 0.256], [64720.5, 5.423], [64722.0, 0.51], [64737.4, 10.429], [64780.1, 4.369], [65181.5, 0.0], [65226.4, 1.301], [65387.9, 18.043], [65517.0, 37.023], [65580.6, 0.03], [65646.2, 4.443], [66066.0, 4.318]]}
{"kind": "depth", "E": 1787089932027, "U": 11316021350930, "u": 11316021358171, "recv_ms": 1787089931991, "bids": [[1000.0, 35.76], [14180.5, 0.028], [14280.5, 3.724], [14380.5, 0.448], [58122.4, 0.004], [61351.4, 0.054], [61351.6, 0.004], [61997.2, 0.0], [63567.2, 0.779], [63580.5, 0.006], [63660.2, 0.001], [63805.5, 65.36], [63864.7, 0.237], [63934.7, 3.972], [64422.3, 4.783], [64439.3, 5.19], [64551.5, 0.242], [64552.3, 0.096], [64564.8, 0.157], [64565.5, 0.927], [64566.0, 0.217], [64567.3, 0.004], [64570.0, 0.004], [64579.4, 0.017], [64580.5, 1.921]], "asks": [[64580.6, 57.164], [64581.8, 0.01], [64583.4, 0.257], [64585.1, 0.088], [64588.3, 2.025], [64720.5, 5.423], [64722.3, 1.47], [64737.4, 10.429], [65194.1, 25.169], [65226.4, 1.301], [65395.1, 3.061], [65492.0, 2.352], [65580.6, 0.01], [66066.0, 5.073]]}
{"kind": "depth", "E": 1787089932129, "U": 11316021358286, "u": 11316021367243, "recv_ms": 1787089932094, "bids": [[1000.0, 35.76], [14180.5, 0.21], [14280.5, 3.71], [14380.5, 0.28], [51664.0, 0.0], [58122.4, 0.004], [61339.6, 0.0], [61351.4, 0.054], [61351.5, 0.002], [61351.6, 0.006], [61649.0, 0.001], [63097.8, 0.0], [63597.6, 0.0], [63599.4, 0.011], [63934.7, 3.972], [64381.9, 0.01], [64383.6, 7.864], [64398.0, 0.804], [64422.3, 5.11], [64439.3, 5.57], [64503.0, 0.029], [64508.8, 1.729], [64535.2, 0.064], [64558.3, 0.0], [64559.5, 0.193], [64559.7, 0.0], [64560.6, 0.56], [64563.1, 3.687], [64563.6, 0.008], [64568.9, 0.0], [64572.1, 0.544], [64574.6, 0.205], [64574.7, 0.071], [64576.1, 0.042], [64576.3, 0.003], [64576.8, 0.048]], "asks": [[64580.6, 57.17], [64584.5, 0.094], [64586.8, 0.002], [64600.0, 3.187], [64600.7, 0.577], [64601.1, 0.38], [64602.2, 0.924], [64603.2, 1.125], [64603.8, 0.078], [64638.8, 0.003], [65226.4, 1.301], [65355.5, 6.082], [65355.6, 60.68], [65561.6, 0.017], [65563.4, 0.0], [65743.1, 11.963], [65846.5, 3.255]]}
{"kind": "depth", "E": 1787089932231, "U": 11316021367321, "u": 11316021374585, "recv_ms": 1787089932195, "bids": [[14180.5, 0.448], [14280.5, 3.598], [14380.5, 0.154], [51664.0, 0.0], [58122.4, 0.004], [61997.2, 0.003], [63580.5, 0.026], [63597.6, 0.011], [63599.5, 5.551], [63669.9, 5.055], [63934.7, 3.972], [64257.6, 6.819], [64495.3, 0.01], [64495.4, 0.003], [64508.5, 31.88], [64563.7, 0.001]], "asks": [[64582.5, 0.002], [64596.1, 0.0], [64657.9, 39.593], [64664.5, 3.808], [65387.9, 17.784], [65524.3, 0.019], [65549.3, 19.733], [65561.7, 0.029], [65563.5, 0.043], [65580.6, 0.03]]}
{"kind": "depth", "E": 1787089932333, "U": 11316021374825, "u": 11316021382597, "recv_ms": 1787089932297, "bids": [[1000.0, 35.76], [14180.5, 0.686], [14280.5, 3.472], [14380.5, 0.042], [51664.0, 0.0], [58122.4, 0.004], [61351.5, 2.443], [61997.2, 0.0], [63579.5, 30.236], [63724.3, 0.0], [63934.7, 3.974], [64388.4, 0.795], [64404.6, 0.001], [64563.7, 0.003]], "asks": [[64580.6, 57.166], [64596.1, 0.002], [64814.8, 0.003], [64831.0, 0.014], [65226.4, 1.301], [65872.2, 7.598], [66524.6, 2.572]]}
{"kind": "depth", "E": 1787089932435, "U": 11316021382636, "u": 11316021390318, "recv_ms": 1787089932399, "bids": [[1000.0, 35.76], [14180.5, 1.008], [14280.5, 3.192], [14380.5, 0.0], [58122.4, 0.004], [61351.4, 0.054], [61997.2, 0.003], [63580.5, 0.006], [63669.9, 5.681], [63934.7, 3.972], [64370.6, 0.048], [64383.6, 4.84], [64422.3, 3.121], [64439.3, 4.299], [64517.6, 4.956], [64517.7, 1.002], [64522.3, 0.003], [64541.4, 10.001], [64571.2, 0.234], [64571.5, 0.006], [64572.1, 0.312], [64575.4, 2.323], [64575.6, 0.084], [64576.0, 0.079], [64576.1, 0.352], [64576.2, 1.862]], "asks": [[64580.6, 57.184], [64584.1, 0.312], [64597.8, 0.56], [64597.9, 10.001], [64598.0, 0.933], [64614.5, 0.005], [64621.1, 0.459], [64634.9, 0.003], [64641.5, 2.569], [64643.5, 2.216], [64658.1, 0.018], [64774.4, 0.006], [64903.6, 0.0], [65226.4, 1.301], [65298.3, 5.357], [65484.7, 78.063], [65549.3, 20.113], [65580.6, 0.01], [65678.6, 0.76]]}
{"kind": "depth", "E": 1787089932537, "U": 11316021390507, "u": 11316021397198, "recv_ms": 1787089932504, "bids": [[14180.5, 1.358], [14280.5, 2.842], [51664.4, 0.0], [58122.4, 0.004], [61351.4, 0.054], [61997.2, 0.0], [63097.7, 0.001], [63289.0, 0.074], [63360.7, 0.122], [63432.5, 0.059], [63504.3, 0.059], [63576.0, 0.059], [63647.8, 0.059], [63719.5, 0.059], [63740.9, 5.324], [63791.3, 0.059], [63837.7, 0.97], [63863.0, 1.403], [63934.7, 3.972], [63934.8, 0.105], [64257.5, 0.158], [64257.6, 6.809], [64383.6, 7.176], [64386.8, 0.005], [64422.3, 4.831], [64439.3, 5.198], [64503.0, 0.02], [64534.0, 0.029], [64536.4, 0.074], [64571.9, 0.002], [64576.0, 1.719], [64576.1, 0.034], [64576.2, 0.314], [64576.8, 0.058]], "asks": [[64580.6, 57.181], [64597.9, 0.001], [64603.9, 0.003], [64604.2, 0.066], [64657.9, 40.032], [64660.1, 0.013], [65200.0, 140.885], [65226.4, 1.36], [65298.2, 2.354], [65369.9, 0.079], [65441.7, 0.083], [65513.4, 0.061], [65516.4, 6.12], [65529.9, 19.568], [65585.2, 0.067], [65656.9, 0.059], [65728.7, 0.061], [65800.5, 0.371], [65872.2, 7.657]]}
{"kind": "depth", "E": 1787089932639, "U": 11316021397392, "u": 11316021404064, "recv_ms": 1787089932603, "bids": [[1000.0, 35.76], [14180.5, 1.722], [14280.5, 2.478], [51664.0, 0.0], [58122.4, 0.004], [61351.5, 2.445], [61649.0, 0.002], [63580.5, 0.026], [63773.2, 23.66], [63837.8, 8.842], [63934.7, 3.972], [64561.8, 0.001], [64563.2, 0.041], [64566.7, 0.0], [64567.4, 0.317], [64574.6, 0.202], [64574.9, 0.075], [64576.0, 0.163], [64576.1, 0.042], [64576.3, 1.551], [64576.8, 0.058], [64578.1, 0.001]], "asks": [[64590.5, 0.08], [64591.1, 0.557], [64595.8, 0.017], [64596.4, 0.542], [64598.0, 0.006], [64598.3, 0.927], [64633.8, 0.211], [64641.5, 2.359], [64808.2, 0.0], [64824.5, 0.014], [65226.4, 1.36], [65323.3, 0.0], [65580.6, 0.03]]}
{"kind": "depth", "E": 1787089932741, "U": 11316021404073, "u": 11316021410243, "recv_ms": 1787089932706, "bids": [[1000.0, 35.76], [14180.5, 2.072], [14280.5, 2.128], [58122.4, 0.004], [61997.2, 0.003], [63773.2, 23.309], [63934.7, 3.972], [64383.7, 1.758], [64389.8, 0.47], [64406.0, 1.031], [64420.3, 0.0], [64422.4, 0.971], [64494.5, 1.887], [64517.7, 1.615], [64543.2, 2.421], [64559.0, 0.015], [64559.4, 0.0], [64561.7, 0.108], [64576.1, 0.034], [64576.3, 1.559]], "asks": [[64625.0, 1.366], [64657.5, 6.319], [64686.4, 4.414], [64720.4, 1.472], [64722.0, 0.016], [64753.6, 3.935], [64754.2, 0.014], [64780.9, 2.578], [64806.8, 0.0], [64823.1, 0.412], [65161.8, 14.142], [65226.4, 1.362]]}
{"kind": "depth", "E": 1787089932843, "U": 11316021410294, "u": 11316021416186, "recv_ms": 1787089932808, "bids": [[14180.5, 2.436], [14280.5, 1.764], [58122.4, 0.004], [61997.2, 0.0], [63580.5, 0.006], [63934.7, 3.972], [63935.2, 0.41], [64257.6, 6.819], [64383.3, 0.08], [64399.5, 0.002], [64439.3, 2.319], [64534.0, 0.015], [64561.7, 0.1], [64563.2, 0.049], [64576.8, 0.05], [64578.0, 0.65]], "asks": [[64584.0, 0.357], [64720.5, 0.015], [65226.4, 1.36], [65298.3, 6.122], [65419.6, 0.0], [65517.0, 38.09], [65557.3, 0.762], [65580.6, 0.01]]}
{"kind": "depth", "E": 1787089932945, "U": 11316021416311, "u": 11316021421887, "recv_ms": 1787089932909, "bids": [[1000.0, 35.76], [14180.5, 2.786], [14280.5, 1.414], [58122.4, 0.004], [61351.4, 0.054], [61997.2, 0.003], [63288.9, 4.27], [63934.7, 3.972], [64269.8, 0.128], [64289.2, 0.006], [64318.5, 0.11], [64337.9, 0.001], [64439.2, 3.261], [64567.6, 0.164], [64567.8, 0.624], [64568.7, 0.157], [64576.2, 0.624], [64576.3, 0.003], [64576.7, 1.561], [64576.8, 0.174], [64578.0, 0.642], [64578.1, 0.009]], "asks": [[64580.6, 57.111], [64581.2, 0.007], [64720.4, 0.0], [64720.5, 5.423], [64813.3, 0.04], [64829.6, 0.005], [65226.4, 1.36], [65678.5, 23.452]]}
{"kind": "depth", "E": 1787089933047, "U": 11316021422113, "u": 11316021429228, "recv_ms": 1787089933012, "bids": [[1000.0, 35.76], [14180.5, 3.15], [14280.5, 1.05], [58122.4, 0.004], [61351.4, 0.054], [63314.6, 2.704], [63580.5, 0.026], [63805.5, 65.579], [63934.7, 3.972], [63947.6, 4.956], [64439.2, 3.238], [64541.4, 0.001], [64545.5, 3.015], [64563.5, 0.061], [64564.0, 0.038], [64565.5, 0.0], [64565.9, 1.508], [64567.8, 0.005], [64568.9, 0.005], [64571.1, 0.001], [64572.0, 0.158], [64579.4, 0.018], [64580.5, 2.52]], "asks": [[64580.6, 57.111], [64584.5, 0.093], [64592.4, 0.004], [64592.5, 0.003], [64592.7, 0.008], [64594.3, 0.001], [64594.5, 0.025], [64594.8, 0.007], [64598.7, 2.57], [64600.7, 0.02], [64601.3, 15.651], [64602.2, 0.808], [64602.8, 0.116], [64604.2, 0.009], [64604.5, 0.131], [64606.1, 0.314], [64609.4, 0.963], [64609.5, 0.012], [64609.6, 7.13], [64612.4, 0.001], [64612.5, 0.0], [64612.6, 0.0], [64613.3, 0.0], [64613.4, 0.093], [64613.5, 0.159], [64615.4, 0.029], [64615.5, 0.001], [64615.6, 0.001], [64720.5, 5.423], [65226.4, 1.36], [65580.6, 0.03]]}
{"kind": "depth", "E": 1787089933149, "U": 11316021429400, "u": 11316021436443, "recv_ms": 1787089933117, "bids": [[14180.5, 3.5], [14280.5, 0.7], [58122.4, 0.004], [61997.2, 0.0], [63676.4, 58.901], [63934.7, 3.972], [64207.4, 0.003], [64208.0, 1.36], [64257.6, 6.819], [64304.9, 0.003], [64307.0, 0.476], [64375.8, 0.0], [64377.5, 0.585], [64501.1, 3.579], [64508.5, 31.881], [64508.7, 2.439], [64508.8, 1.727], [64515.9, 0.02], [64528.9, 0.057], [64531.6, 0.752], [64534.0, 0.029], [64536.7, 0.983], [64543.2, 1.084], [64559.5, 0.077], [64559.7, 0.116], [64560.0, 3.408], [64560.6, 0.002], [64561.1, 2.053], [64568.6, 0.094], [64568.9, 0.0], [64569.2, 0.327], [64572.8, 2.338], [64573.2, 0.004], [64573.3, 0.395], [64574.9, 0.072], [64575.2, 0.036], [64580.5, 2.521]], "asks": [[64580.6, 57.111], [64581.9, 0.001], [64587.2, 0.111], [64587.8, 0.383], [64597.4, 0.005], [64597.7, 0.621], [64599.5, 3.366], [64602.7, 0.628], [64603.8, 0.071], [64604.1, 0.007], [64645.2, 0.363], [64657.5, 0.442], [64657.9, 0.029], [64660.1, 40.016], [64780.1, 0.216], [64780.2, 0.0], [64851.3, 0.418], [64851.4, 2.501], [64947.6, 5.15], [64948.7, 0.0], [65097.2, 9.049], [65188.0, 210.699], [65207.3, 0.0], [65226.4, 1.36], [65355.5, 4.249], [65554.6, 0.327], [65580.5, 0.654]]}
{"kind": "depth", "E": 1787089933251, "U": 11316021436615, "u": 11316021442294, "recv_ms": 1787089933215, "bids": [[1000.0, 35.76], [14080.5, 0.056], [14180.5, 3.752], [14280.5, 0.392], [51664.0, 0.0], [58122.4, 0.004], [61351.4, 0.054], [61997.2, 0.003], [63288.9, 4.273], [63580.5, 0.006], [63618.8, 0.011], [63757.1, 0.01], [63934.7, 3.972], [64439.2, 3.297], [64552.3, 0.039], [64553.3, 0.057], [64558.4, 1.681], [64558.5, 0.793], [64560.6, 0.002], [64561.1, 1.495], [64561.8, 0.559], [64565.9, 0.039], [64566.0, 0.14], [64566.6, 1.145], [64566.7, 0.619], [64572.9, 1.74], [64573.2, 0.002], [64576.7, 1.553], [64576.9, 0.009], [64580.5, 2.23]], "asks": [[64580.6, 57.112], [64581.9, 0.0], [64596.4, 0.0], [64597.6, 0.55], [64598.3, 0.0], [64599.0, 0.956], [64601.3, 15.094], [64601.9, 0.558], [64602.8, 0.0], [64603.2, 1.241], [64604.5, 0.074], [64605.1, 0.368], [65200.6, 1.718], [65226.4, 1.36], [65298.2, 3.119], [65580.6, 0.01], [65677.8, 0.0]]}
{"kind": "depth", "E": 1787089933353, "U": 11316021442436, "u": 11316021449270, "recv_ms": 1787089933324, "bids": [[1000.0, 35.76], [14080.5, 0.266], [14180.5, 3.682], [14280.5, 0.252], [51664.0, 0.002], [58122.4, 0.004], [61997.2, 0.0], [63580.5, 0.026], [63595.5, 0.768], [63773.2, 23.543], [63805.4, 1.002], [63934.6, 0.005], [63934.7, 3.972], [63945.5, 0.003], [64091.9, 0.0], [64363.0, 5.331], [64375.9, 0.001], [64506.9, 0.032], [64522.3, 0.0], [64529.5, 0.003], [64535.2, 0.064], [64545.7, 0.167], [64552.4, 0.064], [64553.3, 0.0], [64558.4, 1.679], [64558.5, 0.791], [64560.6, 0.56], [64561.8, 0.001], [64563.7, 0.003], [64565.4, 0.002], [64565.7, 0.932], [64565.9, 0.666], [64566.0, 0.132], [64566.6, 0.218], [64566.7, 0.0], [64566.8, 0.002], [64580.5, 2.491]], "asks": [[64580.6, 57.112], [64586.1, 0.061], [64595.8, 0.559], [64596.1, 0.002], [64597.6, 0.008], [64598.1, 0.956], [64598.9, 0.016], [64599.0, 0.029], [64604.2, 0.066], [64605.1, 0.311], [64609.4, 0.001], [64625.0, 0.967], [64625.5, 0.001], [64638.8, 0.0], [64648.1, 0.348], [64657.9, 40.513], [64658.1, 0.018], [64660.1, 0.013], [64780.1, 0.0], [64803.7, 8.606], [65065.6, 0.0], [65097.2, 9.969], [65215.3, 0.0], [65226.4, 1.362], [65355.6, 62.513], [65580.6, 0.03], [65691.4, 3.212]]}
{"kind": "depth", "E": 1787089933455, "U": 11316021449287, "u": 11316021456599, "recv_ms": 1787089933420, "bids": [[14080.5, 0.504], [14180.5, 3.57], [14280.5, 0.126], [51664.0, 0.0], [58122.4, 0.004], [61351.4, 0.054], [61997.2, 0.003], [63934.7, 3.972], [64257.6, 6.819], [64474.6, 0.001], [64522.3, 0.003], [64572.9, 1.738], [64573.2, 0.004], [64580.5, 2.52]], "asks": [[64595.8, 0.017], [64596.4, 0.542], [64638.8, 0.003], [64680.5, 0.0], [64737.4, 10.429], [64737.7, 0.0], [65226.4, 1.36], [65271.9, 0.688], [65387.9, 18.127], [65491.2, 7.478], [65838.8, 0.0], [65872.2, 7.66]]}
{"kind": "depth", "E": 1787089933557, "U": 11316021456713, "u": 11316021463477, "recv_ms": 1787089933521, "bids": [[1000.0, 35.76], [14080.5, 0.756], [14180.5, 3.43], [14280.5, 0.014], [51664.4, 0.0], [58122.4, 0.004], [61351.4, 0.054], [63631.2, 19.212], [63856.3, 0.0], [63934.7, 3.972], [64173.7, 0.0], [64193.0, 0.065], [64257.5, 0.156], [64506.9, 6.032], [64529.5, 3.503], [64545.6, 2.122], [64572.9, 1.74], [64573.2, 0.002], [64573.3, 0.085], [64576.0, 0.079], [64576.7, 1.561], [64576.8, 0.164], [64576.9, 0.011], [64580.5, 2.524]], "asks": [[64580.6, 57.175], [64593.1, 0.008], [64594.5, 0.017], [64609.1, 1.395], [64625.3, 3.5], [64647.9, 6.022], [64903.6, 0.002], [65226.4, 1.36], [65387.9, 17.784], [65691.4, 3.819]]}
{"kind": "depth", "E": 1787089933659, "U": 11316021463548, "u": 11316021469779, "recv_ms": 1787089933624, "bids": [[1000.0, 35.76], [14080.5, 1.092], [14180.5, 3.108], [14280.5, 0.0], [58122.4, 0.004], [61351.4, 0.054], [61997.2, 0.0], [63495.5, 3.771], [63580.5, 0.006], [63805.5, 66.36], [63934.7, 3.972], [63999.2, 6.618], [64439.2, 2.856], [64571.2, 0.002], [64571.6, 0.234], [64580.4, 0.009]], "asks": [[64580.6, 57.141], [64657.9, 0.029], [64660.1, 40.497], [64720.5, 5.423], [65226.4, 1.36], [65284.5, 15.733], [65580.6, 0.01], [65839.9, 2.582]]}
{"kind": "depth", "E": 1787089933761, "U": 11316021470125, "u": 11316021479541, "recv_ms": 1787089933726, "bids": [[14080.5, 1.442], [14180.5, 2.758], [58122.4, 0.004], [61351.4, 0.054], [61997.2, 0.003], [63495.5, 4.399], [63644.1, 35.816], [63669.1, 3.136], [63805.5, 66.579], [63876.6, 12.66], [63934.7, 3.972], [64257.6, 6.819], [64374.7, 27.73], [64377.5, 4.569], [64383.5, 9.152], [64383.6, 0.0], [64383.7, 0.415], [64422.3, 4.855], [64422.4, 0.63], [64439.2, 2.893], [64474.7, 10.0], [64508.7, 7.681], [64517.6, 4.98], [64530.9, 1.26], [64580.4, 0.008], [64580.5, 2.229]], "asks": [[64595.9, 1.579], [64596.4, 0.0], [64602.7, 0.63], [64602.8, 0.002], [64625.0, 1.366], [64643.5, 2.222], [64647.0, 1.548], [64680.2, 10.0], [64720.4, 1.472], [64779.9, 0.203], [65226.4, 1.36], [65387.9, 18.043], [65872.2, 7.657]]}
{"kind": "depth", "E": 1787089933863, "U": 11316021479777, "u": 11316021487664, "recv_ms": 1787089933828, "bids": [[1000.0, 35.76], [14080.5, 1.806], [14180.5, 2.394], [51664.0, 0.0], [58122.4, 0.004], [61351.4, 0.055], [61351.5, 2.447], [61997.2, 0.0], [63580.5, 0.026], [63793.2, 11.428], [63934.7, 3.972], [64305.1, 0.007], [64312.3, 0.464], [64383.5, 8.943], [64422.3, 5.546], [64439.2, 3.257], [64450.5, 0.005], [64563.7, 0.011], [64564.0, 0.03], [64570.1, 0.057], [64574.9, 0.075], [64575.2, 0.033], [64576.3, 1.559], [64576.7, 0.005], [64580.5, 2.21]], "asks": [[64580.6, 57.141], [64595.9, 1.037], [64596.4, 0.542], [64609.4, 0.003], [64609.5, 0.014], [64609.6, 7.132], [64612.4, 0.003], [64612.5, 0.002], [64612.6, 0.002], [64613.3, 0.002], [64613.4, 0.095], [64613.5, 0.161], [64615.4, 0.031], [64615.5, 0.003], [64615.6, 0.003], [65097.2, 9.662], [65226.4, 1.36], [65355.6, 61.749], [65580.6, 0.03], [65776.2, 0.0], [65872.2, 7.66], [71038.7, 0.002]]}
{"kind": "depth", "E": 1787089933965, "U": 11316021488013, "u": 11316021495514, "recv_ms": 1787089933930, "bids": [[1000.0, 35.76], [14080.5, 2.156], [14180.5, 2.044], [58122.4, 0.004], [61351.4, 0.054], [61997.2, 0.003], [63644.1, 36.915], [63934.7, 3.972], [63946.8, 2.81], [63999.3, 13.763], [64363.0, 5.115], [64374.8, 0.217], [64551.7, 0.511], [64552.4, 0.007], [64558.7, 0.116], [64559.7, 0.0], [64565.0, 1.195], [64565.7, 0.005], [64566.0, 0.674], [64566.5, 0.001]], "asks": [[64595.9, 1.579], [64596.4, 0.0], [65226.4, 1.36], [65484.7, 78.52], [65581.5, 1.075]]}
{"kind": "depth", "E": 1787089934067, "U": 11316021495798, "u": 11316021503842, "recv_ms": 1787089934032, "bids": [[14080.5, 2.52], [14180.5, 1.68], [58122.4, 0.004], [61351.4, 0.054], [61351.5, 2.447], [61351.6, 0.008], [63580.5, 0.006], [63599.5, 5.543], [63644.1, 35.816], [63664.1, 0.0], [63810.1, 0.0], [63934.7, 3.972], [64257.6, 6.819], [64305.1, 0.003], [64551.7, 0.454], [64552.7, 0.06], [64560.0, 4.027], [64565.0, 0.268], [64566.0, 1.059], [64566.5, 0.543], [64567.3, 0.623], [64568.9, 0.0]], "asks": [[64580.6, 57.141], [64595.8, 0.017], [64595.9, 1.037], [64596.4, 0.542], [64598.1, 0.029], [64598.4, 0.968], [64598.8, 0.661], [64604.2, 0.009], [64604.5, 0.131], [64606.1, 0.933], [65097.2, 9.969], [65226.4, 1.36], [65497.1, 0.004], [65561.7, 0.021], [65580.6, 0.01]]}
{"kind": "depth", "E": 1787089934169, "U": 11316021503962, "u": 11316021510677, "recv_ms": 1787089934134, "bids": [[1000.0, 35.76], [14080.5, 2.87], [14180.5, 1.33], [51664.0, 0.002], [58122.4, 0.004], [61997.2, 0.0], [63514.9, 6.403], [63664.0, 17.242], [63665.1, 0.009], [63665.3, 0.188], [63773.2, 23.23], [63805.5, 68.143], [63824.9, 6.057], [63934.7, 3.972], [64313.2, 0.004], [64501.1, 3.578], [64508.6, 0.03], [64528.8, 0.093], [64531.6, 0.753], [64536.8, 0.108], [64551.9, 0.012], [64552.7, 0.003], [64552.8, 0.059], [64558.7, 0.0], [64559.7, 0.116], [64560.0, 4.027], [64565.2, 0.002], [64566.0, 1.059], [64566.1, 0.542], [64566.5, 0.001], [64568.9, 0.309], [64569.2, 0.018]], "asks": [[64584.8, 0.313], [64595.8, 0.017], [64596.4, 0.542], [64597.6, 0.008], [64598.4, 0.968], [64601.3, 15.651], [64601.9, 0.001], [64603.7, 0.002], [64604.5, 0.131], [64622.8, 0.154], [64622.9, 0.102], [64737.4, 10.429], [64737.7, 0.0], [65226.4, 1.36], [65495.9, 0.002], [65685.7, 3.048], [65872.2, 7.657]]}
{"kind": "depth", "E": 1787089934271, "U": 11316021510799, "u": 11316021517793, "recv_ms": 1787089934235, "bids": [[1000.0, 35.76], [14080.5, 3.234], [14180.5, 0.966], [51664.0, 0.002], [58122.4, 0.004], [61997.2, 0.003], [63514.9, 7.504], [63580.5, 0.026], [63644.1, 36.915], [63821.5, 0.0], [63934.6, 0.004], [63934.7, 3.972], [64091.9, 52.643], [64207.5, 40.746], [64208.0, 7.268], [64303.5, 0.0], [64303.9, 32.994], [64304.0, 5.976]], "asks": [[64780.1, 0.216], [64780.2, 27.056], [64803.7, 8.39], [64824.6, 0.0], [64851.3, 6.424], [64851.4, 37.305], [64852.5, 0.001], [64887.9, 29.864], [64947.6, 10.927], [64948.7, 43.11], [64959.9, 11.49], [64964.5, 0.0], [64992.5, 0.016], [65226.4, 1.36], [65495.8, 0.008], [65497.0, 0.692], [65568.9, 4.716], [65580.6, 0.03], [65581.6, 29.8]]}
{"kind": "depth", "E": 1787089934373, "U": 11316021518142, "u": 11316021524796, "recv_ms": 1787089934337, "bids": [[14080.5, 3.584], [14180.5, 0.616], [51664.0, 0.0], [58122.4, 0.004], [61997.2, 0.0], [63288.9, 4.276], [63599.4, 0.019], [63934.7, 3.972], [63944.5, 66.237], [64257.6, 6.809], [64563.7, 0.011]], "asks": [[64581.4, 0.0], [64581.7, 0.002], [64596.1, 0.002], [64903.5, 4.77], [65065.6, 52.572], [65226.4, 1.36], [65330.3, 1.531], [65440.5, 0.023], [65561.6, 0.025], [65581.6, 30.865]]}
{"kind": "depth", "E": 1787089934475, "U": 11316021525182, "u": 11316021533783, "recv_ms": 1787089934439, "bids": [[1000.0, 35.76], [14080.5, 3.78], [14180.5, 0.336], [14480.5, 0.084], [58122.4, 0.004], [61351.4, 0.054], [63580.5, 0.006], [63631.8, 4.175], [63773.2, 24.128], [63934.7, 3.972], [64383.5, 4.748], [64422.3, 3.084], [64439.2, 1.962], [64503.0, 0.023], [64551.9, 0.069], [64552.8, 0.002], [64559.0, 0.131], [64559.7, 0.0], [64560.1, 0.559], [64560.6, 0.002], [64565.1, 0.944], [64566.0, 0.132]], "asks": [[64580.6, 57.139], [64595.8, 0.559], [64596.4, 0.0], [64597.5, 1.377], [64598.4, 0.041], [64601.9, 0.117], [64603.2, 1.125], [64603.6, 0.089], [64604.5, 0.074], [64618.4, 0.006], [64622.8, 0.0], [64622.9, 0.256], [64625.2, 0.019], [64690.4, 0.036], [64720.5, 5.423], [65214.0, 64.664], [65226.4, 1.36], [65355.6, 60.986], [65580.6, 0.01]]}
{"kind": "depth", "E": 1787089934577, "U": 11316021533968, "u": 11316021540979, "recv_ms": 1787089934541, "bids": [[1000.0, 35.76], [14080.5, 3.654], [14180.5, 0.224], [14480.5, 0.322], [51664.4, 0.0], [58122.4, 0.004], [61997.2, 0.003], [63697.0, 2.668], [63837.7, 0.031], [63934.7, 3.972], [63991.2, 0.234], [64257.5, 0.158], [64383.5, 9.065], [64422.3, 5.592], [64439.2, 3.279], [64450.5, 0.01], [64541.7, 10.032], [64545.5, 1.015], [64551.9, 0.012], [64552.8, 0.059], [64560.0, 3.408], [64567.3, 0.004], [64570.1, 0.052], [64576.3, 1.551], [64576.7, 0.013], [64576.9, 0.001], [64580.5, 1.92]], "asks": [[64580.6, 57.14], [64595.8, 0.017], [64596.4, 0.542], [64597.0, 0.619], [64597.1, 2.317], [64597.5, 0.45], [64597.7, 0.002], [64598.4, 0.968], [64601.9, 0.001], [64602.7, 0.746], [64603.6, 0.032], [64604.5, 0.131], [64903.5, 4.924], [64903.6, 0.0], [65226.4, 1.36]]}
{"kind": "depth", "E": 1787089934679, "U": 11316021541051, "u": 11316021548754, "recv_ms": 1787089934676, "bids": [[14080.5, 3.542], [14180.5, 0.098], [14480.5, 0.56], [58122.4, 0.004], [61997.2, 0.0], [63708.7, 16.662], [63837.8, 9.781], [63934.7, 3.972], [64257.6, 6.809], [64485.7, 0.008], [64503.0, 0.023], [64519.1, 0.019], [64522.3, 0.0], [64563.7, 0.003], [64564.3, 0.009], [64576.4, 0.124], [64576.7, 0.013]], "asks": [[64592.7, 0.0], [64593.1, 0.008], [64594.8, 0.015], [64622.9, 0.102], [64638.8, 0.003], [64658.1, 0.015], [64690.4, 0.033], [65226.4, 1.36], [65427.5, 3.064], [65452.4, 19.014], [71038.7, 0.004]]}
{"kind": "depth", "E": 1787089934781, "U": 11316021548912, "u": 11316021555435, "recv_ms": 1787089934746, "bids": [[1000.0, 35.76], [14080.5, 3.374], [14180.5, 0.0], [14480.5, 0.826], [58122.4, 0.004], [61351.4, 0.054], [61997.2, 0.003], [63288.9, 4.279], [63580.5, 0.026], [63644.1, 38.014], [63934.7, 3.972], [64383.6, 1.625], [64422.4, 1.005], [64517.6, 5.054], [64517.7, 1.629], [64543.2, 2.421], [64551.9, 0.069], [64552.8, 0.002], [64574.9, 0.072], [64575.1, 0.004], [64576.3, 0.003], [64576.7, 1.553], [64576.9, 0.009], [64580.5, 2.52]], "asks": [[64580.6, 56.466], [64580.7, 0.152], [64595.9, 1.452], [64597.0, 0.0], [64597.1, 0.317], [64597.7, 0.621], [64598.8, 0.042], [64599.5, 2.168], [64601.3, 5.651], [64606.1, 0.314], [64643.5, 2.222], [64657.9, 40.675], [64659.8, 1.062], [64660.1, 0.013], [64737.3, 2.256], [64779.9, 4.248], [65226.4, 1.362], [65355.6, 61.749], [65452.4, 18.724], [65497.6, 2.281], [65580.6, 0.03], [71038.7, 0.002]]}
{"kind": "depth", "E": 1787089934883, "U": 11316021555448, "u": 11316021562801, "recv_ms": 1787089934851, "bids": [[1000.0, 35.76], [14080.5, 3.024], [14480.5, 1.176], [58122.4, 0.004], [61351.4, 0.054], [61351.6, 0.006], [61997.2, 0.0], [63620.2, 3.267], [63631.2, 19.761], [63660.9, 0.023], [63676.4, 59.089], [63766.0, 1.625], [63773.2, 23.862], [63934.7, 3.972], [63994.0, 0.235], [64041.9, 0.0], [64534.0, 0.015], [64541.7, 0.031], [64543.2, 1.084], [64544.3, 0.001], [64545.9, 4.322], [64559.0, 0.129], [64560.1, 0.561], [64564.0, 0.038], [64564.3, 0.001], [64572.2, 0.002], [64573.1, 0.312], [64575.1, 0.001], [64575.4, 2.326], [64575.9, 1.351], [64576.6, 1.813], [64576.8, 0.172], [64576.9, 0.011]], "asks": [[64580.6, 56.366], [64581.6, 0.112], [64581.9, 0.023], [64584.0, 0.354], [64591.1, 0.549], [64591.7, 0.008], [64598.5, 0.003], [64598.9, 0.018], [64600.3, 10.008], [64622.8, 0.154], [64640.1, 0.009], [64657.9, 0.029], [64660.1, 40.895], [64664.5, 3.808], [65219.9, 1.713], [65226.4, 1.36], [65588.2, 1.963], [65872.2, 7.654]]}
{"kind": "depth", "E": 1787089934985, "U": 11316021562896, "u": 11316021571015, "recv_ms": 1787089934949, "bids": [[14080.5, 2.66], [14480.5, 1.54], [58122.4, 0.004], [63580.5, 0.006], [63934.7, 3.972], [64043.5, 0.0], [64172.6, 0.001], [64257.6, 6.819], [64559.7, 0.002], [64560.1, 0.559]], "asks": [[64590.5, 0.088], [64591.7, 0.0], [65162.1, 1.073], [65226.4, 1.36], [65580.6, 0.01], [65685.7, 3.808]]}
{"kind": "depth", "E": 1787089935087, "U": 11316021571105, "u": 11316021584208, "recv_ms": 1787089935051, "bids": [[1000.0, 35.76], [14080.5, 2.31], [14480.5, 1.89], [58122.4, 0.004], [61351.4, 0.054], [61997.2, 0.003], [63914.4, 1.874], [63934.7, 3.972], [64534.0, 0.044], [64551.9, 0.012], [64552.9, 0.057], [64560.0, 4.027], [64565.1, 0.017], [64565.9, 0.039], [64566.0, 0.125], [64566.1, 0.0], [64566.2, 0.929], [64566.5, 0.543], [64566.6, 0.218], [64567.3, 0.623], [64568.9, 0.309], [64570.0, 0.638]], "asks": [[64580.6, 56.366], [64595.8, 0.017], [64596.4, 0.542], [64598.8, 0.661], [64601.3, 0.651], [64602.7, 0.744], [64602.8, 0.0], [64606.1, 0.933], [65162.4, 0.268], [65226.4, 1.36]]}
{"kind": "depth", "E": 1787089935189, "U": 11316021584421, "u": 11316021596852, "recv_ms": 1787089935154, "bids": [[1000.0, 35.76], [14080.5, 1.96], [14480.5, 2.24], [58122.4, 0.004], [61989.2, 0.0], [61997.2, 0.0], [63580.5, 0.026], [63604.4, 2.356], [63934.7, 3.972], [64063.8, 0.001], [64257.6, 6.819], [64383.5, 3.029], [64383.6, 0.0], [64422.3, 2.611], [64422.4, 0.63], [64439.2, 1.598], [64508.8, 1.728], [64528.9, 0.058], [64559.0, 0.013], [64560.0, 4.143], [64560.1, 0.001], [64561.1, 2.053]], "asks": [[64580.6, 56.367], [64597.7, 0.002], [64598.0, 0.625], [64659.7, 0.019], [64720.5, 5.423], [65040.6, 0.0], [65226.4, 1.362], [65491.2, 8.087], [65580.6, 0.03], [65846.5, 3.905]]}
{"kind": "depth", "E": 1787089935393, "U": 11316021605123, "u": 11316021614010, "recv_ms": 1787089935358, "bids": [[1000.0, 35.76], [14080.5, 1.246], [14480.5, 2.954], [58122.4, 0.004], [61997.2, 0.0], [63580.5, 0.006], [63934.7, 3.972], [64063.9, 10.44], [64383.5, 9.115], [64422.3, 5.616], [64439.2, 3.319], [64558.4, 1.683], [64560.6, 0.56], [64561.1, 1.495], [64563.7, 0.003]], "asks": [[64596.1, 0.002], [65037.9, 0.115], [65226.4, 1.36], [65497.6, 2.053], [65580.6, 0.01]]}
{"kind": "depth", "E": 1787089935495, "U": 11316021614215, "u": 11316021623185, "recv_ms": 1787089935460, "bids": [[1000.0, 35.76], [14080.5, 0.882], [14480.5, 3.318], [58122.4, 0.004], [63288.9, 4.282], [63934.7, 3.972], [64257.6, 6.819]], "asks": [[64622.5, 0.002], [64622.8, 0.0], [64657.9, 40.911], [64660.1, 0.013], [65076.5, 0.0], [65226.4, 1.36], [65362.6, 0.777]]}
{"kind": "depth", "E": 1787089935597, "U": 11316021623377, "u": 11316021631774, "recv_ms": 1787089935562, "bids": [[14080.5, 0.532], [14480.5, 3.668], [51664.0, 0.0], [51664.4, 0.0], [58122.4, 0.004], [61351.4, 0.054], [61997.2, 0.003], [63580.5, 0.026], [63934.7, 3.972], [63999.2, 7.709], [64257.5, 0.156], [64298.5, 0.007], [64313.2, 0.0], [64422.3, 5.592], [64439.2, 3.306], [64534.5, 0.076], [64541.0, 0.011], [64565.9, 0.966], [64566.0, 0.759], [64566.2, 0.002], [64570.0, 0.004]], "asks": [[64580.6, 56.367], [64590.5, 0.003], [64591.1, 0.077], [64591.7, 0.557], [64609.4, 0.001], [64609.5, 0.012], [64609.6, 7.13], [64612.4, 0.001], [64612.5, 0.0], [64612.6, 0.0], [64613.3, 0.0], [64613.4, 0.093], [64613.5, 0.159], [64615.4, 0.029], [64615.5, 0.001], [64615.6, 0.001], [64622.8, 0.154], [64636.0, 0.066], [64642.5, 0.093], [64657.9, 0.029], [64660.1, 40.895], [64720.4, 0.0], [64720.5, 5.423], [64737.3, 0.001], [64737.4, 10.429], [64867.6, 0.0], [64874.1, 0.0], [65226.4, 1.36], [65580.6, 0.03], [65788.3, 6.141]]}
{"kind": "depth", "E": 1787089935699, "U": 11316021631903, "u": 11316021639243, "recv_ms": 1787089935663, "bids": [[1000.0, 35.76], [14080.5, 0.308], [14380.5, 0.14], [14480.5, 3.752], [58122.4, 0.004], [61351.4, 0.054], [61997.2, 0.0], [63623.9, 0.942], [63870.1, 7.898], [63934.7, 3.972], [63967.0, 24.535], [64551.9, 0.069], [64552.9, 0.0], [64559.1, 0.117], [64560.0, 4.027], [64565.2, 0.929], [64565.9, 0.039], [64566.1, 0.542], [64566.5, 0.001]], "asks": [[64580.6, 56.362], [64583.4, 0.198], [64595.8, 0.559], [64596.4, 0.0], [64597.6, 0.935], [64598.4, 0.041], [64603.7, 0.059], [64604.5, 0.074], [64657.9, 40.911], [64660.1, 0.013], [64715.2, 0.452], [64903.6, 0.002], [65226.4, 1.36], [65355.6, 59.917], [65465.4, 3.654], [65872.2, 7.651]]}
{"kind": "depth", "E": 1787089935801, "U": 11316021639478, "u": 11316021646910, "recv_ms": 1787089935767, "bids": [[1000.0, 35.76], [14080.5, 0.196], [14380.5, 0.378], [14480.5, 3.626], [58122.4, 0.004], [61351.4, 0.054], [61997.2, 0.003], [63580.5, 0.006], [63753.0, 0.121], [63870.1, 8.133], [63934.7, 3.972], [64257.6, 6.664], [64383.6, 1.632], [64422.4, 1.005], [64551.9, 0.012], [64552.8, 0.059], [64558.4, 1.681], [64565.2, 0.002], [64566.1, 1.469], [64576.8, 0.132], [64579.2, 0.045], [64579.4, 0.003], [64580.0, 0.018], [64580.5, 2.517]], "asks": [[64580.6, 56.325], [64580.7, 0.153], [64595.8, 0.017], [64596.4, 0.542], [64597.6, 0.008], [64598.5, 0.93], [64599.5, 3.366], [64600.3, 15.008], [64603.7, 0.002], [64604.6, 0.155], [64622.7, 0.0], [64622.8, 0.0], [64657.5, 0.442], [64657.9, 0.029], [64660.1, 40.895], [64720.4, 1.472], [65226.4, 1.36], [65580.6, 0.01]]}
{"kind": "depth", "E": 1787089935903, "U": 11316021647025, "u": 11316021654199, "recv_ms": 1787089935868, "bids": [[14080.5, 0.07], [14380.5, 0.616], [14480.5, 3.514], [58122.4, 0.004], [61351.5, 2.451], [63644.1, 38.956], [63934.7, 3.972], [64120.5, 0.137], [64439.2, 3.016], [64503.0, 0.02], [64522.1, 0.002], [64522.3, 0.003], [64522.4, 0.205], [64522.7, 0.056], [64523.1, 0.082], [64523.4, 0.014], [64539.8, 0.002], [64540.1, 0.383], [64540.2, 0.066], [64540.4, 2.326], [64540.8, 0.007], [64541.1, 0.094], [64545.4, 0.015], [64554.5, 0.312], [64554.6, 1.252], [64554.7, 0.047], [64554.8, 0.003], [64554.9, 0.003], [64555.0, 0.003], [64555.1, 0.0], [64555.2, 1.111], [64555.3, 0.0], [64555.6, 0.14], [64556.4, 0.0], [64556.9, 0.002], [64560.0, 3.408], [64567.3, 0.004], [64573.9, 0.003], [64574.0, 0.019], [64574.1, 0.21], [64574.2, 0.012], [64574.3, 0.0], [64574.4, 0.003], [64574.5, 0.084], [64574.6, 0.002], [64574.7, 0.001], [64574.8, 0.014], [64574.9, 0.002], [64575.2, 0.001], [64575.5, 0.001], [64575.6, 0.116], [64575.8, 0.002], [64576.1, 0.002], [64576.4, 0.092], [64576.9, 0.001]], "asks": [[64580.6, 57.734], [64586.9, 0.0], [64587.2, 0.037], [64587.5, 0.098], [64587.8, 0.309], [64588.2, 0.315], [64588.4, 0.001], [64588.6, 0.014], [64588.7, 0.011], [64588.8, 1.067], [64588.9, 0.002], [64589.0, 0.002], [64589.1, 0.001], [64589.2, 0.001], [64589.3, 0.08], [64589.4, 0.059], [64590.0, 0.145], [64598.8, 0.042], [64602.6, 0.006], [64604.5, 0.0], [64604.9, 0.0], [64605.1, 0.394], [64605.2, 0.163], [64605.5, 0.015], [64605.9, 2.325], [64606.1, 0.314], [64606.2, 0.002], [64606.7, 0.008], [64607.7, 0.024], [64607.8, 0.002], [64607.9, 0.004], [64608.0, 0.459], [64608.1, 0.061], [64608.2, 0.0], [64608.3, 0.017], [64608.4, 1.239], [64608.5, 0.105], [64608.6, 0.013], [64612.2, 0.013], [64622.2, 0.041], [64622.6, 0.003], [64622.8, 0.083], [64622.9, 0.173], [64623.2, 0.005], [64623.5, 0.025], [64636.0, 0.062], [64638.8, 0.003], [64643.7, 0.005], [64659.7, 0.026], [64720.5, 5.423], [65226.4, 1.36], [65355.6, 61.749], [65465.4, 4.263], [65872.2, 7.648]]}
{"kind": "depth", "E": 1787089936005, "U": 11316021654296, "u": 11316021660923, "recv_ms": 1787089935969, "bids": [[1000.0, 35.91], [14080.5, 0.0], [14380.5, 0.896], [14480.5, 3.304], [58122.4, 0.004], [61351.4, 0.054], [61997.2, 0.0], [63288.9, 4.279], [63580.5, 0.026], [63676.4, 58.901], [63830.5, 3.134], [63934.7, 3.974], [64257.6, 6.819], [64439.2, 2.604], [64480.8, 0.02], [64545.4, 0.017], [64545.9, 4.324], [64546.7, 0.0], [64558.4, 1.679], [64573.9, 0.073], [64574.6, 0.072], [64576.6, 1.729], [64579.3, 0.0], [64580.5, 2.221]], "asks": [[64580.6, 57.734], [64584.1, 0.315], [64588.4, 0.162], [64589.2, 0.155], [64600.0, 3.185], [64600.3, 15.01], [64607.6, 0.333], [64608.4, 1.393], [64612.2, 0.015], [64640.1, 0.0], [64657.9, 41.05], [64660.1, 0.013], [64720.5, 5.423], [64771.4, 0.007], [65000.0, 116.93], [65226.4, 1.36], [65284.4, 1.186], [65580.6, 0.03]]}
{"kind": "depth", "E": 1787089936107, "U": 11316021660931, "u": 11316021668276, "recv_ms": 1787089936077, "bids": [[1000.0, 35.76], [14380.5, 1.26], [14480.5, 2.94], [58122.4, 0.004], [61351.4, 0.055], [61997.2, 0.003], [63599.4, 0.009], [63773.2, 24.645], [63934.7, 3.972], [64257.6, 6.809], [64438.1, 0.036], [64480.9, 0.003], [64508.8, 1.729], [64552.5, 0.138], [64552.8, 0.002], [64560.0, 4.027], [64565.8, 3.267], [64566.1, 0.542], [64567.3, 0.623], [64568.9, 0.309], [64573.1, 0.002], [64574.0, 0.089], [64574.2, 0.112], [64574.3, 0.07], [64575.9, 1.267], [64579.1, 0.046], [64579.2, 0.001], [64579.7, 0.025]], "asks": [[64580.6, 57.734], [64583.7, 0.066], [64584.8, 0.312], [64588.8, 1.193], [64588.9, 0.222], [64589.1, 0.141], [64590.5, 0.011], [64591.1, 0.619], [64591.7, 0.007], [64595.9, 1.452], [64596.4, 0.542], [64597.7, 0.002], [64598.1, 0.956], [64598.5, 0.003], [64598.8, 0.661], [64599.0, 0.029], [64601.3, 0.094], [64601.9, 0.558], [64604.2, 0.066], [64604.6, 0.098], [64605.1, 0.394], [64606.1, 0.933], [64608.0, 0.585], [64608.1, 0.281], [64608.3, 0.157], [64635.9, 0.016], [64639.3, 0.0], [64643.7, 0.001], [64670.4, 2.909], [64722.3, 1.47], [64771.5, 0.003], [64903.5, 4.77], [65226.4, 1.36], [65561.6, 0.015], [67809.6, 0.004]]}
{"kind": "depth", "E": 1787089936209, "U": 11316021668709, "u": 11316021676380, "recv_ms": 1787089936174, "bids": [[14380.5, 1.61], [14480.5, 2.59], [58122.4, 0.004], [61351.4, 0.054], [61997.2, 0.0], [63580.5, 0.006], [63599.5, 5.553], [63934.7, 3.972], [64063.9, 10.783], [64123.2, 0.117], [64193.0, 0.407], [64501.2, 0.149], [64510.0, 2.387], [64522.5, 0.064], [64528.9, 0.059], [64539.6, 0.034], [64539.9, 0.033], [64540.5, 2.113], [64540.9, 1.288], [64573.7, 0.155], [64573.8, 0.132], [64573.9, 0.143], [64574.1, 0.31], [64574.2, 0.212], [64574.4, 0.103], [64574.5, 0.154], [64574.6, 0.172], [64575.0, 0.274], [64575.3, 0.034], [64575.9, 1.299], [64576.2, 0.656]], "asks": [[64584.8, 0.313], [64586.8, 0.076], [64587.2, 0.111], [64587.5, 0.106], [64587.8, 0.383], [64588.1, 0.084], [64588.5, 0.271], [64588.6, 0.161], [64588.7, 0.261], [64588.9, 0.742], [64589.1, 0.288], [64589.3, 0.213], [64589.4, 0.206], [64590.0, 0.137], [64590.5, 0.088], [64591.1, 0.542], [64601.1, 0.937], [64601.9, 0.001], [64604.5, 0.074], [64604.8, 0.088], [64605.5, 0.089], [64605.8, 0.065], [64606.2, 0.262], [64606.6, 0.271], [64607.8, 0.149], [64607.9, 0.254], [64608.1, 0.531], [64608.4, 1.54], [64608.5, 0.238], [64608.6, 0.16], [64622.2, 0.115], [64622.5, 0.076], [64622.9, 0.173], [64623.2, 0.079], [64623.5, 0.089], [65226.4, 1.36], [65355.8, 1.188], [65580.6, 0.01]]}
{"kind": "depth", "E": 1787089936311, "U": 11316021676701, "u": 11316021683047, "recv_ms": 1787089936276, "bids": [[1000.0, 35.76], [14380.5, 1.974], [14480.5, 2.226], [51664.0, 0.0], [58122.4, 0.004], [61997.2, 0.003], [63288.9, 4.282], [63547.2, 8.773], [63773.2, 24.294], [63934.7, 3.972], [64063.9, 10.783], [64559.2, 0.002], [64559.7, 0.0], [64573.8, 0.202], [64574.1, 0.41], [64574.4, 0.203], [64575.1, 0.004], [64575.4, 2.323], [64576.3, 0.011], [64576.8, 0.124]], "asks": [[64588.6, 0.441], [64589.0, 0.272], [64589.3, 0.36], [64593.1, 0.016], [64594.8, 0.007], [64607.9, 0.534], [64608.2, 0.27], [64608.5, 0.385], [64622.9, 0.173], [64657.9, 0.029], [64660.1, 41.034], [64903.5, 4.924], [65226.4, 1.36], [65284.5, 16.497], [65561.7, 0.031], [71038.7, 0.002]]}
{"kind": "depth", "E": 1787089936413, "U": 11316021683216, "u": 11316021688913, "recv_ms": 1787089936378, "bids": [[14380.5, 2.338], [14480.5, 1.862], [51664.0, 0.0], [58122.4, 0.004], [63547.2, 9.873], [63580.5, 0.026], [63934.7, 3.972], [64257.6, 6.819], [64453.6, 0.032], [64453.7, 0.022], [64545.1, 0.0], [64545.2, 0.016], [64552.5, 0.138], [64553.3, 0.0], [64554.7, 0.117], [64555.4, 0.071], [64558.5, 0.793], [64559.1, 0.001], [64559.7, 0.116], [64560.6, 0.002], [64560.7, 0.56], [64561.8, 0.001], [64563.7, 0.003], [64565.8, 3.267], [64566.0, 0.125], [64566.1, 0.0], [64566.5, 0.543], [64566.7, 0.0], [64567.4, 0.317], [64570.0, 0.638], [64572.2, 0.086], [64575.6, 0.032], [64576.0, 1.635], [64576.2, 0.346], [64576.3, 0.003], [64576.7, 0.005]], "asks": [[64595.9, 1.452], [64596.1, 0.002], [64596.4, 0.542], [64597.7, 0.002], [64598.1, 0.029], [64598.3, 0.927], [64599.1, 0.04], [64601.1, 0.38], [64601.9, 0.558], [64602.7, 0.628], [64603.3, 0.132], [64604.2, 0.009], [64604.3, 0.499], [64605.2, 0.163], [64622.9, 0.019], [64623.0, 0.187], [64688.0, 0.377], [64688.1, 0.013], [64702.3, 4.677], [64702.5, 0.0], [64716.9, 0.017], [64776.1, 0.002], [64776.2, 11.567], [64780.1, 0.288], [65226.4, 1.36], [65271.9, 0.0], [65580.6, 0.03]]}
{"kind": "depth", "E": 1787089936515, "U": 11316021689001, "u": 11316021695937, "recv_ms": 1787089936480, "bids": [[14380.5, 2.688], [14480.5, 1.512], [58122.4, 0.004], [61351.4, 0.054], [61997.2, 0.0], [63934.7, 3.972], [64383.5, 3.054], [64422.3, 2.881], [64439.2, 1.83], [64503.0, 0.023], [64521.9, 0.034], [64522.2, 0.032], [64522.9, 0.032], [64523.2, 1.137], [64541.8, 10.059], [64545.9, 2.324], [64554.0, 0.311], [64554.8, 0.073], [64555.0, 0.103], [64555.1, 0.07], [64555.3, 0.07], [64565.9, 0.673], [64570.0, 0.004], [64576.0, 1.635], [64576.3, 0.003], [64576.4, 0.092], [64576.5, 0.003], [64576.6, 1.729]], "asks": [[64580.6, 57.885], [64596.5, 4.012], [64609.4, 0.003], [64609.5, 0.014], [64609.6, 7.132], [64612.4, 0.003], [64612.5, 0.002], [64612.6, 0.002], [64613.3, 0.002], [64613.4, 0.095], [64613.5, 0.161], [64615.4, 0.031], [64615.5, 0.003], [64615.6, 0.003], [64622.9, 0.019], [64623.0, 0.187], [64658.1, 0.018], [64716.6, 0.016], [64720.5, 5.423], [64780.1, 0.072], [64803.7, 8.606], [65000.0, 116.815], [65097.2, 10.306], [65226.4, 1.36], [65497.6, 2.281], [65872.2, 7.645], [71038.7, 0.002]]}
{"kind": "depth", "E": 1787089936617, "U": 11316021695986, "u": 11316021701675, "recv_ms": 1787089936582, "bids": [[1000.0, 35.76], [14380.5, 3.052], [14480.5, 1.148], [51664.4, 0.0], [58122.4, 0.004], [61997.2, 0.003], [63580.5, 0.006], [63631.8, 3.076], [63669.0, 3.141], [63741.0, 18.135], [63773.2, 24.56], [63934.7, 3.972], [64063.7, 0.702], [64383.5, 9.672], [64383.6, 0.0], [64422.3, 5.818], [64422.4, 0.63], [64439.2, 3.396], [64495.7, 0.101], [64534.0, 0.015], [64543.2, 2.417], [64554.5, 0.382], [64554.6, 1.322], [64554.7, 0.187], [64555.0, 0.203], [64555.1, 0.17], [64556.4, 0.1], [64556.9, 0.102], [64576.0, 1.627], [64576.3, 0.011]], "asks": [[64580.6, 57.852], [64700.0, 1.85], [64776.2, 11.516], [65226.4, 1.36], [65284.5, 17.184], [65387.9, 18.271], [65452.4, 19.014], [65580.6, 0.01]]}
{"kind": "depth", "E": 1787089936719, "U": 11316021701763, "u": 11316021707059, "recv_ms": 1787089936684, "bids": [[14380.5, 3.402], [14480.5, 0.798], [58122.4, 0.004], [61997.2, 0.0], [63741.0, 17.822], [63934.7, 3.816], [64120.5, 0.02], [64257.6, 6.809], [64529.9, 0.004], [64541.0, 0.007], [64554.5, 0.452], [64554.8, 0.173], [64555.2, 1.211]], "asks": [[64599.5, 2.168], [64600.3, 5.01], [64657.9, 41.05], [64660.1, 0.013], [64903.6, 0.0], [65226.4, 1.36], [65387.9, 18.386]]}
{"kind": "depth", "E": 1787089936821, "U": 11316021707234, "u": 11316021713160, "recv_ms": 1787089936786, "bids": [[14280.5, 0.028], [14380.5, 3.696], [14480.5, 0.476], [51664.0, 0.0], [58122.4, 0.004], [61351.5, 2.453], [61997.2, 0.003], [63580.5, 0.026], [63644.1, 38.957], [63663.5, 3.07], [63837.8, 8.842], [63854.6, 1.569], [63934.7, 5.377], [64383.6, 1.715], [64422.4, 1.039]], "asks": [[64580.8, 0.04], [64657.5, 6.471], [64737.3, 2.256], [65097.2, 9.08], [65226.4, 1.362], [65517.0, 37.023], [65580.6, 0.03], [67155.9, 1.274]]}
{"kind": "depth", "E": 1787089936923, "U": 11316021713167, "u": 11316021720319, "recv_ms": 1787089936887, "bids": [[1000.0, 35.76], [14280.5, 0.196], [14380.5, 3.724], [14480.5, 0.28], [58122.4, 0.004], [61997.3, 1.381], [63741.0, 18.448], [63790.3, 2.336], [63934.7, 5.533], [64123.2, 0.234]], "asks": [[64623.0, 0.033], [64635.9, 0.012], [64642.5, 0.015], [65226.4, 1.36], [65339.2, 0.0], [65418.9, 0.004], [65425.4, 0.075]]}
{"kind": "depth", "E": 1787089937025, "U": 11316021720411, "u": 11316021726715, "recv_ms": 1787089936990, "bids": [[14280.5, 0.448], [14380.5, 3.584], [14480.5, 0.168], [58122.4, 0.004], [61351.4, 0.054], [61351.5, 2.451], [61351.6, 0.008], [61997.2, 0.0], [63308.9, 0.001], [63580.5, 0.006], [63611.8, 14.304], [63644.1, 40.055], [63837.8, 9.781], [63934.7, 5.533], [64165.2, 0.001], [64193.0, 0.408], [64257.5, 0.003], [64257.6, 6.819], [64494.5, 0.0], [64495.3, 29.534], [64495.4, 6.61], [64508.5, 1.807], [64508.7, 2.439], [64551.9, 0.012], [64552.5, 0.081], [64552.8, 0.059], [64560.0, 3.408], [64561.7, 0.002], [64565.1, 0.017], [64565.8, 2.34], [64566.0, 0.667], [64566.1, 0.927], [64566.5, 0.001], [64567.3, 0.004], [64572.9, 1.738], [64573.9, 0.145], [64576.1, 1.469], [64576.2, 0.656], [64578.0, 0.988]], "asks": [[64580.6, 56.58], [64598.8, 0.042], [64599.5, 3.283], [64600.3, 15.01], [64604.1, 0.0], [64604.5, 0.081], [64606.1, 0.314], [64622.8, 0.083], [64622.9, 0.019], [64657.5, 0.442], [64657.9, 0.029], [64660.1, 41.034], [64940.1, 0.017], [64968.1, 0.762], [65097.2, 9.999], [65226.4, 1.36], [65418.9, 0.0], [65425.4, 0.0], [65517.0, 38.09], [65580.6, 0.01]]}
{"kind": "depth", "E": 1787089937127, "U": 11316021726796, "u": 11316021732459, "recv_ms": 1787089937092, "bids": [[14280.5, 0.672], [14380.5, 3.486], [14480.5, 0.042], [51664.0, 0.0], [58122.4, 0.004], [61997.2, 0.003], [63288.9, 4.279], [63934.7, 5.533], [64165.2, 0.0], [64193.0, 0.409], [64495.3, 0.01], [64495.4, 0.003], [64501.9, 0.001], [64508.1, 0.05], [64508.5, 31.331], [64544.3, 0.015], [64555.8, 0.218], [64568.9, 0.309]], "asks": [[64580.6, 56.595], [64599.5, 2.168], [64600.3, 5.01], [64622.8, 0.237], [64643.6, 0.004], [64650.0, 0.77], [64657.9, 41.286], [64660.1, 0.013], [64903.5, 4.77], [64940.1, 0.015], [64968.1, 0.764], [65226.4, 1.36], [65497.6, 2.509], [65872.2, 7.648]]}
{"kind": "depth", "E": 1787089937229, "U": 11316021732596, "u": 11316021739422, "recv_ms": 1787089937193, "bids": [[1000.0, 35.76], [14280.5, 0.98], [14380.5, 3.22], [14480.5, 0.0], [51664.0, 0.0], [58122.4, 0.004], [61351.4, 0.054], [61997.2, 0.0], [63580.5, 0.026], [63934.7, 5.535], [64461.6, 0.001], [64461.9, 3.934], [64472.3, 0.0], [64472.4, 2.342], [64503.0, 0.02], [64509.3, 0.014], [64509.4, 0.051], [64522.3, 0.003], [64529.9, 0.0], [64540.6, 0.004], [64541.7, 0.003], [64541.8, 0.059], [64543.2, 1.084], [64546.8, 2.011], [64552.0, 1.08], [64552.8, 0.002], [64559.1, 0.117], [64559.7, 0.0], [64560.0, 4.027], [64563.2, 0.173], [64565.2, 0.002], [64566.0, 1.594], [64566.1, 0.0], [64567.3, 0.623], [64572.9, 0.011], [64573.7, 0.465], [64575.7, 0.084], [64576.0, 0.079], [64576.3, 0.087], [64576.7, 1.561], [64576.8, 0.0], [64579.2, 1.543], [64579.9, 0.013], [64580.5, 2.512]], "asks": [[64580.6, 56.499], [64584.1, 0.312], [64584.8, 0.312], [64593.1, 0.008], [64594.6, 0.025], [64595.7, 0.311], [64595.8, 0.017], [64596.4, 0.542], [64597.7, 0.002], [64598.0, 0.625], [64598.7, 2.57], [64600.5, 0.0], [64601.2, 0.584], [64601.8, 0.004], [64601.9, 0.001], [64602.6, 0.12], [64603.3, 0.016], [64606.1, 0.314], [64622.8, 0.083], [64622.9, 0.019], [64638.8, 0.003], [64640.1, 0.009], [64651.5, 0.046], [64658.1, 0.015], [64687.7, 0.0], [64687.8, 2.323], [64717.4, 0.0], [64717.5, 3.871], [65226.4, 1.36], [65355.8, 2.44], [65580.5, 0.001], [65580.6, 0.03]]}
{"kind": "depth", "E": 1787089937331, "U": 11316021739481, "u": 11316021745793, "recv_ms": 1787089937295, "bids": [[14280.5, 1.344], [14380.5, 2.856], [58122.4, 0.004], [61351.6, 0.006], [63934.7, 5.533], [64257.6, 6.974], [64573.9, 0.143], [64575.3, 0.036]], "asks": [[64622.9, 0.019], [64623.0, 0.187], [64635.9, 0.016], [64643.6, 0.0], [64903.5, 4.924], [65097.2, 10.306], [65226.4, 1.36]]}
{"kind": "depth", "E": 1787089937433, "U": 11316021745955, "u": 11316021751765, "recv_ms": 1787089937427, "bids": [[1000.0, 35.76], [14280.5, 1.694], [14380.5, 2.506], [58122.4, 0.004], [61997.2, 0.003], [63580.5, 0.006], [63934.7, 5.533], [64005.4, 0.117], [64120.4, 0.002], [64422.3, 0.001], [64422.4, 0.007], [64439.2, 0.001], [64563.7, 0.003]], "asks": [[64596.1, 0.002], [64623.0, 0.033], [64720.4, 0.0], [64720.5, 0.015], [64737.3, 0.001], [64737.4, 0.002], [65226.4, 1.36], [65387.9, 18.127], [65580.6, 0.01]]}
{"kind": "depth", "E": 1787089937535, "U": 11316021751879, "u": 11316021757349, "recv_ms": 1787089937498, "bids": [[1000.0, 35.76], [14280.5, 2.058], [14380.5, 2.142], [51664.0, 0.0], [58122.4, 0.004], [61997.2, 0.0], [63676.4, 59.089], [63934.7, 5.533], [64018.6, 4.68], [64383.5, 0.0], [64383.6, 0.0]], "asks": [[64623.0, 0.033], [64657.9, 0.029], [64660.1, 41.27], [64775.8, 1.15], [64776.2, 0.0], [65226.4, 1.362]]}
{"kind": "depth", "E": 1787089937637, "U": 11316021757383, "u": 11316021762571, "recv_ms": 1787089937602, "bids": [[14280.5, 2.408], [14380.5, 1.792], [51664.4, 0.0], [58122.4, 0.004], [61351.4, 0.054], [61997.2, 0.003], [62629.1, 0.0], [63580.5, 0.026], [63591.6, 0.785], [63611.0, 0.179], [63805.5, 67.518], [63934.7, 5.533], [64123.0, 0.173], [64257.6, 6.964], [64558.5, 0.795], [64575.1, 0.001], [64575.5, 0.004], [64580.5, 2.513]], "asks": [[64580.6, 56.499], [64623.0, 0.033], [64623.1, 0.059], [64657.9, 41.286], [64659.7, 0.019], [64660.1, 0.013], [65226.4, 1.36], [65580.6, 0.03]]}
{"kind": "depth", "E": 1787089937739, "U": 11316021762595, "u": 11316021768474, "recv_ms": 1787089937704, "bids": [[1000.0, 35.76], [14280.5, 2.772], [14380.5, 1.428], [51664.0, 0.0], [58122.4, 0.004], [61997.2, 0.0], [63288.9, 4.282], [63934.7, 5.533], [63945.7, 0.0], [64383.5, 9.57], [64422.2, 5.782], [64439.2, 3.379], [64552.0, 1.023], [64552.9, 0.057], [64565.2, 0.002], [64566.0, 0.667], [64566.1, 0.927], [64572.2, 0.002], [64576.7, 1.645]], "asks": [[64595.8, 0.017], [64596.4, 0.542], [64623.1, 0.213], [64720.4, 5.408], [64737.4, 10.429], [64775.8, 3.307], [64776.0, 7.493], [64776.1, 15.44], [64780.1, 0.0], [65226.4, 1.36], [65387.9, 17.784], [65452.5, 0.007]]}
{"kind": "depth", "E": 1787089937841, "U": 11316021768597, "u": 11316021774811, "recv_ms": 1787089937806, "bids": [[1000.0, 35.76], [14280.5, 3.136], [14380.5, 1.064], [58122.4, 0.004], [63580.5, 0.006], [63631.2, 21.094], [63805.5, 68.143], [63934.7, 5.533], [64383.6, 1.7], [64422.3, 1.107], [64559.2, 0.0], [64559.7, 0.002], [64560.1, 0.001], [64568.9, 0.0], [64569.7, 0.472]], "asks": [[64590.5, 0.003], [64591.1, 0.0], [64591.7, 0.634], [64594.6, 0.017], [64594.9, 0.189], [64623.1, 0.059], [64623.2, 0.233], [64657.5, 6.505], [64720.3, 1.472], [64780.1, 0.216], [64803.7, 8.39], [65226.4, 1.36], [65400.0, 110.754], [65549.3, 19.733], [65580.6, 0.01]]}
{"kind": "depth", "E": 1787089937943, "U": 11316021774984, "u": 11316021780832, "recv_ms": 1787089937907, "bids": [[14280.5, 3.486], [14380.5, 0.714], [58122.4, 0.004], [61997.2, 0.003], [63288.9, 4.279], [63934.7, 5.533], [63960.5, 2.416], [64257.6, 6.964], [64576.7, 1.561]], "asks": [[64590.5, 0.088], [64591.1, 0.542], [64591.7, 0.007], [64623.2, 0.079], [64623.3, 2.487], [65226.4, 1.36], [65362.8, 3.839], [65452.4, 19.776], [66869.5, 0.0]]}
{"kind": "depth", "E": 1787089938045, "U": 11316021780905, "u": 11316021787334, "recv_ms": 1787089938009, "bids": [[1000.0, 35.76], [14180.5, 0.056], [14280.5, 3.724], [14380.5, 0.42], [58122.4, 0.004], [61997.2, 0.0], [63580.5, 0.026], [63736.0, 0.088], [63773.2, 24.911], [63934.7, 5.533], [64257.5, 0.001], [64552.5, 0.138], [64552.9, 0.0], [64568.9, 0.005]], "asks": [[64584.1, 0.315], [64623.3, 2.333], [64623.4, 0.154], [64903.6, 0.002], [65226.4, 1.36], [65387.9, 17.524], [65549.3, 20.113], [65580.6, 0.03], [66877.8, 0.148], [71038.7, 0.002]]}
{"kind": "depth", "E": 1787089938147, "U": 11316021787386, "u": 11316021795903, "recv_ms": 1787089938112, "bids": [[1000.0, 35.76], [14180.5, 0.252], [14280.5, 3.696], [14380.5, 0.252], [58122.4, 0.004], [61997.2, 0.003], [61997.3, 1.382], [63695.7, 4.383], [63734.4, 0.274], [63934.7, 5.533], [63991.2, 0.0], [64063.9, 10.471], [64257.6, 6.809], [64568.9, 0.0]], "asks": [[64581.6, 0.092], [64581.9, 0.0], [64584.8, 0.313], [65226.4, 1.36], [65678.4, 0.986], [65872.2, 7.651]]}
{"kind": "depth", "E": 1787089938249, "U": 11316021796107, "u": 11316021805282, "recv_ms": 1787089938214, "bids": [[14180.5, 0.49], [14280.5, 3.57], [14380.5, 0.14], [58122.4, 0.004], [61351.4, 0.054], [63580.5, 0.006], [63624.1, 2.595], [63670.5, 0.0], [63837.8, 8.842], [63934.7, 5.533], [64257.6, 6.819], [64515.9, 0.019], [64534.0, 0.015], [64536.5, 0.699], [64544.0, 10.007], [64546.0, 2.603], [64546.8, 0.011], [64558.5, 0.791], [64559.9, 0.622], [64560.0, 3.408], [64565.7, 0.932], [64566.1, 0.0], [64567.3, 0.623], [64569.2, 0.327], [64569.7, 0.163], [64573.7, 0.155], [64575.2, 0.004], [64575.5, 0.001], [64576.3, 0.003], [64579.4, 0.002], [64580.5, 2.217]], "asks": [[64580.6, 57.876], [64598.7, 3.189], [64606.1, 0.933], [64609.4, 0.001], [64609.5, 0.012], [64609.6, 7.13], [64612.4, 0.001], [64612.5, 0.0], [64612.6, 0.0], [64613.3, 0.0], [64613.4, 0.093], [64613.5, 0.159], [64615.4, 0.029], [64615.5, 0.001], [64615.6, 0.001], [64640.1, 0.0], [64645.2, 0.362], [65226.4, 1.36], [65580.6, 0.01]]}
{"kind": "depth", "E": 1787089938351, "U": 11316021805611, "u": 11316021813852, "recv_ms": 1787089938316, "bids": [[1000.0, 35.76], [14180.5, 0.728], [14280.5, 3.458], [14380.5, 0.014], [51664.0, 0.0], [58122.4, 0.004], [61351.4, 0.054], [61997.2, 0.0], [63430.2, 0.0], [63682.8, 22.877], [63695.7, 5.009], [63740.9, 6.42], [63805.5, 66.266], [63854.6, 0.787], [63993.8, 0.312], [64063.9, 9.537], [64257.6, 6.197], [64543.1, 4.014], [64544.0, 10.009], [64551.7, 0.454], [64552.5, 0.081], [64552.6, 0.082], [64560.0, 3.966], [64560.7, 0.002], [64565.0, 0.268], [64565.7, 0.005], [64565.9, 1.6], [64580.5, 2.23]], "asks": [[64584.8, 0.312], [64595.8, 0.017], [64596.5, 4.014], [64596.9, 0.001], [64597.4, 0.005], [64597.7, 0.621], [64598.0, 0.006], [64598.3, 0.927], [64623.3, 2.333], [64623.4, 0.0], [64903.5, 4.155], [65097.2, 9.999], [65226.4, 1.36], [65226.5, 0.004]]}
{"kind": "depth", "E": 1787089938453, "U": 11316021814074, "u": 11316021821424, "recv_ms": 1787089938418, "bids": [[1000.0, 35.76], [14180.5, 1.078], [14280.5, 3.122], [14380.5, 0.0], [58122.4, 0.004], [61997.2, 0.003], [63580.5, 0.026], [63644.1, 38.957], [63740.8, 2.195], [63773.2, 24.677], [63869.4, 0.001], [63934.7, 5.533], [64450.7, 0.015], [64483.0, 0.001], [64499.7, 0.015], [64506.2, 29.581], [64508.5, 1.807], [64522.3, 0.003], [64532.9, 0.015], [64540.6, 0.0], [64541.2, 0.004], [64563.7, 0.003], [64566.1, 0.001], [64570.0, 0.004], [64576.7, 1.561]], "asks": [[64586.8, 0.077], [64593.1, 0.016], [64594.9, 0.181], [64596.1, 0.002], [64623.3, 2.487], [64623.4, 0.0], [64638.8, 0.003], [65097.2, 10.306], [65226.4, 1.36], [65580.6, 0.03], [65872.2, 7.648]]}
{"kind": "depth", "E": 1787089938555, "U": 11316021821485, "u": 11316021828560, "recv_ms": 1787089938520, "bids": [[14180.5, 1.414], [14280.5, 2.786], [51664.4, 0.0], [58122.4, 0.004], [61351.4, 0.054], [61351.5, 2.449], [61351.6, 0.008], [61997.2, 0.0], [63631.2, 22.349], [63700.0, 25.621], [63837.8, 9.781], [63934.7, 5.533], [64257.6, 6.187], [64503.0, 0.023], [64506.2, 0.005], [64508.5, 31.383], [64554.6, 1.325], [64559.9, 0.003], [64567.3, 0.004]], "asks": [[64580.6, 58.302], [64593.1, 0.008], [64594.5, 0.025], [64598.7, 2.57], [64606.1, 0.314], [64623.3, 2.333], [64658.1, 0.018], [65226.4, 1.36], [67163.8, 2.548], [71038.7, 0.002]]}
{"kind": "depth", "E": 1787089938657, "U": 11316021829322, "u": 11316021836882, "recv_ms": 1787089938620, "bids": [[1000.0, 35.76], [14180.5, 1.792], [14280.5, 2.408], [51664.0, 0.0], [58122.4, 0.004], [61997.2, 0.003], [63450.3, 7.555], [63580.5, 0.006], [63644.1, 40.055], [63798.5, 0.783], [63805.5, 67.518], [63862.8, 8.976], [63876.6, 13.363], [63934.7, 5.533], [64063.9, 10.472], [64257.6, 6.964]], "asks": [[64580.6, 58.302], [64582.5, 0.022], [64582.7, 0.201], [64623.3, 2.333], [64623.4, 0.154], [64903.5, 4.924], [65226.4, 1.36], [65580.6, 0.01]]}
{"kind": "depth", "E": 1787089938759, "U": 11316021836933, "u": 11316021844930, "recv_ms": 1787089938723, "bids": [[1000.0, 35.76], [14180.5, 2.142], [14280.5, 2.058], [58122.4, 0.004], [61351.4, 0.054], [63321.2, 1.107], [63805.5, 68.144], [63934.7, 5.533], [64063.9, 10.784], [64383.5, 3.052], [64383.6, 0.0], [64422.2, 2.875], [64422.3, 0.001], [64439.2, 1.827], [64517.6, 0.007], [64517.7, 1.002], [64580.5, 2.521]], "asks": [[64602.6, 0.124], [64623.4, 0.0], [64623.5, 0.243], [64643.5, 0.002], [65162.5, 0.014], [65226.4, 1.36]]}
{"kind": "depth", "E": 1787089938861, "U": 11316021845121, "u": 11316021852000, "recv_ms": 1787089938740, "bids": [[14180.5, 2.506], [14280.5, 1.694], [58122.4, 0.004], [61997.2, 0.0], [63580.5, 0.026], [63664.0, 14.889], [63934.7, 5.533], [64257.6, 6.974], [64532.9, 0.019], [64541.2, 0.0]], "asks": [[65226.4, 1.36], [65420.3, 2.135], [65580.6, 0.03]]}
{"kind": "depth", "E": 1787089939065, "U": 11316021859150, "u": 11316021866685, "recv_ms": 1787089938944, "bids": [[1000.0, 35.76], [14180.5, 3.22], [14280.5, 0.98], [58122.4, 0.004], [61351.4, 0.054], [61351.5, 2.451], [61997.2, 0.0], [63559.3, 3.32], [63580.5, 0.006], [63934.7, 5.533], [64257.5, 0.003], [64383.5, 9.48], [64422.2, 5.747], [64439.2, 3.36], [64517.6, 4.936], [64568.8, 0.192], [64580.5, 2.52]], "asks": [[64580.6, 58.287], [64635.9, 0.012], [64643.5, 2.208], [64650.0, 0.693], [64903.6, 0.0], [65226.4, 1.362], [65418.2, 0.004], [65424.8, 0.076], [65580.6, 0.01], [65588.2, 2.615]]}
{"kind": "depth", "E": 1787089939167, "U": 11316021866846, "u": 11316021876741, "recv_ms": 1787089939046, "bids": [[14180.5, 3.57], [14280.5, 0.63], [58122.4, 0.004], [61997.2, 0.003], [63288.9, 4.276], [63676.4, 61.442], [63934.7, 5.533], [64063.9, 10.784], [64257.6, 6.974], [64573.1, 0.312]], "asks": [[64580.6, 58.288], [64585.0, 0.02], [64638.6, 0.016], [64645.0, 0.174], [65226.4, 1.36], [65291.2, 0.401], [65418.2, 0.0], [65424.8, 0.0], [65581.6, 31.931]]}
{"kind": "depth", "E": 1787089939269, "U": 11316021877170, "u": 11316021885170, "recv_ms": 1787089939148, "bids": [[1000.0, 35.76], [14080.5, 0.084], [14180.5, 3.766], [14280.5, 0.35], [51664.0, 0.0], [58122.4, 0.004], [61351.4, 0.054], [61997.3, 1.381], [63580.5, 0.026], [63837.8, 9.781], [63934.7, 5.535], [64383.5, 9.571], [64422.2, 5.783], [64439.2, 3.391], [64560.0, 3.966], [64567.3, 0.004], [64576.1, 1.553]], "asks": [[64580.6, 56.907], [64598.7, 2.57], [64606.1, 0.314], [64720.4, 5.408], [65226.4, 1.36], [65226.5, 0.003], [65387.9, 17.783], [65580.6, 0.03], [65872.2, 7.651], [66516.8, 0.001]]}
{"kind": "depth", "E": 1787089939371, "U": 11316021885193, "u": 11316021891289, "recv_ms": 1787089939250, "bids": [[1000.0, 35.76], [14080.5, 0.308], [14180.5, 3.668], [14280.5, 0.224], [51664.0, 0.0], [58122.4, 0.004], [61997.2, 0.0], [62636.5, 4.106], [63579.5, 29.844], [63934.7, 5.533], [64257.6, 6.819]], "asks": [[64580.6, 56.891], [64903.5, 4.77], [65226.4, 1.36], [65581.6, 30.865]]}
{"kind": "depth", "E": 1787089939473, "U": 11316021891329, "u": 11316021901354, "recv_ms": 1787089939352, "bids": [[14080.5, 0.546], [14180.5, 3.542], [14280.5, 0.112], [51664.0, 0.0], [58122.4, 0.004], [61351.4, 0.054], [61351.5, 2.449], [61351.6, 0.01], [61997.2, 0.003], [63812.0, 5.835], [63817.8, 0.554], [63934.7, 5.533], [64257.6, 6.809], [64563.7, 0.003], [64564.0, 0.03], [64566.1, 0.009]], "asks": [[64580.6, 56.892], [64587.5, 0.098], [64590.3, 0.011], [64590.5, 0.003], [64591.1, 0.0], [64591.7, 0.092], [64591.9, 0.542], [64594.5, 0.017], [64594.9, 0.189], [64596.1, 0.002], [64597.7, 0.002], [64598.2, 0.62], [64640.1, 0.009], [65226.4, 1.36], [65387.9, 18.126]]}
{"kind": "depth", "E": 1787089939575, "U": 11316021901416, "u": 11316021909282, "recv_ms": 1787089939454, "bids": [[1000.0, 35.76], [14080.5, 0.798], [14180.5, 3.402], [14280.5, 0.0], [51664.4, 0.0], [58122.4, 0.004], [61351.4, 0.054], [61997.2, 0.0], [63417.8, 0.0], [63579.5, 29.843], [63580.5, 0.006], [63644.1, 38.956], [63934.7, 5.533], [64257.6, 6.964]], "asks": [[64580.6, 57.058], [64581.2, 0.0], [64581.6, 0.099], [64597.2, 0.041], [64599.1, 0.36], [64776.1, 11.486], [64903.5, 4.924], [65226.4, 1.36], [65580.6, 0.01], [65581.6, 31.931]]}
{"kind": "depth", "E": 1787089939677, "U": 11316021909475, "u": 11316021915767, "recv_ms": 1787089939629, "bids": [[1000.0, 35.76], [14080.5, 1.148], [14180.5, 3.052], [58122.4, 0.004], [63288.9, 4.279], [63771.1, 0.0], [63812.0, 6.774], [63837.8, 8.842], [63934.7, 5.533], [64544.3, 0.001]], "asks": [[64587.5, 0.106], [64590.3, 0.003], [64776.0, 7.421], [64780.1, 0.072], [64803.7, 8.606], [65226.4, 1.36]]}
{"kind": "depth", "E": 1787089939779, "U": 11316021915960, "u": 11316021921889, "recv_ms": 1787089939730, "bids": [[14080.5, 1.512], [14180.5, 2.688], [58122.4, 0.004], [61997.2, 0.003], [63288.9, 4.276], [63418.1, 4.615], [63580.5, 0.026], [63669.9, 4.897], [63824.9, 6.605], [63934.7, 5.533], [64257.6, 6.974], [64503.0, 0.02], [64522.3, 0.0], [64547.6, 0.019], [64558.4, 1.792]], "asks": [[64638.8, 0.003], [64658.1, 0.015], [65226.4, 1.36], [65580.6, 0.03]]}
{"kind": "depth", "E": 1787089939881, "U": 11316021922050, "u": 11316021928638, "recv_ms": 1787089939833, "bids": [[1000.0, 35.76], [14080.5, 1.862], [14180.5, 2.338], [51664.0, 0.0], [58122.4, 0.004], [61351.4, 0.054], [61997.2, 0.0], [63579.5, 30.943], [63644.1, 40.055], [63669.9, 5.68], [63837.8, 9.781], [63934.7, 5.533], [64153.0, 0.189], [64159.4, 0.004], [64383.5, 9.391], [64422.2, 5.711], [64439.2, 3.598], [64440.1, 1.429], [64532.9, 0.015], [64534.5, 0.001], [64548.1, 2.001], [64580.5, 2.662]], "asks": [[64580.6, 57.059], [64585.0, 0.019], [64587.5, 0.106], [64590.3, 0.003], [64596.5, 2.014], [64599.5, 1.404], [64600.3, 0.01], [64638.6, 0.012], [64645.0, 0.097], [64720.4, 5.408], [64737.4, 10.429], [64776.1, 15.44], [65226.4, 1.36], [65387.9, 18.386], [65418.2, 0.004], [65424.8, 0.077], [65517.0, 37.023], [65685.5, 0.76]]}
{"kind": "depth", "E": 1787089939983, "U": 11316021928770, "u": 11316021936021, "recv_ms": 1787089939934, "bids": [[1000.0, 35.76], [14080.5, 2.226], [14180.5, 1.974], [58122.4, 0.004], [61351.4, 0.054], [61997.2, 0.003], [63580.5, 0.006], [63805.5, 67.674], [63934.7, 5.533], [64153.0, 0.113], [64159.4, 0.0], [64383.5, 9.571], [64383.6, 0.727], [64422.2, 4.993], [64422.3, 0.673], [64439.2, 2.982], [64494.5, 1.887], [64495.3, 0.01], [64503.0, 0.038], [64506.2, 29.862], [64508.5, 1.807], [64508.7, 2.439], [64517.6, 4.957], [64517.7, 1.612], [64526.5, 0.081], [64532.9, 0.019], [64536.5, 0.685], [64544.0, 0.009], [64546.0, 1.248]], "asks": [[64580.6, 57.059], [64603.0, 10.0], [64639.4, 0.168], [64643.5, 2.208], [64645.9, 0.075], [64776.0, 7.493], [64780.1, 0.216], [64803.7, 8.39], [65226.4, 1.36], [65418.2, 0.0], [65424.8, 0.0], [65580.6, 0.01], [66195.1, 3.637]]}
{"kind": "depth", "E": 1787089940085, "U": 11316021936174, "u": 11316021946585, "recv_ms": 1787089940037, "bids": [[14080.5, 2.576], [14180.5, 1.624], [51664.0, 0.0], [58122.4, 0.004], [61351.6, 0.008], [61997.2, 0.0], [63599.5, 5.545], [63663.5, 3.54], [63773.2, 24.326], [63934.7, 5.533], [64257.5, 0.001], [64257.6, 6.964], [64383.5, 9.674], [64422.2, 5.819], [64439.2, 3.409], [64503.0, 0.02], [64506.2, 0.005], [64508.5, 31.664], [64532.2, 0.074], [64533.1, 0.02], [64564.5, 0.01], [64566.0, 0.125], [64566.1, 0.001], [64566.5, 0.543], [64568.9, 0.0], [64580.5, 2.663]], "asks": [[64580.6, 57.074], [64635.8, 0.061], [64636.5, 0.001], [64657.5, 0.442], [64657.9, 0.029], [64659.7, 0.026], [64659.8, 7.593], [64660.1, 41.564], [64776.1, 11.436], [65226.4, 1.36], [65561.7, 0.023]]}
{"kind": "depth", "E": 1787089940187, "U": 11316021946622, "u": 11316021957644, "recv_ms": 1787089940139, "bids": [[1000.0, 35.76], [14080.5, 2.94], [14180.5, 1.26], [51664.0, 0.0], [58122.4, 0.004], [63580.5, 0.026], [63599.5, 5.553], [63611.7, 0.689], [63773.2, 24.56], [63805.5, 68.144], [63862.8, 9.758], [63934.7, 5.533]], "asks": [[64584.6, 0.008], [64776.0, 7.421], [64780.1, 0.288], [64903.6, 0.002], [65226.4, 1.36], [65517.0, 38.09], [65580.6, 0.03]]}
{"kind": "depth", "E": 1787089940289, "U": 11316021958067, "u": 11316021966873, "recv_ms": 1787089940239, "bids": [[1000.0, 35.76], [14080.5, 3.304], [14180.5, 0.896], [51664.0, 0.0], [58122.4, 0.004], [61351.6, 0.006], [61997.2, 0.003], [63934.7, 5.762], [64422.2, 0.001], [64422.3, 0.001], [64439.2, 0.001], [64440.1, 1.023]], "asks": [[64657.9, 41.58], [64659.8, 1.062], [64660.1, 0.013], [64720.3, 0.665], [64720.4, 0.0], [64737.3, 0.001], [64737.4, 0.002], [64780.1, 0.072], [64803.7, 8.606], [65226.4, 1.36], [65561.7, 0.031]]}
{"kind": "depth", "E": 1787089940391, "U": 11316021966959, "u": 11316021974679, "recv_ms": 1787089940344, "bids": [[14080.5, 3.654], [14180.5, 0.546], [58122.4, 0.004], [61351.4, 0.054], [61997.2, 0.0], [63580.5, 0.006], [63934.7, 5.762], [64257.6, 6.974], [64383.5, 9.492], [64383.6, 0.0], [64422.2, 4.953], [64439.2, 2.955], [64534.0, 0.001], [64558.5, 0.051], [64559.9, 5.003], [64560.0, 5.565], [64563.2, 0.049], [64563.3, 0.354], [64567.3, 0.004], [64579.9, 0.012]], "asks": [[64580.6, 58.349], [64582.6, 0.002], [64587.5, 0.098], [64590.2, 0.026], [64598.7, 2.57], [64606.0, 0.01], [64657.9, 0.029], [64660.1, 41.564], [64662.3, 0.001], [64664.5, 3.808], [64720.4, 5.408], [64737.4, 10.429], [64775.8, 2.928], [64776.1, 12.9], [65182.5, 0.831], [65226.4, 1.36], [65580.6, 0.01]]}
{"kind": "depth", "E": 1787089940493, "U": 11316021974891, "u": 11316021983439, "recv_ms": 1787089940445, "bids": [[1000.0, 35.76], [14080.5, 3.738], [14180.5, 0.322], [14480.5, 0.14], [58122.4, 0.004], [61351.4, 0.054], [61351.5, 2.451], [61997.2, 0.003], [63288.9, 4.273], [63934.7, 5.762], [63991.4, 0.003], [64383.5, 9.583], [64422.2, 5.784], [64439.2, 3.63], [64461.9, 3.934], [64480.9, 0.0], [64481.0, 0.034], [64509.4, 0.051], [64534.0, 0.029], [64563.7, 0.001], [64578.0, 1.008], [64579.1, 0.002], [64580.5, 2.658]], "asks": [[64580.6, 58.349], [64596.1, 0.0], [64651.5, 0.046], [64717.5, 0.0], [64717.6, 3.899], [64771.5, 0.0], [64771.6, 0.004], [64776.1, 11.343], [65226.4, 1.36], [65387.9, 18.127], [65839.9, 1.823]]}
{"kind": "depth", "E": 1787089940595, "U": 11316021983514, "u": 11316021989498, "recv_ms": 1787089940546, "bids": [[1000.0, 35.76], [14080.5, 3.64], [14180.5, 0.196], [14480.5, 0.364], [51664.4, 0.0], [58122.4, 0.004], [60498.2, 0.004], [61997.2, 0.0], [63580.5, 0.026], [63778.0, 0.14], [63934.7, 5.762], [64257.6, 6.984], [64563.7, 0.003]], "asks": [[64596.1, 0.002], [64640.1, 0.0], [65194.1, 25.781], [65226.4, 1.36], [65427.4, 2.307], [65580.6, 0.03]]}
{"kind": "depth", "E": 1787089940799, "U": 11316021994851, "u": 11316021999847, "recv_ms": 1787089940752, "bids": [[1000.0, 35.76], [14080.5, 3.318], [14180.5, 0.0], [14480.5, 0.882], [58122.4, 0.004], [61351.4, 0.054], [61997.2, 0.003], [63580.5, 0.006], [63667.7, 0.075], [63934.7, 5.533], [64439.2, 3.335], [64472.4, 2.342], [64580.5, 2.695]], "asks": [[64580.6, 58.347], [64687.8, 2.323], [64720.4, 5.408], [65097.2, 9.999], [65226.3, 2.298], [65226.4, 1.36], [65580.6, 0.01], [65839.9, 2.581]]}
{"kind": "depth", "E": 1787089940901, "U": 11316022000043, "u": 11316022006485, "recv_ms": 1787089941435, "bids": [[1000.0, 35.76], [14080.5, 2.968], [14480.5, 1.232], [58122.4, 0.004], [61997.2, 0.0], [63514.9, 6.403], [63644.1, 38.957], [63805.5, 69.427], [63934.7, 5.533], [64257.6, 6.964]], "asks": [[64580.6, 58.328], [64640.1, 0.009], [65226.4, 1.36], [65678.5, 23.072]]}
{"kind": "depth", "E": 1787089941003, "U": 11316022006714, "u": 11316022012508, "recv_ms": 1787089941436, "bids": [[14080.5, 2.604], [14480.5, 1.596], [58122.4, 0.004], [61351.4, 0.054], [61997.2, 0.003], [63580.5, 0.026], [63611.8, 15.323], [63644.1, 38.957], [63934.7, 5.533], [64383.6, 1.687], [64422.3, 1.102], [64508.7, 7.65], [64522.3, 0.003]], "asks": [[64580.6, 58.343], [64602.2, 2.23], [64638.8, 0.003], [64658.1, 0.015], [65097.2, 9.385], [65226.4, 1.36], [65298.2, 3.884], [65467.8, 0.0], [65580.6, 0.03], [66524.6, 3.215], [68390.8, 0.0]]}
{"kind": "depth", "E": 1787089941105, "U": 11316022012595, "u": 11316022018970, "recv_ms": 1787089941438, "bids": [[1000.0, 35.76], [14080.5, 2.24], [14480.5, 1.96], [51664.0, 0.04], [58122.4, 0.004], [61351.4, 0.054], [63514.9, 7.504], [63599.4, 0.001], [63599.5, 5.544], [63644.1, 40.055], [63664.0, 14.881], [63665.1, 0.001], [63696.7, 1.962], [63934.7, 5.533], [64383.5, 9.391], [64383.6, 0.0], [64422.2, 5.712], [64422.3, 0.001], [64439.2, 3.354], [64559.9, 0.003], [64560.0, 3.966], [64568.9, 0.0], [64579.7, 0.001], [64579.9, 0.039]], "asks": [[64580.6, 58.33], [64720.4, 5.408], [65097.2, 10.306], [65226.4, 1.36], [65495.8, 0.0], [65497.0, 0.684], [65561.6, 0.007], [65561.7, 0.022]]}
{"kind": "depth", "E": 1787089941207, "U": 11316022019091, "u": 11316022024701, "recv_ms": 1787089941439, "bids": [[1000.0, 35.76], [14080.5, 1.89], [14480.5, 2.31], [51664.0, 0.0], [58122.4, 0.004], [61351.5, 2.449], [61351.6, 0.008], [61997.2, 0.0], [63093.0, 0.001], [63599.5, 5.561], [63664.1, 0.008], [63665.3, 0.196], [63741.0, 21.581], [63805.5, 69.208], [63934.7, 5.533], [64257.5, 0.003], [64257.6, 6.974], [64559.1, 0.001], [64559.8, 0.116], [64560.0, 3.408], [64560.6, 0.56], [64569.2, 0.018], [64569.7, 0.472], [64575.2, 0.001], [64575.7, 0.087]], "asks": [[64584.9, 0.002], [64587.8, 0.074], [64588.1, 0.393], [64903.6, 0.0], [65226.4, 1.36], [65420.1, 23.665], [65428.0, 1.562]]}
{"kind": "depth", "E": 1787089941309, "U": 11316022024923, "u": 11316022029931, "recv_ms": 1787089941440, "bids": [[14080.5, 1.54], [14480.5, 2.66], [58122.4, 0.004], [61997.2, 0.003], [63580.5, 0.006], [63757.9, 0.001], [63934.7, 5.533], [63999.3, 14.699], [64063.9, 10.784], [64551.8, 0.0], [64553.1, 0.311]], "asks": [[65161.8, 16.133], [65226.4, 1.36], [65355.6, 61.139], [65495.9, 0.01], [65497.1, 0.012], [65561.7, 0.039], [65580.6, 0.01], [68390.9, 4.964]]}
{"kind": "depth", "E": 1787089941411, "U": 11316022030083, "u": 11316022035349, "recv_ms": 1787089941441, "bids": [[1000.0, 35.76], [14080.5, 1.176], [14480.5, 3.024], [58122.4, 0.004], [61351.4, 0.054], [61997.2, 0.0], [63725.5, 0.784], [63773.2, 24.717], [63934.7, 5.533], [64560.0, 4.027], [64563.3, 0.23], [64563.4, 0.223], [64567.3, 0.623]], "asks": [[64580.6, 58.329], [64598.8, 0.661], [64600.3, 5.01], [64606.1, 0.933], [65226.4, 1.36], [65425.4, 0.267]]}
{"kind": "depth", "E": 1787089941513, "U": 11316022035452, "u": 11316022040565, "recv_ms": 1787089941464, "bids": [[14080.5, 0.826], [14480.5, 3.374], [58122.4, 0.004], [61997.2, 0.003], [63579.5, 29.845], [63580.5, 0.026], [63934.7, 5.533], [64257.6, 6.974], [64510.7, 0.018], [64563.7, 0.001]], "asks": [[64596.1, 0.0], [65226.4, 1.36], [65355.6, 61.749], [65580.6, 0.03]]}
{"kind": "depth", "E": 1787089941615, "U": 11316022040685, "u": 11316022047007, "recv_ms": 1787089941567, "bids": [[14080.5, 0.476], [14380.5, 0.014], [14480.5, 3.71], [51664.0, 0.0], [51664.4, 0.0], [58122.4, 0.004], [61351.4, 0.054], [61351.6, 0.006], [63934.7, 5.533], [64383.4, 10.259], [64383.5, 0.0], [64422.2, 5.748], [64439.1, 3.372], [64439.2, 0.001], [64517.6, 4.977], [64517.7, 1.002], [64563.7, 0.003]], "asks": [[64580.6, 58.329], [64596.1, 0.002], [64643.5, 2.197], [64888.8, 1.141], [65226.4, 1.36], [65497.6, 2.281], [66515.1, 0.0]]}
{"kind": "depth", "E": 1787089941717, "U": 11316022047189, "u": 11316022052544, "recv_ms": 1787089941669, "bids": [[1000.0, 35.76], [14080.5, 0.294], [14380.5, 0.182], [14480.5, 3.724], [58122.4, 0.006], [61351.4, 0.054], [61997.2, 0.0], [63579.5, 30.943], [63580.5, 0.006], [63934.7, 5.533], [64521.0, 0.401], [64532.2, 0.013], [64532.3, 0.063]], "asks": [[64580.6, 58.327], [65226.4, 1.36], [65496.2, 3.337], [65517.0, 39.157], [65580.6, 0.01], [66195.1, 4.09]]}
{"kind": "depth", "E": 1787089941819, "U": 11316022052740, "u": 11316022058768, "recv_ms": 1787089941772, "bids": [[14080.5, 0.168], [14380.5, 0.42], [14480.5, 3.612], [58122.4, 0.004], [61351.4, 0.054], [61997.2, 0.003], [63288.9, 4.273], [63773.2, 25.068], [63934.7, 5.533], [64257.6, 6.974], [64546.3, 10.001], [64548.1, 0.001], [64560.0, 3.408], [64560.6, 0.002], [64561.1, 2.053], [64564.1, 0.008], [64564.5, 0.002], [64567.3, 0.004], [64569.4, 0.309], [64569.7, 0.163], [64569.8, 0.094], [64571.1, 0.321], [64571.6, 0.002], [64572.0, 0.39], [64572.2, 0.086], [64573.1, 0.002], [64574.9, 0.004], [64575.3, 0.034], [64575.4, 2.407], [64575.7, 0.003], [64575.8, 0.121], [64576.1, 0.002], [64577.7, 0.0], [64578.3, 0.001], [64580.5, 3.045]], "asks": [[64580.6, 56.356], [64584.1, 0.312], [64584.9, 0.001], [64587.5, 0.106], [64587.8, 0.154], [64589.9, 0.004], [64590.2, 0.018], [64590.5, 0.095], [64591.1, 0.542], [64591.7, 0.0], [64591.9, 0.0], [64598.8, 0.042], [64599.0, 0.029], [64602.6, 0.008], [64602.8, 0.116], [64606.1, 0.314], [64640.1, 0.0], [64903.5, 4.77], [65226.4, 1.36]]}
{"kind": "depth", "E": 1787089941921, "U": 11316022058891, "u": 11316022063858, "recv_ms": 1787089941873, "bids": [[14080.5, 0.056], [14380.5, 0.658], [14480.5, 3.486], [58122.4, 0.004], [61997.2, 0.0], [63580.5, 0.026], [63773.2, 24.717], [63934.7, 5.533], [64532.9, 0.015], [64541.1, 0.098], [64560.6, 0.56], [64561.1, 1.495]], "asks": [[65226.4, 1.36], [65580.6, 0.03]]}
{"kind": "depth", "E": 1787089942023, "U": 11316022063986, "u": 11316022070346, "recv_ms": 1787089941975, "bids": [[1000.0, 35.76], [14080.5, 0.0], [14380.5, 0.966], [14480.5, 3.234], [58122.4, 0.004], [61351.4, 0.054], [61997.2, 0.003], [63934.7, 5.533], [63997.5, 0.0], [64383.4, 10.123], [64383.5, 0.0], [64422.2, 5.7], [64422.3, 0.001], [64439.1, 3.348], [64517.6, 0.007], [64517.7, 5.993], [64534.0, 0.001], [64536.5, 0.699], [64558.5, 0.766], [64564.2, 0.0], [64572.2, 0.002], [64573.1, 0.312], [64574.9, 0.002], [64575.2, 0.003], [64576.3, 0.087], [64577.6, 0.002], [64578.3, 0.0], [64580.5, 3.045]], "asks": [[64580.6, 56.25], [64599.5, 1.404], [64600.3, 0.01], [64640.1, 0.009], [64643.5, 2.208], [64659.8, 7.593], [64720.3, 1.387], [64720.4, 5.408], [64903.5, 4.924], [65226.4, 1.362]]}
{"kind": "depth", "E": 1787089942125, "U": 11316022070411, "u": 11316022078012, "recv_ms": 1787089942077, "bids": [[14380.5, 1.316], [14480.5, 2.884], [58122.4, 0.004], [61351.4, 0.054], [61351.5, 2.447], [61351.6, 0.008], [63580.5, 0.006], [63934.7, 5.533], [64257.5, 0.002], [64257.6, 6.974], [64532.9, 0.019], [64541.1, 0.094], [64568.9, 0.0], [64575.3, 0.037], [64575.7, 0.0], [64580.5, 3.046]], "asks": [[64580.6, 56.355], [64582.0, 0.046], [64584.3, 0.001], [64587.1, 0.003], [64589.7, 0.114], [65226.4, 1.36], [65387.9, 18.386], [65580.6, 0.01]]}
{"kind": "depth", "E": 1787089942227, "U": 11316022078103, "u": 11316022084490, "recv_ms": 1787089942179, "bids": [[14380.5, 1.68], [14480.5, 2.52], [58122.4, 0.004], [61997.2, 0.0], [63934.7, 5.533], [63999.2, 8.801], [64257.5, 0.001], [64439.1, 3.347], [64521.9, 0.002], [64522.2, 0.0], [64522.3, 0.003], [64522.5, 0.032], [64522.9, 0.0], [64523.2, 1.105], [64536.6, 0.0], [64539.6, 0.002], [64539.9, 0.001], [64540.2, 0.066], [64540.5, 2.081], [64540.6, 0.032], [64540.9, 1.288], [64546.2, 0.025], [64554.5, 0.312], [64554.6, 1.255], [64554.7, 0.047], [64554.8, 0.003], [64555.0, 0.003], [64555.1, 0.0], [64555.2, 1.111], [64555.3, 0.0], [64555.4, 0.001], [64556.4, 0.0], [64556.9, 0.002], [64570.0, 0.004], [64573.7, 0.085], [64573.8, 0.132], [64573.9, 0.073], [64574.0, 0.021], [64574.1, 0.21], [64574.2, 0.012], [64574.3, 0.0], [64574.4, 0.003], [64574.5, 0.084], [64574.6, 0.102], [64574.9, 0.002], [64575.0, 0.242], [64575.2, 0.001], [64575.3, 0.005], [64575.6, 0.032], [64575.9, 0.78], [64576.2, 0.656], [64576.7, 0.005], [64576.8, 0.0], [64576.9, 1.557]], "asks": [[64586.8, 0.077], [64587.1, 0.077], [64587.2, 0.037], [64587.4, 0.084], [64587.5, 0.015], [64587.8, 0.08], [64588.1, 0.329], [64588.4, 0.001], [64588.5, 0.271], [64588.6, 0.014], [64588.7, 0.011], [64588.8, 1.067], [64588.9, 0.002], [64589.0, 0.002], [64589.1, 0.148], [64589.2, 0.134], [64589.3, 0.08], [64589.4, 0.059], [64589.9, 0.012], [64590.5, 0.003], [64591.1, 0.0], [64591.7, 0.634], [64604.5, 0.081], [64604.8, 0.088], [64605.1, 0.394], [64605.5, 0.015], [64605.8, 0.001], [64606.2, 0.262], [64606.6, 0.001], [64607.6, 0.172], [64607.8, 0.002], [64607.9, 0.004], [64608.0, 0.459], [64608.1, 0.061], [64608.2, 0.0], [64608.3, 0.164], [64608.4, 1.239], [64608.5, 0.238], [64608.6, 0.013], [64622.2, 0.115], [64622.5, 0.076], [64622.8, 0.083], [64623.2, 0.005], [64623.5, 0.179], [64638.8, 0.003], [64720.4, 5.408], [64903.6, 0.002], [65000.0, 116.694], [65226.4, 1.36]]}
{"kind": "depth", "E": 1787089942329, "U": 11316022084647, "u": 11316022090469, "recv_ms": 1787089942281, "bids": [[1000.0, 35.76], [14380.5, 2.03], [14480.5, 2.17], [51664.0, 0.0], [58122.4, 0.004], [61351.4, 0.054], [61997.2, 0.003], [63580.5, 0.026], [63934.7, 5.533], [64564.1, 0.0], [64565.9, 0.966], [64569.2, 0.018], [64570.0, 1.56], [64570.1, 0.694], [64572.7, 0.931], [64573.8, 0.202], [64574.0, 0.019], [64574.1, 0.31], [64574.2, 0.01], [64574.4, 0.103], [64575.3, 0.002], [64575.6, 0.035], [64576.8, 0.002], [64576.9, 0.001], [64577.0, 0.001], [64577.1, 0.108], [64577.2, 0.003], [64578.0, 0.662]], "asks": [[64580.6, 56.319], [64588.6, 0.294], [64589.0, 0.272], [64589.3, 0.227], [64591.1, 0.077], [64591.7, 0.557], [64607.8, 0.282], [64608.2, 0.27], [64608.5, 0.385], [65226.4, 1.36], [65580.6, 0.03]]}
{"kind": "depth", "E": 1787089942431, "U": 11316022090697, "u": 11316022097409, "recv_ms": 1787089942383, "bids": [[14380.5, 2.394], [14480.5, 1.806], [51664.0, 0.0], [58122.4, 0.004], [61997.2, 0.0], [63288.9, 4.276], [63417.6, 0.0], [63604.1, 0.061], [63697.0, 1.885], [63934.7, 5.533], [63959.9, 1.719], [64257.6, 6.964], [64564.4, 0.024], [64566.0, 0.751], [64566.1, 0.009], [64570.0, 0.004], [64570.1, 0.052], [64572.7, 0.929], [64573.9, 0.143], [64574.0, 0.021], [64574.3, 0.07], [64574.7, 0.071], [64576.7, 1.561]], "asks": [[64588.4, 0.162], [64588.8, 1.193], [64589.2, 0.288], [64591.1, 0.0], [64591.9, 0.077], [64607.6, 0.333], [64608.0, 0.585], [64608.4, 1.393], [65226.4, 1.36]]}
{"kind": "depth", "E": 1787089942533, "U": 11316022097620, "u": 11316022103683, "recv_ms": 1787089942487, "bids": [[14380.5, 2.744], [14480.5, 1.456], [58122.4, 0.004], [61351.4, 0.054], [63580.5, 0.006], [63637.6, 0.689], [63669.9, 6.463], [63805.5, 68.738], [63869.5, 0.4], [63934.7, 5.533], [63967.0, 25.314], [64063.9, 10.472], [64439.1, 0.0], [64522.5, 0.064], [64522.9, 0.032], [64523.2, 1.137], [64532.9, 0.015], [64539.6, 0.034], [64539.9, 0.033], [64541.2, 0.004], [64559.2, 5.0], [64559.4, 0.619], [64563.7, 0.001], [64566.8, 0.621], [64574.0, 0.091], [64574.3, 0.17], [64574.4, 0.203], [64574.5, 0.154], [64575.0, 0.274], [64575.3, 0.034]], "asks": [[64580.6, 56.349], [64583.7, 0.007], [64587.8, 0.074], [64588.1, 0.393], [64588.6, 0.441], [64588.7, 0.261], [64588.8, 1.413], [64589.1, 0.288], [64589.9, 0.084], [64590.4, 0.023], [64594.9, 0.181], [64595.2, 0.183], [64596.1, 0.0], [64598.2, 1.239], [64605.4, 1.919], [64605.6, 0.654], [64605.8, 0.065], [64607.8, 0.429], [64607.9, 0.254], [64608.0, 0.805], [64608.3, 0.304], [64623.1, 0.133], [64623.5, 0.243], [64657.9, 41.907], [64659.8, 1.062], [64660.1, 0.013], [64720.3, 0.665], [64720.4, 0.0], [64903.5, 4.308], [65226.4, 2.89], [65580.6, 0.01]]}
{"kind": "depth", "E": 1787089942635, "U": 11316022103772, "u": 11316022109840, "recv_ms": 1787089942587, "bids": [[1000.0, 35.76], [14380.5, 3.108], [14480.5, 1.092], [51664.0, 0.0], [51664.4, 0.0], [58122.4, 0.004], [61997.2, 0.003], [63934.7, 5.533], [64383.4, 10.103], [64422.2, 4.902], [64439.1, 2.934], [64451.3, 0.014], [64503.0, 0.023], [64554.6, 1.325], [64554.7, 0.117], [64556.9, 0.102], [64563.7, 0.003], [64564.2, 0.037], [64566.1, 0.001], [64566.8, 0.002], [64567.1, 0.088], [64568.8, 0.155], [64573.1, 0.002], [64573.7, 0.155], [64574.0, 0.089], [64574.1, 0.41], [64574.2, 0.11], [64574.4, 0.205], [64575.9, 1.066], [64580.5, 3.041]], "asks": [[64580.6, 57.62], [64581.7, 0.022], [64582.7, 0.179], [64584.1, 0.315], [64588.9, 0.522], [64589.4, 0.206], [64591.1, 0.0], [64591.8, 0.08], [64591.9, 0.0], [64596.1, 0.002], [64598.2, 0.62], [64606.6, 0.271], [64608.1, 0.311], [64608.6, 0.16], [64658.1, 0.018], [64720.4, 5.408], [64737.4, 10.429], [64776.1, 13.13], [65226.4, 2.89], [65303.9, 3.34], [65484.7, 79.282], [65549.3, 19.808], [65678.5, 23.452], [65872.2, 7.648]]}
{"kind": "depth", "E": 1787089942737, "U": 11316022109927, "u": 11316022114523, "recv_ms": 1787089942687, "bids": [[14380.5, 3.458], [14480.5, 0.742], [58122.4, 0.004], [61351.4, 0.054], [61997.2, 0.0], [63288.9, 4.273], [63418.1, 4.993], [63580.5, 0.026], [63606.5, 0.55], [63708.7, 18.072], [63934.7, 5.533], [64063.9, 10.784], [64257.6, 6.964], [64383.4, 10.169], [64422.2, 5.713], [64439.1, 3.598], [64440.1, 1.429], [64472.4, 2.342], [64554.5, 0.382], [64554.8, 0.103], [64555.2, 1.211], [64559.0, 0.129], [64559.4, 0.0], [64559.8, 0.0], [64566.1, 0.009], [64566.6, 0.218], [64567.1, 0.08], [64576.3, 0.003], [64580.5, 3.037]], "asks": [[64580.6, 57.621], [64587.5, 0.023], [64590.4, 0.015], [64591.1, 0.542], [64591.7, 0.015], [64601.9, 0.117], [64602.8, 0.0], [64605.6, 0.035], [64657.9, 0.029], [64664.5, 45.686], [64684.8, 2.563], [64687.8, 2.323], [64903.5, 4.924], [65226.4, 2.89], [65355.9, 1.713], [65580.6, 0.03]]}
{"kind": "depth", "E": 1787089942839, "U": 11316022114602, "u": 11316022119644, "recv_ms": 1787089942791, "bids": [[1000.0, 35.76], [14280.5, 0.042], [14380.5, 3.738], [14480.5, 0.42], [51664.0, 0.0], [58122.4, 0.004], [61351.4, 0.048], [61997.2, 0.003], [63663.5, 3.306], [63773.2, 24.366], [63805.5, 68.957], [63876.6, 14.144], [63934.7, 5.533], [64521.9, 0.034], [64522.2, 0.032], [64551.8, 0.0], [64552.6, 0.335], [64552.7, 0.06], [64553.1, 0.001], [64554.7, 0.187], [64555.1, 0.07], [64555.4, 0.071], [64559.0, 0.013], [64560.0, 3.524], [64560.1, 0.559], [64560.6, 0.002], [64565.1, 0.017], [64565.9, 0.039], [64566.0, 1.678], [64566.1, 0.551], [64566.5, 0.001]], "asks": [[64580.6, 57.62], [64580.7, 0.185], [64581.0, 0.163], [64590.5, 0.08], [64591.8, 0.003], [64595.8, 0.017], [64596.4, 0.542], [64597.5, 0.45], [64598.3, 0.0], [64598.4, 0.968], [64600.5, 0.0], [64601.2, 0.584], [64601.9, 0.001], [64602.8, 0.116], [64660.1, 41.735], [64664.5, 3.808], [65226.4, 2.89]]}
{"kind": "depth", "E": 1787089942941, "U": 11316022119739, "u": 11316022124653, "recv_ms": 1787089942893, "bids": [[1000.0, 35.76], [14280.5, 0.238], [14380.5, 3.696], [14480.5, 0.266], [58122.4, 0.004], [61351.4, 0.048], [61997.2, 0.0], [63095.1, 2.692], [63580.5, 0.006], [63934.7, 5.533], [64554.8, 0.173], [64555.0, 0.103], [64555.2, 1.311], [64555.3, 0.07]], "asks": [[64580.6, 57.624], [64581.0, 0.009], [65226.4, 2.89], [65549.3, 20.113], [65580.6, 0.01]]}
{"kind": "depth", "E": 1787089943043, "U": 11316022124832, "u": 11316022131395, "recv_ms": 1787089942994, "bids": [[14280.5, 0.476], [14380.5, 3.584], [14480.5, 0.14], [58122.4, 0.004], [61351.4, 0.048], [63766.0, 2.408], [63934.7, 5.533], [64257.6, 6.974], [64383.5, 1.674], [64422.3, 1.097], [64494.5, 0.0], [64495.3, 29.73], [64495.4, 6.64], [64503.0, 0.032], [64508.5, 1.807], [64508.7, 2.439], [64517.7, 5.008], [64517.8, 1.746], [64554.5, 0.452], [64555.0, 0.203], [64556.5, 0.104], [64558.5, 0.051], [64559.3, 1.479], [64567.5, 0.029], [64568.9, 0.005]], "asks": [[64580.6, 57.624], [64609.4, 0.003], [64609.5, 0.014], [64609.6, 7.132], [64612.4, 0.003], [64612.5, 0.002], [64612.6, 0.002], [64613.3, 0.002], [64613.4, 0.095], [64613.5, 0.161], [64615.4, 0.031], [64615.5, 0.003], [64615.6, 0.003], [64659.8, 7.619], [64669.9, 3.191], [64720.3, 1.387], [65226.4, 2.89], [65452.4, 19.167], [65872.2, 7.651]]}
{"kind": "depth", "E": 1787089943145, "U": 11316022131715, "u": 11316022137598, "recv_ms": 1787089943096, "bids": [[1000.0, 35.76], [14280.5, 0.728], [14380.5, 3.444], [14480.5, 0.028], [51664.0, 0.0], [58122.4, 0.004], [61997.2, 0.003], [63580.5, 0.026], [63597.6, 0.0], [63733.6, 6.274], [63934.7, 5.533], [64495.3, 0.01], [64495.4, 0.003], [64503.0, 0.023], [64506.2, 29.725], [64568.9, 0.0]], "asks": [[64581.6, 0.121], [64582.5, 0.002], [65226.4, 2.89], [65388.1, 0.001], [65563.5, 0.032], [65580.6, 0.03], [67155.9, 0.637]]}
{"kind": "depth", "E": 1787089943247, "U": 11316022137667, "u": 11316022142805, "recv_ms": 1787089943199, "bids": [[1000.0, 35.76], [14280.5, 1.05], [14380.5, 3.15], [14480.5, 0.0], [51664.0, 0.0], [58122.4, 0.004], [61351.4, 0.042], [61351.5, 2.449], [61997.2, 0.0], [63597.6, 0.011], [63805.5, 69.427], [63854.6, 0.005], [63934.7, 5.533], [64383.4, 5.838]], "asks": [[64581.6, 0.099], [64590.5, 0.088], [64591.7, 0.007], [64594.8, 0.015], [64595.2, 0.175], [64640.1, 0.0], [64737.4, 0.002], [64737.6, 11.74], [64903.6, 0.0], [65226.4, 2.89], [65563.4, 0.011]]}
{"kind": "depth", "E": 1787089943451, "U": 11316022148526, "u": 11316022153510, "recv_ms": 1787089943403, "bids": [[1000.0, 35.76], [14280.5, 1.764], [14380.5, 2.436], [58122.4, 0.004], [61997.2, 0.0], [63482.6, 16.485], [63934.6, 0.005], [63934.7, 5.533], [64288.4, 0.202], [64327.8, 0.0], [64367.2, 0.001], [64406.6, 0.006], [64409.1, 0.014], [64446.0, 0.864], [64470.7, 0.007], [64485.4, 0.002], [64564.4, 0.016], [64566.2, 0.01]], "asks": [[64587.5, 0.015], [64590.3, 0.011], [64590.5, 0.003], [64591.1, 0.0], [64591.7, 0.626], [64591.9, 0.008], [64594.8, 0.007], [64595.2, 0.183], [64637.0, 1.248], [64637.3, 0.0], [64637.6, 0.009], [64677.0, 0.504], [64716.4, 0.0], [64755.4, 1.517], [64755.8, 0.0], [64794.6, 1.175], [64795.1, 0.0], [64795.2, 1.735], [64834.6, 0.001], [65226.4, 2.892], [65400.0, 110.792], [65484.7, 79.099], [65908.3, 0.005]]}
{"kind": "depth", "E": 1787089943553, "U": 11316022153572, "u": 11316022158419, "recv_ms": 1787089943504, "bids": [[1000.0, 35.76], [14280.5, 2.114], [14380.5, 2.086], [58122.4, 0.004], [61351.4, 0.042], [63482.6, 16.877], [63580.5, 0.026], [63934.7, 5.533], [64470.7, 0.004], [64503.0, 0.02], [64522.3, 0.0], [64524.1, 6.899], [64534.0, 0.015], [64559.2, 0.0], [64559.3, 0.002], [64560.1, 0.62], [64567.5, 0.648], [64579.9, 0.04]], "asks": [[64580.6, 57.628], [64598.9, 0.637], [64606.2, 0.881], [64636.9, 2.616], [64638.8, 0.0], [64658.1, 0.015], [64690.4, 0.033], [65226.4, 2.89], [65420.4, 3.209], [65580.6, 0.03]]}
{"kind": "depth", "E": 1787089943655, "U": 11316022158579, "u": 11316022164791, "recv_ms": 1787089943607, "bids": [[14280.5, 2.478], [14380.5, 1.722], [51664.0, 0.0], [51664.4, 0.0], [58122.4, 0.004], [61351.4, 0.036], [61997.2, 0.003], [63773.2, 24.482], [63934.7, 5.533], [64257.6, 6.964], [64506.2, 0.005], [64508.5, 31.527], [64559.8, 0.116], [64560.1, 0.001], [64560.7, 0.002], [64560.8, 0.559], [64561.7, 0.002], [64563.7, 0.003], [64563.8, 0.012], [64564.3, 0.001], [64565.8, 3.267], [64566.0, 0.125], [64566.1, 0.001], [64566.2, 0.002], [64566.5, 0.543], [64566.7, 0.0], [64566.8, 0.002], [64567.5, 0.029], [64567.6, 0.164], [64568.9, 0.309], [64569.4, 0.0], [64570.0, 1.56], [64570.1, 0.686], [64572.2, 0.086], [64572.7, 0.931], [64574.0, 0.089], [64574.2, 0.11], [64574.4, 0.203], [64575.1, 0.004], [64575.4, 2.323], [64575.8, 0.037], [64576.7, 0.005], [64580.5, 2.728]], "asks": [[64580.6, 57.628], [64580.8, 0.047], [64581.6, 0.092], [64584.3, 0.0], [64587.4, 0.393], [64587.5, 0.023], [64588.1, 0.084], [64590.3, 0.003], [64591.1, 0.077], [64591.7, 0.549], [64593.1, 0.016], [64594.8, 0.007], [64595.2, 0.175], [64596.1, 0.002], [64596.4, 0.542], [64597.7, 0.002], [64598.3, 0.927], [64598.4, 0.041], [64598.9, 0.018], [64599.2, 0.003], [64601.2, 0.027], [64602.0, 0.697], [64602.8, 0.0], [64603.5, 0.13], [64603.7, 0.002], [64604.1, 0.007], [64604.3, 0.499], [64604.5, 0.074], [64605.3, 0.002], [65226.4, 2.89], [65452.4, 19.167]]}
{"kind": "depth", "E": 1787089943757, "U": 11316022165027, "u": 11316022171572, "recv_ms": 1787089943709, "bids": [[1000.0, 35.76], [14280.5, 2.828], [14380.5, 1.372], [51664.0, 0.0], [58122.4, 0.004], [61351.5, 2.449], [61351.6, 0.01], [61997.2, 0.0], [63580.5, 0.006], [63934.7, 5.533], [64120.6, 0.0], [64559.0, 0.015], [64559.7, 0.0]], "asks": [[64590.5, 0.003], [64591.1, 0.085], [64591.9, 0.0], [64597.9, 0.003], [64598.9, 0.016], [65226.4, 2.89], [65580.6, 0.01]]}
{"kind": "depth", "E": 1787089943961, "U": 11316022179073, "u": 11316022185265, "recv_ms": 1787089943913, "bids": [[14280.5, 3.556], [14380.5, 0.644], [58122.4, 0.004], [63580.5, 0.026], [63693.6, 0.0], [63934.7, 5.533], [64122.9, 0.137], [64257.6, 6.974], [64439.1, 0.0], [64517.7, 0.017], [64560.7, 0.021]], "asks": [[64580.6, 57.628], [64600.3, 5.01], [64643.5, 0.002], [64720.4, 0.0], [65226.4, 2.892], [65580.6, 0.03], [65872.2, 7.651]]}
{"kind": "depth", "E": 1787089944063, "U": 11316022185301, "u": 11316022191530, "recv_ms": 1787089944015, "bids": [[1000.0, 35.76], [14180.5, 0.07], [14280.5, 3.766], [14380.5, 0.364], [58122.4, 0.004], [61351.4, 0.03], [61997.2, 0.0], [63288.9, 4.276], [63661.0, 0.002], [63664.0, 12.529], [63695.7, 5.635], [63708.7, 18.072], [63934.7, 5.533], [63955.9, 0.624], [64383.4, 10.385], [64383.5, 0.791], [64422.2, 4.851], [64422.3, 0.603], [64439.1, 3.019], [64494.5, 1.887], [64517.7, 4.986], [64517.8, 1.743], [64558.5, 0.766], [64568.9, 0.309]], "asks": [[64643.4, 2.526], [64720.4, 5.408], [64737.3, 2.256], [65226.4, 2.89], [65743.1, 11.598], [71038.7, 0.002]]}
{"kind": "depth", "E": 1787089944267, "U": 11316022199286, "u": 11316022205698, "recv_ms": 1787089944219, "bids": [[14180.5, 0.532], [14280.5, 3.556], [14380.5, 0.112], [51664.0, 0.0], [58122.4, 0.004], [61997.2, 0.0], [63637.6, 1.081], [63773.1, 2.168], [63934.7, 5.533], [64257.5, 0.001], [64257.6, 6.964], [64575.6, 0.116]], "asks": [[65226.4, 2.89], [65561.6, 0.017], [65743.1, 11.963]]}
{"kind": "depth", "E": 1787089944369, "U": 11316022205840, "u": 11316022212577, "recv_ms": 1787089944321, "bids": [[1000.0, 35.76], [14180.5, 0.784], [14280.5, 3.416], [14380.5, 0.0], [58122.4, 0.004], [61351.4, 0.03], [61997.2, 0.003], [63580.5, 0.026], [63773.2, 24.217], [63854.7, 2.346], [63934.7, 5.533], [63967.0, 26.349], [64257.6, 6.809], [64574.9, 0.005], [64575.1, 0.001]], "asks": [[64580.6, 57.638], [64597.5, 1.069], [64598.2, 0.001], [64599.5, 1.971], [64601.2, 0.584], [64602.0, 0.14], [64602.8, 0.116], [64603.5, 0.014], [64903.6, 0.002], [65226.4, 2.89], [65303.9, 3.348], [65580.6, 0.03]]}
{"kind": "depth", "E": 1787089944573, "U": 11316022218501, "u": 11316022223894, "recv_ms": 1787089944525, "bids": [[14180.5, 1.498], [14280.5, 2.702], [58122.4, 0.004], [61351.4, 0.031], [61351.6, 0.01], [61997.2, 0.0], [63580.5, 0.006], [63773.2, 24.568], [63934.7, 5.533], [64257.6, 6.964], [64495.3, 29.986], [64508.5, 1.807], [64515.8, 0.002], [64552.1, 1.01], [64552.3, 0.096], [64552.6, 0.025], [64552.7, 0.003], [64559.4, 0.116], [64559.8, 0.0], [64560.0, 4.027], [64560.6, 0.56], [64560.7, 0.021], [64560.8, 0.001], [64561.7, 0.002], [64561.9, 0.009], [64563.2, 0.041], [64563.5, 0.069], [64563.8, 0.004], [64565.5, 0.927], [64565.8, 2.34], [64565.9, 0.039], [64566.3, 0.002], [64566.7, 0.0], [64567.4, 0.936], [64570.3, 0.254], [64570.4, 0.543], [64571.4, 0.154], [64572.0, 0.236], [64572.7, 0.931], [64574.1, 0.287], [64576.7, 0.013], [64578.1, 0.001]], "asks": [[64580.6, 57.645], [64580.8, 0.04], [64590.5, 0.622], [64591.1, 0.008], [64591.7, 0.007], [64592.5, 0.011], [64593.1, 0.008], [64595.8, 0.559], [64596.4, 0.0], [64597.4, 0.005], [64597.9, 0.93], [64598.3, 0.0], [64598.4, 0.66], [64599.2, 0.003], [64600.7, 0.577], [64601.2, 0.027], [64602.0, 0.14], [64602.8, 0.0], [64603.5, 0.13], [64604.0, 0.059], [64604.3, 0.442], [64605.3, 0.002], [64605.8, 0.684], [64737.4, 0.002], [64737.5, 7.162], [64776.1, 10.766], [65226.4, 2.89], [65484.7, 78.916], [65496.2, 2.27], [65549.5, 0.762], [65580.6, 0.01]]}
{"kind": "depth", "E": 1787089944675, "U": 11316022223916, "u": 11316022229469, "recv_ms": 1787089944627, "bids": [[1000.0, 35.76], [14180.5, 1.848], [14280.5, 2.352], [34000.0, 1.146], [51664.0, 0.0], [51664.4, 0.0], [58122.4, 0.004], [61351.4, 0.03], [61351.5, 2.449], [61997.2, 0.003], [63663.5, 3.54], [63934.7, 5.533], [64445.3, 2.617], [64495.3, 0.01], [64506.2, 29.981], [64506.9, 0.032], [64515.9, 0.023], [64522.3, 0.003], [64529.5, 0.003], [64534.0, 0.001], [64545.6, 1.14], [64563.7, 0.003], [64567.0, 0.403], [64567.4, 0.929]], "asks": [[64580.6, 57.646], [64596.1, 0.002], [64609.1, 0.389], [64625.3, 0.0], [64638.8, 0.003], [64647.9, 0.022], [64715.7, 2.616], [64737.4, 10.429], [64737.5, 0.001], [65226.4, 2.89]]}
{"kind": "depth", "E": 1787089944777, "U": 11316022229621, "u": 11316022235447, "recv_ms": 1787089944734, "bids": [[1000.0, 35.76], [14180.5, 2.198], [14280.5, 2.002], [58122.4, 0.004], [61997.2, 0.0], [63580.5, 0.026], [63934.7, 5.533], [64522.3, 0.0], [64530.9, 0.77], [64534.0, 0.015]], "asks": [[64625.0, 0.967], [64638.8, 0.0], [64647.0, 0.684], [65226.4, 2.89], [65395.2, 1.528], [65517.0, 40.224], [65580.6, 0.03]]}
{"kind": "depth", "E": 1787089944879, "U": 11316022235512, "u": 11316022241446, "recv_ms": 1787089944831, "bids": [[14180.5, 2.562], [14280.5, 1.638], [58122.4, 0.004], [63934.7, 5.533], [64257.6, 6.964], [64422.2, 0.001], [64439.1, 0.0], [64461.9, 0.063], [64472.4, 0.019], [64474.7, 0.0], [64499.7, 29.991], [64506.2, 0.005], [64508.5, 1.807], [64509.4, 0.005], [64510.2, 8.322], [64517.7, 0.017], [64532.8, 4.59], [64534.0, 0.001], [64548.9, 0.99]], "asks": [[64580.6, 57.644], [64580.7, 0.161], [64581.7, 0.002], [64582.0, 0.023], [64595.8, 0.017], [64596.4, 0.542], [64597.9, 0.003], [64598.3, 0.927], [64606.9, 0.955], [64623.1, 3.633], [64643.4, 0.093], [64645.7, 6.0], [64651.5, 0.0], [64657.5, 6.569], [64657.9, 0.029], [64659.8, 1.062], [64660.1, 0.013], [64664.5, 45.481], [64680.2, 0.0], [64687.8, 0.0], [64717.6, 0.028], [64720.4, 0.0], [64737.4, 0.002], [65226.4, 2.89], [65872.2, 7.654]]}
{"kind": "depth", "E": 1787089944981, "U": 11316022241560, "u": 11316022246334, "recv_ms": 1787089944932, "bids": [[1000.0, 35.76], [14180.5, 2.912], [14280.5, 1.288], [58122.4, 0.004], [61351.4, 0.03], [61997.2, 0.003], [63569.0, 0.001], [63580.5, 0.006], [63659.4, 0.0], [63862.8, 10.54], [63934.7, 5.533], [64383.4, 4.128], [64422.2, 3.143], [64422.3, 0.001], [64439.1, 2.389], [64440.1, 1.023], [64461.9, 3.934], [64472.0, 4.011], [64499.7, 0.015], [64503.0, 0.029], [64508.5, 31.918], [64509.4, 0.051], [64517.8, 0.014], [64576.1, 0.086]], "asks": [[64580.6, 57.644], [64583.4, 0.257], [64651.6, 0.36], [64657.5, 0.442], [64660.1, 41.686], [64664.5, 3.808], [64687.8, 2.323], [64717.6, 3.899], [64720.3, 0.665], [64720.4, 5.408], [64737.3, 0.001], [64737.4, 10.429], [65226.4, 2.89], [65580.6, 0.01], [67163.8, 3.185]]}
{"kind": "depth", "E": 1787089945083, "U": 11316022246543, "u": 11316022253103, "recv_ms": 1787089945035, "bids": [[1000.0, 35.76], [14180.5, 3.276], [14280.5, 0.924], [58122.4, 0.004], [61351.4, 0.03], [61997.2, 0.0], [63934.7, 5.533], [64383.4, 10.466], [64383.5, 1.617], [64422.2, 5.667], [64422.3, 0.713], [64439.1, 4.26], [64440.1, 1.528], [64477.9, 10.001], [64479.0, 2.222], [64503.0, 0.02], [64508.1, 0.041], [64516.9, 0.885], [64517.7, 4.868], [64546.0, 0.155], [64546.4, 2.471], [64568.9, 0.309]], "asks": [[64580.6, 57.649], [64609.4, 0.001], [64609.5, 0.012], [64609.6, 7.13], [64612.4, 0.001], [64612.5, 0.0], [64612.6, 0.0], [64613.3, 0.0], [64613.4, 0.093], [64613.5, 0.159], [64615.4, 0.029], [64615.5, 0.001], [64615.6, 0.001], [64643.4, 2.473], [64676.4, 2.376], [64678.2, 0.008], [64678.3, 10.005], [64679.8, 0.0], [64720.3, 1.387], [64776.1, 10.738], [65226.4, 2.89], [65484.7, 79.099]]}
{"kind": "depth", "E": 1787089945287, "U": 11316022261175, "u": 11316022266944, "recv_ms": 1787089945239, "bids": [[1000.0, 35.76], [14080.5, 0.112], [14180.5, 3.766], [14280.5, 0.322], [51664.0, 0.0], [58122.4, 0.004], [61997.2, 0.0], [63789.9, 0.013], [63934.7, 5.533], [64551.8, 0.057], [64552.3, 0.039], [64565.0, 1.195], [64565.5, 0.0], [64565.9, 0.581], [64566.5, 0.001]], "asks": [[64595.8, 0.559], [64596.4, 0.0], [64597.4, 0.932], [64598.3, 0.0], [65137.5, 0.015], [65226.4, 2.89], [65387.9, 17.93], [65388.0, 8.456], [65517.0, 40.11], [65872.2, 7.651], [65936.8, 3.486]]}
{"kind": "depth", "E": 1787089945389, "U": 11316022267173, "u": 11316022273555, "recv_ms": 1787089945341, "bids": [[1000.0, 35.76], [14080.5, 0.35], [14180.5, 3.64], [14280.5, 0.21], [51664.0, 0.0], [58122.4, 0.004], [61351.4, 0.03], [63580.5, 0.006], [63805.5, 68.646], [63934.7, 5.533], [63967.0, 27.051], [64063.9, 10.472], [64383.4, 10.798], [64422.2, 5.899], [64439.1, 4.387], [64495.3, 30.121], [64503.0, 0.029], [64508.5, 1.806], [64559.0, 0.015], [64559.4, 0.0], [64559.7, 0.116], [64560.1, 0.001], [64560.6, 0.002], [64560.8, 0.559], [64565.0, 0.268], [64565.9, 0.966], [64566.0, 0.125], [64566.5, 0.543], [64570.0, 1.552], [64570.1, 0.671], [64570.2, 0.161], [64570.3, 0.177], [64570.4, 0.001], [64570.5, 0.012], [64570.6, 0.0], [64574.6, 0.105], [64574.9, 0.002]], "asks": [[64580.6, 57.651], [64582.5, 0.021], [64582.7, 0.201], [64595.8, 0.017], [64596.4, 0.542], [64597.4, 0.005], [64598.3, 0.927], [64600.7, 0.02], [64601.1, 0.937], [64601.7, 0.004], [64602.6, 0.124], [64603.5, 0.014], [64604.0, 0.002], [64604.5, 0.131], [64776.1, 10.066], [64903.6, 0.0], [65226.4, 2.89], [65387.9, 17.671], [65472.1, 23.029], [65580.6, 0.01], [71038.7, 0.002]]}
{"kind": "depth", "E": 1787089945491, "U": 11316022273746, "u": 11316022279547, "recv_ms": 1787089945443, "bids": [[14080.5, 0.588], [14180.5, 3.528], [14280.5, 0.084], [58122.4, 0.004], [61997.2, 0.003], [63773.2, 24.802], [63805.5, 66.768], [63934.7, 5.533], [64153.4, 0.001], [64159.8, 0.0], [64257.5, 0.003], [64257.6, 6.964], [64495.3, 0.01], [64499.7, 0.015], [64503.0, 0.02], [64504.1, 30.146], [64526.5, 0.003], [64531.0, 0.001], [64535.0, 0.091], [64541.2, 0.0], [64541.4, 0.005], [64576.1, 0.002], [64580.5, 2.727]], "asks": [[64580.6, 57.651], [64638.1, 0.099], [64639.4, 0.164], [64644.6, 0.078], [64645.9, 0.0], [64737.4, 0.002], [64737.5, 7.219], [65134.3, 0.077], [65226.4, 2.89], [65417.8, 0.21], [65424.3, 0.002], [65517.0, 40.224]]}
{"kind": "depth", "E": 1787089945593, "U": 11316022279655, "u": 11316022286241, "recv_ms": 1787089945545, "bids": [[1000.0, 35.76], [14080.5, 0.854], [14180.5, 3.346], [14280.5, 0.0], [58122.4, 0.004], [61351.4, 0.03], [61997.2, 0.0], [63580.5, 0.026], [63760.9, 0.785], [63805.5, 67.549], [63934.7, 5.533], [64038.0, 100.109], [64063.9, 10.784], [64439.1, 0.0]], "asks": [[64580.6, 57.675], [64720.4, 0.0], [65226.4, 2.89], [65580.6, 0.03], [66769.6, 0.0]]}
{"kind": "depth", "E": 1787089945695, "U": 11316022286441, "u": 11316022292865, "recv_ms": 1787089945646, "bids": [[1000.0, 35.76], [14080.5, 1.218], [14180.5, 2.982], [51664.4, 0.0], [58122.4, 0.004], [61351.4, 0.03], [61997.2, 0.003], [63934.7, 5.533], [64038.0, 100.164], [64366.5, 2.616], [64439.1, 4.438], [64440.1, 1.023], [64559.0, 0.131], [64559.7, 0.0], [64560.1, 0.559], [64560.8, 0.001], [64563.7, 0.003], [64565.1, 0.944], [64565.9, 0.039], [64566.0, 0.667], [64566.5, 0.001], [64579.7, 0.008], [64579.9, 0.031], [64580.5, 2.718]], "asks": [[64580.6, 57.675], [64584.9, 0.001], [64587.0, 0.627], [64589.6, 0.6], [64595.8, 0.559], [64596.1, 0.002], [64596.4, 0.0], [64597.5, 1.996], [64598.3, 0.0], [64720.3, 0.665], [64720.4, 5.408], [64737.3, 10.428], [64737.5, 0.001], [64794.5, 2.617], [65226.4, 2.89], [65484.7, 81.387]]}
{"kind": "depth", "E": 1787089945797, "U": 11316022293077, "u": 11316022298246, "recv_ms": 1787089945752, "bids": [[14080.5, 1.568], [14180.5, 2.632], [51664.0, 0.0], [58122.4, 0.004], [61351.4, 0.03], [61997.2, 0.0], [63547.2, 8.773], [63580.5, 0.006], [63638.7, 0.135], [63669.1, 3.92], [63676.4, 63.794], [63773.2, 25.585], [63805.5, 69.427], [63934.7, 5.533], [64257.6, 6.964], [64565.1, 0.017], [64566.0, 1.594], [64575.3, 0.157]], "asks": [[64580.6, 57.675], [64595.8, 0.017], [64596.4, 0.542], [64597.5, 1.069], [64598.4, 1.587], [65226.4, 2.89], [65580.6, 0.01]]}
{"kind": "depth", "E": 1787089946103, "U": 11316022311253, "u": 11316022317707, "recv_ms": 1787089946056, "bids": [[14080.5, 2.646], [14180.5, 1.554], [51664.0, 0.0], [58122.4, 0.004], [61997.2, 0.0], [62431.1, 0.0], [63862.9, 2.314], [63934.7, 5.533], [64257.6, 6.964], [64383.4, 9.186], [64422.2, 4.424], [64422.3, 1.034], [64439.1, 3.614], [64469.2, 12.596], [64470.2, 6.127], [64504.8, 5.565], [64517.7, 4.902], [64536.6, 0.001], [64568.9, 0.309]], "asks": [[64580.6, 57.684], [64643.4, 2.478], [64659.8, 7.611], [64691.8, 2.319], [64691.9, 11.73], [64720.3, 1.387], [64776.1, 10.737], [65226.4, 2.89]]}
{"kind": "depth", "E": 1787089946205, "U": 11316022317905, "u": 11316022326883, "recv_ms": 1787089946156, "bids": [[1000.0, 35.76], [14080.5, 2.996], [14180.5, 1.204], [51664.0, 0.0], [58122.4, 0.004], [61997.2, 0.003], [63288.9, 4.273], [63418.1, 5.622], [63580.5, 0.006], [63620.1, 0.0], [63682.8, 23.785], [63773.2, 28.168], [63934.7, 5.533], [64501.1, 3.579], [64508.3, 0.107], [64528.5, 0.015], [64531.4, 0.001], [64567.8, 0.002], [64569.6, 0.012]], "asks": [[64584.9, 0.002], [65226.4, 2.89], [65342.9, 14.228], [65580.6, 0.01]]}
{"kind": "depth", "E": 1787089946307, "U": 11316022326918, "u": 11316022333159, "recv_ms": 1787089946259, "bids": [[1000.0, 35.76], [14080.5, 3.36], [14180.5, 0.84], [51664.0, 0.0], [58122.4, 0.004], [61351.4, 0.031], [63580.5, 0.026], [63934.7, 5.533], [64063.9, 10.784], [64257.6, 6.964], [64259.3, 0.108], [64327.1, 2.654], [64383.4, 4.259], [64422.2, 3.199], [64439.1, 2.421], [64517.7, 0.017], [64575.6, 0.032]], "asks": [[64580.6, 57.684], [64602.2, 2.23], [64643.4, 0.093], [64720.4, 5.408], [64737.3, 10.428], [64833.9, 2.617], [64911.0, 0.308], [65226.4, 2.89], [65556.6, 2.286], [65580.6, 0.03]]}
{"kind": "depth", "E": 1787089946409, "U": 11316022333254, "u": 11316022338440, "recv_ms": 1787089946362, "bids": [[14080.5, 3.682], [14180.5, 0.504], [14480.5, 0.014], [58122.4, 0.004], [61351.4, 0.03], [61351.5, 2.447], [61351.6, 0.012], [61997.2, 0.0], [63288.9, 4.115], [63934.7, 5.533], [64257.5, 0.001], [64422.3, 0.713], [64528.8, 0.046], [64545.9, 2.322], [64546.3, 10.003]], "asks": [[64602.3, 1.271], [64603.0, 10.002], [65226.4, 2.89], [65355.8, 1.676], [65460.6, 0.0], [65484.7, 81.57]]}
{"kind": "depth", "E": 1787089946511, "U": 11316022338596, "u": 11316022344369, "recv_ms": 1787089946462, "bids": [[1000.0, 35.76], [14080.5, 3.738], [14180.5, 0.294], [14480.5, 0.168], [58122.4, 0.004], [61997.2, 0.003], [63631.2, 23.682], [63862.7, 1.564], [63934.7, 5.533], [64383.4, 10.766], [64422.2, 5.889], [64439.1, 4.54], [64495.3, 30.257], [64499.7, 0.015], [64504.1, 0.035], [64504.8, 1.191], [64508.5, 1.806], [64517.7, 4.902], [64533.4, 0.137], [64541.4, 0.001], [64551.8, 0.0], [64553.3, 0.057], [64559.0, 0.015], [64559.7, 0.116], [64560.1, 0.001], [64560.6, 0.002], [64561.7, 0.56], [64566.0, 1.052], [64567.5, 0.571], [64571.9, 0.086], [64575.0, 0.19], [64576.2, 0.346]], "asks": [[64596.4, 0.0], [64597.4, 0.547], [64598.4, 0.66], [64599.1, 1.287], [64601.1, 0.38], [64601.9, 0.558], [64602.6, 0.008], [64603.3, 0.132], [64604.5, 0.074], [64605.2, 0.22], [64643.4, 2.465], [64776.1, 9.903], [64903.6, 0.002], [65226.4, 2.89]]}
{"kind": "depth", "E": 1787089946613, "U": 11316022344486, "u": 11316022350183, "recv_ms": 1787089946565, "bids": [[1000.0, 35.76], [14080.5, 3.612], [14180.5, 0.182], [14480.5, 0.406], [58122.4, 0.004], [61997.2, 0.0], [63580.5, 0.006], [63817.8, 0.006], [63934.7, 5.533], [64257.6, 6.352], [64495.3, 0.01], [64501.9, 0.001], [64504.1, 30.282], [64552.5, 0.138], [64553.3, 0.0], [64560.8, 0.559], [64561.7, 0.002], [64566.5, 0.543], [64567.5, 0.029], [64570.1, 0.594], [64570.3, 0.497], [64570.4, 0.078], [64571.1, 0.001]], "asks": [[64595.8, 0.636], [64595.9, 1.452], [64596.4, 0.542], [64597.4, 0.005], [64597.5, 0.45], [64598.3, 0.927], [64599.1, 0.36], [64604.2, 0.066], [64605.2, 0.163], [65226.4, 2.89], [65468.3, 5.658], [65471.0, 1.917], [65580.6, 0.01]]}
{"kind": "depth", "E": 1787089946715, "U": 11316022350320, "u": 11316022356520, "recv_ms": 1787089946667, "bids": [[14080.5, 3.5], [14180.5, 0.056], [14480.5, 0.644], [51664.4, 0.0], [58122.4, 0.004], [61351.4, 0.03], [61997.2, 0.003], [63669.9, 7.403], [63934.7, 5.533], [64257.6, 6.974], [64439.1, 0.0], [64522.3, 0.003], [64533.4, 0.133], [64541.6, 0.007], [64563.7, 0.003], [64580.5, 2.72]], "asks": [[64584.9, 0.001], [64596.1, 0.002], [64612.8, 1.115], [64720.3, 0.665], [64720.4, 0.0], [65226.4, 2.89], [65484.7, 81.113], [71038.7, 0.002]]}
{"kind": "depth", "E": 1787089946817, "U": 11316022356626, "u": 11316022362309, "recv_ms": 1787089946769, "bids": [[1000.0, 35.76], [14080.5, 3.262], [14180.5, 0.0], [14480.5, 0.938], [58122.4, 0.004], [61351.6, 0.01], [63580.5, 0.026], [63708.7, 17.727], [63864.7, 0.472], [63934.7, 5.533], [64439.1, 3.86], [64528.8, 0.092], [64561.9, 0.001], [64563.2, 0.049], [64576.7, 0.013], [64578.1, 0.001]], "asks": [[64580.6, 57.7], [64720.4, 5.408], [65226.4, 2.89], [65278.4, 3.119], [65349.1, 7.336], [65452.4, 19.167], [65478.3, 23.077], [65580.6, 0.03], [65601.2, 0.002], [65678.6, 0.0]]}
{"kind": "depth", "E": 1787089946919, "U": 11316022362348, "u": 11316022367809, "recv_ms": 1787089946871, "bids": [[14080.5, 2.898], [14480.5, 1.302], [58122.4, 0.004], [61997.2, 0.0], [63708.7, 18.072], [63824.9, 7.153], [63934.7, 5.533], [64257.6, 6.964], [64561.9, 0.009], [64563.2, 0.041]], "asks": [[65226.4, 2.89], [65387.9, 17.899], [65395.1, 3.825], [65452.4, 19.776], [65492.5, 0.762]]}
{"kind": "depth", "E": 1787089947021, "U": 11316022367988, "u": 11316022373420, "recv_ms": 1787089946973, "bids": [[14080.5, 2.548], [14480.5, 1.652], [58122.4, 0.004], [61351.4, 0.031], [61997.2, 0.003], [63580.5, 0.006], [63664.0, 10.176], [63798.2, 4.698], [63934.7, 5.533], [64383.5, 1.662], [64422.3, 1.032], [64440.1, 1.469], [64516.9, 0.0], [64517.8, 1.731], [64533.4, 0.137], [64541.6, 0.003], [64567.4, 0.31], [64574.3, 0.17], [64580.5, 2.719]], "asks": [[64580.6, 57.316], [64598.4, 0.041], [64605.4, 1.919], [64605.8, 0.065], [64612.7, 0.659], [64720.3, 1.387], [65226.4, 2.89], [65387.9, 18.387], [65484.7, 81.57], [65580.6, 0.01]]}
{"kind": "depth", "E": 1787089947123, "U": 11316022373470, "u": 11316022380229, "recv_ms": 1787089947074, "bids": [[1000.0, 35.76], [14080.5, 2.184], [14480.5, 2.016], [58122.4, 0.004], [61351.4, 0.03], [61997.2, 0.0], [62965.4, 2.777], [63288.9, 4.118], [63482.6, 16.562], [63708.7, 17.446], [63934.7, 5.533], [64383.4, 10.365], [64383.5, 0.791], [64422.1, 5.545], [64422.2, 0.001], [64422.3, 0.713], [64439.1, 4.343], [64461.9, 3.934], [64470.9, 2.323], [64472.0, 1.688], [64494.5, 0.0], [64495.3, 0.01], [64495.4, 6.718], [64500.7, 0.02], [64501.9, 30.349], [64503.0, 0.029], [64504.1, 0.035], [64508.3, 0.108], [64509.4, 0.051], [64531.3, 6.073], [64549.5, 1.59], [64568.9, 0.309], [64575.2, 0.085], [64576.3, 0.313]], "asks": [[64580.6, 57.3], [64585.5, 0.003], [64604.2, 0.009], [64605.2, 0.22], [64651.6, 0.36], [64687.8, 2.323], [64690.6, 0.0], [64717.6, 3.899], [64776.1, 10.82], [65226.4, 2.89], [65349.1, 8.253], [65472.1, 20.741]]}
{"kind": "depth", "E": 1787089947225, "U": 11316022380411, "u": 11316022386064, "recv_ms": 1787089947177, "bids": [[14080.5, 1.82], [14480.5, 2.38], [58122.4, 0.004], [61351.4, 0.03], [61351.5, 2.445], [61351.6, 0.012], [61997.2, 0.003], [63580.5, 0.026], [63596.5, 0.002], [63708.7, 18.072], [63934.7, 5.533], [64257.6, 6.964], [64493.9, 0.0], [64495.4, 0.003], [64528.5, 0.016], [64533.4, 0.133], [64542.9, 0.318], [64560.0, 3.408]], "asks": [[64580.6, 57.689], [64583.9, 0.001], [64612.7, 0.04], [64617.3, 0.015], [64621.2, 0.237], [64850.0, 25.686], [65226.4, 2.89], [65580.6, 0.03]]}
{"kind": "depth", "E": 1787089947327, "U": 11316022386149, "u": 11316022391623, "recv_ms": 1787089947281, "bids": [[14080.5, 1.47], [14480.5, 2.73], [58122.4, 0.004], [61351.4, 0.03], [61351.6, 0.01], [63482.6, 16.877], [63790.1, 0.0], [63934.7, 5.533], [64501.9, 0.001], [64503.0, 0.02], [64504.1, 30.383], [64522.3, 0.003], [64575.8, 0.121]], "asks": [[64580.6, 57.714], [64583.9, 0.011], [64612.9, 0.021], [65226.4, 2.89], [65484.7, 83.857], [65522.6, 1.832], [71038.7, 0.002]]}
{"kind": "depth", "E": 1787089947429, "U": 11316022391764, "u": 11316022396636, "recv_ms": 1787089947380, "bids": [[1000.0, 35.76], [14080.5, 1.106], [14480.5, 3.094], [58122.4, 0.004], [61997.2, 0.0], [62966.0, 4.186], [63579.5, 30.47], [63580.5, 0.006], [63611.8, 14.931], [63644.1, 40.054], [63708.7, 17.446], [63934.7, 5.533], [64561.9, 0.001], [64563.2, 0.049], [64574.6, 0.102], [64574.9, 0.005], [64576.7, 0.005], [64578.1, 0.009]], "asks": [[64583.9, 0.001], [64590.5, 0.08], [64591.1, 0.55], [64595.8, 0.017], [64597.4, 0.624], [64776.1, 11.161], [65226.4, 2.89], [65529.9, 20.862], [65580.6, 0.01]]}
{"kind": "depth", "E": 1787089947531, "U": 11316022396693, "u": 11316022401257, "recv_ms": 1787089947482, "bids": [[14080.5, 0.756], [14480.5, 3.444], [58122.4, 0.004], [61997.2, 0.003], [63276.6, 1.578], [63288.9, 4.115], [63934.7, 5.533], [64257.6, 6.974]], "asks": [[64633.8, 0.001], [64640.4, 2.579], [64903.6, 0.0], [65226.4, 2.89], [65872.2, 7.648]]}
{"kind": "depth", "E": 1787089947633, "U": 11316022401403, "u": 11316022406945, "recv_ms": 1787089947587, "bids": [[14080.5, 0.434], [14380.5, 0.042], [14480.5, 3.724], [51664.0, 0.0], [58122.4, 0.004], [61351.4, 0.031], [61997.2, 0.0], [63580.5, 0.026], [63611.8, 15.323], [63644.1, 41.153], [63773.2, 27.903], [63934.7, 5.533], [64257.5, 0.003], [64552.5, 0.081], [64552.7, 0.06], [64553.6, 0.016], [64559.7, 0.116], [64560.8, 0.559], [64566.0, 1.052], [64566.9, 0.462], [64576.7, 0.013], [64578.1, 0.001]], "asks": [[64580.6, 57.714], [64583.9, 0.011], [64596.4, 0.542], [64597.3, 0.101], [64598.3, 0.0], [64598.4, 0.968], [64599.3, 0.241], [64609.4, 0.001], [64609.5, 0.012], [64609.6, 7.13], [64612.4, 0.001], [64612.5, 0.0], [64612.6, 0.0], [64613.3, 0.0], [64613.4, 0.093], [64613.5, 0.159], [64615.4, 0.029], [64615.5, 0.001], [64615.6, 0.001], [64776.1, 11.302], [65226.4, 2.89], [65277.3, 0.156], [65580.6, 0.03]]}
{"kind": "depth", "E": 1787089947735, "U": 11316022406997, "u": 11316022411526, "recv_ms": 1787089947694, "bids": [[1000.0, 35.76], [14080.5, 0.266], [14380.5, 0.224], [14480.5, 3.71], [51664.4, 0.0], [58122.4, 0.004], [61351.4, 0.03], [63579.5, 31.57], [63611.8, 15.025], [63708.7, 18.072], [63760.0, 1.739], [63934.7, 5.533], [64495.3, 0.01], [64501.9, 30.349], [64503.0, 0.029], [64504.1, 0.035], [64563.7, 0.003]], "asks": [[64596.1, 0.002], [65226.4, 2.89], [65387.9, 18.54]]}
{"kind": "depth", "E": 1787089947939, "U": 11316022416341, "u": 11316022421001, "recv_ms": 1787089947892, "bids": [[14080.5, 0.028], [14380.5, 0.7], [14480.5, 3.472], [58122.4, 0.004], [61351.5, 2.445], [61351.6, 0.012], [61997.2, 0.0], [63934.7, 5.533]], "asks": [[64583.9, 0.011], [64776.1, 11.171], [65226.4, 2.89], [65284.5, 17.871], [65387.9, 18.281]]}
{"kind": "depth", "E": 1787089948041, "U": 11316022421080, "u": 11316022428006, "recv_ms": 1787089947993, "bids": [[1000.0, 35.76], [14080.5, 0.0], [14380.5, 1.022], [14480.5, 3.178], [58122.4, 0.004], [61351.4, 0.03], [61997.2, 0.003], [63288.9, 4.273], [63773.2, 28.02], [63934.7, 5.533], [64383.4, 10.631], [64383.5, 1.641], [64409.1, 1.214], [64422.1, 5.007], [64439.1, 4.08], [64495.3, 30.471], [64504.1, 0.035], [64508.4, 0.004], [64517.7, 4.964], [64517.8, 1.74], [64568.9, 0.314], [64580.5, 2.723]], "asks": [[64580.6, 57.715], [64583.9, 0.001], [64585.5, 0.002], [64643.4, 2.478], [64737.2, 2.505], [64776.1, 11.341], [64781.0, 15.521], [65226.4, 2.89], [65387.9, 18.022], [65872.2, 7.651]]}
{"kind": "depth", "E": 1787089948143, "U": 11316022428163, "u": 11316022434483, "recv_ms": 1787089948094, "bids": [[14380.5, 1.386], [14480.5, 2.814], [58122.4, 0.004], [61351.4, 0.03], [61997.2, 0.0], [63580.5, 0.026], [63599.5, 5.543], [63664.1, 0.0], [63665.3, 0.188], [63934.7, 5.533], [64257.6, 6.974], [64494.4, 3.197], [64495.3, 0.01], [64500.7, 0.018], [64501.1, 3.58], [64501.9, 30.462], [64503.0, 0.029], [64504.0, 1.105], [64508.3, 0.106], [64528.5, 0.014], [64531.3, 6.072], [64531.4, 0.0], [64536.4, 0.072], [64536.6, 0.0], [64560.2, 1.247], [64562.0, 0.319], [64563.2, 0.041], [64567.6, 0.783], [64568.9, 0.309]], "asks": [[64580.6, 57.717], [64584.9, 0.002], [64598.6, 0.621], [64606.0, 0.629], [65226.4, 2.89], [65362.9, 5.348], [65495.9, 0.002], [65497.1, 0.004], [65561.7, 0.021], [65580.6, 0.03]]}
{"kind": "depth", "E": 1787089948245, "U": 11316022434548, "u": 11316022440441, "recv_ms": 1787089948196, "bids": [[1000.0, 35.76], [14380.5, 1.736], [14480.5, 2.464], [58122.4, 0.004], [63599.5, 5.551], [63664.1, 0.008], [63665.3, 0.196], [63854.7, 1.564], [63934.7, 5.533], [64439.1, 4.331], [64470.8, 2.329], [64470.9, 0.0], [64501.1, 3.581], [64501.9, 0.001], [64503.0, 0.02], [64504.0, 31.566], [64508.2, 0.006], [64528.4, 0.019]], "asks": [[64687.8, 2.323], [64720.4, 5.408], [64776.1, 11.002], [64781.0, 5.892], [65226.4, 2.89], [65387.9, 17.793], [65495.9, 0.01], [65497.1, 0.012], [65561.7, 0.029], [71038.7, 0.002]]}
{"kind": "depth", "E": 1787089948347, "U": 11316022440450, "u": 11316022446211, "recv_ms": 1787089948298, "bids": [[1000.0, 35.76], [14380.5, 2.1], [14480.5, 2.1], [51664.0, 0.0], [58122.4, 0.004], [61351.4, 0.03], [61997.2, 0.003], [63580.5, 0.006], [63934.7, 5.533], [64439.1, 0.0], [64440.1, 1.023], [64574.7, 0.074], [64574.9, 0.002]], "asks": [[64580.6, 57.716], [64720.3, 0.665], [64720.4, 0.0], [65226.4, 2.89], [65580.6, 0.01], [65872.2, 7.654]]}
{"kind": "depth", "E": 1787089948449, "U": 11316022446542, "u": 11316022454075, "recv_ms": 1787089948400, "bids": [[14380.5, 2.45], [14480.5, 1.75], [51664.0, 0.0], [58122.4, 0.004], [61351.4, 0.03], [61997.2, 0.0], [61997.3, 1.382], [62448.8, 1.601], [63676.4, 63.324], [63741.0, 21.503], [63934.7, 5.533], [64257.6, 6.964], [64383.4, 5.573], [64422.1, 2.912], [64439.1, 2.954], [64440.1, 1.539], [64515.9, 0.022], [64567.6, 0.164]], "asks": [[64580.6, 57.33], [64598.6, 0.002], [64606.0, 0.01], [64622.7, 0.025], [64630.3, 0.001], [64645.2, 0.362], [64720.4, 5.408], [64737.3, 10.428], [64776.1, 15.44], [65226.4, 2.89], [65226.5, 0.004], [65549.5, 0.0], [66776.9, 1.346]]}
{"kind": "depth", "E": 1787089948551, "U": 11316022454205, "u": 11316022459693, "recv_ms": 1787089948502, "bids": [[1000.0, 35.76], [14380.5, 2.814], [14480.5, 1.386], [58122.4, 0.004], [61997.2, 0.003], [63580.5, 0.026], [63934.7, 5.533], [64383.4, 10.365], [64383.5, 0.791], [64386.6, 0.0], [64418.9, 0.014], [64422.1, 5.546], [64439.1, 4.358], [64503.0, 0.023]], "asks": [[64580.6, 57.356], [64638.8, 0.003], [64742.0, 0.0], [64776.1, 10.805], [65226.4, 2.89], [65580.6, 0.03], [65613.9, 17.168], [65685.7, 4.568]]}
{"kind": "depth", "E": 1787089948653, "U": 11316022459867, "u": 11316022465614, "recv_ms": 1787089948606, "bids": [[1000.0, 35.76], [14380.5, 3.178], [14480.5, 1.022], [58122.4, 0.004], [61351.4, 0.03], [61997.2, 0.0], [63934.7, 5.533], [64038.0, 100.191], [64257.5, 0.001], [64439.1, 0.0], [64440.1, 1.023], [64470.7, 0.007], [64503.0, 0.02], [64521.9, 0.002], [64522.2, 0.0], [64522.3, 0.0], [64522.5, 0.032], [64522.9, 0.0], [64523.2, 1.105], [64534.0, 0.015], [64536.1, 0.006], [64539.6, 0.002], [64539.9, 0.001], [64540.2, 0.034], [64540.6, 0.0], [64540.9, 1.256], [64542.9, 0.314], [64554.5, 0.312], [64554.6, 1.255], [64554.7, 0.047], [64554.8, 0.003], [64555.0, 0.003], [64555.1, 0.0], [64555.2, 1.111], [64555.3, 0.0], [64555.4, 0.001], [64556.5, 0.004], [64556.9, 0.002], [64570.4, 0.086], [64573.7, 0.085], [64573.8, 0.062], [64573.9, 0.003], [64574.0, 0.019], [64574.1, 0.187], [64574.2, 0.01], [64574.3, 0.0], [64574.4, 0.003], [64574.5, 0.084], [64574.6, 0.002], [64574.7, 0.004], [64575.0, 0.158], [64575.3, 0.125], [64575.6, 0.0], [64575.9, 1.034], [64576.2, 0.314], [64576.7, 0.005]], "asks": [[64580.6, 57.356], [64586.8, 0.003], [64587.1, 0.003], [64587.4, 0.001], [64587.5, 0.015], [64587.8, 0.0], [64588.1, 0.02], [64588.4, 0.001], [64588.5, 0.011], [64588.6, 0.014], [64588.7, 0.011], [64588.8, 1.067], [64588.9, 0.272], [64589.0, 0.002], [64589.1, 0.001], [64589.2, 0.009], [64589.3, 0.08], [64589.4, 0.059], [64604.5, 0.0], [64604.8, 0.014], [64605.1, 0.311], [64605.4, 1.845], [64605.8, 0.001], [64606.2, 0.002], [64606.6, 0.001], [64607.6, 0.172], [64607.8, 0.002], [64607.9, 0.004], [64608.0, 0.459], [64608.1, 0.061], [64608.2, 0.27], [64608.3, 0.017], [64608.4, 1.239], [64608.5, 0.105], [64608.6, 0.013], [64612.9, 0.021], [64622.2, 0.041], [64622.5, 0.002], [64622.8, 0.0], [64623.1, 3.559], [64623.5, 0.179], [64638.8, 0.0], [64720.4, 0.0], [65226.4, 2.89], [65291.0, 12.655], [71038.7, 0.004]]}
{"kind": "depth", "E": 1787089948755, "U": 11316022465669, "u": 11316022471449, "recv_ms": 1787089948707, "bids": [[14380.5, 3.528], [14480.5, 0.672], [51664.4, 0.0], [58122.4, 0.004], [63805.5, 68.176], [63934.7, 5.533], [64257.6, 6.974], [64422.1, 5.428], [64422.3, 0.001], [64439.1, 4.289], [64495.3, 0.01], [64503.0, 0.02], [64504.0, 1.105], [64504.1, 30.496], [64508.4, 0.004], [64534.0, 0.001], [64539.5, 0.033], [64552.7, 0.003], [64553.9, 0.057], [64556.8, 0.007], [64559.7, 0.0], [64560.2, 0.628], [64560.8, 0.001], [64561.1, 1.611], [64562.0, 0.311], [64562.1, 0.562], [64563.2, 0.049], [64563.5, 0.061], [64563.7, 0.003], [64566.0, 0.125], [64566.5, 0.001], [64567.1, 1.007], [64567.2, 0.544], [64570.0, 0.004], [64570.1, 0.052], [64570.3, 0.474], [64570.4, 1.728], [64570.5, 1.56], [64572.7, 1.441], [64572.9, 2.252], [64573.0, 0.105], [64573.8, 0.132], [64573.9, 0.073], [64574.4, 0.103], [64574.6, 0.072], [64574.9, 0.034], [64576.7, 0.005], [64578.1, 0.009], [64579.2, 1.544]], "asks": [[64580.6, 57.744], [64588.1, 0.084], [64588.3, 2.186], [64588.6, 0.294], [64589.1, 0.155], [64589.2, 0.001], [64589.3, 0.235], [64596.1, 0.002], [64596.4, 0.0], [64597.3, 0.643], [64598.4, 0.041], [64599.5, 2.898], [64601.9, 0.001], [64602.5, 0.56], [64603.3, 0.016], [64603.8, 0.187], [64604.1, 0.0], [64604.9, 0.007], [64605.8, 0.065], [64607.6, 0.333], [64607.8, 0.282], [64608.3, 0.171], [64608.5, 0.252], [64623.4, 0.064], [64720.5, 4.515], [64737.2, 0.249], [64737.3, 0.001], [64737.5, 7.31], [64903.6, 0.002], [65225.8, 0.0], [65226.4, 2.89], [65427.9, 4.578], [65491.8, 1.525], [71038.7, 0.002]]}
{"kind": "depth", "E": 1787089948857, "U": 11316022471503, "u": 11316022480047, "recv_ms": 1787089948812, "bids": [[1000.0, 35.76], [14280.5, 0.07], [14380.5, 3.752], [14480.5, 0.378], [51664.0, 0.0], [58122.4, 0.004], [61351.4, 0.03], [61997.2, 0.003], [63288.9, 4.273], [63580.5, 0.006], [63676.4, 65.677], [63805.5, 69.427], [63934.7, 5.533], [64481.0, 0.031], [64481.1, 10.666], [64522.3, 0.003], [64536.1, 0.002], [64536.5, 0.685], [64539.9, 0.033], [64540.2, 0.066], [64540.6, 0.032], [64540.9, 1.288], [64542.9, 0.318], [64546.3, 0.003], [64546.4, 0.978], [64549.5, 1.576], [64550.1, 2.0], [64557.5, 0.041], [64561.7, 0.002], [64563.2, 0.049], [64563.3, 0.23], [64563.6, 0.001], [64563.9, 0.012], [64564.9, 0.008], [64565.4, 0.037], [64565.9, 0.673], [64566.1, 0.0], [64566.7, 0.001], [64568.0, 0.006], [64570.4, 0.001], [64570.5, 0.012], [64571.9, 0.002], [64572.7, 0.929], [64572.9, 1.61], [64573.0, 0.097], [64573.1, 0.002], [64573.4, 0.311], [64574.3, 0.07], [64574.7, 0.001], [64575.1, 0.003], [64575.2, 0.088], [64575.3, 0.157], [64575.6, 0.032], [64575.9, 1.069], [64576.2, 0.398], [64576.3, 0.345], [64576.7, 1.561], [64578.1, 0.009], [64580.5, 3.537]], "asks": [[64580.6, 57.22], [64581.2, 0.007], [64582.1, 0.084], [64582.4, 0.004], [64583.4, 0.198], [64584.1, 0.312], [64584.9, 0.001], [64586.8, 0.076], [64587.1, 0.077], [64587.4, 0.085], [64587.5, 0.015], [64587.7, 2.705], [64588.7, 0.137], [64589.3, 0.227], [64589.5, 0.172], [64599.5, 2.331], [64600.3, 0.01], [64604.4, 0.186], [64604.8, 0.088], [64605.1, 0.394], [64605.4, 1.919], [64607.9, 0.13], [64622.1, 0.088], [64622.4, 1.165], [64622.8, 0.083], [64623.1, 3.633], [64624.6, 0.079], [64638.8, 0.003], [64640.1, 0.009], [64657.5, 6.613], [64657.9, 42.01], [64659.8, 1.062], [64660.1, 0.013], [64737.3, 10.428], [64737.5, 0.001], [64771.6, 0.001], [64771.7, 0.004], [65226.4, 2.892], [65580.6, 0.01], [65872.2, 7.651]]}
{"kind": "depth", "E": 1787089948959, "U": 11316022480085, "u": 11316022485162, "recv_ms": 1787089948911, "bids": [[1000.0, 35.76], [14280.5, 0.28], [14380.5, 3.682], [14480.5, 0.238], [58122.4, 0.004], [61997.2, 0.0], [63604.7, 3.093], [63934.7, 5.533], [64038.0, 100.154], [64504.1, 0.035], [64508.5, 32.273], [64521.0, 0.373], [64553.2, 0.058], [64553.9, 0.0], [64560.4, 0.613], [64561.1, 1.495], [64566.5, 0.928], [64566.6, 0.218], [64567.0, 0.396], [64567.1, 0.08], [64567.2, 0.002], [64567.3, 0.004], [64567.4, 0.852], [64568.2, 0.312], [64568.5, 0.003], [64573.7, 0.155], [64574.0, 0.089], [64574.1, 0.287], [64574.3, 0.17], [64574.4, 0.203], [64574.5, 0.154], [64576.8, 0.01], [64578.0, 0.033], [64578.1, 0.0], [64579.3, 1.122], [64580.3, 0.002]], "asks": [[64581.2, 0.0], [64581.6, 0.099], [64587.7, 2.396], [64588.2, 0.624], [64588.5, 0.158], [64588.6, 0.544], [64588.8, 1.287], [64588.9, 0.542], [64589.0, 0.142], [64589.3, 0.374], [64589.5, 0.164], [64590.1, 0.182], [64590.5, 0.003], [64591.1, 0.0], [64591.7, 0.015], [64591.9, 0.619], [64592.5, 0.003], [64593.1, 0.008], [64594.6, 0.017], [64594.9, 0.189], [64597.3, 0.101], [64597.7, 0.544], [64598.9, 0.943], [64599.5, 1.404], [64599.9, 0.005], [64605.2, 0.163], [64605.9, 2.382], [64606.6, 0.271], [64607.7, 0.171], [64607.9, 0.38], [64608.0, 0.679], [64608.2, 0.41], [64608.5, 0.399], [64657.5, 0.442], [64657.9, 0.029], [64664.5, 45.789], [64690.6, 0.1], [65226.4, 3.043], [65387.9, 17.534]]}
{"kind": "depth", "E": 1787089949163, "U": 11316022491971, "u": 11316022497377, "recv_ms": 1787089949116, "bids": [[1000.0, 35.76], [14280.5, 0.756], [14380.5, 3.444], [14480.5, 0.0], [51664.0, 0.0], [58122.4, 0.004], [61351.4, 0.03], [61351.6, 0.01], [63708.7, 17.289], [63934.7, 5.533], [64450.5, 0.005], [64501.0, 4.912], [64501.1, 3.578], [64508.3, 0.107], [64522.2, 0.032], [64522.5, 0.064], [64522.9, 0.032], [64523.2, 1.137], [64528.3, 0.006], [64528.4, 0.018], [64531.3, 6.073], [64536.5, 0.686], [64547.6, 0.021], [64547.7, 0.006], [64547.8, 0.003], [64551.1, 0.002], [64551.2, 0.005], [64551.3, 2.322], [64554.6, 1.325], [64554.7, 0.117], [64555.2, 1.211], [64555.4, 0.071], [64560.2, 1.247], [64560.3, 7.319], [64563.9, 0.004], [64564.0, 0.038], [64564.3, 0.001], [64564.6, 0.002], [64565.7, 0.005], [64565.9, 0.797], [64566.0, 0.125], [64566.6, 0.218], [64566.7, 0.001], [64566.8, 0.544], [64567.6, 0.783], [64567.7, 0.011], [64569.0, 0.868], [64570.0, 0.004], [64570.1, 0.057], [64578.0, 0.013], [64579.9, 0.003], [64580.5, 3.578]], "asks": [[64580.6, 57.22], [64586.4, 0.003], [64587.5, 0.023], [64590.3, 0.003], [64590.5, 0.011], [64591.1, 0.542], [64591.7, 0.007], [64591.9, 0.077], [64597.9, 0.001], [64598.4, 0.043], [64598.6, 0.621], [64602.2, 0.826], [64602.6, 0.004], [64603.0, 0.002], [64606.0, 0.629], [64624.6, 0.065], [64627.1, 0.016], [64657.9, 42.01], [64660.1, 0.013], [64776.1, 10.465], [65226.4, 3.043], [65492.7, 0.001]]}
{"kind": "depth", "E": 1787089949265, "U": 11316022497492, "u": 11316022501841, "recv_ms": 1787089949216, "bids": [[1000.0, 35.76], [14280.5, 1.106], [14380.5, 3.094], [51664.0, 0.0], [58122.4, 0.002], [61997.2, 0.0], [63580.5, 0.006], [63934.7, 5.533], [64038.0, 100.117], [64495.3, 0.01], [64504.1, 30.502], [64508.4, 0.004], [64508.5, 1.806], [64508.7, 2.439], [64555.1, 0.07], [64558.4, 1.794], [64558.5, 0.768], [64572.2, 0.002], [64576.6, 1.813], [64578.0, 0.011]], "asks": [[64591.1, 0.0], [64591.7, 0.549], [65000.0, 116.809], [65097.2, 10.0], [65194.1, 26.469], [65226.4, 3.043], [65580.6, 0.01]]}
{"kind": "depth", "E": 1787089949367, "U": 11316022501846, "u": 11316022507733, "recv_ms": 1787089949319, "bids": [[14280.5, 1.47], [14380.5, 2.73], [58122.4, 0.004], [61351.4, 0.03], [61997.2, 0.003], [63482.6, 17.506], [63708.7, 18.072], [63773.2, 28.285], [63934.7, 5.533], [64038.0, 100.052], [64257.6, 6.974], [64450.5, 0.01], [64554.5, 0.382], [64554.8, 0.073], [64555.1, 0.17], [64555.2, 1.311], [64555.3, 0.07], [64556.5, 0.104], [64561.4, 0.561], [64562.1, 0.004], [64564.5, 0.009], [64564.9, 0.001], [64570.1, 0.052], [64580.4, 0.038], [64580.5, 3.579]], "asks": [[64580.6, 57.219], [64590.5, 0.003], [64591.1, 0.085], [64591.9, 0.0], [64597.4, 0.005], [64598.3, 0.619], [64604.9, 3.079], [64605.0, 10.06], [64605.4, 0.894], [64624.6, 0.023], [64627.1, 0.002], [64657.9, 0.029], [64660.1, 41.994], [64664.5, 3.808], [65226.4, 3.043]]}
{"kind": "depth", "E": 1787089949469, "U": 11316022507993, "u": 11316022513074, "recv_ms": 1787089949421, "bids": [[1000.0, 35.76], [14280.5, 1.834], [14380.5, 2.366], [58122.4, 0.004], [61351.6, 0.008], [61997.2, 0.0], [61997.3, 1.383], [63580.5, 0.026], [63611.8, 15.323], [63934.7, 5.533], [64521.0, 0.401], [64554.6, 1.395], [64554.7, 0.187], [64555.0, 0.103], [64556.9, 0.102], [64566.7, 0.0], [64566.8, 0.002], [64567.7, 0.553], [64580.3, 0.005]], "asks": [[64587.4, 0.084], [65226.4, 3.043], [65226.5, 0.003], [65580.6, 0.03]]}
{"kind": "depth", "E": 1787089949571, "U": 11316022513132, "u": 11316022520257, "recv_ms": 1787089949523, "bids": [[1000.0, 35.76], [14280.5, 2.184], [14380.5, 2.016], [51664.0, 0.0], [58122.4, 0.004], [61351.4, 0.03], [61997.2, 0.003], [63934.7, 5.533], [63955.9, 0.0], [64501.0, 4.914], [64504.1, 0.035], [64508.3, 0.108], [64508.4, 30.471], [64528.4, 0.019], [64531.3, 6.075], [64535.4, 0.008], [64536.5, 0.687], [64542.9, 0.314], [64565.9, 0.178], [64566.6, 0.76], [64566.7, 0.619], [64567.7, 0.011]], "asks": [[64580.6, 57.219], [64596.4, 0.0], [64597.7, 0.544], [64598.6, 1.548], [64599.4, 0.018], [65097.2, 10.306], [65226.4, 3.043], [65450.0, 23.333]]}
{"kind": "depth", "E": 1787089949673, "U": 11316022520352, "u": 11316022525673, "recv_ms": 1787089949626, "bids": [[14280.5, 2.534], [14380.5, 1.666], [51664.0, 0.0], [58122.4, 0.004], [61997.3, 1.382], [63288.9, 5.223], [63580.5, 0.006], [63624.1, 1.262], [63934.7, 5.533], [64038.0, 100.028], [64257.6, 6.974], [64422.1, 0.0], [64422.2, 0.001], [64424.2, 0.007], [64428.2, 0.0], [64431.9, 0.005], [64435.1, 0.121], [64438.0, 0.513], [64439.1, 0.0], [64440.1, 0.0], [64444.2, 0.0], [64447.9, 0.001], [64450.4, 0.024], [64454.4, 0.007], [64456.9, 0.0], [64458.2, 2.339], [64463.4, 0.027], [64466.9, 0.776], [64470.2, 3.161], [64472.1, 0.004], [64476.5, 0.005], [64479.0, 0.028], [64481.2, 0.003], [64485.5, 0.001], [64488.1, 0.63], [64491.1, 0.0], [64498.8, 0.044], [64501.0, 0.409], [64504.8, 0.208], [64508.7, 0.116], [64510.5, 0.752], [64514.6, 0.064], [64517.8, 0.014], [64520.9, 0.003], [64524.6, 0.25], [64527.9, 0.057], [64530.9, 0.03], [64533.7, 0.002], [64536.5, 0.688], [64536.7, 0.002], [64540.5, 0.006], [64543.2, 0.009], [64546.4, 0.002], [64549.5, 0.0], [64552.1, 0.31], [64556.6, 0.0], [64558.5, 0.053], [64560.0, 3.406], [64560.3, 7.321], [64563.1, 2.402], [64566.4, 0.024], [64569.0, 0.004], [64572.7, 0.002], [64575.9, 0.037], [64579.3, 0.0]], "asks": [[64580.7, 0.104], [64582.9, 0.017], [64585.6, 0.014], [64588.8, 0.483], [64592.9, 0.005], [64595.9, 0.0], [64599.5, 0.001], [64600.0, 3.187], [64600.3, 0.008], [64602.2, 0.058], [64604.9, 0.007], [64608.9, 0.002], [64611.8, 0.072], [64615.2, 0.002], [64622.3, 0.093], [64625.0, 0.006], [64628.0, 0.002], [64631.5, 0.002], [64634.2, 0.151], [64637.0, 0.018], [64641.5, 0.003], [64643.9, 0.002], [64647.0, 0.049], [64653.5, 0.003], [64657.5, 0.002], [64659.8, 0.0], [64662.8, 0.048], [64666.8, 0.013], [64669.8, 0.0], [64672.2, 0.097], [64676.4, 0.019], [64679.9, 1.243], [64681.6, 0.009], [64684.8, 0.012], [64688.3, 0.009], [64691.8, 0.0], [64694.7, 0.0], [64698.6, 0.002], [64702.2, 0.001], [64704.1, 0.005], [64707.6, 0.0], [64714.8, 0.026], [64718.3, 0.005], [64720.3, 0.0], [64720.5, 0.015], [64724.7, 0.0], [64727.7, 0.294], [64731.1, 0.0], [64734.4, 0.001], [64737.3, 0.001], [65226.4, 3.045], [65580.6, 0.01], [66137.1, 3.882]]}
{"kind": "depth", "E": 1787089949775, "U": 11316022525686, "u": 11316022535604, "recv_ms": 1787089949728, "bids": [[1000.0, 35.76], [14280.5, 2.898], [14380.5, 1.302], [51664.0, 0.0], [51664.4, 0.0], [58122.4, 0.004], [61351.4, 0.03], [61997.2, 0.0], [63631.2, 25.015], [63934.7, 5.533], [63967.0, 27.674], [64038.0, 100.004], [64140.1, 0.025], [64142.1, 0.0], [64146.6, 0.001], [64150.1, 0.006], [64152.9, 0.0], [64156.8, 0.003], [64158.6, 0.0], [64162.7, 0.0], [64165.7, 0.005], [64169.5, 0.155], [64172.7, 0.0], [64175.3, 0.0], [64177.6, 0.001], [64182.1, 0.003], [64185.6, 0.001], [64188.1, 0.26], [64191.7, 0.001], [64193.2, 0.004], [64198.1, 0.002], [64200.1, 0.0], [64201.8, 0.0], [64208.0, 0.001], [64211.1, 0.02], [64214.1, 0.0], [64215.2, 0.002], [64220.1, 0.0], [64222.1, 0.0], [64226.1, 0.172], [64230.1, 0.552], [64233.1, 0.0], [64235.1, 0.004], [64239.8, 0.003], [64243.0, 0.011], [64245.9, 0.0], [64249.6, 0.0], [64250.3, 0.52], [64255.5, 0.0], [64258.4, 0.0], [64260.5, 0.002], [64265.1, 0.032], [64268.5, 0.0], [64271.1, 0.002], [64275.1, 0.0], [64277.1, 0.01], [64281.1, 0.0], [64284.1, 0.0], [64287.1, 0.126], [64290.3, 0.066], [64293.6, 0.575], [64297.1, 0.0], [64300.1, 0.922], [64304.0, 0.0], [64307.0, 0.0], [64310.3, 0.054], [64313.0, 0.126], [64315.4, 0.002], [64319.4, 0.0], [64321.7, 0.0], [64324.9, 0.085], [64329.1, 0.001], [64332.1, 0.211], [64335.3, 0.283], [64339.1, 0.062], [64342.1, 0.134], [64345.1, 0.0], [64348.1, 0.004], [64351.1, 0.9], [64355.1, 0.0], [64358.1, 0.001], [64360.1, 0.001], [64364.4, 0.161], [64367.3, 0.002], [64370.9, 0.0], [64373.1, 0.003], [64377.5, 0.077], [64380.1, 0.0], [64383.4, 9.765], [64383.5, 0.0], [64385.7, 0.0], [64390.1, 0.0], [64393.0, 0.113], [64396.8, 0.003], [64398.5, 0.001], [64400.4, 0.105], [64406.2, 0.004], [64409.1, 0.014], [64412.3, 0.009], [64416.0, 0.246], [64418.1, 0.076], [64422.1, 5.365], [64439.1, 4.577], [64520.9, 0.007], [64521.0, 0.397], [64563.7, 0.001], [64565.9, 0.72], [64566.0, 0.202], [64566.7, 0.0], [64567.6, 0.164], [64573.8, 0.134], [64575.1, 0.001], [64576.8, 0.002], [64578.0, 0.02]], "asks": [[64580.6, 57.324], [64585.5, 0.001], [64587.5, 0.015], [64590.1, 0.182], [64596.1, 0.0], [64617.7, 0.061], [64626.8, 0.0], [64635.3, 0.09], [64649.7, 0.0], [64650.4, 0.036], [64711.0, 0.5], [64720.4, 5.408], [64737.3, 10.428], [64739.6, 0.0], [64742.8, 0.216], [64747.4, 0.0], [64749.9, 0.0], [64752.9, 0.074], [64755.4, 0.001], [64758.4, 0.002], [64763.1, 0.002], [64765.1, 0.0], [64768.0, 0.007], [64772.2, 0.0], [64775.8, 0.0], [64776.1, 11.871], [64779.9, 0.008], [64780.9, 0.473], [64784.9, 0.004], [64788.6, 0.003], [64794.6, 0.0], [64799.9, 0.0], [64801.5, 0.001], [64803.7, 0.224], [64807.9, 0.0], [64809.9, 0.0], [64814.3, 0.001], [64817.8, 0.002], [64819.9, 0.002], [64823.2, 0.0], [64827.1, 0.0], [64831.8, 0.411], [64833.2, 0.002], [64836.6, 0.013], [64839.3, 0.001], [64841.7, 0.0], [64845.2, 0.002], [64849.6, 0.0], [64851.3, 0.864], [64854.6, 0.487], [64858.5, 0.0], [64862.0, 0.136], [64864.9, 0.0], [64868.5, 0.125], [64870.6, 0.0], [64874.5, 0.0], [64879.9, 0.412], [64880.9, 0.0], [64885.8, 0.003], [64887.9, 4.32], [64889.9, 0.0], [64894.8, 0.0], [64896.2, 0.0], [64899.9, 0.059], [64902.8, 0.0], [64903.6, 0.0], [65226.4, 3.043], [65387.9, 18.052], [65420.1, 23.36]]}
{"kind": "depth", "E": 1787089949877, "U": 11316022535746, "u": 11316022545252, "recv_ms": 1787089949829, "bids": [[1000.0, 35.76], [14280.5, 3.248], [14380.5, 0.952], [58122.4, 0.004], [61351.5, 2.447], [61997.2, 0.003], [63580.5, 0.026], [63934.7, 5.533], [64063.9, 9.849], [64257.5, 0.003], [64470.7, 0.004], [64495.3, 0.01], [64500.4, 0.019], [64501.9, 30.485], [64503.0, 0.023], [64508.4, 0.004], [64522.3, 0.0], [64535.4, 0.004], [64541.9, 0.007], [64546.2, 0.039], [64554.6, 1.381], [64563.7, 0.003], [64567.0, 0.397], [64578.0, 0.022]], "asks": [[64587.7, 2.397], [64596.1, 0.002], [64599.9, 0.002], [64612.9, 0.018], [64638.8, 0.0], [65226.4, 3.043], [65387.9, 18.28], [65420.1, 23.665], [65484.9, 0.0], [65580.6, 0.03], [65658.4, 0.0]]}
{"kind": "depth", "E": 1787089949979, "U": 11316022545388, "u": 11316022551471, "recv_ms": 1787089949931, "bids": [[14280.5, 3.598], [14380.5, 0.602], [58122.4, 0.004], [61351.4, 0.03], [61351.5, 2.449], [61997.2, 0.0], [63314.5, 0.676], [63862.9, 3.096], [63934.7, 5.533], [64257.6, 6.974], [64461.9, 3.934], [64470.8, 0.006], [64473.3, 2.324], [64503.0, 0.041], [64509.4, 0.051], [64534.0, 0.029], [64558.5, 0.051], [64575.9, 0.034], [64576.6, 1.729], [64580.5, 3.569]], "asks": [[64580.6, 57.325], [64584.0, 0.355], [64622.0, 0.164], [64632.8, 0.304], [64640.4, 2.369], [64651.6, 0.36], [64687.8, 2.323], [64717.6, 0.028], [64718.8, 3.871], [65226.4, 3.043], [65500.0, 341.834]]}
{"kind": "depth", "E": 1787089950081, "U": 11316022551542, "u": 11316022560322, "recv_ms": 1787089950033, "bids": [[1000.0, 35.76], [14180.5, 0.098], [14280.5, 3.766], [14380.5, 0.336], [58122.4, 0.004], [61997.2, 0.003], [63580.5, 0.006], [63599.5, 5.534], [63934.7, 5.533], [64063.9, 10.784], [64383.4, 9.858], [64422.1, 5.401], [64439.1, 4.065], [64495.3, 0.01], [64499.7, 30.499], [64501.9, 0.001], [64535.4, 0.008], [64541.9, 0.003], [64565.9, 0.178], [64566.7, 0.542], [64568.9, 0.309], [64575.6, 0.035], [64576.2, 0.314], [64576.5, 0.001], [64576.7, 1.563]], "asks": [[64580.6, 57.31], [64591.1, 0.0], [64591.9, 0.085], [64632.8, 0.094], [64639.5, 0.248], [64660.1, 0.013], [64662.3, 42.057], [64673.3, 0.002], [64675.5, 0.0], [64906.8, 0.0], [64909.7, 0.0], [64913.1, 0.014], [64915.5, 0.012], [64919.9, 0.008], [64921.9, 0.001], [64926.9, 0.0], [64929.1, 0.0], [64932.5, 0.0], [64935.2, 0.003], [64938.5, 0.0], [64941.5, 0.034], [64944.9, 0.0], [64947.6, 0.01], [64950.4, 0.003], [64953.8, 0.071], [64959.9, 0.0], [64960.0, 76.987], [64963.3, 0.0], [64967.9, 0.0], [64969.6, 2.633], [64974.5, 0.0], [64976.9, 0.0], [64979.9, 0.001], [64983.7, 0.0], [64988.4, 0.002], [64989.9, 0.0], [64993.6, 0.0], [64996.2, 0.0], [64999.9, 0.096], [65003.2, 0.0], [65005.2, 0.006], [65009.9, 0.183], [65011.9, 0.001], [65014.9, 0.002], [65018.3, 0.0], [65021.9, 0.0], [65024.9, 0.0], [65027.6, 0.002], [65226.4, 3.043], [65561.7, 0.012], [65580.6, 0.01], [65872.2, 7.648]]}
{"kind": "depth", "E": 1787089950183, "U": 11316022560530, "u": 11316022570537, "recv_ms": 1787089950135, "bids": [[1000.0, 35.76], [14180.5, 0.336], [14280.5, 3.654], [14380.5, 0.21], [58122.4, 0.004], [63288.9, 5.226], [63599.5, 5.551], [63676.4, 66.147], [63741.0, 21.581], [63934.7, 5.533], [64038.0, 100.135], [64461.9, 0.063], [64462.0, 3.878], [64494.4, 3.196], [64501.0, 0.41], [64508.3, 0.106], [64509.4, 0.051], [64528.4, 0.02], [64531.3, 6.067], [64532.0, 0.126], [64532.3, 0.002], [64565.9, 0.17], [64566.0, 0.125], [64566.1, 0.085], [64566.6, 0.218], [64566.7, 0.542], [64566.8, 0.002], [64567.1, 0.08], [64567.2, 0.002], [64567.3, 0.546], [64572.0, 0.004], [64572.5, 0.232], [64576.3, 0.429], [64576.8, 0.012]], "asks": [[64584.6, 0.008], [64586.4, 0.002], [64599.1, 0.32], [64600.0, 3.227], [64635.4, 0.061], [64635.8, 0.0], [64651.6, 0.36], [64662.3, 0.001], [64675.5, 42.056], [64718.8, 0.0], [64718.9, 3.886], [65226.4, 3.043], [65387.9, 18.052], [65556.6, 3.048], [65672.0, 5.734]]}
{"kind": "depth", "E": 1787089950285, "U": 11316022570767, "u": 11316022576886, "recv_ms": 1787089950236, "bids": [[14180.5, 0.574], [14280.5, 3.528], [14380.5, 0.098], [51664.0, 0.0], [58122.4, 0.004], [61997.2, 0.0], [63580.5, 0.026], [63611.7, 0.689], [63805.5, 68.724], [63934.7, 5.533], [64257.6, 6.974], [64561.3, 0.002], [64563.0, 0.097], [64564.0, 0.03], [64564.8, 0.165], [64566.2, 0.544], [64566.6, 0.76], [64566.7, 0.0], [64567.3, 0.004], [64567.4, 0.31], [64576.8, 0.002]], "asks": [[64589.7, 0.094], [64591.7, 0.007], [64592.1, 0.543], [64594.9, 0.181], [64595.3, 0.017], [64600.1, 0.028], [64654.8, 0.003], [64664.5, 45.864], [64675.5, 0.0], [65226.4, 3.043], [65561.7, 0.029], [65580.6, 0.03]]}
{"kind": "depth", "E": 1787089950387, "U": 11316022576976, "u": 11316022582691, "recv_ms": 1787089950338, "bids": [[1000.0, 35.76], [14180.5, 0.84], [14280.5, 3.36], [14380.5, 0.0], [58122.4, 0.004], [61997.2, 0.003], [63611.8, 14.97], [63663.5, 3.306], [63934.7, 5.533], [64038.0, 100.126], [64439.1, 4.039], [64495.3, 0.01], [64499.6, 30.49], [64499.7, 0.015], [64568.4, 0.577], [64575.2, 0.085], [64576.0, 0.082], [64576.8, 0.012]], "asks": [[64592.2, 0.59], [64600.1, 0.008], [64720.4, 5.408], [64957.0, 2.038], [65226.4, 3.043]]}
{"kind": "depth", "E": 1787089950489, "U": 11316022582863, "u": 11316022589135, "recv_ms": 1787089950441, "bids": [[1000.0, 35.76], [14180.5, 1.19], [14280.5, 3.01], [58122.4, 0.004], [61351.4, 0.031], [61997.2, 0.0], [61997.3, 1.381], [63580.5, 0.006], [63736.2, 0.0], [63773.2, 28.051], [63934.7, 5.533], [64567.5, 0.648], [64576.8, 0.002], [64580.5, 3.572]], "asks": [[64584.6, 0.007], [64602.6, 0.006], [65226.4, 3.043], [65427.2, 1.526], [65580.6, 0.01]]}
{"kind": "depth", "E": 1787089950591, "U": 11316022589159, "u": 11316022595679, "recv_ms": 1787089950543, "bids": [[14180.5, 1.554], [14280.5, 2.646], [58122.4, 0.004], [61351.4, 0.03], [63611.8, 15.323], [63663.5, 3.072], [63805.5, 69.427], [63934.7, 5.533], [64257.6, 6.974]], "asks": [[64580.6, 57.31], [64607.6, 0.213], [64614.7, 0.121], [65226.4, 3.043], [65667.5, 0.912], [67155.9, 0.0]]}
{"kind": "depth", "E": 1787089950795, "U": 11316022601100, "u": 11316022606643, "recv_ms": 1787089950747, "bids": [[1000.0, 35.76], [14180.5, 2.268], [14280.5, 1.932], [51664.4, 0.0], [58122.4, 0.004], [61351.4, 0.03], [61997.2, 0.0], [63611.7, 0.697], [63934.7, 5.533], [64383.4, 9.743], [64419.0, 0.014], [64422.1, 4.594], [64439.1, 3.635], [64522.3, 0.003], [64547.6, 0.019], [64547.7, 0.004], [64547.8, 0.001], [64551.1, 0.0], [64551.2, 0.003], [64551.3, 2.32], [64558.4, 1.792], [64560.3, 2.321], [64563.7, 0.001]], "asks": [[64580.6, 57.309], [64596.1, 0.0], [64600.0, 3.23], [64645.2, 0.359], [64653.0, 0.045], [64720.4, 5.408], [64737.3, 10.428], [64776.1, 13.033], [65226.4, 3.043], [65298.2, 4.649], [65328.9, 0.765]]}
{"kind": "depth", "E": 1787089950897, "U": 11316022606776, "u": 11316022612571, "recv_ms": 1787089950849, "bids": [[14180.5, 2.632], [14280.5, 1.568], [58122.4, 0.004], [61351.5, 2.447], [61351.6, 0.01], [61997.2, 0.003], [63580.5, 0.006], [63854.7, 0.0], [63934.7, 5.533], [64257.5, 0.001], [64257.6, 6.964], [64513.3, 0.082], [64563.7, 0.003], [64567.0, 0.397]], "asks": [[64587.7, 2.397], [64596.1, 0.002], [64903.6, 0.002], [65226.4, 3.043], [65492.0, 3.114], [65549.6, 0.343], [65580.6, 0.01], [65678.5, 24.211]]}
{"kind": "depth", "E": 1787089950999, "U": 11316022612642, "u": 11316022617501, "recv_ms": 1787089950950, "bids": [[1000.0, 35.76], [14180.5, 2.982], [14280.5, 1.218], [58122.4, 0.004], [61351.4, 0.03], [61997.2, 0.0], [63725.5, 0.0], [63757.7, 0.002], [63934.7, 5.533], [64383.4, 4.156], [64422.1, 2.322], [64439.1, 1.897], [64510.7, 0.046], [64517.7, 0.017], [64545.4, 0.015]], "asks": [[64580.6, 57.308], [64609.1, 3.574], [64612.2, 0.013], [64643.4, 0.093], [64653.0, 0.027], [65226.4, 3.043], [65336.2, 6.42]]}
{"kind": "depth", "E": 1787089951101, "U": 11316022617574, "u": 11316022622864, "recv_ms": 1787089951053, "bids": [[1000.0, 35.76], [14180.5, 3.332], [14280.5, 0.868], [58122.4, 0.004], [63580.5, 0.026], [63934.7, 5.533], [63959.9, 0.315], [64383.4, 9.943], [64422.1, 5.436], [64439.1, 4.083], [64469.2, 0.006], [64469.3, 10.483], [64508.1, 0.04], [64510.7, 0.0], [64517.7, 4.141], [64536.5, 0.686], [64545.4, 0.017], [64568.9, 0.309]], "asks": [[64580.6, 57.309], [64600.1, 5.008], [64602.6, 0.008], [64612.2, 0.015], [64643.4, 2.313], [64691.8, 7.816], [64691.9, 2.319], [65226.4, 3.045], [65355.6, 58.693], [65497.6, 2.281], [65557.2, 1.524], [65580.6, 0.03]]}
