{"kind": "depth", "E": 1787089951203, "U": 11316022622969, "u": 11316022628189, "recv_ms": 1787089951154, "bids": [[14180.5, 3.696], [14280.5, 0.504], [58122.4, 0.004], [61351.4, 0.03], [61351.6, 0.008], [61997.2, 0.003], [63797.4, 0.0], [63934.7, 5.533], [64257.6, 6.964], [64494.4, 3.197], [64503.0, 0.038], [64503.8, 0.003], [64508.3, 0.107], [64522.3, 0.003], [64528.2, 0.001], [64531.3, 6.068], [64563.6, 0.008], [64564.5, 0.002], [64566.6, 0.76], [64567.6, 0.164]], "asks": [[64580.6, 57.309], [64585.1, 0.089], [64596.4, 0.542], [64597.7, 0.002], [64598.6, 1.548], [64599.5, 0.001], [64604.7, 0.065], [64605.9, 2.325], [64612.9, 0.021], [65226.4, 3.043], [65428.1, 2.289]]}
{"kind": "depth", "E": 1787089951305, "U": 11316022628289, "u": 11316022634272, "recv_ms": 1787089951257, "bids": [[1000.0, 35.76], [14080.5, 0.154], [14180.5, 3.738], [14280.5, 0.308], [51664.0, 0.0], [58122.4, 0.004], [61997.2, 0.0], [63580.5, 0.006], [63934.7, 5.533], [63967.0, 28.376], [64383.4, 7.115], [64566.1, 0.008], [64566.7, 0.077], [64568.9, 0.0], [64570.1, 0.361], [64576.3, 0.429]], "asks": [[64596.4, 0.0], [64597.7, 0.544], [64601.5, 1.798], [64602.5, 0.003], [64603.1, 0.116], [64603.8, 0.071], [64650.0, 0.694], [65226.4, 3.043], [65355.6, 63.277], [65580.6, 0.01]]}
{"kind": "depth", "E": 1787089951407, "U": 11316022634610, "u": 11316022639864, "recv_ms": 1787089951360, "bids": [[1000.0, 35.76], [14080.5, 0.392], [14180.5, 3.626], [14280.5, 0.182], [51664.0, 0.0], [58122.4, 0.004], [61997.2, 0.003], [63934.7, 5.533], [64063.9, 10.784], [64568.9, 0.011], [64572.8, 2.329], [64578.0, 0.012], [64579.3, 0.008]], "asks": [[64588.2, 0.315], [64588.5, 0.727], [64591.9, 0.008], [64592.3, 0.095], [64594.8, 0.0], [64595.6, 0.008], [64607.5, 0.123], [64614.7, 0.001], [65226.4, 3.043], [65427.9, 3.815], [65872.2, 7.651]]}
{"kind": "depth", "E": 1787089951509, "U": 11316022640072, "u": 11316022645032, "recv_ms": 1787089951462, "bids": [[14080.5, 0.63], [14180.5, 3.5], [14280.5, 0.07], [58122.4, 0.004], [63580.5, 0.026], [63934.7, 5.533], [64257.6, 6.964], [64383.4, 9.546], [64572.5, 0.0], [64573.0, 0.329]], "asks": [[64580.6, 57.33], [64589.9, 0.004], [64594.8, 0.08], [64601.5, 1.241], [64601.9, 0.558], [65226.4, 3.045], [65522.6, 0.538], [65580.6, 0.03]]}
{"kind": "depth", "E": 1787089951611, "U": 11316022645090, "u": 11316022650174, "recv_ms": 1787089951564, "bids": [[1000.0, 35.76], [14080.5, 0.924], [14180.5, 3.276], [14280.5, 0.0], [58122.4, 0.004], [61351.4, 0.03], [61997.2, 0.0], [63934.7, 5.533], [64462.0, 3.878], [64473.3, 0.001], [64474.1, 2.487], [64495.3, 30.192], [64499.6, 0.006], [64509.4, 0.051], [64535.4, 0.004], [64543.1, 4.016], [64543.5, 0.007], [64544.0, 0.007], [64555.6, 0.148], [64557.7, 0.004], [64559.5, 0.088], [64559.7, 0.116], [64560.2, 0.628], [64560.4, 0.497], [64560.6, 0.001], [64561.2, 0.56], [64561.4, 0.003], [64564.5, 0.003], [64564.8, 0.157], [64564.9, 0.001], [64566.1, 0.935], [64566.3, 0.01], [64566.5, 0.001], [64566.7, 0.077], [64567.4, 0.31], [64567.5, 0.029], [64571.4, 0.0], [64572.6, 0.002], [64572.9, 1.764], [64574.8, 0.014], [64576.7, 1.647], [64577.3, 0.1]], "asks": [[64580.6, 44.242], [64580.7, 0.02], [64581.6, 0.092], [64582.0, 0.03], [64587.6, 0.045], [64591.7, 0.0], [64592.3, 0.102], [64595.3, 0.009], [64595.5, 0.319], [64596.4, 0.0], [64597.7, 0.544], [64598.6, 0.002], [64599.0, 0.956], [64600.6, 0.032], [64601.4, 2.339], [64601.9, 0.558], [64602.1, 0.207], [64602.6, 0.006], [64605.0, 0.062], [64605.9, 2.323], [64606.0, 0.01], [64607.5, 0.003], [64609.4, 2.001], [64616.6, 0.43], [64625.2, 0.005], [64627.1, 0.058], [64632.0, 1.106], [64636.7, 0.21], [64639.5, 0.038], [64640.1, 0.0], [64647.0, 0.049], [64651.6, 0.36], [64655.6, 0.03], [64660.7, 0.079], [64662.3, 41.683], [64664.5, 3.808], [64687.8, 2.323], [64718.9, 0.015], [64720.5, 3.886], [64788.2, 0.0], [64828.7, 0.01], [64836.0, 0.016], [65018.4, 0.011], [65226.4, 3.043], [65557.2, 0.762], [67163.6, 0.0]]}
{"kind": "depth", "E": 1787089951713, "U": 11316022650307, "u": 11316022655681, "recv_ms": 1787089951666, "bids": [[1000.0, 35.76], [14080.5, 1.274], [14180.5, 2.926], [51664.4, 0.002], [58122.4, 0.004], [61997.2, 0.003], [63314.6, 3.38], [63580.5, 0.006], [63934.7, 5.533], [64257.6, 6.974], [64495.3, 0.01], [64499.6, 0.006], [64501.8, 30.186], [64534.0, 0.001], [64552.1, 0.0], [64553.8, 0.316], [64566.2, 0.002], [64566.7, 0.0], [64566.8, 0.079], [64567.1, 0.622], [64576.0, 0.079], [64576.3, 0.432], [64576.7, 1.639], [64576.8, 0.002], [64578.0, 0.02]], "asks": [[64591.9, 0.0], [64592.1, 0.001], [64592.3, 0.025], [64592.5, 0.63], [64598.4, 0.041], [64598.9, 0.018], [64601.3, 0.014], [64605.9, 2.403], [64632.3, 0.02], [64634.7, 0.21], [64636.7, 0.0], [64643.3, 0.004], [65492.0, 3.876], [65529.9, 22.156], [65580.6, 0.01]]}
{"kind": "depth", "E": 1787089951815, "U": 11316022655825, "u": 11316022660886, "recv_ms": 1787089951768, "bids": [[14080.5, 1.638], [14180.5, 2.562], [51664.0, 0.0], [51664.4, 0.0], [58122.4, 0.004], [61351.4, 0.03], [61997.2, 0.0], [62620.0, 0.254], [63934.7, 5.533], [64495.3, 0.01], [64499.7, 29.894], [64501.8, 0.004], [64563.7, 0.001], [64576.8, 0.002], [64580.5, 3.872]], "asks": [[64585.1, 0.088], [64596.1, 0.0], [64600.1, 0.008], [64602.6, 0.004], [65226.4, 3.043], [65342.9, 12.699], [66517.9, 2.182]]}
{"kind": "depth", "E": 1787089951917, "U": 11316022660999, "u": 11316022665586, "recv_ms": 1787089951870, "bids": [[1000.0, 35.76], [14080.5, 2.002], [14180.5, 2.198], [58122.4, 0.004], [61997.2, 0.003], [63288.9, 5.223], [63482.6, 16.878], [63580.5, 0.026], [63934.7, 5.533], [64499.7, 0.015], [64501.8, 29.883], [64563.7, 0.003], [64566.2, 0.544], [64566.6, 0.218], [64566.7, 0.542], [64567.1, 0.08], [64576.8, 0.02], [64578.0, 0.012]], "asks": [[64596.1, 0.002], [64609.3, 0.132], [64616.6, 0.31], [64627.6, 0.07], [64635.3, 0.03], [64658.1, 0.024], [64660.1, 41.281], [64660.7, 0.07], [64662.3, 0.001], [64903.6, 0.0], [65097.2, 6.472], [65226.4, 3.043], [65387.9, 18.311], [65580.6, 0.03]]}
{"kind": "depth", "E": 1787089952019, "U": 11316022665640, "u": 11316022670483, "recv_ms": 1787089951973, "bids": [[1000.0, 35.76], [14080.5, 2.352], [14180.5, 1.848], [58122.4, 0.004], [61351.4, 0.03], [63288.9, 5.226], [63289.0, 0.015], [63360.7, 0.063], [63432.5, 0.0], [63504.3, 0.0], [63576.0, 0.0], [63647.8, 0.0], [63719.5, 0.0], [63791.3, 0.0], [63863.0, 1.344], [63934.7, 5.533], [63934.8, 0.046], [64257.5, 0.003], [64257.6, 6.974], [64422.1, 4.524], [64439.0, 3.632], [64439.1, 0.0], [64576.8, 0.01], [64579.3, 0.01], [64580.5, 3.873]], "asks": [[64580.6, 44.242], [64634.7, 0.0], [64642.9, 0.212], [64720.4, 5.408], [64737.3, 10.428], [65097.2, 10.306], [65226.4, 2.984], [65298.2, 4.59], [65349.1, 7.336], [65369.9, 0.02], [65441.7, 0.024], [65451.8, 1.523], [65513.4, 0.002], [65585.2, 0.008], [65656.9, 0.0], [65728.7, 0.002], [65800.5, 0.312], [65872.2, 7.592]]}
{"kind": "depth", "E": 1787089952121, "U": 11316022670619, "u": 11316022680298, "recv_ms": 1787089952075, "bids": [[14080.5, 2.702], [14180.5, 1.498], [51664.0, 0.002], [58122.4, 0.004], [61997.2, 0.0], [63580.5, 0.006], [63599.4, 0.001], [63663.5, 3.306], [63773.2, 28.285], [63934.7, 5.533], [64494.0, 0.051], [64494.4, 3.196], [64500.7, 0.017], [64501.0, 0.406], [64508.1, 0.041], [64508.2, 0.001], [64508.3, 0.106], [64528.3, 0.005], [64531.1, 0.001], [64531.3, 6.067], [64534.9, 0.004], [64536.5, 0.68], [64543.5, 0.003], [64568.9, 0.011], [64576.4, 0.72], [64576.8, 0.01]], "asks": [[64580.6, 44.212], [64585.7, 0.004], [65226.4, 2.984], [65561.6, 0.007], [65580.6, 0.01], [67163.8, 3.822]]}
{"kind": "depth", "E": 1787089952223, "U": 11316022680831, "u": 11316022688080, "recv_ms": 1787089952178, "bids": [[1000.0, 35.76], [14080.5, 3.066], [14180.5, 1.134], [51664.0, 0.0], [58122.4, 0.004], [61997.2, 0.003], [63482.6, 17.506], [63599.5, 5.561], [63934.7, 5.533], [64450.0, 9.766], [64500.7, 0.016], [64500.9, 4.494], [64503.8, 0.002], [64504.6, 0.023], [64528.3, 0.004], [64528.4, 0.018], [64536.3, 0.002], [64550.0, 0.007], [64558.1, 0.002], [64558.5, 0.053], [64576.8, 0.02]], "asks": [[65226.4, 2.984], [65465.4, 4.872], [65471.0, 1.003], [65561.7, 0.039]]}
{"kind": "depth", "E": 1787089952325, "U": 11316022688303, "u": 11316022694797, "recv_ms": 1787089952280, "bids": [[14080.5, 3.416], [14180.5, 0.784], [51664.0, 0.0], [58122.4, 0.004], [61997.2, 0.0], [63288.9, 5.223], [63643.5, 4.525], [63663.5, 3.54], [63934.7, 5.533], [64257.6, 6.974], [64422.1, 0.0], [64439.0, 0.034], [64528.3, 0.005], [64532.8, 4.592], [64533.7, 0.0], [64547.3, 0.0], [64555.6, 0.268], [64576.7, 0.091], [64576.8, 0.012], [64578.0, 1.568]], "asks": [[64584.8, 0.002], [64609.3, 0.012], [64616.3, 0.122], [64720.4, 0.0], [64737.3, 0.001], [65226.4, 2.986], [65349.1, 8.253], [65478.3, 23.991], [65872.2, 7.589]]}
{"kind": "depth", "E": 1787089952427, "U": 11316022694849, "u": 11316022702483, "recv_ms": 1787089952379, "bids": [[14080.5, 3.724], [14180.5, 0.448], [14480.5, 0.028], [58122.4, 0.004], [61351.6, 0.006], [61997.2, 0.003], [63580.5, 0.026], [63934.7, 5.533], [64422.1, 5.264], [64439.0, 4.029], [64503.0, 0.041], [64522.3, 0.0], [64545.6, 1.05], [64552.8, 0.092], [64559.7, 0.0], [64560.3, 2.437], [64567.0, 0.396], [64573.0, 0.245], [64576.7, 0.099], [64576.8, 0.002], [64577.8, 0.085], [64578.0, 1.56]], "asks": [[64587.7, 2.396], [64588.5, 0.418], [64588.9, 0.851], [64598.3, 0.0], [64598.5, 0.002], [64598.6, 0.621], [64601.5, 1.242], [64612.9, 0.021], [64634.9, 0.017], [64720.4, 5.408], [64737.3, 10.428], [65226.4, 2.984], [65580.6, 0.03], [65678.5, 19.65], [65749.6, 1.315], [65750.8, 0.76], [65788.3, 5.413]]}
{"kind": "depth", "E": 1787089952529, "U": 11316022702653, "u": 11316022708937, "recv_ms": 1787089952481, "bids": [[1000.0, 35.76], [14080.5, 3.71], [14180.5, 0.28], [14480.5, 0.21], [58122.4, 0.004], [61351.4, 0.03], [61351.5, 2.451], [63288.9, 5.22], [63644.1, 42.252], [63862.9, 4.66], [63934.7, 5.533], [64495.3, 29.889], [64499.6, 0.006], [64501.8, 0.004], [64513.3, 0.054], [64517.5, 0.001], [64517.7, 4.143], [64519.0, 0.122], [64527.9, 0.267], [64534.9, 0.0], [64541.2, 0.004], [64547.6, 0.021], [64547.7, 0.006], [64547.8, 0.003], [64550.1, 0.0], [64551.1, 0.002], [64551.2, 0.005], [64551.3, 2.322], [64554.4, 10.059], [64558.0, 0.324], [64559.0, 0.013], [64559.5, 5.088], [64560.1, 0.003], [64560.3, 2.321], [64561.0, 0.123], [64561.2, 0.002], [64561.7, 0.56], [64563.2, 0.041], [64563.8, 0.012], [64565.9, 0.163], [64566.1, 0.927], [64566.7, 0.0], [64566.8, 0.002], [64570.0, 0.012], [64570.4, 1.549], [64570.5, 0.654], [64571.2, 0.017], [64572.0, 0.008], [64572.9, 0.165], [64573.3, 0.001], [64573.8, 0.134], [64574.9, 0.034], [64575.3, 0.157], [64576.7, 0.091], [64578.0, 0.012], [64578.1, 0.0], [64578.9, 0.002], [64579.3, 0.0], [64580.5, 4.383]], "asks": [[64580.6, 44.212], [64581.5, 0.036], [64581.6, 0.008], [64581.8, 0.012], [64581.9, 0.084], [64582.1, 0.0], [64582.6, 0.002], [64585.4, 0.085], [64585.7, 0.003], [64590.1, 0.174], [64591.1, 0.008], [64592.5, 0.553], [64592.7, 0.077], [64595.5, 0.311], [64595.9, 0.008], [64603.1, 0.0], [64603.7, 0.118], [64609.4, 0.001], [64610.4, 2.283], [64614.6, 0.024], [64617.4, 0.154], [64623.5, 0.025], [64629.7, 0.018], [64632.3, 0.006], [64634.9, 0.017], [64660.1, 41.281], [64660.7, 0.079], [64671.1, 0.0], [64903.5, 2.617], [65226.4, 2.984], [65474.9, 0.0]]}
{"kind": "depth", "E": 1787089952631, "U": 11316022709124, "u": 11316022715303, "recv_ms": 1787089952584, "bids": [[14080.5, 3.598], [14180.5, 0.154], [14480.5, 0.448], [58122.4, 0.004], [61351.4, 0.03], [61997.2, 0.0], [63580.5, 0.006], [63675.7, 0.909], [63934.7, 5.533], [64038.0, 100.089], [64257.6, 6.974], [64554.8, 0.074], [64560.3, 2.94], [64560.4, 0.613], [64561.0, 0.007], [64561.2, 0.56], [64561.7, 0.002], [64567.6, 0.783], [64576.8, 0.012]], "asks": [[64580.6, 44.213], [64598.7, 3.189], [64600.0, 3.19], [64601.5, 1.282], [64606.0, 0.629], [64617.4, 0.0], [64617.5, 0.002], [64617.6, 1.161], [64632.3, 0.02], [64634.9, 0.003], [64660.7, 0.07], [65226.4, 2.984], [65497.6, 2.509], [65580.6, 0.01]]}
{"kind": "depth", "E": 1787089952733, "U": 11316022715481, "u": 11316022720801, "recv_ms": 1787089952686, "bids": [[14080.5, 3.472], [14180.5, 0.042], [14480.5, 0.686], [51664.4, 0.0], [58122.4, 0.004], [61997.2, 0.003], [63580.5, 0.026], [63766.1, 2.349], [63934.7, 5.533], [64439.0, 0.034], [64546.0, 0.001], [64551.9, 0.166]], "asks": [[64580.6, 44.21], [64589.5, 0.165], [64720.4, 0.0], [65226.4, 2.988], [65491.2, 8.848], [65580.6, 0.03], [65678.5, 24.211], [65788.3, 6.141]]}
{"kind": "depth", "E": 1787089952835, "U": 11316022720856, "u": 11316022726567, "recv_ms": 1787089952788, "bids": [[1000.0, 35.76], [14080.5, 3.192], [14180.5, 0.0], [14480.5, 1.008], [58122.4, 0.004], [61351.4, 0.03], [61997.2, 0.0], [63578.9, 1.104], [63643.5, 3.427], [63682.8, 24.725], [63733.7, 6.433], [63790.2, 0.0], [63934.7, 5.533], [64439.0, 4.029], [64538.6, 0.013], [64554.8, 0.073]], "asks": [[64617.6, 1.007], [64617.7, 0.215], [64720.4, 5.408], [64903.5, 4.924], [65226.4, 2.984], [65427.9, 3.052], [65477.4, 0.001], [65556.6, 3.81]]}
{"kind": "depth", "E": 1787089953039, "U": 11316022735245, "u": 11316022743898, "recv_ms": 1787089952990, "bids": [[14080.5, 2.478], [14480.5, 1.722], [58122.4, 0.004], [61997.2, 0.003], [63579.5, 32.669], [63580.5, 0.006], [63644.1, 43.35], [63798.3, 3.132], [63934.7, 5.533], [64038.0, 100.004], [64257.5, 0.001], [64383.3, 4.919], [64383.4, 0.777], [64422.1, 2.918], [64439.0, 2.777], [64551.7, 0.608], [64551.9, 0.012], [64556.9, 0.103], [64563.8, 0.004], [64564.3, 0.009], [64567.1, 0.081], [64568.2, 0.305], [64568.9, 0.016], [64569.4, 0.007], [64570.5, 0.646], [64576.3, 0.429], [64576.9, 0.004], [64578.0, 0.012], [64578.2, 0.085], [64579.3, 0.008], [64580.5, 4.373]], "asks": [[64582.0, 0.023], [64582.8, 0.008], [64587.8, 0.001], [64592.3, 0.018], [64592.5, 0.003], [64592.7, 0.0], [64593.1, 0.642], [64595.6, 0.001], [64596.5, 2.021], [64598.9, 0.016], [64599.5, 0.003], [64607.1, 0.0], [64609.2, 0.623], [65226.4, 2.984], [65355.6, 63.277], [65375.2, 1.534], [65580.6, 0.01], [65872.2, 7.589]]}
{"kind": "depth", "E": 1787089953141, "U": 11316022744142, "u": 11316022753058, "recv_ms": 1787089953093, "bids": [[1000.0, 35.76], [14080.5, 2.114], [14480.5, 2.086], [51664.0, 0.0], [58122.4, 0.004], [61997.2, 0.0], [63934.7, 5.533], [64383.3, 8.978], [64422.1, 5.326], [64439.0, 4.06], [64494.4, 3.197], [64501.0, 0.407], [64504.8, 0.209], [64508.3, 0.108], [64528.4, 0.019], [64528.8, 0.092], [64531.3, 6.068], [64536.4, 0.073], [64556.9, 0.102], [64560.7, 0.002], [64562.0, 0.312], [64563.0, 0.01], [64568.9, 0.011], [64570.6, 0.008], [64578.0, 0.014], [64579.3, 0.0]], "asks": [[64587.6, 0.046], [64598.6, 0.002], [64599.6, 0.712], [65226.4, 2.984], [65363.6, 0.787], [65377.0, 0.475], [65427.2, 2.289]]}
{"kind": "depth", "E": 1787089953345, "U": 11316022759758, "u": 11316022765751, "recv_ms": 1787089953297, "bids": [[1000.0, 35.91], [14080.5, 1.414], [14480.5, 2.786], [58122.4, 0.004], [61351.4, 0.03], [61997.2, 0.0], [63643.5, 2.328], [63934.7, 5.533], [64422.1, 5.302], [64439.0, 4.049], [64558.1, 0.0], [64558.8, 0.002], [64560.6, 0.001], [64566.3, 0.01], [64569.2, 0.018], [64569.6, 0.009], [64570.4, 0.001], [64570.6, 0.0], [64571.7, 0.004], [64573.6, 0.001], [64575.7, 0.003], [64578.0, 1.562], [64579.3, 0.008]], "asks": [[64720.4, 5.408], [64737.3, 10.428], [64903.6, 0.002], [64943.7, 0.69], [65226.4, 2.984], [65348.8, 0.177], [65556.6, 4.572], [67163.8, 4.459]]}
{"kind": "depth", "E": 1787089953447, "U": 11316022765794, "u": 11316022772348, "recv_ms": 1787089953400, "bids": [[1000.0, 35.76], [14080.5, 1.05], [14480.5, 3.15], [58122.4, 0.004], [61351.4, 0.03], [63580.5, 0.006], [63934.7, 5.533], [64439.0, 3.635], [64558.8, 0.001], [64561.2, 0.561], [64567.7, 0.553], [64570.0, 0.096], [64570.1, 0.052], [64570.4, 0.001], [64570.5, 0.012], [64570.6, 0.0], [64571.1, 0.31], [64573.8, 0.132], [64575.2, 0.087], [64578.0, 0.014], [64578.1, 0.008], [64578.2, 1.633]], "asks": [[64580.6, 44.211], [64588.9, 0.542], [64589.5, 0.474], [64603.1, 0.116], [64603.7, 0.002], [64617.7, 0.061], [64720.4, 5.408], [65226.4, 2.984], [65580.6, 0.01]]}
{"kind": "depth", "E": 1787089953549, "U": 11316022772385, "u": 11316022779015, "recv_ms": 1787089953501, "bids": [[14080.5, 0.7], [14480.5, 3.5], [58122.4, 0.004], [61351.4, 0.03], [61997.2, 0.003], [63644.1, 44.449], [63934.6, 0.005], [63934.7, 5.533], [64257.6, 6.964], [64470.7, 0.007], [64515.9, 0.023], [64556.3, 0.014], [64560.3, 2.321], [64561.2, 0.56], [64567.6, 0.164], [64567.7, 0.553], [64570.0, 0.104], [64570.1, 0.052], [64570.4, 0.001], [64570.5, 0.012], [64578.0, 0.014], [64578.1, 0.0], [64578.2, 0.085], [64578.3, 0.001], [64578.4, 0.002], [64578.5, 0.0], [64578.6, 1.548], [64580.5, 4.383]], "asks": [[64580.6, 42.939], [64582.5, 0.002], [64582.7, 0.179], [64583.1, 0.029], [64583.3, 0.025], [64598.7, 2.57], [64606.0, 0.01], [64611.6, 0.325], [64617.8, 0.155], [64617.9, 0.0], [64621.2, 0.071], [64622.7, 0.0], [64625.9, 0.0], [64630.1, 0.037], [64634.9, 0.017], [64645.2, 0.363], [64658.1, 0.19], [64742.1, 0.003], [65226.4, 2.984], [65349.1, 9.17], [65355.6, 64.805], [65557.3, 0.0]]}
{"kind": "depth", "E": 1787089953651, "U": 11316022779206, "u": 11316022784888, "recv_ms": 1787089953603, "bids": [[1000.0, 35.76], [14080.5, 0.392], [14380.5, 0.056], [14480.5, 3.752], [51664.0, 0.0], [58122.4, 0.004], [61351.4, 0.03], [61997.2, 0.0], [63580.5, 0.026], [63934.7, 5.533], [64470.7, 0.007], [64503.0, 0.038], [64522.3, 0.0], [64556.3, 0.013], [64559.4, 0.619], [64565.6, 0.217], [64566.7, 0.619], [64567.7, 0.011], [64568.9, 0.085], [64570.0, 0.027], [64570.4, 1.549], [64570.5, 0.631], [64573.9, 0.145], [64575.2, 0.085], [64578.6, 0.0], [64580.5, 4.384]], "asks": [[64580.6, 42.942], [64597.8, 1.179], [64605.1, 1.013], [64612.9, 0.021], [64617.5, 0.002], [64617.7, 0.215], [64617.8, 0.001], [64737.3, 10.428], [64737.4, 0.002], [65226.4, 2.984], [65342.9, 11.17], [65387.9, 19.303], [65580.6, 0.03]]}
{"kind": "depth", "E": 1787089953753, "U": 11316022784984, "u": 11316022789478, "recv_ms": 1787089953705, "bids": [[1000.0, 35.76], [14080.5, 0.252], [14380.5, 0.266], [14480.5, 3.682], [51664.4, 0.0], [58122.4, 0.004], [61997.2, 0.003], [63759.6, 0.0], [63773.2, 27.934], [63793.2, 9.862], [63934.7, 5.533], [64383.3, 6.612], [64563.3, 0.231], [64565.6, 0.216], [64567.5, 0.663], [64570.0, 0.012], [64570.4, 0.001], [64570.5, 0.012], [64570.6, 0.0], [64573.9, 0.143], [64575.2, 0.087], [64578.0, 0.014], [64578.1, 0.0], [64578.2, 0.085], [64578.3, 0.001], [64578.4, 1.55], [64579.2, 1.589], [64580.5, 4.362]], "asks": [[65226.4, 2.984], [65471.4, 0.0], [65549.4, 0.343], [65872.2, 7.592]]}
{"kind": "depth", "E": 1787089953855, "U": 11316022789754, "u": 11316022794869, "recv_ms": 1787089953806, "bids": [[14080.5, 0.126], [14380.5, 0.504], [14480.5, 3.57], [58122.4, 0.004], [61997.2, 0.0], [63580.5, 0.006], [63934.7, 5.533], [64257.6, 6.964], [64383.3, 9.016], [64563.3, 0.23], [64565.4, 0.038], [64567.1, 0.08], [64567.5, 0.029], [64570.4, 1.549], [64570.5, 0.646], [64573.9, 0.145], [64575.2, 0.085], [64578.4, 0.002], [64578.5, 0.0], [64578.6, 0.0]], "asks": [[64587.8, 0.0], [65226.4, 2.984], [65580.6, 0.01]]}
{"kind": "depth", "E": 1787089954059, "U": 11316022799465, "u": 11316022806390, "recv_ms": 1787089954010, "bids": [[1000.0, 35.76], [14080.5, 0.0], [14380.5, 1.092], [14480.5, 3.108], [58122.4, 0.004], [61997.2, 0.003], [63418.0, 0.315], [63580.5, 0.026], [63675.7, 0.0], [63934.7, 5.533], [64495.3, 0.01], [64499.7, 29.548], [64556.3, 0.014], [64563.7, 0.003], [64568.9, 0.085], [64573.0, 0.013], [64573.4, 0.543], [64578.2, 0.001]], "asks": [[65199.8, 0.029], [65580.6, 0.03], [65750.1, 1.522]]}
{"kind": "depth", "E": 1787089954161, "U": 11316022806553, "u": 11316022815908, "recv_ms": 1787089954114, "bids": [[14380.5, 1.442], [14480.5, 2.758], [58122.4, 0.004], [61351.4, 0.03], [61997.2, 0.0], [63288.9, 5.22], [63597.6, 0.011], [63682.8, 25.634], [63805.5, 69.208], [63864.7, 0.707], [63934.7, 5.602], [64257.6, 4.643], [64494.4, 3.198], [64495.3, 29.254], [64499.7, 0.015], [64501.1, 3.579], [64508.3, 0.109], [64521.0, 0.397], [64528.4, 0.021], [64531.3, 6.07], [64536.5, 0.681], [64556.3, 0.013], [64559.4, 0.0], [64560.8, 0.002], [64561.2, 0.002], [64561.7, 0.56], [64566.7, 0.0], [64570.8, 0.249], [64573.9, 0.143], [64575.1, 0.003], [64578.4, 0.002], [64579.2, 1.544], [64579.3, 0.0], [64580.4, 0.008], [64580.5, 6.067]], "asks": [[64580.6, 44.729], [64581.4, 0.0], [64581.9, 0.0], [64582.0, 0.107], [64582.8, 0.011], [64585.1, 0.088], [64587.6, 0.045], [64588.0, 0.023], [64591.1, 0.0], [64591.7, 0.008], [64597.8, 0.56], [64603.1, 0.0], [64603.4, 0.118], [64605.1, 0.394], [64610.4, 0.283], [64610.9, 10.008], [64611.6, 0.311], [64632.3, 0.006], [64634.9, 0.003], [65226.4, 2.984], [65363.5, 3.118], [65563.4, 0.0], [65749.7, 2.611]]}
{"kind": "depth", "E": 1787089954263, "U": 11316022816036, "u": 11316022824362, "recv_ms": 1787089954215, "bids": [[1000.0, 35.76], [14380.5, 1.806], [14480.5, 2.394], [51664.0, 0.002], [58122.4, 0.004], [61351.5, 2.451], [61997.2, 0.003], [63580.5, 0.006], [63934.7, 5.602], [64257.5, 0.003], [64560.8, 0.001], [64561.2, 0.56], [64561.7, 0.002], [64567.2, 0.003], [64573.4, 0.544], [64578.0, 0.012], [64578.2, 0.085]], "asks": [[64587.9, 0.236], [64621.7, 0.025], [64630.1, 0.012], [64903.6, 0.0], [65226.4, 2.984], [65563.5, 0.043], [65580.6, 0.01], [65667.5, 0.0]]}
{"kind": "depth", "E": 1787089954365, "U": 11316022824570, "u": 11316022830813, "recv_ms": 1787089954334, "bids": [[1000.0, 35.76], [14380.5, 2.156], [14480.5, 2.044], [51664.0, 0.0], [58122.4, 0.004], [63773.2, 27.583], [63934.7, 5.602], [64569.1, 0.002], [64573.4, 0.543]], "asks": [[65207.0, 4.218], [65226.4, 2.984], [65506.1, 0.0]]}
{"kind": "depth", "E": 1787089954467, "U": 11316022830984, "u": 11316022837612, "recv_ms": 1787089954418, "bids": [[14380.5, 2.52], [14480.5, 1.68], [58122.4, 0.004], [61351.4, 0.03], [61997.2, 0.0], [63469.6, 0.0], [63580.5, 0.026], [63934.7, 5.602], [64257.6, 6.964], [64495.3, 0.01], [64499.7, 29.259], [64569.1, 0.001], [64572.0, 0.009], [64579.1, 0.046], [64580.5, 6.077]], "asks": [[64660.1, 0.013], [64675.5, 39.989], [65226.4, 2.984], [65291.0, 12.426], [65580.6, 0.03], [65872.2, 7.592]]}
{"kind": "depth", "E": 1787089954569, "U": 11316022837709, "u": 11316022846655, "recv_ms": 1787089954537, "bids": [[1000.0, 35.76], [14380.5, 2.87], [14480.5, 1.33], [58122.4, 0.004], [61351.4, 0.03], [61997.2, 0.003], [63798.5, 1.566], [63934.6, 0.004], [63934.7, 5.602], [64438.1, 0.036], [64439.0, 4.036], [64495.3, 29.254], [64499.7, 0.015], [64534.0, 0.029], [64550.5, 0.002], [64551.7, 0.688], [64552.6, 0.082], [64553.2, 0.001], [64555.6, 0.188], [64556.8, 0.008], [64559.4, 0.002], [64559.7, 0.116], [64560.1, 0.001], [64560.4, 0.491], [64560.6, 0.559], [64561.0, 0.004], [64561.2, 0.002], [64562.8, 0.042], [64563.2, 0.049], [64563.4, 0.099], [64563.7, 0.003], [64564.3, 0.001], [64564.7, 0.001], [64565.0, 0.228], [64565.1, 0.002], [64566.3, 0.559], [64566.4, 0.032], [64566.6, 0.295], [64566.9, 0.442], [64567.0, 0.402], [64567.1, 0.08], [64567.2, 0.003], [64567.7, 0.005], [64568.1, 0.325], [64568.2, 0.302], [64568.3, 0.008], [64568.7, 0.157], [64569.4, 0.0], [64569.9, 4.495], [64570.0, 1.552], [64570.4, 0.001], [64570.5, 0.012], [64570.6, 0.0], [64570.7, 0.007], [64570.8, 0.241], [64571.1, 0.001], [64571.2, 0.017], [64571.3, 0.004], [64571.5, 0.009], [64571.9, 0.002], [64572.8, 2.328], [64573.3, 0.085], [64573.4, 0.311], [64574.4, 0.205], [64574.5, 0.154], [64575.1, 0.001], [64575.6, 0.032], [64575.7, 0.0], [64575.8, 0.141], [64576.0, 0.078], [64576.3, 0.432], [64576.7, 0.099], [64576.8, 0.012], [64576.9, 0.001], [64577.2, 0.087], [64577.3, 0.016], [64577.4, 0.004], [64577.8, 0.001], [64578.0, 0.005], [64578.2, 0.001], [64579.2, 1.543], [64579.3, 0.008], [64580.5, 4.022]], "asks": [[64580.6, 44.64], [64580.8, 0.04], [64581.2, 0.084], [64581.6, 0.015], [64581.8, 0.009], [64582.0, 0.105], [64582.4, 0.003], [64582.6, 0.004], [64582.8, 0.084], [64583.0, 0.244], [64583.1, 0.009], [64583.3, 0.002], [64584.0, 0.358], [64585.0, 0.022], [64585.2, 0.003], [64585.4, 0.001], [64585.6, 0.013], [64587.0, 0.624], [64587.2, 0.043], [64587.9, 0.236], [64588.0, 0.022], [64588.1, 0.064], [64588.3, 2.495], [64588.8, 0.482], [64589.3, 0.294], [64589.4, 0.059], [64589.5, 0.005], [64589.8, 0.318], [64590.7, 0.037], [64590.8, 0.103], [64590.9, 0.006], [64592.0, 0.622], [64592.2, 0.57], [64592.5, 0.08], [64592.7, 0.015], [64592.8, 0.487], [64593.1, 0.023], [64594.4, 0.001], [64594.7, 0.632], [64595.0, 0.023], [64595.3, 0.017], [64595.8, 0.002], [64595.9, 0.0], [64596.4, 0.542], [64597.7, 0.002], [64598.3, 0.002], [64598.6, 0.621], [64599.5, 0.001], [64599.6, 0.093], [64600.1, 0.028], [64601.3, 0.571], [64601.9, 0.001], [64602.5, 0.119], [64603.4, 0.002], [64607.0, 2.006], [64610.9, 0.008], [64617.7, 0.061], [64618.1, 0.156], [64621.7, 0.0], [64627.1, 0.002], [64629.7, 0.004], [64630.1, 0.037], [64660.7, 0.079], [64662.3, 39.99], [64675.5, 0.0], [64694.8, 7.396], [64720.3, 5.408], [64720.4, 0.0], [64722.3, 0.47], [64737.3, 10.428], [64737.4, 0.002], [65226.4, 2.984], [65427.2, 3.052], [65484.7, 84.62], [65504.3, 4.497]]}
{"kind": "depth", "E": 1787089954671, "U": 11316022846682, "u": 11316022853827, "recv_ms": 1787089954623, "bids": [[1000.0, 35.76], [14380.5, 3.234], [14480.5, 0.966], [51664.0, 0.0], [58122.4, 0.004], [61351.4, 0.03], [61997.2, 0.0], [63288.9, 5.217], [63580.5, 0.006], [63934.7, 5.602], [64401.5, 0.442], [64402.7, 3.015], [64438.1, 0.036], [64461.9, 3.934], [64462.0, 0.007], [64470.2, 0.014], [64470.7, 3.022], [64474.1, 0.164], [64474.3, 2.336], [64495.3, 0.01], [64499.7, 29.259], [64509.4, 0.051], [64538.8, 3.131], [64539.0, 0.003], [64552.7, 0.313], [64553.8, 0.006], [64558.5, 0.051], [64558.7, 0.002], [64559.4, 0.0], [64560.4, 1.11], [64561.1, 1.493], [64562.2, 0.008], [64562.3, 0.01], [64563.0, 0.003], [64563.2, 0.041], [64563.9, 0.012], [64564.3, 0.001], [64566.3, 0.002], [64566.4, 0.024], [64566.6, 0.218], [64567.6, 0.171], [64567.7, 0.624], [64568.3, 0.001], [64569.2, 0.327], [64569.9, 4.186], [64570.1, 0.702], [64570.4, 0.001], [64572.0, 0.008], [64572.2, 0.156], [64572.8, 2.329], [64572.9, 0.011], [64573.0, 0.097], [64573.3, 0.087], [64574.4, 0.203], [64575.6, 0.035], [64576.0, 0.079], [64576.3, 0.429], [64576.7, 0.007], [64576.8, 0.002], [64577.2, 0.003], [64579.3, 0.0], [64580.4, 0.006], [64580.5, 4.018]], "asks": [[64580.6, 44.639], [64580.7, 0.104], [64582.4, 0.004], [64584.8, 0.312], [64585.6, 0.014], [64587.6, 0.053], [64588.8, 0.483], [64590.5, 0.08], [64591.1, 0.557], [64591.7, 0.0], [64592.0, 0.08], [64592.5, 0.003], [64593.1, 0.016], [64594.6, 0.024], [64595.3, 0.009], [64595.6, 0.001], [64596.5, 2.014], [64598.5, 0.621], [64600.4, 5.004], [64605.9, 3.022], [64650.4, 0.027], [64651.6, 0.36], [64655.6, 0.012], [64658.1, 0.181], [64660.1, 0.013], [64660.7, 0.088], [64662.3, 0.001], [64671.1, 39.989], [64687.8, 2.323], [64720.5, 0.015], [64721.1, 3.879], [64722.3, 1.47], [65226.4, 2.984], [65517.0, 40.338], [65580.6, 0.01]]}
{"kind": "depth", "E": 1787089954773, "U": 11316022853953, "u": 11316022860000, "recv_ms": 1787089954725, "bids": [[14380.5, 3.584], [14480.5, 0.616], [51664.0, 0.0], [51664.4, 0.0], [58122.4, 0.004], [61351.4, 0.03], [61997.2, 0.003], [63694.7, 0.007], [63708.7, 17.681], [63934.7, 5.602], [64257.6, 6.974], [64438.1, 0.036], [64551.8, 0.31], [64552.7, 0.003], [64554.4, 0.059], [64557.8, 0.002], [64558.7, 0.0], [64560.4, 0.491], [64560.7, 0.126], [64561.8, 0.009], [64562.1, 1.542], [64562.3, 0.002], [64563.2, 0.044], [64563.4, 0.107], [64563.9, 0.004], [64565.9, 0.039], [64566.2, 1.235], [64566.3, 0.636], [64567.2, 0.002], [64567.7, 0.005], [64568.7, 0.608], [64570.1, 0.068], [64570.4, 1.016], [64571.4, 0.154], [64572.2, 0.002], [64572.7, 0.004], [64573.3, 0.085], [64574.9, 0.037], [64575.5, 1.072], [64575.6, 0.032], [64579.3, 0.985], [64580.5, 3.709]], "asks": [[64580.6, 46.011], [64580.8, 0.09], [64581.6, 0.008], [64587.9, 0.235], [64592.3, 0.026], [64593.1, 0.008], [64596.6, 0.14], [64596.7, 0.032], [64598.3, 0.0], [64598.5, 0.002], [64602.8, 10.0], [64605.9, 2.403], [64621.6, 0.415], [64630.1, 0.012], [64660.1, 40.002], [64662.3, 0.001], [64671.1, 0.0], [64722.3, 0.47], [65226.4, 2.984], [65291.0, 12.655], [65363.5, 2.354], [65428.1, 1.526], [65517.0, 41.252], [65549.3, 19.427]]}
{"kind": "depth", "E": 1787089954875, "U": 11316022860042, "u": 11316022866486, "recv_ms": 1787089954828, "bids": [[1000.0, 35.76], [14280.5, 0.084], [14380.5, 3.78], [14480.5, 0.336], [58122.4, 0.004], [63580.5, 0.026], [63741.0, 22.168], [63934.7, 5.602], [64513.3, 0.054], [64515.1, 3.274], [64521.8, 0.025], [64522.2, 0.0], [64522.5, 0.032], [64522.9, 0.0], [64523.2, 1.105], [64532.9, 2.888], [64539.5, 0.001], [64539.9, 0.001], [64540.2, 0.066], [64540.6, 0.032], [64540.9, 1.256], [64547.0, 10.026], [64554.5, 0.312], [64554.6, 1.241], [64554.7, 0.047], [64554.8, 0.003], [64554.9, 0.003], [64555.0, 0.003], [64555.1, 0.0], [64555.2, 1.111], [64555.3, 0.0], [64555.4, 0.001], [64556.5, 0.004], [64556.9, 0.002], [64560.7, 0.002], [64563.2, 0.168], [64566.3, 0.002], [64568.6, 0.001], [64570.1, 0.06], [64570.5, 0.646], [64570.6, 1.735], [64572.6, 0.234], [64572.7, 0.004], [64573.3, 0.085], [64573.7, 0.085], [64573.8, 0.062], [64573.9, 0.003], [64574.0, 0.019], [64574.1, 0.087], [64574.2, 0.01], [64574.3, 0.07], [64574.4, 0.003], [64574.5, 0.084], [64574.6, 0.002], [64574.9, 0.005], [64575.3, 0.002], [64575.4, 0.004], [64575.5, 0.529], [64575.6, 0.032], [64575.9, 0.034], [64576.3, 0.397], [64576.7, 0.007], [64579.1, 0.003], [64579.3, 0.987]], "asks": [[64580.6, 46.012], [64582.9, 0.31], [64586.8, 0.002], [64587.0, 0.698], [64587.1, 0.003], [64587.4, 0.084], [64587.6, 0.833], [64587.7, 2.322], [64588.1, 0.0], [64588.3, 2.334], [64588.5, 0.011], [64588.6, 0.014], [64588.7, 0.137], [64588.8, 0.013], [64588.9, 0.002], [64589.0, 0.002], [64589.1, 0.009], [64589.2, 0.001], [64589.3, 0.0], [64589.5, 1.049], [64593.1, 1.209], [64604.4, 0.112], [64604.7, 0.139], [64604.8, 0.014], [64605.0, 0.145], [64605.1, 0.311], [64605.4, 0.82], [64605.8, 0.001], [64606.1, 0.314], [64606.6, 0.001], [64607.0, 0.006], [64607.6, 0.052], [64607.7, 0.024], [64607.8, 0.002], [64607.9, 0.13], [64608.0, 0.459], [64608.1, 0.061], [64608.2, 0.0], [64608.3, 0.017], [64608.4, 1.239], [64608.5, 0.105], [64608.9, 2.528], [64618.7, 0.061], [64622.1, 0.088], [64622.4, 1.165], [64622.7, 0.083], [64622.8, 0.0], [64623.1, 3.559], [64623.4, 0.0], [64627.6, 0.01], [64628.0, 2.59], [64650.1, 1.494], [64660.7, 0.07], [64669.8, 1.187], [64688.6, 0.828], [64719.0, 3.175], [64722.3, 1.47], [65226.4, 2.984], [65387.9, 19.456], [65549.3, 19.77], [65580.6, 0.03]]}
{"kind": "depth", "E": 1787089954977, "U": 11316022866676, "u": 11316022871755, "recv_ms": 1787089954931, "bids": [[1000.0, 35.76], [14280.5, 0.322], [14380.5, 3.654], [14480.5, 0.224], [58122.4, 0.004], [61997.2, 0.0], [63934.7, 5.602], [64470.7, 3.019], [64485.0, 2.34], [64499.7, 0.015], [64500.4, 0.001], [64501.9, 28.936], [64504.1, 0.035], [64537.4, 0.326], [64547.5, 0.028], [64561.1, 1.49], [64563.7, 0.003], [64566.3, 0.087], [64570.0, 0.004], [64570.1, 0.052], [64570.5, 0.012], [64570.6, 1.727], [64572.9, 1.622], [64573.0, 2.21], [64573.7, 0.155], [64574.0, 0.089], [64574.2, 0.11], [64574.3, 0.17], [64574.4, 0.103], [64574.5, 0.154], [64575.5, 1.055], [64579.2, 1.586]], "asks": [[64587.5, 0.023], [64588.5, 0.158], [64588.6, 0.264], [64588.8, 0.503], [64589.0, 0.142], [64589.1, 0.001], [64589.3, 0.147], [64596.1, 0.002], [64596.4, 0.0], [64597.7, 0.544], [64602.8, 10.002], [64606.5, 0.277], [64607.7, 0.171], [64607.8, 0.252], [64608.0, 0.679], [64608.2, 0.14], [64608.5, 0.252], [64612.9, 0.021], [64657.9, 39.355], [64659.7, 0.019], [64660.1, 0.013], [65226.4, 2.984], [65362.9, 6.112], [65387.9, 18.885]]}
{"kind": "depth", "E": 1787089955079, "U": 11316022871909, "u": 11316022877954, "recv_ms": 1787089955030, "bids": [[14280.5, 0.56], [14380.5, 3.542], [14480.5, 0.098], [51664.0, 0.004], [58122.4, 0.004], [61351.4, 0.03], [61351.5, 2.449], [61351.6, 0.01], [61997.2, 0.003], [63580.5, 0.006], [63599.5, 5.553], [63631.8, 2.37], [63665.3, 0.188], [63708.7, 18.072], [63934.7, 5.602], [64257.6, 6.964], [64260.5, 6.649], [64294.1, 3.056], [64315.4, 3.041], [64335.3, 5.486], [64355.1, 5.522], [64373.1, 0.428], [64393.0, 4.379], [64418.1, 3.967], [64422.1, 0.0], [64438.0, 2.183], [64439.0, 0.034], [64458.3, 4.788], [64531.3, 6.069], [64539.6, 0.034], [64561.1, 1.493], [64563.2, 0.044], [64563.4, 0.231], [64566.3, 0.087], [64568.4, 1.041], [64568.9, 0.085], [64570.7, 0.007], [64573.0, 2.202], [64573.8, 0.132], [64573.9, 0.073], [64574.0, 0.159], [64574.1, 0.187], [64574.2, 0.21], [64574.6, 0.102], [64575.0, 0.19], [64576.6, 1.813], [64576.7, 0.015], [64580.5, 3.71]], "asks": [[64580.6, 46.012], [64584.5, 0.135], [64588.0, 0.086], [64588.4, 0.261], [64588.8, 0.753], [64588.9, 0.272], [64589.0, 0.289], [64589.2, 0.281], [64605.7, 0.849], [64606.1, 0.574], [64608.0, 0.929], [64608.1, 0.331], [64608.3, 0.164], [64608.4, 1.519], [64623.4, 0.064], [64625.9, 0.003], [64657.9, 0.029], [64660.1, 39.339], [64664.5, 3.808], [64695.2, 3.703], [64720.3, 0.0], [64737.3, 0.001], [64737.5, 0.7], [65226.4, 2.984], [65495.9, 0.002], [65504.3, 3.811], [65561.7, 0.031], [65580.6, 0.01]]}
{"kind": "depth", "E": 1787089955181, "U": 11316022877975, "u": 11316022883651, "recv_ms": 1787089955134, "bids": [[1000.0, 35.76], [14280.5, 0.812], [14380.5, 3.388], [14480.5, 0.0], [51664.0, 0.0], [58122.4, 0.004], [61351.4, 0.03], [61997.2, 0.0], [63599.5, 5.561], [63664.1, 0.008], [63665.3, 0.196], [63805.5, 69.208], [63934.7, 5.602], [63954.7, 0.781], [64165.7, 0.748], [64188.1, 1.298], [64207.6, 7.441], [64229.4, 2.483], [64422.1, 5.317], [64439.0, 4.073], [64494.4, 3.196], [64501.0, 0.409], [64501.1, 3.578], [64504.8, 0.208], [64508.2, 0.003], [64508.3, 0.106], [64522.6, 0.148], [64522.9, 0.032], [64528.4, 0.018], [64531.2, 0.009], [64531.3, 6.067], [64536.4, 0.076], [64536.5, 0.68], [64539.9, 0.033], [64540.9, 1.288], [64561.4, 0.01], [64561.5, 0.054], [64561.8, 0.001], [64562.2, 0.009], [64563.4, 0.107], [64563.9, 0.004], [64564.2, 0.037], [64564.9, 0.125], [64566.3, 0.087], [64570.0, 0.097], [64570.5, 0.012], [64570.6, 0.0], [64572.6, 0.002], [64573.0, 0.344], [64573.1, 2.092], [64573.9, 0.143], [64574.5, 0.254], [64574.7, 0.071], [64575.3, 0.034], [64576.3, 0.429], [64580.5, 3.714]], "asks": [[64580.6, 46.012], [64584.7, 0.085], [64586.7, 0.076], [64587.7, 2.396], [64588.3, 2.495], [64588.5, 0.438], [64589.1, 0.155], [64601.3, 0.014], [64601.9, 0.558], [64604.4, 0.186], [64605.4, 0.894], [64606.8, 0.121], [64607.5, 0.164], [64607.8, 0.532], [64608.3, 0.318], [64616.3, 0.002], [64623.1, 3.633], [64657.9, 39.355], [64660.1, 0.013], [64720.3, 5.408], [64737.3, 10.428], [64768.0, 3.54], [64799.9, 3.567], [64817.8, 0.292], [64849.9, 3.928], [64879.9, 1.298], [64897.4, 0.642], [64926.9, 1.773], [64944.9, 0.455], [64976.9, 1.574], [64999.9, 17.674], [65018.5, 1.169], [65226.4, 2.984], [65355.6, 66.333], [65497.1, 0.004], [65556.7, 3.048]]}
{"kind": "depth", "E": 1787089955385, "U": 11316022888927, "u": 11316022894358, "recv_ms": 1787089955337, "bids": [[14280.5, 1.54], [14380.5, 2.66], [58122.4, 0.004], [61351.4, 0.025], [63580.5, 0.006], [63934.7, 5.602], [63962.2, 8.391], [64257.6, 6.974], [64439.0, 4.051], [64521.9, 0.034], [64522.2, 0.032], [64554.5, 0.382], [64555.0, 0.103], [64555.2, 1.211], [64555.3, 0.07], [64556.5, 0.104], [64567.4, 0.311], [64574.1, 0.31], [64580.5, 3.715]], "asks": [[64588.1, 0.001], [64720.3, 5.408], [65226.4, 2.986], [65323.9, 8.385], [65580.6, 0.01], [65751.0, 0.786], [68228.8, 0.0], [71038.7, 0.002]]}
{"kind": "depth", "E": 1787089955487, "U": 11316022894392, "u": 11316022899962, "recv_ms": 1787089955440, "bids": [[1000.0, 35.76], [14280.5, 1.89], [14380.5, 2.31], [58122.4, 0.004], [61351.4, 0.024], [61997.2, 0.0], [63288.9, 5.223], [63314.5, 0.0], [63766.2, 0.794], [63773.2, 27.934], [63934.7, 5.602], [64439.0, 0.034], [64523.2, 1.137], [64554.6, 1.311], [64554.7, 0.117], [64554.8, 0.143], [64554.9, 0.103], [64556.9, 0.102], [64559.7, 0.0], [64560.3, 2.437], [64560.6, 0.001], [64561.2, 0.56], [64567.0, 0.409], [64567.6, 0.164], [64568.6, 0.31], [64569.2, 0.018], [64574.6, 0.105], [64574.9, 0.002]], "asks": [[64587.0, 1.007], [64588.3, 2.186], [64597.2, 0.66], [64598.6, 0.002], [64602.5, 0.003], [64603.1, 0.116], [64657.9, 0.029], [64659.7, 0.0], [64664.5, 43.134], [64720.3, 0.0], [65226.4, 2.984], [65323.9, 7.468], [65387.9, 18.657]]}
{"kind": "depth", "E": 1787089955589, "U": 11316022900052, "u": 11316022904892, "recv_ms": 1787089955541, "bids": [[1000.0, 35.76], [14280.5, 2.24], [14380.5, 1.96], [58122.4, 0.004], [60387.2, 0.004], [61351.4, 0.024], [61997.2, 0.003], [63775.2, 4.959], [63805.5, 70.773], [64422.1, 0.0], [64496.3, 0.165], [64554.7, 0.187], [64555.2, 1.311], [64555.5, 1.372]], "asks": [[64580.6, 46.012], [64660.1, 39.339], [64664.5, 3.808], [64737.3, 0.001], [65226.4, 2.984], [65323.9, 7.467], [68228.8, 0.076]]}
{"kind": "depth", "E": 1787089955691, "U": 11316022905022, "u": 11316022910046, "recv_ms": 1787089955643, "bids": [[14280.5, 2.604], [14380.5, 1.596], [51664.0, 0.0], [58122.4, 0.006], [61351.5, 2.447], [61351.6, 0.01], [61997.2, 0.0], [63580.5, 0.026], [63934.7, 5.602], [64257.6, 6.974]], "asks": [[65226.4, 2.984], [65323.9, 8.384], [65349.1, 8.253], [65580.6, 0.03]]}
{"kind": "depth", "E": 1787089955793, "U": 11316022910188, "u": 11316022915601, "recv_ms": 1787089955746, "bids": [[1000.0, 35.76], [14280.5, 2.954], [14380.5, 1.246], [51664.0, 0.0], [51664.4, 0.0], [58122.4, 0.004], [63418.1, 5.63], [63785.3, 0.0], [63934.7, 5.602], [64422.1, 5.284], [64439.0, 4.051], [64559.4, 0.116], [64560.3, 2.321], [64560.6, 0.559], [64561.2, 0.002], [64565.5, 0.0], [64565.7, 0.005], [64566.1, 0.0], [64566.5, 0.001], [64566.6, 1.145], [64573.0, 0.097], [64573.5, 0.234], [64577.0, 0.085]], "asks": [[64580.7, 0.02], [64595.9, 0.0], [64596.4, 0.0], [64597.1, 0.859], [64597.7, 0.002], [64597.9, 0.001], [64598.9, 0.943], [64599.0, 0.029], [64601.0, 0.0], [64601.9, 0.558], [64602.2, 0.058], [64603.1, 0.116], [64720.3, 5.408], [64737.3, 10.428], [65226.4, 2.984], [65323.9, 8.384], [65331.2, 0.822], [65452.4, 19.44]]}
{"kind": "depth", "E": 1787089955997, "U": 11316022922771, "u": 11316022929093, "recv_ms": 1787089955950, "bids": [[14280.5, 3.668], [14380.5, 0.532], [58122.4, 0.004], [61351.4, 0.024], [61997.2, 0.0], [63698.0, 2.284], [63934.7, 5.602], [64257.6, 6.974], [64520.9, 2.668], [64521.0, 0.401], [64559.4, 0.0], [64560.6, 0.001], [64561.2, 0.118], [64561.3, 0.56], [64562.1, 2.161], [64562.3, 0.002], [64563.7, 0.003], [64569.5, 0.0], [64577.0, 0.001], [64580.5, 3.818]], "asks": [[64580.7, 0.104], [64596.1, 0.002], [64597.1, 0.317], [64597.7, 0.544], [64598.7, 3.497], [64598.9, 2.148], [64599.6, 0.093], [64600.3, 0.627], [64603.1, 0.0], [64603.9, 0.119], [64604.7, 0.082], [64605.7, 0.906], [64607.7, 0.79], [65226.4, 2.984], [65355.6, 65.111], [65452.4, 19.776]]}
{"kind": "depth", "E": 1787089956201, "U": 11316022937441, "u": 11316022946799, "recv_ms": 1787089956153, "bids": [[1000.0, 35.76], [14180.5, 0.378], [14280.5, 3.626], [14380.5, 0.196], [51664.0, 0.0], [58122.4, 0.004], [61351.5, 2.445], [61351.6, 0.012], [61997.2, 0.0], [63773.2, 28.051], [63934.7, 5.602], [64494.3, 0.031], [64495.3, 0.01], [64501.1, 3.579], [64501.9, 28.691], [64504.9, 0.001], [64508.2, 0.004], [64522.3, 0.003], [64528.4, 0.019], [64531.3, 6.068], [64536.5, 0.682]], "asks": [[64580.7, 0.02], [64585.1, 0.089], [64596.4, 0.0], [64597.1, 0.859], [64612.9, 0.021], [64638.8, 0.0], [65226.4, 2.984], [65291.0, 12.426], [65420.3, 2.44]]}
{"kind": "depth", "E": 1787089956303, "U": 11316022946836, "u": 11316022953945, "recv_ms": 1787089956256, "bids": [[14180.5, 0.616], [14280.5, 3.514], [14380.5, 0.07], [51664.0, 0.0], [58122.4, 0.004], [61351.4, 0.024], [61351.6, 0.01], [63288.9, 5.22], [63482.6, 18.45], [63580.5, 0.006], [63708.7, 18.855], [63732.8, 0.0], [63934.7, 5.602], [64257.6, 6.974], [64439.0, 4.016], [64461.9, 3.934], [64471.4, 0.003], [64474.3, 2.336], [64495.3, 28.7], [64496.3, 0.164], [64501.9, 0.001], [64504.1, 0.035], [64509.4, 0.051], [64528.4, 0.02], [64547.0, 0.026], [64547.1, 10.0], [64547.6, 0.019], [64547.7, 0.004], [64547.8, 0.001], [64551.1, 0.0], [64551.2, 0.003], [64551.3, 2.32], [64562.1, 1.542], [64567.4, 0.31], [64571.3, 0.001], [64571.6, 0.005], [64577.0, 0.001], [64577.6, 0.001], [64578.2, 0.002], [64580.5, 3.475]], "asks": [[64580.6, 46.095], [64585.1, 0.088], [64588.1, 0.0], [64600.3, 0.008], [64607.7, 0.171], [64651.6, 0.36], [64657.9, 0.029], [64660.0, 0.044], [64660.1, 0.013], [64664.5, 42.667], [64687.8, 2.323], [64695.2, 3.615], [64719.9, 3.871], [64720.3, 5.408], [64721.1, 0.008], [64903.6, 0.0], [65226.4, 2.984], [65323.9, 7.467], [65355.6, 66.333], [65580.6, 0.01], [65872.2, 7.595], [104929.0, 0.0]]}
{"kind": "depth", "E": 1787089956405, "U": 11316022954012, "u": 11316022959095, "recv_ms": 1787089956359, "bids": [[1000.0, 35.76], [14180.5, 0.896], [14280.5, 3.304], [14380.5, 0.0], [58122.4, 0.004], [61997.2, 0.003], [63288.9, 5.223], [63624.1, 0.007], [63689.5, 0.005], [63934.7, 5.602], [64063.9, 10.784], [64257.5, 0.003], [64453.5, 0.088], [64456.0, 4.573]], "asks": [[64580.6, 46.104], [64592.1, 0.021], [64600.1, 0.008], [64695.9, 0.087], [65226.4, 2.984], [65291.2, 0.63], [65323.9, 8.384]]}
{"kind": "depth", "E": 1787089956507, "U": 11316022959352, "u": 11316022965574, "recv_ms": 1787089956459, "bids": [[1000.0, 35.76], [14180.5, 1.26], [14280.5, 2.94], [51664.4, 0.002], [58122.4, 0.004], [61997.2, 0.0], [63695.7, 6.261], [63708.5, 1.97], [63934.7, 5.602], [64495.3, 0.01], [64501.9, 0.001], [64504.1, 28.725], [64560.3, 2.437], [64561.2, 0.002], [64573.3, 0.085], [64573.9, 0.375]], "asks": [[64603.1, 0.116], [64603.9, 0.003], [64657.9, 38.888], [64664.5, 3.808], [65226.4, 2.984], [65323.9, 9.301], [65362.8, 5.367], [65427.4, 3.833], [65517.0, 41.938]]}
{"kind": "depth", "E": 1787089956609, "U": 11316022966086, "u": 11316022972742, "recv_ms": 1787089956561, "bids": [[14180.5, 1.624], [14280.5, 2.576], [51664.0, 0.0], [51664.4, 0.0], [58122.4, 0.004], [61997.2, 0.003], [63580.5, 0.026], [63697.0, 1.259], [63793.2, 8.296], [63934.7, 5.604], [64257.6, 6.974], [64439.0, 0.034], [64574.9, 0.005]], "asks": [[64720.3, 0.0], [64903.5, 4.77], [65226.4, 2.984], [65355.6, 65.646], [65363.5, 1.59], [65580.6, 0.03], [104929.0, 0.236]]}
{"kind": "depth", "E": 1787089956711, "U": 11316022972752, "u": 11316022978688, "recv_ms": 1787089956664, "bids": [[1000.0, 35.76], [14180.5, 1.974], [14280.5, 2.226], [58122.4, 0.004], [61351.4, 0.024], [61997.2, 0.0], [63631.2, 26.27], [63708.7, 19.481], [63741.0, 22.286], [63934.7, 5.602], [64383.3, 9.268], [64422.1, 5.362], [64439.0, 4.09], [64471.3, 0.003], [64481.1, 10.663], [64481.2, 0.006], [64553.0, 0.0], [64560.4, 0.487], [64567.1, 0.065], [64575.6, 2.351], [64575.8, 0.17], [64577.1, 0.192], [64577.6, 0.002], [64578.2, 0.001], [64580.5, 3.62]], "asks": [[64580.6, 46.007], [64609.4, 0.003], [64609.5, 0.014], [64609.6, 7.132], [64612.4, 0.003], [64612.5, 0.002], [64612.6, 0.002], [64613.3, 0.002], [64613.4, 0.095], [64613.5, 0.161], [64615.4, 0.031], [64615.5, 0.003], [64615.6, 0.003], [64720.3, 5.408], [64771.7, 0.001], [64771.8, 0.004], [65226.4, 2.984], [65331.2, 0.058], [65387.9, 19.0], [65420.1, 23.36]]}
{"kind": "depth", "E": 1787089956813, "U": 11316022978750, "u": 11316022985335, "recv_ms": 1787089956765, "bids": [[1000.0, 35.76], [14180.5, 2.324], [14280.5, 1.876], [51664.4, 0.0], [58122.4, 0.004], [61351.4, 0.025], [63482.6, 18.058], [63580.5, 0.006], [63805.5, 72.557], [63934.7, 5.602], [64439.0, 4.05], [64510.7, 0.009], [64547.1, 0.0], [64552.0, 3.023], [64556.8, 0.007], [64559.4, 0.116], [64560.3, 2.321], [64560.6, 0.559], [64561.3, 0.002], [64562.2, 0.001], [64563.2, 0.052], [64564.9, 0.001], [64565.5, 0.927], [64565.9, 0.163], [64566.1, 0.0], [64566.3, 0.002], [64566.4, 0.024], [64566.6, 0.218], [64570.5, 0.012], [64570.6, 0.634], [64572.7, 0.002], [64572.9, 0.011], [64573.0, 0.013], [64574.6, 0.102], [64575.0, 0.193], [64575.5, 0.003], [64575.7, 1.13], [64575.8, 0.17], [64576.1, 0.005], [64576.7, 1.571], [64577.5, 0.085], [64579.2, 1.587], [64579.4, 0.002], [64580.5, 3.998]], "asks": [[64580.6, 45.901], [64581.0, 0.016], [64581.2, 0.0], [64584.0, 0.355], [64587.0, 0.698], [64587.8, 0.309], [64592.3, 0.018], [64593.0, 0.011], [64595.9, 0.0], [64596.4, 0.542], [64597.1, 0.317], [64601.0, 0.557], [64601.9, 0.001], [64602.2, 0.174], [64602.7, 2.584], [64602.8, 0.002], [64603.1, 0.0], [64604.1, 0.057], [64605.7, 0.849], [64607.3, 2.001], [64645.2, 0.372], [64720.3, 5.408], [65149.2, 2.299], [65226.4, 2.984], [65387.9, 19.228], [65407.5, 6.032], [65427.3, 0.766], [65580.6, 0.01], [65613.9, 16.103], [65872.2, 7.592]]}
{"kind": "depth", "E": 1787089956915, "U": 11316022985346, "u": 11316022991162, "recv_ms": 1787089956868, "bids": [[14180.5, 2.688], [14280.5, 1.512], [58122.4, 0.004], [61351.4, 0.025], [61997.2, 0.003], [63698.0, 1.658], [63934.7, 5.602], [64257.6, 6.964], [64453.5, 0.002], [64454.0, 3.338], [64476.4, 3.882], [64498.3, 2.066], [64517.8, 1.617], [64536.1, 0.882], [64555.6, 1.368], [64562.5, 0.002], [64563.2, 0.052], [64565.5, 0.0], [64566.3, 0.636], [64566.6, 1.145], [64570.6, 0.0], [64576.7, 1.563], [64578.0, 0.013], [64579.4, 0.002], [64580.5, 4.306]], "asks": [[64580.6, 45.902], [64583.0, 0.084], [64584.1, 0.472], [64596.4, 0.0], [64597.1, 0.859], [64598.6, 0.002], [64599.0, 0.956], [64601.0, 0.0], [64601.9, 0.558], [64602.2, 0.058], [64602.7, 0.628], [64603.2, 1.241], [64604.1, 0.0], [64605.1, 0.368], [64625.5, 0.878], [64632.3, 0.172], [64643.9, 3.489], [64650.4, 0.036], [64658.1, 0.015], [64662.8, 3.323], [64685.6, 2.52], [64714.8, 2.896], [64737.2, 2.505], [64737.5, 0.001], [64755.2, 2.091], [64780.1, 4.227], [64801.5, 0.448], [64819.9, 1.949], [64839.3, 1.499], [64858.5, 1.027], [64880.9, 0.117], [64899.9, 5.531], [64903.5, 4.924], [65226.4, 2.984], [65355.6, 66.333], [65420.1, 23.665], [65472.1, 18.454], [65750.3, 0.759]]}
{"kind": "depth", "E": 1787089957017, "U": 11316022991288, "u": 11316022996526, "recv_ms": 1787089956969, "bids": [[1000.0, 35.76], [14180.5, 3.038], [14280.5, 1.162], [58122.4, 0.004], [61351.4, 0.024], [61997.2, 0.0], [63482.6, 18.45], [63580.5, 0.026], [63812.0, 5.835], [63934.7, 5.602], [64534.0, 0.001], [64560.3, 2.94], [64562.5, 0.01], [64563.2, 0.044], [64563.7, 0.003], [64566.3, 0.551], [64567.7, 0.624], [64570.5, 0.097], [64579.4, 0.002]], "asks": [[64580.6, 45.901], [64596.1, 0.002], [64598.5, 0.621], [64605.9, 3.022], [64642.6, 0.022], [64650.4, 0.027], [64919.9, 0.548], [64938.5, 6.272], [64959.9, 11.49], [64988.4, 13.837], [65009.9, 1.857], [65027.9, 0.211], [65161.8, 18.431], [65226.4, 2.984], [65395.6, 1.531], [65420.1, 25.954], [65425.7, 0.267], [65580.6, 0.03]]}
{"kind": "depth", "E": 1787089957119, "U": 11316022996626, "u": 11316023003452, "recv_ms": 1787089957070, "bids": [[1000.0, 35.76], [14180.5, 3.402], [14280.5, 0.798], [58122.4, 0.004], [61351.4, 0.024], [61997.2, 0.003], [63314.6, 4.056], [63708.7, 20.107], [63934.7, 5.602], [64257.6, 6.974], [64501.2, 0.149], [64503.0, 0.041], [64508.2, 0.005], [64531.4, 0.001], [64560.6, 0.001], [64561.2, 0.56], [64562.2, 0.001], [64566.3, 0.636], [64567.7, 0.005], [64568.9, 0.085], [64570.5, 0.012], [64576.1, 0.002], [64579.4, 0.012], [64580.5, 4.307]], "asks": [[64580.6, 46.003], [64581.5, 0.12], [64582.1, 0.03], [64585.2, 0.004], [64588.0, 0.087], [64596.4, 0.0], [64597.1, 0.859], [64597.7, 0.002], [64599.0, 0.029], [64599.6, 1.02], [64605.1, 0.311], [64605.7, 0.906], [64627.1, 0.058], [64638.8, 0.003], [64776.0, 18.897], [64776.1, 0.002], [65226.4, 2.984], [65484.7, 86.907], [65522.6, 0.004], [65613.9, 17.168]]}
{"kind": "depth", "E": 1787089957221, "U": 11316023003579, "u": 11316023009236, "recv_ms": 1787089957177, "bids": [[14080.5, 0.028], [14180.5, 3.71], [14280.5, 0.462], [51664.0, 0.002], [58122.4, 0.004], [61351.4, 0.018], [63288.9, 5.226], [63502.6, 0.0], [63580.5, 0.006], [63934.7, 5.602], [64156.8, 0.881], [64175.3, 0.752], [64193.2, 0.703], [64213.9, 0.498], [64235.1, 0.746], [64257.6, 6.819], [64257.7, 1.182], [64277.1, 4.181], [64313.0, 0.833], [64339.1, 3.861], [64358.1, 2.372], [64374.8, 4.377], [64406.2, 3.028], [64431.8, 3.907], [64439.0, 0.034], [64528.5, 0.015], [64579.4, 0.002]], "asks": [[64580.6, 46.005], [64588.0, 0.086], [64720.3, 0.0], [64775.9, 0.098], [64780.1, 4.371], [64803.7, 0.008], [65226.4, 2.984], [65387.9, 19.456], [65428.0, 0.799], [65580.6, 0.01]]}
{"kind": "depth", "E": 1787089957323, "U": 11316023009304, "u": 11316023014907, "recv_ms": 1787089957276, "bids": [[1000.0, 35.76], [14080.5, 0.196], [14180.5, 3.724], [14280.5, 0.28], [51664.0, 0.0], [58122.4, 0.004], [61351.4, 0.018], [61997.2, 0.0], [63805.5, 73.34], [63812.0, 5.835], [63868.1, 0.0], [63934.7, 5.602], [64259.3, 0.108], [64416.1, 0.001], [64417.7, 0.071], [64422.1, 5.493], [64439.0, 4.163], [64486.0, 0.071], [64489.8, 1.058], [64533.1, 0.02], [64544.8, 0.001], [64551.9, 0.019], [64559.1, 0.004], [64561.0, 0.001], [64562.5, 0.002], [64563.2, 0.052], [64563.4, 0.099], [64564.3, 0.009], [64576.8, 0.002], [64580.5, 4.362]], "asks": [[64580.6, 46.005], [64585.2, 0.003], [64589.9, 0.001], [64591.3, 1.698], [64593.9, 0.212], [64596.9, 0.008], [64602.2, 0.04], [64603.7, 0.02], [64618.7, 0.079], [64620.6, 0.041], [64668.9, 0.042], [64674.3, 0.182], [64720.3, 5.408], [64737.2, 0.249], [64737.3, 10.428], [64752.6, 0.069], [64752.9, 0.006], [64776.0, 18.848], [64911.0, 0.2], [64912.8, 0.109], [65226.4, 2.984], [65517.0, 40.871], [65529.9, 22.689], [65581.6, 30.865], [66676.5, 0.299]]}
{"kind": "depth", "E": 1787089957425, "U": 11316023015026, "u": 11316023019737, "recv_ms": 1787089957377, "bids": [[1000.0, 35.76], [14080.5, 0.448], [14180.5, 3.584], [14280.5, 0.168], [51664.0, 0.0], [58122.4, 0.004], [61997.2, 0.003], [63580.5, 0.026], [63812.0, 6.774], [63934.7, 5.602], [64257.5, 0.001], [64257.6, 6.974], [64454.2, 2.486], [64562.5, 0.01], [64563.2, 0.044]], "asks": [[64596.7, 0.03], [64597.4, 0.007], [65226.4, 2.984], [65349.0, 2.974], [65580.6, 0.03], [71038.7, 0.002]]}
{"kind": "depth", "E": 1787089957527, "U": 11316023019841, "u": 11316023025059, "recv_ms": 1787089957479, "bids": [[14080.5, 0.672], [14180.5, 3.486], [14280.5, 0.042], [58122.4, 0.004], [61351.4, 0.018], [61351.5, 2.443], [61351.6, 0.014], [61997.2, 0.0], [63514.9, 7.693], [63798.5, 2.349], [63934.7, 5.604], [64383.3, 3.495], [64422.1, 3.182], [64439.0, 2.408], [64503.0, 0.038], [64517.7, 0.019], [64517.8, 0.014], [64522.3, 0.003], [64559.4, 0.0], [64560.3, 3.056], [64576.8, 0.012], [64580.5, 4.356]], "asks": [[64580.6, 46.02], [64588.0, 0.087], [64597.1, 0.317], [64597.2, 0.041], [64597.7, 0.544], [64598.0, 0.625], [64612.9, 0.021], [64638.8, 0.0], [64643.4, 0.093], [64650.4, 0.036], [64720.3, 5.131], [64737.3, 10.428], [64776.0, 22.859], [64903.6, 0.002], [65226.4, 2.984], [65330.5, 0.764], [65517.0, 41.938], [65549.4, 0.0], [65581.6, 31.931]]}
{"kind": "depth", "E": 1787089957629, "U": 11316023025084, "u": 11316023029735, "recv_ms": 1787089957581, "bids": [[1000.0, 35.76], [14080.5, 0.98], [14180.5, 3.22], [14280.5, 0.0], [58122.4, 0.004], [61997.2, 0.003], [63580.5, 0.006], [63720.7, 0.057], [63812.0, 5.835], [63934.7, 5.602], [64504.1, 0.035], [64508.5, 30.382], [64576.8, 0.002]], "asks": [[64580.6, 46.02], [64588.0, 0.087], [65226.4, 2.984], [65387.9, 19.228], [65420.2, 8.016], [65517.0, 40.871], [65549.5, 0.686], [65580.6, 0.01], [65693.9, 0.001], [65872.2, 7.595], [66683.6, 0.135]]}
{"kind": "depth", "E": 1787089957731, "U": 11316023029824, "u": 11316023033808, "recv_ms": 1787089957683, "bids": [[14080.5, 1.344], [14180.5, 2.856], [58122.4, 0.004], [63288.9, 5.223], [63663.5, 3.54], [63812.0, 6.774], [63934.7, 5.602], [64257.6, 6.974], [64383.3, 9.452], [64422.1, 5.631], [64439.0, 4.236], [64499.7, 28.591], [64508.5, 1.806], [64517.7, 4.076], [64559.4, 0.116], [64560.3, 2.94], [64560.6, 0.001], [64561.2, 0.002], [64561.6, 1.134], [64565.5, 0.0], [64566.5, 0.928], [64566.6, 0.218]], "asks": [[64595.9, 0.0], [64597.7, 0.544], [64598.0, 0.625], [64598.9, 3.075], [64599.6, 0.093], [64602.2, 0.04], [64603.1, 0.116], [64603.2, 1.125], [64604.1, 0.0], [64605.0, 0.202], [64605.7, 0.849], [64643.4, 2.315], [64650.4, 0.027], [64776.0, 18.469], [64781.0, 15.572], [65226.4, 2.984], [65349.1, 10.087], [65387.9, 19.0], [65420.1, 25.649], [65517.0, 41.938], [65975.6, 0.005], [71038.7, 0.002]]}
{"kind": "depth", "E": 1787089957833, "U": 11316023033910, "u": 11316023040493, "recv_ms": 1787089957784, "bids": [[14080.5, 1.694], [14180.5, 2.506], [51664.0, 0.0], [51664.4, 0.0], [58122.4, 0.004], [61351.4, 0.012], [61997.2, 0.0], [63580.5, 0.026], [63934.7, 5.602], [64499.7, 0.015], [64506.3, 28.607]], "asks": [[64625.7, 0.498], [65226.4, 2.984], [65420.3, 2.745], [65580.6, 0.03]]}
{"kind": "depth", "E": 1787089958037, "U": 11316023046229, "u": 11316023052927, "recv_ms": 1787089957988, "bids": [[14080.5, 2.422], [14180.5, 1.778], [58122.4, 0.004], [61351.4, 0.012], [61997.2, 0.0], [63288.9, 5.226], [63580.5, 0.006], [63934.7, 5.602], [64257.6, 6.974], [64422.1, 4.618], [64439.0, 3.691], [64444.2, 2.631], [64463.4, 2.832], [64481.2, 4.565], [64563.7, 0.003], [64568.9, 0.09], [64576.8, 0.01], [64577.5, 0.001], [64578.0, 0.005]], "asks": [[64580.6, 46.021], [64581.0, 0.1], [64588.0, 0.086], [64596.1, 0.002], [64596.4, 0.542], [64597.7, 0.002], [64598.9, 2.148], [64599.6, 1.02], [64601.9, 0.001], [64602.5, 0.56], [64605.0, 0.145], [64605.7, 0.906], [64605.8, 1.537], [64630.5, 2.309], [64640.1, 0.009], [64657.8, 5.894], [64676.4, 2.52], [64694.7, 1.955], [64720.2, 1.472], [64720.3, 5.408], [64737.3, 10.428], [64749.9, 1.169], [64780.9, 3.632], [64803.7, 8.39], [64833.5, 1.338], [64851.3, 6.477], [64871.1, 0.294], [64889.9, 0.411], [64913.1, 1.454], [65000.0, 116.993], [65226.4, 2.984], [65580.6, 0.01]]}
{"kind": "depth", "E": 1787089958139, "U": 11316023053036, "u": 11316023059761, "recv_ms": 1787089958091, "bids": [[14080.5, 2.772], [14180.5, 1.428], [51664.0, 0.0], [58122.4, 0.004], [61351.4, 0.012], [63812.0, 7.713], [63934.7, 5.602], [64063.9, 6.888], [64495.3, 28.38], [64501.1, 3.578], [64501.2, 0.148], [64504.9, 0.0], [64508.3, 0.108], [64508.5, 1.806], [64528.4, 0.018], [64528.5, 0.014], [64531.2, 0.01], [64531.3, 6.067], [64531.4, 0.0], [64536.5, 0.68], [64566.3, 0.002], [64567.7, 0.624], [64568.9, 0.085], [64570.5, 0.646]], "asks": [[64580.6, 46.021], [64585.1, 0.089], [64596.4, 0.0], [64597.7, 0.544], [65226.4, 2.984]]}
{"kind": "depth", "E": 1787089958241, "U": 11316023059909, "u": 11316023065069, "recv_ms": 1787089958193, "bids": [[1000.0, 35.76], [14080.5, 3.122], [14180.5, 1.078], [51664.0, 0.0], [58122.4, 0.004], [61997.2, 0.003], [63349.0, 0.001], [63580.5, 0.026], [63676.4, 65.677], [63934.7, 5.602], [64439.0, 3.077], [64495.3, 0.01], [64501.0, 4.914], [64504.1, 0.035], [64508.5, 30.176], [64531.2, 0.011], [64580.5, 4.361]], "asks": [[64580.6, 46.02], [64588.0, 0.087], [64720.2, 0.0], [64720.3, 5.408], [65226.4, 2.986], [65580.6, 0.03], [65872.2, 7.592]]}
{"kind": "depth", "E": 1787089958343, "U": 11316023065147, "u": 11316023073005, "recv_ms": 1787089958295, "bids": [[14080.5, 3.486], [14180.5, 0.714], [51664.0, 0.0], [58122.4, 0.004], [61351.4, 0.012], [61997.2, 0.0], [63773.2, 27.934], [63934.7, 5.602], [64063.9, 10.784], [64257.6, 6.964], [64383.3, 7.409], [64439.0, 3.803], [64575.7, 1.133], [64577.6, 0.086]], "asks": [[64580.6, 46.015], [64581.0, 0.016], [64585.1, 0.088], [64609.4, 0.001], [64609.5, 0.012], [64609.6, 7.13], [64612.4, 0.001], [64612.5, 0.0], [64612.6, 0.0], [64613.3, 0.0], [64613.4, 0.093], [64613.5, 0.159], [64615.4, 0.029], [64615.5, 0.001], [64615.6, 0.001], [65226.4, 2.984], [65362.8, 6.131], [65568.9, 2.585]]}
{"kind": "depth", "E": 1787089958547, "U": 11316023079594, "u": 11316023086427, "recv_ms": 1787089958499, "bids": [[1000.0, 35.76], [14080.5, 3.696], [14180.5, 0.252], [14480.5, 0.252], [58122.4, 0.004], [61997.2, 0.0], [63676.4, 66.147], [63934.7, 5.602], [64503.0, 0.023], [64576.8, 0.002]], "asks": [[64593.6, 0.004], [64638.8, 0.003], [64903.5, 4.77], [64903.6, 0.0], [65420.1, 25.344]]}
{"kind": "depth", "E": 1787089958649, "U": 11316023086490, "u": 11316023091370, "recv_ms": 1787089958615, "bids": [[14080.5, 3.57], [14180.5, 0.14], [14480.5, 0.49], [51664.0, 0.0], [58122.4, 0.004], [61351.4, 0.006], [63580.5, 0.026], [63663.5, 3.306], [63934.7, 5.602], [64257.5, 0.003], [64257.6, 6.964], [64422.1, 0.0], [64439.0, 0.034], [64515.9, 0.022], [64534.0, 0.029], [64576.8, 0.012], [64577.6, 0.002], [64579.4, 0.002]], "asks": [[64580.6, 46.015], [64627.1, 0.002], [64645.2, 0.371], [64720.3, 0.0], [64737.3, 0.001], [64903.5, 4.924], [65226.4, 2.984], [65226.5, 0.004], [65517.0, 40.871], [65529.9, 22.156], [65549.3, 19.77], [65580.6, 0.03], [65581.6, 32.997]]}
{"kind": "depth", "E": 1787089958751, "U": 11316023091443, "u": 11316023096619, "recv_ms": 1787089958703, "bids": [[1000.0, 35.76], [14080.5, 3.458], [14180.5, 0.014], [14480.5, 0.728], [58122.4, 0.004], [61351.4, 0.006], [61351.6, 0.012], [61997.2, 0.003], [63934.7, 5.602], [64422.0, 5.435], [64439.0, 4.123], [64470.7, 3.022], [64503.0, 0.02], [64522.3, 0.0], [64576.8, 0.02], [64577.1, 0.108], [64578.0, 0.005]], "asks": [[64580.6, 46.016], [64580.9, 0.142], [64588.0, 0.086], [64612.9, 0.021], [64638.8, 0.0], [64720.3, 5.408], [64737.3, 10.428], [65226.4, 2.984], [65355.6, 65.722], [65394.9, 1.541], [65420.3, 3.355], [65517.0, 41.938]]}
{"kind": "depth", "E": 1787089958853, "U": 11316023096688, "u": 11316023102804, "recv_ms": 1787089958804, "bids": [[1000.0, 35.76], [14080.5, 3.136], [14180.5, 0.0], [14480.5, 1.064], [51664.4, 0.0], [58122.4, 0.004], [61351.4, 0.006], [61997.2, 0.0], [63580.5, 0.006], [63611.8, 14.932], [63857.1, 0.015], [63934.7, 5.602], [64383.3, 1.271], [64422.0, 2.444], [64439.0, 2.01], [64454.2, 2.4], [64517.7, 4.082], [64563.9, 0.012], [64564.3, 0.001], [64570.6, 0.008], [64575.7, 1.13], [64576.7, 1.555], [64576.8, 0.02], [64579.4, 0.002]], "asks": [[64580.6, 46.015], [64588.0, 0.086], [64643.4, 2.304], [65226.4, 2.984], [65427.4, 4.596], [65517.0, 40.871], [65529.9, 22.689], [65580.6, 0.01]]}
{"kind": "depth", "E": 1787089959057, "U": 11316023108946, "u": 11316023114891, "recv_ms": 1787089959010, "bids": [[1000.0, 35.76], [14080.5, 2.422], [14480.5, 1.778], [58122.4, 0.004], [61351.4, 0.006], [61997.2, 0.0], [63580.5, 0.026], [63793.2, 6.73], [63870.0, 1.067], [63934.7, 5.602], [64438.1, 1.036], [64495.3, 0.01], [64496.3, 0.164], [64503.0, 0.029], [64508.5, 29.99], [64534.0, 0.015], [64536.5, 0.694], [64548.1, 0.001], [64549.4, 1.725], [64560.6, 0.559], [64561.6, 0.576], [64563.7, 0.001], [64565.8, 3.267], [64566.5, 0.001], [64568.9, 0.085], [64572.2, 0.086], [64572.6, 0.086], [64574.5, 0.259], [64575.0, 0.19], [64575.8, 0.086], [64576.3, 0.345], [64580.5, 3.527]], "asks": [[64580.6, 46.023], [64587.0, 1.007], [64587.8, 0.0], [64592.1, 0.029], [64593.0, 0.003], [64595.8, 0.621], [64595.9, 1.101], [64596.1, 0.0], [64596.4, 0.542], [64597.7, 0.002], [64598.0, 0.006], [64601.2, 0.584], [64602.5, 0.003], [64603.4, 10.002], [64619.0, 1.39], [64636.8, 1.625], [64640.1, 0.0], [64642.6, 0.013], [64645.2, 0.362], [64657.9, 0.029], [64659.8, 1.527], [64664.5, 41.527], [64683.5, 1.086], [64702.2, 0.989], [64720.2, 1.323], [64722.3, 0.47], [65226.4, 2.984], [65355.6, 66.333], [65387.9, 18.741], [65500.8, 1.098], [65580.6, 0.03], [65872.2, 7.589]]}
{"kind": "depth", "E": 1787089959159, "U": 11316023114906, "u": 11316023119205, "recv_ms": 1787089959111, "bids": [[1000.0, 35.76], [14080.5, 2.058], [14480.5, 2.142], [58122.4, 0.004], [61351.4, 0.006], [63288.9, 5.229], [63547.2, 8.773], [63599.5, 5.561], [63611.8, 15.323], [63644.1, 44.056], [63934.7, 5.602], [64162.7, 0.568], [64180.1, 0.633], [64200.1, 5.187], [64220.1, 0.824], [64245.9, 0.761], [64438.1, 0.036], [64501.0, 4.915], [64504.9, 0.001], [64508.3, 0.109], [64531.2, 0.012], [64536.4, 0.077], [64563.7, 0.003], [64579.9, 0.036], [64580.5, 3.635]], "asks": [[64580.6, 46.023], [64584.5, 0.116], [64586.8, 0.003], [64596.1, 0.002], [64607.3, 0.001], [64657.8, 0.0], [64657.9, 37.748], [64660.1, 0.013], [64664.5, 3.808], [64722.3, 1.47], [64743.7, 1.168], [64765.4, 0.816], [64784.9, 0.063], [64809.9, 0.483], [64831.8, 1.161], [64855.5, 0.982], [64874.5, 0.146], [64894.8, 0.26], [64915.5, 0.257], [64935.2, 0.625], [64954.9, 0.493], [64974.5, 0.147], [64993.6, 0.756], [65024.9, 0.34], [65226.4, 2.984], [65517.0, 41.938], [65523.5, 1.691], [65557.1, 0.77], [65561.7, 0.03]]}
{"kind": "depth", "E": 1787089959261, "U": 11316023119311, "u": 11316023125395, "recv_ms": 1787089959213, "bids": [[14080.5, 1.708], [14480.5, 2.492], [58122.4, 0.004], [61351.4, 0.006], [61997.2, 0.003], [63580.5, 0.006], [63805.5, 74.905], [63934.7, 5.602], [64257.6, 6.974], [64522.3, 0.003], [64528.3, 0.008], [64558.7, 0.619], [64561.3, 0.002], [64562.2, 0.009], [64562.5, 0.002], [64566.0, 0.744], [64568.2, 0.611], [64568.6, 0.001], [64575.6, 2.435], [64577.6, 0.001], [64578.2, 0.002], [64580.5, 3.436]], "asks": [[64580.6, 46.023], [64586.8, 0.002], [64587.5, 0.565], [64590.5, 0.095], [64591.1, 0.0], [64593.6, 0.007], [64596.9, 0.627], [64638.8, 0.003], [65132.2, 0.0], [65226.4, 2.984], [65349.1, 9.17], [65387.9, 18.741], [65517.0, 40.871], [65561.7, 0.039], [65580.6, 0.01], [65613.9, 16.102]]}
{"kind": "depth", "E": 1787089959363, "U": 11316023125411, "u": 11316023132233, "recv_ms": 1787089959316, "bids": [[1000.0, 35.76], [14080.5, 1.344], [14480.5, 2.856], [58122.4, 0.004], [61997.2, 0.0], [63288.9, 5.229], [63733.8, 4.546], [63934.7, 5.602], [64063.9, 10.473], [64455.5, 0.127], [64528.3, 0.009], [64576.2, 0.398]], "asks": [[64587.5, 0.023], [64590.5, 0.637], [64596.4, 0.0], [64596.8, 0.547], [64599.1, 0.32], [65097.2, 9.999], [65161.9, 14.705], [65226.4, 2.984], [65517.0, 40.985]]}
{"kind": "depth", "E": 1787089959465, "U": 11316023132345, "u": 11316023138768, "recv_ms": 1787089959418, "bids": [[1000.0, 35.76], [14080.5, 0.994], [14480.5, 3.206], [51664.0, 0.0], [58122.4, 0.004], [61351.5, 2.445], [61997.2, 0.003], [63469.5, 2.375], [63547.2, 9.873], [63580.5, 0.026], [63611.8, 14.97], [63644.1, 45.155], [63934.7, 5.602]], "asks": [[64584.5, 0.093], [65226.4, 2.984], [65349.1, 9.17], [65420.1, 25.039], [65517.0, 42.052], [65523.5, 2.071], [65580.6, 0.03], [65581.6, 31.932], [65613.9, 17.168], [65646.2, 3.378], [65975.7, 3.896]]}
{"kind": "depth", "E": 1787089959567, "U": 11316023138879, "u": 11316023144161, "recv_ms": 1787089959520, "bids": [[14080.5, 0.63], [14480.5, 3.57], [58122.4, 0.004], [63482.6, 19.236], [63611.8, 15.323], [63934.7, 5.602], [64063.9, 10.784], [64257.6, 6.964], [64439.0, 0.034]], "asks": [[64720.2, 0.0], [64720.3, 0.0], [65097.2, 10.306], [65226.4, 2.984], [65387.9, 18.969], [65568.9, 1.519]]}
{"kind": "depth", "E": 1787089959669, "U": 11316023144247, "u": 11316023149606, "recv_ms": 1787089959623, "bids": [[1000.0, 35.76], [14080.5, 0.364], [14380.5, 0.084], [14480.5, 3.752], [51664.0, 0.0], [58122.4, 0.004], [61351.4, 0.0], [61997.2, 0.0], [63580.5, 0.006], [63934.7, 5.604], [64257.5, 0.001], [64422.0, 5.301], [64439.0, 4.043], [64539.5, 0.001], [64547.5, 0.003], [64547.9, 0.026], [64557.2, 0.002], [64557.8, 0.0], [64558.7, 0.0], [64559.4, 0.0], [64560.1, 0.117], [64560.6, 0.001], [64561.0, 0.001], [64561.2, 0.56], [64561.3, 0.002], [64562.2, 0.009], [64565.8, 2.34], [64566.0, 0.125], [64566.1, 0.927], [64566.2, 0.693], [64566.3, 0.002], [64567.1, 0.065], [64567.2, 0.002], [64567.3, 0.546], [64571.5, 0.093], [64571.6, 0.002], [64571.9, 0.086], [64572.8, 2.328], [64573.4, 0.001], [64574.0, 0.161], [64574.2, 0.213], [64574.5, 0.17], [64575.2, 0.001], [64575.6, 2.351], [64576.0, 0.078], [64576.2, 0.314], [64576.3, 0.035], [64577.6, 0.002], [64578.2, 0.001], [64579.2, 1.586], [64580.5, 2.914]], "asks": [[64580.6, 46.023], [64583.6, 0.02], [64587.5, 0.023], [64590.4, 0.642], [64590.5, 0.01], [64596.2, 0.004], [64596.4, 0.0], [64596.8, 0.547], [64597.4, 0.005], [64597.7, 0.002], [64598.6, 0.002], [64599.5, 0.928], [64601.2, 0.027], [64602.3, 1.828], [64603.1, 0.0], [64603.8, 0.187], [64605.8, 0.001], [64605.9, 2.403], [64609.4, 0.003], [64609.5, 0.014], [64609.6, 7.132], [64612.4, 0.003], [64612.5, 0.002], [64612.6, 0.002], [64613.3, 0.002], [64613.4, 0.095], [64613.5, 0.161], [64615.4, 0.031], [64615.5, 0.003], [64615.6, 0.003], [64720.3, 5.408], [64737.3, 10.428], [64903.6, 0.002], [65226.4, 2.984], [65226.5, 0.003], [65349.1, 10.087], [65420.1, 25.344], [65472.1, 14.641], [65580.6, 0.01], [65613.9, 16.103], [65646.2, 4.443]]}
{"kind": "depth", "E": 1787089959771, "U": 11316023149672, "u": 11316023155286, "recv_ms": 1787089959725, "bids": [[1000.0, 35.76], [14080.5, 0.224], [14380.5, 0.308], [14480.5, 3.668], [58122.4, 0.004], [61997.2, 0.003], [63591.6, 0.0], [63934.7, 5.602], [64566.3, 0.544], [64567.3, 0.004], [64573.2, 0.002], [64573.7, 0.157], [64573.8, 0.364], [64573.9, 0.143], [64574.0, 0.159], [64574.4, 0.187], [64574.8, 0.098]], "asks": [[64598.3, 0.927], [64599.5, 0.001], [64656.5, 0.019], [65213.8, 0.542], [65226.4, 2.984], [65581.6, 31.931], [65613.9, 17.168], [65872.2, 7.586]]}
{"kind": "depth", "E": 1787089959873, "U": 11316023155434, "u": 11316023164656, "recv_ms": 1787089959828, "bids": [[14080.5, 0.112], [14380.5, 0.56], [14480.5, 3.528], [34000.0, 1.146], [51664.4, 0.0], [58122.4, 0.004], [61351.4, 0.0], [61997.2, 0.0], [63560.6, 1.284], [63579.5, 31.57], [63580.5, 0.026], [63644.1, 44.057], [63934.7, 5.602], [64257.6, 6.964], [64438.1, 0.036], [64455.5, 0.04], [64542.2, 0.093], [64543.7, 0.062], [64549.1, 0.001], [64549.2, 0.0], [64552.0, 1.025], [64552.1, 0.0], [64553.5, 0.013], [64556.1, 0.004], [64556.6, 0.049], [64557.2, 0.0], [64558.5, 0.053], [64559.4, 0.116], [64560.1, 0.001], [64562.2, 0.009], [64567.5, 0.03], [64571.4, 0.157], [64571.5, 0.009], [64571.9, 0.002], [64572.2, 0.002], [64572.6, 0.002], [64573.1, 0.234], [64573.3, 0.395], [64573.8, 0.132], [64575.2, 0.085], [64575.7, 1.214], [64576.4, 0.804], [64576.6, 2.039], [64576.7, 0.007], [64576.8, 0.086], [64578.0, 0.013], [64579.3, 0.002], [64580.4, 0.006], [64580.5, 3.628]], "asks": [[64580.6, 46.023], [64581.8, 0.007], [64581.9, 0.002], [64582.4, 0.003], [64585.6, 0.013], [64587.5, 0.657], [64588.2, 0.944], [64590.4, 0.015], [64590.5, 0.003], [64592.1, 0.001], [64592.5, 0.011], [64595.8, 0.002], [64596.2, 0.002], [64596.9, 0.008], [64597.3, 0.103], [64597.4, 0.624], [64597.6, 0.057], [64598.3, 0.0], [64598.8, 0.969], [64598.9, 2.148], [64600.7, 0.04], [64602.1, 0.207], [64603.0, 0.0], [64603.1, 0.116], [64603.4, 0.004], [64603.5, 10.014], [64603.8, 0.071], [64605.0, 0.096], [64606.7, 0.078], [64606.8, 0.001], [64613.5, 0.281], [64613.9, 0.0], [64656.5, 0.026], [64722.3, 1.47], [64767.9, 0.385], [65226.4, 2.984], [65580.6, 0.03], [65581.6, 32.997]]}
{"kind": "depth", "E": 1787089959975, "U": 11316023164677, "u": 11316023169409, "recv_ms": 1787089959928, "bids": [[1000.0, 35.76], [14080.5, 0.0], [14380.5, 0.798], [14480.5, 3.402], [58122.4, 0.004], [61351.4, 0.0], [61997.2, 0.003], [63934.7, 5.602], [64542.2, 0.023], [64546.6, 10.093], [64549.4, 1.795], [64552.1, 0.802], [64572.8, 2.329], [64573.1, 0.002], [64573.6, 0.233], [64576.0, 0.079], [64579.2, 1.587], [64580.5, 3.63]], "asks": [[64580.6, 46.024], [64583.7, 0.029], [64583.8, 0.101], [64584.2, 0.089], [64587.3, 0.543], [64587.4, 1.338], [64587.5, 0.115], [64587.6, 0.045], [64590.5, 0.003], [64591.1, 0.0], [64596.7, 0.03], [64596.8, 0.005], [64597.3, 0.645], [64597.7, 0.002], [65226.4, 5.28], [65342.9, 9.642], [65484.7, 90.719], [65581.6, 34.063]]}
{"kind": "depth", "E": 1787089960077, "U": 11316023169520, "u": 11316023175136, "recv_ms": 1787089960029, "bids": [[1000.0, 35.76], [14380.5, 1.148], [14480.5, 3.052], [58122.4, 0.004], [63288.9, 5.232], [63397.7, 0.788], [63580.5, 0.006], [63599.5, 5.543], [63934.7, 5.602], [64257.6, 6.809], [64281.1, 2.606], [64300.1, 15.498], [64324.9, 0.84], [64345.1, 2.85], [64363.0, 16.036], [64390.1, 1.087], [64422.1, 1.033], [64450.4, 2.507], [64469.4, 2.292], [64470.7, 3.019], [64488.1, 1.79], [64496.3, 0.165], [64503.0, 0.023], [64505.5, 0.313], [64508.6, 6.71], [64521.0, 0.373], [64522.3, 0.0], [64527.9, 1.511], [64531.1, 0.062], [64532.0, 0.065], [64534.0, 0.001], [64536.5, 0.68], [64562.2, 0.001], [64563.2, 0.052], [64563.5, 0.061], [64563.7, 0.001], [64564.6, 0.01], [64566.4, 0.658], [64567.0, 0.402], [64568.0, 0.013], [64568.9, 0.085], [64570.5, 0.012], [64570.6, 0.0], [64570.7, 0.007], [64573.0, 0.013], [64573.3, 0.311], [64573.7, 0.155], [64574.2, 0.21], [64575.3, 0.037], [64575.4, 0.007], [64575.5, 0.003], [64576.7, 1.563], [64576.8, 0.086], [64577.5, 0.085], [64577.8, 0.085], [64578.0, 0.013], [64579.1, 1.009], [64580.5, 4.444]], "asks": [[64580.6, 45.912], [64580.9, 0.058], [64581.4, 0.007], [64581.5, 0.036], [64582.1, 0.0], [64584.1, 0.502], [64584.2, 0.086], [64587.0, 0.698], [64587.3, 0.001], [64587.5, 0.023], [64588.1, 0.309], [64590.5, 0.003], [64591.7, 0.627], [64591.9, 0.007], [64592.5, 0.003], [64592.9, 0.013], [64593.1, 1.201], [64595.2, 0.183], [64596.1, 0.0], [64597.3, 0.643], [64597.6, 0.008], [64598.3, 0.002], [64602.8, 1.977], [64604.3, 0.491], [64612.9, 0.021], [64624.6, 0.037], [64627.1, 0.002], [64634.5, 0.081], [64635.4, 0.0], [64638.8, 0.0], [64640.1, 0.009], [64664.8, 0.003], [65226.4, 5.28], [65557.2, 0.0], [65561.7, 0.021], [65580.6, 0.01], [66292.8, 0.05], [67809.6, 0.009]]}
{"kind": "depth", "E": 1787089960179, "U": 11316023175331, "u": 11316023180746, "recv_ms": 1787089960133, "bids": [[14380.5, 1.512], [14480.5, 2.688], [58122.4, 0.004], [61351.4, 0.0], [61351.6, 0.008], [61997.2, 0.0], [62636.5, 4.789], [63579.5, 32.669], [63599.4, 0.019], [63644.1, 45.155], [63773.2, 28.285], [63863.3, 0.703], [63934.7, 5.602], [63973.4, 0.69], [64257.6, 6.809], [64450.5, 0.005], [64528.4, 0.019], [64531.4, 0.001], [64536.5, 0.681], [64539.1, 0.04], [64546.3, 0.001], [64546.6, 10.095], [64550.5, 0.042], [64563.7, 0.003], [64570.1, 0.057], [64580.5, 4.445]], "asks": [[64580.6, 46.022], [64581.9, 0.004], [64582.4, 0.004], [64582.6, 0.002], [64585.6, 0.014], [64586.9, 0.001], [64596.1, 0.002], [64598.9, 0.016], [64600.4, 0.004], [64602.8, 1.975], [64603.4, 0.002], [64603.5, 10.016], [64627.1, 0.044], [64655.7, 40.04], [64657.9, 0.029], [65226.4, 5.28], [65613.9, 16.102]]}
{"kind": "depth", "E": 1787089960281, "U": 11316023180865, "u": 11316023185482, "recv_ms": 1787089960234, "bids": [[1000.0, 35.76], [14380.5, 1.862], [14480.5, 2.338], [51664.0, 0.0], [58122.4, 0.004], [61351.4, 0.0], [61997.2, 0.003], [63288.9, 5.229], [63934.7, 5.602], [64250.1, 2.586], [64257.6, 6.964], [64439.0, 0.034], [64560.3, 2.94], [64567.6, 0.783]], "asks": [[64580.6, 46.023], [64598.5, 0.621], [64605.9, 3.022], [64656.5, 0.019], [64720.3, 0.0], [65226.4, 5.28], [65478.3, 23.991], [65517.0, 39.918], [65561.6, 0.025]]}
{"kind": "depth", "E": 1787089960383, "U": 11316023185704, "u": 11316023192275, "recv_ms": 1787089960337, "bids": [[1000.0, 35.76], [14380.5, 2.226], [14480.5, 1.974], [51664.0, 0.0], [58122.4, 0.004], [61997.2, 0.0], [63462.3, 0.787], [63580.5, 0.026], [63611.7, 0.689], [63663.5, 3.54], [63749.3, 4.659], [63934.7, 5.602], [64383.3, 0.08], [64422.0, 0.011], [64422.1, 0.0], [64456.8, 0.085], [64514.6, 0.062], [64515.1, 3.276]], "asks": [[64605.0, 0.094], [64605.9, 3.024], [64737.3, 0.001], [64776.0, 7.421], [65226.4, 5.28], [65580.6, 0.03], [66324.3, 0.905]]}
{"kind": "depth", "E": 1787089960485, "U": 11316023192395, "u": 11316023199095, "recv_ms": 1787089960438, "bids": [[14380.5, 2.576], [14480.5, 1.624], [58122.4, 0.004], [61351.4, 0.0], [61351.5, 2.447], [61997.2, 0.003], [63547.2, 8.773], [63644.1, 42.959], [63812.0, 5.835], [63864.9, 2.422], [63934.7, 5.602], [63973.4, 1.313], [64257.6, 6.974], [64383.3, 9.319], [64422.0, 4.7], [64439.0, 3.761], [64539.4, 0.0], [64547.9, 0.026], [64551.0, 2.628], [64558.5, 0.053]], "asks": [[64580.6, 46.016], [64602.8, 0.0], [64603.5, 0.016], [64642.6, 0.022], [64650.4, 0.036], [64720.3, 5.408], [64737.3, 10.428], [64775.9, 0.026], [64776.0, 19.98], [64780.1, 4.443], [65194.1, 25.781], [65226.4, 5.28], [65613.9, 17.168]]}
{"kind": "depth", "E": 1787089960587, "U": 11316023199214, "u": 11316023204594, "recv_ms": 1787089960538, "bids": [[1000.0, 35.76], [14380.5, 2.94], [14480.5, 1.26], [58122.4, 0.004], [61351.4, 0.0], [63580.5, 0.006], [63749.3, 8.887], [63811.9, 3.448], [63870.1, 8.524], [63895.3, 0.0], [63934.7, 5.602], [64063.9, 10.473], [64495.3, 0.01], [64503.0, 0.041], [64508.5, 29.819], [64508.6, 0.029], [64521.0, 0.401], [64546.6, 0.095], [64568.2, 0.302], [64569.9, 4.495], [64580.5, 4.446]], "asks": [[64580.6, 46.027], [64581.6, 0.092], [64587.0, 0.54], [64589.6, 0.257], [64597.3, 0.101], [64597.4, 0.005], [64597.7, 0.544], [64598.4, 0.66], [64606.5, 10.277], [64650.4, 0.027], [64655.7, 2.321], [64660.1, 37.592], [65219.1, 0.308], [65226.4, 5.28], [65478.3, 25.515], [65517.0, 42.052], [65580.6, 0.01], [66195.0, 0.135]]}
{"kind": "depth", "E": 1787089960689, "U": 11316023204667, "u": 11316023210578, "recv_ms": 1787089960641, "bids": [[1000.0, 35.76], [14380.5, 3.304], [14480.5, 0.896], [58122.4, 0.004], [61351.6, 0.006], [61997.2, 0.0], [63644.1, 44.057], [63812.0, 7.713], [63902.4, 2.499], [63934.7, 5.602], [64257.5, 0.003], [64450.5, 0.01], [64510.2, 2.322], [64532.8, 1.092], [64548.9, 0.001], [64570.1, 0.052]], "asks": [[64657.9, 37.608], [64660.1, 0.013], [64775.9, 0.098], [64780.1, 4.371], [64903.6, 0.0], [65226.4, 5.282], [65355.6, 65.875]]}
{"kind": "depth", "E": 1787089960791, "U": 11316023210597, "u": 11316023216688, "recv_ms": 1787089960744, "bids": [[14380.5, 3.654], [14480.5, 0.546], [51664.0, 0.0], [58122.4, 0.004], [61351.4, 0.0], [61997.2, 0.003], [63011.8, 0.679], [63288.9, 5.232], [63547.2, 9.873], [63580.5, 0.026], [63644.1, 45.155], [63676.4, 65.959], [63812.0, 8.652], [63934.7, 5.602], [64063.9, 10.784], [64257.6, 6.964], [64383.3, 9.866], [64422.0, 4.998], [64439.0, 3.93], [64517.7, 4.141], [64558.5, 0.051], [64559.2, 0.002], [64560.0, 8.406], [64564.4, 0.024], [64564.6, 0.002], [64566.4, 0.65], [64566.5, 0.009], [64575.3, 0.034], [64575.7, 1.217], [64576.1, 0.002], [64576.8, 0.094], [64577.8, 0.001], [64578.0, 0.005], [64580.5, 4.54]], "asks": [[64580.6, 46.027], [64580.8, 0.109], [64581.4, 0.0], [64582.1, 0.007], [64587.3, 0.009], [64587.5, 0.015], [64588.1, 0.0], [64588.8, 1.062], [64590.5, 0.003], [64591.1, 0.0], [64591.7, 0.619], [64591.8, 0.011], [64593.0, 0.011], [64594.6, 0.017], [64595.2, 0.175], [64595.6, 0.001], [64595.7, 0.318], [64598.5, 0.002], [64606.9, 0.0], [64623.0, 0.033], [64623.1, 0.133], [64643.4, 2.352], [64643.9, 0.002], [64645.7, 0.0], [64650.4, 0.036], [64653.0, 0.036], [64655.7, 39.9], [64657.9, 0.029], [64720.3, 5.145], [64737.3, 10.428], [64776.0, 18.992], [65186.9, 0.082], [65194.1, 27.157], [65226.4, 5.28], [65387.9, 19.228], [65536.6, 5.393], [65580.6, 0.03]]}
{"kind": "depth", "E": 1787089960893, "U": 11316023216879, "u": 11316023221999, "recv_ms": 1787089960846, "bids": [[1000.0, 35.76], [14280.5, 0.126], [14380.5, 3.752], [14480.5, 0.322], [51664.4, 0.0], [58122.4, 0.004], [61997.2, 0.0], [63288.9, 5.229], [63611.8, 15.331], [63775.2, 4.02], [63934.7, 5.602], [64257.6, 5.518], [64383.3, 9.509], [64422.0, 5.562], [64439.0, 4.221], [64450.5, 0.005], [64477.9, 0.001], [64496.3, 0.164], [64508.8, 7.727], [64531.4, 3.501], [64534.0, 0.029], [64547.5, 0.982], [64565.9, 0.163], [64566.1, 0.927], [64566.3, 0.636], [64566.4, 0.566], [64566.5, 0.001], [64567.1, 0.065], [64567.2, 0.002], [64567.3, 0.004], [64567.6, 0.164], [64567.7, 0.005], [64570.1, 0.057], [64570.5, 0.012], [64573.3, 0.395], [64575.4, 0.004], [64576.8, 0.01], [64576.9, 0.001], [64577.5, 0.001], [64580.5, 4.441]], "asks": [[64580.6, 46.027], [64580.8, 0.193], [64583.7, 0.032], [64596.4, 0.542], [64597.7, 0.002], [64598.8, 0.042], [64599.5, 0.928], [64609.1, 4.566], [64624.6, 0.023], [64625.3, 3.5], [64627.1, 0.002], [64664.8, 0.002], [64676.4, 0.019], [64678.2, 0.0], [64678.3, 0.005], [64679.8, 0.008], [64776.0, 18.507], [65226.4, 5.891], [65355.6, 66.333], [65686.4, 0.762], [66195.1, 4.165]]}
{"kind": "depth", "E": 1787089960995, "U": 11316023222210, "u": 11316023227456, "recv_ms": 1787089960947, "bids": [[1000.0, 35.76], [14280.5, 0.364], [14380.5, 3.64], [14480.5, 0.196], [58122.4, 0.004], [61351.4, 0.0], [63580.5, 0.006], [63849.7, 3.91], [63934.7, 5.602], [64503.0, 0.023], [64539.5, 0.001], [64540.5, 1.629], [64547.9, 0.026], [64558.5, 0.759], [64559.5, 0.027], [64562.7, 0.063], [64573.6, 0.001], [64574.0, 0.391], [64580.5, 4.542]], "asks": [[64586.9, 0.0], [64596.4, 0.0], [64597.7, 0.544], [64602.6, 0.008], [64653.0, 0.027], [65226.4, 5.891], [65556.4, 0.765], [65580.6, 0.01]]}
{"kind": "depth", "E": 1787089961097, "U": 11316023227587, "u": 11316023232679, "recv_ms": 1787089961049, "bids": [[14280.5, 0.616], [14380.5, 3.5], [14480.5, 0.084], [51664.0, 0.0], [58122.4, 0.004], [61997.2, 0.003], [62901.4, 0.006], [63785.2, 3.258], [63934.7, 5.602], [64257.6, 5.518], [64476.5, 10.005], [64531.3, 6.068], [64531.4, 3.5], [64568.9, 0.085], [64576.4, 0.858], [64577.1, 0.054]], "asks": [[64582.7, 0.233], [64583.4, 0.144], [64605.8, 2.581], [64625.2, 1.42], [64625.5, 0.001], [64643.9, 2.592], [64647.9, 6.022], [64650.4, 0.027], [64666.8, 1.325], [64680.2, 10.0], [65226.4, 5.891], [65387.9, 19.456], [65446.0, 0.0], [65549.3, 22.816]]}
{"kind": "depth", "E": 1787089961199, "U": 11316023232753, "u": 11316023239064, "recv_ms": 1787089961151, "bids": [[1000.0, 35.76], [14280.5, 0.882], [14380.5, 3.318], [14480.5, 0.0], [51664.0, 0.0], [58122.4, 0.004], [61997.2, 0.0], [63580.5, 0.026], [63805.5, 75.843], [63934.7, 5.602], [64450.5, 0.01], [64504.9, 0.0], [64521.9, 0.002], [64522.2, 0.0], [64522.6, 0.116], [64522.9, 0.0], [64523.2, 1.105], [64528.4, 0.018], [64531.3, 6.069], [64539.6, 0.002], [64539.9, 0.001], [64540.2, 0.034], [64540.6, 0.0], [64540.9, 1.256], [64554.5, 0.312], [64554.6, 1.241], [64554.7, 0.047], [64554.8, 0.003], [64554.9, 0.003], [64555.0, 0.003], [64555.1, 0.0], [64555.2, 1.111], [64555.3, 0.0], [64555.5, 1.302], [64556.5, 0.004], [64556.9, 0.002], [64563.7, 0.003], [64570.1, 0.052], [64573.7, 0.085], [64573.8, 0.062], [64573.9, 0.003], [64574.0, 0.251], [64574.1, 0.21], [64574.2, 0.01], [64574.3, 0.0], [64574.4, 0.087], [64574.5, 0.0], [64574.6, 0.002], [64574.7, 0.001], [64575.0, 0.158], [64575.3, 0.002], [64575.6, 2.319], [64575.9, 0.002], [64576.3, 0.003]], "asks": [[64586.7, 0.002], [64587.0, 0.466], [64587.4, 1.255], [64587.7, 2.322], [64588.0, 0.022], [64588.3, 2.025], [64588.4, 0.001], [64588.5, 0.011], [64588.6, 0.014], [64588.7, 0.012], [64588.8, 0.322], [64588.9, 0.002], [64589.0, 0.002], [64589.1, 0.001], [64589.2, 0.001], [64589.3, 0.0], [64596.1, 0.002], [64604.4, 0.112], [64604.7, 0.008], [64605.0, 0.011], [64605.4, 0.82], [64605.7, 0.842], [64606.1, 0.314], [64606.5, 10.007], [64607.5, 0.003], [64607.7, 0.024], [64607.8, 0.002], [64607.9, 0.004], [64608.0, 0.459], [64608.1, 0.061], [64608.2, 0.0], [64608.3, 0.017], [64608.4, 1.239], [64608.5, 0.105], [64622.1, 0.014], [64622.4, 1.091], [64622.7, 0.0], [64623.1, 0.059], [64623.4, 0.0], [65226.4, 5.891], [65375.2, 0.77], [65452.4, 20.385], [65580.6, 0.03]]}
{"kind": "depth", "E": 1787089961301, "U": 11316023239274, "u": 11316023247746, "recv_ms": 1787089961254, "bids": [[1000.0, 35.76], [14280.5, 1.246], [14380.5, 2.954], [58122.4, 0.004], [61351.4, 0.0], [61997.2, 0.003], [63604.7, 3.878], [63934.7, 5.602], [64169.5, 0.295], [64198.1, 0.255], [64222.1, 0.817], [64249.6, 0.175], [64439.0, 0.034], [64503.0, 0.02], [64522.3, 0.003], [64541.7, 0.0], [64564.4, 0.016], [64566.3, 0.002], [64566.7, 0.619], [64570.5, 1.576], [64570.6, 0.642], [64574.1, 0.28], [64574.3, 0.1], [64574.4, 0.157], [64576.7, 0.007], [64576.8, 0.002], [64579.1, 0.746], [64580.5, 4.486]], "asks": [[64587.3, 0.001], [64587.4, 0.892], [64588.7, 0.358], [64588.9, 0.142], [64589.9, 0.009], [64597.5, 1.069], [64606.5, 10.004], [64607.9, 0.35], [64608.2, 0.14], [64612.9, 0.021], [64691.7, 2.215], [64720.2, 0.0], [64720.3, 0.0], [64753.5, 0.983], [64775.9, 2.899], [64794.4, 1.567], [64814.3, 0.294], [64845.3, 0.788], [64864.9, 0.134], [64887.9, 29.751], [64909.7, 0.299], [64929.1, 0.193], [64948.6, 10.478], [64969.6, 3.923], [64989.9, 0.716], [65011.9, 0.081], [65226.4, 5.891], [65387.9, 20.22], [65686.1, 0.0]]}
{"kind": "depth", "E": 1787089961403, "U": 11316023247805, "u": 11316023254363, "recv_ms": 1787089961355, "bids": [[14280.5, 1.596], [14380.5, 2.604], [58122.4, 0.004], [61351.4, 0.0], [61997.2, 0.0], [62901.4, 0.005], [63934.7, 5.602], [64063.9, 10.784], [64257.6, 5.528], [64383.3, 9.325], [64422.0, 4.593], [64439.0, 3.954], [64531.1, 0.066], [64539.6, 0.034], [64539.9, 0.033], [64541.2, 0.0], [64570.5, 0.012], [64573.8, 0.132], [64574.2, 0.21], [64574.4, 0.257], [64574.5, 0.07], [64575.0, 0.19], [64575.3, 0.034], [64576.7, 1.571], [64580.5, 4.482]], "asks": [[64580.6, 46.027], [64587.6, 0.042], [64587.7, 2.396], [64588.0, 0.086], [64588.4, 0.148], [64588.6, 0.264], [64588.8, 0.842], [64589.2, 0.148], [64605.3, 0.076], [64605.7, 0.906], [64606.5, 10.274], [64607.7, 0.171], [64607.8, 0.252], [64608.0, 0.709], [64608.5, 0.252], [64623.0, 0.107], [64623.4, 0.064], [64686.6, 0.631], [64720.3, 5.408], [64737.3, 10.428], [64775.9, 0.098], [64776.0, 19.891], [65193.3, 0.0], [65226.4, 5.891], [65342.9, 8.114], [65451.8, 0.914], [65872.2, 7.589]]}
{"kind": "depth", "E": 1787089961607, "U": 11316023260548, "u": 11316023267436, "recv_ms": 1787089961560, "bids": [[1000.0, 35.76], [14280.5, 2.31], [14380.5, 1.89], [51664.0, 0.0], [58122.4, 0.004], [61997.2, 0.003], [63572.9, 4.038], [63580.5, 0.026], [63934.7, 5.602], [64439.0, 0.034], [64564.4, 0.024], [64566.3, 0.636], [64569.4, 0.309], [64569.9, 4.186], [64570.5, 0.012], [64570.6, 0.0], [64573.9, 0.143], [64574.5, 0.17], [64574.7, 0.071], [64576.7, 0.007], [64576.8, 0.002], [64576.9, 0.001], [64577.0, 0.093], [64577.1, 1.602], [64577.4, 0.004], [64578.0, 0.013]], "asks": [[64580.6, 45.824], [64585.6, 0.073], [64588.2, 1.119], [64588.3, 2.186], [64588.5, 0.291], [64589.0, 0.303], [64591.1, 0.077], [64591.7, 0.542], [64601.5, 1.839], [64602.3, 1.271], [64607.5, 0.164], [64607.7, 0.451], [64608.3, 0.304], [64609.4, 0.001], [64609.5, 0.012], [64609.6, 7.13], [64612.4, 0.001], [64612.5, 0.0], [64612.6, 0.0], [64613.3, 0.0], [64615.4, 0.029], [64615.5, 0.001], [64615.6, 0.001], [64656.5, 0.0], [64720.3, 0.0], [65200.6, 2.391], [65226.4, 5.891], [65363.5, 0.826], [65465.4, 5.481], [65580.6, 0.03], [65872.2, 7.586]]}
{"kind": "depth", "E": 1787089961709, "U": 11316023267526, "u": 11316023272713, "recv_ms": 1787089961663, "bids": [[14280.5, 2.66], [14380.5, 1.54], [51664.0, 0.0], [58122.4, 0.004], [61351.4, 0.0], [61997.2, 0.0], [63397.9, 1.579], [63773.2, 28.051], [63934.7, 5.602], [64257.5, 0.001], [64257.6, 5.518], [64439.0, 3.954], [64522.0, 0.195], [64522.3, 0.035], [64554.8, 0.073], [64555.1, 0.17], [64559.4, 0.0], [64560.3, 3.056], [64564.4, 0.024], [64566.3, 0.636], [64570.5, 0.012], [64570.6, 0.0], [64576.7, 1.571], [64577.0, 0.085], [64577.1, 0.054], [64577.2, 0.003], [64578.0, 0.005]], "asks": [[64583.9, 0.023], [64601.5, 1.282], [64601.9, 0.558], [64613.4, 0.093], [64613.5, 0.279], [64720.3, 5.408], [65226.4, 5.891], [65355.6, 69.388]]}
{"kind": "depth", "E": 1787089961811, "U": 11316023272766, "u": 11316023278209, "recv_ms": 1787089961764, "bids": [[1000.0, 35.76], [14280.5, 3.024], [14380.5, 1.176], [51664.0, 0.0], [58122.4, 0.004], [61997.2, 0.003], [63482.6, 14.517], [63547.2, 9.873], [63934.7, 5.602], [64439.0, 0.034], [64522.6, 0.148], [64522.9, 0.032], [64523.2, 1.137], [64535.4, 0.008], [64542.9, 0.314], [64554.5, 0.382], [64555.0, 0.103], [64555.2, 1.211], [64555.3, 0.07], [64556.5, 0.104]], "asks": [[64619.1, 6.427], [64720.3, 0.0], [64903.6, 0.002], [65226.4, 5.891], [65349.1, 9.17], [65387.9, 19.992], [65556.5, 1.791]]}
{"kind": "depth", "E": 1787089961913, "U": 11316023278300, "u": 11316023283048, "recv_ms": 1787089961872, "bids": [[1000.0, 35.76], [14280.5, 3.374], [14380.5, 0.826], [51664.4, 0.0], [58122.4, 0.004], [61351.4, 0.001], [61997.2, 0.0], [63288.9, 5.229], [63410.9, 2.454], [63580.5, 0.006], [63729.3, 0.0], [63934.7, 5.602], [64422.0, 4.827], [64439.0, 3.552], [64547.6, 0.021], [64547.7, 0.006], [64547.8, 0.003], [64551.1, 0.002], [64551.2, 0.005], [64551.3, 2.322], [64554.6, 1.311], [64554.7, 0.117], [64554.8, 0.143], [64554.9, 0.103], [64556.9, 0.102]], "asks": [[64580.6, 45.824], [64593.0, 0.003], [64595.1, 0.008], [64605.7, 0.774], [64720.3, 5.408], [64737.3, 10.428], [65226.4, 5.891], [65349.1, 10.087], [65484.7, 90.263], [65549.3, 22.473], [65580.6, 0.01], [66124.3, 0.002]]}
{"kind": "depth", "E": 1787089962015, "U": 11316023283130, "u": 11316023288575, "recv_ms": 1787089961969, "bids": [[14180.5, 0.014], [14280.5, 3.71], [14380.5, 0.476], [58122.4, 0.004], [61351.4, 0.0], [63288.9, 5.232], [63934.7, 5.602], [64257.6, 5.528], [64517.7, 4.356], [64554.7, 0.187], [64555.3, 0.17], [64555.5, 1.372], [64560.0, 3.406], [64562.1, 2.182], [64580.5, 4.438]], "asks": [[64580.6, 45.922], [64583.9, 0.001], [64597.3, 0.181], [64643.4, 2.416], [65226.4, 5.891], [65550.3, 0.001]]}
{"kind": "depth", "E": 1787089962117, "U": 11316023288670, "u": 11316023294413, "recv_ms": 1787089962069, "bids": [[1000.0, 35.76], [14180.5, 0.182], [14280.5, 3.724], [14380.5, 0.294], [58122.4, 0.004], [61351.4, 0.0], [61351.5, 2.449], [61997.2, 0.003], [63475.4, 3.967], [63482.6, 19.236], [63580.5, 0.026], [63599.5, 5.535], [63664.1, 0.0], [63665.3, 0.188], [63817.4, 3.917], [63934.7, 5.602], [64383.3, 9.675], [64385.7, 1.413], [64409.1, 1.214], [64422.0, 5.619], [64428.2, 0.934], [64439.0, 4.257], [64447.2, 1.906], [64472.1, 1.281], [64508.6, 6.684], [64531.3, 6.07], [64543.2, 1.056], [64562.1, 1.542], [64568.9, 0.085], [64580.5, 4.481]], "asks": [[64598.6, 1.918], [64622.3, 1.59], [64655.6, 5.972], [64655.7, 2.321], [64662.3, 37.627], [64673.1, 1.408], [64776.0, 18.254], [65226.4, 5.891], [65484.7, 90.719], [65495.9, 0.002], [65497.1, 0.004], [65561.7, 0.013], [65580.6, 0.03], [66181.5, 0.001]]}
{"kind": "depth", "E": 1787089962219, "U": 11316023294691, "u": 11316023300868, "recv_ms": 1787089962171, "bids": [[1000.0, 35.76], [14180.5, 0.42], [14280.5, 3.612], [14380.5, 0.168], [58122.4, 0.004], [61351.4, 0.0], [61997.2, 0.0], [63288.9, 5.229], [63599.5, 5.543], [63609.7, 0.01], [63625.8, 0.0], [63664.1, 0.008], [63665.3, 0.196], [63741.0, 22.991], [63817.4, 3.134], [63934.7, 5.602], [64383.3, 4.903], [64422.0, 2.914], [64439.0, 2.797], [64495.7, 0.001], [64504.8, 1.2], [64528.4, 0.019], [64534.0, 0.029], [64562.4, 0.01], [64563.2, 0.044], [64563.7, 0.003], [64573.0, 0.097], [64575.2, 0.088], [64575.4, 0.004], [64576.4, 0.774], [64577.0, 0.001], [64580.5, 4.376]], "asks": [[64580.6, 46.005], [64580.9, 0.065], [64582.1, 0.0], [64583.1, 0.029], [64584.2, 0.089], [64585.1, 0.004], [64587.8, 0.309], [64588.8, 0.533], [64593.0, 0.011], [64595.1, 0.0], [64596.1, 0.002], [64627.1, 0.002], [64655.6, 0.012], [64657.9, 37.713], [64662.3, 0.001], [64720.3, 5.408], [65226.4, 5.891], [65472.1, 12.353], [65497.1, 0.012], [65517.0, 40.985], [65549.3, 22.816], [65561.7, 0.021], [65646.2, 3.378]]}
{"kind": "depth", "E": 1787089962321, "U": 11316023300962, "u": 11316023306280, "recv_ms": 1787089962273, "bids": [[14180.5, 0.658], [14280.5, 3.486], [14380.5, 0.056], [51664.0, 0.0], [58122.4, 0.004], [61997.2, 0.003], [63580.5, 0.006], [63644.1, 45.273], [63741.0, 19.858], [63934.7, 5.602], [63999.3, 13.763], [64257.6, 5.518], [64265.1, 1.943], [64284.1, 3.051], [64304.0, 5.976], [64329.1, 2.169], [64348.1, 4.03], [64366.8, 2.006], [64383.3, 9.667], [64422.0, 5.61], [64439.0, 4.238], [64576.1, 0.086]], "asks": [[64583.1, 0.009], [64583.5, 0.024], [64776.0, 18.289], [65161.8, 17.512], [65226.4, 5.891], [65284.5, 17.184], [65420.1, 22.291], [65447.3, 0.03], [65495.9, 0.01], [65549.4, 0.343], [65580.6, 0.01]]}
{"kind": "depth", "E": 1787089962423, "U": 11316023306549, "u": 11316023311679, "recv_ms": 1787089962374, "bids": [[1000.0, 35.76], [14180.5, 0.966], [14280.5, 3.234], [14380.5, 0.0], [58122.4, 0.004], [61351.4, 0.0], [63934.7, 5.602], [63967.0, 27.674], [64539.7, 0.0], [64576.7, 1.655], [64580.5, 4.469]], "asks": [[64580.6, 46.005], [64592.1, 0.021], [64598.6, 1.918], [64600.4, 5.004], [64600.7, 0.02], [64640.1, 0.0], [64642.6, 0.013], [64647.8, 0.468], [64690.6, 0.0], [64863.2, 0.001], [65123.2, 0.0], [65226.4, 5.891], [65383.2, 0.769], [65484.7, 93.007], [65517.0, 42.052], [65646.2, 4.443]]}
{"kind": "depth", "E": 1787089962525, "U": 11316023311683, "u": 11316023317649, "recv_ms": 1787089962477, "bids": [[1000.0, 35.76], [14180.5, 1.33], [14280.5, 2.87], [58122.4, 0.004], [61997.2, 0.0], [63024.0, 2.07], [63580.5, 0.026], [63611.7, 2.055], [63934.7, 5.602], [64005.4, 0.008], [64268.6, 0.001], [64383.3, 9.92], [64422.0, 5.701], [64426.5, 0.027], [64439.0, 4.291], [64494.9, 0.079], [64522.3, 0.032], [64564.4, 0.016], [64566.3, 0.002], [64570.5, 2.21], [64570.6, 0.008], [64574.2, 0.212], [64575.5, 0.001], [64576.6, 0.312], [64576.7, 0.091], [64579.3, 0.747]], "asks": [[64612.9, 0.018], [64613.5, 0.275], [64617.9, 0.0], [64618.1, 0.156], [64618.2, 0.0], [64639.5, 0.027], [64707.2, 0.0], [64776.0, 17.903], [65226.4, 5.891], [65284.5, 17.871], [65355.6, 68.93], [65465.4, 6.09], [65556.5, 1.524], [65580.6, 0.03]]}
{"kind": "depth", "E": 1787089962627, "U": 11316023317654, "u": 11316023322635, "recv_ms": 1787089962580, "bids": [[14180.5, 1.68], [14280.5, 2.52], [51664.0, 0.0], [58122.4, 0.004], [61351.4, 0.0], [61997.2, 0.003], [63676.4, 66.147], [63862.9, 5.442], [63934.7, 5.602], [63967.0, 28.376], [64257.6, 5.528], [64522.3, 0.035]], "asks": [[64580.6, 45.969], [64597.6, 0.627], [64598.4, 0.041], [64612.9, 0.021], [64618.1, 0.002], [64618.3, 0.158], [64640.1, 0.018], [65226.4, 5.891], [65355.6, 68.716], [65427.9, 2.289], [65554.7, 0.267], [65685.7, 5.328], [71038.7, 0.004]]}
{"kind": "depth", "E": 1787089962729, "U": 11316023322740, "u": 11316023328153, "recv_ms": 1787089962682, "bids": [[1000.0, 35.91], [14180.5, 2.044], [14280.5, 2.156], [58122.4, 0.004], [61351.4, 0.0], [61997.2, 0.0], [63580.5, 0.006], [63637.6, 0.783], [63752.9, 2.349], [63934.7, 5.602], [63967.0, 27.674], [64559.4, 0.0], [64560.3, 2.321], [64560.4, 0.603], [64560.6, 0.001], [64561.2, 0.002], [64561.6, 1.134], [64563.4, 0.107], [64563.9, 0.004], [64565.5, 0.927], [64566.1, 0.0], [64566.7, 0.0], [64567.2, 0.009], [64568.0, 0.006], [64568.5, 0.312], [64568.9, 0.085], [64569.4, 0.0], [64570.6, 0.0], [64573.9, 0.145], [64574.2, 0.21], [64574.6, 0.105], [64575.0, 0.19], [64575.2, 0.085], [64580.5, 4.16]], "asks": [[64580.6, 45.976], [64580.9, 0.058], [64587.6, 0.142], [64590.5, 0.545], [64591.1, 0.0], [64591.7, 0.0], [64591.8, 0.003], [64591.9, 0.0], [64595.8, 0.002], [64597.5, 0.992], [64597.7, 0.002], [64597.9, 0.001], [64598.9, 0.943], [64599.5, 0.001], [64601.0, 0.0], [64601.9, 0.558], [64602.2, 0.04], [64603.1, 0.116], [64604.1, 0.0], [64605.0, 0.151], [64605.7, 0.717], [65226.4, 5.891], [65580.6, 0.01], [71038.7, 0.002]]}
{"kind": "depth", "E": 1787089962831, "U": 11316023328230, "u": 11316023334474, "recv_ms": 1787089962785, "bids": [[1000.0, 35.76], [14180.5, 2.394], [14280.5, 1.806], [58122.4, 0.004], [61351.4, 0.0], [61351.5, 2.447], [61351.6, 0.008], [61997.2, 0.003], [63934.7, 5.602], [64257.5, 0.003], [64257.6, 5.528], [64439.0, 0.034]], "asks": [[64580.6, 45.976], [64583.4, 0.163], [64720.3, 0.0], [64903.6, 0.0], [65226.4, 5.891], [65355.6, 69.174]]}
{"kind": "depth", "E": 1787089962933, "U": 11316023334614, "u": 11316023339083, "recv_ms": 1787089962885, "bids": [[14180.5, 2.744], [14280.5, 1.456], [51664.4, 0.0], [58122.4, 0.004], [63580.5, 0.026], [63798.3, 3.915], [63811.9, 2.509], [63934.7, 5.602]], "asks": [[65226.4, 5.891], [65529.9, 22.156], [65580.6, 0.03]]}
{"kind": "depth", "E": 1787089963035, "U": 11316023339218, "u": 11316023344185, "recv_ms": 1787089962986, "bids": [[1000.0, 35.76], [14180.5, 3.108], [14280.5, 1.092], [58122.4, 0.004], [61351.4, 0.0], [61351.6, 0.006], [61997.2, 0.0], [63811.9, 1.57], [63837.8, 8.842], [63927.6, 0.669], [63934.7, 5.604], [63967.0, 28.376], [64383.3, 9.949], [64422.0, 5.83], [64439.0, 4.354], [64546.0, 0.933], [64558.1, 0.002], [64559.2, 0.0], [64568.8, 0.16], [64576.7, 0.007], [64580.5, 4.159]], "asks": [[64580.6, 45.975], [64720.3, 5.408], [64737.3, 10.428], [64776.0, 17.689], [65226.4, 5.891], [65529.9, 22.689], [65685.5, 1.52], [65872.2, 7.583]]}
{"kind": "depth", "E": 1787089963239, "U": 11316023349625, "u": 11316023355449, "recv_ms": 1787089963190, "bids": [[14080.5, 0.042], [14180.5, 3.738], [14280.5, 0.42], [51664.0, 0.0], [58122.4, 0.004], [61997.2, 0.0], [63812.0, 10.53], [63837.8, 9.781], [63934.7, 5.602], [64038.0, 100.14], [64158.6, 0.029], [64185.1, 0.437], [64211.1, 0.312], [64233.1, 0.479], [64439.0, 0.034], [64556.8, 0.007], [64563.7, 0.003]], "asks": [[64596.1, 0.002], [64720.3, 0.0], [65226.4, 5.891], [65872.2, 7.586]]}
{"kind": "depth", "E": 1787089963341, "U": 11316023355541, "u": 11316023363382, "recv_ms": 1787089963293, "bids": [[1000.0, 35.76], [14080.5, 0.238], [14180.5, 3.696], [14280.5, 0.266], [58122.4, 0.004], [61351.4, 0.0], [61997.2, 0.003], [63580.5, 0.026], [63654.0, 0.065], [63773.2, 28.285], [63934.7, 6.226], [64439.0, 4.406], [64503.0, 0.023], [64541.7, 0.003], [64544.7, 0.04], [64550.5, 0.002], [64573.0, 0.013], [64576.5, 0.085], [64576.9, 0.085]], "asks": [[64580.6, 45.975], [64602.2, 0.818], [64635.1, 0.874], [64638.8, 0.003], [64657.8, 5.719], [64676.2, 1.401], [64677.5, 0.0], [64698.6, 1.381], [64720.3, 5.408], [64722.0, 0.659], [64725.0, 0.023], [64747.4, 0.234], [64775.9, 2.777], [64776.0, 18.376], [64807.9, 0.3], [64827.1, 0.57], [64862.0, 0.399], [64886.1, 0.282], [64903.4, 1.535], [64921.9, 0.224], [64942.5, 0.169], [64960.0, 77.307], [64979.9, 1.873], [65003.2, 1.632], [65021.9, 0.04], [65226.4, 5.891], [65362.8, 6.895], [65580.6, 0.03]]}
{"kind": "depth", "E": 1787089963443, "U": 11316023363433, "u": 11316023368471, "recv_ms": 1787089963395, "bids": [[14080.5, 0.476], [14180.5, 3.584], [14280.5, 0.14], [51664.0, 0.0], [58122.4, 0.004], [61351.4, 0.0], [63288.9, 5.229], [63934.7, 6.226], [64257.6, 5.528], [64439.0, 4.406], [64505.7, 0.101], [64560.3, 2.94], [64567.7, 0.624], [64573.3, 0.311], [64577.3, 0.1]], "asks": [[64580.6, 45.887], [64587.6, 0.05], [64590.5, 0.003], [64591.1, 0.634], [64598.5, 0.002], [64685.6, 2.62], [64720.3, 5.408], [65226.4, 5.891], [65323.9, 10.217], [65387.9, 20.22]]}
{"kind": "depth", "E": 1787089963545, "U": 11316023368689, "u": 11316023373728, "recv_ms": 1787089963497, "bids": [[14080.5, 0.728], [14180.5, 3.444], [14280.5, 0.028], [58122.4, 0.004], [61351.4, 0.0], [61351.5, 2.449], [61997.2, 0.0], [63410.8, 2.364], [63580.5, 0.006], [63793.2, 5.164], [63934.7, 6.226], [64470.7, 3.022], [64535.4, 0.008], [64542.9, 0.314], [64547.6, 0.019], [64547.7, 0.004], [64547.8, 0.001], [64549.3, 0.007], [64549.4, 0.081], [64551.0, 0.628], [64551.1, 0.0], [64551.2, 0.003], [64551.3, 2.32], [64567.7, 0.005], [64574.9, 0.012], [64577.3, 0.016], [64580.5, 4.158]], "asks": [[64580.6, 45.979], [64585.3, 0.005], [64596.8, 0.007], [64598.3, 0.0], [64606.5, 10.277], [64658.1, 0.018], [65226.4, 5.891], [65580.6, 0.01]]}
{"kind": "depth", "E": 1787089963647, "U": 11316023373774, "u": 11316023379329, "recv_ms": 1787089963599, "bids": [[1000.0, 35.76], [14080.5, 1.05], [14180.5, 3.15], [14280.5, 0.0], [58122.4, 0.004], [61997.2, 0.003], [63438.1, 1.261], [63934.7, 6.226], [64438.1, 1.036], [64548.5, 10.0], [64560.3, 2.321], [64561.2, 0.56], [64561.6, 0.576], [64580.5, 3.554]], "asks": [[64580.6, 45.979], [64590.5, 0.08], [64591.1, 0.557], [64596.4, 0.542], [64597.5, 0.45], [64602.4, 2.022], [64605.8, 0.001], [64605.9, 2.405], [64606.5, 0.277], [64640.1, 0.0], [64685.6, 2.52], [64722.3, 0.47], [65097.2, 9.386], [65226.4, 5.891], [65355.6, 67.341], [66137.1, 4.529]]}
{"kind": "depth", "E": 1787089963749, "U": 11316023379473, "u": 11316023384340, "recv_ms": 1787089963703, "bids": [[14080.5, 1.4], [14180.5, 2.8], [58122.4, 0.004], [61997.2, 0.0], [63580.5, 0.026], [63830.6, 1.798], [63934.6, 0.005], [63934.7, 6.226], [64257.6, 5.528], [64438.1, 0.036], [64515.9, 0.023], [64580.5, 3.548]], "asks": [[64580.6, 45.979], [64596.4, 0.0], [64597.5, 0.992], [64645.2, 0.363], [64655.7, 40.593], [64657.8, 0.0], [64657.9, 0.029], [64722.3, 1.47], [65226.4, 5.893], [65497.6, 2.281], [65580.6, 0.03]]}
{"kind": "depth", "E": 1787089963851, "U": 11316023384378, "u": 11316023389281, "recv_ms": 1787089963805, "bids": [[14080.5, 1.764], [14180.5, 2.436], [51664.0, 0.0], [58122.4, 0.004], [61351.4, 0.0], [61351.5, 2.451], [61351.6, 0.004], [63224.2, 0.002], [63450.3, 10.073], [63934.7, 6.228], [64038.0, 100.253], [64257.5, 0.001], [64470.7, 3.019], [64503.0, 0.02], [64522.3, 0.035], [64535.4, 0.004], [64539.5, 0.026], [64541.9, 0.007], [64547.9, 0.001]], "asks": [[64612.9, 0.021], [64638.8, 0.0], [64658.1, 0.015], [64776.0, 18.324], [65226.4, 5.891]]}
{"kind": "depth", "E": 1787089963953, "U": 11316023389334, "u": 11316023393438, "recv_ms": 1787089963906, "bids": [[1000.0, 35.76], [14080.5, 2.114], [14180.5, 2.086], [51664.4, 0.0], [58122.4, 0.004], [61351.4, 0.0], [61997.2, 0.003], [63224.3, 2.691], [63288.9, 5.232], [63410.5, 0.801], [63830.6, 2.58], [63934.7, 6.226], [64576.9, 0.001], [64580.5, 3.649]], "asks": [[64580.6, 45.979], [64903.6, 0.002], [65097.2, 10.306], [65226.4, 5.891], [65355.6, 69.174], [66195.1, 4.618]]}
{"kind": "depth", "E": 1787089964055, "U": 11316023393603, "u": 11316023398542, "recv_ms": 1787089964008, "bids": [[14080.5, 2.478], [14180.5, 1.722], [58122.4, 0.004], [61351.4, 0.0], [61997.2, 0.0], [63397.9, 0.791], [63580.5, 0.006], [63805.5, 75.062], [63934.7, 6.226], [64257.6, 5.518], [64275.1, 3.307], [64297.1, 2.362], [64332.1, 3.375], [64351.1, 5.288], [64370.9, 0.922], [64399.1, 0.92], [64422.0, 5.548], [64422.1, 1.07], [64439.0, 4.482], [64456.1, 1.954], [64481.3, 0.012], [64481.4, 0.22], [64491.1, 1.374], [64510.3, 2.097], [64530.9, 0.833], [64534.0, 0.001], [64548.9, 2.764], [64549.3, 2.989], [64568.9, 0.085], [64576.9, 0.085], [64579.9, 0.003], [64580.5, 4.155]], "asks": [[64580.6, 45.849], [64606.3, 10.003], [64609.4, 0.003], [64609.5, 0.014], [64609.6, 7.132], [64612.4, 0.003], [64612.5, 0.002], [64612.6, 0.002], [64613.3, 0.002], [64613.4, 0.095], [64613.5, 0.277], [64615.4, 0.031], [64615.5, 0.003], [64615.6, 0.003], [64640.1, 0.009], [64647.8, 0.468], [64655.7, 2.321], [64662.3, 38.273], [64720.3, 5.408], [64737.3, 10.428], [64771.9, 0.0], [64772.0, 0.003], [64776.0, 17.947], [65226.4, 5.891], [65350.9, 3.218], [65580.6, 0.01]]}
{"kind": "depth", "E": 1787089964157, "U": 11316023398656, "u": 11316023403992, "recv_ms": 1787089964109, "bids": [[1000.0, 35.76], [14080.5, 2.828], [14180.5, 1.372], [51664.0, 0.0], [58122.4, 0.004], [61997.2, 0.003], [63288.9, 5.229], [63545.2, 0.003], [63934.7, 6.226], [64449.8, 0.009]], "asks": [[64586.1, 0.062], [64657.9, 38.893], [64661.3, 0.082], [64662.3, 0.001], [65226.4, 5.891], [65387.9, 19.992], [65395.1, 4.589], [65504.3, 2.744]]}
{"kind": "depth", "E": 1787089964259, "U": 11316023404041, "u": 11316023408611, "recv_ms": 1787089964212, "bids": [[1000.0, 35.76], [14080.5, 3.192], [14180.5, 1.008], [51664.0, 0.006], [58122.4, 0.004], [61997.2, 0.0], [63580.5, 0.026], [63805.5, 75.844], [63934.7, 6.226], [64383.3, 9.843], [64422.0, 5.633], [64422.1, 0.0], [64439.0, 4.689], [64563.7, 0.003], [64569.2, 0.0], [64570.3, 0.492]], "asks": [[64596.1, 0.002], [64599.9, 1.525], [64600.0, 1.814], [64737.2, 10.676], [64737.3, 0.001], [64776.0, 17.656], [65226.4, 5.891], [65355.6, 69.388], [65580.6, 0.03]]}
{"kind": "depth", "E": 1787089964361, "U": 11316023408676, "u": 11316023413077, "recv_ms": 1787089964314, "bids": [[14080.5, 3.542], [14180.5, 0.658], [51664.0, 0.0], [58122.4, 0.004], [61351.4, 0.0], [63288.9, 5.226], [63611.8, 16.587], [63644.1, 43.39], [63773.2, 28.02], [63837.8, 10.876], [63934.7, 6.226], [64254.4, 0.477], [64257.6, 5.528], [64577.3, 0.1], [64579.9, 0.039], [64580.5, 4.156]], "asks": [[64580.6, 45.86], [64606.3, 0.003], [64647.8, 0.477], [65097.2, 9.999], [65226.4, 5.891], [65323.3, 1.07], [65549.3, 24.035], [65736.9, 0.0]]}
{"kind": "depth", "E": 1787089964463, "U": 11316023413260, "u": 11316023418426, "recv_ms": 1787089964416, "bids": [[1000.0, 35.76], [14080.5, 3.766], [14180.5, 0.364], [14480.5, 0.07], [58122.4, 0.004], [61351.4, 0.0], [61997.2, 0.003], [63547.1, 1.369], [63580.5, 0.006], [63637.6, 1.081], [63741.0, 19.545], [63766.0, 3.191], [63934.7, 6.226], [64029.4, 0.11], [64288.7, 0.07], [64383.3, 9.843], [64422.0, 5.633], [64444.2, 2.66], [64511.6, 0.011], [64536.5, 0.709], [64537.5, 0.005], [64560.3, 2.94], [64567.6, 0.164], [64576.9, 0.001], [64577.3, 0.016], [64580.5, 4.048]], "asks": [[64580.6, 45.944], [64598.5, 0.621], [64605.9, 3.024], [64626.8, 0.004], [64627.1, 0.002], [64652.4, 0.011], [64719.0, 3.204], [64776.0, 17.656], [64872.7, 0.067], [65128.9, 0.112], [65226.4, 5.891], [65427.2, 3.815], [65517.0, 43.119], [65580.6, 0.01], [65581.6, 32.997], [65872.2, 7.589]]}
{"kind": "depth", "E": 1787089964565, "U": 11316023418562, "u": 11316023423498, "recv_ms": 1787089964518, "bids": [[1000.0, 35.76], [14080.5, 3.668], [14180.5, 0.238], [14480.5, 0.294], [58122.4, 0.004], [61997.2, 0.0], [63644.1, 44.489], [63934.7, 6.226], [64038.0, 100.301], [64461.9, 3.934], [64509.4, 0.051]], "asks": [[64651.6, 0.36], [64655.7, 41.185], [64657.9, 0.029], [64717.4, 3.871], [64719.9, 0.0], [65097.2, 10.306], [65226.4, 5.891], [65472.1, 10.065], [67078.3, 0.002]]}
{"kind": "depth", "E": 1787089964667, "U": 11316023423564, "u": 11316023428426, "recv_ms": 1787089964619, "bids": [[14080.5, 3.556], [14180.5, 0.112], [14480.5, 0.532], [58122.4, 0.004], [61997.2, 0.003], [63954.1, 2.829], [64038.0, 100.416], [64257.6, 5.518]], "asks": [[65226.4, 5.891], [65449.1, 0.0]]}
{"kind": "depth", "E": 1787089964769, "U": 11316023428610, "u": 11316023433536, "recv_ms": 1787089964721, "bids": [[1000.0, 35.76], [14080.5, 3.416], [14180.5, 0.0], [14480.5, 0.784], [58122.4, 0.004], [61351.4, 0.0], [63514.9, 6.592], [63580.5, 0.026], [63644.1, 43.39], [63741.0, 19.858], [63934.6, 0.004], [63934.7, 6.226], [64383.3, 5.367], [64422.0, 3.082], [64439.0, 2.83], [64517.7, 0.019], [64517.8, 4.426], [64535.2, 0.068], [64541.9, 0.003], [64560.3, 2.321], [64573.2, 0.004], [64573.9, 0.143], [64579.2, 1.544], [64579.3, 0.788], [64579.8, 0.002], [64580.5, 3.649]], "asks": [[64580.6, 45.944], [64586.1, 0.061], [64596.4, 0.0], [64597.5, 0.992], [64598.5, 0.002], [64605.9, 2.405], [64643.4, 2.315], [64776.0, 22.859], [64903.5, 4.77], [65226.4, 5.891], [65428.1, 0.763], [65580.6, 0.03], [65581.6, 34.063]]}
{"kind": "depth", "E": 1787089964871, "U": 11316023433569, "u": 11316023437777, "recv_ms": 1787089964823, "bids": [[1000.0, 35.76], [14080.5, 3.066], [14480.5, 1.134], [58122.4, 0.004], [61997.2, 0.0], [62900.0, 29.335], [63934.7, 6.226], [63954.1, 3.518], [64383.3, 9.843], [64422.0, 5.633]], "asks": [[64776.0, 17.917], [64903.6, 0.0], [65226.4, 5.891], [67071.1, 0.149]]}
{"kind": "depth", "E": 1787089964973, "U": 11316023437879, "u": 11316023441738, "recv_ms": 1787089964925, "bids": [[14080.5, 2.716], [14480.5, 1.484], [51664.4, 0.0], [58122.4, 0.004], [61351.4, 0.0], [61997.2, 0.003], [63837.8, 9.937], [63934.7, 6.226], [64038.0, 100.354], [64257.5, 0.003], [64257.6, 5.528]], "asks": [[64580.6, 45.944], [65226.4, 5.893], [65388.2, 3.785], [65680.5, 0.0]]}
{"kind": "depth", "E": 1787089965075, "U": 11316023441789, "u": 11316023446193, "recv_ms": 1787089965029, "bids": [[1000.0, 35.76], [14080.5, 2.352], [14480.5, 1.848], [58122.4, 0.004], [61997.2, 0.0], [63514.9, 7.693], [63597.6, 0.0], [63611.8, 16.234], [63644.1, 44.489], [63934.7, 6.226], [64522.3, 0.035], [64535.2, 0.064], [64561.2, 0.002], [64562.2, 0.559], [64565.5, 0.0], [64567.1, 0.992], [64568.9, 0.085]], "asks": [[64598.9, 0.016], [64599.5, 0.928], [64601.9, 0.001], [64602.3, 1.828], [64603.1, 0.0], [64603.8, 0.187], [64612.9, 0.018], [64638.8, 0.003], [64737.2, 0.249], [64737.3, 6.883], [64903.5, 4.924], [65226.4, 5.891], [65355.6, 68.625], [65387.9, 19.649], [65563.5, 0.032], [65665.5, 0.607], [65686.3, 0.0]]}
{"kind": "depth", "E": 1787089965177, "U": 11316023446311, "u": 11316023450585, "recv_ms": 1787089965129, "bids": [[1000.0, 35.76], [14080.5, 2.002], [14480.5, 2.198], [51664.0, 0.0], [58122.4, 0.004], [61351.4, 0.0], [61997.2, 0.003], [63580.5, 0.006], [63597.6, 0.011], [63669.9, 8.343], [63934.7, 6.226], [64542.9, 0.318], [64561.2, 0.56], [64562.2, 0.001], [64566.1, 0.927], [64567.1, 0.065], [64573.3, 0.395], [64576.5, 0.001], [64580.5, 4.155]], "asks": [[64580.6, 45.959], [64586.7, 0.077], [64596.4, 0.0], [64597.5, 0.992], [64602.8, 0.116], [64603.8, 0.071], [64737.2, 10.676], [64737.3, 0.001], [65226.4, 5.891], [65388.5, 3.82], [65478.3, 24.601], [65580.6, 0.01], [65678.6, 1.323]]}
{"kind": "depth", "E": 1787089965279, "U": 11316023450658, "u": 11316023458806, "recv_ms": 1787089965231, "bids": [[14080.5, 1.638], [14480.5, 2.562], [58122.4, 0.004], [63288.9, 5.223], [63611.8, 16.587], [63805.5, 77.409], [63837.8, 10.876], [63934.7, 6.226], [64170.8, 0.14], [64191.7, 0.235], [64215.2, 0.434], [64239.8, 0.326], [64257.6, 5.518], [64287.1, 2.533], [64321.7, 0.679], [64396.8, 0.654], [64422.1, 1.082], [64440.0, 2.041], [64478.5, 0.798], [64517.9, 1.7], [64521.0, 0.373], [64536.5, 0.681], [64563.7, 0.001], [64574.6, 0.102], [64575.1, 0.004], [64576.6, 0.396], [64577.2, 0.087]], "asks": [[64580.6, 45.775], [64596.1, 0.0], [64596.8, 0.005], [64597.6, 0.629], [64605.6, 1.137], [64627.1, 0.058], [64655.6, 6.164], [64720.2, 1.472], [64722.0, 0.016], [64739.6, 0.031], [64763.1, 0.685], [64788.6, 0.351], [64823.2, 0.61], [64841.7, 0.219], [64868.5, 0.609], [64907.2, 0.056], [64932.5, 0.581], [64951.0, 0.602], [64983.7, 0.299], [65005.9, 0.117], [65226.4, 5.891], [65336.2, 5.885], [65355.6, 69.388], [65388.2, 3.028], [65563.4, 0.011], [65872.2, 7.592]]}
{"kind": "depth", "E": 1787089965381, "U": 11316023458985, "u": 11316023463603, "recv_ms": 1787089965334, "bids": [[1000.0, 35.76], [14080.5, 1.274], [14480.5, 2.926], [58122.4, 0.004], [61351.5, 2.453], [61997.2, 0.0], [63580.5, 0.026], [63934.7, 6.226], [64439.0, 0.034], [64440.0, 0.706], [64563.7, 0.003], [64573.2, 0.002], [64573.3, 0.311], [64574.0, 0.323], [64577.6, 0.086]], "asks": [[64581.2, 0.0], [64584.8, 0.002], [64596.1, 0.002], [64720.2, 0.0], [64720.3, 0.0], [65149.2, 0.0], [65226.4, 5.891], [65342.9, 6.585], [65478.3, 25.515], [65580.6, 0.03], [65665.6, 4.491]]}
{"kind": "depth", "E": 1787089965483, "U": 11316023463643, "u": 11316023467594, "recv_ms": 1787089965435, "bids": [[1000.0, 35.76], [14080.5, 0.924], [14480.5, 3.276], [58122.4, 0.004], [61351.4, 0.0], [61351.5, 2.451], [61351.6, 0.006], [61997.2, 0.003], [63934.7, 6.226], [64422.0, 4.765], [64439.0, 3.956], [64450.5, 0.005], [64503.0, 0.023], [64560.3, 2.94], [64567.7, 0.005], [64570.1, 0.057], [64580.5, 4.463]], "asks": [[64580.6, 45.774], [64598.6, 1.918], [64605.9, 2.405], [64612.9, 0.021], [64677.5, 0.003], [64695.6, 0.101], [64720.3, 5.408], [64737.2, 10.676], [65226.4, 5.891], [65230.8, 0.0], [65295.4, 0.186], [65336.2, 6.42], [65388.5, 4.584], [65497.6, 2.509], [65549.3, 23.692], [67809.6, 0.014]]}
{"kind": "depth", "E": 1787089965585, "U": 11316023467712, "u": 11316023472438, "recv_ms": 1787089965537, "bids": [[14080.5, 0.56], [14480.5, 3.64], [51664.0, 0.0], [58122.4, 0.004], [61351.5, 2.449], [61351.6, 0.008], [61997.2, 0.0], [63580.5, 0.006], [63934.7, 6.226], [64257.6, 5.528], [64439.0, 0.034]], "asks": [[64720.3, 0.0], [65161.8, 19.81], [65216.6, 0.013], [65226.4, 5.891], [65580.6, 0.01]]}
{"kind": "depth", "E": 1787089965687, "U": 11316023472482, "u": 11316023475722, "recv_ms": 1787089965639, "bids": [[1000.0, 35.76], [14080.5, 0.336], [14380.5, 0.112], [14480.5, 3.752], [58122.4, 0.004], [61997.2, 0.003], [63418.1, 6.495], [63934.7, 6.226], [64063.9, 9.849], [64562.4, 0.002], [64563.2, 0.052]], "asks": [[64695.6, 0.001], [65131.4, 0.0], [65226.4, 5.891], [65227.6, 0.858], [65292.2, 0.859], [65388.2, 2.271]]}
{"kind": "depth", "E": 1787089965789, "U": 11316023475869, "u": 11316023479805, "recv_ms": 1787089965742, "bids": [[1000.0, 35.76], [14080.5, 0.21], [14380.5, 0.364], [14480.5, 3.626], [58122.4, 0.004], [61351.4, 0.0], [63411.0, 0.788], [63580.5, 0.026], [63934.7, 6.226], [64383.3, 9.668], [64422.0, 4.765], [64439.0, 3.956], [64536.4, 0.081], [64542.9, 0.314], [64547.6, 0.021], [64547.7, 0.006], [64547.8, 0.003], [64551.1, 0.002], [64551.2, 0.005], [64551.3, 2.322], [64562.4, 0.01], [64563.2, 0.044], [64576.7, 0.007], [64580.5, 4.637]], "asks": [[64586.7, 0.076], [64600.4, 0.004], [64602.6, 0.004], [64609.1, 4.58], [64609.4, 0.001], [64609.5, 0.012], [64609.6, 7.13], [64612.4, 0.001], [64612.5, 0.0], [64612.6, 0.0], [64613.3, 0.0], [64613.4, 0.093], [64613.5, 0.275], [64615.4, 0.029], [64615.5, 0.001], [64615.6, 0.001], [64720.3, 5.408], [64737.2, 10.676], [64776.0, 19.387], [65226.4, 5.891], [65226.7, 3.445], [65362.8, 7.659], [65387.9, 19.421], [65523.5, 1.691], [65549.3, 24.035], [65580.6, 0.03]]}
{"kind": "depth", "E": 1787089965891, "U": 11316023479869, "u": 11316023483637, "recv_ms": 1787089965843, "bids": [[14080.5, 0.084], [14380.5, 0.588], [14480.5, 3.528], [58122.4, 0.004], [61997.2, 0.0], [63934.7, 6.228], [64063.9, 10.784], [64257.6, 5.528], [64576.7, 0.017]], "asks": [[65226.4, 5.891], [65387.9, 19.306], [65388.5, 5.348], [65523.5, 2.071]]}
{"kind": "depth", "E": 1787089965993, "U": 11316023483688, "u": 11316023487631, "recv_ms": 1787089965946, "bids": [[1000.0, 35.76], [14080.5, 0.0], [14380.5, 0.868], [14480.5, 3.332], [51664.4, 0.0], [58122.4, 0.004], [61351.6, 0.006], [61997.2, 0.003], [62966.0, 4.184], [63580.5, 0.006], [63644.1, 45.273], [63934.7, 6.226], [64038.0, 100.317], [64257.5, 0.001], [64576.7, 0.007]], "asks": [[65226.4, 5.891], [65580.6, 0.01], [67809.6, 0.01]]}
{"kind": "depth", "E": 1787089966095, "U": 11316023487659, "u": 11316023491910, "recv_ms": 1787089966047, "bids": [[1000.0, 35.76], [14380.5, 1.218], [14480.5, 2.982], [58122.4, 0.004], [61351.4, 0.0], [61997.2, 0.0], [63773.2, 28.285], [63934.7, 6.226], [64383.3, 9.844], [64422.0, 5.633], [64422.1, 0.0], [64439.0, 3.001], [64536.4, 0.077], [64542.9, 0.318], [64545.4, 0.015], [64562.4, 0.002], [64563.2, 0.052], [64568.9, 0.085], [64576.7, 0.007]], "asks": [[64580.6, 45.774], [64612.2, 0.013], [64720.3, 5.408], [64776.0, 17.916], [64903.6, 0.002], [65194.1, 26.545], [65226.4, 5.891], [65318.7, 2.297], [65749.7, 3.262]]}
{"kind": "depth", "E": 1787089966299, "U": 11316023496266, "u": 11316023500691, "recv_ms": 1787089966258, "bids": [[1000.0, 35.76], [14380.5, 1.932], [14480.5, 2.268], [51664.0, 0.0], [58122.4, 0.004], [61351.4, 0.0], [61997.2, 0.003], [62966.0, 4.186], [63934.7, 6.226], [64422.0, 0.011], [64439.0, 0.034], [64560.0, 8.406], [64562.1, 2.182], [64563.7, 0.001], [64576.7, 0.007]], "asks": [[64580.6, 45.875], [64596.1, 0.0], [64602.6, 0.008], [64615.6, 1.14], [64647.0, 1.63], [64693.0, 0.002], [64711.9, 1.047], [64720.3, 0.0], [64731.1, 1.148], [64737.2, 0.249], [64758.4, 0.158], [64836.6, 0.104], [64967.9, 0.749], [64996.2, 1.281], [65014.9, 0.038], [65226.4, 5.891], [65278.4, 1.529], [65420.1, 21.986], [65484.7, 95.295]]}
{"kind": "depth", "E": 1787089966401, "U": 11316023500885, "u": 11316023505320, "recv_ms": 1787089966353, "bids": [[1000.0, 35.76], [14380.5, 2.282], [14480.5, 1.918], [51664.0, 0.0], [58122.4, 0.004], [61997.2, 0.0], [63580.5, 0.006], [63720.5, 1.585], [63934.7, 6.226], [64038.0, 100.275], [64050.8, 0.0], [64063.9, 10.784], [64257.6, 5.363], [64300.3, 0.0], [64470.7, 3.022], [64503.0, 0.02], [64522.3, 0.032], [64536.4, 0.081], [64542.9, 0.314], [64563.7, 0.003], [64576.7, 0.017]], "asks": [[64596.1, 0.002], [64612.9, 0.021], [64638.8, 0.0], [65226.4, 5.891], [65415.6, 3.815], [65427.4, 5.359], [65465.4, 6.699], [65580.6, 0.01]]}
{"kind": "depth", "E": 1787089966503, "U": 11316023505603, "u": 11316023510301, "recv_ms": 1787089966455, "bids": [[14380.5, 2.646], [14480.5, 1.554], [51664.0, 0.0], [58122.4, 0.004], [61351.4, 0.0], [61997.2, 0.003], [62949.0, 0.06], [63288.9, 5.226], [63547.2, 8.773], [63676.4, 66.139], [63934.7, 6.226], [64038.0, 100.222], [64257.6, 5.363], [64383.3, 9.844], [64422.0, 5.633], [64439.0, 4.689], [64563.4, 0.099], [64567.5, 0.649], [64570.6, 0.008], [64576.7, 0.007]], "asks": [[64580.6, 45.892], [64598.8, 0.661], [64606.1, 1.193], [64720.3, 5.408], [64737.2, 10.676], [64776.0, 17.656], [65000.0, 116.809], [65226.4, 5.891], [65291.0, 14.016], [65407.5, 5.116], [65420.1, 22.291], [65556.3, 0.767], [65872.2, 7.589], [71038.7, 0.003]]}
{"kind": "depth", "E": 1787089966605, "U": 11316023510426, "u": 11316023515330, "recv_ms": 1787089966560, "bids": [[1000.0, 35.76], [14380.5, 3.01], [14480.5, 1.19], [51664.0, 0.0], [58122.4, 0.004], [61351.4, 0.0], [61351.5, 2.451], [61997.2, 0.0], [63580.5, 0.026], [63934.7, 6.226], [64257.6, 5.518], [64521.0, 0.401], [64536.4, 0.077], [64542.9, 0.318], [64548.5, 0.0], [64548.9, 0.001], [64552.5, 2.081], [64566.4, 0.024], [64567.6, 0.706]], "asks": [[64580.6, 45.784], [64581.2, 0.084], [64584.2, 0.086], [64598.8, 0.042], [64602.8, 0.0], [64603.3, 0.132], [64903.5, 4.77], [65226.4, 5.891], [65420.1, 23.207], [65580.6, 0.03], [65678.5, 24.362], [71038.7, 0.002]]}
{"kind": "depth", "E": 1787089966809, "U": 11316023519364, "u": 11316023523581, "recv_ms": 1787089966761, "bids": [[14280.5, 0.014], [14380.5, 3.682], [14480.5, 0.504], [51664.0, 0.0], [58122.4, 0.002], [61997.2, 0.003], [63580.5, 0.006], [63934.7, 6.226], [64038.0, 100.153], [64257.6, 5.528], [64566.3, 0.544], [64567.6, 0.164]], "asks": [[64618.1, 0.002], [64618.4, 0.16], [64903.5, 4.924], [65194.1, 26.392], [65226.4, 5.891], [65387.9, 19.389], [65480.1, 2.289], [65554.8, 0.267], [65580.6, 0.01], [65685.7, 6.088], [65936.8, 3.486]]}
{"kind": "depth", "E": 1787089966911, "U": 11316023523588, "u": 11316023527540, "recv_ms": 1787089966864, "bids": [[1000.0, 35.76], [14280.5, 0.168], [14380.5, 3.738], [14480.5, 0.294], [51664.4, 0.0], [58122.4, 0.004], [61997.2, 0.0], [63611.8, 16.234], [63693.2, 8.464], [63934.7, 6.226], [64038.0, 100.149], [64383.2, 9.933], [64422.0, 5.596], [64510.7, 0.018], [64539.5, 0.001], [64547.8, 0.028]], "asks": [[64587.5, 0.007], [64587.6, 0.058], [64590.5, 0.088], [64591.1, 0.549], [64592.9, 0.005], [64593.0, 0.019], [64776.0, 17.549], [65226.4, 5.891], [65237.6, 0.001], [65872.2, 7.592], [71038.7, 0.002]]}
{"kind": "depth", "E": 1787089967013, "U": 11316023527627, "u": 11316023531700, "recv_ms": 1787089966966, "bids": [[1000.0, 35.76], [14280.5, 0.406], [14380.5, 3.612], [14480.5, 0.182], [58122.4, 0.004], [61351.5, 2.449], [61351.6, 0.008], [61997.2, 0.003], [63580.5, 0.026], [63934.7, 6.226], [64539.5, 0.001], [64547.8, 0.003], [64547.9, 0.026]], "asks": [[64903.6, 0.0], [65194.1, 27.157], [65226.4, 5.891], [65467.9, 0.0], [65580.6, 0.03]]}
{"kind": "depth", "E": 1787089967115, "U": 11316023531867, "u": 11316023535779, "recv_ms": 1787089967073, "bids": [[14280.5, 0.644], [14380.5, 3.5], [14480.5, 0.056], [51664.0, 0.002], [58122.4, 0.004], [61351.4, 0.0], [61997.2, 0.0], [63288.9, 5.223], [63611.8, 16.587], [63720.6, 2.355], [63934.7, 6.226], [64257.5, 0.003], [64257.6, 5.518], [64271.1, 2.421], [64319.4, 0.218], [64383.2, 4.27], [64383.3, 1.706], [64422.0, 3.369], [64422.1, 1.077], [64438.9, 2.684], [64439.0, 0.034], [64439.4, 1.453], [64466.9, 1.957], [64568.9, 0.085]], "asks": [[64580.6, 45.794], [64580.9, 0.042], [64597.2, 0.0], [65226.4, 5.891], [65355.6, 70.916], [66517.9, 2.179]]}
{"kind": "depth", "E": 1787089967217, "U": 11316023535891, "u": 11316023539731, "recv_ms": 1787089967169, "bids": [[1000.0, 35.76], [14280.5, 0.938], [14380.5, 3.262], [14480.5, 0.0], [51664.0, 0.0], [58122.4, 0.004], [63385.8, 5.138], [63580.5, 0.006], [63934.7, 6.226], [64038.0, 100.14], [64111.0, 2.947], [64177.6, 0.04], [64201.8, 0.073], [64243.0, 0.282], [64383.2, 9.768], [64383.3, 0.08], [64422.0, 5.633], [64422.1, 0.0], [64561.2, 0.56], [64562.2, 0.001], [64566.1, 0.0], [64566.3, 0.929], [64566.4, 0.566], [64567.2, 0.009], [64567.6, 0.164], [64577.6, 0.002]], "asks": [[64596.4, 0.542], [64597.5, 0.45], [64603.3, 0.016], [64603.8, 0.187], [64605.0, 0.094], [64605.7, 0.774], [64776.0, 17.915], [65161.9, 16.083], [65226.4, 5.891], [65355.6, 70.702], [65467.9, 4.117], [65580.6, 0.01]]}
{"kind": "depth", "E": 1787089967319, "U": 11316023539786, "u": 11316023543801, "recv_ms": 1787089967271, "bids": [[1000.0, 35.76], [14280.5, 1.302], [14380.5, 2.898], [58122.4, 0.004], [61997.2, 0.003], [63288.9, 5.217], [63644.1, 44.175], [63837.8, 9.937], [63934.7, 6.226], [64038.0, 100.004], [64555.8, 0.128], [64563.2, 0.044]], "asks": [[64596.4, 0.0], [64597.6, 0.552], [64597.7, 0.002], [64611.8, 0.876], [64657.5, 0.404], [64720.2, 1.472], [64772.2, 2.051], [64963.3, 0.723], [65226.4, 5.891], [65517.0, 42.052]]}
{"kind": "depth", "E": 1787089967421, "U": 11316023543813, "u": 11316023548558, "recv_ms": 1787089967373, "bids": [[14280.5, 1.666], [14380.5, 2.534], [58122.4, 0.004], [61997.2, 0.0], [63385.8, 6.161], [63580.5, 0.026], [63611.8, 15.331], [63676.4, 65.951], [63837.8, 8.842], [64257.6, 5.373], [64545.4, 0.015], [64562.3, 0.01], [64563.7, 0.003], [64563.8, 0.082], [64563.9, 0.012], [64570.6, 0.0], [64577.7, 0.084]], "asks": [[64581.2, 0.0], [64596.1, 0.002], [64611.4, 0.066], [64903.5, 4.77], [65097.2, 9.999], [65226.4, 5.891], [65323.3, 0.0], [65536.6, 3.809], [65549.3, 24.4], [65580.6, 0.03], [71038.7, 0.002]]}
{"kind": "depth", "E": 1787089967523, "U": 11316023548608, "u": 11316023552136, "recv_ms": 1787089967476, "bids": [[1000.0, 35.76], [14280.5, 2.016], [14380.5, 2.184], [58122.4, 0.004], [61997.2, 0.003], [63934.7, 6.226], [64118.6, 0.083], [64539.5, 0.001], [64547.9, 0.026], [64577.7, 0.0]], "asks": [[64581.2, 0.084], [64903.5, 4.924], [65097.2, 10.305], [65226.4, 5.891], [65745.1, 3.042]]}
{"kind": "depth", "E": 1787089967625, "U": 11316023552217, "u": 11316023555710, "recv_ms": 1787089967580, "bids": [[1000.0, 35.76], [14280.5, 2.366], [14380.5, 1.834], [58122.4, 0.004], [61351.4, 0.0], [63288.9, 5.22], [63580.5, 0.006], [63644.1, 45.273], [63837.8, 9.781], [63934.7, 6.226], [64257.6, 5.528], [64438.9, 3.956], [64439.4, 0.003], [64470.7, 3.019], [64522.0, 0.163], [64522.3, 0.003], [64522.6, 0.116], [64522.9, 0.0], [64523.2, 1.105], [64539.4, 0.025], [64539.6, 0.002], [64539.9, 0.001], [64540.3, 0.031], [64540.6, 0.0], [64540.9, 1.256], [64547.9, 0.001], [64554.5, 0.312], [64554.6, 1.241], [64554.7, 0.047], [64554.8, 0.003], [64554.9, 0.003], [64555.0, 0.003], [64555.1, 0.0], [64555.2, 1.111], [64555.3, 0.0], [64555.5, 1.302], [64556.5, 0.004], [64556.9, 0.002], [64560.0, 3.406], [64562.1, 1.542], [64563.9, 0.004], [64570.6, 0.008], [64573.2, 0.004], [64573.8, 0.062], [64573.9, 0.003], [64574.0, 0.321], [64574.1, 0.21], [64574.2, 0.01], [64574.3, 0.0], [64574.4, 0.087], [64574.5, 0.0], [64574.6, 0.002], [64574.7, 0.071], [64575.0, 0.158], [64575.3, 0.002], [64575.6, 2.319], [64576.0, 0.079], [64576.3, 0.003]], "asks": [[64580.6, 45.794], [64586.7, 0.002], [64587.0, 0.466], [64587.3, 0.001], [64587.6, 0.05], [64587.7, 2.322], [64588.0, 0.022], [64588.2, 1.28], [64588.3, 2.025], [64588.4, 0.001], [64588.5, 0.011], [64588.6, 0.014], [64588.7, 0.011], [64588.8, 0.013], [64588.9, 0.002], [64589.0, 0.156], [64589.1, 0.001], [64589.2, 0.001], [64589.4, 0.067], [64598.8, 0.661], [64604.4, 0.112], [64604.7, 0.008], [64605.0, 0.011], [64605.3, 0.002], [64605.7, 0.71], [64606.1, 0.933], [64606.5, 0.007], [64607.4, 0.253], [64607.5, 0.003], [64607.7, 0.024], [64607.8, 0.002], [64607.9, 0.004], [64608.0, 0.459], [64608.1, 0.061], [64608.2, 0.154], [64608.3, 0.017], [64608.4, 1.239], [64608.5, 0.105], [64612.9, 0.018], [64622.1, 0.014], [64622.4, 1.091], [64622.7, 0.0], [64623.0, 0.033], [64623.4, 0.0], [64627.1, 0.002], [64638.8, 0.003], [64650.4, 0.027], [64720.2, 0.0], [64720.3, 5.408], [65184.4, 1.361], [65226.4, 5.891], [65387.9, 19.96], [65517.0, 43.119], [65580.6, 0.01]]}
{"kind": "depth", "E": 1787089967727, "U": 11316023555810, "u": 11316023559802, "recv_ms": 1787089967680, "bids": [[14280.5, 2.73], [14380.5, 1.47], [51664.0, 0.0], [58122.4, 0.004], [61997.2, 0.0], [63752.8, 0.784], [63934.7, 6.226], [64207.5, 0.0], [64207.6, 0.001], [64257.6, 5.518], [64303.9, 0.011], [64304.0, 0.0], [64374.7, 0.0], [64374.8, 0.217], [64453.7, 0.007], [64539.7, 0.032], [64540.0, 0.183], [64573.8, 0.077], [64574.1, 0.28], [64574.3, 0.1], [64574.4, 0.157], [64575.0, 0.19], [64575.3, 0.034]], "asks": [[64587.6, 0.124], [64588.0, 0.086], [64588.6, 0.14], [64588.7, 0.231], [64588.9, 0.142], [64601.5, 1.839], [64602.3, 1.271], [64605.3, 0.076], [64605.6, 1.201], [64607.8, 0.128], [64607.9, 0.224], [64608.1, 0.201], [64623.0, 0.107], [64623.3, 2.397], [64695.6, 0.101], [64780.1, 0.216], [64780.2, 0.0], [64851.3, 1.283], [64851.4, 2.501], [64948.6, 0.005], [64948.7, 0.0], [65194.3, 1.381], [65226.4, 5.891], [65330.5, 2.292]]}
{"kind": "depth", "E": 1787089967829, "U": 11316023559939, "u": 11316023564119, "recv_ms": 1787089967782, "bids": [[1000.0, 35.76], [14280.5, 3.08], [14380.5, 1.12], [58122.4, 0.002], [61351.4, 0.0], [61997.2, 0.003], [63580.5, 0.026], [63934.7, 6.226], [64383.2, 4.968], [64422.0, 2.964], [64438.9, 3.0], [64450.5, 0.005], [64453.7, 0.022], [64461.9, 3.934], [64474.3, 2.336], [64509.4, 0.051], [64534.0, 0.029], [64539.4, 0.0], [64540.3, 0.063], [64540.6, 0.032], [64540.9, 1.288], [64547.8, 0.028], [64559.7, 0.116], [64560.3, 2.321], [64560.4, 0.487], [64560.6, 0.559], [64561.2, 0.002], [64563.6, 0.016], [64565.5, 0.927], [64566.3, 0.002], [64567.5, 0.029], [64570.1, 0.057], [64570.6, 0.0], [64573.2, 0.002], [64573.3, 0.395], [64573.8, 0.132], [64574.0, 0.323], [64574.2, 0.21], [64574.4, 0.257], [64574.6, 0.172], [64574.9, 0.015], [64575.1, 0.001], [64575.6, 2.351], [64576.0, 0.111], [64576.3, 0.035], [64576.6, 0.312], [64577.2, 0.003], [64580.5, 4.216]], "asks": [[64580.6, 45.879], [64584.2, 0.089], [64584.7, 0.395], [64585.1, 0.004], [64585.6, 0.068], [64586.7, 0.076], [64587.0, 0.54], [64587.3, 0.084], [64587.6, 0.132], [64588.2, 1.279], [64588.3, 2.285], [64588.4, 0.148], [64588.5, 0.261], [64588.7, 0.481], [64588.8, 0.283], [64589.2, 0.148], [64589.4, 0.059], [64596.4, 0.542], [64597.6, 0.01], [64598.0, 1.552], [64598.8, 0.042], [64599.5, 0.001], [64602.4, 2.138], [64603.8, 0.071], [64604.3, 0.565], [64604.7, 0.082], [64605.0, 0.094], [64606.0, 0.27], [64606.5, 0.277], [64607.6, 0.199], [64607.8, 0.378], [64608.0, 0.709], [64608.4, 1.386], [64622.0, 0.238], [64622.3, 1.664], [64622.6, 0.086], [64640.1, 0.0], [64647.8, 0.468], [64651.6, 0.36], [64687.8, 2.323], [64717.4, 0.0], [64718.8, 3.871], [64720.3, 5.408], [64722.3, 0.47], [64729.5, 0.031], [65065.6, 0.0], [65214.0, 0.003], [65226.4, 5.891], [65407.5, 3.208], [65580.6, 0.03], [65743.2, 1.356]]}
{"kind": "depth", "E": 1787089967931, "U": 11316023564176, "u": 11316023567178, "recv_ms": 1787089967884, "bids": [[1000.0, 35.76], [14280.5, 3.444], [14380.5, 0.756], [51664.4, 0.0], [58122.4, 0.004], [61997.2, 0.0], [63934.7, 6.226], [63944.5, 1.252], [64063.8, 0.157], [64091.9, 0.0], [64207.9, 41.753], [64304.3, 34.441], [64363.0, 16.252], [64374.8, 0.001], [64375.2, 27.418], [64383.2, 9.722], [64422.0, 5.624], [64438.9, 4.41], [64450.5, 0.01], [64461.9, 3.934], [64509.4, 0.051], [64560.6, 0.559], [64561.6, 0.576], [64566.7, 0.007], [64567.2, 0.002], [64570.1, 0.052], [64573.0, 0.097], [64573.8, 0.202], [64573.9, 0.073], [64574.0, 0.393], [64574.1, 0.38], [64574.5, 0.103], [64574.9, 0.012], [64576.1, 0.002]], "asks": [[64588.5, 0.541], [64588.8, 0.553], [64589.0, 0.303], [64589.1, 0.281], [64595.8, 0.621], [64595.9, 1.101], [64596.4, 0.542], [64597.0, 0.0], [64597.7, 0.002], [64598.0, 0.006], [64598.9, 0.943], [64601.5, 1.282], [64601.9, 0.558], [64602.4, 2.022], [64603.1, 0.116], [64607.7, 0.304], [64608.1, 0.471], [64608.2, 0.301], [64608.3, 0.15], [64608.4, 1.533], [64651.6, 0.36], [64718.8, 3.871], [64776.0, 17.98], [64779.8, 26.799], [64780.1, 0.0], [64803.7, 8.606], [64851.1, 34.097], [64851.3, 0.419], [64887.9, 26.295], [64948.4, 42.058], [64959.9, 15.81], [65226.4, 5.891], [65342.9, 5.056], [65349.1, 9.17], [65387.9, 20.22], [65472.1, 7.778]]}
{"kind": "depth", "E": 1787089968033, "U": 11316023567190, "u": 11316023570424, "recv_ms": 1787089967985, "bids": [[14180.5, 0.042], [14280.5, 3.71], [14380.5, 0.448], [58122.4, 0.004], [61351.4, 0.0], [61997.2, 0.003], [63580.5, 0.006], [63611.8, 14.978], [63805.5, 76.784], [63934.7, 6.226], [64257.6, 5.518], [64522.0, 0.195], [64522.3, 0.035], [64523.2, 1.137], [64547.6, 0.019], [64547.7, 0.004], [64547.8, 0.026], [64548.5, 10.0], [64551.1, 0.0], [64551.2, 0.003], [64551.3, 2.32], [64552.5, 0.081], [64554.7, 0.117], [64555.5, 1.372], [64568.9, 0.09], [64573.6, 0.003], [64574.0, 0.391], [64580.5, 3.711]], "asks": [[64580.6, 45.88], [64606.1, 0.314], [64695.6, 0.001], [64722.3, 1.47], [64776.0, 18.273], [65065.3, 53.196], [65214.9, 65.032], [65226.4, 5.891], [65349.1, 10.087], [65427.5, 3.827], [65580.6, 0.01]]}
{"kind": "depth", "E": 1787089968135, "U": 11316023570460, "u": 11316023573429, "recv_ms": 1787089968087, "bids": [[1000.0, 35.91], [14180.5, 0.224], [14280.5, 3.71], [14380.5, 0.266], [51664.0, 0.0], [58122.4, 0.004], [63599.4, 0.009], [63599.5, 5.534], [63733.7, 8.001], [63934.7, 6.226], [64257.5, 0.001], [64505.7, 0.001], [64522.6, 0.148], [64522.9, 0.032], [64548.9, 2.768], [64554.8, 0.073], [64555.1, 0.1], [64555.2, 1.181], [64568.9, 0.085]], "asks": [[64580.6, 45.887], [64584.6, 0.008], [64591.4, 0.09], [65226.4, 5.891], [65387.9, 20.067], [65420.1, 25.114], [65504.3, 1.677], [65561.6, 0.015], [65561.7, 0.012]]}
{"kind": "depth", "E": 1787089968237, "U": 11316023573492, "u": 11316023578729, "recv_ms": 1787089968189, "bids": [[1000.0, 35.76], [14180.5, 0.462], [14280.5, 3.584], [14380.5, 0.154], [51664.0, 0.0], [58122.4, 0.004], [61351.4, 0.0], [61997.2, 0.0], [62966.0, 4.583], [63580.5, 0.026], [63599.4, 0.028], [63611.8, 15.331], [63676.4, 65.959], [63773.2, 27.785], [63805.5, 77.409], [63934.7, 6.226], [64094.1, 52.908], [64257.6, 5.518], [64304.4, 5.146], [64363.0, 16.036], [64375.3, 4.409], [64422.1, 1.081], [64439.4, 1.411], [64481.4, 0.217], [64481.5, 0.004], [64534.0, 0.001], [64536.5, 0.709], [64554.5, 0.382], [64554.8, 0.143], [64555.0, 0.103], [64555.2, 1.281], [64555.3, 0.07], [64556.5, 0.104], [64556.9, 0.102], [64580.5, 4.305]], "asks": [[64580.6, 45.884], [64584.6, 0.007], [64595.8, 0.002], [64596.4, 0.0], [64597.2, 0.619], [64597.7, 0.544], [64612.8, 1.101], [64772.0, 0.0], [64772.1, 0.007], [64779.7, 0.216], [64803.7, 8.39], [64903.6, 0.002], [65226.4, 5.891], [65355.6, 72.23], [65561.6, 0.034], [65580.6, 0.03], [65872.2, 7.595]]}
{"kind": "depth", "E": 1787089968339, "U": 11316023578736, "u": 11316023582644, "recv_ms": 1787089968292, "bids": [[14180.5, 0.7], [14280.5, 3.472], [14380.5, 0.028], [51664.0, 0.0], [58122.4, 0.004], [61997.2, 0.003], [63605.2, 0.0], [63675.8, 13.266], [63934.7, 6.226], [64259.3, 0.108], [64554.6, 1.311], [64554.7, 0.187], [64554.9, 0.103], [64555.3, 0.17], [64565.5, 0.0], [64566.1, 0.927], [64567.1, 0.065], [64576.1, 0.086], [64579.3, 0.747], [64580.3, 0.002], [64580.5, 3.821]], "asks": [[64580.6, 45.884], [64595.8, 0.621], [64596.4, 0.542], [64597.2, 0.0], [64597.7, 0.002], [64598.9, 0.016], [64599.4, 0.945], [64600.5, 5.0], [64603.1, 0.0], [64603.7, 0.02], [64603.8, 0.187], [64654.1, 0.726], [64655.6, 0.012], [64655.7, 2.321], [64662.3, 39.406], [64720.2, 1.472], [64779.7, 4.412], [64912.8, 0.109], [64948.3, 10.317], [65226.4, 5.891], [65517.0, 44.186], [65678.5, 25.122], [65872.2, 7.592]]}
{"kind": "depth", "E": 1787089968441, "U": 11316023582726, "u": 11316023585834, "recv_ms": 1787089968393, "bids": [[1000.0, 35.76], [14180.5, 1.022], [14280.5, 3.178], [14380.5, 0.0], [58122.4, 0.004], [61351.5, 2.451], [61997.2, 0.0], [63288.9, 5.217], [63482.6, 19.236], [63676.4, 66.428], [63712.7, 1.569], [63934.7, 6.226], [64532.4, 0.316], [64542.9, 0.314], [64563.7, 0.003]], "asks": [[64596.1, 0.002], [64596.4, 0.0], [64597.7, 0.544], [64657.9, 39.494], [64662.3, 0.001], [65226.4, 5.891], [65407.5, 2.292]]}
{"kind": "depth", "E": 1787089968543, "U": 11316023585894, "u": 11316023590969, "recv_ms": 1787089968495, "bids": [[14180.5, 1.386], [14280.5, 2.814], [58122.4, 0.004], [61351.4, 0.0], [61351.6, 0.006], [61997.2, 0.003], [63580.5, 0.006], [63606.3, 0.275], [63934.7, 6.226], [64257.6, 5.518], [64474.3, 2.336], [64503.0, 0.023], [64528.8, 0.089], [64539.4, 0.0], [64541.0, 0.011], [64547.8, 0.026]], "asks": [[64580.6, 45.885], [64595.8, 0.002], [64597.0, 0.619], [64612.9, 0.021], [64619.4, 0.0], [64655.7, 41.786], [64657.9, 0.029], [64687.8, 2.323], [65226.4, 5.891], [65580.6, 0.01]]}
{"kind": "depth", "E": 1787089968645, "U": 11316023591043, "u": 11316023595118, "recv_ms": 1787089968597, "bids": [[14180.5, 1.736], [14280.5, 2.464], [51664.0, 0.0], [58122.4, 0.004], [61351.4, 0.0], [63664.0, 7.824], [63934.7, 6.226], [64257.6, 5.363], [64438.9, 4.382], [64439.4, 0.003], [64556.6, 0.064], [64560.0, 3.391], [64560.2, 1.247], [64567.5, 0.648], [64573.9, 0.071], [64577.5, 0.003]], "asks": [[64580.6, 45.892], [64598.4, 0.66], [64605.8, 0.62], [64720.2, 0.0], [64720.3, 5.408], [64776.0, 17.933], [65226.4, 5.891], [65342.9, 3.527], [65491.9, 1.524]]}
{"kind": "depth", "E": 1787089968747, "U": 11316023595420, "u": 11316023599340, "recv_ms": 1787089968699, "bids": [[1000.0, 35.76], [14180.5, 2.1], [14280.5, 2.1], [58122.4, 0.004], [61997.2, 0.0], [63580.5, 0.026], [63841.7, 0.782], [63934.7, 6.226], [63946.7, 73.012], [64450.5, 0.005], [64570.1, 0.057], [64580.3, 0.003]], "asks": [[64655.7, 2.321], [64657.9, 39.494], [64660.1, 0.013], [65097.2, 9.998], [65226.4, 5.891], [65420.1, 26.03], [65452.4, 19.654], [65580.6, 0.03], [65778.0, 0.153]]}
{"kind": "depth", "E": 1787089968849, "U": 11316023599445, "u": 11316023603926, "recv_ms": 1787089968803, "bids": [[14180.5, 2.464], [14280.5, 1.736], [58122.4, 0.004], [61351.4, 0.0], [61997.2, 0.003], [63288.9, 5.22], [63773.2, 27.551], [63825.5, 2.809], [63837.8, 8.842], [63934.7, 6.226], [64257.6, 5.518], [64422.0, 4.745], [64438.9, 3.94], [64450.5, 0.01], [64515.9, 0.022], [64570.1, 0.052], [64576.5, 0.085]], "asks": [[64580.6, 45.892], [64645.2, 0.362], [64720.3, 5.408], [64737.2, 10.676], [65226.4, 5.891], [65226.5, 0.004]]}
{"kind": "depth", "E": 1787089968951, "U": 11316023603929, "u": 11316023608734, "recv_ms": 1787089968903, "bids": [[14180.5, 2.814], [14280.5, 1.386], [51664.4, 0.0], [58122.4, 0.004], [61351.5, 2.451], [61351.6, 0.008], [61997.2, 0.0], [63580.5, 0.006], [63676.4, 68.779], [63733.8, 5.33], [63773.2, 27.2], [63934.7, 6.226], [64438.9, 0.033], [64503.0, 0.023], [64522.3, 0.032], [64577.8, 0.003]], "asks": [[64612.9, 0.021], [64638.8, 0.0], [64720.3, 0.0], [65097.2, 10.305], [65194.1, 26.469], [65226.4, 5.891], [65355.6, 72.444], [65580.6, 0.01]]}
{"kind": "depth", "E": 1787089969053, "U": 11316023608839, "u": 11316023613990, "recv_ms": 1787089969005, "bids": [[1000.0, 35.76], [14180.5, 3.164], [14280.5, 1.036], [58122.4, 0.004], [61351.4, 0.0], [63644.1, 44.175], [63663.5, 3.306], [63805.5, 77.19], [63934.7, 6.226], [64063.9, 10.472], [64383.2, 5.033], [64422.0, 2.99], [64422.1, 0.0], [64438.9, 4.124], [64450.5, 0.005], [64560.2, 0.628], [64560.6, 0.001], [64561.5, 0.612], [64567.5, 0.029], [64568.9, 0.09], [64570.1, 0.057], [64573.0, 0.013], [64577.3, 0.1], [64579.7, 0.082], [64579.9, 0.003], [64580.5, 4.324]], "asks": [[64580.6, 45.807], [64581.6, 0.13], [64598.4, 0.041], [64605.8, 0.001], [64647.8, 0.477], [64720.3, 5.408], [64737.2, 10.676], [65226.4, 5.891], [65452.4, 20.385], [65788.3, 6.899]]}
{"kind": "depth", "E": 1787089969155, "U": 11316023614173, "u": 11316023618823, "recv_ms": 1787089969107, "bids": [[14180.5, 3.528], [14280.5, 0.672], [58122.4, 0.004], [61997.2, 0.003], [63288.9, 5.223], [63580.5, 0.026], [63599.4, 0.036], [63599.5, 5.526], [63664.0, 7.832], [63664.1, 0.0], [63665.1, 0.009], [63665.3, 0.188], [63805.5, 76.564], [63837.8, 10.72], [63934.7, 6.226], [64063.9, 10.16], [64208.0, 7.592], [64226.1, 0.343], [64257.6, 5.528], [64300.0, 85.172], [64383.2, 9.835], [64422.0, 5.66], [64438.9, 4.702], [64450.5, 0.01], [64568.9, 0.085], [64570.1, 0.052], [64580.5, 4.323]], "asks": [[64580.6, 45.806], [64585.2, 0.004], [64776.0, 17.55], [65194.1, 27.157], [65226.4, 5.891], [65495.9, 0.002], [65497.1, 0.004], [65561.7, 0.004], [65580.6, 0.03]]}
{"kind": "depth", "E": 1787089969257, "U": 11316023618941, "u": 11316023623404, "recv_ms": 1787089969211, "bids": [[14080.5, 0.07], [14180.5, 3.738], [14280.5, 0.392], [51664.0, 0.0], [58122.4, 0.004], [61351.4, 0.0], [61997.2, 0.0], [63288.9, 5.22], [63644.1, 45.273], [63676.4, 68.967], [63934.7, 6.226], [64450.5, 0.005], [64536.5, 0.681], [64570.1, 0.057], [64573.3, 0.311], [64576.9, 0.085], [64577.3, 0.016], [64577.4, 0.088], [64580.5, 3.818]], "asks": [[64580.6, 45.803], [64580.8, 0.109], [64585.2, 0.003], [64597.0, 0.0], [64597.4, 0.624], [64627.1, 0.058], [64903.6, 0.0], [65226.4, 5.891], [65495.8, 0.008], [65497.0, 0.692], [65561.6, 0.042]]}
{"kind": "depth", "E": 1787089969359, "U": 11316023623555, "u": 11316023627527, "recv_ms": 1787089969311, "bids": [[1000.0, 35.76], [14080.5, 0.28], [14180.5, 3.682], [14280.5, 0.238], [51664.0, 0.0], [58122.4, 0.004], [61351.4, 0.0], [61997.2, 0.003], [63580.5, 0.006], [63805.5, 77.19], [63934.7, 6.226], [63951.7, 0.007], [64063.9, 10.783], [64257.5, 0.003], [64536.5, 0.709], [64577.4, 0.004], [64580.5, 3.809]], "asks": [[64580.6, 45.804], [64580.7, 0.108], [64580.8, 0.143], [64581.2, 0.0], [64581.3, 0.088], [64598.6, 2.721], [64600.0, 3.71], [64627.1, 0.002], [64640.1, 0.009], [64647.8, 0.468], [64657.5, 6.243], [64720.2, 1.472], [64849.9, 8.515], [65184.4, 0.059], [65226.4, 5.891], [65580.6, 0.01], [65691.4, 3.06]]}
{"kind": "depth", "E": 1787089969461, "U": 11316023627567, "u": 11316023631277, "recv_ms": 1787089969413, "bids": [[14080.5, 0.518], [14180.5, 3.556], [14280.5, 0.126], [58122.4, 0.004], [61351.4, 0.0], [61997.2, 0.0], [63708.7, 19.716], [63824.9, 6.605], [63837.8, 9.782], [63934.7, 6.226], [64063.9, 10.471], [64257.6, 5.518], [64450.5, 0.01], [64563.7, 0.003], [64570.1, 0.052], [64580.5, 3.705]], "asks": [[64580.6, 45.805], [64580.9, 0.036], [64596.1, 0.002], [65226.4, 5.891], [65872.2, 7.589]]}
{"kind": "depth", "E": 1787089969563, "U": 11316023631475, "u": 11316023637643, "recv_ms": 1787089969516, "bids": [[1000.0, 35.76], [14080.5, 0.756], [14180.5, 3.444], [14280.5, 0.0], [58122.4, 0.004], [61351.4, 0.0], [63580.5, 0.026], [63766.0, 3.974], [63934.7, 6.226], [63966.8, 1.343], [64438.1, 0.036], [64546.4, 10.002], [64548.5, 0.0], [64548.9, 1.275], [64560.6, 0.559], [64561.5, 0.054], [64563.3, 0.238], [64563.6, 0.008], [64570.5, 0.569], [64570.6, 1.727], [64570.7, 1.555], [64570.9, 0.088], [64572.7, 0.004], [64573.0, 0.097], [64573.3, 0.395], [64573.5, 0.234], [64573.6, 0.001], [64574.0, 0.159], [64575.7, 1.217], [64575.8, 0.086], [64576.1, 0.086], [64576.3, 0.345], [64576.5, 0.009], [64576.6, 0.086], [64576.7, 0.007], [64576.9, 0.001], [64577.4, 0.001], [64579.3, 0.753], [64580.5, 3.703]], "asks": [[64580.6, 45.838], [64581.9, 0.004], [64596.4, 0.542], [64597.7, 0.002], [64598.3, 0.927], [64599.4, 0.018], [64600.9, 10.003], [64602.4, 0.022], [64602.5, 0.003], [64603.1, 0.116], [64603.8, 0.071], [64722.3, 1.47], [65194.3, 2.683], [65226.4, 5.891], [65580.6, 0.03]]}
{"kind": "depth", "E": 1787089969665, "U": 11316023637780, "u": 11316023642035, "recv_ms": 1787089969618, "bids": [[1000.0, 35.76], [14080.5, 1.106], [14180.5, 3.094], [58122.4, 0.006], [61351.4, 0.0], [61997.2, 0.003], [63708.7, 20.107], [63824.9, 7.153], [63934.7, 6.226], [64522.3, 0.035], [64528.8, 0.092], [64561.2, 0.621], [64568.6, 0.62], [64572.7, 0.002], [64573.6, 0.003], [64580.5, 3.8]], "asks": [[64580.6, 45.814], [64596.4, 0.0], [64597.3, 0.723], [64598.4, 0.66], [64600.9, 0.003], [64605.4, 2.82], [64605.8, 0.62], [64619.4, 0.003], [64638.8, 0.003], [65226.4, 5.891], [65278.4, 0.0], [65484.7, 97.582], [65529.9, 21.471], [65536.6, 0.762], [65691.4, 3.819]]}
{"kind": "depth", "E": 1787089969767, "U": 11316023642188, "u": 11316023646542, "recv_ms": 1787089969720, "bids": [[14080.5, 1.47], [14180.5, 2.73], [58122.4, 0.004], [61351.4, 0.0], [61997.2, 0.0], [63004.0, 0.72], [63580.5, 0.006], [63837.8, 10.72], [63934.7, 6.226], [64063.9, 10.783], [64257.6, 5.518], [64500.7, 0.116], [64546.4, 0.002], [64551.6, 2.107], [64560.6, 0.001], [64560.7, 0.002], [64561.6, 0.576], [64561.7, 0.56], [64563.3, 0.23], [64563.7, 0.011], [64568.6, 0.001], [64570.8, 0.257], [64570.9, 0.08], [64573.0, 0.013], [64573.3, 0.311], [64573.7, 0.001], [64576.5, 0.001], [64577.1, 0.138], [64577.7, 0.084], [64578.1, 0.084], [64580.5, 4.308]], "asks": [[64580.6, 45.814], [64580.7, 0.069], [64580.8, 0.059], [64581.3, 0.004], [64581.6, 0.046], [64584.2, 0.086], [64585.0, 0.106], [64598.3, 0.0], [64598.4, 0.041], [64598.9, 0.943], [64605.8, 0.001], [64695.6, 0.101], [64903.5, 4.77], [65226.4, 5.891], [65291.0, 15.545], [65387.9, 20.22], [65529.9, 22.689], [65549.3, 27.446], [65580.6, 0.01], [65872.2, 7.592]]}
{"kind": "depth", "E": 1787089969869, "U": 11316023646569, "u": 11316023649812, "recv_ms": 1787089969822, "bids": [[1000.0, 35.76], [14080.5, 1.834], [14180.5, 2.366], [51664.0, 0.0], [58122.4, 0.004], [61997.2, 0.003], [63579.5, 31.57], [63675.8, 12.797], [63934.7, 6.226], [64257.6, 5.363], [64563.7, 0.003], [64570.9, 0.088], [64574.5, 0.1], [64575.1, 0.004], [64575.4, 0.007]], "asks": [[64580.6, 45.7], [64584.7, 0.085], [64627.1, 0.058], [65226.4, 5.891], [65226.5, 0.003], [65581.6, 32.997]]}
{"kind": "depth", "E": 1787089969971, "U": 11316023649817, "u": 11316023653584, "recv_ms": 1787089969924, "bids": [[1000.0, 35.76], [14080.5, 2.184], [14180.5, 2.016], [51664.4, 0.0], [58122.4, 0.004], [61997.2, 0.0], [63580.5, 0.026], [63708.7, 19.481], [63773.2, 27.7], [63785.2, 2.475], [63812.0, 9.591], [63934.7, 6.226], [64559.7, 0.0], [64560.8, 0.117], [64562.3, 0.002], [64562.4, 0.01], [64563.2, 0.044]], "asks": [[64603.1, 0.0], [64603.6, 0.148], [64606.7, 0.008], [64613.2, 0.071], [64737.2, 10.676], [64737.3, 0.001], [65149.8, 0.155], [65226.4, 5.891], [65286.4, 3.825], [65580.6, 0.03]]}
{"kind": "depth", "E": 1787089970073, "U": 11316023653670, "u": 11316023657984, "recv_ms": 1787089970026, "bids": [[14080.5, 2.548], [14180.5, 1.652], [51664.0, 0.004], [58122.4, 0.004], [61351.4, 0.0], [63599.4, 0.028], [63676.4, 69.436], [63712.7, 0.785], [63890.0, 2.268], [63934.7, 6.228], [64257.6, 5.518], [64530.0, 0.093], [64531.1, 0.001], [64568.9, 0.085], [64580.5, 4.615]], "asks": [[64633.5, 0.114], [64634.5, 0.02], [64903.5, 4.924], [65226.4, 5.891], [65427.8, 0.001], [65561.6, 0.034], [65872.2, 7.595]]}
{"kind": "depth", "E": 1787089970175, "U": 11316023658023, "u": 11316023662632, "recv_ms": 1787089970129, "bids": [[1000.0, 35.76], [14080.5, 2.898], [14180.5, 1.302], [51664.0, 0.002], [58122.4, 0.004], [61351.4, 0.0], [61997.2, 0.003], [63579.5, 31.569], [63580.5, 0.006], [63599.5, 5.534], [63644.1, 44.174], [63733.8, 6.113], [63837.8, 9.781], [63934.7, 6.226], [64470.7, 3.022], [64503.0, 0.02], [64522.3, 0.032], [64534.0, 0.015], [64575.4, 0.004], [64577.6, 0.001], [64577.7, 0.085], [64578.1, 0.0], [64578.2, 0.001], [64580.5, 4.539]], "asks": [[64580.6, 45.8], [64581.6, 0.13], [64583.6, 0.001], [64583.7, 0.007], [64584.3, 0.003], [64586.7, 0.077], [64612.9, 0.021], [64638.8, 0.0], [65226.4, 5.891], [65580.6, 0.01], [65581.6, 34.063]]}
{"kind": "depth", "E": 1787089970277, "U": 11316023662669, "u": 11316023667840, "recv_ms": 1787089970254, "bids": [[1000.0, 35.76], [14080.5, 3.248], [14180.5, 0.952], [51664.0, 0.0], [58122.4, 0.004], [61351.6, 0.006], [61997.2, 0.0], [63708.7, 20.107], [63741.0, 19.545], [63812.0, 10.53], [63902.4, 4.061], [63934.7, 6.226], [64383.2, 9.783], [64383.3, 1.683], [64422.0, 5.542], [64422.1, 1.069], [64439.4, 1.455]], "asks": [[64776.0, 17.759], [65226.4, 5.891], [65336.2, 5.885], [65423.0, 2.085], [65517.0, 43.119], [65551.4, 0.0], [65561.7, 0.012], [65613.9, 16.103]]}
{"kind": "depth", "E": 1787089970379, "U": 11316023667967, "u": 11316023672509, "recv_ms": 1787089970330, "bids": [[14080.5, 3.612], [14180.5, 0.588], [58122.4, 0.004], [61997.2, 0.003], [63934.7, 6.226], [64257.5, 0.001], [64257.6, 5.518], [64302.7, 0.954], [64517.7, 0.017], [64517.8, 4.428]], "asks": [[64625.3, 3.502], [64626.4, 0.0], [64707.6, 0.798], [64737.1, 2.293], [64850.0, 25.612], [65226.4, 5.891], [65387.9, 19.877], [65549.3, 27.066], [65613.9, 17.168], [65872.2, 7.595]]}
{"kind": "depth", "E": 1787089970481, "U": 11316023672638, "u": 11316023676622, "recv_ms": 1787089970454, "bids": [[1000.0, 35.76], [14080.5, 3.766], [14180.5, 0.336], [14480.5, 0.098], [58122.4, 0.004], [63579.5, 32.669], [63644.1, 45.273], [63734.4, 0.0], [63741.0, 19.858], [63805.5, 76.72], [63837.8, 10.72], [63862.8, 11.322], [63934.7, 6.226], [64563.7, 0.003], [64573.5, 0.002], [64574.0, 0.391], [64577.7, 0.001]], "asks": [[64584.2, 0.396], [64596.1, 0.002], [65226.4, 5.891], [65322.7, 0.0], [65336.2, 6.42], [65355.6, 73.972], [65452.4, 19.623], [65549.4, 1.668]]}
{"kind": "depth", "E": 1787089970583, "U": 11316023676724, "u": 11316023680615, "recv_ms": 1787089970535, "bids": [[1000.0, 35.76], [14080.5, 3.654], [14180.5, 0.21], [14480.5, 0.336], [58122.4, 0.004], [61997.2, 0.0], [63390.0, 0.824], [63580.5, 0.026], [63631.2, 24.937], [63825.5, 1.871], [63934.7, 6.226], [64383.2, 0.004], [64422.0, 0.011], [64438.9, 0.033], [64532.4, 0.32], [64541.0, 0.007]], "asks": [[64580.7, 0.088], [64581.2, 0.084], [64720.3, 0.0], [64737.2, 0.249], [64776.0, 7.421], [64903.6, 0.002], [65226.4, 5.891], [65517.0, 44.186], [65549.3, 27.446], [65580.6, 0.03]]}
{"kind": "depth", "E": 1787089970685, "U": 11316023680692, "u": 11316023685897, "recv_ms": 1787089970639, "bids": [[14080.5, 3.528], [14180.5, 0.098], [14480.5, 0.574], [58122.4, 0.004], [61997.2, 0.003], [63631.8, 1.428], [63644.1, 46.214], [63663.5, 3.54], [63735.5, 0.274], [63773.2, 27.934], [63805.5, 76.939], [63837.8, 11.658], [63934.7, 6.226], [64257.6, 5.528], [64383.3, 0.08], [64422.1, 0.0], [64439.4, 0.003]], "asks": [[64582.7, 0.252], [64582.9, 0.332], [64627.1, 0.002], [64720.2, 0.0], [64737.1, 0.0], [64775.9, 1.244], [65226.4, 5.891]]}
{"kind": "depth", "E": 1787089970787, "U": 11316023686081, "u": 11316023691368, "recv_ms": 1787089970741, "bids": [[1000.0, 35.76], [14080.5, 3.36], [14180.5, 0.0], [14480.5, 0.84], [58122.4, 0.004], [61351.4, 0.0], [61351.5, 2.449], [61351.6, 0.008], [61997.2, 0.0], [63514.9, 6.592], [63580.5, 0.006], [63773.2, 28.285], [63805.5, 77.409], [63934.7, 6.226], [64383.2, 3.374], [64422.0, 3.116], [64438.9, 2.825], [64517.8, 0.016], [64517.9, 1.042], [64560.3, 2.437], [64560.8, 0.001], [64567.6, 0.165], [64568.1, 0.944]], "asks": [[64580.6, 45.8], [64588.3, 2.286], [64598.2, 0.62], [64605.6, 1.82], [64609.4, 0.003], [64609.5, 0.014], [64609.6, 7.132], [64612.4, 0.003], [64612.5, 0.002], [64612.6, 0.002], [64613.3, 0.002], [64613.4, 0.095], [64613.5, 0.277], [64615.4, 0.031], [64615.5, 0.003], [64615.6, 1.142], [64632.2, 0.288], [64643.4, 0.093], [64655.7, 41.823], [64657.9, 0.029], [64720.3, 5.408], [64737.2, 10.676], [64776.0, 22.859], [64779.7, 4.196], [64803.7, 8.606], [65226.4, 5.891], [65452.4, 20.385], [65580.6, 0.01]]}
{"kind": "depth", "E": 1787089970889, "U": 11316023691549, "u": 11316023696288, "recv_ms": 1787089970841, "bids": [[1000.0, 35.76], [14080.5, 2.996], [14480.5, 1.204], [58122.4, 0.004], [61351.4, 0.0], [61997.2, 0.003], [63514.9, 7.693], [63631.2, 26.27], [63934.7, 6.226], [64469.3, 0.018], [64469.4, 0.0], [64470.2, 1.261], [64580.5, 4.533]], "asks": [[64580.6, 45.8], [64632.2, 0.357], [64654.1, 6.546], [64657.5, 0.404], [64691.7, 0.0], [64691.8, 0.0], [65226.4, 5.891], [65350.9, 2.454]]}
{"kind": "depth", "E": 1787089970991, "U": 11316023696319, "u": 11316023700410, "recv_ms": 1787089970944, "bids": [[14080.5, 2.646], [14480.5, 1.554], [51664.4, 0.0], [58122.4, 0.004], [63580.5, 0.026], [63934.7, 6.226], [64257.6, 5.518], [64431.7, 0.025], [64431.8, 0.01], [64438.9, 0.033], [64562.4, 0.002], [64563.2, 0.052]], "asks": [[64580.6, 45.851], [64580.8, 0.143], [64585.0, 0.022], [64720.3, 0.0], [64727.7, 0.294], [64729.3, 0.0], [65226.4, 5.891], [65387.9, 19.649], [65537.3, 0.0], [65580.6, 0.03]]}
{"kind": "depth", "E": 1787089971093, "U": 11316023700560, "u": 11316023705466, "recv_ms": 1787089971046, "bids": [[1000.0, 35.76], [14080.5, 2.282], [14480.5, 1.918], [58122.4, 0.004], [61997.2, 0.0], [63611.8, 15.323], [63644.1, 45.117], [63934.7, 6.226], [64383.2, 9.783], [64422.0, 5.542], [64432.0, 14.962], [64438.9, 3.198], [64469.3, 11.554], [64517.8, 4.371], [64532.4, 0.316], [64543.2, 1.06], [64568.9, 0.085]], "asks": [[64583.4, 0.144], [64643.3, 2.209], [64654.1, 0.726], [64655.7, 2.321], [64662.3, 39.669], [64691.8, 9.164], [64720.3, 5.408], [64729.1, 11.827], [64737.2, 10.676], [64737.3, 0.001], [64776.0, 17.777], [64779.7, 4.412], [64781.0, 19.269], [64803.7, 8.39], [65226.4, 5.891], [65363.5, 0.062]]}
{"kind": "depth", "E": 1787089971297, "U": 11316023711843, "u": 11316023717698, "recv_ms": 1787089971251, "bids": [[14080.5, 1.582], [14480.5, 2.618], [58122.4, 0.004], [61351.4, 0.0], [61997.2, 0.0], [63288.9, 5.223], [63514.9, 7.693], [63580.5, 0.006], [63644.1, 46.214], [63842.0, 0.046], [63934.7, 6.226], [64257.6, 5.518], [64383.2, 4.357], [64438.9, 2.266]], "asks": [[64580.6, 45.851], [64638.1, 0.095], [64644.9, 0.005], [64720.3, 5.408], [64780.9, 0.473], [64781.0, 8.463], [65226.4, 5.891], [65580.6, 0.01]]}
{"kind": "depth", "E": 1787089971501, "U": 11316023723771, "u": 11316023728815, "recv_ms": 1787089971463, "bids": [[1000.0, 35.76], [14080.5, 0.868], [14480.5, 3.332], [58122.4, 0.004], [61351.4, 0.0], [61351.5, 2.451], [61997.2, 0.003], [63580.5, 0.026], [63712.7, 0.001], [63735.6, 0.535], [63934.7, 6.226], [64063.9, 10.783], [64383.2, 8.48], [64422.0, 4.117], [64438.9, 3.633], [64470.7, 3.019], [64517.8, 4.353], [64522.3, 0.035], [64532.4, 0.316], [64543.2, 1.06], [64563.7, 0.003]], "asks": [[64580.6, 45.851], [64583.4, 0.163], [64596.1, 0.002], [64612.9, 0.021], [64640.1, 0.0], [64643.3, 2.209], [64655.7, 41.989], [64657.9, 0.029], [65226.4, 5.891], [65355.6, 73.758], [65484.7, 97.399], [65580.6, 0.03]]}
{"kind": "depth", "E": 1787089971603, "U": 11316023728904, "u": 11316023733096, "recv_ms": 1787089971556, "bids": [[14080.5, 0.504], [14480.5, 3.696], [58122.4, 0.004], [61351.5, 2.453], [61997.2, 0.0], [63934.7, 6.226], [64257.6, 5.518]], "asks": [[64618.4, 0.006], [64655.7, 2.321], [64660.1, 39.681], [64903.6, 0.0], [65161.9, 16.121], [65226.4, 5.891], [65407.5, 0.002]]}
{"kind": "depth", "E": 1787089971705, "U": 11316023733164, "u": 11316023737340, "recv_ms": 1787089971659, "bids": [[1000.0, 35.76], [14080.5, 0.308], [14380.5, 0.154], [14480.5, 3.738], [58122.4, 0.004], [61997.2, 0.003], [63644.1, 45.116], [63772.7, 4.221], [63773.2, 28.051], [63837.8, 10.719], [63934.7, 6.226], [64257.5, 0.003], [64438.9, 4.418]], "asks": [[64617.7, 0.215], [64720.2, 0.0], [64720.3, 5.408], [64776.0, 17.944], [65097.2, 10.305], [65226.4, 5.891], [65298.2, 5.355], [65355.6, 73.148], [65387.3, 3.55]]}
{"kind": "depth", "E": 1787089971807, "U": 11316023737520, "u": 11316023741974, "recv_ms": 1787089971759, "bids": [[1000.0, 35.76], [14080.5, 0.182], [14380.5, 0.392], [14480.5, 3.626], [58122.4, 0.004], [61351.4, 0.0], [61997.2, 0.0], [63580.5, 0.006], [63733.7, 8.784], [63798.3, 4.698], [63934.7, 6.226], [64383.2, 5.123], [64422.0, 3.049], [64450.5, 0.005], [64503.0, 0.023], [64570.1, 0.057]], "asks": [[64580.6, 45.851], [64638.8, 0.003], [64657.9, 39.697], [64660.1, 0.013], [65226.4, 5.891], [65355.6, 73.758], [65580.6, 0.01]]}
{"kind": "depth", "E": 1787089971909, "U": 11316023742093, "u": 11316023745943, "recv_ms": 1787089971864, "bids": [[14080.5, 0.07], [14380.5, 0.63], [14480.5, 3.5], [58122.4, 0.004], [63728.6, 0.0], [63773.2, 27.817], [63934.7, 6.226], [64257.6, 5.518], [64450.5, 0.01], [64570.1, 0.052]], "asks": [[65226.4, 5.891], [65351.0, 2.678], [65420.1, 28.319], [65472.1, 5.49], [65872.2, 7.592]]}
{"kind": "depth", "E": 1787089972011, "U": 11316023746103, "u": 11316023752316, "recv_ms": 1787089971964, "bids": [[1000.0, 35.76], [14080.5, 0.0], [14380.5, 0.924], [14480.5, 3.276], [51664.4, 0.0], [58122.4, 0.004], [61997.2, 0.003], [63580.5, 0.026], [63611.7, 2.063], [63741.0, 21.816], [63934.7, 6.228], [64383.2, 9.717], [64422.0, 5.616], [64549.4, 0.011], [64551.7, 0.534], [64552.0, 1.179], [64556.6, 0.015], [64556.7, 0.073], [64560.2, 0.677], [64561.3, 0.56], [64561.7, 0.002], [64562.3, 0.01], [64563.2, 0.044], [64566.4, 0.024], [64566.5, 0.543], [64566.7, 0.007], [64568.2, 0.302], [64573.7, 0.085], [64577.0, 0.085], [64577.1, 0.054]], "asks": [[64584.3, 0.0], [64598.9, 0.016], [64599.5, 0.928], [64601.5, 1.839], [64601.9, 0.001], [64602.5, 0.003], [64776.0, 17.991], [65226.4, 5.891], [65580.6, 0.03]]}
{"kind": "depth", "E": 1787089972113, "U": 11316023752374, "u": 11316023757184, "recv_ms": 1787089972071, "bids": [[1000.0, 35.76], [14380.5, 1.274], [14480.5, 2.926], [58122.4, 0.004], [61351.4, 0.0], [61351.5, 2.449], [61351.6, 0.012], [61997.2, 0.0], [63579.5, 31.571], [63644.1, 46.214], [63777.3, 0.786], [63837.8, 11.658], [63934.7, 6.226], [64450.5, 0.005], [64550.2, 0.074], [64556.7, 0.003], [64568.9, 0.085], [64570.1, 0.057], [64580.5, 4.533]], "asks": [[64586.7, 0.076], [65226.4, 5.891], [65387.9, 19.992], [65613.9, 16.742]]}
{"kind": "depth", "E": 1787089972215, "U": 11316023757362, "u": 11316023762743, "recv_ms": 1787089972168, "bids": [[14380.5, 1.638], [14480.5, 2.562], [58122.4, 0.004], [61351.4, 0.0], [61997.2, 0.003], [63580.5, 0.006], [63934.7, 6.226], [64257.6, 5.528]], "asks": [[64580.6, 45.852], [64588.7, 0.482], [64776.0, 17.852], [65226.4, 5.891], [65580.6, 0.01]]}
{"kind": "depth", "E": 1787089972317, "U": 11316023762884, "u": 11316023768222, "recv_ms": 1787089972272, "bids": [[1000.0, 35.76], [14380.5, 2.002], [14480.5, 2.198], [51664.0, 0.0], [58122.4, 0.004], [61351.4, 0.0], [61997.2, 0.0], [63288.9, 5.22], [63410.8, 3.152], [63579.5, 32.669], [63772.7, 3.987], [63775.2, 2.377], [63934.7, 6.226]], "asks": [[64580.6, 45.852], [64601.5, 1.282], [64602.3, 1.828], [65226.4, 5.891], [65323.3, 0.381]]}
{"kind": "depth", "E": 1787089972419, "U": 11316023768275, "u": 11316023775366, "recv_ms": 1787089972375, "bids": [[1000.0, 35.76], [14380.5, 2.352], [14480.5, 1.848], [51664.0, 0.0], [58122.4, 0.004], [63805.5, 79.052], [63934.7, 6.226], [64383.3, 1.674], [64422.1, 1.08], [64439.4, 1.413], [64470.2, 2.823], [64517.9, 1.562]], "asks": [[64657.5, 6.273], [64695.6, 0.001], [64720.2, 1.472], [64780.9, 2.571], [64903.5, 4.77], [65226.4, 5.891], [65613.9, 17.168]]}
{"kind": "depth", "E": 1787089972521, "U": 11316023775532, "u": 11316023782171, "recv_ms": 1787089972473, "bids": [[14380.5, 2.702], [14480.5, 1.498], [58122.4, 0.004], [61351.4, 0.001], [61997.2, 0.003], [63580.5, 0.026], [63712.6, 0.029], [63934.7, 6.226], [64257.6, 5.528], [64438.9, 0.033], [64544.7, 0.0], [64550.5, 0.042], [64560.7, 0.002], [64563.7, 0.001], [64574.0, 0.159], [64574.3, 0.332]], "asks": [[64580.6, 45.884], [64596.1, 0.0], [64638.0, 0.016], [64644.9, 0.005], [64720.3, 0.0], [65226.4, 5.891], [65452.4, 19.623], [65580.6, 0.03]]}
{"kind": "depth", "E": 1787089972623, "U": 11316023782417, "u": 11316023787759, "recv_ms": 1787089972606, "bids": [[1000.0, 35.76], [14380.5, 3.066], [14480.5, 1.134], [58122.4, 0.004], [61351.4, 0.0], [61997.2, 0.0], [63173.2, 1.354], [63599.5, 3.964], [63934.7, 6.226], [64257.5, 0.001], [64422.0, 0.011], [64422.1, 0.0], [64439.4, 0.003], [64545.1, 0.04], [64550.5, 0.002], [64563.7, 0.003]], "asks": [[64580.6, 45.857], [64596.1, 0.002], [64606.0, 0.34], [64613.2, 0.001], [64638.0, 0.02], [64644.9, 0.001], [64720.2, 0.0], [64737.2, 0.249], [64903.5, 4.924], [64903.6, 0.002], [65226.4, 5.891], [65362.8, 8.423]]}
{"kind": "depth", "E": 1787089972725, "U": 11316023787893, "u": 11316023793764, "recv_ms": 1787089972679, "bids": [[1000.0, 35.76], [14380.5, 3.416], [14480.5, 0.784], [58122.4, 0.004], [61351.4, 0.0], [61997.2, 0.003], [63288.4, 0.092], [63360.2, 2.13], [63431.9, 0.009], [63503.7, 0.0], [63575.4, 0.001], [63647.2, 0.0], [63718.9, 0.0], [63790.7, 0.002], [63862.4, 0.806], [63934.2, 0.0], [63934.7, 6.226], [64386.8, 0.005], [64422.0, 4.702], [64438.9, 4.18], [64450.5, 0.01], [64470.7, 3.022], [64503.0, 0.02], [64522.3, 0.032], [64536.7, 0.006], [64543.2, 1.056], [64550.4, 0.058], [64560.2, 0.628], [64570.1, 0.052]], "asks": [[64612.9, 0.021], [64638.8, 0.0], [64720.3, 5.408], [64737.2, 10.676], [64903.5, 4.308], [65225.8, 0.0], [65226.4, 5.893], [65297.6, 0.0], [65362.8, 9.187], [65369.3, 0.006], [65387.9, 20.221], [65441.1, 0.014], [65452.4, 20.386], [65512.8, 0.0], [65549.3, 27.522], [65584.6, 0.0], [65656.3, 0.0], [65728.1, 0.0], [65799.8, 0.004], [65871.6, 0.002]]}
{"kind": "depth", "E": 1787089972827, "U": 11316023793789, "u": 11316023799785, "recv_ms": 1787089972780, "bids": [[14280.5, 0.028], [14380.5, 3.724], [14480.5, 0.448], [51664.0, 0.0], [58122.4, 0.004], [63288.9, 5.223], [63580.5, 0.006], [63934.7, 6.226], [64257.6, 5.528]], "asks": [[64584.2, 0.399], [65226.4, 5.891], [65580.6, 0.01]]}
{"kind": "depth", "E": 1787089972929, "U": 11316023799930, "u": 11316023806224, "recv_ms": 1787089972882, "bids": [[1000.0, 35.76], [14280.5, 0.21], [14380.5, 3.71], [14480.5, 0.28], [58122.4, 0.004], [61351.4, 0.0], [61997.2, 0.0], [63611.8, 16.892], [63934.7, 6.226], [64450.5, 0.005], [64461.9, 0.063], [64462.0, 3.878], [64474.3, 2.336], [64509.4, 0.051], [64517.8, 4.407], [64530.0, 0.032], [64530.1, 0.064], [64534.6, 2.329], [64552.0, 1.179], [64559.4, 0.0], [64560.3, 2.321], [64560.4, 0.603], [64560.6, 0.001], [64561.3, 0.002], [64561.6, 1.134], [64565.5, 0.927], [64566.1, 0.0], [64570.1, 0.057]], "asks": [[64580.6, 45.876], [64580.8, 0.059], [64594.6, 0.057], [64595.8, 0.002], [64597.3, 0.723], [64598.0, 0.006], [64598.8, 0.969], [64599.5, 0.001], [64601.0, 0.0], [64601.5, 1.242], [64601.9, 0.558], [64602.2, 0.818], [64602.3, 1.271], [64603.1, 0.116], [64603.6, 0.032], [64640.1, 0.009], [64643.3, 2.221], [64651.6, 0.36], [64687.8, 2.323], [64718.8, 0.0], [64719.4, 3.876], [65226.4, 5.891], [65517.0, 43.119]]}
{"kind": "depth", "E": 1787089973031, "U": 11316023806374, "u": 11316023811233, "recv_ms": 1787089972993, "bids": [[1000.0, 35.76], [14280.5, 0.448], [14380.5, 3.598], [14480.5, 0.154], [51664.4, 0.0], [58122.4, 0.004], [61997.2, 0.003], [63580.5, 0.026], [63825.5, 0.932], [63863.1, 1.564], [63919.5, 0.01], [63934.7, 6.226], [64438.9, 4.658], [64450.5, 0.01], [64535.3, 0.375], [64550.4, 0.009], [64557.6, 0.143], [64570.1, 0.052]], "asks": [[64720.3, 5.408], [64776.0, 17.626], [64903.5, 4.924], [65575.5, 1.963], [65580.6, 0.03]]}
{"kind": "depth", "E": 1787089973133, "U": 11316023811318, "u": 11316023815969, "recv_ms": 1787089973089, "bids": [[14280.5, 0.7], [14380.5, 3.458], [14480.5, 0.042], [51664.0, 0.0], [58122.4, 0.004], [61351.4, 0.0], [61997.2, 0.0], [63934.7, 6.226], [64257.6, 5.528], [64536.7, 0.002], [64543.2, 1.06], [64568.9, 0.085]], "asks": [[64580.6, 45.861], [64586.0, 0.008], [64588.7, 0.481], [64609.4, 0.001], [64609.5, 0.012], [64609.6, 7.13], [64612.4, 0.001], [64612.5, 0.0], [64612.6, 0.0], [64613.3, 0.0], [64613.4, 0.093], [64613.5, 0.275], [64615.4, 0.029], [64615.5, 0.001], [64615.6, 1.14], [64617.7, 0.061], [64617.8, 0.155], [65226.4, 5.891], [65517.0, 44.186]]}
{"kind": "depth", "E": 1787089973235, "U": 11316023815996, "u": 11316023828237, "recv_ms": 1787089973192, "bids": [[1000.0, 35.76], [14280.5, 0.994], [14380.5, 3.206], [14480.5, 0.0], [51664.0, 0.0], [58122.4, 0.004], [58122.5, 0.0], [61351.4, 0.001], [61997.2, 0.003], [63580.5, 0.006], [63837.8, 12.597], [63934.4, 3.516], [63934.7, 6.228], [64383.2, 7.817], [64492.4, 0.062], [64499.0, 0.173], [64504.0, 1.105], [64512.7, 0.0], [64519.1, 0.019], [64520.3, 0.277], [64523.1, 0.082], [64527.9, 1.301], [64530.0, 0.032], [64534.3, 0.0], [64536.8, 0.103], [64536.9, 2.002], [64537.5, 0.005], [64543.6, 0.071], [64545.5, 1.105], [64547.8, 0.001], [64549.0, 0.122], [64549.7, 0.014], [64550.2, 0.004], [64550.6, 0.051], [64550.9, 0.052], [64551.6, 0.107], [64552.8, 0.002], [64555.3, 0.789], [64555.6, 1.248], [64557.6, 0.094], [64558.5, 0.709], [64561.2, 0.002], [64562.2, 0.001], [64562.3, 0.002], [64562.7, 0.682], [64563.2, 0.044], [64563.3, 0.238], [64563.4, 0.095], [64565.4, 0.035], [64566.4, 0.023], [64566.7, 0.0], [64567.2, 0.022], [64568.1, 0.332], [64568.5, 0.003], [64569.7, 0.472], [64570.0, 0.004], [64570.5, 0.561], [64570.8, 0.241], [64570.9, 0.128], [64571.4, 0.154], [64572.6, 0.086], [64573.0, 0.097], [64573.2, 0.002], [64573.3, 0.085], [64574.2, 0.202], [64574.3, 0.103], [64574.7, 0.071], [64575.1, 0.001], [64575.2, 0.001], [64575.6, 0.032], [64575.7, 1.133], [64575.8, 0.066], [64576.0, 0.102], [64576.1, 0.002], [64576.2, 0.0], [64576.3, 0.035], [64576.4, 0.146], [64576.6, 0.002], [64577.0, 0.001], [64579.2, 1.543], [64580.5, 2.134]], "asks": [[64580.6, 58.943], [64580.7, 0.172], [64581.1, 0.019], [64581.4, 0.0], [64581.9, 0.011], [64582.4, 0.003], [64582.8, 0.081], [64583.9, 0.011], [64585.6, 0.067], [64586.0, 0.007], [64587.6, 0.124], [64587.8, 0.02], [64588.6, 0.449], [64590.5, 0.011], [64591.0, 0.064], [64591.1, 0.0], [64591.9, 0.542], [64592.1, 0.001], [64592.3, 0.11], [64592.7, 0.015], [64593.0, 0.011], [64594.5, 2.017], [64594.6, 0.017], [64595.0, 0.003], [64595.1, 0.0], [64595.5, 0.319], [64595.8, 0.002], [64597.2, 0.0], [64597.4, 0.005], [64598.0, 0.625], [64598.2, 0.001], [64599.1, 0.0], [64600.0, 3.73], [64600.2, 0.208], [64600.4, 10.004], [64603.4, 0.322], [64605.4, 0.82], [64606.0, 0.27], [64607.4, 0.163], [64607.8, 0.378], [64612.6, 0.07], [64614.5, 0.095], [64617.6, 1.161], [64617.8, 0.001], [64618.7, 0.019], [64621.6, 0.39], [64628.2, 0.11], [65226.4, 5.893], [65355.6, 73.972], [65484.7, 97.582], [65580.6, 0.01]]}
{"kind": "depth", "E": 1787089973337, "U": 11316023828321, "u": 11316023881053, "recv_ms": 1787089973554, "bids": [[1000.0, 35.76], [14272.1, 0.014], [14273.0, 0.014], [14274.4, 0.084], [14274.6, 0.028], [14274.8, 0.014], [14279.1, 0.042], [14279.4, 0.014], [14280.3, 0.014], [14280.5, 1.134], [14380.5, 2.842], [58122.4, 0.002], [61337.9, 0.004], [61351.4, 0.0], [63004.0, 0.041], [63288.9, 5.22], [63733.8, 6.897], [63735.0, 1.216], [63922.2, 0.007], [63926.4, 0.007], [63927.3, 0.025], [63928.4, 0.004], [63928.9, 0.002], [63929.1, 0.002], [63933.3, 0.023], [63933.6, 1.711], [63934.7, 6.226], [64121.8, 0.002], [64244.7, 0.006], [64250.9, 0.001], [64257.5, 0.0], [64362.4, 15.702], [64366.4, 4.379], [64372.8, 3.934], [64380.1, 2.266], [64383.2, 0.004], [64383.3, 0.08], [64392.0, 4.391], [64396.6, 0.213], [64414.6, 0.003], [64418.1, 9.123], [64421.7, 0.113], [64422.0, 5.43], [64431.3, 1.001], [64434.0, 0.003], [64435.9, 30.484], [64436.2, 1.666], [64436.8, 4.352], [64437.4, 0.0], [64438.1, 1.036], [64438.9, 0.033], [64439.2, 0.002], [64444.7, 0.015], [64447.2, 1.99], [64451.8, 1.592], [64452.7, 0.014], [64453.5, 0.001], [64454.7, 0.0], [64455.7, 0.003], [64456.8, 0.0], [64457.1, 0.007], [64459.4, 0.006], [64460.5, 0.048], [64463.4, 2.835], [64463.9, 4.097], [64464.4, 0.029], [64464.5, 0.212], [64466.2, 0.0], [64467.1, 0.005], [64467.4, 0.067], [64467.8, 0.0], [64468.0, 0.291], [64468.3, 0.007], [64468.7, 0.035], [64469.5, 0.001], [64469.6, 0.001], [64469.7, 0.0], [64470.8, 0.006], [64471.1, 0.0], [64471.5, 3.001], [64472.0, 1.688], [64472.5, 0.011], [64473.1, 0.004], [64473.4, 0.001], [64473.6, 0.012], [64474.3, 0.013], [64476.6, 1.522], [64483.6, 0.035], [64484.5, 0.004], [64484.6, 0.0], [64484.7, 2.616], [64485.1, 0.001], [64485.2, 1.554], [64486.5, 0.106], [64487.1, 0.007], [64487.5, 0.486], [64487.6, 0.002], [64488.7, 0.0], [64488.9, 0.0], [64490.4, 0.003], [64490.5, 3.986], [64490.6, 0.0], [64490.9, 0.428], [64492.4, 0.002], [64493.1, 0.002], [64493.2, 0.001], [64495.0, 1.855], [64495.1, 0.002], [64495.3, 0.01], [64495.5, 0.469], [64496.2, 2.32], [64496.6, 0.0], [64496.9, 0.001], [64497.7, 0.108], [64497.9, 0.21], [64498.2, 7.119], [64498.9, 0.072], [64499.0, 0.148], [64499.5, 0.323], [64499.7, 0.015], [64500.2, 0.0], [64500.7, 0.116], [64502.1, 0.193], [64502.5, 0.015], [64502.7, 1.0], [64503.0, 0.47], [64503.1, 0.033], [64503.4, 0.004], [64503.5, 0.313], [64504.7, 0.754], [64505.2, 0.0], [64505.6, 0.037], [64506.0, 0.04], [64506.3, 2.004], [64506.5, 0.163], [64507.3, 0.0], [64507.5, 4.915], [64508.0, 0.002], [64508.1, 0.045], [64508.5, 1.806], [64508.6, 0.029], [64508.7, 1.589], [64508.8, 6.281], [64509.1, 0.002], [64509.6, 0.046], [64510.0, 2.361], [64510.3, 2.096], [64510.7, 0.019], [64511.0, 0.03], [64511.5, 0.329], [64512.5, 0.051], [64512.7, 0.0], [64513.4, 0.035], [64513.5, 0.46], [64513.6, 1.086], [64513.7, 0.163], [64514.2, 0.035], [64514.4, 0.001], [64514.5, 1.973], [64514.7, 0.015], [64514.9, 0.091], [64515.1, 1.887], [64515.8, 0.034], [64516.0, 1.533], [64516.1, 0.002], [64516.3, 0.008], [64516.4, 0.008], [64516.5, 0.0], [64516.6, 0.009], [64517.3, 0.003], [64517.7, 0.035], [64518.1, 0.041], [64518.2, 0.001], [64519.0, 0.124], [64519.1, 0.042], [64519.7, 0.01], [64519.9, 0.121], [64520.0, 10.45], [64520.2, 0.061], [64520.3, 0.067], [64520.6, 0.636], [64521.1, 0.261], [64521.2, 0.041], [64521.5, 0.016], [64521.6, 0.009], [64521.7, 0.0], [64522.5, 0.034], [64522.6, 0.15], [64522.7, 0.065], [64522.8, 0.002], [64523.2, 1.148], [64523.3, 0.159], [64523.4, 0.014], [64523.5, 0.32], [64523.9, 0.461], [64524.0, 0.118], [64524.1, 6.898], [64524.4, 2.127], [64524.5, 2.391], [64524.7, 0.103], [64524.8, 0.024], [64524.9, 0.007], [64525.1, 0.087], [64525.5, 1.224], [64526.2, 0.029], [64526.4, 1.087], [64526.8, 0.001], [64527.0, 0.004], [64527.2, 0.051], [64527.5, 0.31], [64527.6, 0.036], [64527.7, 0.413], [64528.0, 0.095], [64528.3, 0.034], [64528.4, 0.001], [64528.5, 0.001], [64528.8, 0.023], [64528.9, 0.064], [64529.3, 0.022], [64529.4, 0.002], [64529.7, 0.0], [64529.9, 0.0], [64530.1, 0.003], [64530.3, 0.18], [64531.0, 0.001], [64531.6, 0.802], [64531.7, 0.001], [64531.8, 0.006], [64532.2, 0.003], [64532.3, 0.002], [64532.5, 1.0], [64532.7, 0.0], [64532.9, 2.873], [64533.1, 0.0], [64533.6, 0.008], [64533.8, 0.011], [64533.9, 0.0], [64534.2, 0.12], [64534.5, 0.001], [64534.6, 2.32], [64535.0, 0.091], [64535.4, 0.003], [64535.7, 0.0], [64535.8, 0.003], [64535.9, 0.436], [64536.0, 1.095], [64536.1, 0.002], [64536.5, 0.705], [64536.7, 0.0], [64536.8, 0.0], [64536.9, 0.002], [64537.0, 1.332], [64537.1, 0.018], [64537.2, 0.003], [64537.4, 0.33], [64537.5, 0.005], [64537.6, 0.006], [64537.7, 0.0], [64537.8, 2.964], [64538.1, 0.444], [64538.2, 0.001], [64538.3, 0.018], [64538.5, 2.956], [64538.6, 0.002], [64538.8, 3.131], [64539.1, 0.008], [64539.5, 0.081], [64539.6, 0.017], [64539.8, 0.002], [64539.9, 0.001], [64540.0, 0.226], [64540.1, 0.32], [64540.2, 0.003], [64540.3, 0.063], [64540.6, 0.033], [64540.8, 0.007], [64541.1, 0.009], [64541.4, 0.311], [64541.6, 0.051], [64541.7, 0.003], [64541.8, 0.003], [64541.9, 0.083], [64542.2, 0.018], [64542.3, 0.002], [64542.6, 0.001], [64542.7, 0.046], [64542.9, 0.314], [64543.2, 1.056], [64543.3, 0.101], [64543.4, 0.001], [64543.5, 0.003], [64543.6, 0.001], [64543.7, 0.062], [64543.9, 0.003], [64544.0, 0.008], [64544.2, 0.001], [64544.4, 0.645], [64544.9, 0.008], [64545.0, 0.137], [64545.1, 0.0], [64545.2, 0.016], [64545.3, 0.003], [64545.4, 0.022], [64545.5, 1.015], [64545.6, 1.112], [64545.7, 0.265], [64545.8, 0.0], [64546.1, 0.009], [64546.2, 0.0], [64546.6, 0.002], [64546.7, 0.0], [64546.8, 0.024], [64547.1, 0.039], [64547.2, 0.132], [64547.3, 0.936], [64547.4, 0.086], [64547.7, 0.004], [64547.8, 0.006], [64547.9, 0.012], [64548.0, 0.555], [64548.1, 0.028], [64548.2, 1.734], [64548.3, 0.002], [64548.5, 0.093], [64548.6, 0.001], [64548.9, 1.276], [64549.0, 0.002], [64549.1, 0.001], [64549.3, 2.985], [64549.4, 3.577], [64549.5, 0.0], [64549.6, 0.08], [64549.8, 0.002], [64550.0, 0.008], [64550.1, 0.0], [64550.3, 0.004], [64550.4, 0.01], [64550.6, 0.001], [64550.8, 0.0], [64550.9, 0.003], [64551.0, 0.0], [64551.2, 0.004], [64551.3, 0.001], [64551.4, 0.001], [64551.5, 0.195], [64551.6, 0.107], [64551.7, 0.016], [64551.8, 0.001], [64551.9, 0.004], [64552.0, 1.016], [64552.1, 0.802], [64552.2, 0.004], [64552.3, 0.001], [64552.5, 0.569], [64552.6, 0.025], [64552.7, 0.01], [64552.9, 0.116], [64553.1, 0.002], [64553.2, 0.003], [64553.3, 0.002], [64553.4, 0.069], [64553.6, 0.012], [64553.7, 0.003], [64553.8, 0.006], [64554.0, 0.313], [64554.1, 0.003], [64554.2, 0.99], [64554.4, 0.0], [64554.5, 0.07], [64554.6, 0.074], [64554.7, 0.141], [64554.9, 0.478], [64555.1, 0.101], [64555.2, 0.268], [64555.3, 0.17], [64555.5, 0.073], [64555.6, 1.24], [64555.7, 0.0], [64555.8, 0.127], [64556.0, 0.001], [64556.2, 0.004], [64556.6, 0.0], [64556.8, 0.008], [64556.9, 0.383], [64557.0, 0.001], [64557.1, 0.37], [64557.2, 0.02], [64557.3, 0.003], [64557.4, 0.002], [64557.6, 0.001], [64557.7, 0.085], [64558.0, 0.012], [64558.1, 0.62], [64558.2, 0.335], [64558.3, 0.313], [64558.4, 0.611], [64558.5, 1.033], [64558.6, 0.312], [64558.7, 0.31], [64558.8, 0.001], [64558.9, 0.001], [64559.0, 0.086], [64559.1, 0.004], [64559.2, 0.001], [64559.3, 0.003], [64559.4, 0.0], [64559.5, 0.337], [64559.6, 0.086], [64559.7, 0.001], [64559.9, 0.087], [64560.0, 3.315], [64560.1, 0.157], [64560.2, 0.0], [64560.3, 0.016], [64560.4, 0.049], [64560.5, 0.001], [64560.6, 0.002], [64560.7, 0.002], [64560.9, 0.005], [64561.0, 0.002], [64561.1, 0.235], [64561.2, 0.002], [64561.3, 0.002], [64561.4, 0.083], [64561.5, 0.072], [64561.6, 0.004], [64561.7, 0.13], [64561.8, 0.0], [64562.0, 0.001], [64562.1, 0.109], [64562.2, 0.0], [64562.3, 0.0], [64562.4, 0.0], [64562.5, 0.019], [64562.6, 0.0], [64562.7, 0.0], [64562.8, 0.0], [64562.9, 0.0], [64563.0, 0.0], [64563.1, 0.046], [64563.2, 0.0], [64563.3, 0.0], [64563.4, 0.155], [64563.5, 0.0], [64563.6, 0.0], [64563.7, 0.0], [64563.8, 0.0], [64563.9, 0.0], [64564.0, 0.0], [64564.1, 0.0], [64564.2, 0.0], [64564.3, 0.0], [64564.4, 0.0], [64564.5, 0.0], [64564.6, 0.0], [64564.7, 0.0], [64564.8, 0.0], [64564.9, 0.0], [64565.0, 0.0], [64565.1, 0.0], [64565.2, 0.0], [64565.3, 0.0], [64565.4, 0.0], [64565.5, 0.0], [64565.6, 0.0], [64565.7, 0.0], [64565.8, 0.0], [64565.9, 0.0], [64566.0, 0.0], [64566.1, 0.0], [64566.2, 0.0], [64566.3, 0.0], [64566.4, 0.0], [64566.5, 0.0], [64566.6, 0.0], [64566.7, 0.0], [64566.8, 0.0], [64566.9, 0.0], [64567.0, 0.0], [64567.1, 0.0], [64567.2, 0.0], [64567.3, 0.0], [64567.4, 0.0], [64567.5, 0.0], [64567.6, 0.0], [64567.7, 0.0], [64567.8, 0.0], [64567.9, 0.0], [64568.0, 0.0], [64568.1, 0.0], [64568.2, 0.0], [64568.3, 0.0], [64568.4, 0.0], [64568.5, 0.0], [64568.6, 0.0], [64568.7, 0.0], [64568.8, 0.0], [64568.9, 0.0], [64569.0, 0.0], [64569.1, 0.0], [64569.3, 0.0], [64569.4, 0.0], [64569.5, 0.0], [64569.6, 0.0], [64569.7, 0.0], [64569.8, 0.0], [64569.9, 0.0], [64570.0, 0.0], [64570.1, 0.0], [64570.2, 0.0], [64570.3, 0.0], [64570.4, 0.0], [64570.5, 0.0], [64570.6, 0.0], [64570.7, 0.0], [64570.8, 0.0], [64570.9, 0.0], [64571.0, 0.0], [64571.1, 0.0], [64571.2, 0.0], [64571.3, 0.0], [64571.4, 0.0], [64571.5, 0.0], [64571.6, 0.0], [64571.7, 0.0], [64571.8, 0.0], [64571.9, 0.0], [64572.0, 0.0], [64572.1, 0.0], [64572.2, 0.0], [64572.3, 0.0], [64572.4, 0.0], [64572.6, 0.0], [64572.7, 0.0], [64572.8, 0.0], [64572.9, 0.0], [64573.0, 0.0], [64573.1, 0.0], [64573.2, 0.0], [64573.3, 0.0], [64573.4, 0.0], [64573.5, 0.0], [64573.6, 0.0], [64573.7, 0.0], [64573.8, 0.0], [64573.9, 0.0], [64574.0, 0.0], [64574.1, 0.0], [64574.2, 0.0], [64574.3, 0.0], [64574.4, 0.0], [64574.5, 0.0], [64574.6, 0.0], [64574.7, 0.0], [64574.8, 0.0], [64574.9, 0.0], [64575.0, 0.0], [64575.1, 0.0], [64575.2, 0.0], [64575.3, 0.0], [64575.4, 0.0], [64575.5, 0.0], [64575.6, 0.0], [64575.7, 0.0], [64575.8, 0.0], [64575.9, 0.0], [64576.0, 0.0], [64576.1, 0.0], [64576.3, 0.0], [64576.4, 0.0], [64576.5, 0.0], [64576.6, 0.0], [64576.7, 0.0], [64576.8, 0.0], [64576.9, 0.0], [64577.0, 0.0], [64577.1, 0.0], [64577.2, 0.0], [64577.3, 0.0], [64577.4, 0.0], [64577.5, 0.0], [64577.6, 0.0], [64577.7, 0.0], [64577.8, 0.0], [64577.9, 0.0], [64578.0, 0.0], [64578.2, 0.0], [64578.3, 0.0], [64578.4, 0.0], [64578.7, 0.0], [64578.8, 0.0], [64578.9, 0.0], [64579.0, 0.0], [64579.1, 0.0], [64579.2, 0.0], [64579.3, 0.0], [64579.4, 0.0], [64579.7, 0.0], [64579.8, 0.0], [64579.9, 0.0], [64580.0, 0.0], [64580.3, 0.0], [64580.4, 0.0], [64580.5, 0.0]], "asks": [[64563.9, 2.22], [64564.0, 6.956], [64565.7, 0.505], [64565.8, 0.657], [64565.9, 1.016], [64566.0, 2.032], [64566.1, 3.588], [64566.2, 0.332], [64566.3, 13.778], [64566.4, 4.36], [64566.5, 0.002], [64566.7, 3.258], [64566.8, 0.311], [64567.1, 0.0], [64567.2, 0.001], [64567.3, 0.0], [64567.4, 0.442], [64567.5, 2.391], [64567.6, 3.448], [64567.7, 2.215], [64567.8, 0.0], [64567.9, 1.82], [64568.0, 4.461], [64568.1, 0.42], [64568.2, 0.0], [64568.3, 2.619], [64568.4, 5.6], [64568.5, 0.002], [64568.6, 0.0], [64568.7, 0.001], [64568.8, 0.0], [64568.9, 2.058], [64569.0, 0.0], [64569.1, 0.001], [64569.2, 1.711], [64569.3, 0.001], [64569.4, 0.002], [64569.5, 0.0], [64569.6, 0.001], [64569.8, 0.003], [64569.9, 1.711], [64570.0, 0.002], [64570.1, 0.583], [64570.2, 1.727], [64570.3, 0.078], [64570.4, 0.0], [64570.5, 3.424], [64570.6, 1.146], [64570.7, 1.63], [64570.8, 0.263], [64570.9, 0.002], [64571.0, 0.0], [64571.1, 0.014], [64571.2, 0.069], [64571.3, 2.294], [64571.5, 8.668], [64571.6, 15.516], [64571.7, 0.001], [64571.8, 1.007], [64571.9, 0.364], [64572.0, 0.127], [64572.1, 1.851], [64572.2, 1.801], [64572.3, 0.002], [64572.4, 0.0], [64572.5, 0.007], [64572.6, 0.001], [64572.7, 1.486], [64572.8, 0.006], [64572.9, 0.36], [64573.0, 10.712], [64573.1, 6.628], [64573.2, 0.003], [64573.3, 0.0], [64573.4, 0.506], [64573.5, 3.129], [64573.6, 4.888], [64573.7, 1.203], [64573.8, 0.001], [64573.9, 2.388], [64574.0, 2.707], [64574.1, 1.863], [64574.2, 7.161], [64574.3, 0.066], [64574.4, 4.209], [64574.5, 0.447], [64574.6, 0.05], [64574.7, 15.438], [64574.8, 0.231], [64574.9, 0.012], [64575.0, 0.001], [64575.1, 4.304], [64575.2, 0.004], [64575.3, 0.003], [64575.4, 0.052], [64575.5, 2.624], [64575.6, 0.001], [64575.7, 0.982], [64575.8, 0.023], [64575.9, 0.064], [64576.0, 0.004], [64576.1, 0.261], [64576.2, 0.002], [64576.3, 0.0], [64576.4, 0.032], [64576.5, 0.01], [64576.6, 0.001], [64576.7, 0.003], [64576.8, 0.101], [64576.9, 0.0], [64577.1, 0.001], [64577.2, 0.0], [64577.3, 0.0], [64577.4, 0.011], [64577.5, 0.0], [64577.6, 0.0], [64577.7, 0.002], [64577.8, 0.013], [64577.9, 0.411], [64578.0, 0.997], [64578.1, 0.042], [64578.2, 0.002], [64578.3, 0.002], [64578.4, 0.002], [64578.5, 0.002], [64578.6, 0.221], [64578.8, 0.001], [64578.9, 0.002], [64579.0, 0.007], [64579.1, 1.248], [64579.2, 2.662], [64579.3, 2.496], [64579.4, 0.024], [64579.5, 0.009], [64579.6, 0.002], [64579.7, 0.015], [64579.8, 0.503], [64579.9, 0.008], [64580.0, 0.0], [64580.1, 0.074], [64580.3, 3.269], [64580.4, 2.094], [64580.5, 3.926], [64580.6, 26.426], [64580.7, 0.016], [64580.8, 0.04], [64580.9, 0.042], [64581.1, 0.031], [64581.2, 0.131], [64581.3, 0.237], [64581.4, 0.001], [64581.5, 0.036], [64581.6, 0.211], [64581.7, 0.002], [64581.8, 0.048], [64581.9, 0.003], [64582.0, 0.006], [64582.1, 0.0], [64582.2, 0.06], [64582.3, 0.0], [64582.4, 0.013], [64582.7, 0.004], [64582.8, 0.24], [64582.9, 0.308], [64583.0, 0.002], [64583.1, 0.155], [64583.2, 0.001], [64583.3, 0.002], [64583.4, 0.003], [64583.5, 0.24], [64583.6, 0.001], [64583.7, 0.004], [64583.8, 0.085], [64583.9, 0.448], [64584.0, 0.354], [64584.1, 0.34], [64584.2, 0.315], [64584.4, 0.008], [64584.6, 0.229], [64584.7, 0.0], [64584.8, 0.008], [64584.9, 0.0], [64585.0, 0.019], [64585.1, 0.004], [64585.2, 1.816], [64585.3, 0.002], [64585.6, 0.068], [64585.7, 0.004], [64585.8, 0.332], [64585.9, 0.001], [64586.0, 0.001], [64586.1, 0.072], [64586.2, 0.003], [64586.3, 0.003], [64586.4, 0.001], [64586.5, 0.023], [64586.6, 0.155], [64586.7, 1.312], [64586.8, 1.51], [64586.9, 0.449], [64587.0, 0.091], [64587.1, 0.026], [64587.2, 0.284], [64587.3, 0.084], [64587.4, 0.921], [64587.5, 0.027], [64587.6, 0.239], [64587.7, 2.321], [64587.8, 0.33], [64587.9, 0.234], [64588.0, 0.07], [64588.1, 0.542], [64588.3, 2.289], [64588.4, 0.705], [64588.5, 0.54], [64588.6, 0.452], [64588.7, 0.47], [64588.8, 0.552], [64588.9, 1.623], [64589.1, 0.281], [64589.2, 0.148], [64589.3, 0.0], [64589.4, 1.099], [64589.5, 1.097], [64589.6, 0.223], [64589.7, 0.209], [64589.8, 0.311], [64589.9, 0.0], [64590.0, 0.135], [64590.1, 0.174], [64590.2, 0.177], [64590.3, 0.003], [64590.5, 0.019], [64590.6, 2.321], [64590.7, 0.002], [64590.8, 0.076], [64590.9, 0.0], [64591.0, 0.004], [64591.1, 0.0], [64591.3, 0.001], [64591.5, 0.001], [64591.6, 0.14], [64591.8, 0.059], [64591.9, 0.0], [64592.0, 0.009], [64592.1, 0.043], [64592.2, 0.569], [64592.3, 0.018], [64592.4, 0.004], [64592.5, 0.005], [64592.6, 0.003], [64592.7, 0.034], [64592.8, 0.487], [64592.9, 0.02], [64593.0, 0.016], [64593.1, 2.616], [64593.2, 1.237], [64593.3, 0.004], [64593.4, 2.32], [64593.5, 0.001], [64593.6, 0.138], [64593.7, 0.003], [64593.8, 0.002], [64593.9, 0.211], [64594.1, 0.073], [64594.3, 0.0], [64594.4, 0.001], [64594.5, 0.015], [64594.6, 0.0], [64594.7, 0.631], [64594.9, 0.03], [64595.1, 0.0], [64595.3, 0.009], [64595.5, 0.099], [64595.6, 0.001], [64595.7, 0.326], [64595.8, 0.004], [64595.9, 1.101], [64596.0, 2.442], [64596.1, 0.0], [64596.2, 0.001], [64596.3, 0.088], [64596.4, 0.0], [64596.5, 1.994], [64596.6, 0.018], [64596.7, 0.015], [64596.8, 0.388], [64596.9, 0.0], [64597.0, 0.0], [64597.1, 0.317], [64597.2, 0.694], [64597.3, 0.108], [64597.4, 0.454], [64597.5, 0.0], [64597.6, 0.007], [64597.7, 0.002], [64597.8, 0.559], [64597.9, 0.0], [64598.0, 0.161], [64598.2, 0.0], [64598.3, 0.0], [64598.4, 0.009], [64598.5, 0.033], [64598.6, 2.721], [64598.8, 0.002], [64598.9, 0.016], [64599.1, 0.0], [64599.2, 0.002], [64599.3, 0.161], [64599.6, 0.061], [64599.7, 0.001], [64599.8, 0.0], [64599.9, 1.527], [64600.0, 3.726], [64600.1, 0.016], [64600.2, 0.168], [64600.3, 0.008], [64600.4, 0.004], [64600.5, 5.0], [64600.6, 0.0], [64600.7, 0.02], [64600.8, 0.408], [64600.9, 0.003], [64601.0, 0.011], [64601.2, 0.027], [64601.3, 0.013], [64601.4, 2.319], [64601.5, 1.264], [64601.6, 0.009], [64601.7, 0.004], [64601.8, 0.0], [64601.9, 0.001], [64602.0, 0.14], [64602.2, 0.778], [64602.4, 0.008], [64602.8, 0.0], [64602.9, 1.001], [64603.1, 0.0], [64603.2, 1.125], [64603.3, 0.016], [64603.4, 0.321], [64603.6, 0.0], [64603.7, 0.02], [64603.8, 0.071], [64603.9, 0.003], [64604.1, 0.07], [64604.2, 0.003], [64604.3, 0.516], [64604.4, 0.072], [64604.6, 0.093], [64604.7, 0.077], [64604.8, 0.011], [64604.9, 0.04], [64605.0, 0.183], [64605.3, 0.892], [64605.4, 0.004], [64605.6, 1.286], [64605.7, 0.005], [64605.8, 0.001], [64606.0, 0.27], [64606.1, 0.31], [64606.2, 0.001], [64606.3, 0.002], [64606.4, 1.206], [64606.5, 0.276], [64606.6, 0.001], [64606.7, 0.0], [64607.2, 0.004], [64607.3, 0.079], [64607.6, 0.149], [64607.7, 0.295], [64607.9, 0.673], [64608.0, 0.26], [64608.3, 0.14], [64608.5, 0.003], [64609.1, 4.566], [64609.2, 0.005], [64609.3, 0.0], [64609.4, 0.001], [64610.0, 0.063], [64610.2, 0.131], [64610.4, 0.167], [64610.6, 0.002], [64610.9, 0.0], [64611.0, 0.001], [64611.1, 0.001], [64611.2, 1.285], [64611.3, 0.001], [64611.4, 0.003], [64611.5, 0.004], [64611.7, 0.001], [64612.0, 0.039], [64612.1, 0.016], [64612.3, 0.007], [64612.6, 0.0], [64612.8, 1.093], [64613.0, 2.324], [64613.1, 0.39], [64613.2, 0.001], [64613.4, 0.128], [64613.5, 0.155], [64614.0, 0.029], [64614.1, 0.01], [64614.5, 0.005], [64614.6, 0.02], [64614.8, 0.017], [64615.2, 0.001], [64615.8, 0.015], [64616.1, 0.002], [64616.6, 0.31], [64616.9, 0.027], [64617.4, 0.0], [64617.5, 0.001], [64617.6, 1.007], [64617.7, 0.061], [64617.9, 0.0], [64618.0, 0.001], [64618.2, 0.006], [64618.3, 0.0], [64618.4, 0.161], [64618.6, 0.224], [64618.7, 0.001], [64618.9, 0.004], [64619.0, 1.39], [64619.1, 7.898], [64619.2, 1.16], [64619.3, 0.225], [64619.8, 0.0], [64620.0, 0.015], [64620.1, 0.004], [64620.2, 0.443], [64620.3, 0.001], [64620.6, 0.03], [64621.4, 0.011], [64621.6, 0.389], [64621.8, 0.004], [64621.9, 0.015], [64622.2, 0.001], [64622.7, 0.003], [64623.0, 0.125], [64623.3, 2.397], [64623.6, 0.019], [64624.2, 0.034], [64624.4, 0.061], [64624.5, 0.003], [64625.0, 0.012], [64625.3, 3.502], [64625.5, 0.001], [64625.6, 1.095], [64625.7, 0.497], [64626.0, 0.001], [64626.1, 1.39], [64626.4, 0.0], [64626.6, 2.636], [64626.9, 0.0], [64627.0, 0.001], [64627.8, 0.183], [64628.2, 0.085], [64628.6, 0.029], [64628.9, 6.334], [64629.0, 0.017], [64631.7, 0.03], [64631.9, 0.001], [64632.0, 1.092], [64632.1, 0.0], [64632.3, 0.195], [64632.8, 0.108], [64632.9, 2.736], [64633.0, 0.385], [64633.1, 0.078], [64633.2, 0.028], [64633.5, 0.053], [64633.7, 0.003], [64634.4, 0.005], [64634.5, 0.001], [64634.6, 0.031], [64635.1, 0.874], [64635.8, 0.0], [64635.9, 0.004], [64637.1, 3.834], [64638.0, 0.016], [64638.3, 0.016], [64638.6, 0.002], [64639.1, 0.294], [64639.4, 0.164], [64640.0, 0.03], [64640.1, 0.0], [64640.3, 0.001], [64640.6, 0.077], [64640.8, 0.011], [64641.1, 0.032], [64642.4, 0.02], [64642.9, 0.001], [64643.3, 2.221], [64644.3, 4.598], [64645.0, 3.834], [64648.0, 1.031], [64649.0, 0.013], [64649.4, 0.003], [64649.7, 0.0], [64650.0, 0.693], [64650.1, 1.35], [64650.5, 0.628], [64650.6, 0.077], [64651.3, 0.007], [64651.4, 0.0], [64651.6, 0.05], [64651.7, 0.001], [64652.2, 0.0], [64653.4, 0.383], [64654.0, 0.06], [64654.4, 1.051], [64656.0, 0.003], [64656.6, 0.001], [64657.5, 0.404], [64657.9, 0.029], [64658.0, 0.002], [64660.0, 0.043], [64661.3, 0.063], [64661.4, 0.2], [64661.8, 0.063], [64661.9, 1.958], [64662.1, 0.429], [64662.2, 1.968], [64663.4, 0.029], [64664.5, 0.004], [64665.5, 6.392], [64667.1, 1.088], [64667.3, 0.041], [64668.5, 0.017], [64668.9, 0.001], [64670.4, 0.004], [64670.9, 0.002], [64673.1, 1.208], [64673.2, 0.014], [64673.7, 0.015], [64677.3, 0.0], [64678.9, 0.0], [64679.0, 0.09], [64679.1, 0.117], [64679.3, 0.001], [64679.7, 0.0], [64679.8, 12.525], [64679.9, 1.243], [64681.4, 0.0], [64682.1, 0.002], [64683.3, 0.0], [64685.7, 0.001], [64686.6, 0.628], [64687.3, 0.0], [64687.8, 0.0], [64690.2, 0.0], [64692.0, 11.864], [64694.3, 0.001], [64695.9, 0.0], [64698.8, 0.391], [64705.7, 0.001], [64707.3, 0.02], [64707.5, 0.053], [64709.4, 0.0], [64712.2, 0.0], [64714.8, 0.026], [64714.9, 0.023], [64715.1, 0.0], [64715.2, 0.049], [64715.3, 0.0], [64720.3, 3.226], [64721.8, 0.04], [64722.3, 0.47], [64729.5, 0.026], [64737.2, 7.239], [64742.8, 0.004], [64767.8, 0.002], [64767.9, 0.251], [64776.0, 17.346], [64796.7, 0.0], [64813.5, 0.263], [64816.7, 0.0], [64820.6, 0.009], [64828.1, 0.113], [64848.5, 0.078], [64848.6, 1.83], [64885.7, 0.009], [64886.3, 1.019], [64886.8, 0.308], [64886.9, 0.269], [64887.1, 0.203], [64887.2, 0.007], [64887.3, 0.006], [64887.4, 0.231], [64890.7, 0.0], [64895.4, 0.008], [64955.8, 0.012], [64992.0, 0.01], [65202.6, 0.325], [65220.4, 0.0], [65220.6, 0.303], [65226.4, 5.893], [65567.6, 0.003], [65568.4, 0.002], [65572.2, 0.006], [65573.5, 0.0], [65573.9, 0.918], [65579.5, 0.002], [65580.0, 14.58], [65872.2, 7.592]]}
