{"receive_ns":1788567767880398000,"stream":"btcusdt@depth@100ms","event_type":"depthUpdate","event_time_ms":1788567767901,"raw_json":"{\"stream\":\"btcusdt@depth@100ms\",\"data\":{\"e\":\"depthUpdate\",\"E\":1788567767901,\"T\":1788567767897,\"s\":\"BTCUSDT\",\"ps\":\"BTCUSDT\",\"U\":11478510710956,\"u\":11478510715304,\"pu\":11478510710899,\"b\":[[\"29396.90\",\"1.015\"],[\"29496.90\",\"1.085\"],[\"63677.50\",\"0.000\"],[\"63678.00\",\"0.006\"],[\"71637.20\",\"0.002\"],[\"75500.00\",\"53.402\"],[\"75617.20\",\"0.006\"],[\"76413.00\",\"0.023\"],[\"78466.70\",\"1.377\"],[\"78598.70\",\"0.000\"],[\"78601.10\",\"0.005\"],[\"78613.90\",\"0.000\"],[\"78618.40\",\"1.891\"],[\"78641.70\",\"28.602\"],[\"78800.90\",\"11.562\"],[\"78960.10\",\"8.335\"],[\"79198.90\",\"3.971\"],[\"79534.00\",\"0.253\"],[\"79534.50\",\"2.356\"],[\"79536.70\",\"19.958\"],[\"79539.00\",\"3.787\"],[\"79555.10\",\"0.156\"],[\"79559.10\",\"0.047\"]],\"a\":[[\"79597.00\",\"8.719\"],[\"79638.90\",\"0.087\"],[\"79643.30\",\"0.101\"],[\"80280.20\",\"0.058\"],[\"80393.00\",\"14.824\"],[\"80520.50\",\"0.003\"]],\"st\":1}}"}
{"receive_ns":1788567767950490000,"stream":"btcusdt@trade","event_type":"trade","event_time_ms":1788567767968,"raw_json":"{\"stream\":\"btcusdt@trade\",\"data\":{\"e\":\"trade\",\"E\":1788567767968,\"T\":1788567767968,\"s\":\"BTCUSDT\",\"t\":8054122796,\"p\":\"0\",\"q\":\"0\",\"X\":\"NA\",\"m\":false,\"st\":1}}"}
{"receive_ns":1788567767978360000,"stream":"btcusdt@depth@100ms","event_type":"depthUpdate","event_time_ms":1788567768003,"raw_json":"{\"stream\":\"btcusdt@depth@100ms\",\"data\":{\"e\":\"depthUpdate\",\"E\":1788567768003,\"T\":1788567768001,\"s\":\"BTCUSDT\",\"ps\":\"BTCUSDT\",\"U\":11478510715556,\"u\":11478510719557,\"pu\":11478510715304,\"b\":[[\"1000.00\",\"24.604\"],[\"29396.90\",\"1.197\"],[\"29496.90\",\"0.903\"],[\"63678.00\",\"0.006\"],[\"71637.20\",\"0.002\"],[\"76413.00\",\"0.025\"],[\"78602.00\",\"13.393\"],[\"78800.90\",\"11.562\"],[\"79592.80\",\"0.505\"]],\"a\":[[\"79598.20\",\"0.028\"],[\"79600.30\",\"0.002\"],[\"79650.90\",\"0.020\"],[\"79663.40\",\"0.014\"],[\"80384.80\",\"0.124\"],[\"80393.00\",\"14.824\"]],\"st\":1}}"}
{"receive_ns":1788567768080023000,"stream":"btcusdt@depth@100ms","event_type":"depthUpdate","event_time_ms":1788567768105,"raw_json":"{\"stream\":\"btcusdt@depth@100ms\",\"data\":{\"e\":\"depthUpdate\",\"E\":1788567768105,\"T\":1788567768104,\"s\":\"BTCUSDT\",\"ps\":\"BTCUSDT\",\"U\":11478510719623,\"u\":11478510723529,\"pu\":11478510719557,\"b\":[[\"29396.90\",\"1.372\"],[\"29496.90\",\"0.728\"],[\"63678.00\",\"0.008\"],[\"71637.20\",\"0.002\"],[\"78005.00\",\"0.162\"],[\"78641.80\",\"11.741\"],[\"78800.90\",\"11.561\"],[\"79495.00\",\"0.157\"],[\"79582.60\",\"0.070\"]],\"a\":[[\"80378.80\",\"0.496\"],[\"80393.00\",\"14.824\"],[\"80552.20\",\"27.122\"],[\"80776.70\",\"1.824\"],[\"80938.50\",\"0.617\"]],\"st\":1}}"}
{"receive_ns":1788567768137411000,"stream":"btcusdt@bookTicker","event_type":"bookTicker","event_time_ms":1788567768148,"raw_json":"{\"stream\":\"btcusdt@bookTicker\",\"data\":{\"e\":\"bookTicker\",\"u\":11478510725649,\"s\":\"BTCUSDT\",\"ps\":\"BTCUSDT\",\"b\":\"79596.90\",\"B\":\"5.035\",\"a\":\"79597.00\",\"A\":\"8.720\",\"T\":1788567768147,\"E\":1788567768148,\"st\":1}}"}
{"receive_ns":1788567768177545000,"stream":"btcusdt@bookTicker","event_type":"bookTicker","event_time_ms":1788567768186,"raw_json":"{\"stream\":\"btcusdt@bookTicker\",\"data\":{\"e\":\"bookTicker\",\"u\":11478510728943,\"s\":\"BTCUSDT\",\"ps\":\"BTCUSDT\",\"b\":\"79596.90\",\"B\":\"5.035\",\"a\":\"79597.00\",\"A\":\"8.718\",\"T\":1788567768186,\"E\":1788567768186,\"st\":1}}"}
{"receive_ns":1788567768177764000,"stream":"btcusdt@trade","event_type":"trade","event_time_ms":1788567768186,"raw_json":"{\"stream\":\"btcusdt@trade\",\"data\":{\"e\":\"trade\",\"E\":1788567768186,\"T\":1788567768186,\"s\":\"BTCUSDT\",\"t\":8054122797,\"p\":\"79597.00\",\"q\":\"0.002\",\"X\":\"MARKET\",\"m\":false,\"st\":1}}"}
{"receive_ns":1788567768177991000,"stream":"btcusdt@bookTicker","event_type":"bookTicker","event_time_ms":1788567768188,"raw_json":"{\"stream\":\"btcusdt@bookTicker\",\"data\":{\"e\":\"bookTicker\",\"u\":11478510729289,\"s\":\"BTCUSDT\",\"ps\":\"BTCUSDT\",\"b\":\"79596.90\",\"B\":\"4.868\",\"a\":\"79597.00\",\"A\":\"8.718\",\"T\":1788567768188,\"E\":1788567768188,\"st\":1}}"}
{"receive_ns":1788567768178259000,"stream":"btcusdt@bookTicker","event_type":"bookTicker","event_time_ms":1788567768189,"raw_json":"{\"stream\":\"btcusdt@bookTicker\",\"data\":{\"e\":\"bookTicker\",\"u\":11478510729363,\"s\":\"BTCUSDT\",\"ps\":\"BTCUSDT\",\"b\":\"79596.90\",\"B\":\"4.869\",\"a\":\"79597.00\",\"A\":\"8.718\",\"T\":1788567768189,\"E\":1788567768189,\"st\":1}}"}
{"receive_ns":1788567768190214000,"stream":"btcusdt@depth@100ms","event_type":"depthUpdate","event_time_ms":1788567768207,"raw_json":"{\"stream\":\"btcusdt@depth@100ms\",\"data\":{\"e\":\"depthUpdate\",\"E\":1788567768207,\"T\":1788567768205,\"s\":\"BTCUSDT\",\"ps\":\"BTCUSDT\",\"U\":11478510723577,\"u\":11478510730558,\"pu\":11478510723529,\"b\":[[\"1000.00\",\"24.754\"],[\"29396.90\",\"1.554\"],[\"29496.90\",\"0.546\"],[\"63678.00\",\"0.006\"],[\"71637.20\",\"0.002\"],[\"71673.00\",\"0.000\"],[\"76413.00\",\"0.023\"],[\"78506.20\",\"0.000\"],[\"78641.70\",\"24.793\"],[\"78800.90\",\"11.561\"],[\"79198.90\",\"3.971\"],[\"79506.70\",\"4.386\"],[\"79596.70\",\"0.015\"],[\"79596.90\",\"4.869\"]],\"a\":[[\"79597.00\",\"8.718\"],[\"79598.10\",\"0.026\"],[\"79598.20\",\"0.002\"],[\"79688.30\",\"3.413\"],[\"79806.20\",\"2.655\"],[\"79819.00\",\"6.875\"],[\"79995.00\",\"4.448\"],[\"80472.60\",\"4.965\"],[\"80528.30\",\"1.732\"],[\"80601.70\",\"0.002\"]],\"st\":1}}"}
{"receive_ns":1788567768233281000,"stream":"btcusdt@bookTicker","event_type":"bookTicker","event_time_ms":1788567768243,"raw_json":"{\"stream\":\"btcusdt@bookTicker\",\"data\":{\"e\":\"bookTicker\",\"u\":11478510732966,\"s\":\"BTCUSDT\",\"ps\":\"BTCUSDT\",\"b\":\"79596.90\",\"B\":\"4.869\",\"a\":\"79597.00\",\"A\":\"8.744\",\"T\":1788567768242,\"E\":1788567768243,\"st\":1}}"}
{"receive_ns":1788567768243222000,"stream":"btcusdt@bookTicker","event_type":"bookTicker","event_time_ms":1788567768262,"raw_json":"{\"stream\":\"btcusdt@bookTicker\",\"data\":{\"e\":\"bookTicker\",\"u\":11478510734222,\"s\":\"BTCUSDT\",\"ps\":\"BTCUSDT\",\"b\":\"79596.90\",\"B\":\"4.858\",\"a\":\"79597.00\",\"A\":\"8.744\",\"T\":1788567768262,\"E\":1788567768262,\"st\":1}}"}
{"receive_ns":1788567768248830000,"stream":"btcusdt@bookTicker","event_type":"bookTicker","event_time_ms":1788567768265,"raw_json":"{\"stream\":\"btcusdt@bookTicker\",\"data\":{\"e\":\"bookTicker\",\"u\":11478510734376,\"s\":\"BTCUSDT\",\"ps\":\"BTCUSDT\",\"b\":\"79596.90\",\"B\":\"4.880\",\"a\":\"79597.00\",\"A\":\"8.744\",\"T\":1788567768265,\"E\":1788567768265,\"st\":1}}"}
{"receive_ns":1788567768291125000,"stream":"btcusdt@bookTicker","event_type":"bookTicker","event_time_ms":1788567768302,"raw_json":"{\"stream\":\"btcusdt@bookTicker\",\"data\":{\"e\":\"bookTicker\",\"u\":11478510736698,\"s\":\"BTCUSDT\",\"ps\":\"BTCUSDT\",\"b\":\"79596.90\",\"B\":\"4.880\",\"a\":\"79597.00\",\"A\":\"8.718\",\"T\":1788567768302,\"E\":1788567768302,\"st\":1}}"}
{"receive_ns":1788567768297949000,"stream":"btcusdt@depth@100ms","event_type":"depthUpdate","event_time_ms":1788567768309,"raw_json":"{\"stream\":\"btcusdt@depth@100ms\",\"data\":{\"e\":\"depthUpdate\",\"E\":1788567768309,\"T\":1788567768306,\"s\":\"BTCUSDT\",\"ps\":\"BTCUSDT\",\"U\":11478510730673,\"u\":11478510736869,\"pu\":11478510730558,\"b\":[[\"1000.00\",\"24.604\"],[\"29396.90\",\"1.729\"],[\"29496.90\",\"0.371\"],[\"71637.20\",\"0.002\"],[\"76413.00\",\"0.025\"],[\"77368.30\",\"1.031\"],[\"77607.10\",\"0.517\"],[\"77991.20\",\"1.793\"],[\"78005.00\",\"0.168\"],[\"78389.10\",\"0.000\"],[\"78402.90\",\"0.709\"],[\"78578.10\",\"0.006\"],[\"78641.70\",\"25.554\"],[\"78800.90\",\"11.567\"],[\"79198.90\",\"3.845\"],[\"79451.20\",\"0.001\"],[\"79451.30\",\"1.885\"],[\"79568.90\",\"0.455\"],[\"79570.10\",\"0.001\"],[\"79590.00\",\"0.094\"],[\"79591.40\",\"0.079\"],[\"79591.70\",\"0.003\"],[\"79595.00\",\"0.002\"],[\"79595.90\",\"0.037\"],[\"79596.00\",\"0.082\"],[\"79596.20\",\"0.026\"],[\"79596.30\",\"0.026\"],[\"79596.50\",\"0.470\"],[\"79596.80\",\"0.159\"],[\"79596.90\",\"4.880\"]],\"a\":[[\"79597.00\",\"8.718\"],[\"79597.60\",\"0.117\"],[\"79597.80\",\"0.031\"],[\"79599.90\",\"0.002\"],[\"79600.10\",\"0.002\"],[\"79600.20\",\"0.001\"],[\"79623.80\",\"0.008\"],[\"79628.80\",\"0.000\"],[\"79657.50\",\"0.052\"],[\"79719.50\",\"0.030\"],[\"79719.70\",\"1.884\"],[\"79806.20\",\"4.747\"],[\"79995.00\",\"4.448\"],[\"80233.80\",\"7.090\"],[\"80313.40\",\"0.127\"],[\"80393.00\",\"14.830\"],[\"80615.90\",\"0.008\"],[\"80776.70\",\"1.818\"],[\"80791.00\",\"1.952\"],[\"81174.70\",\"3.443\"],[\"81189.00\",\"1.483\"]],\"st\":1}}"}
{"receive_ns":1788567768351375000,"stream":"btcusdt@bookTicker","event_type":"bookTicker","event_time_ms":1788567768366,"raw_json":"{\"stream\":\"btcusdt@bookTicker\",\"data\":{\"e\":\"bookTicker\",\"u\":11478510740129,\"s\":\"BTCUSDT\",\"ps\":\"BTCUSDT\",\"b\":\"79596.90\",\"B\":\"5.047\",\"a\":\"79597.00\",\"A\":\"8.718\",\"T\":1788567768366,\"E\":1788567768366,\"st\":1}}"}
{"receive_ns":1788567768357845000,"stream":"btcusdt@bookTicker","event_type":"bookTicker","event_time_ms":1788567768368,"raw_json":"{\"stream\":\"btcusdt@bookTicker\",\"data\":{\"e\":\"bookTicker\",\"u\":11478510740197,\"s\":\"BTCUSDT\",\"ps\":\"BTCUSDT\",\"b\":\"79596.90\",\"B\":\"5.046\",\"a\":\"79597.00\",\"A\":\"8.718\",\"T\":1788567768368,\"E\":1788567768368,\"st\":1}}"}
{"receive_ns":1788567768403436000,"stream":"btcusdt@depth@100ms","event_type":"depthUpdate","event_time_ms":1788567768411,"raw_json":"{\"stream\":\"btcusdt@depth@100ms\",\"data\":{\"e\":\"depthUpdate\",\"E\":1788567768411,\"T\":1788567768410,\"s\":\"BTCUSDT\",\"ps\":\"BTCUSDT\",\"U\":11478510737058,\"u\":11478510742959,\"pu\":11478510736869,\"b\":[[\"29296.90\",\"0.056\"],[\"29396.90\",\"1.799\"],[\"29496.90\",\"0.245\"],[\"71637.20\",\"0.002\"],[\"76413.00\",\"0.023\"],[\"78005.00\",\"0.174\"],[\"78402.90\",\"0.721\"],[\"78522.30\",\"5.785\"],[\"78578.10\",\"0.018\"],[\"78641.70\",\"29.363\"],[\"78800.90\",\"10.318\"],[\"78813.70\",\"0.004\"],[\"79379.00\",\"0.022\"],[\"79541.10\",\"1.098\"],[\"79559.10\",\"0.001\"],[\"79563.00\",\"0.047\"],[\"79568.90\",\"0.003\"],[\"79570.00\",\"0.457\"],[\"79573.20\",\"0.538\"],[\"79594.60\",\"0.027\"],[\"79595.10\",\"0.002\"],[\"79596.70\",\"0.041\"],[\"79596.90\",\"5.046\"]],\"a\":[[\"79613.10\",\"0.194\"],[\"79617.10\",\"0.002\"],[\"79617.20\",\"0.002\"],[\"79635.10\",\"0.046\"],[\"79638.90\",\"0.041\"],[\"79668.70\",\"2.054\"],[\"79692.60\",\"0.002\"],[\"80393.00\",\"14.842\"],[\"80552.20\",\"25.882\"],[\"80615.90\",\"0.020\"],[\"80711.40\",\"26.967\"],[\"80791.00\",\"2.242\"],[\"80934.20\",\"1.479\"],[\"81189.00\",\"1.489\"]],\"st\":1}}"}
{"receive_ns":1788567768409997000,"stream":"btcusdt@bookTicker","event_type":"bookTicker","event_time_ms":1788567768418,"raw_json":"{\"stream\":\"btcusdt@bookTicker\",\"data\":{\"e\":\"bookTicker\",\"u\":11478510743574,\"s\":\"BTCUSDT\",\"ps\":\"BTCUSDT\",\"b\":\"79596.90\",\"B\":\"5.046\",\"a\":\"79597.00\",\"A\":\"8.722\",\"T\":1788567768417,\"E\":1788567768418,\"st\":1}}"}
{"receive_ns":1788567768505318000,"stream":"btcusdt@depth@100ms","event_type":"depthUpdate","event_time_ms":1788567768513,"raw_json":"{\"stream\":\"btcusdt@depth@100ms\",\"data\":{\"e\":\"depthUpdate\",\"E\":1788567768513,\"T\":1788567768509,\"s\":\"BTCUSDT\",\"ps\":\"BTCUSDT\",\"U\":11478510742994,\"u\":11478510749696,\"pu\":11478510742959,\"b\":[[\"1000.00\",\"24.604\"],[\"29296.90\",\"0.112\"],[\"29396.90\",\"1.862\"],[\"29496.90\",\"0.126\"],[\"71637.20\",\"0.002\"],[\"76413.00\",\"0.025\"],[\"78432.90\",\"1.019\"],[\"78466.70\",\"1.224\"],[\"78578.10\",\"0.024\"],[\"78800.90\",\"10.318\"],[\"79198.90\",\"3.845\"],[\"79525.20\",\"0.002\"],[\"79549.20\",\"0.840\"],[\"79591.50\",\"0.000\"],[\"79592.10\",\"0.004\"],[\"79592.60\",\"0.076\"],[\"79595.20\",\"0.000\"],[\"79596.80\",\"0.185\"]],\"a\":[[\"79597.00\",\"8.722\"],[\"79597.60\",\"0.091\"],[\"79597.80\",\"0.005\"],[\"79598.10\",\"0.000\"],[\"79599.90\",\"0.028\"],[\"79600.00\",\"0.075\"],[\"79692.60\",\"0.004\"],[\"79796.00\",\"0.003\"],[\"80393.00\",\"14.842\"],[\"80615.90\",\"0.026\"],[\"80727.30\",\"1.184\"]],\"st\":1}}"}
{"receive_ns":1788567768511678000,"stream":"btcusdt@bookTicker","event_type":"bookTicker","event_time_ms":1788567768518,"raw_json":"{\"stream\":\"btcusdt@bookTicker\",\"data\":{\"e\":\"bookTicker\",\"u\":11478510750176,\"s\":\"BTCUSDT\",\"ps\":\"BTCUSDT\",\"b\":\"79596.90\",\"B\":\"5.046\",\"a\":\"79597.00\",\"A\":\"8.720\",\"T\":1788567768518,\"E\":1788567768518,\"st\":1}}"}
{"receive_ns":1788567768517464000,"stream":"btcusdt@trade","event_type":"trade","event_time_ms":1788567768518,"raw_json":"{\"stream\":\"btcusdt@trade\",\"data\":{\"e\":\"trade\",\"E\":1788567768518,\"T\":1788567768518,\"s\":\"BTCUSDT\",\"t\":8054122798,\"p\":\"79597.00\",\"q\":\"0.002\",\"X\":\"MARKET\",\"m\":false,\"st\":1}}"}
{"receive_ns":1788567768523010000,"stream":"btcusdt@bookTicker","event_type":"bookTicker","event_time_ms":1788567768527,"raw_json":"{\"stream\":\"btcusdt@bookTicker\",\"data\":{\"e\":\"bookTicker\",\"u\":11478510751230,\"s\":\"BTCUSDT\",\"ps\":\"BTCUSDT\",\"b\":\"79596.90\",\"B\":\"5.046\",\"a\":\"79597.00\",\"A\":\"8.723\",\"T\":1788567768527,\"E\":1788567768527,\"st\":1}}"}
{"receive_ns":1788567768624077000,"stream":"btcusdt@depth@100ms","event_type":"depthUpdate","event_time_ms":1788567768615,"raw_json":"{\"stream\":\"btcusdt@depth@100ms\",\"data\":{\"e\":\"depthUpdate\",\"E\":1788567768615,\"T\":1788567768614,\"s\":\"BTCUSDT\",\"ps\":\"BTCUSDT\",\"U\":11478510749906,\"u\":11478510757612,\"pu\":11478510749696,\"b\":[[\"1000.00\",\"24.604\"],[\"29296.90\",\"0.182\"],[\"29396.90\",\"1.904\"],[\"29496.90\",\"0.014\"],[\"63678.00\",\"0.006\"],[\"71637.20\",\"0.002\"],[\"78402.90\",\"2.593\"],[\"78800.90\",\"10.318\"],[\"79531.30\",\"0.011\"],[\"79534.00\",\"20.207\"],[\"79536.70\",\"0.000\"],[\"79537.70\",\"0.830\"],[\"79539.00\",\"0.881\"],[\"79553.60\",\"0.691\"],[\"79584.50\",\"0.078\"],[\"79594.00\",\"0.001\"]],\"a\":[[\"79597.00\",\"8.723\"],[\"79611.90\",\"0.692\"],[\"79627.80\",\"0.832\"],[\"80393.00\",\"14.842\"],[\"80552.20\",\"25.263\"],[\"80592.10\",\"7.081\"],[\"81188.90\",\"0.043\"]],\"st\":1}}"}
{"receive_ns":1788567768713439000,"stream":"btcusdt@depth@100ms","event_type":"depthUpdate","event_time_ms":1788567768717,"raw_json":"{\"stream\":\"btcusdt@depth@100ms\",\"data\":{\"e\":\"depthUpdate\",\"E\":1788567768717,\"T\":1788567768714,\"s\":\"BTCUSDT\",\"ps\":\"BTCUSDT\",\"U\":11478510757693,\"u\":11478510763059,\"pu\":11478510757612,\"b\":[[\"29296.90\",\"0.343\"],[\"29396.90\",\"1.757\"],[\"29496.90\",\"0.000\"],[\"71637.20\",\"0.002\"],[\"76413.00\",\"0.023\"],[\"78005.00\",\"0.180\"],[\"78402.90\",\"2.599\"],[\"78426.80\",\"5.978\"],[\"78578.10\",\"0.030\"],[\"78800.90\",\"10.324\"]],\"a\":[[\"79665.50\",\"6.300\"],[\"79666.10\",\"22.026\"],[\"80393.00\",\"14.848\"],[\"80615.90\",\"0.032\"],[\"80657.40\",\"3.742\"],[\"80791.00\",\"2.248\"],[\"81189.00\",\"1.495\"]],\"st\":1}}"}
{"receive_ns":1788567768790255000,"stream":"btcusdt@bookTicker","event_type":"bookTicker","event_time_ms":1788567768802,"raw_json":"{\"stream\":\"btcusdt@bookTicker\",\"data\":{\"e\":\"bookTicker\",\"u\":11478510767079,\"s\":\"BTCUSDT\",\"ps\":\"BTCUSDT\",\"b\":\"79596.90\",\"B\":\"5.046\",\"a\":\"79597.00\",\"A\":\"8.724\",\"T\":1788567768801,\"E\":1788567768802,\"st\":1}}"}
{"receive_ns":1788567768808703000,"stream":"btcusdt@depth@100ms","event_type":"depthUpdate","event_time_ms":1788567768819,"raw_json":"{\"stream\":\"btcusdt@depth@100ms\",\"data\":{\"e\":\"depthUpdate\",\"E\":1788567768819,\"T\":1788567768817,\"s\":\"BTCUSDT\",\"ps\":\"BTCUSDT\",\"U\":11478510763224,\"u\":11478510767754,\"pu\":11478510763059,\"b\":[[\"1000.00\",\"24.604\"],[\"29296.90\",\"0.525\"],[\"29396.90\",\"1.575\"],[\"71637.20\",\"0.002\"],[\"75617.10\",\"0.016\"],[\"76413.00\",\"0.025\"],[\"78005.00\",\"0.177\"],[\"78391.70\",\"0.223\"],[\"78482.50\",\"26.846\"],[\"78641.70\",\"30.633\"],[\"78800.90\",\"10.330\"],[\"79198.90\",\"3.845\"],[\"79595.90\",\"0.002\"]],\"a\":[[\"79597.00\",\"8.724\"],[\"79623.80\",\"0.002\"],[\"80393.00\",\"14.848\"],[\"81188.90\",\"0.040\"]],\"st\":1}}"}
{"receive_ns":1788567768907056000,"stream":"btcusdt@depth@100ms","event_type":"depthUpdate","event_time_ms":1788567768921,"raw_json":"{\"stream\":\"btcusdt@depth@100ms\",\"data\":{\"e\":\"depthUpdate\",\"E\":1788567768921,\"T\":1788567768918,\"s\":\"BTCUSDT\",\"ps\":\"BTCUSDT\",\"U\":11478510767817,\"u\":11478510771751,\"pu\":11478510767754,\"b\":[[\"1000.00\",\"24.604\"],[\"29296.90\",\"0.700\"],[\"29396.90\",\"1.400\"],[\"63677.50\",\"0.000\"],[\"71637.20\",\"0.002\"],[\"76413.00\",\"0.023\"],[\"76413.20\",\"0.001\"],[\"78005.00\",\"0.183\"],[\"78402.90\",\"2.605\"],[\"78800.90\",\"10.342\"],[\"79592.60\",\"0.000\"]],\"a\":[[\"79598.00\",\"0.107\"],[\"80393.00\",\"14.866\"],[\"80552.20\",\"25.882\"],[\"80631.80\",\"4.635\"],[\"80791.00\",\"2.254\"],[\"81189.00\",\"1.501\"]],\"st\":1}}"}
{"receive_ns":1788567768999539000,"stream":"btcusdt@bookTicker","event_type":"bookTicker","event_time_ms":1788567769009,"raw_json":"{\"stream\":\"btcusdt@bookTicker\",\"data\":{\"e\":\"bookTicker\",\"u\":11478510776959,\"s\":\"BTCUSDT\",\"ps\":\"BTCUSDT\",\"b\":\"79596.90\",\"B\":\"5.046\",\"a\":\"79597.00\",\"A\":\"8.718\",\"T\":1788567769009,\"E\":1788567769009,\"st\":1}}"}
{"receive_ns":1788567769007166000,"stream":"btcusdt@trade","event_type":"trade","event_time_ms":1788567769009,"raw_json":"{\"stream\":\"btcusdt@trade\",\"data\":{\"e\":\"trade\",\"E\":1788567769009,\"T\":1788567769009,\"s\":\"BTCUSDT\",\"t\":8054122799,\"p\":\"79597.00\",\"q\":\"0.006\",\"X\":\"MARKET\",\"m\":false,\"st\":1}}"}
{"receive_ns":1788567769012162000,"stream":"btcusdt@depth@100ms","event_type":"depthUpdate","event_time_ms":1788567769023,"raw_json":"{\"stream\":\"btcusdt@depth@100ms\",\"data\":{\"e\":\"depthUpdate\",\"E\":1788567769023,\"T\":1788567769021,\"s\":\"BTCUSDT\",\"ps\":\"BTCUSDT\",\"U\":11478510771898,\"u\":11478510777666,\"pu\":11478510771751,\"b\":[[\"29296.90\",\"0.882\"],[\"29396.90\",\"1.218\"],[\"71637.20\",\"0.002\"],[\"76413.00\",\"0.025\"],[\"78005.00\",\"0.201\"],[\"78402.90\",\"2.617\"],[\"78578.10\",\"0.042\"],[\"78800.90\",\"10.342\"],[\"79198.90\",\"3.855\"],[\"79475.50\",\"0.000\"],[\"79475.60\",\"0.377\"],[\"79506.70\",\"4.364\"]],\"a\":[[\"79597.00\",\"8.718\"],[\"79688.30\",\"3.397\"],[\"79719.00\",\"0.343\"],[\"79719.10\",\"0.000\"],[\"79806.20\",\"1.561\"],[\"79819.00\",\"6.913\"],[\"79995.00\",\"4.323\"],[\"80384.80\",\"0.000\"],[\"80393.00\",\"14.866\"],[\"80478.70\",\"9.354\"],[\"80615.90\",\"0.044\"],[\"80791.00\",\"2.266\"],[\"81189.00\",\"1.519\"]],\"st\":1}}"}
{"receive_ns":1788567769019178000,"stream":"btcusdt@bookTicker","event_type":"bookTicker","event_time_ms":1788567769033,"raw_json":"{\"stream\":\"btcusdt@bookTicker\",\"data\":{\"e\":\"bookTicker\",\"u\":11478510778161,\"s\":\"BTCUSDT\",\"ps\":\"BTCUSDT\",\"b\":\"79596.90\",\"B\":\"5.046\",\"a\":\"79597.00\",\"A\":\"8.710\",\"T\":1788567769033,\"E\":1788567769033,\"st\":1}}"}
{"receive_ns":1788567769025977000,"stream":"btcusdt@bookTicker","event_type":"bookTicker","event_time_ms":1788567769037,"raw_json":"{\"stream\":\"btcusdt@bookTicker\",\"data\":{\"e\":\"bookTicker\",\"u\":11478510778461,\"s\":\"BTCUSDT\",\"ps\":\"BTCUSDT\",\"b\":\"79596.90\",\"B\":\"5.024\",\"a\":\"79597.00\",\"A\":\"8.710\",\"T\":1788567769037,\"E\":1788567769037,\"st\":1}}"}
{"receive_ns":1788567769032199000,"stream":"btcusdt@bookTicker","event_type":"bookTicker","event_time_ms":1788567769040,"raw_json":"{\"stream\":\"btcusdt@bookTicker\",\"data\":{\"e\":\"bookTicker\",\"u\":11478510778622,\"s\":\"BTCUSDT\",\"ps\":\"BTCUSDT\",\"b\":\"79596.90\",\"B\":\"5.041\",\"a\":\"79597.00\",\"A\":\"8.710\",\"T\":1788567769040,\"E\":1788567769040,\"st\":1}}"}
{"receive_ns":1788567769039109000,"stream":"btcusdt@bookTicker","event_type":"bookTicker","event_time_ms":1788567769041,"raw_json":"{\"stream\":\"btcusdt@bookTicker\",\"data\":{\"e\":\"bookTicker\",\"u\":11478510778690,\"s\":\"BTCUSDT\",\"ps\":\"BTCUSDT\",\"b\":\"79596.90\",\"B\":\"5.042\",\"a\":\"79597.00\",\"A\":\"8.710\",\"T\":1788567769041,\"E\":1788567769041,\"st\":1}}"}
{"receive_ns":1788567769045372000,"stream":"btcusdt@bookTicker","event_type":"bookTicker","event_time_ms":1788567769044,"raw_json":"{\"stream\":\"btcusdt@bookTicker\",\"data\":{\"e\":\"bookTicker\",\"u\":11478510778796,\"s\":\"BTCUSDT\",\"ps\":\"BTCUSDT\",\"b\":\"79596.90\",\"B\":\"5.034\",\"a\":\"79597.00\",\"A\":\"8.710\",\"T\":1788567769044,\"E\":1788567769044,\"st\":1}}"}
{"receive_ns":1788567769051116000,"stream":"btcusdt@trade","event_type":"trade","event_time_ms":1788567769044,"raw_json":"{\"stream\":\"btcusdt@trade\",\"data\":{\"e\":\"trade\",\"E\":1788567769044,\"T\":1788567769044,\"s\":\"BTCUSDT\",\"t\":8054122800,\"p\":\"79596.90\",\"q\":\"0.008\",\"X\":\"MARKET\",\"m\":true,\"st\":1}}"}
{"receive_ns":1788567769057142000,"stream":"btcusdt@bookTicker","event_type":"bookTicker","event_time_ms":1788567769047,"raw_json":"{\"stream\":\"btcusdt@bookTicker\",\"data\":{\"e\":\"bookTicker\",\"u\":11478510778975,\"s\":\"BTCUSDT\",\"ps\":\"BTCUSDT\",\"b\":\"79596.90\",\"B\":\"5.029\",\"a\":\"79597.00\",\"A\":\"8.710\",\"T\":1788567769047,\"E\":1788567769047,\"st\":1}}"}
{"receive_ns":1788567769063216000,"stream":"btcusdt@bookTicker","event_type":"bookTicker","event_time_ms":1788567769052,"raw_json":"{\"stream\":\"btcusdt@bookTicker\",\"data\":{\"e\":\"bookTicker\",\"u\":11478510779297,\"s\":\"BTCUSDT\",\"ps\":\"BTCUSDT\",\"b\":\"79596.90\",\"B\":\"5.008\",\"a\":\"79597.00\",\"A\":\"8.710\",\"T\":1788567769052,\"E\":1788567769052,\"st\":1}}"}
{"receive_ns":1788567769065253000,"stream":"btcusdt@bookTicker","event_type":"bookTicker","event_time_ms":1788567769056,"raw_json":"{\"stream\":\"btcusdt@bookTicker\",\"data\":{\"e\":\"bookTicker\",\"u\":11478510779508,\"s\":\"BTCUSDT\",\"ps\":\"BTCUSDT\",\"b\":\"79596.90\",\"B\":\"5.027\",\"a\":\"79597.00\",\"A\":\"8.710\",\"T\":1788567769056,\"E\":1788567769056,\"st\":1}}"}
{"receive_ns":1788567769086592000,"stream":"btcusdt@bookTicker","event_type":"bookTicker","event_time_ms":1788567769097,"raw_json":"{\"stream\":\"btcusdt@bookTicker\",\"data\":{\"e\":\"bookTicker\",\"u\":11478510781789,\"s\":\"BTCUSDT\",\"ps\":\"BTCUSDT\",\"b\":\"79596.90\",\"B\":\"5.023\",\"a\":\"79597.00\",\"A\":\"8.710\",\"T\":1788567769097,\"E\":1788567769097,\"st\":1}}"}
{"receive_ns":1788567769092324000,"stream":"btcusdt@bookTicker","event_type":"bookTicker","event_time_ms":1788567769104,"raw_json":"{\"stream\":\"btcusdt@bookTicker\",\"data\":{\"e\":\"bookTicker\",\"u\":11478510782275,\"s\":\"BTCUSDT\",\"ps\":\"BTCUSDT\",\"b\":\"79596.90\",\"B\":\"5.023\",\"a\":\"79597.00\",\"A\":\"8.706\",\"T\":1788567769104,\"E\":1788567769104,\"st\":1}}"}
{"receive_ns":1788567769098268000,"stream":"btcusdt@trade","event_type":"trade","event_time_ms":1788567769104,"raw_json":"{\"stream\":\"btcusdt@trade\",\"data\":{\"e\":\"trade\",\"E\":1788567769104,\"T\":1788567769104,\"s\":\"BTCUSDT\",\"t\":8054122801,\"p\":\"79597.00\",\"q\":\"0.004\",\"X\":\"MARKET\",\"m\":false,\"st\":1}}"}
{"receive_ns":1788567769117020000,"stream":"btcusdt@depth@100ms","event_type":"depthUpdate","event_time_ms":1788567769125,"raw_json":"{\"stream\":\"btcusdt@depth@100ms\",\"data\":{\"e\":\"depthUpdate\",\"E\":1788567769125,\"T\":1788567769122,\"s\":\"BTCUSDT\",\"ps\":\"BTCUSDT\",\"U\":11478510777767,\"u\":11478510783599,\"pu\":11478510777666,\"b\":[[\"1000.00\",\"24.604\"],[\"29296.90\",\"1.057\"],[\"29396.90\",\"1.043\"],[\"71637.20\",\"0.002\"],[\"78005.00\",\"0.204\"],[\"78601.90\",\"6.314\"],[\"78800.90\",\"10.342\"],[\"79501.30\",\"0.002\"],[\"79549.10\",\"0.002\"],[\"79582.60\",\"0.070\"],[\"79588.00\",\"1.889\"],[\"79589.00\",\"0.004\"],[\"79589.60\",\"1.042\"],[\"79596.70\",\"0.033\"],[\"79596.90\",\"5.023\"]],\"a\":[[\"79597.00\",\"8.706\"],[\"79597.70\",\"0.000\"],[\"79597.90\",\"0.028\"],[\"79598.00\",\"0.081\"],[\"79598.30\",\"0.028\"],[\"79599.00\",\"0.028\"],[\"79601.20\",\"0.002\"],[\"79732.40\",\"0.007\"],[\"79806.20\",\"4.747\"],[\"79835.80\",\"0.003\"],[\"80393.00\",\"14.866\"]],\"st\":1}}"}
{"receive_ns":1788567769216542000,"stream":"btcusdt@depth@100ms","event_type":"depthUpdate","event_time_ms":1788567769227,"raw_json":"{\"stream\":\"btcusdt@depth@100ms\",\"data\":{\"e\":\"depthUpdate\",\"E\":1788567769227,\"T\":1788567769225,\"s\":\"BTCUSDT\",\"ps\":\"BTCUSDT\",\"U\":11478510783688,\"u\":11478510788575,\"pu\":11478510783599,\"b\":[[\"1000.00\",\"24.604\"],[\"29296.90\",\"1.239\"],[\"29396.90\",\"0.861\"],[\"71637.20\",\"0.002\"],[\"71673.00\",\"0.000\"],[\"75617.10\",\"0.014\"],[\"75617.20\",\"0.008\"],[\"76413.00\",\"0.023\"],[\"78005.00\",\"0.210\"],[\"78244.80\",\"0.031\"],[\"78402.90\",\"2.623\"],[\"78578.10\",\"0.048\"],[\"78800.90\",\"10.348\"],[\"79534.50\",\"4.473\"],[\"79563.00\",\"0.001\"],[\"79566.60\",\"0.799\"]],\"a\":[[\"79631.70\",\"0.046\"],[\"79635.10\",\"0.000\"],[\"80313.40\",\"0.251\"],[\"80393.00\",\"14.872\"],[\"80558.30\",\"10.710\"],[\"80615.90\",\"0.050\"],[\"80791.00\",\"2.272\"],[\"81189.00\",\"1.525\"]],\"st\":1}}"}
{"receive_ns":1788567769269963000,"stream":"btcusdt@bookTicker","event_type":"bookTicker","event_time_ms":1788567769280,"raw_json":"{\"stream\":\"btcusdt@bookTicker\",\"data\":{\"e\":\"bookTicker\",\"u\":11478510791494,\"s\":\"BTCUSDT\",\"ps\":\"BTCUSDT\",\"b\":\"79596.90\",\"B\":\"5.023\",\"a\":\"79597.00\",\"A\":\"8.702\",\"T\":1788567769280,\"E\":1788567769280,\"st\":1}}"}
{"receive_ns":1788567769271263000,"stream":"btcusdt@trade","event_type":"trade","event_time_ms":1788567769280,"raw_json":"{\"stream\":\"btcusdt@trade\",\"data\":{\"e\":\"trade\",\"E\":1788567769280,\"T\":1788567769280,\"s\":\"BTCUSDT\",\"t\":8054122802,\"p\":\"79597.00\",\"q\":\"0.004\",\"X\":\"MARKET\",\"m\":false,\"st\":1}}"}
{"receive_ns":1788567769314940000,"stream":"btcusdt@depth@100ms","event_type":"depthUpdate","event_time_ms":1788567769329,"raw_json":"{\"stream\":\"btcusdt@depth@100ms\",\"data\":{\"e\":\"depthUpdate\",\"E\":1788567769329,\"T\":1788567769328,\"s\":\"BTCUSDT\",\"ps\":\"BTCUSDT\",\"U\":11478510788759,\"u\":11478510794999,\"pu\":11478510788575,\"b\":[[\"29296.90\",\"1.414\"],[\"29396.90\",\"0.686\"],[\"63678.00\",\"0.008\"],[\"71637.20\",\"0.002\"],[\"76413.00\",\"0.025\"],[\"78251.70\",\"5.711\"],[\"78800.90\",\"10.348\"],[\"79022.10\",\"0.000\"],[\"79196.30\",\"0.000\"],[\"79198.90\",\"3.844\"],[\"79199.90\",\"0.885\"],[\"79315.30\",\"0.000\"],[\"79316.00\",\"1.020\"],[\"79565.50\",\"0.046\"],[\"79566.60\",\"0.753\"],[\"79568.90\",\"0.455\"],[\"79570.00\",\"0.005\"],[\"79571.10\",\"0.000\"],[\"79575.40\",\"0.392\"],[\"79575.60\",\"0.877\"],[\"79576.40\",\"2.897\"],[\"79577.40\",\"0.000\"],[\"79592.80\",\"0.505\"],[\"79593.00\",\"0.133\"]],\"a\":[[\"79597.00\",\"8.702\"],[\"79597.80\",\"0.005\"],[\"79597.90\",\"0.002\"],[\"79598.20\",\"0.002\"],[\"79598.30\",\"0.002\"],[\"79598.80\",\"0.029\"],[\"79610.60\",\"0.441\"],[\"79610.70\",\"0.106\"],[\"79611.80\",\"0.001\"],[\"79615.30\",\"0.559\"],[\"79616.70\",\"0.751\"],[\"79617.50\",\"0.000\"],[\"79618.50\",\"0.454\"],[\"79619.90\",\"0.000\"],[\"79620.60\",\"0.002\"],[\"79627.40\",\"0.007\"],[\"79884.10\",\"4.476\"],[\"79884.20\",\"0.000\"],[\"79995.00\",\"4.322\"],[\"80004.00\",\"3.825\"],[\"80004.10\",\"0.000\"],[\"80180.10\",\"0.000\"],[\"80393.00\",\"14.872\"],[\"80791.00\",\"4.089\"],[\"80934.40\",\"0.000\"]],\"st\":1}}"}
{"receive_ns":1788567769416653000,"stream":"btcusdt@depth@100ms","event_type":"depthUpdate","event_time_ms":1788567769431,"raw_json":"{\"stream\":\"btcusdt@depth@100ms\",\"data\":{\"e\":\"depthUpdate\",\"E\":1788567769431,\"T\":1788567769430,\"s\":\"BTCUSDT\",\"ps\":\"BTCUSDT\",\"U\":11478510795053,\"u\":11478510800464,\"pu\":11478510794999,\"b\":[[\"1000.00\",\"24.604\"],[\"29296.90\",\"1.596\"],[\"29396.90\",\"0.504\"],[\"63678.00\",\"0.008\"],[\"71637.20\",\"0.002\"],[\"75617.20\",\"0.006\"],[\"76413.00\",\"0.023\"],[\"78005.00\",\"0.216\"],[\"78402.90\",\"2.629\"],[\"78578.10\",\"0.054\"],[\"78800.90\",\"10.354\"],[\"78816.10\",\"3.240\"],[\"78888.10\",\"0.648\"],[\"79000.10\",\"0.212\"],[\"79022.20\",\"0.000\"],[\"79196.40\",\"0.002\"],[\"79315.40\",\"0.000\"],[\"79568.90\",\"0.003\"],[\"79570.10\",\"0.453\"],[\"79573.20\",\"0.538\"],[\"79592.50\",\"0.078\"],[\"79593.00\",\"0.057\"],[\"79596.10\",\"0.058\"]],\"a\":[[\"79598.00\",\"0.081\"],[\"79598.50\",\"0.026\"],[\"79598.70\",\"0.030\"],[\"79600.00\",\"0.049\"],[\"79613.10\",\"0.194\"],[\"79615.30\",\"0.187\"],[\"79616.60\",\"0.423\"],[\"79618.50\",\"0.002\"],[\"79619.90\",\"0.452\"],[\"79626.30\",\"0.008\"],[\"79626.70\",\"0.046\"],[\"79884.10\",\"4.314\"],[\"79887.90\",\"0.463\"],[\"80001.40\",\"0.000\"],[\"80004.00\",\"0.585\"],[\"80099.90\",\"10.726\"],[\"80393.00\",\"14.872\"],[\"80615.90\",\"0.056\"],[\"80711.40\",\"25.111\"],[\"80751.20\",\"9.862\"],[\"80830.80\",\"4.326\"],[\"81189.00\",\"1.531\"]],\"st\":1}}"}
{"receive_ns":1788567769437479000,"stream":"btcusdt@bookTicker","event_type":"bookTicker","event_time_ms":1788567769444,"raw_json":"{\"stream\":\"btcusdt@bookTicker\",\"data\":{\"e\":\"bookTicker\",\"u\":11478510801312,\"s\":\"BTCUSDT\",\"ps\":\"BTCUSDT\",\"b\":\"79596.90\",\"B\":\"5.022\",\"a\":\"79597.00\",\"A\":\"8.702\",\"T\":1788567769444,\"E\":1788567769444,\"st\":1}}"}
{"receive_ns":1788567769450151000,"stream":"btcusdt@trade","event_type":"trade","event_time_ms":1788567769444,"raw_json":"{\"stream\":\"btcusdt@trade\",\"data\":{\"e\":\"trade\",\"E\":1788567769444,\"T\":1788567769444,\"s\":\"BTCUSDT\",\"t\":8054122803,\"p\":\"79596.90\",\"q\":\"0.001\",\"X\":\"MARKET\",\"m\":true,\"st\":1}}"}
{"receive_ns":1788567769474225000,"stream":"btcusdt@bookTicker","event_type":"bookTicker","event_time_ms":1788567769481,"raw_json":"{\"stream\":\"btcusdt@bookTicker\",\"data\":{\"e\":\"bookTicker\",\"u\":11478510802855,\"s\":\"BTCUSDT\",\"ps\":\"BTCUSDT\",\"b\":\"79596.90\",\"B\":\"5.017\",\"a\":\"79597.00\",\"A\":\"8.702\",\"T\":1788567769481,\"E\":1788567769481,\"st\":1}}"}
{"receive_ns":1788567769480510000,"stream":"btcusdt@bookTicker","event_type":"bookTicker","event_time_ms":1788567769484,"raw_json":"{\"stream\":\"btcusdt@bookTicker\",\"data\":{\"e\":\"bookTicker\",\"u\":11478510803001,\"s\":\"BTCUSDT\",\"ps\":\"BTCUSDT\",\"b\":\"79596.90\",\"B\":\"5.024\",\"a\":\"79597.00\",\"A\":\"8.702\",\"T\":1788567769484,\"E\":1788567769484,\"st\":1}}"}
{"receive_ns":1788567769486414000,"stream":"btcusdt@bookTicker","event_type":"bookTicker","event_time_ms":1788567769491,"raw_json":"{\"stream\":\"btcusdt@bookTicker\",\"data\":{\"e\":\"bookTicker\",\"u\":11478510803563,\"s\":\"BTCUSDT\",\"ps\":\"BTCUSDT\",\"b\":\"79596.90\",\"B\":\"5.024\",\"a\":\"79597.00\",\"A\":\"8.642\",\"T\":1788567769491,\"E\":1788567769491,\"st\":1}}"}
{"receive_ns":1788567769487347000,"stream":"btcusdt@trade","event_type":"trade","event_time_ms":1788567769491,"raw_json":"{\"stream\":\"btcusdt@trade\",\"data\":{\"e\":\"trade\",\"E\":1788567769491,\"T\":1788567769491,\"s\":\"BTCUSDT\",\"t\":8054122804,\"p\":\"79597.00\",\"q\":\"0.060\",\"X\":\"MARKET\",\"m\":false,\"st\":1}}"}
{"receive_ns":1788567769493686000,"stream":"btcusdt@bookTicker","event_type":"bookTicker","event_time_ms":1788567769503,"raw_json":"{\"stream\":\"btcusdt@bookTicker\",\"data\":{\"e\":\"bookTicker\",\"u\":11478510804338,\"s\":\"BTCUSDT\",\"ps\":\"BTCUSDT\",\"b\":\"79596.90\",\"B\":\"5.024\",\"a\":\"79597.00\",\"A\":\"8.657\",\"T\":1788567769503,\"E\":1788567769503,\"st\":1}}"}
{"receive_ns":1788567769522047000,"stream":"btcusdt@depth@100ms","event_type":"depthUpdate","event_time_ms":1788567769533,"raw_json":"{\"stream\":\"btcusdt@depth@100ms\",\"data\":{\"e\":\"depthUpdate\",\"E\":1788567769533,\"T\":1788567769529,\"s\":\"BTCUSDT\",\"ps\":\"BTCUSDT\",\"U\":11478510800573,\"u\":11478510805643,\"pu\":11478510800464,\"b\":[[\"1000.00\",\"24.604\"],[\"29196.90\",\"0.007\"],[\"29296.90\",\"1.757\"],[\"29396.90\",\"0.336\"],[\"71637.20\",\"0.002\"],[\"78466.60\",\"1.404\"],[\"78548.70\",\"4.452\"],[\"78562.20\",\"15.670\"],[\"78578.10\",\"0.060\"],[\"78602.00\",\"13.108\"],[\"78800.90\",\"10.354\"],[\"78808.80\",\"0.000\"],[\"79198.90\",\"3.845\"],[\"79475.60\",\"0.504\"],[\"79592.50\",\"0.002\"],[\"79592.70\",\"0.002\"],[\"79593.30\",\"0.076\"],[\"79596.90\",\"5.024\"]],\"a\":[[\"79597.00\",\"8.657\"],[\"79598.30\",\"0.002\"],[\"79598.50\",\"0.000\"],[\"79598.70\",\"0.004\"],[\"79598.80\",\"0.003\"],[\"79599.00\",\"0.002\"],[\"79599.20\",\"0.000\"],[\"79599.30\",\"0.018\"],[\"79599.40\",\"0.026\"],[\"79599.50\",\"0.029\"],[\"79599.90\",\"0.028\"],[\"79600.00\",\"0.075\"],[\"79600.10\",\"0.028\"],[\"79600.20\",\"0.027\"],[\"79600.30\",\"0.028\"],[\"79719.00\",\"0.462\"],[\"79995.00\",\"4.323\"],[\"80393.00\",\"14.878\"],[\"80396.50\",\"0.000\"],[\"80659.70\",\"0.000\"]],\"st\":1}}"}
{"receive_ns":1788567769542322000,"stream":"btcusdt@bookTicker","event_type":"bookTicker","event_time_ms":1788567769547,"raw_json":"{\"stream\":\"btcusdt@bookTicker\",\"data\":{\"e\":\"bookTicker\",\"u\":11478510806530,\"s\":\"BTCUSDT\",\"ps\":\"BTCUSDT\",\"b\":\"79596.90\",\"B\":\"5.007\",\"a\":\"79597.00\",\"A\":\"8.657\",\"T\":1788567769547,\"E\":1788567769547,\"st\":1}}"}
{"receive_ns":1788567769559491000,"stream":"btcusdt@bookTicker","event_type":"bookTicker","event_time_ms":1788567769551,"raw_json":"{\"stream\":\"btcusdt@bookTicker\",\"data\":{\"e\":\"bookTicker\",\"u\":11478510806740,\"s\":\"BTCUSDT\",\"ps\":\"BTCUSDT\",\"b\":\"79596.90\",\"B\":\"5.022\",\"a\":\"79597.00\",\"A\":\"8.657\",\"T\":1788567769550,\"E\":1788567769551,\"st\":1}}"}
{"receive_ns":1788567769630747000,"stream":"btcusdt@depth@100ms","event_type":"depthUpdate","event_time_ms":1788567769635,"raw_json":"{\"stream\":\"btcusdt@depth@100ms\",\"data\":{\"e\":\"depthUpdate\",\"E\":1788567769635,\"T\":1788567769634,\"s\":\"BTCUSDT\",\"ps\":\"BTCUSDT\",\"U\":11478510805873,\"u\":11478510813143,\"pu\":11478510805643,\"b\":[[\"29196.90\",\"0.070\"],[\"29296.90\",\"1.813\"],[\"29396.90\",\"0.217\"],[\"63678.00\",\"0.008\"],[\"71637.20\",\"0.002\"],[\"76413.00\",\"0.025\"],[\"78800.90\",\"10.354\"],[\"79022.80\",\"73.976\"],[\"79197.00\",\"62.563\"],[\"79198.90\",\"1.839\"],[\"79199.90\",\"10.169\"],[\"79316.00\",\"49.736\"],[\"79319.30\",\"7.915\"],[\"79593.30\",\"0.000\"],[\"79596.70\",\"0.041\"],[\"79596.90\",\"5.022\"]],\"a\":[[\"79598.90\",\"0.027\"],[\"79882.70\",\"48.999\"],[\"80002.60\",\"62.290\"],[\"80178.60\",\"78.845\"],[\"80393.00\",\"14.878\"]],\"st\":1}}"}
{"receive_ns":1788567769681608000,"stream":"btcusdt@bookTicker","event_type":"bookTicker","event_time_ms":1788567769691,"raw_json":"{\"stream\":\"btcusdt@bookTicker\",\"data\":{\"e\":\"bookTicker\",\"u\":11478510815876,\"s\":\"BTCUSDT\",\"ps\":\"BTCUSDT\",\"b\":\"79596.90\",\"B\":\"5.022\",\"a\":\"79597.00\",\"A\":\"8.662\",\"T\":1788567769691,\"E\":1788567769691,\"st\":1}}"}
{"receive_ns":1788567769717195000,"stream":"btcusdt@bookTicker","event_type":"bookTicker","event_time_ms":1788567769726,"raw_json":"{\"stream\":\"btcusdt@bookTicker\",\"data\":{\"e\":\"bookTicker\",\"u\":11478510817857,\"s\":\"BTCUSDT\",\"ps\":\"BTCUSDT\",\"b\":\"79596.90\",\"B\":\"5.022\",\"a\":\"79597.00\",\"A\":\"8.646\",\"T\":1788567769726,\"E\":1788567769726,\"st\":1}}"}
{"receive_ns":1788567769723218000,"stream":"btcusdt@trade","event_type":"trade","event_time_ms":1788567769726,"raw_json":"{\"stream\":\"btcusdt@trade\",\"data\":{\"e\":\"trade\",\"E\":1788567769726,\"T\":1788567769726,\"s\":\"BTCUSDT\",\"t\":8054122805,\"p\":\"79597.00\",\"q\":\"0.016\",\"X\":\"MARKET\",\"m\":false,\"st\":1}}"}
{"receive_ns":1788567769729345000,"stream":"btcusdt@depth@100ms","event_type":"depthUpdate","event_time_ms":1788567769737,"raw_json":"{\"stream\":\"btcusdt@depth@100ms\",\"data\":{\"e\":\"depthUpdate\",\"E\":1788567769737,\"T\":1788567769735,\"s\":\"BTCUSDT\",\"ps\":\"BTCUSDT\",\"U\":11478510813202,\"u\":11478510818443,\"pu\":11478510813143,\"b\":[[\"1000.00\",\"24.604\"],[\"29196.90\",\"0.126\"],[\"29296.90\",\"1.876\"],[\"29396.90\",\"0.098\"],[\"63678.00\",\"0.008\"],[\"71637.20\",\"0.002\"],[\"76413.00\",\"0.023\"],[\"78601.90\",\"6.466\"],[\"78800.90\",\"10.354\"],[\"78809.40\",\"93.666\"],[\"78816.10\",\"0.000\"],[\"78888.10\",\"0.000\"],[\"79000.10\",\"0.050\"],[\"79022.90\",\"3.240\"],[\"79197.10\",\"0.932\"],[\"79316.10\",\"0.164\"],[\"79473.00\",\"0.000\"],[\"79473.10\",\"0.019\"],[\"79501.30\",\"0.000\"],[\"79506.70\",\"4.385\"],[\"79525.20\",\"0.002\"],[\"79541.10\",\"1.096\"],[\"79592.50\",\"0.078\"]],\"a\":[[\"79597.00\",\"8.646\"],[\"79668.70\",\"2.054\"],[\"79688.30\",\"3.351\"],[\"79692.60\",\"0.002\"],[\"79732.40\",\"0.005\"],[\"79806.20\",\"1.594\"],[\"79819.00\",\"6.937\"],[\"79882.60\",\"0.356\"],[\"79887.90\",\"0.301\"],[\"80002.50\",\"3.247\"],[\"80099.90\",\"7.486\"],[\"80393.00\",\"14.878\"],[\"80395.00\",\"97.230\"]],\"st\":1}}"}
{"receive_ns":1788567769738961000,"stream":"btcusdt@bookTicker","event_type":"bookTicker","event_time_ms":1788567769749,"raw_json":"{\"stream\":\"btcusdt@bookTicker\",\"data\":{\"e\":\"bookTicker\",\"u\":11478510819022,\"s\":\"BTCUSDT\",\"ps\":\"BTCUSDT\",\"b\":\"79596.90\",\"B\":\"5.003\",\"a\":\"79597.00\",\"A\":\"8.646\",\"T\":1788567769749,\"E\":1788567769749,\"st\":1}}"}
{"receive_ns":1788567769749658000,"stream":"btcusdt@bookTicker","event_type":"bookTicker","event_time_ms":1788567769752,"raw_json":"{\"stream\":\"btcusdt@bookTicker\",\"data\":{\"e\":\"bookTicker\",\"u\":11478510819167,\"s\":\"BTCUSDT\",\"ps\":\"BTCUSDT\",\"b\":\"79596.90\",\"B\":\"5.021\",\"a\":\"79597.00\",\"A\":\"8.646\",\"T\":1788567769752,\"E\":1788567769752,\"st\":1}}"}
{"receive_ns":1788567769772891000,"stream":"btcusdt@bookTicker","event_type":"bookTicker","event_time_ms":1788567769782,"raw_json":"{\"stream\":\"btcusdt@bookTicker\",\"data\":{\"e\":\"bookTicker\",\"u\":11478510820369,\"s\":\"BTCUSDT\",\"ps\":\"BTCUSDT\",\"b\":\"79596.90\",\"B\":\"5.021\",\"a\":\"79597.00\",\"A\":\"8.593\",\"T\":1788567769782,\"E\":1788567769782,\"st\":1}}"}
{"receive_ns":1788567769779065000,"stream":"btcusdt@trade","event_type":"trade","event_time_ms":1788567769782,"raw_json":"{\"stream\":\"btcusdt@trade\",\"data\":{\"e\":\"trade\",\"E\":1788567769782,\"T\":1788567769782,\"s\":\"BTCUSDT\",\"t\":8054122806,\"p\":\"79597.00\",\"q\":\"0.009\",\"X\":\"MARKET\",\"m\":false,\"st\":1}}"}
{"receive_ns":1788567769779826000,"stream":"btcusdt@trade","event_type":"trade","event_time_ms":1788567769782,"raw_json":"{\"stream\":\"btcusdt@trade\",\"data\":{\"e\":\"trade\",\"E\":1788567769782,\"T\":1788567769782,\"s\":\"BTCUSDT\",\"t\":8054122807,\"p\":\"79597.00\",\"q\":\"0.031\",\"X\":\"MARKET\",\"m\":false,\"st\":1}}"}
{"receive_ns":1788567769780555000,"stream":"btcusdt@trade","event_type":"trade","event_time_ms":1788567769782,"raw_json":"{\"stream\":\"btcusdt@trade\",\"data\":{\"e\":\"trade\",\"E\":1788567769782,\"T\":1788567769782,\"s\":\"BTCUSDT\",\"t\":8054122808,\"p\":\"79597.00\",\"q\":\"0.008\",\"X\":\"MARKET\",\"m\":false,\"st\":1}}"}
{"receive_ns":1788567769781283000,"stream":"btcusdt@trade","event_type":"trade","event_time_ms":1788567769782,"raw_json":"{\"stream\":\"btcusdt@trade\",\"data\":{\"e\":\"trade\",\"E\":1788567769782,\"T\":1788567769782,\"s\":\"BTCUSDT\",\"t\":8054122809,\"p\":\"79597.00\",\"q\":\"0.005\",\"X\":\"MARKET\",\"m\":false,\"st\":1}}"}
{"receive_ns":1788567769787292000,"stream":"btcusdt@bookTicker","event_type":"bookTicker","event_time_ms":1788567769784,"raw_json":"{\"stream\":\"btcusdt@bookTicker\",\"data\":{\"e\":\"bookTicker\",\"u\":11478510820457,\"s\":\"BTCUSDT\",\"ps\":\"BTCUSDT\",\"b\":\"79596.90\",\"B\":\"5.021\",\"a\":\"79597.00\",\"A\":\"8.594\",\"T\":1788567769783,\"E\":1788567769784,\"st\":1}}"}
{"receive_ns":1788567769788259000,"stream":"btcusdt@bookTicker","event_type":"bookTicker","event_time_ms":1788567769784,"raw_json":"{\"stream\":\"btcusdt@bookTicker\",\"data\":{\"e\":\"bookTicker\",\"u\":11478510820476,\"s\":\"BTCUSDT\",\"ps\":\"BTCUSDT\",\"b\":\"79596.90\",\"B\":\"5.022\",\"a\":\"79597.00\",\"A\":\"8.594\",\"T\":1788567769783,\"E\":1788567769784,\"st\":1}}"}
{"receive_ns":1788567769832196000,"stream":"btcusdt@depth@100ms","event_type":"depthUpdate","event_time_ms":1788567769839,"raw_json":"{\"stream\":\"btcusdt@depth@100ms\",\"data\":{\"e\":\"depthUpdate\",\"E\":1788567769839,\"T\":1788567769837,\"s\":\"BTCUSDT\",\"ps\":\"BTCUSDT\",\"U\":11478510818617,\"u\":11478510823278,\"pu\":11478510818443,\"b\":[[\"1000.00\",\"24.604\"],[\"29196.90\",\"0.203\"],[\"29296.90\",\"1.897\"],[\"29396.90\",\"0.000\"],[\"63678.00\",\"0.010\"],[\"71637.20\",\"0.002\"],[\"76413.00\",\"0.025\"],[\"78394.50\",\"0.637\"],[\"78800.90\",\"10.354\"],[\"79596.90\",\"5.022\"]],\"a\":[[\"79597.00\",\"8.594\"],[\"79598.90\",\"0.027\"],[\"79601.20\",\"0.000\"],[\"79627.40\",\"0.001\"],[\"79804.90\",\"0.635\"],[\"79806.20\",\"4.784\"],[\"80393.00\",\"14.878\"],[\"80727.40\",\"1.340\"],[\"80773.40\",\"0.000\"],[\"80950.10\",\"4.194\"],[\"81188.90\",\"0.037\"]],\"st\":1}}"}
{"receive_ns":1788567769930238000,"stream":"btcusdt@depth@100ms","event_type":"depthUpdate","event_time_ms":1788567769941,"raw_json":"{\"stream\":\"btcusdt@depth@100ms\",\"data\":{\"e\":\"depthUpdate\",\"E\":1788567769941,\"T\":1788567769937,\"s\":\"BTCUSDT\",\"ps\":\"BTCUSDT\",\"U\":11478510823369,\"u\":11478510828838,\"pu\":11478510823278,\"b\":[[\"29196.90\",\"0.385\"],[\"29296.90\",\"1.715\"],[\"63677.50\",\"0.000\"],[\"63678.00\",\"0.008\"],[\"71637.20\",\"0.002\"],[\"76413.00\",\"0.023\"],[\"76413.20\",\"0.000\"],[\"78080.20\",\"0.057\"],[\"78602.00\",\"12.823\"],[\"78641.70\",\"31.014\"],[\"78800.90\",\"10.354\"],[\"78960.10\",\"8.588\"],[\"79198.90\",\"3.719\"]],\"a\":[[\"80233.80\",\"7.339\"],[\"80393.00\",\"14.884\"],[\"80552.20\",\"26.254\"],[\"80791.00\",\"4.095\"]],\"st\":1}}"}
{"receive_ns":1788567770106419000,"stream":"btcusdt@depth@100ms","event_type":"depthUpdate","event_time_ms":1788567770043,"raw_json":"{\"stream\":\"btcusdt@depth@100ms\",\"data\":{\"e\":\"depthUpdate\",\"E\":1788567770043,\"T\":1788567770042,\"s\":\"BTCUSDT\",\"ps\":\"BTCUSDT\",\"U\":11478510829042,\"u\":11478510834264,\"pu\":11478510828838,\"b\":[[\"1000.00\",\"24.604\"],[\"29196.90\",\"0.567\"],[\"29296.90\",\"1.533\"],[\"63678.00\",\"0.008\"],[\"71637.20\",\"0.002\"],[\"75617.10\",\"0.016\"],[\"78005.00\",\"0.225\"],[\"78402.90\",\"2.635\"],[\"78508.50\",\"6.460\"],[\"78549.50\",\"0.636\"],[\"78800.90\",\"11.621\"],[\"79198.90\",\"3.845\"],[\"79582.60\",\"0.074\"]],\"a\":[[\"79598.60\",\"0.027\"],[\"79600.30\",\"0.002\"],[\"79995.00\",\"4.448\"],[\"80393.00\",\"14.884\"],[\"80552.20\",\"27.494\"],[\"80615.90\",\"0.062\"],[\"80791.00\",\"4.101\"],[\"81189.00\",\"1.537\"]],\"st\":1}}"}
{"receive_ns":1788567770117515000,"stream":"btcusdt@bookTicker","event_type":"bookTicker","event_time_ms":1788567770087,"raw_json":"{\"stream\":\"btcusdt@bookTicker\",\"data\":{\"e\":\"bookTicker\",\"u\":11478510837133,\"s\":\"BTCUSDT\",\"ps\":\"BTCUSDT\",\"b\":\"79596.90\",\"B\":\"4.959\",\"a\":\"79597.00\",\"A\":\"8.594\",\"T\":1788567770087,\"E\":1788567770087,\"st\":1}}"}
{"receive_ns":1788567770128615000,"stream":"btcusdt@trade","event_type":"trade","event_time_ms":1788567770087,"raw_json":"{\"stream\":\"btcusdt@trade\",\"data\":{\"e\":\"trade\",\"E\":1788567770087,\"T\":1788567770087,\"s\":\"BTCUSDT\",\"t\":8054122810,\"p\":\"79596.90\",\"q\":\"0.063\",\"X\":\"MARKET\",\"m\":true,\"st\":1}}"}
{"receive_ns":1788567770135226000,"stream":"btcusdt@depth@100ms","event_type":"depthUpdate","event_time_ms":1788567770145,"raw_json":"{\"stream\":\"btcusdt@depth@100ms\",\"data\":{\"e\":\"depthUpdate\",\"E\":1788567770145,\"T\":1788567770141,\"s\":\"BTCUSDT\",\"ps\":\"BTCUSDT\",\"U\":11478510834465,\"u\":11478510840287,\"pu\":11478510834264,\"b\":[[\"1000.00\",\"24.604\"],[\"29196.90\",\"0.742\"],[\"29296.90\",\"1.358\"],[\"63678.00\",\"0.008\"],[\"71637.20\",\"0.002\"],[\"76413.00\",\"0.025\"],[\"77368.20\",\"1.552\"],[\"77607.00\",\"1.352\"],[\"78087.70\",\"3.453\"],[\"78800.90\",\"11.621\"],[\"78840.00\",\"1.209\"],[\"79511.40\",\"0.003\"],[\"79535.30\",\"0.003\"],[\"79555.20\",\"0.106\"],[\"79575.10\",\"0.072\"],[\"79582.60\",\"0.070\"],[\"79591.40\",\"0.003\"],[\"79592.50\",\"0.002\"],[\"79596.80\",\"0.185\"],[\"79596.90\",\"4.959\"]],\"a\":[[\"79597.40\",\"0.005\"],[\"79598.00\",\"0.107\"],[\"79600.20\",\"0.001\"],[\"79601.20\",\"0.002\"],[\"79618.80\",\"3.428\"],[\"79620.80\",\"0.127\"],[\"79623.90\",\"0.049\"],[\"79638.70\",\"0.343\"],[\"79658.60\",\"0.316\"],[\"79682.50\",\"0.004\"],[\"79831.20\",\"0.000\"],[\"79831.30\",\"0.362\"],[\"80393.00\",\"14.884\"],[\"80767.10\",\"4.198\"],[\"87556.70\",\"0.000\"]],\"st\":1}}"}
{"receive_ns":1788567770147861000,"stream":"btcusdt@bookTicker","event_type":"bookTicker","event_time_ms":1788567770164,"raw_json":"{\"stream\":\"btcusdt@bookTicker\",\"data\":{\"e\":\"bookTicker\",\"u\":11478510841995,\"s\":\"BTCUSDT\",\"ps\":\"BTCUSDT\",\"b\":\"79596.90\",\"B\":\"6.215\",\"a\":\"79597.00\",\"A\":\"8.594\",\"T\":1788567770164,\"E\":1788567770164,\"st\":1}}"}
{"receive_ns":1788567770167202000,"stream":"btcusdt@bookTicker","event_type":"bookTicker","event_time_ms":1788567770165,"raw_json":"{\"stream\":\"btcusdt@bookTicker\",\"data\":{\"e\":\"bookTicker\",\"u\":11478510842056,\"s\":\"BTCUSDT\",\"ps\":\"BTCUSDT\",\"b\":\"79596.90\",\"B\":\"6.214\",\"a\":\"79597.00\",\"A\":\"8.594\",\"T\":1788567770165,\"E\":1788567770165,\"st\":1}}"}
{"receive_ns":1788567770167437000,"stream":"btcusdt@bookTicker","event_type":"bookTicker","event_time_ms":1788567770165,"raw_json":"{\"stream\":\"btcusdt@bookTicker\",\"data\":{\"e\":\"bookTicker\",\"u\":11478510842058,\"s\":\"BTCUSDT\",\"ps\":\"BTCUSDT\",\"b\":\"79596.90\",\"B\":\"6.213\",\"a\":\"79597.00\",\"A\":\"8.594\",\"T\":1788567770165,\"E\":1788567770165,\"st\":1}}"}
{"receive_ns":1788567770167623000,"stream":"btcusdt@bookTicker","event_type":"bookTicker","event_time_ms":1788567770166,"raw_json":"{\"stream\":\"btcusdt@bookTicker\",\"data\":{\"e\":\"bookTicker\",\"u\":11478510842064,\"s\":\"BTCUSDT\",\"ps\":\"BTCUSDT\",\"b\":\"79596.90\",\"B\":\"6.213\",\"a\":\"79597.00\",\"A\":\"8.593\",\"T\":1788567770165,\"E\":1788567770166,\"st\":1}}"}
{"receive_ns":1788567770167847000,"stream":"btcusdt@bookTicker","event_type":"bookTicker","event_time_ms":1788567770166,"raw_json":"{\"stream\":\"btcusdt@bookTicker\",\"data\":{\"e\":\"bookTicker\",\"u\":11478510842068,\"s\":\"BTCUSDT\",\"ps\":\"BTCUSDT\",\"b\":\"79596.90\",\"B\":\"6.213\",\"a\":\"79597.00\",\"A\":\"8.591\",\"T\":1788567770165,\"E\":1788567770166,\"st\":1}}"}
{"receive_ns":1788567770179704000,"stream":"btcusdt@bookTicker","event_type":"bookTicker","event_time_ms":1788567770168,"raw_json":"{\"stream\":\"btcusdt@bookTicker\",\"data\":{\"e\":\"bookTicker\",\"u\":11478510842189,\"s\":\"BTCUSDT\",\"ps\":\"BTCUSDT\",\"b\":\"79596.90\",\"B\":\"6.213\",\"a\":\"79597.00\",\"A\":\"8.509\",\"T\":1788567770167,\"E\":1788567770168,\"st\":1}}"}
{"receive_ns":1788567770185355000,"stream":"btcusdt@bookTicker","event_type":"bookTicker","event_time_ms":1788567770168,"raw_json":"{\"stream\":\"btcusdt@bookTicker\",\"data\":{\"e\":\"bookTicker\",\"u\":11478510842194,\"s\":\"BTCUSDT\",\"ps\":\"BTCUSDT\",\"b\":\"79596.90\",\"B\":\"6.213\",\"a\":\"79597.00\",\"A\":\"8.427\",\"T\":1788567770168,\"E\":1788567770168,\"st\":1}}"}
{"receive_ns":1788567770185591000,"stream":"btcusdt@bookTicker","event_type":"bookTicker","event_time_ms":1788567770168,"raw_json":"{\"stream\":\"btcusdt@bookTicker\",\"data\":{\"e\":\"bookTicker\",\"u\":11478510842200,\"s\":\"BTCUSDT\",\"ps\":\"BTCUSDT\",\"b\":\"79596.90\",\"B\":\"6.213\",\"a\":\"79597.00\",\"A\":\"8.345\",\"T\":1788567770168,\"E\":1788567770168,\"st\":1}}"}
{"receive_ns":1788567770196458000,"stream":"btcusdt@bookTicker","event_type":"bookTicker","event_time_ms":1788567770195,"raw_json":"{\"stream\":\"btcusdt@bookTicker\",\"data\":{\"e\":\"bookTicker\",\"u\":11478510843310,\"s\":\"BTCUSDT\",\"ps\":\"BTCUSDT\",\"b\":\"79596.90\",\"B\":\"6.213\",\"a\":\"79597.00\",\"A\":\"7.005\",\"T\":1788567770195,\"E\":1788567770195,\"st\":1}}"}
{"receive_ns":1788567770201928000,"stream":"btcusdt@bookTicker","event_type":"bookTicker","event_time_ms":1788567770195,"raw_json":"{\"stream\":\"btcusdt@bookTicker\",\"data\":{\"e\":\"bookTicker\",\"u\":11478510843311,\"s\":\"BTCUSDT\",\"ps\":\"BTCUSDT\",\"b\":\"79596.90\",\"B\":\"6.213\",\"a\":\"79597.00\",\"A\":\"6.992\",\"T\":1788567770195,\"E\":1788567770195,\"st\":1}}"}
{"receive_ns":1788567770208676000,"stream":"btcusdt@bookTicker","event_type":"bookTicker","event_time_ms":1788567770195,"raw_json":"{\"stream\":\"btcusdt@bookTicker\",\"data\":{\"e\":\"bookTicker\",\"u\":11478510843314,\"s\":\"BTCUSDT\",\"ps\":\"BTCUSDT\",\"b\":\"79596.90\",\"B\":\"6.213\",\"a\":\"79597.00\",\"A\":\"6.968\",\"T\":1788567770195,\"E\":1788567770195,\"st\":1}}"}
{"receive_ns":1788567770214334000,"stream":"btcusdt@bookTicker","event_type":"bookTicker","event_time_ms":1788567770195,"raw_json":"{\"stream\":\"btcusdt@bookTicker\",\"data\":{\"e\":\"bookTicker\",\"u\":11478510843320,\"s\":\"BTCUSDT\",\"ps\":\"BTCUSDT\",\"b\":\"79596.90\",\"B\":\"6.213\",\"a\":\"79597.00\",\"A\":\"6.836\",\"T\":1788567770195,\"E\":1788567770195,\"st\":1}}"}
{"receive_ns":1788567770227360000,"stream":"btcusdt@bookTicker","event_type":"bookTicker","event_time_ms":1788567770196,"raw_json":"{\"stream\":\"btcusdt@bookTicker\",\"data\":{\"e\":\"bookTicker\",\"u\":11478510843368,\"s\":\"BTCUSDT\",\"ps\":\"BTCUSDT\",\"b\":\"79596.90\",\"B\":\"6.214\",\"a\":\"79597.00\",\"A\":\"6.836\",\"T\":1788567770196,\"E\":1788567770196,\"st\":1}}"}
{"receive_ns":1788567770227600000,"stream":"btcusdt@bookTicker","event_type":"bookTicker","event_time_ms":1788567770196,"raw_json":"{\"stream\":\"btcusdt@bookTicker\",\"data\":{\"e\":\"bookTicker\",\"u\":11478510843395,\"s\":\"BTCUSDT\",\"ps\":\"BTCUSDT\",\"b\":\"79596.90\",\"B\":\"6.214\",\"a\":\"79597.00\",\"A\":\"6.837\",\"T\":1788567770196,\"E\":1788567770196,\"st\":1}}"}
{"receive_ns":1788567770227796000,"stream":"btcusdt@bookTicker","event_type":"bookTicker","event_time_ms":1788567770196,"raw_json":"{\"stream\":\"btcusdt@bookTicker\",\"data\":{\"e\":\"bookTicker\",\"u\":11478510843398,\"s\":\"BTCUSDT\",\"ps\":\"BTCUSDT\",\"b\":\"79596.90\",\"B\":\"6.214\",\"a\":\"79597.00\",\"A\":\"6.836\",\"T\":1788567770196,\"E\":1788567770196,\"st\":1}}"}
{"receive_ns":1788567770233691000,"stream":"btcusdt@bookTicker","event_type":"bookTicker","event_time_ms":1788567770199,"raw_json":"{\"stream\":\"btcusdt@bookTicker\",\"data\":{\"e\":\"bookTicker\",\"u\":11478510843559,\"s\":\"BTCUSDT\",\"ps\":\"BTCUSDT\",\"b\":\"79596.90\",\"B\":\"6.214\",\"a\":\"79597.00\",\"A\":\"6.835\",\"T\":1788567770199,\"E\":1788567770199,\"st\":1}}"}
{"receive_ns":1788567770240389000,"stream":"btcusdt@bookTicker","event_type":"bookTicker","event_time_ms":1788567770199,"raw_json":"{\"stream\":\"btcusdt@bookTicker\",\"data\":{\"e\":\"bookTicker\",\"u\":11478510843565,\"s\":\"BTCUSDT\",\"ps\":\"BTCUSDT\",\"b\":\"79596.90\",\"B\":\"6.214\",\"a\":\"79597.00\",\"A\":\"6.832\",\"T\":1788567770199,\"E\":1788567770199,\"st\":1}}"}
{"receive_ns":1788567770245745000,"stream":"btcusdt@bookTicker","event_type":"bookTicker","event_time_ms":1788567770199,"raw_json":"{\"stream\":\"btcusdt@bookTicker\",\"data\":{\"e\":\"bookTicker\",\"u\":11478510843584,\"s\":\"BTCUSDT\",\"ps\":\"BTCUSDT\",\"b\":\"79596.90\",\"B\":\"6.214\",\"a\":\"79597.00\",\"A\":\"6.830\",\"T\":1788567770199,\"E\":1788567770199,\"st\":1}}"}
{"receive_ns":1788567770262930000,"stream":"btcusdt@bookTicker","event_type":"bookTicker","event_time_ms":1788567770199,"raw_json":"{\"stream\":\"btcusdt@bookTicker\",\"data\":{\"e\":\"bookTicker\",\"u\":11478510843587,\"s\":\"BTCUSDT\",\"ps\":\"BTCUSDT\",\"b\":\"79596.90\",\"B\":\"6.214\",\"a\":\"79597.00\",\"A\":\"6.826\",\"T\":1788567770199,\"E\":1788567770199,\"st\":1}}"}
{"receive_ns":1788567770283831000,"stream":"btcusdt@bookTicker","event_type":"bookTicker","event_time_ms":1788567770201,"raw_json":"{\"stream\":\"btcusdt@bookTicker\",\"data\":{\"e\":\"bookTicker\",\"u\":11478510843742,\"s\":\"BTCUSDT\",\"ps\":\"BTCUSDT\",\"b\":\"79596.90\",\"B\":\"6.215\",\"a\":\"79597.00\",\"A\":\"6.826\",\"T\":1788567770201,\"E\":1788567770201,\"st\":1}}"}
{"receive_ns":1788567770296554000,"stream":"btcusdt@depth@100ms","event_type":"depthUpdate","event_time_ms":1788567770247,"raw_json":"{\"stream\":\"btcusdt@depth@100ms\",\"data\":{\"e\":\"depthUpdate\",\"E\":1788567770247,\"T\":1788567770245,\"s\":\"BTCUSDT\",\"ps\":\"BTCUSDT\",\"U\":11478510840559,\"u\":11478510845479,\"pu\":11478510840287,\"b\":[[\"29196.90\",\"0.924\"],[\"29296.90\",\"1.176\"],[\"71637.20\",\"0.002\"],[\"75617.20\",\"0.004\"],[\"76413.00\",\"0.023\"],[\"78005.00\",\"0.222\"],[\"78800.90\",\"11.621\"],[\"79198.90\",\"3.845\"],[\"79495.00\",\"0.163\"],[\"79507.10\",\"0.002\"],[\"79535.00\",\"0.003\"],[\"79537.70\",\"0.001\"],[\"79553.60\",\"0.000\"],[\"79555.40\",\"1.133\"],[\"79562.20\",\"0.002\"],[\"79575.40\",\"0.019\"],[\"79576.90\",\"0.375\"],[\"79578.20\",\"0.002\"],[\"79585.00\",\"0.349\"],[\"79586.10\",\"0.005\"],[\"79586.20\",\"0.002\"],[\"79586.30\",\"0.062\"],[\"79586.70\",\"0.078\"],[\"79591.90\",\"0.077\"],[\"79593.00\",\"0.055\"],[\"79596.60\",\"0.002\"],[\"79596.70\",\"0.042\"],[\"79596.90\",\"6.215\"]],\"a\":[[\"79597.00\",\"6.826\"],[\"79597.70\",\"0.002\"],[\"79597.90\",\"0.248\"],[\"79598.00\",\"0.081\"],[\"79598.60\",\"0.001\"],[\"79598.90\",\"0.001\"],[\"79599.40\",\"0.000\"],[\"79599.50\",\"0.003\"],[\"79600.20\",\"0.027\"],[\"79600.30\",\"0.028\"],[\"79600.50\",\"0.107\"],[\"79601.20\",\"0.000\"],[\"79602.30\",\"0.003\"],[\"79604.00\",\"0.175\"],[\"79604.20\",\"0.007\"],[\"79605.60\",\"1.892\"],[\"79611.90\",\"0.001\"],[\"79617.10\",\"0.000\"],[\"79617.20\",\"0.000\"],[\"79627.80\",\"0.003\"],[\"79639.10\",\"0.000\"],[\"79643.70\",\"2.747\"],[\"79655.00\",\"0.000\"],[\"79663.60\",\"0.252\"],[\"79667.70\",\"3.140\"],[\"79668.80\",\"0.034\"],[\"79691.50\",\"10.087\"],[\"80393.00\",\"14.884\"]],\"st\":1}}"}
{"receive_ns":1788567770308415000,"stream":"btcusdt@bookTicker","event_type":"bookTicker","event_time_ms":1788567770256,"raw_json":"{\"stream\":\"btcusdt@bookTicker\",\"data\":{\"e\":\"bookTicker\",\"u\":11478510845770,\"s\":\"BTCUSDT\",\"ps\":\"BTCUSDT\",\"b\":\"79596.90\",\"B\":\"6.197\",\"a\":\"79597.00\",\"A\":\"6.826\",\"T\":1788567770256,\"E\":1788567770256,\"st\":1}}"}
{"receive_ns":1788567770320079000,"stream":"btcusdt@bookTicker","event_type":"bookTicker","event_time_ms":1788567770259,"raw_json":"{\"stream\":\"btcusdt@bookTicker\",\"data\":{\"e\":\"bookTicker\",\"u\":11478510845867,\"s\":\"BTCUSDT\",\"ps\":\"BTCUSDT\",\"b\":\"79596.90\",\"B\":\"6.210\",\"a\":\"79597.00\",\"A\":\"6.826\",\"T\":1788567770259,\"E\":1788567770259,\"st\":1}}"}
{"receive_ns":1788567770336561000,"stream":"btcusdt@bookTicker","event_type":"bookTicker","event_time_ms":1788567770281,"raw_json":"{\"stream\":\"btcusdt@bookTicker\",\"data\":{\"e\":\"bookTicker\",\"u\":11478510846759,\"s\":\"BTCUSDT\",\"ps\":\"BTCUSDT\",\"b\":\"79596.90\",\"B\":\"6.837\",\"a\":\"79597.00\",\"A\":\"6.826\",\"T\":1788567770281,\"E\":1788567770281,\"st\":1}}"}
{"receive_ns":1788567770353279000,"stream":"btcusdt@bookTicker","event_type":"bookTicker","event_time_ms":1788567770282,"raw_json":"{\"stream\":\"btcusdt@bookTicker\",\"data\":{\"e\":\"bookTicker\",\"u\":11478510846798,\"s\":\"BTCUSDT\",\"ps\":\"BTCUSDT\",\"b\":\"79596.90\",\"B\":\"6.838\",\"a\":\"79597.00\",\"A\":\"6.826\",\"T\":1788567770281,\"E\":1788567770282,\"st\":1}}"}
{"receive_ns":1788567770353518000,"stream":"btcusdt@bookTicker","event_type":"bookTicker","event_time_ms":1788567770282,"raw_json":"{\"stream\":\"btcusdt@bookTicker\",\"data\":{\"e\":\"bookTicker\",\"u\":11478510846829,\"s\":\"BTCUSDT\",\"ps\":\"BTCUSDT\",\"b\":\"79596.90\",\"B\":\"6.839\",\"a\":\"79597.00\",\"A\":\"6.826\",\"T\":1788567770282,\"E\":1788567770282,\"st\":1}}"}
{"receive_ns":1788567770360118000,"stream":"btcusdt@bookTicker","event_type":"bookTicker","event_time_ms":1788567770283,"raw_json":"{\"stream\":\"btcusdt@bookTicker\",\"data\":{\"e\":\"bookTicker\",\"u\":11478510846901,\"s\":\"BTCUSDT\",\"ps\":\"BTCUSDT\",\"b\":\"79596.90\",\"B\":\"6.838\",\"a\":\"79597.00\",\"A\":\"6.826\",\"T\":1788567770282,\"E\":1788567770283,\"st\":1}}"}
{"receive_ns":1788567770365512000,"stream":"btcusdt@bookTicker","event_type":"bookTicker","event_time_ms":1788567770292,"raw_json":"{\"stream\":\"btcusdt@bookTicker\",\"data\":{\"e\":\"bookTicker\",\"u\":11478510847375,\"s\":\"BTCUSDT\",\"ps\":\"BTCUSDT\",\"b\":\"79596.90\",\"B\":\"6.838\",\"a\":\"79597.00\",\"A\":\"6.823\",\"T\":1788567770292,\"E\":1788567770292,\"st\":1}}"}
{"receive_ns":1788567770382755000,"stream":"btcusdt@trade","event_type":"trade","event_time_ms":1788567770292,"raw_json":"{\"stream\":\"btcusdt@trade\",\"data\":{\"e\":\"trade\",\"E\":1788567770292,\"T\":1788567770292,\"s\":\"BTCUSDT\",\"t\":8054122811,\"p\":\"79597.00\",\"q\":\"0.003\",\"X\":\"MARKET\",\"m\":false,\"st\":1}}"}
{"receive_ns":1788567770388915000,"stream":"btcusdt@depth@100ms","event_type":"depthUpdate","event_time_ms":1788567770349,"raw_json":"{\"stream\":\"btcusdt@depth@100ms\",\"data\":{\"e\":\"depthUpdate\",\"E\":1788567770349,\"T\":1788567770345,\"s\":\"BTCUSDT\",\"ps\":\"BTCUSDT\",\"U\":11478510845528,\"u\":11478510850786,\"pu\":11478510845479,\"b\":[[\"1000.00\",\"24.604\"],[\"29196.90\",\"1.099\"],[\"29296.90\",\"1.001\"],[\"63678.00\",\"0.008\"],[\"71637.20\",\"0.002\"],[\"71673.00\",\"0.000\"],[\"76413.00\",\"0.025\"],[\"78466.60\",\"1.557\"],[\"78647.90\",\"17.648\"],[\"78800.90\",\"11.621\"],[\"79467.70\",\"0.007\"],[\"79467.80\",\"0.678\"],[\"79582.30\",\"0.119\"],[\"79593.00\",\"0.131\"],[\"79594.10\",\"0.002\"],[\"79596.90\",\"6.838\"]],\"a\":[[\"79597.00\",\"6.823\"],[\"79597.40\",\"0.007\"],[\"79597.70\",\"0.000\"],[\"79598.40\",\"0.004\"],[\"79599.70\",\"0.000\"],[\"79599.80\",\"0.001\"],[\"79599.90\",\"0.002\"],[\"79600.00\",\"0.049\"],[\"79600.10\",\"0.028\"],[\"79600.20\",\"0.001\"],[\"79609.40\",\"0.288\"],[\"79635.80\",\"0.001\"],[\"79637.90\",\"0.001\"],[\"79728.00\",\"1.007\"],[\"79731.40\",\"0.000\"],[\"79871.80\",\"0.282\"],[\"80393.00\",\"14.884\"],[\"80552.20\",\"26.999\"],[\"80759.20\",\"0.374\"],[\"81188.90\",\"0.040\"]],\"st\":1}}"}
{"receive_ns":1788567770401663000,"stream":"btcusdt@bookTicker","event_type":"bookTicker","event_time_ms":1788567770360,"raw_json":"{\"stream\":\"btcusdt@bookTicker\",\"data\":{\"e\":\"bookTicker\",\"u\":11478510851553,\"s\":\"BTCUSDT\",\"ps\":\"BTCUSDT\",\"b\":\"79596.90\",\"B\":\"6.838\",\"a\":\"79597.00\",\"A\":\"6.844\",\"T\":1788567770360,\"E\":1788567770360,\"st\":1}}"}
{"receive_ns":1788567770410003000,"stream":"btcusdt@bookTicker","event_type":"bookTicker","event_time_ms":1788567770361,"raw_json":"{\"stream\":\"btcusdt@bookTicker\",\"data\":{\"e\":\"bookTicker\",\"u\":11478510851623,\"s\":\"BTCUSDT\",\"ps\":\"BTCUSDT\",\"b\":\"79596.90\",\"B\":\"6.839\",\"a\":\"79597.00\",\"A\":\"6.844\",\"T\":1788567770361,\"E\":1788567770361,\"st\":1}}"}
{"receive_ns":1788567770415582000,"stream":"btcusdt@bookTicker","event_type":"bookTicker","event_time_ms":1788567770361,"raw_json":"{\"stream\":\"btcusdt@bookTicker\",\"data\":{\"e\":\"bookTicker\",\"u\":11478510851645,\"s\":\"BTCUSDT\",\"ps\":\"BTCUSDT\",\"b\":\"79596.90\",\"B\":\"6.831\",\"a\":\"79597.00\",\"A\":\"6.844\",\"T\":1788567770361,\"E\":1788567770361,\"st\":1}}"}
{"receive_ns":1788567770427652000,"stream":"btcusdt@bookTicker","event_type":"bookTicker","event_time_ms":1788567770364,"raw_json":"{\"stream\":\"btcusdt@bookTicker\",\"data\":{\"e\":\"bookTicker\",\"u\":11478510851799,\"s\":\"BTCUSDT\",\"ps\":\"BTCUSDT\",\"b\":\"79596.90\",\"B\":\"6.837\",\"a\":\"79597.00\",\"A\":\"6.844\",\"T\":1788567770363,\"E\":1788567770364,\"st\":1}}"}
{"receive_ns":1788567770439634000,"stream":"btcusdt@depth@100ms","event_type":"depthUpdate","event_time_ms":1788567770451,"raw_json":"{\"stream\":\"btcusdt@depth@100ms\",\"data\":{\"e\":\"depthUpdate\",\"E\":1788567770451,\"T\":1788567770450,\"s\":\"BTCUSDT\",\"ps\":\"BTCUSDT\",\"U\":11478510851095,\"u\":11478510856350,\"pu\":11478510850786,\"b\":[[\"1000.00\",\"24.604\"],[\"29196.90\",\"1.281\"],[\"29296.90\",\"0.819\"],[\"71637.20\",\"0.002\"],[\"76413.00\",\"0.023\"],[\"78548.80\",\"121.755\"],[\"78800.90\",\"11.621\"],[\"79198.90\",\"3.844\"],[\"79495.00\",\"0.156\"],[\"79507.70\",\"7.309\"],[\"79535.50\",\"3.500\"],[\"79555.40\",\"1.688\"],[\"79573.20\",\"0.538\"],[\"79579.40\",\"0.000\"],[\"79579.80\",\"0.047\"],[\"79586.10\",\"0.067\"],[\"79586.30\",\"0.000\"],[\"79591.80\",\"0.000\"],[\"79594.10\",\"0.078\"],[\"79596.90\",\"6.837\"]],\"a\":[[\"79597.00\",\"6.844\"],[\"79600.60\",\"0.026\"],[\"79600.70\",\"0.030\"],[\"79600.80\",\"0.035\"],[\"79600.90\",\"0.028\"],[\"79601.00\",\"0.343\"],[\"79613.10\",\"0.194\"],[\"79643.90\",\"0.579\"],[\"79663.80\",\"5.056\"],[\"79691.60\",\"6.000\"],[\"79995.00\",\"4.447\"],[\"80393.00\",\"14.884\"],[\"80592.00\",\"7.663\"],[\"80660.70\",\"120.454\"],[\"80675.80\",\"0.000\"]],\"st\":1}}"}
{"receive_ns":1788567770543676000,"stream":"btcusdt@depth@100ms","event_type":"depthUpdate","event_time_ms":1788567770553,"raw_json":"{\"stream\":\"btcusdt@depth@100ms\",\"data\":{\"e\":\"depthUpdate\",\"E\":1788567770553,\"T\":1788567770552,\"s\":\"BTCUSDT\",\"ps\":\"BTCUSDT\",\"U\":11478510856475,\"u\":11478510861975,\"pu\":11478510856350,\"b\":[[\"29196.90\",\"1.456\"],[\"29296.90\",\"0.644\"],[\"63678.00\",\"0.106\"],[\"71637.20\",\"0.002\"],[\"78482.50\",\"24.937\"],[\"78641.70\",\"29.744\"],[\"78800.90\",\"11.621\"],[\"79198.90\",\"3.855\"],[\"79467.80\",\"0.001\"],[\"79467.90\",\"10.001\"],[\"79468.00\",\"2.174\"]],\"a\":[[\"79598.50\",\"0.252\"],[\"79600.00\",\"0.075\"],[\"79728.00\",\"2.370\"],[\"79730.50\",\"10.000\"],[\"80393.00\",\"14.884\"],[\"80671.60\",\"3.587\"]],\"st\":1}}"}
{"receive_ns":1788567770571449000,"stream":"btcusdt@bookTicker","event_type":"bookTicker","event_time_ms":1788567770580,"raw_json":"{\"stream\":\"btcusdt@bookTicker\",\"data\":{\"e\":\"bookTicker\",\"u\":11478510863205,\"s\":\"BTCUSDT\",\"ps\":\"BTCUSDT\",\"b\":\"79596.90\",\"B\":\"6.837\",\"a\":\"79597.00\",\"A\":\"6.842\",\"T\":1788567770580,\"E\":1788567770580,\"st\":1}}"}
{"receive_ns":1788567770571954000,"stream":"btcusdt@trade","event_type":"trade","event_time_ms":1788567770580,"raw_json":"{\"stream\":\"btcusdt@trade\",\"data\":{\"e\":\"trade\",\"E\":1788567770580,\"T\":1788567770580,\"s\":\"BTCUSDT\",\"t\":8054122812,\"p\":\"79597.00\",\"q\":\"0.002\",\"X\":\"MARKET\",\"m\":false,\"st\":1}}"}
{"receive_ns":1788567770636255000,"stream":"btcusdt@bookTicker","event_type":"bookTicker","event_time_ms":1788567770646,"raw_json":"{\"stream\":\"btcusdt@bookTicker\",\"data\":{\"e\":\"bookTicker\",\"u\":11478510866490,\"s\":\"BTCUSDT\",\"ps\":\"BTCUSDT\",\"b\":\"79596.90\",\"B\":\"6.837\",\"a\":\"79597.00\",\"A\":\"6.830\",\"T\":1788567770645,\"E\":1788567770646,\"st\":1}}"}
{"receive_ns":1788567770647028000,"stream":"btcusdt@bookTicker","event_type":"bookTicker","event_time_ms":1788567770648,"raw_json":"{\"stream\":\"btcusdt@bookTicker\",\"data\":{\"e\":\"bookTicker\",\"u\":11478510866589,\"s\":\"BTCUSDT\",\"ps\":\"BTCUSDT\",\"b\":\"79596.90\",\"B\":\"6.837\",\"a\":\"79597.00\",\"A\":\"6.839\",\"T\":1788567770648,\"E\":1788567770648,\"st\":1}}"}
{"receive_ns":1788567770652830000,"stream":"btcusdt@depth@100ms","event_type":"depthUpdate","event_time_ms":1788567770655,"raw_json":"{\"stream\":\"btcusdt@depth@100ms\",\"data\":{\"e\":\"depthUpdate\",\"E\":1788567770655,\"T\":1788567770653,\"s\":\"BTCUSDT\",\"ps\":\"BTCUSDT\",\"U\":11478510861979,\"u\":11478510866753,\"pu\":11478510861975,\"b\":[[\"1000.00\",\"24.604\"],[\"29196.90\",\"1.638\"],[\"29296.90\",\"0.462\"],[\"63678.00\",\"0.008\"],[\"71637.20\",\"0.002\"],[\"76413.00\",\"0.025\"],[\"78641.70\",\"31.013\"],[\"78800.90\",\"11.621\"],[\"79565.50\",\"0.000\"],[\"79567.00\",\"0.300\"],[\"79568.20\",\"0.002\"],[\"79568.90\",\"0.455\"],[\"79570.00\",\"0.005\"],[\"79570.10\",\"0.001\"],[\"79571.10\",\"0.000\"],[\"79576.30\",\"0.510\"],[\"79576.90\",\"0.002\"],[\"79584.50\",\"0.081\"],[\"79591.80\",\"0.004\"],[\"79591.90\",\"0.259\"],[\"79592.10\",\"0.000\"],[\"79594.10\",\"0.002\"],[\"79594.70\",\"0.000\"],[\"79596.70\",\"0.034\"]],\"a\":[[\"79597.00\",\"6.839\"],[\"79610.60\",\"0.002\"],[\"79610.70\",\"0.545\"],[\"79612.80\",\"0.003\"],[\"79616.60\",\"0.051\"],[\"79617.50\",\"0.372\"],[\"79619.90\",\"0.000\"],[\"79620.60\",\"0.454\"],[\"79928.70\",\"0.317\"],[\"79930.30\",\"0.003\"],[\"79995.00\",\"4.448\"],[\"80393.00\",\"14.884\"],[\"80472.60\",\"6.206\"],[\"80717.50\",\"13.726\"]],\"st\":1}}"}
{"receive_ns":1788567770658670000,"stream":"btcusdt@bookTicker","event_type":"bookTicker","event_time_ms":1788567770668,"raw_json":"{\"stream\":\"btcusdt@bookTicker\",\"data\":{\"e\":\"bookTicker\",\"u\":11478510867214,\"s\":\"BTCUSDT\",\"ps\":\"BTCUSDT\",\"b\":\"79596.90\",\"B\":\"6.844\",\"a\":\"79597.00\",\"A\":\"6.839\",\"T\":1788567770667,\"E\":1788567770668,\"st\":1}}"}
{"receive_ns":1788567770733978000,"stream":"btcusdt@trade","event_type":"trade","event_time_ms":1788567770744,"raw_json":"{\"stream\":\"btcusdt@trade\",\"data\":{\"e\":\"trade\",\"E\":1788567770744,\"T\":1788567770744,\"s\":\"BTCUSDT\",\"t\":8054122813,\"p\":\"79597.00\",\"q\":\"0.045\",\"X\":\"MARKET\",\"m\":false,\"st\":1}}"}
{"receive_ns":1788567770744834000,"stream":"btcusdt@trade","event_type":"trade","event_time_ms":1788567770744,"raw_json":"{\"stream\":\"btcusdt@trade\",\"data\":{\"e\":\"trade\",\"E\":1788567770744,\"T\":1788567770744,\"s\":\"BTCUSDT\",\"t\":8054122814,\"p\":\"79597.00\",\"q\":\"0.001\",\"X\":\"MARKET\",\"m\":false,\"st\":1}}"}
{"receive_ns":1788567770755423000,"stream":"btcusdt@bookTicker","event_type":"bookTicker","event_time_ms":1788567770744,"raw_json":"{\"stream\":\"btcusdt@bookTicker\",\"data\":{\"e\":\"bookTicker\",\"u\":11478510870668,\"s\":\"BTCUSDT\",\"ps\":\"BTCUSDT\",\"b\":\"79596.90\",\"B\":\"6.844\",\"a\":\"79597.00\",\"A\":\"6.276\",\"T\":1788567770744,\"E\":1788567770744,\"st\":1}}"}
{"receive_ns":1788567770762182000,"stream":"btcusdt@trade","event_type":"trade","event_time_ms":1788567770744,"raw_json":"{\"stream\":\"btcusdt@trade\",\"data\":{\"e\":\"trade\",\"E\":1788567770744,\"T\":1788567770744,\"s\":\"BTCUSDT\",\"t\":8054122815,\"p\":\"79597.00\",\"q\":\"0.002\",\"X\":\"MARKET\",\"m\":false,\"st\":1}}"}
{"receive_ns":1788567770762412000,"stream":"btcusdt@trade","event_type":"trade","event_time_ms":1788567770744,"raw_json":"{\"stream\":\"btcusdt@trade\",\"data\":{\"e\":\"trade\",\"E\":1788567770744,\"T\":1788567770744,\"s\":\"BTCUSDT\",\"t\":8054122816,\"p\":\"79597.00\",\"q\":\"0.030\",\"X\":\"MARKET\",\"m\":false,\"st\":1}}"}
{"receive_ns":1788567770762585000,"stream":"btcusdt@trade","event_type":"trade","event_time_ms":1788567770744,"raw_json":"{\"stream\":\"btcusdt@trade\",\"data\":{\"e\":\"trade\",\"E\":1788567770744,\"T\":1788567770744,\"s\":\"BTCUSDT\",\"t\":8054122817,\"p\":\"79597.00\",\"q\":\"0.030\",\"X\":\"MARKET\",\"m\":false,\"st\":1}}"}
{"receive_ns":1788567770762767000,"stream":"btcusdt@trade","event_type":"trade","event_time_ms":1788567770744,"raw_json":"{\"stream\":\"btcusdt@trade\",\"data\":{\"e\":\"trade\",\"E\":1788567770744,\"T\":1788567770744,\"s\":\"BTCUSDT\",\"t\":8054122818,\"p\":\"79597.00\",\"q\":\"0.455\",\"X\":\"MARKET\",\"m\":false,\"st\":1}}"}
{"receive_ns":1788567770775619000,"stream":"btcusdt@depth@100ms","event_type":"depthUpdate","event_time_ms":1788567770757,"raw_json":"{\"stream\":\"btcusdt@depth@100ms\",\"data\":{\"e\":\"depthUpdate\",\"E\":1788567770757,\"T\":1788567770754,\"s\":\"BTCUSDT\",\"ps\":\"BTCUSDT\",\"U\":11478510866803,\"u\":11478510871392,\"pu\":11478510866753,\"b\":[[\"1000.00\",\"24.604\"],[\"29096.90\",\"0.021\"],[\"29196.90\",\"1.771\"],[\"29296.90\",\"0.308\"],[\"71637.20\",\"0.002\"],[\"76413.00\",\"0.023\"],[\"78403.00\",\"3.355\"],[\"78800.90\",\"11.621\"],[\"79562.50\",\"1.893\"],[\"79562.60\",\"0.003\"],[\"79568.90\",\"0.455\"],[\"79570.90\",\"0.002\"],[\"79583.40\",\"0.241\"],[\"79593.40\",\"0.163\"],[\"79594.10\",\"0.254\"],[\"79594.40\",\"0.076\"],[\"79595.90\",\"0.078\"],[\"79596.90\",\"6.844\"]],\"a\":[[\"79597.00\",\"6.276\"],[\"79597.40\",\"0.005\"],[\"79597.90\",\"0.002\"],[\"79598.50\",\"0.000\"],[\"79599.80\",\"0.001\"],[\"79600.00\",\"0.049\"],[\"79600.10\",\"0.002\"],[\"79600.30\",\"0.002\"],[\"79600.50\",\"0.078\"],[\"79600.60\",\"0.000\"],[\"79600.70\",\"0.004\"],[\"79600.80\",\"0.009\"],[\"79600.90\",\"0.002\"],[\"79601.00\",\"0.317\"],[\"79601.50\",\"0.029\"],[\"79601.60\",\"0.107\"],[\"79601.80\",\"0.027\"],[\"79601.90\",\"0.028\"],[\"79602.10\",\"0.026\"],[\"79602.20\",\"0.027\"],[\"79602.30\",\"0.029\"],[\"79602.40\",\"1.011\"],[\"79602.50\",\"0.005\"],[\"79602.60\",\"0.026\"],[\"79602.70\",\"0.282\"],[\"79602.80\",\"0.076\"],[\"79602.90\",\"0.005\"],[\"79610.70\",\"0.106\"],[\"79610.90\",\"0.442\"],[\"79612.80\",\"0.003\"],[\"79616.10\",\"1.009\"],[\"79617.50\",\"0.000\"],[\"79625.70\",\"0.000\"],[\"79995.00\",\"4.573\"],[\"80393.00\",\"14.884\"],[\"81188.90\",\"0.037\"],[\"81825.80\",\"1.463\"]],\"st\":1}}"}
{"receive_ns":1788567770845507000,"stream":"btcusdt@depth@100ms","event_type":"depthUpdate","event_time_ms":1788567770859,"raw_json":"{\"stream\":\"btcusdt@depth@100ms\",\"data\":{\"e\":\"depthUpdate\",\"E\":1788567770859,\"T\":1788567770858,\"s\":\"BTCUSDT\",\"ps\":\"BTCUSDT\",\"U\":11478510871488,\"u\":11478510875703,\"pu\":11478510871392,\"b\":[[\"29096.90\",\"0.084\"],[\"29196.90\",\"1.827\"],[\"29296.90\",\"0.189\"],[\"63678.00\",\"0.008\"],[\"71637.20\",\"0.002\"],[\"76413.00\",\"0.025\"],[\"78800.90\",\"11.621\"],[\"79198.90\",\"3.855\"],[\"79576.80\",\"0.330\"],[\"79585.00\",\"0.097\"],[\"79586.10\",\"0.005\"],[\"79593.40\",\"0.161\"],[\"79595.90\",\"0.002\"]],\"a\":[[\"79597.50\",\"0.066\"],[\"79600.80\",\"0.008\"],[\"79601.10\",\"0.035\"],[\"79601.30\",\"0.027\"],[\"79602.60\",\"0.000\"],[\"79602.70\",\"0.256\"],[\"79625.70\",\"0.003\"],[\"80552.20\",\"26.379\"],[\"80592.10\",\"6.932\"],[\"80711.40\",\"26.967\"],[\"80819.10\",\"1.730\"]],\"st\":1}}"}
{"receive_ns":1788567770949563000,"stream":"btcusdt@depth@100ms","event_type":"depthUpdate","event_time_ms":1788567770961,"raw_json":"{\"stream\":\"btcusdt@depth@100ms\",\"data\":{\"e\":\"depthUpdate\",\"E\":1788567770961,\"T\":1788567770957,\"s\":\"BTCUSDT\",\"ps\":\"BTCUSDT\",\"U\":11478510875771,\"u\":11478510881126,\"pu\":11478510875703,\"b\":[[\"1000.00\",\"24.604\"],[\"29096.90\",\"0.140\"],[\"29196.90\",\"1.890\"],[\"29296.90\",\"0.070\"],[\"63677.50\",\"0.000\"],[\"63678.00\",\"0.008\"],[\"71637.20\",\"0.002\"],[\"75617.10\",\"0.011\"],[\"78243.60\",\"1.111\"],[\"78800.90\",\"11.621\"],[\"79525.20\",\"0.000\"],[\"79541.10\",\"1.098\"],[\"79564.30\",\"0.000\"],[\"79564.50\",\"0.142\"],[\"79585.00\",\"0.101\"],[\"79586.10\",\"0.001\"]],\"a\":[[\"79600.60\",\"0.026\"],[\"79601.00\",\"0.343\"],[\"79602.30\",\"0.003\"],[\"79602.40\",\"0.985\"],[\"79668.70\",\"2.054\"],[\"80393.00\",\"14.884\"],[\"80552.20\",\"27.619\"]],\"st\":1}}"}
{"receive_ns":1788567771052196000,"stream":"btcusdt@depth@100ms","event_type":"depthUpdate","event_time_ms":1788567771063,"raw_json":"{\"stream\":\"btcusdt@depth@100ms\",\"data\":{\"e\":\"depthUpdate\",\"E\":1788567771063,\"T\":1788567771061,\"s\":\"BTCUSDT\",\"ps\":\"BTCUSDT\",\"U\":11478510881290,\"u\":11478510887450,\"pu\":11478510881126,\"b\":[[\"1000.00\",\"24.604\"],[\"29096.90\",\"0.252\"],[\"29196.90\",\"1.848\"],[\"29296.90\",\"0.000\"],[\"63678.00\",\"0.008\"],[\"71637.20\",\"0.002\"],[\"75617.10\",\"0.009\"],[\"75617.20\",\"0.006\"],[\"76413.00\",\"0.023\"],[\"78681.50\",\"4.928\"],[\"78800.90\",\"11.621\"],[\"79582.60\",\"0.070\"],[\"79585.00\",\"0.097\"],[\"79586.10\",\"0.005\"],[\"79596.70\",\"0.042\"]],\"a\":[[\"79995.10\",\"0.000\"],[\"80393.00\",\"14.884\"],[\"80552.20\",\"28.239\"],[\"80942.20\",\"0.986\"],[\"81188.90\",\"0.040\"]],\"st\":1}}"}
{"receive_ns":1788567771059967000,"stream":"btcusdt@bookTicker","event_type":"bookTicker","event_time_ms":1788567771073,"raw_json":"{\"stream\":\"btcusdt@bookTicker\",\"data\":{\"e\":\"bookTicker\",\"u\":11478510887986,\"s\":\"BTCUSDT\",\"ps\":\"BTCUSDT\",\"b\":\"79596.90\",\"B\":\"6.829\",\"a\":\"79597.00\",\"A\":\"6.276\",\"T\":1788567771073,\"E\":1788567771073,\"st\":1}}"}
{"receive_ns":1788567771071448000,"stream":"btcusdt@bookTicker","event_type":"bookTicker","event_time_ms":1788567771077,"raw_json":"{\"stream\":\"btcusdt@bookTicker\",\"data\":{\"e\":\"bookTicker\",\"u\":11478510888158,\"s\":\"BTCUSDT\",\"ps\":\"BTCUSDT\",\"b\":\"79596.90\",\"B\":\"6.848\",\"a\":\"79597.00\",\"A\":\"6.276\",\"T\":1788567771076,\"E\":1788567771077,\"st\":1}}"}
{"receive_ns":1788567771124724000,"stream":"btcusdt@bookTicker","event_type":"bookTicker","event_time_ms":1788567771133,"raw_json":"{\"stream\":\"btcusdt@bookTicker\",\"data\":{\"e\":\"bookTicker\",\"u\":11478510890936,\"s\":\"BTCUSDT\",\"ps\":\"BTCUSDT\",\"b\":\"79596.90\",\"B\":\"6.848\",\"a\":\"79597.00\",\"A\":\"6.279\",\"T\":1788567771133,\"E\":1788567771133,\"st\":1}}"}
{"receive_ns":1788567771148753000,"stream":"btcusdt@bookTicker","event_type":"bookTicker","event_time_ms":1788567771134,"raw_json":"{\"stream\":\"btcusdt@bookTicker\",\"data\":{\"e\":\"bookTicker\",\"u\":11478510891010,\"s\":\"BTCUSDT\",\"ps\":\"BTCUSDT\",\"b\":\"79596.90\",\"B\":\"6.848\",\"a\":\"79597.00\",\"A\":\"6.281\",\"T\":1788567771134,\"E\":1788567771134,\"st\":1}}"}
{"receive_ns":1788567771167145000,"stream":"btcusdt@depth@100ms","event_type":"depthUpdate","event_time_ms":1788567771165,"raw_json":"{\"stream\":\"btcusdt@depth@100ms\",\"data\":{\"e\":\"depthUpdate\",\"E\":1788567771165,\"T\":1788567771163,\"s\":\"BTCUSDT\",\"ps\":\"BTCUSDT\",\"U\":11478510887545,\"u\":11478510893000,\"pu\":11478510887450,\"b\":[[\"29096.90\",\"0.427\"],[\"29196.90\",\"1.673\"],[\"63678.00\",\"0.008\"],[\"71637.20\",\"0.002\"],[\"76413.00\",\"0.025\"],[\"78573.40\",\"0.004\"],[\"78581.30\",\"0.000\"],[\"78590.70\",\"0.005\"],[\"78601.10\",\"0.000\"],[\"78602.00\",\"12.607\"],[\"78608.00\",\"0.851\"],[\"78618.40\",\"1.889\"],[\"78800.90\",\"11.621\"],[\"79198.90\",\"3.855\"],[\"79525.20\",\"0.002\"],[\"79576.80\",\"0.016\"],[\"79585.00\",\"0.097\"],[\"79586.10\",\"0.319\"],[\"79594.10\",\"0.002\"],[\"79594.40\",\"0.000\"],[\"79594.60\",\"0.040\"],[\"79596.90\",\"6.848\"]],\"a\":[[\"79597.00\",\"6.281\"],[\"79597.10\",\"0.727\"],[\"79597.20\",\"0.250\"],[\"79597.50\",\"0.014\"],[\"79599.80\",\"0.027\"],[\"79599.90\",\"0.028\"],[\"79600.10\",\"0.028\"],[\"79600.20\",\"0.027\"],[\"79600.40\",\"0.034\"],[\"79600.60\",\"0.000\"],[\"79601.80\",\"0.001\"],[\"79601.90\",\"0.002\"],[\"79602.10\",\"0.000\"],[\"79602.20\",\"0.001\"],[\"79657.50\",\"0.031\"],[\"79692.00\",\"1.358\"],[\"79692.60\",\"0.004\"],[\"79995.00\",\"4.448\"],[\"80393.00\",\"14.884\"]],\"st\":1}}"}
{"receive_ns":1788567771194374000,"stream":"btcusdt@bookTicker","event_type":"bookTicker","event_time_ms":1788567771202,"raw_json":"{\"stream\":\"btcusdt@bookTicker\",\"data\":{\"e\":\"bookTicker\",\"u\":11478510895213,\"s\":\"BTCUSDT\",\"ps\":\"BTCUSDT\",\"b\":\"79596.90\",\"B\":\"6.848\",\"a\":\"79597.00\",\"A\":\"6.263\",\"T\":1788567771202,\"E\":1788567771202,\"st\":1}}"}
{"receive_ns":1788567771211767000,"stream":"btcusdt@trade","event_type":"trade","event_time_ms":1788567771202,"raw_json":"{\"stream\":\"btcusdt@trade\",\"data\":{\"e\":\"trade\",\"E\":1788567771202,\"T\":1788567771202,\"s\":\"BTCUSDT\",\"t\":8054122819,\"p\":\"79597.00\",\"q\":\"0.018\",\"X\":\"MARKET\",\"m\":false,\"st\":1}}"}
{"receive_ns":1788567771259034000,"stream":"btcusdt@depth@100ms","event_type":"depthUpdate","event_time_ms":1788567771267,"raw_json":"{\"stream\":\"btcusdt@depth@100ms\",\"data\":{\"e\":\"depthUpdate\",\"E\":1788567771267,\"T\":1788567771265,\"s\":\"BTCUSDT\",\"ps\":\"BTCUSDT\",\"U\":11478510893179,\"u\":11478510898795,\"pu\":11478510893000,\"b\":[[\"1000.00\",\"24.604\"],[\"29096.90\",\"0.609\"],[\"29196.90\",\"1.491\"],[\"71637.20\",\"0.002\"],[\"76413.00\",\"0.023\"],[\"78248.60\",\"0.000\"],[\"78562.10\",\"7.500\"],[\"78601.90\",\"6.751\"],[\"78800.90\",\"11.621\"],[\"79473.10\",\"0.016\"],[\"79473.20\",\"0.431\"],[\"79538.20\",\"0.830\"],[\"79554.10\",\"0.738\"],[\"79585.00\",\"0.349\"],[\"79586.10\",\"0.005\"],[\"79586.20\",\"0.064\"],[\"79593.00\",\"0.131\"]],\"a\":[[\"79597.00\",\"6.263\"],[\"79598.70\",\"0.030\"],[\"79598.90\",\"0.027\"],[\"79599.20\",\"0.000\"],[\"79599.60\",\"0.026\"],[\"79601.30\",\"0.001\"],[\"79601.50\",\"0.003\"],[\"79601.60\",\"0.081\"],[\"79610.70\",\"0.545\"],[\"79610.90\",\"0.003\"],[\"79612.30\",\"0.694\"],[\"79612.80\",\"0.003\"],[\"79616.10\",\"0.637\"],[\"79617.50\",\"0.372\"],[\"79628.10\",\"0.326\"],[\"79628.20\",\"0.841\"],[\"79628.50\",\"0.000\"],[\"79628.80\",\"0.006\"],[\"79692.00\",\"1.357\"],[\"79804.90\",\"1.030\"],[\"79831.30\",\"0.359\"],[\"79831.40\",\"0.024\"],[\"79880.70\",\"7.585\"],[\"80002.50\",\"12.694\"],[\"80393.00\",\"14.884\"],[\"80711.40\",\"28.823\"],[\"80751.20\",\"10.728\"],[\"80830.80\",\"5.191\"]],\"st\":1}}"}
{"receive_ns":1788567771311065000,"stream":"btcusdt@bookTicker","event_type":"bookTicker","event_time_ms":1788567771316,"raw_json":"{\"stream\":\"btcusdt@bookTicker\",\"data\":{\"e\":\"bookTicker\",\"u\":11478510901358,\"s\":\"BTCUSDT\",\"ps\":\"BTCUSDT\",\"b\":\"79596.90\",\"B\":\"6.848\",\"a\":\"79597.00\",\"A\":\"6.260\",\"T\":1788567771316,\"E\":1788567771316,\"st\":1}}"}
{"receive_ns":1788567771329374000,"stream":"btcusdt@trade","event_type":"trade","event_time_ms":1788567771316,"raw_json":"{\"stream\":\"btcusdt@trade\",\"data\":{\"e\":\"trade\",\"E\":1788567771316,\"T\":1788567771316,\"s\":\"BTCUSDT\",\"t\":8054122820,\"p\":\"79597.00\",\"q\":\"0.003\",\"X\":\"MARKET\",\"m\":false,\"st\":1}}"}
{"receive_ns":1788567771353557000,"stream":"btcusdt@depth@100ms","event_type":"depthUpdate","event_time_ms":1788567771369,"raw_json":"{\"stream\":\"btcusdt@depth@100ms\",\"data\":{\"e\":\"depthUpdate\",\"E\":1788567771369,\"T\":1788567771366,\"s\":\"BTCUSDT\",\"ps\":\"BTCUSDT\",\"U\":11478510898871,\"u\":11478510904249,\"pu\":11478510898795,\"b\":[[\"1000.00\",\"24.604\"],[\"29096.90\",\"0.784\"],[\"29196.90\",\"1.316\"],[\"71637.20\",\"0.002\"],[\"71673.00\",\"0.000\"],[\"76413.00\",\"0.025\"],[\"78800.90\",\"11.621\"],[\"78960.10\",\"8.590\"],[\"79576.80\",\"0.016\"],[\"79585.00\",\"0.035\"],[\"79586.10\",\"0.319\"],[\"79594.30\",\"0.064\"]],\"a\":[[\"79597.00\",\"6.260\"],[\"79597.20\",\"0.004\"],[\"79598.70\",\"0.004\"],[\"79598.90\",\"0.001\"],[\"79692.00\",\"1.358\"],[\"80393.00\",\"14.884\"]],\"st\":1}}"}
{"receive_ns":1788567771460727000,"stream":"btcusdt@depth@100ms","event_type":"depthUpdate","event_time_ms":1788567771471,"raw_json":"{\"stream\":\"btcusdt@depth@100ms\",\"data\":{\"e\":\"depthUpdate\",\"E\":1788567771471,\"T\":1788567771469,\"s\":\"BTCUSDT\",\"ps\":\"BTCUSDT\",\"U\":11478510904433,\"u\":11478510910218,\"pu\":11478510904249,\"b\":[[\"29096.90\",\"0.966\"],[\"29196.90\",\"1.134\"],[\"71637.20\",\"0.002\"],[\"78721.70\",\"0.133\"],[\"78800.90\",\"11.621\"],[\"78960.10\",\"8.588\"],[\"79198.90\",\"3.846\"],[\"79568.90\",\"0.003\"],[\"79570.10\",\"0.453\"],[\"79573.20\",\"0.538\"],[\"79576.80\",\"0.016\"],[\"79585.00\",\"0.035\"],[\"79586.10\",\"0.319\"],[\"79586.20\",\"0.064\"]],\"a\":[[\"79598.60\",\"0.253\"],[\"79599.60\",\"0.000\"],[\"79599.80\",\"0.001\"],[\"79599.90\",\"0.002\"],[\"79613.10\",\"0.194\"],[\"80393.00\",\"14.884\"],[\"80691.70\",\"0.000\"]],\"st\":1}}"}
{"receive_ns":1788567771562297000,"stream":"btcusdt@depth@100ms","event_type":"depthUpdate","event_time_ms":1788567771573,"raw_json":"{\"stream\":\"btcusdt@depth@100ms\",\"data\":{\"e\":\"depthUpdate\",\"E\":1788567771573,\"T\":1788567771571,\"s\":\"BTCUSDT\",\"ps\":\"BTCUSDT\",\"U\":11478510910301,\"u\":11478510914049,\"pu\":11478510910218,\"b\":[[\"1000.00\",\"24.604\"],[\"29096.90\",\"1.141\"],[\"29196.90\",\"0.959\"],[\"71637.20\",\"0.002\"],[\"76413.00\",\"0.023\"],[\"78005.00\",\"0.219\"],[\"78363.10\",\"3.568\"],[\"78442.70\",\"8.249\"],[\"78601.90\",\"7.036\"],[\"78800.90\",\"11.621\"],[\"79198.90\",\"3.845\"],[\"79585.00\",\"0.349\"],[\"79586.10\",\"0.005\"]],\"a\":[[\"79598.30\",\"0.028\"],[\"79599.10\",\"0.104\"],[\"79599.40\",\"0.026\"],[\"79619.40\",\"1.251\"],[\"79620.60\",\"0.002\"],[\"79643.10\",\"0.126\"],[\"79645.50\",\"0.000\"],[\"79995.00\",\"4.447\"],[\"80393.00\",\"14.884\"],[\"80711.50\",\"11.402\"],[\"80727.30\",\"1.332\"]],\"st\":1}}"}
{"receive_ns":1788567771664501000,"stream":"btcusdt@depth@100ms","event_type":"depthUpdate","event_time_ms":1788567771675,"raw_json":"{\"stream\":\"btcusdt@depth@100ms\",\"data\":{\"e\":\"depthUpdate\",\"E\":1788567771675,\"T\":1788567771673,\"s\":\"BTCUSDT\",\"ps\":\"BTCUSDT\",\"U\":11478510914221,\"u\":11478510920091,\"pu\":11478510914049,\"b\":[[\"1000.00\",\"24.604\"],[\"29096.90\",\"1.323\"],[\"29196.90\",\"0.777\"],[\"71637.20\",\"0.002\"],[\"76413.00\",\"0.025\"],[\"78391.60\",\"4.259\"],[\"78729.30\",\"4.495\"],[\"78800.90\",\"11.621\"]],\"a\":[[\"79642.90\",\"0.003\"],[\"79643.10\",\"0.001\"],[\"79643.20\",\"0.366\"],[\"80393.00\",\"14.884\"],[\"81188.90\",\"0.043\"]],\"st\":1}}"}
{"receive_ns":1788567771758017000,"stream":"btcusdt@bookTicker","event_type":"bookTicker","event_time_ms":1788567771767,"raw_json":"{\"stream\":\"btcusdt@bookTicker\",\"data\":{\"e\":\"bookTicker\",\"u\":11478510924947,\"s\":\"BTCUSDT\",\"ps\":\"BTCUSDT\",\"b\":\"79596.90\",\"B\":\"6.848\",\"a\":\"79597.00\",\"A\":\"7.724\",\"T\":1788567771767,\"E\":1788567771767,\"st\":1}}"}
{"receive_ns":1788567771774941000,"stream":"btcusdt@bookTicker","event_type":"bookTicker","event_time_ms":1788567771771,"raw_json":"{\"stream\":\"btcusdt@bookTicker\",\"data\":{\"e\":\"bookTicker\",\"u\":11478510925182,\"s\":\"BTCUSDT\",\"ps\":\"BTCUSDT\",\"b\":\"79596.90\",\"B\":\"6.848\",\"a\":\"79597.00\",\"A\":\"7.806\",\"T\":1788567771771,\"E\":1788567771771,\"st\":1}}"}
{"receive_ns":1788567771786723000,"stream":"btcusdt@bookTicker","event_type":"bookTicker","event_time_ms":1788567771771,"raw_json":"{\"stream\":\"btcusdt@bookTicker\",\"data\":{\"e\":\"bookTicker\",\"u\":11478510925183,\"s\":\"BTCUSDT\",\"ps\":\"BTCUSDT\",\"b\":\"79596.90\",\"B\":\"6.848\",\"a\":\"79597.00\",\"A\":\"7.888\",\"T\":1788567771771,\"E\":1788567771771,\"st\":1}}"}
{"receive_ns":1788567771793555000,"stream":"btcusdt@bookTicker","event_type":"bookTicker","event_time_ms":1788567771771,"raw_json":"{\"stream\":\"btcusdt@bookTicker\",\"data\":{\"e\":\"bookTicker\",\"u\":11478510925185,\"s\":\"BTCUSDT\",\"ps\":\"BTCUSDT\",\"b\":\"79596.90\",\"B\":\"6.848\",\"a\":\"79597.00\",\"A\":\"7.970\",\"T\":1788567771771,\"E\":1788567771771,\"st\":1}}"}
{"receive_ns":1788567771804539000,"stream":"btcusdt@depth@100ms","event_type":"depthUpdate","event_time_ms":1788567771777,"raw_json":"{\"stream\":\"btcusdt@depth@100ms\",\"data\":{\"e\":\"depthUpdate\",\"E\":1788567771777,\"T\":1788567771775,\"s\":\"BTCUSDT\",\"ps\":\"BTCUSDT\",\"U\":11478510920254,\"u\":11478510925282,\"pu\":11478510920091,\"b\":[[\"29096.90\",\"1.498\"],[\"29196.90\",\"0.602\"],[\"71637.20\",\"0.002\"],[\"76413.00\",\"0.023\"],[\"78800.90\",\"11.621\"],[\"78999.90\",\"3.793\"],[\"79198.90\",\"3.846\"],[\"79538.20\",\"0.001\"],[\"79554.10\",\"0.047\"],[\"79562.50\",\"1.891\"],[\"79562.60\",\"0.001\"]],\"a\":[[\"79597.00\",\"7.970\"],[\"79598.30\",\"0.028\"],[\"79598.60\",\"0.279\"],[\"79598.80\",\"0.029\"],[\"79602.20\",\"0.018\"],[\"79604.20\",\"0.008\"],[\"79605.60\",\"1.891\"],[\"79628.80\",\"0.000\"],[\"79643.20\",\"0.241\"],[\"79643.80\",\"1.161\"],[\"79651.50\",\"0.015\"],[\"79663.40\",\"0.000\"],[\"79995.00\",\"4.448\"],[\"80393.00\",\"14.884\"]],\"st\":1}}"}
{"receive_ns":1788567771817359000,"stream":"btcusdt@bookTicker","event_type":"bookTicker","event_time_ms":1788567771788,"raw_json":"{\"stream\":\"btcusdt@bookTicker\",\"data\":{\"e\":\"bookTicker\",\"u\":11478510925984,\"s\":\"BTCUSDT\",\"ps\":\"BTCUSDT\",\"b\":\"79596.90\",\"B\":\"6.848\",\"a\":\"79597.00\",\"A\":\"8.141\",\"T\":1788567771788,\"E\":1788567771788,\"st\":1}}"}
{"receive_ns":1788567771833781000,"stream":"btcusdt@bookTicker","event_type":"bookTicker","event_time_ms":1788567771838,"raw_json":"{\"stream\":\"btcusdt@bookTicker\",\"data\":{\"e\":\"bookTicker\",\"u\":11478510927996,\"s\":\"BTCUSDT\",\"ps\":\"BTCUSDT\",\"b\":\"79596.90\",\"B\":\"6.848\",\"a\":\"79597.00\",\"A\":\"8.158\",\"T\":1788567771838,\"E\":1788567771838,\"st\":1}}"}
{"receive_ns":1788567771868034000,"stream":"btcusdt@depth@100ms","event_type":"depthUpdate","event_time_ms":1788567771879,"raw_json":"{\"stream\":\"btcusdt@depth@100ms\",\"data\":{\"e\":\"depthUpdate\",\"E\":1788567771879,\"T\":1788567771877,\"s\":\"BTCUSDT\",\"ps\":\"BTCUSDT\",\"U\":11478510925398,\"u\":11478510930440,\"pu\":11478510925282,\"b\":[[\"1000.00\",\"24.604\"],[\"29096.90\",\"1.680\"],[\"29196.90\",\"0.420\"],[\"71637.20\",\"0.002\"],[\"76413.00\",\"0.025\"],[\"78522.30\",\"6.294\"],[\"78800.90\",\"11.621\"],[\"79299.80\",\"0.011\"],[\"79495.00\",\"0.163\"],[\"79506.70\",\"0.001\"],[\"79507.50\",\"0.013\"],[\"79507.70\",\"7.302\"],[\"79507.80\",\"2.259\"],[\"79576.80\",\"0.330\"],[\"79585.00\",\"0.035\"],[\"79594.50\",\"0.076\"]],\"a\":[[\"79597.00\",\"8.158\"],[\"79598.30\",\"0.002\"],[\"79598.60\",\"0.253\"],[\"79598.80\",\"0.003\"],[\"79599.00\",\"0.028\"],[\"79599.10\",\"0.078\"],[\"79599.20\",\"0.026\"],[\"79600.50\",\"0.104\"],[\"79600.60\",\"0.026\"],[\"79601.20\",\"0.002\"],[\"79617.10\",\"0.002\"],[\"79617.20\",\"0.002\"],[\"79688.30\",\"0.035\"],[\"79806.20\",\"2.661\"],[\"80393.00\",\"14.884\"]],\"st\":1}}"}
{"receive_ns":1788567771880640000,"stream":"btcusdt@bookTicker","event_type":"bookTicker","event_time_ms":1788567771888,"raw_json":"{\"stream\":\"btcusdt@bookTicker\",\"data\":{\"e\":\"bookTicker\",\"u\":11478510930830,\"s\":\"BTCUSDT\",\"ps\":\"BTCUSDT\",\"b\":\"79596.90\",\"B\":\"6.848\",\"a\":\"79597.00\",\"A\":\"8.160\",\"T\":1788567771887,\"E\":1788567771888,\"st\":1}}"}
{"receive_ns":1788567771906641000,"stream":"btcusdt@bookTicker","event_type":"bookTicker","event_time_ms":1788567771917,"raw_json":"{\"stream\":\"btcusdt@bookTicker\",\"data\":{\"e\":\"bookTicker\",\"u\":11478510932059,\"s\":\"BTCUSDT\",\"ps\":\"BTCUSDT\",\"b\":\"79596.90\",\"B\":\"6.848\",\"a\":\"79597.00\",\"A\":\"8.151\",\"T\":1788567771917,\"E\":1788567771917,\"st\":1}}"}
{"receive_ns":1788567771917583000,"stream":"btcusdt@bookTicker","event_type":"bookTicker","event_time_ms":1788567771923,"raw_json":"{\"stream\":\"btcusdt@bookTicker\",\"data\":{\"e\":\"bookTicker\",\"u\":11478510932221,\"s\":\"BTCUSDT\",\"ps\":\"BTCUSDT\",\"b\":\"79596.90\",\"B\":\"6.848\",\"a\":\"79597.00\",\"A\":\"8.161\",\"T\":1788567771923,\"E\":1788567771923,\"st\":1}}"}
{"receive_ns":1788567771918040000,"stream":"btcusdt@bookTicker","event_type":"bookTicker","event_time_ms":1788567771937,"raw_json":"{\"stream\":\"btcusdt@bookTicker\",\"data\":{\"e\":\"bookTicker\",\"u\":11478510932706,\"s\":\"BTCUSDT\",\"ps\":\"BTCUSDT\",\"b\":\"79596.90\",\"B\":\"6.847\",\"a\":\"79597.00\",\"A\":\"8.161\",\"T\":1788567771936,\"E\":1788567771937,\"st\":1}}"}
{"receive_ns":1788567771938032000,"stream":"btcusdt@trade","event_type":"trade","event_time_ms":1788567771937,"raw_json":"{\"stream\":\"btcusdt@trade\",\"data\":{\"e\":\"trade\",\"E\":1788567771937,\"T\":1788567771936,\"s\":\"BTCUSDT\",\"t\":8054122821,\"p\":\"79596.90\",\"q\":\"0.001\",\"X\":\"MARKET\",\"m\":true,\"st\":1}}"}
{"receive_ns":1788567771970577000,"stream":"btcusdt@depth@100ms","event_type":"depthUpdate","event_time_ms":1788567771981,"raw_json":"{\"stream\":\"btcusdt@depth@100ms\",\"data\":{\"e\":\"depthUpdate\",\"E\":1788567771981,\"T\":1788567771979,\"s\":\"BTCUSDT\",\"ps\":\"BTCUSDT\",\"U\":11478510930469,\"u\":11478510934205,\"pu\":11478510930440,\"b\":[[\"1000.00\",\"24.604\"],[\"29096.90\",\"1.785\"],[\"29196.90\",\"0.280\"],[\"29496.90\",\"0.035\"],[\"63677.50\",\"0.000\"],[\"71637.20\",\"0.002\"],[\"78466.70\",\"1.071\"],[\"78573.40\",\"0.000\"],[\"78575.80\",\"0.007\"],[\"78608.00\",\"0.846\"],[\"78610.30\",\"0.004\"],[\"78800.90\",\"11.621\"],[\"79453.10\",\"0.011\"],[\"79453.20\",\"17.620\"],[\"79454.60\",\"2.861\"],[\"79506.70\",\"4.394\"],[\"79507.70\",\"7.309\"],[\"79576.80\",\"0.016\"],[\"79585.00\",\"0.097\"],[\"79586.10\",\"0.319\"],[\"79586.20\",\"0.002\"],[\"79594.50\",\"0.000\"],[\"79596.90\",\"6.847\"]],\"a\":[[\"79597.00\",\"8.161\"],[\"79598.40\",\"0.004\"],[\"79598.70\",\"0.030\"],[\"79598.90\",\"0.027\"],[\"79600.60\",\"0.000\"],[\"79601.00\",\"0.317\"],[\"79601.10\",\"0.009\"],[\"79688.30\",\"3.341\"],[\"79740.40\",\"0.751\"],[\"79741.80\",\"17.557\"],[\"79806.20\",\"4.746\"],[\"79819.00\",\"6.938\"],[\"80393.00\",\"14.884\"],[\"80759.10\",\"0.250\"]],\"st\":1}}"}
{"receive_ns":1788567772003295000,"stream":"btcusdt@bookTicker","event_type":"bookTicker","event_time_ms":1788567772015,"raw_json":"{\"stream\":\"btcusdt@bookTicker\",\"data\":{\"e\":\"bookTicker\",\"u\":11478510935639,\"s\":\"BTCUSDT\",\"ps\":\"BTCUSDT\",\"b\":\"79596.90\",\"B\":\"6.835\",\"a\":\"79597.00\",\"A\":\"8.161\",\"T\":1788567772014,\"E\":1788567772015,\"st\":1}}"}
{"receive_ns":1788567772008953000,"stream":"btcusdt@bookTicker","event_type":"bookTicker","event_time_ms":1788567772019,"raw_json":"{\"stream\":\"btcusdt@bookTicker\",\"data\":{\"e\":\"bookTicker\",\"u\":11478510935800,\"s\":\"BTCUSDT\",\"ps\":\"BTCUSDT\",\"b\":\"79596.90\",\"B\":\"6.847\",\"a\":\"79597.00\",\"A\":\"8.161\",\"T\":1788567772019,\"E\":1788567772019,\"st\":1}}"}
{"receive_ns":1788567772068217000,"stream":"btcusdt@depth@100ms","event_type":"depthUpdate","event_time_ms":1788567772083,"raw_json":"{\"stream\":\"btcusdt@depth@100ms\",\"data\":{\"e\":\"depthUpdate\",\"E\":1788567772083,\"T\":1788567772082,\"s\":\"BTCUSDT\",\"ps\":\"BTCUSDT\",\"U\":11478510934279,\"u\":11478510938278,\"pu\":11478510934205,\"b\":[[\"29096.90\",\"1.841\"],[\"29196.90\",\"0.161\"],[\"29496.90\",\"0.098\"],[\"71637.20\",\"0.002\"],[\"76413.00\",\"0.023\"],[\"78800.90\",\"11.621\"],[\"79198.90\",\"3.846\"],[\"79576.80\",\"0.016\"],[\"79582.60\",\"0.070\"],[\"79585.00\",\"0.097\"],[\"79586.10\",\"0.319\"],[\"79586.20\",\"0.002\"],[\"79596.70\",\"0.034\"],[\"79596.90\",\"6.847\"]],\"a\":[[\"80393.00\",\"14.884\"],[\"80589.40\",\"2.215\"],[\"80687.50\",\"2.471\"]],\"st\":1}}"}
{"receive_ns":1788567772121451000,"stream":"btcusdt@bookTicker","event_type":"bookTicker","event_time_ms":1788567772137,"raw_json":"{\"stream\":\"btcusdt@bookTicker\",\"data\":{\"e\":\"bookTicker\",\"u\":11478510941378,\"s\":\"BTCUSDT\",\"ps\":\"BTCUSDT\",\"b\":\"79596.90\",\"B\":\"6.834\",\"a\":\"79597.00\",\"A\":\"8.161\",\"T\":1788567772137,\"E\":1788567772137,\"st\":1}}"}
{"receive_ns":1788567772137657000,"stream":"btcusdt@bookTicker","event_type":"bookTicker","event_time_ms":1788567772141,"raw_json":"{\"stream\":\"btcusdt@bookTicker\",\"data\":{\"e\":\"bookTicker\",\"u\":11478510941592,\"s\":\"BTCUSDT\",\"ps\":\"BTCUSDT\",\"b\":\"79596.90\",\"B\":\"6.846\",\"a\":\"79597.00\",\"A\":\"8.161\",\"T\":1788567772141,\"E\":1788567772141,\"st\":1}}"}
{"receive_ns":1788567772170059000,"stream":"btcusdt@depth@100ms","event_type":"depthUpdate","event_time_ms":1788567772185,"raw_json":"{\"stream\":\"btcusdt@depth@100ms\",\"data\":{\"e\":\"depthUpdate\",\"E\":1788567772185,\"T\":1788567772184,\"s\":\"BTCUSDT\",\"ps\":\"BTCUSDT\",\"U\":11478510938317,\"u\":11478510944091,\"pu\":11478510938278,\"b\":[[\"1000.00\",\"24.604\"],[\"29096.90\",\"1.904\"],[\"29196.90\",\"0.042\"],[\"29496.90\",\"0.154\"],[\"71637.20\",\"0.002\"],[\"76413.00\",\"0.025\"],[\"78005.00\",\"0.216\"],[\"78482.50\",\"26.846\"],[\"78641.70\",\"32.283\"],[\"78800.90\",\"11.621\"],[\"79525.20\",\"0.000\"],[\"79541.10\",\"1.098\"],[\"79576.80\",\"0.016\"],[\"79585.00\",\"0.097\"],[\"79586.10\",\"0.319\"],[\"79586.20\",\"0.002\"],[\"79596.90\",\"6.846\"]],\"a\":[[\"79598.70\",\"0.004\"],[\"79598.90\",\"0.001\"],[\"79599.00\",\"0.002\"],[\"79599.10\",\"0.078\"],[\"79599.20\",\"0.000\"],[\"79600.60\",\"0.026\"],[\"79600.70\",\"0.030\"],[\"79600.80\",\"0.034\"],[\"79602.20\",\"0.035\"],[\"79668.70\",\"2.054\"],[\"79691.90\",\"0.062\"],[\"79692.60\",\"0.002\"],[\"80393.00\",\"14.884\"],[\"80552.20\",\"28.734\"],[\"80558.40\",\"8.651\"],[\"80711.50\",\"11.031\"],[\"81188.90\",\"0.046\"]],\"st\":1}}"}
{"receive_ns":1788567772266662000,"stream":"btcusdt@bookTicker","event_type":"bookTicker","event_time_ms":1788567772278,"raw_json":"{\"stream\":\"btcusdt@bookTicker\",\"data\":{\"e\":\"bookTicker\",\"u\":11478510948884,\"s\":\"BTCUSDT\",\"ps\":\"BTCUSDT\",\"b\":\"79596.90\",\"B\":\"6.846\",\"a\":\"79597.00\",\"A\":\"8.157\",\"T\":1788567772278,\"E\":1788567772278,\"st\":1}}"}
{"receive_ns":1788567772266888000,"stream":"btcusdt@trade","event_type":"trade","event_time_ms":1788567772278,"raw_json":"{\"stream\":\"btcusdt@trade\",\"data\":{\"e\":\"trade\",\"E\":1788567772278,\"T\":1788567772278,\"s\":\"BTCUSDT\",\"t\":8054122822,\"p\":\"79597.00\",\"q\":\"0.004\",\"X\":\"MARKET\",\"m\":false,\"st\":1}}"}
{"receive_ns":1788567772278385000,"stream":"btcusdt@bookTicker","event_type":"bookTicker","event_time_ms":1788567772280,"raw_json":"{\"stream\":\"btcusdt@bookTicker\",\"data\":{\"e\":\"bookTicker\",\"u\":11478510948972,\"s\":\"BTCUSDT\",\"ps\":\"BTCUSDT\",\"b\":\"79596.90\",\"B\":\"6.845\",\"a\":\"79597.00\",\"A\":\"8.157\",\"T\":1788567772279,\"E\":1788567772280,\"st\":1}}"}
{"receive_ns":1788567772278660000,"stream":"btcusdt@bookTicker","event_type":"bookTicker","event_time_ms":1788567772280,"raw_json":"{\"stream\":\"btcusdt@bookTicker\",\"data\":{\"e\":\"bookTicker\",\"u\":11478510948981,\"s\":\"BTCUSDT\",\"ps\":\"BTCUSDT\",\"b\":\"79596.90\",\"B\":\"6.835\",\"a\":\"79597.00\",\"A\":\"8.157\",\"T\":1788567772279,\"E\":1788567772280,\"st\":1}}"}
{"receive_ns":1788567772290303000,"stream":"btcusdt@depth@100ms","event_type":"depthUpdate","event_time_ms":1788567772287,"raw_json":"{\"stream\":\"btcusdt@depth@100ms\",\"data\":{\"e\":\"depthUpdate\",\"E\":1788567772287,\"T\":1788567772285,\"s\":\"BTCUSDT\",\"ps\":\"BTCUSDT\",\"U\":11478510944162,\"u\":11478510949372,\"pu\":11478510944091,\"b\":[[\"1000.00\",\"24.604\"],[\"29096.90\",\"1.806\"],[\"29196.90\",\"0.000\"],[\"29496.90\",\"0.294\"],[\"71637.20\",\"0.002\"],[\"75617.20\",\"0.004\"],[\"76413.00\",\"0.023\"],[\"78602.00\",\"12.131\"],[\"78800.90\",\"11.621\"],[\"79454.60\",\"5.135\"],[\"79507.70\",\"7.321\"],[\"79537.80\",\"0.832\"],[\"79553.70\",\"0.818\"],[\"79568.90\",\"0.455\"],[\"79570.10\",\"0.001\"],[\"79583.40\",\"0.317\"],[\"79593.00\",\"0.131\"],[\"79596.90\",\"6.835\"]],\"a\":[[\"79597.00\",\"8.157\"],[\"79598.90\",\"0.001\"],[\"79599.10\",\"0.104\"],[\"79599.20\",\"0.026\"],[\"79600.80\",\"0.008\"],[\"79603.90\",\"0.126\"],[\"79604.00\",\"0.125\"],[\"79740.40\",\"3.106\"],[\"80393.00\",\"14.885\"],[\"80713.70\",\"7.484\"],[\"81825.80\",\"1.219\"]],\"st\":1}}"}
{"receive_ns":1788567772383191000,"stream":"btcusdt@depth@100ms","event_type":"depthUpdate","event_time_ms":1788567772389,"raw_json":"{\"stream\":\"btcusdt@depth@100ms\",\"data\":{\"e\":\"depthUpdate\",\"E\":1788567772389,\"T\":1788567772386,\"s\":\"BTCUSDT\",\"ps\":\"BTCUSDT\",\"U\":11478510949469,\"u\":11478510952831,\"pu\":11478510949372,\"b\":[[\"29096.90\",\"1.631\"],[\"29496.90\",\"0.469\"],[\"63678.00\",\"0.008\"],[\"71637.20\",\"0.002\"],[\"75617.10\",\"0.004\"],[\"77368.30\",\"0.773\"],[\"78402.90\",\"2.922\"],[\"78800.90\",\"11.621\"],[\"79198.90\",\"3.856\"],[\"79593.00\",\"0.055\"]],\"a\":[[\"79598.40\",\"0.007\"],[\"79598.70\",\"0.030\"],[\"80393.00\",\"14.885\"],[\"80552.20\",\"29.973\"]],\"st\":1}}"}
{"receive_ns":1788567772434524000,"stream":"btcusdt@bookTicker","event_type":"bookTicker","event_time_ms":1788567772444,"raw_json":"{\"stream\":\"btcusdt@bookTicker\",\"data\":{\"e\":\"bookTicker\",\"u\":11478510955680,\"s\":\"BTCUSDT\",\"ps\":\"BTCUSDT\",\"b\":\"79596.90\",\"B\":\"6.835\",\"a\":\"79597.00\",\"A\":\"8.156\",\"T\":1788567772444,\"E\":1788567772444,\"st\":1}}"}
{"receive_ns":1788567772456493000,"stream":"btcusdt@trade","event_type":"trade","event_time_ms":1788567772444,"raw_json":"{\"stream\":\"btcusdt@trade\",\"data\":{\"e\":\"trade\",\"E\":1788567772444,\"T\":1788567772444,\"s\":\"BTCUSDT\",\"t\":8054122823,\"p\":\"79597.00\",\"q\":\"0.001\",\"X\":\"MARKET\",\"m\":false,\"st\":1}}"}
{"receive_ns":1788567772464959000,"stream":"btcusdt@bookTicker","event_type":"bookTicker","event_time_ms":1788567772471,"raw_json":"{\"stream\":\"btcusdt@bookTicker\",\"data\":{\"e\":\"bookTicker\",\"u\":11478510956932,\"s\":\"BTCUSDT\",\"ps\":\"BTCUSDT\",\"b\":\"79596.90\",\"B\":\"6.835\",\"a\":\"79597.00\",\"A\":\"8.182\",\"T\":1788567772471,\"E\":1788567772471,\"st\":1}}"}
{"receive_ns":1788567772470727000,"stream":"btcusdt@bookTicker","event_type":"bookTicker","event_time_ms":1788567772481,"raw_json":"{\"stream\":\"btcusdt@bookTicker\",\"data\":{\"e\":\"bookTicker\",\"u\":11478510958088,\"s\":\"BTCUSDT\",\"ps\":\"BTCUSDT\",\"b\":\"79596.90\",\"B\":\"6.834\",\"a\":\"79597.00\",\"A\":\"8.182\",\"T\":1788567772481,\"E\":1788567772481,\"st\":1}}"}
{"receive_ns":1788567772481985000,"stream":"btcusdt@depth@100ms","event_type":"depthUpdate","event_time_ms":1788567772491,"raw_json":"{\"stream\":\"btcusdt@depth@100ms\",\"data\":{\"e\":\"depthUpdate\",\"E\":1788567772491,\"T\":1788567772490,\"s\":\"BTCUSDT\",\"ps\":\"BTCUSDT\",\"U\":11478510952970,\"u\":11478510958614,\"pu\":11478510952831,\"b\":[[\"1000.00\",\"24.604\"],[\"29096.90\",\"1.449\"],[\"29496.90\",\"0.651\"],[\"71637.20\",\"0.002\"],[\"71673.00\",\"0.000\"],[\"75617.10\",\"0.006\"],[\"76413.00\",\"0.025\"],[\"78403.00\",\"3.068\"],[\"78800.90\",\"11.621\"],[\"79477.40\",\"0.006\"],[\"79528.60\",\"20.190\"],[\"79534.00\",\"0.253\"],[\"79548.80\",\"0.001\"],[\"79568.90\",\"0.455\"],[\"79570.00\",\"0.005\"],[\"79570.30\",\"0.001\"],[\"79570.60\",\"0.041\"],[\"79573.20\",\"0.536\"],[\"79575.10\",\"0.092\"],[\"79576.80\",\"0.016\"],[\"79581.20\",\"0.077\"],[\"79582.30\",\"0.195\"],[\"79585.00\",\"0.035\"],[\"79586.10\",\"1.645\"],[\"79586.20\",\"0.002\"],[\"79586.90\",\"0.001\"],[\"79589.40\",\"0.007\"],[\"79589.70\",\"0.009\"],[\"79590.20\",\"0.001\"],[\"79590.50\",\"0.000\"],[\"79590.90\",\"0.074\"],[\"79591.20\",\"0.081\"],[\"79591.80\",\"0.000\"],[\"79591.90\",\"0.183\"],[\"79592.40\",\"0.002\"],[\"79592.50\",\"0.028\"],[\"79592.60\",\"0.026\"],[\"79592.70\",\"0.028\"],[\"79592.80\",\"0.531\"],[\"79592.90\",\"0.028\"],[\"79593.10\",\"0.048\"],[\"79593.20\",\"0.000\"],[\"79593.30\",\"0.026\"],[\"79594.00\",\"0.027\"],[\"79594.40\",\"0.000\"],[\"79595.10\",\"0.001\"],[\"79595.30\",\"0.001\"],[\"79595.40\",\"0.001\"],[\"79595.50\",\"0.000\"],[\"79595.60\",\"0.012\"],[\"79595.70\",\"0.001\"],[\"79595.90\",\"0.028\"],[\"79596.00\",\"0.082\"],[\"79596.10\",\"0.058\"],[\"79596.20\",\"0.000\"],[\"79596.30\",\"0.000\"],[\"79596.50\",\"0.444\"],[\"79596.70\",\"0.008\"],[\"79596.80\",\"0.159\"],[\"79596.90\",\"6.834\"]],\"a\":[[\"79597.00\",\"8.182\"],[\"79597.20\",\"0.030\"],[\"79597.80\",\"0.005\"],[\"79597.90\",\"0.028\"],[\"79600.50\",\"0.078\"],[\"79600.60\",\"0.000\"],[\"79600.70\",\"0.004\"],[\"79613.10\",\"0.192\"],[\"79615.90\",\"0.372\"],[\"79617.50\",\"0.000\"],[\"79620.90\",\"0.024\"],[\"79646.10\",\"0.001\"],[\"79646.20\",\"3.176\"],[\"79648.80\",\"0.264\"],[\"79658.60\",\"0.256\"],[\"79729.90\",\"3.145\"],[\"79810.70\",\"1.938\"],[\"79813.60\",\"3.147\"],[\"80393.00\",\"14.885\"],[\"81825.70\",\"0.977\"]],\"st\":1}}"}
{"receive_ns":1788567772503849000,"stream":"btcusdt@bookTicker","event_type":"bookTicker","event_time_ms":1788567772495,"raw_json":"{\"stream\":\"btcusdt@bookTicker\",\"data\":{\"e\":\"bookTicker\",\"u\":11478510958802,\"s\":\"BTCUSDT\",\"ps\":\"BTCUSDT\",\"b\":\"79596.90\",\"B\":\"6.834\",\"a\":\"79597.00\",\"A\":\"8.156\",\"T\":1788567772495,\"E\":1788567772495,\"st\":1}}"}
{"receive_ns":1788567772515580000,"stream":"btcusdt@bookTicker","event_type":"bookTicker","event_time_ms":1788567772496,"raw_json":"{\"stream\":\"btcusdt@bookTicker\",\"data\":{\"e\":\"bookTicker\",\"u\":11478510958837,\"s\":\"BTCUSDT\",\"ps\":\"BTCUSDT\",\"b\":\"79596.90\",\"B\":\"6.834\",\"a\":\"79597.00\",\"A\":\"8.182\",\"T\":1788567772496,\"E\":1788567772496,\"st\":1}}"}
{"receive_ns":1788567772527139000,"stream":"btcusdt@bookTicker","event_type":"bookTicker","event_time_ms":1788567772497,"raw_json":"{\"stream\":\"btcusdt@bookTicker\",\"data\":{\"e\":\"bookTicker\",\"u\":11478510958887,\"s\":\"BTCUSDT\",\"ps\":\"BTCUSDT\",\"b\":\"79596.90\",\"B\":\"6.834\",\"a\":\"79597.00\",\"A\":\"8.156\",\"T\":1788567772497,\"E\":1788567772497,\"st\":1}}"}
{"receive_ns":1788567772538892000,"stream":"btcusdt@bookTicker","event_type":"bookTicker","event_time_ms":1788567772499,"raw_json":"{\"stream\":\"btcusdt@bookTicker\",\"data\":{\"e\":\"bookTicker\",\"u\":11478510958977,\"s\":\"BTCUSDT\",\"ps\":\"BTCUSDT\",\"b\":\"79596.90\",\"B\":\"6.834\",\"a\":\"79597.00\",\"A\":\"8.182\",\"T\":1788567772499,\"E\":1788567772499,\"st\":1}}"}
{"receive_ns":1788567772554933000,"stream":"btcusdt@bookTicker","event_type":"bookTicker","event_time_ms":1788567772501,"raw_json":"{\"stream\":\"btcusdt@bookTicker\",\"data\":{\"e\":\"bookTicker\",\"u\":11478510959108,\"s\":\"BTCUSDT\",\"ps\":\"BTCUSDT\",\"b\":\"79596.90\",\"B\":\"6.834\",\"a\":\"79597.00\",\"A\":\"8.156\",\"T\":1788567772501,\"E\":1788567772501,\"st\":1}}"}
{"receive_ns":1788567772561149000,"stream":"btcusdt@bookTicker","event_type":"bookTicker","event_time_ms":1788567772503,"raw_json":"{\"stream\":\"btcusdt@bookTicker\",\"data\":{\"e\":\"bookTicker\",\"u\":11478510959271,\"s\":\"BTCUSDT\",\"ps\":\"BTCUSDT\",\"b\":\"79596.90\",\"B\":\"6.834\",\"a\":\"79597.00\",\"A\":\"8.169\",\"T\":1788567772503,\"E\":1788567772503,\"st\":1}}"}
{"receive_ns":1788567772578201000,"stream":"btcusdt@bookTicker","event_type":"bookTicker","event_time_ms":1788567772505,"raw_json":"{\"stream\":\"btcusdt@bookTicker\",\"data\":{\"e\":\"bookTicker\",\"u\":11478510959387,\"s\":\"BTCUSDT\",\"ps\":\"BTCUSDT\",\"b\":\"79596.90\",\"B\":\"6.834\",\"a\":\"79597.00\",\"A\":\"8.195\",\"T\":1788567772505,\"E\":1788567772505,\"st\":1}}"}
{"receive_ns":1788567772587281000,"stream":"btcusdt@bookTicker","event_type":"bookTicker","event_time_ms":1788567772535,"raw_json":"{\"stream\":\"btcusdt@bookTicker\",\"data\":{\"e\":\"bookTicker\",\"u\":11478510960630,\"s\":\"BTCUSDT\",\"ps\":\"BTCUSDT\",\"b\":\"79596.90\",\"B\":\"6.490\",\"a\":\"79597.00\",\"A\":\"8.195\",\"T\":1788567772534,\"E\":1788567772535,\"st\":1}}"}
{"receive_ns":1788567772587600000,"stream":"btcusdt@bookTicker","event_type":"bookTicker","event_time_ms":1788567772581,"raw_json":"{\"stream\":\"btcusdt@bookTicker\",\"data\":{\"e\":\"bookTicker\",\"u\":11478510962653,\"s\":\"BTCUSDT\",\"ps\":\"BTCUSDT\",\"b\":\"79596.90\",\"B\":\"6.491\",\"a\":\"79597.00\",\"A\":\"8.195\",\"T\":1788567772581,\"E\":1788567772581,\"st\":1}}"}
{"receive_ns":1788567772588199000,"stream":"btcusdt@depth@100ms","event_type":"depthUpdate","event_time_ms":1788567772593,"raw_json":"{\"stream\":\"btcusdt@depth@100ms\",\"data\":{\"e\":\"depthUpdate\",\"E\":1788567772593,\"T\":1788567772591,\"s\":\"BTCUSDT\",\"ps\":\"BTCUSDT\",\"U\":11478510958685,\"u\":11478510963105,\"pu\":11478510958614,\"b\":[[\"29096.90\",\"1.274\"],[\"29496.90\",\"0.826\"],[\"63678.00\",\"0.010\"],[\"71637.20\",\"0.002\"],[\"75617.10\",\"0.008\"],[\"76413.00\",\"0.023\"],[\"78800.90\",\"11.621\"],[\"79528.60\",\"0.210\"],[\"79531.30\",\"20.009\"],[\"79531.70\",\"3.496\"],[\"79534.50\",\"2.356\"],[\"79537.80\",\"0.003\"],[\"79553.70\",\"0.127\"],[\"79573.20\",\"0.538\"],[\"79583.50\",\"0.251\"],[\"79584.40\",\"0.010\"],[\"79586.90\",\"0.002\"],[\"79588.10\",\"0.034\"],[\"79588.20\",\"0.001\"],[\"79590.50\",\"0.076\"],[\"79591.20\",\"0.006\"],[\"79592.40\",\"0.002\"],[\"79592.50\",\"0.002\"],[\"79592.60\",\"0.000\"],[\"79593.80\",\"0.026\"],[\"79593.90\",\"0.000\"],[\"79594.50\",\"0.026\"],[\"79595.00\",\"0.002\"],[\"79595.10\",\"0.002\"],[\"79595.20\",\"0.026\"],[\"79595.30\",\"0.001\"],[\"79595.40\",\"0.001\"],[\"79595.50\",\"0.000\"],[\"79595.90\",\"0.035\"],[\"79596.10\",\"0.000\"],[\"79596.20\",\"0.000\"],[\"79596.40\",\"0.082\"],[\"79596.50\",\"0.444\"],[\"79596.70\",\"0.016\"],[\"79596.90\",\"6.491\"]],\"a\":[[\"79597.00\",\"8.195\"],[\"79597.10\",\"0.727\"],[\"79597.20\",\"0.004\"],[\"79597.30\",\"0.126\"],[\"79597.70\",\"0.026\"],[\"79600.40\",\"0.008\"],[\"79605.50\",\"1.804\"],[\"79607.10\",\"0.001\"],[\"79613.10\",\"0.194\"],[\"79646.20\",\"3.175\"],[\"79646.30\",\"0.001\"],[\"80393.00\",\"14.885\"],[\"80592.00\",\"7.812\"],[\"80759.20\",\"0.003\"],[\"80830.80\",\"5.685\"],[\"81188.90\",\"0.049\"]],\"st\":1}}"}
{"receive_ns":1788567772635859000,"stream":"btcusdt@bookTicker","event_type":"bookTicker","event_time_ms":1788567772644,"raw_json":"{\"stream\":\"btcusdt@bookTicker\",\"data\":{\"e\":\"bookTicker\",\"u\":11478510968260,\"s\":\"BTCUSDT\",\"ps\":\"BTCUSDT\",\"b\":\"79596.90\",\"B\":\"6.491\",\"a\":\"79597.00\",\"A\":\"8.185\",\"T\":1788567772643,\"E\":1788567772644,\"st\":1}}"}
{"receive_ns":1788567772647560000,"stream":"btcusdt@bookTicker","event_type":"bookTicker","event_time_ms":1788567772646,"raw_json":"{\"stream\":\"btcusdt@bookTicker\",\"data\":{\"e\":\"bookTicker\",\"u\":11478510968406,\"s\":\"BTCUSDT\",\"ps\":\"BTCUSDT\",\"b\":\"79596.90\",\"B\":\"6.491\",\"a\":\"79597.00\",\"A\":\"8.198\",\"T\":1788567772646,\"E\":1788567772646,\"st\":1}}"}
{"receive_ns":1788567772685283000,"stream":"btcusdt@depth@100ms","event_type":"depthUpdate","event_time_ms":1788567772695,"raw_json":"{\"stream\":\"btcusdt@depth@100ms\",\"data\":{\"e\":\"depthUpdate\",\"E\":1788567772695,\"T\":1788567772694,\"s\":\"BTCUSDT\",\"ps\":\"BTCUSDT\",\"U\":11478510963171,\"u\":11478510970786,\"pu\":11478510963105,\"b\":[[\"29096.90\",\"1.092\"],[\"29496.90\",\"1.008\"],[\"63678.00\",\"0.008\"],[\"71637.20\",\"0.002\"],[\"76413.00\",\"0.025\"],[\"76413.20\",\"0.001\"],[\"78660.90\",\"0.883\"],[\"78800.90\",\"11.621\"],[\"79198.90\",\"3.845\"],[\"79523.00\",\"0.016\"],[\"79531.30\",\"0.011\"],[\"79531.70\",\"0.677\"],[\"79534.00\",\"20.251\"],[\"79536.10\",\"0.001\"],[\"79568.90\",\"0.003\"],[\"79570.90\",\"0.454\"],[\"79594.60\",\"0.066\"],[\"79595.00\",\"0.002\"],[\"79595.10\",\"0.028\"],[\"79595.20\",\"0.000\"],[\"79595.30\",\"0.001\"],[\"79595.40\",\"0.001\"],[\"79595.50\",\"0.000\"]],\"a\":[[\"79597.00\",\"8.198\"],[\"79610.70\",\"0.106\"],[\"79612.20\",\"0.443\"],[\"79615.90\",\"0.000\"],[\"79617.20\",\"0.374\"],[\"79619.40\",\"0.799\"],[\"79620.60\",\"0.454\"],[\"79995.00\",\"4.571\"],[\"80393.00\",\"14.885\"],[\"80592.10\",\"6.783\"],[\"80617.60\",\"4.276\"]],\"st\":1}}"}
{"receive_ns":1788567772749791000,"stream":"btcusdt@bookTicker","event_type":"bookTicker","event_time_ms":1788567772760,"raw_json":"{\"stream\":\"btcusdt@bookTicker\",\"data\":{\"e\":\"bookTicker\",\"u\":11478510974479,\"s\":\"BTCUSDT\",\"ps\":\"BTCUSDT\",\"b\":\"79596.90\",\"B\":\"6.501\",\"a\":\"79597.00\",\"A\":\"8.198\",\"T\":1788567772760,\"E\":1788567772760,\"st\":1}}"}
{"receive_ns":1788567772791463000,"stream":"btcusdt@depth@100ms","event_type":"depthUpdate","event_time_ms":1788567772797,"raw_json":"{\"stream\":\"btcusdt@depth@100ms\",\"data\":{\"e\":\"depthUpdate\",\"E\":1788567772797,\"T\":1788567772795,\"s\":\"BTCUSDT\",\"ps\":\"BTCUSDT\",\"U\":11478510970860,\"u\":11478510976325,\"pu\":11478510970786,\"b\":[[\"1000.00\",\"24.604\"],[\"29096.90\",\"0.917\"],[\"29496.90\",\"1.183\"],[\"63678.00\",\"0.008\"],[\"71637.20\",\"0.002\"],[\"76413.00\",\"0.023\"],[\"78681.50\",\"5.690\"],[\"78800.90\",\"11.621\"],[\"79198.90\",\"3.846\"],[\"79523.00\",\"0.002\"],[\"79531.90\",\"0.014\"],[\"79568.90\",\"0.455\"],[\"79570.90\",\"0.002\"],[\"79595.10\",\"0.002\"],[\"79595.20\",\"0.000\"],[\"79595.30\",\"0.001\"],[\"79595.40\",\"0.001\"],[\"79595.50\",\"0.000\"],[\"79595.60\",\"0.012\"],[\"79595.70\",\"0.027\"],[\"79596.90\",\"6.501\"]],\"a\":[[\"79610.90\",\"0.442\"],[\"79612.20\",\"0.004\"],[\"79995.00\",\"4.572\"],[\"80393.00\",\"14.885\"],[\"81188.90\",\"0.046\"]],\"st\":1}}"}
{"receive_ns":1788567772890213000,"stream":"btcusdt@depth@100ms","event_type":"depthUpdate","event_time_ms":1788567772899,"raw_json":"{\"stream\":\"btcusdt@depth@100ms\",\"data\":{\"e\":\"depthUpdate\",\"E\":1788567772899,\"T\":1788567772898,\"s\":\"BTCUSDT\",\"ps\":\"BTCUSDT\",\"U\":11478510976378,\"u\":11478510981573,\"pu\":11478510976325,\"b\":[[\"29096.90\",\"0.735\"],[\"29496.90\",\"1.365\"],[\"63678.00\",\"0.012\"],[\"71637.20\",\"0.002\"],[\"78800.90\",\"11.621\"],[\"79417.40\",\"0.000\"],[\"79419.50\",\"0.534\"],[\"79432.10\",\"0.251\"],[\"79503.70\",\"0.150\"],[\"79504.00\",\"0.002\"],[\"79546.40\",\"0.000\"],[\"79546.70\",\"0.065\"],[\"79565.30\",\"0.930\"],[\"79565.40\",\"1.887\"],[\"79572.50\",\"0.266\"],[\"79572.60\",\"0.000\"],[\"79591.60\",\"0.000\"],[\"79591.70\",\"0.003\"],[\"79592.70\",\"0.002\"],[\"79592.80\",\"0.505\"],[\"79594.00\",\"0.026\"],[\"79594.80\",\"0.026\"],[\"79595.60\",\"0.012\"],[\"79595.70\",\"0.001\"],[\"79595.80\",\"0.000\"],[\"79595.90\",\"0.002\"]],\"a\":[[\"79607.80\",\"0.067\"],[\"79613.50\",\"0.010\"],[\"79622.00\",\"0.027\"],[\"79623.20\",\"0.020\"],[\"79645.90\",\"0.065\"],[\"79647.20\",\"0.000\"],[\"79708.50\",\"0.149\"],[\"79715.30\",\"0.000\"],[\"79808.90\",\"0.001\"],[\"79812.70\",\"0.249\"],[\"79819.00\",\"7.030\"],[\"80393.00\",\"14.885\"],[\"80592.10\",\"6.505\"]],\"st\":1}}"}
{"receive_ns":1788567772992005000,"stream":"btcusdt@depth@100ms","event_type":"depthUpdate","event_time_ms":1788567773001,"raw_json":"{\"stream\":\"btcusdt@depth@100ms\",\"data\":{\"e\":\"depthUpdate\",\"E\":1788567773001,\"T\":1788567772999,\"s\":\"BTCUSDT\",\"ps\":\"BTCUSDT\",\"U\":11478510981611,\"u\":11478510987482,\"pu\":11478510981573,\"b\":[[\"29096.90\",\"0.560\"],[\"29496.90\",\"1.540\"],[\"63677.50\",\"0.000\"],[\"63678.00\",\"0.008\"],[\"71637.20\",\"0.002\"],[\"76413.00\",\"0.025\"],[\"78590.70\",\"0.000\"],[\"78595.40\",\"0.004\"],[\"78601.90\",\"7.252\"],[\"78800.90\",\"11.621\"],[\"79198.90\",\"3.846\"],[\"79590.00\",\"0.095\"],[\"79591.60\",\"0.000\"],[\"79591.70\",\"0.003\"],[\"79595.80\",\"0.026\"],[\"79595.90\",\"0.002\"],[\"79596.00\",\"0.082\"]],\"a\":[[\"79995.00\",\"4.697\"],[\"80194.00\",\"3.926\"],[\"80393.00\",\"14.885\"]],\"st\":1}}"}
{"receive_ns":1788567773077404000,"stream":"btcusdt@bookTicker","event_type":"bookTicker","event_time_ms":1788567773083,"raw_json":"{\"stream\":\"btcusdt@bookTicker\",\"data\":{\"e\":\"bookTicker\",\"u\":11478510994334,\"s\":\"BTCUSDT\",\"ps\":\"BTCUSDT\",\"b\":\"79596.90\",\"B\":\"6.501\",\"a\":\"79597.00\",\"A\":\"8.196\",\"T\":1788567773083,\"E\":1788567773083,\"st\":1}}"}
{"receive_ns":1788567773090542000,"stream":"btcusdt@bookTicker","event_type":"bookTicker","event_time_ms":1788567773085,"raw_json":"{\"stream\":\"btcusdt@bookTicker\",\"data\":{\"e\":\"bookTicker\",\"u\":11478510994502,\"s\":\"BTCUSDT\",\"ps\":\"BTCUSDT\",\"b\":\"79596.90\",\"B\":\"6.482\",\"a\":\"79597.00\",\"A\":\"8.196\",\"T\":1788567773085,\"E\":1788567773085,\"st\":1}}"}
{"receive_ns":1788567773107188000,"stream":"btcusdt@bookTicker","event_type":"bookTicker","event_time_ms":1788567773088,"raw_json":"{\"stream\":\"btcusdt@bookTicker\",\"data\":{\"e\":\"bookTicker\",\"u\":11478510994723,\"s\":\"BTCUSDT\",\"ps\":\"BTCUSDT\",\"b\":\"79596.90\",\"B\":\"6.500\",\"a\":\"79597.00\",\"A\":\"8.196\",\"T\":1788567773088,\"E\":1788567773088,\"st\":1}}"}
{"receive_ns":1788567773123774000,"stream":"btcusdt@bookTicker","event_type":"bookTicker","event_time_ms":1788567773096,"raw_json":"{\"stream\":\"btcusdt@bookTicker\",\"data\":{\"e\":\"bookTicker\",\"u\":11478510995317,\"s\":\"BTCUSDT\",\"ps\":\"BTCUSDT\",\"b\":\"79596.90\",\"B\":\"6.852\",\"a\":\"79597.00\",\"A\":\"8.196\",\"T\":1788567773096,\"E\":1788567773096,\"st\":1}}"}
{"receive_ns":1788567773141101000,"stream":"btcusdt@bookTicker","event_type":"bookTicker","event_time_ms":1788567773097,"raw_json":"{\"stream\":\"btcusdt@bookTicker\",\"data\":{\"e\":\"bookTicker\",\"u\":11478510995379,\"s\":\"BTCUSDT\",\"ps\":\"BTCUSDT\",\"b\":\"79596.90\",\"B\":\"6.851\",\"a\":\"79597.00\",\"A\":\"8.196\",\"T\":1788567773097,\"E\":1788567773097,\"st\":1}}"}
{"receive_ns":1788567773151928000,"stream":"btcusdt@bookTicker","event_type":"bookTicker","event_time_ms":1788567773099,"raw_json":"{\"stream\":\"btcusdt@bookTicker\",\"data\":{\"e\":\"bookTicker\",\"u\":11478510995581,\"s\":\"BTCUSDT\",\"ps\":\"BTCUSDT\",\"b\":\"79596.90\",\"B\":\"6.851\",\"a\":\"79597.00\",\"A\":\"8.114\",\"T\":1788567773099,\"E\":1788567773099,\"st\":1}}"}
{"receive_ns":1788567773158320000,"stream":"btcusdt@bookTicker","event_type":"bookTicker","event_time_ms":1788567773099,"raw_json":"{\"stream\":\"btcusdt@bookTicker\",\"data\":{\"e\":\"bookTicker\",\"u\":11478510995587,\"s\":\"BTCUSDT\",\"ps\":\"BTCUSDT\",\"b\":\"79596.90\",\"B\":\"6.851\",\"a\":\"79597.00\",\"A\":\"8.032\",\"T\":1788567773099,\"E\":1788567773099,\"st\":1}}"}
{"receive_ns":1788567773164655000,"stream":"btcusdt@bookTicker","event_type":"bookTicker","event_time_ms":1788567773099,"raw_json":"{\"stream\":\"btcusdt@bookTicker\",\"data\":{\"e\":\"bookTicker\",\"u\":11478510995591,\"s\":\"BTCUSDT\",\"ps\":\"BTCUSDT\",\"b\":\"79596.90\",\"B\":\"6.851\",\"a\":\"79597.00\",\"A\":\"7.950\",\"T\":1788567773099,\"E\":1788567773099,\"st\":1}}"}
{"receive_ns":1788567773176084000,"stream":"btcusdt@depth@100ms","event_type":"depthUpdate","event_time_ms":1788567773103,"raw_json":"{\"stream\":\"btcusdt@depth@100ms\",\"data\":{\"e\":\"depthUpdate\",\"E\":1788567773103,\"T\":1788567773102,\"s\":\"BTCUSDT\",\"ps\":\"BTCUSDT\",\"U\":11478510987619,\"u\":11478510995947,\"pu\":11478510987482,\"b\":[[\"1000.00\",\"24.604\"],[\"29096.90\",\"0.378\"],[\"29496.90\",\"1.722\"],[\"63678.00\",\"0.008\"],[\"71637.20\",\"0.002\"],[\"76413.00\",\"0.023\"],[\"78259.70\",\"1.023\"],[\"78800.90\",\"11.621\"],[\"79198.90\",\"3.971\"],[\"79581.90\",\"0.323\"],[\"79582.60\",\"0.070\"],[\"79585.30\",\"0.000\"],[\"79591.60\",\"0.000\"],[\"79591.70\",\"0.079\"],[\"79592.90\",\"0.002\"],[\"79594.20\",\"0.252\"],[\"79595.00\",\"0.028\"],[\"79595.20\",\"0.026\"],[\"79595.60\",\"0.012\"],[\"79595.70\",\"0.001\"],[\"79595.80\",\"0.000\"],[\"79595.90\",\"0.002\"],[\"79596.00\",\"0.082\"],[\"79596.20\",\"0.000\"],[\"79596.90\",\"6.851\"]],\"a\":[[\"79597.00\",\"7.950\"],[\"79597.20\",\"0.002\"],[\"79612.30\",\"0.003\"],[\"79628.20\",\"0.012\"],[\"80393.00\",\"14.885\"]],\"st\":1}}"}
{"receive_ns":1788567773182347000,"stream":"btcusdt@bookTicker","event_type":"bookTicker","event_time_ms":1788567773103,"raw_json":"{\"stream\":\"btcusdt@bookTicker\",\"data\":{\"e\":\"bookTicker\",\"u\":11478510995961,\"s\":\"BTCUSDT\",\"ps\":\"BTCUSDT\",\"b\":\"79596.90\",\"B\":\"6.851\",\"a\":\"79597.00\",\"A\":\"8.032\",\"T\":1788567773102,\"E\":1788567773103,\"st\":1}}"}
{"receive_ns":1788567773182590000,"stream":"btcusdt@bookTicker","event_type":"bookTicker","event_time_ms":1788567773103,"raw_json":"{\"stream\":\"btcusdt@bookTicker\",\"data\":{\"e\":\"bookTicker\",\"u\":11478510995971,\"s\":\"BTCUSDT\",\"ps\":\"BTCUSDT\",\"b\":\"79596.90\",\"B\":\"6.851\",\"a\":\"79597.00\",\"A\":\"8.114\",\"T\":1788567773103,\"E\":1788567773103,\"st\":1}}"}
{"receive_ns":1788567773188612000,"stream":"btcusdt@bookTicker","event_type":"bookTicker","event_time_ms":1788567773103,"raw_json":"{\"stream\":\"btcusdt@bookTicker\",\"data\":{\"e\":\"bookTicker\",\"u\":11478510995994,\"s\":\"BTCUSDT\",\"ps\":\"BTCUSDT\",\"b\":\"79596.90\",\"B\":\"6.851\",\"a\":\"79597.00\",\"A\":\"8.196\",\"T\":1788567773103,\"E\":1788567773103,\"st\":1}}"}
{"receive_ns":1788567773200031000,"stream":"btcusdt@bookTicker","event_type":"bookTicker","event_time_ms":1788567773104,"raw_json":"{\"stream\":\"btcusdt@bookTicker\",\"data\":{\"e\":\"bookTicker\",\"u\":11478510996036,\"s\":\"BTCUSDT\",\"ps\":\"BTCUSDT\",\"b\":\"79596.90\",\"B\":\"6.852\",\"a\":\"79597.00\",\"A\":\"8.196\",\"T\":1788567773104,\"E\":1788567773104,\"st\":1}}"}
{"receive_ns":1788567773203747000,"stream":"btcusdt@bookTicker","event_type":"bookTicker","event_time_ms":1788567773104,"raw_json":"{\"stream\":\"btcusdt@bookTicker\",\"data\":{\"e\":\"bookTicker\",\"u\":11478510996042,\"s\":\"BTCUSDT\",\"ps\":\"BTCUSDT\",\"b\":\"79596.90\",\"B\":\"6.852\",\"a\":\"79597.00\",\"A\":\"8.198\",\"T\":1788567773104,\"E\":1788567773104,\"st\":1}}"}
{"receive_ns":1788567773209800000,"stream":"btcusdt@bookTicker","event_type":"bookTicker","event_time_ms":1788567773113,"raw_json":"{\"stream\":\"btcusdt@bookTicker\",\"data\":{\"e\":\"bookTicker\",\"u\":11478510996616,\"s\":\"BTCUSDT\",\"ps\":\"BTCUSDT\",\"b\":\"79596.90\",\"B\":\"6.852\",\"a\":\"79597.00\",\"A\":\"8.172\",\"T\":1788567773113,\"E\":1788567773113,\"st\":1}}"}
{"receive_ns":1788567773226444000,"stream":"btcusdt@bookTicker","event_type":"bookTicker","event_time_ms":1788567773114,"raw_json":"{\"stream\":\"btcusdt@bookTicker\",\"data\":{\"e\":\"bookTicker\",\"u\":11478510996678,\"s\":\"BTCUSDT\",\"ps\":\"BTCUSDT\",\"b\":\"79596.90\",\"B\":\"6.852\",\"a\":\"79597.00\",\"A\":\"8.170\",\"T\":1788567773114,\"E\":1788567773114,\"st\":1}}"}
{"receive_ns":1788567773237607000,"stream":"btcusdt@bookTicker","event_type":"bookTicker","event_time_ms":1788567773116,"raw_json":"{\"stream\":\"btcusdt@bookTicker\",\"data\":{\"e\":\"bookTicker\",\"u\":11478510996823,\"s\":\"BTCUSDT\",\"ps\":\"BTCUSDT\",\"b\":\"79596.90\",\"B\":\"6.852\",\"a\":\"79597.00\",\"A\":\"8.088\",\"T\":1788567773116,\"E\":1788567773116,\"st\":1}}"}
{"receive_ns":1788567773248838000,"stream":"btcusdt@bookTicker","event_type":"bookTicker","event_time_ms":1788567773116,"raw_json":"{\"stream\":\"btcusdt@bookTicker\",\"data\":{\"e\":\"bookTicker\",\"u\":11478510996833,\"s\":\"BTCUSDT\",\"ps\":\"BTCUSDT\",\"b\":\"79596.90\",\"B\":\"6.852\",\"a\":\"79597.00\",\"A\":\"8.006\",\"T\":1788567773116,\"E\":1788567773116,\"st\":1}}"}
{"receive_ns":1788567773255529000,"stream":"btcusdt@bookTicker","event_type":"bookTicker","event_time_ms":1788567773116,"raw_json":"{\"stream\":\"btcusdt@bookTicker\",\"data\":{\"e\":\"bookTicker\",\"u\":11478510996840,\"s\":\"BTCUSDT\",\"ps\":\"BTCUSDT\",\"b\":\"79596.90\",\"B\":\"6.852\",\"a\":\"79597.00\",\"A\":\"7.924\",\"T\":1788567773116,\"E\":1788567773116,\"st\":1}}"}
{"receive_ns":1788567773258734000,"stream":"btcusdt@bookTicker","event_type":"bookTicker","event_time_ms":1788567773117,"raw_json":"{\"stream\":\"btcusdt@bookTicker\",\"data\":{\"e\":\"bookTicker\",\"u\":11478510996917,\"s\":\"BTCUSDT\",\"ps\":\"BTCUSDT\",\"b\":\"79596.90\",\"B\":\"6.852\",\"a\":\"79597.00\",\"A\":\"7.922\",\"T\":1788567773117,\"E\":1788567773117,\"st\":1}}"}
{"receive_ns":1788567773264423000,"stream":"btcusdt@bookTicker","event_type":"bookTicker","event_time_ms":1788567773117,"raw_json":"{\"stream\":\"btcusdt@bookTicker\",\"data\":{\"e\":\"bookTicker\",\"u\":11478510996922,\"s\":\"BTCUSDT\",\"ps\":\"BTCUSDT\",\"b\":\"79596.90\",\"B\":\"6.852\",\"a\":\"79597.00\",\"A\":\"7.905\",\"T\":1788567773117,\"E\":1788567773117,\"st\":1}}"}
{"receive_ns":1788567773264648000,"stream":"btcusdt@bookTicker","event_type":"bookTicker","event_time_ms":1788567773117,"raw_json":"{\"stream\":\"btcusdt@bookTicker\",\"data\":{\"e\":\"bookTicker\",\"u\":11478510996936,\"s\":\"BTCUSDT\",\"ps\":\"BTCUSDT\",\"b\":\"79596.90\",\"B\":\"6.852\",\"a\":\"79597.00\",\"A\":\"6.441\",\"T\":1788567773117,\"E\":1788567773117,\"st\":1}}"}
{"receive_ns":1788567773264874000,"stream":"btcusdt@bookTicker","event_type":"bookTicker","event_time_ms":1788567773117,"raw_json":"{\"stream\":\"btcusdt@bookTicker\",\"data\":{\"e\":\"bookTicker\",\"u\":11478510996938,\"s\":\"BTCUSDT\",\"ps\":\"BTCUSDT\",\"b\":\"79596.90\",\"B\":\"6.852\",\"a\":\"79597.00\",\"A\":\"6.270\",\"T\":1788567773117,\"E\":1788567773117,\"st\":1}}"}
{"receive_ns":1788567773270445000,"stream":"btcusdt@bookTicker","event_type":"bookTicker","event_time_ms":1788567773155,"raw_json":"{\"stream\":\"btcusdt@bookTicker\",\"data\":{\"e\":\"bookTicker\",\"u\":11478510999527,\"s\":\"BTCUSDT\",\"ps\":\"BTCUSDT\",\"b\":\"79596.90\",\"B\":\"6.852\",\"a\":\"79597.00\",\"A\":\"6.257\",\"T\":1788567773154,\"E\":1788567773155,\"st\":1}}"}
{"receive_ns":1788567773282507000,"stream":"btcusdt@bookTicker","event_type":"bookTicker","event_time_ms":1788567773157,"raw_json":"{\"stream\":\"btcusdt@bookTicker\",\"data\":{\"e\":\"bookTicker\",\"u\":11478510999693,\"s\":\"BTCUSDT\",\"ps\":\"BTCUSDT\",\"b\":\"79596.90\",\"B\":\"6.852\",\"a\":\"79597.00\",\"A\":\"6.268\",\"T\":1788567773157,\"E\":1788567773157,\"st\":1}}"}
{"receive_ns":1788567773294071000,"stream":"btcusdt@bookTicker","event_type":"bookTicker","event_time_ms":1788567773195,"raw_json":"{\"stream\":\"btcusdt@bookTicker\",\"data\":{\"e\":\"bookTicker\",\"u\":11478511001762,\"s\":\"BTCUSDT\",\"ps\":\"BTCUSDT\",\"b\":\"79596.90\",\"B\":\"6.853\",\"a\":\"79597.00\",\"A\":\"6.268\",\"T\":1788567773195,\"E\":1788567773195,\"st\":1}}"}
{"receive_ns":1788567773306332000,"stream":"btcusdt@depth@100ms","event_type":"depthUpdate","event_time_ms":1788567773205,"raw_json":"{\"stream\":\"btcusdt@depth@100ms\",\"data\":{\"e\":\"depthUpdate\",\"E\":1788567773205,\"T\":1788567773204,\"s\":\"BTCUSDT\",\"ps\":\"BTCUSDT\",\"U\":11478510995955,\"u\":11478511002338,\"pu\":11478510995947,\"b\":[[\"29096.90\",\"0.252\"],[\"29396.90\",\"0.049\"],[\"29496.90\",\"1.799\"],[\"71637.20\",\"0.002\"],[\"71637.30\",\"0.000\"],[\"75617.10\",\"0.006\"],[\"75617.20\",\"0.006\"],[\"76413.00\",\"0.025\"],[\"78005.00\",\"0.219\"],[\"78800.90\",\"11.621\"],[\"79525.20\",\"0.002\"],[\"79575.50\",\"2.625\"],[\"79576.30\",\"0.137\"],[\"79581.20\",\"0.001\"],[\"79582.30\",\"0.119\"],[\"79586.90\",\"0.001\"],[\"79587.00\",\"0.004\"],[\"79587.60\",\"0.002\"],[\"79592.90\",\"0.002\"],[\"79593.00\",\"0.055\"],[\"79593.10\",\"0.022\"],[\"79593.30\",\"0.076\"],[\"79593.40\",\"0.161\"],[\"79593.80\",\"0.000\"],[\"79594.00\",\"0.000\"],[\"79594.40\",\"0.000\"],[\"79594.50\",\"0.026\"],[\"79594.60\",\"0.066\"],[\"79594.70\",\"0.000\"],[\"79595.70\",\"0.027\"],[\"79596.00\",\"0.108\"],[\"79596.10\",\"0.026\"],[\"79596.30\",\"0.000\"],[\"79596.40\",\"0.108\"],[\"79596.80\",\"0.185\"],[\"79596.90\",\"6.853\"]],\"a\":[[\"79597.00\",\"6.268\"],[\"79597.20\",\"0.002\"],[\"79597.30\",\"0.348\"],[\"79597.50\",\"0.014\"],[\"79597.70\",\"0.000\"],[\"79597.90\",\"0.002\"],[\"79598.50\",\"0.000\"],[\"79598.70\",\"0.004\"],[\"79598.80\",\"0.003\"],[\"79598.90\",\"0.001\"],[\"79599.00\",\"0.002\"],[\"79599.10\",\"0.078\"],[\"79599.20\",\"0.000\"],[\"79599.40\",\"0.000\"],[\"79599.80\",\"0.027\"],[\"79599.90\",\"0.028\"],[\"79600.40\",\"0.034\"],[\"79600.50\",\"0.104\"],[\"79600.60\",\"0.026\"],[\"79600.70\",\"0.030\"],[\"79600.80\",\"0.034\"],[\"79600.90\",\"0.002\"],[\"79601.20\",\"0.000\"],[\"79604.20\",\"0.007\"],[\"79605.50\",\"1.553\"],[\"79605.60\",\"1.892\"],[\"79606.10\",\"0.251\"],[\"79615.40\",\"0.004\"],[\"79616.80\",\"0.375\"],[\"79617.10\",\"0.000\"],[\"79617.20\",\"0.000\"],[\"79628.10\",\"0.001\"],[\"79648.80\",\"0.204\"],[\"79658.00\",\"0.063\"],[\"79692.60\",\"0.004\"],[\"79806.20\",\"4.790\"],[\"79995.00\",\"4.572\"],[\"80393.00\",\"14.885\"],[\"80592.10\",\"6.356\"],[\"80703.40\",\"3.838\"]],\"st\":1}}"}
{"receive_ns":1788567773312271000,"stream":"btcusdt@bookTicker","event_type":"bookTicker","event_time_ms":1788567773209,"raw_json":"{\"stream\":\"btcusdt@bookTicker\",\"data\":{\"e\":\"bookTicker\",\"u\":11478511002772,\"s\":\"BTCUSDT\",\"ps\":\"BTCUSDT\",\"b\":\"79596.90\",\"B\":\"6.852\",\"a\":\"79597.00\",\"A\":\"6.268\",\"T\":1788567773208,\"E\":1788567773209,\"st\":1}}"}
{"receive_ns":1788567773319686000,"stream":"btcusdt@bookTicker","event_type":"bookTicker","event_time_ms":1788567773221,"raw_json":"{\"stream\":\"btcusdt@bookTicker\",\"data\":{\"e\":\"bookTicker\",\"u\":11478511003595,\"s\":\"BTCUSDT\",\"ps\":\"BTCUSDT\",\"b\":\"79596.90\",\"B\":\"6.853\",\"a\":\"79597.00\",\"A\":\"6.268\",\"T\":1788567773221,\"E\":1788567773221,\"st\":1}}"}
{"receive_ns":1788567773325841000,"stream":"btcusdt@bookTicker","event_type":"bookTicker","event_time_ms":1788567773261,"raw_json":"{\"stream\":\"btcusdt@bookTicker\",\"data\":{\"e\":\"bookTicker\",\"u\":11478511006309,\"s\":\"BTCUSDT\",\"ps\":\"BTCUSDT\",\"b\":\"79596.90\",\"B\":\"6.852\",\"a\":\"79597.00\",\"A\":\"6.268\",\"T\":1788567773261,\"E\":1788567773261,\"st\":1}}"}
{"receive_ns":1788567773332256000,"stream":"btcusdt@bookTicker","event_type":"bookTicker","event_time_ms":1788567773261,"raw_json":"{\"stream\":\"btcusdt@bookTicker\",\"data\":{\"e\":\"bookTicker\",\"u\":11478511006314,\"s\":\"BTCUSDT\",\"ps\":\"BTCUSDT\",\"b\":\"79596.90\",\"B\":\"6.845\",\"a\":\"79597.00\",\"A\":\"6.268\",\"T\":1788567773261,\"E\":1788567773261,\"st\":1}}"}
{"receive_ns":1788567773354185000,"stream":"btcusdt@bookTicker","event_type":"bookTicker","event_time_ms":1788567773264,"raw_json":"{\"stream\":\"btcusdt@bookTicker\",\"data\":{\"e\":\"bookTicker\",\"u\":11478511006483,\"s\":\"BTCUSDT\",\"ps\":\"BTCUSDT\",\"b\":\"79596.90\",\"B\":\"6.853\",\"a\":\"79597.00\",\"A\":\"6.268\",\"T\":1788567773264,\"E\":1788567773264,\"st\":1}}"}
{"receive_ns":1788567773365366000,"stream":"btcusdt@depth@100ms","event_type":"depthUpdate","event_time_ms":1788567773307,"raw_json":"{\"stream\":\"btcusdt@depth@100ms\",\"data\":{\"e\":\"depthUpdate\",\"E\":1788567773307,\"T\":1788567773305,\"s\":\"BTCUSDT\",\"ps\":\"BTCUSDT\",\"U\":11478511002466,\"u\":11478511008769,\"pu\":11478511002338,\"b\":[[\"29096.90\",\"0.133\"],[\"29396.90\",\"0.112\"],[\"29496.90\",\"1.855\"],[\"71637.20\",\"0.002\"],[\"78401.60\",\"1.185\"],[\"78800.90\",\"11.621\"],[\"79198.90\",\"3.971\"],[\"79575.10\",\"0.072\"],[\"79575.50\",\"2.252\"],[\"79576.50\",\"0.373\"],[\"79577.70\",\"0.000\"],[\"79586.10\",\"1.637\"],[\"79586.20\",\"0.010\"],[\"79586.90\",\"0.021\"],[\"79587.00\",\"0.005\"],[\"79589.70\",\"0.009\"],[\"79590.90\",\"0.072\"],[\"79591.10\",\"0.005\"],[\"79591.50\",\"0.000\"],[\"79592.80\",\"0.581\"],[\"79593.00\",\"0.055\"],[\"79593.30\",\"0.000\"],[\"79596.90\",\"6.853\"]],\"a\":[[\"79597.10\",\"0.775\"],[\"79597.80\",\"0.005\"],[\"79597.90\",\"0.002\"],[\"79598.00\",\"0.107\"],[\"79598.10\",\"0.000\"],[\"79598.30\",\"0.028\"],[\"79598.60\",\"0.253\"],[\"79598.70\",\"0.004\"],[\"79598.80\",\"0.003\"],[\"79598.90\",\"0.027\"],[\"79599.30\",\"0.044\"],[\"79600.60\",\"0.000\"],[\"79600.70\",\"0.004\"],[\"79600.80\",\"0.008\"],[\"79610.70\",\"0.545\"],[\"79610.90\",\"0.003\"],[\"79612.80\",\"0.003\"],[\"79616.80\",\"0.003\"],[\"79617.60\",\"0.374\"],[\"79629.00\",\"0.304\"],[\"80393.00\",\"14.884\"],[\"80711.40\",\"29.194\"]],\"st\":1}}"}
{"receive_ns":1788567773378847000,"stream":"btcusdt@bookTicker","event_type":"bookTicker","event_time_ms":1788567773316,"raw_json":"{\"stream\":\"btcusdt@bookTicker\",\"data\":{\"e\":\"bookTicker\",\"u\":11478511009880,\"s\":\"BTCUSDT\",\"ps\":\"BTCUSDT\",\"b\":\"79596.90\",\"B\":\"6.853\",\"a\":\"79597.00\",\"A\":\"6.266\",\"T\":1788567773316,\"E\":1788567773316,\"st\":1}}"}
{"receive_ns":1788567773389652000,"stream":"btcusdt@trade","event_type":"trade","event_time_ms":1788567773316,"raw_json":"{\"stream\":\"btcusdt@trade\",\"data\":{\"e\":\"trade\",\"E\":1788567773316,\"T\":1788567773316,\"s\":\"BTCUSDT\",\"t\":8054122824,\"p\":\"79597.00\",\"q\":\"0.002\",\"X\":\"MARKET\",\"m\":false,\"st\":1}}"}
{"receive_ns":1788567773400804000,"stream":"btcusdt@bookTicker","event_type":"bookTicker","event_time_ms":1788567773319,"raw_json":"{\"stream\":\"btcusdt@bookTicker\",\"data\":{\"e\":\"bookTicker\",\"u\":11478511010131,\"s\":\"BTCUSDT\",\"ps\":\"BTCUSDT\",\"b\":\"79596.90\",\"B\":\"6.686\",\"a\":\"79597.00\",\"A\":\"6.266\",\"T\":1788567773318,\"E\":1788567773319,\"st\":1}}"}
{"receive_ns":1788567773411918000,"stream":"btcusdt@bookTicker","event_type":"bookTicker","event_time_ms":1788567773360,"raw_json":"{\"stream\":\"btcusdt@bookTicker\",\"data\":{\"e\":\"bookTicker\",\"u\":11478511012415,\"s\":\"BTCUSDT\",\"ps\":\"BTCUSDT\",\"b\":\"79596.90\",\"B\":\"6.686\",\"a\":\"79597.00\",\"A\":\"7.738\",\"T\":1788567773360,\"E\":1788567773360,\"st\":1}}"}
{"receive_ns":1788567773422912000,"stream":"btcusdt@bookTicker","event_type":"bookTicker","event_time_ms":1788567773367,"raw_json":"{\"stream\":\"btcusdt@bookTicker\",\"data\":{\"e\":\"bookTicker\",\"u\":11478511012859,\"s\":\"BTCUSDT\",\"ps\":\"BTCUSDT\",\"b\":\"79596.90\",\"B\":\"6.853\",\"a\":\"79597.00\",\"A\":\"7.738\",\"T\":1788567773366,\"E\":1788567773367,\"st\":1}}"}
{"receive_ns":1788567773434496000,"stream":"btcusdt@bookTicker","event_type":"bookTicker","event_time_ms":1788567773368,"raw_json":"{\"stream\":\"btcusdt@bookTicker\",\"data\":{\"e\":\"bookTicker\",\"u\":11478511012912,\"s\":\"BTCUSDT\",\"ps\":\"BTCUSDT\",\"b\":\"79596.90\",\"B\":\"6.852\",\"a\":\"79597.00\",\"A\":\"7.738\",\"T\":1788567773367,\"E\":1788567773368,\"st\":1}}"}
{"receive_ns":1788567773440449000,"stream":"btcusdt@bookTicker","event_type":"bookTicker","event_time_ms":1788567773400,"raw_json":"{\"stream\":\"btcusdt@bookTicker\",\"data\":{\"e\":\"bookTicker\",\"u\":11478511014400,\"s\":\"BTCUSDT\",\"ps\":\"BTCUSDT\",\"b\":\"79596.90\",\"B\":\"6.852\",\"a\":\"79597.00\",\"A\":\"7.902\",\"T\":1788567773400,\"E\":1788567773400,\"st\":1}}"}
{"receive_ns":1788567773440772000,"stream":"btcusdt@bookTicker","event_type":"bookTicker","event_time_ms":1788567773401,"raw_json":"{\"stream\":\"btcusdt@bookTicker\",\"data\":{\"e\":\"bookTicker\",\"u\":11478511014536,\"s\":\"BTCUSDT\",\"ps\":\"BTCUSDT\",\"b\":\"79596.90\",\"B\":\"6.853\",\"a\":\"79597.00\",\"A\":\"7.902\",\"T\":1788567773401,\"E\":1788567773401,\"st\":1}}"}
{"receive_ns":1788567773451524000,"stream":"btcusdt@bookTicker","event_type":"bookTicker","event_time_ms":1788567773402,"raw_json":"{\"stream\":\"btcusdt@bookTicker\",\"data\":{\"e\":\"bookTicker\",\"u\":11478511014538,\"s\":\"BTCUSDT\",\"ps\":\"BTCUSDT\",\"b\":\"79596.90\",\"B\":\"6.853\",\"a\":\"79597.00\",\"A\":\"7.901\",\"T\":1788567773401,\"E\":1788567773402,\"st\":1}}"}
{"receive_ns":1788567773462547000,"stream":"btcusdt@bookTicker","event_type":"bookTicker","event_time_ms":1788567773403,"raw_json":"{\"stream\":\"btcusdt@bookTicker\",\"data\":{\"e\":\"bookTicker\",\"u\":11478511014600,\"s\":\"BTCUSDT\",\"ps\":\"BTCUSDT\",\"b\":\"79596.90\",\"B\":\"6.853\",\"a\":\"79597.00\",\"A\":\"7.902\",\"T\":1788567773402,\"E\":1788567773403,\"st\":1}}"}
{"receive_ns":1788567773469023000,"stream":"btcusdt@depth@100ms","event_type":"depthUpdate","event_time_ms":1788567773409,"raw_json":"{\"stream\":\"btcusdt@depth@100ms\",\"data\":{\"e\":\"depthUpdate\",\"E\":1788567773409,\"T\":1788567773408,\"s\":\"BTCUSDT\",\"ps\":\"BTCUSDT\",\"U\":11478511008847,\"u\":11478511014972,\"pu\":11478511008769,\"b\":[[\"1000.00\",\"24.604\"],[\"29096.90\",\"0.021\"],[\"29396.90\",\"0.175\"],[\"29496.90\",\"1.904\"],[\"71637.20\",\"0.002\"],[\"76413.00\",\"0.023\"],[\"78363.10\",\"4.460\"],[\"78442.70\",\"9.140\"],[\"78602.00\",\"11.940\"],[\"78800.90\",\"11.621\"],[\"79537.80\",\"0.003\"],[\"79553.70\",\"0.127\"],[\"79596.90\",\"6.853\"]],\"a\":[[\"79597.00\",\"7.902\"],[\"79598.00\",\"0.081\"],[\"79598.10\",\"0.000\"],[\"79598.20\",\"0.002\"],[\"79598.30\",\"0.028\"],[\"79598.60\",\"0.253\"],[\"79598.70\",\"0.004\"],[\"79601.00\",\"0.319\"],[\"79604.20\",\"0.008\"],[\"79605.60\",\"1.891\"],[\"79612.00\",\"0.003\"],[\"79627.90\",\"0.830\"],[\"79995.00\",\"4.697\"],[\"80233.80\",\"6.841\"],[\"80393.00\",\"14.884\"],[\"80555.10\",\"0.000\"]],\"st\":1}}"}
{"receive_ns":1788567773474498000,"stream":"btcusdt@bookTicker","event_type":"bookTicker","event_time_ms":1788567773450,"raw_json":"{\"stream\":\"btcusdt@bookTicker\",\"data\":{\"e\":\"bookTicker\",\"u\":11478511017202,\"s\":\"BTCUSDT\",\"ps\":\"BTCUSDT\",\"b\":\"79596.90\",\"B\":\"6.853\",\"a\":\"79597.00\",\"A\":\"7.919\",\"T\":1788567773449,\"E\":1788567773450,\"st\":1}}"}
{"receive_ns":1788567773498582000,"stream":"btcusdt@bookTicker","event_type":"bookTicker","event_time_ms":1788567773510,"raw_json":"{\"stream\":\"btcusdt@bookTicker\",\"data\":{\"e\":\"bookTicker\",\"u\":11478511021188,\"s\":\"BTCUSDT\",\"ps\":\"BTCUSDT\",\"b\":\"79596.90\",\"B\":\"6.853\",\"a\":\"79597.00\",\"A\":\"7.920\",\"T\":1788567773509,\"E\":1788567773510,\"st\":1}}"}
{"receive_ns":1788567773516760000,"stream":"btcusdt@depth@100ms","event_type":"depthUpdate","event_time_ms":1788567773511,"raw_json":"{\"stream\":\"btcusdt@depth@100ms\",\"data\":{\"e\":\"depthUpdate\",\"E\":1788567773511,\"T\":1788567773510,\"s\":\"BTCUSDT\",\"ps\":\"BTCUSDT\",\"U\":11478511015093,\"u\":11478511021190,\"pu\":11478511014972,\"b\":[[\"29096.90\",\"0.000\"],[\"29396.90\",\"0.336\"],[\"29496.90\",\"1.764\"],[\"71637.20\",\"0.002\"],[\"71673.00\",\"0.000\"],[\"76413.00\",\"0.025\"],[\"78442.70\",\"9.713\"],[\"78602.00\",\"11.655\"],[\"78800.90\",\"11.621\"],[\"78999.90\",\"4.425\"],[\"79525.20\",\"0.000\"],[\"79541.10\",\"1.098\"],[\"79568.90\",\"0.003\"],[\"79570.00\",\"0.457\"],[\"79595.90\",\"0.038\"],[\"79596.70\",\"0.008\"]],\"a\":[[\"79597.00\",\"7.920\"],[\"79598.00\",\"0.107\"],[\"79598.10\",\"0.000\"],[\"79598.20\",\"0.002\"],[\"79598.30\",\"0.002\"],[\"79619.40\",\"1.251\"],[\"79620.60\",\"0.002\"],[\"79668.70\",\"2.054\"],[\"79692.60\",\"0.002\"],[\"80393.00\",\"14.884\"],[\"80558.30\",\"9.481\"]],\"st\":1}}"}
{"receive_ns":1788567773602738000,"stream":"btcusdt@depth@100ms","event_type":"depthUpdate","event_time_ms":1788567773613,"raw_json":"{\"stream\":\"btcusdt@depth@100ms\",\"data\":{\"e\":\"depthUpdate\",\"E\":1788567773613,\"T\":1788567773612,\"s\":\"BTCUSDT\",\"ps\":\"BTCUSDT\",\"U\":11478511021221,\"u\":11478511026671,\"pu\":11478511021190,\"b\":[[\"1000.00\",\"24.604\"],[\"29396.90\",\"0.511\"],[\"29496.90\",\"1.589\"],[\"63678.00\",\"0.010\"],[\"71637.20\",\"0.002\"],[\"76413.00\",\"0.023\"],[\"78466.60\",\"1.710\"],[\"78800.90\",\"11.621\"],[\"79198.90\",\"3.981\"],[\"79451.30\",\"1.885\"],[\"79477.40\",\"0.000\"],[\"79498.60\",\"0.006\"],[\"79562.30\",\"0.005\"],[\"79573.20\",\"0.538\"],[\"79594.00\",\"0.000\"],[\"79594.10\",\"0.002\"]],\"a\":[[\"79598.00\",\"0.081\"],[\"79598.10\",\"0.026\"],[\"79598.30\",\"0.002\"],[\"79598.40\",\"0.007\"],[\"79598.50\",\"0.000\"],[\"79598.60\",\"0.253\"],[\"79598.70\",\"0.004\"],[\"79598.80\",\"0.003\"],[\"79598.90\",\"0.001\"],[\"79600.60\",\"0.026\"],[\"79613.10\",\"0.194\"],[\"79719.70\",\"1.884\"],[\"80233.80\",\"7.339\"],[\"80393.00\",\"14.886\"]],\"st\":1}}"}
{"receive_ns":1788567773702272000,"stream":"btcusdt@depth@100ms","event_type":"depthUpdate","event_time_ms":1788567773715,"raw_json":"{\"stream\":\"btcusdt@depth@100ms\",\"data\":{\"e\":\"depthUpdate\",\"E\":1788567773715,\"T\":1788567773713,\"s\":\"BTCUSDT\",\"ps\":\"BTCUSDT\",\"U\":11478511026698,\"u\":11478511031207,\"pu\":11478511026671,\"b\":[[\"1000.00\",\"24.604\"],[\"29396.90\",\"0.693\"],[\"29496.90\",\"1.407\"],[\"63678.00\",\"0.008\"],[\"71637.20\",\"0.002\"],[\"76413.00\",\"0.025\"],[\"78800.90\",\"11.621\"],[\"79586.20\",\"0.002\"],[\"79589.70\",\"0.017\"]],\"a\":[[\"79598.10\",\"0.000\"],[\"79598.20\",\"0.002\"],[\"79598.30\",\"0.002\"],[\"79598.60\",\"0.253\"],[\"79599.30\",\"0.018\"],[\"79599.40\",\"0.026\"],[\"79600.70\",\"0.030\"],[\"79606.10\",\"0.000\"],[\"79606.80\",\"0.506\"],[\"79995.00\",\"4.696\"],[\"80393.00\",\"14.884\"],[\"80552.20\",\"29.478\"],[\"80757.40\",\"5.454\"],[\"81825.80\",\"0.731\"]],\"st\":1}}"}
{"receive_ns":1788567773807070000,"stream":"btcusdt@depth@100ms","event_type":"depthUpdate","event_time_ms":1788567773817,"raw_json":"{\"stream\":\"btcusdt@depth@100ms\",\"data\":{\"e\":\"depthUpdate\",\"E\":1788567773817,\"T\":1788567773816,\"s\":\"BTCUSDT\",\"ps\":\"BTCUSDT\",\"U\":11478511031296,\"u\":11478511035690,\"pu\":11478511031207,\"b\":[[\"29396.90\",\"0.868\"],[\"29496.90\",\"1.232\"],[\"71637.20\",\"0.002\"],[\"78800.90\",\"11.621\"],[\"79198.90\",\"3.981\"],[\"79412.70\",\"0.003\"],[\"79414.80\",\"0.506\"],[\"79417.90\",\"3.337\"],[\"79508.80\",\"0.611\"],[\"79509.00\",\"0.048\"]],\"a\":[[\"79599.10\",\"0.104\"],[\"79599.20\",\"0.000\"],[\"79684.00\",\"0.104\"],[\"79684.20\",\"0.046\"],[\"79739.40\",\"3.141\"],[\"79740.20\",\"0.002\"],[\"80393.00\",\"14.884\"],[\"80631.80\",\"4.821\"],[\"81188.90\",\"0.043\"]],\"st\":1}}"}
{"receive_ns":1788567773812795000,"stream":"btcusdt@bookTicker","event_type":"bookTicker","event_time_ms":1788567773821,"raw_json":"{\"stream\":\"btcusdt@bookTicker\",\"data\":{\"e\":\"bookTicker\",\"u\":11478511035968,\"s\":\"BTCUSDT\",\"ps\":\"BTCUSDT\",\"b\":\"79596.90\",\"B\":\"6.853\",\"a\":\"79597.00\",\"A\":\"7.940\",\"T\":1788567773820,\"E\":1788567773821,\"st\":1}}"}
{"receive_ns":1788567773824258000,"stream":"btcusdt@bookTicker","event_type":"bookTicker","event_time_ms":1788567773834,"raw_json":"{\"stream\":\"btcusdt@bookTicker\",\"data\":{\"e\":\"bookTicker\",\"u\":11478511036799,\"s\":\"BTCUSDT\",\"ps\":\"BTCUSDT\",\"b\":\"79596.90\",\"B\":\"6.853\",\"a\":\"79597.00\",\"A\":\"7.939\",\"T\":1788567773834,\"E\":1788567773834,\"st\":1}}"}
{"receive_ns":1788567773836768000,"stream":"btcusdt@bookTicker","event_type":"bookTicker","event_time_ms":1788567773840,"raw_json":"{\"stream\":\"btcusdt@bookTicker\",\"data\":{\"e\":\"bookTicker\",\"u\":11478511037405,\"s\":\"BTCUSDT\",\"ps\":\"BTCUSDT\",\"b\":\"79596.90\",\"B\":\"6.853\",\"a\":\"79597.00\",\"A\":\"7.941\",\"T\":1788567773840,\"E\":1788567773840,\"st\":1}}"}
{"receive_ns":1788567773910019000,"stream":"btcusdt@depth@100ms","event_type":"depthUpdate","event_time_ms":1788567773919,"raw_json":"{\"stream\":\"btcusdt@depth@100ms\",\"data\":{\"e\":\"depthUpdate\",\"E\":1788567773919,\"T\":1788567773918,\"s\":\"BTCUSDT\",\"ps\":\"BTCUSDT\",\"U\":11478511035717,\"u\":11478511040437,\"pu\":11478511035690,\"b\":[[\"1000.00\",\"24.604\"],[\"29396.90\",\"1.050\"],[\"29496.90\",\"1.050\"],[\"63678.00\",\"0.008\"],[\"71637.20\",\"0.002\"],[\"76413.00\",\"0.023\"],[\"76413.20\",\"0.000\"],[\"78553.90\",\"0.300\"],[\"78800.90\",\"11.621\"],[\"79198.90\",\"3.981\"],[\"79562.30\",\"0.001\"],[\"79564.50\",\"0.017\"],[\"79565.20\",\"2.602\"],[\"79576.80\",\"0.334\"],[\"79585.00\",\"0.097\"],[\"79586.10\",\"0.001\"],[\"79586.20\",\"0.002\"],[\"79589.60\",\"0.942\"],[\"79589.70\",\"1.374\"],[\"79594.30\",\"0.140\"]],\"a\":[[\"79597.00\",\"7.941\"],[\"79599.00\",\"0.002\"],[\"79599.10\",\"0.078\"],[\"79599.20\",\"0.000\"],[\"79599.40\",\"0.000\"],[\"79599.60\",\"0.000\"],[\"79599.70\",\"0.000\"],[\"79819.00\",\"7.090\"],[\"79995.00\",\"4.697\"],[\"80393.00\",\"14.884\"],[\"80552.20\",\"29.973\"],[\"80711.40\",\"30.183\"],[\"81825.70\",\"1.221\"]],\"st\":1}}"}
{"receive_ns":1788567773982213000,"stream":"btcusdt@bookTicker","event_type":"bookTicker","event_time_ms":1788567773990,"raw_json":"{\"stream\":\"btcusdt@bookTicker\",\"data\":{\"e\":\"bookTicker\",\"u\":11478511043660,\"s\":\"BTCUSDT\",\"ps\":\"BTCUSDT\",\"b\":\"79596.90\",\"B\":\"6.853\",\"a\":\"79597.00\",\"A\":\"7.942\",\"T\":1788567773990,\"E\":1788567773990,\"st\":1}}"}
{"receive_ns":1788567774010663000,"stream":"btcusdt@bookTicker","event_type":"bookTicker","event_time_ms":1788567774020,"raw_json":"{\"stream\":\"btcusdt@bookTicker\",\"data\":{\"e\":\"bookTicker\",\"u\":11478511046345,\"s\":\"BTCUSDT\",\"ps\":\"BTCUSDT\",\"b\":\"79596.90\",\"B\":\"6.847\",\"a\":\"79597.00\",\"A\":\"7.942\",\"T\":1788567774020,\"E\":1788567774020,\"st\":1}}"}
{"receive_ns":1788567774016554000,"stream":"btcusdt@depth@100ms","event_type":"depthUpdate","event_time_ms":1788567774021,"raw_json":"{\"stream\":\"btcusdt@depth@100ms\",\"data\":{\"e\":\"depthUpdate\",\"E\":1788567774021,\"T\":1788567774020,\"s\":\"BTCUSDT\",\"ps\":\"BTCUSDT\",\"U\":11478511040459,\"u\":11478511046345,\"pu\":11478511040437,\"b\":[[\"1000.00\",\"24.604\"],[\"29396.90\",\"1.225\"],[\"29496.90\",\"0.875\"],[\"63677.50\",\"0.000\"],[\"63678.00\",\"0.008\"],[\"71637.20\",\"0.002\"],[\"76413.00\",\"0.025\"],[\"77368.20\",\"1.810\"],[\"78562.20\",\"15.575\"],[\"78575.80\",\"0.002\"],[\"78580.50\",\"0.005\"],[\"78595.40\",\"0.000\"],[\"78597.70\",\"0.005\"],[\"78602.00\",\"11.439\"],[\"78610.30\",\"0.000\"],[\"78614.90\",\"0.003\"],[\"78800.90\",\"11.621\"],[\"79565.20\",\"2.477\"],[\"79594.10\",\"0.002\"],[\"79594.30\",\"0.064\"],[\"79596.70\",\"0.016\"],[\"79596.90\",\"6.847\"]],\"a\":[[\"79597.00\",\"7.942\"],[\"79599.10\",\"0.078\"],[\"79599.40\",\"0.000\"],[\"79599.50\",\"0.003\"],[\"79599.60\",\"0.000\"],[\"80393.00\",\"14.884\"],[\"80751.20\",\"11.594\"]],\"st\":1}}"}
{"receive_ns":1788567774027983000,"stream":"btcusdt@bookTicker","event_type":"bookTicker","event_time_ms":1788567774023,"raw_json":"{\"stream\":\"btcusdt@bookTicker\",\"data\":{\"e\":\"bookTicker\",\"u\":11478511046731,\"s\":\"BTCUSDT\",\"ps\":\"BTCUSDT\",\"b\":\"79596.90\",\"B\":\"6.854\",\"a\":\"79597.00\",\"A\":\"7.942\",\"T\":1788567774023,\"E\":1788567774023,\"st\":1}}"}
{"receive_ns":1788567774047782000,"stream":"btcusdt@bookTicker","event_type":"bookTicker","event_time_ms":1788567774057,"raw_json":"{\"stream\":\"btcusdt@bookTicker\",\"data\":{\"e\":\"bookTicker\",\"u\":11478511049615,\"s\":\"BTCUSDT\",\"ps\":\"BTCUSDT\",\"b\":\"79596.90\",\"B\":\"6.854\",\"a\":\"79597.00\",\"A\":\"7.941\",\"T\":1788567774057,\"E\":1788567774057,\"st\":1}}"}
{"receive_ns":1788567774048875000,"stream":"btcusdt@bookTicker","event_type":"bookTicker","event_time_ms":1788567774057,"raw_json":"{\"stream\":\"btcusdt@bookTicker\",\"data\":{\"e\":\"bookTicker\",\"u\":11478511049617,\"s\":\"BTCUSDT\",\"ps\":\"BTCUSDT\",\"b\":\"79596.90\",\"B\":\"6.854\",\"a\":\"79597.00\",\"A\":\"7.777\",\"T\":1788567774057,\"E\":1788567774057,\"st\":1}}"}
{"receive_ns":1788567774049101000,"stream":"btcusdt@bookTicker","event_type":"bookTicker","event_time_ms":1788567774057,"raw_json":"{\"stream\":\"btcusdt@bookTicker\",\"data\":{\"e\":\"bookTicker\",\"u\":11478511049620,\"s\":\"BTCUSDT\",\"ps\":\"BTCUSDT\",\"b\":\"79596.90\",\"B\":\"6.854\",\"a\":\"79597.00\",\"A\":\"6.305\",\"T\":1788567774057,\"E\":1788567774057,\"st\":1}}"}
{"receive_ns":1788567774049287000,"stream":"btcusdt@bookTicker","event_type":"bookTicker","event_time_ms":1788567774057,"raw_json":"{\"stream\":\"btcusdt@bookTicker\",\"data\":{\"e\":\"bookTicker\",\"u\":11478511049624,\"s\":\"BTCUSDT\",\"ps\":\"BTCUSDT\",\"b\":\"79596.90\",\"B\":\"6.854\",\"a\":\"79597.00\",\"A\":\"6.288\",\"T\":1788567774057,\"E\":1788567774057,\"st\":1}}"}
{"receive_ns":1788567774060818000,"stream":"btcusdt@bookTicker","event_type":"bookTicker","event_time_ms":1788567774061,"raw_json":"{\"stream\":\"btcusdt@bookTicker\",\"data\":{\"e\":\"bookTicker\",\"u\":11478511049943,\"s\":\"BTCUSDT\",\"ps\":\"BTCUSDT\",\"b\":\"79596.90\",\"B\":\"6.854\",\"a\":\"79597.00\",\"A\":\"6.286\",\"T\":1788567774061,\"E\":1788567774061,\"st\":1}}"}
{"receive_ns":1788567774073827000,"stream":"btcusdt@bookTicker","event_type":"bookTicker","event_time_ms":1788567774062,"raw_json":"{\"stream\":\"btcusdt@bookTicker\",\"data\":{\"e\":\"bookTicker\",\"u\":11478511049991,\"s\":\"BTCUSDT\",\"ps\":\"BTCUSDT\",\"b\":\"79596.90\",\"B\":\"6.854\",\"a\":\"79597.00\",\"A\":\"6.285\",\"T\":1788567774062,\"E\":1788567774062,\"st\":1}}"}
{"receive_ns":1788567774085131000,"stream":"btcusdt@bookTicker","event_type":"bookTicker","event_time_ms":1788567774091,"raw_json":"{\"stream\":\"btcusdt@bookTicker\",\"data\":{\"e\":\"bookTicker\",\"u\":11478511052168,\"s\":\"BTCUSDT\",\"ps\":\"BTCUSDT\",\"b\":\"79596.90\",\"B\":\"6.855\",\"a\":\"79597.00\",\"A\":\"6.285\",\"T\":1788567774091,\"E\":1788567774091,\"st\":1}}"}
{"receive_ns":1788567774109572000,"stream":"btcusdt@depth@100ms","event_type":"depthUpdate","event_time_ms":1788567774123,"raw_json":"{\"stream\":\"btcusdt@depth@100ms\",\"data\":{\"e\":\"depthUpdate\",\"E\":1788567774123,\"T\":1788567774121,\"s\":\"BTCUSDT\",\"ps\":\"BTCUSDT\",\"U\":11478511046470,\"u\":11478511053776,\"pu\":11478511046345,\"b\":[[\"29396.90\",\"1.407\"],[\"29496.90\",\"0.693\"],[\"63678.00\",\"0.008\"],[\"71637.20\",\"0.002\"],[\"76413.00\",\"0.023\"],[\"77989.50\",\"0.000\"],[\"78005.00\",\"0.222\"],[\"78601.90\",\"7.728\"],[\"78800.90\",\"11.621\"],[\"79565.70\",\"0.210\"],[\"79566.00\",\"0.033\"],[\"79582.60\",\"0.070\"],[\"79587.00\",\"0.004\"],[\"79590.90\",\"0.070\"],[\"79591.10\",\"0.003\"],[\"79591.80\",\"0.004\"],[\"79594.00\",\"0.076\"],[\"79594.10\",\"0.002\"],[\"79594.20\",\"0.252\"],[\"79596.90\",\"6.855\"]],\"a\":[[\"79597.00\",\"6.285\"],[\"79599.00\",\"0.002\"],[\"79599.10\",\"0.078\"],[\"79599.20\",\"0.000\"],[\"79599.40\",\"0.026\"],[\"79599.50\",\"0.003\"],[\"79601.00\",\"0.317\"],[\"79604.20\",\"0.007\"],[\"79605.60\",\"1.892\"],[\"79617.20\",\"0.000\"],[\"79617.30\",\"0.064\"],[\"79627.90\",\"0.001\"],[\"79806.10\",\"4.791\"],[\"79806.20\",\"0.000\"],[\"80393.00\",\"14.884\"],[\"80922.50\",\"0.000\"]],\"st\":1}}"}
{"receive_ns":1788567774120619000,"stream":"btcusdt@bookTicker","event_type":"bookTicker","event_time_ms":1788567774123,"raw_json":"{\"stream\":\"btcusdt@bookTicker\",\"data\":{\"e\":\"bookTicker\",\"u\":11478511053859,\"s\":\"BTCUSDT\",\"ps\":\"BTCUSDT\",\"b\":\"79596.90\",\"B\":\"6.837\",\"a\":\"79597.00\",\"A\":\"6.285\",\"T\":1788567774123,\"E\":1788567774123,\"st\":1}}"}
{"receive_ns":1788567774131562000,"stream":"btcusdt@bookTicker","event_type":"bookTicker","event_time_ms":1788567774126,"raw_json":"{\"stream\":\"btcusdt@bookTicker\",\"data\":{\"e\":\"bookTicker\",\"u\":11478511054011,\"s\":\"BTCUSDT\",\"ps\":\"BTCUSDT\",\"b\":\"79596.90\",\"B\":\"6.854\",\"a\":\"79597.00\",\"A\":\"6.285\",\"T\":1788567774126,\"E\":1788567774126,\"st\":1}}"}
{"receive_ns":1788567774142477000,"stream":"btcusdt@bookTicker","event_type":"bookTicker","event_time_ms":1788567774130,"raw_json":"{\"stream\":\"btcusdt@bookTicker\",\"data\":{\"e\":\"bookTicker\",\"u\":11478511054186,\"s\":\"BTCUSDT\",\"ps\":\"BTCUSDT\",\"b\":\"79596.90\",\"B\":\"6.842\",\"a\":\"79597.00\",\"A\":\"6.285\",\"T\":1788567774129,\"E\":1788567774130,\"st\":1}}"}
{"receive_ns":1788567774153451000,"stream":"btcusdt@bookTicker","event_type":"bookTicker","event_time_ms":1788567774133,"raw_json":"{\"stream\":\"btcusdt@bookTicker\",\"data\":{\"e\":\"bookTicker\",\"u\":11478511054334,\"s\":\"BTCUSDT\",\"ps\":\"BTCUSDT\",\"b\":\"79596.90\",\"B\":\"6.852\",\"a\":\"79597.00\",\"A\":\"6.285\",\"T\":1788567774132,\"E\":1788567774133,\"st\":1}}"}
{"receive_ns":1788567774166511000,"stream":"btcusdt@bookTicker","event_type":"bookTicker","event_time_ms":1788567774160,"raw_json":"{\"stream\":\"btcusdt@bookTicker\",\"data\":{\"e\":\"bookTicker\",\"u\":11478511055624,\"s\":\"BTCUSDT\",\"ps\":\"BTCUSDT\",\"b\":\"79596.90\",\"B\":\"6.852\",\"a\":\"79597.00\",\"A\":\"7.776\",\"T\":1788567774160,\"E\":1788567774160,\"st\":1}}"}
{"receive_ns":1788567774190396000,"stream":"btcusdt@bookTicker","event_type":"bookTicker","event_time_ms":1788567774181,"raw_json":"{\"stream\":\"btcusdt@bookTicker\",\"data\":{\"e\":\"bookTicker\",\"u\":11478511056594,\"s\":\"BTCUSDT\",\"ps\":\"BTCUSDT\",\"b\":\"79596.90\",\"B\":\"6.851\",\"a\":\"79597.00\",\"A\":\"7.776\",\"T\":1788567774181,\"E\":1788567774181,\"st\":1}}"}
{"receive_ns":1788567774202487000,"stream":"btcusdt@bookTicker","event_type":"bookTicker","event_time_ms":1788567774200,"raw_json":"{\"stream\":\"btcusdt@bookTicker\",\"data\":{\"e\":\"bookTicker\",\"u\":11478511057489,\"s\":\"BTCUSDT\",\"ps\":\"BTCUSDT\",\"b\":\"79596.90\",\"B\":\"6.851\",\"a\":\"79597.00\",\"A\":\"7.925\",\"T\":1788567774200,\"E\":1788567774200,\"st\":1}}"}
{"receive_ns":1788567774214213000,"stream":"btcusdt@depth@100ms","event_type":"depthUpdate","event_time_ms":1788567774225,"raw_json":"{\"stream\":\"btcusdt@depth@100ms\",\"data\":{\"e\":\"depthUpdate\",\"E\":1788567774225,\"T\":1788567774223,\"s\":\"BTCUSDT\",\"ps\":\"BTCUSDT\",\"U\":11478511053842,\"u\":11478511058486,\"pu\":11478511053776,\"b\":[[\"1000.00\",\"24.604\"],[\"29396.90\",\"1.582\"],[\"29496.90\",\"0.518\"],[\"71637.20\",\"0.002\"],[\"75617.10\",\"0.008\"],[\"76413.00\",\"0.025\"],[\"78005.00\",\"0.219\"],[\"78402.90\",\"3.209\"],[\"78800.90\",\"11.621\"],[\"79198.90\",\"3.981\"],[\"79587.00\",\"0.005\"],[\"79588.40\",\"0.003\"],[\"79590.40\",\"0.001\"],[\"79591.50\",\"0.002\"],[\"79591.80\",\"0.002\"],[\"79594.00\",\"0.000\"],[\"79594.10\",\"0.002\"],[\"79596.90\",\"6.851\"]],\"a\":[[\"79597.00\",\"7.925\"],[\"79598.80\",\"0.029\"],[\"79598.90\",\"0.001\"],[\"79599.00\",\"0.002\"],[\"79599.10\",\"0.078\"],[\"79599.20\",\"0.000\"],[\"79599.40\",\"0.000\"],[\"79599.50\",\"0.003\"],[\"79599.60\",\"0.000\"],[\"79599.80\",\"0.001\"],[\"79599.90\",\"0.028\"],[\"79600.80\",\"0.034\"],[\"79600.90\",\"0.028\"],[\"79601.40\",\"0.109\"],[\"79604.20\",\"0.008\"],[\"79605.60\",\"1.891\"],[\"80393.00\",\"14.884\"]],\"st\":1}}"}
{"receive_ns":1788567774250096000,"stream":"btcusdt@bookTicker","event_type":"bookTicker","event_time_ms":1788567774260,"raw_json":"{\"stream\":\"btcusdt@bookTicker\",\"data\":{\"e\":\"bookTicker\",\"u\":11478511059725,\"s\":\"BTCUSDT\",\"ps\":\"BTCUSDT\",\"b\":\"79596.90\",\"B\":\"6.851\",\"a\":\"79597.00\",\"A\":\"7.940\",\"T\":1788567774260,\"E\":1788567774260,\"st\":1}}"}
{"receive_ns":1788567774299234000,"stream":"btcusdt@bookTicker","event_type":"bookTicker","event_time_ms":1788567774310,"raw_json":"{\"stream\":\"btcusdt@bookTicker\",\"data\":{\"e\":\"bookTicker\",\"u\":11478511062263,\"s\":\"BTCUSDT\",\"ps\":\"BTCUSDT\",\"b\":\"79596.90\",\"B\":\"6.851\",\"a\":\"79597.00\",\"A\":\"7.941\",\"T\":1788567774310,\"E\":1788567774310,\"st\":1}}"}
{"receive_ns":1788567774317054000,"stream":"btcusdt@depth@100ms","event_type":"depthUpdate","event_time_ms":1788567774327,"raw_json":"{\"stream\":\"btcusdt@depth@100ms\",\"data\":{\"e\":\"depthUpdate\",\"E\":1788567774327,\"T\":1788567774325,\"s\":\"BTCUSDT\",\"ps\":\"BTCUSDT\",\"U\":11478511058556,\"u\":11478511063023,\"pu\":11478511058486,\"b\":[[\"1000.00\",\"24.604\"],[\"29296.90\",\"0.007\"],[\"29396.90\",\"1.750\"],[\"29496.90\",\"0.343\"],[\"71637.20\",\"0.002\"],[\"77925.40\",\"1.282\"],[\"78005.00\",\"0.222\"],[\"78800.90\",\"11.621\"],[\"79419.50\",\"0.935\"],[\"79534.50\",\"4.480\"],[\"79565.10\",\"0.981\"],[\"79565.70\",\"0.085\"]],\"a\":[[\"79597.00\",\"7.941\"],[\"79598.80\",\"0.029\"],[\"79598.90\",\"0.001\"],[\"79599.80\",\"0.027\"],[\"79600.90\",\"0.002\"],[\"80393.00\",\"14.884\"],[\"80592.00\",\"7.961\"],[\"80657.40\",\"3.161\"],[\"80757.40\",\"4.535\"]],\"st\":1}}"}
{"receive_ns":1788567774421050000,"stream":"btcusdt@bookTicker","event_type":"bookTicker","event_time_ms":1788567774424,"raw_json":"{\"stream\":\"btcusdt@bookTicker\",\"data\":{\"e\":\"bookTicker\",\"u\":11478511067984,\"s\":\"BTCUSDT\",\"ps\":\"BTCUSDT\",\"b\":\"79596.90\",\"B\":\"6.867\",\"a\":\"79597.00\",\"A\":\"7.941\",\"T\":1788567774424,\"E\":1788567774424,\"st\":1}}"}
{"receive_ns":1788567774439985000,"stream":"btcusdt@depth@100ms","event_type":"depthUpdate","event_time_ms":1788567774429,"raw_json":"{\"stream\":\"btcusdt@depth@100ms\",\"data\":{\"e\":\"depthUpdate\",\"E\":1788567774429,\"T\":1788567774428,\"s\":\"BTCUSDT\",\"ps\":\"BTCUSDT\",\"U\":11478511063105,\"u\":11478511068120,\"pu\":11478511063023,\"b\":[[\"29296.90\",\"0.063\"],[\"29396.90\",\"1.813\"],[\"29496.90\",\"0.224\"],[\"71637.20\",\"0.002\"],[\"76413.00\",\"0.023\"],[\"78675.30\",\"0.057\"],[\"78800.90\",\"11.621\"],[\"78846.80\",\"0.506\"],[\"79198.90\",\"3.981\"],[\"79475.60\",\"0.498\"],[\"79554.00\",\"0.751\"],[\"79565.10\",\"0.856\"],[\"79595.90\",\"0.002\"],[\"79596.90\",\"6.867\"]],\"a\":[[\"79598.80\",\"0.003\"],[\"79719.00\",\"0.470\"],[\"79819.00\",\"6.975\"],[\"80393.00\",\"14.884\"],[\"80759.10\",\"0.621\"]],\"st\":1}}"}
{"receive_ns":1788567774449012000,"stream":"btcusdt@bookTicker","event_type":"bookTicker","event_time_ms":1788567774440,"raw_json":"{\"stream\":\"btcusdt@bookTicker\",\"data\":{\"e\":\"bookTicker\",\"u\":11478511069280,\"s\":\"BTCUSDT\",\"ps\":\"BTCUSDT\",\"b\":\"79596.90\",\"B\":\"6.867\",\"a\":\"79597.00\",\"A\":\"7.938\",\"T\":1788567774440,\"E\":1788567774440,\"st\":1}}"}
{"receive_ns":1788567774460072000,"stream":"btcusdt@trade","event_type":"trade","event_time_ms":1788567774440,"raw_json":"{\"stream\":\"btcusdt@trade\",\"data\":{\"e\":\"trade\",\"E\":1788567774440,\"T\":1788567774440,\"s\":\"BTCUSDT\",\"t\":8054122825,\"p\":\"79597.00\",\"q\":\"0.003\",\"X\":\"MARKET\",\"m\":false,\"st\":1}}"}
{"receive_ns":1788567774487502000,"stream":"btcusdt@bookTicker","event_type":"bookTicker","event_time_ms":1788567774490,"raw_json":"{\"stream\":\"btcusdt@bookTicker\",\"data\":{\"e\":\"bookTicker\",\"u\":11478511072194,\"s\":\"BTCUSDT\",\"ps\":\"BTCUSDT\",\"b\":\"79596.90\",\"B\":\"6.867\",\"a\":\"79597.00\",\"A\":\"7.940\",\"T\":1788567774490,\"E\":1788567774490,\"st\":1}}"}
{"receive_ns":1788567774521645000,"stream":"btcusdt@depth@100ms","event_type":"depthUpdate","event_time_ms":1788567774531,"raw_json":"{\"stream\":\"btcusdt@depth@100ms\",\"data\":{\"e\":\"depthUpdate\",\"E\":1788567774531,\"T\":1788567774530,\"s\":\"BTCUSDT\",\"ps\":\"BTCUSDT\",\"U\":11478511068137,\"u\":11478511073961,\"pu\":11478511068120,\"b\":[[\"1000.00\",\"24.604\"],[\"29296.90\",\"0.126\"],[\"29396.90\",\"1.869\"],[\"29496.90\",\"0.105\"],[\"71637.20\",\"0.002\"],[\"76413.00\",\"0.025\"],[\"78511.00\",\"32.208\"],[\"78602.00\",\"11.287\"],[\"78800.90\",\"11.621\"],[\"79538.10\",\"0.829\"],[\"79576.80\",\"0.330\"],[\"79581.90\",\"0.649\"],[\"79585.00\",\"0.101\"],[\"79585.30\",\"0.085\"],[\"79586.10\",\"0.001\"],[\"79590.00\",\"0.094\"],[\"79593.40\",\"0.161\"],[\"79594.00\",\"0.000\"],[\"79594.10\",\"0.078\"],[\"79594.20\",\"0.252\"],[\"79596.70\",\"0.017\"]],\"a\":[[\"79597.00\",\"7.940\"],[\"79598.80\",\"0.003\"],[\"79612.20\",\"0.695\"],[\"79628.10\",\"0.326\"],[\"79628.20\",\"0.841\"],[\"79629.00\",\"0.129\"],[\"80393.00\",\"14.884\"],[\"80631.80\",\"6.679\"]],\"st\":1}}"}
{"receive_ns":1788567774527165000,"stream":"btcusdt@bookTicker","event_type":"bookTicker","event_time_ms":1788567774535,"raw_json":"{\"stream\":\"btcusdt@bookTicker\",\"data\":{\"e\":\"bookTicker\",\"u\":11478511074085,\"s\":\"BTCUSDT\",\"ps\":\"BTCUSDT\",\"b\":\"79596.90\",\"B\":\"6.867\",\"a\":\"79597.00\",\"A\":\"7.939\",\"T\":1788567774535,\"E\":1788567774535,\"st\":1}}"}
{"receive_ns":1788567774533812000,"stream":"btcusdt@trade","event_type":"trade","event_time_ms":1788567774535,"raw_json":"{\"stream\":\"btcusdt@trade\",\"data\":{\"e\":\"trade\",\"E\":1788567774535,\"T\":1788567774535,\"s\":\"BTCUSDT\",\"t\":8054122826,\"p\":\"79597.00\",\"q\":\"0.001\",\"X\":\"MARKET\",\"m\":false,\"st\":1}}"}
{"receive_ns":1788567774618155000,"stream":"btcusdt@depth@100ms","event_type":"depthUpdate","event_time_ms":1788567774633,"raw_json":"{\"stream\":\"btcusdt@depth@100ms\",\"data\":{\"e\":\"depthUpdate\",\"E\":1788567774633,\"T\":1788567774631,\"s\":\"BTCUSDT\",\"ps\":\"BTCUSDT\",\"U\":11478511073983,\"u\":11478511078518,\"pu\":11478511073961,\"b\":[[\"1000.00\",\"24.604\"],[\"29296.90\",\"0.203\"],[\"29396.90\",\"1.890\"],[\"29496.90\",\"0.007\"],[\"63678.00\",\"0.008\"],[\"71637.20\",\"0.002\"],[\"71673.00\",\"0.000\"],[\"76413.00\",\"0.023\"],[\"78560.70\",\"1.592\"],[\"78800.90\",\"11.621\"],[\"78840.70\",\"3.413\"],[\"79475.60\",\"0.498\"],[\"79498.60\",\"0.000\"],[\"79511.30\",\"0.008\"],[\"79553.50\",\"0.859\"],[\"79573.20\",\"0.538\"],[\"79594.00\",\"0.000\"],[\"79594.10\",\"0.002\"],[\"79594.20\",\"0.328\"],[\"79594.30\",\"0.065\"]],\"a\":[[\"79597.00\",\"7.939\"],[\"79613.10\",\"0.194\"],[\"79617.10\",\"0.002\"],[\"79617.20\",\"0.002\"],[\"79663.90\",\"0.048\"],[\"79719.00\",\"0.470\"],[\"79806.10\",\"2.691\"],[\"79819.00\",\"7.028\"],[\"80393.00\",\"14.884\"],[\"87556.70\",\"0.002\"]],\"st\":1}}"}
{"receive_ns":1788567774634055000,"stream":"btcusdt@bookTicker","event_type":"bookTicker","event_time_ms":1788567774650,"raw_json":"{\"stream\":\"btcusdt@bookTicker\",\"data\":{\"e\":\"bookTicker\",\"u\":11478511079283,\"s\":\"BTCUSDT\",\"ps\":\"BTCUSDT\",\"b\":\"79596.90\",\"B\":\"6.860\",\"a\":\"79597.00\",\"A\":\"7.939\",\"T\":1788567774650,\"E\":1788567774650,\"st\":1}}"}
{"receive_ns":1788567774645138000,"stream":"btcusdt@bookTicker","event_type":"bookTicker","event_time_ms":1788567774653,"raw_json":"{\"stream\":\"btcusdt@bookTicker\",\"data\":{\"e\":\"bookTicker\",\"u\":11478511079554,\"s\":\"BTCUSDT\",\"ps\":\"BTCUSDT\",\"b\":\"79596.90\",\"B\":\"6.869\",\"a\":\"79597.00\",\"A\":\"7.939\",\"T\":1788567774653,\"E\":1788567774653,\"st\":1}}"}
{"receive_ns":1788567774665946000,"stream":"btcusdt@bookTicker","event_type":"bookTicker","event_time_ms":1788567774674,"raw_json":"{\"stream\":\"btcusdt@bookTicker\",\"data\":{\"e\":\"bookTicker\",\"u\":11478511080855,\"s\":\"BTCUSDT\",\"ps\":\"BTCUSDT\",\"b\":\"79596.90\",\"B\":\"6.869\",\"a\":\"79597.00\",\"A\":\"7.938\",\"T\":1788567774674,\"E\":1788567774674,\"st\":1}}"}
{"receive_ns":1788567774701933000,"stream":"btcusdt@bookTicker","event_type":"bookTicker","event_time_ms":1788567774711,"raw_json":"{\"stream\":\"btcusdt@bookTicker\",\"data\":{\"e\":\"bookTicker\",\"u\":11478511082317,\"s\":\"BTCUSDT\",\"ps\":\"BTCUSDT\",\"b\":\"79596.90\",\"B\":\"6.869\",\"a\":\"79597.00\",\"A\":\"7.878\",\"T\":1788567774711,\"E\":1788567774711,\"st\":1}}"}
{"receive_ns":1788567774714478000,"stream":"btcusdt@trade","event_type":"trade","event_time_ms":1788567774711,"raw_json":"{\"stream\":\"btcusdt@trade\",\"data\":{\"e\":\"trade\",\"E\":1788567774711,\"T\":1788567774711,\"s\":\"BTCUSDT\",\"t\":8054122827,\"p\":\"79597.00\",\"q\":\"0.060\",\"X\":\"MARKET\",\"m\":false,\"st\":1}}"}
{"receive_ns":1788567774721691000,"stream":"btcusdt@depth@100ms","event_type":"depthUpdate","event_time_ms":1788567774735,"raw_json":"{\"stream\":\"btcusdt@depth@100ms\",\"data\":{\"e\":\"depthUpdate\",\"E\":1788567774735,\"T\":1788567774729,\"s\":\"BTCUSDT\",\"ps\":\"BTCUSDT\",\"U\":11478511078572,\"u\":11478511083093,\"pu\":11478511078518,\"b\":[[\"29296.90\",\"0.371\"],[\"29396.90\",\"1.729\"],[\"29496.90\",\"0.000\"],[\"71637.20\",\"0.002\"],[\"78602.00\",\"11.135\"],[\"78800.90\",\"11.621\"],[\"79198.90\",\"3.981\"],[\"79377.20\",\"0.618\"],[\"79541.10\",\"1.098\"],[\"79553.50\",\"0.860\"],[\"79565.00\",\"0.495\"],[\"79594.10\",\"0.002\"],[\"79594.20\",\"0.328\"],[\"79596.90\",\"6.869\"]],\"a\":[[\"79597.00\",\"7.878\"],[\"79597.10\",\"0.727\"],[\"79598.60\",\"0.001\"],[\"79599.80\",\"0.001\"],[\"79599.90\",\"0.002\"],[\"79663.90\",\"0.049\"],[\"79668.70\",\"2.054\"],[\"79806.10\",\"4.791\"],[\"80194.00\",\"4.549\"],[\"80393.00\",\"14.884\"],[\"80552.20\",\"29.601\"],[\"80592.00\",\"8.239\"],[\"80659.90\",\"2.971\"],[\"87556.70\",\"0.000\"]],\"st\":1}}"}
{"receive_ns":1788567774829850000,"stream":"btcusdt@depth@100ms","event_type":"depthUpdate","event_time_ms":1788567774837,"raw_json":"{\"stream\":\"btcusdt@depth@100ms\",\"data\":{\"e\":\"depthUpdate\",\"E\":1788567774837,\"T\":1788567774835,\"s\":\"BTCUSDT\",\"ps\":\"BTCUSDT\",\"U\":11478511083315,\"u\":11478511086567,\"pu\":11478511083093,\"b\":[[\"1000.00\",\"24.604\"],[\"29296.90\",\"0.553\"],[\"29396.90\",\"1.547\"],[\"71637.20\",\"0.002\"],[\"76413.00\",\"0.025\"],[\"78562.20\",\"15.067\"],[\"78800.90\",\"11.621\"],[\"79198.90\",\"3.980\"],[\"79475.60\",\"0.498\"],[\"79565.00\",\"0.495\"],[\"79585.00\",\"0.109\"],[\"79589.70\",\"1.366\"],[\"79594.00\",\"0.076\"],[\"79594.20\",\"0.252\"]],\"a\":[[\"79601.40\",\"0.107\"],[\"79604.20\",\"0.007\"],[\"79604.70\",\"0.002\"],[\"79610.70\",\"0.545\"],[\"79612.10\",\"0.002\"],[\"79619.40\",\"0.799\"],[\"79620.60\",\"0.454\"],[\"79620.90\",\"0.002\"],[\"79719.00\",\"0.470\"],[\"79994.10\",\"0.517\"],[\"79995.00\",\"2.827\"],[\"80393.00\",\"14.886\"],[\"80961.10\",\"0.000\"]],\"st\":1}}"}
{"receive_ns":1788567774867049000,"stream":"btcusdt@bookTicker","event_type":"bookTicker","event_time_ms":1788567774876,"raw_json":"{\"stream\":\"btcusdt@bookTicker\",\"data\":{\"e\":\"bookTicker\",\"u\":11478511088224,\"s\":\"BTCUSDT\",\"ps\":\"BTCUSDT\",\"b\":\"79596.90\",\"B\":\"6.870\",\"a\":\"79597.00\",\"A\":\"7.878\",\"T\":1788567774875,\"E\":1788567774876,\"st\":1}}"}
{"receive_ns":1788567774922917000,"stream":"btcusdt@bookTicker","event_type":"bookTicker","event_time_ms":1788567774932,"raw_json":"{\"stream\":\"btcusdt@bookTicker\",\"data\":{\"e\":\"bookTicker\",\"u\":11478511091589,\"s\":\"BTCUSDT\",\"ps\":\"BTCUSDT\",\"b\":\"79596.90\",\"B\":\"6.869\",\"a\":\"79597.00\",\"A\":\"7.878\",\"T\":1788567774932,\"E\":1788567774932,\"st\":1}}"}
{"receive_ns":1788567774933552000,"stream":"btcusdt@depth@100ms","event_type":"depthUpdate","event_time_ms":1788567774939,"raw_json":"{\"stream\":\"btcusdt@depth@100ms\",\"data\":{\"e\":\"depthUpdate\",\"E\":1788567774939,\"T\":1788567774937,\"s\":\"BTCUSDT\",\"ps\":\"BTCUSDT\",\"U\":11478511086656,\"u\":11478511091808,\"pu\":11478511086567,\"b\":[[\"1000.00\",\"24.604\"],[\"29296.90\",\"0.735\"],[\"29396.90\",\"1.365\"],[\"63677.50\",\"0.000\"],[\"71637.20\",\"0.002\"],[\"76168.10\",\"0.000\"],[\"76413.00\",\"0.023\"],[\"78560.70\",\"0.957\"],[\"78800.90\",\"11.621\"],[\"79198.90\",\"3.981\"],[\"79564.60\",\"0.126\"],[\"79565.00\",\"0.370\"],[\"79576.80\",\"0.016\"],[\"79585.00\",\"0.039\"],[\"79586.10\",\"1.641\"],[\"79587.00\",\"0.004\"],[\"79589.60\",\"0.941\"],[\"79589.70\",\"0.110\"],[\"79596.90\",\"6.869\"]],\"a\":[[\"79995.00\",\"2.826\"],[\"80393.00\",\"14.884\"],[\"80592.00\",\"8.388\"]],\"st\":1}}"}
{"receive_ns":1788567775030527000,"stream":"btcusdt@depth@100ms","event_type":"depthUpdate","event_time_ms":1788567775041,"raw_json":"{\"stream\":\"btcusdt@depth@100ms\",\"data\":{\"e\":\"depthUpdate\",\"E\":1788567775041,\"T\":1788567775037,\"s\":\"BTCUSDT\",\"ps\":\"BTCUSDT\",\"U\":11478511091867,\"u\":11478511096314,\"pu\":11478511091808,\"b\":[[\"29296.90\",\"0.910\"],[\"29396.90\",\"1.190\"],[\"71637.20\",\"0.002\"],[\"76413.00\",\"0.025\"],[\"78800.90\",\"11.621\"],[\"79198.90\",\"3.981\"],[\"79582.60\",\"0.074\"],[\"79584.50\",\"0.078\"],[\"79585.00\",\"0.035\"],[\"79586.20\",\"0.006\"],[\"79587.00\",\"0.005\"],[\"79591.50\",\"0.004\"],[\"79591.80\",\"0.000\"],[\"79594.00\",\"0.000\"],[\"79596.70\",\"0.009\"]],\"a\":[[\"80393.00\",\"14.884\"],[\"81188.90\",\"0.046\"]],\"st\":1}}"}
{"receive_ns":1788567775135937000,"stream":"btcusdt@depth@100ms","event_type":"depthUpdate","event_time_ms":1788567775143,"raw_json":"{\"stream\":\"btcusdt@depth@100ms\",\"data\":{\"e\":\"depthUpdate\",\"E\":1788567775143,\"T\":1788567775141,\"s\":\"BTCUSDT\",\"ps\":\"BTCUSDT\",\"U\":11478511096496,\"u\":11478511101566,\"pu\":11478511096314,\"b\":[[\"1000.00\",\"24.604\"],[\"29296.90\",\"1.092\"],[\"29396.90\",\"1.008\"],[\"71637.20\",\"0.002\"],[\"76413.00\",\"0.023\"],[\"78403.00\",\"2.781\"],[\"78601.90\",\"7.919\"],[\"78800.90\",\"11.621\"],[\"79487.10\",\"0.109\"],[\"79487.20\",\"0.000\"],[\"79582.60\",\"0.070\"]],\"a\":[[\"79994.10\",\"0.732\"],[\"79995.00\",\"4.697\"],[\"80393.00\",\"14.884\"]],\"st\":1}}"}
{"receive_ns":1788567775146098000,"stream":"btcusdt@bookTicker","event_type":"bookTicker","event_time_ms":1788567775152,"raw_json":"{\"stream\":\"btcusdt@bookTicker\",\"data\":{\"e\":\"bookTicker\",\"u\":11478511102236,\"s\":\"BTCUSDT\",\"ps\":\"BTCUSDT\",\"b\":\"79596.90\",\"B\":\"6.869\",\"a\":\"79597.00\",\"A\":\"7.825\",\"T\":1788567775152,\"E\":1788567775152,\"st\":1}}"}
{"receive_ns":1788567775146439000,"stream":"btcusdt@trade","event_type":"trade","event_time_ms":1788567775152,"raw_json":"{\"stream\":\"btcusdt@trade\",\"data\":{\"e\":\"trade\",\"E\":1788567775152,\"T\":1788567775152,\"s\":\"BTCUSDT\",\"t\":8054122828,\"p\":\"79597.00\",\"q\":\"0.039\",\"X\":\"MARKET\",\"m\":false,\"st\":1}}"}
{"receive_ns":1788567775153010000,"stream":"btcusdt@trade","event_type":"trade","event_time_ms":1788567775152,"raw_json":"{\"stream\":\"btcusdt@trade\",\"data\":{\"e\":\"trade\",\"E\":1788567775152,\"T\":1788567775152,\"s\":\"BTCUSDT\",\"t\":8054122829,\"p\":\"79597.00\",\"q\":\"0.014\",\"X\":\"MARKET\",\"m\":false,\"st\":1}}"}
{"receive_ns":1788567775163643000,"stream":"btcusdt@bookTicker","event_type":"bookTicker","event_time_ms":1788567775153,"raw_json":"{\"stream\":\"btcusdt@bookTicker\",\"data\":{\"e\":\"bookTicker\",\"u\":11478511102287,\"s\":\"BTCUSDT\",\"ps\":\"BTCUSDT\",\"b\":\"79596.90\",\"B\":\"6.869\",\"a\":\"79597.00\",\"A\":\"8.411\",\"T\":1788567775153,\"E\":1788567775153,\"st\":1}}"}
{"receive_ns":1788567775181573000,"stream":"btcusdt@bookTicker","event_type":"bookTicker","event_time_ms":1788567775171,"raw_json":"{\"stream\":\"btcusdt@bookTicker\",\"data\":{\"e\":\"bookTicker\",\"u\":11478511103291,\"s\":\"BTCUSDT\",\"ps\":\"BTCUSDT\",\"b\":\"79596.90\",\"B\":\"6.869\",\"a\":\"79597.00\",\"A\":\"8.453\",\"T\":1788567775171,\"E\":1788567775171,\"st\":1}}"}
{"receive_ns":1788567775212711000,"stream":"btcusdt@bookTicker","event_type":"bookTicker","event_time_ms":1788567775220,"raw_json":"{\"stream\":\"btcusdt@bookTicker\",\"data\":{\"e\":\"bookTicker\",\"u\":11478511105511,\"s\":\"BTCUSDT\",\"ps\":\"BTCUSDT\",\"b\":\"79596.90\",\"B\":\"6.869\",\"a\":\"79597.00\",\"A\":\"8.457\",\"T\":1788567775220,\"E\":1788567775220,\"st\":1}}"}
{"receive_ns":1788567775236040000,"stream":"btcusdt@depth@100ms","event_type":"depthUpdate","event_time_ms":1788567775245,"raw_json":"{\"stream\":\"btcusdt@depth@100ms\",\"data\":{\"e\":\"depthUpdate\",\"E\":1788567775245,\"T\":1788567775242,\"s\":\"BTCUSDT\",\"ps\":\"BTCUSDT\",\"U\":11478511101715,\"u\":11478511106410,\"pu\":11478511101566,\"b\":[[\"1000.00\",\"24.604\"],[\"29296.90\",\"1.267\"],[\"29396.90\",\"0.833\"],[\"63678.00\",\"0.008\"],[\"71637.20\",\"0.002\"],[\"78152.90\",\"0.000\"],[\"78240.40\",\"0.000\"],[\"78562.20\",\"14.813\"],[\"78601.90\",\"8.839\"],[\"78800.90\",\"11.621\"],[\"78899.40\",\"0.000\"],[\"79473.20\",\"0.428\"],[\"79473.30\",\"0.132\"],[\"79525.20\",\"0.002\"],[\"79538.10\",\"0.000\"],[\"79554.00\",\"0.060\"],[\"79594.00\",\"0.000\"],[\"79594.10\",\"0.002\"],[\"79594.30\",\"0.065\"]],\"a\":[[\"79597.00\",\"8.457\"],[\"79598.60\",\"0.253\"],[\"79602.50\",\"0.055\"],[\"79603.70\",\"0.003\"],[\"79603.90\",\"0.076\"],[\"79628.20\",\"0.847\"],[\"79692.60\",\"0.004\"],[\"79724.50\",\"2.564\"],[\"79724.60\",\"0.628\"],[\"80233.80\",\"7.090\"],[\"80393.00\",\"14.884\"],[\"80552.20\",\"32.081\"],[\"87556.70\",\"0.000\"]],\"st\":1}}"}
{"receive_ns":1788567775291205000,"stream":"btcusdt@bookTicker","event_type":"bookTicker","event_time_ms":1788567775286,"raw_json":"{\"stream\":\"btcusdt@bookTicker\",\"data\":{\"e\":\"bookTicker\",\"u\":11478511109069,\"s\":\"BTCUSDT\",\"ps\":\"BTCUSDT\",\"b\":\"79596.90\",\"B\":\"6.869\",\"a\":\"79597.00\",\"A\":\"8.456\",\"T\":1788567775286,\"E\":1788567775286,\"st\":1}}"}
{"receive_ns":1788567775302816000,"stream":"btcusdt@bookTicker","event_type":"bookTicker","event_time_ms":1788567775288,"raw_json":"{\"stream\":\"btcusdt@bookTicker\",\"data\":{\"e\":\"bookTicker\",\"u\":11478511109219,\"s\":\"BTCUSDT\",\"ps\":\"BTCUSDT\",\"b\":\"79596.90\",\"B\":\"6.859\",\"a\":\"79597.00\",\"A\":\"8.456\",\"T\":1788567775288,\"E\":1788567775288,\"st\":1}}"}
{"receive_ns":1788567775318697000,"stream":"btcusdt@bookTicker","event_type":"bookTicker","event_time_ms":1788567775291,"raw_json":"{\"stream\":\"btcusdt@bookTicker\",\"data\":{\"e\":\"bookTicker\",\"u\":11478511109317,\"s\":\"BTCUSDT\",\"ps\":\"BTCUSDT\",\"b\":\"79596.90\",\"B\":\"6.871\",\"a\":\"79597.00\",\"A\":\"8.456\",\"T\":1788567775291,\"E\":1788567775291,\"st\":1}}"}
{"receive_ns":1788567775345574000,"stream":"btcusdt@bookTicker","event_type":"bookTicker","event_time_ms":1788567775342,"raw_json":"{\"stream\":\"btcusdt@bookTicker\",\"data\":{\"e\":\"bookTicker\",\"u\":11478511112181,\"s\":\"BTCUSDT\",\"ps\":\"BTCUSDT\",\"b\":\"79596.90\",\"B\":\"6.871\",\"a\":\"79597.00\",\"A\":\"8.445\",\"T\":1788567775342,\"E\":1788567775342,\"st\":1}}"}
{"receive_ns":1788567775351414000,"stream":"btcusdt@bookTicker","event_type":"bookTicker","event_time_ms":1788567775345,"raw_json":"{\"stream\":\"btcusdt@bookTicker\",\"data\":{\"e\":\"bookTicker\",\"u\":11478511112306,\"s\":\"BTCUSDT\",\"ps\":\"BTCUSDT\",\"b\":\"79596.90\",\"B\":\"6.871\",\"a\":\"79597.00\",\"A\":\"8.460\",\"T\":1788567775345,\"E\":1788567775345,\"st\":1}}"}
{"receive_ns":1788567775357327000,"stream":"btcusdt@depth@100ms","event_type":"depthUpdate","event_time_ms":1788567775347,"raw_json":"{\"stream\":\"btcusdt@depth@100ms\",\"data\":{\"e\":\"depthUpdate\",\"E\":1788567775347,\"T\":1788567775346,\"s\":\"BTCUSDT\",\"ps\":\"BTCUSDT\",\"U\":11478511106552,\"u\":11478511112508,\"pu\":11478511106410,\"b\":[[\"29296.90\",\"1.449\"],[\"29396.90\",\"0.651\"],[\"63678.00\",\"0.010\"],[\"71637.20\",\"0.002\"],[\"76413.00\",\"0.025\"],[\"78448.90\",\"4.608\"],[\"78800.90\",\"11.621\"],[\"78960.10\",\"8.082\"],[\"79198.90\",\"3.981\"],[\"79506.70\",\"0.001\"],[\"79594.00\",\"0.076\"],[\"79596.90\",\"6.871\"]],\"a\":[[\"79597.00\",\"8.460\"],[\"79688.30\",\"0.035\"],[\"79724.50\",\"2.532\"],[\"79724.60\",\"0.660\"],[\"79806.10\",\"2.623\"],[\"80393.00\",\"14.886\"],[\"80717.50\",\"11.886\"],[\"81188.90\",\"0.043\"],[\"87556.70\",\"0.001\"]],\"st\":1}}"}
{"receive_ns":1788567775367987000,"stream":"btcusdt@bookTicker","event_type":"bookTicker","event_time_ms":1788567775380,"raw_json":"{\"stream\":\"btcusdt@bookTicker\",\"data\":{\"e\":\"bookTicker\",\"u\":11478511113933,\"s\":\"BTCUSDT\",\"ps\":\"BTCUSDT\",\"b\":\"79596.90\",\"B\":\"6.871\",\"a\":\"79597.00\",\"A\":\"8.461\",\"T\":1788567775380,\"E\":1788567775380,\"st\":1}}"}
{"receive_ns":1788567775438688000,"stream":"btcusdt@depth@100ms","event_type":"depthUpdate","event_time_ms":1788567775449,"raw_json":"{\"stream\":\"btcusdt@depth@100ms\",\"data\":{\"e\":\"depthUpdate\",\"E\":1788567775449,\"T\":1788567775445,\"s\":\"BTCUSDT\",\"ps\":\"BTCUSDT\",\"U\":11478511112580,\"u\":11478511116833,\"pu\":11478511112508,\"b\":[[\"1000.00\",\"24.604\"],[\"29296.90\",\"1.624\"],[\"29396.90\",\"0.476\"],[\"63678.00\",\"0.010\"],[\"71637.20\",\"0.002\"],[\"75617.10\",\"0.010\"],[\"76413.00\",\"0.023\"],[\"78448.90\",\"3.662\"],[\"78800.90\",\"11.621\"],[\"78838.10\",\"0.545\"],[\"78960.10\",\"8.588\"],[\"79451.30\",\"1.885\"],[\"79506.70\",\"4.390\"],[\"79549.10\",\"0.033\"],[\"79592.80\",\"0.505\"],[\"79594.00\",\"0.000\"],[\"79596.70\",\"0.018\"]],\"a\":[[\"79597.00\",\"8.461\"],[\"79601.30\",\"0.003\"],[\"79632.40\",\"0.001\"],[\"79688.30\",\"3.326\"],[\"79719.70\",\"1.884\"],[\"79806.10\",\"4.812\"],[\"79819.00\",\"6.956\"],[\"80393.00\",\"14.884\"],[\"81825.70\",\"1.465\"],[\"87556.70\",\"0.000\"]],\"st\":1}}"}
{"receive_ns":1788567775449943000,"stream":"btcusdt@bookTicker","event_type":"bookTicker","event_time_ms":1788567775455,"raw_json":"{\"stream\":\"btcusdt@bookTicker\",\"data\":{\"e\":\"bookTicker\",\"u\":11478511117656,\"s\":\"BTCUSDT\",\"ps\":\"BTCUSDT\",\"b\":\"79596.90\",\"B\":\"6.871\",\"a\":\"79597.00\",\"A\":\"8.482\",\"T\":1788567775455,\"E\":1788567775455,\"st\":1}}"}
{"receive_ns":1788567775481200000,"stream":"btcusdt@bookTicker","event_type":"bookTicker","event_time_ms":1788567775490,"raw_json":"{\"stream\":\"btcusdt@bookTicker\",\"data\":{\"e\":\"bookTicker\",\"u\":11478511118970,\"s\":\"BTCUSDT\",\"ps\":\"BTCUSDT\",\"b\":\"79596.90\",\"B\":\"6.871\",\"a\":\"79597.00\",\"A\":\"8.485\",\"T\":1788567775490,\"E\":1788567775490,\"st\":1}}"}
{"receive_ns":1788567775493917000,"stream":"btcusdt@bookTicker","event_type":"bookTicker","event_time_ms":1788567775503,"raw_json":"{\"stream\":\"btcusdt@bookTicker\",\"data\":{\"e\":\"bookTicker\",\"u\":11478511119499,\"s\":\"BTCUSDT\",\"ps\":\"BTCUSDT\",\"b\":\"79596.90\",\"B\":\"6.871\",\"a\":\"79597.00\",\"A\":\"8.497\",\"T\":1788567775503,\"E\":1788567775503,\"st\":1}}"}
{"receive_ns":1788567775528501000,"stream":"btcusdt@bookTicker","event_type":"bookTicker","event_time_ms":1788567775544,"raw_json":"{\"stream\":\"btcusdt@bookTicker\",\"data\":{\"e\":\"bookTicker\",\"u\":11478511121680,\"s\":\"BTCUSDT\",\"ps\":\"BTCUSDT\",\"b\":\"79596.90\",\"B\":\"6.871\",\"a\":\"79597.00\",\"A\":\"8.495\",\"T\":1788567775544,\"E\":1788567775544,\"st\":1}}"}
{"receive_ns":1788567775545514000,"stream":"btcusdt@trade","event_type":"trade","event_time_ms":1788567775544,"raw_json":"{\"stream\":\"btcusdt@trade\",\"data\":{\"e\":\"trade\",\"E\":1788567775544,\"T\":1788567775544,\"s\":\"BTCUSDT\",\"t\":8054122830,\"p\":\"79597.00\",\"q\":\"0.002\",\"X\":\"MARKET\",\"m\":false,\"st\":1}}"}
{"receive_ns":1788567775557143000,"stream":"btcusdt@bookTicker","event_type":"bookTicker","event_time_ms":1788567775550,"raw_json":"{\"stream\":\"btcusdt@bookTicker\",\"data\":{\"e\":\"bookTicker\",\"u\":11478511122463,\"s\":\"BTCUSDT\",\"ps\":\"BTCUSDT\",\"b\":\"79596.90\",\"B\":\"6.871\",\"a\":\"79597.00\",\"A\":\"8.496\",\"T\":1788567775550,\"E\":1788567775550,\"st\":1}}"}
{"receive_ns":1788567775567105000,"stream":"btcusdt@depth@100ms","event_type":"depthUpdate","event_time_ms":1788567775551,"raw_json":"{\"stream\":\"btcusdt@depth@100ms\",\"data\":{\"e\":\"depthUpdate\",\"E\":1788567775551,\"T\":1788567775550,\"s\":\"BTCUSDT\",\"ps\":\"BTCUSDT\",\"U\":11478511117063,\"u\":11478511122463,\"pu\":11478511116833,\"b\":[[\"1000.00\",\"24.604\"],[\"29196.90\",\"0.021\"],[\"29296.90\",\"1.764\"],[\"29396.90\",\"0.315\"],[\"71637.20\",\"0.002\"],[\"75617.10\",\"0.008\"],[\"75617.20\",\"0.008\"],[\"76413.00\",\"0.025\"],[\"78403.00\",\"2.494\"],[\"78800.90\",\"11.621\"],[\"79487.10\",\"0.077\"],[\"79487.20\",\"0.032\"],[\"79537.30\",\"0.830\"],[\"79553.20\",\"0.691\"],[\"79584.50\",\"0.081\"],[\"79592.80\",\"0.581\"]],\"a\":[[\"79597.00\",\"8.496\"],[\"80393.00\",\"14.884\"],[\"81825.70\",\"1.709\"]],\"st\":1}}"}
{"receive_ns":1788567775641689000,"stream":"btcusdt@depth@100ms","event_type":"depthUpdate","event_time_ms":1788567775653,"raw_json":"{\"stream\":\"btcusdt@depth@100ms\",\"data\":{\"e\":\"depthUpdate\",\"E\":1788567775653,\"T\":1788567775649,\"s\":\"BTCUSDT\",\"ps\":\"BTCUSDT\",\"U\":11478511122529,\"u\":11478511127960,\"pu\":11478511122463,\"b\":[[\"29196.90\",\"0.077\"],[\"29296.90\",\"1.827\"],[\"29396.90\",\"0.196\"],[\"63678.00\",\"0.010\"],[\"71637.20\",\"0.002\"],[\"75617.10\",\"0.012\"],[\"75617.20\",\"0.006\"],[\"76413.00\",\"0.023\"],[\"78442.70\",\"10.604\"],[\"78551.00\",\"0.223\"],[\"78687.70\",\"3.272\"],[\"78800.90\",\"11.621\"],[\"79198.90\",\"3.971\"],[\"79511.30\",\"0.002\"],[\"79523.40\",\"0.013\"],[\"79573.20\",\"0.538\"]],\"a\":[[\"79613.10\",\"0.194\"],[\"80393.00\",\"14.884\"],[\"80659.90\",\"2.352\"]],\"st\":1}}"}
{"receive_ns":1788567775743734000,"stream":"btcusdt@depth@100ms","event_type":"depthUpdate","event_time_ms":1788567775755,"raw_json":"{\"stream\":\"btcusdt@depth@100ms\",\"data\":{\"e\":\"depthUpdate\",\"E\":1788567775755,\"T\":1788567775754,\"s\":\"BTCUSDT\",\"ps\":\"BTCUSDT\",\"U\":11478511128081,\"u\":11478511134954,\"pu\":11478511127960,\"b\":[[\"1000.00\",\"24.604\"],[\"29196.90\",\"0.140\"],[\"29296.90\",\"1.883\"],[\"29396.90\",\"0.077\"],[\"63678.00\",\"0.010\"],[\"71637.20\",\"0.002\"],[\"71673.00\",\"0.000\"],[\"75617.10\",\"0.010\"],[\"75617.20\",\"0.008\"],[\"78562.10\",\"7.595\"],[\"78800.90\",\"11.621\"],[\"79479.30\",\"0.000\"],[\"79593.90\",\"0.076\"]],\"a\":[[\"79676.60\",\"0.020\"],[\"80393.00\",\"14.884\"]],\"st\":1}}"}
{"receive_ns":1788567775757513000,"stream":"btcusdt@bookTicker","event_type":"bookTicker","event_time_ms":1788567775773,"raw_json":"{\"stream\":\"btcusdt@bookTicker\",\"data\":{\"e\":\"bookTicker\",\"u\":11478511135846,\"s\":\"BTCUSDT\",\"ps\":\"BTCUSDT\",\"b\":\"79596.90\",\"B\":\"6.871\",\"a\":\"79597.00\",\"A\":\"8.471\",\"T\":1788567775773,\"E\":1788567775773,\"st\":1}}"}
{"receive_ns":1788567775769112000,"stream":"btcusdt@trade","event_type":"trade","event_time_ms":1788567775773,"raw_json":"{\"stream\":\"btcusdt@trade\",\"data\":{\"e\":\"trade\",\"E\":1788567775773,\"T\":1788567775773,\"s\":\"BTCUSDT\",\"t\":8054122831,\"p\":\"79597.00\",\"q\":\"0.025\",\"X\":\"MARKET\",\"m\":false,\"st\":1}}"}
{"receive_ns":1788567775828439000,"stream":"btcusdt@bookTicker","event_type":"bookTicker","event_time_ms":1788567775837,"raw_json":"{\"stream\":\"btcusdt@bookTicker\",\"data\":{\"e\":\"bookTicker\",\"u\":11478511139971,\"s\":\"BTCUSDT\",\"ps\":\"BTCUSDT\",\"b\":\"79596.90\",\"B\":\"6.854\",\"a\":\"79597.00\",\"A\":\"8.471\",\"T\":1788567775837,\"E\":1788567775837,\"st\":1}}"}
{"receive_ns":1788567775840459000,"stream":"btcusdt@bookTicker","event_type":"bookTicker","event_time_ms":1788567775840,"raw_json":"{\"stream\":\"btcusdt@bookTicker\",\"data\":{\"e\":\"bookTicker\",\"u\":11478511140148,\"s\":\"BTCUSDT\",\"ps\":\"BTCUSDT\",\"b\":\"79596.90\",\"B\":\"6.867\",\"a\":\"79597.00\",\"A\":\"8.471\",\"T\":1788567775840,\"E\":1788567775840,\"st\":1}}"}
{"receive_ns":1788567775858278000,"stream":"btcusdt@depth@100ms","event_type":"depthUpdate","event_time_ms":1788567775857,"raw_json":"{\"stream\":\"btcusdt@depth@100ms\",\"data\":{\"e\":\"depthUpdate\",\"E\":1788567775857,\"T\":1788567775855,\"s\":\"BTCUSDT\",\"ps\":\"BTCUSDT\",\"U\":11478511134984,\"u\":11478511141059,\"pu\":11478511134954,\"b\":[[\"1000.00\",\"24.604\"],[\"29196.90\",\"0.238\"],[\"29296.90\",\"1.862\"],[\"29396.90\",\"0.000\"],[\"71202.30\",\"0.019\"],[\"71637.20\",\"0.002\"],[\"76413.00\",\"0.025\"],[\"78447.50\",\"2.838\"],[\"78601.90\",\"9.055\"],[\"78800.90\",\"11.621\"],[\"79198.90\",\"3.972\"],[\"79453.20\",\"0.000\"],[\"79454.60\",\"2.861\"],[\"79506.70\",\"0.001\"],[\"79582.90\",\"0.275\"],[\"79596.90\",\"6.867\"]],\"a\":[[\"79597.00\",\"8.471\"],[\"79602.20\",\"0.001\"],[\"79688.30\",\"0.035\"],[\"79740.40\",\"0.751\"],[\"79741.80\",\"0.000\"],[\"79804.90\",\"0.635\"],[\"79806.10\",\"1.610\"],[\"79995.00\",\"4.696\"],[\"80194.00\",\"3.926\"],[\"80233.80\",\"6.344\"],[\"80393.00\",\"14.884\"],[\"80757.40\",\"3.616\"],[\"80934.20\",\"1.972\"]],\"st\":1}}"}
{"receive_ns":1788567775910422000,"stream":"btcusdt@bookTicker","event_type":"bookTicker","event_time_ms":1788567775923,"raw_json":"{\"stream\":\"btcusdt@bookTicker\",\"data\":{\"e\":\"bookTicker\",\"u\":11478511144872,\"s\":\"BTCUSDT\",\"ps\":\"BTCUSDT\",\"b\":\"79596.90\",\"B\":\"6.858\",\"a\":\"79597.00\",\"A\":\"8.471\",\"T\":1788567775923,\"E\":1788567775923,\"st\":1}}"}
{"receive_ns":1788567775922506000,"stream":"btcusdt@bookTicker","event_type":"bookTicker","event_time_ms":1788567775926,"raw_json":"{\"stream\":\"btcusdt@bookTicker\",\"data\":{\"e\":\"bookTicker\",\"u\":11478511145002,\"s\":\"BTCUSDT\",\"ps\":\"BTCUSDT\",\"b\":\"79596.90\",\"B\":\"6.874\",\"a\":\"79597.00\",\"A\":\"8.471\",\"T\":1788567775926,\"E\":1788567775926,\"st\":1}}"}
{"receive_ns":1788567775951795000,"stream":"btcusdt@depth@100ms","event_type":"depthUpdate","event_time_ms":1788567775959,"raw_json":"{\"stream\":\"btcusdt@depth@100ms\",\"data\":{\"e\":\"depthUpdate\",\"E\":1788567775959,\"T\":1788567775957,\"s\":\"BTCUSDT\",\"ps\":\"BTCUSDT\",\"U\":11478511141144,\"u\":11478511146276,\"pu\":11478511141059,\"b\":[[\"29196.90\",\"0.420\"],[\"29296.90\",\"1.680\"],[\"63677.50\",\"0.000\"],[\"71202.30\",\"0.000\"],[\"71637.20\",\"0.002\"],[\"76413.00\",\"0.023\"],[\"78800.90\",\"11.621\"],[\"79198.90\",\"3.981\"],[\"79453.20\",\"17.620\"],[\"79454.60\",\"5.135\"],[\"79506.70\",\"4.390\"],[\"79596.90\",\"6.874\"]],\"a\":[[\"79688.30\",\"3.329\"],[\"79740.40\",\"3.106\"],[\"79741.80\",\"17.557\"],[\"79804.90\",\"1.033\"],[\"79806.10\",\"4.812\"],[\"79819.00\",\"6.954\"],[\"80393.00\",\"14.884\"],[\"80671.60\",\"4.168\"],[\"80717.60\",\"12.944\"]],\"st\":1}}"}
{"receive_ns":1788567776051663000,"stream":"btcusdt@depth@100ms","event_type":"depthUpdate","event_time_ms":1788567776061,"raw_json":"{\"stream\":\"btcusdt@depth@100ms\",\"data\":{\"e\":\"depthUpdate\",\"E\":1788567776061,\"T\":1788567776058,\"s\":\"BTCUSDT\",\"ps\":\"BTCUSDT\",\"U\":11478511146357,\"u\":11478511150401,\"pu\":11478511146276,\"b\":[[\"1000.00\",\"24.604\"],[\"29196.90\",\"0.595\"],[\"29296.90\",\"1.505\"],[\"63678.00\",\"0.010\"],[\"71637.20\",\"0.002\"],[\"76413.00\",\"0.025\"],[\"78442.70\",\"11.495\"],[\"78647.90\",\"16.389\"],[\"78800.90\",\"11.621\"],[\"78999.90\",\"3.793\"],[\"79501.30\",\"0.002\"],[\"79525.20\",\"0.000\"],[\"79541.10\",\"1.096\"],[\"79582.60\",\"0.070\"]],\"a\":[[\"79665.40\",\"1.810\"],[\"79666.10\",\"0.015\"],[\"79668.70\",\"2.054\"],[\"79676.20\",\"4.741\"],[\"79676.90\",\"22.061\"],[\"79692.60\",\"0.002\"],[\"80393.00\",\"14.884\"],[\"80751.20\",\"12.521\"],[\"81188.90\",\"0.040\"]],\"st\":1}}"}
{"receive_ns":1788567776156946000,"stream":"btcusdt@depth@100ms","event_type":"depthUpdate","event_time_ms":1788567776163,"raw_json":"{\"stream\":\"btcusdt@depth@100ms\",\"data\":{\"e\":\"depthUpdate\",\"E\":1788567776163,\"T\":1788567776158,\"s\":\"BTCUSDT\",\"ps\":\"BTCUSDT\",\"U\":11478511150610,\"u\":11478511154968,\"pu\":11478511150401,\"b\":[[\"1000.00\",\"24.604\"],[\"29196.90\",\"0.770\"],[\"29296.90\",\"1.330\"],[\"63678.00\",\"0.010\"],[\"71637.20\",\"0.002\"],[\"78800.90\",\"11.621\"]],\"a\":[[\"79666.20\",\"21.949\"],[\"79676.20\",\"1.487\"],[\"79676.90\",\"0.102\"],[\"80233.80\",\"7.090\"],[\"80393.00\",\"14.884\"],[\"81825.80\",\"0.487\"]],\"st\":1}}"}
{"receive_ns":1788567776259009000,"stream":"btcusdt@depth@100ms","event_type":"depthUpdate","event_time_ms":1788567776265,"raw_json":"{\"stream\":\"btcusdt@depth@100ms\",\"data\":{\"e\":\"depthUpdate\",\"E\":1788567776265,\"T\":1788567776261,\"s\":\"BTCUSDT\",\"ps\":\"BTCUSDT\",\"U\":11478511155184,\"u\":11478511159888,\"pu\":11478511154968,\"b\":[[\"29196.90\",\"0.952\"],[\"29296.90\",\"1.148\"],[\"71637.20\",\"0.002\"],[\"75617.20\",\"0.006\"],[\"76413.00\",\"0.023\"],[\"78403.00\",\"2.207\"],[\"78432.90\",\"0.001\"],[\"78522.30\",\"6.803\"],[\"78580.50\",\"0.001\"],[\"78585.20\",\"1.887\"],[\"78597.70\",\"0.000\"],[\"78602.30\",\"0.004\"],[\"78614.90\",\"0.000\"],[\"78619.40\",\"0.002\"],[\"78800.90\",\"11.621\"],[\"78807.10\",\"3.104\"],[\"79198.90\",\"3.981\"],[\"79568.90\",\"0.455\"],[\"79570.00\",\"0.005\"],[\"79575.40\",\"0.392\"],[\"79576.50\",\"0.000\"],[\"79576.80\",\"0.334\"],[\"79583.40\",\"0.241\"],[\"79583.50\",\"0.000\"],[\"79585.00\",\"0.286\"],[\"79586.10\",\"0.063\"],[\"79586.20\",\"0.002\"],[\"79589.60\",\"0.942\"],[\"79589.70\",\"1.374\"],[\"79595.10\",\"0.002\"]],\"a\":[[\"79598.60\",\"0.001\"],[\"79615.30\",\"0.187\"],[\"79616.50\",\"1.147\"],[\"79617.60\",\"0.002\"],[\"79618.50\",\"0.002\"],[\"79619.70\",\"0.454\"],[\"79620.60\",\"0.002\"],[\"79628.20\",\"0.841\"],[\"79995.00\",\"4.697\"],[\"80393.00\",\"14.884\"],[\"80659.90\",\"1.857\"],[\"80671.70\",\"11.465\"],[\"80716.50\",\"0.387\"],[\"80724.90\",\"0.000\"],[\"81188.90\",\"0.043\"]],\"st\":1}}"}
{"receive_ns":1788567776356623000,"stream":"btcusdt@depth@100ms","event_type":"depthUpdate","event_time_ms":1788567776367,"raw_json":"{\"stream\":\"btcusdt@depth@100ms\",\"data\":{\"e\":\"depthUpdate\",\"E\":1788567776367,\"T\":1788567776366,\"s\":\"BTCUSDT\",\"ps\":\"BTCUSDT\",\"U\":11478511160022,\"u\":11478511163798,\"pu\":11478511159888,\"b\":[[\"1000.00\",\"24.604\"],[\"29196.90\",\"1.134\"],[\"29296.90\",\"0.966\"],[\"63678.00\",\"0.010\"],[\"71637.20\",\"0.002\"],[\"76413.00\",\"0.025\"],[\"78005.00\",\"0.219\"],[\"78403.00\",\"1.920\"],[\"78601.90\",\"9.359\"],[\"78800.90\",\"11.623\"],[\"78960.10\",\"8.590\"],[\"79199.70\",\"0.037\"],[\"79576.80\",\"0.016\"],[\"79586.10\",\"1.327\"],[\"79586.20\",\"0.320\"],[\"79589.70\",\"0.110\"],[\"79595.20\",\"0.026\"],[\"79595.30\",\"0.001\"],[\"79595.50\",\"0.000\"]],\"a\":[[\"79598.70\",\"0.256\"],[\"80393.00\",\"14.884\"]],\"st\":1}}"}
{"receive_ns":1788567776459945000,"stream":"btcusdt@depth@100ms","event_type":"depthUpdate","event_time_ms":1788567776469,"raw_json":"{\"stream\":\"btcusdt@depth@100ms\",\"data\":{\"e\":\"depthUpdate\",\"E\":1788567776469,\"T\":1788567776467,\"s\":\"BTCUSDT\",\"ps\":\"BTCUSDT\",\"U\":11478511163826,\"u\":11478511167838,\"pu\":11478511163798,\"b\":[[\"1000.00\",\"24.604\"],[\"29196.90\",\"1.309\"],[\"29296.90\",\"0.791\"],[\"71637.20\",\"0.002\"],[\"76413.00\",\"0.023\"],[\"78426.80\",\"6.996\"],[\"78601.90\",\"10.312\"],[\"78800.90\",\"11.621\"],[\"78960.10\",\"8.588\"],[\"79199.80\",\"0.094\"],[\"79576.80\",\"0.016\"],[\"79586.10\",\"1.327\"],[\"79586.20\",\"0.320\"],[\"79589.60\",\"0.941\"],[\"79596.70\",\"0.009\"]],\"a\":[[\"80393.00\",\"14.884\"],[\"80552.20\",\"32.453\"],[\"80671.60\",\"4.662\"]],\"st\":1}}"}
{"receive_ns":1788567776523197000,"stream":"btcusdt@bookTicker","event_type":"bookTicker","event_time_ms":1788567776532,"raw_json":"{\"stream\":\"btcusdt@bookTicker\",\"data\":{\"e\":\"bookTicker\",\"u\":11478511170894,\"s\":\"BTCUSDT\",\"ps\":\"BTCUSDT\",\"b\":\"79596.90\",\"B\":\"6.861\",\"a\":\"79597.00\",\"A\":\"8.471\",\"T\":1788567776532,\"E\":1788567776532,\"st\":1}}"}
{"receive_ns":1788567776533334000,"stream":"btcusdt@bookTicker","event_type":"bookTicker","event_time_ms":1788567776535,"raw_json":"{\"stream\":\"btcusdt@bookTicker\",\"data\":{\"e\":\"bookTicker\",\"u\":11478511171065,\"s\":\"BTCUSDT\",\"ps\":\"BTCUSDT\",\"b\":\"79596.90\",\"B\":\"6.877\",\"a\":\"79597.00\",\"A\":\"8.471\",\"T\":1788567776535,\"E\":1788567776535,\"st\":1}}"}
{"receive_ns":1788567776560246000,"stream":"btcusdt@depth@100ms","event_type":"depthUpdate","event_time_ms":1788567776571,"raw_json":"{\"stream\":\"btcusdt@depth@100ms\",\"data\":{\"e\":\"depthUpdate\",\"E\":1788567776571,\"T\":1788567776570,\"s\":\"BTCUSDT\",\"ps\":\"BTCUSDT\",\"U\":11478511167961,\"u\":11478511172252,\"pu\":11478511167838,\"b\":[[\"29196.90\",\"1.491\"],[\"29296.90\",\"0.609\"],[\"71637.20\",\"0.002\"],[\"76413.00\",\"0.025\"],[\"78562.10\",\"8.103\"],[\"78562.20\",\"14.559\"],[\"78800.90\",\"11.621\"],[\"79198.90\",\"3.971\"],[\"79586.10\",\"0.063\"],[\"79586.30\",\"1.264\"],[\"79589.60\",\"0.941\"],[\"79589.70\",\"0.110\"],[\"79595.00\",\"0.028\"],[\"79596.90\",\"6.877\"]],\"a\":[[\"80359.40\",\"0.128\"],[\"80393.00\",\"14.884\"],[\"80950.30\",\"7.920\"]],\"st\":1}}"}
{"receive_ns":1788567776584041000,"stream":"btcusdt@bookTicker","event_type":"bookTicker","event_time_ms":1788567776574,"raw_json":"{\"stream\":\"btcusdt@bookTicker\",\"data\":{\"e\":\"bookTicker\",\"u\":11478511172382,\"s\":\"BTCUSDT\",\"ps\":\"BTCUSDT\",\"b\":\"79596.90\",\"B\":\"6.877\",\"a\":\"79597.00\",\"A\":\"8.453\",\"T\":1788567776573,\"E\":1788567776574,\"st\":1}}"}
{"receive_ns":1788567776586713000,"stream":"btcusdt@trade","event_type":"trade","event_time_ms":1788567776574,"raw_json":"{\"stream\":\"btcusdt@trade\",\"data\":{\"e\":\"trade\",\"E\":1788567776574,\"T\":1788567776573,\"s\":\"BTCUSDT\",\"t\":8054122832,\"p\":\"79597.00\",\"q\":\"0.018\",\"X\":\"MARKET\",\"m\":false,\"st\":1}}"}
{"receive_ns":1788567776663322000,"stream":"btcusdt@depth@100ms","event_type":"depthUpdate","event_time_ms":1788567776673,"raw_json":"{\"stream\":\"btcusdt@depth@100ms\",\"data\":{\"e\":\"depthUpdate\",\"E\":1788567776673,\"T\":1788567776670,\"s\":\"BTCUSDT\",\"ps\":\"BTCUSDT\",\"U\":11478511172307,\"u\":11478511176249,\"pu\":11478511172252,\"b\":[[\"1000.00\",\"24.604\"],[\"29196.90\",\"1.666\"],[\"29296.90\",\"0.434\"],[\"63678.00\",\"0.010\"],[\"71637.20\",\"0.002\"],[\"78751.30\",\"0.001\"],[\"78800.90\",\"11.621\"],[\"79573.20\",\"0.538\"]],\"a\":[[\"79597.00\",\"8.453\"],[\"79613.10\",\"0.194\"],[\"79831.40\",\"0.021\"],[\"79831.50\",\"17.806\"],[\"80393.00\",\"14.884\"]],\"st\":1}}"}
{"receive_ns":1788567776741718000,"stream":"btcusdt@bookTicker","event_type":"bookTicker","event_time_ms":1788567776748,"raw_json":"{\"stream\":\"btcusdt@bookTicker\",\"data\":{\"e\":\"bookTicker\",\"u\":11478511179846,\"s\":\"BTCUSDT\",\"ps\":\"BTCUSDT\",\"b\":\"79596.90\",\"B\":\"6.877\",\"a\":\"79597.00\",\"A\":\"8.449\",\"T\":1788567776748,\"E\":1788567776748,\"st\":1}}"}
{"receive_ns":1788567776754611000,"stream":"btcusdt@trade","event_type":"trade","event_time_ms":1788567776748,"raw_json":"{\"stream\":\"btcusdt@trade\",\"data\":{\"e\":\"trade\",\"E\":1788567776748,\"T\":1788567776748,\"s\":\"BTCUSDT\",\"t\":8054122833,\"p\":\"79597.00\",\"q\":\"0.004\",\"X\":\"MARKET\",\"m\":false,\"st\":1}}"}
{"receive_ns":1788567776773097000,"stream":"btcusdt@depth@100ms","event_type":"depthUpdate","event_time_ms":1788567776775,"raw_json":"{\"stream\":\"btcusdt@depth@100ms\",\"data\":{\"e\":\"depthUpdate\",\"E\":1788567776775,\"T\":1788567776774,\"s\":\"BTCUSDT\",\"ps\":\"BTCUSDT\",\"U\":11478511176364,\"u\":11478511180778,\"pu\":11478511176249,\"b\":[[\"1000.00\",\"24.604\"],[\"29096.90\",\"0.035\"],[\"29196.90\",\"1.778\"],[\"29296.90\",\"0.287\"],[\"71637.20\",\"0.002\"],[\"76413.00\",\"0.023\"],[\"78602.00\",\"10.944\"],[\"78800.90\",\"11.621\"],[\"79198.90\",\"3.970\"],[\"79506.70\",\"4.348\"],[\"79586.30\",\"0.000\"],[\"79589.60\",\"2.205\"]],\"a\":[[\"79597.00\",\"8.449\"],[\"79628.80\",\"0.006\"],[\"79688.30\",\"3.340\"],[\"79806.10\",\"4.791\"],[\"79819.00\",\"6.984\"],[\"80233.80\",\"6.841\"],[\"80353.20\",\"4.218\"],[\"80393.00\",\"14.263\"]],\"st\":1}}"}
{"receive_ns":1788567776874443000,"stream":"btcusdt@depth@100ms","event_type":"depthUpdate","event_time_ms":1788567776877,"raw_json":"{\"stream\":\"btcusdt@depth@100ms\",\"data\":{\"e\":\"depthUpdate\",\"E\":1788567776877,\"T\":1788567776874,\"s\":\"BTCUSDT\",\"ps\":\"BTCUSDT\",\"U\":11478511180804,\"u\":11478511184590,\"pu\":11478511180778,\"b\":[[\"29096.90\",\"0.091\"],[\"29196.90\",\"1.841\"],[\"29296.90\",\"0.168\"],[\"63678.00\",\"0.010\"],[\"71637.20\",\"0.002\"],[\"76413.00\",\"0.025\"],[\"78402.90\",\"3.496\"],[\"78602.00\",\"10.728\"],[\"78745.20\",\"0.760\"],[\"78800.90\",\"11.621\"],[\"79198.90\",\"3.970\"],[\"79564.60\",\"0.001\"],[\"79576.80\",\"0.334\"],[\"79586.10\",\"0.063\"],[\"79586.20\",\"0.002\"],[\"79586.30\",\"0.008\"],[\"79589.60\",\"2.197\"]],\"a\":[[\"80233.80\",\"7.090\"],[\"80393.00\",\"14.263\"],[\"80592.10\",\"6.145\"],[\"81188.90\",\"0.040\"]],\"st\":1}}"}
{"receive_ns":1788567776969508000,"stream":"btcusdt@depth@100ms","event_type":"depthUpdate","event_time_ms":1788567776979,"raw_json":"{\"stream\":\"btcusdt@depth@100ms\",\"data\":{\"e\":\"depthUpdate\",\"E\":1788567776979,\"T\":1788567776978,\"s\":\"BTCUSDT\",\"ps\":\"BTCUSDT\",\"U\":11478511184678,\"u\":11478511188658,\"pu\":11478511184590,\"b\":[[\"1000.00\",\"24.604\"],[\"29096.90\",\"0.154\"],[\"29196.90\",\"1.897\"],[\"29296.90\",\"0.049\"],[\"63677.50\",\"0.000\"],[\"63678.00\",\"0.012\"],[\"71637.20\",\"0.002\"],[\"71673.00\",\"0.000\"],[\"76413.00\",\"0.023\"],[\"78005.00\",\"0.222\"],[\"78164.20\",\"1.533\"],[\"78562.10\",\"8.357\"],[\"78585.20\",\"1.882\"],[\"78587.60\",\"0.005\"],[\"78602.30\",\"0.000\"],[\"78604.60\",\"0.006\"],[\"78800.90\",\"11.621\"],[\"78914.10\",\"0.251\"],[\"79551.80\",\"0.015\"],[\"79561.40\",\"0.001\"],[\"79565.90\",\"0.000\"],[\"79566.20\",\"0.002\"],[\"79576.80\",\"0.334\"],[\"79586.10\",\"1.319\"],[\"79586.20\",\"0.002\"],[\"79586.30\",\"0.008\"],[\"79589.60\",\"0.941\"],[\"79596.70\",\"0.018\"]],\"a\":[[\"80233.80\",\"7.339\"],[\"80375.30\",\"0.000\"],[\"80393.00\",\"14.263\"],[\"80711.40\",\"32.039\"]],\"st\":1}}"}
{"receive_ns":1788567777017892000,"stream":"btcusdt@bookTicker","event_type":"bookTicker","event_time_ms":1788567777026,"raw_json":"{\"stream\":\"btcusdt@bookTicker\",\"data\":{\"e\":\"bookTicker\",\"u\":11478511190197,\"s\":\"BTCUSDT\",\"ps\":\"BTCUSDT\",\"b\":\"79596.90\",\"B\":\"6.877\",\"a\":\"79597.00\",\"A\":\"8.452\",\"T\":1788567777026,\"E\":1788567777026,\"st\":1}}"}
{"receive_ns":1788567777074756000,"stream":"btcusdt@depth@100ms","event_type":"depthUpdate","event_time_ms":1788567777081,"raw_json":"{\"stream\":\"btcusdt@depth@100ms\",\"data\":{\"e\":\"depthUpdate\",\"E\":1788567777081,\"T\":1788567777078,\"s\":\"BTCUSDT\",\"ps\":\"BTCUSDT\",\"U\":11478511188700,\"u\":11478511192602,\"pu\":11478511188658,\"b\":[[\"1000.00\",\"24.604\"],[\"29096.90\",\"0.280\"],[\"29196.90\",\"1.820\"],[\"29296.90\",\"0.000\"],[\"63678.00\",\"0.010\"],[\"71637.20\",\"0.002\"],[\"76413.00\",\"0.025\"],[\"78251.70\",\"6.094\"],[\"78442.70\",\"12.450\"],[\"78800.90\",\"11.621\"],[\"79536.40\",\"0.019\"],[\"79566.00\",\"0.158\"],[\"79576.80\",\"0.330\"],[\"79582.60\",\"0.070\"],[\"79586.10\",\"1.319\"],[\"79586.20\",\"0.006\"],[\"79586.30\",\"0.008\"],[\"79589.60\",\"0.941\"],[\"79595.10\",\"0.002\"]],\"a\":[[\"79597.00\",\"8.452\"],[\"79806.10\",\"4.791\"],[\"79819.00\",\"6.946\"],[\"79995.00\",\"4.698\"],[\"80393.00\",\"14.263\"]],\"st\":1}}"}
{"receive_ns":1788567777100200000,"stream":"btcusdt@bookTicker","event_type":"bookTicker","event_time_ms":1788567777102,"raw_json":"{\"stream\":\"btcusdt@bookTicker\",\"data\":{\"e\":\"bookTicker\",\"u\":11478511193497,\"s\":\"BTCUSDT\",\"ps\":\"BTCUSDT\",\"b\":\"79596.90\",\"B\":\"6.877\",\"a\":\"79597.00\",\"A\":\"8.406\",\"T\":1788567777102,\"E\":1788567777102,\"st\":1}}"}
{"receive_ns":1788567777136439000,"stream":"btcusdt@bookTicker","event_type":"bookTicker","event_time_ms":1788567777152,"raw_json":"{\"stream\":\"btcusdt@bookTicker\",\"data\":{\"e\":\"bookTicker\",\"u\":11478511194979,\"s\":\"BTCUSDT\",\"ps\":\"BTCUSDT\",\"b\":\"79596.90\",\"B\":\"6.861\",\"a\":\"79597.00\",\"A\":\"8.406\",\"T\":1788567777152,\"E\":1788567777152,\"st\":1}}"}
{"receive_ns":1788567777149124000,"stream":"btcusdt@bookTicker","event_type":"bookTicker","event_time_ms":1788567777154,"raw_json":"{\"stream\":\"btcusdt@bookTicker\",\"data\":{\"e\":\"bookTicker\",\"u\":11478511195040,\"s\":\"BTCUSDT\",\"ps\":\"BTCUSDT\",\"b\":\"79596.90\",\"B\":\"6.881\",\"a\":\"79597.00\",\"A\":\"8.406\",\"T\":1788567777154,\"E\":1788567777154,\"st\":1}}"}
{"receive_ns":1788567777167977000,"stream":"btcusdt@depth@100ms","event_type":"depthUpdate","event_time_ms":1788567777183,"raw_json":"{\"stream\":\"btcusdt@depth@100ms\",\"data\":{\"e\":\"depthUpdate\",\"E\":1788567777183,\"T\":1788567777181,\"s\":\"BTCUSDT\",\"ps\":\"BTCUSDT\",\"U\":11478511192720,\"u\":11478511195967,\"pu\":11478511192602,\"b\":[[\"29096.90\",\"0.462\"],[\"29196.90\",\"1.638\"],[\"63678.00\",\"0.010\"],[\"71637.20\",\"0.002\"],[\"78674.80\",\"0.000\"],[\"78800.90\",\"11.621\"],[\"79198.90\",\"3.970\"],[\"79565.90\",\"0.000\"],[\"79566.00\",\"0.033\"],[\"79576.80\",\"0.334\"],[\"79586.10\",\"1.319\"],[\"79586.20\",\"0.002\"],[\"79586.30\",\"0.008\"],[\"79589.60\",\"0.941\"],[\"79596.90\",\"6.881\"]],\"a\":[[\"79597.00\",\"8.406\"],[\"79643.80\",\"1.036\"],[\"79806.10\",\"1.638\"],[\"79995.00\",\"4.697\"],[\"80369.10\",\"1.278\"],[\"80393.00\",\"14.263\"]],\"st\":1}}"}
{"receive_ns":1788567777191761000,"stream":"btcusdt@bookTicker","event_type":"bookTicker","event_time_ms":1788567777203,"raw_json":"{\"stream\":\"btcusdt@bookTicker\",\"data\":{\"e\":\"bookTicker\",\"u\":11478511196979,\"s\":\"BTCUSDT\",\"ps\":\"BTCUSDT\",\"b\":\"79596.90\",\"B\":\"6.835\",\"a\":\"79597.00\",\"A\":\"8.406\",\"T\":1788567777202,\"E\":1788567777203,\"st\":1}}"}
{"receive_ns":1788567777198132000,"stream":"btcusdt@trade","event_type":"trade","event_time_ms":1788567777203,"raw_json":"{\"stream\":\"btcusdt@trade\",\"data\":{\"e\":\"trade\",\"E\":1788567777203,\"T\":1788567777202,\"s\":\"BTCUSDT\",\"t\":8054122834,\"p\":\"79596.90\",\"q\":\"0.046\",\"X\":\"MARKET\",\"m\":true,\"st\":1}}"}
{"receive_ns":1788567777215145000,"stream":"btcusdt@bookTicker","event_type":"bookTicker","event_time_ms":1788567777205,"raw_json":"{\"stream\":\"btcusdt@bookTicker\",\"data\":{\"e\":\"bookTicker\",\"u\":11478511197163,\"s\":\"BTCUSDT\",\"ps\":\"BTCUSDT\",\"b\":\"79596.90\",\"B\":\"6.834\",\"a\":\"79597.00\",\"A\":\"8.406\",\"T\":1788567777204,\"E\":1788567777205,\"st\":1}}"}
{"receive_ns":1788567777215416000,"stream":"btcusdt@bookTicker","event_type":"bookTicker","event_time_ms":1788567777205,"raw_json":"{\"stream\":\"btcusdt@bookTicker\",\"data\":{\"e\":\"bookTicker\",\"u\":11478511197174,\"s\":\"BTCUSDT\",\"ps\":\"BTCUSDT\",\"b\":\"79596.90\",\"B\":\"6.824\",\"a\":\"79597.00\",\"A\":\"8.406\",\"T\":1788567777205,\"E\":1788567777205,\"st\":1}}"}
{"receive_ns":1788567777275063000,"stream":"btcusdt@bookTicker","event_type":"bookTicker","event_time_ms":1788567777284,"raw_json":"{\"stream\":\"btcusdt@bookTicker\",\"data\":{\"e\":\"bookTicker\",\"u\":11478511201598,\"s\":\"BTCUSDT\",\"ps\":\"BTCUSDT\",\"b\":\"79596.90\",\"B\":\"6.824\",\"a\":\"79597.00\",\"A\":\"8.376\",\"T\":1788567777283,\"E\":1788567777284,\"st\":1}}"}
{"receive_ns":1788567777278936000,"stream":"btcusdt@trade","event_type":"trade","event_time_ms":1788567777284,"raw_json":"{\"stream\":\"btcusdt@trade\",\"data\":{\"e\":\"trade\",\"E\":1788567777284,\"T\":1788567777283,\"s\":\"BTCUSDT\",\"t\":8054122835,\"p\":\"79597.00\",\"q\":\"0.030\",\"X\":\"MARKET\",\"m\":false,\"st\":1}}"}
{"receive_ns":1788567777296984000,"stream":"btcusdt@depth@100ms","event_type":"depthUpdate","event_time_ms":1788567777285,"raw_json":"{\"stream\":\"btcusdt@depth@100ms\",\"data\":{\"e\":\"depthUpdate\",\"E\":1788567777285,\"T\":1788567777283,\"s\":\"BTCUSDT\",\"ps\":\"BTCUSDT\",\"U\":11478511196097,\"u\":11478511201598,\"pu\":11478511195967,\"b\":[[\"1000.00\",\"24.604\"],[\"29096.90\",\"0.637\"],[\"29196.90\",\"1.463\"],[\"71637.20\",\"0.002\"],[\"76413.00\",\"0.023\"],[\"78487.30\",\"0.000\"],[\"78641.70\",\"31.776\"],[\"78800.90\",\"11.621\"],[\"79198.90\",\"3.971\"],[\"79501.30\",\"0.000\"],[\"79536.40\",\"0.000\"],[\"79541.10\",\"1.096\"],[\"79576.80\",\"0.330\"],[\"79583.40\",\"0.317\"],[\"79586.10\",\"0.075\"],[\"79586.20\",\"0.002\"],[\"79586.30\",\"0.000\"],[\"79589.70\",\"1.366\"],[\"79590.00\",\"0.094\"],[\"79592.80\",\"0.505\"],[\"79593.90\",\"0.000\"],[\"79596.80\",\"0.159\"],[\"79596.90\",\"6.824\"]],\"a\":[[\"79597.00\",\"8.376\"],[\"79598.00\",\"0.333\"],[\"79598.70\",\"0.004\"],[\"79613.00\",\"1.248\"],[\"79624.80\",\"0.108\"],[\"79628.80\",\"0.000\"],[\"79635.60\",\"1.801\"],[\"79637.90\",\"0.000\"],[\"79643.30\",\"0.101\"],[\"79668.70\",\"2.052\"],[\"79692.60\",\"0.002\"],[\"79804.90\",\"0.635\"],[\"79806.10\",\"4.792\"],[\"79819.00\",\"6.977\"],[\"79927.10\",\"0.018\"],[\"79928.70\",\"0.299\"],[\"80393.00\",\"14.263\"]],\"st\":1}}"}
{"receive_ns":1788567777322322000,"stream":"btcusdt@bookTicker","event_type":"bookTicker","event_time_ms":1788567777330,"raw_json":"{\"stream\":\"btcusdt@bookTicker\",\"data\":{\"e\":\"bookTicker\",\"u\":11478511204288,\"s\":\"BTCUSDT\",\"ps\":\"BTCUSDT\",\"b\":\"79596.90\",\"B\":\"6.812\",\"a\":\"79597.00\",\"A\":\"8.376\",\"T\":1788567777330,\"E\":1788567777330,\"st\":1}}"}
{"receive_ns":1788567777329115000,"stream":"btcusdt@bookTicker","event_type":"bookTicker","event_time_ms":1788567777333,"raw_json":"{\"stream\":\"btcusdt@bookTicker\",\"data\":{\"e\":\"bookTicker\",\"u\":11478511204463,\"s\":\"BTCUSDT\",\"ps\":\"BTCUSDT\",\"b\":\"79596.90\",\"B\":\"6.825\",\"a\":\"79597.00\",\"A\":\"8.376\",\"T\":1788567777333,\"E\":1788567777333,\"st\":1}}"}
{"receive_ns":1788567777348206000,"stream":"btcusdt@bookTicker","event_type":"bookTicker","event_time_ms":1788567777358,"raw_json":"{\"stream\":\"btcusdt@bookTicker\",\"data\":{\"e\":\"bookTicker\",\"u\":11478511206298,\"s\":\"BTCUSDT\",\"ps\":\"BTCUSDT\",\"b\":\"79596.90\",\"B\":\"6.825\",\"a\":\"79597.00\",\"A\":\"8.227\",\"T\":1788567777357,\"E\":1788567777358,\"st\":1}}"}
{"receive_ns":1788567777359930000,"stream":"btcusdt@bookTicker","event_type":"bookTicker","event_time_ms":1788567777358,"raw_json":"{\"stream\":\"btcusdt@bookTicker\",\"data\":{\"e\":\"bookTicker\",\"u\":11478511206299,\"s\":\"BTCUSDT\",\"ps\":\"BTCUSDT\",\"b\":\"79596.90\",\"B\":\"6.825\",\"a\":\"79597.00\",\"A\":\"6.736\",\"T\":1788567777357,\"E\":1788567777358,\"st\":1}}"}
{"receive_ns":1788567777370977000,"stream":"btcusdt@bookTicker","event_type":"bookTicker","event_time_ms":1788567777358,"raw_json":"{\"stream\":\"btcusdt@bookTicker\",\"data\":{\"e\":\"bookTicker\",\"u\":11478511206308,\"s\":\"BTCUSDT\",\"ps\":\"BTCUSDT\",\"b\":\"79596.90\",\"B\":\"6.825\",\"a\":\"79597.00\",\"A\":\"6.735\",\"T\":1788567777358,\"E\":1788567777358,\"st\":1}}"}
{"receive_ns":1788567777377733000,"stream":"btcusdt@bookTicker","event_type":"bookTicker","event_time_ms":1788567777358,"raw_json":"{\"stream\":\"btcusdt@bookTicker\",\"data\":{\"e\":\"bookTicker\",\"u\":11478511206323,\"s\":\"BTCUSDT\",\"ps\":\"BTCUSDT\",\"b\":\"79596.90\",\"B\":\"6.825\",\"a\":\"79597.00\",\"A\":\"6.720\",\"T\":1788567777358,\"E\":1788567777358,\"st\":1}}"}
