{"receive_ns":1788567787476515000,"stream":"btcusdt@depth@100ms","event_type":"depthUpdate","event_time_ms":1788567787485,"raw_json":"{\"stream\":\"btcusdt@depth@100ms\",\"data\":{\"e\":\"depthUpdate\",\"E\":1788567787485,\"T\":1788567787484,\"s\":\"BTCUSDT\",\"ps\":\"BTCUSDT\",\"U\":11478511811795,\"u\":11478511817184,\"pu\":11478511811707,\"b\":[[\"1000.00\",\"24.604\"],[\"29296.90\",\"1.687\"],[\"29396.90\",\"0.413\"],[\"71637.20\",\"0.002\"],[\"78601.90\",\"13.493\"],[\"78800.90\",\"13.521\"],[\"79358.10\",\"0.012\"],[\"79501.30\",\"0.000\"],[\"79541.10\",\"1.098\"],[\"79565.80\",\"0.000\"],[\"79567.20\",\"0.048\"],[\"79573.30\",\"0.564\"],[\"79573.70\",\"0.001\"],[\"79583.40\",\"0.241\"],[\"79594.90\",\"0.026\"],[\"79596.00\",\"0.108\"],[\"79596.90\",\"6.837\"]],\"a\":[[\"79599.90\",\"0.028\"],[\"79600.00\",\"0.075\"],[\"79600.40\",\"0.008\"],[\"79600.60\",\"0.000\"],[\"79600.70\",\"0.004\"],[\"79600.80\",\"0.036\"],[\"79616.90\",\"1.969\"],[\"79628.90\",\"0.033\"],[\"79668.70\",\"2.054\"],[\"79806.00\",\"3.117\"],[\"80393.00\",\"15.389\"]],\"st\":1}}"}
{"receive_ns":1788567787493479000,"stream":"btcusdt@bookTicker","event_type":"bookTicker","event_time_ms":1788567787500,"raw_json":"{\"stream\":\"btcusdt@bookTicker\",\"data\":{\"e\":\"bookTicker\",\"u\":11478511817964,\"s\":\"BTCUSDT\",\"ps\":\"BTCUSDT\",\"b\":\"79596.90\",\"B\":\"6.815\",\"a\":\"79597.00\",\"A\":\"8.040\",\"T\":1788567787500,\"E\":1788567787500,\"st\":1}}"}
{"receive_ns":1788567787510318000,"stream":"btcusdt@bookTicker","event_type":"bookTicker","event_time_ms":1788567787502,"raw_json":"{\"stream\":\"btcusdt@bookTicker\",\"data\":{\"e\":\"bookTicker\",\"u\":11478511818146,\"s\":\"BTCUSDT\",\"ps\":\"BTCUSDT\",\"b\":\"79596.90\",\"B\":\"6.839\",\"a\":\"79597.00\",\"A\":\"8.040\",\"T\":1788567787502,\"E\":1788567787502,\"st\":1}}"}
{"receive_ns":1788567787574402000,"stream":"btcusdt@bookTicker","event_type":"bookTicker","event_time_ms":1788567787582,"raw_json":"{\"stream\":\"btcusdt@bookTicker\",\"data\":{\"e\":\"bookTicker\",\"u\":11478511824815,\"s\":\"BTCUSDT\",\"ps\":\"BTCUSDT\",\"b\":\"79596.90\",\"B\":\"6.840\",\"a\":\"79597.00\",\"A\":\"8.040\",\"T\":1788567787582,\"E\":1788567787582,\"st\":1}}"}
{"receive_ns":1788567787580818000,"stream":"btcusdt@depth@100ms","event_type":"depthUpdate","event_time_ms":1788567787587,"raw_json":"{\"stream\":\"btcusdt@depth@100ms\",\"data\":{\"e\":\"depthUpdate\",\"E\":1788567787587,\"T\":1788567787585,\"s\":\"BTCUSDT\",\"ps\":\"BTCUSDT\",\"U\":11478511817270,\"u\":11478511825041,\"pu\":11478511817184,\"b\":[[\"1000.00\",\"24.604\"],[\"29196.90\",\"0.042\"],[\"29296.90\",\"1.785\"],[\"29396.90\",\"0.273\"],[\"71637.20\",\"0.002\"],[\"71673.00\",\"0.000\"],[\"76413.00\",\"0.025\"],[\"78800.90\",\"13.521\"],[\"79596.90\",\"6.840\"]],\"a\":[[\"79599.70\",\"0.026\"],[\"79599.80\",\"0.027\"],[\"79616.90\",\"1.974\"],[\"79637.50\",\"0.000\"],[\"79638.20\",\"0.542\"],[\"79638.40\",\"0.125\"],[\"80230.20\",\"3.733\"],[\"80393.00\",\"15.389\"],[\"80727.30\",\"1.628\"]],\"st\":1}}"}
{"receive_ns":1788567787603376000,"stream":"btcusdt@bookTicker","event_type":"bookTicker","event_time_ms":1788567787612,"raw_json":"{\"stream\":\"btcusdt@bookTicker\",\"data\":{\"e\":\"bookTicker\",\"u\":11478511826732,\"s\":\"BTCUSDT\",\"ps\":\"BTCUSDT\",\"b\":\"79596.90\",\"B\":\"6.421\",\"a\":\"79597.00\",\"A\":\"8.040\",\"T\":1788567787612,\"E\":1788567787612,\"st\":1}}"}
{"receive_ns":1788567787609884000,"stream":"btcusdt@trade","event_type":"trade","event_time_ms":1788567787612,"raw_json":"{\"stream\":\"btcusdt@trade\",\"data\":{\"e\":\"trade\",\"E\":1788567787612,\"T\":1788567787612,\"s\":\"BTCUSDT\",\"t\":8054122867,\"p\":\"79596.90\",\"q\":\"0.277\",\"X\":\"MARKET\",\"m\":true,\"st\":1}}"}
{"receive_ns":1788567787615341000,"stream":"btcusdt@trade","event_type":"trade","event_time_ms":1788567787612,"raw_json":"{\"stream\":\"btcusdt@trade\",\"data\":{\"e\":\"trade\",\"E\":1788567787612,\"T\":1788567787612,\"s\":\"BTCUSDT\",\"t\":8054122868,\"p\":\"79596.90\",\"q\":\"0.001\",\"X\":\"MARKET\",\"m\":true,\"st\":1}}"}
{"receive_ns":1788567787621326000,"stream":"btcusdt@trade","event_type":"trade","event_time_ms":1788567787612,"raw_json":"{\"stream\":\"btcusdt@trade\",\"data\":{\"e\":\"trade\",\"E\":1788567787612,\"T\":1788567787612,\"s\":\"BTCUSDT\",\"t\":8054122869,\"p\":\"79596.90\",\"q\":\"0.075\",\"X\":\"MARKET\",\"m\":true,\"st\":1}}"}
{"receive_ns":1788567787627976000,"stream":"btcusdt@trade","event_type":"trade","event_time_ms":1788567787612,"raw_json":"{\"stream\":\"btcusdt@trade\",\"data\":{\"e\":\"trade\",\"E\":1788567787612,\"T\":1788567787612,\"s\":\"BTCUSDT\",\"t\":8054122870,\"p\":\"79596.90\",\"q\":\"0.001\",\"X\":\"MARKET\",\"m\":true,\"st\":1}}"}
{"receive_ns":1788567787639979000,"stream":"btcusdt@trade","event_type":"trade","event_time_ms":1788567787612,"raw_json":"{\"stream\":\"btcusdt@trade\",\"data\":{\"e\":\"trade\",\"E\":1788567787612,\"T\":1788567787612,\"s\":\"BTCUSDT\",\"t\":8054122871,\"p\":\"79596.90\",\"q\":\"0.065\",\"X\":\"MARKET\",\"m\":true,\"st\":1}}"}
{"receive_ns":1788567787655723000,"stream":"btcusdt@bookTicker","event_type":"bookTicker","event_time_ms":1788567787613,"raw_json":"{\"stream\":\"btcusdt@bookTicker\",\"data\":{\"e\":\"bookTicker\",\"u\":11478511826772,\"s\":\"BTCUSDT\",\"ps\":\"BTCUSDT\",\"b\":\"79596.90\",\"B\":\"7.007\",\"a\":\"79597.00\",\"A\":\"8.040\",\"T\":1788567787613,\"E\":1788567787613,\"st\":1}}"}
{"receive_ns":1788567787663134000,"stream":"btcusdt@bookTicker","event_type":"bookTicker","event_time_ms":1788567787613,"raw_json":"{\"stream\":\"btcusdt@bookTicker\",\"data\":{\"e\":\"bookTicker\",\"u\":11478511826778,\"s\":\"BTCUSDT\",\"ps\":\"BTCUSDT\",\"b\":\"79596.90\",\"B\":\"7.007\",\"a\":\"79597.00\",\"A\":\"8.041\",\"T\":1788567787613,\"E\":1788567787613,\"st\":1}}"}
{"receive_ns":1788567787674270000,"stream":"btcusdt@bookTicker","event_type":"bookTicker","event_time_ms":1788567787613,"raw_json":"{\"stream\":\"btcusdt@bookTicker\",\"data\":{\"e\":\"bookTicker\",\"u\":11478511826786,\"s\":\"BTCUSDT\",\"ps\":\"BTCUSDT\",\"b\":\"79596.90\",\"B\":\"7.008\",\"a\":\"79597.00\",\"A\":\"8.041\",\"T\":1788567787613,\"E\":1788567787613,\"st\":1}}"}
{"receive_ns":1788567787692005000,"stream":"btcusdt@bookTicker","event_type":"bookTicker","event_time_ms":1788567787614,"raw_json":"{\"stream\":\"btcusdt@bookTicker\",\"data\":{\"e\":\"bookTicker\",\"u\":11478511826903,\"s\":\"BTCUSDT\",\"ps\":\"BTCUSDT\",\"b\":\"79596.90\",\"B\":\"7.008\",\"a\":\"79597.00\",\"A\":\"8.067\",\"T\":1788567787614,\"E\":1788567787614,\"st\":1}}"}
{"receive_ns":1788567787702770000,"stream":"btcusdt@bookTicker","event_type":"bookTicker","event_time_ms":1788567787615,"raw_json":"{\"stream\":\"btcusdt@bookTicker\",\"data\":{\"e\":\"bookTicker\",\"u\":11478511826933,\"s\":\"BTCUSDT\",\"ps\":\"BTCUSDT\",\"b\":\"79596.90\",\"B\":\"7.007\",\"a\":\"79597.00\",\"A\":\"8.067\",\"T\":1788567787614,\"E\":1788567787615,\"st\":1}}"}
{"receive_ns":1788567787708487000,"stream":"btcusdt@bookTicker","event_type":"bookTicker","event_time_ms":1788567787615,"raw_json":"{\"stream\":\"btcusdt@bookTicker\",\"data\":{\"e\":\"bookTicker\",\"u\":11478511826945,\"s\":\"BTCUSDT\",\"ps\":\"BTCUSDT\",\"b\":\"79596.90\",\"B\":\"7.007\",\"a\":\"79597.00\",\"A\":\"8.066\",\"T\":1788567787614,\"E\":1788567787615,\"st\":1}}"}
{"receive_ns":1788567787720509000,"stream":"btcusdt@bookTicker","event_type":"bookTicker","event_time_ms":1788567787615,"raw_json":"{\"stream\":\"btcusdt@bookTicker\",\"data\":{\"e\":\"bookTicker\",\"u\":11478511826946,\"s\":\"BTCUSDT\",\"ps\":\"BTCUSDT\",\"b\":\"79596.90\",\"B\":\"7.006\",\"a\":\"79597.00\",\"A\":\"8.066\",\"T\":1788567787614,\"E\":1788567787615,\"st\":1}}"}
{"receive_ns":1788567787732031000,"stream":"btcusdt@bookTicker","event_type":"bookTicker","event_time_ms":1788567787634,"raw_json":"{\"stream\":\"btcusdt@bookTicker\",\"data\":{\"e\":\"bookTicker\",\"u\":11478511828204,\"s\":\"BTCUSDT\",\"ps\":\"BTCUSDT\",\"b\":\"79596.90\",\"B\":\"7.006\",\"a\":\"79597.00\",\"A\":\"7.669\",\"T\":1788567787634,\"E\":1788567787634,\"st\":1}}"}
{"receive_ns":1788567787744335000,"stream":"btcusdt@trade","event_type":"trade","event_time_ms":1788567787634,"raw_json":"{\"stream\":\"btcusdt@trade\",\"data\":{\"e\":\"trade\",\"E\":1788567787634,\"T\":1788567787634,\"s\":\"BTCUSDT\",\"t\":8054122872,\"p\":\"79597.00\",\"q\":\"0.009\",\"X\":\"MARKET\",\"m\":false,\"st\":1}}"}
{"receive_ns":1788567787756729000,"stream":"btcusdt@trade","event_type":"trade","event_time_ms":1788567787634,"raw_json":"{\"stream\":\"btcusdt@trade\",\"data\":{\"e\":\"trade\",\"E\":1788567787634,\"T\":1788567787634,\"s\":\"BTCUSDT\",\"t\":8054122873,\"p\":\"79597.00\",\"q\":\"0.098\",\"X\":\"MARKET\",\"m\":false,\"st\":1}}"}
{"receive_ns":1788567787762420000,"stream":"btcusdt@trade","event_type":"trade","event_time_ms":1788567787634,"raw_json":"{\"stream\":\"btcusdt@trade\",\"data\":{\"e\":\"trade\",\"E\":1788567787634,\"T\":1788567787634,\"s\":\"BTCUSDT\",\"t\":8054122874,\"p\":\"79597.00\",\"q\":\"0.290\",\"X\":\"MARKET\",\"m\":false,\"st\":1}}"}
{"receive_ns":1788567787773282000,"stream":"btcusdt@bookTicker","event_type":"bookTicker","event_time_ms":1788567787635,"raw_json":"{\"stream\":\"btcusdt@bookTicker\",\"data\":{\"e\":\"bookTicker\",\"u\":11478511828354,\"s\":\"BTCUSDT\",\"ps\":\"BTCUSDT\",\"b\":\"79596.90\",\"B\":\"7.007\",\"a\":\"79597.00\",\"A\":\"7.669\",\"T\":1788567787635,\"E\":1788567787635,\"st\":1}}"}
{"receive_ns":1788567787790595000,"stream":"btcusdt@bookTicker","event_type":"bookTicker","event_time_ms":1788567787636,"raw_json":"{\"stream\":\"btcusdt@bookTicker\",\"data\":{\"e\":\"bookTicker\",\"u\":11478511828490,\"s\":\"BTCUSDT\",\"ps\":\"BTCUSDT\",\"b\":\"79596.90\",\"B\":\"7.007\",\"a\":\"79597.00\",\"A\":\"7.643\",\"T\":1788567787636,\"E\":1788567787636,\"st\":1}}"}
{"receive_ns":1788567787810007000,"stream":"btcusdt@depth@100ms","event_type":"depthUpdate","event_time_ms":1788567787689,"raw_json":"{\"stream\":\"btcusdt@depth@100ms\",\"data\":{\"e\":\"depthUpdate\",\"E\":1788567787689,\"T\":1788567787686,\"s\":\"BTCUSDT\",\"ps\":\"BTCUSDT\",\"U\":11478511825134,\"u\":11478511831163,\"pu\":11478511825041,\"b\":[[\"29196.90\",\"0.098\"],[\"29296.90\",\"1.848\"],[\"29396.90\",\"0.154\"],[\"63678.00\",\"0.010\"],[\"71637.20\",\"0.002\"],[\"76413.00\",\"0.023\"],[\"78800.90\",\"13.521\"],[\"79198.90\",\"3.981\"],[\"79473.50\",\"0.026\"],[\"79473.60\",\"1.199\"],[\"79475.60\",\"0.504\"],[\"79528.70\",\"0.000\"],[\"79537.80\",\"0.003\"],[\"79538.40\",\"0.002\"],[\"79544.60\",\"0.008\"],[\"79554.30\",\"0.000\"],[\"79567.80\",\"0.628\"],[\"79568.20\",\"0.002\"],[\"79575.90\",\"0.628\"],[\"79576.20\",\"0.247\"],[\"79576.80\",\"0.016\"],[\"79576.90\",\"0.002\"],[\"79581.20\",\"0.077\"],[\"79581.90\",\"0.688\"],[\"79582.30\",\"0.195\"],[\"79583.40\",\"0.317\"],[\"79584.90\",\"2.997\"],[\"79585.00\",\"0.349\"],[\"79585.30\",\"0.096\"],[\"79585.50\",\"0.082\"],[\"79586.10\",\"0.075\"],[\"79587.70\",\"0.001\"],[\"79589.80\",\"0.000\"],[\"79590.00\",\"0.108\"],[\"79590.50\",\"0.000\"],[\"79590.80\",\"0.003\"],[\"79591.00\",\"0.077\"],[\"79591.50\",\"0.004\"],[\"79591.60\",\"0.000\"],[\"79591.80\",\"0.000\"],[\"79591.90\",\"0.343\"],[\"79592.10\",\"0.000\"],[\"79592.80\",\"0.581\"],[\"79593.20\",\"0.000\"],[\"79593.40\",\"0.001\"],[\"79593.50\",\"0.003\"],[\"79594.00\",\"0.252\"],[\"79594.10\",\"0.003\"],[\"79594.20\",\"0.000\"],[\"79594.30\",\"0.064\"],[\"79594.40\",\"0.080\"],[\"79594.50\",\"0.026\"],[\"79594.70\",\"0.026\"],[\"79594.80\",\"0.026\"],[\"79595.70\",\"0.001\"],[\"79595.80\",\"0.000\"],[\"79595.90\",\"0.038\"],[\"79596.00\",\"0.082\"],[\"79596.20\",\"0.026\"],[\"79596.40\",\"0.002\"],[\"79596.80\",\"0.183\"],[\"79596.90\",\"7.007\"]],\"a\":[[\"79597.00\",\"7.643\"],[\"79597.10\",\"0.739\"],[\"79597.20\",\"0.002\"],[\"79597.60\",\"0.117\"],[\"79597.80\",\"0.031\"],[\"79597.90\",\"0.028\"],[\"79598.00\",\"0.107\"],[\"79598.10\",\"0.026\"],[\"79598.30\",\"0.028\"],[\"79598.40\",\"0.285\"],[\"79598.50\",\"0.026\"],[\"79598.60\",\"0.001\"],[\"79599.90\",\"0.002\"],[\"79600.00\",\"0.049\"],[\"79600.80\",\"0.008\"],[\"79600.90\",\"0.002\"],[\"79601.00\",\"0.321\"],[\"79601.20\",\"0.000\"],[\"79601.30\",\"0.001\"],[\"79601.40\",\"0.107\"],[\"79602.50\",\"0.005\"],[\"79603.70\",\"0.003\"],[\"79604.00\",\"0.175\"],[\"79604.20\",\"0.007\"],[\"79605.20\",\"0.117\"],[\"79612.50\",\"0.001\"],[\"79625.70\",\"0.003\"],[\"79628.00\",\"1.697\"],[\"79628.40\",\"0.000\"],[\"79638.40\",\"0.000\"],[\"79718.90\",\"0.471\"],[\"79806.00\",\"5.076\"],[\"80393.00\",\"15.389\"]],\"st\":1}}"}
{"receive_ns":1788567787821145000,"stream":"btcusdt@bookTicker","event_type":"bookTicker","event_time_ms":1788567787711,"raw_json":"{\"stream\":\"btcusdt@bookTicker\",\"data\":{\"e\":\"bookTicker\",\"u\":11478511832621,\"s\":\"BTCUSDT\",\"ps\":\"BTCUSDT\",\"b\":\"79596.90\",\"B\":\"7.007\",\"a\":\"79597.00\",\"A\":\"7.641\",\"T\":1788567787711,\"E\":1788567787711,\"st\":1}}"}
{"receive_ns":1788567787827954000,"stream":"btcusdt@trade","event_type":"trade","event_time_ms":1788567787711,"raw_json":"{\"stream\":\"btcusdt@trade\",\"data\":{\"e\":\"trade\",\"E\":1788567787711,\"T\":1788567787711,\"s\":\"BTCUSDT\",\"t\":8054122875,\"p\":\"79597.00\",\"q\":\"0.002\",\"X\":\"MARKET\",\"m\":false,\"st\":1}}"}
{"receive_ns":1788567787846105000,"stream":"btcusdt@bookTicker","event_type":"bookTicker","event_time_ms":1788567787712,"raw_json":"{\"stream\":\"btcusdt@bookTicker\",\"data\":{\"e\":\"bookTicker\",\"u\":11478511832642,\"s\":\"BTCUSDT\",\"ps\":\"BTCUSDT\",\"b\":\"79596.90\",\"B\":\"7.009\",\"a\":\"79597.00\",\"A\":\"7.641\",\"T\":1788567787712,\"E\":1788567787712,\"st\":1}}"}
{"receive_ns":1788567787863983000,"stream":"btcusdt@bookTicker","event_type":"bookTicker","event_time_ms":1788567787760,"raw_json":"{\"stream\":\"btcusdt@bookTicker\",\"data\":{\"e\":\"bookTicker\",\"u\":11478511835374,\"s\":\"BTCUSDT\",\"ps\":\"BTCUSDT\",\"b\":\"79596.90\",\"B\":\"7.019\",\"a\":\"79597.00\",\"A\":\"7.641\",\"T\":1788567787760,\"E\":1788567787760,\"st\":1}}"}
{"receive_ns":1788567787882477000,"stream":"btcusdt@depth@100ms","event_type":"depthUpdate","event_time_ms":1788567787791,"raw_json":"{\"stream\":\"btcusdt@depth@100ms\",\"data\":{\"e\":\"depthUpdate\",\"E\":1788567787791,\"T\":1788567787790,\"s\":\"BTCUSDT\",\"ps\":\"BTCUSDT\",\"U\":11478511831299,\"u\":11478511836806,\"pu\":11478511831163,\"b\":[[\"1000.00\",\"24.604\"],[\"29196.90\",\"0.161\"],[\"29296.90\",\"1.904\"],[\"29396.90\",\"0.035\"],[\"63678.00\",\"0.010\"],[\"71637.20\",\"0.002\"],[\"75617.10\",\"0.006\"],[\"76413.00\",\"0.025\"],[\"78800.90\",\"12.254\"],[\"79586.10\",\"0.067\"],[\"79588.80\",\"0.257\"],[\"79589.80\",\"0.008\"],[\"79590.80\",\"0.001\"],[\"79596.90\",\"7.019\"]],\"a\":[[\"79597.00\",\"7.641\"],[\"79597.10\",\"0.741\"],[\"79597.20\",\"0.248\"],[\"79604.20\",\"0.008\"],[\"79605.20\",\"0.116\"],[\"79637.70\",\"0.696\"],[\"79668.80\",\"21.826\"],[\"79671.50\",\"0.000\"],[\"79806.00\",\"5.076\"],[\"80393.00\",\"15.389\"],[\"80552.20\",\"34.933\"],[\"81188.90\",\"0.012\"]],\"st\":1}}"}
{"receive_ns":1788567787896433000,"stream":"btcusdt@depth@100ms","event_type":"depthUpdate","event_time_ms":1788567787893,"raw_json":"{\"stream\":\"btcusdt@depth@100ms\",\"data\":{\"e\":\"depthUpdate\",\"E\":1788567787893,\"T\":1788567787891,\"s\":\"BTCUSDT\",\"ps\":\"BTCUSDT\",\"U\":11478511836935,\"u\":11478511845023,\"pu\":11478511836806,\"b\":[[\"1000.00\",\"24.604\"],[\"29196.90\",\"0.301\"],[\"29296.90\",\"1.799\"],[\"29396.90\",\"0.000\"],[\"71637.20\",\"0.002\"],[\"75617.10\",\"0.008\"],[\"76413.00\",\"0.023\"],[\"78492.60\",\"3.560\"],[\"78800.90\",\"12.256\"],[\"79582.90\",\"0.274\"]],\"a\":[[\"79601.10\",\"0.011\"],[\"79637.60\",\"0.010\"],[\"79637.70\",\"0.571\"],[\"80393.00\",\"15.389\"],[\"80671.70\",\"11.279\"]],\"st\":1}}"}
{"receive_ns":1788567787919779000,"stream":"btcusdt@bookTicker","event_type":"bookTicker","event_time_ms":1788567787930,"raw_json":"{\"stream\":\"btcusdt@bookTicker\",\"data\":{\"e\":\"bookTicker\",\"u\":11478511849485,\"s\":\"BTCUSDT\",\"ps\":\"BTCUSDT\",\"b\":\"79596.90\",\"B\":\"7.019\",\"a\":\"79597.00\",\"A\":\"7.625\",\"T\":1788567787930,\"E\":1788567787930,\"st\":1}}"}
{"receive_ns":1788567787937918000,"stream":"btcusdt@bookTicker","event_type":"bookTicker","event_time_ms":1788567787933,"raw_json":"{\"stream\":\"btcusdt@bookTicker\",\"data\":{\"e\":\"bookTicker\",\"u\":11478511849848,\"s\":\"BTCUSDT\",\"ps\":\"BTCUSDT\",\"b\":\"79596.90\",\"B\":\"7.019\",\"a\":\"79597.00\",\"A\":\"7.644\",\"T\":1788567787933,\"E\":1788567787933,\"st\":1}}"}
{"receive_ns":1788567787985800000,"stream":"btcusdt@depth@100ms","event_type":"depthUpdate","event_time_ms":1788567787995,"raw_json":"{\"stream\":\"btcusdt@depth@100ms\",\"data\":{\"e\":\"depthUpdate\",\"E\":1788567787995,\"T\":1788567787993,\"s\":\"BTCUSDT\",\"ps\":\"BTCUSDT\",\"U\":11478511845169,\"u\":11478511855714,\"pu\":11478511845023,\"b\":[[\"29196.90\",\"0.483\"],[\"29296.90\",\"1.617\"],[\"63678.00\",\"0.010\"],[\"71637.20\",\"0.002\"],[\"76797.00\",\"0.199\"],[\"78520.90\",\"1.909\"],[\"78577.50\",\"0.002\"],[\"78610.80\",\"0.000\"],[\"78800.90\",\"12.255\"],[\"79198.90\",\"3.981\"],[\"79475.60\",\"0.504\"],[\"79506.80\",\"4.367\"],[\"79568.90\",\"0.455\"],[\"79570.90\",\"0.002\"],[\"79573.20\",\"0.538\"],[\"79575.70\",\"0.002\"],[\"79576.10\",\"0.382\"],[\"79576.30\",\"0.143\"],[\"79577.20\",\"0.000\"],[\"79584.60\",\"0.348\"],[\"79592.10\",\"0.076\"],[\"79592.80\",\"0.505\"]],\"a\":[[\"79597.00\",\"7.644\"],[\"79597.60\",\"0.091\"],[\"79606.90\",\"0.252\"],[\"79607.20\",\"0.004\"],[\"79610.90\",\"0.442\"],[\"79612.80\",\"0.003\"],[\"79613.10\",\"0.194\"],[\"79616.00\",\"0.381\"],[\"79616.10\",\"0.009\"],[\"79616.20\",\"0.654\"],[\"79616.40\",\"1.732\"],[\"79617.20\",\"0.002\"],[\"79619.30\",\"0.001\"],[\"79619.70\",\"0.002\"],[\"79620.30\",\"1.079\"],[\"79625.90\",\"0.008\"],[\"79626.30\",\"0.002\"],[\"79630.60\",\"0.027\"],[\"79631.70\",\"0.046\"],[\"79638.50\",\"0.130\"],[\"79688.30\",\"3.352\"],[\"79718.90\",\"0.471\"],[\"79804.90\",\"0.635\"],[\"79806.00\",\"5.074\"],[\"79819.10\",\"6.970\"],[\"80393.00\",\"15.389\"],[\"80727.40\",\"0.896\"]],\"st\":1}}"}
{"receive_ns":1788567788037541000,"stream":"btcusdt@bookTicker","event_type":"bookTicker","event_time_ms":1788567788052,"raw_json":"{\"stream\":\"btcusdt@bookTicker\",\"data\":{\"e\":\"bookTicker\",\"u\":11478511860597,\"s\":\"BTCUSDT\",\"ps\":\"BTCUSDT\",\"b\":\"79596.90\",\"B\":\"7.019\",\"a\":\"79597.00\",\"A\":\"7.638\",\"T\":1788567788052,\"E\":1788567788052,\"st\":1}}"}
{"receive_ns":1788567788049720000,"stream":"btcusdt@bookTicker","event_type":"bookTicker","event_time_ms":1788567788059,"raw_json":"{\"stream\":\"btcusdt@bookTicker\",\"data\":{\"e\":\"bookTicker\",\"u\":11478511860996,\"s\":\"BTCUSDT\",\"ps\":\"BTCUSDT\",\"b\":\"79596.90\",\"B\":\"7.019\",\"a\":\"79597.00\",\"A\":\"7.645\",\"T\":1788567788059,\"E\":1788567788059,\"st\":1}}"}
{"receive_ns":1788567788082221000,"stream":"btcusdt@bookTicker","event_type":"bookTicker","event_time_ms":1788567788086,"raw_json":"{\"stream\":\"btcusdt@bookTicker\",\"data\":{\"e\":\"bookTicker\",\"u\":11478511862294,\"s\":\"BTCUSDT\",\"ps\":\"BTCUSDT\",\"b\":\"79596.90\",\"B\":\"7.019\",\"a\":\"79597.00\",\"A\":\"7.642\",\"T\":1788567788086,\"E\":1788567788086,\"st\":1}}"}
{"receive_ns":1788567788091637000,"stream":"btcusdt@trade","event_type":"trade","event_time_ms":1788567788086,"raw_json":"{\"stream\":\"btcusdt@trade\",\"data\":{\"e\":\"trade\",\"E\":1788567788086,\"T\":1788567788086,\"s\":\"BTCUSDT\",\"t\":8054122876,\"p\":\"79597.00\",\"q\":\"0.003\",\"X\":\"MARKET\",\"m\":false,\"st\":1}}"}
{"receive_ns":1788567788103253000,"stream":"btcusdt@depth@100ms","event_type":"depthUpdate","event_time_ms":1788567788097,"raw_json":"{\"stream\":\"btcusdt@depth@100ms\",\"data\":{\"e\":\"depthUpdate\",\"E\":1788567788097,\"T\":1788567788094,\"s\":\"BTCUSDT\",\"ps\":\"BTCUSDT\",\"U\":11478511855783,\"u\":11478511862772,\"pu\":11478511855714,\"b\":[[\"1000.00\",\"24.604\"],[\"29196.90\",\"0.658\"],[\"29296.90\",\"1.442\"],[\"63678.00\",\"0.012\"],[\"71637.20\",\"0.002\"],[\"76413.00\",\"0.025\"],[\"78579.90\",\"0.006\"],[\"78613.10\",\"0.003\"],[\"78800.90\",\"12.255\"],[\"79198.90\",\"3.981\"],[\"79582.60\",\"0.070\"],[\"79584.60\",\"0.351\"]],\"a\":[[\"79597.00\",\"7.642\"],[\"79597.10\",\"0.741\"],[\"79638.00\",\"0.127\"],[\"79638.50\",\"0.005\"],[\"79804.90\",\"1.030\"],[\"79806.00\",\"5.076\"],[\"79831.70\",\"0.000\"],[\"79831.80\",\"0.056\"],[\"79995.00\",\"4.697\"],[\"80393.00\",\"15.389\"],[\"80706.10\",\"0.379\"],[\"80714.70\",\"0.374\"],[\"80715.40\",\"0.000\"],[\"80724.00\",\"0.139\"]],\"st\":1}}"}
{"receive_ns":1788567788119305000,"stream":"btcusdt@bookTicker","event_type":"bookTicker","event_time_ms":1788567788129,"raw_json":"{\"stream\":\"btcusdt@bookTicker\",\"data\":{\"e\":\"bookTicker\",\"u\":11478511864816,\"s\":\"BTCUSDT\",\"ps\":\"BTCUSDT\",\"b\":\"79596.90\",\"B\":\"7.012\",\"a\":\"79597.00\",\"A\":\"7.642\",\"T\":1788567788129,\"E\":1788567788129,\"st\":1}}"}
{"receive_ns":1788567788136465000,"stream":"btcusdt@bookTicker","event_type":"bookTicker","event_time_ms":1788567788132,"raw_json":"{\"stream\":\"btcusdt@bookTicker\",\"data\":{\"e\":\"bookTicker\",\"u\":11478511864993,\"s\":\"BTCUSDT\",\"ps\":\"BTCUSDT\",\"b\":\"79596.90\",\"B\":\"7.018\",\"a\":\"79597.00\",\"A\":\"7.642\",\"T\":1788567788132,\"E\":1788567788132,\"st\":1}}"}
{"receive_ns":1788567788178787000,"stream":"btcusdt@bookTicker","event_type":"bookTicker","event_time_ms":1788567788194,"raw_json":"{\"stream\":\"btcusdt@bookTicker\",\"data\":{\"e\":\"bookTicker\",\"u\":11478511870756,\"s\":\"BTCUSDT\",\"ps\":\"BTCUSDT\",\"b\":\"79596.90\",\"B\":\"6.997\",\"a\":\"79597.00\",\"A\":\"7.642\",\"T\":1788567788194,\"E\":1788567788194,\"st\":1}}"}
{"receive_ns":1788567788189827000,"stream":"btcusdt@bookTicker","event_type":"bookTicker","event_time_ms":1788567788196,"raw_json":"{\"stream\":\"btcusdt@bookTicker\",\"data\":{\"e\":\"bookTicker\",\"u\":11478511870935,\"s\":\"BTCUSDT\",\"ps\":\"BTCUSDT\",\"b\":\"79596.90\",\"B\":\"7.015\",\"a\":\"79597.00\",\"A\":\"7.642\",\"T\":1788567788196,\"E\":1788567788196,\"st\":1}}"}
{"receive_ns":1788567788206863000,"stream":"btcusdt@depth@100ms","event_type":"depthUpdate","event_time_ms":1788567788199,"raw_json":"{\"stream\":\"btcusdt@depth@100ms\",\"data\":{\"e\":\"depthUpdate\",\"E\":1788567788199,\"T\":1788567788198,\"s\":\"BTCUSDT\",\"ps\":\"BTCUSDT\",\"U\":11478511862918,\"u\":11478511871015,\"pu\":11478511862772,\"b\":[[\"1000.00\",\"24.604\"],[\"29196.90\",\"0.840\"],[\"29296.90\",\"1.260\"],[\"63677.50\",\"0.000\"],[\"63678.00\",\"0.010\"],[\"71637.20\",\"0.002\"],[\"76413.00\",\"0.023\"],[\"78800.90\",\"12.255\"],[\"79596.90\",\"7.015\"]],\"a\":[[\"79597.60\",\"0.091\"],[\"79597.80\",\"0.005\"],[\"79597.90\",\"0.002\"],[\"79598.00\",\"0.081\"],[\"79598.10\",\"0.000\"],[\"79599.90\",\"0.028\"],[\"79600.00\",\"0.075\"],[\"79600.10\",\"0.028\"],[\"79638.00\",\"0.127\"],[\"79638.10\",\"0.014\"],[\"79806.00\",\"3.079\"],[\"80233.80\",\"7.339\"],[\"80393.00\",\"14.149\"],[\"80472.60\",\"8.688\"]],\"st\":1}}"}
{"receive_ns":1788567788295916000,"stream":"btcusdt@depth@100ms","event_type":"depthUpdate","event_time_ms":1788567788301,"raw_json":"{\"stream\":\"btcusdt@depth@100ms\",\"data\":{\"e\":\"depthUpdate\",\"E\":1788567788301,\"T\":1788567788299,\"s\":\"BTCUSDT\",\"ps\":\"BTCUSDT\",\"U\":11478511871273,\"u\":11478511878093,\"pu\":11478511871015,\"b\":[[\"29196.90\",\"1.015\"],[\"29296.90\",\"1.085\"],[\"71637.20\",\"0.002\"],[\"76413.00\",\"0.025\"],[\"78800.90\",\"12.255\"],[\"79198.90\",\"3.981\"]],\"a\":[[\"79604.20\",\"0.007\"],[\"79604.70\",\"0.002\"],[\"79626.50\",\"0.009\"],[\"79638.00\",\"0.002\"],[\"79819.10\",\"7.014\"],[\"80393.00\",\"14.147\"],[\"80673.30\",\"0.988\"]],\"st\":1}}"}
{"receive_ns":1788567788414747000,"stream":"btcusdt@depth@100ms","event_type":"depthUpdate","event_time_ms":1788567788403,"raw_json":"{\"stream\":\"btcusdt@depth@100ms\",\"data\":{\"e\":\"depthUpdate\",\"E\":1788567788403,\"T\":1788567788402,\"s\":\"BTCUSDT\",\"ps\":\"BTCUSDT\",\"U\":11478511878285,\"u\":11478511884746,\"pu\":11478511878093,\"b\":[[\"1000.00\",\"24.604\"],[\"29196.90\",\"1.197\"],[\"29296.90\",\"0.903\"],[\"63678.00\",\"0.010\"],[\"71637.20\",\"0.002\"],[\"75617.00\",\"0.024\"],[\"75617.10\",\"0.006\"],[\"75617.20\",\"0.006\"],[\"78562.10\",\"9.183\"],[\"78641.70\",\"34.824\"],[\"78800.90\",\"12.255\"],[\"79572.20\",\"0.629\"],[\"79573.30\",\"0.439\"],[\"79581.20\",\"0.001\"],[\"79589.20\",\"0.005\"],[\"79589.40\",\"0.001\"],[\"79589.70\",\"0.116\"],[\"79590.00\",\"0.094\"],[\"79593.40\",\"0.001\"]],\"a\":[[\"79597.90\",\"0.002\"],[\"79598.20\",\"0.028\"],[\"79598.30\",\"0.028\"],[\"79600.30\",\"0.028\"],[\"79604.20\",\"0.007\"],[\"79604.70\",\"0.002\"],[\"79610.90\",\"0.442\"],[\"79612.80\",\"0.003\"],[\"79616.00\",\"0.381\"],[\"79617.20\",\"0.002\"],[\"79638.10\",\"0.139\"],[\"79657.50\",\"0.019\"],[\"80393.00\",\"14.147\"],[\"80552.20\",\"34.314\"],[\"80592.00\",\"10.074\"]],\"st\":1}}"}
{"receive_ns":1788567788426169000,"stream":"btcusdt@bookTicker","event_type":"bookTicker","event_time_ms":1788567788437,"raw_json":"{\"stream\":\"btcusdt@bookTicker\",\"data\":{\"e\":\"bookTicker\",\"u\":11478511887016,\"s\":\"BTCUSDT\",\"ps\":\"BTCUSDT\",\"b\":\"79596.90\",\"B\":\"7.015\",\"a\":\"79597.00\",\"A\":\"7.623\",\"T\":1788567788436,\"E\":1788567788437,\"st\":1}}"}
{"receive_ns":1788567788434805000,"stream":"btcusdt@bookTicker","event_type":"bookTicker","event_time_ms":1788567788439,"raw_json":"{\"stream\":\"btcusdt@bookTicker\",\"data\":{\"e\":\"bookTicker\",\"u\":11478511887187,\"s\":\"BTCUSDT\",\"ps\":\"BTCUSDT\",\"b\":\"79596.90\",\"B\":\"7.015\",\"a\":\"79597.00\",\"A\":\"7.643\",\"T\":1788567788439,\"E\":1788567788439,\"st\":1}}"}
{"receive_ns":1788567788475677000,"stream":"btcusdt@bookTicker","event_type":"bookTicker","event_time_ms":1788567788487,"raw_json":"{\"stream\":\"btcusdt@bookTicker\",\"data\":{\"e\":\"bookTicker\",\"u\":11478511889263,\"s\":\"BTCUSDT\",\"ps\":\"BTCUSDT\",\"b\":\"79596.90\",\"B\":\"6.995\",\"a\":\"79597.00\",\"A\":\"7.643\",\"T\":1788567788486,\"E\":1788567788487,\"st\":1}}"}
{"receive_ns":1788567788482474000,"stream":"btcusdt@trade","event_type":"trade","event_time_ms":1788567788487,"raw_json":"{\"stream\":\"btcusdt@trade\",\"data\":{\"e\":\"trade\",\"E\":1788567788487,\"T\":1788567788486,\"s\":\"BTCUSDT\",\"t\":8054122877,\"p\":\"79596.90\",\"q\":\"0.020\",\"X\":\"MARKET\",\"m\":true,\"st\":1}}"}
{"receive_ns":1788567788493987000,"stream":"btcusdt@depth@100ms","event_type":"depthUpdate","event_time_ms":1788567788505,"raw_json":"{\"stream\":\"btcusdt@depth@100ms\",\"data\":{\"e\":\"depthUpdate\",\"E\":1788567788505,\"T\":1788567788501,\"s\":\"BTCUSDT\",\"ps\":\"BTCUSDT\",\"U\":11478511884894,\"u\":11478511890024,\"pu\":11478511884746,\"b\":[[\"29196.90\",\"1.372\"],[\"29296.90\",\"0.728\"],[\"71637.20\",\"0.002\"],[\"76413.00\",\"0.023\"],[\"76506.50\",\"0.002\"],[\"78800.90\",\"12.255\"],[\"79475.60\",\"0.520\"],[\"79477.50\",\"0.003\"],[\"79525.20\",\"0.002\"],[\"79573.20\",\"0.663\"],[\"79588.80\",\"0.255\"],[\"79592.10\",\"0.000\"],[\"79596.90\",\"6.995\"]],\"a\":[[\"79597.00\",\"7.643\"],[\"79597.60\",\"0.117\"],[\"79600.30\",\"0.002\"],[\"79604.20\",\"0.008\"],[\"79604.70\",\"0.001\"],[\"79660.70\",\"0.006\"],[\"79692.60\",\"0.004\"],[\"79718.90\",\"0.489\"],[\"80393.00\",\"14.147\"],[\"80592.00\",\"10.352\"],[\"81188.90\",\"0.015\"]],\"st\":1}}"}
{"receive_ns":1788567788548066000,"stream":"btcusdt@bookTicker","event_type":"bookTicker","event_time_ms":1788567788564,"raw_json":"{\"stream\":\"btcusdt@bookTicker\",\"data\":{\"e\":\"bookTicker\",\"u\":11478511893640,\"s\":\"BTCUSDT\",\"ps\":\"BTCUSDT\",\"b\":\"79596.90\",\"B\":\"6.971\",\"a\":\"79597.00\",\"A\":\"7.643\",\"T\":1788567788564,\"E\":1788567788564,\"st\":1}}"}
{"receive_ns":1788567788553995000,"stream":"btcusdt@bookTicker","event_type":"bookTicker","event_time_ms":1788567788568,"raw_json":"{\"stream\":\"btcusdt@bookTicker\",\"data\":{\"e\":\"bookTicker\",\"u\":11478511893889,\"s\":\"BTCUSDT\",\"ps\":\"BTCUSDT\",\"b\":\"79596.90\",\"B\":\"6.994\",\"a\":\"79597.00\",\"A\":\"7.643\",\"T\":1788567788567,\"E\":1788567788568,\"st\":1}}"}
{"receive_ns":1788567788575997000,"stream":"btcusdt@bookTicker","event_type":"bookTicker","event_time_ms":1788567788582,"raw_json":"{\"stream\":\"btcusdt@bookTicker\",\"data\":{\"e\":\"bookTicker\",\"u\":11478511894453,\"s\":\"BTCUSDT\",\"ps\":\"BTCUSDT\",\"b\":\"79596.90\",\"B\":\"6.994\",\"a\":\"79597.00\",\"A\":\"7.666\",\"T\":1788567788582,\"E\":1788567788582,\"st\":1}}"}
{"receive_ns":1788567788598137000,"stream":"btcusdt@depth@100ms","event_type":"depthUpdate","event_time_ms":1788567788607,"raw_json":"{\"stream\":\"btcusdt@depth@100ms\",\"data\":{\"e\":\"depthUpdate\",\"E\":1788567788607,\"T\":1788567788605,\"s\":\"BTCUSDT\",\"ps\":\"BTCUSDT\",\"U\":11478511890160,\"u\":11478511895425,\"pu\":11478511890024,\"b\":[[\"29196.90\",\"1.554\"],[\"29296.90\",\"0.546\"],[\"63678.00\",\"0.010\"],[\"71637.20\",\"0.002\"],[\"76413.00\",\"0.025\"],[\"78562.10\",\"11.090\"],[\"78601.90\",\"13.645\"],[\"78800.90\",\"13.205\"],[\"79198.90\",\"3.981\"],[\"79572.90\",\"0.171\"],[\"79573.20\",\"0.538\"],[\"79587.90\",\"0.143\"],[\"79589.70\",\"0.112\"],[\"79590.00\",\"0.098\"],[\"79596.90\",\"6.994\"]],\"a\":[[\"79597.00\",\"7.666\"],[\"80393.00\",\"14.147\"]],\"st\":1}}"}
{"receive_ns":1788567788701038000,"stream":"btcusdt@depth@100ms","event_type":"depthUpdate","event_time_ms":1788567788709,"raw_json":"{\"stream\":\"btcusdt@depth@100ms\",\"data\":{\"e\":\"depthUpdate\",\"E\":1788567788709,\"T\":1788567788707,\"s\":\"BTCUSDT\",\"ps\":\"BTCUSDT\",\"U\":11478511895464,\"u\":11478511901816,\"pu\":11478511895425,\"b\":[[\"1000.00\",\"24.604\"],[\"29196.90\",\"1.729\"],[\"29296.90\",\"0.371\"],[\"63678.00\",\"0.010\"],[\"71637.20\",\"0.002\"],[\"76413.00\",\"0.023\"],[\"78647.90\",\"13.871\"],[\"78800.90\",\"13.205\"],[\"79525.20\",\"0.000\"],[\"79541.10\",\"1.098\"],[\"79565.80\",\"0.046\"],[\"79567.20\",\"0.002\"],[\"79572.30\",\"0.439\"],[\"79573.30\",\"0.000\"],[\"79575.30\",\"0.510\"],[\"79576.10\",\"0.009\"],[\"79576.30\",\"0.137\"],[\"79576.90\",\"0.008\"],[\"79584.90\",\"2.746\"],[\"79585.00\",\"0.035\"],[\"79585.10\",\"0.251\"],[\"79586.10\",\"0.381\"],[\"79589.70\",\"0.112\"],[\"79590.00\",\"0.098\"],[\"79591.50\",\"0.000\"],[\"79591.80\",\"0.004\"],[\"79592.30\",\"0.076\"]],\"a\":[[\"79597.60\",\"0.091\"],[\"79605.30\",\"0.066\"],[\"79605.40\",\"0.415\"],[\"79618.30\",\"0.543\"],[\"79619.30\",\"0.001\"],[\"79620.30\",\"0.627\"],[\"79625.90\",\"0.002\"],[\"79626.30\",\"0.008\"],[\"79629.70\",\"0.068\"],[\"79631.70\",\"0.000\"],[\"79668.70\",\"2.054\"],[\"79692.60\",\"0.002\"],[\"79806.00\",\"5.027\"],[\"80393.00\",\"14.149\"],[\"87556.70\",\"0.002\"]],\"st\":1}}"}
{"receive_ns":1788567788802889000,"stream":"btcusdt@depth@100ms","event_type":"depthUpdate","event_time_ms":1788567788811,"raw_json":"{\"stream\":\"btcusdt@depth@100ms\",\"data\":{\"e\":\"depthUpdate\",\"E\":1788567788811,\"T\":1788567788809,\"s\":\"BTCUSDT\",\"ps\":\"BTCUSDT\",\"U\":11478511901931,\"u\":11478511907123,\"pu\":11478511901816,\"b\":[[\"29096.90\",\"0.056\"],[\"29196.90\",\"1.799\"],[\"29296.90\",\"0.245\"],[\"71637.20\",\"0.002\"],[\"75617.10\",\"0.008\"],[\"76413.00\",\"0.025\"],[\"78005.00\",\"0.219\"],[\"78442.70\",\"15.251\"],[\"78800.90\",\"13.205\"],[\"79572.30\",\"0.000\"],[\"79573.30\",\"0.439\"],[\"79575.30\",\"0.137\"],[\"79576.50\",\"0.373\"],[\"79589.70\",\"0.116\"],[\"79590.00\",\"0.094\"]],\"a\":[[\"79598.20\",\"0.002\"],[\"79604.00\",\"0.172\"],[\"79605.60\",\"1.894\"],[\"79618.30\",\"0.091\"],[\"79619.70\",\"0.454\"],[\"79626.50\",\"0.003\"],[\"79628.40\",\"0.006\"],[\"79629.70\",\"0.022\"],[\"79630.80\",\"0.047\"],[\"79806.00\",\"3.117\"],[\"80393.00\",\"14.147\"],[\"80631.80\",\"8.723\"],[\"87556.70\",\"0.000\"]],\"st\":1}}"}
{"receive_ns":1788567788901465000,"stream":"btcusdt@depth@100ms","event_type":"depthUpdate","event_time_ms":1788567788913,"raw_json":"{\"stream\":\"btcusdt@depth@100ms\",\"data\":{\"e\":\"depthUpdate\",\"E\":1788567788913,\"T\":1788567788909,\"s\":\"BTCUSDT\",\"ps\":\"BTCUSDT\",\"U\":11478511907496,\"u\":11478511914542,\"pu\":11478511907123,\"b\":[[\"29096.90\",\"0.112\"],[\"29196.90\",\"1.862\"],[\"29296.90\",\"0.126\"],[\"63678.00\",\"0.010\"],[\"71637.20\",\"0.002\"],[\"71673.00\",\"0.000\"],[\"78800.90\",\"13.205\"],[\"79198.90\",\"3.971\"]],\"a\":[[\"79606.90\",\"0.001\"],[\"79607.20\",\"0.255\"],[\"79819.10\",\"6.997\"],[\"80194.00\",\"4.549\"],[\"80393.00\",\"14.147\"]],\"st\":1}}"}
{"receive_ns":1788567789003998000,"stream":"btcusdt@depth@100ms","event_type":"depthUpdate","event_time_ms":1788567789015,"raw_json":"{\"stream\":\"btcusdt@depth@100ms\",\"data\":{\"e\":\"depthUpdate\",\"E\":1788567789015,\"T\":1788567789013,\"s\":\"BTCUSDT\",\"ps\":\"BTCUSDT\",\"U\":11478511914736,\"u\":11478511919672,\"pu\":11478511914542,\"b\":[[\"1000.00\",\"24.604\"],[\"29096.90\",\"0.182\"],[\"29196.90\",\"1.904\"],[\"29296.90\",\"0.014\"],[\"63678.00\",\"0.010\"],[\"71637.20\",\"0.002\"],[\"76413.00\",\"0.023\"],[\"78488.70\",\"10.902\"],[\"78598.80\",\"0.004\"],[\"78601.60\",\"0.000\"],[\"78800.90\",\"13.204\"],[\"79551.80\",\"0.001\"],[\"79561.20\",\"0.019\"],[\"79563.10\",\"0.266\"],[\"79572.90\",\"0.046\"],[\"79573.20\",\"0.538\"]],\"a\":[[\"79613.10\",\"0.194\"],[\"80393.00\",\"14.147\"]],\"st\":1}}"}
{"receive_ns":1788567789076150000,"stream":"btcusdt@bookTicker","event_type":"bookTicker","event_time_ms":1788567789088,"raw_json":"{\"stream\":\"btcusdt@bookTicker\",\"data\":{\"e\":\"bookTicker\",\"u\":11478511923967,\"s\":\"BTCUSDT\",\"ps\":\"BTCUSDT\",\"b\":\"79596.90\",\"B\":\"6.994\",\"a\":\"79597.00\",\"A\":\"7.663\",\"T\":1788567789088,\"E\":1788567789088,\"st\":1}}"}
{"receive_ns":1788567789081819000,"stream":"btcusdt@trade","event_type":"trade","event_time_ms":1788567789088,"raw_json":"{\"stream\":\"btcusdt@trade\",\"data\":{\"e\":\"trade\",\"E\":1788567789088,\"T\":1788567789088,\"s\":\"BTCUSDT\",\"t\":8054122878,\"p\":\"79597.00\",\"q\":\"0.003\",\"X\":\"MARKET\",\"m\":false,\"st\":1}}"}
{"receive_ns":1788567789092661000,"stream":"btcusdt@bookTicker","event_type":"bookTicker","event_time_ms":1788567789090,"raw_json":"{\"stream\":\"btcusdt@bookTicker\",\"data\":{\"e\":\"bookTicker\",\"u\":11478511924143,\"s\":\"BTCUSDT\",\"ps\":\"BTCUSDT\",\"b\":\"79596.90\",\"B\":\"6.827\",\"a\":\"79597.00\",\"A\":\"7.663\",\"T\":1788567789090,\"E\":1788567789090,\"st\":1}}"}
{"receive_ns":1788567789103354000,"stream":"btcusdt@bookTicker","event_type":"bookTicker","event_time_ms":1788567789096,"raw_json":"{\"stream\":\"btcusdt@bookTicker\",\"data\":{\"e\":\"bookTicker\",\"u\":11478511924395,\"s\":\"BTCUSDT\",\"ps\":\"BTCUSDT\",\"b\":\"79596.90\",\"B\":\"6.827\",\"a\":\"79597.00\",\"A\":\"7.662\",\"T\":1788567789096,\"E\":1788567789096,\"st\":1}}"}
{"receive_ns":1788567789109327000,"stream":"btcusdt@trade","event_type":"trade","event_time_ms":1788567789096,"raw_json":"{\"stream\":\"btcusdt@trade\",\"data\":{\"e\":\"trade\",\"E\":1788567789096,\"T\":1788567789096,\"s\":\"BTCUSDT\",\"t\":8054122879,\"p\":\"79597.00\",\"q\":\"0.001\",\"X\":\"MARKET\",\"m\":false,\"st\":1}}"}
{"receive_ns":1788567789115498000,"stream":"btcusdt@depth@100ms","event_type":"depthUpdate","event_time_ms":1788567789117,"raw_json":"{\"stream\":\"btcusdt@depth@100ms\",\"data\":{\"e\":\"depthUpdate\",\"E\":1788567789117,\"T\":1788567789116,\"s\":\"BTCUSDT\",\"ps\":\"BTCUSDT\",\"U\":11478511919775,\"u\":11478511925403,\"pu\":11478511919672,\"b\":[[\"29096.90\",\"0.343\"],[\"29196.90\",\"1.757\"],[\"29296.90\",\"0.000\"],[\"63678.00\",\"0.010\"],[\"71637.20\",\"0.002\"],[\"76413.00\",\"0.025\"],[\"78094.70\",\"0.638\"],[\"78243.80\",\"9.249\"],[\"78602.00\",\"8.539\"],[\"78641.70\",\"34.443\"],[\"78687.70\",\"2.517\"],[\"78800.90\",\"13.206\"],[\"79198.90\",\"3.970\"],[\"79436.10\",\"0.340\"],[\"79436.20\",\"2.645\"],[\"79475.60\",\"0.520\"],[\"79537.90\",\"1.030\"],[\"79553.80\",\"0.000\"],[\"79573.30\",\"0.564\"],[\"79582.60\",\"0.070\"],[\"79589.70\",\"0.112\"],[\"79596.90\",\"6.827\"]],\"a\":[[\"79597.00\",\"7.662\"],[\"79598.30\",\"0.002\"],[\"79598.40\",\"0.259\"],[\"79600.30\",\"0.028\"],[\"79600.40\",\"0.034\"],[\"79604.20\",\"0.007\"],[\"79604.30\",\"0.006\"],[\"79612.00\",\"0.694\"],[\"79627.90\",\"0.830\"],[\"79718.90\",\"0.489\"],[\"79758.30\",\"2.166\"],[\"79758.50\",\"0.000\"],[\"79995.00\",\"4.696\"],[\"80393.00\",\"14.147\"],[\"80951.80\",\"0.493\"]],\"st\":1}}"}
{"receive_ns":1788567789127295000,"stream":"btcusdt@bookTicker","event_type":"bookTicker","event_time_ms":1788567789143,"raw_json":"{\"stream\":\"btcusdt@bookTicker\",\"data\":{\"e\":\"bookTicker\",\"u\":11478511926513,\"s\":\"BTCUSDT\",\"ps\":\"BTCUSDT\",\"b\":\"79596.90\",\"B\":\"6.834\",\"a\":\"79597.00\",\"A\":\"7.662\",\"T\":1788567789143,\"E\":1788567789143,\"st\":1}}"}
{"receive_ns":1788567789138461000,"stream":"btcusdt@bookTicker","event_type":"bookTicker","event_time_ms":1788567789144,"raw_json":"{\"stream\":\"btcusdt@bookTicker\",\"data\":{\"e\":\"bookTicker\",\"u\":11478511926602,\"s\":\"BTCUSDT\",\"ps\":\"BTCUSDT\",\"b\":\"79596.90\",\"B\":\"6.827\",\"a\":\"79597.00\",\"A\":\"7.662\",\"T\":1788567789144,\"E\":1788567789144,\"st\":1}}"}
{"receive_ns":1788567789212855000,"stream":"btcusdt@depth@100ms","event_type":"depthUpdate","event_time_ms":1788567789219,"raw_json":"{\"stream\":\"btcusdt@depth@100ms\",\"data\":{\"e\":\"depthUpdate\",\"E\":1788567789219,\"T\":1788567789217,\"s\":\"BTCUSDT\",\"ps\":\"BTCUSDT\",\"U\":11478511925419,\"u\":11478511929922,\"pu\":11478511925403,\"b\":[[\"29096.90\",\"0.525\"],[\"29196.90\",\"1.575\"],[\"63677.50\",\"0.000\"],[\"71637.20\",\"0.002\"],[\"76413.00\",\"0.023\"],[\"78522.40\",\"11.228\"],[\"78800.90\",\"13.204\"],[\"79198.90\",\"3.971\"],[\"79377.30\",\"0.019\"],[\"79463.10\",\"0.300\"],[\"79539.50\",\"0.151\"],[\"79589.70\",\"0.112\"],[\"79590.00\",\"0.098\"],[\"79596.80\",\"0.183\"],[\"79596.90\",\"6.827\"]],\"a\":[[\"79597.40\",\"0.005\"],[\"79598.10\",\"0.026\"],[\"79598.50\",\"0.000\"],[\"79599.10\",\"0.104\"],[\"79806.00\",\"3.117\"],[\"79995.00\",\"4.697\"],[\"80393.00\",\"14.147\"],[\"80549.60\",\"2.792\"]],\"st\":1}}"}
{"receive_ns":1788567789310232000,"stream":"btcusdt@depth@100ms","event_type":"depthUpdate","event_time_ms":1788567789321,"raw_json":"{\"stream\":\"btcusdt@depth@100ms\",\"data\":{\"e\":\"depthUpdate\",\"E\":1788567789321,\"T\":1788567789317,\"s\":\"BTCUSDT\",\"ps\":\"BTCUSDT\",\"U\":11478511930081,\"u\":11478511935062,\"pu\":11478511929922,\"b\":[[\"1000.00\",\"24.604\"],[\"29096.90\",\"0.700\"],[\"29196.90\",\"1.400\"],[\"71637.20\",\"0.002\"],[\"76413.00\",\"0.025\"],[\"78005.00\",\"0.216\"],[\"78230.00\",\"6.250\"],[\"79377.20\",\"0.517\"],[\"79565.80\",\"0.000\"],[\"79567.90\",\"0.046\"],[\"79568.90\",\"0.003\"],[\"79570.90\",\"0.454\"],[\"79573.30\",\"0.439\"],[\"79575.70\",\"0.008\"],[\"79576.90\",\"0.002\"],[\"79589.70\",\"0.112\"],[\"79590.00\",\"0.098\"]],\"a\":[[\"79610.90\",\"0.003\"],[\"79611.90\",\"0.440\"],[\"79616.00\",\"0.009\"],[\"79617.20\",\"0.374\"],[\"79619.70\",\"0.002\"],[\"79620.60\",\"0.454\"],[\"79621.90\",\"0.000\"],[\"79630.80\",\"0.001\"],[\"79631.70\",\"0.046\"],[\"79665.40\",\"4.854\"],[\"79666.10\",\"21.843\"],[\"79668.50\",\"2.666\"],[\"79668.80\",\"0.034\"],[\"80393.00\",\"14.147\"]],\"st\":1}}"}
{"receive_ns":1788567789363665000,"stream":"btcusdt@bookTicker","event_type":"bookTicker","event_time_ms":1788567789367,"raw_json":"{\"stream\":\"btcusdt@bookTicker\",\"data\":{\"e\":\"bookTicker\",\"u\":11478511936829,\"s\":\"BTCUSDT\",\"ps\":\"BTCUSDT\",\"b\":\"79596.90\",\"B\":\"6.994\",\"a\":\"79597.00\",\"A\":\"7.662\",\"T\":1788567789367,\"E\":1788567789367,\"st\":1}}"}
{"receive_ns":1788567789412748000,"stream":"btcusdt@depth@100ms","event_type":"depthUpdate","event_time_ms":1788567789423,"raw_json":"{\"stream\":\"btcusdt@depth@100ms\",\"data\":{\"e\":\"depthUpdate\",\"E\":1788567789423,\"T\":1788567789421,\"s\":\"BTCUSDT\",\"ps\":\"BTCUSDT\",\"U\":11478511935212,\"u\":11478511938992,\"pu\":11478511935062,\"b\":[[\"29096.90\",\"0.882\"],[\"29196.90\",\"1.218\"],[\"71637.20\",\"0.002\"],[\"78005.00\",\"0.219\"],[\"78800.90\",\"13.204\"],[\"79377.20\",\"0.309\"],[\"79566.70\",\"0.046\"],[\"79567.90\",\"0.000\"],[\"79568.90\",\"0.455\"],[\"79570.90\",\"0.002\"],[\"79573.80\",\"0.074\"],[\"79589.70\",\"0.116\"],[\"79590.00\",\"0.094\"],[\"79596.90\",\"6.994\"]],\"a\":[[\"79597.10\",\"0.739\"],[\"79598.10\",\"0.000\"],[\"79598.70\",\"0.030\"],[\"79610.90\",\"0.442\"],[\"79611.90\",\"0.001\"],[\"79612.00\",\"0.003\"],[\"79806.00\",\"3.079\"],[\"80011.70\",\"0.087\"],[\"80393.00\",\"14.147\"]],\"st\":1}}"}
{"receive_ns":1788567789435649000,"stream":"btcusdt@bookTicker","event_type":"bookTicker","event_time_ms":1788567789446,"raw_json":"{\"stream\":\"btcusdt@bookTicker\",\"data\":{\"e\":\"bookTicker\",\"u\":11478511939841,\"s\":\"BTCUSDT\",\"ps\":\"BTCUSDT\",\"b\":\"79596.90\",\"B\":\"6.994\",\"a\":\"79597.00\",\"A\":\"7.642\",\"T\":1788567789446,\"E\":1788567789446,\"st\":1}}"}
{"receive_ns":1788567789448255000,"stream":"btcusdt@bookTicker","event_type":"bookTicker","event_time_ms":1788567789448,"raw_json":"{\"stream\":\"btcusdt@bookTicker\",\"data\":{\"e\":\"bookTicker\",\"u\":11478511939979,\"s\":\"BTCUSDT\",\"ps\":\"BTCUSDT\",\"b\":\"79596.90\",\"B\":\"6.994\",\"a\":\"79597.00\",\"A\":\"7.664\",\"T\":1788567789448,\"E\":1788567789448,\"st\":1}}"}
{"receive_ns":1788567789514402000,"stream":"btcusdt@depth@100ms","event_type":"depthUpdate","event_time_ms":1788567789525,"raw_json":"{\"stream\":\"btcusdt@depth@100ms\",\"data\":{\"e\":\"depthUpdate\",\"E\":1788567789525,\"T\":1788567789522,\"s\":\"BTCUSDT\",\"ps\":\"BTCUSDT\",\"U\":11478511939095,\"u\":11478511942651,\"pu\":11478511938992,\"b\":[[\"29096.90\",\"1.057\"],[\"29196.90\",\"1.043\"],[\"71637.20\",\"0.002\"],[\"76413.00\",\"0.023\"],[\"78005.00\",\"0.216\"],[\"78447.50\",\"0.946\"],[\"78800.90\",\"14.471\"],[\"79198.90\",\"3.981\"],[\"79377.20\",\"0.106\"],[\"79451.30\",\"0.001\"],[\"79451.40\",\"1.884\"]],\"a\":[[\"79597.00\",\"7.664\"],[\"79597.10\",\"0.741\"],[\"79597.70\",\"0.000\"],[\"79598.00\",\"0.107\"],[\"79600.40\",\"0.008\"],[\"79683.00\",\"0.000\"],[\"79719.70\",\"0.000\"],[\"79719.80\",\"1.884\"],[\"80393.00\",\"14.147\"],[\"80671.60\",\"6.705\"]],\"st\":1}}"}
{"receive_ns":1788567789619092000,"stream":"btcusdt@depth@100ms","event_type":"depthUpdate","event_time_ms":1788567789627,"raw_json":"{\"stream\":\"btcusdt@depth@100ms\",\"data\":{\"e\":\"depthUpdate\",\"E\":1788567789627,\"T\":1788567789625,\"s\":\"BTCUSDT\",\"ps\":\"BTCUSDT\",\"U\":11478511942740,\"u\":11478511946181,\"pu\":11478511942651,\"b\":[[\"1000.00\",\"24.604\"],[\"29096.90\",\"1.239\"],[\"29196.90\",\"0.861\"],[\"71637.20\",\"0.002\"],[\"76413.00\",\"0.025\"],[\"78506.40\",\"1.016\"],[\"78562.10\",\"12.997\"],[\"78800.90\",\"14.471\"],[\"78999.90\",\"3.793\"],[\"79198.90\",\"3.983\"],[\"79355.80\",\"0.106\"],[\"79377.20\",\"0.000\"],[\"79537.70\",\"3.502\"],[\"79539.00\",\"1.327\"],[\"79565.80\",\"0.046\"],[\"79566.70\",\"0.000\"],[\"79572.30\",\"0.000\"],[\"79573.30\",\"0.564\"],[\"79573.80\",\"0.074\"],[\"79575.30\",\"0.510\"],[\"79576.50\",\"0.000\"],[\"79593.60\",\"0.003\"]],\"a\":[[\"79598.00\",\"0.081\"],[\"79598.50\",\"0.026\"],[\"79615.20\",\"0.001\"],[\"79616.40\",\"2.104\"],[\"79617.20\",\"0.002\"],[\"79629.70\",\"0.022\"],[\"79630.80\",\"0.047\"],[\"79631.70\",\"0.000\"],[\"79633.50\",\"2.770\"],[\"79634.40\",\"0.022\"],[\"79636.90\",\"0.064\"],[\"79638.10\",\"0.014\"],[\"79806.00\",\"3.079\"],[\"80393.00\",\"14.147\"],[\"80673.30\",\"0.494\"]],\"st\":1}}"}
{"receive_ns":1788567789720945000,"stream":"btcusdt@depth@100ms","event_type":"depthUpdate","event_time_ms":1788567789729,"raw_json":"{\"stream\":\"btcusdt@depth@100ms\",\"data\":{\"e\":\"depthUpdate\",\"E\":1788567789729,\"T\":1788567789725,\"s\":\"BTCUSDT\",\"ps\":\"BTCUSDT\",\"U\":11478511946236,\"u\":11478511950324,\"pu\":11478511946181,\"b\":[[\"29096.90\",\"1.414\"],[\"29196.90\",\"0.686\"],[\"71637.20\",\"0.002\"],[\"76413.00\",\"0.023\"],[\"78800.90\",\"14.471\"],[\"79198.90\",\"3.981\"],[\"79553.50\",\"0.859\"],[\"79565.80\",\"0.000\"],[\"79566.70\",\"0.046\"],[\"79567.90\",\"0.000\"],[\"79568.90\",\"0.455\"],[\"79570.00\",\"0.005\"],[\"79571.70\",\"0.146\"],[\"79573.30\",\"0.439\"],[\"79575.30\",\"0.137\"],[\"79575.70\",\"0.002\"],[\"79576.20\",\"0.620\"],[\"79576.40\",\"2.903\"],[\"79577.40\",\"0.000\"],[\"79586.10\",\"0.319\"],[\"79586.20\",\"0.064\"],[\"79591.80\",\"0.000\"],[\"79591.90\",\"0.347\"]],\"a\":[[\"79597.80\",\"0.031\"],[\"79598.40\",\"0.285\"],[\"79600.30\",\"0.002\"],[\"79606.80\",\"0.506\"],[\"79607.20\",\"0.004\"],[\"79610.70\",\"0.545\"],[\"79610.90\",\"0.003\"],[\"79612.80\",\"0.003\"],[\"79616.40\",\"1.732\"],[\"79617.30\",\"0.438\"],[\"79619.70\",\"0.002\"],[\"79620.50\",\"0.453\"],[\"79620.60\",\"0.002\"],[\"79630.80\",\"0.001\"],[\"79631.90\",\"0.046\"],[\"79636.30\",\"0.221\"],[\"79637.30\",\"0.012\"],[\"79663.90\",\"0.048\"],[\"79806.00\",\"3.079\"],[\"80393.00\",\"14.147\"]],\"st\":1}}"}
{"receive_ns":1788567789820682000,"stream":"btcusdt@depth@100ms","event_type":"depthUpdate","event_time_ms":1788567789831,"raw_json":"{\"stream\":\"btcusdt@depth@100ms\",\"data\":{\"e\":\"depthUpdate\",\"E\":1788567789831,\"T\":1788567789830,\"s\":\"BTCUSDT\",\"ps\":\"BTCUSDT\",\"U\":11478511950453,\"u\":11478511955551,\"pu\":11478511950324,\"b\":[[\"1000.00\",\"24.604\"],[\"29096.90\",\"1.596\"],[\"29196.90\",\"0.504\"],[\"71637.20\",\"0.002\"],[\"78800.90\",\"14.471\"],[\"79198.90\",\"3.981\"],[\"79553.50\",\"0.860\"]],\"a\":[[\"79597.80\",\"0.005\"],[\"79626.00\",\"0.949\"],[\"79628.40\",\"0.000\"],[\"79663.90\",\"0.049\"],[\"80393.00\",\"14.147\"],[\"80727.30\",\"1.776\"]],\"st\":1}}"}
{"receive_ns":1788567789918065000,"stream":"btcusdt@depth@100ms","event_type":"depthUpdate","event_time_ms":1788567789933,"raw_json":"{\"stream\":\"btcusdt@depth@100ms\",\"data\":{\"e\":\"depthUpdate\",\"E\":1788567789933,\"T\":1788567789931,\"s\":\"BTCUSDT\",\"ps\":\"BTCUSDT\",\"U\":11478511955713,\"u\":11478511960744,\"pu\":11478511955551,\"b\":[[\"1000.00\",\"24.604\"],[\"29096.90\",\"1.757\"],[\"29196.90\",\"0.336\"],[\"29496.90\",\"0.007\"],[\"71637.20\",\"0.002\"],[\"76413.00\",\"0.025\"],[\"78800.90\",\"14.471\"]],\"a\":[[\"79637.20\",\"0.000\"],[\"79637.50\",\"0.000\"],[\"80355.50\",\"0.000\"],[\"80393.00\",\"14.147\"]],\"st\":1}}"}
{"receive_ns":1788567790025370000,"stream":"btcusdt@depth@100ms","event_type":"depthUpdate","event_time_ms":1788567790035,"raw_json":"{\"stream\":\"btcusdt@depth@100ms\",\"data\":{\"e\":\"depthUpdate\",\"E\":1788567790035,\"T\":1788567790034,\"s\":\"BTCUSDT\",\"ps\":\"BTCUSDT\",\"U\":11478511960826,\"u\":11478511966342,\"pu\":11478511960744,\"b\":[[\"29096.90\",\"1.813\"],[\"29196.90\",\"0.217\"],[\"29496.90\",\"0.070\"],[\"71637.20\",\"0.002\"],[\"71673.00\",\"0.000\"],[\"76413.00\",\"0.023\"],[\"78800.90\",\"14.471\"],[\"78960.10\",\"8.335\"],[\"79520.40\",\"0.004\"],[\"79520.50\",\"0.050\"],[\"79541.10\",\"1.096\"],[\"79557.10\",\"0.002\"],[\"79573.20\",\"0.538\"]],\"a\":[[\"79597.10\",\"0.794\"],[\"79604.20\",\"0.008\"],[\"79604.30\",\"0.005\"],[\"79613.10\",\"0.194\"],[\"79615.90\",\"0.628\"],[\"79616.20\",\"1.026\"],[\"79616.30\",\"0.013\"],[\"79617.30\",\"0.066\"],[\"79619.90\",\"0.627\"],[\"79620.30\",\"0.000\"],[\"79623.80\",\"0.629\"],[\"79624.40\",\"0.000\"],[\"79630.70\",\"0.049\"],[\"79631.90\",\"0.000\"],[\"79637.40\",\"0.002\"],[\"79647.80\",\"0.091\"],[\"79648.00\",\"0.198\"],[\"79668.70\",\"2.054\"],[\"80393.00\",\"15.389\"],[\"80687.50\",\"2.966\"]],\"st\":1}}"}
{"receive_ns":1788567790128774000,"stream":"btcusdt@depth@100ms","event_type":"depthUpdate","event_time_ms":1788567790137,"raw_json":"{\"stream\":\"btcusdt@depth@100ms\",\"data\":{\"e\":\"depthUpdate\",\"E\":1788567790137,\"T\":1788567790133,\"s\":\"BTCUSDT\",\"ps\":\"BTCUSDT\",\"U\":11478511966408,\"u\":11478511972512,\"pu\":11478511966342,\"b\":[[\"1000.00\",\"24.604\"],[\"29096.90\",\"1.876\"],[\"29196.90\",\"0.098\"],[\"29496.90\",\"0.126\"],[\"71637.20\",\"0.002\"],[\"76413.00\",\"0.025\"],[\"78800.90\",\"14.471\"],[\"79198.90\",\"3.971\"],[\"79566.70\",\"0.046\"],[\"79567.60\",\"0.000\"],[\"79567.90\",\"0.000\"],[\"79575.70\",\"0.008\"],[\"79576.10\",\"0.382\"],[\"79576.20\",\"0.247\"],[\"79576.40\",\"2.897\"],[\"79577.20\",\"0.000\"],[\"79582.60\",\"0.070\"],[\"79596.80\",\"0.157\"]],\"a\":[[\"79597.40\",\"0.031\"],[\"79597.80\",\"0.031\"],[\"79600.10\",\"0.002\"],[\"79610.70\",\"0.106\"],[\"79610.90\",\"0.442\"],[\"79612.80\",\"0.003\"],[\"79616.00\",\"0.381\"],[\"79616.20\",\"0.654\"],[\"79617.20\",\"0.002\"],[\"79630.50\",\"0.046\"],[\"79630.70\",\"0.003\"],[\"79631.70\",\"0.000\"],[\"79637.70\",\"0.571\"],[\"79806.00\",\"3.079\"],[\"80393.00\",\"15.389\"],[\"80711.50\",\"10.414\"]],\"st\":1}}"}
{"receive_ns":1788567790159026000,"stream":"btcusdt@bookTicker","event_type":"bookTicker","event_time_ms":1788567790169,"raw_json":"{\"stream\":\"btcusdt@bookTicker\",\"data\":{\"e\":\"bookTicker\",\"u\":11478511975077,\"s\":\"BTCUSDT\",\"ps\":\"BTCUSDT\",\"b\":\"79596.90\",\"B\":\"6.994\",\"a\":\"79597.00\",\"A\":\"7.655\",\"T\":1788567790169,\"E\":1788567790169,\"st\":1}}"}
{"receive_ns":1788567790170164000,"stream":"btcusdt@trade","event_type":"trade","event_time_ms":1788567790169,"raw_json":"{\"stream\":\"btcusdt@trade\",\"data\":{\"e\":\"trade\",\"E\":1788567790169,\"T\":1788567790169,\"s\":\"BTCUSDT\",\"t\":8054122880,\"p\":\"79597.00\",\"q\":\"0.009\",\"X\":\"MARKET\",\"m\":false,\"st\":1}}"}
{"receive_ns":1788567790187097000,"stream":"btcusdt@bookTicker","event_type":"bookTicker","event_time_ms":1788567790185,"raw_json":"{\"stream\":\"btcusdt@bookTicker\",\"data\":{\"e\":\"bookTicker\",\"u\":11478511976161,\"s\":\"BTCUSDT\",\"ps\":\"BTCUSDT\",\"b\":\"79596.90\",\"B\":\"7.002\",\"a\":\"79597.00\",\"A\":\"7.655\",\"T\":1788567790185,\"E\":1788567790185,\"st\":1}}"}
{"receive_ns":1788567790205081000,"stream":"btcusdt@bookTicker","event_type":"bookTicker","event_time_ms":1788567790204,"raw_json":"{\"stream\":\"btcusdt@bookTicker\",\"data\":{\"e\":\"bookTicker\",\"u\":11478511977385,\"s\":\"BTCUSDT\",\"ps\":\"BTCUSDT\",\"b\":\"79596.90\",\"B\":\"7.002\",\"a\":\"79597.00\",\"A\":\"7.652\",\"T\":1788567790204,\"E\":1788567790204,\"st\":1}}"}
{"receive_ns":1788567790217628000,"stream":"btcusdt@trade","event_type":"trade","event_time_ms":1788567790204,"raw_json":"{\"stream\":\"btcusdt@trade\",\"data\":{\"e\":\"trade\",\"E\":1788567790204,\"T\":1788567790204,\"s\":\"BTCUSDT\",\"t\":8054122881,\"p\":\"79597.00\",\"q\":\"0.003\",\"X\":\"MARKET\",\"m\":false,\"st\":1}}"}
{"receive_ns":1788567790230639000,"stream":"btcusdt@depth@100ms","event_type":"depthUpdate","event_time_ms":1788567790239,"raw_json":"{\"stream\":\"btcusdt@depth@100ms\",\"data\":{\"e\":\"depthUpdate\",\"E\":1788567790239,\"T\":1788567790238,\"s\":\"BTCUSDT\",\"ps\":\"BTCUSDT\",\"U\":11478511972720,\"u\":11478511979486,\"pu\":11478511972512,\"b\":[[\"1000.00\",\"24.604\"],[\"29096.90\",\"1.890\"],[\"29196.90\",\"0.000\"],[\"29496.90\",\"0.210\"],[\"63677.50\",\"0.000\"],[\"71637.20\",\"0.002\"],[\"75617.20\",\"0.004\"],[\"76413.00\",\"0.023\"],[\"78800.90\",\"14.471\"],[\"78805.70\",\"0.000\"],[\"79198.90\",\"3.971\"],[\"79397.90\",\"0.326\"],[\"79417.90\",\"0.196\"],[\"79418.00\",\"3.141\"],[\"79509.10\",\"0.361\"],[\"79553.90\",\"0.691\"],[\"79557.10\",\"0.004\"],[\"79566.70\",\"0.046\"],[\"79567.80\",\"0.628\"],[\"79568.20\",\"0.008\"],[\"79576.10\",\"0.382\"],[\"79577.20\",\"0.000\"],[\"79592.10\",\"0.076\"],[\"79592.30\",\"0.000\"],[\"79594.50\",\"0.000\"],[\"79595.90\",\"0.002\"],[\"79596.00\",\"0.118\"],[\"79596.30\",\"0.026\"],[\"79596.50\",\"0.470\"],[\"79596.60\",\"0.002\"],[\"79596.90\",\"7.002\"]],\"a\":[[\"79597.00\",\"7.652\"],[\"79597.10\",\"0.794\"],[\"79600.00\",\"0.049\"],[\"79610.70\",\"0.734\"],[\"79610.90\",\"0.442\"],[\"79612.10\",\"0.693\"],[\"79612.80\",\"0.003\"],[\"79616.00\",\"0.381\"],[\"79616.20\",\"0.026\"],[\"79617.10\",\"0.000\"],[\"79626.00\",\"0.943\"],[\"79630.50\",\"0.000\"],[\"79631.70\",\"0.046\"],[\"79638.10\",\"0.014\"],[\"79638.20\",\"0.542\"],[\"79638.60\",\"0.520\"],[\"79665.40\",\"1.810\"],[\"79666.10\",\"0.015\"],[\"79674.20\",\"21.805\"],[\"79676.60\",\"0.019\"],[\"79684.30\",\"0.024\"],[\"79684.40\",\"0.038\"],[\"79692.60\",\"0.004\"],[\"79739.40\",\"0.000\"],[\"79739.50\",\"3.141\"],[\"79806.00\",\"3.079\"],[\"79995.00\",\"4.697\"],[\"80353.20\",\"4.751\"],[\"80359.20\",\"0.000\"],[\"80393.00\",\"14.147\"],[\"80552.20\",\"34.933\"],[\"87556.70\",\"0.000\"]],\"st\":1}}"}
{"receive_ns":1788567790246881000,"stream":"btcusdt@bookTicker","event_type":"bookTicker","event_time_ms":1788567790240,"raw_json":"{\"stream\":\"btcusdt@bookTicker\",\"data\":{\"e\":\"bookTicker\",\"u\":11478511979596,\"s\":\"BTCUSDT\",\"ps\":\"BTCUSDT\",\"b\":\"79596.90\",\"B\":\"6.993\",\"a\":\"79597.00\",\"A\":\"7.652\",\"T\":1788567790240,\"E\":1788567790240,\"st\":1}}"}
{"receive_ns":1788567790252506000,"stream":"btcusdt@bookTicker","event_type":"bookTicker","event_time_ms":1788567790243,"raw_json":"{\"stream\":\"btcusdt@bookTicker\",\"data\":{\"e\":\"bookTicker\",\"u\":11478511979857,\"s\":\"BTCUSDT\",\"ps\":\"BTCUSDT\",\"b\":\"79596.90\",\"B\":\"7.003\",\"a\":\"79597.00\",\"A\":\"7.652\",\"T\":1788567790243,\"E\":1788567790243,\"st\":1}}"}
{"receive_ns":1788567790330488000,"stream":"btcusdt@depth@100ms","event_type":"depthUpdate","event_time_ms":1788567790341,"raw_json":"{\"stream\":\"btcusdt@depth@100ms\",\"data\":{\"e\":\"depthUpdate\",\"E\":1788567790341,\"T\":1788567790338,\"s\":\"BTCUSDT\",\"ps\":\"BTCUSDT\",\"U\":11478511979565,\"u\":11478511985079,\"pu\":11478511979486,\"b\":[[\"29096.90\",\"1.715\"],[\"29496.90\",\"0.385\"],[\"63678.00\",\"0.012\"],[\"71637.20\",\"0.002\"],[\"78800.90\",\"14.471\"],[\"78960.10\",\"8.588\"],[\"79475.60\",\"0.000\"],[\"79594.70\",\"0.000\"],[\"79596.60\",\"0.028\"],[\"79596.90\",\"7.003\"]],\"a\":[[\"79718.90\",\"0.001\"],[\"80393.00\",\"14.147\"]],\"st\":1}}"}
{"receive_ns":1788567790428999000,"stream":"btcusdt@depth@100ms","event_type":"depthUpdate","event_time_ms":1788567790443,"raw_json":"{\"stream\":\"btcusdt@depth@100ms\",\"data\":{\"e\":\"depthUpdate\",\"E\":1788567790443,\"T\":1788567790441,\"s\":\"BTCUSDT\",\"ps\":\"BTCUSDT\",\"U\":11478511985177,\"u\":11478511990816,\"pu\":11478511985079,\"b\":[[\"1000.00\",\"24.604\"],[\"29096.90\",\"1.533\"],[\"29496.90\",\"0.567\"],[\"63678.00\",\"0.012\"],[\"71637.20\",\"0.002\"],[\"76413.00\",\"0.025\"],[\"78641.70\",\"35.713\"],[\"78800.90\",\"14.471\"],[\"79198.90\",\"3.971\"],[\"79475.60\",\"0.504\"],[\"79589.70\",\"0.124\"],[\"79589.80\",\"0.000\"]],\"a\":[[\"79718.90\",\"0.471\"]],\"st\":1}}"}
{"receive_ns":1788567790477253000,"stream":"btcusdt@bookTicker","event_type":"bookTicker","event_time_ms":1788567790485,"raw_json":"{\"stream\":\"btcusdt@bookTicker\",\"data\":{\"e\":\"bookTicker\",\"u\":11478511993450,\"s\":\"BTCUSDT\",\"ps\":\"BTCUSDT\",\"b\":\"79596.90\",\"B\":\"6.958\",\"a\":\"79597.00\",\"A\":\"7.652\",\"T\":1788567790485,\"E\":1788567790485,\"st\":1}}"}
{"receive_ns":1788567790477484000,"stream":"btcusdt@trade","event_type":"trade","event_time_ms":1788567790485,"raw_json":"{\"stream\":\"btcusdt@trade\",\"data\":{\"e\":\"trade\",\"E\":1788567790485,\"T\":1788567790485,\"s\":\"BTCUSDT\",\"t\":8054122882,\"p\":\"79596.90\",\"q\":\"0.045\",\"X\":\"MARKET\",\"m\":true,\"st\":1}}"}
{"receive_ns":1788567790509233000,"stream":"btcusdt@bookTicker","event_type":"bookTicker","event_time_ms":1788567790520,"raw_json":"{\"stream\":\"btcusdt@bookTicker\",\"data\":{\"e\":\"bookTicker\",\"u\":11478511996081,\"s\":\"BTCUSDT\",\"ps\":\"BTCUSDT\",\"b\":\"79596.90\",\"B\":\"6.958\",\"a\":\"79597.00\",\"A\":\"7.592\",\"T\":1788567790519,\"E\":1788567790520,\"st\":1}}"}
{"receive_ns":1788567790521224000,"stream":"btcusdt@trade","event_type":"trade","event_time_ms":1788567790520,"raw_json":"{\"stream\":\"btcusdt@trade\",\"data\":{\"e\":\"trade\",\"E\":1788567790520,\"T\":1788567790519,\"s\":\"BTCUSDT\",\"t\":8054122883,\"p\":\"79597.00\",\"q\":\"0.051\",\"X\":\"MARKET\",\"m\":false,\"st\":1}}"}
{"receive_ns":1788567790521780000,"stream":"btcusdt@trade","event_type":"trade","event_time_ms":1788567790520,"raw_json":"{\"stream\":\"btcusdt@trade\",\"data\":{\"e\":\"trade\",\"E\":1788567790520,\"T\":1788567790519,\"s\":\"BTCUSDT\",\"t\":8054122884,\"p\":\"79597.00\",\"q\":\"0.009\",\"X\":\"MARKET\",\"m\":false,\"st\":1}}"}
{"receive_ns":1788567790522326000,"stream":"btcusdt@bookTicker","event_type":"bookTicker","event_time_ms":1788567790520,"raw_json":"{\"stream\":\"btcusdt@bookTicker\",\"data\":{\"e\":\"bookTicker\",\"u\":11478511996130,\"s\":\"BTCUSDT\",\"ps\":\"BTCUSDT\",\"b\":\"79596.90\",\"B\":\"6.958\",\"a\":\"79597.00\",\"A\":\"7.986\",\"T\":1788567790520,\"E\":1788567790520,\"st\":1}}"}
{"receive_ns":1788567790541496000,"stream":"btcusdt@depth@100ms","event_type":"depthUpdate","event_time_ms":1788567790545,"raw_json":"{\"stream\":\"btcusdt@depth@100ms\",\"data\":{\"e\":\"depthUpdate\",\"E\":1788567790545,\"T\":1788567790541,\"s\":\"BTCUSDT\",\"ps\":\"BTCUSDT\",\"U\":11478511990935,\"u\":11478511997504,\"pu\":11478511990816,\"b\":[[\"1000.00\",\"24.604\"],[\"29096.90\",\"1.358\"],[\"29496.90\",\"0.742\"],[\"71637.20\",\"0.002\"],[\"76413.00\",\"0.023\"],[\"78150.40\",\"1.150\"],[\"78800.90\",\"14.471\"],[\"79473.60\",\"1.196\"],[\"79473.70\",\"0.003\"],[\"79537.90\",\"0.201\"],[\"79553.90\",\"0.000\"],[\"79589.70\",\"0.116\"],[\"79590.00\",\"0.102\"],[\"79591.90\",\"0.347\"],[\"79592.10\",\"0.000\"],[\"79592.50\",\"0.078\"],[\"79594.80\",\"0.000\"],[\"79596.60\",\"0.002\"],[\"79596.80\",\"0.183\"],[\"79596.90\",\"6.958\"]],\"a\":[[\"79597.00\",\"7.986\"],[\"79597.10\",\"0.794\"],[\"79597.30\",\"0.100\"],[\"79597.40\",\"0.005\"],[\"79597.80\",\"0.005\"],[\"79598.40\",\"0.285\"],[\"79598.80\",\"0.029\"],[\"79598.90\",\"0.027\"],[\"79603.90\",\"0.126\"],[\"79604.00\",\"0.122\"],[\"79674.00\",\"3.895\"],[\"79806.00\",\"3.079\"],[\"80353.20\",\"5.284\"],[\"80393.00\",\"14.147\"],[\"81188.90\",\"0.012\"]],\"st\":1}}"}
{"receive_ns":1788567790556527000,"stream":"btcusdt@bookTicker","event_type":"bookTicker","event_time_ms":1788567790564,"raw_json":"{\"stream\":\"btcusdt@bookTicker\",\"data\":{\"e\":\"bookTicker\",\"u\":11478511998813,\"s\":\"BTCUSDT\",\"ps\":\"BTCUSDT\",\"b\":\"79596.90\",\"B\":\"6.958\",\"a\":\"79597.00\",\"A\":\"7.964\",\"T\":1788567790564,\"E\":1788567790564,\"st\":1}}"}
{"receive_ns":1788567790568038000,"stream":"btcusdt@bookTicker","event_type":"bookTicker","event_time_ms":1788567790567,"raw_json":"{\"stream\":\"btcusdt@bookTicker\",\"data\":{\"e\":\"bookTicker\",\"u\":11478511998976,\"s\":\"BTCUSDT\",\"ps\":\"BTCUSDT\",\"b\":\"79596.90\",\"B\":\"6.958\",\"a\":\"79597.00\",\"A\":\"7.988\",\"T\":1788567790567,\"E\":1788567790567,\"st\":1}}"}
{"receive_ns":1788567790636247000,"stream":"btcusdt@depth@100ms","event_type":"depthUpdate","event_time_ms":1788567790647,"raw_json":"{\"stream\":\"btcusdt@depth@100ms\",\"data\":{\"e\":\"depthUpdate\",\"E\":1788567790647,\"T\":1788567790646,\"s\":\"BTCUSDT\",\"ps\":\"BTCUSDT\",\"U\":11478511997727,\"u\":11478512003866,\"pu\":11478511997504,\"b\":[[\"29096.90\",\"1.176\"],[\"29496.90\",\"0.924\"],[\"63678.00\",\"0.012\"],[\"71637.20\",\"0.002\"],[\"76413.00\",\"0.025\"],[\"78800.90\",\"14.471\"],[\"79534.00\",\"0.253\"],[\"79534.50\",\"2.356\"],[\"79536.70\",\"20.247\"],[\"79539.00\",\"4.286\"],[\"79587.10\",\"0.000\"],[\"79589.70\",\"0.124\"],[\"79590.00\",\"0.094\"],[\"79591.50\",\"0.004\"],[\"79591.90\",\"0.343\"],[\"79595.40\",\"0.027\"],[\"79596.50\",\"0.444\"],[\"79596.80\",\"0.157\"]],\"a\":[[\"79597.00\",\"7.988\"],[\"79597.10\",\"0.820\"],[\"79597.90\",\"0.028\"],[\"79598.20\",\"0.028\"],[\"79599.80\",\"0.001\"],[\"79599.90\",\"0.002\"],[\"79668.80\",\"21.838\"],[\"79674.00\",\"0.735\"],[\"79674.20\",\"0.001\"],[\"80393.00\",\"14.147\"]],\"st\":1}}"}
{"receive_ns":1788567790736106000,"stream":"btcusdt@depth@100ms","event_type":"depthUpdate","event_time_ms":1788567790749,"raw_json":"{\"stream\":\"btcusdt@depth@100ms\",\"data\":{\"e\":\"depthUpdate\",\"E\":1788567790749,\"T\":1788567790748,\"s\":\"BTCUSDT\",\"ps\":\"BTCUSDT\",\"U\":11478512003934,\"u\":11478512010048,\"pu\":11478512003866,\"b\":[[\"1000.00\",\"24.604\"],[\"29096.90\",\"1.001\"],[\"29496.90\",\"1.099\"],[\"63678.00\",\"0.012\"],[\"71637.20\",\"0.002\"],[\"76413.00\",\"0.023\"],[\"78482.50\",\"34.989\"],[\"78601.90\",\"13.861\"],[\"78800.90\",\"14.471\"],[\"79198.90\",\"3.981\"],[\"79568.20\",\"0.002\"],[\"79568.90\",\"0.455\"],[\"79570.10\",\"0.001\"],[\"79570.90\",\"0.002\"],[\"79584.90\",\"2.997\"],[\"79585.00\",\"0.035\"],[\"79585.10\",\"0.000\"],[\"79586.10\",\"0.005\"],[\"79586.20\",\"0.378\"],[\"79589.60\",\"0.949\"],[\"79589.70\",\"0.116\"],[\"79590.00\",\"0.094\"],[\"79591.50\",\"0.000\"],[\"79591.60\",\"0.002\"],[\"79591.70\",\"0.005\"],[\"79592.50\",\"0.002\"],[\"79594.70\",\"0.026\"],[\"79594.80\",\"0.026\"],[\"79595.70\",\"0.038\"],[\"79596.00\",\"0.082\"],[\"79596.20\",\"0.000\"],[\"79596.30\",\"0.000\"]],\"a\":[[\"79610.60\",\"0.630\"],[\"79610.70\",\"0.106\"],[\"79610.90\",\"0.442\"],[\"79612.00\",\"0.003\"],[\"79616.00\",\"0.009\"],[\"79616.30\",\"0.013\"],[\"79617.20\",\"0.374\"],[\"79619.30\",\"0.453\"],[\"79620.50\",\"0.001\"],[\"79806.00\",\"3.079\"],[\"80393.00\",\"14.147\"],[\"80513.20\",\"5.957\"],[\"81188.90\",\"0.015\"]],\"st\":1}}"}
{"receive_ns":1788567790804649000,"stream":"btcusdt@bookTicker","event_type":"bookTicker","event_time_ms":1788567790814,"raw_json":"{\"stream\":\"btcusdt@bookTicker\",\"data\":{\"e\":\"bookTicker\",\"u\":11478512013227,\"s\":\"BTCUSDT\",\"ps\":\"BTCUSDT\",\"b\":\"79596.90\",\"B\":\"6.958\",\"a\":\"79597.00\",\"A\":\"7.989\",\"T\":1788567790814,\"E\":1788567790814,\"st\":1}}"}
{"receive_ns":1788567790841591000,"stream":"btcusdt@depth@100ms","event_type":"depthUpdate","event_time_ms":1788567790851,"raw_json":"{\"stream\":\"btcusdt@depth@100ms\",\"data\":{\"e\":\"depthUpdate\",\"E\":1788567790851,\"T\":1788567790849,\"s\":\"BTCUSDT\",\"ps\":\"BTCUSDT\",\"U\":11478512010147,\"u\":11478512015181,\"pu\":11478512010048,\"b\":[[\"1000.00\",\"24.604\"],[\"29096.90\",\"0.819\"],[\"29496.90\",\"1.281\"],[\"71637.20\",\"0.002\"],[\"78108.40\",\"1.405\"],[\"78800.90\",\"14.471\"],[\"79571.70\",\"0.774\"],[\"79572.10\",\"0.001\"],[\"79585.00\",\"0.035\"],[\"79586.10\",\"0.001\"],[\"79586.20\",\"0.002\"],[\"79586.30\",\"0.380\"],[\"79589.60\",\"0.949\"],[\"79591.50\",\"0.002\"],[\"79591.70\",\"0.003\"],[\"79595.80\",\"0.026\"],[\"79596.60\",\"0.003\"]],\"a\":[[\"79597.00\",\"7.989\"],[\"79601.10\",\"0.012\"],[\"79608.20\",\"0.070\"],[\"79608.30\",\"0.629\"],[\"79610.60\",\"0.002\"],[\"79610.70\",\"0.106\"],[\"79616.30\",\"0.013\"],[\"79666.10\",\"21.822\"],[\"79668.80\",\"0.034\"],[\"80393.00\",\"14.147\"]],\"st\":1}}"}
{"receive_ns":1788567790944192000,"stream":"btcusdt@depth@100ms","event_type":"depthUpdate","event_time_ms":1788567790953,"raw_json":"{\"stream\":\"btcusdt@depth@100ms\",\"data\":{\"e\":\"depthUpdate\",\"E\":1788567790953,\"T\":1788567790950,\"s\":\"BTCUSDT\",\"ps\":\"BTCUSDT\",\"U\":11478512015291,\"u\":11478512020384,\"pu\":11478512015181,\"b\":[[\"29096.90\",\"0.644\"],[\"29496.90\",\"1.456\"],[\"63678.00\",\"0.012\"],[\"71637.20\",\"0.002\"],[\"76413.00\",\"0.025\"],[\"78508.50\",\"5.443\"],[\"78641.70\",\"36.094\"],[\"78681.50\",\"7.214\"],[\"78800.90\",\"14.471\"],[\"78960.10\",\"8.336\"],[\"79002.90\",\"0.002\"],[\"79063.50\",\"0.000\"],[\"79565.80\",\"0.046\"],[\"79566.70\",\"0.000\"],[\"79572.30\",\"0.439\"],[\"79573.30\",\"0.000\"],[\"79575.20\",\"0.375\"],[\"79575.70\",\"0.002\"],[\"79576.10\",\"0.009\"],[\"79576.40\",\"2.903\"],[\"79576.90\",\"0.002\"],[\"79585.00\",\"0.349\"],[\"79586.10\",\"0.067\"],[\"79586.20\",\"0.002\"],[\"79586.30\",\"0.000\"],[\"79589.60\",\"0.941\"],[\"79589.70\",\"0.116\"],[\"79590.00\",\"0.102\"],[\"79592.40\",\"0.078\"],[\"79596.20\",\"0.026\"]],\"a\":[[\"79608.10\",\"0.003\"],[\"79608.20\",\"0.070\"],[\"79608.30\",\"0.001\"],[\"79610.70\",\"0.734\"],[\"79615.10\",\"0.254\"],[\"79616.30\",\"0.385\"],[\"79617.20\",\"0.002\"],[\"79629.70\",\"0.022\"],[\"79630.80\",\"0.047\"],[\"79631.70\",\"0.000\"],[\"79819.10\",\"6.966\"],[\"80191.00\",\"0.004\"],[\"80252.60\",\"0.000\"],[\"80393.00\",\"14.147\"],[\"80513.20\",\"6.701\"],[\"80592.00\",\"11.281\"],[\"80966.10\",\"1.987\"]],\"st\":1}}"}
{"receive_ns":1788567790988075000,"stream":"btcusdt@bookTicker","event_type":"bookTicker","event_time_ms":1788567791000,"raw_json":"{\"stream\":\"btcusdt@bookTicker\",\"data\":{\"e\":\"bookTicker\",\"u\":11478512023423,\"s\":\"BTCUSDT\",\"ps\":\"BTCUSDT\",\"b\":\"79596.90\",\"B\":\"6.958\",\"a\":\"79597.00\",\"A\":\"7.936\",\"T\":1788567791000,\"E\":1788567791000,\"st\":1}}"}
{"receive_ns":1788567790994310000,"stream":"btcusdt@bookTicker","event_type":"bookTicker","event_time_ms":1788567791008,"raw_json":"{\"stream\":\"btcusdt@bookTicker\",\"data\":{\"e\":\"bookTicker\",\"u\":11478512023802,\"s\":\"BTCUSDT\",\"ps\":\"BTCUSDT\",\"b\":\"79596.90\",\"B\":\"6.953\",\"a\":\"79597.00\",\"A\":\"7.936\",\"T\":1788567791007,\"E\":1788567791008,\"st\":1}}"}
{"receive_ns":1788567791016616000,"stream":"btcusdt@bookTicker","event_type":"bookTicker","event_time_ms":1788567791027,"raw_json":"{\"stream\":\"btcusdt@bookTicker\",\"data\":{\"e\":\"bookTicker\",\"u\":11478512024736,\"s\":\"BTCUSDT\",\"ps\":\"BTCUSDT\",\"b\":\"79596.90\",\"B\":\"6.958\",\"a\":\"79597.00\",\"A\":\"7.936\",\"T\":1788567791026,\"E\":1788567791027,\"st\":1}}"}
{"receive_ns":1788567791041610000,"stream":"btcusdt@depth@100ms","event_type":"depthUpdate","event_time_ms":1788567791055,"raw_json":"{\"stream\":\"btcusdt@depth@100ms\",\"data\":{\"e\":\"depthUpdate\",\"E\":1788567791055,\"T\":1788567791054,\"s\":\"BTCUSDT\",\"ps\":\"BTCUSDT\",\"U\":11478512020531,\"u\":11478512026239,\"pu\":11478512020384,\"b\":[[\"1000.00\",\"24.604\"],[\"29096.90\",\"0.462\"],[\"29496.90\",\"1.638\"],[\"63678.00\",\"0.012\"],[\"71637.20\",\"0.002\"],[\"75617.10\",\"0.010\"],[\"76413.00\",\"0.023\"],[\"78243.80\",\"9.760\"],[\"78429.20\",\"0.000\"],[\"78522.30\",\"7.820\"],[\"78602.00\",\"8.323\"],[\"78800.90\",\"14.471\"],[\"79198.90\",\"3.981\"],[\"79531.30\",\"0.011\"],[\"79534.00\",\"20.507\"],[\"79536.70\",\"0.000\"],[\"79539.00\",\"0.284\"],[\"79565.80\",\"0.000\"],[\"79567.00\",\"0.300\"],[\"79567.90\",\"0.000\"],[\"79568.90\",\"0.003\"],[\"79570.90\",\"0.454\"],[\"79572.30\",\"0.000\"],[\"79573.20\",\"0.536\"],[\"79573.30\",\"0.439\"],[\"79575.20\",\"0.002\"],[\"79575.70\",\"0.630\"],[\"79575.90\",\"0.000\"],[\"79576.30\",\"0.510\"],[\"79577.40\",\"0.000\"],[\"79582.60\",\"0.070\"],[\"79584.10\",\"0.004\"],[\"79589.70\",\"0.116\"],[\"79590.00\",\"0.102\"],[\"79592.40\",\"0.002\"],[\"79594.70\",\"0.000\"],[\"79595.70\",\"0.001\"],[\"79596.40\",\"0.028\"],[\"79596.90\",\"6.958\"]],\"a\":[[\"79597.00\",\"7.936\"],[\"79604.60\",\"0.140\"],[\"79607.70\",\"0.003\"],[\"79608.30\",\"0.629\"],[\"79610.60\",\"0.441\"],[\"79610.70\",\"0.106\"],[\"79610.90\",\"0.003\"],[\"79612.00\",\"0.003\"],[\"79613.10\",\"0.192\"],[\"79616.20\",\"0.398\"],[\"79616.30\",\"0.013\"],[\"79617.30\",\"0.066\"],[\"79619.30\",\"0.001\"],[\"79620.60\",\"0.454\"],[\"79630.70\",\"0.049\"],[\"79630.80\",\"0.001\"],[\"79631.90\",\"0.000\"],[\"79806.00\",\"3.079\"],[\"80393.00\",\"14.147\"],[\"80513.20\",\"5.957\"]],\"st\":1}}"}
{"receive_ns":1788567791054083000,"stream":"btcusdt@bookTicker","event_type":"bookTicker","event_time_ms":1788567791070,"raw_json":"{\"stream\":\"btcusdt@bookTicker\",\"data\":{\"e\":\"bookTicker\",\"u\":11478512027042,\"s\":\"BTCUSDT\",\"ps\":\"BTCUSDT\",\"b\":\"79596.90\",\"B\":\"6.958\",\"a\":\"79597.00\",\"A\":\"7.912\",\"T\":1788567791070,\"E\":1788567791070,\"st\":1}}"}
{"receive_ns":1788567791072807000,"stream":"btcusdt@bookTicker","event_type":"bookTicker","event_time_ms":1788567791077,"raw_json":"{\"stream\":\"btcusdt@bookTicker\",\"data\":{\"e\":\"bookTicker\",\"u\":11478512027253,\"s\":\"BTCUSDT\",\"ps\":\"BTCUSDT\",\"b\":\"79596.90\",\"B\":\"6.958\",\"a\":\"79597.00\",\"A\":\"7.934\",\"T\":1788567791077,\"E\":1788567791077,\"st\":1}}"}
{"receive_ns":1788567791124253000,"stream":"btcusdt@bookTicker","event_type":"bookTicker","event_time_ms":1788567791140,"raw_json":"{\"stream\":\"btcusdt@bookTicker\",\"data\":{\"e\":\"bookTicker\",\"u\":11478512030781,\"s\":\"BTCUSDT\",\"ps\":\"BTCUSDT\",\"b\":\"79596.90\",\"B\":\"6.952\",\"a\":\"79597.00\",\"A\":\"7.934\",\"T\":1788567791140,\"E\":1788567791140,\"st\":1}}"}
{"receive_ns":1788567791135084000,"stream":"btcusdt@bookTicker","event_type":"bookTicker","event_time_ms":1788567791143,"raw_json":"{\"stream\":\"btcusdt@bookTicker\",\"data\":{\"e\":\"bookTicker\",\"u\":11478512031176,\"s\":\"BTCUSDT\",\"ps\":\"BTCUSDT\",\"b\":\"79596.90\",\"B\":\"6.955\",\"a\":\"79597.00\",\"A\":\"7.934\",\"T\":1788567791143,\"E\":1788567791143,\"st\":1}}"}
{"receive_ns":1788567791143723000,"stream":"btcusdt@depth@100ms","event_type":"depthUpdate","event_time_ms":1788567791157,"raw_json":"{\"stream\":\"btcusdt@depth@100ms\",\"data\":{\"e\":\"depthUpdate\",\"E\":1788567791157,\"T\":1788567791153,\"s\":\"BTCUSDT\",\"ps\":\"BTCUSDT\",\"U\":11478512026289,\"u\":11478512031689,\"pu\":11478512026239,\"b\":[[\"1000.00\",\"24.604\"],[\"29096.90\",\"0.308\"],[\"29396.90\",\"0.021\"],[\"29496.90\",\"1.771\"],[\"63678.00\",\"0.012\"],[\"71637.20\",\"0.002\"],[\"76413.00\",\"0.025\"],[\"78170.00\",\"0.070\"],[\"78800.90\",\"14.471\"],[\"79531.30\",\"20.265\"],[\"79534.00\",\"0.253\"],[\"79536.70\",\"0.000\"],[\"79565.80\",\"0.000\"],[\"79567.00\",\"0.254\"],[\"79567.10\",\"0.047\"],[\"79568.90\",\"0.455\"],[\"79570.90\",\"0.002\"],[\"79572.30\",\"0.000\"],[\"79573.20\",\"0.538\"],[\"79573.30\",\"0.439\"],[\"79575.40\",\"0.059\"],[\"79576.30\",\"0.137\"],[\"79576.50\",\"0.373\"],[\"79589.70\",\"0.116\"],[\"79590.00\",\"0.102\"],[\"79591.90\",\"0.161\"],[\"79592.60\",\"0.000\"],[\"79594.80\",\"0.000\"],[\"79595.90\",\"0.036\"],[\"79596.80\",\"0.183\"],[\"79596.90\",\"6.955\"]],\"a\":[[\"79597.00\",\"7.934\"],[\"79597.10\",\"0.794\"],[\"79597.70\",\"0.026\"],[\"79597.80\",\"0.031\"],[\"79599.70\",\"0.000\"],[\"79608.20\",\"0.070\"],[\"79608.30\",\"0.001\"],[\"79613.10\",\"0.194\"],[\"79615.30\",\"0.187\"],[\"79616.20\",\"0.026\"],[\"79616.30\",\"0.641\"],[\"79616.40\",\"2.104\"],[\"79629.80\",\"0.002\"],[\"79630.70\",\"0.003\"],[\"79630.90\",\"0.057\"],[\"79806.00\",\"3.079\"],[\"80393.00\",\"14.147\"],[\"80513.20\",\"5.213\"]],\"st\":1}}"}
{"receive_ns":1788567791155423000,"stream":"btcusdt@bookTicker","event_type":"bookTicker","event_time_ms":1788567791161,"raw_json":"{\"stream\":\"btcusdt@bookTicker\",\"data\":{\"e\":\"bookTicker\",\"u\":11478512032079,\"s\":\"BTCUSDT\",\"ps\":\"BTCUSDT\",\"b\":\"79596.90\",\"B\":\"6.955\",\"a\":\"79597.00\",\"A\":\"7.881\",\"T\":1788567791161,\"E\":1788567791161,\"st\":1}}"}
{"receive_ns":1788567791167374000,"stream":"btcusdt@trade","event_type":"trade","event_time_ms":1788567791161,"raw_json":"{\"stream\":\"btcusdt@trade\",\"data\":{\"e\":\"trade\",\"E\":1788567791161,\"T\":1788567791161,\"s\":\"BTCUSDT\",\"t\":8054122885,\"p\":\"79597.00\",\"q\":\"0.053\",\"X\":\"MARKET\",\"m\":false,\"st\":1}}"}
{"receive_ns":1788567791238259000,"stream":"btcusdt@bookTicker","event_type":"bookTicker","event_time_ms":1788567791247,"raw_json":"{\"stream\":\"btcusdt@bookTicker\",\"data\":{\"e\":\"bookTicker\",\"u\":11478512036721,\"s\":\"BTCUSDT\",\"ps\":\"BTCUSDT\",\"b\":\"79596.90\",\"B\":\"6.945\",\"a\":\"79597.00\",\"A\":\"7.881\",\"T\":1788567791247,\"E\":1788567791247,\"st\":1}}"}
{"receive_ns":1788567791250465000,"stream":"btcusdt@bookTicker","event_type":"bookTicker","event_time_ms":1788567791250,"raw_json":"{\"stream\":\"btcusdt@bookTicker\",\"data\":{\"e\":\"bookTicker\",\"u\":11478512036840,\"s\":\"BTCUSDT\",\"ps\":\"BTCUSDT\",\"b\":\"79596.90\",\"B\":\"6.945\",\"a\":\"79597.00\",\"A\":\"7.882\",\"T\":1788567791250,\"E\":1788567791250,\"st\":1}}"}
{"receive_ns":1788567791261205000,"stream":"btcusdt@depth@100ms","event_type":"depthUpdate","event_time_ms":1788567791259,"raw_json":"{\"stream\":\"btcusdt@depth@100ms\",\"data\":{\"e\":\"depthUpdate\",\"E\":1788567791259,\"T\":1788567791258,\"s\":\"BTCUSDT\",\"ps\":\"BTCUSDT\",\"U\":11478512031846,\"u\":11478512037171,\"pu\":11478512031689,\"b\":[[\"29096.90\",\"0.189\"],[\"29396.90\",\"0.084\"],[\"29496.90\",\"1.827\"],[\"63677.50\",\"0.000\"],[\"71637.20\",\"0.002\"],[\"71673.00\",\"0.003\"],[\"78385.60\",\"0.000\"],[\"78426.80\",\"10.113\"],[\"78492.60\",\"3.051\"],[\"78602.00\",\"8.132\"],[\"78800.90\",\"14.471\"],[\"79198.90\",\"3.981\"],[\"79531.30\",\"0.011\"],[\"79536.70\",\"20.254\"],[\"79537.60\",\"0.831\"],[\"79541.10\",\"1.098\"],[\"79553.50\",\"1.551\"],[\"79568.60\",\"0.008\"],[\"79589.70\",\"0.124\"],[\"79590.00\",\"0.094\"],[\"79592.40\",\"0.078\"],[\"79596.90\",\"6.945\"]],\"a\":[[\"79597.00\",\"7.882\"],[\"79597.70\",\"0.000\"],[\"79597.80\",\"0.005\"],[\"79597.90\",\"0.002\"],[\"79598.10\",\"0.026\"],[\"79657.50\",\"0.019\"],[\"79668.70\",\"2.054\"],[\"79692.60\",\"0.002\"],[\"79923.80\",\"0.018\"],[\"79925.50\",\"0.282\"],[\"79995.00\",\"4.697\"],[\"80393.00\",\"14.147\"],[\"80513.20\",\"5.213\"]],\"st\":1}}"}
{"receive_ns":1788567791306056000,"stream":"btcusdt@bookTicker","event_type":"bookTicker","event_time_ms":1788567791316,"raw_json":"{\"stream\":\"btcusdt@bookTicker\",\"data\":{\"e\":\"bookTicker\",\"u\":11478512039483,\"s\":\"BTCUSDT\",\"ps\":\"BTCUSDT\",\"b\":\"79596.90\",\"B\":\"6.945\",\"a\":\"79597.00\",\"A\":\"7.880\",\"T\":1788567791316,\"E\":1788567791316,\"st\":1}}"}
{"receive_ns":1788567791313038000,"stream":"btcusdt@trade","event_type":"trade","event_time_ms":1788567791316,"raw_json":"{\"stream\":\"btcusdt@trade\",\"data\":{\"e\":\"trade\",\"E\":1788567791316,\"T\":1788567791316,\"s\":\"BTCUSDT\",\"t\":8054122886,\"p\":\"79597.00\",\"q\":\"0.002\",\"X\":\"MARKET\",\"m\":false,\"st\":1}}"}
{"receive_ns":1788567791350608000,"stream":"btcusdt@depth@100ms","event_type":"depthUpdate","event_time_ms":1788567791361,"raw_json":"{\"stream\":\"btcusdt@depth@100ms\",\"data\":{\"e\":\"depthUpdate\",\"E\":1788567791361,\"T\":1788567791360,\"s\":\"BTCUSDT\",\"ps\":\"BTCUSDT\",\"U\":11478512037232,\"u\":11478512042142,\"pu\":11478512037171,\"b\":[[\"1000.00\",\"24.604\"],[\"29096.90\",\"0.070\"],[\"29396.90\",\"0.140\"],[\"29496.90\",\"1.890\"],[\"71637.20\",\"0.002\"],[\"76413.00\",\"0.023\"],[\"78442.70\",\"16.206\"],[\"78800.90\",\"14.471\"],[\"79507.70\",\"1.310\"],[\"79531.30\",\"0.011\"],[\"79534.00\",\"20.507\"],[\"79536.70\",\"0.000\"],[\"79571.60\",\"0.126\"],[\"79571.70\",\"0.649\"],[\"79589.70\",\"0.124\"],[\"79590.00\",\"0.094\"],[\"79591.90\",\"0.343\"],[\"79596.80\",\"0.157\"]],\"a\":[[\"79597.00\",\"7.880\"],[\"79597.30\",\"0.126\"],[\"79806.00\",\"5.073\"],[\"80393.00\",\"14.147\"],[\"80513.20\",\"5.957\"],[\"80671.70\",\"10.784\"],[\"80687.50\",\"3.460\"]],\"st\":1}}"}
{"receive_ns":1788567791362101000,"stream":"btcusdt@bookTicker","event_type":"bookTicker","event_time_ms":1788567791369,"raw_json":"{\"stream\":\"btcusdt@bookTicker\",\"data\":{\"e\":\"bookTicker\",\"u\":11478512042822,\"s\":\"BTCUSDT\",\"ps\":\"BTCUSDT\",\"b\":\"79596.90\",\"B\":\"7.143\",\"a\":\"79597.00\",\"A\":\"7.880\",\"T\":1788567791369,\"E\":1788567791369,\"st\":1}}"}
{"receive_ns":1788567791379346000,"stream":"btcusdt@bookTicker","event_type":"bookTicker","event_time_ms":1788567791370,"raw_json":"{\"stream\":\"btcusdt@bookTicker\",\"data\":{\"e\":\"bookTicker\",\"u\":11478512042891,\"s\":\"BTCUSDT\",\"ps\":\"BTCUSDT\",\"b\":\"79596.90\",\"B\":\"7.142\",\"a\":\"79597.00\",\"A\":\"7.880\",\"T\":1788567791370,\"E\":1788567791370,\"st\":1}}"}
{"receive_ns":1788567791463931000,"stream":"btcusdt@depth@100ms","event_type":"depthUpdate","event_time_ms":1788567791463,"raw_json":"{\"stream\":\"btcusdt@depth@100ms\",\"data\":{\"e\":\"depthUpdate\",\"E\":1788567791463,\"T\":1788567791462,\"s\":\"BTCUSDT\",\"ps\":\"BTCUSDT\",\"U\":11478512042248,\"u\":11478512047808,\"pu\":11478512042142,\"b\":[[\"1000.00\",\"24.604\"],[\"29096.90\",\"0.000\"],[\"29396.90\",\"0.252\"],[\"29496.90\",\"1.848\"],[\"71637.20\",\"0.002\"],[\"71673.00\",\"0.000\"],[\"75617.10\",\"0.012\"],[\"76413.00\",\"0.025\"],[\"78005.00\",\"0.219\"],[\"78426.80\",\"11.131\"],[\"78508.50\",\"4.808\"],[\"78800.90\",\"14.471\"],[\"78960.10\",\"8.336\"],[\"78999.90\",\"4.425\"],[\"79596.90\",\"7.142\"]],\"a\":[[\"79612.10\",\"0.002\"],[\"79626.70\",\"0.046\"],[\"80393.00\",\"14.147\"],[\"80513.20\",\"6.701\"]],\"st\":1}}"}
{"receive_ns":1788567791480270000,"stream":"btcusdt@bookTicker","event_type":"bookTicker","event_time_ms":1788567791493,"raw_json":"{\"stream\":\"btcusdt@bookTicker\",\"data\":{\"e\":\"bookTicker\",\"u\":11478512049305,\"s\":\"BTCUSDT\",\"ps\":\"BTCUSDT\",\"b\":\"79596.90\",\"B\":\"7.124\",\"a\":\"79597.00\",\"A\":\"7.880\",\"T\":1788567791493,\"E\":1788567791493,\"st\":1}}"}
{"receive_ns":1788567791480567000,"stream":"btcusdt@bookTicker","event_type":"bookTicker","event_time_ms":1788567791496,"raw_json":"{\"stream\":\"btcusdt@bookTicker\",\"data\":{\"e\":\"bookTicker\",\"u\":11478512049552,\"s\":\"BTCUSDT\",\"ps\":\"BTCUSDT\",\"b\":\"79596.90\",\"B\":\"7.144\",\"a\":\"79597.00\",\"A\":\"7.880\",\"T\":1788567791496,\"E\":1788567791496,\"st\":1}}"}
{"receive_ns":1788567791486480000,"stream":"btcusdt@bookTicker","event_type":"bookTicker","event_time_ms":1788567791497,"raw_json":"{\"stream\":\"btcusdt@bookTicker\",\"data\":{\"e\":\"bookTicker\",\"u\":11478512049668,\"s\":\"BTCUSDT\",\"ps\":\"BTCUSDT\",\"b\":\"79596.90\",\"B\":\"7.145\",\"a\":\"79597.00\",\"A\":\"7.880\",\"T\":1788567791497,\"E\":1788567791497,\"st\":1}}"}
{"receive_ns":1788567791555089000,"stream":"btcusdt@depth@100ms","event_type":"depthUpdate","event_time_ms":1788567791565,"raw_json":"{\"stream\":\"btcusdt@depth@100ms\",\"data\":{\"e\":\"depthUpdate\",\"E\":1788567791565,\"T\":1788567791561,\"s\":\"BTCUSDT\",\"ps\":\"BTCUSDT\",\"U\":11478512047860,\"u\":11478512054252,\"pu\":11478512047808,\"b\":[[\"29396.90\",\"0.427\"],[\"29496.90\",\"1.673\"],[\"71637.20\",\"0.002\"],[\"75617.20\",\"0.002\"],[\"76413.00\",\"0.023\"],[\"78613.10\",\"0.000\"],[\"78620.00\",\"5.528\"],[\"78800.90\",\"14.471\"],[\"79198.90\",\"3.971\"],[\"79596.90\",\"7.145\"]],\"a\":[[\"79597.10\",\"0.792\"],[\"79665.40\",\"4.851\"],[\"80393.00\",\"14.147\"],[\"81188.90\",\"0.009\"]],\"st\":1}}"}
{"receive_ns":1788567791663296000,"stream":"btcusdt@depth@100ms","event_type":"depthUpdate","event_time_ms":1788567791667,"raw_json":"{\"stream\":\"btcusdt@depth@100ms\",\"data\":{\"e\":\"depthUpdate\",\"E\":1788567791667,\"T\":1788567791665,\"s\":\"BTCUSDT\",\"ps\":\"BTCUSDT\",\"U\":11478512054553,\"u\":11478512061770,\"pu\":11478512054252,\"b\":[[\"1000.00\",\"24.604\"],[\"29396.90\",\"0.609\"],[\"29496.90\",\"1.491\"],[\"63678.00\",\"0.012\"],[\"71637.20\",\"0.002\"],[\"76413.00\",\"0.025\"],[\"78800.90\",\"14.471\"],[\"79506.80\",\"4.399\"],[\"79507.70\",\"1.290\"],[\"79594.90\",\"0.000\"],[\"79596.70\",\"0.055\"],[\"79596.80\",\"0.183\"]],\"a\":[[\"79597.30\",\"0.100\"],[\"79688.30\",\"3.337\"],[\"79804.90\",\"1.030\"],[\"79806.00\",\"5.075\"],[\"79819.10\",\"6.953\"],[\"80393.00\",\"14.147\"],[\"80513.00\",\"3.690\"]],\"st\":1}}"}
{"receive_ns":1788567791759041000,"stream":"btcusdt@depth@100ms","event_type":"depthUpdate","event_time_ms":1788567791769,"raw_json":"{\"stream\":\"btcusdt@depth@100ms\",\"data\":{\"e\":\"depthUpdate\",\"E\":1788567791769,\"T\":1788567791766,\"s\":\"BTCUSDT\",\"ps\":\"BTCUSDT\",\"U\":11478512061925,\"u\":11478512067307,\"pu\":11478512061770,\"b\":[[\"1000.00\",\"24.604\"],[\"29396.90\",\"0.784\"],[\"29496.90\",\"1.316\"],[\"71637.20\",\"0.002\"],[\"75617.10\",\"0.010\"],[\"75617.20\",\"0.004\"],[\"78800.90\",\"14.471\"],[\"79568.60\",\"0.002\"],[\"79568.90\",\"0.455\"],[\"79570.00\",\"0.005\"],[\"79571.60\",\"0.001\"],[\"79571.80\",\"0.127\"],[\"79591.50\",\"0.000\"],[\"79591.60\",\"0.000\"],[\"79591.80\",\"0.004\"]],\"a\":[[\"79597.90\",\"0.028\"],[\"79619.40\",\"1.251\"],[\"79620.60\",\"0.002\"],[\"80393.00\",\"14.147\"],[\"81188.90\",\"0.012\"]],\"st\":1}}"}
{"receive_ns":1788567791902754000,"stream":"btcusdt@depth@100ms","event_type":"depthUpdate","event_time_ms":1788567791871,"raw_json":"{\"stream\":\"btcusdt@depth@100ms\",\"data\":{\"e\":\"depthUpdate\",\"E\":1788567791871,\"T\":1788567791870,\"s\":\"BTCUSDT\",\"ps\":\"BTCUSDT\",\"U\":11478512067428,\"u\":11478512073310,\"pu\":11478512067307,\"b\":[[\"29396.90\",\"0.966\"],[\"29496.90\",\"1.134\"],[\"63678.00\",\"0.012\"],[\"71637.20\",\"0.002\"],[\"76413.00\",\"0.023\"],[\"78800.90\",\"14.471\"],[\"79198.90\",\"3.981\"],[\"79571.70\",\"0.021\"],[\"79572.20\",\"1.257\"],[\"79575.70\",\"0.002\"],[\"79576.20\",\"0.875\"]],\"a\":[[\"79597.90\",\"0.002\"],[\"79606.80\",\"0.255\"],[\"79607.10\",\"0.252\"],[\"79615.90\",\"0.000\"],[\"79616.10\",\"0.637\"],[\"79623.80\",\"0.002\"],[\"79624.10\",\"0.628\"],[\"79665.40\",\"1.810\"],[\"79666.10\",\"0.015\"],[\"79674.20\",\"21.756\"],[\"80393.00\",\"14.147\"],[\"80717.60\",\"11.104\"]],\"st\":1}}"}
{"receive_ns":1788567791931918000,"stream":"btcusdt@bookTicker","event_type":"bookTicker","event_time_ms":1788567791942,"raw_json":"{\"stream\":\"btcusdt@bookTicker\",\"data\":{\"e\":\"bookTicker\",\"u\":11478512078006,\"s\":\"BTCUSDT\",\"ps\":\"BTCUSDT\",\"b\":\"79596.90\",\"B\":\"7.122\",\"a\":\"79597.00\",\"A\":\"7.880\",\"T\":1788567791941,\"E\":1788567791942,\"st\":1}}"}
{"receive_ns":1788567791937938000,"stream":"btcusdt@bookTicker","event_type":"bookTicker","event_time_ms":1788567791945,"raw_json":"{\"stream\":\"btcusdt@bookTicker\",\"data\":{\"e\":\"bookTicker\",\"u\":11478512079847,\"s\":\"BTCUSDT\",\"ps\":\"BTCUSDT\",\"b\":\"79596.90\",\"B\":\"7.143\",\"a\":\"79597.00\",\"A\":\"7.880\",\"T\":1788567791945,\"E\":1788567791945,\"st\":1}}"}
{"receive_ns":1788567791965800000,"stream":"btcusdt@depth@100ms","event_type":"depthUpdate","event_time_ms":1788567791973,"raw_json":"{\"stream\":\"btcusdt@depth@100ms\",\"data\":{\"e\":\"depthUpdate\",\"E\":1788567791973,\"T\":1788567791971,\"s\":\"BTCUSDT\",\"ps\":\"BTCUSDT\",\"U\":11478512073366,\"u\":11478512083616,\"pu\":11478512073310,\"b\":[[\"1000.00\",\"24.604\"],[\"29396.90\",\"1.141\"],[\"29496.90\",\"0.959\"],[\"71637.20\",\"0.002\"],[\"75617.10\",\"0.012\"],[\"76413.00\",\"0.025\"],[\"78800.90\",\"14.471\"],[\"79577.00\",\"0.022\"],[\"79584.60\",\"0.348\"],[\"79596.90\",\"7.143\"]],\"a\":[[\"79597.10\",\"0.794\"],[\"79597.70\",\"0.026\"],[\"79668.80\",\"21.789\"],[\"79674.20\",\"0.001\"],[\"80393.00\",\"14.147\"],[\"80513.20\",\"7.445\"],[\"80711.40\",\"34.513\"],[\"80727.40\",\"0.748\"],[\"81158.70\",\"0.012\"]],\"st\":1}}"}
{"receive_ns":1788567791980583000,"stream":"btcusdt@bookTicker","event_type":"bookTicker","event_time_ms":1788567791982,"raw_json":"{\"stream\":\"btcusdt@bookTicker\",\"data\":{\"e\":\"bookTicker\",\"u\":11478512084761,\"s\":\"BTCUSDT\",\"ps\":\"BTCUSDT\",\"b\":\"79596.90\",\"B\":\"7.143\",\"a\":\"79597.00\",\"A\":\"7.865\",\"T\":1788567791981,\"E\":1788567791982,\"st\":1}}"}
{"receive_ns":1788567791980833000,"stream":"btcusdt@bookTicker","event_type":"bookTicker","event_time_ms":1788567791982,"raw_json":"{\"stream\":\"btcusdt@bookTicker\",\"data\":{\"e\":\"bookTicker\",\"u\":11478512084770,\"s\":\"BTCUSDT\",\"ps\":\"BTCUSDT\",\"b\":\"79596.90\",\"B\":\"7.143\",\"a\":\"79597.00\",\"A\":\"6.350\",\"T\":1788567791982,\"E\":1788567791982,\"st\":1}}"}
{"receive_ns":1788567791992015000,"stream":"btcusdt@bookTicker","event_type":"bookTicker","event_time_ms":1788567791982,"raw_json":"{\"stream\":\"btcusdt@bookTicker\",\"data\":{\"e\":\"bookTicker\",\"u\":11478512084771,\"s\":\"BTCUSDT\",\"ps\":\"BTCUSDT\",\"b\":\"79596.90\",\"B\":\"7.143\",\"a\":\"79597.00\",\"A\":\"6.198\",\"T\":1788567791982,\"E\":1788567791982,\"st\":1}}"}
{"receive_ns":1788567791997842000,"stream":"btcusdt@bookTicker","event_type":"bookTicker","event_time_ms":1788567791982,"raw_json":"{\"stream\":\"btcusdt@bookTicker\",\"data\":{\"e\":\"bookTicker\",\"u\":11478512084776,\"s\":\"BTCUSDT\",\"ps\":\"BTCUSDT\",\"b\":\"79596.90\",\"B\":\"7.143\",\"a\":\"79597.00\",\"A\":\"6.197\",\"T\":1788567791982,\"E\":1788567791982,\"st\":1}}"}
{"receive_ns":1788567792010592000,"stream":"btcusdt@bookTicker","event_type":"bookTicker","event_time_ms":1788567791986,"raw_json":"{\"stream\":\"btcusdt@bookTicker\",\"data\":{\"e\":\"bookTicker\",\"u\":11478512085023,\"s\":\"BTCUSDT\",\"ps\":\"BTCUSDT\",\"b\":\"79596.90\",\"B\":\"7.143\",\"a\":\"79597.00\",\"A\":\"6.196\",\"T\":1788567791986,\"E\":1788567791986,\"st\":1}}"}
{"receive_ns":1788567792016274000,"stream":"btcusdt@bookTicker","event_type":"bookTicker","event_time_ms":1788567791986,"raw_json":"{\"stream\":\"btcusdt@bookTicker\",\"data\":{\"e\":\"bookTicker\",\"u\":11478512085028,\"s\":\"BTCUSDT\",\"ps\":\"BTCUSDT\",\"b\":\"79596.90\",\"B\":\"7.143\",\"a\":\"79597.00\",\"A\":\"6.194\",\"T\":1788567791986,\"E\":1788567791986,\"st\":1}}"}
{"receive_ns":1788567792021713000,"stream":"btcusdt@bookTicker","event_type":"bookTicker","event_time_ms":1788567791986,"raw_json":"{\"stream\":\"btcusdt@bookTicker\",\"data\":{\"e\":\"bookTicker\",\"u\":11478512085031,\"s\":\"BTCUSDT\",\"ps\":\"BTCUSDT\",\"b\":\"79596.90\",\"B\":\"7.143\",\"a\":\"79597.00\",\"A\":\"6.193\",\"T\":1788567791986,\"E\":1788567791986,\"st\":1}}"}
{"receive_ns":1788567792032367000,"stream":"btcusdt@bookTicker","event_type":"bookTicker","event_time_ms":1788567792027,"raw_json":"{\"stream\":\"btcusdt@bookTicker\",\"data\":{\"e\":\"bookTicker\",\"u\":11478512088315,\"s\":\"BTCUSDT\",\"ps\":\"BTCUSDT\",\"b\":\"79596.90\",\"B\":\"7.131\",\"a\":\"79597.00\",\"A\":\"6.193\",\"T\":1788567792027,\"E\":1788567792027,\"st\":1}}"}
{"receive_ns":1788567792044506000,"stream":"btcusdt@bookTicker","event_type":"bookTicker","event_time_ms":1788567792032,"raw_json":"{\"stream\":\"btcusdt@bookTicker\",\"data\":{\"e\":\"bookTicker\",\"u\":11478512088674,\"s\":\"BTCUSDT\",\"ps\":\"BTCUSDT\",\"b\":\"79596.90\",\"B\":\"7.143\",\"a\":\"79597.00\",\"A\":\"6.193\",\"T\":1788567792032,\"E\":1788567792032,\"st\":1}}"}
{"receive_ns":1788567792051345000,"stream":"btcusdt@bookTicker","event_type":"bookTicker","event_time_ms":1788567792033,"raw_json":"{\"stream\":\"btcusdt@bookTicker\",\"data\":{\"e\":\"bookTicker\",\"u\":11478512088833,\"s\":\"BTCUSDT\",\"ps\":\"BTCUSDT\",\"b\":\"79596.90\",\"B\":\"7.143\",\"a\":\"79597.00\",\"A\":\"6.257\",\"T\":1788567792033,\"E\":1788567792033,\"st\":1}}"}
{"receive_ns":1788567792087738000,"stream":"btcusdt@depth@100ms","event_type":"depthUpdate","event_time_ms":1788567792075,"raw_json":"{\"stream\":\"btcusdt@depth@100ms\",\"data\":{\"e\":\"depthUpdate\",\"E\":1788567792075,\"T\":1788567792074,\"s\":\"BTCUSDT\",\"ps\":\"BTCUSDT\",\"U\":11478512083985,\"u\":11478512092193,\"pu\":11478512083616,\"b\":[[\"1000.00\",\"24.604\"],[\"29396.90\",\"1.323\"],[\"29496.90\",\"0.777\"],[\"63678.00\",\"0.012\"],[\"71637.20\",\"0.002\"],[\"75617.10\",\"0.010\"],[\"75617.20\",\"0.006\"],[\"76413.00\",\"0.023\"],[\"78579.90\",\"0.001\"],[\"78589.30\",\"0.012\"],[\"78641.70\",\"35.587\"],[\"78800.90\",\"15.422\"],[\"79515.50\",\"0.074\"],[\"79537.60\",\"0.002\"],[\"79553.50\",\"0.860\"],[\"79555.20\",\"0.108\"],[\"79557.70\",\"0.546\"],[\"79558.40\",\"0.001\"],[\"79573.20\",\"0.536\"],[\"79575.90\",\"0.628\"],[\"79576.20\",\"0.247\"],[\"79582.60\",\"0.070\"],[\"79596.90\",\"7.143\"]],\"a\":[[\"79597.00\",\"6.257\"],[\"79597.10\",\"0.792\"],[\"79597.30\",\"0.102\"],[\"79597.70\",\"0.000\"],[\"79601.10\",\"0.010\"],[\"79604.20\",\"0.007\"],[\"79605.60\",\"1.895\"],[\"79613.10\",\"0.192\"],[\"79617.20\",\"0.000\"],[\"79617.30\",\"0.064\"],[\"79627.90\",\"0.001\"],[\"79659.70\",\"0.152\"],[\"79662.30\",\"0.038\"],[\"79665.50\",\"6.301\"],[\"79666.10\",\"21.769\"],[\"79668.80\",\"0.034\"],[\"79699.60\",\"0.198\"],[\"80393.00\",\"15.389\"],[\"80549.60\",\"1.862\"]],\"st\":1}}"}
{"receive_ns":1788567792099250000,"stream":"btcusdt@bookTicker","event_type":"bookTicker","event_time_ms":1788567792084,"raw_json":"{\"stream\":\"btcusdt@bookTicker\",\"data\":{\"e\":\"bookTicker\",\"u\":11478512092879,\"s\":\"BTCUSDT\",\"ps\":\"BTCUSDT\",\"b\":\"79596.90\",\"B\":\"7.143\",\"a\":\"79597.00\",\"A\":\"6.282\",\"T\":1788567792084,\"E\":1788567792084,\"st\":1}}"}
{"receive_ns":1788567792105145000,"stream":"btcusdt@bookTicker","event_type":"bookTicker","event_time_ms":1788567792100,"raw_json":"{\"stream\":\"btcusdt@bookTicker\",\"data\":{\"e\":\"bookTicker\",\"u\":11478512093771,\"s\":\"BTCUSDT\",\"ps\":\"BTCUSDT\",\"b\":\"79596.90\",\"B\":\"7.143\",\"a\":\"79597.00\",\"A\":\"6.260\",\"T\":1788567792100,\"E\":1788567792100,\"st\":1}}"}
{"receive_ns":1788567792115847000,"stream":"btcusdt@bookTicker","event_type":"bookTicker","event_time_ms":1788567792102,"raw_json":"{\"stream\":\"btcusdt@bookTicker\",\"data\":{\"e\":\"bookTicker\",\"u\":11478512094004,\"s\":\"BTCUSDT\",\"ps\":\"BTCUSDT\",\"b\":\"79596.90\",\"B\":\"7.143\",\"a\":\"79597.00\",\"A\":\"6.276\",\"T\":1788567792102,\"E\":1788567792102,\"st\":1}}"}
{"receive_ns":1788567792121450000,"stream":"btcusdt@bookTicker","event_type":"bookTicker","event_time_ms":1788567792102,"raw_json":"{\"stream\":\"btcusdt@bookTicker\",\"data\":{\"e\":\"bookTicker\",\"u\":11478512094015,\"s\":\"BTCUSDT\",\"ps\":\"BTCUSDT\",\"b\":\"79596.90\",\"B\":\"7.143\",\"a\":\"79597.00\",\"A\":\"6.220\",\"T\":1788567792102,\"E\":1788567792102,\"st\":1}}"}
{"receive_ns":1788567792127055000,"stream":"btcusdt@bookTicker","event_type":"bookTicker","event_time_ms":1788567792107,"raw_json":"{\"stream\":\"btcusdt@bookTicker\",\"data\":{\"e\":\"bookTicker\",\"u\":11478512094776,\"s\":\"BTCUSDT\",\"ps\":\"BTCUSDT\",\"b\":\"79596.90\",\"B\":\"7.143\",\"a\":\"79597.00\",\"A\":\"6.270\",\"T\":1788567792107,\"E\":1788567792107,\"st\":1}}"}
{"receive_ns":1788567792143836000,"stream":"btcusdt@bookTicker","event_type":"bookTicker","event_time_ms":1788567792144,"raw_json":"{\"stream\":\"btcusdt@bookTicker\",\"data\":{\"e\":\"bookTicker\",\"u\":11478512097475,\"s\":\"BTCUSDT\",\"ps\":\"BTCUSDT\",\"b\":\"79596.90\",\"B\":\"7.143\",\"a\":\"79597.00\",\"A\":\"7.789\",\"T\":1788567792144,\"E\":1788567792144,\"st\":1}}"}
{"receive_ns":1788567792164082000,"stream":"btcusdt@bookTicker","event_type":"bookTicker","event_time_ms":1788567792175,"raw_json":"{\"stream\":\"btcusdt@bookTicker\",\"data\":{\"e\":\"bookTicker\",\"u\":11478512099810,\"s\":\"BTCUSDT\",\"ps\":\"BTCUSDT\",\"b\":\"79596.90\",\"B\":\"7.143\",\"a\":\"79597.00\",\"A\":\"7.946\",\"T\":1788567792174,\"E\":1788567792175,\"st\":1}}"}
{"receive_ns":1788567792176787000,"stream":"btcusdt@depth@100ms","event_type":"depthUpdate","event_time_ms":1788567792177,"raw_json":"{\"stream\":\"btcusdt@depth@100ms\",\"data\":{\"e\":\"depthUpdate\",\"E\":1788567792177,\"T\":1788567792176,\"s\":\"BTCUSDT\",\"ps\":\"BTCUSDT\",\"U\":11478512092276,\"u\":11478512099921,\"pu\":11478512092193,\"b\":[[\"29396.90\",\"1.498\"],[\"29496.90\",\"0.602\"],[\"63678.00\",\"0.012\"],[\"71637.20\",\"0.002\"],[\"76413.00\",\"0.025\"],[\"78800.90\",\"15.424\"],[\"79198.90\",\"3.981\"],[\"79437.70\",\"0.029\"],[\"79495.00\",\"0.181\"],[\"79534.00\",\"0.253\"],[\"79536.70\",\"20.210\"],[\"79558.30\",\"0.294\"],[\"79566.70\",\"0.046\"],[\"79567.10\",\"0.001\"],[\"79571.90\",\"0.630\"],[\"79572.20\",\"0.629\"],[\"79573.20\",\"0.538\"],[\"79576.20\",\"0.620\"],[\"79576.50\",\"0.000\"]],\"a\":[[\"79597.00\",\"7.946\"],[\"79597.20\",\"0.002\"],[\"79597.30\",\"0.348\"],[\"79598.00\",\"0.107\"],[\"79598.10\",\"0.000\"],[\"79598.20\",\"0.002\"],[\"79599.00\",\"0.028\"],[\"79599.30\",\"0.044\"],[\"79604.20\",\"0.008\"],[\"79605.60\",\"1.894\"],[\"79613.10\",\"0.194\"],[\"79692.50\",\"0.000\"],[\"80393.00\",\"15.389\"],[\"83576.80\",\"0.016\"]],\"st\":1}}"}
{"receive_ns":1788567792210283000,"stream":"btcusdt@bookTicker","event_type":"bookTicker","event_time_ms":1788567792202,"raw_json":"{\"stream\":\"btcusdt@bookTicker\",\"data\":{\"e\":\"bookTicker\",\"u\":11478512101388,\"s\":\"BTCUSDT\",\"ps\":\"BTCUSDT\",\"b\":\"79596.90\",\"B\":\"7.087\",\"a\":\"79597.00\",\"A\":\"7.946\",\"T\":1788567792201,\"E\":1788567792202,\"st\":1}}"}
{"receive_ns":1788567792226591000,"stream":"btcusdt@trade","event_type":"trade","event_time_ms":1788567792202,"raw_json":"{\"stream\":\"btcusdt@trade\",\"data\":{\"e\":\"trade\",\"E\":1788567792202,\"T\":1788567792201,\"s\":\"BTCUSDT\",\"t\":8054122887,\"p\":\"79596.90\",\"q\":\"0.056\",\"X\":\"MARKET\",\"m\":true,\"st\":1}}"}
{"receive_ns":1788567792236568000,"stream":"btcusdt@bookTicker","event_type":"bookTicker","event_time_ms":1788567792203,"raw_json":"{\"stream\":\"btcusdt@bookTicker\",\"data\":{\"e\":\"bookTicker\",\"u\":11478512101568,\"s\":\"BTCUSDT\",\"ps\":\"BTCUSDT\",\"b\":\"79596.90\",\"B\":\"7.087\",\"a\":\"79597.00\",\"A\":\"7.972\",\"T\":1788567792203,\"E\":1788567792203,\"st\":1}}"}
{"receive_ns":1788567792242859000,"stream":"btcusdt@bookTicker","event_type":"bookTicker","event_time_ms":1788567792203,"raw_json":"{\"stream\":\"btcusdt@bookTicker\",\"data\":{\"e\":\"bookTicker\",\"u\":11478512101623,\"s\":\"BTCUSDT\",\"ps\":\"BTCUSDT\",\"b\":\"79596.90\",\"B\":\"7.086\",\"a\":\"79597.00\",\"A\":\"7.972\",\"T\":1788567792203,\"E\":1788567792203,\"st\":1}}"}
{"receive_ns":1788567792255488000,"stream":"btcusdt@bookTicker","event_type":"bookTicker","event_time_ms":1788567792204,"raw_json":"{\"stream\":\"btcusdt@bookTicker\",\"data\":{\"e\":\"bookTicker\",\"u\":11478512101652,\"s\":\"BTCUSDT\",\"ps\":\"BTCUSDT\",\"b\":\"79596.90\",\"B\":\"7.076\",\"a\":\"79597.00\",\"A\":\"7.972\",\"T\":1788567792203,\"E\":1788567792204,\"st\":1}}"}
{"receive_ns":1788567792266344000,"stream":"btcusdt@bookTicker","event_type":"bookTicker","event_time_ms":1788567792224,"raw_json":"{\"stream\":\"btcusdt@bookTicker\",\"data\":{\"e\":\"bookTicker\",\"u\":11478512102830,\"s\":\"BTCUSDT\",\"ps\":\"BTCUSDT\",\"b\":\"79596.90\",\"B\":\"7.076\",\"a\":\"79597.00\",\"A\":\"7.981\",\"T\":1788567792224,\"E\":1788567792224,\"st\":1}}"}
{"receive_ns":1788567792279282000,"stream":"btcusdt@bookTicker","event_type":"bookTicker","event_time_ms":1788567792231,"raw_json":"{\"stream\":\"btcusdt@bookTicker\",\"data\":{\"e\":\"bookTicker\",\"u\":11478512103181,\"s\":\"BTCUSDT\",\"ps\":\"BTCUSDT\",\"b\":\"79596.90\",\"B\":\"7.024\",\"a\":\"79597.00\",\"A\":\"7.981\",\"T\":1788567792231,\"E\":1788567792231,\"st\":1}}"}
{"receive_ns":1788567792286108000,"stream":"btcusdt@trade","event_type":"trade","event_time_ms":1788567792231,"raw_json":"{\"stream\":\"btcusdt@trade\",\"data\":{\"e\":\"trade\",\"E\":1788567792231,\"T\":1788567792231,\"s\":\"BTCUSDT\",\"t\":8054122888,\"p\":\"79596.90\",\"q\":\"0.052\",\"X\":\"MARKET\",\"m\":true,\"st\":1}}"}
{"receive_ns":1788567792303667000,"stream":"btcusdt@bookTicker","event_type":"bookTicker","event_time_ms":1788567792232,"raw_json":"{\"stream\":\"btcusdt@bookTicker\",\"data\":{\"e\":\"bookTicker\",\"u\":11478512103275,\"s\":\"BTCUSDT\",\"ps\":\"BTCUSDT\",\"b\":\"79596.90\",\"B\":\"7.024\",\"a\":\"79597.00\",\"A\":\"7.982\",\"T\":1788567792232,\"E\":1788567792232,\"st\":1}}"}
{"receive_ns":1788567792309269000,"stream":"btcusdt@bookTicker","event_type":"bookTicker","event_time_ms":1788567792232,"raw_json":"{\"stream\":\"btcusdt@bookTicker\",\"data\":{\"e\":\"bookTicker\",\"u\":11478512103291,\"s\":\"BTCUSDT\",\"ps\":\"BTCUSDT\",\"b\":\"79596.90\",\"B\":\"7.025\",\"a\":\"79597.00\",\"A\":\"7.982\",\"T\":1788567792232,\"E\":1788567792232,\"st\":1}}"}
{"receive_ns":1788567792315618000,"stream":"btcusdt@bookTicker","event_type":"bookTicker","event_time_ms":1788567792243,"raw_json":"{\"stream\":\"btcusdt@bookTicker\",\"data\":{\"e\":\"bookTicker\",\"u\":11478512103838,\"s\":\"BTCUSDT\",\"ps\":\"BTCUSDT\",\"b\":\"79596.90\",\"B\":\"7.025\",\"a\":\"79597.00\",\"A\":\"8.022\",\"T\":1788567792243,\"E\":1788567792243,\"st\":1}}"}
{"receive_ns":1788567792321908000,"stream":"btcusdt@bookTicker","event_type":"bookTicker","event_time_ms":1788567792244,"raw_json":"{\"stream\":\"btcusdt@bookTicker\",\"data\":{\"e\":\"bookTicker\",\"u\":11478512103933,\"s\":\"BTCUSDT\",\"ps\":\"BTCUSDT\",\"b\":\"79596.90\",\"B\":\"7.024\",\"a\":\"79597.00\",\"A\":\"8.022\",\"T\":1788567792244,\"E\":1788567792244,\"st\":1}}"}
{"receive_ns":1788567792327450000,"stream":"btcusdt@bookTicker","event_type":"bookTicker","event_time_ms":1788567792244,"raw_json":"{\"stream\":\"btcusdt@bookTicker\",\"data\":{\"e\":\"bookTicker\",\"u\":11478512103957,\"s\":\"BTCUSDT\",\"ps\":\"BTCUSDT\",\"b\":\"79596.90\",\"B\":\"7.024\",\"a\":\"79597.00\",\"A\":\"8.021\",\"T\":1788567792244,\"E\":1788567792244,\"st\":1}}"}
{"receive_ns":1788567792333747000,"stream":"btcusdt@depth@100ms","event_type":"depthUpdate","event_time_ms":1788567792279,"raw_json":"{\"stream\":\"btcusdt@depth@100ms\",\"data\":{\"e\":\"depthUpdate\",\"E\":1788567792279,\"T\":1788567792278,\"s\":\"BTCUSDT\",\"ps\":\"BTCUSDT\",\"U\":11478512099958,\"u\":11478512105850,\"pu\":11478512099921,\"b\":[[\"1000.00\",\"24.604\"],[\"29396.90\",\"1.680\"],[\"29496.90\",\"0.420\"],[\"63677.50\",\"0.000\"],[\"71637.20\",\"0.002\"],[\"75617.20\",\"0.004\"],[\"78005.00\",\"0.222\"],[\"78164.20\",\"2.171\"],[\"78482.60\",\"12.418\"],[\"78800.90\",\"15.422\"],[\"79198.90\",\"3.980\"],[\"79525.20\",\"0.002\"],[\"79536.70\",\"20.211\"],[\"79537.70\",\"3.501\"],[\"79581.20\",\"0.077\"],[\"79587.90\",\"0.141\"],[\"79590.20\",\"0.077\"],[\"79591.00\",\"0.001\"],[\"79591.50\",\"0.004\"],[\"79591.80\",\"0.000\"],[\"79591.90\",\"0.343\"],[\"79592.40\",\"0.002\"],[\"79594.20\",\"0.000\"],[\"79594.30\",\"0.064\"],[\"79594.40\",\"0.080\"],[\"79594.50\",\"0.026\"],[\"79594.70\",\"0.026\"],[\"79594.80\",\"0.026\"],[\"79594.90\",\"0.026\"],[\"79595.20\",\"0.026\"],[\"79595.30\",\"0.027\"],[\"79595.40\",\"0.001\"],[\"79595.50\",\"0.026\"],[\"79595.60\",\"0.038\"],[\"79595.70\",\"0.035\"],[\"79595.80\",\"0.026\"],[\"79595.90\",\"0.002\"],[\"79596.20\",\"0.000\"],[\"79596.40\",\"0.002\"],[\"79596.70\",\"0.029\"],[\"79596.80\",\"0.157\"],[\"79596.90\",\"7.024\"]],\"a\":[[\"79597.00\",\"8.021\"],[\"79597.30\",\"0.374\"],[\"79599.30\",\"0.018\"],[\"79599.40\",\"0.002\"],[\"79627.80\",\"0.009\"],[\"79660.70\",\"0.008\"],[\"79665.50\",\"6.300\"],[\"79666.10\",\"21.770\"],[\"79692.60\",\"0.004\"],[\"79831.80\",\"0.053\"],[\"79831.90\",\"0.003\"],[\"79995.00\",\"4.697\"],[\"80393.00\",\"15.389\"]],\"st\":1}}"}
{"receive_ns":1788567792346031000,"stream":"btcusdt@bookTicker","event_type":"bookTicker","event_time_ms":1788567792294,"raw_json":"{\"stream\":\"btcusdt@bookTicker\",\"data\":{\"e\":\"bookTicker\",\"u\":11478512106717,\"s\":\"BTCUSDT\",\"ps\":\"BTCUSDT\",\"b\":\"79596.90\",\"B\":\"7.024\",\"a\":\"79597.00\",\"A\":\"8.018\",\"T\":1788567792294,\"E\":1788567792294,\"st\":1}}"}
{"receive_ns":1788567792351447000,"stream":"btcusdt@trade","event_type":"trade","event_time_ms":1788567792294,"raw_json":"{\"stream\":\"btcusdt@trade\",\"data\":{\"e\":\"trade\",\"E\":1788567792294,\"T\":1788567792294,\"s\":\"BTCUSDT\",\"t\":8054122889,\"p\":\"79597.00\",\"q\":\"0.003\",\"X\":\"MARKET\",\"m\":false,\"st\":1}}"}
{"receive_ns":1788567792353659000,"stream":"btcusdt@bookTicker","event_type":"bookTicker","event_time_ms":1788567792350,"raw_json":"{\"stream\":\"btcusdt@bookTicker\",\"data\":{\"e\":\"bookTicker\",\"u\":11478512112196,\"s\":\"BTCUSDT\",\"ps\":\"BTCUSDT\",\"b\":\"79596.90\",\"B\":\"7.024\",\"a\":\"79597.00\",\"A\":\"7.992\",\"T\":1788567792350,\"E\":1788567792350,\"st\":1}}"}
{"receive_ns":1788567792365244000,"stream":"btcusdt@depth@100ms","event_type":"depthUpdate","event_time_ms":1788567792381,"raw_json":"{\"stream\":\"btcusdt@depth@100ms\",\"data\":{\"e\":\"depthUpdate\",\"E\":1788567792381,\"T\":1788567792377,\"s\":\"BTCUSDT\",\"ps\":\"BTCUSDT\",\"U\":11478512105989,\"u\":11478512114822,\"pu\":11478512105850,\"b\":[[\"1000.00\",\"24.604\"],[\"29296.90\",\"0.035\"],[\"29396.90\",\"1.785\"],[\"29496.90\",\"0.280\"],[\"71637.20\",\"0.002\"],[\"75617.00\",\"0.029\"],[\"76413.00\",\"0.023\"],[\"78800.90\",\"15.422\"],[\"79198.90\",\"3.981\"],[\"79537.90\",\"1.030\"],[\"79553.80\",\"0.691\"],[\"79566.70\",\"0.046\"],[\"79567.90\",\"0.000\"],[\"79575.70\",\"0.008\"],[\"79576.10\",\"0.382\"],[\"79576.20\",\"0.247\"],[\"79576.40\",\"2.897\"],[\"79577.20\",\"0.000\"],[\"79579.80\",\"0.048\"],[\"79581.20\",\"0.001\"],[\"79586.10\",\"0.067\"],[\"79587.50\",\"0.002\"],[\"79589.70\",\"0.124\"],[\"79591.30\",\"0.000\"],[\"79591.40\",\"0.079\"],[\"79592.50\",\"0.078\"],[\"79594.50\",\"0.000\"],[\"79594.70\",\"0.000\"],[\"79594.80\",\"0.000\"],[\"79595.90\",\"0.028\"],[\"79596.20\",\"0.000\"],[\"79596.70\",\"0.055\"],[\"79596.80\",\"0.183\"]],\"a\":[[\"79597.00\",\"7.992\"],[\"79597.30\",\"0.348\"],[\"79597.90\",\"0.002\"],[\"79598.00\",\"0.081\"],[\"79598.40\",\"0.259\"],[\"79598.50\",\"0.000\"],[\"79598.70\",\"0.004\"],[\"79599.30\",\"0.044\"],[\"79599.40\",\"0.028\"],[\"79599.50\",\"0.029\"],[\"79599.60\",\"0.026\"],[\"79610.60\",\"0.002\"],[\"79610.70\",\"0.734\"],[\"79610.90\",\"0.442\"],[\"79612.00\",\"0.694\"],[\"79612.80\",\"0.003\"],[\"79616.00\",\"0.381\"],[\"79616.30\",\"0.013\"],[\"79616.40\",\"1.732\"],[\"79617.00\",\"0.005\"],[\"79617.10\",\"0.002\"],[\"79617.20\",\"0.000\"],[\"79619.40\",\"0.799\"],[\"79620.30\",\"0.452\"],[\"79627.90\",\"0.830\"],[\"79630.50\",\"0.046\"],[\"79630.90\",\"0.011\"],[\"79631.70\",\"0.000\"],[\"79666.10\",\"0.015\"],[\"79674.20\",\"21.756\"],[\"79806.00\",\"5.028\"],[\"80393.00\",\"15.389\"]],\"st\":1}}"}
{"receive_ns":1788567792378117000,"stream":"btcusdt@bookTicker","event_type":"bookTicker","event_time_ms":1788567792390,"raw_json":"{\"stream\":\"btcusdt@bookTicker\",\"data\":{\"e\":\"bookTicker\",\"u\":11478512115463,\"s\":\"BTCUSDT\",\"ps\":\"BTCUSDT\",\"b\":\"79596.90\",\"B\":\"6.826\",\"a\":\"79597.00\",\"A\":\"7.992\",\"T\":1788567792390,\"E\":1788567792390,\"st\":1}}"}
{"receive_ns":1788567792384866000,"stream":"btcusdt@bookTicker","event_type":"bookTicker","event_time_ms":1788567792394,"raw_json":"{\"stream\":\"btcusdt@bookTicker\",\"data\":{\"e\":\"bookTicker\",\"u\":11478512115632,\"s\":\"BTCUSDT\",\"ps\":\"BTCUSDT\",\"b\":\"79596.90\",\"B\":\"7.011\",\"a\":\"79597.00\",\"A\":\"7.992\",\"T\":1788567792394,\"E\":1788567792394,\"st\":1}}"}
{"receive_ns":1788567792414877000,"stream":"btcusdt@bookTicker","event_type":"bookTicker","event_time_ms":1788567792426,"raw_json":"{\"stream\":\"btcusdt@bookTicker\",\"data\":{\"e\":\"bookTicker\",\"u\":11478512117935,\"s\":\"BTCUSDT\",\"ps\":\"BTCUSDT\",\"b\":\"79596.90\",\"B\":\"7.011\",\"a\":\"79597.00\",\"A\":\"7.974\",\"T\":1788567792426,\"E\":1788567792426,\"st\":1}}"}
{"receive_ns":1788567792426125000,"stream":"btcusdt@trade","event_type":"trade","event_time_ms":1788567792426,"raw_json":"{\"stream\":\"btcusdt@trade\",\"data\":{\"e\":\"trade\",\"E\":1788567792426,\"T\":1788567792426,\"s\":\"BTCUSDT\",\"t\":8054122890,\"p\":\"79597.00\",\"q\":\"0.018\",\"X\":\"MARKET\",\"m\":false,\"st\":1}}"}
{"receive_ns":1788567792467901000,"stream":"btcusdt@bookTicker","event_type":"bookTicker","event_time_ms":1788567792451,"raw_json":"{\"stream\":\"btcusdt@bookTicker\",\"data\":{\"e\":\"bookTicker\",\"u\":11478512119660,\"s\":\"BTCUSDT\",\"ps\":\"BTCUSDT\",\"b\":\"79596.90\",\"B\":\"6.990\",\"a\":\"79597.00\",\"A\":\"7.974\",\"T\":1788567792450,\"E\":1788567792451,\"st\":1}}"}
{"receive_ns":1788567792471112000,"stream":"btcusdt@bookTicker","event_type":"bookTicker","event_time_ms":1788567792453,"raw_json":"{\"stream\":\"btcusdt@bookTicker\",\"data\":{\"e\":\"bookTicker\",\"u\":11478512119828,\"s\":\"BTCUSDT\",\"ps\":\"BTCUSDT\",\"b\":\"79596.90\",\"B\":\"7.010\",\"a\":\"79597.00\",\"A\":\"7.974\",\"T\":1788567792453,\"E\":1788567792453,\"st\":1}}"}
{"receive_ns":1788567792482650000,"stream":"btcusdt@depth@100ms","event_type":"depthUpdate","event_time_ms":1788567792483,"raw_json":"{\"stream\":\"btcusdt@depth@100ms\",\"data\":{\"e\":\"depthUpdate\",\"E\":1788567792483,\"T\":1788567792481,\"s\":\"BTCUSDT\",\"ps\":\"BTCUSDT\",\"U\":11478512115052,\"u\":11478512122132,\"pu\":11478512114822,\"b\":[[\"29296.90\",\"0.098\"],[\"29396.90\",\"1.841\"],[\"29496.90\",\"0.161\"],[\"71637.20\",\"0.002\"],[\"76413.00\",\"0.025\"],[\"78800.90\",\"15.422\"],[\"79198.90\",\"3.971\"],[\"79553.80\",\"0.000\"],[\"79582.30\",\"0.119\"],[\"79593.70\",\"0.076\"],[\"79596.90\",\"7.010\"]],\"a\":[[\"79597.00\",\"7.974\"],[\"79598.80\",\"0.003\"],[\"79598.90\",\"0.001\"],[\"79599.00\",\"0.002\"],[\"79599.10\",\"0.078\"],[\"79599.30\",\"0.018\"],[\"79599.40\",\"0.000\"],[\"79599.50\",\"0.003\"],[\"79599.60\",\"0.000\"],[\"79599.70\",\"0.000\"],[\"79600.00\",\"0.075\"],[\"79600.20\",\"0.027\"],[\"79600.30\",\"0.028\"],[\"79600.40\",\"0.034\"],[\"79600.50\",\"0.104\"],[\"79600.60\",\"0.026\"],[\"79600.70\",\"0.030\"],[\"79600.90\",\"0.028\"],[\"79601.20\",\"0.002\"],[\"79610.70\",\"0.106\"],[\"79612.00\",\"0.003\"],[\"79615.90\",\"0.628\"],[\"79666.10\",\"21.686\"],[\"79668.80\",\"0.034\"],[\"79674.20\",\"0.001\"],[\"80393.00\",\"15.389\"]],\"st\":1}}"}
{"receive_ns":1788567792532701000,"stream":"btcusdt@bookTicker","event_type":"bookTicker","event_time_ms":1788567792543,"raw_json":"{\"stream\":\"btcusdt@bookTicker\",\"data\":{\"e\":\"bookTicker\",\"u\":11478512124897,\"s\":\"BTCUSDT\",\"ps\":\"BTCUSDT\",\"b\":\"79596.90\",\"B\":\"6.990\",\"a\":\"79597.00\",\"A\":\"7.974\",\"T\":1788567792543,\"E\":1788567792543,\"st\":1}}"}
{"receive_ns":1788567792542578000,"stream":"btcusdt@bookTicker","event_type":"bookTicker","event_time_ms":1788567792546,"raw_json":"{\"stream\":\"btcusdt@bookTicker\",\"data\":{\"e\":\"bookTicker\",\"u\":11478512125012,\"s\":\"BTCUSDT\",\"ps\":\"BTCUSDT\",\"b\":\"79596.90\",\"B\":\"7.012\",\"a\":\"79597.00\",\"A\":\"7.974\",\"T\":1788567792546,\"E\":1788567792546,\"st\":1}}"}
{"receive_ns":1788567792571160000,"stream":"btcusdt@bookTicker","event_type":"bookTicker","event_time_ms":1788567792582,"raw_json":"{\"stream\":\"btcusdt@bookTicker\",\"data\":{\"e\":\"bookTicker\",\"u\":11478512126572,\"s\":\"BTCUSDT\",\"ps\":\"BTCUSDT\",\"b\":\"79596.90\",\"B\":\"7.013\",\"a\":\"79597.00\",\"A\":\"7.974\",\"T\":1788567792582,\"E\":1788567792582,\"st\":1}}"}
{"receive_ns":1788567792577388000,"stream":"btcusdt@depth@100ms","event_type":"depthUpdate","event_time_ms":1788567792585,"raw_json":"{\"stream\":\"btcusdt@depth@100ms\",\"data\":{\"e\":\"depthUpdate\",\"E\":1788567792585,\"T\":1788567792584,\"s\":\"BTCUSDT\",\"ps\":\"BTCUSDT\",\"U\":11478512122214,\"u\":11478512126762,\"pu\":11478512122132,\"b\":[[\"1000.00\",\"24.604\"],[\"29296.90\",\"0.154\"],[\"29396.90\",\"1.904\"],[\"29496.90\",\"0.042\"],[\"63678.00\",\"0.012\"],[\"71637.20\",\"0.002\"],[\"76413.00\",\"0.023\"],[\"78005.00\",\"0.219\"],[\"78492.60\",\"2.543\"],[\"78522.30\",\"8.329\"],[\"78601.90\",\"14.077\"],[\"78800.90\",\"15.422\"],[\"78960.10\",\"8.084\"],[\"79451.40\",\"1.884\"],[\"79496.40\",\"0.000\"],[\"79517.30\",\"0.068\"],[\"79525.20\",\"0.002\"],[\"79537.80\",\"3.696\"],[\"79541.10\",\"1.096\"],[\"79576.10\",\"0.009\"],[\"79577.20\",\"0.373\"],[\"79593.70\",\"0.000\"],[\"79595.70\",\"0.001\"],[\"79596.90\",\"7.013\"]],\"a\":[[\"79599.70\",\"0.026\"],[\"79600.00\",\"0.049\"],[\"79601.00\",\"0.347\"],[\"79610.90\",\"0.003\"],[\"79612.80\",\"0.442\"],[\"79616.00\",\"0.009\"],[\"79617.20\",\"0.372\"],[\"79630.50\",\"0.000\"],[\"79631.70\",\"0.046\"],[\"79665.40\",\"4.831\"],[\"79668.70\",\"2.054\"],[\"79692.60\",\"0.002\"],[\"79719.80\",\"1.884\"],[\"80393.00\",\"15.389\"],[\"83576.80\",\"0.012\"]],\"st\":1}}"}
{"receive_ns":1788567792630927000,"stream":"btcusdt@bookTicker","event_type":"bookTicker","event_time_ms":1788567792646,"raw_json":"{\"stream\":\"btcusdt@bookTicker\",\"data\":{\"e\":\"bookTicker\",\"u\":11478512129727,\"s\":\"BTCUSDT\",\"ps\":\"BTCUSDT\",\"b\":\"79596.90\",\"B\":\"7.013\",\"a\":\"79597.00\",\"A\":\"7.953\",\"T\":1788567792646,\"E\":1788567792646,\"st\":1}}"}
{"receive_ns":1788567792675883000,"stream":"btcusdt@depth@100ms","event_type":"depthUpdate","event_time_ms":1788567792687,"raw_json":"{\"stream\":\"btcusdt@depth@100ms\",\"data\":{\"e\":\"depthUpdate\",\"E\":1788567792687,\"T\":1788567792685,\"s\":\"BTCUSDT\",\"ps\":\"BTCUSDT\",\"U\":11478512126835,\"u\":11478512132169,\"pu\":11478512126762,\"b\":[[\"1000.00\",\"24.604\"],[\"29296.90\",\"0.294\"],[\"29396.90\",\"1.806\"],[\"29496.90\",\"0.000\"],[\"71637.20\",\"0.002\"],[\"78005.00\",\"0.222\"],[\"78800.90\",\"15.422\"],[\"79499.10\",\"0.004\"],[\"79520.00\",\"0.772\"],[\"79541.10\",\"1.098\"],[\"79571.80\",\"0.002\"],[\"79576.20\",\"0.620\"],[\"79577.20\",\"0.000\"],[\"79587.10\",\"0.001\"],[\"79593.70\",\"0.076\"]],\"a\":[[\"79597.00\",\"7.953\"],[\"79610.70\",\"0.545\"],[\"79612.80\",\"0.003\"],[\"79615.90\",\"0.000\"],[\"79616.10\",\"1.009\"],[\"79616.30\",\"0.641\"],[\"79617.20\",\"0.000\"],[\"79692.60\",\"0.004\"],[\"80393.00\",\"15.389\"]],\"st\":1}}"}
{"receive_ns":1788567792770877000,"stream":"btcusdt@bookTicker","event_type":"bookTicker","event_time_ms":1788567792760,"raw_json":"{\"stream\":\"btcusdt@bookTicker\",\"data\":{\"e\":\"bookTicker\",\"u\":11478512138106,\"s\":\"BTCUSDT\",\"ps\":\"BTCUSDT\",\"b\":\"79596.90\",\"B\":\"7.023\",\"a\":\"79597.00\",\"A\":\"7.953\",\"T\":1788567792760,\"E\":1788567792760,\"st\":1}}"}
{"receive_ns":1788567792793830000,"stream":"btcusdt@depth@100ms","event_type":"depthUpdate","event_time_ms":1788567792789,"raw_json":"{\"stream\":\"btcusdt@depth@100ms\",\"data\":{\"e\":\"depthUpdate\",\"E\":1788567792789,\"T\":1788567792787,\"s\":\"BTCUSDT\",\"ps\":\"BTCUSDT\",\"U\":11478512132356,\"u\":11478512139487,\"pu\":11478512132169,\"b\":[[\"29296.90\",\"0.469\"],[\"29396.90\",\"1.631\"],[\"71637.20\",\"0.002\"],[\"76413.00\",\"0.025\"],[\"78800.90\",\"15.422\"],[\"78960.10\",\"8.336\"],[\"79198.90\",\"3.981\"],[\"79418.00\",\"3.141\"],[\"79475.60\",\"0.000\"],[\"79509.10\",\"0.323\"],[\"79509.20\",\"0.038\"],[\"79515.00\",\"0.012\"],[\"79539.90\",\"0.001\"],[\"79571.80\",\"0.127\"],[\"79591.50\",\"0.000\"],[\"79591.80\",\"0.004\"],[\"79596.90\",\"7.023\"]],\"a\":[[\"79599.30\",\"0.044\"],[\"79627.80\",\"0.003\"],[\"79684.40\",\"0.038\"],[\"79718.90\",\"0.001\"],[\"79739.50\",\"3.141\"],[\"80393.00\",\"15.389\"],[\"80592.10\",\"5.135\"]],\"st\":1}}"}
{"receive_ns":1788567792879749000,"stream":"btcusdt@depth@100ms","event_type":"depthUpdate","event_time_ms":1788567792891,"raw_json":"{\"stream\":\"btcusdt@depth@100ms\",\"data\":{\"e\":\"depthUpdate\",\"E\":1788567792891,\"T\":1788567792890,\"s\":\"BTCUSDT\",\"ps\":\"BTCUSDT\",\"U\":11478512139625,\"u\":11478512145558,\"pu\":11478512139487,\"b\":[[\"1000.00\",\"24.604\"],[\"29296.90\",\"0.651\"],[\"29396.90\",\"1.449\"],[\"71637.20\",\"0.002\"],[\"71673.00\",\"0.003\"],[\"76413.00\",\"0.023\"],[\"78164.20\",\"2.810\"],[\"78601.90\",\"14.268\"],[\"78800.90\",\"15.422\"],[\"79475.60\",\"0.421\"],[\"79506.80\",\"0.019\"],[\"79571.80\",\"0.002\"],[\"79572.10\",\"0.001\"],[\"79595.80\",\"0.059\"]],\"a\":[[\"79688.30\",\"0.035\"],[\"79718.80\",\"1.554\"],[\"79806.00\",\"1.834\"],[\"80393.00\",\"15.389\"]],\"st\":1}}"}
{"receive_ns":1788567792896191000,"stream":"btcusdt@bookTicker","event_type":"bookTicker","event_time_ms":1788567792896,"raw_json":"{\"stream\":\"btcusdt@bookTicker\",\"data\":{\"e\":\"bookTicker\",\"u\":11478512145824,\"s\":\"BTCUSDT\",\"ps\":\"BTCUSDT\",\"b\":\"79596.90\",\"B\":\"6.838\",\"a\":\"79597.00\",\"A\":\"7.953\",\"T\":1788567792896,\"E\":1788567792896,\"st\":1}}"}
{"receive_ns":1788567792908054000,"stream":"btcusdt@bookTicker","event_type":"bookTicker","event_time_ms":1788567792900,"raw_json":"{\"stream\":\"btcusdt@bookTicker\",\"data\":{\"e\":\"bookTicker\",\"u\":11478512146011,\"s\":\"BTCUSDT\",\"ps\":\"BTCUSDT\",\"b\":\"79596.90\",\"B\":\"7.023\",\"a\":\"79597.00\",\"A\":\"7.953\",\"T\":1788567792899,\"E\":1788567792900,\"st\":1}}"}
{"receive_ns":1788567792993716000,"stream":"btcusdt@depth@100ms","event_type":"depthUpdate","event_time_ms":1788567792993,"raw_json":"{\"stream\":\"btcusdt@depth@100ms\",\"data\":{\"e\":\"depthUpdate\",\"E\":1788567792993,\"T\":1788567792991,\"s\":\"BTCUSDT\",\"ps\":\"BTCUSDT\",\"U\":11478512145632,\"u\":11478512152040,\"pu\":11478512145558,\"b\":[[\"1000.00\",\"24.604\"],[\"29296.90\",\"0.826\"],[\"29396.90\",\"1.274\"],[\"71637.20\",\"0.002\"],[\"76413.00\",\"0.025\"],[\"78506.40\",\"1.525\"],[\"78800.90\",\"15.422\"],[\"79572.10\",\"0.126\"],[\"79572.30\",\"0.000\"],[\"79596.90\",\"7.023\"]],\"a\":[[\"79804.90\",\"0.635\"],[\"80000.00\",\"41.728\"],[\"80393.00\",\"15.389\"],[\"80592.10\",\"4.986\"]],\"st\":1}}"}
{"receive_ns":1788567793054095000,"stream":"btcusdt@bookTicker","event_type":"bookTicker","event_time_ms":1788567793044,"raw_json":"{\"stream\":\"btcusdt@bookTicker\",\"data\":{\"e\":\"bookTicker\",\"u\":11478512155355,\"s\":\"BTCUSDT\",\"ps\":\"BTCUSDT\",\"b\":\"79596.90\",\"B\":\"7.023\",\"a\":\"79597.00\",\"A\":\"7.952\",\"T\":1788567793044,\"E\":1788567793044,\"st\":1}}"}
{"receive_ns":1788567793054813000,"stream":"btcusdt@bookTicker","event_type":"bookTicker","event_time_ms":1788567793045,"raw_json":"{\"stream\":\"btcusdt@bookTicker\",\"data\":{\"e\":\"bookTicker\",\"u\":11478512155401,\"s\":\"BTCUSDT\",\"ps\":\"BTCUSDT\",\"b\":\"79596.90\",\"B\":\"7.021\",\"a\":\"79597.00\",\"A\":\"7.952\",\"T\":1788567793044,\"E\":1788567793045,\"st\":1}}"}
{"receive_ns":1788567793055101000,"stream":"btcusdt@bookTicker","event_type":"bookTicker","event_time_ms":1788567793045,"raw_json":"{\"stream\":\"btcusdt@bookTicker\",\"data\":{\"e\":\"bookTicker\",\"u\":11478512155406,\"s\":\"BTCUSDT\",\"ps\":\"BTCUSDT\",\"b\":\"79596.90\",\"B\":\"7.021\",\"a\":\"79597.00\",\"A\":\"7.944\",\"T\":1788567793044,\"E\":1788567793045,\"st\":1}}"}
{"receive_ns":1788567793066390000,"stream":"btcusdt@bookTicker","event_type":"bookTicker","event_time_ms":1788567793047,"raw_json":"{\"stream\":\"btcusdt@bookTicker\",\"data\":{\"e\":\"bookTicker\",\"u\":11478512155705,\"s\":\"BTCUSDT\",\"ps\":\"BTCUSDT\",\"b\":\"79596.90\",\"B\":\"7.038\",\"a\":\"79597.00\",\"A\":\"7.944\",\"T\":1788567793047,\"E\":1788567793047,\"st\":1}}"}
{"receive_ns":1788567793072058000,"stream":"btcusdt@bookTicker","event_type":"bookTicker","event_time_ms":1788567793051,"raw_json":"{\"stream\":\"btcusdt@bookTicker\",\"data\":{\"e\":\"bookTicker\",\"u\":11478512155817,\"s\":\"BTCUSDT\",\"ps\":\"BTCUSDT\",\"b\":\"79596.90\",\"B\":\"7.016\",\"a\":\"79597.00\",\"A\":\"7.944\",\"T\":1788567793050,\"E\":1788567793051,\"st\":1}}"}
{"receive_ns":1788567793078811000,"stream":"btcusdt@bookTicker","event_type":"bookTicker","event_time_ms":1788567793054,"raw_json":"{\"stream\":\"btcusdt@bookTicker\",\"data\":{\"e\":\"bookTicker\",\"u\":11478512156093,\"s\":\"BTCUSDT\",\"ps\":\"BTCUSDT\",\"b\":\"79596.90\",\"B\":\"7.046\",\"a\":\"79597.00\",\"A\":\"7.944\",\"T\":1788567793054,\"E\":1788567793054,\"st\":1}}"}
{"receive_ns":1788567793090830000,"stream":"btcusdt@bookTicker","event_type":"bookTicker","event_time_ms":1788567793066,"raw_json":"{\"stream\":\"btcusdt@bookTicker\",\"data\":{\"e\":\"bookTicker\",\"u\":11478512156582,\"s\":\"BTCUSDT\",\"ps\":\"BTCUSDT\",\"b\":\"79596.90\",\"B\":\"7.046\",\"a\":\"79597.00\",\"A\":\"7.945\",\"T\":1788567793066,\"E\":1788567793066,\"st\":1}}"}
{"receive_ns":1788567793096530000,"stream":"btcusdt@bookTicker","event_type":"bookTicker","event_time_ms":1788567793072,"raw_json":"{\"stream\":\"btcusdt@bookTicker\",\"data\":{\"e\":\"bookTicker\",\"u\":11478512156886,\"s\":\"BTCUSDT\",\"ps\":\"BTCUSDT\",\"b\":\"79596.90\",\"B\":\"7.046\",\"a\":\"79597.00\",\"A\":\"7.953\",\"T\":1788567793072,\"E\":1788567793072,\"st\":1}}"}
{"receive_ns":1788567793102612000,"stream":"btcusdt@bookTicker","event_type":"bookTicker","event_time_ms":1788567793078,"raw_json":"{\"stream\":\"btcusdt@bookTicker\",\"data\":{\"e\":\"bookTicker\",\"u\":11478512157135,\"s\":\"BTCUSDT\",\"ps\":\"BTCUSDT\",\"b\":\"79596.90\",\"B\":\"7.048\",\"a\":\"79597.00\",\"A\":\"7.953\",\"T\":1788567793077,\"E\":1788567793078,\"st\":1}}"}
{"receive_ns":1788567793109285000,"stream":"btcusdt@depth@100ms","event_type":"depthUpdate","event_time_ms":1788567793095,"raw_json":"{\"stream\":\"btcusdt@depth@100ms\",\"data\":{\"e\":\"depthUpdate\",\"E\":1788567793095,\"T\":1788567793093,\"s\":\"BTCUSDT\",\"ps\":\"BTCUSDT\",\"U\":11478512152218,\"u\":11478512158078,\"pu\":11478512152040,\"b\":[[\"29296.90\",\"1.008\"],[\"29396.90\",\"1.092\"],[\"71637.20\",\"0.002\"],[\"71673.00\",\"0.000\"],[\"75617.10\",\"0.008\"],[\"75617.20\",\"0.006\"],[\"76413.00\",\"0.023\"],[\"78575.20\",\"1.043\"],[\"78589.30\",\"0.007\"],[\"78608.10\",\"0.014\"],[\"78620.00\",\"5.526\"],[\"78800.90\",\"15.422\"],[\"79198.90\",\"3.981\"],[\"79506.80\",\"4.386\"],[\"79572.10\",\"0.001\"],[\"79572.30\",\"0.000\"],[\"79582.60\",\"0.070\"],[\"79584.60\",\"0.351\"],[\"79595.80\",\"0.026\"],[\"79596.90\",\"7.048\"]],\"a\":[[\"79597.00\",\"7.953\"],[\"79630.70\",\"0.049\"],[\"79631.70\",\"0.000\"],[\"79688.30\",\"3.343\"],[\"79696.80\",\"0.000\"],[\"79725.50\",\"0.041\"],[\"79725.90\",\"0.000\"],[\"79806.00\",\"4.869\"],[\"79819.10\",\"6.960\"],[\"80371.40\",\"0.000\"],[\"80393.00\",\"15.389\"],[\"80399.10\",\"4.284\"],[\"80466.90\",\"0.015\"],[\"80671.60\",\"7.200\"]],\"st\":1}}"}
{"receive_ns":1788567793182955000,"stream":"btcusdt@bookTicker","event_type":"bookTicker","event_time_ms":1788567793188,"raw_json":"{\"stream\":\"btcusdt@bookTicker\",\"data\":{\"e\":\"bookTicker\",\"u\":11478512162987,\"s\":\"BTCUSDT\",\"ps\":\"BTCUSDT\",\"b\":\"79596.90\",\"B\":\"7.045\",\"a\":\"79597.00\",\"A\":\"7.953\",\"T\":1788567793187,\"E\":1788567793188,\"st\":1}}"}
{"receive_ns":1788567793183900000,"stream":"btcusdt@bookTicker","event_type":"bookTicker","event_time_ms":1788567793190,"raw_json":"{\"stream\":\"btcusdt@bookTicker\",\"data\":{\"e\":\"bookTicker\",\"u\":11478512163157,\"s\":\"BTCUSDT\",\"ps\":\"BTCUSDT\",\"b\":\"79596.90\",\"B\":\"7.050\",\"a\":\"79597.00\",\"A\":\"7.953\",\"T\":1788567793190,\"E\":1788567793190,\"st\":1}}"}
{"receive_ns":1788567793207708000,"stream":"btcusdt@depth@100ms","event_type":"depthUpdate","event_time_ms":1788567793197,"raw_json":"{\"stream\":\"btcusdt@depth@100ms\",\"data\":{\"e\":\"depthUpdate\",\"E\":1788567793197,\"T\":1788567793193,\"s\":\"BTCUSDT\",\"ps\":\"BTCUSDT\",\"U\":11478512158211,\"u\":11478512163328,\"pu\":11478512158078,\"b\":[[\"1000.00\",\"24.604\"],[\"29296.90\",\"1.183\"],[\"29396.90\",\"0.917\"],[\"71637.20\",\"0.002\"],[\"74293.00\",\"1.000\"],[\"78522.30\",\"8.964\"],[\"78641.70\",\"34.953\"],[\"78726.10\",\"0.001\"],[\"78800.90\",\"15.422\"],[\"79436.20\",\"0.014\"],[\"79475.60\",\"0.000\"],[\"79572.50\",\"0.266\"],[\"79573.20\",\"0.538\"],[\"79596.90\",\"7.050\"]],\"a\":[[\"79613.10\",\"0.194\"],[\"79691.40\",\"2.077\"],[\"79693.50\",\"0.005\"],[\"79693.70\",\"0.000\"],[\"79703.30\",\"0.000\"],[\"79705.40\",\"0.001\"],[\"79718.80\",\"1.168\"],[\"79758.30\",\"0.000\"],[\"79995.00\",\"4.199\"],[\"80393.00\",\"15.315\"],[\"80464.60\",\"3.413\"],[\"81188.90\",\"0.015\"],[\"87556.70\",\"0.000\"]],\"st\":1}}"}
{"receive_ns":1788567793265120000,"stream":"btcusdt@bookTicker","event_type":"bookTicker","event_time_ms":1788567793272,"raw_json":"{\"stream\":\"btcusdt@bookTicker\",\"data\":{\"e\":\"bookTicker\",\"u\":11478512167447,\"s\":\"BTCUSDT\",\"ps\":\"BTCUSDT\",\"b\":\"79596.90\",\"B\":\"7.050\",\"a\":\"79597.00\",\"A\":\"7.950\",\"T\":1788567793272,\"E\":1788567793272,\"st\":1}}"}
{"receive_ns":1788567793277646000,"stream":"btcusdt@trade","event_type":"trade","event_time_ms":1788567793272,"raw_json":"{\"stream\":\"btcusdt@trade\",\"data\":{\"e\":\"trade\",\"E\":1788567793272,\"T\":1788567793272,\"s\":\"BTCUSDT\",\"t\":8054122891,\"p\":\"79597.00\",\"q\":\"0.003\",\"X\":\"MARKET\",\"m\":false,\"st\":1}}"}
{"receive_ns":1788567793288978000,"stream":"btcusdt@depth@100ms","event_type":"depthUpdate","event_time_ms":1788567793299,"raw_json":"{\"stream\":\"btcusdt@depth@100ms\",\"data\":{\"e\":\"depthUpdate\",\"E\":1788567793299,\"T\":1788567793298,\"s\":\"BTCUSDT\",\"ps\":\"BTCUSDT\",\"U\":11478512163504,\"u\":11478512171135,\"pu\":11478512163328,\"b\":[[\"1000.00\",\"24.604\"],[\"29296.90\",\"1.365\"],[\"29396.90\",\"0.735\"],[\"63677.50\",\"0.000\"],[\"71637.20\",\"0.002\"],[\"76413.00\",\"0.025\"],[\"78230.00\",\"5.612\"],[\"78647.90\",\"12.612\"],[\"78800.90\",\"15.424\"],[\"79198.90\",\"3.981\"],[\"79270.10\",\"0.000\"],[\"79293.60\",\"0.005\"],[\"79436.20\",\"1.819\"],[\"79475.60\",\"0.393\"],[\"79529.80\",\"0.003\"],[\"79543.90\",\"0.295\"],[\"79553.00\",\"0.062\"]],\"a\":[[\"79597.00\",\"7.950\"],[\"79598.40\",\"0.007\"],[\"79599.30\",\"0.018\"],[\"79599.70\",\"0.000\"],[\"79600.20\",\"0.001\"],[\"79626.60\",\"0.010\"],[\"79660.30\",\"1.977\"],[\"79670.00\",\"0.015\"],[\"79718.80\",\"1.534\"],[\"79758.20\",\"2.012\"],[\"79819.10\",\"6.974\"],[\"79995.00\",\"4.696\"],[\"80369.10\",\"1.961\"],[\"80393.00\",\"15.315\"],[\"80751.30\",\"8.324\"]],\"st\":1}}"}
{"receive_ns":1788567793391347000,"stream":"btcusdt@depth@100ms","event_type":"depthUpdate","event_time_ms":1788567793401,"raw_json":"{\"stream\":\"btcusdt@depth@100ms\",\"data\":{\"e\":\"depthUpdate\",\"E\":1788567793401,\"T\":1788567793398,\"s\":\"BTCUSDT\",\"ps\":\"BTCUSDT\",\"U\":11478512171206,\"u\":11478512183057,\"pu\":11478512171135,\"b\":[[\"29296.90\",\"1.540\"],[\"29396.90\",\"0.560\"],[\"63678.00\",\"0.012\"],[\"71637.20\",\"0.002\"],[\"76413.00\",\"0.023\"],[\"78800.90\",\"15.422\"],[\"79198.90\",\"3.981\"],[\"79544.60\",\"0.068\"],[\"79553.00\",\"0.002\"],[\"79567.80\",\"0.000\"],[\"79568.50\",\"0.630\"],[\"79572.20\",\"0.754\"],[\"79572.50\",\"0.266\"],[\"79575.90\",\"0.000\"],[\"79576.40\",\"3.525\"]],\"a\":[[\"79600.30\",\"0.002\"],[\"79600.40\",\"0.008\"],[\"79600.50\",\"0.078\"],[\"79600.60\",\"0.000\"],[\"79600.70\",\"0.004\"],[\"79600.90\",\"0.002\"],[\"79601.00\",\"0.321\"],[\"79601.60\",\"0.107\"],[\"79604.20\",\"0.007\"],[\"79604.60\",\"0.141\"],[\"79619.90\",\"0.000\"],[\"79620.30\",\"1.079\"],[\"79624.10\",\"0.001\"],[\"79624.40\",\"0.627\"],[\"79658.00\",\"0.003\"],[\"79666.10\",\"21.746\"],[\"79995.00\",\"4.572\"],[\"80393.00\",\"15.315\"],[\"80592.10\",\"4.708\"]],\"st\":1}}"}
{"receive_ns":1788567793402377000,"stream":"btcusdt@bookTicker","event_type":"bookTicker","event_time_ms":1788567793403,"raw_json":"{\"stream\":\"btcusdt@bookTicker\",\"data\":{\"e\":\"bookTicker\",\"u\":11478512183545,\"s\":\"BTCUSDT\",\"ps\":\"BTCUSDT\",\"b\":\"79596.90\",\"B\":\"6.865\",\"a\":\"79597.00\",\"A\":\"7.950\",\"T\":1788567793403,\"E\":1788567793403,\"st\":1}}"}
{"receive_ns":1788567793414692000,"stream":"btcusdt@bookTicker","event_type":"bookTicker","event_time_ms":1788567793406,"raw_json":"{\"stream\":\"btcusdt@bookTicker\",\"data\":{\"e\":\"bookTicker\",\"u\":11478512183960,\"s\":\"BTCUSDT\",\"ps\":\"BTCUSDT\",\"b\":\"79596.90\",\"B\":\"7.050\",\"a\":\"79597.00\",\"A\":\"7.950\",\"T\":1788567793406,\"E\":1788567793406,\"st\":1}}"}
{"receive_ns":1788567793443544000,"stream":"btcusdt@bookTicker","event_type":"bookTicker","event_time_ms":1788567793455,"raw_json":"{\"stream\":\"btcusdt@bookTicker\",\"data\":{\"e\":\"bookTicker\",\"u\":11478512188859,\"s\":\"BTCUSDT\",\"ps\":\"BTCUSDT\",\"b\":\"79596.90\",\"B\":\"7.041\",\"a\":\"79597.00\",\"A\":\"7.950\",\"T\":1788567793454,\"E\":1788567793455,\"st\":1}}"}
{"receive_ns":1788567793459452000,"stream":"btcusdt@trade","event_type":"trade","event_time_ms":1788567793455,"raw_json":"{\"stream\":\"btcusdt@trade\",\"data\":{\"e\":\"trade\",\"E\":1788567793455,\"T\":1788567793454,\"s\":\"BTCUSDT\",\"t\":8054122892,\"p\":\"79596.90\",\"q\":\"0.009\",\"X\":\"MARKET\",\"m\":true,\"st\":1}}"}
{"receive_ns":1788567793470956000,"stream":"btcusdt@bookTicker","event_type":"bookTicker","event_time_ms":1788567793459,"raw_json":"{\"stream\":\"btcusdt@bookTicker\",\"data\":{\"e\":\"bookTicker\",\"u\":11478512189338,\"s\":\"BTCUSDT\",\"ps\":\"BTCUSDT\",\"b\":\"79596.90\",\"B\":\"7.021\",\"a\":\"79597.00\",\"A\":\"7.950\",\"T\":1788567793459,\"E\":1788567793459,\"st\":1}}"}
{"receive_ns":1788567793487380000,"stream":"btcusdt@bookTicker","event_type":"bookTicker","event_time_ms":1788567793462,"raw_json":"{\"stream\":\"btcusdt@bookTicker\",\"data\":{\"e\":\"bookTicker\",\"u\":11478512189533,\"s\":\"BTCUSDT\",\"ps\":\"BTCUSDT\",\"b\":\"79596.90\",\"B\":\"7.039\",\"a\":\"79597.00\",\"A\":\"7.950\",\"T\":1788567793462,\"E\":1788567793462,\"st\":1}}"}
{"receive_ns":1788567793499515000,"stream":"btcusdt@depth@100ms","event_type":"depthUpdate","event_time_ms":1788567793503,"raw_json":"{\"stream\":\"btcusdt@depth@100ms\",\"data\":{\"e\":\"depthUpdate\",\"E\":1788567793503,\"T\":1788567793501,\"s\":\"BTCUSDT\",\"ps\":\"BTCUSDT\",\"U\":11478512183476,\"u\":11478512192605,\"pu\":11478512183057,\"b\":[[\"1000.00\",\"24.604\"],[\"29296.90\",\"1.722\"],[\"29396.90\",\"0.378\"],[\"71637.20\",\"0.002\"],[\"76413.00\",\"0.025\"],[\"78800.90\",\"15.422\"],[\"79397.90\",\"0.328\"],[\"79501.30\",\"0.002\"],[\"79549.70\",\"0.715\"],[\"79572.20\",\"0.629\"],[\"79584.60\",\"0.348\"],[\"79596.90\",\"7.039\"]],\"a\":[[\"79601.00\",\"0.347\"],[\"79601.70\",\"0.026\"],[\"79601.80\",\"0.027\"],[\"79601.90\",\"0.028\"],[\"79602.10\",\"0.026\"],[\"79602.20\",\"0.027\"],[\"79602.30\",\"0.029\"],[\"79602.40\",\"1.011\"],[\"79604.20\",\"0.008\"],[\"79604.60\",\"0.140\"],[\"79610.90\",\"0.003\"],[\"79616.10\",\"0.381\"],[\"79616.40\",\"2.360\"],[\"79622.40\",\"2.026\"],[\"79665.40\",\"1.810\"],[\"79666.10\",\"0.075\"],[\"79674.20\",\"21.672\"],[\"79676.60\",\"0.021\"],[\"79732.40\",\"0.007\"],[\"79995.00\",\"4.573\"],[\"80393.00\",\"15.315\"]],\"st\":1}}"}
{"receive_ns":1788567793594046000,"stream":"btcusdt@depth@100ms","event_type":"depthUpdate","event_time_ms":1788567793605,"raw_json":"{\"stream\":\"btcusdt@depth@100ms\",\"data\":{\"e\":\"depthUpdate\",\"E\":1788567793605,\"T\":1788567793604,\"s\":\"BTCUSDT\",\"ps\":\"BTCUSDT\",\"U\":11478512192785,\"u\":11478512199234,\"pu\":11478512192605,\"b\":[[\"1000.00\",\"24.604\"],[\"29196.90\",\"0.049\"],[\"29296.90\",\"1.799\"],[\"29396.90\",\"0.252\"],[\"63678.00\",\"0.012\"],[\"71637.20\",\"0.002\"],[\"78800.90\",\"15.422\"],[\"79572.20\",\"0.001\"],[\"79576.80\",\"0.644\"],[\"79591.80\",\"0.000\"],[\"79592.50\",\"0.082\"]],\"a\":[[\"79600.90\",\"0.028\"],[\"79622.90\",\"0.274\"],[\"79668.50\",\"5.748\"],[\"79668.80\",\"21.712\"],[\"79674.20\",\"0.001\"],[\"79804.90\",\"0.999\"],[\"80393.00\",\"15.315\"],[\"80711.40\",\"36.369\"],[\"81173.00\",\"0.614\"]],\"st\":1}}"}
{"receive_ns":1788567793668773000,"stream":"btcusdt@bookTicker","event_type":"bookTicker","event_time_ms":1788567793683,"raw_json":"{\"stream\":\"btcusdt@bookTicker\",\"data\":{\"e\":\"bookTicker\",\"u\":11478512204699,\"s\":\"BTCUSDT\",\"ps\":\"BTCUSDT\",\"b\":\"79596.90\",\"B\":\"7.039\",\"a\":\"79597.00\",\"A\":\"7.949\",\"T\":1788567793683,\"E\":1788567793683,\"st\":1}}"}
{"receive_ns":1788567793681787000,"stream":"btcusdt@bookTicker","event_type":"bookTicker","event_time_ms":1788567793686,"raw_json":"{\"stream\":\"btcusdt@bookTicker\",\"data\":{\"e\":\"bookTicker\",\"u\":11478512205050,\"s\":\"BTCUSDT\",\"ps\":\"BTCUSDT\",\"b\":\"79596.90\",\"B\":\"7.042\",\"a\":\"79597.00\",\"A\":\"7.949\",\"T\":1788567793686,\"E\":1788567793686,\"st\":1}}"}
{"receive_ns":1788567793694526000,"stream":"btcusdt@depth@100ms","event_type":"depthUpdate","event_time_ms":1788567793707,"raw_json":"{\"stream\":\"btcusdt@depth@100ms\",\"data\":{\"e\":\"depthUpdate\",\"E\":1788567793707,\"T\":1788567793706,\"s\":\"BTCUSDT\",\"ps\":\"BTCUSDT\",\"U\":11478512199410,\"u\":11478512206414,\"pu\":11478512199234,\"b\":[[\"29196.90\",\"0.112\"],[\"29296.90\",\"1.855\"],[\"29396.90\",\"0.133\"],[\"63678.00\",\"0.012\"],[\"71637.20\",\"0.002\"],[\"76413.00\",\"0.023\"],[\"78800.90\",\"15.422\"],[\"79198.90\",\"3.981\"],[\"79566.70\",\"0.000\"],[\"79567.80\",\"0.046\"],[\"79568.90\",\"0.003\"],[\"79570.90\",\"0.454\"],[\"79573.00\",\"0.290\"],[\"79576.20\",\"0.247\"],[\"79577.20\",\"0.373\"],[\"79593.70\",\"0.000\"],[\"79596.90\",\"7.042\"]],\"a\":[[\"79597.00\",\"7.949\"],[\"79600.30\",\"0.028\"],[\"79600.40\",\"0.034\"],[\"79602.30\",\"0.003\"],[\"79602.40\",\"0.985\"],[\"79610.70\",\"0.106\"],[\"79610.90\",\"0.442\"],[\"79612.80\",\"0.003\"],[\"79616.10\",\"0.009\"],[\"79617.20\",\"0.372\"],[\"79630.70\",\"0.003\"],[\"79631.70\",\"0.046\"],[\"79806.00\",\"4.967\"],[\"79995.00\",\"4.448\"],[\"80393.00\",\"15.315\"]],\"st\":1}}"}
{"receive_ns":1788567793825605000,"stream":"btcusdt@depth@100ms","event_type":"depthUpdate","event_time_ms":1788567793809,"raw_json":"{\"stream\":\"btcusdt@depth@100ms\",\"data\":{\"e\":\"depthUpdate\",\"E\":1788567793809,\"T\":1788567793807,\"s\":\"BTCUSDT\",\"ps\":\"BTCUSDT\",\"U\":11478512206505,\"u\":11478512214352,\"pu\":11478512206414,\"b\":[[\"1000.00\",\"24.604\"],[\"29196.90\",\"0.175\"],[\"29296.90\",\"1.904\"],[\"29396.90\",\"0.021\"],[\"71637.20\",\"0.002\"],[\"76413.00\",\"0.025\"],[\"78800.90\",\"15.422\"],[\"79501.30\",\"0.000\"],[\"79525.20\",\"0.000\"],[\"79541.10\",\"1.098\"],[\"79566.70\",\"0.046\"],[\"79567.80\",\"0.000\"],[\"79568.90\",\"0.455\"],[\"79570.10\",\"0.001\"],[\"79570.90\",\"0.002\"],[\"79572.20\",\"0.126\"],[\"79572.80\",\"0.000\"],[\"79572.90\",\"0.046\"],[\"79576.10\",\"0.382\"],[\"79576.80\",\"0.644\"],[\"79577.20\",\"0.000\"],[\"79577.60\",\"0.002\"]],\"a\":[[\"79600.30\",\"0.002\"],[\"79616.00\",\"0.381\"],[\"79617.20\",\"0.000\"],[\"79626.60\",\"0.004\"],[\"79630.50\",\"0.046\"],[\"79631.70\",\"0.000\"],[\"79661.20\",\"0.014\"],[\"79668.70\",\"2.054\"],[\"79670.00\",\"0.001\"],[\"79692.60\",\"0.002\"],[\"79732.40\",\"0.005\"],[\"79995.00\",\"4.573\"],[\"80393.00\",\"15.315\"],[\"80592.00\",\"12.210\"],[\"80727.30\",\"1.924\"]],\"st\":1}}"}
{"receive_ns":1788567793896231000,"stream":"btcusdt@bookTicker","event_type":"bookTicker","event_time_ms":1788567793909,"raw_json":"{\"stream\":\"btcusdt@bookTicker\",\"data\":{\"e\":\"bookTicker\",\"u\":11478512220988,\"s\":\"BTCUSDT\",\"ps\":\"BTCUSDT\",\"b\":\"79596.90\",\"B\":\"6.857\",\"a\":\"79597.00\",\"A\":\"7.949\",\"T\":1788567793908,\"E\":1788567793909,\"st\":1}}"}
{"receive_ns":1788567793908687000,"stream":"btcusdt@depth@100ms","event_type":"depthUpdate","event_time_ms":1788567793911,"raw_json":"{\"stream\":\"btcusdt@depth@100ms\",\"data\":{\"e\":\"depthUpdate\",\"E\":1788567793911,\"T\":1788567793910,\"s\":\"BTCUSDT\",\"ps\":\"BTCUSDT\",\"U\":11478512214494,\"u\":11478512221159,\"pu\":11478512214352,\"b\":[[\"29196.90\",\"0.336\"],[\"29296.90\",\"1.764\"],[\"29396.90\",\"0.000\"],[\"63678.00\",\"0.012\"],[\"71637.20\",\"0.002\"],[\"76413.00\",\"0.023\"],[\"78482.50\",\"35.243\"],[\"78641.70\",\"35.460\"],[\"78800.90\",\"15.424\"],[\"79506.80\",\"0.019\"],[\"79507.70\",\"1.302\"],[\"79509.80\",\"0.013\"],[\"79510.90\",\"0.003\"],[\"79511.80\",\"1.101\"],[\"79537.70\",\"0.001\"],[\"79557.60\",\"0.003\"],[\"79572.20\",\"0.001\"],[\"79596.90\",\"6.857\"]],\"a\":[[\"79600.40\",\"0.008\"],[\"79640.60\",\"0.000\"],[\"79660.50\",\"1.568\"],[\"79666.10\",\"21.753\"],[\"79666.30\",\"0.000\"],[\"79668.50\",\"2.666\"],[\"79668.80\",\"0.034\"],[\"79676.60\",\"0.027\"],[\"79676.90\",\"0.102\"],[\"79688.30\",\"0.035\"],[\"79688.40\",\"0.000\"],[\"80393.00\",\"15.315\"],[\"80552.20\",\"31.214\"],[\"80788.30\",\"0.742\"],[\"81188.90\",\"0.009\"]],\"st\":1}}"}
{"receive_ns":1788567793909109000,"stream":"btcusdt@bookTicker","event_type":"bookTicker","event_time_ms":1788567793913,"raw_json":"{\"stream\":\"btcusdt@bookTicker\",\"data\":{\"e\":\"bookTicker\",\"u\":11478512221283,\"s\":\"BTCUSDT\",\"ps\":\"BTCUSDT\",\"b\":\"79596.90\",\"B\":\"7.042\",\"a\":\"79597.00\",\"A\":\"7.949\",\"T\":1788567793913,\"E\":1788567793913,\"st\":1}}"}
{"receive_ns":1788567793977054000,"stream":"btcusdt@bookTicker","event_type":"bookTicker","event_time_ms":1788567793984,"raw_json":"{\"stream\":\"btcusdt@bookTicker\",\"data\":{\"e\":\"bookTicker\",\"u\":11478512225412,\"s\":\"BTCUSDT\",\"ps\":\"BTCUSDT\",\"b\":\"79596.90\",\"B\":\"7.042\",\"a\":\"79597.00\",\"A\":\"7.933\",\"T\":1788567793983,\"E\":1788567793984,\"st\":1}}"}
{"receive_ns":1788567793987855000,"stream":"btcusdt@trade","event_type":"trade","event_time_ms":1788567793984,"raw_json":"{\"stream\":\"btcusdt@trade\",\"data\":{\"e\":\"trade\",\"E\":1788567793984,\"T\":1788567793983,\"s\":\"BTCUSDT\",\"t\":8054122893,\"p\":\"79597.00\",\"q\":\"0.016\",\"X\":\"MARKET\",\"m\":false,\"st\":1}}"}
{"receive_ns":1788567794748656000,"stream":"btcusdt@depth@100ms","event_type":"depthUpdate","event_time_ms":1788567794013,"raw_json":"{\"stream\":\"btcusdt@depth@100ms\",\"data\":{\"e\":\"depthUpdate\",\"E\":1788567794013,\"T\":1788567794012,\"s\":\"BTCUSDT\",\"ps\":\"BTCUSDT\",\"U\":11478512221189,\"u\":11478512227644,\"pu\":11478512221159,\"b\":[[\"29196.90\",\"0.511\"],[\"29296.90\",\"1.589\"],[\"63678.00\",\"0.012\"],[\"71637.20\",\"0.002\"],[\"76413.00\",\"0.025\"],[\"78800.90\",\"15.422\"],[\"79198.90\",\"3.981\"],[\"79470.20\",\"0.001\"],[\"79471.80\",\"1.317\"],[\"79506.80\",\"4.377\"],[\"79549.10\",\"0.002\"],[\"79571.90\",\"0.127\"],[\"79572.60\",\"0.628\"],[\"79572.70\",\"0.019\"],[\"79576.80\",\"0.644\"],[\"79589.70\",\"0.124\"],[\"79590.00\",\"0.094\"],[\"79594.80\",\"0.076\"],[\"79596.90\",\"7.042\"]],\"a\":[[\"79597.00\",\"7.933\"],[\"79600.90\",\"0.002\"],[\"79601.00\",\"0.321\"],[\"79601.20\",\"0.026\"],[\"79601.40\",\"0.133\"],[\"79645.00\",\"0.012\"],[\"79661.20\",\"0.000\"],[\"79670.20\",\"3.887\"],[\"79688.30\",\"3.320\"],[\"79728.00\",\"1.007\"],[\"79728.20\",\"0.001\"],[\"79804.90\",\"0.635\"],[\"79806.00\",\"4.869\"],[\"79819.10\",\"6.991\"],[\"80393.00\",\"15.315\"]],\"st\":1}}"}
{"receive_ns":1788567794756214000,"stream":"btcusdt@bookTicker","event_type":"bookTicker","event_time_ms":1788567794071,"raw_json":"{\"stream\":\"btcusdt@bookTicker\",\"data\":{\"e\":\"bookTicker\",\"u\":11478512231972,\"s\":\"BTCUSDT\",\"ps\":\"BTCUSDT\",\"b\":\"79596.90\",\"B\":\"7.012\",\"a\":\"79597.00\",\"A\":\"7.933\",\"T\":1788567794071,\"E\":1788567794071,\"st\":1}}"}
{"receive_ns":1788567794773922000,"stream":"btcusdt@bookTicker","event_type":"bookTicker","event_time_ms":1788567794074,"raw_json":"{\"stream\":\"btcusdt@bookTicker\",\"data\":{\"e\":\"bookTicker\",\"u\":11478512232178,\"s\":\"BTCUSDT\",\"ps\":\"BTCUSDT\",\"b\":\"79596.90\",\"B\":\"7.041\",\"a\":\"79597.00\",\"A\":\"7.933\",\"T\":1788567794074,\"E\":1788567794074,\"st\":1}}"}
{"receive_ns":1788567794796624000,"stream":"btcusdt@depth@100ms","event_type":"depthUpdate","event_time_ms":1788567794115,"raw_json":"{\"stream\":\"btcusdt@depth@100ms\",\"data\":{\"e\":\"depthUpdate\",\"E\":1788567794115,\"T\":1788567794114,\"s\":\"BTCUSDT\",\"ps\":\"BTCUSDT\",\"U\":11478512227738,\"u\":11478512234820,\"pu\":11478512227644,\"b\":[[\"1000.00\",\"24.604\"],[\"29196.90\",\"0.693\"],[\"29296.90\",\"1.407\"],[\"63678.00\",\"0.012\"],[\"71637.20\",\"0.002\"],[\"77593.30\",\"0.001\"],[\"78460.80\",\"3.308\"],[\"78575.20\",\"1.038\"],[\"78577.60\",\"0.004\"],[\"78594.00\",\"0.007\"],[\"78598.80\",\"0.000\"],[\"78608.10\",\"0.009\"],[\"78610.40\",\"0.012\"],[\"78800.90\",\"15.422\"],[\"78999.90\",\"3.793\"],[\"79510.00\",\"6.155\"],[\"79510.90\",\"0.022\"],[\"79511.80\",\"1.847\"],[\"79537.80\",\"7.196\"],[\"79557.70\",\"1.091\"],[\"79572.70\",\"0.647\"],[\"79576.80\",\"0.016\"],[\"79576.90\",\"0.002\"],[\"79581.90\",\"0.323\"],[\"79582.60\",\"0.070\"],[\"79585.30\",\"0.000\"],[\"79596.90\",\"7.041\"]],\"a\":[[\"79601.10\",\"0.036\"],[\"79640.60\",\"0.547\"],[\"79660.50\",\"5.068\"],[\"79666.10\",\"0.075\"],[\"79674.20\",\"21.679\"],[\"79688.40\",\"6.000\"],[\"79693.50\",\"0.004\"],[\"80021.00\",\"0.070\"],[\"80393.00\",\"15.314\"]],\"st\":1}}"}
{"receive_ns":1788567794808754000,"stream":"btcusdt@depth@100ms","event_type":"depthUpdate","event_time_ms":1788567794217,"raw_json":"{\"stream\":\"btcusdt@depth@100ms\",\"data\":{\"e\":\"depthUpdate\",\"E\":1788567794217,\"T\":1788567794214,\"s\":\"BTCUSDT\",\"ps\":\"BTCUSDT\",\"U\":11478512234919,\"u\":11478512242601,\"pu\":11478512234820,\"b\":[[\"29196.90\",\"0.868\"],[\"29296.90\",\"1.232\"],[\"71637.20\",\"0.002\"],[\"76413.00\",\"0.023\"],[\"78800.90\",\"15.422\"],[\"79495.00\",\"0.174\"],[\"79573.20\",\"0.538\"],[\"79585.10\",\"0.004\"],[\"79586.10\",\"0.063\"]],\"a\":[[\"79600.90\",\"0.028\"],[\"79613.10\",\"0.194\"],[\"79671.50\",\"21.678\"],[\"79674.20\",\"0.001\"],[\"79692.30\",\"0.004\"],[\"79695.30\",\"5.101\"],[\"79702.10\",\"0.003\"],[\"79704.10\",\"0.002\"],[\"79898.90\",\"0.006\"],[\"80260.80\",\"0.019\"],[\"80393.00\",\"15.314\"],[\"80552.20\",\"34.933\"],[\"80830.80\",\"6.241\"]],\"st\":1}}"}
{"receive_ns":1788567794825230000,"stream":"btcusdt@bookTicker","event_type":"bookTicker","event_time_ms":1788567794217,"raw_json":"{\"stream\":\"btcusdt@bookTicker\",\"data\":{\"e\":\"bookTicker\",\"u\":11478512242758,\"s\":\"BTCUSDT\",\"ps\":\"BTCUSDT\",\"b\":\"79596.90\",\"B\":\"7.041\",\"a\":\"79597.00\",\"A\":\"7.931\",\"T\":1788567794217,\"E\":1788567794217,\"st\":1}}"}
{"receive_ns":1788567794837152000,"stream":"btcusdt@bookTicker","event_type":"bookTicker","event_time_ms":1788567794249,"raw_json":"{\"stream\":\"btcusdt@bookTicker\",\"data\":{\"e\":\"bookTicker\",\"u\":11478512244461,\"s\":\"BTCUSDT\",\"ps\":\"BTCUSDT\",\"b\":\"79596.90\",\"B\":\"7.038\",\"a\":\"79597.00\",\"A\":\"7.931\",\"T\":1788567794248,\"E\":1788567794249,\"st\":1}}"}
{"receive_ns":1788567794853551000,"stream":"btcusdt@bookTicker","event_type":"bookTicker","event_time_ms":1788567794252,"raw_json":"{\"stream\":\"btcusdt@bookTicker\",\"data\":{\"e\":\"bookTicker\",\"u\":11478512244619,\"s\":\"BTCUSDT\",\"ps\":\"BTCUSDT\",\"b\":\"79596.90\",\"B\":\"7.045\",\"a\":\"79597.00\",\"A\":\"7.931\",\"T\":1788567794251,\"E\":1788567794252,\"st\":1}}"}
{"receive_ns":1788567794871584000,"stream":"btcusdt@bookTicker","event_type":"bookTicker","event_time_ms":1788567794263,"raw_json":"{\"stream\":\"btcusdt@bookTicker\",\"data\":{\"e\":\"bookTicker\",\"u\":11478512245204,\"s\":\"BTCUSDT\",\"ps\":\"BTCUSDT\",\"b\":\"79596.90\",\"B\":\"7.046\",\"a\":\"79597.00\",\"A\":\"7.931\",\"T\":1788567794263,\"E\":1788567794263,\"st\":1}}"}
{"receive_ns":1788567794884839000,"stream":"btcusdt@bookTicker","event_type":"bookTicker","event_time_ms":1788567794282,"raw_json":"{\"stream\":\"btcusdt@bookTicker\",\"data\":{\"e\":\"bookTicker\",\"u\":11478512246140,\"s\":\"BTCUSDT\",\"ps\":\"BTCUSDT\",\"b\":\"79596.90\",\"B\":\"7.046\",\"a\":\"79597.00\",\"A\":\"7.933\",\"T\":1788567794282,\"E\":1788567794282,\"st\":1}}"}
{"receive_ns":1788567794902512000,"stream":"btcusdt@depth@100ms","event_type":"depthUpdate","event_time_ms":1788567794319,"raw_json":"{\"stream\":\"btcusdt@depth@100ms\",\"data\":{\"e\":\"depthUpdate\",\"E\":1788567794319,\"T\":1788567794318,\"s\":\"BTCUSDT\",\"ps\":\"BTCUSDT\",\"U\":11478512242758,\"u\":11478512248305,\"pu\":11478512242601,\"b\":[[\"29196.90\",\"1.050\"],[\"29296.90\",\"1.050\"],[\"63677.50\",\"0.000\"],[\"71637.20\",\"0.002\"],[\"76413.00\",\"0.025\"],[\"78506.40\",\"2.033\"],[\"78647.90\",\"11.353\"],[\"78800.90\",\"15.422\"],[\"78960.10\",\"8.588\"],[\"79198.90\",\"3.592\"],[\"79358.10\",\"0.014\"],[\"79470.20\",\"10.001\"],[\"79471.80\",\"2.623\"],[\"79525.20\",\"0.002\"],[\"79585.10\",\"0.004\"],[\"79586.10\",\"0.063\"],[\"79596.80\",\"0.184\"],[\"79596.90\",\"7.046\"]],\"a\":[[\"79597.00\",\"7.933\"],[\"79620.90\",\"0.024\"],[\"79627.30\",\"0.008\"],[\"79632.10\",\"0.427\"],[\"79668.80\",\"21.712\"],[\"79671.50\",\"0.000\"],[\"79692.60\",\"0.004\"],[\"79728.00\",\"2.839\"],[\"79728.20\",\"10.001\"],[\"79995.00\",\"4.074\"],[\"80393.00\",\"15.314\"],[\"80589.40\",\"1.843\"],[\"80711.50\",\"10.044\"]],\"st\":1}}"}
{"receive_ns":1788567794909424000,"stream":"btcusdt@bookTicker","event_type":"bookTicker","event_time_ms":1788567794325,"raw_json":"{\"stream\":\"btcusdt@bookTicker\",\"data\":{\"e\":\"bookTicker\",\"u\":11478512248614,\"s\":\"BTCUSDT\",\"ps\":\"BTCUSDT\",\"b\":\"79596.90\",\"B\":\"7.046\",\"a\":\"79597.00\",\"A\":\"7.917\",\"T\":1788567794325,\"E\":1788567794325,\"st\":1}}"}
{"receive_ns":1788567794927543000,"stream":"btcusdt@bookTicker","event_type":"bookTicker","event_time_ms":1788567794328,"raw_json":"{\"stream\":\"btcusdt@bookTicker\",\"data\":{\"e\":\"bookTicker\",\"u\":11478512248783,\"s\":\"BTCUSDT\",\"ps\":\"BTCUSDT\",\"b\":\"79596.90\",\"B\":\"7.046\",\"a\":\"79597.00\",\"A\":\"7.927\",\"T\":1788567794328,\"E\":1788567794328,\"st\":1}}"}
{"receive_ns":1788567794944312000,"stream":"btcusdt@bookTicker","event_type":"bookTicker","event_time_ms":1788567794342,"raw_json":"{\"stream\":\"btcusdt@bookTicker\",\"data\":{\"e\":\"bookTicker\",\"u\":11478512249336,\"s\":\"BTCUSDT\",\"ps\":\"BTCUSDT\",\"b\":\"79596.90\",\"B\":\"7.046\",\"a\":\"79597.00\",\"A\":\"7.926\",\"T\":1788567794342,\"E\":1788567794342,\"st\":1}}"}
{"receive_ns":1788567794949804000,"stream":"btcusdt@trade","event_type":"trade","event_time_ms":1788567794342,"raw_json":"{\"stream\":\"btcusdt@trade\",\"data\":{\"e\":\"trade\",\"E\":1788567794342,\"T\":1788567794342,\"s\":\"BTCUSDT\",\"t\":8054122894,\"p\":\"79597.00\",\"q\":\"0.001\",\"X\":\"MARKET\",\"m\":false,\"st\":1}}"}
{"receive_ns":1788567794965766000,"stream":"btcusdt@bookTicker","event_type":"bookTicker","event_time_ms":1788567794344,"raw_json":"{\"stream\":\"btcusdt@bookTicker\",\"data\":{\"e\":\"bookTicker\",\"u\":11478512249445,\"s\":\"BTCUSDT\",\"ps\":\"BTCUSDT\",\"b\":\"79596.90\",\"B\":\"6.879\",\"a\":\"79597.00\",\"A\":\"7.926\",\"T\":1788567794343,\"E\":1788567794344,\"st\":1}}"}
{"receive_ns":1788567794983039000,"stream":"btcusdt@bookTicker","event_type":"bookTicker","event_time_ms":1788567794366,"raw_json":"{\"stream\":\"btcusdt@bookTicker\",\"data\":{\"e\":\"bookTicker\",\"u\":11478512250658,\"s\":\"BTCUSDT\",\"ps\":\"BTCUSDT\",\"b\":\"79596.90\",\"B\":\"7.046\",\"a\":\"79597.00\",\"A\":\"7.926\",\"T\":1788567794366,\"E\":1788567794366,\"st\":1}}"}
{"receive_ns":1788567794994395000,"stream":"btcusdt@bookTicker","event_type":"bookTicker","event_time_ms":1788567794417,"raw_json":"{\"stream\":\"btcusdt@bookTicker\",\"data\":{\"e\":\"bookTicker\",\"u\":11478512253637,\"s\":\"BTCUSDT\",\"ps\":\"BTCUSDT\",\"b\":\"79596.90\",\"B\":\"6.861\",\"a\":\"79597.00\",\"A\":\"7.926\",\"T\":1788567794417,\"E\":1788567794417,\"st\":1}}"}
{"receive_ns":1788567795007474000,"stream":"btcusdt@depth@100ms","event_type":"depthUpdate","event_time_ms":1788567794421,"raw_json":"{\"stream\":\"btcusdt@depth@100ms\",\"data\":{\"e\":\"depthUpdate\",\"E\":1788567794421,\"T\":1788567794419,\"s\":\"BTCUSDT\",\"ps\":\"BTCUSDT\",\"U\":11478512248407,\"u\":11478512253888,\"pu\":11478512248305,\"b\":[[\"1000.00\",\"24.604\"],[\"29196.90\",\"1.225\"],[\"29296.90\",\"0.875\"],[\"63678.00\",\"0.012\"],[\"71637.20\",\"0.002\"],[\"71673.00\",\"0.000\"],[\"76413.00\",\"0.023\"],[\"78800.90\",\"15.422\"],[\"79198.90\",\"3.970\"],[\"79495.00\",\"0.188\"],[\"79585.10\",\"0.000\"],[\"79586.10\",\"0.067\"],[\"79594.00\",\"0.328\"],[\"79594.80\",\"0.000\"],[\"79596.90\",\"6.861\"]],\"a\":[[\"79597.00\",\"7.926\"],[\"79600.80\",\"0.034\"],[\"79602.20\",\"0.001\"],[\"79870.00\",\"0.543\"],[\"79995.00\",\"4.448\"],[\"80393.00\",\"15.314\"],[\"80708.80\",\"1.115\"],[\"80717.50\",\"10.046\"]],\"st\":1}}"}
{"receive_ns":1788567795021020000,"stream":"btcusdt@bookTicker","event_type":"bookTicker","event_time_ms":1788567794421,"raw_json":"{\"stream\":\"btcusdt@bookTicker\",\"data\":{\"e\":\"bookTicker\",\"u\":11478512253952,\"s\":\"BTCUSDT\",\"ps\":\"BTCUSDT\",\"b\":\"79596.90\",\"B\":\"7.046\",\"a\":\"79597.00\",\"A\":\"7.926\",\"T\":1788567794421,\"E\":1788567794421,\"st\":1}}"}
{"receive_ns":1788567795022244000,"stream":"btcusdt@depth@100ms","event_type":"depthUpdate","event_time_ms":1788567794523,"raw_json":"{\"stream\":\"btcusdt@depth@100ms\",\"data\":{\"e\":\"depthUpdate\",\"E\":1788567794523,\"T\":1788567794521,\"s\":\"BTCUSDT\",\"ps\":\"BTCUSDT\",\"U\":11478512253952,\"u\":11478512258888,\"pu\":11478512253888,\"b\":[[\"29196.90\",\"1.407\"],[\"29296.90\",\"0.693\"],[\"71637.20\",\"0.002\"],[\"75617.10\",\"0.010\"],[\"76413.00\",\"0.025\"],[\"78641.70\",\"36.730\"],[\"78679.20\",\"0.000\"],[\"78800.90\",\"15.422\"],[\"79198.90\",\"3.971\"],[\"79571.90\",\"0.002\"],[\"79585.10\",\"0.000\"],[\"79586.10\",\"0.067\"],[\"79589.70\",\"0.124\"],[\"79590.00\",\"0.094\"],[\"79596.90\",\"7.046\"]],\"a\":[[\"79610.90\",\"0.442\"],[\"79995.00\",\"4.573\"],[\"80393.00\",\"15.314\"],[\"80592.00\",\"12.396\"],[\"81188.90\",\"0.012\"]],\"st\":1}}"}
{"receive_ns":1788567795035910000,"stream":"btcusdt@depth@100ms","event_type":"depthUpdate","event_time_ms":1788567794625,"raw_json":"{\"stream\":\"btcusdt@depth@100ms\",\"data\":{\"e\":\"depthUpdate\",\"E\":1788567794625,\"T\":1788567794621,\"s\":\"BTCUSDT\",\"ps\":\"BTCUSDT\",\"U\":11478512258985,\"u\":11478512263200,\"pu\":11478512258888,\"b\":[[\"29196.90\",\"1.582\"],[\"29296.90\",\"0.518\"],[\"63678.00\",\"0.012\"],[\"71637.20\",\"0.002\"],[\"75617.10\",\"0.008\"],[\"75617.20\",\"0.008\"],[\"78488.70\",\"9.010\"],[\"78800.90\",\"15.422\"],[\"79198.90\",\"3.971\"],[\"79565.80\",\"0.000\"],[\"79566.70\",\"0.000\"],[\"79567.00\",\"0.300\"],[\"79572.80\",\"0.000\"],[\"79573.30\",\"0.439\"],[\"79575.30\",\"0.137\"],[\"79576.10\",\"0.009\"],[\"79576.50\",\"0.373\"],[\"79585.10\",\"0.000\"],[\"79586.10\",\"0.067\"]],\"a\":[[\"79615.20\",\"0.001\"],[\"79616.00\",\"0.009\"],[\"79616.30\",\"1.013\"],[\"79618.30\",\"0.091\"],[\"79619.70\",\"0.454\"],[\"79620.30\",\"0.627\"],[\"79668.50\",\"5.748\"],[\"79804.90\",\"0.992\"],[\"79806.00\",\"4.820\"],[\"79819.10\",\"6.981\"],[\"80592.10\",\"4.559\"]],\"st\":1}}"}
{"receive_ns":1788567795048146000,"stream":"btcusdt@bookTicker","event_type":"bookTicker","event_time_ms":1788567794639,"raw_json":"{\"stream\":\"btcusdt@bookTicker\",\"data\":{\"e\":\"bookTicker\",\"u\":11478512263792,\"s\":\"BTCUSDT\",\"ps\":\"BTCUSDT\",\"b\":\"79596.90\",\"B\":\"7.017\",\"a\":\"79597.00\",\"A\":\"7.926\",\"T\":1788567794639,\"E\":1788567794639,\"st\":1}}"}
{"receive_ns":1788567795057171000,"stream":"btcusdt@bookTicker","event_type":"bookTicker","event_time_ms":1788567794643,"raw_json":"{\"stream\":\"btcusdt@bookTicker\",\"data\":{\"e\":\"bookTicker\",\"u\":11478512263999,\"s\":\"BTCUSDT\",\"ps\":\"BTCUSDT\",\"b\":\"79596.90\",\"B\":\"7.045\",\"a\":\"79597.00\",\"A\":\"7.926\",\"T\":1788567794642,\"E\":1788567794643,\"st\":1}}"}
{"receive_ns":1788567795080141000,"stream":"btcusdt@bookTicker","event_type":"bookTicker","event_time_ms":1788567794706,"raw_json":"{\"stream\":\"btcusdt@bookTicker\",\"data\":{\"e\":\"bookTicker\",\"u\":11478512267732,\"s\":\"BTCUSDT\",\"ps\":\"BTCUSDT\",\"b\":\"79596.90\",\"B\":\"6.939\",\"a\":\"79597.00\",\"A\":\"7.926\",\"T\":1788567794706,\"E\":1788567794706,\"st\":1}}"}
{"receive_ns":1788567795092435000,"stream":"btcusdt@trade","event_type":"trade","event_time_ms":1788567794706,"raw_json":"{\"stream\":\"btcusdt@trade\",\"data\":{\"e\":\"trade\",\"E\":1788567794706,\"T\":1788567794706,\"s\":\"BTCUSDT\",\"t\":8054122895,\"p\":\"79596.90\",\"q\":\"0.104\",\"X\":\"MARKET\",\"m\":true,\"st\":1}}"}
{"receive_ns":1788567795108680000,"stream":"btcusdt@trade","event_type":"trade","event_time_ms":1788567794706,"raw_json":"{\"stream\":\"btcusdt@trade\",\"data\":{\"e\":\"trade\",\"E\":1788567794706,\"T\":1788567794706,\"s\":\"BTCUSDT\",\"t\":8054122896,\"p\":\"79596.90\",\"q\":\"0.002\",\"X\":\"MARKET\",\"m\":true,\"st\":1}}"}
{"receive_ns":1788567795125041000,"stream":"btcusdt@bookTicker","event_type":"bookTicker","event_time_ms":1788567794707,"raw_json":"{\"stream\":\"btcusdt@bookTicker\",\"data\":{\"e\":\"bookTicker\",\"u\":11478512267818,\"s\":\"BTCUSDT\",\"ps\":\"BTCUSDT\",\"b\":\"79596.90\",\"B\":\"7.028\",\"a\":\"79597.00\",\"A\":\"7.926\",\"T\":1788567794707,\"E\":1788567794707,\"st\":1}}"}
{"receive_ns":1788567795143749000,"stream":"btcusdt@bookTicker","event_type":"bookTicker","event_time_ms":1788567794709,"raw_json":"{\"stream\":\"btcusdt@bookTicker\",\"data\":{\"e\":\"bookTicker\",\"u\":11478512268107,\"s\":\"BTCUSDT\",\"ps\":\"BTCUSDT\",\"b\":\"79596.90\",\"B\":\"6.939\",\"a\":\"79597.00\",\"A\":\"7.926\",\"T\":1788567794709,\"E\":1788567794709,\"st\":1}}"}
{"receive_ns":1788567795160354000,"stream":"btcusdt@bookTicker","event_type":"bookTicker","event_time_ms":1788567794710,"raw_json":"{\"stream\":\"btcusdt@bookTicker\",\"data\":{\"e\":\"bookTicker\",\"u\":11478512268221,\"s\":\"BTCUSDT\",\"ps\":\"BTCUSDT\",\"b\":\"79596.90\",\"B\":\"7.021\",\"a\":\"79597.00\",\"A\":\"7.926\",\"T\":1788567794710,\"E\":1788567794710,\"st\":1}}"}
{"receive_ns":1788567795183949000,"stream":"btcusdt@bookTicker","event_type":"bookTicker","event_time_ms":1788567794712,"raw_json":"{\"stream\":\"btcusdt@bookTicker\",\"data\":{\"e\":\"bookTicker\",\"u\":11478512268339,\"s\":\"BTCUSDT\",\"ps\":\"BTCUSDT\",\"b\":\"79596.90\",\"B\":\"6.939\",\"a\":\"79597.00\",\"A\":\"7.926\",\"T\":1788567794712,\"E\":1788567794712,\"st\":1}}"}
{"receive_ns":1788567795189799000,"stream":"btcusdt@bookTicker","event_type":"bookTicker","event_time_ms":1788567794714,"raw_json":"{\"stream\":\"btcusdt@bookTicker\",\"data\":{\"e\":\"bookTicker\",\"u\":11478512268403,\"s\":\"BTCUSDT\",\"ps\":\"BTCUSDT\",\"b\":\"79596.90\",\"B\":\"7.020\",\"a\":\"79597.00\",\"A\":\"7.926\",\"T\":1788567794714,\"E\":1788567794714,\"st\":1}}"}
{"receive_ns":1788567795206932000,"stream":"btcusdt@bookTicker","event_type":"bookTicker","event_time_ms":1788567794716,"raw_json":"{\"stream\":\"btcusdt@bookTicker\",\"data\":{\"e\":\"bookTicker\",\"u\":11478512268498,\"s\":\"BTCUSDT\",\"ps\":\"BTCUSDT\",\"b\":\"79596.90\",\"B\":\"6.939\",\"a\":\"79597.00\",\"A\":\"7.926\",\"T\":1788567794715,\"E\":1788567794716,\"st\":1}}"}
{"receive_ns":1788567795218586000,"stream":"btcusdt@bookTicker","event_type":"bookTicker","event_time_ms":1788567794717,"raw_json":"{\"stream\":\"btcusdt@bookTicker\",\"data\":{\"e\":\"bookTicker\",\"u\":11478512268577,\"s\":\"BTCUSDT\",\"ps\":\"BTCUSDT\",\"b\":\"79596.90\",\"B\":\"7.023\",\"a\":\"79597.00\",\"A\":\"7.926\",\"T\":1788567794717,\"E\":1788567794717,\"st\":1}}"}
{"receive_ns":1788567795229705000,"stream":"btcusdt@bookTicker","event_type":"bookTicker","event_time_ms":1788567794719,"raw_json":"{\"stream\":\"btcusdt@bookTicker\",\"data\":{\"e\":\"bookTicker\",\"u\":11478512268721,\"s\":\"BTCUSDT\",\"ps\":\"BTCUSDT\",\"b\":\"79596.90\",\"B\":\"6.939\",\"a\":\"79597.00\",\"A\":\"7.926\",\"T\":1788567794719,\"E\":1788567794719,\"st\":1}}"}
{"receive_ns":1788567795246696000,"stream":"btcusdt@bookTicker","event_type":"bookTicker","event_time_ms":1788567794720,"raw_json":"{\"stream\":\"btcusdt@bookTicker\",\"data\":{\"e\":\"bookTicker\",\"u\":11478512268821,\"s\":\"BTCUSDT\",\"ps\":\"BTCUSDT\",\"b\":\"79596.90\",\"B\":\"7.030\",\"a\":\"79597.00\",\"A\":\"7.926\",\"T\":1788567794720,\"E\":1788567794720,\"st\":1}}"}
{"receive_ns":1788567795258226000,"stream":"btcusdt@bookTicker","event_type":"bookTicker","event_time_ms":1788567794722,"raw_json":"{\"stream\":\"btcusdt@bookTicker\",\"data\":{\"e\":\"bookTicker\",\"u\":11478512268929,\"s\":\"BTCUSDT\",\"ps\":\"BTCUSDT\",\"b\":\"79596.90\",\"B\":\"6.939\",\"a\":\"79597.00\",\"A\":\"7.926\",\"T\":1788567794722,\"E\":1788567794722,\"st\":1}}"}
{"receive_ns":1788567795269517000,"stream":"btcusdt@bookTicker","event_type":"bookTicker","event_time_ms":1788567794723,"raw_json":"{\"stream\":\"btcusdt@bookTicker\",\"data\":{\"e\":\"bookTicker\",\"u\":11478512268982,\"s\":\"BTCUSDT\",\"ps\":\"BTCUSDT\",\"b\":\"79596.90\",\"B\":\"7.022\",\"a\":\"79597.00\",\"A\":\"7.926\",\"T\":1788567794723,\"E\":1788567794723,\"st\":1}}"}
{"receive_ns":1788567795281912000,"stream":"btcusdt@bookTicker","event_type":"bookTicker","event_time_ms":1788567794725,"raw_json":"{\"stream\":\"btcusdt@bookTicker\",\"data\":{\"e\":\"bookTicker\",\"u\":11478512269096,\"s\":\"BTCUSDT\",\"ps\":\"BTCUSDT\",\"b\":\"79596.90\",\"B\":\"6.939\",\"a\":\"79597.00\",\"A\":\"7.926\",\"T\":1788567794725,\"E\":1788567794725,\"st\":1}}"}
{"receive_ns":1788567795291939000,"stream":"btcusdt@depth@100ms","event_type":"depthUpdate","event_time_ms":1788567794727,"raw_json":"{\"stream\":\"btcusdt@depth@100ms\",\"data\":{\"e\":\"depthUpdate\",\"E\":1788567794727,\"T\":1788567794726,\"s\":\"BTCUSDT\",\"ps\":\"BTCUSDT\",\"U\":11478512263316,\"u\":11478512269151,\"pu\":11478512263200,\"b\":[[\"1000.00\",\"24.604\"],[\"29096.90\",\"0.007\"],[\"29196.90\",\"1.750\"],[\"29296.90\",\"0.343\"],[\"71637.20\",\"0.002\"],[\"76413.00\",\"0.023\"],[\"78005.00\",\"0.225\"],[\"78641.70\",\"36.349\"],[\"78800.90\",\"15.422\"],[\"78803.00\",\"4.550\"],[\"78814.20\",\"0.000\"],[\"78815.10\",\"0.000\"],[\"79198.90\",\"3.468\"],[\"79549.10\",\"0.078\"],[\"79555.60\",\"0.203\"],[\"79557.60\",\"0.002\"],[\"79585.10\",\"0.004\"],[\"79586.10\",\"0.063\"],[\"79594.00\",\"0.252\"],[\"79596.90\",\"6.939\"]],\"a\":[[\"79598.00\",\"0.333\"],[\"79599.50\",\"0.003\"],[\"79600.10\",\"0.002\"],[\"79600.80\",\"0.036\"],[\"79602.10\",\"0.000\"],[\"79660.70\",\"0.084\"],[\"79668.50\",\"2.666\"],[\"79668.80\",\"0.034\"],[\"79676.90\",\"21.780\"],[\"79804.90\",\"0.635\"],[\"79806.00\",\"4.869\"],[\"80233.80\",\"7.090\"],[\"80366.70\",\"0.000\"],[\"80393.00\",\"15.314\"],[\"80592.00\",\"12.545\"],[\"80751.20\",\"14.931\"]],\"st\":1}}"}
{"receive_ns":1788567795310331000,"stream":"btcusdt@bookTicker","event_type":"bookTicker","event_time_ms":1788567794727,"raw_json":"{\"stream\":\"btcusdt@bookTicker\",\"data\":{\"e\":\"bookTicker\",\"u\":11478512269178,\"s\":\"BTCUSDT\",\"ps\":\"BTCUSDT\",\"b\":\"79596.90\",\"B\":\"7.032\",\"a\":\"79597.00\",\"A\":\"7.926\",\"T\":1788567794726,\"E\":1788567794727,\"st\":1}}"}
{"receive_ns":1788567795326846000,"stream":"btcusdt@bookTicker","event_type":"bookTicker","event_time_ms":1788567794728,"raw_json":"{\"stream\":\"btcusdt@bookTicker\",\"data\":{\"e\":\"bookTicker\",\"u\":11478512269294,\"s\":\"BTCUSDT\",\"ps\":\"BTCUSDT\",\"b\":\"79596.90\",\"B\":\"6.939\",\"a\":\"79597.00\",\"A\":\"7.926\",\"T\":1788567794728,\"E\":1788567794728,\"st\":1}}"}
{"receive_ns":1788567795338391000,"stream":"btcusdt@bookTicker","event_type":"bookTicker","event_time_ms":1788567794730,"raw_json":"{\"stream\":\"btcusdt@bookTicker\",\"data\":{\"e\":\"bookTicker\",\"u\":11478512269385,\"s\":\"BTCUSDT\",\"ps\":\"BTCUSDT\",\"b\":\"79596.90\",\"B\":\"7.023\",\"a\":\"79597.00\",\"A\":\"7.926\",\"T\":1788567794730,\"E\":1788567794730,\"st\":1}}"}
{"receive_ns":1788567795355499000,"stream":"btcusdt@bookTicker","event_type":"bookTicker","event_time_ms":1788567794732,"raw_json":"{\"stream\":\"btcusdt@bookTicker\",\"data\":{\"e\":\"bookTicker\",\"u\":11478512269542,\"s\":\"BTCUSDT\",\"ps\":\"BTCUSDT\",\"b\":\"79596.90\",\"B\":\"6.939\",\"a\":\"79597.00\",\"A\":\"7.926\",\"T\":1788567794732,\"E\":1788567794732,\"st\":1}}"}
{"receive_ns":1788567795366435000,"stream":"btcusdt@bookTicker","event_type":"bookTicker","event_time_ms":1788567794733,"raw_json":"{\"stream\":\"btcusdt@bookTicker\",\"data\":{\"e\":\"bookTicker\",\"u\":11478512269593,\"s\":\"BTCUSDT\",\"ps\":\"BTCUSDT\",\"b\":\"79596.90\",\"B\":\"6.938\",\"a\":\"79597.00\",\"A\":\"7.926\",\"T\":1788567794733,\"E\":1788567794733,\"st\":1}}"}
{"receive_ns":1788567795373266000,"stream":"btcusdt@bookTicker","event_type":"bookTicker","event_time_ms":1788567794733,"raw_json":"{\"stream\":\"btcusdt@bookTicker\",\"data\":{\"e\":\"bookTicker\",\"u\":11478512269609,\"s\":\"BTCUSDT\",\"ps\":\"BTCUSDT\",\"b\":\"79596.90\",\"B\":\"7.026\",\"a\":\"79597.00\",\"A\":\"7.926\",\"T\":1788567794733,\"E\":1788567794733,\"st\":1}}"}
{"receive_ns":1788567795379449000,"stream":"btcusdt@bookTicker","event_type":"bookTicker","event_time_ms":1788567794734,"raw_json":"{\"stream\":\"btcusdt@bookTicker\",\"data\":{\"e\":\"bookTicker\",\"u\":11478512269652,\"s\":\"BTCUSDT\",\"ps\":\"BTCUSDT\",\"b\":\"79596.90\",\"B\":\"7.025\",\"a\":\"79597.00\",\"A\":\"7.926\",\"T\":1788567794734,\"E\":1788567794734,\"st\":1}}"}
{"receive_ns":1788567795391175000,"stream":"btcusdt@bookTicker","event_type":"bookTicker","event_time_ms":1788567794734,"raw_json":"{\"stream\":\"btcusdt@bookTicker\",\"data\":{\"e\":\"bookTicker\",\"u\":11478512269657,\"s\":\"BTCUSDT\",\"ps\":\"BTCUSDT\",\"b\":\"79596.90\",\"B\":\"7.026\",\"a\":\"79597.00\",\"A\":\"7.926\",\"T\":1788567794734,\"E\":1788567794734,\"st\":1}}"}
{"receive_ns":1788567795408313000,"stream":"btcusdt@bookTicker","event_type":"bookTicker","event_time_ms":1788567794735,"raw_json":"{\"stream\":\"btcusdt@bookTicker\",\"data\":{\"e\":\"bookTicker\",\"u\":11478512269935,\"s\":\"BTCUSDT\",\"ps\":\"BTCUSDT\",\"b\":\"79596.90\",\"B\":\"6.938\",\"a\":\"79597.00\",\"A\":\"7.926\",\"T\":1788567794735,\"E\":1788567794735,\"st\":1}}"}
{"receive_ns":1788567795419396000,"stream":"btcusdt@bookTicker","event_type":"bookTicker","event_time_ms":1788567794736,"raw_json":"{\"stream\":\"btcusdt@bookTicker\",\"data\":{\"e\":\"bookTicker\",\"u\":11478512270132,\"s\":\"BTCUSDT\",\"ps\":\"BTCUSDT\",\"b\":\"79596.90\",\"B\":\"7.025\",\"a\":\"79597.00\",\"A\":\"7.926\",\"T\":1788567794736,\"E\":1788567794736,\"st\":1}}"}
{"receive_ns":1788567795419961000,"stream":"btcusdt@bookTicker","event_type":"bookTicker","event_time_ms":1788567794738,"raw_json":"{\"stream\":\"btcusdt@bookTicker\",\"data\":{\"e\":\"bookTicker\",\"u\":11478512270298,\"s\":\"BTCUSDT\",\"ps\":\"BTCUSDT\",\"b\":\"79596.90\",\"B\":\"7.026\",\"a\":\"79597.00\",\"A\":\"7.926\",\"T\":1788567794738,\"E\":1788567794738,\"st\":1}}"}
{"receive_ns":1788567795437061000,"stream":"btcusdt@bookTicker","event_type":"bookTicker","event_time_ms":1788567794738,"raw_json":"{\"stream\":\"btcusdt@bookTicker\",\"data\":{\"e\":\"bookTicker\",\"u\":11478512270384,\"s\":\"BTCUSDT\",\"ps\":\"BTCUSDT\",\"b\":\"79596.90\",\"B\":\"6.939\",\"a\":\"79597.00\",\"A\":\"7.926\",\"T\":1788567794738,\"E\":1788567794738,\"st\":1}}"}
{"receive_ns":1788567795445901000,"stream":"btcusdt@bookTicker","event_type":"bookTicker","event_time_ms":1788567794740,"raw_json":"{\"stream\":\"btcusdt@bookTicker\",\"data\":{\"e\":\"bookTicker\",\"u\":11478512270569,\"s\":\"BTCUSDT\",\"ps\":\"BTCUSDT\",\"b\":\"79596.90\",\"B\":\"7.020\",\"a\":\"79597.00\",\"A\":\"7.926\",\"T\":1788567794740,\"E\":1788567794740,\"st\":1}}"}
{"receive_ns":1788567795457190000,"stream":"btcusdt@bookTicker","event_type":"bookTicker","event_time_ms":1788567794742,"raw_json":"{\"stream\":\"btcusdt@bookTicker\",\"data\":{\"e\":\"bookTicker\",\"u\":11478512270736,\"s\":\"BTCUSDT\",\"ps\":\"BTCUSDT\",\"b\":\"79596.90\",\"B\":\"6.939\",\"a\":\"79597.00\",\"A\":\"7.926\",\"T\":1788567794742,\"E\":1788567794742,\"st\":1}}"}
{"receive_ns":1788567795468730000,"stream":"btcusdt@bookTicker","event_type":"bookTicker","event_time_ms":1788567794743,"raw_json":"{\"stream\":\"btcusdt@bookTicker\",\"data\":{\"e\":\"bookTicker\",\"u\":11478512270815,\"s\":\"BTCUSDT\",\"ps\":\"BTCUSDT\",\"b\":\"79596.90\",\"B\":\"7.021\",\"a\":\"79597.00\",\"A\":\"7.926\",\"T\":1788567794743,\"E\":1788567794743,\"st\":1}}"}
{"receive_ns":1788567795486593000,"stream":"btcusdt@bookTicker","event_type":"bookTicker","event_time_ms":1788567794745,"raw_json":"{\"stream\":\"btcusdt@bookTicker\",\"data\":{\"e\":\"bookTicker\",\"u\":11478512270935,\"s\":\"BTCUSDT\",\"ps\":\"BTCUSDT\",\"b\":\"79596.90\",\"B\":\"6.939\",\"a\":\"79597.00\",\"A\":\"7.926\",\"T\":1788567794745,\"E\":1788567794745,\"st\":1}}"}
{"receive_ns":1788567795498608000,"stream":"btcusdt@bookTicker","event_type":"bookTicker","event_time_ms":1788567794746,"raw_json":"{\"stream\":\"btcusdt@bookTicker\",\"data\":{\"e\":\"bookTicker\",\"u\":11478512271020,\"s\":\"BTCUSDT\",\"ps\":\"BTCUSDT\",\"b\":\"79596.90\",\"B\":\"7.037\",\"a\":\"79597.00\",\"A\":\"7.926\",\"T\":1788567794746,\"E\":1788567794746,\"st\":1}}"}
{"receive_ns":1788567795509293000,"stream":"btcusdt@bookTicker","event_type":"bookTicker","event_time_ms":1788567794748,"raw_json":"{\"stream\":\"btcusdt@bookTicker\",\"data\":{\"e\":\"bookTicker\",\"u\":11478512271143,\"s\":\"BTCUSDT\",\"ps\":\"BTCUSDT\",\"b\":\"79596.90\",\"B\":\"6.939\",\"a\":\"79597.00\",\"A\":\"7.926\",\"T\":1788567794748,\"E\":1788567794748,\"st\":1}}"}
{"receive_ns":1788567795529544000,"stream":"btcusdt@bookTicker","event_type":"bookTicker","event_time_ms":1788567794749,"raw_json":"{\"stream\":\"btcusdt@bookTicker\",\"data\":{\"e\":\"bookTicker\",\"u\":11478512271202,\"s\":\"BTCUSDT\",\"ps\":\"BTCUSDT\",\"b\":\"79596.90\",\"B\":\"7.018\",\"a\":\"79597.00\",\"A\":\"7.926\",\"T\":1788567794749,\"E\":1788567794749,\"st\":1}}"}
{"receive_ns":1788567795542290000,"stream":"btcusdt@bookTicker","event_type":"bookTicker","event_time_ms":1788567794751,"raw_json":"{\"stream\":\"btcusdt@bookTicker\",\"data\":{\"e\":\"bookTicker\",\"u\":11478512271285,\"s\":\"BTCUSDT\",\"ps\":\"BTCUSDT\",\"b\":\"79596.90\",\"B\":\"6.939\",\"a\":\"79597.00\",\"A\":\"7.926\",\"T\":1788567794751,\"E\":1788567794751,\"st\":1}}"}
{"receive_ns":1788567795565229000,"stream":"btcusdt@bookTicker","event_type":"bookTicker","event_time_ms":1788567794752,"raw_json":"{\"stream\":\"btcusdt@bookTicker\",\"data\":{\"e\":\"bookTicker\",\"u\":11478512271391,\"s\":\"BTCUSDT\",\"ps\":\"BTCUSDT\",\"b\":\"79596.90\",\"B\":\"7.037\",\"a\":\"79597.00\",\"A\":\"7.926\",\"T\":1788567794752,\"E\":1788567794752,\"st\":1}}"}
{"receive_ns":1788567795577336000,"stream":"btcusdt@bookTicker","event_type":"bookTicker","event_time_ms":1788567794754,"raw_json":"{\"stream\":\"btcusdt@bookTicker\",\"data\":{\"e\":\"bookTicker\",\"u\":11478512271492,\"s\":\"BTCUSDT\",\"ps\":\"BTCUSDT\",\"b\":\"79596.90\",\"B\":\"6.939\",\"a\":\"79597.00\",\"A\":\"7.926\",\"T\":1788567794754,\"E\":1788567794754,\"st\":1}}"}
{"receive_ns":1788567795592588000,"stream":"btcusdt@bookTicker","event_type":"bookTicker","event_time_ms":1788567794755,"raw_json":"{\"stream\":\"btcusdt@bookTicker\",\"data\":{\"e\":\"bookTicker\",\"u\":11478512271565,\"s\":\"BTCUSDT\",\"ps\":\"BTCUSDT\",\"b\":\"79596.90\",\"B\":\"7.020\",\"a\":\"79597.00\",\"A\":\"7.926\",\"T\":1788567794755,\"E\":1788567794755,\"st\":1}}"}
{"receive_ns":1788567795604970000,"stream":"btcusdt@bookTicker","event_type":"bookTicker","event_time_ms":1788567794758,"raw_json":"{\"stream\":\"btcusdt@bookTicker\",\"data\":{\"e\":\"bookTicker\",\"u\":11478512271710,\"s\":\"BTCUSDT\",\"ps\":\"BTCUSDT\",\"b\":\"79596.90\",\"B\":\"6.939\",\"a\":\"79597.00\",\"A\":\"7.926\",\"T\":1788567794757,\"E\":1788567794758,\"st\":1}}"}
{"receive_ns":1788567795616297000,"stream":"btcusdt@bookTicker","event_type":"bookTicker","event_time_ms":1788567794759,"raw_json":"{\"stream\":\"btcusdt@bookTicker\",\"data\":{\"e\":\"bookTicker\",\"u\":11478512271808,\"s\":\"BTCUSDT\",\"ps\":\"BTCUSDT\",\"b\":\"79596.90\",\"B\":\"7.027\",\"a\":\"79597.00\",\"A\":\"7.926\",\"T\":1788567794759,\"E\":1788567794759,\"st\":1}}"}
{"receive_ns":1788567795622766000,"stream":"btcusdt@bookTicker","event_type":"bookTicker","event_time_ms":1788567794761,"raw_json":"{\"stream\":\"btcusdt@bookTicker\",\"data\":{\"e\":\"bookTicker\",\"u\":11478512271912,\"s\":\"BTCUSDT\",\"ps\":\"BTCUSDT\",\"b\":\"79596.90\",\"B\":\"6.939\",\"a\":\"79597.00\",\"A\":\"7.926\",\"T\":1788567794761,\"E\":1788567794761,\"st\":1}}"}
{"receive_ns":1788567795642260000,"stream":"btcusdt@bookTicker","event_type":"bookTicker","event_time_ms":1788567794762,"raw_json":"{\"stream\":\"btcusdt@bookTicker\",\"data\":{\"e\":\"bookTicker\",\"u\":11478512271966,\"s\":\"BTCUSDT\",\"ps\":\"BTCUSDT\",\"b\":\"79596.90\",\"B\":\"7.028\",\"a\":\"79597.00\",\"A\":\"7.926\",\"T\":1788567794762,\"E\":1788567794762,\"st\":1}}"}
{"receive_ns":1788567795656988000,"stream":"btcusdt@bookTicker","event_type":"bookTicker","event_time_ms":1788567794764,"raw_json":"{\"stream\":\"btcusdt@bookTicker\",\"data\":{\"e\":\"bookTicker\",\"u\":11478512272131,\"s\":\"BTCUSDT\",\"ps\":\"BTCUSDT\",\"b\":\"79596.90\",\"B\":\"6.939\",\"a\":\"79597.00\",\"A\":\"7.926\",\"T\":1788567794764,\"E\":1788567794764,\"st\":1}}"}
{"receive_ns":1788567795657630000,"stream":"btcusdt@bookTicker","event_type":"bookTicker","event_time_ms":1788567794766,"raw_json":"{\"stream\":\"btcusdt@bookTicker\",\"data\":{\"e\":\"bookTicker\",\"u\":11478512272254,\"s\":\"BTCUSDT\",\"ps\":\"BTCUSDT\",\"b\":\"79596.90\",\"B\":\"7.029\",\"a\":\"79597.00\",\"A\":\"7.926\",\"T\":1788567794766,\"E\":1788567794766,\"st\":1}}"}
{"receive_ns":1788567795658082000,"stream":"btcusdt@bookTicker","event_type":"bookTicker","event_time_ms":1788567794768,"raw_json":"{\"stream\":\"btcusdt@bookTicker\",\"data\":{\"e\":\"bookTicker\",\"u\":11478512272378,\"s\":\"BTCUSDT\",\"ps\":\"BTCUSDT\",\"b\":\"79596.90\",\"B\":\"6.939\",\"a\":\"79597.00\",\"A\":\"7.926\",\"T\":1788567794767,\"E\":1788567794768,\"st\":1}}"}
{"receive_ns":1788567795658535000,"stream":"btcusdt@bookTicker","event_type":"bookTicker","event_time_ms":1788567794769,"raw_json":"{\"stream\":\"btcusdt@bookTicker\",\"data\":{\"e\":\"bookTicker\",\"u\":11478512272511,\"s\":\"BTCUSDT\",\"ps\":\"BTCUSDT\",\"b\":\"79596.90\",\"B\":\"7.034\",\"a\":\"79597.00\",\"A\":\"7.926\",\"T\":1788567794769,\"E\":1788567794769,\"st\":1}}"}
{"receive_ns":1788567795658961000,"stream":"btcusdt@bookTicker","event_type":"bookTicker","event_time_ms":1788567794772,"raw_json":"{\"stream\":\"btcusdt@bookTicker\",\"data\":{\"e\":\"bookTicker\",\"u\":11478512272650,\"s\":\"BTCUSDT\",\"ps\":\"BTCUSDT\",\"b\":\"79596.90\",\"B\":\"6.939\",\"a\":\"79597.00\",\"A\":\"7.926\",\"T\":1788567794771,\"E\":1788567794772,\"st\":1}}"}
{"receive_ns":1788567795659381000,"stream":"btcusdt@bookTicker","event_type":"bookTicker","event_time_ms":1788567794773,"raw_json":"{\"stream\":\"btcusdt@bookTicker\",\"data\":{\"e\":\"bookTicker\",\"u\":11478512272716,\"s\":\"BTCUSDT\",\"ps\":\"BTCUSDT\",\"b\":\"79596.90\",\"B\":\"7.019\",\"a\":\"79597.00\",\"A\":\"7.926\",\"T\":1788567794773,\"E\":1788567794773,\"st\":1}}"}
{"receive_ns":1788567795665462000,"stream":"btcusdt@bookTicker","event_type":"bookTicker","event_time_ms":1788567794775,"raw_json":"{\"stream\":\"btcusdt@bookTicker\",\"data\":{\"e\":\"bookTicker\",\"u\":11478512272835,\"s\":\"BTCUSDT\",\"ps\":\"BTCUSDT\",\"b\":\"79596.90\",\"B\":\"6.939\",\"a\":\"79597.00\",\"A\":\"7.926\",\"T\":1788567794775,\"E\":1788567794775,\"st\":1}}"}
{"receive_ns":1788567795683172000,"stream":"btcusdt@bookTicker","event_type":"bookTicker","event_time_ms":1788567794776,"raw_json":"{\"stream\":\"btcusdt@bookTicker\",\"data\":{\"e\":\"bookTicker\",\"u\":11478512272968,\"s\":\"BTCUSDT\",\"ps\":\"BTCUSDT\",\"b\":\"79596.90\",\"B\":\"7.036\",\"a\":\"79597.00\",\"A\":\"7.926\",\"T\":1788567794776,\"E\":1788567794776,\"st\":1}}"}
{"receive_ns":1788567795695438000,"stream":"btcusdt@bookTicker","event_type":"bookTicker","event_time_ms":1788567794778,"raw_json":"{\"stream\":\"btcusdt@bookTicker\",\"data\":{\"e\":\"bookTicker\",\"u\":11478512273078,\"s\":\"BTCUSDT\",\"ps\":\"BTCUSDT\",\"b\":\"79596.90\",\"B\":\"6.939\",\"a\":\"79597.00\",\"A\":\"7.926\",\"T\":1788567794778,\"E\":1788567794778,\"st\":1}}"}
{"receive_ns":1788567795707377000,"stream":"btcusdt@bookTicker","event_type":"bookTicker","event_time_ms":1788567794780,"raw_json":"{\"stream\":\"btcusdt@bookTicker\",\"data\":{\"e\":\"bookTicker\",\"u\":11478512273175,\"s\":\"BTCUSDT\",\"ps\":\"BTCUSDT\",\"b\":\"79596.90\",\"B\":\"7.024\",\"a\":\"79597.00\",\"A\":\"7.926\",\"T\":1788567794780,\"E\":1788567794780,\"st\":1}}"}
{"receive_ns":1788567795713302000,"stream":"btcusdt@bookTicker","event_type":"bookTicker","event_time_ms":1788567794782,"raw_json":"{\"stream\":\"btcusdt@bookTicker\",\"data\":{\"e\":\"bookTicker\",\"u\":11478512273347,\"s\":\"BTCUSDT\",\"ps\":\"BTCUSDT\",\"b\":\"79596.90\",\"B\":\"6.939\",\"a\":\"79597.00\",\"A\":\"7.926\",\"T\":1788567794782,\"E\":1788567794782,\"st\":1}}"}
{"receive_ns":1788567795720916000,"stream":"btcusdt@bookTicker","event_type":"bookTicker","event_time_ms":1788567794783,"raw_json":"{\"stream\":\"btcusdt@bookTicker\",\"data\":{\"e\":\"bookTicker\",\"u\":11478512273522,\"s\":\"BTCUSDT\",\"ps\":\"BTCUSDT\",\"b\":\"79596.90\",\"B\":\"7.023\",\"a\":\"79597.00\",\"A\":\"7.926\",\"T\":1788567794783,\"E\":1788567794783,\"st\":1}}"}
{"receive_ns":1788567795732434000,"stream":"btcusdt@bookTicker","event_type":"bookTicker","event_time_ms":1788567794785,"raw_json":"{\"stream\":\"btcusdt@bookTicker\",\"data\":{\"e\":\"bookTicker\",\"u\":11478512273688,\"s\":\"BTCUSDT\",\"ps\":\"BTCUSDT\",\"b\":\"79596.90\",\"B\":\"6.939\",\"a\":\"79597.00\",\"A\":\"7.926\",\"T\":1788567794785,\"E\":1788567794785,\"st\":1}}"}
{"receive_ns":1788567795744950000,"stream":"btcusdt@bookTicker","event_type":"bookTicker","event_time_ms":1788567794787,"raw_json":"{\"stream\":\"btcusdt@bookTicker\",\"data\":{\"e\":\"bookTicker\",\"u\":11478512273762,\"s\":\"BTCUSDT\",\"ps\":\"BTCUSDT\",\"b\":\"79596.90\",\"B\":\"7.028\",\"a\":\"79597.00\",\"A\":\"7.926\",\"T\":1788567794786,\"E\":1788567794787,\"st\":1}}"}
{"receive_ns":1788567795756144000,"stream":"btcusdt@bookTicker","event_type":"bookTicker","event_time_ms":1788567794788,"raw_json":"{\"stream\":\"btcusdt@bookTicker\",\"data\":{\"e\":\"bookTicker\",\"u\":11478512273817,\"s\":\"BTCUSDT\",\"ps\":\"BTCUSDT\",\"b\":\"79596.90\",\"B\":\"7.027\",\"a\":\"79597.00\",\"A\":\"7.926\",\"T\":1788567794788,\"E\":1788567794788,\"st\":1}}"}
{"receive_ns":1788567795762745000,"stream":"btcusdt@bookTicker","event_type":"bookTicker","event_time_ms":1788567794789,"raw_json":"{\"stream\":\"btcusdt@bookTicker\",\"data\":{\"e\":\"bookTicker\",\"u\":11478512273850,\"s\":\"BTCUSDT\",\"ps\":\"BTCUSDT\",\"b\":\"79596.90\",\"B\":\"6.938\",\"a\":\"79597.00\",\"A\":\"7.926\",\"T\":1788567794788,\"E\":1788567794789,\"st\":1}}"}
{"receive_ns":1788567795774378000,"stream":"btcusdt@bookTicker","event_type":"bookTicker","event_time_ms":1788567794790,"raw_json":"{\"stream\":\"btcusdt@bookTicker\",\"data\":{\"e\":\"bookTicker\",\"u\":11478512274010,\"s\":\"BTCUSDT\",\"ps\":\"BTCUSDT\",\"b\":\"79596.90\",\"B\":\"7.022\",\"a\":\"79597.00\",\"A\":\"7.926\",\"T\":1788567794790,\"E\":1788567794790,\"st\":1}}"}
{"receive_ns":1788567795774685000,"stream":"btcusdt@bookTicker","event_type":"bookTicker","event_time_ms":1788567794792,"raw_json":"{\"stream\":\"btcusdt@bookTicker\",\"data\":{\"e\":\"bookTicker\",\"u\":11478512274067,\"s\":\"BTCUSDT\",\"ps\":\"BTCUSDT\",\"b\":\"79596.90\",\"B\":\"7.023\",\"a\":\"79597.00\",\"A\":\"7.926\",\"T\":1788567794791,\"E\":1788567794792,\"st\":1}}"}
{"receive_ns":1788567795775006000,"stream":"btcusdt@bookTicker","event_type":"bookTicker","event_time_ms":1788567794792,"raw_json":"{\"stream\":\"btcusdt@bookTicker\",\"data\":{\"e\":\"bookTicker\",\"u\":11478512274122,\"s\":\"BTCUSDT\",\"ps\":\"BTCUSDT\",\"b\":\"79596.90\",\"B\":\"6.939\",\"a\":\"79597.00\",\"A\":\"7.926\",\"T\":1788567794792,\"E\":1788567794792,\"st\":1}}"}
{"receive_ns":1788567795786820000,"stream":"btcusdt@bookTicker","event_type":"bookTicker","event_time_ms":1788567794794,"raw_json":"{\"stream\":\"btcusdt@bookTicker\",\"data\":{\"e\":\"bookTicker\",\"u\":11478512274221,\"s\":\"BTCUSDT\",\"ps\":\"BTCUSDT\",\"b\":\"79596.90\",\"B\":\"7.025\",\"a\":\"79597.00\",\"A\":\"7.926\",\"T\":1788567794794,\"E\":1788567794794,\"st\":1}}"}
{"receive_ns":1788567795794562000,"stream":"btcusdt@bookTicker","event_type":"bookTicker","event_time_ms":1788567794796,"raw_json":"{\"stream\":\"btcusdt@bookTicker\",\"data\":{\"e\":\"bookTicker\",\"u\":11478512274322,\"s\":\"BTCUSDT\",\"ps\":\"BTCUSDT\",\"b\":\"79596.90\",\"B\":\"6.939\",\"a\":\"79597.00\",\"A\":\"7.926\",\"T\":1788567794795,\"E\":1788567794796,\"st\":1}}"}
{"receive_ns":1788567795806510000,"stream":"btcusdt@bookTicker","event_type":"bookTicker","event_time_ms":1788567794797,"raw_json":"{\"stream\":\"btcusdt@bookTicker\",\"data\":{\"e\":\"bookTicker\",\"u\":11478512274378,\"s\":\"BTCUSDT\",\"ps\":\"BTCUSDT\",\"b\":\"79596.90\",\"B\":\"7.029\",\"a\":\"79597.00\",\"A\":\"7.926\",\"T\":1788567794797,\"E\":1788567794797,\"st\":1}}"}
{"receive_ns":1788567795818810000,"stream":"btcusdt@bookTicker","event_type":"bookTicker","event_time_ms":1788567794799,"raw_json":"{\"stream\":\"btcusdt@bookTicker\",\"data\":{\"e\":\"bookTicker\",\"u\":11478512274458,\"s\":\"BTCUSDT\",\"ps\":\"BTCUSDT\",\"b\":\"79596.90\",\"B\":\"6.939\",\"a\":\"79597.00\",\"A\":\"7.926\",\"T\":1788567794799,\"E\":1788567794799,\"st\":1}}"}
{"receive_ns":1788567795831267000,"stream":"btcusdt@bookTicker","event_type":"bookTicker","event_time_ms":1788567794800,"raw_json":"{\"stream\":\"btcusdt@bookTicker\",\"data\":{\"e\":\"bookTicker\",\"u\":11478512274511,\"s\":\"BTCUSDT\",\"ps\":\"BTCUSDT\",\"b\":\"79596.90\",\"B\":\"7.026\",\"a\":\"79597.00\",\"A\":\"7.926\",\"T\":1788567794800,\"E\":1788567794800,\"st\":1}}"}
{"receive_ns":1788567795837156000,"stream":"btcusdt@bookTicker","event_type":"bookTicker","event_time_ms":1788567794802,"raw_json":"{\"stream\":\"btcusdt@bookTicker\",\"data\":{\"e\":\"bookTicker\",\"u\":11478512274619,\"s\":\"BTCUSDT\",\"ps\":\"BTCUSDT\",\"b\":\"79596.90\",\"B\":\"6.939\",\"a\":\"79597.00\",\"A\":\"7.926\",\"T\":1788567794802,\"E\":1788567794802,\"st\":1}}"}
{"receive_ns":1788567795847982000,"stream":"btcusdt@bookTicker","event_type":"bookTicker","event_time_ms":1788567794803,"raw_json":"{\"stream\":\"btcusdt@bookTicker\",\"data\":{\"e\":\"bookTicker\",\"u\":11478512274715,\"s\":\"BTCUSDT\",\"ps\":\"BTCUSDT\",\"b\":\"79596.90\",\"B\":\"7.033\",\"a\":\"79597.00\",\"A\":\"7.926\",\"T\":1788567794803,\"E\":1788567794803,\"st\":1}}"}
{"receive_ns":1788567795867679000,"stream":"btcusdt@bookTicker","event_type":"bookTicker","event_time_ms":1788567794805,"raw_json":"{\"stream\":\"btcusdt@bookTicker\",\"data\":{\"e\":\"bookTicker\",\"u\":11478512274807,\"s\":\"BTCUSDT\",\"ps\":\"BTCUSDT\",\"b\":\"79596.90\",\"B\":\"6.939\",\"a\":\"79597.00\",\"A\":\"7.926\",\"T\":1788567794805,\"E\":1788567794805,\"st\":1}}"}
{"receive_ns":1788567795874592000,"stream":"btcusdt@bookTicker","event_type":"bookTicker","event_time_ms":1788567794806,"raw_json":"{\"stream\":\"btcusdt@bookTicker\",\"data\":{\"e\":\"bookTicker\",\"u\":11478512274885,\"s\":\"BTCUSDT\",\"ps\":\"BTCUSDT\",\"b\":\"79596.90\",\"B\":\"7.021\",\"a\":\"79597.00\",\"A\":\"7.926\",\"T\":1788567794806,\"E\":1788567794806,\"st\":1}}"}
{"receive_ns":1788567795886632000,"stream":"btcusdt@bookTicker","event_type":"bookTicker","event_time_ms":1788567794808,"raw_json":"{\"stream\":\"btcusdt@bookTicker\",\"data\":{\"e\":\"bookTicker\",\"u\":11478512275052,\"s\":\"BTCUSDT\",\"ps\":\"BTCUSDT\",\"b\":\"79596.90\",\"B\":\"6.939\",\"a\":\"79597.00\",\"A\":\"7.926\",\"T\":1788567794808,\"E\":1788567794808,\"st\":1}}"}
{"receive_ns":1788567795893526000,"stream":"btcusdt@bookTicker","event_type":"bookTicker","event_time_ms":1788567794809,"raw_json":"{\"stream\":\"btcusdt@bookTicker\",\"data\":{\"e\":\"bookTicker\",\"u\":11478512275152,\"s\":\"BTCUSDT\",\"ps\":\"BTCUSDT\",\"b\":\"79596.90\",\"B\":\"7.020\",\"a\":\"79597.00\",\"A\":\"7.926\",\"T\":1788567794809,\"E\":1788567794809,\"st\":1}}"}
{"receive_ns":1788567795899520000,"stream":"btcusdt@bookTicker","event_type":"bookTicker","event_time_ms":1788567794811,"raw_json":"{\"stream\":\"btcusdt@bookTicker\",\"data\":{\"e\":\"bookTicker\",\"u\":11478512275295,\"s\":\"BTCUSDT\",\"ps\":\"BTCUSDT\",\"b\":\"79596.90\",\"B\":\"6.939\",\"a\":\"79597.00\",\"A\":\"7.926\",\"T\":1788567794811,\"E\":1788567794811,\"st\":1}}"}
{"receive_ns":1788567795918400000,"stream":"btcusdt@bookTicker","event_type":"bookTicker","event_time_ms":1788567794813,"raw_json":"{\"stream\":\"btcusdt@bookTicker\",\"data\":{\"e\":\"bookTicker\",\"u\":11478512275440,\"s\":\"BTCUSDT\",\"ps\":\"BTCUSDT\",\"b\":\"79596.90\",\"B\":\"7.026\",\"a\":\"79597.00\",\"A\":\"7.926\",\"T\":1788567794812,\"E\":1788567794813,\"st\":1}}"}
{"receive_ns":1788567795929629000,"stream":"btcusdt@bookTicker","event_type":"bookTicker","event_time_ms":1788567794814,"raw_json":"{\"stream\":\"btcusdt@bookTicker\",\"data\":{\"e\":\"bookTicker\",\"u\":11478512275667,\"s\":\"BTCUSDT\",\"ps\":\"BTCUSDT\",\"b\":\"79596.90\",\"B\":\"6.939\",\"a\":\"79597.00\",\"A\":\"7.926\",\"T\":1788567794814,\"E\":1788567794814,\"st\":1}}"}
{"receive_ns":1788567795946430000,"stream":"btcusdt@bookTicker","event_type":"bookTicker","event_time_ms":1788567794816,"raw_json":"{\"stream\":\"btcusdt@bookTicker\",\"data\":{\"e\":\"bookTicker\",\"u\":11478512275814,\"s\":\"BTCUSDT\",\"ps\":\"BTCUSDT\",\"b\":\"79596.90\",\"B\":\"7.037\",\"a\":\"79597.00\",\"A\":\"7.926\",\"T\":1788567794816,\"E\":1788567794816,\"st\":1}}"}
{"receive_ns":1788567795964384000,"stream":"btcusdt@bookTicker","event_type":"bookTicker","event_time_ms":1788567794818,"raw_json":"{\"stream\":\"btcusdt@bookTicker\",\"data\":{\"e\":\"bookTicker\",\"u\":11478512275966,\"s\":\"BTCUSDT\",\"ps\":\"BTCUSDT\",\"b\":\"79596.90\",\"B\":\"6.939\",\"a\":\"79597.00\",\"A\":\"7.926\",\"T\":1788567794817,\"E\":1788567794818,\"st\":1}}"}
{"receive_ns":1788567795981368000,"stream":"btcusdt@bookTicker","event_type":"bookTicker","event_time_ms":1788567794819,"raw_json":"{\"stream\":\"btcusdt@bookTicker\",\"data\":{\"e\":\"bookTicker\",\"u\":11478512276031,\"s\":\"BTCUSDT\",\"ps\":\"BTCUSDT\",\"b\":\"79596.90\",\"B\":\"7.022\",\"a\":\"79597.00\",\"A\":\"7.926\",\"T\":1788567794819,\"E\":1788567794819,\"st\":1}}"}
{"receive_ns":1788567795999063000,"stream":"btcusdt@bookTicker","event_type":"bookTicker","event_time_ms":1788567794821,"raw_json":"{\"stream\":\"btcusdt@bookTicker\",\"data\":{\"e\":\"bookTicker\",\"u\":11478512276200,\"s\":\"BTCUSDT\",\"ps\":\"BTCUSDT\",\"b\":\"79596.90\",\"B\":\"6.939\",\"a\":\"79597.00\",\"A\":\"7.926\",\"T\":1788567794821,\"E\":1788567794821,\"st\":1}}"}
{"receive_ns":1788567796008076000,"stream":"btcusdt@bookTicker","event_type":"bookTicker","event_time_ms":1788567794822,"raw_json":"{\"stream\":\"btcusdt@bookTicker\",\"data\":{\"e\":\"bookTicker\",\"u\":11478512276320,\"s\":\"BTCUSDT\",\"ps\":\"BTCUSDT\",\"b\":\"79596.90\",\"B\":\"7.022\",\"a\":\"79597.00\",\"A\":\"7.926\",\"T\":1788567794822,\"E\":1788567794822,\"st\":1}}"}
{"receive_ns":1788567796025093000,"stream":"btcusdt@bookTicker","event_type":"bookTicker","event_time_ms":1788567794824,"raw_json":"{\"stream\":\"btcusdt@bookTicker\",\"data\":{\"e\":\"bookTicker\",\"u\":11478512276492,\"s\":\"BTCUSDT\",\"ps\":\"BTCUSDT\",\"b\":\"79596.90\",\"B\":\"6.939\",\"a\":\"79597.00\",\"A\":\"7.926\",\"T\":1788567794824,\"E\":1788567794824,\"st\":1}}"}
{"receive_ns":1788567796036454000,"stream":"btcusdt@bookTicker","event_type":"bookTicker","event_time_ms":1788567794825,"raw_json":"{\"stream\":\"btcusdt@bookTicker\",\"data\":{\"e\":\"bookTicker\",\"u\":11478512276615,\"s\":\"BTCUSDT\",\"ps\":\"BTCUSDT\",\"b\":\"79596.90\",\"B\":\"7.018\",\"a\":\"79597.00\",\"A\":\"7.926\",\"T\":1788567794825,\"E\":1788567794825,\"st\":1}}"}
{"receive_ns":1788567796047248000,"stream":"btcusdt@bookTicker","event_type":"bookTicker","event_time_ms":1788567794827,"raw_json":"{\"stream\":\"btcusdt@bookTicker\",\"data\":{\"e\":\"bookTicker\",\"u\":11478512276739,\"s\":\"BTCUSDT\",\"ps\":\"BTCUSDT\",\"b\":\"79596.90\",\"B\":\"6.939\",\"a\":\"79597.00\",\"A\":\"7.926\",\"T\":1788567794827,\"E\":1788567794827,\"st\":1}}"}
{"receive_ns":1788567796059558000,"stream":"btcusdt@depth@100ms","event_type":"depthUpdate","event_time_ms":1788567794829,"raw_json":"{\"stream\":\"btcusdt@depth@100ms\",\"data\":{\"e\":\"depthUpdate\",\"E\":1788567794829,\"T\":1788567794828,\"s\":\"BTCUSDT\",\"ps\":\"BTCUSDT\",\"U\":11478512269177,\"u\":11478512276779,\"pu\":11478512269151,\"b\":[[\"29096.90\",\"0.063\"],[\"29196.90\",\"1.813\"],[\"29296.90\",\"0.224\"],[\"71637.20\",\"0.002\"],[\"76413.00\",\"0.025\"],[\"78005.00\",\"0.228\"],[\"78800.90\",\"15.422\"],[\"79198.90\",\"3.216\"],[\"79475.60\",\"0.000\"],[\"79571.50\",\"1.108\"],[\"79572.10\",\"0.001\"],[\"79585.10\",\"0.000\"],[\"79586.10\",\"0.067\"],[\"79589.70\",\"0.124\"],[\"79590.00\",\"0.094\"],[\"79593.60\",\"0.003\"],[\"79596.90\",\"6.939\"]],\"a\":[[\"79599.90\",\"0.028\"],[\"79600.30\",\"0.028\"],[\"79600.50\",\"0.104\"],[\"79600.70\",\"0.030\"],[\"79601.70\",\"0.000\"],[\"79601.80\",\"0.001\"],[\"79601.90\",\"0.002\"],[\"79627.30\",\"0.002\"],[\"79671.50\",\"21.661\"],[\"79676.90\",\"0.102\"],[\"79718.80\",\"1.168\"],[\"80393.00\",\"16.246\"]],\"st\":1}}"}
{"receive_ns":1788567796071161000,"stream":"btcusdt@bookTicker","event_type":"bookTicker","event_time_ms":1788567794829,"raw_json":"{\"stream\":\"btcusdt@bookTicker\",\"data\":{\"e\":\"bookTicker\",\"u\":11478512276811,\"s\":\"BTCUSDT\",\"ps\":\"BTCUSDT\",\"b\":\"79596.90\",\"B\":\"7.018\",\"a\":\"79597.00\",\"A\":\"7.926\",\"T\":1788567794829,\"E\":1788567794829,\"st\":1}}"}
{"receive_ns":1788567796078567000,"stream":"btcusdt@bookTicker","event_type":"bookTicker","event_time_ms":1788567794831,"raw_json":"{\"stream\":\"btcusdt@bookTicker\",\"data\":{\"e\":\"bookTicker\",\"u\":11478512276931,\"s\":\"BTCUSDT\",\"ps\":\"BTCUSDT\",\"b\":\"79596.90\",\"B\":\"6.939\",\"a\":\"79597.00\",\"A\":\"7.926\",\"T\":1788567794831,\"E\":1788567794831,\"st\":1}}"}
{"receive_ns":1788567796096800000,"stream":"btcusdt@bookTicker","event_type":"bookTicker","event_time_ms":1788567794832,"raw_json":"{\"stream\":\"btcusdt@bookTicker\",\"data\":{\"e\":\"bookTicker\",\"u\":11478512277040,\"s\":\"BTCUSDT\",\"ps\":\"BTCUSDT\",\"b\":\"79596.90\",\"B\":\"7.029\",\"a\":\"79597.00\",\"A\":\"7.926\",\"T\":1788567794832,\"E\":1788567794832,\"st\":1}}"}
{"receive_ns":1788567796114433000,"stream":"btcusdt@bookTicker","event_type":"bookTicker","event_time_ms":1788567794834,"raw_json":"{\"stream\":\"btcusdt@bookTicker\",\"data\":{\"e\":\"bookTicker\",\"u\":11478512277169,\"s\":\"BTCUSDT\",\"ps\":\"BTCUSDT\",\"b\":\"79596.90\",\"B\":\"6.939\",\"a\":\"79597.00\",\"A\":\"7.926\",\"T\":1788567794834,\"E\":1788567794834,\"st\":1}}"}
{"receive_ns":1788567796125397000,"stream":"btcusdt@bookTicker","event_type":"bookTicker","event_time_ms":1788567794835,"raw_json":"{\"stream\":\"btcusdt@bookTicker\",\"data\":{\"e\":\"bookTicker\",\"u\":11478512277247,\"s\":\"BTCUSDT\",\"ps\":\"BTCUSDT\",\"b\":\"79596.90\",\"B\":\"7.037\",\"a\":\"79597.00\",\"A\":\"7.926\",\"T\":1788567794835,\"E\":1788567794835,\"st\":1}}"}
{"receive_ns":1788567796142082000,"stream":"btcusdt@bookTicker","event_type":"bookTicker","event_time_ms":1788567794837,"raw_json":"{\"stream\":\"btcusdt@bookTicker\",\"data\":{\"e\":\"bookTicker\",\"u\":11478512277410,\"s\":\"BTCUSDT\",\"ps\":\"BTCUSDT\",\"b\":\"79596.90\",\"B\":\"6.939\",\"a\":\"79597.00\",\"A\":\"7.926\",\"T\":1788567794837,\"E\":1788567794837,\"st\":1}}"}
{"receive_ns":1788567796152271000,"stream":"btcusdt@bookTicker","event_type":"bookTicker","event_time_ms":1788567794839,"raw_json":"{\"stream\":\"btcusdt@bookTicker\",\"data\":{\"e\":\"bookTicker\",\"u\":11478512277496,\"s\":\"BTCUSDT\",\"ps\":\"BTCUSDT\",\"b\":\"79596.90\",\"B\":\"7.019\",\"a\":\"79597.00\",\"A\":\"7.926\",\"T\":1788567794838,\"E\":1788567794839,\"st\":1}}"}
{"receive_ns":1788567796175703000,"stream":"btcusdt@bookTicker","event_type":"bookTicker","event_time_ms":1788567794841,"raw_json":"{\"stream\":\"btcusdt@bookTicker\",\"data\":{\"e\":\"bookTicker\",\"u\":11478512277610,\"s\":\"BTCUSDT\",\"ps\":\"BTCUSDT\",\"b\":\"79596.90\",\"B\":\"6.939\",\"a\":\"79597.00\",\"A\":\"7.926\",\"T\":1788567794840,\"E\":1788567794841,\"st\":1}}"}
{"receive_ns":1788567796187763000,"stream":"btcusdt@bookTicker","event_type":"bookTicker","event_time_ms":1788567794842,"raw_json":"{\"stream\":\"btcusdt@bookTicker\",\"data\":{\"e\":\"bookTicker\",\"u\":11478512277738,\"s\":\"BTCUSDT\",\"ps\":\"BTCUSDT\",\"b\":\"79596.90\",\"B\":\"7.022\",\"a\":\"79597.00\",\"A\":\"7.926\",\"T\":1788567794842,\"E\":1788567794842,\"st\":1}}"}
{"receive_ns":1788567796193590000,"stream":"btcusdt@bookTicker","event_type":"bookTicker","event_time_ms":1788567794844,"raw_json":"{\"stream\":\"btcusdt@bookTicker\",\"data\":{\"e\":\"bookTicker\",\"u\":11478512277867,\"s\":\"BTCUSDT\",\"ps\":\"BTCUSDT\",\"b\":\"79596.90\",\"B\":\"6.939\",\"a\":\"79597.00\",\"A\":\"7.926\",\"T\":1788567794844,\"E\":1788567794844,\"st\":1}}"}
{"receive_ns":1788567796210023000,"stream":"btcusdt@bookTicker","event_type":"bookTicker","event_time_ms":1788567794846,"raw_json":"{\"stream\":\"btcusdt@bookTicker\",\"data\":{\"e\":\"bookTicker\",\"u\":11478512277955,\"s\":\"BTCUSDT\",\"ps\":\"BTCUSDT\",\"b\":\"79596.90\",\"B\":\"7.023\",\"a\":\"79597.00\",\"A\":\"7.926\",\"T\":1788567794846,\"E\":1788567794846,\"st\":1}}"}
{"receive_ns":1788567796220290000,"stream":"btcusdt@bookTicker","event_type":"bookTicker","event_time_ms":1788567794848,"raw_json":"{\"stream\":\"btcusdt@bookTicker\",\"data\":{\"e\":\"bookTicker\",\"u\":11478512278070,\"s\":\"BTCUSDT\",\"ps\":\"BTCUSDT\",\"b\":\"79596.90\",\"B\":\"6.939\",\"a\":\"79597.00\",\"A\":\"7.926\",\"T\":1788567794848,\"E\":1788567794848,\"st\":1}}"}
{"receive_ns":1788567796231814000,"stream":"btcusdt@bookTicker","event_type":"bookTicker","event_time_ms":1788567794849,"raw_json":"{\"stream\":\"btcusdt@bookTicker\",\"data\":{\"e\":\"bookTicker\",\"u\":11478512278139,\"s\":\"BTCUSDT\",\"ps\":\"BTCUSDT\",\"b\":\"79596.90\",\"B\":\"7.029\",\"a\":\"79597.00\",\"A\":\"7.926\",\"T\":1788567794849,\"E\":1788567794849,\"st\":1}}"}
{"receive_ns":1788567796243149000,"stream":"btcusdt@bookTicker","event_type":"bookTicker","event_time_ms":1788567794851,"raw_json":"{\"stream\":\"btcusdt@bookTicker\",\"data\":{\"e\":\"bookTicker\",\"u\":11478512278224,\"s\":\"BTCUSDT\",\"ps\":\"BTCUSDT\",\"b\":\"79596.90\",\"B\":\"6.939\",\"a\":\"79597.00\",\"A\":\"7.926\",\"T\":1788567794851,\"E\":1788567794851,\"st\":1}}"}
{"receive_ns":1788567796254420000,"stream":"btcusdt@bookTicker","event_type":"bookTicker","event_time_ms":1788567794852,"raw_json":"{\"stream\":\"btcusdt@bookTicker\",\"data\":{\"e\":\"bookTicker\",\"u\":11478512278298,\"s\":\"BTCUSDT\",\"ps\":\"BTCUSDT\",\"b\":\"79596.90\",\"B\":\"7.034\",\"a\":\"79597.00\",\"A\":\"7.926\",\"T\":1788567794852,\"E\":1788567794852,\"st\":1}}"}
{"receive_ns":1788567796265771000,"stream":"btcusdt@bookTicker","event_type":"bookTicker","event_time_ms":1788567794854,"raw_json":"{\"stream\":\"btcusdt@bookTicker\",\"data\":{\"e\":\"bookTicker\",\"u\":11478512278396,\"s\":\"BTCUSDT\",\"ps\":\"BTCUSDT\",\"b\":\"79596.90\",\"B\":\"6.939\",\"a\":\"79597.00\",\"A\":\"7.926\",\"T\":1788567794854,\"E\":1788567794854,\"st\":1}}"}
{"receive_ns":1788567796282449000,"stream":"btcusdt@bookTicker","event_type":"bookTicker","event_time_ms":1788567794856,"raw_json":"{\"stream\":\"btcusdt@bookTicker\",\"data\":{\"e\":\"bookTicker\",\"u\":11478512278483,\"s\":\"BTCUSDT\",\"ps\":\"BTCUSDT\",\"b\":\"79596.90\",\"B\":\"7.023\",\"a\":\"79597.00\",\"A\":\"7.926\",\"T\":1788567794855,\"E\":1788567794856,\"st\":1}}"}
{"receive_ns":1788567796288800000,"stream":"btcusdt@bookTicker","event_type":"bookTicker","event_time_ms":1788567794858,"raw_json":"{\"stream\":\"btcusdt@bookTicker\",\"data\":{\"e\":\"bookTicker\",\"u\":11478512278579,\"s\":\"BTCUSDT\",\"ps\":\"BTCUSDT\",\"b\":\"79596.90\",\"B\":\"6.939\",\"a\":\"79597.00\",\"A\":\"7.926\",\"T\":1788567794857,\"E\":1788567794858,\"st\":1}}"}
{"receive_ns":1788567796300788000,"stream":"btcusdt@bookTicker","event_type":"bookTicker","event_time_ms":1788567794859,"raw_json":"{\"stream\":\"btcusdt@bookTicker\",\"data\":{\"e\":\"bookTicker\",\"u\":11478512278661,\"s\":\"BTCUSDT\",\"ps\":\"BTCUSDT\",\"b\":\"79596.90\",\"B\":\"7.024\",\"a\":\"79597.00\",\"A\":\"7.926\",\"T\":1788567794859,\"E\":1788567794859,\"st\":1}}"}
{"receive_ns":1788567796312987000,"stream":"btcusdt@bookTicker","event_type":"bookTicker","event_time_ms":1788567794861,"raw_json":"{\"stream\":\"btcusdt@bookTicker\",\"data\":{\"e\":\"bookTicker\",\"u\":11478512278739,\"s\":\"BTCUSDT\",\"ps\":\"BTCUSDT\",\"b\":\"79596.90\",\"B\":\"6.939\",\"a\":\"79597.00\",\"A\":\"7.926\",\"T\":1788567794861,\"E\":1788567794861,\"st\":1}}"}
{"receive_ns":1788567796336275000,"stream":"btcusdt@bookTicker","event_type":"bookTicker","event_time_ms":1788567794862,"raw_json":"{\"stream\":\"btcusdt@bookTicker\",\"data\":{\"e\":\"bookTicker\",\"u\":11478512278822,\"s\":\"BTCUSDT\",\"ps\":\"BTCUSDT\",\"b\":\"79596.90\",\"B\":\"7.020\",\"a\":\"79597.00\",\"A\":\"7.926\",\"T\":1788567794862,\"E\":1788567794862,\"st\":1}}"}
{"receive_ns":1788567796365128000,"stream":"btcusdt@bookTicker","event_type":"bookTicker","event_time_ms":1788567794864,"raw_json":"{\"stream\":\"btcusdt@bookTicker\",\"data\":{\"e\":\"bookTicker\",\"u\":11478512278942,\"s\":\"BTCUSDT\",\"ps\":\"BTCUSDT\",\"b\":\"79596.90\",\"B\":\"6.939\",\"a\":\"79597.00\",\"A\":\"7.926\",\"T\":1788567794864,\"E\":1788567794864,\"st\":1}}"}
{"receive_ns":1788567796377212000,"stream":"btcusdt@bookTicker","event_type":"bookTicker","event_time_ms":1788567794865,"raw_json":"{\"stream\":\"btcusdt@bookTicker\",\"data\":{\"e\":\"bookTicker\",\"u\":11478512279009,\"s\":\"BTCUSDT\",\"ps\":\"BTCUSDT\",\"b\":\"79596.90\",\"B\":\"6.938\",\"a\":\"79597.00\",\"A\":\"7.926\",\"T\":1788567794865,\"E\":1788567794865,\"st\":1}}"}
{"receive_ns":1788567796388503000,"stream":"btcusdt@bookTicker","event_type":"bookTicker","event_time_ms":1788567794866,"raw_json":"{\"stream\":\"btcusdt@bookTicker\",\"data\":{\"e\":\"bookTicker\",\"u\":11478512279045,\"s\":\"BTCUSDT\",\"ps\":\"BTCUSDT\",\"b\":\"79596.90\",\"B\":\"7.035\",\"a\":\"79597.00\",\"A\":\"7.926\",\"T\":1788567794865,\"E\":1788567794866,\"st\":1}}"}
{"receive_ns":1788567796399714000,"stream":"btcusdt@bookTicker","event_type":"bookTicker","event_time_ms":1788567794866,"raw_json":"{\"stream\":\"btcusdt@bookTicker\",\"data\":{\"e\":\"bookTicker\",\"u\":11478512279092,\"s\":\"BTCUSDT\",\"ps\":\"BTCUSDT\",\"b\":\"79596.90\",\"B\":\"7.036\",\"a\":\"79597.00\",\"A\":\"7.926\",\"T\":1788567794866,\"E\":1788567794866,\"st\":1}}"}
{"receive_ns":1788567796406414000,"stream":"btcusdt@bookTicker","event_type":"bookTicker","event_time_ms":1788567794867,"raw_json":"{\"stream\":\"btcusdt@bookTicker\",\"data\":{\"e\":\"bookTicker\",\"u\":11478512279125,\"s\":\"BTCUSDT\",\"ps\":\"BTCUSDT\",\"b\":\"79596.90\",\"B\":\"7.035\",\"a\":\"79597.00\",\"A\":\"7.926\",\"T\":1788567794866,\"E\":1788567794867,\"st\":1}}"}
{"receive_ns":1788567796418500000,"stream":"btcusdt@bookTicker","event_type":"bookTicker","event_time_ms":1788567794868,"raw_json":"{\"stream\":\"btcusdt@bookTicker\",\"data\":{\"e\":\"bookTicker\",\"u\":11478512279182,\"s\":\"BTCUSDT\",\"ps\":\"BTCUSDT\",\"b\":\"79596.90\",\"B\":\"6.938\",\"a\":\"79597.00\",\"A\":\"7.926\",\"T\":1788567794868,\"E\":1788567794868,\"st\":1}}"}
{"receive_ns":1788567796425336000,"stream":"btcusdt@bookTicker","event_type":"bookTicker","event_time_ms":1788567794869,"raw_json":"{\"stream\":\"btcusdt@bookTicker\",\"data\":{\"e\":\"bookTicker\",\"u\":11478512279248,\"s\":\"BTCUSDT\",\"ps\":\"BTCUSDT\",\"b\":\"79596.90\",\"B\":\"7.023\",\"a\":\"79597.00\",\"A\":\"7.926\",\"T\":1788567794869,\"E\":1788567794869,\"st\":1}}"}
{"receive_ns":1788567796438030000,"stream":"btcusdt@bookTicker","event_type":"bookTicker","event_time_ms":1788567794871,"raw_json":"{\"stream\":\"btcusdt@bookTicker\",\"data\":{\"e\":\"bookTicker\",\"u\":11478512279298,\"s\":\"BTCUSDT\",\"ps\":\"BTCUSDT\",\"b\":\"79596.90\",\"B\":\"7.024\",\"a\":\"79597.00\",\"A\":\"7.926\",\"T\":1788567794870,\"E\":1788567794871,\"st\":1}}"}
{"receive_ns":1788567796449812000,"stream":"btcusdt@bookTicker","event_type":"bookTicker","event_time_ms":1788567794871,"raw_json":"{\"stream\":\"btcusdt@bookTicker\",\"data\":{\"e\":\"bookTicker\",\"u\":11478512279335,\"s\":\"BTCUSDT\",\"ps\":\"BTCUSDT\",\"b\":\"79596.90\",\"B\":\"6.939\",\"a\":\"79597.00\",\"A\":\"7.926\",\"T\":1788567794871,\"E\":1788567794871,\"st\":1}}"}
{"receive_ns":1788567796461477000,"stream":"btcusdt@bookTicker","event_type":"bookTicker","event_time_ms":1788567794873,"raw_json":"{\"stream\":\"btcusdt@bookTicker\",\"data\":{\"e\":\"bookTicker\",\"u\":11478512279417,\"s\":\"BTCUSDT\",\"ps\":\"BTCUSDT\",\"b\":\"79596.90\",\"B\":\"7.031\",\"a\":\"79597.00\",\"A\":\"7.926\",\"T\":1788567794873,\"E\":1788567794873,\"st\":1}}"}
{"receive_ns":1788567796479815000,"stream":"btcusdt@bookTicker","event_type":"bookTicker","event_time_ms":1788567794875,"raw_json":"{\"stream\":\"btcusdt@bookTicker\",\"data\":{\"e\":\"bookTicker\",\"u\":11478512279489,\"s\":\"BTCUSDT\",\"ps\":\"BTCUSDT\",\"b\":\"79596.90\",\"B\":\"6.939\",\"a\":\"79597.00\",\"A\":\"7.926\",\"T\":1788567794875,\"E\":1788567794875,\"st\":1}}"}
{"receive_ns":1788567796496940000,"stream":"btcusdt@bookTicker","event_type":"bookTicker","event_time_ms":1788567794877,"raw_json":"{\"stream\":\"btcusdt@bookTicker\",\"data\":{\"e\":\"bookTicker\",\"u\":11478512279569,\"s\":\"BTCUSDT\",\"ps\":\"BTCUSDT\",\"b\":\"79596.90\",\"B\":\"7.034\",\"a\":\"79597.00\",\"A\":\"7.926\",\"T\":1788567794876,\"E\":1788567794877,\"st\":1}}"}
{"receive_ns":1788567796503442000,"stream":"btcusdt@bookTicker","event_type":"bookTicker","event_time_ms":1788567794879,"raw_json":"{\"stream\":\"btcusdt@bookTicker\",\"data\":{\"e\":\"bookTicker\",\"u\":11478512279642,\"s\":\"BTCUSDT\",\"ps\":\"BTCUSDT\",\"b\":\"79596.90\",\"B\":\"6.939\",\"a\":\"79597.00\",\"A\":\"7.926\",\"T\":1788567794878,\"E\":1788567794879,\"st\":1}}"}
{"receive_ns":1788567796507466000,"stream":"btcusdt@bookTicker","event_type":"bookTicker","event_time_ms":1788567794880,"raw_json":"{\"stream\":\"btcusdt@bookTicker\",\"data\":{\"e\":\"bookTicker\",\"u\":11478512279714,\"s\":\"BTCUSDT\",\"ps\":\"BTCUSDT\",\"b\":\"79596.90\",\"B\":\"7.021\",\"a\":\"79597.00\",\"A\":\"7.926\",\"T\":1788567794880,\"E\":1788567794880,\"st\":1}}"}
{"receive_ns":1788567796520701000,"stream":"btcusdt@bookTicker","event_type":"bookTicker","event_time_ms":1788567794882,"raw_json":"{\"stream\":\"btcusdt@bookTicker\",\"data\":{\"e\":\"bookTicker\",\"u\":11478512279795,\"s\":\"BTCUSDT\",\"ps\":\"BTCUSDT\",\"b\":\"79596.90\",\"B\":\"6.939\",\"a\":\"79597.00\",\"A\":\"7.926\",\"T\":1788567794882,\"E\":1788567794882,\"st\":1}}"}
{"receive_ns":1788567796526618000,"stream":"btcusdt@bookTicker","event_type":"bookTicker","event_time_ms":1788567794883,"raw_json":"{\"stream\":\"btcusdt@bookTicker\",\"data\":{\"e\":\"bookTicker\",\"u\":11478512279844,\"s\":\"BTCUSDT\",\"ps\":\"BTCUSDT\",\"b\":\"79596.90\",\"B\":\"7.034\",\"a\":\"79597.00\",\"A\":\"7.926\",\"T\":1788567794883,\"E\":1788567794883,\"st\":1}}"}
{"receive_ns":1788567796543857000,"stream":"btcusdt@bookTicker","event_type":"bookTicker","event_time_ms":1788567794885,"raw_json":"{\"stream\":\"btcusdt@bookTicker\",\"data\":{\"e\":\"bookTicker\",\"u\":11478512279982,\"s\":\"BTCUSDT\",\"ps\":\"BTCUSDT\",\"b\":\"79596.90\",\"B\":\"6.939\",\"a\":\"79597.00\",\"A\":\"7.926\",\"T\":1788567794885,\"E\":1788567794885,\"st\":1}}"}
{"receive_ns":1788567796555796000,"stream":"btcusdt@bookTicker","event_type":"bookTicker","event_time_ms":1788567794887,"raw_json":"{\"stream\":\"btcusdt@bookTicker\",\"data\":{\"e\":\"bookTicker\",\"u\":11478512280058,\"s\":\"BTCUSDT\",\"ps\":\"BTCUSDT\",\"b\":\"79596.90\",\"B\":\"7.018\",\"a\":\"79597.00\",\"A\":\"7.926\",\"T\":1788567794886,\"E\":1788567794887,\"st\":1}}"}
{"receive_ns":1788567796568465000,"stream":"btcusdt@bookTicker","event_type":"bookTicker","event_time_ms":1788567794888,"raw_json":"{\"stream\":\"btcusdt@bookTicker\",\"data\":{\"e\":\"bookTicker\",\"u\":11478512280207,\"s\":\"BTCUSDT\",\"ps\":\"BTCUSDT\",\"b\":\"79596.90\",\"B\":\"6.939\",\"a\":\"79597.00\",\"A\":\"7.926\",\"T\":1788567794888,\"E\":1788567794888,\"st\":1}}"}
{"receive_ns":1788567796569171000,"stream":"btcusdt@bookTicker","event_type":"bookTicker","event_time_ms":1788567794890,"raw_json":"{\"stream\":\"btcusdt@bookTicker\",\"data\":{\"e\":\"bookTicker\",\"u\":11478512280308,\"s\":\"BTCUSDT\",\"ps\":\"BTCUSDT\",\"b\":\"79596.90\",\"B\":\"7.031\",\"a\":\"79597.00\",\"A\":\"7.926\",\"T\":1788567794890,\"E\":1788567794890,\"st\":1}}"}
{"receive_ns":1788567796569799000,"stream":"btcusdt@bookTicker","event_type":"bookTicker","event_time_ms":1788567794892,"raw_json":"{\"stream\":\"btcusdt@bookTicker\",\"data\":{\"e\":\"bookTicker\",\"u\":11478512280409,\"s\":\"BTCUSDT\",\"ps\":\"BTCUSDT\",\"b\":\"79596.90\",\"B\":\"6.939\",\"a\":\"79597.00\",\"A\":\"7.926\",\"T\":1788567794892,\"E\":1788567794892,\"st\":1}}"}
{"receive_ns":1788567796570541000,"stream":"btcusdt@bookTicker","event_type":"bookTicker","event_time_ms":1788567794894,"raw_json":"{\"stream\":\"btcusdt@bookTicker\",\"data\":{\"e\":\"bookTicker\",\"u\":11478512280522,\"s\":\"BTCUSDT\",\"ps\":\"BTCUSDT\",\"b\":\"79596.90\",\"B\":\"7.036\",\"a\":\"79597.00\",\"A\":\"7.926\",\"T\":1788567794894,\"E\":1788567794894,\"st\":1}}"}
{"receive_ns":1788567796588122000,"stream":"btcusdt@bookTicker","event_type":"bookTicker","event_time_ms":1788567794896,"raw_json":"{\"stream\":\"btcusdt@bookTicker\",\"data\":{\"e\":\"bookTicker\",\"u\":11478512280660,\"s\":\"BTCUSDT\",\"ps\":\"BTCUSDT\",\"b\":\"79596.90\",\"B\":\"6.939\",\"a\":\"79597.00\",\"A\":\"7.926\",\"T\":1788567794896,\"E\":1788567794896,\"st\":1}}"}
{"receive_ns":1788567796610537000,"stream":"btcusdt@bookTicker","event_type":"bookTicker","event_time_ms":1788567794897,"raw_json":"{\"stream\":\"btcusdt@bookTicker\",\"data\":{\"e\":\"bookTicker\",\"u\":11478512280751,\"s\":\"BTCUSDT\",\"ps\":\"BTCUSDT\",\"b\":\"79596.90\",\"B\":\"7.032\",\"a\":\"79597.00\",\"A\":\"7.926\",\"T\":1788567794897,\"E\":1788567794897,\"st\":1}}"}
{"receive_ns":1788567796616461000,"stream":"btcusdt@bookTicker","event_type":"bookTicker","event_time_ms":1788567794899,"raw_json":"{\"stream\":\"btcusdt@bookTicker\",\"data\":{\"e\":\"bookTicker\",\"u\":11478512280883,\"s\":\"BTCUSDT\",\"ps\":\"BTCUSDT\",\"b\":\"79596.90\",\"B\":\"6.939\",\"a\":\"79597.00\",\"A\":\"7.926\",\"T\":1788567794899,\"E\":1788567794899,\"st\":1}}"}
{"receive_ns":1788567796633217000,"stream":"btcusdt@bookTicker","event_type":"bookTicker","event_time_ms":1788567794900,"raw_json":"{\"stream\":\"btcusdt@bookTicker\",\"data\":{\"e\":\"bookTicker\",\"u\":11478512280995,\"s\":\"BTCUSDT\",\"ps\":\"BTCUSDT\",\"b\":\"79596.90\",\"B\":\"7.025\",\"a\":\"79597.00\",\"A\":\"7.926\",\"T\":1788567794900,\"E\":1788567794900,\"st\":1}}"}
{"receive_ns":1788567796645143000,"stream":"btcusdt@bookTicker","event_type":"bookTicker","event_time_ms":1788567794902,"raw_json":"{\"stream\":\"btcusdt@bookTicker\",\"data\":{\"e\":\"bookTicker\",\"u\":11478512281135,\"s\":\"BTCUSDT\",\"ps\":\"BTCUSDT\",\"b\":\"79596.90\",\"B\":\"6.939\",\"a\":\"79597.00\",\"A\":\"7.926\",\"T\":1788567794902,\"E\":1788567794902,\"st\":1}}"}
{"receive_ns":1788567796657508000,"stream":"btcusdt@bookTicker","event_type":"bookTicker","event_time_ms":1788567794904,"raw_json":"{\"stream\":\"btcusdt@bookTicker\",\"data\":{\"e\":\"bookTicker\",\"u\":11478512281209,\"s\":\"BTCUSDT\",\"ps\":\"BTCUSDT\",\"b\":\"79596.90\",\"B\":\"7.026\",\"a\":\"79597.00\",\"A\":\"7.926\",\"T\":1788567794903,\"E\":1788567794904,\"st\":1}}"}
{"receive_ns":1788567796670688000,"stream":"btcusdt@bookTicker","event_type":"bookTicker","event_time_ms":1788567794906,"raw_json":"{\"stream\":\"btcusdt@bookTicker\",\"data\":{\"e\":\"bookTicker\",\"u\":11478512281300,\"s\":\"BTCUSDT\",\"ps\":\"BTCUSDT\",\"b\":\"79596.90\",\"B\":\"6.939\",\"a\":\"79597.00\",\"A\":\"7.926\",\"T\":1788567794906,\"E\":1788567794906,\"st\":1}}"}
{"receive_ns":1788567796684716000,"stream":"btcusdt@bookTicker","event_type":"bookTicker","event_time_ms":1788567794907,"raw_json":"{\"stream\":\"btcusdt@bookTicker\",\"data\":{\"e\":\"bookTicker\",\"u\":11478512281351,\"s\":\"BTCUSDT\",\"ps\":\"BTCUSDT\",\"b\":\"79596.90\",\"B\":\"7.020\",\"a\":\"79597.00\",\"A\":\"7.926\",\"T\":1788567794907,\"E\":1788567794907,\"st\":1}}"}
{"receive_ns":1788567796702417000,"stream":"btcusdt@bookTicker","event_type":"bookTicker","event_time_ms":1788567794909,"raw_json":"{\"stream\":\"btcusdt@bookTicker\",\"data\":{\"e\":\"bookTicker\",\"u\":11478512281450,\"s\":\"BTCUSDT\",\"ps\":\"BTCUSDT\",\"b\":\"79596.90\",\"B\":\"6.939\",\"a\":\"79597.00\",\"A\":\"7.926\",\"T\":1788567794909,\"E\":1788567794909,\"st\":1}}"}
