{"receive_ns":1788567777383841000,"stream":"btcusdt@bookTicker","event_type":"bookTicker","event_time_ms":1788567777360,"raw_json":"{\"stream\":\"btcusdt@bookTicker\",\"data\":{\"e\":\"bookTicker\",\"u\":11478511206462,\"s\":\"BTCUSDT\",\"ps\":\"BTCUSDT\",\"b\":\"79596.90\",\"B\":\"6.831\",\"a\":\"79597.00\",\"A\":\"6.720\",\"T\":1788567777360,\"E\":1788567777360,\"st\":1}}"}
{"receive_ns":1788567777384348000,"stream":"btcusdt@bookTicker","event_type":"bookTicker","event_time_ms":1788567777362,"raw_json":"{\"stream\":\"btcusdt@bookTicker\",\"data\":{\"e\":\"bookTicker\",\"u\":11478511206627,\"s\":\"BTCUSDT\",\"ps\":\"BTCUSDT\",\"b\":\"79596.90\",\"B\":\"6.831\",\"a\":\"79597.00\",\"A\":\"6.719\",\"T\":1788567777362,\"E\":1788567777362,\"st\":1}}"}
{"receive_ns":1788567777384634000,"stream":"btcusdt@bookTicker","event_type":"bookTicker","event_time_ms":1788567777362,"raw_json":"{\"stream\":\"btcusdt@bookTicker\",\"data\":{\"e\":\"bookTicker\",\"u\":11478511206635,\"s\":\"BTCUSDT\",\"ps\":\"BTCUSDT\",\"b\":\"79596.90\",\"B\":\"6.831\",\"a\":\"79597.00\",\"A\":\"6.717\",\"T\":1788567777362,\"E\":1788567777362,\"st\":1}}"}
{"receive_ns":1788567777385026000,"stream":"btcusdt@bookTicker","event_type":"bookTicker","event_time_ms":1788567777362,"raw_json":"{\"stream\":\"btcusdt@bookTicker\",\"data\":{\"e\":\"bookTicker\",\"u\":11478511206636,\"s\":\"BTCUSDT\",\"ps\":\"BTCUSDT\",\"b\":\"79596.90\",\"B\":\"6.831\",\"a\":\"79597.00\",\"A\":\"6.713\",\"T\":1788567777362,\"E\":1788567777362,\"st\":1}}"}
{"receive_ns":1788567777385412000,"stream":"btcusdt@bookTicker","event_type":"bookTicker","event_time_ms":1788567777363,"raw_json":"{\"stream\":\"btcusdt@bookTicker\",\"data\":{\"e\":\"bookTicker\",\"u\":11478511206662,\"s\":\"BTCUSDT\",\"ps\":\"BTCUSDT\",\"b\":\"79596.90\",\"B\":\"6.831\",\"a\":\"79597.00\",\"A\":\"6.671\",\"T\":1788567777363,\"E\":1788567777363,\"st\":1}}"}
{"receive_ns":1788567777386047000,"stream":"btcusdt@bookTicker","event_type":"bookTicker","event_time_ms":1788567777367,"raw_json":"{\"stream\":\"btcusdt@bookTicker\",\"data\":{\"e\":\"bookTicker\",\"u\":11478511206905,\"s\":\"BTCUSDT\",\"ps\":\"BTCUSDT\",\"b\":\"79596.90\",\"B\":\"6.831\",\"a\":\"79597.00\",\"A\":\"6.670\",\"T\":1788567777367,\"E\":1788567777367,\"st\":1}}"}
{"receive_ns":1788567777386484000,"stream":"btcusdt@bookTicker","event_type":"bookTicker","event_time_ms":1788567777370,"raw_json":"{\"stream\":\"btcusdt@bookTicker\",\"data\":{\"e\":\"bookTicker\",\"u\":11478511206988,\"s\":\"BTCUSDT\",\"ps\":\"BTCUSDT\",\"b\":\"79596.90\",\"B\":\"6.831\",\"a\":\"79597.00\",\"A\":\"6.667\",\"T\":1788567777369,\"E\":1788567777370,\"st\":1}}"}
{"receive_ns":1788567777403970000,"stream":"btcusdt@bookTicker","event_type":"bookTicker","event_time_ms":1788567777381,"raw_json":"{\"stream\":\"btcusdt@bookTicker\",\"data\":{\"e\":\"bookTicker\",\"u\":11478511207507,\"s\":\"BTCUSDT\",\"ps\":\"BTCUSDT\",\"b\":\"79596.90\",\"B\":\"6.832\",\"a\":\"79597.00\",\"A\":\"6.667\",\"T\":1788567777381,\"E\":1788567777381,\"st\":1}}"}
{"receive_ns":1788567777417896000,"stream":"btcusdt@depth@100ms","event_type":"depthUpdate","event_time_ms":1788567777387,"raw_json":"{\"stream\":\"btcusdt@depth@100ms\",\"data\":{\"e\":\"depthUpdate\",\"E\":1788567777387,\"T\":1788567777386,\"s\":\"BTCUSDT\",\"ps\":\"BTCUSDT\",\"U\":11478511201723,\"u\":11478511207709,\"pu\":11478511201598,\"b\":[[\"1000.00\",\"24.604\"],[\"29096.90\",\"0.819\"],[\"29196.90\",\"1.281\"],[\"71637.20\",\"0.002\"],[\"76413.00\",\"0.025\"],[\"78402.90\",\"3.783\"],[\"78681.50\",\"6.452\"],[\"78800.90\",\"11.621\"],[\"79536.40\",\"0.040\"],[\"79537.30\",\"0.001\"],[\"79553.20\",\"0.000\"],[\"79562.30\",\"0.001\"],[\"79566.80\",\"0.000\"],[\"79578.20\",\"0.002\"],[\"79586.10\",\"0.067\"],[\"79587.00\",\"0.004\"],[\"79590.00\",\"0.102\"],[\"79593.20\",\"0.076\"],[\"79596.90\",\"6.832\"]],\"a\":[[\"79597.00\",\"6.667\"],[\"79598.00\",\"0.081\"],[\"79598.50\",\"0.252\"],[\"79602.50\",\"0.005\"],[\"79603.90\",\"0.076\"],[\"79604.70\",\"0.001\"],[\"79605.30\",\"0.062\"],[\"79605.60\",\"1.892\"],[\"79612.20\",\"0.004\"],[\"79616.90\",\"1.974\"],[\"79617.10\",\"0.000\"],[\"79617.20\",\"0.000\"],[\"79628.10\",\"0.202\"],[\"79628.20\",\"0.012\"],[\"79643.60\",\"0.253\"],[\"79644.30\",\"0.001\"],[\"79660.20\",\"0.210\"],[\"79665.40\",\"4.872\"],[\"79804.90\",\"1.031\"],[\"80393.00\",\"14.263\"],[\"80552.20\",\"31.213\"],[\"80671.60\",\"5.281\"],[\"80757.40\",\"2.697\"]],\"st\":1}}"}
{"receive_ns":1788567777480500000,"stream":"btcusdt@depth@100ms","event_type":"depthUpdate","event_time_ms":1788567777489,"raw_json":"{\"stream\":\"btcusdt@depth@100ms\",\"data\":{\"e\":\"depthUpdate\",\"E\":1788567777489,\"T\":1788567777486,\"s\":\"BTCUSDT\",\"ps\":\"BTCUSDT\",\"U\":11478511207812,\"u\":11478511212855,\"pu\":11478511207709,\"b\":[[\"29096.90\",\"0.994\"],[\"29196.90\",\"1.106\"],[\"71202.30\",\"0.019\"],[\"71637.20\",\"0.002\"],[\"76413.00\",\"0.023\"],[\"78641.70\",\"31.141\"],[\"78800.90\",\"11.621\"],[\"79198.90\",\"3.981\"],[\"79565.80\",\"0.125\"],[\"79594.40\",\"0.076\"],[\"79594.60\",\"0.053\"]],\"a\":[[\"79643.90\",\"0.579\"],[\"80194.00\",\"4.549\"],[\"80233.80\",\"4.229\"],[\"80393.00\",\"14.263\"],[\"80399.10\",\"5.208\"],[\"81188.90\",\"0.043\"]],\"st\":1}}"}
{"receive_ns":1788567777548906000,"stream":"btcusdt@bookTicker","event_type":"bookTicker","event_time_ms":1788567777552,"raw_json":"{\"stream\":\"btcusdt@bookTicker\",\"data\":{\"e\":\"bookTicker\",\"u\":11478511215583,\"s\":\"BTCUSDT\",\"ps\":\"BTCUSDT\",\"b\":\"79596.90\",\"B\":\"6.831\",\"a\":\"79597.00\",\"A\":\"6.667\",\"T\":1788567777552,\"E\":1788567777552,\"st\":1}}"}
{"receive_ns":1788567777573916000,"stream":"btcusdt@bookTicker","event_type":"bookTicker","event_time_ms":1788567777581,"raw_json":"{\"stream\":\"btcusdt@bookTicker\",\"data\":{\"e\":\"bookTicker\",\"u\":11478511216694,\"s\":\"BTCUSDT\",\"ps\":\"BTCUSDT\",\"b\":\"79596.90\",\"B\":\"6.832\",\"a\":\"79597.00\",\"A\":\"6.667\",\"T\":1788567777581,\"E\":1788567777581,\"st\":1}}"}
{"receive_ns":1788567777592435000,"stream":"btcusdt@depth@100ms","event_type":"depthUpdate","event_time_ms":1788567777591,"raw_json":"{\"stream\":\"btcusdt@depth@100ms\",\"data\":{\"e\":\"depthUpdate\",\"E\":1788567777591,\"T\":1788567777590,\"s\":\"BTCUSDT\",\"ps\":\"BTCUSDT\",\"U\":11478511212959,\"u\":11478511217123,\"pu\":11478511212855,\"b\":[[\"1000.00\",\"24.754\"],[\"29096.90\",\"1.176\"],[\"29196.90\",\"0.924\"],[\"71202.30\",\"0.000\"],[\"71637.20\",\"0.002\"],[\"78641.70\",\"32.284\"],[\"78800.90\",\"11.622\"],[\"79565.10\",\"0.858\"],[\"79586.90\",\"0.022\"],[\"79596.90\",\"6.832\"]],\"a\":[[\"79806.10\",\"4.791\"],[\"79819.00\",\"6.989\"],[\"79844.10\",\"0.000\"],[\"80393.00\",\"14.263\"],[\"80751.20\",\"13.448\"]],\"st\":1}}"}
{"receive_ns":1788567777683599000,"stream":"btcusdt@depth@100ms","event_type":"depthUpdate","event_time_ms":1788567777693,"raw_json":"{\"stream\":\"btcusdt@depth@100ms\",\"data\":{\"e\":\"depthUpdate\",\"E\":1788567777693,\"T\":1788567777689,\"s\":\"BTCUSDT\",\"ps\":\"BTCUSDT\",\"U\":11478511217184,\"u\":11478511222003,\"pu\":11478511217123,\"b\":[[\"1000.00\",\"24.604\"],[\"29096.90\",\"1.351\"],[\"29196.90\",\"0.749\"],[\"71637.20\",\"0.002\"],[\"76413.00\",\"0.025\"],[\"78800.90\",\"11.622\"],[\"79541.10\",\"1.098\"],[\"79565.50\",\"0.046\"],[\"79567.00\",\"0.254\"],[\"79572.10\",\"0.001\"],[\"79573.20\",\"0.538\"],[\"79573.30\",\"0.439\"],[\"79576.90\",\"0.006\"],[\"79583.40\",\"0.241\"],[\"79586.10\",\"0.063\"],[\"79595.60\",\"0.012\"]],\"a\":[[\"79600.10\",\"0.002\"],[\"79600.20\",\"0.001\"],[\"79601.30\",\"0.001\"],[\"79608.90\",\"0.230\"],[\"79610.70\",\"0.545\"],[\"79613.10\",\"0.194\"],[\"79614.70\",\"0.038\"],[\"79615.90\",\"0.372\"],[\"79616.50\",\"0.775\"],[\"79618.00\",\"0.004\"],[\"79618.90\",\"0.464\"],[\"79619.70\",\"0.002\"],[\"79643.20\",\"0.241\"],[\"79643.50\",\"0.787\"],[\"79643.70\",\"2.747\"],[\"79668.70\",\"2.054\"],[\"80393.00\",\"14.263\"],[\"80552.20\",\"32.453\"],[\"81043.10\",\"0.616\"]],\"st\":1}}"}
{"receive_ns":1788567777778907000,"stream":"btcusdt@bookTicker","event_type":"bookTicker","event_time_ms":1788567777763,"raw_json":"{\"stream\":\"btcusdt@bookTicker\",\"data\":{\"e\":\"bookTicker\",\"u\":11478511225458,\"s\":\"BTCUSDT\",\"ps\":\"BTCUSDT\",\"b\":\"79596.90\",\"B\":\"6.842\",\"a\":\"79597.00\",\"A\":\"6.667\",\"T\":1788567777762,\"E\":1788567777763,\"st\":1}}"}
{"receive_ns":1788567777791592000,"stream":"btcusdt@depth@100ms","event_type":"depthUpdate","event_time_ms":1788567777795,"raw_json":"{\"stream\":\"btcusdt@depth@100ms\",\"data\":{\"e\":\"depthUpdate\",\"E\":1788567777795,\"T\":1788567777793,\"s\":\"BTCUSDT\",\"ps\":\"BTCUSDT\",\"U\":11478511222341,\"u\":11478511226453,\"pu\":11478511222003,\"b\":[[\"29096.90\",\"1.533\"],[\"29196.90\",\"0.567\"],[\"71637.20\",\"0.002\"],[\"75617.10\",\"0.008\"],[\"75617.20\",\"0.008\"],[\"76413.00\",\"0.023\"],[\"78602.00\",\"10.443\"],[\"78641.70\",\"33.554\"],[\"78800.90\",\"11.622\"],[\"79198.90\",\"3.971\"],[\"79596.90\",\"6.842\"]],\"a\":[[\"80233.80\",\"7.339\"],[\"80393.00\",\"14.796\"],[\"80711.40\",\"33.895\"]],\"st\":1}}"}
{"receive_ns":1788567777803124000,"stream":"btcusdt@bookTicker","event_type":"bookTicker","event_time_ms":1788567777811,"raw_json":"{\"stream\":\"btcusdt@bookTicker\",\"data\":{\"e\":\"bookTicker\",\"u\":11478511227162,\"s\":\"BTCUSDT\",\"ps\":\"BTCUSDT\",\"b\":\"79596.90\",\"B\":\"6.842\",\"a\":\"79597.00\",\"A\":\"6.337\",\"T\":1788567777811,\"E\":1788567777811,\"st\":1}}"}
{"receive_ns":1788567777803372000,"stream":"btcusdt@trade","event_type":"trade","event_time_ms":1788567777811,"raw_json":"{\"stream\":\"btcusdt@trade\",\"data\":{\"e\":\"trade\",\"E\":1788567777811,\"T\":1788567777811,\"s\":\"BTCUSDT\",\"t\":8054122836,\"p\":\"79597.00\",\"q\":\"0.288\",\"X\":\"MARKET\",\"m\":false,\"st\":1}}"}
{"receive_ns":1788567777803587000,"stream":"btcusdt@trade","event_type":"trade","event_time_ms":1788567777811,"raw_json":"{\"stream\":\"btcusdt@trade\",\"data\":{\"e\":\"trade\",\"E\":1788567777811,\"T\":1788567777811,\"s\":\"BTCUSDT\",\"t\":8054122837,\"p\":\"79597.00\",\"q\":\"0.042\",\"X\":\"MARKET\",\"m\":false,\"st\":1}}"}
{"receive_ns":1788567777809675000,"stream":"btcusdt@bookTicker","event_type":"bookTicker","event_time_ms":1788567777812,"raw_json":"{\"stream\":\"btcusdt@bookTicker\",\"data\":{\"e\":\"bookTicker\",\"u\":11478511227203,\"s\":\"BTCUSDT\",\"ps\":\"BTCUSDT\",\"b\":\"79596.90\",\"B\":\"7.026\",\"a\":\"79597.00\",\"A\":\"6.337\",\"T\":1788567777812,\"E\":1788567777812,\"st\":1}}"}
{"receive_ns":1788567777815217000,"stream":"btcusdt@bookTicker","event_type":"bookTicker","event_time_ms":1788567777812,"raw_json":"{\"stream\":\"btcusdt@bookTicker\",\"data\":{\"e\":\"bookTicker\",\"u\":11478511227226,\"s\":\"BTCUSDT\",\"ps\":\"BTCUSDT\",\"b\":\"79596.90\",\"B\":\"7.026\",\"a\":\"79597.00\",\"A\":\"6.723\",\"T\":1788567777812,\"E\":1788567777812,\"st\":1}}"}
{"receive_ns":1788567777823268000,"stream":"btcusdt@bookTicker","event_type":"bookTicker","event_time_ms":1788567777813,"raw_json":"{\"stream\":\"btcusdt@bookTicker\",\"data\":{\"e\":\"bookTicker\",\"u\":11478511227413,\"s\":\"BTCUSDT\",\"ps\":\"BTCUSDT\",\"b\":\"79596.90\",\"B\":\"7.025\",\"a\":\"79597.00\",\"A\":\"6.723\",\"T\":1788567777813,\"E\":1788567777813,\"st\":1}}"}
{"receive_ns":1788567777830096000,"stream":"btcusdt@bookTicker","event_type":"bookTicker","event_time_ms":1788567777816,"raw_json":"{\"stream\":\"btcusdt@bookTicker\",\"data\":{\"e\":\"bookTicker\",\"u\":11478511227528,\"s\":\"BTCUSDT\",\"ps\":\"BTCUSDT\",\"b\":\"79596.90\",\"B\":\"7.025\",\"a\":\"79597.00\",\"A\":\"6.720\",\"T\":1788567777816,\"E\":1788567777816,\"st\":1}}"}
{"receive_ns":1788567777830327000,"stream":"btcusdt@trade","event_type":"trade","event_time_ms":1788567777816,"raw_json":"{\"stream\":\"btcusdt@trade\",\"data\":{\"e\":\"trade\",\"E\":1788567777816,\"T\":1788567777816,\"s\":\"BTCUSDT\",\"t\":8054122838,\"p\":\"79597.00\",\"q\":\"0.003\",\"X\":\"MARKET\",\"m\":false,\"st\":1}}"}
{"receive_ns":1788567777880361000,"stream":"btcusdt@depth@100ms","event_type":"depthUpdate","event_time_ms":1788567777897,"raw_json":"{\"stream\":\"btcusdt@depth@100ms\",\"data\":{\"e\":\"depthUpdate\",\"E\":1788567777897,\"T\":1788567777896,\"s\":\"BTCUSDT\",\"ps\":\"BTCUSDT\",\"U\":11478511226515,\"u\":11478511231471,\"pu\":11478511226453,\"b\":[[\"1000.00\",\"24.604\"],[\"29096.90\",\"1.708\"],[\"29196.90\",\"0.392\"],[\"71637.20\",\"0.002\"],[\"76413.00\",\"0.025\"],[\"78800.90\",\"11.624\"],[\"78999.90\",\"4.425\"],[\"79198.90\",\"3.845\"],[\"79572.10\",\"0.440\"],[\"79573.30\",\"0.000\"],[\"79589.70\",\"1.370\"],[\"79590.00\",\"0.098\"],[\"79594.30\",\"0.317\"],[\"79595.70\",\"0.027\"],[\"79596.70\",\"0.009\"],[\"79596.90\",\"7.025\"]],\"a\":[[\"79597.00\",\"6.720\"],[\"79598.50\",\"0.000\"],[\"79600.40\",\"0.008\"],[\"79600.50\",\"0.078\"],[\"79600.60\",\"0.000\"],[\"79600.70\",\"0.004\"],[\"79600.80\",\"0.008\"],[\"79643.30\",\"0.101\"],[\"80393.00\",\"14.796\"],[\"80950.10\",\"0.493\"],[\"81825.70\",\"1.953\"]],\"st\":1}}"}
{"receive_ns":1788567777987957000,"stream":"btcusdt@depth@100ms","event_type":"depthUpdate","event_time_ms":1788567777999,"raw_json":"{\"stream\":\"btcusdt@depth@100ms\",\"data\":{\"e\":\"depthUpdate\",\"E\":1788567777999,\"T\":1788567777997,\"s\":\"BTCUSDT\",\"ps\":\"BTCUSDT\",\"U\":11478511231498,\"u\":11478511236514,\"pu\":11478511231471,\"b\":[[\"29096.90\",\"1.792\"],[\"29196.90\",\"0.259\"],[\"29496.90\",\"0.049\"],[\"63677.50\",\"0.000\"],[\"71637.20\",\"0.002\"],[\"76413.00\",\"0.023\"],[\"78572.90\",\"0.004\"],[\"78587.60\",\"0.001\"],[\"78589.90\",\"0.005\"],[\"78604.60\",\"0.001\"],[\"78607.00\",\"0.005\"],[\"78619.40\",\"0.000\"],[\"78800.90\",\"11.622\"]],\"a\":[[\"79643.60\",\"0.378\"],[\"79995.00\",\"4.696\"],[\"80393.00\",\"14.796\"],[\"80950.10\",\"4.194\"],[\"80954.40\",\"0.000\"],[\"81036.90\",\"4.398\"]],\"st\":1}}"}
{"receive_ns":1788567778092366000,"stream":"btcusdt@depth@100ms","event_type":"depthUpdate","event_time_ms":1788567778101,"raw_json":"{\"stream\":\"btcusdt@depth@100ms\",\"data\":{\"e\":\"depthUpdate\",\"E\":1788567778101,\"T\":1788567778099,\"s\":\"BTCUSDT\",\"ps\":\"BTCUSDT\",\"U\":11478511236612,\"u\":11478511240597,\"pu\":11478511236514,\"b\":[[\"29096.90\",\"1.855\"],[\"29196.90\",\"0.140\"],[\"29496.90\",\"0.105\"],[\"71637.20\",\"0.002\"],[\"71673.00\",\"0.000\"],[\"78402.90\",\"4.357\"],[\"78432.80\",\"1.082\"],[\"78447.50\",\"1.892\"],[\"78800.90\",\"12.572\"],[\"79198.90\",\"3.981\"],[\"79550.90\",\"0.078\"],[\"79562.50\",\"1.895\"],[\"79582.60\",\"0.070\"],[\"79594.30\",\"0.065\"]],\"a\":[[\"79806.10\",\"4.811\"],[\"79819.00\",\"7.029\"],[\"80393.00\",\"14.796\"],[\"80671.60\",\"5.900\"],[\"81188.90\",\"0.040\"]],\"st\":1}}"}
{"receive_ns":1788567778192960000,"stream":"btcusdt@depth@100ms","event_type":"depthUpdate","event_time_ms":1788567778203,"raw_json":"{\"stream\":\"btcusdt@depth@100ms\",\"data\":{\"e\":\"depthUpdate\",\"E\":1788567778203,\"T\":1788567778201,\"s\":\"BTCUSDT\",\"ps\":\"BTCUSDT\",\"U\":11478511240779,\"u\":11478511246132,\"pu\":11478511240597,\"b\":[[\"1000.00\",\"24.604\"],[\"29096.90\",\"1.911\"],[\"29196.90\",\"0.021\"],[\"29496.90\",\"0.168\"],[\"71637.20\",\"0.002\"],[\"76372.90\",\"0.023\"],[\"76413.00\",\"0.025\"],[\"77168.40\",\"0.955\"],[\"78800.90\",\"12.572\"],[\"79596.70\",\"0.010\"]],\"a\":[[\"80393.00\",\"14.796\"],[\"80751.20\",\"12.582\"]],\"st\":1}}"}
{"receive_ns":1788567778283928000,"stream":"btcusdt@bookTicker","event_type":"bookTicker","event_time_ms":1788567778294,"raw_json":"{\"stream\":\"btcusdt@bookTicker\",\"data\":{\"e\":\"bookTicker\",\"u\":11478511251747,\"s\":\"BTCUSDT\",\"ps\":\"BTCUSDT\",\"b\":\"79596.90\",\"B\":\"7.009\",\"a\":\"79597.00\",\"A\":\"6.720\",\"T\":1788567778294,\"E\":1788567778294,\"st\":1}}"}
{"receive_ns":1788567778295826000,"stream":"btcusdt@bookTicker","event_type":"bookTicker","event_time_ms":1788567778297,"raw_json":"{\"stream\":\"btcusdt@bookTicker\",\"data\":{\"e\":\"bookTicker\",\"u\":11478511252281,\"s\":\"BTCUSDT\",\"ps\":\"BTCUSDT\",\"b\":\"79596.90\",\"B\":\"7.023\",\"a\":\"79597.00\",\"A\":\"6.720\",\"T\":1788567778297,\"E\":1788567778297,\"st\":1}}"}
{"receive_ns":1788567778304725000,"stream":"btcusdt@bookTicker","event_type":"bookTicker","event_time_ms":1788567778299,"raw_json":"{\"stream\":\"btcusdt@bookTicker\",\"data\":{\"e\":\"bookTicker\",\"u\":11478511252475,\"s\":\"BTCUSDT\",\"ps\":\"BTCUSDT\",\"b\":\"79596.90\",\"B\":\"7.024\",\"a\":\"79597.00\",\"A\":\"6.720\",\"T\":1788567778298,\"E\":1788567778299,\"st\":1}}"}
{"receive_ns":1788567778305021000,"stream":"btcusdt@bookTicker","event_type":"bookTicker","event_time_ms":1788567778304,"raw_json":"{\"stream\":\"btcusdt@bookTicker\",\"data\":{\"e\":\"bookTicker\",\"u\":11478511253031,\"s\":\"BTCUSDT\",\"ps\":\"BTCUSDT\",\"b\":\"79596.90\",\"B\":\"7.024\",\"a\":\"79597.00\",\"A\":\"6.595\",\"T\":1788567778304,\"E\":1788567778304,\"st\":1}}"}
{"receive_ns":1788567778315647000,"stream":"btcusdt@trade","event_type":"trade","event_time_ms":1788567778304,"raw_json":"{\"stream\":\"btcusdt@trade\",\"data\":{\"e\":\"trade\",\"E\":1788567778304,\"T\":1788567778304,\"s\":\"BTCUSDT\",\"t\":8054122839,\"p\":\"79597.00\",\"q\":\"0.125\",\"X\":\"MARKET\",\"m\":false,\"st\":1}}"}
{"receive_ns":1788567778321172000,"stream":"btcusdt@depth@100ms","event_type":"depthUpdate","event_time_ms":1788567778305,"raw_json":"{\"stream\":\"btcusdt@depth@100ms\",\"data\":{\"e\":\"depthUpdate\",\"E\":1788567778305,\"T\":1788567778304,\"s\":\"BTCUSDT\",\"ps\":\"BTCUSDT\",\"U\":11478511246274,\"u\":11478511253031,\"pu\":11478511246132,\"b\":[[\"29096.90\",\"1.778\"],[\"29196.90\",\"0.000\"],[\"29496.90\",\"0.322\"],[\"71637.20\",\"0.002\"],[\"74781.80\",\"0.070\"],[\"76413.00\",\"0.023\"],[\"77964.00\",\"2.116\"],[\"78426.80\",\"8.014\"],[\"78562.10\",\"8.611\"],[\"78800.90\",\"12.572\"],[\"79198.90\",\"3.981\"],[\"79572.10\",\"0.001\"],[\"79573.30\",\"0.439\"],[\"79584.50\",\"0.078\"],[\"79584.60\",\"0.351\"],[\"79594.40\",\"0.000\"],[\"79594.50\",\"0.026\"],[\"79596.90\",\"7.024\"]],\"a\":[[\"79597.00\",\"6.595\"],[\"79597.30\",\"0.100\"],[\"79657.50\",\"0.013\"],[\"79995.00\",\"4.697\"],[\"80393.00\",\"14.796\"],[\"131335.00\",\"0.002\"],[\"135314.90\",\"0.002\"]],\"st\":1}}"}
{"receive_ns":1788567778327566000,"stream":"btcusdt@bookTicker","event_type":"bookTicker","event_time_ms":1788567778306,"raw_json":"{\"stream\":\"btcusdt@bookTicker\",\"data\":{\"e\":\"bookTicker\",\"u\":11478511253221,\"s\":\"BTCUSDT\",\"ps\":\"BTCUSDT\",\"b\":\"79596.90\",\"B\":\"6.857\",\"a\":\"79597.00\",\"A\":\"6.595\",\"T\":1788567778306,\"E\":1788567778306,\"st\":1}}"}
{"receive_ns":1788567778340183000,"stream":"btcusdt@bookTicker","event_type":"bookTicker","event_time_ms":1788567778306,"raw_json":"{\"stream\":\"btcusdt@bookTicker\",\"data\":{\"e\":\"bookTicker\",\"u\":11478511253275,\"s\":\"BTCUSDT\",\"ps\":\"BTCUSDT\",\"b\":\"79596.90\",\"B\":\"6.837\",\"a\":\"79597.00\",\"A\":\"6.595\",\"T\":1788567778306,\"E\":1788567778306,\"st\":1}}"}
{"receive_ns":1788567778345561000,"stream":"btcusdt@bookTicker","event_type":"bookTicker","event_time_ms":1788567778307,"raw_json":"{\"stream\":\"btcusdt@bookTicker\",\"data\":{\"e\":\"bookTicker\",\"u\":11478511253331,\"s\":\"BTCUSDT\",\"ps\":\"BTCUSDT\",\"b\":\"79596.90\",\"B\":\"6.837\",\"a\":\"79597.00\",\"A\":\"6.620\",\"T\":1788567778307,\"E\":1788567778307,\"st\":1}}"}
{"receive_ns":1788567778349504000,"stream":"btcusdt@bookTicker","event_type":"bookTicker","event_time_ms":1788567778307,"raw_json":"{\"stream\":\"btcusdt@bookTicker\",\"data\":{\"e\":\"bookTicker\",\"u\":11478511253346,\"s\":\"BTCUSDT\",\"ps\":\"BTCUSDT\",\"b\":\"79596.90\",\"B\":\"6.837\",\"a\":\"79597.00\",\"A\":\"6.702\",\"T\":1788567778307,\"E\":1788567778307,\"st\":1}}"}
{"receive_ns":1788567778349707000,"stream":"btcusdt@bookTicker","event_type":"bookTicker","event_time_ms":1788567778307,"raw_json":"{\"stream\":\"btcusdt@bookTicker\",\"data\":{\"e\":\"bookTicker\",\"u\":11478511253349,\"s\":\"BTCUSDT\",\"ps\":\"BTCUSDT\",\"b\":\"79596.90\",\"B\":\"6.837\",\"a\":\"79597.00\",\"A\":\"6.620\",\"T\":1788567778307,\"E\":1788567778307,\"st\":1}}"}
{"receive_ns":1788567778349898000,"stream":"btcusdt@bookTicker","event_type":"bookTicker","event_time_ms":1788567778307,"raw_json":"{\"stream\":\"btcusdt@bookTicker\",\"data\":{\"e\":\"bookTicker\",\"u\":11478511253350,\"s\":\"BTCUSDT\",\"ps\":\"BTCUSDT\",\"b\":\"79596.90\",\"B\":\"6.837\",\"a\":\"79597.00\",\"A\":\"6.702\",\"T\":1788567778307,\"E\":1788567778307,\"st\":1}}"}
{"receive_ns":1788567778350074000,"stream":"btcusdt@bookTicker","event_type":"bookTicker","event_time_ms":1788567778307,"raw_json":"{\"stream\":\"btcusdt@bookTicker\",\"data\":{\"e\":\"bookTicker\",\"u\":11478511253354,\"s\":\"BTCUSDT\",\"ps\":\"BTCUSDT\",\"b\":\"79596.90\",\"B\":\"6.837\",\"a\":\"79597.00\",\"A\":\"6.784\",\"T\":1788567778307,\"E\":1788567778307,\"st\":1}}"}
{"receive_ns":1788567778356320000,"stream":"btcusdt@bookTicker","event_type":"bookTicker","event_time_ms":1788567778307,"raw_json":"{\"stream\":\"btcusdt@bookTicker\",\"data\":{\"e\":\"bookTicker\",\"u\":11478511253359,\"s\":\"BTCUSDT\",\"ps\":\"BTCUSDT\",\"b\":\"79596.90\",\"B\":\"6.837\",\"a\":\"79597.00\",\"A\":\"6.702\",\"T\":1788567778307,\"E\":1788567778307,\"st\":1}}"}
{"receive_ns":1788567778356614000,"stream":"btcusdt@bookTicker","event_type":"bookTicker","event_time_ms":1788567778310,"raw_json":"{\"stream\":\"btcusdt@bookTicker\",\"data\":{\"e\":\"bookTicker\",\"u\":11478511253518,\"s\":\"BTCUSDT\",\"ps\":\"BTCUSDT\",\"b\":\"79596.90\",\"B\":\"6.856\",\"a\":\"79597.00\",\"A\":\"6.702\",\"T\":1788567778310,\"E\":1788567778310,\"st\":1}}"}
{"receive_ns":1788567778367621000,"stream":"btcusdt@bookTicker","event_type":"bookTicker","event_time_ms":1788567778330,"raw_json":"{\"stream\":\"btcusdt@bookTicker\",\"data\":{\"e\":\"bookTicker\",\"u\":11478511254800,\"s\":\"BTCUSDT\",\"ps\":\"BTCUSDT\",\"b\":\"79596.90\",\"B\":\"6.856\",\"a\":\"79597.00\",\"A\":\"8.221\",\"T\":1788567778330,\"E\":1788567778330,\"st\":1}}"}
{"receive_ns":1788567778379053000,"stream":"btcusdt@bookTicker","event_type":"bookTicker","event_time_ms":1788567778331,"raw_json":"{\"stream\":\"btcusdt@bookTicker\",\"data\":{\"e\":\"bookTicker\",\"u\":11478511254854,\"s\":\"BTCUSDT\",\"ps\":\"BTCUSDT\",\"b\":\"79596.90\",\"B\":\"6.856\",\"a\":\"79597.00\",\"A\":\"8.220\",\"T\":1788567778331,\"E\":1788567778331,\"st\":1}}"}
{"receive_ns":1788567778379362000,"stream":"btcusdt@bookTicker","event_type":"bookTicker","event_time_ms":1788567778332,"raw_json":"{\"stream\":\"btcusdt@bookTicker\",\"data\":{\"e\":\"bookTicker\",\"u\":11478511254876,\"s\":\"BTCUSDT\",\"ps\":\"BTCUSDT\",\"b\":\"79596.90\",\"B\":\"6.856\",\"a\":\"79597.00\",\"A\":\"8.222\",\"T\":1788567778332,\"E\":1788567778332,\"st\":1}}"}
{"receive_ns":1788567778379619000,"stream":"btcusdt@bookTicker","event_type":"bookTicker","event_time_ms":1788567778334,"raw_json":"{\"stream\":\"btcusdt@bookTicker\",\"data\":{\"e\":\"bookTicker\",\"u\":11478511255027,\"s\":\"BTCUSDT\",\"ps\":\"BTCUSDT\",\"b\":\"79596.90\",\"B\":\"6.856\",\"a\":\"79597.00\",\"A\":\"8.223\",\"T\":1788567778334,\"E\":1788567778334,\"st\":1}}"}
{"receive_ns":1788567778391676000,"stream":"btcusdt@bookTicker","event_type":"bookTicker","event_time_ms":1788567778337,"raw_json":"{\"stream\":\"btcusdt@bookTicker\",\"data\":{\"e\":\"bookTicker\",\"u\":11478511255199,\"s\":\"BTCUSDT\",\"ps\":\"BTCUSDT\",\"b\":\"79596.90\",\"B\":\"6.843\",\"a\":\"79597.00\",\"A\":\"8.223\",\"T\":1788567778337,\"E\":1788567778337,\"st\":1}}"}
{"receive_ns":1788567778410750000,"stream":"btcusdt@bookTicker","event_type":"bookTicker","event_time_ms":1788567778341,"raw_json":"{\"stream\":\"btcusdt@bookTicker\",\"data\":{\"e\":\"bookTicker\",\"u\":11478511255367,\"s\":\"BTCUSDT\",\"ps\":\"BTCUSDT\",\"b\":\"79596.90\",\"B\":\"6.854\",\"a\":\"79597.00\",\"A\":\"8.223\",\"T\":1788567778341,\"E\":1788567778341,\"st\":1}}"}
{"receive_ns":1788567778417368000,"stream":"btcusdt@bookTicker","event_type":"bookTicker","event_time_ms":1788567778367,"raw_json":"{\"stream\":\"btcusdt@bookTicker\",\"data\":{\"e\":\"bookTicker\",\"u\":11478511256465,\"s\":\"BTCUSDT\",\"ps\":\"BTCUSDT\",\"b\":\"79596.90\",\"B\":\"7.021\",\"a\":\"79597.00\",\"A\":\"8.223\",\"T\":1788567778366,\"E\":1788567778367,\"st\":1}}"}
{"receive_ns":1788567778433906000,"stream":"btcusdt@bookTicker","event_type":"bookTicker","event_time_ms":1788567778368,"raw_json":"{\"stream\":\"btcusdt@bookTicker\",\"data\":{\"e\":\"bookTicker\",\"u\":11478511256532,\"s\":\"BTCUSDT\",\"ps\":\"BTCUSDT\",\"b\":\"79596.90\",\"B\":\"7.020\",\"a\":\"79597.00\",\"A\":\"8.223\",\"T\":1788567778368,\"E\":1788567778368,\"st\":1}}"}
{"receive_ns":1788567778447343000,"stream":"btcusdt@bookTicker","event_type":"bookTicker","event_time_ms":1788567778368,"raw_json":"{\"stream\":\"btcusdt@bookTicker\",\"data\":{\"e\":\"bookTicker\",\"u\":11478511256537,\"s\":\"BTCUSDT\",\"ps\":\"BTCUSDT\",\"b\":\"79596.90\",\"B\":\"7.020\",\"a\":\"79597.00\",\"A\":\"8.221\",\"T\":1788567778368,\"E\":1788567778368,\"st\":1}}"}
{"receive_ns":1788567778465610000,"stream":"btcusdt@bookTicker","event_type":"bookTicker","event_time_ms":1788567778371,"raw_json":"{\"stream\":\"btcusdt@bookTicker\",\"data\":{\"e\":\"bookTicker\",\"u\":11478511256624,\"s\":\"BTCUSDT\",\"ps\":\"BTCUSDT\",\"b\":\"79596.90\",\"B\":\"7.020\",\"a\":\"79597.00\",\"A\":\"8.372\",\"T\":1788567778371,\"E\":1788567778371,\"st\":1}}"}
{"receive_ns":1788567778471234000,"stream":"btcusdt@bookTicker","event_type":"bookTicker","event_time_ms":1788567778372,"raw_json":"{\"stream\":\"btcusdt@bookTicker\",\"data\":{\"e\":\"bookTicker\",\"u\":11478511256676,\"s\":\"BTCUSDT\",\"ps\":\"BTCUSDT\",\"b\":\"79596.90\",\"B\":\"7.021\",\"a\":\"79597.00\",\"A\":\"8.372\",\"T\":1788567778372,\"E\":1788567778372,\"st\":1}}"}
{"receive_ns":1788567778488379000,"stream":"btcusdt@bookTicker","event_type":"bookTicker","event_time_ms":1788567778372,"raw_json":"{\"stream\":\"btcusdt@bookTicker\",\"data\":{\"e\":\"bookTicker\",\"u\":11478511256682,\"s\":\"BTCUSDT\",\"ps\":\"BTCUSDT\",\"b\":\"79596.90\",\"B\":\"7.021\",\"a\":\"79597.00\",\"A\":\"8.374\",\"T\":1788567778372,\"E\":1788567778372,\"st\":1}}"}
{"receive_ns":1788567778496530000,"stream":"btcusdt@bookTicker","event_type":"bookTicker","event_time_ms":1788567778406,"raw_json":"{\"stream\":\"btcusdt@bookTicker\",\"data\":{\"e\":\"bookTicker\",\"u\":11478511257972,\"s\":\"BTCUSDT\",\"ps\":\"BTCUSDT\",\"b\":\"79596.90\",\"B\":\"7.015\",\"a\":\"79597.00\",\"A\":\"8.374\",\"T\":1788567778405,\"E\":1788567778406,\"st\":1}}"}
{"receive_ns":1788567778508307000,"stream":"btcusdt@depth@100ms","event_type":"depthUpdate","event_time_ms":1788567778407,"raw_json":"{\"stream\":\"btcusdt@depth@100ms\",\"data\":{\"e\":\"depthUpdate\",\"E\":1788567778407,\"T\":1788567778406,\"s\":\"BTCUSDT\",\"ps\":\"BTCUSDT\",\"U\":11478511253122,\"u\":11478511257988,\"pu\":11478511253031,\"b\":[[\"29096.90\",\"1.596\"],[\"29496.90\",\"0.504\"],[\"63678.00\",\"0.010\"],[\"71637.20\",\"0.002\"],[\"75577.30\",\"0.000\"],[\"76413.00\",\"0.025\"],[\"78005.00\",\"0.219\"],[\"78322.00\",\"0.934\"],[\"78800.90\",\"11.938\"],[\"79198.90\",\"3.971\"],[\"79473.30\",\"0.129\"],[\"79473.40\",\"0.004\"],[\"79541.40\",\"0.041\"],[\"79557.30\",\"0.001\"],[\"79562.50\",\"1.891\"],[\"79572.10\",\"0.440\"],[\"79573.30\",\"0.000\"],[\"79583.40\",\"0.317\"],[\"79592.80\",\"0.505\"],[\"79593.20\",\"0.000\"],[\"79593.90\",\"0.000\"],[\"79594.60\",\"0.053\"],[\"79596.70\",\"0.019\"],[\"79596.90\",\"7.015\"]],\"a\":[[\"79597.00\",\"8.374\"],[\"79597.10\",\"0.744\"],[\"79597.20\",\"0.166\"],[\"79598.60\",\"0.253\"],[\"79603.90\",\"0.126\"],[\"79604.00\",\"0.125\"],[\"79604.20\",\"0.008\"],[\"79605.30\",\"0.012\"],[\"79605.60\",\"1.891\"],[\"79608.90\",\"0.669\"],[\"79610.70\",\"0.106\"],[\"79615.50\",\"0.692\"],[\"79631.40\",\"0.875\"],[\"79657.50\",\"0.019\"],[\"80011.70\",\"0.087\"],[\"80393.00\",\"14.796\"],[\"80751.20\",\"13.448\"],[\"81188.90\",\"0.037\"]],\"st\":1}}"}
{"receive_ns":1788567778520147000,"stream":"btcusdt@bookTicker","event_type":"bookTicker","event_time_ms":1788567778420,"raw_json":"{\"stream\":\"btcusdt@bookTicker\",\"data\":{\"e\":\"bookTicker\",\"u\":11478511258526,\"s\":\"BTCUSDT\",\"ps\":\"BTCUSDT\",\"b\":\"79596.90\",\"B\":\"7.015\",\"a\":\"79597.00\",\"A\":\"8.406\",\"T\":1788567778420,\"E\":1788567778420,\"st\":1}}"}
{"receive_ns":1788567778525572000,"stream":"btcusdt@bookTicker","event_type":"bookTicker","event_time_ms":1788567778470,"raw_json":"{\"stream\":\"btcusdt@bookTicker\",\"data\":{\"e\":\"bookTicker\",\"u\":11478511260111,\"s\":\"BTCUSDT\",\"ps\":\"BTCUSDT\",\"b\":\"79596.90\",\"B\":\"7.015\",\"a\":\"79597.00\",\"A\":\"8.409\",\"T\":1788567778470,\"E\":1788567778470,\"st\":1}}"}
{"receive_ns":1788567778537845000,"stream":"btcusdt@bookTicker","event_type":"bookTicker","event_time_ms":1788567778503,"raw_json":"{\"stream\":\"btcusdt@bookTicker\",\"data\":{\"e\":\"bookTicker\",\"u\":11478511262010,\"s\":\"BTCUSDT\",\"ps\":\"BTCUSDT\",\"b\":\"79596.90\",\"B\":\"7.015\",\"a\":\"79597.00\",\"A\":\"8.421\",\"T\":1788567778503,\"E\":1788567778503,\"st\":1}}"}
{"receive_ns":1788567778547215000,"stream":"btcusdt@depth@100ms","event_type":"depthUpdate","event_time_ms":1788567778509,"raw_json":"{\"stream\":\"btcusdt@depth@100ms\",\"data\":{\"e\":\"depthUpdate\",\"E\":1788567778509,\"T\":1788567778506,\"s\":\"BTCUSDT\",\"ps\":\"BTCUSDT\",\"U\":11478511258027,\"u\":11478511262166,\"pu\":11478511257988,\"b\":[[\"1000.00\",\"24.604\"],[\"29096.90\",\"1.421\"],[\"29496.90\",\"0.679\"],[\"71637.20\",\"0.002\"],[\"76413.00\",\"0.023\"],[\"78800.90\",\"11.938\"],[\"79525.20\",\"0.002\"],[\"79568.40\",\"0.453\"],[\"79568.90\",\"0.003\"],[\"79576.90\",\"0.002\"],[\"79586.10\",\"0.067\"],[\"79592.80\",\"0.505\"],[\"79592.90\",\"0.002\"],[\"79593.00\",\"0.055\"],[\"79593.10\",\"0.022\"],[\"79593.20\",\"0.076\"]],\"a\":[[\"79597.00\",\"8.421\"],[\"79603.70\",\"0.053\"],[\"79603.90\",\"0.076\"],[\"79613.00\",\"1.250\"],[\"79692.60\",\"0.004\"],[\"80393.00\",\"14.796\"],[\"81188.90\",\"0.040\"]],\"st\":1}}"}
{"receive_ns":1788567778552914000,"stream":"btcusdt@bookTicker","event_type":"bookTicker","event_time_ms":1788567778543,"raw_json":"{\"stream\":\"btcusdt@bookTicker\",\"data\":{\"e\":\"bookTicker\",\"u\":11478511264112,\"s\":\"BTCUSDT\",\"ps\":\"BTCUSDT\",\"b\":\"79596.90\",\"B\":\"7.015\",\"a\":\"79597.00\",\"A\":\"8.423\",\"T\":1788567778543,\"E\":1788567778543,\"st\":1}}"}
{"receive_ns":1788567778599300000,"stream":"btcusdt@bookTicker","event_type":"bookTicker","event_time_ms":1788567778608,"raw_json":"{\"stream\":\"btcusdt@bookTicker\",\"data\":{\"e\":\"bookTicker\",\"u\":11478511266548,\"s\":\"BTCUSDT\",\"ps\":\"BTCUSDT\",\"b\":\"79596.90\",\"B\":\"7.015\",\"a\":\"79597.00\",\"A\":\"8.422\",\"T\":1788567778608,\"E\":1788567778608,\"st\":1}}"}
{"receive_ns":1788567778612320000,"stream":"btcusdt@depth@100ms","event_type":"depthUpdate","event_time_ms":1788567778611,"raw_json":"{\"stream\":\"btcusdt@depth@100ms\",\"data\":{\"e\":\"depthUpdate\",\"E\":1788567778611,\"T\":1788567778609,\"s\":\"BTCUSDT\",\"ps\":\"BTCUSDT\",\"U\":11478511262373,\"u\":11478511266656,\"pu\":11478511262166,\"b\":[[\"29096.90\",\"1.239\"],[\"29496.90\",\"0.861\"],[\"63678.00\",\"0.010\"],[\"71637.20\",\"0.002\"],[\"75617.00\",\"0.023\"],[\"78482.60\",\"12.925\"],[\"78601.90\",\"10.719\"],[\"78800.90\",\"11.939\"],[\"79039.80\",\"0.013\"],[\"79523.40\",\"0.007\"],[\"79525.20\",\"0.000\"],[\"79539.80\",\"0.006\"],[\"79541.10\",\"1.096\"]],\"a\":[[\"79597.00\",\"8.422\"],[\"79617.20\",\"0.002\"],[\"79617.40\",\"0.037\"],[\"79668.70\",\"2.052\"],[\"79692.60\",\"0.002\"],[\"80393.00\",\"15.417\"]],\"st\":1}}"}
{"receive_ns":1788567778703056000,"stream":"btcusdt@depth@100ms","event_type":"depthUpdate","event_time_ms":1788567778713,"raw_json":"{\"stream\":\"btcusdt@depth@100ms\",\"data\":{\"e\":\"depthUpdate\",\"E\":1788567778713,\"T\":1788567778712,\"s\":\"BTCUSDT\",\"ps\":\"BTCUSDT\",\"U\":11478511266954,\"u\":11478511271128,\"pu\":11478511266656,\"b\":[[\"29096.90\",\"1.064\"],[\"29496.90\",\"1.036\"],[\"63678.00\",\"0.010\"],[\"71637.20\",\"0.002\"],[\"75617.10\",\"0.006\"],[\"75617.20\",\"0.010\"],[\"76413.00\",\"0.025\"],[\"78363.10\",\"5.034\"],[\"78800.90\",\"11.937\"],[\"79198.90\",\"3.981\"],[\"79572.10\",\"0.001\"],[\"79573.20\",\"0.536\"],[\"79573.30\",\"0.439\"],[\"79592.80\",\"0.505\"],[\"79593.20\",\"0.000\"],[\"79596.10\",\"0.000\"],[\"79596.40\",\"0.082\"]],\"a\":[[\"79608.90\",\"0.230\"],[\"79610.70\",\"0.545\"],[\"79613.10\",\"0.194\"],[\"79661.80\",\"2.760\"],[\"79663.80\",\"5.057\"],[\"80393.00\",\"15.417\"],[\"80592.00\",\"8.599\"],[\"80830.80\",\"4.820\"],[\"87556.70\",\"0.000\"]],\"st\":1}}"}
{"receive_ns":1788567778785533000,"stream":"btcusdt@bookTicker","event_type":"bookTicker","event_time_ms":1788567778800,"raw_json":"{\"stream\":\"btcusdt@bookTicker\",\"data\":{\"e\":\"bookTicker\",\"u\":11478511274123,\"s\":\"BTCUSDT\",\"ps\":\"BTCUSDT\",\"b\":\"79596.90\",\"B\":\"7.015\",\"a\":\"79597.00\",\"A\":\"8.419\",\"T\":1788567778800,\"E\":1788567778800,\"st\":1}}"}
{"receive_ns":1788567778796480000,"stream":"btcusdt@trade","event_type":"trade","event_time_ms":1788567778800,"raw_json":"{\"stream\":\"btcusdt@trade\",\"data\":{\"e\":\"trade\",\"E\":1788567778800,\"T\":1788567778800,\"s\":\"BTCUSDT\",\"t\":8054122840,\"p\":\"79597.00\",\"q\":\"0.003\",\"X\":\"MARKET\",\"m\":false,\"st\":1}}"}
{"receive_ns":1788567778807467000,"stream":"btcusdt@bookTicker","event_type":"bookTicker","event_time_ms":1788567778814,"raw_json":"{\"stream\":\"btcusdt@bookTicker\",\"data\":{\"e\":\"bookTicker\",\"u\":11478511275127,\"s\":\"BTCUSDT\",\"ps\":\"BTCUSDT\",\"b\":\"79596.90\",\"B\":\"7.015\",\"a\":\"79597.00\",\"A\":\"8.418\",\"T\":1788567778814,\"E\":1788567778814,\"st\":1}}"}
{"receive_ns":1788567778823782000,"stream":"btcusdt@trade","event_type":"trade","event_time_ms":1788567778814,"raw_json":"{\"stream\":\"btcusdt@trade\",\"data\":{\"e\":\"trade\",\"E\":1788567778814,\"T\":1788567778814,\"s\":\"BTCUSDT\",\"t\":8054122841,\"p\":\"79597.00\",\"q\":\"0.001\",\"X\":\"MARKET\",\"m\":false,\"st\":1}}"}
{"receive_ns":1788567778829451000,"stream":"btcusdt@depth@100ms","event_type":"depthUpdate","event_time_ms":1788567778815,"raw_json":"{\"stream\":\"btcusdt@depth@100ms\",\"data\":{\"e\":\"depthUpdate\",\"E\":1788567778815,\"T\":1788567778814,\"s\":\"BTCUSDT\",\"ps\":\"BTCUSDT\",\"U\":11478511271168,\"u\":11478511275127,\"pu\":11478511271128,\"b\":[[\"1000.00\",\"24.604\"],[\"29096.90\",\"0.882\"],[\"29496.90\",\"1.218\"],[\"71637.20\",\"0.002\"],[\"76413.00\",\"0.023\"],[\"78800.90\",\"11.937\"],[\"78960.10\",\"8.589\"],[\"79572.10\",\"0.440\"],[\"79573.30\",\"0.000\"],[\"79592.80\",\"0.505\"],[\"79592.90\",\"0.002\"],[\"79593.00\",\"0.055\"],[\"79593.20\",\"0.000\"],[\"79593.30\",\"0.000\"],[\"79593.40\",\"0.161\"],[\"79593.50\",\"0.003\"]],\"a\":[[\"79597.00\",\"8.418\"],[\"79608.90\",\"0.669\"],[\"79610.70\",\"0.106\"],[\"79624.80\",\"0.102\"],[\"80233.80\",\"7.340\"],[\"80393.00\",\"15.417\"]],\"st\":1}}"}
{"receive_ns":1788567778909216000,"stream":"btcusdt@depth@100ms","event_type":"depthUpdate","event_time_ms":1788567778917,"raw_json":"{\"stream\":\"btcusdt@depth@100ms\",\"data\":{\"e\":\"depthUpdate\",\"E\":1788567778917,\"T\":1788567778915,\"s\":\"BTCUSDT\",\"ps\":\"BTCUSDT\",\"U\":11478511275182,\"u\":11478511281049,\"pu\":11478511275127,\"b\":[[\"29096.90\",\"0.707\"],[\"29496.90\",\"1.393\"],[\"63678.00\",\"0.014\"],[\"71637.20\",\"0.002\"],[\"75617.20\",\"0.008\"],[\"76413.00\",\"0.025\"],[\"78641.70\",\"32.920\"],[\"78720.10\",\"1.268\"],[\"78800.90\",\"11.937\"],[\"79039.70\",\"0.068\"],[\"79593.40\",\"0.161\"],[\"79593.50\",\"0.079\"],[\"79593.60\",\"0.003\"]],\"a\":[[\"80393.00\",\"15.417\"],[\"80711.40\",\"32.039\"],[\"80751.20\",\"11.716\"]],\"st\":1}}"}
{"receive_ns":1788567779009399000,"stream":"btcusdt@depth@100ms","event_type":"depthUpdate","event_time_ms":1788567779019,"raw_json":"{\"stream\":\"btcusdt@depth@100ms\",\"data\":{\"e\":\"depthUpdate\",\"E\":1788567779019,\"T\":1788567779018,\"s\":\"BTCUSDT\",\"ps\":\"BTCUSDT\",\"U\":11478511281126,\"u\":11478511286639,\"pu\":11478511281049,\"b\":[[\"1000.00\",\"24.604\"],[\"29096.90\",\"0.525\"],[\"29496.90\",\"1.575\"],[\"63677.50\",\"0.000\"],[\"63678.00\",\"0.010\"],[\"71637.20\",\"0.002\"],[\"78572.90\",\"0.000\"],[\"78575.30\",\"0.016\"],[\"78607.00\",\"0.000\"],[\"78609.30\",\"0.004\"],[\"78641.70\",\"33.554\"],[\"78800.90\",\"11.937\"],[\"79198.90\",\"3.981\"],[\"79572.10\",\"0.440\"],[\"79573.30\",\"0.000\"],[\"79592.90\",\"0.002\"],[\"79593.00\",\"0.055\"],[\"79593.10\",\"0.022\"],[\"79593.20\",\"0.000\"],[\"79593.30\",\"0.000\"],[\"79593.40\",\"0.161\"],[\"79593.50\",\"0.003\"]],\"a\":[[\"79608.90\",\"0.669\"],[\"79610.70\",\"0.106\"],[\"80393.00\",\"15.417\"],[\"80751.20\",\"12.582\"],[\"80830.80\",\"5.685\"]],\"st\":1}}"}
{"receive_ns":1788567779062995000,"stream":"btcusdt@bookTicker","event_type":"bookTicker","event_time_ms":1788567779074,"raw_json":"{\"stream\":\"btcusdt@bookTicker\",\"data\":{\"e\":\"bookTicker\",\"u\":11478511290278,\"s\":\"BTCUSDT\",\"ps\":\"BTCUSDT\",\"b\":\"79596.90\",\"B\":\"7.015\",\"a\":\"79597.00\",\"A\":\"8.416\",\"T\":1788567779074,\"E\":1788567779074,\"st\":1}}"}
{"receive_ns":1788567779082478000,"stream":"btcusdt@bookTicker","event_type":"bookTicker","event_time_ms":1788567779092,"raw_json":"{\"stream\":\"btcusdt@bookTicker\",\"data\":{\"e\":\"bookTicker\",\"u\":11478511291144,\"s\":\"BTCUSDT\",\"ps\":\"BTCUSDT\",\"b\":\"79596.90\",\"B\":\"7.013\",\"a\":\"79597.00\",\"A\":\"8.416\",\"T\":1788567779092,\"E\":1788567779092,\"st\":1}}"}
{"receive_ns":1788567779095378000,"stream":"btcusdt@bookTicker","event_type":"bookTicker","event_time_ms":1788567779097,"raw_json":"{\"stream\":\"btcusdt@bookTicker\",\"data\":{\"e\":\"bookTicker\",\"u\":11478511291892,\"s\":\"BTCUSDT\",\"ps\":\"BTCUSDT\",\"b\":\"79596.90\",\"B\":\"7.014\",\"a\":\"79597.00\",\"A\":\"8.416\",\"T\":1788567779096,\"E\":1788567779097,\"st\":1}}"}
{"receive_ns":1788567779113096000,"stream":"btcusdt@depth@100ms","event_type":"depthUpdate","event_time_ms":1788567779121,"raw_json":"{\"stream\":\"btcusdt@depth@100ms\",\"data\":{\"e\":\"depthUpdate\",\"E\":1788567779121,\"T\":1788567779119,\"s\":\"BTCUSDT\",\"ps\":\"BTCUSDT\",\"U\":11478511286685,\"u\":11478511293654,\"pu\":11478511286639,\"b\":[[\"1000.00\",\"24.604\"],[\"29096.90\",\"0.350\"],[\"29496.90\",\"1.750\"],[\"63678.00\",\"0.010\"],[\"71637.20\",\"0.002\"],[\"76413.00\",\"0.023\"],[\"78005.00\",\"0.216\"],[\"78482.50\",\"28.755\"],[\"78800.90\",\"11.937\"],[\"78846.80\",\"0.000\"],[\"78960.10\",\"5.428\"],[\"79582.60\",\"0.070\"],[\"79593.20\",\"0.076\"],[\"79593.30\",\"0.000\"],[\"79593.40\",\"0.161\"],[\"79596.80\",\"0.157\"],[\"79596.90\",\"7.014\"]],\"a\":[[\"79597.00\",\"8.416\"],[\"79601.40\",\"0.109\"],[\"80393.00\",\"15.417\"],[\"80711.50\",\"10.784\"],[\"80751.20\",\"13.509\"]],\"st\":1}}"}
{"receive_ns":1788567779128779000,"stream":"btcusdt@bookTicker","event_type":"bookTicker","event_time_ms":1788567779139,"raw_json":"{\"stream\":\"btcusdt@bookTicker\",\"data\":{\"e\":\"bookTicker\",\"u\":11478511294647,\"s\":\"BTCUSDT\",\"ps\":\"BTCUSDT\",\"b\":\"79596.90\",\"B\":\"7.014\",\"a\":\"79597.00\",\"A\":\"8.418\",\"T\":1788567779138,\"E\":1788567779139,\"st\":1}}"}
{"receive_ns":1788567779214520000,"stream":"btcusdt@depth@100ms","event_type":"depthUpdate","event_time_ms":1788567779223,"raw_json":"{\"stream\":\"btcusdt@depth@100ms\",\"data\":{\"e\":\"depthUpdate\",\"E\":1788567779223,\"T\":1788567779221,\"s\":\"BTCUSDT\",\"ps\":\"BTCUSDT\",\"U\":11478511293801,\"u\":11478511299997,\"pu\":11478511293654,\"b\":[[\"29096.90\",\"0.231\"],[\"29396.90\",\"0.063\"],[\"29496.90\",\"1.806\"],[\"71637.20\",\"0.002\"],[\"71673.00\",\"0.000\"],[\"76413.00\",\"0.025\"],[\"78800.90\",\"11.937\"],[\"78960.10\",\"8.589\"],[\"79475.60\",\"0.392\"],[\"79567.80\",\"0.452\"],[\"79568.40\",\"0.001\"],[\"79571.60\",\"0.440\"],[\"79572.10\",\"0.001\"],[\"79574.20\",\"0.374\"],[\"79575.40\",\"0.019\"],[\"79584.30\",\"0.000\"],[\"79584.60\",\"0.348\"],[\"79589.20\",\"0.003\"],[\"79594.30\",\"0.065\"],[\"79594.50\",\"0.026\"],[\"79594.60\",\"0.053\"]],\"a\":[[\"79597.00\",\"8.418\"],[\"79608.90\",\"0.230\"],[\"79610.70\",\"0.545\"],[\"79614.10\",\"0.001\"],[\"79615.20\",\"0.373\"],[\"79615.90\",\"0.000\"],[\"79617.20\",\"0.002\"],[\"79618.50\",\"0.454\"],[\"79618.90\",\"0.012\"],[\"79628.60\",\"0.046\"],[\"79631.70\",\"0.000\"],[\"79718.90\",\"0.370\"],[\"79719.00\",\"0.000\"],[\"79806.10\",\"4.764\"],[\"80393.00\",\"15.417\"],[\"80711.40\",\"33.895\"],[\"80751.20\",\"14.375\"]],\"st\":1}}"}
{"receive_ns":1788567779247127000,"stream":"btcusdt@bookTicker","event_type":"bookTicker","event_time_ms":1788567779258,"raw_json":"{\"stream\":\"btcusdt@bookTicker\",\"data\":{\"e\":\"bookTicker\",\"u\":11478511301789,\"s\":\"BTCUSDT\",\"ps\":\"BTCUSDT\",\"b\":\"79596.90\",\"B\":\"7.014\",\"a\":\"79597.00\",\"A\":\"8.417\",\"T\":1788567779258,\"E\":1788567779258,\"st\":1}}"}
{"receive_ns":1788567779313997000,"stream":"btcusdt@depth@100ms","event_type":"depthUpdate","event_time_ms":1788567779325,"raw_json":"{\"stream\":\"btcusdt@depth@100ms\",\"data\":{\"e\":\"depthUpdate\",\"E\":1788567779325,\"T\":1788567779321,\"s\":\"BTCUSDT\",\"ps\":\"BTCUSDT\",\"U\":11478511300110,\"u\":11478511304567,\"pu\":11478511299997,\"b\":[[\"1000.00\",\"24.604\"],[\"29096.90\",\"0.112\"],[\"29396.90\",\"0.119\"],[\"29496.90\",\"1.869\"],[\"71637.20\",\"0.002\"],[\"76413.00\",\"0.023\"],[\"78005.00\",\"0.213\"],[\"78800.90\",\"11.937\"],[\"78840.70\",\"3.919\"],[\"79198.90\",\"3.970\"],[\"79541.10\",\"1.098\"],[\"79565.70\",\"0.086\"],[\"79580.90\",\"0.001\"]],\"a\":[[\"79597.00\",\"8.417\"],[\"79628.10\",\"0.208\"],[\"79668.70\",\"2.054\"],[\"79995.00\",\"4.696\"],[\"80233.80\",\"7.091\"],[\"80393.00\",\"15.417\"],[\"81572.60\",\"1.285\"]],\"st\":1}}"}
{"receive_ns":1788567779332283000,"stream":"btcusdt@bookTicker","event_type":"bookTicker","event_time_ms":1788567779348,"raw_json":"{\"stream\":\"btcusdt@bookTicker\",\"data\":{\"e\":\"bookTicker\",\"u\":11478511305992,\"s\":\"BTCUSDT\",\"ps\":\"BTCUSDT\",\"b\":\"79596.90\",\"B\":\"7.003\",\"a\":\"79597.00\",\"A\":\"8.417\",\"T\":1788567779347,\"E\":1788567779348,\"st\":1}}"}
{"receive_ns":1788567779338675000,"stream":"btcusdt@bookTicker","event_type":"bookTicker","event_time_ms":1788567779350,"raw_json":"{\"stream\":\"btcusdt@bookTicker\",\"data\":{\"e\":\"bookTicker\",\"u\":11478511306096,\"s\":\"BTCUSDT\",\"ps\":\"BTCUSDT\",\"b\":\"79596.90\",\"B\":\"7.015\",\"a\":\"79597.00\",\"A\":\"8.417\",\"T\":1788567779350,\"E\":1788567779350,\"st\":1}}"}
{"receive_ns":1788567779412176000,"stream":"btcusdt@depth@100ms","event_type":"depthUpdate","event_time_ms":1788567779427,"raw_json":"{\"stream\":\"btcusdt@depth@100ms\",\"data\":{\"e\":\"depthUpdate\",\"E\":1788567779427,\"T\":1788567779426,\"s\":\"BTCUSDT\",\"ps\":\"BTCUSDT\",\"U\":11478511304686,\"u\":11478511309318,\"pu\":11478511304567,\"b\":[[\"1000.00\",\"24.604\"],[\"29096.90\",\"0.007\"],[\"29396.90\",\"0.196\"],[\"29496.90\",\"1.897\"],[\"71637.20\",\"0.002\"],[\"75617.10\",\"0.008\"],[\"76413.00\",\"0.025\"],[\"78161.60\",\"0.010\"],[\"78800.90\",\"11.937\"],[\"79198.90\",\"3.971\"],[\"79475.60\",\"0.487\"],[\"79592.80\",\"0.505\"],[\"79592.90\",\"0.002\"],[\"79593.00\",\"0.055\"],[\"79593.20\",\"0.000\"],[\"79593.30\",\"0.000\"],[\"79593.40\",\"0.237\"],[\"79596.70\",\"0.010\"],[\"79596.90\",\"7.015\"]],\"a\":[[\"79628.10\",\"0.306\"],[\"79718.90\",\"0.471\"],[\"80393.00\",\"15.417\"],[\"81188.90\",\"0.043\"]],\"st\":1}}"}
{"receive_ns":1788567779442316000,"stream":"btcusdt@bookTicker","event_type":"bookTicker","event_time_ms":1788567779452,"raw_json":"{\"stream\":\"btcusdt@bookTicker\",\"data\":{\"e\":\"bookTicker\",\"u\":11478511310592,\"s\":\"BTCUSDT\",\"ps\":\"BTCUSDT\",\"b\":\"79596.90\",\"B\":\"7.015\",\"a\":\"79597.00\",\"A\":\"8.402\",\"T\":1788567779451,\"E\":1788567779452,\"st\":1}}"}
{"receive_ns":1788567779447754000,"stream":"btcusdt@bookTicker","event_type":"bookTicker","event_time_ms":1788567779454,"raw_json":"{\"stream\":\"btcusdt@bookTicker\",\"data\":{\"e\":\"bookTicker\",\"u\":11478511310682,\"s\":\"BTCUSDT\",\"ps\":\"BTCUSDT\",\"b\":\"79596.90\",\"B\":\"7.015\",\"a\":\"79597.00\",\"A\":\"8.415\",\"T\":1788567779454,\"E\":1788567779454,\"st\":1}}"}
{"receive_ns":1788567779519602000,"stream":"btcusdt@depth@100ms","event_type":"depthUpdate","event_time_ms":1788567779529,"raw_json":"{\"stream\":\"btcusdt@depth@100ms\",\"data\":{\"e\":\"depthUpdate\",\"E\":1788567779529,\"T\":1788567779527,\"s\":\"BTCUSDT\",\"ps\":\"BTCUSDT\",\"U\":11478511309334,\"u\":11478511313192,\"pu\":11478511309318,\"b\":[[\"29096.90\",\"0.000\"],[\"29396.90\",\"0.364\"],[\"29496.90\",\"1.736\"],[\"71637.20\",\"0.002\"],[\"75617.20\",\"0.006\"],[\"78214.10\",\"0.511\"],[\"78562.20\",\"14.305\"],[\"78601.90\",\"11.004\"],[\"78800.90\",\"11.939\"],[\"79475.60\",\"0.000\"],[\"79538.10\",\"0.829\"],[\"79554.00\",\"0.751\"],[\"79585.20\",\"0.003\"],[\"79585.40\",\"0.126\"],[\"79593.20\",\"0.076\"],[\"79593.30\",\"0.000\"],[\"79593.40\",\"0.161\"],[\"79593.50\",\"0.003\"]],\"a\":[[\"79597.00\",\"8.415\"],[\"79718.90\",\"0.001\"],[\"79995.00\",\"4.697\"],[\"80393.00\",\"15.417\"]],\"st\":1}}"}
{"receive_ns":1788567779580365000,"stream":"btcusdt@bookTicker","event_type":"bookTicker","event_time_ms":1788567779590,"raw_json":"{\"stream\":\"btcusdt@bookTicker\",\"data\":{\"e\":\"bookTicker\",\"u\":11478511315648,\"s\":\"BTCUSDT\",\"ps\":\"BTCUSDT\",\"b\":\"79596.90\",\"B\":\"7.015\",\"a\":\"79597.00\",\"A\":\"8.406\",\"T\":1788567779590,\"E\":1788567779590,\"st\":1}}"}
{"receive_ns":1788567779591459000,"stream":"btcusdt@trade","event_type":"trade","event_time_ms":1788567779590,"raw_json":"{\"stream\":\"btcusdt@trade\",\"data\":{\"e\":\"trade\",\"E\":1788567779590,\"T\":1788567779590,\"s\":\"BTCUSDT\",\"t\":8054122842,\"p\":\"79597.00\",\"q\":\"0.009\",\"X\":\"MARKET\",\"m\":false,\"st\":1}}"}
{"receive_ns":1788567779603474000,"stream":"btcusdt@bookTicker","event_type":"bookTicker","event_time_ms":1788567779612,"raw_json":"{\"stream\":\"btcusdt@bookTicker\",\"data\":{\"e\":\"bookTicker\",\"u\":11478511318070,\"s\":\"BTCUSDT\",\"ps\":\"BTCUSDT\",\"b\":\"79596.90\",\"B\":\"7.015\",\"a\":\"79597.00\",\"A\":\"8.412\",\"T\":1788567779612,\"E\":1788567779612,\"st\":1}}"}
{"receive_ns":1788567779619526000,"stream":"btcusdt@depth@100ms","event_type":"depthUpdate","event_time_ms":1788567779631,"raw_json":"{\"stream\":\"btcusdt@depth@100ms\",\"data\":{\"e\":\"depthUpdate\",\"E\":1788567779631,\"T\":1788567779629,\"s\":\"BTCUSDT\",\"ps\":\"BTCUSDT\",\"U\":11478511313205,\"u\":11478511318914,\"pu\":11478511313192,\"b\":[[\"1000.00\",\"24.604\"],[\"29396.90\",\"0.546\"],[\"29496.90\",\"1.554\"],[\"63678.00\",\"0.010\"],[\"71637.20\",\"0.002\"],[\"76413.00\",\"0.023\"],[\"78005.00\",\"0.216\"],[\"78077.00\",\"0.384\"],[\"78647.90\",\"15.130\"],[\"78800.90\",\"11.937\"],[\"78960.10\",\"8.588\"],[\"79198.90\",\"3.981\"],[\"79475.60\",\"0.487\"],[\"79576.80\",\"0.330\"],[\"79586.10\",\"0.067\"]],\"a\":[[\"79597.00\",\"8.412\"],[\"79605.40\",\"0.469\"],[\"79606.80\",\"0.255\"],[\"79608.10\",\"0.254\"],[\"79610.60\",\"0.002\"],[\"79718.90\",\"0.471\"],[\"79831.50\",\"17.803\"],[\"79831.60\",\"0.003\"],[\"80233.80\",\"7.090\"],[\"80393.00\",\"15.417\"],[\"80592.10\",\"5.996\"],[\"80659.90\",\"1.238\"]],\"st\":1}}"}
{"receive_ns":1788567779725143000,"stream":"btcusdt@depth@100ms","event_type":"depthUpdate","event_time_ms":1788567779733,"raw_json":"{\"stream\":\"btcusdt@depth@100ms\",\"data\":{\"e\":\"depthUpdate\",\"E\":1788567779733,\"T\":1788567779731,\"s\":\"BTCUSDT\",\"ps\":\"BTCUSDT\",\"U\":11478511319056,\"u\":11478511326590,\"pu\":11478511318914,\"b\":[[\"1000.00\",\"24.604\"],[\"29396.90\",\"0.721\"],[\"29496.90\",\"1.379\"],[\"71637.20\",\"0.002\"],[\"76413.00\",\"0.025\"],[\"78800.90\",\"11.937\"],[\"78880.50\",\"2.156\"],[\"79573.20\",\"0.538\"]],\"a\":[[\"79613.10\",\"0.194\"],[\"80393.00\",\"15.417\"],[\"80552.20\",\"31.213\"],[\"80711.40\",\"32.039\"]],\"st\":1}}"}
{"receive_ns":1788567779747251000,"stream":"btcusdt@bookTicker","event_type":"bookTicker","event_time_ms":1788567779748,"raw_json":"{\"stream\":\"btcusdt@bookTicker\",\"data\":{\"e\":\"bookTicker\",\"u\":11478511327328,\"s\":\"BTCUSDT\",\"ps\":\"BTCUSDT\",\"b\":\"79596.90\",\"B\":\"7.015\",\"a\":\"79597.00\",\"A\":\"8.410\",\"T\":1788567779748,\"E\":1788567779748,\"st\":1}}"}
{"receive_ns":1788567779753069000,"stream":"btcusdt@trade","event_type":"trade","event_time_ms":1788567779748,"raw_json":"{\"stream\":\"btcusdt@trade\",\"data\":{\"e\":\"trade\",\"E\":1788567779748,\"T\":1788567779748,\"s\":\"BTCUSDT\",\"t\":8054122843,\"p\":\"79597.00\",\"q\":\"0.002\",\"X\":\"MARKET\",\"m\":false,\"st\":1}}"}
{"receive_ns":1788567779826098000,"stream":"btcusdt@depth@100ms","event_type":"depthUpdate","event_time_ms":1788567779835,"raw_json":"{\"stream\":\"btcusdt@depth@100ms\",\"data\":{\"e\":\"depthUpdate\",\"E\":1788567779835,\"T\":1788567779833,\"s\":\"BTCUSDT\",\"ps\":\"BTCUSDT\",\"U\":11478511326698,\"u\":11478511330647,\"pu\":11478511326590,\"b\":[[\"29396.90\",\"0.903\"],[\"29496.90\",\"1.197\"],[\"71637.20\",\"0.002\"],[\"76413.00\",\"0.023\"],[\"78442.70\",\"13.405\"],[\"78800.90\",\"11.937\"],[\"79475.60\",\"0.487\"],[\"79507.70\",\"1.321\"],[\"79525.20\",\"0.002\"],[\"79535.50\",\"0.000\"],[\"79541.10\",\"1.096\"],[\"79555.40\",\"1.133\"],[\"79566.60\",\"0.759\"],[\"79596.70\",\"0.026\"]],\"a\":[[\"79597.00\",\"8.410\"],[\"79620.90\",\"0.024\"],[\"79628.10\",\"0.300\"],[\"79643.90\",\"0.013\"],[\"79663.80\",\"1.557\"],[\"79668.70\",\"2.054\"],[\"79691.60\",\"0.000\"],[\"79718.90\",\"0.471\"],[\"80393.00\",\"15.417\"],[\"80966.10\",\"1.001\"]],\"st\":1}}"}
{"receive_ns":1788567779926875000,"stream":"btcusdt@depth@100ms","event_type":"depthUpdate","event_time_ms":1788567779937,"raw_json":"{\"stream\":\"btcusdt@depth@100ms\",\"data\":{\"e\":\"depthUpdate\",\"E\":1788567779937,\"T\":1788567779934,\"s\":\"BTCUSDT\",\"ps\":\"BTCUSDT\",\"U\":11478511330763,\"u\":11478511334862,\"pu\":11478511330647,\"b\":[[\"1000.00\",\"24.604\"],[\"29396.90\",\"1.078\"],[\"29496.90\",\"1.022\"],[\"63678.00\",\"0.010\"],[\"71637.20\",\"0.002\"],[\"78482.60\",\"12.672\"],[\"78800.90\",\"11.937\"],[\"78960.10\",\"8.335\"],[\"79198.90\",\"3.971\"],[\"79467.90\",\"0.001\"],[\"79468.00\",\"0.682\"],[\"79507.60\",\"6.000\"],[\"79535.50\",\"3.500\"],[\"79555.40\",\"1.687\"]],\"a\":[[\"79643.80\",\"1.606\"],[\"79663.70\",\"3.601\"],[\"79691.60\",\"6.000\"],[\"79728.00\",\"1.007\"],[\"79730.50\",\"0.000\"],[\"80393.00\",\"15.417\"],[\"80478.70\",\"8.124\"],[\"80552.20\",\"32.453\"],[\"80711.40\",\"33.895\"],[\"81002.10\",\"0.000\"]],\"st\":1}}"}
{"receive_ns":1788567780012138000,"stream":"btcusdt@bookTicker","event_type":"bookTicker","event_time_ms":1788567780003,"raw_json":"{\"stream\":\"btcusdt@bookTicker\",\"data\":{\"e\":\"bookTicker\",\"u\":11478511339324,\"s\":\"BTCUSDT\",\"ps\":\"BTCUSDT\",\"b\":\"79596.90\",\"B\":\"7.015\",\"a\":\"79597.00\",\"A\":\"8.411\",\"T\":1788567780002,\"E\":1788567780003,\"st\":1}}"}
{"receive_ns":1788567780029606000,"stream":"btcusdt@bookTicker","event_type":"bookTicker","event_time_ms":1788567780011,"raw_json":"{\"stream\":\"btcusdt@bookTicker\",\"data\":{\"e\":\"bookTicker\",\"u\":11478511341146,\"s\":\"BTCUSDT\",\"ps\":\"BTCUSDT\",\"b\":\"79596.90\",\"B\":\"6.968\",\"a\":\"79597.00\",\"A\":\"8.411\",\"T\":1788567780011,\"E\":1788567780011,\"st\":1}}"}
{"receive_ns":1788567780041426000,"stream":"btcusdt@bookTicker","event_type":"bookTicker","event_time_ms":1788567780026,"raw_json":"{\"stream\":\"btcusdt@bookTicker\",\"data\":{\"e\":\"bookTicker\",\"u\":11478511342558,\"s\":\"BTCUSDT\",\"ps\":\"BTCUSDT\",\"b\":\"79596.90\",\"B\":\"6.968\",\"a\":\"79597.00\",\"A\":\"8.413\",\"T\":1788567780026,\"E\":1788567780026,\"st\":1}}"}
{"receive_ns":1788567780051512000,"stream":"btcusdt@bookTicker","event_type":"bookTicker","event_time_ms":1788567780032,"raw_json":"{\"stream\":\"btcusdt@bookTicker\",\"data\":{\"e\":\"bookTicker\",\"u\":11478511343103,\"s\":\"BTCUSDT\",\"ps\":\"BTCUSDT\",\"b\":\"79596.90\",\"B\":\"6.968\",\"a\":\"79597.00\",\"A\":\"8.381\",\"T\":1788567780032,\"E\":1788567780032,\"st\":1}}"}
{"receive_ns":1788567780058068000,"stream":"btcusdt@bookTicker","event_type":"bookTicker","event_time_ms":1788567780032,"raw_json":"{\"stream\":\"btcusdt@bookTicker\",\"data\":{\"e\":\"bookTicker\",\"u\":11478511343122,\"s\":\"BTCUSDT\",\"ps\":\"BTCUSDT\",\"b\":\"79596.90\",\"B\":\"6.968\",\"a\":\"79597.00\",\"A\":\"6.862\",\"T\":1788567780032,\"E\":1788567780032,\"st\":1}}"}
{"receive_ns":1788567780069789000,"stream":"btcusdt@bookTicker","event_type":"bookTicker","event_time_ms":1788567780033,"raw_json":"{\"stream\":\"btcusdt@bookTicker\",\"data\":{\"e\":\"bookTicker\",\"u\":11478511343234,\"s\":\"BTCUSDT\",\"ps\":\"BTCUSDT\",\"b\":\"79596.90\",\"B\":\"6.968\",\"a\":\"79597.00\",\"A\":\"6.859\",\"T\":1788567780033,\"E\":1788567780033,\"st\":1}}"}
{"receive_ns":1788567780080799000,"stream":"btcusdt@bookTicker","event_type":"bookTicker","event_time_ms":1788567780036,"raw_json":"{\"stream\":\"btcusdt@bookTicker\",\"data\":{\"e\":\"bookTicker\",\"u\":11478511343556,\"s\":\"BTCUSDT\",\"ps\":\"BTCUSDT\",\"b\":\"79596.90\",\"B\":\"6.968\",\"a\":\"79597.00\",\"A\":\"6.857\",\"T\":1788567780036,\"E\":1788567780036,\"st\":1}}"}
{"receive_ns":1788567780092406000,"stream":"btcusdt@depth@100ms","event_type":"depthUpdate","event_time_ms":1788567780039,"raw_json":"{\"stream\":\"btcusdt@depth@100ms\",\"data\":{\"e\":\"depthUpdate\",\"E\":1788567780039,\"T\":1788567780037,\"s\":\"BTCUSDT\",\"ps\":\"BTCUSDT\",\"U\":11478511335032,\"u\":11478511343703,\"pu\":11478511334862,\"b\":[[\"1000.00\",\"24.604\"],[\"29396.90\",\"1.253\"],[\"29496.90\",\"0.847\"],[\"63677.50\",\"0.000\"],[\"63678.00\",\"0.010\"],[\"71637.20\",\"0.002\"],[\"76413.00\",\"0.025\"],[\"78671.60\",\"0.000\"],[\"78800.90\",\"11.937\"],[\"79463.10\",\"0.306\"],[\"79475.60\",\"0.425\"],[\"79519.50\",\"0.000\"],[\"79520.30\",\"0.050\"],[\"79565.50\",\"0.000\"],[\"79565.90\",\"0.046\"],[\"79566.60\",\"0.131\"],[\"79567.80\",\"0.000\"],[\"79568.20\",\"0.630\"],[\"79568.90\",\"0.455\"],[\"79570.50\",\"0.002\"],[\"79571.60\",\"0.001\"],[\"79572.10\",\"0.001\"],[\"79572.20\",\"0.629\"],[\"79572.30\",\"0.000\"],[\"79573.30\",\"0.439\"],[\"79574.20\",\"0.001\"],[\"79574.80\",\"0.001\"],[\"79575.30\",\"0.510\"],[\"79575.50\",\"1.624\"],[\"79575.70\",\"0.002\"],[\"79576.10\",\"0.009\"],[\"79576.20\",\"0.875\"],[\"79576.30\",\"0.143\"],[\"79589.00\",\"0.002\"],[\"79589.40\",\"0.003\"],[\"79590.00\",\"0.104\"],[\"79591.50\",\"0.000\"],[\"79592.10\",\"0.004\"],[\"79596.80\",\"0.183\"],[\"79596.90\",\"6.968\"]],\"a\":[[\"79597.00\",\"6.857\"],[\"79598.70\",\"0.004\"],[\"79598.80\",\"0.003\"],[\"79598.90\",\"0.027\"],[\"79599.10\",\"0.104\"],[\"79599.20\",\"0.026\"],[\"79599.30\",\"0.044\"],[\"79599.40\",\"0.026\"],[\"79599.50\",\"0.029\"],[\"79599.60\",\"0.026\"],[\"79599.80\",\"0.027\"],[\"79602.50\",\"0.055\"],[\"79603.70\",\"0.003\"],[\"79604.20\",\"0.007\"],[\"79605.30\",\"0.325\"],[\"79605.40\",\"0.156\"],[\"79605.50\",\"1.554\"],[\"79615.20\",\"0.001\"],[\"79615.30\",\"0.559\"],[\"79620.00\",\"0.773\"],[\"79620.30\",\"0.000\"],[\"79623.40\",\"0.013\"],[\"79624.00\",\"0.633\"],[\"79625.90\",\"0.008\"],[\"79626.30\",\"0.002\"],[\"79628.60\",\"0.000\"],[\"79629.70\",\"0.068\"],[\"79647.00\",\"0.059\"],[\"79647.80\",\"0.141\"],[\"79718.90\",\"0.410\"],[\"80393.00\",\"15.419\"]],\"st\":1}}"}
{"receive_ns":1788567780098688000,"stream":"btcusdt@bookTicker","event_type":"bookTicker","event_time_ms":1788567780042,"raw_json":"{\"stream\":\"btcusdt@bookTicker\",\"data\":{\"e\":\"bookTicker\",\"u\":11478511344284,\"s\":\"BTCUSDT\",\"ps\":\"BTCUSDT\",\"b\":\"79596.90\",\"B\":\"6.968\",\"a\":\"79597.00\",\"A\":\"6.706\",\"T\":1788567780042,\"E\":1788567780042,\"st\":1}}"}
{"receive_ns":1788567780104211000,"stream":"btcusdt@bookTicker","event_type":"bookTicker","event_time_ms":1788567780043,"raw_json":"{\"stream\":\"btcusdt@bookTicker\",\"data\":{\"e\":\"bookTicker\",\"u\":11478511344389,\"s\":\"BTCUSDT\",\"ps\":\"BTCUSDT\",\"b\":\"79596.90\",\"B\":\"6.968\",\"a\":\"79597.00\",\"A\":\"6.704\",\"T\":1788567780043,\"E\":1788567780043,\"st\":1}}"}
{"receive_ns":1788567780119989000,"stream":"btcusdt@bookTicker","event_type":"bookTicker","event_time_ms":1788567780045,"raw_json":"{\"stream\":\"btcusdt@bookTicker\",\"data\":{\"e\":\"bookTicker\",\"u\":11478511344657,\"s\":\"BTCUSDT\",\"ps\":\"BTCUSDT\",\"b\":\"79596.90\",\"B\":\"6.968\",\"a\":\"79597.00\",\"A\":\"6.622\",\"T\":1788567780045,\"E\":1788567780045,\"st\":1}}"}
{"receive_ns":1788567780137603000,"stream":"btcusdt@bookTicker","event_type":"bookTicker","event_time_ms":1788567780048,"raw_json":"{\"stream\":\"btcusdt@bookTicker\",\"data\":{\"e\":\"bookTicker\",\"u\":11478511344906,\"s\":\"BTCUSDT\",\"ps\":\"BTCUSDT\",\"b\":\"79596.90\",\"B\":\"6.968\",\"a\":\"79597.00\",\"A\":\"6.620\",\"T\":1788567780047,\"E\":1788567780048,\"st\":1}}"}
{"receive_ns":1788567780149101000,"stream":"btcusdt@bookTicker","event_type":"bookTicker","event_time_ms":1788567780068,"raw_json":"{\"stream\":\"btcusdt@bookTicker\",\"data\":{\"e\":\"bookTicker\",\"u\":11478511346341,\"s\":\"BTCUSDT\",\"ps\":\"BTCUSDT\",\"b\":\"79596.90\",\"B\":\"6.968\",\"a\":\"79597.00\",\"A\":\"6.621\",\"T\":1788567780068,\"E\":1788567780068,\"st\":1}}"}
{"receive_ns":1788567780154847000,"stream":"btcusdt@bookTicker","event_type":"bookTicker","event_time_ms":1788567780082,"raw_json":"{\"stream\":\"btcusdt@bookTicker\",\"data\":{\"e\":\"bookTicker\",\"u\":11478511347052,\"s\":\"BTCUSDT\",\"ps\":\"BTCUSDT\",\"b\":\"79596.90\",\"B\":\"6.968\",\"a\":\"79597.00\",\"A\":\"6.561\",\"T\":1788567780081,\"E\":1788567780082,\"st\":1}}"}
{"receive_ns":1788567780161629000,"stream":"btcusdt@trade","event_type":"trade","event_time_ms":1788567780082,"raw_json":"{\"stream\":\"btcusdt@trade\",\"data\":{\"e\":\"trade\",\"E\":1788567780082,\"T\":1788567780081,\"s\":\"BTCUSDT\",\"t\":8054122844,\"p\":\"79597.00\",\"q\":\"0.060\",\"X\":\"MARKET\",\"m\":false,\"st\":1}}"}
{"receive_ns":1788567780178968000,"stream":"btcusdt@bookTicker","event_type":"bookTicker","event_time_ms":1788567780083,"raw_json":"{\"stream\":\"btcusdt@bookTicker\",\"data\":{\"e\":\"bookTicker\",\"u\":11478511347128,\"s\":\"BTCUSDT\",\"ps\":\"BTCUSDT\",\"b\":\"79596.90\",\"B\":\"6.968\",\"a\":\"79597.00\",\"A\":\"6.562\",\"T\":1788567780082,\"E\":1788567780083,\"st\":1}}"}
{"receive_ns":1788567780184464000,"stream":"btcusdt@bookTicker","event_type":"bookTicker","event_time_ms":1788567780083,"raw_json":"{\"stream\":\"btcusdt@bookTicker\",\"data\":{\"e\":\"bookTicker\",\"u\":11478511347186,\"s\":\"BTCUSDT\",\"ps\":\"BTCUSDT\",\"b\":\"79596.90\",\"B\":\"6.969\",\"a\":\"79597.00\",\"A\":\"6.562\",\"T\":1788567780083,\"E\":1788567780083,\"st\":1}}"}
{"receive_ns":1788567780197027000,"stream":"btcusdt@bookTicker","event_type":"bookTicker","event_time_ms":1788567780099,"raw_json":"{\"stream\":\"btcusdt@bookTicker\",\"data\":{\"e\":\"bookTicker\",\"u\":11478511348438,\"s\":\"BTCUSDT\",\"ps\":\"BTCUSDT\",\"b\":\"79596.90\",\"B\":\"6.969\",\"a\":\"79597.00\",\"A\":\"6.538\",\"T\":1788567780098,\"E\":1788567780099,\"st\":1}}"}
{"receive_ns":1788567780202461000,"stream":"btcusdt@trade","event_type":"trade","event_time_ms":1788567780099,"raw_json":"{\"stream\":\"btcusdt@trade\",\"data\":{\"e\":\"trade\",\"E\":1788567780099,\"T\":1788567780098,\"s\":\"BTCUSDT\",\"t\":8054122845,\"p\":\"79597.00\",\"q\":\"0.024\",\"X\":\"MARKET\",\"m\":false,\"st\":1}}"}
{"receive_ns":1788567780209075000,"stream":"btcusdt@bookTicker","event_type":"bookTicker","event_time_ms":1788567780100,"raw_json":"{\"stream\":\"btcusdt@bookTicker\",\"data\":{\"e\":\"bookTicker\",\"u\":11478511348535,\"s\":\"BTCUSDT\",\"ps\":\"BTCUSDT\",\"b\":\"79596.90\",\"B\":\"6.969\",\"a\":\"79597.00\",\"A\":\"6.478\",\"T\":1788567780100,\"E\":1788567780100,\"st\":1}}"}
{"receive_ns":1788567780209332000,"stream":"btcusdt@bookTicker","event_type":"bookTicker","event_time_ms":1788567780103,"raw_json":"{\"stream\":\"btcusdt@bookTicker\",\"data\":{\"e\":\"bookTicker\",\"u\":11478511348959,\"s\":\"BTCUSDT\",\"ps\":\"BTCUSDT\",\"b\":\"79596.90\",\"B\":\"6.969\",\"a\":\"79597.00\",\"A\":\"6.534\",\"T\":1788567780102,\"E\":1788567780103,\"st\":1}}"}
{"receive_ns":1788567780215588000,"stream":"btcusdt@bookTicker","event_type":"bookTicker","event_time_ms":1788567780104,"raw_json":"{\"stream\":\"btcusdt@bookTicker\",\"data\":{\"e\":\"bookTicker\",\"u\":11478511349101,\"s\":\"BTCUSDT\",\"ps\":\"BTCUSDT\",\"b\":\"79596.90\",\"B\":\"6.968\",\"a\":\"79597.00\",\"A\":\"6.534\",\"T\":1788567780104,\"E\":1788567780104,\"st\":1}}"}
{"receive_ns":1788567780215811000,"stream":"btcusdt@bookTicker","event_type":"bookTicker","event_time_ms":1788567780104,"raw_json":"{\"stream\":\"btcusdt@bookTicker\",\"data\":{\"e\":\"bookTicker\",\"u\":11478511349111,\"s\":\"BTCUSDT\",\"ps\":\"BTCUSDT\",\"b\":\"79596.90\",\"B\":\"6.968\",\"a\":\"79597.00\",\"A\":\"6.533\",\"T\":1788567780104,\"E\":1788567780104,\"st\":1}}"}
{"receive_ns":1788567780221359000,"stream":"btcusdt@bookTicker","event_type":"bookTicker","event_time_ms":1788567780137,"raw_json":"{\"stream\":\"btcusdt@bookTicker\",\"data\":{\"e\":\"bookTicker\",\"u\":11478511351389,\"s\":\"BTCUSDT\",\"ps\":\"BTCUSDT\",\"b\":\"79596.90\",\"B\":\"6.968\",\"a\":\"79597.00\",\"A\":\"6.538\",\"T\":1788567780137,\"E\":1788567780137,\"st\":1}}"}
{"receive_ns":1788567780221984000,"stream":"btcusdt@depth@100ms","event_type":"depthUpdate","event_time_ms":1788567780141,"raw_json":"{\"stream\":\"btcusdt@depth@100ms\",\"data\":{\"e\":\"depthUpdate\",\"E\":1788567780141,\"T\":1788567780139,\"s\":\"BTCUSDT\",\"ps\":\"BTCUSDT\",\"U\":11478511343867,\"u\":11478511351521,\"pu\":11478511343703,\"b\":[[\"29396.90\",\"1.435\"],[\"29496.90\",\"0.665\"],[\"63678.00\",\"0.010\"],[\"71637.20\",\"0.002\"],[\"76413.00\",\"0.023\"],[\"78005.00\",\"0.219\"],[\"78800.90\",\"11.939\"],[\"79467.90\",\"10.001\"],[\"79495.00\",\"0.157\"],[\"79538.10\",\"0.000\"],[\"79554.00\",\"0.060\"],[\"79562.50\",\"1.893\"],[\"79562.60\",\"0.003\"],[\"79570.60\",\"0.001\"],[\"79572.30\",\"0.439\"],[\"79573.30\",\"0.000\"],[\"79578.90\",\"0.246\"],[\"79582.60\",\"0.070\"],[\"79596.90\",\"6.968\"]],\"a\":[[\"79597.00\",\"6.538\"],[\"79597.10\",\"0.743\"],[\"79597.20\",\"0.250\"],[\"79598.60\",\"0.001\"],[\"79598.80\",\"0.029\"],[\"79598.90\",\"0.001\"],[\"79599.10\",\"0.078\"],[\"79599.20\",\"0.000\"],[\"79599.30\",\"0.044\"],[\"79599.40\",\"0.000\"],[\"79599.90\",\"0.028\"],[\"79600.00\",\"0.075\"],[\"79600.10\",\"0.028\"],[\"79600.20\",\"0.027\"],[\"79600.30\",\"0.002\"],[\"79601.40\",\"0.107\"],[\"79602.50\",\"0.005\"],[\"79605.20\",\"0.166\"],[\"79605.30\",\"0.325\"],[\"79605.50\",\"1.553\"],[\"79605.60\",\"1.892\"],[\"79615.50\",\"0.001\"],[\"79617.20\",\"0.000\"],[\"79617.40\",\"0.035\"],[\"79628.10\",\"0.202\"],[\"79631.40\",\"0.046\"],[\"79693.20\",\"0.000\"],[\"79728.00\",\"2.839\"],[\"79731.40\",\"10.000\"],[\"80393.00\",\"15.417\"],[\"80578.20\",\"0.000\"],[\"80612.80\",\"0.016\"]],\"st\":1}}"}
{"receive_ns":1788567780228708000,"stream":"btcusdt@bookTicker","event_type":"bookTicker","event_time_ms":1788567780141,"raw_json":"{\"stream\":\"btcusdt@bookTicker\",\"data\":{\"e\":\"bookTicker\",\"u\":11478511351683,\"s\":\"BTCUSDT\",\"ps\":\"BTCUSDT\",\"b\":\"79596.90\",\"B\":\"6.968\",\"a\":\"79597.00\",\"A\":\"6.539\",\"T\":1788567780141,\"E\":1788567780141,\"st\":1}}"}
{"receive_ns":1788567780234409000,"stream":"btcusdt@bookTicker","event_type":"bookTicker","event_time_ms":1788567780146,"raw_json":"{\"stream\":\"btcusdt@bookTicker\",\"data\":{\"e\":\"bookTicker\",\"u\":11478511352106,\"s\":\"BTCUSDT\",\"ps\":\"BTCUSDT\",\"b\":\"79596.90\",\"B\":\"6.968\",\"a\":\"79597.00\",\"A\":\"8.058\",\"T\":1788567780146,\"E\":1788567780146,\"st\":1}}"}
{"receive_ns":1788567780245773000,"stream":"btcusdt@bookTicker","event_type":"bookTicker","event_time_ms":1788567780170,"raw_json":"{\"stream\":\"btcusdt@bookTicker\",\"data\":{\"e\":\"bookTicker\",\"u\":11478511354009,\"s\":\"BTCUSDT\",\"ps\":\"BTCUSDT\",\"b\":\"79596.90\",\"B\":\"6.968\",\"a\":\"79597.00\",\"A\":\"8.066\",\"T\":1788567780170,\"E\":1788567780170,\"st\":1}}"}
{"receive_ns":1788567780251158000,"stream":"btcusdt@bookTicker","event_type":"bookTicker","event_time_ms":1788567780171,"raw_json":"{\"stream\":\"btcusdt@bookTicker\",\"data\":{\"e\":\"bookTicker\",\"u\":11478511354010,\"s\":\"BTCUSDT\",\"ps\":\"BTCUSDT\",\"b\":\"79596.90\",\"B\":\"6.970\",\"a\":\"79597.00\",\"A\":\"8.066\",\"T\":1788567780170,\"E\":1788567780171,\"st\":1}}"}
{"receive_ns":1788567780262076000,"stream":"btcusdt@bookTicker","event_type":"bookTicker","event_time_ms":1788567780174,"raw_json":"{\"stream\":\"btcusdt@bookTicker\",\"data\":{\"e\":\"bookTicker\",\"u\":11478511354274,\"s\":\"BTCUSDT\",\"ps\":\"BTCUSDT\",\"b\":\"79596.90\",\"B\":\"6.970\",\"a\":\"79597.00\",\"A\":\"8.224\",\"T\":1788567780174,\"E\":1788567780174,\"st\":1}}"}
{"receive_ns":1788567780267586000,"stream":"btcusdt@bookTicker","event_type":"bookTicker","event_time_ms":1788567780186,"raw_json":"{\"stream\":\"btcusdt@bookTicker\",\"data\":{\"e\":\"bookTicker\",\"u\":11478511355016,\"s\":\"BTCUSDT\",\"ps\":\"BTCUSDT\",\"b\":\"79596.90\",\"B\":\"6.956\",\"a\":\"79597.00\",\"A\":\"8.224\",\"T\":1788567780186,\"E\":1788567780186,\"st\":1}}"}
{"receive_ns":1788567780270664000,"stream":"btcusdt@bookTicker","event_type":"bookTicker","event_time_ms":1788567780189,"raw_json":"{\"stream\":\"btcusdt@bookTicker\",\"data\":{\"e\":\"bookTicker\",\"u\":11478511355248,\"s\":\"BTCUSDT\",\"ps\":\"BTCUSDT\",\"b\":\"79596.90\",\"B\":\"6.969\",\"a\":\"79597.00\",\"A\":\"8.224\",\"T\":1788567780189,\"E\":1788567780189,\"st\":1}}"}
{"receive_ns":1788567780276168000,"stream":"btcusdt@bookTicker","event_type":"bookTicker","event_time_ms":1788567780224,"raw_json":"{\"stream\":\"btcusdt@bookTicker\",\"data\":{\"e\":\"bookTicker\",\"u\":11478511357899,\"s\":\"BTCUSDT\",\"ps\":\"BTCUSDT\",\"b\":\"79596.90\",\"B\":\"6.974\",\"a\":\"79597.00\",\"A\":\"8.224\",\"T\":1788567780223,\"E\":1788567780224,\"st\":1}}"}
{"receive_ns":1788567780287217000,"stream":"btcusdt@bookTicker","event_type":"bookTicker","event_time_ms":1788567780234,"raw_json":"{\"stream\":\"btcusdt@bookTicker\",\"data\":{\"e\":\"bookTicker\",\"u\":11478511358742,\"s\":\"BTCUSDT\",\"ps\":\"BTCUSDT\",\"b\":\"79596.90\",\"B\":\"6.974\",\"a\":\"79597.00\",\"A\":\"8.241\",\"T\":1788567780234,\"E\":1788567780234,\"st\":1}}"}
{"receive_ns":1788567780293231000,"stream":"btcusdt@depth@100ms","event_type":"depthUpdate","event_time_ms":1788567780243,"raw_json":"{\"stream\":\"btcusdt@depth@100ms\",\"data\":{\"e\":\"depthUpdate\",\"E\":1788567780243,\"T\":1788567780242,\"s\":\"BTCUSDT\",\"ps\":\"BTCUSDT\",\"U\":11478511351669,\"u\":11478511359648,\"pu\":11478511351521,\"b\":[[\"1000.00\",\"24.604\"],[\"29396.90\",\"1.617\"],[\"29496.90\",\"0.483\"],[\"71637.20\",\"0.002\"],[\"71637.30\",\"0.041\"],[\"76413.00\",\"0.025\"],[\"78383.90\",\"0.005\"],[\"78384.20\",\"0.000\"],[\"78800.90\",\"12.571\"],[\"79198.90\",\"3.971\"],[\"79566.60\",\"0.125\"],[\"79568.40\",\"0.453\"],[\"79568.90\",\"0.003\"],[\"79575.40\",\"0.059\"],[\"79578.90\",\"0.206\"],[\"79593.20\",\"0.000\"],[\"79596.90\",\"6.974\"]],\"a\":[[\"79597.00\",\"8.241\"],[\"79598.20\",\"0.002\"],[\"79598.30\",\"0.002\"],[\"79598.40\",\"0.007\"],[\"79598.60\",\"0.279\"],[\"79600.20\",\"0.001\"],[\"79601.20\",\"0.002\"],[\"79602.70\",\"0.306\"],[\"79603.10\",\"0.004\"],[\"79604.00\",\"0.125\"],[\"79604.20\",\"0.008\"],[\"79605.20\",\"0.116\"],[\"79605.60\",\"1.891\"],[\"79608.90\",\"0.669\"],[\"79610.70\",\"0.106\"],[\"79691.90\",\"0.061\"],[\"79692.00\",\"1.357\"],[\"79701.80\",\"0.000\"],[\"80393.00\",\"15.417\"],[\"80844.80\",\"0.003\"],[\"80845.10\",\"0.000\"]],\"st\":1}}"}
{"receive_ns":1788567780299187000,"stream":"btcusdt@bookTicker","event_type":"bookTicker","event_time_ms":1788567780285,"raw_json":"{\"stream\":\"btcusdt@bookTicker\",\"data\":{\"e\":\"bookTicker\",\"u\":11478511363744,\"s\":\"BTCUSDT\",\"ps\":\"BTCUSDT\",\"b\":\"79596.90\",\"B\":\"6.974\",\"a\":\"79597.00\",\"A\":\"8.243\",\"T\":1788567780285,\"E\":1788567780285,\"st\":1}}"}
{"receive_ns":1788567780333776000,"stream":"btcusdt@depth@100ms","event_type":"depthUpdate","event_time_ms":1788567780345,"raw_json":"{\"stream\":\"btcusdt@depth@100ms\",\"data\":{\"e\":\"depthUpdate\",\"E\":1788567780345,\"T\":1788567780341,\"s\":\"BTCUSDT\",\"ps\":\"BTCUSDT\",\"U\":11478511359861,\"u\":11478511368437,\"pu\":11478511359648,\"b\":[[\"1000.00\",\"24.604\"],[\"29296.90\",\"0.014\"],[\"29396.90\",\"1.764\"],[\"29496.90\",\"0.322\"],[\"71637.20\",\"0.002\"],[\"71673.00\",\"0.000\"],[\"76413.00\",\"0.023\"],[\"76506.60\",\"0.004\"],[\"78005.00\",\"0.222\"],[\"78107.20\",\"0.000\"],[\"78467.30\",\"0.000\"],[\"78482.50\",\"29.009\"],[\"78623.70\",\"0.000\"],[\"78665.60\",\"1.772\"],[\"78766.10\",\"0.000\"],[\"78800.90\",\"12.571\"],[\"78895.80\",\"0.000\"],[\"79013.90\",\"0.000\"],[\"79140.00\",\"0.089\"],[\"79216.40\",\"2.255\"],[\"79308.40\",\"0.000\"],[\"79323.70\",\"0.000\"],[\"79388.30\",\"0.001\"],[\"79389.40\",\"0.000\"],[\"79395.90\",\"0.002\"],[\"79405.00\",\"0.951\"],[\"79437.70\",\"0.028\"],[\"79438.60\",\"0.002\"],[\"79463.20\",\"0.000\"],[\"79530.30\",\"0.001\"],[\"79562.50\",\"1.891\"],[\"79562.60\",\"0.001\"],[\"79580.90\",\"0.003\"],[\"79592.80\",\"0.581\"]],\"a\":[[\"79597.00\",\"8.243\"],[\"79866.40\",\"0.002\"],[\"79897.00\",\"0.908\"],[\"79930.60\",\"0.002\"],[\"79967.70\",\"0.019\"],[\"80008.40\",\"0.002\"],[\"80053.20\",\"0.002\"],[\"80102.60\",\"0.002\"],[\"80156.90\",\"0.005\"],[\"80216.60\",\"0.002\"],[\"80282.50\",\"0.192\"],[\"80354.90\",\"0.029\"],[\"80393.00\",\"15.417\"],[\"80434.70\",\"0.005\"],[\"80522.50\",\"0.005\"],[\"80619.30\",\"0.003\"],[\"80725.80\",\"0.002\"],[\"80773.20\",\"0.000\"],[\"80843.20\",\"0.003\"],[\"80972.50\",\"0.006\"],[\"81115.00\",\"0.002\"],[\"81272.00\",\"0.003\"]],\"st\":1}}"}
{"receive_ns":1788567780340507000,"stream":"btcusdt@bookTicker","event_type":"bookTicker","event_time_ms":1788567780350,"raw_json":"{\"stream\":\"btcusdt@bookTicker\",\"data\":{\"e\":\"bookTicker\",\"u\":11478511369033,\"s\":\"BTCUSDT\",\"ps\":\"BTCUSDT\",\"b\":\"79596.90\",\"B\":\"6.955\",\"a\":\"79597.00\",\"A\":\"8.243\",\"T\":1788567780350,\"E\":1788567780350,\"st\":1}}"}
{"receive_ns":1788567780351728000,"stream":"btcusdt@bookTicker","event_type":"bookTicker","event_time_ms":1788567780353,"raw_json":"{\"stream\":\"btcusdt@bookTicker\",\"data\":{\"e\":\"bookTicker\",\"u\":11478511369320,\"s\":\"BTCUSDT\",\"ps\":\"BTCUSDT\",\"b\":\"79596.90\",\"B\":\"6.978\",\"a\":\"79597.00\",\"A\":\"8.243\",\"T\":1788567780353,\"E\":1788567780353,\"st\":1}}"}
{"receive_ns":1788567780362191000,"stream":"btcusdt@bookTicker","event_type":"bookTicker","event_time_ms":1788567780373,"raw_json":"{\"stream\":\"btcusdt@bookTicker\",\"data\":{\"e\":\"bookTicker\",\"u\":11478511370982,\"s\":\"BTCUSDT\",\"ps\":\"BTCUSDT\",\"b\":\"79596.90\",\"B\":\"6.978\",\"a\":\"79597.00\",\"A\":\"8.190\",\"T\":1788567780373,\"E\":1788567780373,\"st\":1}}"}
{"receive_ns":1788567780379666000,"stream":"btcusdt@trade","event_type":"trade","event_time_ms":1788567780373,"raw_json":"{\"stream\":\"btcusdt@trade\",\"data\":{\"e\":\"trade\",\"E\":1788567780373,\"T\":1788567780373,\"s\":\"BTCUSDT\",\"t\":8054122846,\"p\":\"79597.00\",\"q\":\"0.053\",\"X\":\"MARKET\",\"m\":false,\"st\":1}}"}
{"receive_ns":1788567780435743000,"stream":"btcusdt@depth@100ms","event_type":"depthUpdate","event_time_ms":1788567780447,"raw_json":"{\"stream\":\"btcusdt@depth@100ms\",\"data\":{\"e\":\"depthUpdate\",\"E\":1788567780447,\"T\":1788567780446,\"s\":\"BTCUSDT\",\"ps\":\"BTCUSDT\",\"U\":11478511368660,\"u\":11478511376115,\"pu\":11478511368437,\"b\":[[\"29296.90\",\"0.077\"],[\"29396.90\",\"1.820\"],[\"29496.90\",\"0.203\"],[\"63678.00\",\"0.012\"],[\"71637.20\",\"0.002\"],[\"78800.90\",\"12.571\"],[\"79198.90\",\"3.970\"],[\"79421.80\",\"0.020\"],[\"79589.70\",\"1.358\"],[\"79590.00\",\"0.116\"],[\"79596.90\",\"6.978\"]],\"a\":[[\"79597.00\",\"8.190\"],[\"79598.60\",\"0.001\"],[\"79598.80\",\"0.003\"],[\"79598.90\",\"0.001\"],[\"79599.00\",\"0.002\"],[\"79599.10\",\"0.104\"],[\"79599.20\",\"0.026\"],[\"79599.30\",\"0.018\"],[\"79601.20\",\"0.000\"],[\"79605.00\",\"0.017\"],[\"79605.30\",\"0.317\"],[\"79605.40\",\"0.148\"],[\"79626.70\",\"0.045\"],[\"80393.00\",\"15.417\"]],\"st\":1}}"}
{"receive_ns":1788567780448835000,"stream":"btcusdt@bookTicker","event_type":"bookTicker","event_time_ms":1788567780459,"raw_json":"{\"stream\":\"btcusdt@bookTicker\",\"data\":{\"e\":\"bookTicker\",\"u\":11478511376845,\"s\":\"BTCUSDT\",\"ps\":\"BTCUSDT\",\"b\":\"79596.90\",\"B\":\"6.978\",\"a\":\"79597.00\",\"A\":\"8.177\",\"T\":1788567780458,\"E\":1788567780459,\"st\":1}}"}
{"receive_ns":1788567780461150000,"stream":"btcusdt@bookTicker","event_type":"bookTicker","event_time_ms":1788567780461,"raw_json":"{\"stream\":\"btcusdt@bookTicker\",\"data\":{\"e\":\"bookTicker\",\"u\":11478511377220,\"s\":\"BTCUSDT\",\"ps\":\"BTCUSDT\",\"b\":\"79596.90\",\"B\":\"6.978\",\"a\":\"79597.00\",\"A\":\"8.187\",\"T\":1788567780461,\"E\":1788567780461,\"st\":1}}"}
{"receive_ns":1788567780537353000,"stream":"btcusdt@depth@100ms","event_type":"depthUpdate","event_time_ms":1788567780549,"raw_json":"{\"stream\":\"btcusdt@depth@100ms\",\"data\":{\"e\":\"depthUpdate\",\"E\":1788567780549,\"T\":1788567780546,\"s\":\"BTCUSDT\",\"ps\":\"BTCUSDT\",\"U\":11478511376180,\"u\":11478511396151,\"pu\":11478511376115,\"b\":[[\"1000.00\",\"24.604\"],[\"29296.90\",\"0.133\"],[\"29396.90\",\"1.883\"],[\"29496.90\",\"0.084\"],[\"63678.00\",\"0.010\"],[\"71637.20\",\"0.002\"],[\"76413.00\",\"0.025\"],[\"78800.90\",\"12.571\"],[\"79198.90\",\"3.971\"],[\"79357.20\",\"0.512\"],[\"79538.00\",\"0.830\"],[\"79554.00\",\"0.751\"],[\"79554.70\",\"0.035\"],[\"79554.80\",\"0.230\"],[\"79576.90\",\"0.006\"],[\"79577.00\",\"0.001\"],[\"79586.10\",\"0.063\"],[\"79592.10\",\"0.000\"],[\"79592.20\",\"0.004\"],[\"79596.30\",\"0.026\"],[\"79596.80\",\"0.183\"]],\"a\":[[\"79597.00\",\"8.187\"],[\"79597.40\",\"0.031\"],[\"79597.90\",\"0.028\"],[\"79598.40\",\"0.259\"],[\"79598.60\",\"0.027\"],[\"79598.70\",\"0.004\"],[\"79598.80\",\"0.003\"],[\"79600.10\",\"0.002\"],[\"79605.00\",\"0.079\"],[\"79605.40\",\"0.086\"],[\"79611.40\",\"0.005\"],[\"79612.20\",\"0.695\"],[\"79612.30\",\"0.000\"],[\"79618.20\",\"0.456\"],[\"79618.50\",\"0.002\"],[\"79628.00\",\"1.821\"],[\"79628.10\",\"0.830\"],[\"79995.00\",\"4.697\"],[\"80393.00\",\"15.417\"],[\"80558.30\",\"8.252\"],[\"80617.60\",\"2.417\"],[\"80709.60\",\"0.720\"]],\"st\":1}}"}
{"receive_ns":1788567780642645000,"stream":"btcusdt@depth@100ms","event_type":"depthUpdate","event_time_ms":1788567780651,"raw_json":"{\"stream\":\"btcusdt@depth@100ms\",\"data\":{\"e\":\"depthUpdate\",\"E\":1788567780651,\"T\":1788567780649,\"s\":\"BTCUSDT\",\"ps\":\"BTCUSDT\",\"U\":11478511396671,\"u\":11478511404882,\"pu\":11478511396151,\"b\":[[\"1000.00\",\"24.604\"],[\"29296.90\",\"0.231\"],[\"29396.90\",\"1.869\"],[\"29496.90\",\"0.000\"],[\"63678.00\",\"0.010\"],[\"71637.20\",\"0.002\"],[\"75617.10\",\"0.006\"],[\"75617.20\",\"0.008\"],[\"76413.00\",\"0.023\"],[\"78800.90\",\"12.571\"],[\"79576.90\",\"0.002\"],[\"79584.60\",\"0.351\"],[\"79586.10\",\"0.067\"]],\"a\":[[\"79597.40\",\"0.005\"],[\"79617.30\",\"0.068\"],[\"80393.00\",\"15.417\"],[\"80552.20\",\"33.693\"],[\"80703.40\",\"5.075\"],[\"80767.10\",\"5.248\"]],\"st\":1}}"}
{"receive_ns":1788567780662141000,"stream":"btcusdt@bookTicker","event_type":"bookTicker","event_time_ms":1788567780668,"raw_json":"{\"stream\":\"btcusdt@bookTicker\",\"data\":{\"e\":\"bookTicker\",\"u\":11478511406087,\"s\":\"BTCUSDT\",\"ps\":\"BTCUSDT\",\"b\":\"79596.90\",\"B\":\"6.978\",\"a\":\"79597.00\",\"A\":\"8.189\",\"T\":1788567780667,\"E\":1788567780668,\"st\":1}}"}
{"receive_ns":1788567780717421000,"stream":"btcusdt@bookTicker","event_type":"bookTicker","event_time_ms":1788567780728,"raw_json":"{\"stream\":\"btcusdt@bookTicker\",\"data\":{\"e\":\"bookTicker\",\"u\":11478511410482,\"s\":\"BTCUSDT\",\"ps\":\"BTCUSDT\",\"b\":\"79596.90\",\"B\":\"6.978\",\"a\":\"79597.00\",\"A\":\"8.187\",\"T\":1788567780728,\"E\":1788567780728,\"st\":1}}"}
{"receive_ns":1788567780726854000,"stream":"btcusdt@trade","event_type":"trade","event_time_ms":1788567780728,"raw_json":"{\"stream\":\"btcusdt@trade\",\"data\":{\"e\":\"trade\",\"E\":1788567780728,\"T\":1788567780728,\"s\":\"BTCUSDT\",\"t\":8054122847,\"p\":\"79597.00\",\"q\":\"0.002\",\"X\":\"MARKET\",\"m\":false,\"st\":1}}"}
{"receive_ns":1788567780738101000,"stream":"btcusdt@depth@100ms","event_type":"depthUpdate","event_time_ms":1788567780753,"raw_json":"{\"stream\":\"btcusdt@depth@100ms\",\"data\":{\"e\":\"depthUpdate\",\"E\":1788567780753,\"T\":1788567780752,\"s\":\"BTCUSDT\",\"ps\":\"BTCUSDT\",\"U\":11478511405018,\"u\":11478511411938,\"pu\":11478511404882,\"b\":[[\"29296.90\",\"0.406\"],[\"29396.90\",\"1.694\"],[\"71637.20\",\"0.002\"],[\"76413.00\",\"0.025\"],[\"78800.90\",\"12.571\"],[\"79198.90\",\"3.981\"],[\"79475.60\",\"0.441\"],[\"79564.80\",\"1.057\"],[\"79565.90\",\"0.000\"],[\"79567.80\",\"0.452\"],[\"79568.40\",\"0.001\"],[\"79571.60\",\"0.001\"],[\"79572.30\",\"0.000\"],[\"79573.20\",\"0.538\"],[\"79573.30\",\"0.439\"],[\"79574.20\",\"0.001\"],[\"79575.30\",\"0.137\"],[\"79575.50\",\"1.997\"],[\"79576.30\",\"0.137\"],[\"79576.80\",\"0.336\"],[\"79576.90\",\"0.002\"],[\"79586.10\",\"0.067\"],[\"79593.90\",\"0.000\"],[\"79594.20\",\"0.252\"]],\"a\":[[\"79597.00\",\"8.187\"],[\"79597.40\",\"0.005\"],[\"79597.90\",\"0.002\"],[\"79598.20\",\"0.028\"],[\"79598.30\",\"0.002\"],[\"79598.40\",\"0.259\"],[\"79598.50\",\"0.000\"],[\"79598.60\",\"0.027\"],[\"79599.30\",\"0.044\"],[\"79608.90\",\"0.230\"],[\"79610.70\",\"0.545\"],[\"79613.10\",\"0.194\"],[\"79614.10\",\"0.001\"],[\"79614.40\",\"0.020\"],[\"79615.30\",\"0.187\"],[\"79615.40\",\"0.376\"],[\"79617.20\",\"0.000\"],[\"79618.20\",\"0.004\"],[\"79618.50\",\"0.454\"],[\"79620.90\",\"0.002\"],[\"79625.90\",\"0.002\"],[\"79626.30\",\"0.008\"],[\"79718.90\",\"0.428\"],[\"80393.00\",\"15.417\"],[\"81188.90\",\"0.040\"],[\"87556.70\",\"0.000\"]],\"st\":1}}"}
{"receive_ns":1788567780771046000,"stream":"btcusdt@bookTicker","event_type":"bookTicker","event_time_ms":1788567780790,"raw_json":"{\"stream\":\"btcusdt@bookTicker\",\"data\":{\"e\":\"bookTicker\",\"u\":11478511413693,\"s\":\"BTCUSDT\",\"ps\":\"BTCUSDT\",\"b\":\"79596.90\",\"B\":\"6.998\",\"a\":\"79597.00\",\"A\":\"8.187\",\"T\":1788567780790,\"E\":1788567780790,\"st\":1}}"}
{"receive_ns":1788567780845758000,"stream":"btcusdt@depth@100ms","event_type":"depthUpdate","event_time_ms":1788567780855,"raw_json":"{\"stream\":\"btcusdt@depth@100ms\",\"data\":{\"e\":\"depthUpdate\",\"E\":1788567780855,\"T\":1788567780853,\"s\":\"BTCUSDT\",\"ps\":\"BTCUSDT\",\"U\":11478511411989,\"u\":11478511418426,\"pu\":11478511411938,\"b\":[[\"1000.00\",\"24.604\"],[\"29296.90\",\"0.588\"],[\"29396.90\",\"1.512\"],[\"71637.20\",\"0.002\"],[\"78800.90\",\"12.571\"],[\"79572.30\",\"0.439\"],[\"79573.30\",\"0.000\"],[\"79576.90\",\"0.006\"],[\"79581.90\",\"0.323\"],[\"79585.10\",\"0.062\"],[\"79585.30\",\"0.000\"],[\"79586.10\",\"0.001\"],[\"79596.90\",\"6.998\"]],\"a\":[[\"79597.90\",\"0.002\"],[\"79598.00\",\"0.081\"],[\"79598.10\",\"0.000\"],[\"79598.20\",\"0.002\"],[\"80393.00\",\"15.417\"],[\"80910.40\",\"1.728\"]],\"st\":1}}"}
{"receive_ns":1788567780951453000,"stream":"btcusdt@depth@100ms","event_type":"depthUpdate","event_time_ms":1788567780957,"raw_json":"{\"stream\":\"btcusdt@depth@100ms\",\"data\":{\"e\":\"depthUpdate\",\"E\":1788567780957,\"T\":1788567780955,\"s\":\"BTCUSDT\",\"ps\":\"BTCUSDT\",\"U\":11478511418500,\"u\":11478511425244,\"pu\":11478511418426,\"b\":[[\"1000.00\",\"24.604\"],[\"29296.90\",\"0.763\"],[\"29396.90\",\"1.337\"],[\"34000.00\",\"0.975\"],[\"71637.20\",\"0.002\"],[\"76413.00\",\"0.023\"],[\"78800.90\",\"12.571\"]],\"a\":[[\"79597.70\",\"0.000\"],[\"79597.80\",\"0.005\"],[\"80393.00\",\"15.417\"],[\"80711.40\",\"34.142\"],[\"81586.90\",\"0.857\"]],\"st\":1}}"}
{"receive_ns":1788567781049821000,"stream":"btcusdt@depth@100ms","event_type":"depthUpdate","event_time_ms":1788567781059,"raw_json":"{\"stream\":\"btcusdt@depth@100ms\",\"data\":{\"e\":\"depthUpdate\",\"E\":1788567781059,\"T\":1788567781058,\"s\":\"BTCUSDT\",\"ps\":\"BTCUSDT\",\"U\":11478511425416,\"u\":11478511431879,\"pu\":11478511425244,\"b\":[[\"29296.90\",\"0.945\"],[\"29396.90\",\"1.155\"],[\"63677.50\",\"0.000\"],[\"67255.00\",\"0.143\"],[\"71637.20\",\"0.002\"],[\"76413.00\",\"0.025\"],[\"78232.40\",\"0.009\"],[\"78800.90\",\"12.571\"],[\"79198.90\",\"3.981\"],[\"79564.80\",\"1.011\"],[\"79565.90\",\"0.046\"],[\"79572.20\",\"0.001\"],[\"79572.30\",\"0.000\"],[\"79572.40\",\"0.631\"],[\"79572.50\",\"0.705\"],[\"79575.30\",\"0.510\"],[\"79575.50\",\"1.624\"],[\"79576.20\",\"0.247\"],[\"79576.40\",\"3.525\"],[\"79582.60\",\"0.070\"]],\"a\":[[\"79597.50\",\"0.014\"],[\"79597.60\",\"0.091\"],[\"79597.70\",\"0.000\"],[\"79604.90\",\"0.009\"],[\"79605.00\",\"0.001\"],[\"79605.30\",\"0.004\"],[\"79605.40\",\"0.469\"],[\"79615.20\",\"0.373\"],[\"79615.40\",\"0.004\"],[\"79616.10\",\"0.009\"],[\"79616.30\",\"1.269\"],[\"79620.00\",\"0.146\"],[\"79620.30\",\"0.627\"],[\"79624.00\",\"0.006\"],[\"79624.20\",\"0.628\"],[\"79804.90\",\"1.026\"],[\"79806.10\",\"4.763\"],[\"79819.00\",\"0.002\"],[\"79819.10\",\"7.003\"],[\"80233.80\",\"7.339\"],[\"80393.00\",\"15.417\"]],\"st\":1}}"}
{"receive_ns":1788567781075269000,"stream":"btcusdt@bookTicker","event_type":"bookTicker","event_time_ms":1788567781085,"raw_json":"{\"stream\":\"btcusdt@bookTicker\",\"data\":{\"e\":\"bookTicker\",\"u\":11478511433307,\"s\":\"BTCUSDT\",\"ps\":\"BTCUSDT\",\"b\":\"79596.90\",\"B\":\"6.998\",\"a\":\"79597.00\",\"A\":\"8.186\",\"T\":1788567781085,\"E\":1788567781085,\"st\":1}}"}
{"receive_ns":1788567781151214000,"stream":"btcusdt@depth@100ms","event_type":"depthUpdate","event_time_ms":1788567781161,"raw_json":"{\"stream\":\"btcusdt@depth@100ms\",\"data\":{\"e\":\"depthUpdate\",\"E\":1788567781161,\"T\":1788567781160,\"s\":\"BTCUSDT\",\"ps\":\"BTCUSDT\",\"U\":11478511431954,\"u\":11478511437933,\"pu\":11478511431879,\"b\":[[\"1000.00\",\"24.604\"],[\"29296.90\",\"1.120\"],[\"29396.90\",\"0.980\"],[\"71637.20\",\"0.002\"],[\"75617.00\",\"0.026\"],[\"76413.00\",\"0.023\"],[\"78800.90\",\"12.571\"],[\"79525.20\",\"0.000\"],[\"79541.10\",\"1.098\"],[\"79564.90\",\"0.000\"],[\"79565.90\",\"0.000\"],[\"79566.10\",\"0.049\"],[\"79572.10\",\"0.001\"],[\"79572.50\",\"0.705\"],[\"79573.30\",\"0.000\"],[\"79574.30\",\"0.001\"],[\"79575.30\",\"0.137\"],[\"79575.40\",\"0.432\"],[\"79593.90\",\"0.000\"],[\"79594.00\",\"0.000\"],[\"79594.10\",\"0.002\"],[\"79594.20\",\"0.252\"]],\"a\":[[\"79597.00\",\"8.186\"],[\"79597.40\",\"0.005\"],[\"79597.50\",\"0.014\"],[\"79597.60\",\"0.091\"],[\"79597.70\",\"0.000\"],[\"79597.90\",\"0.002\"],[\"79598.00\",\"0.081\"],[\"79598.10\",\"0.000\"],[\"79598.20\",\"0.002\"],[\"79598.30\",\"0.002\"],[\"79598.60\",\"0.001\"],[\"79598.70\",\"0.030\"],[\"79598.90\",\"0.027\"],[\"79600.00\",\"0.049\"],[\"79604.90\",\"0.001\"],[\"79605.30\",\"0.012\"],[\"79608.30\",\"0.001\"],[\"79610.70\",\"0.545\"],[\"79614.20\",\"0.001\"],[\"79615.20\",\"0.001\"],[\"79615.30\",\"0.559\"],[\"79628.80\",\"0.000\"],[\"79629.70\",\"0.022\"],[\"79629.80\",\"0.048\"],[\"79657.50\",\"0.012\"],[\"79668.70\",\"2.054\"],[\"80393.00\",\"15.417\"],[\"80910.40\",\"2.592\"]],\"st\":1}}"}
{"receive_ns":1788567781249054000,"stream":"btcusdt@depth@100ms","event_type":"depthUpdate","event_time_ms":1788567781263,"raw_json":"{\"stream\":\"btcusdt@depth@100ms\",\"data\":{\"e\":\"depthUpdate\",\"E\":1788567781263,\"T\":1788567781261,\"s\":\"BTCUSDT\",\"ps\":\"BTCUSDT\",\"U\":11478511438050,\"u\":11478511443965,\"pu\":11478511437933,\"b\":[[\"1000.00\",\"24.604\"],[\"29296.90\",\"1.302\"],[\"29396.90\",\"0.798\"],[\"71637.20\",\"0.002\"],[\"76413.00\",\"0.025\"],[\"77168.40\",\"1.955\"],[\"77964.00\",\"2.416\"],[\"78227.80\",\"2.042\"],[\"78562.10\",\"8.865\"],[\"78800.90\",\"12.571\"],[\"79198.90\",\"3.981\"],[\"79475.60\",\"0.519\"]],\"a\":[[\"79597.70\",\"0.000\"],[\"79597.90\",\"0.002\"],[\"79598.00\",\"0.081\"],[\"79598.40\",\"0.259\"],[\"79598.50\",\"0.026\"],[\"79599.90\",\"0.002\"],[\"79657.50\",\"0.019\"],[\"79691.70\",\"0.001\"],[\"79692.80\",\"0.001\"],[\"79701.50\",\"0.343\"],[\"79718.90\",\"0.471\"],[\"80393.00\",\"15.417\"]],\"st\":1}}"}
{"receive_ns":1788567781309910000,"stream":"btcusdt@bookTicker","event_type":"bookTicker","event_time_ms":1788567781321,"raw_json":"{\"stream\":\"btcusdt@bookTicker\",\"data\":{\"e\":\"bookTicker\",\"u\":11478511453033,\"s\":\"BTCUSDT\",\"ps\":\"BTCUSDT\",\"b\":\"79596.90\",\"B\":\"6.998\",\"a\":\"79597.00\",\"A\":\"8.175\",\"T\":1788567781321,\"E\":1788567781321,\"st\":1}}"}
{"receive_ns":1788567781315563000,"stream":"btcusdt@bookTicker","event_type":"bookTicker","event_time_ms":1788567781329,"raw_json":"{\"stream\":\"btcusdt@bookTicker\",\"data\":{\"e\":\"bookTicker\",\"u\":11478511453754,\"s\":\"BTCUSDT\",\"ps\":\"BTCUSDT\",\"b\":\"79596.90\",\"B\":\"6.998\",\"a\":\"79597.00\",\"A\":\"8.168\",\"T\":1788567781329,\"E\":1788567781329,\"st\":1}}"}
{"receive_ns":1788567781315772000,"stream":"btcusdt@trade","event_type":"trade","event_time_ms":1788567781329,"raw_json":"{\"stream\":\"btcusdt@trade\",\"data\":{\"e\":\"trade\",\"E\":1788567781329,\"T\":1788567781329,\"s\":\"BTCUSDT\",\"t\":8054122848,\"p\":\"79597.00\",\"q\":\"0.007\",\"X\":\"MARKET\",\"m\":false,\"st\":1}}"}
{"receive_ns":1788567781348827000,"stream":"btcusdt@bookTicker","event_type":"bookTicker","event_time_ms":1788567781358,"raw_json":"{\"stream\":\"btcusdt@bookTicker\",\"data\":{\"e\":\"bookTicker\",\"u\":11478511456996,\"s\":\"BTCUSDT\",\"ps\":\"BTCUSDT\",\"b\":\"79596.90\",\"B\":\"6.975\",\"a\":\"79597.00\",\"A\":\"8.168\",\"T\":1788567781358,\"E\":1788567781358,\"st\":1}}"}
{"receive_ns":1788567781349143000,"stream":"btcusdt@bookTicker","event_type":"bookTicker","event_time_ms":1788567781361,"raw_json":"{\"stream\":\"btcusdt@bookTicker\",\"data\":{\"e\":\"bookTicker\",\"u\":11478511457233,\"s\":\"BTCUSDT\",\"ps\":\"BTCUSDT\",\"b\":\"79596.90\",\"B\":\"6.995\",\"a\":\"79597.00\",\"A\":\"8.168\",\"T\":1788567781361,\"E\":1788567781361,\"st\":1}}"}
{"receive_ns":1788567781349662000,"stream":"btcusdt@depth@100ms","event_type":"depthUpdate","event_time_ms":1788567781365,"raw_json":"{\"stream\":\"btcusdt@depth@100ms\",\"data\":{\"e\":\"depthUpdate\",\"E\":1788567781365,\"T\":1788567781363,\"s\":\"BTCUSDT\",\"ps\":\"BTCUSDT\",\"U\":11478511444405,\"u\":11478511457494,\"pu\":11478511443965,\"b\":[[\"29296.90\",\"1.477\"],[\"29396.90\",\"0.623\"],[\"63678.00\",\"0.010\"],[\"71637.20\",\"0.002\"],[\"71673.00\",\"0.000\"],[\"75577.30\",\"3.000\"],[\"76372.90\",\"2.023\"],[\"78609.30\",\"0.000\"],[\"78613.80\",\"0.025\"],[\"78800.90\",\"12.571\"],[\"79198.90\",\"3.971\"],[\"79525.20\",\"0.002\"],[\"79533.20\",\"1.148\"],[\"79564.90\",\"0.000\"],[\"79566.10\",\"0.049\"],[\"79572.10\",\"0.001\"],[\"79572.50\",\"0.266\"],[\"79573.30\",\"0.439\"],[\"79574.30\",\"0.374\"],[\"79575.40\",\"0.059\"],[\"79594.00\",\"0.076\"],[\"79594.40\",\"0.000\"],[\"79596.90\",\"6.995\"]],\"a\":[[\"79597.00\",\"8.168\"],[\"79598.50\",\"0.000\"],[\"79598.70\",\"0.004\"],[\"79598.90\",\"0.027\"],[\"79599.90\",\"0.028\"],[\"79600.00\",\"0.075\"],[\"79608.30\",\"0.001\"],[\"79610.70\",\"0.545\"],[\"79614.20\",\"0.001\"],[\"79615.30\",\"0.187\"],[\"79615.40\",\"0.376\"],[\"79628.80\",\"0.000\"],[\"79629.80\",\"0.002\"],[\"79629.90\",\"0.047\"],[\"79644.80\",\"0.272\"],[\"79692.60\",\"0.004\"],[\"80393.00\",\"15.417\"],[\"80671.60\",\"6.519\"]],\"st\":1}}"}
{"receive_ns":1788567781398881000,"stream":"btcusdt@bookTicker","event_type":"bookTicker","event_time_ms":1788567781412,"raw_json":"{\"stream\":\"btcusdt@bookTicker\",\"data\":{\"e\":\"bookTicker\",\"u\":11478511461231,\"s\":\"BTCUSDT\",\"ps\":\"BTCUSDT\",\"b\":\"79596.90\",\"B\":\"6.995\",\"a\":\"79597.00\",\"A\":\"8.159\",\"T\":1788567781412,\"E\":1788567781412,\"st\":1}}"}
{"receive_ns":1788567781405365000,"stream":"btcusdt@bookTicker","event_type":"bookTicker","event_time_ms":1788567781415,"raw_json":"{\"stream\":\"btcusdt@bookTicker\",\"data\":{\"e\":\"bookTicker\",\"u\":11478511461461,\"s\":\"BTCUSDT\",\"ps\":\"BTCUSDT\",\"b\":\"79596.90\",\"B\":\"6.982\",\"a\":\"79597.00\",\"A\":\"8.159\",\"T\":1788567781415,\"E\":1788567781415,\"st\":1}}"}
{"receive_ns":1788567781416125000,"stream":"btcusdt@bookTicker","event_type":"bookTicker","event_time_ms":1788567781418,"raw_json":"{\"stream\":\"btcusdt@bookTicker\",\"data\":{\"e\":\"bookTicker\",\"u\":11478511461608,\"s\":\"BTCUSDT\",\"ps\":\"BTCUSDT\",\"b\":\"79596.90\",\"B\":\"6.996\",\"a\":\"79597.00\",\"A\":\"8.159\",\"T\":1788567781418,\"E\":1788567781418,\"st\":1}}"}
{"receive_ns":1788567781461261000,"stream":"btcusdt@bookTicker","event_type":"bookTicker","event_time_ms":1788567781454,"raw_json":"{\"stream\":\"btcusdt@bookTicker\",\"data\":{\"e\":\"bookTicker\",\"u\":11478511463572,\"s\":\"BTCUSDT\",\"ps\":\"BTCUSDT\",\"b\":\"79596.90\",\"B\":\"6.984\",\"a\":\"79597.00\",\"A\":\"8.159\",\"T\":1788567781454,\"E\":1788567781454,\"st\":1}}"}
{"receive_ns":1788567781467890000,"stream":"btcusdt@bookTicker","event_type":"bookTicker","event_time_ms":1788567781458,"raw_json":"{\"stream\":\"btcusdt@bookTicker\",\"data\":{\"e\":\"bookTicker\",\"u\":11478511464848,\"s\":\"BTCUSDT\",\"ps\":\"BTCUSDT\",\"b\":\"79596.90\",\"B\":\"6.993\",\"a\":\"79597.00\",\"A\":\"8.159\",\"T\":1788567781458,\"E\":1788567781458,\"st\":1}}"}
{"receive_ns":1788567781480193000,"stream":"btcusdt@depth@100ms","event_type":"depthUpdate","event_time_ms":1788567781467,"raw_json":"{\"stream\":\"btcusdt@depth@100ms\",\"data\":{\"e\":\"depthUpdate\",\"E\":1788567781467,\"T\":1788567781465,\"s\":\"BTCUSDT\",\"ps\":\"BTCUSDT\",\"U\":11478511457772,\"u\":11478511465923,\"pu\":11478511457494,\"b\":[[\"1000.00\",\"24.604\"],[\"29296.90\",\"1.659\"],[\"29396.90\",\"0.441\"],[\"71637.20\",\"0.002\"],[\"74781.80\",\"4.070\"],[\"76413.00\",\"0.023\"],[\"78641.70\",\"34.824\"],[\"78800.90\",\"12.571\"],[\"78960.10\",\"8.335\"],[\"79198.90\",\"3.970\"],[\"79468.00\",\"2.088\"],[\"79475.60\",\"0.519\"],[\"79572.50\",\"0.705\"],[\"79573.30\",\"0.000\"],[\"79579.80\",\"0.046\"],[\"79584.60\",\"0.348\"],[\"79596.90\",\"6.993\"]],\"a\":[[\"79597.00\",\"8.159\"],[\"79598.60\",\"0.001\"],[\"79598.70\",\"0.004\"],[\"79598.90\",\"0.027\"],[\"79600.00\",\"0.075\"],[\"79718.90\",\"0.471\"],[\"79995.00\",\"4.696\"],[\"80393.00\",\"14.175\"],[\"80592.00\",\"8.748\"],[\"80727.40\",\"1.192\"]],\"st\":1}}"}
{"receive_ns":1788567781497437000,"stream":"btcusdt@bookTicker","event_type":"bookTicker","event_time_ms":1788567781507,"raw_json":"{\"stream\":\"btcusdt@bookTicker\",\"data\":{\"e\":\"bookTicker\",\"u\":11478511469485,\"s\":\"BTCUSDT\",\"ps\":\"BTCUSDT\",\"b\":\"79596.90\",\"B\":\"6.993\",\"a\":\"79597.00\",\"A\":\"8.169\",\"T\":1788567781507,\"E\":1788567781507,\"st\":1}}"}
{"receive_ns":1788567781562250000,"stream":"btcusdt@depth@100ms","event_type":"depthUpdate","event_time_ms":1788567781569,"raw_json":"{\"stream\":\"btcusdt@depth@100ms\",\"data\":{\"e\":\"depthUpdate\",\"E\":1788567781569,\"T\":1788567781568,\"s\":\"BTCUSDT\",\"ps\":\"BTCUSDT\",\"U\":11478511466114,\"u\":11478511474796,\"pu\":11478511465923,\"b\":[[\"1000.00\",\"24.604\"],[\"29196.90\",\"0.028\"],[\"29296.90\",\"1.778\"],[\"29396.90\",\"0.294\"],[\"71637.20\",\"0.002\"],[\"76413.00\",\"0.025\"],[\"78164.00\",\"1.114\"],[\"78508.50\",\"5.952\"],[\"78800.90\",\"12.571\"],[\"78960.10\",\"8.588\"],[\"79198.90\",\"3.971\"],[\"79539.80\",\"0.000\"],[\"79548.80\",\"0.007\"],[\"79567.80\",\"0.000\"],[\"79568.90\",\"0.455\"],[\"79576.30\",\"0.143\"],[\"79576.80\",\"0.330\"],[\"79594.00\",\"0.000\"]],\"a\":[[\"79597.00\",\"8.169\"],[\"79597.90\",\"0.002\"],[\"79598.10\",\"0.026\"],[\"79598.30\",\"0.002\"],[\"79598.40\",\"0.285\"],[\"79598.50\",\"0.000\"],[\"79598.60\",\"0.027\"],[\"79598.70\",\"0.004\"],[\"79598.80\",\"0.029\"],[\"79598.90\",\"0.001\"],[\"79599.10\",\"0.078\"],[\"79599.20\",\"0.026\"],[\"79599.30\",\"0.018\"],[\"79599.50\",\"0.003\"],[\"79599.60\",\"0.026\"],[\"79599.80\",\"0.001\"],[\"79599.90\",\"0.002\"],[\"79600.10\",\"0.028\"],[\"79600.20\",\"0.027\"],[\"79600.30\",\"0.002\"],[\"79600.40\",\"0.008\"],[\"79600.60\",\"0.000\"],[\"79600.70\",\"0.004\"],[\"79600.80\",\"0.008\"],[\"79607.20\",\"0.255\"],[\"79608.10\",\"0.003\"],[\"79637.00\",\"0.127\"],[\"79643.60\",\"0.253\"],[\"79995.00\",\"4.697\"],[\"80393.00\",\"14.175\"],[\"80830.80\",\"4.820\"],[\"81013.80\",\"0.615\"],[\"83576.90\",\"0.005\"]],\"st\":1}}"}
{"receive_ns":1788567781766021000,"stream":"btcusdt@depth@100ms","event_type":"depthUpdate","event_time_ms":1788567781671,"raw_json":"{\"stream\":\"btcusdt@depth@100ms\",\"data\":{\"e\":\"depthUpdate\",\"E\":1788567781671,\"T\":1788567781670,\"s\":\"BTCUSDT\",\"ps\":\"BTCUSDT\",\"U\":11478511474871,\"u\":11478511480188,\"pu\":11478511474796,\"b\":[[\"29196.90\",\"0.091\"],[\"29296.90\",\"1.834\"],[\"29396.90\",\"0.175\"],[\"63678.00\",\"0.010\"],[\"71637.20\",\"0.004\"],[\"76413.00\",\"0.023\"],[\"78562.20\",\"14.051\"],[\"78800.90\",\"12.571\"],[\"79198.90\",\"3.971\"],[\"79495.00\",\"0.150\"],[\"79564.90\",\"0.046\"],[\"79566.10\",\"0.003\"],[\"79567.80\",\"0.452\"],[\"79568.90\",\"0.003\"],[\"79594.00\",\"0.076\"]],\"a\":[[\"79597.90\",\"0.002\"],[\"79598.10\",\"0.000\"],[\"79598.40\",\"0.259\"],[\"79598.60\",\"0.001\"],[\"79598.80\",\"0.003\"],[\"79599.40\",\"0.026\"],[\"79600.30\",\"0.028\"],[\"79600.40\",\"0.034\"],[\"79608.30\",\"0.440\"],[\"79610.70\",\"0.106\"],[\"79617.30\",\"0.520\"],[\"79618.50\",\"0.002\"],[\"80393.00\",\"14.175\"],[\"80472.60\",\"7.447\"],[\"81188.90\",\"0.043\"]],\"st\":1}}"}
{"receive_ns":1788567781777279000,"stream":"btcusdt@bookTicker","event_type":"bookTicker","event_time_ms":1788567781753,"raw_json":"{\"stream\":\"btcusdt@bookTicker\",\"data\":{\"e\":\"bookTicker\",\"u\":11478511485669,\"s\":\"BTCUSDT\",\"ps\":\"BTCUSDT\",\"b\":\"79596.90\",\"B\":\"6.993\",\"a\":\"79597.00\",\"A\":\"8.167\",\"T\":1788567781752,\"E\":1788567781753,\"st\":1}}"}
{"receive_ns":1788567781794379000,"stream":"btcusdt@trade","event_type":"trade","event_time_ms":1788567781753,"raw_json":"{\"stream\":\"btcusdt@trade\",\"data\":{\"e\":\"trade\",\"E\":1788567781753,\"T\":1788567781752,\"s\":\"BTCUSDT\",\"t\":8054122849,\"p\":\"79597.00\",\"q\":\"0.002\",\"X\":\"MARKET\",\"m\":false,\"st\":1}}"}
{"receive_ns":1788567781805505000,"stream":"btcusdt@depth@100ms","event_type":"depthUpdate","event_time_ms":1788567781773,"raw_json":"{\"stream\":\"btcusdt@depth@100ms\",\"data\":{\"e\":\"depthUpdate\",\"E\":1788567781773,\"T\":1788567781769,\"s\":\"BTCUSDT\",\"ps\":\"BTCUSDT\",\"U\":11478511480215,\"u\":11478511486966,\"pu\":11478511480188,\"b\":[[\"1000.00\",\"24.604\"],[\"29196.90\",\"0.147\"],[\"29296.90\",\"1.897\"],[\"29396.90\",\"0.056\"],[\"63678.00\",\"0.010\"],[\"71637.20\",\"0.002\"],[\"76413.00\",\"0.025\"],[\"78482.50\",\"29.262\"],[\"78488.70\",\"14.686\"],[\"78800.90\",\"12.571\"],[\"78807.10\",\"2.162\"],[\"79377.20\",\"0.724\"],[\"79565.80\",\"0.000\"],[\"79572.60\",\"0.125\"],[\"79572.80\",\"0.000\"],[\"79573.20\",\"0.536\"],[\"79573.60\",\"0.000\"]],\"a\":[[\"79597.00\",\"8.167\"],[\"79599.20\",\"0.000\"],[\"79599.40\",\"0.000\"],[\"79600.60\",\"0.026\"],[\"79600.70\",\"0.030\"],[\"79608.30\",\"0.001\"],[\"79610.70\",\"0.545\"],[\"79613.10\",\"0.192\"],[\"79617.30\",\"0.068\"],[\"79618.50\",\"0.454\"],[\"80393.00\",\"14.175\"],[\"80830.80\",\"5.685\"]],\"st\":1}}"}
{"receive_ns":1788567781828296000,"stream":"btcusdt@bookTicker","event_type":"bookTicker","event_time_ms":1788567781834,"raw_json":"{\"stream\":\"btcusdt@bookTicker\",\"data\":{\"e\":\"bookTicker\",\"u\":11478511491787,\"s\":\"BTCUSDT\",\"ps\":\"BTCUSDT\",\"b\":\"79596.90\",\"B\":\"6.993\",\"a\":\"79597.00\",\"A\":\"8.149\",\"T\":1788567781833,\"E\":1788567781834,\"st\":1}}"}
{"receive_ns":1788567781828519000,"stream":"btcusdt@trade","event_type":"trade","event_time_ms":1788567781834,"raw_json":"{\"stream\":\"btcusdt@trade\",\"data\":{\"e\":\"trade\",\"E\":1788567781834,\"T\":1788567781833,\"s\":\"BTCUSDT\",\"t\":8054122850,\"p\":\"79597.00\",\"q\":\"0.007\",\"X\":\"MARKET\",\"m\":false,\"st\":1}}"}
{"receive_ns":1788567781828695000,"stream":"btcusdt@trade","event_type":"trade","event_time_ms":1788567781834,"raw_json":"{\"stream\":\"btcusdt@trade\",\"data\":{\"e\":\"trade\",\"E\":1788567781834,\"T\":1788567781833,\"s\":\"BTCUSDT\",\"t\":8054122851,\"p\":\"79597.00\",\"q\":\"0.011\",\"X\":\"MARKET\",\"m\":false,\"st\":1}}"}
{"receive_ns":1788567781841828000,"stream":"btcusdt@bookTicker","event_type":"bookTicker","event_time_ms":1788567781843,"raw_json":"{\"stream\":\"btcusdt@bookTicker\",\"data\":{\"e\":\"bookTicker\",\"u\":11478511492484,\"s\":\"BTCUSDT\",\"ps\":\"BTCUSDT\",\"b\":\"79596.90\",\"B\":\"6.993\",\"a\":\"79597.00\",\"A\":\"8.148\",\"T\":1788567781843,\"E\":1788567781843,\"st\":1}}"}
{"receive_ns":1788567781862254000,"stream":"btcusdt@depth@100ms","event_type":"depthUpdate","event_time_ms":1788567781875,"raw_json":"{\"stream\":\"btcusdt@depth@100ms\",\"data\":{\"e\":\"depthUpdate\",\"E\":1788567781875,\"T\":1788567781874,\"s\":\"BTCUSDT\",\"ps\":\"BTCUSDT\",\"U\":11478511487294,\"u\":11478511494841,\"pu\":11478511486966,\"b\":[[\"1000.00\",\"24.604\"],[\"29196.90\",\"0.273\"],[\"29296.90\",\"1.827\"],[\"29396.90\",\"0.000\"],[\"63678.00\",\"0.010\"],[\"71637.20\",\"0.002\"],[\"75617.20\",\"0.006\"],[\"78800.90\",\"12.571\"],[\"79572.60\",\"0.125\"],[\"79573.20\",\"0.538\"]],\"a\":[[\"79597.00\",\"8.148\"],[\"79597.10\",\"0.742\"],[\"79599.40\",\"0.026\"],[\"79613.10\",\"0.194\"],[\"79636.30\",\"0.221\"],[\"79636.40\",\"0.154\"],[\"79636.90\",\"0.064\"],[\"79637.00\",\"0.002\"],[\"80393.00\",\"14.175\"]],\"st\":1}}"}
{"receive_ns":1788567781967495000,"stream":"btcusdt@depth@100ms","event_type":"depthUpdate","event_time_ms":1788567781977,"raw_json":"{\"stream\":\"btcusdt@depth@100ms\",\"data\":{\"e\":\"depthUpdate\",\"E\":1788567781977,\"T\":1788567781974,\"s\":\"BTCUSDT\",\"ps\":\"BTCUSDT\",\"U\":11478511494948,\"u\":11478511501643,\"pu\":11478511494841,\"b\":[[\"29196.90\",\"0.448\"],[\"29296.90\",\"1.652\"],[\"63678.00\",\"0.012\"],[\"71637.20\",\"0.002\"],[\"76413.00\",\"0.023\"],[\"77831.70\",\"0.217\"],[\"78005.00\",\"0.219\"],[\"78402.00\",\"0.001\"],[\"78800.90\",\"12.571\"],[\"79198.90\",\"3.981\"],[\"79507.70\",\"1.328\"]],\"a\":[[\"79599.40\",\"0.000\"],[\"79608.30\",\"0.001\"],[\"79610.70\",\"0.545\"],[\"79636.80\",\"0.144\"],[\"79636.90\",\"0.064\"],[\"79637.30\",\"0.137\"],[\"79819.10\",\"6.997\"],[\"80393.00\",\"14.175\"]],\"st\":1}}"}
{"receive_ns":1788567781985548000,"stream":"btcusdt@bookTicker","event_type":"bookTicker","event_time_ms":1788567781996,"raw_json":"{\"stream\":\"btcusdt@bookTicker\",\"data\":{\"e\":\"bookTicker\",\"u\":11478511503000,\"s\":\"BTCUSDT\",\"ps\":\"BTCUSDT\",\"b\":\"79596.90\",\"B\":\"6.993\",\"a\":\"79597.00\",\"A\":\"8.165\",\"T\":1788567781996,\"E\":1788567781996,\"st\":1}}"}
{"receive_ns":1788567782005528000,"stream":"btcusdt@bookTicker","event_type":"bookTicker","event_time_ms":1788567782021,"raw_json":"{\"stream\":\"btcusdt@bookTicker\",\"data\":{\"e\":\"bookTicker\",\"u\":11478511504653,\"s\":\"BTCUSDT\",\"ps\":\"BTCUSDT\",\"b\":\"79596.90\",\"B\":\"6.981\",\"a\":\"79597.00\",\"A\":\"8.165\",\"T\":1788567782021,\"E\":1788567782021,\"st\":1}}"}
{"receive_ns":1788567782017572000,"stream":"btcusdt@bookTicker","event_type":"bookTicker","event_time_ms":1788567782022,"raw_json":"{\"stream\":\"btcusdt@bookTicker\",\"data\":{\"e\":\"bookTicker\",\"u\":11478511504732,\"s\":\"BTCUSDT\",\"ps\":\"BTCUSDT\",\"b\":\"79596.90\",\"B\":\"6.980\",\"a\":\"79597.00\",\"A\":\"8.165\",\"T\":1788567782022,\"E\":1788567782022,\"st\":1}}"}
{"receive_ns":1788567782029545000,"stream":"btcusdt@bookTicker","event_type":"bookTicker","event_time_ms":1788567782023,"raw_json":"{\"stream\":\"btcusdt@bookTicker\",\"data\":{\"e\":\"bookTicker\",\"u\":11478511504800,\"s\":\"BTCUSDT\",\"ps\":\"BTCUSDT\",\"b\":\"79596.90\",\"B\":\"6.981\",\"a\":\"79597.00\",\"A\":\"8.165\",\"T\":1788567782023,\"E\":1788567782023,\"st\":1}}"}
{"receive_ns":1788567782041461000,"stream":"btcusdt@bookTicker","event_type":"bookTicker","event_time_ms":1788567782025,"raw_json":"{\"stream\":\"btcusdt@bookTicker\",\"data\":{\"e\":\"bookTicker\",\"u\":11478511504910,\"s\":\"BTCUSDT\",\"ps\":\"BTCUSDT\",\"b\":\"79596.90\",\"B\":\"6.993\",\"a\":\"79597.00\",\"A\":\"8.165\",\"T\":1788567782025,\"E\":1788567782025,\"st\":1}}"}
{"receive_ns":1788567782074631000,"stream":"btcusdt@bookTicker","event_type":"bookTicker","event_time_ms":1788567782070,"raw_json":"{\"stream\":\"btcusdt@bookTicker\",\"data\":{\"e\":\"bookTicker\",\"u\":11478511508363,\"s\":\"BTCUSDT\",\"ps\":\"BTCUSDT\",\"b\":\"79596.90\",\"B\":\"6.979\",\"a\":\"79597.00\",\"A\":\"8.165\",\"T\":1788567782070,\"E\":1788567782070,\"st\":1}}"}
{"receive_ns":1788567782092169000,"stream":"btcusdt@bookTicker","event_type":"bookTicker","event_time_ms":1788567782074,"raw_json":"{\"stream\":\"btcusdt@bookTicker\",\"data\":{\"e\":\"bookTicker\",\"u\":11478511508506,\"s\":\"BTCUSDT\",\"ps\":\"BTCUSDT\",\"b\":\"79596.90\",\"B\":\"6.991\",\"a\":\"79597.00\",\"A\":\"8.165\",\"T\":1788567782073,\"E\":1788567782074,\"st\":1}}"}
{"receive_ns":1788567782106465000,"stream":"btcusdt@depth@100ms","event_type":"depthUpdate","event_time_ms":1788567782079,"raw_json":"{\"stream\":\"btcusdt@depth@100ms\",\"data\":{\"e\":\"depthUpdate\",\"E\":1788567782079,\"T\":1788567782077,\"s\":\"BTCUSDT\",\"ps\":\"BTCUSDT\",\"U\":11478511501820,\"u\":11478511508722,\"pu\":11478511501643,\"b\":[[\"1000.00\",\"24.604\"],[\"29196.90\",\"0.630\"],[\"29296.90\",\"1.470\"],[\"63677.50\",\"0.000\"],[\"63678.00\",\"0.010\"],[\"71637.20\",\"0.002\"],[\"76413.00\",\"0.025\"],[\"78589.90\",\"0.000\"],[\"78599.30\",\"2.545\"],[\"78602.00\",\"10.227\"],[\"78800.90\",\"12.571\"],[\"79564.90\",\"0.000\"],[\"79565.80\",\"0.046\"],[\"79574.30\",\"0.001\"],[\"79575.40\",\"0.432\"],[\"79582.60\",\"0.070\"],[\"79594.00\",\"0.000\"],[\"79596.90\",\"6.991\"]],\"a\":[[\"79597.00\",\"8.165\"],[\"79599.10\",\"0.104\"],[\"79599.50\",\"0.029\"],[\"79605.00\",\"0.392\"],[\"79605.30\",\"0.004\"],[\"79605.40\",\"0.086\"],[\"79624.20\",\"0.001\"],[\"79624.40\",\"0.627\"],[\"79637.30\",\"0.012\"],[\"79637.50\",\"0.000\"],[\"80393.00\",\"14.175\"]],\"st\":1}}"}
{"receive_ns":1788567782106791000,"stream":"btcusdt@bookTicker","event_type":"bookTicker","event_time_ms":1788567782086,"raw_json":"{\"stream\":\"btcusdt@bookTicker\",\"data\":{\"e\":\"bookTicker\",\"u\":11478511509832,\"s\":\"BTCUSDT\",\"ps\":\"BTCUSDT\",\"b\":\"79596.90\",\"B\":\"6.983\",\"a\":\"79597.00\",\"A\":\"8.165\",\"T\":1788567782086,\"E\":1788567782086,\"st\":1}}"}
{"receive_ns":1788567782118466000,"stream":"btcusdt@bookTicker","event_type":"bookTicker","event_time_ms":1788567782089,"raw_json":"{\"stream\":\"btcusdt@bookTicker\",\"data\":{\"e\":\"bookTicker\",\"u\":11478511510145,\"s\":\"BTCUSDT\",\"ps\":\"BTCUSDT\",\"b\":\"79596.90\",\"B\":\"6.990\",\"a\":\"79597.00\",\"A\":\"8.165\",\"T\":1788567782089,\"E\":1788567782089,\"st\":1}}"}
{"receive_ns":1788567782129487000,"stream":"btcusdt@bookTicker","event_type":"bookTicker","event_time_ms":1788567782106,"raw_json":"{\"stream\":\"btcusdt@bookTicker\",\"data\":{\"e\":\"bookTicker\",\"u\":11478511511267,\"s\":\"BTCUSDT\",\"ps\":\"BTCUSDT\",\"b\":\"79596.90\",\"B\":\"6.989\",\"a\":\"79597.00\",\"A\":\"8.165\",\"T\":1788567782106,\"E\":1788567782106,\"st\":1}}"}
{"receive_ns":1788567782135299000,"stream":"btcusdt@trade","event_type":"trade","event_time_ms":1788567782106,"raw_json":"{\"stream\":\"btcusdt@trade\",\"data\":{\"e\":\"trade\",\"E\":1788567782106,\"T\":1788567782106,\"s\":\"BTCUSDT\",\"t\":8054122852,\"p\":\"79596.90\",\"q\":\"0.001\",\"X\":\"MARKET\",\"m\":true,\"st\":1}}"}
{"receive_ns":1788567782147375000,"stream":"btcusdt@bookTicker","event_type":"bookTicker","event_time_ms":1788567782107,"raw_json":"{\"stream\":\"btcusdt@bookTicker\",\"data\":{\"e\":\"bookTicker\",\"u\":11478511511392,\"s\":\"BTCUSDT\",\"ps\":\"BTCUSDT\",\"b\":\"79596.90\",\"B\":\"6.988\",\"a\":\"79597.00\",\"A\":\"8.165\",\"T\":1788567782107,\"E\":1788567782107,\"st\":1}}"}
{"receive_ns":1788567782161897000,"stream":"btcusdt@bookTicker","event_type":"bookTicker","event_time_ms":1788567782108,"raw_json":"{\"stream\":\"btcusdt@bookTicker\",\"data\":{\"e\":\"bookTicker\",\"u\":11478511511433,\"s\":\"BTCUSDT\",\"ps\":\"BTCUSDT\",\"b\":\"79596.90\",\"B\":\"6.978\",\"a\":\"79597.00\",\"A\":\"8.165\",\"T\":1788567782108,\"E\":1788567782108,\"st\":1}}"}
{"receive_ns":1788567782168848000,"stream":"btcusdt@depth@100ms","event_type":"depthUpdate","event_time_ms":1788567782181,"raw_json":"{\"stream\":\"btcusdt@depth@100ms\",\"data\":{\"e\":\"depthUpdate\",\"E\":1788567782181,\"T\":1788567782177,\"s\":\"BTCUSDT\",\"ps\":\"BTCUSDT\",\"U\":11478511509177,\"u\":11478511514959,\"pu\":11478511508722,\"b\":[[\"1000.00\",\"24.604\"],[\"29196.90\",\"0.805\"],[\"29296.90\",\"1.295\"],[\"63678.00\",\"0.010\"],[\"71637.20\",\"0.002\"],[\"75617.10\",\"0.006\"],[\"75617.20\",\"0.008\"],[\"76413.00\",\"0.023\"],[\"78522.40\",\"11.355\"],[\"78602.00\",\"10.036\"],[\"78800.90\",\"12.571\"],[\"79473.40\",\"0.001\"],[\"79473.50\",\"0.029\"],[\"79495.00\",\"0.156\"],[\"79596.90\",\"6.978\"]],\"a\":[[\"79598.90\",\"0.027\"],[\"79600.70\",\"0.004\"],[\"79604.90\",\"0.001\"],[\"79605.00\",\"0.017\"],[\"79605.30\",\"0.379\"],[\"79605.40\",\"0.086\"],[\"79637.50\",\"0.125\"],[\"79692.70\",\"0.004\"],[\"80393.00\",\"14.175\"]],\"st\":1}}"}
{"receive_ns":1788567782273970000,"stream":"btcusdt@depth@100ms","event_type":"depthUpdate","event_time_ms":1788567782283,"raw_json":"{\"stream\":\"btcusdt@depth@100ms\",\"data\":{\"e\":\"depthUpdate\",\"E\":1788567782283,\"T\":1788567782282,\"s\":\"BTCUSDT\",\"ps\":\"BTCUSDT\",\"U\":11478511515178,\"u\":11478511521481,\"pu\":11478511514959,\"b\":[[\"29196.90\",\"0.987\"],[\"29296.90\",\"1.113\"],[\"71637.20\",\"0.002\"],[\"78800.90\",\"12.571\"],[\"79198.90\",\"3.981\"],[\"79581.90\",\"0.675\"],[\"79585.30\",\"0.091\"],[\"79592.80\",\"0.505\"]],\"a\":[[\"79598.10\",\"0.000\"],[\"79600.60\",\"0.000\"],[\"79637.50\",\"0.000\"],[\"79637.80\",\"0.008\"],[\"79638.10\",\"0.139\"],[\"79651.50\",\"0.001\"],[\"79660.30\",\"1.991\"],[\"79691.60\",\"6.001\"],[\"80393.00\",\"14.175\"],[\"80631.80\",\"8.537\"]],\"st\":1}}"}
{"receive_ns":1788567782375556000,"stream":"btcusdt@depth@100ms","event_type":"depthUpdate","event_time_ms":1788567782385,"raw_json":"{\"stream\":\"btcusdt@depth@100ms\",\"data\":{\"e\":\"depthUpdate\",\"E\":1788567782385,\"T\":1788567782382,\"s\":\"BTCUSDT\",\"ps\":\"BTCUSDT\",\"U\":11478511521618,\"u\":11478511527034,\"pu\":11478511521481,\"b\":[[\"1000.00\",\"24.604\"],[\"29196.90\",\"1.162\"],[\"29296.90\",\"0.938\"],[\"63678.00\",\"0.010\"],[\"71637.20\",\"0.002\"],[\"71673.00\",\"0.000\"],[\"76413.00\",\"0.025\"],[\"78800.90\",\"12.571\"],[\"79507.70\",\"1.322\"],[\"79525.20\",\"0.002\"],[\"79541.10\",\"1.096\"],[\"79576.90\",\"0.002\"],[\"79585.10\",\"0.000\"],[\"79586.10\",\"0.067\"]],\"a\":[[\"79638.00\",\"0.127\"],[\"79638.10\",\"0.014\"],[\"79668.70\",\"2.054\"],[\"79692.60\",\"0.002\"],[\"79819.10\",\"7.009\"],[\"80393.00\",\"14.175\"],[\"80904.60\",\"0.000\"],[\"81188.90\",\"0.046\"]],\"st\":1}}"}
{"receive_ns":1788567782453786000,"stream":"btcusdt@bookTicker","event_type":"bookTicker","event_time_ms":1788567782468,"raw_json":"{\"stream\":\"btcusdt@bookTicker\",\"data\":{\"e\":\"bookTicker\",\"u\":11478511534067,\"s\":\"BTCUSDT\",\"ps\":\"BTCUSDT\",\"b\":\"79596.90\",\"B\":\"6.978\",\"a\":\"79597.00\",\"A\":\"8.155\",\"T\":1788567782468,\"E\":1788567782468,\"st\":1}}"}
{"receive_ns":1788567782459499000,"stream":"btcusdt@bookTicker","event_type":"bookTicker","event_time_ms":1788567782472,"raw_json":"{\"stream\":\"btcusdt@bookTicker\",\"data\":{\"e\":\"bookTicker\",\"u\":11478511534415,\"s\":\"BTCUSDT\",\"ps\":\"BTCUSDT\",\"b\":\"79596.90\",\"B\":\"6.978\",\"a\":\"79597.00\",\"A\":\"8.163\",\"T\":1788567782472,\"E\":1788567782472,\"st\":1}}"}
{"receive_ns":1788567782475538000,"stream":"btcusdt@depth@100ms","event_type":"depthUpdate","event_time_ms":1788567782487,"raw_json":"{\"stream\":\"btcusdt@depth@100ms\",\"data\":{\"e\":\"depthUpdate\",\"E\":1788567782487,\"T\":1788567782485,\"s\":\"BTCUSDT\",\"ps\":\"BTCUSDT\",\"U\":11478511527214,\"u\":11478511535071,\"pu\":11478511527034,\"b\":[[\"1000.00\",\"24.604\"],[\"29196.90\",\"1.344\"],[\"29296.90\",\"0.756\"],[\"71637.20\",\"0.002\"],[\"76413.00\",\"0.023\"],[\"78602.00\",\"9.820\"],[\"78800.90\",\"12.571\"]],\"a\":[[\"79597.00\",\"8.163\"],[\"79636.50\",\"0.572\"],[\"79637.60\",\"0.010\"],[\"80898.40\",\"4.630\"],[\"81188.90\",\"0.043\"]],\"st\":1}}"}
{"receive_ns":1788567782571103000,"stream":"btcusdt@bookTicker","event_type":"bookTicker","event_time_ms":1788567782582,"raw_json":"{\"stream\":\"btcusdt@bookTicker\",\"data\":{\"e\":\"bookTicker\",\"u\":11478511540411,\"s\":\"BTCUSDT\",\"ps\":\"BTCUSDT\",\"b\":\"79596.90\",\"B\":\"6.979\",\"a\":\"79597.00\",\"A\":\"8.163\",\"T\":1788567782581,\"E\":1788567782582,\"st\":1}}"}
{"receive_ns":1788567782577437000,"stream":"btcusdt@depth@100ms","event_type":"depthUpdate","event_time_ms":1788567782589,"raw_json":"{\"stream\":\"btcusdt@depth@100ms\",\"data\":{\"e\":\"depthUpdate\",\"E\":1788567782589,\"T\":1788567782587,\"s\":\"BTCUSDT\",\"ps\":\"BTCUSDT\",\"U\":11478511535210,\"u\":11478511540821,\"pu\":11478511535071,\"b\":[[\"29196.90\",\"1.519\"],[\"29296.90\",\"0.581\"],[\"63678.00\",\"0.012\"],[\"71637.20\",\"0.002\"],[\"75617.10\",\"0.004\"],[\"75617.20\",\"0.010\"],[\"76413.00\",\"0.025\"],[\"78800.90\",\"12.571\"],[\"79198.90\",\"3.981\"],[\"79567.80\",\"0.000\"],[\"79568.90\",\"0.455\"],[\"79576.20\",\"0.875\"],[\"79576.40\",\"2.897\"],[\"79584.50\",\"0.329\"],[\"79585.00\",\"0.101\"],[\"79586.10\",\"0.001\"],[\"79589.70\",\"1.366\"],[\"79589.80\",\"0.000\"],[\"79590.00\",\"0.108\"],[\"79592.10\",\"0.004\"],[\"79592.20\",\"0.000\"],[\"79596.90\",\"6.979\"]],\"a\":[[\"79598.00\",\"0.081\"],[\"79598.60\",\"0.027\"],[\"79600.30\",\"0.030\"],[\"79605.00\",\"0.079\"],[\"79605.30\",\"0.317\"],[\"79638.00\",\"0.002\"],[\"79665.40\",\"1.810\"],[\"79666.20\",\"0.001\"],[\"79674.20\",\"21.661\"],[\"79683.00\",\"0.012\"],[\"79806.10\",\"4.810\"],[\"79995.00\",\"4.697\"],[\"80393.00\",\"14.175\"],[\"80950.30\",\"7.673\"]],\"st\":1}}"}
{"receive_ns":1788567782682444000,"stream":"btcusdt@depth@100ms","event_type":"depthUpdate","event_time_ms":1788567782691,"raw_json":"{\"stream\":\"btcusdt@depth@100ms\",\"data\":{\"e\":\"depthUpdate\",\"E\":1788567782691,\"T\":1788567782690,\"s\":\"BTCUSDT\",\"ps\":\"BTCUSDT\",\"U\":11478511541012,\"u\":11478511546138,\"pu\":11478511540821,\"b\":[[\"1000.00\",\"24.604\"],[\"29196.90\",\"1.701\"],[\"29296.90\",\"0.399\"],[\"63678.00\",\"0.010\"],[\"71637.20\",\"0.002\"],[\"76413.00\",\"0.023\"],[\"77925.50\",\"0.008\"],[\"78243.80\",\"8.164\"],[\"78727.50\",\"5.030\"],[\"78800.90\",\"12.571\"],[\"79564.90\",\"0.000\"],[\"79565.80\",\"0.000\"],[\"79566.10\",\"0.049\"],[\"79567.80\",\"0.452\"],[\"79568.90\",\"0.003\"],[\"79572.10\",\"0.001\"],[\"79572.50\",\"0.266\"],[\"79573.30\",\"0.439\"],[\"79574.30\",\"0.001\"],[\"79575.40\",\"0.432\"],[\"79576.90\",\"0.006\"],[\"79581.90\",\"0.323\"],[\"79585.00\",\"0.097\"],[\"79585.30\",\"0.000\"]],\"a\":[[\"79597.70\",\"0.026\"],[\"79600.40\",\"0.008\"],[\"79608.30\",\"0.001\"],[\"79610.70\",\"0.545\"],[\"79614.20\",\"0.001\"],[\"79615.30\",\"0.559\"],[\"79615.40\",\"0.004\"],[\"79617.30\",\"0.068\"],[\"79618.50\",\"0.454\"],[\"79628.80\",\"0.000\"],[\"79629.80\",\"0.048\"],[\"79629.90\",\"0.001\"],[\"79637.10\",\"0.252\"],[\"79666.10\",\"21.676\"],[\"79674.00\",\"0.735\"],[\"79674.20\",\"0.001\"],[\"80233.80\",\"7.091\"],[\"80393.00\",\"14.176\"]],\"st\":1}}"}
{"receive_ns":1788567782753090000,"stream":"btcusdt@bookTicker","event_type":"bookTicker","event_time_ms":1788567782761,"raw_json":"{\"stream\":\"btcusdt@bookTicker\",\"data\":{\"e\":\"bookTicker\",\"u\":11478511550841,\"s\":\"BTCUSDT\",\"ps\":\"BTCUSDT\",\"b\":\"79596.90\",\"B\":\"6.989\",\"a\":\"79597.00\",\"A\":\"8.163\",\"T\":1788567782760,\"E\":1788567782761,\"st\":1}}"}
{"receive_ns":1788567782782297000,"stream":"btcusdt@depth@100ms","event_type":"depthUpdate","event_time_ms":1788567782793,"raw_json":"{\"stream\":\"btcusdt@depth@100ms\",\"data\":{\"e\":\"depthUpdate\",\"E\":1788567782793,\"T\":1788567782789,\"s\":\"BTCUSDT\",\"ps\":\"BTCUSDT\",\"U\":11478511546329,\"u\":11478511552160,\"pu\":11478511546138,\"b\":[[\"1000.00\",\"24.604\"],[\"29096.90\",\"0.042\"],[\"29196.90\",\"1.792\"],[\"29296.90\",\"0.266\"],[\"71637.20\",\"0.002\"],[\"75617.20\",\"0.008\"],[\"78230.00\",\"7.399\"],[\"78800.90\",\"12.571\"],[\"79572.50\",\"0.705\"],[\"79573.20\",\"0.536\"],[\"79573.30\",\"0.000\"],[\"79589.70\",\"1.358\"],[\"79590.00\",\"0.116\"],[\"79596.90\",\"6.989\"]],\"a\":[[\"79613.10\",\"0.192\"],[\"79637.60\",\"0.010\"],[\"79638.00\",\"0.127\"],[\"80393.00\",\"14.176\"]],\"st\":1}}"}
{"receive_ns":1788567782827204000,"stream":"btcusdt@bookTicker","event_type":"bookTicker","event_time_ms":1788567782834,"raw_json":"{\"stream\":\"btcusdt@bookTicker\",\"data\":{\"e\":\"bookTicker\",\"u\":11478511553977,\"s\":\"BTCUSDT\",\"ps\":\"BTCUSDT\",\"b\":\"79596.90\",\"B\":\"6.989\",\"a\":\"79597.00\",\"A\":\"8.162\",\"T\":1788567782834,\"E\":1788567782834,\"st\":1}}"}
{"receive_ns":1788567782839022000,"stream":"btcusdt@bookTicker","event_type":"bookTicker","event_time_ms":1788567782842,"raw_json":"{\"stream\":\"btcusdt@bookTicker\",\"data\":{\"e\":\"bookTicker\",\"u\":11478511554304,\"s\":\"BTCUSDT\",\"ps\":\"BTCUSDT\",\"b\":\"79596.90\",\"B\":\"6.989\",\"a\":\"79597.00\",\"A\":\"8.158\",\"T\":1788567782841,\"E\":1788567782842,\"st\":1}}"}
{"receive_ns":1788567782845740000,"stream":"btcusdt@trade","event_type":"trade","event_time_ms":1788567782842,"raw_json":"{\"stream\":\"btcusdt@trade\",\"data\":{\"e\":\"trade\",\"E\":1788567782842,\"T\":1788567782841,\"s\":\"BTCUSDT\",\"t\":8054122853,\"p\":\"79597.00\",\"q\":\"0.004\",\"X\":\"MARKET\",\"m\":false,\"st\":1}}"}
{"receive_ns":1788567782884647000,"stream":"btcusdt@depth@100ms","event_type":"depthUpdate","event_time_ms":1788567782895,"raw_json":"{\"stream\":\"btcusdt@depth@100ms\",\"data\":{\"e\":\"depthUpdate\",\"E\":1788567782895,\"T\":1788567782894,\"s\":\"BTCUSDT\",\"ps\":\"BTCUSDT\",\"U\":11478511552332,\"u\":11478511557407,\"pu\":11478511552160,\"b\":[[\"29096.90\",\"0.105\"],[\"29196.90\",\"1.848\"],[\"29296.90\",\"0.147\"],[\"63678.00\",\"0.010\"],[\"71637.20\",\"0.002\"],[\"76413.00\",\"0.025\"],[\"78005.00\",\"0.222\"],[\"78800.90\",\"12.571\"],[\"79198.90\",\"3.981\"],[\"79573.20\",\"0.538\"]],\"a\":[[\"79597.00\",\"8.158\"],[\"79597.70\",\"0.000\"],[\"79598.40\",\"0.285\"],[\"79613.10\",\"0.194\"],[\"79638.00\",\"0.002\"],[\"79638.70\",\"0.468\"],[\"80393.00\",\"14.176\"]],\"st\":1}}"}
{"receive_ns":1788567782945069000,"stream":"btcusdt@bookTicker","event_type":"bookTicker","event_time_ms":1788567782961,"raw_json":"{\"stream\":\"btcusdt@bookTicker\",\"data\":{\"e\":\"bookTicker\",\"u\":11478511561053,\"s\":\"BTCUSDT\",\"ps\":\"BTCUSDT\",\"b\":\"79596.90\",\"B\":\"6.964\",\"a\":\"79597.00\",\"A\":\"8.158\",\"T\":1788567782961,\"E\":1788567782961,\"st\":1}}"}
{"receive_ns":1788567782951024000,"stream":"btcusdt@trade","event_type":"trade","event_time_ms":1788567782961,"raw_json":"{\"stream\":\"btcusdt@trade\",\"data\":{\"e\":\"trade\",\"E\":1788567782961,\"T\":1788567782961,\"s\":\"BTCUSDT\",\"t\":8054122854,\"p\":\"79596.90\",\"q\":\"0.025\",\"X\":\"MARKET\",\"m\":true,\"st\":1}}"}
{"receive_ns":1788567782991341000,"stream":"btcusdt@depth@100ms","event_type":"depthUpdate","event_time_ms":1788567782997,"raw_json":"{\"stream\":\"btcusdt@depth@100ms\",\"data\":{\"e\":\"depthUpdate\",\"E\":1788567782997,\"T\":1788567782995,\"s\":\"BTCUSDT\",\"ps\":\"BTCUSDT\",\"U\":11478511557510,\"u\":11478511562372,\"pu\":11478511557407,\"b\":[[\"1000.00\",\"24.754\"],[\"29096.90\",\"0.161\"],[\"29196.90\",\"1.911\"],[\"29296.90\",\"0.028\"],[\"63678.00\",\"0.010\"],[\"71637.20\",\"0.002\"],[\"76413.00\",\"0.023\"],[\"77595.80\",\"0.000\"],[\"78575.30\",\"0.011\"],[\"78584.80\",\"0.004\"],[\"78599.30\",\"2.541\"],[\"78601.60\",\"0.005\"],[\"78613.80\",\"0.022\"],[\"78618.40\",\"1.891\"],[\"78800.90\",\"10.037\"],[\"78999.90\",\"3.793\"],[\"79593.50\",\"0.003\"],[\"79596.90\",\"6.964\"]],\"a\":[[\"79598.40\",\"0.259\"],[\"79598.60\",\"0.001\"],[\"79598.90\",\"0.027\"],[\"79599.00\",\"0.028\"],[\"79599.10\",\"0.078\"],[\"79638.00\",\"0.002\"],[\"79638.10\",\"0.014\"],[\"79638.20\",\"0.667\"],[\"79638.70\",\"0.343\"],[\"79666.10\",\"0.015\"],[\"79674.20\",\"21.662\"],[\"79806.10\",\"4.810\"],[\"80194.00\",\"3.926\"],[\"80393.00\",\"14.176\"],[\"81188.90\",\"0.040\"]],\"st\":1}}"}
{"receive_ns":1788567783092565000,"stream":"btcusdt@depth@100ms","event_type":"depthUpdate","event_time_ms":1788567783099,"raw_json":"{\"stream\":\"btcusdt@depth@100ms\",\"data\":{\"e\":\"depthUpdate\",\"E\":1788567783099,\"T\":1788567783098,\"s\":\"BTCUSDT\",\"ps\":\"BTCUSDT\",\"U\":11478511562412,\"u\":11478511569256,\"pu\":11478511562372,\"b\":[[\"1000.00\",\"24.604\"],[\"29096.90\",\"0.308\"],[\"29196.90\",\"1.792\"],[\"29296.90\",\"0.000\"],[\"63677.50\",\"0.000\"],[\"63678.00\",\"0.012\"],[\"71637.20\",\"0.002\"],[\"76413.00\",\"0.025\"],[\"78005.00\",\"0.225\"],[\"78800.90\",\"10.037\"],[\"78999.90\",\"3.161\"],[\"79565.80\",\"0.046\"],[\"79566.10\",\"0.003\"],[\"79582.60\",\"0.070\"]],\"a\":[[\"79604.90\",\"0.001\"],[\"79605.00\",\"0.001\"],[\"79605.30\",\"0.004\"],[\"79605.40\",\"0.477\"],[\"79637.80\",\"0.008\"],[\"79638.20\",\"0.542\"],[\"79666.10\",\"21.676\"],[\"79668.80\",\"0.034\"],[\"79674.20\",\"0.001\"],[\"80009.00\",\"0.153\"],[\"80393.00\",\"15.418\"],[\"87556.70\",\"0.000\"]],\"st\":1}}"}
{"receive_ns":1788567783188188000,"stream":"btcusdt@depth@100ms","event_type":"depthUpdate","event_time_ms":1788567783201,"raw_json":"{\"stream\":\"btcusdt@depth@100ms\",\"data\":{\"e\":\"depthUpdate\",\"E\":1788567783201,\"T\":1788567783197,\"s\":\"BTCUSDT\",\"ps\":\"BTCUSDT\",\"U\":11478511569389,\"u\":11478511574165,\"pu\":11478511569256,\"b\":[[\"29096.90\",\"0.490\"],[\"29196.90\",\"1.610\"],[\"63678.00\",\"0.010\"],[\"71637.20\",\"0.002\"],[\"76413.00\",\"0.023\"],[\"78800.90\",\"10.037\"],[\"79198.90\",\"3.981\"],[\"79572.50\",\"0.266\"],[\"79573.30\",\"0.439\"],[\"79584.60\",\"0.351\"]],\"a\":[[\"79598.70\",\"0.030\"],[\"79615.30\",\"0.187\"],[\"79615.50\",\"0.001\"],[\"79615.90\",\"0.372\"],[\"79629.80\",\"0.002\"],[\"79630.10\",\"0.047\"],[\"79638.10\",\"0.014\"],[\"79666.10\",\"0.015\"],[\"79674.20\",\"21.662\"],[\"79692.70\",\"0.005\"],[\"79806.10\",\"4.810\"],[\"79819.10\",\"6.976\"],[\"80393.00\",\"15.418\"]],\"st\":1}}"}
{"receive_ns":1788567783293655000,"stream":"btcusdt@depth@100ms","event_type":"depthUpdate","event_time_ms":1788567783303,"raw_json":"{\"stream\":\"btcusdt@depth@100ms\",\"data\":{\"e\":\"depthUpdate\",\"E\":1788567783303,\"T\":1788567783301,\"s\":\"BTCUSDT\",\"ps\":\"BTCUSDT\",\"U\":11478511574306,\"u\":11478511578530,\"pu\":11478511574165,\"b\":[[\"1000.00\",\"24.604\"],[\"29096.90\",\"0.672\"],[\"29196.90\",\"1.428\"],[\"71637.20\",\"0.002\"],[\"78800.90\",\"10.037\"],[\"79565.80\",\"0.000\"],[\"79566.50\",\"0.169\"],[\"79575.40\",\"0.059\"],[\"79575.90\",\"0.373\"],[\"79576.90\",\"0.006\"],[\"79582.30\",\"0.195\"],[\"79585.00\",\"0.097\"],[\"79587.60\",\"0.000\"],[\"79591.70\",\"0.079\"],[\"79596.80\",\"0.183\"]],\"a\":[[\"79597.20\",\"0.250\"],[\"79597.50\",\"0.014\"],[\"79598.00\",\"0.081\"],[\"79600.30\",\"0.004\"],[\"79601.00\",\"0.319\"],[\"79630.10\",\"0.001\"],[\"79630.50\",\"0.046\"],[\"79636.80\",\"0.144\"],[\"79637.90\",\"0.125\"],[\"79668.80\",\"21.695\"],[\"79674.20\",\"0.001\"],[\"79692.70\",\"0.006\"],[\"80393.00\",\"15.418\"],[\"80552.20\",\"32.453\"],[\"80711.40\",\"32.287\"]],\"st\":1}}"}
{"receive_ns":1788567783346214000,"stream":"btcusdt@bookTicker","event_type":"bookTicker","event_time_ms":1788567783359,"raw_json":"{\"stream\":\"btcusdt@bookTicker\",\"data\":{\"e\":\"bookTicker\",\"u\":11478511581124,\"s\":\"BTCUSDT\",\"ps\":\"BTCUSDT\",\"b\":\"79596.90\",\"B\":\"6.964\",\"a\":\"79597.00\",\"A\":\"8.162\",\"T\":1788567783359,\"E\":1788567783359,\"st\":1}}"}
{"receive_ns":1788567783357399000,"stream":"btcusdt@bookTicker","event_type":"bookTicker","event_time_ms":1788567783366,"raw_json":"{\"stream\":\"btcusdt@bookTicker\",\"data\":{\"e\":\"bookTicker\",\"u\":11478511581443,\"s\":\"BTCUSDT\",\"ps\":\"BTCUSDT\",\"b\":\"79596.90\",\"B\":\"6.797\",\"a\":\"79597.00\",\"A\":\"8.162\",\"T\":1788567783366,\"E\":1788567783366,\"st\":1}}"}
{"receive_ns":1788567783393374000,"stream":"btcusdt@depth@100ms","event_type":"depthUpdate","event_time_ms":1788567783405,"raw_json":"{\"stream\":\"btcusdt@depth@100ms\",\"data\":{\"e\":\"depthUpdate\",\"E\":1788567783405,\"T\":1788567783401,\"s\":\"BTCUSDT\",\"ps\":\"BTCUSDT\",\"U\":11478511578652,\"u\":11478511582790,\"pu\":11478511578530,\"b\":[[\"29096.90\",\"0.847\"],[\"29196.90\",\"1.253\"],[\"71637.20\",\"0.002\"],[\"71673.00\",\"0.000\"],[\"76413.00\",\"0.025\"],[\"78522.30\",\"7.311\"],[\"78800.90\",\"10.037\"],[\"79533.20\",\"1.150\"],[\"79541.10\",\"1.098\"],[\"79550.10\",\"0.692\"],[\"79554.00\",\"0.060\"],[\"79565.80\",\"0.000\"],[\"79566.50\",\"0.123\"],[\"79567.10\",\"0.047\"],[\"79572.50\",\"0.266\"],[\"79573.30\",\"0.439\"],[\"79575.20\",\"0.002\"],[\"79575.90\",\"0.000\"],[\"79576.50\",\"0.373\"],[\"79592.90\",\"0.078\"],[\"79593.60\",\"0.003\"],[\"79596.90\",\"6.797\"]],\"a\":[[\"79597.00\",\"8.162\"],[\"79608.90\",\"0.230\"],[\"79610.60\",\"0.441\"],[\"79610.70\",\"0.106\"],[\"79615.10\",\"0.254\"],[\"79615.90\",\"0.000\"],[\"79616.40\",\"2.104\"],[\"79618.50\",\"0.002\"],[\"79619.70\",\"0.454\"],[\"79629.60\",\"0.002\"],[\"79630.50\",\"0.000\"],[\"79630.90\",\"0.057\"],[\"79637.90\",\"0.000\"],[\"79644.80\",\"0.274\"],[\"79692.60\",\"0.004\"],[\"79806.10\",\"2.769\"],[\"80194.00\",\"3.303\"],[\"80393.00\",\"15.418\"],[\"80727.30\",\"1.480\"],[\"81572.60\",\"0.795\"]],\"st\":1}}"}
{"receive_ns":1788567783453658000,"stream":"btcusdt@bookTicker","event_type":"bookTicker","event_time_ms":1788567783464,"raw_json":"{\"stream\":\"btcusdt@bookTicker\",\"data\":{\"e\":\"bookTicker\",\"u\":11478511585096,\"s\":\"BTCUSDT\",\"ps\":\"BTCUSDT\",\"b\":\"79596.90\",\"B\":\"6.777\",\"a\":\"79597.00\",\"A\":\"8.162\",\"T\":1788567783463,\"E\":1788567783464,\"st\":1}}"}
{"receive_ns":1788567783464825000,"stream":"btcusdt@bookTicker","event_type":"bookTicker","event_time_ms":1788567783465,"raw_json":"{\"stream\":\"btcusdt@bookTicker\",\"data\":{\"e\":\"bookTicker\",\"u\":11478511585295,\"s\":\"BTCUSDT\",\"ps\":\"BTCUSDT\",\"b\":\"79596.90\",\"B\":\"6.768\",\"a\":\"79597.00\",\"A\":\"8.162\",\"T\":1788567783465,\"E\":1788567783465,\"st\":1}}"}
{"receive_ns":1788567783476707000,"stream":"btcusdt@bookTicker","event_type":"bookTicker","event_time_ms":1788567783466,"raw_json":"{\"stream\":\"btcusdt@bookTicker\",\"data\":{\"e\":\"bookTicker\",\"u\":11478511585371,\"s\":\"BTCUSDT\",\"ps\":\"BTCUSDT\",\"b\":\"79596.90\",\"B\":\"6.790\",\"a\":\"79597.00\",\"A\":\"8.162\",\"T\":1788567783466,\"E\":1788567783466,\"st\":1}}"}
{"receive_ns":1788567783493840000,"stream":"btcusdt@bookTicker","event_type":"bookTicker","event_time_ms":1788567783466,"raw_json":"{\"stream\":\"btcusdt@bookTicker\",\"data\":{\"e\":\"bookTicker\",\"u\":11478511585381,\"s\":\"BTCUSDT\",\"ps\":\"BTCUSDT\",\"b\":\"79596.90\",\"B\":\"6.790\",\"a\":\"79597.00\",\"A\":\"8.161\",\"T\":1788567783466,\"E\":1788567783466,\"st\":1}}"}
{"receive_ns":1788567783505721000,"stream":"btcusdt@trade","event_type":"trade","event_time_ms":1788567783466,"raw_json":"{\"stream\":\"btcusdt@trade\",\"data\":{\"e\":\"trade\",\"E\":1788567783466,\"T\":1788567783466,\"s\":\"BTCUSDT\",\"t\":8054122855,\"p\":\"79597.00\",\"q\":\"0.001\",\"X\":\"MARKET\",\"m\":false,\"st\":1}}"}
{"receive_ns":1788567783512190000,"stream":"btcusdt@bookTicker","event_type":"bookTicker","event_time_ms":1788567783468,"raw_json":"{\"stream\":\"btcusdt@bookTicker\",\"data\":{\"e\":\"bookTicker\",\"u\":11478511585603,\"s\":\"BTCUSDT\",\"ps\":\"BTCUSDT\",\"b\":\"79596.90\",\"B\":\"6.812\",\"a\":\"79597.00\",\"A\":\"8.161\",\"T\":1788567783468,\"E\":1788567783468,\"st\":1}}"}
{"receive_ns":1788567783524068000,"stream":"btcusdt@bookTicker","event_type":"bookTicker","event_time_ms":1788567783476,"raw_json":"{\"stream\":\"btcusdt@bookTicker\",\"data\":{\"e\":\"bookTicker\",\"u\":11478511585848,\"s\":\"BTCUSDT\",\"ps\":\"BTCUSDT\",\"b\":\"79596.90\",\"B\":\"6.812\",\"a\":\"79597.00\",\"A\":\"8.153\",\"T\":1788567783475,\"E\":1788567783476,\"st\":1}}"}
{"receive_ns":1788567783529682000,"stream":"btcusdt@bookTicker","event_type":"bookTicker","event_time_ms":1788567783479,"raw_json":"{\"stream\":\"btcusdt@bookTicker\",\"data\":{\"e\":\"bookTicker\",\"u\":11478511586021,\"s\":\"BTCUSDT\",\"ps\":\"BTCUSDT\",\"b\":\"79596.90\",\"B\":\"6.812\",\"a\":\"79597.00\",\"A\":\"8.163\",\"T\":1788567783479,\"E\":1788567783479,\"st\":1}}"}
{"receive_ns":1788567783541777000,"stream":"btcusdt@depth@100ms","event_type":"depthUpdate","event_time_ms":1788567783507,"raw_json":"{\"stream\":\"btcusdt@depth@100ms\",\"data\":{\"e\":\"depthUpdate\",\"E\":1788567783507,\"T\":1788567783505,\"s\":\"BTCUSDT\",\"ps\":\"BTCUSDT\",\"U\":11478511582895,\"u\":11478511587257,\"pu\":11478511582790,\"b\":[[\"29096.90\",\"1.029\"],[\"29196.90\",\"1.071\"],[\"71637.20\",\"0.002\"],[\"75617.20\",\"0.006\"],[\"76413.00\",\"0.023\"],[\"78482.50\",\"31.171\"],[\"78562.10\",\"9.119\"],[\"78800.90\",\"10.987\"],[\"79039.80\",\"0.000\"],[\"79198.90\",\"3.971\"],[\"79501.30\",\"0.002\"],[\"79576.90\",\"0.002\"],[\"79585.00\",\"0.101\"],[\"79592.90\",\"0.002\"],[\"79593.10\",\"0.098\"],[\"79596.90\",\"6.812\"]],\"a\":[[\"79597.00\",\"8.163\"],[\"79598.50\",\"0.000\"],[\"79598.60\",\"0.001\"],[\"79598.70\",\"0.004\"],[\"79599.70\",\"0.026\"],[\"79732.40\",\"0.007\"],[\"79806.10\",\"4.790\"],[\"79850.60\",\"0.185\"],[\"80194.00\",\"2.680\"],[\"80229.30\",\"0.000\"],[\"80393.00\",\"15.418\"],[\"80552.20\",\"33.693\"],[\"80711.40\",\"34.142\"]],\"st\":1}}"}
{"receive_ns":1788567783601757000,"stream":"btcusdt@depth@100ms","event_type":"depthUpdate","event_time_ms":1788567783609,"raw_json":"{\"stream\":\"btcusdt@depth@100ms\",\"data\":{\"e\":\"depthUpdate\",\"E\":1788567783609,\"T\":1788567783608,\"s\":\"BTCUSDT\",\"ps\":\"BTCUSDT\",\"U\":11478511587324,\"u\":11478511591576,\"pu\":11478511587257,\"b\":[[\"1000.00\",\"24.604\"],[\"29096.90\",\"1.204\"],[\"29196.90\",\"0.896\"],[\"71637.20\",\"0.002\"],[\"75617.10\",\"0.006\"],[\"76413.00\",\"0.025\"],[\"78800.90\",\"10.987\"],[\"79039.70\",\"0.081\"],[\"79198.90\",\"3.970\"],[\"79417.90\",\"3.337\"],[\"79501.30\",\"0.000\"],[\"79509.00\",\"0.010\"],[\"79509.10\",\"0.361\"],[\"79525.20\",\"0.002\"],[\"79541.10\",\"1.096\"],[\"79567.80\",\"0.000\"],[\"79570.00\",\"0.457\"],[\"79576.90\",\"0.006\"],[\"79585.00\",\"0.097\"]],\"a\":[[\"79597.10\",\"0.739\"],[\"79598.50\",\"0.026\"],[\"79598.60\",\"0.027\"],[\"79598.70\",\"0.030\"],[\"79600.20\",\"0.001\"],[\"79668.70\",\"2.054\"],[\"79684.20\",\"0.008\"],[\"79684.30\",\"0.062\"],[\"79692.60\",\"0.002\"],[\"79732.40\",\"0.005\"],[\"79739.40\",\"3.141\"],[\"79995.00\",\"4.696\"],[\"80393.00\",\"15.418\"]],\"st\":1}}"}
{"receive_ns":1788567783699548000,"stream":"btcusdt@depth@100ms","event_type":"depthUpdate","event_time_ms":1788567783711,"raw_json":"{\"stream\":\"btcusdt@depth@100ms\",\"data\":{\"e\":\"depthUpdate\",\"E\":1788567783711,\"T\":1788567783709,\"s\":\"BTCUSDT\",\"ps\":\"BTCUSDT\",\"U\":11478511591629,\"u\":11478511595948,\"pu\":11478511591576,\"b\":[[\"29096.90\",\"1.386\"],[\"29196.90\",\"0.714\"],[\"71637.20\",\"0.002\"],[\"78800.90\",\"10.987\"],[\"78960.10\",\"7.830\"]],\"a\":[[\"79637.80\",\"0.008\"],[\"79638.00\",\"0.002\"],[\"79806.10\",\"2.622\"],[\"79819.10\",\"6.968\"],[\"80393.00\",\"15.417\"]],\"st\":1}}"}
{"receive_ns":1788567783805519000,"stream":"btcusdt@depth@100ms","event_type":"depthUpdate","event_time_ms":1788567783813,"raw_json":"{\"stream\":\"btcusdt@depth@100ms\",\"data\":{\"e\":\"depthUpdate\",\"E\":1788567783813,\"T\":1788567783812,\"s\":\"BTCUSDT\",\"ps\":\"BTCUSDT\",\"U\":11478511596003,\"u\":11478511601106,\"pu\":11478511595948,\"b\":[[\"29096.90\",\"1.561\"],[\"29196.90\",\"0.539\"],[\"71637.20\",\"0.002\"],[\"75617.00\",\"0.029\"],[\"76413.00\",\"0.023\"],[\"78005.10\",\"1.924\"],[\"78093.50\",\"0.000\"],[\"78181.90\",\"0.002\"],[\"78270.40\",\"0.002\"],[\"78358.80\",\"0.000\"],[\"78447.30\",\"0.000\"],[\"78522.30\",\"7.693\"],[\"78535.70\",\"0.000\"],[\"78601.90\",\"11.220\"],[\"78624.10\",\"2.146\"],[\"78712.60\",\"0.001\"],[\"78801.00\",\"5.317\"],[\"79198.90\",\"3.981\"],[\"79573.20\",\"0.536\"]],\"a\":[[\"79613.10\",\"0.192\"],[\"79638.00\",\"0.002\"],[\"79806.10\",\"4.790\"],[\"79995.00\",\"4.697\"],[\"80393.00\",\"15.389\"],[\"80481.40\",\"0.026\"],[\"80569.90\",\"0.001\"],[\"80658.30\",\"0.125\"],[\"80746.70\",\"0.000\"],[\"80835.20\",\"0.002\"],[\"80923.60\",\"0.001\"],[\"81012.10\",\"0.004\"],[\"81100.50\",\"0.009\"],[\"81188.90\",\"0.012\"]],\"st\":1}}"}
{"receive_ns":1788567783823341000,"stream":"btcusdt@bookTicker","event_type":"bookTicker","event_time_ms":1788567783820,"raw_json":"{\"stream\":\"btcusdt@bookTicker\",\"data\":{\"e\":\"bookTicker\",\"u\":11478511601446,\"s\":\"BTCUSDT\",\"ps\":\"BTCUSDT\",\"b\":\"79596.90\",\"B\":\"6.806\",\"a\":\"79597.00\",\"A\":\"8.163\",\"T\":1788567783820,\"E\":1788567783820,\"st\":1}}"}
{"receive_ns":1788567783878635000,"stream":"btcusdt@bookTicker","event_type":"bookTicker","event_time_ms":1788567783838,"raw_json":"{\"stream\":\"btcusdt@bookTicker\",\"data\":{\"e\":\"bookTicker\",\"u\":11478511602147,\"s\":\"BTCUSDT\",\"ps\":\"BTCUSDT\",\"b\":\"79596.90\",\"B\":\"6.806\",\"a\":\"79597.00\",\"A\":\"8.161\",\"T\":1788567783838,\"E\":1788567783838,\"st\":1}}"}
{"receive_ns":1788567783885360000,"stream":"btcusdt@trade","event_type":"trade","event_time_ms":1788567783838,"raw_json":"{\"stream\":\"btcusdt@trade\",\"data\":{\"e\":\"trade\",\"E\":1788567783838,\"T\":1788567783838,\"s\":\"BTCUSDT\",\"t\":8054122856,\"p\":\"79597.00\",\"q\":\"0.002\",\"X\":\"MARKET\",\"m\":false,\"st\":1}}"}
{"receive_ns":1788567783910438000,"stream":"btcusdt@depth@100ms","event_type":"depthUpdate","event_time_ms":1788567783915,"raw_json":"{\"stream\":\"btcusdt@depth@100ms\",\"data\":{\"e\":\"depthUpdate\",\"E\":1788567783915,\"T\":1788567783914,\"s\":\"BTCUSDT\",\"ps\":\"BTCUSDT\",\"U\":11478511601133,\"u\":11478511605073,\"pu\":11478511601106,\"b\":[[\"1000.00\",\"24.604\"],[\"29096.90\",\"1.743\"],[\"29196.90\",\"0.357\"],[\"71637.20\",\"0.002\"],[\"76413.00\",\"0.025\"],[\"78601.90\",\"11.411\"],[\"78800.90\",\"10.987\"],[\"79022.80\",\"0.000\"],[\"79197.00\",\"0.002\"],[\"79199.90\",\"0.885\"],[\"79316.00\",\"1.020\"],[\"79319.30\",\"0.759\"],[\"79474.40\",\"0.001\"],[\"79573.20\",\"0.538\"],[\"79587.70\",\"0.003\"],[\"79596.90\",\"6.806\"]],\"a\":[[\"79597.00\",\"8.161\"],[\"79613.10\",\"0.194\"],[\"79637.90\",\"0.000\"],[\"79638.30\",\"0.126\"],[\"79719.50\",\"0.031\"],[\"79831.60\",\"0.000\"],[\"79831.70\",\"0.003\"],[\"79880.70\",\"0.331\"],[\"79882.70\",\"0.000\"],[\"80001.40\",\"0.713\"],[\"80002.50\",\"3.247\"],[\"80002.60\",\"0.000\"],[\"80178.60\",\"0.013\"],[\"80393.00\",\"15.389\"],[\"81188.90\",\"0.009\"]],\"st\":1}}"}
{"receive_ns":1788567783936561000,"stream":"btcusdt@bookTicker","event_type":"bookTicker","event_time_ms":1788567783950,"raw_json":"{\"stream\":\"btcusdt@bookTicker\",\"data\":{\"e\":\"bookTicker\",\"u\":11478511606650,\"s\":\"BTCUSDT\",\"ps\":\"BTCUSDT\",\"b\":\"79596.90\",\"B\":\"6.790\",\"a\":\"79597.00\",\"A\":\"8.161\",\"T\":1788567783950,\"E\":1788567783950,\"st\":1}}"}
{"receive_ns":1788567784001617000,"stream":"btcusdt@depth@100ms","event_type":"depthUpdate","event_time_ms":1788567784017,"raw_json":"{\"stream\":\"btcusdt@depth@100ms\",\"data\":{\"e\":\"depthUpdate\",\"E\":1788567784017,\"T\":1788567784014,\"s\":\"BTCUSDT\",\"ps\":\"BTCUSDT\",\"U\":11478511605093,\"u\":11478511609514,\"pu\":11478511605073,\"b\":[[\"29096.90\",\"1.806\"],[\"29196.90\",\"0.238\"],[\"29496.90\",\"0.056\"],[\"71637.20\",\"0.002\"],[\"76413.00\",\"0.023\"],[\"78584.80\",\"0.000\"],[\"78587.10\",\"0.012\"],[\"78602.00\",\"9.668\"],[\"78800.90\",\"10.987\"],[\"78960.10\",\"8.588\"],[\"79568.90\",\"0.003\"],[\"79570.00\",\"0.005\"],[\"79571.10\",\"0.452\"],[\"79575.40\",\"0.059\"],[\"79575.70\",\"0.008\"],[\"79576.30\",\"0.137\"],[\"79576.40\",\"3.270\"],[\"79576.50\",\"0.000\"],[\"79576.80\",\"0.334\"],[\"79576.90\",\"0.002\"],[\"79577.60\",\"0.002\"],[\"79582.30\",\"0.119\"],[\"79585.00\",\"0.097\"],[\"79593.10\",\"0.022\"],[\"79594.60\",\"0.053\"],[\"79595.90\",\"0.039\"],[\"79596.80\",\"0.157\"],[\"79596.90\",\"6.790\"]],\"a\":[[\"79597.40\",\"0.031\"],[\"79598.00\",\"0.107\"],[\"79598.20\",\"0.028\"],[\"79598.50\",\"0.000\"],[\"79598.60\",\"0.001\"],[\"79598.70\",\"0.004\"],[\"79598.90\",\"0.001\"],[\"79599.00\",\"0.002\"],[\"79609.40\",\"0.291\"],[\"79610.50\",\"0.443\"],[\"79610.60\",\"0.002\"],[\"79612.10\",\"0.002\"],[\"79616.30\",\"1.641\"],[\"79616.40\",\"1.732\"],[\"79617.50\",\"0.000\"],[\"79618.50\",\"0.002\"],[\"79619.70\",\"0.002\"],[\"79620.60\",\"0.454\"],[\"79638.10\",\"0.014\"],[\"79638.30\",\"0.001\"],[\"79668.80\",\"0.034\"],[\"79674.20\",\"21.662\"],[\"80393.00\",\"15.389\"],[\"80395.00\",\"0.277\"],[\"80660.70\",\"0.000\"],[\"80706.10\",\"0.753\"],[\"80714.60\",\"0.000\"],[\"80716.50\",\"0.013\"]],\"st\":1}}"}
{"receive_ns":1788567784118053000,"stream":"btcusdt@bookTicker","event_type":"bookTicker","event_time_ms":1788567784113,"raw_json":"{\"stream\":\"btcusdt@bookTicker\",\"data\":{\"e\":\"bookTicker\",\"u\":11478511615521,\"s\":\"BTCUSDT\",\"ps\":\"BTCUSDT\",\"b\":\"79596.90\",\"B\":\"6.778\",\"a\":\"79597.00\",\"A\":\"8.161\",\"T\":1788567784113,\"E\":1788567784113,\"st\":1}}"}
{"receive_ns":1788567784132409000,"stream":"btcusdt@bookTicker","event_type":"bookTicker","event_time_ms":1788567784116,"raw_json":"{\"stream\":\"btcusdt@bookTicker\",\"data\":{\"e\":\"bookTicker\",\"u\":11478511615679,\"s\":\"BTCUSDT\",\"ps\":\"BTCUSDT\",\"b\":\"79596.90\",\"B\":\"6.789\",\"a\":\"79597.00\",\"A\":\"8.161\",\"T\":1788567784116,\"E\":1788567784116,\"st\":1}}"}
{"receive_ns":1788567784143593000,"stream":"btcusdt@depth@100ms","event_type":"depthUpdate","event_time_ms":1788567784119,"raw_json":"{\"stream\":\"btcusdt@depth@100ms\",\"data\":{\"e\":\"depthUpdate\",\"E\":1788567784119,\"T\":1788567784117,\"s\":\"BTCUSDT\",\"ps\":\"BTCUSDT\",\"U\":11478511609628,\"u\":11478511615716,\"pu\":11478511609514,\"b\":[[\"29096.90\",\"1.862\"],[\"29196.90\",\"0.119\"],[\"29496.90\",\"0.119\"],[\"63677.50\",\"0.000\"],[\"71637.20\",\"0.002\"],[\"75617.10\",\"0.004\"],[\"75617.20\",\"0.008\"],[\"76413.00\",\"0.025\"],[\"78548.80\",\"1.908\"],[\"78800.90\",\"10.987\"],[\"78809.40\",\"0.000\"],[\"78816.10\",\"3.240\"],[\"78888.10\",\"0.648\"],[\"79000.10\",\"0.212\"],[\"79022.90\",\"0.000\"],[\"79197.10\",\"0.284\"],[\"79198.90\",\"3.971\"],[\"79316.10\",\"0.002\"],[\"79576.80\",\"0.016\"],[\"79581.90\",\"0.663\"],[\"79582.60\",\"0.070\"],[\"79585.00\",\"0.349\"],[\"79585.30\",\"0.084\"],[\"79586.10\",\"0.067\"],[\"79596.50\",\"0.470\"],[\"79596.60\",\"0.028\"],[\"79596.90\",\"6.789\"]],\"a\":[[\"79638.20\",\"0.542\"],[\"79639.40\",\"0.002\"],[\"79671.50\",\"21.625\"],[\"79674.20\",\"0.001\"],[\"79882.60\",\"0.194\"],[\"79887.90\",\"0.463\"],[\"80001.40\",\"0.000\"],[\"80002.50\",\"0.007\"],[\"80099.90\",\"10.726\"],[\"80393.00\",\"15.391\"],[\"80751.20\",\"13.509\"],[\"80830.80\",\"4.820\"],[\"81036.90\",\"3.326\"]],\"st\":1}}"}
{"receive_ns":1788567784165957000,"stream":"btcusdt@bookTicker","event_type":"bookTicker","event_time_ms":1788567784140,"raw_json":"{\"stream\":\"btcusdt@bookTicker\",\"data\":{\"e\":\"bookTicker\",\"u\":11478511616938,\"s\":\"BTCUSDT\",\"ps\":\"BTCUSDT\",\"b\":\"79596.90\",\"B\":\"6.788\",\"a\":\"79597.00\",\"A\":\"8.161\",\"T\":1788567784140,\"E\":1788567784140,\"st\":1}}"}
{"receive_ns":1788567784172938000,"stream":"btcusdt@trade","event_type":"trade","event_time_ms":1788567784140,"raw_json":"{\"stream\":\"btcusdt@trade\",\"data\":{\"e\":\"trade\",\"E\":1788567784140,\"T\":1788567784140,\"s\":\"BTCUSDT\",\"t\":8054122857,\"p\":\"79596.90\",\"q\":\"0.001\",\"X\":\"MARKET\",\"m\":true,\"st\":1}}"}
{"receive_ns":1788567784211557000,"stream":"btcusdt@depth@100ms","event_type":"depthUpdate","event_time_ms":1788567784221,"raw_json":"{\"stream\":\"btcusdt@depth@100ms\",\"data\":{\"e\":\"depthUpdate\",\"E\":1788567784221,\"T\":1788567784218,\"s\":\"BTCUSDT\",\"ps\":\"BTCUSDT\",\"U\":11478511615768,\"u\":11478511621683,\"pu\":11478511615716,\"b\":[[\"1000.00\",\"24.604\"],[\"29096.90\",\"1.897\"],[\"29196.90\",\"0.014\"],[\"29496.90\",\"0.189\"],[\"71637.20\",\"0.002\"],[\"78601.90\",\"11.627\"],[\"78800.90\",\"10.987\"],[\"79198.70\",\"58.521\"],[\"79199.90\",\"9.585\"],[\"79317.70\",\"47.561\"],[\"79319.30\",\"7.743\"],[\"79474.40\",\"0.000\"],[\"79507.60\",\"0.000\"],[\"79594.50\",\"0.000\"],[\"79596.60\",\"0.002\"],[\"79596.70\",\"0.026\"],[\"79596.90\",\"6.788\"]],\"a\":[[\"79597.10\",\"0.765\"],[\"79620.90\",\"0.055\"],[\"79638.70\",\"0.343\"],[\"79643.80\",\"1.036\"],[\"79644.80\",\"0.242\"],[\"79663.70\",\"0.101\"],[\"79691.60\",\"0.001\"],[\"79719.50\",\"0.030\"],[\"79880.70\",\"7.596\"],[\"79880.80\",\"49.853\"],[\"79925.50\",\"0.300\"],[\"79927.10\",\"0.000\"],[\"80000.60\",\"62.507\"],[\"80176.60\",\"76.330\"],[\"80393.00\",\"15.389\"],[\"80751.20\",\"14.375\"]],\"st\":1}}"}
{"receive_ns":1788567784312335000,"stream":"btcusdt@depth@100ms","event_type":"depthUpdate","event_time_ms":1788567784323,"raw_json":"{\"stream\":\"btcusdt@depth@100ms\",\"data\":{\"e\":\"depthUpdate\",\"E\":1788567784323,\"T\":1788567784321,\"s\":\"BTCUSDT\",\"ps\":\"BTCUSDT\",\"U\":11478511621917,\"u\":11478511628138,\"pu\":11478511621683,\"b\":[[\"29096.90\",\"1.743\"],[\"29196.90\",\"0.000\"],[\"29496.90\",\"0.357\"],[\"71637.20\",\"0.002\"],[\"76413.00\",\"0.023\"],[\"78800.90\",\"10.987\"],[\"79467.90\",\"0.001\"],[\"79535.50\",\"0.000\"],[\"79555.40\",\"1.133\"],[\"79596.80\",\"0.183\"]],\"a\":[[\"79597.10\",\"0.739\"],[\"79597.40\",\"0.005\"],[\"79638.40\",\"0.000\"],[\"79639.10\",\"0.125\"],[\"79668.80\",\"21.659\"],[\"79671.50\",\"0.000\"],[\"79731.40\",\"0.000\"],[\"80393.00\",\"15.389\"],[\"80715.40\",\"0.374\"],[\"80830.80\",\"5.685\"],[\"80950.10\",\"4.441\"]],\"st\":1}}"}
{"receive_ns":1788567784355479000,"stream":"btcusdt@bookTicker","event_type":"bookTicker","event_time_ms":1788567784367,"raw_json":"{\"stream\":\"btcusdt@bookTicker\",\"data\":{\"e\":\"bookTicker\",\"u\":11478511630242,\"s\":\"BTCUSDT\",\"ps\":\"BTCUSDT\",\"b\":\"79596.90\",\"B\":\"6.955\",\"a\":\"79597.00\",\"A\":\"8.161\",\"T\":1788567784366,\"E\":1788567784367,\"st\":1}}"}
{"receive_ns":1788567784371969000,"stream":"btcusdt@bookTicker","event_type":"bookTicker","event_time_ms":1788567784368,"raw_json":"{\"stream\":\"btcusdt@bookTicker\",\"data\":{\"e\":\"bookTicker\",\"u\":11478511630291,\"s\":\"BTCUSDT\",\"ps\":\"BTCUSDT\",\"b\":\"79596.90\",\"B\":\"6.954\",\"a\":\"79597.00\",\"A\":\"8.161\",\"T\":1788567784368,\"E\":1788567784368,\"st\":1}}"}
{"receive_ns":1788567784416014000,"stream":"btcusdt@depth@100ms","event_type":"depthUpdate","event_time_ms":1788567784425,"raw_json":"{\"stream\":\"btcusdt@depth@100ms\",\"data\":{\"e\":\"depthUpdate\",\"E\":1788567784425,\"T\":1788567784422,\"s\":\"BTCUSDT\",\"ps\":\"BTCUSDT\",\"U\":11478511628214,\"u\":11478511634069,\"pu\":11478511628138,\"b\":[[\"1000.00\",\"24.604\"],[\"29096.90\",\"1.568\"],[\"29496.90\",\"0.532\"],[\"71637.20\",\"0.002\"],[\"76413.00\",\"0.025\"],[\"78448.90\",\"2.779\"],[\"78721.30\",\"1.269\"],[\"78800.90\",\"10.987\"],[\"78816.10\",\"0.000\"],[\"78888.10\",\"0.000\"],[\"79000.10\",\"0.050\"],[\"79024.50\",\"71.464\"],[\"79024.60\",\"3.241\"],[\"79198.80\",\"0.649\"],[\"79198.90\",\"3.971\"],[\"79317.80\",\"0.163\"],[\"79468.00\",\"0.682\"],[\"79487.10\",\"0.109\"],[\"79487.20\",\"0.000\"],[\"79495.00\",\"0.163\"],[\"79509.80\",\"6.013\"],[\"79510.90\",\"0.009\"],[\"79511.80\",\"1.847\"],[\"79576.80\",\"0.334\"],[\"79581.90\",\"0.323\"],[\"79585.00\",\"0.097\"],[\"79585.30\",\"0.000\"],[\"79586.10\",\"0.001\"],[\"79593.00\",\"0.131\"],[\"79596.90\",\"6.954\"]],\"a\":[[\"79597.20\",\"0.002\"],[\"79598.00\",\"0.081\"],[\"79598.20\",\"0.002\"],[\"79598.30\",\"0.002\"],[\"79599.80\",\"0.027\"],[\"79600.20\",\"0.027\"],[\"79600.30\",\"0.030\"],[\"79620.90\",\"0.002\"],[\"79638.20\",\"0.667\"],[\"79639.10\",\"0.000\"],[\"79728.00\",\"1.007\"],[\"79880.70\",\"7.758\"],[\"79887.90\",\"0.301\"],[\"80000.50\",\"3.247\"],[\"80099.90\",\"7.486\"],[\"80233.80\",\"7.339\"],[\"80393.00\",\"15.389\"],[\"80552.20\",\"32.453\"],[\"80711.40\",\"32.286\"],[\"80751.20\",\"13.509\"]],\"st\":1}}"}
{"receive_ns":1788567784433360000,"stream":"btcusdt@bookTicker","event_type":"bookTicker","event_time_ms":1788567784428,"raw_json":"{\"stream\":\"btcusdt@bookTicker\",\"data\":{\"e\":\"bookTicker\",\"u\":11478511634464,\"s\":\"BTCUSDT\",\"ps\":\"BTCUSDT\",\"b\":\"79596.90\",\"B\":\"6.954\",\"a\":\"79597.00\",\"A\":\"8.162\",\"T\":1788567784428,\"E\":1788567784428,\"st\":1}}"}
{"receive_ns":1788567784434242000,"stream":"btcusdt@bookTicker","event_type":"bookTicker","event_time_ms":1788567784430,"raw_json":"{\"stream\":\"btcusdt@bookTicker\",\"data\":{\"e\":\"bookTicker\",\"u\":11478511634555,\"s\":\"BTCUSDT\",\"ps\":\"BTCUSDT\",\"b\":\"79596.90\",\"B\":\"6.954\",\"a\":\"79597.00\",\"A\":\"8.164\",\"T\":1788567784429,\"E\":1788567784430,\"st\":1}}"}
{"receive_ns":1788567784439756000,"stream":"btcusdt@bookTicker","event_type":"bookTicker","event_time_ms":1788567784432,"raw_json":"{\"stream\":\"btcusdt@bookTicker\",\"data\":{\"e\":\"bookTicker\",\"u\":11478511634679,\"s\":\"BTCUSDT\",\"ps\":\"BTCUSDT\",\"b\":\"79596.90\",\"B\":\"6.954\",\"a\":\"79597.00\",\"A\":\"8.246\",\"T\":1788567784431,\"E\":1788567784432,\"st\":1}}"}
{"receive_ns":1788567784445869000,"stream":"btcusdt@bookTicker","event_type":"bookTicker","event_time_ms":1788567784432,"raw_json":"{\"stream\":\"btcusdt@bookTicker\",\"data\":{\"e\":\"bookTicker\",\"u\":11478511634681,\"s\":\"BTCUSDT\",\"ps\":\"BTCUSDT\",\"b\":\"79596.90\",\"B\":\"6.954\",\"a\":\"79597.00\",\"A\":\"8.328\",\"T\":1788567784431,\"E\":1788567784432,\"st\":1}}"}
{"receive_ns":1788567784457788000,"stream":"btcusdt@bookTicker","event_type":"bookTicker","event_time_ms":1788567784432,"raw_json":"{\"stream\":\"btcusdt@bookTicker\",\"data\":{\"e\":\"bookTicker\",\"u\":11478511634688,\"s\":\"BTCUSDT\",\"ps\":\"BTCUSDT\",\"b\":\"79596.90\",\"B\":\"6.954\",\"a\":\"79597.00\",\"A\":\"8.410\",\"T\":1788567784432,\"E\":1788567784432,\"st\":1}}"}
{"receive_ns":1788567784469325000,"stream":"btcusdt@bookTicker","event_type":"bookTicker","event_time_ms":1788567784432,"raw_json":"{\"stream\":\"btcusdt@bookTicker\",\"data\":{\"e\":\"bookTicker\",\"u\":11478511634708,\"s\":\"BTCUSDT\",\"ps\":\"BTCUSDT\",\"b\":\"79596.90\",\"B\":\"6.955\",\"a\":\"79597.00\",\"A\":\"8.410\",\"T\":1788567784432,\"E\":1788567784432,\"st\":1}}"}
{"receive_ns":1788567784486077000,"stream":"btcusdt@bookTicker","event_type":"bookTicker","event_time_ms":1788567784469,"raw_json":"{\"stream\":\"btcusdt@bookTicker\",\"data\":{\"e\":\"bookTicker\",\"u\":11478511636368,\"s\":\"BTCUSDT\",\"ps\":\"BTCUSDT\",\"b\":\"79596.90\",\"B\":\"6.933\",\"a\":\"79597.00\",\"A\":\"8.410\",\"T\":1788567784469,\"E\":1788567784469,\"st\":1}}"}
{"receive_ns":1788567784493757000,"stream":"btcusdt@bookTicker","event_type":"bookTicker","event_time_ms":1788567784471,"raw_json":"{\"stream\":\"btcusdt@bookTicker\",\"data\":{\"e\":\"bookTicker\",\"u\":11478511636693,\"s\":\"BTCUSDT\",\"ps\":\"BTCUSDT\",\"b\":\"79596.90\",\"B\":\"6.956\",\"a\":\"79597.00\",\"A\":\"8.410\",\"T\":1788567784471,\"E\":1788567784471,\"st\":1}}"}
{"receive_ns":1788567784499556000,"stream":"btcusdt@bookTicker","event_type":"bookTicker","event_time_ms":1788567784482,"raw_json":"{\"stream\":\"btcusdt@bookTicker\",\"data\":{\"e\":\"bookTicker\",\"u\":11478511637386,\"s\":\"BTCUSDT\",\"ps\":\"BTCUSDT\",\"b\":\"79596.90\",\"B\":\"6.956\",\"a\":\"79597.00\",\"A\":\"6.891\",\"T\":1788567784482,\"E\":1788567784482,\"st\":1}}"}
{"receive_ns":1788567784505116000,"stream":"btcusdt@bookTicker","event_type":"bookTicker","event_time_ms":1788567784482,"raw_json":"{\"stream\":\"btcusdt@bookTicker\",\"data\":{\"e\":\"bookTicker\",\"u\":11478511637387,\"s\":\"BTCUSDT\",\"ps\":\"BTCUSDT\",\"b\":\"79596.90\",\"B\":\"6.956\",\"a\":\"79597.00\",\"A\":\"6.874\",\"T\":1788567784482,\"E\":1788567784482,\"st\":1}}"}
{"receive_ns":1788567784510900000,"stream":"btcusdt@bookTicker","event_type":"bookTicker","event_time_ms":1788567784482,"raw_json":"{\"stream\":\"btcusdt@bookTicker\",\"data\":{\"e\":\"bookTicker\",\"u\":11478511637390,\"s\":\"BTCUSDT\",\"ps\":\"BTCUSDT\",\"b\":\"79596.90\",\"B\":\"6.956\",\"a\":\"79597.00\",\"A\":\"6.716\",\"T\":1788567784482,\"E\":1788567784482,\"st\":1}}"}
{"receive_ns":1788567784521549000,"stream":"btcusdt@bookTicker","event_type":"bookTicker","event_time_ms":1788567784483,"raw_json":"{\"stream\":\"btcusdt@bookTicker\",\"data\":{\"e\":\"bookTicker\",\"u\":11478511637412,\"s\":\"BTCUSDT\",\"ps\":\"BTCUSDT\",\"b\":\"79596.90\",\"B\":\"6.956\",\"a\":\"79597.00\",\"A\":\"6.714\",\"T\":1788567784483,\"E\":1788567784483,\"st\":1}}"}
{"receive_ns":1788567784538198000,"stream":"btcusdt@bookTicker","event_type":"bookTicker","event_time_ms":1788567784484,"raw_json":"{\"stream\":\"btcusdt@bookTicker\",\"data\":{\"e\":\"bookTicker\",\"u\":11478511637475,\"s\":\"BTCUSDT\",\"ps\":\"BTCUSDT\",\"b\":\"79596.90\",\"B\":\"6.956\",\"a\":\"79597.00\",\"A\":\"6.712\",\"T\":1788567784483,\"E\":1788567784484,\"st\":1}}"}
{"receive_ns":1788567784557309000,"stream":"btcusdt@bookTicker","event_type":"bookTicker","event_time_ms":1788567784486,"raw_json":"{\"stream\":\"btcusdt@bookTicker\",\"data\":{\"e\":\"bookTicker\",\"u\":11478511637611,\"s\":\"BTCUSDT\",\"ps\":\"BTCUSDT\",\"b\":\"79596.90\",\"B\":\"6.956\",\"a\":\"79597.00\",\"A\":\"6.630\",\"T\":1788567784485,\"E\":1788567784486,\"st\":1}}"}
{"receive_ns":1788567784562147000,"stream":"btcusdt@bookTicker","event_type":"bookTicker","event_time_ms":1788567784486,"raw_json":"{\"stream\":\"btcusdt@bookTicker\",\"data\":{\"e\":\"bookTicker\",\"u\":11478511637612,\"s\":\"BTCUSDT\",\"ps\":\"BTCUSDT\",\"b\":\"79596.90\",\"B\":\"6.956\",\"a\":\"79597.00\",\"A\":\"6.548\",\"T\":1788567784485,\"E\":1788567784486,\"st\":1}}"}
{"receive_ns":1788567784567911000,"stream":"btcusdt@bookTicker","event_type":"bookTicker","event_time_ms":1788567784486,"raw_json":"{\"stream\":\"btcusdt@bookTicker\",\"data\":{\"e\":\"bookTicker\",\"u\":11478511637614,\"s\":\"BTCUSDT\",\"ps\":\"BTCUSDT\",\"b\":\"79596.90\",\"B\":\"6.956\",\"a\":\"79597.00\",\"A\":\"6.466\",\"T\":1788567784485,\"E\":1788567784486,\"st\":1}}"}
{"receive_ns":1788567784579339000,"stream":"btcusdt@bookTicker","event_type":"bookTicker","event_time_ms":1788567784517,"raw_json":"{\"stream\":\"btcusdt@bookTicker\",\"data\":{\"e\":\"bookTicker\",\"u\":11478511640269,\"s\":\"BTCUSDT\",\"ps\":\"BTCUSDT\",\"b\":\"79596.90\",\"B\":\"6.937\",\"a\":\"79597.00\",\"A\":\"6.466\",\"T\":1788567784517,\"E\":1788567784517,\"st\":1}}"}
{"receive_ns":1788567784595483000,"stream":"btcusdt@trade","event_type":"trade","event_time_ms":1788567784517,"raw_json":"{\"stream\":\"btcusdt@trade\",\"data\":{\"e\":\"trade\",\"E\":1788567784517,\"T\":1788567784517,\"s\":\"BTCUSDT\",\"t\":8054122858,\"p\":\"79596.90\",\"q\":\"0.019\",\"X\":\"MARKET\",\"m\":true,\"st\":1}}"}
{"receive_ns":1788567784613349000,"stream":"btcusdt@depth@100ms","event_type":"depthUpdate","event_time_ms":1788567784527,"raw_json":"{\"stream\":\"btcusdt@depth@100ms\",\"data\":{\"e\":\"depthUpdate\",\"E\":1788567784527,\"T\":1788567784525,\"s\":\"BTCUSDT\",\"ps\":\"BTCUSDT\",\"U\":11478511634280,\"u\":11478511641075,\"pu\":11478511634069,\"b\":[[\"1000.00\",\"24.604\"],[\"29096.90\",\"1.386\"],[\"29496.90\",\"0.714\"],[\"71637.20\",\"0.002\"],[\"71673.00\",\"0.000\"],[\"76413.00\",\"0.023\"],[\"77925.40\",\"1.538\"],[\"78005.00\",\"0.228\"],[\"78800.90\",\"12.254\"],[\"78960.10\",\"8.335\"],[\"79510.90\",\"0.023\"],[\"79538.00\",\"0.001\"],[\"79550.10\",\"0.001\"],[\"79562.30\",\"0.001\"],[\"79572.60\",\"0.000\"],[\"79578.20\",\"0.002\"],[\"79593.00\",\"0.055\"],[\"79596.90\",\"6.937\"]],\"a\":[[\"79597.00\",\"6.466\"],[\"79597.10\",\"0.741\"],[\"79597.20\",\"0.248\"],[\"79598.00\",\"0.107\"],[\"79598.60\",\"0.027\"],[\"79599.20\",\"0.026\"],[\"79599.30\",\"0.044\"],[\"79600.20\",\"0.001\"],[\"79600.30\",\"0.004\"],[\"79602.70\",\"0.256\"],[\"79604.20\",\"0.007\"],[\"79605.30\",\"0.054\"],[\"79605.60\",\"1.892\"],[\"79612.20\",\"0.004\"],[\"79617.30\",\"0.064\"],[\"79628.00\",\"1.697\"],[\"79628.10\",\"0.001\"],[\"79644.90\",\"0.003\"],[\"79660.80\",\"0.350\"],[\"79666.10\",\"21.640\"],[\"79668.50\",\"2.666\"],[\"79668.80\",\"0.034\"],[\"80393.00\",\"15.389\"]],\"st\":1}}"}
{"receive_ns":1788567784640634000,"stream":"btcusdt@bookTicker","event_type":"bookTicker","event_time_ms":1788567784540,"raw_json":"{\"stream\":\"btcusdt@bookTicker\",\"data\":{\"e\":\"bookTicker\",\"u\":11478511641895,\"s\":\"BTCUSDT\",\"ps\":\"BTCUSDT\",\"b\":\"79596.90\",\"B\":\"6.937\",\"a\":\"79597.00\",\"A\":\"6.456\",\"T\":1788567784540,\"E\":1788567784540,\"st\":1}}"}
{"receive_ns":1788567784652584000,"stream":"btcusdt@bookTicker","event_type":"bookTicker","event_time_ms":1788567784543,"raw_json":"{\"stream\":\"btcusdt@bookTicker\",\"data\":{\"e\":\"bookTicker\",\"u\":11478511642012,\"s\":\"BTCUSDT\",\"ps\":\"BTCUSDT\",\"b\":\"79596.90\",\"B\":\"6.937\",\"a\":\"79597.00\",\"A\":\"6.462\",\"T\":1788567784543,\"E\":1788567784543,\"st\":1}}"}
{"receive_ns":1788567784664819000,"stream":"btcusdt@depth@100ms","event_type":"depthUpdate","event_time_ms":1788567784629,"raw_json":"{\"stream\":\"btcusdt@depth@100ms\",\"data\":{\"e\":\"depthUpdate\",\"E\":1788567784629,\"T\":1788567784627,\"s\":\"BTCUSDT\",\"ps\":\"BTCUSDT\",\"U\":11478511641195,\"u\":11478511646064,\"pu\":11478511641075,\"b\":[[\"29096.90\",\"1.211\"],[\"29496.90\",\"0.889\"],[\"63678.00\",\"0.010\"],[\"71637.20\",\"0.002\"],[\"76413.00\",\"0.025\"],[\"78243.80\",\"8.611\"],[\"78363.10\",\"4.142\"],[\"78442.70\",\"12.514\"],[\"78681.50\",\"5.690\"],[\"78800.90\",\"12.254\"],[\"78846.70\",\"0.000\"],[\"79537.70\",\"3.501\"],[\"79539.00\",\"1.328\"],[\"79557.60\",\"0.563\"],[\"79570.10\",\"0.453\"],[\"79571.10\",\"0.000\"],[\"79574.00\",\"0.128\"],[\"79575.70\",\"0.002\"],[\"79576.50\",\"0.006\"],[\"79587.10\",\"0.001\"],[\"79596.80\",\"0.157\"]],\"a\":[[\"79597.00\",\"6.462\"],[\"79597.40\",\"0.031\"],[\"79597.50\",\"0.040\"],[\"79600.00\",\"0.049\"],[\"79600.10\",\"0.002\"],[\"79640.60\",\"0.553\"],[\"79660.50\",\"5.068\"],[\"79688.40\",\"6.000\"],[\"80393.00\",\"15.389\"],[\"80751.20\",\"14.375\"]],\"st\":1}}"}
{"receive_ns":1788567784711901000,"stream":"btcusdt@bookTicker","event_type":"bookTicker","event_time_ms":1788567784724,"raw_json":"{\"stream\":\"btcusdt@bookTicker\",\"data\":{\"e\":\"bookTicker\",\"u\":11478511652988,\"s\":\"BTCUSDT\",\"ps\":\"BTCUSDT\",\"b\":\"79596.90\",\"B\":\"6.937\",\"a\":\"79597.00\",\"A\":\"6.488\",\"T\":1788567784724,\"E\":1788567784724,\"st\":1}}"}
{"receive_ns":1788567784729873000,"stream":"btcusdt@depth@100ms","event_type":"depthUpdate","event_time_ms":1788567784731,"raw_json":"{\"stream\":\"btcusdt@depth@100ms\",\"data\":{\"e\":\"depthUpdate\",\"E\":1788567784731,\"T\":1788567784730,\"s\":\"BTCUSDT\",\"ps\":\"BTCUSDT\",\"U\":11478511646142,\"u\":11478511653397,\"pu\":11478511646064,\"b\":[[\"1000.00\",\"24.604\"],[\"29096.90\",\"1.029\"],[\"29496.90\",\"1.071\"],[\"63678.00\",\"0.010\"],[\"71637.20\",\"0.002\"],[\"77607.00\",\"1.738\"],[\"78005.00\",\"0.225\"],[\"78363.10\",\"5.034\"],[\"78442.70\",\"14.296\"],[\"78482.50\",\"29.262\"],[\"78641.70\",\"33.554\"],[\"78681.50\",\"6.452\"],[\"78800.90\",\"12.254\"],[\"78840.70\",\"4.488\"],[\"79198.90\",\"3.971\"],[\"79572.90\",\"0.171\"],[\"79573.20\",\"0.538\"],[\"79574.00\",\"0.003\"],[\"79575.70\",\"0.008\"],[\"79576.40\",\"2.897\"],[\"79576.50\",\"0.000\"],[\"79577.40\",\"0.373\"],[\"79582.30\",\"0.195\"],[\"79591.70\",\"0.003\"],[\"79595.50\",\"0.026\"],[\"79595.60\",\"0.038\"],[\"79596.30\",\"0.000\"],[\"79596.50\",\"0.444\"],[\"79596.70\",\"0.010\"]],\"a\":[[\"79597.00\",\"6.488\"],[\"79599.80\",\"0.001\"],[\"79610.50\",\"0.004\"],[\"79612.80\",\"0.442\"],[\"79616.30\",\"1.269\"],[\"79617.30\",\"0.436\"],[\"79630.90\",\"0.011\"],[\"79631.90\",\"0.046\"],[\"79666.10\",\"0.015\"],[\"79674.20\",\"21.626\"],[\"80393.00\",\"15.389\"],[\"80552.20\",\"33.693\"],[\"80711.40\",\"34.142\"],[\"80951.80\",\"0.987\"]],\"st\":1}}"}
{"receive_ns":1788567784753370000,"stream":"btcusdt@bookTicker","event_type":"bookTicker","event_time_ms":1788567784746,"raw_json":"{\"stream\":\"btcusdt@bookTicker\",\"data\":{\"e\":\"bookTicker\",\"u\":11478511654205,\"s\":\"BTCUSDT\",\"ps\":\"BTCUSDT\",\"b\":\"79596.90\",\"B\":\"6.937\",\"a\":\"79597.00\",\"A\":\"8.003\",\"T\":1788567784746,\"E\":1788567784746,\"st\":1}}"}
{"receive_ns":1788567784770149000,"stream":"btcusdt@bookTicker","event_type":"bookTicker","event_time_ms":1788567784766,"raw_json":"{\"stream\":\"btcusdt@bookTicker\",\"data\":{\"e\":\"bookTicker\",\"u\":11478511655316,\"s\":\"BTCUSDT\",\"ps\":\"BTCUSDT\",\"b\":\"79596.90\",\"B\":\"6.937\",\"a\":\"79597.00\",\"A\":\"8.155\",\"T\":1788567784766,\"E\":1788567784766,\"st\":1}}"}
{"receive_ns":1788567784800438000,"stream":"btcusdt@bookTicker","event_type":"bookTicker","event_time_ms":1788567784804,"raw_json":"{\"stream\":\"btcusdt@bookTicker\",\"data\":{\"e\":\"bookTicker\",\"u\":11478511657685,\"s\":\"BTCUSDT\",\"ps\":\"BTCUSDT\",\"b\":\"79596.90\",\"B\":\"6.937\",\"a\":\"79597.00\",\"A\":\"8.129\",\"T\":1788567784803,\"E\":1788567784804,\"st\":1}}"}
{"receive_ns":1788567784812155000,"stream":"btcusdt@bookTicker","event_type":"bookTicker","event_time_ms":1788567784825,"raw_json":"{\"stream\":\"btcusdt@bookTicker\",\"data\":{\"e\":\"bookTicker\",\"u\":11478511659101,\"s\":\"BTCUSDT\",\"ps\":\"BTCUSDT\",\"b\":\"79596.90\",\"B\":\"6.937\",\"a\":\"79597.00\",\"A\":\"8.144\",\"T\":1788567784825,\"E\":1788567784825,\"st\":1}}"}
{"receive_ns":1788567784826148000,"stream":"btcusdt@depth@100ms","event_type":"depthUpdate","event_time_ms":1788567784833,"raw_json":"{\"stream\":\"btcusdt@depth@100ms\",\"data\":{\"e\":\"depthUpdate\",\"E\":1788567784833,\"T\":1788567784831,\"s\":\"BTCUSDT\",\"ps\":\"BTCUSDT\",\"U\":11478511653468,\"u\":11478511659469,\"pu\":11478511653397,\"b\":[[\"1000.00\",\"24.604\"],[\"29096.90\",\"0.854\"],[\"29496.90\",\"1.246\"],[\"71637.20\",\"0.002\"],[\"76413.00\",\"0.023\"],[\"78482.50\",\"27.354\"],[\"78602.00\",\"9.477\"],[\"78641.70\",\"32.284\"],[\"78800.90\",\"13.521\"],[\"78999.90\",\"4.425\"],[\"79198.90\",\"3.970\"],[\"79568.90\",\"0.455\"],[\"79570.10\",\"0.001\"],[\"79572.10\",\"0.629\"],[\"79572.40\",\"0.128\"],[\"79572.90\",\"0.046\"],[\"79576.10\",\"0.382\"],[\"79576.80\",\"0.334\"],[\"79577.40\",\"0.000\"],[\"79578.80\",\"0.003\"],[\"79582.50\",\"0.204\"],[\"79585.00\",\"0.097\"],[\"79591.80\",\"0.076\"],[\"79592.00\",\"0.007\"],[\"79592.10\",\"0.002\"],[\"79595.70\",\"0.059\"],[\"79595.90\",\"0.002\"],[\"79596.50\",\"0.470\"],[\"79596.80\",\"0.183\"]],\"a\":[[\"79597.00\",\"8.144\"],[\"79597.40\",\"0.005\"],[\"79597.50\",\"0.014\"],[\"79598.70\",\"0.030\"],[\"79603.70\",\"0.053\"],[\"79603.90\",\"0.076\"],[\"79604.20\",\"0.008\"],[\"79605.30\",\"0.004\"],[\"79605.60\",\"1.891\"],[\"79609.50\",\"0.186\"],[\"79610.90\",\"0.442\"],[\"79612.50\",\"0.001\"],[\"79612.80\",\"0.003\"],[\"79616.00\",\"0.381\"],[\"79617.30\",\"0.064\"],[\"79630.50\",\"0.046\"],[\"79631.90\",\"0.000\"],[\"79638.20\",\"0.542\"],[\"79668.80\",\"0.034\"],[\"79674.20\",\"0.001\"],[\"79676.90\",\"21.727\"],[\"79712.70\",\"0.088\"],[\"79943.00\",\"0.024\"],[\"79995.00\",\"4.696\"],[\"80194.00\",\"3.303\"],[\"80393.00\",\"15.389\"]],\"st\":1}}"}
{"receive_ns":1788567784865532000,"stream":"btcusdt@bookTicker","event_type":"bookTicker","event_time_ms":1788567784875,"raw_json":"{\"stream\":\"btcusdt@bookTicker\",\"data\":{\"e\":\"bookTicker\",\"u\":11478511662595,\"s\":\"BTCUSDT\",\"ps\":\"BTCUSDT\",\"b\":\"79596.90\",\"B\":\"6.937\",\"a\":\"79597.00\",\"A\":\"8.145\",\"T\":1788567784875,\"E\":1788567784875,\"st\":1}}"}
{"receive_ns":1788567784924476000,"stream":"btcusdt@depth@100ms","event_type":"depthUpdate","event_time_ms":1788567784935,"raw_json":"{\"stream\":\"btcusdt@depth@100ms\",\"data\":{\"e\":\"depthUpdate\",\"E\":1788567784935,\"T\":1788567784934,\"s\":\"BTCUSDT\",\"ps\":\"BTCUSDT\",\"U\":11478511659883,\"u\":11478511665363,\"pu\":11478511659469,\"b\":[[\"29096.90\",\"0.672\"],[\"29496.90\",\"1.428\"],[\"63678.00\",\"0.010\"],[\"71637.20\",\"0.002\"],[\"76413.00\",\"0.025\"],[\"78482.50\",\"29.263\"],[\"78551.00\",\"116.058\"],[\"78641.70\",\"33.554\"],[\"78800.90\",\"13.521\"],[\"78811.10\",\"92.700\"],[\"79198.90\",\"3.971\"],[\"79525.20\",\"0.000\"],[\"79541.10\",\"1.098\"],[\"79572.40\",\"0.003\"],[\"79573.20\",\"0.538\"],[\"79576.10\",\"0.382\"],[\"79576.80\",\"0.330\"],[\"79577.20\",\"0.000\"],[\"79585.00\",\"0.097\"]],\"a\":[[\"79597.00\",\"8.145\"],[\"79597.70\",\"0.026\"],[\"79613.10\",\"0.194\"],[\"79616.00\",\"0.009\"],[\"79617.20\",\"0.372\"],[\"79630.50\",\"0.046\"],[\"79631.70\",\"0.000\"],[\"79668.70\",\"2.054\"],[\"79671.50\",\"21.625\"],[\"79676.90\",\"0.102\"],[\"79995.00\",\"4.697\"],[\"80393.00\",\"15.389\"],[\"80393.10\",\"98.849\"],[\"80549.60\",\"3.722\"],[\"80592.10\",\"5.810\"],[\"80658.40\",\"116.670\"],[\"80910.40\",\"1.728\"],[\"81268.60\",\"0.003\"]],\"st\":1}}"}
{"receive_ns":1788567784935876000,"stream":"btcusdt@bookTicker","event_type":"bookTicker","event_time_ms":1788567784940,"raw_json":"{\"stream\":\"btcusdt@bookTicker\",\"data\":{\"e\":\"bookTicker\",\"u\":11478511665714,\"s\":\"BTCUSDT\",\"ps\":\"BTCUSDT\",\"b\":\"79596.90\",\"B\":\"6.937\",\"a\":\"79597.00\",\"A\":\"8.143\",\"T\":1788567784939,\"E\":1788567784940,\"st\":1}}"}
{"receive_ns":1788567784948111000,"stream":"btcusdt@trade","event_type":"trade","event_time_ms":1788567784940,"raw_json":"{\"stream\":\"btcusdt@trade\",\"data\":{\"e\":\"trade\",\"E\":1788567784940,\"T\":1788567784939,\"s\":\"BTCUSDT\",\"t\":8054122859,\"p\":\"79597.00\",\"q\":\"0.002\",\"X\":\"MARKET\",\"m\":false,\"st\":1}}"}
{"receive_ns":1788567785024066000,"stream":"btcusdt@depth@100ms","event_type":"depthUpdate","event_time_ms":1788567785037,"raw_json":"{\"stream\":\"btcusdt@depth@100ms\",\"data\":{\"e\":\"depthUpdate\",\"E\":1788567785037,\"T\":1788567785036,\"s\":\"BTCUSDT\",\"ps\":\"BTCUSDT\",\"U\":11478511665423,\"u\":11478511670803,\"pu\":11478511665363,\"b\":[[\"1000.00\",\"24.604\"],[\"29096.90\",\"0.497\"],[\"29496.90\",\"1.603\"],[\"63678.00\",\"0.010\"],[\"71637.20\",\"0.002\"],[\"76413.00\",\"0.023\"],[\"78005.20\",\"1.758\"],[\"78093.60\",\"0.029\"],[\"78182.00\",\"0.098\"],[\"78270.50\",\"0.028\"],[\"78358.90\",\"0.028\"],[\"78447.40\",\"0.029\"],[\"78535.80\",\"0.678\"],[\"78602.00\",\"9.192\"],[\"78624.20\",\"0.031\"],[\"78712.70\",\"0.028\"],[\"78800.90\",\"13.521\"],[\"78801.10\",\"0.028\"],[\"78942.10\",\"0.000\"],[\"79198.90\",\"3.971\"],[\"79573.40\",\"0.001\"],[\"79573.50\",\"0.001\"],[\"79576.80\",\"0.334\"],[\"79582.60\",\"0.074\"],[\"79593.00\",\"0.131\"]],\"a\":[[\"79597.00\",\"8.143\"],[\"79597.70\",\"0.000\"],[\"79598.00\",\"0.081\"],[\"79616.10\",\"0.381\"],[\"79617.20\",\"0.000\"],[\"79636.20\",\"0.001\"],[\"79636.50\",\"0.572\"],[\"79644.80\",\"0.274\"],[\"79806.10\",\"2.769\"],[\"80393.00\",\"15.389\"],[\"80393.10\",\"98.877\"],[\"80481.50\",\"0.028\"],[\"80570.00\",\"0.864\"],[\"80658.40\",\"116.698\"],[\"80746.80\",\"0.028\"],[\"80835.30\",\"0.032\"],[\"80923.70\",\"0.028\"],[\"81012.20\",\"0.028\"],[\"81100.60\",\"0.028\"],[\"81188.90\",\"0.006\"],[\"81189.00\",\"1.565\"]],\"st\":1}}"}
{"receive_ns":1788567785042731000,"stream":"btcusdt@bookTicker","event_type":"bookTicker","event_time_ms":1788567785053,"raw_json":"{\"stream\":\"btcusdt@bookTicker\",\"data\":{\"e\":\"bookTicker\",\"u\":11478511671605,\"s\":\"BTCUSDT\",\"ps\":\"BTCUSDT\",\"b\":\"79596.90\",\"B\":\"6.937\",\"a\":\"79597.00\",\"A\":\"8.163\",\"T\":1788567785053,\"E\":1788567785053,\"st\":1}}"}
{"receive_ns":1788567785054222000,"stream":"btcusdt@bookTicker","event_type":"bookTicker","event_time_ms":1788567785065,"raw_json":"{\"stream\":\"btcusdt@bookTicker\",\"data\":{\"e\":\"bookTicker\",\"u\":11478511672942,\"s\":\"BTCUSDT\",\"ps\":\"BTCUSDT\",\"b\":\"79596.90\",\"B\":\"6.937\",\"a\":\"79597.00\",\"A\":\"8.165\",\"T\":1788567785065,\"E\":1788567785065,\"st\":1}}"}
{"receive_ns":1788567785112975000,"stream":"btcusdt@bookTicker","event_type":"bookTicker","event_time_ms":1788567785123,"raw_json":"{\"stream\":\"btcusdt@bookTicker\",\"data\":{\"e\":\"bookTicker\",\"u\":11478511677484,\"s\":\"BTCUSDT\",\"ps\":\"BTCUSDT\",\"b\":\"79596.90\",\"B\":\"6.926\",\"a\":\"79597.00\",\"A\":\"8.165\",\"T\":1788567785123,\"E\":1788567785123,\"st\":1}}"}
{"receive_ns":1788567785129538000,"stream":"btcusdt@bookTicker","event_type":"bookTicker","event_time_ms":1788567785126,"raw_json":"{\"stream\":\"btcusdt@bookTicker\",\"data\":{\"e\":\"bookTicker\",\"u\":11478511677763,\"s\":\"BTCUSDT\",\"ps\":\"BTCUSDT\",\"b\":\"79596.90\",\"B\":\"6.926\",\"a\":\"79597.00\",\"A\":\"8.166\",\"T\":1788567785125,\"E\":1788567785126,\"st\":1}}"}
{"receive_ns":1788567785140769000,"stream":"btcusdt@bookTicker","event_type":"bookTicker","event_time_ms":1788567785126,"raw_json":"{\"stream\":\"btcusdt@bookTicker\",\"data\":{\"e\":\"bookTicker\",\"u\":11478511677830,\"s\":\"BTCUSDT\",\"ps\":\"BTCUSDT\",\"b\":\"79596.90\",\"B\":\"6.929\",\"a\":\"79597.00\",\"A\":\"8.166\",\"T\":1788567785126,\"E\":1788567785126,\"st\":1}}"}
{"receive_ns":1788567785146554000,"stream":"btcusdt@depth@100ms","event_type":"depthUpdate","event_time_ms":1788567785139,"raw_json":"{\"stream\":\"btcusdt@depth@100ms\",\"data\":{\"e\":\"depthUpdate\",\"E\":1788567785139,\"T\":1788567785138,\"s\":\"BTCUSDT\",\"ps\":\"BTCUSDT\",\"U\":11478511670945,\"u\":11478511679179,\"pu\":11478511670803,\"b\":[[\"1000.00\",\"24.604\"],[\"29096.90\",\"0.329\"],[\"29396.90\",\"0.014\"],[\"29496.90\",\"1.757\"],[\"63677.50\",\"0.000\"],[\"63678.00\",\"0.010\"],[\"71637.20\",\"0.002\"],[\"75617.10\",\"0.006\"],[\"78482.50\",\"31.171\"],[\"78641.70\",\"34.824\"],[\"78800.90\",\"13.521\"],[\"79573.90\",\"0.363\"],[\"79582.60\",\"0.070\"],[\"79596.90\",\"6.929\"]],\"a\":[[\"79597.00\",\"8.166\"],[\"79598.80\",\"0.029\"],[\"79617.20\",\"0.002\"],[\"79617.30\",\"0.066\"],[\"79636.30\",\"0.221\"],[\"79636.70\",\"0.000\"],[\"79806.10\",\"4.789\"],[\"80194.00\",\"3.926\"],[\"80393.00\",\"15.389\"],[\"80910.40\",\"2.592\"],[\"81188.90\",\"0.009\"],[\"81586.90\",\"1.347\"]],\"st\":1}}"}
{"receive_ns":1788567785220846000,"stream":"btcusdt@bookTicker","event_type":"bookTicker","event_time_ms":1788567785235,"raw_json":"{\"stream\":\"btcusdt@bookTicker\",\"data\":{\"e\":\"bookTicker\",\"u\":11478511686372,\"s\":\"BTCUSDT\",\"ps\":\"BTCUSDT\",\"b\":\"79596.90\",\"B\":\"6.929\",\"a\":\"79597.00\",\"A\":\"8.167\",\"T\":1788567785235,\"E\":1788567785235,\"st\":1}}"}
{"receive_ns":1788567785232446000,"stream":"btcusdt@depth@100ms","event_type":"depthUpdate","event_time_ms":1788567785241,"raw_json":"{\"stream\":\"btcusdt@depth@100ms\",\"data\":{\"e\":\"depthUpdate\",\"E\":1788567785241,\"T\":1788567785238,\"s\":\"BTCUSDT\",\"ps\":\"BTCUSDT\",\"U\":11478511679354,\"u\":11478511686505,\"pu\":11478511679179,\"b\":[[\"29096.90\",\"0.210\"],[\"29396.90\",\"0.070\"],[\"29496.90\",\"1.820\"],[\"71637.20\",\"0.002\"],[\"76413.00\",\"0.025\"],[\"78800.90\",\"13.521\"],[\"78963.80\",\"0.000\"],[\"79566.60\",\"0.171\"],[\"79567.10\",\"0.001\"],[\"79572.90\",\"0.171\"],[\"79593.00\",\"0.055\"],[\"79596.70\",\"0.029\"],[\"79596.80\",\"0.183\"]],\"a\":[[\"79597.00\",\"8.167\"],[\"79597.30\",\"0.100\"],[\"79597.90\",\"0.028\"],[\"79636.90\",\"0.189\"],[\"79697.00\",\"0.135\"],[\"79819.10\",\"7.126\"],[\"80194.00\",\"4.549\"],[\"80393.00\",\"15.389\"]],\"st\":1}}"}
{"receive_ns":1788567785286164000,"stream":"btcusdt@bookTicker","event_type":"bookTicker","event_time_ms":1788567785301,"raw_json":"{\"stream\":\"btcusdt@bookTicker\",\"data\":{\"e\":\"bookTicker\",\"u\":11478511690441,\"s\":\"BTCUSDT\",\"ps\":\"BTCUSDT\",\"b\":\"79596.90\",\"B\":\"6.929\",\"a\":\"79597.00\",\"A\":\"8.107\",\"T\":1788567785301,\"E\":1788567785301,\"st\":1}}"}
{"receive_ns":1788567785303038000,"stream":"btcusdt@trade","event_type":"trade","event_time_ms":1788567785301,"raw_json":"{\"stream\":\"btcusdt@trade\",\"data\":{\"e\":\"trade\",\"E\":1788567785301,\"T\":1788567785301,\"s\":\"BTCUSDT\",\"t\":8054122860,\"p\":\"79597.00\",\"q\":\"0.060\",\"X\":\"MARKET\",\"m\":false,\"st\":1}}"}
{"receive_ns":1788567785336054000,"stream":"btcusdt@depth@100ms","event_type":"depthUpdate","event_time_ms":1788567785343,"raw_json":"{\"stream\":\"btcusdt@depth@100ms\",\"data\":{\"e\":\"depthUpdate\",\"E\":1788567785343,\"T\":1788567785341,\"s\":\"BTCUSDT\",\"ps\":\"BTCUSDT\",\"U\":11478511686867,\"u\":11478511694242,\"pu\":11478511686505,\"b\":[[\"1000.00\",\"24.604\"],[\"29096.90\",\"0.091\"],[\"29396.90\",\"0.133\"],[\"29496.90\",\"1.876\"],[\"71637.20\",\"0.002\"],[\"75617.10\",\"0.004\"],[\"75617.20\",\"0.010\"],[\"76413.00\",\"0.023\"],[\"78124.40\",\"0.832\"],[\"78130.20\",\"0.000\"],[\"78602.00\",\"8.907\"],[\"78735.20\",\"0.633\"],[\"78800.90\",\"13.521\"],[\"79198.90\",\"3.981\"],[\"79470.20\",\"10.001\"],[\"79471.80\",\"2.623\"],[\"79575.70\",\"0.381\"],[\"79576.10\",\"0.009\"],[\"79593.20\",\"0.076\"]],\"a\":[[\"79597.00\",\"8.107\"],[\"79597.90\",\"0.028\"],[\"79598.10\",\"0.026\"],[\"79598.30\",\"0.028\"],[\"79598.50\",\"0.026\"],[\"79599.60\",\"0.000\"],[\"79599.70\",\"0.000\"],[\"79632.10\",\"0.239\"],[\"79636.90\",\"0.064\"],[\"79637.90\",\"0.125\"],[\"79728.00\",\"2.839\"],[\"79728.20\",\"10.001\"],[\"80393.00\",\"15.389\"]],\"st\":1}}"}
{"receive_ns":1788567785405173000,"stream":"btcusdt@bookTicker","event_type":"bookTicker","event_time_ms":1788567785418,"raw_json":"{\"stream\":\"btcusdt@bookTicker\",\"data\":{\"e\":\"bookTicker\",\"u\":11478511699525,\"s\":\"BTCUSDT\",\"ps\":\"BTCUSDT\",\"b\":\"79596.90\",\"B\":\"6.929\",\"a\":\"79597.00\",\"A\":\"8.101\",\"T\":1788567785418,\"E\":1788567785418,\"st\":1}}"}
{"receive_ns":1788567785416289000,"stream":"btcusdt@bookTicker","event_type":"bookTicker","event_time_ms":1788567785421,"raw_json":"{\"stream\":\"btcusdt@bookTicker\",\"data\":{\"e\":\"bookTicker\",\"u\":11478511699654,\"s\":\"BTCUSDT\",\"ps\":\"BTCUSDT\",\"b\":\"79596.90\",\"B\":\"6.929\",\"a\":\"79597.00\",\"A\":\"8.123\",\"T\":1788567785421,\"E\":1788567785421,\"st\":1}}"}
{"receive_ns":1788567785428100000,"stream":"btcusdt@bookTicker","event_type":"bookTicker","event_time_ms":1788567785422,"raw_json":"{\"stream\":\"btcusdt@bookTicker\",\"data\":{\"e\":\"bookTicker\",\"u\":11478511699691,\"s\":\"BTCUSDT\",\"ps\":\"BTCUSDT\",\"b\":\"79596.90\",\"B\":\"6.929\",\"a\":\"79597.00\",\"A\":\"8.122\",\"T\":1788567785422,\"E\":1788567785422,\"st\":1}}"}
{"receive_ns":1788567785439298000,"stream":"btcusdt@bookTicker","event_type":"bookTicker","event_time_ms":1788567785422,"raw_json":"{\"stream\":\"btcusdt@bookTicker\",\"data\":{\"e\":\"bookTicker\",\"u\":11478511699701,\"s\":\"BTCUSDT\",\"ps\":\"BTCUSDT\",\"b\":\"79596.90\",\"B\":\"6.929\",\"a\":\"79597.00\",\"A\":\"8.123\",\"T\":1788567785422,\"E\":1788567785422,\"st\":1}}"}
{"receive_ns":1788567785454820000,"stream":"btcusdt@depth@100ms","event_type":"depthUpdate","event_time_ms":1788567785445,"raw_json":"{\"stream\":\"btcusdt@depth@100ms\",\"data\":{\"e\":\"depthUpdate\",\"E\":1788567785445,\"T\":1788567785442,\"s\":\"BTCUSDT\",\"ps\":\"BTCUSDT\",\"U\":11478511694346,\"u\":11478511700763,\"pu\":11478511694242,\"b\":[[\"1000.00\",\"24.604\"],[\"29096.90\",\"0.000\"],[\"29396.90\",\"0.217\"],[\"29496.90\",\"1.883\"],[\"71637.20\",\"0.002\"],[\"76413.00\",\"0.025\"],[\"78005.00\",\"0.222\"],[\"78488.70\",\"12.794\"],[\"78800.90\",\"13.521\"],[\"79437.70\",\"0.026\"],[\"79477.50\",\"0.000\"],[\"79525.20\",\"0.002\"],[\"79566.10\",\"0.049\"],[\"79566.60\",\"0.125\"],[\"79593.20\",\"0.000\"],[\"79596.80\",\"0.157\"]],\"a\":[[\"79597.00\",\"8.123\"],[\"79597.30\",\"0.126\"],[\"79599.50\",\"0.003\"],[\"79628.90\",\"0.031\"],[\"79637.40\",\"0.127\"],[\"79637.90\",\"0.000\"],[\"79659.20\",\"0.555\"],[\"79692.60\",\"0.004\"],[\"80393.00\",\"15.389\"],[\"81188.90\",\"0.012\"]],\"st\":1}}"}
{"receive_ns":1788567785460622000,"stream":"btcusdt@bookTicker","event_type":"bookTicker","event_time_ms":1788567785445,"raw_json":"{\"stream\":\"btcusdt@bookTicker\",\"data\":{\"e\":\"bookTicker\",\"u\":11478511701174,\"s\":\"BTCUSDT\",\"ps\":\"BTCUSDT\",\"b\":\"79596.90\",\"B\":\"6.929\",\"a\":\"79597.00\",\"A\":\"8.149\",\"T\":1788567785445,\"E\":1788567785445,\"st\":1}}"}
{"receive_ns":1788567785477313000,"stream":"btcusdt@bookTicker","event_type":"bookTicker","event_time_ms":1788567785472,"raw_json":"{\"stream\":\"btcusdt@bookTicker\",\"data\":{\"e\":\"bookTicker\",\"u\":11478511702800,\"s\":\"BTCUSDT\",\"ps\":\"BTCUSDT\",\"b\":\"79596.90\",\"B\":\"6.907\",\"a\":\"79597.00\",\"A\":\"8.149\",\"T\":1788567785472,\"E\":1788567785472,\"st\":1}}"}
{"receive_ns":1788567785488575000,"stream":"btcusdt@bookTicker","event_type":"bookTicker","event_time_ms":1788567785475,"raw_json":"{\"stream\":\"btcusdt@bookTicker\",\"data\":{\"e\":\"bookTicker\",\"u\":11478511702934,\"s\":\"BTCUSDT\",\"ps\":\"BTCUSDT\",\"b\":\"79596.90\",\"B\":\"6.931\",\"a\":\"79597.00\",\"A\":\"8.149\",\"T\":1788567785475,\"E\":1788567785475,\"st\":1}}"}
{"receive_ns":1788567785499288000,"stream":"btcusdt@bookTicker","event_type":"bookTicker","event_time_ms":1788567785478,"raw_json":"{\"stream\":\"btcusdt@bookTicker\",\"data\":{\"e\":\"bookTicker\",\"u\":11478511703172,\"s\":\"BTCUSDT\",\"ps\":\"BTCUSDT\",\"b\":\"79596.90\",\"B\":\"6.908\",\"a\":\"79597.00\",\"A\":\"8.149\",\"T\":1788567785478,\"E\":1788567785478,\"st\":1}}"}
{"receive_ns":1788567785510881000,"stream":"btcusdt@bookTicker","event_type":"bookTicker","event_time_ms":1788567785483,"raw_json":"{\"stream\":\"btcusdt@bookTicker\",\"data\":{\"e\":\"bookTicker\",\"u\":11478511703734,\"s\":\"BTCUSDT\",\"ps\":\"BTCUSDT\",\"b\":\"79596.90\",\"B\":\"6.935\",\"a\":\"79597.00\",\"A\":\"8.149\",\"T\":1788567785483,\"E\":1788567785483,\"st\":1}}"}
{"receive_ns":1788567785540629000,"stream":"btcusdt@depth@100ms","event_type":"depthUpdate","event_time_ms":1788567785547,"raw_json":"{\"stream\":\"btcusdt@depth@100ms\",\"data\":{\"e\":\"depthUpdate\",\"E\":1788567785547,\"T\":1788567785546,\"s\":\"BTCUSDT\",\"ps\":\"BTCUSDT\",\"U\":11478511701174,\"u\":11478511708703,\"pu\":11478511700763,\"b\":[[\"29396.90\",\"0.399\"],[\"29496.90\",\"1.701\"],[\"71637.20\",\"0.002\"],[\"71673.00\",\"0.000\"],[\"78214.10\",\"0.001\"],[\"78681.50\",\"5.690\"],[\"78729.30\",\"5.065\"],[\"78800.90\",\"13.521\"],[\"79538.40\",\"0.831\"],[\"79554.30\",\"0.691\"],[\"79566.10\",\"0.003\"],[\"79566.40\",\"0.047\"],[\"79567.40\",\"0.005\"],[\"79575.70\",\"0.381\"],[\"79576.80\",\"0.334\"],[\"79591.60\",\"0.076\"],[\"79591.80\",\"0.000\"],[\"79594.90\",\"0.026\"],[\"79595.90\",\"0.028\"],[\"79596.00\",\"0.108\"],[\"79596.50\",\"0.444\"],[\"79596.90\",\"6.935\"]],\"a\":[[\"79597.00\",\"8.149\"],[\"79599.30\",\"0.018\"],[\"79612.50\",\"0.692\"],[\"79615.60\",\"0.374\"],[\"79616.10\",\"0.009\"],[\"79616.70\",\"0.751\"],[\"79628.40\",\"0.829\"],[\"79630.10\",\"0.047\"],[\"79630.50\",\"0.000\"],[\"79631.20\",\"0.110\"],[\"79637.30\",\"0.012\"],[\"79637.40\",\"0.002\"],[\"79668.50\",\"5.738\"],[\"79806.10\",\"4.742\"],[\"80000.50\",\"12.820\"],[\"80393.00\",\"15.389\"]],\"st\":1}}"}
{"receive_ns":1788567785641726000,"stream":"btcusdt@depth@100ms","event_type":"depthUpdate","event_time_ms":1788567785649,"raw_json":"{\"stream\":\"btcusdt@depth@100ms\",\"data\":{\"e\":\"depthUpdate\",\"E\":1788567785649,\"T\":1788567785646,\"s\":\"BTCUSDT\",\"ps\":\"BTCUSDT\",\"U\":11478511708808,\"u\":11478511717603,\"pu\":11478511708703,\"b\":[[\"1000.00\",\"24.604\"],[\"29396.90\",\"0.574\"],[\"29496.90\",\"1.526\"],[\"63678.00\",\"0.010\"],[\"71637.20\",\"0.002\"],[\"76413.00\",\"0.023\"],[\"78681.50\",\"6.452\"],[\"78800.90\",\"12.254\"],[\"79198.90\",\"3.981\"]],\"a\":[[\"79615.60\",\"0.002\"],[\"79616.10\",\"0.381\"],[\"79630.10\",\"0.001\"],[\"79630.60\",\"0.073\"],[\"79632.30\",\"0.000\"],[\"80393.00\",\"15.389\"]],\"st\":1}}"}
{"receive_ns":1788567785672433000,"stream":"btcusdt@bookTicker","event_type":"bookTicker","event_time_ms":1788567785683,"raw_json":"{\"stream\":\"btcusdt@bookTicker\",\"data\":{\"e\":\"bookTicker\",\"u\":11478511719780,\"s\":\"BTCUSDT\",\"ps\":\"BTCUSDT\",\"b\":\"79596.90\",\"B\":\"6.935\",\"a\":\"79597.00\",\"A\":\"8.123\",\"T\":1788567785682,\"E\":1788567785683,\"st\":1}}"}
{"receive_ns":1788567785745413000,"stream":"btcusdt@depth@100ms","event_type":"depthUpdate","event_time_ms":1788567785751,"raw_json":"{\"stream\":\"btcusdt@depth@100ms\",\"data\":{\"e\":\"depthUpdate\",\"E\":1788567785751,\"T\":1788567785750,\"s\":\"BTCUSDT\",\"ps\":\"BTCUSDT\",\"U\":11478511717753,\"u\":11478511724079,\"pu\":11478511717603,\"b\":[[\"1000.00\",\"24.604\"],[\"29396.90\",\"0.756\"],[\"29496.90\",\"1.344\"],[\"71637.20\",\"0.002\"],[\"75617.20\",\"0.006\"],[\"76413.00\",\"0.025\"],[\"78560.70\",\"0.003\"],[\"78601.90\",\"11.779\"],[\"78641.70\",\"33.554\"],[\"78800.90\",\"12.254\"],[\"79475.60\",\"0.439\"],[\"79495.00\",\"0.175\"],[\"79506.70\",\"0.001\"],[\"79506.80\",\"4.385\"],[\"79507.80\",\"1.347\"],[\"79568.40\",\"0.007\"],[\"79593.20\",\"0.076\"],[\"79594.60\",\"0.027\"],[\"79594.80\",\"0.000\"],[\"79596.40\",\"0.108\"],[\"79596.80\",\"0.183\"]],\"a\":[[\"79597.00\",\"8.123\"],[\"79597.30\",\"0.100\"],[\"79597.90\",\"0.002\"],[\"79598.10\",\"0.000\"],[\"79598.30\",\"0.002\"],[\"79598.50\",\"0.000\"],[\"79598.60\",\"0.001\"],[\"79598.70\",\"0.004\"],[\"79598.80\",\"0.003\"],[\"79599.30\",\"0.044\"],[\"79599.40\",\"0.026\"],[\"79599.50\",\"0.029\"],[\"79599.70\",\"0.026\"],[\"79599.80\",\"0.027\"],[\"79599.90\",\"0.028\"],[\"79600.00\",\"0.075\"],[\"79638.50\",\"0.130\"],[\"79688.30\",\"3.179\"],[\"79718.90\",\"0.471\"],[\"79819.10\",\"7.111\"],[\"80230.30\",\"0.000\"],[\"80393.00\",\"15.389\"]],\"st\":1}}"}
{"receive_ns":1788567785780627000,"stream":"btcusdt@bookTicker","event_type":"bookTicker","event_time_ms":1788567785792,"raw_json":"{\"stream\":\"btcusdt@bookTicker\",\"data\":{\"e\":\"bookTicker\",\"u\":11478511726286,\"s\":\"BTCUSDT\",\"ps\":\"BTCUSDT\",\"b\":\"79596.90\",\"B\":\"6.935\",\"a\":\"79597.00\",\"A\":\"8.070\",\"T\":1788567785792,\"E\":1788567785792,\"st\":1}}"}
{"receive_ns":1788567785787000000,"stream":"btcusdt@trade","event_type":"trade","event_time_ms":1788567785792,"raw_json":"{\"stream\":\"btcusdt@trade\",\"data\":{\"e\":\"trade\",\"E\":1788567785792,\"T\":1788567785792,\"s\":\"BTCUSDT\",\"t\":8054122861,\"p\":\"79597.00\",\"q\":\"0.053\",\"X\":\"MARKET\",\"m\":false,\"st\":1}}"}
{"receive_ns":1788567785846572000,"stream":"btcusdt@depth@100ms","event_type":"depthUpdate","event_time_ms":1788567785853,"raw_json":"{\"stream\":\"btcusdt@depth@100ms\",\"data\":{\"e\":\"depthUpdate\",\"E\":1788567785853,\"T\":1788567785850,\"s\":\"BTCUSDT\",\"ps\":\"BTCUSDT\",\"U\":11478511724186,\"u\":11478511729948,\"pu\":11478511724079,\"b\":[[\"29396.90\",\"0.931\"],[\"29496.90\",\"1.169\"],[\"71637.20\",\"0.002\"],[\"76413.00\",\"0.023\"],[\"78363.10\",\"4.142\"],[\"78442.70\",\"13.405\"],[\"78464.20\",\"0.000\"],[\"78681.50\",\"5.690\"],[\"78735.20\",\"0.000\"],[\"78800.90\",\"12.254\"],[\"79198.90\",\"3.981\"],[\"79520.30\",\"0.000\"],[\"79520.40\",\"0.054\"],[\"79576.80\",\"0.016\"],[\"79581.90\",\"0.672\"],[\"79585.00\",\"0.415\"],[\"79585.30\",\"0.091\"]],\"a\":[[\"79597.00\",\"8.070\"],[\"79599.20\",\"0.000\"],[\"79599.30\",\"0.018\"],[\"79599.40\",\"0.000\"],[\"79599.50\",\"0.029\"],[\"79599.60\",\"0.026\"],[\"79599.70\",\"0.026\"],[\"79599.80\",\"0.001\"],[\"79600.10\",\"0.028\"],[\"79600.20\",\"0.027\"],[\"79600.40\",\"0.034\"],[\"79600.50\",\"0.104\"],[\"79600.60\",\"0.026\"],[\"79600.70\",\"0.004\"],[\"79638.50\",\"0.005\"],[\"80393.00\",\"15.389\"],[\"80727.40\",\"1.044\"]],\"st\":1}}"}
{"receive_ns":1788567785859017000,"stream":"btcusdt@bookTicker","event_type":"bookTicker","event_time_ms":1788567785866,"raw_json":"{\"stream\":\"btcusdt@bookTicker\",\"data\":{\"e\":\"bookTicker\",\"u\":11478511730932,\"s\":\"BTCUSDT\",\"ps\":\"BTCUSDT\",\"b\":\"79596.90\",\"B\":\"6.941\",\"a\":\"79597.00\",\"A\":\"8.070\",\"T\":1788567785866,\"E\":1788567785866,\"st\":1}}"}
{"receive_ns":1788567785945339000,"stream":"btcusdt@depth@100ms","event_type":"depthUpdate","event_time_ms":1788567785955,"raw_json":"{\"stream\":\"btcusdt@depth@100ms\",\"data\":{\"e\":\"depthUpdate\",\"E\":1788567785955,\"T\":1788567785953,\"s\":\"BTCUSDT\",\"ps\":\"BTCUSDT\",\"U\":11478511730114,\"u\":11478511736252,\"pu\":11478511729948,\"b\":[[\"1000.00\",\"24.604\"],[\"29396.90\",\"1.113\"],[\"29496.90\",\"0.987\"],[\"71637.20\",\"0.002\"],[\"76413.00\",\"0.025\"],[\"78442.70\",\"12.514\"],[\"78641.70\",\"34.824\"],[\"78681.50\",\"4.928\"],[\"78800.90\",\"12.254\"],[\"79198.90\",\"3.981\"],[\"79573.20\",\"0.538\"],[\"79576.80\",\"0.016\"],[\"79584.50\",\"0.078\"],[\"79585.00\",\"0.035\"],[\"79585.50\",\"0.333\"],[\"79586.10\",\"0.381\"],[\"79596.90\",\"6.941\"]],\"a\":[[\"79599.50\",\"0.003\"],[\"79599.60\",\"0.000\"],[\"79599.70\",\"0.000\"],[\"79600.70\",\"0.030\"],[\"79613.10\",\"0.194\"],[\"79637.60\",\"0.010\"],[\"79806.10\",\"4.789\"],[\"79995.00\",\"4.697\"],[\"80393.00\",\"15.389\"],[\"83576.80\",\"0.020\"]],\"st\":1}}"}
{"receive_ns":1788567786009256000,"stream":"btcusdt@bookTicker","event_type":"bookTicker","event_time_ms":1788567786016,"raw_json":"{\"stream\":\"btcusdt@bookTicker\",\"data\":{\"e\":\"bookTicker\",\"u\":11478511740752,\"s\":\"BTCUSDT\",\"ps\":\"BTCUSDT\",\"b\":\"79596.90\",\"B\":\"6.941\",\"a\":\"79597.00\",\"A\":\"8.067\",\"T\":1788567786016,\"E\":1788567786016,\"st\":1}}"}
{"receive_ns":1788567786015839000,"stream":"btcusdt@trade","event_type":"trade","event_time_ms":1788567786016,"raw_json":"{\"stream\":\"btcusdt@trade\",\"data\":{\"e\":\"trade\",\"E\":1788567786016,\"T\":1788567786016,\"s\":\"BTCUSDT\",\"t\":8054122862,\"p\":\"79597.00\",\"q\":\"0.003\",\"X\":\"MARKET\",\"m\":false,\"st\":1}}"}
{"receive_ns":1788567786045830000,"stream":"btcusdt@depth@100ms","event_type":"depthUpdate","event_time_ms":1788567786057,"raw_json":"{\"stream\":\"btcusdt@depth@100ms\",\"data\":{\"e\":\"depthUpdate\",\"E\":1788567786057,\"T\":1788567786056,\"s\":\"BTCUSDT\",\"ps\":\"BTCUSDT\",\"U\":11478511736343,\"u\":11478511743255,\"pu\":11478511736252,\"b\":[[\"1000.00\",\"24.604\"],[\"29396.90\",\"1.288\"],[\"29496.90\",\"0.812\"],[\"63678.00\",\"0.010\"],[\"71637.20\",\"0.002\"],[\"78363.10\",\"3.250\"],[\"78402.90\",\"4.994\"],[\"78482.50\",\"29.262\"],[\"78641.70\",\"33.554\"],[\"78729.30\",\"5.698\"],[\"78800.90\",\"12.254\"],[\"79576.80\",\"0.330\"],[\"79582.60\",\"0.070\"],[\"79586.10\",\"0.067\"],[\"79586.20\",\"0.002\"]],\"a\":[[\"79597.00\",\"8.067\"],[\"79600.30\",\"0.002\"],[\"79638.40\",\"0.000\"],[\"79806.10\",\"4.789\"],[\"80393.00\",\"15.389\"],[\"80558.40\",\"7.422\"]],\"st\":1}}"}
{"receive_ns":1788567786122503000,"stream":"btcusdt@bookTicker","event_type":"bookTicker","event_time_ms":1788567786132,"raw_json":"{\"stream\":\"btcusdt@bookTicker\",\"data\":{\"e\":\"bookTicker\",\"u\":11478511746826,\"s\":\"BTCUSDT\",\"ps\":\"BTCUSDT\",\"b\":\"79596.90\",\"B\":\"6.938\",\"a\":\"79597.00\",\"A\":\"8.067\",\"T\":1788567786131,\"E\":1788567786132,\"st\":1}}"}
{"receive_ns":1788567786134234000,"stream":"btcusdt@bookTicker","event_type":"bookTicker","event_time_ms":1788567786135,"raw_json":"{\"stream\":\"btcusdt@bookTicker\",\"data\":{\"e\":\"bookTicker\",\"u\":11478511746970,\"s\":\"BTCUSDT\",\"ps\":\"BTCUSDT\",\"b\":\"79596.90\",\"B\":\"6.947\",\"a\":\"79597.00\",\"A\":\"8.067\",\"T\":1788567786134,\"E\":1788567786135,\"st\":1}}"}
{"receive_ns":1788567786153998000,"stream":"btcusdt@depth@100ms","event_type":"depthUpdate","event_time_ms":1788567786159,"raw_json":"{\"stream\":\"btcusdt@depth@100ms\",\"data\":{\"e\":\"depthUpdate\",\"E\":1788567786159,\"T\":1788567786157,\"s\":\"BTCUSDT\",\"ps\":\"BTCUSDT\",\"U\":11478511743298,\"u\":11478511748059,\"pu\":11478511743255,\"b\":[[\"29396.90\",\"1.470\"],[\"29496.90\",\"0.630\"],[\"63677.50\",\"0.000\"],[\"63678.00\",\"0.010\"],[\"71637.20\",\"0.002\"],[\"76413.00\",\"0.023\"],[\"78442.70\",\"11.623\"],[\"78496.40\",\"0.000\"],[\"78800.90\",\"12.254\"],[\"79198.90\",\"3.971\"],[\"79501.30\",\"0.002\"],[\"79525.20\",\"0.000\"],[\"79541.10\",\"1.096\"],[\"79576.90\",\"0.006\"],[\"79582.30\",\"0.119\"],[\"79586.10\",\"0.063\"],[\"79594.30\",\"0.141\"],[\"79596.90\",\"6.947\"]],\"a\":[[\"79637.60\",\"0.010\"],[\"79637.70\",\"0.571\"],[\"79668.70\",\"2.054\"],[\"79692.60\",\"0.002\"],[\"80393.00\",\"15.389\"],[\"80709.60\",\"0.002\"],[\"81029.90\",\"1.069\"]],\"st\":1}}"}
{"receive_ns":1788567786231553000,"stream":"btcusdt@bookTicker","event_type":"bookTicker","event_time_ms":1788567786240,"raw_json":"{\"stream\":\"btcusdt@bookTicker\",\"data\":{\"e\":\"bookTicker\",\"u\":11478511752367,\"s\":\"BTCUSDT\",\"ps\":\"BTCUSDT\",\"b\":\"79596.90\",\"B\":\"6.928\",\"a\":\"79597.00\",\"A\":\"8.067\",\"T\":1788567786240,\"E\":1788567786240,\"st\":1}}"}
{"receive_ns":1788567786243155000,"stream":"btcusdt@trade","event_type":"trade","event_time_ms":1788567786240,"raw_json":"{\"stream\":\"btcusdt@trade\",\"data\":{\"e\":\"trade\",\"E\":1788567786240,\"T\":1788567786240,\"s\":\"BTCUSDT\",\"t\":8054122863,\"p\":\"79596.90\",\"q\":\"0.019\",\"X\":\"MARKET\",\"m\":true,\"st\":1}}"}
{"receive_ns":1788567786253803000,"stream":"btcusdt@bookTicker","event_type":"bookTicker","event_time_ms":1788567786243,"raw_json":"{\"stream\":\"btcusdt@bookTicker\",\"data\":{\"e\":\"bookTicker\",\"u\":11478511752743,\"s\":\"BTCUSDT\",\"ps\":\"BTCUSDT\",\"b\":\"79596.90\",\"B\":\"6.922\",\"a\":\"79597.00\",\"A\":\"8.067\",\"T\":1788567786243,\"E\":1788567786243,\"st\":1}}"}
{"receive_ns":1788567786260965000,"stream":"btcusdt@depth@100ms","event_type":"depthUpdate","event_time_ms":1788567786261,"raw_json":"{\"stream\":\"btcusdt@depth@100ms\",\"data\":{\"e\":\"depthUpdate\",\"E\":1788567786261,\"T\":1788567786258,\"s\":\"BTCUSDT\",\"ps\":\"BTCUSDT\",\"U\":11478511748134,\"u\":11478511753727,\"pu\":11478511748059,\"b\":[[\"1000.00\",\"24.604\"],[\"29396.90\",\"1.645\"],[\"29496.90\",\"0.455\"],[\"71637.20\",\"0.002\"],[\"76413.00\",\"0.025\"],[\"78432.80\",\"0.001\"],[\"78442.70\",\"12.514\"],[\"78681.50\",\"5.690\"],[\"78800.90\",\"12.254\"],[\"78960.10\",\"8.588\"],[\"79536.40\",\"0.000\"],[\"79568.40\",\"0.001\"],[\"79581.90\",\"0.323\"],[\"79585.30\",\"0.000\"],[\"79594.30\",\"0.065\"],[\"79596.90\",\"6.922\"]],\"a\":[[\"79599.60\",\"0.026\"],[\"79599.90\",\"0.002\"],[\"79600.80\",\"0.034\"],[\"79601.10\",\"0.011\"],[\"79626.40\",\"1.657\"],[\"79637.00\",\"0.002\"],[\"79724.60\",\"0.628\"],[\"79725.90\",\"0.032\"],[\"80393.00\",\"15.389\"],[\"81188.90\",\"0.015\"],[\"83097.90\",\"0.000\"],[\"83112.40\",\"0.100\"]],\"st\":1}}"}
{"receive_ns":1788567786353448000,"stream":"btcusdt@depth@100ms","event_type":"depthUpdate","event_time_ms":1788567786363,"raw_json":"{\"stream\":\"btcusdt@depth@100ms\",\"data\":{\"e\":\"depthUpdate\",\"E\":1788567786363,\"T\":1788567786362,\"s\":\"BTCUSDT\",\"ps\":\"BTCUSDT\",\"U\":11478511753869,\"u\":11478511758391,\"pu\":11478511753727,\"b\":[[\"1000.00\",\"24.604\"],[\"29296.90\",\"0.028\"],[\"29396.90\",\"1.771\"],[\"29496.90\",\"0.301\"],[\"71637.20\",\"0.002\"],[\"76413.00\",\"0.023\"],[\"78363.10\",\"5.034\"],[\"78426.80\",\"9.095\"],[\"78442.70\",\"14.296\"],[\"78482.50\",\"31.171\"],[\"78490.50\",\"7.350\"],[\"78641.70\",\"34.824\"],[\"78671.50\",\"0.127\"],[\"78681.50\",\"6.452\"],[\"78800.90\",\"12.254\"]],\"a\":[[\"79599.50\",\"0.029\"],[\"80233.80\",\"7.091\"],[\"80393.00\",\"15.389\"],[\"80703.40\",\"5.793\"],[\"87556.70\",\"0.000\"]],\"st\":1}}"}
{"receive_ns":1788567786479944000,"stream":"btcusdt@depth@100ms","event_type":"depthUpdate","event_time_ms":1788567786465,"raw_json":"{\"stream\":\"btcusdt@depth@100ms\",\"data\":{\"e\":\"depthUpdate\",\"E\":1788567786465,\"T\":1788567786462,\"s\":\"BTCUSDT\",\"ps\":\"BTCUSDT\",\"U\":11478511758458,\"u\":11478511762888,\"pu\":11478511758391,\"b\":[[\"29296.90\",\"0.084\"],[\"29396.90\",\"1.834\"],[\"29496.90\",\"0.182\"],[\"71637.20\",\"0.002\"],[\"76413.00\",\"0.025\"],[\"78283.60\",\"5.026\"],[\"78800.90\",\"12.254\"],[\"78960.10\",\"8.588\"],[\"79198.90\",\"3.971\"],[\"79572.90\",\"0.046\"]],\"a\":[[\"79599.50\",\"0.003\"],[\"79599.60\",\"0.000\"],[\"79635.90\",\"1.053\"],[\"79636.10\",\"0.129\"],[\"79636.60\",\"0.197\"],[\"80393.00\",\"15.389\"],[\"80966.10\",\"1.494\"]],\"st\":1}}"}
{"receive_ns":1788567786504142000,"stream":"btcusdt@bookTicker","event_type":"bookTicker","event_time_ms":1788567786493,"raw_json":"{\"stream\":\"btcusdt@bookTicker\",\"data\":{\"e\":\"bookTicker\",\"u\":11478511764818,\"s\":\"BTCUSDT\",\"ps\":\"BTCUSDT\",\"b\":\"79596.90\",\"B\":\"6.895\",\"a\":\"79597.00\",\"A\":\"8.067\",\"T\":1788567786493,\"E\":1788567786493,\"st\":1}}"}
{"receive_ns":1788567786510287000,"stream":"btcusdt@bookTicker","event_type":"bookTicker","event_time_ms":1788567786497,"raw_json":"{\"stream\":\"btcusdt@bookTicker\",\"data\":{\"e\":\"bookTicker\",\"u\":11478511765086,\"s\":\"BTCUSDT\",\"ps\":\"BTCUSDT\",\"b\":\"79596.90\",\"B\":\"6.917\",\"a\":\"79597.00\",\"A\":\"8.067\",\"T\":1788567786496,\"E\":1788567786497,\"st\":1}}"}
{"receive_ns":1788567786556245000,"stream":"btcusdt@depth@100ms","event_type":"depthUpdate","event_time_ms":1788567786567,"raw_json":"{\"stream\":\"btcusdt@depth@100ms\",\"data\":{\"e\":\"depthUpdate\",\"E\":1788567786567,\"T\":1788567786566,\"s\":\"BTCUSDT\",\"ps\":\"BTCUSDT\",\"U\":11478511763141,\"u\":11478511768713,\"pu\":11478511762888,\"b\":[[\"1000.00\",\"24.604\"],[\"29296.90\",\"0.147\"],[\"29396.90\",\"1.890\"],[\"29496.90\",\"0.063\"],[\"63678.00\",\"0.014\"],[\"71637.20\",\"0.002\"],[\"71673.00\",\"0.000\"],[\"78283.60\",\"4.133\"],[\"78442.70\",\"13.405\"],[\"78601.90\",\"11.970\"],[\"78665.60\",\"2.215\"],[\"78681.50\",\"5.690\"],[\"78800.90\",\"12.254\"],[\"79198.90\",\"3.971\"],[\"79596.90\",\"6.917\"]],\"a\":[[\"79628.00\",\"1.795\"],[\"79636.10\",\"0.004\"],[\"79636.40\",\"0.154\"],[\"79806.00\",\"5.078\"],[\"79806.10\",\"0.002\"],[\"79819.10\",\"7.150\"],[\"80393.00\",\"15.389\"],[\"80478.80\",\"2.460\"]],\"st\":1}}"}
{"receive_ns":1788567786658753000,"stream":"btcusdt@depth@100ms","event_type":"depthUpdate","event_time_ms":1788567786669,"raw_json":"{\"stream\":\"btcusdt@depth@100ms\",\"data\":{\"e\":\"depthUpdate\",\"E\":1788567786669,\"T\":1788567786668,\"s\":\"BTCUSDT\",\"ps\":\"BTCUSDT\",\"U\":11478511768731,\"u\":11478511773246,\"pu\":11478511768713,\"b\":[[\"1000.00\",\"24.604\"],[\"29296.90\",\"0.259\"],[\"29396.90\",\"1.841\"],[\"29496.90\",\"0.000\"],[\"63678.00\",\"0.010\"],[\"71637.20\",\"0.002\"],[\"76413.00\",\"0.023\"],[\"78562.20\",\"13.987\"],[\"78641.70\",\"34.254\"],[\"78800.90\",\"12.254\"],[\"79475.60\",\"0.505\"]],\"a\":[[\"79718.90\",\"0.471\"],[\"80393.00\",\"15.389\"],[\"80592.00\",\"8.934\"]],\"st\":1}}"}
{"receive_ns":1788567786688473000,"stream":"btcusdt@bookTicker","event_type":"bookTicker","event_time_ms":1788567786704,"raw_json":"{\"stream\":\"btcusdt@bookTicker\",\"data\":{\"e\":\"bookTicker\",\"u\":11478511774640,\"s\":\"BTCUSDT\",\"ps\":\"BTCUSDT\",\"b\":\"79596.90\",\"B\":\"6.917\",\"a\":\"79597.00\",\"A\":\"8.045\",\"T\":1788567786704,\"E\":1788567786704,\"st\":1}}"}
{"receive_ns":1788567786692471000,"stream":"btcusdt@bookTicker","event_type":"bookTicker","event_time_ms":1788567786707,"raw_json":"{\"stream\":\"btcusdt@bookTicker\",\"data\":{\"e\":\"bookTicker\",\"u\":11478511774825,\"s\":\"BTCUSDT\",\"ps\":\"BTCUSDT\",\"b\":\"79596.90\",\"B\":\"6.917\",\"a\":\"79597.00\",\"A\":\"8.061\",\"T\":1788567786707,\"E\":1788567786707,\"st\":1}}"}
{"receive_ns":1788567786759828000,"stream":"btcusdt@depth@100ms","event_type":"depthUpdate","event_time_ms":1788567786771,"raw_json":"{\"stream\":\"btcusdt@depth@100ms\",\"data\":{\"e\":\"depthUpdate\",\"E\":1788567786771,\"T\":1788567786769,\"s\":\"BTCUSDT\",\"ps\":\"BTCUSDT\",\"U\":11478511773263,\"u\":11478511777570,\"pu\":11478511773246,\"b\":[[\"29296.90\",\"0.441\"],[\"29396.90\",\"1.659\"],[\"71637.20\",\"0.002\"],[\"76413.00\",\"0.025\"],[\"78005.00\",\"0.225\"],[\"78283.60\",\"5.919\"],[\"78442.70\",\"14.296\"],[\"78482.50\",\"29.262\"],[\"78548.30\",\"4.771\"],[\"78601.90\",\"12.255\"],[\"78681.50\",\"6.452\"],[\"78800.90\",\"12.254\"],[\"79198.90\",\"3.971\"]],\"a\":[[\"79597.00\",\"8.061\"],[\"79626.40\",\"1.651\"],[\"79636.80\",\"0.269\"],[\"80393.00\",\"15.389\"],[\"80592.00\",\"9.863\"],[\"80592.10\",\"5.321\"],[\"81188.90\",\"0.012\"],[\"81268.50\",\"0.246\"]],\"st\":1}}"}
{"receive_ns":1788567786864310000,"stream":"btcusdt@depth@100ms","event_type":"depthUpdate","event_time_ms":1788567786873,"raw_json":"{\"stream\":\"btcusdt@depth@100ms\",\"data\":{\"e\":\"depthUpdate\",\"E\":1788567786873,\"T\":1788567786869,\"s\":\"BTCUSDT\",\"ps\":\"BTCUSDT\",\"U\":11478511777616,\"u\":11478511781044,\"pu\":11478511777570,\"b\":[[\"1000.00\",\"24.604\"],[\"29296.90\",\"0.616\"],[\"29396.90\",\"1.484\"],[\"71637.20\",\"0.002\"],[\"76413.00\",\"0.023\"],[\"78482.50\",\"31.171\"],[\"78800.90\",\"12.254\"],[\"78880.50\",\"3.548\"],[\"78963.70\",\"5.167\"],[\"79565.70\",\"0.085\"],[\"79565.80\",\"0.046\"],[\"79566.40\",\"0.001\"],[\"79573.60\",\"0.125\"],[\"79592.00\",\"0.005\"],[\"79592.10\",\"0.000\"],[\"79592.50\",\"0.006\"],[\"79594.60\",\"0.103\"],[\"79594.80\",\"0.000\"]],\"a\":[[\"79600.00\",\"0.049\"],[\"79600.10\",\"0.002\"],[\"79600.20\",\"0.001\"],[\"79600.40\",\"0.008\"],[\"79600.50\",\"0.078\"],[\"79600.60\",\"0.000\"],[\"79600.90\",\"0.028\"],[\"79601.00\",\"0.345\"],[\"79601.20\",\"0.026\"],[\"79601.30\",\"0.027\"],[\"79601.40\",\"0.133\"],[\"79601.50\",\"0.029\"],[\"79616.30\",\"0.641\"],[\"79618.00\",\"0.631\"],[\"79618.50\",\"0.454\"],[\"79620.60\",\"0.002\"],[\"79636.80\",\"0.144\"],[\"79819.10\",\"7.144\"],[\"80393.00\",\"15.389\"]],\"st\":1}}"}
{"receive_ns":1788567786898927000,"stream":"btcusdt@bookTicker","event_type":"bookTicker","event_time_ms":1788567786909,"raw_json":"{\"stream\":\"btcusdt@bookTicker\",\"data\":{\"e\":\"bookTicker\",\"u\":11478511782615,\"s\":\"BTCUSDT\",\"ps\":\"BTCUSDT\",\"b\":\"79596.90\",\"B\":\"6.893\",\"a\":\"79597.00\",\"A\":\"8.061\",\"T\":1788567786909,\"E\":1788567786909,\"st\":1}}"}
{"receive_ns":1788567786904596000,"stream":"btcusdt@bookTicker","event_type":"bookTicker","event_time_ms":1788567786912,"raw_json":"{\"stream\":\"btcusdt@bookTicker\",\"data\":{\"e\":\"bookTicker\",\"u\":11478511782844,\"s\":\"BTCUSDT\",\"ps\":\"BTCUSDT\",\"b\":\"79596.90\",\"B\":\"6.914\",\"a\":\"79597.00\",\"A\":\"8.061\",\"T\":1788567786912,\"E\":1788567786912,\"st\":1}}"}
{"receive_ns":1788567786970108000,"stream":"btcusdt@depth@100ms","event_type":"depthUpdate","event_time_ms":1788567786975,"raw_json":"{\"stream\":\"btcusdt@depth@100ms\",\"data\":{\"e\":\"depthUpdate\",\"E\":1788567786975,\"T\":1788567786974,\"s\":\"BTCUSDT\",\"ps\":\"BTCUSDT\",\"U\":11478511781191,\"u\":11478511785882,\"pu\":11478511781044,\"b\":[[\"1000.00\",\"24.604\"],[\"29296.90\",\"0.798\"],[\"29396.90\",\"1.302\"],[\"71637.20\",\"0.002\"],[\"78490.50\",\"8.088\"],[\"78492.90\",\"0.037\"],[\"78800.90\",\"12.254\"],[\"78805.70\",\"0.942\"],[\"79198.90\",\"3.970\"],[\"79565.80\",\"0.000\"],[\"79567.20\",\"0.048\"],[\"79573.20\",\"0.538\"],[\"79596.90\",\"6.914\"]],\"a\":[[\"79600.60\",\"0.026\"],[\"79601.10\",\"0.009\"],[\"79613.10\",\"0.194\"],[\"79618.50\",\"0.002\"],[\"79619.70\",\"0.454\"],[\"79637.10\",\"0.252\"],[\"79995.00\",\"4.696\"],[\"80393.00\",\"15.389\"]],\"st\":1}}"}
{"receive_ns":1788567787045865000,"stream":"btcusdt@bookTicker","event_type":"bookTicker","event_time_ms":1788567787055,"raw_json":"{\"stream\":\"btcusdt@bookTicker\",\"data\":{\"e\":\"bookTicker\",\"u\":11478511789414,\"s\":\"BTCUSDT\",\"ps\":\"BTCUSDT\",\"b\":\"79596.90\",\"B\":\"6.914\",\"a\":\"79597.00\",\"A\":\"8.043\",\"T\":1788567787054,\"E\":1788567787055,\"st\":1}}"}
{"receive_ns":1788567787057005000,"stream":"btcusdt@trade","event_type":"trade","event_time_ms":1788567787055,"raw_json":"{\"stream\":\"btcusdt@trade\",\"data\":{\"e\":\"trade\",\"E\":1788567787055,\"T\":1788567787054,\"s\":\"BTCUSDT\",\"t\":8054122864,\"p\":\"79597.00\",\"q\":\"0.018\",\"X\":\"MARKET\",\"m\":false,\"st\":1}}"}
{"receive_ns":1788567787064010000,"stream":"btcusdt@bookTicker","event_type":"bookTicker","event_time_ms":1788567787057,"raw_json":"{\"stream\":\"btcusdt@bookTicker\",\"data\":{\"e\":\"bookTicker\",\"u\":11478511789557,\"s\":\"BTCUSDT\",\"ps\":\"BTCUSDT\",\"b\":\"79596.90\",\"B\":\"6.913\",\"a\":\"79597.00\",\"A\":\"8.043\",\"T\":1788567787056,\"E\":1788567787057,\"st\":1}}"}
{"receive_ns":1788567787064341000,"stream":"btcusdt@bookTicker","event_type":"bookTicker","event_time_ms":1788567787057,"raw_json":"{\"stream\":\"btcusdt@bookTicker\",\"data\":{\"e\":\"bookTicker\",\"u\":11478511789560,\"s\":\"BTCUSDT\",\"ps\":\"BTCUSDT\",\"b\":\"79596.90\",\"B\":\"6.903\",\"a\":\"79597.00\",\"A\":\"8.043\",\"T\":1788567787057,\"E\":1788567787057,\"st\":1}}"}
{"receive_ns":1788567787076835000,"stream":"btcusdt@bookTicker","event_type":"bookTicker","event_time_ms":1788567787068,"raw_json":"{\"stream\":\"btcusdt@bookTicker\",\"data\":{\"e\":\"bookTicker\",\"u\":11478511790047,\"s\":\"BTCUSDT\",\"ps\":\"BTCUSDT\",\"b\":\"79596.90\",\"B\":\"6.903\",\"a\":\"79597.00\",\"A\":\"8.040\",\"T\":1788567787068,\"E\":1788567787068,\"st\":1}}"}
{"receive_ns":1788567787087704000,"stream":"btcusdt@trade","event_type":"trade","event_time_ms":1788567787068,"raw_json":"{\"stream\":\"btcusdt@trade\",\"data\":{\"e\":\"trade\",\"E\":1788567787068,\"T\":1788567787068,\"s\":\"BTCUSDT\",\"t\":8054122865,\"p\":\"79597.00\",\"q\":\"0.003\",\"X\":\"MARKET\",\"m\":false,\"st\":1}}"}
{"receive_ns":1788567787104419000,"stream":"btcusdt@depth@100ms","event_type":"depthUpdate","event_time_ms":1788567787077,"raw_json":"{\"stream\":\"btcusdt@depth@100ms\",\"data\":{\"e\":\"depthUpdate\",\"E\":1788567787077,\"T\":1788567787074,\"s\":\"BTCUSDT\",\"ps\":\"BTCUSDT\",\"U\":11478511785957,\"u\":11478511790367,\"pu\":11478511785882,\"b\":[[\"29296.90\",\"0.973\"],[\"29396.90\",\"1.127\"],[\"71637.20\",\"0.002\"],[\"76413.00\",\"0.025\"],[\"78448.90\",\"1.833\"],[\"78601.90\",\"12.540\"],[\"78602.00\",\"8.755\"],[\"78800.90\",\"12.254\"],[\"78830.80\",\"0.000\"],[\"79198.90\",\"3.981\"],[\"79573.60\",\"0.000\"],[\"79574.50\",\"0.001\"],[\"79582.60\",\"0.070\"],[\"79592.10\",\"0.004\"],[\"79592.50\",\"0.002\"],[\"79594.60\",\"0.027\"],[\"79595.10\",\"0.078\"],[\"79596.90\",\"6.903\"]],\"a\":[[\"79597.00\",\"8.040\"],[\"79600.40\",\"0.008\"],[\"79600.70\",\"0.032\"],[\"79616.40\",\"2.360\"],[\"79618.00\",\"0.004\"],[\"79637.20\",\"0.125\"],[\"79806.00\",\"5.076\"],[\"79995.00\",\"4.697\"],[\"80393.00\",\"15.389\"]],\"st\":1}}"}
{"receive_ns":1788567787170274000,"stream":"btcusdt@depth@100ms","event_type":"depthUpdate","event_time_ms":1788567787179,"raw_json":"{\"stream\":\"btcusdt@depth@100ms\",\"data\":{\"e\":\"depthUpdate\",\"E\":1788567787179,\"T\":1788567787178,\"s\":\"BTCUSDT\",\"ps\":\"BTCUSDT\",\"U\":11478511790479,\"u\":11478511796720,\"pu\":11478511790367,\"b\":[[\"1000.00\",\"24.604\"],[\"29296.90\",\"1.155\"],[\"29396.90\",\"0.945\"],[\"63677.50\",\"0.000\"],[\"63678.00\",\"0.026\"],[\"71637.20\",\"0.002\"],[\"76413.00\",\"0.023\"],[\"78005.00\",\"0.222\"],[\"78482.50\",\"33.080\"],[\"78577.50\",\"0.006\"],[\"78587.10\",\"0.007\"],[\"78610.80\",\"0.004\"],[\"78618.40\",\"1.889\"],[\"78800.90\",\"12.254\"],[\"79437.70\",\"0.027\"],[\"79477.50\",\"0.001\"],[\"79517.30\",\"0.070\"],[\"79557.10\",\"0.004\"],[\"79573.30\",\"0.000\"],[\"79573.80\",\"0.199\"],[\"79573.90\",\"0.363\"],[\"79574.00\",\"0.003\"],[\"79574.10\",\"0.003\"],[\"79574.20\",\"0.440\"]],\"a\":[[\"79600.60\",\"0.000\"],[\"79601.00\",\"0.347\"],[\"79636.80\",\"0.145\"],[\"79637.10\",\"0.252\"],[\"79637.20\",\"0.000\"],[\"79676.60\",\"0.021\"],[\"79716.40\",\"0.004\"],[\"79756.20\",\"0.026\"],[\"80194.00\",\"3.926\"],[\"80393.00\",\"15.389\"]],\"st\":1}}"}
{"receive_ns":1788567787269961000,"stream":"btcusdt@depth@100ms","event_type":"depthUpdate","event_time_ms":1788567787281,"raw_json":"{\"stream\":\"btcusdt@depth@100ms\",\"data\":{\"e\":\"depthUpdate\",\"E\":1788567787281,\"T\":1788567787277,\"s\":\"BTCUSDT\",\"ps\":\"BTCUSDT\",\"U\":11478511796790,\"u\":11478511805342,\"pu\":11478511796720,\"b\":[[\"1000.00\",\"24.604\"],[\"29296.90\",\"1.330\"],[\"29396.90\",\"0.770\"],[\"63678.00\",\"0.010\"],[\"71637.20\",\"0.002\"],[\"76413.00\",\"0.025\"],[\"78227.80\",\"2.552\"],[\"78800.90\",\"12.254\"],[\"78824.80\",\"1.241\"],[\"79569.90\",\"1.109\"],[\"79570.70\",\"0.005\"],[\"79573.30\",\"0.439\"],[\"79573.80\",\"0.074\"],[\"79574.20\",\"0.001\"],[\"79594.90\",\"0.102\"],[\"79595.10\",\"0.002\"]],\"a\":[[\"79599.50\",\"0.003\"],[\"79600.60\",\"0.026\"],[\"79633.50\",\"2.769\"],[\"79634.40\",\"0.023\"],[\"79637.10\",\"0.252\"],[\"80393.00\",\"15.389\"],[\"80589.40\",\"2.029\"]],\"st\":1}}"}
{"receive_ns":1788567787373692000,"stream":"btcusdt@depth@100ms","event_type":"depthUpdate","event_time_ms":1788567787383,"raw_json":"{\"stream\":\"btcusdt@depth@100ms\",\"data\":{\"e\":\"depthUpdate\",\"E\":1788567787383,\"T\":1788567787382,\"s\":\"BTCUSDT\",\"ps\":\"BTCUSDT\",\"U\":11478511805554,\"u\":11478511811707,\"pu\":11478511805342,\"b\":[[\"29296.90\",\"1.512\"],[\"29396.90\",\"0.588\"],[\"71637.20\",\"0.002\"],[\"76413.00\",\"0.023\"],[\"78230.00\",\"6.761\"],[\"78800.90\",\"13.521\"],[\"79198.90\",\"3.971\"],[\"79199.80\",\"0.094\"],[\"79574.00\",\"0.003\"]],\"a\":[[\"79600.20\",\"0.001\"],[\"79600.40\",\"0.034\"],[\"79601.50\",\"0.003\"],[\"79638.20\",\"0.667\"],[\"79806.00\",\"3.079\"],[\"80393.00\",\"15.389\"],[\"81188.90\",\"0.009\"]],\"st\":1}}"}
{"receive_ns":1788567787440894000,"stream":"btcusdt@bookTicker","event_type":"bookTicker","event_time_ms":1788567787450,"raw_json":"{\"stream\":\"btcusdt@bookTicker\",\"data\":{\"e\":\"bookTicker\",\"u\":11478511815021,\"s\":\"BTCUSDT\",\"ps\":\"BTCUSDT\",\"b\":\"79596.90\",\"B\":\"6.837\",\"a\":\"79597.00\",\"A\":\"8.040\",\"T\":1788567787450,\"E\":1788567787450,\"st\":1}}"}
{"receive_ns":1788567787446543000,"stream":"btcusdt@trade","event_type":"trade","event_time_ms":1788567787450,"raw_json":"{\"stream\":\"btcusdt@trade\",\"data\":{\"e\":\"trade\",\"E\":1788567787450,\"T\":1788567787450,\"s\":\"BTCUSDT\",\"t\":8054122866,\"p\":\"79596.90\",\"q\":\"0.066\",\"X\":\"MARKET\",\"m\":true,\"st\":1}}"}
