{"kind": "depth", "E": 1787082382203, "U": 11315507899027, "u": 11315507905422, "recv_ms": 1787082382174, "bids": [[1000.0, 35.81], [14353.9, 1.596], [14453.9, 2.604], [58188.5, 0.002], [62067.7, 0.738], [63360.9, 0.02], [64007.4, 4.751], [64330.6, 5.2], [64513.6, 4.554], [64580.7, 0.19], [64638.3, 0.634], [64650.3, 0.02]], "asks": [[64654.0, 16.101], [64662.6, 1.014], [64735.6, 0.101], [64793.5, 0.0], [64977.3, 4.822], [65300.5, 2.194], [65354.8, 0.856]]}
{"kind": "depth", "E": 1787082382305, "U": 11315507905704, "u": 11315507912898, "recv_ms": 1787082382275, "bids": [[14353.9, 1.946], [14453.9, 2.254], [51723.0, 0.0], [51723.1, 0.0], [58188.5, 0.002], [61421.2, 0.008], [62067.7, 0.741], [62088.8, 0.083], [63360.9, 0.017], [63444.9, 0.944], [63653.9, 0.044], [63763.2, 2.506], [63942.7, 5.231], [64007.4, 4.751], [64034.8, 7.201], [64330.6, 5.21], [64496.7, 5.732], [64513.7, 3.362], [64574.7, 0.142], [64587.8, 2.512], [64600.4, 0.004], [64608.0, 0.487], [64628.5, 0.004], [64630.4, 1.266], [64633.0, 0.209], [64633.4, 1.229], [64649.5, 2.254], [64650.3, 0.078], [64651.9, 0.006], [64652.8, 0.002]], "asks": [[64655.7, 0.0], [64655.9, 0.0], [64656.4, 0.003], [64719.9, 0.001], [64793.5, 1.391], [64810.5, 1.981], [64849.3, 2.77], [65300.5, 2.194], [65654.0, 0.03], [67886.7, 0.09]]}
{"kind": "depth", "E": 1787082382407, "U": 11315507913027, "u": 11315507920460, "recv_ms": 1787082382379, "bids": [[1000.0, 35.81], [14353.9, 2.31], [14453.9, 1.89], [51723.0, 0.0], [58188.5, 0.002], [62067.7, 0.738], [63898.4, 0.014], [64007.4, 4.751], [64496.7, 8.3], [64513.7, 4.846], [64524.0, 4.513], [64540.3, 10.46], [64540.4, 0.001], [64587.9, 3.336], [64607.6, 0.055], [64650.3, 0.078]], "asks": [[64656.4, 0.022], [64719.8, 2.601], [64766.3, 0.594], [64767.4, 12.589], [64783.9, 2.322], [64793.5, 5.402], [64810.5, 10.415], [65239.9, 0.23], [65300.5, 2.196]]}
{"kind": "depth", "E": 1787082382509, "U": 11315507920516, "u": 11315507926690, "recv_ms": 1787082382480, "bids": [[1000.0, 35.81], [14353.9, 2.66], [14453.9, 1.54], [58188.5, 0.002], [63653.9, 0.024], [63768.1, 3.756], [64007.4, 4.751], [64524.0, 6.302], [64650.3, 0.078]], "asks": [[64654.0, 16.145], [64656.6, 0.018], [64783.6, 1.212], [64849.3, 1.933], [65211.4, 0.239], [65235.8, 0.0], [65300.5, 2.194], [65358.7, 2.824], [65654.0, 0.01]]}
{"kind": "depth", "E": 1787082382611, "U": 11315507926888, "u": 11315507937517, "recv_ms": 1787082382582, "bids": [[14353.9, 3.01], [14453.9, 1.19], [51723.0, 0.0], [58188.5, 0.002], [61421.2, 0.008], [62067.7, 0.741], [63944.3, 5.469], [64007.4, 4.751], [64039.7, 4.91], [64330.6, 5.21], [64537.7, 6.186], [64543.9, 0.595], [64574.7, 0.565], [64575.9, 0.109], [64582.0, 3.464], [64591.8, 0.002], [64595.7, 0.05], [64622.1, 0.002], [64625.4, 2.147], [64625.5, 1.3], [64625.7, 0.025], [64626.4, 2.316], [64627.3, 0.311], [64632.9, 0.003], [64633.1, 0.379], [64633.5, 4.485], [64633.6, 5.018], [64634.3, 0.002], [64634.5, 0.456], [64635.4, 0.083], [64636.0, 3.341], [64636.5, 1.423], [64636.8, 0.193], [64637.0, 0.067], [64638.3, 0.015], [64640.9, 0.023], [64641.0, 0.919], [64641.6, 0.209], [64641.7, 0.022], [64643.0, 2.389], [64643.2, 0.194], [64645.4, 0.407], [64646.1, 0.232], [64646.7, 0.003], [64646.9, 0.126], [64647.0, 0.018], [64648.5, 0.004], [64648.6, 0.001], [64649.1, 0.001], [64649.2, 0.102], [64649.5, 2.257], [64649.8, 1.025], [64649.9, 3.455], [64650.0, 1.025], [64650.1, 0.732], [64650.3, 0.001], [64650.7, 0.336], [64651.4, 0.003], [64651.7, 0.001], [64652.6, 0.001], [64652.7, 0.017], [64653.0, 0.002], [64653.1, 0.127], [64653.5, 0.002], [64653.8, 0.918], [64653.9, 15.904]], "asks": [[64654.0, 13.878], [64654.1, 0.055], [64654.9, 0.003], [64655.5, 0.115], [64655.7, 0.007], [64656.0, 0.015], [64656.1, 0.001], [64656.2, 0.106], [64656.4, 0.003], [64656.5, 0.003], [64656.6, 0.102], [64656.7, 0.686], [64656.8, 0.028], [64656.9, 0.0], [64657.0, 0.089], [64657.4, 0.313], [64657.5, 0.002], [64657.8, 0.691], [64657.9, 2.57], [64658.0, 1.535], [64658.6, 0.103], [64658.7, 0.024], [64659.2, 1.279], [64659.6, 0.589], [64659.9, 0.088], [64660.3, 0.122], [64660.5, 0.096], [64661.0, 0.91], [64661.6, 0.004], [64661.8, 0.045], [64662.4, 1.462], [64666.9, 0.007], [64668.0, 0.12], [64668.5, 0.018], [64668.9, 1.138], [64669.1, 0.775], [64670.1, 0.738], [64671.3, 0.0], [64671.9, 0.06], [64672.2, 0.133], [64672.5, 0.001], [64672.7, 0.009], [64673.3, 0.133], [64673.4, 1.001], [64673.5, 2.978], [64674.4, 0.327], [64674.5, 6.657], [64675.8, 0.996], [64676.2, 0.002], [64676.3, 0.019], [64676.4, 0.001], [64677.3, 0.08], [64677.5, 0.049], [64679.5, 0.007], [64679.9, 1.546], [64682.3, 3.264], [64683.1, 10.036], [64700.6, 0.016], [64706.6, 2.068], [64706.7, 6.96], [64712.2, 0.004], [64714.7, 2.144], [64714.9, 1.153], [64720.7, 0.942], [64721.3, 0.052], [64721.7, 0.0], [64723.9, 38.985], [64724.3, 0.003], [64724.4, 0.426], [64726.7, 7.168], [64728.3, 0.002], [64731.6, 0.003], [64764.0, 1.285], [64779.8, 2.14], [64779.9, 0.004], [64788.5, 2.481], [64788.6, 3.87], [64849.3, 1.559], [65276.2, 0.0], [65300.5, 2.194], [65405.5, 2.14], [65410.5, 1.168], [71119.4, 0.001]]}
{"kind": "depth", "E": 1787082382815, "U": 11315507948350, "u": 11315507955761, "recv_ms": 1787082382788, "bids": [[1000.0, 35.81], [14253.9, 0.014], [14353.9, 3.71], [14453.9, 0.476], [58188.5, 0.002], [62067.7, 0.741], [64007.4, 4.751], [64574.7, 0.572], [64631.4, 0.526], [64631.5, 0.005], [64631.9, 0.002], [64632.9, 0.002], [64633.6, 5.018], [64635.6, 0.235], [64639.3, 0.043]], "asks": [[64656.5, 0.003], [64656.6, 0.125], [64657.8, 0.691], [64721.7, 38.985], [64723.9, 0.0], [65216.5, 0.23], [65239.7, 0.238], [65281.1, 1.515], [67886.7, 0.085]]}
{"kind": "depth", "E": 1787082382917, "U": 11315507955828, "u": 11315507960635, "recv_ms": 1787082382887, "bids": [[14253.9, 0.182], [14353.9, 3.724], [14453.9, 0.294], [58188.5, 0.002], [62067.7, 0.738], [63546.8, 4.946], [63653.9, 0.024], [64007.4, 4.751], [64330.6, 5.21], [64618.8, 0.001], [64619.4, 0.076], [64620.3, 1.599], [64621.7, 0.041], [64631.4, 0.527], [64633.8, 0.197], [64635.6, 0.234], [64640.4, 0.223], [64640.8, 0.001], [64640.9, 0.026], [64646.9, 0.674], [64649.9, 2.604], [64650.0, 1.018], [64650.7, 0.137]], "asks": [[64654.0, 13.915], [64655.8, 0.085], [64656.5, 0.022], [64656.7, 0.942], [64656.8, 0.028], [64657.3, 0.48], [64657.8, 0.784], [64659.6, 0.505], [64660.5, 0.003], [64668.2, 0.927], [64668.9, 0.212], [64669.3, 0.0], [64671.4, 0.165], [64672.1, 0.557], [64673.0, 0.541], [64673.4, 0.885], [64673.5, 2.437], [64674.3, 0.121], [64674.4, 0.327], [64810.5, 10.415], [64848.0, 0.653], [64849.3, 2.132], [65268.2, 9.315], [65300.5, 2.196], [65654.0, 0.01]]}
{"kind": "depth", "E": 1787082383121, "U": 11315507970148, "u": 11315507975468, "recv_ms": 1787082383099, "bids": [[1000.0, 35.81], [14253.9, 0.658], [14353.9, 3.486], [14453.9, 0.056], [51723.0, 0.0], [58188.5, 0.002], [61421.2, 0.006], [62067.7, 0.741], [63554.8, 6.599], [63651.5, 0.036], [63653.9, 0.044], [63781.1, 7.603], [64007.4, 4.751], [64454.2, 1.723], [64498.2, 1.905], [64540.4, 3.453], [64553.2, 0.026], [64553.3, 0.003], [64577.7, 1.2], [64633.7, 0.156], [64633.8, 0.043], [64640.9, 0.028], [64641.0, 0.917], [64642.3, 0.352], [64650.2, 0.02], [64650.7, 0.144], [64652.9, 0.084]], "asks": [[64654.0, 16.256], [64655.4, 0.01], [64655.8, 0.001], [64656.4, 0.044], [64659.0, 0.11], [64662.6, 1.013], [64666.9, 0.007], [64667.0, 3.067], [64674.5, 6.637], [64679.9, 1.552], [64700.6, 0.044], [64766.3, 2.046], [64810.4, 2.257], [64844.1, 0.002], [64844.2, 0.013], [65300.5, 2.194], [65654.0, 0.03], [65656.5, 0.083]]}
{"kind": "depth", "E": 1787082383223, "U": 11315507975622, "u": 11315507982162, "recv_ms": 1787082383199, "bids": [[14253.9, 0.966], [14353.9, 3.234], [14453.9, 0.0], [51723.0, 0.0], [58188.5, 0.002], [61421.2, 0.006], [62067.7, 0.738], [63651.5, 0.046], [64007.4, 4.751], [64330.6, 5.209], [64560.5, 0.026], [64609.9, 0.014], [64630.4, 1.267], [64630.9, 2.962], [64633.4, 0.001], [64633.6, 1.943], [64636.3, 1.19], [64636.4, 2.911], [64638.2, 0.746], [64646.4, 0.033], [64650.7, 0.137], [64652.9, 0.0], [64653.9, 15.903]], "asks": [[64655.5, 0.199], [64657.8, 0.768], [64658.6, 0.088], [64659.0, 0.109], [64660.5, 0.019], [64667.9, 0.625], [64672.3, 0.147], [64672.6, 0.485], [64675.2, 0.635], [64679.9, 1.532], [64717.7, 0.063], [64717.8, 0.004], [64977.3, 4.821], [65171.2, 9.372], [65300.5, 2.194], [65807.6, 4.815], [65947.0, 0.157]]}
{"kind": "depth", "E": 1787082383325, "U": 11315507982342, "u": 11315507987805, "recv_ms": 1787082383301, "bids": [[1000.0, 35.81], [14253.9, 1.316], [14353.9, 2.884], [51723.1, 0.0], [58188.5, 0.002], [61421.2, 0.007], [62067.7, 0.741], [63373.4, 2.383], [63383.8, 2.025], [63653.9, 0.024], [63942.7, 5.465], [64007.4, 4.751], [64330.6, 5.21], [64346.0, 5.017], [64460.0, 1.063], [64513.7, 5.837], [64600.4, 0.004], [64607.6, 0.055], [64630.4, 1.266], [64633.5, 4.639], [64633.7, 0.002], [64638.2, 0.127], [64640.9, 0.026], [64641.0, 0.919], [64649.8, 1.006], [64650.3, 0.078], [64650.7, 0.413]], "asks": [[64654.0, 14.366], [64654.1, 0.055], [64654.3, 0.0], [64655.3, 0.002], [64656.5, 0.003], [64657.8, 0.691], [64660.5, 0.096], [64666.9, 0.004], [64667.0, 3.07], [64667.9, 0.006], [64673.0, 0.0], [64673.3, 0.674], [64675.2, 0.016], [64793.5, 4.591], [64810.5, 7.214], [64849.3, 4.28], [64977.3, 4.822], [65171.2, 9.677], [65300.5, 2.196], [65613.6, 0.005], [65654.0, 0.01], [65656.5, 0.093]]}
{"kind": "depth", "E": 1787082383427, "U": 11315507987843, "u": 11315507992926, "recv_ms": 1787082383399, "bids": [[1000.0, 35.81], [14253.9, 1.68], [14353.9, 2.52], [58188.5, 0.002], [61421.2, 0.006], [63360.9, 0.02], [64007.4, 4.751], [64609.9, 0.0], [64649.9, 2.606], [64650.3, 0.078], [64650.5, 0.024], [64650.7, 0.413], [64651.9, 0.004], [64652.8, 0.086], [64653.8, 0.908], [64653.9, 15.893]], "asks": [[64654.0, 14.362], [64655.5, 0.115], [64656.4, 0.003], [64656.6, 0.102], [64656.7, 0.922], [64661.5, 0.36], [64672.6, 0.465], [64677.3, 0.08], [64679.9, 1.552], [64810.5, 10.415], [64849.3, 0.344], [65300.5, 2.194], [65387.6, 0.0], [65454.0, 4.286], [65947.0, 0.16]]}
{"kind": "depth", "E": 1787082383631, "U": 11315507998404, "u": 11315508004206, "recv_ms": 1787082383602, "bids": [[1000.0, 35.81], [14253.9, 2.394], [14353.9, 1.806], [58188.5, 0.002], [62067.7, 0.741], [63684.1, 7.68], [64007.4, 4.751], [64629.9, 0.022], [64630.3, 0.022], [64630.7, 0.131], [64631.1, 0.56], [64636.8, 0.657], [64637.2, 0.001], [64643.1, 2.462], [64643.6, 0.349], [64650.3, 0.001], [64650.7, 0.144], [64652.8, 0.002]], "asks": [[64655.3, 0.086], [64671.3, 0.557], [64672.1, 0.0], [64673.5, 2.553], [64674.3, 0.005], [65300.5, 2.194]]}
{"kind": "depth", "E": 1787082383733, "U": 11315508004343, "u": 11315508009250, "recv_ms": 1787082383704, "bids": [[1000.0, 35.81], [14253.9, 2.744], [14353.9, 1.456], [51723.0, 0.0], [58188.5, 0.002], [62067.7, 0.738], [63567.7, 2.51], [63653.9, 0.024], [64007.4, 4.751], [64524.5, 0.005], [64637.5, 0.013], [64652.5, 0.084], [64652.9, 0.084]], "asks": [[64655.3, 0.002], [64670.0, 0.007], [64849.3, 5.81], [65108.8, 0.0], [65300.5, 2.194], [65645.1, 7.539], [65654.0, 0.01]]}
{"kind": "depth", "E": 1787082383835, "U": 11315508009282, "u": 11315508013910, "recv_ms": 1787082383805, "bids": [[14253.9, 3.108], [14353.9, 1.092], [58188.5, 0.002], [61421.2, 0.006], [62067.7, 0.741], [63755.2, 4.321], [63944.3, 4.767], [64007.4, 4.753], [64330.6, 5.2], [64600.4, 0.004], [64607.6, 0.055], [64630.9, 2.343], [64633.2, 5.157], [64650.7, 0.137]], "asks": [[64654.0, 15.41], [64654.3, 0.002], [64655.3, 0.0], [64656.4, 0.003], [64803.9, 0.019], [64810.5, 10.415], [64849.3, 9.465], [65300.5, 2.194], [65462.7, 5.292], [65656.1, 13.233]]}
{"kind": "depth", "E": 1787082383937, "U": 11315508013985, "u": 11315508019593, "recv_ms": 1787082383906, "bids": [[1000.0, 35.81], [14253.9, 3.472], [14353.9, 0.728], [58188.5, 0.002], [61421.2, 0.006], [63653.9, 0.044], [64007.4, 4.751], [64575.7, 0.0], [64595.7, 0.05], [64630.5, 0.116], [64630.7, 0.015], [64630.9, 2.9], [64631.1, 0.003], [64632.1, 0.008], [64632.8, 0.009], [64635.6, 0.234], [64635.7, 1.107], [64636.6, 0.001], [64636.9, 0.09], [64637.0, 0.059], [64646.9, 0.658], [64647.0, 0.034], [64650.1, 0.714], [64650.2, 0.036], [64650.3, 0.001], [64650.7, 0.137], [64652.2, 0.005], [64652.9, 0.0], [64653.1, 0.0], [64653.9, 15.922]], "asks": [[64654.0, 16.25], [64655.7, 0.091], [64656.9, 0.019], [64657.0, 0.111], [64657.7, 0.632], [64657.8, 0.15], [64658.5, 0.09], [64660.4, 0.103], [64660.5, 0.466], [64661.3, 0.0], [64668.2, 0.927], [64669.1, 0.775], [64671.3, 0.557], [64672.1, 0.0], [64673.0, 0.541], [64673.3, 0.249], [64673.5, 2.437], [64674.2, 0.478], [64674.4, 0.327], [64712.2, 0.004], [64731.6, 0.003], [64849.3, 1.848], [65113.1, 0.062], [65300.5, 2.194], [65517.0, 0.102], [65654.0, 0.03]]}
{"kind": "depth", "E": 1787082384039, "U": 11315508019633, "u": 11315508025795, "recv_ms": 1787082384011, "bids": [[1000.0, 35.81], [14153.9, 0.042], [14253.9, 3.738], [14353.9, 0.42], [58188.5, 0.002], [61421.2, 0.006], [62067.7, 1.428], [63653.9, 0.024], [63702.0, 0.403], [63892.6, 2.188], [63949.2, 6.631], [64007.4, 4.751], [64574.5, 0.034], [64574.6, 0.001], [64575.9, 0.032], [64576.7, 42.063], [64577.6, 3.44], [64577.7, 7.314], [64577.9, 0.438], [64633.5, 4.485], [64640.9, 0.028], [64641.0, 0.917], [64642.3, 0.357], [64649.7, 1.147], [64650.3, 0.001], [64650.7, 0.144], [64651.9, 0.006], [64652.2, 0.003], [64652.5, 0.0], [64653.9, 15.922]], "asks": [[64654.0, 16.246], [64655.2, 0.841], [64656.3, 0.005], [64656.4, 0.003], [64657.6, 0.002], [64657.7, 0.091], [64657.8, 0.127], [64658.6, 0.085], [64660.3, 0.663], [64660.4, 0.465], [64660.5, 0.127], [64665.8, 0.158], [64666.9, 0.007], [64667.0, 3.067], [64677.3, 0.066], [64678.8, 3.473], [64679.1, 0.449], [64720.7, 6.61], [64844.2, 0.01], [64844.3, 0.003], [65300.5, 2.194], [65462.8, 3.052], [65580.4, 13.067], [65654.0, 0.01]]}
{"kind": "depth", "E": 1787082384141, "U": 11315508025930, "u": 11315508032912, "recv_ms": 1787082384114, "bids": [[14153.9, 0.238], [14253.9, 3.696], [14353.9, 0.266], [51723.0, 0.0], [58188.5, 0.002], [62067.7, 1.431], [63651.5, 0.035], [64007.4, 4.751], [64330.6, 5.21], [64557.2, 0.004], [64570.1, 0.006], [64571.1, 0.421], [64572.2, 0.002], [64574.5, 41.974], [64574.7, 0.565], [64576.7, 0.073], [64577.7, 1.2], [64579.2, 0.034], [64600.4, 0.008], [64600.7, 0.382], [64607.6, 0.051], [64633.7, 0.002], [64642.3, 0.352], [64650.3, 0.078], [64650.7, 0.336]], "asks": [[64657.8, 0.784], [64660.2, 0.472], [64660.3, 0.122], [64660.4, 0.002], [64660.5, 0.003], [64662.6, 1.014], [64665.8, 0.158], [64721.3, 0.043], [65300.5, 2.194], [65429.8, 23.79], [65437.2, 0.0], [65591.5, 21.772], [65656.5, 0.082], [67142.9, 0.0]]}
{"kind": "depth", "E": 1787082384243, "U": 11315508033123, "u": 11315508038850, "recv_ms": 1787082384215, "bids": [[1000.0, 35.81], [14153.9, 0.476], [14253.9, 3.584], [14353.9, 0.14], [51723.0, 0.0], [58188.5, 0.002], [62067.7, 1.428], [63651.5, 0.046], [63710.0, 2.287], [63867.8, 0.782], [63897.4, 3.829], [64007.4, 4.751], [64645.9, 2.36], [64650.3, 0.001]], "asks": [[64656.4, 0.003], [64657.8, 0.127], [64660.2, 0.001], [64660.5, 1.131], [64665.8, 0.158], [65547.7, 8.403], [65656.5, 0.093], [65947.0, 0.157]]}
{"kind": "depth", "E": 1787082384345, "U": 11315508038978, "u": 11315508045423, "recv_ms": 1787082384315, "bids": [[1000.0, 35.81], [14153.9, 0.714], [14253.9, 3.458], [14353.9, 0.028], [51723.0, 0.0], [51723.1, 0.0], [58188.5, 0.002], [61421.2, 0.006], [63653.9, 0.044], [64007.4, 4.751], [64067.1, 9.743], [64330.6, 5.209], [64457.9, 8.54], [64496.7, 9.785], [64513.7, 5.527], [64575.9, 0.109], [64587.9, 3.411], [64595.7, 0.053], [64602.1, 0.003], [64633.6, 1.943], [64637.3, 0.031], [64640.9, 0.026], [64641.0, 0.919], [64644.6, 0.142], [64650.3, 0.001], [64650.7, 0.144]], "asks": [[64654.0, 15.814], [64666.9, 0.004], [64667.0, 3.07], [64673.0, 0.0], [64673.3, 0.79], [64682.7, 0.017], [64690.1, 0.017], [64719.8, 2.604], [64731.6, 0.006], [64793.5, 5.402], [64849.3, 1.841], [64977.3, 4.821], [65300.5, 2.194], [65654.0, 0.03]]}
{"kind": "depth", "E": 1787082384447, "U": 11315508045572, "u": 11315508051702, "recv_ms": 1787082384418, "bids": [[14153.9, 1.05], [14253.9, 3.15], [14353.9, 0.0], [58188.5, 0.002], [61421.3, 0.006], [62067.7, 1.431], [63360.9, 0.023], [63653.9, 0.024], [63892.6, 1.641], [64330.6, 2.881], [64513.7, 0.412], [64574.7, 0.572], [64580.7, 0.19], [64633.6, 1.943], [64647.0, 0.019], [64647.1, 0.017], [64650.7, 0.137], [64652.7, 0.101]], "asks": [[64656.4, 0.003], [64668.0, 0.135], [64668.1, 0.006], [64793.5, 0.0], [64977.3, 2.516], [65300.5, 2.194], [65423.4, 7.328], [65429.8, 28.369], [65654.0, 0.01], [67146.4, 0.149]]}
{"kind": "depth", "E": 1787082384549, "U": 11315508051834, "u": 11315508062428, "recv_ms": 1787082384521, "bids": [[1000.0, 35.81], [14153.9, 1.4], [14253.9, 2.8], [58188.5, 0.002], [62067.7, 1.428], [63932.7, 0.0], [64007.4, 4.751], [64072.0, 13.496], [64513.7, 5.527], [64570.1, 41.946], [64571.1, 0.498], [64571.5, 1.704], [64574.5, 0.034], [64633.0, 0.209], [64633.8, 0.043]], "asks": [[64655.7, 0.007], [64677.3, 0.08], [64684.2, 0.172], [64793.5, 5.402], [64830.0, 0.177], [65300.5, 2.194], [65423.4, 8.244], [65552.7, 5.486]]}
{"kind": "depth", "E": 1787082384651, "U": 11315508062716, "u": 11315508078108, "recv_ms": 1787082384623, "bids": [[1000.0, 35.81], [14153.9, 1.764], [14253.9, 2.436], [51723.0, 0.0], [58188.5, 0.002], [61421.2, 0.006], [61421.3, 0.008], [62067.7, 1.431], [63897.4, 4.376], [64007.4, 4.751], [64524.5, 0.006], [64570.1, 41.946], [64574.5, 0.034], [64600.4, 0.004], [64607.6, 0.055], [64623.5, 0.141], [64628.0, 0.677], [64633.9, 0.002], [64646.9, 0.11], [64649.5, 2.235], [64649.9, 2.604], [64650.0, 1.566], [64650.7, 0.137], [64653.2, 0.085], [64653.9, 15.922]], "asks": [[64654.0, 14.765], [64654.3, 0.0], [64655.3, 0.002], [64656.4, 0.001], [64658.6, 0.088], [64661.5, 0.361], [64672.3, 0.057], [64678.8, 0.004], [64678.9, 0.004], [64679.2, 1.119], [64682.5, 0.155], [64682.8, 10.006], [64683.9, 2.418], [64684.1, 0.311], [64721.3, 0.052], [64810.5, 7.291], [64849.3, 3.93], [65300.5, 2.194]]}
{"kind": "depth", "E": 1787082384753, "U": 11315508078412, "u": 11315508088668, "recv_ms": 1787082384723, "bids": [[14153.9, 2.128], [14253.9, 2.072], [58188.5, 0.002], [61421.2, 0.006], [62067.7, 1.428], [63653.9, 0.044], [63673.2, 5.354], [63705.7, 11.836], [63938.8, 0.236], [64007.4, 4.751], [64061.3, 1.546], [64330.6, 5.199], [64524.5, 0.005], [64580.7, 0.09], [64620.7, 0.004], [64636.8, 0.193], [64636.9, 0.082], [64637.5, 0.013], [64644.0, 0.412], [64646.9, 0.582], [64650.1, 1.024], [64650.3, 0.024], [64650.7, 0.137]], "asks": [[64654.0, 14.725], [64656.2, 0.106], [64656.4, 0.001], [64657.8, 0.691], [64659.2, 1.279], [64660.5, 0.567], [64661.5, 0.36], [64670.0, 0.007], [64672.9, 0.008], [64674.4, 0.347], [64683.9, 2.418], [64684.0, 0.366], [64684.4, 0.304], [64691.9, 0.06], [64810.5, 10.415], [64849.3, 0.352], [64869.7, 0.0], [64977.3, 4.821], [65300.5, 2.194], [65580.4, 12.001], [65654.0, 0.03]]}
{"kind": "depth", "E": 1787082384855, "U": 11315508088835, "u": 11315508099086, "recv_ms": 1787082384830, "bids": [[1000.0, 35.81], [14153.9, 2.478], [14253.9, 1.722], [58188.5, 0.002], [61421.2, 0.006], [63653.9, 0.024], [64007.4, 4.751], [64568.9, 0.017], [64570.1, 0.006], [64572.3, 41.968], [64573.1, 0.616], [64574.3, 0.457], [64600.7, 0.381], [64612.1, 0.001], [64624.7, 0.339], [64628.0, 0.341], [64628.1, 0.049], [64630.4, 1.267], [64633.9, 0.001], [64637.3, 0.031], [64646.9, 0.574], [64647.0, 0.027], [64649.9, 2.606], [64653.9, 15.922]], "asks": [[64654.0, 16.643], [64654.1, 0.057], [64655.3, 0.0], [64655.4, 0.002], [64657.2, 0.034], [64657.6, 0.002], [64657.7, 0.091], [64657.8, 0.15], [64660.3, 0.662], [64660.4, 0.543], [64660.5, 0.027], [64665.8, 0.158], [64678.9, 10.004], [64682.8, 0.006], [64684.0, 0.212], [64684.1, 0.311], [64684.2, 0.172], [64698.0, 0.456], [64700.6, 0.002], [64721.3, 0.043], [64721.7, 0.0], [64810.5, 7.429], [64849.3, 3.749], [64870.3, 0.022], [64923.2, 5.055], [65171.2, 5.848], [65300.5, 2.194], [65580.4, 10.935], [65654.0, 0.01]]}
{"kind": "depth", "E": 1787082384957, "U": 11315508099161, "u": 11315508104317, "recv_ms": 1787082384931, "bids": [[1000.0, 35.81], [14153.9, 2.828], [14253.9, 1.372], [58188.5, 0.002], [61421.2, 0.006], [62067.7, 1.431], [63350.2, 0.0], [63360.9, 0.026], [63422.1, 0.0], [63493.9, 0.0], [63565.7, 0.0], [63637.5, 0.673], [63651.8, 14.899], [63673.2, 4.256], [63709.4, 0.0], [63781.2, 0.0], [63853.0, 0.118], [63924.8, 0.0], [63996.7, 0.001], [64007.4, 4.751], [64330.6, 5.209], [64550.3, 0.621], [64570.9, 0.005], [64633.0, 0.055], [64640.9, 0.028], [64641.0, 0.917], [64643.6, 0.04], [64644.2, 0.309], [64645.6, 0.267], [64646.1, 0.0]], "asks": [[64654.0, 16.646], [64655.3, 0.002], [64656.5, 0.003], [64657.7, 0.091], [64657.8, 0.127], [64658.0, 1.533], [64660.2, 0.001], [64660.3, 0.122], [64660.4, 0.002], [64660.5, 1.131], [64662.4, 1.138], [64662.8, 0.513], [64665.7, 0.001], [64665.8, 0.158], [64666.9, 0.007], [64667.0, 3.067], [64684.1, 0.465], [64684.2, 0.172], [64720.7, 0.942], [64721.3, 0.052], [64721.7, 39.13], [64769.1, 0.019], [64774.8, 0.289], [65289.5, 0.611], [65300.5, 2.194], [65361.4, 0.0], [65433.2, 0.384], [65505.0, 1.094], [65576.8, 0.83], [65648.7, 0.006], [65720.5, 0.002], [65792.3, 0.0], [65864.1, 0.086], [65910.8, 0.001], [65936.0, 0.001], [65947.0, 0.154]]}
{"kind": "depth", "E": 1787082385059, "U": 11315508104451, "u": 11315508109802, "recv_ms": 1787082385030, "bids": [[14153.9, 3.192], [14253.9, 1.008], [58188.5, 0.002], [61421.2, 0.006], [62067.7, 1.428], [63653.9, 0.044], [63716.4, 18.417], [64007.4, 4.751], [64553.3, 0.0], [64553.4, 0.119], [64629.0, 0.905], [64630.4, 1.266], [64633.2, 5.155], [64633.7, 0.002], [64633.9, 0.003], [64635.9, 0.023], [64637.5, 0.02], [64640.4, 0.216], [64641.3, 0.007], [64642.3, 0.352], [64649.0, 0.0], [64650.7, 0.137], [64652.9, 0.31], [64653.6, 0.085]], "asks": [[64654.0, 15.645], [64655.3, 0.0], [64655.7, 0.0], [64656.1, 0.008], [64656.6, 0.018], [64656.7, 0.919], [64656.8, 0.006], [64657.7, 0.093], [64657.8, 0.003], [64658.0, 0.633], [64659.6, 0.589], [64661.0, 0.01], [64662.4, 1.153], [64673.3, 0.674], [64673.5, 2.553], [64684.1, 0.311], [64700.6, 0.03], [64769.1, 0.004], [64810.5, 10.415], [64849.3, 0.459], [65171.2, 9.677], [65300.5, 2.194], [65591.5, 22.838], [65654.0, 0.03]]}
{"kind": "depth", "E": 1787082385161, "U": 11315508109836, "u": 11315508115946, "recv_ms": 1787082385133, "bids": [[1000.0, 35.96], [14153.9, 3.542], [14253.9, 0.658], [58188.5, 0.002], [61421.2, 0.006], [62067.7, 1.431], [63651.8, 15.997], [64007.3, 0.001], [64007.4, 4.751], [64572.2, 0.0], [64574.5, 1.696], [64589.2, 0.192], [64591.8, 0.002], [64595.7, 0.053], [64612.1, 0.002], [64628.1, 0.03], [64629.0, 0.904], [64634.1, 0.154], [64637.0, 0.06], [64640.9, 0.026], [64641.0, 0.919], [64649.9, 2.604], [64650.7, 0.137], [64653.9, 15.922]], "asks": [[64654.0, 13.792], [64654.1, 0.055], [64656.1, 0.001], [64656.6, 0.025], [64656.8, 0.008], [64657.0, 0.027], [64657.8, 0.003], [64659.0, 1.009], [64659.9, 0.088], [64660.3, 0.122], [64660.4, 0.034], [64660.5, 0.628], [64661.6, 0.006], [64662.2, 0.492], [64665.8, 0.158], [64666.9, 0.004], [64667.0, 3.07], [64668.2, 0.001], [64668.7, 0.926], [64669.1, 0.621], [64669.6, 0.126], [64670.2, 0.157], [64670.3, 0.101], [64671.3, 0.0], [64671.5, 2.15], [64671.8, 0.558], [64673.3, 0.133], [64673.5, 2.437], [64673.8, 0.119], [64674.4, 0.888], [64678.8, 3.486], [64682.5, 0.141], [64683.1, 0.036], [64700.6, 0.002], [64712.2, 0.004], [64718.7, 0.011], [64720.7, 6.632], [64721.3, 0.043], [64731.6, 0.003], [64810.5, 7.27], [64849.3, 4.109], [64870.3, 0.003], [65300.5, 2.194], [65365.5, 0.038], [65429.8, 27.149], [65462.2, 10.261], [65591.5, 23.904]]}
{"kind": "depth", "E": 1787082385263, "U": 11315508116022, "u": 11315508125998, "recv_ms": 1787082385235, "bids": [[1000.0, 35.81], [14153.9, 3.766], [14253.9, 0.364], [14553.9, 0.07], [51723.0, 0.0], [51723.1, 0.0], [58188.5, 0.002], [62067.7, 1.428], [63536.9, 0.63], [63641.0, 3.14], [64007.4, 4.751], [64156.3, 0.816], [64330.6, 5.209], [64585.8, 4.273], [64585.9, 0.439], [64605.8, 0.053], [64619.8, 0.005], [64619.9, 0.017], [64621.3, 0.027], [64626.3, 2.701], [64630.6, 0.003], [64630.9, 2.343], [64631.5, 0.02], [64631.9, 0.559], [64634.1, 0.0], [64634.2, 0.07], [64634.9, 0.027], [64635.5, 0.001], [64635.7, 0.181], [64635.8, 0.066], [64636.1, 2.321], [64636.6, 0.927], [64636.8, 0.233], [64637.0, 0.059], [64638.3, 0.169], [64639.3, 0.003], [64640.1, 0.318], [64640.7, 1.633], [64643.4, 0.007], [64644.4, 0.45], [64645.6, 0.035], [64646.1, 0.232], [64648.3, 0.004], [64650.3, 0.001], [64650.5, 0.005]], "asks": [[64654.0, 12.732], [64656.8, 0.006], [64656.9, 0.0], [64657.0, 0.005], [64657.3, 0.017], [64657.4, 0.313], [64657.6, 0.021], [64657.7, 0.009], [64657.8, 0.59], [64657.9, 2.572], [64658.0, 1.533], [64660.3, 0.206], [64660.4, 0.002], [64660.5, 0.003], [64660.7, 2.406], [64660.8, 0.003], [64662.1, 0.143], [64665.1, 0.003], [64666.0, 0.003], [64668.6, 2.775], [64668.7, 0.0], [64669.2, 1.706], [64669.3, 0.926], [64669.5, 0.001], [64670.9, 0.134], [64672.7, 0.007], [64673.0, 0.002], [64673.4, 0.9], [64673.8, 0.003], [64674.2, 0.463], [64674.3, 0.121], [64674.4, 0.888], [64677.0, 0.063], [64677.2, 0.026], [64677.5, 0.098], [64679.1, 0.379], [64679.8, 1.686], [64685.7, 0.106], [64686.5, 0.143], [64688.3, 0.001], [64688.5, 0.018], [64700.6, 0.03], [64704.5, 0.02], [64711.5, 0.211], [64810.5, 7.291], [64849.3, 4.165], [65300.5, 2.194], [65645.1, 6.474], [65947.0, 0.157]]}
{"kind": "depth", "E": 1787082385365, "U": 11315508126192, "u": 11315508137454, "recv_ms": 1787082385335, "bids": [[14153.9, 3.668], [14253.9, 0.238], [14553.9, 0.294], [51723.0, 0.0], [58188.5, 0.002], [61421.2, 0.006], [63653.9, 0.024], [63705.7, 10.738], [63845.7, 12.384], [64007.4, 4.751], [64136.7, 6.261], [64624.7, 0.003], [64630.9, 2.962], [64631.2, 0.336], [64633.9, 0.157], [64638.3, 0.788], [64640.7, 1.632], [64644.6, 0.143], [64650.6, 0.028], [64653.9, 15.921]], "asks": [[64654.0, 12.734], [64656.6, 0.025], [64657.4, 0.336], [64657.8, 0.59], [64667.0, 3.97], [64667.9, 0.625], [64671.8, 0.001], [64672.5, 0.558], [64675.3, 0.622], [64678.8, 0.004], [64678.9, 0.004], [64684.3, 0.767], [64686.7, 10.001], [64810.5, 10.415], [64849.3, 0.506], [65300.5, 2.194], [65429.8, 28.369], [65654.0, 0.01], [65709.7, 1.064]]}
{"kind": "depth", "E": 1787082385569, "U": 11315508145287, "u": 11315508151206, "recv_ms": 1787082385538, "bids": [[14153.9, 3.43], [14253.9, 0.0], [14553.9, 0.77], [58188.5, 0.002], [61421.2, 0.008], [62067.7, 1.428], [63653.9, 0.044], [63737.9, 2.194], [63942.7, 5.699], [64007.4, 4.751], [64330.6, 5.209], [64513.7, 0.412], [64621.8, 0.001], [64629.0, 1.024], [64641.9, 0.02], [64644.6, 0.142], [64650.7, 0.144], [64653.9, 15.921]], "asks": [[64654.0, 12.78], [64656.6, 0.025], [64656.7, 0.666], [64657.5, 0.002], [64657.8, 0.15], [64658.0, 0.635], [64659.0, 0.109], [64660.5, 0.583], [64661.3, 0.31], [64661.8, 0.045], [64662.1, 0.135], [64662.2, 0.484], [64666.0, 0.903], [64667.0, 3.07], [64684.3, 0.816], [64721.3, 0.052], [64793.5, 0.0], [64875.4, 0.0], [64895.5, 0.004], [65230.9, 7.959], [65300.5, 2.194], [65591.5, 22.838], [65654.0, 0.03]]}
{"kind": "depth", "E": 1787082385671, "U": 11315508151413, "u": 11315508160734, "recv_ms": 1787082385642, "bids": [[14153.9, 3.066], [14553.9, 1.134], [58188.5, 0.002], [62067.7, 1.431], [63360.9, 0.029], [63716.4, 19.514], [64007.4, 4.751], [64091.4, 1.223], [64136.7, 10.152], [64513.7, 5.837], [64524.5, 0.005], [64563.5, 0.0], [64568.2, 0.079], [64572.3, 41.979], [64574.5, 1.696], [64635.5, 0.02], [64640.2, 0.055], [64641.9, 0.019], [64645.0, 0.145], [64650.7, 0.137]], "asks": [[64657.8, 0.714], [64658.0, 1.535], [64660.5, 0.019], [64793.5, 5.402], [64849.3, 0.0], [64877.7, 0.024], [65300.5, 2.194], [65591.5, 23.904], [65720.8, 3.192]]}
{"kind": "depth", "E": 1787082385773, "U": 11315508160962, "u": 11315508166973, "recv_ms": 1787082385742, "bids": [[1000.0, 35.81], [14153.9, 2.702], [14553.9, 1.498], [34000.0, 1.146], [51723.0, 0.0], [58188.5, 0.002], [63360.9, 0.026], [63653.9, 0.024], [63716.4, 20.611], [63770.2, 8.19], [64028.6, 0.003], [64627.4, 1.297], [64633.9, 0.003], [64634.2, 0.0], [64637.5, 0.02], [64650.2, 0.016], [64650.9, 0.02]], "asks": [[64656.6, 0.025], [64656.9, 0.084], [64660.6, 0.386], [64662.1, 0.127], [64670.0, 0.007], [64810.5, 7.385], [64849.3, 3.813], [65300.5, 2.194], [65322.9, 0.0], [65429.8, 27.607], [65494.9, 2.748], [65654.0, 0.01], [65947.0, 0.154]]}
{"kind": "depth", "E": 1787082385875, "U": 11315508167073, "u": 11315508174506, "recv_ms": 1787082385845, "bids": [[14153.9, 2.352], [14553.9, 1.848], [51723.0, 0.0], [58188.5, 0.002], [62067.7, 1.428], [64007.4, 4.751], [64330.6, 5.209], [64572.3, 0.028], [64574.5, 43.647], [64633.8, 0.197], [64650.7, 0.144]], "asks": [[64657.8, 0.714], [64658.0, 0.635], [64659.0, 1.009], [64660.4, 0.002], [64660.5, 0.019], [64673.4, 0.971], [65235.9, 10.349], [65300.5, 2.194], [65429.8, 28.369]]}
{"kind": "depth", "E": 1787082385977, "U": 11315508174696, "u": 11315508181533, "recv_ms": 1787082385951, "bids": [[14153.9, 2.002], [14553.9, 2.198], [58188.5, 0.002], [62067.7, 1.431], [63653.9, 0.044], [64007.4, 4.751], [64513.7, 0.412], [64544.7, 0.002], [64621.8, 0.154], [64630.5, 0.0], [64631.6, 0.119], [64636.0, 3.342], [64640.2, 0.054], [64648.3, 0.001], [64650.7, 0.144]], "asks": [[64656.8, 0.004], [64658.0, 0.637], [64660.5, 0.096], [64662.1, 0.05], [64662.8, 0.204], [64663.3, 2.779], [64723.1, 0.0], [64724.1, 0.001], [64729.4, 0.02], [64730.5, 0.008], [64793.5, 0.0], [65300.5, 2.194], [65407.4, 1.164], [65654.0, 0.03]]}
{"kind": "depth", "E": 1787082386079, "U": 11315508181737, "u": 11315508188617, "recv_ms": 1787082386049, "bids": [[1000.0, 35.81], [14153.9, 1.638], [14553.9, 2.562], [51723.0, 0.004], [58188.5, 0.002], [61421.2, 0.008], [62067.7, 1.428], [63651.5, 0.038], [63716.1, 0.0], [63719.5, 0.0], [63748.7, 12.029], [64007.4, 4.751], [64034.8, 6.512], [64496.7, 10.466], [64498.2, 2.228], [64513.7, 5.837], [64571.5, 1.697], [64573.1, 0.609], [64574.5, 41.985], [64574.6, 7.929], [64633.8, 0.043], [64633.9, 0.157], [64636.0, 3.341], [64639.0, 1.01], [64642.3, 0.352], [64650.7, 0.144], [64653.9, 15.921]], "asks": [[64656.5, 0.087], [64656.6, 0.025], [64656.7, 0.946], [64657.6, 0.023], [64658.0, 1.535], [64660.5, 0.003], [64660.6, 0.378], [64660.7, 2.322], [64662.1, 0.151], [64679.1, 2.283], [64683.7, 0.068], [64685.1, 0.014], [64691.9, 0.0], [64793.5, 5.402], [64810.4, 2.257], [64810.5, 10.415], [64849.3, 0.446], [65300.5, 2.194], [65521.8, 10.229], [65588.5, 0.008], [65591.8, 0.007], [65656.5, 0.085]]}
{"kind": "depth", "E": 1787082386181, "U": 11315508188746, "u": 11315508198984, "recv_ms": 1787082386153, "bids": [[14153.9, 1.288], [14553.9, 2.912], [51723.0, 0.0], [58188.5, 0.002], [61421.2, 0.006], [61421.3, 0.01], [62067.7, 1.431], [63350.1, 2.722], [63422.0, 0.097], [63493.8, 0.062], [63565.6, 0.374], [63637.4, 0.064], [63651.5, 0.046], [63653.9, 0.024], [63709.3, 0.058], [63716.1, 0.008], [63719.5, 0.008], [63781.1, 7.661], [63852.9, 0.058], [63924.7, 0.058], [63996.6, 1.684], [64007.3, 0.0], [64007.4, 4.751], [64330.6, 5.199], [64568.9, 0.016], [64571.9, 0.034], [64612.1, 0.0], [64627.0, 0.34], [64630.9, 2.343], [64631.2, 0.0], [64631.3, 0.117], [64631.6, 0.003], [64633.9, 0.003], [64638.3, 0.169], [64639.0, 1.009], [64644.1, 0.007], [64650.1, 1.026], [64650.7, 0.144], [64652.9, 0.0], [64653.2, 0.001], [64653.6, 0.001]], "asks": [[64654.0, 15.892], [64654.1, 0.057], [64655.3, 0.0], [64656.1, 0.085], [64656.9, 0.087], [64657.6, 0.021], [64660.3, 0.122], [64660.5, 0.003], [64661.6, 0.005], [64662.1, 0.05], [64662.2, 0.021], [64665.7, 0.025], [64665.8, 0.698], [64667.9, 0.006], [64675.3, 0.003], [64682.9, 10.07], [64683.7, 0.008], [64685.1, 0.0], [64686.7, 0.001], [64691.9, 0.06], [64700.6, 0.002], [64721.3, 0.043], [64721.7, 0.0], [64726.1, 39.24], [65300.5, 2.194], [65654.0, 0.01]]}
{"kind": "depth", "E": 1787082386283, "U": 11315508199041, "u": 11315508205779, "recv_ms": 1787082386255, "bids": [[14153.9, 0.924], [14553.9, 3.276], [51723.0, 0.0], [51723.1, 0.0], [58188.5, 0.002], [61421.2, 0.006], [64007.4, 4.751], [64039.7, 5.599], [64285.9, 0.123], [64563.5, 41.971], [64571.1, 0.498], [64571.5, 1.505], [64573.1, 0.34], [64574.3, 0.38], [64574.5, 0.034], [64574.6, 0.001], [64574.7, 0.565], [64575.9, 0.032], [64576.3, 0.01], [64591.8, 0.011], [64615.1, 0.391], [64628.5, 0.005], [64644.1, 0.006], [64649.0, 0.084], [64650.3, 0.001], [64650.7, 0.413], [64652.7, 0.017], [64653.9, 15.92]], "asks": [[64654.0, 15.894], [64655.6, 0.084], [64656.6, 0.025], [64659.9, 0.004], [64677.3, 0.066], [64682.5, 0.155], [64686.4, 1.032], [64700.6, 0.03], [64720.7, 0.942], [64721.3, 0.052], [64721.7, 39.257], [64723.4, 1.072], [64726.1, 0.0], [65289.4, 0.063], [65300.5, 2.194], [65361.3, 0.512], [65433.1, 0.058], [65504.9, 2.344], [65526.8, 4.444], [65576.7, 0.058], [65588.5, 0.016], [65591.8, 0.015], [65648.6, 1.115], [65656.5, 0.093], [65720.4, 0.068], [65792.2, 0.058], [65864.0, 0.058], [65935.9, 0.059]]}
{"kind": "depth", "E": 1787082386487, "U": 11315508213331, "u": 11315508219262, "recv_ms": 1787082386458, "bids": [[14153.9, 0.322], [14453.9, 0.112], [14553.9, 3.766], [58188.5, 0.002], [61421.2, 0.006], [62067.7, 1.431], [63360.9, 0.029], [64007.4, 4.751], [64039.7, 8.717], [64330.6, 5.208], [64563.5, 0.0], [64571.1, 0.421], [64571.5, 1.351], [64572.3, 41.999], [64573.1, 0.263], [64574.3, 0.399], [64574.7, 0.142], [64576.3, 0.007], [64577.6, 3.344], [64577.9, 0.015], [64579.2, 0.015], [64585.7, 0.111], [64595.7, 0.053], [64628.5, 0.004], [64633.9, 0.003], [64634.9, 0.028], [64637.3, 0.031], [64644.6, 0.142], [64649.0, 0.0], [64650.1, 1.024], [64650.3, 0.001], [64650.7, 0.567], [64652.5, 0.31], [64652.7, 0.101], [64653.1, 0.084], [64653.5, 0.086]], "asks": [[64654.0, 12.791], [64654.1, 0.055], [64655.6, 0.0], [64656.1, 0.001], [64656.6, 0.025], [64656.7, 0.946], [64657.0, 0.005], [64657.5, 0.004], [64661.6, 0.005], [64661.7, 0.001], [64662.1, 0.074], [64662.2, 0.561], [64665.7, 0.001], [64665.8, 0.158], [64686.4, 1.037], [64704.1, 0.0], [64711.5, 0.211], [64712.2, 0.001], [64977.3, 4.82], [65263.6, 2.746], [65300.5, 2.194]]}
{"kind": "depth", "E": 1787082386589, "U": 11315508219352, "u": 11315508224301, "recv_ms": 1787082386559, "bids": [[1000.0, 35.81], [14153.9, 0.21], [14453.9, 0.364], [14553.9, 3.626], [58188.5, 0.002], [61421.2, 0.006], [61421.3, 0.008], [62067.7, 1.428], [63653.9, 0.024], [63837.7, 5.155], [63891.3, 0.0], [63942.7, 5.933], [64007.4, 4.751], [64028.7, 0.546], [64330.6, 5.209], [64513.7, 0.412], [64634.9, 0.027], [64636.5, 0.498], [64650.3, 0.078], [64653.9, 15.922]], "asks": [[64658.0, 0.635], [64658.5, 0.301], [64660.5, 0.567], [64661.2, 0.359], [64662.1, 0.05], [64662.2, 0.021], [64679.9, 1.546], [64684.3, 0.613], [64793.5, 0.0], [64977.3, 4.821], [65300.5, 2.194], [65322.8, 0.535], [65429.8, 28.369], [65591.5, 24.97], [65654.0, 0.01], [65761.0, 1.523], [65766.0, 2.647]]}
{"kind": "depth", "E": 1787082386691, "U": 11315508224357, "u": 11315508231394, "recv_ms": 1787082386661, "bids": [[1000.0, 35.81], [14153.9, 0.084], [14453.9, 0.588], [14553.9, 3.528], [58188.5, 0.002], [61421.2, 0.006], [62067.7, 1.431], [63522.5, 1.292], [64007.4, 4.751], [64062.0, 0.0], [64496.7, 8.579], [64513.7, 4.712], [64524.5, 0.005], [64537.7, 2.319], [64537.9, 3.867], [64547.9, 2.699], [64548.4, 0.002], [64572.3, 0.028], [64573.1, 0.609], [64574.3, 0.476], [64574.5, 42.005], [64574.7, 0.565], [64575.9, 0.109], [64582.0, 3.418], [64582.1, 0.068], [64600.4, 0.004], [64607.6, 0.055], [64621.0, 0.039], [64621.1, 0.072], [64621.2, 0.256], [64624.5, 0.159], [64624.6, 0.323], [64624.7, 0.001], [64634.0, 0.002], [64650.3, 0.001], [64650.7, 0.182], [64653.5, 0.002], [64653.9, 15.898]], "asks": [[64654.0, 12.911], [64656.6, 0.025], [64684.2, 0.326], [64724.4, 0.38], [64724.5, 0.074], [64760.2, 0.842], [64761.6, 3.618], [64762.1, 0.001], [64788.6, 0.003], [64788.7, 4.33], [64793.5, 5.402], [64810.5, 7.546], [64849.3, 3.671], [65268.2, 10.003], [65300.5, 2.196], [65656.1, 15.363], [65914.8, 1.06]]}
{"kind": "depth", "E": 1787082386793, "U": 11315508231440, "u": 11315508236735, "recv_ms": 1787082386762, "bids": [[14153.9, 0.0], [14453.9, 0.868], [14553.9, 3.332], [58188.5, 0.002], [63653.9, 0.044], [63807.5, 0.0], [64007.4, 4.751], [64028.7, 0.0], [64136.7, 10.152], [64330.6, 5.199], [64634.1, 0.0], [64635.2, 0.004], [64636.5, 0.497], [64637.5, 0.02], [64650.7, 0.144]], "asks": [[64658.0, 0.635], [64659.0, 0.109], [64660.4, 0.465], [64660.5, 0.104], [64662.2, 0.021], [64670.0, 0.007], [64684.2, 0.172], [64684.3, 0.767], [65300.5, 2.194], [65322.8, 0.0], [65654.0, 0.03], [65735.2, 0.0]]}
{"kind": "depth", "E": 1787082386895, "U": 11315508236763, "u": 11315508242476, "recv_ms": 1787082386865, "bids": [[1000.0, 35.81], [14453.9, 1.218], [14553.9, 2.982], [58188.5, 0.002], [61421.3, 0.006], [62067.7, 1.428], [64007.4, 4.751], [64028.9, 4.86], [64574.7, 0.572], [64634.1, 0.0], [64635.2, 0.003], [64638.8, 0.001], [64650.7, 0.144]], "asks": [[64664.0, 1.478], [64673.4, 0.9], [64684.3, 0.613], [64684.4, 0.458], [65300.5, 2.194]]}
{"kind": "depth", "E": 1787082386997, "U": 11315508242662, "u": 11315508247889, "recv_ms": 1787082386970, "bids": [[1000.0, 35.81], [14453.9, 1.568], [14553.9, 2.632], [58188.5, 0.002], [62067.7, 1.431], [63653.9, 0.024], [64007.4, 4.751], [64068.3, 0.234], [64134.4, 0.702], [64457.9, 11.423], [64460.1, 0.548], [64496.7, 10.466], [64498.2, 0.742], [64513.7, 5.837], [64633.8, 0.197], [64637.3, 0.039], [64640.9, 0.033], [64641.3, 0.0], [64647.0, 0.019], [64649.0, 0.084], [64650.0, 1.568], [64650.1, 0.714], [64650.7, 0.137], [64652.5, 0.0], [64652.7, 0.017], [64653.1, 0.0]], "asks": [[64654.0, 16.013], [64655.3, 0.086], [64655.7, 0.091], [64656.5, 0.087], [64656.6, 0.018], [64657.5, 0.002], [64658.0, 1.535], [64660.4, 0.002], [64660.5, 0.003], [64662.2, 0.585], [64672.1, 0.557], [64672.5, 0.001], [64679.9, 1.532], [64682.5, 0.141], [64684.4, 0.458], [64698.0, 0.442], [64721.7, 0.0], [64726.1, 39.257], [64793.5, 5.402], [64810.4, 0.805], [64810.5, 10.415], [64849.3, 0.514], [65300.5, 2.196], [65654.0, 0.01], [65740.2, 2.428]]}
{"kind": "depth", "E": 1787082387099, "U": 11315508247919, "u": 11315508253013, "recv_ms": 1787082387069, "bids": [[14453.9, 1.932], [14553.9, 2.268], [58188.5, 0.002], [61421.2, 0.006], [62067.7, 1.428], [63651.5, 0.038], [64007.4, 4.751], [64330.6, 5.199], [64460.1, 2.248], [64498.2, 2.228], [64567.9, 41.976], [64568.2, 0.079], [64568.8, 0.001], [64571.1, 0.498], [64571.5, 1.627], [64573.1, 0.263], [64574.3, 0.38], [64574.5, 0.034], [64574.6, 0.001], [64574.7, 0.572], [64575.9, 0.109], [64611.9, 0.033], [64628.5, 0.005], [64634.3, 0.002], [64637.1, 0.0], [64637.2, 0.001], [64638.8, 0.0], [64642.3, 0.352], [64646.9, 0.574], [64650.3, 0.001], [64650.7, 0.413], [64653.1, 0.0], [64653.9, 15.896]], "asks": [[64654.0, 15.862], [64654.1, 0.057], [64655.3, 0.0], [64655.5, 0.199], [64655.7, 0.007], [64656.1, 0.085], [64657.7, 0.009], [64657.8, 0.15], [64658.0, 0.635], [64660.5, 0.668], [64661.6, 0.005], [64661.7, 0.001], [64662.2, 0.484], [64662.5, 0.326], [64663.3, 2.47], [64682.3, 3.255], [64684.4, 0.458], [64723.9, 39.307], [64726.1, 0.0], [64810.4, 1.819], [64810.5, 10.415], [64849.3, 0.533], [65300.5, 2.194], [65656.5, 0.085], [66593.5, 0.031]]}
{"kind": "depth", "E": 1787082387201, "U": 11315508253127, "u": 11315508258856, "recv_ms": 1787082387170, "bids": [[1000.0, 35.81], [14453.9, 2.282], [14553.9, 1.918], [58188.5, 0.002], [61421.2, 0.006], [63651.4, 0.01], [63653.9, 0.044], [63834.6, 3.6], [64007.4, 4.753], [64567.9, 0.008], [64568.2, 0.002], [64571.1, 0.421], [64571.5, 1.351], [64574.5, 42.002], [64574.7, 0.565], [64575.9, 0.032], [64628.5, 0.004], [64633.0, 0.056], [64637.3, 0.031], [64646.1, 0.0], [64646.4, 0.265], [64646.9, 0.574], [64647.0, 0.027], [64650.0, 1.566], [64650.3, 0.078], [64650.4, 0.023], [64650.6, 0.005], [64650.7, 0.586], [64650.9, 0.001], [64653.9, 15.896]], "asks": [[64654.0, 14.812], [64654.1, 0.055], [64655.3, 0.002], [64656.7, 0.666], [64657.6, 0.002], [64657.7, 0.028], [64659.0, 0.109], [64660.4, 0.465], [64662.2, 0.021], [64662.6, 1.013], [64684.4, 0.304], [64684.5, 0.385], [64810.5, 10.415], [64849.3, 0.592], [65300.5, 2.194], [65623.6, 0.0], [65654.0, 0.03], [65947.0, 0.157]]}
{"kind": "depth", "E": 1787082387303, "U": 11315508258940, "u": 11315508263797, "recv_ms": 1787082387273, "bids": [[1000.0, 35.81], [14453.9, 2.646], [14553.9, 1.554], [51723.1, 0.0], [58188.5, 0.002], [62067.7, 1.431], [63813.4, 13.38], [64007.4, 4.751], [64072.0, 12.561], [64464.8, 0.089], [64571.1, 0.498], [64574.5, 0.034], [64575.9, 0.109], [64576.7, 0.073], [64577.6, 3.44], [64577.9, 0.169], [64633.3, 0.163], [64633.8, 0.043], [64650.3, 0.001]], "asks": [[64662.0, 1.03], [64662.5, 0.017], [64663.0, 0.543], [64671.7, 0.68], [64672.3, 0.017], [65235.9, 9.431], [65300.5, 2.194], [65494.5, 26.537], [65656.4, 0.008]]}
{"kind": "depth", "E": 1787082387405, "U": 11315508263931, "u": 11315508268355, "recv_ms": 1787082387377, "bids": [[14453.9, 2.996], [14553.9, 1.204], [58188.5, 0.002], [61421.2, 0.004], [61421.3, 0.008], [62067.7, 1.428], [63653.9, 0.024], [63705.7, 9.641], [64007.0, 4.39], [64007.4, 4.751], [64330.6, 5.209], [64513.7, 0.412], [64571.1, 0.421], [64574.5, 42.002], [64575.9, 0.032], [64589.7, 0.002], [64590.1, 0.102], [64590.4, 1.21], [64590.7, 0.0], [64591.0, 0.001], [64608.4, 0.0], [64608.7, 0.85], [64609.0, 0.167], [64609.3, 0.0], [64609.6, 1.539], [64623.3, 0.014], [64623.4, 0.159], [64623.5, 0.001], [64623.6, 2.023], [64623.7, 2.444], [64623.8, 0.004], [64623.9, 1.871], [64624.0, 0.469], [64624.2, 0.451], [64626.1, 0.023], [64626.6, 0.013], [64633.0, 0.055], [64635.3, 0.032], [64643.4, 0.572], [64644.4, 0.311], [64644.5, 0.001], [64644.6, 0.002], [64644.7, 0.239], [64644.8, 0.174], [64644.9, 0.311], [64645.0, 0.115], [64645.1, 0.024], [64645.2, 0.002], [64645.3, 0.071], [64645.6, 0.003], [64645.9, 2.36], [64646.2, 0.166], [64646.6, 2.502], [64646.9, 0.001], [64647.0, 0.003], [64650.3, 0.097]], "asks": [[64656.4, 0.001], [64660.2, 0.001], [64660.3, 0.122], [64660.4, 0.002], [64660.5, 1.131], [64661.1, 0.241], [64661.5, 0.322], [64661.8, 0.0], [64662.1, 0.005], [64662.4, 1.108], [64662.6, 1.058], [64662.7, 0.003], [64662.8, 0.014], [64662.9, 0.007], [64663.0, 0.333], [64663.1, 0.343], [64663.2, 0.224], [64663.3, 2.33], [64663.4, 0.002], [64663.5, 0.101], [64663.6, 0.002], [64663.7, 0.001], [64665.7, 0.001], [64665.8, 0.158], [64679.8, 1.651], [64680.1, 0.502], [64680.4, 0.048], [64680.7, 0.0], [64681.1, 0.013], [64681.2, 0.169], [64681.4, 0.155], [64681.8, 0.318], [64683.8, 0.0], [64683.9, 2.32], [64684.0, 0.032], [64684.1, 0.003], [64684.2, 0.002], [64684.3, 0.561], [64684.4, 0.066], [64684.5, 0.154], [64684.6, 0.1], [64684.7, 0.186], [64698.4, 0.001], [64698.7, 0.029], [64699.0, 0.011], [64699.4, 0.002], [64699.7, 0.001], [64699.8, 2.426], [64721.7, 39.307], [64723.9, 0.009], [64793.5, 0.0], [65300.5, 2.194], [65454.0, 4.057], [65654.0, 0.01]]}
{"kind": "depth", "E": 1787082387507, "U": 11315508268460, "u": 11315508272931, "recv_ms": 1787082387477, "bids": [[1000.0, 35.81], [14453.9, 3.36], [14553.9, 0.84], [58188.5, 0.002], [61421.2, 0.004], [62067.7, 1.431], [63711.6, 12.226], [64007.4, 4.751], [64457.9, 0.483], [64460.1, 0.548], [64464.8, 0.012], [64496.7, 0.0], [64498.2, 0.742], [64570.1, 0.006], [64571.1, 0.402], [64571.5, 1.274], [64572.3, 41.996], [64574.5, 0.034], [64574.7, 0.219], [64577.6, 3.363], [64577.9, 0.015], [64609.7, 0.05], [64610.0, 0.963], [64629.5, 0.18], [64630.9, 2.962], [64635.3, 0.031], [64638.3, 0.788], [64643.4, 0.471], [64644.7, 0.309], [64644.9, 0.381], [64645.7, 0.237], [64646.4, 0.033], [64646.9, 0.134], [64647.2, 0.033], [64649.9, 2.606], [64650.3, 0.02], [64653.9, 15.897]], "asks": [[64661.3, 0.345], [64661.6, 0.043], [64663.6, 0.107], [64663.8, 0.292], [64667.9, 0.625], [64675.3, 0.622], [64679.9, 1.567], [64680.2, 0.389], [64684.6, 0.205], [64684.9, 0.091], [64698.8, 0.194], [64721.7, 0.0], [64723.9, 39.307], [64726.1, 0.0], [64810.4, 0.805], [64810.5, 0.0], [64849.3, 0.0], [64977.3, 4.82], [65300.5, 2.194], [65300.9, 3.221], [65454.0, 3.828], [65627.3, 0.266]]}
{"kind": "depth", "E": 1787082387609, "U": 11315508272935, "u": 11315508277744, "recv_ms": 1787082387580, "bids": [[1000.0, 35.81], [14353.9, 0.014], [14453.9, 3.696], [14553.9, 0.49], [51723.0, 0.0], [58188.5, 0.002], [62067.7, 1.428], [63590.6, 0.001], [63653.9, 0.044], [63716.4, 21.708], [64007.4, 4.751], [64330.6, 5.209], [64457.9, 11.333], [64496.7, 10.46], [64513.7, 5.837], [64572.3, 0.028], [64574.3, 0.38], [64574.5, 42.002], [64575.9, 0.013], [64609.0, 0.199], [64630.8, 0.352], [64631.1, 0.56], [64631.3, 0.001], [64631.9, 0.002], [64636.0, 4.267], [64636.6, 0.001], [64637.7, 0.026], [64643.4, 0.007], [64644.8, 0.244], [64645.0, 0.215], [64645.1, 0.124], [64645.3, 0.171], [64645.4, 0.507], [64645.5, 0.171], [64646.2, 0.198], [64646.9, 0.598], [64650.3, 0.078], [64650.4, 0.001], [64652.6, 0.085], [64653.1, 0.084]], "asks": [[64655.5, 0.115], [64655.7, 0.0], [64656.2, 0.113], [64662.3, 0.705], [64663.0, 0.621], [64663.1, 0.523], [64663.2, 0.434], [64663.3, 2.48], [64663.4, 0.142], [64663.7, 0.106], [64668.4, 2.179], [64669.3, 0.0], [64673.3, 0.674], [64673.5, 2.553], [64674.3, 0.005], [64674.4, 0.347], [64680.9, 0.107], [64681.6, 1.936], [64682.5, 0.155], [64684.1, 0.101], [64684.2, 0.392], [64684.4, 0.216], [64684.5, 0.294], [64684.7, 0.291], [64698.5, 0.289], [64699.5, 0.067], [64793.5, 5.402], [64810.5, 10.415], [64849.3, 0.607], [64977.3, 4.821], [65300.5, 2.194], [65654.0, 0.03], [71119.4, 0.001]]}
{"kind": "depth", "E": 1787082387813, "U": 11315508282735, "u": 11315508287238, "recv_ms": 1787082387783, "bids": [[1000.0, 35.81], [14353.9, 0.406], [14453.9, 3.612], [14553.9, 0.182], [58188.5, 0.002], [61421.2, 0.004], [61421.3, 0.01], [62067.7, 1.431], [63653.9, 0.024], [63835.0, 9.298], [63837.7, 4.92], [64007.4, 4.751], [64464.8, 0.089], [64513.7, 0.412], [64547.9, 2.699], [64571.1, 0.498], [64571.5, 1.627], [64574.5, 0.034], [64574.7, 0.565], [64591.0, 0.033], [64591.4, 0.06], [64623.9, 1.941], [64624.2, 0.521], [64629.7, 0.004], [64630.9, 2.343], [64637.5, 0.02], [64638.3, 0.169], [64649.9, 2.604], [64650.7, 0.156], [64651.7, 0.0], [64653.6, 0.002], [64653.9, 16.567]], "asks": [[64667.9, 0.006], [64670.0, 0.007], [64675.3, 0.003], [64761.6, 3.618], [64793.5, 0.0], [64977.3, 4.667], [65171.2, 9.372], [65300.5, 2.194], [65454.0, 3.486], [65654.0, 0.01]]}
{"kind": "depth", "E": 1787082387915, "U": 11315508287439, "u": 11315508291276, "recv_ms": 1787082387884, "bids": [[1000.0, 35.81], [14353.9, 0.644], [14453.9, 3.5], [14553.9, 0.056], [58188.5, 0.002], [62067.7, 1.428], [64007.4, 4.751], [64571.1, 0.421], [64571.5, 1.582], [64574.5, 42.002], [64575.9, 0.032], [64590.4, 1.242], [64623.6, 2.093], [64623.8, 0.074], [64629.7, 0.003], [64631.0, 0.498], [64633.3, 0.009], [64649.8, 1.008], [64650.3, 0.001], [64650.7, 0.586], [64653.1, 0.0]], "asks": [[65300.5, 2.194], [65526.8, 5.175], [65563.9, 0.016], [68228.8, 0.0]]}
{"kind": "depth", "E": 1787082388017, "U": 11315508291324, "u": 11315508295009, "recv_ms": 1787082387987, "bids": [[14353.9, 0.938], [14453.9, 3.262], [14553.9, 0.0], [58188.5, 0.002], [61421.3, 0.008], [62067.7, 1.431], [63032.8, 0.238], [63217.6, 2.384], [63576.4, 1.287], [63641.0, 2.041], [63653.9, 0.044], [63705.7, 8.543], [63761.0, 0.09], [64007.4, 4.751], [64330.6, 5.054], [64457.9, 0.483], [64496.7, 0.0], [64571.5, 1.351], [64576.3, 0.01], [64589.2, 0.189], [64590.7, 0.032], [64623.7, 2.514], [64624.0, 0.569], [64624.1, 0.108], [64624.3, 0.201], [64624.4, 0.07], [64626.5, 0.102], [64626.9, 1.577], [64630.8, 0.236], [64631.0, 0.497], [64631.1, 0.003], [64631.6, 0.119], [64631.9, 0.559], [64632.7, 0.02], [64633.9, 0.157], [64650.3, 0.001]], "asks": [[64673.4, 0.9], [64705.8, 0.003], [64810.5, 0.0], [64849.3, 0.0], [64977.3, 4.667], [65171.2, 9.677], [65300.5, 2.194], [65454.0, 3.144], [65580.4, 8.803], [65654.0, 0.03]]}
{"kind": "depth", "E": 1787082388119, "U": 11315508295021, "u": 11315508298995, "recv_ms": 1787082388089, "bids": [[1000.0, 35.81], [14353.9, 1.302], [14453.9, 2.898], [58188.5, 0.002], [61421.2, 0.004], [63576.4, 0.188], [63651.5, 0.029], [63651.8, 18.193], [63673.2, 3.315], [63705.7, 7.446], [63845.7, 13.166], [63899.6, 9.944], [64007.4, 4.751], [64457.9, 11.333], [64460.1, 2.234], [64496.7, 10.46], [64498.2, 2.227], [64513.7, 5.837], [64571.5, 1.274], [64574.6, 7.868], [64611.9, 0.034], [64623.7, 2.584], [64623.8, 0.144], [64624.1, 0.208], [64624.6, 0.395], [64632.7, 0.019], [64633.9, 0.157], [64640.5, 0.004], [64642.3, 0.352], [64650.3, 0.078]], "asks": [[64654.0, 15.86], [64654.1, 0.057], [64655.3, 0.0], [64655.7, 0.084], [64656.5, 0.087], [64658.6, 0.089], [64723.4, 6.764], [64793.5, 5.402], [64810.4, 2.257], [64810.5, 10.415], [64849.3, 0.608], [65300.5, 2.194], [65580.4, 7.737], [65591.5, 26.036], [65645.1, 4.344], [65656.5, 0.076], [65709.7, 0.0], [68228.8, 0.076]]}
{"kind": "depth", "E": 1787082388221, "U": 11315508299142, "u": 11315508308413, "recv_ms": 1787082388193, "bids": [[1000.0, 35.81], [14353.9, 1.652], [14453.9, 2.548], [58188.5, 0.002], [61421.2, 0.004], [62067.7, 1.428], [63511.2, 0.059], [63587.1, 3.487], [63651.4, 0.019], [63653.9, 0.024], [63740.8, 11.032], [63765.6, 4.249], [64007.4, 4.751], [64330.6, 5.209], [64513.7, 5.837], [64574.7, 0.572], [64575.9, 0.109], [64623.7, 2.92], [64627.0, 0.004], [64633.7, 0.156], [64633.9, 0.004], [64634.1, 0.0], [64637.1, 0.464], [64640.5, 0.003], [64640.9, 0.035], [64641.0, 0.917], [64644.5, 0.233], [64645.7, 0.005], [64646.9, 0.134], [64650.0, 1.543], [64650.3, 0.001], [64650.7, 0.163], [64652.6, 0.001]], "asks": [[64654.0, 16.773], [64655.3, 0.002], [64656.4, 0.003], [64658.0, 0.633], [64658.6, 0.086], [64666.9, 0.007], [64667.0, 3.067], [64682.5, 0.141], [64793.5, 5.402], [64810.5, 7.293], [64849.3, 4.097], [64977.3, 4.821], [65300.5, 2.194], [65516.9, 0.891], [65654.0, 0.01], [65656.4, 0.017]]}
{"kind": "depth", "E": 1787082388323, "U": 11315508308790, "u": 11315508317932, "recv_ms": 1787082388293, "bids": [[14353.9, 2.016], [14453.9, 2.184], [51723.0, 0.0], [51723.1, 0.0], [58188.5, 0.002], [62067.7, 1.431], [63360.9, 0.032], [63587.1, 4.586], [63651.8, 19.134], [63716.4, 23.902], [63867.6, 3.131], [63910.4, 9.769], [64007.2, 0.546], [64007.4, 4.751], [64330.6, 5.209], [64464.8, 0.012], [64543.9, 0.598], [64571.1, 0.402], [64574.7, 0.527], [64575.9, 0.109], [64602.1, 0.006], [64612.5, 3.11], [64614.6, 0.31], [64616.5, 1.178], [64637.1, 0.464], [64637.3, 0.031], [64637.4, 0.22], [64640.9, 0.033], [64641.0, 0.919], [64646.9, 0.126], [64647.0, 0.003], [64649.8, 1.006], [64650.2, 0.326], [64650.3, 0.001], [64650.7, 0.586], [64652.6, 0.311], [64653.1, 0.084], [64653.9, 16.567]], "asks": [[64654.0, 14.44], [64654.1, 0.055], [64655.2, 0.843], [64655.3, 0.0], [64655.4, 0.01], [64655.7, 0.0], [64656.4, 0.001], [64656.8, 0.006], [64658.6, 0.088], [64661.6, 0.044], [64661.7, 0.0], [64662.0, 0.13], [64666.9, 0.004], [64667.0, 3.07], [64699.3, 0.794], [64700.6, 0.044], [64705.8, 0.006], [65300.5, 2.194], [65300.7, 0.544], [65591.5, 27.102], [65656.1, 16.428], [65720.8, 4.256]]}
{"kind": "depth", "E": 1787082388425, "U": 11315508318117, "u": 11315508345107, "recv_ms": 1787082388394, "bids": [[1000.0, 35.81], [14353.9, 2.38], [14453.9, 1.82], [51723.0, 0.0], [58188.5, 0.002], [61421.2, 0.006], [62067.7, 1.428], [63516.0, 2.565], [63653.9, 0.044], [63727.8, 0.238], [63748.7, 12.969], [63845.7, 13.4], [64007.4, 4.751], [64574.7, 0.565], [64633.9, 0.003], [64637.1, 0.464], [64637.4, 0.212], [64638.3, 0.17], [64646.9, 0.134], [64650.7, 0.163], [64652.6, 0.001], [64653.8, 0.916], [64653.9, 16.568]], "asks": [[64658.0, 1.533], [64660.5, 1.115], [64662.4, 1.595], [64663.0, 1.521], [64810.5, 10.415], [64849.3, 0.571], [65106.4, 0.0], [65300.5, 2.196], [65654.0, 0.03]]}
{"kind": "depth", "E": 1787082388527, "U": 11315508345131, "u": 11315508354872, "recv_ms": 1787082388497, "bids": [[1000.0, 35.81], [14353.9, 2.73], [14453.9, 1.47], [58188.5, 0.002], [61421.2, 0.006], [62067.7, 1.431], [64007.2, 1.092], [64007.4, 4.751], [64630.1, 2.03], [64630.8, 0.352], [64631.1, 0.56], [64631.6, 0.003], [64631.9, 0.002], [64634.3, 0.003], [64636.1, 2.321], [64637.0, 0.985], [64637.3, 0.039], [64637.5, 0.639], [64638.3, 0.169], [64646.9, 0.126], [64649.9, 2.606], [64650.3, 0.001], [64650.7, 0.586], [64651.9, 0.004], [64653.1, 0.0]], "asks": [[64654.0, 14.485], [64655.7, 0.084], [64656.6, 0.018], [64656.9, 0.084], [64657.0, 0.008], [64657.8, 0.691], [64660.4, 0.002], [64660.5, 0.567], [64662.2, 0.021], [64667.1, 0.998], [64668.5, 0.018], [64669.4, 0.949], [64671.4, 0.165], [64672.1, 0.0], [64672.5, 0.558], [64673.3, 0.133], [64673.6, 2.499], [64674.4, 0.888], [64674.5, 7.372], [64683.4, 1.298], [64691.9, 0.0], [65110.0, 0.338], [65300.5, 2.194], [65300.7, 1.079], [65753.1, 13.015]]}
{"kind": "depth", "E": 1787082388629, "U": 11315508355045, "u": 11315508360843, "recv_ms": 1787082388598, "bids": [[14353.9, 3.094], [14453.9, 1.106], [58188.5, 0.002], [63653.9, 0.024], [64007.4, 6.311], [64330.6, 5.209], [64574.7, 0.142], [64575.9, 0.013], [64591.8, 0.002], [64637.1, 0.0], [64637.3, 0.031], [64646.9, 0.598], [64650.3, 0.001]], "asks": [[64660.5, 0.104], [64662.2, 0.484], [64849.8, 0.019], [64877.7, 0.005], [64977.3, 4.821], [65300.5, 2.194], [65654.0, 0.01], [71119.4, 0.003]]}
{"kind": "depth", "E": 1787082388731, "U": 11315508360959, "u": 11315508374091, "recv_ms": 1787082388701, "bids": [[1000.0, 35.81], [14353.9, 3.444], [14453.9, 0.756], [58188.5, 0.002], [61421.2, 0.006], [62067.7, 1.428], [63878.1, 17.736], [63884.5, 8.443], [64007.4, 6.311], [64524.0, 6.284], [64524.5, 0.005], [64537.9, 3.867], [64547.9, 2.699], [64577.6, 3.344], [64582.1, 0.022], [64582.2, 0.17], [64632.5, 0.011], [64633.4, 0.155], [64633.7, 0.002], [64634.3, 0.002], [64635.5, 0.001], [64636.1, 2.321], [64637.0, 0.985], [64637.1, 0.464], [64637.3, 0.039], [64646.9, 0.126], [64650.3, 0.001], [64652.8, 0.086], [64653.9, 16.568]], "asks": [[64654.0, 14.483], [64656.5, 0.087], [64668.5, 0.018], [64669.4, 0.949], [64673.3, 0.133], [64674.4, 0.888], [64682.5, 0.155], [64698.0, 0.456], [64700.0, 0.275], [64700.6, 0.002], [64724.5, 0.074], [64733.9, 0.035], [64760.2, 0.842], [64761.6, 3.618], [64780.5, 0.022], [64787.3, 1.549], [64788.7, 4.33], [64810.5, 10.415], [64827.1, 0.75], [64849.3, 0.573], [65300.5, 2.194], [65423.4, 7.328], [65534.8, 0.0], [65753.1, 17.571], [71119.4, 0.001]]}
{"kind": "depth", "E": 1787082388833, "U": 11315508374366, "u": 11315508390073, "recv_ms": 1787082388806, "bids": [[1000.0, 35.81], [14253.9, 0.028], [14353.9, 3.724], [14453.9, 0.448], [58188.5, 0.002], [61421.2, 0.006], [62067.7, 1.431], [63653.9, 0.044], [64007.4, 6.313], [64330.6, 5.054], [64513.7, 5.837], [64525.3, 0.042], [64553.9, 0.006], [64562.9, 0.006], [64568.3, 0.001], [64575.9, 0.013], [64585.2, 0.002], [64586.6, 0.04], [64596.1, 0.124], [64604.3, 1.447], [64608.2, 0.158], [64612.4, 0.759], [64614.7, 0.027], [64614.8, 0.002], [64621.3, 0.002], [64623.7, 2.584], [64630.1, 1.411], [64630.8, 0.236], [64632.2, 0.504], [64632.5, 0.126], [64633.9, 0.339], [64636.7, 1.868], [64637.1, 0.0], [64637.3, 0.031], [64637.5, 0.018], [64644.5, 0.001], [64645.1, 0.456], [64646.9, 0.598], [64648.5, 0.004], [64649.0, 0.0], [64650.1, 0.862], [64650.3, 0.001], [64650.8, 0.556], [64652.4, 0.312], [64653.2, 0.085], [64653.7, 0.144]], "asks": [[64654.0, 11.14], [64654.2, 0.001], [64654.4, 0.004], [64654.7, 0.044], [64655.2, 0.841], [64655.7, 0.0], [64656.0, 0.014], [64656.1, 0.001], [64656.5, 0.003], [64656.9, 0.0], [64657.0, 0.005], [64657.4, 0.313], [64657.7, 0.017], [64657.8, 0.551], [64657.9, 0.276], [64658.1, 0.005], [64658.5, 0.217], [64658.8, 0.002], [64659.0, 0.077], [64659.2, 1.278], [64659.9, 0.108], [64660.3, 0.206], [64660.5, 0.08], [64660.7, 2.406], [64661.0, 0.094], [64661.3, 0.035], [64661.4, 0.088], [64661.8, 0.084], [64662.3, 0.045], [64662.4, 1.594], [64663.0, 1.501], [64663.1, 0.431], [64663.8, 0.329], [64665.6, 0.023], [64666.4, 0.002], [64667.1, 0.379], [64668.1, 0.001], [64668.5, 0.002], [64668.8, 0.636], [64670.0, 0.005], [64671.7, 0.66], [64671.9, 0.003], [64672.0, 0.011], [64672.3, 0.017], [64672.6, 0.522], [64673.0, 0.092], [64673.5, 2.439], [64674.5, 0.722], [64675.2, 0.015], [64675.9, 0.919], [64676.1, 0.099], [64676.3, 0.003], [64677.0, 0.068], [64682.6, 0.013], [64682.9, 0.072], [64683.0, 0.071], [64683.4, 1.288], [64685.7, 0.036], [64687.3, 10.676], [64689.5, 6.053], [64692.5, 0.0], [64692.7, 0.112], [64699.1, 0.294], [64700.6, 0.03], [64710.1, 0.0], [64727.1, 0.0], [64728.5, 0.972], [64793.5, 5.402], [64923.2, 2.282], [65300.5, 2.198], [65654.0, 0.03]]}
{"kind": "depth", "E": 1787082388935, "U": 11315508390111, "u": 11315508408731, "recv_ms": 1787082388908, "bids": [[14253.9, 0.224], [14353.9, 3.71], [14453.9, 0.266], [58188.5, 0.002], [62067.7, 1.428], [63360.9, 0.026], [64007.4, 6.311], [64330.6, 5.054], [64412.6, 0.016], [64570.1, 41.976], [64574.5, 0.034], [64574.6, 0.001], [64574.7, 0.142], [64575.9, 0.013], [64576.7, 0.073], [64608.1, 0.149], [64608.2, 0.098], [64614.7, 0.002], [64615.4, 0.063], [64619.4, 0.019], [64621.3, 0.059], [64622.0, 0.738], [64623.0, 0.048], [64623.6, 2.118], [64629.2, 0.095], [64632.1, 0.001], [64633.1, 0.386], [64633.2, 5.157], [64633.9, 0.337], [64634.8, 0.314], [64636.7, 1.867], [64637.0, 0.059], [64637.5, 0.02], [64638.2, 1.053], [64640.9, 0.026], [64641.4, 0.024], [64642.0, 0.15], [64643.1, 1.921], [64643.2, 0.132], [64643.4, 0.533], [64645.1, 0.224], [64646.1, 0.541], [64646.3, 0.002], [64646.7, 0.243], [64646.8, 0.0], [64646.9, 0.033], [64648.7, 0.007], [64649.3, 1.251], [64649.9, 2.697], [64650.1, 0.714], [64650.2, 0.326], [64650.3, 0.001], [64650.5, 0.005], [64650.7, 0.567], [64650.8, 0.0], [64651.0, 0.0], [64651.3, 0.0], [64651.9, 0.027], [64652.1, 0.106], [64652.2, 0.023], [64652.3, 0.001], [64652.7, 0.017], [64653.9, 16.678]], "asks": [[64654.0, 7.478], [64654.1, 0.051], [64654.2, 0.0], [64654.3, 0.002], [64654.7, 0.004], [64655.3, 0.002], [64655.9, 0.12], [64656.0, 0.015], [64656.2, 0.106], [64656.3, 0.003], [64656.5, 0.003], [64656.7, 0.491], [64656.8, 0.004], [64656.9, 0.0], [64657.4, 0.01], [64657.7, 0.009], [64657.8, 0.003], [64657.9, 0.251], [64658.1, 0.165], [64658.2, 0.003], [64658.3, 0.0], [64658.6, 0.088], [64658.8, 0.086], [64659.0, 0.08], [64659.2, 1.195], [64659.3, 0.005], [64659.4, 0.096], [64659.5, 0.001], [64659.9, 0.088], [64660.0, 0.028], [64660.4, 0.018], [64660.5, 0.644], [64660.7, 2.408], [64661.0, 0.091], [64661.4, 0.398], [64662.1, 0.097], [64662.4, 1.595], [64662.5, 0.049], [64663.0, 1.192], [64664.0, 1.787], [64664.2, 0.125], [64665.6, 0.024], [64666.0, 0.003], [64667.0, 2.99], [64667.8, 0.0], [64668.0, 1.035], [64668.8, 0.637], [64669.4, 0.023], [64669.8, 0.007], [64670.0, 0.007], [64670.3, 0.094], [64670.6, 0.926], [64670.7, 0.082], [64671.3, 0.007], [64671.7, 0.64], [64671.9, 0.163], [64672.0, 0.012], [64672.5, 0.001], [64672.6, 0.465], [64673.5, 2.147], [64673.6, 2.556], [64673.9, 0.35], [64674.4, 0.347], [64674.5, 0.606], [64674.8, 0.04], [64675.2, 0.132], [64675.7, 0.542], [64676.2, 0.037], [64682.3, 1.681], [64682.4, 4.578], [64682.9, 0.07], [64684.5, 0.14], [64684.7, 0.571], [64686.0, 0.248], [64686.5, 0.023], [64686.6, 0.001], [64691.5, 0.002], [64693.2, 0.027], [64694.0, 2.441], [64711.5, 0.001], [64718.3, 0.211], [64810.5, 10.415], [64849.3, 0.359], [64923.2, 5.048], [65300.5, 2.194], [65539.8, 3.053], [65580.4, 6.68], [65947.0, 0.151]]}
{"kind": "depth", "E": 1787082389037, "U": 11315508408750, "u": 11315508423432, "recv_ms": 1787082389009, "bids": [[1000.0, 35.81], [14253.9, 0.462], [14353.9, 3.584], [14453.9, 0.154], [58188.5, 0.002], [61421.2, 0.006], [62067.7, 1.431], [63653.9, 0.024], [63808.5, 12.998], [63813.2, 1.643], [63878.1, 22.426], [63884.5, 9.381], [64007.4, 6.311], [64136.7, 9.841], [64330.6, 5.209], [64562.9, 0.001], [64563.6, 0.087], [64570.1, 0.006], [64576.3, 0.01], [64576.7, 42.079], [64585.3, 0.719], [64586.6, 0.014], [64595.7, 0.05], [64627.3, 0.002], [64628.9, 0.312], [64629.1, 0.0], [64631.1, 0.003], [64633.4, 0.712], [64636.7, 1.917], [64637.7, 0.027], [64642.3, 0.357], [64643.4, 0.069], [64644.0, 0.396], [64644.2, 0.0], [64645.5, 0.48], [64646.6, 2.551], [64646.7, 0.707], [64647.3, 0.374], [64650.3, 0.001], [64652.0, 0.002], [64652.4, 0.332], [64653.6, 0.005], [64653.9, 16.677]], "asks": [[64654.0, 7.317], [64655.1, 0.175], [64655.2, 0.85], [64656.7, 0.696], [64657.3, 0.015], [64657.4, 0.01], [64657.8, 0.003], [64657.9, 2.694], [64658.0, 0.633], [64658.8, 0.002], [64659.1, 0.0], [64659.2, 1.299], [64659.3, 0.003], [64659.6, 0.505], [64659.7, 0.002], [64660.0, 0.03], [64660.4, 0.002], [64660.5, 0.628], [64660.7, 2.408], [64661.4, 0.088], [64662.1, 0.089], [64662.5, 0.133], [64664.3, 1.316], [64675.2, 0.016], [64675.8, 1.112], [64677.0, 0.063], [64677.8, 0.469], [64684.7, 0.417], [64684.8, 0.259], [64686.4, 1.157], [64691.9, 0.06], [64694.0, 2.321], [64699.1, 0.234], [64710.7, 1.317], [64715.5, 0.66], [64718.3, 0.001], [64727.2, 0.026], [64728.5, 0.946], [64748.8, 0.018], [64748.9, 0.0], [64809.2, 0.002], [65300.5, 2.194], [65423.4, 8.244], [65462.2, 10.49], [65654.0, 0.01], [65857.9, 3.863]]}
{"kind": "depth", "E": 1787082389139, "U": 11315508423810, "u": 11315508434946, "recv_ms": 1787082389110, "bids": [[1000.0, 35.81], [14253.9, 0.7], [14353.9, 3.472], [14453.9, 0.028], [51723.0, 0.0], [58188.5, 0.002], [63813.4, 13.693], [64191.5, 0.002], [64513.7, 0.412], [64570.1, 0.006], [64574.5, 43.638], [64574.7, 0.296], [64576.7, 0.073], [64577.6, 3.363], [64577.9, 0.169], [64642.3, 0.352], [64646.2, 0.43], [64646.7, 0.475], [64647.2, 0.034], [64650.3, 0.001], [64652.0, 0.001], [64653.6, 0.002]], "asks": [[64656.4, 0.001], [64657.4, 0.32], [64657.8, 0.019], [64658.4, 0.085], [64658.8, 0.086], [64659.1, 0.032], [64660.4, 0.018], [64661.3, 0.036], [64661.4, 0.398], [64662.0, 1.03], [64662.1, 0.097], [64662.5, 0.049], [64678.8, 0.029], [64684.6, 0.205], [64684.8, 0.105], [64686.0, 0.223], [64793.5, 0.0], [65300.5, 2.194], [65423.4, 7.328], [65591.5, 28.168]]}
{"kind": "depth", "E": 1787082389241, "U": 11315508435202, "u": 11315508445027, "recv_ms": 1787082389213, "bids": [[14253.9, 1.036], [14353.9, 3.164], [14453.9, 0.0], [51723.0, 0.0], [58188.5, 0.002], [61421.2, 0.006], [62067.7, 1.428], [63554.8, 7.07], [63653.9, 0.044], [63716.4, 24.059], [63837.7, 4.655], [64007.4, 6.313], [64197.9, 0.117], [64330.6, 5.199], [64513.7, 5.837], [64574.5, 43.638], [64574.7, 0.565], [64575.9, 0.032], [64576.7, 0.073], [64632.6, 0.562], [64633.2, 5.003], [64633.4, 0.155], [64637.5, 0.02], [64638.2, 0.127], [64638.5, 0.928], [64643.4, 0.069], [64643.8, 0.024], [64646.1, 0.541], [64647.2, 0.033], [64650.7, 0.221], [64653.9, 16.677]], "asks": [[64654.0, 7.318], [64654.2, 0.002], [64654.3, 0.037], [64654.7, 0.002], [64656.6, 0.02], [64661.2, 0.362], [64663.8, 0.292], [64669.0, 0.044], [64674.8, 0.04], [64675.7, 0.542], [64676.2, 0.002], [64679.9, 1.716], [64684.7, 0.417], [64684.8, 0.259], [64687.4, 0.0], [64793.5, 5.402], [64849.3, 4.501], [65263.6, 2.089], [65300.5, 2.194], [65462.2, 10.719], [65654.0, 0.03], [65863.0, 3.549]]}
{"kind": "depth", "E": 1787082389343, "U": 11315508445040, "u": 11315508453683, "recv_ms": 1787082389314, "bids": [[1000.0, 35.81], [14253.9, 1.386], [14353.9, 2.814], [51723.1, 0.0], [58188.5, 0.002], [61421.2, 0.006], [62067.7, 1.431], [64007.4, 6.311], [64136.7, 10.152], [64574.5, 1.632], [64574.7, 0.572], [64576.7, 42.079], [64577.9, 0.445], [64605.7, 0.211], [64612.4, 0.549], [64634.1, 0.002], [64634.8, 0.312], [64644.6, 0.234], [64646.2, 0.198], [64646.8, 0.093], [64649.9, 2.604], [64650.7, 0.144], [64653.9, 16.569]], "asks": [[64654.0, 7.546], [64656.3, 0.003], [64657.5, 0.086], [64657.8, 0.567], [64657.9, 2.778], [64658.1, 0.164], [64659.3, 0.005], [64660.0, 0.028], [64660.4, 0.018], [64660.5, 0.08], [64661.3, 0.035], [64661.8, 0.0], [64662.1, 0.013], [64668.0, 1.053], [64669.8, 0.008], [64684.7, 0.571], [64684.8, 0.105], [64714.0, 0.069], [64849.3, 1.918], [65300.5, 2.194], [65423.4, 8.244], [65947.0, 0.154]]}
{"kind": "depth", "E": 1787082389445, "U": 11315508453846, "u": 11315508461283, "recv_ms": 1787082389416, "bids": [[1000.0, 35.81], [14253.9, 1.75], [14353.9, 2.45], [51723.0, 0.0], [58188.5, 0.002], [62067.7, 1.428], [63653.9, 0.024], [64007.4, 6.311], [64570.1, 0.006], [64571.5, 1.697], [64572.3, 42.034], [64576.7, 0.073], [64651.9, 0.004], [64652.1, 0.084], [64652.2, 0.003], [64652.4, 0.312], [64653.9, 16.577]], "asks": [[64662.0, 0.13], [64676.2, 0.052], [64683.4, 1.238], [64684.7, 0.571], [65267.3, 0.005], [65300.5, 2.194], [65462.2, 11.061], [65654.0, 0.01], [65830.7, 0.826], [67886.7, 0.08]]}
{"kind": "depth", "E": 1787082389547, "U": 11315508461367, "u": 11315508467974, "recv_ms": 1787082389518, "bids": [[14253.9, 2.1], [14353.9, 2.1], [51723.0, 0.0], [58188.5, 0.002], [63550.0, 4.978], [63845.7, 13.556], [64007.4, 6.311], [64330.6, 5.199], [64572.3, 0.028], [64574.5, 43.638], [64650.7, 0.221]], "asks": [[64656.3, 0.003], [64684.7, 0.417], [64684.8, 0.259], [65300.5, 2.194]]}
{"kind": "depth", "E": 1787082389649, "U": 11315508468052, "u": 11315508474774, "recv_ms": 1787082389621, "bids": [[1000.0, 35.81], [14253.9, 2.45], [14353.9, 1.75], [51723.0, 0.002], [58188.5, 0.002], [61421.2, 0.006], [62067.7, 1.431], [63453.3, 2.044], [63653.9, 0.044], [63845.7, 13.791], [64007.4, 6.311], [64330.6, 5.198], [64524.5, 0.005], [64570.1, 42.012], [64574.5, 1.632], [64600.7, 0.4], [64631.0, 1.116], [64632.3, 0.017], [64632.7, 0.004], [64633.1, 0.379], [64636.6, 0.016], [64638.4, 0.62], [64643.8, 0.023], [64645.7, 0.006], [64650.7, 0.49], [64651.6, 0.023], [64651.9, 0.024], [64653.9, 16.578]], "asks": [[64662.0, 1.03], [64668.0, 1.672], [64670.6, 0.0], [64671.5, 3.076], [64673.5, 1.59], [64673.6, 2.499], [64674.4, 0.904], [64674.5, 0.663], [64675.3, 0.622], [64675.6, 0.542], [64675.7, 0.001], [64675.8, 0.996], [64676.6, 0.146], [64676.7, 0.016], [64849.3, 1.918], [64977.3, 4.82], [65268.2, 10.691], [65300.5, 2.194], [65357.8, 0.0], [65572.1, 3.77], [65654.0, 0.03], [65809.5, 0.88]]}
{"kind": "depth", "E": 1787082389751, "U": 11315508474961, "u": 11315508480146, "recv_ms": 1787082389724, "bids": [[1000.0, 35.81], [14253.9, 2.814], [14353.9, 1.386], [51723.0, 0.0], [58188.5, 0.002], [61421.2, 0.006], [62067.7, 1.428], [63037.6, 1.827], [63360.9, 0.023], [63785.0, 1.689], [64007.4, 6.311], [64136.7, 9.842], [64330.6, 5.199], [64570.1, 0.006], [64572.3, 0.028], [64574.5, 43.638], [64636.5, 0.496], [64638.1, 0.93], [64638.4, 0.001], [64638.5, 0.002], [64643.1, 1.922], [64650.7, 0.221], [64651.5, 0.108], [64651.6, 0.0], [64651.7, 0.019], [64651.9, 0.004], [64653.9, 16.578]], "asks": [[64654.0, 7.653], [64654.7, 0.004], [64656.3, 0.003], [64659.3, 0.028], [64659.4, 0.074], [64660.0, 0.006], [64675.6, 0.001], [64675.7, 0.542], [64676.7, 0.016], [64977.3, 4.821], [65300.5, 2.194], [65947.0, 0.157]]}
{"kind": "depth", "E": 1787082390159, "U": 11315508500990, "u": 11315508508953, "recv_ms": 1787082390129, "bids": [[14153.9, 0.28], [14253.9, 3.682], [14353.9, 0.238], [58188.5, 0.002], [61421.2, 0.006], [62067.7, 1.431], [63735.8, 2.341], [63954.9, 0.001], [64007.4, 6.311], [64071.9, 4.361], [64330.6, 5.209], [64557.2, 0.003], [64564.0, 0.004], [64568.7, 0.982], [64568.8, 0.0], [64571.2, 3.63], [64577.7, 7.32], [64600.7, 0.399], [64611.9, 0.032], [64613.5, 1.085], [64614.1, 0.027], [64644.3, 0.004], [64647.7, 0.003]], "asks": [[64659.2, 1.279], [64666.0, 0.004], [64668.0, 0.153], [64675.3, 0.003], [64685.9, 2.743], [64717.2, 0.905], [64717.7, 0.002], [65300.5, 2.194], [65454.0, 2.915], [66040.2, 0.003]]}
{"kind": "depth", "E": 1787082390261, "U": 11315508509110, "u": 11315508515499, "recv_ms": 1787082390232, "bids": [[1000.0, 35.81], [14153.9, 0.518], [14253.9, 3.556], [14353.9, 0.126], [51723.0, 0.002], [58188.5, 0.002], [61421.2, 0.006], [62067.7, 1.428], [63360.9, 0.023], [63651.8, 20.232], [63653.9, 0.024], [63684.1, 7.672], [63808.4, 1.095], [63934.3, 0.0], [64007.4, 6.311], [64160.2, 0.005], [64513.7, 5.474], [64576.3, 0.007], [64579.2, 0.034], [64589.2, 0.188], [64595.7, 0.053], [64632.6, 0.005], [64633.6, 2.5], [64644.6, 0.002], [64645.9, 2.592], [64647.7, 0.002], [64650.7, 0.221], [64651.2, 0.005], [64653.9, 16.864]], "asks": [[64654.0, 7.429], [64686.4, 1.157], [64718.7, 0.01], [64793.5, 5.402], [65300.5, 2.194], [65300.6, 0.082], [65654.0, 0.01], [67886.7, 0.07]]}
{"kind": "depth", "E": 1787082390363, "U": 11315508515655, "u": 11315508523440, "recv_ms": 1787082390332, "bids": [[1000.0, 35.81], [14153.9, 0.756], [14253.9, 3.43], [14353.9, 0.014], [51723.0, 0.0], [51723.1, 0.0], [58188.5, 0.002], [62067.7, 1.431], [64007.4, 6.311], [64330.6, 5.209], [64574.7, 0.565], [64589.2, 0.191], [64650.7, 0.336], [64651.2, 0.004], [64653.9, 16.865]], "asks": [[64656.3, 0.003], [65300.5, 2.194], [65979.4, 1.514]]}
{"kind": "depth", "E": 1787082390465, "U": 11315508523634, "u": 11315508531592, "recv_ms": 1787082390434, "bids": [[14153.9, 1.106], [14253.9, 3.094], [14353.9, 0.0], [58188.5, 0.002], [62067.7, 1.428], [63653.9, 0.044], [63702.0, 0.011], [64007.4, 6.311], [64191.4, 0.005], [64496.7, 0.0], [64498.2, 0.742], [64513.7, 0.412], [64636.2, 0.017], [64643.2, 0.152], [64651.4, 0.026], [64651.5, 0.085]], "asks": [[64658.8, 0.109], [64793.5, 0.0], [64810.4, 0.805], [64810.5, 0.0], [65300.5, 2.194], [65654.0, 0.03]]}
{"kind": "depth", "E": 1787082390567, "U": 11315508531865, "u": 11315508540009, "recv_ms": 1787082390537, "bids": [[1000.0, 35.81], [14153.9, 1.47], [14253.9, 2.73], [58188.5, 0.002], [63813.3, 4.317], [64007.4, 6.311], [64629.1, 0.0], [64636.9, 0.002], [64638.2, 0.207]], "asks": [[64658.7, 0.063], [64658.8, 0.086], [64716.1, 0.506]]}
{"kind": "depth", "E": 1787082390873, "U": 11315508555684, "u": 11315508562348, "recv_ms": 1787082390844, "bids": [[1000.0, 35.81], [14153.9, 2.534], [14253.9, 1.666], [58188.5, 0.002], [62067.7, 1.431], [63653.9, 0.044], [63673.2, 2.217], [64007.4, 6.311], [64513.7, 5.474], [64537.9, 0.0], [64538.0, 4.359], [64547.9, 2.699], [64582.2, 0.17], [64642.3, 0.372], [64643.2, 0.132], [64648.5, 0.001], [64650.3, 0.001], [64650.7, 0.144], [64653.7, 0.06], [64653.9, 16.826]], "asks": [[64656.3, 0.003], [64656.5, 0.087], [64661.4, 0.314], [64684.2, 0.392], [64684.7, 0.571], [64684.8, 0.105], [64685.1, 0.014], [64717.0, 0.089], [64717.2, 0.844], [64724.5, 0.074], [64761.6, 3.618], [64787.3, 1.549], [64788.7, 4.33], [64793.5, 4.56], [64810.5, 10.415], [64844.3, 0.0], [64844.4, 2.501], [64849.3, 2.014], [64977.3, 4.667], [65300.5, 2.194], [65654.0, 0.03], [67886.7, 0.075]]}
{"kind": "depth", "E": 1787082391077, "U": 11315508568549, "u": 11315508575473, "recv_ms": 1787082391049, "bids": [[14153.9, 3.248], [14253.9, 0.952], [58188.5, 0.002], [61421.2, 0.004], [62067.7, 1.428], [63360.9, 0.023], [63651.5, 0.019], [63651.8, 21.33], [63653.9, 0.024], [63703.5, 5.014], [64007.4, 6.311], [64625.3, 2.152], [64625.4, 0.002], [64633.4, 2.301], [64633.5, 2.341], [64641.5, 0.095], [64641.6, 0.133], [64642.3, 0.372], [64648.8, 0.005], [64650.3, 0.155], [64650.7, 0.137], [64652.1, 0.084], [64652.3, 0.02], [64653.9, 16.91]], "asks": [[64654.0, 7.28], [64656.3, 0.003], [64656.5, 0.003], [64667.9, 0.006], [64674.4, 0.884], [64675.3, 0.003], [64681.0, 0.042], [64706.5, 2.449], [64706.6, 0.0], [64714.6, 2.389], [64714.7, 0.0], [64717.0, 0.028], [64717.2, 0.905], [64779.6, 2.177], [64779.8, 0.0], [64977.3, 4.821], [65300.5, 2.194], [65429.8, 28.369], [65654.0, 0.01], [65656.5, 0.066]]}
{"kind": "depth", "E": 1787082391179, "U": 11315508575524, "u": 11315508580913, "recv_ms": 1787082391156, "bids": [[1000.0, 35.81], [14153.9, 3.612], [14253.9, 0.588], [58188.5, 0.002], [61421.3, 0.008], [62067.7, 1.431], [63651.4, 0.029], [63835.0, 8.947], [64007.4, 6.311], [64513.7, 0.412], [64564.0, 0.003], [64568.8, 0.001], [64571.2, 3.629], [64575.4, 0.005], [64582.8, 0.004], [64591.3, 1.327], [64600.7, 0.398], [64611.9, 0.034], [64614.4, 0.114], [64650.3, 0.154], [64650.7, 0.144], [64651.4, 0.003], [64651.9, 0.026], [64652.2, 0.004], [64653.9, 16.91]], "asks": [[64661.3, 0.035], [64666.0, 0.003], [64674.4, 0.904], [64681.0, 0.022], [64683.5, 0.446], [64689.0, 1.385], [64793.5, 0.0], [65300.5, 2.194], [65591.5, 27.102]]}
{"kind": "depth", "E": 1787082391281, "U": 11315508581064, "u": 11315508596684, "recv_ms": 1787082391254, "bids": [[14153.9, 3.766], [14253.9, 0.336], [14553.9, 0.098], [51723.0, 0.0], [58188.5, 0.002], [61421.2, 0.004], [62067.7, 1.428], [63554.8, 7.573], [63653.9, 0.044], [63684.1, 7.68], [63699.0, 2.617], [64007.4, 6.317], [64330.6, 5.199], [64415.9, 0.523], [64496.8, 9.68], [64498.2, 0.742], [64513.7, 5.473], [64563.6, 0.082], [64563.7, 0.065], [64571.5, 1.274], [64574.7, 0.142], [64575.9, 0.013], [64576.7, 0.073], [64577.6, 3.344], [64577.7, 1.2], [64577.9, 0.361], [64579.2, 0.015], [64585.3, 0.693], [64585.9, 0.424], [64587.3, 0.026], [64588.4, 0.004], [64591.0, 0.033], [64595.3, 0.013], [64598.2, 0.016], [64605.7, 0.001], [64614.3, 2.53], [64615.1, 0.02], [64615.4, 0.003], [64616.5, 1.143], [64616.9, 0.043], [64619.2, 1.203], [64619.9, 0.0], [64622.5, 0.002], [64623.0, 0.019], [64623.6, 2.093], [64625.0, 1.59], [64625.7, 0.025], [64626.2, 0.0], [64627.4, 1.227], [64628.0, 0.72], [64628.1, 0.1], [64628.3, 0.002], [64629.2, 0.113], [64629.4, 0.242], [64629.5, 0.179], [64629.7, 0.063], [64629.9, 0.072], [64630.9, 2.652], [64631.0, 0.497], [64631.5, 0.005], [64632.0, 1.686], [64632.2, 0.504], [64632.3, 0.023], [64632.5, 0.01], [64632.7, 0.022], [64633.9, 0.001], [64634.0, 0.675], [64634.1, 0.0], [64634.6, 0.001], [64635.0, 3.639], [64635.1, 1.001], [64635.8, 0.06], [64636.2, 0.017], [64636.7, 1.867], [64636.8, 0.233], [64637.1, 0.0], [64637.5, 0.013], [64637.9, 0.001], [64638.2, 0.129], [64638.3, 0.169], [64639.0, 1.009], [64639.4, 0.338], [64640.2, 0.051], [64640.9, 0.033], [64641.1, 0.042], [64641.8, 0.232], [64642.0, 0.143], [64643.4, 0.066], [64644.4, 0.31], [64644.6, 0.009], [64645.1, 0.228], [64645.5, 0.171], [64645.9, 2.36], [64646.1, 0.541], [64646.7, 0.606], [64646.8, 0.077], [64647.0, 0.003], [64647.1, 0.018], [64647.5, 0.0], [64647.8, 0.001], [64648.1, 0.005], [64648.6, 0.06], [64649.3, 0.533], [64649.4, 2.602], [64649.5, 3.472], [64649.7, 1.087], [64649.9, 2.55], [64650.0, 2.007], [64650.1, 0.722], [64650.3, 0.182], [64650.5, 0.002], [64650.7, 0.49], [64651.7, 0.0], [64651.9, 1.002], [64652.1, 0.084], [64652.2, 0.003], [64652.6, 0.024], [64652.9, 0.023], [64653.2, 0.088], [64653.5, 0.061], [64653.7, 0.061], [64653.9, 28.524]], "asks": [[64654.0, 4.606], [64654.3, 0.0], [64655.0, 0.002], [64655.1, 0.001], [64655.3, 0.0], [64655.5, 0.015], [64655.9, 0.0], [64656.0, 0.013], [64656.1, 0.001], [64656.2, 0.006], [64656.3, 0.003], [64656.6, 0.01], [64657.0, 0.004], [64657.3, 0.005], [64657.4, 0.01], [64657.5, 0.002], [64657.8, 0.544], [64657.9, 0.253], [64658.4, 0.001], [64658.6, 0.067], [64658.7, 0.021], [64658.8, 0.002], [64659.1, 0.0], [64659.2, 0.541], [64659.3, 0.003], [64659.4, 0.004], [64659.5, 0.001], [64659.9, 0.004], [64660.0, 0.002], [64660.3, 0.122], [64660.4, 0.102], [64660.6, 0.415], [64660.7, 0.005], [64660.8, 0.005], [64661.0, 0.007], [64661.1, 0.341], [64661.2, 0.669], [64661.4, 0.004], [64661.5, 0.012], [64661.8, 0.0], [64661.9, 0.513], [64662.0, 1.026], [64662.1, 0.399], [64662.2, 0.021], [64662.3, 0.355], [64662.4, 1.594], [64662.5, 0.017], [64662.8, 0.21], [64663.0, 1.655], [64663.1, 1.051], [64663.2, 0.394], [64663.6, 0.233], [64663.9, 0.002], [64664.0, 1.295], [64664.2, 0.105], [64664.3, 1.313], [64664.7, 0.089], [64665.0, 0.047], [64665.1, 0.003], [64665.3, 0.431], [64665.4, 0.084], [64665.6, 0.023], [64665.8, 0.158], [64666.8, 0.001], [64667.0, 1.135], [64668.0, 0.135], [64668.3, 0.188], [64668.4, 0.016], [64668.8, 0.636], [64669.2, 1.7], [64669.6, 0.002], [64669.8, 0.132], [64670.3, 0.089], [64671.3, 0.0], [64671.4, 0.165], [64671.5, 3.075], [64672.0, 0.011], [64672.7, 0.001], [64673.3, 0.002], [64673.4, 0.768], [64673.5, 1.55], [64673.7, 0.003], [64673.8, 0.01], [64673.9, 0.0], [64674.4, 0.027], [64674.8, 0.06], [64675.0, 3.504], [64675.2, 0.015], [64675.5, 0.001], [64675.7, 0.001], [64676.1, 0.099], [64676.2, 0.008], [64676.7, 0.892], [64677.1, 0.061], [64677.2, 0.011], [64677.8, 0.483], [64677.9, 0.004], [64678.0, 0.016], [64678.8, 0.004], [64679.2, 1.029], [64679.7, 0.0], [64681.5, 0.021], [64682.0, 0.173], [64682.2, 0.215], [64682.7, 0.067], [64682.9, 0.07], [64683.0, 0.022], [64683.1, 0.001], [64683.2, 1.021], [64685.4, 0.031], [64685.8, 0.013], [64686.5, 0.036], [64687.0, 0.011], [64687.1, 0.192], [64687.3, 0.678], [64687.6, 3.89], [64688.0, 0.034], [64688.4, 0.147], [64688.5, 0.001], [64689.5, 6.055], [64689.6, 1.03], [64689.8, 0.214], [64691.0, 0.066], [64691.9, 0.0], [64692.4, 0.009], [64692.5, 0.006], [64692.8, 1.032], [64693.0, 0.028], [64693.3, 0.016], [64693.6, 0.348], [64694.9, 0.001], [64697.0, 0.065], [64698.0, 0.47], [64698.3, 0.002], [64698.5, 0.289], [64699.3, 0.812], [64705.0, 0.025], [64705.8, 0.066], [64712.9, 0.164], [64721.2, 0.39], [64723.2, 0.229], [64727.2, 0.0], [64729.2, 0.03], [64767.0, 0.143], [64793.5, 4.839], [64810.4, 0.805], [64810.5, 7.14], [64849.3, 5.742], [65300.5, 2.204], [65300.6, 0.081], [65654.0, 0.03], [65656.4, 0.027], [65752.2, 0.0], [67886.7, 0.07]]}
{"kind": "depth", "E": 1787082391383, "U": 11315508596730, "u": 11315508626092, "recv_ms": 1787082391419, "bids": [[14153.9, 3.654], [14253.9, 0.21], [14553.9, 0.336], [51723.0, 0.0], [51723.1, 0.0], [58188.5, 0.002], [61421.2, 0.004], [62067.7, 1.431], [63653.9, 0.024], [64007.4, 6.317], [64287.4, 0.007], [64287.5, 2.449], [64305.6, 0.005], [64319.9, 2.833], [64384.0, 0.105], [64387.2, 1.695], [64454.9, 0.027], [64457.6, 2.082], [64464.8, 0.089], [64563.7, 0.06], [64571.1, 0.498], [64571.5, 1.704], [64572.3, 0.0], [64572.7, 2.519], [64574.3, 0.476], [64574.5, 43.831], [64574.7, 0.572], [64575.9, 0.109], [64576.4, 0.03], [64576.8, 0.26], [64577.9, 0.33], [64578.8, 0.005], [64579.2, 0.092], [64584.3, 1.972], [64584.4, 0.002], [64587.3, 0.0], [64589.4, 0.0], [64596.6, 0.027], [64598.2, 0.001], [64599.3, 0.001], [64599.8, 1.137], [64600.9, 5.049], [64602.2, 2.288], [64605.8, 0.028], [64606.3, 1.966], [64609.7, 0.075], [64611.3, 1.048], [64614.4, 0.112], [64615.7, 0.008], [64616.8, 0.13], [64616.9, 0.018], [64617.0, 0.009], [64617.6, 0.026], [64620.9, 0.015], [64621.3, 0.002], [64621.7, 0.047], [64622.3, 0.057], [64622.6, 0.062], [64623.1, 0.125], [64624.8, 0.012], [64625.5, 1.3], [64626.8, 0.362], [64627.6, 0.004], [64628.1, 0.03], [64628.4, 0.001], [64629.2, 0.095], [64629.4, 0.228], [64629.6, 0.311], [64629.7, 0.003], [64630.0, 3.113], [64630.9, 2.674], [64631.4, 0.532], [64631.8, 1.254], [64632.0, 1.68], [64632.3, 0.01], [64632.7, 0.004], [64633.2, 5.119], [64633.5, 2.328], [64633.6, 1.943], [64634.0, 0.575], [64634.8, 0.312], [64635.0, 3.793], [64635.2, 0.693], [64635.4, 0.153], [64635.8, 0.06], [64636.1, 2.338], [64636.8, 0.193], [64636.9, 0.081], [64637.0, 0.043], [64637.3, 0.001], [64637.4, 0.232], [64638.1, 0.003], [64638.2, 0.127], [64638.6, 0.004], [64639.4, 0.352], [64639.7, 1.406], [64641.1, 0.043], [64641.6, 0.017], [64641.8, 0.18], [64642.1, 0.164], [64642.3, 0.024], [64643.1, 1.962], [64643.3, 3.018], [64643.4, 0.004], [64644.4, 0.313], [64644.6, 0.039], [64644.8, 0.244], [64645.0, 0.22], [64645.1, 0.227], [64646.1, 0.541], [64646.2, 0.197], [64646.3, 0.0], [64646.4, 0.347], [64646.7, 0.003], [64646.8, 0.0], [64647.1, 0.017], [64647.6, 0.0], [64648.4, 0.333], [64649.1, 0.001], [64649.2, 0.002], [64649.4, 2.601], [64649.5, 2.475], [64649.6, 2.787], [64649.7, 3.406], [64649.9, 2.504], [64650.0, 1.173], [64650.2, 0.403], [64650.3, 0.191], [64650.6, 0.475], [64650.7, 0.336], [64650.9, 0.001], [64651.2, 0.002], [64651.3, 0.1], [64651.6, 0.001], [64651.8, 0.595], [64651.9, 2.364], [64652.0, 0.012], [64652.3, 0.001], [64652.6, 0.001], [64652.9, 0.003], [64653.5, 0.002], [64653.9, 31.62]], "asks": [[64654.0, 3.018], [64654.1, 0.051], [64654.2, 0.0], [64654.3, 0.002], [64654.7, 0.002], [64655.2, 1.85], [64655.3, 0.001], [64656.6, 0.008], [64656.7, 0.003], [64656.9, 0.1], [64657.4, 0.001], [64657.6, 0.102], [64657.7, 0.366], [64657.8, 0.003], [64657.9, 0.255], [64658.1, 0.284], [64658.7, 0.021], [64659.0, 0.077], [64659.2, 0.949], [64659.6, 0.575], [64659.8, 0.009], [64660.0, 0.002], [64660.2, 0.001], [64660.3, 0.138], [64660.4, 1.813], [64660.5, 0.0], [64660.6, 0.039], [64660.7, 0.003], [64660.8, 0.003], [64660.9, 0.009], [64661.1, 0.241], [64661.2, 0.359], [64661.7, 0.548], [64661.8, 1.819], [64662.0, 1.025], [64662.1, 0.005], [64662.2, 0.105], [64662.3, 0.045], [64662.4, 1.594], [64662.5, 0.019], [64662.7, 0.003], [64662.8, 0.126], [64662.9, 0.086], [64663.0, 1.586], [64663.1, 0.433], [64663.2, 0.31], [64663.3, 2.647], [64663.4, 0.396], [64663.5, 0.101], [64663.9, 0.086], [64664.0, 0.986], [64664.3, 1.313], [64664.6, 0.159], [64664.7, 0.005], [64664.8, 0.0], [64664.9, 0.005], [64665.0, 0.128], [64665.3, 0.372], [64665.4, 0.084], [64665.8, 0.118], [64665.9, 3.515], [64666.1, 0.485], [64666.3, 0.814], [64666.4, 0.004], [64666.5, 1.157], [64666.8, 0.0], [64666.9, 0.088], [64667.0, 1.138], [64667.2, 0.005], [64667.6, 0.001], [64667.8, 0.0], [64668.0, 0.139], [64668.3, 0.104], [64669.0, 0.009], [64669.1, 0.158], [64669.2, 1.225], [64669.6, 0.002], [64669.8, 0.008], [64670.0, 0.907], [64670.1, 0.584], [64670.2, 0.003], [64670.3, 0.089], [64670.5, 0.03], [64670.6, 0.0], [64670.8, 0.086], [64670.9, 0.464], [64671.0, 1.148], [64671.4, 0.048], [64671.5, 2.141], [64671.9, 0.003], [64672.1, 0.926], [64673.2, 0.041], [64673.4, 0.761], [64673.5, 1.624], [64673.6, 2.478], [64673.7, 0.004], [64673.8, 0.01], [64673.9, 0.154], [64674.4, 0.007], [64674.5, 0.693], [64674.6, 0.225], [64674.9, 1.261], [64675.3, 0.06], [64675.8, 0.877], [64675.9, 0.919], [64676.2, 0.002], [64676.5, 0.074], [64676.6, 0.03], [64676.7, 0.163], [64676.9, 0.321], [64677.0, 0.069], [64677.1, 0.059], [64677.3, 0.187], [64677.5, 0.049], [64677.8, 0.478], [64678.0, 0.544], [64678.1, 0.002], [64678.4, 0.226], [64678.6, 0.002], [64678.8, 0.019], [64679.0, 0.0], [64679.3, 0.312], [64679.8, 1.651], [64680.0, 1.536], [64680.7, 0.154], [64681.3, 2.345], [64681.4, 0.039], [64683.5, 0.444], [64683.6, 0.311], [64683.8, 0.0], [64684.2, 0.398], [64684.3, 0.098], [64684.8, 0.125], [64685.4, 0.006], [64685.9, 1.414], [64686.4, 1.037], [64686.5, 0.023], [64687.2, 2.473], [64687.3, 1.142], [64689.8, 0.263], [64690.1, 0.006], [64691.0, 0.071], [64691.1, 0.128], [64692.5, 0.0], [64692.7, 0.042], [64692.8, 1.019], [64694.1, 0.015], [64695.4, 3.622], [64695.7, 0.698], [64696.2, 2.03], [64696.8, 14.252], [64696.9, 2.632], [64697.0, 0.016], [64697.5, 0.332], [64698.0, 0.456], [64698.1, 0.025], [64698.6, 0.065], [64699.3, 0.794], [64702.2, 0.744], [64702.6, 0.016], [64702.9, 0.163], [64704.0, 0.156], [64705.8, 0.006], [64710.7, 1.107], [64710.9, 0.412], [64712.9, 0.161], [64713.3, 0.003], [64719.5, 0.21], [64723.4, 1.072], [64723.9, 0.0], [64726.1, 39.345], [64726.7, 1.666], [64728.3, 0.002], [64729.2, 0.004], [64730.4, 0.029], [64742.8, 0.045], [64744.1, 0.026], [64753.2, 0.629], [64765.8, 0.001], [64810.5, 10.415], [64849.3, 2.045], [64852.4, 0.655], [64852.5, 0.0], [64923.1, 0.777], [64923.8, 0.001], [64992.9, 0.003], [64993.4, 0.0], [65021.1, 0.022], [65021.2, 0.055], [65263.5, 0.002], [65300.5, 2.2], [65654.0, 0.01], [65817.8, 8.869], [65947.0, 0.157]]}
{"kind": "depth", "E": 1787082391485, "U": 11315508626261, "u": 11315508672544, "recv_ms": 1787082391647, "bids": [[1000.0, 35.81], [14153.9, 3.472], [14155.1, 0.056], [14253.9, 0.098], [14553.9, 0.448], [14554.0, 0.014], [14554.6, 0.014], [14555.1, 0.098], [58188.5, 0.0], [58188.7, 0.005], [58189.5, 0.002], [58189.6, 0.003], [58304.9, 0.013], [61422.3, 0.0], [63360.9, 0.023], [63362.0, 0.105], [63645.8, 0.001], [63646.5, 0.002], [63652.0, 0.038], [63652.7, 0.011], [63653.0, 0.839], [63654.9, 0.003], [63655.1, 0.014], [63693.1, 0.023], [63740.8, 10.375], [64007.4, 6.311], [64008.1, 0.0], [64008.4, 0.0], [64008.5, 0.014], [64061.8, 0.005], [64319.4, 0.585], [64372.2, 0.077], [64395.3, 0.0], [64451.4, 0.088], [64454.8, 0.22], [64464.4, 2.404], [64468.1, 0.0], [64492.1, 0.0], [64543.7, 42.199], [64543.8, 8.449], [64555.2, 1.188], [64562.5, 1.992], [64563.5, 0.0], [64564.4, 0.505], [64571.0, 0.54], [64571.5, 1.543], [64572.4, 0.001], [64574.5, 1.632], [64575.7, 0.122], [64575.9, 0.301], [64576.3, 0.01], [64576.7, 0.078], [64576.8, 0.255], [64576.9, 0.013], [64577.8, 0.18], [64578.8, 0.004], [64580.3, 0.503], [64582.3, 0.001], [64583.3, 0.017], [64584.1, 0.103], [64588.4, 0.001], [64588.5, 0.021], [64590.9, 0.044], [64594.1, 0.378], [64594.7, 0.033], [64595.1, 0.629], [64595.7, 0.013], [64595.8, 0.04], [64596.9, 0.025], [64597.0, 0.017], [64599.3, 0.001], [64599.6, 0.353], [64599.8, 1.122], [64601.4, 0.027], [64602.0, 0.226], [64602.1, 0.004], [64602.2, 2.262], [64602.3, 0.031], [64602.9, 0.001], [64603.2, 1.688], [64603.4, 0.006], [64603.7, 0.083], [64603.9, 0.0], [64604.4, 0.154], [64605.1, 1.494], [64605.2, 0.137], [64606.8, 0.001], [64607.5, 2.326], [64608.3, 0.03], [64608.4, 0.008], [64609.0, 0.202], [64611.2, 0.01], [64612.9, 0.004], [64613.2, 1.652], [64616.8, 0.105], [64618.4, 0.0], [64620.8, 0.008], [64621.4, 0.027], [64622.3, 0.0], [64623.2, 0.001], [64623.8, 0.144], [64624.1, 0.207], [64625.2, 2.204], [64625.3, 0.006], [64626.8, 0.353], [64627.2, 1.968], [64627.5, 0.001], [64628.0, 0.729], [64628.9, 0.006], [64629.0, 1.024], [64629.4, 0.213], [64629.9, 0.022], [64630.0, 3.113], [64630.1, 1.426], [64630.2, 0.753], [64630.6, 0.002], [64630.7, 0.034], [64630.8, 0.235], [64630.9, 2.652], [64631.0, 0.496], [64631.2, 0.0], [64631.3, 0.007], [64631.4, 0.526], [64631.5, 0.005], [64631.7, 0.023], [64631.8, 1.246], [64632.8, 0.345], [64633.2, 5.083], [64633.3, 2.155], [64633.4, 0.155], [64633.5, 2.321], [64633.8, 0.057], [64634.0, 0.002], [64634.1, 0.014], [64634.3, 0.001], [64634.4, 0.001], [64634.6, 0.0], [64634.8, 0.311], [64635.1, 0.001], [64635.2, 0.692], [64635.4, 0.16], [64635.5, 0.001], [64635.9, 0.139], [64636.6, 0.573], [64636.7, 1.867], [64636.9, 0.003], [64637.1, 0.019], [64637.4, 0.262], [64637.9, 1.001], [64638.6, 0.002], [64639.1, 0.248], [64639.3, 0.002], [64639.4, 0.002], [64639.6, 0.005], [64639.7, 0.48], [64640.0, 1.905], [64640.1, 0.31], [64640.2, 0.04], [64640.3, 1.267], [64640.5, 0.135], [64641.0, 0.919], [64641.1, 0.045], [64641.2, 0.006], [64641.3, 0.0], [64641.4, 0.101], [64641.5, 0.133], [64641.6, 0.067], [64641.7, 0.948], [64642.0, 0.143], [64642.2, 0.005], [64642.3, 0.025], [64642.4, 0.002], [64642.5, 0.005], [64642.9, 0.14], [64643.0, 2.389], [64643.2, 0.132], [64643.3, 2.966], [64643.4, 0.467], [64643.5, 0.002], [64643.6, 0.04], [64643.9, 0.002], [64644.1, 0.469], [64644.2, 0.008], [64644.5, 0.0], [64644.6, 0.032], [64644.7, 0.431], [64644.8, 0.592], [64645.0, 0.215], [64645.3, 0.17], [64645.5, 0.251], [64645.6, 0.072], [64646.0, 2.775], [64646.1, 0.0], [64646.3, 0.001], [64646.4, 0.331], [64646.5, 0.017], [64646.6, 0.369], [64646.7, 0.0], [64647.3, 0.381], [64647.4, 0.07], [64648.1, 0.011], [64648.7, 0.019], [64649.3, 0.448], [64649.4, 2.603], [64649.5, 1.475], [64649.6, 1.007], [64649.7, 3.382], [64649.8, 1.023], [64650.0, 0.702], [64650.1, 0.714], [64650.2, 0.31], [64650.3, 0.156], [64650.6, 0.376], [64650.7, 1.823], [64651.0, 0.015], [64651.2, 0.003], [64651.3, 0.0], [64651.4, 0.002], [64651.5, 0.085], [64651.7, 0.232], [64651.8, 0.159], [64651.9, 1.0], [64652.1, 0.085], [64652.2, 0.007], [64652.4, 0.312], [64652.5, 0.134], [64652.6, 0.002], [64652.7, 0.016], [64652.8, 0.145], [64653.0, 0.439], [64653.2, 0.085], [64653.6, 0.003], [64653.8, 0.913], [64653.9, 6.852], [64654.0, 4.063], [64654.1, 0.01], [64654.2, 0.42], [64654.3, 0.0], [64654.5, 0.001], [64654.6, 0.135], [64654.7, 0.001], [64654.8, 0.013], [64654.9, 1.486], [64655.0, 0.027], [64655.1, 53.505]], "asks": [[64654.0, 0.0], [64654.1, 0.0], [64654.3, 0.0], [64654.4, 0.0], [64654.7, 0.0], [64654.8, 0.0], [64654.9, 0.0], [64655.0, 0.0], [64655.1, 0.0], [64655.2, 1.27], [64655.3, 0.002], [64655.4, 0.011], [64655.8, 0.0], [64656.0, 0.012], [64656.3, 0.003], [64656.6, 0.007], [64656.7, 0.002], [64656.8, 0.002], [64656.9, 0.0], [64657.2, 0.028], [64657.3, 0.003], [64657.5, 0.002], [64657.6, 0.002], [64657.7, 0.243], [64657.9, 0.253], [64658.0, 0.634], [64658.1, 0.004], [64658.4, 0.005], [64658.6, 0.064], [64658.7, 0.001], [64658.9, 0.126], [64659.1, 0.0], [64659.2, 0.522], [64659.3, 0.003], [64659.6, 0.005], [64659.8, 0.006], [64659.9, 0.006], [64660.0, 2.068], [64660.2, 0.001], [64660.3, 0.121], [64660.4, 0.004], [64660.5, 2.319], [64660.6, 1.04], [64660.7, 0.002], [64660.8, 0.002], [64660.9, 0.002], [64661.0, 0.003], [64661.5, 0.013], [64661.6, 2.13], [64661.7, 0.0], [64661.8, 0.013], [64662.0, 0.011], [64662.1, 0.005], [64662.2, 0.294], [64662.3, 1.81], [64662.4, 1.579], [64662.5, 0.017], [64662.6, 0.13], [64662.7, 0.004], [64662.8, 0.115], [64662.9, 0.003], [64663.0, 0.376], [64663.2, 0.41], [64663.4, 0.397], [64663.6, 0.233], [64663.7, 0.264], [64663.8, 0.376], [64663.9, 0.104], [64664.0, 0.085], [64664.1, 0.099], [64664.3, 1.395], [64664.4, 0.251], [64664.6, 0.075], [64664.7, 0.089], [64665.0, 0.044], [64665.2, 0.162], [64665.3, 0.003], [64665.4, 0.084], [64665.6, 0.023], [64665.7, 0.085], [64665.8, 0.652], [64666.1, 0.085], [64666.3, 0.504], [64666.4, 0.312], [64666.5, 0.418], [64666.6, 0.0], [64666.7, 0.002], [64666.9, 0.004], [64667.0, 1.052], [64667.2, 0.005], [64667.6, 0.001], [64667.7, 0.001], [64668.0, 0.223], [64668.1, 0.001], [64668.2, 0.004], [64668.3, 0.0], [64668.5, 0.002], [64668.7, 0.084], [64668.8, 0.009], [64668.9, 0.212], [64669.1, 0.467], [64669.2, 1.225], [64669.3, 0.003], [64669.4, 0.003], [64669.7, 0.419], [64669.8, 0.011], [64669.9, 0.002], [64670.0, 0.025], [64670.1, 0.444], [64670.2, 0.147], [64670.5, 0.088], [64670.6, 0.003], [64670.8, 0.001], [64671.4, 0.071], [64671.5, 1.978], [64671.6, 2.322], [64671.7, 0.44], [64671.8, 0.117], [64671.9, 0.002], [64672.0, 0.012], [64672.1, 0.0], [64672.2, 0.597], [64672.3, 0.019], [64672.5, 0.134], [64672.6, 0.483], [64672.8, 0.37], [64673.2, 0.001], [64673.3, 0.001], [64673.5, 1.47], [64673.6, 2.97], [64673.8, 0.003], [64673.9, 0.0], [64674.0, 0.135], [64674.4, 0.047], [64674.5, 0.606], [64674.7, 0.001], [64674.8, 0.06], [64674.9, 1.253], [64675.0, 2.963], [64675.2, 0.939], [64675.3, 0.003], [64675.7, 0.008], [64675.8, 0.842], [64675.9, 0.795], [64676.0, 0.162], [64676.7, 0.246], [64676.8, 1.34], [64677.0, 0.02], [64677.1, 0.059], [64677.3, 0.071], [64677.9, 0.034], [64678.0, 0.125], [64678.1, 0.559], [64678.2, 2.378], [64678.4, 0.226], [64678.6, 0.002], [64678.7, 0.693], [64678.8, 0.005], [64678.9, 0.01], [64679.0, 0.008], [64679.1, 2.289], [64679.5, 0.003], [64679.7, 0.541], [64679.9, 1.716], [64680.1, 0.504], [64680.2, 0.404], [64680.3, 0.294], [64680.4, 0.396], [64680.5, 0.003], [64681.2, 0.045], [64681.3, 2.336], [64681.5, 0.023], [64681.6, 1.922], [64682.0, 0.173], [64682.4, 4.613], [64682.5, 0.164], [64682.7, 0.017], [64683.2, 1.145], [64684.7, 0.418], [64684.8, 0.105], [64685.5, 0.001], [64685.6, 0.007], [64685.7, 0.034], [64686.4, 1.038], [64687.1, 0.102], [64688.0, 0.051], [64688.1, 0.121], [64690.5, 0.07], [64690.8, 0.041], [64690.9, 0.007], [64691.0, 0.066], [64691.1, 0.113], [64691.2, 0.497], [64691.3, 1.494], [64691.7, 0.001], [64692.0, 0.005], [64692.5, 0.0], [64694.7, 0.526], [64695.2, 0.118], [64695.4, 3.502], [64695.5, 0.001], [64695.7, 0.723], [64696.2, 2.024], [64696.8, 4.254], [64696.9, 2.631], [64697.3, 0.101], [64697.5, 0.335], [64697.6, 0.135], [64698.1, 0.0], [64698.4, 0.002], [64698.6, 0.005], [64699.4, 0.005], [64700.4, 0.0], [64700.8, 0.059], [64701.4, 0.02], [64701.5, 10.0], [64702.1, 0.029], [64702.4, 3.331], [64702.5, 4.986], [64702.6, 0.0], [64702.7, 0.111], [64703.0, 0.343], [64703.1, 0.023], [64703.8, 0.041], [64704.0, 0.136], [64704.7, 0.001], [64704.9, 0.442], [64705.0, 0.0], [64705.5, 0.003], [64705.7, 10.531], [64705.8, 0.066], [64705.9, 0.169], [64706.4, 2.068], [64706.5, 0.382], [64710.7, 1.082], [64711.1, 0.221], [64712.3, 0.042], [64713.0, 0.029], [64713.3, 0.0], [64714.0, 0.071], [64714.5, 2.586], [64714.6, 0.244], [64717.6, 2.057], [64718.1, 6.103], [64719.1, 0.016], [64719.3, 0.002], [64719.5, 0.0], [64726.1, 0.0], [64729.1, 0.513], [64730.0, 0.758], [64730.5, 0.008], [64730.8, 0.001], [64731.0, 0.59], [64733.5, 0.503], [64734.0, 0.004], [64734.9, 39.372], [64735.6, 0.001], [64737.2, 0.028], [64743.4, 2.364], [64744.1, 0.0], [64745.4, 1.009], [64750.4, 12.935], [64751.1, 0.064], [64766.0, 0.044], [64766.9, 0.115], [64768.4, 0.021], [64769.1, 0.019], [64770.4, 0.003], [64771.0, 3.567], [64771.3, 0.0], [64773.6, 0.154], [64774.8, 0.565], [64775.2, 2.949], [64775.6, 0.002], [64777.8, 0.0], [64779.5, 2.235], [64779.6, 0.036], [64790.5, 0.266], [64790.7, 0.003], [64790.8, 0.619], [64805.9, 0.0], [64810.5, 0.0], [64811.7, 7.286], [64819.5, 0.307], [64831.4, 0.258], [64831.8, 0.566], [64848.0, 0.377], [64849.2, 0.334], [64849.3, 0.0], [64850.5, 5.436], [64994.4, 0.116], [65300.5, 3.173], [65301.8, 0.006], [65398.1, 0.0], [65398.2, 0.0], [65398.9, 1.531], [65399.2, 13.62], [65462.7, 0.0], [65462.8, 0.763], [65463.8, 7.56], [65591.5, 28.168], [67241.1, 0.013]]}
{"kind": "depth", "E": 1787082391587, "U": 11315508672609, "u": 11315508700992, "recv_ms": 1787082391711, "bids": [[14153.9, 3.234], [14155.1, 0.14], [14253.9, 0.0], [14555.1, 0.35], [58189.5, 0.002], [61422.3, 0.0], [62067.7, 1.428], [63362.0, 0.117], [63655.1, 0.036], [63703.5, 5.563], [64008.5, 0.002], [64024.1, 0.003], [64171.7, 0.005], [64330.6, 5.209], [64468.3, 0.0], [64543.7, 0.0], [64543.8, 2.466], [64566.7, 0.06], [64570.1, 0.006], [64572.3, 42.199], [64572.6, 0.015], [64574.4, 1.424], [64575.5, 0.046], [64576.3, 0.007], [64585.7, 0.011], [64589.6, 0.31], [64592.6, 0.025], [64595.7, 0.01], [64596.2, 0.211], [64602.8, 0.0], [64611.2, 0.007], [64612.5, 3.109], [64613.0, 0.118], [64613.1, 0.234], [64613.5, 0.931], [64614.3, 2.32], [64614.7, 0.063], [64622.3, 0.002], [64622.4, 1.196], [64622.5, 0.004], [64622.8, 1.369], [64623.4, 0.159], [64624.1, 0.656], [64624.2, 0.072], [64624.3, 0.201], [64625.2, 2.147], [64625.4, 0.059], [64625.7, 0.027], [64625.8, 0.008], [64625.9, 0.003], [64626.8, 1.823], [64626.9, 0.107], [64627.3, 0.003], [64628.4, 0.07], [64630.4, 1.269], [64630.8, 0.234], [64631.4, 0.528], [64632.6, 0.006], [64634.0, 0.051], [64634.2, 0.116], [64634.4, 0.45], [64634.5, 0.007], [64634.9, 0.584], [64635.4, 0.09], [64635.8, 0.061], [64635.9, 0.023], [64636.1, 2.361], [64636.6, 0.48], [64637.3, 0.337], [64638.0, 0.368], [64638.8, 0.0], [64639.1, 0.365], [64639.2, 0.022], [64639.5, 0.003], [64639.7, 0.48], [64640.7, 1.632], [64641.0, 0.917], [64641.2, 0.008], [64641.5, 0.133], [64641.6, 0.018], [64641.7, 0.022], [64641.8, 1.106], [64642.2, 0.005], [64642.7, 0.435], [64643.4, 0.475], [64644.0, 0.513], [64644.1, 0.469], [64644.2, 0.0], [64645.9, 2.361], [64646.1, 0.64], [64646.2, 0.205], [64646.5, 0.015], [64646.6, 0.033], [64647.3, 0.374], [64649.3, 0.448], [64649.6, 1.007], [64649.8, 1.564], [64649.9, 2.504], [64650.0, 0.177], [64650.1, 0.713], [64650.2, 0.542], [64650.6, 0.375], [64651.7, 0.0], [64651.8, 0.159], [64652.1, 0.085], [64652.2, 0.003], [64652.5, 0.001], [64652.8, 0.086], [64653.1, 0.001], [64653.7, 0.06], [64653.8, 0.912], [64653.9, 6.769], [64654.0, 3.522], [64654.1, 0.002], [64654.6, 0.176], [64654.8, 0.012], [64655.0, 0.005], [64655.1, 51.432]], "asks": [[64655.2, 0.471], [64655.3, 0.002], [64655.5, 0.014], [64655.8, 0.281], [64656.1, 0.0], [64656.8, 0.002], [64657.6, 0.012], [64657.7, 0.77], [64657.8, 0.127], [64657.9, 2.572], [64658.4, 1.77], [64658.9, 0.002], [64659.1, 0.008], [64659.2, 0.835], [64659.4, 0.007], [64659.5, 0.001], [64659.6, 1.005], [64659.9, 0.006], [64660.0, 0.002], [64660.4, 0.004], [64660.6, 0.04], [64661.0, 0.087], [64661.2, 0.359], [64661.4, 0.088], [64661.5, 0.013], [64661.6, 0.064], [64661.7, 0.0], [64661.8, 0.102], [64662.0, 0.552], [64662.1, 0.005], [64662.3, 0.052], [64662.4, 1.58], [64662.5, 0.361], [64662.8, 0.114], [64663.8, 0.395], [64663.9, 0.125], [64664.1, 0.08], [64665.5, 0.025], [64665.6, 0.024], [64665.7, 0.004], [64665.8, 0.034], [64666.0, 0.003], [64666.1, 0.001], [64666.4, 0.002], [64666.5, 0.644], [64666.9, 0.007], [64667.6, 0.125], [64668.0, 0.139], [64668.4, 1.253], [64668.5, 0.63], [64668.7, 0.0], [64669.3, 0.0], [64670.0, 0.925], [64670.3, 0.089], [64670.8, 0.078], [64671.4, 0.033], [64673.1, 1.476], [64674.2, 1.389], [64674.5, 0.607], [64674.6, 0.38], [64674.8, 0.04], [64675.0, 2.995], [64675.2, 0.013], [64676.2, 0.002], [64676.4, 0.001], [64677.0, 0.0], [64677.3, 0.128], [64678.0, 0.125], [64678.1, 0.559], [64678.2, 2.321], [64678.3, 0.039], [64678.6, 0.003], [64678.7, 0.846], [64679.0, 0.549], [64679.7, 0.0], [64680.1, 0.502], [64680.7, 0.158], [64680.8, 0.061], [64681.6, 1.922], [64682.4, 4.578], [64684.0, 0.082], [64685.0, 0.016], [64686.4, 1.036], [64686.6, 0.091], [64688.7, 0.001], [64689.1, 0.174], [64691.2, 0.447], [64693.9, 10.006], [64694.4, 0.031], [64695.1, 1.878], [64695.2, 0.028], [64695.7, 0.724], [64696.1, 0.064], [64696.4, 0.091], [64696.7, 1.241], [64698.8, 0.196], [64699.4, 0.002], [64701.5, 0.0], [64705.7, 0.531], [64705.8, 0.006], [64706.8, 0.277], [64706.9, 0.0], [64708.1, 0.028], [64709.9, 0.001], [64711.2, 0.032], [64713.6, 0.13], [64717.1, 0.449], [64717.2, 0.395], [64718.3, 0.062], [64720.3, 0.023], [64727.6, 0.001], [64730.4, 0.0], [64731.3, 0.076], [64732.7, 0.0], [64732.8, 0.0], [64733.2, 0.022], [64734.0, 0.003], [64734.4, 1.789], [64734.9, 39.372], [64737.8, 1.488], [64737.9, 0.159], [64739.7, 0.025], [64739.9, 0.029], [64740.5, 0.002], [64740.9, 0.029], [64746.9, 0.026], [64747.0, 0.0], [64747.3, 0.049], [64750.6, 0.03], [64757.0, 0.039], [64760.8, 0.028], [64774.8, 0.565], [64803.9, 0.218], [64811.7, 0.022], [64811.8, 7.681], [64821.2, 1.55], [64821.3, 0.248], [64831.4, 0.373], [64835.1, 1.856], [64835.2, 0.001], [64849.2, 0.257], [64850.5, 0.028], [64850.6, 3.873], [65138.2, 0.1], [65288.0, 11.537], [65300.5, 3.572], [65301.8, 0.008], [65462.8, 0.0], [65463.8, 8.316], [65655.2, 0.02], [65948.3, 0.034]]}
{"kind": "depth", "E": 1787082391689, "U": 11315508701022, "u": 11315508718535, "recv_ms": 1787082391754, "bids": [[14153.9, 2.996], [14155.1, 0.014], [14555.1, 0.714], [58189.5, 0.002], [61422.3, 0.0], [62068.8, 0.083], [63362.0, 0.12], [63770.2, 5.841], [64008.5, 0.0], [64062.1, 0.013], [64068.3, 0.468], [64287.8, 43.959], [64330.6, 5.208], [64384.4, 35.332], [64387.2, 6.949], [64444.5, 9.814], [64455.0, 0.031], [64455.3, 28.521], [64457.6, 5.951], [64525.7, 2.711], [64608.5, 0.156], [64609.1, 0.0], [64619.5, 0.444], [64621.6, 0.019], [64621.9, 2.343], [64623.6, 1.939], [64628.0, 0.793], [64632.2, 1.123], [64634.7, 0.003], [64636.3, 1.212], [64637.3, 0.001], [64638.2, 0.463], [64641.5, 0.133], [64644.2, 0.008], [64646.2, 0.197], [64649.5, 2.016], [64649.8, 1.023], [64651.9, 1.0], [64653.1, 0.003], [64653.9, 4.881], [64654.9, 1.487], [64655.0, 0.008], [64655.1, 54.137]], "asks": [[64655.2, 1.168], [64655.8, 0.0], [64655.9, 0.271], [64656.8, 0.002], [64657.6, 0.012], [64657.7, 0.77], [64659.1, 0.0], [64659.2, 0.834], [64659.5, 0.302], [64660.2, 0.003], [64660.4, 0.02], [64660.6, 0.124], [64660.9, 0.004], [64661.8, 0.097], [64662.0, 0.011], [64662.3, 0.045], [64662.4, 1.58], [64662.5, 0.329], [64662.9, 0.551], [64663.5, 0.121], [64665.4, 0.0], [64665.5, 0.005], [64665.6, 0.024], [64665.8, 0.034], [64666.5, 0.343], [64667.0, 1.952], [64667.9, 0.545], [64668.3, 0.0], [64670.0, 0.025], [64671.4, 0.057], [64672.7, 0.293], [64674.1, 0.03], [64674.4, 0.043], [64678.2, 2.325], [64678.7, 0.015], [64681.4, 0.007], [64682.6, 0.062], [64682.7, 0.021], [64683.8, 0.478], [64687.0, 0.011], [64688.5, 0.071], [64689.1, 1.074], [64689.8, 0.214], [64691.6, 0.176], [64693.8, 0.059], [64693.9, 0.004], [64695.1, 0.001], [64695.7, 0.654], [64695.9, 0.159], [64696.7, 1.24], [64696.8, 4.252], [64697.1, 0.003], [64697.6, 10.137], [64698.5, 0.035], [64699.1, 0.236], [64701.0, 0.33], [64704.0, 0.138], [64704.9, 0.441], [64709.6, 0.256], [64711.2, 1.936], [64715.4, 0.125], [64715.6, 0.029], [64730.5, 39.353], [64734.9, 0.027], [64766.9, 0.0], [64767.2, 0.112], [64855.1, 27.733], [64926.4, 33.897], [65021.1, 6.414], [65023.8, 42.848], [65269.3, 0.613], [65300.5, 2.194], [65301.1, 0.046], [65301.8, 0.0], [65302.3, 0.379], [65493.8, 1.364], [65747.8, 0.76], [65948.3, 0.04]]}
{"kind": "depth", "E": 1787082391791, "U": 11315508718550, "u": 11315508730613, "recv_ms": 1787082391778, "bids": [[1000.0, 35.81], [14153.9, 2.646], [14155.1, 0.0], [14555.1, 1.078], [51724.0, 0.004], [58189.5, 0.002], [61422.3, 0.0], [62068.8, 0.08], [63197.2, 0.002], [63362.0, 0.126], [63655.1, 0.016], [63748.7, 13.626], [63932.4, 0.781], [64008.5, 0.0], [64137.9, 0.094], [64385.6, 1.639], [64572.3, 0.0], [64574.5, 43.831], [64595.7, 0.013], [64603.2, 1.689], [64608.3, 0.005], [64609.7, 0.05], [64617.5, 0.029], [64622.3, 0.027], [64624.8, 0.012], [64629.1, 0.001], [64632.2, 0.504], [64644.2, 0.0], [64644.3, 0.004], [64646.2, 0.205], [64649.3, 0.448], [64649.5, 2.016], [64651.6, 0.001], [64653.7, 0.001], [64653.8, 0.911], [64653.9, 1.822], [64654.0, 3.502], [64654.1, 0.001], [64654.7, 0.0], [64654.9, 1.178], [64655.1, 58.375]], "asks": [[64655.2, 1.696], [64655.3, 0.003], [64658.5, 0.006], [64659.1, 0.008], [64660.4, 0.004], [64660.7, 0.002], [64661.7, 0.003], [64661.8, 0.094], [64662.3, 0.085], [64663.3, 2.667], [64663.5, 0.144], [64663.8, 0.376], [64664.1, 0.058], [64665.8, 0.058], [64668.1, 0.001], [64670.0, 0.025], [64670.8, 0.004], [64671.4, 0.11], [64680.1, 0.503], [64699.4, 0.005], [64718.9, 0.221], [64728.4, 39.362], [64730.5, 0.008], [64811.7, 10.437], [64811.8, 0.41], [64850.5, 1.01], [64850.6, 0.003], [64978.5, 0.001], [65290.7, 69.296], [65301.8, 0.0], [65463.3, 0.232], [65655.2, 0.0], [65948.3, 0.043]]}
{"kind": "depth", "E": 1787082391893, "U": 11315508730631, "u": 11315508743199, "recv_ms": 1787082391867, "bids": [[14153.9, 2.296], [14555.1, 1.428], [51724.0, 0.0], [58189.5, 0.002], [61422.3, 0.0], [62068.8, 0.083], [63362.0, 0.129], [63748.7, 15.976], [64008.5, 0.0], [64330.6, 5.198], [64599.6, 0.338], [64601.5, 0.035], [64614.1, 0.052], [64621.9, 2.333], [64622.0, 0.748], [64622.3, 0.002], [64630.1, 1.411], [64630.7, 0.03], [64631.3, 0.001], [64631.5, 0.011], [64632.6, 0.029], [64633.8, 0.042], [64635.8, 0.077], [64637.1, 0.0], [64639.1, 0.385], [64649.6, 1.007], [64651.5, 0.085], [64651.7, 0.0], [64654.3, 0.002], [64655.1, 57.966]], "asks": [[64655.2, 1.744], [64655.9, 0.0], [64657.6, 0.012], [64657.8, 0.127], [64661.7, 0.003], [64662.3, 0.209], [64667.1, 0.381], [64670.3, 0.089], [64678.9, 0.004], [64679.8, 1.657], [64680.2, 0.389], [64680.9, 0.122], [64687.3, 1.142], [64687.4, 0.0], [64687.5, 0.159], [64690.8, 0.026], [64692.8, 1.035], [64697.3, 0.082], [64699.3, 0.817], [64702.4, 3.316], [64703.8, 0.022], [64704.4, 0.098], [64705.7, 0.551], [64715.6, 0.019], [64715.8, 0.025], [64811.7, 0.022], [64811.8, 7.716], [64850.5, 0.028], [64850.6, 4.196], [64977.3, 4.666], [65171.2, 9.372], [65301.8, 0.008], [65948.3, 0.046], [67886.7, 0.065]]}
{"kind": "depth", "E": 1787082391995, "U": 11315508743205, "u": 11315508751559, "recv_ms": 1787082391969, "bids": [[1000.0, 35.81], [14153.9, 1.932], [14555.1, 1.792], [58189.5, 0.002], [61422.3, 0.0], [63362.0, 0.135], [63655.1, 0.036], [64008.5, 0.0], [64035.1, 1.25], [64068.6, 0.418], [64175.5, 54.348], [64331.8, 0.001], [64444.5, 9.598], [64455.4, 0.218], [64533.6, 1.448], [64534.8, 0.156], [64540.7, 0.0], [64541.9, 0.26], [64547.7, 0.006], [64548.9, 0.015], [64554.8, 0.012], [64556.0, 0.06], [64561.8, 0.0], [64563.0, 0.015], [64568.9, 0.003], [64570.1, 0.019], [64575.9, 0.288], [64577.1, 0.014], [64583.0, 0.019], [64584.2, 2.303], [64622.0, 0.738], [64622.2, 0.011], [64637.5, 0.011], [64638.7, 2.339], [64651.6, 0.001], [64653.6, 0.002], [64655.1, 56.823]], "asks": [[64655.2, 1.746], [64656.8, 0.012], [64657.6, 0.012], [64660.2, 0.087], [64661.7, 0.006], [64663.1, 0.476], [64663.5, 0.124], [64663.9, 0.102], [64664.7, 0.005], [64667.2, 0.003], [64670.0, 0.023], [64671.2, 0.005], [64674.6, 0.504], [64715.8, 0.015], [64715.9, 0.032], [64727.7, 0.381], [64730.9, 0.037], [64734.7, 0.002], [64737.9, 0.172], [64741.8, 0.022], [64745.0, 0.055], [64748.8, 0.005], [64752.0, 0.02], [64755.9, 0.006], [64759.1, 0.061], [64763.0, 0.167], [64766.1, 0.013], [64770.0, 0.134], [64771.6, 0.085], [64773.2, 0.173], [64777.1, 0.003], [64780.3, 2.447], [64811.7, 10.437], [64811.8, 0.41], [64850.5, 0.741], [64850.6, 0.003], [65142.4, 53.89], [65301.8, 0.0], [65655.2, 0.02], [65948.3, 0.049]]}
{"kind": "depth", "E": 1787082392097, "U": 11315508751749, "u": 11315508757988, "recv_ms": 1787082392074, "bids": [[1000.0, 35.81], [14153.9, 1.568], [14555.1, 2.156], [58189.5, 0.0], [62068.8, 0.08], [63857.7, 0.001], [64008.5, 0.0], [64039.7, 9.418], [64571.2, 3.628], [64575.4, 0.006], [64583.3, 0.018], [64591.3, 1.326], [64594.2, 0.011], [64612.5, 3.11], [64615.7, 0.004], [64616.9, 0.022], [64622.2, 0.001], [64622.3, 0.012], [64622.8, 0.377], [64626.0, 1.219], [64630.9, 2.343], [64632.9, 0.311], [64634.2, 0.0], [64634.9, 0.027], [64636.1, 2.344], [64636.7, 1.983], [64637.1, 0.557], [64637.9, 1.018], [64638.3, 0.015], [64642.6, 0.322], [64643.5, 0.002], [64646.4, 0.022], [64649.3, 0.294], [64649.4, 2.912], [64649.5, 2.015], [64650.6, 0.529], [64651.6, 0.005], [64653.9, 1.807], [64654.8, 0.013], [64655.1, 56.448]], "asks": [[64656.3, 0.013], [64656.8, 0.002], [64657.0, 0.014], [64657.6, 0.002], [64658.6, 0.003], [64659.6, 1.066], [64661.2, 0.004], [64661.8, 0.102], [64662.1, 0.546], [64662.3, 0.201], [64662.9, 0.01], [64665.6, 0.01], [64665.8, 0.135], [64670.8, 0.018], [64671.4, 0.033], [64676.8, 1.39], [64677.8, 0.464], [64681.6, 1.936], [64684.0, 0.032], [64686.6, 0.093], [64715.9, 0.022], [64716.1, 0.516], [64850.5, 2.197], [64978.5, 0.155], [65172.4, 0.418], [65301.8, 0.0], [65857.9, 3.151]]}
{"kind": "depth", "E": 1787082392199, "U": 11315508757990, "u": 11315508764059, "recv_ms": 1787082392172, "bids": [[14153.9, 1.218], [14555.1, 2.506], [51724.0, 0.0], [58189.5, 0.002], [61422.3, 0.0], [62068.8, 0.083], [63710.1, 1.081], [63878.1, 24.457], [64008.5, 0.0], [64191.1, 0.001], [64331.8, 0.001], [64498.2, 2.111], [64513.7, 0.412], [64594.3, 0.005], [64603.3, 0.021], [64612.5, 3.111], [64643.1, 1.961], [64651.6, 0.001], [64653.9, 1.806], [64655.0, 0.062], [64655.1, 56.449]], "asks": [[64656.3, 0.003], [64657.0, 0.004], [64657.6, 0.012], [64657.8, 0.127], [64669.1, 0.468], [64679.0, 0.008], [64679.7, 0.541], [64694.6, 3.788], [64793.5, 0.0], [64810.4, 2.257], [65301.8, 0.0], [65429.8, 27.759], [65807.6, 3.601]]}
{"kind": "depth", "E": 1787082392301, "U": 11315508764220, "u": 11315508772110, "recv_ms": 1787082392270, "bids": [[1000.0, 35.81], [14153.9, 0.868], [14555.1, 2.856], [51723.0, 0.0], [51724.0, 0.0], [58189.5, 0.002], [61422.3, 0.0], [62068.8, 0.08], [63655.1, 0.016], [63716.4, 22.962], [63944.6, 1.482], [64008.5, 0.0], [64457.9, 0.483], [64459.2, 10.79], [64460.1, 0.548], [64496.8, 0.0], [64498.0, 9.824], [64498.2, 0.742], [64515.0, 6.876], [64614.1, 0.027], [64622.3, 0.002], [64622.4, 1.231], [64629.2, 0.112], [64648.5, 0.233], [64649.7, 3.382], [64650.2, 0.31], [64651.5, 0.085], [64653.9, 1.655], [64655.1, 56.601]], "asks": [[64659.6, 1.15], [64660.4, 0.004], [64661.7, 0.003], [64661.8, 0.102], [64664.3, 1.311], [64691.8, 0.002], [64716.1, 0.506], [64716.2, 0.059], [64794.7, 5.402], [64810.4, 0.805], [64811.7, 10.437], [64850.5, 1.868], [65301.8, 0.0], [65655.2, 0.0], [65864.2, 0.712]]}
{"kind": "depth", "E": 1787082392403, "U": 11315508772684, "u": 11315508779868, "recv_ms": 1787082392376, "bids": [[1000.0, 35.81], [14153.9, 0.504], [14555.1, 3.22], [51724.1, 0.005], [58189.5, 0.002], [63837.7, 4.421], [64028.0, 62.384], [64197.6, 0.13], [64525.7, 2.711], [64622.4, 1.221], [64622.5, 0.014], [64649.3, 0.295], [64654.6, 0.194]], "asks": [[64664.2, 0.267], [64665.8, 0.598], [64666.6, 0.02], [64666.8, 0.429], [64670.0, 0.924], [64670.9, 0.001], [64674.1, 0.01], [65301.8, 0.0], [65457.2, 0.763], [65463.3, 0.346], [65635.3, 0.761], [65786.7, 1.538]]}
{"kind": "depth", "E": 1787082392505, "U": 11315508780163, "u": 11315508787136, "recv_ms": 1787082392475, "bids": [[14153.9, 0.308], [14455.1, 0.154], [14555.1, 3.262], [58189.5, 0.002], [61422.3, 0.0], [62068.8, 0.083], [63655.1, 0.036], [63716.4, 24.059], [63735.9, 0.237], [63949.2, 7.333], [64008.5, 0.0], [64331.8, 0.011], [64512.0, 0.029], [64644.2, 0.008], [64646.2, 0.197], [64651.3, 0.004], [64651.4, 0.002], [64655.1, 56.6]], "asks": [[64655.2, 2.744], [64657.8, 0.127], [64659.1, 0.008], [64659.4, 0.007], [64660.4, 0.012], [64661.0, 0.094], [64661.8, 0.097], [64662.0, 0.552], [64662.1, 0.005], [64662.2, 0.287], [64662.9, 0.01], [64666.6, 0.022], [64667.0, 1.95], [64667.7, 0.003], [64668.2, 0.006], [64692.7, 10.042], [64694.6, 0.016], [64697.6, 0.137], [65301.8, 0.0], [65431.0, 2.534], [65655.2, 0.02], [70035.1, 0.55]]}
{"kind": "depth", "E": 1787082392607, "U": 11315508787456, "u": 11315508795814, "recv_ms": 1787082392578, "bids": [[1000.0, 35.81], [14153.9, 0.182], [14455.1, 0.392], [14555.1, 3.15], [58189.5, 0.002], [61422.3, 0.0], [62068.8, 0.08], [64008.5, 0.0], [64538.0, 0.492], [64540.0, 4.095], [64547.9, 2.699], [64553.4, 0.116], [64553.9, 0.009], [64582.2, 0.124], [64584.2, 2.349], [64595.7, 0.113], [64596.2, 0.001], [64603.6, 0.504], [64622.5, 0.004], [64622.6, 0.072], [64648.5, 0.001], [64649.5, 2.247], [64651.3, 0.0], [64654.8, 0.014], [64655.1, 57.345]], "asks": [[64655.2, 2.698], [64657.9, 2.574], [64659.2, 0.836], [64659.6, 1.066], [64680.0, 1.538], [64681.0, 0.023], [64688.9, 0.643], [64704.4, 0.112], [64706.9, 0.001], [64716.2, 0.049], [64716.3, 0.01], [64724.5, 0.028], [64726.6, 0.172], [64727.7, 0.39], [64750.6, 0.13], [64760.2, 0.549], [64761.6, 1.298], [64763.9, 2.321], [64787.3, 1.114], [64788.7, 0.463], [64791.6, 3.87], [64844.4, 2.498], [64844.9, 0.003], [64850.5, 1.69], [65301.8, 1.529], [65947.0, 0.154], [65948.3, 0.052]]}
{"kind": "depth", "E": 1787082392709, "U": 11315508796024, "u": 11315508812776, "recv_ms": 1787082392682, "bids": [[1000.0, 35.81], [14153.9, 0.07], [14455.1, 0.63], [14555.1, 3.024], [58189.5, 0.002], [61422.3, 0.0], [62068.8, 0.083], [63362.0, 0.141], [63655.1, 0.016], [63808.3, 0.004], [63808.4, 0.001], [63878.1, 23.832], [64008.5, 0.002], [64136.7, 9.841], [64330.6, 5.043], [64576.3, 0.01], [64608.1, 0.118], [64618.3, 0.038], [64625.1, 2.149], [64625.2, 0.001], [64633.2, 7.23], [64633.3, 0.009], [64640.5, 0.135], [64641.4, 0.103], [64644.2, 0.0], [64645.3, 0.174], [64646.2, 0.205], [64647.8, 0.001], [64649.5, 1.706], [64650.2, 0.851], [64650.8, 0.0], [64651.3, 0.0], [64653.3, 0.015], [64655.0, 0.062], [64655.1, 61.417]], "asks": [[64655.2, 1.131], [64655.3, 0.002], [64656.8, 0.012], [64657.7, 0.691], [64657.8, 0.003], [64657.9, 0.255], [64658.4, 1.865], [64658.9, 0.01], [64659.0, 0.201], [64659.1, 1.941], [64659.2, 1.164], [64659.5, 0.54], [64659.6, 0.066], [64660.2, 0.003], [64660.4, 0.002], [64660.6, 0.04], [64660.7, 0.002], [64660.8, 1.002], [64661.0, 0.01], [64661.3, 0.119], [64661.4, 0.004], [64661.5, 0.021], [64661.6, 2.13], [64661.7, 0.087], [64661.8, 0.012], [64662.0, 0.011], [64662.1, 0.089], [64662.2, 0.828], [64662.3, 0.203], [64662.5, 0.017], [64663.1, 0.786], [64663.4, 0.397], [64664.1, 0.142], [64664.5, 0.088], [64664.9, 0.089], [64665.2, 0.162], [64665.8, 0.034], [64667.9, 0.006], [64668.4, 0.014], [64669.1, 0.467], [64670.1, 0.38], [64671.4, 0.597], [64672.7, 0.771], [64674.2, 0.463], [64675.1, 1.237], [64675.7, 0.001], [64676.4, 0.008], [64677.3, 0.071], [64677.9, 0.034], [64678.1, 0.616], [64679.0, 0.509], [64679.7, 0.0], [64680.5, 0.544], [64680.7, 0.158], [64683.8, 0.399], [64685.3, 0.003], [64689.1, 0.174], [64692.6, 4.199], [64692.7, 10.044], [64697.1, 0.003], [64701.2, 0.966], [64706.3, 2.07], [64706.4, 0.001], [64707.7, 7.255], [64712.3, 0.045], [64714.1, 0.966], [64714.4, 2.148], [64714.5, 0.441], [64720.6, 2.303], [64734.4, 1.52], [64779.4, 2.148], [64779.5, 0.094], [64849.2, 0.372], [64977.3, 4.512], [64978.5, 0.154], [65171.2, 9.066], [65301.8, 1.531], [65428.1, 0.0], [65655.2, 0.0], [65948.3, 0.058], [67241.1, 0.0], [67887.9, 0.007]]}
{"kind": "depth", "E": 1787082392811, "U": 11315508812851, "u": 11315508821289, "recv_ms": 1787082392781, "bids": [[14153.9, 0.0], [14455.1, 0.924], [14555.1, 2.8], [58189.5, 0.002], [61422.3, 0.0], [62068.8, 0.08], [63655.1, 0.036], [64008.5, 0.0], [64331.8, 0.002], [64543.9, 0.598], [64583.8, 0.001], [64584.3, 0.215], [64595.7, 0.11], [64606.4, 1.246], [64626.0, 0.237], [64638.8, 0.002], [64639.5, 0.001], [64644.1, 0.477], [64646.2, 0.197], [64651.5, 0.085], [64653.9, 1.69], [64655.1, 61.429]], "asks": [[64656.7, 0.012], [64656.8, 0.002], [64657.9, 0.253], [64658.9, 0.01], [64660.4, 0.01], [64661.0, 0.003], [64661.5, 0.02], [64661.7, 0.087], [64662.1, 0.63], [64662.2, 0.287], [64662.9, 0.01], [64663.0, 0.395], [64663.1, 0.766], [64679.2, 0.029], [64695.4, 0.002], [64696.8, 4.254], [64697.6, 0.135], [64699.4, 0.005], [64704.4, 0.043], [64712.3, 0.042], [64716.3, 0.0], [64716.4, 0.048], [64717.5, 0.002], [64718.1, 0.103], [64726.2, 41.319], [64727.7, 0.381], [64728.4, 0.017], [64850.5, 0.028], [65172.4, 0.724], [65301.8, 1.529], [65655.2, 0.02]]}
{"kind": "depth", "E": 1787082392913, "U": 11315508821340, "u": 11315508832009, "recv_ms": 1787082392886, "bids": [[1000.0, 35.81], [14455.1, 1.274], [14555.1, 2.45], [58189.5, 0.002], [61422.3, 0.0], [63812.2, 1.096], [63846.9, 1.436], [63878.1, 24.457], [64008.5, 0.006], [64136.7, 10.152], [64330.6, 5.043], [64550.6, 0.0], [64553.6, 1.286], [64622.6, 0.062], [64622.7, 0.011], [64644.0, 0.517], [64649.8, 1.564], [64650.2, 0.31], [64651.4, 0.002], [64655.1, 61.012]], "asks": [[64655.2, 2.158], [64655.3, 0.003], [64656.7, 0.002], [64657.8, 0.003], [64658.9, 0.02], [64659.6, 1.066], [64660.8, 0.002], [64660.9, 0.088], [64661.7, 0.089], [64661.8, 0.015], [64662.3, 0.201], [64663.0, 0.418], [64663.1, 0.743], [64664.9, 0.005], [64674.0, 1.061], [64675.1, 0.311], [64679.0, 1.05], [64680.5, 0.003], [64692.7, 0.044], [64693.8, 10.059], [64729.0, 0.091], [64749.0, 1.71], [64750.4, 2.935], [64978.5, 0.308], [65171.2, 8.759], [65263.6, 1.401], [65301.8, 1.531], [65948.3, 0.067], [67886.7, 0.06]]}
{"kind": "depth", "E": 1787082393015, "U": 11315508832216, "u": 11315508841568, "recv_ms": 1787082392986, "bids": [[1000.0, 35.81], [14455.1, 1.638], [14555.1, 2.086], [58189.5, 0.002], [61422.3, 0.0], [62068.8, 0.083], [63810.6, 3.279], [64008.5, 0.0], [64331.8, 0.001], [64587.8, 8.512], [64610.2, 0.15], [64610.4, 3.528], [64610.5, 1.402], [64610.7, 0.276], [64626.5, 1.062], [64638.7, 2.339], [64651.3, 0.0], [64655.1, 61.019]], "asks": [[64655.3, 0.004], [64656.8, 0.012], [64658.9, 0.01], [64671.2, 0.005], [64684.5, 1.127], [64692.7, 0.042], [64693.8, 10.061], [64696.4, 0.031], [64700.6, 3.53], [64704.1, 0.06], [64716.4, 0.038], [64716.5, 0.01], [64723.3, 7.237], [64784.6, 0.0], [64850.5, 1.773], [64854.4, 0.001], [64950.0, 24.248], [65301.8, 1.529], [65451.1, 7.999], [65494.4, 0.0], [65948.3, 0.07]]}
{"kind": "depth", "E": 1787082393117, "U": 11315508841585, "u": 11315508849880, "recv_ms": 1787082393089, "bids": [[14455.1, 1.988], [14555.1, 1.736], [51724.0, 0.02], [58189.5, 0.002], [61422.3, 0.0], [61605.5, 0.0], [61606.7, 0.016], [62068.8, 0.08], [63651.5, 0.011], [63655.1, 0.016], [63716.1, 0.0], [63719.5, 0.0], [64008.5, 0.0], [64329.2, 0.124], [64329.8, 1.664], [64331.8, 0.011], [64540.0, 4.095], [64553.9, 0.006], [64554.1, 0.005], [64555.1, 10.0], [64571.3, 0.002], [64583.3, 0.017], [64584.2, 2.349], [64591.4, 0.058], [64594.3, 0.004], [64600.8, 4.489], [64606.2, 0.503], [64612.5, 3.109], [64629.2, 0.095], [64638.8, 0.003], [64643.5, 0.002], [64648.9, 0.233], [64649.5, 1.474], [64651.3, 0.0], [64653.3, 0.015], [64655.0, 0.062], [64655.1, 60.196]], "asks": [[64655.2, 2.021], [64656.7, 0.012], [64656.8, 0.002], [64657.7, 1.006], [64657.8, 0.127], [64657.9, 2.572], [64658.5, 0.008], [64658.9, 0.002], [64659.0, 0.085], [64660.2, 0.087], [64660.6, 0.042], [64661.1, 0.241], [64661.6, 0.064], [64661.7, 0.087], [64661.8, 0.013], [64663.0, 0.376], [64663.1, 0.784], [64669.6, 0.003], [64694.7, 0.586], [64704.1, 0.0], [64726.2, 2.32], [64726.6, 0.172], [64728.3, 38.753], [64730.5, 0.008], [64755.0, 10.103], [64791.3, 3.881], [64791.6, 0.003], [64844.9, 0.0], [64845.1, 0.979], [64850.5, 0.028], [64978.5, 0.309], [64978.6, 0.016], [64982.6, 0.108], [65269.4, 0.688], [65301.8, 1.531], [65588.5, 0.008], [65591.8, 0.007], [65655.2, 0.0], [65656.5, 0.058], [65744.9, 1.958], [65754.3, 1.142], [65948.3, 0.073], [67683.0, 0.028], [67684.2, 0.04]]}
{"kind": "depth", "E": 1787082393219, "U": 11315508849959, "u": 11315508861978, "recv_ms": 1787082393188, "bids": [[1000.0, 35.81], [14455.1, 2.352], [14555.1, 1.372], [51724.0, 0.0], [58189.5, 0.002], [62068.8, 0.083], [63362.0, 0.144], [63652.6, 0.008], [63717.4, 0.011], [64008.5, 0.0], [64287.5, 0.001], [64287.9, 9.759], [64331.8, 0.166], [64460.1, 2.224], [64498.2, 2.044], [64554.4, 0.009], [64555.2, 1.196], [64583.2, 1.813], [64584.4, 0.906], [64603.3, 0.022], [64651.4, 0.002], [64653.8, 0.913], [64655.1, 60.198]], "asks": [[64656.7, 0.002], [64664.5, 0.004], [64691.3, 3.145], [64717.5, 1.403], [64810.4, 2.257], [64855.0, 5.538], [64855.5, 0.012], [64925.9, 5.571], [65172.4, 1.031], [65301.8, 1.529], [65499.2, 0.267], [65677.4, 4.257], [67887.9, 0.012]]}
{"kind": "depth", "E": 1787082393321, "U": 11315508862189, "u": 11315508870715, "recv_ms": 1787082393294, "bids": [[1000.0, 35.81], [14455.1, 2.702], [14555.1, 1.022], [58189.5, 0.002], [61422.3, 0.0], [62068.8, 0.08], [63655.1, 0.036], [63720.6, 0.011], [63749.9, 0.212], [64008.5, 0.002], [64515.0, 6.926], [64622.7, 0.001], [64622.8, 0.387], [64624.5, 0.216], [64625.4, 0.002], [64635.5, 0.117], [64636.0, 3.898], [64636.7, 1.867], [64637.1, 0.0], [64640.8, 0.927], [64641.8, 0.18], [64646.2, 0.197], [64649.7, 3.923], [64649.8, 1.023], [64651.4, 0.002], [64655.1, 61.032]], "asks": [[64655.2, 2.023], [64656.8, 0.012], [64657.8, 0.127], [64663.1, 0.743], [64676.3, 0.003], [64677.1, 0.616], [64677.2, 0.068], [64678.0, 0.125], [64678.1, 0.002], [64678.4, 0.226], [64679.0, 1.05], [64679.4, 0.117], [64680.3, 0.178], [64687.5, 0.005], [64750.6, 0.03], [64794.7, 5.402], [64850.5, 0.028], [65301.8, 1.529], [65593.0, 0.008], [65655.2, 0.02], [65657.7, 0.009], [65948.3, 0.076]]}
{"kind": "depth", "E": 1787082393423, "U": 11315508870782, "u": 11315508884827, "recv_ms": 1787082393393, "bids": [[14455.1, 3.066], [14553.9, 0.392], [14554.0, 0.0], [14555.1, 0.728], [51724.1, 0.005], [58189.5, 0.002], [61422.3, 0.0], [63740.8, 10.187], [63770.2, 3.492], [64008.5, 0.0], [64331.8, 0.166], [64629.2, 0.107], [64648.9, 0.001], [64649.3, 0.527], [64651.4, 0.002], [64655.1, 60.606]], "asks": [[64656.8, 0.012], [64663.2, 0.432], [64687.2, 2.473], [64687.3, 1.296], [65263.6, 0.713], [65301.8, 1.529], [65473.3, 0.929], [65589.8, 0.008], [65929.1, 0.0], [65948.3, 0.079], [67886.7, 0.055]]}
{"kind": "depth", "E": 1787082393525, "U": 11315508885022, "u": 11315508894242, "recv_ms": 1787082393494, "bids": [[1000.0, 35.81], [14455.1, 3.416], [14553.9, 0.266], [14554.6, 0.0], [14555.1, 0.518], [58189.5, 0.002], [61422.3, 0.0], [62068.8, 0.083], [63360.9, 0.02], [63648.5, 0.13], [63655.1, 0.016], [64008.5, 0.004], [64330.6, 4.888], [64574.5, 1.632], [64576.7, 43.71], [64617.8, 0.158], [64646.2, 0.738], [64649.7, 3.382], [64651.3, 0.0], [64651.4, 0.002], [64653.3, 0.074], [64655.1, 60.609]], "asks": [[64655.2, 2.019], [64656.8, 0.012], [64657.8, 0.127], [64660.2, 0.003], [64678.1, 0.543], [64679.0, 0.509], [64687.3, 1.296], [64694.7, 0.526], [64701.5, 0.06], [65230.9, 6.888], [65269.4, 1.376], [65301.8, 1.529], [65655.2, 0.0], [65689.7, 0.426], [65948.3, 0.082]]}
{"kind": "depth", "E": 1787082393627, "U": 11315508894313, "u": 11315508902490, "recv_ms": 1787082393595, "bids": [[1000.0, 35.81], [14355.1, 0.028], [14455.1, 3.724], [14553.9, 0.056], [14555.1, 0.392], [58189.5, 0.002], [61422.3, 0.0], [62068.8, 0.08], [63835.8, 0.782], [64008.5, 0.0], [64646.2, 0.197], [64649.8, 1.564], [64655.1, 59.807]], "asks": [[64656.8, 0.002], [64659.2, 1.165], [64678.1, 0.002], [64679.0, 1.05], [64680.2, 6.42], [64681.6, 1.935], [64689.0, 0.555], [64689.5, 0.024], [64716.5, 0.0], [64716.6, 0.011], [64850.5, 0.028], [65301.8, 1.529]]}
{"kind": "depth", "E": 1787082393729, "U": 11315508902666, "u": 11315508910219, "recv_ms": 1787082393699, "bids": [[14355.1, 0.21], [14455.1, 3.71], [14553.9, 0.0], [14555.1, 0.28], [58189.5, 0.002], [62068.8, 0.083], [63654.2, 4.235], [63655.1, 0.036], [64008.5, 0.0], [64331.8, 0.321], [64633.4, 0.001], [64637.0, 0.197]], "asks": [[64663.1, 0.743], [64663.2, 0.41], [64850.5, 1.763], [65301.8, 1.529], [65655.2, 0.02]]}
{"kind": "depth", "E": 1787082393831, "U": 11315508910365, "u": 11315508919046, "recv_ms": 1787082393802, "bids": [[1000.0, 35.81], [14355.1, 0.448], [14455.1, 3.598], [14555.1, 0.154], [58189.5, 0.002], [61421.2, 0.002], [61421.3, 0.01], [61422.3, 0.0], [62068.8, 0.08], [64008.5, 0.0], [64331.8, 0.32], [64515.0, 1.716], [64554.1, 0.002], [64554.2, 0.006], [64590.1, 0.102], [64590.4, 1.21], [64590.7, 0.0], [64591.0, 0.001], [64591.4, 0.026], [64608.7, 0.818], [64609.0, 0.17], [64609.3, 0.0], [64609.7, 0.018], [64610.0, 0.931], [64623.6, 1.869], [64623.7, 2.444], [64623.8, 0.004], [64623.9, 1.871], [64624.0, 0.469], [64624.1, 0.456], [64624.2, 0.002], [64624.3, 0.001], [64624.4, 0.0], [64624.6, 0.323], [64626.5, 0.962], [64626.9, 0.007], [64634.8, 0.311], [64636.6, 0.634], [64636.9, 0.003], [64637.0, 0.043], [64642.1, 0.164], [64644.7, 0.291], [64644.8, 0.522], [64644.9, 0.311], [64645.0, 0.045], [64645.1, 0.027], [64645.2, 0.002], [64645.3, 0.004], [64645.4, 0.407], [64645.5, 0.081], [64645.6, 0.002], [64645.9, 2.329], [64646.2, 0.165], [64646.6, 0.001], [64646.9, 0.001], [64647.2, 0.001], [64650.2, 0.31], [64651.3, 0.0], [64652.9, 0.0], [64655.1, 59.806]], "asks": [[64657.8, 0.127], [64660.3, 0.205], [64660.4, 0.002], [64661.3, 0.084], [64661.6, 0.026], [64661.8, 0.013], [64661.9, 0.468], [64662.1, 0.089], [64662.3, 0.156], [64662.4, 1.093], [64662.6, 0.085], [64662.8, 0.002], [64662.9, 0.003], [64663.0, 0.088], [64663.1, 0.563], [64663.2, 0.124], [64663.3, 2.347], [64663.4, 0.087], [64663.5, 0.026], [64663.6, 0.002], [64663.7, 0.061], [64663.8, 0.285], [64665.8, 0.042], [64668.0, 0.448], [64669.1, 0.158], [64670.7, 0.082], [64670.9, 0.626], [64671.4, 0.52], [64678.1, 0.002], [64679.9, 1.681], [64680.2, 6.382], [64680.6, 0.627], [64680.9, 0.077], [64681.2, 0.0], [64681.6, 1.745], [64682.0, 0.003], [64683.9, 2.32], [64684.1, 0.003], [64684.2, 0.008], [64684.3, 0.0], [64684.4, 0.066], [64684.5, 0.987], [64684.6, 0.002], [64684.7, 0.187], [64684.8, 0.007], [64684.9, 0.0], [64687.3, 1.142], [64687.4, 0.154], [64698.5, 0.0], [64698.8, 0.158], [64699.2, 1.018], [64699.5, 0.022], [64699.8, 2.381], [64794.7, 0.0], [64803.9, 0.295], [65237.4, 1.075], [65301.8, 1.529], [65591.5, 27.102]]}
{"kind": "depth", "E": 1787082393933, "U": 11315508919207, "u": 11315508926201, "recv_ms": 1787082393905, "bids": [[1000.0, 35.81], [14355.1, 0.7], [14455.1, 3.458], [14555.1, 0.042], [58189.5, 0.002], [63655.1, 0.016], [63878.1, 23.833], [64008.5, 0.0], [64136.7, 9.842], [64498.0, 0.593], [64498.2, 0.742], [64610.2, 0.182], [64645.9, 2.399], [64646.1, 0.71], [64647.4, 0.102]], "asks": [[64657.6, 0.002], [64662.7, 0.049], [64664.0, 0.19], [64664.2, 0.358], [64665.8, 0.042], [64670.8, 0.018], [64670.9, 0.001], [64671.4, 1.145], [64681.3, 2.381], [64685.0, 0.121], [64685.3, 0.094], [64699.9, 0.433], [64784.6, 0.001], [64810.4, 0.805], [64811.7, 0.022], [64978.5, 0.31], [65301.8, 1.531], [65451.2, 3.254], [65655.2, 0.0]]}
{"kind": "depth", "E": 1787082394035, "U": 11315508926260, "u": 11315508934355, "recv_ms": 1787082394006, "bids": [[14355.1, 1.008], [14455.1, 3.192], [14555.1, 0.0], [58189.5, 0.002], [61421.3, 0.008], [61422.3, 0.002], [62068.8, 0.083], [63362.0, 0.147], [63846.9, 1.67], [64008.5, 0.0], [64331.8, 0.32], [64459.2, 10.958], [64460.1, 0.548], [64498.0, 11.058], [64515.0, 7.141], [64543.9, 0.595], [64609.9, 0.032], [64610.5, 1.434], [64621.5, 0.0], [64622.3, 0.0], [64622.4, 1.219], [64622.5, 0.002], [64625.7, 0.025], [64625.8, 0.006], [64625.9, 0.001], [64636.0, 3.341], [64636.6, 0.48], [64636.7, 2.424], [64636.8, 0.347], [64637.6, 0.817], [64638.7, 2.339], [64640.7, 2.558], [64640.8, 0.001], [64641.5, 0.133], [64642.4, 0.002], [64643.5, 0.007], [64646.0, 2.845], [64646.2, 0.165], [64646.3, 0.301], [64646.5, 0.115], [64646.6, 0.101], [64646.7, 0.17], [64646.9, 0.071], [64647.1, 0.049], [64647.8, 0.033], [64649.7, 3.923], [64649.8, 1.023], [64651.3, 0.0], [64655.1, 59.806]], "asks": [[64657.6, 0.012], [64662.3, 0.201], [64663.0, 0.141], [64663.2, 0.236], [64663.4, 0.375], [64663.5, 0.206], [64663.6, 0.212], [64663.7, 0.211], [64663.8, 0.595], [64664.1, 0.247], [64665.8, 0.034], [64671.2, 0.005], [64673.2, 0.001], [64674.0, 0.135], [64674.1, 0.936], [64674.6, 0.38], [64674.8, 0.04], [64677.1, 0.059], [64677.8, 1.021], [64678.1, 0.002], [64679.0, 1.05], [64679.7, 0.0], [64681.0, 0.068], [64681.6, 1.79], [64682.0, 0.193], [64682.4, 4.748], [64684.3, 0.112], [64684.5, 1.085], [64684.6, 0.392], [64684.8, 0.157], [64684.9, 0.14], [64685.1, 0.119], [64699.4, 0.005], [64699.6, 0.045], [64700.2, 0.047], [64776.8, 2.157], [64784.6, 0.0], [64794.7, 5.402], [64811.7, 10.437], [64850.5, 0.028], [64978.5, 0.309], [65301.8, 1.529], [65592.7, 1.224], [67887.9, 0.017]]}
{"kind": "depth", "E": 1787082394137, "U": 11315508934455, "u": 11315508942437, "recv_ms": 1787082394108, "bids": [[1000.0, 35.81], [14355.1, 1.358], [14455.1, 2.842], [58189.5, 0.002], [62068.8, 0.08], [63655.1, 0.036], [63837.7, 4.186], [64008.5, 0.0], [64331.8, 0.321], [64515.0, 1.716], [64571.4, 0.028], [64594.3, 0.003], [64594.4, 0.069], [64600.8, 4.487], [64603.3, 0.021], [64606.1, 0.006], [64606.2, 0.502], [64610.8, 0.064], [64611.2, 0.039], [64635.5, 0.001], [64636.4, 3.027], [64636.8, 0.193], [64637.0, 0.043], [64637.1, 0.0], [64643.5, 0.002], [64646.0, 2.915], [64646.1, 0.78], [64646.4, 0.122], [64648.1, 0.043], [64648.4, 0.365], [64649.0, 0.309], [64649.4, 2.603]], "asks": [[64657.6, 0.002], [64657.8, 0.127], [64661.7, 0.122], [64662.0, 0.049], [64663.7, 0.381], [64664.0, 0.316], [64664.1, 0.345], [64670.9, 0.078], [64671.4, 1.068], [64677.0, 0.557], [64677.8, 0.464], [64680.3, 0.213], [64680.6, 0.665], [64684.8, 0.327], [64685.1, 0.245], [64685.2, 2.099], [64698.9, 0.035], [64699.3, 0.855], [64776.8, 0.371], [64794.7, 0.0], [64850.5, 10.499], [65301.8, 1.529], [65655.2, 0.02]]}
{"kind": "depth", "E": 1787082394239, "U": 11315508942455, "u": 11315508951809, "recv_ms": 1787082394209, "bids": [[1000.0, 35.81], [14355.1, 1.722], [14455.1, 2.478], [58189.5, 0.002], [61421.2, 0.0], [61421.3, 0.01], [61422.3, 0.002], [62068.8, 0.083], [63453.3, 1.022], [63554.8, 2.859], [63674.2, 0.544], [63716.4, 22.962], [63879.2, 0.645], [64008.5, 0.0], [64137.9, 0.404], [64460.1, 2.249], [64498.2, 2.228], [64515.0, 7.077], [64525.7, 2.711], [64540.0, 4.095], [64577.7, 7.566], [64583.2, 1.815], [64584.2, 2.349], [64591.6, 0.035], [64603.2, 1.691], [64603.3, 0.02], [64612.3, 0.108], [64621.8, 0.001], [64636.2, 0.171], [64636.9, 0.003], [64646.2, 0.235], [64646.5, 0.185], [64651.3, 0.0], [64655.1, 60.193]], "asks": [[64663.0, 0.689], [64663.6, 0.31], [64663.9, 0.2], [64671.4, 0.52], [64684.7, 0.285], [64685.0, 0.219], [64696.1, 1.704], [64726.5, 0.059], [64726.6, 0.126], [64726.7, 7.22], [64790.9, 3.867], [64791.3, 0.014], [64794.7, 5.402], [64810.4, 2.257], [64850.5, 1.618], [65301.8, 1.529], [67886.7, 0.05]]}
{"kind": "depth", "E": 1787082394341, "U": 11315508951912, "u": 11315508961536, "recv_ms": 1787082394311, "bids": [[14355.1, 2.072], [14455.1, 2.128], [51724.0, 0.0], [58189.5, 0.002], [61422.3, 0.002], [63655.1, 0.016], [64008.5, 0.002], [64331.8, 0.311], [64515.0, 1.716], [64591.3, 1.358], [64591.9, 0.034], [64624.8, 0.082], [64625.0, 1.66], [64649.7, 3.942], [64649.8, 1.006], [64654.1, 0.045], [64655.1, 60.174]], "asks": [[64657.8, 0.127], [64676.6, 0.01], [64685.7, 0.004], [64687.1, 0.102], [64687.4, 0.0], [64794.7, 0.0], [65301.8, 1.529], [65655.2, 0.0], [65656.1, 15.363]]}
{"kind": "depth", "E": 1787082394443, "U": 11315508961606, "u": 11315508971287, "recv_ms": 1787082394413, "bids": [[1000.0, 35.81], [14355.1, 2.436], [14455.1, 1.764], [51723.0, 0.0], [51724.1, 0.005], [58189.5, 0.002], [62068.8, 0.08], [63459.0, 1.022], [63556.0, 5.25], [63717.6, 1.097], [64008.5, 0.0], [64066.9, 0.0], [64459.2, 10.74], [64460.1, 0.548], [64498.0, 9.932], [64498.2, 0.742], [64515.0, 7.077], [64592.2, 0.034], [64592.5, 0.034], [64624.9, 0.071], [64625.2, 0.101], [64625.3, 0.106], [64625.5, 1.5], [64625.6, 2.074], [64625.8, 0.076], [64627.7, 0.101], [64628.1, 0.13]], "asks": [[64687.1, 0.102], [64687.6, 4.044], [64794.7, 5.402], [64810.4, 0.805], [64811.7, 10.437], [64850.5, 1.618], [65301.8, 1.529], [65408.6, 1.087], [67886.7, 0.045]]}
{"kind": "depth", "E": 1787082394545, "U": 11315508971366, "u": 11315508981044, "recv_ms": 1787082394515, "bids": [[1000.0, 35.81], [14355.1, 2.8], [14455.1, 1.4], [58189.5, 0.002], [61421.3, 0.008], [61422.3, 0.002], [62068.8, 0.083], [63362.0, 0.15], [63655.1, 0.036], [63682.0, 0.275], [64008.5, 0.0], [64070.4, 1.091], [64531.6, 0.007], [64622.7, 0.004], [64624.9, 0.141], [64625.0, 1.73], [64625.3, 0.206], [64628.0, 0.79], [64651.3, 0.0], [64655.1, 60.174]], "asks": [[64655.2, 2.034], [64657.6, 0.012], [64657.8, 0.127], [64660.3, 0.121], [64668.4, 1.251], [64713.4, 0.317], [64850.5, 1.618], [65301.8, 1.529], [65463.4, 0.232], [65599.7, 0.001], [65655.2, 0.02], [65947.0, 0.151]]}
{"kind": "depth", "E": 1787082394647, "U": 11315508981149, "u": 11315508989116, "recv_ms": 1787082394617, "bids": [[14355.1, 3.15], [14455.1, 1.05], [51724.0, 0.0], [58189.5, 0.002], [61422.3, 0.002], [62068.8, 0.08], [63910.4, 8.831], [64008.5, 0.0], [64331.8, 0.311], [64622.8, 0.377], [64622.9, 0.023], [64625.1, 2.219], [64625.4, 0.072], [64635.5, 0.117], [64636.0, 3.898], [64636.4, 2.911], [64636.7, 1.867], [64640.7, 1.632], [64641.8, 1.106], [64646.2, 0.235], [64649.7, 3.942], [64651.3, 0.0], [64655.1, 60.173]], "asks": [[64655.2, 2.036], [64664.3, 1.312], [64678.1, 0.002], [64678.4, 0.226], [64679.0, 1.05], [64679.4, 0.117], [64745.6, 0.1], [64850.5, 0.028], [65301.8, 1.529], [65412.4, 0.02], [65657.4, 1.826], [71120.8, 0.0]]}
{"kind": "depth", "E": 1787082394749, "U": 11315508989212, "u": 11315508997193, "recv_ms": 1787082394721, "bids": [[1000.0, 35.81], [14355.1, 3.5], [14455.1, 0.7], [58189.5, 0.002], [61422.3, 0.002], [62068.8, 0.083], [63651.8, 20.232], [63655.1, 0.016], [63716.4, 21.865], [63910.4, 7.893], [64008.5, 0.0], [64651.3, 0.0], [64655.1, 60.166]], "asks": [[64657.6, 0.012], [64663.1, 0.606], [64663.2, 0.214], [65301.8, 1.529], [65389.3, 0.02], [65655.2, 0.0]]}
{"kind": "depth", "E": 1787082394851, "U": 11315508997289, "u": 11315509012180, "recv_ms": 1787082394823, "bids": [[1000.0, 35.81], [14255.1, 0.056], [14355.1, 3.752], [14455.1, 0.392], [58189.5, 0.002], [61422.3, 0.002], [63619.4, 4.836], [63655.1, 0.036], [63716.4, 20.768], [63825.4, 0.782], [63911.6, 0.938], [64008.5, 0.006], [64601.5, 0.019], [64603.2, 1.708], [64607.5, 2.32], [64610.8, 0.07], [64631.5, 0.005], [64632.6, 0.006], [64633.0, 0.061], [64634.3, 0.028], [64634.7, 0.003], [64635.8, 0.061], [64636.2, 0.017], [64637.2, 0.001], [64637.5, 0.028], [64639.1, 0.365], [64640.8, 0.022], [64642.1, 0.164], [64646.5, 0.18], [64651.3, 0.0], [64653.9, 1.689], [64655.1, 60.945]], "asks": [[64655.2, 1.512], [64655.3, 0.002], [64657.6, 0.002], [64657.8, 0.127], [64659.2, 0.837], [64660.4, 0.002], [64660.6, 0.04], [64661.2, 0.006], [64662.3, 0.077], [64662.9, 0.011], [64663.0, 0.681], [64664.2, 0.196], [64665.8, 0.034], [64666.8, 0.0], [64668.3, 0.0], [64670.7, 0.082], [64670.9, 0.001], [64671.4, 0.597], [64678.1, 0.002], [64678.7, 0.027], [64679.0, 0.509], [64679.1, 2.283], [64679.7, 0.541], [64679.8, 1.651], [64684.5, 0.098], [64692.8, 1.019], [64694.5, 0.087], [64699.3, 0.832], [64701.0, 0.357], [64704.4, 0.027], [64705.7, 0.531], [64706.1, 0.048], [64707.4, 0.058], [64850.5, 3.073], [64978.5, 0.308], [65301.8, 1.529], [65605.6, 1.298], [65655.2, 0.02], [65947.0, 0.148], [65948.3, 0.088], [67887.9, 0.022]]}
{"kind": "depth", "E": 1787082394953, "U": 11315509012286, "u": 11315509020411, "recv_ms": 1787082394925, "bids": [[14255.1, 0.28], [14355.1, 3.668], [14455.1, 0.252], [58189.5, 0.002], [61422.3, 0.004], [62068.8, 0.08], [63362.0, 0.153], [63546.8, 4.554], [63835.0, 8.596], [64008.5, 0.0], [64331.8, 0.312], [64532.6, 0.09], [64637.1, 0.154], [64639.6, 0.135], [64640.9, 0.18], [64641.1, 0.971], [64641.8, 0.18], [64646.2, 0.235], [64649.7, 3.401], [64649.9, 3.045], [64651.5, 0.085], [64652.8, 0.089], [64655.1, 60.985]], "asks": [[64657.6, 0.002], [64661.2, 0.004], [64662.0, 0.051], [64683.7, 0.975], [64685.6, 0.034], [64695.0, 0.042], [64771.6, 0.0], [65301.8, 1.529], [65424.6, 0.917], [65548.1, 23.743], [65645.2, 2.113]]}
{"kind": "depth", "E": 1787082395055, "U": 11315509020436, "u": 11315509028317, "recv_ms": 1787082395024, "bids": [[1000.0, 35.81], [14255.1, 0.504], [14355.1, 3.57], [14455.1, 0.126], [58189.5, 0.002], [61422.3, 0.004], [62068.8, 0.083], [63620.6, 1.193], [63652.9, 1.099], [63717.6, 3.291], [63750.7, 1.572], [63911.6, 1.876], [64006.7, 0.476], [64007.9, 1.167], [64008.5, 0.0], [64331.8, 0.311], [64515.0, 7.028], [64622.3, 0.002], [64622.4, 1.221], [64622.5, 0.004], [64625.7, 0.027], [64625.8, 0.078], [64625.9, 0.003], [64629.2, 0.095], [64636.9, 0.157], [64637.1, 0.0], [64638.7, 2.339], [64643.5, 0.002], [64644.7, 0.816], [64647.3, 0.515], [64651.5, 0.085], [64654.9, 1.18], [64655.1, 60.627]], "asks": [[64655.2, 1.347], [64657.6, 0.012], [64657.8, 0.127], [64658.5, 0.006], [64659.0, 0.077], [64659.1, 0.008], [64659.2, 0.839], [64660.4, 0.01], [64661.9, 0.498], [64662.0, 0.049], [64662.7, 0.051], [64662.9, 0.003], [64663.1, 0.586], [64665.8, 0.598], [64671.2, 0.005], [64671.4, 0.033], [64681.3, 2.383], [64794.7, 5.402], [64850.5, 1.815], [65301.8, 1.529]]}
{"kind": "depth", "E": 1787082395157, "U": 11315509028403, "u": 11315509037181, "recv_ms": 1787082395126, "bids": [[1000.0, 35.81], [14255.1, 0.742], [14355.1, 3.444], [14455.1, 0.014], [51724.0, 0.0], [58189.5, 0.002], [61422.3, 0.006], [62068.8, 0.08], [63556.0, 5.642], [63651.5, 0.0], [63652.6, 0.019], [63655.1, 0.016], [63749.9, 2.562], [64008.5, 0.0], [64075.2, 0.0], [64076.4, 0.02], [64235.4, 0.0], [64236.6, 0.023], [64396.0, 0.068], [64397.2, 0.004], [64460.1, 2.216], [64498.2, 2.06], [64525.7, 2.711], [64571.4, 0.027], [64583.2, 1.816], [64594.4, 0.068], [64603.2, 1.709], [64606.2, 0.503], [64612.4, 0.55], [64635.5, 0.001], [64636.0, 3.341], [64636.4, 3.027], [64636.7, 1.867], [64636.8, 0.75], [64637.1, 0.0], [64651.5, 0.085], [64652.8, 0.086], [64655.1, 61.538]], "asks": [[64655.2, 1.873], [64655.3, 0.004], [64655.4, 0.003], [64656.8, 0.012], [64657.6, 0.012], [64659.6, 1.15], [64660.1, 0.1], [64662.9, 0.026], [64663.0, 0.681], [64663.1, 0.563], [64663.5, 0.183], [64664.1, 0.261], [64665.7, 0.004], [64665.8, 0.034], [64671.4, 0.597], [64677.0, 0.0], [64677.3, 0.628], [64693.0, 0.088], [64701.5, 0.0], [64723.2, 2.336], [64723.4, 0.001], [64741.0, 0.003], [64753.2, 0.626], [64810.4, 2.257], [64850.5, 0.028], [64912.8, 0.001], [64914.0, 0.435], [64978.5, 0.309], [65075.1, 0.0], [65076.3, 0.016], [65237.7, 0.0], [65239.0, 0.092], [65301.8, 1.529], [65589.7, 0.336], [65655.2, 0.0], [65656.5, 0.047], [65935.4, 0.606], [65948.3, 0.1], [71120.8, 0.0]]}
{"kind": "depth", "E": 1787082395259, "U": 11315509037214, "u": 11315509046424, "recv_ms": 1787082395231, "bids": [[14255.1, 1.092], [14355.1, 3.108], [14455.1, 0.0], [51724.0, 0.0], [58189.5, 0.002], [61422.3, 0.007], [63360.9, 0.017], [63655.1, 0.036], [63749.9, 2.75], [63756.4, 1.566], [64008.5, 0.001], [64331.8, 0.321], [64459.2, 8.322], [64498.0, 7.77], [64515.0, 5.614], [64557.0, 0.214], [64558.2, 0.233], [64583.2, 1.817], [64603.2, 1.71], [64606.2, 0.504], [64612.4, 0.551], [64651.4, 0.002], [64655.1, 59.939]], "asks": [[64655.4, 0.002], [64656.8, 0.002], [64657.6, 0.002], [64657.8, 0.127], [64662.7, 0.073], [64665.7, 0.004], [64665.8, 0.034], [64671.4, 0.597], [64745.6, 0.0], [64750.9, 0.024], [64752.1, 0.018], [64794.7, 0.0], [64794.8, 2.884], [64811.7, 4.881], [64850.5, 7.527], [65301.8, 1.531], [65655.2, 0.02], [65657.4, 2.891], [65657.7, 0.02]]}
{"kind": "depth", "E": 1787082395361, "U": 11315509046459, "u": 11315509054267, "recv_ms": 1787082395330, "bids": [[1000.0, 35.81], [14255.1, 1.456], [14355.1, 2.744], [58189.5, 0.002], [61422.3, 0.006], [62068.8, 0.083], [64008.5, 0.001], [64498.0, 11.058], [64515.0, 7.141], [64590.4, 1.211], [64608.6, 0.198], [64629.2, 0.116], [64635.5, 0.117], [64636.0, 3.898], [64636.4, 2.911], [64636.8, 0.193], [64646.2, 0.776], [64649.9, 2.504], [64651.4, 0.002], [64655.1, 61.546]], "asks": [[64657.6, 0.012], [64659.6, 1.066], [64661.7, 0.122], [64662.1, 0.63], [64662.3, 0.201], [64662.6, 0.105], [64663.0, 0.14], [64663.3, 2.327], [64665.7, 0.004], [64665.8, 0.135], [64671.4, 0.496], [64676.3, 0.56], [64677.3, 0.071], [64678.1, 0.543], [64679.7, 0.0], [64699.4, 0.002], [64700.5, 0.005], [64713.4, 0.314], [64719.9, 0.002], [64771.0, 3.564], [64771.7, 0.085], [64794.7, 5.402], [64794.8, 0.0], [64811.7, 10.437], [64850.5, 0.028], [65301.8, 1.529], [65518.6, 3.763], [65599.2, 0.307], [65948.3, 0.103], [71120.8, 0.0]]}
{"kind": "depth", "E": 1787082395463, "U": 11315509054291, "u": 11315509061119, "recv_ms": 1787082395434, "bids": [[1000.0, 35.81], [14255.1, 1.806], [14355.1, 2.394], [51724.1, 0.005], [58189.5, 0.002], [61421.3, 0.006], [61422.3, 0.006], [62068.8, 0.08], [63502.0, 0.0], [63655.1, 0.016], [64008.5, 0.003], [64636.9, 0.157], [64637.1, 0.0], [64646.2, 0.235], [64649.8, 1.547], [64651.4, 0.002], [64655.1, 61.163]], "asks": [[64655.2, 1.872], [64657.6, 0.012], [64657.8, 0.127], [64660.1, 0.016], [64661.9, 0.498], [64662.0, 0.597], [64662.1, 0.089], [64662.6, 0.085], [64662.7, 0.07], [64663.0, 0.133], [64676.3, 0.003], [64677.1, 0.616], [64678.1, 0.002], [64679.0, 1.05], [65301.8, 1.535], [65655.2, 0.0], [65948.3, 0.106]]}
{"kind": "depth", "E": 1787082395667, "U": 11315509068629, "u": 11315509077840, "recv_ms": 1787082395636, "bids": [[1000.0, 35.81], [14255.1, 2.52], [14355.1, 1.68], [51724.0, 0.0], [58189.5, 0.002], [58189.6, 0.005], [61422.3, 0.006], [62068.8, 0.08], [63362.0, 0.159], [63717.6, 4.387], [63911.6, 2.813], [64008.5, 0.001], [64515.0, 7.141], [64622.4, 1.196], [64630.1, 1.436], [64636.9, 0.003], [64651.4, 0.002], [64655.0, 0.063], [64655.1, 59.928]], "asks": [[64655.2, 1.346], [64655.3, 0.002], [64657.6, 0.012], [64660.3, 0.121], [64661.9, 0.498], [64662.0, 0.056], [64662.1, 0.63], [64663.0, 0.133], [64665.8, 0.598], [64671.4, 0.033], [64679.0, 0.509], [64679.7, 0.541], [64693.0, 0.028], [64701.6, 0.061], [64794.7, 5.402], [64850.5, 0.028], [65301.8, 1.529]]}
{"kind": "depth", "E": 1787082395769, "U": 11315509078024, "u": 11315509084973, "recv_ms": 1787082395741, "bids": [[1000.0, 35.81], [14255.1, 2.87], [14355.1, 1.33], [51724.0, 0.0], [58189.5, 0.002], [58189.6, 0.003], [61422.3, 0.006], [63655.1, 0.036], [63809.1, 0.076], [63846.9, 1.905], [63884.5, 7.505], [64008.5, 0.001], [64331.8, 0.311], [64515.0, 7.141], [64623.5, 0.026], [64630.1, 1.411], [64637.0, 0.043], [64641.1, 0.045], [64642.6, 1.248], [64644.1, 0.469], [64646.2, 0.243], [64649.9, 2.503], [64650.0, 0.177], [64651.5, 0.085], [64655.1, 61.906]], "asks": [[64657.6, 0.012], [64657.8, 0.127], [64659.1, 0.0], [64659.2, 0.838], [64659.4, 0.004], [64659.8, 0.09], [64660.4, 0.01], [64660.5, 2.403], [64661.4, 0.007], [64661.8, 0.021], [64662.1, 0.089], [64662.4, 1.092], [64663.0, 0.674], [64663.2, 0.291], [64665.6, 0.009], [64665.7, 0.02], [64665.8, 0.497], [64668.8, 0.008], [64670.0, 0.024], [64671.4, 0.041], [64674.1, 0.01], [64674.4, 0.003], [64675.1, 1.237], [64676.6, 0.05], [64677.2, 0.011], [64678.1, 0.059], [64679.4, 0.001], [64680.2, 6.5], [64681.4, 0.005], [64689.6, 1.055], [64697.5, 0.31], [64771.7, 0.0], [64794.7, 5.402], [64810.8, 0.001], [64836.7, 0.102], [64850.5, 0.028], [64862.6, 0.028], [64888.4, 0.199], [64914.3, 0.004], [65301.8, 1.529], [65463.4, 0.46], [65548.2, 0.914], [65591.5, 26.036], [65655.2, 0.02]]}
{"kind": "depth", "E": 1787082395871, "U": 11315509084985, "u": 11315509093729, "recv_ms": 1787082395842, "bids": [[14255.1, 3.234], [14355.1, 0.966], [58189.5, 0.002], [61422.3, 0.006], [62068.8, 0.083], [63362.0, 0.162], [63550.0, 4.193], [63655.1, 0.016], [63717.6, 5.484], [64008.5, 0.003], [64636.9, 0.003], [64639.0, 0.689], [64640.5, 0.135], [64641.7, 0.948], [64641.8, 0.06], [64642.1, 0.004], [64642.6, 0.322], [64644.4, 0.321], [64646.1, 0.773], [64646.2, 0.235], [64646.3, 0.628], [64647.3, 0.515], [64647.8, 0.033], [64651.5, 0.085], [64651.8, 0.439], [64655.1, 61.602]], "asks": [[64657.6, 0.012], [64659.1, 0.008], [64659.8, 0.006], [64660.0, 0.086], [64660.4, 0.01], [64661.5, 0.013], [64661.7, 0.087], [64661.8, 0.013], [64662.0, 0.011], [64662.1, 0.089], [64662.2, 0.294], [64662.3, 0.156], [64662.7, 0.006], [64662.9, 0.003], [64663.0, 0.636], [64663.2, 0.102], [64663.4, 0.087], [64663.5, 0.003], [64663.6, 0.002], [64663.7, 0.061], [64663.8, 0.425], [64665.7, 0.467], [64665.8, 0.135], [64666.3, 0.542], [64666.6, 0.002], [64667.2, 0.048], [64667.9, 0.104], [64668.0, 0.139], [64669.3, 0.309], [64670.9, 0.001], [64671.4, 0.033], [64672.2, 0.617], [64677.7, 0.001], [64685.1, 0.245], [64705.8, 0.104], [64717.9, 0.242], [64718.8, 0.046], [64850.5, 0.028], [64977.3, 4.358], [65301.8, 1.529], [65429.8, 27.301], [65655.2, 0.0], [65688.5, 16.724], [65948.3, 0.109]]}
{"kind": "depth", "E": 1787082396075, "U": 11315509101563, "u": 11315509107636, "recv_ms": 1787082396045, "bids": [[14155.1, 0.084], [14255.1, 3.78], [14355.1, 0.336], [58189.5, 0.002], [61421.3, 0.004], [61422.3, 0.006], [62068.8, 0.083], [63360.9, 0.014], [63944.6, 0.702], [64008.5, 0.001], [64035.1, 0.549], [64136.7, 9.531], [64331.8, 0.32], [64515.0, 7.079], [64636.1, 2.498], [64637.1, 0.0], [64638.7, 2.339], [64643.5, 0.002], [64651.5, 0.085], [64655.1, 59.87]], "asks": [[64657.6, 0.002], [64663.0, 0.636], [64663.1, 0.605], [64665.8, 0.135], [64666.6, 0.047], [64666.9, 0.052], [64667.5, 0.132], [64668.0, 0.289], [64668.1, 0.171], [64671.2, 0.005], [64674.6, 0.504], [64681.3, 2.338], [64684.6, 0.212], [64701.0, 0.527], [64705.4, 0.113], [64705.6, 1.308], [64705.9, 0.319], [64718.2, 2.377], [64718.5, 0.355], [64730.0, 0.761], [64741.0, 0.0], [64794.7, 5.402], [64850.5, 1.628], [64978.5, 0.464], [65301.8, 1.529], [65451.2, 3.025], [65548.1, 23.56], [65744.9, 1.579], [67886.7, 0.041]]}
{"kind": "depth", "E": 1787082396177, "U": 11315509107847, "u": 11315509115339, "recv_ms": 1787082396147, "bids": [[14155.1, 0.322], [14255.1, 3.654], [14355.1, 0.224], [51724.0, 0.0], [58189.5, 0.002], [62068.8, 0.08], [63655.1, 0.036], [63835.0, 7.821], [64008.5, 0.001], [64331.8, 0.321], [64525.7, 2.711], [64583.2, 1.818], [64594.4, 0.067], [64606.1, 0.007], [64606.2, 0.502], [64612.3, 0.11], [64612.4, 0.549], [64635.5, 0.001], [64636.0, 3.457], [64636.4, 3.468], [64636.8, 0.193], [64637.1, 0.0], [64646.4, 0.663], [64649.8, 1.006], [64651.5, 0.089], [64655.1, 59.87]], "asks": [[64655.2, 1.347], [64657.8, 0.127], [64661.1, 0.248], [64662.2, 0.287], [64665.8, 1.989], [64665.9, 2.361], [64666.9, 0.053], [64667.9, 0.274], [64668.1, 0.48], [64669.3, 0.0], [64669.6, 0.002], [64673.7, 0.93], [64675.1, 0.311], [64677.1, 0.059], [64677.4, 0.597], [64678.8, 0.121], [64679.6, 0.011], [64680.2, 6.384], [64681.0, 0.023], [64682.0, 0.003], [64682.4, 4.578], [64684.3, 0.0], [64684.5, 0.0], [64684.6, 0.002], [64684.8, 0.177], [64691.5, 0.016], [64705.7, 0.531], [64705.8, 0.274], [64718.8, 0.046], [64725.1, 0.01], [64978.5, 0.463], [65301.8, 1.529], [65655.2, 0.02], [65689.7, 1.49]]}
{"kind": "depth", "E": 1787082396279, "U": 11315509115451, "u": 11315509131554, "recv_ms": 1787082396257, "bids": [[1000.0, 35.81], [14155.1, 0.406], [14157.6, 0.154], [14255.1, 3.458], [14257.6, 0.084], [14355.1, 0.098], [51724.0, 0.0], [51726.0, 0.0], [58189.5, 0.0], [58191.8, 0.002], [61422.3, 0.006], [61424.7, 0.006], [63364.5, 0.004], [63655.1, 0.016], [63950.4, 1.567], [64008.5, 0.0], [64011.0, 0.065], [64040.9, 6.886], [64372.2, 0.0], [64443.1, 2.616], [64451.4, 0.004], [64460.8, 0.97], [64464.4, 2.385], [64464.8, 0.012], [64511.6, 0.366], [64517.1, 0.0], [64523.3, 0.233], [64526.9, 0.0], [64551.4, 0.037], [64552.5, 0.007], [64552.6, 0.015], [64553.6, 8.083], [64555.2, 1.188], [64556.8, 0.002], [64558.5, 2.35], [64568.6, 0.002], [64571.0, 0.386], [64571.1, 0.402], [64571.5, 1.274], [64571.9, 0.56], [64572.7, 2.524], [64573.1, 0.063], [64573.5, 2.867], [64574.0, 0.008], [64574.3, 0.38], [64574.7, 0.142], [64575.7, 0.0], [64575.9, 0.0], [64576.0, 0.007], [64576.7, 45.789], [64577.7, 1.2], [64577.9, 0.015], [64578.4, 0.204], [64579.2, 0.015], [64579.6, 0.001], [64580.3, 0.003], [64582.0, 2.754], [64589.2, 0.16], [64590.2, 0.04], [64592.0, 0.003], [64592.2, 0.033], [64592.9, 0.119], [64594.0, 0.002], [64597.5, 0.004], [64601.4, 0.001], [64601.6, 2.339], [64602.2, 0.351], [64603.2, 1.693], [64604.6, 1.663], [64605.1, 1.492], [64607.6, 0.057], [64608.1, 0.002], [64608.4, 0.0], [64609.0, 0.167], [64609.5, 0.005], [64609.8, 0.005], [64610.6, 0.015], [64610.8, 0.064], [64612.1, 1.912], [64612.9, 0.0], [64613.2, 0.0], [64616.7, 0.001], [64616.9, 0.018], [64619.4, 0.023], [64619.7, 0.315], [64620.0, 3.159], [64623.1, 1.613], [64623.4, 0.005], [64623.5, 0.0], [64623.9, 1.896], [64624.5, 0.159], [64625.0, 3.89], [64625.1, 0.07], [64626.0, 0.294], [64626.4, 0.069], [64626.9, 0.021], [64627.0, 0.01], [64627.1, 0.005], [64628.0, 0.781], [64628.6, 0.005], [64629.2, 0.128], [64629.3, 0.06], [64629.8, 0.48], [64630.1, 1.402], [64630.4, 1.269], [64630.7, 0.015], [64630.8, 0.234], [64630.9, 2.343], [64631.2, 0.123], [64631.3, 0.007], [64631.4, 0.543], [64631.8, 1.257], [64632.0, 1.699], [64632.1, 0.0], [64632.3, 0.014], [64632.5, 0.164], [64632.9, 0.002], [64633.0, 0.055], [64633.1, 2.525], [64633.2, 5.083], [64633.4, 0.501], [64633.6, 1.941], [64633.8, 0.157], [64634.1, 1.859], [64634.3, 0.001], [64635.0, 3.908], [64635.1, 0.002], [64635.2, 1.167], [64635.4, 0.083], [64635.5, 0.31], [64636.0, 3.341], [64636.4, 2.911], [64636.5, 0.495], [64636.6, 0.465], [64636.7, 1.869], [64636.9, 0.01], [64637.4, 0.0], [64637.5, 0.127], [64637.6, 0.815], [64637.7, 0.363], [64637.8, 0.561], [64637.9, 0.0], [64638.1, 0.018], [64638.2, 0.127], [64638.4, 0.696], [64638.5, 0.021], [64638.6, 0.002], [64638.8, 0.001], [64638.9, 0.003], [64639.0, 0.477], [64639.1, 0.365], [64640.3, 0.017], [64640.4, 1.004], [64640.8, 0.001], [64640.9, 0.173], [64641.1, 0.025], [64641.2, 0.085], [64641.4, 0.022], [64641.5, 0.155], [64641.6, 0.02], [64641.7, 0.022], [64642.1, 0.0], [64642.2, 0.217], [64642.5, 0.004], [64642.7, 0.002], [64642.8, 0.007], [64643.1, 1.626], [64643.3, 2.955], [64643.4, 0.003], [64643.5, 0.928], [64643.7, 0.002], [64643.9, 0.214], [64644.0, 0.503], [64644.1, 1.512], [64644.2, 0.004], [64644.3, 0.004], [64644.4, 0.313], [64644.6, 0.031], [64644.8, 0.986], [64644.9, 0.313], [64645.3, 0.011], [64645.4, 0.014], [64645.5, 0.293], [64645.6, 0.338], [64645.9, 2.398], [64646.1, 0.14], [64646.2, 0.244], [64646.3, 0.621], [64646.4, 0.123], [64646.5, 0.174], [64646.6, 0.102], [64647.0, 0.018], [64647.1, 0.275], [64647.4, 0.087], [64647.5, 0.393], [64647.7, 0.001], [64647.8, 0.053], [64647.9, 0.433], [64648.1, 0.033], [64648.7, 0.012], [64648.9, 0.007], [64649.0, 0.0], [64649.1, 0.002], [64649.3, 0.294], [64649.4, 0.101], [64649.6, 0.744], [64649.7, 2.34], [64649.9, 2.504], [64650.0, 0.393], [64650.1, 0.63], [64650.2, 0.852], [64650.7, 1.739], [64650.9, 0.007], [64651.0, 0.015], [64651.1, 0.119], [64651.2, 0.004], [64651.3, 0.003], [64651.5, 0.085], [64651.9, 0.002], [64652.0, 0.013], [64652.1, 0.394], [64652.4, 0.314], [64652.6, 0.001], [64652.8, 0.086], [64653.0, 0.004], [64653.1, 0.004], [64653.2, 0.085], [64653.4, 0.032], [64653.5, 0.002], [64653.6, 0.001], [64653.8, 0.912], [64653.9, 1.687], [64654.0, 3.504], [64654.1, 0.001], [64654.2, 0.422], [64654.3, 0.003], [64654.4, 0.001], [64654.6, 0.136], [64654.7, 0.001], [64654.8, 0.031], [64654.9, 0.133], [64655.0, 1.06], [64655.1, 7.701], [64655.2, 6.293], [64655.3, 0.036], [64655.4, 0.001], [64655.5, 0.437], [64655.8, 0.001], [64655.9, 0.0], [64656.0, 0.003], [64656.1, 0.086], [64656.2, 0.0], [64656.3, 0.001], [64656.4, 0.029], [64656.5, 0.0], [64656.6, 0.31], [64656.9, 0.1], [64657.0, 0.0], [64657.1, 0.0], [64657.2, 0.001], [64657.3, 0.003], [64657.4, 0.001], [64657.5, 0.006], [64657.6, 39.638]], "asks": [[64655.2, 0.0], [64655.3, 0.0], [64655.4, 0.0], [64655.5, 0.0], [64656.0, 0.0], [64656.2, 0.0], [64656.3, 0.0], [64656.4, 0.0], [64656.5, 0.0], [64656.6, 0.0], [64656.7, 0.0], [64656.8, 0.0], [64657.0, 0.0], [64657.2, 0.0], [64657.3, 0.0], [64657.4, 0.0], [64657.5, 0.0], [64657.6, 0.0], [64657.7, 1.07], [64657.8, 0.002], [64657.9, 0.001], [64658.0, 0.632], [64658.1, 0.002], [64658.4, 0.001], [64658.5, 0.0], [64658.6, 0.002], [64658.7, 0.001], [64658.9, 0.0], [64659.1, 0.0], [64659.2, 0.835], [64659.4, 0.005], [64659.5, 0.09], [64659.6, 0.066], [64659.8, 0.003], [64659.9, 0.003], [64660.0, 0.013], [64660.2, 0.001], [64660.3, 0.002], [64660.4, 2.322], [64660.5, 0.0], [64660.7, 0.026], [64660.9, 0.006], [64661.0, 0.001], [64661.1, 0.002], [64661.3, 0.0], [64661.4, 1.003], [64661.6, 0.006], [64661.7, 0.0], [64661.8, 0.01], [64661.9, 0.033], [64662.0, 0.013], [64662.1, 0.005], [64662.2, 0.135], [64662.3, 0.28], [64662.5, 0.005], [64662.6, 0.001], [64662.7, 0.004], [64662.9, 0.168], [64663.0, 0.088], [64663.1, 0.001], [64663.2, 0.102], [64663.3, 2.446], [64663.4, 0.023], [64663.7, 0.144], [64663.8, 0.341], [64664.0, 0.331], [64664.1, 0.345], [64664.3, 1.313], [64664.4, 0.001], [64664.5, 0.088], [64664.6, 0.01], [64664.8, 0.004], [64664.9, 0.089], [64665.0, 0.064], [64665.1, 0.025], [64665.2, 0.247], [64665.5, 0.013], [64665.6, 0.642], [64665.7, 0.017], [64665.8, 1.888], [64665.9, 2.364], [64666.0, 0.087], [64666.3, 0.626], [64666.5, 0.033], [64666.7, 0.085], [64666.9, 0.052], [64667.3, 0.001], [64667.4, 0.003], [64667.6, 0.387], [64668.1, 0.171], [64668.2, 0.001], [64668.4, 0.014], [64668.5, 0.002], [64669.1, 0.786], [64669.7, 0.35], [64670.0, 0.023], [64670.2, 0.147], [64670.4, 0.008], [64670.7, 0.005], [64670.9, 0.025], [64671.4, 0.573], [64671.5, 0.015], [64671.6, 2.631], [64671.7, 0.44], [64672.2, 0.597], [64672.3, 0.004], [64672.6, 0.465], [64672.7, 0.167], [64673.2, 0.116], [64673.4, 0.101], [64673.6, 0.996], [64673.7, 0.004], [64673.8, 0.083], [64673.9, 0.002], [64674.0, 0.121], [64674.2, 0.578], [64674.6, 0.35], [64674.7, 0.021], [64674.8, 0.041], [64675.0, 2.872], [64675.2, 0.01], [64675.9, 0.795], [64676.0, 0.001], [64676.1, 0.001], [64676.4, 0.001], [64676.5, 1.0], [64676.7, 0.247], [64676.9, 0.336], [64677.0, 0.154], [64677.1, 0.719], [64677.2, 0.018], [64677.3, 0.066], [64677.4, 0.04], [64677.9, 0.188], [64678.1, 0.002], [64678.3, 0.026], [64678.4, 0.227], [64678.5, 0.029], [64678.6, 0.008], [64678.7, 0.015], [64678.8, 0.005], [64679.0, 0.127], [64679.3, 0.31], [64679.5, 0.56], [64679.6, 0.011], [64679.7, 0.0], [64679.8, 0.001], [64680.0, 2.464], [64680.1, 0.503], [64680.3, 0.163], [64680.5, 0.005], [64680.7, 0.0], [64680.9, 0.062], [64681.2, 0.541], [64681.3, 2.336], [64681.4, 0.121], [64681.6, 1.746], [64681.7, 0.246], [64682.5, 0.157], [64682.6, 0.049], [64682.7, 0.006], [64683.0, 0.024], [64683.2, 1.147], [64683.3, 0.004], [64683.4, 1.244], [64683.6, 0.434], [64683.7, 0.984], [64683.8, 0.112], [64684.1, 0.014], [64684.5, 0.154], [64684.8, 0.007], [64685.0, 0.206], [64685.1, 0.252], [64685.2, 0.098], [64685.7, 0.005], [64685.9, 1.399], [64686.0, 0.262], [64686.9, 0.007], [64687.0, 0.107], [64687.2, 2.319], [64687.4, 0.018], [64687.6, 3.89], [64688.0, 0.037], [64688.5, 0.071], [64688.6, 0.207], [64689.2, 0.027], [64690.8, 0.18], [64690.9, 0.002], [64691.1, 0.109], [64691.2, 0.448], [64691.3, 3.093], [64691.5, 0.014], [64692.5, 0.027], [64692.8, 1.034], [64693.3, 0.002], [64694.5, 0.07], [64694.7, 0.502], [64694.8, 0.004], [64695.6, 0.009], [64695.7, 0.701], [64696.1, 0.064], [64696.2, 0.023], [64696.7, 1.241], [64696.8, 0.003], [64697.3, 0.083], [64697.7, 0.001], [64698.6, 0.003], [64698.7, 0.048], [64698.9, 0.086], [64699.1, 0.051], [64699.8, 2.395], [64700.2, 0.116], [64700.7, 0.075], [64701.0, 0.5], [64702.1, 0.033], [64702.2, 0.628], [64703.0, 0.335], [64703.8, 0.037], [64705.1, 2.368], [64705.2, 0.341], [64705.5, 0.0], [64705.6, 1.239], [64706.1, 2.098], [64706.3, 0.003], [64707.4, 0.037], [64707.5, 0.031], [64709.3, 0.57], [64711.1, 0.211], [64714.3, 2.146], [64714.4, 0.002], [64714.5, 0.626], [64714.9, 0.003], [64715.1, 0.059], [64715.9, 0.025], [64721.3, 0.043], [64721.7, 0.001], [64722.1, 0.202], [64723.3, 7.239], [64726.2, 40.349], [64726.5, 0.059], [64728.1, 0.012], [64728.3, 0.002], [64729.7, 2.322], [64732.0, 0.001], [64732.1, 0.026], [64733.0, 1.361], [64733.1, 3.8], [64734.0, 0.004], [64734.3, 0.003], [64736.0, 0.006], [64738.0, 0.001], [64740.6, 1.504], [64743.4, 2.338], [64744.2, 0.0], [64752.3, 0.001], [64754.0, 0.831], [64754.9, 0.011], [64755.7, 0.001], [64766.4, 1.397], [64767.2, 0.0], [64767.6, 0.142], [64771.5, 1.714], [64771.8, 0.023], [64772.5, 0.014], [64777.3, 0.001], [64778.2, 2.331], [64779.0, 0.454], [64779.1, 4.899], [64779.3, 2.142], [64779.4, 0.006], [64780.3, 2.448], [64786.3, 0.001], [64791.5, 0.39], [64794.1, 0.38], [64843.6, 0.0], [64845.1, 0.976], [64845.2, 0.82], [64848.4, 0.077], [64849.9, 0.002], [64851.0, 0.021], [64855.0, 5.754], [64908.4, 0.0], [64915.6, 0.001], [64972.9, 0.001], [64980.3, 0.001], [65037.7, 0.0], [65044.9, 0.001], [65102.2, 0.001], [65109.6, 0.001], [65166.9, 0.021], [65174.3, 0.012], [65301.8, 1.678], [65304.3, 0.377], [65315.9, 0.0], [65398.9, 0.623], [65399.2, 0.0], [65401.8, 14.726], [65463.8, 0.0], [65466.5, 8.316], [65591.5, 24.97], [65655.2, 0.0], [65710.6, 0.0], [65754.3, 1.521], [65950.8, 0.003]]}
{"kind": "depth", "E": 1787082396381, "U": 11315509131581, "u": 11315509140466, "recv_ms": 1787082396358, "bids": [[14157.6, 0.406], [14255.1, 3.22], [14257.6, 0.168], [14355.1, 0.0], [58191.8, 0.002], [61424.7, 0.005], [62071.2, 0.003], [63364.5, 0.013], [63846.9, 2.687], [64011.0, 0.067], [64137.9, 0.715], [64281.8, 0.0], [64331.8, 0.321], [64471.5, 3.0], [64495.6, 0.006], [64522.4, 0.396], [64526.8, 0.0], [64548.2, 0.052], [64548.5, 0.001], [64553.6, 1.286], [64556.9, 0.006], [64572.3, 0.0], [64574.5, 47.348], [64575.2, 0.45], [64576.7, 0.073], [64576.8, 0.781], [64596.9, 0.021], [64598.7, 0.006], [64603.2, 1.653], [64604.4, 0.114], [64608.3, 0.045], [64609.6, 1.579], [64613.4, 0.0], [64613.9, 0.012], [64614.2, 1.891], [64614.7, 0.002], [64614.8, 0.001], [64617.2, 0.076], [64619.1, 0.506], [64622.9, 0.013], [64623.1, 1.623], [64624.0, 0.918], [64624.1, 0.007], [64626.7, 1.99], [64626.8, 0.353], [64629.8, 0.52], [64630.0, 3.112], [64634.3, 0.45], [64634.4, 0.001], [64635.8, 0.06], [64636.9, 0.01], [64639.0, 0.266], [64640.6, 1.472], [64640.7, 0.162], [64642.7, 0.213], [64643.9, 0.216], [64644.7, 0.989], [64644.8, 0.814], [64645.5, 0.213], [64646.1, 0.148], [64646.2, 0.236], [64647.0, 0.016], [64648.1, 0.113], [64649.5, 1.706], [64649.8, 0.006], [64650.0, 0.161], [64650.7, 1.311], [64651.0, 0.017], [64652.0, 0.012], [64653.1, 0.004], [64653.9, 1.686], [64654.0, 3.505], [64654.3, 0.004], [64654.8, 0.013], [64654.9, 0.134], [64655.1, 7.661], [64655.3, 0.036], [64656.0, 0.081], [64656.6, 0.33], [64656.7, 0.005], [64656.9, 0.102], [64657.2, 0.019], [64657.6, 40.942]], "asks": [[64657.7, 1.072], [64657.8, 0.0], [64657.9, 0.002], [64658.1, 0.0], [64659.2, 0.61], [64659.5, 0.1], [64659.6, 0.076], [64660.2, 0.001], [64660.3, 0.012], [64662.1, 0.008], [64662.2, 0.127], [64662.3, 2.222], [64663.2, 2.176], [64665.0, 0.066], [64665.5, 0.005], [64668.5, 0.0], [64668.9, 0.001], [64669.2, 0.886], [64669.8, 0.009], [64670.2, 0.145], [64670.7, 0.007], [64670.9, 0.001], [64671.4, 0.11], [64671.5, 0.023], [64672.6, 0.676], [64672.7, 0.162], [64673.5, 1.087], [64674.5, 0.606], [64674.6, 0.349], [64674.8, 0.52], [64675.8, 1.207], [64677.1, 0.72], [64677.3, 0.026], [64677.7, 0.001], [64678.0, 0.165], [64678.1, 0.002], [64678.3, 0.006], [64679.0, 0.163], [64679.1, 2.303], [64680.5, 0.003], [64680.8, 0.063], [64681.6, 1.749], [64683.8, 0.121], [64687.6, 3.921], [64688.8, 0.098], [64688.9, 0.853], [64697.9, 0.169], [64698.5, 0.001], [64706.7, 7.237], [64706.8, 0.0], [64710.6, 4.251], [64711.2, 1.906], [64713.4, 0.31], [64713.7, 0.03], [64716.6, 0.001], [64716.7, 0.026], [64716.9, 0.382], [64717.0, 0.477], [64717.1, 0.0], [64718.3, 0.001], [64720.8, 2.381], [64724.0, 0.001], [64725.1, 0.001], [64726.1, 0.0], [64726.2, 2.32], [64726.7, 1.666], [64727.4, 0.448], [64727.5, 0.224], [64728.3, 38.031], [64737.7, 3.793], [64737.8, 0.019], [64756.8, 2.828], [64770.3, 1.087], [64773.7, 0.0], [64785.7, 0.015], [64799.9, 0.138], [64821.1, 1.466], [64821.2, 0.084], [64828.2, 0.004], [64831.4, 0.374], [64835.0, 1.466], [64835.1, 0.391], [65304.3, 0.377], [65451.1, 7.77], [65947.0, 0.145], [65950.8, 0.006]]}
{"kind": "depth", "E": 1787082396483, "U": 11315509140470, "u": 11315509151033, "recv_ms": 1787082396454, "bids": [[14157.6, 0.77], [14255.1, 2.982], [14257.6, 0.042], [51726.1, 0.0], [58191.8, 0.002], [61424.7, 0.005], [62071.2, 0.0], [63360.9, 0.011], [63362.0, 0.168], [63364.5, 0.019], [63456.8, 0.475], [63657.6, 0.02], [63804.7, 0.784], [64006.4, 0.479], [64006.7, 0.001], [64011.0, 0.069], [64035.1, 0.004], [64040.9, 7.431], [64281.2, 0.791], [64385.6, 0.002], [64534.2, 0.095], [64538.7, 0.449], [64572.3, 0.0], [64574.5, 1.632], [64576.7, 45.789], [64609.0, 0.164], [64610.4, 3.643], [64611.3, 1.163], [64614.4, 0.033], [64614.7, 0.08], [64615.2, 2.309], [64615.4, 0.006], [64619.4, 0.022], [64623.1, 1.613], [64623.5, 0.01], [64633.8, 0.042], [64635.0, 3.793], [64636.0, 2.441], [64636.3, 1.19], [64636.9, 0.01], [64637.9, 0.0], [64638.3, 0.016], [64639.0, 0.231], [64639.5, 0.025], [64643.0, 3.315], [64643.5, 0.002], [64643.7, 0.003], [64645.5, 0.293], [64646.2, 0.271], [64646.8, 0.008], [64647.0, 0.916], [64648.1, 0.033], [64651.5, 0.086], [64652.8, 0.087], [64653.0, 0.004], [64653.1, 0.004], [64653.9, 1.677], [64654.6, 0.135], [64654.9, 0.127], [64655.0, 1.059], [64655.1, 4.58], [64655.2, 5.586], [64655.3, 0.09], [64656.0, 0.081], [64656.7, 0.028], [64657.0, 0.001], [64657.4, 0.008], [64657.6, 43.941]], "asks": [[64657.7, 1.573], [64657.8, 0.002], [64659.2, 0.84], [64659.6, 0.076], [64660.3, 0.012], [64661.3, 0.008], [64662.1, 0.0], [64662.2, 0.251], [64662.3, 2.222], [64662.6, 0.085], [64664.1, 0.347], [64664.2, 0.197], [64665.7, 0.015], [64666.7, 0.311], [64672.2, 0.598], [64673.2, 0.001], [64674.2, 0.463], [64675.0, 3.798], [64676.5, 0.074], [64677.0, 0.155], [64680.1, 1.044], [64681.2, 0.0], [64682.5, 0.143], [64688.5, 0.071], [64688.6, 0.207], [64691.3, 1.442], [64692.8, 1.033], [64693.8, 0.061], [64696.7, 1.356], [64696.9, 12.631], [64698.3, 0.117], [64716.9, 0.372], [64717.3, 0.011], [64720.4, 0.001], [64726.2, 40.349], [64728.3, 0.002], [64831.4, 0.373], [65302.3, 0.0], [65304.3, 0.373], [65304.9, 0.38], [65401.3, 2.381], [65457.5, 1.013], [65465.9, 0.686], [65595.2, 1.068], [65657.7, 0.04], [67886.7, 0.037]]}
{"kind": "depth", "E": 1787082396585, "U": 11315509151110, "u": 11315509161664, "recv_ms": 1787082396554, "bids": [[1000.0, 35.81], [14157.6, 1.12], [14255.1, 2.674], [14257.6, 0.0], [51724.0, 0.0], [58191.8, 0.002], [61424.7, 0.005], [62071.2, 0.003], [63362.0, 0.156], [63364.5, 0.025], [64011.0, 0.065], [64596.9, 0.024], [64622.3, 0.0], [64622.4, 1.194], [64622.5, 0.002], [64623.5, 0.0], [64623.9, 1.906], [64625.7, 0.025], [64625.8, 0.076], [64625.9, 0.001], [64629.2, 0.107], [64636.6, 0.542], [64639.5, 0.024], [64642.5, 0.93], [64643.0, 2.389], [64643.8, 0.025], [64649.5, 1.474], [64650.0, 0.393], [64650.3, 0.797], [64651.5, 0.085], [64653.1, 0.004], [64654.2, 0.374], [64654.8, 0.012], [64655.0, 1.004], [64655.1, 1.638], [64655.2, 4.961], [64655.3, 0.074], [64656.0, 0.004], [64656.4, 0.007], [64657.0, 0.023], [64657.6, 46.582]], "asks": [[64659.6, 0.076], [64660.1, 0.016], [64660.3, 0.002], [64661.3, 0.0], [64662.1, 0.008], [64669.7, 0.348], [64672.2, 0.597], [64688.6, 0.053], [64688.7, 0.155], [64700.5, 0.002], [64703.0, 0.338], [64715.9, 0.022], [64717.3, 0.001], [64717.6, 2.102], [64750.6, 0.13], [64850.5, 0.028], [64853.0, 1.42], [65304.3, 0.375], [65423.4, 7.328], [65451.1, 7.512], [65591.5, 23.904], [65656.1, 14.298], [65744.9, 1.29], [65948.3, 0.103], [66073.8, 0.648]]}
{"kind": "depth", "E": 1787082396687, "U": 11315509161707, "u": 11315509174869, "recv_ms": 1787082396663, "bids": [[14157.6, 1.484], [14255.1, 2.31], [58191.8, 0.002], [61424.7, 0.005], [62071.2, 0.0], [63362.0, 0.15], [63364.5, 0.028], [63657.6, 0.0], [63716.4, 18.575], [63910.4, 6.018], [64011.0, 0.065], [64331.8, 0.311], [64334.3, 0.003], [64534.8, 0.143], [64537.3, 0.036], [64541.9, 0.247], [64544.4, 2.833], [64548.9, 0.002], [64551.4, 0.05], [64554.2, 0.003], [64554.8, 0.015], [64556.0, 0.047], [64558.5, 2.363], [64563.0, 0.002], [64565.5, 0.017], [64570.1, 0.006], [64572.6, 0.028], [64577.1, 0.001], [64579.6, 0.014], [64584.2, 2.336], [64586.7, 0.053], [64648.0, 0.63], [64649.6, 0.992], [64650.3, 0.171], [64651.2, 0.012], [64653.1, 0.004], [64655.0, 1.005], [64655.1, 1.634], [64655.3, 0.066], [64657.6, 46.985]], "asks": [[64657.7, 1.764], [64658.5, 0.079], [64659.4, 0.003], [64659.5, 0.001], [64659.6, 0.076], [64660.3, 0.014], [64661.3, 0.002], [64662.1, 0.008], [64663.1, 0.062], [64663.5, 0.005], [64664.1, 0.345], [64665.7, 0.1], [64671.4, 0.033], [64671.5, 0.015], [64672.7, 0.101], [64688.7, 0.001], [64688.8, 0.252], [64700.8, 0.158], [64707.2, 0.062], [64845.2, 0.817], [64845.7, 0.004], [64852.4, 0.655], [64853.0, 0.859], [65301.8, 1.529], [65304.3, 0.373], [65396.8, 0.764], [65427.1, 1.673], [65484.2, 0.0], [65562.9, 0.184], [65595.2, 2.134], [65657.7, 0.02], [65659.9, 1.065], [65948.3, 0.1], [65950.8, 0.009]]}
{"kind": "depth", "E": 1787082396789, "U": 11315509175249, "u": 11315509185009, "recv_ms": 1787082396762, "bids": [[14157.6, 1.834], [14255.1, 1.96], [58191.8, 0.002], [61424.7, 0.005], [63034.8, 0.002], [63362.0, 0.147], [63364.5, 0.031], [63619.4, 3.737], [63846.9, 3.038], [64011.0, 0.065], [64140.3, 0.126], [64576.7, 0.073], [64578.9, 45.719], [64612.7, 0.015], [64621.5, 0.002], [64623.9, 1.896], [64624.1, 0.017], [64624.7, 0.003], [64624.8, 0.084], [64624.9, 0.143], [64628.2, 0.004], [64628.3, 0.004], [64628.4, 0.072], [64633.3, 0.318], [64634.4, 0.001], [64635.5, 0.001], [64636.9, 0.01], [64637.3, 0.62], [64639.3, 0.004], [64640.7, 0.182], [64640.8, 0.001], [64641.5, 0.135], [64641.6, 0.018], [64641.8, 0.986], [64642.5, 0.004], [64643.1, 1.633], [64643.4, 0.475], [64644.7, 0.989], [64644.8, 0.35], [64645.3, 0.004], [64645.5, 0.293], [64646.1, 0.14], [64646.4, 0.215], [64646.5, 0.715], [64646.7, 0.177], [64647.8, 0.053], [64648.0, 0.005], [64648.9, 0.0], [64649.3, 0.526], [64649.6, 1.533], [64649.7, 2.341], [64649.9, 2.813], [64650.0, 0.163], [64650.2, 0.311], [64650.3, 0.172], [64650.4, 0.004], [64651.1, 0.12], [64651.2, 0.004], [64652.1, 0.085], [64653.1, 0.004], [64653.3, 1.013], [64653.4, 0.029], [64654.9, 0.126], [64655.0, 1.004], [64655.1, 1.695], [64655.2, 3.963], [64655.3, 0.004], [64655.6, 0.002], [64656.5, 0.084], [64656.6, 0.02], [64656.7, 0.005], [64657.3, 0.0], [64657.4, 0.01], [64657.5, 0.029], [64657.6, 43.466]], "asks": [[64657.7, 5.269], [64658.7, 0.0], [64659.6, 0.079], [64660.0, 0.021], [64660.1, 1.1], [64660.3, 0.014], [64661.3, 0.002], [64661.4, 0.003], [64661.6, 0.09], [64661.7, 0.007], [64662.0, 0.021], [64662.1, 0.549], [64662.2, 0.127], [64662.9, 0.165], [64663.1, 0.379], [64663.2, 0.102], [64664.4, 0.024], [64664.6, 0.003], [64665.1, 0.003], [64665.6, 0.01], [64665.7, 0.015], [64665.8, 1.891], [64666.0, 0.003], [64666.3, 0.542], [64671.4, 0.033], [64671.5, 1.26], [64673.0, 0.1], [64674.1, 0.134], [64674.5, 0.604], [64674.8, 0.512], [64675.0, 3.8], [64675.5, 0.008], [64678.2, 2.327], [64678.5, 0.022], [64678.9, 0.623], [64679.0, 0.704], [64680.1, 0.503], [64680.8, 0.061], [64688.7, 0.001], [64688.8, 0.098], [64689.0, 10.555], [64693.0, 0.028], [64696.9, 2.631], [64698.8, 0.159], [64699.4, 0.002], [64702.1, 0.029], [64717.6, 2.092], [64717.9, 0.252], [64726.2, 2.32], [64728.4, 38.046], [64768.6, 0.117], [65304.3, 0.373], [65354.1, 0.61], [65429.8, 25.47], [65688.5, 15.66], [65948.3, 0.094]]}
{"kind": "depth", "E": 1787082396891, "U": 11315509185267, "u": 11315509196580, "recv_ms": 1787082396864, "bids": [[1000.0, 35.81], [14157.6, 2.198], [14255.1, 1.596], [58191.8, 0.002], [61424.7, 0.005], [62071.2, 0.003], [63258.2, 2.383], [63362.0, 0.141], [63657.6, 0.02], [63717.6, 6.581], [63911.6, 3.751], [64011.0, 0.065], [64545.1, 0.017], [64550.5, 0.633], [64629.3, 0.01], [64631.7, 0.041], [64636.5, 0.545], [64637.3, 0.001], [64642.6, 0.324], [64648.3, 0.004], [64652.3, 0.005], [64652.5, 0.001], [64653.1, 0.001], [64654.9, 0.026], [64655.0, 1.003], [64656.3, 0.003], [64656.6, 0.0], [64656.9, 0.122], [64657.1, 0.31], [64657.4, 0.031], [64657.5, 0.03], [64657.6, 42.772]], "asks": [[64657.7, 6.808], [64662.5, 0.007], [64662.9, 0.165], [64663.0, 0.088], [64663.1, 0.372], [64663.5, 0.003], [64664.1, 0.367], [64666.9, 0.072], [64671.4, 0.033], [64671.5, 0.648], [64674.7, 0.009], [64674.8, 0.504], [64677.0, 0.212], [64678.9, 0.004], [64679.0, 0.647], [64687.1, 0.116], [64688.6, 0.053], [64699.8, 2.381], [64706.9, 0.015], [64715.9, 0.025], [64721.8, 0.021], [64725.0, 0.111], [64726.1, 38.029], [64728.4, 0.017], [64773.9, 0.087], [64810.4, 0.805], [64811.7, 0.022], [64814.1, 1.931], [64814.2, 7.011], [64814.3, 0.163], [64814.9, 0.019], [64849.8, 0.0], [64853.0, 5.527], [65304.3, 0.375], [65451.1, 7.254], [65465.9, 1.449], [65657.7, 0.04], [65948.3, 0.091], [65950.8, 0.012]]}
{"kind": "depth", "E": 1787082396993, "U": 11315509196611, "u": 11315509202771, "recv_ms": 1787082396962, "bids": [[14157.6, 2.562], [14255.1, 1.232], [58191.8, 0.002], [61424.7, 0.005], [62071.2, 0.0], [63362.0, 0.138], [64011.0, 0.065], [64334.3, 0.004], [64624.1, 0.007], [64624.4, 0.01], [64647.4, 0.089], [64647.8, 0.061], [64650.3, 0.164], [64653.9, 1.662], [64657.6, 42.385]], "asks": [[64662.2, 0.127], [64671.4, 0.04], [64671.5, 0.641], [64688.8, 0.252], [64717.9, 0.242], [64718.1, 0.113], [64814.2, 10.415], [64853.0, 1.608], [64978.5, 0.462], [65304.3, 0.373], [65362.5, 0.689], [65433.6, 1.837]]}
{"kind": "depth", "E": 1787082397095, "U": 11315509202833, "u": 11315509210299, "recv_ms": 1787082397065, "bids": [[1000.0, 35.96], [14157.6, 2.912], [14255.1, 0.882], [58191.8, 0.002], [61424.7, 0.006], [62071.2, 0.003], [63362.0, 0.135], [63623.1, 1.099], [63651.4, 0.012], [63657.6, 0.0], [63910.4, 5.08], [64011.0, 0.065], [64572.3, 0.0], [64578.9, 46.157], [64631.7, 0.023], [64636.6, 0.465], [64638.7, 2.337], [64641.2, 0.087], [64642.5, 0.006], [64646.0, 2.915], [64647.8, 0.053], [64648.0, 0.008], [64650.0, 0.171], [64650.6, 0.375], [64650.8, 0.0], [64651.3, 0.0], [64653.3, 1.167], [64655.0, 1.003], [64655.1, 1.662], [64656.5, 0.129], [64656.9, 0.144], [64657.0, 0.001], [64657.1, 0.33], [64657.4, 0.011], [64657.5, 0.061], [64657.6, 42.281]], "asks": [[64657.7, 6.665], [64659.6, 0.018], [64659.7, 0.086], [64660.1, 1.1], [64661.3, 0.0], [64662.0, 0.082], [64662.2, 0.134], [64663.3, 2.693], [64664.0, 0.373], [64664.1, 0.345], [64664.2, 0.197], [64664.9, 0.324], [64665.0, 0.046], [64665.2, 0.163], [64666.5, 0.283], [64667.1, 0.384], [64668.2, 0.251], [64670.6, 0.0], [64671.2, 0.003], [64671.4, 0.033], [64671.5, 0.641], [64673.5, 1.211], [64673.7, 0.006], [64674.1, 0.01], [64724.0, 0.001], [64725.0, 0.102], [64726.1, 0.0], [64728.3, 37.598], [64967.7, 0.233], [64969.1, 0.154], [65304.3, 0.373], [65591.5, 22.838], [65656.4, 0.01], [65657.7, 0.02], [65692.2, 1.084], [65948.3, 0.088], [65950.8, 0.015]]}
{"kind": "depth", "E": 1787082397197, "U": 11315509210365, "u": 11315509217803, "recv_ms": 1787082397166, "bids": [[1000.0, 35.81], [14157.6, 3.262], [14255.1, 0.532], [58191.8, 0.002], [61422.3, 0.004], [61422.4, 2.462], [61424.7, 0.005], [62071.2, 0.0], [63480.9, 0.787], [63655.1, 0.033], [63835.0, 7.587], [64011.0, 0.065], [64136.7, 8.597], [64331.8, 0.31], [64515.0, 1.716], [64528.2, 0.002], [64581.6, 0.084], [64585.8, 4.274], [64608.8, 0.004], [64614.9, 0.063], [64624.4, 0.0], [64624.5, 0.169], [64636.7, 1.985], [64637.1, 0.557], [64637.5, 0.011], [64637.8, 0.004], [64639.5, 0.022], [64643.2, 0.133], [64646.1, 0.217], [64646.2, 0.27], [64646.4, 0.138], [64649.5, 1.783], [64649.9, 2.504], [64652.8, 0.09], [64655.0, 1.004]], "asks": [[64657.7, 6.667], [64659.3, 0.005], [64662.2, 0.127], [64662.5, 0.005], [64663.0, 0.636], [64665.7, 0.015], [64667.7, 0.102], [64668.5, 0.309], [64671.5, 0.1], [64671.6, 2.322], [64675.2, 0.012], [64677.3, 0.583], [64679.0, 0.106], [64679.5, 0.119], [64679.8, 0.542], [64681.4, 0.005], [64718.1, 0.103], [64718.3, 0.011], [64724.0, 0.001], [64726.1, 37.596], [64728.3, 0.002], [64794.7, 0.0], [65304.3, 0.373], [66265.3, 0.226]]}
{"kind": "depth", "E": 1787082397299, "U": 11315509218148, "u": 11315509224585, "recv_ms": 1787082397270, "bids": [[14157.6, 3.346], [14255.1, 0.308], [14557.6, 0.14], [51726.0, 0.0], [58191.8, 0.002], [61424.7, 0.007], [62872.3, 0.009], [63657.6, 0.02], [63892.9, 0.0], [63901.1, 0.548], [63911.6, 4.689], [64011.0, 0.065], [64334.3, 0.004], [64459.2, 0.012], [64498.0, 0.593], [64498.2, 0.742], [64624.5, 0.159], [64624.7, 0.013], [64631.8, 1.246], [64647.8, 0.061], [64649.3, 0.294], [64650.0, 0.163], [64652.2, 0.235], [64655.0, 1.003], [64656.8, 0.002], [64657.4, 0.033], [64657.6, 42.281]], "asks": [[64657.7, 7.854], [64659.2, 0.841], [64660.0, 0.023], [64660.1, 1.1], [64661.7, 0.009], [64662.2, 0.129], [64662.3, 0.156], [64662.9, 0.168], [64663.0, 0.636], [64663.7, 0.167], [64663.8, 0.341], [64663.9, 0.222], [64664.0, 0.351], [64665.7, 0.023], [64668.6, 2.76], [64671.5, 0.092], [64673.4, 0.116], [64681.6, 1.748], [64704.7, 0.002], [64709.5, 0.001], [64718.3, 0.001], [64718.4, 1.119], [64766.7, 0.003], [64814.1, 0.0], [64814.2, 0.001], [64853.0, 0.0], [64981.0, 0.121], [65105.8, 0.014], [65304.3, 0.373], [65387.2, 0.002], [65433.6, 2.051], [65490.1, 0.059], [65657.7, 0.04], [65660.2, 1.321], [65950.8, 0.018]]}
{"kind": "depth", "E": 1787082397401, "U": 11315509224771, "u": 11315509230008, "recv_ms": 1787082397371, "bids": [[1000.0, 35.81], [14157.6, 3.22], [14255.1, 0.196], [14557.6, 0.378], [51726.0, 0.0], [58191.8, 0.0], [61424.7, 0.007], [62071.2, 0.003], [63248.1, 0.0], [63249.1, 0.035], [63737.4, 0.642], [63922.4, 0.001], [64011.0, 0.065], [64458.8, 11.379], [64497.6, 9.785], [64498.2, 2.126], [64514.6, 5.915], [64624.7, 0.003], [64624.8, 0.094], [64631.7, 0.041], [64656.5, 0.084], [64656.7, 0.045], [64656.9, 0.124], [64657.6, 42.282]], "asks": [[64657.7, 7.9], [64662.5, 0.003], [64663.0, 0.638], [64665.7, 0.015], [64671.5, 0.1], [64688.7, 0.001], [64688.8, 0.098], [64718.4, 1.109], [64718.6, 0.01], [64723.9, 37.596], [64726.1, 0.0], [64797.2, 5.401], [64814.2, 10.415], [64853.0, 5.475], [65304.3, 0.373], [65362.9, 0.0], [65427.6, 0.001], [65595.2, 3.2]]}
{"kind": "depth", "E": 1787082397503, "U": 11315509230030, "u": 11315509235978, "recv_ms": 1787082397473, "bids": [[1000.0, 35.81], [14157.6, 3.108], [14255.1, 0.07], [14557.6, 0.616], [51726.1, 0.0], [58191.8, 0.002], [61421.3, 0.002], [62071.2, 0.0], [63745.9, 0.782], [63823.5, 0.516], [64011.0, 0.065], [64140.3, 1.06], [64514.6, 7.406], [64624.8, 0.084], [64624.9, 0.153]], "asks": [[64660.1, 1.1], [64667.2, 0.05], [64686.7, 0.003], [64688.7, 0.001], [64688.8, 0.252], [64718.6, 0.0], [64718.7, 0.02], [64853.0, 0.838], [65304.3, 0.373], [65451.1, 6.995], [66274.1, 0.528]]}
{"kind": "depth", "E": 1787082397605, "U": 11315509236110, "u": 11315509243309, "recv_ms": 1787082397575, "bids": [[14157.6, 2.898], [14255.1, 0.0], [14557.6, 0.896], [58191.8, 0.002], [61424.7, 0.007], [62071.2, 0.003], [63657.6, 0.0], [63716.4, 17.478], [63867.3, 18.391], [64011.0, 0.065], [64334.3, 0.004], [64514.6, 2.001], [64574.5, 1.632], [64576.7, 46.227], [64578.9, 0.003], [64608.3, 0.041], [64624.7, 0.043], [64629.8, 0.48], [64640.4, 1.024], [64640.7, 0.162], [64641.4, 0.145], [64652.2, 0.003], [64652.8, 0.322], [64654.3, 0.066], [64655.1, 1.6], [64655.5, 0.44], [64656.1, 0.002], [64656.5, 0.0], [64657.1, 0.02], [64657.5, 0.062], [64657.6, 41.762]], "asks": [[64657.7, 13.022], [64658.1, 0.31], [64658.4, 0.085], [64664.5, 0.091], [64664.9, 0.24], [64666.9, 0.069], [64667.7, 0.101], [64668.4, 1.251], [64670.7, 1.862], [64687.9, 0.539], [64688.8, 0.098], [64688.9, 1.007], [64701.2, 0.0], [64707.7, 6.289], [64714.1, 0.0], [64720.6, 0.371], [64722.4, 0.009], [64797.2, 0.0], [65304.3, 0.373], [65499.0, 3.165], [65657.7, 0.02], [71123.5, 0.001]]}
{"kind": "depth", "E": 1787082397707, "U": 11315509243392, "u": 11315509252357, "recv_ms": 1787082397680, "bids": [[1000.0, 35.81], [14157.6, 2.534], [14557.6, 1.26], [58191.8, 0.002], [61424.7, 0.007], [63362.0, 0.132], [63364.5, 0.034], [63587.1, 3.487], [63878.1, 23.364], [63935.4, 0.0], [64011.0, 0.065], [64514.6, 7.405], [64576.7, 0.073], [64578.9, 46.157], [64596.8, 1.462], [64603.6, 0.294], [64606.2, 0.527], [64612.0, 0.688], [64622.1, 0.122], [64623.9, 1.871], [64624.0, 1.254], [64624.9, 0.143], [64625.0, 3.9], [64625.1, 0.127], [64626.0, 0.237], [64627.9, 0.0], [64629.0, 0.904], [64632.6, 0.315], [64633.2, 0.083], [64633.3, 0.009], [64636.0, 2.557], [64636.3, 1.197], [64636.4, 3.468], [64636.7, 1.869], [64636.9, 0.003], [64637.1, 0.0], [64637.7, 0.027], [64638.6, 0.003], [64639.7, 0.52], [64641.2, 1.013], [64641.4, 0.225], [64641.8, 0.06], [64642.1, 0.007], [64643.1, 1.586], [64643.2, 0.132], [64643.4, 0.467], [64644.1, 1.047], [64644.2, 0.469], [64645.3, 0.324], [64645.5, 0.213], [64645.7, 0.012], [64646.1, 0.241], [64646.2, 0.27], [64646.3, 0.301], [64646.4, 0.138], [64646.7, 0.17], [64646.8, 0.0], [64647.1, 0.816], [64647.2, 0.071], [64647.8, 0.053], [64648.6, 0.068], [64648.7, 0.172], [64648.8, 0.314], [64649.3, 0.314], [64649.5, 0.237], [64649.6, 0.868], [64649.7, 0.003], [64650.0, 0.163], [64650.2, 0.001], [64650.3, 0.156], [64650.4, 0.088], [64650.7, 0.844], [64651.1, 0.117], [64651.7, 0.0], [64651.8, 0.279], [64652.3, 0.001], [64652.5, 0.999], [64652.8, 0.087], [64653.3, 0.169], [64653.6, 0.003], [64653.9, 1.663], [64654.2, 0.001], [64654.3, 0.004], [64654.4, 0.004], [64654.6, 0.051], [64655.0, 1.003], [64655.1, 1.519], [64655.2, 3.963], [64655.3, 0.001], [64655.6, 0.044], [64656.1, 0.002], [64656.2, 0.002], [64656.7, 0.005], [64656.9, 0.102], [64657.1, 0.0], [64657.2, 0.018], [64657.4, 0.011], [64657.6, 25.588]], "asks": [[64657.7, 13.034], [64658.0, 0.716], [64659.3, 0.005], [64660.0, 0.015], [64660.2, 0.003], [64660.5, 0.009], [64660.8, 0.004], [64660.9, 0.008], [64661.7, 0.315], [64662.0, 0.074], [64663.0, 0.088], [64663.2, 0.759], [64663.3, 2.713], [64663.5, 0.026], [64663.6, 0.002], [64663.7, 0.144], [64664.0, 0.331], [64664.3, 1.683], [64664.4, 0.001], [64664.5, 0.007], [64665.6, 0.481], [64665.7, 0.015], [64665.9, 2.362], [64666.9, 0.049], [64670.0, 0.026], [64671.0, 1.272], [64671.5, 0.015], [64672.0, 0.032], [64673.0, 0.092], [64673.5, 1.087], [64673.6, 1.922], [64674.7, 0.001], [64674.8, 0.09], [64675.0, 2.874], [64676.7, 0.244], [64681.4, 10.005], [64682.6, 0.0], [64685.1, 0.238], [64685.2, 0.098], [64688.9, 0.839], [64689.0, 0.557], [64689.5, 0.022], [64691.5, 0.0], [64698.0, 0.442], [64706.9, 0.015], [64723.9, 0.0], [64724.0, 37.597], [64727.6, 0.001], [64728.4, 0.017], [64735.3, 0.003], [64797.2, 5.401], [64814.2, 7.279], [64853.0, 0.839], [65171.2, 7.84], [65304.3, 0.373], [65423.4, 6.412], [65465.9, 1.678], [65762.7, 0.001], [65948.3, 0.079]]}
{"kind": "depth", "E": 1787082397809, "U": 11315509252402, "u": 11315509263378, "recv_ms": 1787082397783, "bids": [[1000.0, 35.81], [14157.6, 2.184], [14557.6, 1.61], [51726.0, 0.0], [58191.8, 0.002], [61424.7, 0.007], [62071.2, 0.0], [63362.0, 0.129], [63590.7, 1.099], [63657.6, 0.02], [63720.1, 1.103], [64011.0, 0.065], [64571.9, 0.483], [64572.6, 0.047], [64573.5, 2.79], [64576.8, 0.704], [64592.9, 0.141], [64595.5, 0.038], [64595.8, 0.04], [64600.7, 0.379], [64601.6, 2.324], [64605.8, 0.068], [64607.1, 0.06], [64608.3, 0.001], [64609.6, 1.539], [64614.7, 0.002], [64615.3, 0.463], [64620.0, 3.159], [64621.4, 0.117], [64621.8, 0.071], [64623.8, 0.397], [64624.0, 0.918], [64625.1, 0.07], [64626.8, 0.373], [64627.8, 0.154], [64628.4, 0.002], [64629.2, 0.017], [64629.5, 0.179], [64629.6, 0.317], [64629.9, 0.037], [64630.6, 0.002], [64631.3, 0.001], [64631.4, 0.541], [64631.5, 0.003], [64631.9, 0.311], [64632.0, 1.68], [64632.3, 0.013], [64632.5, 0.01], [64632.6, 0.006], [64633.2, 0.101], [64633.6, 1.942], [64634.0, 0.051], [64635.2, 1.268], [64635.4, 0.64], [64635.5, 0.627], [64636.0, 2.441], [64636.3, 1.19], [64636.4, 2.911], [64636.5, 0.669], [64636.8, 0.069], [64637.6, 0.817], [64638.4, 0.696], [64638.5, 0.002], [64639.1, 0.4], [64639.3, 0.002], [64639.7, 0.54], [64640.2, 0.966], [64640.8, 0.008], [64641.1, 0.489], [64641.2, 0.087], [64641.3, 0.0], [64641.4, 0.225], [64641.6, 0.02], [64642.1, 0.32], [64642.3, 0.016], [64642.9, 0.759], [64643.2, 0.008], [64643.4, 0.003], [64644.0, 0.499], [64644.1, 1.047], [64644.2, 0.477], [64644.3, 0.019], [64644.4, 0.31], [64644.5, 0.007], [64645.3, 0.004], [64645.7, 0.005], [64645.9, 0.079], [64646.0, 2.015], [64646.1, 2.467], [64646.2, 0.784], [64646.3, 0.378], [64646.4, 0.368], [64646.5, 0.174], [64647.2, 0.001], [64647.4, 0.149], [64647.5, 0.702], [64647.6, 0.008], [64647.8, 0.058], [64648.0, 0.008], [64648.3, 0.004], [64648.4, 0.597], [64648.6, 0.06], [64648.7, 0.001], [64648.8, 0.005], [64648.9, 0.001], [64649.3, 0.314], [64649.4, 0.099], [64649.6, 0.952], [64649.8, 0.007], [64650.0, 0.247], [64650.4, 0.085], [64650.6, 0.002], [64651.6, 0.999], [64652.4, 0.004], [64652.5, 0.31], [64652.8, 0.003], [64652.9, 0.084], [64653.2, 0.001], [64653.3, 0.253], [64653.5, 0.005], [64653.6, 0.001], [64653.8, 0.915], [64653.9, 1.662], [64654.0, 3.548], [64654.2, 0.02], [64654.6, 0.001], [64654.8, 0.001], [64654.9, 0.024], [64655.1, 1.023], [64655.2, 2.504], [64655.3, 1.628], [64655.5, 0.437], [64655.6, 0.002], [64656.0, 0.08], [64656.4, 0.0], [64657.0, 0.0], [64657.3, 0.002], [64657.6, 20.221]], "asks": [[64657.7, 14.189], [64657.8, 0.005], [64659.3, 0.007], [64659.6, 0.015], [64659.7, 0.097], [64660.2, 0.001], [64660.9, 0.029], [64661.6, 0.089], [64661.9, 0.033], [64662.3, 0.156], [64662.6, 0.108], [64662.7, 0.008], [64662.9, 0.165], [64663.0, 0.088], [64663.2, 0.759], [64663.3, 2.693], [64663.5, 0.003], [64663.9, 0.2], [64664.8, 0.004], [64665.3, 0.023], [64665.4, 0.001], [64665.5, 0.013], [64665.6, 0.473], [64665.7, 0.015], [64666.0, 0.903], [64667.3, 0.06], [64668.9, 0.014], [64669.0, 0.009], [64669.7, 0.967], [64670.2, 0.134], [64670.5, 0.212], [64670.8, 0.001], [64671.0, 1.148], [64672.0, 0.012], [64672.6, 0.676], [64673.0, 0.092], [64673.2, 0.008], [64673.3, 0.155], [64674.4, 0.003], [64675.5, 0.001], [64675.7, 0.565], [64675.8, 1.207], [64676.5, 0.076], [64677.1, 1.339], [64677.2, 0.011], [64677.3, 0.024], [64678.1, 0.002], [64679.0, 0.647], [64679.1, 2.283], [64679.8, 0.001], [64680.1, 0.514], [64680.2, 6.382], [64680.3, 10.163], [64681.1, 0.002], [64681.4, 0.007], [64683.0, 0.024], [64683.4, 1.238], [64683.5, 0.444], [64683.7, 1.004], [64683.8, 0.127], [64684.1, 0.027], [64687.0, 0.107], [64689.1, 0.328], [64690.4, 0.027], [64692.8, 1.018], [64693.4, 0.367], [64698.5, 0.016], [64698.7, 0.029], [64699.8, 2.399], [64700.6, 3.692], [64703.8, 0.022], [64704.4, 0.013], [64705.1, 2.349], [64750.6, 0.03], [64814.2, 10.415], [64853.0, 0.0], [65304.3, 0.373], [65451.1, 6.766], [65657.7, 0.04]]}
{"kind": "depth", "E": 1787082397911, "U": 11315509263688, "u": 11315509269962, "recv_ms": 1787082397881, "bids": [[14157.6, 1.82], [14557.6, 1.974], [58191.8, 0.002], [61424.7, 0.007], [62071.2, 0.003], [62709.9, 0.002], [63364.5, 0.037], [63879.2, 1.114], [64011.0, 0.065], [64322.6, 0.156], [64334.3, 0.004], [64545.1, 0.014], [64588.1, 0.077], [64592.9, 0.132], [64596.9, 0.024], [64621.4, 0.027], [64623.8, 0.061], [64625.0, 3.89], [64625.1, 0.08], [64627.7, 0.437], [64628.7, 0.092], [64635.5, 0.008], [64642.9, 0.14], [64643.4, 0.143], [64646.2, 0.776], [64646.4, 0.36], [64647.1, 0.275], [64647.6, 0.0], [64648.0, 0.008], [64648.1, 0.034], [64648.5, 0.542], [64648.9, 0.0], [64649.6, 0.868], [64652.1, 0.086], [64654.0, 3.505], [64654.2, 0.001], [64654.3, 0.088], [64654.5, 0.043], [64654.8, 0.023], [64654.9, 0.043], [64655.4, 0.009], [64656.0, 0.003], [64656.3, 0.045], [64657.6, 20.223]], "asks": [[64657.7, 13.139], [64659.3, 0.005], [64659.7, 0.086], [64660.0, 0.015], [64660.2, 0.003], [64660.9, 0.01], [64662.1, 0.549], [64662.2, 0.129], [64662.3, 0.051], [64662.4, 1.115], [64663.0, 0.091], [64664.1, 0.356], [64665.5, 0.005], [64665.7, 0.023], [64666.0, 0.003], [64668.4, 1.253], [64668.8, 0.01], [64669.7, 0.348], [64673.0, 0.092], [64673.2, 0.001], [64674.2, 0.47], [64674.8, 0.041], [64677.1, 0.72], [64681.4, 0.056], [64684.4, 0.066], [64692.9, 0.001], [64703.0, 0.338], [64703.8, 0.232], [64704.3, 1.796], [64706.9, 0.015], [64711.1, 0.001], [64715.9, 0.022], [64716.2, 0.052], [64718.7, 0.007], [64718.8, 0.056], [64719.8, 2.613], [64721.8, 37.617], [64724.0, 0.001], [64730.0, 0.758], [64735.3, 0.0], [64814.2, 7.352], [64853.0, 5.673], [65304.3, 0.373], [65427.1, 2.589], [65562.9, 0.367], [65692.2, 4.884], [65771.0, 4.102], [65948.3, 0.076], [65950.8, 0.021]]}
{"kind": "depth", "E": 1787082398013, "U": 11315509270311, "u": 11315509286544, "recv_ms": 1787082397985, "bids": [[1000.0, 35.81], [14157.6, 1.47], [14557.6, 2.324], [58191.8, 0.002], [61424.7, 0.007], [62071.2, 0.0], [63657.6, 0.0], [63944.9, 0.882], [64011.0, 0.065], [64334.3, 0.003], [64571.9, 0.303], [64573.5, 2.61], [64575.2, 0.27], [64576.8, 0.524], [64581.6, 0.007], [64588.1, 0.257], [64592.9, 0.119], [64594.8, 0.001], [64595.7, 0.01], [64596.8, 1.474], [64612.7, 0.011], [64621.8, 0.001], [64624.9, 2.29], [64625.0, 1.744], [64627.7, 0.101], [64628.9, 0.006], [64629.0, 0.974], [64629.2, 0.023], [64629.4, 0.213], [64629.6, 0.311], [64629.9, 0.022], [64630.9, 2.357], [64631.4, 0.526], [64632.1, 0.015], [64633.0, 2.202], [64633.1, 0.379], [64633.9, 0.337], [64635.3, 0.033], [64635.4, 0.642], [64636.6, 0.484], [64639.1, 0.365], [64640.2, 0.04], [64641.1, 0.57], [64641.2, 0.008], [64641.8, 0.986], [64643.4, 0.138], [64644.0, 0.503], [64646.1, 2.469], [64646.3, 0.558], [64646.4, 0.403], [64647.6, 0.541], [64647.8, 0.055], [64648.1, 0.033], [64648.4, 0.365], [64648.5, 0.001], [64648.6, 0.06], [64648.7, 0.001], [64648.9, 0.0], [64649.7, 0.003], [64650.0, 0.164], [64650.2, 0.004], [64650.4, 0.001], [64650.6, 0.312], [64651.0, 0.388], [64652.0, 0.019], [64652.1, 0.085], [64653.0, 0.007], [64653.5, 0.002], [64654.5, 0.043], [64654.8, 0.001], [64654.9, 0.047], [64655.0, 1.023], [64655.3, 1.631], [64655.4, 0.011], [64655.6, 0.0], [64656.0, 0.08], [64656.2, 0.084], [64656.6, 0.001], [64656.9, 0.412], [64657.5, 0.007], [64657.6, 20.223]], "asks": [[64657.7, 12.223], [64658.0, 0.641], [64658.1, 0.0], [64658.4, 0.001], [64659.2, 0.84], [64659.6, 0.005], [64659.7, 0.002], [64659.9, 0.087], [64660.1, 1.016], [64660.2, 0.001], [64660.3, 0.004], [64660.4, 2.406], [64660.5, 0.009], [64660.8, 0.088], [64661.2, 0.088], [64661.6, 0.089], [64661.7, 0.002], [64662.0, 0.09], [64662.1, 0.465], [64662.2, 0.213], [64662.3, 0.156], [64662.4, 1.092], [64662.5, 0.003], [64662.6, 0.085], [64662.7, 0.004], [64662.9, 0.165], [64663.0, 0.088], [64663.2, 0.65], [64663.4, 0.025], [64664.3, 1.672], [64664.5, 0.007], [64664.9, 0.24], [64665.2, 0.163], [64665.3, 0.003], [64665.6, 0.013], [64665.7, 0.1], [64665.8, 1.888], [64666.0, 0.003], [64668.8, 0.009], [64668.9, 0.001], [64669.6, 0.015], [64670.7, 0.008], [64671.5, 0.015], [64672.1, 0.011], [64673.0, 0.1], [64673.3, 0.001], [64673.6, 0.996], [64674.0, 0.129], [64674.1, 0.473], [64674.2, 1.396], [64674.7, 0.021], [64674.8, 0.041], [64675.7, 0.008], [64677.1, 1.277], [64680.3, 0.165], [64681.4, 0.054], [64681.7, 0.231], [64682.4, 4.593], [64683.3, 0.004], [64683.8, 0.121], [64684.1, 0.014], [64684.5, 0.154], [64685.2, 0.104], [64686.1, 0.0], [64688.0, 0.051], [64688.8, 0.112], [64689.3, 10.017], [64690.4, 0.0], [64692.4, 0.009], [64694.4, 0.049], [64697.5, 0.31], [64698.5, 0.001], [64699.5, 0.036], [64699.8, 2.381], [64700.9, 0.019], [64701.3, 0.007], [64706.0, 2.288], [64706.1, 0.031], [64714.1, 2.146], [64714.3, 0.001], [64718.8, 0.046], [64718.9, 0.231], [64721.8, 0.021], [64730.5, 37.113], [64732.7, 0.0], [64734.9, 0.027], [64779.1, 7.041], [64779.3, 0.001], [65175.0, 2.328], [65304.3, 0.373], [65657.7, 0.02], [65948.3, 0.067]]}
{"kind": "depth", "E": 1787082398115, "U": 11315509286719, "u": 11315509294249, "recv_ms": 1787082398088, "bids": [[1000.0, 35.81], [14157.6, 1.106], [14557.6, 2.688], [51724.0, 0.0], [51726.0, 0.002], [58191.8, 0.002], [62071.2, 0.003], [63619.4, 2.638], [63651.8, 19.134], [64011.0, 0.067], [64608.9, 0.006], [64615.0, 0.033], [64623.8, 0.004], [64625.1, 0.137], [64626.0, 0.237], [64630.5, 0.336], [64633.9, 0.001], [64641.2, 0.006], [64646.0, 2.015], [64646.3, 0.558], [64647.6, 0.541], [64649.5, 0.237], [64650.0, 0.163], [64650.2, 0.004], [64656.0, 0.08], [64657.1, 0.001], [64657.6, 20.242]], "asks": [[64657.7, 12.226], [64659.2, 0.841], [64659.4, 0.087], [64660.0, 0.025], [64662.0, 0.074], [64662.4, 1.093], [64663.0, 0.088], [64663.2, 0.102], [64664.1, 0.272], [64665.7, 0.124], [64670.7, 0.007], [64671.5, 0.556], [64673.7, 0.004], [64674.0, 0.121], [64674.2, 0.47], [64674.7, 0.029], [64674.8, 0.967], [64679.0, 0.106], [64679.8, 0.542], [64688.9, 0.839], [64689.1, 0.328], [64724.0, 37.106], [64730.2, 0.001], [64730.5, 0.008], [64814.2, 10.415], [64853.0, 1.76], [64981.0, 0.276], [65304.3, 0.373], [65429.8, 24.708], [65465.9, 1.906], [65688.5, 14.596]]}
{"kind": "depth", "E": 1787082398217, "U": 11315509294256, "u": 11315509301092, "recv_ms": 1787082398187, "bids": [[14155.1, 0.364], [14157.6, 0.798], [14557.6, 3.038], [51726.0, 0.0], [58191.8, 0.002], [61424.7, 0.007], [63362.0, 0.126], [63657.6, 0.02], [63935.3, 0.022], [64011.0, 0.065], [64334.3, 0.013], [64528.2, 0.002], [64577.7, 0.006], [64579.0, 8.304], [64602.3, 0.03], [64608.9, 0.007], [64635.2, 1.152], [64635.4, 0.085], [64636.4, 3.027], [64636.8, 0.626], [64637.3, 0.001], [64641.1, 0.106], [64641.2, 0.008], [64643.4, 0.594], [64643.5, 0.002], [64644.5, 0.0], [64646.1, 2.476], [64646.3, 0.558], [64646.5, 0.182], [64647.5, 0.393], [64647.6, 0.0], [64649.2, 0.311], [64649.7, 0.544], [64650.1, 0.631], [64653.0, 0.004], [64653.8, 0.912], [64655.6, 0.002], [64656.0, 0.003], [64656.6, 0.0], [64657.6, 20.243]], "asks": [[64657.7, 12.724], [64660.1, 1.016], [64660.5, 0.004], [64661.0, 0.008], [64661.7, 0.312], [64663.4, 0.023], [64665.7, 0.032], [64671.4, 0.125], [64673.7, 0.006], [64674.1, 0.01], [64674.7, 0.492], [64675.7, 0.001], [64676.4, 0.008], [64680.2, 6.384], [64680.3, 0.163], [64682.3, 3.096], [64684.8, 10.007], [64688.9, 0.993], [64689.1, 0.174], [64689.2, 0.029], [64689.3, 0.017], [64710.5, 2.04], [64710.7, 0.01], [64729.6, 1.74], [64814.1, 2.439], [64981.0, 0.275], [65304.3, 0.373], [65433.6, 2.813], [65548.0, 0.001], [65657.7, 0.04], [65950.8, 0.024]]}
{"kind": "depth", "E": 1787082398319, "U": 11315509301360, "u": 11315509308932, "recv_ms": 1787082398314, "bids": [[1000.0, 35.81], [14155.1, 0.252], [14157.6, 0.546], [14557.6, 3.402], [51726.0, 0.0], [58191.8, 0.002], [61424.7, 0.007], [62071.2, 0.0], [63655.4, 1.099], [63884.5, 6.567], [63929.5, 0.005], [64011.0, 0.065], [64334.3, 0.014], [64554.8, 0.012], [64555.3, 2.322], [64578.9, 0.003], [64579.0, 0.049], [64581.1, 48.842], [64625.1, 0.127], [64625.2, 0.111], [64650.1, 0.63], [64652.3, 0.002], [64656.0, 0.183], [64656.3, 0.003], [64656.7, 0.046], [64657.6, 20.335]], "asks": [[64657.7, 12.678], [64659.1, 0.006], [64663.0, 0.111], [64663.1, 0.992], [64664.2, 0.217], [64664.3, 1.694], [64665.7, 0.016], [64668.0, 0.292], [64671.4, 0.118], [64672.7, 0.392], [64679.0, 0.97], [64683.8, 0.518], [64688.4, 0.147], [64688.9, 0.839], [64689.0, 0.711], [64689.1, 0.174], [64700.8, 0.936], [64707.2, 0.817], [64845.7, 0.001], [64846.2, 0.003], [65304.3, 0.91], [65465.9, 2.164], [65556.4, 0.886], [65756.9, 0.289], [66057.2, 0.65]]}
{"kind": "depth", "E": 1787082398421, "U": 11315509309074, "u": 11315509317860, "recv_ms": 1787082398390, "bids": [[1000.0, 35.81], [14155.1, 0.056], [14157.6, 0.406], [14457.6, 0.028], [14557.6, 3.71], [58191.8, 0.002], [61424.7, 0.007], [62071.2, 0.003], [62547.4, 0.003], [63623.1, 2.198], [63657.6, 0.0], [63943.3, 0.312], [64011.0, 0.065], [64334.3, 0.169], [64586.6, 0.006], [64591.7, 0.014], [64613.2, 0.004], [64632.3, 0.014], [64633.6, 1.941], [64652.3, 0.001], [64654.5, 0.024], [64655.0, 1.003], [64656.0, 0.184], [64656.1, 0.004], [64657.6, 20.336]], "asks": [[64660.0, 0.025], [64665.3, 0.023], [64668.6, 2.771], [64672.1, 0.0], [64674.7, 0.472], [64689.0, 0.557], [64689.3, 0.171], [64853.0, 1.846], [65171.2, 7.533], [65304.3, 0.91], [65378.8, 0.764], [65657.7, 0.02], [65692.2, 5.948], [65948.3, 0.064]]}
{"kind": "depth", "E": 1787082398523, "U": 11315509317891, "u": 11315509325957, "recv_ms": 1787082398491, "bids": [[14155.1, 0.0], [14157.6, 0.28], [14457.6, 0.196], [14557.6, 3.724], [51726.1, 0.0], [58191.8, 0.002], [62071.2, 0.0], [63888.2, 0.938], [63945.1, 0.874], [64011.0, 0.065], [64334.3, 0.169], [64609.0, 0.161], [64615.4, 0.009], [64647.1, 0.816], [64649.7, 0.003], [64654.5, 0.001], [64654.9, 0.024], [64656.1, 0.002], [64656.2, 0.106], [64656.5, 0.019], [64657.2, 0.019], [64657.5, 0.054]], "asks": [[64669.0, 0.011], [64718.9, 0.221], [64719.0, 0.245], [65304.3, 0.91]]}
{"kind": "depth", "E": 1787082398625, "U": 11315509326149, "u": 11315509332492, "recv_ms": 1787082398597, "bids": [[1000.0, 35.81], [14157.6, 0.168], [14457.6, 0.448], [14557.6, 3.584], [51726.0, 0.004], [58191.8, 0.002], [62071.2, 0.003], [63453.3, 0.0], [63657.6, 0.02], [63825.6, 0.0], [63884.5, 5.629], [64011.0, 0.065], [64590.7, 0.1], [64639.5, 0.021], [64647.1, 0.816], [64649.7, 0.003], [64656.5, 0.042]], "asks": [[64660.0, 0.025], [64663.6, 0.022], [64663.8, 0.364], [64745.6, 0.1], [65175.0, 2.635], [65304.3, 0.91], [65465.9, 2.422], [65492.6, 0.0], [65657.7, 0.04]]}
{"kind": "depth", "E": 1787082398727, "U": 11315509332562, "u": 11315509339148, "recv_ms": 1787082398698, "bids": [[1000.0, 35.81], [14157.6, 0.042], [14457.6, 0.672], [14557.6, 3.486], [51726.0, 0.0], [58191.8, 0.002], [61424.7, 0.009], [62538.1, 0.0], [64011.0, 0.067], [64547.6, 2.324], [64576.8, 0.447], [64588.1, 0.18], [64591.4, 0.003], [64605.9, 0.026], [64635.3, 0.031], [64638.1, 5.018], [64639.9, 1.893], [64653.8, 0.905], [64653.9, 1.655], [64655.3, 1.632], [64656.0, 0.261], [64656.1, 0.004], [64657.2, 0.018], [64657.5, 0.059], [64657.6, 20.341]], "asks": [[64657.7, 13.354], [64661.0, 0.399], [64663.0, 0.088], [64663.1, 0.311], [64663.6, 0.002], [64665.7, 0.665], [64668.9, 0.963], [64671.4, 0.033], [64671.5, 0.015], [64672.7, 0.001], [64672.9, 0.016], [64673.0, 0.61], [64679.0, 0.008], [64680.4, 1.273], [64683.8, 0.0], [64686.2, 0.015], [64686.8, 0.828], [64688.8, 0.098], [64696.3, 0.537], [64700.8, 0.059], [64701.3, 0.003], [64707.2, 0.012], [64715.9, 0.025], [64722.4, 0.012], [64846.2, 0.0], [64846.3, 0.005], [65304.3, 0.373]]}
{"kind": "depth", "E": 1787082398829, "U": 11315509339213, "u": 11315509346758, "recv_ms": 1787082398799, "bids": [[14157.6, 0.0], [14457.6, 0.98], [14557.6, 3.22], [58191.8, 0.002], [62071.2, 0.0], [63657.6, 0.0], [63888.2, 1.876], [64011.0, 0.065], [64334.3, 0.159], [64532.6, 0.005], [64533.5, 0.086], [64625.2, 0.101], [64625.3, 0.216], [64636.1, 2.344], [64638.6, 0.157], [64646.3, 0.635], [64651.6, 1.0], [64655.3, 1.631], [64656.8, 0.021], [64657.6, 20.341]], "asks": [[64657.7, 13.451], [64663.5, 0.022], [64664.2, 0.197], [64773.9, 0.0], [64774.2, 0.085], [64814.2, 7.309], [64852.4, 1.278], [64853.0, 4.737], [65304.3, 0.373], [65657.7, 0.02], [65948.3, 0.058], [67777.0, 5.158]]}
{"kind": "depth", "E": 1787082399033, "U": 11315509357178, "u": 11315509363166, "recv_ms": 1787082399003, "bids": [[1000.0, 35.81], [14457.6, 1.694], [14557.6, 2.506], [58191.8, 0.002], [62071.2, 0.0], [63657.6, 0.02], [63676.1, 2.071], [63770.2, 3.304], [63901.6, 0.783], [64011.0, 0.065], [64631.7, 0.033], [64645.4, 0.633], [64646.0, 2.02], [64653.5, 0.003], [64655.2, 2.504], [64656.5, 0.019]], "asks": [[64657.7, 13.311], [64661.6, 0.092], [64669.7, 0.35], [64853.0, 4.738], [65304.3, 0.373], [65368.9, 3.055], [65421.7, 8.398], [65657.7, 0.04], [65857.9, 2.394]]}
{"kind": "depth", "E": 1787082399135, "U": 11315509363170, "u": 11315509370267, "recv_ms": 1787082399106, "bids": [[14457.6, 2.058], [14557.6, 2.142], [58191.8, 0.002], [61424.7, 0.009], [63651.4, 0.002], [64011.0, 0.065], [64334.3, 0.315], [64547.6, 2.321], [64571.9, 0.226], [64573.5, 2.533], [64575.2, 0.193], [64588.1, 0.077], [64596.9, 0.021], [64599.4, 0.21], [64602.3, 0.029], [64606.0, 0.095], [64608.9, 0.008], [64617.5, 0.026], [64638.0, 0.368], [64641.2, 0.006], [64643.4, 0.594], [64645.4, 0.014], [64646.0, 2.015], [64646.5, 0.182], [64646.6, 0.102], [64651.9, 0.234], [64655.0, 1.087], [64656.0, 0.338], [64656.1, 0.002], [64656.2, 0.022], [64656.5, 0.329], [64656.6, 0.023], [64656.9, 0.102], [64657.6, 20.322]], "asks": [[64658.7, 0.084], [64659.1, 0.316], [64659.9, 0.087], [64660.0, 0.027], [64660.5, 0.002], [64663.5, 0.003], [64663.6, 0.022], [64663.7, 0.06], [64663.8, 0.341], [64663.9, 0.222], [64665.6, 0.021], [64672.2, 1.216], [64672.9, 0.008], [64673.7, 0.004], [64674.2, 0.463], [64675.3, 0.01], [64679.6, 0.63], [64681.6, 1.75], [64686.2, 0.001], [64715.5, 0.658], [64715.9, 0.025], [64814.2, 10.415], [64852.4, 0.655], [64853.0, 1.583], [64981.0, 0.274], [65304.3, 0.375], [65370.2, 1.008], [65434.9, 0.912], [65465.9, 2.681], [65656.4, 0.0]]}
{"kind": "depth", "E": 1787082399237, "U": 11315509370344, "u": 11315509376296, "recv_ms": 1787082399215, "bids": [[1000.0, 35.81], [14457.6, 2.408], [14557.6, 1.792], [58191.8, 0.002], [61421.3, 0.0], [61424.7, 0.009], [62071.2, 0.003], [63364.5, 0.04], [63651.8, 18.036], [63655.1, 0.043], [63657.6, 0.0], [63752.4, 0.188], [63776.1, 11.111], [64011.0, 0.065], [64528.2, 0.002], [64574.5, 48.152], [64581.1, 2.322], [64582.0, 2.754], [64634.0, 0.051], [64635.5, 0.01], [64641.2, 0.008], [64641.4, 0.145], [64642.7, 0.293], [64650.3, 0.003], [64653.5, 0.002], [64654.9, 0.025], [64655.5, 0.001], [64655.6, 0.086], [64655.7, 0.023], [64655.9, 0.019], [64656.0, 0.081], [64656.2, 0.0], [64656.5, 0.31], [64656.6, 0.0], [64656.8, 0.002], [64657.6, 20.958]], "asks": [[64657.7, 13.085], [64659.1, 0.006], [64660.0, 0.025], [64660.2, 0.003], [64663.6, 0.002], [64663.9, 0.2], [64664.0, 0.35], [64664.1, 0.294], [64665.6, 0.013], [64665.7, 0.664], [64672.2, 0.597], [64672.9, 0.016], [64673.7, 0.006], [64679.6, 0.011], [64695.9, 1.119], [64714.0, 1.103], [64745.6, 0.0], [64853.0, 1.58], [65304.3, 0.373], [65548.1, 21.294], [65656.1, 13.233], [65657.7, 0.02], [65660.2, 1.331], [65720.8, 3.192], [65866.8, 0.759]]}
{"kind": "depth", "E": 1787082399339, "U": 11315509376429, "u": 11315509380840, "recv_ms": 1787082399310, "bids": [[1000.0, 35.81], [14457.6, 2.758], [14557.6, 1.442], [58191.8, 0.002], [62071.2, 0.0], [63687.7, 0.861], [63763.2, 1.88], [63771.8, 0.625], [63881.7, 0.219], [64011.0, 0.065], [64334.3, 0.314], [64514.6, 2.001], [64574.5, 1.632], [64581.1, 48.737], [64590.7, 0.0], [64634.0, 0.051], [64642.7, 0.293], [64655.7, 0.0], [64656.0, 0.088], [64656.5, 0.332], [64656.7, 0.065], [64657.6, 20.958]], "asks": [[64659.9, 0.087], [64797.2, 0.0], [65304.3, 0.373], [65534.7, 1.218]]}
{"kind": "depth", "E": 1787082399441, "U": 11315509381286, "u": 11315509386131, "recv_ms": 1787082399411, "bids": [[14457.6, 3.122], [14557.6, 1.078], [51726.1, 0.002], [58191.8, 0.002], [62071.2, 0.003], [63619.4, 1.539], [63657.6, 0.02], [63716.4, 16.381], [63884.5, 4.691], [64011.0, 0.065], [64334.3, 0.324], [64515.0, 6.859], [64656.0, 0.184], [64656.5, 0.31]], "asks": [[64658.7, 0.0], [64665.6, 0.021], [64672.9, 0.008], [64797.2, 5.401], [64853.0, 1.582], [64981.0, 0.275], [65292.8, 0.248], [65304.3, 0.373], [65657.7, 0.04], [65688.5, 13.532]]}
{"kind": "depth", "E": 1787082399543, "U": 11315509386188, "u": 11315509390720, "recv_ms": 1787082399513, "bids": [[1000.0, 35.81], [14457.6, 3.486], [14557.6, 0.714], [51726.1, 0.0], [58191.8, 0.002], [61424.7, 0.009], [62071.2, 0.0], [63362.0, 0.123], [63655.4, 2.197], [63784.7, 0.625], [64011.0, 0.065], [64515.0, 1.716], [64555.3, 2.319], [64555.4, 0.008], [64595.5, 0.029], [64637.8, 0.158], [64637.9, 0.0], [64650.7, 0.76], [64653.9, 1.654], [64655.9, 0.0], [64656.0, 0.165], [64656.4, 0.023], [64656.5, 0.394]], "asks": [[64657.7, 13.086], [64659.4, 0.003], [64660.0, 0.025], [64663.7, 0.083], [64664.3, 1.672], [64670.3, 0.091], [64719.0, 0.235], [64719.1, 0.026], [64797.2, 0.0], [65304.3, 0.373], [65465.9, 2.91], [65562.9, 2.651], [65659.9, 2.13], [65724.6, 1.065]]}
{"kind": "depth", "E": 1787082399645, "U": 11315509390826, "u": 11315509395971, "recv_ms": 1787082399614, "bids": [[1000.0, 35.81], [14357.6, 0.056], [14457.6, 3.724], [14557.6, 0.42], [51726.0, 0.0], [58191.8, 0.002], [63362.0, 0.12], [63657.6, 0.0], [63888.2, 2.814], [64011.0, 0.065], [64497.6, 0.0], [64498.0, 10.141], [64498.2, 2.091], [64515.0, 6.859], [64641.4, 0.225], [64642.7, 0.213], [64651.1, 0.033], [64651.9, 0.002], [64653.4, 0.261], [64656.0, 0.184], [64656.1, 0.004], [64656.4, 0.0], [64656.7, 0.046], [64657.2, 0.102]], "asks": [[64659.9, 0.003], [64661.6, 0.089], [64661.7, 0.002], [64663.2, 0.125], [64663.4, 0.107], [64663.7, 0.103], [64665.7, 0.641], [64797.2, 5.401], [64814.1, 0.885], [64814.2, 10.415], [64853.0, 1.583], [64977.3, 4.204], [65171.2, 7.227], [65275.3, 1.147], [65304.3, 0.373], [65543.5, 0.794], [65657.7, 0.02], [65948.3, 0.055]]}
{"kind": "depth", "E": 1787082399747, "U": 11315509396142, "u": 11315509402481, "recv_ms": 1787082399717, "bids": [[14357.6, 0.252], [14457.6, 3.696], [14557.6, 0.252], [58191.8, 0.002], [62071.2, 0.003], [63388.6, 0.005], [63623.1, 3.297], [63651.8, 16.939], [63720.1, 2.2], [63870.8, 0.006], [64007.9, 0.78], [64010.4, 0.387], [64011.0, 0.065], [64334.3, 0.324], [64515.0, 1.716], [64587.8, 2.512], [64610.4, 0.143], [64610.5, 0.878], [64626.5, 0.002], [64656.1, 0.002], [64656.2, 0.023], [64656.4, 0.02]], "asks": [[64663.5, 0.022], [64664.0, 0.331], [64683.7, 0.037], [64700.6, 0.192], [64723.3, 1.239], [64797.2, 0.0], [64969.1, 0.0], [65304.3, 0.373], [65591.5, 21.773], [65656.1, 12.169], [65692.2, 7.012], [65950.8, 0.027]]}
