{"kind": "depth", "E": 1787082399849, "U": 11315509402574, "u": 11315509408797, "recv_ms": 1787082399819, "bids": [[1000.0, 35.81], [14357.6, 0.504], [14457.6, 3.556], [14557.6, 0.14], [58191.8, 0.002], [61424.7, 0.009], [62071.2, 0.0], [63655.4, 3.295], [63657.6, 0.02], [63825.4, 0.0], [63878.1, 21.488], [64011.0, 0.065], [64515.0, 6.859], [64555.1, 0.0], [64587.7, 6.0], [64610.4, 3.643], [64626.5, 0.982], [64629.2, 0.017], [64630.3, 0.028], [64637.8, 0.004], [64638.1, 5.172], [64642.1, 0.0], [64643.5, 0.01], [64644.3, 0.011], [64646.1, 2.468], [64646.5, 0.174], [64647.2, 0.009], [64647.8, 0.063], [64648.7, 0.321], [64655.3, 1.628], [64655.4, 0.011], [64656.0, 0.184], [64656.7, 0.005], [64656.8, 0.045], [64657.0, 0.003], [64657.6, 20.958]], "asks": [[64657.7, 12.994], [64657.8, 0.002], [64659.2, 0.84], [64660.0, 0.028], [64661.0, 0.392], [64662.0, 0.081], [64662.4, 1.092], [64663.2, 0.102], [64665.3, 0.003], [64665.6, 0.044], [64671.0, 1.146], [64671.7, 0.46], [64674.1, 0.01], [64683.5, 1.408], [64684.3, 0.006], [64685.2, 0.098], [64687.1, 0.102], [64687.2, 2.319], [64688.8, 0.112], [64696.2, 0.023], [64696.7, 1.37], [64699.6, 3.545], [64700.7, 0.079], [64722.3, 6.442], [64754.9, 0.003], [64755.0, 0.103], [64756.0, 0.025], [64797.2, 5.401], [64814.2, 7.243], [64853.0, 5.195], [64981.0, 0.429], [65175.0, 2.941], [65304.3, 0.373], [65595.2, 4.266], [65657.7, 0.04], [65948.3, 0.052], [67262.8, 0.636]]}
{"kind": "depth", "E": 1787082399951, "U": 11315509408877, "u": 11315509418639, "recv_ms": 1787082399923, "bids": [[1000.0, 35.81], [14357.6, 0.728], [14457.6, 3.458], [14557.6, 0.014], [58191.8, 0.002], [62071.2, 0.003], [63725.1, 1.653], [64011.0, 0.065], [64581.1, 2.322], [64596.8, 1.462], [64598.7, 0.019], [64626.8, 0.353], [64629.7, 0.017], [64630.9, 2.343], [64632.9, 0.016], [64633.2, 0.083], [64636.2, 0.035], [64643.5, 0.002], [64646.5, 0.182], [64647.1, 0.275], [64647.8, 0.063], [64649.7, 0.544], [64654.9, 0.024], [64655.4, 0.011], [64656.0, 0.107], [64657.0, 0.004], [64657.2, 0.018]], "asks": [[64660.0, 0.112], [64661.9, 0.043], [64663.2, 0.102], [64663.5, 0.003], [64663.7, 0.06], [64665.6, 0.044], [64684.3, 0.0], [64684.6, 0.008], [64688.0, 0.039], [64690.0, 0.014], [64694.4, 0.031], [64696.4, 0.045], [64699.5, 0.022], [64700.9, 0.002], [64701.5, 0.014], [64702.8, 0.02], [64814.2, 10.415], [64853.0, 1.75], [65304.3, 0.373], [65659.9, 3.195]]}
{"kind": "depth", "E": 1787082400053, "U": 11315509418962, "u": 11315509424872, "recv_ms": 1787082400025, "bids": [[14357.6, 1.078], [14457.6, 3.122], [14557.6, 0.0], [58191.8, 0.002], [61424.7, 0.01], [62071.2, 0.0], [63556.3, 0.0], [63657.6, 0.0], [63880.4, 0.892], [64011.0, 0.065], [64136.7, 8.286], [64334.3, 0.324], [64555.5, 10.018], [64578.9, 46.405], [64636.6, 1.103], [64637.7, 0.008], [64642.3, 0.035], [64644.0, 1.122], [64646.0, 2.015], [64647.8, 0.055], [64651.8, 0.28], [64652.8, 0.006], [64654.0, 3.508], [64655.4, 0.017], [64655.6, 0.084], [64655.7, 0.002], [64656.0, 0.319], [64657.0, 0.003], [64657.1, 0.085], [64657.6, 21.019]], "asks": [[64657.7, 11.185], [64660.0, 0.028], [64660.2, 0.001], [64660.5, 0.002], [64661.4, 0.005], [64661.5, 0.003], [64661.9, 0.003], [64662.2, 0.215], [64663.2, 0.65], [64663.8, 0.142], [64663.9, 0.219], [64664.4, 0.055], [64665.2, 0.172], [64665.6, 0.037], [64665.7, 0.1], [64667.4, 0.185], [64670.8, 0.001], [64678.2, 2.327], [64689.0, 0.557], [64754.6, 0.044], [64754.7, 10.022], [64756.0, 0.017], [65304.3, 0.373], [65657.7, 0.02]]}
{"kind": "depth", "E": 1787082400155, "U": 11315509424878, "u": 11315509429898, "recv_ms": 1787082400124, "bids": [[1000.0, 35.81], [14357.6, 1.428], [14457.6, 2.772], [58191.8, 0.002], [61424.7, 0.009], [63362.0, 0.117], [63652.6, 0.011], [63655.1, 0.051], [63676.1, 1.773], [63717.4, 0.003], [63719.8, 0.039], [63720.6, 0.003], [63723.1, 0.008], [63881.7, 2.095], [64011.0, 0.065], [64049.2, 0.004], [64330.7, 0.469], [64334.3, 0.323], [64528.2, 0.003], [64540.0, 0.228], [64540.2, 4.449], [64584.2, 2.29], [64584.5, 0.046], [64602.3, 0.028], [64606.0, 0.096], [64608.9, 0.009], [64636.4, 2.911], [64637.6, 0.933], [64640.8, 0.001], [64643.1, 1.593], [64643.4, 0.13], [64646.5, 0.646], [64648.0, 0.008], [64649.7, 0.003], [64650.8, 0.541], [64651.7, 0.004], [64651.8, 0.279], [64653.9, 1.655], [64654.0, 3.505], [64655.4, 0.017], [64655.6, 0.086], [64656.0, 0.261], [64656.5, 0.416], [64656.7, 0.024], [64657.6, 21.022]], "asks": [[64657.8, 0.004], [64659.2, 0.841], [64659.3, 0.003], [64659.9, 0.001], [64660.0, 0.036], [64662.0, 0.089], [64662.4, 1.093], [64662.8, 0.002], [64662.9, 0.165], [64663.0, 0.088], [64663.2, 0.102], [64663.6, 0.022], [64663.8, 0.164], [64665.6, 0.021], [64665.7, 0.648], [64666.1, 0.002], [64677.0, 0.155], [64677.1, 0.72], [64678.2, 2.941], [64679.5, 0.003], [64680.4, 1.389], [64726.5, 0.013], [64726.8, 6.357], [64790.9, 0.0], [64791.0, 3.894], [64799.3, 0.22], [64799.7, 0.044], [65304.3, 0.373], [65589.8, 0.0], [65593.0, 0.0], [65657.7, 0.012], [65948.3, 0.049]]}
{"kind": "depth", "E": 1787082400257, "U": 11315509430004, "u": 11315509436717, "recv_ms": 1787082400232, "bids": [[1000.0, 35.81], [14357.6, 1.778], [14457.6, 2.422], [51726.0, 0.002], [58191.8, 0.002], [62071.2, 0.003], [63564.9, 0.63], [63804.3, 0.786], [64011.0, 0.065], [64140.3, 1.371], [64528.2, 0.002], [64579.0, 8.33], [64588.1, 0.25], [64591.3, 1.326], [64591.6, 0.003], [64591.9, 0.002], [64592.2, 0.001], [64592.5, 0.002], [64609.9, 0.0], [64610.2, 0.15], [64610.5, 0.846], [64610.8, 0.032], [64611.2, 0.007], [64612.7, 0.043], [64624.8, 0.014], [64624.9, 2.15], [64625.0, 1.59], [64625.1, 0.057], [64625.2, 0.001], [64625.3, 0.016], [64625.4, 0.002], [64625.5, 1.3], [64625.6, 2.004], [64625.8, 0.006], [64627.7, 0.001], [64628.1, 0.03], [64636.7, 1.985], [64637.3, 0.015], [64637.6, 0.817], [64641.2, 0.008], [64643.4, 0.594], [64645.9, 0.009], [64646.0, 1.875], [64646.1, 2.328], [64646.2, 0.706], [64646.3, 0.351], [64646.4, 0.303], [64646.5, 0.004], [64646.6, 0.002], [64646.7, 0.0], [64646.9, 0.001], [64647.1, 0.243], [64647.2, 0.001], [64647.4, 0.117], [64647.8, 0.023], [64648.0, 0.016], [64648.1, 0.001], [64648.4, 0.333], [64649.7, 0.544], [64650.0, 0.195], [64650.2, 0.004], [64650.8, 0.0], [64654.2, 0.004], [64655.4, 0.009], [64655.6, 0.084], [64656.0, 0.004], [64656.4, 0.042], [64656.5, 0.394], [64656.6, 0.019], [64656.7, 0.005], [64656.8, 0.045], [64657.1, 0.001]], "asks": [[64659.9, 0.085], [64660.0, 0.028], [64661.9, 0.013], [64662.0, 0.081], [64663.2, 0.102], [64663.6, 0.002], [64663.8, 0.002], [64663.9, 0.121], [64664.0, 0.1], [64664.1, 0.091], [64664.2, 0.106], [64665.6, 0.029], [64665.7, 0.115], [64665.9, 2.327], [64666.3, 0.549], [64666.6, 0.002], [64666.9, 0.004], [64667.2, 0.005], [64667.5, 0.02], [64667.6, 0.197], [64667.7, 0.003], [64667.8, 0.0], [64667.9, 0.006], [64668.0, 0.142], [64668.1, 0.001], [64671.5, 0.556], [64672.9, 0.008], [64673.7, 0.006], [64674.4, 0.011], [64674.7, 0.464], [64684.9, 0.0], [64685.0, 0.048], [64685.1, 0.007], [64685.2, 0.0], [64685.3, 0.003], [64688.8, 0.014], [64688.9, 0.629], [64689.3, 0.017], [64698.9, 0.051], [64699.3, 0.794], [64699.6, 3.5], [64699.9, 0.388], [64700.2, 0.071], [64700.6, 0.002], [64700.7, 0.079], [64701.0, 0.33], [64703.6, 0.045], [64705.4, 0.001], [64705.6, 1.059], [64705.8, 0.006], [64705.9, 0.169], [64717.6, 2.057], [64717.9, 0.204], [64718.2, 2.332], [64718.5, 0.31], [64718.8, 0.001], [64720.7, 1.749], [64981.0, 0.43], [65304.3, 0.373], [65418.8, 12.589], [65591.5, 19.641], [65592.3, 0.021], [65595.6, 0.014], [65660.2, 1.339]]}
{"kind": "depth", "E": 1787082400359, "U": 11315509436758, "u": 11315509442627, "recv_ms": 1787082400330, "bids": [[14357.6, 2.142], [14457.6, 2.058], [51726.0, 0.002], [58191.8, 0.002], [61424.7, 0.007], [61424.8, 0.002], [62071.2, 0.0], [63364.5, 0.043], [63657.6, 0.02], [63750.7, 0.007], [63835.0, 7.117], [64011.0, 0.065], [64334.3, 0.323], [64543.9, 0.072], [64606.2, 0.502], [64612.1, 1.944], [64613.1, 0.266], [64616.5, 1.143], [64624.9, 2.175], [64643.5, 0.01], [64646.3, 0.343], [64648.0, 0.008], [64648.1, 0.071], [64648.3, 0.074], [64649.3, 0.346], [64650.0, 1.432], [64655.4, 0.017], [64656.0, 0.088], [64657.6, 21.022]], "asks": [[64660.0, 0.028], [64661.9, 0.003], [64663.1, 0.331], [64663.3, 2.716], [64663.9, 0.102], [64664.1, 0.069], [64665.6, 0.037], [64665.7, 0.648], [64667.0, 1.995], [64668.0, 0.247], [64668.2, 0.342], [64671.5, 0.015], [64672.9, 0.008], [64685.6, 0.079], [64688.9, 0.629], [64689.1, 0.279], [64689.3, 0.108], [64700.7, 0.075], [64704.2, 0.058], [64814.2, 7.371], [64852.4, 1.369], [64853.0, 5.345], [65304.3, 0.374], [65354.1, 0.0], [65657.7, 0.032]]}
{"kind": "depth", "E": 1787082400461, "U": 11315509442629, "u": 11315509448580, "recv_ms": 1787082400431, "bids": [[1000.0, 35.81], [14357.6, 2.492], [14457.6, 1.708], [51726.0, 0.0], [51726.1, 0.0], [58191.8, 0.002], [61422.4, 2.46], [62071.2, 0.003], [63849.4, 0.469], [64285.1, 0.536], [64498.0, 0.593], [64515.0, 1.716], [64547.6, 2.324], [64571.9, 0.149], [64573.5, 2.456], [64575.2, 0.116], [64576.8, 0.37], [64588.1, 0.154], [64590.4, 1.21], [64599.4, 0.207], [64613.4, 0.032], [64639.5, 0.02], [64648.2, 0.071], [64648.4, 0.433], [64648.5, 0.201], [64648.7, 0.421], [64648.8, 0.105], [64648.9, 0.17], [64649.0, 0.07], [64650.3, 0.035], [64650.6, 0.344], [64653.9, 1.654], [64655.7, 0.003], [64656.0, 0.338], [64656.4, 0.02], [64656.6, 0.0], [64656.9, 0.186], [64657.5, 0.06]], "asks": [[64663.1, 0.311], [64663.3, 2.693], [64665.5, 0.468], [64665.6, 0.045], [64665.7, 0.683], [64666.0, 0.041], [64667.3, 0.172], [64667.4, 0.375], [64667.5, 0.298], [64667.6, 0.407], [64667.8, 0.32], [64667.9, 0.146], [64668.1, 0.106], [64674.4, 0.003], [64674.7, 0.001], [64684.3, 0.035], [64684.6, 0.046], [64686.0, 0.452], [64686.4, 1.206], [64688.3, 0.113], [64688.5, 0.169], [64688.6, 0.233], [64688.7, 0.211], [64688.8, 0.164], [64688.9, 0.629], [64689.0, 0.697], [64689.2, 0.134], [64700.7, 0.075], [64702.9, 0.198], [64703.3, 0.038], [64715.9, 0.025], [64719.9, 0.001], [64797.2, 0.0], [64814.2, 0.001], [64981.0, 0.429], [65304.3, 0.374], [65475.8, 0.767], [65595.2, 5.332]]}
{"kind": "depth", "E": 1787082400563, "U": 11315509448768, "u": 11315509453616, "recv_ms": 1787082400535, "bids": [[1000.0, 35.81], [14357.6, 2.856], [14457.6, 1.344], [58191.8, 0.002], [61424.7, 0.007], [63543.9, 0.06], [63619.4, 1.099], [63657.6, 0.0], [64011.0, 0.065], [64076.4, 0.004], [64078.9, 0.12], [64128.6, 0.311], [64236.6, 0.015], [64239.1, 0.008], [64334.3, 0.324], [64397.2, 0.0], [64399.7, 0.005], [64498.1, 9.935], [64515.1, 5.108], [64558.2, 0.231], [64560.7, 0.065], [64594.1, 0.41], [64612.4, 0.581], [64638.1, 5.018], [64644.0, 0.503], [64646.3, 0.42], [64648.1, 0.141], [64648.3, 0.144], [64648.6, 0.16], [64649.6, 0.9], [64650.7, 0.055], [64651.7, 1.065], [64653.4, 0.029], [64653.8, 1.137], [64656.0, 0.338], [64657.6, 21.024]], "asks": [[64657.7, 11.073], [64659.9, 0.001], [64660.0, 0.028], [64662.0, 0.081], [64663.2, 0.121], [64666.7, 0.356], [64667.7, 0.173], [64668.0, 0.373], [64668.2, 0.44], [64685.3, 0.048], [64688.8, 0.334], [64689.0, 0.697], [64689.1, 0.405], [64689.2, 0.232], [64703.9, 0.047], [64752.1, 0.016], [64754.6, 0.046], [64797.3, 5.405], [64814.2, 10.415], [64852.4, 0.655], [64853.0, 1.708], [64914.0, 0.431], [64916.5, 0.004], [65076.3, 0.008], [65078.8, 0.011], [65239.0, 0.076], [65241.5, 0.016], [65304.3, 0.374], [65362.5, 1.299], [65595.2, 6.398], [65657.7, 0.012]]}
{"kind": "depth", "E": 1787082400665, "U": 11315509453624, "u": 11315509458139, "recv_ms": 1787082400634, "bids": [[14357.6, 3.22], [14457.6, 0.98], [58191.8, 0.002], [62071.2, 0.0], [63362.0, 0.114], [63676.1, 1.42], [63758.9, 1.565], [63878.1, 20.707], [64011.0, 0.065], [64136.7, 7.975], [64330.6, 4.578], [64334.3, 0.324], [64590.7, 0.1], [64593.5, 0.689], [64594.4, 0.099], [64622.1, 0.002], [64630.2, 0.873], [64648.4, 0.503], [64648.7, 0.491]], "asks": [[64661.9, 0.013], [64663.2, 0.102], [64663.3, 2.693], [64663.5, 0.003], [64663.7, 0.06], [64667.6, 0.505], [64667.9, 0.244], [64688.7, 1.148], [64689.0, 0.243], [64750.6, 0.13], [64853.0, 1.896], [65304.3, 0.374]]}
{"kind": "depth", "E": 1787082400767, "U": 11315509458193, "u": 11315509463029, "recv_ms": 1787082400737, "bids": [[1000.0, 35.81], [14357.6, 3.57], [14457.6, 0.63], [58191.8, 0.002], [61424.7, 0.009], [62071.2, 0.003], [63526.1, 1.258], [63657.6, 0.02], [63716.4, 15.284], [63884.5, 3.753], [64011.0, 0.065], [64515.1, 0.0], [64556.9, 0.003], [64594.8, 0.033], [64599.4, 0.21], [64627.0, 0.08], [64627.2, 2.038], [64630.3, 0.128], [64636.5, 0.545], [64643.4, 0.47], [64652.0, 0.02], [64655.7, 0.002], [64657.6, 21.024]], "asks": [[64659.9, 0.085], [64660.0, 0.028], [64661.9, 0.003], [64663.6, 0.022], [64663.8, 0.024], [64689.0, 0.397], [64735.3, 0.003], [64797.3, 0.004], [65304.3, 0.374], [65657.7, 0.032]]}
{"kind": "depth", "E": 1787082400869, "U": 11315509463350, "u": 11315509468848, "recv_ms": 1787082400839, "bids": [[1000.0, 35.81], [14257.6, 0.084], [14357.6, 3.752], [14457.6, 0.364], [58191.8, 0.002], [62071.2, 0.0], [63623.1, 3.737], [63684.1, 7.672], [63699.0, 1.286], [63867.3, 17.609], [63884.5, 2.815], [64011.0, 0.065], [64334.3, 0.479], [64515.1, 5.155], [64581.6, 0.084], [64588.1, 0.334], [64593.8, 2.375], [64627.1, 0.075], [64627.4, 1.327], [64627.5, 0.101], [64627.7, 0.201], [64627.8, 0.224], [64628.0, 0.851], [64629.9, 0.122], [64630.5, 0.0], [64636.6, 0.484], [64636.8, 0.75], [64638.3, 0.17], [64638.7, 2.337], [64643.4, 0.594], [64644.3, 0.004], [64645.0, 0.046], [64646.3, 0.343], [64652.0, 0.019], [64655.4, 0.024], [64655.5, 0.023], [64655.6, 0.103], [64656.0, 0.004], [64656.2, 0.0], [64656.4, 0.0], [64656.9, 0.102]], "asks": [[64657.7, 12.121], [64661.9, 0.013], [64678.4, 0.241], [64681.4, 10.054], [64686.2, 0.015], [64688.8, 0.32], [64706.9, 0.001], [64723.2, 0.229], [64724.0, 0.001], [64725.0, 0.111], [64728.4, 36.57], [64750.6, 0.03], [64797.3, 5.405], [64853.0, 1.722], [65304.3, 0.376], [65433.6, 3.499], [65615.6, 1.385]]}
{"kind": "depth", "E": 1787082400971, "U": 11315509468874, "u": 11315509474486, "recv_ms": 1787082400942, "bids": [[14257.6, 0.308], [14357.6, 3.668], [14457.6, 0.224], [34000.0, 1.146], [58191.8, 0.002], [62071.2, 0.003], [63362.0, 0.111], [63657.6, 0.0], [63687.7, 1.214], [63881.7, 2.876], [64011.0, 0.065], [64140.3, 1.682], [64334.3, 0.479], [64627.1, 0.145], [64627.2, 2.108], [64627.5, 0.201], [64644.3, 0.012], [64646.2, 0.165], [64646.3, 0.42], [64646.4, 0.295], [64654.3, 0.237], [64655.4, 0.565], [64656.0, 0.261], [64656.5, 0.31]], "asks": [[64659.0, 0.387], [64659.4, 0.087], [64663.4, 0.127], [64726.1, 36.553], [64727.6, 0.001], [64728.4, 0.017], [64814.2, 10.415], [64853.0, 1.781], [65304.3, 0.374], [65627.6, 0.381], [65657.7, 0.012]]}
{"kind": "depth", "E": 1787082401073, "U": 11315509474583, "u": 11315509481429, "recv_ms": 1787082401042, "bids": [[1000.0, 35.81], [14257.6, 0.56], [14357.6, 3.528], [14457.6, 0.112], [51726.0, 0.004], [58191.8, 0.002], [61424.7, 0.009], [63364.5, 0.046], [63446.9, 0.007], [63720.1, 3.297], [63849.4, 1.251], [63878.1, 20.238], [63888.2, 3.752], [64011.0, 0.065], [64525.3, 0.024], [64588.1, 0.231], [64616.6, 0.029], [64624.9, 2.15], [64627.3, 0.073], [64627.6, 0.074], [64628.0, 1.187], [64631.7, 0.023], [64637.6, 0.815], [64639.2, 0.024], [64644.3, 0.012], [64646.0, 1.875], [64646.2, 0.165], [64646.4, 0.295], [64652.8, 0.003], [64653.0, 0.007], [64655.4, 0.024], [64655.5, 0.564], [64656.0, 0.415], [64656.3, 0.087], [64657.6, 21.019]], "asks": [[64657.7, 11.958], [64660.0, 0.028], [64661.9, 0.003], [64663.4, 0.107], [64663.6, 0.022], [64666.1, 0.001], [64682.3, 1.681], [64684.8, 0.007], [64688.8, 0.334], [64706.9, 0.015], [65304.3, 0.374], [65461.3, 0.0]]}
{"kind": "depth", "E": 1787082401175, "U": 11315509481443, "u": 11315509487207, "recv_ms": 1787082401146, "bids": [[1000.0, 35.81], [14257.6, 0.798], [14357.6, 3.402], [14457.6, 0.0], [51726.0, 0.0], [58191.8, 0.002], [61424.7, 0.009], [62071.2, 0.0], [63194.3, 0.002], [63657.6, 0.02], [63707.1, 1.457], [63888.2, 4.69], [64011.0, 0.065], [64334.3, 0.469], [64526.6, 0.018], [64528.2, 0.002], [64602.4, 0.006], [64605.9, 0.027], [64606.0, 0.094], [64608.9, 0.01], [64635.6, 0.853], [64642.9, 0.759], [64644.3, 0.004], [64645.0, 0.045], [64646.2, 0.706], [64646.4, 0.303], [64647.9, 0.753], [64648.2, 0.072], [64648.7, 0.171], [64655.4, 0.024], [64655.5, 0.023], [64656.7, 0.089], [64657.6, 21.02]], "asks": [[64659.4, 0.003], [64660.9, 0.017], [64662.0, 0.074], [64663.2, 0.122], [64663.3, 2.693], [64663.5, 0.026], [64669.8, 0.628], [64677.1, 1.339], [64681.4, 0.054], [64706.0, 2.291], [64716.2, 0.049], [64981.0, 0.428], [65304.3, 0.374], [65396.8, 0.0], [65451.1, 6.508], [65657.7, 0.032]]}
{"kind": "depth", "E": 1787082401277, "U": 11315509487311, "u": 11315509495782, "recv_ms": 1787082401248, "bids": [[14257.6, 1.162], [14357.6, 3.038], [58191.8, 0.002], [62071.2, 0.003], [63826.4, 0.0], [63881.7, 3.345], [63884.5, 1.877], [64011.0, 0.065], [64334.3, 0.47], [64610.5, 1.253], [64641.2, 0.008], [64648.2, 0.071], [64652.0, 0.02], [64655.7, 0.002], [64655.9, 0.0], [64657.6, 21.021]], "asks": [[64657.7, 11.96], [64659.9, 0.087], [64661.5, 0.022], [64661.8, 0.033], [64662.9, 0.165], [64663.2, 0.102], [64663.5, 0.003], [64663.6, 0.002], [64663.8, 0.002], [64673.7, 0.006], [64684.8, 10.007], [64688.8, 0.32], [64726.0, 5.817], [64814.1, 2.326], [64814.2, 7.346], [64853.0, 4.877], [65304.3, 0.373]]}
{"kind": "depth", "E": 1787082401379, "U": 11315509495832, "u": 11315509508970, "recv_ms": 1787082401348, "bids": [[1000.0, 35.81], [14257.6, 1.512], [14357.6, 2.688], [58191.8, 0.002], [61424.7, 0.009], [62071.2, 0.0], [63202.8, 0.633], [63364.5, 0.043], [63657.6, 0.0], [63687.8, 0.008], [63716.4, 14.187], [64011.0, 0.065], [64533.5, 0.0], [64631.7, 0.047], [64637.9, 0.154], [64638.3, 0.016], [64646.6, 0.003], [64652.0, 0.019], [64655.8, 0.021], [64656.0, 0.415], [64656.7, 0.005], [64657.6, 21.021]], "asks": [[64660.0, 0.028], [64688.5, 0.169], [64688.6, 0.387], [64689.0, 0.243], [64724.0, 36.413], [64725.0, 0.102], [64726.0, 0.001], [64726.1, 0.0], [65304.3, 0.373], [65657.7, 0.012]]}
{"kind": "depth", "E": 1787082401481, "U": 11315509509158, "u": 11315509526266, "recv_ms": 1787082401453, "bids": [[14257.6, 1.862], [14357.6, 2.338], [51726.1, 0.0], [58191.8, 0.002], [61424.7, 0.015], [62071.2, 0.003], [63396.8, 0.629], [64011.0, 0.065], [64334.3, 0.48], [64498.1, 0.676], [64498.2, 9.692], [64498.3, 1.933], [64515.1, 0.0], [64515.2, 5.227], [64518.2, 1.406], [64571.9, 0.072], [64575.2, 0.039], [64576.8, 0.293], [64588.1, 0.154], [64636.0, 2.557], [64636.7, 1.869], [64643.1, 1.594], [64646.6, 0.002], [64648.0, 0.008], [64649.3, 0.347], [64649.7, 0.003], [64650.1, 1.171], [64655.0, 1.11]], "asks": [[64670.0, 0.027], [64676.6, 0.05], [64677.7, 0.558], [64678.2, 2.384], [64678.8, 0.005], [64679.7, 0.116], [64680.4, 1.273], [64688.6, 0.233], [64688.7, 1.302], [64797.3, 5.405], [64814.1, 0.885], [64814.2, 0.001], [64814.3, 10.577], [64853.0, 0.0], [64853.1, 1.424], [64981.0, 0.582], [65304.3, 0.373], [65561.0, 0.919], [65591.5, 18.575], [65595.2, 7.464], [65656.1, 11.104], [65659.9, 4.26]]}
{"kind": "depth", "E": 1787082401583, "U": 11315509526320, "u": 11315509537398, "recv_ms": 1787082401553, "bids": [[14257.6, 2.226], [14357.6, 1.974], [51726.0, 0.0], [58191.8, 0.002], [63364.5, 0.037], [63657.6, 0.02], [63720.1, 4.394], [63806.6, 0.788], [63888.2, 5.628], [64011.0, 0.065], [64334.3, 0.479], [64515.2, 3.802], [64637.9, 0.0], [64638.0, 0.522], [64643.1, 1.593], [64646.3, 0.497], [64649.1, 0.003]], "asks": [[64660.0, 0.028], [64688.6, 0.233], [64688.7, 1.302], [64814.3, 7.509], [64853.1, 4.623], [65304.3, 0.373], [65657.7, 0.032], [67244.0, 12.136]]}
{"kind": "depth", "E": 1787082401685, "U": 11315509537404, "u": 11315509545604, "recv_ms": 1787082401656, "bids": [[1000.0, 35.81], [14257.6, 2.59], [14357.6, 1.61], [51726.0, 0.0], [58191.8, 0.002], [61424.7, 0.015], [62071.2, 0.0], [64011.0, 0.065], [64515.2, 5.322], [64547.6, 2.321], [64599.4, 0.21], [64617.8, 0.006], [64642.9, 0.14], [64649.1, 0.002], [64650.5, 0.003], [64656.0, 0.492], [64657.6, 21.022]], "asks": [[64657.7, 12.07], [64659.5, 0.085], [64715.9, 0.025], [64735.3, 0.0], [64814.3, 10.577], [64853.1, 1.424], [64981.0, 0.583], [65304.3, 0.373], [65950.8, 0.024]]}
{"kind": "depth", "E": 1787082401787, "U": 11315509545676, "u": 11315509551763, "recv_ms": 1787082401757, "bids": [[14257.6, 2.94], [14357.6, 1.26], [51726.0, 0.0], [58191.8, 0.002], [62071.2, 0.003], [63364.5, 0.034], [63657.6, 0.0], [63739.5, 0.234], [64011.0, 0.065], [64140.3, 1.682], [64334.3, 0.469], [64383.6, 0.001], [64392.3, 0.001], [64409.5, 0.001], [64418.2, 0.001], [64435.3, 0.0], [64444.0, 3.567], [64461.2, 0.002], [64469.9, 0.5], [64487.1, 0.002], [64495.8, 0.607], [64515.2, 0.0], [64534.5, 0.086], [64650.5, 0.002], [64651.8, 0.28]], "asks": [[64659.1, 0.0], [64660.1, 1.016], [64797.3, 0.004], [64819.5, 0.308], [64845.4, 0.001], [64871.3, 0.004], [64897.1, 0.003], [64923.0, 0.022], [65304.3, 0.373], [65657.7, 0.012]]}
{"kind": "depth", "E": 1787082401889, "U": 11315509551902, "u": 11315509557747, "recv_ms": 1787082401859, "bids": [[14257.6, 3.29], [14357.6, 0.91], [58191.8, 0.002], [61424.7, 0.015], [62071.2, 0.0], [63362.0, 0.102], [63364.5, 0.025], [63770.2, 0.955], [64011.0, 0.065], [64518.2, 0.716], [64624.7, 0.043], [64624.8, 0.014], [64624.9, 2.15], [64628.2, 0.004], [64628.3, 0.004], [64628.4, 0.002], [64653.0, 0.004], [64655.7, 0.025], [64655.8, 0.001], [64657.5, 0.061], [64657.6, 21.022]], "asks": [[65304.3, 0.373], [65948.3, 0.043]]}
{"kind": "depth", "E": 1787082402195, "U": 11315509574248, "u": 11315509580195, "recv_ms": 1787082402165, "bids": [[14157.6, 0.364], [14257.6, 3.64], [14357.6, 0.196], [58191.8, 0.002], [61424.7, 0.015], [62071.2, 0.0], [63448.5, 0.755], [63657.6, 0.0], [63849.4, 1.486], [64011.0, 0.065], [64528.2, 0.002], [64585.8, 4.273], [64605.6, 0.003], [64605.9, 0.026], [64608.9, 0.005], [64642.9, 0.759], [64649.4, 0.1], [64651.8, 0.279], [64653.8, 1.135], [64655.9, 0.02]], "asks": [[64657.7, 12.067], [64660.1, 1.016], [64666.9, 0.005], [64696.2, 0.023], [64705.2, 0.341], [64814.3, 10.577], [64853.1, 1.519], [65171.2, 6.307], [65304.3, 0.373], [65645.2, 1.057], [65657.7, 0.012], [66593.5, 0.028]]}
{"kind": "depth", "E": 1787082402297, "U": 11315509580338, "u": 11315509585036, "recv_ms": 1787082402266, "bids": [[1000.0, 35.81], [14157.6, 0.602], [14257.6, 3.514], [14357.6, 0.084], [51726.0, 0.0], [58191.8, 0.002], [61424.7, 0.015], [62071.2, 0.003], [63364.5, 0.028], [64011.0, 0.065], [64334.3, 0.478], [64641.2, 0.008], [64642.9, 0.14], [64649.4, 0.099], [64652.1, 0.086], [64656.0, 0.415], [64657.6, 21.023]], "asks": [[64657.7, 12.065], [64669.8, 0.009], [64673.7, 0.006], [64682.3, 3.089], [64723.9, 6.069], [64814.1, 2.326], [64814.3, 7.583], [64853.1, 4.72], [65304.3, 0.373], [65429.8, 24.099], [65530.6, 0.767], [65547.7, 7.52], [65767.4, 0.0]]}
{"kind": "depth", "E": 1787082402399, "U": 11315509585109, "u": 11315509593708, "recv_ms": 1787082402370, "bids": [[14157.6, 0.882], [14257.6, 3.318], [14357.6, 0.0], [58191.8, 0.002], [62071.2, 0.0], [63587.1, 2.387], [63657.6, 0.02], [64011.0, 0.065], [64140.3, 1.993], [64334.3, 0.478], [64515.2, 0.0], [64515.3, 5.334], [64588.1, 0.231], [64646.4, 0.31], [64650.3, 0.036], [64652.1, 0.085], [64655.4, 0.017], [64655.5, 0.001], [64655.6, 0.084], [64655.7, 0.002], [64655.9, 0.0], [64656.0, 0.184]], "asks": [[64660.1, 1.016], [64688.6, 0.387], [64688.7, 1.148], [64814.3, 10.577], [64852.4, 0.655], [64853.1, 0.962], [64981.0, 0.584], [65175.0, 3.861], [65304.3, 0.373], [65433.6, 4.322], [65657.7, 0.032], [65659.9, 5.325], [65720.8, 2.128], [65776.3, 0.761]]}
{"kind": "depth", "E": 1787082402501, "U": 11315509593937, "u": 11315509600298, "recv_ms": 1787082402472, "bids": [[1000.0, 35.96], [14157.6, 1.246], [14257.6, 2.954], [51726.1, 0.0], [58191.8, 0.002], [63276.8, 0.0], [63562.8, 0.628], [63884.5, 0.939], [64011.0, 0.065], [64515.3, 0.0], [64648.6, 0.161], [64650.3, 0.035]], "asks": [[64688.6, 0.387], [64797.3, 0.004], [65304.3, 0.375], [65548.1, 20.838], [65556.4, 1.768], [65562.9, 3.107]]}
{"kind": "depth", "E": 1787082402603, "U": 11315509600346, "u": 11315509607558, "recv_ms": 1787082402575, "bids": [[1000.0, 35.81], [14157.6, 1.596], [14257.6, 2.604], [51726.0, 0.0], [58191.8, 0.002], [61424.7, 0.017], [62071.2, 0.003], [63590.7, 2.199], [63657.6, 0.0], [64011.0, 0.065], [64498.2, 0.147], [64498.3, 0.093], [64498.4, 10.196], [64515.3, 5.321], [64638.0, 0.368], [64644.3, 0.012], [64646.2, 0.172], [64646.4, 0.295], [64655.4, 0.581], [64655.5, 0.021], [64656.0, 0.261]], "asks": [[64688.6, 0.233], [64688.7, 1.148], [64688.8, 0.474], [64797.3, 5.405], [64814.3, 10.577], [65304.3, 0.373], [65657.7, 0.012], [65724.6, 2.129]]}
{"kind": "depth", "E": 1787082402705, "U": 11315509607720, "u": 11315509614156, "recv_ms": 1787082402675, "bids": [[14157.6, 1.946], [14257.6, 2.254], [58191.8, 0.002], [62071.2, 0.0], [63888.2, 6.566], [64011.0, 0.065], [64334.3, 0.469], [64547.6, 2.324], [64560.6, 0.005], [64637.8, 0.158], [64648.6, 0.16], [64652.5, 0.311], [64655.6, 0.107], [64655.7, 0.022], [64656.0, 0.415]], "asks": [[64688.7, 1.302], [64688.8, 0.32], [64735.3, 0.003], [64981.0, 0.583], [65304.3, 0.373], [65378.9, 0.766], [65451.1, 6.28], [65486.3, 4.58], [71123.5, 0.003]]}
{"kind": "depth", "E": 1787082402807, "U": 11315509614209, "u": 11315509619587, "recv_ms": 1787082402777, "bids": [[1000.0, 35.81], [14157.6, 2.31], [14257.6, 1.89], [58191.8, 0.002], [61424.7, 0.017], [62071.2, 0.003], [63571.4, 3.402], [63657.6, 0.02], [63944.6, 0.0], [64011.0, 0.065], [64515.3, 0.0], [64515.4, 4.533], [64534.5, 0.001], [64637.8, 0.004], [64638.0, 0.522], [64644.3, 0.004], [64646.2, 0.706], [64646.4, 0.303], [64652.5, 0.31], [64653.8, 1.136], [64655.4, 0.047], [64655.7, 0.002], [64655.8, 0.021], [64657.6, 21.023]], "asks": [[64660.1, 1.016], [64688.7, 1.148], [64688.8, 0.474], [64767.7, 0.01], [64797.3, 5.405], [64853.1, 4.065], [65163.1, 0.306], [65263.6, 0.025], [65304.3, 0.373], [65443.8, 0.763], [65524.9, 3.176], [65657.7, 0.032], [71123.5, 0.001]]}
{"kind": "depth", "E": 1787082403011, "U": 11315509625546, "u": 11315509631519, "recv_ms": 1787082402981, "bids": [[14157.6, 3.024], [14257.6, 1.176], [58191.8, 0.002], [62071.2, 0.0], [63657.6, 0.0], [63807.1, 1.413], [63857.9, 0.003], [63935.5, 0.0], [63952.8, 0.702], [64011.0, 0.065], [64334.3, 0.469], [64547.6, 2.324], [64599.4, 0.207], [64638.0, 0.368]], "asks": [[64715.9, 0.025], [64735.3, 0.0], [64767.7, 0.007], [65271.9, 0.687], [65304.3, 0.373], [65657.7, 0.012], [71123.5, 0.001]]}
{"kind": "depth", "E": 1787082403113, "U": 11315509631768, "u": 11315509640739, "recv_ms": 1787082403128, "bids": [[1000.0, 35.81], [14157.6, 3.374], [14257.6, 0.826], [58191.8, 0.002], [61424.7, 0.017], [62071.2, 0.003], [63364.5, 0.031], [64011.0, 0.065], [64498.4, 10.229], [64515.4, 5.337], [64573.5, 2.379], [64576.8, 0.255], [64581.6, 0.007], [64585.7, 0.012], [64588.1, 0.346], [64608.7, 0.819], [64608.8, 0.028], [64614.9, 0.063], [64617.5, 0.001], [64622.1, 0.122], [64628.5, 0.018], [64630.2, 0.753], [64631.7, 0.024], [64631.9, 0.647], [64636.2, 0.035], [64637.3, 0.001], [64637.8, 0.561], [64638.0, 0.522], [64641.0, 0.917], [64642.8, 0.933], [64646.0, 1.875], [64646.2, 0.165], [64646.4, 0.31], [64651.5, 0.001], [64652.4, 0.004], [64653.3, 0.256], [64654.2, 0.001], [64655.4, 0.017], [64655.5, 0.544], [64655.7, 0.0], [64656.0, 0.184], [64656.4, 0.023], [64656.7, 0.024], [64657.1, 0.085], [64657.5, 0.145], [64657.6, 21.024]], "asks": [[64657.7, 5.79], [64657.8, 0.002], [64659.0, 0.077], [64659.5, 0.001], [64659.9, 0.003], [64660.0, 0.026], [64660.1, 1.016], [64660.2, 0.003], [64660.4, 2.322], [64660.5, 0.0], [64660.8, 0.004], [64660.9, 0.006], [64661.2, 0.004], [64661.5, 0.01], [64661.8, 0.01], [64662.0, 0.082], [64662.1, 0.484], [64662.2, 0.216], [64662.4, 1.116], [64663.0, 0.636], [64663.1, 0.314], [64663.4, 0.109], [64663.7, 0.144], [64664.1, 0.155], [64664.5, 0.091], [64665.6, 0.021], [64665.7, 0.135], [64665.8, 1.896], [64674.3, 0.005], [64674.8, 0.041], [64675.2, 0.938], [64677.1, 0.72], [64677.2, 0.011], [64678.1, 0.559], [64684.8, 10.009], [64685.6, 0.077], [64688.6, 0.387], [64688.8, 0.32], [64797.3, 5.405], [64814.1, 0.885], [64814.3, 10.577], [64846.3, 0.002], [64846.4, 3.459], [64853.1, 0.964], [65263.3, 5.776], [65304.3, 0.373], [65369.0, 0.692], [65547.7, 6.637], [65548.1, 18.572], [65651.1, 6.39], [65756.9, 0.668]]}
{"kind": "depth", "E": 1787082403215, "U": 11315509640863, "u": 11315509647979, "recv_ms": 1787082403185, "bids": [[1000.0, 35.81], [14157.6, 3.71], [14257.6, 0.476], [14557.6, 0.014], [58191.8, 0.002], [61606.7, 0.002], [61609.0, 0.015], [62071.2, 0.0], [63657.6, 0.02], [63673.4, 0.317], [64011.0, 0.065], [64498.5, 2.161], [64518.2, 1.422], [64528.2, 0.002], [64605.7, 0.003], [64608.7, 0.82], [64637.1, 0.557], [64637.8, 0.004], [64646.2, 0.706], [64655.5, 0.003], [64655.6, 0.084], [64655.8, 0.001], [64656.0, 0.415]], "asks": [[64660.0, 0.051], [64660.9, 0.008], [64661.1, 0.086], [64662.3, 0.697], [64663.0, 0.095], [64663.1, 0.311], [64688.6, 0.233], [64688.7, 1.148], [64688.8, 0.32], [64723.9, 0.0], [64724.0, 36.529], [64726.7, 6.889], [64728.3, 0.002], [64814.1, 2.326], [65304.3, 0.373], [65657.7, 0.032], [67684.2, 0.0], [67686.9, 0.04]]}
{"kind": "depth", "E": 1787082403317, "U": 11315509648162, "u": 11315509656430, "recv_ms": 1787082403287, "bids": [[14157.6, 3.71], [14257.6, 0.294], [14557.6, 0.196], [51726.0, 0.0], [58191.8, 0.002], [61422.3, 0.002], [61422.4, 2.462], [61424.7, 0.017], [62071.2, 0.003], [63362.0, 0.099], [63364.5, 0.016], [64011.0, 0.067], [64334.3, 0.479], [64535.2, 0.088], [64628.0, 0.851], [64641.2, 0.008], [64642.1, 0.926], [64642.8, 0.007], [64643.0, 3.008], [64656.7, 0.005], [64657.5, 0.144], [64657.6, 21.024]], "asks": [[64660.0, 0.061], [64660.1, 1.016], [64669.8, 0.628], [64673.7, 0.006], [64677.1, 1.339], [64688.8, 0.474], [64724.0, 0.001], [64726.7, 1.666], [64728.3, 36.53], [65271.9, 1.375], [65304.3, 0.373], [65451.1, 6.022], [65659.9, 5.932], [65948.3, 0.028], [65950.8, 0.009]]}
{"kind": "depth", "E": 1787082403419, "U": 11315509656460, "u": 11315509664212, "recv_ms": 1787082403393, "bids": [[1000.0, 35.81], [14157.6, 3.612], [14257.6, 0.168], [14557.6, 0.42], [51726.0, 0.0], [58191.8, 0.002], [61422.3, 0.0], [61422.4, 2.464], [61424.7, 0.019], [63657.6, 0.0], [63835.0, 6.851], [64011.0, 0.065], [64334.3, 0.48], [64638.0, 0.368], [64638.2, 0.281], [64653.8, 0.903], [64654.2, 0.233], [64656.6, 0.02], [64657.6, 21.023]], "asks": [[64659.9, 0.001], [64688.8, 0.474], [64724.0, 36.529], [64728.3, 0.002], [64981.0, 0.582], [65304.3, 0.373], [65556.4, 2.651], [65562.9, 5.392], [65657.7, 0.012]]}
{"kind": "depth", "E": 1787082403521, "U": 11315509664296, "u": 11315509670401, "recv_ms": 1787082403492, "bids": [[1000.0, 35.81], [14157.6, 3.486], [14257.6, 0.056], [14557.6, 0.658], [51726.1, 0.0], [58191.8, 0.002], [61424.7, 0.021], [61424.8, 0.0], [62071.2, 0.0], [63687.7, 1.903], [63750.4, 7.482], [64011.0, 0.065], [64498.4, 0.423], [64498.5, 0.004], [64515.4, 0.003], [64518.2, 0.716], [64657.6, 21.024]], "asks": [[64657.7, 5.829], [64660.1, 1.016], [64675.6, 1.858], [64686.6, 1.702], [64697.5, 2.312], [64708.5, 2.002], [64797.3, 0.004], [64814.1, 0.885], [64814.3, 0.163], [65304.3, 0.373]]}
{"kind": "depth", "E": 1787082403623, "U": 11315509670704, "u": 11315509676653, "recv_ms": 1787082403593, "bids": [[14157.6, 3.234], [14257.6, 0.0], [14557.6, 0.966], [58191.8, 0.002], [62071.2, 0.003], [63364.5, 0.019], [63657.6, 0.02], [63673.2, 1.12], [63760.7, 0.849], [63776.1, 10.486], [63870.1, 9.787], [64011.0, 0.065], [64334.3, 0.47], [64458.8, 0.399], [64460.1, 0.548], [64637.9, 0.154], [64638.2, 0.127], [64646.3, 0.42], [64646.4, 0.303], [64655.4, 0.024], [64655.5, 0.025], [64655.7, 0.019], [64656.0, 0.184], [64656.4, 0.0], [64656.6, 0.0]], "asks": [[64657.7, 5.828], [64724.0, 0.001], [64726.1, 36.528], [64728.3, 0.002], [64853.1, 0.0], [65304.3, 0.373], [65547.7, 5.114], [65657.7, 0.032]]}
{"kind": "depth", "E": 1787082403725, "U": 11315509676824, "u": 11315509686523, "recv_ms": 1787082403695, "bids": [[1000.0, 35.81], [14157.6, 2.87], [14557.6, 1.33], [58191.8, 0.002], [61424.7, 0.021], [62071.2, 0.0], [63364.5, 0.022], [64011.0, 0.065], [64334.3, 0.469], [64459.7, 10.796], [64460.1, 2.226], [64498.5, 9.436], [64515.4, 5.107], [64629.4, 0.549], [64631.9, 0.311], [64634.0, 0.131], [64635.6, 0.234], [64641.4, 0.145], [64643.0, 2.389], [64646.3, 0.497], [64646.4, 0.31], [64652.5, 0.311], [64655.4, 0.017], [64656.0, 0.261], [64657.5, 0.06], [64657.6, 21.023]], "asks": [[64657.7, 7.865], [64658.1, 0.002], [64660.2, 0.001], [64660.3, 0.004], [64660.4, 2.406], [64662.0, 0.082], [64662.5, 0.005], [64663.4, 0.107], [64669.8, 0.009], [64797.3, 5.405], [64814.3, 10.577], [64853.1, 1.911], [64981.0, 0.583], [65263.3, 5.241], [65304.3, 0.373], [65521.8, 7.976], [65950.8, 0.003]]}
{"kind": "depth", "E": 1787082403827, "U": 11315509686571, "u": 11315509693712, "recv_ms": 1787082403797, "bids": [[1000.0, 35.81], [14157.6, 2.52], [14557.6, 1.68], [51726.0, 0.0], [58191.8, 0.002], [62071.2, 0.003], [63655.4, 4.392], [63657.6, 0.0], [63758.9, 3.131], [64011.0, 0.065], [64615.3, 0.385], [64615.4, 0.087], [64634.0, 0.051], [64637.8, 0.158], [64637.9, 0.0], [64641.4, 0.225], [64642.7, 0.213], [64646.4, 0.303], [64655.4, 0.024], [64655.7, 0.042], [64655.9, 0.019], [64656.0, 0.338], [64656.8, 0.002], [64657.5, 0.064], [64657.6, 21.044]], "asks": [[64660.0, 0.061], [64696.2, 0.019], [64705.2, 0.345], [64726.1, 36.528], [64728.3, 0.002], [65304.3, 0.373], [65530.6, 1.528], [65657.7, 0.012]]}
{"kind": "depth", "E": 1787082404031, "U": 11315509703811, "u": 11315509714897, "recv_ms": 1787082404001, "bids": [[1000.0, 35.81], [14157.6, 1.806], [14557.6, 2.394], [58191.8, 0.002], [62071.2, 0.0], [63657.6, 0.02], [64011.0, 0.065], [64285.2, 0.0], [64329.8, 1.556], [64332.4, 0.109]], "asks": [[64696.2, 0.023], [64705.2, 0.341], [64982.6, 0.108], [65271.9, 1.91], [65304.3, 0.373], [65657.7, 0.032], [65748.4, 1.323]]}
{"kind": "depth", "E": 1787082404133, "U": 11315509715195, "u": 11315509722882, "recv_ms": 1787082404103, "bids": [[1000.0, 35.81], [14157.6, 1.456], [14557.6, 2.744], [51726.0, 0.0], [58191.8, 0.002], [62071.2, 0.003], [63738.0, 8.568], [64011.0, 0.065], [64608.7, 0.821], [64614.9, 0.064], [64634.0, 0.051], [64641.4, 0.145], [64642.7, 0.293], [64646.0, 1.875], [64651.2, 0.004], [64655.4, 0.025]], "asks": [[64814.3, 7.376], [64853.1, 5.104], [65304.3, 0.373], [65423.4, 5.496]]}
{"kind": "depth", "E": 1787082404235, "U": 11315509722955, "u": 11315509728362, "recv_ms": 1787082404205, "bids": [[14157.6, 1.092], [14557.6, 3.108], [51726.0, 0.0], [58191.8, 0.002], [62071.2, 0.0], [63257.5, 2.383], [63258.2, 0.0], [63657.6, 0.0], [63738.0, 8.38], [64011.0, 0.065], [64256.6, 0.011], [64334.3, 0.469], [64498.6, 3.095], [64518.2, 1.388], [64528.2, 0.002], [64547.6, 2.321], [64599.4, 0.21], [64651.9, 0.003], [64655.4, 0.024]], "asks": [[64660.0, 0.061], [64661.6, 0.108], [64661.9, 0.026], [64715.9, 0.025], [64726.0, 5.813], [64814.1, 1.848], [64852.4, 1.333], [65304.3, 0.373], [65618.2, 1.292], [65657.7, 0.012]]}
{"kind": "depth", "E": 1787082404337, "U": 11315509728626, "u": 11315509737934, "recv_ms": 1787082404306, "bids": [[1000.0, 35.81], [14157.6, 0.742], [14557.6, 3.458], [51726.0, 0.0], [58191.8, 0.002], [61424.7, 0.019], [63258.1, 0.677], [64011.0, 0.065], [64515.4, 0.003], [64515.5, 5.319], [64636.9, 0.56], [64637.1, 0.0], [64637.9, 0.0], [64641.2, 0.008], [64651.9, 0.002], [64655.1, 1.024], [64656.0, 0.415], [64657.6, 21.044]], "asks": [[64673.1, 0.0], [64673.7, 0.006], [64677.2, 0.568], [64678.1, 0.002], [64679.4, 0.117], [64679.7, 0.0], [64680.3, 0.163], [64814.3, 10.577], [64852.4, 0.655], [64853.1, 1.058], [65304.3, 0.373]]}
{"kind": "depth", "E": 1787082404541, "U": 11315509745012, "u": 11315509751123, "recv_ms": 1787082404511, "bids": [[14157.6, 0.266], [14457.6, 0.238], [14557.6, 3.696], [51726.1, 0.0], [58191.8, 0.002], [61424.7, 0.021], [62071.2, 0.0], [64011.0, 0.065], [64334.3, 0.478], [64638.4, 0.696], [64644.3, 0.004], [64646.2, 0.165], [64646.4, 0.836], [64646.5, 0.012], [64655.4, 0.024], [64655.5, 0.025], [64656.7, 0.089]], "asks": [[64659.9, 0.087], [64660.3, 0.012], [64661.9, 0.033], [64662.0, 0.615], [64663.2, 0.102], [64665.6, 0.021], [64682.4, 4.747], [64688.8, 0.32], [64688.9, 0.629], [64814.3, 10.577], [64853.1, 1.06], [65304.3, 0.373], [65465.9, 3.396]]}
{"kind": "depth", "E": 1787082404643, "U": 11315509751490, "u": 11315509758000, "recv_ms": 1787082404614, "bids": [[1000.0, 35.81], [14157.6, 0.14], [14457.6, 0.476], [14557.6, 3.584], [58191.8, 0.002], [61424.7, 0.021], [62071.2, 0.003], [63657.6, 0.0], [63835.0, 6.5], [63839.2, 0.789], [63929.4, 0.0], [64011.0, 0.065], [64515.5, 0.0], [64515.6, 5.161], [64518.2, 0.716], [64547.9, 0.379], [64548.8, 3.522], [64588.1, 0.115], [64636.2, 0.151], [64636.7, 1.869], [64641.5, 1.061], [64642.1, 0.0], [64646.5, 0.019], [64648.0, 0.008], [64649.7, 0.003], [64650.2, 0.545], [64652.1, 0.001], [64653.3, 0.256], [64655.4, 0.017], [64656.0, 0.338], [64657.1, 0.085], [64657.6, 21.128]], "asks": [[64657.7, 5.827], [64658.1, 0.0], [64659.9, 0.003], [64660.2, 0.003], [64660.3, 0.004], [64660.4, 2.322], [64661.9, 0.041], [64662.0, 0.074], [64662.2, 0.213], [64662.3, 0.697], [64662.5, 0.003], [64663.4, 0.109], [64673.9, 0.002], [64674.8, 0.967], [64675.2, 0.012], [64681.1, 0.002], [64682.3, 1.681], [64682.4, 4.593], [64684.8, 0.009], [64763.9, 0.001], [64767.4, 14.909], [64787.1, 0.0], [64797.3, 0.004], [64797.4, 5.401], [64853.1, 1.799], [65175.0, 4.166], [65304.3, 0.373], [65508.2, 0.772], [65657.7, 0.012]]}
{"kind": "depth", "E": 1787082404745, "U": 11315509758107, "u": 11315509763703, "recv_ms": 1787082404715, "bids": [[1000.0, 35.81], [14157.6, 0.028], [14457.6, 0.714], [14557.6, 3.458], [58191.8, 0.002], [61424.7, 0.022], [62071.2, 0.0], [63758.9, 4.697], [63945.2, 0.876], [64011.0, 0.065], [64334.3, 0.479], [64515.6, 0.029], [64644.8, 0.504], [64654.2, 0.001], [64654.6, 0.233], [64655.5, 0.003], [64655.7, 0.023], [64656.0, 0.415], [64656.3, 0.11], [64657.1, 0.001], [64657.6, 21.019]], "asks": [[64660.0, 0.145], [64660.1, 1.016], [64662.9, 0.168], [64670.7, 1.862], [64677.1, 0.844], [64682.5, 0.143], [64685.9, 3.235], [64687.5, 10.005], [64724.0, 0.001], [64726.0, 0.001], [64726.1, 0.0], [64728.3, 36.621], [64797.4, 0.0], [64981.0, 0.583], [65304.3, 0.373], [65950.8, 0.003]]}
{"kind": "depth", "E": 1787082404847, "U": 11315509763838, "u": 11315509772256, "recv_ms": 1787082404817, "bids": [[14157.6, 0.0], [14457.6, 1.036], [14557.6, 3.164], [58191.8, 0.002], [61424.7, 0.021], [63657.6, 0.02], [64011.0, 0.065], [64334.3, 0.479], [64515.6, 5.161], [64524.5, 0.002], [64547.6, 2.324], [64655.7, 0.0], [64656.0, 0.492], [64656.5, 0.334], [64656.6, 0.019], [64657.2, 0.102], [64657.5, 0.06]], "asks": [[64657.7, 5.794], [64660.0, 0.061], [64660.7, 0.11], [64667.0, 1.992], [64682.6, 0.154], [64726.1, 36.619], [64727.6, 0.001], [64728.3, 0.002], [64735.3, 0.003], [64751.0, 0.003], [64797.4, 5.401], [64853.1, 1.8], [65304.3, 0.373], [65657.7, 0.032]]}
{"kind": "depth", "E": 1787082404949, "U": 11315509772400, "u": 11315509780198, "recv_ms": 1787082404918, "bids": [[1000.0, 35.81], [14457.6, 1.414], [14557.6, 2.786], [58191.8, 0.002], [62071.2, 0.003], [63942.8, 0.239], [64011.0, 0.065], [64641.4, 0.225], [64642.7, 0.213], [64644.8, 0.35], [64656.0, 0.415], [64656.3, 0.087], [64656.5, 0.311], [64656.6, 0.0]], "asks": [[64660.1, 1.016], [65615.6, 1.043]]}
{"kind": "depth", "E": 1787082405051, "U": 11315509780417, "u": 11315509791806, "recv_ms": 1787082405020, "bids": [[1000.0, 35.81], [14457.6, 1.764], [14557.6, 2.436], [58191.8, 0.002], [61424.7, 0.021], [62071.2, 0.0], [63657.6, 0.0], [64011.0, 0.065], [64588.1, 0.192], [64616.6, 0.004], [64625.0, 1.615], [64633.6, 2.277], [64646.0, 1.88], [64646.5, 0.019], [64654.6, 0.001], [64655.2, 2.736], [64655.4, 0.017], [64655.6, 0.107], [64655.8, 0.021], [64655.9, 0.0], [64656.0, 0.415], [64656.1, 0.002]], "asks": [[64657.7, 5.61], [64660.7, 0.026], [64661.1, 0.002], [64661.4, 0.007], [64661.6, 0.089], [64661.9, 0.018], [64662.1, 0.465], [64662.4, 1.093], [64662.8, 0.022], [64663.1, 0.334], [64664.5, 0.091], [64853.1, 1.019], [65304.3, 0.373], [65465.9, 3.654], [65548.1, 18.389], [65657.7, 0.012], [106000.0, 1.433]]}
{"kind": "depth", "E": 1787082405153, "U": 11315509792206, "u": 11315509803209, "recv_ms": 1787082405128, "bids": [[14457.6, 2.128], [14557.6, 2.072], [51726.0, 0.0], [58191.8, 0.002], [61424.7, 0.021], [62071.2, 0.003], [63849.4, 1.752], [64011.0, 0.065], [64322.6, 0.001], [64334.3, 0.479], [64515.6, 0.029], [64608.6, 0.199], [64608.7, 0.818], [64624.9, 2.151], [64629.4, 0.213], [64633.0, 2.203], [64641.1, 0.108], [64646.0, 1.875], [64656.1, 0.025], [64656.3, 0.106]], "asks": [[64657.7, 5.76], [64659.9, 0.001], [64705.9, 2.233], [64706.0, 0.225], [64714.0, 2.219], [64714.1, 0.0], [64779.0, 2.597], [64779.1, 4.899], [64797.4, 0.0], [65304.3, 0.373], [65575.8, 1.981], [65627.6, 1.065]]}
{"kind": "depth", "E": 1787082405255, "U": 11315509803311, "u": 11315509812274, "recv_ms": 1787082405226, "bids": [[1000.0, 35.81], [14457.6, 2.478], [14557.6, 1.722], [58191.8, 0.002], [62071.2, 0.0], [63657.6, 0.02], [63725.1, 1.419], [63737.9, 0.0], [64011.0, 0.065], [64459.7, 0.002], [64460.1, 0.548], [64498.5, 0.004], [64498.6, 1.687], [64653.6, 0.002], [64653.9, 1.652], [64654.1, 0.002], [64654.2, 0.003], [64655.6, 0.084], [64655.8, 0.001], [64656.3, 0.129], [64656.5, 0.329], [64657.5, 0.064], [64657.6, 21.019]], "asks": [[64657.7, 5.758], [64660.1, 1.016], [64661.9, 0.037], [64662.3, 0.697], [64662.6, 0.085], [64662.8, 0.002], [64663.1, 0.311], [64713.9, 1.044], [64745.6, 0.0], [64814.1, 0.885], [64814.3, 0.163], [64853.1, 0.0], [65304.3, 0.373], [65657.7, 0.032]]}
{"kind": "depth", "E": 1787082405357, "U": 11315509812474, "u": 11315509819129, "recv_ms": 1787082405328, "bids": [[1000.0, 35.81], [14457.6, 2.828], [14557.6, 1.372], [58191.8, 0.002], [63742.5, 0.783], [63881.7, 4.047], [64011.0, 0.065], [64590.7, 0.0], [64641.2, 0.006], [64652.6, 0.002], [64654.1, 0.001]], "asks": [[64661.2, 0.088], [64661.5, 0.03], [64661.9, 0.059], [64673.7, 0.004], [65304.3, 0.373], [65521.8, 7.367]]}
{"kind": "depth", "E": 1787082405459, "U": 11315509819142, "u": 11315509824847, "recv_ms": 1787082405430, "bids": [[14457.6, 3.192], [14557.6, 1.008], [58191.8, 0.002], [62071.2, 0.003], [63364.5, 0.019], [63657.6, 0.0], [63711.5, 10.502], [63720.1, 5.491], [63737.4, 0.016], [64011.0, 0.066], [64334.3, 0.469], [64547.6, 2.321], [64551.4, 0.035], [64552.0, 3.573], [64556.7, 0.0], [64557.3, 0.027], [64562.0, 0.006], [64567.3, 0.0], [64572.6, 0.032], [64577.9, 0.0], [64583.2, 1.803], [64588.5, 0.006], [64593.8, 2.36], [64599.1, 0.0], [64599.4, 0.21], [64604.4, 0.099], [64609.7, 0.003], [64615.0, 0.017], [64620.3, 1.584], [64625.6, 1.989], [64630.9, 2.328], [64636.2, 0.136], [64641.2, 0.008], [64641.5, 1.046], [64644.7, 1.143], [64647.1, 0.228]], "asks": [[64660.1, 1.016], [64673.3, 0.016], [64673.4, 0.101], [64673.7, 0.006], [64678.6, 0.023], [64678.7, 0.0], [64684.0, 0.017], [64689.3, 0.093], [64694.6, 0.001], [64699.9, 0.373], [64705.2, 0.326], [64710.5, 2.025], [64715.8, 0.0], [64715.9, 0.025], [64721.1, 0.002], [64726.4, 0.078], [64731.7, 0.0], [64735.3, 0.0], [64737.0, 0.0], [64742.3, 0.003], [64747.6, 1.141], [64752.9, 0.536], [64758.2, 0.0], [64763.5, 0.0], [64769.1, 0.004], [64981.0, 0.582], [65304.3, 0.373], [65657.7, 0.012]]}
{"kind": "depth", "E": 1787082405561, "U": 11315509825001, "u": 11315509831166, "recv_ms": 1787082405532, "bids": [[1000.0, 35.81], [14457.6, 3.542], [14557.6, 0.658], [51726.1, 0.0], [58191.8, 0.002], [61424.7, 0.021], [62071.2, 0.0], [63720.1, 5.609], [63766.4, 0.0], [64011.0, 0.066], [64334.3, 0.47], [64459.8, 10.882], [64498.6, 11.116], [64515.6, 5.206], [64553.9, 0.001], [64554.1, 0.007], [64559.3, 0.002], [64559.5, 0.028], [64562.6, 2.334], [64564.7, 0.001], [64570.1, 0.001], [64575.5, 0.041], [64580.9, 0.587], [64586.3, 0.032], [64588.1, 0.442], [64591.7, 0.009], [64592.9, 0.12], [64597.1, 0.0], [64602.5, 0.001], [64607.9, 0.002], [64613.3, 0.467], [64617.2, 0.015], [64617.3, 0.099], [64618.7, 0.001], [64624.1, 0.002], [64629.5, 0.174], [64634.9, 0.022], [64635.7, 0.8], [64640.3, 0.012], [64643.0, 3.008], [64644.6, 0.185], [64644.7, 0.989], [64644.8, 0.35], [64645.7, 0.0], [64646.3, 0.343], [64646.5, 0.012], [64647.9, 0.753], [64651.1, 0.028], [64652.6, 0.001], [64654.8, 0.002], [64655.4, 0.024], [64656.0, 0.081]], "asks": [[64657.7, 5.755], [64659.1, 0.006], [64669.8, 0.628], [64677.2, 1.187], [64683.9, 2.335], [64722.4, 0.013], [64770.1, 0.034], [64770.3, 1.082], [64797.4, 5.401], [64814.3, 10.577], [64846.4, 3.456], [64846.5, 0.003], [64853.1, 1.02], [65304.3, 0.373], [65530.6, 2.136], [65748.0, 5.333]]}
{"kind": "depth", "E": 1787082405663, "U": 11315509831427, "u": 11315509838380, "recv_ms": 1787082405636, "bids": [[1000.0, 35.81], [14357.6, 0.07], [14457.6, 3.766], [14557.6, 0.364], [51726.0, 0.0], [58191.8, 0.002], [62071.2, 0.003], [63657.6, 0.02], [64011.0, 0.066], [64460.1, 2.239], [64515.6, 0.029], [64518.2, 0.716], [64548.8, 1.202], [64548.9, 2.322], [64564.9, 0.006], [64567.9, 0.023], [64573.2, 0.015], [64588.1, 0.449], [64644.5, 0.154], [64644.6, 0.031], [64646.3, 0.42], [64654.8, 0.001], [64656.0, 0.184], [64656.1, 0.026]], "asks": [[64661.5, 0.01], [64661.9, 0.018], [64689.2, 0.247], [64694.5, 0.085], [64767.4, 12.589], [64767.8, 2.32], [64787.1, 0.0], [64797.4, 0.0], [64814.1, 2.326], [65304.3, 0.373], [65615.6, 0.701], [65657.7, 0.032], [65756.9, 1.427]]}
{"kind": "depth", "E": 1787082405765, "U": 11315509838505, "u": 11315509846054, "recv_ms": 1787082405736, "bids": [[14357.6, 0.308], [14457.6, 3.654], [14557.6, 0.238], [58191.8, 0.002], [61424.7, 0.021], [63350.1, 2.664], [63422.0, 0.039], [63493.8, 0.004], [63565.6, 0.316], [63637.4, 0.006], [63709.3, 0.0], [63720.1, 6.393], [63738.0, 8.372], [63752.4, 2.725], [63781.1, 7.603], [63852.9, 0.0], [63924.7, 0.0], [63996.6, 1.626], [64011.0, 0.066], [64334.3, 0.469], [64515.6, 5.206], [64570.3, 2.324], [64575.7, 0.005], [64578.5, 0.018], [64656.1, 0.025], [64656.7, 0.091], [64657.6, 21.023]], "asks": [[64660.0, 0.061], [64662.1, 0.465], [64662.4, 1.093], [64662.8, 0.025], [64699.8, 2.396], [64797.4, 5.401], [64853.1, 1.021], [64981.0, 0.583], [65163.1, 0.0], [65289.4, 0.005], [65304.3, 0.373], [65361.3, 0.454], [65433.1, 0.0], [65504.9, 2.286], [65576.7, 0.0], [65648.6, 1.057], [65720.4, 0.01], [65756.9, 2.033], [65792.2, 0.0], [65864.0, 0.0], [65935.9, 0.001], [65950.8, 0.006]]}
{"kind": "depth", "E": 1787082405867, "U": 11315509846130, "u": 11315509854187, "recv_ms": 1787082405836, "bids": [[1000.0, 35.81], [14357.6, 0.532], [14457.6, 3.556], [14557.6, 0.112], [58191.8, 0.002], [62071.2, 0.0], [63364.5, 0.016], [63657.6, 0.0], [64011.0, 0.066], [64034.8, 5.811], [64581.1, 2.327], [64583.8, 0.016], [64589.1, 0.016]], "asks": [[64662.5, 0.023], [64705.1, 2.364], [64710.4, 0.043], [65304.3, 0.373], [65451.1, 5.68], [65657.7, 0.012]]}
{"kind": "depth", "E": 1787082405969, "U": 11315509854297, "u": 11315509861996, "recv_ms": 1787082405939, "bids": [[1000.0, 35.81], [14357.6, 0.77], [14457.6, 3.43], [14557.6, 0.0], [58191.8, 0.002], [62071.2, 0.003], [63752.4, 2.913], [63944.3, 4.221], [64011.0, 0.066], [64586.5, 0.08], [64591.9, 0.007], [64594.4, 0.114], [64644.5, 0.0], [64644.6, 0.185], [64646.3, 0.343], [64646.5, 0.332], [64647.9, 0.433], [64656.0, 0.081]], "asks": [[64662.1, 0.488], [64662.8, 0.002], [64715.7, 0.015], [65304.3, 0.373], [65618.2, 0.95], [65627.6, 1.407]]}
{"kind": "depth", "E": 1787082406071, "U": 11315509862189, "u": 11315509868909, "recv_ms": 1787082406041, "bids": [[14357.6, 1.134], [14457.6, 3.066], [58191.8, 0.002], [61424.7, 0.021], [62071.2, 0.0], [63225.8, 0.0], [63657.6, 0.02], [64011.0, 0.066], [64043.4, 0.701], [64334.3, 0.469], [64597.3, 0.005], [64599.7, 0.418], [64605.0, 0.891], [64629.8, 0.816], [64633.6, 1.941], [64635.7, 0.181], [64643.0, 2.389], [64646.0, 1.875], [64646.5, 0.339], [64649.7, 0.544], [64650.2, 0.004], [64655.4, 0.017]], "asks": [[64657.7, 6.463], [64660.0, 0.061], [64660.3, 0.012], [64661.9, 0.01], [64669.8, 0.009], [64696.2, 0.019], [64705.2, 0.33], [64721.0, 0.058], [64726.3, 0.016], [64853.1, 0.463], [65304.3, 0.373], [65657.7, 0.032]]}
{"kind": "depth", "E": 1787082406173, "U": 11315509869089, "u": 11315509876853, "recv_ms": 1787082406143, "bids": [[1000.0, 35.81], [14357.6, 1.484], [14457.6, 2.716], [58191.8, 0.002], [62071.2, 0.003], [63225.8, 0.052], [63652.6, 0.0], [63655.1, 0.062], [63789.9, 0.013], [63952.8, 1.248], [64011.0, 0.066], [64375.0, 0.077], [64476.7, 2.254], [64483.3, 5.537], [64544.4, 0.013], [64585.7, 0.011], [64602.7, 0.226], [64605.7, 0.001], [64608.1, 0.007], [64608.6, 0.2], [64610.3, 0.022], [64614.9, 0.062], [64616.9, 0.02], [64646.5, 0.339], [64655.4, 0.017]], "asks": [[64660.4, 2.406], [64661.7, 0.021], [64662.5, 0.003], [64663.6, 0.003], [64666.9, 0.004], [64688.0, 0.041], [64696.2, 0.023], [64705.2, 0.326], [64731.6, 0.018], [65304.3, 0.375], [65423.4, 4.58], [65627.6, 1.749], [65657.7, 0.021], [65660.2, 1.33]]}
{"kind": "depth", "E": 1787082406275, "U": 11315509876904, "u": 11315509888645, "recv_ms": 1787082406245, "bids": [[1000.0, 35.81], [14357.6, 1.848], [14457.6, 2.352], [51726.0, 0.0], [58191.8, 0.002], [61424.7, 0.021], [63657.6, 0.0], [63673.2, 0.022], [63676.1, 1.067], [63738.0, 8.184], [63867.3, 17.39], [64011.0, 0.066], [64498.6, 10.422], [64498.7, 2.253], [64591.6, 0.001], [64613.5, 0.936], [64615.6, 0.041], [64620.9, 0.03], [64636.4, 3.468], [64636.9, 0.003], [64644.2, 0.631], [64644.6, 0.031], [64644.7, 1.004], [64646.3, 0.42], [64646.5, 0.339], [64647.1, 0.769], [64649.7, 0.003], [64653.6, 0.004], [64655.4, 0.017], [64656.0, 0.107], [64656.5, 0.31], [64657.5, 0.06], [64657.6, 21.023]], "asks": [[64660.0, 0.061], [64663.6, 0.002], [64726.0, 5.827], [64736.9, 0.461], [64742.2, 1.086], [64853.1, 0.464], [65304.3, 0.373], [65657.7, 0.001], [65660.2, 1.35]]}
{"kind": "depth", "E": 1787082406377, "U": 11315509888890, "u": 11315509899282, "recv_ms": 1787082406347, "bids": [[14357.6, 2.212], [14457.6, 1.988], [51726.0, 0.0], [58191.8, 0.002], [61424.7, 0.021], [62071.2, 0.0], [63364.5, 0.013], [63657.6, 0.02], [63849.4, 2.103], [64011.0, 0.065], [64334.3, 0.479], [64596.7, 0.004], [64597.7, 0.962], [64603.2, 1.453], [64604.2, 0.222], [64616.1, 0.001], [64617.1, 0.403], [64618.9, 0.005], [64624.3, 0.006], [64626.2, 0.015], [64634.0, 0.051], [64641.2, 0.006], [64641.4, 0.145], [64642.1, 0.007], [64642.7, 0.293], [64643.1, 1.586], [64645.9, 0.329], [64646.3, 0.497], [64646.5, 0.019], [64647.1, 0.228], [64650.1, 1.171], [64655.9, 0.0], [64656.0, 0.338], [64656.1, 0.002], [64656.2, 0.0], [64656.3, 0.087], [64657.2, 0.018], [64657.6, 21.025]], "asks": [[64657.7, 6.464], [64660.1, 1.1], [64661.4, 0.027], [64661.6, 0.111], [64664.5, 0.007], [64673.7, 0.004], [64677.2, 0.63], [64677.7, 0.558], [64747.5, 0.015], [65304.3, 0.373], [65494.5, 26.232], [65657.7, 0.021]]}
{"kind": "depth", "E": 1787082406479, "U": 11315509899300, "u": 11315509909144, "recv_ms": 1787082406450, "bids": [[1000.0, 35.81], [14357.6, 2.562], [14457.6, 1.638], [51726.0, 0.0], [58191.8, 0.002], [61424.7, 0.022], [62071.2, 0.003], [63026.9, 0.396], [63655.4, 5.49], [63687.7, 2.256], [64011.0, 0.065], [64515.6, 0.029], [64515.7, 5.177], [64629.7, 0.022], [64629.8, 0.48], [64631.5, 0.018], [64636.2, 0.02], [64636.4, 2.911], [64636.8, 0.208], [64637.1, 0.116], [64637.8, 0.561], [64641.2, 0.008], [64641.4, 0.225], [64642.1, 0.022], [64642.7, 0.213], [64644.2, 0.477], [64652.5, 0.394], [64654.0, 3.737], [64655.0, 1.132], [64655.1, 1.043], [64655.2, 2.504], [64656.7, 0.007]], "asks": [[64657.7, 7.74], [64658.1, 0.002], [64659.1, 0.316], [64659.5, 0.085], [64660.0, 0.061], [64660.2, 0.001], [64661.4, 0.007], [64661.5, 0.03], [64661.6, 0.089], [64661.8, 0.032], [64662.5, 0.005], [64663.2, 0.102], [64663.4, 0.107], [64664.1, 0.071], [64665.6, 0.029], [64665.7, 0.59], [64673.7, 0.006], [64677.7, 0.001], [64678.1, 0.559], [64679.4, 0.001], [64680.3, 0.279], [64682.3, 3.113], [64683.0, 10.024], [64687.5, 0.005], [64706.9, 0.001], [64725.0, 0.111], [64726.1, 0.0], [64730.5, 36.532], [64752.8, 0.017], [64758.1, 0.015], [64763.4, 0.03], [64768.6, 0.002], [64797.4, 4.945], [64814.3, 0.163], [64814.4, 10.889], [64852.4, 1.235], [64853.1, 4.446], [65304.3, 0.373], [65427.1, 4.421], [65488.9, 0.307]]}
{"kind": "depth", "E": 1787082406581, "U": 11315509909253, "u": 11315509915506, "recv_ms": 1787082406580, "bids": [[1000.0, 35.81], [14357.6, 2.912], [14457.6, 1.288], [51726.0, 0.016], [51726.1, 0.0], [58191.8, 0.002], [61424.7, 0.019], [61424.8, 0.004], [62071.2, 0.0], [63041.2, 0.002], [63657.6, 0.0], [64011.0, 0.067], [64334.3, 0.488], [64581.6, 0.084], [64588.1, 0.449], [64627.5, 0.537], [64635.1, 0.007], [64636.2, 0.639], [64636.5, 0.661], [64636.9, 0.56], [64637.1, 0.0], [64637.8, 0.004], [64640.5, 0.14], [64643.5, 0.002], [64643.6, 0.659], [64644.5, 0.0], [64644.6, 0.185], [64644.7, 1.004], [64646.3, 0.497], [64646.5, 0.027], [64647.4, 0.132], [64650.1, 1.172], [64652.2, 0.087], [64652.9, 0.087], [64653.3, 0.253], [64656.0, 0.338], [64656.3, 0.003], [64656.5, 0.0], [64657.6, 21.024]], "asks": [[64657.7, 7.745], [64659.1, 0.4], [64660.9, 0.008], [64661.8, 0.032], [64661.9, 0.003], [64662.0, 0.074], [64662.3, 0.156], [64663.7, 0.06], [64665.6, 0.577], [64670.4, 0.627], [64685.9, 1.399], [64706.9, 0.001], [64726.0, 0.001], [64726.1, 36.648], [64730.5, 0.008], [64768.7, 0.02], [64787.1, 0.0], [64814.4, 13.927], [64852.4, 0.655], [64853.1, 0.476], [64981.0, 0.584], [65304.3, 0.373], [65498.3, 0.611], [65657.7, 0.001]]}
{"kind": "depth", "E": 1787082406683, "U": 11315509915532, "u": 11315509921741, "recv_ms": 1787082406660, "bids": [[14357.6, 3.276], [14457.6, 0.924], [51726.0, 0.0], [58191.8, 0.002], [61424.7, 0.021], [62071.2, 0.003], [63763.2, 1.254], [64011.0, 0.065], [64334.3, 0.468], [64593.5, 0.657], [64593.8, 2.328], [64594.1, 0.378], [64594.4, 0.082], [64594.8, 0.001], [64612.1, 1.912], [64612.4, 0.549], [64612.7, 0.011], [64613.1, 0.234], [64613.4, 0.0], [64614.3, 2.352], [64627.0, 0.01], [64627.1, 0.005], [64627.2, 1.968], [64627.3, 0.003], [64627.4, 1.227], [64627.5, 0.337], [64627.6, 0.004], [64627.7, 0.001], [64627.8, 0.154], [64628.0, 0.781], [64629.9, 0.022], [64630.3, 0.028], [64639.5, 0.019], [64643.4, 0.602], [64644.2, 0.631], [64644.5, 0.0], [64644.6, 0.031], [64645.9, 0.334], [64646.3, 0.42], [64646.5, 0.019], [64648.1, 0.001], [64648.2, 0.001], [64648.3, 0.004], [64648.4, 0.333], [64648.5, 0.001], [64648.6, 0.06], [64648.7, 0.001], [64648.8, 0.075], [64648.9, 0.0], [64649.0, 0.0], [64649.3, 0.315], [64649.6, 0.868], [64650.0, 1.4], [64650.1, 1.171], [64650.3, 0.003], [64650.6, 0.312], [64650.7, 0.087], [64653.9, 1.27], [64654.8, 0.002], [64655.2, 2.526], [64656.0, 0.268], [64657.6, 21.024]], "asks": [[64657.7, 7.635], [64660.3, 0.004], [64661.5, 0.01], [64661.7, 0.002], [64661.8, 0.01], [64662.0, 0.089], [64662.1, 0.465], [64665.5, 0.043], [64665.6, 0.57], [64665.7, 0.555], [64666.0, 0.003], [64666.3, 0.504], [64666.7, 0.311], [64667.0, 1.947], [64667.3, 0.06], [64667.4, 0.185], [64667.5, 0.125], [64667.6, 0.197], [64667.7, 0.003], [64667.8, 0.0], [64667.9, 0.006], [64668.0, 0.142], [64668.1, 0.001], [64668.2, 0.251], [64670.4, 0.008], [64683.7, 0.075], [64684.3, 0.0], [64684.6, 0.008], [64685.0, 0.003], [64685.3, 0.003], [64685.6, 0.032], [64686.0, 0.262], [64686.4, 1.036], [64687.7, 0.418], [64688.3, 0.001], [64688.5, 0.071], [64688.6, 0.053], [64688.7, 0.84], [64688.8, 0.014], [64689.0, 0.005], [64689.1, 0.174], [64689.2, 0.044], [64689.3, 0.002], [64701.9, 0.558], [64702.9, 0.163], [64703.3, 0.0], [64703.6, 0.0], [64703.9, 0.002], [64704.2, 0.013], [64706.9, 0.015], [65304.3, 0.373], [65498.3, 0.916], [65562.9, 5.575], [71123.5, 0.001]]}
{"kind": "depth", "E": 1787082406785, "U": 11315509921884, "u": 11315509929269, "recv_ms": 1787082406759, "bids": [[1000.0, 35.81], [14357.6, 3.612], [14457.6, 0.588], [58191.8, 0.002], [63657.6, 0.02], [63750.0, 11.667], [64011.0, 0.065], [64128.6, 0.0], [64140.3, 1.993], [64334.3, 0.624], [64515.7, 5.169], [64595.5, 0.038], [64599.4, 0.21], [64614.7, 0.034], [64643.4, 0.13], [64645.9, 0.334], [64646.5, 0.491], [64647.1, 0.236], [64648.5, 0.071], [64649.2, 0.411], [64649.4, 0.199], [64651.0, 0.42], [64651.3, 0.005], [64651.6, 1.0], [64654.8, 0.001], [64655.4, 0.009], [64656.0, 0.184], [64657.5, 0.064], [64657.6, 20.943]], "asks": [[64658.6, 0.086], [64659.9, 0.005], [64660.0, 0.069], [64662.0, 0.622], [64662.2, 0.235], [64663.2, 0.102], [64663.4, 0.023], [64665.2, 0.207], [64665.6, 0.106], [64665.7, 0.478], [64666.9, 0.194], [64667.0, 2.127], [64667.7, 0.094], [64678.4, 0.227], [64683.4, 1.273], [64685.1, 0.197], [64686.2, 0.001], [64687.2, 2.499], [64687.9, 0.63], [64701.5, 0.049], [64715.9, 0.025], [64783.4, 0.378], [64797.4, 5.401], [64853.1, 0.0], [64853.2, 1.037], [64981.0, 0.583], [65304.3, 0.375], [65657.7, 0.021]]}
{"kind": "depth", "E": 1787082406887, "U": 11315509929288, "u": 11315509936457, "recv_ms": 1787082406862, "bids": [[14257.6, 0.112], [14357.6, 3.766], [14457.6, 0.322], [58191.8, 0.002], [61424.7, 0.017], [61424.8, 0.008], [62071.2, 0.0], [62600.0, 19.935], [63360.9, 0.069], [63364.5, 0.016], [63432.8, 0.058], [63504.6, 0.058], [63878.1, 18.988], [64011.0, 0.065], [64334.3, 0.634], [64528.2, 0.005], [64581.6, 0.007], [64588.1, 0.192], [64613.7, 0.033], [64614.8, 0.033], [64616.9, 0.018], [64624.7, 0.041], [64624.8, 0.012], [64624.9, 2.149], [64628.2, 0.002], [64628.3, 0.002], [64628.4, 0.0], [64643.4, 0.602], [64643.6, 0.04], [64646.3, 0.497], [64646.5, 0.019], [64647.1, 0.228], [64648.7, 0.071], [64648.9, 0.1], [64649.0, 0.2], [64649.3, 0.415], [64649.4, 0.269], [64649.6, 0.938], [64650.1, 1.203], [64650.5, 0.034], [64651.6, 0.999], [64652.9, 0.087], [64653.5, 0.003], [64655.2, 2.504], [64655.4, 0.017], [64656.0, 0.422], [64656.4, 0.084], [64656.5, 0.31], [64657.6, 20.942]], "asks": [[64657.7, 7.286], [64658.6, 0.002], [64659.1, 0.316], [64659.9, 0.003], [64662.0, 0.622], [64665.6, 0.106], [64665.7, 0.523], [64666.1, 0.046], [64666.6, 0.114], [64666.9, 0.502], [64667.2, 0.175], [64667.3, 0.21], [64667.4, 0.325], [64667.6, 0.302], [64677.2, 0.011], [64683.6, 0.479], [64684.3, 0.045], [64685.3, 0.173], [64686.2, 0.113], [64686.5, 0.233], [64686.8, 0.926], [64687.5, 0.155], [64687.6, 4.061], [64687.8, 0.182], [64688.0, 0.039], [64701.4, 0.065], [64702.5, 5.031], [64853.2, 1.939], [64977.3, 3.589], [65304.3, 0.373]]}
{"kind": "depth", "E": 1787082406989, "U": 11315509936468, "u": 11315509946129, "recv_ms": 1787082406961, "bids": [[14257.6, 0.35], [14357.6, 3.64], [14457.6, 0.21], [58191.8, 0.002], [61424.7, 0.017], [62071.2, 0.003], [63576.4, 0.246], [63648.3, 0.059], [63720.1, 6.451], [63771.8, 1.25], [63791.9, 0.841], [63863.8, 0.062], [63935.6, 0.058], [64007.5, 0.058], [64011.0, 0.065], [64252.9, 0.022], [64330.6, 3.957], [64498.6, 0.993], [64498.7, 0.003], [64498.8, 9.36], [64515.7, 5.123], [64590.7, 0.1], [64596.5, 0.033], [64614.1, 0.059], [64636.2, 0.02], [64646.3, 0.42], [64648.7, 0.141], [64648.9, 0.17], [64649.0, 0.27], [64649.2, 0.511], [64649.9, 2.536], [64656.0, 0.191], [64657.6, 20.943]], "asks": [[64657.7, 7.54], [64666.3, 0.549], [64667.0, 2.297], [64667.3, 0.308], [64667.4, 0.451], [64667.5, 0.223], [64684.2, 0.053], [64686.7, 0.173], [64686.9, 0.105], [64687.0, 0.233], [64687.1, 0.2], [64688.8, 0.0], [64702.1, 0.074], [64750.6, 0.13], [64768.7, 0.133], [64797.4, 5.401], [64814.4, 13.927], [64853.2, 1.94], [65300.5, 2.252], [65304.3, 0.373], [65372.4, 0.058], [65444.2, 0.058], [65516.1, 0.058], [65587.9, 0.058], [65659.7, 0.059], [65731.6, 0.058], [65803.4, 0.058], [65875.2, 0.058], [65947.1, 8.761]]}
{"kind": "depth", "E": 1787082407091, "U": 11315509946256, "u": 11315509960816, "recv_ms": 1787082407062, "bids": [[1000.0, 35.81], [14257.6, 0.588], [14357.6, 3.528], [14457.6, 0.084], [51726.0, 0.0], [58191.8, 0.002], [61424.7, 0.017], [62071.2, 0.0], [63655.1, 0.036], [63657.6, 0.0], [63719.8, 0.031], [63723.1, 0.0], [63739.5, 0.468], [63881.7, 5.298], [64011.0, 0.065], [64224.3, 0.053], [64334.3, 1.255], [64555.5, 10.018], [64555.6, 0.165], [64588.1, 0.423], [64596.8, 1.494], [64629.1, 0.071], [64645.9, 0.014], [64646.0, 1.875], [64647.9, 0.753], [64649.3, 0.485], [64650.2, 0.005], [64653.5, 0.002], [64654.0, 3.505], [64654.4, 0.236], [64656.0, 0.172]], "asks": [[64657.7, 7.168], [64659.9, 0.003], [64660.0, 0.061], [64660.3, 0.012], [64661.8, 0.03], [64666.9, 0.6], [64672.6, 0.695], [64686.5, 0.331], [64687.4, 0.0], [64722.4, 0.004], [64846.5, 0.0], [64846.6, 0.018], [64981.0, 1.198], [65175.0, 4.472], [65304.3, 0.373], [65488.9, 0.002], [65592.3, 0.013], [65595.6, 0.006], [65657.7, 0.001], [65660.2, 1.324]]}
{"kind": "depth", "E": 1787082407193, "U": 11315509961104, "u": 11315509969086, "recv_ms": 1787082407165, "bids": [[14257.6, 0.854], [14357.6, 3.346], [14457.6, 0.0], [51726.0, 0.0], [58191.8, 0.002], [61424.8, 0.006], [63655.1, 0.062], [63657.6, 0.02], [63719.6, 0.013], [63723.0, 0.544], [63745.9, 1.408], [64011.0, 0.065], [64334.3, 1.255], [64366.6, 0.383], [64498.8, 9.468], [64515.7, 0.0], [64515.8, 5.17], [64585.6, 0.001], [64588.1, 0.442], [64595.5, 0.029], [64595.8, 0.072], [64596.9, 0.053], [64605.6, 0.004], [64608.6, 0.201], [64614.8, 0.034], [64628.9, 0.076], [64629.6, 0.411], [64629.7, 0.122], [64629.8, 0.55], [64631.5, 0.118], [64650.2, 0.004], [64652.1, 0.002], [64655.3, 1.651], [64656.0, 0.165], [64657.6, 20.943]], "asks": [[64661.5, 0.033], [64662.2, 0.213], [64664.0, 0.101], [64797.4, 5.401], [64814.4, 13.927], [64853.2, 1.76], [65304.3, 0.373], [65357.0, 0.0], [65498.3, 1.221], [65657.7, 0.021]]}
{"kind": "depth", "E": 1787082407397, "U": 11315509978001, "u": 11315509989468, "recv_ms": 1787082407373, "bids": [[1000.0, 35.81], [14257.6, 1.568], [14357.6, 2.632], [58191.8, 0.002], [62071.2, 0.0], [64011.0, 0.065], [64498.8, 0.042], [64498.9, 0.008], [64515.8, 0.001], [64518.2, 0.716], [64629.3, 0.18], [64629.6, 0.511], [64647.9, 0.753], [64650.2, 0.005], [64652.1, 0.001], [64655.5, 0.022]], "asks": [[64662.2, 0.235], [64719.8, 2.604], [64797.4, 0.0], [64814.1, 0.885], [64814.4, 3.513], [65304.3, 0.373]]}
{"kind": "depth", "E": 1787082407499, "U": 11315509989682, "u": 11315509997587, "recv_ms": 1787082407470, "bids": [[14257.6, 1.932], [14357.6, 2.268], [58191.8, 0.002], [62071.2, 0.003], [63249.1, 0.033], [63252.7, 0.002], [63657.6, 0.0], [64011.0, 0.065], [64152.3, 0.031], [64334.3, 1.245], [64459.8, 0.0], [64460.1, 0.548], [64629.6, 0.581], [64641.2, 0.008], [64650.2, 0.004], [64653.5, 0.003]], "asks": [[64673.7, 0.006], [64853.2, 0.0], [65304.3, 0.373], [65368.9, 3.284], [65465.9, 3.996], [65657.7, 0.001]]}
{"kind": "depth", "E": 1787082407601, "U": 11315509997706, "u": 11315510005470, "recv_ms": 1787082407571, "bids": [[14257.6, 2.296], [14357.6, 1.904], [51726.1, 0.0], [58191.8, 0.002], [61424.7, 0.017], [62071.2, 0.0], [63364.5, 0.019], [63743.8, 48.696], [63752.4, 2.921], [63835.0, 6.149], [64011.0, 0.065], [64152.7, 0.004], [64624.7, 0.043], [64624.8, 0.014], [64624.9, 2.151], [64628.2, 0.004], [64628.3, 0.004], [64628.4, 0.002], [64644.0, 0.657], [64644.2, 0.477], [64646.3, 0.42], [64653.9, 1.268], [64656.0, 0.165]], "asks": [[64657.7, 7.166], [64659.5, 0.001], [64659.9, 0.003], [64662.1, 0.47], [64770.1, 0.029], [64787.1, 0.0], [64981.0, 1.197], [65304.3, 0.373]]}
{"kind": "depth", "E": 1787082407703, "U": 11315510005679, "u": 11315510015016, "recv_ms": 1787082407674, "bids": [[1000.0, 35.81], [14257.6, 2.646], [14357.6, 1.554], [51726.0, 0.0], [58191.8, 0.002], [61424.7, 0.017], [63657.6, 0.02], [64011.0, 0.065], [64334.3, 1.246], [64547.6, 2.324], [64635.7, 0.181], [64643.1, 1.586], [64644.0, 0.503], [64644.5, 0.154], [64644.8, 0.35], [64646.3, 0.343], [64651.6, 1.0], [64652.2, 0.003], [64653.5, 0.002], [64653.9, 1.263], [64656.7, 0.01], [64656.9, 0.186], [64657.5, 0.06], [64657.6, 20.948]], "asks": [[64657.7, 7.394], [64659.1, 0.006], [64660.0, 0.064], [64660.8, 0.088], [64669.9, 0.002], [64670.7, 1.865], [64677.1, 1.401], [64677.2, 0.63], [64678.1, 0.002], [64679.5, 0.119], [64680.3, 0.163], [64704.3, 1.754], [64735.3, 0.003], [65304.3, 0.373], [65405.5, 1.605], [65451.1, 5.451], [65657.7, 0.021]]}
{"kind": "depth", "E": 1787082407805, "U": 11315510015153, "u": 11315510021366, "recv_ms": 1787082407774, "bids": [[14257.6, 2.996], [14357.6, 1.204], [51726.0, 0.0], [58191.8, 0.002], [61424.7, 0.017], [62071.2, 0.003], [64011.0, 0.065], [64334.3, 1.255], [64460.0, 11.937], [64460.1, 2.238], [64498.8, 9.468], [64515.8, 5.17], [64651.6, 0.999], [64653.1, 0.002], [64655.5, 0.003], [64657.6, 20.958]], "asks": [[64657.7, 7.395], [64659.9, 0.001], [64661.5, 0.032], [64662.1, 0.465], [64662.2, 0.213], [64770.1, 0.034], [64797.4, 5.401], [64814.1, 2.326], [64814.4, 13.927], [64853.2, 1.76], [65304.3, 0.373], [65618.2, 0.608]]}
{"kind": "depth", "E": 1787082407907, "U": 11315510021449, "u": 11315510029577, "recv_ms": 1787082407878, "bids": [[1000.0, 35.81], [14257.6, 3.36], [14357.6, 0.84], [58191.8, 0.002], [62071.2, 0.0], [63364.5, 0.016], [63657.6, 0.0], [63752.4, 3.469], [64011.0, 0.065], [64515.8, 5.169], [64655.6, 0.104]], "asks": [[64677.1, 0.844], [64677.7, 0.558], [64797.4, 5.401], [64853.2, 1.762], [65304.3, 0.373], [65414.2, 0.535], [65627.6, 2.091], [65657.7, 0.001], [65950.8, 0.009]]}
{"kind": "depth", "E": 1787082408009, "U": 11315510029647, "u": 11315510035669, "recv_ms": 1787082407981, "bids": [[1000.0, 35.81], [14157.6, 0.014], [14257.6, 3.682], [14357.6, 0.504], [58191.8, 0.002], [61424.7, 0.017], [62071.2, 0.003], [63781.8, 1.963], [63881.7, 5.517], [64011.0, 0.065], [64515.8, 0.001], [64547.6, 2.324], [64599.4, 0.207], [64657.6, 20.953]], "asks": [[64659.9, 0.001], [64715.9, 0.025], [64735.3, 0.0], [64797.4, 0.0], [64981.0, 1.198], [65304.3, 0.373], [65494.1, 3.049], [65618.2, 0.266], [65645.2, 0.001]]}
{"kind": "depth", "E": 1787082408111, "U": 11315510035713, "u": 11315510042092, "recv_ms": 1787082408081, "bids": [[14157.6, 0.168], [14257.6, 3.738], [14357.6, 0.294], [51726.0, 0.004], [58191.8, 0.002], [62071.2, 0.0], [63657.6, 0.02], [63752.4, 3.657], [64011.0, 0.067], [64334.3, 1.255], [64515.8, 5.169], [64608.6, 0.202], [64614.8, 0.035], [64644.1, 1.201], [64644.5, 0.0], [64646.0, 1.875], [64646.3, 0.42], [64649.3, 0.486], [64653.1, 0.001]], "asks": [[64660.1, 1.016], [64663.4, 0.107], [64797.4, 5.401], [65304.3, 0.373], [65501.7, 0.267], [65626.5, 0.0], [65627.6, 2.433], [65657.7, 0.021], [67886.7, 0.032]]}
{"kind": "depth", "E": 1787082408213, "U": 11315510042094, "u": 11315510047363, "recv_ms": 1787082408199, "bids": [[1000.0, 35.81], [14157.6, 0.406], [14257.6, 3.612], [14357.6, 0.182], [51726.0, 0.0], [58191.8, 0.002], [63364.5, 0.013], [63733.9, 1.1], [64011.0, 0.065], [64605.7, 0.002], [64607.6, 0.053], [64646.3, 0.497], [64656.0, 0.422], [64657.5, 0.064], [64657.6, 20.953]], "asks": [[64659.9, 0.001], [64667.7, 0.095], [64726.1, 0.0], [64730.5, 37.002], [64853.2, 1.872], [65304.3, 0.373], [65589.7, 0.001], [65659.9, 6.997]]}
{"kind": "depth", "E": 1787082408315, "U": 11315510047502, "u": 11315510055797, "recv_ms": 1787082408286, "bids": [[1000.0, 35.81], [14157.6, 0.644], [14257.6, 3.5], [14357.6, 0.056], [51726.0, 0.0], [58191.8, 0.002], [61424.7, 0.017], [62071.2, 0.003], [63657.6, 0.0], [64011.0, 0.065], [64498.9, 2.264], [64518.2, 1.397], [64548.9, 0.002], [64549.1, 2.922], [64585.0, 0.038], [64588.1, 0.192], [64600.5, 0.156], [64644.1, 1.047], [64652.5, 0.31], [64654.1, 0.004], [64655.4, 0.04], [64656.0, 0.576], [64657.4, 0.011]], "asks": [[64657.7, 9.207], [64661.9, 0.003], [64662.0, 0.074], [64665.6, 0.654], [64677.2, 0.011], [64678.4, 0.241], [64682.4, 4.591], [64683.0, 10.026], [64685.9, 1.95], [64686.8, 0.926], [64696.2, 0.019], [64702.2, 0.632], [64704.3, 1.782], [64706.9, 0.001], [64726.0, 0.001], [64726.7, 7.014], [64728.3, 37.317], [64730.5, 0.008], [64767.4, 14.909], [64767.8, 0.0], [64853.2, 2.061], [65010.2, 0.004], [65030.2, 0.002], [65304.3, 0.373], [65423.4, 3.664], [65657.7, 0.001]]}
{"kind": "depth", "E": 1787082408417, "U": 11315510055950, "u": 11315510060013, "recv_ms": 1787082408388, "bids": [[14157.6, 0.938], [14257.6, 3.262], [14357.6, 0.0], [58191.8, 0.002], [61424.7, 0.017], [62071.2, 0.0], [64011.0, 0.065], [64334.3, 1.255], [64642.2, 0.215], [64644.4, 0.464], [64644.7, 1.006], [64645.9, 0.334], [64646.6, 0.003], [64647.9, 0.433], [64649.3, 0.485], [64655.4, 0.017], [64655.6, 0.084], [64657.6, 20.952]], "asks": [[64657.7, 9.208], [64659.9, 0.001], [64660.0, 0.148], [64661.2, 0.108], [64692.6, 4.201], [64693.8, 0.059], [65304.3, 0.373], [65608.2, 1.217]]}
{"kind": "depth", "E": 1787082408519, "U": 11315510060169, "u": 11315510066895, "recv_ms": 1787082408490, "bids": [[1000.0, 35.81], [14157.6, 1.288], [14257.6, 2.912], [58191.8, 0.002], [61424.7, 0.017], [62071.2, 0.003], [63364.5, 0.016], [63657.6, 0.02], [64011.0, 0.065], [64600.5, 0.152], [64610.1, 0.005], [64638.1, 0.018], [64639.9, 1.303], [64641.2, 0.008], [64652.5, 0.394], [64652.9, 0.084], [64655.5, 0.026], [64655.7, 0.019], [64656.0, 0.499], [64656.4, 0.0], [64656.9, 0.102]], "asks": [[64657.7, 12.297], [64659.0, 0.387], [64659.5, 0.085], [64660.0, 0.14], [64660.3, 0.004], [64660.5, 0.004], [64661.2, 0.088], [64661.3, 0.003], [64661.7, 0.312], [64661.9, 0.013], [64662.1, 0.47], [64662.5, 0.003], [64664.1, 0.069], [64665.5, 0.059], [64673.7, 0.006], [64681.3, 12.336], [64695.6, 0.013], [64702.2, 0.628], [64709.6, 0.254], [64710.6, 4.253], [64770.1, 0.029], [65304.3, 0.373], [65451.1, 5.223], [65601.7, 0.342], [65657.7, 0.021]]}
{"kind": "depth", "E": 1787082408621, "U": 11315510067138, "u": 11315510073709, "recv_ms": 1787082408592, "bids": [[1000.0, 35.81], [14157.6, 1.652], [14257.6, 2.548], [51726.0, 0.0], [51726.1, 0.0], [58191.8, 0.002], [63364.5, 0.013], [64011.0, 0.065], [64334.3, 1.254], [64578.9, 0.003], [64579.0, 0.049], [64581.1, 44.815], [64582.0, 8.885], [64644.1, 1.048], [64646.6, 0.002], [64654.4, 0.004], [64655.1, 1.275], [64655.3, 1.651], [64655.5, 0.023], [64655.7, 0.0], [64656.0, 0.499], [64656.1, 0.002]], "asks": [[64657.7, 12.639], [64659.9, 0.001], [64661.1, 0.021], [64661.3, 0.025], [64661.8, 0.01], [64675.7, 0.021], [64682.3, 1.681], [64683.0, 0.026], [64683.7, 0.055], [64787.1, 0.0], [65304.3, 0.373], [65427.1, 5.337]]}
{"kind": "depth", "E": 1787082408723, "U": 11315510073826, "u": 11315510087415, "recv_ms": 1787082408703, "bids": [[14157.6, 2.016], [14257.6, 2.184], [58191.8, 0.002], [61424.7, 0.017], [62071.2, 0.0], [63364.5, 0.01], [64011.0, 0.065], [64334.3, 1.244], [64636.6, 0.561], [64644.1, 1.047], [64644.4, 0.31], [64646.7, 0.001], [64656.1, 0.004], [64657.6, 20.86]], "asks": [[64657.7, 12.642], [64660.8, 0.107], [64661.5, 0.01], [64682.6, 0.0], [65304.3, 0.373], [65515.8, 5.24], [67886.7, 0.027]]}
{"kind": "depth", "E": 1787082408825, "U": 11315510087608, "u": 11315510095715, "recv_ms": 1787082408795, "bids": [[1000.0, 35.81], [14157.6, 2.366], [14257.6, 1.834], [58191.8, 0.002], [61424.7, 0.017], [62071.2, 0.003], [63657.6, 0.0], [64011.0, 0.065], [64167.6, 0.019], [64492.2, 0.002], [64599.4, 0.21], [64635.5, 0.629], [64642.9, 0.759], [64644.6, 0.031], [64644.8, 0.351], [64646.7, 0.0], [64655.3, 1.628], [64656.1, 0.002], [64657.6, 20.86]], "asks": [[64659.9, 0.001], [64660.9, 0.008], [64661.0, 0.414], [64661.9, 0.003], [64669.7, 0.969], [64677.1, 1.463], [64677.2, 5.011], [64682.1, 0.157], [64735.3, 0.003], [64754.7, 10.025], [64852.4, 1.223], [64853.2, 4.367], [64981.0, 1.199], [65304.3, 0.373], [65515.8, 4.95], [65657.7, 0.001]]}
{"kind": "depth", "E": 1787082408927, "U": 11315510095927, "u": 11315510101503, "recv_ms": 1787082408898, "bids": [[1000.0, 35.81], [14157.6, 2.73], [14257.6, 1.47], [58191.8, 0.002], [62071.2, 0.0], [64011.0, 0.065], [64641.9, 0.022], [64644.2, 0.477], [64644.3, 0.158], [64644.8, 0.35], [64654.3, 0.469], [64655.1, 1.043], [64655.5, 0.003], [64656.5, 0.0]], "asks": [[64659.0, 0.471], [64659.9, 0.003], [64660.9, 0.018], [64663.4, 0.023], [64682.1, 0.003], [64682.3, 1.835], [64695.6, 0.009], [64702.2, 0.632], [64745.6, 0.1], [64852.4, 0.655], [64853.2, 1.58], [64981.0, 1.198], [65304.3, 0.373], [65530.6, 2.516], [67886.7, 0.022]]}
{"kind": "depth", "E": 1787082409029, "U": 11315510101644, "u": 11315510108821, "recv_ms": 1787082408998, "bids": [[14157.6, 3.08], [14257.6, 1.12], [58191.8, 0.002], [62071.2, 0.003], [63372.7, 0.0], [63657.6, 0.02], [64011.0, 0.065], [64334.3, 1.255], [64515.8, 0.001], [64515.9, 5.308], [64518.2, 0.716], [64622.6, 0.002], [64630.1, 1.462], [64652.2, 0.087], [64656.0, 0.415], [64656.1, 0.004]], "asks": [[64797.4, 5.401], [64853.2, 1.201], [65304.3, 0.373], [65548.1, 18.206], [65657.7, 0.021]]}
{"kind": "depth", "E": 1787082409233, "U": 11315510114880, "u": 11315510120444, "recv_ms": 1787082409203, "bids": [[1000.0, 35.81], [14157.6, 3.71], [14257.6, 0.448], [14557.6, 0.042], [51726.0, 0.0], [58191.8, 0.002], [61424.7, 0.017], [62071.2, 0.0], [63657.6, 0.0], [63849.4, 2.454], [64011.0, 0.065], [64653.4, 0.261], [64654.3, 0.088], [64655.5, 0.022], [64656.1, 0.086], [64657.6, 20.952]], "asks": [[64659.0, 0.387], [64660.9, 0.008], [64661.9, 0.013], [65304.3, 0.373], [65657.7, 0.001]]}
{"kind": "depth", "E": 1787082409335, "U": 11315510120479, "u": 11315510128444, "recv_ms": 1787082409307, "bids": [[14157.6, 3.71], [14257.6, 0.266], [14557.6, 0.224], [58191.8, 0.002], [61424.7, 0.017], [62071.2, 0.003], [63960.6, 0.115], [64011.0, 0.065], [64290.0, 5.188], [64334.3, 1.245], [64335.3, 0.0], [64518.2, 1.418], [64518.6, 0.013], [64547.6, 2.321], [64599.4, 0.21], [64619.1, 0.546], [64624.7, 0.003], [64636.5, 0.545], [64636.9, 0.003], [64637.9, 0.116], [64638.3, 0.573], [64638.4, 0.696], [64638.8, 0.001], [64641.5, 0.12], [64643.0, 3.315], [64643.4, 0.13], [64643.6, 0.04], [64646.5, 0.491], [64650.2, 0.001], [64652.3, 0.004], [64655.4, 0.04], [64655.5, 0.003], [64656.0, 0.338], [64656.6, 0.084], [64657.6, 20.932]], "asks": [[64657.7, 11.201], [64659.5, 0.001], [64659.9, 0.003], [64660.5, 0.002], [64660.9, 0.008], [64661.3, 0.0], [64661.7, 0.004], [64661.9, 0.003], [64662.0, 0.094], [64662.3, 0.178], [64671.0, 0.246], [64672.0, 0.912], [64674.8, 0.041], [64676.0, 0.927], [64676.4, 0.001], [64677.3, 0.031], [64677.7, 0.001], [64679.0, 0.565], [64679.1, 2.283], [64679.5, 0.003], [64679.8, 0.001], [64680.1, 0.514], [64681.2, 0.657], [64681.3, 2.336], [64682.0, 0.003], [64682.2, 0.215], [64682.3, 1.681], [64686.0, 10.262], [64715.9, 0.025], [64723.4, 1.029], [64735.3, 0.0], [64814.4, 13.927], [64853.2, 1.761], [65304.3, 0.373]]}
{"kind": "depth", "E": 1787082409437, "U": 11315510128499, "u": 11315510134473, "recv_ms": 1787082409407, "bids": [[1000.0, 35.81], [14157.6, 3.584], [14257.6, 0.154], [14557.6, 0.462], [51726.0, 0.0], [58191.8, 0.002], [62071.2, 0.0], [63657.6, 0.02], [64011.0, 0.065], [64631.7, 0.045], [64636.0, 2.557], [64636.4, 3.468], [64636.6, 0.638], [64637.9, 0.0], [64638.3, 0.016], [64640.5, 0.141], [64641.3, 0.926], [64641.9, 0.021], [64643.0, 2.389], [64643.4, 0.602], [64644.2, 0.631], [64644.3, 0.004], [64646.5, 0.019], [64647.1, 0.769], [64650.1, 0.662], [64653.9, 1.259], [64655.6, 0.103]], "asks": [[64659.5, 0.085], [64671.0, 1.146], [64673.7, 0.932], [64676.0, 0.001], [64676.6, 0.607], [64678.8, 0.121], [64678.9, 0.545], [64679.0, 0.008], [64681.2, 0.0], [64682.2, 0.369], [65304.3, 0.373], [65465.9, 4.224], [65657.7, 0.021], [65950.8, 0.015]]}
{"kind": "depth", "E": 1787082409641, "U": 11315510145216, "u": 11315510153816, "recv_ms": 1787082409613, "bids": [[14157.6, 3.178], [14257.6, 0.0], [14557.6, 1.022], [51726.1, 0.0], [58191.8, 0.004], [62071.2, 0.003], [63657.6, 0.0], [63725.1, 1.185], [64011.0, 0.065], [64334.3, 1.245], [64640.5, 0.14], [64649.2, 0.512], [64655.4, 0.017], [64655.5, 0.026], [64657.5, 0.064], [64657.6, 20.932]], "asks": [[64657.7, 11.235], [64673.7, 0.006], [64674.3, 0.931], [64678.9, 0.004], [64679.8, 0.542], [64745.6, 0.0], [64787.1, 0.0], [64853.2, 2.031], [65304.3, 0.373], [65657.7, 0.001], [67886.7, 0.017]]}
{"kind": "depth", "E": 1787082409743, "U": 11315510154064, "u": 11315510160805, "recv_ms": 1787082409713, "bids": [[1000.0, 35.81], [14157.6, 2.814], [14557.6, 1.386], [58191.8, 0.002], [61424.7, 0.015], [61424.8, 0.008], [62071.2, 0.0], [64011.0, 0.065], [64643.1, 1.587], [64647.1, 0.228], [64649.2, 0.511], [64649.7, 0.544], [64657.2, 0.022], [64657.6, 20.937]], "asks": [[64657.7, 12.285], [64659.5, 0.085], [64659.9, 0.003], [64853.2, 1.851], [65304.3, 0.373], [65530.6, 3.124], [65562.9, 7.86]]}
{"kind": "depth", "E": 1787082409845, "U": 11315510160989, "u": 11315510168951, "recv_ms": 1787082409817, "bids": [[1000.0, 35.81], [14157.6, 2.45], [14557.6, 1.75], [51726.0, 0.0], [58191.8, 0.002], [61424.7, 0.013], [61424.8, 0.008], [62071.2, 0.003], [63364.4, 0.971], [63657.6, 0.02], [63687.7, 3.04], [64011.0, 0.065], [64588.1, 0.115], [64643.1, 1.586], [64643.7, 0.157], [64644.2, 0.477], [64644.4, 0.311], [64653.1, 0.004], [64653.9, 1.257], [64655.6, 0.084], [64656.6, 0.0]], "asks": [[64657.7, 11.235], [64853.2, 1.851], [64981.0, 1.197], [65304.3, 0.373], [65657.7, 0.021], [65742.0, 1.831], [65950.8, 0.018]]}
{"kind": "depth", "E": 1787082409947, "U": 11315510169031, "u": 11315510174108, "recv_ms": 1787082409941, "bids": [[14157.6, 2.1], [14557.6, 2.1], [58191.8, 0.002], [62071.2, 0.0], [64011.0, 0.065], [64334.3, 1.245], [64515.9, 0.0], [64516.0, 6.15], [64630.5, 0.0], [64637.9, 0.0], [64644.4, 0.31], [64647.0, 0.917], [64653.1, 0.001], [64655.5, 0.024], [64655.7, 0.021]], "asks": [[64657.7, 12.285], [64659.9, 0.003], [64661.4, 0.026], [64664.7, 0.005], [64672.1, 0.0], [64676.6, 0.05], [64677.4, 0.597], [64695.6, 0.009], [64702.2, 0.632], [64797.4, 0.0], [64797.5, 5.401], [64799.7, 0.005], [64799.8, 2.359], [64853.2, 1.853], [65304.3, 0.373]]}
{"kind": "depth", "E": 1787082410049, "U": 11315510174278, "u": 11315510180454, "recv_ms": 1787082410021, "bids": [[1000.0, 35.81], [14157.6, 1.75], [14557.6, 2.45], [58191.8, 0.002], [61424.7, 0.013], [63657.6, 0.0], [63890.1, 3.129], [64011.0, 0.065], [64516.0, 6.195], [64616.8, 0.166], [64617.3, 0.038], [64646.0, 1.88], [64657.6, 20.923]], "asks": [[64657.7, 12.272], [64720.4, 0.062], [64720.8, 2.32], [64797.5, 5.401], [64853.2, 1.673], [64981.0, 1.198], [65304.3, 0.373], [65657.7, 0.001], [65756.9, 2.489]]}
{"kind": "depth", "E": 1787082410151, "U": 11315510180544, "u": 11315510187744, "recv_ms": 1787082410128, "bids": [[1000.0, 35.81], [14157.6, 1.386], [14557.6, 2.814], [51726.0, 0.0], [58191.8, 0.002], [61424.7, 0.014], [62071.2, 0.003], [64011.0, 0.065], [64459.9, 0.003], [64575.2, 0.039], [64642.0, 0.144], [64646.0, 1.875], [64647.0, 0.916], [64656.0, 0.492], [64657.6, 20.923]], "asks": [[64659.9, 0.003], [64661.2, 0.108], [64661.4, 0.007], [64661.6, 0.111], [64662.0, 0.074], [64665.0, 0.046], [64667.7, 0.094], [64853.2, 4.718], [65304.3, 0.373], [65465.9, 4.452]]}
{"kind": "depth", "E": 1787082410253, "U": 11315510187866, "u": 11315510194117, "recv_ms": 1787082410223, "bids": [[14157.6, 1.036], [14557.6, 3.164], [51726.0, 0.004], [58191.8, 0.002], [61424.7, 0.015], [62071.2, 0.0], [63657.6, 0.02], [64011.0, 0.067], [64334.3, 1.255], [64657.6, 20.924]], "asks": [[64662.3, 0.156], [64853.2, 2.034], [65257.9, 2.644], [65304.3, 0.373], [65423.4, 2.748], [65657.7, 0.021]]}
{"kind": "depth", "E": 1787082410355, "U": 11315510194135, "u": 11315510203565, "recv_ms": 1787082410326, "bids": [[1000.0, 35.81], [14157.6, 0.672], [14557.6, 3.528], [51726.0, 0.0], [58191.8, 0.002], [62071.2, 0.003], [64011.0, 0.065], [64579.0, 7.721], [64640.5, 0.141], [64642.0, 0.143], [64654.3, 0.109], [64655.1, 1.023]], "asks": [[64661.4, 0.029], [64678.8, 0.005], [64679.5, 0.119], [64685.9, 3.374], [65304.3, 0.373], [65486.3, 4.275], [65488.2, 0.305], [65498.3, 1.526], [65548.1, 18.198]]}
{"kind": "depth", "E": 1787082410457, "U": 11315510203782, "u": 11315510211090, "recv_ms": 1787082410426, "bids": [[1000.0, 35.81], [14157.6, 0.392], [14457.6, 0.07], [14557.6, 3.738], [58191.8, 0.002], [61424.7, 0.015], [62071.2, 0.0], [63657.6, 0.0], [64011.0, 0.065], [64460.0, 1.063], [64460.1, 0.548], [64460.3, 10.197], [64498.8, 0.042], [64498.9, 0.857], [64499.1, 7.847], [64516.0, 0.977], [64516.1, 4.422], [64518.2, 0.716], [64640.5, 0.14], [64643.6, 0.041], [64657.6, 20.925]], "asks": [[64659.9, 0.003], [64662.1, 0.465], [64770.1, 0.034], [64797.5, 5.401], [64814.1, 0.885], [64814.4, 13.927], [64853.2, 2.034], [65304.3, 0.374], [65657.7, 0.001]]}
{"kind": "depth", "E": 1787082410661, "U": 11315510218034, "u": 11315510224974, "recv_ms": 1787082410631, "bids": [[1000.0, 35.81], [14157.6, 0.126], [14457.6, 0.518], [14557.6, 3.556], [51726.1, 0.0], [58191.8, 0.002], [61424.7, 0.014], [61424.8, 0.01], [62071.2, 0.003], [63364.5, 0.013], [63657.6, 0.02], [64011.0, 0.067], [64192.5, 0.315], [64499.1, 5.531], [64516.1, 2.896], [64592.9, 0.119], [64615.4, 0.009], [64615.5, 0.095], [64615.6, 0.119], [64639.8, 0.312], [64642.4, 0.003], [64644.5, 0.154], [64654.3, 0.324], [64655.0, 1.11], [64655.7, 0.043], [64655.9, 0.019], [64656.0, 0.415], [64657.6, 20.925]], "asks": [[64659.9, 0.003], [64660.9, 0.01], [64661.2, 0.088], [64661.4, 0.007], [64661.6, 0.089], [64662.9, 0.165], [64722.4, 0.003], [64787.1, 0.0], [64814.4, 13.927], [64852.4, 1.955], [64853.2, 9.272], [65304.3, 0.374], [65498.3, 1.831], [65586.9, 1.431], [65601.7, 0.722], [65657.7, 0.021]]}
{"kind": "depth", "E": 1787082410763, "U": 11315510225018, "u": 11315510230958, "recv_ms": 1787082410735, "bids": [[1000.0, 35.81], [14157.6, 0.0], [14457.6, 0.756], [14557.6, 3.444], [58191.8, 0.002], [61424.7, 0.013], [62071.2, 0.0], [64011.0, 0.065], [64460.3, 10.756], [64499.1, 9.348], [64516.1, 5.126], [64636.0, 2.441], [64637.0, 0.159], [64640.7, 0.163], [64642.4, 0.002], [64656.0, 0.492]], "asks": [[64661.9, 0.022], [64662.2, 0.236], [64852.4, 0.655], [64853.2, 2.023], [65304.3, 0.374], [65498.3, 2.136], [65562.9, 8.043], [65950.8, 0.015]]}
{"kind": "depth", "E": 1787082410865, "U": 11315510231133, "u": 11315510236774, "recv_ms": 1787082410839, "bids": [[14457.6, 1.12], [14557.6, 3.08], [58191.8, 0.002], [61424.7, 0.013], [62071.2, 0.003], [63657.6, 0.0], [63938.2, 0.014], [64011.0, 0.065], [64140.3, 3.238], [64334.3, 1.245], [64495.9, 0.062], [64599.4, 0.21], [64640.7, 0.162], [64643.8, 0.026], [64657.6, 20.924]], "asks": [[64659.9, 0.003], [64693.0, 0.032], [64702.2, 0.628], [64735.3, 0.003], [64787.1, 0.003], [65657.7, 0.001], [71123.5, 0.002]]}
{"kind": "depth", "E": 1787082410967, "U": 11315510236827, "u": 11315510242581, "recv_ms": 1787082410937, "bids": [[1000.0, 35.81], [14457.6, 1.47], [14557.6, 2.73], [58191.8, 0.002], [63687.8, 0.0], [64011.0, 0.065], [64184.2, 0.0], [64334.3, 1.244], [64597.4, 0.388], [64615.6, 0.041], [64615.7, 0.082], [64630.5, 0.149], [64642.3, 0.036], [64643.8, 0.025]], "asks": [[64745.6, 0.1], [65304.3, 0.374], [71123.5, 0.001]]}
{"kind": "depth", "E": 1787082411069, "U": 11315510242677, "u": 11315510249066, "recv_ms": 1787082411046, "bids": [[1000.0, 35.81], [14457.6, 1.82], [14557.6, 2.38], [58191.8, 0.002], [61422.4, 2.462], [61424.7, 0.013], [62071.2, 0.0], [63543.4, 0.3], [63657.6, 0.02], [63878.1, 18.286], [64011.0, 0.065], [64198.5, 0.093], [64334.3, 1.245], [64571.9, 0.034], [64573.5, 2.341], [64575.2, 0.001], [64588.1, 0.038], [64600.5, 0.156], [64610.1, 0.001], [64617.5, 0.132], [64631.7, 0.03], [64638.1, 0.637], [64642.2, 0.233], [64642.3, 0.016], [64643.4, 0.594], [64643.6, 0.041], [64645.5, 0.832], [64646.0, 1.875], [64646.3, 0.535], [64646.5, 0.027], [64652.2, 0.003], [64653.4, 0.264], [64656.7, 0.094], [64657.3, 0.086], [64657.5, 0.064]], "asks": [[64657.7, 11.079], [64659.0, 0.077], [64659.5, 0.001], [64659.9, 0.001], [64660.0, 0.056], [64662.4, 1.096], [64663.4, 0.107], [64664.5, 0.004], [64665.6, 0.657], [64672.3, 0.004], [64679.6, 0.63], [64853.2, 0.0], [64853.3, 2.036], [64981.0, 1.198], [65304.3, 0.374], [65615.6, 0.358], [65657.7, 0.021]]}
{"kind": "depth", "E": 1787082411171, "U": 11315510249672, "u": 11315510256886, "recv_ms": 1787082411140, "bids": [[14457.6, 2.184], [14557.6, 2.016], [58191.8, 0.002], [61424.7, 0.013], [62071.2, 0.003], [63739.5, 0.702], [63835.0, 5.884], [64011.0, 0.065], [64334.3, 1.255], [64585.6, 0.0], [64588.1, 0.115], [64600.5, 0.152], [64605.6, 0.005], [64605.7, 0.001], [64608.3, 0.005], [64614.7, 0.035], [64614.8, 0.033], [64638.1, 0.018], [64643.5, 0.01], [64644.4, 0.464], [64644.5, 0.0], [64645.5, 0.213], [64646.5, 0.019], [64656.0, 0.338], [64657.6, 20.929]], "asks": [[64659.9, 0.001], [64661.5, 0.029], [64661.9, 0.044], [64666.3, 0.55], [65304.3, 0.374], [65353.8, 5.436], [65488.2, 0.0]]}
{"kind": "depth", "E": 1787082411273, "U": 11315510257011, "u": 11315510263024, "recv_ms": 1787082411246, "bids": [[1000.0, 35.81], [14457.6, 2.548], [14557.6, 1.652], [58191.8, 0.002], [61424.7, 0.014], [62071.2, 0.0], [63657.6, 0.0], [63750.4, 4.351], [63881.7, 6.219], [64011.0, 0.065], [64516.1, 4.444], [64636.5, 0.661], [64637.0, 0.043], [64646.3, 0.497], [64649.3, 0.484], [64653.4, 0.261], [64656.0, 0.261], [64656.7, 0.01], [64657.3, 0.002]], "asks": [[64657.7, 12.127], [64659.8, 0.087], [64662.0, 0.084], [64670.0, 0.026], [64797.5, 5.401], [64853.3, 4.479], [65304.3, 0.374], [65340.8, 0.002], [65362.5, 2.062], [65627.6, 2.775], [65657.7, 0.001]]}
{"kind": "depth", "E": 1787082411579, "U": 11315510275475, "u": 11315510283080, "recv_ms": 1787082411550, "bids": [[1000.0, 35.81], [14457.6, 3.612], [14557.6, 0.588], [51726.0, 0.004], [58191.8, 0.002], [61424.7, 0.011], [61424.8, 0.012], [62071.2, 0.0], [63758.9, 6.262], [64011.0, 0.065], [64635.4, 0.086], [64636.8, 0.208], [64641.2, 0.008], [64646.3, 0.535], [64656.0, 0.415], [64657.6, 20.928]], "asks": [[64657.7, 12.126], [64659.9, 0.001], [64661.2, 0.088], [64661.4, 0.007], [64661.5, 0.01], [64662.0, 0.084], [64662.2, 0.213], [64673.7, 0.006], [64787.1, 0.003], [64853.3, 4.322], [65304.3, 0.373], [65418.8, 12.375], [65756.9, 2.869]]}
{"kind": "depth", "E": 1787082411681, "U": 11315510283189, "u": 11315510289597, "recv_ms": 1787082411651, "bids": [[1000.0, 35.81], [14357.6, 0.112], [14457.6, 3.752], [14557.6, 0.336], [51726.0, 0.0], [51726.1, 0.0], [58191.8, 0.002], [61422.4, 2.46], [61424.7, 0.011], [62071.2, 0.003], [63657.6, 0.0], [63871.7, 0.783], [64011.0, 0.065], [64463.6, 0.01], [64516.2, 4.481], [64588.1, 0.423], [64635.4, 0.085], [64638.9, 0.004], [64644.1, 1.201], [64644.5, 0.0], [64646.3, 0.497], [64656.0, 0.107], [64657.6, 20.928]], "asks": [[64657.7, 12.238], [64659.8, 0.003], [64659.9, 0.003], [64661.8, 0.029], [64662.0, 0.074], [64662.2, 0.235], [64681.5, 0.023], [64682.2, 0.369], [64693.0, 0.028], [64702.2, 0.632], [64797.5, 4.538], [64814.4, 3.513], [64814.5, 7.375], [64853.3, 5.042], [65304.3, 0.373], [65657.7, 0.001], [65950.8, 0.012]]}
{"kind": "depth", "E": 1787082411783, "U": 11315510289616, "u": 11315510295808, "recv_ms": 1787082411753, "bids": [[14357.6, 0.336], [14457.6, 3.654], [14557.6, 0.21], [58191.8, 0.002], [62071.2, 0.0], [64011.0, 0.065], [64334.3, 1.245], [64657.2, 0.031]], "asks": [[64658.3, 0.003], [64659.8, 0.087], [64660.0, 0.053], [64693.0, 0.032], [64702.2, 0.628], [65304.3, 0.373]]}
{"kind": "depth", "E": 1787082411885, "U": 11315510296031, "u": 11315510302345, "recv_ms": 1787082411855, "bids": [[1000.0, 35.96], [14357.6, 0.588], [14457.6, 3.514], [14557.6, 0.098], [58191.8, 0.002], [61424.7, 0.011], [62071.2, 0.003], [63657.6, 0.02], [64011.0, 0.065], [64140.3, 3.238], [64499.1, 0.029], [64516.2, 0.001], [64547.6, 2.324], [64599.4, 0.207], [64656.0, 0.184]], "asks": [[64657.7, 12.24], [64715.9, 0.025], [64735.3, 0.0], [64797.5, 0.0], [64814.1, 0.885], [64814.5, 0.022], [65304.3, 0.373], [65657.7, 0.021]]}
{"kind": "depth", "E": 1787082411987, "U": 11315510302402, "u": 11315510308684, "recv_ms": 1787082411956, "bids": [[1000.0, 35.81], [14357.6, 0.84], [14457.6, 3.36], [14557.6, 0.0], [58191.8, 0.002], [63345.7, 0.0], [64011.0, 0.065], [64499.2, 10.623], [64516.2, 5.214], [64636.0, 2.557], [64636.5, 0.545], [64647.1, 0.228], [64649.7, 0.003], [64650.1, 1.203], [64653.5, 0.002]], "asks": [[64693.0, 0.028], [64702.2, 0.632], [64797.5, 5.401], [64814.5, 10.436], [64853.3, 1.537], [65304.3, 0.373]]}
{"kind": "depth", "E": 1787082412089, "U": 11315510308752, "u": 11315510314780, "recv_ms": 1787082412059, "bids": [[14357.6, 1.19], [14457.6, 3.01], [58191.8, 0.002], [61424.7, 0.011], [62071.2, 0.0], [63657.6, 0.0], [63723.8, 5.553], [63770.3, 8.762], [64011.0, 0.065], [64334.3, 1.255], [64635.6, 0.853], [64642.9, 0.759], [64646.0, 1.875], [64646.3, 0.535], [64652.8, 0.235], [64653.0, 0.007], [64653.4, 0.029], [64656.0, 0.338], [64657.1, 0.085], [64657.5, 0.06]], "asks": [[64657.7, 11.191], [64659.1, 0.0], [64659.8, 0.003], [64661.5, 0.029], [64661.9, 0.026], [64669.2, 1.236], [64669.7, 0.969], [64677.1, 1.463], [64679.6, 0.011], [64693.0, 0.032], [64702.2, 0.628], [64853.3, 1.805], [64981.0, 1.198], [65304.3, 0.373], [65562.9, 8.051], [65657.7, 0.001]]}
{"kind": "depth", "E": 1787082412293, "U": 11315510320527, "u": 11315510326048, "recv_ms": 1787082412263, "bids": [[14357.6, 1.918], [14457.6, 2.282], [51726.0, 0.0], [58191.8, 0.002], [62071.2, 0.0], [63657.6, 0.02], [64011.0, 0.065], [64334.3, 1.255]], "asks": [[64659.9, 0.001], [64661.5, 0.01], [64661.9, 0.003], [64662.1, 0.47], [64770.1, 0.029], [64853.3, 1.806], [65304.3, 0.373], [65657.7, 0.021], [66595.1, 0.003]]}
{"kind": "depth", "E": 1787082412395, "U": 11315510326143, "u": 11315510333067, "recv_ms": 1787082412365, "bids": [[14357.6, 2.268], [14457.6, 1.932], [51726.0, 0.0], [58191.8, 0.002], [63657.6, 0.0], [64011.0, 0.065], [64643.0, 2.389], [64646.3, 0.498], [64656.0, 0.261]], "asks": [[64660.0, 0.137], [65304.3, 0.373], [65561.0, 0.692], [65657.7, 0.001], [65950.8, 0.015]]}
{"kind": "depth", "E": 1787082412497, "U": 11315510333167, "u": 11315510339863, "recv_ms": 1787082412468, "bids": [[1000.0, 35.81], [14357.6, 2.618], [14457.6, 1.582], [58191.8, 0.002], [62071.2, 0.003], [63738.0, 7.996], [63813.4, 13.38], [64011.0, 0.065], [64516.2, 0.001], [64518.2, 1.404], [64646.3, 0.42], [64648.0, 0.009], [64656.0, 0.081], [64657.5, 0.064]], "asks": [[64659.9, 0.001], [64797.5, 0.0], [64814.1, 2.326], [104929.0, 0.0]]}
{"kind": "depth", "E": 1787082412599, "U": 11315510340067, "u": 11315510346989, "recv_ms": 1787082412572, "bids": [[14357.6, 2.982], [14457.6, 1.218], [58191.8, 0.002], [61424.7, 0.011], [62071.2, 0.0], [63364.5, 0.01], [63657.6, 0.02], [64007.4, 6.155], [64011.0, 0.065], [64136.8, 0.501], [64334.3, 1.255], [64499.2, 1.087], [64499.3, 9.799], [64516.2, 5.322], [64518.2, 0.716], [64543.4, 0.0], [64580.0, 1.725], [64635.6, 0.234], [64635.9, 0.139], [64636.0, 2.441], [64636.3, 1.747], [64636.4, 2.911], [64636.6, 0.484], [64637.1, 0.0], [64637.6, 0.815], [64637.8, 0.004], [64641.1, 1.034], [64641.2, 0.008], [64641.3, 0.0], [64641.4, 0.102], [64641.9, 0.021], [64642.8, 0.007], [64642.9, 0.14], [64646.3, 0.343], [64647.1, 0.228], [64650.0, 1.941], [64650.1, 0.662], [64653.0, 0.004], [64657.1, 0.001], [64657.6, 20.928]], "asks": [[64657.7, 12.385], [64659.7, 0.086], [64661.9, 0.013], [64669.7, 0.35], [64673.6, 0.996], [64673.7, 0.006], [64674.3, 0.005], [64674.4, 0.929], [64675.3, 0.01], [64676.5, 0.633], [64677.4, 0.04], [64678.2, 2.384], [64678.7, 0.0], [64679.5, 0.119], [64680.4, 1.273], [64681.9, 3.357], [64682.0, 10.003], [64682.3, 0.021], [64685.9, 0.007], [64686.0, 0.262], [64787.1, 0.003], [64797.5, 5.401], [64814.5, 10.436], [64852.4, 1.144], [64853.3, 3.841], [65304.3, 0.373], [65561.0, 0.464], [65657.7, 0.021]]}
{"kind": "depth", "E": 1787082412701, "U": 11315510347113, "u": 11315510352396, "recv_ms": 1787082412674, "bids": [[14357.6, 3.332], [14457.6, 0.868], [51726.1, 0.0], [58191.8, 0.002], [61424.7, 0.012], [62071.2, 0.003], [64011.0, 0.065], [64459.9, 0.0], [64599.4, 0.21], [64624.7, 0.003], [64624.8, 0.014], [64624.9, 2.151], [64628.2, 0.004], [64628.3, 0.004], [64628.4, 0.002], [64638.1, 0.019], [64646.3, 0.42], [64647.1, 0.228], [64648.0, 0.008], [64650.0, 1.4], [64650.1, 1.203], [64656.0, 0.107], [64657.6, 20.932]], "asks": [[64659.0, 0.387], [64659.9, 0.001], [64676.5, 0.076], [64677.7, 0.558], [64678.4, 0.227], [64686.2, 0.113], [64735.3, 0.003], [64800.0, 11.227], [64814.5, 7.317], [64853.3, 5.133], [65304.3, 0.373], [65845.1, 0.002]]}
{"kind": "depth", "E": 1787082412803, "U": 11315510352466, "u": 11315510357765, "recv_ms": 1787082412774, "bids": [[1000.0, 35.81], [14357.6, 3.696], [14457.6, 0.504], [58191.8, 0.002], [61424.7, 0.011], [62071.2, 0.0], [63552.0, 1.003], [63817.1, 0.316], [63835.0, 5.533], [64011.0, 0.221], [64638.1, 0.018], [64644.7, 1.007], [64651.1, 0.027]], "asks": [[64659.9, 0.003], [64661.4, 0.03], [64662.2, 0.213], [65304.3, 0.373], [104929.0, 0.236]]}
{"kind": "depth", "E": 1787082412905, "U": 11315510357883, "u": 11315510364627, "recv_ms": 1787082412877, "bids": [[14257.6, 0.154], [14357.6, 3.738], [14457.6, 0.308], [58191.8, 0.002], [61424.7, 0.011], [63550.0, 3.408], [63657.6, 0.0], [63849.4, 2.719], [64011.0, 0.221], [64284.6, 0.503], [64334.3, 1.245], [64463.6, 0.013], [64499.3, 0.001], [64516.2, 0.001], [64657.6, 20.93]], "asks": [[64657.7, 12.285], [64659.9, 0.003], [64767.7, 0.01], [64797.5, 0.0], [64814.1, 0.885], [64814.5, 0.022], [65304.3, 0.373], [65657.7, 0.001], [65950.8, 0.015]]}
{"kind": "depth", "E": 1787082413007, "U": 11315510364792, "u": 11315510370947, "recv_ms": 1787082412980, "bids": [[14257.6, 0.392], [14357.6, 3.626], [14457.6, 0.182], [58191.8, 0.002], [61424.7, 0.013], [61424.8, 0.008], [62071.2, 0.003], [64011.0, 0.221], [64460.3, 0.0], [64460.4, 0.0], [64460.5, 10.353], [64460.6, 2.238], [64499.3, 7.975], [64516.2, 4.48], [64540.2, 0.582], [64540.9, 3.882], [64549.1, 0.602], [64549.4, 2.32], [64581.6, 0.084], [64584.5, 0.0], [64585.2, 0.048], [64588.1, 0.526], [64595.5, 0.038], [64595.8, 0.04], [64596.2, 0.001], [64596.5, 0.001], [64596.8, 1.462], [64596.9, 0.021], [64606.2, 0.506], [64608.3, 0.001], [64613.7, 0.001], [64614.1, 0.059], [64614.3, 2.32], [64614.7, 0.004], [64614.8, 0.002], [64615.1, 0.052], [64628.9, 0.006], [64629.0, 0.974], [64629.1, 0.001], [64629.2, 0.017], [64629.3, 0.01], [64629.4, 0.213], [64629.6, 0.311], [64629.7, 0.022], [64629.8, 0.48], [64630.0, 3.112], [64631.1, 0.003], [64631.5, 0.018], [64646.3, 0.42], [64647.2, 0.009], [64648.5, 0.001], [64648.7, 0.001], [64648.8, 0.005], [64648.9, 0.0], [64649.0, 0.07], [64649.2, 0.311], [64649.3, 0.314], [64649.4, 0.099], [64649.6, 0.868], [64649.9, 2.536], [64650.1, 1.171], [64650.5, 0.002], [64650.7, 0.055], [64650.9, 0.039], [64651.0, 0.388], [64655.4, 0.009], [64656.0, 0.081], [64656.6, 0.0], [64657.6, 20.917]], "asks": [[64661.2, 0.091], [64665.1, 0.041], [64665.2, 0.172], [64665.4, 0.001], [64665.5, 0.492], [64665.7, 0.015], [64665.8, 1.888], [64666.1, 0.046], [64666.3, 0.504], [64666.6, 0.002], [64666.9, 0.004], [64667.0, 2.045], [64667.2, 0.005], [64667.3, 0.06], [64667.4, 0.185], [64667.5, 0.02], [64667.6, 0.197], [64667.7, 0.003], [64668.5, 0.311], [64670.6, 0.0], [64670.7, 1.865], [64674.3, 0.005], [64683.0, 0.064], [64683.4, 1.238], [64683.6, 0.434], [64683.7, 0.017], [64684.0, 0.062], [64684.2, 0.008], [64684.3, 0.0], [64685.1, 0.007], [64685.3, 0.003], [64686.2, 0.001], [64686.5, 0.023], [64686.6, 1.8], [64686.7, 0.003], [64686.8, 0.828], [64686.9, 0.007], [64687.0, 0.107], [64687.1, 0.102], [64687.2, 2.319], [64687.5, 0.005], [64687.6, 3.921], [64687.7, 0.313], [64687.8, 0.077], [64687.9, 0.539], [64700.9, 0.04], [64701.4, 0.02], [64701.5, 0.014], [64701.9, 0.565], [64702.1, 0.029], [64702.5, 4.986], [64704.3, 1.754], [64726.8, 6.311], [64727.5, 0.27], [64767.2, 2.32], [64767.4, 12.589], [64791.0, 0.027], [64791.7, 4.086], [64797.5, 5.401], [64814.5, 10.436], [64853.3, 4.325], [65304.3, 0.373], [65349.5, 0.84], [65615.6, 0.015], [65853.9, 0.989]]}
{"kind": "depth", "E": 1787082413109, "U": 11315510371142, "u": 11315510384990, "recv_ms": 1787082413080, "bids": [[1000.0, 35.81], [14257.6, 0.644], [14357.6, 3.486], [14457.6, 0.07], [58188.6, 0.0], [58191.8, 0.002], [61424.7, 0.013], [62071.2, 0.0], [62976.5, 0.002], [63235.1, 0.003], [63657.6, 0.02], [64011.0, 0.221], [64334.3, 1.245], [64526.6, 0.0], [64527.9, 0.044], [64547.6, 2.321], [64599.4, 0.21], [64614.8, 0.001], [64615.8, 0.042], [64631.7, 0.028], [64635.5, 0.629], [64638.0, 0.368], [64642.9, 0.759], [64644.7, 1.006], [64646.0, 1.875], [64646.3, 0.497], [64649.0, 0.14], [64649.3, 0.384], [64651.3, 0.037], [64656.0, 0.107], [64656.1, 0.002], [64656.3, 0.087], [64657.6, 20.917]], "asks": [[64657.7, 12.709], [64658.8, 0.002], [64659.9, 0.003], [64663.4, 0.023], [64664.7, 0.04], [64665.4, 0.464], [64665.5, 0.029], [64666.7, 0.409], [64667.0, 2.15], [64669.7, 0.969], [64674.3, 0.005], [64677.1, 1.463], [64682.5, 0.178], [64686.1, 0.098], [64686.2, 0.015], [64686.4, 1.141], [64700.2, 0.106], [64704.3, 1.796], [64706.9, 0.001], [64715.9, 0.025], [64735.3, 0.0], [64767.7, 0.007], [64814.5, 7.439], [64846.6, 0.015], [64846.7, 0.004], [64853.3, 4.943], [64981.0, 1.198], [65304.3, 0.373], [65657.7, 0.021]]}
{"kind": "depth", "E": 1787082413211, "U": 11315510385006, "u": 11315510391664, "recv_ms": 1787082413183, "bids": [[14257.6, 0.924], [14357.6, 3.276], [14457.6, 0.0], [51726.0, 0.0], [58191.8, 0.002], [62071.2, 0.003], [63383.8, 2.03], [63676.1, 0.714], [63881.7, 8.563], [64334.3, 1.245], [64578.9, 0.003], [64579.0, 0.049], [64581.1, 44.859], [64582.0, 8.915], [64614.8, 0.033], [64615.6, 0.073], [64632.3, 0.015], [64636.6, 0.561], [64639.9, 1.303], [64647.2, 0.001], [64648.8, 0.075], [64649.2, 0.411], [64649.3, 0.484], [64649.5, 0.337], [64649.6, 1.038], [64649.7, 0.103], [64650.3, 0.035], [64650.7, 0.087], [64655.4, 0.017], [64656.8, 0.086]], "asks": [[64657.7, 12.711], [64659.7, 0.002], [64664.3, 1.673], [64665.3, 0.048], [64665.7, 0.06], [64666.3, 0.694], [64666.4, 0.28], [64666.5, 0.493], [64666.7, 0.559], [64666.8, 0.14], [64667.2, 0.096], [64682.9, 0.115], [64683.4, 1.283], [64683.9, 2.525], [64685.4, 0.284], [64685.5, 0.211], [64685.7, 0.155], [64685.8, 0.153], [64686.2, 0.106], [64701.2, 0.045], [64745.6, 0.0], [64814.5, 10.436], [64853.3, 1.541], [65304.3, 0.373], [65627.6, 3.117]]}
{"kind": "depth", "E": 1787082413313, "U": 11315510391863, "u": 11315510399423, "recv_ms": 1787082413285, "bids": [[1000.0, 35.81], [14257.6, 1.288], [14357.6, 2.912], [58191.8, 0.002], [61424.7, 0.011], [61424.8, 0.01], [62071.2, 0.0], [63440.0, 1.728], [63530.3, 0.0], [63657.6, 0.0], [63725.1, 0.951], [64011.0, 0.221], [64580.0, 1.648], [64588.1, 0.449], [64596.6, 0.059], [64597.5, 0.036], [64632.3, 0.014], [64633.7, 0.003], [64636.6, 0.638], [64644.1, 1.047], [64646.3, 0.497], [64648.9, 0.07], [64649.0, 0.28], [64649.3, 0.584], [64649.4, 0.199], [64649.8, 0.077], [64656.0, 0.261]], "asks": [[64659.9, 0.001], [64666.2, 0.115], [64666.6, 0.172], [64666.7, 0.729], [64667.0, 2.276], [64667.1, 0.587], [64684.3, 0.17], [64685.2, 0.112], [64685.6, 0.202], [64686.0, 0.388], [64686.1, 0.301], [64688.0, 0.053], [64692.6, 0.002], [64696.6, 3.766], [64696.7, 1.356], [64764.8, 3.752], [64823.9, 0.921], [64825.3, 0.0], [64833.0, 3.925], [64853.3, 1.721], [65304.3, 0.373], [65657.7, 0.001]]}
{"kind": "depth", "E": 1787082413619, "U": 11315510408705, "u": 11315510413855, "recv_ms": 1787082413589, "bids": [[1000.0, 35.81], [14257.6, 2.352], [14357.6, 1.848], [51726.0, 0.0], [58191.8, 0.002], [62071.2, 0.0], [63526.1, 2.516], [63724.3, 0.0], [63849.4, 3.501], [64011.0, 0.223], [64630.2, 0.853], [64630.3, 0.198], [64630.5, 0.249], [64630.6, 0.172], [64632.1, 0.115], [64634.7, 0.004], [64636.6, 0.799], [64641.2, 0.008], [64644.3, 0.158], [64644.5, 0.0], [64646.3, 0.189], [64656.0, 0.081]], "asks": [[64673.7, 0.006], [64677.2, 5.011], [64787.1, 0.003], [64814.5, 10.436], [64853.3, 1.774], [65171.2, 6.002], [65190.1, 0.001], [65304.3, 0.373], [65601.8, 0.0]]}
{"kind": "depth", "E": 1787082413721, "U": 11315510413864, "u": 11315510419064, "recv_ms": 1787082413691, "bids": [[1000.0, 35.81], [14257.6, 2.716], [14357.6, 1.484], [51726.0, 0.002], [51726.1, 0.0], [58191.8, 0.002], [61424.7, 0.011], [62071.2, 0.003], [63657.6, 0.0], [63784.7, 1.406], [63805.4, 2.191], [63944.3, 3.519], [64011.0, 0.221], [64400.0, 22.879], [64516.3, 4.409], [64588.1, 0.526], [64614.7, 0.005], [64629.9, 0.092], [64630.0, 3.392], [64630.4, 1.369], [64630.8, 0.304], [64631.7, 0.128], [64634.7, 0.003], [64635.5, 0.01], [64636.6, 0.645], [64642.9, 0.14], [64646.3, 0.24], [64652.2, 0.087], [64655.7, 0.021], [64655.9, 0.0], [64656.0, 0.088], [64656.3, 0.003], [64656.5, 0.0], [64656.8, 0.002], [64657.6, 20.631]], "asks": [[64657.7, 9.275], [64658.5, 0.079], [64658.7, 0.0], [64659.1, 0.084], [64659.8, 0.003], [64660.5, 0.0], [64660.9, 0.32], [64661.1, 0.004], [64661.4, 0.007], [64661.8, 0.01], [64662.0, 0.094], [64662.3, 0.179], [64664.3, 1.672], [64669.7, 0.35], [64677.1, 0.844], [64682.0, 0.003], [64682.1, 0.003], [64682.2, 0.369], [64686.2, 0.106], [64797.5, 5.401], [64853.3, 1.774], [64931.3, 0.295], [65304.3, 0.373], [65657.7, 0.001]]}
{"kind": "depth", "E": 1787082413823, "U": 11315510419139, "u": 11315510424494, "recv_ms": 1787082413794, "bids": [[14257.6, 3.066], [14357.6, 1.134], [51726.0, 0.0], [58191.8, 0.002], [61424.7, 0.011], [63235.1, 0.0], [63299.8, 1.577], [63952.8, 1.95], [64011.0, 0.221], [64334.3, 1.245], [64636.6, 0.722], [64637.5, 0.012], [64646.3, 0.105], [64646.5, 0.019], [64655.4, 0.017], [64656.0, 0.004], [64656.3, 0.087], [64656.7, 0.094], [64657.6, 20.742]], "asks": [[64657.7, 9.499], [64659.1, 0.0], [64660.0, 0.145], [64660.9, 0.01], [64661.2, 0.088], [64662.0, 0.109], [64665.5, 0.013], [64665.6, 0.65], [64681.9, 0.0], [64682.2, 0.369], [64684.9, 10.0], [64706.9, 0.001], [64814.5, 7.336], [64853.3, 5.39], [65304.3, 0.373]]}
{"kind": "depth", "E": 1787082413925, "U": 11315510424595, "u": 11315510429921, "recv_ms": 1787082413895, "bids": [[1000.0, 35.81], [14257.6, 3.43], [14357.6, 0.77], [58191.8, 0.002], [61424.7, 0.012], [62071.2, 0.0], [63657.6, 0.02], [63687.7, 3.628], [63720.1, 7.156], [63817.1, 0.629], [63890.0, 1.987], [63929.9, 0.0], [64011.0, 0.221], [64516.3, 3.79], [64595.5, 0.029], [64634.3, 0.451], [64637.5, 0.011], [64646.3, 0.086], [64652.2, 0.003], [64656.8, 0.312], [64657.4, 0.095]], "asks": [[64657.7, 9.496], [64659.9, 0.001], [64660.0, 0.061], [64660.4, 2.322], [64661.6, 0.109], [64661.9, 0.035], [64677.2, 0.011], [64682.2, 0.215], [64814.5, 10.436], [64853.3, 6.068], [65175.0, 4.777], [65304.3, 0.373], [65547.7, 4.231], [65595.2, 8.149], [65657.7, 0.021], [65761.0, 0.916]]}
{"kind": "depth", "E": 1787082414027, "U": 11315510429993, "u": 11315510435398, "recv_ms": 1787082413998, "bids": [[1000.0, 35.81], [14157.6, 0.028], [14257.6, 3.724], [14357.6, 0.448], [58191.8, 0.002], [61424.7, 0.011], [62071.2, 0.003], [63657.6, 0.0], [63881.7, 10.127], [64011.0, 0.221], [64516.3, 5.166], [64576.6, 42.881], [64576.8, 0.685], [64581.1, 2.327], [64582.0, 2.754], [64634.3, 0.45], [64636.6, 0.799], [64636.8, 0.209], [64654.1, 0.001], [64655.4, 0.019], [64657.5, 0.064]], "asks": [[64853.3, 1.663], [65304.3, 0.373], [65575.8, 2.208], [65657.7, 0.001]]}
{"kind": "depth", "E": 1787082414129, "U": 11315510435479, "u": 11315510441173, "recv_ms": 1787082414100, "bids": [[14157.6, 0.21], [14257.6, 3.71], [14357.6, 0.28], [58191.8, 0.002], [61424.7, 0.011], [62071.2, 0.0], [63364.5, 0.016], [63655.1, 0.054], [63719.6, 0.005], [63723.0, 0.536], [63835.0, 5.299], [64011.0, 0.221], [64334.3, 1.244], [64576.6, 0.368], [64578.9, 42.425], [64635.6, 0.853], [64635.9, 0.023], [64636.8, 0.208], [64636.9, 0.119], [64639.1, 0.366], [64642.9, 0.759], [64646.0, 1.875], [64646.3, 0.112], [64655.7, 0.043], [64657.6, 20.742]], "asks": [[64661.2, 0.108], [64661.6, 0.089], [64661.9, 0.013], [64662.0, 0.65], [64663.4, 0.107], [64663.7, 0.144], [64665.4, 0.001], [64665.6, 0.109], [64665.7, 0.523], [64667.0, 2.277], [64669.8, 0.628], [64677.1, 1.463], [64981.0, 1.197], [65304.3, 0.373], [65421.7, 7.635], [65556.4, 5.057], [65592.2, 0.0], [65595.5, 0.02], [65660.1, 0.018], [65769.8, 0.606], [65950.8, 0.012]]}
{"kind": "depth", "E": 1787082414333, "U": 11315510447915, "u": 11315510453838, "recv_ms": 1787082414304, "bids": [[1000.0, 35.81], [14157.6, 0.686], [14257.6, 3.472], [14357.6, 0.042], [51726.0, 0.0], [58191.8, 0.002], [61424.7, 0.011], [63657.6, 0.02], [64011.0, 0.221], [64555.7, 0.016], [64555.8, 0.003], [64580.0, 1.84], [64624.7, 0.001], [64624.8, 2.161], [64624.9, 0.001], [64628.2, 0.002], [64628.3, 0.002], [64628.4, 0.0], [64632.9, 2.165], [64633.0, 0.055], [64635.1, 0.007], [64636.4, 0.836], [64636.6, 0.542], [64636.7, 6.869], [64636.8, 3.874], [64640.8, 0.002], [64641.0, 1.003], [64641.1, 0.951], [64642.9, 0.14], [64646.3, 0.086], [64653.3, 0.256], [64655.4, 0.019], [64656.0, 0.004], [64657.1, 0.007]], "asks": [[64657.7, 8.024], [64659.0, 0.077], [64660.8, 0.004], [64661.1, 0.002], [64661.2, 0.088], [64661.7, 0.002], [64661.9, 0.021], [64662.0, 0.622], [64662.2, 0.213], [64662.4, 1.116], [64662.5, 0.005], [64662.7, 0.027], [64663.0, 0.09], [64664.1, 0.153], [64664.5, 0.088], [64665.5, 0.013], [64665.6, 0.109], [64669.8, 0.009], [64677.1, 0.844], [64679.5, 0.003], [64679.9, 1.797], [64682.2, 0.369], [64682.4, 4.593], [64683.0, 0.062], [64705.8, 2.069], [64705.9, 0.169], [64713.9, 2.872], [64714.0, 0.071], [64778.8, 2.171], [64779.0, 0.454], [64853.3, 1.846], [64931.2, 0.424], [65190.0, 2.04], [65304.3, 0.373], [65575.8, 2.435], [65657.7, 0.021]]}
{"kind": "depth", "E": 1787082414435, "U": 11315510453866, "u": 11315510458919, "recv_ms": 1787082414413, "bids": [[14157.6, 1.008], [14257.6, 3.192], [14357.6, 0.0], [58191.8, 0.002], [61424.7, 0.011], [62071.2, 0.0], [63979.3, 0.0], [64011.0, 0.221], [64334.3, 1.255], [64547.6, 2.324], [64599.4, 0.207], [64640.8, 0.001], [64642.4, 0.003], [64657.6, 20.75]], "asks": [[64659.9, 0.001], [64682.2, 0.215], [64682.3, 0.175], [64715.9, 0.025], [65304.3, 0.373], [65658.6, 4.162]]}
{"kind": "depth", "E": 1787082414537, "U": 11315510459109, "u": 11315510464543, "recv_ms": 1787082414510, "bids": [[1000.0, 35.81], [14157.6, 1.372], [14257.6, 2.828], [58191.8, 0.002], [61424.7, 0.012], [62071.2, 0.003], [63657.6, 0.0], [64011.0, 0.221], [64499.3, 0.001], [64516.3, 0.0], [64518.2, 0.716], [64579.0, 7.771], [64624.7, 0.003], [64624.8, 2.163], [64624.9, 0.003], [64628.2, 0.004], [64628.3, 0.004], [64628.4, 0.002], [64644.1, 1.201], [64644.3, 0.004], [64653.3, 0.253], [64655.4, 0.017], [64657.6, 21.748]], "asks": [[64660.9, 0.008], [64663.2, 0.105], [64684.8, 3.638], [64797.5, 0.0], [64814.1, 0.885], [64814.5, 0.022], [65304.3, 0.373], [65657.7, 0.001]]}
{"kind": "depth", "E": 1787082414639, "U": 11315510464553, "u": 11315510470900, "recv_ms": 1787082414610, "bids": [[1000.0, 35.81], [14157.6, 1.722], [14257.6, 2.478], [51726.1, 0.0], [58191.8, 0.002], [61424.7, 0.011], [62071.2, 0.0], [63558.4, 0.813], [63750.4, 3.412], [63849.4, 3.852], [63975.9, 1.171], [64011.0, 0.221], [64460.5, 0.013], [64549.4, 0.0], [64549.5, 2.32], [64580.0, 1.917], [64636.6, 0.465], [64641.2, 0.006], [64657.6, 21.748]], "asks": [[64657.7, 8.025], [64660.3, 0.012], [64661.9, 0.032], [64662.1, 0.465], [64662.3, 0.178], [64667.0, 2.276], [64673.7, 0.004], [64767.1, 2.32], [64767.2, 0.0], [64770.1, 0.034], [64787.1, 0.003], [64853.3, 0.002], [65304.3, 0.373], [65429.8, 19.52], [65486.3, 3.665]]}
{"kind": "depth", "E": 1787082414741, "U": 11315510471023, "u": 11315510476359, "recv_ms": 1787082414713, "bids": [[14157.6, 2.072], [14257.6, 2.128], [58191.8, 0.002], [62067.8, 0.001], [62071.2, 0.003], [63657.6, 0.02], [63826.2, 0.009], [64011.0, 0.221], [64334.3, 1.255], [64460.6, 0.695], [64636.9, 0.12], [64641.2, 0.008], [64642.4, 0.002], [64646.3, 0.009]], "asks": [[64662.1, 0.47], [64662.7, 0.004], [64673.7, 0.006], [64693.0, 0.028], [64702.2, 0.632], [64770.1, 0.029], [64852.4, 0.655], [65304.3, 0.373], [65599.4, 8.217], [65622.3, 0.0], [65657.7, 0.021]]}
{"kind": "depth", "E": 1787082414945, "U": 11315510480596, "u": 11315510485632, "recv_ms": 1787082414916, "bids": [[1000.0, 35.81], [14157.6, 2.786], [14257.6, 1.414], [58191.8, 0.002], [61424.7, 0.012], [62071.2, 0.0], [63364.5, 0.019], [63657.6, 0.0], [63758.9, 7.201], [64011.0, 0.221], [64516.4, 4.573], [64518.2, 0.716], [64599.4, 0.21], [64631.4, 0.862], [64652.8, 0.238], [64657.5, 0.06], [64657.6, 21.749]], "asks": [[64657.7, 7.798], [64660.3, 0.004], [64660.4, 2.322], [64660.7, 0.11], [64661.9, 0.063], [64662.1, 0.465], [64692.8, 1.015], [64735.3, 0.003], [64770.1, 0.034], [64797.5, 5.401], [64853.3, 4.53], [65304.3, 0.373], [65423.4, 1.832], [65630.7, 0.271], [65657.7, 0.001]]}
{"kind": "depth", "E": 1787082415047, "U": 11315510485643, "u": 11315510493264, "recv_ms": 1787082415018, "bids": [[14157.6, 3.15], [14257.6, 1.05], [58191.8, 0.002], [61424.7, 0.011], [62071.2, 0.003], [63364.5, 0.013], [63448.5, 1.7], [63657.6, 0.02], [63739.5, 0.936], [64011.0, 0.221], [64332.4, 0.109], [64334.3, 1.245], [64580.0, 1.994], [64627.5, 0.001], [64635.6, 0.234], [64646.0, 1.88], [64657.6, 21.749]], "asks": [[64657.7, 8.156], [64659.9, 0.001], [64660.3, 0.012], [64661.9, 0.055], [64662.1, 0.47], [64684.9, 0.0], [64687.4, 10.0], [64693.0, 0.032], [64702.2, 0.628], [64770.1, 0.029], [64852.4, 1.247], [64982.6, 0.108], [65304.3, 0.373], [65608.2, 2.51], [65657.7, 0.021], [65950.8, 0.009]]}
{"kind": "depth", "E": 1787082415149, "U": 11315510493536, "u": 11315510503597, "recv_ms": 1787082415119, "bids": [[1000.0, 35.81], [14157.6, 3.5], [14257.6, 0.7], [58191.8, 0.002], [61424.7, 0.011], [61424.8, 0.006], [62071.2, 0.0], [63655.1, 0.062], [64011.0, 0.221], [64330.6, 1.629], [64633.0, 0.674], [64640.3, 0.631], [64643.5, 0.011], [64645.4, 0.014], [64646.0, 1.875]], "asks": [[64657.7, 8.396], [64660.3, 0.096], [64663.9, 0.103], [64664.5, 0.004], [64667.1, 0.587], [64674.5, 0.604], [64750.6, 0.13], [64853.3, 1.965], [64977.3, 1.284], [65304.3, 0.373], [65622.7, 0.003], [65660.1, 0.016], [65660.2, 1.315]]}
{"kind": "depth", "E": 1787082415251, "U": 11315510503744, "u": 11315510511809, "recv_ms": 1787082415221, "bids": [[1000.0, 35.81], [14157.6, 3.752], [14257.6, 0.392], [14557.6, 0.056], [51726.0, 0.0], [58191.8, 0.002], [63472.4, 0.002], [64011.0, 0.221], [64334.3, 1.244], [64358.9, 0.001], [64499.4, 5.849], [64516.4, 3.217], [64580.0, 2.097], [64602.1, 0.008], [64640.9, 0.026], [64644.1, 1.201], [64652.8, 0.235], [64655.4, 0.019], [64655.7, 0.021], [64655.9, 0.0], [64657.4, 0.011], [64657.6, 21.748]], "asks": [[64659.7, 0.086], [64660.3, 0.088], [64661.9, 0.063], [64662.0, 0.615], [64664.1, 0.069], [64665.6, 0.116], [64706.9, 0.015], [64853.3, 8.873], [64933.0, 2.039], [64981.0, 1.197], [65055.9, 0.006], [65171.2, 2.173], [65304.3, 0.373], [65427.1, 7.169], [65660.2, 1.334]]}
{"kind": "depth", "E": 1787082415353, "U": 11315510511860, "u": 11315510517143, "recv_ms": 1787082415325, "bids": [[14157.6, 3.668], [14257.6, 0.252], [14557.6, 0.28], [51726.0, 0.002], [58191.8, 0.0], [61424.7, 0.011], [62071.2, 0.003], [63619.4, 0.0], [63657.6, 0.0], [63716.4, 13.09], [63870.1, 9.005], [64011.0, 0.223], [64334.3, 3.574], [64460.6, 0.695], [64460.7, 10.932], [64499.4, 0.003], [64499.5, 9.912], [64516.4, 5.326], [64581.6, 0.495], [64587.9, 0.128], [64590.7, 3.412], [64643.5, 0.01], [64644.1, 1.047], [64644.6, 0.185], [64645.6, 0.339]], "asks": [[64659.9, 0.001], [64661.6, 0.089], [64661.9, 0.021], [64662.1, 0.465], [64662.3, 0.156], [64662.5, 0.024], [64662.8, 0.024], [64663.9, 0.102], [64717.5, 0.002], [64719.8, 0.015], [64723.8, 2.84], [64770.1, 0.034], [64852.4, 0.655], [64853.3, 1.729], [64981.0, 3.504], [65304.3, 0.373], [65429.1, 0.0], [65429.8, 18.3], [65657.7, 0.001]]}
{"kind": "depth", "E": 1787082415455, "U": 11315510517144, "u": 11315510524164, "recv_ms": 1787082415426, "bids": [[1000.0, 35.81], [14157.6, 3.57], [14257.6, 0.126], [14557.6, 0.504], [51726.0, 0.0], [58191.8, 0.002], [62071.2, 0.0], [63738.0, 7.527], [64011.0, 0.221], [64516.4, 0.161], [64644.4, 0.464], [64644.6, 0.031], [64655.4, 0.017], [64656.7, 0.01], [64657.5, 0.065]], "asks": [[64659.9, 0.003], [64662.0, 0.622], [64665.6, 0.109], [64797.5, 0.0], [65304.3, 0.373], [65630.9, 0.271], [65950.8, 0.006], [71123.5, 0.001]]}
{"kind": "depth", "E": 1787082415659, "U": 11315510531465, "u": 11315510536663, "recv_ms": 1787082415628, "bids": [[14157.6, 3.108], [14257.6, 0.0], [14557.6, 1.092], [51726.1, 0.0], [58191.8, 0.002], [62071.2, 0.0], [63378.1, 0.017], [63752.4, 4.314], [64011.0, 0.222], [64334.3, 3.574], [64460.7, 10.398], [64499.5, 8.461], [64516.4, 4.638], [64524.6, 0.691], [64547.6, 2.321], [64599.4, 0.21], [64628.7, 0.428], [64631.4, 0.526], [64636.5, 0.661], [64636.9, 0.003], [64641.2, 0.006], [64644.1, 1.047], [64645.4, 0.015], [64653.6, 0.005], [64655.4, 0.042], [64655.5, 0.001], [64655.6, 0.103], [64655.7, 0.002], [64656.2, 0.084], [64657.6, 21.747]], "asks": [[64659.1, 0.003], [64660.3, 0.088], [64661.9, 0.013], [64662.0, 0.089], [64662.1, 0.47], [64665.5, 0.554], [64665.6, 0.109], [64673.7, 0.004], [64693.0, 0.028], [64702.2, 0.632], [64715.9, 0.025], [64735.3, 0.0], [64770.1, 0.029], [64787.1, 0.003], [64846.7, 0.001], [64846.8, 0.019], [64853.3, 1.55], [65304.3, 0.373], [65748.0, 4.726]]}
{"kind": "depth", "E": 1787082415761, "U": 11315510537474, "u": 11315510544417, "recv_ms": 1787082415733, "bids": [[1000.0, 35.81], [14157.6, 2.758], [14557.6, 1.442], [51726.0, 0.004], [58191.8, 0.002], [62067.8, 0.0], [63657.6, 0.0], [64011.0, 0.224], [64136.7, 3.15], [64592.9, 0.12], [64636.2, 0.021], [64638.2, 0.204], [64641.2, 0.008], [64644.3, 0.012], [64644.7, 0.481], [64645.4, 0.014], [64646.5, 0.011], [64647.3, 0.374]], "asks": [[64661.9, 0.032], [64673.7, 0.006], [64688.0, 0.039], [64696.2, 0.033], [64722.4, 0.004], [65657.7, 0.001]]}
{"kind": "depth", "E": 1787082415863, "U": 11315510544472, "u": 11315510557975, "recv_ms": 1787082415835, "bids": [[1000.0, 35.81], [14157.6, 2.394], [14557.6, 1.806], [51726.0, 0.0], [58191.8, 0.002], [62071.2, 0.003], [63332.1, 1.577], [63364.5, 0.01], [63657.6, 0.02], [63728.3, 1.104], [63881.7, 10.909], [64011.0, 0.222], [64516.4, 0.161], [64636.2, 0.02], [64644.4, 0.31], [64645.1, 0.028], [64652.8, 0.003], [64653.5, 0.234], [64657.6, 21.767]], "asks": [[64657.7, 9.488], [64659.8, 0.003], [64797.6, 0.001], [65304.3, 0.373], [65612.7, 2.693], [65657.7, 0.021], [65756.9, 3.476]]}
{"kind": "depth", "E": 1787082415965, "U": 11315510558054, "u": 11315510565608, "recv_ms": 1787082415938, "bids": [[14157.6, 2.03], [14557.6, 2.17], [58191.8, 0.002], [61424.7, 0.011], [62071.2, 0.0], [63440.0, 0.942], [63696.0, 0.804], [63835.0, 4.683], [63849.4, 4.086], [64011.0, 0.222], [64269.6, 0.005], [64306.1, 0.0], [64334.3, 3.574], [64365.6, 0.001], [64401.0, 0.885], [64644.4, 0.31]], "asks": [[64660.0, 0.069], [64662.0, 0.081], [64662.3, 0.179], [64663.2, 0.121], [64665.6, 0.093], [65069.8, 0.001], [65105.6, 0.005], [65304.3, 0.373], [65627.6, 3.496], [65950.8, 0.009], [71123.5, 0.001]]}
{"kind": "depth", "E": 1787082416067, "U": 11315510565670, "u": 11315510570477, "recv_ms": 1787082416040, "bids": [[1000.0, 35.81], [14157.6, 1.68], [14557.6, 2.52], [34000.0, 1.146], [58191.8, 0.002], [61424.7, 0.013], [62071.2, 0.003], [63720.1, 9.35], [64140.3, 7.129], [64516.5, 5.165], [64644.5, 0.154], [64645.1, 0.027], [64646.0, 1.875], [64646.4, 0.837], [64657.6, 21.766]], "asks": [[64797.6, 5.402], [64853.3, 1.73], [65045.7, 0.003], [65082.6, 0.008], [65211.5, 0.0], [65304.3, 0.373]]}
{"kind": "depth", "E": 1787082416169, "U": 11315510570542, "u": 11315510577364, "recv_ms": 1787082416139, "bids": [[1000.0, 35.81], [14157.6, 1.316], [14557.6, 2.884], [51726.0, 0.002], [58191.8, 0.002], [61424.7, 0.013], [63657.6, 0.0], [64011.0, 0.222], [64581.6, 0.533], [64606.3, 0.08], [64624.7, 0.001], [64624.8, 2.161], [64624.9, 0.001], [64628.2, 0.002], [64628.3, 0.002], [64628.4, 0.0], [64644.1, 1.048], [64644.5, 0.154], [64644.6, 0.031], [64646.3, 0.009], [64646.4, 0.836], [64657.6, 21.767]], "asks": [[64659.1, 0.005], [64659.8, 0.003], [64661.2, 0.107], [64662.5, 0.003], [64667.2, 0.097], [64686.1, 2.186], [64817.5, 0.311], [64817.8, 0.002], [65304.3, 0.373], [65429.8, 17.538], [65534.7, 0.609], [65657.7, 0.001]]}
{"kind": "depth", "E": 1787082416271, "U": 11315510577458, "u": 11315510585050, "recv_ms": 1787082416241, "bids": [[14157.6, 0.966], [14557.6, 3.234], [51726.0, 0.0], [58191.8, 0.002], [61424.7, 0.011], [61424.8, 0.008], [62071.2, 0.0], [63776.1, 9.704], [64011.0, 0.222], [64334.3, 3.574]], "asks": [[64659.1, 0.399], [64661.1, 0.004], [64661.7, 0.002], [64661.9, 0.013], [64981.0, 3.504], [65304.3, 0.373], [65477.0, 0.32], [65543.5, 1.403]]}
{"kind": "depth", "E": 1787082416373, "U": 11315510585147, "u": 11315510591848, "recv_ms": 1787082416343, "bids": [[1000.0, 35.81], [14157.6, 0.602], [14557.6, 3.598], [58191.8, 0.002], [61424.7, 0.011], [62071.2, 0.003], [63657.6, 0.02], [64011.0, 0.222], [64635.5, 0.008], [64635.6, 0.853], [64642.9, 0.759], [64644.1, 1.047], [64644.2, 0.631], [64644.5, 0.0], [64646.2, 0.166], [64656.2, 0.0], [64657.6, 21.766]], "asks": [[64659.8, 0.003], [64661.2, 0.088], [64662.8, 0.002], [64669.8, 0.628], [64677.1, 1.463], [64693.0, 0.032], [64702.2, 0.628], [64853.3, 1.552], [65220.2, 0.395], [65304.3, 0.373], [65657.7, 0.021]]}
{"kind": "depth", "E": 1787082416475, "U": 11315510591898, "u": 11315510602592, "recv_ms": 1787082416452, "bids": [[1000.0, 35.81], [14157.6, 0.336], [14457.6, 0.084], [14557.6, 3.78], [58191.8, 0.004], [61424.8, 0.006], [62071.2, 0.0], [63784.7, 2.188], [63806.9, 0.783], [64011.0, 0.222], [64136.8, 0.504], [64516.5, 0.0], [64552.0, 3.558], [64557.3, 0.012], [64562.6, 2.319], [64566.3, 0.016], [64567.9, 0.008], [64568.4, 2.767], [64571.1, 0.417], [64572.7, 2.519], [64573.2, 0.0], [64578.5, 0.003], [64583.8, 0.001], [64587.9, 0.154], [64589.1, 0.001], [64589.4, 0.21], [64590.2, 0.014], [64594.4, 0.067], [64595.5, 0.038], [64596.8, 1.252], [64599.7, 0.403], [64605.0, 0.876], [64610.3, 0.007], [64615.6, 0.058], [64618.1, 0.026], [64620.9, 0.015], [64623.1, 1.673], [64625.0, 1.59], [64626.2, 0.0], [64627.0, 0.06], [64630.1, 1.402], [64631.5, 0.003], [64636.5, 0.611], [64636.8, 3.859], [64639.7, 0.434], [64642.1, 0.007], [64643.5, 0.01], [64644.3, 0.004], [64646.2, 0.166], [64646.3, 0.001], [64647.4, 0.117], [64650.0, 0.163], [64650.6, 0.002], [64650.7, 0.171], [64651.4, 0.086], [64651.8, 0.363], [64653.5, 0.002], [64653.9, 1.173], [64654.3, 0.24], [64655.0, 1.026], [64655.4, 0.003], [64655.6, 0.0], [64656.8, 0.002], [64657.6, 21.746]], "asks": [[64657.7, 9.536], [64657.8, 0.086], [64658.2, 0.087], [64658.6, 0.086], [64661.6, 0.402], [64661.8, 0.029], [64662.6, 0.001], [64663.0, 0.006], [64663.4, 0.023], [64672.8, 0.385], [64673.3, 0.001], [64677.6, 0.02], [64678.6, 0.008], [64680.9, 10.062], [64682.3, 2.039], [64682.6, 0.0], [64683.9, 2.51], [64686.2, 0.092], [64686.9, 0.002], [64689.2, 0.029], [64689.6, 1.03], [64694.5, 0.07], [64696.2, 0.058], [64699.8, 2.381], [64701.6, 0.001], [64705.1, 2.349], [64708.3, 0.062], [64710.4, 0.028], [64715.7, 0.0], [64721.0, 0.043], [64726.3, 0.001], [64729.8, 0.049], [64731.6, 0.003], [64732.1, 0.0], [64736.9, 0.446], [64742.2, 1.071], [64747.5, 0.0], [64752.8, 0.002], [64758.1, 0.0], [64763.4, 0.015], [64768.7, 0.118], [64797.6, 4.434], [64814.5, 0.022], [64814.6, 6.808], [64853.3, 6.213], [65304.3, 0.373], [65433.6, 11.859], [65657.7, 0.001]]}
