{"receive_ns":1788563740463992000,"stream":"btcusdt@depth@100ms","event_type":"depthUpdate","event_time_ms":1788563740493,"raw_json":"{\"stream\":\"btcusdt@depth@100ms\",\"data\":{\"e\":\"depthUpdate\",\"E\":1788563740493,\"T\":1788563740492,\"s\":\"BTCUSDT\",\"ps\":\"BTCUSDT\",\"U\":11478251496053,\"u\":11478251505559,\"pu\":11478251495799,\"b\":[[\"1000.00\",\"24.754\"],[\"29096.20\",\"1.449\"],[\"29496.30\",\"0.357\"],[\"63677.00\",\"0.000\"],[\"71636.60\",\"0.005\"],[\"71671.00\",\"0.000\"],[\"76412.40\",\"0.002\"],[\"78533.40\",\"7.958\"],[\"78800.30\",\"0.000\"],[\"79198.30\",\"0.078\"],[\"79222.20\",\"0.340\"],[\"79449.50\",\"0.000\"],[\"79451.50\",\"0.014\"],[\"79466.80\",\"0.000\"],[\"79471.80\",\"0.101\"],[\"79472.50\",\"0.052\"],[\"79476.30\",\"5.567\"],[\"79479.90\",\"1.485\"],[\"79488.80\",\"1.531\"],[\"79500.70\",\"0.000\"],[\"79510.60\",\"0.004\"],[\"79522.10\",\"2.541\"],[\"79524.60\",\"0.002\"],[\"79539.40\",\"18.687\"],[\"79539.90\",\"0.001\"],[\"79540.60\",\"1.810\"],[\"79540.80\",\"0.001\"],[\"79542.60\",\"0.326\"],[\"79554.30\",\"0.001\"],[\"79554.90\",\"0.005\"],[\"79558.40\",\"0.492\"],[\"79560.70\",\"0.003\"],[\"79564.50\",\"2.002\"],[\"79565.50\",\"0.003\"],[\"79566.60\",\"0.167\"],[\"79569.60\",\"0.023\"],[\"79570.40\",\"1.287\"],[\"79572.30\",\"0.046\"],[\"79575.20\",\"0.003\"],[\"79575.60\",\"1.077\"],[\"79583.10\",\"0.002\"],[\"79584.50\",\"0.069\"],[\"79585.60\",\"0.055\"],[\"79588.40\",\"2.139\"],[\"79588.80\",\"0.005\"],[\"79589.20\",\"0.105\"],[\"79590.10\",\"0.362\"],[\"79594.00\",\"0.002\"],[\"79596.10\",\"0.008\"],[\"79596.20\",\"5.550\"],[\"79596.30\",\"14.778\"]],\"a\":[[\"79599.50\",\"0.001\"],[\"79599.70\",\"0.001\"],[\"79600.00\",\"1.468\"],[\"79600.10\",\"0.034\"],[\"79602.20\",\"0.002\"],[\"79602.30\",\"0.002\"],[\"79604.60\",\"0.003\"],[\"79608.20\",\"0.002\"],[\"79609.30\",\"0.439\"],[\"79614.60\",\"0.004\"],[\"79619.70\",\"0.278\"],[\"79626.80\",\"0.000\"],[\"79636.10\",\"0.068\"],[\"79647.30\",\"0.012\"],[\"79647.50\",\"0.051\"],[\"79650.80\",\"0.002\"],[\"79652.20\",\"0.041\"],[\"79665.80\",\"1.011\"],[\"79665.90\",\"5.652\"],[\"79666.10\",\"0.001\"],[\"79668.10\",\"0.003\"],[\"79676.80\",\"5.169\"],[\"79676.90\",\"25.839\"],[\"79696.90\",\"0.031\"],[\"79697.00\",\"0.019\"],[\"79766.50\",\"0.000\"],[\"79948.60\",\"1.121\"],[\"79993.90\",\"0.371\"],[\"79994.30\",\"0.251\"],[\"79994.40\",\"1.580\"],[\"80392.40\",\"0.000\"]],\"st\":1}}"}
{"receive_ns":1788563740592405000,"stream":"btcusdt@depth@100ms","event_type":"depthUpdate","event_time_ms":1788563740595,"raw_json":"{\"stream\":\"btcusdt@depth@100ms\",\"data\":{\"e\":\"depthUpdate\",\"E\":1788563740595,\"T\":1788563740594,\"s\":\"BTCUSDT\",\"ps\":\"BTCUSDT\",\"U\":11478251505635,\"u\":11478251512971,\"pu\":11478251505559,\"b\":[[\"1000.00\",\"24.754\"],[\"29096.20\",\"1.267\"],[\"29496.30\",\"0.539\"],[\"63675.00\",\"0.002\"],[\"71636.60\",\"0.005\"],[\"78800.30\",\"0.000\"],[\"79198.20\",\"0.010\"],[\"79472.30\",\"0.000\"],[\"79476.40\",\"0.007\"],[\"79488.00\",\"1.089\"],[\"79515.80\",\"2.655\"],[\"79544.60\",\"1.024\"],[\"79572.40\",\"0.373\"],[\"79572.50\",\"0.002\"],[\"79572.60\",\"0.006\"],[\"79573.70\",\"0.006\"],[\"79580.80\",\"0.345\"],[\"79584.50\",\"0.073\"],[\"79585.40\",\"0.240\"],[\"79585.60\",\"0.051\"],[\"79586.40\",\"0.002\"],[\"79587.20\",\"0.424\"],[\"79590.00\",\"0.508\"],[\"79590.40\",\"0.003\"],[\"79592.20\",\"0.119\"],[\"79596.00\",\"0.081\"],[\"79596.10\",\"0.014\"],[\"79596.20\",\"5.504\"],[\"79596.30\",\"14.827\"]],\"a\":[[\"79599.30\",\"0.002\"],[\"79599.50\",\"0.001\"],[\"79604.20\",\"0.005\"],[\"79604.90\",\"0.000\"],[\"79606.40\",\"0.004\"],[\"79606.90\",\"0.011\"],[\"79612.40\",\"1.593\"],[\"79612.50\",\"0.005\"],[\"79614.90\",\"0.004\"],[\"79630.30\",\"0.001\"],[\"79694.60\",\"0.007\"],[\"79713.80\",\"0.000\"],[\"79721.60\",\"0.001\"],[\"79792.00\",\"3.135\"],[\"79812.20\",\"0.751\"],[\"79812.60\",\"2.987\"],[\"80392.40\",\"0.000\"],[\"80591.30\",\"0.806\"]],\"st\":1}}"}
{"receive_ns":1788563740707221000,"stream":"btcusdt@depth@100ms","event_type":"depthUpdate","event_time_ms":1788563740697,"raw_json":"{\"stream\":\"btcusdt@depth@100ms\",\"data\":{\"e\":\"depthUpdate\",\"E\":1788563740697,\"T\":1788563740694,\"s\":\"BTCUSDT\",\"ps\":\"BTCUSDT\",\"U\":11478251513097,\"u\":11478251518511,\"pu\":11478251512971,\"b\":[[\"29096.20\",\"1.092\"],[\"29496.30\",\"0.714\"],[\"63675.00\",\"0.000\"],[\"71636.60\",\"0.005\"],[\"76412.40\",\"0.000\"],[\"78613.30\",\"8.114\"],[\"78800.30\",\"0.000\"],[\"79222.20\",\"0.340\"],[\"79460.40\",\"0.876\"],[\"79461.30\",\"0.003\"],[\"79488.80\",\"1.531\"],[\"79508.70\",\"0.038\"],[\"79537.50\",\"0.898\"],[\"79539.10\",\"0.000\"],[\"79539.40\",\"0.072\"],[\"79539.50\",\"0.126\"],[\"79539.90\",\"0.000\"],[\"79540.60\",\"0.002\"],[\"79542.00\",\"0.002\"],[\"79542.10\",\"18.469\"],[\"79542.60\",\"0.100\"],[\"79544.00\",\"3.977\"],[\"79544.60\",\"1.727\"],[\"79548.60\",\"0.002\"],[\"79567.80\",\"0.116\"],[\"79576.40\",\"1.006\"],[\"79579.40\",\"0.220\"],[\"79585.60\",\"0.001\"],[\"79588.00\",\"0.007\"],[\"79592.30\",\"0.012\"],[\"79593.50\",\"0.271\"],[\"79593.60\",\"0.081\"],[\"79596.20\",\"3.774\"],[\"79596.30\",\"16.539\"]],\"a\":[[\"79596.40\",\"1.338\"],[\"79600.00\",\"1.442\"],[\"79600.10\",\"0.034\"],[\"79659.20\",\"0.069\"],[\"79668.20\",\"8.385\"],[\"79668.90\",\"25.925\"],[\"79676.80\",\"1.539\"],[\"79676.90\",\"0.204\"],[\"79696.80\",\"0.000\"],[\"79697.20\",\"0.944\"],[\"79697.60\",\"1.779\"],[\"79818.50\",\"0.000\"],[\"79819.40\",\"0.003\"],[\"79948.60\",\"1.121\"],[\"79993.90\",\"0.401\"],[\"79994.40\",\"1.380\"],[\"80392.40\",\"0.000\"]],\"st\":1}}"}
{"receive_ns":1788563740823080000,"stream":"btcusdt@depth@100ms","event_type":"depthUpdate","event_time_ms":1788563740799,"raw_json":"{\"stream\":\"btcusdt@depth@100ms\",\"data\":{\"e\":\"depthUpdate\",\"E\":1788563740799,\"T\":1788563740797,\"s\":\"BTCUSDT\",\"ps\":\"BTCUSDT\",\"U\":11478251518670,\"u\":11478251525295,\"pu\":11478251518511,\"b\":[[\"1000.00\",\"24.754\"],[\"29096.20\",\"0.910\"],[\"29496.30\",\"0.896\"],[\"63675.00\",\"0.000\"],[\"71636.60\",\"0.005\"],[\"75609.70\",\"0.004\"],[\"75609.80\",\"0.002\"],[\"75616.50\",\"0.002\"],[\"76412.40\",\"0.002\"],[\"78800.30\",\"0.000\"],[\"79198.30\",\"0.079\"],[\"79470.20\",\"1.529\"],[\"79470.40\",\"0.429\"],[\"79516.50\",\"0.003\"],[\"79537.40\",\"0.786\"],[\"79539.40\",\"0.071\"],[\"79540.30\",\"0.004\"],[\"79544.60\",\"1.727\"],[\"79547.20\",\"0.503\"],[\"79569.40\",\"0.440\"],[\"79569.50\",\"0.000\"],[\"79571.00\",\"0.436\"],[\"79571.50\",\"0.001\"],[\"79572.40\",\"0.000\"],[\"79575.80\",\"0.000\"],[\"79580.20\",\"0.001\"],[\"79580.40\",\"0.075\"],[\"79581.00\",\"0.237\"],[\"79583.40\",\"0.260\"],[\"79584.20\",\"0.127\"],[\"79596.20\",\"3.773\"],[\"79596.30\",\"16.541\"]],\"a\":[[\"79599.30\",\"0.002\"],[\"79604.20\",\"0.001\"],[\"79604.90\",\"0.004\"],[\"79606.40\",\"0.443\"],[\"79609.30\",\"0.000\"],[\"79615.40\",\"1.295\"],[\"79616.30\",\"1.112\"],[\"79681.00\",\"0.001\"],[\"79694.90\",\"0.196\"],[\"79697.20\",\"0.944\"],[\"79717.60\",\"0.433\"],[\"79717.70\",\"0.000\"],[\"79757.70\",\"0.000\"],[\"79770.50\",\"0.005\"],[\"79994.30\",\"0.250\"],[\"79994.40\",\"1.580\"],[\"80392.40\",\"0.000\"]],\"st\":1}}"}
{"receive_ns":1788563740885174000,"stream":"btcusdt@depth@100ms","event_type":"depthUpdate","event_time_ms":1788563740901,"raw_json":"{\"stream\":\"btcusdt@depth@100ms\",\"data\":{\"e\":\"depthUpdate\",\"E\":1788563740901,\"T\":1788563740899,\"s\":\"BTCUSDT\",\"ps\":\"BTCUSDT\",\"U\":11478251525374,\"u\":11478251531300,\"pu\":11478251525295,\"b\":[[\"1000.00\",\"24.754\"],[\"29096.20\",\"0.735\"],[\"29496.30\",\"1.071\"],[\"63677.00\",\"0.004\"],[\"71636.60\",\"0.005\"],[\"75614.10\",\"0.000\"],[\"75614.20\",\"0.002\"],[\"76412.40\",\"0.000\"],[\"78641.00\",\"8.415\"],[\"78800.30\",\"0.000\"],[\"78925.20\",\"0.044\"],[\"78927.60\",\"0.021\"],[\"79198.20\",\"0.000\"],[\"79198.30\",\"0.089\"],[\"79222.20\",\"0.199\"],[\"79450.80\",\"0.504\"],[\"79473.50\",\"0.064\"],[\"79488.80\",\"1.299\"],[\"79542.60\",\"0.000\"],[\"79544.60\",\"1.024\"],[\"79576.40\",\"0.001\"],[\"79581.40\",\"0.076\"],[\"79587.70\",\"0.059\"],[\"79594.90\",\"0.126\"],[\"79596.30\",\"16.541\"]],\"a\":[[\"79599.80\",\"0.462\"],[\"79600.00\",\"1.468\"],[\"79602.10\",\"0.000\"],[\"79606.40\",\"0.004\"],[\"79607.50\",\"0.139\"],[\"79608.70\",\"0.439\"],[\"79619.10\",\"0.554\"],[\"79644.00\",\"0.672\"],[\"79647.20\",\"0.002\"],[\"79679.80\",\"0.016\"],[\"79680.20\",\"0.002\"],[\"79680.80\",\"3.703\"],[\"79681.10\",\"0.000\"],[\"79682.20\",\"0.023\"],[\"79692.00\",\"1.929\"],[\"79693.60\",\"0.033\"],[\"79694.10\",\"0.018\"],[\"79695.00\",\"0.148\"],[\"79696.20\",\"0.062\"],[\"79698.20\",\"0.128\"],[\"79948.60\",\"0.000\"],[\"79993.90\",\"0.188\"],[\"79994.40\",\"0.200\"],[\"80392.40\",\"0.000\"]],\"st\":1}}"}
{"receive_ns":1788563740978526000,"stream":"btcusdt@depth@100ms","event_type":"depthUpdate","event_time_ms":1788563741003,"raw_json":"{\"stream\":\"btcusdt@depth@100ms\",\"data\":{\"e\":\"depthUpdate\",\"E\":1788563741003,\"T\":1788563741002,\"s\":\"BTCUSDT\",\"ps\":\"BTCUSDT\",\"U\":11478251531427,\"u\":11478251536610,\"pu\":11478251531300,\"b\":[[\"29096.20\",\"0.553\"],[\"29496.30\",\"1.253\"],[\"63675.00\",\"0.000\"],[\"63677.00\",\"0.000\"],[\"71636.60\",\"0.005\"],[\"76412.40\",\"0.002\"],[\"78601.20\",\"0.711\"],[\"78800.30\",\"0.000\"],[\"79222.20\",\"0.340\"],[\"79303.10\",\"0.038\"],[\"79436.60\",\"0.021\"],[\"79454.00\",\"0.101\"],[\"79488.80\",\"1.531\"],[\"79544.60\",\"1.073\"],[\"79554.20\",\"0.034\"],[\"79565.40\",\"0.103\"],[\"79569.40\",\"0.001\"],[\"79573.10\",\"0.439\"],[\"79576.40\",\"1.006\"],[\"79580.40\",\"0.075\"],[\"79588.50\",\"0.077\"]],\"a\":[[\"79604.20\",\"0.001\"],[\"79604.90\",\"0.004\"],[\"79682.30\",\"0.000\"],[\"79684.10\",\"0.001\"],[\"79696.40\",\"0.066\"],[\"79697.30\",\"1.629\"],[\"79697.80\",\"0.001\"],[\"79711.00\",\"0.170\"],[\"79948.60\",\"1.121\"],[\"79993.90\",\"0.371\"],[\"79994.40\",\"1.580\"],[\"80392.40\",\"0.000\"],[\"81825.00\",\"0.314\"]],\"st\":1}}"}
{"receive_ns":1788563741095689000,"stream":"btcusdt@depth@100ms","event_type":"depthUpdate","event_time_ms":1788563741105,"raw_json":"{\"stream\":\"btcusdt@depth@100ms\",\"data\":{\"e\":\"depthUpdate\",\"E\":1788563741105,\"T\":1788563741104,\"s\":\"BTCUSDT\",\"ps\":\"BTCUSDT\",\"U\":11478251536830,\"u\":11478251542578,\"pu\":11478251536610,\"b\":[[\"1000.00\",\"24.754\"],[\"29096.20\",\"0.378\"],[\"29496.30\",\"1.428\"],[\"63677.00\",\"0.002\"],[\"71636.60\",\"0.005\"],[\"78800.30\",\"0.000\"],[\"79198.20\",\"0.000\"],[\"79198.30\",\"0.079\"],[\"79544.60\",\"2.078\"],[\"79564.60\",\"0.001\"],[\"79566.70\",\"0.454\"],[\"79568.10\",\"1.421\"],[\"79570.90\",\"0.005\"],[\"79571.00\",\"0.063\"],[\"79571.50\",\"0.440\"],[\"79573.10\",\"0.000\"],[\"79574.00\",\"0.377\"],[\"79576.40\",\"0.001\"],[\"79579.40\",\"0.170\"],[\"79579.80\",\"0.369\"],[\"79580.40\",\"0.000\"],[\"79582.00\",\"0.003\"],[\"79586.50\",\"0.002\"],[\"79590.40\",\"0.003\"],[\"79592.30\",\"0.445\"],[\"79594.30\",\"0.002\"],[\"79594.60\",\"0.001\"],[\"79596.30\",\"16.541\"]],\"a\":[[\"79597.90\",\"0.002\"],[\"79599.30\",\"0.002\"],[\"79599.80\",\"0.436\"],[\"79600.10\",\"0.032\"],[\"79601.30\",\"0.365\"],[\"79602.00\",\"0.032\"],[\"79604.40\",\"2.095\"],[\"79608.70\",\"0.000\"],[\"79609.90\",\"0.073\"],[\"79610.90\",\"0.439\"],[\"79612.80\",\"4.589\"],[\"79613.40\",\"0.004\"],[\"79614.00\",\"0.393\"],[\"79616.60\",\"0.003\"],[\"79616.80\",\"0.037\"],[\"79617.50\",\"0.452\"],[\"79618.90\",\"0.627\"],[\"79620.40\",\"0.003\"],[\"79622.80\",\"0.011\"],[\"79626.60\",\"0.020\"],[\"79632.70\",\"2.709\"],[\"79639.90\",\"0.001\"],[\"79665.80\",\"4.702\"],[\"79666.10\",\"25.800\"],[\"79668.20\",\"4.766\"],[\"79668.90\",\"0.126\"],[\"80392.40\",\"0.000\"],[\"81185.50\",\"0.006\"],[\"81188.30\",\"0.018\"]],\"st\":1}}"}
{"receive_ns":1788563741411647000,"stream":"btcusdt@depth@100ms","event_type":"depthUpdate","event_time_ms":1788563741207,"raw_json":"{\"stream\":\"btcusdt@depth@100ms\",\"data\":{\"e\":\"depthUpdate\",\"E\":1788563741207,\"T\":1788563741206,\"s\":\"BTCUSDT\",\"ps\":\"BTCUSDT\",\"U\":11478251542595,\"u\":11478251549385,\"pu\":11478251542578,\"b\":[[\"1000.00\",\"24.754\"],[\"29096.20\",\"0.245\"],[\"29396.30\",\"0.049\"],[\"29496.30\",\"1.512\"],[\"63677.00\",\"0.000\"],[\"71636.60\",\"0.005\"],[\"76412.40\",\"0.000\"],[\"78800.30\",\"0.000\"],[\"79222.20\",\"0.340\"],[\"79488.80\",\"1.531\"],[\"79544.60\",\"0.822\"],[\"79563.20\",\"0.043\"],[\"79566.90\",\"0.052\"],[\"79568.30\",\"0.003\"],[\"79571.50\",\"0.001\"],[\"79573.10\",\"0.439\"],[\"79574.70\",\"0.707\"],[\"79576.40\",\"1.006\"],[\"79581.40\",\"0.043\"],[\"79582.00\",\"0.003\"],[\"79588.60\",\"0.000\"],[\"79590.30\",\"0.025\"],[\"79590.40\",\"0.003\"],[\"79593.00\",\"0.000\"],[\"79596.30\",\"16.531\"]],\"a\":[[\"79596.40\",\"1.338\"],[\"79597.70\",\"0.000\"],[\"79598.00\",\"0.001\"],[\"79598.10\",\"0.000\"],[\"79598.20\",\"0.001\"],[\"79598.30\",\"0.000\"],[\"79598.40\",\"0.019\"],[\"79598.50\",\"0.000\"],[\"79599.00\",\"0.002\"],[\"79599.10\",\"0.002\"],[\"79599.20\",\"0.067\"],[\"79599.30\",\"0.002\"],[\"79599.40\",\"0.000\"],[\"79599.50\",\"0.027\"],[\"79600.30\",\"0.102\"],[\"79600.70\",\"0.031\"],[\"79600.80\",\"0.641\"],[\"79601.60\",\"0.322\"],[\"79601.70\",\"0.065\"],[\"79601.90\",\"0.001\"],[\"79602.00\",\"0.006\"],[\"79604.20\",\"0.005\"],[\"79604.90\",\"0.000\"],[\"79606.50\",\"3.088\"],[\"79607.60\",\"1.120\"],[\"79614.00\",\"0.021\"],[\"79615.30\",\"0.374\"],[\"79617.10\",\"0.016\"],[\"79617.50\",\"0.000\"],[\"79618.50\",\"0.454\"],[\"79619.10\",\"0.548\"],[\"79629.20\",\"0.001\"],[\"79630.80\",\"0.046\"],[\"79646.80\",\"0.001\"],[\"79647.50\",\"0.052\"],[\"79677.00\",\"0.514\"],[\"79682.10\",\"0.001\"],[\"79682.20\",\"0.022\"],[\"79682.30\",\"0.001\"],[\"79688.80\",\"0.033\"],[\"79689.50\",\"0.001\"],[\"79695.50\",\"0.000\"],[\"79695.70\",\"0.001\"],[\"79696.90\",\"0.029\"],[\"79697.10\",\"0.001\"],[\"79704.90\",\"0.005\"],[\"79705.10\",\"0.002\"],[\"79709.70\",\"0.830\"],[\"79948.60\",\"1.121\"],[\"79993.90\",\"0.400\"],[\"79994.40\",\"1.380\"],[\"80392.40\",\"0.002\"],[\"81079.90\",\"3.997\"]],\"st\":1}}"}
{"receive_ns":1788563741453467000,"stream":"btcusdt@depth@100ms","event_type":"depthUpdate","event_time_ms":1788563741309,"raw_json":"{\"stream\":\"btcusdt@depth@100ms\",\"data\":{\"e\":\"depthUpdate\",\"E\":1788563741309,\"T\":1788563741307,\"s\":\"BTCUSDT\",\"ps\":\"BTCUSDT\",\"U\":11478251549453,\"u\":11478251556262,\"pu\":11478251549385,\"b\":[[\"29096.20\",\"0.133\"],[\"29396.30\",\"0.112\"],[\"29496.30\",\"1.561\"],[\"71636.60\",\"0.005\"],[\"76412.40\",\"0.002\"],[\"77976.50\",\"0.000\"],[\"78065.00\",\"0.040\"],[\"78153.40\",\"0.000\"],[\"78241.80\",\"0.000\"],[\"78330.20\",\"0.011\"],[\"78418.60\",\"0.000\"],[\"78507.00\",\"0.002\"],[\"78595.40\",\"0.000\"],[\"78683.80\",\"0.000\"],[\"78772.20\",\"0.000\"],[\"78800.30\",\"0.000\"],[\"78959.50\",\"0.002\"],[\"79426.40\",\"6.963\"],[\"79442.30\",\"0.093\"],[\"79470.40\",\"0.000\"],[\"79470.50\",\"0.435\"],[\"79500.70\",\"0.002\"],[\"79526.30\",\"0.060\"],[\"79534.60\",\"0.003\"],[\"79544.60\",\"2.153\"],[\"79566.00\",\"1.369\"],[\"79573.90\",\"0.028\"],[\"79579.80\",\"0.319\"],[\"79581.00\",\"0.287\"],[\"79581.40\",\"0.076\"],[\"79582.20\",\"0.131\"],[\"79588.20\",\"0.097\"],[\"79594.90\",\"0.191\"],[\"79596.10\",\"0.015\"],[\"79596.20\",\"3.772\"],[\"79596.30\",\"12.388\"]],\"a\":[[\"79598.50\",\"0.017\"],[\"79599.50\",\"0.005\"],[\"79599.70\",\"0.027\"],[\"79600.90\",\"0.026\"],[\"79604.20\",\"0.001\"],[\"79604.30\",\"0.748\"],[\"79608.60\",\"1.408\"],[\"79624.50\",\"1.467\"],[\"79647.50\",\"0.051\"],[\"79668.10\",\"0.005\"],[\"79695.70\",\"0.002\"],[\"79717.60\",\"0.433\"],[\"79994.40\",\"1.580\"],[\"80363.60\",\"3.716\"],[\"80392.40\",\"0.000\"],[\"80452.00\",\"0.078\"],[\"80540.40\",\"0.000\"],[\"80628.80\",\"0.000\"],[\"80717.20\",\"0.000\"],[\"80805.60\",\"0.000\"],[\"80894.00\",\"0.000\"],[\"80982.40\",\"0.000\"],[\"81070.80\",\"0.058\"],[\"81087.90\",\"0.001\"],[\"81159.30\",\"4.677\"]],\"st\":1}}"}
{"receive_ns":1788563741502487000,"stream":"btcusdt@depth@100ms","event_type":"depthUpdate","event_time_ms":1788563741411,"raw_json":"{\"stream\":\"btcusdt@depth@100ms\",\"data\":{\"e\":\"depthUpdate\",\"E\":1788563741411,\"T\":1788563741409,\"s\":\"BTCUSDT\",\"ps\":\"BTCUSDT\",\"U\":11478251556329,\"u\":11478251561557,\"pu\":11478251556262,\"b\":[[\"1000.00\",\"24.754\"],[\"29096.20\",\"0.014\"],[\"29396.30\",\"0.175\"],[\"29496.30\",\"1.617\"],[\"71636.60\",\"0.005\"],[\"76412.40\",\"0.000\"],[\"78800.30\",\"0.000\"],[\"78927.60\",\"0.004\"],[\"79198.20\",\"0.000\"],[\"79222.20\",\"0.340\"],[\"79488.80\",\"1.531\"],[\"79510.70\",\"0.100\"],[\"79544.60\",\"3.058\"],[\"79566.00\",\"1.289\"],[\"79574.20\",\"0.001\"],[\"79576.40\",\"0.001\"],[\"79577.60\",\"0.160\"],[\"79578.20\",\"0.072\"],[\"79581.00\",\"0.237\"],[\"79581.10\",\"0.161\"],[\"79590.40\",\"0.003\"],[\"79596.30\",\"12.389\"]],\"a\":[[\"79604.30\",\"0.744\"],[\"79604.90\",\"0.004\"],[\"79948.60\",\"0.921\"],[\"79993.90\",\"0.188\"],[\"79994.40\",\"1.580\"],[\"80392.30\",\"0.932\"],[\"80392.40\",\"0.000\"]],\"st\":1}}"}
{"receive_ns":1788563741647387000,"stream":"btcusdt@depth@100ms","event_type":"depthUpdate","event_time_ms":1788563741513,"raw_json":"{\"stream\":\"btcusdt@depth@100ms\",\"data\":{\"e\":\"depthUpdate\",\"E\":1788563741513,\"T\":1788563741510,\"s\":\"BTCUSDT\",\"ps\":\"BTCUSDT\",\"U\":11478251561621,\"u\":11478251567629,\"pu\":11478251561557,\"b\":[[\"1000.00\",\"24.754\"],[\"29096.20\",\"0.000\"],[\"29396.30\",\"0.336\"],[\"29496.30\",\"1.470\"],[\"63677.00\",\"0.000\"],[\"71636.60\",\"0.005\"],[\"76412.40\",\"0.002\"],[\"78002.00\",\"0.050\"],[\"78004.40\",\"0.003\"],[\"78436.90\",\"8.126\"],[\"78800.30\",\"0.000\"],[\"79198.30\",\"0.078\"],[\"79544.50\",\"0.004\"],[\"79544.60\",\"3.058\"],[\"79566.20\",\"0.002\"],[\"79568.80\",\"0.009\"],[\"79570.20\",\"0.003\"],[\"79596.30\",\"12.388\"]],\"a\":[[\"79596.40\",\"1.888\"],[\"79598.30\",\"0.026\"],[\"79598.60\",\"0.026\"],[\"79599.10\",\"0.028\"],[\"79600.80\",\"0.615\"],[\"79600.90\",\"0.000\"],[\"79603.40\",\"0.788\"],[\"79619.70\",\"0.272\"],[\"79720.60\",\"10.204\"],[\"79749.30\",\"0.208\"],[\"79948.60\",\"1.121\"],[\"79994.40\",\"1.581\"],[\"80392.40\",\"0.000\"],[\"80523.10\",\"0.000\"],[\"80538.60\",\"4.038\"],[\"81068.90\",\"0.800\"],[\"81185.50\",\"0.000\"]],\"st\":1}}"}
{"receive_ns":1788563741659632000,"stream":"btcusdt@depth@100ms","event_type":"depthUpdate","event_time_ms":1788563741615,"raw_json":"{\"stream\":\"btcusdt@depth@100ms\",\"data\":{\"e\":\"depthUpdate\",\"E\":1788563741615,\"T\":1788563741613,\"s\":\"BTCUSDT\",\"ps\":\"BTCUSDT\",\"U\":11478251567750,\"u\":11478251572808,\"pu\":11478251567629,\"b\":[[\"29396.30\",\"0.518\"],[\"29496.30\",\"1.288\"],[\"63677.00\",\"0.002\"],[\"71636.60\",\"0.005\"],[\"71672.00\",\"0.000\"],[\"78573.20\",\"13.938\"],[\"78800.30\",\"0.000\"],[\"79564.20\",\"0.001\"],[\"79568.00\",\"0.021\"],[\"79568.10\",\"1.423\"],[\"79572.60\",\"0.006\"]],\"a\":[[\"79597.80\",\"0.000\"],[\"79598.00\",\"0.001\"],[\"79598.30\",\"0.000\"],[\"79600.70\",\"0.005\"],[\"79604.20\",\"0.001\"],[\"79604.90\",\"0.004\"],[\"79612.50\",\"0.005\"],[\"79681.30\",\"0.007\"],[\"79694.60\",\"0.001\"],[\"79701.00\",\"0.015\"],[\"79709.20\",\"0.001\"],[\"80392.40\",\"0.000\"],[\"80716.10\",\"19.985\"]],\"st\":1}}"}
{"receive_ns":1788563741784471000,"stream":"btcusdt@depth@100ms","event_type":"depthUpdate","event_time_ms":1788563741717,"raw_json":"{\"stream\":\"btcusdt@depth@100ms\",\"data\":{\"e\":\"depthUpdate\",\"E\":1788563741717,\"T\":1788563741716,\"s\":\"BTCUSDT\",\"ps\":\"BTCUSDT\",\"U\":11478251572877,\"u\":11478251578667,\"pu\":11478251572808,\"b\":[[\"1000.00\",\"24.754\"],[\"29396.30\",\"0.693\"],[\"29496.30\",\"1.113\"],[\"63677.00\",\"0.000\"],[\"71636.60\",\"0.005\"],[\"76412.40\",\"0.000\"],[\"78002.00\",\"0.047\"],[\"78004.40\",\"0.006\"],[\"78800.30\",\"0.000\"],[\"78925.00\",\"0.007\"],[\"79198.30\",\"0.088\"],[\"79222.20\",\"0.340\"],[\"79488.80\",\"1.531\"],[\"79510.70\",\"0.351\"],[\"79526.30\",\"0.000\"],[\"79537.10\",\"0.067\"],[\"79544.60\",\"1.802\"],[\"79566.70\",\"0.002\"],[\"79569.70\",\"0.454\"],[\"79574.00\",\"0.004\"],[\"79577.00\",\"0.449\"],[\"79590.40\",\"0.003\"],[\"79596.30\",\"12.389\"]],\"a\":[[\"79596.40\",\"1.893\"],[\"79598.10\",\"0.026\"],[\"79598.60\",\"0.000\"],[\"79598.70\",\"0.078\"],[\"79598.90\",\"0.027\"],[\"79599.00\",\"0.028\"],[\"79599.20\",\"0.067\"],[\"79599.90\",\"0.124\"],[\"79600.60\",\"0.227\"],[\"79610.90\",\"0.000\"],[\"79612.30\",\"0.440\"],[\"79615.30\",\"0.002\"],[\"79616.90\",\"0.416\"],[\"79618.50\",\"0.002\"],[\"79619.50\",\"0.455\"],[\"79630.80\",\"0.000\"],[\"79632.30\",\"0.047\"],[\"79660.10\",\"0.146\"],[\"79948.60\",\"1.121\"],[\"79994.40\",\"1.581\"],[\"80392.40\",\"0.000\"],[\"80631.20\",\"1.858\"],[\"80671.00\",\"0.495\"]],\"st\":1}}"}
{"receive_ns":1788563741797839000,"stream":"btcusdt@depth@100ms","event_type":"depthUpdate","event_time_ms":1788563741819,"raw_json":"{\"stream\":\"btcusdt@depth@100ms\",\"data\":{\"e\":\"depthUpdate\",\"E\":1788563741819,\"T\":1788563741818,\"s\":\"BTCUSDT\",\"ps\":\"BTCUSDT\",\"U\":11478251578736,\"u\":11478251583067,\"pu\":11478251578667,\"b\":[[\"1000.00\",\"24.754\"],[\"29396.30\",\"0.875\"],[\"29496.30\",\"0.931\"],[\"71636.60\",\"0.005\"],[\"76412.40\",\"0.002\"],[\"76600.00\",\"29.837\"],[\"78426.10\",\"0.449\"],[\"78604.70\",\"0.000\"],[\"78609.50\",\"0.003\"],[\"78700.00\",\"128.277\"],[\"78800.30\",\"0.000\"],[\"79198.30\",\"0.087\"],[\"79338.80\",\"0.011\"],[\"79371.60\",\"7.535\"],[\"79371.70\",\"2.844\"],[\"79500.70\",\"0.002\"],[\"79510.70\",\"1.356\"],[\"79524.60\",\"0.000\"],[\"79568.30\",\"0.455\"],[\"79569.70\",\"0.002\"],[\"79575.60\",\"1.450\"],[\"79577.00\",\"0.076\"]],\"a\":[[\"79632.10\",\"0.420\"],[\"79660.40\",\"0.090\"],[\"79668.10\",\"0.005\"],[\"79687.80\",\"0.033\"],[\"79994.40\",\"1.582\"],[\"80392.40\",\"0.000\"],[\"80527.60\",\"1.673\"],[\"81427.00\",\"0.615\"]],\"st\":1}}"}
{"receive_ns":1788563741898105000,"stream":"btcusdt@depth@100ms","event_type":"depthUpdate","event_time_ms":1788563741921,"raw_json":"{\"stream\":\"btcusdt@depth@100ms\",\"data\":{\"e\":\"depthUpdate\",\"E\":1788563741921,\"T\":1788563741919,\"s\":\"BTCUSDT\",\"ps\":\"BTCUSDT\",\"U\":11478251583195,\"u\":11478251589017,\"pu\":11478251583067,\"b\":[[\"29396.30\",\"1.050\"],[\"29496.30\",\"0.756\"],[\"63677.00\",\"0.000\"],[\"71636.60\",\"0.005\"],[\"76412.40\",\"0.000\"],[\"78800.30\",\"0.000\"],[\"78879.90\",\"0.963\"],[\"79222.20\",\"0.340\"],[\"79488.80\",\"1.531\"],[\"79510.70\",\"1.105\"],[\"79544.60\",\"1.727\"],[\"79547.20\",\"0.514\"]],\"a\":[[\"79598.40\",\"0.003\"],[\"79948.60\",\"1.121\"],[\"79994.40\",\"1.382\"],[\"80392.40\",\"0.000\"],[\"80642.10\",\"33.781\"]],\"st\":1}}"}
{"receive_ns":1788563742010879000,"stream":"btcusdt@depth@100ms","event_type":"depthUpdate","event_time_ms":1788563742023,"raw_json":"{\"stream\":\"btcusdt@depth@100ms\",\"data\":{\"e\":\"depthUpdate\",\"E\":1788563742023,\"T\":1788563742022,\"s\":\"BTCUSDT\",\"ps\":\"BTCUSDT\",\"U\":11478251589124,\"u\":11478251593345,\"pu\":11478251589017,\"b\":[[\"1000.00\",\"24.754\"],[\"29396.30\",\"1.232\"],[\"29496.20\",\"0.252\"],[\"29496.30\",\"0.616\"],[\"63677.00\",\"0.000\"],[\"71636.60\",\"0.005\"],[\"75616.50\",\"0.004\"],[\"78800.30\",\"0.000\"],[\"79198.30\",\"0.087\"],[\"79470.50\",\"0.006\"],[\"79470.70\",\"0.430\"],[\"79510.70\",\"1.105\"],[\"79523.80\",\"0.105\"],[\"79535.70\",\"0.029\"],[\"79544.60\",\"2.053\"],[\"79568.80\",\"0.003\"],[\"79590.40\",\"0.003\"],[\"79594.90\",\"0.193\"],[\"79596.30\",\"12.389\"]],\"a\":[[\"79598.10\",\"0.026\"],[\"79599.20\",\"0.067\"],[\"79602.00\",\"0.001\"],[\"79628.00\",\"2.178\"],[\"79717.60\",\"0.433\"],[\"79994.40\",\"1.582\"],[\"80392.40\",\"0.000\"],[\"80774.10\",\"0.001\"],[\"81427.00\",\"1.228\"]],\"st\":1}}"}
{"receive_ns":1788563742174583000,"stream":"btcusdt@depth@100ms","event_type":"depthUpdate","event_time_ms":1788563742125,"raw_json":"{\"stream\":\"btcusdt@depth@100ms\",\"data\":{\"e\":\"depthUpdate\",\"E\":1788563742125,\"T\":1788563742124,\"s\":\"BTCUSDT\",\"ps\":\"BTCUSDT\",\"U\":11478251593417,\"u\":11478251599584,\"pu\":11478251593345,\"b\":[[\"1000.00\",\"24.754\"],[\"29396.30\",\"1.407\"],[\"29496.20\",\"0.189\"],[\"29496.30\",\"0.504\"],[\"63677.00\",\"0.000\"],[\"71636.60\",\"0.005\"],[\"76412.40\",\"0.002\"],[\"78004.40\",\"0.009\"],[\"78800.30\",\"0.002\"],[\"79222.20\",\"0.199\"],[\"79488.80\",\"1.299\"],[\"79510.70\",\"1.005\"],[\"79544.60\",\"0.345\"],[\"79547.20\",\"0.321\"],[\"79567.00\",\"0.452\"],[\"79568.30\",\"0.003\"],[\"79574.40\",\"0.628\"],[\"79575.60\",\"1.077\"],[\"79582.00\",\"0.003\"],[\"79590.40\",\"0.003\"],[\"79596.30\",\"12.376\"]],\"a\":[[\"79598.10\",\"0.000\"],[\"79598.30\",\"0.000\"],[\"79598.50\",\"0.033\"],[\"79598.70\",\"0.104\"],[\"79600.50\",\"0.002\"],[\"79611.20\",\"0.006\"],[\"79613.40\",\"0.003\"],[\"79616.80\",\"0.489\"],[\"79619.50\",\"0.003\"],[\"79637.70\",\"0.410\"],[\"79639.90\",\"0.000\"],[\"79752.50\",\"0.000\"],[\"79948.60\",\"0.000\"],[\"79994.40\",\"0.202\"],[\"80392.40\",\"0.000\"],[\"80591.40\",\"0.278\"],[\"80713.70\",\"10.014\"],[\"81185.70\",\"0.006\"]],\"st\":1}}"}
{"receive_ns":1788563742228017000,"stream":"btcusdt@depth@100ms","event_type":"depthUpdate","event_time_ms":1788563742227,"raw_json":"{\"stream\":\"btcusdt@depth@100ms\",\"data\":{\"e\":\"depthUpdate\",\"E\":1788563742227,\"T\":1788563742225,\"s\":\"BTCUSDT\",\"ps\":\"BTCUSDT\",\"U\":11478251599628,\"u\":11478251605603,\"pu\":11478251599584,\"b\":[[\"29396.30\",\"1.589\"],[\"29496.20\",\"0.133\"],[\"29496.30\",\"0.378\"],[\"71636.60\",\"0.005\"],[\"76412.40\",\"0.000\"],[\"78800.30\",\"0.000\"],[\"78999.20\",\"1.264\"],[\"79222.20\",\"0.340\"],[\"79452.40\",\"3.754\"],[\"79488.80\",\"1.782\"],[\"79510.70\",\"0.175\"],[\"79529.10\",\"0.061\"],[\"79537.10\",\"0.007\"],[\"79544.60\",\"1.727\"],[\"79565.20\",\"0.046\"],[\"79566.90\",\"0.006\"],[\"79571.50\",\"0.001\"],[\"79573.10\",\"0.000\"],[\"79574.90\",\"0.505\"],[\"79589.70\",\"0.253\"],[\"79592.10\",\"0.002\"],[\"79596.20\",\"3.672\"],[\"79596.30\",\"12.381\"]],\"a\":[[\"79598.10\",\"0.000\"],[\"79598.30\",\"0.000\"],[\"79599.30\",\"0.002\"],[\"79599.50\",\"0.007\"],[\"79609.30\",\"0.000\"],[\"79610.90\",\"0.439\"],[\"79612.30\",\"0.001\"],[\"79613.50\",\"0.000\"],[\"79615.60\",\"0.522\"],[\"79616.80\",\"0.037\"],[\"79616.90\",\"0.044\"],[\"79618.10\",\"0.453\"],[\"79677.50\",\"0.003\"],[\"79682.30\",\"0.000\"],[\"79682.50\",\"0.020\"],[\"79695.70\",\"0.000\"],[\"79695.90\",\"0.025\"],[\"79697.10\",\"0.000\"],[\"79697.20\",\"0.945\"],[\"79705.10\",\"0.001\"],[\"79705.20\",\"0.002\"],[\"79709.90\",\"0.005\"],[\"79948.60\",\"1.121\"],[\"79994.40\",\"1.582\"],[\"80392.40\",\"0.000\"],[\"80642.10\",\"31.923\"],[\"80702.70\",\"1.238\"]],\"st\":1}}"}
{"receive_ns":1788563744466637000,"stream":"btcusdt@depth@100ms","event_type":"depthUpdate","event_time_ms":1788563742329,"raw_json":"{\"stream\":\"btcusdt@depth@100ms\",\"data\":{\"e\":\"depthUpdate\",\"E\":1788563742329,\"T\":1788563742328,\"s\":\"BTCUSDT\",\"ps\":\"BTCUSDT\",\"U\":11478251605731,\"u\":11478251618381,\"pu\":11478251605603,\"b\":[[\"1000.00\",\"24.754\"],[\"29299.50\",\"0.007\"],[\"29396.30\",\"1.701\"],[\"29399.50\",\"0.049\"],[\"29496.20\",\"0.077\"],[\"29496.30\",\"0.266\"],[\"71636.60\",\"0.003\"],[\"71639.50\",\"0.002\"],[\"76412.40\",\"0.002\"],[\"78561.40\",\"0.254\"],[\"78589.50\",\"0.198\"],[\"78599.50\",\"0.005\"],[\"78800.30\",\"0.001\"],[\"78803.50\",\"0.000\"],[\"78927.60\",\"0.031\"],[\"78952.30\",\"0.000\"],[\"78962.70\",\"0.001\"],[\"79031.90\",\"0.000\"],[\"79042.30\",\"0.004\"],[\"79111.50\",\"0.001\"],[\"79121.90\",\"0.127\"],[\"79167.00\",\"0.000\"],[\"79191.10\",\"0.000\"],[\"79198.30\",\"0.087\"],[\"79201.50\",\"0.001\"],[\"79250.80\",\"0.500\"],[\"79270.60\",\"0.000\"],[\"79281.10\",\"0.212\"],[\"79350.20\",\"0.190\"],[\"79360.70\",\"0.001\"],[\"79418.40\",\"11.179\"],[\"79428.90\",\"0.001\"],[\"79429.80\",\"0.004\"],[\"79440.30\",\"0.022\"],[\"79443.80\",\"0.000\"],[\"79452.40\",\"3.729\"],[\"79454.30\",\"0.031\"],[\"79468.40\",\"0.000\"],[\"79470.20\",\"1.229\"],[\"79470.70\",\"0.001\"],[\"79470.80\",\"0.367\"],[\"79475.40\",\"0.000\"],[\"79478.00\",\"0.429\"],[\"79478.10\",\"0.000\"],[\"79478.40\",\"2.483\"],[\"79478.50\",\"0.339\"],[\"79480.30\",\"0.034\"],[\"79486.00\",\"0.000\"],[\"79488.80\",\"2.787\"],[\"79488.90\",\"0.000\"],[\"79490.90\",\"0.038\"],[\"79491.30\",\"2.551\"],[\"79491.40\",\"1.513\"],[\"79492.80\",\"0.002\"],[\"79493.10\",\"0.004\"],[\"79494.00\",\"0.001\"],[\"79495.60\",\"0.039\"],[\"79495.90\",\"0.000\"],[\"79498.80\",\"0.000\"],[\"79499.20\",\"1.257\"],[\"79500.00\",\"3.671\"],[\"79500.30\",\"1.195\"],[\"79500.40\",\"0.038\"],[\"79500.70\",\"0.040\"],[\"79500.80\",\"0.038\"],[\"79501.50\",\"0.000\"],[\"79501.90\",\"0.197\"],[\"79502.00\",\"0.001\"],[\"79502.20\",\"0.333\"],[\"79504.00\",\"0.375\"],[\"79507.40\",\"0.038\"],[\"79508.00\",\"6.119\"],[\"79508.70\",\"0.000\"],[\"79509.40\",\"4.520\"],[\"79509.90\",\"0.361\"],[\"79510.00\",\"0.342\"],[\"79510.30\",\"0.038\"],[\"79510.70\",\"0.100\"],[\"79511.00\",\"0.038\"],[\"79512.30\",\"0.000\"],[\"79514.00\",\"0.008\"],[\"79514.70\",\"0.079\"],[\"79515.10\",\"0.122\"],[\"79515.30\",\"0.001\"],[\"79515.70\",\"1.209\"],[\"79516.30\",\"1.326\"],[\"79516.50\",\"0.001\"],[\"79517.30\",\"0.003\"],[\"79518.10\",\"0.000\"],[\"79518.80\",\"0.015\"],[\"79518.90\",\"0.065\"],[\"79519.30\",\"0.000\"],[\"79519.40\",\"0.000\"],[\"79519.90\",\"0.351\"],[\"79520.70\",\"0.010\"],[\"79522.10\",\"2.513\"],[\"79522.70\",\"0.003\"],[\"79523.40\",\"0.041\"],[\"79524.10\",\"3.488\"],[\"79528.00\",\"0.022\"],[\"79528.60\",\"0.001\"],[\"79529.10\",\"0.001\"],[\"79531.00\",\"0.045\"],[\"79531.80\",\"0.020\"],[\"79532.10\",\"0.799\"],[\"79532.50\",\"2.831\"],[\"79532.60\",\"2.355\"],[\"79532.70\",\"1.307\"],[\"79533.10\",\"0.242\"],[\"79533.30\",\"0.057\"],[\"79533.50\",\"0.002\"],[\"79535.80\",\"0.152\"],[\"79536.70\",\"18.417\"],[\"79537.10\",\"0.004\"],[\"79537.80\",\"0.000\"],[\"79538.80\",\"0.000\"],[\"79539.00\",\"0.206\"],[\"79540.90\",\"0.003\"],[\"79541.20\",\"0.076\"],[\"79542.10\",\"0.001\"],[\"79542.80\",\"0.084\"],[\"79542.90\",\"0.003\"],[\"79543.10\",\"1.288\"],[\"79543.80\",\"1.007\"],[\"79544.00\",\"1.423\"],[\"79544.60\",\"1.708\"],[\"79545.10\",\"0.197\"],[\"79547.10\",\"1.290\"],[\"79547.30\",\"0.002\"],[\"79548.10\",\"0.001\"],[\"79549.20\",\"0.000\"],[\"79551.50\",\"0.073\"],[\"79551.70\",\"0.002\"],[\"79552.00\",\"1.088\"],[\"79552.20\",\"0.298\"],[\"79553.60\",\"0.003\"],[\"79554.00\",\"0.002\"],[\"79556.30\",\"0.000\"],[\"79556.90\",\"0.709\"],[\"79557.10\",\"2.003\"],[\"79557.20\",\"0.114\"],[\"79557.30\",\"0.005\"],[\"79557.70\",\"0.002\"],[\"79558.60\",\"0.001\"],[\"79559.70\",\"0.004\"],[\"79559.90\",\"0.000\"],[\"79560.00\",\"1.600\"],[\"79560.10\",\"0.006\"],[\"79560.60\",\"0.019\"],[\"79560.70\",\"0.004\"],[\"79561.50\",\"0.341\"],[\"79561.70\",\"0.200\"],[\"79562.00\",\"0.002\"],[\"79562.20\",\"0.002\"],[\"79562.40\",\"0.807\"],[\"79563.10\",\"10.548\"],[\"79563.30\",\"0.122\"],[\"79564.50\",\"0.002\"],[\"79564.70\",\"0.001\"],[\"79564.80\",\"0.715\"],[\"79565.20\",\"0.000\"],[\"79565.80\",\"0.050\"],[\"79566.30\",\"0.001\"],[\"79566.70\",\"0.001\"],[\"79566.80\",\"0.046\"],[\"79566.90\",\"0.000\"],[\"79567.00\",\"0.000\"],[\"79567.50\",\"0.248\"],[\"79567.60\",\"0.779\"],[\"79567.80\",\"0.115\"],[\"79568.00\",\"0.020\"],[\"79568.20\",\"0.707\"],[\"79568.30\",\"0.009\"],[\"79568.60\",\"0.000\"],[\"79568.80\",\"0.004\"],[\"79569.00\",\"0.628\"],[\"79569.30\",\"1.193\"],[\"79569.40\",\"0.001\"],[\"79570.30\",\"0.305\"],[\"79570.40\",\"1.288\"],[\"79570.60\",\"0.000\"],[\"79570.70\",\"0.000\"],[\"79570.80\",\"0.040\"],[\"79570.90\",\"0.003\"],[\"79571.00\",\"0.001\"],[\"79571.70\",\"0.005\"],[\"79572.30\",\"0.045\"],[\"79572.60\",\"0.005\"],[\"79573.00\",\"0.001\"],[\"79573.10\",\"0.000\"],[\"79573.40\",\"0.064\"],[\"79574.00\",\"0.002\"],[\"79574.20\",\"0.003\"],[\"79574.40\",\"0.255\"],[\"79574.70\",\"0.079\"],[\"79574.90\",\"0.001\"],[\"79575.40\",\"0.071\"],[\"79575.50\",\"0.042\"],[\"79575.60\",\"1.079\"],[\"79575.70\",\"0.441\"],[\"79576.00\",\"0.007\"],[\"79576.20\",\"0.374\"],[\"79576.50\",\"0.002\"],[\"79576.60\",\"0.629\"],[\"79576.70\",\"0.628\"],[\"79576.90\",\"0.002\"],[\"79577.00\",\"0.076\"],[\"79577.30\",\"0.126\"],[\"79577.40\",\"0.061\"],[\"79577.60\",\"0.081\"],[\"79577.90\",\"0.116\"],[\"79578.30\",\"0.000\"],[\"79578.60\",\"0.072\"],[\"79578.70\",\"1.358\"],[\"79579.20\",\"0.102\"],[\"79579.30\",\"0.695\"],[\"79579.60\",\"0.002\"],[\"79579.70\",\"0.832\"],[\"79579.80\",\"0.350\"],[\"79579.90\",\"0.033\"],[\"79580.00\",\"0.006\"],[\"79580.60\",\"0.628\"],[\"79580.80\",\"0.339\"],[\"79580.90\",\"0.080\"],[\"79581.10\",\"0.076\"],[\"79581.30\",\"0.007\"],[\"79581.70\",\"0.000\"],[\"79582.20\",\"0.077\"],[\"79582.50\",\"0.000\"],[\"79582.60\",\"0.051\"],[\"79582.70\",\"0.000\"],[\"79582.80\",\"0.003\"],[\"79582.90\",\"0.050\"],[\"79583.00\",\"0.001\"],[\"79583.40\",\"0.322\"],[\"79584.30\",\"0.000\"],[\"79584.50\",\"0.071\"],[\"79585.00\",\"0.002\"],[\"79585.20\",\"0.541\"],[\"79585.30\",\"0.000\"],[\"79585.60\",\"0.011\"],[\"79585.90\",\"0.002\"],[\"79586.50\",\"0.005\"],[\"79586.60\",\"0.001\"],[\"79587.20\",\"0.004\"],[\"79587.30\",\"0.759\"],[\"79587.40\",\"0.005\"],[\"79587.70\",\"0.000\"],[\"79587.80\",\"0.003\"],[\"79588.40\",\"0.255\"],[\"79588.50\",\"0.078\"],[\"79589.00\",\"0.002\"],[\"79589.30\",\"0.076\"],[\"79590.10\",\"0.198\"],[\"79590.20\",\"0.002\"],[\"79590.30\",\"0.000\"],[\"79590.50\",\"0.077\"],[\"79590.70\",\"0.000\"],[\"79591.00\",\"0.000\"],[\"79591.10\",\"0.001\"],[\"79592.10\",\"0.001\"],[\"79592.30\",\"0.446\"],[\"79592.40\",\"0.123\"],[\"79592.80\",\"0.002\"],[\"79593.20\",\"0.031\"],[\"79593.40\",\"0.003\"],[\"79593.50\",\"0.156\"],[\"79593.60\",\"0.082\"],[\"79594.00\",\"0.034\"],[\"79594.30\",\"0.028\"],[\"79594.80\",\"0.254\"],[\"79594.90\",\"0.000\"],[\"79595.00\",\"0.002\"],[\"79595.10\",\"0.028\"],[\"79595.20\",\"0.002\"],[\"79595.30\",\"0.000\"],[\"79595.40\",\"0.001\"],[\"79595.60\",\"0.003\"],[\"79595.70\",\"0.002\"],[\"79596.00\",\"0.001\"],[\"79596.10\",\"0.013\"],[\"79596.20\",\"2.779\"],[\"79596.30\",\"4.801\"],[\"79596.40\",\"1.081\"],[\"79596.50\",\"0.000\"],[\"79596.60\",\"0.000\"],[\"79596.70\",\"1.000\"],[\"79596.80\",\"0.084\"],[\"79597.00\",\"0.000\"],[\"79597.10\",\"0.001\"],[\"79597.30\",\"0.278\"],[\"79597.40\",\"0.000\"],[\"79597.50\",\"0.016\"],[\"79597.60\",\"0.080\"],[\"79597.70\",\"0.026\"],[\"79597.80\",\"0.001\"],[\"79597.90\",\"0.001\"],[\"79598.00\",\"0.000\"],[\"79598.10\",\"0.000\"],[\"79598.20\",\"0.000\"],[\"79598.30\",\"0.000\"],[\"79598.40\",\"0.002\"],[\"79598.60\",\"0.000\"],[\"79598.80\",\"0.000\"],[\"79598.90\",\"0.000\"],[\"79599.00\",\"0.001\"],[\"79599.10\",\"0.000\"],[\"79599.20\",\"0.000\"],[\"79599.30\",\"0.002\"],[\"79599.40\",\"0.004\"],[\"79599.50\",\"9.048\"]],\"a\":[[\"79596.40\",\"0.000\"],[\"79596.50\",\"0.000\"],[\"79596.70\",\"0.000\"],[\"79596.80\",\"0.000\"],[\"79597.10\",\"0.000\"],[\"79597.20\",\"0.000\"],[\"79597.40\",\"0.000\"],[\"79597.50\",\"0.000\"],[\"79597.60\",\"0.000\"],[\"79597.90\",\"0.000\"],[\"79598.00\",\"0.000\"],[\"79598.20\",\"0.000\"],[\"79598.40\",\"0.000\"],[\"79598.50\",\"0.000\"],[\"79598.70\",\"0.000\"],[\"79598.90\",\"0.000\"],[\"79599.00\",\"0.000\"],[\"79599.10\",\"0.000\"],[\"79599.20\",\"0.000\"],[\"79599.30\",\"0.000\"],[\"79599.50\",\"0.000\"],[\"79599.60\",\"2.319\"],[\"79599.70\",\"0.026\"],[\"79599.80\",\"0.002\"],[\"79599.90\",\"0.003\"],[\"79600.00\",\"0.022\"],[\"79600.10\",\"0.005\"],[\"79600.30\",\"0.076\"],[\"79600.40\",\"0.000\"],[\"79600.50\",\"0.002\"],[\"79600.60\",\"0.003\"],[\"79600.70\",\"0.000\"],[\"79600.80\",\"0.001\"],[\"79600.90\",\"0.588\"],[\"79601.00\",\"0.000\"],[\"79601.10\",\"0.000\"],[\"79601.20\",\"0.002\"],[\"79601.30\",\"0.003\"],[\"79601.50\",\"0.001\"],[\"79601.60\",\"0.321\"],[\"79601.70\",\"0.064\"],[\"79602.00\",\"0.039\"],[\"79602.10\",\"0.026\"],[\"79602.30\",\"0.026\"],[\"79602.40\",\"1.676\"],[\"79602.50\",\"0.091\"],[\"79602.60\",\"0.434\"],[\"79602.70\",\"0.026\"],[\"79602.80\",\"0.026\"],[\"79602.90\",\"0.002\"],[\"79603.00\",\"0.076\"],[\"79603.10\",\"0.028\"],[\"79603.20\",\"0.030\"],[\"79603.30\",\"0.093\"],[\"79603.40\",\"0.027\"],[\"79603.50\",\"0.027\"],[\"79603.60\",\"0.026\"],[\"79603.70\",\"0.254\"],[\"79603.80\",\"0.001\"],[\"79603.90\",\"0.000\"],[\"79604.00\",\"0.029\"],[\"79604.10\",\"0.079\"],[\"79604.20\",\"0.127\"],[\"79604.30\",\"0.743\"],[\"79604.40\",\"2.093\"],[\"79604.50\",\"0.002\"],[\"79604.60\",\"0.001\"],[\"79604.70\",\"0.063\"],[\"79604.80\",\"0.009\"],[\"79604.90\",\"0.006\"],[\"79605.00\",\"0.406\"],[\"79605.10\",\"2.190\"],[\"79605.20\",\"0.262\"],[\"79605.70\",\"0.010\"],[\"79606.00\",\"0.013\"],[\"79606.30\",\"0.303\"],[\"79606.40\",\"4.639\"],[\"79606.50\",\"0.005\"],[\"79606.70\",\"0.000\"],[\"79606.80\",\"0.003\"],[\"79606.90\",\"0.019\"],[\"79607.00\",\"0.003\"],[\"79607.10\",\"2.698\"],[\"79607.20\",\"0.082\"],[\"79607.60\",\"1.120\"],[\"79607.70\",\"1.008\"],[\"79608.30\",\"0.021\"],[\"79608.40\",\"0.505\"],[\"79608.60\",\"0.717\"],[\"79608.80\",\"0.890\"],[\"79609.20\",\"0.002\"],[\"79609.30\",\"0.375\"],[\"79609.40\",\"0.549\"],[\"79609.70\",\"0.004\"],[\"79609.80\",\"0.004\"],[\"79609.90\",\"0.027\"],[\"79610.60\",\"0.004\"],[\"79610.80\",\"0.133\"],[\"79610.90\",\"0.788\"],[\"79611.10\",\"1.762\"],[\"79611.20\",\"0.006\"],[\"79611.40\",\"0.637\"],[\"79611.50\",\"0.422\"],[\"79611.60\",\"0.000\"],[\"79611.70\",\"0.007\"],[\"79612.00\",\"0.004\"],[\"79612.70\",\"0.271\"],[\"79613.00\",\"0.251\"],[\"79613.10\",\"0.006\"],[\"79614.00\",\"0.158\"],[\"79614.60\",\"0.003\"],[\"79614.90\",\"0.170\"],[\"79615.00\",\"0.496\"],[\"79615.50\",\"0.000\"],[\"79615.60\",\"1.016\"],[\"79617.10\",\"0.010\"],[\"79618.00\",\"0.001\"],[\"79618.10\",\"0.001\"],[\"79618.20\",\"0.375\"],[\"79618.80\",\"0.008\"],[\"79618.90\",\"0.000\"],[\"79619.00\",\"0.197\"],[\"79619.20\",\"0.002\"],[\"79619.40\",\"1.930\"],[\"79619.60\",\"0.002\"],[\"79619.70\",\"0.253\"],[\"79619.80\",\"0.456\"],[\"79619.90\",\"0.035\"],[\"79620.20\",\"0.010\"],[\"79620.30\",\"0.146\"],[\"79620.40\",\"0.629\"],[\"79620.50\",\"2.031\"],[\"79620.60\",\"7.009\"],[\"79620.70\",\"0.006\"],[\"79621.00\",\"0.000\"],[\"79621.10\",\"0.001\"],[\"79621.20\",\"0.068\"],[\"79621.40\",\"0.110\"],[\"79621.60\",\"0.000\"],[\"79621.70\",\"0.002\"],[\"79622.00\",\"0.022\"],[\"79622.40\",\"0.004\"],[\"79622.80\",\"0.060\"],[\"79622.90\",\"0.000\"],[\"79623.00\",\"0.014\"],[\"79623.20\",\"0.548\"],[\"79623.50\",\"0.061\"],[\"79623.70\",\"0.083\"],[\"79624.00\",\"0.061\"],[\"79624.20\",\"0.073\"],[\"79624.50\",\"0.638\"],[\"79625.20\",\"0.000\"],[\"79625.30\",\"0.002\"],[\"79625.50\",\"0.000\"],[\"79625.70\",\"0.000\"],[\"79626.20\",\"0.017\"],[\"79626.30\",\"0.008\"],[\"79626.50\",\"0.000\"],[\"79626.90\",\"0.010\"],[\"79627.10\",\"0.000\"],[\"79627.50\",\"0.040\"],[\"79627.70\",\"0.630\"],[\"79627.90\",\"0.000\"],[\"79628.00\",\"1.360\"],[\"79628.20\",\"0.210\"],[\"79628.70\",\"0.890\"],[\"79628.80\",\"0.318\"],[\"79628.90\",\"0.020\"],[\"79629.30\",\"0.000\"],[\"79629.70\",\"0.019\"],[\"79630.00\",\"0.308\"],[\"79630.50\",\"0.137\"],[\"79630.60\",\"0.039\"],[\"79630.80\",\"0.047\"],[\"79631.00\",\"0.514\"],[\"79631.30\",\"0.038\"],[\"79631.40\",\"0.129\"],[\"79631.50\",\"0.812\"],[\"79631.80\",\"0.001\"],[\"79632.00\",\"1.303\"],[\"79632.30\",\"0.071\"],[\"79632.40\",\"0.397\"],[\"79632.60\",\"0.245\"],[\"79633.00\",\"0.291\"],[\"79633.20\",\"10.831\"],[\"79633.50\",\"0.002\"],[\"79634.00\",\"0.040\"],[\"79634.20\",\"0.004\"],[\"79634.50\",\"0.002\"],[\"79634.60\",\"0.003\"],[\"79635.60\",\"0.001\"],[\"79635.80\",\"0.001\"],[\"79636.00\",\"0.011\"],[\"79636.10\",\"0.558\"],[\"79636.80\",\"0.318\"],[\"79637.30\",\"0.060\"],[\"79637.60\",\"0.010\"],[\"79637.70\",\"0.046\"],[\"79638.20\",\"0.001\"],[\"79638.30\",\"0.014\"],[\"79638.80\",\"0.149\"],[\"79639.20\",\"0.081\"],[\"79639.40\",\"0.068\"],[\"79640.00\",\"0.399\"],[\"79641.10\",\"0.067\"],[\"79641.30\",\"0.002\"],[\"79641.90\",\"0.039\"],[\"79642.00\",\"0.000\"],[\"79642.10\",\"0.832\"],[\"79642.60\",\"0.000\"],[\"79642.70\",\"0.000\"],[\"79643.70\",\"0.016\"],[\"79644.00\",\"0.634\"],[\"79644.10\",\"0.003\"],[\"79644.70\",\"0.038\"],[\"79644.80\",\"0.316\"],[\"79645.10\",\"0.230\"],[\"79645.30\",\"0.000\"],[\"79646.60\",\"0.005\"],[\"79647.20\",\"0.004\"],[\"79647.40\",\"0.033\"],[\"79647.50\",\"0.052\"],[\"79647.90\",\"0.000\"],[\"79648.20\",\"1.206\"],[\"79649.60\",\"0.068\"],[\"79650.00\",\"0.215\"],[\"79651.90\",\"0.000\"],[\"79652.20\",\"0.003\"],[\"79653.20\",\"1.571\"],[\"79654.20\",\"0.039\"],[\"79655.30\",\"0.040\"],[\"79656.90\",\"0.002\"],[\"79659.10\",\"0.000\"],[\"79659.40\",\"0.000\"],[\"79660.80\",\"0.316\"],[\"79661.10\",\"6.304\"],[\"79661.20\",\"0.150\"],[\"79661.50\",\"0.210\"],[\"79662.20\",\"0.001\"],[\"79662.50\",\"0.003\"],[\"79663.50\",\"0.032\"],[\"79663.70\",\"0.000\"],[\"79664.60\",\"0.003\"],[\"79664.80\",\"0.000\"],[\"79665.10\",\"0.002\"],[\"79665.80\",\"1.011\"],[\"79665.90\",\"5.651\"],[\"79666.10\",\"0.002\"],[\"79666.70\",\"0.010\"],[\"79666.90\",\"0.038\"],[\"79668.20\",\"4.825\"],[\"79669.10\",\"0.043\"],[\"79670.30\",\"0.014\"],[\"79672.20\",\"0.001\"],[\"79673.40\",\"0.000\"],[\"79673.90\",\"0.039\"],[\"79674.50\",\"2.899\"],[\"79676.10\",\"0.007\"],[\"79676.20\",\"0.001\"],[\"79676.90\",\"26.243\"],[\"79677.10\",\"0.450\"],[\"79678.00\",\"0.004\"],[\"79678.70\",\"0.038\"],[\"79679.00\",\"0.017\"],[\"79679.10\",\"3.327\"],[\"79679.40\",\"0.582\"],[\"79681.40\",\"0.200\"],[\"79682.40\",\"0.120\"],[\"79682.50\",\"0.023\"],[\"79688.00\",\"6.736\"],[\"79693.00\",\"0.600\"],[\"79695.10\",\"3.465\"],[\"79695.20\",\"0.597\"],[\"79695.30\",\"0.000\"],[\"79695.50\",\"0.059\"],[\"79708.90\",\"0.423\"],[\"79711.30\",\"0.500\"],[\"79717.60\",\"0.371\"],[\"79725.80\",\"0.002\"],[\"79728.10\",\"0.681\"],[\"79732.80\",\"0.000\"],[\"79764.10\",\"0.000\"],[\"79770.10\",\"0.002\"],[\"79776.90\",\"0.019\"],[\"79785.20\",\"1.191\"],[\"79785.30\",\"0.010\"],[\"79785.40\",\"0.427\"],[\"79785.50\",\"0.002\"],[\"79800.30\",\"0.165\"],[\"79807.40\",\"0.434\"],[\"79807.50\",\"0.001\"],[\"79820.80\",\"0.002\"],[\"79825.30\",\"0.000\"],[\"79828.70\",\"0.976\"],[\"79829.10\",\"1.193\"],[\"79829.20\",\"0.025\"],[\"79829.40\",\"0.426\"],[\"79829.50\",\"0.017\"],[\"79836.60\",\"0.001\"],[\"79854.50\",\"0.029\"],[\"79870.50\",\"0.020\"],[\"79944.00\",\"0.730\"],[\"80021.90\",\"0.001\"],[\"80025.90\",\"0.002\"],[\"80029.90\",\"0.368\"],[\"80392.40\",\"0.000\"],[\"80395.60\",\"1.430\"],[\"80512.30\",\"0.000\"],[\"80515.50\",\"17.712\"],[\"80591.80\",\"0.614\"],[\"80595.10\",\"6.140\"],[\"81185.70\",\"0.003\"],[\"81191.50\",\"0.003\"],[\"84880.40\",\"0.000\"],[\"85079.60\",\"0.000\"],[\"85278.90\",\"0.000\"],[\"85478.10\",\"0.014\"]],\"st\":1}}"}
{"receive_ns":1788563744776376000,"stream":"btcusdt@depth@100ms","event_type":"depthUpdate","event_time_ms":1788563742431,"raw_json":"{\"stream\":\"btcusdt@depth@100ms\",\"data\":{\"e\":\"depthUpdate\",\"E\":1788563742431,\"T\":1788563742430,\"s\":\"BTCUSDT\",\"ps\":\"BTCUSDT\",\"U\":11478251618420,\"u\":11478251624618,\"pu\":11478251618381,\"b\":[[\"1000.00\",\"24.754\"],[\"29299.50\",\"0.063\"],[\"29396.30\",\"1.652\"],[\"29399.50\",\"0.168\"],[\"29496.30\",\"0.140\"],[\"71639.50\",\"0.002\"],[\"72327.80\",\"0.002\"],[\"76412.40\",\"0.000\"],[\"78007.60\",\"0.005\"],[\"78803.50\",\"0.004\"],[\"79219.40\",\"0.148\"],[\"79222.20\",\"0.199\"],[\"79483.90\",\"0.000\"],[\"79488.80\",\"2.304\"],[\"79510.00\",\"1.201\"],[\"79510.30\",\"0.091\"],[\"79510.70\",\"0.000\"],[\"79519.90\",\"0.326\"],[\"79523.10\",\"0.070\"],[\"79524.20\",\"0.001\"],[\"79527.40\",\"0.041\"],[\"79530.70\",\"0.003\"],[\"79532.60\",\"2.350\"],[\"79535.90\",\"1.471\"],[\"79536.60\",\"0.035\"],[\"79536.70\",\"0.080\"],[\"79539.40\",\"18.407\"],[\"79541.40\",\"2.316\"],[\"79542.00\",\"0.002\"],[\"79542.10\",\"0.001\"],[\"79542.80\",\"0.089\"],[\"79544.50\",\"0.002\"],[\"79544.60\",\"0.000\"],[\"79545.20\",\"0.000\"],[\"79545.90\",\"0.035\"],[\"79549.00\",\"0.827\"],[\"79551.50\",\"0.003\"],[\"79556.20\",\"0.006\"],[\"79557.80\",\"0.268\"],[\"79560.40\",\"0.070\"],[\"79564.40\",\"0.000\"],[\"79564.80\",\"0.717\"],[\"79567.50\",\"0.050\"],[\"79568.00\",\"0.026\"],[\"79569.30\",\"1.187\"],[\"79570.80\",\"0.238\"],[\"79571.60\",\"0.013\"],[\"79572.80\",\"0.001\"],[\"79576.10\",\"0.002\"],[\"79577.90\",\"0.000\"],[\"79579.90\",\"0.119\"],[\"79581.70\",\"0.002\"],[\"79582.60\",\"0.001\"],[\"79583.50\",\"0.126\"],[\"79584.70\",\"0.083\"],[\"79585.60\",\"0.007\"],[\"79587.20\",\"0.003\"],[\"79587.30\",\"0.618\"],[\"79588.40\",\"0.257\"],[\"79588.90\",\"0.006\"],[\"79591.80\",\"0.001\"],[\"79592.00\",\"0.007\"],[\"79592.90\",\"0.000\"],[\"79593.60\",\"0.080\"],[\"79595.00\",\"0.003\"],[\"79595.70\",\"0.003\"],[\"79595.90\",\"0.059\"],[\"79596.10\",\"0.011\"],[\"79596.20\",\"1.154\"],[\"79596.30\",\"2.920\"],[\"79596.40\",\"0.003\"],[\"79596.80\",\"0.000\"],[\"79597.50\",\"0.004\"],[\"79597.70\",\"0.000\"],[\"79597.90\",\"0.027\"],[\"79598.10\",\"0.026\"],[\"79598.40\",\"0.082\"],[\"79599.10\",\"0.000\"],[\"79599.20\",\"1.601\"],[\"79599.30\",\"0.001\"],[\"79599.40\",\"0.007\"],[\"79599.50\",\"11.800\"]],\"a\":[[\"79599.60\",\"2.302\"],[\"79599.70\",\"0.027\"],[\"79599.80\",\"0.102\"],[\"79600.10\",\"0.003\"],[\"79601.30\",\"0.001\"],[\"79602.00\",\"0.039\"],[\"79602.50\",\"0.085\"],[\"79603.20\",\"0.029\"],[\"79603.80\",\"0.003\"],[\"79604.10\",\"0.083\"],[\"79604.30\",\"0.741\"],[\"79604.50\",\"0.004\"],[\"79604.80\",\"0.001\"],[\"79605.40\",\"0.097\"],[\"79606.10\",\"0.227\"],[\"79606.30\",\"0.426\"],[\"79606.60\",\"0.641\"],[\"79606.70\",\"0.410\"],[\"79607.00\",\"0.001\"],[\"79607.20\",\"0.334\"],[\"79607.60\",\"1.221\"],[\"79607.70\",\"1.000\"],[\"79607.80\",\"1.006\"],[\"79607.90\",\"1.000\"],[\"79608.10\",\"0.212\"],[\"79608.30\",\"0.017\"],[\"79609.20\",\"0.006\"],[\"79609.90\",\"0.000\"],[\"79610.50\",\"0.003\"],[\"79610.90\",\"0.666\"],[\"79611.00\",\"1.717\"],[\"79611.50\",\"0.013\"],[\"79612.00\",\"0.007\"],[\"79613.40\",\"0.001\"],[\"79613.80\",\"0.011\"],[\"79615.00\",\"0.494\"],[\"79615.90\",\"0.002\"],[\"79619.10\",\"0.546\"],[\"79620.20\",\"0.009\"],[\"79623.50\",\"0.062\"],[\"79624.40\",\"0.000\"],[\"79625.00\",\"0.395\"],[\"79626.30\",\"0.006\"],[\"79627.00\",\"0.010\"],[\"79627.20\",\"0.090\"],[\"79628.20\",\"0.213\"],[\"79628.30\",\"0.198\"],[\"79630.80\",\"0.001\"],[\"79632.70\",\"2.755\"],[\"79633.20\",\"10.832\"],[\"79633.30\",\"1.385\"],[\"79634.60\",\"0.002\"],[\"79634.70\",\"0.000\"],[\"79635.90\",\"0.876\"],[\"79639.90\",\"0.122\"],[\"79640.10\",\"0.409\"],[\"79647.00\",\"0.003\"],[\"79647.50\",\"0.002\"],[\"79648.90\",\"0.340\"],[\"79649.10\",\"0.002\"],[\"79649.60\",\"0.069\"],[\"79650.60\",\"0.050\"],[\"79651.20\",\"0.002\"],[\"79658.70\",\"0.420\"],[\"79659.90\",\"0.000\"],[\"79661.80\",\"0.253\"],[\"79663.10\",\"1.840\"],[\"79663.20\",\"0.007\"],[\"79666.20\",\"0.225\"],[\"79668.10\",\"0.002\"],[\"79669.80\",\"0.224\"],[\"79669.90\",\"0.410\"],[\"79670.10\",\"0.211\"],[\"79670.70\",\"0.279\"],[\"79671.50\",\"0.004\"],[\"79671.60\",\"26.048\"],[\"79676.00\",\"0.002\"],[\"79676.90\",\"0.204\"],[\"79679.10\",\"3.340\"],[\"79683.20\",\"0.745\"],[\"79695.00\",\"0.186\"],[\"79696.80\",\"0.001\"],[\"79698.20\",\"0.003\"],[\"79711.00\",\"0.182\"],[\"79825.70\",\"0.001\"],[\"79829.60\",\"0.001\"],[\"79854.50\",\"0.016\"],[\"79870.50\",\"0.008\"],[\"79947.80\",\"0.419\"],[\"79948.60\",\"0.000\"],[\"79949.80\",\"0.712\"],[\"79987.60\",\"0.203\"],[\"79994.40\",\"0.002\"],[\"79995.60\",\"0.829\"],[\"79997.60\",\"0.766\"],[\"80392.90\",\"0.130\"],[\"80395.60\",\"1.430\"],[\"80396.10\",\"0.246\"],[\"80591.80\",\"0.000\"],[\"80595.10\",\"6.754\"],[\"80681.90\",\"12.527\"]],\"st\":1}}"}
{"receive_ns":1788563745128481000,"stream":"btcusdt@depth@100ms","event_type":"depthUpdate","event_time_ms":1788563742533,"raw_json":"{\"stream\":\"btcusdt@depth@100ms\",\"data\":{\"e\":\"depthUpdate\",\"E\":1788563742533,\"T\":1788563742532,\"s\":\"BTCUSDT\",\"ps\":\"BTCUSDT\",\"U\":11478251624635,\"u\":11478251630590,\"pu\":11478251624618,\"b\":[[\"29299.50\",\"0.126\"],[\"29396.30\",\"1.589\"],[\"29399.50\",\"0.280\"],[\"29496.20\",\"0.070\"],[\"29496.30\",\"0.035\"],[\"63677.00\",\"0.000\"],[\"71639.50\",\"0.002\"],[\"77976.40\",\"3.742\"],[\"78064.90\",\"0.029\"],[\"78153.30\",\"0.040\"],[\"78241.70\",\"0.028\"],[\"78330.10\",\"0.028\"],[\"78418.50\",\"0.028\"],[\"78506.90\",\"0.028\"],[\"78595.30\",\"0.029\"],[\"78683.70\",\"0.030\"],[\"78772.10\",\"3.471\"],[\"78796.90\",\"0.000\"],[\"78799.40\",\"0.262\"],[\"78803.50\",\"0.006\"],[\"78909.30\",\"0.002\"],[\"79366.20\",\"0.001\"],[\"79467.60\",\"0.011\"],[\"79467.90\",\"2.432\"],[\"79488.80\",\"1.299\"],[\"79494.00\",\"1.006\"],[\"79494.40\",\"0.033\"],[\"79501.40\",\"0.046\"],[\"79508.00\",\"0.000\"],[\"79509.60\",\"0.809\"],[\"79526.10\",\"0.010\"],[\"79536.40\",\"0.001\"],[\"79536.50\",\"0.003\"],[\"79537.40\",\"0.785\"],[\"79537.50\",\"0.000\"],[\"79539.30\",\"0.001\"],[\"79542.00\",\"0.001\"],[\"79546.60\",\"0.002\"],[\"79547.30\",\"0.001\"],[\"79555.20\",\"0.006\"],[\"79557.00\",\"0.253\"],[\"79563.10\",\"0.548\"],[\"79567.80\",\"0.116\"],[\"79568.20\",\"2.708\"],[\"79582.70\",\"0.062\"],[\"79583.40\",\"0.260\"],[\"79586.50\",\"0.003\"],[\"79590.50\",\"0.001\"],[\"79592.30\",\"0.013\"],[\"79593.10\",\"0.001\"],[\"79593.60\",\"0.080\"],[\"79595.10\",\"0.027\"],[\"79596.20\",\"1.148\"],[\"79596.30\",\"1.652\"],[\"79596.60\",\"0.001\"],[\"79598.50\",\"0.026\"],[\"79599.10\",\"0.000\"],[\"79599.20\",\"0.000\"],[\"79599.40\",\"0.008\"],[\"79599.50\",\"13.070\"]],\"a\":[[\"79599.60\",\"1.754\"],[\"79605.20\",\"0.260\"],[\"79606.40\",\"4.641\"],[\"79606.50\",\"0.735\"],[\"79607.30\",\"0.210\"],[\"79607.50\",\"0.240\"],[\"79607.60\",\"1.120\"],[\"79608.50\",\"0.121\"],[\"79609.20\",\"0.002\"],[\"79618.60\",\"0.019\"],[\"79620.50\",\"2.037\"],[\"79628.00\",\"1.354\"],[\"79632.90\",\"0.680\"],[\"79649.60\",\"0.068\"],[\"79655.80\",\"0.391\"],[\"79659.00\",\"0.321\"],[\"79661.80\",\"0.001\"],[\"79663.70\",\"0.410\"],[\"79664.50\",\"0.210\"],[\"79665.90\",\"5.652\"],[\"79666.10\",\"0.001\"],[\"79669.80\",\"0.000\"],[\"79670.10\",\"0.001\"],[\"79699.30\",\"0.001\"],[\"79699.40\",\"2.527\"],[\"79699.60\",\"0.125\"],[\"79701.80\",\"0.100\"],[\"79829.60\",\"0.000\"],[\"79994.40\",\"0.001\"],[\"80339.70\",\"1.217\"],[\"80363.50\",\"12.386\"],[\"80371.60\",\"0.740\"],[\"80395.60\",\"1.430\"],[\"80451.90\",\"0.038\"],[\"80530.30\",\"0.016\"],[\"80540.30\",\"0.028\"],[\"80628.70\",\"0.028\"],[\"80681.90\",\"11.909\"],[\"80717.10\",\"0.028\"],[\"80805.50\",\"0.028\"],[\"80893.90\",\"0.029\"],[\"80982.30\",\"0.028\"],[\"81070.70\",\"0.028\"],[\"81159.20\",\"0.678\"]],\"st\":1}}"}
{"receive_ns":1788563745638711000,"stream":"btcusdt@depth@100ms","event_type":"depthUpdate","event_time_ms":1788563742635,"raw_json":"{\"stream\":\"btcusdt@depth@100ms\",\"data\":{\"e\":\"depthUpdate\",\"E\":1788563742635,\"T\":1788563742634,\"s\":\"BTCUSDT\",\"ps\":\"BTCUSDT\",\"U\":11478251630595,\"u\":11478251637721,\"pu\":11478251630590,\"b\":[[\"1000.00\",\"24.754\"],[\"29299.50\",\"0.203\"],[\"29396.30\",\"1.533\"],[\"29399.50\",\"0.364\"],[\"29496.20\",\"0.000\"],[\"29496.30\",\"0.000\"],[\"63680.00\",\"0.072\"],[\"71639.50\",\"0.002\"],[\"71674.00\",\"0.000\"],[\"76415.50\",\"0.002\"],[\"78452.80\",\"0.573\"],[\"78461.30\",\"0.255\"],[\"78620.50\",\"10.158\"],[\"78803.50\",\"0.002\"],[\"79198.20\",\"0.000\"],[\"79198.30\",\"0.077\"],[\"79201.50\",\"0.002\"],[\"79219.40\",\"0.148\"],[\"79461.30\",\"0.000\"],[\"79462.60\",\"0.016\"],[\"79494.00\",\"1.238\"],[\"79506.00\",\"1.828\"],[\"79510.00\",\"0.342\"],[\"79539.30\",\"0.000\"],[\"79539.40\",\"0.070\"],[\"79542.00\",\"0.002\"],[\"79542.10\",\"18.168\"],[\"79555.30\",\"0.004\"],[\"79556.50\",\"0.000\"],[\"79558.10\",\"2.314\"],[\"79564.20\",\"10.001\"],[\"79568.20\",\"0.708\"],[\"79571.50\",\"0.001\"],[\"79572.60\",\"0.003\"],[\"79574.60\",\"1.288\"],[\"79574.90\",\"0.440\"],[\"79575.50\",\"0.041\"],[\"79575.70\",\"0.002\"],[\"79575.80\",\"0.002\"],[\"79584.50\",\"0.077\"],[\"79585.60\",\"0.001\"],[\"79586.50\",\"0.007\"],[\"79587.40\",\"0.001\"],[\"79589.30\",\"0.000\"],[\"79593.50\",\"0.002\"],[\"79594.90\",\"0.161\"],[\"79596.00\",\"0.027\"],[\"79596.10\",\"0.006\"],[\"79596.30\",\"1.677\"],[\"79596.70\",\"1.026\"],[\"79597.10\",\"0.001\"],[\"79597.30\",\"0.252\"],[\"79597.60\",\"0.000\"],[\"79597.90\",\"0.001\"],[\"79598.10\",\"0.000\"],[\"79598.50\",\"0.000\"],[\"79598.70\",\"0.000\"],[\"79599.20\",\"0.080\"],[\"79599.30\",\"1.608\"],[\"79599.50\",\"13.071\"]],\"a\":[[\"79599.60\",\"2.247\"],[\"79601.20\",\"0.001\"],[\"79602.00\",\"0.039\"],[\"79602.20\",\"0.003\"],[\"79602.30\",\"0.026\"],[\"79603.70\",\"0.256\"],[\"79604.10\",\"0.417\"],[\"79604.20\",\"0.127\"],[\"79604.40\",\"0.883\"],[\"79604.50\",\"0.002\"],[\"79606.30\",\"0.426\"],[\"79606.80\",\"0.363\"],[\"79607.00\",\"0.225\"],[\"79607.20\",\"0.435\"],[\"79607.50\",\"0.139\"],[\"79607.60\",\"2.330\"],[\"79608.30\",\"0.330\"],[\"79609.30\",\"0.062\"],[\"79610.80\",\"0.133\"],[\"79612.30\",\"0.440\"],[\"79612.50\",\"0.003\"],[\"79613.80\",\"0.009\"],[\"79614.90\",\"0.170\"],[\"79615.00\",\"0.055\"],[\"79615.40\",\"1.293\"],[\"79615.70\",\"0.550\"],[\"79620.30\",\"0.146\"],[\"79627.20\",\"0.010\"],[\"79627.60\",\"0.092\"],[\"79631.40\",\"0.003\"],[\"79631.80\",\"0.127\"],[\"79637.70\",\"0.048\"],[\"79658.70\",\"0.000\"],[\"79660.20\",\"0.437\"],[\"79669.90\",\"0.000\"],[\"79670.50\",\"0.435\"],[\"79671.40\",\"0.083\"],[\"79681.30\",\"0.001\"],[\"79690.30\",\"0.015\"],[\"79701.00\",\"0.000\"],[\"79819.40\",\"0.000\"],[\"79820.70\",\"0.003\"],[\"79947.80\",\"0.921\"],[\"79949.80\",\"0.210\"],[\"79987.60\",\"0.203\"],[\"79995.60\",\"0.867\"],[\"79997.60\",\"0.528\"],[\"80395.60\",\"1.430\"],[\"81191.50\",\"0.006\"],[\"87559.60\",\"0.002\"]],\"st\":1}}"}
{"receive_ns":1788563745860273000,"stream":"btcusdt@depth@100ms","event_type":"depthUpdate","event_time_ms":1788563742737,"raw_json":"{\"stream\":\"btcusdt@depth@100ms\",\"data\":{\"e\":\"depthUpdate\",\"E\":1788563742737,\"T\":1788563742734,\"s\":\"BTCUSDT\",\"ps\":\"BTCUSDT\",\"U\":11478251637805,\"u\":11478251643155,\"pu\":11478251637721,\"b\":[[\"1000.00\",\"24.754\"],[\"29299.50\",\"0.378\"],[\"29396.30\",\"1.470\"],[\"29399.50\",\"0.252\"],[\"71639.50\",\"0.002\"],[\"76415.50\",\"0.000\"],[\"78007.60\",\"0.008\"],[\"78803.50\",\"0.000\"],[\"79471.00\",\"10.198\"],[\"79494.00\",\"0.233\"],[\"79511.40\",\"6.157\"],[\"79539.40\",\"18.237\"],[\"79539.80\",\"0.034\"],[\"79539.90\",\"3.569\"],[\"79542.10\",\"0.001\"],[\"79544.40\",\"0.000\"],[\"79560.20\",\"0.020\"],[\"79560.50\",\"0.559\"],[\"79564.10\",\"0.004\"],[\"79571.50\",\"0.001\"],[\"79571.60\",\"0.339\"],[\"79574.20\",\"0.376\"],[\"79574.60\",\"1.727\"],[\"79574.90\",\"0.001\"],[\"79576.20\",\"0.001\"],[\"79582.90\",\"0.150\"],[\"79592.10\",\"0.002\"],[\"79593.20\",\"0.005\"],[\"79593.70\",\"0.021\"],[\"79594.20\",\"0.000\"],[\"79594.40\",\"0.000\"],[\"79596.20\",\"1.146\"],[\"79596.30\",\"0.058\"],[\"79596.40\",\"0.001\"],[\"79596.90\",\"0.026\"],[\"79597.50\",\"0.030\"],[\"79597.60\",\"0.106\"],[\"79597.80\",\"0.027\"],[\"79598.60\",\"0.026\"],[\"79599.20\",\"0.001\"],[\"79599.50\",\"14.691\"]],\"a\":[[\"79599.60\",\"1.697\"],[\"79603.70\",\"0.254\"],[\"79604.10\",\"0.083\"],[\"79604.20\",\"0.461\"],[\"79604.90\",\"0.132\"],[\"79606.20\",\"0.128\"],[\"79606.30\",\"0.942\"],[\"79608.30\",\"0.017\"],[\"79608.50\",\"0.121\"],[\"79609.30\",\"0.375\"],[\"79610.80\",\"0.133\"],[\"79612.30\",\"0.440\"],[\"79614.10\",\"0.008\"],[\"79615.00\",\"0.181\"],[\"79615.50\",\"0.372\"],[\"79618.20\",\"0.003\"],[\"79620.30\",\"0.272\"],[\"79631.40\",\"0.129\"],[\"79648.30\",\"0.428\"],[\"79659.00\",\"0.001\"],[\"79660.20\",\"0.077\"],[\"79682.40\",\"0.059\"],[\"79683.20\",\"0.649\"],[\"79699.30\",\"0.001\"],[\"79699.50\",\"0.021\"],[\"79699.60\",\"0.000\"],[\"79995.60\",\"1.067\"],[\"80395.60\",\"1.430\"],[\"81185.70\",\"0.000\"],[\"87559.60\",\"0.000\"]],\"st\":1}}"}
{"receive_ns":1788563746158425000,"stream":"btcusdt@depth@100ms","event_type":"depthUpdate","event_time_ms":1788563742839,"raw_json":"{\"stream\":\"btcusdt@depth@100ms\",\"data\":{\"e\":\"depthUpdate\",\"E\":1788563742839,\"T\":1788563742837,\"s\":\"BTCUSDT\",\"ps\":\"BTCUSDT\",\"U\":11478251643323,\"u\":11478251648314,\"pu\":11478251643155,\"b\":[[\"29299.50\",\"0.560\"],[\"29396.30\",\"1.414\"],[\"29399.50\",\"0.126\"],[\"71639.50\",\"0.002\"],[\"76415.50\",\"0.002\"],[\"78342.00\",\"0.892\"],[\"78421.60\",\"1.974\"],[\"78445.30\",\"0.111\"],[\"78660.30\",\"0.762\"],[\"78803.50\",\"0.000\"],[\"79201.50\",\"0.003\"],[\"79219.40\",\"0.007\"],[\"79494.00\",\"0.001\"],[\"79506.00\",\"0.020\"],[\"79539.30\",\"0.001\"],[\"79539.40\",\"0.070\"],[\"79541.80\",\"0.008\"],[\"79542.00\",\"0.001\"],[\"79542.10\",\"18.168\"],[\"79571.50\",\"0.440\"],[\"79571.60\",\"0.088\"],[\"79574.60\",\"1.288\"],[\"79575.90\",\"0.077\"],[\"79581.20\",\"0.000\"],[\"79582.00\",\"0.001\"],[\"79587.30\",\"0.542\"],[\"79587.60\",\"0.002\"],[\"79594.90\",\"0.163\"],[\"79595.80\",\"0.026\"],[\"79595.90\",\"0.085\"],[\"79596.20\",\"1.141\"],[\"79596.30\",\"0.057\"],[\"79597.30\",\"0.278\"],[\"79597.50\",\"0.004\"],[\"79597.60\",\"0.002\"],[\"79597.80\",\"0.001\"],[\"79598.10\",\"0.126\"],[\"79598.60\",\"0.000\"],[\"79598.80\",\"0.002\"],[\"79599.20\",\"0.081\"],[\"79599.50\",\"14.694\"]],\"a\":[[\"79599.60\",\"2.908\"],[\"79601.50\",\"0.001\"],[\"79602.00\",\"0.039\"],[\"79602.30\",\"0.026\"],[\"79603.50\",\"0.031\"],[\"79603.60\",\"0.026\"],[\"79604.10\",\"0.079\"],[\"79604.20\",\"0.127\"],[\"79604.30\",\"0.741\"],[\"79604.50\",\"0.004\"],[\"79604.90\",\"0.006\"],[\"79606.20\",\"0.002\"],[\"79606.30\",\"0.816\"],[\"79607.00\",\"0.326\"],[\"79607.10\",\"2.698\"],[\"79607.20\",\"0.334\"],[\"79608.30\",\"0.330\"],[\"79609.30\",\"0.062\"],[\"79615.00\",\"0.055\"],[\"79620.30\",\"0.146\"],[\"79631.40\",\"0.003\"],[\"79666.20\",\"0.001\"],[\"79666.50\",\"0.007\"],[\"79670.50\",\"0.211\"],[\"79684.00\",\"0.000\"],[\"79699.20\",\"0.125\"],[\"79699.70\",\"0.002\"],[\"79947.80\",\"0.000\"],[\"79987.60\",\"0.003\"],[\"79994.40\",\"0.000\"],[\"79995.60\",\"0.213\"],[\"79997.60\",\"0.002\"],[\"80395.60\",\"1.430\"],[\"80562.50\",\"28.731\"]],\"st\":1}}"}
{"receive_ns":1788563746302627000,"stream":"btcusdt@depth@100ms","event_type":"depthUpdate","event_time_ms":1788563742941,"raw_json":"{\"stream\":\"btcusdt@depth@100ms\",\"data\":{\"e\":\"depthUpdate\",\"E\":1788563742941,\"T\":1788563742938,\"s\":\"BTCUSDT\",\"ps\":\"BTCUSDT\",\"U\":11478251648384,\"u\":11478251652706,\"pu\":11478251648314,\"b\":[[\"1000.00\",\"24.754\"],[\"29299.50\",\"0.735\"],[\"29396.30\",\"1.337\"],[\"29399.50\",\"0.028\"],[\"71639.50\",\"0.002\"],[\"72128.50\",\"0.002\"],[\"76415.50\",\"0.000\"],[\"78680.00\",\"5.957\"],[\"78683.30\",\"0.812\"],[\"78803.50\",\"0.000\"],[\"78817.80\",\"0.000\"],[\"78851.30\",\"1.365\"],[\"79198.30\",\"0.077\"],[\"79219.40\",\"0.148\"],[\"79470.20\",\"1.639\"],[\"79470.80\",\"0.000\"],[\"79494.00\",\"2.292\"],[\"79539.30\",\"0.000\"],[\"79542.00\",\"0.002\"],[\"79571.50\",\"0.001\"],[\"79571.60\",\"0.088\"],[\"79575.70\",\"0.441\"],[\"79578.80\",\"0.100\"],[\"79593.60\",\"0.080\"],[\"79595.10\",\"0.001\"],[\"79595.70\",\"0.029\"],[\"79596.20\",\"1.136\"],[\"79597.30\",\"0.278\"],[\"79597.50\",\"0.004\"],[\"79597.70\",\"0.000\"],[\"79599.50\",\"14.704\"]],\"a\":[[\"79599.60\",\"2.882\"],[\"79602.20\",\"0.002\"],[\"79602.30\",\"0.027\"],[\"79603.50\",\"0.027\"],[\"79604.10\",\"0.083\"],[\"79604.20\",\"0.127\"],[\"79608.30\",\"0.017\"],[\"79608.50\",\"0.121\"],[\"79609.30\",\"0.375\"],[\"79618.60\",\"0.013\"],[\"79623.30\",\"0.009\"],[\"79644.10\",\"0.001\"],[\"79659.60\",\"0.674\"],[\"79664.50\",\"0.000\"],[\"79699.20\",\"0.000\"],[\"79717.60\",\"0.000\"],[\"79720.90\",\"0.432\"],[\"79733.40\",\"0.000\"],[\"79947.80\",\"0.921\"],[\"79987.60\",\"0.203\"],[\"79995.60\",\"1.393\"],[\"79997.60\",\"0.202\"],[\"80395.60\",\"1.430\"],[\"81191.50\",\"0.009\"]],\"st\":1}}"}
{"receive_ns":1788563746303381000,"stream":"btcusdt@depth@100ms","event_type":"depthUpdate","event_time_ms":1788563743043,"raw_json":"{\"stream\":\"btcusdt@depth@100ms\",\"data\":{\"e\":\"depthUpdate\",\"E\":1788563743043,\"T\":1788563743042,\"s\":\"BTCUSDT\",\"ps\":\"BTCUSDT\",\"U\":11478251652856,\"u\":11478251657328,\"pu\":11478251652706,\"b\":[[\"1000.00\",\"24.754\"],[\"29299.50\",\"0.917\"],[\"29396.30\",\"1.183\"],[\"29399.50\",\"0.000\"],[\"71639.50\",\"0.002\"],[\"75616.40\",\"0.006\"],[\"79398.30\",\"0.000\"],[\"79511.90\",\"1.006\"],[\"79543.70\",\"0.003\"],[\"79544.00\",\"3.896\"],[\"79567.80\",\"0.115\"],[\"79567.90\",\"2.794\"],[\"79576.90\",\"0.004\"],[\"79585.20\",\"0.545\"],[\"79589.70\",\"0.255\"],[\"79595.10\",\"0.002\"],[\"79595.50\",\"0.433\"],[\"79596.20\",\"1.131\"],[\"79597.40\",\"0.026\"],[\"79597.60\",\"0.082\"],[\"79599.20\",\"0.001\"],[\"79599.50\",\"14.709\"]],\"a\":[[\"79602.00\",\"0.039\"],[\"79604.30\",\"0.741\"],[\"79608.50\",\"0.183\"],[\"79609.30\",\"0.313\"],[\"79652.20\",\"0.001\"],[\"79655.40\",\"2.960\"],[\"79663.70\",\"0.000\"],[\"79668.20\",\"8.491\"],[\"79695.20\",\"0.595\"],[\"79699.30\",\"0.001\"],[\"79699.50\",\"0.021\"],[\"79733.40\",\"0.000\"],[\"79993.90\",\"0.371\"],[\"80212.10\",\"3.420\"],[\"80395.60\",\"1.430\"],[\"81080.20\",\"0.617\"]],\"st\":1}}"}
{"receive_ns":1788563746406265000,"stream":"btcusdt@depth@100ms","event_type":"depthUpdate","event_time_ms":1788563743145,"raw_json":"{\"stream\":\"btcusdt@depth@100ms\",\"data\":{\"e\":\"depthUpdate\",\"E\":1788563743145,\"T\":1788563743143,\"s\":\"BTCUSDT\",\"ps\":\"BTCUSDT\",\"U\":11478251657418,\"u\":11478251664399,\"pu\":11478251657328,\"b\":[[\"29299.50\",\"1.092\"],[\"29396.30\",\"1.008\"],[\"71639.50\",\"0.002\"],[\"76415.50\",\"0.002\"],[\"78379.10\",\"0.000\"],[\"78389.60\",\"0.019\"],[\"78730.20\",\"3.747\"],[\"78803.50\",\"0.000\"],[\"78852.10\",\"0.002\"],[\"78862.60\",\"0.006\"],[\"78927.60\",\"0.011\"],[\"79219.40\",\"0.148\"],[\"79452.60\",\"0.000\"],[\"79458.50\",\"0.002\"],[\"79462.60\",\"0.013\"],[\"79462.70\",\"0.013\"],[\"79492.40\",\"0.013\"],[\"79494.00\",\"2.041\"],[\"79498.30\",\"0.003\"],[\"79532.20\",\"0.001\"],[\"79535.70\",\"0.001\"],[\"79538.10\",\"0.002\"],[\"79566.90\",\"0.452\"],[\"79567.80\",\"0.116\"],[\"79568.20\",\"0.256\"],[\"79571.50\",\"0.001\"],[\"79571.60\",\"0.013\"],[\"79574.80\",\"2.406\"],[\"79574.90\",\"0.440\"],[\"79575.70\",\"0.002\"],[\"79578.90\",\"0.202\"],[\"79584.70\",\"0.007\"],[\"79585.20\",\"0.541\"],[\"79593.60\",\"0.080\"],[\"79593.90\",\"0.002\"],[\"79595.50\",\"0.459\"],[\"79595.60\",\"0.029\"],[\"79596.20\",\"1.119\"],[\"79596.70\",\"1.000\"],[\"79596.90\",\"0.026\"],[\"79597.30\",\"0.252\"],[\"79597.40\",\"0.000\"],[\"79597.60\",\"0.002\"],[\"79599.20\",\"0.081\"],[\"79599.50\",\"14.696\"]],\"a\":[[\"79599.60\",\"2.880\"],[\"79604.20\",\"0.396\"],[\"79610.80\",\"0.131\"],[\"79617.00\",\"0.002\"],[\"79618.50\",\"0.454\"],[\"79619.80\",\"0.004\"],[\"79621.10\",\"0.003\"],[\"79628.60\",\"0.001\"],[\"79648.30\",\"0.038\"],[\"79655.00\",\"0.000\"],[\"79661.00\",\"0.002\"],[\"79682.50\",\"0.021\"],[\"79685.50\",\"0.019\"],[\"79694.90\",\"0.194\"],[\"79695.90\",\"0.024\"],[\"79697.20\",\"0.944\"],[\"79698.90\",\"0.002\"],[\"79699.60\",\"0.000\"],[\"79700.90\",\"0.002\"],[\"79705.20\",\"0.001\"],[\"79708.20\",\"0.002\"],[\"79709.90\",\"0.004\"],[\"79713.10\",\"0.009\"],[\"79734.80\",\"0.076\"],[\"79740.80\",\"0.004\"],[\"79820.70\",\"0.000\"],[\"79820.80\",\"0.005\"],[\"79947.80\",\"0.921\"],[\"79949.80\",\"0.410\"],[\"79987.60\",\"0.003\"],[\"79993.90\",\"0.188\"],[\"79995.60\",\"0.867\"],[\"79997.60\",\"0.528\"],[\"80326.00\",\"0.003\"],[\"80395.60\",\"1.430\"],[\"80799.00\",\"0.000\"]],\"st\":1}}"}
{"receive_ns":1788563746675768000,"stream":"btcusdt@depth@100ms","event_type":"depthUpdate","event_time_ms":1788563743247,"raw_json":"{\"stream\":\"btcusdt@depth@100ms\",\"data\":{\"e\":\"depthUpdate\",\"E\":1788563743247,\"T\":1788563743246,\"s\":\"BTCUSDT\",\"ps\":\"BTCUSDT\",\"U\":11478251664524,\"u\":11478251668918,\"pu\":11478251664399,\"b\":[[\"1000.00\",\"24.754\"],[\"29299.50\",\"1.274\"],[\"29396.30\",\"0.826\"],[\"63680.00\",\"0.072\"],[\"71639.50\",\"0.002\"],[\"76415.50\",\"0.000\"],[\"78007.60\",\"0.011\"],[\"78680.00\",\"5.202\"],[\"78683.30\",\"1.567\"],[\"78803.50\",\"0.000\"],[\"78925.20\",\"0.024\"],[\"79198.20\",\"0.000\"],[\"79470.20\",\"1.229\"],[\"79470.40\",\"0.410\"],[\"79494.00\",\"3.297\"],[\"79511.90\",\"0.076\"],[\"79539.30\",\"0.001\"],[\"79539.40\",\"18.237\"],[\"79542.00\",\"0.001\"],[\"79542.10\",\"0.001\"],[\"79544.00\",\"1.423\"],[\"79567.00\",\"0.006\"],[\"79568.00\",\"0.020\"],[\"79571.50\",\"0.001\"],[\"79574.90\",\"0.440\"],[\"79578.20\",\"0.002\"],[\"79580.50\",\"0.003\"],[\"79581.00\",\"0.205\"],[\"79582.20\",\"0.147\"],[\"79584.10\",\"0.035\"],[\"79585.00\",\"0.034\"],[\"79589.20\",\"0.067\"],[\"79593.20\",\"0.003\"],[\"79594.80\",\"0.002\"],[\"79594.90\",\"0.363\"],[\"79596.90\",\"0.026\"],[\"79597.20\",\"0.000\"],[\"79599.50\",\"14.696\"]],\"a\":[[\"79599.60\",\"2.881\"],[\"79600.90\",\"0.000\"],[\"79601.50\",\"0.497\"],[\"79604.20\",\"0.396\"],[\"79615.50\",\"0.000\"],[\"79616.70\",\"2.143\"],[\"79616.80\",\"0.409\"],[\"79618.80\",\"0.002\"],[\"79677.50\",\"0.001\"],[\"79685.50\",\"0.020\"],[\"79698.90\",\"0.003\"],[\"79699.70\",\"0.127\"],[\"79699.90\",\"0.003\"],[\"79700.10\",\"0.015\"],[\"79700.20\",\"0.549\"],[\"79708.20\",\"0.003\"],[\"79720.90\",\"0.416\"],[\"79995.60\",\"1.067\"],[\"80336.60\",\"0.862\"],[\"80395.60\",\"1.430\"],[\"80554.80\",\"0.372\"],[\"80753.80\",\"0.928\"],[\"80809.60\",\"0.006\"]],\"st\":1}}"}
{"receive_ns":1788563746963529000,"stream":"btcusdt@depth@100ms","event_type":"depthUpdate","event_time_ms":1788563743349,"raw_json":"{\"stream\":\"btcusdt@depth@100ms\",\"data\":{\"e\":\"depthUpdate\",\"E\":1788563743349,\"T\":1788563743348,\"s\":\"BTCUSDT\",\"ps\":\"BTCUSDT\",\"U\":11478251669001,\"u\":11478251674448,\"pu\":11478251668918,\"b\":[[\"1000.00\",\"24.754\"],[\"29299.50\",\"1.449\"],[\"29396.30\",\"0.651\"],[\"71639.50\",\"0.002\"],[\"76415.50\",\"0.002\"],[\"78800.30\",\"0.000\"],[\"78803.50\",\"0.000\"],[\"79219.40\",\"0.148\"],[\"79317.30\",\"0.001\"],[\"79319.60\",\"1.290\"],[\"79353.10\",\"18.018\"],[\"79355.90\",\"5.126\"],[\"79415.10\",\"3.142\"],[\"79420.80\",\"0.000\"],[\"79422.70\",\"0.693\"],[\"79494.00\",\"1.589\"],[\"79511.20\",\"0.038\"],[\"79511.40\",\"6.119\"],[\"79513.50\",\"0.829\"],[\"79529.40\",\"0.692\"],[\"79541.80\",\"1.214\"],[\"79571.60\",\"0.515\"],[\"79581.40\",\"0.043\"],[\"79593.60\",\"0.080\"],[\"79594.90\",\"0.361\"],[\"79596.80\",\"0.028\"],[\"79596.90\",\"0.000\"],[\"79597.60\",\"0.082\"],[\"79598.00\",\"0.002\"],[\"79598.10\",\"0.191\"],[\"79598.20\",\"0.008\"],[\"79599.20\",\"0.001\"],[\"79599.50\",\"14.445\"]],\"a\":[[\"79599.60\",\"2.882\"],[\"79602.10\",\"0.026\"],[\"79604.20\",\"0.127\"],[\"79611.00\",\"2.408\"],[\"79686.50\",\"0.039\"],[\"79686.70\",\"0.001\"],[\"79699.70\",\"0.002\"],[\"79699.80\",\"0.017\"],[\"79699.90\",\"0.003\"],[\"79744.30\",\"3.141\"],[\"79744.90\",\"0.000\"],[\"79850.00\",\"5.566\"],[\"79947.80\",\"0.921\"],[\"79949.80\",\"0.210\"],[\"79973.40\",\"2.753\"],[\"79987.60\",\"0.203\"],[\"79995.60\",\"1.067\"],[\"79997.60\",\"0.528\"],[\"80236.40\",\"0.249\"],[\"80395.60\",\"1.430\"],[\"80550.00\",\"3.752\"],[\"81188.20\",\"0.013\"]],\"st\":1}}"}
{"receive_ns":1788563747022745000,"stream":"btcusdt@depth@100ms","event_type":"depthUpdate","event_time_ms":1788563743451,"raw_json":"{\"stream\":\"btcusdt@depth@100ms\",\"data\":{\"e\":\"depthUpdate\",\"E\":1788563743451,\"T\":1788563743450,\"s\":\"BTCUSDT\",\"ps\":\"BTCUSDT\",\"U\":11478251674518,\"u\":11478251678583,\"pu\":11478251674448,\"b\":[[\"29299.50\",\"1.631\"],[\"29396.30\",\"0.469\"],[\"63680.00\",\"0.072\"],[\"71639.50\",\"0.002\"],[\"71929.30\",\"0.002\"],[\"78601.30\",\"0.177\"],[\"78763.70\",\"0.698\"],[\"78803.50\",\"0.000\"],[\"79494.00\",\"0.584\"],[\"79511.90\",\"0.001\"],[\"79571.60\",\"0.590\"],[\"79575.30\",\"0.208\"],[\"79580.10\",\"0.003\"],[\"79595.50\",\"0.433\"],[\"79596.00\",\"0.029\"],[\"79597.60\",\"0.028\"],[\"79597.70\",\"0.026\"],[\"79599.20\",\"0.081\"]],\"a\":[[\"79599.60\",\"2.883\"],[\"79623.30\",\"0.003\"],[\"79628.10\",\"0.009\"],[\"79668.80\",\"26.278\"],[\"79671.60\",\"0.009\"],[\"79699.90\",\"0.003\"],[\"79995.60\",\"1.067\"],[\"80395.60\",\"1.430\"],[\"80517.10\",\"46.750\"],[\"80562.50\",\"25.385\"]],\"st\":1}}"}
{"receive_ns":1788563747586592000,"stream":"btcusdt@depth@100ms","event_type":"depthUpdate","event_time_ms":1788563743553,"raw_json":"{\"stream\":\"btcusdt@depth@100ms\",\"data\":{\"e\":\"depthUpdate\",\"E\":1788563743553,\"T\":1788563743552,\"s\":\"BTCUSDT\",\"ps\":\"BTCUSDT\",\"U\":11478251678628,\"u\":11478251683731,\"pu\":11478251678583,\"b\":[[\"1000.00\",\"24.754\"],[\"29199.50\",\"0.021\"],[\"29299.50\",\"1.764\"],[\"29396.30\",\"0.315\"],[\"63679.60\",\"0.000\"],[\"71639.50\",\"0.002\"],[\"76415.50\",\"0.000\"],[\"78007.60\",\"0.014\"],[\"78573.20\",\"13.653\"],[\"78803.50\",\"0.002\"],[\"78850.80\",\"11.548\"],[\"79201.50\",\"0.013\"],[\"79494.00\",\"1.589\"],[\"79513.50\",\"0.000\"],[\"79529.40\",\"0.001\"],[\"79571.70\",\"0.005\"],[\"79573.70\",\"0.082\"],[\"79574.90\",\"0.440\"],[\"79582.50\",\"0.070\"],[\"79583.10\",\"0.072\"],[\"79583.40\",\"0.330\"],[\"79583.50\",\"0.050\"],[\"79591.80\",\"0.003\"],[\"79593.60\",\"0.080\"],[\"79595.60\",\"0.029\"],[\"79596.20\",\"1.116\"],[\"79597.40\",\"0.026\"],[\"79597.60\",\"0.002\"],[\"79597.70\",\"0.000\"],[\"79598.30\",\"0.000\"],[\"79598.40\",\"0.085\"],[\"79599.50\",\"14.470\"]],\"a\":[[\"79602.10\",\"0.026\"],[\"79605.50\",\"0.000\"],[\"79616.70\",\"2.137\"],[\"79617.70\",\"0.052\"],[\"79629.40\",\"0.002\"],[\"79668.20\",\"4.825\"],[\"79668.80\",\"0.000\"],[\"79671.40\",\"0.086\"],[\"79671.50\",\"26.454\"],[\"79672.30\",\"0.000\"],[\"79672.90\",\"0.007\"],[\"79674.20\",\"0.001\"],[\"79699.90\",\"0.003\"],[\"79700.50\",\"0.156\"],[\"80395.60\",\"1.430\"],[\"80554.70\",\"1.240\"],[\"81188.20\",\"0.010\"]],\"st\":1}}"}
{"receive_ns":1788563747712278000,"stream":"btcusdt@depth@100ms","event_type":"depthUpdate","event_time_ms":1788563743655,"raw_json":"{\"stream\":\"btcusdt@depth@100ms\",\"data\":{\"e\":\"depthUpdate\",\"E\":1788563743655,\"T\":1788563743653,\"s\":\"BTCUSDT\",\"ps\":\"BTCUSDT\",\"U\":11478251683752,\"u\":11478251688764,\"pu\":11478251683731,\"b\":[[\"29199.50\",\"0.077\"],[\"29299.50\",\"1.834\"],[\"29396.30\",\"0.189\"],[\"63680.00\",\"0.072\"],[\"71639.50\",\"0.002\"],[\"71674.00\",\"0.000\"],[\"76415.50\",\"0.002\"],[\"78004.30\",\"0.006\"],[\"78680.00\",\"4.447\"],[\"78683.30\",\"2.322\"],[\"78770.00\",\"14.003\"],[\"78803.50\",\"0.000\"],[\"79201.50\",\"0.012\"],[\"79219.40\",\"0.148\"],[\"79494.00\",\"1.238\"],[\"79541.80\",\"0.108\"],[\"79567.80\",\"0.108\"],[\"79571.60\",\"1.721\"],[\"79575.80\",\"0.002\"],[\"79579.10\",\"0.004\"],[\"79581.20\",\"0.002\"],[\"79595.60\",\"0.003\"],[\"79595.70\",\"0.027\"],[\"79596.50\",\"0.002\"],[\"79597.50\",\"0.030\"],[\"79597.60\",\"0.082\"],[\"79598.70\",\"0.026\"],[\"79599.20\",\"0.001\"],[\"79599.50\",\"14.470\"]],\"a\":[[\"79599.60\",\"1.673\"],[\"79599.70\",\"1.237\"],[\"79607.60\",\"1.120\"],[\"79607.70\",\"2.210\"],[\"79608.50\",\"0.121\"],[\"79609.20\",\"0.064\"],[\"79615.70\",\"0.550\"],[\"79620.30\",\"0.146\"],[\"79620.40\",\"0.002\"],[\"79624.40\",\"0.627\"],[\"79645.30\",\"0.072\"],[\"79662.00\",\"0.007\"],[\"79671.40\",\"0.080\"],[\"79733.40\",\"0.000\"],[\"79947.80\",\"0.921\"],[\"79987.60\",\"0.203\"],[\"79995.60\",\"1.393\"],[\"79997.60\",\"0.376\"],[\"80395.60\",\"1.430\"],[\"80554.70\",\"4.586\"],[\"80634.40\",\"0.186\"]],\"st\":1}}"}
{"receive_ns":1788563747844443000,"stream":"btcusdt@depth@100ms","event_type":"depthUpdate","event_time_ms":1788563743757,"raw_json":"{\"stream\":\"btcusdt@depth@100ms\",\"data\":{\"e\":\"depthUpdate\",\"E\":1788563743757,\"T\":1788563743756,\"s\":\"BTCUSDT\",\"ps\":\"BTCUSDT\",\"U\":11478251689012,\"u\":11478251692868,\"pu\":11478251688764,\"b\":[[\"29199.50\",\"0.140\"],[\"29299.50\",\"1.883\"],[\"29396.30\",\"0.077\"],[\"63680.00\",\"0.072\"],[\"71639.50\",\"0.002\"],[\"75600.40\",\"0.001\"],[\"76415.50\",\"0.000\"],[\"78803.50\",\"0.002\"],[\"79494.00\",\"1.238\"],[\"79511.90\",\"0.252\"],[\"79575.60\",\"1.154\"],[\"79578.50\",\"0.073\"],[\"79579.40\",\"0.100\"],[\"79596.20\",\"1.113\"],[\"79599.50\",\"14.473\"]],\"a\":[[\"79602.10\",\"0.026\"],[\"79620.40\",\"0.629\"],[\"79624.40\",\"0.000\"],[\"79639.30\",\"0.071\"],[\"79995.60\",\"1.593\"],[\"79997.60\",\"0.377\"],[\"80395.60\",\"1.430\"],[\"80676.30\",\"68.846\"],[\"80713.70\",\"9.296\"],[\"83546.20\",\"0.004\"]],\"st\":1}}"}
{"receive_ns":1788563748234433000,"stream":"btcusdt@depth@100ms","event_type":"depthUpdate","event_time_ms":1788563743859,"raw_json":"{\"stream\":\"btcusdt@depth@100ms\",\"data\":{\"e\":\"depthUpdate\",\"E\":1788563743859,\"T\":1788563743858,\"s\":\"BTCUSDT\",\"ps\":\"BTCUSDT\",\"U\":11478251692895,\"u\":11478251697212,\"pu\":11478251692868,\"b\":[[\"1000.00\",\"24.754\"],[\"29199.50\",\"0.245\"],[\"29299.50\",\"1.855\"],[\"29396.30\",\"0.000\"],[\"71639.50\",\"0.002\"],[\"76415.50\",\"0.002\"],[\"78680.00\",\"3.692\"],[\"78683.30\",\"3.077\"],[\"78770.00\",\"13.060\"],[\"78772.50\",\"0.000\"],[\"78803.50\",\"0.000\"],[\"78843.30\",\"0.570\"],[\"79201.50\",\"0.011\"],[\"79219.40\",\"0.148\"],[\"79494.00\",\"3.046\"],[\"79511.40\",\"0.000\"],[\"79539.80\",\"0.033\"],[\"79539.90\",\"0.000\"],[\"79541.80\",\"0.008\"],[\"79560.50\",\"0.123\"],[\"79571.50\",\"0.440\"],[\"79571.60\",\"0.013\"],[\"79571.70\",\"0.005\"],[\"79574.90\",\"0.001\"],[\"79575.60\",\"1.079\"],[\"79579.30\",\"0.694\"],[\"79582.90\",\"0.168\"],[\"79583.10\",\"0.087\"],[\"79594.90\",\"0.109\"],[\"79595.70\",\"0.001\"],[\"79596.70\",\"1.026\"],[\"79597.50\",\"0.004\"],[\"79597.60\",\"0.002\"],[\"79597.70\",\"0.000\"],[\"79597.90\",\"0.001\"],[\"79598.10\",\"0.193\"],[\"79598.70\",\"0.000\"],[\"79599.20\",\"0.081\"],[\"79599.50\",\"14.483\"]],\"a\":[[\"79599.60\",\"2.230\"],[\"79599.70\",\"1.238\"],[\"79631.00\",\"0.085\"],[\"79633.40\",\"0.001\"],[\"79651.50\",\"1.759\"],[\"79651.60\",\"0.040\"],[\"79680.10\",\"0.050\"],[\"79947.80\",\"0.921\"],[\"79987.60\",\"0.203\"],[\"79995.60\",\"1.593\"],[\"79997.60\",\"0.378\"],[\"80395.60\",\"1.430\"],[\"80634.30\",\"1.858\"],[\"80812.10\",\"0.216\"],[\"81188.20\",\"0.007\"],[\"81191.50\",\"0.012\"]],\"st\":1}}"}
{"receive_ns":1788563748445029000,"stream":"btcusdt@depth@100ms","event_type":"depthUpdate","event_time_ms":1788563743961,"raw_json":"{\"stream\":\"btcusdt@depth@100ms\",\"data\":{\"e\":\"depthUpdate\",\"E\":1788563743961,\"T\":1788563743960,\"s\":\"BTCUSDT\",\"ps\":\"BTCUSDT\",\"U\":11478251697288,\"u\":11478251701813,\"pu\":11478251697212,\"b\":[[\"29199.50\",\"0.420\"],[\"29299.50\",\"1.680\"],[\"71639.50\",\"0.002\"],[\"71730.00\",\"0.004\"],[\"78004.30\",\"0.003\"],[\"78007.60\",\"0.017\"],[\"78573.20\",\"13.437\"],[\"78680.00\",\"2.182\"],[\"78683.30\",\"4.587\"],[\"78803.50\",\"0.000\"],[\"79462.70\",\"0.010\"],[\"79462.80\",\"0.003\"],[\"79494.00\",\"2.041\"],[\"79506.00\",\"0.346\"],[\"79511.90\",\"0.001\"],[\"79522.00\",\"0.021\"],[\"79529.80\",\"0.073\"],[\"79571.50\",\"0.001\"],[\"79574.60\",\"1.727\"],[\"79593.60\",\"0.080\"],[\"79597.20\",\"0.002\"],[\"79597.60\",\"0.082\"],[\"79598.00\",\"0.028\"],[\"79598.30\",\"0.026\"],[\"79599.20\",\"0.001\"],[\"79599.50\",\"14.505\"]],\"a\":[[\"79599.60\",\"2.148\"],[\"79600.70\",\"0.002\"],[\"79602.10\",\"0.026\"],[\"79605.50\",\"0.000\"],[\"79648.20\",\"0.012\"],[\"79680.00\",\"2.837\"],[\"79820.80\",\"0.002\"],[\"79820.90\",\"0.003\"],[\"79995.60\",\"1.393\"],[\"79997.60\",\"0.578\"],[\"80395.60\",\"1.432\"],[\"80706.00\",\"0.934\"]],\"st\":1}}"}
{"receive_ns":1788563748814344000,"stream":"btcusdt@depth@100ms","event_type":"depthUpdate","event_time_ms":1788563744063,"raw_json":"{\"stream\":\"btcusdt@depth@100ms\",\"data\":{\"e\":\"depthUpdate\",\"E\":1788563744063,\"T\":1788563744062,\"s\":\"BTCUSDT\",\"ps\":\"BTCUSDT\",\"U\":11478251701843,\"u\":11478251706405,\"pu\":11478251701813,\"b\":[[\"29199.50\",\"0.602\"],[\"29299.50\",\"1.498\"],[\"63680.00\",\"0.072\"],[\"71639.50\",\"0.002\"],[\"75614.20\",\"0.000\"],[\"75616.50\",\"0.002\"],[\"75616.60\",\"0.003\"],[\"76415.50\",\"0.000\"],[\"78803.50\",\"0.000\"],[\"79219.40\",\"0.007\"],[\"79471.00\",\"0.000\"],[\"79483.90\",\"0.561\"],[\"79492.00\",\"0.000\"],[\"79494.00\",\"1.006\"],[\"79495.80\",\"0.946\"],[\"79501.30\",\"4.767\"],[\"79503.90\",\"0.021\"],[\"79511.40\",\"6.119\"],[\"79529.30\",\"0.001\"],[\"79539.40\",\"0.071\"],[\"79539.50\",\"3.349\"],[\"79539.90\",\"3.569\"],[\"79542.10\",\"18.186\"],[\"79560.50\",\"0.546\"],[\"79561.60\",\"0.004\"],[\"79575.70\",\"0.003\"],[\"79585.20\",\"0.541\"],[\"79595.70\",\"0.027\"],[\"79597.40\",\"0.000\"],[\"79597.60\",\"0.002\"],[\"79598.00\",\"0.002\"],[\"79598.30\",\"0.000\"],[\"79599.20\",\"0.081\"],[\"79599.50\",\"14.460\"]],\"a\":[[\"79599.60\",\"2.150\"],[\"79603.50\",\"0.027\"],[\"79603.60\",\"0.026\"],[\"79604.10\",\"0.083\"],[\"79605.30\",\"0.005\"],[\"79607.60\",\"1.000\"],[\"79610.00\",\"0.176\"],[\"79611.50\",\"0.093\"],[\"79620.50\",\"2.031\"],[\"79633.70\",\"0.457\"],[\"79648.80\",\"0.971\"],[\"79654.20\",\"3.608\"],[\"79662.60\",\"0.029\"],[\"79668.80\",\"26.453\"],[\"79671.50\",\"0.001\"],[\"79672.40\",\"0.847\"],[\"79675.30\",\"0.000\"],[\"79680.70\",\"1.249\"],[\"79682.80\",\"6.120\"],[\"79689.80\",\"3.595\"],[\"79704.70\",\"0.001\"],[\"79717.90\",\"0.000\"],[\"79720.10\",\"3.322\"],[\"79720.60\",\"0.006\"],[\"79733.40\",\"0.006\"],[\"79742.90\",\"0.002\"],[\"79751.80\",\"0.001\"],[\"79797.10\",\"0.001\"],[\"79800.00\",\"4.049\"],[\"79800.80\",\"0.000\"],[\"79804.00\",\"0.470\"],[\"79806.00\",\"0.298\"],[\"79808.10\",\"2.617\"],[\"79820.50\",\"7.362\"],[\"79820.90\",\"0.000\"],[\"79821.00\",\"0.091\"],[\"79947.80\",\"0.000\"],[\"79987.60\",\"0.003\"],[\"79993.90\",\"0.188\"],[\"79995.60\",\"0.013\"],[\"80395.60\",\"1.430\"],[\"80714.00\",\"1.855\"]],\"st\":1}}"}
{"receive_ns":1788563748876691000,"stream":"btcusdt@depth@100ms","event_type":"depthUpdate","event_time_ms":1788563744165,"raw_json":"{\"stream\":\"btcusdt@depth@100ms\",\"data\":{\"e\":\"depthUpdate\",\"E\":1788563744165,\"T\":1788563744162,\"s\":\"BTCUSDT\",\"ps\":\"BTCUSDT\",\"U\":11478251706458,\"u\":11478251710977,\"pu\":11478251706405,\"b\":[[\"1000.00\",\"24.754\"],[\"29199.50\",\"0.777\"],[\"29299.50\",\"1.323\"],[\"63677.00\",\"0.000\"],[\"71639.50\",\"0.002\"],[\"76415.50\",\"0.002\"],[\"78383.80\",\"0.064\"],[\"78389.50\",\"0.007\"],[\"78463.30\",\"0.003\"],[\"78469.10\",\"0.008\"],[\"78803.50\",\"0.000\"],[\"79201.50\",\"0.001\"],[\"79219.40\",\"0.148\"],[\"79433.90\",\"2.558\"],[\"79488.10\",\"1.776\"],[\"79506.00\",\"0.020\"],[\"79509.60\",\"0.003\"],[\"79511.50\",\"1.878\"],[\"79511.90\",\"0.427\"],[\"79539.30\",\"0.000\"],[\"79539.50\",\"0.126\"],[\"79542.00\",\"0.002\"],[\"79543.80\",\"2.715\"],[\"79572.60\",\"0.079\"],[\"79582.20\",\"0.071\"],[\"79593.60\",\"0.080\"],[\"79595.40\",\"0.253\"],[\"79595.70\",\"0.027\"],[\"79596.20\",\"1.090\"],[\"79597.30\",\"0.252\"],[\"79597.50\",\"0.004\"],[\"79597.60\",\"0.002\"],[\"79597.70\",\"0.026\"],[\"79598.30\",\"0.026\"],[\"79599.50\",\"14.483\"]],\"a\":[[\"79599.60\",\"1.600\"],[\"79604.20\",\"0.127\"],[\"79605.50\",\"0.000\"],[\"79608.50\",\"0.117\"],[\"79609.20\",\"0.068\"],[\"79620.30\",\"0.773\"],[\"79620.40\",\"0.002\"],[\"79624.40\",\"0.000\"],[\"79641.10\",\"2.994\"],[\"79641.20\",\"0.202\"],[\"79671.40\",\"0.077\"],[\"79674.40\",\"0.005\"],[\"79680.20\",\"0.004\"],[\"79685.50\",\"0.021\"],[\"79695.10\",\"0.003\"],[\"79695.20\",\"0.597\"],[\"79698.90\",\"0.004\"],[\"79700.10\",\"0.016\"],[\"79700.20\",\"0.550\"],[\"79708.20\",\"0.004\"],[\"79713.00\",\"0.001\"],[\"79720.00\",\"0.240\"],[\"79722.80\",\"0.619\"],[\"79752.90\",\"26.331\"],[\"79779.10\",\"0.000\"],[\"79803.80\",\"2.927\"],[\"79947.80\",\"0.619\"],[\"79987.60\",\"0.505\"],[\"79995.60\",\"0.213\"],[\"79997.60\",\"1.758\"],[\"80395.60\",\"1.430\"],[\"80554.80\",\"0.867\"],[\"80653.50\",\"0.494\"],[\"80714.00\",\"2.102\"],[\"80724.20\",\"0.390\"],[\"80803.80\",\"0.000\"],[\"83546.20\",\"0.000\"]],\"st\":1}}"}
{"receive_ns":1788563749601514000,"stream":"btcusdt@depth@100ms","event_type":"depthUpdate","event_time_ms":1788563744267,"raw_json":"{\"stream\":\"btcusdt@depth@100ms\",\"data\":{\"e\":\"depthUpdate\",\"E\":1788563744267,\"T\":1788563744266,\"s\":\"BTCUSDT\",\"ps\":\"BTCUSDT\",\"U\":11478251711090,\"u\":11478251715758,\"pu\":11478251710977,\"b\":[[\"29199.50\",\"0.959\"],[\"29299.50\",\"1.141\"],[\"71639.50\",\"0.002\"],[\"76415.50\",\"0.000\"],[\"78573.20\",\"13.221\"],[\"78803.50\",\"0.000\"],[\"78930.90\",\"0.007\"],[\"79471.00\",\"10.198\"],[\"79488.10\",\"2.781\"],[\"79494.00\",\"0.001\"],[\"79571.50\",\"0.077\"],[\"79574.60\",\"1.288\"],[\"79574.90\",\"0.440\"],[\"79580.90\",\"0.004\"],[\"79591.80\",\"0.001\"],[\"79595.40\",\"0.001\"],[\"79595.50\",\"0.433\"],[\"79595.60\",\"0.029\"],[\"79595.70\",\"0.027\"],[\"79596.40\",\"0.027\"],[\"79596.60\",\"0.027\"],[\"79596.70\",\"1.026\"],[\"79596.80\",\"0.002\"],[\"79597.70\",\"0.000\"],[\"79598.30\",\"0.000\"],[\"79598.90\",\"0.000\"],[\"79599.50\",\"14.483\"]],\"a\":[[\"79599.60\",\"2.149\"],[\"79601.40\",\"0.002\"],[\"79602.00\",\"0.039\"],[\"79608.50\",\"0.121\"],[\"79609.20\",\"0.064\"],[\"79618.50\",\"0.002\"],[\"79619.90\",\"0.487\"],[\"79620.30\",\"0.146\"],[\"79620.40\",\"0.629\"],[\"79624.40\",\"0.000\"],[\"79662.80\",\"0.000\"],[\"79668.80\",\"0.000\"],[\"79671.40\",\"0.080\"],[\"79671.50\",\"26.454\"],[\"79674.40\",\"0.002\"],[\"79676.90\",\"0.204\"],[\"79698.80\",\"0.001\"],[\"79708.10\",\"0.001\"],[\"79723.30\",\"10.214\"],[\"80395.60\",\"1.430\"],[\"80674.20\",\"0.618\"],[\"80729.90\",\"0.254\"],[\"80809.50\",\"0.008\"],[\"81188.20\",\"0.004\"],[\"81191.50\",\"0.015\"]],\"st\":1}}"}
{"receive_ns":1788563751091659000,"stream":"btcusdt@depth@100ms","event_type":"depthUpdate","event_time_ms":1788563744369,"raw_json":"{\"stream\":\"btcusdt@depth@100ms\",\"data\":{\"e\":\"depthUpdate\",\"E\":1788563744369,\"T\":1788563744368,\"s\":\"BTCUSDT\",\"ps\":\"BTCUSDT\",\"U\":11478251715838,\"u\":11478251724054,\"pu\":11478251715758,\"b\":[[\"29199.50\",\"1.134\"],[\"29299.50\",\"0.966\"],[\"63680.00\",\"0.072\"],[\"71639.50\",\"0.002\"],[\"76415.50\",\"0.002\"],[\"78007.60\",\"0.020\"],[\"78579.30\",\"0.005\"],[\"78803.50\",\"0.000\"],[\"79219.40\",\"0.148\"],[\"79293.90\",\"0.502\"],[\"79411.70\",\"0.031\"],[\"79418.40\",\"0.000\"],[\"79419.70\",\"0.001\"],[\"79445.80\",\"11.301\"],[\"79448.00\",\"2.526\"],[\"79488.10\",\"2.549\"],[\"79490.10\",\"0.232\"],[\"79495.60\",\"0.001\"],[\"79498.30\",\"0.041\"],[\"79510.30\",\"0.053\"],[\"79511.90\",\"1.809\"],[\"79512.10\",\"0.333\"],[\"79513.50\",\"0.032\"],[\"79513.60\",\"0.038\"],[\"79515.70\",\"1.171\"],[\"79516.30\",\"1.288\"],[\"79517.50\",\"0.055\"],[\"79518.70\",\"0.077\"],[\"79518.90\",\"0.027\"],[\"79519.00\",\"0.020\"],[\"79521.90\",\"0.827\"],[\"79523.40\",\"0.000\"],[\"79524.10\",\"3.460\"],[\"79525.20\",\"0.028\"],[\"79525.60\",\"0.343\"],[\"79527.80\",\"0.003\"],[\"79528.20\",\"0.002\"],[\"79533.20\",\"0.801\"],[\"79536.70\",\"0.020\"],[\"79537.40\",\"0.845\"],[\"79542.10\",\"18.214\"],[\"79542.80\",\"0.051\"],[\"79543.80\",\"1.007\"],[\"79546.10\",\"0.038\"],[\"79551.70\",\"0.033\"],[\"79557.10\",\"2.832\"],[\"79560.70\",\"0.002\"],[\"79560.80\",\"0.002\"],[\"79563.10\",\"0.547\"],[\"79564.20\",\"10.002\"],[\"79566.60\",\"0.166\"],[\"79566.90\",\"0.000\"],[\"79567.90\",\"2.795\"],[\"79568.30\",\"0.008\"],[\"79569.10\",\"0.498\"],[\"79570.50\",\"0.002\"],[\"79571.50\",\"0.516\"],[\"79572.20\",\"0.003\"],[\"79572.30\",\"0.047\"],[\"79573.10\",\"0.000\"],[\"79574.90\",\"0.001\"],[\"79582.90\",\"0.244\"],[\"79584.00\",\"0.010\"],[\"79584.70\",\"0.005\"],[\"79587.30\",\"0.544\"],[\"79591.50\",\"0.194\"],[\"79593.10\",\"0.003\"],[\"79593.60\",\"0.080\"],[\"79594.90\",\"0.000\"],[\"79595.20\",\"0.002\"],[\"79595.60\",\"0.003\"],[\"79595.70\",\"0.253\"],[\"79595.80\",\"0.239\"],[\"79597.20\",\"0.028\"],[\"79597.60\",\"0.082\"],[\"79598.70\",\"0.026\"],[\"79599.20\",\"0.001\"],[\"79599.50\",\"14.482\"]],\"a\":[[\"79599.60\",\"1.655\"],[\"79599.70\",\"1.238\"],[\"79599.80\",\"0.104\"],[\"79599.90\",\"0.027\"],[\"79600.00\",\"0.055\"],[\"79600.10\",\"0.029\"],[\"79600.30\",\"0.102\"],[\"79600.50\",\"0.001\"],[\"79600.60\",\"0.001\"],[\"79601.00\",\"0.026\"],[\"79601.10\",\"0.026\"],[\"79601.20\",\"0.027\"],[\"79601.40\",\"0.028\"],[\"79601.50\",\"0.001\"],[\"79601.70\",\"0.090\"],[\"79601.90\",\"0.027\"],[\"79602.00\",\"0.039\"],[\"79602.10\",\"0.000\"],[\"79602.30\",\"0.296\"],[\"79602.40\",\"1.676\"],[\"79602.60\",\"0.001\"],[\"79602.70\",\"0.000\"],[\"79602.80\",\"0.000\"],[\"79603.10\",\"0.002\"],[\"79603.20\",\"0.003\"],[\"79603.40\",\"0.001\"],[\"79603.50\",\"0.001\"],[\"79603.60\",\"0.000\"],[\"79603.70\",\"0.002\"],[\"79604.10\",\"0.335\"],[\"79604.20\",\"0.127\"],[\"79604.40\",\"0.001\"],[\"79604.50\",\"0.000\"],[\"79604.90\",\"0.006\"],[\"79605.50\",\"0.000\"],[\"79607.00\",\"0.550\"],[\"79607.50\",\"0.446\"],[\"79608.00\",\"1.114\"],[\"79608.10\",\"0.007\"],[\"79608.50\",\"0.117\"],[\"79608.60\",\"0.006\"],[\"79608.80\",\"0.001\"],[\"79609.10\",\"0.001\"],[\"79609.20\",\"0.068\"],[\"79609.50\",\"1.666\"],[\"79609.80\",\"0.886\"],[\"79611.00\",\"1.717\"],[\"79611.10\",\"0.537\"],[\"79611.20\",\"0.004\"],[\"79611.40\",\"0.000\"],[\"79611.90\",\"0.127\"],[\"79612.60\",\"0.205\"],[\"79612.70\",\"0.271\"],[\"79613.80\",\"0.646\"],[\"79614.20\",\"0.713\"],[\"79614.40\",\"0.637\"],[\"79616.00\",\"0.038\"],[\"79616.90\",\"1.269\"],[\"79619.40\",\"1.932\"],[\"79620.10\",\"0.693\"],[\"79620.30\",\"0.146\"],[\"79620.40\",\"0.002\"],[\"79621.40\",\"0.082\"],[\"79622.50\",\"0.028\"],[\"79623.10\",\"0.001\"],[\"79624.00\",\"0.042\"],[\"79624.40\",\"0.627\"],[\"79624.60\",\"0.028\"],[\"79624.70\",\"1.695\"],[\"79627.50\",\"0.002\"],[\"79628.20\",\"0.213\"],[\"79629.30\",\"0.038\"],[\"79630.60\",\"0.001\"],[\"79630.90\",\"0.023\"],[\"79633.00\",\"0.329\"],[\"79633.20\",\"0.831\"],[\"79634.80\",\"10.001\"],[\"79634.90\",\"0.002\"],[\"79635.00\",\"0.026\"],[\"79638.30\",\"0.064\"],[\"79649.60\",\"0.069\"],[\"79650.30\",\"0.000\"],[\"79654.20\",\"3.571\"],[\"79654.70\",\"1.169\"],[\"79657.00\",\"0.247\"],[\"79666.90\",\"0.000\"],[\"79667.00\",\"0.000\"],[\"79668.10\",\"0.000\"],[\"79669.10\",\"0.002\"],[\"79670.10\",\"0.039\"],[\"79671.30\",\"0.043\"],[\"79671.40\",\"0.077\"],[\"79671.50\",\"0.001\"],[\"79673.90\",\"0.001\"],[\"79674.40\",\"0.005\"],[\"79675.70\",\"1.809\"],[\"79676.90\",\"26.657\"],[\"79677.20\",\"0.038\"],[\"79678.70\",\"0.000\"],[\"79681.70\",\"0.039\"],[\"79695.20\",\"0.595\"],[\"79700.50\",\"0.031\"],[\"79700.60\",\"0.125\"],[\"79808.10\",\"5.856\"],[\"79947.80\",\"0.619\"],[\"79949.80\",\"0.712\"],[\"79987.60\",\"0.003\"],[\"79995.60\",\"0.777\"],[\"79997.60\",\"0.994\"],[\"80395.60\",\"1.430\"],[\"83579.60\",\"0.000\"]],\"st\":1}}"}
{"receive_ns":1788563751181861000,"stream":"btcusdt@depth@100ms","event_type":"depthUpdate","event_time_ms":1788563744471,"raw_json":"{\"stream\":\"btcusdt@depth@100ms\",\"data\":{\"e\":\"depthUpdate\",\"E\":1788563744471,\"T\":1788563744469,\"s\":\"BTCUSDT\",\"ps\":\"BTCUSDT\",\"U\":11478251724173,\"u\":11478251729927,\"pu\":11478251724054,\"b\":[[\"1000.00\",\"24.754\"],[\"29199.50\",\"1.316\"],[\"29299.50\",\"0.784\"],[\"71639.50\",\"0.002\"],[\"78007.60\",\"0.023\"],[\"78482.00\",\"4.442\"],[\"78641.10\",\"1.270\"],[\"78803.50\",\"0.000\"],[\"79177.50\",\"9.276\"],[\"79201.50\",\"0.011\"],[\"79488.10\",\"1.544\"],[\"79490.10\",\"0.483\"],[\"79511.90\",\"2.889\"],[\"79552.90\",\"0.009\"],[\"79564.60\",\"0.007\"],[\"79571.50\",\"0.077\"],[\"79574.90\",\"0.440\"],[\"79595.70\",\"0.001\"],[\"79595.80\",\"0.213\"],[\"79596.40\",\"0.029\"],[\"79597.40\",\"0.000\"],[\"79597.60\",\"0.028\"],[\"79598.70\",\"0.000\"],[\"79599.20\",\"0.081\"],[\"79599.50\",\"14.482\"]],\"a\":[[\"79599.60\",\"1.700\"],[\"79601.70\",\"0.090\"],[\"79604.20\",\"0.001\"],[\"79604.60\",\"0.003\"],[\"79606.00\",\"0.282\"],[\"79606.30\",\"0.690\"],[\"79610.80\",\"0.005\"],[\"79614.90\",\"0.044\"],[\"79620.30\",\"0.020\"],[\"79621.30\",\"0.008\"],[\"79628.10\",\"0.003\"],[\"79631.80\",\"0.001\"],[\"79671.40\",\"0.080\"],[\"79671.50\",\"26.454\"],[\"79674.40\",\"0.002\"],[\"79676.90\",\"0.204\"],[\"79808.10\",\"5.855\"],[\"79995.60\",\"0.977\"],[\"80395.60\",\"1.430\"],[\"80530.40\",\"7.189\"],[\"80594.60\",\"0.186\"]],\"st\":1}}"}
{"receive_ns":1788563751233958000,"stream":"btcusdt@depth@100ms","event_type":"depthUpdate","event_time_ms":1788563744573,"raw_json":"{\"stream\":\"btcusdt@depth@100ms\",\"data\":{\"e\":\"depthUpdate\",\"E\":1788563744573,\"T\":1788563744570,\"s\":\"BTCUSDT\",\"ps\":\"BTCUSDT\",\"U\":11478251730012,\"u\":11478251734209,\"pu\":11478251729927,\"b\":[[\"29199.50\",\"1.491\"],[\"29299.50\",\"0.609\"],[\"63679.60\",\"0.000\"],[\"71639.50\",\"0.002\"],[\"75616.40\",\"0.004\"],[\"75616.50\",\"0.004\"],[\"76415.50\",\"0.000\"],[\"78362.50\",\"0.892\"],[\"78442.10\",\"0.891\"],[\"78680.80\",\"0.762\"],[\"78803.50\",\"0.000\"],[\"79219.40\",\"0.148\"],[\"79488.10\",\"1.776\"],[\"79490.10\",\"0.251\"],[\"79511.90\",\"1.683\"],[\"79571.60\",\"1.219\"],[\"79593.60\",\"0.080\"],[\"79593.80\",\"0.009\"],[\"79597.70\",\"0.026\"],[\"79599.50\",\"14.514\"]],\"a\":[[\"79599.60\",\"1.701\"],[\"79605.50\",\"0.000\"],[\"79606.00\",\"0.282\"],[\"79607.60\",\"2.210\"],[\"79607.70\",\"1.000\"],[\"79947.80\",\"0.419\"],[\"79949.80\",\"0.712\"],[\"79987.60\",\"0.203\"],[\"79995.60\",\"1.067\"],[\"79997.60\",\"0.904\"],[\"80395.60\",\"1.430\"]],\"st\":1}}"}
{"receive_ns":1788563751324774000,"stream":"btcusdt@depth@100ms","event_type":"depthUpdate","event_time_ms":1788563744675,"raw_json":"{\"stream\":\"btcusdt@depth@100ms\",\"data\":{\"e\":\"depthUpdate\",\"E\":1788563744675,\"T\":1788563744674,\"s\":\"BTCUSDT\",\"ps\":\"BTCUSDT\",\"U\":11478251734314,\"u\":11478251739996,\"pu\":11478251734209,\"b\":[[\"1000.00\",\"24.904\"],[\"29199.50\",\"1.673\"],[\"29299.50\",\"0.427\"],[\"63677.00\",\"0.000\"],[\"63680.00\",\"0.072\"],[\"71639.50\",\"0.002\"],[\"71674.00\",\"0.003\"],[\"76415.50\",\"0.002\"],[\"78600.60\",\"0.004\"],[\"78609.50\",\"0.000\"],[\"78614.20\",\"0.660\"],[\"78618.50\",\"0.394\"],[\"78803.50\",\"0.000\"],[\"79201.50\",\"0.389\"],[\"79470.40\",\"0.000\"],[\"79471.00\",\"10.692\"],[\"79488.10\",\"2.027\"],[\"79490.10\",\"0.000\"],[\"79511.90\",\"0.678\"],[\"79571.60\",\"0.013\"],[\"79575.80\",\"0.002\"],[\"79582.90\",\"0.168\"],[\"79597.40\",\"0.026\"],[\"79597.60\",\"0.002\"],[\"79597.70\",\"0.000\"],[\"79599.50\",\"14.514\"]],\"a\":[[\"79599.60\",\"2.912\"],[\"79599.70\",\"0.028\"],[\"79601.70\",\"0.090\"],[\"79604.00\",\"0.298\"],[\"79606.00\",\"0.013\"],[\"79606.20\",\"0.156\"],[\"79615.70\",\"0.550\"],[\"79669.40\",\"8.786\"],[\"79671.50\",\"26.455\"],[\"79720.90\",\"0.430\"],[\"79995.60\",\"1.067\"],[\"80395.60\",\"1.430\"],[\"80530.40\",\"5.949\"],[\"80538.60\",\"3.605\"]],\"st\":1}}"}
{"receive_ns":1788563751666168000,"stream":"btcusdt@depth@100ms","event_type":"depthUpdate","event_time_ms":1788563744777,"raw_json":"{\"stream\":\"btcusdt@depth@100ms\",\"data\":{\"e\":\"depthUpdate\",\"E\":1788563744777,\"T\":1788563744776,\"s\":\"BTCUSDT\",\"ps\":\"BTCUSDT\",\"U\":11478251740076,\"u\":11478251744788,\"pu\":11478251739996,\"b\":[[\"1000.00\",\"24.754\"],[\"29099.50\",\"0.035\"],[\"29199.50\",\"1.778\"],[\"29299.50\",\"0.287\"],[\"71639.50\",\"0.002\"],[\"71674.00\",\"0.000\"],[\"75619.50\",\"0.005\"],[\"76415.50\",\"0.000\"],[\"78739.40\",\"7.157\"],[\"78803.50\",\"0.000\"],[\"79201.50\",\"0.389\"],[\"79219.40\",\"0.007\"],[\"79415.10\",\"0.001\"],[\"79415.40\",\"3.141\"],[\"79488.10\",\"1.795\"],[\"79511.20\",\"0.000\"],[\"79511.30\",\"0.040\"],[\"79511.90\",\"1.081\"],[\"79581.10\",\"0.152\"],[\"79582.90\",\"0.150\"],[\"79583.10\",\"0.072\"],[\"79595.90\",\"0.059\"],[\"79596.00\",\"0.003\"],[\"79597.60\",\"0.082\"],[\"79597.70\",\"0.026\"],[\"79597.90\",\"0.027\"],[\"79598.00\",\"0.002\"],[\"79599.20\",\"0.001\"],[\"79599.50\",\"14.514\"]],\"a\":[[\"79599.60\",\"2.940\"],[\"79599.70\",\"0.002\"],[\"79599.90\",\"0.001\"],[\"79600.00\",\"0.021\"],[\"79600.10\",\"0.003\"],[\"79600.30\",\"0.092\"],[\"79600.40\",\"0.017\"],[\"79602.00\",\"0.065\"],[\"79602.10\",\"0.026\"],[\"79604.00\",\"0.029\"],[\"79606.20\",\"0.002\"],[\"79614.90\",\"0.004\"],[\"79622.40\",\"0.044\"],[\"79686.50\",\"0.039\"],[\"79744.30\",\"0.000\"],[\"79744.70\",\"3.141\"],[\"79947.80\",\"0.000\"],[\"79949.80\",\"0.210\"],[\"79987.60\",\"0.003\"],[\"79995.60\",\"0.213\"],[\"79997.60\",\"0.377\"],[\"80236.40\",\"0.498\"],[\"80395.60\",\"1.430\"],[\"80554.80\",\"1.486\"],[\"80761.50\",\"2.689\"]],\"st\":1}}"}
{"receive_ns":1788563751804627000,"stream":"btcusdt@depth@100ms","event_type":"depthUpdate","event_time_ms":1788563744879,"raw_json":"{\"stream\":\"btcusdt@depth@100ms\",\"data\":{\"e\":\"depthUpdate\",\"E\":1788563744879,\"T\":1788563744877,\"s\":\"BTCUSDT\",\"ps\":\"BTCUSDT\",\"U\":11478251744840,\"u\":11478251749047,\"pu\":11478251744788,\"b\":[[\"29099.50\",\"0.091\"],[\"29199.50\",\"1.848\"],[\"29299.50\",\"0.161\"],[\"63680.00\",\"0.072\"],[\"71639.50\",\"0.002\"],[\"78573.20\",\"13.030\"],[\"78600.60\",\"0.000\"],[\"78603.00\",\"0.013\"],[\"78803.50\",\"0.000\"],[\"78850.80\",\"10.979\"],[\"79201.50\",\"0.390\"],[\"79219.40\",\"0.148\"],[\"79488.10\",\"1.876\"],[\"79511.90\",\"2.714\"],[\"79557.10\",\"2.003\"],[\"79574.20\",\"0.003\"],[\"79577.50\",\"0.374\"],[\"79579.00\",\"0.098\"],[\"79583.00\",\"0.071\"],[\"79595.90\",\"0.085\"],[\"79596.00\",\"0.029\"],[\"79597.40\",\"0.000\"],[\"79597.60\",\"0.002\"],[\"79597.70\",\"0.000\"],[\"79597.90\",\"0.001\"],[\"79599.20\",\"0.081\"],[\"79599.50\",\"14.516\"]],\"a\":[[\"79601.60\",\"0.321\"],[\"79612.30\",\"0.001\"],[\"79613.70\",\"0.439\"],[\"79614.50\",\"0.254\"],[\"79629.90\",\"2.001\"],[\"79632.70\",\"1.118\"],[\"79634.80\",\"0.001\"],[\"79634.90\",\"0.000\"],[\"79660.10\",\"0.153\"],[\"79808.10\",\"3.717\"],[\"79943.90\",\"0.200\"],[\"79947.80\",\"0.419\"],[\"79949.80\",\"0.712\"],[\"79995.60\",\"0.867\"],[\"79997.60\",\"0.902\"],[\"80395.60\",\"1.430\"],[\"80530.90\",\"0.433\"]],\"st\":1}}"}
{"receive_ns":1788563751916603000,"stream":"btcusdt@depth@100ms","event_type":"depthUpdate","event_time_ms":1788563744981,"raw_json":"{\"stream\":\"btcusdt@depth@100ms\",\"data\":{\"e\":\"depthUpdate\",\"E\":1788563744981,\"T\":1788563744979,\"s\":\"BTCUSDT\",\"ps\":\"BTCUSDT\",\"U\":11478251749172,\"u\":11478251753247,\"pu\":11478251749047,\"b\":[[\"1000.00\",\"24.754\"],[\"29099.50\",\"0.154\"],[\"29199.50\",\"1.897\"],[\"29299.50\",\"0.049\"],[\"63677.00\",\"0.002\"],[\"63680.00\",\"0.072\"],[\"71639.50\",\"0.002\"],[\"76415.50\",\"0.002\"],[\"78007.60\",\"0.026\"],[\"78728.60\",\"0.570\"],[\"78803.50\",\"0.000\"],[\"78811.00\",\"2.660\"],[\"79201.50\",\"0.391\"],[\"79488.10\",\"2.127\"],[\"79511.90\",\"2.789\"],[\"79575.40\",\"0.444\"],[\"79577.50\",\"0.001\"],[\"79590.80\",\"0.049\"],[\"79593.60\",\"0.080\"],[\"79594.70\",\"0.255\"],[\"79595.90\",\"0.059\"],[\"79597.40\",\"0.026\"],[\"79597.50\",\"0.030\"],[\"79598.10\",\"0.219\"],[\"79599.50\",\"14.530\"]],\"a\":[[\"79599.60\",\"2.943\"],[\"79605.50\",\"0.000\"],[\"79610.80\",\"0.005\"],[\"79612.30\",\"0.440\"],[\"79613.70\",\"0.000\"],[\"79621.30\",\"0.002\"],[\"79624.40\",\"0.633\"],[\"79666.10\",\"26.486\"],[\"79671.40\",\"0.077\"],[\"79671.50\",\"0.002\"],[\"79674.40\",\"0.005\"],[\"79995.60\",\"1.023\"],[\"79997.60\",\"0.946\"],[\"80212.10\",\"3.172\"],[\"80395.60\",\"1.430\"]],\"st\":1}}"}
{"receive_ns":1788563752049822000,"stream":"btcusdt@depth@100ms","event_type":"depthUpdate","event_time_ms":1788563745083,"raw_json":"{\"stream\":\"btcusdt@depth@100ms\",\"data\":{\"e\":\"depthUpdate\",\"E\":1788563745083,\"T\":1788563745081,\"s\":\"BTCUSDT\",\"ps\":\"BTCUSDT\",\"U\":11478251753292,\"u\":11478251758503,\"pu\":11478251753247,\"b\":[[\"1000.00\",\"24.754\"],[\"29099.50\",\"0.287\"],[\"29199.50\",\"1.813\"],[\"29299.50\",\"0.000\"],[\"63677.00\",\"0.000\"],[\"63680.00\",\"0.072\"],[\"71639.50\",\"0.002\"],[\"75616.50\",\"0.002\"],[\"75616.60\",\"0.005\"],[\"76415.50\",\"0.000\"],[\"78803.50\",\"0.000\"],[\"78843.30\",\"1.139\"],[\"79201.50\",\"0.391\"],[\"79219.40\",\"0.148\"],[\"79462.80\",\"0.000\"],[\"79463.60\",\"0.012\"],[\"79470.20\",\"0.000\"],[\"79471.10\",\"2.575\"],[\"79477.00\",\"0.001\"],[\"79488.10\",\"2.629\"],[\"79503.50\",\"2.306\"],[\"79511.90\",\"2.287\"],[\"79518.80\",\"0.001\"],[\"79536.10\",\"0.015\"],[\"79544.00\",\"3.898\"],[\"79572.10\",\"0.007\"],[\"79574.20\",\"0.001\"],[\"79581.10\",\"0.076\"],[\"79585.20\",\"0.541\"],[\"79593.10\",\"0.001\"],[\"79595.50\",\"0.459\"],[\"79595.60\",\"0.029\"],[\"79595.70\",\"0.027\"],[\"79595.80\",\"0.239\"],[\"79595.90\",\"0.085\"],[\"79596.40\",\"0.003\"],[\"79596.60\",\"0.001\"],[\"79596.70\",\"1.000\"],[\"79596.90\",\"0.000\"],[\"79597.20\",\"0.002\"],[\"79597.40\",\"0.000\"],[\"79597.50\",\"0.004\"],[\"79598.10\",\"0.193\"],[\"79599.50\",\"14.522\"]],\"a\":[[\"79601.60\",\"0.321\"],[\"79612.30\",\"0.001\"],[\"79613.70\",\"0.439\"],[\"79637.70\",\"0.047\"],[\"79641.20\",\"0.203\"],[\"79652.10\",\"1.453\"],[\"79680.70\",\"2.009\"],[\"79798.00\",\"1.032\"],[\"79820.40\",\"1.518\"],[\"79821.00\",\"0.088\"],[\"79821.10\",\"0.000\"],[\"79821.70\",\"0.003\"],[\"79943.90\",\"0.000\"],[\"79947.80\",\"1.121\"],[\"79949.80\",\"0.210\"],[\"79995.60\",\"0.169\"],[\"79997.60\",\"1.800\"],[\"80395.60\",\"1.430\"]],\"st\":1}}"}
{"receive_ns":1788563752114469000,"stream":"btcusdt@depth@100ms","event_type":"depthUpdate","event_time_ms":1788563745185,"raw_json":"{\"stream\":\"btcusdt@depth@100ms\",\"data\":{\"e\":\"depthUpdate\",\"E\":1788563745185,\"T\":1788563745183,\"s\":\"BTCUSDT\",\"ps\":\"BTCUSDT\",\"U\":11478251758600,\"u\":11478251763107,\"pu\":11478251758503,\"b\":[[\"29099.50\",\"0.462\"],[\"29199.50\",\"1.638\"],[\"63677.00\",\"0.000\"],[\"71639.50\",\"0.002\"],[\"76415.50\",\"0.002\"],[\"78222.60\",\"1.021\"],[\"78803.50\",\"0.000\"],[\"79177.50\",\"9.150\"],[\"79471.00\",\"10.198\"],[\"79471.30\",\"0.494\"],[\"79488.10\",\"2.378\"],[\"79490.10\",\"0.251\"],[\"79511.90\",\"1.282\"],[\"79568.20\",\"0.382\"],[\"79584.20\",\"0.001\"],[\"79586.70\",\"0.033\"],[\"79594.70\",\"0.003\"],[\"79595.30\",\"0.026\"],[\"79596.30\",\"0.031\"],[\"79597.30\",\"0.000\"]],\"a\":[[\"79599.60\",\"2.944\"],[\"79604.00\",\"0.550\"],[\"79612.60\",\"0.833\"],[\"79624.40\",\"0.006\"],[\"79685.30\",\"1.215\"],[\"79698.70\",\"0.001\"],[\"79700.00\",\"0.601\"],[\"79700.60\",\"0.000\"],[\"79720.90\",\"0.000\"],[\"79721.00\",\"0.427\"],[\"79995.60\",\"0.213\"],[\"79997.60\",\"1.756\"],[\"80395.60\",\"1.430\"]],\"st\":1}}"}
{"receive_ns":1788563752175700000,"stream":"btcusdt@depth@100ms","event_type":"depthUpdate","event_time_ms":1788563745287,"raw_json":"{\"stream\":\"btcusdt@depth@100ms\",\"data\":{\"e\":\"depthUpdate\",\"E\":1788563745287,\"T\":1788563745285,\"s\":\"BTCUSDT\",\"ps\":\"BTCUSDT\",\"U\":11478251763341,\"u\":11478251767924,\"pu\":11478251763107,\"b\":[[\"1000.00\",\"24.754\"],[\"29099.50\",\"0.644\"],[\"29199.50\",\"1.456\"],[\"71639.50\",\"0.002\"],[\"76415.50\",\"0.000\"],[\"78246.30\",\"3.828\"],[\"78644.30\",\"0.292\"],[\"78803.50\",\"0.000\"],[\"79219.40\",\"0.007\"],[\"79488.10\",\"1.544\"],[\"79511.90\",\"1.081\"],[\"79557.00\",\"0.253\"],[\"79593.60\",\"0.080\"],[\"79595.20\",\"0.028\"],[\"79596.20\",\"1.064\"],[\"79597.60\",\"0.082\"],[\"79599.20\",\"0.001\"],[\"79599.50\",\"14.528\"]],\"a\":[[\"79604.00\",\"0.281\"],[\"79605.50\",\"0.000\"],[\"79612.50\",\"0.631\"],[\"79612.60\",\"0.205\"],[\"79624.30\",\"0.077\"],[\"79685.30\",\"1.216\"],[\"79698.60\",\"0.040\"],[\"79700.30\",\"1.569\"],[\"79947.80\",\"0.000\"],[\"79997.60\",\"0.376\"],[\"80395.60\",\"1.430\"],[\"80530.40\",\"4.958\"],[\"80713.70\",\"8.060\"],[\"81191.50\",\"0.018\"]],\"st\":1}}"}
{"receive_ns":1788563755023611000,"stream":"btcusdt@depth@100ms","event_type":"depthUpdate","event_time_ms":1788563745389,"raw_json":"{\"stream\":\"btcusdt@depth@100ms\",\"data\":{\"e\":\"depthUpdate\",\"E\":1788563745389,\"T\":1788563745388,\"s\":\"BTCUSDT\",\"ps\":\"BTCUSDT\",\"U\":11478251767992,\"u\":11478251777376,\"pu\":11478251767924,\"b\":[[\"1000.00\",\"24.754\"],[\"29099.50\",\"0.665\"],[\"29101.50\",\"0.154\"],[\"29199.50\",\"1.281\"],[\"71639.50\",\"0.000\"],[\"71641.30\",\"0.002\"],[\"75605.40\",\"0.000\"],[\"78004.30\",\"0.000\"],[\"78009.50\",\"0.009\"],[\"78589.50\",\"0.184\"],[\"78592.10\",\"0.124\"],[\"78601.50\",\"0.018\"],[\"78604.50\",\"0.290\"],[\"78680.00\",\"1.427\"],[\"78683.30\",\"5.342\"],[\"78803.50\",\"0.950\"],[\"78805.50\",\"0.000\"],[\"79171.00\",\"0.010\"],[\"79175.00\",\"3.143\"],[\"79179.00\",\"0.003\"],[\"79183.00\",\"0.000\"],[\"79201.50\",\"0.517\"],[\"79202.00\",\"0.104\"],[\"79219.40\",\"0.148\"],[\"79250.80\",\"0.000\"],[\"79456.70\",\"0.000\"],[\"79470.70\",\"0.495\"],[\"79471.30\",\"0.000\"],[\"79477.00\",\"0.000\"],[\"79477.60\",\"0.001\"],[\"79482.80\",\"0.026\"],[\"79485.60\",\"0.000\"],[\"79485.80\",\"0.652\"],[\"79486.10\",\"0.000\"],[\"79486.80\",\"0.029\"],[\"79487.20\",\"0.000\"],[\"79488.10\",\"1.544\"],[\"79489.90\",\"0.209\"],[\"79490.10\",\"0.101\"],[\"79493.20\",\"0.029\"],[\"79499.00\",\"0.041\"],[\"79499.90\",\"0.429\"],[\"79500.00\",\"3.243\"],[\"79500.20\",\"0.045\"],[\"79500.30\",\"1.206\"],[\"79500.40\",\"0.000\"],[\"79500.80\",\"0.000\"],[\"79502.40\",\"0.019\"],[\"79504.10\",\"0.076\"],[\"79505.80\",\"0.040\"],[\"79507.40\",\"0.000\"],[\"79510.70\",\"0.038\"],[\"79511.00\",\"0.000\"],[\"79511.90\",\"1.006\"],[\"79512.60\",\"0.009\"],[\"79514.60\",\"0.004\"],[\"79517.30\",\"0.041\"],[\"79518.70\",\"0.039\"],[\"79520.50\",\"0.001\"],[\"79521.10\",\"0.565\"],[\"79521.80\",\"0.440\"],[\"79521.90\",\"0.399\"],[\"79525.00\",\"0.000\"],[\"79527.40\",\"0.038\"],[\"79527.90\",\"0.097\"],[\"79528.40\",\"0.010\"],[\"79529.30\",\"0.004\"],[\"79530.20\",\"0.001\"],[\"79530.50\",\"0.003\"],[\"79531.00\",\"0.038\"],[\"79531.40\",\"0.417\"],[\"79531.90\",\"0.000\"],[\"79533.10\",\"0.032\"],[\"79533.60\",\"0.041\"],[\"79533.90\",\"0.406\"],[\"79535.10\",\"0.001\"],[\"79535.90\",\"1.466\"],[\"79536.10\",\"0.001\"],[\"79536.60\",\"0.036\"],[\"79536.70\",\"0.020\"],[\"79536.80\",\"0.042\"],[\"79536.90\",\"0.046\"],[\"79537.40\",\"0.785\"],[\"79537.80\",\"0.033\"],[\"79537.90\",\"0.238\"],[\"79539.00\",\"0.266\"],[\"79539.90\",\"3.571\"],[\"79541.00\",\"0.061\"],[\"79542.00\",\"0.001\"],[\"79542.10\",\"18.235\"],[\"79542.90\",\"0.010\"],[\"79543.30\",\"0.019\"],[\"79543.70\",\"0.018\"],[\"79544.00\",\"1.423\"],[\"79545.60\",\"0.003\"],[\"79546.00\",\"0.012\"],[\"79546.10\",\"0.000\"],[\"79548.00\",\"0.257\"],[\"79548.70\",\"0.000\"],[\"79550.20\",\"0.001\"],[\"79550.60\",\"0.002\"],[\"79551.50\",\"0.003\"],[\"79552.90\",\"0.003\"],[\"79553.20\",\"0.013\"],[\"79553.80\",\"0.000\"],[\"79556.60\",\"0.000\"],[\"79557.40\",\"0.204\"],[\"79557.90\",\"0.000\"],[\"79558.20\",\"0.001\"],[\"79558.30\",\"0.197\"],[\"79558.50\",\"0.001\"],[\"79558.90\",\"0.949\"],[\"79559.30\",\"0.003\"],[\"79559.70\",\"0.002\"],[\"79559.80\",\"0.000\"],[\"79560.00\",\"0.025\"],[\"79560.20\",\"0.006\"],[\"79560.40\",\"0.000\"],[\"79560.50\",\"0.616\"],[\"79561.60\",\"0.002\"],[\"79561.90\",\"0.015\"],[\"79562.00\",\"0.093\"],[\"79562.10\",\"10.001\"],[\"79562.40\",\"0.717\"],[\"79562.60\",\"0.065\"],[\"79562.70\",\"0.005\"],[\"79563.30\",\"0.122\"],[\"79564.10\",\"0.003\"],[\"79564.20\",\"0.002\"],[\"79564.80\",\"0.723\"],[\"79565.00\",\"0.009\"],[\"79565.10\",\"0.003\"],[\"79565.20\",\"0.001\"],[\"79566.50\",\"0.462\"],[\"79566.80\",\"0.000\"],[\"79566.90\",\"0.001\"],[\"79567.00\",\"0.000\"],[\"79567.50\",\"0.001\"],[\"79567.90\",\"1.388\"],[\"79568.10\",\"1.421\"],[\"79568.20\",\"0.302\"],[\"79569.00\",\"0.000\"],[\"79569.10\",\"0.046\"],[\"79569.20\",\"0.907\"],[\"79569.40\",\"0.007\"],[\"79569.70\",\"0.051\"],[\"79569.80\",\"0.083\"],[\"79570.50\",\"0.002\"],[\"79570.80\",\"0.040\"],[\"79571.50\",\"0.001\"],[\"79571.60\",\"0.013\"],[\"79571.70\",\"0.004\"],[\"79572.10\",\"0.005\"],[\"79572.70\",\"0.000\"],[\"79572.80\",\"0.199\"],[\"79574.20\",\"0.629\"],[\"79575.40\",\"0.071\"],[\"79575.50\",\"0.040\"],[\"79575.70\",\"0.015\"],[\"79575.90\",\"0.079\"],[\"79576.40\",\"0.394\"],[\"79576.70\",\"0.000\"],[\"79578.30\",\"0.691\"],[\"79578.50\",\"0.108\"],[\"79578.60\",\"0.071\"],[\"79578.70\",\"1.359\"],[\"79578.80\",\"0.728\"],[\"79579.10\",\"0.005\"],[\"79579.30\",\"0.693\"],[\"79579.50\",\"0.080\"],[\"79579.70\",\"0.834\"],[\"79579.80\",\"0.001\"],[\"79579.90\",\"0.119\"],[\"79580.10\",\"0.342\"],[\"79580.60\",\"0.630\"],[\"79580.80\",\"0.000\"],[\"79580.90\",\"0.000\"],[\"79581.30\",\"0.077\"],[\"79581.40\",\"0.004\"],[\"79581.90\",\"0.440\"],[\"79582.10\",\"0.002\"],[\"79582.20\",\"0.075\"],[\"79582.70\",\"0.076\"],[\"79582.80\",\"0.009\"],[\"79582.90\",\"0.150\"],[\"79583.40\",\"0.437\"],[\"79583.80\",\"0.001\"],[\"79584.10\",\"0.097\"],[\"79584.20\",\"0.001\"],[\"79585.20\",\"0.543\"],[\"79585.50\",\"0.462\"],[\"79585.60\",\"0.001\"],[\"79585.70\",\"0.000\"],[\"79585.90\",\"0.001\"],[\"79587.30\",\"0.293\"],[\"79587.80\",\"0.002\"],[\"79587.90\",\"0.002\"],[\"79589.50\",\"0.005\"],[\"79589.90\",\"0.252\"],[\"79590.00\",\"0.508\"],[\"79591.00\",\"0.002\"],[\"79591.60\",\"0.005\"],[\"79592.30\",\"0.014\"],[\"79592.50\",\"0.098\"],[\"79592.90\",\"0.040\"],[\"79593.00\",\"0.002\"],[\"79593.30\",\"0.002\"],[\"79593.40\",\"0.004\"],[\"79593.50\",\"0.003\"],[\"79593.60\",\"0.081\"],[\"79594.70\",\"0.004\"],[\"79595.10\",\"0.002\"],[\"79595.20\",\"0.002\"],[\"79595.30\",\"0.000\"],[\"79595.50\",\"0.433\"],[\"79595.60\",\"0.029\"],[\"79596.00\",\"0.030\"],[\"79596.10\",\"0.005\"],[\"79596.20\",\"1.064\"],[\"79596.30\",\"0.031\"],[\"79596.50\",\"0.000\"],[\"79596.70\",\"0.001\"],[\"79596.80\",\"0.000\"],[\"79597.50\",\"0.002\"],[\"79597.60\",\"0.002\"],[\"79598.00\",\"0.004\"],[\"79598.10\",\"0.000\"],[\"79598.40\",\"0.006\"],[\"79598.50\",\"0.000\"],[\"79598.60\",\"1.252\"],[\"79598.70\",\"0.002\"],[\"79599.10\",\"0.001\"],[\"79599.20\",\"0.081\"],[\"79599.30\",\"1.607\"],[\"79599.40\",\"0.004\"],[\"79599.50\",\"3.879\"],[\"79599.60\",\"0.037\"],[\"79599.70\",\"0.000\"],[\"79599.80\",\"0.027\"],[\"79599.90\",\"0.000\"],[\"79600.00\",\"0.080\"],[\"79600.10\",\"0.026\"],[\"79600.20\",\"0.000\"],[\"79600.30\",\"0.000\"],[\"79600.40\",\"0.000\"],[\"79600.50\",\"0.000\"],[\"79600.60\",\"0.000\"],[\"79600.70\",\"0.041\"],[\"79600.90\",\"0.000\"],[\"79601.00\",\"0.000\"],[\"79601.10\",\"0.000\"],[\"79601.20\",\"0.001\"],[\"79601.30\",\"0.001\"],[\"79601.40\",\"0.006\"],[\"79601.50\",\"10.586\"]],\"a\":[[\"79599.60\",\"0.000\"],[\"79599.70\",\"0.000\"],[\"79599.80\",\"0.000\"],[\"79599.90\",\"0.000\"],[\"79600.00\",\"0.000\"],[\"79600.10\",\"0.000\"],[\"79600.20\",\"0.000\"],[\"79600.30\",\"0.000\"],[\"79600.40\",\"0.000\"],[\"79600.50\",\"0.000\"],[\"79600.60\",\"0.000\"],[\"79600.70\",\"0.000\"],[\"79600.80\",\"0.000\"],[\"79601.00\",\"0.000\"],[\"79601.10\",\"0.000\"],[\"79601.20\",\"0.000\"],[\"79601.30\",\"0.000\"],[\"79601.40\",\"0.000\"],[\"79601.50\",\"0.000\"],[\"79601.60\",\"4.470\"],[\"79601.70\",\"0.059\"],[\"79601.80\",\"0.000\"],[\"79601.90\",\"0.027\"],[\"79602.00\",\"0.039\"],[\"79602.10\",\"0.344\"],[\"79602.20\",\"1.606\"],[\"79602.30\",\"0.000\"],[\"79602.40\",\"0.000\"],[\"79602.50\",\"0.002\"],[\"79602.80\",\"0.000\"],[\"79602.90\",\"0.002\"],[\"79603.00\",\"0.076\"],[\"79603.10\",\"0.000\"],[\"79603.20\",\"0.003\"],[\"79603.30\",\"0.003\"],[\"79603.40\",\"0.278\"],[\"79603.50\",\"0.026\"],[\"79603.70\",\"0.028\"],[\"79603.80\",\"0.027\"],[\"79603.90\",\"0.027\"],[\"79604.00\",\"0.030\"],[\"79604.10\",\"0.105\"],[\"79604.20\",\"0.565\"],[\"79604.30\",\"0.566\"],[\"79604.50\",\"0.000\"],[\"79604.60\",\"0.001\"],[\"79604.70\",\"0.002\"],[\"79604.80\",\"0.000\"],[\"79604.90\",\"2.819\"],[\"79605.00\",\"0.007\"],[\"79605.10\",\"2.190\"],[\"79605.20\",\"0.082\"],[\"79605.40\",\"0.027\"],[\"79605.50\",\"0.026\"],[\"79605.60\",\"0.002\"],[\"79605.70\",\"0.010\"],[\"79605.80\",\"0.000\"],[\"79605.90\",\"0.000\"],[\"79606.00\",\"0.002\"],[\"79606.10\",\"0.003\"],[\"79606.20\",\"1.606\"],[\"79606.30\",\"0.076\"],[\"79606.40\",\"0.000\"],[\"79606.50\",\"0.011\"],[\"79606.60\",\"0.011\"],[\"79606.70\",\"0.000\"],[\"79606.80\",\"0.005\"],[\"79606.90\",\"0.137\"],[\"79607.00\",\"0.225\"],[\"79607.20\",\"0.334\"],[\"79607.40\",\"0.152\"],[\"79607.60\",\"2.218\"],[\"79607.80\",\"1.006\"],[\"79608.00\",\"1.124\"],[\"79608.30\",\"0.001\"],[\"79608.90\",\"0.000\"],[\"79609.20\",\"0.101\"],[\"79609.30\",\"0.226\"],[\"79609.40\",\"0.129\"],[\"79609.50\",\"1.229\"],[\"79609.60\",\"2.977\"],[\"79609.80\",\"0.884\"],[\"79609.90\",\"0.002\"],[\"79610.40\",\"0.001\"],[\"79610.50\",\"0.064\"],[\"79610.80\",\"0.002\"],[\"79610.90\",\"0.000\"],[\"79611.00\",\"1.707\"],[\"79611.10\",\"0.538\"],[\"79611.20\",\"0.097\"],[\"79612.00\",\"0.003\"],[\"79612.20\",\"0.132\"],[\"79612.30\",\"1.256\"],[\"79612.50\",\"0.004\"],[\"79612.60\",\"0.565\"],[\"79612.70\",\"0.252\"],[\"79613.00\",\"0.000\"],[\"79613.10\",\"0.003\"],[\"79613.70\",\"0.442\"],[\"79614.00\",\"0.138\"],[\"79614.10\",\"0.260\"],[\"79614.40\",\"0.638\"],[\"79614.80\",\"0.003\"],[\"79615.10\",\"0.952\"],[\"79616.40\",\"0.373\"],[\"79616.60\",\"0.005\"],[\"79616.70\",\"2.157\"],[\"79616.80\",\"0.037\"],[\"79617.00\",\"0.000\"],[\"79617.70\",\"0.049\"],[\"79618.80\",\"0.128\"],[\"79618.90\",\"0.000\"],[\"79619.00\",\"0.197\"],[\"79619.20\",\"0.001\"],[\"79619.30\",\"0.401\"],[\"79619.40\",\"1.892\"],[\"79619.50\",\"0.003\"],[\"79619.90\",\"0.006\"],[\"79620.10\",\"0.454\"],[\"79620.40\",\"0.128\"],[\"79620.50\",\"1.403\"],[\"79620.70\",\"0.004\"],[\"79621.10\",\"0.002\"],[\"79621.20\",\"0.025\"],[\"79621.90\",\"0.035\"],[\"79622.10\",\"0.641\"],[\"79622.30\",\"0.001\"],[\"79622.40\",\"0.042\"],[\"79622.70\",\"0.063\"],[\"79622.80\",\"0.011\"],[\"79623.50\",\"0.001\"],[\"79623.70\",\"0.003\"],[\"79623.80\",\"0.023\"],[\"79624.00\",\"0.004\"],[\"79624.20\",\"0.023\"],[\"79624.50\",\"0.478\"],[\"79624.60\",\"0.029\"],[\"79624.70\",\"1.068\"],[\"79625.10\",\"0.120\"],[\"79625.50\",\"0.061\"],[\"79625.60\",\"0.163\"],[\"79625.80\",\"0.635\"],[\"79626.40\",\"0.546\"],[\"79626.60\",\"0.647\"],[\"79626.70\",\"0.004\"],[\"79627.20\",\"0.011\"],[\"79627.50\",\"0.040\"],[\"79627.70\",\"0.003\"],[\"79628.20\",\"0.210\"],[\"79628.30\",\"0.000\"],[\"79629.50\",\"0.263\"],[\"79629.90\",\"0.001\"],[\"79630.00\",\"0.935\"],[\"79630.20\",\"0.005\"],[\"79630.30\",\"0.199\"],[\"79630.50\",\"0.140\"],[\"79630.70\",\"0.051\"],[\"79630.90\",\"0.072\"],[\"79631.30\",\"0.000\"],[\"79631.50\",\"0.781\"],[\"79631.80\",\"0.127\"],[\"79632.30\",\"0.001\"],[\"79632.40\",\"0.077\"],[\"79632.50\",\"0.072\"],[\"79632.70\",\"1.072\"],[\"79633.00\",\"0.239\"],[\"79633.30\",\"0.003\"],[\"79633.50\",\"10.034\"],[\"79633.60\",\"0.003\"],[\"79633.70\",\"0.507\"],[\"79633.80\",\"2.427\"],[\"79634.30\",\"0.056\"],[\"79634.80\",\"0.000\"],[\"79635.60\",\"0.002\"],[\"79636.30\",\"0.003\"],[\"79638.30\",\"0.050\"],[\"79638.80\",\"0.030\"],[\"79638.90\",\"0.001\"],[\"79639.20\",\"0.201\"],[\"79639.40\",\"0.004\"],[\"79641.20\",\"0.293\"],[\"79641.40\",\"0.001\"],[\"79641.50\",\"0.269\"],[\"79642.00\",\"0.001\"],[\"79642.10\",\"0.003\"],[\"79644.40\",\"0.086\"],[\"79644.70\",\"0.000\"],[\"79647.20\",\"0.002\"],[\"79647.40\",\"0.001\"],[\"79648.10\",\"0.005\"],[\"79648.50\",\"0.038\"],[\"79648.80\",\"0.973\"],[\"79649.10\",\"0.016\"],[\"79649.40\",\"0.033\"],[\"79649.60\",\"0.070\"],[\"79649.90\",\"0.001\"],[\"79650.20\",\"0.002\"],[\"79650.90\",\"0.002\"],[\"79652.70\",\"0.000\"],[\"79653.30\",\"0.001\"],[\"79655.20\",\"0.038\"],[\"79656.70\",\"0.000\"],[\"79659.00\",\"0.321\"],[\"79659.30\",\"0.010\"],[\"79660.20\",\"0.437\"],[\"79661.40\",\"0.000\"],[\"79661.50\",\"0.000\"],[\"79662.50\",\"0.000\"],[\"79663.20\",\"0.002\"],[\"79663.50\",\"0.018\"],[\"79663.90\",\"0.000\"],[\"79664.10\",\"0.059\"],[\"79664.50\",\"0.003\"],[\"79665.20\",\"0.005\"],[\"79665.30\",\"0.083\"],[\"79665.90\",\"5.651\"],[\"79666.10\",\"0.002\"],[\"79668.20\",\"4.765\"],[\"79668.30\",\"0.238\"],[\"79668.50\",\"0.007\"],[\"79668.60\",\"1.435\"],[\"79669.40\",\"8.787\"],[\"79670.60\",\"0.211\"],[\"79671.50\",\"26.486\"],[\"79672.00\",\"0.047\"],[\"79672.60\",\"0.002\"],[\"79673.40\",\"0.000\"],[\"79674.20\",\"0.001\"],[\"79676.80\",\"1.535\"],[\"79676.90\",\"0.204\"],[\"79677.10\",\"0.450\"],[\"79677.20\",\"0.000\"],[\"79682.40\",\"0.120\"],[\"79683.20\",\"0.745\"],[\"79687.70\",\"0.009\"],[\"79694.40\",\"0.013\"],[\"79695.70\",\"0.002\"],[\"79700.40\",\"0.000\"],[\"79700.70\",\"0.005\"],[\"79700.80\",\"0.040\"],[\"79702.20\",\"0.251\"],[\"79721.00\",\"0.000\"],[\"79723.00\",\"0.613\"],[\"79724.40\",\"0.000\"],[\"79725.70\",\"0.000\"],[\"79730.40\",\"0.012\"],[\"79735.40\",\"0.006\"],[\"79740.20\",\"0.006\"],[\"79740.40\",\"0.287\"],[\"79748.40\",\"0.005\"],[\"79762.80\",\"0.126\"],[\"79772.20\",\"0.003\"],[\"79785.30\",\"0.436\"],[\"79785.40\",\"0.001\"],[\"79785.50\",\"0.000\"],[\"79807.10\",\"1.194\"],[\"79807.20\",\"0.000\"],[\"79807.30\",\"0.427\"],[\"79807.40\",\"0.008\"],[\"79829.30\",\"0.426\"],[\"79829.40\",\"0.000\"],[\"79947.80\",\"0.619\"],[\"79949.80\",\"0.712\"],[\"79960.20\",\"0.000\"],[\"79993.90\",\"0.309\"],[\"79995.60\",\"0.777\"],[\"79997.60\",\"0.992\"],[\"79998.00\",\"0.710\"],[\"79999.60\",\"0.443\"],[\"80008.90\",\"0.000\"],[\"80017.50\",\"0.094\"],[\"80395.60\",\"1.430\"],[\"80396.10\",\"0.000\"],[\"80397.60\",\"0.000\"],[\"80398.20\",\"0.494\"],[\"80515.50\",\"0.000\"],[\"80517.60\",\"17.714\"],[\"80556.60\",\"0.991\"],[\"80595.10\",\"0.000\"],[\"80597.20\",\"6.754\"],[\"81188.20\",\"0.001\"],[\"81188.30\",\"0.012\"],[\"87559.60\",\"0.000\"]],\"st\":1}}"}
{"receive_ns":1788563755196700000,"stream":"btcusdt@depth@100ms","event_type":"depthUpdate","event_time_ms":1788563745491,"raw_json":"{\"stream\":\"btcusdt@depth@100ms\",\"data\":{\"e\":\"depthUpdate\",\"E\":1788563745491,\"T\":1788563745490,\"s\":\"BTCUSDT\",\"ps\":\"BTCUSDT\",\"U\":11478251777445,\"u\":11478251782553,\"pu\":11478251777376,\"b\":[[\"29101.50\",\"0.336\"],[\"29199.50\",\"1.099\"],[\"71641.30\",\"0.002\"],[\"76417.40\",\"0.002\"],[\"78680.00\",\"0.672\"],[\"78683.40\",\"0.755\"],[\"78803.50\",\"1.900\"],[\"78805.50\",\"0.000\"],[\"79369.90\",\"1.364\"],[\"79471.00\",\"0.000\"],[\"79471.10\",\"0.001\"],[\"79505.90\",\"0.220\"],[\"79511.40\",\"0.000\"],[\"79511.50\",\"0.022\"],[\"79511.90\",\"0.001\"],[\"79523.10\",\"0.020\"],[\"79525.10\",\"0.063\"],[\"79536.60\",\"0.035\"],[\"79539.90\",\"0.002\"],[\"79542.00\",\"0.002\"],[\"79543.80\",\"1.007\"],[\"79549.40\",\"2.344\"],[\"79560.50\",\"0.193\"],[\"79565.80\",\"0.000\"],[\"79569.70\",\"0.052\"],[\"79571.50\",\"0.077\"],[\"79574.60\",\"1.338\"],[\"79581.30\",\"0.001\"],[\"79581.60\",\"0.041\"],[\"79582.70\",\"0.000\"],[\"79582.80\",\"0.003\"],[\"79585.40\",\"0.080\"],[\"79586.40\",\"0.162\"],[\"79595.30\",\"0.000\"],[\"79595.50\",\"0.459\"],[\"79597.30\",\"0.002\"],[\"79597.90\",\"0.253\"],[\"79598.00\",\"0.002\"],[\"79598.40\",\"0.007\"],[\"79598.60\",\"1.000\"],[\"79599.20\",\"0.001\"],[\"79599.50\",\"2.432\"],[\"79599.70\",\"0.026\"],[\"79599.80\",\"0.027\"],[\"79599.90\",\"0.026\"],[\"79600.10\",\"0.000\"],[\"79600.70\",\"0.015\"],[\"79600.80\",\"0.080\"],[\"79601.50\",\"12.136\"]],\"a\":[[\"79601.60\",\"4.473\"],[\"79601.70\",\"0.061\"],[\"79601.80\",\"0.101\"],[\"79601.90\",\"0.026\"],[\"79604.70\",\"0.004\"],[\"79609.50\",\"1.229\"],[\"79610.90\",\"0.317\"],[\"79612.10\",\"0.392\"],[\"79612.20\",\"0.190\"],[\"79612.30\",\"0.881\"],[\"79612.90\",\"0.248\"],[\"79616.40\",\"0.001\"],[\"79617.90\",\"0.373\"],[\"79621.30\",\"0.008\"],[\"79623.80\",\"0.003\"],[\"79624.40\",\"0.000\"],[\"79627.60\",\"0.012\"],[\"79627.90\",\"0.080\"],[\"79630.30\",\"0.219\"],[\"79633.40\",\"0.002\"],[\"79648.30\",\"0.428\"],[\"79650.60\",\"0.000\"],[\"79652.60\",\"0.050\"],[\"79656.00\",\"0.043\"],[\"79659.20\",\"0.314\"],[\"79664.00\",\"0.020\"],[\"79665.90\",\"5.652\"],[\"79666.10\",\"26.486\"],[\"79671.50\",\"0.001\"],[\"79679.50\",\"0.002\"],[\"80371.30\",\"2.298\"],[\"80397.60\",\"0.000\"],[\"80397.80\",\"7.964\"],[\"80707.90\",\"3.091\"],[\"80777.40\",\"5.002\"]],\"st\":1}}"}
{"receive_ns":1788563755327538000,"stream":"btcusdt@depth@100ms","event_type":"depthUpdate","event_time_ms":1788563745593,"raw_json":"{\"stream\":\"btcusdt@depth@100ms\",\"data\":{\"e\":\"depthUpdate\",\"E\":1788563745593,\"T\":1788563745592,\"s\":\"BTCUSDT\",\"ps\":\"BTCUSDT\",\"U\":11478251782563,\"u\":11478251786861,\"pu\":11478251782553,\"b\":[[\"1000.00\",\"24.754\"],[\"29101.50\",\"0.511\"],[\"29199.50\",\"0.924\"],[\"63681.20\",\"0.000\"],[\"71641.30\",\"0.002\"],[\"76417.40\",\"0.000\"],[\"78805.50\",\"0.002\"],[\"79219.40\",\"0.148\"],[\"79471.80\",\"0.001\"],[\"79488.10\",\"1.776\"],[\"79506.00\",\"1.828\"],[\"79527.80\",\"0.001\"],[\"79539.40\",\"0.070\"],[\"79543.70\",\"0.018\"],[\"79563.10\",\"0.548\"],[\"79563.60\",\"1.384\"],[\"79582.80\",\"0.001\"],[\"79583.20\",\"0.001\"],[\"79583.60\",\"0.000\"],[\"79584.40\",\"0.262\"],[\"79586.50\",\"0.004\"],[\"79588.50\",\"0.081\"],[\"79589.70\",\"0.253\"],[\"79593.70\",\"0.133\"],[\"79595.50\",\"0.000\"],[\"79595.60\",\"0.003\"],[\"79595.70\",\"0.001\"],[\"79595.80\",\"0.000\"],[\"79595.90\",\"0.059\"],[\"79596.10\",\"0.006\"],[\"79596.40\",\"0.001\"],[\"79599.20\",\"0.029\"],[\"79599.30\",\"1.627\"],[\"79599.50\",\"2.423\"],[\"79600.10\",\"0.026\"],[\"79600.20\",\"0.000\"],[\"79600.30\",\"0.000\"],[\"79600.90\",\"0.000\"],[\"79601.00\",\"0.000\"],[\"79601.20\",\"0.003\"],[\"79601.30\",\"0.007\"],[\"79601.50\",\"12.151\"]],\"a\":[[\"79601.60\",\"4.501\"],[\"79601.70\",\"0.035\"],[\"79602.00\",\"0.040\"],[\"79603.90\",\"0.026\"],[\"79604.00\",\"0.029\"],[\"79604.10\",\"0.374\"],[\"79606.90\",\"0.088\"],[\"79607.00\",\"0.379\"],[\"79609.40\",\"0.003\"],[\"79610.10\",\"0.066\"],[\"79610.90\",\"0.400\"],[\"79611.60\",\"0.090\"],[\"79611.70\",\"0.004\"],[\"79611.90\",\"0.351\"],[\"79612.00\",\"0.006\"],[\"79612.20\",\"0.288\"],[\"79612.40\",\"1.803\"],[\"79612.50\",\"0.424\"],[\"79612.80\",\"4.813\"],[\"79613.70\",\"0.445\"],[\"79618.80\",\"0.002\"],[\"79620.40\",\"0.002\"],[\"79622.40\",\"0.043\"],[\"79625.00\",\"0.005\"],[\"79627.20\",\"0.010\"],[\"79630.30\",\"0.199\"],[\"79631.40\",\"0.023\"],[\"79631.80\",\"0.001\"],[\"79632.60\",\"0.000\"],[\"79638.60\",\"1.382\"],[\"79653.10\",\"0.006\"],[\"79655.40\",\"2.958\"],[\"79656.90\",\"0.004\"],[\"79658.70\",\"0.420\"],[\"79659.20\",\"0.069\"],[\"79662.00\",\"0.001\"],[\"79666.20\",\"0.225\"],[\"79667.00\",\"0.224\"],[\"79669.80\",\"0.224\"],[\"79670.10\",\"0.249\"],[\"79680.30\",\"0.269\"],[\"79680.90\",\"0.068\"],[\"79683.60\",\"0.090\"],[\"79690.30\",\"0.000\"],[\"79690.50\",\"0.211\"],[\"79695.70\",\"0.000\"],[\"79947.80\",\"0.419\"],[\"79949.80\",\"0.461\"],[\"79949.90\",\"0.252\"],[\"79993.90\",\"0.188\"],[\"79995.60\",\"1.067\"],[\"79997.60\",\"0.902\"],[\"79999.60\",\"0.243\"],[\"80397.60\",\"0.000\"],[\"81193.60\",\"0.003\"]],\"st\":1}}"}
{"receive_ns":1788563755448371000,"stream":"btcusdt@depth@100ms","event_type":"depthUpdate","event_time_ms":1788563745695,"raw_json":"{\"stream\":\"btcusdt@depth@100ms\",\"data\":{\"e\":\"depthUpdate\",\"E\":1788563745695,\"T\":1788563745694,\"s\":\"BTCUSDT\",\"ps\":\"BTCUSDT\",\"U\":11478251786890,\"u\":11478251791754,\"pu\":11478251786861,\"b\":[[\"1000.00\",\"24.754\"],[\"29101.50\",\"0.693\"],[\"29199.50\",\"0.742\"],[\"71641.30\",\"0.002\"],[\"76417.40\",\"0.002\"],[\"78253.80\",\"2.807\"],[\"78604.50\",\"0.506\"],[\"78683.30\",\"4.587\"],[\"78683.40\",\"1.510\"],[\"78803.50\",\"2.534\"],[\"78805.50\",\"0.000\"],[\"78883.80\",\"0.001\"],[\"78889.10\",\"1.112\"],[\"79201.50\",\"0.517\"],[\"79471.00\",\"10.198\"],[\"79510.00\",\"0.668\"],[\"79511.40\",\"6.119\"],[\"79511.90\",\"1.006\"],[\"79539.90\",\"3.571\"],[\"79559.30\",\"0.001\"],[\"79560.40\",\"0.446\"],[\"79575.80\",\"0.000\"],[\"79577.80\",\"0.002\"],[\"79581.30\",\"0.271\"],[\"79584.80\",\"0.002\"],[\"79585.00\",\"0.194\"],[\"79586.40\",\"0.002\"],[\"79595.60\",\"0.029\"],[\"79595.70\",\"0.027\"],[\"79595.80\",\"0.026\"],[\"79595.90\",\"0.085\"],[\"79596.20\",\"1.045\"],[\"79599.40\",\"0.003\"],[\"79599.50\",\"0.670\"],[\"79599.70\",\"0.000\"],[\"79599.80\",\"0.001\"],[\"79599.90\",\"0.000\"],[\"79600.00\",\"0.106\"],[\"79600.10\",\"0.000\"],[\"79601.40\",\"0.007\"],[\"79601.50\",\"12.812\"]],\"a\":[[\"79601.60\",\"4.500\"],[\"79602.00\",\"0.379\"],[\"79604.00\",\"0.030\"],[\"79604.10\",\"0.106\"],[\"79606.90\",\"0.214\"],[\"79607.00\",\"0.225\"],[\"79607.60\",\"1.008\"],[\"79609.40\",\"0.508\"],[\"79609.60\",\"4.187\"],[\"79610.90\",\"0.083\"],[\"79612.20\",\"0.352\"],[\"79612.30\",\"1.291\"],[\"79612.60\",\"0.975\"],[\"79612.70\",\"0.652\"],[\"79612.90\",\"0.430\"],[\"79615.70\",\"0.548\"],[\"79616.60\",\"0.003\"],[\"79617.70\",\"0.051\"],[\"79619.00\",\"0.323\"],[\"79620.40\",\"0.128\"],[\"79620.80\",\"0.378\"],[\"79630.30\",\"0.289\"],[\"79631.80\",\"0.127\"],[\"79641.20\",\"0.203\"],[\"79658.70\",\"0.000\"],[\"79659.40\",\"0.400\"],[\"79660.20\",\"0.077\"],[\"79663.70\",\"0.410\"],[\"79666.10\",\"26.420\"],[\"79668.80\",\"0.000\"],[\"79669.90\",\"0.410\"],[\"79670.50\",\"0.393\"],[\"79674.10\",\"0.017\"],[\"79674.20\",\"0.001\"],[\"79674.40\",\"0.005\"],[\"79682.40\",\"0.059\"],[\"79999.60\",\"0.443\"],[\"80315.00\",\"0.186\"],[\"80320.30\",\"0.016\"],[\"80397.60\",\"0.000\"],[\"80437.30\",\"0.682\"],[\"80771.60\",\"0.432\"]],\"st\":1}}"}
{"receive_ns":1788563755552019000,"stream":"btcusdt@depth@100ms","event_type":"depthUpdate","event_time_ms":1788563745797,"raw_json":"{\"stream\":\"btcusdt@depth@100ms\",\"data\":{\"e\":\"depthUpdate\",\"E\":1788563745797,\"T\":1788563745795,\"s\":\"BTCUSDT\",\"ps\":\"BTCUSDT\",\"U\":11478251791798,\"u\":11478251795860,\"pu\":11478251791754,\"b\":[[\"29101.50\",\"0.868\"],[\"29199.50\",\"0.567\"],[\"71641.30\",\"0.002\"],[\"71675.00\",\"0.002\"],[\"78588.60\",\"0.256\"],[\"78591.80\",\"0.006\"],[\"78603.00\",\"0.010\"],[\"78605.30\",\"0.004\"],[\"78614.20\",\"0.657\"],[\"78618.90\",\"0.002\"],[\"78805.50\",\"0.000\"],[\"78869.40\",\"0.002\"],[\"79043.80\",\"0.000\"],[\"79081.00\",\"0.002\"],[\"79086.30\",\"0.008\"],[\"79203.50\",\"0.142\"],[\"79218.20\",\"0.000\"],[\"79218.90\",\"0.979\"],[\"79219.40\",\"0.007\"],[\"79278.70\",\"0.001\"],[\"79284.00\",\"0.010\"],[\"79337.50\",\"0.004\"],[\"79339.20\",\"0.315\"],[\"79463.60\",\"0.009\"],[\"79465.10\",\"0.020\"],[\"79476.90\",\"0.000\"],[\"79482.20\",\"0.003\"],[\"79488.10\",\"2.781\"],[\"79506.00\",\"0.321\"],[\"79511.90\",\"1.508\"],[\"79539.80\",\"0.034\"],[\"79594.80\",\"0.254\"],[\"79595.60\",\"0.003\"],[\"79595.70\",\"0.001\"],[\"79597.40\",\"0.252\"],[\"79597.90\",\"0.001\"],[\"79599.40\",\"0.002\"],[\"79599.50\",\"0.669\"],[\"79600.20\",\"0.026\"],[\"79600.40\",\"0.026\"],[\"79600.50\",\"0.026\"],[\"79600.70\",\"0.003\"],[\"79601.50\",\"13.934\"]],\"a\":[[\"79601.60\",\"4.499\"],[\"79604.10\",\"0.106\"],[\"79604.80\",\"0.269\"],[\"79606.90\",\"0.011\"],[\"79609.40\",\"0.382\"],[\"79612.20\",\"0.226\"],[\"79612.40\",\"1.804\"],[\"79615.20\",\"0.002\"],[\"79619.00\",\"0.197\"],[\"79620.40\",\"0.002\"],[\"79624.20\",\"0.021\"],[\"79631.80\",\"0.001\"],[\"79632.10\",\"0.000\"],[\"79632.80\",\"0.659\"],[\"79659.40\",\"0.000\"],[\"79666.10\",\"0.001\"],[\"79674.10\",\"0.020\"],[\"79674.20\",\"26.420\"],[\"79674.40\",\"0.002\"],[\"79683.20\",\"0.649\"],[\"79702.20\",\"0.126\"],[\"79702.30\",\"0.126\"],[\"79715.60\",\"0.000\"],[\"79720.90\",\"0.002\"],[\"79722.60\",\"0.007\"],[\"79735.40\",\"0.012\"],[\"79821.70\",\"0.000\"],[\"79823.20\",\"0.004\"],[\"79833.30\",\"0.560\"],[\"79835.50\",\"0.000\"],[\"79914.90\",\"0.000\"],[\"79920.20\",\"0.362\"],[\"79947.80\",\"0.000\"],[\"79949.80\",\"0.210\"],[\"79949.90\",\"0.001\"],[\"79952.20\",\"0.202\"],[\"79955.50\",\"0.017\"],[\"79987.60\",\"0.673\"],[\"79987.70\",\"0.411\"],[\"79995.60\",\"1.593\"],[\"79997.60\",\"0.376\"],[\"80114.70\",\"0.000\"],[\"80120.00\",\"0.937\"],[\"80131.60\",\"0.000\"],[\"80397.60\",\"0.000\"],[\"80795.60\",\"12.870\"],[\"80835.40\",\"0.859\"]],\"st\":1}}"}
{"receive_ns":1788563755744358000,"stream":"btcusdt@depth@100ms","event_type":"depthUpdate","event_time_ms":1788563745899,"raw_json":"{\"stream\":\"btcusdt@depth@100ms\",\"data\":{\"e\":\"depthUpdate\",\"E\":1788563745899,\"T\":1788563745898,\"s\":\"BTCUSDT\",\"ps\":\"BTCUSDT\",\"U\":11478251795903,\"u\":11478251799345,\"pu\":11478251795860,\"b\":[[\"1000.00\",\"24.754\"],[\"29101.50\",\"1.050\"],[\"29199.50\",\"0.385\"],[\"71641.30\",\"0.002\"],[\"76417.40\",\"0.000\"],[\"78451.80\",\"58.683\"],[\"78569.30\",\"0.002\"],[\"78796.00\",\"0.696\"],[\"78805.50\",\"0.000\"],[\"78827.50\",\"0.691\"],[\"78829.70\",\"0.000\"],[\"78829.80\",\"4.245\"],[\"78888.10\",\"0.648\"],[\"79000.10\",\"0.212\"],[\"79043.90\",\"0.128\"],[\"79201.50\",\"0.516\"],[\"79218.30\",\"0.000\"],[\"79337.60\",\"0.000\"],[\"79470.70\",\"0.001\"],[\"79471.10\",\"0.485\"],[\"79510.00\",\"0.342\"],[\"79511.90\",\"0.754\"],[\"79543.80\",\"1.082\"],[\"79578.30\",\"0.000\"],[\"79581.50\",\"0.007\"],[\"79582.20\",\"0.071\"],[\"79599.20\",\"0.028\"],[\"79599.50\",\"0.151\"],[\"79600.10\",\"0.126\"],[\"79601.30\",\"0.008\"],[\"79601.50\",\"14.442\"]],\"a\":[[\"79601.60\",\"5.707\"],[\"79604.80\",\"0.000\"],[\"79639.60\",\"0.470\"],[\"79666.10\",\"26.420\"],[\"79666.20\",\"0.001\"],[\"79667.00\",\"0.000\"],[\"79668.60\",\"0.606\"],[\"79674.10\",\"0.017\"],[\"79674.20\",\"0.001\"],[\"79674.40\",\"0.005\"],[\"79683.60\",\"0.000\"],[\"79718.00\",\"0.196\"],[\"79723.00\",\"0.186\"],[\"79723.10\",\"0.429\"],[\"79835.40\",\"0.000\"],[\"79836.80\",\"3.632\"],[\"79955.40\",\"0.001\"],[\"79995.60\",\"1.793\"],[\"79999.60\",\"0.243\"],[\"79999.70\",\"0.002\"],[\"79999.90\",\"10.724\"],[\"80099.90\",\"10.442\"],[\"80348.20\",\"0.000\"],[\"80397.60\",\"0.000\"],[\"80615.50\",\"1.719\"],[\"80795.60\",\"12.012\"]],\"st\":1}}"}
{"receive_ns":1788563755829822000,"stream":"btcusdt@depth@100ms","event_type":"depthUpdate","event_time_ms":1788563746001,"raw_json":"{\"stream\":\"btcusdt@depth@100ms\",\"data\":{\"e\":\"depthUpdate\",\"E\":1788563746001,\"T\":1788563745999,\"s\":\"BTCUSDT\",\"ps\":\"BTCUSDT\",\"U\":11478251799404,\"u\":11478251804270,\"pu\":11478251799345,\"b\":[[\"1000.00\",\"24.754\"],[\"29101.50\",\"1.127\"],[\"29199.50\",\"0.259\"],[\"29501.50\",\"0.049\"],[\"71641.30\",\"0.002\"],[\"76417.40\",\"0.002\"],[\"78009.50\",\"0.012\"],[\"78604.50\",\"0.722\"],[\"78683.30\",\"3.832\"],[\"78683.40\",\"0.000\"],[\"78685.30\",\"2.265\"],[\"78805.50\",\"0.000\"],[\"79201.50\",\"0.505\"],[\"79203.50\",\"0.011\"],[\"79471.10\",\"0.001\"],[\"79471.20\",\"0.484\"],[\"79488.10\",\"1.544\"],[\"79506.00\",\"1.025\"],[\"79511.90\",\"0.252\"],[\"79557.20\",\"2.114\"],[\"79567.80\",\"0.109\"],[\"79570.40\",\"1.364\"],[\"79576.00\",\"0.004\"],[\"79579.50\",\"0.004\"],[\"79583.60\",\"0.002\"],[\"79584.00\",\"0.007\"],[\"79594.80\",\"0.002\"],[\"79595.10\",\"0.001\"],[\"79595.80\",\"0.000\"],[\"79596.20\",\"1.026\"],[\"79596.80\",\"0.000\"],[\"79597.40\",\"0.000\"],[\"79599.50\",\"0.146\"],[\"79600.00\",\"0.107\"],[\"79600.50\",\"0.000\"],[\"79600.70\",\"0.000\"],[\"79601.30\",\"0.007\"],[\"79601.50\",\"13.918\"]],\"a\":[[\"79601.60\",\"6.241\"],[\"79604.00\",\"0.029\"],[\"79604.10\",\"0.106\"],[\"79604.20\",\"0.566\"],[\"79604.40\",\"0.253\"],[\"79607.60\",\"1.109\"],[\"79609.20\",\"0.000\"],[\"79612.50\",\"0.423\"],[\"79619.60\",\"0.008\"],[\"79621.30\",\"0.002\"],[\"79623.90\",\"1.298\"],[\"79627.80\",\"2.002\"],[\"79627.90\",\"0.000\"],[\"79629.90\",\"0.081\"],[\"79633.50\",\"0.034\"],[\"79639.10\",\"0.458\"],[\"79660.00\",\"1.030\"],[\"79663.70\",\"0.000\"],[\"79666.10\",\"0.001\"],[\"79669.80\",\"0.000\"],[\"79670.10\",\"0.039\"],[\"79674.20\",\"26.420\"],[\"79723.10\",\"0.429\"],[\"79735.40\",\"0.000\"],[\"79987.60\",\"0.003\"],[\"79987.70\",\"0.160\"],[\"79995.60\",\"0.213\"],[\"80397.60\",\"0.000\"],[\"80676.20\",\"0.511\"],[\"80795.60\",\"1.804\"],[\"80835.40\",\"11.021\"]],\"st\":1}}"}
{"receive_ns":1788563755995436000,"stream":"btcusdt@depth@100ms","event_type":"depthUpdate","event_time_ms":1788563746103,"raw_json":"{\"stream\":\"btcusdt@depth@100ms\",\"data\":{\"e\":\"depthUpdate\",\"E\":1788563746103,\"T\":1788563746101,\"s\":\"BTCUSDT\",\"ps\":\"BTCUSDT\",\"U\":11478251804458,\"u\":11478251810350,\"pu\":11478251804270,\"b\":[[\"29101.50\",\"1.197\"],[\"29199.50\",\"0.133\"],[\"29501.50\",\"0.105\"],[\"71641.30\",\"0.002\"],[\"76417.40\",\"0.000\"],[\"77896.90\",\"0.001\"],[\"78805.50\",\"0.000\"],[\"79056.70\",\"53.850\"],[\"79203.50\",\"0.152\"],[\"79231.20\",\"44.222\"],[\"79231.90\",\"6.745\"],[\"79250.80\",\"0.000\"],[\"79350.40\",\"35.337\"],[\"79427.10\",\"0.002\"],[\"79427.20\",\"3.424\"],[\"79471.10\",\"2.502\"],[\"79488.10\",\"2.781\"],[\"79506.00\",\"1.326\"],[\"79511.50\",\"1.872\"],[\"79511.90\",\"0.503\"],[\"79540.00\",\"1.337\"],[\"79543.80\",\"1.007\"],[\"79552.50\",\"0.332\"],[\"79557.20\",\"0.114\"],[\"79562.50\",\"2.352\"],[\"79565.80\",\"0.046\"],[\"79566.70\",\"0.453\"],[\"79568.00\",\"0.020\"],[\"79568.20\",\"0.332\"],[\"79569.20\",\"0.455\"],[\"79569.30\",\"1.263\"],[\"79571.50\",\"0.516\"],[\"79572.30\",\"0.044\"],[\"79574.20\",\"1.002\"],[\"79574.90\",\"0.001\"],[\"79576.00\",\"0.007\"],[\"79576.40\",\"0.021\"],[\"79577.00\",\"0.000\"],[\"79577.30\",\"0.002\"],[\"79577.40\",\"0.689\"],[\"79578.10\",\"0.000\"],[\"79578.80\",\"0.100\"],[\"79581.10\",\"0.390\"],[\"79581.90\",\"0.126\"],[\"79583.10\",\"0.104\"],[\"79583.20\",\"0.101\"],[\"79583.50\",\"0.112\"],[\"79584.10\",\"0.035\"],[\"79584.80\",\"0.162\"],[\"79585.00\",\"0.034\"],[\"79586.70\",\"0.001\"],[\"79587.20\",\"0.003\"],[\"79588.60\",\"0.251\"],[\"79589.90\",\"0.001\"],[\"79591.70\",\"0.002\"],[\"79593.00\",\"0.000\"],[\"79595.30\",\"0.026\"],[\"79595.50\",\"0.026\"],[\"79595.60\",\"0.029\"],[\"79595.70\",\"0.027\"],[\"79595.80\",\"0.026\"],[\"79596.80\",\"0.002\"],[\"79597.30\",\"0.000\"],[\"79597.50\",\"0.435\"],[\"79597.90\",\"0.027\"],[\"79598.30\",\"0.026\"],[\"79598.50\",\"0.027\"],[\"79598.90\",\"0.000\"],[\"79599.00\",\"0.001\"],[\"79599.10\",\"0.001\"],[\"79599.20\",\"0.003\"],[\"79599.30\",\"1.601\"],[\"79599.50\",\"0.115\"],[\"79600.00\",\"0.082\"],[\"79600.20\",\"0.000\"],[\"79600.40\",\"0.000\"],[\"79601.40\",\"0.006\"],[\"79601.50\",\"11.259\"]],\"a\":[[\"79601.60\",\"7.249\"],[\"79604.80\",\"0.009\"],[\"79605.00\",\"0.007\"],[\"79606.10\",\"0.009\"],[\"79606.50\",\"0.005\"],[\"79607.30\",\"0.215\"],[\"79607.50\",\"0.547\"],[\"79607.60\",\"1.008\"],[\"79607.80\",\"1.004\"],[\"79609.70\",\"0.443\"],[\"79613.70\",\"0.006\"],[\"79614.30\",\"0.374\"],[\"79616.30\",\"1.092\"],[\"79616.60\",\"0.455\"],[\"79617.90\",\"0.001\"],[\"79619.20\",\"0.021\"],[\"79620.10\",\"0.002\"],[\"79624.60\",\"0.656\"],[\"79625.80\",\"0.008\"],[\"79630.60\",\"0.047\"],[\"79633.50\",\"0.033\"],[\"79633.60\",\"0.002\"],[\"79633.80\",\"2.428\"],[\"79634.30\",\"0.010\"],[\"79636.20\",\"1.078\"],[\"79639.30\",\"0.471\"],[\"79654.40\",\"0.000\"],[\"79665.80\",\"4.785\"],[\"79666.10\",\"26.420\"],[\"79666.40\",\"0.000\"],[\"79669.90\",\"0.000\"],[\"79674.20\",\"0.001\"],[\"79690.50\",\"0.128\"],[\"79702.30\",\"0.001\"],[\"79735.40\",\"0.012\"],[\"79792.70\",\"0.000\"],[\"79792.80\",\"0.804\"],[\"79804.00\",\"0.666\"],[\"79833.30\",\"0.881\"],[\"79848.00\",\"8.116\"],[\"79848.30\",\"35.755\"],[\"79965.80\",\"0.419\"],[\"79967.70\",\"1.105\"],[\"79967.80\",\"0.451\"],[\"79968.20\",\"7.128\"],[\"79968.30\",\"45.776\"],[\"79995.60\",\"0.013\"],[\"79999.60\",\"0.769\"],[\"79999.70\",\"0.003\"],[\"80144.50\",\"56.599\"],[\"80397.60\",\"0.000\"],[\"80795.60\",\"0.074\"],[\"80835.40\",\"13.600\"]],\"st\":1}}"}
{"receive_ns":1788563756021857000,"stream":"btcusdt@depth@100ms","event_type":"depthUpdate","event_time_ms":1788563746205,"raw_json":"{\"stream\":\"btcusdt@depth@100ms\",\"data\":{\"e\":\"depthUpdate\",\"E\":1788563746205,\"T\":1788563746204,\"s\":\"BTCUSDT\",\"ps\":\"BTCUSDT\",\"U\":11478251810430,\"u\":11478251816297,\"pu\":11478251810350,\"b\":[[\"1000.00\",\"24.754\"],[\"29101.50\",\"1.246\"],[\"29199.50\",\"0.021\"],[\"29501.50\",\"0.168\"],[\"71641.30\",\"0.002\"],[\"75605.50\",\"0.000\"],[\"76417.40\",\"0.002\"],[\"78573.20\",\"12.745\"],[\"78799.40\",\"0.011\"],[\"78802.70\",\"0.252\"],[\"78805.50\",\"0.000\"],[\"78829.80\",\"1.005\"],[\"78843.00\",\"67.508\"],[\"78888.10\",\"3.240\"],[\"79000.10\",\"0.050\"],[\"79056.80\",\"0.648\"],[\"79231.30\",\"0.162\"],[\"79506.00\",\"0.321\"],[\"79509.80\",\"0.003\"],[\"79511.90\",\"1.508\"],[\"79531.30\",\"18.287\"],[\"79542.10\",\"0.029\"],[\"79552.70\",\"0.375\"],[\"79555.70\",\"0.002\"],[\"79566.70\",\"0.001\"],[\"79567.10\",\"0.076\"],[\"79568.40\",\"0.459\"],[\"79569.40\",\"0.001\"],[\"79571.50\",\"0.077\"],[\"79571.60\",\"0.088\"],[\"79574.90\",\"0.440\"],[\"79575.90\",\"0.003\"],[\"79579.30\",\"0.593\"],[\"79580.80\",\"0.004\"],[\"79580.90\",\"0.001\"],[\"79581.50\",\"0.003\"],[\"79582.60\",\"0.071\"],[\"79582.90\",\"0.250\"],[\"79583.30\",\"0.353\"],[\"79583.90\",\"0.032\"],[\"79584.70\",\"0.037\"],[\"79585.60\",\"0.033\"],[\"79589.40\",\"0.000\"],[\"79595.30\",\"0.026\"],[\"79595.50\",\"0.026\"],[\"79595.60\",\"0.029\"],[\"79596.80\",\"0.028\"],[\"79597.40\",\"0.001\"],[\"79597.60\",\"0.002\"],[\"79597.80\",\"0.001\"],[\"79597.90\",\"0.001\"],[\"79598.30\",\"0.000\"],[\"79598.40\",\"0.007\"],[\"79598.50\",\"0.000\"],[\"79598.70\",\"0.002\"],[\"79598.80\",\"0.002\"],[\"79599.00\",\"0.001\"],[\"79600.40\",\"0.002\"],[\"79601.50\",\"11.259\"]],\"a\":[[\"79601.60\",\"7.477\"],[\"79601.70\",\"0.037\"],[\"79604.10\",\"0.106\"],[\"79604.80\",\"0.015\"],[\"79605.20\",\"0.080\"],[\"79606.10\",\"0.003\"],[\"79607.60\",\"1.004\"],[\"79609.30\",\"0.000\"],[\"79609.70\",\"0.004\"],[\"79610.90\",\"0.522\"],[\"79616.60\",\"0.003\"],[\"79618.50\",\"0.454\"],[\"79630.90\",\"0.074\"],[\"79665.80\",\"1.011\"],[\"79666.10\",\"0.001\"],[\"79670.50\",\"0.211\"],[\"79674.20\",\"26.420\"],[\"79680.20\",\"0.002\"],[\"79685.30\",\"1.214\"],[\"79685.50\",\"0.018\"],[\"79687.40\",\"0.001\"],[\"79698.60\",\"0.039\"],[\"79698.70\",\"0.000\"],[\"79698.80\",\"0.000\"],[\"79698.90\",\"0.001\"],[\"79700.00\",\"0.600\"],[\"79700.10\",\"0.015\"],[\"79700.20\",\"0.547\"],[\"79702.00\",\"0.670\"],[\"79702.10\",\"0.000\"],[\"79708.10\",\"0.000\"],[\"79708.20\",\"0.001\"],[\"79713.00\",\"0.000\"],[\"79713.10\",\"0.008\"],[\"79968.20\",\"7.776\"],[\"79997.60\",\"0.532\"],[\"79999.60\",\"0.813\"],[\"79999.90\",\"13.316\"],[\"80099.90\",\"7.202\"],[\"80172.30\",\"1.869\"],[\"80361.00\",\"68.726\"],[\"80397.60\",\"0.000\"],[\"80562.50\",\"25.199\"],[\"80697.80\",\"2.272\"]],\"st\":1}}"}
{"receive_ns":1788563756271311000,"stream":"btcusdt@depth@100ms","event_type":"depthUpdate","event_time_ms":1788563746307,"raw_json":"{\"stream\":\"btcusdt@depth@100ms\",\"data\":{\"e\":\"depthUpdate\",\"E\":1788563746307,\"T\":1788563746306,\"s\":\"BTCUSDT\",\"ps\":\"BTCUSDT\",\"U\":11478251816339,\"u\":11478251820942,\"pu\":11478251816297,\"b\":[[\"1000.00\",\"24.754\"],[\"29101.50\",\"1.106\"],[\"29199.50\",\"0.000\"],[\"29501.50\",\"0.329\"],[\"71641.30\",\"0.002\"],[\"75840.80\",\"0.140\"],[\"75848.30\",\"0.213\"],[\"78500.60\",\"10.537\"],[\"78620.50\",\"6.348\"],[\"78805.50\",\"0.000\"],[\"78964.70\",\"0.002\"],[\"79203.50\",\"0.152\"],[\"79488.10\",\"2.781\"],[\"79506.00\",\"0.020\"],[\"79511.90\",\"1.207\"],[\"79513.90\",\"0.197\"],[\"79527.80\",\"0.003\"],[\"79529.80\",\"0.073\"],[\"79531.20\",\"0.002\"],[\"79531.30\",\"0.013\"],[\"79536.60\",\"0.036\"],[\"79536.70\",\"18.294\"],[\"79537.80\",\"0.033\"],[\"79542.00\",\"0.001\"],[\"79552.00\",\"1.018\"],[\"79564.90\",\"0.001\"],[\"79566.00\",\"1.365\"],[\"79567.20\",\"0.455\"],[\"79568.40\",\"0.007\"],[\"79571.20\",\"0.022\"],[\"79571.50\",\"0.516\"],[\"79573.10\",\"0.002\"],[\"79574.70\",\"0.080\"],[\"79574.80\",\"2.330\"],[\"79574.90\",\"0.001\"],[\"79575.90\",\"0.001\"],[\"79576.40\",\"0.001\"],[\"79578.70\",\"1.358\"],[\"79579.20\",\"0.002\"],[\"79579.90\",\"0.087\"],[\"79580.30\",\"0.006\"],[\"79581.60\",\"0.003\"],[\"79582.50\",\"0.140\"],[\"79582.60\",\"0.133\"],[\"79583.40\",\"0.537\"],[\"79583.50\",\"0.050\"],[\"79589.80\",\"0.009\"],[\"79591.60\",\"0.002\"],[\"79596.10\",\"0.006\"],[\"79596.50\",\"0.002\"],[\"79596.80\",\"0.026\"],[\"79596.90\",\"0.026\"],[\"79597.40\",\"0.000\"],[\"79598.50\",\"0.001\"],[\"79599.20\",\"0.003\"],[\"79601.50\",\"11.827\"]],\"a\":[[\"79601.60\",\"7.474\"],[\"79606.90\",\"0.015\"],[\"79613.00\",\"0.691\"],[\"79616.80\",\"0.489\"],[\"79618.50\",\"0.002\"],[\"79626.00\",\"0.046\"],[\"79628.90\",\"0.849\"],[\"79666.10\",\"26.420\"],[\"79668.80\",\"0.000\"],[\"79674.10\",\"0.017\"],[\"79674.20\",\"0.001\"],[\"79674.40\",\"0.005\"],[\"79680.80\",\"3.705\"],[\"79696.70\",\"0.002\"],[\"79700.70\",\"0.007\"],[\"79702.40\",\"0.134\"],[\"79702.50\",\"0.000\"],[\"79718.10\",\"0.023\"],[\"79965.80\",\"1.775\"],[\"79967.70\",\"0.000\"],[\"79967.80\",\"0.200\"],[\"79999.60\",\"0.813\"],[\"80397.60\",\"0.000\"]],\"st\":1}}"}
{"receive_ns":1788563756525076000,"stream":"btcusdt@depth@100ms","event_type":"depthUpdate","event_time_ms":1788563746409,"raw_json":"{\"stream\":\"btcusdt@depth@100ms\",\"data\":{\"e\":\"depthUpdate\",\"E\":1788563746409,\"T\":1788563746406,\"s\":\"BTCUSDT\",\"ps\":\"BTCUSDT\",\"U\":11478251820971,\"u\":11478251826159,\"pu\":11478251820942,\"b\":[[\"29101.50\",\"0.931\"],[\"29501.50\",\"0.504\"],[\"63680.00\",\"0.072\"],[\"71641.30\",\"0.002\"],[\"76417.40\",\"0.000\"],[\"78690.50\",\"7.548\"],[\"78805.50\",\"0.000\"],[\"79465.10\",\"0.017\"],[\"79465.20\",\"0.004\"],[\"79488.70\",\"1.581\"],[\"79511.90\",\"0.202\"],[\"79567.30\",\"0.251\"],[\"79569.20\",\"0.204\"],[\"79571.60\",\"0.264\"],[\"79571.80\",\"0.628\"],[\"79574.20\",\"0.374\"],[\"79575.50\",\"0.041\"],[\"79575.60\",\"1.154\"],[\"79576.00\",\"0.635\"],[\"79576.10\",\"0.001\"],[\"79577.40\",\"0.061\"],[\"79578.50\",\"0.038\"],[\"79578.60\",\"0.001\"],[\"79578.90\",\"0.102\"],[\"79579.40\",\"0.000\"],[\"79579.80\",\"0.319\"],[\"79580.70\",\"0.001\"],[\"79580.80\",\"0.000\"],[\"79581.10\",\"0.076\"],[\"79581.40\",\"0.070\"],[\"79582.50\",\"0.300\"],[\"79582.60\",\"0.071\"],[\"79582.90\",\"0.246\"],[\"79583.10\",\"0.072\"],[\"79583.50\",\"0.054\"],[\"79584.70\",\"0.033\"],[\"79584.80\",\"0.002\"],[\"79585.00\",\"0.074\"],[\"79585.60\",\"0.037\"],[\"79586.50\",\"0.000\"],[\"79587.10\",\"0.251\"],[\"79587.40\",\"0.005\"],[\"79588.60\",\"0.000\"],[\"79588.90\",\"0.002\"],[\"79592.90\",\"0.000\"],[\"79593.60\",\"0.080\"],[\"79595.20\",\"0.028\"],[\"79595.30\",\"0.026\"],[\"79595.60\",\"0.029\"],[\"79595.80\",\"0.028\"],[\"79596.50\",\"0.000\"],[\"79596.80\",\"0.000\"],[\"79596.90\",\"0.000\"],[\"79597.30\",\"0.000\"],[\"79597.40\",\"0.001\"],[\"79597.50\",\"0.435\"],[\"79597.60\",\"0.037\"],[\"79598.50\",\"0.000\"],[\"79599.50\",\"0.103\"],[\"79599.60\",\"0.002\"],[\"79601.50\",\"11.085\"]],\"a\":[[\"79601.60\",\"7.454\"],[\"79601.90\",\"0.030\"],[\"79604.10\",\"0.106\"],[\"79604.20\",\"0.562\"],[\"79606.10\",\"0.011\"],[\"79606.90\",\"0.011\"],[\"79607.40\",\"0.218\"],[\"79607.60\",\"1.313\"],[\"79609.40\",\"0.003\"],[\"79609.60\",\"4.185\"],[\"79611.40\",\"0.251\"],[\"79612.20\",\"0.854\"],[\"79614.10\",\"0.009\"],[\"79619.40\",\"1.954\"],[\"79621.60\",\"0.006\"],[\"79622.70\",\"0.001\"],[\"79624.60\",\"0.029\"],[\"79649.40\",\"0.001\"],[\"79666.10\",\"0.001\"],[\"79674.10\",\"0.020\"],[\"79674.20\",\"26.420\"],[\"79674.40\",\"0.002\"],[\"79702.00\",\"0.670\"],[\"79702.40\",\"0.009\"],[\"79808.10\",\"0.000\"],[\"79810.20\",\"5.697\"],[\"79823.20\",\"0.001\"],[\"79823.30\",\"0.003\"],[\"79997.60\",\"0.532\"],[\"79999.60\",\"0.813\"],[\"80397.60\",\"0.000\"],[\"81193.60\",\"0.006\"]],\"st\":1}}"}
{"receive_ns":1788563756680459000,"stream":"btcusdt@depth@100ms","event_type":"depthUpdate","event_time_ms":1788563746511,"raw_json":"{\"stream\":\"btcusdt@depth@100ms\",\"data\":{\"e\":\"depthUpdate\",\"E\":1788563746511,\"T\":1788563746510,\"s\":\"BTCUSDT\",\"ps\":\"BTCUSDT\",\"U\":11478251826343,\"u\":11478251830503,\"pu\":11478251826159,\"b\":[[\"1000.00\",\"24.754\"],[\"29101.50\",\"0.749\"],[\"29501.50\",\"0.686\"],[\"71641.30\",\"0.002\"],[\"76417.40\",\"0.002\"],[\"78269.70\",\"1.018\"],[\"78493.10\",\"1.271\"],[\"78644.30\",\"4.101\"],[\"78805.50\",\"0.000\"],[\"79177.50\",\"9.024\"],[\"79203.50\",\"0.152\"],[\"79488.10\",\"1.776\"],[\"79509.80\",\"0.035\"],[\"79511.90\",\"2.011\"],[\"79536.60\",\"0.035\"],[\"79536.70\",\"0.020\"],[\"79537.80\",\"0.033\"],[\"79539.30\",\"0.001\"],[\"79539.40\",\"18.344\"],[\"79571.60\",\"0.766\"],[\"79582.00\",\"0.003\"],[\"79582.40\",\"0.070\"],[\"79582.70\",\"0.070\"],[\"79582.80\",\"0.101\"],[\"79582.90\",\"0.346\"],[\"79596.40\",\"0.027\"],[\"79601.50\",\"11.111\"]],\"a\":[[\"79601.60\",\"7.459\"],[\"79607.40\",\"0.152\"],[\"79607.70\",\"1.066\"],[\"79619.60\",\"0.002\"],[\"79625.90\",\"0.057\"],[\"79663.40\",\"26.421\"],[\"79674.20\",\"0.001\"],[\"79702.00\",\"0.670\"],[\"79965.80\",\"1.685\"],[\"79967.70\",\"0.090\"],[\"79967.80\",\"0.000\"],[\"79997.60\",\"1.058\"],[\"79999.60\",\"0.287\"],[\"80397.60\",\"0.000\"],[\"80530.40\",\"4.338\"],[\"80556.70\",\"2.852\"],[\"80755.80\",\"16.568\"]],\"st\":1}}"}
{"receive_ns":1788563756749498000,"stream":"btcusdt@depth@100ms","event_type":"depthUpdate","event_time_ms":1788563746613,"raw_json":"{\"stream\":\"btcusdt@depth@100ms\",\"data\":{\"e\":\"depthUpdate\",\"E\":1788563746613,\"T\":1788563746612,\"s\":\"BTCUSDT\",\"ps\":\"BTCUSDT\",\"U\":11478251830527,\"u\":11478251834316,\"pu\":11478251830503,\"b\":[[\"1000.00\",\"24.754\"],[\"29099.50\",\"0.623\"],[\"29101.50\",\"0.616\"],[\"29501.50\",\"0.861\"],[\"63680.00\",\"0.072\"],[\"63681.20\",\"0.000\"],[\"71641.30\",\"0.002\"],[\"76417.40\",\"0.000\"],[\"78604.50\",\"0.913\"],[\"78805.50\",\"0.002\"],[\"79203.50\",\"0.152\"],[\"79426.40\",\"0.000\"],[\"79428.00\",\"1.629\"],[\"79460.20\",\"6.977\"],[\"79471.80\",\"0.101\"],[\"79541.80\",\"0.209\"],[\"79556.00\",\"0.073\"],[\"79556.70\",\"0.101\"],[\"79559.60\",\"0.148\"],[\"79570.30\",\"0.309\"],[\"79571.60\",\"0.013\"],[\"79575.60\",\"1.079\"],[\"79578.40\",\"0.273\"],[\"79578.80\",\"0.000\"],[\"79578.90\",\"0.002\"],[\"79579.70\",\"0.568\"],[\"79581.40\",\"0.004\"],[\"79582.30\",\"0.062\"],[\"79582.90\",\"0.363\"],[\"79583.00\",\"0.087\"],[\"79583.50\",\"0.058\"],[\"79592.80\",\"0.004\"],[\"79595.20\",\"0.002\"],[\"79595.30\",\"0.000\"],[\"79595.50\",\"0.000\"],[\"79595.60\",\"0.003\"],[\"79595.70\",\"0.001\"],[\"79596.20\",\"1.007\"],[\"79596.80\",\"0.026\"],[\"79597.00\",\"0.026\"],[\"79597.80\",\"0.027\"],[\"79598.70\",\"0.028\"],[\"79598.90\",\"0.026\"],[\"79599.00\",\"0.001\"],[\"79601.50\",\"11.129\"]],\"a\":[[\"79601.60\",\"6.248\"],[\"79601.70\",\"1.247\"],[\"79601.90\",\"0.026\"],[\"79604.10\",\"0.110\"],[\"79606.10\",\"0.003\"],[\"79606.90\",\"0.019\"],[\"79607.60\",\"1.000\"],[\"79607.70\",\"1.000\"],[\"79609.30\",\"0.379\"],[\"79609.40\",\"0.129\"],[\"79609.60\",\"2.975\"],[\"79609.70\",\"1.214\"],[\"79611.90\",\"0.225\"],[\"79674.10\",\"0.017\"],[\"79674.40\",\"0.005\"],[\"79687.60\",\"2.912\"],[\"79702.00\",\"0.795\"],[\"79810.20\",\"5.693\"],[\"79967.80\",\"0.200\"],[\"79997.60\",\"0.902\"],[\"79999.60\",\"0.243\"],[\"80397.60\",\"0.000\"],[\"80681.90\",\"11.661\"]],\"st\":1}}"}
{"receive_ns":1788563756784235000,"stream":"btcusdt@depth@100ms","event_type":"depthUpdate","event_time_ms":1788563746715,"raw_json":"{\"stream\":\"btcusdt@depth@100ms\",\"data\":{\"e\":\"depthUpdate\",\"E\":1788563746715,\"T\":1788563746714,\"s\":\"BTCUSDT\",\"ps\":\"BTCUSDT\",\"U\":11478251834356,\"u\":11478251837702,\"pu\":11478251834316,\"b\":[[\"29099.50\",\"0.567\"],[\"29101.50\",\"0.497\"],[\"29501.50\",\"1.036\"],[\"63680.00\",\"0.072\"],[\"71641.30\",\"0.002\"],[\"76417.40\",\"0.002\"],[\"78805.50\",\"0.000\"],[\"79201.50\",\"0.631\"],[\"79511.90\",\"2.011\"],[\"79567.80\",\"0.100\"],[\"79571.50\",\"0.077\"],[\"79571.60\",\"0.264\"],[\"79571.90\",\"0.441\"],[\"79574.90\",\"0.001\"],[\"79575.60\",\"1.154\"],[\"79577.80\",\"0.000\"],[\"79578.70\",\"1.288\"],[\"79582.30\",\"0.066\"],[\"79583.50\",\"0.054\"],[\"79594.80\",\"0.000\"],[\"79598.10\",\"0.026\"],[\"79598.70\",\"0.002\"],[\"79598.90\",\"0.000\"],[\"79599.60\",\"0.004\"]],\"a\":[[\"79601.60\",\"6.253\"],[\"79606.90\",\"0.019\"],[\"79609.40\",\"0.129\"],[\"79610.90\",\"0.083\"],[\"79612.00\",\"0.006\"],[\"79612.10\",\"0.831\"],[\"79614.30\",\"0.002\"],[\"79615.90\",\"0.374\"],[\"79616.80\",\"0.037\"],[\"79617.70\",\"0.049\"],[\"79618.80\",\"0.002\"],[\"79618.90\",\"0.452\"],[\"79620.40\",\"0.002\"],[\"79628.40\",\"0.341\"],[\"79631.80\",\"0.001\"],[\"79701.90\",\"0.001\"],[\"79702.00\",\"0.795\"],[\"79999.60\",\"0.443\"],[\"80238.40\",\"0.248\"],[\"80397.60\",\"0.000\"],[\"80562.50\",\"25.050\"]],\"st\":1}}"}
{"receive_ns":1788563757162558000,"stream":"btcusdt@depth@100ms","event_type":"depthUpdate","event_time_ms":1788563746817,"raw_json":"{\"stream\":\"btcusdt@depth@100ms\",\"data\":{\"e\":\"depthUpdate\",\"E\":1788563746817,\"T\":1788563746816,\"s\":\"BTCUSDT\",\"ps\":\"BTCUSDT\",\"U\":11478251837725,\"u\":11478251842759,\"pu\":11478251837702,\"b\":[[\"1000.00\",\"24.754\"],[\"29099.50\",\"0.504\"],[\"29101.50\",\"0.378\"],[\"29501.50\",\"1.218\"],[\"71641.30\",\"0.002\"],[\"78004.40\",\"0.003\"],[\"78582.10\",\"88.256\"],[\"78591.80\",\"0.003\"],[\"78594.20\",\"0.005\"],[\"78805.50\",\"0.002\"],[\"79203.50\",\"0.142\"],[\"79488.10\",\"2.781\"],[\"79491.80\",\"0.060\"],[\"79492.30\",\"0.069\"],[\"79498.30\",\"0.003\"],[\"79499.00\",\"0.003\"],[\"79506.40\",\"0.206\"],[\"79510.70\",\"0.000\"],[\"79511.90\",\"1.207\"],[\"79513.80\",\"0.040\"],[\"79514.60\",\"0.042\"],[\"79515.20\",\"0.045\"],[\"79517.50\",\"0.017\"],[\"79518.70\",\"0.001\"],[\"79521.20\",\"1.365\"],[\"79521.90\",\"0.361\"],[\"79523.90\",\"0.125\"],[\"79525.20\",\"0.000\"],[\"79525.60\",\"0.302\"],[\"79541.80\",\"0.610\"],[\"79546.40\",\"2.034\"],[\"79562.10\",\"0.001\"],[\"79563.80\",\"0.077\"],[\"79564.90\",\"0.077\"],[\"79571.60\",\"0.013\"],[\"79571.90\",\"0.441\"],[\"79572.60\",\"0.003\"],[\"79573.70\",\"0.006\"],[\"79574.90\",\"0.001\"],[\"79575.60\",\"1.079\"],[\"79577.80\",\"0.002\"],[\"79578.80\",\"0.006\"],[\"79580.30\",\"0.000\"],[\"79581.10\",\"0.080\"],[\"79582.30\",\"0.062\"],[\"79585.50\",\"0.002\"],[\"79588.50\",\"0.005\"],[\"79592.80\",\"0.002\"],[\"79593.60\",\"0.081\"],[\"79594.00\",\"0.060\"],[\"79594.10\",\"0.026\"],[\"79594.30\",\"0.054\"],[\"79594.40\",\"0.026\"],[\"79594.50\",\"0.027\"],[\"79594.60\",\"0.027\"],[\"79594.70\",\"0.030\"],[\"79594.80\",\"0.026\"],[\"79595.10\",\"0.003\"],[\"79595.80\",\"0.000\"],[\"79595.90\",\"0.059\"],[\"79596.00\",\"0.004\"],[\"79596.20\",\"1.007\"],[\"79596.40\",\"0.001\"],[\"79596.60\",\"0.001\"],[\"79596.70\",\"0.001\"],[\"79596.80\",\"0.000\"],[\"79597.00\",\"0.000\"],[\"79597.40\",\"0.001\"],[\"79597.80\",\"0.001\"],[\"79598.10\",\"0.000\"],[\"79599.20\",\"0.002\"],[\"79601.50\",\"8.704\"]],\"a\":[[\"79601.60\",\"6.702\"],[\"79601.70\",\"1.248\"],[\"79601.90\",\"0.030\"],[\"79602.00\",\"0.379\"],[\"79603.70\",\"0.029\"],[\"79604.10\",\"0.106\"],[\"79605.00\",\"0.011\"],[\"79606.10\",\"0.007\"],[\"79606.90\",\"0.015\"],[\"79607.40\",\"0.527\"],[\"79609.30\",\"0.000\"],[\"79610.70\",\"0.006\"],[\"79613.70\",\"0.003\"],[\"79617.70\",\"0.051\"],[\"79621.20\",\"0.053\"],[\"79622.30\",\"0.039\"],[\"79622.50\",\"0.000\"],[\"79625.50\",\"0.083\"],[\"79626.40\",\"0.584\"],[\"79628.10\",\"0.041\"],[\"79629.30\",\"0.000\"],[\"79629.50\",\"0.225\"],[\"79633.00\",\"0.201\"],[\"79640.10\",\"0.447\"],[\"79644.40\",\"0.048\"],[\"79650.90\",\"0.040\"],[\"79657.00\",\"0.209\"],[\"79664.70\",\"0.040\"],[\"79666.50\",\"0.000\"],[\"79666.90\",\"0.041\"],[\"79671.30\",\"0.002\"],[\"79672.00\",\"0.009\"],[\"79675.00\",\"0.038\"],[\"79681.70\",\"0.001\"],[\"79701.90\",\"0.126\"],[\"79702.00\",\"0.670\"],[\"79702.50\",\"0.000\"],[\"79965.80\",\"1.685\"],[\"79967.70\",\"0.090\"],[\"79967.80\",\"0.200\"],[\"79997.60\",\"0.902\"],[\"79999.60\",\"0.243\"],[\"80397.60\",\"0.000\"],[\"80556.80\",\"0.621\"],[\"80624.40\",\"87.349\"],[\"81188.30\",\"0.009\"],[\"81193.60\",\"0.009\"]],\"st\":1}}"}
{"receive_ns":1788563757352233000,"stream":"btcusdt@depth@100ms","event_type":"depthUpdate","event_time_ms":1788563746919,"raw_json":"{\"stream\":\"btcusdt@depth@100ms\",\"data\":{\"e\":\"depthUpdate\",\"E\":1788563746919,\"T\":1788563746918,\"s\":\"BTCUSDT\",\"ps\":\"BTCUSDT\",\"U\":11478251842766,\"u\":11478251848022,\"pu\":11478251842759,\"b\":[[\"1000.00\",\"24.754\"],[\"29099.50\",\"0.448\"],[\"29101.50\",\"0.252\"],[\"29501.50\",\"1.400\"],[\"63681.00\",\"0.000\"],[\"71641.30\",\"0.002\"],[\"71675.00\",\"0.002\"],[\"76417.40\",\"0.000\"],[\"78805.50\",\"0.000\"],[\"79203.40\",\"0.001\"],[\"79250.80\",\"0.500\"],[\"79444.10\",\"0.108\"],[\"79449.40\",\"1.884\"],[\"79486.10\",\"0.038\"],[\"79491.80\",\"0.022\"],[\"79502.40\",\"0.057\"],[\"79503.00\",\"0.038\"],[\"79506.40\",\"0.168\"],[\"79511.90\",\"1.533\"],[\"79513.60\",\"0.000\"],[\"79524.00\",\"2.736\"],[\"79527.80\",\"0.003\"],[\"79527.90\",\"0.135\"],[\"79531.20\",\"0.001\"],[\"79533.70\",\"0.257\"],[\"79535.80\",\"0.151\"],[\"79539.30\",\"0.000\"],[\"79539.40\",\"0.070\"],[\"79541.00\",\"0.023\"],[\"79541.80\",\"0.008\"],[\"79543.70\",\"0.016\"],[\"79544.10\",\"0.007\"],[\"79546.40\",\"0.034\"],[\"79551.60\",\"10.071\"],[\"79562.00\",\"0.092\"],[\"79562.50\",\"1.016\"],[\"79562.70\",\"0.081\"],[\"79564.90\",\"0.157\"],[\"79565.00\",\"0.002\"],[\"79568.00\",\"0.023\"],[\"79569.80\",\"0.003\"],[\"79571.50\",\"0.001\"],[\"79574.00\",\"0.082\"],[\"79574.70\",\"0.079\"],[\"79574.80\",\"0.017\"],[\"79575.20\",\"0.129\"],[\"79575.60\",\"0.763\"],[\"79576.00\",\"0.632\"],[\"79577.60\",\"0.001\"],[\"79578.90\",\"0.316\"],[\"79579.10\",\"0.630\"],[\"79579.60\",\"0.001\"],[\"79579.80\",\"0.005\"],[\"79580.60\",\"0.002\"],[\"79581.50\",\"0.163\"],[\"79581.90\",\"0.000\"],[\"79582.50\",\"0.140\"],[\"79582.60\",\"0.151\"],[\"79585.40\",\"0.000\"],[\"79587.30\",\"0.219\"],[\"79590.00\",\"0.514\"],[\"79590.30\",\"0.000\"],[\"79593.70\",\"0.159\"],[\"79593.80\",\"0.035\"],[\"79593.90\",\"0.028\"],[\"79594.30\",\"0.054\"],[\"79594.60\",\"0.001\"],[\"79594.70\",\"0.030\"],[\"79594.80\",\"0.000\"],[\"79594.90\",\"0.000\"],[\"79595.60\",\"0.003\"],[\"79596.10\",\"0.006\"],[\"79597.40\",\"0.001\"],[\"79601.50\",\"9.288\"]],\"a\":[[\"79601.60\",\"6.708\"],[\"79605.00\",\"0.007\"],[\"79606.10\",\"0.011\"],[\"79606.90\",\"0.011\"],[\"79607.20\",\"0.338\"],[\"79607.40\",\"0.628\"],[\"79607.50\",\"0.446\"],[\"79616.60\",\"0.041\"],[\"79622.30\",\"0.001\"],[\"79628.10\",\"0.042\"],[\"79636.70\",\"0.125\"],[\"79639.80\",\"0.117\"],[\"79640.10\",\"0.409\"],[\"79652.90\",\"0.000\"],[\"79656.90\",\"0.004\"],[\"79658.90\",\"0.040\"],[\"79659.00\",\"0.359\"],[\"79664.70\",\"0.002\"],[\"79670.10\",\"0.001\"],[\"79672.90\",\"0.000\"],[\"79676.10\",\"0.000\"],[\"79696.70\",\"0.000\"],[\"79701.90\",\"0.001\"],[\"79702.30\",\"0.126\"],[\"79716.20\",\"0.411\"],[\"79716.30\",\"0.165\"],[\"79724.30\",\"3.450\"],[\"79810.20\",\"0.000\"],[\"79810.30\",\"3.658\"],[\"79967.80\",\"0.356\"],[\"79999.60\",\"0.287\"],[\"79999.70\",\"0.002\"],[\"80397.60\",\"0.000\"]],\"st\":1}}"}
{"receive_ns":1788563764615750000,"stream":"btcusdt@depth@100ms","event_type":"depthUpdate","event_time_ms":1788563747021,"raw_json":"{\"stream\":\"btcusdt@depth@100ms\",\"data\":{\"e\":\"depthUpdate\",\"E\":1788563747021,\"T\":1788563747020,\"s\":\"BTCUSDT\",\"ps\":\"BTCUSDT\",\"U\":11478251848061,\"u\":11478251882894,\"pu\":11478251848022,\"b\":[[\"29099.50\",\"0.385\"],[\"29101.50\",\"0.140\"],[\"29495.70\",\"0.084\"],[\"29495.90\",\"0.007\"],[\"29496.20\",\"0.007\"],[\"29497.50\",\"0.007\"],[\"29500.80\",\"0.014\"],[\"29501.50\",\"1.456\"],[\"63680.00\",\"0.072\"],[\"71636.10\",\"0.006\"],[\"71637.70\",\"0.000\"],[\"71641.30\",\"0.000\"],[\"71730.00\",\"0.002\"],[\"71929.30\",\"0.000\"],[\"76413.50\",\"0.002\"],[\"78437.90\",\"1.683\"],[\"78679.80\",\"0.945\"],[\"78679.90\",\"3.775\"],[\"78681.60\",\"1.516\"],[\"78683.30\",\"0.057\"],[\"78685.10\",\"0.017\"],[\"78685.30\",\"0.000\"],[\"78799.20\",\"0.273\"],[\"78799.70\",\"0.052\"],[\"78799.90\",\"0.151\"],[\"78801.50\",\"0.009\"],[\"78802.70\",\"0.001\"],[\"78803.20\",\"0.000\"],[\"78804.80\",\"0.000\"],[\"78805.40\",\"0.000\"],[\"78805.50\",\"0.000\"],[\"78869.40\",\"0.000\"],[\"79040.00\",\"1.285\"],[\"79171.00\",\"0.011\"],[\"79175.00\",\"3.144\"],[\"79179.00\",\"0.004\"],[\"79183.00\",\"0.001\"],[\"79197.70\",\"0.001\"],[\"79202.00\",\"0.105\"],[\"79203.50\",\"0.001\"],[\"79203.70\",\"0.148\"],[\"79340.90\",\"0.001\"],[\"79343.30\",\"0.000\"],[\"79368.80\",\"0.129\"],[\"79373.10\",\"35.276\"],[\"79375.90\",\"5.895\"],[\"79419.70\",\"0.000\"],[\"79437.40\",\"0.002\"],[\"79444.50\",\"0.004\"],[\"79448.10\",\"1.396\"],[\"79455.40\",\"0.000\"],[\"79468.00\",\"1.287\"],[\"79468.40\",\"0.001\"],[\"79468.60\",\"0.014\"],[\"79470.80\",\"0.002\"],[\"79471.80\",\"0.001\"],[\"79472.10\",\"0.038\"],[\"79475.60\",\"0.498\"],[\"79476.40\",\"0.045\"],[\"79476.60\",\"0.019\"],[\"79477.20\",\"0.011\"],[\"79477.90\",\"1.255\"],[\"79478.00\",\"0.001\"],[\"79478.30\",\"1.195\"],[\"79478.40\",\"1.288\"],[\"79482.50\",\"0.003\"],[\"79484.40\",\"0.054\"],[\"79486.10\",\"0.038\"],[\"79487.90\",\"0.000\"],[\"79488.10\",\"1.544\"],[\"79488.20\",\"0.233\"],[\"79488.30\",\"0.040\"],[\"79488.90\",\"0.038\"],[\"79489.00\",\"0.001\"],[\"79489.90\",\"0.247\"],[\"79490.90\",\"0.000\"],[\"79491.10\",\"0.007\"],[\"79491.30\",\"2.514\"],[\"79491.40\",\"1.513\"],[\"79492.30\",\"0.031\"],[\"79494.30\",\"0.015\"],[\"79494.90\",\"0.000\"],[\"79495.20\",\"0.000\"],[\"79495.60\",\"0.039\"],[\"79496.00\",\"0.021\"],[\"79497.40\",\"0.015\"],[\"79498.20\",\"0.002\"],[\"79499.80\",\"0.743\"],[\"79499.90\",\"0.001\"],[\"79500.00\",\"3.244\"],[\"79500.20\",\"1.240\"],[\"79500.30\",\"0.011\"],[\"79500.70\",\"0.002\"],[\"79501.00\",\"0.040\"],[\"79501.80\",\"0.091\"],[\"79502.40\",\"0.020\"],[\"79503.00\",\"0.000\"],[\"79504.10\",\"0.038\"],[\"79504.30\",\"0.033\"],[\"79505.30\",\"0.039\"],[\"79505.80\",\"0.002\"],[\"79506.10\",\"0.056\"],[\"79507.00\",\"0.039\"],[\"79507.20\",\"0.061\"],[\"79507.60\",\"0.038\"],[\"79509.70\",\"0.001\"],[\"79510.20\",\"0.002\"],[\"79510.30\",\"0.305\"],[\"79510.50\",\"0.070\"],[\"79510.80\",\"0.001\"],[\"79511.10\",\"0.001\"],[\"79511.40\",\"6.120\"],[\"79511.90\",\"0.001\"],[\"79512.10\",\"0.333\"],[\"79513.60\",\"0.041\"],[\"79513.80\",\"0.002\"],[\"79514.00\",\"0.046\"],[\"79514.60\",\"0.004\"],[\"79514.90\",\"0.039\"],[\"79515.20\",\"0.007\"],[\"79515.30\",\"0.253\"],[\"79517.00\",\"0.001\"],[\"79517.30\",\"0.041\"],[\"79517.50\",\"0.059\"],[\"79517.70\",\"0.000\"],[\"79517.90\",\"1.991\"],[\"79518.70\",\"0.000\"],[\"79519.00\",\"0.001\"],[\"79520.50\",\"0.002\"],[\"79520.90\",\"0.001\"],[\"79521.20\",\"1.324\"],[\"79521.70\",\"0.005\"],[\"79522.00\",\"0.022\"],[\"79522.10\",\"3.708\"],[\"79522.20\",\"1.005\"],[\"79522.30\",\"0.001\"],[\"79523.20\",\"17.996\"],[\"79523.30\",\"0.001\"],[\"79523.90\",\"0.097\"],[\"79524.00\",\"2.988\"],[\"79524.20\",\"0.004\"],[\"79524.40\",\"0.211\"],[\"79525.80\",\"0.051\"],[\"79525.90\",\"0.198\"],[\"79527.90\",\"0.097\"],[\"79528.00\",\"0.274\"],[\"79529.30\",\"0.001\"],[\"79530.20\",\"0.002\"],[\"79531.00\",\"0.000\"],[\"79531.30\",\"0.013\"],[\"79531.80\",\"0.001\"],[\"79532.00\",\"0.254\"],[\"79532.10\",\"0.804\"],[\"79532.20\",\"0.074\"],[\"79532.50\",\"2.891\"],[\"79533.60\",\"0.003\"],[\"79533.90\",\"0.196\"],[\"79534.60\",\"0.000\"],[\"79535.60\",\"0.097\"],[\"79536.60\",\"0.035\"],[\"79536.70\",\"0.004\"],[\"79536.80\",\"0.028\"],[\"79537.50\",\"0.000\"],[\"79537.60\",\"0.032\"],[\"79537.90\",\"0.233\"],[\"79538.60\",\"0.002\"],[\"79539.00\",\"0.206\"],[\"79539.60\",\"0.003\"],[\"79539.90\",\"3.572\"],[\"79540.30\",\"0.005\"],[\"79540.40\",\"0.000\"],[\"79540.80\",\"0.002\"],[\"79541.10\",\"0.751\"],[\"79541.20\",\"0.116\"],[\"79542.10\",\"0.119\"],[\"79542.90\",\"0.007\"],[\"79543.30\",\"0.013\"],[\"79543.80\",\"0.967\"],[\"79544.00\",\"1.424\"],[\"79544.30\",\"0.009\"],[\"79545.10\",\"10.219\"],[\"79545.80\",\"0.026\"],[\"79547.20\",\"0.406\"],[\"79547.40\",\"0.059\"],[\"79547.70\",\"0.027\"],[\"79547.90\",\"0.709\"],[\"79548.80\",\"0.096\"],[\"79549.00\",\"0.736\"],[\"79549.10\",\"0.738\"],[\"79549.40\",\"2.395\"],[\"79549.50\",\"0.104\"],[\"79549.80\",\"0.001\"],[\"79550.60\",\"0.036\"],[\"79551.50\",\"1.228\"],[\"79551.60\",\"0.072\"],[\"79551.70\",\"0.002\"],[\"79552.00\",\"1.017\"],[\"79552.20\",\"0.298\"],[\"79552.40\",\"1.839\"],[\"79552.60\",\"0.000\"],[\"79552.70\",\"0.451\"],[\"79552.80\",\"0.479\"],[\"79552.90\",\"0.052\"],[\"79553.30\",\"0.105\"],[\"79553.50\",\"0.002\"],[\"79553.60\",\"0.006\"],[\"79553.70\",\"0.067\"],[\"79553.80\",\"0.076\"],[\"79554.60\",\"0.001\"],[\"79554.90\",\"0.081\"],[\"79555.30\",\"0.004\"],[\"79555.50\",\"0.000\"],[\"79555.80\",\"0.002\"],[\"79556.10\",\"0.079\"],[\"79557.00\",\"0.504\"],[\"79557.10\",\"1.325\"],[\"79557.20\",\"0.156\"],[\"79557.30\",\"0.002\"],[\"79557.40\",\"0.250\"],[\"79558.30\",\"0.273\"],[\"79558.60\",\"0.001\"],[\"79559.40\",\"0.076\"],[\"79559.50\",\"0.472\"],[\"79559.60\",\"0.197\"],[\"79560.00\",\"0.028\"],[\"79560.20\",\"0.004\"],[\"79560.40\",\"0.481\"],[\"79560.50\",\"0.199\"],[\"79561.00\",\"0.000\"],[\"79561.10\",\"0.638\"],[\"79561.20\",\"1.423\"],[\"79561.60\",\"0.078\"],[\"79561.90\",\"0.001\"],[\"79562.00\",\"0.002\"],[\"79562.40\",\"0.718\"],[\"79562.50\",\"1.036\"],[\"79562.60\",\"0.008\"],[\"79562.70\",\"0.003\"],[\"79562.90\",\"0.045\"],[\"79563.30\",\"0.002\"],[\"79563.60\",\"0.001\"],[\"79563.80\",\"0.001\"],[\"79563.90\",\"0.196\"],[\"79564.00\",\"0.004\"],[\"79564.90\",\"0.440\"],[\"79565.00\",\"0.122\"],[\"79565.20\",\"0.629\"],[\"79565.80\",\"0.000\"],[\"79566.00\",\"1.289\"],[\"79566.10\",\"0.003\"],[\"79566.20\",\"2.316\"],[\"79566.30\",\"0.374\"],[\"79566.60\",\"0.126\"],[\"79567.00\",\"0.198\"],[\"79567.10\",\"0.000\"],[\"79567.20\",\"0.003\"],[\"79567.30\",\"0.000\"],[\"79567.70\",\"0.005\"],[\"79567.80\",\"0.060\"],[\"79567.90\",\"1.390\"],[\"79568.00\",\"0.007\"],[\"79568.10\",\"0.045\"],[\"79568.20\",\"0.256\"],[\"79568.30\",\"0.084\"],[\"79568.40\",\"0.001\"],[\"79569.00\",\"0.006\"],[\"79569.20\",\"0.832\"],[\"79569.30\",\"1.187\"],[\"79569.40\",\"0.160\"],[\"79569.60\",\"0.003\"],[\"79569.70\",\"0.003\"],[\"79569.90\",\"0.006\"],[\"79570.00\",\"0.009\"],[\"79570.30\",\"0.305\"],[\"79570.40\",\"1.887\"],[\"79570.50\",\"0.342\"],[\"79570.90\",\"0.003\"],[\"79571.20\",\"0.002\"],[\"79571.30\",\"0.001\"],[\"79571.40\",\"0.000\"],[\"79571.50\",\"0.002\"],[\"79571.60\",\"1.306\"],[\"79571.70\",\"0.003\"],[\"79571.80\",\"1.004\"],[\"79571.90\",\"0.064\"],[\"79572.00\",\"0.009\"],[\"79572.80\",\"0.051\"],[\"79572.90\",\"0.005\"],[\"79573.10\",\"0.006\"],[\"79573.20\",\"0.001\"],[\"79573.30\",\"0.000\"],[\"79573.50\",\"0.080\"],[\"79573.60\",\"0.254\"],[\"79573.70\",\"0.006\"],[\"79573.80\",\"0.016\"],[\"79573.90\",\"0.002\"],[\"79574.00\",\"0.002\"],[\"79574.10\",\"0.003\"],[\"79574.20\",\"0.001\"],[\"79574.40\",\"0.256\"],[\"79574.50\",\"0.000\"],[\"79574.60\",\"0.001\"],[\"79574.70\",\"0.002\"],[\"79574.80\",\"0.002\"],[\"79575.30\",\"0.206\"],[\"79575.60\",\"0.276\"],[\"79575.70\",\"0.002\"],[\"79576.00\",\"0.004\"],[\"79576.10\",\"0.001\"],[\"79576.20\",\"0.001\"],[\"79576.40\",\"0.117\"],[\"79576.60\",\"0.001\"],[\"79576.80\",\"0.087\"],[\"79577.00\",\"0.251\"],[\"79577.40\",\"0.079\"],[\"79577.80\",\"0.002\"],[\"79578.20\",\"0.002\"],[\"79578.50\",\"0.002\"],[\"79578.60\",\"0.253\"],[\"79578.70\",\"0.001\"],[\"79578.80\",\"0.000\"],[\"79578.90\",\"0.002\"],[\"79579.10\",\"0.001\"],[\"79579.20\",\"0.003\"],[\"79579.30\",\"0.341\"],[\"79579.40\",\"0.251\"],[\"79579.50\",\"0.003\"],[\"79579.60\",\"0.253\"],[\"79579.70\",\"0.006\"],[\"79579.80\",\"0.001\"],[\"79580.10\",\"0.003\"],[\"79580.20\",\"0.002\"],[\"79580.60\",\"0.002\"],[\"79580.80\",\"0.002\"],[\"79581.10\",\"0.000\"],[\"79581.20\",\"0.080\"],[\"79581.40\",\"0.003\"],[\"79581.50\",\"0.028\"],[\"79581.80\",\"0.000\"],[\"79582.10\",\"0.001\"],[\"79582.30\",\"0.000\"],[\"79582.60\",\"0.071\"],[\"79582.90\",\"0.300\"],[\"79583.00\",\"0.071\"],[\"79583.20\",\"0.102\"],[\"79583.30\",\"0.102\"],[\"79583.40\",\"0.174\"],[\"79583.50\",\"1.314\"],[\"79583.60\",\"0.002\"],[\"79583.70\",\"0.252\"],[\"79583.80\",\"0.002\"],[\"79583.90\",\"0.032\"],[\"79584.00\",\"0.007\"],[\"79584.10\",\"0.035\"],[\"79584.20\",\"1.063\"],[\"79584.40\",\"0.036\"],[\"79584.50\",\"0.071\"],[\"79584.70\",\"0.059\"],[\"79584.80\",\"0.002\"],[\"79584.90\",\"0.066\"],[\"79585.00\",\"0.034\"],[\"79585.20\",\"0.005\"],[\"79585.30\",\"0.001\"],[\"79585.40\",\"0.000\"],[\"79585.50\",\"0.001\"],[\"79585.60\",\"0.033\"],[\"79585.70\",\"0.002\"],[\"79585.90\",\"0.985\"],[\"79586.00\",\"0.055\"],[\"79586.10\",\"0.026\"],[\"79586.20\",\"0.070\"],[\"79586.30\",\"0.004\"],[\"79586.40\",\"0.002\"],[\"79586.50\",\"0.026\"],[\"79586.70\",\"0.001\"],[\"79586.80\",\"0.028\"],[\"79587.00\",\"0.027\"],[\"79587.10\",\"0.000\"],[\"79587.20\",\"0.030\"],[\"79587.30\",\"0.003\"],[\"79587.40\",\"0.027\"],[\"79587.70\",\"1.061\"],[\"79588.10\",\"0.000\"],[\"79588.40\",\"0.005\"],[\"79588.50\",\"0.004\"],[\"79588.60\",\"0.023\"],[\"79588.70\",\"0.001\"],[\"79588.80\",\"0.002\"],[\"79589.00\",\"0.003\"],[\"79589.50\",\"0.003\"],[\"79589.60\",\"0.027\"],[\"79589.70\",\"0.001\"],[\"79589.80\",\"0.006\"],[\"79589.90\",\"0.000\"],[\"79590.10\",\"0.002\"],[\"79590.70\",\"0.031\"],[\"79590.80\",\"0.002\"],[\"79591.20\",\"0.005\"],[\"79591.50\",\"0.000\"],[\"79592.00\",\"0.006\"],[\"79592.10\",\"0.001\"],[\"79592.30\",\"0.033\"],[\"79592.40\",\"0.003\"],[\"79592.50\",\"0.000\"],[\"79592.70\",\"0.000\"],[\"79592.80\",\"0.004\"],[\"79593.20\",\"0.002\"],[\"79593.30\",\"0.000\"],[\"79593.40\",\"0.002\"],[\"79593.50\",\"0.002\"],[\"79593.60\",\"0.077\"],[\"79593.70\",\"0.000\"],[\"79593.80\",\"0.008\"],[\"79593.90\",\"0.002\"],[\"79594.00\",\"0.003\"],[\"79594.10\",\"0.000\"],[\"79594.20\",\"0.000\"],[\"79594.30\",\"0.001\"],[\"79594.40\",\"0.000\"],[\"79594.50\",\"0.000\"],[\"79594.70\",\"0.004\"],[\"79595.00\",\"0.001\"],[\"79595.10\",\"0.001\"],[\"79595.50\",\"0.002\"],[\"79595.60\",\"0.001\"],[\"79595.70\",\"0.897\"],[\"79595.90\",\"0.000\"],[\"79596.00\",\"0.000\"],[\"79596.10\",\"0.000\"],[\"79596.20\",\"0.000\"],[\"79596.30\",\"0.000\"],[\"79596.40\",\"0.000\"],[\"79596.60\",\"0.000\"],[\"79596.70\",\"0.000\"],[\"79597.10\",\"0.000\"],[\"79597.20\",\"0.000\"],[\"79597.40\",\"0.000\"],[\"79597.50\",\"0.000\"],[\"79597.60\",\"0.000\"],[\"79597.80\",\"0.000\"],[\"79597.90\",\"0.000\"],[\"79598.00\",\"0.000\"],[\"79598.20\",\"0.000\"],[\"79598.40\",\"0.000\"],[\"79598.60\",\"0.000\"],[\"79598.70\",\"0.000\"],[\"79598.80\",\"0.000\"],[\"79599.00\",\"0.000\"],[\"79599.10\",\"0.000\"],[\"79599.20\",\"0.000\"],[\"79599.30\",\"0.000\"],[\"79599.40\",\"0.000\"],[\"79599.50\",\"0.000\"],[\"79599.60\",\"0.000\"],[\"79599.80\",\"0.000\"],[\"79600.00\",\"0.000\"],[\"79600.10\",\"0.000\"],[\"79600.40\",\"0.000\"],[\"79600.80\",\"0.000\"],[\"79601.20\",\"0.000\"],[\"79601.30\",\"0.000\"],[\"79601.40\",\"0.000\"],[\"79601.50\",\"0.000\"]],\"a\":[[\"79595.80\",\"12.845\"],[\"79595.90\",\"0.016\"],[\"79596.00\",\"6.315\"],[\"79596.10\",\"0.002\"],[\"79596.20\",\"3.553\"],[\"79596.30\",\"1.552\"],[\"79596.40\",\"0.001\"],[\"79596.60\",\"0.026\"],[\"79597.00\",\"0.001\"],[\"79597.20\",\"0.000\"],[\"79597.30\",\"0.000\"],[\"79597.40\",\"0.009\"],[\"79597.50\",\"2.501\"],[\"79597.60\",\"0.230\"],[\"79597.70\",\"1.905\"],[\"79597.90\",\"0.000\"],[\"79598.00\",\"0.000\"],[\"79598.10\",\"0.000\"],[\"79598.20\",\"0.001\"],[\"79598.30\",\"0.380\"],[\"79598.40\",\"0.003\"],[\"79598.50\",\"0.000\"],[\"79598.60\",\"0.000\"],[\"79598.70\",\"0.000\"],[\"79598.80\",\"0.003\"],[\"79598.90\",\"0.001\"],[\"79599.00\",\"0.002\"],[\"79599.10\",\"0.000\"],[\"79599.20\",\"0.380\"],[\"79599.30\",\"0.268\"],[\"79599.40\",\"9.586\"],[\"79599.50\",\"0.002\"],[\"79599.60\",\"0.003\"],[\"79599.70\",\"0.001\"],[\"79599.90\",\"0.000\"],[\"79600.00\",\"0.232\"],[\"79600.10\",\"0.892\"],[\"79600.20\",\"0.000\"],[\"79600.30\",\"0.001\"],[\"79600.50\",\"0.073\"],[\"79600.80\",\"0.082\"],[\"79600.90\",\"0.257\"],[\"79601.00\",\"0.003\"],[\"79601.10\",\"0.000\"],[\"79601.20\",\"0.000\"],[\"79601.30\",\"0.000\"],[\"79601.40\",\"0.000\"],[\"79601.50\",\"2.500\"],[\"79601.60\",\"0.629\"],[\"79601.70\",\"1.246\"],[\"79601.80\",\"0.000\"],[\"79601.90\",\"0.026\"],[\"79602.00\",\"0.341\"],[\"79602.10\",\"0.000\"],[\"79602.20\",\"1.652\"],[\"79602.40\",\"0.011\"],[\"79602.80\",\"0.002\"],[\"79603.20\",\"0.005\"],[\"79603.40\",\"0.252\"],[\"79603.50\",\"0.136\"],[\"79603.60\",\"0.001\"],[\"79603.70\",\"0.003\"],[\"79603.80\",\"0.001\"],[\"79603.90\",\"0.000\"],[\"79604.00\",\"0.004\"],[\"79604.10\",\"0.538\"],[\"79604.20\",\"0.561\"],[\"79604.30\",\"0.817\"],[\"79604.40\",\"0.663\"],[\"79604.60\",\"0.001\"],[\"79604.80\",\"0.001\"],[\"79604.90\",\"0.038\"],[\"79605.00\",\"0.007\"],[\"79605.10\",\"2.192\"],[\"79605.20\",\"0.078\"],[\"79605.40\",\"0.001\"],[\"79605.50\",\"0.000\"],[\"79605.60\",\"0.023\"],[\"79605.80\",\"0.126\"],[\"79605.90\",\"0.000\"],[\"79606.00\",\"0.040\"],[\"79606.10\",\"0.003\"],[\"79606.40\",\"0.000\"],[\"79606.50\",\"0.002\"],[\"79606.60\",\"0.002\"],[\"79606.80\",\"0.003\"],[\"79607.00\",\"0.250\"],[\"79607.20\",\"0.334\"],[\"79607.40\",\"0.253\"],[\"79607.70\",\"1.373\"],[\"79607.80\",\"1.005\"],[\"79608.00\",\"1.117\"],[\"79608.20\",\"0.048\"],[\"79608.30\",\"0.001\"],[\"79608.60\",\"0.004\"],[\"79608.80\",\"0.044\"],[\"79608.90\",\"0.000\"],[\"79609.30\",\"0.452\"],[\"79609.40\",\"0.041\"],[\"79609.50\",\"1.859\"],[\"79609.60\",\"2.899\"],[\"79609.70\",\"1.216\"],[\"79609.80\",\"0.002\"],[\"79609.90\",\"0.630\"],[\"79610.00\",\"0.139\"],[\"79610.40\",\"0.188\"],[\"79610.70\",\"0.003\"],[\"79610.90\",\"3.047\"],[\"79611.00\",\"1.709\"],[\"79611.10\",\"0.541\"],[\"79611.30\",\"0.001\"],[\"79611.40\",\"0.000\"],[\"79611.50\",\"0.013\"],[\"79611.80\",\"0.001\"],[\"79612.00\",\"0.631\"],[\"79612.10\",\"0.392\"],[\"79612.20\",\"0.226\"],[\"79612.90\",\"0.431\"],[\"79613.10\",\"0.049\"],[\"79613.50\",\"0.628\"],[\"79613.70\",\"0.028\"],[\"79614.00\",\"0.281\"],[\"79614.10\",\"0.008\"],[\"79614.20\",\"0.713\"],[\"79614.40\",\"0.637\"],[\"79614.60\",\"0.022\"],[\"79614.80\",\"0.028\"],[\"79615.00\",\"0.030\"],[\"79615.10\",\"0.949\"],[\"79615.40\",\"1.294\"],[\"79615.60\",\"0.828\"],[\"79615.90\",\"0.002\"],[\"79616.00\",\"0.019\"],[\"79616.20\",\"0.003\"],[\"79616.30\",\"0.705\"],[\"79616.50\",\"0.002\"],[\"79616.60\",\"0.003\"],[\"79616.70\",\"0.272\"],[\"79616.80\",\"0.035\"],[\"79616.90\",\"0.044\"],[\"79617.60\",\"0.005\"],[\"79617.70\",\"0.048\"],[\"79618.10\",\"0.003\"],[\"79618.20\",\"0.630\"],[\"79618.30\",\"0.001\"],[\"79618.70\",\"0.001\"],[\"79618.90\",\"0.000\"],[\"79619.10\",\"0.584\"],[\"79619.20\",\"0.001\"],[\"79619.30\",\"0.362\"],[\"79619.40\",\"1.931\"],[\"79619.50\",\"0.009\"],[\"79619.70\",\"0.288\"],[\"79619.80\",\"0.004\"],[\"79619.90\",\"0.060\"],[\"79620.30\",\"0.023\"],[\"79620.40\",\"0.040\"],[\"79620.60\",\"6.990\"],[\"79621.20\",\"0.025\"],[\"79621.50\",\"0.001\"],[\"79621.70\",\"0.002\"],[\"79621.90\",\"0.000\"],[\"79622.00\",\"0.021\"],[\"79622.10\",\"0.014\"],[\"79622.40\",\"0.004\"],[\"79623.00\",\"0.060\"],[\"79623.10\",\"10.002\"],[\"79623.20\",\"0.547\"],[\"79623.30\",\"0.003\"],[\"79623.40\",\"0.002\"],[\"79624.00\",\"0.003\"],[\"79624.40\",\"0.090\"],[\"79624.50\",\"0.676\"],[\"79624.60\",\"0.028\"],[\"79624.70\",\"1.067\"],[\"79624.80\",\"0.616\"],[\"79625.10\",\"0.000\"],[\"79625.50\",\"0.045\"],[\"79625.60\",\"0.003\"],[\"79625.90\",\"0.001\"],[\"79626.30\",\"0.004\"],[\"79626.40\",\"0.546\"],[\"79626.60\",\"0.019\"],[\"79626.70\",\"0.001\"],[\"79627.10\",\"0.001\"],[\"79627.50\",\"0.051\"],[\"79627.60\",\"0.013\"],[\"79627.80\",\"0.002\"],[\"79628.10\",\"0.004\"],[\"79628.20\",\"0.248\"],[\"79628.90\",\"0.830\"],[\"79629.50\",\"0.256\"],[\"79629.60\",\"0.003\"],[\"79630.00\",\"0.307\"],[\"79630.30\",\"0.001\"],[\"79630.50\",\"0.137\"],[\"79630.60\",\"0.001\"],[\"79630.80\",\"0.000\"],[\"79630.90\",\"0.006\"],[\"79631.00\",\"0.123\"],[\"79631.30\",\"0.050\"],[\"79631.40\",\"0.002\"],[\"79631.50\",\"0.103\"],[\"79632.20\",\"0.039\"],[\"79632.30\",\"0.555\"],[\"79632.40\",\"0.748\"],[\"79632.50\",\"0.002\"],[\"79632.60\",\"0.380\"],[\"79632.80\",\"0.316\"],[\"79632.90\",\"0.003\"],[\"79633.30\",\"0.001\"],[\"79633.50\",\"0.003\"],[\"79633.70\",\"0.457\"],[\"79634.00\",\"0.002\"],[\"79634.70\",\"0.038\"],[\"79635.10\",\"0.556\"],[\"79635.40\",\"0.121\"],[\"79635.70\",\"0.327\"],[\"79635.80\",\"0.083\"],[\"79635.90\",\"0.876\"],[\"79636.10\",\"0.004\"],[\"79636.30\",\"0.001\"],[\"79636.40\",\"0.000\"],[\"79636.50\",\"0.515\"],[\"79636.70\",\"0.087\"],[\"79637.70\",\"0.002\"],[\"79637.90\",\"0.225\"],[\"79638.60\",\"0.000\"],[\"79638.80\",\"0.029\"],[\"79638.90\",\"0.001\"],[\"79639.20\",\"0.081\"],[\"79639.70\",\"0.000\"],[\"79639.90\",\"0.000\"],[\"79640.00\",\"0.383\"],[\"79640.10\",\"0.000\"],[\"79641.20\",\"0.202\"],[\"79641.30\",\"0.000\"],[\"79641.50\",\"0.129\"],[\"79641.90\",\"0.001\"],[\"79642.10\",\"0.003\"],[\"79643.00\",\"0.039\"],[\"79643.40\",\"0.250\"],[\"79643.60\",\"0.000\"],[\"79643.80\",\"0.601\"],[\"79644.50\",\"0.001\"],[\"79647.60\",\"0.000\"],[\"79648.30\",\"0.466\"],[\"79648.50\",\"0.000\"],[\"79649.10\",\"0.002\"],[\"79649.20\",\"0.019\"],[\"79649.60\",\"0.032\"],[\"79650.10\",\"0.002\"],[\"79650.20\",\"0.001\"],[\"79650.90\",\"0.001\"],[\"79651.20\",\"0.001\"],[\"79651.60\",\"0.009\"],[\"79652.20\",\"0.039\"],[\"79652.60\",\"0.090\"],[\"79652.80\",\"0.362\"],[\"79654.90\",\"0.031\"],[\"79655.20\",\"0.000\"],[\"79655.30\",\"0.000\"],[\"79656.40\",\"0.034\"],[\"79656.60\",\"1.381\"],[\"79658.90\",\"0.002\"],[\"79659.00\",\"0.321\"],[\"79659.20\",\"0.072\"],[\"79659.40\",\"0.005\"],[\"79659.70\",\"0.001\"],[\"79660.00\",\"1.024\"],[\"79660.10\",\"0.140\"],[\"79661.20\",\"0.210\"],[\"79662.70\",\"3.455\"],[\"79663.00\",\"0.007\"],[\"79663.40\",\"0.002\"],[\"79663.60\",\"0.041\"],[\"79664.10\",\"0.045\"],[\"79664.50\",\"0.000\"],[\"79665.20\",\"0.000\"],[\"79666.80\",\"0.054\"],[\"79666.90\",\"0.210\"],[\"79668.10\",\"0.017\"],[\"79668.20\",\"2.949\"],[\"79668.30\",\"0.178\"],[\"79668.50\",\"0.000\"],[\"79669.40\",\"0.001\"],[\"79670.60\",\"0.001\"],[\"79671.50\",\"0.001\"],[\"79671.60\",\"0.009\"],[\"79671.70\",\"0.000\"],[\"79674.40\",\"0.002\"],[\"79675.00\",\"0.000\"],[\"79675.70\",\"1.557\"],[\"79677.20\",\"0.000\"],[\"79679.50\",\"0.001\"],[\"79679.60\",\"26.347\"],[\"79679.70\",\"0.010\"],[\"79680.10\",\"0.010\"],[\"79680.40\",\"0.000\"],[\"79680.60\",\"0.000\"],[\"79682.40\",\"0.019\"],[\"79685.00\",\"0.000\"],[\"79687.60\",\"2.905\"],[\"79693.20\",\"0.002\"],[\"79694.40\",\"0.012\"],[\"79695.10\",\"0.002\"],[\"79695.90\",\"0.024\"],[\"79696.20\",\"0.102\"],[\"79696.60\",\"0.079\"],[\"79696.80\",\"0.000\"],[\"79696.90\",\"0.034\"],[\"79698.60\",\"0.079\"],[\"79702.20\",\"0.126\"],[\"79702.30\",\"0.001\"],[\"79707.30\",\"0.025\"],[\"79707.80\",\"8.782\"],[\"79708.00\",\"5.071\"],[\"79709.30\",\"1.508\"],[\"79712.00\",\"0.099\"],[\"79720.60\",\"0.000\"],[\"79722.60\",\"0.001\"],[\"79728.10\",\"0.680\"],[\"79730.40\",\"0.011\"],[\"79733.40\",\"0.000\"],[\"79735.40\",\"0.000\"],[\"79748.70\",\"0.032\"],[\"79749.30\",\"0.202\"],[\"79785.10\",\"1.192\"],[\"79785.20\",\"0.000\"],[\"79829.00\",\"1.191\"],[\"79829.10\",\"0.003\"],[\"79965.80\",\"0.000\"],[\"79965.90\",\"1.437\"],[\"79967.70\",\"0.000\"],[\"79967.80\",\"0.156\"],[\"79967.90\",\"0.879\"],[\"79993.80\",\"0.526\"],[\"79994.00\",\"0.204\"],[\"79997.60\",\"0.376\"],[\"79998.00\",\"0.708\"],[\"79999.60\",\"0.243\"],[\"79999.70\",\"0.001\"],[\"80005.20\",\"0.106\"],[\"80017.50\",\"0.000\"],[\"80021.90\",\"0.000\"],[\"80025.90\",\"0.001\"],[\"80029.90\",\"0.367\"],[\"80391.80\",\"0.002\"],[\"80393.60\",\"0.003\"],[\"80396.90\",\"0.000\"],[\"80397.60\",\"0.000\"],[\"80517.60\",\"9.596\"],[\"80517.70\",\"8.314\"],[\"80595.80\",\"0.013\"],[\"80596.30\",\"0.006\"],[\"80597.20\",\"3.070\"],[\"80597.30\",\"3.698\"],[\"80597.40\",\"0.000\"],[\"80597.60\",\"0.008\"],[\"80597.70\",\"0.004\"],[\"80598.20\",\"0.282\"],[\"80602.40\",\"2.609\"],[\"81187.70\",\"0.006\"],[\"81795.80\",\"0.976\"],[\"87540.00\",\"0.001\"],[\"87557.40\",\"0.001\"],[\"159174.70\",\"0.000\"],[\"159191.50\",\"0.010\"],[\"159213.70\",\"0.000\"],[\"159216.50\",\"0.000\"],[\"159223.50\",\"0.000\"],[\"159293.20\",\"0.000\"],[\"159294.30\",\"0.002\"],[\"159350.10\",\"0.000\"]],\"st\":1}}"}
