{"kind": "depth", "E": 1787080149813, "U": 11315332812613, "u": 11315332822404, "recv_ms": 1787080149759, "bids": [[14412.2, 0.406], [14512.2, 3.612], [14612.2, 0.182], [58240.9, 0.053], [61476.5, 0.001], [61476.6, 0.006], [63712.2, 5.509], [63838.6, 10.455], [63902.5, 0.111], [64065.1, 9.91], [64168.6, 0.034], [64388.6, 5.889], [64633.9, 33.592], [64636.9, 0.441], [64639.4, 0.0], [64641.4, 0.016], [64642.7, 0.146], [64644.8, 1.164], [64653.0, 0.051], [64654.7, 0.001], [64656.8, 0.021], [64660.4, 0.132], [64663.5, 0.0], [64665.7, 2.527], [64668.1, 0.0], [64668.5, 0.031], [64669.8, 0.0], [64685.3, 0.461], [64687.2, 0.295], [64687.4, 1.759], [64687.5, 0.475], [64687.7, 2.348], [64689.5, 0.004], [64690.6, 0.004], [64691.5, 0.34], [64691.6, 0.0], [64692.5, 0.746], [64692.6, 0.126], [64692.7, 5.008], [64693.1, 0.045], [64693.2, 0.559], [64693.5, 2.338], [64694.2, 0.232], [64694.7, 1.819], [64696.0, 0.104], [64696.1, 0.023], [64697.1, 0.723], [64697.3, 0.261], [64698.0, 1.024], [64698.2, 0.941], [64698.3, 0.008], [64698.7, 2.056], [64699.4, 0.258], [64700.8, 1.49], [64702.1, 3.066], [64702.3, 1.062], [64702.4, 0.468], [64703.7, 0.995], [64704.1, 0.173], [64704.2, 0.073], [64704.3, 0.142], [64704.8, 0.534], [64704.9, 0.256], [64705.0, 0.638], [64705.1, 0.217], [64705.2, 2.534], [64705.6, 0.399], [64705.7, 0.121], [64706.0, 0.002], [64706.1, 0.394], [64706.2, 0.774], [64706.3, 0.547], [64706.5, 0.026], [64706.6, 0.411], [64706.8, 0.0], [64707.2, 0.318], [64707.3, 0.117], [64707.4, 0.014], [64707.5, 0.001], [64707.7, 0.007], [64708.0, 0.006], [64708.2, 0.019], [64708.7, 0.087], [64708.8, 0.012], [64710.0, 0.01], [64710.4, 0.093], [64710.8, 0.084], [64711.0, 0.0], [64711.6, 0.262], [64711.7, 0.221], [64711.8, 0.174], [64712.0, 0.034], [64712.2, 26.175]], "asks": [[64712.3, 3.551], [64712.4, 0.06], [64712.9, 0.1], [64713.6, 0.101], [64713.7, 0.004], [64714.3, 0.001], [64714.4, 0.442], [64714.6, 0.016], [64714.7, 0.003], [64714.8, 0.002], [64715.1, 0.0], [64715.5, 0.003], [64715.7, 0.003], [64715.9, 0.023], [64716.0, 0.006], [64716.4, 0.002], [64716.6, 0.003], [64716.8, 0.037], [64716.9, 0.012], [64717.1, 0.189], [64717.2, 0.047], [64717.3, 0.003], [64717.5, 2.408], [64717.6, 0.002], [64717.8, 1.087], [64718.0, 0.001], [64718.1, 0.05], [64718.2, 0.086], [64718.3, 0.002], [64718.6, 0.087], [64718.7, 0.042], [64718.8, 0.0], [64718.9, 0.085], [64719.2, 0.011], [64719.3, 0.397], [64719.5, 0.014], [64719.7, 0.099], [64719.8, 0.778], [64719.9, 0.263], [64720.3, 0.17], [64721.4, 0.006], [64721.8, 0.004], [64721.9, 0.79], [64722.0, 1.298], [64722.2, 0.0], [64722.4, 1.324], [64723.5, 0.023], [64724.3, 0.069], [64725.3, 0.011], [64726.1, 0.218], [64726.5, 0.271], [64726.9, 0.011], [64727.7, 0.026], [64728.1, 0.503], [64728.6, 0.879], [64728.7, 0.418], [64729.4, 2.763], [64730.4, 0.252], [64730.6, 0.38], [64730.7, 0.928], [64731.4, 0.154], [64731.6, 0.008], [64731.7, 0.862], [64731.8, 0.005], [64731.9, 0.102], [64732.2, 0.064], [64732.7, 1.589], [64732.8, 2.271], [64733.2, 0.002], [64733.5, 0.558], [64734.3, 0.027], [64734.8, 0.017], [64735.1, 0.001], [64735.6, 0.003], [64735.9, 0.541], [64736.0, 1.606], [64736.2, 0.036], [64736.4, 0.111], [64737.2, 2.46], [64737.4, 0.005], [64737.5, 0.132], [64737.8, 0.014], [64738.3, 0.306], [64738.5, 0.515], [64738.6, 0.072], [64739.1, 0.416], [64739.3, 0.002], [64740.4, 3.503], [64741.9, 0.016], [64743.4, 0.016], [64744.2, 0.154], [64744.6, 0.144], [64745.7, 0.072], [64748.7, 0.001], [64749.2, 0.023], [64749.3, 1.536], [64754.6, 0.393], [64761.9, 0.005], [64775.7, 1.868], [64783.3, 0.0], [64789.9, 0.004], [64792.1, 0.0], [64803.1, 0.005], [64805.3, 38.181], [64868.5, 1.597], [64869.6, 10.407], [65359.4, 5.525], [65712.3, 0.027]]}
{"kind": "depth", "E": 1787080149915, "U": 11315332822417, "u": 11315332832531, "recv_ms": 1787080149857, "bids": [[1000.0, 35.81], [14412.2, 0.644], [14512.2, 3.5], [14612.2, 0.056], [58240.9, 0.053], [61476.5, 0.0], [61476.7, 0.004], [62123.7, 0.692], [63767.4, 1.444], [63882.5, 2.193], [63946.0, 3.44], [64065.1, 9.906], [64168.6, 0.005], [64593.7, 2.32], [64633.9, 0.0], [64634.5, 0.003], [64636.1, 0.0], [64638.3, 33.592], [64642.8, 0.002], [64647.4, 0.007], [64655.2, 0.025], [64666.9, 0.722], [64670.7, 0.163], [64676.4, 0.02], [64679.7, 0.0], [64679.8, 0.002], [64681.7, 0.161], [64682.4, 0.0], [64685.9, 0.0], [64686.3, 0.47], [64687.2, 0.297], [64687.7, 2.039], [64690.1, 0.313], [64691.5, 0.004], [64692.7, 5.023], [64693.1, 0.03], [64693.4, 0.131], [64693.8, 0.35], [64694.0, 1.917], [64695.7, 0.172], [64696.0, 0.853], [64696.2, 0.005], [64697.4, 0.01], [64697.7, 1.051], [64698.2, 0.016], [64698.3, 0.002], [64698.9, 0.026], [64699.7, 0.359], [64699.8, 0.008], [64701.3, 0.436], [64701.4, 0.463], [64702.1, 3.06], [64702.2, 0.001], [64702.4, 0.005], [64704.0, 1.078], [64704.4, 0.261], [64705.2, 2.41], [64705.3, 0.465], [64705.7, 0.079], [64706.2, 1.068], [64706.3, 0.008], [64706.4, 0.58], [64706.7, 0.033], [64707.4, 0.014], [64707.6, 0.002], [64707.7, 0.005], [64708.3, 0.18], [64708.6, 0.653], [64709.2, 0.26], [64709.3, 0.128], [64710.0, 0.069], [64710.1, 0.009], [64710.3, 0.001], [64710.4, 0.096], [64710.5, 0.009], [64711.2, 0.293], [64711.7, 0.237], [64712.1, 0.043], [64712.2, 25.866]], "asks": [[64712.3, 6.336], [64713.0, 0.304], [64713.1, 0.844], [64713.5, 0.082], [64714.5, 0.004], [64715.0, 0.003], [64715.5, 0.087], [64715.8, 0.022], [64716.0, 0.09], [64716.8, 0.036], [64716.9, 0.001], [64717.1, 0.109], [64717.2, 0.04], [64717.3, 0.02], [64718.1, 0.045], [64718.3, 0.01], [64718.8, 0.0], [64719.8, 0.758], [64719.9, 0.344], [64720.2, 0.229], [64720.5, 0.158], [64721.5, 0.012], [64721.8, 0.053], [64722.0, 0.398], [64722.1, 0.007], [64722.9, 0.0], [64724.2, 0.14], [64724.6, 0.309], [64725.0, 0.905], [64725.6, 0.628], [64726.3, 0.164], [64726.5, 0.265], [64726.9, 0.004], [64727.6, 0.002], [64727.9, 0.007], [64728.0, 1.028], [64728.7, 0.418], [64728.9, 0.011], [64730.0, 0.5], [64730.4, 0.212], [64730.5, 0.942], [64730.7, 0.003], [64731.2, 3.371], [64731.3, 0.169], [64731.6, 0.008], [64731.7, 0.847], [64732.2, 0.007], [64732.7, 1.583], [64732.8, 2.286], [64733.1, 0.32], [64733.4, 2.378], [64733.6, 0.504], [64734.3, 0.027], [64734.9, 0.848], [64735.9, 0.541], [64737.0, 0.349], [64737.5, 0.132], [64738.3, 0.312], [64739.1, 0.417], [64739.2, 3.415], [64745.2, 0.106], [64747.7, 0.002], [64749.3, 1.382], [64749.6, 0.241], [64750.9, 0.001], [64751.2, 10.008], [64755.5, 0.002], [64756.1, 0.0], [64757.6, 0.003], [64758.0, 0.904], [64782.2, 0.0], [64783.2, 0.376], [64788.2, 0.0], [64794.3, 36.054], [64796.5, 0.211], [64799.3, 0.013], [64805.3, 2.128], [64822.4, 0.014], [64850.5, 0.028], [65359.4, 5.521], [66006.5, 0.018]]}
{"kind": "depth", "E": 1787080150017, "U": 11315332832607, "u": 11315332839381, "recv_ms": 1787080149958, "bids": [[14412.2, 0.938], [14512.2, 3.262], [14612.2, 0.0], [58240.9, 0.053], [61476.5, 0.0], [62123.7, 0.689], [63676.8, 13.775], [63806.2, 45.758], [64065.1, 9.906], [64655.4, 0.17], [64666.3, 0.552], [64678.5, 0.005], [64681.0, 0.065], [64681.2, 1.658], [64681.7, 0.104], [64685.6, 0.154], [64687.6, 0.14], [64689.0, 0.223], [64691.8, 0.557], [64692.2, 0.184], [64693.2, 0.003], [64693.4, 0.247], [64693.6, 0.155], [64693.8, 0.368], [64694.1, 0.019], [64694.5, 0.019], [64694.7, 1.703], [64697.2, 0.949], [64697.7, 0.126], [64698.7, 2.21], [64698.8, 0.581], [64698.9, 0.025], [64699.4, 0.251], [64701.8, 0.002], [64705.3, 1.006], [64706.4, 0.039], [64707.2, 0.322], [64709.2, 0.319], [64710.0, 0.01], [64710.8, 0.315], [64712.2, 26.019]], "asks": [[64720.0, 0.377], [64720.9, 0.002], [64721.9, 0.713], [64722.5, 1.002], [64724.0, 1.058], [64725.0, 0.005], [64728.7, 0.436], [64729.3, 0.628], [64729.4, 3.688], [64730.5, 0.017], [64732.7, 1.64], [64733.4, 2.321], [64749.7, 0.156], [64749.9, 2.66], [64787.7, 36.277], [64794.3, 0.001], [65359.4, 5.521], [65650.6, 35.12], [65718.5, 12.991]]}
{"kind": "depth", "E": 1787080150119, "U": 11315332839644, "u": 11315332852833, "recv_ms": 1787080150059, "bids": [[1000.0, 35.81], [14412.2, 1.302], [14512.2, 2.898], [58240.9, 0.053], [61476.5, 0.0], [62123.7, 0.692], [63610.6, 0.627], [63647.5, 1.111], [63712.2, 5.489], [63870.9, 23.297], [64065.1, 9.906], [64388.6, 5.889], [64615.1, 2.336], [64632.8, 0.01], [64638.3, 0.0], [64642.7, 33.861], [64669.2, 0.001], [64669.7, 0.062], [64673.6, 1.209], [64680.7, 0.217], [64681.0, 0.008], [64690.2, 0.002], [64694.5, 0.018], [64696.7, 0.947], [64696.9, 0.31], [64697.2, 0.024], [64700.6, 0.245], [64704.0, 1.194], [64706.9, 0.006], [64707.2, 0.319], [64709.3, 0.004], [64710.0, 0.01], [64710.3, 0.125], [64712.2, 26.003]], "asks": [[64713.1, 0.001], [64714.5, 0.003], [64715.8, 0.825], [64715.9, 0.024], [64716.8, 0.037], [64717.3, 0.02], [64719.7, 0.099], [64719.8, 0.766], [64721.8, 0.045], [64722.1, 0.007], [64723.8, 0.007], [64725.9, 0.003], [64728.6, 0.959], [64734.8, 0.558], [64735.9, 0.0], [64736.4, 0.031], [64739.2, 3.414], [64748.6, 0.028], [64749.7, 0.002], [64766.7, 0.014], [64772.8, 1.279], [64777.3, 0.062], [64787.4, 0.186], [65359.4, 5.521], [65499.9, 1.534], [65712.3, 0.007], [66665.7, 1.926]]}
{"kind": "depth", "E": 1787080150221, "U": 11315332852988, "u": 11315332863228, "recv_ms": 1787080150164, "bids": [[1000.0, 35.81], [14412.2, 1.666], [14512.2, 2.534], [51769.8, 0.0], [58240.9, 0.053], [61476.5, 0.0], [63773.9, 49.473], [64003.8, 3.9], [64065.1, 9.906], [64175.9, 0.001], [64593.8, 0.009], [64605.5, 2.318], [64625.7, 0.024], [64625.8, 0.006], [64632.8, 0.011], [64633.9, 33.715], [64640.2, 1.278], [64642.7, 0.146], [64642.8, 0.002], [64647.4, 0.007], [64660.4, 0.133], [64663.3, 0.009], [64669.7, 0.063], [64679.6, 0.166], [64680.4, 0.221], [64680.7, 0.16], [64688.6, 0.033], [64690.2, 0.001], [64692.5, 0.592], [64696.5, 0.928], [64696.7, 0.022], [64701.8, 0.001], [64712.2, 26.046]], "asks": [[64717.3, 0.02], [64718.0, 0.004], [64719.7, 0.099], [64720.7, 0.005], [64721.8, 0.045], [64722.1, 0.007], [64722.5, 1.001], [64725.9, 0.003], [64729.0, 1.062], [64729.4, 2.763], [64734.8, 0.017], [64735.9, 0.541], [64739.2, 3.415], [64749.3, 3.156], [64750.6, 4.155], [64775.7, 1.872], [64787.2, 6.33], [64787.9, 0.002], [64799.3, 0.009], [64819.4, 2.321], [64850.0, 29.478], [65359.4, 5.521], [65597.8, 7.45], [65715.3, 12.37]]}
{"kind": "depth", "E": 1787080150323, "U": 11315332863261, "u": 11315332869423, "recv_ms": 1787080150264, "bids": [[14412.2, 2.016], [14512.2, 2.184], [51770.0, 0.0], [58240.9, 0.053], [61476.5, 0.0], [62123.7, 0.689], [63599.1, 0.63], [63712.2, 5.509], [63771.3, 0.095], [63859.3, 0.784], [63859.9, 5.77], [63949.1, 0.0], [64065.1, 9.906], [64175.9, 0.002], [64633.9, 0.0], [64638.3, 0.0], [64640.5, 33.715], [64679.6, 0.002], [64680.2, 0.071], [64680.4, 0.164], [64681.1, 0.001], [64688.6, 0.032], [64694.3, 0.001], [64695.2, 0.003], [64696.0, 0.851], [64696.3, 1.166], [64696.5, 0.003], [64697.2, 0.024], [64705.1, 0.758], [64705.3, 0.465], [64711.2, 0.251], [64712.2, 26.091]], "asks": [[64715.1, 0.084], [64717.3, 0.02], [64719.3, 0.313], [64719.7, 0.099], [64720.3, 0.212], [64721.8, 0.045], [64722.1, 0.007], [64725.9, 0.003], [64728.8, 1.531], [64729.0, 0.137], [64729.7, 2.185], [64732.1, 0.523], [64732.7, 1.583], [64733.0, 0.035], [64734.8, 0.558], [64735.9, 0.0], [65359.4, 5.521], [65499.0, 10.881], [65697.3, 0.001], [65712.3, 0.027]]}
{"kind": "depth", "E": 1787080150425, "U": 11315332869546, "u": 11315332875610, "recv_ms": 1787080150366, "bids": [[1000.0, 35.81], [14412.2, 2.366], [14512.2, 1.834], [51770.0, 0.0], [58240.9, 0.053], [61476.5, 0.0], [62123.7, 0.692], [63644.4, 5.809], [63773.9, 50.569], [63935.7, 47.813], [64065.1, 9.906], [64175.9, 0.003], [64388.6, 5.888], [64633.9, 33.715], [64640.5, 0.0], [64688.8, 0.008], [64694.3, 0.0], [64695.1, 1.083], [64702.4, 0.623], [64704.1, 0.157], [64705.4, 0.02], [64712.0, 0.057], [64712.2, 26.138]], "asks": [[64712.3, 6.336], [64717.3, 0.02], [64719.6, 0.008], [64719.7, 0.099], [64721.8, 0.192], [64722.1, 0.162], [64725.2, 0.135], [64725.3, 0.013], [64725.9, 0.003], [64726.1, 0.218], [64730.5, 0.002], [64733.5, 1.176], [64738.5, 0.53], [64766.7, 0.0], [64817.0, 0.019], [65359.4, 5.521], [65521.2, 14.872], [65686.3, 0.266], [65934.3, 1.482]]}
{"kind": "depth", "E": 1787080150527, "U": 11315332875733, "u": 11315332881316, "recv_ms": 1787080150468, "bids": [[1000.0, 35.81], [14412.2, 2.73], [14512.2, 1.47], [58240.9, 0.053], [61476.5, 0.0], [62123.7, 0.689], [62273.2, 0.004], [63418.0, 9.308], [63712.2, 5.489], [64065.1, 9.906], [64175.9, 0.004], [64633.9, 0.0], [64638.3, 33.715], [64688.8, 0.007], [64692.5, 0.593], [64712.1, 0.042], [64712.2, 26.211]], "asks": [[64717.3, 0.175], [64719.7, 0.254], [64721.8, 0.347], [64722.1, 0.472], [64725.9, 0.158], [64728.8, 0.606], [64729.5, 0.93], [64732.1, 0.466], [64732.8, 2.343], [64734.3, 0.568], [64734.8, 0.017], [64735.9, 0.0], [64766.7, 0.0], [64813.1, 0.007], [65035.9, 3.997], [65359.4, 5.521], [65359.5, 0.001], [65585.9, 4.97], [65641.9, 0.0], [65712.3, 0.007]]}
{"kind": "depth", "E": 1787080150629, "U": 11315332881451, "u": 11315332887382, "recv_ms": 1787080150574, "bids": [[14412.2, 3.094], [14512.2, 1.106], [51770.0, 0.0], [58240.9, 0.053], [61476.5, 0.0], [62123.7, 0.692], [64065.1, 9.906], [64615.1, 2.344], [64638.3, 0.0], [64642.7, 33.861], [64683.1, 0.35], [64688.2, 0.316], [64690.1, 0.004], [64690.8, 0.558], [64691.5, 0.34], [64691.8, 0.003], [64692.5, 0.709], [64693.0, 0.002], [64693.4, 0.131], [64693.9, 0.64], [64695.1, 0.465], [64698.3, 0.009], [64698.8, 0.574], [64699.7, 0.023], [64702.4, 0.005], [64704.1, 0.157], [64705.1, 0.681], [64705.4, 0.097], [64705.5, 0.349], [64706.6, 0.102], [64707.1, 0.379], [64707.2, 0.318], [64709.3, 0.005], [64709.5, 0.094], [64710.1, 0.001], [64712.2, 26.126]], "asks": [[64712.3, 7.326], [64713.6, 0.102], [64714.6, 0.1], [64715.9, 0.023], [64717.3, 0.02], [64718.9, 0.001], [64719.4, 0.04], [64719.6, 0.085], [64719.7, 0.099], [64719.9, 0.343], [64720.0, 0.3], [64721.7, 0.002], [64721.8, 0.184], [64721.9, 0.258], [64722.1, 0.162], [64722.2, 0.463], [64723.7, 0.313], [64724.6, 0.0], [64725.3, 0.013], [64725.9, 0.003], [64727.2, 1.859], [64728.5, 0.926], [64728.9, 0.004], [64729.5, 0.005], [64731.0, 0.624], [64733.5, 0.62], [64734.1, 0.01], [64734.8, 0.01], [64735.4, 0.497], [64737.5, 0.017], [64739.2, 3.414], [64749.4, 0.464], [65359.4, 5.521]]}
{"kind": "depth", "E": 1787080150731, "U": 11315332887434, "u": 11315332893496, "recv_ms": 1787080150672, "bids": [[1000.0, 35.81], [14412.2, 3.444], [14512.2, 0.756], [58240.9, 0.053], [61476.5, 0.0], [63712.2, 4.412], [64065.1, 9.906], [64388.6, 5.877], [64582.7, 0.003], [64633.9, 0.0], [64638.3, 33.715], [64642.7, 0.146], [64644.8, 1.173], [64686.4, 1.589], [64690.6, 0.053], [64691.5, 0.004], [64692.5, 0.708], [64692.7, 5.177], [64692.9, 0.617], [64693.1, 0.03], [64693.4, 0.061], [64695.5, 0.337], [64696.0, 0.851], [64696.5, 0.004], [64697.3, 0.212], [64698.7, 2.051], [64700.8, 1.488], [64706.4, 0.041], [64709.2, 0.317], [64710.5, 0.002], [64710.9, 0.012], [64712.0, 0.141], [64712.2, 26.126]], "asks": [[64712.3, 4.049], [64713.6, 0.101], [64714.6, 0.016], [64715.1, 0.0], [64717.2, 0.04], [64717.3, 0.02], [64717.5, 2.409], [64718.0, 0.001], [64719.4, 0.039], [64719.7, 0.223], [64719.9, 0.343], [64720.2, 0.23], [64722.1, 0.162], [64723.0, 0.903], [64723.5, 0.021], [64724.0, 0.158], [64724.5, 0.003], [64725.9, 0.003], [64726.1, 0.216], [64728.0, 1.028], [64728.1, 0.505], [64728.5, 0.001], [64729.2, 1.041], [64731.0, 0.068], [64731.8, 0.561], [64733.5, 0.002], [64734.0, 0.303], [64734.3, 0.027], [64734.8, 0.01], [64735.4, 0.382], [64735.9, 0.541], [64736.0, 1.721], [64749.4, 0.31], [64749.8, 0.218], [64766.7, 0.014], [64805.6, 0.056], [65359.4, 5.521], [65521.2, 15.214], [65712.3, 0.027], [65747.7, 4.252], [65922.4, 3.18]]}
{"kind": "depth", "E": 1787080150833, "U": 11315332893624, "u": 11315332899431, "recv_ms": 1787080150773, "bids": [[1000.0, 35.81], [14312.2, 0.042], [14412.2, 3.71], [14512.2, 0.448], [58240.9, 0.053], [61476.5, 0.0], [62123.7, 0.689], [64065.1, 9.906], [64638.3, 0.0], [64640.5, 33.715], [64657.5, 0.272], [64658.9, 0.001], [64666.4, 6.027], [64692.7, 5.175], [64693.3, 1.256], [64696.5, 0.003], [64698.5, 0.013], [64704.0, 0.202], [64705.0, 1.538], [64712.2, 26.311]], "asks": [[64717.2, 0.102], [64717.3, 1.812], [64717.4, 0.94], [64719.7, 0.223], [64721.3, 0.001], [64722.1, 0.164], [64722.9, 0.003], [64724.5, 0.001], [64725.7, 0.004], [64725.9, 0.003], [64749.8, 0.218], [64751.2, 10.01], [64752.3, 0.034], [65035.9, 3.998], [65359.4, 5.521], [65531.8, 0.996]]}
{"kind": "depth", "E": 1787080150935, "U": 11315332899648, "u": 11315332905856, "recv_ms": 1787080150876, "bids": [[14312.2, 0.224], [14412.2, 3.71], [14512.2, 0.266], [58240.9, 0.053], [61476.6, 0.008], [62123.7, 0.692], [63712.2, 4.392], [63911.6, 1.796], [64065.1, 9.908], [64633.9, 33.715], [64640.5, 0.0], [64680.2, 0.014], [64680.6, 0.059], [64681.5, 0.049], [64692.5, 0.592], [64693.2, 0.119], [64694.1, 0.019], [64696.2, 0.003], [64696.3, 0.241], [64696.7, 0.947], [64697.6, 2.71], [64698.5, 0.012], [64699.8, 0.009], [64701.5, 0.061], [64704.0, 0.135], [64704.1, 0.003], [64705.1, 0.14], [64705.3, 1.006], [64706.3, 0.008], [64710.2, 0.231], [64710.8, 0.084], [64712.2, 26.317]], "asks": [[64714.1, 0.015], [64717.2, 0.102], [64719.7, 0.223], [64722.1, 0.164], [64725.9, 0.003], [64728.7, 0.434], [64729.2, 0.116], [64730.1, 0.926], [64731.8, 0.005], [64732.5, 0.632], [64732.8, 2.286], [64733.4, 2.378], [64736.0, 1.606], [64736.9, 0.554], [65038.0, 0.814], [65359.4, 5.521], [65712.3, 0.007]]}
{"kind": "depth", "E": 1787080151037, "U": 11315332905960, "u": 11315332913130, "recv_ms": 1787080150996, "bids": [[1000.0, 35.81], [14312.2, 0.462], [14412.2, 3.584], [14512.2, 0.154], [58240.9, 0.053], [62123.7, 0.689], [62758.8, 2.046], [63709.2, 18.272], [64065.1, 9.906], [64388.6, 5.887], [64633.9, 0.0], [64642.7, 33.861], [64668.5, 0.185], [64692.5, 0.746], [64692.7, 5.021], [64696.2, 0.005], [64699.8, 0.008], [64700.6, 0.25], [64701.3, 0.437]], "asks": [[64728.7, 0.436], [64729.3, 1.553], [64730.1, 0.001], [64732.6, 0.127], [64733.4, 2.321], [64734.2, 1.345], [64735.6, 0.001], [64773.7, 0.003], [64773.8, 0.243], [65359.4, 5.521], [65747.7, 5.315], [65842.0, 2.259]]}
{"kind": "depth", "E": 1787080151139, "U": 11315332913415, "u": 11315332921623, "recv_ms": 1787080151080, "bids": [[1000.0, 35.81], [14312.2, 0.7], [14412.2, 3.472], [14512.2, 0.028], [51770.0, 0.0], [58240.9, 0.053], [61476.5, 0.0], [63418.0, 9.311], [63712.2, 4.412], [63725.1, 0.034], [63725.3, 0.026], [64065.1, 9.906], [64619.3, 0.02], [64619.4, 0.0], [64625.7, 0.025], [64632.7, 6.954], [64632.8, 2.233], [64640.2, 1.279], [64657.7, 0.77], [64660.3, 0.016], [64660.4, 0.131], [64663.3, 0.01], [64669.7, 0.064], [64680.2, 0.071], [64680.6, 0.002], [64692.5, 0.746], [64692.7, 5.021], [64692.8, 1.471], [64695.5, 0.338], [64696.3, 1.166], [64696.7, 0.022], [64698.0, 1.178], [64698.7, 1.897], [64700.6, 0.245], [64701.3, 0.436], [64703.8, 1.597], [64705.1, 0.681], [64705.3, 0.465], [64706.3, 0.008], [64708.4, 0.06], [64709.2, 0.258], [64710.5, 0.009], [64710.9, 0.005], [64711.8, 0.181], [64712.2, 26.309]], "asks": [[64712.3, 7.062], [64714.5, 0.004], [64715.3, 0.312], [64716.0, 0.093], [64717.2, 0.102], [64717.5, 2.408], [64717.6, 0.003], [64717.9, 0.002], [64719.7, 0.223], [64720.2, 0.229], [64720.4, 0.08], [64722.1, 0.164], [64723.0, 0.003], [64723.8, 0.006], [64725.9, 0.003], [64728.8, 1.531], [64728.9, 0.164], [64729.3, 0.628], [64730.5, 0.009], [64731.2, 3.211], [64731.9, 0.095], [64734.8, 0.551], [64735.9, 0.0], [64746.0, 0.707], [64748.6, 0.028], [64755.5, 0.0], [64756.0, 3.517], [64766.7, 0.0], [64781.3, 1.206], [64910.5, 0.003], [64910.6, 0.0], [65359.4, 5.521], [65699.3, 1.328], [65712.3, 0.027], [66006.5, 0.018]]}
{"kind": "depth", "E": 1787080151241, "U": 11315332921783, "u": 11315332927149, "recv_ms": 1787080151183, "bids": [[14312.2, 1.022], [14412.2, 3.178], [14512.2, 0.0], [51769.8, 0.0], [51770.0, 0.0], [58240.9, 0.053], [61476.5, 0.0], [62123.7, 0.692], [63712.2, 4.392], [64065.1, 9.906], [64633.9, 34.085], [64634.5, 0.0], [64642.7, 0.146], [64679.3, 2.328], [64679.4, 0.009], [64679.5, 2.852], [64679.8, 0.005], [64682.8, 0.016], [64682.9, 1.309], [64683.0, 0.002], [64690.9, 0.013], [64692.5, 0.592], [64695.5, 0.337], [64706.3, 0.008], [64707.3, 0.302], [64711.8, 0.174], [64712.2, 26.102]], "asks": [[64712.3, 7.062], [64715.2, 0.087], [64717.2, 0.257], [64719.7, 0.378], [64720.4, 0.079], [64722.1, 0.629], [64724.0, 1.058], [64725.9, 0.158], [64748.6, 0.028], [64757.6, 0.003], [65359.4, 5.521], [65363.1, 0.001], [65699.2, 0.021], [65712.3, 0.007]]}
{"kind": "depth", "E": 1787080151343, "U": 11315332927209, "u": 11315332932581, "recv_ms": 1787080151283, "bids": [[1000.0, 35.81], [14312.2, 1.386], [14412.2, 2.814], [58240.9, 0.053], [61476.7, 0.002], [62123.7, 0.689], [63029.6, 0.001], [63744.9, 0.003], [64065.1, 9.906], [64388.6, 5.877], [64633.9, 0.0], [64640.5, 34.085], [64642.7, 0.146], [64647.5, 0.004], [64690.9, 0.012], [64692.3, 0.046], [64699.2, 0.008], [64712.2, 26.131]], "asks": [[64712.3, 4.889], [64714.5, 0.003], [64716.0, 0.09], [64717.1, 0.11], [64717.2, 0.102], [64717.6, 0.002], [64719.6, 0.008], [64719.7, 0.223], [64719.8, 0.844], [64721.8, 0.029], [64721.9, 0.25], [64722.1, 0.017], [64725.9, 0.003], [64728.8, 0.606], [64729.1, 0.938], [64730.5, 0.002], [64730.8, 1.354], [64731.1, 1.336], [64731.2, 1.731], [64748.6, 0.028], [64766.7, 0.014], [64777.0, 0.076], [65359.4, 5.521], [65521.2, 15.443], [65618.3, 31.112], [65628.9, 5.211]]}
{"kind": "depth", "E": 1787080151445, "U": 11315332932609, "u": 11315332938252, "recv_ms": 1787080151385, "bids": [[1000.0, 35.81], [14312.2, 1.736], [14412.2, 2.464], [58240.9, 0.053], [62123.7, 0.692], [63775.7, 0.393], [64065.1, 9.908], [64640.5, 0.0], [64642.7, 34.231], [64692.2, 0.338], [64697.9, 0.016], [64699.2, 0.007]], "asks": [[64715.3, 0.002], [64849.7, 0.028], [65359.4, 5.521], [65618.3, 31.568]]}
{"kind": "depth", "E": 1787080151547, "U": 11315332938282, "u": 11315332944985, "recv_ms": 1787080151487, "bids": [[14312.2, 2.1], [14412.2, 2.1], [58240.9, 0.053], [61476.5, 0.0], [62123.7, 0.689], [63558.9, 1.493], [63712.2, 4.412], [63809.6, 1.566], [63935.7, 48.032], [64065.1, 9.906], [64194.5, 8.568], [64605.5, 2.318], [64666.9, 0.725], [64694.9, 0.468], [64695.1, 1.083], [64695.2, 0.001], [64697.9, 0.015], [64699.2, 0.01], [64702.1, 3.061], [64702.4, 0.623], [64712.2, 26.13]], "asks": [[64712.3, 4.888], [64715.2, 0.397], [64717.2, 0.102], [64717.8, 1.09], [64719.7, 0.223], [64722.1, 0.017], [64725.9, 0.003], [64726.1, 0.834], [64733.5, 0.62], [64766.7, 0.0], [64819.4, 2.321], [64822.4, 0.017], [64869.6, 6.331], [65035.9, 3.997], [65359.4, 5.521], [65359.5, 0.0], [65712.3, 0.027]]}
{"kind": "depth", "E": 1787080151649, "U": 11315332945245, "u": 11315332952560, "recv_ms": 1787080151592, "bids": [[1000.0, 35.81], [14312.2, 2.45], [14412.2, 1.75], [51770.0, 0.0], [58240.9, 0.053], [61476.5, 0.0], [61476.6, 0.01], [63767.4, 1.834], [64065.1, 9.906], [64388.6, 5.888], [64633.9, 34.085], [64642.7, 0.146], [64651.7, 0.001], [64651.8, 0.055], [64660.4, 0.231], [64690.8, 0.002], [64691.3, 0.577], [64696.3, 0.241], [64696.8, 0.926], [64705.2, 2.719], [64705.5, 0.04], [64710.2, 0.0], [64710.5, 0.24], [64711.8, 0.181], [64712.2, 26.123]], "asks": [[64712.3, 4.048], [64717.2, 0.257], [64719.7, 0.378], [64719.8, 0.843], [64720.0, 0.301], [64721.8, 0.647], [64721.9, 0.25], [64722.1, 0.327], [64722.2, 0.0], [64725.3, 0.012], [64725.9, 0.158], [64726.1, 0.216], [64731.5, 0.558], [64732.5, 0.076], [64733.5, 0.002], [64734.8, 0.01], [64735.9, 0.656], [64736.9, 0.439], [64766.7, 0.014], [64810.6, 0.202], [64869.6, 8.555], [65359.4, 5.521]]}
{"kind": "depth", "E": 1787080151751, "U": 11315332952779, "u": 11315332960086, "recv_ms": 1787080151693, "bids": [[1000.0, 35.81], [14312.2, 2.814], [14412.2, 1.386], [51770.0, 0.0], [58240.9, 0.053], [61476.5, 0.0], [62123.7, 0.692], [63547.4, 9.969], [63615.5, 0.788], [63712.2, 4.392], [63816.6, 0.33], [64065.1, 9.906], [64582.7, 0.003], [64633.9, 0.0], [64638.3, 34.085], [64690.7, 0.716], [64691.3, 0.021], [64692.5, 0.708], [64693.2, 0.003], [64696.1, 0.948], [64696.8, 0.001], [64702.1, 3.06], [64703.9, 0.022], [64704.2, 0.074], [64705.1, 0.681], [64712.2, 26.125]], "asks": [[64715.2, 0.313], [64715.5, 0.003], [64717.2, 0.102], [64718.9, 0.085], [64719.7, 0.223], [64721.7, 0.002], [64721.8, 0.029], [64721.9, 0.258], [64722.1, 0.009], [64722.2, 0.463], [64725.3, 0.013], [64725.9, 0.003], [64731.8, 0.062], [64732.6, 0.07], [64734.1, 0.003], [64734.3, 0.568], [64734.4, 1.247], [64735.9, 0.115], [65359.4, 5.521], [65712.3, 0.007]]}
{"kind": "depth", "E": 1787080151853, "U": 11315332960267, "u": 11315332968740, "recv_ms": 1787080151804, "bids": [[14312.2, 3.164], [14412.2, 1.036], [58240.9, 0.053], [61476.5, 0.0], [62123.7, 0.689], [63989.3, 1.561], [64065.1, 9.906], [64388.6, 5.889], [64597.4, 0.384], [64600.6, 0.325], [64619.2, 1.222], [64619.3, 0.017], [64629.8, 0.006], [64633.0, 0.063], [64662.2, 0.002], [64665.4, 0.0], [64680.2, 0.014], [64680.8, 0.057], [64694.6, 0.005], [64696.1, 0.023], [64697.0, 1.022], [64697.8, 0.003], [64701.1, 1.247], [64703.1, 0.324], [64704.2, 0.073], [64706.9, 0.007], [64707.3, 0.117], [64707.6, 0.004], [64708.2, 0.017], [64712.1, 0.043], [64712.2, 26.233]], "asks": [[64715.2, 0.003], [64715.6, 0.085], [64716.9, 0.003], [64717.2, 0.102], [64719.7, 0.223], [64720.0, 0.299], [64721.8, 0.037], [64721.9, 0.25], [64722.1, 0.009], [64723.4, 0.024], [64725.3, 0.012], [64725.9, 0.003], [64726.9, 0.002], [64731.8, 0.003], [64732.8, 2.343], [64734.3, 0.027], [64735.9, 0.656], [64765.4, 0.31], [64797.8, 0.002], [64830.2, 0.137], [65035.9, 3.996], [65359.4, 5.521], [65531.7, 0.005]]}
{"kind": "depth", "E": 1787080151955, "U": 11315332968961, "u": 11315332975006, "recv_ms": 1787080151897, "bids": [[1000.0, 35.81], [14312.2, 3.528], [14412.2, 0.672], [58240.9, 0.053], [62123.7, 0.692], [63712.2, 4.412], [63753.0, 1.257], [64065.1, 9.906], [64388.6, 5.879], [64638.3, 0.0], [64640.5, 34.085], [64689.4, 1.045], [64692.2, 0.338], [64696.2, 0.003], [64696.9, 0.347], [64697.3, 0.376], [64712.2, 26.248]], "asks": [[64717.2, 0.102], [64717.8, 1.087], [64719.7, 0.223], [64721.8, 0.029], [64722.1, 0.017], [64725.9, 0.003], [64728.7, 0.434], [64729.9, 0.004], [64762.3, 0.633], [64794.7, 0.002], [64827.1, 0.631], [65359.4, 5.521], [65488.8, 49.943], [65712.3, 0.027], [65750.8, 0.001], [66006.5, 0.015]]}
{"kind": "depth", "E": 1787080152057, "U": 11315332975078, "u": 11315332980545, "recv_ms": 1787080151996, "bids": [[1000.0, 35.81], [14212.2, 0.07], [14312.2, 3.738], [14412.2, 0.392], [58240.9, 0.053], [61476.5, 0.0], [62123.7, 0.689], [63418.0, 9.314], [63847.9, 3.517], [64065.1, 9.906], [64633.9, 34.085], [64640.5, 0.0], [64685.8, 1.841], [64687.4, 0.637], [64687.6, 1.899], [64696.2, 0.005], [64700.6, 0.245], [64706.9, 0.006], [64712.2, 26.248]], "asks": [[64715.2, 0.087], [64717.2, 0.102], [64719.7, 0.223], [64721.8, 0.029], [64722.1, 0.017], [64725.3, 0.013], [64725.9, 0.003], [64728.7, 0.436], [64729.1, 0.013], [64729.4, 3.688], [65359.4, 5.521], [65488.8, 51.468], [65724.9, 6.261]]}
{"kind": "depth", "E": 1787080152159, "U": 11315332980729, "u": 11315332988863, "recv_ms": 1787080152103, "bids": [[14212.2, 0.28], [14312.2, 3.682], [14412.2, 0.238], [51770.0, 0.044], [58240.9, 0.053], [61476.5, 0.0], [63712.2, 4.392], [63725.1, 0.042], [63725.3, 0.018], [63741.5, 27.766], [63965.0, 3.402], [64065.1, 9.906], [64388.6, 5.879], [64632.8, 2.234], [64633.9, 0.0], [64638.3, 34.451], [64639.9, 6.025], [64640.2, 1.28], [64660.4, 0.232], [64663.3, 0.011], [64680.0, 3.044], [64680.8, 0.057], [64696.1, 0.023], [64697.0, 1.022], [64711.7, 0.214]], "asks": [[64712.3, 4.05], [64717.2, 0.102], [64719.7, 0.223], [64721.6, 0.003], [64721.8, 0.037], [64722.1, 0.009], [64725.3, 0.012], [64725.9, 0.003], [64728.6, 0.959], [64729.4, 2.763], [64729.5, 0.93], [64731.9, 0.095], [64732.8, 2.343], [64734.3, 0.027], [64734.8, 0.01], [64735.9, 0.656], [65359.4, 5.521], [65699.3, 1.32], [65712.3, 0.007], [65715.3, 12.977]]}
{"kind": "depth", "E": 1787080152261, "U": 11315332989007, "u": 11315332995618, "recv_ms": 1787080152206, "bids": [[1000.0, 35.81], [14212.2, 0.518], [14312.2, 3.556], [14412.2, 0.126], [51769.8, 0.0], [51770.0, 0.0], [58240.9, 0.053], [61476.5, 0.004], [62123.7, 0.692], [64065.1, 9.906], [64702.4, 0.005]], "asks": [[64712.3, 4.061], [64717.2, 0.273], [64717.3, 1.796], [64719.6, 0.016], [64719.7, 0.378], [64719.8, 0.835], [64721.8, 0.029], [64722.1, 0.482], [64725.3, 0.013], [64725.9, 0.158], [65359.4, 5.521], [65699.2, 0.029], [65747.7, 5.74]]}
{"kind": "depth", "E": 1787080152363, "U": 11315332995678, "u": 11315333001858, "recv_ms": 1787080152304, "bids": [[1000.0, 35.81], [14212.2, 0.756], [14312.2, 3.444], [14412.2, 0.0], [58240.9, 0.053], [61476.5, 0.004], [62123.7, 0.689], [63712.2, 4.412], [63838.6, 11.08], [63911.6, 1.562], [63955.1, 3.282], [64065.1, 9.906], [64554.6, 0.031], [64571.6, 0.0], [64691.7, 0.657], [64692.2, 0.184], [64698.5, 0.014], [64698.8, 0.59], [64712.2, 26.246]], "asks": [[64717.2, 0.118], [64719.7, 0.223], [64721.8, 0.029], [64722.1, 0.017], [64725.3, 0.012], [64725.9, 0.003], [64730.5, 0.004], [64730.7, 0.019], [64852.6, 0.001], [64868.5, 0.731], [64869.6, 0.001], [65359.4, 5.521], [65499.0, 9.356], [65631.2, 2.953], [65712.3, 0.027]]}
{"kind": "depth", "E": 1787080152465, "U": 11315333002027, "u": 11315333008017, "recv_ms": 1787080152409, "bids": [[14212.2, 1.106], [14312.2, 3.094], [58240.9, 0.053], [61476.5, 0.004], [62123.7, 0.692], [63029.6, 0.0], [63819.6, 0.0], [63880.3, 1.645], [64065.1, 9.906], [64388.6, 5.879], [64554.6, 3.969], [64571.6, 3.139], [64571.7, 1.199], [64655.9, 0.004], [64663.4, 0.002], [64666.9, 0.725], [64679.8, 0.002], [64698.7, 2.058]], "asks": [[64712.3, 4.075], [64717.2, 0.118], [64719.7, 0.223], [64721.8, 0.029], [64722.1, 0.017], [64725.3, 0.013], [64725.9, 0.003], [64757.6, 0.003], [64775.7, 1.868], [64782.4, 1.254], [64822.4, 0.014], [64852.6, 5.398], [64869.5, 10.414], [65359.4, 5.521], [65521.2, 15.701]]}
{"kind": "depth", "E": 1787080152567, "U": 11315333008052, "u": 11315333013440, "recv_ms": 1787080152507, "bids": [[1000.0, 35.81], [14212.2, 1.47], [14312.2, 2.73], [58240.9, 0.053], [63712.2, 4.392], [63867.6, 0.277], [63903.3, 13.872], [64065.1, 9.906], [64132.9, 0.161], [64655.9, 0.0], [64666.5, 0.648], [64680.4, 0.166]], "asks": [[64746.8, 0.032], [65359.4, 5.521], [65712.3, 0.007]]}
{"kind": "depth", "E": 1787080152669, "U": 11315333013565, "u": 11315333018553, "recv_ms": 1787080152610, "bids": [[1000.0, 35.81], [14212.2, 1.82], [14312.2, 2.38], [51770.0, 0.0], [58240.9, 0.053], [61476.5, 0.004], [62123.7, 0.689], [63589.6, 1.257], [63806.2, 48.106], [63913.2, 2.344], [64065.1, 9.906], [64133.5, 0.004], [64388.6, 5.878], [64571.6, 2.618], [64690.7, 0.16], [64691.5, 0.56], [64692.5, 0.592], [64693.3, 1.372], [64693.6, 0.162], [64693.9, 0.633], [64701.6, 0.62], [64712.2, 26.191]], "asks": [[64712.3, 4.077], [64717.2, 0.273], [64717.9, 0.005], [64718.3, 0.32], [64719.7, 0.378], [64721.6, 0.002], [64721.7, 0.157], [64721.8, 0.029], [64721.9, 0.25], [64722.1, 0.327], [64722.2, 0.463], [64725.3, 0.013], [64725.9, 0.158], [64731.5, 0.002], [64731.8, 0.559], [64732.6, 0.688], [64766.7, 0.0], [64775.7, 1.872], [64782.4, 1.25], [64852.6, 5.398], [64869.5, 7.747], [65359.4, 5.521], [65694.7, 0.764], [65821.0, 0.758]]}
{"kind": "depth", "E": 1787080152771, "U": 11315333018687, "u": 11315333024097, "recv_ms": 1787080152712, "bids": [[14212.2, 2.184], [14312.2, 2.016], [58240.9, 0.053], [62123.7, 0.692], [63418.0, 9.311], [63551.5, 0.673], [63712.2, 4.412], [64065.1, 9.906], [64107.3, 2.693], [64168.6, 0.029], [64388.6, 5.888], [64582.7, 0.003], [64593.9, 0.032], [64647.5, 0.004], [64679.6, 0.002]], "asks": [[64717.2, 0.118], [64719.7, 0.223], [64721.7, 0.002], [64722.1, 0.017], [64725.3, 0.012], [64725.9, 0.003], [64750.6, 4.155], [64787.9, 0.002], [64791.2, 0.012], [64792.2, 0.014], [64792.3, 0.0], [64796.6, 3.805], [64850.0, 29.478], [65035.9, 3.997], [65359.4, 5.521], [65712.3, 0.027]]}
{"kind": "depth", "E": 1787080152873, "U": 11315333024305, "u": 11315333044797, "recv_ms": 1787080152814, "bids": [[1000.0, 35.81], [14212.2, 2.548], [14312.2, 1.652], [58240.9, 0.053], [61476.5, 0.004], [61476.7, 0.0], [62123.7, 0.689], [63615.5, 0.003], [63903.3, 14.653], [64065.1, 9.906], [64388.6, 5.887], [64571.6, 2.62], [64571.7, 0.838], [64691.7, 0.503], [64691.8, 0.157], [64710.4, 0.097], [64712.2, 26.208]], "asks": [[64714.7, 0.087], [64715.3, 0.312], [64717.2, 0.118], [64718.9, 0.001], [64719.7, 0.223], [64722.1, 0.017], [64725.3, 0.013], [64725.9, 0.003], [64766.7, 0.014], [64852.6, 5.398], [64869.5, 8.409], [65359.4, 5.521], [65610.7, 3.041], [65823.5, 1.518]]}
{"kind": "depth", "E": 1787080152975, "U": 11315333044842, "u": 11315333057863, "recv_ms": 1787080152920, "bids": [[1000.0, 35.81], [14212.2, 2.898], [14312.2, 1.302], [58240.9, 0.053], [61476.5, 0.004], [62123.7, 0.692], [63418.0, 9.308], [63550.7, 0.0], [63579.7, 5.732], [63712.2, 4.392], [63911.7, 0.003], [64065.1, 9.906], [64097.4, 15.21], [64654.1, 0.021], [64654.5, 0.001], [64654.8, 0.002], [64655.1, 0.36], [64655.4, 0.138], [64671.2, 1.071], [64671.6, 0.047], [64671.8, 0.039], [64671.9, 0.818], [64672.2, 1.027], [64672.5, 0.003], [64686.2, 0.002], [64686.3, 0.4], [64686.4, 1.449], [64686.5, 0.034], [64686.7, 0.097], [64686.8, 0.023], [64686.9, 0.371], [64687.0, 0.001], [64687.1, 0.345], [64687.5, 0.375], [64688.0, 0.18], [64697.0, 1.023], [64702.4, 1.117], [64704.1, 0.073], [64704.2, 0.003], [64704.3, 0.002], [64704.4, 0.191], [64704.5, 0.0], [64704.6, 0.001], [64704.7, 0.001], [64704.8, 0.464], [64704.9, 0.056], [64705.0, 0.92], [64705.1, 0.581], [64705.2, 2.641], [64705.3, 0.002], [64705.4, 0.036], [64705.5, 0.008], [64705.8, 0.021], [64706.0, 0.034], [64706.1, 0.362], [64706.4, 0.041], [64706.7, 0.001], [64707.3, 0.063], [64708.0, 0.06], [64710.4, 0.096], [64712.2, 26.209]], "asks": [[64712.3, 4.091], [64713.6, 0.047], [64714.3, 0.055], [64717.2, 0.118], [64718.1, 0.013], [64718.3, 0.352], [64718.4, 0.004], [64718.6, 0.122], [64718.7, 0.007], [64719.1, 0.002], [64719.3, 0.348], [64719.4, 0.004], [64719.5, 0.014], [64719.6, 0.016], [64719.7, 0.132], [64719.8, 0.087], [64719.9, 0.243], [64720.0, 0.66], [64720.1, 2.319], [64720.2, 0.019], [64720.3, 0.119], [64720.4, 0.002], [64720.5, 0.004], [64720.6, 1.595], [64721.8, 0.029], [64722.1, 0.017], [64725.9, 0.003], [64735.2, 0.003], [64735.4, 0.414], [64735.5, 0.0], [64735.7, 0.226], [64735.8, 0.081], [64736.2, 0.001], [64736.4, 0.066], [64736.5, 0.0], [64736.9, 0.309], [64737.3, 1.704], [64737.7, 0.003], [64737.9, 0.003], [64738.0, 0.534], [64738.1, 0.042], [64738.2, 0.004], [64738.3, 0.289], [64738.4, 0.0], [64738.5, 0.376], [64738.6, 0.072], [64738.7, 0.003], [64752.3, 0.002], [64752.5, 0.06], [64752.6, 0.0], [64752.8, 0.037], [64752.9, 0.0], [64753.3, 2.322], [64753.5, 0.056], [64753.6, 2.382], [65035.9, 3.998], [65353.0, 2.216], [65359.4, 5.521], [65598.9, 2.433], [65712.3, 0.007]]}
{"kind": "depth", "E": 1787080153179, "U": 11315333066915, "u": 11315333073265, "recv_ms": 1787080153121, "bids": [[1000.0, 35.81], [14212.2, 3.612], [14312.2, 0.588], [58240.9, 0.053], [61476.5, 0.004], [62123.7, 0.689], [63712.2, 4.412], [64003.8, 3.12], [64065.1, 9.906], [64593.8, 0.009], [64632.7, 6.956], [64632.8, 2.233], [64640.2, 1.282], [64641.8, 2.068], [64647.4, 0.007], [64660.4, 0.233], [64663.3, 0.013], [64679.6, 0.002], [64703.0, 0.004], [64703.8, 1.596], [64704.2, 0.073], [64704.3, 0.142], [64704.4, 0.261], [64704.5, 0.1], [64704.6, 0.201], [64704.7, 0.101], [64705.1, 0.651], [64707.4, 0.015], [64711.7, 0.048], [64712.2, 26.208]], "asks": [[64714.7, 0.003], [64715.3, 0.002], [64717.2, 0.118], [64719.6, 0.107], [64719.8, 0.187], [64720.0, 0.76], [64720.1, 2.529], [64720.2, 0.189], [64720.4, 0.156], [64720.5, 0.074], [64722.1, 0.017], [64724.0, 1.059], [64725.3, 0.013], [64725.9, 0.003], [64737.2, 2.57], [64737.6, 1.39], [64738.0, 0.634], [64738.2, 0.104], [64738.3, 0.359], [64738.4, 0.084], [64738.5, 0.516], [64750.6, 4.155], [64766.7, 0.0], [64784.0, 2.878], [64787.4, 0.186], [64787.7, 35.103], [64787.9, 0.002], [64789.9, 0.004], [64850.0, 29.478], [65359.4, 5.521], [65712.3, 0.027], [65854.9, 2.426]]}
{"kind": "depth", "E": 1787080153281, "U": 11315333073349, "u": 11315333079069, "recv_ms": 1787080153221, "bids": [[1000.0, 35.81], [14212.2, 3.752], [14312.2, 0.336], [14612.2, 0.112], [51769.8, 0.0], [51770.0, 0.0], [58240.9, 0.053], [61476.5, 0.004], [61476.6, 0.01], [62123.7, 0.692], [63783.7, 5.324], [63794.5, 1.566], [64065.1, 9.906], [64515.8, 7.41], [64518.1, 0.361], [64554.6, 3.965], [64571.6, 2.801], [64644.8, 1.164], [64654.1, 0.053], [64654.7, 0.033], [64655.1, 0.395], [64660.4, 0.234], [64701.8, 0.487], [64703.0, 0.003], [64704.4, 0.481], [64704.7, 0.171], [64707.4, 0.014], [64712.1, 0.044], [64712.2, 26.132]], "asks": [[64712.3, 4.087], [64715.1, 0.0], [64715.2, 0.003], [64717.2, 0.273], [64718.3, 0.042], [64718.6, 0.122], [64719.8, 0.342], [64719.9, 0.423], [64722.1, 0.482], [64725.9, 0.158], [64732.6, 0.07], [64738.0, 0.704], [64766.7, 0.014], [64852.5, 5.397], [64852.6, 0.001], [64869.5, 10.414], [64908.4, 15.406], [64910.4, 4.742], [64910.5, 0.0], [65359.4, 5.521], [65595.4, 4.258], [65906.0, 0.006], [66006.5, 0.018]]}
{"kind": "depth", "E": 1787080153383, "U": 11315333079129, "u": 11315333085084, "recv_ms": 1787080153323, "bids": [[14212.2, 3.654], [14312.2, 0.21], [14612.2, 0.336], [51770.0, 0.0], [58240.9, 0.053], [61476.5, 0.005], [62123.7, 0.689], [63558.9, 0.866], [63712.2, 4.392], [63750.8, 1.575], [63806.2, 48.575], [64065.1, 9.906], [64388.6, 5.887], [64518.1, 1.313], [64593.8, 0.29], [64647.5, 0.173], [64654.4, 1.194], [64655.4, 0.17], [64679.6, 0.075], [64686.1, 0.084], [64686.4, 1.519], [64687.9, 0.1], [64712.2, 26.148]], "asks": [[64712.3, 4.086], [64715.6, 0.001], [64716.0, 0.006], [64717.2, 0.273], [64718.9, 0.085], [64719.3, 0.432], [64719.8, 0.342], [64722.1, 0.482], [64725.9, 0.158], [64749.0, 0.158], [64749.8, 0.064], [64750.6, 4.228], [64787.9, 0.171], [64850.0, 29.76], [65359.4, 5.521], [65712.3, 0.007], [65822.0, 14.131], [65844.8, 6.068]]}
{"kind": "depth", "E": 1787080153485, "U": 11315333085123, "u": 11315333096041, "recv_ms": 1787080153425, "bids": [[1000.0, 35.81], [14212.2, 3.528], [14312.2, 0.098], [14612.2, 0.574], [58240.9, 0.053], [61476.5, 0.004], [62123.7, 0.692], [63547.4, 10.597], [63601.0, 4.522], [63713.4, 0.001], [63939.1, 0.0], [64065.1, 9.906], [64593.8, 0.009], [64647.5, 0.004], [64679.6, 0.002], [64680.0, 3.044], [64680.8, 0.0], [64680.9, 0.43], [64686.2, 0.072], [64686.5, 0.134], [64686.6, 0.193], [64686.8, 0.223], [64686.9, 0.441], [64687.1, 0.415], [64690.7, 0.716], [64691.5, 0.004], [64692.5, 0.708], [64693.3, 1.256], [64696.1, 0.023], [64697.0, 1.022], [64704.9, 0.226], [64705.1, 0.11], [64705.4, 0.577]], "asks": [[64717.2, 0.118], [64719.8, 0.187], [64722.1, 0.017], [64725.9, 0.003], [64728.5, 0.001], [64729.5, 0.93], [64731.8, 0.559], [64732.7, 1.64], [64732.8, 2.286], [64734.3, 0.027], [64735.9, 0.656], [64749.0, 0.004], [64749.3, 3.31], [64750.6, 4.155], [64785.5, 0.029], [64787.4, 0.177], [64787.7, 35.103], [64787.9, 0.002], [64789.9, 0.004], [64850.0, 29.478], [65359.4, 5.521], [65812.4, 6.606], [65828.4, 0.018]]}
{"kind": "depth", "E": 1787080153587, "U": 11315333096057, "u": 11315333103247, "recv_ms": 1787080153527, "bids": [[1000.0, 35.81], [14212.2, 3.36], [14312.2, 0.0], [14612.2, 0.84], [58240.9, 0.053], [61476.5, 0.004], [63738.1, 0.274], [63850.1, 11.273], [64065.1, 9.906], [64168.6, 0.005], [64605.5, 2.318], [64651.7, 0.04], [64651.8, 0.016], [64679.8, 0.005], [64686.2, 0.142], [64686.3, 0.47], [64686.4, 1.589], [64686.6, 0.293], [64687.5, 0.475], [64698.7, 0.164], [64712.2, 26.124]], "asks": [[64715.5, 0.087], [64716.3, 0.174], [64717.2, 0.118], [64719.8, 0.187], [64722.1, 0.017], [64724.0, 0.159], [64725.9, 0.003], [64728.0, 0.128], [64787.4, 0.186], [64790.0, 0.024], [64805.6, 0.156], [64810.6, 0.102], [64819.4, 2.321], [65359.4, 5.521], [65585.9, 5.73]]}
{"kind": "depth", "E": 1787080153689, "U": 11315333103326, "u": 11315333111996, "recv_ms": 1787080153630, "bids": [[14212.2, 3.01], [14612.2, 1.19], [58240.9, 0.053], [62123.7, 0.689], [63712.2, 4.412], [63773.9, 51.509], [63838.6, 11.814], [63906.4, 8.899], [64065.1, 9.906], [64388.6, 5.887], [64582.7, 0.003], [64644.8, 1.173], [64680.1, 0.077], [64680.4, 0.002], [64680.9, 0.373], [64686.7, 0.167], [64695.1, 0.465], [64695.5, 0.001], [64696.5, 0.928], [64697.0, 0.097], [64698.0, 0.278], [64701.0, 1.175], [64701.4, 0.464], [64701.6, 0.002], [64704.4, 0.48], [64704.9, 0.767], [64705.0, 0.104], [64705.3, 0.009], [64705.4, 0.036], [64706.0, 0.934], [64706.3, 1.129], [64707.2, 0.503], [64709.9, 0.331], [64710.5, 0.009], [64712.2, 25.966]], "asks": [[64712.3, 6.409], [64714.8, 0.086], [64717.2, 0.273], [64717.9, 0.006], [64718.3, 0.352], [64719.3, 0.348], [64719.8, 0.342], [64720.0, 0.759], [64722.1, 0.482], [64725.0, 0.905], [64725.9, 0.158], [64726.1, 0.216], [64728.7, 1.361], [64729.0, 1.037], [64729.5, 0.005], [64732.0, 0.081], [64732.7, 1.583], [64733.5, 0.62], [64733.6, 0.511], [64734.3, 0.568], [64734.4, 1.24], [64734.8, 0.01], [64735.9, 0.115], [64741.2, 0.25], [64741.3, 1.325], [64741.4, 0.564], [64745.2, 0.108], [64747.5, 0.014], [64748.6, 0.028], [64766.7, 0.0], [65359.4, 5.521], [65521.2, 15.93], [65712.3, 0.027]]}
{"kind": "depth", "E": 1787080153791, "U": 11315333111997, "u": 11315333120739, "recv_ms": 1787080153735, "bids": [[1000.0, 35.81], [14212.2, 2.646], [14612.2, 1.554], [51770.0, 0.004], [58240.9, 0.053], [61476.5, 0.004], [62123.7, 0.692], [63418.0, 9.308], [63712.2, 4.392], [63753.0, 0.904], [64065.1, 9.908], [64388.6, 5.888], [64471.2, 0.019], [64499.3, 0.001], [64593.7, 2.6], [64647.3, 0.171], [64660.4, 0.134], [64666.9, 0.722], [64668.1, 0.014], [64679.3, 2.385], [64679.5, 2.925], [64679.8, 0.005], [64680.1, 0.02], [64689.9, 0.556], [64690.7, 0.16], [64691.8, 0.609], [64692.5, 0.592], [64692.9, 0.618], [64693.2, 0.01], [64693.6, 0.155], [64695.4, 0.946], [64696.1, 0.023], [64696.5, 0.003], [64701.4, 0.463], [64703.9, 0.022], [64704.9, 0.767], [64706.3, 1.126], [64707.9, 0.001], [64709.3, 0.129], [64710.3, 0.001], [64711.2, 0.335], [64711.6, 0.178], [64711.7, 0.132], [64712.0, 0.057], [64712.1, 0.128], [64712.2, 25.874]], "asks": [[64712.3, 7.473], [64713.1, 0.002], [64714.2, 0.0], [64715.0, 0.313], [64715.1, 0.0], [64717.1, 0.109], [64717.2, 0.273], [64717.6, 0.003], [64717.9, 0.005], [64718.9, 0.001], [64719.8, 0.342], [64722.1, 0.482], [64725.9, 0.158], [64731.0, 0.624], [64731.1, 1.336], [64731.8, 0.003], [64732.0, 0.024], [64732.1, 0.523], [64733.5, 0.002], [64734.3, 0.027], [64734.6, 0.397], [64734.8, 0.551], [64735.6, 0.116], [64735.9, 0.0], [64743.4, 0.002], [64744.2, 0.156], [64744.3, 0.004], [64744.4, 0.126], [64745.0, 2.959], [64745.1, 1.012], [64746.0, 0.693], [64747.3, 0.063], [64747.4, 10.008], [64748.6, 0.014], [64749.3, 1.991], [64750.5, 0.138], [64751.2, 0.01], [64757.6, 0.003], [64758.9, 0.0], [64761.5, 0.076], [64764.1, 0.048], [64787.8, 0.289], [64849.9, 0.28], [65035.9, 3.997], [65359.4, 5.523], [65457.1, 11.84], [65518.4, 1.524], [65712.3, 0.007], [65842.0, 1.501]]}
{"kind": "depth", "E": 1787080153893, "U": 11315333120834, "u": 11315333128468, "recv_ms": 1787080153834, "bids": [[1000.0, 35.81], [14212.2, 2.296], [14612.2, 1.904], [51770.0, 0.0], [58240.9, 0.053], [61476.5, 0.005], [62123.7, 0.689], [63418.0, 9.311], [64065.1, 9.906], [64388.6, 5.889], [64593.7, 2.32], [64647.3, 0.003], [64679.5, 2.852], [64709.0, 0.234], [64709.3, 0.005], [64709.6, 0.126], [64709.9, 0.1], [64712.1, 0.127], [64712.2, 25.876]], "asks": [[64712.3, 7.249], [64713.1, 0.001], [64714.2, 0.001], [64717.2, 0.118], [64719.8, 0.187], [64722.1, 0.017], [64724.0, 1.059], [64725.0, 0.005], [64725.9, 0.003], [64749.3, 1.837], [64749.6, 0.395], [64750.5, 0.066], [64787.8, 0.122], [64849.9, 0.002], [65035.9, 3.996], [65359.4, 5.521], [65457.1, 10.933], [66006.5, 0.015]]}
{"kind": "depth", "E": 1787080154097, "U": 11315333133877, "u": 11315333143204, "recv_ms": 1787080154038, "bids": [[1000.0, 35.96], [14212.2, 1.582], [14612.2, 2.618], [51770.0, 0.0], [58240.9, 0.053], [61476.5, 0.005], [62123.7, 0.692], [63712.2, 4.412], [63725.3, 0.008], [63749.8, 0.011], [63906.4, 8.666], [64065.1, 9.906], [64194.5, 8.568], [64403.3, 0.079], [64593.7, 2.32], [64640.2, 1.283], [64647.3, 0.003], [64679.3, 2.328], [64679.5, 2.852], [64680.2, 0.071], [64695.4, 0.021], [64695.6, 0.002], [64696.0, 0.818], [64696.2, 0.005], [64696.3, 1.166], [64697.1, 0.724], [64699.0, 0.913], [64700.6, 0.245], [64705.7, 0.111], [64711.8, 1.181], [64712.0, 1.057], [64712.1, 1.127], [64712.2, 25.832]], "asks": [[64717.2, 0.273], [64719.8, 0.342], [64722.1, 0.482], [64725.9, 0.158], [64728.7, 1.361], [64746.0, 0.707], [64750.5, 0.066], [64787.8, 0.122], [64805.6, 0.056], [64849.9, 0.002], [65359.4, 5.521], [65457.1, 12.764], [65488.8, 52.993], [65660.2, 3.954], [65699.3, 1.31], [65712.3, 0.027]]}
{"kind": "depth", "E": 1787080154199, "U": 11315333143274, "u": 11315333152434, "recv_ms": 1787080154139, "bids": [[1000.0, 35.81], [14212.2, 1.218], [14612.2, 2.982], [51770.0, 0.0], [58240.9, 0.053], [61476.5, 0.004], [61476.6, 0.008], [61476.7, 0.006], [62123.7, 0.689], [63418.0, 9.308], [63725.1, 0.052], [63846.9, 0.626], [64065.1, 9.906], [64571.6, 2.829], [64571.7, 0.838], [64632.7, 6.958], [64646.3, 3.671], [64660.4, 0.135], [64663.3, 0.014], [64696.0, 0.851], [64697.1, 0.723], [64702.4, 0.005], [64702.5, 0.001], [64703.7, 0.996], [64705.3, 0.094], [64706.2, 1.069], [64706.3, 1.041], [64706.4, 0.041], [64712.2, 25.831]], "asks": [[64717.2, 0.118], [64719.8, 0.187], [64722.1, 0.017], [64725.3, 0.012], [64725.9, 0.003], [64787.2, 6.155], [64852.5, 5.397], [64868.5, 2.206], [65359.4, 5.521], [65457.1, 11.85], [65683.0, 10.775]]}
{"kind": "depth", "E": 1787080154301, "U": 11315333152623, "u": 11315333160079, "recv_ms": 1787080154240, "bids": [[14212.2, 0.868], [14612.2, 3.332], [51769.8, 0.0], [51770.0, 0.0], [58240.9, 0.053], [61476.5, 0.004], [62123.7, 0.692], [63712.2, 4.392], [64065.1, 9.906], [64388.6, 5.879], [64593.7, 2.32], [64647.3, 0.003], [64666.9, 0.725], [64673.3, 0.066], [64679.5, 2.852], [64686.3, 0.467], [64702.4, 0.005], [64702.5, 0.001], [64705.3, 0.086], [64706.3, 0.037], [64706.4, 1.053], [64712.2, 25.833]], "asks": [[64717.2, 0.118], [64719.8, 0.187], [64722.1, 0.017], [64725.3, 0.013], [64725.9, 0.003], [64750.4, 1.365], [64751.2, 0.007], [64787.7, 35.103], [64790.0, 0.027], [64849.8, 0.0], [64906.5, 0.0], [65359.4, 5.521], [65457.1, 12.766], [65699.2, 0.039], [65712.3, 0.007], [65799.5, 1.818]]}
{"kind": "depth", "E": 1787080154505, "U": 11315333167809, "u": 11315333174039, "recv_ms": 1787080154444, "bids": [[14212.2, 0.308], [14512.2, 0.154], [14612.2, 3.738], [58240.9, 0.053], [61476.5, 0.004], [63418.0, 9.311], [63536.7, 1.359], [63712.2, 4.412], [63838.6, 12.204], [64065.1, 9.906], [64571.6, 2.284], [64593.7, 2.32], [64647.3, 0.003], [64668.1, 0.0], [64679.5, 2.852], [64712.1, 1.043], [64712.2, 25.84]], "asks": [[64714.4, 0.442], [64715.0, 0.003], [64717.2, 0.118], [64717.6, 0.002], [64717.9, 0.006], [64719.8, 0.187], [64722.1, 0.017], [64725.9, 0.003], [64750.5, 0.066], [64787.7, 35.103], [64849.9, 0.002], [64852.5, 4.992], [64869.5, 8.561], [65350.1, 0.0], [65359.4, 5.521], [65427.8, 0.001], [65712.3, 0.027]]}
{"kind": "depth", "E": 1787080154709, "U": 11315333184972, "u": 11315333192747, "recv_ms": 1787080154651, "bids": [[1000.0, 35.81], [14212.2, 0.07], [14512.2, 0.63], [14612.2, 3.5], [58240.9, 0.053], [62123.7, 0.689], [63537.1, 0.788], [63644.4, 6.515], [63712.2, 4.392], [64065.1, 9.906], [64168.6, 0.0], [64582.7, 0.003], [64593.7, 2.602], [64647.3, 0.172], [64679.4, 0.009], [64679.5, 2.925], [64680.3, 0.102], [64689.9, 0.0], [64691.1, 1.023], [64695.5, 0.001], [64696.4, 0.935], [64702.4, 0.468], [64703.9, 0.022], [64705.3, 0.543], [64705.4, 0.036], [64706.3, 0.121], [64706.4, 0.049], [64708.4, 0.061]], "asks": [[64714.8, 0.086], [64717.6, 0.002], [64717.9, 0.006], [64725.3, 0.013], [64728.0, 0.128], [64728.9, 1.089], [64731.3, 0.169], [64732.2, 0.064], [64734.1, 0.003], [64734.8, 0.551], [64750.5, 0.14], [64787.7, 35.274], [64849.9, 0.286], [65359.4, 5.521], [65417.7, 9.071], [65531.8, 0.768], [65712.3, 0.007]]}
{"kind": "depth", "E": 1787080154811, "U": 11315333193033, "u": 11315333200719, "recv_ms": 1787080154753, "bids": [[14212.2, 0.0], [14512.2, 0.924], [14612.2, 3.276], [58240.9, 0.053], [61476.5, 0.004], [62123.7, 0.692], [64065.1, 9.906], [64388.6, 5.888], [64593.7, 2.32], [64596.6, 0.002], [64600.4, 7.791], [64641.0, 0.277], [64645.3, 0.046], [64647.3, 0.003], [64675.7, 0.207], [64679.5, 2.852], [64682.8, 0.002], [64694.8, 0.623], [64701.4, 0.464], [64702.1, 3.678], [64703.7, 0.996], [64708.4, 0.06], [64712.2, 25.823]], "asks": [[64715.0, 0.313], [64717.2, 0.118], [64717.6, 0.002], [64717.9, 0.006], [64719.8, 0.187], [64722.1, 0.018], [64725.8, 0.002], [64725.9, 0.003], [64730.9, 0.118], [64733.2, 0.62], [64738.5, 0.501], [64741.9, 0.002], [64748.8, 1.284], [64750.5, 0.066], [64783.5, 0.002], [64787.7, 35.103], [64787.8, 0.168], [64847.8, 0.948], [64849.9, 0.002], [64852.1, 7.675], [65147.4, 0.0], [65230.0, 4.969], [65359.4, 5.521]]}
{"kind": "depth", "E": 1787080154913, "U": 11315333201102, "u": 11315333207469, "recv_ms": 1787080154854, "bids": [[14512.2, 1.274], [14612.2, 2.926], [58240.9, 0.053], [61476.5, 0.004], [61476.6, 0.006], [61476.7, 0.008], [62123.7, 0.689], [63712.2, 4.412], [64065.1, 9.906], [64388.6, 5.887], [64593.7, 2.32], [64647.3, 0.003], [64679.5, 2.852], [64691.1, 1.177], [64692.2, 0.03], [64693.9, 0.635], [64694.9, 0.466], [64697.3, 0.383], [64697.7, 0.597], [64698.3, 0.002], [64698.7, 0.165], [64702.4, 0.005], [64703.7, 0.995], [64704.4, 0.789], [64705.2, 2.332], [64706.3, 0.113], [64707.4, 0.073], [64707.9, 0.085], [64708.4, 0.001], [64711.0, 0.007], [64711.2, 0.251], [64711.7, 0.048], [64711.8, 1.174], [64712.2, 25.739]], "asks": [[64713.7, 0.088], [64717.1, 0.657], [64717.2, 0.118], [64717.6, 0.003], [64717.9, 0.005], [64719.8, 0.18], [64720.0, 0.218], [64721.9, 0.258], [64722.1, 0.01], [64722.7, 3.07], [64723.7, 0.004], [64725.9, 0.003], [64726.3, 0.171], [64727.2, 1.852], [64733.0, 0.037], [64734.2, 1.343], [64743.4, 0.002], [64746.0, 0.693], [64750.4, 1.365], [64787.7, 35.103], [64849.8, 0.0], [65035.9, 3.997], [65127.0, 0.008], [65359.4, 5.521], [65712.3, 0.027]]}
{"kind": "depth", "E": 1787080155117, "U": 11315333213841, "u": 11315333220967, "recv_ms": 1787080155058, "bids": [[14512.2, 2.002], [14612.2, 2.198], [58240.9, 0.053], [62123.7, 0.692], [63712.2, 4.392], [63725.1, 0.041], [64065.1, 9.906], [64168.6, 0.062], [64646.9, 0.31], [64647.0, 2.134], [64647.5, 0.004], [64655.3, 2.154], [64663.6, 2.134], [64668.5, 0.031], [64687.4, 0.946], [64688.2, 0.007], [64693.3, 1.257], [64696.2, 0.005], [64698.7, 0.164], [64700.6, 0.245], [64712.0, 1.057], [64712.2, 25.165]], "asks": [[64712.3, 7.455], [64713.7, 0.004], [64714.0, 0.087], [64717.0, 0.152], [64719.8, 0.18], [64719.9, 0.886], [64720.0, 0.226], [64721.9, 0.25], [64722.1, 0.01], [64722.2, 0.0], [64725.9, 0.003], [64728.7, 0.436], [64796.9, 2.129], [64797.0, 0.0], [64804.0, 0.383], [64805.2, 2.129], [64805.3, 0.0], [64812.0, 0.002], [64813.6, 5.899], [65230.0, 8.795], [65359.4, 5.521], [65699.2, 0.028], [65712.3, 0.007], [66006.5, 0.015]]}
{"kind": "depth", "E": 1787080155219, "U": 11315333220987, "u": 11315333230937, "recv_ms": 1787080155160, "bids": [[14512.2, 2.352], [14612.2, 1.848], [58240.9, 0.053], [62123.7, 0.689], [63725.1, 0.052], [64065.1, 9.906], [64388.6, 5.877], [64593.7, 2.32], [64647.3, 0.003], [64660.4, 0.136], [64675.7, 0.193], [64679.4, 0.009], [64682.9, 1.323]], "asks": [[64719.9, 0.423], [64720.0, 0.218], [64722.2, 0.471], [64741.6, 0.019], [64746.2, 2.247], [64748.8, 1.27], [64750.4, 1.365], [64787.7, 35.103], [64849.8, 0.0], [65359.4, 5.521], [65699.2, 0.039]]}
{"kind": "depth", "E": 1787080155321, "U": 11315333231189, "u": 11315333238655, "recv_ms": 1787080155260, "bids": [[1000.0, 35.81], [14512.2, 2.702], [14612.2, 1.498], [51769.8, 0.0], [58240.9, 0.053], [61476.5, 0.004], [62123.7, 0.692], [63698.5, 0.672], [63712.2, 4.412], [63906.7, 0.782], [63923.9, 2.345], [64065.1, 9.906], [64550.0, 5.962], [64570.0, 0.705], [64674.2, 3.791], [64706.2, 1.068], [64711.2, 0.335], [64712.2, 25.166]], "asks": [[64712.3, 7.477], [64717.0, 0.152], [64719.8, 0.18], [64719.9, 0.423], [64720.0, 0.218], [64722.1, 0.01], [64722.2, 0.471], [64725.9, 0.003], [64733.2, 0.002], [65359.4, 5.521], [65712.3, 0.027]]}
{"kind": "depth", "E": 1787080155423, "U": 11315333239008, "u": 11315333245923, "recv_ms": 1787080155365, "bids": [[14512.2, 3.066], [14612.2, 1.134], [58240.9, 0.053], [61476.5, 0.004], [63551.5, 0.0], [63770.8, 2.506], [63775.7, 0.003], [63903.3, 15.471], [64065.1, 9.906], [64571.6, 2.803], [64571.7, 1.162], [64593.7, 2.32], [64633.9, 0.0], [64635.5, 1.308], [64636.1, 35.554], [64638.3, 0.0], [64639.9, 0.97], [64647.3, 0.003], [64679.4, 0.009], [64679.5, 2.852], [64680.3, 0.102], [64690.1, 0.56], [64691.1, 0.621], [64691.8, 0.455], [64692.9, 0.771], [64693.0, 0.002], [64695.5, 0.001], [64696.4, 0.935], [64703.9, 0.022], [64704.5, 0.1], [64704.9, 0.226], [64705.3, 0.659], [64711.8, 1.258], [64712.2, 25.276]], "asks": [[64714.0, 0.003], [64717.0, 0.152], [64719.8, 0.18], [64719.9, 0.886], [64720.0, 0.218], [64722.1, 0.01], [64722.2, 0.008], [64725.9, 0.003], [64727.9, 0.007], [64728.9, 1.089], [64731.3, 0.169], [64732.2, 0.064], [64734.1, 0.003], [64734.8, 0.551], [64750.4, 1.365], [64787.7, 35.103], [64849.8, 0.0], [64852.5, 5.397], [65359.4, 5.521], [65824.1, 0.759]]}
{"kind": "depth", "E": 1787080155525, "U": 11315333246110, "u": 11315333252639, "recv_ms": 1787080155466, "bids": [[1000.0, 35.81], [14512.2, 3.43], [14612.2, 0.77], [58240.9, 0.053], [62123.7, 0.689], [63712.2, 4.392], [64009.9, 3.673], [64065.1, 9.906], [64388.6, 5.877], [64677.0, 0.268], [64693.3, 1.256], [64698.4, 0.14], [64702.4, 0.082], [64705.3, 0.543], [64706.3, 0.044]], "asks": [[64714.3, 0.139], [64719.9, 0.423], [64720.0, 0.226], [64722.1, 0.01], [64722.2, 0.463], [64784.0, 7.881], [64785.5, 34.285], [64787.2, 1.214], [64787.4, 0.177], [64787.7, 0.224], [65359.4, 5.521], [65423.9, 0.005], [65498.7, 0.762], [65712.3, 0.007], [71183.6, 0.0]]}
{"kind": "depth", "E": 1787080155627, "U": 11315333252680, "u": 11315333259614, "recv_ms": 1787080155568, "bids": [[1000.0, 35.81], [14412.2, 0.028], [14512.2, 3.724], [14612.2, 0.448], [51770.0, 0.0], [58240.9, 0.053], [58241.0, 0.01], [61476.5, 0.004], [62123.7, 0.692], [63760.9, 6.498], [63803.2, 1.566], [63971.1, 0.0], [64065.1, 9.906], [64571.6, 2.801], [64571.7, 0.838], [64593.6, 1.259], [64619.1, 0.004], [64619.2, 1.219], [64647.3, 0.003], [64651.7, 0.001], [64651.8, 0.055], [64666.9, 0.725], [64668.1, 0.0], [64679.4, 0.009], [64686.3, 0.47], [64698.4, 0.139], [64699.9, 0.533], [64706.6, 0.102], [64711.8, 1.174], [64712.1, 1.045], [64712.2, 25.286]], "asks": [[64712.3, 7.296], [64714.3, 0.139], [64717.0, 0.307], [64719.8, 0.335], [64720.0, 0.226], [64722.1, 0.475], [64722.2, 0.463], [64725.9, 0.158], [64746.0, 0.707], [64750.4, 1.365], [64751.2, 0.01], [64787.7, 0.224], [64822.4, 0.017], [64849.8, 0.0], [64852.5, 5.397], [64910.3, 0.013], [64910.4, 4.739], [65359.4, 5.521]]}
{"kind": "depth", "E": 1787080155831, "U": 11315333264844, "u": 11315333272600, "recv_ms": 1787080155772, "bids": [[1000.0, 35.81], [14412.2, 0.448], [14512.2, 3.598], [14612.2, 0.154], [58240.9, 0.053], [61476.5, 0.004], [62123.7, 0.692], [63880.3, 1.371], [63903.3, 15.704], [64065.1, 9.906], [64388.6, 5.887], [64554.6, 2.899], [64571.6, 2.262], [64593.6, 1.259], [64642.3, 0.039], [64647.3, 0.003], [64679.4, 0.009], [64694.0, 2.535], [64697.7, 0.589], [64701.4, 1.082], [64705.3, 0.126], [64707.9, 0.001], [64709.0, 0.003], [64709.4, 0.233], [64711.6, 0.262], [64712.0, 1.141], [64712.2, 25.287]], "asks": [[64712.3, 7.425], [64714.3, 0.055], [64717.0, 0.152], [64719.8, 0.18], [64720.0, 0.689], [64722.1, 0.01], [64722.2, 0.0], [64725.0, 0.005], [64725.3, 0.013], [64725.9, 0.003], [64732.4, 0.002], [64750.4, 1.365], [64755.9, 0.511], [64766.7, 0.028], [64778.0, 0.026], [64787.7, 0.224], [64849.8, 0.0], [64852.5, 3.648], [64868.5, 1.535], [64869.5, 5.912], [65359.4, 5.521]]}
{"kind": "depth", "E": 1787080155933, "U": 11315333272824, "u": 11315333278901, "recv_ms": 1787080155876, "bids": [[1000.0, 35.81], [14412.2, 0.686], [14512.2, 3.472], [14612.2, 0.042], [58240.9, 0.053], [61476.5, 0.004], [63712.2, 4.392], [63741.5, 28.417], [63794.5, 2.349], [63880.2, 3.289], [63882.5, 1.88], [64065.1, 9.908], [64390.3, 0.229], [64593.7, 2.32], [64610.8, 0.006], [64611.0, 2.554], [64645.2, 6.0], [64647.3, 0.003], [64647.4, 0.025], [64667.8, 3.52], [64679.4, 0.009], [64680.3, 0.102], [64684.0, 1.016], [64694.0, 1.917], [64695.5, 0.001], [64696.4, 0.01], [64696.5, 0.928], [64697.8, 0.011], [64699.9, 0.532], [64701.4, 0.464], [64702.5, 0.543], [64704.5, 0.1], [64704.9, 0.226], [64705.3, 0.635], [64706.4, 0.039], [64706.6, 0.048], [64707.3, 0.117], [64712.2, 25.646]], "asks": [[64712.3, 7.425], [64714.8, 0.002], [64717.0, 0.152], [64719.8, 0.18], [64719.9, 0.423], [64720.0, 0.689], [64722.1, 0.01], [64722.2, 0.0], [64724.0, 1.058], [64725.9, 0.003], [64728.0, 0.128], [64728.9, 1.089], [64731.3, 0.169], [64732.2, 0.064], [64734.1, 0.003], [64734.8, 0.551], [64739.9, 0.993], [64750.4, 1.365], [64756.1, 3.5], [64778.7, 6.173], [64787.7, 0.224], [64806.9, 2.09], [64809.1, 0.0], [64849.8, 0.0], [64869.5, 8.423], [65035.9, 3.997], [65359.4, 5.523], [65712.3, 0.007], [66006.5, 0.018], [67318.0, 0.003]]}
{"kind": "depth", "E": 1787080156035, "U": 11315333278906, "u": 11315333285415, "recv_ms": 1787080156034, "bids": [[14412.2, 1.008], [14512.2, 3.192], [14612.2, 0.0], [58240.9, 0.053], [61476.5, 0.004], [62123.7, 0.689], [63418.0, 9.311], [63712.2, 4.412], [63818.8, 0.012], [63867.5, 0.274], [64065.1, 9.906], [64388.6, 5.889], [64642.3, 0.03], [64702.4, 0.113], [64702.5, 0.542], [64705.2, 2.333], [64705.3, 0.543], [64706.3, 0.013], [64712.2, 25.286]], "asks": [[64715.1, 0.084], [64717.0, 0.307], [64719.8, 0.335], [64719.9, 0.886], [64720.0, 0.226], [64722.1, 0.475], [64722.2, 0.0], [64725.9, 0.158], [64746.0, 0.693], [64766.7, 0.0], [64785.5, 34.285], [64787.4, 0.177], [64789.9, 0.004], [65035.9, 3.996], [65359.4, 5.523], [65585.9, 6.11], [65594.4, 0.609], [65712.3, 0.027], [66006.5, 0.012]]}
{"kind": "depth", "E": 1787080156137, "U": 11315333285428, "u": 11315333294306, "recv_ms": 1787080156079, "bids": [[1000.0, 35.81], [14412.2, 1.372], [14512.2, 2.828], [58240.9, 0.053], [61476.5, 0.004], [61476.6, 0.008], [62123.7, 0.692], [63418.0, 9.311], [63725.3, 0.0], [63790.0, 0.153], [63791.6, 0.01], [63867.6, 0.551], [63870.9, 23.61], [64065.1, 9.908], [64388.6, 5.879], [64593.7, 2.32], [64612.6, 10.0], [64647.3, 0.003], [64669.7, 0.063], [64679.5, 2.852], [64692.8, 1.625], [64693.0, 0.002], [64696.2, 0.005], [64700.6, 0.245], [64702.4, 0.113], [64703.6, 0.004], [64705.2, 2.332], [64706.3, 0.016], [64707.1, 0.379], [64708.9, 0.002], [64712.2, 25.626]], "asks": [[64712.3, 7.266], [64715.1, 0.0], [64715.3, 0.086], [64715.5, 0.003], [64717.0, 0.307], [64718.3, 0.042], [64718.9, 0.085], [64719.8, 0.335], [64722.1, 0.475], [64725.3, 0.013], [64725.5, 0.013], [64725.9, 0.158], [64728.7, 0.436], [64743.4, 0.016], [64746.0, 0.707], [64750.4, 1.365], [64787.7, 0.224], [64811.0, 2.801], [64811.1, 10.001], [64849.8, 0.0], [65359.4, 5.521], [65632.9, 0.0], [65634.6, 0.014], [65699.3, 1.302], [66006.5, 0.015]]}
{"kind": "depth", "E": 1787080156239, "U": 11315333294315, "u": 11315333300819, "recv_ms": 1787080156180, "bids": [[1000.0, 35.81], [14412.2, 1.722], [14512.2, 2.478], [58240.9, 0.053], [61476.7, 0.006], [62123.7, 0.689], [63712.2, 4.392], [63725.1, 0.06], [63789.9, 0.021], [63791.6, 0.018], [63812.7, 14.919], [64003.8, 2.34], [64065.1, 9.908], [64571.6, 2.77], [64632.8, 2.234], [64660.4, 0.137], [64692.7, 5.175], [64692.8, 1.471], [64700.6, 0.246], [64702.4, 0.005], [64703.6, 0.003], [64704.9, 0.767], [64705.3, 0.111], [64706.3, 0.012], [64711.6, 0.178], [64712.0, 1.057], [64712.2, 25.204]], "asks": [[64712.3, 7.413], [64713.7, 0.088], [64714.1, 0.099], [64714.5, 0.087], [64717.0, 0.307], [64717.9, 0.315], [64718.6, 0.038], [64718.9, 0.001], [64719.8, 0.335], [64719.9, 0.423], [64720.0, 0.218], [64722.1, 0.475], [64722.2, 0.471], [64725.9, 0.158], [64755.9, 0.944], [64800.6, 0.0], [64811.0, 2.809], [64812.5, 0.019], [64852.5, 5.397], [65340.0, 1.598], [65359.4, 5.523], [65420.4, 0.004], [65453.7, 2.291], [65632.8, 0.008], [65634.5, 0.01], [65699.2, 0.047], [65712.3, 0.007]]}
{"kind": "depth", "E": 1787080156341, "U": 11315333300839, "u": 11315333306605, "recv_ms": 1787080156281, "bids": [[14412.2, 2.072], [14512.2, 2.128], [51769.8, 0.0], [51770.0, 0.0], [58240.9, 0.053], [61476.5, 0.004], [62123.7, 0.692], [63834.9, 1.01], [64065.1, 9.906], [64593.7, 2.32], [64647.3, 0.003], [64666.9, 0.725], [64679.5, 2.852], [64679.8, 0.002], [64695.1, 0.466], [64700.6, 0.245], [64708.9, 0.001], [64712.2, 25.203]], "asks": [[64717.0, 0.152], [64719.8, 0.18], [64719.9, 0.886], [64720.0, 0.226], [64722.1, 0.01], [64722.2, 0.0], [64725.9, 0.003], [64750.4, 1.365], [64757.6, 0.003], [64787.7, 0.224], [64822.4, 0.014], [64849.8, 0.0], [64869.5, 7.781], [65359.4, 5.521], [71183.6, 0.0]]}
{"kind": "depth", "E": 1787080156443, "U": 11315333306829, "u": 11315333312105, "recv_ms": 1787080156383, "bids": [[1000.0, 35.81], [14412.2, 2.436], [14512.2, 1.764], [51770.0, 0.0], [58240.9, 0.053], [64388.6, 5.879], [64605.5, 2.318], [64647.5, 0.003], [64655.4, 0.17], [64692.6, 0.28], [64692.7, 5.021]], "asks": [[64719.9, 0.423], [64720.0, 0.226], [64722.2, 0.463], [64725.3, 0.013], [64777.0, 0.075], [64819.4, 0.003], [64819.5, 2.318], [64869.5, 10.414], [65359.4, 5.521], [65459.6, 0.007], [65521.2, 16.158], [65524.3, 5.938]]}
{"kind": "depth", "E": 1787080156545, "U": 11315333312210, "u": 11315333316640, "recv_ms": 1787080156485, "bids": [[1000.0, 35.81], [14412.2, 2.786], [14512.2, 1.414], [58240.9, 0.053], [61476.5, 0.004], [62123.7, 0.689], [63712.2, 4.412], [63847.6, 0.004], [64065.1, 9.906], [64194.5, 8.568], [64571.6, 2.076], [64593.6, 1.259], [64647.3, 0.003], [64679.4, 0.009], [64687.9, 0.436], [64691.8, 0.119], [64695.1, 0.465], [64697.1, 0.724], [64712.2, 25.21]], "asks": [[64712.3, 7.413], [64717.0, 0.152], [64719.8, 0.18], [64720.0, 0.689], [64722.1, 0.01], [64722.2, 0.0], [64725.9, 0.003], [64750.4, 1.365], [64787.7, 0.224], [64849.8, 0.0], [65359.4, 5.521], [65417.7, 10.367], [65660.2, 3.802], [65712.3, 0.027]]}
{"kind": "depth", "E": 1787080156647, "U": 11315333316816, "u": 11315333322032, "recv_ms": 1787080156588, "bids": [[14412.2, 3.15], [14512.2, 1.05], [58240.9, 0.053], [61476.5, 0.005], [62123.7, 0.692], [63712.2, 4.392], [63825.6, 3.125], [64065.1, 9.906], [64712.2, 25.21]], "asks": [[64717.0, 0.307], [64719.8, 0.335], [64719.9, 0.423], [64720.0, 0.226], [64722.1, 0.475], [64722.2, 0.463], [64725.9, 0.158], [65359.4, 5.521], [65567.7, 0.0], [65712.3, 0.007]]}
{"kind": "depth", "E": 1787080156851, "U": 11315333328415, "u": 11315333334779, "recv_ms": 1787080156791, "bids": [[1000.0, 35.81], [14312.2, 0.056], [14412.2, 3.752], [14512.2, 0.392], [58240.9, 0.053], [61476.5, 0.004], [62123.7, 0.692], [63816.1, 10.361], [63837.5, 2.163], [64013.0, 0.011], [64065.1, 9.906], [64194.5, 4.68], [64554.6, 3.88], [64571.6, 2.752], [64692.4, 0.176], [64692.6, 0.126], [64711.7, 0.132], [64712.2, 25.133]], "asks": [[64714.1, 0.015], [64717.0, 0.152], [64719.8, 0.18], [64719.9, 0.423], [64720.0, 0.218], [64722.1, 0.01], [64722.2, 0.463], [64725.9, 0.003], [64743.4, 0.002], [64746.0, 0.693], [64852.5, 5.397], [64868.5, 0.125], [64869.5, 10.414], [65359.4, 5.523], [65595.4, 3.498], [65621.9, 0.0], [65641.4, 0.0], [66006.5, 0.018]]}
{"kind": "depth", "E": 1787080156953, "U": 11315333334796, "u": 11315333341017, "recv_ms": 1787080156894, "bids": [[14312.2, 0.266], [14412.2, 3.682], [14512.2, 0.252], [58240.9, 0.053], [61476.5, 0.004], [63532.5, 0.001], [63712.2, 4.412], [63892.2, 0.782], [64065.1, 9.906], [64168.6, 0.136], [64194.5, 8.568], [64388.6, 5.888], [64593.6, 1.259], [64647.2, 0.003], [64679.4, 0.009], [64694.2, 0.85], [64697.1, 0.723], [64697.7, 0.597], [64697.8, 0.003], [64699.1, 0.312], [64701.6, 0.62], [64702.4, 0.546], [64702.5, 0.001], [64705.3, 0.002], [64706.3, 0.105], [64706.4, 0.055], [64712.1, 1.129], [64712.2, 25.056]], "asks": [[64714.5, 0.003], [64714.8, 0.086], [64715.6, 0.085], [64717.0, 0.152], [64719.8, 0.18], [64719.9, 0.423], [64720.0, 0.218], [64722.1, 0.01], [64722.2, 0.471], [64725.2, 0.753], [64725.3, 0.013], [64725.9, 0.003], [64732.6, 0.688], [64750.4, 1.365], [64787.7, 0.224], [64849.8, 0.0], [65359.4, 5.521], [65583.1, 0.0], [65712.3, 0.027]]}
{"kind": "depth", "E": 1787080157055, "U": 11315333341101, "u": 11315333349757, "recv_ms": 1787080156997, "bids": [[1000.0, 35.81], [14312.2, 0.504], [14412.2, 3.57], [14512.2, 0.126], [58240.9, 0.053], [61476.5, 0.004], [62123.7, 0.689], [63418.0, 9.314], [63535.3, 2.022], [63712.2, 4.392], [64006.8, 8.568], [64065.1, 9.908], [64388.6, 5.887], [64694.2, 0.232], [64697.7, 0.597], [64699.1, 0.311], [64700.4, 0.003], [64700.6, 0.245], [64701.6, 0.002], [64702.4, 0.546], [64705.3, 0.118], [64706.3, 0.005], [64706.4, 0.039], [64712.1, 1.044], [64712.2, 25.056]], "asks": [[64714.4, 0.526], [64717.0, 0.307], [64719.8, 0.335], [64720.0, 0.689], [64722.1, 0.475], [64722.2, 0.0], [64725.2, 0.135], [64725.3, 0.013], [64725.9, 0.158], [64732.6, 0.07], [64746.0, 0.707], [64921.6, 0.005], [65035.9, 3.843], [65230.0, 8.49], [65359.4, 5.521], [65712.3, 0.007]]}
{"kind": "depth", "E": 1787080157157, "U": 11315333349826, "u": 11315333356577, "recv_ms": 1787080157098, "bids": [[1000.0, 35.81], [14312.2, 0.756], [14412.2, 3.43], [14512.2, 0.014], [51770.0, 0.0], [58240.9, 0.053], [61476.5, 0.004], [62123.7, 0.692], [63418.0, 9.317], [64065.1, 9.908], [64644.8, 1.164], [64658.7, 0.006], [64660.4, 0.138], [64666.5, 0.644], [64669.7, 0.062], [64669.8, 0.001], [64691.9, 0.908], [64692.4, 0.022], [64695.4, 0.022], [64696.2, 0.003], [64700.4, 0.002], [64709.1, 0.094], [64712.2, 25.392]], "asks": [[64714.4, 0.442], [64717.0, 0.307], [64719.8, 0.335], [64722.1, 0.475], [64725.3, 0.013], [64725.9, 0.158], [64728.7, 0.434], [64748.0, 0.399], [64748.9, 0.185], [64749.6, 0.241], [65035.9, 3.844], [65359.4, 5.521], [65453.7, 1.528], [65585.9, 6.87], [65611.8, 14.095], [66006.5, 0.021]]}
{"kind": "depth", "E": 1787080157259, "U": 11315333356586, "u": 11315333363362, "recv_ms": 1787080157202, "bids": [[14312.2, 1.092], [14412.2, 3.108], [14512.2, 0.0], [51770.0, 0.0], [58240.9, 0.053], [61476.5, 0.004], [61476.7, 0.004], [62123.7, 0.689], [63712.2, 4.412], [63968.0, 13.84], [64000.1, 1.312], [64016.7, 0.0], [64065.1, 9.908], [64571.6, 2.747], [64635.5, 0.0], [64636.2, 6.707], [64696.2, 0.005], [64712.2, 25.384]], "asks": [[64717.0, 0.307], [64719.8, 0.335], [64722.1, 0.475], [64725.3, 0.013], [64725.9, 0.158], [64728.7, 0.436], [64748.9, 0.185], [64784.0, 7.881], [64852.5, 5.397], [64868.5, 2.284], [65035.9, 3.998], [65230.0, 8.795], [65359.4, 5.521], [65482.4, 8.247], [65488.8, 51.774], [65712.3, 0.027], [66006.5, 0.024]]}
{"kind": "depth", "E": 1787080157361, "U": 11315333363439, "u": 11315333370265, "recv_ms": 1787080157303, "bids": [[1000.0, 35.81], [14312.2, 1.456], [14412.2, 2.744], [51769.8, 0.0], [58240.9, 0.053], [61476.5, 0.004], [62123.7, 0.692], [63418.0, 9.32], [63906.4, 8.401], [64003.8, 1.56], [64065.1, 9.908], [64388.6, 5.887], [64658.7, 0.002], [64666.5, 0.648], [64712.2, 25.139]], "asks": [[64713.2, 0.05], [64715.8, 0.806], [64717.0, 0.307], [64719.8, 0.335], [64722.1, 0.475], [64725.9, 0.158], [64743.4, 0.016], [64748.9, 0.031], [64749.0, 0.158], [64869.5, 7.781], [65035.9, 1.695], [65359.4, 5.521], [66653.5, 0.001]]}
{"kind": "depth", "E": 1787080157565, "U": 11315333377082, "u": 11315333385412, "recv_ms": 1787080157509, "bids": [[14312.2, 2.156], [14412.2, 2.044], [51770.0, 0.0], [58240.9, 0.053], [61476.5, 0.004], [62123.7, 0.689], [64006.8, 9.269], [64065.1, 9.906], [64194.5, 8.257], [64388.6, 5.732], [64619.0, 0.17], [64619.1, 0.001], [64651.7, 0.04], [64651.8, 0.016], [64666.9, 0.722], [64673.3, 0.069], [64679.8, 0.005], [64687.9, 0.1], [64692.0, 0.73], [64693.9, 0.633], [64694.0, 1.917], [64694.9, 0.468], [64697.1, 0.724], [64697.7, 0.126], [64698.2, 0.016], [64702.4, 1.016], [64705.3, 0.119], [64706.3, 0.005], [64706.4, 0.039], [64707.8, 0.011], [64712.1, 1.045], [64712.2, 25.378]], "asks": [[64712.3, 6.422], [64714.2, 0.0], [64714.5, 0.003], [64714.8, 0.002], [64714.9, 0.013], [64715.0, 0.003], [64715.1, 0.0], [64715.7, 0.004], [64717.0, 0.152], [64717.1, 0.109], [64717.2, 0.273], [64717.6, 0.002], [64717.9, 0.006], [64719.5, 0.169], [64719.6, 0.655], [64719.8, 0.18], [64720.0, 0.218], [64721.8, 0.184], [64721.9, 0.721], [64722.1, 0.32], [64722.7, 2.761], [64723.5, 0.33], [64725.9, 0.158], [64726.3, 0.164], [64727.0, 0.028], [64733.0, 0.035], [64733.8, 0.003], [64757.6, 0.0], [64822.4, 0.017], [64869.5, 7.809], [64906.5, 0.003], [65035.9, 3.998], [65359.4, 5.523], [65482.4, 9.162], [65488.8, 52.307], [65683.1, 0.376], [66006.5, 0.03], [66294.3, 0.0]]}
{"kind": "depth", "E": 1787080157667, "U": 11315333385432, "u": 11315333392316, "recv_ms": 1787080157609, "bids": [[1000.0, 35.81], [14312.2, 2.52], [14412.2, 1.68], [51770.0, 0.0], [58240.9, 0.053], [61476.5, 0.004], [62123.7, 0.692], [63418.0, 9.326], [63712.2, 4.412], [64065.1, 9.91], [64388.6, 5.722], [64655.7, 0.271], [64697.1, 0.723], [64698.2, 0.016], [64702.4, 1.093], [64702.5, 0.002], [64705.3, 0.042], [64706.3, 0.005], [64706.4, 0.039], [64706.5, 0.029], [64707.8, 0.008], [64711.6, 0.0], [64712.2, 25.391]], "asks": [[64717.2, 0.273], [64719.5, 0.169], [64721.8, 0.184], [64722.1, 0.32], [64725.9, 0.158], [64779.2, 1.269], [64805.6, 0.156], [64869.5, 10.414], [65359.4, 5.521], [65563.7, 2.742], [65712.3, 0.027], [66006.5, 0.033]]}
{"kind": "depth", "E": 1787080157769, "U": 11315333392337, "u": 11315333399816, "recv_ms": 1787080157710, "bids": [[1000.0, 35.81], [14312.2, 2.87], [14412.2, 1.33], [51770.0, 0.0], [58240.9, 0.053], [61476.5, 0.004], [62123.7, 0.689], [63418.0, 9.323], [63760.9, 7.75], [64065.1, 9.908], [64571.6, 2.588], [64582.7, 0.003], [64593.7, 2.32], [64647.3, 0.003], [64679.5, 2.852], [64702.4, 1.093], [64705.3, 0.018], [64706.3, 0.005], [64706.4, 0.039], [64712.2, 25.064]], "asks": [[64712.3, 6.422], [64717.2, 0.118], [64718.5, 0.313], [64719.5, 0.014], [64721.8, 0.029], [64722.1, 0.01], [64725.9, 0.003], [64750.5, 0.066], [64787.7, 0.224], [64849.8, 0.0], [64852.5, 5.397], [64869.5, 7.756], [65359.4, 5.521], [65436.6, 0.779], [65553.6, 49.852], [66006.5, 0.033], [67300.8, 2.01]]}
{"kind": "depth", "E": 1787080157871, "U": 11315333399824, "u": 11315333405912, "recv_ms": 1787080157813, "bids": [[14312.2, 3.234], [14412.2, 0.966], [58240.9, 0.053], [60903.6, 0.0], [61476.5, 0.004], [62123.7, 0.692], [63418.0, 9.329], [63712.2, 4.392], [64003.8, 0.78], [64065.1, 9.906], [64194.5, 8.567], [64388.6, 3.561], [64593.7, 2.32], [64647.3, 0.003], [64679.5, 2.852], [64691.9, 0.754], [64692.7, 5.175], [64702.4, 1.117], [64705.3, 0.01], [64706.3, 0.005], [64706.4, 0.047], [64709.4, 0.002], [64709.7, 0.237], [64712.2, 25.431]], "asks": [[64712.3, 6.422], [64717.2, 0.273], [64719.5, 0.169], [64721.8, 0.184], [64722.1, 0.32], [64725.3, 0.013], [64725.9, 0.158], [64749.0, 0.004], [64749.1, 0.185], [64750.5, 0.066], [64787.7, 0.224], [64849.8, 0.0], [64869.5, 10.414], [65359.4, 5.521], [65488.8, 52.992], [65712.3, 0.007], [71183.6, 0.0]]}
{"kind": "depth", "E": 1787080158075, "U": 11315333411923, "u": 11315333417713, "recv_ms": 1787080158022, "bids": [[1000.0, 35.81], [14212.2, 0.084], [14312.2, 3.78], [14412.2, 0.336], [58240.9, 0.053], [61476.5, 0.004], [61476.7, 0.002], [62123.7, 0.689], [63418.0, 9.332], [63712.2, 4.412], [63880.3, 1.097], [64065.1, 9.908], [64388.6, 5.888], [64668.1, 0.014], [64688.0, 0.18], [64693.7, 0.003], [64694.9, 0.466], [64696.0, 0.841], [64697.7, 0.126], [64698.2, 0.479], [64700.6, 0.245], [64702.4, 0.546], [64705.3, 0.126], [64706.3, 0.005], [64706.4, 0.039], [64706.7, 0.033], [64711.7, 0.048], [64712.2, 24.903]], "asks": [[64712.3, 6.572], [64713.3, 0.0], [64714.2, 0.084], [64714.7, 0.087], [64715.3, 0.087], [64717.0, 0.307], [64717.1, 0.657], [64717.2, 0.118], [64717.6, 0.003], [64717.9, 0.005], [64719.5, 0.014], [64719.6, 0.107], [64719.8, 0.335], [64720.0, 0.226], [64721.8, 0.184], [64721.9, 0.713], [64722.1, 0.32], [64725.9, 0.158], [64732.8, 2.288], [64733.8, 0.001], [64743.4, 0.002], [64743.5, 3.654], [64743.6, 10.009], [64744.9, 0.022], [64746.0, 0.693], [64746.2, 0.928], [64747.4, 0.008], [64869.5, 10.414], [65035.9, 3.996], [65359.4, 5.521], [65650.6, 35.424], [65712.3, 0.027], [66339.7, 0.0]]}
{"kind": "depth", "E": 1787080158279, "U": 11315333422911, "u": 11315333435046, "recv_ms": 1787080158222, "bids": [[1000.0, 35.81], [14212.2, 0.56], [14312.2, 3.542], [14412.2, 0.098], [51770.0, 0.0], [58240.9, 0.053], [61476.5, 0.004], [61476.6, 0.01], [62123.7, 0.689], [63418.0, 9.335], [63712.2, 4.392], [63806.2, 48.387], [63935.7, 47.813], [64065.1, 9.908], [64168.6, 0.041], [64692.5, 0.746], [64696.2, 0.005], [64697.3, 0.384], [64697.7, 0.126], [64699.7, 0.023], [64705.3, 0.126], [64707.1, 0.069], [64712.2, 25.17]], "asks": [[64712.3, 7.414], [64713.3, 0.001], [64715.3, 0.086], [64717.0, 0.307], [64719.8, 0.335], [64720.0, 0.709], [64721.8, 0.029], [64721.9, 0.25], [64722.1, 0.475], [64725.9, 0.158], [64728.7, 0.436], [64764.1, 0.048], [64778.0, 2.191], [64868.5, 1.671], [64869.5, 6.305], [65359.4, 5.521], [65456.5, 0.38], [65482.4, 9.162], [65488.8, 52.018], [65618.3, 31.385], [65663.6, 11.324], [65712.3, 0.007], [66006.5, 0.042]]}
{"kind": "depth", "E": 1787080158381, "U": 11315333435087, "u": 11315333441612, "recv_ms": 1787080158323, "bids": [[1000.0, 35.81], [14212.2, 0.826], [14312.2, 3.374], [14412.2, 0.0], [51769.8, 0.0], [58240.9, 0.053], [61476.5, 0.004], [62123.7, 0.692], [63418.0, 9.338], [63773.9, 52.449], [63867.5, 0.548], [64065.1, 9.908], [64571.6, 2.262], [64692.3, 0.2], [64692.5, 0.592], [64697.3, 0.383], [64697.7, 0.126], [64699.0, 0.914], [64705.3, 0.126], [64712.2, 25.259]], "asks": [[64712.3, 7.414], [64717.0, 0.307], [64719.8, 0.335], [64722.1, 0.475], [64725.9, 0.158], [64748.7, 0.001], [64748.9, 0.031], [64749.1, 0.031], [64852.5, 5.397], [64869.5, 10.414], [65359.4, 5.521], [65488.8, 52.779], [65531.8, 0.539], [66006.5, 0.045]]}
{"kind": "depth", "E": 1787080158585, "U": 11315333448119, "u": 11315333453747, "recv_ms": 1787080158526, "bids": [[1000.0, 35.81], [14212.2, 1.526], [14312.2, 2.674], [51770.0, 0.0], [58240.9, 0.053], [61476.5, 0.004], [61476.6, 0.008], [61476.7, 0.004], [62123.7, 0.689], [64065.1, 9.906], [64571.6, 2.593], [64593.6, 1.259], [64598.5, 3.866], [64600.4, 3.928], [64644.8, 1.21], [64645.3, 0.0], [64647.2, 0.003], [64679.4, 0.066], [64680.3, 0.045], [64692.2, 0.184], [64692.3, 0.046], [64693.7, 0.001], [64694.9, 0.468], [64695.5, 0.926], [64696.5, 0.003], [64698.2, 0.016], [64701.8, 0.487], [64703.9, 0.022], [64704.9, 0.226], [64705.0, 0.645], [64705.3, 0.59], [64707.6, 0.314], [64709.1, 0.093], [64712.2, 24.912]], "asks": [[64714.2, 0.0], [64714.7, 0.003], [64714.8, 0.086], [64715.2, 0.397], [64715.3, 0.002], [64717.0, 0.152], [64717.1, 0.109], [64718.6, 0.122], [64719.6, 0.655], [64719.8, 0.18], [64720.0, 0.238], [64722.1, 0.01], [64722.2, 0.471], [64725.9, 0.003], [64728.0, 0.128], [64728.8, 1.531], [64728.9, 0.164], [64731.4, 0.203], [64732.8, 2.286], [64733.8, 0.003], [64734.1, 0.003], [64734.7, 0.765], [64734.8, 0.01], [64739.1, 0.368], [64748.8, 1.424], [64748.9, 0.031], [64750.4, 1.365], [64787.3, 2.366], [64787.7, 0.224], [64787.8, 0.122], [64849.8, 0.0], [64851.6, 3.922], [64852.1, 3.812], [64852.5, 5.009], [65359.4, 5.521], [66006.5, 0.051]]}
{"kind": "depth", "E": 1787080158687, "U": 11315333453892, "u": 11315333459746, "recv_ms": 1787080158628, "bids": [[1000.0, 35.81], [14212.2, 1.89], [14312.2, 2.31], [58240.9, 0.053], [61476.5, 0.004], [62123.7, 0.692], [63712.2, 4.392], [63847.9, 2.736], [63906.7, 0.0], [64065.1, 9.906], [64168.6, 0.15], [64340.6, 0.026], [64342.2, 4.398], [64437.3, 0.417], [64437.8, 0.715], [64508.2, 0.0], [64508.3, 0.582], [64582.7, 0.003], [64668.1, 0.0], [64679.4, 0.009], [64680.2, 0.071], [64681.0, 0.008], [64690.1, 0.004], [64690.8, 0.558], [64691.5, 0.004], [64695.5, 0.001], [64696.3, 1.166], [64697.1, 0.723], [64698.2, 0.016], [64702.4, 0.553], [64703.5, 0.128], [64705.3, 0.582], [64706.3, 0.005], [64706.4, 0.039], [64706.5, 0.026], [64712.2, 24.911]], "asks": [[64712.3, 7.413], [64714.8, 0.002], [64717.2, 0.118], [64719.5, 0.014], [64722.1, 0.01], [64725.9, 0.003], [64728.8, 0.606], [64729.5, 0.93], [64731.0, 0.068], [64732.0, 0.58], [64732.2, 0.007], [64732.7, 1.564], [64732.8, 2.343], [64734.6, 0.954], [64734.7, 0.224], [64735.6, 0.001], [64735.9, 0.0], [64736.5, 0.115], [64743.4, 0.016], [64748.8, 1.27], [64748.9, 0.031], [64749.1, 0.031], [64749.2, 0.177], [64905.7, 2.574], [64906.7, 0.002], [64976.9, 0.492], [64978.1, 0.003], [65075.5, 1.178], [65075.6, 0.0], [65359.4, 5.521], [65482.4, 9.162], [65564.6, 2.287], [65631.2, 3.18], [65712.3, 0.007]]}
{"kind": "depth", "E": 1787080158789, "U": 11315333459833, "u": 11315333465708, "recv_ms": 1787080158730, "bids": [[14212.2, 2.24], [14312.2, 1.96], [58240.9, 0.053], [62123.7, 0.689], [63418.0, 9.335], [63533.1, 0.796], [63838.6, 12.985], [63906.4, 8.167], [64010.9, 0.0], [64065.1, 9.906], [64388.6, 5.889], [64473.2, 6.294], [64508.3, 0.366], [64698.2, 0.479], [64700.9, 0.003], [64702.4, 0.654], [64703.5, 0.127], [64705.3, 0.018], [64706.3, 0.005], [64706.4, 0.039], [64706.5, 0.026]], "asks": [[64725.3, 0.012], [64749.0, 0.158], [64749.2, 0.023], [64906.6, 0.002], [64924.2, 0.217], [65192.7, 0.0], [65359.4, 5.521], [65524.3, 5.596]]}
{"kind": "depth", "E": 1787080158891, "U": 11315333465778, "u": 11315333470724, "recv_ms": 1787080158856, "bids": [[1000.0, 35.81], [14212.2, 2.604], [14312.2, 1.596], [58240.9, 0.053], [62123.7, 0.692], [63712.2, 4.412], [64065.1, 9.908], [64077.1, 0.0], [64224.8, 0.07], [64571.6, 0.0], [64571.7, 0.838], [64647.4, 0.007], [64679.8, 0.005], [64698.2, 0.016], [64700.9, 0.621], [64702.4, 1.117], [64705.3, 0.002], [64706.3, 0.005], [64706.4, 0.039], [64706.5, 0.034], [64706.6, 0.056], [64711.0, 0.0], [64712.1, 1.052], [64712.2, 25.251]], "asks": [[64717.2, 0.273], [64719.5, 0.169], [64722.1, 0.475], [64725.3, 0.013], [64725.9, 0.158], [64741.2, 0.25], [64741.3, 1.325], [64741.4, 0.564], [64744.2, 0.154], [64744.3, 0.004], [64744.4, 0.128], [64745.0, 2.959], [64745.1, 1.012], [64745.2, 0.108], [64747.3, 0.063], [64747.4, 0.008], [64747.5, 0.014], [64749.0, 0.004], [64749.1, 0.031], [64757.6, 0.003], [64822.4, 0.014], [64852.5, 0.0], [65342.7, 0.078], [65359.4, 5.521], [65434.0, 1.06], [65712.3, 0.027], [65842.0, 0.743], [67947.9, 0.04], [68540.9, 0.002]]}
{"kind": "depth", "E": 1787080158993, "U": 11315333470748, "u": 11315333474417, "recv_ms": 1787080158935, "bids": [[1000.0, 35.81], [14212.2, 2.954], [14312.2, 1.246], [58240.9, 0.053], [61476.5, 0.004], [63822.6, 0.0], [63903.3, 15.969], [64065.1, 9.906], [64443.8, 34.823], [64444.7, 6.45], [64514.8, 27.702], [64571.6, 2.591], [64687.4, 0.637], [64688.2, 0.316], [64691.8, 0.003], [64692.7, 5.137], [64693.5, 2.338], [64700.9, 0.002], [64702.2, 0.002], [64702.4, 0.553], [64704.4, 0.48], [64705.3, 0.582], [64705.4, 0.345], [64706.3, 0.005], [64706.4, 0.039], [64706.5, 0.026], [64706.6, 0.048], [64706.7, 0.036], [64712.2, 24.912]], "asks": [[64717.2, 0.118], [64719.5, 0.014], [64722.1, 0.01], [64723.5, 0.021], [64723.7, 0.313], [64724.2, 0.14], [64725.9, 0.003], [64731.2, 2.287], [64731.6, 0.008], [64732.0, 0.024], [64735.6, 0.116], [64736.5, 0.0], [64744.2, 0.156], [64744.4, 0.126], [64748.9, 0.031], [64852.5, 5.397], [64909.9, 4.809], [64910.7, 26.546], [64979.2, 7.439], [64982.1, 33.59], [65359.4, 5.521]]}
