{"kind": "depth", "E": 1787080128597, "U": 11315331291242, "u": 11315331297611, "recv_ms": 1787080128544, "bids": [[1000.0, 35.81], [14212.2, 1.568], [14312.2, 2.632], [51770.0, 0.0], [58240.9, 0.002], [61476.5, 0.0], [61476.7, 0.002], [62123.7, 0.692], [63094.4, 1.347], [63418.0, 2.695], [63625.0, 2.58], [63712.2, 7.703], [63812.7, 10.603], [63838.6, 5.999], [63952.0, 3.168], [64000.4, 3.445], [64065.1, 9.883], [64143.3, 5.666], [64390.3, 0.229], [64584.8, 0.084], [64586.6, 0.121], [64620.6, 2.478], [64620.7, 0.12], [64639.8, 2.371], [64640.4, 0.033], [64670.7, 0.179], [64673.9, 2.802], [64690.6, 0.56], [64691.2, 0.011], [64691.7, 0.503], [64692.8, 1.48], [64693.6, 0.173], [64693.8, 0.39], [64695.2, 0.001], [64695.7, 1.097], [64696.1, 0.023], [64696.7, 0.022], [64697.9, 0.015], [64698.1, 1.003], [64699.3, 0.004], [64699.5, 0.234], [64699.9, 0.532], [64700.5, 0.313], [64701.0, 0.275], [64702.2, 0.477], [64702.4, 0.02], [64703.1, 0.326], [64703.8, 1.601], [64703.9, 0.563], [64704.1, 0.062], [64704.7, 0.001], [64704.9, 0.166], [64705.1, 0.04], [64705.2, 0.013], [64705.3, 0.118], [64705.9, 0.033], [64706.3, 0.003], [64707.4, 0.014], [64708.3, 0.211], [64708.4, 0.125], [64708.5, 0.002], [64708.7, 0.106], [64708.9, 0.003], [64709.1, 0.009], [64709.3, 0.004], [64709.4, 1.849], [64709.5, 0.011], [64709.7, 0.006], [64710.0, 0.01], [64712.2, 2.863]], "asks": [[64712.3, 27.616], [64713.4, 0.312], [64713.8, 0.009], [64713.9, 0.09], [64717.0, 1.052], [64717.4, 0.94], [64718.8, 0.309], [64720.0, 0.12], [64720.1, 2.319], [64721.9, 0.094], [64722.3, 1.142], [64722.9, 0.007], [64723.5, 0.0], [64724.2, 0.442], [64725.8, 0.002], [64726.0, 0.465], [64726.1, 0.224], [64727.1, 0.013], [64727.6, 0.002], [64732.4, 0.002], [64733.0, 0.001], [64733.2, 0.002], [64734.1, 0.003], [64734.4, 1.24], [64734.8, 0.551], [64735.0, 0.004], [64735.2, 0.007], [64735.3, 0.371], [64736.0, 1.718], [64736.8, 0.001], [64741.9, 0.016], [64754.7, 0.281], [64759.0, 0.401], [64790.3, 0.013], [64791.5, 0.0], [64797.3, 0.019], [64798.6, 0.024], [64804.4, 0.015], [64805.6, 2.178], [64811.5, 0.051], [64812.7, 0.832], [64818.5, 0.033], [64819.7, 5.135], [64825.6, 3.866], [64826.8, 0.03], [64832.6, 0.062], [64833.8, 0.002], [64839.7, 0.085], [64840.9, 0.0], [64869.7, 10.431], [64908.6, 15.406], [64911.8, 0.003], [64911.9, 0.0], [65359.4, 5.346], [65488.8, 37.563], [65624.7, 2.586], [65683.0, 3.875], [65712.3, 0.027]]}
{"kind": "depth", "E": 1787080128699, "U": 11315331297748, "u": 11315331302969, "recv_ms": 1787080128638, "bids": [[14212.2, 1.932], [14312.2, 2.268], [58240.9, 0.002], [61476.5, 0.0], [62123.7, 0.689], [64065.1, 9.883], [64168.6, 0.214], [64582.7, 0.003], [64640.7, 0.244], [64641.1, 0.032], [64671.7, 0.0], [64671.8, 0.207], [64673.9, 2.702], [64699.8, 0.156], [64704.8, 0.534], [64705.0, 0.158], [64706.3, 0.038], [64706.6, 1.654], [64712.2, 2.863]], "asks": [[64712.3, 27.611], [64718.8, 0.0], [64719.3, 0.622], [64869.7, 6.273], [64908.6, 11.31], [65359.4, 5.346]]}
{"kind": "depth", "E": 1787080128801, "U": 11315331303175, "u": 11315331309778, "recv_ms": 1787080128742, "bids": [[1000.0, 35.81], [14212.2, 2.282], [14312.2, 1.918], [58240.9, 0.002], [61476.5, 0.0], [62123.7, 0.692], [63712.2, 7.683], [63914.9, 6.744], [64065.1, 9.883], [64129.8, 34.245], [64388.6, 4.436], [64640.1, 0.034], [64640.4, 0.001], [64641.1, 0.0], [64691.8, 0.117], [64692.6, 0.001], [64705.6, 0.05], [64708.8, 0.087], [64712.2, 2.86]], "asks": [[64725.2, 0.141], [64727.8, 0.025], [64728.8, 1.531], [64729.5, 0.005], [64731.1, 1.329], [64732.1, 0.523], [64733.1, 0.0], [64869.7, 10.431], [64908.6, 15.406], [65359.4, 5.346], [65712.3, 0.007], [66006.5, 0.015], [71183.6, 0.0]]}
{"kind": "depth", "E": 1787080128903, "U": 11315331309812, "u": 11315331315307, "recv_ms": 1787080128844, "bids": [[1000.0, 35.81], [14212.2, 2.646], [14312.2, 1.554], [58240.9, 0.002], [63770.8, 5.48], [63935.7, 29.572], [64065.1, 9.883], [64108.9, 0.0], [64268.2, 0.026], [64571.5, 3.064], [64571.6, 0.838], [64640.7, 0.209], [64699.7, 0.416], [64699.8, 0.002], [64712.2, 2.887]], "asks": [[64712.3, 27.609], [64713.9, 0.087], [64734.8, 0.01], [64735.9, 0.541], [64740.6, 2.487], [64741.2, 0.404], [64742.4, 0.009], [64781.3, 6.429], [64852.8, 9.284], [64868.5, 2.203], [65359.4, 5.346], [65488.9, 5.312], [67947.9, 0.073]]}
{"kind": "depth", "E": 1787080129005, "U": 11315331315541, "u": 11315331320430, "recv_ms": 1787080128944, "bids": [[14212.2, 2.996], [14312.2, 1.204], [51769.8, 0.0], [58240.9, 0.002], [62123.7, 0.689], [63712.2, 7.703], [63794.5, 0.783], [64065.1, 9.883], [64168.6, 0.183], [64343.4, 0.004], [64640.1, 0.002], [64695.0, 0.004], [64696.0, 1.898], [64699.3, 0.158], [64699.7, 0.262]], "asks": [[64731.7, 0.847], [64741.2, 0.25], [64868.5, 0.753], [64869.7, 6.273], [64908.6, 11.31], [65038.0, 0.814], [65359.4, 5.346], [65533.1, 2.397], [65712.3, 0.027], [65919.7, 0.004]]}
{"kind": "depth", "E": 1787080129107, "U": 11315331320501, "u": 11315331325867, "recv_ms": 1787080129050, "bids": [[1000.0, 35.81], [14212.2, 3.36], [14312.2, 0.84], [58240.9, 0.002], [61476.5, 0.0], [62123.7, 0.692], [63712.2, 7.683], [63760.9, 3.524], [63795.1, 1.579], [64065.1, 9.885], [64388.6, 4.445], [64550.4, 0.03], [64620.5, 3.82], [64620.6, 2.475], [64639.8, 2.339], [64695.8, 0.002], [64700.6, 0.245], [64707.0, 0.097], [64707.4, 0.245], [64708.5, 0.021], [64712.2, 2.857]], "asks": [[64712.3, 27.612], [64741.3, 1.479], [64757.6, 0.003], [64780.2, 0.0], [64869.7, 10.431], [64908.6, 15.406], [65035.9, 3.842], [65230.0, 8.49], [65359.4, 5.346], [65488.8, 42.138], [65712.3, 0.007], [66006.5, 0.018]]}
{"kind": "depth", "E": 1787080129209, "U": 11315331325932, "u": 11315331331081, "recv_ms": 1787080129150, "bids": [[1000.0, 35.81], [14212.2, 3.682], [14312.2, 0.504], [14612.2, 0.014], [58240.9, 0.002], [61476.5, 0.0], [62123.7, 0.689], [63850.1, 13.336], [64042.6, 0.002], [64065.1, 9.883], [64095.6, 2.583], [64168.6, 0.142], [64255.4, 0.117], [64584.8, 0.0], [64586.6, 0.006], [64633.1, 0.024], [64640.3, 0.002], [64660.5, 0.001], [64663.4, 0.007], [64669.8, 0.063], [64691.8, 0.001], [64692.8, 1.596], [64694.1, 0.49], [64696.0, 0.989], [64699.3, 0.004], [64699.5, 0.388], [64699.7, 0.262], [64699.9, 0.532], [64702.2, 0.006], [64702.3, 0.001], [64704.1, 1.7], [64707.5, 0.381], [64708.8, 0.087]], "asks": [[64712.3, 27.614], [64715.7, 0.1], [64715.8, 0.003], [64715.9, 0.065], [64716.9, 0.074], [64717.8, 0.004], [64720.3, 0.08], [64721.5, 0.092], [64728.6, 0.725], [64734.1, 0.003], [64734.8, 0.551], [64735.9, 0.0], [64869.7, 6.245], [64908.6, 11.228], [65035.9, 3.843], [65359.4, 5.346], [65424.1, 7.223], [65631.2, 2.045], [104929.0, 0.0]]}
{"kind": "depth", "E": 1787080129311, "U": 11315331331099, "u": 11315331336296, "recv_ms": 1787080129251, "bids": [[14212.2, 3.738], [14312.2, 0.294], [14612.2, 0.168], [51770.0, 0.0], [58240.9, 0.002], [63418.0, 2.692], [63838.6, 6.78], [63939.1, 3.905], [64065.1, 9.906], [64660.5, 0.002], [64692.7, 0.012], [64696.0, 1.899], [64696.2, 0.005], [64699.5, 0.234], [64712.2, 2.858]], "asks": [[64712.3, 27.615], [64714.4, 0.009], [64717.4, 0.94], [64717.8, 0.003], [64728.7, 0.418], [64738.2, 0.004], [64822.4, 0.017], [64869.7, 10.431], [64908.6, 15.406], [65035.9, 3.997], [65230.0, 8.795], [65359.4, 5.368], [65553.6, 45.432], [65909.5, 0.992]]}
{"kind": "depth", "E": 1787080129413, "U": 11315331336322, "u": 11315331341904, "recv_ms": 1787080129353, "bids": [[1000.0, 35.81], [14212.2, 3.612], [14312.2, 0.182], [14612.2, 0.406], [51770.0, 0.0], [58240.9, 0.002], [61476.5, 0.0], [62123.7, 0.692], [63418.0, 2.695], [63712.2, 7.703], [63754.9, 9.459], [64065.1, 9.908], [64168.0, 0.036], [64168.6, 0.074], [64388.6, 4.434], [64571.5, 0.001], [64680.4, 0.09], [64692.6, 0.174], [64699.2, 0.166], [64708.8, 0.003], [64712.2, 2.784]], "asks": [[64720.3, 0.0], [64723.5, 0.08], [64728.1, 0.552], [64731.9, 0.721], [64737.7, 0.003], [64741.8, 0.0], [64746.8, 0.03], [64852.8, 3.887], [64906.3, 0.0], [65359.4, 5.368], [65712.3, 0.027], [67947.9, 0.078], [104929.0, 0.236]]}
{"kind": "depth", "E": 1787080129617, "U": 11315331348063, "u": 11315331353047, "recv_ms": 1787080129557, "bids": [[14212.2, 3.248], [14312.2, 0.0], [14612.2, 0.952], [58240.9, 0.002], [61476.5, 0.0], [62123.7, 0.692], [62770.9, 0.023], [63967.7, 4.563], [64065.1, 9.906], [64168.6, 0.037], [64679.8, 0.005], [64684.1, 0.002], [64692.3, 0.162], [64692.8, 1.48], [64694.1, 0.019], [64694.4, 0.627], [64694.8, 0.476], [64695.0, 0.904], [64696.0, 0.999], [64699.2, 0.012], [64702.2, 0.006], [64707.5, 0.071], [64708.3, 0.119], [64710.6, 0.209]], "asks": [[64714.1, 0.003], [64725.2, 0.141], [64730.7, 0.577], [64731.9, 0.165], [64757.6, 0.003], [64822.4, 0.014], [64971.3, 0.015], [64990.9, 0.019], [65359.4, 5.368], [65533.1, 2.054], [65629.4, 0.761], [66653.6, 0.022], [67947.9, 0.083], [71183.6, 0.0]]}
{"kind": "depth", "E": 1787080129719, "U": 11315331353079, "u": 11315331357886, "recv_ms": 1787080129659, "bids": [[1000.0, 35.81], [14212.2, 2.898], [14612.2, 1.302], [58240.9, 0.002], [61476.5, 0.0], [61476.6, 0.008], [62123.7, 0.689], [63730.4, 0.796], [63741.5, 11.411], [63799.2, 1.249], [64158.9, 0.078], [64388.6, 4.434], [64571.5, 0.001], [64582.7, 0.004], [64584.6, 0.739], [64586.4, 0.115], [64694.8, 0.005], [64698.9, 0.179], [64702.2, 0.477], [64707.2, 0.325], [64712.2, 2.6]], "asks": [[64744.1, 0.003], [64744.4, 0.124], [64852.7, 0.0], [64902.3, 0.013], [65359.4, 5.368], [65631.2, 2.272], [65650.6, 27.665], [65683.0, 6.915], [65888.9, 0.761]]}
{"kind": "depth", "E": 1787080129821, "U": 11315331358051, "u": 11315331364984, "recv_ms": 1787080129763, "bids": [[1000.0, 35.81], [14212.2, 2.534], [14612.2, 1.666], [51770.0, 0.0], [58240.9, 0.002], [63418.0, 2.692], [63712.2, 7.703], [63779.9, 0.094], [63935.6, 2.498], [63964.8, 1.128], [64065.1, 9.906], [64342.1, 0.055], [64342.2, 4.398], [64438.8, 0.144], [64440.4, 0.728], [64509.7, 0.0], [64511.7, 1.611], [64554.5, 7.43], [64571.5, 3.053], [64582.7, 0.003], [64646.9, 2.44], [64655.3, 2.15], [64663.6, 2.129], [64666.6, 4.309], [64694.4, 0.009], [64701.8, 0.001], [64704.0, 0.73], [64704.2, 0.211], [64704.4, 0.212], [64706.9, 0.233], [64707.2, 0.015], [64707.4, 0.014], [64707.5, 0.073], [64707.6, 0.142], [64708.4, 0.001], [64708.9, 0.001], [64712.1, 0.015], [64712.2, 1.449]], "asks": [[64712.3, 27.61], [64713.8, 0.002], [64714.4, 0.017], [64719.8, 0.001], [64726.3, 0.163], [64730.6, 0.38], [64734.8, 0.666], [64736.0, 1.603], [64797.2, 2.139], [64805.5, 2.219], [64805.6, 0.054], [64813.9, 2.125], [64814.0, 0.002], [64852.7, 5.397], [64869.7, 10.431], [64905.7, 2.574], [64907.0, 0.001], [64911.7, 0.003], [64911.8, 0.0], [64976.9, 0.492], [64978.4, 0.001], [65075.7, 1.183], [65075.9, 0.0], [65359.4, 5.368], [65597.8, 8.817], [65712.3, 0.027], [66006.5, 0.015]]}
{"kind": "depth", "E": 1787080129923, "U": 11315331365041, "u": 11315331369967, "recv_ms": 1787080129864, "bids": [[14212.2, 2.184], [14612.2, 2.016], [58240.9, 0.002], [60829.5, 0.043], [61476.5, 0.0], [62123.7, 0.692], [63418.0, 2.695], [63817.8, 30.431], [63882.4, 0.001], [63903.3, 9.732], [64065.1, 9.906], [64168.6, 0.0], [64571.5, 3.064], [64571.6, 1.186], [64674.8, 0.398], [64679.2, 0.058], [64680.1, 0.02], [64689.9, 0.656], [64690.6, 0.004], [64691.6, 0.116], [64692.3, 0.046], [64712.2, 1.375]], "asks": [[64725.2, 0.14], [64734.8, 0.551], [64735.3, 0.486], [64741.1, 0.451], [64741.4, 0.562], [64852.7, 5.397], [64868.5, 2.203], [64869.7, 6.249], [64908.6, 11.237], [65359.4, 5.368], [65520.6, 0.19], [68595.0, 0.038], [92300.0, 0.164]]}
{"kind": "depth", "E": 1787080130025, "U": 11315331370088, "u": 11315331376401, "recv_ms": 1787080129966, "bids": [[1000.0, 35.81], [14212.2, 1.834], [14612.2, 2.366], [51769.8, 0.0], [58240.9, 0.002], [61476.5, 0.0], [62123.7, 0.689], [63712.2, 7.683], [63720.3, 0.016], [63770.7, 0.096], [63973.9, 0.0], [64065.1, 9.906], [64079.9, 0.7], [64227.7, 0.025], [64388.6, 4.444], [64535.9, 2.93], [64537.9, 0.0], [64605.2, 0.001], [64670.0, 4.312], [64695.2, 0.464], [64696.5, 0.158], [64697.6, 3.71], [64697.7, 0.144], [64698.1, 0.003], [64702.2, 0.006], [64704.0, 0.182], [64704.2, 0.164], [64704.4, 0.135], [64704.7, 0.001], [64705.2, 1.851], [64705.3, 0.666], [64706.7, 0.209], [64706.9, 0.002], [64707.3, 0.232], [64708.5, 0.002], [64712.1, 0.015], [64712.2, 0.656]], "asks": [[64713.8, 0.01], [64716.8, 0.037], [64731.7, 0.918], [64732.9, 0.035], [64747.8, 0.006], [64868.5, 0.753], [64869.7, 10.431], [64908.6, 15.406], [65193.0, 0.036], [65342.9, 0.944], [65359.4, 5.368], [65533.0, 2.804], [65712.3, 0.007]]}
{"kind": "depth", "E": 1787080130127, "U": 11315331376451, "u": 11315331383671, "recv_ms": 1787080130068, "bids": [[1000.0, 35.81], [14212.2, 1.47], [14612.2, 2.73], [51770.0, 0.0], [58240.9, 0.002], [61476.5, 0.0], [62123.7, 0.692], [63725.3, 0.028], [63870.8, 3.288], [64065.1, 9.906], [64340.6, 42.863], [64437.3, 34.188], [64437.8, 5.695], [64507.3, 0.0], [64508.2, 27.669], [64508.3, 5.463], [64509.8, 0.931], [64640.4, 0.002], [64660.7, 0.227], [64663.5, 0.019], [64669.4, 0.364], [64669.8, 0.002], [64696.5, 0.158], [64697.6, 3.71], [64700.6, 0.245], [64700.7, 0.262], [64701.5, 0.219], [64703.9, 0.022], [64704.1, 1.696], [64704.6, 0.086], [64705.3, 0.118], [64705.4, 0.545], [64706.7, 0.757], [64707.7, 0.232], [64709.5, 0.016], [64712.1, 0.017], [64712.2, 1.591]], "asks": [[64712.3, 27.623], [64713.6, 0.002], [64713.8, 0.002], [64714.4, 0.009], [64716.7, 0.099], [64719.6, 0.008], [64721.2, 0.074], [64725.2, 0.141], [64730.7, 0.021], [64731.5, 0.558], [64733.7, 0.153], [64773.0, 0.101], [64773.4, 0.01], [64906.6, 0.218], [64906.7, 27.047], [64906.9, 0.002], [64976.9, 5.275], [64978.1, 33.236], [65054.4, 2.393], [65075.5, 7.616], [65075.6, 43.133], [65075.7, 0.006], [65359.4, 5.368], [65699.3, 1.33]]}
{"kind": "depth", "E": 1787080130229, "U": 11315331383767, "u": 11315331389432, "recv_ms": 1787080130170, "bids": [[14212.2, 1.12], [14612.2, 3.08], [51770.0, 0.0], [58240.9, 0.002], [61476.5, 0.0], [63712.2, 7.703], [63725.1, 0.032], [63964.7, 0.088], [64065.1, 9.906], [64224.8, 53.415], [64388.6, 4.444], [64633.2, 0.033], [64660.7, 0.228], [64663.5, 0.02], [64669.8, 0.004], [64689.9, 0.1], [64691.2, 0.567], [64691.6, 0.0], [64693.0, 0.118], [64699.7, 0.103], [64704.2, 0.705], [64705.4, 0.004], [64705.7, 0.062], [64707.4, 0.324], [64708.4, 0.085], [64712.2, 1.803]], "asks": [[64713.8, 0.009], [64714.0, 0.003], [64735.3, 0.371], [64735.9, 0.115], [65035.9, 3.997], [65192.7, 51.494], [65306.5, 2.293], [65359.4, 5.368], [65699.2, 0.019], [65712.3, 0.027]]}
{"kind": "depth", "E": 1787080130331, "U": 11315331389540, "u": 11315331395711, "recv_ms": 1787080130271, "bids": [[1000.0, 35.81], [14212.2, 0.756], [14612.2, 3.444], [51770.0, 0.0], [58240.9, 0.002], [62123.7, 0.689], [63710.5, 4.903], [63750.5, 0.015], [63935.7, 30.353], [64388.6, 4.445], [64696.2, 0.005]], "asks": [[64728.7, 0.418], [64869.7, 6.202], [64908.5, 11.419], [64908.6, 0.0], [65359.4, 5.368], [65533.1, 1.712]]}
{"kind": "depth", "E": 1787080130433, "U": 11315331395841, "u": 11315331404481, "recv_ms": 1787080130376, "bids": [[1000.0, 35.81], [14212.2, 0.462], [14512.2, 0.042], [14612.2, 3.696], [58240.9, 0.002], [61476.5, 0.0], [62123.7, 0.692], [63712.2, 7.683], [63819.3, 0.0], [64065.1, 9.908], [64078.2, 0.0], [64620.5, 3.817], [64668.5, 0.185], [64670.7, 0.179], [64679.2, 0.001], [64681.6, 1.215], [64690.2, 0.001], [64691.2, 0.011], [64692.1, 0.118], [64692.3, 0.602], [64693.0, 0.002], [64695.0, 0.004], [64695.3, 0.01], [64695.7, 0.172], [64696.0, 1.899], [64697.6, 2.71], [64697.7, 1.061], [64698.9, 1.179], [64701.5, 0.061], [64703.8, 1.599], [64704.0, 0.166], [64704.1, 0.003], [64704.2, 0.544], [64704.6, 0.085], [64705.1, 0.04], [64705.2, 0.013], [64705.3, 0.752], [64705.4, 0.011], [64706.0, 0.012], [64706.3, 0.038], [64706.7, 0.209], [64708.5, 0.025], [64708.6, 0.044], [64708.8, 0.003], [64709.0, 0.157], [64712.2, 4.025]], "asks": [[64712.3, 27.619], [64713.3, 0.31], [64713.4, 0.002], [64713.8, 0.002], [64714.1, 0.0], [64714.2, 0.007], [64714.4, 0.001], [64716.1, 0.011], [64726.0, 0.002], [64726.5, 0.61], [64728.8, 0.606], [64730.2, 0.928], [64730.5, 10.019], [64731.5, 0.002], [64731.9, 0.721], [64732.1, 0.466], [64733.4, 2.468], [64734.7, 0.224], [64734.8, 0.01], [64734.9, 0.851], [64735.6, 0.001], [64735.9, 0.541], [64736.9, 0.424], [64869.7, 8.617], [64908.5, 15.721], [64911.7, 0.0], [65119.2, 0.636], [65294.7, 7.035], [65359.4, 5.37], [65359.5, 0.001], [65673.7, 6.995], [65712.3, 0.007], [67947.9, 0.088]]}
{"kind": "depth", "E": 1787080130535, "U": 11315331404539, "u": 11315331412510, "recv_ms": 1787080130476, "bids": [[14212.2, 0.266], [14512.2, 0.224], [14612.2, 3.71], [58240.9, 0.002], [61476.5, 0.0], [61476.6, 0.008], [61476.7, 0.004], [62123.7, 0.689], [63418.0, 2.698], [63625.5, 6.286], [63903.3, 10.083], [63949.1, 9.369], [64065.1, 9.906], [64388.6, 4.435], [64594.9, 0.689], [64595.0, 4.112], [64620.2, 0.035], [64641.0, 0.323], [64670.7, 0.179], [64694.1, 0.482], [64694.8, 0.005], [64695.0, 0.012], [64695.2, 0.001], [64695.3, 0.002], [64702.2, 0.006], [64702.3, 0.001], [64702.5, 0.06], [64703.9, 0.122], [64704.2, 0.546], [64704.4, 0.676], [64704.7, 0.001], [64705.3, 0.118], [64705.4, 0.004], [64705.7, 0.003], [64705.9, 0.033], [64706.0, 0.01], [64706.5, 0.025], [64706.7, 0.209], [64706.8, 0.006], [64708.1, 0.083], [64708.5, 0.002], [64708.6, 0.025], [64708.8, 0.087], [64712.2, 4.647]], "asks": [[64712.3, 27.618], [64714.4, 0.011], [64715.9, 0.023], [64716.0, 0.132], [64721.2, 0.073], [64723.5, 0.0], [64724.5, 0.081], [64733.3, 1.562], [64734.1, 0.01], [64741.2, 0.248], [64741.4, 0.564], [64744.2, 0.0], [64744.4, 0.126], [64744.9, 0.022], [64745.2, 0.006], [64783.5, 0.048], [64847.8, 4.811], [64902.3, 1.768], [64911.4, 0.005], [65035.9, 3.996], [65184.0, 0.184], [65359.4, 5.368], [65663.6, 4.332]]}
{"kind": "depth", "E": 1787080130637, "U": 11315331412664, "u": 11315331417905, "recv_ms": 1787080130577, "bids": [[1000.0, 35.81], [14212.2, 0.154], [14512.2, 0.462], [14612.2, 3.584], [58240.9, 0.002], [61476.5, 0.0], [62123.7, 0.692], [63712.2, 7.703], [63737.5, 0.298], [64065.1, 9.906], [64388.6, 4.436], [64680.7, 0.217], [64681.6, 1.158], [64686.3, 0.034], [64691.3, 0.577], [64692.3, 0.046], [64694.1, 0.019], [64694.9, 1.084], [64695.0, 0.004], [64696.0, 1.9], [64697.0, 0.942], [64697.7, 0.136], [64702.2, 0.006], [64702.3, 1.662], [64702.4, 0.491], [64703.9, 0.586], [64704.4, 0.135], [64704.5, 0.077], [64708.2, 0.216], [64708.3, 0.096], [64712.2, 4.63]], "asks": [[64714.4, 0.011], [64726.8, 1.663], [64734.2, 1.961], [65248.8, 0.0], [65359.4, 5.368], [65521.2, 9.493], [65712.3, 0.027]]}
{"kind": "depth", "E": 1787080130739, "U": 11315331418049, "u": 11315331423927, "recv_ms": 1787080130678, "bids": [[1000.0, 35.81], [14212.2, 0.028], [14512.2, 0.7], [14612.2, 3.472], [58240.9, 0.002], [61476.5, 0.0], [63811.3, 2.659], [63884.4, 3.157], [64016.7, 1.402], [64065.1, 9.906], [64571.5, 0.001], [64571.6, 0.838], [64582.7, 0.003], [64696.5, 0.003]], "asks": [[64712.3, 27.623], [64714.4, 0.001], [64740.5, 0.248], [64741.3, 1.325], [64852.7, 0.0], [65359.4, 5.368], [65521.2, 9.751], [65712.6, 2.286]]}
{"kind": "depth", "E": 1787080130841, "U": 11315331424034, "u": 11315331429944, "recv_ms": 1787080130780, "bids": [[14212.2, 0.0], [14512.2, 1.022], [14612.2, 3.178], [58240.9, 0.002], [61476.5, 0.001], [62123.7, 0.689], [63612.1, 8.475], [63712.2, 7.683], [63935.7, 32.695], [64065.1, 9.908], [64077.1, 67.198], [64143.3, 3.331], [64388.6, 4.436], [64554.5, 3.627], [64709.9, 0.039], [64710.2, 0.02], [64712.2, 4.6]], "asks": [[64716.0, 0.09], [64740.7, 0.226], [64869.7, 0.026], [64986.6, 0.099], [65051.3, 0.08], [65342.7, 65.757], [65359.4, 5.37], [65712.3, 0.007], [71183.6, 0.001]]}
{"kind": "depth", "E": 1787080130943, "U": 11315331430125, "u": 11315331437016, "recv_ms": 1787080130884, "bids": [[1000.0, 35.81], [14512.2, 1.386], [14612.2, 2.814], [58240.9, 0.002], [60000.0, 97.817], [61476.5, 0.001], [62123.7, 0.692], [63712.2, 7.703], [63870.9, 13.057], [64006.8, 7.166], [64065.1, 9.906], [64129.8, 36.58], [64141.3, 0.005], [64342.2, 10.229], [64554.5, 6.691], [64571.5, 2.051], [64615.1, 2.336], [64620.1, 0.082], [64620.2, 0.032], [64647.5, 0.004], [64666.9, 0.54], [64668.5, 0.339], [64677.1, 0.057], [64679.7, 0.0], [64679.8, 0.002], [64680.7, 0.16], [64688.3, 0.557], [64689.9, 0.1], [64690.8, 0.118], [64691.3, 0.021], [64691.8, 0.008], [64692.1, 0.002], [64692.8, 1.473], [64693.2, 0.928], [64694.1, 0.027], [64694.3, 0.0], [64694.9, 0.466], [64695.3, 0.002], [64696.0, 1.0], [64696.3, 0.241], [64696.8, 1.001], [64697.0, 0.017], [64698.9, 0.179], [64702.3, 1.044], [64702.4, 0.483], [64702.5, 0.001], [64702.8, 0.0], [64703.7, 0.997], [64704.1, 0.157], [64704.2, 0.544], [64704.4, 0.143], [64706.7, 0.216], [64707.2, 0.008], [64707.4, 0.014], [64708.1, 0.083], [64708.2, 0.216], [64708.4, 0.001], [64708.8, 0.003], [64709.0, 0.003], [64709.5, 0.008], [64710.6, 0.055], [64712.1, 0.015], [64712.2, 0.683]], "asks": [[64713.2, 0.005], [64713.7, 0.046], [64714.4, 0.009], [64716.6, 0.024], [64716.7, 0.086], [64716.8, 0.059], [64717.3, 0.163], [64719.6, 0.0], [64721.9, 0.565], [64726.1, 0.216], [64726.5, 0.147], [64726.8, 1.97], [64728.5, 0.001], [64729.2, 0.116], [64730.2, 0.003], [64730.5, 0.019], [64731.0, 0.136], [64732.1, 0.473], [64733.4, 2.411], [64733.6, 0.584], [64733.9, 10.013], [64734.1, 0.544], [64734.2, 1.343], [64735.9, 0.0], [64736.9, 0.309], [64740.7, 0.072], [64740.8, 1.426], [64741.0, 0.109], [64741.1, 0.605], [64757.6, 0.003], [64777.0, 0.076], [64852.7, 5.397], [64868.5, 1.583], [64869.7, 6.306], [64905.7, 5.664], [64908.5, 11.68], [65000.0, 116.975], [65359.4, 5.368], [65712.3, 0.027], [71183.6, 0.0]]}
{"kind": "depth", "E": 1787080131045, "U": 11315331437201, "u": 11315331444649, "recv_ms": 1787080130989, "bids": [[1000.0, 35.81], [14512.2, 1.75], [14612.2, 2.45], [51769.8, 0.0], [58240.9, 0.002], [61476.5, 0.0], [62123.7, 0.689], [63418.0, 2.701], [63924.5, 0.781], [64065.1, 9.906], [64668.5, 0.185], [64693.2, 0.003], [64694.0, 2.817], [64694.1, 0.49], [64694.8, 0.93], [64700.6, 0.25], [64702.2, 0.547], [64702.4, 0.02], [64702.8, 0.0], [64703.7, 0.997], [64703.9, 0.03], [64704.2, 0.003], [64704.4, 1.857], [64704.5, 0.085], [64704.9, 0.707], [64705.2, 1.663], [64705.3, 0.125], [64705.7, 0.062], [64706.5, 0.027], [64706.8, 0.014], [64707.5, 0.071], [64708.1, 0.075], [64708.3, 0.096], [64709.5, 0.016], [64710.4, 0.078], [64710.6, 0.209]], "asks": [[64716.0, 0.093], [64719.4, 0.004], [64719.9, 0.003], [64720.0, 0.762], [64721.9, 0.464], [64722.1, 0.217], [64722.2, 0.136], [64728.2, 0.002], [64729.7, 2.185], [64729.9, 0.558], [64731.6, 0.014], [64731.9, 0.165], [64732.6, 0.611], [64733.3, 2.684], [64734.1, 0.003], [64741.1, 0.451], [64741.2, 0.402], [64869.7, 10.431], [64908.5, 15.721], [65116.0, 0.125], [65359.4, 5.368], [65621.9, 3.618], [65673.7, 5.779]]}
{"kind": "depth", "E": 1787080131147, "U": 11315331444725, "u": 11315331453441, "recv_ms": 1787080131091, "bids": [[14512.2, 2.1], [14612.2, 2.1], [58240.9, 0.002], [61476.5, 0.0], [62123.7, 0.692], [64065.1, 9.906], [64129.6, 3.27], [64388.6, 4.446], [64453.1, 0.004], [64472.9, 0.049], [64640.4, 0.003], [64660.7, 0.229], [64663.6, 2.13], [64677.1, 0.0], [64679.3, 2.385], [64679.8, 0.005], [64695.0, 0.004], [64697.7, 0.126], [64700.3, 0.323], [64700.6, 0.245], [64701.4, 0.464], [64702.2, 0.006], [64703.6, 0.013], [64703.8, 2.14], [64703.9, 0.107], [64704.2, 0.087], [64704.5, 0.008], [64706.6, 1.885], [64707.3, 0.001], [64707.7, 0.148], [64708.3, 0.096], [64709.2, 0.024], [64709.5, 0.011], [64710.4, 0.059], [64712.1, 1.405], [64712.2, 0.636]], "asks": [[64712.3, 27.625], [64713.8, 0.01], [64714.2, 0.0], [64714.4, 0.03], [64716.1, 0.0], [64718.0, 0.494], [64719.9, 0.628], [64720.0, 0.136], [64722.2, 0.129], [64725.7, 0.057], [64725.8, 0.01], [64726.8, 1.045], [64727.5, 0.927], [64730.5, 0.017], [64732.0, 5.026], [64732.6, 0.07], [64733.8, 0.696], [64777.1, 0.005], [64822.4, 0.017], [64869.7, 10.431], [64908.5, 15.721], [64916.3, 0.0], [65180.7, 0.08], [65359.4, 5.368], [65583.1, 0.761], [66006.5, 0.015]]}
{"kind": "depth", "E": 1787080131249, "U": 11315331453605, "u": 11315331463583, "recv_ms": 1787080131190, "bids": [[1000.0, 35.81], [14512.2, 2.45], [14612.2, 1.75], [58240.9, 0.002], [61476.5, 0.0], [63712.2, 7.683], [64013.8, 6.239], [64065.1, 9.906], [64388.6, 4.445], [64673.8, 0.573], [64676.4, 0.39], [64688.3, 0.001], [64690.4, 0.56], [64690.8, 0.002], [64692.2, 0.146], [64694.1, 0.027], [64695.0, 0.467], [64696.8, 0.001], [64697.9, 1.015], [64701.4, 0.463], [64703.8, 1.599], [64703.9, 0.114], [64704.5, 0.085], [64705.3, 0.666], [64705.7, 0.157], [64706.8, 0.006], [64707.0, 0.013], [64708.1, 0.083], [64710.6, 0.055], [64712.1, 0.015], [64712.2, 1.006]], "asks": [[64712.3, 27.238], [64713.8, 0.01], [64714.4, 0.027], [64716.7, 0.086], [64719.9, 0.003], [64720.0, 0.12], [64721.9, 0.001], [64722.2, 0.77], [64725.2, 0.141], [64725.8, 0.01], [64726.0, 0.465], [64727.2, 3.051], [64727.5, 0.002], [64728.2, 0.927], [64728.5, 10.001], [64729.9, 0.002], [64730.6, 0.38], [64731.2, 3.765], [64733.6, 0.469], [64733.8, 0.155], [64733.9, 0.013], [64734.8, 0.551], [64735.1, 0.001], [64735.6, 0.116], [64740.9, 0.001], [64741.2, 0.248], [65359.4, 5.368], [65550.8, 2.288], [65611.8, 10.477], [65667.4, 0.009], [65712.3, 0.007]]}
{"kind": "depth", "E": 1787080131351, "U": 11315331463626, "u": 11315331473308, "recv_ms": 1787080131292, "bids": [[1000.0, 35.81], [14512.2, 2.814], [14612.2, 1.386], [58240.9, 0.002], [61476.5, 0.0], [62123.7, 0.689], [64065.1, 9.906], [64168.1, 0.0], [64665.3, 0.125], [64666.3, 0.737], [64671.8, 0.007], [64672.8, 0.602], [64684.7, 1.582], [64685.7, 0.564], [64696.2, 0.005], [64696.7, 1.022], [64697.9, 0.015], [64704.5, 0.626], [64705.3, 0.125], [64706.8, 0.014], [64708.1, 0.075], [64712.1, 1.405], [64712.2, 0.559]], "asks": [[64712.3, 27.625], [64713.8, 0.002], [64716.8, 0.072], [64719.9, 0.01], [64720.0, 0.754], [64721.9, 0.464], [64722.2, 0.129], [64725.2, 0.141], [64725.8, 0.01], [64726.0, 0.002], [64728.7, 0.418], [64731.0, 0.079], [64732.1, 0.53], [64733.3, 1.562], [64741.1, 0.605], [65035.9, 3.997], [65054.0, 0.351], [65359.4, 5.368], [65359.5, 0.0], [65663.6, 5.548]]}
{"kind": "depth", "E": 1787080131453, "U": 11315331473318, "u": 11315331491951, "recv_ms": 1787080131393, "bids": [[14512.2, 3.164], [14612.2, 1.036], [58240.9, 0.002], [61476.5, 0.001], [62123.7, 0.692], [63712.2, 7.703], [63779.9, 0.0], [63799.8, 1.576], [64000.4, 5.067], [64065.1, 9.906], [64194.5, 8.569], [64388.6, 4.435], [64615.1, 2.344], [64631.8, 0.015], [64675.8, 1.835], [64680.4, 0.09], [64694.0, 1.917], [64694.1, 0.49], [64694.8, 0.005], [64695.0, 0.904], [64696.5, 0.928], [64696.7, 1.022], [64697.8, 0.005], [64703.9, 0.106], [64704.5, 0.549], [64704.6, 0.162], [64704.9, 0.715], [64705.7, 0.216], [64706.8, 0.006], [64707.2, 0.092], [64708.1, 0.083], [64712.1, 0.015], [64712.2, 0.96]], "asks": [[64712.3, 27.235], [64718.0, 0.493], [64719.9, 0.003], [64720.0, 1.217], [64721.9, 0.001], [64722.2, 0.136], [64726.0, 0.002], [64728.2, 0.002], [64729.0, 1.062], [64731.2, 3.209], [64731.9, 0.721], [64732.1, 0.523], [64733.2, 0.009], [64734.8, 0.01], [64735.6, 0.001], [64735.9, 0.541], [64736.3, 0.296], [64746.6, 0.018], [65359.4, 5.368], [65521.2, 10.093], [65650.6, 28.73], [65712.3, 0.027]]}
{"kind": "depth", "E": 1787080131555, "U": 11315331492250, "u": 11315331502949, "recv_ms": 1787080131496, "bids": [[1000.0, 35.81], [14512.2, 3.528], [14612.2, 0.672], [58240.9, 0.002], [61476.5, 0.0], [62123.7, 0.689], [63770.5, 0.391], [63806.2, 26.369], [64065.1, 9.906], [64388.6, 4.434], [64651.7, 0.001], [64651.9, 0.349], [64670.7, 0.165], [64673.8, 0.237], [64677.6, 0.337], [64679.3, 2.328], [64680.4, 0.092], [64681.8, 0.057], [64682.8, 0.016], [64690.4, 0.004], [64691.8, 0.001], [64692.2, 0.03], [64693.6, 0.729], [64694.1, 0.598], [64694.3, 0.007], [64695.2, 0.009], [64695.4, 0.021], [64696.0, 1.9], [64696.5, 0.003], [64696.7, 0.022], [64697.8, 0.005], [64698.2, 0.941], [64698.9, 0.179], [64699.1, 1.311], [64703.7, 0.995], [64703.9, 0.022], [64704.2, 0.003], [64704.4, 0.135], [64704.5, 0.0], [64704.6, 0.078], [64704.9, 0.174], [64705.1, 0.042], [64705.3, 0.667], [64705.7, 0.157], [64706.3, 0.041], [64706.7, 0.092], [64706.8, 0.554], [64706.9, 0.126], [64707.3, 0.311], [64707.6, 0.226], [64708.1, 0.167], [64708.8, 0.087], [64709.2, 0.108], [64712.1, 0.017], [64712.2, 5.341]], "asks": [[64713.2, 0.002], [64713.3, 0.0], [64713.4, 0.002], [64713.8, 0.002], [64714.4, 0.009], [64716.1, 0.011], [64716.6, 0.004], [64716.8, 0.05], [64719.6, 0.008], [64719.9, 0.003], [64720.0, 0.12], [64722.2, 0.77], [64726.0, 0.465], [64727.2, 1.859], [64728.5, 0.003], [64729.0, 0.137], [64729.4, 2.761], [64730.6, 0.38], [64731.4, 0.925], [64731.7, 0.847], [64731.9, 0.165], [64732.0, 0.026], [64732.1, 0.466], [64732.8, 12.271], [64733.2, 0.002], [64733.8, 0.711], [64734.5, 0.007], [64734.6, 0.439], [64735.2, 0.003], [64735.9, 0.0], [64736.3, 0.181], [64737.1, 0.869], [64737.3, 1.819], [64746.8, 0.032], [64869.7, 10.431], [64908.5, 15.721], [65118.8, 0.05], [65359.4, 5.368], [65362.6, 0.013], [65585.9, 2.995]]}
{"kind": "depth", "E": 1787080131657, "U": 11315331503291, "u": 11315331509953, "recv_ms": 1787080131598, "bids": [[1000.0, 35.81], [14412.2, 0.07], [14512.2, 3.752], [14612.2, 0.378], [51770.0, 0.0], [58240.9, 0.002], [61476.5, 0.0], [62123.7, 0.692], [63418.0, 2.698], [63712.2, 7.683], [64065.1, 9.906], [64158.7, 0.078], [64388.6, 4.279], [64654.2, 0.0], [64666.3, 0.74], [64680.2, 0.071], [64681.8, 0.0], [64690.1, 0.078], [64692.1, 0.558], [64693.6, 0.173], [64694.1, 0.135], [64695.0, 0.904], [64695.2, 0.001], [64696.3, 1.166], [64697.5, 0.002], [64697.8, 1.005], [64698.2, 0.016], [64699.1, 0.311], [64702.3, 1.044], [64702.4, 0.483], [64702.5, 0.06], [64702.8, 0.008], [64703.9, 0.65], [64704.0, 0.174], [64704.6, 0.001], [64704.7, 0.001], [64704.9, 0.166], [64705.1, 0.04], [64705.3, 0.118], [64705.4, 0.552], [64706.3, 0.038], [64706.8, 0.006], [64706.9, 0.134], [64708.1, 0.159], [64708.8, 0.003], [64709.2, 0.024], [64712.2, 2.335]], "asks": [[64713.5, 1.516], [64713.8, 0.009], [64714.4, 0.017], [64716.1, 0.0], [64717.2, 0.02], [64717.3, 0.186], [64719.6, 0.0], [64721.9, 0.009], [64725.8, 0.002], [64726.9, 0.158], [64729.7, 3.11], [64731.2, 3.211], [64731.4, 0.0], [64732.0, 0.024], [64732.1, 0.523], [64734.2, 1.961], [64734.6, 0.382], [64734.8, 0.551], [64737.1, 0.328], [64741.0, 0.109], [64741.1, 0.449], [64741.2, 0.404], [64744.1, 0.001], [64744.2, 0.002], [64869.7, 6.27], [64908.5, 11.579], [65035.9, 3.998], [65183.6, 0.006], [65359.4, 5.368], [65712.3, 0.007], [66006.5, 0.012]]}
{"kind": "depth", "E": 1787080131759, "U": 11315331510013, "u": 11315331522800, "recv_ms": 1787080131700, "bids": [[14412.2, 0.28], [14512.2, 3.682], [14612.2, 0.238], [58240.9, 0.002], [61476.5, 0.0], [61476.6, 0.008], [61476.7, 0.006], [63754.9, 7.831], [64065.1, 9.906], [64388.6, 4.289], [64582.7, 0.003], [64634.5, 0.003], [64642.8, 0.002], [64657.8, 0.016], [64665.5, 0.034], [64670.7, 0.165], [64681.6, 0.183], [64690.1, 0.074], [64692.8, 1.473], [64695.2, 0.464], [64695.3, 0.01], [64697.8, 0.005], [64699.1, 1.311], [64702.4, 0.02], [64702.8, 0.0], [64703.9, 0.022], [64704.0, 0.166], [64705.1, 0.042], [64705.3, 0.211], [64705.4, 0.004], [64705.5, 0.549], [64706.6, 1.654], [64706.7, 0.64], [64706.9, 0.126], [64707.3, 0.542], [64708.1, 0.167], [64709.0, 0.087], [64712.2, 5.381]], "asks": [[64712.3, 27.235], [64712.4, 0.042], [64712.5, 0.0], [64713.2, 0.002], [64713.5, 1.513], [64713.8, 0.002], [64714.4, 0.018], [64715.0, 0.105], [64716.0, 0.104], [64716.5, 0.002], [64719.3, 0.313], [64719.6, 0.0], [64719.9, 0.011], [64720.0, 0.119], [64721.9, 0.001], [64722.2, 0.145], [64722.9, 0.0], [64725.0, 0.004], [64725.2, 0.141], [64725.9, 0.011], [64726.0, 0.002], [64727.2, 1.852], [64727.3, 0.531], [64729.7, 2.185], [64730.0, 0.499], [64732.1, 0.466], [64733.0, 0.0], [64733.8, 0.001], [64734.2, 1.343], [64734.5, 0.0], [64734.8, 0.01], [64735.0, 0.003], [64737.3, 1.704], [64739.9, 0.016], [64740.0, 0.563], [64740.2, 0.146], [64755.9, 0.511], [64756.1, 0.002], [64778.6, 1.394], [64778.7, 0.173], [64779.0, 2.677], [64869.7, 8.411], [64908.5, 15.721], [65359.4, 5.521], [65521.2, 10.474], [65533.1, 1.37], [66006.5, 0.015]]}
{"kind": "depth", "E": 1787080131861, "U": 11315331523147, "u": 11315331535815, "recv_ms": 1787080131802, "bids": [[1000.0, 35.81], [14412.2, 0.532], [14512.2, 3.542], [14612.2, 0.126], [58240.9, 0.002], [61476.6, 0.01], [62123.7, 0.689], [63712.2, 7.703], [64065.1, 9.906], [64388.6, 4.444], [64610.5, 0.003], [64611.0, 2.554], [64647.4, 0.007], [64707.0, 0.016], [64709.7, 0.09], [64712.2, 5.381]], "asks": [[64712.3, 27.622], [64712.4, 0.046], [64712.5, 0.001], [64714.4, 0.018], [64715.0, 0.106], [64717.1, 0.018], [64719.4, 0.313], [64720.0, 0.12], [64722.2, 0.77], [64723.0, 0.01], [64725.0, 0.005], [64725.2, 0.14], [64726.1, 0.679], [64726.5, 0.301], [64726.6, 0.485], [64729.3, 1.553], [64730.0, 0.5], [64731.3, 0.17], [64731.8, 0.558], [64732.6, 0.127], [64733.1, 0.154], [64734.2, 1.35], [64735.0, 0.004], [64735.9, 0.541], [64736.2, 0.116], [64737.9, 0.998], [64739.5, 0.166], [64740.0, 0.564], [64753.2, 1.505], [64754.1, 3.502], [64776.8, 6.0], [64811.0, 1.537], [64812.3, 2.319], [64812.4, 0.0], [64812.5, 0.03], [64980.8, 5.077], [65248.4, 0.003], [65337.2, 3.284], [65359.4, 5.523], [65597.8, 8.666], [65630.1, 27.982], [65712.3, 0.027]]}
{"kind": "depth", "E": 1787080131963, "U": 11315331535875, "u": 11315331546611, "recv_ms": 1787080131905, "bids": [[1000.0, 35.81], [14412.2, 0.756], [14512.2, 3.444], [14612.2, 0.0], [58240.9, 0.002], [61476.5, 0.0], [62123.7, 0.692], [64065.1, 9.906], [64571.5, 2.065], [64642.7, 39.113], [64665.3, 3.625], [64679.6, 0.162], [64681.5, 1.116], [64692.1, 0.674], [64694.1, 0.019], [64695.2, 0.001], [64695.3, 0.002], [64697.8, 1.005], [64698.9, 0.025], [64699.1, 0.311], [64702.4, 0.491], [64702.5, 0.001], [64703.9, 0.658], [64704.3, 0.246], [64705.1, 0.04], [64705.3, 0.118], [64705.5, 0.008], [64705.6, 0.598], [64706.7, 0.092], [64707.0, 0.013], [64709.7, 0.006], [64712.2, 2.229]], "asks": [[64713.3, 0.003], [64713.8, 0.009], [64714.4, 0.018], [64716.0, 0.093], [64719.6, 0.008], [64719.9, 0.003], [64734.1, 0.544], [64735.9, 0.0], [64852.7, 5.397], [65035.9, 3.844], [65230.0, 8.49], [65327.1, 6.456], [65359.4, 5.521], [65453.7, 4.58]]}
{"kind": "depth", "E": 1787080132065, "U": 11315331546789, "u": 11315331560280, "recv_ms": 1787080132006, "bids": [[14412.2, 1.12], [14512.2, 3.08], [51769.8, 0.0], [58240.9, 0.002], [61476.5, 0.0], [62123.7, 0.689], [63418.0, 2.701], [63712.2, 7.683], [63725.3, 0.02], [63741.5, 13.04], [63914.9, 6.393], [64065.1, 9.906], [64388.6, 4.444], [64390.3, 0.288], [64610.1, 10.001], [64611.0, 3.411], [64670.7, 0.165], [64697.8, 1.005], [64698.4, 0.302], [64699.1, 0.311], [64699.7, 0.103], [64700.6, 0.245], [64701.5, 0.226], [64703.9, 0.642], [64704.0, 0.182], [64704.1, 0.213], [64705.3, 0.118], [64705.6, 0.05], [64706.7, 0.633], [64706.8, 0.013], [64709.4, 1.933], [64710.4, 0.009], [64711.7, 0.101], [64712.2, 2.276]], "asks": [[64712.3, 27.61], [64713.3, 0.0], [64713.7, 0.049], [64725.2, 0.141], [64740.4, 3.601], [64741.1, 0.603], [64741.2, 0.25], [64806.9, 3.31], [64809.2, 10.0], [65035.9, 3.998], [65230.0, 8.795], [65359.4, 5.521], [65521.2, 10.816], [65699.3, 1.322], [65712.3, 0.007], [66214.6, 0.022], [67947.9, 0.083], [71183.6, 0.0]]}
{"kind": "depth", "E": 1787080132167, "U": 11315331560431, "u": 11315331568748, "recv_ms": 1787080132121, "bids": [[1000.0, 35.81], [14412.2, 1.47], [14512.2, 2.73], [58240.9, 0.002], [61476.5, 0.001], [63725.1, 0.04], [64065.1, 9.906], [64633.4, 0.003], [64634.5, 0.0], [64640.5, 0.001], [64660.8, 1.171], [64663.6, 2.131], [64666.9, 0.537], [64679.8, 0.005], [64704.8, 0.534], [64709.4, 1.849], [64710.9, 0.046], [64711.0, 0.019], [64712.2, 2.304]], "asks": [[64714.4, 0.018], [64721.4, 0.029], [64725.2, 0.14], [64734.4, 1.244], [64741.3, 1.325], [64744.1, 0.003], [64744.3, 0.004], [64744.4, 0.124], [64744.9, 0.024], [64745.0, 2.959], [64745.1, 1.012], [64745.2, 0.004], [64747.2, 1.398], [64747.3, 0.063], [64747.4, 0.008], [64757.6, 0.003], [64822.4, 0.014], [64824.4, 0.0], [64986.5, 0.486], [65359.4, 5.521], [65499.0, 12.406], [66653.5, 0.001]]}
{"kind": "depth", "E": 1787080132269, "U": 11315331569260, "u": 11315331576408, "recv_ms": 1787080132209, "bids": [[1000.0, 35.81], [14412.2, 1.834], [14512.2, 2.366], [51770.0, 0.0], [58240.9, 0.002], [61476.5, 0.0], [62123.7, 0.692], [63712.2, 7.703], [63770.8, 4.932], [63806.1, 2.347], [64065.0, 2.36], [64065.1, 9.906], [64690.8, 0.558], [64692.1, 0.118], [64693.2, 0.01], [64694.3, 0.0], [64712.2, 2.257]], "asks": [[64712.3, 27.611], [64714.4, 0.018], [65359.4, 5.521], [65518.4, 2.286], [65694.9, 4.484], [65699.2, 0.027], [65712.3, 0.027], [66006.5, 0.012]]}
{"kind": "depth", "E": 1787080132371, "U": 11315331576551, "u": 11315331582388, "recv_ms": 1787080132312, "bids": [[14412.2, 2.184], [14512.2, 2.016], [51770.0, 0.0], [58240.9, 0.002], [61476.5, 0.0], [62123.7, 0.689], [63612.1, 3.766], [64065.1, 9.906], [64388.6, 4.434], [64657.8, 0.002], [64670.7, 0.179], [64696.2, 0.003], [64697.8, 0.005], [64698.3, 1.002], [64699.4, 0.249], [64701.5, 0.061], [64702.4, 0.02], [64702.5, 0.001], [64703.9, 1.034], [64704.0, 0.166], [64704.1, 0.157], [64704.7, 0.003], [64705.1, 0.04], [64705.3, 0.211], [64709.6, 0.002], [64712.2, 3.071]], "asks": [[64713.7, 0.046], [64713.8, 0.002], [64714.0, 0.003], [64714.4, 0.018], [64716.0, 0.104], [64728.7, 0.416], [64734.1, 0.003], [64734.8, 0.551], [64741.1, 0.605], [64741.4, 0.562], [65035.9, 3.997], [65051.2, 0.487], [65359.4, 5.521], [65488.8, 46.254], [65812.4, 1.448]]}
{"kind": "depth", "E": 1787080132473, "U": 11315331582445, "u": 11315331588015, "recv_ms": 1787080132414, "bids": [[1000.0, 35.81], [14412.2, 2.534], [14512.2, 1.666], [58240.9, 0.002], [61476.5, 0.0], [61476.7, 0.004], [62123.7, 0.692], [63712.2, 7.683], [63760.9, 4.072], [63817.8, 30.243], [64065.1, 9.906], [64388.6, 4.435], [64670.7, 0.165], [64673.3, 0.069], [64686.2, 0.157], [64686.7, 0.106], [64689.8, 2.497], [64692.1, 0.002], [64693.3, 1.388], [64695.2, 0.464], [64695.3, 0.01], [64696.2, 0.005], [64698.3, 0.002], [64699.4, 1.249], [64703.9, 0.563], [64704.0, 0.807], [64704.1, 0.157], [64704.2, 0.127], [64704.7, 0.001], [64705.2, 0.013], [64705.3, 0.118], [64705.4, 0.004], [64706.5, 0.029], [64706.6, 0.034], [64706.7, 0.741], [64706.8, 0.006], [64706.9, 0.002], [64707.3, 0.311], [64707.7, 0.379], [64708.2, 0.223], [64709.8, 0.088], [64709.9, 0.016], [64710.2, 0.0], [64712.2, 6.798]], "asks": [[64712.3, 27.628], [64714.4, 0.018], [64719.4, 0.004], [64719.9, 0.312], [64721.0, 0.904], [64723.0, 0.003], [64723.5, 0.007], [64726.1, 0.216], [64726.7, 0.805], [64728.7, 0.418], [64732.6, 5.127], [64734.8, 0.01], [64735.9, 0.541], [64774.5, 0.02], [64777.1, 0.023], [64800.6, 0.0], [65359.4, 5.521], [65479.6, 1.848], [65694.7, 1.053], [65712.3, 0.007], [66006.5, 0.015]]}
{"kind": "depth", "E": 1787080132575, "U": 11315331588199, "u": 11315331595807, "recv_ms": 1787080132516, "bids": [[1000.0, 35.81], [14412.2, 2.898], [14512.2, 1.302], [58240.9, 0.002], [61476.5, 0.0], [62123.7, 0.689], [63418.0, 2.701], [63799.8, 2.515], [63999.3, 0.879], [64065.1, 9.906], [64673.3, 0.083], [64695.2, 0.001], [64695.3, 0.002], [64696.0, 1.284], [64697.0, 0.917], [64698.4, 0.148], [64698.9, 0.179], [64704.1, 0.644], [64704.8, 0.536], [64706.5, 0.027], [64708.1, 0.159], [64709.5, 0.003], [64712.2, 6.752]], "asks": [[64712.3, 27.629], [64714.4, 0.018], [64720.0, 0.121], [64720.1, 2.32], [64869.7, 8.761], [64908.5, 15.721], [64911.3, 0.004], [64911.4, 0.002], [65115.9, 0.489], [65359.4, 5.521], [65683.0, 7.294]]}
{"kind": "depth", "E": 1787080132677, "U": 11315331595985, "u": 11315331602332, "recv_ms": 1787080132617, "bids": [[14412.2, 3.248], [14512.2, 0.952], [58240.9, 0.002], [61476.5, 0.0], [63612.1, 8.475], [63712.2, 7.703], [63787.3, 4.226], [64065.1, 9.906], [64194.5, 8.259], [64388.6, 4.435], [64582.7, 0.004], [64692.3, 0.162], [64693.3, 1.272], [64697.1, 0.96], [64698.9, 0.179], [64704.8, 0.534], [64704.9, 0.168], [64706.0, 0.01], [64706.2, 0.085], [64706.7, 0.738], [64709.5, 0.087], [64709.8, 0.004], [64712.2, 6.977]], "asks": [[64730.7, 0.021], [64730.8, 0.042], [64731.6, 0.57], [64731.8, 0.002], [64732.6, 0.127], [64734.1, 0.003], [64734.4, 1.24], [64734.8, 0.551], [64735.1, 0.001], [64735.9, 0.0], [64736.0, 1.718], [64736.2, 0.001], [64738.2, 0.622], [64823.7, 0.086], [64869.7, 6.27], [64908.5, 11.579], [65035.9, 3.996], [65180.6, 0.506], [65359.4, 5.521], [65712.3, 0.027], [65812.4, 6.0]]}
{"kind": "depth", "E": 1787080132779, "U": 11315331602365, "u": 11315331607264, "recv_ms": 1787080132721, "bids": [[1000.0, 35.81], [14412.2, 3.612], [14512.2, 0.588], [58240.9, 0.002], [61476.5, 0.0], [62123.7, 0.692], [63968.0, 9.704], [64065.1, 9.906], [64388.6, 4.436], [64582.7, 0.003], [64688.2, 0.168], [64691.7, 0.518], [64698.9, 0.025], [64699.1, 0.465], [64703.6, 0.0], [64707.8, 0.078]], "asks": [[64712.3, 27.631], [64812.5, 0.027], [64869.7, 10.431], [64908.5, 15.721], [65359.4, 5.521], [65469.4, 2.899]]}
{"kind": "depth", "E": 1787080132983, "U": 11315331628536, "u": 11315331641912, "recv_ms": 1787080132925, "bids": [[14312.2, 0.336], [14412.2, 3.654], [14512.2, 0.21], [58240.9, 0.002], [61476.5, 0.0], [62123.7, 0.692], [63773.9, 40.862], [64065.1, 9.906], [64388.6, 4.436], [64603.7, 2.4], [64604.9, 0.002], [64607.9, 0.995], [64686.7, 0.097], [64690.0, 0.384], [64692.6, 0.299], [64692.7, 0.012], [64709.6, 0.086], [64712.2, 6.977]], "asks": [[64712.3, 27.629], [64714.4, 0.008], [64729.7, 3.1], [64741.1, 0.451], [64819.1, 2.318], [64820.7, 0.043], [65035.9, 3.842], [65359.4, 5.521], [65488.8, 45.796], [65533.7, 0.762]]}
{"kind": "depth", "E": 1787080133085, "U": 11315331642198, "u": 11315331651758, "recv_ms": 1787080133026, "bids": [[1000.0, 35.81], [14312.2, 0.574], [14412.2, 3.528], [14512.2, 0.098], [51769.8, 0.0], [51770.0, 0.0], [58240.9, 0.002], [61476.5, 0.0], [62123.7, 0.689], [63418.0, 2.698], [63712.2, 7.703], [63725.3, 0.0], [63935.7, 28.009], [64065.1, 9.906], [64094.4, 0.0], [64620.0, 1.787], [64620.1, 0.079], [64666.9, 0.54], [64668.5, 0.339], [64694.0, 1.919], [64695.2, 0.472], [64700.6, 0.245], [64702.4, 0.02], [64703.9, 0.563], [64704.1, 0.228], [64704.9, 0.166], [64705.5, 0.01], [64705.7, 0.003], [64706.0, 0.01], [64706.5, 0.025], [64706.7, 0.555], [64709.2, 0.108], [64709.6, 0.002], [64710.6, 0.0], [64711.1, 0.002], [64712.2, 7.488]], "asks": [[64712.3, 27.602], [64714.4, 0.008], [64738.2, 0.004], [64741.2, 0.404], [64809.4, 0.474], [64822.4, 0.017], [64869.7, 6.305], [64908.5, 11.679], [64911.2, 0.104], [64911.3, 0.001], [65359.4, 5.521], [65699.3, 1.302], [65712.3, 0.027], [65974.2, 0.763], [67947.9, 0.078]]}
{"kind": "depth", "E": 1787080133187, "U": 11315331652018, "u": 11315331660138, "recv_ms": 1787080133128, "bids": [[14312.2, 0.84], [14412.2, 3.36], [14512.2, 0.0], [51770.0, 0.0], [58240.9, 0.002], [58243.8, 0.0], [61476.5, 0.0], [62126.7, 0.01], [63418.0, 2.701], [63712.2, 7.683], [63725.1, 0.06], [63914.9, 6.128], [63935.7, 27.229], [64065.1, 9.908], [64571.5, 2.79], [64593.7, 2.6], [64594.9, 0.409], [64640.5, 0.002], [64647.4, 0.175], [64649.1, 0.116], [64660.8, 1.172], [64663.7, 0.035], [64679.7, 0.073], [64681.5, 1.043], [64688.2, 0.007], [64689.7, 0.105], [64695.2, 0.464], [64695.3, 0.002], [64699.1, 0.311], [64699.9, 0.686], [64700.0, 0.572], [64702.4, 0.028], [64703.8, 1.6], [64705.0, 0.074], [64709.6, 0.002], [64712.2, 7.491]], "asks": [[64714.4, 0.008], [64741.2, 0.404], [64750.9, 0.073], [64753.7, 0.012], [64788.2, 0.167], [64791.3, 0.0], [64800.6, 0.1], [64850.5, 0.306], [64852.7, 5.397], [64854.0, 0.0], [64869.7, 10.431], [64908.5, 15.721], [65035.9, 3.996], [65359.4, 5.523], [65488.8, 46.254], [65712.3, 0.007]]}
{"kind": "depth", "E": 1787080133289, "U": 11315331660343, "u": 11315331666207, "recv_ms": 1787080133229, "bids": [[14312.2, 1.19], [14412.2, 3.01], [58240.9, 0.002], [61476.5, 0.001], [61630.7, 0.104], [62123.7, 0.692], [63787.3, 3.287], [63809.6, 3.132], [63939.1, 3.124], [63949.1, 7.808], [64065.1, 9.906], [64388.6, 4.446], [64670.7, 0.179], [64695.2, 0.001], [64699.7, 0.257], [64699.8, 0.002], [64699.9, 0.532], [64700.0, 0.572], [64702.4, 0.491], [64703.9, 0.565], [64704.1, 0.228], [64705.0, 0.158], [64705.5, 0.008], [64706.7, 0.552], [64707.7, 0.386], [64708.2, 0.216], [64708.6, 0.025], [64709.2, 0.024], [64709.3, 0.006], [64711.1, 0.0], [64712.2, 5.608]], "asks": [[64712.3, 27.604], [64714.4, 0.018], [64720.0, 0.12], [64720.1, 2.319], [64740.4, 3.601], [64741.0, 0.109], [64741.1, 0.605], [64741.2, 0.25], [64869.7, 10.431], [64908.5, 15.721], [65359.4, 5.521], [65699.2, 0.047]]}
{"kind": "depth", "E": 1787080133391, "U": 11315331666399, "u": 11315331676858, "recv_ms": 1787080133332, "bids": [[1000.0, 35.81], [14312.2, 1.554], [14412.2, 2.646], [58240.9, 0.002], [61476.5, 0.0], [62123.7, 0.689], [63935.7, 32.695], [64065.1, 9.906], [64107.3, 4.918], [64388.6, 4.445], [64390.3, 0.229], [64657.0, 0.0], [64657.3, 0.122], [64657.7, 0.003], [64658.0, 0.023], [64658.3, 0.0], [64668.5, 0.185], [64670.9, 2.468], [64671.6, 0.039], [64674.3, 0.0], [64674.6, 0.001], [64674.9, 0.016], [64675.2, 0.152], [64675.6, 0.0], [64689.2, 0.029], [64689.3, 0.042], [64689.4, 1.082], [64689.5, 0.053], [64689.6, 1.326], [64689.7, 0.005], [64689.8, 2.327], [64689.9, 0.0], [64690.0, 0.314], [64690.1, 0.004], [64690.7, 0.16], [64691.1, 0.467], [64704.1, 0.287], [64704.2, 1.841], [64704.8, 0.564], [64704.9, 0.066], [64705.0, 0.088], [64705.1, 0.164], [64705.3, 0.086], [64705.4, 0.036], [64705.6, 0.018], [64705.9, 0.001], [64706.1, 0.397], [64706.3, 0.003], [64706.6, 0.002], [64706.7, 0.757], [64707.5, 0.001], [64707.6, 0.086], [64707.7, 0.246], [64707.8, 0.008], [64707.9, 0.001], [64708.0, 1.72], [64708.1, 0.089], [64708.2, 0.016], [64712.2, 5.654]], "asks": [[64712.3, 27.602], [64719.0, 0.044], [64719.7, 0.087], [64719.8, 0.002], [64720.2, 0.018], [64720.3, 0.11], [64720.5, 0.004], [64720.6, 2.041], [64721.2, 0.003], [64721.5, 0.001], [64721.6, 0.003], [64721.7, 0.002], [64721.8, 0.012], [64722.0, 0.518], [64722.1, 0.007], [64722.2, 0.7], [64722.3, 1.042], [64722.4, 1.952], [64722.5, 1.001], [64722.7, 2.761], [64722.8, 0.502], [64736.3, 0.216], [64736.9, 0.344], [64737.4, 0.02], [64737.8, 0.01], [64738.4, 0.0], [64738.5, 0.361], [64738.6, 0.112], [64738.9, 0.001], [64739.3, 0.008], [64739.8, 0.009], [64740.0, 0.487], [64740.1, 0.059], [64740.3, 0.025], [64740.4, 3.501], [64740.5, 0.178], [64740.6, 2.387], [64740.7, 0.002], [64740.8, 1.279], [64741.0, 0.025], [64741.1, 0.311], [64741.2, 0.404], [64754.7, 0.249], [64755.0, 0.018], [64755.1, 0.023], [64755.7, 0.002], [65359.4, 5.523]]}
{"kind": "depth", "E": 1787080133493, "U": 11315331676868, "u": 11315331685043, "recv_ms": 1787080133441, "bids": [[14312.2, 1.904], [14412.2, 2.296], [58240.9, 0.002], [61476.5, 0.0], [62123.7, 0.692], [63418.0, 2.704], [63712.2, 7.703], [63935.7, 32.071], [64065.1, 9.906], [64388.6, 4.29], [64571.5, 0.001], [64634.5, 0.003], [64666.9, 0.537], [64671.9, 0.853], [64672.2, 1.024], [64679.8, 0.002], [64689.7, 0.001], [64695.2, 0.001], [64696.2, 0.005], [64699.7, 0.103], [64699.8, 0.156], [64702.4, 0.028], [64702.5, 0.464], [64704.0, 0.181], [64704.3, 0.316], [64704.4, 0.282], [64704.5, 0.1], [64704.6, 0.201], [64704.9, 0.715], [64705.0, 0.158], [64705.1, 0.234], [64705.7, 0.157], [64706.4, 0.039], [64706.7, 0.789], [64712.2, 5.654]], "asks": [[64712.3, 27.602], [64718.4, 0.036], [64718.7, 0.413], [64719.8, 0.003], [64720.0, 0.211], [64720.1, 2.396], [64720.2, 0.118], [64720.5, 0.214], [64720.6, 2.141], [64720.8, 0.156], [64728.7, 0.418], [64735.6, 0.033], [64735.9, 0.032], [64737.8, 0.12], [64738.3, 0.213], [64738.4, 0.077], [64738.5, 0.461], [64738.8, 0.102], [64738.9, 0.101], [64739.1, 0.521], [64741.2, 0.25], [64741.3, 1.479], [64757.6, 0.003], [64822.4, 0.014], [64852.7, 0.0], [65035.9, 3.997], [65359.4, 5.521], [65712.3, 0.027]]}
{"kind": "depth", "E": 1787080133595, "U": 11315331685141, "u": 11315331694096, "recv_ms": 1787080133542, "bids": [[14312.2, 2.268], [14412.2, 1.932], [51770.0, 0.0], [58240.9, 0.002], [61476.5, 0.0], [63712.2, 7.683], [63773.9, 41.802], [63939.1, 2.343], [64065.1, 9.906], [64388.6, 4.28], [64554.5, 7.484], [64571.5, 3.09], [64571.6, 1.192], [64651.7, 0.04], [64651.9, 0.31], [64671.3, 0.035], [64690.9, 0.012], [64691.0, 0.987], [64695.2, 0.464], [64700.0, 0.574], [64702.4, 0.028], [64702.5, 0.001], [64702.8, 0.0], [64702.9, 0.128], [64704.0, 0.173], [64704.1, 0.22], [64704.2, 1.911], [64704.4, 0.205], [64704.5, 0.17], [64704.7, 0.101], [64705.2, 0.106], [64705.8, 0.137], [64712.2, 5.549]], "asks": [[64712.3, 27.603], [64719.3, 0.348], [64719.8, 0.002], [64720.4, 0.102], [64720.6, 2.211], [64720.9, 0.196], [64736.6, 0.061], [64738.7, 0.103], [64738.9, 0.171], [64739.2, 3.486], [64852.7, 5.397], [64868.5, 2.203], [64869.7, 10.431], [65265.7, 0.076], [65275.1, 0.0], [65359.4, 5.521], [65435.2, 1.997], [65521.2, 11.158], [65585.9, 3.146], [65618.3, 25.411], [65630.1, 27.799], [65712.3, 0.007]]}
{"kind": "depth", "E": 1787080133697, "U": 11315331694150, "u": 11315331703451, "recv_ms": 1787080133638, "bids": [[1000.0, 35.81], [14312.2, 2.618], [14412.2, 1.582], [51770.0, 0.0], [58240.9, 0.002], [61476.5, 0.0], [62123.7, 0.689], [64065.1, 9.906], [64097.4, 12.985], [64390.3, 0.288], [64582.7, 0.003], [64653.7, 0.059], [64654.3, 0.032], [64660.3, 0.015], [64673.6, 1.148], [64679.1, 0.627], [64680.2, 0.014], [64686.2, 0.158], [64689.7, 0.557], [64690.8, 0.002], [64691.6, 0.116], [64692.3, 0.046], [64692.4, 0.029], [64693.2, 0.003], [64694.9, 1.084], [64695.2, 0.926], [64695.3, 0.473], [64696.0, 0.384], [64696.3, 0.241], [64698.1, 1.003], [64699.4, 0.249], [64699.5, 0.388], [64699.7, 0.103], [64699.8, 0.002], [64702.2, 0.624], [64702.4, 0.02], [64703.9, 0.024], [64704.0, 0.707], [64704.1, 0.157], [64704.3, 0.386], [64704.4, 0.275], [64704.5, 0.186], [64704.6, 0.285], [64704.7, 0.178], [64704.8, 0.634], [64704.9, 0.707], [64705.1, 0.11], [64705.2, 1.851], [64705.3, 1.138], [64705.4, 0.043], [64706.6, 1.655], [64706.7, 0.241], [64707.0, 0.015], [64707.2, 0.099], [64707.7, 0.239], [64708.1, 0.013], [64709.3, 0.004], [64709.5, 0.011], [64710.6, 0.055], [64710.9, 0.023], [64711.0, 0.0], [64712.2, 2.264]], "asks": [[64712.3, 27.606], [64712.7, 0.311], [64713.8, 0.005], [64714.2, 0.007], [64714.4, 0.018], [64716.0, 0.093], [64719.6, 0.008], [64719.8, 0.001], [64720.3, 0.18], [64720.7, 0.079], [64720.9, 0.266], [64726.8, 1.663], [64727.6, 0.927], [64728.5, 0.001], [64729.3, 0.628], [64729.7, 3.102], [64730.2, 0.559], [64731.6, 0.014], [64732.5, 5.076], [64733.2, 0.543], [64734.1, 0.621], [64734.5, 0.115], [64734.8, 0.01], [64736.0, 1.603], [64738.6, 0.182], [64739.0, 0.933], [64739.2, 3.556], [64753.5, 0.056], [64754.2, 0.345], [64774.5, 0.002], [64777.1, 0.005], [64852.7, 4.224], [64868.5, 0.753], [64869.7, 10.431], [64908.5, 15.721], [64980.8, 2.099], [65359.4, 5.521], [66333.3, 3.746], [67947.9, 0.073]]}
{"kind": "depth", "E": 1787080133799, "U": 11315331703456, "u": 11315331708421, "recv_ms": 1787080133741, "bids": [[14312.2, 2.982], [14412.2, 1.218], [51770.0, 0.0], [58240.9, 0.002], [61476.5, 0.0], [61476.6, 0.01], [61476.7, 0.004], [62123.7, 0.692], [63418.0, 2.701], [63903.3, 10.434], [63935.7, 32.695], [64065.1, 9.906], [64388.6, 4.434], [64654.7, 0.058], [64655.0, 0.159], [64686.5, 0.134], [64688.1, 0.26], [64690.0, 0.305], [64693.1, 0.03], [64699.3, 0.158], [64699.5, 0.234], [64704.7, 0.101], [64704.9, 0.166], [64705.0, 0.258], [64705.1, 0.187], [64705.4, 0.036], [64706.7, 0.789], [64712.2, 2.311]], "asks": [[64720.1, 2.526], [64733.2, 0.002], [64734.0, 0.84], [64737.3, 1.834], [64752.9, 0.032], [64753.2, 1.537], [65035.9, 3.998], [65359.4, 5.521], [66200.7, 1.056], [66329.5, 0.001]]}
{"kind": "depth", "E": 1787080133901, "U": 11315331708618, "u": 11315331715322, "recv_ms": 1787080133843, "bids": [[14312.2, 3.332], [14412.2, 0.868], [58240.9, 0.002], [62123.7, 0.689], [63712.2, 7.703], [64065.1, 9.906], [64388.6, 4.434], [64654.0, 0.034], [64686.0, 0.144], [64686.2, 0.258], [64686.3, 0.134], [64686.6, 0.193], [64686.7, 0.167], [64686.8, 0.093], [64687.4, 1.874], [64712.2, 2.282]], "asks": [[64727.6, 0.002], [64728.3, 1.177], [64730.2, 0.003], [64730.8, 0.598], [64734.3, 0.014], [64734.5, 0.0], [64735.2, 0.118], [64753.8, 0.066], [65337.2, 2.292], [65359.4, 5.521], [65500.0, 330.091], [65712.3, 0.027], [66330.1, 0.081]]}
{"kind": "depth", "E": 1787080134003, "U": 11315331715470, "u": 11315331723889, "recv_ms": 1787080133943, "bids": [[1000.0, 35.81], [14312.2, 3.696], [14412.2, 0.504], [51769.8, 0.002], [58240.9, 0.002], [61476.5, 0.0], [62123.7, 0.692], [64065.1, 9.906], [64390.3, 0.229], [64685.9, 0.14], [64686.2, 0.328], [64686.4, 1.479], [64696.0, 0.384], [64701.5, 0.245], [64702.9, 0.004], [64704.1, 0.217], [64704.2, 0.073], [64704.5, 0.178], [64704.9, 0.251], [64705.1, 0.11], [64705.3, 1.138], [64705.4, 0.584], [64705.7, 0.216], [64706.7, 0.241], [64707.3, 0.542], [64707.7, 0.008], [64708.0, 1.804], [64712.2, 2.237]], "asks": [[64714.4, 0.008], [64741.1, 0.309], [64741.4, 0.564], [64816.3, 0.913], [65359.4, 5.521], [66330.1, 0.608]]}
{"kind": "depth", "E": 1787080134105, "U": 11315331724047, "u": 11315331734456, "recv_ms": 1787080134047, "bids": [[14212.2, 0.154], [14312.2, 3.738], [14412.2, 0.308], [51769.8, 0.0], [58240.9, 0.002], [61476.5, 0.0], [63712.2, 7.683], [64065.1, 9.906], [64685.9, 0.21], [64686.1, 0.084], [64686.5, 0.204], [64700.6, 0.245], [64705.7, 0.216], [64708.9, 0.023], [64709.1, 0.028], [64712.2, 2.284]], "asks": [[64713.5, 1.516], [64714.4, 0.008], [65359.4, 5.521], [65712.3, 0.007], [66006.5, 0.012]]}
{"kind": "depth", "E": 1787080134207, "U": 11315331734603, "u": 11315331747237, "recv_ms": 1787080134152, "bids": [[1000.0, 35.81], [14212.2, 0.392], [14312.2, 3.626], [14412.2, 0.182], [58240.9, 0.002], [61476.5, 0.0], [62123.7, 0.689], [63806.2, 26.557], [64065.1, 9.906], [64388.6, 4.434], [64617.3, 0.006], [64619.4, 0.0], [64636.5, 0.0], [64639.8, 2.364], [64640.7, 0.211], [64642.9, 7.758], [64644.0, 0.001], [64649.4, 2.078], [64660.9, 1.077], [64663.8, 0.004], [64687.8, 0.1], [64695.3, 0.465], [64696.0, 0.372], [64699.3, 0.004], [64701.2, 0.027], [64701.8, 0.002], [64702.2, 0.006], [64703.8, 1.599], [64703.9, 0.108], [64704.2, 0.157], [64704.5, 0.17], [64704.9, 0.243], [64705.4, 0.036], [64705.5, 0.008], [64705.7, 0.216], [64706.7, 0.789], [64707.2, 0.099], [64707.3, 0.232], [64707.6, 0.002], [64707.7, 0.008], [64708.0, 1.72], [64708.1, 0.005], [64709.5, 0.003], [64710.5, 0.001], [64712.2, 2.207]], "asks": [[64712.3, 27.712], [64714.4, 0.008], [64718.4, 0.036], [64721.4, 0.028], [64730.9, 0.153], [64731.6, 0.019], [64733.6, 0.464], [64739.7, 0.906], [64750.4, 1.575], [64758.1, 0.004], [64781.8, 0.048], [64786.0, 0.002], [65327.1, 7.449], [65359.4, 5.521]]}
{"kind": "depth", "E": 1787080134309, "U": 11315331747409, "u": 11315331757360, "recv_ms": 1787080134253, "bids": [[1000.0, 35.81], [14212.2, 0.63], [14312.2, 3.5], [14412.2, 0.07], [51770.0, 0.0], [58240.9, 0.002], [61476.5, 0.0], [62123.7, 0.692], [62126.7, 0.009], [63709.2, 12.943], [63712.2, 7.703], [63773.9, 40.706], [63880.2, 3.563], [63999.5, 0.875], [64065.1, 9.906], [64571.5, 3.053], [64617.0, 0.032], [64623.5, 0.029], [64630.0, 3.089], [64679.8, 0.005], [64681.8, 0.003], [64689.7, 0.001], [64691.4, 0.656], [64691.6, 0.0], [64693.0, 0.118], [64695.4, 0.029], [64696.0, 0.384], [64699.2, 0.166], [64701.5, 0.061], [64702.2, 0.003], [64702.9, 0.007], [64703.9, 0.106], [64704.1, 0.157], [64704.9, 0.245], [64705.1, 0.126], [64705.7, 0.157], [64707.2, 0.409], [64707.8, 0.092], [64708.1, 0.013], [64709.5, 0.011], [64712.2, 3.859]], "asks": [[64712.3, 27.7], [64712.7, 0.001], [64713.3, 0.31], [64714.4, 0.001], [64716.1, 0.011], [64726.8, 1.045], [64727.2, 3.02], [64728.3, 0.252], [64728.8, 10.606], [64729.2, 1.041], [64730.8, 0.042], [64731.6, 0.575], [64732.8, 2.271], [64734.0, 0.299], [64734.1, 0.003], [64734.8, 0.01], [64735.2, 0.003], [64735.8, 0.196], [64735.9, 0.573], [64738.1, 0.042], [64744.1, 0.001], [64744.4, 0.126], [64744.9, 0.022], [64745.2, 0.006], [64764.0, 0.061], [64822.4, 0.017], [64852.7, 5.397], [64877.2, 0.212], [65230.0, 8.489], [65359.4, 5.521], [65488.8, 45.644], [65712.3, 0.027], [66006.5, 0.012]]}
{"kind": "depth", "E": 1787080134411, "U": 11315331757583, "u": 11315331763670, "recv_ms": 1787080134351, "bids": [[14212.2, 0.91], [14312.2, 3.29], [14412.2, 0.0], [58240.9, 0.002], [61476.5, 0.0], [62123.7, 0.689], [64065.1, 9.906], [64657.5, 6.295], [64667.5, 1.252], [64690.8, 0.558], [64691.4, 0.1], [64695.2, 0.001], [64695.4, 0.029], [64697.1, 1.885], [64699.2, 0.012], [64705.0, 0.266], [64705.1, 0.118], [64705.4, 0.584], [64705.7, 0.157], [64706.7, 0.241], [64707.8, 0.008], [64712.2, 3.982]], "asks": [[64712.3, 27.713], [64713.8, 0.002], [64714.4, 0.001], [64734.3, 0.014], [64735.8, 0.622], [64735.9, 0.032], [64736.5, 0.115], [65035.9, 3.997], [65359.4, 5.521]]}
{"kind": "depth", "E": 1787080134513, "U": 11315331763680, "u": 11315331769647, "recv_ms": 1787080134453, "bids": [[1000.0, 35.81], [14212.2, 1.288], [14312.2, 2.912], [58240.9, 0.002], [61476.5, 0.001], [62123.7, 0.692], [63288.5, 0.003], [63418.0, 2.698], [63712.2, 7.683], [64065.1, 9.906], [64194.5, 8.258], [64388.6, 4.445], [64594.9, 4.272], [64595.0, 0.249], [64641.0, 0.323], [64657.8, 0.016], [64658.9, 1.651], [64689.9, 0.556], [64690.8, 0.002], [64691.6, 0.116], [64693.0, 0.002], [64695.3, 1.39], [64695.4, 0.037], [64696.2, 0.005], [64697.1, 0.96], [64699.0, 0.167], [64705.0, 0.258], [64705.5, 0.202], [64707.6, 0.086], [64712.2, 3.907]], "asks": [[64714.4, 0.011], [64728.7, 0.418], [64734.1, 0.003], [64734.6, 0.382], [64734.8, 0.551], [64735.7, 0.306], [64735.8, 0.081], [64736.5, 0.0], [64783.5, 0.048], [64847.8, 4.811], [65359.4, 5.521], [65533.1, 1.141], [65565.4, 2.137], [65712.3, 0.007]]}
{"kind": "depth", "E": 1787080134615, "U": 11315331769705, "u": 11315331775060, "recv_ms": 1787080134557, "bids": [[1000.0, 35.81], [14212.2, 1.638], [14312.2, 2.562], [51770.0, 0.0], [58240.9, 0.002], [61476.5, 0.0], [63709.2, 14.04], [63712.2, 7.703], [63773.9, 41.802], [63870.9, 13.761], [63939.1, 1.562], [64065.1, 9.906], [64084.5, 1.79], [64705.5, 0.008], [64705.7, 0.216]], "asks": [[64712.3, 27.712], [65230.0, 8.795], [65359.4, 5.521], [65488.8, 46.254], [65712.3, 0.027]]}
{"kind": "depth", "E": 1787080134717, "U": 11315331775200, "u": 11315331787844, "recv_ms": 1787080134662, "bids": [[14212.2, 1.988], [14312.2, 2.212], [58240.9, 0.002], [61476.5, 0.0], [62123.7, 0.689], [64065.1, 9.906], [64582.7, 0.003], [64634.5, 0.0], [64666.9, 0.54], [64679.5, 2.852], [64679.8, 0.002], [64682.7, 0.001], [64688.7, 1.12], [64692.0, 0.392], [64694.9, 0.466], [64704.7, 0.186], [64704.9, 0.168], [64705.1, 0.11], [64705.5, 0.008], [64705.7, 0.216], [64705.8, 0.137], [64706.8, 0.014], [64708.1, 0.005], [64712.2, 3.207]], "asks": [[64713.9, 0.09], [64714.4, 0.019], [64719.6, 0.0], [64757.6, 0.003], [64822.4, 0.014], [65359.4, 5.521], [65553.6, 46.498], [71183.5, 0.01]]}
{"kind": "depth", "E": 1787080134921, "U": 11315331796697, "u": 11315331803696, "recv_ms": 1787080134862, "bids": [[1000.0, 35.81], [14212.2, 2.702], [14312.2, 1.498], [58240.9, 0.002], [61476.5, 0.0], [62123.7, 0.689], [63712.2, 7.683], [63819.6, 7.042], [63935.7, 32.07], [64003.8, 5.46], [64009.6, 0.0], [64065.1, 9.906], [64194.5, 8.257], [64388.6, 4.291], [64554.5, 3.627], [64571.5, 0.001], [64571.6, 0.838], [64619.9, 0.004], [64620.0, 1.784], [64642.7, 33.113], [64665.3, 0.125], [64681.5, 0.049], [64695.4, 0.029], [64699.6, 0.156], [64699.7, 0.103], [64704.9, 0.176], [64705.7, 0.157], [64705.8, 0.137], [64707.6, 0.002], [64712.2, 3.622]], "asks": [[64712.3, 27.713], [64712.4, 0.048], [64713.2, 0.002], [64732.6, 0.127], [64737.9, 0.001], [64753.2, 1.018], [64754.1, 0.002], [64776.8, 0.0], [64852.7, 0.0], [64869.7, 0.026], [65359.4, 5.523], [65427.8, 2.744], [65712.3, 0.007]]}
{"kind": "depth", "E": 1787080135023, "U": 11315331803764, "u": 11315331809731, "recv_ms": 1787080134965, "bids": [[14212.2, 3.066], [14312.2, 1.134], [51769.8, 0.0], [58240.9, 0.002], [61476.5, 0.0], [61476.6, 0.012], [62123.7, 0.692], [63418.0, 2.695], [63793.7, 3.894], [63924.6, 0.781], [63935.7, 33.631], [63996.6, 1.791], [64065.1, 9.906], [64388.6, 4.136], [64554.6, 2.844], [64571.5, 2.561], [64610.1, 0.001], [64695.4, 0.037], [64701.8, 0.001], [64704.9, 0.168], [64710.7, 0.175], [64712.2, 3.619]], "asks": [[64712.3, 27.794], [64712.6, 0.086], [64713.3, 0.354], [64713.8, 0.005], [64714.4, 0.011], [64719.4, 0.012], [64809.2, 0.0], [64852.7, 5.397], [64868.5, 2.203], [64869.7, 10.431], [64911.1, 0.02], [64911.2, 0.101], [65065.4, 0.003], [65230.0, 8.489], [65359.4, 5.521], [66006.5, 0.015]]}
{"kind": "depth", "E": 1787080135125, "U": 11315331809882, "u": 11315331815780, "recv_ms": 1787080135069, "bids": [[1000.0, 35.81], [14212.2, 3.416], [14312.2, 0.784], [58240.9, 0.002], [61476.5, 0.0], [61476.6, 0.01], [61476.7, 0.006], [63029.6, 0.001], [63712.2, 7.703], [63725.1, 0.052], [63789.9, 0.013], [63791.6, 0.01], [63806.2, 28.905], [63935.7, 34.256], [64065.1, 9.906], [64194.5, 8.568], [64388.6, 4.35], [64611.0, 2.554], [64641.7, 6.629], [64664.4, 3.502], [64679.8, 0.005], [64680.5, 0.97], [64700.3, 0.324], [64700.6, 0.245], [64712.2, 3.742]], "asks": [[64712.3, 27.812], [64713.8, 0.002], [64716.9, 0.075], [64737.9, 0.952], [64753.2, 1.527], [64754.1, 3.502], [64776.8, 6.0], [64806.9, 2.09], [64822.4, 0.017], [64874.1, 0.004], [65035.9, 3.996], [65327.5, 0.012], [65359.4, 5.521], [65417.7, 6.327], [65632.1, 2.285], [65632.8, 0.0], [65634.5, 0.002], [65673.7, 4.563], [65699.2, 0.039], [65712.3, 0.027]]}
{"kind": "depth", "E": 1787080135227, "U": 11315331815845, "u": 11315331821736, "recv_ms": 1787080135167, "bids": [[1000.0, 35.81], [14212.2, 3.724], [14312.2, 0.448], [14612.2, 0.028], [51770.0, 0.002], [58240.9, 0.002], [61476.5, 0.0], [62123.7, 0.689], [63725.1, 0.06], [63789.9, 0.021], [63791.6, 0.018], [64013.8, 3.119], [64065.1, 9.906], [64712.2, 3.741]], "asks": [[64712.4, 0.064], [64713.7, 0.048], [64716.9, 0.074], [64775.8, 0.027], [65359.4, 5.521], [65632.8, 0.008], [65699.2, 0.047]]}
{"kind": "depth", "E": 1787080135329, "U": 11315331821866, "u": 11315331829399, "recv_ms": 1787080135270, "bids": [[14212.2, 3.696], [14312.2, 0.28], [14612.2, 0.224], [51770.0, 0.0], [58240.9, 0.002], [61476.5, 0.0], [62123.7, 0.692], [63712.2, 7.683], [63923.9, 1.564], [64065.1, 9.906], [64388.6, 4.505], [64609.4, 12.501], [64611.0, 3.411], [64670.7, 0.165], [64703.9, 0.022], [64707.2, 2.299], [64707.7, 0.092], [64708.1, 0.097], [64712.2, 3.695]], "asks": [[64713.1, 0.311], [64713.3, 0.044], [64809.2, 10.0], [65230.0, 8.795], [65359.4, 5.521], [65618.3, 25.594], [65634.5, 0.01], [65663.6, 6.764], [65712.3, 0.007], [65715.3, 6.443]]}
{"kind": "depth", "E": 1787080135431, "U": 11315331829444, "u": 11315331834713, "recv_ms": 1787080135373, "bids": [[1000.0, 35.81], [14212.2, 3.598], [14312.2, 0.154], [14612.2, 0.448], [51770.0, 0.0], [58240.9, 0.002], [62123.7, 0.689], [63615.5, 2.358], [64065.1, 9.906], [64388.6, 4.505], [64571.5, 3.07], [64571.6, 1.189], [64644.8, 1.173], [64699.0, 0.167], [64699.6, 0.002]], "asks": [[64852.7, 5.397], [65359.4, 5.521], [65650.6, 27.665], [71183.6, 0.0]]}
{"kind": "depth", "E": 1787080135533, "U": 11315331834817, "u": 11315331840368, "recv_ms": 1787080135474, "bids": [[1000.0, 35.81], [14212.2, 3.472], [14312.2, 0.042], [14612.2, 0.686], [58240.9, 0.002], [61476.5, 0.0], [63418.0, 2.692], [63712.2, 7.703], [63850.1, 13.023], [64065.0, 2.361], [64065.1, 9.906], [64388.6, 4.504], [64603.4, 2.411], [64603.7, 0.082], [64690.0, 0.303], [64696.2, 0.005], [64699.0, 0.167], [64702.6, 0.233], [64703.9, 0.182], [64708.1, 0.013], [64712.2, 3.771]], "asks": [[64712.3, 27.812], [64728.7, 0.418], [64819.1, 0.0], [64819.2, 2.326], [65359.4, 5.521], [65712.3, 0.027]]}
{"kind": "depth", "E": 1787080135635, "U": 11315331840409, "u": 11315331845258, "recv_ms": 1787080135582, "bids": [[14212.2, 3.192], [14312.2, 0.0], [14612.2, 1.008], [58240.9, 0.002], [62123.7, 0.692], [63418.0, 2.695], [64065.1, 9.906], [64194.5, 8.257], [64388.6, 4.504], [64571.5, 3.07], [64571.6, 0.838], [64676.6, 0.352], [64677.6, 0.001], [64695.4, 0.029], [64704.9, 0.176], [64705.2, 0.013], [64705.3, 0.609], [64705.4, 0.584], [64706.7, 0.241], [64712.2, 3.57]], "asks": [[64713.3, 0.044], [64714.4, 0.001], [64852.7, 5.397], [65035.9, 3.997], [65359.4, 5.521], [65650.6, 28.73], [65715.3, 7.507]]}
{"kind": "depth", "E": 1787080135839, "U": 11315331853565, "u": 11315331859139, "recv_ms": 1787080135782, "bids": [[1000.0, 35.81], [14212.2, 2.478], [14612.2, 1.722], [51770.0, 0.0], [58240.9, 0.002], [61476.5, 0.0], [61476.6, 0.008], [61476.7, 0.008], [62123.7, 0.692], [63838.6, 7.093], [64065.1, 9.906], [64194.5, 8.568], [64388.6, 4.503], [64689.9, 0.0], [64691.5, 0.56], [64691.6, 0.0], [64693.4, 0.177], [64694.9, 1.084], [64695.3, 0.465], [64695.8, 0.002], [64697.0, 1.842], [64702.3, 1.662], [64704.2, 0.073], [64704.9, 0.243], [64705.1, 0.118], [64705.4, 0.577], [64706.0, 0.012], [64706.5, 0.025], [64706.7, 0.124], [64706.8, 0.006], [64706.9, 0.002], [64707.3, 0.356], [64708.6, 0.109], [64712.2, 5.821]], "asks": [[64714.4, 0.001], [64726.8, 1.045], [64734.2, 1.968], [64734.8, 0.01], [64735.9, 0.573], [64750.4, 1.365], [64761.5, 0.286], [64868.5, 0.753], [64869.7, 10.431], [64908.5, 15.721], [65359.4, 5.521], [65650.6, 28.73]]}
{"kind": "depth", "E": 1787080135941, "U": 11315331859227, "u": 11315331864145, "recv_ms": 1787080135884, "bids": [[14212.2, 2.128], [14612.2, 2.072], [58240.9, 0.002], [62123.7, 0.689], [64065.1, 9.908], [64388.6, 4.493], [64668.1, 0.0], [64695.4, 0.021], [64696.0, 1.284], [64701.4, 0.619], [64702.4, 0.028], [64704.0, 0.754], [64704.6, 0.201], [64709.0, 0.087]], "asks": [[64714.4, 0.011], [64735.7, 0.191], [64736.5, 0.115], [65035.9, 3.998], [65359.4, 5.521], [65417.7, 7.013], [65482.4, 8.247], [65712.6, 1.526], [71183.6, 0.0]]}
{"kind": "depth", "E": 1787080136043, "U": 11315331864223, "u": 11315331869823, "recv_ms": 1787080135985, "bids": [[1000.0, 35.81], [14212.2, 1.764], [14612.2, 2.436], [51769.8, 0.0], [58240.9, 0.002], [63418.0, 2.692], [63712.2, 7.703], [63935.7, 33.787], [64065.1, 9.906], [64647.5, 0.003], [64666.9, 0.537], [64679.1, 0.57], [64679.8, 0.005], [64680.4, 0.149], [64681.4, 0.448], [64695.2, 0.009], [64699.0, 0.013], [64699.3, 0.158], [64700.6, 0.25], [64702.4, 0.02], [64705.5, 0.396]], "asks": [[64729.2, 0.116], [64730.0, 1.425], [64731.6, 0.019], [64732.4, 0.558], [64757.6, 0.003], [64777.0, 0.075], [64822.4, 0.014], [64869.7, 8.759], [64908.5, 15.721], [65359.4, 5.521], [65712.3, 0.027]]}
{"kind": "depth", "E": 1787080136145, "U": 11315331870054, "u": 11315331875261, "recv_ms": 1787080136088, "bids": [[1000.0, 35.81], [14212.2, 1.4], [14612.2, 2.8], [51770.0, 0.0], [58240.9, 0.002], [61476.5, 0.0], [62123.7, 0.692], [63852.0, 0.122], [64065.1, 9.906], [64619.8, 0.007], [64619.9, 0.001], [64695.2, 0.009], [64700.3, 0.323], [64700.6, 0.245], [64702.3, 1.044], [64702.4, 0.02], [64704.9, 0.244], [64705.4, 0.577], [64705.5, 0.015], [64705.7, 0.003], [64706.7, 0.117], [64706.8, 0.006], [64707.3, 0.51], [64712.2, 5.967]], "asks": [[64714.4, 0.011], [64721.5, 0.002], [64727.2, 1.852], [64728.8, 0.608], [64734.2, 1.35], [64734.3, 0.01], [65035.9, 3.844], [65359.4, 5.521], [65488.8, 45.796]]}
{"kind": "depth", "E": 1787080136247, "U": 11315331875297, "u": 11315331879617, "recv_ms": 1787080136188, "bids": [[14212.2, 1.05], [14612.2, 3.15], [51770.0, 0.0], [58240.9, 0.002], [62123.7, 0.689], [63712.2, 7.683], [63949.1, 6.247], [64065.1, 9.906], [64388.6, 4.493], [64646.9, 2.441], [64655.3, 2.151], [64663.6, 2.133], [64679.4, 0.066], [64680.4, 0.092], [64690.1, 0.56], [64691.5, 0.004], [64692.0, 0.508], [64693.4, 0.061], [64695.5, 0.926], [64695.6, 0.01], [64697.0, 0.917], [64701.4, 0.463], [64704.0, 0.707], [64704.9, 0.243], [64705.0, 0.174], [64705.1, 0.11], [64705.5, 0.015], [64709.5, 0.095], [64712.2, 5.891]], "asks": [[64712.3, 27.814], [64714.4, 0.001], [64728.0, 0.124], [64728.9, 1.089], [64730.0, 0.5], [64730.4, 0.599], [64731.5, 0.558], [64732.4, 0.002], [64733.3, 2.653], [64734.1, 0.003], [64734.8, 0.551], [64735.6, 10.033], [64735.9, 0.032], [64797.1, 2.156], [64797.2, 0.014], [64805.4, 2.147], [64805.5, 0.094], [64813.8, 2.126], [64813.9, 0.0], [64848.9, 0.039], [64849.0, 0.071], [65337.2, 1.529], [65359.4, 5.521], [65482.4, 9.162], [65502.6, 1.525], [65521.2, 11.386], [65712.3, 0.007]]}
{"kind": "depth", "E": 1787080136349, "U": 11315331879722, "u": 11315331883905, "recv_ms": 1787080136290, "bids": [[1000.0, 35.81], [14212.2, 0.7], [14612.2, 3.5], [51770.0, 0.0], [58240.9, 0.002], [61476.5, 0.0], [62123.7, 0.692], [63925.3, 0.781], [63935.7, 35.818], [64065.1, 9.906], [64695.6, 0.002], [64705.0, 0.182], [64705.5, 0.209], [64706.2, 0.279], [64709.1, 0.051]], "asks": [[64714.4, 0.001], [65327.1, 8.212], [65359.4, 5.521], [66006.5, 0.018]]}
{"kind": "depth", "E": 1787080136451, "U": 11315331884158, "u": 11315331888815, "recv_ms": 1787080136395, "bids": [[1000.0, 35.81], [14212.2, 0.392], [14512.2, 0.056], [14612.2, 3.752], [58240.9, 0.002], [61476.5, 0.0], [62123.7, 0.689], [63712.2, 7.703], [64065.0, 2.36], [64065.1, 9.906], [64194.5, 8.568], [64694.1, 0.49], [64694.9, 0.466], [64695.2, 0.001], [64695.3, 0.002], [64696.1, 0.023], [64705.0, 0.182], [64705.4, 0.424], [64705.5, 0.008], [64705.6, 0.018], [64706.2, 0.085], [64706.6, 0.002], [64706.7, 0.117], [64706.8, 0.554], [64712.2, 6.157]], "asks": [[64712.3, 27.828], [64714.4, 0.011], [65035.9, 3.998], [65359.4, 5.521], [65488.8, 46.254], [65712.3, 0.027]]}
{"kind": "depth", "E": 1787080136553, "U": 11315331888961, "u": 11315331893065, "recv_ms": 1787080136493, "bids": [[14212.2, 0.252], [14512.2, 0.266], [14612.2, 3.682], [58240.9, 0.002], [61476.5, 0.0], [63989.3, 0.781], [64065.1, 9.906], [64388.6, 4.503], [64668.5, 0.339], [64673.3, 0.083], [64694.1, 0.482], [64695.2, 0.001], [64696.2, 0.005], [64699.3, 0.004], [64704.1, 0.165], [64704.9, 0.707], [64705.0, 0.259], [64705.3, 0.527], [64705.4, 0.424], [64705.5, 0.015], [64705.6, 0.018], [64706.0, 0.01], [64706.8, 0.006], [64707.3, 0.356], [64709.9, 0.1], [64710.5, 0.002], [64712.2, 6.221]], "asks": [[64712.3, 27.827], [64714.4, 0.001], [64728.7, 0.418], [64777.1, 0.023], [64980.8, 5.084], [65359.4, 5.521], [65643.1, 0.003]]}
{"kind": "depth", "E": 1787080136655, "U": 11315331893178, "u": 11315331901422, "recv_ms": 1787080136597, "bids": [[1000.0, 35.81], [14212.2, 0.126], [14512.2, 0.504], [14612.2, 3.57], [58240.9, 0.002], [61476.5, 0.0], [62123.7, 0.692], [63029.6, 0.0], [63712.2, 7.683], [64065.1, 9.906], [64388.6, 4.504], [64666.3, 0.555], [64680.6, 0.338], [64681.2, 1.658], [64690.0, 0.307], [64694.1, 0.019], [64695.2, 0.009], [64699.6, 0.156], [64699.8, 0.002], [64704.1, 0.157], [64704.2, 0.536], [64705.0, 0.259], [64705.4, 0.424], [64705.5, 0.015]], "asks": [[64712.3, 27.825], [64719.8, 0.003], [64741.2, 0.25], [64744.2, 0.002], [65035.9, 3.997], [65359.4, 5.521], [65650.6, 27.665], [65712.3, 0.007]]}
{"kind": "depth", "E": 1787080136757, "U": 11315331901654, "u": 11315331911182, "recv_ms": 1787080136698, "bids": [[1000.0, 35.81], [14212.2, 0.014], [14512.2, 0.742], [14612.2, 3.444], [58240.9, 0.002], [61476.5, 0.0], [62123.7, 0.689], [63712.2, 7.703], [63773.9, 40.706], [64065.1, 9.908], [64582.7, 0.003], [64666.9, 0.722], [64673.9, 2.662], [64675.2, 0.112], [64676.6, 0.016], [64695.2, 0.001], [64704.1, 0.157], [64704.2, 0.536], [64705.4, 0.036], [64712.2, 6.292]], "asks": [[64712.6, 0.002], [64741.3, 1.325], [65359.4, 5.523], [65550.8, 1.526], [65650.6, 28.73], [65712.3, 0.027], [66006.5, 0.015]]}
{"kind": "depth", "E": 1787080136859, "U": 11315331911254, "u": 11315331919672, "recv_ms": 1787080136802, "bids": [[14212.2, 0.0], [14512.2, 1.092], [14612.2, 3.108], [58240.9, 0.002], [62123.7, 0.692], [63773.9, 41.802], [63814.5, 10.187], [64065.1, 9.906], [64388.6, 4.504], [64695.2, 0.001], [64695.4, 0.021], [64702.8, 0.0], [64702.9, 0.131], [64704.1, 0.011], [64704.9, 0.709], [64705.3, 0.525], [64705.4, 0.23], [64705.7, 0.157], [64707.3, 0.411], [64709.9, 0.016], [64710.6, 0.0], [64712.2, 5.852]], "asks": [[64712.4, 0.148], [64727.3, 0.531], [64734.7, 0.842], [64740.9, 0.155], [64741.2, 0.25], [65035.9, 3.996], [65359.4, 5.521], [65486.0, 0.791], [65618.3, 27.877]]}
{"kind": "depth", "E": 1787080136961, "U": 11315331919747, "u": 11315331924618, "recv_ms": 1787080136903, "bids": [[1000.0, 35.81], [14512.2, 1.442], [14612.2, 2.758], [58240.9, 0.002], [61476.5, 0.001], [61476.6, 0.01], [61476.7, 0.006], [63418.0, 2.695], [63712.2, 7.683], [63753.0, 3.097], [63914.9, 5.894], [64065.1, 9.906], [64201.0, 0.084], [64388.6, 4.505], [64704.9, 0.168], [64705.4, 0.577], [64705.5, 0.008], [64707.4, 0.021], [64712.2, 6.05]], "asks": [[64712.3, 27.826], [64719.8, 0.001], [64734.8, 0.01], [64735.5, 0.541], [64740.9, 0.001], [64741.2, 0.404], [65294.7, 9.328], [65359.4, 5.523], [65502.6, 0.0], [65533.1, 0.799], [65712.3, 0.007]]}
{"kind": "depth", "E": 1787080137063, "U": 11315331924632, "u": 11315331929845, "recv_ms": 1787080137002, "bids": [[1000.0, 35.81], [14512.2, 1.806], [14612.2, 2.394], [51769.8, 0.0], [58240.9, 0.002], [61476.5, 0.0], [61476.6, 0.008], [61476.7, 0.008], [62123.7, 0.689], [63418.0, 2.698], [63741.5, 13.393], [63753.0, 2.706], [64000.4, 8.187], [64016.7, 0.701], [64065.1, 9.906], [64571.6, 1.189], [64668.5, 0.185], [64695.2, 0.009], [64700.6, 0.245], [64704.1, 0.003], [64705.4, 0.036], [64707.3, 0.565], [64707.4, 0.562], [64711.7, 0.048], [64712.2, 6.356]], "asks": [[64712.3, 27.824], [64719.8, 0.003], [64734.7, 0.224], [64741.2, 0.404], [64806.9, 3.316], [64868.5, 1.954], [65359.4, 5.521], [66006.5, 0.012]]}
{"kind": "depth", "E": 1787080137165, "U": 11315331929945, "u": 11315331941935, "recv_ms": 1787080137112, "bids": [[14512.2, 2.156], [14612.2, 2.044], [51770.0, 0.0], [58240.9, 0.002], [61476.5, 0.0], [62123.7, 0.692], [63601.0, 2.952], [63806.2, 29.374], [64000.0, 129.35], [64065.1, 9.906], [64388.6, 4.495], [64656.5, 0.001], [64704.2, 0.537], [64704.9, 0.166], [64706.0, 0.012], [64707.3, 0.441], [64707.5, 0.125], [64712.2, 6.4]], "asks": [[64741.1, 0.463], [64741.2, 0.25], [64747.8, 0.003], [65230.0, 8.489], [65359.4, 5.521]]}
{"kind": "depth", "E": 1787080137267, "U": 11315331942017, "u": 11315331948354, "recv_ms": 1787080137209, "bids": [[1000.0, 35.81], [14512.2, 2.52], [14612.2, 1.68], [58240.9, 0.002], [61476.5, 0.0], [62123.7, 0.689], [63356.3, 0.0], [63712.2, 7.703], [63741.5, 13.784], [64065.1, 9.906], [64571.5, 3.07], [64571.6, 0.838], [64679.8, 0.005], [64695.2, 0.001], [64699.5, 0.388], [64699.6, 0.002], [64704.1, 0.474], [64704.2, 0.074], [64704.9, 0.714], [64705.2, 0.015], [64706.0, 0.01], [64707.4, 0.014], [64707.5, 0.125], [64708.9, 0.001], [64712.2, 6.445]], "asks": [[64741.3, 1.325], [64744.3, 0.004], [64744.7, 1.869], [64745.0, 2.959], [64745.1, 1.012], [64747.2, 1.398], [64747.3, 0.063], [64747.4, 0.008], [64852.7, 5.397], [65337.2, 0.766], [65359.4, 5.521], [65712.3, 0.027]]}
{"kind": "depth", "E": 1787080137471, "U": 11315331953514, "u": 11315331964275, "recv_ms": 1787080137422, "bids": [[14512.2, 3.234], [14612.2, 0.966], [58240.9, 0.002], [61476.5, 0.0], [63536.3, 0.795], [63712.2, 7.683], [63914.9, 5.66], [64065.1, 9.908], [64388.6, 4.505], [64554.6, 3.856], [64571.5, 0.001], [64571.6, 3.907], [64680.4, 0.09], [64704.2, 0.073], [64705.4, 0.23], [64707.3, 0.441], [64709.1, 0.028], [64709.5, 0.095], [64709.6, 0.022], [64709.9, 0.039], [64712.2, 6.265]], "asks": [[64712.3, 27.825], [64712.9, 0.844], [64713.2, 0.044], [64713.3, 0.0], [64714.6, 2.504], [64734.5, 0.115], [64736.5, 0.0], [64746.8, 0.03], [64852.7, 5.397], [64868.5, 0.753], [64869.7, 8.759], [64911.0, 0.203], [64911.1, 0.017], [65230.0, 8.795], [65359.4, 5.521], [65650.6, 27.665], [65712.3, 0.007]]}
{"kind": "depth", "E": 1787080137573, "U": 11315331964414, "u": 11315331972454, "recv_ms": 1787080137515, "bids": [[1000.0, 35.81], [14512.2, 3.584], [14612.2, 0.616], [51770.0, 0.004], [58240.9, 0.002], [61476.5, 0.0], [62123.7, 0.689], [63288.5, 0.0], [63353.2, 0.318], [64065.1, 9.906], [64680.4, 0.092], [64696.2, 0.005], [64704.9, 0.707], [64705.4, 0.043], [64707.4, 0.014], [64709.1, 0.009], [64712.2, 6.013]], "asks": [[64712.3, 27.827], [64714.6, 2.505], [64717.1, 0.041], [64719.8, 0.001], [64728.7, 0.418], [64734.5, 0.0], [64735.6, 10.15], [64746.6, 0.02], [65327.1, 8.975], [65359.4, 5.521], [65488.8, 44.424], [65934.3, 2.088], [66006.5, 0.009]]}
{"kind": "depth", "E": 1787080137675, "U": 11315331972504, "u": 11315331980424, "recv_ms": 1787080137623, "bids": [[1000.0, 35.81], [14412.2, 0.084], [14512.2, 3.78], [14612.2, 0.336], [51770.0, 0.0], [58240.9, 0.002], [61476.5, 0.0], [62123.7, 0.692], [63418.0, 2.698], [63712.2, 7.703], [63965.0, 4.496], [64065.1, 9.906], [64388.6, 4.504], [64582.7, 0.004], [64651.7, 0.001], [64651.9, 0.349], [64692.6, 0.126], [64699.6, 0.156], [64712.2, 6.06]], "asks": [[65035.9, 3.997], [65359.4, 5.521], [65650.6, 28.73], [65694.1, 0.76], [65712.3, 0.027]]}
{"kind": "depth", "E": 1787080137879, "U": 11315331987845, "u": 11315331992360, "recv_ms": 1787080137822, "bids": [[1000.0, 35.81], [14412.2, 0.56], [14512.2, 3.542], [14612.2, 0.098], [58240.9, 0.002], [61476.5, 0.0], [63712.2, 7.683], [63838.6, 8.657], [63955.1, 1.641], [64065.1, 9.906], [64690.9, 0.63], [64698.3, 0.002], [64699.4, 1.403], [64699.6, 0.002], [64704.9, 0.166], [64705.4, 0.036], [64705.5, 0.202], [64707.4, 0.562], [64707.5, 0.125], [64709.4, 1.849], [64712.2, 5.923]], "asks": [[64722.8, 0.502], [64730.2, 0.003], [64869.7, 8.626], [64908.5, 15.721], [65359.4, 5.521], [65712.3, 0.007]]}
{"kind": "depth", "E": 1787080137981, "U": 11315331992429, "u": 11315331996482, "recv_ms": 1787080137927, "bids": [[1000.0, 35.81], [14412.2, 0.812], [14512.2, 3.388], [14612.2, 0.0], [51769.8, 0.002], [58240.9, 0.002], [61476.5, 0.0], [61476.6, 0.008], [62123.7, 0.692], [63850.1, 12.632], [63914.9, 5.309], [64065.1, 9.906], [64175.9, 0.003], [64388.6, 4.348], [64701.5, 0.268], [64704.0, 0.767], [64705.4, 0.12], [64705.5, 0.008], [64705.6, 0.018], [64709.0, 0.087], [64709.4, 1.933], [64710.0, 0.03], [64712.2, 5.821]], "asks": [[64717.0, 1.071], [64734.5, 0.154], [65035.9, 3.844], [65230.0, 8.489], [65359.4, 5.521], [65488.8, 47.018]]}
{"kind": "depth", "E": 1787080138083, "U": 11315331996516, "u": 11315332001969, "recv_ms": 1787080138026, "bids": [[14412.2, 1.176], [14512.2, 3.024], [51769.8, 0.0], [58240.9, 0.002], [61476.5, 0.0], [62123.7, 0.689], [63712.2, 7.703], [63725.1, 0.05], [64065.1, 9.906], [64194.5, 7.635], [64388.6, 4.348], [64571.6, 3.069], [64571.7, 1.296], [64696.0, 1.274], [64700.6, 0.245], [64704.1, 0.628], [64705.4, 0.855], [64705.5, 0.015], [64707.3, 0.287], [64707.4, 0.014], [64712.2, 5.682]], "asks": [[64733.3, 1.562], [64735.6, 0.15], [64736.0, 3.243], [64738.0, 10.534], [64777.1, 0.005], [64868.5, 1.934], [65230.0, 7.571], [65359.4, 5.521], [65597.8, 8.058], [65699.2, 0.037], [65712.3, 0.027], [65842.0, 3.017]]}
{"kind": "depth", "E": 1787080138185, "U": 11315332002012, "u": 11315332006997, "recv_ms": 1787080138126, "bids": [[1000.0, 35.81], [14412.2, 1.526], [14512.2, 2.674], [58240.9, 0.002], [61476.5, 0.0], [62123.7, 0.692], [62770.3, 0.002], [63418.0, 2.695], [63725.1, 0.06], [63773.9, 40.706], [64065.1, 9.906], [64175.9, 0.002], [64674.8, 0.238], [64690.9, 0.012], [64696.0, 1.284], [64703.9, 0.183], [64705.4, 0.12], [64705.5, 0.008], [64705.6, 0.018], [64705.7, 0.351], [64707.4, 0.562], [64712.2, 5.897]], "asks": [[64712.3, 27.826], [65359.4, 5.521]]}
{"kind": "depth", "E": 1787080138287, "U": 11315332007027, "u": 11315332011470, "recv_ms": 1787080138230, "bids": [[14412.2, 1.89], [14512.2, 2.31], [51770.0, 0.0], [58240.9, 0.002], [61476.0, 0.172], [62123.1, 0.002], [62123.7, 0.689], [63712.2, 7.683], [64065.1, 9.906], [64388.6, 4.503], [64571.6, 0.0], [64571.7, 0.0], [64699.3, 0.158], [64699.4, 1.249], [64703.9, 0.182], [64705.4, 0.12], [64705.5, 0.015], [64705.7, 0.157], [64707.0, 0.015], [64707.4, 0.014], [64707.5, 0.666], [64709.4, 1.849], [64712.2, 5.962]], "asks": [[64712.3, 27.83], [64740.7, 0.002], [64740.8, 1.433], [64741.2, 0.25], [64852.7, 0.0], [65035.9, 3.998], [65230.0, 7.877], [65359.4, 5.521], [65488.8, 47.779], [65585.9, 3.754], [65631.2, 2.499], [65699.2, 0.047], [65712.3, 0.007], [66006.5, 0.012]]}
{"kind": "depth", "E": 1787080138389, "U": 11315332011575, "u": 11315332016157, "recv_ms": 1787080138341, "bids": [[14412.2, 2.24], [14512.2, 1.96], [51770.0, 0.0], [58240.9, 0.002], [60828.9, 0.0], [61476.5, 0.0], [61476.7, 0.008], [63417.4, 0.003], [63968.0, 8.767], [64065.1, 9.906], [64194.5, 8.568], [64388.6, 4.493], [64554.6, 3.898], [64571.6, 3.096], [64670.7, 0.179], [64699.3, 0.004], [64699.8, 0.156], [64705.4, 0.661], [64705.5, 0.008], [64707.4, 0.021], [64707.5, 0.125], [64709.4, 1.933], [64712.2, 5.79]], "asks": [[64712.7, 0.015], [64740.8, 1.279], [64741.0, 0.025], [64741.1, 0.463], [64852.7, 5.397], [64868.5, 0.753], [64869.7, 10.431], [65230.0, 8.795], [65359.4, 5.521], [65639.7, 0.001]]}
{"kind": "depth", "E": 1787080138491, "U": 11315332016323, "u": 11315332019841, "recv_ms": 1787080138433, "bids": [[1000.0, 35.81], [14412.2, 2.604], [14512.2, 1.596], [58240.9, 0.002], [61476.5, 0.0], [62123.7, 0.692], [63712.2, 7.703], [63773.9, 40.706], [64065.1, 9.906], [64070.5, 0.952], [64175.9, 0.001], [64231.1, 0.0], [64392.1, 0.001], [64553.5, 0.007], [64670.7, 0.165], [64679.8, 0.005], [64704.9, 0.243], [64705.0, 0.182], [64705.4, 0.12], [64705.5, 0.008], [64705.6, 0.018], [64707.4, 0.562], [64712.2, 5.834]], "asks": [[64734.9, 0.848], [64741.1, 0.309], [64741.3, 1.479], [64757.6, 0.0], [64883.0, 0.067], [65045.3, 0.0], [65208.0, 0.517], [65359.4, 5.521], [65371.1, 0.008], [65533.7, 1.524], [65712.3, 0.027], [65747.7, 4.252]]}
{"kind": "depth", "E": 1787080138593, "U": 11315332019940, "u": 11315332023161, "recv_ms": 1787080138535, "bids": [[14412.2, 2.954], [14512.2, 1.246], [51770.0, 0.0], [58240.9, 0.002], [61476.5, 0.0], [62123.7, 0.689], [63773.9, 41.802], [63935.7, 36.599], [63968.0, 10.641], [64065.1, 9.906], [64067.4, 0.009], [64194.5, 8.257], [64228.0, 0.005], [64389.0, 0.018], [64550.4, 0.032], [64571.6, 3.089], [64670.7, 0.179], [64695.2, 0.009], [64696.2, 0.005], [64697.1, 0.962], [64704.1, 0.62], [64704.3, 0.142], [64705.0, 0.73], [64707.4, 0.014], [64707.5, 0.125], [64709.0, 0.003], [64709.4, 1.849], [64712.2, 5.908]], "asks": [[64721.9, 0.25], [64723.4, 0.022], [64728.7, 0.418], [64852.7, 5.397], [64879.8, 0.002], [65042.0, 0.004], [65204.7, 0.068], [65359.4, 5.521], [65367.8, 0.008], [65469.0, 1.088]]}
{"kind": "depth", "E": 1787080138695, "U": 11315332023354, "u": 11315332028370, "recv_ms": 1787080138636, "bids": [[14412.2, 3.318], [14512.2, 0.882], [58240.9, 0.002], [62123.7, 0.692], [63712.2, 7.683], [63773.9, 40.707], [63799.2, 0.467], [63903.3, 10.933], [63968.0, 9.705], [63971.5, 0.005], [63995.7, 0.035], [64065.1, 9.906], [64175.9, 0.0], [64388.6, 4.494], [64582.7, 0.004], [64695.2, 0.001], [64697.1, 0.96], [64704.2, 0.081], [64704.9, 0.166], [64705.4, 0.197], [64709.0, 0.087], [64712.2, 5.996]], "asks": [[64714.4, 0.001], [65035.9, 3.997], [65359.4, 5.521], [65521.2, 11.728], [65712.3, 0.007], [65747.7, 5.315]]}
{"kind": "depth", "E": 1787080138797, "U": 11315332028576, "u": 11315332034656, "recv_ms": 1787080138738, "bids": [[1000.0, 35.81], [14412.2, 3.682], [14512.2, 0.518], [58240.9, 0.002], [61476.5, 0.0], [62123.7, 0.689], [63418.0, 2.689], [63676.8, 4.833], [63935.7, 37.379], [64065.1, 9.906], [64194.5, 8.568], [64582.7, 0.003], [64670.7, 0.165], [64695.2, 0.001], [64703.9, 0.182], [64704.0, 1.23], [64704.1, 0.157], [64705.0, 0.182], [64705.4, 0.197], [64705.5, 0.008], [64705.6, 0.018], [64707.3, 0.828], [64709.5, 0.095], [64712.2, 5.967]], "asks": [[64714.4, 0.001], [64869.6, 10.406], [64869.7, 0.026], [64908.5, 15.721], [64980.8, 2.099], [65359.4, 5.521], [65436.3, 1.072], [65488.8, 49.304], [65747.7, 4.252]]}
{"kind": "depth", "E": 1787080139001, "U": 11315332039549, "u": 11315332043087, "recv_ms": 1787080138944, "bids": [[14312.2, 0.378], [14412.2, 3.626], [14512.2, 0.196], [58240.9, 0.002], [61476.5, 0.0], [62123.7, 0.692], [62384.2, 0.018], [63657.8, 0.0], [63712.2, 7.683], [64065.1, 9.906], [64129.8, 38.915], [64388.6, 4.505], [64571.6, 3.096], [64693.6, 0.173], [64694.9, 0.466], [64702.3, 1.044], [64704.1, 0.157], [64704.9, 0.173], [64705.4, 0.669], [64712.2, 6.488]], "asks": [[64712.3, 27.83], [64726.8, 1.045], [64729.3, 0.646], [64730.8, 0.024], [64734.2, 1.35], [64741.4, 0.564], [64777.1, 0.023], [64852.7, 4.245], [64869.6, 6.285], [64908.5, 15.721], [65035.9, 3.996], [65359.4, 5.523], [65712.3, 0.007], [66006.5, 0.018]]}
{"kind": "depth", "E": 1787080139103, "U": 11315332043157, "u": 11315332048221, "recv_ms": 1787080139043, "bids": [[1000.0, 35.81], [14312.2, 0.616], [14412.2, 3.514], [14512.2, 0.07], [51769.8, 0.0], [51770.0, 0.0], [58240.9, 0.002], [61476.5, 0.001], [62123.7, 0.689], [63741.5, 16.917], [63903.3, 11.166], [63911.6, 3.644], [64065.1, 9.906], [64571.7, 1.3], [64700.6, 0.245], [64704.1, 0.798], [64704.9, 0.166], [64705.0, 0.174], [64705.4, 0.12], [64705.5, 0.008], [64705.6, 0.018], [64707.4, 0.014], [64709.5, 0.011], [64712.2, 6.014]], "asks": [[64712.3, 27.83], [64741.2, 0.404], [64741.3, 1.325], [64868.5, 1.588], [64869.6, 10.406], [65359.4, 5.521], [65598.3, 0.0], [65922.4, 2.574]]}
{"kind": "depth", "E": 1787080139205, "U": 11315332048450, "u": 11315332053660, "recv_ms": 1787080139145, "bids": [[14312.2, 0.896], [14412.2, 3.304], [14512.2, 0.0], [51770.0, 0.0], [58240.9, 0.002], [61476.5, 0.0], [62123.7, 0.692], [63618.6, 5.498], [63644.4, 2.907], [63712.2, 7.703], [64065.1, 9.906], [64194.5, 8.257], [64388.6, 4.35], [64666.9, 0.725], [64670.7, 0.179], [64702.7, 0.465], [64704.1, 0.713], [64704.9, 0.243], [64705.0, 0.182], [64712.2, 5.941]], "asks": [[64712.3, 27.831], [64719.3, 0.349], [64721.5, 0.001], [64731.8, 0.005], [64741.2, 0.25], [64741.3, 1.325], [65359.4, 5.521], [65520.6, 0.038], [65712.3, 0.027]]}
{"kind": "depth", "E": 1787080139307, "U": 11315332053812, "u": 11315332060604, "recv_ms": 1787080139251, "bids": [[1000.0, 35.96], [14312.2, 1.26], [14412.2, 2.94], [58240.9, 0.002], [61476.5, 0.0], [61476.7, 0.006], [63967.7, 3.626], [64065.1, 9.906], [64168.6, 0.004], [64388.6, 4.35], [64571.6, 2.229], [64670.7, 0.165], [64696.0, 1.284], [64704.8, 0.636], [64705.2, 0.013], [64709.0, 0.003], [64712.2, 6.207]], "asks": [[64719.3, 0.348], [64741.1, 0.309], [64741.3, 1.479], [64852.7, 5.397], [64869.6, 10.406], [65359.4, 5.521], [65598.9, 1.217], [66006.5, 0.015]]}
{"kind": "depth", "E": 1787080139409, "U": 11315332060638, "u": 11315332064794, "recv_ms": 1787080139350, "bids": [[1000.0, 35.81], [14312.2, 1.61], [14412.2, 2.59], [58240.9, 0.002], [61476.5, 0.0], [62123.7, 0.689], [63418.0, 2.692], [63773.9, 40.706], [63968.0, 9.704], [64003.8, 4.68], [64065.1, 9.906], [64168.6, 0.039], [64388.6, 4.505], [64571.6, 2.74], [64670.7, 0.179], [64680.4, 0.09], [64709.1, 0.093], [64712.2, 5.757]], "asks": [[64717.4, 0.962], [64741.3, 1.479], [64744.4, 0.126], [64745.2, 0.006], [64746.6, 0.018], [64852.7, 5.397], [65359.4, 5.521], [65521.9, 9.076], [65565.4, 1.832]]}
{"kind": "depth", "E": 1787080139511, "U": 11315332064973, "u": 11315332068267, "recv_ms": 1787080139451, "bids": [[14312.2, 1.974], [14412.2, 2.226], [58240.9, 0.002], [61476.5, 0.0], [62123.7, 0.692], [63712.2, 7.683], [64065.1, 9.908], [64194.5, 8.568], [64670.7, 0.165], [64692.3, 0.222], [64709.5, 0.095], [64712.2, 6.367]], "asks": [[64741.3, 1.325], [65359.4, 5.525], [65712.3, 0.007], [65714.7, 3.195]]}
{"kind": "depth", "E": 1787080139613, "U": 11315332068277, "u": 11315332073372, "recv_ms": 1787080139562, "bids": [[1000.0, 35.81], [14312.2, 2.338], [14412.2, 1.862], [58240.9, 0.002], [61476.5, 0.0], [62123.7, 0.689], [63147.1, 1.356], [63611.5, 0.0], [63612.1, 9.259], [63819.6, 4.694], [63935.7, 38.316], [64065.1, 9.906], [64168.6, 0.144], [64388.6, 4.495], [64670.7, 0.179], [64675.8, 0.001], [64696.2, 0.005], [64709.1, 0.009], [64709.5, 0.011], [64712.2, 5.86]], "asks": [[64728.7, 0.418], [64741.2, 0.25], [64741.3, 1.479], [65359.4, 5.523], [65521.9, 9.838], [65553.6, 46.803]]}
{"kind": "depth", "E": 1787080139715, "U": 11315332073393, "u": 11315332078492, "recv_ms": 1787080139656, "bids": [[1000.0, 35.81], [14312.2, 2.688], [14412.2, 1.512], [51770.0, 0.002], [58240.9, 0.002], [61476.5, 0.0], [62123.7, 0.692], [63712.2, 7.703], [63773.9, 41.802], [63838.6, 9.048], [63935.7, 36.442], [63967.7, 2.689], [63968.0, 10.641], [64065.1, 9.906], [64388.6, 4.494], [64515.7, 7.058], [64518.1, 0.361], [64554.6, 3.856], [64571.6, 2.74], [64582.7, 0.003], [64653.7, 0.027], [64654.0, 0.002], [64654.3, 0.0], [64654.7, 0.023], [64655.0, 0.127], [64670.9, 2.436], [64671.0, 0.066], [64671.3, 0.003], [64671.6, 0.007], [64671.9, 0.818], [64672.2, 0.992], [64685.9, 0.07], [64686.0, 0.004], [64686.1, 0.014], [64686.2, 0.158], [64686.3, 0.034], [64686.4, 1.379], [64686.5, 0.034], [64686.6, 0.093], [64686.7, 0.097], [64686.8, 0.023], [64687.4, 1.774], [64687.8, 0.0], [64699.8, 0.002], [64704.1, 0.798], [64704.2, 0.011], [64704.3, 0.002], [64704.4, 0.135], [64704.5, 0.0], [64704.6, 0.001], [64704.7, 0.001], [64704.8, 0.466], [64704.9, 0.066], [64705.0, 0.004], [64705.1, 0.04], [64705.4, 0.12], [64705.5, 0.008], [64705.8, 0.105], [64706.1, 0.365], [64706.4, 0.004], [64706.7, 0.085], [64707.4, 0.014], [64709.1, 0.093], [64712.2, 5.728]], "asks": [[64718.4, 0.004], [64718.7, 0.381], [64719.0, 0.009], [64719.3, 0.313], [64719.6, 0.035], [64719.7, 0.052], [64720.0, 0.12], [64720.1, 2.319], [64720.2, 0.018], [64720.3, 0.0], [64720.4, 0.002], [64720.5, 0.004], [64720.6, 2.041], [64720.7, 0.002], [64720.8, 0.002], [64720.9, 0.126], [64735.6, 0.118], [64735.9, 0.0], [64736.3, 0.181], [64736.6, 0.026], [64736.8, 0.036], [64736.9, 0.309], [64737.3, 1.704], [64737.8, 0.01], [64738.3, 0.122], [64738.4, 0.0], [64738.5, 0.361], [64738.6, 0.002], [64738.7, 0.003], [64738.8, 0.002], [64738.9, 0.001], [64739.0, 0.856], [64739.1, 0.367], [64739.2, 3.416], [64740.8, 1.433], [64741.3, 1.325], [64752.9, 0.0], [64753.2, 1.495], [64753.5, 0.021], [64753.8, 0.031], [64754.2, 0.31], [64852.7, 5.397], [65359.4, 5.521], [65695.1, 1.037], [65712.3, 0.027], [65715.3, 8.114]]}
{"kind": "depth", "E": 1787080139817, "U": 11315332078567, "u": 11315332083024, "recv_ms": 1787080139758, "bids": [[14312.2, 3.038], [14412.2, 1.162], [51770.0, 0.0], [58240.9, 0.002], [61476.5, 0.0], [63744.9, 1.569], [63903.3, 11.517], [63935.7, 35.973], [64009.5, 0.704], [64065.1, 9.906], [64518.1, 1.261], [64638.3, 33.074], [64642.7, 0.146], [64642.9, 3.256], [64644.9, 0.004], [64646.3, 2.638], [64647.4, 0.184], [64666.9, 0.722], [64671.9, 0.853], [64672.2, 1.024], [64679.8, 0.005], [64699.7, 0.257], [64704.2, 0.019], [64704.9, 0.166], [64705.1, 0.14], [64706.4, 0.039], [64706.7, 0.117], [64708.1, 0.005], [64709.1, 0.009], [64712.2, 5.829]], "asks": [[64718.3, 0.034], [64718.6, 0.035], [64719.9, 0.442], [64720.1, 2.429], [64734.1, 10.003], [64735.5, 0.573], [64735.8, 0.113], [64736.0, 1.603], [64737.2, 2.59], [64738.0, 0.534], [64738.4, 0.11], [64740.8, 1.279], [64741.3, 1.325], [64757.6, 0.003], [65035.9, 3.997], [65359.4, 5.521], [65683.0, 7.636]]}
{"kind": "depth", "E": 1787080139919, "U": 11315332083069, "u": 11315332088636, "recv_ms": 1787080139860, "bids": [[1000.0, 35.81], [14312.2, 3.402], [14412.2, 0.798], [58240.9, 0.002], [62123.7, 0.689], [63644.4, 1.809], [63709.2, 12.943], [63712.2, 7.683], [63754.9, 1.567], [63773.9, 40.706], [63935.7, 38.784], [64065.1, 9.906], [64388.6, 4.504], [64638.3, 0.0], [64642.3, 0.039], [64642.7, 33.22], [64671.3, 0.035], [64704.2, 0.081], [64704.3, 0.072], [64704.4, 0.205], [64704.6, 0.201], [64704.7, 0.101], [64704.9, 0.266], [64705.0, 0.074], [64705.2, 0.083], [64705.8, 0.137], [64708.1, 0.013], [64709.0, 0.087]], "asks": [[64719.2, 0.043], [64719.8, 0.092], [64720.0, 0.197], [64720.1, 2.529], [64720.3, 0.1], [64720.4, 0.212], [64720.6, 2.125], [64720.7, 0.072], [64720.8, 0.072], [64736.5, 0.035], [64737.6, 1.409], [64738.2, 0.095], [64738.3, 0.199], [64738.4, 0.21], [64738.6, 0.102], [64738.8, 0.102], [64738.9, 0.085], [64739.0, 0.926], [64739.1, 0.437], [64741.3, 1.479], [65359.4, 5.521], [65529.7, 1.78], [65712.3, 0.007], [65824.9, 0.76]]}
{"kind": "depth", "E": 1787080140021, "U": 11315332088769, "u": 11315332096995, "recv_ms": 1787080139963, "bids": [[1000.0, 35.81], [14212.2, 0.028], [14312.2, 3.696], [14412.2, 0.476], [58240.9, 0.002], [61476.5, 0.0], [62123.7, 0.692], [63644.4, 2.907], [63753.0, 2.315], [63935.7, 39.253], [64065.1, 9.906], [64388.6, 4.444], [64571.6, 2.231], [64571.7, 1.171], [64651.7, 0.04], [64651.9, 0.31], [64653.7, 0.059], [64668.5, 0.031], [64671.6, 0.039], [64673.3, 0.069], [64679.4, 0.009], [64680.0, 3.101], [64682.4, 0.162], [64690.1, 0.004], [64690.6, 0.56], [64692.0, 0.392], [64692.4, 0.022], [64692.5, 0.708], [64692.9, 0.616], [64694.4, 0.627], [64695.2, 0.001], [64695.5, 0.001], [64696.1, 0.948], [64701.8, 0.619], [64703.9, 0.653], [64704.0, 0.226], [64704.1, 0.257], [64704.2, 1.155], [64704.5, 0.07], [64704.7, 0.201], [64704.8, 0.464], [64704.9, 0.268], [64705.0, 0.074], [64705.4, 0.036], [64706.1, 0.397], [64707.2, 2.292], [64707.3, 0.232], [64707.4, 0.324], [64708.0, 1.727], [64709.4, 1.933], [64710.4, 0.093], [64712.2, 5.775]], "asks": [[64712.3, 27.712], [64712.4, 0.064], [64714.4, 0.001], [64718.9, 0.036], [64719.8, 0.092], [64720.0, 0.197], [64720.3, 0.2], [64720.5, 0.074], [64722.1, 0.007], [64726.0, 0.002], [64726.3, 0.163], [64728.5, 0.926], [64728.9, 0.164], [64731.0, 0.635], [64731.5, 0.002], [64731.8, 0.062], [64732.6, 0.07], [64733.2, 0.009], [64733.3, 2.693], [64733.7, 0.771], [64734.2, 1.343], [64734.3, 0.551], [64735.5, 0.032], [64736.1, 0.039], [64737.8, 0.014], [64738.6, 0.202], [64738.8, 0.172], [64739.0, 0.922], [64741.3, 1.325], [64741.4, 0.718], [64754.0, 0.038], [64786.6, 0.073], [64789.8, 0.0], [64852.7, 5.397], [64886.7, 0.049], [65038.0, 0.814], [65359.4, 5.521]]}
{"kind": "depth", "E": 1787080140123, "U": 11315332097037, "u": 11315332105759, "recv_ms": 1787080140064, "bids": [[14212.2, 0.196], [14312.2, 3.724], [14412.2, 0.28], [51769.8, 0.0], [51770.0, 0.0], [58240.9, 0.002], [61476.5, 0.0], [61476.6, 0.008], [61476.7, 0.008], [62123.7, 0.689], [63676.8, 4.833], [63712.2, 7.703], [63773.9, 41.802], [63996.9, 4.134], [64065.1, 9.906], [64642.7, 33.22], [64644.9, 0.004], [64654.7, 0.058], [64655.0, 0.159], [64666.8, 0.003], [64669.2, 0.062], [64669.4, 0.303], [64680.0, 3.044], [64680.3, 0.102], [64696.1, 0.023], [64696.4, 0.935], [64700.6, 0.245], [64704.0, 0.226], [64704.1, 0.157], [64704.2, 0.143], [64704.4, 0.275], [64704.8, 0.534], [64704.9, 0.266], [64705.0, 0.089], [64705.1, 0.14], [64705.2, 0.626], [64705.4, 0.662], [64712.2, 5.83]], "asks": [[64714.4, 0.001], [64719.8, 0.092], [64720.0, 0.197], [64720.2, 0.089], [64720.6, 2.202], [64720.8, 0.142], [64722.1, 0.007], [64726.0, 0.002], [64728.5, 0.001], [64728.6, 0.725], [64728.9, 1.089], [64731.0, 0.079], [64731.5, 0.558], [64731.8, 0.005], [64732.2, 0.081], [64734.3, 0.01], [64734.8, 0.551], [64738.5, 0.431], [64738.9, 0.162], [64739.1, 0.507], [64741.2, 0.248], [64741.3, 1.323], [64744.2, 0.0], [64744.3, 0.002], [64745.0, 2.957], [64745.1, 1.01], [64747.2, 1.396], [64747.3, 0.061], [64747.4, 0.006], [64749.3, 1.382], [64752.7, 0.032], [64753.1, 0.323], [64753.8, 0.001], [64763.8, 0.004], [64772.8, 1.34], [64773.0, 0.04], [64774.5, 0.011], [64869.6, 10.406], [64908.5, 15.721], [65035.9, 3.998], [65359.4, 5.523], [65631.2, 2.726], [65712.3, 0.027]]}
{"kind": "depth", "E": 1787080140225, "U": 11315332105839, "u": 11315332112526, "recv_ms": 1787080140167, "bids": [[1000.0, 35.81], [14212.2, 0.434], [14312.2, 3.598], [14412.2, 0.168], [51770.0, 0.0], [58240.9, 0.053], [62123.7, 0.692], [63709.2, 14.04], [63712.2, 7.683], [63967.7, 1.752], [64065.1, 9.906], [64107.3, 4.249], [64388.6, 4.434], [64654.0, 0.034], [64679.6, 0.002], [64686.6, 0.193], [64687.8, 0.1], [64699.7, 0.103], [64704.0, 0.767], [64704.1, 0.798], [64705.0, 0.074], [64705.2, 0.085], [64705.4, 0.036], [64705.5, 0.008], [64707.4, 0.324], [64712.2, 5.694]], "asks": [[64712.3, 27.585], [64714.4, 0.156], [64719.8, 0.247], [64720.0, 0.352], [64722.1, 0.317], [64726.0, 0.157], [64726.5, 0.147], [64726.9, 0.312], [64740.3, 0.179], [64741.4, 0.564], [64753.7, 0.047], [65359.4, 5.521], [65650.6, 27.665], [65712.3, 0.007], [67947.9, 0.068]]}
{"kind": "depth", "E": 1787080140327, "U": 11315332112547, "u": 11315332118605, "recv_ms": 1787080140268, "bids": [[1000.0, 35.81], [14212.2, 0.672], [14312.2, 3.486], [14412.2, 0.042], [51770.0, 0.0], [58240.9, 0.053], [61476.5, 0.0], [61630.7, 0.103], [63676.8, 5.931], [63741.5, 17.308], [63773.9, 40.706], [63902.9, 2.814], [63942.1, 8.446], [63957.7, 0.83], [63987.4, 1.256], [64065.1, 9.906], [64571.6, 2.759], [64654.4, 1.194], [64679.4, 0.066], [64680.3, 0.045], [64685.9, 0.14], [64686.0, 0.074], [64686.1, 0.084], [64686.2, 0.258], [64686.4, 1.479], [64686.6, 0.293], [64686.7, 0.167], [64686.8, 0.093], [64687.4, 1.874], [64690.1, 0.56], [64690.6, 0.004], [64692.0, 0.508], [64692.5, 0.592], [64695.2, 0.001], [64695.5, 0.926], [64696.4, 0.01], [64699.2, 0.166], [64701.8, 0.001], [64703.9, 0.19], [64704.0, 1.23], [64704.1, 0.157], [64704.2, 0.143], [64705.0, 0.166], [64705.1, 0.14], [64705.4, 0.585], [64712.2, 5.983]], "asks": [[64712.3, 27.722], [64713.0, 0.0], [64714.4, 0.001], [64719.8, 0.092], [64720.0, 0.197], [64722.1, 0.007], [64726.0, 0.002], [64728.0, 1.049], [64728.9, 0.164], [64731.4, 0.057], [64732.2, 0.024], [64733.7, 0.153], [64740.3, 0.025], [64740.8, 1.279], [64741.4, 0.718], [64753.4, 0.478], [64852.7, 4.34], [64869.6, 6.383], [64908.5, 11.824], [65359.4, 5.521], [66006.5, 0.018]]}
{"kind": "depth", "E": 1787080140429, "U": 11315332118688, "u": 11315332124374, "recv_ms": 1787080140371, "bids": [[14212.2, 0.98], [14312.2, 3.22], [14412.2, 0.0], [58240.9, 0.053], [61476.5, 0.0], [62123.7, 0.689], [64065.1, 9.906], [64679.4, 0.009], [64680.3, 0.102], [64686.2, 0.328], [64686.4, 1.579], [64690.1, 0.004], [64691.0, 1.543], [64692.0, 0.392], [64692.8, 1.589], [64692.9, 0.609], [64693.0, 0.009], [64695.2, 0.464], [64695.5, 0.001], [64696.4, 0.935], [64700.5, 0.004], [64701.3, 0.705], [64703.9, 0.19], [64704.0, 0.767], [64704.1, 0.798], [64705.0, 0.074], [64705.2, 0.085], [64705.4, 0.036], [64705.5, 0.008], [64705.7, 0.157], [64707.0, 0.013], [64707.4, 0.324], [64709.3, 0.006], [64712.2, 6.03]], "asks": [[64713.2, 0.002], [64713.4, 0.044], [64713.6, 0.086], [64714.4, 0.001], [64715.4, 0.184], [64717.1, 0.017], [64719.4, 0.004], [64719.5, 0.31], [64719.8, 0.092], [64719.9, 0.133], [64720.0, 0.213], [64721.7, 0.002], [64721.8, 0.004], [64721.9, 0.25], [64722.1, 0.1], [64722.2, 0.607], [64725.9, 0.003], [64726.0, 0.002], [64726.1, 0.224], [64726.5, 0.61], [64726.7, 0.364], [64728.0, 0.124], [64728.9, 1.089], [64731.4, 0.0], [64732.2, 0.081], [64733.2, 0.002], [64733.3, 2.7], [64735.6, 0.003], [64735.9, 0.115], [64748.9, 0.031], [64749.0, 0.004], [64869.6, 10.406], [64908.5, 15.721], [65359.4, 5.521], [65694.9, 4.142], [66074.4, 2.27]]}
{"kind": "depth", "E": 1787080140531, "U": 11315332124530, "u": 11315332145880, "recv_ms": 1787080140472, "bids": [[1000.0, 35.81], [14212.2, 1.344], [14312.2, 2.856], [58240.9, 0.053], [61476.5, 0.0], [62123.7, 0.692], [63418.0, 2.695], [63712.2, 7.703], [63773.9, 41.802], [63838.2, 3.625], [63935.7, 40.19], [63968.0, 9.704], [64065.1, 9.906], [64388.6, 4.434], [64619.7, 0.259], [64619.8, 0.004], [64670.7, 0.179], [64673.3, 0.083], [64685.9, 0.21], [64686.1, 0.154], [64686.5, 0.104], [64694.4, 0.009], [64695.3, 0.01], [64703.9, 0.182], [64705.2, 0.083], [64705.6, 0.02], [64706.1, 0.397], [64707.4, 0.014], [64709.4, 1.849], [64710.4, 0.009], [64712.2, 6.891]], "asks": [[64712.3, 27.806], [64712.7, 0.099], [64714.4, 0.001], [64716.7, 0.002], [64720.0, 0.205], [64720.2, 0.088], [64721.8, 0.012], [64721.9, 0.258], [64722.1, 0.092], [64726.0, 0.002], [64733.3, 1.569], [64734.1, 0.003], [64734.8, 0.551], [64735.9, 0.115], [64737.9, 10.952], [64741.4, 0.562], [64741.5, 0.181], [64869.6, 6.383], [64908.5, 11.823], [65359.4, 5.521], [65359.5, 0.001], [65427.8, 1.449], [65497.3, 7.842], [65650.6, 28.73], [65712.3, 0.027], [65780.1, 1.264], [66006.5, 0.015]]}
{"kind": "depth", "E": 1787080140633, "U": 11315332146404, "u": 11315332161149, "recv_ms": 1787080140577, "bids": [[1000.0, 35.81], [14212.2, 1.708], [14312.2, 2.492], [58240.9, 0.053], [62123.7, 0.689], [63615.5, 1.573], [63712.2, 7.683], [63809.6, 2.349], [63870.9, 14.699], [63942.1, 9.383], [64065.1, 9.906], [64594.9, 0.409], [64595.2, 1.105], [64596.3, 3.905], [64641.0, 0.323], [64664.0, 1.217], [64670.7, 0.165], [64672.6, 0.029], [64680.6, 0.002], [64684.7, 1.918], [64690.3, 0.17], [64691.8, 0.003], [64692.7, 0.012], [64695.2, 0.001], [64695.3, 0.002], [64696.0, 1.284], [64696.2, 0.005], [64700.0, 0.574], [64704.1, 0.798], [64704.2, 0.614], [64705.4, 0.036], [64705.6, 0.018], [64707.1, 0.381], [64708.1, 0.021], [64709.3, 0.004], [64709.5, 0.087], [64710.3, 0.085], [64712.1, 0.019], [64712.2, 8.418]], "asks": [[64712.3, 14.659], [64712.4, 0.063], [64712.5, 0.0], [64712.7, 0.015], [64713.0, 0.001], [64713.2, 0.086], [64714.0, 0.004], [64714.2, 0.0], [64714.4, 3.309], [64714.5, 0.005], [64714.6, 2.521], [64715.4, 0.183], [64715.9, 0.031], [64716.8, 0.037], [64718.3, 0.047], [64719.8, 0.094], [64720.0, 0.282], [64720.7, 0.073], [64721.8, 0.004], [64721.9, 0.25], [64722.1, 0.031], [64722.2, 0.059], [64725.7, 0.022], [64726.0, 0.002], [64726.1, 0.216], [64726.5, 0.147], [64727.1, 0.484], [64728.7, 0.418], [64728.9, 0.164], [64729.7, 4.025], [64730.2, 0.001], [64730.9, 0.103], [64731.5, 0.002], [64732.2, 0.024], [64732.4, 0.558], [64732.5, 0.076], [64732.6, 0.127], [64733.0, 0.035], [64733.1, 0.0], [64733.3, 1.562], [64733.4, 2.321], [64733.8, 0.155], [64734.1, 0.01], [64734.8, 0.01], [64735.9, 0.541], [64736.5, 0.15], [64737.1, 0.326], [64737.9, 10.954], [64738.3, 0.249], [64741.5, 0.181], [64742.5, 0.093], [64743.7, 0.003], [64761.5, 0.076], [64770.6, 0.588], [64782.2, 0.018], [64783.5, 0.048], [64847.8, 4.811], [64869.6, 10.406], [64908.5, 15.721], [65359.4, 5.521], [65712.3, 0.007], [65889.0, 1.595], [67947.9, 0.063]]}
{"kind": "depth", "E": 1787080140735, "U": 11315332161167, "u": 11315332172405, "recv_ms": 1787080140679, "bids": [[14212.2, 2.058], [14312.2, 2.142], [58240.9, 0.053], [61476.5, 0.0], [63806.2, 30.313], [63967.7, 0.815], [63968.0, 10.641], [64065.1, 9.908], [64168.6, 0.218], [64582.7, 0.003], [64642.3, 0.03], [64656.4, 0.0], [64657.8, 0.002], [64664.7, 0.21], [64677.4, 0.008], [64678.1, 0.0], [64684.7, 1.582], [64686.2, 0.172], [64689.1, 0.361], [64691.0, 0.987], [64692.8, 2.029], [64693.7, 0.001], [64694.6, 0.273], [64694.9, 0.473], [64695.2, 0.472], [64697.1, 0.962], [64704.0, 0.226], [64704.1, 0.782], [64704.2, 0.143], [64704.3, 0.072], [64704.9, 0.266], [64705.0, 0.074], [64705.2, 0.083], [64705.4, 0.036], [64705.5, 0.008], [64705.6, 0.559], [64705.8, 0.053], [64707.0, 0.016], [64707.3, 0.001], [64707.5, 0.001], [64707.7, 0.323], [64708.0, 1.72], [64708.4, 0.125], [64708.6, 0.116], [64708.7, 0.103], [64710.6, 0.003], [64710.7, 0.259], [64710.8, 0.0], [64711.4, 0.312], [64712.2, 8.423]], "asks": [[64712.3, 14.66], [64712.4, 0.061], [64712.5, 0.002], [64713.2, 0.041], [64713.4, 0.002], [64713.5, 1.014], [64713.7, 0.008], [64714.2, 0.0], [64714.3, 0.084], [64714.4, 2.761], [64714.6, 0.019], [64714.7, 0.087], [64715.1, 0.394], [64715.4, 0.143], [64717.2, 0.0], [64717.4, 0.94], [64718.9, 0.077], [64719.9, 0.133], [64720.0, 0.274], [64722.1, 0.007], [64722.2, 0.607], [64723.5, 0.0], [64723.8, 0.013], [64724.5, 0.001], [64726.0, 0.002], [64726.1, 0.216], [64726.5, 0.61], [64726.6, 0.478], [64726.9, 0.158], [64727.1, 0.013], [64727.3, 0.538], [64727.5, 0.156], [64728.6, 0.805], [64729.7, 3.11], [64730.6, 0.382], [64731.0, 0.06], [64731.1, 1.348], [64731.9, 0.095], [64732.6, 0.07], [64733.1, 0.057], [64736.2, 0.001], [64736.5, 0.035], [64737.4, 0.135], [64738.3, 0.129], [64738.5, 0.501], [64741.5, 0.027], [64741.8, 0.154], [64745.8, 0.141], [64761.5, 0.118], [64848.9, 0.0], [64849.0, 0.11], [64869.6, 8.822], [64908.5, 15.721], [65359.4, 5.521], [65683.0, 7.978], [65780.1, 2.327], [66006.5, 0.018], [66071.3, 0.302]]}
{"kind": "depth", "E": 1787080140837, "U": 11315332172490, "u": 11315332181579, "recv_ms": 1787080140779, "bids": [[1000.0, 35.81], [14212.2, 2.422], [14312.2, 1.778], [58240.9, 0.053], [61476.5, 0.0], [62123.7, 0.692], [63418.0, 2.692], [63676.8, 4.833], [63773.9, 40.706], [63819.6, 2.348], [63903.3, 11.868], [64065.1, 9.906], [64388.6, 4.435], [64642.7, 0.146], [64644.9, 33.135], [64657.8, 0.03], [64663.8, 1.257], [64673.3, 0.069], [64680.2, 0.071], [64680.3, 0.045], [64681.4, 0.448], [64682.1, 0.02], [64685.0, 0.349], [64686.0, 0.074], [64687.8, 0.282], [64689.1, 0.025], [64691.0, 1.543], [64692.0, 0.388], [64692.6, 0.128], [64692.8, 1.473], [64693.5, 2.457], [64694.6, 0.157], [64695.2, 0.001], [64696.0, 1.286], [64696.3, 1.166], [64696.4, 0.01], [64697.1, 0.962], [64697.6, 2.71], [64698.0, 0.12], [64698.1, 1.003], [64698.2, 0.016], [64699.4, 0.249], [64700.3, 0.321], [64702.2, 0.001], [64702.9, 0.007], [64704.1, 0.003], [64704.2, 1.147], [64704.3, 0.08], [64705.0, 0.092], [64705.4, 0.23], [64705.5, 0.085], [64705.6, 0.018], [64705.7, 0.157], [64706.2, 0.085], [64707.0, 0.013], [64707.1, 0.379], [64707.2, 2.523], [64707.3, 0.549], [64707.7, 0.092], [64708.1, 0.013], [64709.0, 0.104], [64709.3, 0.006], [64709.5, 0.095], [64709.6, 0.002], [64710.1, 0.001], [64710.2, 0.0], [64710.3, 0.001], [64710.5, 0.086], [64710.6, 0.003], [64710.7, 0.175], [64712.1, 0.017], [64712.2, 4.817]], "asks": [[64712.3, 14.654], [64712.6, 0.002], [64713.1, 0.085], [64714.0, 0.003], [64714.3, 0.085], [64714.5, 0.013], [64715.0, 0.103], [64715.2, 0.004], [64716.1, 0.0], [64716.9, 0.077], [64717.0, 1.052], [64717.8, 1.003], [64718.3, 0.067], [64718.4, 0.027], [64718.5, 0.313], [64719.1, 0.002], [64719.8, 0.094], [64719.9, 0.165], [64720.0, 1.293], [64721.0, 0.004], [64722.2, 0.059], [64724.2, 0.122], [64726.0, 0.002], [64726.1, 0.216], [64726.5, 0.147], [64727.6, 0.322], [64728.8, 1.533], [64729.7, 2.185], [64730.7, 0.021], [64732.0, 0.081], [64733.1, 0.0], [64734.0, 0.299], [64734.8, 0.551], [64735.9, 0.0], [64737.1, 0.326], [64737.9, 0.954], [64760.8, 3.743], [64764.1, 0.02], [64766.7, 0.014], [64779.7, 0.036], [64781.0, 6.982], [64781.1, 38.85], [64781.3, 0.034], [64782.2, 0.0], [64783.3, 0.0], [65035.9, 3.997], [65359.4, 5.521], [65417.7, 7.623], [65521.2, 11.88], [65650.6, 27.665], [65747.7, 4.252], [65877.1, 1.574]]}
{"kind": "depth", "E": 1787080140939, "U": 11315332181593, "u": 11315332190190, "recv_ms": 1787080140880, "bids": [[1000.0, 35.81], [14212.2, 2.772], [14312.2, 1.428], [58240.9, 0.053], [61476.5, 0.0], [62123.7, 0.689], [63449.7, 2.026], [63709.2, 12.943], [63712.2, 7.703], [63935.7, 41.127], [64065.1, 9.906], [64670.7, 0.179], [64684.0, 0.344], [64685.0, 0.013], [64691.2, 0.013], [64691.6, 0.116], [64691.8, 0.001], [64693.5, 2.341], [64695.2, 0.001], [64696.0, 1.284], [64697.1, 0.96], [64698.0, 0.124], [64702.2, 0.003], [64702.5, 0.018], [64703.9, 0.182], [64704.2, 0.684], [64704.3, 0.543], [64704.6, 0.201], [64705.0, 0.074], [64705.4, 0.238], [64705.5, 0.093], [64705.7, 0.003], [64705.8, 0.137], [64706.0, 0.012], [64706.2, 0.085], [64706.3, 0.003], [64707.3, 0.703], [64708.1, 0.005], [64709.0, 0.087], [64709.5, 0.019], [64709.8, 0.088], [64710.5, 0.002], [64711.4, 0.002], [64712.2, 6.183]], "asks": [[64712.3, 14.739], [64712.9, 0.0], [64713.0, 0.0], [64713.6, 0.087], [64714.0, 0.003], [64714.2, 0.0], [64714.3, 0.101], [64716.9, 0.232], [64719.7, 0.052], [64719.8, 0.094], [64719.9, 0.133], [64720.0, 0.352], [64722.1, 0.57], [64722.2, 1.073], [64726.1, 0.371], [64726.5, 0.147], [64727.1, 0.013], [64738.8, 10.174], [64739.2, 3.414], [64744.4, 0.124], [64745.2, 0.004], [64764.1, 0.006], [64766.7, 0.0], [64781.0, 0.004], [64781.1, 0.311], [64783.3, 38.539], [64784.8, 0.037], [64785.5, 0.029], [64869.6, 8.822], [64908.5, 15.721], [65359.4, 5.521], [65482.4, 8.247], [65712.3, 0.027]]}
{"kind": "depth", "E": 1787080141041, "U": 11315332190329, "u": 11315332196708, "recv_ms": 1787080140983, "bids": [[14212.2, 3.122], [14312.2, 1.078], [58240.9, 0.053], [61476.5, 0.0], [62123.7, 0.692], [63709.2, 14.04], [63806.2, 32.66], [64065.1, 9.906], [64256.6, 0.0], [64615.1, 2.336], [64636.1, 33.144], [64644.9, 0.004], [64646.3, 7.696], [64679.8, 0.005], [64680.2, 0.014], [64680.5, 1.027], [64692.9, 0.617], [64695.2, 0.001], [64695.3, 0.62], [64697.1, 0.962], [64700.5, 0.009], [64702.7, 1.083], [64703.9, 0.723], [64704.0, 0.782], [64704.1, 0.011], [64704.2, 0.143], [64704.3, 0.072], [64704.5, 0.07], [64705.0, 0.074], [64705.3, 0.002], [64705.4, 0.23], [64705.5, 0.008], [64705.6, 0.018], [64705.7, 0.003], [64706.2, 0.631], [64707.3, 0.162], [64707.4, 0.555], [64708.1, 0.013], [64709.5, 0.011], [64712.2, 6.135]], "asks": [[64713.2, 0.002], [64713.5, 1.055], [64716.9, 0.077], [64718.9, 0.058], [64719.7, 1.072], [64719.8, 0.094], [64719.9, 0.225], [64720.0, 0.197], [64721.9, 0.25], [64722.1, 0.007], [64722.2, 0.059], [64726.1, 0.216], [64726.4, 0.632], [64727.1, 0.013], [64727.6, 0.322], [64728.8, 0.608], [64729.0, 1.062], [64732.0, 0.024], [64732.3, 0.06], [64733.8, 0.773], [64736.0, 3.26], [64739.5, 0.012], [64740.3, 0.179], [64741.2, 0.25], [64741.3, 1.325], [64741.4, 0.564], [64744.2, 0.002], [64744.3, 0.004], [64744.4, 0.126], [64745.0, 2.959], [64745.1, 1.012], [64745.2, 0.006], [64747.2, 1.398], [64747.3, 0.063], [64747.4, 0.008], [64757.6, 0.003], [64782.2, 0.018], [64784.8, 0.019], [64869.6, 10.406], [64908.5, 15.721], [64910.9, 0.028], [64911.0, 0.2], [65359.4, 5.521], [65482.4, 9.162], [67947.9, 0.058]]}
{"kind": "depth", "E": 1787080141143, "U": 11315332196941, "u": 11315332206947, "recv_ms": 1787080141085, "bids": [[1000.0, 35.81], [14212.2, 3.486], [14312.2, 0.714], [51769.8, 0.0], [58240.9, 0.053], [61476.5, 0.0], [62123.7, 0.689], [63417.4, 0.303], [63712.2, 7.683], [63770.8, 4.384], [63838.2, 2.686], [64065.1, 9.906], [64248.5, 0.311], [64388.6, 4.446], [64633.4, 0.002], [64636.1, 0.0], [64637.1, 0.0], [64640.7, 0.209], [64642.7, 33.29], [64646.3, 2.638], [64647.5, 0.004], [64670.7, 0.165], [64680.3, 0.045], [64680.5, 0.97], [64680.8, 0.057], [64696.3, 0.241], [64696.9, 1.237], [64697.1, 0.962], [64700.5, 0.004], [64702.7, 1.082], [64703.6, 0.001], [64703.9, 0.182], [64704.0, 0.766], [64704.1, 0.003], [64704.2, 0.7], [64704.3, 0.08], [64705.4, 0.036], [64705.5, 0.008], [64706.0, 0.01], [64706.2, 0.631], [64706.3, 0.197], [64706.9, 0.005], [64707.1, 0.381], [64707.3, 0.703], [64707.4, 0.014], [64708.1, 0.005], [64709.2, 0.019], [64709.5, 0.019], [64710.9, 0.107], [64711.4, 0.312], [64712.1, 0.022], [64712.2, 7.893]], "asks": [[64712.3, 14.445], [64713.1, 0.001], [64714.3, 0.101], [64714.5, 0.006], [64715.9, 0.031], [64716.8, 0.048], [64716.9, 0.077], [64718.5, 0.003], [64719.7, 0.145], [64719.8, 0.094], [64719.9, 1.152], [64720.0, 0.197], [64720.2, 0.089], [64721.9, 0.25], [64722.1, 0.007], [64722.2, 0.059], [64726.0, 0.002], [64726.1, 0.216], [64726.4, 0.014], [64729.0, 0.137], [64729.4, 3.686], [64732.3, 0.003], [64732.7, 1.605], [64733.8, 0.155], [64734.8, 0.01], [64735.9, 0.541], [64736.0, 1.603], [64738.8, 0.174], [64741.7, 10.0], [64777.0, 0.076], [65035.9, 3.996], [65359.4, 5.521], [65712.3, 0.007], [66006.5, 0.021]]}
{"kind": "depth", "E": 1787080141245, "U": 11315332207120, "u": 11315332224048, "recv_ms": 1787080141185, "bids": [[1000.0, 35.81], [14212.2, 3.738], [14312.2, 0.406], [14612.2, 0.056], [51770.0, 0.0], [58240.9, 0.053], [61476.5, 0.0], [62123.1, 2.002], [62770.3, 1.002], [63418.0, 4.897], [63676.8, 5.931], [63712.2, 7.703], [63760.9, 4.62], [63773.9, 41.802], [63884.4, 0.031], [63988.6, 3.874], [64065.1, 9.906], [64587.2, 1.445], [64608.0, 0.727], [64666.9, 0.725], [64696.7, 0.947], [64696.9, 0.312], [64697.1, 0.962], [64699.3, 0.042], [64702.4, 0.005], [64702.7, 0.464], [64703.6, 0.0], [64704.2, 0.684], [64704.3, 0.62], [64704.5, 0.078], [64705.0, 0.09], [64705.8, 0.053], [64706.2, 0.631], [64706.3, 0.003], [64707.3, 0.17], [64707.4, 0.014], [64707.5, 0.001], [64708.1, 0.005], [64709.5, 0.019], [64710.1, 0.085], [64710.5, 0.086], [64710.9, 0.023], [64712.2, 7.845]], "asks": [[64712.3, 14.058], [64712.9, 0.0], [64713.6, 0.086], [64714.0, 0.003], [64714.1, 0.0], [64714.4, 2.762], [64714.5, 0.006], [64716.9, 0.232], [64717.1, 0.017], [64717.3, 0.163], [64718.3, 0.047], [64718.4, 0.004], [64718.9, 0.036], [64719.7, 0.034], [64719.8, 0.257], [64719.9, 0.697], [64720.0, 0.197], [64720.2, 0.088], [64720.6, 2.221], [64721.9, 0.405], [64722.1, 0.47], [64722.2, 0.291], [64726.1, 0.371], [64727.1, 0.013], [64728.8, 0.606], [64729.4, 3.688], [64734.8, 0.551], [64735.9, 0.0], [64743.4, 0.002], [64781.1, 38.604], [64782.2, 0.0], [64783.3, 0.0], [64822.4, 0.017], [64869.6, 6.347], [64908.5, 11.721], [65359.4, 5.521], [65650.6, 28.73], [65712.3, 0.027], [65747.7, 5.315]]}
{"kind": "depth", "E": 1787080141347, "U": 11315332224159, "u": 11315332230866, "recv_ms": 1787080141288, "bids": [[14212.2, 3.696], [14312.2, 0.252], [14612.2, 0.252], [58240.9, 0.053], [61476.0, 3.172], [61476.5, 0.0], [62123.7, 0.692], [63676.8, 4.833], [63806.2, 33.599], [63942.1, 8.446], [64065.1, 9.906], [64388.6, 4.456], [64571.6, 3.097], [64571.7, 0.838], [64642.7, 0.146], [64644.9, 33.148], [64696.4, 0.935], [64696.7, 0.022], [64697.1, 0.962], [64712.2, 7.816]], "asks": [[64716.9, 0.232], [64718.3, 0.067], [64718.4, 0.026], [64719.7, 0.035], [64719.8, 0.257], [64721.9, 0.405], [64722.2, 0.446], [64726.1, 0.371], [64852.6, 5.398], [64852.7, 0.0], [64869.6, 6.347], [64908.5, 11.721], [64917.5, 0.009], [65497.3, 7.629], [65858.6, 0.003]]}
{"kind": "depth", "E": 1787080141449, "U": 11315332231025, "u": 11315332238420, "recv_ms": 1787080141390, "bids": [[1000.0, 35.81], [14212.2, 3.57], [14312.2, 0.14], [14612.2, 0.49], [51770.0, 0.0], [58240.9, 0.053], [60828.9, 4.0], [61476.5, 0.0], [61476.6, 0.01], [62123.7, 0.689], [63676.8, 5.931], [63712.2, 7.683], [63730.4, 1.58], [63806.2, 35.947], [64065.1, 9.906], [64194.5, 8.568], [64207.6, 0.001], [64388.6, 5.879], [64638.3, 0.0], [64642.3, 0.03], [64642.7, 33.29], [64644.9, 0.004], [64683.8, 0.027], [64685.4, 2.639], [64691.6, 0.0], [64692.0, 0.384], [64692.5, 2.424], [64692.8, 1.589], [64693.0, 0.002], [64693.6, 0.18], [64695.2, 0.472], [64697.1, 0.962], [64700.9, 0.002], [64701.3, 0.396], [64702.3, 1.353], [64703.9, 0.723], [64704.0, 0.226], [64704.2, 0.143], [64704.3, 0.072], [64704.5, 0.07], [64705.0, 0.167], [64706.9, 0.002], [64707.2, 2.292], [64707.6, 0.002], [64708.0, 0.006], [64708.1, 0.553], [64709.3, 0.004], [64711.6, 0.002], [64712.2, 8.77]], "asks": [[64713.2, 0.086], [64714.1, 0.001], [64714.3, 0.101], [64714.4, 2.761], [64716.8, 0.048], [64716.9, 0.232], [64718.6, 0.345], [64719.5, 0.001], [64719.6, 0.506], [64719.7, 0.661], [64719.8, 0.094], [64719.9, 0.148], [64720.0, 0.352], [64720.4, 0.521], [64720.7, 0.072], [64721.6, 0.002], [64721.9, 0.25], [64722.1, 0.007], [64722.2, 0.524], [64722.4, 1.953], [64726.1, 0.371], [64727.1, 0.013], [64731.3, 0.169], [64731.5, 0.558], [64731.8, 0.005], [64732.4, 0.002], [64733.8, 0.162], [64734.1, 0.003], [64734.5, 0.155], [64735.6, 0.118], [64737.4, 0.02], [64741.7, 10.154], [64741.8, 0.0], [64781.1, 0.311], [64785.5, 38.322], [64869.6, 10.406], [64908.5, 15.721], [65359.4, 5.523], [65650.6, 27.665], [65712.3, 0.007], [66006.5, 0.024]]}
{"kind": "depth", "E": 1787080141551, "U": 11315332238436, "u": 11315332246868, "recv_ms": 1787080141491, "bids": [[1000.0, 35.81], [14212.2, 3.458], [14312.2, 0.014], [14612.2, 0.728], [58240.9, 0.053], [61476.5, 0.0], [62123.7, 0.692], [63902.9, 1.876], [64065.1, 9.906], [64107.3, 3.471], [64615.1, 2.344], [64695.2, 0.001], [64697.1, 0.962], [64698.4, 0.139], [64701.1, 1.245], [64704.0, 1.354], [64704.1, 0.127], [64705.0, 0.074], [64706.2, 0.547], [64708.1, 0.004], [64708.4, 0.001], [64709.5, 0.003], [64711.2, 0.335], [64712.2, 8.978]], "asks": [[64712.3, 14.035], [64713.2, 0.002], [64713.6, 0.002], [64714.1, 0.0], [64714.4, 2.762], [64716.7, 0.086], [64716.9, 0.015], [64717.0, 0.152], [64717.2, 0.1], [64717.3, 0.704], [64717.9, 0.064], [64718.0, 1.393], [64718.5, 0.003], [64719.5, 0.001], [64719.6, 0.035], [64719.7, 0.035], [64719.9, 0.604], [64720.0, 0.197], [64722.2, 0.059], [64723.8, 0.006], [64724.1, 0.023], [64726.1, 0.216], [64727.1, 0.013], [64741.7, 10.0], [64741.8, 0.154], [64743.4, 0.016], [64781.1, 0.311], [64784.8, 0.019], [64785.5, 0.029], [64787.7, 38.517], [65359.4, 5.521], [65359.5, 0.0], [65529.7, 1.552]]}
{"kind": "depth", "E": 1787080141653, "U": 11315332247011, "u": 11315332255620, "recv_ms": 1787080141594, "bids": [[14212.2, 3.136], [14312.2, 0.0], [14612.2, 1.064], [58240.9, 0.053], [58241.0, 0.01], [61476.5, 0.0], [62123.7, 0.689], [63496.0, 6.607], [63741.5, 17.661], [63753.0, 1.962], [63902.9, 0.0], [63942.1, 9.383], [64065.1, 9.906], [64388.6, 5.879], [64642.7, 0.146], [64644.9, 33.148], [64680.1, 0.077], [64680.8, 0.0], [64690.8, 0.558], [64691.0, 0.987], [64695.3, 0.002], [64696.2, 0.005], [64697.1, 0.962], [64701.4, 0.464], [64706.0, 0.012], [64707.1, 0.379], [64712.1, 0.021], [64712.2, 7.928]], "asks": [[64717.2, 0.641], [64717.3, 0.163], [64719.9, 0.604], [64720.0, 0.197], [64722.1, 0.008], [64722.2, 0.059], [64726.1, 0.216], [64727.1, 0.013], [64728.7, 1.343], [64729.4, 2.763], [64731.1, 1.329], [64732.7, 1.624], [64782.2, 0.009], [64783.3, 38.293], [64787.4, 0.177], [64787.7, 0.224], [64869.6, 10.406], [64908.5, 15.721], [65359.4, 5.521], [65521.2, 12.109], [65844.8, 4.855], [67947.9, 0.063]]}
{"kind": "depth", "E": 1787080141857, "U": 11315332264413, "u": 11315332272731, "recv_ms": 1787080141802, "bids": [[1000.0, 35.81], [14212.2, 2.408], [14612.2, 1.792], [51770.0, 0.0], [58240.9, 0.053], [61476.5, 0.0], [62123.7, 0.692], [63418.0, 4.9], [63482.7, 2.202], [63709.2, 12.944], [63801.6, 0.056], [63806.2, 36.886], [63870.9, 15.637], [64065.1, 9.906], [64388.6, 5.878], [64571.6, 2.577], [64706.3, 0.003], [64707.3, 0.17], [64712.2, 7.971]], "asks": [[64713.4, 0.086], [64717.1, 0.558], [64717.2, 0.1], [64717.3, 0.163], [64719.8, 0.094], [64719.9, 0.133], [64720.0, 0.197], [64722.2, 0.067], [64726.1, 0.216], [64727.1, 0.476], [64852.6, 5.398], [65650.6, 27.666], [65715.3, 7.051], [65747.7, 4.252], [66132.5, 0.286]]}
{"kind": "depth", "E": 1787080141959, "U": 11315332272740, "u": 11315332282149, "recv_ms": 1787080141899, "bids": [[14212.2, 2.058], [14612.2, 2.142], [58240.9, 0.053], [61476.5, 0.0], [62123.7, 0.689], [63418.0, 4.897], [63712.2, 7.683], [63787.3, 2.192], [63838.2, 0.808], [63870.9, 17.513], [63911.6, 3.379], [64013.8, 0.0], [64065.1, 9.906], [64388.6, 5.878], [64679.6, 0.166], [64697.1, 0.962], [64706.3, 0.197], [64709.9, 0.016], [64712.2, 7.927]], "asks": [[64713.2, 0.0], [64717.1, 0.558], [64717.2, 0.0], [64717.3, 0.263], [64718.3, 0.047], [64718.4, 0.004], [64718.6, 0.387], [64720.0, 0.197], [64722.1, 0.008], [64722.2, 0.067], [64726.1, 0.216], [64727.1, 0.476], [64778.0, 0.026], [65035.9, 3.997], [65359.4, 5.521], [65694.9, 3.8], [65695.1, 0.695], [65712.3, 0.007], [65715.3, 5.987]]}
{"kind": "depth", "E": 1787080142061, "U": 11315332282684, "u": 11315332291619, "recv_ms": 1787080142001, "bids": [[1000.0, 35.81], [14212.2, 1.708], [14612.2, 2.492], [58240.9, 0.053], [61476.5, 0.0], [62123.7, 0.692], [62123.8, 0.009], [63560.7, 5.068], [63709.2, 14.04], [63712.2, 7.703], [63725.1, 0.052], [63806.2, 37.825], [64029.7, 0.315], [64065.1, 9.906], [64097.4, 14.432], [64646.3, 7.698], [64680.0, 3.101], [64680.1, 0.02], [64680.8, 0.0], [64696.1, 0.948], [64696.4, 0.01], [64697.0, 0.917], [64697.1, 0.962], [64699.7, 0.023], [64700.6, 0.245], [64706.2, 0.547], [64706.3, 0.003], [64707.3, 0.171], [64708.7, 0.183], [64710.0, 0.01], [64710.5, 0.086], [64712.2, 7.946]], "asks": [[64712.9, 0.0], [64713.0, 0.084], [64713.5, 1.014], [64713.6, 0.039], [64714.4, 2.761], [64714.5, 0.007], [64717.1, 0.017], [64717.3, 0.804], [64719.8, 0.094], [64719.9, 0.133], [64720.0, 0.197], [64722.2, 0.059], [64726.1, 0.216], [64727.1, 0.484], [64728.6, 1.73], [64728.7, 0.418], [64729.5, 0.005], [64731.5, 0.002], [64731.9, 0.708], [64732.7, 1.567], [64734.3, 0.551], [64734.8, 0.01], [64735.6, 0.003], [64735.9, 0.0], [64736.3, 0.296], [64739.2, 4.674], [64743.4, 0.002], [64783.2, 6.457], [64869.6, 6.347], [64908.5, 15.721], [65359.4, 5.521], [65529.7, 1.324], [65611.8, 11.359], [65650.6, 28.73], [65699.2, 0.039], [65712.3, 0.027], [65715.3, 7.05], [65747.7, 5.315], [67947.9, 0.058], [71183.6, 0.0]]}
{"kind": "depth", "E": 1787080142163, "U": 11315332291744, "u": 11315332305209, "recv_ms": 1787080142105, "bids": [[1000.0, 35.81], [14212.2, 1.358], [14612.2, 2.842], [51769.8, 0.0], [51770.0, 0.0], [58240.9, 0.053], [61476.5, 0.0], [63725.1, 0.035], [63725.3, 0.025], [63773.4, 0.001], [63773.9, 42.897], [63789.9, 0.013], [63790.0, 0.161], [63791.6, 0.018], [64065.1, 9.906], [64388.6, 5.877], [64633.3, 0.164], [64640.7, 0.21], [64679.9, 0.099], [64680.0, 3.044], [64680.8, 0.0], [64684.3, 0.31], [64685.4, 2.33], [64691.0, 0.989], [64691.2, 0.011], [64695.6, 0.62], [64696.0, 2.209], [64696.1, 0.023], [64696.9, 0.312], [64697.1, 0.96], [64701.8, 0.081], [64703.0, 0.003], [64704.0, 1.331], [64704.1, 0.281], [64704.4, 0.276], [64705.0, 0.074], [64705.5, 0.01], [64706.0, 0.094], [64706.3, 0.087], [64707.1, 0.61], [64707.3, 0.04], [64708.1, 0.004], [64708.2, 0.107], [64708.6, 0.109], [64708.7, 0.103], [64709.4, 1.933], [64709.8, 0.004], [64710.1, 0.001], [64710.5, 0.002], [64711.4, 0.002], [64711.7, 0.07], [64711.9, 0.019], [64712.0, 0.037], [64712.1, 0.016], [64712.2, 7.889]], "asks": [[64712.3, 14.036], [64712.4, 0.063], [64712.5, 0.084], [64712.8, 0.084], [64713.0, 0.0], [64714.0, 0.004], [64714.1, 0.003], [64714.3, 0.659], [64714.5, 0.006], [64716.7, 0.002], [64717.0, 0.152], [64717.1, 0.017], [64717.2, 0.101], [64717.3, 0.626], [64718.6, 0.345], [64719.7, 0.034], [64719.9, 0.133], [64720.0, 0.197], [64721.0, 0.005], [64722.1, 0.008], [64722.2, 0.059], [64726.1, 0.216], [64726.6, 1.096], [64727.1, 0.013], [64728.4, 2.797], [64728.6, 0.805], [64729.4, 2.763], [64729.8, 0.004], [64730.6, 0.38], [64731.7, 0.904], [64731.9, 0.651], [64732.7, 1.567], [64734.0, 0.917], [64734.1, 0.544], [64734.3, 0.01], [64735.9, 0.0], [65359.4, 5.521], [65632.8, 0.0], [65634.5, 0.002], [65699.2, 0.022]]}
{"kind": "depth", "E": 1787080142265, "U": 11315332305380, "u": 11315332312717, "recv_ms": 1787080142205, "bids": [[14212.2, 0.994], [14612.2, 3.206], [34000.0, 1.146], [51770.0, 0.002], [58240.9, 0.053], [61476.5, 0.0], [61476.6, 0.008], [61476.7, 0.01], [62123.7, 0.689], [63787.3, 1.096], [63795.2, 0.79], [64065.1, 9.906], [64388.6, 5.887], [64619.6, 0.005], [64619.7, 0.256], [64689.0, 0.059], [64697.0, 0.017], [64700.0, 1.474], [64704.0, 0.79], [64704.4, 0.275], [64705.0, 0.074], [64705.5, 0.008], [64706.0, 0.096], [64706.3, 0.281], [64707.1, 0.379], [64707.3, 0.04], [64707.4, 0.555], [64707.6, 0.233], [64708.6, 0.025], [64709.0, 0.003], [64709.4, 1.849], [64711.0, 0.023], [64711.1, 0.019], [64711.2, 0.256], [64711.7, 0.107], [64711.9, 0.0], [64712.0, 0.032], [64712.2, 7.655]], "asks": [[64712.3, 14.05], [64712.5, 0.085], [64716.9, 0.015], [64717.0, 1.052], [64717.2, 0.0], [64717.3, 0.163], [64717.6, 0.079], [64717.9, 0.002], [64718.0, 0.493], [64718.7, 0.401], [64718.8, 0.022], [64719.8, 0.094], [64719.9, 0.697], [64720.0, 0.197], [64722.1, 0.008], [64722.2, 0.059], [64726.1, 0.216], [64726.5, 0.147], [64737.4, 10.02], [64739.2, 3.414], [64741.7, 0.0], [64761.5, 0.076], [64777.1, 0.005], [64783.2, 0.376], [64783.3, 0.0], [64787.7, 38.517], [64800.6, 0.0], [65035.9, 3.998], [65359.4, 5.521], [65632.9, 0.008], [65634.6, 0.022], [65683.0, 8.662], [65699.3, 1.327], [65715.3, 8.114], [65906.8, 0.761], [66006.5, 0.027], [66653.5, 0.004]]}
{"kind": "depth", "E": 1787080142367, "U": 11315332313026, "u": 11315332337603, "recv_ms": 1787080142312, "bids": [[1000.0, 35.81], [14212.2, 0.63], [14612.2, 3.57], [51770.0, 0.0], [58240.9, 0.053], [61476.5, 0.0], [62123.7, 0.706], [63547.4, 4.941], [63601.0, 3.737], [63624.4, 0.003], [63712.2, 7.683], [64019.8, 1.792], [64065.1, 9.906], [64636.1, 0.0], [64637.1, 0.009], [64642.7, 33.299], [64644.9, 0.004], [64646.3, 2.638], [64653.9, 0.018], [64658.0, 0.233], [64664.7, 0.0], [64666.9, 0.722], [64668.5, 0.185], [64670.7, 0.179], [64673.3, 0.083], [64674.6, 0.001], [64679.7, 0.13], [64679.8, 0.002], [64679.9, 0.042], [64680.0, 3.044], [64681.2, 1.812], [64681.6, 0.029], [64682.1, 0.018], [64683.1, 0.352], [64684.0, 0.008], [64684.3, 0.31], [64685.0, 0.013], [64687.6, 0.204], [64688.1, 0.106], [64690.0, 0.307], [64690.2, 0.001], [64690.4, 0.56], [64690.7, 0.16], [64690.8, 0.002], [64690.9, 0.014], [64691.0, 0.987], [64692.0, 0.394], [64692.2, 0.146], [64692.8, 1.473], [64692.9, 0.624], [64693.6, 0.173], [64694.1, 0.173], [64694.2, 0.239], [64694.6, 0.003], [64694.9, 0.466], [64695.0, 0.904], [64695.2, 0.472], [64695.3, 0.002], [64695.6, 0.002], [64695.8, 0.927], [64696.0, 1.284], [64696.9, 0.31], [64698.0, 0.126], [64700.0, 1.474], [64701.2, 0.027], [64701.4, 0.773], [64702.3, 1.044], [64702.4, 0.005], [64702.5, 0.004], [64702.9, 0.004], [64703.7, 0.993], [64703.9, 0.723], [64704.0, 0.167], [64704.1, 0.003], [64704.2, 0.143], [64704.3, 0.131], [64704.5, 0.154], [64704.9, 0.352], [64705.0, 0.09], [64705.1, 0.142], [64705.2, 2.005], [64705.3, 0.627], [64705.6, 0.102], [64706.0, 0.094], [64706.2, 0.949], [64706.3, 0.087], [64706.9, 0.233], [64707.1, 0.069], [64707.3, 1.709], [64707.4, 0.138], [64707.5, 0.001], [64707.6, 0.002], [64707.7, 0.008], [64707.9, 0.092], [64708.2, 0.016], [64708.7, 0.103], [64709.3, 0.006], [64710.0, 0.01], [64711.6, 0.0], [64712.1, 0.016], [64712.2, 7.019]], "asks": [[64712.3, 14.438], [64712.4, 0.063], [64713.5, 1.324], [64713.6, 0.003], [64714.0, 0.003], [64714.1, 0.013], [64714.3, 0.656], [64714.5, 0.006], [64715.0, 0.103], [64715.4, 0.141], [64716.8, 0.037], [64716.9, 0.17], [64717.4, 1.002], [64717.6, 0.017], [64718.0, 0.506], [64718.3, 0.034], [64719.3, 0.622], [64719.8, 0.094], [64719.9, 0.133], [64720.0, 0.507], [64720.4, 0.212], [64721.0, 0.004], [64721.9, 0.56], [64722.1, 0.572], [64722.2, 0.059], [64722.4, 1.953], [64722.9, 0.007], [64724.1, 0.016], [64725.0, 0.005], [64726.0, 0.157], [64726.1, 0.216], [64726.4, 0.175], [64726.6, 0.478], [64727.2, 3.083], [64727.3, 0.531], [64727.5, 0.002], [64728.3, 1.177], [64728.4, 1.872], [64728.9, 10.164], [64729.1, 0.013], [64729.4, 2.763], [64729.8, 0.002], [64729.9, 0.004], [64730.0, 0.5], [64730.8, 0.58], [64731.7, 0.847], [64731.8, 0.062], [64731.9, 0.095], [64732.8, 2.269], [64732.9, 0.189], [64733.2, 0.009], [64733.4, 2.323], [64733.5, 0.003], [64733.8, 0.001], [64734.0, 0.299], [64734.1, 0.003], [64734.3, 0.551], [64734.5, 0.154], [64735.0, 0.004], [64735.1, 0.116], [64736.3, 0.181], [64737.4, 0.02], [64739.3, 0.162], [64740.0, 0.487], [64740.3, 0.025], [64757.6, 0.003], [64761.8, 0.233], [64770.6, 0.378], [64774.5, 0.002], [64783.3, 0.0], [64785.5, 38.164], [64787.4, 0.195], [64787.7, 0.224], [64822.4, 0.014], [64869.6, 6.382], [64908.5, 11.823], [65359.4, 5.521], [65488.8, 49.517], [65712.3, 0.007], [66006.5, 0.024]]}
{"kind": "depth", "E": 1787080142469, "U": 11315332337927, "u": 11315332346418, "recv_ms": 1787080142410, "bids": [[1000.0, 35.81], [14212.2, 0.35], [14512.2, 0.084], [14612.2, 3.766], [58240.9, 0.053], [61476.5, 0.0], [61476.7, 0.008], [62123.7, 0.689], [63431.3, 3.204], [63496.0, 4.405], [63560.7, 2.868], [63625.5, 4.716], [63741.5, 22.361], [63773.9, 43.993], [63944.0, 10.69], [64065.1, 9.906], [64637.1, 0.0], [64670.7, 0.165], [64678.4, 0.344], [64705.1, 0.14], [64705.3, 0.079], [64706.1, 0.399], [64707.3, 2.257], [64708.3, 0.18], [64712.2, 6.929]], "asks": [[64713.5, 1.014], [64714.1, 0.01], [64714.2, 0.541], [64714.3, 0.108], [64716.9, 0.026], [64719.9, 0.697], [64720.0, 0.197], [64721.9, 0.25], [64722.1, 0.008], [64722.2, 0.059], [64726.0, 0.002], [64726.1, 0.216], [64729.9, 0.002], [64730.2, 0.003], [64735.1, 0.001], [64735.4, 0.497], [64761.8, 0.023], [64768.8, 0.464], [64783.3, 38.135], [64785.5, 0.029], [64787.4, 0.177], [64869.6, 10.406], [64908.5, 15.721], [65359.4, 5.521], [65906.8, 0.003]]}
{"kind": "depth", "E": 1787080142571, "U": 11315332346464, "u": 11315332351858, "recv_ms": 1787080142512, "bids": [[14212.2, 0.224], [14512.2, 0.308], [14612.2, 3.668], [58240.9, 0.053], [61476.5, 0.0], [62123.7, 0.692], [63418.0, 7.104], [63496.0, 2.203], [63625.0, 3.207], [63712.2, 7.703], [63773.9, 42.897], [64065.1, 9.906], [64388.6, 5.887], [64695.2, 0.472], [64698.7, 0.168], [64704.0, 0.175], [64704.1, 0.003], [64704.5, 0.07], [64705.0, 0.159], [64705.2, 0.167], [64705.3, 0.002], [64706.1, 0.397], [64706.2, 0.547], [64707.1, 0.071], [64707.3, 2.257], [64707.4, 0.332], [64708.9, 0.085], [64709.3, 0.004], [64711.6, 0.002], [64712.2, 7.74]], "asks": [[64712.3, 14.436], [64713.2, 0.002], [64714.1, 0.0], [64714.2, 0.0], [64714.3, 0.085], [64716.9, 0.026], [64717.0, 0.152], [64719.3, 0.313], [64719.7, 1.061], [64719.8, 0.403], [64719.9, 0.234], [64720.0, 0.197], [64721.9, 0.25], [64722.1, 0.008], [64722.2, 0.059], [64722.9, 0.0], [64723.5, 0.007], [64726.0, 0.002], [64726.1, 0.216], [64727.2, 1.852], [64727.5, 0.322], [64727.6, 0.002], [64728.9, 0.164], [64730.8, 0.024], [64731.1, 1.885], [64734.3, 0.01], [64734.8, 0.551], [64736.1, 10.039], [65359.4, 5.521], [65533.1, 0.57], [65650.6, 27.665], [65712.3, 0.027]]}
{"kind": "depth", "E": 1787080142673, "U": 11315332351916, "u": 11315332357529, "recv_ms": 1787080142613, "bids": [[1000.0, 35.81], [14212.2, 0.112], [14512.2, 0.546], [14612.2, 3.542], [58240.9, 0.053], [63605.0, 0.082], [63625.5, 3.146], [64065.1, 9.906], [64668.5, 0.031], [64695.2, 0.464], [64696.2, 0.005], [64704.0, 0.268], [64705.0, 0.074], [64707.4, 0.332], [64712.2, 7.739]], "asks": [[64712.3, 14.435], [64712.4, 0.054], [64714.2, 0.0], [64714.3, 0.101], [64717.2, 0.0], [64717.3, 0.163], [64718.0, 1.406], [64719.5, 0.001], [64719.6, 0.035], [64719.7, 0.034], [64719.9, 0.133], [64720.0, 0.197], [64722.1, 0.008], [64722.2, 0.708], [64726.0, 0.002], [64726.1, 0.679], [64728.7, 0.418], [64741.8, 0.0], [64910.8, 0.003], [64910.9, 0.025], [65359.4, 5.521], [67947.9, 0.053]]}
{"kind": "depth", "E": 1787080142775, "U": 11315332357688, "u": 11315332365061, "recv_ms": 1787080142719, "bids": [[1000.0, 35.81], [14212.2, 0.0], [14512.2, 0.798], [14612.2, 3.402], [58240.9, 0.053], [61476.5, 0.0], [62123.7, 0.689], [63482.7, 6.607], [63496.0, 0.001], [63547.4, 7.141], [63612.1, 10.829], [63712.2, 7.683], [63773.9, 43.993], [63874.4, 4.695], [63981.5, 0.001], [64065.1, 9.906], [64168.6, 0.283], [64554.6, 3.917], [64571.6, 3.106], [64582.7, 0.003], [64707.4, 0.332], [64707.5, 0.195], [64709.0, 0.157], [64712.2, 7.784]], "asks": [[64714.2, 0.541], [64714.3, 0.108], [64717.2, 0.093], [64717.3, 0.163], [64720.0, 0.197], [64722.1, 0.471], [64722.2, 0.067], [64726.0, 0.002], [64726.1, 0.216], [64732.8, 7.269], [64741.4, 0.564], [64741.5, 0.027], [64741.7, 0.154], [64852.6, 5.398], [64868.5, 0.753], [64869.6, 10.406], [65228.9, 0.293], [65359.4, 5.521], [65436.0, 3.086], [65453.7, 3.817], [65565.6, 1.449], [65712.3, 0.007]]}
{"kind": "depth", "E": 1787080142877, "U": 11315332365171, "u": 11315332374409, "recv_ms": 1787080142819, "bids": [[14512.2, 1.148], [14612.2, 3.052], [58240.9, 0.053], [61476.5, 0.001], [62123.7, 0.692], [63418.0, 7.101], [63712.2, 7.703], [63754.9, 0.0], [63870.9, 20.64], [63874.4, 3.913], [63949.1, 3.124], [64065.1, 9.906], [64388.6, 5.877], [64673.3, 0.069], [64704.9, 0.268], [64706.9, 0.002], [64707.3, 2.249], [64707.4, 0.377], [64707.5, 0.001], [64707.6, 0.002], [64709.6, 0.086], [64712.2, 7.707]], "asks": [[64712.3, 14.427], [64714.2, 0.0], [64714.3, 0.085], [64717.2, 0.0], [64717.3, 0.434], [64719.9, 0.133], [64720.0, 0.352], [64721.9, 0.405], [64722.1, 0.781], [64722.2, 0.608], [64726.0, 0.157], [64726.1, 0.216], [64726.4, 0.168], [64727.2, 1.859], [64740.8, 1.293], [64761.5, 0.118], [64868.5, 2.203], [65035.9, 3.997], [65217.1, 4.592], [65359.4, 5.521], [65565.6, 1.144], [65650.6, 28.73], [65712.3, 0.027]]}
{"kind": "depth", "E": 1787080142979, "U": 11315332374453, "u": 11315332381887, "recv_ms": 1787080142920, "bids": [[1000.0, 35.81], [14512.2, 1.512], [14612.2, 2.688], [58240.9, 0.053], [61476.5, 0.0], [62123.7, 0.689], [63418.0, 7.104], [63482.7, 8.81], [63551.5, 2.019], [63612.1, 12.399], [64065.1, 9.906], [64388.6, 5.878], [64690.1, 0.004], [64690.4, 0.004], [64690.8, 0.558], [64691.8, 0.001], [64692.7, 0.019], [64692.9, 0.617], [64693.5, 2.341], [64695.8, 0.002], [64696.3, 1.166], [64697.1, 0.96], [64706.8, 0.006], [64707.4, 0.377], [64707.5, 0.001], [64712.2, 7.78]], "asks": [[64714.2, 0.0], [64714.3, 0.659], [64717.2, 0.093], [64717.3, 0.163], [64719.9, 0.604], [64720.0, 0.197], [64721.9, 0.25], [64722.1, 0.008], [64722.2, 0.059], [64726.0, 0.002], [64726.1, 0.216], [64727.1, 0.013], [64728.3, 0.252], [64728.8, 0.606], [64729.6, 0.938], [64730.4, 0.599], [64731.1, 1.329], [64731.5, 0.558], [64733.2, 0.002], [64733.8, 0.008], [64734.7, 0.765], [64734.8, 0.01], [64735.4, 0.382], [64735.9, 0.0], [64736.4, 0.126], [65359.4, 5.521], [65553.6, 47.108]]}
{"kind": "depth", "E": 1787080143081, "U": 11315332381966, "u": 11315332389423, "recv_ms": 1787080143023, "bids": [[1000.0, 35.81], [14512.2, 1.862], [14612.2, 2.338], [58240.9, 0.053], [61476.5, 0.0], [61476.6, 0.006], [61476.7, 0.01], [62123.7, 0.692], [63690.2, 3.136], [63712.2, 7.683], [63968.0, 11.578], [64065.1, 9.908], [64262.3, 0.002], [64571.7, 1.194], [64642.9, 7.785], [64657.8, 0.002], [64682.2, 2.657], [64700.6, 0.245], [64705.2, 0.083], [64707.3, 2.562], [64707.4, 0.377], [64707.5, 0.195], [64710.4, 0.093], [64712.2, 7.781]], "asks": [[64712.3, 14.115], [64712.5, 0.001], [64714.0, 0.013], [64714.1, 0.0], [64714.2, 0.0], [64714.3, 0.085], [64717.2, 0.0], [64717.3, 0.326], [64719.9, 0.133], [64720.0, 0.352], [64720.6, 1.705], [64721.9, 0.405], [64722.1, 0.326], [64722.2, 0.708], [64723.2, 2.535], [64725.9, 0.158], [64726.0, 2.321], [64726.1, 0.679], [64728.7, 1.343], [64729.6, 0.013], [64735.6, 0.017], [64736.0, 3.278], [64740.8, 1.279], [64758.9, 0.014], [64761.5, 0.076], [64783.2, 6.434], [65359.4, 5.521], [65424.1, 7.681], [65488.8, 49.73], [65553.6, 47.413], [65626.8, 6.881], [65647.9, 0.0], [65673.7, 3.347], [65712.3, 0.007]]}
{"kind": "depth", "E": 1787080143183, "U": 11315332389576, "u": 11315332397729, "recv_ms": 1787080143125, "bids": [[14512.2, 2.226], [14612.2, 1.974], [51769.8, 0.0], [58240.9, 0.053], [61476.5, 0.0], [63418.0, 7.101], [63690.2, 1.568], [63741.5, 23.928], [64065.1, 9.906], [64259.2, 0.305], [64388.6, 5.878], [64571.6, 0.0], [64571.7, 0.838], [64640.7, 0.211], [64657.8, 0.03], [64663.8, 1.255], [64678.4, 0.008], [64679.8, 0.005], [64695.2, 0.001], [64695.3, 0.62], [64701.4, 0.774], [64702.7, 0.464], [64704.0, 0.26], [64704.1, 0.474], [64707.3, 2.559], [64707.4, 0.377], [64707.5, 0.001], [64710.4, 0.009], [64710.7, 0.013], [64712.2, 7.748]], "asks": [[64712.3, 14.305], [64712.4, 0.052], [64712.5, 0.002], [64713.6, 0.003], [64713.8, 0.002], [64714.0, 0.013], [64714.2, 0.0], [64714.3, 0.085], [64717.2, 0.0], [64717.3, 0.171], [64718.0, 1.406], [64720.0, 0.197], [64721.9, 0.25], [64722.1, 0.016], [64722.2, 0.708], [64725.9, 0.003], [64726.3, 0.781], [64733.7, 0.771], [64735.6, 0.003], [64741.2, 0.248], [64741.3, 1.323], [64741.4, 0.562], [64744.2, 0.0], [64744.3, 0.002], [64744.4, 0.124], [64745.0, 2.957], [64745.1, 1.01], [64745.2, 0.004], [64747.2, 1.396], [64747.3, 0.061], [64747.4, 0.006], [64822.4, 0.017], [64850.0, 29.478], [64852.6, 0.001], [65035.9, 3.996], [65359.4, 5.521], [65600.0, 70.635], [65663.6, 7.98]]}
{"kind": "depth", "E": 1787080143285, "U": 11315332397766, "u": 11315332403639, "recv_ms": 1787080143226, "bids": [[1000.0, 35.81], [14512.2, 2.576], [14612.2, 1.624], [58240.9, 0.053], [61476.5, 0.0], [61476.6, 0.004], [61476.7, 0.012], [62123.7, 0.689], [63676.8, 7.5], [63690.2, 0.0], [64065.1, 9.906], [64142.9, 0.0], [64388.6, 5.879], [64554.6, 2.894], [64571.6, 2.592], [64703.8, 1.596], [64704.9, 0.271], [64707.4, 0.571], [64707.5, 0.195], [64712.2, 7.705]], "asks": [[64712.4, 0.061], [64714.3, 0.649], [64716.3, 0.09], [64717.2, 0.0], [64717.3, 0.163], [64720.0, 0.197], [64721.9, 0.25], [64722.1, 0.101], [64722.2, 0.067], [64725.8, 0.002], [64725.9, 0.003], [64783.2, 0.376], [64783.3, 0.0], [64785.5, 37.924], [64789.9, 0.004], [64852.6, 5.398], [64869.6, 10.406], [65359.4, 5.521], [65488.8, 49.121], [65521.2, 12.337]]}
{"kind": "depth", "E": 1787080143387, "U": 11315332403690, "u": 11315332412261, "recv_ms": 1787080143328, "bids": [[1000.0, 35.81], [14512.2, 2.94], [14612.2, 1.26], [58240.9, 0.053], [61476.6, 0.002], [61476.7, 0.012], [62123.7, 0.692], [62123.8, 0.008], [63625.5, 1.576], [63712.2, 7.703], [63999.3, 0.005], [64065.1, 9.906], [64571.6, 3.106], [64699.2, 0.012], [64699.7, 0.177], [64700.1, 0.021], [64700.2, 0.051], [64707.4, 0.377], [64707.5, 0.389], [64709.6, 0.002], [64712.2, 7.66]], "asks": [[64714.3, 0.093], [64717.2, 0.0], [64717.3, 0.163], [64720.0, 0.197], [64721.9, 0.25], [64722.1, 0.008], [64722.2, 0.716], [64725.1, 0.239], [64725.9, 0.003], [64784.8, 0.028], [64805.6, 0.154], [64852.6, 5.398], [65359.4, 5.521], [65712.3, 0.027]]}
{"kind": "depth", "E": 1787080143489, "U": 11315332412374, "u": 11315332418457, "recv_ms": 1787080143430, "bids": [[14512.2, 3.29], [14612.2, 0.91], [58240.9, 0.053], [61476.5, 0.0], [62123.7, 0.689], [63676.8, 10.638], [63793.3, 2.814], [63998.8, 0.002], [64065.1, 9.906], [64388.6, 5.879], [64515.7, 0.0], [64515.8, 7.181], [64518.1, 1.279], [64554.6, 3.907], [64571.6, 2.768], [64707.5, 0.001], [64709.2, 0.103], [64712.2, 7.76]], "asks": [[64714.3, 0.101], [64717.2, 0.0], [64717.3, 0.163], [64720.0, 0.197], [64721.8, 0.552], [64721.9, 0.806], [64722.1, 0.008], [64722.2, 0.067], [64725.9, 0.003], [64726.1, 0.216], [64741.6, 0.159], [64741.7, 0.0], [64852.6, 5.398], [64868.5, 0.753], [64869.6, 8.805], [64908.4, 15.406], [64908.5, 0.315], [65359.4, 5.521], [66344.0, 0.232], [67947.9, 0.058]]}
{"kind": "depth", "E": 1787080143591, "U": 11315332418714, "u": 11315332424842, "recv_ms": 1787080143532, "bids": [[1000.0, 35.81], [14512.2, 3.654], [14612.2, 0.546], [58240.9, 0.053], [61476.5, 0.0], [63625.5, 0.006], [63644.4, 1.808], [63712.2, 7.683], [63751.5, 0.0], [63773.9, 42.897], [63793.3, 3.048], [63999.6, 0.874], [64065.1, 9.906], [64168.6, 0.218], [64571.6, 2.241], [64679.3, 2.33], [64679.4, 0.011], [64679.5, 2.854], [64679.8, 0.005], [64682.7, 0.003], [64682.8, 0.018], [64682.9, 1.311], [64690.1, 0.56], [64690.8, 0.002], [64692.7, 0.012], [64693.5, 2.348], [64695.5, 0.926], [64696.3, 0.241], [64699.4, 0.403], [64699.7, 0.023], [64702.8, 0.249], [64702.9, 0.128], [64704.0, 0.183], [64705.0, 0.692], [64706.0, 0.096], [64707.1, 0.069], [64707.2, 0.402], [64707.3, 2.018], [64707.5, 0.001], [64709.8, 0.088], [64712.2, 7.869]], "asks": [[64714.0, 0.003], [64714.3, 0.101], [64717.0, 0.307], [64717.1, 0.017], [64717.2, 0.0], [64717.3, 0.163], [64719.7, 0.034], [64719.9, 0.133], [64720.0, 0.352], [64721.7, 0.002], [64721.8, 0.004], [64721.9, 0.25], [64722.1, 1.114], [64722.2, 0.53], [64725.9, 0.158], [64728.0, 1.049], [64728.7, 0.418], [64730.4, 1.155], [64731.5, 0.002], [64734.1, 0.544], [64734.7, 0.224], [64735.5, 0.147], [64736.4, 0.011], [64757.6, 0.003], [64811.4, 0.448], [64811.5, 0.038], [64822.4, 0.014], [64852.6, 5.398], [65359.4, 5.521], [65488.8, 49.73], [65595.4, 5.018], [65712.3, 0.007]]}
{"kind": "depth", "E": 1787080143693, "U": 11315332424884, "u": 11315332430129, "recv_ms": 1787080143633, "bids": [[14412.2, 0.14], [14512.2, 3.738], [14612.2, 0.322], [58240.9, 0.053], [61476.5, 0.0], [61476.7, 0.01], [62123.7, 0.692], [63431.3, 1.0], [63612.1, 13.969], [63712.2, 7.703], [63770.8, 3.054], [63814.5, 9.718], [64000.4, 11.307], [64065.1, 9.906], [64582.7, 0.003], [64693.0, 0.009], [64693.5, 2.341], [64695.5, 0.001], [64696.2, 0.003], [64696.4, 0.935], [64703.9, 0.022], [64705.0, 0.151], [64705.1, 1.245], [64705.5, 0.008], [64705.6, 0.018], [64706.0, 0.096], [64706.7, 0.12], [64707.3, 2.003], [64707.4, 0.369], [64707.6, 0.002], [64707.9, 0.085], [64708.8, 0.01], [64710.4, 0.093], [64711.6, 0.021], [64711.7, 0.417], [64712.2, 7.814]], "asks": [[64712.3, 14.222], [64712.4, 0.061], [64712.8, 0.0], [64713.6, 0.001], [64714.0, 0.004], [64714.3, 0.101], [64714.5, 0.006], [64716.8, 0.036], [64717.0, 0.152], [64717.1, 0.017], [64717.2, 0.641], [64717.3, 0.163], [64719.8, 0.094], [64720.0, 0.196], [64720.4, 0.521], [64721.8, 0.012], [64721.9, 0.25], [64722.1, 0.008], [64722.2, 0.522], [64722.4, 1.953], [64723.5, 0.0], [64723.9, 0.018], [64725.6, 0.136], [64725.9, 0.003], [64726.3, 0.163], [64728.0, 0.124], [64728.7, 0.416], [64728.9, 1.089], [64730.3, 0.037], [64730.4, 0.599], [64731.5, 0.558], [64732.9, 0.19], [64733.5, 0.002], [64734.1, 0.003], [64734.8, 0.551], [64736.0, 1.603], [64736.1, 0.039], [64739.6, 10.015], [64869.6, 10.406], [65359.4, 5.523], [65529.7, 1.096], [65567.9, 0.771], [65712.3, 0.027], [65780.1, 1.264], [66115.7, 0.647], [67947.9, 0.053]]}
{"kind": "depth", "E": 1787080143795, "U": 11315332430152, "u": 11315332435777, "recv_ms": 1787080143736, "bids": [[14412.2, 0.364], [14512.2, 3.64], [14612.2, 0.196], [58240.9, 0.053], [61476.5, 0.001], [62123.7, 0.689], [63560.6, 4.19], [63773.9, 43.993], [63903.3, 12.133], [63999.7, 0.875], [64065.1, 9.906], [64168.6, 0.28], [64388.6, 5.889], [64696.2, 0.005], [64712.2, 7.767]], "asks": [[64712.3, 14.221], [64713.6, 0.002], [64714.3, 0.093], [64716.8, 0.037], [64717.2, 0.0], [64717.3, 0.318], [64720.0, 0.352], [64721.9, 0.723], [64722.1, 0.649], [64725.9, 0.158], [64728.7, 0.418], [64761.5, 0.104], [65359.4, 5.521], [65521.2, 12.565], [65780.1, 2.327]]}
{"kind": "depth", "E": 1787080143897, "U": 11315332435870, "u": 11315332441652, "recv_ms": 1787080143837, "bids": [[1000.0, 35.81], [14412.2, 0.616], [14512.2, 3.5], [14612.2, 0.084], [58240.9, 0.053], [61476.5, 0.001], [62123.7, 0.692], [63547.4, 9.341], [63612.1, 15.539], [63644.4, 2.907], [63741.5, 25.494], [64013.4, 0.0], [64065.1, 9.906], [64194.3, 0.156], [64215.7, 0.0], [64712.2, 7.661]], "asks": [[64712.3, 14.222], [64713.0, 0.084], [64713.6, 0.003], [64714.0, 0.003], [64714.3, 0.101], [64717.1, 0.017], [64717.2, 0.641], [64717.3, 0.318], [64719.7, 0.034], [64720.0, 0.352], [64721.9, 0.715], [64722.1, 0.008], [64725.9, 0.158], [64761.5, 0.076], [65359.4, 5.521], [65529.7, 0.754], [65585.9, 4.362], [66006.5, 0.027]]}
{"kind": "depth", "E": 1787080143999, "U": 11315332441685, "u": 11315332447984, "recv_ms": 1787080143939, "bids": [[14412.2, 0.882], [14512.2, 3.318], [14612.2, 0.0], [58240.9, 0.053], [61476.5, 0.0], [62123.7, 0.689], [63104.1, 0.0], [63418.0, 9.305], [63712.2, 7.683], [63760.9, 5.95], [64065.1, 9.906], [64388.6, 5.888]], "asks": [[64714.3, 0.095], [64717.2, 0.0], [64717.3, 0.163], [64720.0, 0.205], [64721.9, 0.258], [64722.1, 0.649], [64725.9, 0.003], [65359.4, 5.521], [65556.8, 0.347], [65712.3, 0.007], [65715.3, 7.05], [65888.2, 3.479], [66006.5, 0.024]]}
{"kind": "depth", "E": 1787080144101, "U": 11315332448020, "u": 11315332457455, "recv_ms": 1787080144042, "bids": [[14412.2, 1.232], [14512.2, 2.968], [58240.9, 0.053], [61476.5, 0.0], [63725.1, 0.024], [63935.7, 41.346], [63942.1, 8.446], [64065.1, 9.906], [64207.4, 4.667], [64388.6, 5.888], [64554.6, 3.907], [64571.6, 3.099], [64571.7, 1.193], [64613.5, 0.942], [64616.8, 0.021], [64633.3, 0.163], [64640.7, 0.209], [64663.7, 0.036], [64696.0, 1.286], [64700.6, 0.245], [64703.9, 0.563], [64705.1, 0.14], [64705.2, 0.624], [64706.3, 0.281], [64707.5, 0.024], [64712.2, 7.75]], "asks": [[64712.3, 14.243], [64714.3, 0.111], [64717.2, 0.641], [64717.3, 0.163], [64720.0, 0.197], [64721.9, 0.25], [64722.1, 0.008], [64725.9, 0.003], [64739.2, 4.673], [64784.0, 8.424], [64784.8, 0.019], [64852.6, 5.398], [64868.5, 1.604], [64869.6, 6.414], [65035.9, 3.997], [65359.4, 5.521], [65521.2, 12.794], [65650.6, 27.665], [65699.2, 0.011], [65712.6, 0.766], [66006.5, 0.027], [67947.9, 0.058]]}
{"kind": "depth", "E": 1787080144203, "U": 11315332457530, "u": 11315332465332, "recv_ms": 1787080144145, "bids": [[1000.0, 35.81], [14412.2, 1.596], [14512.2, 2.604], [51769.8, 0.0], [58240.9, 0.053], [61476.5, 0.0], [62123.7, 0.692], [63712.2, 7.703], [63725.1, 0.035], [64065.1, 9.906], [64660.9, 1.076], [64701.4, 0.773], [64702.7, 1.082], [64704.0, 0.175], [64704.6, 0.202], [64705.3, 0.01], [64706.2, 0.547], [64706.3, 0.087], [64706.4, 0.233], [64711.3, 0.023], [64712.2, 7.823]], "asks": [[64712.3, 14.243], [64714.3, 0.085], [64717.2, 0.0], [64717.3, 0.163], [64719.7, 0.034], [64720.0, 0.205], [64721.2, 0.004], [64721.9, 0.258], [64722.1, 0.649], [64725.9, 0.003], [64726.4, 0.786], [64741.2, 0.25], [64741.3, 1.325], [64741.4, 0.564], [64744.2, 0.002], [64744.3, 0.004], [64744.4, 0.126], [64745.0, 2.959], [64745.1, 1.012], [64745.2, 0.006], [64747.2, 1.398], [64747.3, 0.063], [64747.4, 0.008], [64869.6, 10.406], [65359.4, 5.521], [65664.4, 0.0], [65695.1, 0.353], [65712.3, 0.027]]}
{"kind": "depth", "E": 1787080144305, "U": 11315332465557, "u": 11315332478248, "recv_ms": 1787080144246, "bids": [[14412.2, 1.96], [14512.2, 2.24], [51770.0, 0.0], [58240.9, 0.053], [61476.5, 0.0], [61505.0, 0.422], [62123.7, 0.689], [64065.1, 9.906], [64388.6, 5.887], [64518.0, 0.25], [64571.6, 3.079], [64571.7, 0.838], [64666.9, 0.725], [64696.0, 1.286], [64699.4, 0.249], [64704.6, 0.201], [64705.2, 0.083], [64705.3, 0.017], [64706.3, 0.087], [64706.4, 0.039], [64706.5, 0.025], [64706.7, 0.117], [64707.5, 0.558], [64712.2, 7.793]], "asks": [[64712.3, 14.243], [64714.3, 0.101], [64717.1, 0.558], [64717.2, 0.1], [64717.3, 0.163], [64719.7, 0.034], [64720.0, 0.197], [64721.9, 0.25], [64722.1, 0.008], [64725.9, 0.003], [64822.4, 0.017], [64841.8, 0.429], [64852.6, 5.398], [65035.9, 3.998], [65359.4, 5.521], [65650.6, 28.73], [65699.2, 0.022], [65715.3, 8.114], [65888.2, 4.237], [66006.5, 0.021], [67947.9, 0.053]]}
{"kind": "depth", "E": 1787080144407, "U": 11315332478352, "u": 11315332485949, "recv_ms": 1787080144351, "bids": [[14412.2, 2.31], [14512.2, 1.89], [51770.0, 0.0], [58240.9, 0.053], [61476.5, 0.0], [62123.7, 0.692], [63325.0, 0.209], [63418.0, 9.302], [63605.6, 0.942], [63712.2, 7.683], [63942.1, 9.383], [64065.1, 9.906], [64388.6, 5.887], [64631.7, 33.155], [64633.6, 7.754], [64633.9, 0.0], [64637.1, 0.009], [64642.7, 0.146], [64642.9, 3.256], [64646.9, 2.442], [64655.3, 2.152], [64663.6, 2.134], [64666.6, 4.305], [64670.7, 0.179], [64672.3, 0.08], [64673.3, 0.083], [64675.2, 0.032], [64686.3, 0.017], [64695.3, 0.002], [64696.1, 0.948], [64696.4, 0.01], [64699.3, 0.196], [64702.3, 1.047], [64702.5, 0.001], [64702.7, 0.464], [64703.9, 0.022], [64704.1, 0.628], [64704.2, 0.151], [64704.5, 0.154], [64704.8, 0.536], [64704.9, 0.355], [64705.0, 0.158], [64705.1, 2.427], [64705.2, 2.005], [64705.3, 0.002], [64705.6, 0.102], [64706.0, 0.094], [64706.2, 0.547], [64706.3, 0.087], [64706.4, 0.27], [64706.5, 0.025], [64707.3, 1.693], [64707.4, 0.695], [64707.5, 0.085], [64707.6, 0.002], [64707.7, 0.008], [64707.9, 0.085], [64708.3, 0.096], [64708.9, 0.001], [64709.0, 0.003], [64709.2, 0.019], [64709.3, 0.006], [64709.4, 0.102], [64709.5, 0.002], [64709.8, 0.004], [64710.4, 0.009], [64711.0, 0.0], [64711.1, 0.0], [64711.3, 0.001], [64711.6, 0.0], [64711.7, 0.107], [64712.2, 7.459]], "asks": [[64712.3, 14.243], [64712.6, 0.086], [64713.3, 0.31], [64714.0, 0.006], [64714.3, 0.659], [64715.0, 0.113], [64717.0, 0.152], [64717.1, 0.172], [64717.2, 0.0], [64717.3, 0.163], [64719.7, 0.034], [64720.0, 0.352], [64721.2, 0.003], [64721.9, 0.482], [64722.1, 0.334], [64725.9, 0.158], [64726.4, 0.168], [64730.2, 0.001], [64730.6, 0.382], [64732.8, 7.271], [64733.4, 2.321], [64733.7, 0.153], [64734.3, 0.01], [64734.7, 0.765], [64734.8, 0.01], [64735.7, 10.191], [64739.2, 3.414], [64739.6, 0.015], [64758.9, 0.0], [64779.7, 0.027], [64797.0, 2.127], [64797.1, 0.03], [64805.4, 2.148], [64813.7, 2.22], [64813.8, 0.0], [64869.6, 6.342], [64908.4, 11.471], [65359.4, 5.521], [65621.9, 1.824], [65650.6, 29.795], [65673.7, 2.815], [65683.0, 9.004], [65712.3, 0.007]]}
{"kind": "depth", "E": 1787080144509, "U": 11315332486009, "u": 11315332492569, "recv_ms": 1787080144451, "bids": [[1000.0, 35.81], [14412.2, 2.674], [14512.2, 1.526], [58240.9, 0.053], [61476.5, 0.0], [62123.7, 0.689], [63859.9, 4.206], [64065.1, 9.906], [64586.4, 0.001], [64619.6, 0.002], [64631.7, 0.013], [64633.6, 0.807], [64636.1, 33.204], [64666.6, 4.309], [64670.7, 0.165], [64695.2, 0.464], [64695.3, 0.01], [64703.9, 0.022], [64704.1, 0.157], [64704.5, 0.07], [64704.9, 0.271], [64705.2, 1.921], [64705.6, 0.018], [64706.2, 1.056], [64707.5, 0.086], [64708.3, 0.18], [64708.4, 0.008], [64708.8, 0.003], [64709.1, 0.093], [64709.7, 0.09], [64710.2, 0.084], [64710.4, 0.031], [64710.5, 0.021], [64712.2, 7.438]], "asks": [[64712.3, 14.242], [64712.6, 0.002], [64713.3, 0.0], [64714.0, 0.003], [64714.2, 0.0], [64714.3, 0.095], [64715.0, 0.103], [64716.9, 0.026], [64717.0, 0.152], [64717.1, 0.017], [64717.3, 0.318], [64718.0, 0.506], [64719.8, 0.094], [64719.9, 1.238], [64720.0, 0.352], [64721.7, 0.002], [64721.8, 0.004], [64721.9, 0.715], [64722.1, 0.031], [64722.2, 0.059], [64725.9, 0.158], [64727.5, 0.322], [64869.6, 10.406], [64908.4, 15.406], [64909.4, 0.003], [64910.8, 0.0], [65359.4, 5.521], [65435.2, 2.76], [65696.8, 2.281], [66006.5, 0.024]]}
{"kind": "depth", "E": 1787080144611, "U": 11315332492610, "u": 11315332497701, "recv_ms": 1787080144553, "bids": [[14412.2, 3.024], [14512.2, 1.176], [58240.9, 0.053], [61476.5, 0.0], [61476.6, 0.0], [61476.7, 0.012], [63686.6, 1.571], [63712.2, 7.703], [63858.5, 1.097], [63874.4, 3.131], [63935.7, 42.908], [64065.1, 9.906], [64619.4, 0.003], [64636.1, 0.0], [64637.1, 0.0], [64642.7, 33.35], [64695.3, 0.002], [64697.2, 0.024], [64703.9, 0.03], [64712.2, 7.35]], "asks": [[64712.3, 14.241], [64714.3, 0.111], [64717.1, 0.558], [64717.2, 0.1], [64717.3, 0.163], [64718.0, 1.406], [64719.8, 0.094], [64719.9, 0.133], [64720.0, 0.197], [64721.9, 0.25], [64722.1, 0.479], [64722.2, 0.059], [64725.9, 0.003], [64735.7, 0.191], [64739.1, 10.507], [64783.3, 0.0], [64784.0, 2.878], [64784.8, 0.037], [64785.5, 0.029], [64789.9, 37.737], [64869.6, 6.378], [64910.6, 0.003], [65359.4, 5.521], [65673.7, 2.283], [65712.3, 0.027]]}
{"kind": "depth", "E": 1787080144713, "U": 11315332497779, "u": 11315332502092, "recv_ms": 1787080144655, "bids": [[1000.0, 35.96], [14412.2, 3.374], [14512.2, 0.826], [58240.9, 0.053], [62123.7, 0.692], [64065.1, 9.906], [64168.6, 0.218], [64388.6, 5.877], [64571.6, 0.0], [64582.7, 0.003], [64686.3, 0.03], [64696.2, 0.003]], "asks": [[64714.3, 0.095], [64717.1, 0.017], [64717.2, 0.0], [64720.0, 0.205], [64721.8, 0.012], [64721.9, 0.891], [64728.7, 0.416], [64783.3, 37.733], [64784.8, 0.019], [64785.5, 0.029], [64789.9, 0.004], [64852.6, 0.001], [65359.4, 5.523], [65611.8, 12.271], [65618.3, 28.06], [65663.6, 8.512], [65834.9, 0.607]]}
{"kind": "depth", "E": 1787080144815, "U": 11315332502133, "u": 11315332509540, "recv_ms": 1787080144758, "bids": [[1000.0, 35.81], [14312.2, 0.014], [14412.2, 3.71], [14512.2, 0.476], [58240.9, 0.053], [61476.5, 0.0], [62123.7, 0.689], [63537.3, 0.687], [63712.2, 7.683], [63751.4, 2.772], [63911.6, 3.114], [64065.1, 9.906], [64571.6, 3.099], [64696.2, 0.005], [64697.1, 0.962], [64705.3, 0.39], [64710.2, 0.0], [64712.2, 7.375]], "asks": [[64712.4, 0.063], [64712.5, 0.084], [64714.0, 0.006], [64714.3, 0.111], [64715.0, 0.103], [64717.2, 0.641], [64717.3, 0.163], [64719.8, 0.557], [64719.9, 0.141], [64720.0, 0.197], [64721.8, 0.004], [64721.9, 0.25], [64722.1, 0.008], [64722.2, 0.059], [64725.9, 0.003], [64728.7, 0.418], [64852.6, 4.449], [65359.4, 5.521], [65663.6, 9.044], [65695.1, 0.011], [65712.3, 0.007], [66006.5, 0.027]]}
{"kind": "depth", "E": 1787080144917, "U": 11315332509711, "u": 11315332515200, "recv_ms": 1787080144860, "bids": [[14312.2, 0.196], [14412.2, 3.71], [14512.2, 0.294], [58240.9, 0.053], [61476.5, 0.0], [62123.7, 0.692], [63676.8, 12.207], [63911.6, 2.88], [63934.0, 0.0], [64065.1, 9.906], [64571.6, 0.0], [64634.5, 0.003], [64641.7, 0.629], [64664.4, 0.002], [64666.9, 0.722], [64679.8, 0.002], [64680.5, 0.002], [64695.3, 0.002], [64703.9, 0.03], [64705.3, 0.39], [64709.7, 0.006], [64712.2, 7.297]], "asks": [[64712.3, 14.224], [64712.5, 0.085], [64714.3, 0.111], [64717.1, 0.017], [64717.2, 0.796], [64717.3, 0.163], [64719.8, 0.094], [64719.9, 0.133], [64720.0, 0.352], [64721.9, 0.405], [64722.1, 0.318], [64722.2, 0.53], [64725.9, 0.158], [64737.9, 0.003], [64739.4, 0.164], [64754.1, 0.002], [64757.6, 0.003], [64776.8, 0.0], [64822.4, 0.014], [64852.6, 0.001], [64869.6, 10.406], [65359.4, 5.521], [65630.0, 0.954], [65825.4, 1.97], [67947.9, 0.058]]}
{"kind": "depth", "E": 1787080145019, "U": 11315332515241, "u": 11315332521037, "recv_ms": 1787080144963, "bids": [[1000.0, 35.81], [14312.2, 0.42], [14412.2, 3.612], [14512.2, 0.168], [58240.9, 0.053], [61476.5, 0.0], [63712.2, 7.703], [63911.6, 2.646], [64065.1, 9.906], [64129.5, 0.156], [64388.6, 5.877], [64390.3, 0.229], [64571.6, 1.552], [64586.3, 0.144], [64609.4, 2.501], [64695.3, 0.002], [64697.1, 0.962], [64700.5, 0.001], [64702.0, 0.479], [64703.6, 0.003], [64703.9, 0.03], [64705.3, 0.002], [64711.7, 0.273], [64712.2, 7.434]], "asks": [[64714.3, 0.111], [64715.0, 0.113], [64717.1, 0.017], [64717.2, 0.641], [64717.3, 0.163], [64719.9, 0.133], [64720.0, 0.197], [64721.7, 0.002], [64721.8, 0.004], [64721.9, 0.25], [64722.1, 0.008], [64722.2, 0.53], [64725.9, 0.003], [64753.2, 0.986], [64852.6, 5.398], [65035.9, 3.997], [65359.4, 5.521], [65712.3, 0.027], [67947.9, 0.053]]}
{"kind": "depth", "E": 1787080145121, "U": 11315332521115, "u": 11315332527386, "recv_ms": 1787080145065, "bids": [[1000.0, 35.81], [14312.2, 0.672], [14412.2, 3.472], [14512.2, 0.056], [51770.0, 0.002], [58240.9, 0.053], [61476.5, 0.0], [62123.7, 0.689], [63265.4, 0.0], [63741.5, 27.061], [63944.0, 10.471], [64065.1, 9.906], [64571.6, 2.28], [64611.0, 2.554], [64640.6, 0.001], [64643.2, 6.479], [64665.8, 4.0], [64679.3, 2.328], [64679.4, 0.009], [64679.5, 2.852], [64682.0, 1.115], [64682.7, 0.001], [64682.8, 0.016], [64682.9, 1.309], [64690.1, 0.004], [64691.0, 1.543], [64695.3, 0.01], [64697.1, 0.962], [64700.6, 0.245], [64701.4, 0.772], [64701.9, 0.002], [64702.2, 0.004], [64703.0, 0.003], [64703.9, 0.022], [64705.3, 0.196], [64706.4, 0.039], [64706.6, 0.102], [64707.3, 1.793], [64707.6, 0.431], [64708.1, 0.235], [64708.7, 0.003], [64709.4, 0.002], [64709.5, 0.086]], "asks": [[64712.3, 13.818], [64712.9, 0.1], [64713.6, 0.102], [64714.0, 0.004], [64714.3, 0.111], [64714.5, 0.006], [64715.0, 0.013], [64715.7, 0.0], [64717.2, 0.641], [64717.3, 0.163], [64718.8, 0.023], [64720.0, 0.198], [64721.9, 0.25], [64722.1, 0.007], [64722.6, 1.003], [64723.7, 0.004], [64725.9, 0.003], [64726.9, 0.004], [64728.6, 0.959], [64736.0, 3.119], [64739.8, 1.009], [64755.9, 0.944], [64756.0, 3.515], [64778.7, 6.173], [64783.2, 6.374], [64806.9, 2.09], [64809.2, 0.0], [65359.4, 5.521], [65550.8, 0.764], [65673.7, 1.751], [65683.0, 9.346]]}
{"kind": "depth", "E": 1787080145223, "U": 11315332527419, "u": 11315332532644, "recv_ms": 1787080145163, "bids": [[14312.2, 0.966], [14412.2, 3.234], [14512.2, 0.0], [51769.8, 0.0], [51770.0, 0.0], [58240.9, 0.053], [61476.5, 0.001], [61476.7, 0.01], [62123.7, 0.692], [63712.2, 7.683], [63787.3, 0.0], [63874.4, 2.349], [63935.0, 0.927], [64065.1, 9.906], [64388.6, 5.878], [64518.0, 0.253], [64633.2, 0.034], [64660.7, 0.23], [64660.8, 1.17], [64663.7, 0.037], [64679.8, 0.005], [64688.6, 0.65], [64695.2, 0.472], [64695.3, 0.002], [64695.9, 0.146], [64697.1, 0.96], [64701.0, 0.276], [64702.2, 0.003], [64703.9, 0.022], [64705.3, 0.39], [64709.5, 0.002], [64712.2, 7.208]], "asks": [[64712.3, 14.206], [64713.6, 0.103], [64714.0, 0.003], [64714.3, 0.111], [64715.0, 0.003], [64717.1, 0.017], [64717.2, 0.541], [64717.3, 0.263], [64719.8, 0.094], [64719.9, 0.133], [64720.0, 0.197], [64721.6, 0.002], [64721.7, 0.003], [64721.9, 0.25], [64722.1, 0.007], [64722.2, 0.53], [64725.9, 0.003], [64729.0, 0.137], [64736.4, 0.031], [64743.5, 0.005], [64783.2, 0.376], [64783.3, 0.0], [64789.9, 37.737], [64822.4, 0.017], [64841.8, 0.432], [65359.4, 5.521], [65712.3, 0.007], [66330.1, 2.114], [67947.9, 0.048]]}
{"kind": "depth", "E": 1787080145325, "U": 11315332532723, "u": 11315332540924, "recv_ms": 1787080145265, "bids": [[1000.0, 35.81], [14312.2, 1.33], [14412.2, 2.87], [58240.9, 0.053], [61476.5, 0.0], [62123.7, 0.689], [63454.4, 1.352], [64065.1, 9.906], [64388.6, 5.878], [64610.8, 10.006], [64611.0, 3.411], [64633.9, 0.0], [64637.1, 0.0], [64638.3, 0.0], [64640.5, 33.232], [64642.7, 0.146], [64642.9, 0.001], [64644.8, 1.173], [64695.2, 0.464], [64698.7, 2.062], [64700.8, 1.488], [64701.5, 0.061], [64703.9, 0.03], [64704.0, 0.115], [64705.3, 0.002], [64707.0, 0.244], [64708.1, 0.004], [64712.2, 7.161]], "asks": [[64714.3, 0.111], [64717.2, 0.625], [64717.3, 0.163], [64718.8, 0.022], [64720.0, 0.197], [64721.9, 0.25], [64722.1, 0.015], [64725.9, 0.003], [64783.3, 37.493], [64784.8, 0.019], [64789.9, 0.004], [64806.9, 3.316], [64809.1, 10.0], [65035.9, 3.996], [65359.4, 5.521], [65565.6, 0.839], [71183.6, 0.0]]}
{"kind": "depth", "E": 1787080145427, "U": 11315332540942, "u": 11315332546790, "recv_ms": 1787080145369, "bids": [[1000.0, 35.81], [14312.2, 1.68], [14412.2, 2.52], [58240.9, 0.053], [61476.5, 0.0], [62123.7, 0.692], [63256.2, 0.683], [63712.2, 7.703], [63773.9, 45.089], [63806.2, 38.294], [64065.1, 9.906], [64388.6, 5.879], [64571.6, 2.265], [64673.3, 0.069], [64688.6, 0.032], [64695.2, 0.001], [64699.3, 0.042], [64701.0, 0.275], [64703.9, 1.034], [64705.1, 1.886], [64705.2, 1.921], [64709.8, 0.088], [64710.2, 0.084], [64710.9, 0.027], [64712.2, 7.025]], "asks": [[64712.3, 14.186], [64712.5, 0.001], [64714.3, 0.111], [64717.1, 0.172], [64717.2, 0.641], [64717.3, 0.163], [64720.0, 0.352], [64721.7, 0.002], [64721.9, 0.405], [64722.1, 0.317], [64725.9, 0.158], [64741.6, 0.005], [64758.9, 0.042], [64776.3, 0.008], [64783.7, 0.004], [64852.6, 5.398], [65359.4, 5.521], [65521.2, 13.022], [65632.1, 0.002], [65663.6, 9.576], [65712.3, 0.027], [65729.2, 0.0]]}
{"kind": "depth", "E": 1787080145529, "U": 11315332546920, "u": 11315332552474, "recv_ms": 1787080145475, "bids": [[14312.2, 2.03], [14412.2, 2.17], [51770.0, 0.0], [58240.9, 0.053], [61476.5, 0.001], [63825.0, 3.161], [63942.1, 8.446], [64065.0, 2.361], [64065.1, 9.906], [64476.5, 0.005], [64680.4, 0.254], [64692.2, 0.03], [64692.6, 0.251], [64693.0, 0.002], [64693.5, 2.341], [64696.1, 0.948], [64697.0, 0.097], [64701.8, 0.001], [64703.9, 1.034], [64705.2, 1.921], [64706.2, 1.25], [64707.0, 0.554], [64710.3, 0.024], [64710.4, 0.028], [64710.5, 0.002], [64710.9, 0.005], [64712.2, 7.192]], "asks": [[64712.3, 14.186], [64712.4, 0.061], [64712.5, 0.002], [64714.3, 0.095], [64717.1, 0.017], [64717.2, 0.0], [64717.3, 0.326], [64718.5, 0.025], [64720.0, 0.352], [64721.9, 0.723], [64722.1, 0.648], [64725.9, 0.158], [64727.0, 0.021], [64728.6, 1.884], [64728.9, 0.164], [64729.5, 0.005], [64731.5, 0.002], [64731.8, 0.005], [64731.9, 0.651], [64732.8, 7.328], [64732.9, 0.197], [64733.8, 0.001], [64734.3, 0.551], [64734.7, 0.224], [64735.5, 0.032], [64735.9, 0.0], [64736.3, 0.296], [64783.3, 0.0], [64784.8, 0.028], [64785.5, 37.522], [64787.7, 0.224], [64869.6, 10.406], [64906.3, 0.001], [65359.4, 5.521], [65553.6, 47.718], [65986.1, 1.058]]}
{"kind": "depth", "E": 1787080145631, "U": 11315332552499, "u": 11315332558262, "recv_ms": 1787080145571, "bids": [[1000.0, 35.81], [14312.2, 2.394], [14412.2, 1.806], [58240.9, 0.053], [61476.5, 0.0], [62123.7, 0.689], [63418.0, 9.305], [63712.2, 7.683], [63942.1, 9.383], [64000.1, 0.532], [64065.1, 9.906], [64388.6, 5.879], [64706.2, 1.056], [64712.2, 7.129]], "asks": [[64714.3, 0.085], [64717.2, 0.649], [64717.3, 0.171], [64720.0, 0.197], [64721.9, 0.25], [64722.1, 0.007], [64725.9, 0.003], [65359.4, 5.521], [65565.4, 1.527], [65712.3, 0.007], [65715.3, 9.178], [67947.9, 0.053]]}
{"kind": "depth", "E": 1787080145733, "U": 11315332558478, "u": 11315332564933, "recv_ms": 1787080145674, "bids": [[1000.0, 35.81], [14312.2, 2.744], [14412.2, 1.456], [51770.0, 0.0], [58240.9, 0.053], [61476.5, 0.0], [62123.7, 0.692], [63094.4, 2.93], [63825.6, 2.5], [64065.1, 9.906], [64571.6, 0.0], [64582.7, 0.003], [64706.3, 0.087], [64712.2, 7.146]], "asks": [[64714.3, 0.085], [64717.2, 0.0], [64717.3, 0.171], [64720.0, 0.197], [64721.9, 0.258], [64722.1, 0.648], [64725.9, 0.003], [64734.3, 0.01], [64734.8, 0.551], [64852.6, 0.001], [65330.7, 0.204], [65359.4, 5.521], [65521.2, 13.364], [65974.2, 1.52], [66006.5, 0.024]]}
{"kind": "depth", "E": 1787080145835, "U": 11315332564977, "u": 11315332572833, "recv_ms": 1787080145776, "bids": [[14312.2, 3.108], [14412.2, 1.092], [58240.9, 0.053], [61476.5, 0.0], [62123.7, 0.689], [63550.7, 0.786], [63712.2, 7.703], [63945.5, 14.149], [63964.9, 0.012], [64065.1, 9.906], [64515.8, 7.025], [64554.6, 2.862], [64571.6, 2.263], [64633.9, 33.23], [64637.1, 0.018], [64640.5, 0.002], [64642.7, 0.146], [64696.2, 0.005], [64706.2, 1.056], [64706.3, 0.281], [64712.2, 7.147]], "asks": [[64714.3, 0.085], [64717.2, 0.101], [64717.3, 0.171], [64718.5, 0.003], [64718.7, 0.381], [64720.0, 0.197], [64721.9, 0.25], [64722.1, 0.555], [64725.9, 0.003], [64728.7, 0.418], [64852.6, 5.398], [64868.5, 2.203], [64869.6, 10.406], [64908.4, 15.406], [65337.2, 0.003], [65359.4, 5.521], [65553.6, 48.023], [65565.6, 0.534], [65611.8, 13.183], [65621.9, 0.912], [65694.1, 1.52], [65712.3, 0.027]]}
{"kind": "depth", "E": 1787080145937, "U": 11315332572935, "u": 11315332579638, "recv_ms": 1787080145879, "bids": [[1000.0, 35.81], [14312.2, 3.472], [14412.2, 0.728], [58240.9, 0.053], [64065.1, 9.906], [64388.6, 5.889], [64633.9, 0.0], [64637.1, 0.0], [64640.5, 33.232], [64690.1, 0.56], [64691.0, 0.987], [64691.8, 0.117], [64692.6, 0.135], [64695.5, 0.926], [64696.1, 0.023], [64706.3, 0.281], [64707.4, 0.695], [64712.1, 0.02]], "asks": [[64714.3, 0.095], [64717.2, 0.0], [64717.3, 0.171], [64718.8, 0.042], [64720.0, 0.197], [64721.9, 0.892], [64722.1, 0.014], [64727.9, 0.926], [64728.6, 0.959], [64730.3, 0.593], [64731.9, 0.095], [64732.9, 0.19], [64733.7, 0.061], [64733.8, 0.008], [64734.7, 0.339], [64736.3, 0.181], [64775.7, 1.872], [64783.7, 0.0], [65320.6, 0.676], [65359.4, 5.521]]}
{"kind": "depth", "E": 1787080146039, "U": 11315332579665, "u": 11315332584992, "recv_ms": 1787080145980, "bids": [[1000.0, 35.81], [14212.2, 0.042], [14312.2, 3.738], [14412.2, 0.42], [58240.9, 0.053], [61476.5, 0.0], [62123.7, 0.692], [63418.0, 9.302], [63712.2, 7.683], [63935.7, 44.47], [64065.1, 9.906], [64640.5, 0.002], [64642.7, 33.376], [64695.5, 0.001], [64696.3, 1.166], [64700.6, 0.25], [64703.9, 0.493], [64705.2, 2.462], [64706.3, 0.087], [64712.2, 7.146]], "asks": [[64714.3, 0.111], [64717.1, 0.017], [64717.2, 0.0], [64717.3, 0.163], [64719.9, 0.133], [64720.0, 0.197], [64721.8, 0.004], [64721.9, 0.25], [64722.1, 0.648], [64722.2, 0.522], [64725.9, 0.003], [64726.5, 0.265], [64727.9, 0.001], [64728.7, 1.343], [64729.5, 0.005], [64730.3, 0.037], [64731.2, 3.767], [64732.0, 0.024], [64732.8, 7.328], [64734.7, 0.765], [64734.8, 0.01], [64735.5, 0.147], [64735.9, 0.0], [64927.0, 0.031], [65327.1, 9.738], [65359.4, 5.521], [65712.3, 0.007], [66006.5, 0.027]]}
{"kind": "depth", "E": 1787080146141, "U": 11315332585404, "u": 11315332591514, "recv_ms": 1787080146082, "bids": [[14212.2, 0.238], [14312.2, 3.696], [14412.2, 0.266], [58240.9, 0.053], [61476.5, 0.0], [62123.7, 0.689], [63725.1, 0.025], [63822.6, 3.439], [63955.1, 2.188], [64065.1, 9.906], [64388.6, 5.888], [64634.5, 0.0], [64640.6, 0.002], [64642.8, 7.318], [64660.7, 0.231], [64679.8, 0.005], [64700.6, 0.245], [64704.7, 0.202], [64712.2, 7.282]], "asks": [[64712.3, 14.203], [64714.3, 0.095], [64717.2, 0.642], [64717.3, 0.171], [64720.0, 0.197], [64721.3, 0.005], [64721.9, 0.25], [64722.1, 0.014], [64725.9, 0.003], [64757.6, 0.003], [64784.0, 8.364], [64784.8, 0.019], [64822.4, 0.014], [64917.9, 0.0], [65359.4, 5.521], [65453.7, 3.054], [65553.6, 48.328], [65699.2, 0.012]]}
{"kind": "depth", "E": 1787080146243, "U": 11315332591754, "u": 11315332600457, "recv_ms": 1787080146184, "bids": [[1000.0, 35.81], [14212.2, 0.476], [14312.2, 3.584], [14412.2, 0.14], [51769.8, 0.0], [58240.9, 0.053], [61476.5, 0.0], [62123.7, 0.692], [63308.8, 0.676], [63620.3, 1.802], [63712.2, 7.703], [63725.3, 0.035], [63812.7, 11.51], [63939.1, 0.781], [64009.9, 4.219], [64065.1, 9.906], [64388.6, 5.888], [64633.9, 0.0], [64637.1, 0.027], [64638.3, 33.302], [64642.7, 0.146], [64642.8, 0.002], [64647.5, 0.003], [64657.8, 0.002], [64660.7, 0.232], [64695.5, 0.001], [64696.2, 0.623], [64696.3, 0.241], [64696.4, 0.935], [64703.6, 0.621], [64703.9, 0.493], [64705.2, 1.921], [64705.3, 0.543], [64705.4, 0.424], [64706.0, 0.01], [64710.7, 0.097], [64712.2, 7.331]], "asks": [[64713.0, 0.0], [64714.3, 0.085], [64717.1, 0.017], [64717.2, 0.0], [64717.3, 0.171], [64720.0, 0.197], [64721.9, 0.258], [64722.1, 0.648], [64725.9, 0.003], [64727.3, 1.149], [64731.2, 3.767], [64732.2, 0.081], [64732.8, 2.271], [64734.6, 1.0], [64738.2, 0.109], [64761.5, 0.09], [64777.0, 0.075], [64783.3, 37.201], [64784.0, 2.878], [64785.5, 0.029], [65035.9, 3.997], [65359.4, 5.521], [65529.7, 0.525], [65650.6, 28.73], [65683.0, 9.802], [65699.3, 1.337], [65712.3, 0.027]]}
{"kind": "depth", "E": 1787080146345, "U": 11315332600616, "u": 11315332606495, "recv_ms": 1787080146286, "bids": [[1000.0, 35.81], [14212.2, 0.714], [14312.2, 3.458], [14412.2, 0.028], [51770.0, 0.0], [58240.9, 0.053], [61476.5, 0.0], [62123.7, 0.689], [63428.3, 1.935], [63500.3, 0.0], [63572.2, 0.001], [63644.1, 0.0], [63712.2, 7.683], [63716.0, 0.005], [63787.9, 0.0], [63859.2, 0.783], [63859.8, 0.0], [63911.6, 2.412], [63931.7, 0.006], [63942.1, 8.446], [64003.7, 0.001], [64065.1, 9.908], [64075.6, 0.001], [64388.6, 5.887], [64637.1, 0.0], [64638.3, 0.0], [64640.5, 33.304], [64692.4, 0.176], [64703.6, 0.003], [64703.9, 1.034], [64705.1, 0.14], [64705.3, 0.002], [64705.4, 0.036], [64706.2, 0.547], [64712.2, 7.358]], "asks": [[64714.3, 0.095], [64717.2, 0.016], [64717.3, 0.171], [64720.0, 0.197], [64721.9, 0.25], [64722.1, 0.632], [64725.9, 0.003], [64869.6, 10.406], [65230.0, 7.876], [65359.4, 5.523], [65370.0, 2.33], [65441.9, 0.0], [65513.9, 0.228], [65529.7, 0.267], [65585.8, 0.0], [65657.7, 0.001], [65712.3, 0.007], [65729.6, 0.0], [65801.5, 0.001], [65873.4, 0.001], [65945.3, 0.014], [66006.5, 0.024], [66017.3, 0.0]]}
{"kind": "depth", "E": 1787080146447, "U": 11315332606498, "u": 11315332610499, "recv_ms": 1787080146387, "bids": [[14212.2, 1.05], [14312.2, 3.15], [14412.2, 0.0], [58240.9, 0.053], [64065.1, 9.906], [64194.5, 8.572], [64640.5, 0.002], [64642.7, 33.448], [64692.4, 0.022], [64710.7, 0.013]], "asks": [[64713.1, 0.085], [64714.3, 0.085], [64717.2, 0.0], [64717.3, 0.171], [64720.0, 0.197], [64721.9, 0.258], [64722.1, 0.648], [64725.9, 0.003], [64748.8, 1.424], [64868.5, 0.753], [64869.6, 6.342], [64908.4, 11.47], [65359.4, 5.521], [65694.9, 3.458]]}
{"kind": "depth", "E": 1787080146549, "U": 11315332610607, "u": 11315332616080, "recv_ms": 1787080146490, "bids": [[1000.0, 35.81], [14212.2, 1.4], [14312.2, 2.8], [51770.0, 0.0], [58240.9, 0.053], [61476.5, 0.0], [61476.6, 0.002], [62123.7, 0.692], [63612.1, 15.93], [63816.1, 16.62], [63903.3, 12.398], [63942.1, 9.383], [64065.0, 2.36], [64065.1, 9.906], [64194.5, 8.568], [64388.6, 5.887], [64554.6, 3.875], [64571.6, 2.775], [64653.7, 0.027], [64654.0, 0.002], [64654.4, 1.162], [64654.7, 0.023], [64655.0, 0.127], [64671.0, 0.034], [64671.3, 0.003], [64671.6, 0.007], [64671.9, 0.818], [64672.2, 0.992], [64685.9, 0.07], [64686.0, 0.004], [64686.1, 0.014], [64686.2, 0.002], [64686.4, 1.379], [64686.5, 0.034], [64686.6, 0.093], [64686.7, 0.097], [64686.8, 0.023], [64687.4, 1.774], [64687.8, 0.182], [64692.4, 0.022], [64692.7, 5.012], [64704.2, 0.011], [64704.3, 0.061], [64704.4, 0.135], [64704.5, 0.0], [64704.6, 0.001], [64704.7, 0.002], [64704.8, 0.466], [64704.9, 0.071], [64705.0, 0.088], [64705.1, 0.04], [64705.2, 1.851], [64705.4, 0.004], [64705.8, 0.021], [64706.1, 0.365], [64706.4, 0.004], [64706.7, 0.085], [64712.2, 7.286]], "asks": [[64714.3, 0.095], [64717.3, 0.326], [64718.3, 0.002], [64718.6, 0.313], [64718.9, 0.001], [64719.2, 0.008], [64719.6, 0.0], [64719.8, 0.003], [64719.9, 0.003], [64720.0, 0.275], [64720.1, 2.319], [64720.2, 0.018], [64720.3, 0.0], [64720.4, 0.311], [64720.5, 0.004], [64720.6, 1.544], [64720.7, 0.002], [64720.8, 0.002], [64721.9, 0.723], [64725.9, 0.158], [64735.5, 0.115], [64735.8, 0.081], [64736.1, 0.004], [64736.5, 0.0], [64736.8, 0.001], [64737.2, 2.46], [64737.6, 1.299], [64738.2, 0.018], [64738.3, 0.052], [64738.4, 0.0], [64738.5, 0.431], [64738.6, 0.002], [64738.8, 0.004], [64738.9, 0.001], [64739.0, 0.852], [64739.1, 10.367], [64748.8, 1.27], [64752.7, 0.0], [64753.1, 0.291], [64753.4, 0.443], [64753.7, 0.012], [64754.0, 0.003], [64783.3, 0.0], [64787.4, 0.186], [64787.7, 37.425], [64852.6, 4.427], [64869.6, 6.342], [64908.4, 15.406], [65035.9, 3.998], [65230.0, 8.795], [65359.4, 5.521], [65479.6, 1.314], [65565.4, 1.222]]}
{"kind": "depth", "E": 1787080146651, "U": 11315332616137, "u": 11315332620434, "recv_ms": 1787080146592, "bids": [[1000.0, 35.81], [14212.2, 1.764], [14312.2, 2.436], [51770.0, 0.0], [58240.9, 0.053], [61476.7, 0.008], [62123.7, 0.689], [63712.2, 7.703], [63903.3, 12.632], [64065.1, 9.906], [64633.9, 33.302], [64637.1, 0.018], [64642.7, 0.146], [64657.8, 0.03], [64671.2, 1.071], [64671.9, 0.85], [64704.3, 0.131], [64704.9, 0.271], [64705.0, 0.158], [64705.1, 0.14], [64705.5, 0.04], [64706.1, 0.397], [64712.2, 7.259]], "asks": [[64717.2, 0.008], [64717.3, 0.163], [64718.7, 0.416], [64719.4, 0.039], [64719.8, 0.21], [64719.9, 0.103], [64720.0, 0.23], [64720.5, 0.074], [64721.9, 0.258], [64725.9, 0.003], [64735.8, 0.116], [64736.5, 0.035], [64736.9, 0.439], [64737.9, 0.18], [64738.0, 0.644], [64738.5, 0.501], [64752.9, 0.035], [64753.6, 2.417], [64777.9, 0.018], [64780.0, 0.037], [64783.3, 37.201], [64787.4, 0.177], [64787.7, 0.224], [64908.4, 11.47], [65359.4, 5.521], [65650.6, 29.795], [65683.0, 10.144], [65712.3, 0.027], [71183.6, 0.0]]}
{"kind": "depth", "E": 1787080146753, "U": 11315332620525, "u": 11315332627533, "recv_ms": 1787080146694, "bids": [[14212.2, 2.128], [14312.2, 2.072], [58240.9, 0.053], [62123.7, 0.692], [63880.8, 3.508], [63903.3, 12.866], [63965.0, 3.949], [64065.1, 9.906], [64388.6, 5.877], [64499.3, 0.02], [64582.7, 0.003], [64633.9, 0.0], [64637.1, 0.0], [64640.5, 33.304], [64666.9, 0.725], [64672.2, 1.027], [64672.5, 0.035], [64704.3, 0.201], [64704.4, 0.205], [64704.6, 0.201], [64704.7, 0.202], [64705.2, 1.921], [64706.4, 0.039], [64706.7, 0.117]], "asks": [[64718.1, 0.041], [64718.4, 0.036], [64719.7, 0.125], [64720.1, 2.419], [64720.2, 0.228], [64720.3, 0.1], [64720.5, 0.158], [64720.6, 1.614], [64735.2, 0.035], [64735.5, 0.147], [64737.3, 1.814], [64737.7, 0.094], [64738.1, 0.142], [64738.2, 0.118], [64738.3, 0.152], [64738.5, 0.585], [64738.6, 0.072], [64752.3, 0.036], [64752.6, 0.032], [64822.4, 0.017], [65359.4, 5.523]]}
{"kind": "depth", "E": 1787080146855, "U": 11315332627558, "u": 11315332635510, "recv_ms": 1787080146797, "bids": [[1000.0, 35.81], [14212.2, 2.478], [14312.2, 1.722], [58240.9, 0.053], [61476.5, 0.0], [61476.6, 0.004], [62123.7, 0.689], [63712.2, 7.683], [63806.2, 40.642], [64065.1, 9.906], [64554.6, 2.863], [64571.6, 2.265], [64596.0, 3.939], [64596.3, 0.042], [64603.4, 0.093], [64605.4, 2.321], [64640.5, 0.002], [64641.0, 0.323], [64642.7, 33.448], [64671.6, 0.039], [64673.3, 0.083], [64692.7, 0.012], [64695.5, 0.001], [64696.2, 0.005], [64696.4, 0.935], [64703.9, 0.493], [64704.5, 0.07], [64704.8, 0.536], [64705.3, 0.543], [64705.4, 0.392], [64705.8, 0.053], [64707.0, 0.244], [64709.6, 0.086], [64709.8, 0.004], [64710.0, 0.094], [64710.2, 0.0], [64712.2, 7.32]], "asks": [[64712.7, 0.099], [64717.2, 0.163], [64719.1, 0.037], [64720.0, 0.455], [64720.3, 0.17], [64721.9, 0.723], [64725.9, 0.158], [64728.7, 1.343], [64736.2, 0.036], [64738.0, 0.714], [64738.2, 0.104], [64738.4, 0.07], [64753.3, 2.357], [64758.9, 0.0], [64761.5, 0.076], [64783.5, 0.048], [64819.2, 0.008], [64819.3, 2.318], [64847.8, 4.811], [64852.6, 5.398], [64869.6, 6.57], [64908.4, 15.406], [65359.4, 5.521], [65469.4, 3.433], [65532.9, 0.763], [65553.6, 48.633], [65712.3, 0.007], [67947.9, 0.049]]}
{"kind": "depth", "E": 1787080147059, "U": 11315332641595, "u": 11315332648234, "recv_ms": 1787080147001, "bids": [[14212.2, 3.192], [14312.2, 1.008], [58240.9, 0.053], [61476.5, 0.0], [62123.7, 0.692], [63712.2, 7.703], [63870.9, 22.984], [63955.1, 2.735], [64065.1, 9.906], [64388.6, 5.877], [64571.6, 2.793], [64645.4, 2.721], [64646.1, 0.009], [64655.1, 0.395], [64655.4, 0.27], [64686.3, 0.1], [64686.9, 0.571], [64687.0, 0.071], [64688.0, 0.28], [64695.6, 0.002], [64696.4, 0.01], [64696.5, 0.928], [64700.6, 0.245], [64703.9, 0.493], [64704.7, 0.201], [64705.3, 0.543], [64705.4, 0.392], [64710.4, 0.028], [64711.7, 0.214], [64712.2, 7.36]], "asks": [[64712.3, 14.205], [64712.7, 0.099], [64714.3, 0.111], [64717.1, 0.172], [64717.2, 0.0], [64717.3, 0.163], [64719.9, 0.258], [64721.9, 0.25], [64722.1, 1.113], [64725.9, 0.158], [64778.1, 2.895], [64779.0, 0.075], [64780.5, 0.023], [64827.1, 0.629], [64852.6, 5.398], [64869.6, 10.407], [64873.8, 0.009], [65359.4, 5.521], [65712.3, 0.027]]}
{"kind": "depth", "E": 1787080147161, "U": 11315332648403, "u": 11315332656116, "recv_ms": 1787080147104, "bids": [[1000.0, 35.81], [14212.2, 3.542], [14312.2, 0.658], [58240.9, 0.053], [61476.5, 0.0], [62123.7, 0.689], [63902.7, 3.891], [64009.7, 4.056], [64009.9, 4.063], [64065.1, 9.906], [64633.9, 0.0], [64637.1, 0.0], [64640.5, 33.357], [64642.7, 0.146], [64642.8, 0.002], [64654.5, 0.033], [64673.3, 0.069], [64682.2, 2.321], [64684.3, 0.001], [64685.6, 0.309], [64686.2, 0.072], [64686.4, 1.449], [64686.5, 0.47], [64686.6, 0.093], [64686.7, 0.297], [64687.1, 0.415], [64687.5, 0.475], [64690.1, 0.004], [64690.9, 0.012], [64691.4, 0.656], [64691.6, 0.002], [64691.8, 0.001], [64692.9, 0.617], [64693.2, 0.119], [64697.0, 0.997], [64698.8, 0.574], [64700.0, 0.574], [64701.0, 1.175], [64701.4, 0.463], [64702.5, 0.31], [64703.5, 0.127], [64703.9, 0.485], [64704.0, 0.174], [64704.2, 0.073], [64704.3, 0.142], [64704.8, 0.534], [64705.0, 0.081], [64705.4, 0.392], [64705.5, 0.04], [64705.6, 0.111], [64705.7, 0.062], [64706.0, 0.012], [64706.3, 0.003], [64706.7, 0.117], [64707.0, 0.013], [64707.3, 1.776], [64707.4, 1.005], [64707.5, 0.086], [64707.8, 0.239], [64708.4, 0.001], [64709.0, 0.01], [64709.3, 0.004], [64710.0, 0.094], [64711.1, 0.0], [64711.5, 0.003], [64712.1, 0.022], [64712.2, 8.415]], "asks": [[64712.3, 14.198], [64712.7, 0.015], [64713.0, 0.084], [64713.1, 0.001], [64713.4, 0.002], [64713.6, 0.102], [64713.7, 0.009], [64713.9, 0.003], [64714.0, 0.003], [64714.3, 0.095], [64714.5, 0.006], [64714.8, 0.042], [64716.7, 0.086], [64716.9, 0.026], [64717.1, 0.181], [64717.3, 0.163], [64718.0, 0.506], [64719.0, 0.909], [64719.9, 0.267], [64720.4, 0.079], [64720.8, 0.003], [64721.3, 0.004], [64721.6, 0.311], [64721.7, 0.01], [64721.8, 0.552], [64721.9, 0.327], [64722.1, 0.023], [64723.9, 0.011], [64724.0, 0.158], [64725.0, 0.905], [64725.2, 0.147], [64725.9, 0.158], [64726.4, 0.014], [64727.2, 1.852], [64727.3, 0.531], [64727.5, 0.002], [64727.6, 0.322], [64728.6, 1.113], [64728.7, 0.425], [64729.1, 0.938], [64730.6, 0.382], [64731.9, 0.095], [64732.9, 0.036], [64734.6, 0.382], [64734.7, 0.224], [64734.8, 0.551], [64735.1, 0.155], [64735.6, 0.001], [64735.9, 0.0], [64736.0, 1.605], [64739.1, 0.367], [64742.5, 3.739], [64742.6, 10.104], [64744.7, 0.071], [64761.5, 0.118], [64783.2, 0.376], [64783.3, 36.821], [64787.4, 0.177], [64787.7, 0.224], [64817.5, 0.61], [64868.5, 0.753], [64869.6, 10.407], [64908.4, 11.47], [65035.9, 3.997], [65359.4, 5.521], [65650.6, 30.86], [65712.6, 0.006], [66006.5, 0.024], [71183.6, 0.0]]}
{"kind": "depth", "E": 1787080147263, "U": 11315332656138, "u": 11315332662252, "recv_ms": 1787080147206, "bids": [[1000.0, 35.81], [14212.2, 3.766], [14312.2, 0.364], [14612.2, 0.07], [51769.8, 0.0], [51770.0, 0.0], [58240.9, 0.053], [62123.7, 0.692], [63524.8, 0.01], [63551.5, 1.346], [63589.6, 2.514], [63712.2, 7.683], [63911.6, 2.061], [64065.1, 9.906], [64388.6, 5.878], [64686.5, 0.54], [64686.8, 0.093], [64705.4, 0.004], [64705.7, 0.079], [64706.2, 0.774], [64708.7, 0.087], [64710.0, 0.01], [64711.0, 0.022], [64711.2, 0.256]], "asks": [[64712.4, 0.145], [64714.3, 0.095], [64716.9, 0.026], [64717.1, 0.181], [64717.2, 0.0], [64717.3, 0.171], [64719.9, 0.104], [64721.7, 0.002], [64721.8, 0.011], [64721.9, 0.258], [64722.1, 0.633], [64722.2, 0.522], [64725.9, 0.003], [65359.4, 5.521], [65482.4, 9.162], [65618.3, 30.343], [65712.3, 0.007], [66006.5, 0.021], [67947.9, 0.045]]}
{"kind": "depth", "E": 1787080147365, "U": 11315332662426, "u": 11315332668975, "recv_ms": 1787080147306, "bids": [[14212.2, 3.668], [14312.2, 0.238], [14612.2, 0.294], [51770.0, 0.0], [58240.9, 0.053], [61476.5, 0.0], [63579.7, 4.475], [63709.2, 12.943], [63997.1, 0.236], [64065.1, 9.906], [64388.6, 5.888], [64571.6, 0.0], [64633.9, 33.355], [64634.5, 0.003], [64640.5, 0.002], [64657.8, 0.002], [64660.4, 0.159], [64670.1, 0.149], [64685.5, 0.008], [64686.2, 0.142], [64686.4, 1.519], [64692.7, 5.012], [64695.0, 0.004], [64696.2, 0.623], [64697.1, 0.962], [64698.0, 1.026], [64701.0, 0.275], [64702.0, 1.379], [64703.6, 0.003], [64705.4, 0.006], [64706.0, 0.01], [64712.2, 8.445]], "asks": [[64714.3, 0.095], [64716.9, 0.181], [64717.3, 0.163], [64719.0, 0.009], [64719.9, 0.267], [64720.0, 1.2], [64721.9, 0.723], [64725.0, 0.005], [64725.9, 0.158], [64726.0, 3.221], [64727.2, 2.47], [64734.6, 1.0], [64852.6, 0.001], [65359.4, 5.521], [65535.0, 0.176], [65628.4, 12.86]]}
{"kind": "depth", "E": 1787080147467, "U": 11315332669149, "u": 11315332674605, "recv_ms": 1787080147411, "bids": [[1000.0, 35.81], [14212.2, 3.556], [14312.2, 0.112], [14612.2, 0.532], [58240.9, 0.053], [62123.7, 0.689], [63418.0, 9.305], [63515.0, 3.191], [63712.2, 7.703], [63744.9, 0.786], [64571.6, 2.824], [64634.5, 0.0], [64666.9, 0.722], [64679.8, 0.002], [64692.5, 2.424], [64703.9, 1.026], [64705.3, 0.002], [64705.4, 0.006]], "asks": [[64714.3, 0.085], [64716.9, 0.026], [64719.8, 0.287], [64719.9, 1.116], [64721.9, 0.258], [64722.1, 0.015], [64722.2, 0.059], [64725.9, 0.003], [64757.6, 0.0], [64822.4, 0.017], [64852.6, 5.398], [65035.9, 3.996], [65359.4, 5.521], [65712.3, 0.027], [65783.2, 1.069]]}
{"kind": "depth", "E": 1787080147569, "U": 11315332674709, "u": 11315332680731, "recv_ms": 1787080147510, "bids": [[1000.0, 35.81], [14212.2, 3.43], [14312.2, 0.0], [14612.2, 0.77], [58240.9, 0.053], [61476.5, 0.0], [61476.6, 0.006], [62123.7, 0.692], [63418.0, 9.302], [63421.0, 0.098], [63492.9, 0.06], [63536.3, 1.581], [63564.8, 7.066], [63636.7, 3.09], [63708.6, 4.021], [63712.2, 7.683], [63776.9, 10.034], [63780.5, 0.059], [63852.4, 0.06], [63924.3, 0.06], [63996.2, 0.292], [64065.1, 9.906], [64388.6, 5.889], [64571.6, 2.824], [64619.3, 0.02], [64619.4, 0.0], [64633.9, 0.0], [64638.3, 33.355], [64668.1, 0.028], [64690.8, 0.558], [64691.4, 0.1], [64692.3, 0.376], [64692.4, 0.022], [64692.6, 0.251], [64693.2, 0.003], [64696.0, 1.002], [64696.2, 0.005], [64697.1, 0.962], [64705.1, 0.142], [64705.4, 0.004], [64706.2, 0.968], [64707.9, 0.279], [64710.3, 0.001], [64710.7, 0.097], [64711.1, 0.002], [64711.2, 0.275], [64712.1, 0.02], [64712.2, 7.415]], "asks": [[64712.3, 14.139], [64712.4, 0.061], [64713.0, 0.0], [64713.7, 0.093], [64714.3, 0.095], [64716.9, 0.026], [64719.7, 0.125], [64719.9, 1.115], [64722.2, 0.059], [64725.9, 0.003], [64727.2, 1.852], [64740.8, 1.293], [64748.8, 1.424], [64783.3, 0.0], [64787.4, 0.195], [64787.7, 37.045], [64852.6, 5.398], [65359.4, 5.521], [65521.2, 14.126], [65653.8, 7.417], [65712.3, 0.007], [66006.5, 0.018]]}
{"kind": "depth", "E": 1787080147671, "U": 11315332680782, "u": 11315332686886, "recv_ms": 1787080147613, "bids": [[14212.2, 3.066], [14612.2, 1.134], [58240.9, 0.053], [61476.5, 0.0], [61476.7, 0.006], [62123.7, 0.689], [63709.2, 14.04], [63712.2, 6.586], [63776.9, 8.938], [64065.1, 9.908], [64068.1, 0.159], [64388.6, 5.879], [64638.3, 0.0], [64640.5, 33.357], [64686.5, 0.204], [64692.0, 0.548], [64692.3, 0.046], [64697.1, 0.96], [64706.2, 0.774], [64706.3, 0.003], [64707.4, 0.695], [64707.9, 0.085], [64710.7, 0.013], [64712.2, 7.37]], "asks": [[64712.9, 0.184], [64714.3, 0.085], [64716.9, 0.026], [64719.7, 0.125], [64722.2, 0.059], [64725.9, 0.003], [64738.6, 10.072], [64741.2, 0.248], [64741.3, 1.323], [64741.4, 0.562], [64744.2, 0.0], [64744.3, 0.002], [64744.4, 0.124], [64745.0, 2.957], [64745.1, 1.01], [64745.2, 0.004], [64747.2, 1.396], [64747.3, 0.061], [64747.4, 0.006], [64758.9, 0.014], [64761.5, 0.076], [64783.3, 0.0], [64784.8, 0.019], [64785.5, 0.029], [64787.4, 0.177], [64787.7, 0.224], [64789.9, 36.825], [65359.4, 5.521], [65362.5, 0.061], [65434.4, 0.058], [65506.3, 0.108], [65550.8, 0.002], [65578.2, 2.341], [65650.1, 0.373], [65722.0, 0.152], [65793.9, 0.058], [65865.8, 0.061], [65937.7, 0.058], [66009.6, 0.058]]}
{"kind": "depth", "E": 1787080147773, "U": 11315332686899, "u": 11315332693178, "recv_ms": 1787080147714, "bids": [[1000.0, 35.81], [14212.2, 2.702], [14612.2, 1.498], [51770.0, 0.0], [58240.9, 0.053], [62123.7, 0.692], [63815.7, 0.001], [64065.1, 9.906], [64571.6, 2.793], [64582.7, 0.003], [64657.8, 0.002], [64684.4, 0.337], [64706.2, 0.774], [64706.3, 0.003], [64707.5, 0.086], [64707.7, 0.008]], "asks": [[64712.3, 14.138], [64714.3, 0.085], [64716.9, 0.026], [64719.7, 0.126], [64722.2, 0.059], [64725.9, 0.003], [64742.5, 0.093], [64742.6, 0.104], [64748.8, 1.27], [64761.5, 0.104], [64785.5, 36.85], [64787.4, 0.177], [64789.9, 0.004], [65359.4, 5.521], [65780.1, 3.39]]}
{"kind": "depth", "E": 1787080147875, "U": 11315332693270, "u": 11315332699504, "recv_ms": 1787080147816, "bids": [[1000.0, 35.81], [14212.2, 2.352], [14612.2, 1.848], [51770.0, 0.0], [58240.9, 0.053], [61476.5, 0.0], [63418.0, 9.305], [63712.2, 6.606], [63753.0, 1.61], [63773.9, 46.185], [63809.4, 0.0], [64065.1, 9.906], [64571.6, 2.75], [64696.2, 0.005], [64706.3, 0.003]], "asks": [[64712.3, 14.138], [64712.5, 0.086], [64714.3, 0.095], [64716.9, 0.181], [64717.1, 0.097], [64719.7, 0.281], [64722.2, 0.524], [64725.9, 0.158], [64728.7, 0.425], [64783.3, 36.821], [64784.8, 0.019], [64785.5, 0.029], [65359.4, 5.521], [65650.6, 31.925], [65712.3, 0.027]]}
{"kind": "depth", "E": 1787080147977, "U": 11315332699542, "u": 11315332704490, "recv_ms": 1787080147919, "bids": [[14212.2, 2.002], [14612.2, 2.198], [58240.9, 0.053], [61476.5, 0.0], [62123.7, 0.689], [63418.0, 9.302], [63709.2, 15.137], [63773.9, 47.281], [63806.2, 41.11], [63923.2, 2.4], [63935.7, 43.439], [64000.1, 0.922], [64065.1, 9.906], [64168.6, 0.103], [64388.6, 5.889], [64605.4, 0.003], [64605.5, 2.318], [64671.6, 0.079], [64672.9, 0.042], [64696.1, 0.948], [64696.5, 0.003], [64703.9, 1.026], [64705.3, 0.002], [64706.2, 0.968], [64706.3, 0.003], [64707.5, 0.28], [64712.2, 7.394]], "asks": [[64712.3, 14.138], [64712.4, 0.063], [64712.5, 0.085], [64714.3, 0.095], [64716.9, 0.026], [64717.3, 0.163], [64719.7, 0.126], [64722.2, 0.059], [64725.9, 0.003], [64728.6, 2.038], [64729.1, 0.013], [64729.5, 0.005], [64731.2, 3.211], [64731.9, 0.651], [64734.3, 0.551], [64734.8, 0.01], [64735.5, 0.032], [64735.9, 0.0], [64736.3, 0.296], [64740.8, 1.279], [64819.3, 0.0], [64819.4, 2.321], [65035.9, 3.382], [65359.4, 5.521], [65434.4, 0.821], [65521.2, 14.355], [65715.3, 8.114]]}
{"kind": "depth", "E": 1787080148079, "U": 11315332704618, "u": 11315332710034, "recv_ms": 1787080148020, "bids": [[1000.0, 35.81], [14212.2, 1.638], [14612.2, 2.562], [51770.0, 0.0], [58240.9, 0.053], [61476.5, 0.0], [62123.7, 0.692], [63700.0, 26.168], [63712.2, 6.586], [63775.7, 1.174], [63838.0, 0.688], [64065.1, 9.906], [64696.0, 0.102], [64699.0, 0.913], [64700.6, 0.245], [64702.0, 0.479], [64702.9, 0.004], [64703.0, 0.903], [64706.2, 0.968], [64706.3, 0.003], [64707.5, 0.086], [64709.9, 0.1], [64711.2, 0.298]], "asks": [[64712.3, 14.14], [64712.5, 0.001], [64714.3, 0.095], [64717.2, 0.634], [64717.3, 0.318], [64719.5, 0.156], [64719.7, 0.589], [64719.8, 0.21], [64719.9, 0.111], [64720.0, 0.3], [64721.0, 0.904], [64721.9, 0.25], [64722.1, 0.007], [64722.2, 0.524], [64725.9, 0.158], [64726.0, 2.321], [64727.0, 0.921], [64764.1, 0.006], [65359.4, 5.521], [65608.4, 0.0], [65712.3, 0.007], [65718.5, 15.119]]}
{"kind": "depth", "E": 1787080148181, "U": 11315332710168, "u": 11315332720169, "recv_ms": 1787080148123, "bids": [[1000.0, 35.81], [14212.2, 1.288], [14612.2, 2.912], [51769.8, 0.002], [51770.0, 0.0], [58240.9, 0.053], [61476.5, 0.0], [61476.7, 0.004], [62123.7, 0.689], [63741.5, 27.413], [63903.3, 13.1], [64065.1, 9.906], [64168.6, 0.066], [64626.0, 0.234], [64633.0, 0.065], [64633.1, 0.023], [64633.2, 0.031], [64640.4, 0.001], [64640.5, 33.355], [64640.6, 0.0], [64641.4, 6.231], [64657.8, 0.03], [64660.7, 0.226], [64663.5, 0.018], [64663.6, 2.132], [64663.7, 0.034], [64682.4, 0.0], [64692.0, 0.394], [64696.0, 0.102], [64703.8, 1.597], [64706.2, 0.774], [64712.2, 7.423]], "asks": [[64712.3, 14.139], [64712.4, 0.061], [64712.5, 0.002], [64714.3, 0.101], [64716.9, 0.026], [64717.1, 0.097], [64717.2, 0.0], [64717.3, 0.163], [64719.5, 0.001], [64719.6, 0.549], [64719.7, 0.126], [64719.9, 0.103], [64721.0, 0.004], [64722.1, 0.547], [64722.2, 0.059], [64725.9, 0.003], [64727.0, 0.021], [64783.2, 6.238], [64868.5, 2.204], [65035.9, 3.996], [65356.6, 1.393], [65359.4, 5.521], [65521.2, 14.613], [65715.3, 9.178]]}
{"kind": "depth", "E": 1787080148283, "U": 11315332720192, "u": 11315332725638, "recv_ms": 1787080148224, "bids": [[14212.2, 0.924], [14612.2, 3.276], [51769.8, 0.0], [51770.0, 0.0], [58240.9, 0.053], [62123.7, 0.692], [63418.0, 9.305], [63712.2, 6.606], [63814.5, 9.53], [63822.6, 2.501], [63935.7, 44.689], [64065.1, 9.906], [64168.6, 0.031], [64388.6, 5.878], [64657.8, 0.002], [64660.5, 0.003], [64697.0, 0.097], [64700.0, 1.474], [64703.0, 0.003], [64703.2, 0.128], [64703.8, 1.596], [64704.0, 1.074], [64707.1, 0.379], [64707.5, 0.086], [64707.9, 0.085], [64710.3, 0.085], [64712.2, 7.422]], "asks": [[64712.3, 14.138], [64712.9, 0.1], [64713.3, 0.084], [64714.3, 0.085], [64717.3, 0.163], [64719.6, 0.0], [64719.9, 0.111], [64721.8, 0.011], [64721.9, 0.343], [64722.0, 1.418], [64722.1, 1.011], [64728.0, 1.024], [65359.4, 5.521], [65598.9, 1.825], [65653.8, 6.352], [65712.3, 0.027], [65718.5, 14.055], [65893.9, 0.002]]}
{"kind": "depth", "E": 1787080148385, "U": 11315332725736, "u": 11315332737894, "recv_ms": 1787080148326, "bids": [[1000.0, 35.81], [14212.2, 0.56], [14612.2, 3.64], [58240.9, 0.053], [61476.5, 0.0], [63418.0, 9.302], [63686.6, 0.004], [63712.2, 6.586], [63800.0, 39.874], [63822.6, 0.938], [64065.1, 9.906], [64168.6, 0.0], [64675.9, 0.001], [64684.4, 0.001], [64688.4, 0.336], [64692.7, 5.014], [64692.8, 1.471], [64694.6, 0.621], [64699.4, 0.251], [64702.0, 0.479], [64704.1, 0.157], [64704.9, 0.261], [64705.1, 0.14], [64705.2, 0.083], [64705.3, 0.01], [64706.4, 0.042], [64706.7, 0.033], [64707.2, 0.404], [64707.9, 0.085], [64708.0, 0.2], [64708.8, 0.01], [64711.7, 0.298], [64712.1, 0.021], [64712.2, 11.801]], "asks": [[64712.3, 10.597], [64712.9, 0.1], [64713.3, 0.0], [64713.7, 0.008], [64714.3, 0.085], [64714.5, 0.005], [64715.2, 0.005], [64715.3, 0.002], [64715.4, 0.142], [64717.1, 0.181], [64718.1, 0.038], [64718.6, 0.003], [64721.8, 0.027], [64725.6, 0.136], [64728.4, 0.018], [64734.6, 0.382], [64737.8, 0.13], [64738.6, 10.074], [64738.8, 0.002], [64743.4, 0.016], [64743.5, 0.005], [64764.1, 0.02], [65035.9, 3.997], [65359.4, 5.523], [65697.5, 0.0], [65712.3, 0.007], [65715.3, 10.242], [65841.4, 0.002], [65877.1, 1.695], [66682.7, 0.648]]}
{"kind": "depth", "E": 1787080148487, "U": 11315332737909, "u": 11315332746878, "recv_ms": 1787080148449, "bids": [[1000.0, 35.81], [14212.2, 0.322], [14512.2, 0.112], [14612.2, 3.766], [58240.9, 0.053], [62123.7, 0.689], [63780.2, 0.0], [63812.7, 14.012], [64065.1, 9.906], [64633.9, 0.0], [64640.5, 0.0], [64641.4, 0.0], [64642.7, 33.595], [64646.9, 2.443], [64647.4, 0.175], [64655.3, 2.153], [64658.0, 0.023], [64660.4, 0.131], [64663.6, 2.133], [64665.6, 0.217], [64668.1, 0.0], [64668.5, 0.048], [64680.4, 0.164], [64687.6, 0.294], [64688.1, 0.097], [64691.0, 0.995], [64697.0, 0.017], [64699.2, 0.01], [64699.3, 0.044], [64703.9, 0.485], [64704.1, 1.356], [64704.6, 0.281], [64705.0, 0.205], [64705.3, 0.002], [64705.6, 0.018], [64705.7, 0.062], [64706.3, 0.391], [64707.2, 0.32], [64707.4, 0.014], [64707.7, 0.006], [64708.0, 0.006], [64712.1, 0.105], [64712.2, 11.912]], "asks": [[64712.3, 9.958], [64713.5, 0.683], [64714.3, 0.001], [64714.7, 0.003], [64715.2, 0.003], [64715.4, 0.139], [64715.5, 0.094], [64717.1, 0.181], [64717.3, 0.813], [64717.4, 1.003], [64717.5, 2.406], [64717.6, 0.018], [64717.8, 1.087], [64718.8, 0.02], [64719.9, 0.574], [64721.8, 0.011], [64721.9, 0.25], [64722.1, 0.007], [64725.2, 0.144], [64725.3, 0.01], [64727.1, 0.005], [64727.6, 0.322], [64728.6, 1.113], [64729.4, 3.688], [64731.0, 0.068], [64734.3, 0.01], [64734.8, 0.551], [64735.9, 0.0], [64737.8, 0.134], [64738.6, 0.074], [64745.9, 10.032], [64766.7, 0.014], [64797.0, 2.128], [64805.3, 2.128], [64805.4, 0.021], [64813.6, 5.898], [64813.7, 0.093], [65346.5, 0.748], [65359.4, 5.521], [65650.6, 32.99], [65715.3, 11.306]]}
{"kind": "depth", "E": 1787080148589, "U": 11315332747010, "u": 11315332753127, "recv_ms": 1787080148530, "bids": [[14212.2, 0.21], [14512.2, 0.35], [14612.2, 3.64], [58240.9, 0.053], [61476.5, 0.0], [62123.7, 0.692], [63620.3, 1.411], [63776.9, 7.842], [63874.4, 0.785], [63971.1, 0.389], [64065.1, 9.908], [64388.6, 5.877], [64692.4, 0.022], [64692.7, 5.014], [64702.8, 0.329], [64704.6, 0.201], [64706.3, 0.197], [64707.4, 0.208], [64712.2, 11.811]], "asks": [[64723.2, 2.772], [64725.1, 0.007], [64732.9, 0.035], [64737.2, 2.461], [64748.9, 0.031], [65035.9, 3.998], [65359.4, 5.521], [65393.3, 0.002], [65427.8, 0.763], [65531.8, 1.825], [65653.8, 5.287], [65783.2, 0.006], [65831.8, 0.757]]}
{"kind": "depth", "E": 1787080148691, "U": 11315332753162, "u": 11315332757358, "recv_ms": 1787080148656, "bids": [[1000.0, 35.81], [14212.2, 0.084], [14512.2, 0.588], [14612.2, 3.528], [58240.9, 0.053], [61476.5, 0.0], [62123.7, 0.689], [63513.6, 1.73], [63676.8, 13.775], [63712.2, 6.606], [64065.1, 9.906], [64570.6, 0.0], [64582.7, 0.004], [64679.8, 0.005], [64691.9, 0.908], [64694.6, 0.003], [64697.1, 0.719], [64707.4, 0.208], [64712.1, 0.021], [64712.2, 11.855]], "asks": [[64712.3, 10.344], [64714.7, 0.087], [64718.1, 0.041], [64725.3, 0.011], [64741.9, 10.016], [64745.9, 0.032], [64748.3, 0.028], [64748.7, 0.155], [64757.6, 0.003], [64766.7, 0.0], [64816.8, 0.015], [64822.4, 0.014], [65359.4, 5.521], [65673.7, 1.219], [65686.2, 0.267], [65694.9, 3.116], [65712.3, 0.027], [71183.5, 0.01]]}
{"kind": "depth", "E": 1787080148793, "U": 11315332757419, "u": 11315332762281, "recv_ms": 1787080148734, "bids": [[1000.0, 35.81], [14212.2, 0.0], [14512.2, 0.868], [14612.2, 3.332], [58240.9, 0.053], [61476.5, 0.0], [63612.1, 16.321], [63773.9, 48.377], [63968.0, 12.515], [64000.2, 0.197], [64065.1, 9.906], [64443.2, 1.945], [64571.6, 0.0], [64582.7, 0.003], [64707.4, 0.014], [64712.2, 11.912]], "asks": [[64712.3, 10.379], [64720.8, 0.002], [64725.3, 0.01], [64852.6, 0.001], [65359.4, 5.521], [65650.6, 34.055], [65695.5, 0.782], [65780.1, 4.453], [71183.5, 0.008]]}
{"kind": "depth", "E": 1787080148895, "U": 11315332762325, "u": 11315332766082, "recv_ms": 1787080148835, "bids": [[14512.2, 1.218], [14612.2, 2.982], [58240.9, 0.053], [61476.5, 0.0], [62123.7, 0.692], [63502.1, 2.154], [63712.2, 5.489], [64065.1, 9.906], [64388.6, 5.877], [64554.6, 3.917], [64571.6, 2.774], [64692.6, 0.128], [64692.8, 1.587], [64693.2, 0.01], [64696.2, 0.005], [64703.9, 0.022], [64704.1, 1.279], [64704.2, 0.536], [64704.3, 0.219], [64705.0, 0.205], [64706.3, 0.197], [64707.4, 0.014], [64712.2, 11.899]], "asks": [[64712.3, 10.344], [64720.6, 1.993], [64721.6, 0.002], [64724.3, 0.076], [64725.2, 0.137], [64725.3, 0.011], [64728.7, 0.425], [64731.2, 3.767], [64731.9, 0.095], [64735.6, 0.116], [64736.3, 0.181], [64748.7, 0.001], [64852.6, 5.398], [64869.6, 8.627], [65359.4, 5.521], [65373.0, 0.243], [65417.7, 8.309], [65565.4, 0.917], [65653.8, 4.222], [65663.6, 10.108], [65683.0, 10.486], [65712.3, 0.007], [66006.5, 0.021]]}
{"kind": "depth", "E": 1787080148997, "U": 11315332766157, "u": 11315332770533, "recv_ms": 1787080148954, "bids": [[1000.0, 35.81], [14512.2, 1.568], [14612.2, 2.632], [58240.9, 0.053], [61476.5, 0.0], [62123.7, 0.689], [63536.7, 0.685], [63654.3, 1.082], [63709.2, 16.234], [63773.9, 49.473], [63776.9, 6.746], [63903.3, 13.607], [63949.1, 1.562], [64065.1, 9.906], [64562.8, 0.002], [64691.9, 0.754], [64704.3, 0.142], [64705.0, 0.282], [64706.3, 0.003], [64712.2, 11.717]], "asks": [[64712.3, 10.346], [64718.9, 0.024], [64748.7, 0.001], [64805.6, 0.156], [65359.4, 5.521], [65531.8, 1.483], [65650.6, 35.12], [66006.5, 0.018]]}
{"kind": "depth", "E": 1787080149099, "U": 11315332770711, "u": 11315332777176, "recv_ms": 1787080149039, "bids": [[14512.2, 1.932], [14612.2, 2.268], [51770.0, 0.002], [58240.9, 0.053], [61476.5, 0.0], [62123.7, 0.692], [63712.2, 5.509], [63719.0, 2.687], [63725.3, 0.027], [63776.9, 5.65], [63790.0, 0.153], [63791.6, 0.01], [64065.1, 9.906], [64596.0, 0.076], [64596.6, 3.865], [64625.8, 0.007], [64640.2, 1.274], [64640.3, 0.0], [64641.0, 0.323], [64663.4, 0.006], [64669.8, 0.001], [64700.6, 0.245], [64706.3, 0.391], [64712.2, 10.712]], "asks": [[64712.3, 10.381], [64714.3, 0.085], [64725.3, 0.01], [64783.5, 0.048], [64847.8, 4.811], [65359.4, 5.521], [65618.3, 31.104], [65632.9, 0.0], [65634.6, 0.014], [65699.3, 1.329], [65712.3, 0.027]]}
{"kind": "depth", "E": 1787080149201, "U": 11315332777249, "u": 11315332782810, "recv_ms": 1787080149140, "bids": [[14512.2, 2.282], [14612.2, 1.918], [51769.8, 0.0], [51770.0, 0.0], [58240.9, 0.053], [62123.7, 0.689], [62774.8, 0.0], [63725.3, 0.035], [63730.4, 2.364], [63775.7, 0.783], [63790.0, 0.161], [63791.6, 0.018], [63815.5, 9.392], [63816.1, 12.709], [64065.1, 9.906], [64388.6, 5.877], [64632.8, 0.009], [64642.8, 7.35], [64660.4, 0.132], [64660.5, 0.0], [64663.3, 0.007], [64704.8, 0.535], [64706.3, 0.391], [64712.2, 10.667]], "asks": [[64712.3, 10.346], [64714.3, 0.095], [64721.4, 0.029], [64725.3, 0.011], [64744.9, 1.77], [64778.0, 2.188], [64778.6, 0.211], [65359.4, 5.521], [65553.6, 48.938]]}
{"kind": "depth", "E": 1787080149303, "U": 11315332782981, "u": 11315332788686, "recv_ms": 1787080149243, "bids": [[1000.0, 35.81], [14512.2, 2.646], [14612.2, 1.554], [58240.9, 0.053], [61476.5, 0.0], [63644.4, 3.612], [63712.2, 5.489], [63773.9, 50.569], [63850.1, 12.007], [63935.7, 46.251], [64065.1, 9.906], [64666.9, 0.725], [64704.8, 0.534], [64706.3, 0.197], [64712.2, 10.863]], "asks": [[64712.3, 10.38], [64714.3, 0.085], [64822.4, 0.017], [65359.4, 5.521], [65533.7, 2.286], [65632.9, 0.008], [65634.6, 0.022], [65699.3, 1.337], [65712.3, 0.007]]}
{"kind": "depth", "E": 1787080149405, "U": 11315332788788, "u": 11315332798582, "recv_ms": 1787080149372, "bids": [[14512.2, 2.996], [14612.2, 1.204], [51770.0, 0.002], [58240.9, 0.053], [61476.5, 0.0], [62123.7, 0.692], [63709.2, 17.175], [63806.2, 45.57], [64065.1, 9.906], [64691.7, 0.503], [64696.0, 0.102], [64696.3, 0.241], [64699.2, 0.007], [64702.3, 1.062], [64703.6, 0.003], [64704.1, 0.722], [64704.8, 0.535], [64706.2, 0.774], [64706.5, 0.027], [64706.6, 0.333], [64707.2, 0.318], [64707.4, 0.571], [64707.5, 0.085], [64707.8, 0.008], [64711.1, 0.002], [64711.7, 0.524], [64712.2, 10.48]], "asks": [[64713.6, 0.186], [64714.3, 0.085], [64715.0, 0.004], [64716.8, 0.038], [64717.4, 1.002], [64717.6, 0.003], [64717.8, 1.003], [64718.3, 0.312], [64721.4, 0.028], [64727.3, 1.149], [64734.6, 0.397], [64734.7, 0.842], [65035.9, 3.997], [65359.4, 5.521]]}
{"kind": "depth", "E": 1787080149507, "U": 11315332798746, "u": 11315332803763, "recv_ms": 1787080149446, "bids": [[14512.2, 3.36], [14612.2, 0.84], [51770.0, 0.0], [58240.9, 0.053], [61476.5, 0.0], [62123.7, 0.689], [63712.2, 5.509], [63767.4, 1.052], [63806.0, 0.42], [63838.6, 9.673], [64065.1, 9.906], [64388.6, 5.258], [64619.3, 0.017], [64619.4, 0.003], [64704.1, 0.722], [64704.8, 0.534], [64705.1, 0.14], [64705.2, 0.083], [64706.3, 0.197], [64707.4, 0.563], [64707.7, 0.015], [64710.9, 0.089], [64711.6, 0.178], [64712.2, 10.52]], "asks": [[64712.3, 10.325], [64720.6, 1.974], [64722.9, 0.018], [64725.3, 0.01], [65359.4, 5.521], [65626.8, 6.873], [65712.3, 0.027], [66006.5, 0.015]]}
{"kind": "depth", "E": 1787080149609, "U": 11315332803826, "u": 11315332807576, "recv_ms": 1787080149550, "bids": [[1000.0, 35.81], [14412.2, 0.014], [14512.2, 3.682], [14612.2, 0.504], [51770.0, 0.0], [58240.9, 0.053], [61476.5, 0.0], [62123.7, 0.692], [63418.0, 9.305], [63647.5, 2.21], [64065.1, 9.906], [64149.2, 2.337], [64158.5, 0.013], [64657.8, 0.03], [64660.4, 0.146], [64679.3, 2.33], [64679.4, 0.011], [64679.5, 2.854], [64682.8, 0.018], [64682.9, 1.311], [64683.0, 0.004], [64684.3, 0.001], [64685.3, 0.77], [64685.6, 0.0], [64692.5, 0.708], [64692.8, 1.625], [64693.0, 0.009], [64693.2, 0.003], [64697.0, 0.097], [64699.2, 0.007], [64699.3, 0.044], [64701.4, 0.464], [64702.3, 1.371], [64702.5, 0.001], [64702.8, 0.249], [64704.1, 0.568], [64704.8, 0.536], [64705.1, 0.697], [64706.3, 0.003], [64706.4, 0.123], [64706.5, 0.025], [64706.8, 0.09], [64707.2, 0.404], [64707.4, 0.014], [64707.7, 0.007], [64707.8, 0.008], [64707.9, 0.085], [64708.7, 0.094], [64709.0, 0.003], [64709.5, 0.086], [64709.6, 0.002], [64709.9, 0.016], [64710.3, 0.001], [64710.9, 0.005], [64711.7, 0.214], [64712.2, 10.803]], "asks": [[64712.3, 10.375], [64717.5, 2.324], [64720.3, 0.479], [64720.6, 1.665], [64722.1, 0.008], [64725.3, 0.011], [64727.3, 0.531], [64731.0, 0.624], [64731.2, 3.211], [64733.2, 0.009], [64733.8, 0.001], [64734.7, 0.224], [64735.4, 0.497], [64735.6, 0.001], [64743.4, 0.002], [64749.2, 0.177], [65035.9, 3.996], [65359.4, 5.521], [65482.4, 8.247], [65531.8, 1.254], [66006.5, 0.018]]}
{"kind": "depth", "E": 1787080149711, "U": 11315332807662, "u": 11315332812530, "recv_ms": 1787080149651, "bids": [[14412.2, 0.168], [14512.2, 3.738], [14612.2, 0.294], [58240.9, 0.053], [61476.5, 0.0], [61476.6, 0.004], [61476.7, 0.006], [62123.7, 0.689], [63644.4, 4.71], [63676.8, 12.677], [63712.2, 5.489], [64065.1, 9.908], [64168.6, 0.01], [64388.6, 5.879], [64582.7, 0.003], [64657.8, 0.002], [64668.1, 0.028], [64687.5, 0.811], [64688.4, 0.0], [64690.6, 0.56], [64690.8, 0.002], [64691.5, 0.004], [64692.5, 0.862], [64692.6, 0.128], [64692.8, 1.471], [64704.1, 0.722], [64704.3, 0.219], [64704.8, 0.535], [64705.0, 0.205], [64705.1, 0.14], [64705.2, 0.083], [64706.2, 0.968], [64706.3, 0.006], [64706.4, 0.039], [64706.7, 0.035], [64707.2, 0.402], [64707.4, 0.03], [64707.7, 0.548], [64709.9, 0.1], [64710.4, 0.112], [64711.3, 0.311], [64712.2, 11.793]], "asks": [[64712.3, 10.291], [64712.9, 0.184], [64725.3, 0.01], [64731.0, 0.068], [64731.1, 1.329], [64731.8, 0.561], [64734.3, 0.551], [64734.8, 0.01], [64735.4, 0.382], [64735.9, 0.0], [64736.2, 0.151], [64869.6, 6.34], [64908.4, 11.469], [65359.4, 5.521], [65482.4, 9.162], [65650.6, 34.055], [65712.3, 0.007], [71183.6, 0.0]]}
