{"kind": "depth", "E": 1787080104729, "U": 11315329594963, "u": 11315329600356, "recv_ms": 1787080104686, "bids": [[14212.2, 2.044], [14312.2, 2.156], [58240.9, 0.002], [61476.5, 0.0], [62123.7, 0.003], [63712.2, 12.09], [63938.7, 16.591], [64065.1, 1.935], [64195.3, 0.123], [64388.6, 3.128], [64582.7, 0.0], [64672.2, 0.992], [64680.2, 0.225], [64680.7, 0.16], [64690.2, 0.073], [64691.8, 0.557], [64692.1, 0.0], [64692.8, 1.589], [64693.7, 0.001], [64696.3, 1.166], [64696.8, 0.001], [64697.1, 0.962], [64703.9, 0.687], [64705.4, 0.105], [64705.6, 0.018], [64710.2, 0.0], [64712.2, 8.09]], "asks": [[64712.9, 0.084], [64714.5, 0.444], [64719.9, 0.003], [64721.9, 0.001], [64726.1, 0.219], [64731.6, 0.003], [64732.3, 0.557], [64732.5, 0.076], [64733.1, 0.057], [64734.8, 0.551], [64735.7, 0.191], [64735.9, 0.0], [64736.5, 0.269], [64742.4, 0.179], [64742.5, 0.257], [64870.0, 10.514], [65359.4, 0.0], [65712.3, 0.027]]}
{"kind": "depth", "E": 1787080104831, "U": 11315329600398, "u": 11315329605831, "recv_ms": 1787080104770, "bids": [[1000.0, 35.81], [14212.2, 2.394], [14312.2, 1.806], [58240.9, 0.002], [61476.5, 0.0], [62123.7, 0.0], [63822.5, 10.952], [63935.7, 14.67], [64065.1, 1.935], [64194.5, 6.081], [64197.6, 2.189], [64610.1, 10.001], [64642.4, 7.636], [64644.8, 1.173], [64664.1, 0.001], [64690.8, 0.558], [64691.8, 0.001], [64710.2, 0.084], [64712.2, 8.091]], "asks": [[64712.9, 0.0], [64714.4, 0.007], [64714.5, 0.444], [64719.9, 0.003], [64721.9, 0.001], [64723.4, 0.452], [64723.8, 0.223], [64726.1, 0.219], [64731.1, 1.885], [64732.3, 0.001], [64739.8, 1.04], [64756.0, 4.021], [64778.7, 6.173], [64811.1, 10.001], [64870.0, 7.563], [65035.9, 3.075], [65359.4, 0.0], [65585.9, 2.008], [65631.2, 0.454]]}
{"kind": "depth", "E": 1787080104933, "U": 11315329605931, "u": 11315329611503, "recv_ms": 1787080104872, "bids": [[1000.0, 35.81], [14212.2, 2.744], [14312.2, 1.456], [58240.9, 0.002], [61476.5, 0.0], [62123.7, 0.003], [63429.5, 0.0], [63501.4, 5.53], [63573.4, 0.0], [63645.3, 0.0], [63712.2, 12.07], [63717.2, 0.0], [63789.1, 0.003], [63822.6, 10.912], [63861.0, 0.001], [63932.9, 0.001], [64004.8, 0.001], [64065.1, 1.935], [64076.8, 0.011], [64080.0, 67.555], [64227.7, 53.805], [64343.5, 43.338], [64371.4, 0.06], [64371.5, 0.492], [64388.6, 3.129], [64611.0, 3.411], [64671.6, 0.011], [64696.7, 0.04], [64697.1, 0.962], [64703.9, 0.146], [64705.3, 1.114], [64705.7, 0.349], [64710.2, 0.0], [64712.2, 8.523]], "asks": [[64712.7, 0.085], [64714.4, 0.007], [64714.5, 0.444], [64719.9, 0.158], [64721.9, 0.466], [64726.1, 0.374], [64742.5, 0.257], [64811.0, 1.545], [64812.5, 0.022], [64870.0, 10.514], [64907.0, 26.682], [64913.1, 0.017], [64913.2, 3.93], [64978.4, 33.346], [65075.8, 42.838], [65193.0, 51.5], [65308.8, 0.533], [65359.4, 0.0], [65371.2, 5.193], [65443.2, 0.009], [65515.1, 0.0], [65553.6, 34.77], [65566.2, 0.0], [65587.0, 0.002], [65653.8, 21.261], [65658.9, 0.0], [65667.4, 5.941], [65712.3, 0.007], [65718.5, 20.438], [65724.2, 0.759], [65730.8, 0.005], [65802.7, 0.004], [65874.6, 0.0], [65946.6, 0.002], [66018.5, 0.004]]}
{"kind": "depth", "E": 1787080105035, "U": 11315329611522, "u": 11315329616531, "recv_ms": 1787080104976, "bids": [[14212.2, 3.108], [14312.2, 1.092], [58240.9, 0.002], [61476.5, 0.0], [62123.7, 0.0], [63149.0, 0.678], [63627.8, 2.334], [63806.2, 14.099], [63914.9, 10.462], [63967.7, 7.061], [64065.0, 0.023], [64065.1, 1.935], [64345.4, 8.952], [64388.6, 3.129], [64674.7, 0.164], [64679.5, 0.109], [64680.2, 0.168], [64690.2, 0.629], [64690.8, 0.002], [64692.0, 1.626], [64692.8, 1.473], [64695.6, 0.927], [64696.3, 0.241], [64697.1, 0.96], [64700.6, 0.404], [64703.9, 0.146], [64705.3, 0.573], [64705.4, 0.646], [64705.7, 0.349], [64712.2, 8.564]], "asks": [[64712.4, 0.043], [64714.4, 0.017], [64715.4, 1.228], [64719.9, 0.003], [64721.9, 0.001], [64726.1, 0.219], [64728.0, 1.028], [64728.9, 1.089], [64729.3, 0.628], [64731.4, 0.0], [64732.2, 0.063], [64733.1, 0.0], [64733.5, 0.002], [64733.9, 0.02], [64734.8, 0.551], [64735.7, 0.306], [64736.5, 0.154], [64742.3, 0.673], [64742.5, 0.103], [64783.2, 0.376], [64783.3, 0.0], [64787.7, 36.512], [64906.9, 0.218], [64924.2, 0.001], [64976.9, 5.292], [65075.7, 7.576], [65076.8, 0.0], [65359.4, 0.0]]}
{"kind": "depth", "E": 1787080105137, "U": 11315329616840, "u": 11315329622803, "recv_ms": 1787080105077, "bids": [[1000.0, 35.81], [14212.2, 3.472], [14312.2, 0.728], [58240.9, 0.002], [61476.5, 0.0], [63418.0, 2.695], [63557.2, 0.834], [63712.2, 12.09], [64065.1, 1.935], [64194.5, 6.392], [64571.4, 2.925], [64633.2, 0.034], [64663.6, 2.125], [64669.7, 0.061], [64669.8, 0.001], [64700.6, 0.399], [64704.9, 0.457], [64705.7, 0.195], [64707.3, 0.163], [64712.2, 8.523]], "asks": [[64712.3, 15.089], [64714.4, 0.172], [64714.5, 0.444], [64719.9, 0.158], [64721.9, 0.466], [64726.1, 0.374], [64742.6, 3.649], [64784.8, 0.037], [64785.5, 35.993], [64787.7, 0.224], [64870.0, 10.514], [65296.2, 3.209], [65359.4, 0.0], [65650.6, 10.171], [65712.3, 0.027], [65714.1, 4.102], [65715.3, 1.124]]}
{"kind": "depth", "E": 1787080105239, "U": 11315329622853, "u": 11315329628126, "recv_ms": 1787080105177, "bids": [[1000.0, 35.81], [14212.2, 3.738], [14312.2, 0.42], [14612.2, 0.042], [51770.0, 0.0], [58240.9, 0.002], [61476.6, 0.008], [61476.7, 0.004], [62123.7, 0.003], [63712.2, 12.07], [63812.7, 4.035], [63914.9, 10.229], [64065.1, 1.935], [64668.5, 0.339], [64703.9, 0.687], [64704.9, 0.456], [64705.4, 0.105], [64705.7, 0.041], [64712.2, 8.569]], "asks": [[64712.3, 15.091], [64714.4, 0.017], [64719.9, 0.003], [64721.9, 0.001], [64726.1, 0.219], [64741.4, 2.449], [64741.5, 0.027], [65359.4, 0.0], [65554.9, 2.134], [65650.6, 11.084], [65712.3, 0.007], [71183.6, 0.0]]}
{"kind": "depth", "E": 1787080105341, "U": 11315329628229, "u": 11315329635082, "recv_ms": 1787080105280, "bids": [[14212.2, 3.682], [14312.2, 0.266], [14612.2, 0.252], [58240.9, 0.002], [61476.5, 0.0], [61476.7, 0.002], [62123.7, 0.0], [63418.0, 2.698], [63547.4, 1.571], [63625.0, 1.953], [63790.1, 1.096], [63903.3, 2.901], [64016.7, 4.05], [64065.1, 1.935], [64388.6, 3.119], [64515.5, 7.834], [64554.4, 4.255], [64571.4, 2.925], [64605.9, 2.32], [64606.4, 1.224], [64646.4, 2.243], [64646.5, 0.378], [64671.6, 0.007], [64693.9, 2.671], [64694.3, 0.0], [64695.0, 0.004], [64695.5, 0.619], [64702.9, 0.622], [64704.0, 0.6], [64705.7, 0.195], [64707.2, 0.093], [64709.7, 0.122], [64709.9, 0.016], [64712.2, 8.582]], "asks": [[64714.4, 0.172], [64719.9, 0.158], [64721.9, 0.466], [64726.1, 0.374], [64727.4, 0.332], [64734.8, 1.169], [64741.2, 0.25], [64741.3, 1.438], [64741.4, 2.449], [64742.6, 3.495], [64744.2, 0.002], [64744.3, 0.004], [64744.4, 0.126], [64745.0, 2.959], [64745.1, 1.012], [64745.2, 0.006], [64747.2, 1.398], [64747.3, 0.063], [64747.4, 0.008], [64780.0, 2.597], [64780.2, 0.003], [64821.9, 2.318], [64822.6, 0.0], [64853.0, 5.397], [64868.5, 0.125], [64870.0, 10.514], [64908.8, 15.411], [65359.4, 0.0], [65485.5, 3.679], [65643.1, 1.365], [65932.0, 0.756], [66663.8, 0.645], [68228.8, 0.0]]}
{"kind": "depth", "E": 1787080105443, "U": 11315329635138, "u": 11315329641405, "recv_ms": 1787080105383, "bids": [[1000.0, 35.81], [14212.2, 3.584], [14312.2, 0.14], [14612.2, 0.476], [51770.0, 0.0], [58240.9, 0.002], [61476.5, 0.0], [62123.7, 0.003], [62717.2, 0.006], [63938.7, 16.122], [63988.5, 0.78], [64065.1, 1.935], [64647.5, 0.003], [64657.8, 0.002], [64666.4, 0.005], [64682.4, 0.158], [64693.6, 0.155], [64694.0, 1.917], [64704.1, 0.157], [64709.7, 0.038], [64712.2, 8.538]], "asks": [[64712.3, 15.09], [64713.2, 0.002], [64714.4, 0.017], [64719.9, 0.003], [64721.9, 0.001], [64726.1, 0.219], [64777.0, 0.075], [65359.4, 0.0], [65505.5, 13.186], [65653.8, 20.196], [66006.5, 0.018]]}
{"kind": "depth", "E": 1787080105545, "U": 11315329642026, "u": 11315329648900, "recv_ms": 1787080105484, "bids": [[1000.0, 35.81], [14212.2, 3.444], [14312.2, 0.028], [14612.2, 0.728], [58240.9, 0.002], [61476.5, 0.0], [62123.7, 0.0], [63712.2, 12.09], [63773.9, 26.458], [64006.8, 4.518], [64065.1, 1.935], [64666.9, 0.537], [64679.8, 0.005], [64696.2, 0.003], [64704.1, 0.157], [64705.7, 0.195], [64707.3, 0.125], [64712.2, 8.497]], "asks": [[64712.3, 15.09], [64714.4, 0.172], [64719.9, 0.158], [64721.9, 0.466], [64726.1, 0.374], [64728.7, 0.311], [64770.6, 0.378], [64783.3, 35.964], [64784.8, 0.019], [64785.5, 0.029], [64822.4, 0.014], [64870.0, 7.574], [65359.4, 0.0], [65482.4, 3.672], [65650.6, 12.149], [65669.0, 0.94], [65712.3, 0.027], [68228.8, 0.076]]}
{"kind": "depth", "E": 1787080105647, "U": 11315329648969, "u": 11315329655829, "recv_ms": 1787080105586, "bids": [[14212.2, 3.15], [14312.2, 0.0], [14612.2, 1.05], [51769.8, 0.0], [58240.9, 0.002], [61476.5, 0.0], [61476.6, 0.006], [61476.7, 0.004], [63848.5, 0.002], [63879.2, 0.021], [63935.7, 15.139], [64065.1, 1.935], [64388.6, 3.128], [64440.4, 9.948], [64518.1, 1.328], [64696.2, 0.005], [64709.7, 0.122], [64712.2, 8.558]], "asks": [[64714.4, 0.017], [64719.9, 0.003], [64721.9, 0.001], [64726.1, 0.219], [64728.7, 0.313], [64739.2, 4.741], [64742.6, 3.495], [64783.2, 6.11], [64811.0, 2.845], [64868.5, 1.845], [64905.7, 7.889], [65306.9, 0.026], [65359.4, 0.0]]}
{"kind": "depth", "E": 1787080105749, "U": 11315329655977, "u": 11315329661754, "recv_ms": 1787080105689, "bids": [[1000.0, 35.81], [14212.2, 2.786], [14612.2, 1.414], [58240.9, 0.002], [61476.5, 0.0], [62123.7, 0.003], [63712.2, 12.07], [64065.1, 1.935], [64259.4, 0.0], [64501.4, 0.013], [64542.9, 1.246], [64554.4, 3.378], [64571.4, 2.467], [64571.5, 0.839], [64582.7, 0.0], [64694.1, 0.019], [64704.0, 0.6], [64704.1, 0.157], [64705.3, 0.565], [64705.4, 0.113], [64712.2, 8.513]], "asks": [[64714.4, 0.017], [64719.9, 0.003], [64721.9, 0.001], [64722.9, 0.0], [64723.5, 0.107], [64723.8, 0.216], [64726.1, 0.219], [64729.7, 2.185], [64730.2, 0.003], [64730.9, 0.136], [64742.6, 3.495], [64783.2, 0.376], [64783.3, 0.0], [64787.7, 36.188], [64853.0, 5.397], [64868.5, 0.125], [64870.0, 6.964], [64889.6, 0.024], [64931.2, 0.343], [65035.9, 3.076], [65039.0, 1.104], [65337.2, 7.145], [65359.4, 0.0], [65492.0, 13.864], [65500.7, 16.863], [65657.1, 4.456], [65712.3, 0.007]]}
{"kind": "depth", "E": 1787080105851, "U": 11315329661831, "u": 11315329669135, "recv_ms": 1787080105791, "bids": [[1000.0, 35.81], [14212.2, 2.436], [14612.2, 1.764], [51770.0, 0.0], [58240.9, 0.002], [61476.5, 0.001], [61476.6, 0.008], [62123.7, 0.0], [63870.9, 4.379], [64065.1, 1.935], [64087.9, 0.0], [64702.9, 0.004], [64712.2, 8.422]], "asks": [[64714.4, 0.172], [64719.9, 0.158], [64721.9, 0.466], [64726.1, 0.374], [64734.8, 0.551], [64742.6, 3.495], [64742.7, 0.224], [64870.0, 10.514], [65296.0, 3.643], [65337.2, 6.458], [65359.4, 0.0], [65456.9, 0.013], [65488.8, 20.032], [65823.6, 0.049], [65888.3, 0.015]]}
{"kind": "depth", "E": 1787080105953, "U": 11315329669386, "u": 11315329675432, "recv_ms": 1787080105892, "bids": [[14212.2, 2.072], [14612.2, 2.128], [58240.9, 0.002], [61476.5, 0.0], [61774.1, 0.0], [62123.7, 0.003], [63712.2, 12.09], [64065.1, 1.935], [64388.6, 3.117], [64621.8, 0.003], [64621.9, 0.008], [64694.8, 0.476], [64698.0, 0.124], [64704.0, 0.129], [64704.1, 0.157], [64712.2, 8.421]], "asks": [[64714.4, 0.017], [64719.9, 0.003], [64721.9, 0.001], [64726.1, 0.219], [64730.8, 0.042], [64730.9, 0.118], [64785.5, 35.993], [64787.7, 0.224], [65035.9, 3.231], [65327.1, 2.595], [65359.4, 0.0], [65488.8, 20.49], [65653.8, 19.131], [65712.3, 0.027]]}
{"kind": "depth", "E": 1787080106055, "U": 11315329675435, "u": 11315329681689, "recv_ms": 1787080105994, "bids": [[1000.0, 35.81], [14212.2, 1.722], [14612.2, 2.478], [58240.9, 0.002], [61476.5, 0.0], [63225.8, 0.052], [63776.9, 22.089], [64065.0, 0.022], [64065.1, 1.935], [64694.8, 0.005], [64697.0, 1.817], [64700.6, 0.404], [64704.0, 0.6], [64704.1, 0.195], [64705.7, 0.195], [64707.1, 0.379], [64707.6, 0.233], [64712.2, 8.3]], "asks": [[64714.4, 0.017], [64719.9, 0.003], [64721.9, 0.001], [64726.1, 0.219], [64870.0, 10.514], [65195.9, 2.6], [65327.1, 3.282], [65359.4, 0.0]]}
{"kind": "depth", "E": 1787080106157, "U": 11315329681724, "u": 11315329688390, "recv_ms": 1787080106097, "bids": [[14212.2, 1.372], [14612.2, 2.828], [51770.0, 0.0], [58240.9, 0.002], [61476.5, 0.0], [62123.7, 0.0], [63418.0, 2.692], [63429.4, 1.003], [63501.3, 0.059], [63573.3, 0.843], [63645.2, 0.058], [63712.2, 12.07], [63717.1, 0.058], [63725.1, 0.06], [63725.3, 0.0], [63789.0, 1.894], [63800.9, 0.002], [63860.9, 0.058], [63878.5, 2.344], [63932.8, 3.182], [64004.7, 0.068], [64065.1, 1.937], [64076.7, 1.092], [64078.0, 0.709], [64663.6, 2.126], [64669.8, 0.002], [64694.8, 0.468], [64700.6, 0.399], [64704.0, 0.137], [64704.8, 0.465], [64710.3, 0.085], [64712.2, 8.4]], "asks": [[64712.3, 15.105], [64712.7, 0.001], [64714.4, 0.017], [64719.9, 0.003], [64721.9, 0.001], [64726.1, 0.219], [64784.8, 0.037], [65359.4, 0.0], [65371.1, 0.074], [65424.1, 3.942], [65443.1, 0.834], [65515.0, 0.059], [65586.9, 0.059], [65658.8, 0.058], [65699.2, 0.028], [65699.3, 1.302], [65712.3, 0.007], [65730.7, 0.072], [65802.6, 0.667], [65813.6, 1.32], [65874.5, 0.06], [65878.3, 1.319], [65946.5, 0.058], [66006.5, 0.015], [66018.4, 0.068]]}
{"kind": "depth", "E": 1787080106259, "U": 11315329688418, "u": 11315329696110, "recv_ms": 1787080106199, "bids": [[14212.2, 1.022], [14612.2, 3.178], [51770.0, 0.004], [58240.9, 0.002], [62123.7, 0.003], [63773.9, 27.554], [64065.1, 1.935], [64388.6, 3.127], [64673.3, 0.065]], "asks": [[64742.7, 0.224], [65359.4, 0.0], [65479.6, 2.916], [65650.6, 13.214], [65699.2, 0.047]]}
{"kind": "depth", "E": 1787080106361, "U": 11315329696228, "u": 11315329703079, "recv_ms": 1787080106300, "bids": [[1000.0, 35.81], [14212.2, 0.644], [14612.2, 3.556], [51770.0, 0.0], [58240.9, 0.002], [61476.5, 0.0], [61476.6, 0.008], [61476.7, 0.006], [62123.7, 0.0], [63712.2, 12.09], [64065.1, 1.935], [64194.5, 6.396], [64571.4, 2.917], [64694.8, 0.013], [64695.0, 0.004], [64704.0, 0.129], [64704.2, 0.68], [64704.3, 0.709], [64712.2, 8.45]], "asks": [[64712.3, 15.104], [64713.3, 0.0], [64714.4, 0.017], [64719.9, 0.003], [64721.9, 0.001], [64726.1, 0.219], [64728.7, 0.931], [64731.2, 3.209], [64733.7, 0.153], [64736.1, 0.624], [64853.0, 5.397], [64869.9, 7.559], [64870.0, 0.109], [65359.4, 0.0], [65712.3, 0.027], [66342.1, 0.743]]}
{"kind": "depth", "E": 1787080106463, "U": 11315329703295, "u": 11315329708746, "recv_ms": 1787080106402, "bids": [[14212.2, 0.364], [14512.2, 0.07], [14612.2, 3.766], [58240.9, 0.002], [61476.5, 0.0], [62123.7, 0.003], [63725.4, 2.197], [64065.1, 1.935], [64148.6, 0.032], [64194.5, 6.392], [64673.3, 0.079], [64694.8, 0.476], [64703.9, 0.146], [64704.1, 0.041], [64704.3, 0.787], [64705.3, 0.565], [64710.3, 0.001], [64712.2, 8.429]], "asks": [[64713.2, 0.086], [64714.4, 0.017], [64719.9, 0.003], [64721.9, 0.001], [64726.1, 0.219], [64869.9, 10.423], [65306.5, 4.434], [65359.4, 0.0], [65469.4, 1.831]]}
{"kind": "depth", "E": 1787080106565, "U": 11315329709082, "u": 11315329715685, "recv_ms": 1787080106504, "bids": [[14212.2, 0.238], [14512.2, 0.308], [14612.2, 3.654], [58240.9, 0.002], [61476.5, 0.0], [63418.0, 2.686], [63712.2, 12.07], [64065.1, 1.935], [64388.6, 3.117], [64596.7, 3.865], [64596.8, 3.347], [64641.0, 0.323], [64666.9, 0.54], [64670.4, 1.278], [64683.8, 0.027], [64697.0, 0.917], [64698.0, 1.024], [64704.3, 0.246], [64704.8, 0.464], [64705.4, 0.654], [64705.7, 0.195], [64712.2, 8.429]], "asks": [[64712.3, 15.103], [64714.4, 0.017], [64719.9, 0.003], [64721.9, 0.001], [64726.1, 0.219], [64748.7, 0.001], [64783.5, 0.048], [64796.2, 0.0], [64847.8, 4.811], [64884.7, 0.0], [64913.0, 0.003], [64913.1, 0.014], [65359.4, 0.0], [65712.3, 0.007], [66330.1, 0.006]]}
{"kind": "depth", "E": 1787080106667, "U": 11315329715740, "u": 11315329722896, "recv_ms": 1787080106613, "bids": [[1000.0, 35.81], [14212.2, 0.112], [14512.2, 0.532], [14612.2, 3.556], [51769.8, 0.0], [58240.9, 0.002], [61476.5, 0.0], [62123.7, 0.0], [63702.9, 0.672], [63709.2, 7.459], [64065.1, 1.935], [64149.2, 1.169], [64444.7, 1.758], [64666.4, 0.001], [64694.8, 0.005], [64696.2, 0.005], [64697.0, 1.817], [64698.0, 0.124], [64703.9, 0.687], [64704.0, 0.6], [64704.2, 0.062], [64704.3, 0.246], [64705.4, 0.113], [64712.2, 8.417]], "asks": [[64712.6, 0.086], [64714.4, 0.172], [64719.2, 0.008], [64719.9, 0.158], [64721.9, 0.466], [64726.1, 0.374], [64728.7, 0.931], [64755.9, 1.037], [64756.0, 3.515], [64784.0, 8.164], [64784.8, 0.019], [64868.5, 2.284], [64869.9, 7.559], [64909.9, 0.967], [65359.4, 0.0], [65631.2, 0.91], [71183.5, 0.01]]}
{"kind": "depth", "E": 1787080106769, "U": 11315329723194, "u": 11315329727966, "recv_ms": 1787080106708, "bids": [[14212.2, 0.0], [14512.2, 0.77], [14612.2, 3.43], [58240.9, 0.002], [62123.7, 0.003], [62174.3, 0.001], [63226.5, 0.001], [63418.0, 2.689], [63595.9, 0.0], [63712.2, 12.09], [63903.3, 3.166], [63935.6, 0.781], [64065.1, 1.935], [64582.7, 0.0], [64659.2, 0.038], [64666.9, 0.537], [64679.8, 0.005], [64712.2, 8.402]], "asks": [[64714.4, 0.017], [64719.9, 0.003], [64721.9, 0.001], [64726.1, 0.219], [64770.6, 0.378], [65035.9, 3.23], [65233.1, 2.755], [65296.0, 3.872], [65359.4, 0.0], [65477.2, 0.0], [65712.3, 0.027], [71183.5, 0.008]]}
{"kind": "depth", "E": 1787080106871, "U": 11315329727984, "u": 11315329733143, "recv_ms": 1787080106811, "bids": [[14512.2, 1.134], [14612.2, 3.066], [58240.9, 0.002], [61476.5, 0.0], [61774.8, 0.001], [62123.7, 0.0], [64065.1, 1.935], [64141.3, 2.184], [64388.6, 3.118], [64554.4, 4.255], [64571.4, 2.925], [64694.8, 0.476], [64703.9, 0.146], [64704.0, 0.129], [64704.1, 0.582], [64705.3, 0.543], [64705.4, 0.113], [64710.3, 0.085], [64712.2, 8.495]], "asks": [[64712.6, 0.002], [64714.4, 0.017], [64719.9, 0.003], [64721.9, 0.001], [64726.1, 0.219], [64853.0, 5.397], [64869.9, 7.483], [65359.4, 0.0], [65653.8, 18.066], [67308.9, 0.0]]}
{"kind": "depth", "E": 1787080106973, "U": 11315329733179, "u": 11315329737890, "recv_ms": 1787080106913, "bids": [[1000.0, 35.81], [14512.2, 1.498], [14612.2, 2.702], [58240.9, 0.002], [61476.5, 0.0], [62123.7, 0.003], [63712.2, 12.07], [64065.1, 1.935], [64388.6, 3.119], [64695.6, 0.002], [64696.6, 0.939], [64697.0, 0.917], [64698.0, 1.024], [64704.1, 0.041], [64705.4, 0.654], [64705.5, 0.501], [64712.2, 8.554]], "asks": [[64714.4, 0.017], [64719.9, 0.003], [64721.9, 0.001], [64726.1, 0.219], [64746.0, 0.693], [64869.9, 10.423], [65035.9, 3.229], [65037.9, 0.108], [65359.4, 0.0], [65492.0, 12.034], [65631.2, 1.137], [65650.6, 14.279], [65712.3, 0.007], [65922.4, 0.909]]}
{"kind": "depth", "E": 1787080107075, "U": 11315329737918, "u": 11315329743120, "recv_ms": 1787080107015, "bids": [[14512.2, 1.848], [14612.2, 2.352], [58240.9, 0.002], [61476.5, 0.001], [63789.9, 0.013], [64065.1, 1.935], [64161.9, 3.61], [64621.7, 0.133], [64621.8, 0.0], [64659.2, 0.034], [64666.4, 0.005], [64668.1, 0.0], [64673.3, 0.065], [64700.6, 0.399], [64705.5, 0.501], [64706.4, 0.004], [64707.0, 0.071], [64707.7, 0.416], [64711.1, 0.084], [64711.7, 0.014], [64712.2, 8.64]], "asks": [[64712.3, 15.021], [64713.2, 0.002], [64713.7, 0.081], [64714.4, 0.172], [64716.7, 0.086], [64718.7, 0.404], [64719.5, 0.001], [64719.9, 0.158], [64721.9, 0.466], [64726.1, 0.374], [64761.5, 0.118], [65057.9, 2.448], [65230.0, 2.52], [65359.4, 0.0], [65488.8, 22.014], [65489.5, 0.0], [65500.7, 16.65], [65634.5, 0.002], [66654.0, 0.0]]}
{"kind": "depth", "E": 1787080107177, "U": 11315329743179, "u": 11315329748015, "recv_ms": 1787080107117, "bids": [[14512.2, 2.198], [14612.2, 2.002], [58240.9, 0.002], [61476.5, 0.0], [62123.7, 0.0], [63579.7, 3.218], [63712.2, 12.09], [63725.1, 0.06], [63789.9, 0.021], [63791.6, 0.018], [64065.1, 1.935], [64129.8, 30.661], [64388.6, 3.119], [64633.2, 0.035], [64663.6, 2.127], [64668.1, 0.014], [64669.8, 0.003], [64673.3, 0.079], [64697.0, 1.817], [64698.0, 0.124], [64703.9, 0.687], [64705.1, 0.042], [64705.4, 0.501], [64705.5, 0.113], [64705.7, 0.195], [64707.0, 0.068], [64707.3, 0.001], [64707.8, 0.125], [64711.1, 0.0], [64712.2, 8.515]], "asks": [[64712.3, 15.023], [64713.1, 0.085], [64714.4, 0.017], [64714.5, 0.444], [64719.9, 0.003], [64721.9, 0.001], [64726.1, 0.219], [64758.9, 0.042], [64761.5, 0.076], [64869.9, 7.483], [65359.4, 0.0], [65632.8, 0.0], [65699.2, 0.039], [65712.3, 0.027], [65893.1, 0.0]]}
{"kind": "depth", "E": 1787080107279, "U": 11315329748221, "u": 11315329754278, "recv_ms": 1787080107221, "bids": [[1000.0, 35.81], [14512.2, 2.562], [14612.2, 1.638], [58240.9, 0.002], [61476.5, 0.0], [62123.7, 0.003], [63838.6, 2.016], [63903.3, 3.399], [64052.2, 0.0], [64065.1, 1.935], [64248.8, 0.311], [64694.8, 0.476], [64695.5, 0.001], [64697.1, 0.962], [64704.0, 0.129], [64705.4, 0.307], [64706.2, 0.198], [64707.7, 0.106], [64712.2, 8.359]], "asks": [[64712.3, 15.021], [64713.2, 0.002], [64713.6, 0.003], [64714.5, 0.444], [64719.9, 0.003], [64721.9, 0.001], [64726.1, 0.219], [64728.7, 0.313], [64736.1, 0.006], [64758.9, 0.0], [64759.3, 0.061], [64766.0, 0.229], [64869.9, 10.423], [65359.4, 0.0], [65488.8, 23.844], [65621.9, 7.785], [65632.8, 0.008], [65634.5, 0.01], [65699.2, 0.047], [66006.5, 0.018]]}
{"kind": "depth", "E": 1787080107381, "U": 11315329754468, "u": 11315329762880, "recv_ms": 1787080107323, "bids": [[14512.2, 2.912], [14612.2, 1.288], [58240.9, 0.002], [62123.7, 0.0], [63712.2, 12.07], [63725.4, 1.1], [64065.1, 1.935], [64406.5, 0.001], [64471.3, 0.003], [64536.1, 0.028], [64600.9, 0.343], [64705.4, 0.113], [64705.5, 0.113], [64705.6, 0.212], [64706.2, 0.004]], "asks": [[64783.3, 35.658], [64784.0, 2.878], [64785.5, 0.029], [65359.4, 0.0], [65712.3, 0.007]]}
{"kind": "depth", "E": 1787080107483, "U": 11315329763075, "u": 11315329769153, "recv_ms": 1787080107589, "bids": [[1000.0, 35.81], [14512.2, 3.276], [14612.2, 0.924], [58240.9, 0.002], [61476.5, 0.0], [63961.0, 1.566], [64065.1, 1.935], [64197.6, 1.256], [64340.5, 0.477], [64388.6, 3.129], [64405.2, 0.477], [64469.9, 0.499], [64515.5, 0.0], [64515.6, 3.247], [64534.6, 0.78], [64571.4, 2.034], [64656.5, 0.004], [64656.9, 0.331], [64664.3, 0.014], [64665.9, 0.003], [64671.4, 0.0], [64694.8, 0.005], [64696.3, 0.859], [64697.1, 0.962], [64703.6, 0.62], [64704.0, 0.6], [64705.4, 0.113], [64705.5, 0.307], [64705.6, 0.018], [64705.7, 0.195], [64712.2, 8.447]], "asks": [[64712.3, 15.023], [64714.5, 0.444], [64719.9, 0.003], [64721.9, 0.001], [64726.1, 0.219], [64728.2, 0.62], [64735.5, 0.618], [64740.4, 10.052], [64742.2, 0.077], [64749.7, 0.002], [64783.3, 0.0], [64784.8, 0.037], [64787.7, 35.98], [64853.0, 5.397], [65233.1, 1.837], [65359.4, 0.0]]}
{"kind": "depth", "E": 1787080107585, "U": 11315329769392, "u": 11315329776527, "recv_ms": 1787080107591, "bids": [[1000.0, 35.81], [14512.2, 3.64], [14612.2, 0.56], [51770.0, 0.0], [58240.9, 0.002], [61476.5, 0.0], [62123.7, 0.003], [63712.2, 12.09], [63822.6, 9.349], [64065.1, 1.937], [64515.6, 7.783], [64518.1, 1.32], [64554.4, 4.241], [64571.4, 2.917], [64571.5, 1.165], [64646.4, 2.229], [64664.3, 0.0], [64671.5, 0.019], [64694.8, 0.005], [64696.0, 0.379], [64697.0, 0.917], [64697.1, 0.96], [64698.0, 1.024], [64703.9, 0.687], [64704.0, 0.137], [64704.1, 0.504], [64705.3, 0.543], [64705.4, 0.113], [64705.5, 0.307], [64705.7, 0.195], [64712.2, 8.4]], "asks": [[64714.5, 0.599], [64718.6, 0.037], [64719.6, 0.0], [64719.9, 0.158], [64721.9, 0.466], [64726.1, 0.374], [64779.7, 2.611], [64780.0, 0.01], [64784.0, 8.133], [64785.5, 35.785], [64787.7, 0.224], [64853.0, 4.654], [64869.9, 10.423], [64908.8, 13.681], [65359.4, 0.0], [65488.8, 24.057], [65611.8, 6.31], [65712.3, 0.027]]}
{"kind": "depth", "E": 1787080107687, "U": 11315329776534, "u": 11315329782279, "recv_ms": 1787080107627, "bids": [[14412.2, 0.112], [14512.2, 3.766], [14612.2, 0.322], [51769.8, 0.0], [58240.9, 0.002], [61476.5, 0.0], [62123.7, 0.0], [63709.2, 8.556], [63804.8, 1.988], [63947.2, 17.838], [64065.1, 1.935], [64391.7, 2.551], [64582.7, 0.0], [64659.2, 0.038], [64666.4, 0.001], [64679.3, 2.385], [64679.5, 0.052], [64680.0, 3.044], [64680.8, 0.0], [64681.0, 0.008], [64690.1, 1.353], [64690.2, 0.627], [64694.8, 0.468], [64695.4, 0.946], [64696.0, 0.379], [64696.1, 0.003], [64696.2, 0.005], [64696.6, 0.014], [64698.0, 1.024], [64700.6, 0.245], [64700.7, 0.416], [64700.8, 1.038], [64703.9, 0.022], [64704.0, 0.129], [64704.1, 0.049], [64705.3, 1.084], [64705.4, 0.501], [64705.5, 0.113], [64705.7, 0.041], [64710.1, 0.085], [64710.3, 0.001], [64712.2, 8.341]], "asks": [[64712.3, 15.025], [64714.5, 0.599], [64715.2, 0.004], [64715.4, 1.226], [64719.9, 0.158], [64721.9, 0.466], [64726.1, 0.374], [64728.5, 0.926], [64728.7, 0.313], [64728.9, 0.164], [64729.5, 0.005], [64730.3, 0.004], [64731.1, 1.329], [64731.2, 3.765], [64731.9, 5.097], [64732.8, 2.286], [64733.3, 1.571], [64733.9, 0.013], [64734.3, 0.01], [64734.8, 0.551], [64735.4, 0.382], [64784.8, 0.019], [64912.9, 3.247], [64913.0, 0.0], [65037.1, 0.372], [65039.0, 0.95], [65233.1, 1.531], [65359.4, 0.0], [65492.0, 11.273], [65732.1, 1.064]]}
{"kind": "depth", "E": 1787080107789, "U": 11315329782394, "u": 11315329787939, "recv_ms": 1787080107794, "bids": [[1000.0, 35.81], [14412.2, 0.35], [14512.2, 3.64], [14612.2, 0.21], [58240.9, 0.002], [62123.7, 0.003], [63712.2, 12.07], [63812.7, 5.599], [63835.5, 0.012], [63965.0, 5.59], [64065.1, 1.935], [64194.5, 7.325], [64388.6, 3.129], [64694.8, 0.005], [64700.7, 0.262], [64703.9, 1.026], [64705.3, 0.543], [64705.4, 0.113], [64705.5, 0.113], [64705.6, 0.212]], "asks": [[64714.5, 0.444], [64715.2, 0.014], [64719.9, 0.003], [64721.9, 0.001], [64726.1, 0.219], [64869.9, 7.484], [65230.0, 3.438], [65309.0, 0.044], [65359.4, 0.0], [65505.5, 10.9], [65712.3, 0.007], [65715.3, 2.188], [66006.5, 0.021]]}
{"kind": "depth", "E": 1787080107891, "U": 11315329788169, "u": 11315329793766, "recv_ms": 1787080107832, "bids": [[1000.0, 35.81], [14412.2, 0.588], [14512.2, 3.528], [14612.2, 0.084], [58240.9, 0.002], [61476.5, 0.0], [62123.7, 0.0], [63104.1, 1.583], [63776.9, 20.993], [63793.7, 3.111], [63859.7, 0.782], [63971.1, 5.073], [64065.1, 1.935], [64388.6, 3.128], [64659.2, 0.034], [64671.2, 1.043], [64700.6, 0.399], [64705.4, 0.501], [64705.6, 0.018], [64712.2, 8.311]], "asks": [[64714.5, 0.444], [64715.2, 0.014], [64719.9, 0.003], [64721.9, 0.001], [64726.1, 0.219], [64869.9, 10.423], [65035.9, 3.383], [65230.0, 3.744], [65359.4, 0.0], [65488.8, 24.818], [65750.8, 4.678]]}
{"kind": "depth", "E": 1787080107993, "U": 11315329793944, "u": 11315329798253, "recv_ms": 1787080107934, "bids": [[14412.2, 0.854], [14512.2, 3.346], [14612.2, 0.0], [58240.9, 0.002], [61476.5, 0.0], [63621.2, 0.698], [63712.2, 12.09], [63753.0, 3.802], [63776.5, 0.939], [63776.9, 18.802], [63804.8, 1.754], [63825.6, 1.25], [63955.1, 0.547], [63971.1, 4.137], [64065.1, 1.937], [64388.6, 3.282], [64657.0, 0.0], [64657.3, 0.122], [64657.6, 1.475], [64658.0, 0.023], [64658.3, 0.0], [64674.5, 0.002], [64674.7, 0.196], [64674.8, 0.238], [64675.1, 1.914], [64675.4, 0.0], [64675.8, 0.001], [64689.4, 1.082], [64689.5, 0.053], [64689.6, 1.326], [64689.7, 0.001], [64689.9, 0.0], [64690.0, 0.305], [64690.1, 0.828], [64690.2, 0.557], [64690.3, 0.17], [64691.1, 0.469], [64691.5, 0.004], [64700.5, 0.158], [64700.6, 0.245], [64704.1, 0.049], [64704.8, 0.466], [64705.1, 0.04], [64705.4, 0.113], [64705.7, 0.041], [64706.2, 0.128], [64707.8, 0.001], [64708.1, 0.088], [64708.2, 0.016], [64708.3, 0.096], [64708.4, 0.001], [64708.5, 0.086], [64708.6, 0.095], [64708.7, 0.103], [64708.8, 0.003], [64708.9, 0.085], [64709.0, 0.004], [64709.1, 0.009], [64709.4, 0.102], [64709.6, 0.034], [64709.7, 0.09], [64710.0, 0.01], [64710.4, 0.009], [64710.5, 0.089], [64710.7, 0.013], [64712.2, 8.425]], "asks": [[64713.1, 0.001], [64713.8, 0.086], [64714.5, 0.444], [64715.2, 0.004], [64719.9, 0.003], [64721.7, 0.002], [64721.9, 0.001], [64722.0, 2.438], [64722.3, 1.044], [64722.4, 1.987], [64722.7, 2.761], [64723.0, 0.003], [64723.3, 0.382], [64723.4, 0.245], [64723.5, 0.007], [64723.6, 0.383], [64723.7, 0.004], [64723.8, 0.006], [64723.9, 0.011], [64724.0, 0.158], [64724.1, 0.001], [64724.2, 0.002], [64724.3, 0.047], [64726.1, 0.219], [64728.2, 0.002], [64739.2, 4.709], [64739.5, 0.012], [64739.8, 1.04], [64740.1, 0.059], [64740.4, 10.017], [64740.8, 1.279], [64741.3, 1.328], [64742.0, 0.007], [64742.1, 0.077], [64742.2, 0.0], [64742.3, 0.463], [64742.4, 0.009], [64742.5, 0.003], [64742.6, 3.395], [64742.7, 0.154], [64742.8, 0.016], [64742.9, 0.154], [64743.0, 0.001], [64756.6, 0.033], [64757.0, 0.0], [64757.3, 0.035], [64757.6, 0.0], [64757.9, 0.096], [65035.9, 3.385], [65299.5, 0.229], [65359.4, 0.0], [65488.9, 9.887], [65712.3, 0.027]]}
{"kind": "depth", "E": 1787080108095, "U": 11315329798368, "u": 11315329803189, "recv_ms": 1787080108035, "bids": [[1000.0, 35.81], [14412.2, 1.218], [14512.2, 2.982], [58240.9, 0.002], [61476.5, 0.001], [62123.7, 0.003], [63418.0, 2.692], [63919.6, 1.562], [63968.0, 6.894], [64065.1, 1.935], [64388.6, 3.272], [64403.3, 0.001], [64679.8, 0.005], [64700.6, 0.245], [64705.4, 0.113], [64708.0, 0.076], [64708.3, 0.166], [64712.2, 8.412]], "asks": [[64714.5, 0.599], [64715.2, 0.014], [64719.9, 0.158], [64721.9, 0.466], [64723.7, 0.081], [64723.9, 0.081], [64726.1, 0.374], [64742.4, 0.086], [64742.7, 0.224], [64770.6, 0.378], [64853.0, 5.397], [64869.9, 10.423], [64908.8, 15.411], [65359.4, 0.0], [65630.1, 29.719]]}
{"kind": "depth", "E": 1787080108197, "U": 11315329803256, "u": 11315329808891, "recv_ms": 1787080108136, "bids": [[1000.0, 35.81], [14412.2, 1.568], [14512.2, 2.632], [58240.9, 0.002], [61476.5, 0.0], [62123.7, 0.0], [63712.2, 12.07], [63773.9, 30.841], [63938.7, 15.342], [63968.0, 7.83], [64065.1, 1.935], [64197.6, 0.945], [64571.4, 2.477], [64571.5, 0.839], [64600.0, 14.524], [64669.8, 0.004], [64674.4, 0.043], [64675.0, 0.818], [64675.3, 0.107], [64690.2, 0.561], [64700.4, 0.156], [64700.5, 0.004], [64704.6, 0.002], [64705.4, 0.307], [64705.7, 0.041], [64706.2, 0.004], [64706.8, 0.255], [64707.5, 0.001], [64708.2, 0.086], [64708.7, 0.203], [64708.8, 0.173], [64708.9, 0.185], [64709.0, 0.003], [64709.3, 0.12], [64709.9, 0.048], [64710.3, 0.036], [64712.2, 8.321]], "asks": [[64713.2, 0.0], [64713.3, 0.084], [64714.5, 0.444], [64715.2, 0.014], [64719.9, 0.003], [64721.7, 0.034], [64721.9, 0.001], [64722.0, 2.473], [64722.7, 2.796], [64723.1, 0.208], [64723.2, 2.266], [64723.3, 0.492], [64723.8, 0.076], [64726.1, 0.219], [64739.2, 4.741], [64739.5, 0.047], [64740.1, 0.094], [64740.5, 0.308], [64741.9, 0.181], [64742.0, 0.117], [64742.5, 0.073], [64756.6, 0.065], [64756.9, 0.05], [64757.6, 0.035], [64853.0, 5.397], [64869.9, 6.886], [65359.4, 0.0], [65712.3, 0.007], [65747.7, 1.063]]}
{"kind": "depth", "E": 1787080108299, "U": 11315329809115, "u": 11315329817245, "recv_ms": 1787080108240, "bids": [[14412.2, 1.932], [14512.2, 2.268], [51770.0, 0.0], [58240.9, 0.002], [61476.5, 0.0], [62123.7, 0.003], [63618.6, 4.871], [63712.2, 12.09], [63741.5, 3.462], [63882.5, 3.913], [63903.3, 4.18], [63971.1, 3.2], [64065.1, 1.935], [64388.6, 3.282], [64657.2, 0.063], [64675.7, 0.225], [64690.2, 0.005], [64690.8, 0.558], [64692.0, 1.51], [64692.6, 0.117], [64704.1, 0.203], [64705.4, 0.113], [64705.7, 0.195], [64706.8, 0.131], [64707.2, 0.217], [64708.1, 0.158], [64708.2, 0.156], [64708.4, 0.101], [64708.5, 0.286], [64708.6, 0.195], [64709.0, 0.073], [64710.5, 0.005], [64710.6, 0.032], [64712.2, 8.359]], "asks": [[64712.3, 15.026], [64714.5, 0.599], [64715.2, 0.004], [64719.9, 0.158], [64721.4, 0.038], [64721.9, 0.466], [64723.0, 0.094], [64723.4, 0.345], [64723.5, 0.217], [64723.6, 0.483], [64723.7, 0.165], [64723.9, 0.151], [64726.1, 0.374], [64726.2, 1.246], [64738.6, 0.002], [64738.8, 0.034], [64741.0, 0.135], [64741.7, 0.091], [64742.1, 0.177], [64742.2, 0.1], [64742.3, 0.563], [64742.5, 0.157], [64742.6, 3.465], [64756.3, 0.198], [64869.9, 10.423], [65359.4, 0.0], [65618.3, 7.847], [65712.3, 0.027], [65810.0, 2.189]]}
{"kind": "depth", "E": 1787080108401, "U": 11315329817278, "u": 11315329822614, "recv_ms": 1787080108341, "bids": [[1000.0, 35.81], [14412.2, 2.282], [14512.2, 1.918], [51770.0, 0.0], [58240.9, 0.002], [61476.6, 0.01], [61476.7, 0.004], [62123.7, 0.0], [63697.1, 1.35], [63930.4, 0.0], [63968.0, 8.767], [64065.1, 1.935], [64664.0, 1.196], [64671.2, 1.039], [64671.3, 0.003], [64689.9, 0.07], [64704.1, 0.049], [64704.6, 0.001], [64708.3, 0.236], [64712.2, 8.403]], "asks": [[64712.3, 15.025], [64714.5, 0.444], [64719.9, 0.003], [64721.9, 0.001], [64723.6, 0.553], [64726.1, 0.219], [64739.2, 4.739], [64740.4, 10.019], [64742.4, 0.156], [65359.4, 0.0]]}
{"kind": "depth", "E": 1787080108503, "U": 11315329822685, "u": 11315329827814, "recv_ms": 1787080108444, "bids": [[1000.0, 35.81], [14412.2, 2.646], [14512.2, 1.554], [58240.9, 0.002], [61476.5, 0.0], [61476.6, 0.008], [61476.7, 0.006], [63679.9, 4.393], [63870.9, 4.692], [63935.7, 15.919], [64065.1, 1.935], [64194.5, 7.636], [64515.6, 7.783], [64518.1, 0.735], [64554.4, 4.241], [64571.4, 2.917], [64656.9, 0.363], [64657.6, 1.507], [64657.9, 0.037], [64679.3, 2.328], [64680.6, 0.059], [64689.3, 0.112], [64689.5, 0.123], [64695.4, 0.021], [64696.7, 0.965], [64703.9, 0.485], [64704.1, 0.203], [64705.4, 0.577], [64705.5, 0.113], [64705.6, 0.095], [64705.7, 0.041], [64712.2, 8.405]], "asks": [[64715.4, 1.225], [64728.2, 0.62], [64728.5, 0.001], [64729.2, 1.041], [64731.2, 3.209], [64731.6, 0.559], [64734.8, 0.01], [64735.4, 0.923], [64852.9, 4.712], [64853.0, 0.0], [64868.5, 1.457], [64869.9, 10.423], [64908.8, 13.704], [65359.4, 0.0], [65469.1, 1.544], [65750.8, 3.615], [65805.9, 1.368], [67300.8, 1.374], [70021.1, 0.0]]}
{"kind": "depth", "E": 1787080108605, "U": 11315329827944, "u": 11315329833545, "recv_ms": 1787080108546, "bids": [[14412.2, 2.996], [14512.2, 1.204], [58240.9, 0.002], [61476.5, 0.0], [62123.7, 0.003], [63418.0, 2.689], [63676.8, 1.539], [63712.2, 12.07], [64065.1, 1.935], [64388.6, 3.272], [64518.1, 1.32], [64571.5, 1.165], [64646.9, 2.437], [64655.3, 2.146], [64658.2, 0.033], [64663.6, 2.128], [64666.9, 0.54], [64686.3, 0.034], [64689.4, 1.152], [64690.0, 0.505], [64690.1, 0.898], [64691.4, 0.2], [64694.8, 0.476], [64696.3, 0.241], [64703.6, 0.002], [64703.9, 0.022], [64704.1, 0.041], [64704.5, 0.0], [64705.5, 0.113], [64705.7, 0.195], [64706.8, 0.13], [64708.6, 0.196], [64710.1, 0.001], [64712.2, 8.771]], "asks": [[64712.3, 15.075], [64712.8, 0.084], [64713.7, 0.046], [64715.2, 0.014], [64717.3, 0.163], [64728.2, 0.002], [64735.5, 0.0], [64751.2, 0.008], [64778.6, 2.284], [64782.2, 0.018], [64790.0, 0.027], [64797.4, 2.162], [64805.7, 2.124], [64805.8, 0.011], [64814.1, 2.121], [64814.2, 0.001], [65359.4, 0.0], [65712.3, 0.007], [65747.7, 2.126], [66006.5, 0.015]]}
{"kind": "depth", "E": 1787080108707, "U": 11315329833707, "u": 11315329838544, "recv_ms": 1787080108649, "bids": [[1000.0, 35.81], [14412.2, 3.36], [14512.2, 0.84], [51769.8, 0.0], [58240.9, 0.002], [62123.7, 0.0], [63542.8, 0.009], [63702.9, 0.0], [64065.1, 1.935], [64582.7, 0.0], [64689.3, 0.182], [64689.5, 0.193], [64689.6, 1.496], [64689.8, 2.527], [64690.2, 0.075], [64691.0, 0.1], [64696.2, 0.005], [64705.7, 0.195], [64712.2, 8.703]], "asks": [[64713.2, 0.002], [64715.2, 0.004], [64728.7, 0.313], [64869.9, 7.47], [65359.4, 0.0], [65571.3, 1.523], [66006.5, 0.012]]}
{"kind": "depth", "E": 1787080108809, "U": 11315329838655, "u": 11315329842769, "recv_ms": 1787080108748, "bids": [[1000.0, 35.81], [14312.2, 0.014], [14412.2, 3.682], [14512.2, 0.504], [58240.9, 0.002], [61476.5, 0.0], [62123.7, 0.003], [63712.2, 12.09], [64065.1, 1.935], [64073.4, 0.013], [64694.8, 0.468], [64696.0, 0.379], [64703.9, 0.563], [64704.0, 0.137], [64705.4, 0.113], [64705.6, 0.018], [64705.7, 0.041], [64712.2, 8.702]], "asks": [[64731.9, 0.097], [64869.9, 10.423], [65359.4, 0.0], [65467.7, 0.763], [65488.8, 25.031], [65712.3, 0.027], [66006.5, 0.015]]}
{"kind": "depth", "E": 1787080108911, "U": 11315329842894, "u": 11315329849804, "recv_ms": 1787080108851, "bids": [[14312.2, 0.168], [14412.2, 3.738], [14512.2, 0.294], [58240.9, 0.002], [63938.7, 14.873], [64065.1, 1.935], [64197.6, 0.634], [64388.6, 3.272], [64391.7, 2.396], [64679.7, 0.057], [64680.6, 0.002], [64690.4, 0.56], [64690.8, 0.002], [64692.3, 0.162], [64692.6, 0.001], [64695.0, 0.012], [64695.9, 1.071], [64696.7, 0.04], [64698.0, 0.124], [64704.0, 0.129], [64707.6, 0.002], [64708.0, 0.307], [64712.2, 8.672]], "asks": [[64731.1, 1.885], [64731.6, 0.003], [64734.1, 0.003], [64734.8, 0.551], [64735.4, 0.382], [64742.0, 0.117], [64742.7, 0.07], [64783.3, 35.848], [64784.0, 2.878], [64785.5, 0.029], [64869.9, 7.47], [65359.4, 0.0], [65694.1, 0.0], [65882.9, 8.19]]}
{"kind": "depth", "E": 1787080109013, "U": 11315329849934, "u": 11315329854156, "recv_ms": 1787080108952, "bids": [[1000.0, 35.81], [14312.2, 0.406], [14412.2, 3.612], [14512.2, 0.182], [58240.9, 0.002], [61476.5, 0.0], [62123.7, 0.0], [63712.2, 12.07], [63776.9, 17.706], [63971.1, 2.263], [64032.7, 1.548], [64065.1, 1.937], [64097.4, 10.185], [64107.3, 7.718], [64695.0, 0.004], [64697.0, 1.817], [64704.0, 0.137], [64712.2, 8.583]], "asks": [[64741.9, 0.181], [64742.0, 0.117], [64742.1, 0.331], [64869.9, 10.423], [65035.9, 3.383], [65179.5, 0.115], [65359.4, 0.0], [65555.1, 1.841], [65712.3, 0.007]]}
{"kind": "depth", "E": 1787080109115, "U": 11315329854198, "u": 11315329858710, "recv_ms": 1787080109054, "bids": [[1000.0, 35.81], [14312.2, 0.644], [14412.2, 3.5], [14512.2, 0.056], [51770.0, 0.002], [58240.9, 0.002], [61476.5, 0.0], [62123.7, 0.003], [63773.9, 31.937], [63804.8, 1.52], [63938.7, 12.999], [63968.0, 9.704], [64065.1, 2.091], [64194.5, 7.947], [64388.6, 3.429], [64388.9, 1.36], [64695.0, 0.012], [64700.6, 0.245], [64703.1, 0.327], [64704.0, 0.129], [64705.7, 0.195], [64712.2, 8.715]], "asks": [[64712.3, 15.08], [64719.7, 0.005], [64721.8, 0.004], [65359.4, 0.002]]}
{"kind": "depth", "E": 1787080109217, "U": 11315329858718, "u": 11315329864483, "recv_ms": 1787080109160, "bids": [[14312.2, 0.952], [14412.2, 3.248], [14512.2, 0.0], [51770.0, 0.0], [58240.9, 0.002], [62123.7, 0.0], [63679.9, 3.295], [63712.2, 12.09], [63881.9, 0.0], [63914.8, 0.666], [63956.8, 1.562], [64065.1, 2.091], [64388.6, 3.439], [64571.4, 2.92], [64571.5, 0.839], [64621.5, 0.003], [64621.7, 0.13], [64705.7, 0.195], [64712.2, 8.699]], "asks": [[64852.9, 5.455], [64912.8, 0.005], [64912.9, 3.244], [65359.4, 0.0], [65653.8, 17.001], [65684.1, 1.324], [65712.3, 0.027]]}
{"kind": "depth", "E": 1787080109319, "U": 11315329864543, "u": 11315329869168, "recv_ms": 1787080109259, "bids": [[1000.0, 35.81], [14312.2, 1.302], [14412.2, 2.898], [58240.9, 0.002], [61476.5, 0.0], [62123.7, 0.003], [63418.0, 2.686], [64065.1, 2.091], [64571.4, 2.92], [64634.5, 0.0], [64666.9, 0.537], [64673.3, 0.082], [64679.8, 0.002], [64704.1, 0.195], [64705.7, 0.041], [64706.4, 0.088], [64709.7, 0.006], [64712.2, 8.664]], "asks": [[64712.3, 15.162], [64714.0, 0.006], [64716.7, 0.002], [64719.7, 0.004], [64770.6, 0.375], [64822.4, 0.014], [64852.9, 5.455], [64906.5, 0.003], [65170.0, 0.818], [65359.4, 0.0], [65392.1, 0.003], [65500.7, 16.437], [65630.1, 29.536], [66006.5, 0.018]]}
{"kind": "depth", "E": 1787080109421, "U": 11315329869272, "u": 11315329873212, "recv_ms": 1787080109361, "bids": [[1000.0, 35.81], [14312.2, 1.652], [14412.2, 2.548], [51770.0, 0.0], [58240.9, 0.002], [61476.5, 0.0], [61476.6, 0.01], [63647.5, 4.407], [63676.8, 2.637], [63712.2, 10.973], [63750.6, 2.353], [63776.9, 16.61], [63793.3, 0.707], [63870.8, 1.101], [63935.7, 18.481], [64016.7, 3.505], [64065.1, 2.091], [64712.2, 8.666]], "asks": [[64741.9, 0.181], [64742.1, 0.177], [64869.9, 10.423], [65359.4, 0.0], [65427.8, 5.564], [65650.6, 15.344], [65712.3, 0.007], [65732.1, 0.0]]}
{"kind": "depth", "E": 1787080109523, "U": 11315329873257, "u": 11315329879720, "recv_ms": 1787080109463, "bids": [[14312.2, 2.016], [14412.2, 2.184], [51770.0, 0.002], [58240.9, 0.002], [61476.5, 0.0], [61476.7, 0.004], [62123.7, 0.0], [63679.9, 2.197], [63870.3, 0.015], [64065.1, 2.091], [64388.6, 3.439], [64515.6, 3.261], [64518.1, 0.735], [64554.4, 2.541], [64571.4, 1.485], [64646.4, 0.007], [64692.5, 0.592], [64694.8, 0.005], [64695.0, 0.004], [64695.5, 0.619], [64702.9, 0.622], [64703.0, 0.127], [64704.0, 0.6], [64709.7, 0.09], [64711.8, 0.194], [64712.2, 8.627]], "asks": [[64712.3, 15.08], [64714.0, 0.003], [64727.4, 0.332], [64734.8, 1.169], [64742.0, 0.271], [64779.7, 0.027], [64912.7, 0.005], [64912.8, 0.002], [65359.4, 0.0], [65533.1, 5.139]]}
{"kind": "depth", "E": 1787080109625, "U": 11315329879752, "u": 11315329884981, "recv_ms": 1787080109565, "bids": [[1000.0, 35.81], [14312.2, 2.38], [14412.2, 1.82], [51770.0, 0.0], [58240.9, 0.002], [62123.7, 0.003], [63712.2, 10.993], [63737.6, 0.274], [63773.9, 32.094], [63776.9, 15.514], [63870.9, 5.396], [63914.9, 9.964], [64065.1, 2.091], [64515.6, 7.802], [64518.1, 1.323], [64554.4, 3.396], [64571.4, 2.479], [64646.3, 5.312], [64678.4, 0.008], [64697.0, 0.917], [64698.0, 1.024], [64703.9, 0.022], [64704.1, 0.349], [64705.4, 0.577], [64705.5, 0.113], [64705.6, 0.095], [64712.2, 8.626]], "asks": [[64731.1, 1.329], [64731.8, 0.558], [64734.8, 1.169], [64735.7, 0.191], [64735.9, 0.0], [64736.8, 0.116], [64742.0, 0.117], [64779.5, 2.592], [64783.2, 6.093], [64868.5, 2.113], [64869.9, 10.423], [65359.4, 0.0], [65653.8, 15.936], [65712.3, 0.027], [65715.3, 3.252]]}
{"kind": "depth", "E": 1787080109727, "U": 11315329885011, "u": 11315329889814, "recv_ms": 1787080109667, "bids": [[1000.0, 35.81], [14312.2, 2.73], [14412.2, 1.47], [51769.8, 0.0], [51770.0, 0.0], [58240.9, 0.002], [62123.7, 0.0], [63094.4, 0.633], [63644.4, 1.102], [63676.8, 3.735], [63709.2, 9.653], [63757.8, 3.135], [63773.9, 33.19], [63776.9, 14.418], [63793.3, 0.941], [64006.8, 5.063], [64065.1, 2.091], [64582.7, 0.0], [64679.7, 0.0], [64680.3, 0.102], [64681.2, 1.193], [64690.4, 0.004], [64691.0, 0.656], [64692.0, 1.51], [64695.9, 0.146], [64696.2, 0.005], [64696.4, 0.935], [64697.1, 0.962], [64697.3, 0.212], [64704.1, 0.89], [64705.4, 0.036], [64705.5, 0.501]], "asks": [[64728.7, 0.313], [64729.2, 0.116], [64729.8, 0.927], [64732.2, 0.006], [64733.1, 0.057], [64734.7, 0.765], [64734.8, 0.628], [64735.9, 0.0], [64741.9, 0.335], [64742.0, 0.117], [65359.4, 0.0], [65417.7, 3.507], [66343.6, 0.0]]}
{"kind": "depth", "E": 1787080109829, "U": 11315329889980, "u": 11315329895645, "recv_ms": 1787080109768, "bids": [[14312.2, 3.08], [14412.2, 1.12], [58240.9, 0.002], [61476.5, 0.0], [63712.2, 10.973], [63773.9, 34.286], [64029.7, 1.25], [64065.1, 2.091], [64388.6, 3.429], [64571.4, 2.92], [64571.5, 1.165], [64704.1, 0.736], [64705.4, 0.113], [64705.5, 0.113], [64705.6, 0.018], [64705.7, 0.195], [64712.2, 8.626]], "asks": [[64741.9, 0.181], [64742.0, 0.271], [64852.9, 4.712], [64869.9, 7.469], [65359.4, 0.0], [65630.1, 29.08], [65650.6, 16.409], [65712.3, 0.007], [71183.6, 0.0]]}
{"kind": "depth", "E": 1787080109931, "U": 11315329895803, "u": 11315329900813, "recv_ms": 1787080109871, "bids": [[1000.0, 35.81], [14312.2, 3.444], [14412.2, 0.756], [58240.9, 0.002], [61476.5, 0.0], [62123.7, 0.003], [63418.0, 2.689], [64065.1, 2.091], [64571.4, 2.038], [64571.5, 0.839], [64664.0, 1.192], [64670.1, 0.075], [64694.8, 0.476], [64695.5, 0.001], [64697.1, 0.962], [64702.9, 0.004], [64703.1, 0.326], [64704.0, 0.129], [64704.1, 0.582], [64705.7, 0.195], [64712.2, 8.549]], "asks": [[64712.3, 15.078], [64712.5, 0.002], [64713.6, 0.003], [64714.0, 0.006], [64728.7, 1.238], [64729.8, 0.002], [64731.2, 3.765], [64731.8, 0.002], [64734.8, 0.01], [64735.6, 0.116], [64736.8, 0.001], [64741.3, 3.213], [64741.4, 0.564], [64852.9, 5.455], [64869.9, 10.423], [65359.4, 0.0], [65783.2, 3.195], [66333.3, 3.821]]}
{"kind": "depth", "E": 1787080110033, "U": 11315329900918, "u": 11315329906041, "recv_ms": 1787080109971, "bids": [[1000.0, 35.81], [14212.2, 0.042], [14312.2, 3.71], [14412.2, 0.448], [58240.9, 0.002], [61476.5, 0.0], [62123.7, 0.0], [63712.2, 10.993], [63773.9, 35.382], [63945.2, 4.687], [64065.1, 2.091], [64391.7, 2.373], [64401.4, 0.0], [64571.4, 2.92], [64686.3, 1.077], [64697.1, 0.96], [64702.3, 0.001], [64703.4, 0.16], [64703.8, 1.319], [64712.2, 8.55]], "asks": [[64712.3, 15.08], [64732.3, 5.001], [64741.9, 0.181], [64742.0, 0.117], [64772.2, 0.006], [64783.2, 0.376], [64783.3, 0.0], [64785.5, 35.98], [64787.7, 0.224], [65359.4, 0.0], [65712.3, 0.027], [66006.5, 0.015]]}
{"kind": "depth", "E": 1787080110135, "U": 11315329906058, "u": 11315329911520, "recv_ms": 1787080110075, "bids": [[14212.2, 0.224], [14312.2, 3.71], [14412.2, 0.266], [51769.8, 0.024], [58240.9, 0.002], [61476.5, 0.0], [62123.7, 0.003], [62126.7, 0.01], [63418.0, 2.692], [63924.4, 1.575], [64065.1, 2.091], [64388.6, 3.427], [64668.9, 0.004], [64669.3, 0.061], [64698.6, 0.464], [64700.6, 0.245], [64704.9, 0.457], [64712.2, 8.419]], "asks": [[64713.8, 0.089], [64714.0, 0.003], [64714.4, 0.017], [64714.5, 0.444], [64719.9, 0.003], [64721.5, 0.013], [64721.9, 0.001], [64726.1, 0.219], [64732.1, 0.466], [64741.9, 0.335], [64772.5, 0.035], [64773.0, 0.101], [64782.2, 0.0], [64794.0, 0.066], [64869.9, 10.423], [65035.9, 3.385], [65359.4, 0.0], [65359.5, 0.001], [65436.0, 3.544], [65442.9, 0.763], [65565.6, 1.754]]}
{"kind": "depth", "E": 1787080110237, "U": 11315329911637, "u": 11315329916764, "recv_ms": 1787080110176, "bids": [[1000.0, 35.81], [14212.2, 0.462], [14312.2, 3.584], [14412.2, 0.154], [51769.8, 0.0], [58240.9, 0.002], [62123.7, 0.0], [63524.8, 1.031], [63712.2, 10.973], [63942.1, 4.698], [63952.0, 9.416], [63971.1, 1.326], [64065.1, 2.093], [64141.4, 9.186], [64707.4, 0.014]], "asks": [[64741.9, 0.335], [64742.0, 0.117], [65179.5, 0.0], [65359.4, 0.0], [65425.1, 1.084], [65712.3, 0.007], [65750.8, 2.552], [65780.1, 1.264], [67947.9, 0.02]]}
{"kind": "depth", "E": 1787080110339, "U": 11315329916797, "u": 11315329921685, "recv_ms": 1787080110279, "bids": [[1000.0, 35.81], [14212.2, 0.7], [14312.2, 3.472], [14412.2, 0.028], [51770.0, 0.0], [58240.9, 0.002], [61476.5, 0.0], [63515.0, 2.17], [64065.1, 2.091], [64684.3, 0.001], [64704.9, 0.456], [64709.7, 0.006], [64712.2, 8.433]], "asks": [[64712.3, 15.165], [64714.4, 0.172], [64714.5, 0.444], [64715.2, 0.004], [64719.9, 0.158], [64721.9, 0.466], [64726.1, 0.374], [64741.9, 0.181], [64742.1, 0.331], [65359.4, 0.0], [65553.6, 35.836], [65747.7, 3.189]]}
{"kind": "depth", "E": 1787080110441, "U": 11315329922006, "u": 11315329927415, "recv_ms": 1787080110381, "bids": [[14212.2, 1.022], [14312.2, 3.178], [14412.2, 0.0], [58240.9, 0.002], [61476.5, 0.0], [62123.7, 0.003], [63490.2, 0.701], [63535.3, 1.348], [63697.1, 2.022], [63712.2, 10.993], [63822.6, 7.785], [63968.0, 10.641], [64065.1, 2.091], [64129.8, 30.895], [64388.6, 3.427], [64680.8, 0.336], [64692.3, 0.046], [64692.6, 0.117], [64693.5, 2.338], [64696.0, 0.362], [64703.9, 0.563], [64704.1, 0.041], [64705.4, 0.113], [64705.7, 0.195], [64705.8, 0.215], [64712.2, 8.356]], "asks": [[64714.4, 0.017], [64715.2, 0.004], [64719.9, 0.003], [64721.9, 0.001], [64726.1, 0.219], [64728.7, 0.313], [64729.5, 0.93], [64731.2, 3.209], [64731.9, 0.653], [64734.3, 0.551], [64734.7, 0.224], [64735.6, 0.001], [64735.9, 0.0], [64736.3, 0.296], [64741.2, 0.25], [64741.3, 3.213], [64741.4, 0.564], [64742.0, 0.271], [64742.1, 0.177], [64744.2, 0.002], [64744.3, 0.004], [64744.4, 0.126], [64745.0, 2.959], [64745.1, 1.012], [64745.2, 0.006], [64747.2, 1.398], [64747.3, 0.063], [64747.4, 0.008], [64775.0, 0.0], [64781.6, 0.019], [65170.2, 0.366], [65359.4, 0.0], [65490.9, 1.231], [65570.9, 0.076], [65712.3, 0.027], [66006.5, 0.012]]}
{"kind": "depth", "E": 1787080110543, "U": 11315329927600, "u": 11315329932745, "recv_ms": 1787080110485, "bids": [[1000.0, 35.81], [14212.2, 1.386], [14312.2, 2.814], [58240.9, 0.002], [61476.5, 0.0], [62123.7, 0.0], [63679.9, 1.099], [63776.9, 13.322], [63812.7, 7.163], [64065.1, 2.091], [64141.0, 0.123], [64141.4, 8.952], [64571.4, 0.013], [64615.2, 0.445], [64647.5, 0.004], [64679.8, 0.005], [64694.8, 0.005], [64695.5, 0.619], [64696.0, 0.379], [64702.9, 0.622], [64704.0, 0.6], [64705.7, 0.349], [64705.8, 0.215], [64712.2, 8.355]], "asks": [[64714.4, 0.017], [64715.2, 0.014], [64719.9, 0.003], [64721.9, 0.001], [64726.1, 0.219], [64727.4, 0.332], [64734.3, 0.01], [64734.8, 1.169], [64742.0, 0.117], [64742.1, 0.331], [64770.6, 0.378], [64777.0, 0.076], [64852.9, 0.058], [65306.5, 3.363], [65359.4, 0.0], [65653.8, 14.871], [65750.8, 1.489]]}
{"kind": "depth", "E": 1787080110645, "U": 11315329932832, "u": 11315329937686, "recv_ms": 1787080110585, "bids": [[1000.0, 35.81], [14212.2, 1.736], [14312.2, 2.464], [51770.0, 0.0], [58240.9, 0.002], [61476.5, 0.001], [62123.7, 0.003], [63679.9, 0.001], [63712.2, 10.973], [63804.8, 1.051], [64065.1, 2.093], [64515.6, 3.247], [64518.1, 0.735], [64554.4, 2.534], [64571.4, 1.482], [64668.5, 0.185], [64679.8, 0.002], [64694.8, 0.005], [64704.0, 0.129], [64704.1, 0.504], [64705.8, 0.021], [64707.3, 0.155], [64712.2, 8.297]], "asks": [[64714.4, 0.017], [64715.2, 0.004], [64719.9, 0.003], [64721.9, 0.001], [64726.1, 0.219], [64733.3, 2.733], [64735.9, 10.0], [64770.6, 0.375], [64784.0, 8.159], [64852.9, 4.712], [64869.9, 10.423], [65359.4, 0.0], [65482.4, 4.587], [65712.3, 0.007], [67947.9, 0.025]]}
{"kind": "depth", "E": 1787080110747, "U": 11315329937718, "u": 11315329942354, "recv_ms": 1787080110687, "bids": [[14212.2, 2.1], [14312.2, 2.1], [51769.8, 0.0], [58240.9, 0.002], [61476.5, 0.0], [62123.7, 0.0], [63418.0, 2.692], [63551.4, 0.0], [63558.9, 2.12], [63712.2, 9.876], [63725.4, 0.003], [64065.1, 2.091], [64129.6, 1.091], [64129.8, 31.129], [64388.6, 3.427], [64515.6, 7.783], [64518.1, 1.32], [64554.4, 4.241], [64571.4, 2.917], [64582.7, 0.0], [64621.4, 0.005], [64621.5, 0.0], [64646.3, 5.182], [64694.8, 0.468], [64695.0, 0.004], [64696.2, 0.005], [64699.0, 0.028], [64704.0, 0.137], [64704.1, 0.195], [64705.7, 0.195], [64705.8, 0.021], [64712.2, 8.248]], "asks": [[64712.3, 15.166], [64714.4, 0.172], [64715.2, 0.004], [64719.9, 0.158], [64721.9, 0.466], [64726.1, 0.374], [64728.7, 0.313], [64740.4, 0.019], [64779.4, 2.53], [64779.5, 0.0], [65294.7, 1.76], [65359.4, 0.0], [65485.5, 2.764], [65554.8, 2.59]]}
{"kind": "depth", "E": 1787080110849, "U": 11315329942418, "u": 11315329946989, "recv_ms": 1787080110788, "bids": [[1000.0, 35.81], [14212.2, 2.45], [14312.2, 1.75], [58240.9, 0.002], [61476.5, 0.0], [63676.8, 5.931], [63709.2, 10.75], [63712.2, 9.896], [63773.9, 36.478], [63793.3, 1.175], [64065.1, 2.091], [64712.2, 8.22]], "asks": [[64714.4, 0.172], [64714.5, 0.444], [64715.2, 0.014], [64719.9, 0.158], [64721.9, 0.466], [64726.1, 0.374], [64739.2, 3.446], [64869.9, 6.87], [65359.4, 0.0], [65482.4, 5.502], [65650.6, 17.474], [65712.3, 0.027], [65747.7, 4.252]]}
{"kind": "depth", "E": 1787080110951, "U": 11315329947130, "u": 11315329952491, "recv_ms": 1787080110891, "bids": [[1000.0, 35.81], [14212.2, 2.814], [14312.2, 1.386], [58240.9, 0.002], [61476.5, 0.0], [62123.7, 0.003], [63709.2, 11.847], [63790.1, 0.0], [63903.3, 4.531], [64016.7, 2.726], [64065.1, 2.091], [64673.3, 0.068], [64695.0, 0.012], [64704.0, 0.129], [64706.2, 0.007], [64706.6, 0.002], [64707.4, 0.324], [64710.4, 0.093], [64711.2, 0.342], [64711.7, 0.048], [64712.2, 8.291]], "asks": [[64712.3, 15.052], [64712.8, 0.0], [64713.3, 0.0], [64713.8, 0.002], [64714.4, 0.017], [64714.5, 0.444], [64715.2, 0.004], [64716.7, 0.086], [64717.1, 0.101], [64718.6, 0.018], [64719.9, 0.003], [64721.9, 0.001], [64726.1, 0.219], [64731.1, 1.885], [64731.9, 0.097], [64735.6, 0.116], [64736.3, 0.181], [64782.2, 0.018], [64852.9, 5.455], [64869.9, 10.423], [64908.7, 15.417], [64908.8, 0.005], [65359.4, 0.0], [66650.0, 1.589]]}
{"kind": "depth", "E": 1787080111053, "U": 11315329952657, "u": 11315329958073, "recv_ms": 1787080110993, "bids": [[14212.2, 3.164], [14312.2, 1.036], [58240.9, 0.002], [61476.5, 0.0], [61476.7, 0.002], [62123.7, 0.0], [63712.2, 8.78], [63898.0, 0.226], [63945.2, 3.75], [64065.1, 2.091], [64388.6, 3.437], [64615.1, 2.341], [64700.6, 0.25], [64702.9, 0.004], [64712.2, 8.291]], "asks": [[64714.5, 0.444], [64715.2, 0.004], [64717.0, 0.155], [64719.1, 1.021], [64719.9, 0.003], [64721.9, 0.001], [64726.1, 0.219], [64734.8, 0.551], [64761.5, 0.118], [65359.4, 0.002], [65570.3, 4.123], [65653.8, 13.807], [65712.3, 0.007], [65718.5, 19.375], [65897.6, 0.0], [67947.9, 0.03]]}
{"kind": "depth", "E": 1787080111155, "U": 11315329958137, "u": 11315329963395, "recv_ms": 1787080111097, "bids": [[1000.0, 35.81], [14212.2, 3.528], [14312.2, 0.672], [58240.9, 0.002], [61476.5, 0.0], [62123.7, 0.003], [63725.1, 0.06], [63734.5, 0.001], [63773.9, 37.574], [64006.8, 5.842], [64065.1, 2.091], [64700.4, 0.002], [64700.6, 0.245], [64703.3, 0.001], [64703.9, 0.022], [64705.4, 0.654], [64712.2, 8.337]], "asks": [[64712.3, 15.035], [64714.5, 0.599], [64719.9, 0.158], [64721.9, 0.466], [64726.1, 0.374], [64731.1, 1.329], [64731.6, 0.559], [64733.3, 1.571], [64735.9, 0.0], [64738.6, 10.002], [64869.9, 6.885], [65035.9, 3.383], [65359.4, 0.0], [65359.5, 0.0], [65488.8, 25.244], [65618.3, 8.03], [65653.8, 12.742], [65699.2, 0.036], [65750.8, 0.426], [65901.5, 0.694]]}
{"kind": "depth", "E": 1787080111257, "U": 11315329963636, "u": 11315329970425, "recv_ms": 1787080111198, "bids": [[1000.0, 35.81], [14212.2, 3.738], [14312.2, 0.392], [14612.2, 0.07], [51770.0, 0.0], [58240.9, 0.002], [62126.7, 0.009], [63712.2, 8.8], [64065.1, 2.091], [64388.6, 3.439], [64700.8, 1.192], [64704.1, 0.041], [64705.7, 0.349], [64712.2, 8.336]], "asks": [[64714.5, 0.444], [64719.9, 0.003], [64721.9, 0.001], [64726.1, 0.219], [64742.1, 0.177], [64869.9, 10.423], [65054.8, 0.001], [65119.6, 0.061], [65359.4, 0.0], [65515.3, 0.0], [65699.2, 0.047], [65712.3, 0.027]]}
{"kind": "depth", "E": 1787080111359, "U": 11315329970440, "u": 11315329975772, "recv_ms": 1787080111300, "bids": [[14212.2, 3.682], [14312.2, 0.238], [14612.2, 0.28], [51770.0, 0.002], [58240.9, 0.002], [61476.5, 0.0], [62123.7, 0.0], [63709.2, 12.943], [63887.2, 1.876], [63914.9, 9.613], [63942.1, 5.635], [64065.1, 2.091], [64194.5, 7.947], [64388.6, 3.429], [64571.4, 2.917], [64700.7, 0.416], [64700.8, 1.038], [64703.9, 0.563], [64704.8, 0.464], [64705.0, 0.137], [64705.4, 0.113], [64706.0, 0.012], [64706.6, 0.002], [64707.2, 0.093], [64707.4, 0.014], [64710.0, 0.011], [64710.1, 1.825], [64711.1, 0.084], [64711.2, 0.258], [64712.2, 8.293]], "asks": [[64712.3, 15.036], [64713.2, 0.0], [64715.9, 0.023], [64716.8, 0.043], [64718.5, 0.333], [64742.2, 0.254], [64775.0, 0.004], [64781.6, 0.015], [64852.9, 5.455], [64987.4, 0.523], [65052.1, 0.525], [65116.8, 0.558], [65181.5, 1.173], [65184.4, 0.059], [65249.2, 0.0], [65359.4, 0.0], [65521.2, 6.78], [65553.6, 38.121], [65650.6, 18.538], [65715.3, 4.315]]}
{"kind": "depth", "E": 1787080111461, "U": 11315329975905, "u": 11315329981554, "recv_ms": 1787080111401, "bids": [[1000.0, 35.81], [14212.2, 3.556], [14312.2, 0.126], [14612.2, 0.518], [51770.0, 0.0], [58240.9, 0.002], [61476.5, 0.0], [61476.6, 0.012], [61476.7, 0.004], [62123.7, 0.003], [63712.2, 8.78], [63850.1, 15.71], [63863.9, 0.792], [63903.3, 4.796], [64019.8, 0.857], [64065.1, 2.091], [64343.5, 0.0], [64345.4, 2.848], [64438.7, 0.127], [64440.2, 0.015], [64440.4, 0.728], [64712.2, 8.364]], "asks": [[64731.2, 3.211], [64731.9, 0.095], [64852.9, 3.654], [64868.5, 1.457], [64869.9, 7.468], [64905.7, 4.399], [64907.0, 0.001], [64908.7, 10.758], [64976.9, 0.492], [64978.4, 0.001], [65075.7, 1.183], [65075.8, 0.003], [65359.4, 0.0], [65438.3, 0.23], [65505.5, 9.375], [65521.9, 9.069], [65650.6, 19.603], [65712.3, 0.007], [65747.7, 5.315], [65800.0, 54.511], [66006.5, 0.015]]}
{"kind": "depth", "E": 1787080111563, "U": 11315329981702, "u": 11315329986609, "recv_ms": 1787080111503, "bids": [[14212.2, 3.444], [14312.2, 0.0], [14612.2, 0.756], [58240.9, 0.002], [61476.5, 0.0], [61476.6, 0.01], [61476.7, 0.006], [62123.7, 0.0], [63105.8, 1.9], [64065.1, 2.091], [64080.0, 1.562], [64227.7, 0.025], [64270.8, 0.023], [64571.4, 0.013], [64668.1, 0.028], [64700.5, 0.158], [64700.7, 0.262], [64701.5, 0.062], [64712.2, 8.353]], "asks": [[64726.0, 0.023], [64733.4, 2.321], [64852.9, 0.058], [65193.0, 0.036], [65337.2, 5.771], [65343.6, 0.0], [65359.4, 0.0], [65521.9, 9.831]]}
{"kind": "depth", "E": 1787080111665, "U": 11315329986675, "u": 11315329995715, "recv_ms": 1787080111605, "bids": [[14212.2, 3.094], [14612.2, 1.106], [58240.9, 0.002], [61476.5, 0.001], [62123.7, 0.003], [63712.2, 8.8], [63838.6, 2.406], [63870.9, 6.334], [64065.1, 2.091], [64388.6, 3.439], [64438.8, 33.955], [64509.7, 27.103], [64515.6, 6.81], [64554.4, 3.927], [64571.4, 2.917], [64571.5, 1.165], [64647.5, 0.158], [64668.5, 0.339], [64673.3, 0.082], [64679.7, 0.057], [64680.0, 3.044], [64680.2, 0.014], [64680.3, 0.045], [64681.5, 0.276], [64682.6, 0.002], [64684.3, 0.31], [64684.4, 0.001], [64685.0, 0.013], [64686.7, 0.097], [64688.0, 0.334], [64690.0, 0.505], [64690.6, 0.56], [64691.0, 0.1], [64692.1, 0.0], [64692.4, 0.138], [64692.6, 0.008], [64693.0, 0.002], [64693.9, 2.517], [64694.3, 0.007], [64694.5, 0.172], [64694.7, 1.705], [64694.8, 0.468], [64695.0, 0.012], [64695.9, 1.071], [64696.4, 0.01], [64697.5, 0.004], [64700.0, 0.537], [64700.4, 0.156], [64700.5, 0.004], [64701.2, 0.03], [64701.4, 0.772], [64702.2, 0.003], [64703.0, 0.003], [64703.9, 0.563], [64705.0, 0.128], [64705.1, 0.042], [64705.3, 0.659], [64705.4, 0.006], [64705.7, 0.003], [64705.8, 0.021], [64706.0, 0.01], [64706.2, 0.004], [64706.6, 0.233], [64707.3, 0.001], [64707.7, 0.099], [64707.8, 0.008], [64708.0, 0.076], [64710.0, 0.011], [64710.4, 0.009], [64711.1, 0.0], [64712.1, 0.006], [64712.2, 8.342]], "asks": [[64712.3, 15.098], [64712.5, 0.086], [64713.7, 0.13], [64713.9, 0.006], [64715.2, 0.128], [64728.2, 0.927], [64729.5, 0.005], [64731.6, 0.616], [64733.1, 0.0], [64761.5, 0.076], [64781.3, 1.205], [64852.9, 4.712], [64869.9, 10.423], [64906.9, 0.002], [64912.6, 0.786], [64912.7, 0.002], [64924.2, 0.217], [65311.4, 2.217], [65359.4, 0.0], [65442.9, 0.0], [65488.8, 26.769], [65618.3, 8.486], [65712.3, 0.027]]}
{"kind": "depth", "E": 1787080111767, "U": 11315329995755, "u": 11315330001012, "recv_ms": 1787080111705, "bids": [[1000.0, 35.81], [14212.2, 2.73], [14612.2, 1.47], [51769.8, 0.0], [51770.0, 0.002], [58240.9, 0.002], [61476.5, 0.001], [62798.6, 0.0], [63094.4, 0.635], [63919.6, 0.781], [64065.1, 2.091], [64093.4, 0.006], [64341.1, 0.0], [64342.1, 42.509], [64342.2, 10.718], [64582.7, 0.0], [64585.4, 0.0], [64696.2, 0.005], [64705.4, 0.004], [64705.6, 0.02], [64705.7, 0.157], [64706.0, 0.01], [64709.7, 0.09], [64712.2, 8.331]], "asks": [[64712.4, 0.045], [64712.5, 0.001], [64713.2, 0.084], [64713.9, 0.003], [64728.7, 0.313], [64768.4, 2.338], [64777.1, 0.02], [64868.5, 2.113], [64869.9, 10.423], [64907.0, 26.535], [64976.9, 5.19], [64978.4, 32.668], [65075.9, 41.811], [65200.0, 136.934], [65300.0, 133.577], [65327.1, 3.969], [65359.4, 0.0], [65429.0, 0.231], [65653.8, 11.677], [65718.5, 18.311], [66006.5, 0.018]]}
{"kind": "depth", "E": 1787080111869, "U": 11315330001088, "u": 11315330007511, "recv_ms": 1787080111811, "bids": [[14212.2, 2.38], [14612.2, 1.82], [51770.0, 0.0], [58240.9, 0.002], [60856.4, 0.013], [61476.5, 0.001], [61476.6, 0.008], [61476.7, 0.008], [62123.7, 0.0], [63712.2, 8.78], [64065.1, 2.091], [64376.8, 0.112], [64647.5, 0.004], [64668.5, 0.185], [64700.4, 0.002], [64700.5, 0.158], [64705.7, 0.311], [64705.8, 0.021], [64707.3, 0.155], [64712.2, 8.331]], "asks": [[64712.4, 0.043], [64712.5, 0.086], [64715.4, 1.19], [64717.1, 0.017], [65294.7, 4.054], [65306.6, 1.299], [65311.4, 0.306], [65359.4, 0.002], [65368.9, 0.0], [65712.3, 0.007], [66663.3, 0.0], [68604.9, 0.0]]}
{"kind": "depth", "E": 1787080111971, "U": 11315330007531, "u": 11315330023775, "recv_ms": 1787080111911, "bids": [[14212.2, 2.016], [14612.2, 2.184], [34000.0, 1.146], [58240.9, 0.002], [61476.5, 0.001], [62123.7, 0.003], [63817.8, 31.559], [63903.3, 5.577], [63935.7, 20.043], [64065.1, 2.091], [64371.5, 0.0], [64371.6, 0.492], [64388.6, 3.439], [64390.3, 0.229], [64473.2, 6.078], [64509.8, 1.147], [64515.6, 3.234], [64518.1, 0.735], [64571.4, 2.029], [64646.3, 2.636], [64695.5, 0.001], [64700.5, 0.004], [64700.6, 0.399], [64705.8, 0.021], [64706.2, 0.198], [64706.8, 0.324], [64708.0, 0.234], [64712.2, 8.179]], "asks": [[64712.3, 15.482], [64712.4, 0.046], [64712.5, 0.085], [64713.2, 0.086], [64713.6, 0.002], [64728.2, 0.002], [64728.7, 1.238], [64779.4, 0.001], [64906.9, 0.218], [64924.2, 0.001], [65359.4, 0.0], [65435.9, 0.763], [65630.1, 28.897], [65650.6, 20.668], [65667.4, 5.028], [65715.3, 5.379], [65896.0, 0.108]]}
{"kind": "depth", "E": 1787080112073, "U": 11315330024442, "u": 11315330035431, "recv_ms": 1787080112013, "bids": [[1000.0, 35.81], [14212.2, 1.666], [14612.2, 2.534], [51770.0, 0.004], [58240.9, 0.002], [61476.5, 0.001], [62123.7, 0.0], [63712.2, 8.8], [63914.9, 9.379], [64065.1, 2.091], [64515.6, 7.783], [64571.4, 2.476], [64646.3, 5.192], [64666.4, 0.005], [64670.1, 0.071], [64700.6, 0.399], [64705.6, 0.018], [64706.1, 0.444], [64706.2, 0.198], [64706.8, 0.324], [64712.2, 8.148]], "asks": [[64712.3, 15.488], [64779.3, 2.962], [64869.9, 7.508], [65294.8, 1.071], [65359.4, 0.0], [65650.6, 21.581], [65712.3, 0.027], [67947.9, 0.035]]}
{"kind": "depth", "E": 1787080112175, "U": 11315330035510, "u": 11315330044749, "recv_ms": 1787080112115, "bids": [[14212.2, 1.302], [14612.2, 2.898], [51770.0, 0.002], [58240.9, 0.002], [61476.5, 0.0], [62123.7, 0.003], [63418.0, 2.695], [63480.9, 0.149], [63725.1, 0.06], [64065.1, 2.091], [64646.9, 2.438], [64655.3, 2.147], [64663.6, 2.129], [64690.6, 0.004], [64690.8, 0.558], [64691.2, 0.011], [64692.4, 0.022], [64692.7, 0.169], [64693.0, 0.002], [64703.3, 0.0], [64703.9, 0.563], [64705.1, 0.043], [64705.3, 0.659], [64705.6, 0.02], [64705.7, 0.311], [64706.1, 0.442], [64706.2, 0.198], [64706.8, 0.13], [64709.3, 0.036], [64709.7, 0.006], [64712.1, 0.045], [64712.2, 7.936]], "asks": [[64712.3, 15.503], [64712.4, 0.045], [64712.5, 0.086], [64713.8, 0.005], [64715.1, 0.094], [64735.6, 0.001], [64735.9, 0.115], [64782.2, 0.0], [64797.3, 2.129], [64797.4, 0.04], [64805.7, 2.125], [64814.0, 2.124], [64814.1, 0.0], [64869.9, 7.508], [65294.7, 5.965], [65359.4, 0.0], [65571.3, 0.0], [65699.2, 0.039]]}
{"kind": "depth", "E": 1787080112277, "U": 11315330044879, "u": 11315330051766, "recv_ms": 1787080112219, "bids": [[14212.2, 0.952], [14612.2, 3.248], [51770.0, 0.0], [58240.9, 0.002], [61476.5, 0.0], [63712.2, 8.78], [63793.3, 1.644], [64065.1, 2.093], [64388.6, 3.437], [64585.1, 0.088], [64599.1, 0.0], [64646.3, 2.636], [64697.1, 0.962], [64706.1, 0.526], [64706.2, 0.004], [64706.6, 0.002], [64706.7, 0.746], [64707.2, 0.093], [64707.7, 0.33], [64709.3, 0.12], [64712.2, 7.931]], "asks": [[64712.3, 15.119], [64713.8, 0.002], [64728.7, 0.313], [64729.2, 1.041], [64731.6, 0.559], [64732.4, 0.379], [64742.2, 0.1], [64742.5, 0.311], [64779.3, 0.387], [64828.8, 0.083], [64869.9, 7.508], [65035.9, 3.385], [65306.7, 0.0], [65359.4, 0.002], [65505.5, 7.851], [65699.2, 0.047], [65712.3, 0.007], [67986.0, 0.009]]}
{"kind": "depth", "E": 1787080112379, "U": 11315330051785, "u": 11315330063369, "recv_ms": 1787080112319, "bids": [[1000.0, 35.81], [14212.2, 0.588], [14612.2, 3.612], [58240.9, 0.002], [61476.5, 0.0], [62123.7, 0.0], [63418.0, 2.692], [63605.0, 2.593], [63712.2, 8.8], [63776.9, 12.226], [64065.1, 2.091], [64692.6, 0.001], [64693.7, 0.008], [64697.1, 0.962], [64702.2, 0.003], [64703.9, 0.563], [64705.0, 0.004], [64705.1, 0.042], [64705.3, 0.706], [64705.4, 0.004], [64705.5, 0.19], [64705.6, 0.018], [64706.1, 0.444], [64706.2, 0.007], [64706.4, 0.004], [64706.8, 0.13], [64707.2, 0.481], [64709.8, 0.088], [64710.5, 0.089], [64710.9, 0.107], [64712.2, 8.055]], "asks": [[64712.3, 15.115], [64712.5, 0.001], [64713.2, 0.002], [64713.6, 0.003], [64715.1, 0.084], [64718.5, 0.313], [64718.7, 0.381], [64719.1, 1.002], [64733.3, 1.564], [64733.9, 0.02], [64734.8, 0.551], [64735.9, 0.115], [64782.2, 0.018], [64783.3, 0.0], [64784.0, 2.878], [64785.5, 0.029], [64787.7, 36.356], [64825.6, 2.764], [64869.9, 10.423], [65300.0, 133.548], [65359.4, 0.0], [65533.1, 4.911], [65669.0, 0.561], [65712.3, 0.027], [66006.5, 0.015]]}
{"kind": "depth", "E": 1787080112481, "U": 11315330063686, "u": 11315330071778, "recv_ms": 1787080112420, "bids": [[14212.2, 0.336], [14512.2, 0.112], [14612.2, 3.752], [58240.9, 0.002], [61476.5, 0.0], [62123.7, 0.003], [63541.6, 8.487], [63547.4, 1.579], [64065.1, 2.091], [64079.9, 63.317], [64227.7, 50.681], [64526.1, 0.001], [64564.9, 0.001], [64596.7, 0.002], [64596.8, 7.21], [64641.0, 0.323], [64691.3, 0.176], [64692.9, 0.616], [64693.7, 0.001], [64702.2, 0.544], [64703.9, 0.563], [64705.3, 0.165], [64705.4, 0.081], [64705.5, 0.113], [64706.0, 0.012], [64706.1, 0.442], [64706.6, 0.002], [64706.8, 0.13], [64706.9, 0.196], [64707.2, 0.093], [64712.2, 8.109]], "asks": [[64712.4, 0.043], [64712.5, 0.002], [64713.2, 0.0], [64720.0, 0.122], [64721.0, 0.004], [64722.0, 0.673], [64722.2, 1.18], [64728.0, 0.128], [64742.4, 0.156], [64742.5, 0.157], [64742.7, 0.224], [64783.3, 0.0], [64783.5, 0.048], [64784.8, 0.019], [64785.5, 0.029], [64787.7, 36.356], [64847.8, 4.811], [64865.5, 1.012], [64867.0, 0.019], [64869.9, 7.416], [64905.8, 0.0], [65193.0, 52.588], [65342.9, 65.354], [65359.4, 0.0], [65488.8, 28.294], [65490.9, 0.316], [65521.7, 0.0], [65555.1, 3.365]]}
{"kind": "depth", "E": 1787080112583, "U": 11315330071872, "u": 11315330080336, "recv_ms": 1787080112533, "bids": [[1000.0, 35.96], [14212.2, 0.21], [14512.2, 0.336], [14612.2, 3.654], [58240.9, 0.002], [61476.5, 0.0], [62123.7, 0.0], [63773.9, 38.67], [64011.9, 1.404], [64016.7, 2.025], [64065.1, 2.091], [64388.6, 3.427], [64528.0, 1.693], [64663.5, 0.006], [64679.8, 0.005], [64696.3, 0.859], [64697.0, 0.017], [64697.1, 0.962], [64698.0, 1.924], [64702.2, 0.003], [64703.6, 0.62], [64705.3, 0.706], [64706.8, 0.324], [64706.9, 0.002], [64707.2, 0.093], [64712.2, 8.097]], "asks": [[64712.3, 15.114], [64717.9, 0.425], [64720.0, 1.242], [64721.0, 0.904], [64722.2, 0.06], [64722.3, 1.042], [64723.0, 0.994], [64728.1, 1.121], [64728.4, 1.872], [64735.5, 0.618], [64770.6, 0.378], [64784.8, 0.037], [64787.4, 0.177], [64869.9, 7.416], [65294.8, 2.142], [65359.4, 0.0], [65657.1, 4.835], [66006.5, 0.018]]}
{"kind": "depth", "E": 1787080112685, "U": 11315330080460, "u": 11315330085929, "recv_ms": 1787080112626, "bids": [[1000.0, 35.81], [14212.2, 0.098], [14512.2, 0.574], [14612.2, 3.528], [58240.9, 0.002], [61476.5, 0.0], [63712.2, 8.78], [63993.4, 0.0], [64065.1, 2.091], [64141.4, 8.718], [64349.2, 0.002], [64440.4, 5.681], [64453.0, 0.215], [64522.5, 12.301], [64524.1, 2.919], [64561.3, 10.993], [64563.2, 2.809], [64582.7, 0.0], [64598.7, 8.486], [64646.3, 5.184], [64697.1, 0.96], [64703.6, 0.002], [64706.2, 0.007], [64706.8, 0.13], [64706.9, 0.002], [64710.9, 0.023], [64712.2, 8.02]], "asks": [[64712.3, 15.118], [64713.3, 0.084], [64722.6, 1.003], [64736.0, 2.906], [64779.3, 2.976], [64784.0, 8.189], [64784.8, 0.019], [64785.5, 36.161], [64787.7, 0.224], [64825.6, 3.851], [64826.9, 8.712], [64864.3, 11.174], [64869.9, 10.423], [64903.0, 2.913], [64903.1, 12.495], [64903.9, 0.0], [65075.7, 7.273], [65359.4, 0.0], [65489.2, 1.169], [65712.3, 0.007], [67947.9, 0.04]]}
{"kind": "depth", "E": 1787080112787, "U": 11315330086127, "u": 11315330093106, "recv_ms": 1787080112728, "bids": [[14212.2, 0.0], [14512.2, 0.84], [14612.2, 3.36], [51769.8, 0.0], [58240.9, 0.002], [61476.6, 0.01], [62123.7, 0.003], [63647.5, 3.308], [63776.9, 11.13], [64000.4, 0.481], [64065.1, 2.091], [64696.2, 0.003], [64706.2, 0.007], [64706.8, 0.13], [64711.0, 0.084]], "asks": [[64712.3, 15.113], [64713.3, 0.0], [64728.7, 0.311], [64869.9, 7.472], [65359.4, 0.0], [65482.4, 6.417], [65492.0, 10.664], [65783.2, 2.132]]}
{"kind": "depth", "E": 1787080112889, "U": 11315330093212, "u": 11315330100299, "recv_ms": 1787080112831, "bids": [[1000.0, 35.81], [14512.2, 1.19], [14612.2, 3.01], [58240.9, 0.002], [62123.7, 0.0], [63712.2, 8.8], [63892.1, 0.782], [63903.3, 5.928], [64006.8, 6.543], [64065.1, 2.091], [64388.6, 3.437], [64696.2, 0.005], [64705.7, 0.157], [64706.2, 0.007], [64706.8, 0.13], [64712.2, 7.991]], "asks": [[64719.4, 0.045], [64728.7, 0.313], [64869.9, 10.423], [65359.4, 0.0], [65501.4, 0.763], [65712.3, 0.027], [65888.2, 1.963], [65891.4, 0.758]]}
{"kind": "depth", "E": 1787080112991, "U": 11315330100320, "u": 11315330108031, "recv_ms": 1787080112930, "bids": [[1000.0, 35.81], [14512.2, 1.554], [14612.2, 2.646], [58240.9, 0.002], [61476.5, 0.0], [62123.7, 0.003], [63712.2, 8.78], [63730.3, 1.568], [63753.0, 3.45], [64065.1, 2.091], [64081.4, 4.674], [64129.8, 31.363], [64515.6, 3.261], [64554.4, 2.541], [64571.4, 1.485], [64598.7, 8.488], [64646.2, 4.919], [64646.3, 2.636], [64700.6, 0.245], [64700.8, 1.192], [64705.7, 0.311], [64706.2, 0.007], [64711.0, 0.0], [64712.2, 7.977]], "asks": [[64712.3, 15.109], [64713.2, 0.086], [64715.1, 0.084], [64775.0, 0.0], [64779.3, 2.976], [64781.6, 0.015], [64825.6, 2.764], [64826.9, 8.668], [64852.9, 2.149], [64868.5, 1.457], [64869.9, 3.531], [64908.7, 5.128], [65359.4, 0.0], [65488.8, 28.903], [65712.3, 0.007], [65758.8, 0.0]]}
{"kind": "depth", "E": 1787080113093, "U": 11315330108191, "u": 11315330115505, "recv_ms": 1787080113033, "bids": [[14512.2, 1.918], [14612.2, 2.282], [58240.9, 0.002], [61476.5, 0.0], [62123.7, 0.0], [63418.0, 2.689], [63644.4, 2.201], [63741.5, 3.814], [63773.9, 39.766], [63817.8, 31.371], [64065.1, 2.091], [64515.6, 7.802], [64554.4, 4.245], [64571.4, 2.92], [64679.8, 0.002], [64700.6, 0.245], [64705.6, 0.02], [64706.0, 0.01], [64710.5, 0.005], [64712.2, 7.888]], "asks": [[64712.3, 15.111], [64715.1, 0.094], [64715.4, 1.188], [64720.0, 1.21], [64721.0, 0.004], [64722.2, 0.076], [64723.0, 0.094], [64731.0, 0.635], [64731.6, 0.003], [64770.6, 0.375], [64775.0, 0.004], [64852.9, 4.712], [64869.9, 10.423], [64908.7, 13.683], [65359.4, 0.0], [65595.4, 5.626], [65748.8, 1.322], [65780.1, 2.327], [65824.3, 5.031]]}
{"kind": "depth", "E": 1787080113195, "U": 11315330115520, "u": 11315330121712, "recv_ms": 1787080113135, "bids": [[1000.0, 35.81], [14512.2, 2.268], [14612.2, 1.932], [51770.0, 0.0], [58240.9, 0.002], [61476.5, 0.0], [63952.0, 7.854], [64065.1, 5.208], [64388.6, 3.437], [64571.4, 2.474], [64659.7, 0.016], [64666.4, 0.001], [64666.9, 0.54], [64674.7, 0.035], [64706.0, 0.011], [64706.2, 0.004], [64712.2, 7.924]], "asks": [[64720.0, 1.242], [64721.0, 0.904], [64721.9, 0.001], [64722.2, 0.06], [64724.0, 1.058], [64728.1, 0.503], [64770.6, 0.378], [64852.9, 5.455], [64869.9, 6.886], [65359.4, 0.0]]}
{"kind": "depth", "E": 1787080113297, "U": 11315330121952, "u": 11315330132403, "recv_ms": 1787080113238, "bids": [[1000.0, 35.81], [14512.2, 2.618], [14612.2, 1.582], [58240.9, 0.002], [62123.7, 0.003], [63712.2, 8.8], [63859.1, 0.801], [64065.1, 5.208], [64259.2, 0.274], [64343.4, 0.004], [64388.6, 3.439]], "asks": [[64731.7, 0.847], [65035.9, 3.383], [65359.4, 0.0], [65533.1, 4.653], [65585.9, 2.768], [65712.3, 0.027]]}
{"kind": "depth", "E": 1787080113399, "U": 11315330132568, "u": 11315330141608, "recv_ms": 1787080113340, "bids": [[14512.2, 2.982], [14612.2, 1.218], [58240.9, 0.002], [61476.5, 0.0], [62123.7, 0.0], [63825.6, 0.625], [63935.7, 21.605], [64065.1, 5.208], [64515.6, 7.783], [64554.4, 3.393], [64571.4, 2.476], [64621.3, 0.005], [64621.4, 0.002], [64699.9, 0.532], [64702.1, 3.063], [64705.7, 0.157], [64712.2, 7.893]], "asks": [[64712.8, 0.084], [64715.1, 0.094], [64725.1, 0.279], [64725.2, 0.142], [64852.9, 5.455], [64869.9, 10.423], [64912.5, 0.313], [64912.6, 0.783], [65359.4, 0.0], [65812.4, 5.622], [66006.5, 0.021]]}
{"kind": "depth", "E": 1787080113501, "U": 11315330141717, "u": 11315330153851, "recv_ms": 1787080113441, "bids": [[1000.0, 35.81], [14512.2, 3.332], [14612.2, 0.868], [58240.9, 0.002], [61476.5, 0.0], [61476.6, 0.008], [61476.7, 0.01], [62123.7, 0.003], [63712.2, 8.78], [63741.5, 5.145], [64065.1, 5.208], [64388.6, 3.439], [64659.7, 0.012], [64666.4, 0.005], [64690.8, 0.558], [64691.5, 0.004], [64695.9, 0.146], [64696.1, 0.928], [64697.0, 0.017], [64703.9, 0.563], [64705.2, 1.82], [64705.4, 0.081], [64705.6, 0.018], [64705.7, 0.159], [64706.0, 0.011], [64706.2, 0.004], [64706.8, 0.13], [64707.3, 0.001], [64707.7, 0.099], [64708.6, 0.427], [64712.2, 7.806]], "asks": [[64715.1, 0.084], [64731.0, 0.079], [64731.9, 0.651], [64732.8, 2.293], [64733.9, 0.013], [64734.3, 0.551], [64734.8, 0.01], [64735.4, 0.382], [64735.9, 0.0], [64736.3, 0.296], [65359.4, 0.0], [65435.3, 0.763], [65635.0, 13.696], [65712.3, 0.007], [66006.5, 0.018]]}
{"kind": "depth", "E": 1787080113603, "U": 11315330154133, "u": 11315330160317, "recv_ms": 1787080113544, "bids": [[1000.0, 35.81], [14512.2, 3.696], [14612.2, 0.504], [51770.0, 0.0], [58240.9, 0.002], [61476.5, 0.0], [62123.7, 0.0], [63903.3, 6.162], [63947.2, 17.619], [64065.1, 5.231], [64666.4, 0.001], [64693.9, 0.633], [64703.1, 0.944], [64705.2, 1.822], [64705.7, 0.311], [64706.2, 0.004], [64706.8, 0.13], [64707.3, 0.155], [64712.2, 7.775]], "asks": [[64727.6, 0.002], [65359.4, 0.022], [65643.1, 1.138], [67947.9, 0.045]]}
{"kind": "depth", "E": 1787080113705, "U": 11315330160465, "u": 11315330165415, "recv_ms": 1787080113645, "bids": [[14412.2, 0.154], [14512.2, 3.738], [14612.2, 0.308], [58240.9, 0.002], [58241.0, 0.01], [63712.2, 8.8], [64065.1, 5.231], [64511.7, 5.583], [64582.7, 0.0], [64659.7, 0.016], [64682.4, 0.0], [64703.1, 0.326], [64705.2, 1.82], [64705.6, 0.02], [64706.0, 0.011], [64706.2, 0.004], [64706.8, 0.13], [64712.2, 7.774]], "asks": [[64734.3, 0.01], [64734.8, 0.551], [64825.6, 3.844], [64864.2, 2.75], [64865.5, 0.072], [64869.9, 7.467], [65359.4, 0.022], [65618.3, 10.952], [65653.8, 10.612], [65712.3, 0.027], [65718.5, 17.247], [65889.0, 2.2]]}
{"kind": "depth", "E": 1787080113807, "U": 11315330165703, "u": 11315330171040, "recv_ms": 1787080113748, "bids": [[1000.0, 35.81], [14412.2, 0.392], [14512.2, 3.626], [14612.2, 0.182], [51769.8, 0.0], [58240.9, 0.002], [58241.0, 0.008], [61476.5, 0.001], [62123.7, 0.003], [63806.2, 14.287], [63945.2, 2.813], [64065.1, 5.231], [64388.6, 3.429], [64571.4, 2.92], [64571.5, 1.165], [64586.8, 0.004], [64690.2, 0.073], [64696.0, 0.379], [64706.2, 0.004], [64706.4, 0.088], [64706.8, 0.13], [64709.8, 0.004], [64712.2, 7.775]], "asks": [[64712.4, 0.127], [64714.4, 0.011], [64715.8, 0.011], [64716.7, 0.002], [64719.4, 0.023], [64852.9, 4.712], [64869.9, 10.423], [65359.4, 0.022]]}
{"kind": "depth", "E": 1787080113909, "U": 11315330171171, "u": 11315330176117, "recv_ms": 1787080113849, "bids": [[1000.0, 35.81], [14412.2, 0.63], [14512.2, 3.5], [14612.2, 0.07], [58240.9, 0.002], [61476.5, 0.0], [62123.7, 0.0], [62770.9, 0.023], [63712.2, 8.78], [64065.1, 5.231], [64696.2, 0.005], [64706.2, 0.004], [64706.8, 0.13], [64709.8, 0.088], [64712.2, 7.77]], "asks": [[64712.4, 0.043], [64714.4, 0.001], [64728.7, 0.313], [64869.9, 6.885], [65359.4, 0.022], [65650.6, 22.646], [65712.3, 0.007], [65715.3, 6.443], [66006.5, 0.015], [66653.6, 0.022]]}
{"kind": "depth", "E": 1787080114011, "U": 11315330176443, "u": 11315330182688, "recv_ms": 1787080113956, "bids": [[14412.2, 0.924], [14512.2, 3.276], [14612.2, 0.0], [58240.9, 0.002], [61476.5, 0.001], [62123.7, 0.003], [63712.2, 8.8], [63863.9, 0.01], [63942.1, 6.572], [64065.1, 5.231], [64388.6, 3.439], [64690.2, 0.071], [64703.9, 0.563], [64705.4, 0.081], [64706.2, 0.201], [64710.2, 0.0], [64712.2, 7.693]], "asks": [[64712.7, 0.085], [64712.8, 0.0], [64714.4, 0.008], [64715.8, 0.003], [64731.1, 1.329], [64731.9, 0.651], [64734.3, 0.553], [64734.8, 0.01], [64735.3, 0.486], [64735.4, 0.382], [64736.3, 0.181], [64869.9, 10.423], [65359.4, 0.022], [65712.3, 0.027]]}
{"kind": "depth", "E": 1787080114113, "U": 11315330182749, "u": 11315330187857, "recv_ms": 1787080114054, "bids": [[1000.0, 35.81], [14412.2, 1.274], [14512.2, 2.926], [58240.9, 0.002], [61476.5, 0.001], [63600.2, 0.785], [63725.1, 0.042], [63789.9, 0.013], [63791.6, 0.01], [63914.9, 9.145], [64065.1, 5.231], [64696.0, 0.367], [64700.6, 0.245], [64706.2, 0.007], [64712.2, 7.649]], "asks": [[64720.2, 0.018], [64725.2, 0.14], [65359.4, 0.022], [65632.8, 0.0], [65634.5, 0.002], [65699.2, 0.029]]}
{"kind": "depth", "E": 1787080114215, "U": 11315330187932, "u": 11315330193294, "recv_ms": 1787080114157, "bids": [[1000.0, 35.81], [14412.2, 1.638], [14512.2, 2.562], [58240.9, 0.002], [60829.5, 0.043], [61476.5, 0.0], [62123.7, 0.0], [63712.2, 8.78], [63725.1, 0.06], [63789.9, 0.021], [63791.6, 0.018], [63870.9, 7.429], [63882.5, 2.819], [64065.1, 5.231], [64643.8, 0.022], [64644.1, 0.0], [64656.9, 0.331], [64657.2, 0.031], [64657.6, 1.475], [64657.9, 0.002], [64658.2, 0.001], [64668.5, 0.031], [64670.7, 0.179], [64674.4, 0.011], [64674.7, 0.003], [64675.0, 0.786], [64675.2, 0.187], [64675.3, 0.072], [64675.7, 0.193], [64689.3, 0.042], [64689.4, 1.082], [64689.5, 0.053], [64689.6, 1.326], [64689.8, 2.327], [64689.9, 0.0], [64690.0, 0.305], [64690.1, 0.828], [64690.2, 0.001], [64691.0, 0.0], [64691.4, 0.1], [64696.0, 0.379], [64705.1, 0.044], [64705.3, 0.582], [64705.6, 0.018], [64705.7, 0.465], [64705.8, 0.021], [64707.2, 0.217], [64708.0, 0.164], [64708.1, 0.158], [64708.2, 0.016], [64708.3, 0.096], [64708.4, 0.001], [64708.5, 0.086], [64708.6, 0.257], [64708.7, 0.273], [64708.8, 0.003], [64708.9, 0.085], [64709.0, 0.003], [64709.3, 0.088], [64709.6, 0.002], [64709.9, 0.016], [64710.2, 0.035], [64710.3, 0.001], [64710.6, 0.0], [64712.2, 7.717]], "asks": [[64712.7, 0.001], [64721.4, 0.038], [64721.7, 0.002], [64722.0, 0.638], [64722.4, 1.952], [64722.7, 2.761], [64722.8, 0.579], [64722.9, 0.1], [64723.0, 0.003], [64723.1, 0.001], [64723.2, 2.166], [64723.3, 0.312], [64723.4, 0.245], [64723.5, 0.077], [64723.6, 0.383], [64723.7, 0.004], [64723.8, 0.006], [64723.9, 0.011], [64734.3, 0.012], [64734.8, 0.551], [64738.8, 0.002], [64738.9, 0.033], [64739.2, 3.414], [64739.5, 0.012], [64739.8, 1.005], [64740.1, 0.059], [64740.5, 0.178], [64741.0, 0.025], [64741.6, 0.27], [64741.7, 0.0], [64741.9, 0.004], [64742.0, 0.007], [64742.1, 0.007], [64742.2, 0.07], [64742.3, 0.463], [64742.4, 0.009], [64742.5, 0.003], [64742.6, 3.395], [64742.7, 0.154], [64756.3, 0.198], [64756.6, 0.033], [64756.9, 0.015], [64757.3, 0.0], [64757.6, 0.0], [64869.9, 7.476], [65359.4, 0.022], [65521.2, 7.008], [65699.2, 0.039], [65712.3, 0.007], [66006.5, 0.018], [67947.9, 0.05], [68547.8, 0.0], [68595.0, 0.038]]}
{"kind": "depth", "E": 1787080114317, "U": 11315330193451, "u": 11315330198971, "recv_ms": 1787080114258, "bids": [[14412.2, 2.002], [14512.2, 2.198], [51770.0, 0.0], [58240.9, 0.002], [61476.5, 0.0], [62123.7, 0.003], [62129.4, 0.0], [64065.1, 5.231], [64388.6, 3.427], [64586.7, 0.194], [64660.4, 0.131], [64668.5, 0.185], [64674.6, 0.033], [64675.6, 0.032], [64679.8, 0.005], [64705.7, 0.465], [64705.8, 0.021], [64706.0, 0.01], [64706.2, 0.007], [64707.3, 0.309], [64708.0, 0.234], [64708.1, 0.228], [64708.2, 0.086], [64708.3, 0.196], [64708.4, 0.201], [64708.5, 0.186], [64708.6, 0.256], [64708.9, 0.155], [64709.5, 0.034], [64710.5, 0.037], [64712.2, 7.707]], "asks": [[64719.5, 0.024], [64721.1, 0.052], [64722.0, 0.673], [64722.7, 2.852], [64723.1, 0.101], [64723.2, 2.376], [64723.3, 0.482], [64723.4, 0.329], [64723.6, 0.453], [64725.3, 0.007], [64738.5, 0.393], [64739.5, 0.047], [64740.7, 0.112], [64741.4, 0.655], [64741.8, 0.17], [64741.9, 0.104], [64742.0, 0.107], [64742.1, 0.077], [64742.2, 0.154], [64742.3, 0.533], [64756.0, 3.547], [64757.0, 0.035], [64822.4, 0.017], [65359.4, 0.022], [65533.1, 4.395], [65632.8, 0.008], [65634.5, 0.01], [65699.2, 0.047], [66006.5, 0.015]]}
{"kind": "depth", "E": 1787080114419, "U": 11315330198978, "u": 11315330210909, "recv_ms": 1787080114358, "bids": [[1000.0, 35.81], [14412.2, 2.352], [14512.2, 1.848], [51770.0, 0.0], [58240.9, 0.002], [61476.5, 0.0], [62123.7, 0.0], [64065.1, 5.231], [64666.9, 0.537], [64679.8, 0.005], [64708.5, 0.256], [64712.2, 7.75]], "asks": [[64712.3, 15.112], [64712.6, 0.086], [64715.2, 0.004], [64723.0, 0.073], [64732.8, 2.286], [64733.3, 1.571], [64741.8, 0.24], [64770.6, 0.378], [64822.4, 0.014], [64869.9, 6.845], [65035.9, 3.385], [65359.4, 0.022]]}
{"kind": "depth", "E": 1787080114521, "U": 11315330211146, "u": 11315330217291, "recv_ms": 1787080114461, "bids": [[1000.0, 35.81], [14412.2, 2.702], [14512.2, 1.498], [58240.9, 0.002], [60829.5, 0.0], [61476.5, 0.0], [62123.7, 0.003], [62770.9, 0.0], [63712.2, 8.8], [63817.8, 31.183], [63989.2, 1.564], [64065.1, 5.208], [64343.4, 0.0], [64657.8, 0.037], [64670.7, 0.165], [64674.3, 0.032], [64674.9, 0.048], [64692.0, 1.626], [64692.7, 0.053], [64695.5, 0.001], [64696.1, 0.003], [64696.2, 0.93], [64697.0, 0.017], [64703.9, 0.022], [64704.0, 0.67], [64705.4, 0.081], [64707.9, 0.077], [64708.2, 0.156], [64709.2, 0.051], [64709.8, 0.12], [64710.2, 0.035], [64712.2, 7.782]], "asks": [[64712.6, 0.002], [64712.8, 0.084], [64721.7, 0.037], [64722.4, 1.987], [64723.4, 0.406], [64723.6, 0.523], [64728.0, 0.128], [64728.7, 0.313], [64729.2, 0.116], [64729.4, 3.688], [64731.7, 0.843], [64733.3, 1.564], [64733.8, 0.008], [64734.4, 1.242], [64734.8, 0.01], [64735.3, 0.371], [64735.4, 0.923], [64736.3, 0.296], [64739.2, 3.449], [64739.8, 1.04], [64742.1, 0.154], [64742.4, 0.079], [64742.6, 3.549], [64742.7, 0.0], [64756.6, 0.068], [64757.3, 0.035], [64852.9, 5.455], [64869.9, 10.423], [64908.7, 15.417], [65359.4, 0.0], [65712.3, 0.027], [66653.6, 0.0], [68595.0, 0.0]]}
{"kind": "depth", "E": 1787080114623, "U": 11315330217404, "u": 11315330222549, "recv_ms": 1787080114563, "bids": [[14412.2, 3.066], [14512.2, 1.134], [51770.0, 0.0], [58240.9, 0.002], [64065.1, 5.208], [64138.7, 0.472], [64388.6, 3.437], [64621.2, 0.259], [64621.3, 0.002], [64650.5, 0.002], [64657.1, 0.474], [64658.1, 0.036], [64666.9, 0.54], [64689.3, 0.112], [64689.7, 0.101], [64689.9, 0.1], [64690.0, 0.375], [64690.1, 1.384], [64690.8, 0.002], [64695.4, 0.946], [64696.2, 0.005], [64704.0, 0.129], [64705.1, 0.042], [64705.3, 1.123], [64705.7, 0.467], [64706.2, 0.004], [64708.6, 0.356], [64708.8, 0.103], [64710.2, 0.036], [64710.3, 0.001], [64712.2, 7.705]], "asks": [[64712.7, 0.085], [64712.8, 0.0], [64722.7, 2.982], [64722.9, 0.21], [64727.9, 0.001], [64728.8, 1.531], [64729.4, 2.763], [64730.3, 0.004], [64731.2, 3.767], [64731.9, 0.095], [64734.1, 0.003], [64734.8, 0.551], [64735.4, 0.382], [64740.2, 0.276], [64741.7, 0.11], [64742.6, 3.395], [64742.8, 0.17], [64822.4, 0.017], [65359.4, 0.0], [65572.4, 0.762], [66006.5, 0.018]]}
{"kind": "depth", "E": 1787080114725, "U": 11315330222707, "u": 11315330228296, "recv_ms": 1787080114664, "bids": [[1000.0, 35.81], [14412.2, 3.416], [14512.2, 0.784], [58240.9, 0.002], [61476.5, 0.0], [61476.6, 0.006], [61476.7, 0.012], [62123.7, 0.0], [63712.2, 8.78], [64065.1, 5.208], [64518.1, 1.32], [64582.7, 0.0], [64689.2, 0.099], [64689.4, 1.222], [64689.6, 1.426], [64689.7, 0.201], [64690.2, 0.071], [64690.9, 0.114], [64703.1, 0.944], [64703.9, 0.563], [64705.3, 0.582], [64712.2, 7.704]], "asks": [[64727.6, 0.62], [64868.5, 2.113], [65359.4, 0.002], [65712.3, 0.007], [65861.6, 1.213]]}
{"kind": "depth", "E": 1787080114827, "U": 11315330228349, "u": 11315330234335, "recv_ms": 1787080114767, "bids": [[1000.0, 35.81], [14312.2, 0.028], [14412.2, 3.724], [14512.2, 0.448], [51769.8, 0.0], [58240.9, 0.002], [61476.7, 0.01], [62123.7, 0.003], [63605.0, 1.808], [63806.2, 14.475], [64065.1, 5.208], [64125.9, 0.234], [64343.4, 0.004], [64571.4, 2.916], [64644.8, 1.173], [64656.8, 0.032], [64657.5, 0.302], [64659.7, 0.012], [64671.2, 1.043], [64673.3, 0.068], [64689.8, 2.397], [64695.4, 0.021], [64696.8, 0.926], [64697.1, 0.962], [64703.9, 0.022], [64705.4, 0.622], [64710.3, 0.085], [64712.2, 7.636]], "asks": [[64712.3, 15.111], [64712.7, 0.001], [64728.8, 0.606], [64729.3, 1.553], [64731.7, 0.847], [64734.8, 0.01], [64735.4, 0.923], [64761.5, 0.118], [64775.0, 0.004], [64781.6, 0.015], [64852.9, 4.708], [64869.9, 7.475], [65359.4, 0.0], [65565.5, 1.066], [71183.6, 0.0]]}
{"kind": "depth", "E": 1787080114929, "U": 11315330234438, "u": 11315330242204, "recv_ms": 1787080114881, "bids": [[14312.2, 0.224], [14412.2, 3.696], [14512.2, 0.28], [58240.9, 0.002], [61476.5, 0.0], [62123.7, 0.0], [63712.2, 8.8], [63914.9, 8.88], [64065.1, 5.208], [64388.6, 3.437], [64571.4, 0.013], [64571.5, 0.839], [64689.2, 0.169], [64689.4, 1.292], [64691.3, 0.276], [64696.2, 0.005], [64697.1, 0.962], [64712.2, 7.589]], "asks": [[64728.7, 0.313], [64852.9, 0.058], [65359.4, 0.0], [65712.3, 0.027], [65844.8, 2.428]]}
{"kind": "depth", "E": 1787080115031, "U": 11315330242290, "u": 11315330254922, "recv_ms": 1787080114970, "bids": [[1000.0, 35.81], [14312.2, 0.448], [14412.2, 3.598], [14512.2, 0.154], [58240.9, 0.002], [62123.7, 0.003], [63418.0, 2.686], [63804.8, 0.817], [63947.2, 17.4], [64065.1, 5.208], [64571.4, 2.919], [64653.4, 0.013], [64655.1, 0.36], [64662.7, 0.017], [64663.6, 2.129], [64664.0, 1.192], [64665.5, 0.04], [64671.2, 1.039], [64671.3, 0.003], [64671.5, 0.005], [64674.1, 0.062], [64682.3, 0.046], [64689.9, 0.2], [64694.3, 0.167], [64695.9, 1.071], [64696.8, 0.001], [64697.1, 0.96], [64698.0, 1.024], [64703.9, 0.563], [64705.4, 0.081], [64711.1, 0.002], [64712.1, 0.043], [64712.2, 7.575]], "asks": [[64727.6, 0.002], [64734.1, 0.544], [64735.1, 0.116], [64735.4, 0.382], [64736.3, 0.181], [64740.4, 0.005], [64742.5, 0.017], [64749.9, 0.341], [64758.6, 0.21], [64766.0, 0.019], [64852.9, 4.708], [64869.9, 7.44], [65359.4, 0.0], [65521.2, 6.894], [67947.9, 0.055]]}
{"kind": "depth", "E": 1787080115133, "U": 11315330255001, "u": 11315330268772, "recv_ms": 1787080115072, "bids": [[1000.0, 35.81], [14312.2, 0.686], [14412.2, 3.472], [14512.2, 0.042], [51770.0, 0.0], [58240.9, 0.002], [63712.2, 8.78], [63725.1, 0.051], [63825.6, 1.25], [63914.9, 8.646], [63935.7, 21.824], [64065.1, 5.208], [64343.4, 0.0], [64659.7, 0.016], [64665.5, 0.026], [64673.8, 0.251], [64697.0, 0.917], [64700.6, 0.245], [64705.2, 1.821], [64712.2, 7.622]], "asks": [[64731.7, 0.843], [64869.9, 10.423], [65337.2, 5.237], [65359.4, 0.0], [65521.2, 7.152], [65553.6, 39.187], [65699.2, 0.038], [65712.3, 0.007]]}
{"kind": "depth", "E": 1787080115235, "U": 11315330268809, "u": 11315330279674, "recv_ms": 1787080115176, "bids": [[14312.2, 0.994], [14412.2, 3.206], [14512.2, 0.0], [51770.0, 0.0], [58240.9, 0.002], [61476.5, 0.0], [62123.7, 0.0], [63418.0, 2.689], [63725.3, 0.009], [63945.2, 1.876], [64065.0, 0.023], [64065.1, 5.208], [64388.6, 3.437], [64670.7, 0.179], [64673.8, 0.237], [64681.1, 0.015], [64694.8, 0.468], [64696.3, 0.241], [64703.1, 0.326], [64704.0, 0.129], [64705.1, 0.044], [64705.2, 1.82], [64705.7, 0.465], [64706.1, 0.526], [64709.3, 0.004], [64709.4, 0.186], [64709.8, 0.036], [64710.0, 0.013], [64710.3, 0.001], [64711.1, 0.0], [64712.2, 5.416]], "asks": [[64712.3, 15.104], [64712.6, 0.086], [64713.4, 0.312], [64714.4, 0.018], [64715.2, 0.128], [64720.1, 2.319], [64728.1, 1.428], [64729.3, 0.628], [64732.3, 5.003], [64733.3, 2.743], [64733.6, 10.469], [64736.0, 1.603], [64738.6, 0.002], [64761.5, 0.076], [64912.4, 0.003], [64912.5, 0.31], [65359.4, 0.0], [65699.3, 1.311], [67947.9, 0.06]]}
{"kind": "depth", "E": 1787080115337, "U": 11315330279862, "u": 11315330289316, "recv_ms": 1787080115278, "bids": [[1000.0, 35.81], [14312.2, 1.358], [14412.2, 2.842], [58240.9, 0.002], [60909.7, 0.0], [61476.5, 0.0], [62123.7, 0.003], [63712.2, 8.8], [63804.8, 0.583], [63928.6, 0.058], [64065.1, 5.208], [64659.7, 0.012], [64671.2, 1.043], [64677.8, 0.343], [64680.8, 0.0], [64705.3, 0.666], [64705.7, 0.549], [64708.5, 0.172], [64708.9, 0.071], [64709.4, 0.102], [64712.2, 5.338]], "asks": [[64732.3, 5.005], [64869.9, 10.423], [65359.4, 0.0], [65521.2, 7.266], [65621.9, 6.903], [65631.2, 1.364], [65712.3, 0.027], [66006.5, 0.021]]}
{"kind": "depth", "E": 1787080115439, "U": 11315330289684, "u": 11315330298862, "recv_ms": 1787080115379, "bids": [[1000.0, 35.81], [14312.2, 1.722], [14412.2, 2.478], [58240.9, 0.002], [61476.5, 0.0], [62123.7, 0.0], [63942.1, 7.509], [64065.1, 5.208], [64343.4, 0.004], [64670.7, 0.165], [64673.3, 0.082], [64679.8, 1.889], [64712.2, 5.339]], "asks": [[64712.3, 15.102], [64728.1, 0.503], [64728.6, 1.73], [64731.7, 0.847], [64741.2, 0.25], [64741.3, 3.213], [64741.4, 0.655], [64744.2, 0.002], [64744.3, 0.004], [64744.4, 0.126], [64745.0, 2.959], [64745.1, 1.012], [64745.2, 0.006], [64747.2, 1.398], [64747.3, 0.063], [64747.4, 0.008], [65035.9, 3.383], [65327.1, 4.503], [65359.4, 0.0]]}
{"kind": "depth", "E": 1787080115541, "U": 11315330299035, "u": 11315330307869, "recv_ms": 1787080115479, "bids": [[14312.2, 2.072], [14412.2, 2.128], [58240.9, 0.002], [61476.5, 0.001], [63712.2, 8.78], [64065.1, 5.208], [64388.6, 3.429], [64689.7, 0.359], [64700.8, 1.038], [64701.0, 0.429], [64708.5, 0.256], [64712.1, 0.053], [64712.2, 5.338]], "asks": [[64712.3, 15.102], [64719.3, 0.336], [64734.1, 0.003], [64734.8, 0.551], [64869.9, 10.423], [65359.4, 0.0], [65611.8, 7.192], [65635.0, 9.893], [65712.3, 0.007]]}
{"kind": "depth", "E": 1787080115643, "U": 11315330307973, "u": 11315330317340, "recv_ms": 1787080115584, "bids": [[1000.0, 35.81], [14312.2, 2.436], [14412.2, 1.764], [58240.9, 0.002], [61476.5, 0.001], [62123.7, 0.003], [63418.0, 2.686], [63822.5, 8.605], [63850.1, 15.476], [63945.2, 0.939], [64065.1, 5.208], [64634.5, 0.003], [64647.5, 0.003], [64666.9, 0.537], [64670.7, 0.179], [64674.4, 0.347], [64677.8, 0.007], [64679.8, 1.886], [64692.1, 0.007], [64692.9, 0.609], [64694.8, 0.005], [64695.0, 0.004], [64695.3, 0.927], [64695.9, 0.146], [64701.0, 0.429], [64702.2, 0.466], [64702.3, 0.009], [64703.8, 1.321], [64703.9, 0.563], [64704.8, 0.464], [64705.1, 0.042], [64705.3, 0.65], [64705.4, 0.089], [64705.7, 0.549], [64708.1, 0.459], [64708.5, 0.258], [64708.6, 0.125], [64708.8, 0.103], [64708.9, 0.071], [64710.0, 0.011], [64710.2, 0.044], [64711.4, 0.043], [64712.1, 0.014], [64712.2, 2.609]], "asks": [[64712.3, 15.489], [64712.4, 0.044], [64713.5, 1.513], [64713.6, 0.002], [64714.0, 0.01], [64714.4, 0.583], [64714.5, 2.763], [64714.6, 2.501], [64715.1, 0.084], [64715.3, 2.564], [64717.1, 0.017], [64717.4, 0.94], [64717.5, 2.322], [64717.9, 0.002], [64719.0, 0.009], [64719.8, 0.001], [64719.9, 0.003], [64720.0, 0.122], [64722.2, 0.624], [64727.2, 3.01], [64729.1, 10.013], [64732.3, 5.003], [64732.7, 1.555], [64733.6, 0.471], [64733.8, 0.001], [64741.2, 2.135], [64741.3, 1.328], [64770.6, 0.378], [64777.0, 0.075], [64780.5, 0.028], [64782.2, 0.0], [64822.4, 0.014], [64827.1, 0.628], [64843.2, 1.329], [64857.4, 0.001], [64873.8, 0.008], [65359.4, 0.0], [65618.3, 14.756]]}
{"kind": "depth", "E": 1787080115745, "U": 11315330317407, "u": 11315330325448, "recv_ms": 1787080115686, "bids": [[1000.0, 35.81], [14312.2, 2.786], [14412.2, 1.414], [51770.0, 0.0], [58240.9, 0.002], [61476.5, 0.0], [62123.7, 0.0], [63418.0, 2.683], [63712.2, 8.8], [63859.9, 2.642], [63903.3, 6.396], [64065.1, 5.231], [64571.5, 1.165], [64582.7, 0.0], [64670.7, 0.165], [64694.8, 0.005], [64695.7, 0.79], [64702.2, 0.474], [64702.3, 0.001], [64703.1, 0.326], [64703.8, 1.319], [64703.9, 0.563], [64704.1, 0.003], [64704.8, 0.466], [64705.3, 0.102], [64705.4, 0.081], [64706.8, 1.884], [64706.9, 0.55], [64707.3, 0.309], [64707.4, 0.208], [64708.6, 0.125], [64708.8, 0.111], [64710.6, 0.038], [64712.2, 2.565]], "asks": [[64712.3, 15.103], [64712.4, 0.043], [64713.5, 1.514], [64714.6, 2.502], [64727.6, 0.002], [64733.3, 1.562], [64735.5, 0.0], [64869.9, 10.423], [64980.8, 2.099], [65359.4, 0.022], [65712.3, 0.027]]}
{"kind": "depth", "E": 1787080115847, "U": 11315330325778, "u": 11315330334069, "recv_ms": 1787080115787, "bids": [[14312.2, 3.15], [14412.2, 1.05], [51769.8, 0.0], [58240.9, 0.002], [61476.5, 0.0], [62123.7, 0.003], [62199.6, 0.275], [63418.0, 2.686], [63942.1, 8.446], [64065.1, 5.231], [64388.6, 3.429], [64694.8, 0.013], [64698.3, 1.002], [64698.4, 0.62], [64699.4, 0.287], [64701.0, 0.275], [64702.2, 0.003], [64704.0, 0.592], [64704.2, 0.003], [64705.0, 0.088], [64708.1, 0.375], [64708.5, 0.174], [64712.2, 2.366]], "asks": [[64714.5, 2.765], [64736.2, 0.001], [64777.1, 0.002], [65359.4, 0.022], [65507.7, 0.0], [67253.2, 0.0]]}
{"kind": "depth", "E": 1787080115949, "U": 11315330334178, "u": 11315330342939, "recv_ms": 1787080115889, "bids": [[1000.0, 35.81], [14312.2, 3.5], [14412.2, 0.7], [58240.9, 0.002], [61476.5, 0.0], [61476.6, 0.004], [61476.7, 0.012], [62123.7, 0.0], [63712.2, 8.78], [64065.1, 5.231], [64571.4, 0.013], [64571.5, 3.683], [64694.8, 0.005], [64696.2, 0.005], [64696.7, 0.04], [64701.0, 0.275], [64701.2, 0.184], [64702.2, 0.011], [64707.3, 0.503], [64707.4, 0.014], [64712.2, 2.337]], "asks": [[64712.3, 15.105], [64720.6, 2.041], [64728.7, 0.313], [64729.1, 10.015], [64729.4, 2.761], [64852.9, 5.455], [64869.9, 7.478], [64912.5, 0.0], [65233.1, 0.612], [65359.4, 0.022], [65653.8, 9.547], [65712.3, 0.007], [65832.9, 0.0]]}
{"kind": "depth", "E": 1787080116051, "U": 11315330342969, "u": 11315330353306, "recv_ms": 1787080115991, "bids": [[1000.0, 35.81], [14212.2, 0.056], [14312.2, 3.752], [14412.2, 0.392], [58240.9, 0.002], [62123.7, 0.689], [62770.9, 0.023], [63806.2, 14.663], [64011.9, 1.17], [64065.1, 5.231], [64141.4, 8.484], [64697.5, 0.013], [64700.3, 0.321], [64700.6, 0.25], [64701.2, 0.03], [64705.3, 0.179], [64705.4, 0.004], [64706.9, 0.009], [64707.2, 0.219], [64707.3, 0.85], [64707.4, 0.208], [64708.5, 0.172]], "asks": [[64869.9, 10.423], [65359.4, 0.022], [65565.5, 0.0], [65650.6, 23.711], [66653.6, 0.022], [68530.3, 1.312]]}
{"kind": "depth", "E": 1787080116153, "U": 11315330353536, "u": 11315330363742, "recv_ms": 1787080116094, "bids": [[14212.2, 0.266], [14312.2, 3.682], [14412.2, 0.252], [51770.0, 0.048], [58240.9, 0.002], [61476.5, 0.0], [61476.6, 0.006], [62123.7, 0.692], [62606.2, 0.004], [63712.2, 8.8], [64065.1, 5.231], [64388.6, 3.429], [64571.5, 3.217], [64621.1, 0.025], [64621.2, 0.256], [64626.1, 0.045], [64633.2, 0.031], [64640.4, 0.001], [64663.6, 2.127], [64680.4, 0.09], [64690.1, 0.828], [64691.5, 0.56], [64692.0, 1.51], [64693.5, 2.454], [64700.6, 0.246], [64701.1, 1.391], [64702.2, 0.011], [64704.0, 0.592], [64705.7, 0.395], [64706.9, 0.55], [64707.0, 0.013], [64707.3, 0.463], [64707.4, 0.014], [64707.5, 0.195], [64708.5, 0.256], [64712.2, 2.41]], "asks": [[64712.3, 15.095], [64717.2, 0.0], [64721.5, 0.012], [64731.2, 3.211], [64731.9, 0.651], [64735.1, 0.001], [64736.3, 0.296], [64746.8, 0.03], [64782.2, 0.018], [65230.0, 4.663], [65306.6, 0.229], [65359.4, 0.022], [65521.2, 7.524], [65637.1, 0.0], [65712.3, 0.027]]}
{"kind": "depth", "E": 1787080116255, "U": 11315330363762, "u": 11315330373692, "recv_ms": 1787080116195, "bids": [[1000.0, 35.81], [14212.2, 0.504], [14312.2, 3.57], [14412.2, 0.126], [51770.0, 0.006], [58240.9, 0.002], [61476.7, 0.01], [62123.7, 0.689], [63418.0, 2.689], [64065.0, 0.022], [64065.1, 5.231], [64107.3, 6.94], [64633.1, 0.027], [64664.0, 1.192], [64671.2, 1.039], [64690.8, 0.558], [64691.5, 0.004], [64692.6, 0.117], [64693.5, 2.338], [64695.3, 0.002], [64696.1, 0.928], [64697.0, 0.917], [64702.2, 0.474], [64703.9, 0.022], [64704.0, 0.129], [64704.1, 0.544], [64705.3, 0.179], [64706.7, 0.001], [64706.9, 1.166], [64707.3, 1.004], [64707.4, 0.014], [64707.5, 0.195]], "asks": [[64714.1, 0.087], [64728.6, 0.805], [64729.5, 0.93], [64734.3, 0.553], [64734.8, 0.01], [64735.9, 0.0], [64742.6, 3.549], [64742.8, 0.016], [65337.2, 4.581], [65359.4, 0.022]]}
{"kind": "depth", "E": 1787080116357, "U": 11315330373878, "u": 11315330382639, "recv_ms": 1787080116299, "bids": [[1000.0, 35.81], [14212.2, 0.742], [14312.2, 3.444], [14412.2, 0.014], [51770.0, 0.0], [58240.9, 0.002], [60829.5, 0.043], [61476.5, 0.001], [62123.7, 0.692], [63599.6, 1.705], [63712.2, 8.78], [64000.4, 0.715], [64065.1, 5.231], [64129.8, 31.597], [64273.5, 0.075], [64279.9, 0.007], [64651.3, 0.634], [64657.5, 0.302], [64675.0, 0.709], [64680.4, 0.092], [64702.2, 0.466], [64702.3, 0.009], [64705.3, 0.179], [64707.4, 0.014], [64707.5, 0.195], [64708.8, 0.111], [64710.2, 0.044], [64712.2, 2.336]], "asks": [[64734.3, 0.012], [64734.8, 0.551], [64742.6, 3.395], [64742.8, 0.17], [64746.8, 0.032], [64775.0, 0.0], [64783.9, 0.0], [64792.7, 0.004], [64869.9, 7.478], [65294.8, 3.212], [65359.4, 0.022], [65436.0, 3.315], [65553.7, 1.068], [65564.6, 0.763], [65667.4, 4.115], [65712.3, 0.007], [68595.0, 0.038]]}
{"kind": "depth", "E": 1787080116459, "U": 11315330382675, "u": 11315330391881, "recv_ms": 1787080116399, "bids": [[14212.2, 1.092], [14312.2, 3.108], [14412.2, 0.0], [58240.9, 0.002], [61476.5, 0.001], [62123.7, 0.689], [64065.1, 5.231], [64097.4, 10.963], [64194.5, 7.947], [64273.5, 0.0], [64279.9, 0.003], [64388.6, 3.428], [64650.7, 0.244], [64657.1, 0.478], [64707.3, 1.004], [64707.4, 0.208], [64707.5, 0.001], [64708.5, 0.172], [64709.0, 0.087], [64712.2, 2.329]], "asks": [[64712.3, 14.996], [64714.0, 0.02], [64714.4, 0.573], [64715.3, 2.502], [64715.9, 0.085], [64741.1, 2.202], [64741.2, 0.25], [64748.8, 1.27], [64758.1, 0.004], [64779.7, 0.031], [64792.7, 0.0], [64869.9, 10.423], [65359.4, 0.022], [65650.6, 24.624]]}
{"kind": "depth", "E": 1787080116561, "U": 11315330392104, "u": 11315330400569, "recv_ms": 1787080116500, "bids": [[1000.0, 35.81], [14212.2, 1.456], [14312.2, 2.744], [58240.9, 0.002], [61476.5, 0.0], [63712.2, 8.8], [64065.1, 5.231], [64141.4, 8.25], [64388.6, 3.427], [64657.1, 0.474], [64670.9, 2.44], [64704.1, 0.003], [64705.3, 0.72], [64707.4, 0.014], [64707.5, 0.195], [64708.5, 0.172], [64709.6, 0.086], [64712.2, 2.927]], "asks": [[64713.4, 0.002], [64713.5, 1.513], [64713.6, 0.003], [64714.1, 0.084], [64715.8, 0.003], [64715.9, 0.023], [64716.7, 0.064], [64719.2, 0.031], [64719.3, 0.313], [64742.6, 3.549], [64742.8, 0.016], [65035.9, 3.384], [65359.4, 0.022], [65424.1, 4.171], [65712.3, 0.027], [71183.6, 0.0]]}
{"kind": "depth", "E": 1787080116663, "U": 11315330400601, "u": 11315330407534, "recv_ms": 1787080116604, "bids": [[1000.0, 35.81], [14212.2, 1.806], [14312.2, 2.394], [51770.0, 0.0], [58240.9, 0.002], [61476.5, 0.0], [62123.7, 0.692], [63903.3, 6.895], [64065.1, 5.231], [64129.8, 31.831], [64618.2, 0.027], [64633.9, 33.17], [64642.7, 0.146], [64679.8, 1.889], [64692.1, 0.0], [64693.4, 0.068], [64694.8, 0.468], [64695.0, 0.012], [64698.3, 0.002], [64699.4, 1.287], [64701.1, 1.391], [64702.2, 0.08], [64702.3, 0.001], [64704.8, 0.464], [64705.0, 0.004], [64705.3, 0.627], [64705.4, 0.02], [64706.0, 0.012], [64707.4, 0.022], [64707.5, 0.001], [64708.8, 0.103], [64710.1, 1.909], [64712.2, 5.174]], "asks": [[64712.6, 0.002], [64714.0, 0.013], [64714.3, 0.007], [64714.4, 0.565], [64717.5, 2.335], [64732.3, 5.005], [64732.7, 1.548], [64733.4, 2.321], [64733.6, 0.476], [64734.8, 0.01], [64735.9, 0.541], [64742.6, 3.395], [64742.7, 0.154], [64767.2, 0.0], [64822.4, 0.017], [64980.8, 5.049], [65035.9, 3.385], [65359.4, 0.022], [65799.5, 0.606], [65895.2, 0.0]]}
{"kind": "depth", "E": 1787080116765, "U": 11315330407621, "u": 11315330414697, "recv_ms": 1787080116713, "bids": [[14212.2, 2.156], [14312.2, 2.044], [58240.9, 0.002], [61476.5, 0.0], [62123.7, 0.689], [63712.2, 8.78], [63935.7, 22.043], [64065.1, 5.231], [64388.6, 3.427], [64582.7, 0.0], [64635.5, 6.092], [64637.1, 0.009], [64642.8, 0.002], [64666.9, 0.54], [64679.4, 0.345], [64702.2, 0.096], [64705.3, 0.543], [64705.4, 0.004], [64706.0, 0.01], [64706.5, 0.028], [64706.7, 0.003], [64707.3, 0.85], [64707.4, 0.03], [64707.5, 0.001], [64710.2, 0.036], [64710.4, 0.093], [64712.2, 5.846]], "asks": [[64740.0, 0.487], [64747.3, 0.063], [64869.8, 7.473], [64869.9, 0.018], [65359.4, 0.022], [65485.5, 1.849], [65712.3, 0.007], [66006.5, 0.018]]}
{"kind": "depth", "E": 1787080116867, "U": 11315330414962, "u": 11315330422517, "recv_ms": 1787080116809, "bids": [[1000.0, 35.81], [14212.2, 2.52], [14312.2, 1.68], [51769.8, 0.0], [58240.9, 0.002], [61476.5, 0.001], [62123.7, 0.692], [63793.3, 1.878], [64065.1, 5.233], [64633.9, 0.0], [64635.5, 1.308], [64637.1, 0.0], [64640.5, 33.17], [64674.4, 0.011], [64695.0, 0.004], [64701.1, 1.391], [64702.2, 0.08], [64702.5, 0.155], [64703.9, 0.563], [64704.0, 0.153], [64705.2, 0.013], [64705.3, 0.002], [64706.9, 0.788], [64707.3, 0.309], [64707.4, 0.555], [64712.2, 5.817]], "asks": [[64713.2, 0.0], [64714.0, 0.003], [64714.3, 0.007], [64716.7, 0.148], [64734.3, 0.01], [64734.4, 1.24], [64742.6, 3.549], [64742.7, 0.0], [65359.4, 0.022], [65438.7, 0.003], [65505.5, 6.327], [67947.9, 0.064]]}
{"kind": "depth", "E": 1787080116969, "U": 11315330422525, "u": 11315330431820, "recv_ms": 1787080116909, "bids": [[14212.2, 2.884], [14312.2, 1.316], [58240.9, 0.002], [60894.2, 1.476], [61476.5, 0.0], [61476.7, 0.008], [63712.2, 7.703], [64065.1, 5.231], [64634.5, 0.0], [64640.5, 0.0], [64642.7, 33.316], [64666.9, 0.54], [64679.8, 1.886], [64694.8, 0.005], [64696.2, 0.005], [64701.0, 0.429], [64701.1, 1.237], [64702.2, 0.003], [64704.0, 1.257], [64705.6, 0.02], [64706.0, 0.01], [64706.7, 0.001], [64706.9, 0.781], [64707.4, 0.014], [64712.2, 5.787]], "asks": [[64713.3, 0.084], [64714.3, 0.007], [64728.7, 0.313], [64730.8, 0.042], [64770.6, 0.378], [64822.4, 0.014], [65359.4, 0.022], [65438.8, 0.0], [65482.4, 7.332], [65712.3, 0.027], [65799.5, 1.212], [66217.6, 0.0]]}
{"kind": "depth", "E": 1787080117071, "U": 11315330431916, "u": 11315330441451, "recv_ms": 1787080117013, "bids": [[14212.2, 3.234], [14312.2, 0.966], [58240.9, 0.002], [61476.5, 0.0], [62123.7, 0.689], [63556.3, 0.0], [63605.0, 1.023], [63621.0, 2.058], [63793.3, 2.112], [63923.0, 0.781], [64065.1, 5.231], [64388.6, 3.427], [64690.0, 0.379], [64694.8, 0.013], [64700.6, 0.246], [64701.0, 0.429], [64704.0, 1.249], [64705.3, 0.086], [64706.5, 0.025], [64708.6, 0.209], [64709.0, 0.003], [64709.6, 0.002], [64710.1, 1.825], [64710.4, 0.009], [64712.2, 5.666]], "asks": [[64712.3, 15.065], [64714.3, 0.017], [64716.6, 0.066], [64716.7, 0.086], [64869.8, 10.418], [65359.4, 0.022], [65570.3, 3.209], [66653.5, 0.004]]}
{"kind": "depth", "E": 1787080117275, "U": 11315330448731, "u": 11315330456635, "recv_ms": 1787080117217, "bids": [[14212.2, 3.78], [14312.2, 0.336], [14612.2, 0.084], [51770.0, 0.0], [58240.9, 0.002], [61476.5, 0.0], [62123.7, 0.689], [63546.2, 1.37], [63611.0, 1.575], [63838.6, 2.64], [63952.0, 6.292], [63965.0, 5.043], [64065.1, 5.231], [64571.5, 3.745], [64691.7, 0.521], [64694.8, 0.005], [64697.1, 0.962], [64698.2, 0.016], [64701.0, 0.429], [64701.1, 1.237], [64702.2, 0.011], [64702.3, 0.464], [64704.6, 0.016], [64707.2, 0.217], [64710.0, 0.013]], "asks": [[64712.3, 15.081], [64717.6, 0.017], [64724.1, 0.016], [64730.5, 0.017], [64734.3, 0.551], [64735.9, 0.0], [64741.0, 1.91], [64741.1, 0.317], [64852.9, 5.455], [65359.4, 0.022], [65428.0, 1.257], [65635.0, 7.61], [66006.5, 0.021], [67947.9, 0.068]]}
{"kind": "depth", "E": 1787080117377, "U": 11315330456840, "u": 11315330461909, "recv_ms": 1787080117317, "bids": [[14212.2, 3.668], [14312.2, 0.224], [14612.2, 0.308], [51770.0, 0.0], [58240.9, 0.002], [62123.7, 0.692], [63712.2, 7.703], [63806.2, 17.01], [64065.1, 5.231], [64388.6, 3.427], [64571.5, 2.907], [64571.6, 1.271], [64697.1, 0.962], [64701.0, 0.429], [64702.2, 0.003], [64703.9, 0.571], [64712.2, 5.724]], "asks": [[64718.5, 0.313], [64734.3, 0.01], [64734.8, 0.551], [65359.4, 0.022], [65553.6, 40.101], [65650.6, 25.688], [65712.3, 0.027]]}
{"kind": "depth", "E": 1787080117581, "U": 11315330467463, "u": 11315330473744, "recv_ms": 1787080117524, "bids": [[14212.2, 3.374], [14312.2, 0.0], [14612.2, 0.826], [58240.9, 0.002], [61476.5, 0.0], [62123.7, 0.689], [62185.0, 1.29], [63418.0, 2.692], [63557.7, 0.0], [63712.2, 7.683], [63938.7, 11.75], [64065.1, 5.231], [64141.4, 8.016], [64554.4, 0.0], [64571.5, 0.001], [64571.6, 0.0], [64600.0, 14.37], [64657.4, 0.0], [64697.1, 0.96], [64705.0, 0.088], [64708.1, 0.459], [64708.6, 0.125], [64712.2, 5.685]], "asks": [[64719.2, 0.008], [64852.9, 0.058], [64868.5, 0.781], [64869.8, 0.013], [64912.3, 0.594], [64912.4, 0.0], [65035.9, 3.383], [65039.0, 0.336], [65359.4, 0.022], [65618.3, 17.039], [65712.3, 0.007], [66006.5, 0.018], [67236.1, 1.199]]}
{"kind": "depth", "E": 1787080117785, "U": 11315330478953, "u": 11315330484171, "recv_ms": 1787080117724, "bids": [[1000.0, 35.81], [14212.2, 2.674], [14612.2, 1.526], [51770.0, 0.006], [58240.9, 0.002], [61476.7, 0.008], [62123.7, 0.689], [63547.4, 1.956], [63712.2, 7.703], [63935.7, 23.293], [64065.1, 5.231], [64388.6, 3.429], [64472.1, 0.003], [64582.7, 0.0], [64647.4, 0.007], [64658.8, 0.012], [64666.0, 3.261], [64694.8, 0.005], [64701.0, 0.429], [64701.1, 1.237], [64702.2, 0.474], [64702.3, 0.001], [64703.9, 0.563], [64705.1, 0.044], [64705.6, 0.018], [64712.1, 0.017]], "asks": [[64764.1, 0.006], [64980.8, 2.099], [65035.9, 3.997], [65179.8, 0.012], [65359.4, 0.022], [65712.3, 0.027]]}
{"kind": "depth", "E": 1787080117887, "U": 11315330484288, "u": 11315330490147, "recv_ms": 1787080117827, "bids": [[14212.2, 2.324], [14612.2, 1.876], [51769.8, 0.0], [51770.0, 0.0], [58240.9, 0.002], [61476.5, 0.0], [61476.6, 0.006], [62123.7, 0.692], [64011.9, 0.936], [64065.1, 5.231], [64129.8, 32.065], [64407.3, 0.0], [64554.5, 7.213], [64571.5, 2.016], [64696.0, 0.359], [64702.2, 0.003], [64703.3, 0.618], [64703.9, 1.034]], "asks": [[64712.3, 15.098], [64727.8, 0.643], [64735.2, 0.621], [64742.6, 3.549], [64852.8, 9.284], [64869.8, 10.418], [64902.3, 0.013], [65359.4, 0.022]]}
{"kind": "depth", "E": 1787080117989, "U": 11315330491046, "u": 11315330497728, "recv_ms": 1787080117929, "bids": [[1000.0, 35.81], [14212.2, 1.946], [14612.2, 2.254], [58240.9, 0.002], [63239.9, 0.001], [63712.2, 7.683], [64065.1, 5.231], [64388.6, 3.429], [64571.5, 0.001], [64594.7, 0.004], [64594.8, 3.864], [64594.9, 2.227], [64596.8, 3.347], [64598.7, 0.0], [64641.0, 0.323], [64646.2, 2.321], [64694.8, 0.013], [64696.0, 0.379], [64696.2, 0.005], [64701.0, 0.275], [64701.1, 1.391], [64703.9, 1.026], [64712.2, 5.684]], "asks": [[64728.7, 0.313], [64779.3, 0.387], [64781.3, 6.466], [64783.3, 36.251], [64783.5, 0.048], [64784.0, 2.878], [64785.5, 0.029], [64826.9, 0.0], [64847.8, 4.811], [64852.8, 3.887], [65037.9, 0.0], [65038.0, 0.814], [65327.1, 5.159], [65359.4, 0.022], [65630.2, 0.762], [65712.3, 0.007]]}
{"kind": "depth", "E": 1787080118091, "U": 11315330497740, "u": 11315330504443, "recv_ms": 1787080118032, "bids": [[1000.0, 35.81], [14212.2, 1.596], [14612.2, 2.604], [58240.9, 0.002], [61476.5, 0.0], [62123.7, 0.689], [63418.0, 2.689], [64000.4, 0.949], [64065.1, 5.231], [64142.4, 0.0], [64148.8, 0.002], [64515.6, 7.689], [64518.1, 1.306], [64554.5, 6.997], [64571.5, 2.45], [64598.6, 8.502], [64601.7, 0.009], [64642.4, 1.636], [64646.1, 2.555], [64650.7, 0.167], [64652.3, 0.079], [64658.8, 0.012], [64665.4, 0.002], [64676.3, 0.717], [64679.4, 0.009], [64681.6, 0.029], [64694.8, 0.476], [64695.7, 0.172], [64700.6, 0.246], [64701.0, 0.429], [64701.1, 1.237], [64703.3, 0.0], [64703.9, 0.563], [64704.8, 0.466], [64705.1, 0.042], [64707.1, 0.069], [64712.2, 5.607]], "asks": [[64712.3, 15.481], [64712.4, 0.044], [64713.3, 0.394], [64713.6, 0.002], [64715.3, 2.564], [64716.6, 0.004], [64719.0, 0.032], [64719.4, 0.004], [64727.8, 0.025], [64739.8, 0.036], [64742.6, 3.395], [64742.7, 0.154], [64755.9, 0.511], [64756.0, 0.047], [64778.6, 0.211], [64778.7, 0.173], [64779.0, 2.65], [64779.7, 0.027], [64781.3, 1.205], [64782.0, 0.011], [64782.2, 0.0], [64783.3, 0.0], [64787.7, 36.475], [64788.2, 0.0], [64788.5, 0.25], [64825.6, 3.853], [64826.5, 8.732], [64852.8, 8.788], [65169.3, 0.116], [65359.4, 0.022], [65382.5, 0.003], [65389.0, 0.126], [66006.5, 0.015]]}
{"kind": "depth", "E": 1787080118193, "U": 11315330504606, "u": 11315330514666, "recv_ms": 1787080118134, "bids": [[14212.2, 1.246], [14612.2, 2.954], [51770.0, 0.0], [58240.9, 0.002], [62123.7, 0.692], [64065.1, 5.231], [64534.2, 0.095], [64610.1, 0.001], [64611.0, 2.554], [64626.0, 0.236], [64633.2, 0.031], [64640.4, 0.003], [64642.8, 14.207], [64646.9, 2.439], [64655.3, 2.148], [64663.5, 0.008], [64663.6, 2.128], [64665.5, 3.526], [64666.9, 0.537], [64679.8, 1.889], [64681.6, 1.004], [64703.4, 0.002]], "asks": [[64718.4, 0.005], [64739.9, 1.006], [64742.7, 0.0], [64742.8, 0.016], [64742.9, 0.308], [64756.1, 3.502], [64770.6, 0.378], [64778.7, 6.173], [64783.3, 36.277], [64787.7, 0.224], [64797.2, 2.138], [64797.3, 0.006], [64805.6, 2.191], [64805.7, 0.002], [64811.0, 1.537], [64811.1, 0.001], [64812.5, 0.03], [64814.0, 2.125], [64869.8, 7.438], [65359.4, 0.022], [65694.9, 4.863]]}
{"kind": "depth", "E": 1787080118295, "U": 11315330514866, "u": 11315330521077, "recv_ms": 1787080118247, "bids": [[1000.0, 35.81], [14212.2, 0.882], [14612.2, 3.318], [51770.0, 0.0], [58240.9, 0.002], [61476.5, 0.0], [62123.7, 0.689], [63712.2, 7.703], [64065.1, 5.231], [64388.6, 3.429], [64469.5, 0.095], [64571.5, 0.001], [64690.0, 0.375], [64694.8, 0.005], [64697.5, 0.004], [64701.0, 0.438], [64702.2, 0.544], [64702.3, 0.472], [64704.0, 0.229], [64704.1, 0.019], [64707.2, 0.216], [64707.3, 0.619], [64707.4, 0.014], [64709.3, 0.088], [64710.2, 0.036]], "asks": [[64712.3, 15.45], [64712.4, 0.045], [64712.5, 0.001], [64713.3, 0.084], [64740.9, 1.886], [64741.0, 0.025], [64750.6, 4.153], [64753.2, 0.986], [64753.3, 2.322], [64852.8, 3.887], [64882.1, 4.156], [64885.5, 0.0], [64902.3, 0.362], [65359.4, 0.022], [65570.3, 0.163], [65673.7, 8.21], [65712.3, 0.027]]}
{"kind": "depth", "E": 1787080118397, "U": 11315330521166, "u": 11315330527222, "recv_ms": 1787080118340, "bids": [[1000.0, 35.81], [14212.2, 0.532], [14612.2, 3.668], [58240.9, 0.002], [61476.5, 0.0], [63712.2, 7.683], [63776.6, 0.0], [64065.1, 5.231], [64515.6, 7.229], [64518.1, 0.0], [64554.5, 6.88], [64571.5, 2.379], [64610.5, 10.003], [64690.4, 0.56], [64690.8, 0.002], [64692.1, 0.116], [64692.6, 0.001], [64692.7, 0.045], [64693.4, 0.061], [64694.1, 0.019], [64694.8, 0.005], [64695.0, 0.004], [64700.9, 0.311], [64701.4, 0.463], [64702.2, 0.466], [64702.3, 0.009], [64702.5, 0.001], [64703.8, 1.321], [64703.9, 0.563], [64704.0, 0.67], [64704.1, 0.157], [64704.2, 0.003], [64704.4, 0.214], [64704.5, 0.007], [64704.8, 0.464], [64705.0, 0.097], [64705.7, 0.241], [64707.0, 0.013], [64707.3, 0.619], [64707.4, 0.03], [64708.0, 0.236], [64708.8, 0.104], [64709.8, 0.12], [64710.0, 0.011], [64710.2, 0.036], [64712.2, 3.434]], "asks": [[64712.3, 15.368], [64712.4, 0.043], [64712.5, 0.002], [64712.6, 0.086], [64712.7, 0.002], [64713.4, 0.002], [64714.0, 0.006], [64715.2, 0.004], [64715.3, 2.502], [64715.9, 0.085], [64718.4, 0.004], [64728.0, 1.053], [64729.5, 0.005], [64731.1, 1.885], [64731.9, 0.095], [64735.6, 0.116], [64736.3, 0.181], [64739.2, 3.451], [64740.4, 0.003], [64812.3, 2.327], [64812.4, 10.0], [64812.5, 0.022], [64852.8, 9.284], [64868.5, 0.781], [64869.8, 10.418], [64908.7, 15.417], [65359.4, 0.022], [65712.3, 0.007]]}
{"kind": "depth", "E": 1787080118499, "U": 11315330527251, "u": 11315330536805, "recv_ms": 1787080118441, "bids": [[14212.2, 0.308], [14512.2, 0.14], [14612.2, 3.752], [58240.9, 0.002], [62123.7, 0.692], [63573.3, 0.058], [64065.1, 5.231], [64404.8, 0.098], [64668.5, 0.339], [64704.0, 0.129], [64704.1, 0.404], [64704.5, 0.0], [64705.0, 0.004], [64707.0, 0.561], [64707.3, 0.465], [64707.4, 0.022], [64709.8, 0.036], [64710.2, 0.044]], "asks": [[64843.0, 2.745], [64857.1, 0.007], [65359.4, 0.022], [65683.0, 0.835], [65887.8, 0.65], [66006.5, 0.012]]}
{"kind": "depth", "E": 1787080118601, "U": 11315330537244, "u": 11315330545634, "recv_ms": 1787080118544, "bids": [[1000.0, 35.81], [14212.2, 0.196], [14512.2, 0.392], [14612.2, 3.612], [58240.9, 0.002], [61476.5, 0.0], [62123.7, 0.689], [64065.1, 5.231], [64388.6, 3.429], [64658.8, 0.008], [64666.0, 3.265], [64668.5, 0.185], [64704.2, 0.003], [64707.0, 0.554], [64707.1, 0.076], [64712.2, 3.479]], "asks": [[64712.3, 15.367], [64718.9, 0.021], [64728.0, 0.128], [64728.6, 1.73], [65359.4, 0.022], [65451.1, 0.002], [65663.6, 3.116], [71183.6, 0.0]]}
{"kind": "depth", "E": 1787080118703, "U": 11315330545693, "u": 11315330552664, "recv_ms": 1787080118645, "bids": [[1000.0, 35.81], [14212.2, 0.07], [14512.2, 0.616], [14612.2, 3.514], [51770.0, 0.0], [58240.9, 0.002], [61476.5, 0.001], [62123.7, 0.692], [63573.3, 0.843], [63712.2, 7.703], [63766.8, 4.227], [64065.1, 5.231], [64340.1, 0.171], [64388.6, 3.428], [64571.5, 0.001], [64571.6, 0.0], [64582.7, 0.0], [64615.1, 2.344], [64666.9, 0.54], [64707.3, 0.619], [64712.2, 3.463]], "asks": [[64822.4, 0.017], [64852.8, 3.887], [64868.5, 2.2], [64902.3, 0.013], [65035.9, 3.998], [65309.3, 0.031], [65359.4, 0.022], [65533.1, 4.137], [65712.3, 0.027], [66200.7, 0.754], [66437.0, 0.0]]}
{"kind": "depth", "E": 1787080118805, "U": 11315330552807, "u": 11315330559486, "recv_ms": 1787080118745, "bids": [[14212.2, 0.0], [14512.2, 0.896], [14612.2, 3.304], [51769.8, 0.002], [58240.9, 0.002], [61476.5, 0.0], [62123.7, 0.689], [63418.0, 2.692], [63712.2, 7.683], [64065.1, 5.231], [64388.6, 3.427], [64554.5, 7.764], [64571.5, 2.845], [64694.8, 0.468], [64695.0, 0.012], [64699.4, 1.296], [64701.0, 0.429], [64702.2, 0.104], [64702.3, 0.001], [64703.8, 1.319], [64704.1, 0.311], [64704.2, 0.003], [64705.6, 0.02], [64706.3, 0.006], [64707.0, 0.013], [64707.4, 0.555], [64712.2, 5.637]], "asks": [[64714.0, 0.003], [64714.3, 0.007], [64728.6, 0.805], [64729.3, 1.553], [64734.5, 0.005], [64735.2, 0.003], [64749.0, 0.0], [64750.6, 4.155], [64852.8, 9.284], [64869.8, 10.418], [65359.4, 0.022], [65712.3, 0.007]]}
{"kind": "depth", "E": 1787080118907, "U": 11315330559597, "u": 11315330565050, "recv_ms": 1787080118850, "bids": [[1000.0, 35.81], [14512.2, 1.26], [14612.2, 2.94], [51769.8, 0.0], [58240.9, 0.002], [63601.0, 2.167], [64011.9, 0.702], [64065.1, 5.231], [64388.6, 3.427], [64694.8, 0.476], [64695.0, 0.004], [64700.5, 0.158], [64700.9, 0.311], [64701.0, 0.275], [64702.2, 0.003], [64704.0, 0.229], [64704.2, 0.544], [64704.8, 0.466], [64705.6, 0.018], [64706.3, 0.003], [64707.1, 0.069], [64707.4, 0.022], [64710.2, 0.044]], "asks": [[64902.3, 0.512], [65035.9, 3.999], [65240.6, 1.23], [65299.3, 0.229], [65359.4, 0.022], [65485.5, 0.934], [65499.5, 3.36]]}
{"kind": "depth", "E": 1787080119009, "U": 11315330565242, "u": 11315330570346, "recv_ms": 1787080118948, "bids": [[1000.0, 35.81], [14512.2, 1.624], [14612.2, 2.576], [58240.9, 0.002], [62123.7, 0.692], [63935.7, 24.855], [64065.1, 5.231], [64391.7, 1.753], [64694.8, 0.005], [64696.2, 0.005], [64702.2, 0.644], [64702.3, 0.488], [64703.9, 0.022], [64704.0, 0.129], [64704.2, 0.003], [64704.4, 0.214], [64704.5, 0.0], [64705.0, 0.004], [64705.1, 0.042], [64705.2, 0.554], [64707.4, 0.014], [64710.2, 0.036]], "asks": [[64714.3, 0.017], [64728.7, 0.313], [64980.8, 5.058], [65309.2, 0.0], [65359.4, 0.022], [66431.4, 0.12]]}
{"kind": "depth", "E": 1787080119111, "U": 11315330570387, "u": 11315330583585, "recv_ms": 1787080119050, "bids": [[14512.2, 1.974], [14612.2, 2.226], [58240.9, 0.002], [61476.5, 0.0], [61476.7, 0.006], [62123.7, 0.689], [63712.2, 7.703], [63846.1, 0.049], [63847.9, 4.892], [64065.1, 5.231], [64633.2, 0.033], [64673.0, 0.088], [64692.1, 0.0], [64692.3, 0.162], [64692.8, 1.473], [64694.1, 0.019], [64694.2, 0.232], [64694.8, 0.005], [64696.0, 0.379], [64700.6, 0.246], [64701.6, 0.002], [64701.7, 0.53], [64702.2, 0.466], [64702.3, 0.009], [64703.9, 0.565], [64704.0, 0.222], [64704.2, 0.01], [64704.8, 0.464], [64705.2, 0.013], [64707.0, 0.554], [64707.4, 0.022], [64710.2, 0.044], [64712.2, 3.321]], "asks": [[64719.1, 1.002], [64719.3, 0.622], [64719.5, 0.001], [64720.3, 0.019], [64726.1, 0.219], [64733.5, 0.62], [64734.5, 0.001], [64902.3, 0.013], [65359.4, 0.022], [65482.4, 8.247], [65488.8, 30.884], [65667.4, 2.138], [65712.3, 0.027]]}
{"kind": "depth", "E": 1787080119315, "U": 11315330593976, "u": 11315330602316, "recv_ms": 1787080119261, "bids": [[1000.0, 35.81], [14512.2, 2.688], [14612.2, 1.512], [58240.9, 0.002], [61476.5, 0.0], [61476.6, 0.004], [61476.7, 0.008], [62123.7, 0.689], [63712.2, 7.683], [63804.8, 0.349], [63838.6, 3.265], [64065.1, 5.231], [64107.3, 6.318], [64388.6, 4.047], [64634.5, 0.003], [64670.7, 0.179], [64690.4, 0.004], [64691.5, 0.56], [64694.8, 0.468], [64695.0, 0.012], [64696.1, 0.003], [64696.8, 0.926], [64697.4, 0.004], [64702.2, 0.003], [64702.3, 0.542], [64703.8, 1.319], [64703.9, 0.563], [64704.0, 0.238], [64704.2, 0.01], [64705.6, 0.018], [64706.2, 0.007], [64706.7, 0.003], [64707.0, 0.013], [64707.1, 0.069], [64707.4, 0.014], [64709.8, 0.12], [64710.2, 0.036], [64712.2, 6.999]], "asks": [[64712.3, 14.981], [64712.7, 0.001], [64713.6, 0.003], [64714.1, 0.084], [64714.3, 0.01], [64714.4, 0.572], [64715.9, 0.023], [64716.9, 0.063], [64718.4, 0.026], [64719.3, 0.313], [64720.1, 2.628], [64731.1, 1.329], [64731.8, 0.558], [64732.3, 0.005], [64734.8, 0.01], [64735.6, 0.001], [64735.9, 0.541], [64736.2, 0.116], [64775.4, 0.004], [64782.0, 0.007], [64869.8, 10.418], [64905.8, 0.428], [65298.9, 0.234], [65359.4, 0.022], [65712.3, 0.007]]}
{"kind": "depth", "E": 1787080119417, "U": 11315330602481, "u": 11315330612540, "recv_ms": 1787080119359, "bids": [[14512.2, 3.038], [14612.2, 1.162], [58240.9, 0.002], [61476.5, 0.0], [63418.0, 2.695], [63838.6, 3.89], [63946.0, 3.659], [64065.1, 5.231], [64204.9, 0.009], [64388.6, 4.057], [64399.1, 0.613], [64670.7, 0.165], [64673.3, 0.068], [64676.3, 0.381], [64680.5, 0.338], [64690.0, 0.379], [64704.4, 0.338], [64705.3, 0.002], [64707.2, 0.092], [64708.0, 0.234], [64708.1, 0.228], [64708.4, 0.432], [64710.8, 0.084], [64712.1, 0.019], [64712.2, 8.093]], "asks": [[64712.3, 14.98], [64712.6, 0.002], [64713.3, 0.0], [64718.4, 0.004], [64718.7, 0.4], [64719.8, 0.002], [64730.2, 0.001], [64730.7, 0.005], [64736.0, 1.603], [64737.3, 1.704], [64782.2, 0.018], [65359.4, 0.022], [65572.4, 0.0], [65650.6, 26.601]]}
{"kind": "depth", "E": 1787080119519, "U": 11315330612659, "u": 11315330619909, "recv_ms": 1787080119459, "bids": [[1000.0, 35.81], [14512.2, 3.402], [14612.2, 0.798], [58240.9, 0.002], [61476.5, 0.0], [62123.7, 0.692], [63712.2, 7.703], [63914.9, 8.381], [64065.1, 5.231], [64097.4, 11.585], [64388.6, 4.047], [64634.5, 0.0], [64666.9, 0.537], [64673.3, 0.082], [64679.8, 1.889], [64690.8, 0.558], [64691.5, 0.004], [64692.4, 5.022], [64696.2, 0.93], [64696.8, 0.001], [64702.4, 0.005], [64704.0, 0.161], [64704.1, 0.157], [64704.2, 0.087], [64704.4, 0.214], [64704.6, 0.14], [64704.8, 0.636], [64710.0, 0.013], [64712.1, 0.017], [64712.2, 7.089]], "asks": [[64720.4, 0.002], [64734.3, 0.551], [64735.9, 0.0], [64770.6, 0.378], [64822.4, 0.014], [65312.6, 0.0], [65359.4, 0.022], [65621.9, 6.021], [65712.3, 0.027]]}
{"kind": "depth", "E": 1787080119621, "U": 11315330620143, "u": 11315330626360, "recv_ms": 1787080119569, "bids": [[1000.0, 35.81], [14412.2, 0.028], [14512.2, 3.696], [14612.2, 0.476], [58240.9, 0.002], [62123.7, 0.689], [63914.9, 8.029], [64011.9, 0.468], [64065.1, 5.231], [64388.6, 4.435], [64694.8, 0.476], [64695.0, 0.004], [64702.2, 0.003], [64702.3, 0.001], [64704.0, 0.129], [64704.1, 0.311], [64704.2, 0.003], [64704.6, 0.016], [64704.7, 0.001], [64705.0, 0.097], [64705.6, 0.02], [64706.7, 0.001], [64707.0, 0.137], [64707.4, 0.578], [64710.1, 0.001], [64710.2, 0.12], [64710.8, 0.0]], "asks": [[64712.3, 14.981], [64718.8, 0.023], [64719.8, 0.001], [64725.2, 0.141], [64869.8, 7.458], [65359.4, 0.022]]}
{"kind": "depth", "E": 1787080119723, "U": 11315330626574, "u": 11315330632884, "recv_ms": 1787080119663, "bids": [[14412.2, 0.196], [14512.2, 3.724], [14612.2, 0.28], [58240.9, 0.002], [61476.5, 0.0], [62123.7, 0.692], [63418.0, 2.698], [63712.2, 7.683], [63935.7, 25.791], [63961.0, 0.785], [64065.1, 5.231], [64194.5, 8.568], [64388.6, 4.446], [64516.1, 1.155], [64571.6, 1.262], [64582.7, 0.0], [64594.8, 0.001], [64594.9, 0.689], [64595.1, 3.886], [64611.0, 3.411], [64641.0, 0.323], [64670.7, 0.179], [64692.4, 0.022], [64694.8, 0.005], [64702.2, 0.003], [64704.0, 0.677], [64704.2, 0.544], [64704.8, 0.638], [64705.0, 0.02], [64705.6, 0.018], [64707.4, 0.037], [64707.5, 0.001], [64710.0, 0.012], [64710.2, 0.119], [64712.2, 7.028]], "asks": [[64713.1, 0.085], [64713.2, 0.002], [64734.3, 0.551], [64735.9, 0.0], [64740.8, 3.164], [64740.9, 0.001], [64742.6, 0.104], [64743.1, 0.006], [64744.7, 1.866], [64781.3, 6.469], [64783.5, 0.048], [64811.0, 2.838], [64847.8, 4.811], [64869.8, 10.418], [64880.7, 0.933], [65035.9, 3.998], [65359.4, 0.022], [65712.3, 0.007]]}
{"kind": "depth", "E": 1787080119825, "U": 11315330632961, "u": 11315330638405, "recv_ms": 1787080119765, "bids": [[1000.0, 35.81], [14412.2, 0.434], [14512.2, 3.598], [14612.2, 0.168], [51769.8, 0.0], [58240.9, 0.002], [63223.8, 0.793], [63817.8, 30.995], [64009.5, 0.938], [64065.1, 5.233], [64697.1, 0.962], [64700.5, 0.158]], "asks": [[64741.8, 0.394], [64742.9, 0.154], [65359.4, 0.022], [65611.8, 8.074]]}
{"kind": "depth", "E": 1787080119927, "U": 11315330638457, "u": 11315330646576, "recv_ms": 1787080119868, "bids": [[1000.0, 35.81], [14412.2, 0.672], [14512.2, 3.472], [14612.2, 0.056], [58240.9, 0.002], [61476.5, 0.0], [61476.7, 0.006], [62123.7, 0.689], [63712.2, 7.703], [63947.2, 17.181], [64000.4, 1.417], [64065.1, 5.231], [64388.6, 4.447], [64571.5, 2.893], [64697.1, 0.962], [64704.2, 0.003], [64707.4, 0.578], [64712.2, 6.997]], "asks": [[64725.2, 0.141], [64741.8, 0.24], [64742.4, 0.233], [64852.8, 9.284], [64869.8, 10.418], [65035.9, 3.997], [65359.4, 0.024], [65558.9, 0.267], [65630.1, 28.714], [65712.3, 0.027], [66283.5, 0.003]]}
{"kind": "depth", "E": 1787080120029, "U": 11315330646606, "u": 11315330653135, "recv_ms": 1787080119969, "bids": [[14412.2, 0.994], [14512.2, 3.206], [14612.2, 0.0], [58240.9, 0.002], [62123.7, 0.692], [63822.5, 6.258], [63996.2, 0.234], [64065.1, 5.231], [64259.2, 0.289], [64388.6, 4.437], [64669.3, 0.0], [64669.8, 0.065], [64694.8, 0.005], [64696.2, 0.93], [64697.1, 0.96], [64702.2, 0.003], [64704.0, 0.677], [64704.2, 0.544], [64704.8, 0.638], [64705.0, 0.02], [64705.6, 0.018], [64707.4, 0.037], [64707.5, 0.001], [64709.3, 0.246], [64710.2, 0.035], [64712.2, 7.041]], "asks": [[64712.6, 0.086], [64728.7, 0.313], [64740.4, 3.501], [64773.0, 0.04], [64773.4, 0.071], [64869.8, 10.418], [65359.4, 0.022], [65427.8, 4.878], [66006.5, 0.006]]}
{"kind": "depth", "E": 1787080120131, "U": 11315330653194, "u": 11315330661826, "recv_ms": 1787080120070, "bids": [[1000.0, 35.81], [14412.2, 1.344], [14512.2, 2.856], [58240.9, 0.002], [61476.5, 0.0], [62123.7, 0.689], [63712.2, 7.683], [64065.1, 5.231], [64694.8, 0.005], [64696.3, 0.859], [64700.5, 0.158], [64700.6, 0.245], [64702.2, 0.003], [64702.9, 0.005], [64703.6, 0.62], [64704.0, 0.7], [64704.2, 0.544], [64704.8, 0.636], [64705.0, 0.004], [64705.6, 0.02], [64707.4, 0.03], [64711.4, 0.002], [64711.7, 0.092], [64712.2, 7.095]], "asks": [[64712.3, 14.98], [64712.6, 0.002], [64719.5, 0.002], [64725.2, 0.141], [64728.2, 0.62], [64731.1, 1.885], [64731.7, 5.847], [64731.8, 0.002], [64735.5, 0.618], [64777.1, 0.02], [64869.8, 10.418], [65359.4, 0.022], [65376.1, 0.0], [65553.6, 43.147], [65628.4, 13.621], [65712.3, 0.007]]}
{"kind": "depth", "E": 1787080120233, "U": 11315330661920, "u": 11315330668633, "recv_ms": 1787080120172, "bids": [[1000.0, 35.81], [14412.2, 1.708], [14512.2, 2.492], [58240.9, 0.002], [62123.7, 0.692], [63806.2, 19.358], [63919.6, 0.0], [64065.1, 5.231], [64700.0, 0.691], [64700.5, 0.004], [64704.0, 0.6], [64704.1, 0.311], [64704.2, 0.096], [64704.8, 0.636], [64705.0, 0.004], [64705.6, 0.018], [64705.7, 0.243], [64705.8, 0.021], [64707.4, 0.578], [64708.0, 0.076], [64710.2, 0.119], [64712.2, 7.183]], "asks": [[64712.3, 14.981], [64719.5, 0.001], [64725.2, 0.141], [65359.4, 0.024], [65417.7, 4.193]]}
{"kind": "depth", "E": 1787080120335, "U": 11315330668703, "u": 11315330676046, "recv_ms": 1787080120275, "bids": [[14412.2, 2.058], [14512.2, 2.142], [51770.0, 0.0], [58240.9, 0.002], [61476.5, 0.0], [63712.2, 7.703], [64065.1, 5.231], [64141.4, 7.782], [64388.6, 4.447], [64554.5, 7.848], [64571.5, 2.893], [64571.6, 0.0], [64692.3, 0.046], [64693.1, 0.146], [64697.0, 0.017], [64698.0, 1.924], [64700.0, 0.537], [64700.2, 0.205], [64710.2, 0.035]], "asks": [[64714.3, 0.0], [64725.2, 0.141], [64731.1, 1.329], [64731.6, 0.559], [64852.8, 8.581], [64868.5, 0.781], [64869.8, 10.418], [65359.4, 0.022], [65359.5, 0.001], [65435.2, 1.234], [65712.3, 0.027], [66006.5, 0.009]]}
{"kind": "depth", "E": 1787080120437, "U": 11315330676183, "u": 11315330682081, "recv_ms": 1787080120375, "bids": [[1000.0, 35.81], [14412.2, 2.408], [14512.2, 1.792], [51770.0, 0.0], [58240.9, 0.002], [61476.5, 0.0], [62123.7, 0.689], [63418.0, 2.695], [63804.8, 0.115], [63903.3, 7.676], [64065.1, 5.231], [64705.4, 0.006], [64705.7, 0.241], [64709.8, 0.036], [64712.2, 7.228]], "asks": [[64712.6, 0.086], [64742.3, 0.687], [64742.4, 0.079], [64869.8, 7.46], [65359.4, 0.022], [65952.9, 0.0], [66017.6, 0.0]]}
{"kind": "depth", "E": 1787080120539, "U": 11315330682298, "u": 11315330688698, "recv_ms": 1787080120480, "bids": [[1000.0, 35.81], [14412.2, 2.772], [14512.2, 1.428], [58240.9, 0.002], [61476.5, 0.0], [62123.7, 0.692], [63712.2, 7.683], [64065.1, 5.231], [64571.5, 0.001], [64621.0, 0.13], [64621.1, 0.022], [64704.1, 0.868], [64707.3, 0.465], [64707.4, 0.021], [64707.5, 0.001], [64708.5, 0.173], [64709.7, 0.09], [64712.2, 7.262]], "asks": [[64712.3, 14.98], [64741.2, 0.25], [64741.3, 1.328], [64741.4, 0.655], [64744.2, 0.002], [64744.3, 0.004], [64744.4, 0.126], [64745.0, 2.959], [64745.1, 1.012], [64745.2, 0.006], [64747.2, 1.398], [64747.3, 0.063], [64747.4, 0.008], [64781.3, 1.205], [64783.3, 0.0], [64784.8, 0.037], [64785.5, 36.39], [64787.7, 0.224], [64852.8, 3.887], [64894.9, 1.547], [65359.4, 0.022], [65521.2, 7.782], [65583.1, 1.522], [65621.9, 5.139], [65712.3, 0.007]]}
{"kind": "depth", "E": 1787080120641, "U": 11315330688728, "u": 11315330700534, "recv_ms": 1787080120582, "bids": [[14412.2, 3.136], [14512.2, 1.064], [58240.9, 0.002], [61476.5, 0.0], [62123.7, 0.689], [64065.1, 5.231], [64129.8, 32.299], [64388.6, 4.447], [64554.5, 7.838], [64571.5, 2.888], [64692.6, 0.117], [64693.1, 0.03], [64696.0, 0.379], [64704.1, 0.311], [64704.8, 0.636], [64705.4, 0.004], [64705.6, 0.02], [64705.8, 0.021], [64707.3, 0.619], [64707.4, 0.578], [64712.2, 7.205]], "asks": [[64740.7, 1.997], [64740.8, 1.279], [64783.3, 36.361], [64784.8, 0.019], [64785.5, 0.029], [64852.8, 9.284], [64869.8, 10.418], [65064.8, 0.0], [65359.4, 0.022], [65533.0, 3.033], [65861.6, 0.0], [65906.8, 3.035], [65943.0, 0.379], [66007.7, 0.303], [71183.5, 0.01]]}
{"kind": "depth", "E": 1787080120743, "U": 11315330700593, "u": 11315330707167, "recv_ms": 1787080120685, "bids": [[1000.0, 35.81], [14412.2, 3.486], [14512.2, 0.714], [58240.9, 0.0], [62123.7, 0.692], [63712.2, 7.703], [64065.1, 5.231], [64168.6, 0.197], [64388.6, 4.446], [64571.6, 1.269], [64582.7, 0.0], [64595.2, 1.681], [64615.1, 2.336], [64647.5, 0.004], [64656.8, 0.0], [64657.1, 0.442], [64657.5, 0.27], [64657.8, 0.002], [64658.1, 0.004], [64666.9, 0.54], [64674.3, 0.0], [64674.6, 0.001], [64674.9, 0.016], [64675.2, 0.152], [64675.6, 0.0], [64679.8, 1.886], [64689.2, 0.029], [64689.3, 0.042], [64689.4, 1.082], [64689.6, 1.326], [64689.7, 0.159], [64689.8, 2.327], [64689.9, 0.0], [64690.0, 0.309], [64690.2, 0.001], [64690.9, 0.014], [64691.3, 0.021], [64704.3, 0.248], [64705.6, 0.018], [64707.8, 0.078], [64707.9, 0.077], [64708.0, 0.076], [64708.1, 0.088], [64708.2, 0.116], [64708.3, 0.096], [64708.4, 0.232], [64708.5, 0.003], [64708.6, 0.025], [64708.7, 0.103], [64708.8, 0.004], [64708.9, 0.001], [64709.2, 0.019], [64709.5, 0.002], [64709.8, 0.004], [64710.2, 0.0], [64710.5, 0.005], [64712.2, 7.208]], "asks": [[64721.1, 0.02], [64721.4, 0.006], [64721.7, 0.002], [64722.0, 0.638], [64722.2, 0.153], [64722.4, 1.952], [64722.7, 2.761], [64722.8, 0.602], [64722.9, 0.0], [64723.0, 0.073], [64723.1, 0.085], [64723.2, 2.236], [64723.3, 0.312], [64723.4, 0.245], [64723.5, 0.007], [64723.6, 0.383], [64727.1, 0.484], [64738.5, 0.361], [64738.9, 0.001], [64739.2, 3.416], [64739.5, 0.012], [64739.8, 0.001], [64740.2, 0.146], [64740.7, 1.887], [64741.4, 0.564], [64741.5, 0.127], [64741.6, 0.093], [64741.7, 0.07], [64741.8, 0.07], [64741.9, 0.088], [64742.0, 0.077], [64742.1, 0.007], [64742.2, 0.0], [64742.3, 0.617], [64742.4, 0.009], [64749.3, 1.352], [64756.0, 0.015], [64756.3, 0.166], [64756.6, 0.033], [64757.0, 0.0], [64757.3, 0.0], [64770.6, 0.378], [64777.0, 0.076], [64781.3, 6.482], [64868.5, 2.2], [65035.9, 3.998], [65300.0, 133.639], [65359.4, 0.022], [65611.8, 8.956], [65712.3, 0.027], [71183.5, 0.008]]}
{"kind": "depth", "E": 1787080120845, "U": 11315330707172, "u": 11315330713705, "recv_ms": 1787080120786, "bids": [[1000.0, 35.81], [14312.2, 0.056], [14412.2, 3.724], [14512.2, 0.42], [51769.8, 0.0], [58240.9, 0.002], [61476.5, 0.0], [63418.0, 2.698], [63887.2, 0.938], [64065.1, 5.231], [64391.7, 0.31], [64674.0, 0.034], [64674.7, 0.035], [64675.0, 0.744], [64675.3, 0.104], [64690.2, 0.557], [64690.8, 0.002], [64691.8, 0.117], [64692.6, 0.001], [64695.5, 0.926], [64696.2, 0.005], [64706.2, 0.004], [64708.3, 0.166], [64708.9, 0.033], [64709.6, 0.034], [64709.7, 0.006], [64709.9, 0.051], [64710.2, 0.032], [64712.2, 7.132]], "asks": [[64720.7, 0.034], [64721.1, 0.052], [64721.4, 0.041], [64722.0, 0.673], [64722.7, 2.831], [64728.0, 1.053], [64729.3, 0.628], [64734.8, 0.125], [64736.2, 0.001], [64738.2, 0.033], [64738.5, 0.393], [64738.9, 0.036], [64739.5, 0.047], [64741.4, 0.634], [64755.7, 0.034], [64756.0, 0.047], [64756.3, 0.201], [64757.0, 0.035], [64869.8, 7.472], [65359.4, 0.022], [65844.8, 3.642]]}
{"kind": "depth", "E": 1787080120947, "U": 11315330713707, "u": 11315330720142, "recv_ms": 1787080120887, "bids": [[14312.2, 0.252], [14412.2, 3.696], [14512.2, 0.252], [58240.9, 0.002], [61476.5, 0.0], [61476.6, 0.006], [62123.7, 0.689], [63712.2, 7.683], [63817.8, 30.807], [64065.1, 5.231], [64388.6, 4.445], [64393.4, 0.325], [64674.3, 0.032], [64703.6, 0.002], [64704.1, 0.157], [64707.7, 0.169], [64707.9, 0.147], [64708.6, 0.125], [64709.3, 0.278], [64712.2, 6.963]], "asks": [[64714.0, 0.013], [64721.7, 0.037], [64722.2, 0.624], [64722.4, 2.082], [64723.1, 0.162], [64723.3, 0.382], [64727.1, 0.013], [64728.0, 0.128], [64728.9, 1.089], [64734.8, 0.01], [64735.7, 0.306], [64739.2, 3.451], [64739.9, 1.136], [64741.8, 0.147], [64742.0, 0.147], [64756.6, 0.068], [64869.8, 7.548], [65035.9, 3.999], [65043.5, 0.018], [65359.4, 0.022], [65533.1, 3.795], [65712.3, 0.007]]}
{"kind": "depth", "E": 1787080121049, "U": 11315330720316, "u": 11315330726852, "recv_ms": 1787080120990, "bids": [[1000.0, 35.81], [14312.2, 0.504], [14412.2, 3.556], [14512.2, 0.14], [58240.9, 0.002], [61476.5, 0.0], [61476.6, 0.004], [61476.7, 0.008], [62123.7, 0.692], [63793.3, 2.346], [64065.1, 5.231], [64657.2, 0.063], [64696.2, 0.003], [64700.2, 0.051], [64700.6, 0.25], [64700.7, 0.416], [64702.2, 0.466], [64702.3, 0.001], [64702.5, 0.155], [64704.0, 0.222], [64704.1, 0.165], [64704.2, 0.003], [64705.0, 0.004], [64707.8, 0.148], [64708.1, 0.288], [64708.2, 0.216], [64708.4, 0.432], [64708.5, 0.073], [64708.7, 0.173], [64712.2, 7.051]], "asks": [[64722.3, 1.133], [64722.5, 1.179], [64722.6, 1.113], [64722.8, 0.702], [64722.9, 0.21], [64723.2, 2.306], [64725.2, 0.141], [64728.7, 0.311], [64740.3, 0.135], [64741.1, 0.408], [64741.2, 0.327], [64741.3, 1.428], [64741.4, 0.744], [64741.6, 0.193], [64741.7, 0.17], [64741.9, 0.158], [64742.3, 0.463], [64742.6, 0.258], [64776.7, 0.021], [64781.3, 1.205], [64783.3, 0.0], [64784.8, 0.037], [64785.5, 36.26], [64787.7, 0.224], [64789.9, 0.004], [65295.3, 0.071], [65306.6, 0.0], [65359.4, 0.022], [65500.7, 16.224], [65598.9, 0.001], [65650.6, 26.487]]}
{"kind": "depth", "E": 1787080121151, "U": 11315330726894, "u": 11315330733517, "recv_ms": 1787080121092, "bids": [[1000.0, 35.81], [14312.2, 0.728], [14412.2, 3.458], [14512.2, 0.014], [51770.0, 0.0], [58240.9, 0.002], [62123.7, 0.689], [63712.2, 7.703], [63725.1, 0.051], [63789.9, 0.021], [63791.6, 0.018], [63870.9, 8.367], [63928.7, 0.013], [64011.9, 0.234], [64065.1, 5.231], [64571.5, 0.001], [64626.0, 0.234], [64633.2, 0.031], [64640.4, 0.001], [64656.6, 0.035], [64657.5, 0.305], [64657.8, 0.034], [64689.0, 0.07], [64689.1, 0.095], [64689.2, 0.099], [64689.5, 0.153], [64690.2, 0.001], [64691.0, 0.556], [64691.8, 0.001], [64692.6, 0.117], [64696.2, 0.005], [64700.6, 0.245], [64702.2, 0.003], [64702.5, 0.001], [64702.8, 0.618], [64702.9, 0.128], [64704.0, 0.129], [64704.1, 0.319], [64704.2, 0.466], [64704.7, 0.002], [64705.0, 0.645], [64707.3, 0.465], [64707.4, 0.014], [64707.5, 0.001], [64708.5, 0.073], [64712.2, 7.017]], "asks": [[64721.3, 0.005], [64725.2, 0.141], [64728.7, 0.313], [64852.8, 3.887], [65359.4, 0.024], [65564.6, 1.525], [65570.9, 0.0], [65632.8, 0.0], [65634.5, 0.002], [65699.2, 0.03], [65712.3, 0.027]]}
{"kind": "depth", "E": 1787080121253, "U": 11315330733531, "u": 11315330739775, "recv_ms": 1787080121193, "bids": [[14312.2, 1.064], [14412.2, 3.136], [14512.2, 0.0], [51770.0, 0.0], [58240.9, 0.002], [61476.5, 0.0], [61476.7, 0.006], [63418.0, 2.695], [63903.3, 7.941], [64065.1, 5.231], [64388.6, 4.445], [64515.6, 0.0], [64515.7, 5.916], [64554.5, 7.165], [64571.5, 2.556], [64571.6, 0.0], [64615.1, 2.344], [64656.9, 0.363], [64689.5, 0.223], [64699.4, 1.258], [64700.2, 0.205], [64700.7, 0.262], [64704.0, 0.592], [64704.2, 0.096], [64704.3, 0.246], [64705.0, 0.004], [64705.4, 0.006], [64707.3, 0.619], [64707.4, 0.578], [64712.2, 7.187]], "asks": [[64712.3, 14.981], [64728.2, 0.002], [64852.8, 9.284], [65295.3, 0.109], [65359.4, 0.022], [65359.5, 0.0], [65632.8, 0.008], [65634.5, 0.01], [65699.2, 0.038], [65805.9, 0.609]]}
{"kind": "depth", "E": 1787080121355, "U": 11315330739849, "u": 11315330746890, "recv_ms": 1787080121296, "bids": [[1000.0, 35.81], [14312.2, 1.428], [14412.2, 2.772], [58240.9, 0.002], [61476.5, 0.0], [61476.6, 0.002], [61476.7, 0.008], [62123.7, 0.692], [63712.2, 7.683], [64065.1, 5.231], [64333.8, 0.491], [64501.1, 0.148], [64601.5, 0.064], [64604.9, 2.32], [64605.9, 0.002], [64645.0, 0.057], [64661.8, 0.01], [64670.7, 0.165], [64684.1, 1.827], [64688.9, 0.072], [64689.2, 0.169], [64689.6, 1.426], [64690.2, 0.557], [64691.0, 0.0], [64691.1, 0.569], [64692.0, 1.626], [64692.6, 0.001], [64700.2, 0.051], [64700.7, 0.416], [64704.1, 0.165], [64709.7, 0.006], [64712.2, 7.19]], "asks": [[64730.4, 0.599], [64731.2, 3.211], [64731.6, 0.003], [64732.0, 0.58], [64734.8, 0.01], [64735.6, 0.001], [64735.7, 0.191], [64736.3, 0.296], [64748.9, 0.035], [64766.3, 0.024], [64811.4, 0.435], [64821.0, 2.32], [64821.9, 0.0], [64915.5, 0.158], [65089.1, 0.247], [65294.9, 0.241], [65359.4, 0.022], [65598.9, 0.609], [65650.6, 26.601], [65712.3, 0.007]]}
{"kind": "depth", "E": 1787080121559, "U": 11315330755553, "u": 11315330761644, "recv_ms": 1787080121498, "bids": [[14312.2, 2.142], [14412.2, 2.058], [51770.0, 0.0], [58240.9, 0.002], [61476.5, 0.0], [62123.7, 0.692], [63712.2, 7.703], [63806.2, 19.546], [63956.9, 3.899], [64065.1, 5.231], [64388.6, 4.435], [64604.9, 2.32], [64668.1, 0.0], [64673.3, 0.068], [64704.1, 0.867], [64704.7, 0.001], [64708.8, 0.003], [64709.4, 0.103], [64710.2, 0.116]], "asks": [[64712.3, 14.952], [64712.6, 0.002], [64720.3, 0.0], [64722.7, 2.849], [64742.1, 0.007], [64742.2, 0.154], [64758.9, 0.042], [64821.0, 2.32], [65359.4, 0.022], [65533.1, 3.453], [65643.1, 0.911], [65712.3, 0.027]]}
{"kind": "depth", "E": 1787080121661, "U": 11315330761745, "u": 11315330766368, "recv_ms": 1787080121601, "bids": [[1000.0, 35.81], [14312.2, 2.506], [14412.2, 1.694], [51770.0, 0.0], [58240.9, 0.002], [61476.5, 0.0], [62123.7, 0.689], [63935.7, 26.01], [64065.1, 5.231], [64571.5, 0.001], [64668.1, 0.028], [64668.5, 0.185], [64704.1, 0.319], [64704.2, 0.096], [64707.3, 0.619], [64707.4, 0.578], [64712.2, 7.174]], "asks": [[64852.8, 3.887], [65359.4, 2.313], [65547.1, 0.307], [65618.3, 17.222]]}
{"kind": "depth", "E": 1787080121763, "U": 11315330766438, "u": 11315330773493, "recv_ms": 1787080121704, "bids": [[1000.0, 35.81], [14312.2, 2.856], [14412.2, 1.344], [51770.0, 0.0], [58240.9, 0.002], [63712.2, 7.683], [63914.9, 7.796], [64065.1, 5.231], [64571.5, 2.786], [64571.6, 1.253], [64582.7, 0.0], [64700.4, 0.156], [64700.7, 0.262], [64704.8, 0.636], [64705.5, 0.115], [64712.2, 7.22]], "asks": [[64755.9, 0.964], [64784.0, 8.204], [64784.8, 0.019], [64852.8, 9.284], [64869.8, 10.418], [64908.6, 15.406], [64908.7, 0.011], [65035.9, 3.998], [65359.4, 2.313], [65712.3, 0.007], [66277.4, 2.423], [67300.7, 0.025]]}
{"kind": "depth", "E": 1787080121865, "U": 11315330773552, "u": 11315330788772, "recv_ms": 1787080121808, "bids": [[14312.2, 3.206], [14412.2, 0.994], [51769.8, 0.0], [58240.9, 0.002], [61476.5, 0.0], [62123.7, 0.692], [63418.0, 2.698], [64065.1, 5.231], [64388.6, 4.436], [64628.0, 0.001], [64642.3, 0.03], [64680.5, 0.002], [64684.8, 0.596], [64704.2, 0.096], [64706.2, 0.007], [64707.4, 0.037], [64707.5, 0.542], [64710.0, 0.01], [64710.6, 0.122], [64712.1, 0.019], [64712.2, 8.298]], "asks": [[64712.4, 0.042], [64712.5, 0.0], [64713.1, 0.001], [64713.6, 0.002], [64714.0, 0.003], [64714.4, 0.024], [64714.7, 0.447], [64715.0, 0.102], [64715.4, 0.188], [64720.0, 0.121], [64720.1, 2.319], [64722.2, 0.084], [64722.5, 1.178], [64723.5, 0.0], [64725.0, 0.004], [64726.9, 0.158], [64727.0, 0.002], [64728.9, 0.164], [64729.1, 0.015], [64730.0, 0.499], [64732.0, 0.024], [64732.4, 0.322], [64733.6, 0.469], [64734.3, 0.01], [64734.5, 0.0], [64735.0, 0.003], [64735.5, 0.0], [64736.3, 0.181], [64736.5, 0.0], [64740.0, 0.486], [64741.6, 10.193], [64742.9, 0.0], [64761.5, 0.09], [64785.5, 0.029], [64789.9, 36.235], [64852.8, 7.81], [64868.5, 1.482], [64869.8, 8.281], [64908.6, 11.435], [65359.4, 2.319], [65618.3, 17.831]]}
{"kind": "depth", "E": 1787080121967, "U": 11315330788804, "u": 11315330800000, "recv_ms": 1787080121908, "bids": [[1000.0, 35.96], [14312.2, 3.57], [14412.2, 0.63], [58240.9, 0.002], [61476.5, 0.0], [62123.7, 0.689], [63961.0, 0.004], [64065.1, 5.231], [64168.6, 0.139], [64388.6, 4.437], [64699.7, 0.262], [64700.1, 0.175], [64700.4, 0.002], [64700.9, 0.002], [64701.9, 0.311], [64702.2, 0.003], [64702.8, 0.0], [64704.0, 0.129], [64704.2, 1.123], [64705.5, 0.113], [64706.0, 0.012], [64706.7, 0.001], [64707.0, 0.013], [64707.4, 0.138], [64707.5, 0.001], [64712.2, 8.297]], "asks": [[64712.3, 14.951], [64712.4, 0.043], [64712.5, 0.002], [64713.6, 0.003], [64714.4, 0.572], [64714.6, 2.503], [64714.7, 0.397], [64715.0, 0.103], [64719.8, 0.002], [64720.0, 0.122], [64720.1, 2.628], [64722.1, 0.008], [64722.2, 0.624], [64723.7, 0.011], [64725.0, 0.005], [64727.2, 1.859], [64727.3, 0.685], [64729.0, 1.062], [64730.0, 0.5], [64731.6, 0.559], [64732.3, 0.062], [64733.0, 0.041], [64733.5, 0.009], [64733.8, 0.155], [64734.8, 0.551], [64735.0, 0.004], [64735.9, 0.115], [64740.0, 0.487], [64740.2, 0.3], [64784.0, 2.878], [64784.8, 0.028], [64785.5, 36.26], [64789.9, 0.004], [64869.8, 6.415], [64908.6, 11.142], [65035.9, 3.997], [65359.4, 2.313], [65427.8, 4.192], [65457.1, 13.631]]}
{"kind": "depth", "E": 1787080122171, "U": 11315330814791, "u": 11315330823976, "recv_ms": 1787080122113, "bids": [[14212.2, 0.308], [14312.2, 3.668], [14412.2, 0.224], [58240.9, 0.002], [61476.5, 0.0], [62123.7, 0.689], [63418.0, 2.701], [63712.2, 7.683], [63725.1, 0.022], [63725.3, 0.038], [63793.3, 2.58], [63914.9, 7.563], [64065.1, 5.233], [64388.6, 4.447], [64626.0, 0.235], [64633.1, 0.028], [64638.3, 32.989], [64640.4, 0.003], [64644.9, 0.004], [64646.3, 2.636], [64674.8, 2.123], [64690.2, 0.001], [64691.0, 0.556], [64692.0, 1.51], [64692.8, 1.589], [64696.2, 0.005], [64703.3, 0.001], [64703.9, 1.181], [64712.2, 8.389]], "asks": [[64712.3, 14.934], [64714.4, 0.572], [64720.0, 0.122], [64721.9, 0.001], [64722.2, 0.624], [64725.1, 0.254], [64725.2, 0.14], [64728.4, 2.49], [64728.7, 0.313], [64731.7, 0.847], [64735.8, 0.715], [64740.7, 0.002], [64741.2, 0.325], [64741.3, 1.426], [64741.4, 0.742], [64744.2, 0.0], [64744.3, 0.002], [64744.4, 0.124], [64745.0, 2.957], [64745.1, 1.01], [64745.2, 0.004], [64747.2, 1.396], [64747.3, 0.061], [64747.4, 0.006], [64869.8, 6.434], [64908.6, 11.204], [65359.4, 2.313], [65457.1, 14.546], [65479.6, 2.382], [65650.6, 26.487], [65699.2, 0.009], [65712.3, 0.007]]}
{"kind": "depth", "E": 1787080122273, "U": 11315330824042, "u": 11315330833103, "recv_ms": 1787080122213, "bids": [[1000.0, 35.81], [14212.2, 0.546], [14312.2, 3.542], [14412.2, 0.112], [51770.0, 0.002], [58240.9, 0.002], [61476.5, 0.0], [61476.6, 0.006], [63418.0, 2.698], [64065.1, 5.231], [64626.0, 0.236], [64638.3, 0.0], [64642.7, 33.135], [64697.1, 0.962], [64703.3, 0.0], [64706.0, 0.01], [64706.7, 0.003], [64707.5, 0.311], [64712.2, 8.388]], "asks": [[64712.3, 14.16], [64713.7, 0.046], [64717.1, 0.101], [64718.7, 0.381], [64718.8, 0.0], [64718.9, 0.001], [64719.0, 0.009], [64728.4, 1.872], [64735.8, 0.097], [64758.6, 0.0], [64765.4, 0.522], [64816.3, 0.607], [64817.8, 1.888], [64869.8, 10.418], [64908.6, 15.406], [65359.4, 2.313], [65417.7, 4.879], [65521.2, 8.011], [65564.7, 0.762], [65647.9, 2.283], [65699.3, 1.34], [66006.5, 0.003]]}
{"kind": "depth", "E": 1787080122375, "U": 11315330833114, "u": 11315330843228, "recv_ms": 1787080122318, "bids": [[14212.2, 0.798], [14312.2, 3.402], [14412.2, 0.0], [51770.0, 0.0], [58240.9, 0.002], [62123.7, 0.692], [63557.2, 0.048], [63947.2, 16.962], [64065.1, 5.231], [64571.5, 0.001], [64638.3, 32.989], [64642.7, 0.146], [64644.9, 0.004], [64691.1, 0.567], [64692.1, 5.002], [64712.2, 8.359]], "asks": [[64725.2, 0.141], [64736.0, 1.604], [64741.6, 10.195], [64741.9, 0.156], [64852.8, 3.887], [65359.4, 2.313], [65630.1, 28.531], [65647.9, 1.522], [65650.6, 26.6], [65906.8, 2.277]]}
{"kind": "depth", "E": 1787080122477, "U": 11315330843691, "u": 11315330859072, "recv_ms": 1787080122418, "bids": [[14212.2, 1.148], [14312.2, 3.052], [58240.9, 0.002], [61476.5, 0.0], [62123.7, 0.689], [63712.2, 7.703], [64065.1, 5.231], [64168.6, 0.074], [64388.6, 4.447], [64571.5, 3.098], [64571.6, 0.0], [64638.3, 0.0], [64642.7, 33.135], [64690.7, 0.716], [64691.0, 0.0], [64696.5, 0.158], [64697.1, 0.962], [64700.1, 0.021], [64700.6, 0.399], [64700.7, 0.262], [64712.2, 8.35]], "asks": [[64713.2, 0.0], [64719.5, 0.021], [64730.9, 0.659], [64731.6, 0.003], [64742.1, 0.161], [64742.2, 0.0], [64852.8, 9.284], [64869.8, 10.418], [64908.6, 15.406], [65359.4, 2.313], [65469.4, 2.365], [65712.3, 0.027], [65744.2, 0.09], [65888.2, 2.721]]}
{"kind": "depth", "E": 1787080122579, "U": 11315330859240, "u": 11315330867399, "recv_ms": 1787080122521, "bids": [[1000.0, 35.81], [14212.2, 1.498], [14312.2, 2.702], [51770.0, 0.0], [58240.9, 0.002], [61476.5, 0.0], [62123.7, 0.692], [64065.1, 5.231], [64138.8, 0.0], [64690.0, 0.865], [64690.7, 0.16], [64691.8, 0.117], [64692.8, 1.473], [64694.8, 0.476], [64696.0, 0.097], [64696.3, 0.241], [64697.1, 0.96], [64698.0, 1.024], [64700.5, 0.004], [64700.6, 0.245], [64702.2, 0.544], [64703.9, 0.563], [64704.1, 0.311], [64704.2, 0.003], [64704.3, 0.246], [64704.4, 0.222], [64705.0, 0.004], [64705.1, 0.134], [64705.6, 0.02], [64706.7, 0.001], [64708.5, 0.089], [64710.6, 0.124], [64712.1, 0.017], [64712.2, 7.329]], "asks": [[64713.7, 0.13], [64714.0, 0.013], [64719.5, 0.043], [64721.3, 0.004], [64727.7, 0.946], [64729.0, 0.137], [64734.7, 0.339], [64735.9, 0.0], [64742.1, 0.007], [64742.2, 0.154], [65359.4, 2.313], [66000.0, 99.507]]}
{"kind": "depth", "E": 1787080122681, "U": 11315330867518, "u": 11315330874890, "recv_ms": 1787080122623, "bids": [[14212.2, 1.862], [14312.2, 2.338], [58240.9, 0.002], [63712.2, 7.683], [63806.2, 19.734], [63945.2, 0.002], [64065.1, 5.231], [64582.7, 0.0], [64642.7, 0.146], [64644.9, 32.993], [64694.8, 0.476], [64697.0, 0.917], [64700.4, 0.156], [64702.2, 0.08], [64704.0, 0.129], [64704.2, 0.003], [64704.3, 0.246], [64704.4, 0.214], [64705.0, 0.561], [64705.1, 0.042], [64706.2, 0.004], [64707.6, 0.009], [64708.5, 0.089], [64712.2, 7.267]], "asks": [[64725.2, 0.141], [64727.7, 0.021], [64728.3, 1.177], [64869.8, 10.418], [65359.4, 2.313], [65488.8, 31.097], [65521.2, 8.353], [65630.1, 28.348], [65712.3, 0.007], [71183.6, 0.0]]}
{"kind": "depth", "E": 1787080122783, "U": 11315330875017, "u": 11315330881764, "recv_ms": 1787080122728, "bids": [[14212.2, 2.226], [14312.2, 1.974], [58240.9, 0.002], [62123.7, 0.689], [63887.2, 0.0], [64065.1, 5.231], [64125.8, 0.287], [64388.6, 4.437], [64571.6, 1.3], [64694.8, 0.005], [64699.8, 0.156], [64700.4, 0.002], [64702.2, 0.003], [64704.0, 0.716], [64704.2, 0.544], [64705.0, 0.004], [64705.1, 0.042], [64707.6, 0.002], [64708.5, 0.073]], "asks": [[64725.2, 0.141], [64728.7, 0.418], [64734.7, 0.224], [64735.6, 0.116], [64739.2, 5.106], [64781.3, 6.463], [65359.4, 2.313]]}
{"kind": "depth", "E": 1787080122885, "U": 11315330881894, "u": 11315330889341, "recv_ms": 1787080122825, "bids": [[1000.0, 35.81], [14212.2, 2.59], [14312.2, 1.61], [51769.8, 0.0], [58240.9, 0.002], [61476.5, 0.0], [62123.7, 0.692], [63623.6, 8.344], [63712.2, 7.703], [63923.9, 0.783], [63942.1, 9.383], [64065.1, 5.231], [64388.6, 4.436], [64521.2, 2.772], [64571.5, 2.065], [64585.8, 0.001], [64666.9, 0.54], [64692.1, 0.002], [64694.8, 0.005], [64695.0, 0.004], [64702.2, 0.551], [64704.0, 0.709], [64704.2, 0.003], [64705.0, 0.004], [64705.1, 0.042], [64707.6, 0.002], [64708.5, 0.073], [64712.2, 7.315]], "asks": [[64760.8, 0.001], [64852.8, 7.396], [64869.8, 5.701], [64908.6, 9.982], [65035.9, 3.998], [65359.4, 2.313], [65554.1, 0.076], [65712.3, 0.027], [65825.4, 0.758]]}
{"kind": "depth", "E": 1787080122987, "U": 11315330889420, "u": 11315330894725, "recv_ms": 1787080122928, "bids": [[14212.2, 2.94], [14312.2, 1.26], [58240.9, 0.002], [61476.5, 0.001], [62123.7, 0.689], [63870.9, 9.305], [64065.1, 5.231], [64388.6, 4.435], [64390.3, 0.229], [64694.8, 0.476], [64702.2, 0.103], [64704.0, 0.129], [64704.2, 0.003], [64704.4, 0.214], [64705.0, 0.004], [64705.1, 0.042], [64707.6, 0.543], [64708.5, 0.089], [64712.2, 7.316]], "asks": [[64714.0, 0.003], [64725.2, 0.141], [64742.2, 0.0], [64742.3, 0.617], [64869.8, 10.418], [64908.6, 15.406], [65035.9, 3.999], [65359.4, 2.313], [65805.9, 1.368], [65880.3, 0.765]]}
{"kind": "depth", "E": 1787080123089, "U": 11315330894774, "u": 11315330901945, "recv_ms": 1787080123032, "bids": [[14212.2, 3.29], [14312.2, 0.91], [58240.9, 0.002], [61476.5, 0.0], [62123.7, 0.692], [63712.2, 7.683], [63850.1, 15.132], [64065.1, 5.231], [64388.6, 4.435], [64626.0, 0.235], [64694.8, 0.005], [64700.6, 0.245], [64702.2, 0.003], [64704.0, 0.129], [64704.2, 0.551], [64704.4, 0.677], [64705.0, 0.097], [64707.6, 0.002], [64708.5, 0.089], [64712.2, 7.288]], "asks": [[64728.3, 0.252], [64729.2, 1.041], [64869.8, 6.367], [65359.4, 2.315], [65505.5, 4.802], [65712.3, 0.007], [65825.4, 1.364]]}
{"kind": "depth", "E": 1787080123191, "U": 11315330902000, "u": 11315330911486, "recv_ms": 1787080123132, "bids": [[1000.0, 35.81], [14212.2, 3.654], [14312.2, 0.546], [58240.9, 0.002], [61476.5, 0.0], [63418.0, 2.695], [64065.1, 5.231], [64626.0, 0.234], [64633.1, 0.029], [64644.8, 1.164], [64659.2, 0.034], [64666.0, 3.261], [64670.7, 0.169], [64690.0, 0.309], [64691.3, 0.577], [64691.8, 0.001], [64693.0, 0.118], [64694.3, 0.007], [64694.8, 0.005], [64695.9, 0.764], [64696.2, 0.005], [64697.0, 0.017], [64698.0, 1.924], [64703.3, 0.618], [64704.0, 0.6], [64704.1, 0.157], [64704.2, 0.551], [64704.4, 0.214], [64704.5, 0.0], [64704.9, 0.457], [64705.0, 0.115], [64705.6, 0.018], [64707.3, 0.465], [64707.6, 0.002], [64708.5, 0.073], [64712.2, 7.317]], "asks": [[64712.3, 14.177], [64714.0, 0.013], [64721.5, 0.013], [64727.8, 0.643], [64728.7, 0.418], [64730.9, 0.103], [64731.6, 0.559], [64735.2, 0.621], [65359.4, 2.313], [65427.8, 3.506], [65457.1, 13.63], [65485.5, 0.019]]}
{"kind": "depth", "E": 1787080123293, "U": 11315330911811, "u": 11315330921031, "recv_ms": 1787080123235, "bids": [[14212.2, 3.752], [14312.2, 0.322], [14612.2, 0.126], [51770.0, 0.0], [58240.9, 0.002], [61476.5, 0.0], [62123.7, 0.689], [63418.0, 2.701], [63712.2, 7.703], [63770.8, 6.028], [63838.6, 4.234], [63947.2, 16.743], [64065.1, 5.231], [64571.5, 3.091], [64571.6, 0.0], [64595.1, 0.023], [64595.2, 1.105], [64596.4, 3.863], [64604.9, 0.002], [64605.1, 2.318], [64641.0, 0.323], [64666.9, 0.54], [64668.5, 0.339], [64673.3, 0.082], [64679.8, 1.886], [64681.4, 0.784], [64684.8, 0.26], [64690.6, 0.66], [64691.3, 0.021], [64692.4, 0.138], [64693.0, 0.002], [64694.8, 0.476], [64698.0, 1.024], [64701.5, 0.37], [64701.9, 0.002], [64702.2, 0.637], [64703.3, 0.0], [64704.0, 0.129], [64704.1, 0.311], [64704.2, 0.003], [64704.9, 0.435], [64705.0, 0.006], [64705.7, 0.241], [64707.0, 0.036], [64707.5, 0.001], [64707.9, 0.378], [64708.4, 0.201], [64708.5, 0.073], [64709.5, 0.004], [64710.2, 0.032], [64710.6, 0.038], [64711.0, 0.0], [64712.2, 7.227]], "asks": [[64712.3, 14.262], [64713.0, 0.084], [64713.8, 0.005], [64717.1, 0.017], [64719.8, 0.001], [64722.2, 0.623], [64737.1, 10.326], [64741.6, 0.195], [64757.6, 0.003], [64758.9, 0.0], [64761.5, 0.076], [64777.1, 0.002], [64782.2, 0.0], [64783.5, 0.048], [64820.9, 2.319], [64821.0, 0.002], [64847.8, 4.811], [64852.8, 9.284], [64869.8, 10.418], [64912.2, 0.015], [64912.3, 0.591], [65359.4, 2.313], [65457.1, 13.639], [65521.2, 8.695], [65631.2, 1.591], [65669.0, 0.182], [65712.3, 0.027], [65799.5, 0.606], [65877.1, 0.969]]}
{"kind": "depth", "E": 1787080123395, "U": 11315330921057, "u": 11315330927771, "recv_ms": 1787080123335, "bids": [[1000.0, 35.81], [14212.2, 3.64], [14312.2, 0.196], [14612.2, 0.364], [51770.0, 0.0], [58240.9, 0.002], [61476.5, 0.0], [62123.7, 0.692], [63760.9, 2.976], [64011.9, 0.0], [64065.1, 5.231], [64388.6, 4.435], [64518.1, 0.001], [64694.8, 0.005], [64697.0, 0.017], [64698.0, 1.924], [64702.2, 0.003], [64704.0, 1.257], [64704.9, 0.226], [64707.0, 0.013], [64712.2, 7.165]], "asks": [[64713.8, 0.002], [64739.2, 3.451], [64741.6, 0.195], [64742.2, 0.0], [64742.3, 0.617], [64869.8, 10.418], [64908.6, 15.406], [65359.4, 2.313], [65417.7, 5.565], [65457.1, 12.724], [65488.8, 32.622], [65635.0, 5.327]]}
{"kind": "depth", "E": 1787080123497, "U": 11315330927882, "u": 11315330933957, "recv_ms": 1787080123437, "bids": [[1000.0, 35.81], [14212.2, 3.5], [14312.2, 0.084], [14612.2, 0.616], [58240.9, 0.002], [61476.5, 0.0], [62123.7, 0.689], [63288.5, 0.003], [63712.2, 7.683], [63903.3, 8.525], [64065.1, 5.231], [64168.6, 0.218], [64571.5, 3.071], [64605.1, 2.318], [64712.2, 7.165]], "asks": [[64712.3, 14.261], [64713.2, 0.002], [64725.2, 0.14], [64732.0, 5.024], [64742.3, 0.463], [64742.4, 0.163], [64820.9, 2.319], [64852.8, 9.284], [65359.4, 2.313], [65457.1, 11.826], [65482.4, 9.162], [65505.5, 3.277], [65657.1, 5.214], [65712.3, 0.007], [65799.5, 1.212], [65932.0, 0.0]]}
{"kind": "depth", "E": 1787080123599, "U": 11315330934009, "u": 11315330940427, "recv_ms": 1787080123539, "bids": [[14212.2, 3.318], [14312.2, 0.0], [14612.2, 0.882], [58240.9, 0.002], [61476.5, 0.0], [63288.5, 0.0], [64000.4, 1.885], [64065.1, 5.231], [64194.5, 7.634], [64663.6, 2.132], [64670.7, 0.165], [64679.8, 0.002], [64695.5, 0.001], [64696.8, 0.926], [64705.0, 0.004], [64706.0, 0.012], [64708.2, 0.217], [64708.5, 0.072], [64709.5, 0.002], [64709.7, 0.09], [64712.1, 0.019], [64712.2, 8.247]], "asks": [[64712.3, 14.26], [64719.8, 0.002], [64721.5, 0.012], [64725.2, 0.14], [64727.8, 0.025], [64734.8, 0.01], [64735.2, 0.003], [64735.9, 0.541], [64742.1, 0.161], [64742.4, 0.009], [64852.8, 7.793], [64869.8, 10.418], [64908.6, 15.406], [65359.4, 2.313], [65486.0, 1.554], [65618.3, 20.114]]}
{"kind": "depth", "E": 1787080123701, "U": 11315330940631, "u": 11315330945764, "recv_ms": 1787080123641, "bids": [[1000.0, 35.81], [14212.2, 2.968], [14612.2, 1.232], [58240.9, 0.002], [61476.5, 0.0], [62123.7, 0.692], [63712.2, 7.703], [63956.1, 0.782], [64065.1, 5.231], [64388.6, 4.445], [64582.7, 0.0], [64668.5, 0.185], [64689.7, 0.171], [64695.8, 0.93], [64696.8, 0.001], [64712.2, 8.249]], "asks": [[64712.3, 14.176], [64725.2, 0.141], [64741.2, 0.327], [64741.3, 1.428], [64741.4, 0.744], [64742.1, 0.161], [64742.2, 0.0], [64744.2, 0.002], [64744.3, 0.004], [64744.4, 0.126], [64745.0, 2.959], [64745.1, 1.012], [64745.2, 0.006], [64747.2, 1.398], [64747.3, 0.063], [64747.4, 0.008], [65359.4, 2.313], [65457.1, 13.657], [65488.8, 34.147], [65712.3, 0.027]]}
{"kind": "depth", "E": 1787080123803, "U": 11315330945943, "u": 11315330951700, "recv_ms": 1787080123744, "bids": [[1000.0, 35.81], [14212.2, 2.604], [14612.2, 1.596], [51770.0, 0.0], [58240.9, 0.002], [61476.5, 0.0], [62123.7, 0.689], [63822.5, 3.911], [63914.9, 7.33], [63935.7, 25.308], [63952.0, 4.73], [64065.1, 5.231], [64194.5, 8.568], [64571.6, 1.296], [64620.9, 0.003], [64621.0, 0.127], [64646.3, 7.675], [64707.0, 0.323], [64707.3, 0.619], [64710.5, 0.089], [64712.2, 8.246]], "asks": [[64712.3, 14.175], [64713.0, 0.0], [64725.2, 0.14], [64734.1, 0.003], [64734.8, 0.551], [64735.9, 0.0], [64736.0, 2.894], [64777.1, 0.02], [64778.6, 2.286], [64869.8, 6.282], [64908.6, 11.361], [64912.1, 0.004], [64912.2, 0.012], [65359.4, 2.313], [65457.1, 14.571], [65697.5, 0.266]]}
{"kind": "depth", "E": 1787080123905, "U": 11315330951853, "u": 11315330957987, "recv_ms": 1787080123846, "bids": [[14212.2, 2.254], [14612.2, 1.946], [51769.8, 0.0], [58240.9, 0.0], [61476.5, 0.0], [62123.7, 0.692], [63623.6, 7.953], [63712.2, 7.683], [63806.2, 22.081], [64065.1, 5.231], [64388.6, 4.446], [64515.7, 0.718], [64516.1, 0.004], [64518.1, 0.361], [64554.5, 5.439], [64571.5, 1.425], [64686.4, 1.379], [64696.0, 0.098], [64712.2, 8.245]], "asks": [[64724.3, 0.069], [64742.1, 0.161], [64868.5, 2.11], [64869.8, 10.418], [64908.6, 15.406], [65035.9, 3.998], [65359.4, 2.313], [65457.1, 13.664], [65518.4, 3.048], [65533.1, 3.225], [65630.8, 0.761], [65712.3, 0.007], [66006.5, 0.006], [67300.7, 0.012]]}
{"kind": "depth", "E": 1787080124109, "U": 11315330963541, "u": 11315330969076, "recv_ms": 1787080124049, "bids": [[1000.0, 35.81], [14212.2, 1.54], [14612.2, 2.66], [51770.0, 0.0], [58240.9, 0.002], [61476.5, 0.0], [61476.6, 0.006], [61476.7, 0.01], [63612.1, 5.728], [63712.2, 7.703], [63725.3, 0.029], [63935.7, 27.572], [64065.1, 5.231], [64388.6, 4.447], [64626.0, 0.235], [64700.6, 0.245], [64705.7, 0.157], [64706.0, 0.01], [64706.7, 0.003], [64710.4, 0.093], [64710.5, 0.005], [64710.8, 0.084], [64712.2, 8.246]], "asks": [[64713.0, 0.0], [64713.2, 0.0], [64725.2, 0.141], [64852.8, 9.284], [64869.8, 10.418], [64908.6, 15.406], [65359.4, 2.313], [65618.3, 20.297], [65629.3, 0.762], [65686.9, 0.268], [65699.3, 1.331], [65712.3, 0.027]]}
{"kind": "depth", "E": 1787080124211, "U": 11315330969186, "u": 11315330975756, "recv_ms": 1787080124151, "bids": [[14212.2, 1.176], [14612.2, 3.024], [51770.0, 0.0], [58240.9, 0.002], [61476.5, 0.0], [61476.7, 0.008], [62123.7, 0.692], [63418.0, 2.698], [63725.3, 0.038], [63757.8, 0.003], [63935.7, 27.791], [64065.1, 5.231], [64571.5, 2.578], [64626.0, 0.236], [64696.0, 0.098], [64696.2, 0.005], [64703.8, 1.937], [64705.3, 0.002]], "asks": [[64712.3, 14.174], [64721.9, 0.002], [64728.3, 0.87], [64728.7, 0.418], [64735.7, 0.809], [64775.4, 0.0], [64782.0, 0.011], [64852.8, 7.741], [64868.5, 1.482], [64869.8, 5.49], [64908.6, 11.081], [65359.4, 2.315], [65457.1, 14.579], [65727.4, 1.302], [65889.6, 0.758]]}
{"kind": "depth", "E": 1787080124313, "U": 11315330975814, "u": 11315330980692, "recv_ms": 1787080124254, "bids": [[1000.0, 35.81], [14212.2, 0.826], [14612.2, 3.374], [51770.0, 0.0], [58240.9, 0.002], [62123.7, 0.689], [63418.0, 2.701], [63712.2, 7.683], [64065.1, 5.231], [64388.6, 4.447], [64582.7, 0.003], [64679.8, 0.005], [64712.2, 8.245]], "asks": [[64725.2, 0.14], [64822.4, 0.017], [64852.8, 9.284], [64869.8, 10.418], [64908.6, 15.406], [65359.4, 2.313], [65699.3, 1.34], [65712.3, 0.007], [65812.4, 4.863]]}
{"kind": "depth", "E": 1787080124415, "U": 11315330980929, "u": 11315330988944, "recv_ms": 1787080124356, "bids": [[1000.0, 35.81], [14212.2, 0.476], [14512.2, 0.014], [14612.2, 3.71], [58240.9, 0.002], [61476.5, 0.0], [62123.7, 0.692], [63418.0, 2.698], [64065.1, 5.231], [64670.7, 0.179], [64690.1, 1.384], [64690.6, 0.104], [64694.8, 0.476], [64695.9, 0.146], [64697.0, 0.917], [64698.0, 1.024], [64699.8, 0.002], [64700.8, 1.192], [64701.1, 1.237], [64702.2, 0.003], [64702.9, 0.004], [64703.8, 1.319], [64704.0, 0.245], [64704.2, 0.544], [64704.7, 0.003], [64705.3, 0.002], [64706.7, 0.001], [64707.0, 0.013], [64710.1, 0.085], [64710.3, 0.003], [64710.4, 0.009], [64710.8, 0.0], [64712.1, 0.017], [64712.2, 7.195]], "asks": [[64712.3, 14.175], [64712.8, 0.0], [64719.8, 0.001], [64725.2, 0.14], [64727.9, 0.926], [64728.3, 0.252], [64729.2, 0.116], [64730.4, 1.155], [64731.6, 0.003], [64742.2, 0.0], [64742.3, 0.617], [64869.8, 10.418], [64908.6, 15.406], [65233.0, 200.271], [65359.4, 2.313], [65618.3, 20.48], [66682.7, 1.29]]}
{"kind": "depth", "E": 1787080124517, "U": 11315330989090, "u": 11315330995698, "recv_ms": 1787080124460, "bids": [[14212.2, 0.294], [14512.2, 0.196], [14612.2, 3.71], [58240.9, 0.002], [61476.5, 0.0], [62123.7, 0.689], [63712.2, 7.703], [64065.1, 5.231], [64646.3, 7.677], [64648.0, 4.149], [64666.9, 0.537], [64677.1, 0.336], [64679.8, 0.002], [64681.4, 0.448], [64694.8, 0.005], [64702.2, 0.003], [64702.5, 0.155], [64703.8, 1.319], [64704.0, 1.241], [64704.1, 0.173], [64704.2, 0.003], [64704.4, 0.214], [64704.5, 0.0], [64704.7, 0.001], [64704.8, 0.638], [64705.0, 0.004], [64705.7, 0.241], [64707.0, 0.013], [64707.3, 0.619], [64707.8, 0.15], [64708.0, 0.077], [64708.5, 0.072], [64708.8, 0.087], [64709.3, 0.194], [64709.4, 0.102], [64709.7, 0.006], [64710.1, 0.001], [64710.3, 0.001], [64711.3, 0.023], [64711.4, 0.021], [64711.8, 0.0], [64711.9, 0.0], [64712.2, 6.998]], "asks": [[64712.3, 14.261], [64712.8, 0.084], [64714.1, 0.084], [64723.0, 0.973], [64725.2, 0.141], [64727.9, 0.001], [64728.6, 1.73], [64730.4, 0.599], [64731.0, 0.635], [64732.3, 0.06], [64732.8, 12.288], [64735.7, 0.191], [64736.0, 1.604], [64737.1, 0.328], [64737.2, 2.46], [64775.4, 0.004], [64782.0, 0.007], [64822.4, 0.014], [64852.8, 8.206], [64869.8, 10.418], [64908.6, 15.406], [65230.0, 8.795], [65359.4, 2.313], [65363.1, 1.024], [65712.3, 0.027], [65812.4, 5.622]]}
{"kind": "depth", "E": 1787080124619, "U": 11315330995703, "u": 11315331000315, "recv_ms": 1787080124560, "bids": [[1000.0, 35.81], [14212.2, 0.168], [14512.2, 0.42], [14612.2, 3.612], [58240.9, 0.002], [61476.5, 0.0], [63612.1, 6.121], [64065.1, 5.231], [64388.6, 4.437], [64620.8, 1.245], [64620.9, 0.0], [64679.8, 0.005], [64694.8, 0.468], [64700.8, 1.038], [64702.2, 0.003], [64704.0, 0.77], [64704.1, 0.181], [64709.2, 0.103], [64712.2, 6.997]], "asks": [[64712.3, 14.26], [64713.2, 0.002], [64719.2, 0.027], [64719.3, 0.336], [64725.2, 0.14], [64736.0, 1.603], [64757.6, 0.003], [64912.0, 1.607], [64912.1, 0.001], [65359.4, 2.313]]}
{"kind": "depth", "E": 1787080124721, "U": 11315331000414, "u": 11315331006256, "recv_ms": 1787080124661, "bids": [[1000.0, 35.81], [14212.2, 0.056], [14512.2, 0.658], [14612.2, 3.486], [58240.9, 0.002], [61476.5, 0.0], [62123.7, 0.692], [63418.0, 2.701], [63712.2, 7.683], [64065.1, 5.231], [64554.5, 7.48], [64571.5, 3.071], [64582.7, 0.003], [64596.4, 0.0], [64641.0, 0.323], [64700.1, 0.175], [64700.6, 0.245], [64700.7, 0.262], [64702.2, 0.003], [64704.1, 0.173], [64712.2, 6.963]], "asks": [[64712.3, 14.258], [64725.2, 0.141], [64728.6, 0.805], [64729.4, 3.686], [64731.0, 0.079], [64731.8, 0.558], [64732.8, 2.288], [64734.3, 0.551], [64734.8, 0.01], [64735.6, 0.001], [64735.9, 0.0], [64736.2, 0.116], [64783.5, 0.002], [64847.8, 0.948], [64852.8, 8.17], [64869.8, 10.418], [64908.6, 15.406], [64980.8, 2.099], [65353.0, 1.193], [65359.4, 2.313], [65712.3, 0.007]]}
{"kind": "depth", "E": 1787080124823, "U": 11315331006257, "u": 11315331012057, "recv_ms": 1787080124764, "bids": [[14212.2, 0.0], [14512.2, 0.952], [14612.2, 3.248], [58240.9, 0.002], [62123.7, 0.689], [64065.1, 5.231], [64388.6, 4.436], [64595.5, 3.863], [64642.9, 3.285], [64697.1, 0.962], [64702.2, 0.011], [64712.2, 7.006]], "asks": [[64733.3, 2.656], [64736.0, 11.603], [64783.5, 0.048], [64847.8, 4.811], [64869.8, 6.278], [64908.6, 11.352], [65359.4, 2.313]]}
{"kind": "depth", "E": 1787080124925, "U": 11315331012344, "u": 11315331017643, "recv_ms": 1787080124866, "bids": [[1000.0, 35.81], [14512.2, 1.316], [14612.2, 2.884], [51769.8, 0.0], [58240.9, 0.002], [61476.5, 0.0], [62123.7, 0.692], [63712.2, 7.703], [64065.1, 5.231], [64666.9, 0.54], [64681.3, 0.346], [64688.2, 0.168], [64694.8, 0.005], [64697.1, 0.962], [64700.1, 0.021], [64700.9, 0.156], [64702.2, 0.003], [64704.0, 0.229], [64704.1, 1.185], [64706.5, 0.028], [64710.3, 0.085], [64712.2, 7.054]], "asks": [[64712.3, 14.174], [64712.8, 0.0], [64822.4, 0.017], [64869.8, 10.418], [64908.6, 15.406], [65035.9, 3.998], [65103.0, 0.031], [65359.4, 2.313], [65453.0, 0.028], [65712.3, 0.027]]}
{"kind": "depth", "E": 1787080125027, "U": 11315331017673, "u": 11315331027239, "recv_ms": 1787080124971, "bids": [[1000.0, 35.81], [14512.2, 1.68], [14612.2, 2.52], [58240.9, 0.002], [63935.7, 28.01], [64065.1, 5.231], [64388.6, 4.435], [64636.1, 33.014], [64637.1, 0.009], [64644.9, 0.004], [64646.3, 2.638], [64655.2, 0.014], [64668.1, 0.042], [64677.1, 0.0], [64679.7, 0.0], [64680.0, 3.041], [64681.5, 0.122], [64682.6, 0.0], [64684.3, 0.001], [64685.0, 0.01], [64688.0, 0.18], [64690.0, 0.306], [64690.1, 0.828], [64692.4, 0.022], [64692.7, 0.038], [64694.3, 0.0], [64694.5, 0.018], [64694.8, 0.013], [64695.0, 0.001], [64695.8, 0.005], [64697.1, 0.96], [64697.5, 0.002], [64700.0, 0.534], [64700.6, 0.399], [64700.9, 0.002], [64701.5, 0.061], [64702.2, 0.035], [64703.9, 0.022], [64704.0, 0.129], [64704.1, 0.157], [64704.2, 0.003], [64704.8, 0.636], [64705.0, 0.001], [64705.1, 0.04], [64705.7, 0.157], [64707.8, 0.141], [64709.6, 0.118], [64710.0, 0.091], [64710.3, 0.001], [64712.1, 0.016], [64712.2, 7.099]], "asks": [[64712.9, 0.084], [64714.4, 0.565], [64715.8, 0.011], [64721.9, 0.001], [64734.3, 0.01], [64735.9, 0.541], [64852.8, 7.791], [64869.8, 3.99], [64887.1, 0.135], [64908.6, 7.589], [65179.6, 0.001], [65359.4, 2.313]]}
{"kind": "depth", "E": 1787080125129, "U": 11315331027367, "u": 11315331034783, "recv_ms": 1787080125070, "bids": [[14512.2, 2.044], [14612.2, 2.156], [51770.0, 0.0], [58240.9, 0.002], [61476.5, 0.0], [62123.7, 0.689], [63712.2, 7.683], [63882.5, 2.506], [64008.1, 0.0], [64065.1, 5.231], [64388.6, 4.445], [64633.1, 0.025], [64640.4, 0.001], [64655.2, 0.0], [64663.6, 2.128], [64668.1, 0.028], [64669.8, 0.062], [64670.7, 0.183], [64674.8, 0.238], [64680.0, 3.044], [64680.7, 0.217], [64681.6, 1.158], [64682.1, 0.02], [64684.9, 0.32], [64685.0, 0.013], [64688.1, 0.251], [64690.0, 0.309], [64691.5, 0.56], [64693.2, 0.126], [64694.6, 0.164], [64694.7, 1.703], [64694.8, 0.005], [64695.0, 0.004], [64696.8, 0.926], [64696.9, 0.312], [64698.0, 1.924], [64700.0, 0.537], [64700.5, 0.158], [64700.6, 0.245], [64701.7, 0.839], [64702.2, 0.644], [64702.3, 0.472], [64702.5, 0.001], [64703.7, 0.995], [64704.7, 0.001], [64704.8, 0.636], [64704.9, 0.767], [64705.0, 0.004], [64705.2, 0.014], [64705.6, 0.02], [64706.0, 0.01], [64706.1, 0.442], [64707.0, 0.013], [64707.2, 0.402], [64707.4, 0.138], [64708.2, 0.224], [64708.5, 0.088], [64709.5, 0.004], [64710.0, 0.094], [64710.7, 0.097], [64711.7, 0.095], [64712.1, 0.017], [64712.2, 7.041]], "asks": [[64712.6, 0.012], [64712.9, 0.0], [64713.3, 0.084], [64721.8, 0.005], [64739.8, 0.001], [64742.3, 0.463], [64742.4, 0.163], [64812.0, 0.156], [64852.8, 8.205], [64869.8, 6.338], [64908.6, 11.525], [64980.8, 5.065], [65035.9, 3.999], [65359.4, 2.313], [65712.3, 0.007], [71183.6, 0.0]]}
{"kind": "depth", "E": 1787080125231, "U": 11315331034833, "u": 11315331039273, "recv_ms": 1787080125172, "bids": [[1000.0, 35.81], [14512.2, 2.394], [14612.2, 1.806], [58240.9, 0.002], [62123.7, 0.692], [64065.1, 5.231], [64633.1, 0.023], [64691.0, 0.556], [64691.5, 0.004], [64696.2, 0.005], [64700.0, 0.691], [64700.5, 0.004], [64702.2, 0.096], [64702.4, 0.005], [64702.5, 0.06], [64704.8, 0.638], [64705.6, 0.018], [64706.2, 0.198], [64707.3, 0.619], [64707.4, 0.702], [64708.5, 0.072]], "asks": [[64713.2, 0.0], [64728.7, 0.418], [64869.8, 10.418], [64908.6, 15.406], [65169.3, 0.231], [65359.4, 2.313]]}
{"kind": "depth", "E": 1787080125435, "U": 11315331044662, "u": 11315331049365, "recv_ms": 1787080125379, "bids": [[14512.2, 3.108], [14612.2, 1.092], [58240.9, 0.002], [61476.5, 0.0], [62123.7, 0.692], [63882.4, 2.188], [63998.4, 0.874], [64065.1, 5.231], [64388.6, 4.435], [64571.5, 2.578], [64636.1, 0.0], [64637.1, 0.0], [64642.7, 33.135], [64644.8, 1.182], [64673.3, 0.068], [64679.4, 0.066], [64680.7, 0.16], [64690.1, 0.56], [64691.0, 1.393], [64692.0, 1.626], [64693.1, 0.188], [64693.2, 0.01], [64695.5, 0.926], [64696.8, 0.001], [64702.4, 0.005], [64702.5, 0.001], [64704.0, 0.67], [64704.1, 0.705], [64704.2, 0.019], [64704.8, 0.638], [64704.9, 0.226], [64706.0, 0.01], [64706.4, 0.091], [64706.5, 0.025], [64707.4, 0.138], [64707.5, 0.001], [64708.2, 0.418], [64708.5, 0.266], [64711.1, 0.084], [64712.2, 6.964]], "asks": [[64712.3, 14.174], [64713.3, 0.0], [64713.7, 0.046], [64717.1, 0.101], [64719.8, 0.001], [64728.0, 0.128], [64728.9, 1.089], [64729.4, 2.761], [64730.4, 0.599], [64731.6, 0.559], [64731.8, 0.002], [64734.1, 0.003], [64734.8, 0.551], [64735.7, 0.306], [64735.9, 0.0], [64736.2, 0.001], [64761.5, 0.118], [64852.8, 9.284], [65359.4, 2.313]]}
{"kind": "depth", "E": 1787080125537, "U": 11315331049429, "u": 11315331054503, "recv_ms": 1787080125477, "bids": [[1000.0, 35.81], [14512.2, 3.472], [14612.2, 0.728], [58240.9, 0.002], [61476.5, 0.0], [61476.6, 0.004], [61476.7, 0.01], [63418.0, 2.698], [63712.2, 7.683], [63903.3, 8.991], [64065.1, 5.231], [64255.2, 0.233], [64657.4, 0.0], [64670.7, 0.165], [64670.8, 0.006], [64697.0, 0.017], [64700.0, 0.537], [64700.2, 0.205], [64703.6, 0.002], [64704.1, 0.764], [64704.8, 0.636], [64705.6, 0.02], [64707.4, 0.138], [64708.2, 0.224], [64712.2, 7.086]], "asks": [[64712.3, 14.174], [64728.1, 0.503], [64741.2, 0.325], [64741.3, 1.426], [64741.4, 0.742], [64744.2, 0.0], [64744.3, 0.002], [64744.4, 0.124], [64745.0, 2.957], [64745.1, 1.01], [64745.2, 0.004], [64747.2, 1.396], [64747.3, 0.061], [64747.4, 0.006], [64775.4, 0.0], [64776.3, 0.012], [64787.2, 1.214], [64869.8, 10.418], [64908.6, 15.406], [65359.4, 2.313], [65712.3, 0.007], [66006.5, 0.006]]}
{"kind": "depth", "E": 1787080125639, "U": 11315331054553, "u": 11315331063159, "recv_ms": 1787080125579, "bids": [[1000.0, 35.81], [14412.2, 0.042], [14512.2, 3.738], [14612.2, 0.42], [51770.0, 0.0], [58240.9, 0.002], [61476.5, 0.0], [62123.7, 0.689], [63429.4, 0.945], [63501.3, 0.001], [63573.3, 0.785], [63645.2, 0.0], [63712.2, 7.703], [63717.1, 0.0], [63789.0, 1.836], [63825.1, 0.0], [63860.9, 0.0], [63914.9, 7.096], [63932.8, 3.124], [64004.7, 0.01], [64065.1, 5.231], [64076.7, 1.034], [64642.7, 0.146], [64655.4, 0.138], [64706.2, 0.001], [64706.4, 0.004], [64707.4, 0.332], [64707.9, 0.381], [64708.5, 0.072], [64711.5, 0.087], [64712.2, 6.993]], "asks": [[64712.3, 14.173], [64719.8, 0.002], [64723.0, 0.073], [64800.6, 0.0], [64869.8, 6.338], [64908.6, 11.525], [65359.4, 2.313], [65371.1, 0.016], [65443.1, 0.776], [65499.9, 1.747], [65515.0, 0.001], [65521.2, 8.923], [65586.9, 0.001], [65635.0, 0.762], [65658.8, 0.0], [65712.3, 0.027], [65730.7, 0.014], [65802.6, 0.609], [65874.5, 0.002], [65946.5, 0.0], [66018.4, 0.01]]}
{"kind": "depth", "E": 1787080125741, "U": 11315331063211, "u": 11315331070281, "recv_ms": 1787080125683, "bids": [[14412.2, 0.238], [14512.2, 3.696], [14612.2, 0.266], [58240.9, 0.002], [61476.5, 0.0], [62123.7, 0.692], [63741.5, 8.278], [63822.5, 0.0], [63825.6, 1.875], [63870.9, 10.712], [64065.1, 5.231], [64388.6, 4.445], [64582.7, 0.003], [64637.1, 0.0], [64640.5, 0.0], [64642.7, 33.135], [64644.9, 0.004], [64692.0, 1.51], [64692.6, 0.117], [64693.7, 0.001], [64695.5, 0.001], [64696.2, 1.548], [64697.2, 0.003], [64698.0, 1.024], [64703.0, 0.003], [64703.1, 0.326], [64704.8, 0.636], [64705.2, 0.013], [64705.6, 0.02], [64706.2, 0.001], [64707.4, 0.138], [64708.3, 0.36], [64708.5, 0.266], [64712.2, 7.21]], "asks": [[64728.9, 0.164], [64729.7, 3.11], [64734.8, 0.01], [64735.4, 0.923], [64735.5, 0.0], [64735.7, 0.191], [64736.5, 0.115], [64869.8, 10.418], [64908.6, 15.406], [65359.4, 2.313]]}
{"kind": "depth", "E": 1787080125843, "U": 11315331070459, "u": 11315331075987, "recv_ms": 1787080125783, "bids": [[1000.0, 35.81], [14412.2, 0.476], [14512.2, 3.584], [14612.2, 0.14], [58240.9, 0.002], [61476.5, 0.0], [62123.7, 0.689], [63903.3, 9.342], [64065.1, 5.231], [64081.4, 0.0], [64518.1, 1.285], [64640.5, 32.989], [64642.7, 0.146], [64644.9, 0.004], [64646.3, 2.638], [64647.5, 0.003], [64666.9, 0.537], [64679.8, 0.005], [64695.0, 0.004], [64695.6, 0.002], [64696.2, 1.548], [64697.0, 0.017], [64698.0, 1.924], [64702.2, 0.544], [64702.3, 0.008], [64703.9, 0.022], [64704.1, 0.796], [64704.2, 0.003], [64704.4, 0.214], [64704.5, 0.0], [64705.0, 0.004], [64708.3, 0.166], [64708.5, 0.072], [64708.6, 0.125], [64712.2, 7.212]], "asks": [[64714.0, 0.003], [64725.2, 0.14], [64728.0, 0.128], [64728.7, 0.418], [64729.4, 3.686], [64729.7, 2.185], [64757.6, 0.003], [64777.0, 0.075], [64822.4, 0.014], [64868.5, 2.11], [65359.4, 2.313], [65618.3, 22.763], [65630.1, 28.165]]}
{"kind": "depth", "E": 1787080125945, "U": 11315331076082, "u": 11315331090304, "recv_ms": 1787080125886, "bids": [[1000.0, 35.81], [14412.2, 0.714], [14512.2, 3.458], [14612.2, 0.028], [51769.8, 0.0], [58240.9, 0.002], [61476.5, 0.0], [62123.7, 0.692], [63712.2, 7.683], [64065.1, 5.231], [64388.6, 4.446], [64640.5, 32.989], [64643.3, 2.322], [64644.9, 0.004], [64655.3, 2.149], [64663.6, 2.132], [64670.8, 0.002], [64695.0, 0.004], [64695.2, 0.001], [64696.0, 0.998], [64696.2, 0.93], [64698.0, 1.024], [64702.2, 0.653], [64702.3, 0.479], [64704.1, 0.157], [64704.2, 0.003], [64704.4, 0.214], [64705.6, 0.018], [64706.0, 0.012], [64706.4, 0.007], [64706.7, 0.001], [64707.0, 0.207], [64709.5, 0.002], [64711.1, 0.086], [64711.4, 0.331], [64712.1, 0.017], [64712.2, 7.286]], "asks": [[64721.8, 0.004], [64725.2, 0.141], [64869.8, 6.337], [64908.6, 11.524], [65035.9, 3.998], [65359.4, 2.313], [65712.3, 0.007]]}
{"kind": "depth", "E": 1787080126047, "U": 11315331090309, "u": 11315331096988, "recv_ms": 1787080125986, "bids": [[14412.2, 1.05], [14512.2, 3.15], [14612.2, 0.0], [58240.9, 0.002], [61476.5, 0.0], [63806.2, 25.993], [64065.1, 7.568], [64268.2, 0.26], [64388.6, 4.446], [64640.5, 0.0], [64642.7, 0.146], [64644.9, 32.993], [64663.6, 2.128], [64670.7, 0.169], [64694.8, 0.005], [64695.0, 0.004], [64700.6, 0.25], [64702.2, 0.653], [64702.3, 0.479], [64704.1, 0.157], [64704.2, 0.003], [64704.4, 0.214], [64704.5, 0.0], [64706.4, 0.004], [64707.0, 0.013], [64712.2, 7.214]], "asks": [[64869.8, 10.418], [64908.6, 15.406], [65359.4, 2.313], [65500.7, 16.011], [66665.7, 1.284]]}
{"kind": "depth", "E": 1787080126251, "U": 11315331102204, "u": 11315331107279, "recv_ms": 1787080126193, "bids": [[1000.0, 35.81], [14412.2, 1.764], [14512.2, 2.436], [58240.9, 0.002], [61476.5, 0.0], [62123.7, 0.692], [62774.8, 0.682], [63418.0, 2.695], [63712.2, 7.683], [63817.8, 30.619], [64065.1, 7.568], [64388.6, 4.447], [64515.7, 7.395], [64554.5, 7.534], [64571.5, 2.816], [64668.1, 0.0], [64694.8, 0.468], [64695.0, 0.012], [64696.2, 0.93], [64702.2, 0.66], [64702.3, 0.001], [64704.1, 0.157], [64704.2, 0.003], [64704.4, 0.214], [64704.5, 0.0], [64705.0, 0.005], [64707.3, 0.465], [64712.2, 7.201]], "asks": [[64728.7, 0.418], [65359.4, 2.313], [65643.1, 0.684], [65712.3, 0.007]]}
{"kind": "depth", "E": 1787080126353, "U": 11315331107350, "u": 11315331113160, "recv_ms": 1787080126295, "bids": [[14412.2, 2.114], [14512.2, 2.086], [51770.0, 0.002], [58240.9, 0.002], [61476.5, 0.0], [62123.7, 0.689], [64065.0, 0.022], [64065.1, 7.57], [64255.3, 0.117], [64388.6, 4.447], [64668.1, 0.028], [64694.8, 0.005], [64695.0, 0.004], [64700.2, 0.051], [64700.4, 0.156], [64702.2, 0.551], [64702.3, 0.001], [64702.5, 0.001], [64704.1, 0.274], [64704.2, 0.003], [64704.4, 0.214], [64704.5, 0.463], [64711.5, 0.087], [64711.9, 0.019], [64712.2, 7.214]], "asks": [[64712.3, 14.174], [64714.0, 0.013], [64714.1, 0.0], [64714.3, 0.084], [64717.5, 2.419], [64719.5, 0.023], [64869.8, 6.26], [64908.6, 11.311], [65053.6, 0.001], [65118.4, 0.0], [65183.2, 0.001], [65359.4, 2.313]]}
{"kind": "depth", "E": 1787080126455, "U": 11315331113165, "u": 11315331117832, "recv_ms": 1787080126394, "bids": [[1000.0, 35.81], [14412.2, 2.478], [14512.2, 1.722], [51770.0, 0.0], [58240.9, 0.002], [61476.5, 0.0], [63664.0, 0.008], [64065.1, 7.568], [64194.5, 4.68], [64390.3, 0.288], [64694.8, 0.005], [64695.7, 0.79], [64700.4, 0.002], [64700.5, 0.158], [64700.7, 0.262], [64702.2, 0.003], [64702.3, 0.001], [64702.5, 0.155], [64703.1, 0.944], [64703.2, 0.128], [64704.1, 1.27], [64704.2, 0.011], [64704.5, 0.0], [64705.0, 0.012], [64712.2, 7.243]], "asks": [[64727.6, 0.62], [64735.0, 0.622], [64986.7, 0.063], [65035.9, 3.843], [65051.4, 0.063], [65114.6, 0.234], [65116.1, 0.063], [65180.8, 0.063], [65230.0, 8.49], [65248.0, 1.323], [66006.5, 0.009]]}
{"kind": "depth", "E": 1787080126557, "U": 11315331117937, "u": 11315331124083, "recv_ms": 1787080126497, "bids": [[1000.0, 35.81], [14412.2, 2.828], [14512.2, 1.372], [51770.0, 0.0], [58240.9, 0.002], [61476.5, 0.0], [62123.7, 0.692], [63712.2, 7.703], [64065.1, 7.568], [64476.8, 0.0], [64515.7, 7.415], [64518.1, 0.361], [64554.5, 7.537], [64571.5, 2.819], [64595.5, 0.0], [64596.0, 3.939], [64605.1, 0.0], [64605.4, 2.321], [64641.0, 0.323], [64673.3, 0.082], [64695.7, 0.172], [64700.3, 0.475], [64700.5, 0.004], [64701.7, 0.682], [64702.5, 0.001], [64703.1, 0.326], [64703.2, 0.004], [64704.1, 1.27], [64704.2, 0.013], [64704.4, 0.03], [64704.7, 0.001], [64705.6, 0.018], [64705.7, 0.241], [64706.1, 0.526], [64706.4, 0.088], [64707.2, 0.092], [64707.3, 0.619], [64708.7, 0.175], [64709.2, 0.019], [64709.6, 0.034], [64710.0, 0.01], [64710.4, 0.009], [64711.1, 0.0], [64711.2, 0.258], [64711.4, 0.021], [64711.5, 0.003], [64712.2, 5.737]], "asks": [[64712.3, 14.175], [64712.6, 0.096], [64713.0, 0.084], [64713.5, 1.513], [64713.9, 0.087], [64714.3, 0.091], [64717.1, 0.017], [64717.5, 2.322], [64719.8, 0.001], [64721.1, 0.033], [64721.6, 0.002], [64727.6, 0.002], [64735.2, 10.003], [64736.0, 1.603], [64761.5, 0.076], [64783.5, 0.048], [64820.8, 5.745], [64820.9, 0.001], [64847.8, 4.811], [64852.8, 7.916], [64869.8, 6.234], [64908.6, 11.229], [65359.4, 2.313], [65712.3, 0.027]]}
{"kind": "depth", "E": 1787080126659, "U": 11315331124300, "u": 11315331131570, "recv_ms": 1787080126607, "bids": [[14412.2, 3.178], [14512.2, 1.022], [51770.0, 0.0], [58240.9, 0.002], [61476.5, 0.0], [61476.7, 0.006], [62123.7, 0.689], [62495.2, 0.011], [63418.0, 2.698], [63712.2, 7.683], [64065.1, 7.568], [64194.5, 8.568], [64388.6, 4.447], [64656.4, 0.21], [64663.4, 0.002], [64663.6, 2.132], [64670.7, 0.165], [64675.2, 0.488], [64676.8, 1.352], [64678.6, 0.058], [64679.4, 0.009], [64681.3, 0.01], [64683.8, 0.336], [64684.9, 0.011], [64689.3, 0.698], [64690.0, 0.305], [64690.1, 0.004], [64691.5, 0.12], [64692.4, 0.029], [64692.6, 0.001], [64693.2, 0.003], [64694.6, 1.089], [64694.8, 0.476], [64695.4, 0.021], [64696.2, 0.005], [64697.2, 0.003], [64697.7, 0.136], [64699.0, 1.013], [64699.4, 0.258], [64701.0, 0.584], [64701.7, 0.373], [64702.2, 0.621], [64703.7, 0.995], [64704.0, 0.129], [64704.1, 0.157], [64704.2, 0.003], [64704.4, 0.03], [64704.6, 0.1], [64705.0, 0.088], [64705.1, 0.04], [64705.2, 0.013], [64705.3, 0.102], [64705.7, 0.087], [64706.0, 0.012], [64706.8, 0.132], [64706.9, 1.849], [64707.0, 0.013], [64707.3, 0.309], [64707.7, 0.092], [64708.0, 1.875], [64708.1, 0.204], [64708.2, 0.216], [64708.3, 0.166], [64708.5, 0.072], [64708.7, 0.173], [64708.8, 0.011], [64709.4, 1.849], [64709.5, 0.011], [64711.6, 0.02], [64711.9, 0.0], [64712.2, 4.155]], "asks": [[64712.3, 14.175], [64713.0, 0.394], [64713.8, 0.002], [64713.9, 0.09], [64714.3, 0.091], [64714.9, 0.013], [64718.9, 0.021], [64719.5, 0.001], [64719.7, 0.022], [64722.7, 2.831], [64727.8, 0.95], [64729.1, 0.013], [64729.4, 2.763], [64729.5, 0.005], [64729.6, 0.569], [64729.7, 3.877], [64730.2, 0.003], [64730.5, 10.076], [64730.7, 0.003], [64731.2, 3.209], [64731.6, 0.003], [64731.7, 0.918], [64732.3, 0.003], [64733.3, 1.562], [64734.1, 0.544], [64734.8, 0.125], [64735.0, 0.004], [64735.2, 0.003], [64735.4, 0.382], [64736.5, 0.0], [64744.5, 0.081], [64758.1, 0.214], [64765.4, 0.312], [64777.1, 0.002], [64852.8, 7.909], [64869.8, 6.222], [64908.6, 11.196], [65230.0, 8.795], [65247.6, 0.009], [65359.4, 2.317], [65488.8, 32.928], [65712.3, 0.007]]}
{"kind": "depth", "E": 1787080126761, "U": 11315331131609, "u": 11315331137061, "recv_ms": 1787080126702, "bids": [[1000.0, 35.81], [14412.2, 3.542], [14512.2, 0.658], [58240.9, 0.002], [61476.5, 0.0], [62123.7, 0.692], [63654.2, 4.235], [64065.1, 7.568], [64138.7, 0.238], [64342.0, 5.013], [64383.5, 0.359], [64448.4, 0.019], [64582.7, 0.003], [64678.6, 0.001], [64680.4, 0.149], [64689.3, 0.142], [64690.1, 0.56], [64691.1, 0.567], [64694.6, 0.164], [64694.8, 0.005], [64695.6, 0.927], [64696.5, 0.158], [64700.3, 0.321], [64700.5, 0.158], [64702.2, 0.003], [64702.3, 0.471], [64703.8, 1.321], [64703.9, 0.563], [64704.0, 0.779], [64704.2, 0.003], [64705.3, 0.086], [64706.0, 0.01], [64706.2, 0.125], [64706.9, 0.522], [64707.3, 0.155], [64707.4, 0.014], [64708.5, 0.072], [64708.8, 0.003], [64712.2, 4.157]], "asks": [[64712.3, 14.195], [64719.0, 0.031], [64720.0, 0.223], [64721.0, 1.804], [64722.2, 0.522], [64727.8, 0.025], [64728.9, 1.089], [64729.6, 0.013], [64730.3, 0.017], [64730.4, 0.599], [64730.5, 10.019], [64731.4, 0.0], [64731.6, 0.559], [64732.2, 0.063], [64734.1, 0.003], [64734.8, 0.551], [64735.6, 0.116], [64771.8, 0.001], [64852.8, 9.284], [64869.8, 10.418], [64902.3, 0.339], [64905.8, 0.0], [64908.6, 15.406], [64980.8, 2.099], [65035.9, 3.997], [65359.4, 2.313]]}
{"kind": "depth", "E": 1787080126863, "U": 11315331137315, "u": 11315331144029, "recv_ms": 1787080126803, "bids": [[1000.0, 35.81], [14312.2, 0.07], [14412.2, 3.766], [14512.2, 0.364], [58240.9, 0.002], [60829.5, 0.0], [61476.5, 0.0], [62123.7, 0.689], [62770.9, 0.0], [63093.8, 0.0], [63418.0, 2.695], [63428.3, 1.993], [63500.3, 0.058], [63572.2, 0.059], [63644.1, 0.058], [63712.2, 7.703], [63716.0, 0.063], [63787.9, 0.058], [63859.8, 0.058], [63931.7, 0.064], [64003.7, 0.059], [64065.1, 7.545], [64075.6, 0.059], [64343.4, 0.0], [64518.1, 1.314], [64646.3, 7.68], [64663.6, 2.128], [64670.7, 0.169], [64679.5, 0.109], [64680.4, 0.092], [64700.0, 0.691], [64700.4, 0.002], [64700.5, 0.004], [64707.7, 0.402], [64708.8, 0.087], [64712.2, 4.115]], "asks": [[64712.3, 14.193], [64713.2, 0.002], [64731.7, 0.914], [64733.3, 1.562], [64734.1, 0.544], [64734.8, 0.01], [65337.2, 3.971], [65359.4, 2.291], [65370.0, 2.388], [65441.9, 0.058], [65505.5, 1.752], [65513.9, 0.286], [65521.2, 9.265], [65585.8, 0.058], [65634.3, 0.711], [65657.7, 0.059], [65699.7, 0.0], [65712.3, 0.027], [65729.6, 0.058], [65801.5, 0.059], [66653.6, 0.0], [68595.0, 0.0]]}
{"kind": "depth", "E": 1787080126965, "U": 11315331144135, "u": 11315331149696, "recv_ms": 1787080126905, "bids": [[14312.2, 0.294], [14412.2, 3.668], [14512.2, 0.238], [51769.8, 0.0], [58240.9, 0.002], [61476.5, 0.0], [64065.1, 7.545], [64268.2, 0.143], [64388.6, 4.281], [64553.5, 0.009], [64571.5, 0.001], [64666.9, 0.54], [64696.7, 0.041], [64712.2, 4.043]], "asks": [[64741.3, 1.423], [64822.4, 0.017], [64852.8, 3.887], [65359.4, 2.291], [65488.8, 33.462], [65873.4, 0.059], [65945.3, 0.072], [66017.3, 0.058]]}
{"kind": "depth", "E": 1787080127067, "U": 11315331149867, "u": 11315331167447, "recv_ms": 1787080127009, "bids": [[1000.0, 35.81], [14312.2, 0.532], [14412.2, 3.556], [14512.2, 0.112], [34000.0, 1.15], [58240.9, 0.002], [61476.5, 0.0], [62123.7, 0.692], [63822.6, 5.284], [64065.1, 7.545], [64125.9, 0.468], [64141.3, 1.095], [64194.5, 8.258], [64571.5, 2.785], [64620.7, 0.123], [64620.8, 1.242], [64638.3, 32.967], [64639.4, 0.018], [64641.2, 0.0], [64641.5, 0.003], [64644.3, 3.55], [64644.9, 0.006], [64649.7, 0.021], [64653.0, 0.081], [64654.7, 0.023], [64654.9, 0.093], [64656.6, 0.035], [64656.7, 0.026], [64659.4, 0.003], [64662.3, 0.021], [64663.5, 0.026], [64665.4, 0.002], [64665.5, 3.534], [64666.0, 3.261], [64666.9, 0.537], [64667.2, 1.148], [64667.9, 2.319], [64668.5, 0.185], [64670.7, 0.183], [64673.1, 0.016], [64673.3, 0.096], [64677.3, 0.004], [64678.3, 1.294], [64678.7, 0.941], [64679.5, 0.052], [64679.8, 0.002], [64681.1, 0.001], [64683.5, 0.001], [64687.4, 1.774], [64687.7, 2.039], [64687.9, 0.0], [64688.1, 0.251], [64688.9, 0.628], [64690.1, 0.004], [64691.6, 0.007], [64691.7, 0.518], [64692.4, 0.022], [64692.7, 0.118], [64693.0, 0.008], [64693.5, 2.341], [64693.9, 0.633], [64694.6, 1.089], [64694.8, 0.476], [64695.6, 0.002], [64697.3, 1.212], [64698.0, 0.124], [64698.7, 0.009], [64699.0, 0.013], [64699.4, 0.249], [64699.7, 0.182], [64699.8, 0.002], [64700.4, 0.003], [64700.6, 0.245], [64700.9, 0.002], [64701.8, 0.001], [64702.2, 0.544], [64702.3, 0.001], [64702.4, 0.005], [64703.5, 0.127], [64703.6, 0.015], [64703.8, 1.601], [64703.9, 0.022], [64704.0, 0.129], [64704.1, 1.844], [64704.2, 0.003], [64704.8, 0.636], [64704.9, 0.066], [64705.1, 0.04], [64705.2, 1.851], [64705.3, 1.571], [64705.7, 0.241], [64705.8, 0.252], [64706.1, 0.449], [64706.8, 0.092], [64706.9, 0.002], [64707.0, 0.013], [64707.2, 0.092], [64707.3, 0.001], [64707.4, 0.036], [64707.5, 0.021], [64707.7, 0.085], [64707.9, 0.141], [64708.0, 1.874], [64708.1, 0.205], [64708.5, 0.08], [64708.7, 0.257], [64708.8, 0.003], [64709.2, 0.019], [64709.4, 1.849], [64709.5, 0.011], [64710.4, 0.059], [64710.6, 0.055], [64711.2, 0.251], [64711.3, 0.001], [64711.4, 0.002], [64711.6, 0.0], [64711.7, 0.048], [64712.1, 0.015], [64712.2, 0.884]], "asks": [[64712.3, 27.224], [64712.4, 0.044], [64713.6, 0.002], [64714.3, 0.084], [64714.4, 0.009], [64714.8, 0.122], [64715.0, 0.106], [64715.4, 0.189], [64715.8, 0.003], [64717.0, 0.152], [64718.4, 0.023], [64718.5, 0.335], [64719.2, 0.008], [64719.3, 0.313], [64719.7, 0.052], [64719.8, 0.009], [64720.0, 0.128], [64720.5, 0.004], [64721.1, 0.034], [64721.2, 0.003], [64721.4, 0.063], [64721.5, 0.012], [64721.9, 0.017], [64722.0, 0.553], [64722.1, 0.632], [64722.2, 0.059], [64723.2, 2.306], [64724.4, 0.008], [64725.2, 0.14], [64726.0, 0.01], [64726.1, 0.682], [64727.1, 0.938], [64728.9, 0.164], [64730.2, 0.06], [64730.7, 0.021], [64731.2, 3.209], [64731.6, 0.577], [64732.2, 0.024], [64732.5, 0.076], [64732.6, 0.07], [64732.8, 2.271], [64733.2, 0.623], [64733.4, 2.411], [64733.5, 0.002], [64734.0, 0.299], [64734.1, 0.003], [64735.2, 0.017], [64735.8, 0.081], [64737.1, 0.328], [64737.4, 0.02], [64738.0, 0.534], [64739.3, 0.008], [64741.2, 0.327], [64741.3, 1.425], [64741.4, 0.744], [64741.6, 0.105], [64742.1, 0.001], [64742.5, 0.003], [64744.2, 0.002], [64744.3, 0.004], [64744.4, 0.126], [64744.9, 0.024], [64745.0, 2.959], [64745.1, 1.012], [64747.2, 1.398], [64747.3, 0.063], [64747.4, 0.008], [64754.0, 0.003], [64757.6, 0.0], [64760.2, 0.08], [64762.6, 0.016], [64776.0, 1.583], [64780.5, 0.022], [64781.3, 1.205], [64783.3, 36.021], [64787.2, 6.352], [64789.9, 0.004], [64801.9, 0.008], [64822.4, 0.014], [64842.3, 0.451], [64852.8, 9.284], [64856.4, 0.001], [64869.7, 10.431], [64869.8, 0.013], [64908.6, 15.406], [65035.9, 3.998], [65042.2, 0.126], [65072.8, 0.001], [65327.1, 5.769], [65359.4, 2.291], [66006.5, 0.012]]}
{"kind": "depth", "E": 1787080127169, "U": 11315331167525, "u": 11315331181322, "recv_ms": 1787080127114, "bids": [[1000.0, 35.81], [14312.2, 0.77], [14412.2, 3.43], [14512.2, 0.0], [34000.0, 1.146], [51770.0, 0.0], [58240.9, 0.002], [61476.5, 0.0], [61476.7, 0.004], [62123.7, 0.689], [63418.0, 2.692], [63712.2, 7.683], [64065.1, 9.883], [64255.3, 0.234], [64390.3, 0.229], [64585.1, 0.002], [64604.9, 2.32], [64605.4, 0.003], [64633.1, 0.025], [64638.3, 0.0], [64642.7, 33.113], [64644.3, 3.552], [64644.9, 0.004], [64646.3, 2.638], [64655.4, 0.238], [64656.6, 0.003], [64656.9, 0.331], [64657.2, 0.031], [64657.5, 0.27], [64657.8, 0.002], [64663.4, 0.006], [64669.9, 0.008], [64670.7, 0.179], [64674.0, 0.002], [64674.3, 0.0], [64674.7, 0.003], [64675.0, 0.709], [64675.2, 0.523], [64675.3, 0.072], [64675.6, 0.032], [64687.2, 0.298], [64688.9, 0.558], [64689.0, 0.0], [64689.1, 0.025], [64689.2, 0.029], [64689.3, 0.042], [64689.4, 1.082], [64689.5, 0.053], [64689.6, 1.326], [64689.7, 0.001], [64689.9, 0.0], [64690.6, 0.004], [64691.1, 0.467], [64692.7, 0.038], [64693.7, 0.008], [64694.2, 0.232], [64694.6, 1.082], [64694.8, 0.005], [64697.0, 0.017], [64698.1, 0.004], [64700.4, 0.002], [64701.8, 0.081], [64702.2, 0.003], [64702.3, 0.001], [64703.8, 2.142], [64703.9, 0.485], [64704.2, 0.003], [64705.3, 1.571], [64707.6, 0.072], [64707.7, 0.085], [64707.8, 0.071], [64707.9, 0.001], [64708.0, 1.904], [64708.1, 0.005], [64708.2, 0.024], [64708.3, 0.096], [64708.4, 0.001], [64708.5, 0.002], [64708.6, 0.025], [64708.7, 0.187], [64708.9, 0.001], [64709.3, 0.162], [64709.6, 0.002], [64709.7, 0.041], [64709.9, 0.016], [64710.0, 0.042], [64710.2, 0.0], [64712.2, 0.884]], "asks": [[64712.3, 27.23], [64714.6, 2.506], [64714.7, 0.397], [64719.0, 0.009], [64719.4, 0.007], [64720.0, 0.12], [64720.2, 0.05], [64720.5, 0.036], [64720.7, 0.002], [64721.1, 0.001], [64721.4, 0.028], [64721.7, 0.002], [64721.8, 0.012], [64722.0, 0.518], [64722.3, 1.142], [64722.4, 1.952], [64722.5, 1.071], [64722.6, 1.003], [64722.7, 2.845], [64722.8, 0.572], [64722.9, 0.0], [64723.0, 0.01], [64723.1, 0.001], [64723.2, 2.166], [64723.3, 0.312], [64723.7, 0.004], [64725.2, 0.141], [64726.1, 0.679], [64730.2, 0.003], [64731.0, 0.136], [64735.2, 0.021], [64737.4, 0.052], [64737.8, 0.042], [64738.2, 0.001], [64738.5, 0.361], [64738.9, 0.001], [64739.2, 3.416], [64739.5, 0.012], [64739.9, 1.006], [64740.3, 0.025], [64740.6, 2.487], [64740.8, 1.349], [64741.0, 0.109], [64741.1, 0.387], [64741.2, 0.25], [64741.3, 1.325], [64741.4, 0.564], [64741.5, 0.027], [64741.6, 0.005], [64741.7, 0.0], [64741.8, 0.07], [64741.9, 0.002], [64742.0, 0.007], [64754.6, 0.396], [64755.7, 0.002], [64756.0, 0.015], [64756.3, 0.166], [64756.6, 0.033], [64757.0, 0.0], [64765.9, 0.0], [64787.2, 1.214], [64800.6, 0.1], [64820.7, 2.361], [64820.8, 3.427], [64869.7, 6.333], [64908.6, 11.483], [65359.4, 2.291], [65712.3, 0.007]]}
{"kind": "depth", "E": 1787080127373, "U": 11315331193322, "u": 11315331204352, "recv_ms": 1787080127315, "bids": [[1000.0, 35.96], [14312.2, 1.484], [14412.2, 2.716], [58240.9, 0.002], [61476.5, 0.0], [61476.6, 0.004], [61476.7, 0.004], [62123.7, 0.689], [63903.3, 9.576], [64065.1, 9.883], [64585.0, 0.162], [64668.5, 0.339], [64674.9, 0.048], [64677.4, 0.151], [64679.4, 0.066], [64680.4, 0.092], [64689.6, 1.882], [64689.8, 2.336], [64690.6, 0.004], [64691.3, 0.021], [64693.9, 1.251], [64694.8, 0.005], [64694.9, 1.391], [64695.0, 0.004], [64696.0, 1.898], [64696.7, 0.041], [64701.1, 1.246], [64701.3, 1.014], [64702.2, 0.474], [64703.9, 0.563], [64704.1, 0.157], [64704.2, 0.087], [64705.3, 0.186], [64705.4, 0.004], [64705.7, 0.087], [64707.2, 0.008], [64707.3, 0.001], [64707.5, 0.091], [64708.2, 0.124], [64708.4, 0.101], [64709.4, 1.881], [64712.2, 0.733]], "asks": [[64720.6, 2.076], [64721.6, 0.132], [64721.8, 0.122], [64722.8, 0.642], [64725.8, 0.006], [64727.4, 0.332], [64728.3, 1.177], [64729.1, 0.013], [64729.9, 0.558], [64731.6, 0.014], [64733.2, 1.241], [64734.8, 0.01], [64737.8, 0.077], [64738.9, 0.131], [64740.1, 0.169], [64741.1, 0.457], [64830.6, 0.008], [64837.6, 0.03], [65035.9, 3.998], [65359.4, 2.291], [65440.7, 0.005], [65457.1, 13.672]]}
{"kind": "depth", "E": 1787080127475, "U": 11315331204452, "u": 11315331214240, "recv_ms": 1787080127417, "bids": [[1000.0, 35.81], [14312.2, 1.848], [14412.2, 2.352], [58240.9, 0.002], [61476.5, 0.0], [62123.7, 0.703], [64065.1, 9.883], [64594.9, 4.552], [64595.2, 1.54], [64596.0, 0.076], [64641.0, 0.323], [64658.0, 0.058], [64658.3, 0.032], [64674.3, 0.032], [64698.4, 0.629], [64701.1, 1.237], [64704.1, 0.157], [64706.2, 0.001], [64706.7, 0.773], [64707.6, 0.142], [64707.9, 0.201], [64708.0, 1.92], [64708.2, 0.224], [64708.3, 0.166], [64708.4, 0.225], [64708.5, 0.072], [64708.7, 0.135], [64712.2, 0.705]], "asks": [[64712.3, 27.227], [64715.4, 0.183], [64715.7, 0.122], [64718.0, 1.393], [64718.2, 0.021], [64718.3, 0.002], [64718.4, 0.004], [64718.5, 0.313], [64720.0, 0.213], [64721.2, 0.073], [64721.5, 0.103], [64721.7, 0.179], [64721.9, 0.001], [64722.0, 0.618], [64722.1, 0.765], [64722.4, 2.022], [64728.0, 0.124], [64729.9, 0.002], [64730.7, 0.577], [64733.2, 0.7], [64734.1, 0.544], [64738.5, 0.396], [64739.3, 0.118], [64739.8, 0.092], [64740.0, 0.564], [64740.1, 0.269], [64740.3, 0.125], [64740.4, 3.601], [64740.7, 0.072], [64754.7, 0.241], [64755.0, 0.05], [64783.5, 0.048], [64847.8, 4.811], [64905.0, 0.017], [65359.4, 2.291], [65618.3, 25.045], [65643.1, 0.457]]}
{"kind": "depth", "E": 1787080127577, "U": 11315331214415, "u": 11315331223220, "recv_ms": 1787080127516, "bids": [[14312.2, 2.198], [14412.2, 2.002], [58240.9, 0.002], [61476.5, 0.0], [62123.7, 0.706], [63712.2, 7.683], [63882.4, 1.094], [64065.1, 9.883], [64388.6, 4.444], [64571.5, 0.001], [64657.3, 0.154], [64675.2, 0.187], [64688.2, 0.183], [64689.2, 0.099], [64689.4, 1.152], [64689.5, 0.123], [64689.7, 0.101], [64693.9, 0.633], [64699.9, 0.686], [64700.0, 0.537], [64701.3, 0.396], [64704.6, 0.085], [64712.2, 0.694]], "asks": [[64712.3, 27.611], [64718.0, 0.493], [64755.7, 0.037], [64773.0, 0.0], [64780.5, 0.062], [64852.8, 3.887], [64911.9, 0.003], [64912.0, 1.604], [65359.4, 2.291], [65521.8, 2.037], [65570.2, 0.002], [65712.3, 0.007]]}
{"kind": "depth", "E": 1787080127679, "U": 11315331223560, "u": 11315331232069, "recv_ms": 1787080127623, "bids": [[1000.0, 35.81], [14312.2, 2.562], [14412.2, 1.638], [51770.0, 0.0], [58240.9, 0.002], [58241.0, 0.01], [62123.7, 0.689], [64065.1, 9.883], [64554.5, 7.541], [64571.5, 2.819], [64582.7, 0.004], [64657.0, 0.032], [64657.7, 0.035], [64672.3, 0.337], [64673.3, 0.097], [64689.2, 0.169], [64689.4, 1.222], [64689.8, 2.406], [64691.5, 0.004], [64693.8, 0.466], [64694.9, 0.466], [64695.0, 0.004], [64697.1, 1.885], [64699.9, 0.686], [64702.2, 0.466], [64703.9, 0.571], [64704.8, 0.464], [64707.2, 0.092], [64707.6, 0.226], [64712.1, 0.017], [64712.2, 1.769]], "asks": [[64712.3, 27.227], [64713.4, 0.002], [64718.2, 0.002], [64725.2, 0.14], [64728.3, 0.252], [64729.5, 0.93], [64730.7, 0.021], [64731.9, 0.651], [64732.3, 0.003], [64733.1, 0.057], [64733.2, 0.082], [64734.1, 0.003], [64735.6, 0.001], [64735.9, 0.541], [64736.8, 0.116], [64755.1, 0.058], [64755.7, 0.072], [64852.8, 9.284], [64868.5, 2.203], [64869.7, 10.431], [64902.3, 0.464], [65359.4, 2.291], [65488.8, 36.038], [65618.3, 25.228]]}
{"kind": "depth", "E": 1787080127781, "U": 11315331232180, "u": 11315331240603, "recv_ms": 1787080127722, "bids": [[14312.2, 2.912], [14412.2, 1.288], [51770.0, 0.0], [58240.9, 0.002], [58241.0, 0.008], [61476.5, 0.0], [61476.6, 0.006], [62123.7, 0.692], [63712.2, 7.703], [63773.3, 4.236], [64065.1, 9.883], [64582.7, 0.003], [64672.3, 0.336], [64689.8, 2.506], [64691.1, 0.567], [64692.6, 0.117], [64693.8, 0.35], [64696.4, 0.935], [64697.1, 0.96], [64699.9, 0.686], [64702.3, 0.009], [64703.9, 0.563], [64712.2, 1.724]], "asks": [[64712.3, 27.231], [64715.5, 0.114], [65359.4, 2.291], [65482.4, 8.247], [65712.3, 0.027]]}
{"kind": "depth", "E": 1787080127883, "U": 11315331240772, "u": 11315331247638, "recv_ms": 1787080127825, "bids": [[14312.2, 3.276], [14412.2, 0.924], [58240.9, 0.002], [61476.5, 0.0], [63097.4, 0.0], [63418.0, 2.698], [63806.2, 26.181], [63870.8, 2.195], [64065.1, 9.883], [64388.6, 4.444], [64571.5, 0.001], [64603.3, 1.26], [64642.9, 7.787], [64689.3, 0.112], [64689.5, 0.223], [64689.6, 1.982], [64689.9, 0.1], [64690.0, 0.375], [64690.1, 0.074], [64690.7, 0.26], [64702.1, 3.06], [64704.1, 0.003], [64712.1, 0.015], [64712.2, 1.274]], "asks": [[64712.3, 27.617], [64715.5, 0.136], [64725.2, 0.141], [64731.7, 0.843], [64734.3, 0.551], [64735.9, 0.0], [64852.8, 3.887], [64902.3, 0.013], [65359.4, 2.291], [65647.9, 0.761], [65699.6, 0.0], [65906.8, 1.519]]}
{"kind": "depth", "E": 1787080127985, "U": 11315331247815, "u": 11315331254492, "recv_ms": 1787080127970, "bids": [[1000.0, 35.81], [14312.2, 3.626], [14412.2, 0.574], [51769.8, 0.0], [58240.9, 0.002], [62123.7, 0.689], [63712.2, 7.683], [63744.9, 2.352], [64065.1, 9.883], [64571.5, 3.128], [64571.6, 1.197], [64704.1, 0.157], [64708.0, 1.943], [64708.2, 0.243], [64709.0, 0.003], [64712.2, 1.208]], "asks": [[64730.8, 0.042], [64852.8, 9.284], [65359.4, 2.291], [65482.4, 9.162], [65488.8, 35.277], [65631.2, 1.818], [65643.1, 0.23], [65712.3, 0.007]]}
{"kind": "depth", "E": 1787080128087, "U": 11315331254632, "u": 11315331262550, "recv_ms": 1787080128030, "bids": [[14212.2, 0.112], [14312.2, 3.766], [14412.2, 0.322], [58240.9, 0.002], [61476.5, 0.0], [62123.7, 0.692], [62760.2, 0.684], [63725.1, 0.014], [63789.9, 0.013], [63791.6, 0.01], [63847.9, 4.142], [64065.1, 9.883], [64073.0, 0.006], [64388.6, 4.445], [64585.0, 0.076], [64586.7, 0.078], [64654.2, 0.003], [64670.4, 1.275], [64679.4, 0.009], [64680.1, 0.077], [64681.4, 0.448], [64685.3, 0.461], [64686.5, 0.034], [64688.0, 0.181], [64690.3, 0.172], [64690.9, 1.903], [64692.7, 0.044], [64693.0, 0.002], [64694.1, 0.49], [64696.0, 0.998], [64696.1, 0.043], [64698.4, 0.148], [64700.4, 0.003], [64700.6, 0.245], [64702.2, 0.006], [64702.3, 0.001], [64702.4, 0.005], [64702.8, 0.0], [64703.1, 0.41], [64703.5, 0.211], [64703.9, 0.106], [64704.0, 0.741], [64704.1, 0.003], [64704.4, 0.135], [64705.3, 0.093], [64705.4, 0.545], [64705.5, 0.008], [64705.7, 0.157], [64705.8, 0.105], [64706.1, 0.365], [64706.2, 0.085], [64706.4, 0.004], [64706.7, 0.085], [64706.8, 0.006], [64707.0, 0.244], [64707.2, 0.015], [64707.5, 0.071], [64707.6, 0.142], [64707.7, 0.148], [64708.0, 1.92], [64708.1, 0.083], [64708.2, 0.235], [64708.5, 0.072], [64708.7, 0.138], [64710.4, 0.058], [64710.5, 0.002], [64712.2, 1.217]], "asks": [[64712.3, 27.628], [64716.8, 0.048], [64721.1, 0.002], [64723.1, 0.022], [64723.4, 0.266], [64725.8, 0.002], [64726.0, 0.002], [64727.1, 0.021], [64729.3, 0.63], [64730.2, 0.001], [64731.0, 0.079], [64734.3, 0.551], [64735.9, 0.0], [64739.8, 0.1], [64741.1, 0.449], [65035.9, 3.997], [65359.4, 2.291], [65376.0, 0.385], [65488.8, 36.038], [65568.1, 0.005], [65632.8, 0.0], [65634.5, 0.002], [65699.2, 0.001]]}
{"kind": "depth", "E": 1787080128189, "U": 11315331262691, "u": 11315331269034, "recv_ms": 1787080128131, "bids": [[14212.2, 0.35], [14312.2, 3.64], [14412.2, 0.21], [51770.0, 0.0], [58240.9, 0.002], [62123.7, 0.689], [63094.4, 0.714], [63712.2, 7.703], [63725.1, 0.022], [63789.9, 0.021], [63791.6, 0.018], [63850.1, 14.742], [63902.7, 4.047], [64065.1, 9.883], [64107.3, 5.618], [64138.7, 0.004], [64262.0, 1.305], [64388.6, 4.445], [64633.0, 0.067], [64633.1, 0.023], [64640.3, 0.0], [64640.4, 0.001], [64660.6, 0.003], [64663.5, 0.018], [64668.5, 0.185], [64669.9, 0.005], [64694.4, 0.163], [64695.0, 0.004], [64698.1, 0.003], [64699.5, 0.388], [64699.9, 0.532], [64700.4, 0.002], [64700.7, 0.263], [64701.5, 0.167], [64703.1, 0.326], [64704.1, 0.049], [64705.4, 0.004], [64705.7, 0.003], [64706.7, 0.626], [64707.0, 0.328], [64709.0, 0.157], [64709.3, 0.004], [64712.2, 1.173]], "asks": [[64712.3, 27.611], [64717.3, 0.164], [64721.1, 0.001], [64737.6, 1.299], [64744.5, 0.041], [64773.0, 0.04], [64780.5, 0.022], [65359.4, 2.291], [65712.3, 0.027], [65824.3, 4.653]]}
{"kind": "depth", "E": 1787080128291, "U": 11315331269131, "u": 11315331276915, "recv_ms": 1787080128232, "bids": [[1000.0, 35.81], [14212.2, 0.588], [14312.2, 3.528], [14412.2, 0.084], [51770.0, 0.0], [58240.9, 0.002], [61476.5, 0.0], [62123.7, 0.692], [63418.0, 2.698], [63838.6, 4.984], [63850.1, 14.117], [64065.1, 9.883], [64448.4, 0.0], [64476.5, 0.024], [64660.6, 0.001], [64670.7, 0.165], [64672.3, 0.0], [64673.3, 0.083], [64676.4, 0.726], [64682.8, 0.016], [64688.0, 0.18], [64689.6, 1.426], [64692.1, 0.558], [64692.7, 0.009], [64694.1, 0.482], [64694.8, 0.013], [64695.0, 0.904], [64696.2, 0.005], [64697.3, 0.212], [64699.3, 1.004], [64700.0, 0.572], [64703.5, 0.127], [64703.8, 1.599], [64703.9, 0.022], [64704.0, 0.648], [64704.2, 0.003], [64705.1, 0.042], [64705.3, 0.727], [64706.3, 0.006], [64706.7, 0.085], [64706.8, 0.006], [64707.4, 0.324], [64707.6, 0.226], [64708.1, 0.075], [64708.3, 0.273], [64708.4, 0.245], [64708.5, 0.08], [64709.3, 0.088], [64710.4, 0.059], [64712.1, 0.017], [64712.2, 5.093]], "asks": [[64712.3, 27.609], [64713.0, 0.084], [64713.4, 0.002], [64713.8, 0.002], [64713.9, 0.087], [64715.5, 0.094], [64715.7, 0.1], [64717.3, 0.163], [64717.4, 0.953], [64728.7, 0.418], [64729.3, 0.628], [64730.2, 0.003], [64732.4, 0.322], [64733.3, 1.569], [64734.3, 0.01], [64735.9, 0.541], [64868.5, 0.753], [64869.7, 10.431], [64906.3, 0.309], [64908.6, 15.406], [65359.4, 5.346], [65632.8, 0.008], [65634.5, 0.01], [65699.2, 0.009]]}
{"kind": "depth", "E": 1787080128393, "U": 11315331277220, "u": 11315331285074, "recv_ms": 1787080128333, "bids": [[14212.2, 0.854], [14312.2, 3.346], [14412.2, 0.0], [58240.9, 0.002], [61476.5, 0.0], [63712.2, 7.683], [64013.8, 7.861], [64063.4, 0.873], [64065.1, 9.883], [64097.4, 12.285], [64388.6, 4.446], [64699.5, 0.388], [64701.5, 0.061], [64704.1, 0.003], [64712.2, 5.095]], "asks": [[64712.3, 27.613], [64715.7, 0.12], [64715.8, 0.025], [65035.9, 3.996], [65231.1, 0.689], [65359.4, 5.346], [65557.4, 0.455], [65712.3, 0.007], [65812.4, 6.0]]}
{"kind": "depth", "E": 1787080128495, "U": 11315331285093, "u": 11315331291074, "recv_ms": 1787080128435, "bids": [[14212.2, 1.218], [14312.2, 2.982], [58240.9, 0.002], [61476.5, 0.0], [62123.7, 0.689], [63624.4, 0.63], [63822.6, 4.346], [63838.6, 5.374], [63967.7, 6.28], [64065.1, 9.883], [64125.9, 0.702], [64242.0, 0.077], [64388.6, 4.436], [64691.2, 0.567], [64691.6, 0.0], [64692.1, 0.002], [64693.6, 0.162], [64694.1, 0.019], [64694.8, 0.005], [64695.7, 1.715], [64696.4, 0.01], [64700.9, 0.003], [64703.1, 0.944], [64703.9, 1.034], [64704.0, 0.748], [64705.2, 0.015], [64705.3, 0.086], [64705.4, 0.004], [64712.2, 5.18]], "asks": [[64712.3, 27.614], [64721.6, 0.133], [64727.6, 0.62], [64734.1, 0.544], [64735.0, 0.622], [64735.9, 0.0], [64869.7, 6.234], [64908.6, 11.195], [65359.4, 5.346]]}
