{"receive_ns":1788781921507236000,"stream":"btcusdt@depth@100ms","event_type":"depthUpdate","event_time_ms":1788781921578,"raw_json":"{\"stream\":\"btcusdt@depth@100ms\",\"data\":{\"e\":\"depthUpdate\",\"E\":1788781921578,\"T\":1788781921577,\"s\":\"BTCUSDT\",\"ps\":\"BTCUSDT\",\"U\":11496321228494,\"u\":11496321235661,\"pu\":11496321228392,\"b\":[[\"28882.20\",\"1.778\"],[\"28982.20\",\"0.287\"],[\"29282.20\",\"0.035\"],[\"71443.90\",\"0.002\"],[\"76206.90\",\"0.002\"],[\"78027.40\",\"6.842\"],[\"78583.00\",\"11.020\"],[\"78588.40\",\"0.000\"],[\"78612.40\",\"2.014\"],[\"78614.30\",\"2.729\"],[\"78985.30\",\"0.136\"],[\"79134.10\",\"0.125\"],[\"79150.40\",\"0.000\"],[\"79157.10\",\"0.240\"],[\"79161.60\",\"35.371\"],[\"79169.40\",\"1.088\"],[\"79179.80\",\"1.625\"],[\"79182.10\",\"0.443\"],[\"79203.00\",\"0.002\"],[\"79207.40\",\"26.513\"],[\"79234.10\",\"0.000\"],[\"79238.60\",\"17.678\"],[\"79259.20\",\"0.187\"],[\"79287.50\",\"0.003\"],[\"79292.00\",\"10.035\"],[\"79324.60\",\"0.050\"],[\"79335.90\",\"1.570\"],[\"79347.70\",\"0.006\"],[\"79351.80\",\"0.975\"],[\"79362.90\",\"0.100\"],[\"79363.80\",\"0.323\"],[\"79364.90\",\"0.162\"],[\"79365.20\",\"0.108\"],[\"79365.40\",\"0.235\"],[\"79367.10\",\"0.442\"],[\"79367.20\",\"0.001\"],[\"79371.90\",\"0.024\"],[\"79372.70\",\"0.002\"],[\"79373.00\",\"0.000\"]],\"a\":[[\"79382.30\",\"5.847\"],[\"79383.80\",\"0.003\"],[\"79386.80\",\"0.003\"],[\"79387.70\",\"0.001\"],[\"79390.30\",\"0.051\"],[\"79402.60\",\"0.970\"],[\"79409.00\",\"3.199\"],[\"79416.10\",\"1.012\"],[\"79418.50\",\"1.165\"],[\"79576.00\",\"0.047\"],[\"79747.50\",\"0.497\"],[\"80150.10\",\"0.292\"],[\"80176.10\",\"1.565\"],[\"80732.10\",\"0.619\"]],\"st\":1}}"}
{"receive_ns":1788781921613121000,"stream":"btcusdt@depth@100ms","event_type":"depthUpdate","event_time_ms":1788781921680,"raw_json":"{\"stream\":\"btcusdt@depth@100ms\",\"data\":{\"e\":\"depthUpdate\",\"E\":1788781921680,\"T\":1788781921678,\"s\":\"BTCUSDT\",\"ps\":\"BTCUSDT\",\"U\":11496321235700,\"u\":11496321245146,\"pu\":11496321235661,\"b\":[[\"1000.00\",\"24.904\"],[\"28882.20\",\"1.848\"],[\"28982.20\",\"0.161\"],[\"29282.20\",\"0.091\"],[\"63505.80\",\"0.000\"],[\"63506.00\",\"0.002\"],[\"71443.90\",\"0.002\"],[\"76206.90\",\"0.000\"],[\"78372.80\",\"17.033\"],[\"78429.60\",\"1.660\"],[\"78583.00\",\"9.749\"],[\"78588.40\",\"0.000\"],[\"78747.10\",\"3.171\"],[\"79133.00\",\"0.054\"],[\"79134.10\",\"0.915\"],[\"79153.50\",\"0.015\"],[\"79157.20\",\"2.197\"],[\"79161.60\",\"0.000\"],[\"79161.70\",\"0.000\"],[\"79203.00\",\"1.525\"],[\"79207.40\",\"0.000\"],[\"79234.20\",\"0.757\"],[\"79238.60\",\"0.010\"],[\"79287.50\",\"0.138\"],[\"79292.00\",\"1.207\"],[\"79347.20\",\"0.046\"],[\"79348.70\",\"0.000\"],[\"79354.10\",\"0.457\"],[\"79356.10\",\"0.001\"],[\"79361.10\",\"0.006\"],[\"79362.10\",\"1.141\"],[\"79362.90\",\"0.419\"],[\"79363.40\",\"0.083\"],[\"79363.80\",\"0.004\"],[\"79365.20\",\"0.549\"],[\"79365.40\",\"0.231\"],[\"79365.60\",\"0.002\"],[\"79367.10\",\"0.001\"],[\"79371.90\",\"0.028\"]],\"a\":[[\"79382.30\",\"5.849\"],[\"79400.90\",\"0.252\"],[\"79401.50\",\"0.442\"],[\"79401.90\",\"2.463\"],[\"79404.00\",\"0.019\"],[\"79404.50\",\"0.000\"],[\"79409.10\",\"0.003\"],[\"79555.90\",\"0.000\"],[\"79747.50\",\"0.981\"],[\"79972.20\",\"3.120\"],[\"79977.70\",\"1.721\"],[\"80170.70\",\"10.762\"],[\"80176.10\",\"1.565\"],[\"80374.60\",\"1.137\"]],\"st\":1}}"}
{"receive_ns":1788781921713167000,"stream":"btcusdt@depth@100ms","event_type":"depthUpdate","event_time_ms":1788781921782,"raw_json":"{\"stream\":\"btcusdt@depth@100ms\",\"data\":{\"e\":\"depthUpdate\",\"E\":1788781921782,\"T\":1788781921778,\"s\":\"BTCUSDT\",\"ps\":\"BTCUSDT\",\"U\":11496321245268,\"u\":11496321252510,\"pu\":11496321245146,\"b\":[[\"1000.00\",\"24.754\"],[\"28882.20\",\"1.897\"],[\"28982.20\",\"0.049\"],[\"29282.20\",\"0.154\"],[\"63506.00\",\"0.002\"],[\"71443.90\",\"0.002\"],[\"76206.90\",\"0.002\"],[\"77789.30\",\"5.717\"],[\"78032.70\",\"4.351\"],[\"78588.40\",\"0.000\"],[\"78985.20\",\"0.001\"],[\"79150.40\",\"0.015\"],[\"79153.50\",\"0.000\"],[\"79157.20\",\"2.206\"],[\"79161.60\",\"0.000\"],[\"79179.80\",\"1.085\"],[\"79203.00\",\"1.531\"],[\"79207.40\",\"0.000\"],[\"79234.20\",\"0.760\"],[\"79238.60\",\"0.010\"],[\"79259.20\",\"0.000\"],[\"79287.50\",\"0.003\"],[\"79287.60\",\"0.637\"],[\"79292.00\",\"1.207\"],[\"79324.60\",\"0.000\"],[\"79361.10\",\"0.008\"]],\"a\":[[\"79391.00\",\"0.003\"],[\"79400.90\",\"0.254\"],[\"79401.50\",\"0.002\"],[\"79401.90\",\"1.897\"],[\"79402.50\",\"0.441\"],[\"79402.70\",\"0.001\"],[\"79403.10\",\"0.861\"],[\"79555.70\",\"0.126\"],[\"79557.90\",\"0.042\"],[\"79747.50\",\"0.522\"],[\"79779.30\",\"0.002\"],[\"80176.10\",\"1.565\"]],\"st\":1}}"}
{"receive_ns":1788781921813129000,"stream":"btcusdt@depth@100ms","event_type":"depthUpdate","event_time_ms":1788781921884,"raw_json":"{\"stream\":\"btcusdt@depth@100ms\",\"data\":{\"e\":\"depthUpdate\",\"E\":1788781921884,\"T\":1788781921883,\"s\":\"BTCUSDT\",\"ps\":\"BTCUSDT\",\"U\":11496321253052,\"u\":11496321261814,\"pu\":11496321252510,\"b\":[[\"28882.20\",\"1.813\"],[\"28982.20\",\"0.000\"],[\"29282.20\",\"0.287\"],[\"71443.90\",\"0.002\"],[\"76206.90\",\"0.000\"],[\"78588.40\",\"0.000\"],[\"78985.30\",\"0.136\"],[\"79134.10\",\"1.692\"],[\"79150.40\",\"0.000\"],[\"79157.20\",\"0.022\"],[\"79161.60\",\"35.371\"],[\"79203.00\",\"0.002\"],[\"79203.10\",\"0.000\"],[\"79207.40\",\"26.513\"],[\"79234.20\",\"0.000\"],[\"79238.60\",\"17.678\"],[\"79287.60\",\"0.502\"],[\"79292.00\",\"10.035\"],[\"79364.50\",\"0.000\"],[\"79376.70\",\"0.003\"]],\"a\":[[\"79382.30\",\"5.862\"],[\"79418.70\",\"0.007\"],[\"79555.70\",\"0.001\"],[\"79555.90\",\"0.000\"],[\"79747.50\",\"0.981\"],[\"80176.10\",\"1.565\"]],\"st\":1}}"}
{"receive_ns":1788781921916059000,"stream":"btcusdt@depth@100ms","event_type":"depthUpdate","event_time_ms":1788781921986,"raw_json":"{\"stream\":\"btcusdt@depth@100ms\",\"data\":{\"e\":\"depthUpdate\",\"E\":1788781921986,\"T\":1788781921984,\"s\":\"BTCUSDT\",\"ps\":\"BTCUSDT\",\"U\":11496321261921,\"u\":11496321269378,\"pu\":11496321261814,\"b\":[[\"1000.00\",\"24.754\"],[\"28882.20\",\"1.638\"],[\"29282.20\",\"0.462\"],[\"63506.00\",\"0.002\"],[\"71443.90\",\"0.002\"],[\"78306.30\",\"0.995\"],[\"78420.70\",\"4.203\"],[\"78490.20\",\"0.000\"],[\"78588.40\",\"0.002\"],[\"79179.40\",\"3.093\"],[\"79207.50\",\"0.019\"]],\"a\":[[\"79541.10\",\"0.601\"],[\"80176.10\",\"1.565\"],[\"80436.60\",\"2.576\"],[\"80509.50\",\"0.596\"],[\"80964.40\",\"8.082\"]],\"st\":1}}"}
{"receive_ns":1788781922091517000,"stream":"btcusdt@depth@100ms","event_type":"depthUpdate","event_time_ms":1788781922088,"raw_json":"{\"stream\":\"btcusdt@depth@100ms\",\"data\":{\"e\":\"depthUpdate\",\"E\":1788781922088,\"T\":1788781922087,\"s\":\"BTCUSDT\",\"ps\":\"BTCUSDT\",\"U\":11496321269466,\"u\":11496321277050,\"pu\":11496321269378,\"b\":[[\"28882.20\",\"1.456\"],[\"29282.20\",\"0.644\"],[\"55528.00\",\"0.002\"],[\"71443.90\",\"0.002\"],[\"76206.90\",\"0.002\"],[\"78310.50\",\"2.717\"],[\"78588.40\",\"0.000\"],[\"78985.30\",\"0.136\"],[\"79133.00\",\"0.000\"],[\"79134.10\",\"0.664\"],[\"79161.70\",\"0.054\"],[\"79179.80\",\"1.862\"],[\"79347.20\",\"0.000\"],[\"79348.70\",\"0.046\"],[\"79354.10\",\"0.004\"],[\"79356.10\",\"0.454\"],[\"79362.10\",\"0.574\"],[\"79362.90\",\"0.100\"],[\"79363.40\",\"0.650\"],[\"79363.80\",\"0.323\"],[\"79366.50\",\"0.001\"]],\"a\":[[\"79388.60\",\"0.497\"],[\"79390.30\",\"0.151\"],[\"79396.60\",\"0.000\"],[\"79400.50\",\"1.185\"],[\"79402.00\",\"2.492\"],[\"79402.50\",\"0.001\"],[\"79402.90\",\"0.493\"],[\"79405.70\",\"0.453\"],[\"79407.10\",\"0.001\"],[\"79412.40\",\"0.046\"],[\"79413.50\",\"0.049\"],[\"79429.80\",\"0.132\"],[\"79429.90\",\"0.216\"],[\"79541.10\",\"0.599\"],[\"79555.80\",\"0.001\"],[\"79747.50\",\"0.837\"],[\"80170.70\",\"9.516\"],[\"80176.10\",\"1.565\"]],\"st\":1}}"}
{"receive_ns":1788781922118973000,"stream":"btcusdt@depth@100ms","event_type":"depthUpdate","event_time_ms":1788781922190,"raw_json":"{\"stream\":\"btcusdt@depth@100ms\",\"data\":{\"e\":\"depthUpdate\",\"E\":1788781922190,\"T\":1788781922185,\"s\":\"BTCUSDT\",\"ps\":\"BTCUSDT\",\"U\":11496321277133,\"u\":11496321284884,\"pu\":11496321277050,\"b\":[[\"28882.20\",\"1.281\"],[\"29282.20\",\"0.819\"],[\"71443.90\",\"0.002\"],[\"76206.90\",\"0.000\"],[\"78588.40\",\"0.000\"],[\"79134.10\",\"0.664\"],[\"79153.50\",\"0.000\"],[\"79157.30\",\"0.000\"],[\"79161.60\",\"35.371\"],[\"79179.40\",\"3.111\"],[\"79203.20\",\"0.000\"],[\"79207.40\",\"26.513\"],[\"79207.50\",\"0.001\"],[\"79234.30\",\"0.000\"],[\"79238.60\",\"17.678\"],[\"79259.20\",\"0.251\"],[\"79286.90\",\"0.002\"],[\"79287.70\",\"0.212\"],[\"79292.00\",\"10.035\"],[\"79335.90\",\"1.568\"],[\"79336.30\",\"0.040\"],[\"79347.60\",\"0.050\"],[\"79348.70\",\"0.000\"],[\"79349.00\",\"0.000\"],[\"79354.10\",\"0.457\"],[\"79356.10\",\"0.001\"],[\"79358.40\",\"0.034\"],[\"79362.30\",\"0.728\"],[\"79362.90\",\"0.419\"],[\"79363.40\",\"0.083\"],[\"79363.80\",\"0.004\"]],\"a\":[[\"79382.30\",\"5.863\"],[\"79401.50\",\"0.002\"],[\"79401.80\",\"0.488\"],[\"79402.10\",\"0.572\"],[\"79402.20\",\"0.000\"],[\"79402.90\",\"0.053\"],[\"79403.10\",\"0.295\"],[\"79404.50\",\"0.453\"],[\"79405.70\",\"0.000\"],[\"79425.00\",\"0.275\"],[\"79436.30\",\"0.060\"],[\"79444.90\",\"0.000\"],[\"79453.80\",\"0.004\"],[\"79481.30\",\"0.167\"],[\"79747.50\",\"0.981\"],[\"79779.30\",\"0.001\"],[\"80011.90\",\"7.611\"],[\"80176.10\",\"1.565\"],[\"80329.40\",\"32.228\"]],\"st\":1}}"}
{"receive_ns":1788781922221257000,"stream":"btcusdt@depth@100ms","event_type":"depthUpdate","event_time_ms":1788781922292,"raw_json":"{\"stream\":\"btcusdt@depth@100ms\",\"data\":{\"e\":\"depthUpdate\",\"E\":1788781922292,\"T\":1788781922289,\"s\":\"BTCUSDT\",\"ps\":\"BTCUSDT\",\"U\":11496321285228,\"u\":11496321292499,\"pu\":11496321284884,\"b\":[[\"1000.00\",\"24.754\"],[\"28882.20\",\"1.099\"],[\"29282.20\",\"1.001\"],[\"63506.00\",\"0.002\"],[\"71443.90\",\"0.002\"],[\"76206.90\",\"0.002\"],[\"77897.80\",\"0.602\"],[\"78293.50\",\"10.768\"],[\"78509.00\",\"1.276\"],[\"78588.40\",\"0.000\"],[\"78980.40\",\"0.000\"],[\"78980.50\",\"0.020\"],[\"78985.20\",\"0.002\"],[\"79133.00\",\"0.054\"],[\"79134.10\",\"1.341\"],[\"79144.00\",\"0.183\"],[\"79157.40\",\"2.219\"],[\"79161.60\",\"0.000\"],[\"79161.70\",\"0.000\"],[\"79166.20\",\"0.015\"],[\"79179.80\",\"1.085\"],[\"79203.20\",\"1.554\"],[\"79207.40\",\"0.000\"],[\"79234.40\",\"0.776\"],[\"79238.60\",\"0.010\"],[\"79287.80\",\"0.137\"],[\"79292.00\",\"1.207\"],[\"79292.60\",\"0.000\"],[\"79295.90\",\"1.153\"],[\"79322.20\",\"0.004\"],[\"79342.10\",\"0.001\"],[\"79347.60\",\"0.004\"],[\"79349.60\",\"0.046\"],[\"79354.10\",\"0.004\"],[\"79356.10\",\"0.454\"],[\"79362.30\",\"0.161\"],[\"79362.90\",\"0.419\"],[\"79363.40\",\"0.083\"],[\"79363.80\",\"0.004\"],[\"79364.30\",\"0.567\"],[\"79365.20\",\"0.108\"],[\"79367.10\",\"0.442\"]],\"a\":[[\"79382.30\",\"5.867\"],[\"79401.80\",\"0.048\"],[\"79402.10\",\"0.006\"],[\"79402.90\",\"0.053\"],[\"79403.20\",\"0.030\"],[\"79404.00\",\"0.459\"],[\"79404.10\",\"1.586\"],[\"79404.50\",\"0.000\"],[\"79405.70\",\"0.453\"],[\"79412.40\",\"0.000\"],[\"79413.20\",\"0.050\"],[\"79419.70\",\"0.501\"],[\"79439.50\",\"0.000\"],[\"79468.10\",\"0.311\"],[\"79489.70\",\"0.005\"],[\"79747.50\",\"0.916\"],[\"79774.10\",\"0.037\"],[\"79774.20\",\"0.002\"],[\"80176.10\",\"1.565\"]],\"st\":1}}"}
{"receive_ns":1788781922323519000,"stream":"btcusdt@depth@100ms","event_type":"depthUpdate","event_time_ms":1788781922394,"raw_json":"{\"stream\":\"btcusdt@depth@100ms\",\"data\":{\"e\":\"depthUpdate\",\"E\":1788781922394,\"T\":1788781922389,\"s\":\"BTCUSDT\",\"ps\":\"BTCUSDT\",\"U\":11496321292633,\"u\":11496321298832,\"pu\":11496321292499,\"b\":[[\"28882.20\",\"0.924\"],[\"29282.20\",\"1.176\"],[\"63506.00\",\"0.002\"],[\"71443.90\",\"0.002\"],[\"75408.10\",\"0.210\"],[\"78588.40\",\"0.000\"],[\"78985.30\",\"0.136\"],[\"79028.10\",\"0.000\"],[\"79032.00\",\"1.185\"],[\"79134.10\",\"0.902\"],[\"79144.00\",\"0.173\"],[\"79157.40\",\"2.219\"],[\"79161.60\",\"0.000\"],[\"79179.80\",\"1.875\"],[\"79203.20\",\"0.000\"],[\"79203.30\",\"1.554\"],[\"79207.40\",\"0.000\"],[\"79234.40\",\"0.776\"],[\"79238.60\",\"0.010\"],[\"79239.60\",\"3.600\"],[\"79253.00\",\"0.000\"],[\"79254.10\",\"0.022\"],[\"79255.10\",\"2.079\"],[\"79259.20\",\"0.000\"],[\"79283.60\",\"1.285\"],[\"79287.80\",\"0.137\"],[\"79292.00\",\"1.207\"],[\"79292.70\",\"6.001\"],[\"79305.50\",\"0.794\"],[\"79320.40\",\"3.500\"],[\"79340.20\",\"0.972\"],[\"79348.30\",\"0.046\"],[\"79349.60\",\"0.000\"],[\"79362.90\",\"0.100\"],[\"79363.20\",\"0.640\"],[\"79363.80\",\"0.323\"],[\"79364.30\",\"0.000\"],[\"79365.20\",\"0.549\"],[\"79367.10\",\"0.001\"]],\"a\":[[\"79394.20\",\"0.115\"],[\"79402.50\",\"0.441\"],[\"79402.90\",\"0.619\"],[\"79404.00\",\"0.019\"],[\"79404.10\",\"1.020\"],[\"79408.90\",\"1.737\"],[\"79419.70\",\"1.490\"],[\"79420.20\",\"0.002\"],[\"79439.50\",\"3.500\"],[\"79504.40\",\"1.451\"],[\"79507.80\",\"0.000\"],[\"79508.10\",\"0.001\"],[\"79747.50\",\"0.981\"],[\"79836.50\",\"0.494\"],[\"79838.00\",\"0.012\"],[\"80176.10\",\"1.565\"]],\"st\":1}}"}
{"receive_ns":1788781922425870000,"stream":"btcusdt@depth@100ms","event_type":"depthUpdate","event_time_ms":1788781922496,"raw_json":"{\"stream\":\"btcusdt@depth@100ms\",\"data\":{\"e\":\"depthUpdate\",\"E\":1788781922496,\"T\":1788781922494,\"s\":\"BTCUSDT\",\"ps\":\"BTCUSDT\",\"U\":11496321299021,\"u\":11496321303955,\"pu\":11496321298832,\"b\":[[\"28882.20\",\"0.742\"],[\"29282.20\",\"1.358\"],[\"71443.90\",\"0.002\"],[\"75408.10\",\"0.208\"],[\"76206.90\",\"0.000\"],[\"77794.60\",\"1.168\"],[\"78011.50\",\"1.663\"],[\"78588.40\",\"0.000\"],[\"78616.10\",\"0.004\"],[\"78619.10\",\"0.000\"],[\"79134.10\",\"0.125\"],[\"79144.00\",\"0.183\"],[\"79150.40\",\"0.000\"],[\"79157.40\",\"0.000\"],[\"79157.50\",\"2.719\"],[\"79161.60\",\"0.000\"],[\"79201.20\",\"0.875\"],[\"79203.30\",\"1.553\"],[\"79207.40\",\"0.000\"],[\"79234.40\",\"0.004\"],[\"79234.50\",\"0.784\"],[\"79238.60\",\"0.010\"],[\"79239.60\",\"1.103\"],[\"79287.80\",\"0.137\"],[\"79292.00\",\"1.207\"],[\"79335.90\",\"1.567\"],[\"79354.10\",\"0.457\"],[\"79356.10\",\"0.001\"],[\"79362.20\",\"0.071\"],[\"79362.90\",\"0.419\"],[\"79363.20\",\"0.073\"],[\"79363.80\",\"0.004\"],[\"79364.50\",\"0.567\"],[\"79365.20\",\"0.108\"],[\"79367.10\",\"0.442\"],[\"79370.00\",\"0.040\"],[\"79382.20\",\"14.990\"]],\"a\":[[\"79382.30\",\"5.869\"],[\"79401.50\",\"0.002\"],[\"79402.50\",\"0.001\"],[\"79402.60\",\"0.000\"],[\"79402.90\",\"0.053\"],[\"79404.00\",\"0.459\"],[\"79404.30\",\"0.567\"],[\"79409.00\",\"3.200\"],[\"79418.50\",\"0.001\"],[\"79425.90\",\"0.269\"],[\"79433.80\",\"0.003\"],[\"79747.50\",\"0.522\"],[\"80176.10\",\"1.565\"]],\"st\":1}}"}
{"receive_ns":1788781922528686000,"stream":"btcusdt@depth@100ms","event_type":"depthUpdate","event_time_ms":1788781922598,"raw_json":"{\"stream\":\"btcusdt@depth@100ms\",\"data\":{\"e\":\"depthUpdate\",\"E\":1788781922598,\"T\":1788781922597,\"s\":\"BTCUSDT\",\"ps\":\"BTCUSDT\",\"U\":11496321304099,\"u\":11496321309273,\"pu\":11496321303955,\"b\":[[\"1000.00\",\"24.754\"],[\"28882.20\",\"0.567\"],[\"29282.20\",\"1.533\"],[\"63506.00\",\"0.004\"],[\"71443.90\",\"0.002\"],[\"76206.90\",\"0.002\"],[\"78389.90\",\"0.440\"],[\"78486.10\",\"0.015\"],[\"78588.40\",\"0.002\"],[\"78741.80\",\"4.344\"],[\"79144.00\",\"0.173\"],[\"79153.50\",\"0.000\"],[\"79157.50\",\"0.500\"],[\"79161.60\",\"35.371\"],[\"79166.20\",\"0.000\"],[\"79172.60\",\"0.000\"],[\"79179.40\",\"3.093\"],[\"79179.80\",\"2.064\"],[\"79200.80\",\"0.013\"],[\"79201.20\",\"0.868\"],[\"79203.30\",\"0.000\"],[\"79207.40\",\"26.513\"],[\"79207.50\",\"0.019\"],[\"79208.40\",\"4.088\"],[\"79234.50\",\"0.012\"],[\"79238.60\",\"17.678\"],[\"79252.00\",\"10.241\"],[\"79259.20\",\"0.100\"],[\"79286.90\",\"0.000\"],[\"79287.80\",\"0.000\"],[\"79292.00\",\"10.035\"],[\"79298.70\",\"0.057\"],[\"79299.20\",\"0.001\"],[\"79310.70\",\"0.003\"],[\"79324.60\",\"0.488\"],[\"79362.90\",\"0.100\"],[\"79363.30\",\"0.570\"],[\"79363.80\",\"0.323\"],[\"79364.50\",\"0.000\"],[\"79365.20\",\"0.549\"],[\"79367.10\",\"0.001\"],[\"79382.20\",\"14.992\"]],\"a\":[[\"79382.30\",\"5.871\"],[\"79402.60\",\"0.440\"],[\"79402.70\",\"0.970\"],[\"79404.00\",\"0.019\"],[\"79418.60\",\"2.461\"],[\"79437.90\",\"0.243\"],[\"79453.80\",\"0.002\"],[\"79464.20\",\"1.692\"],[\"79467.30\",\"6.000\"],[\"79473.40\",\"0.039\"],[\"79474.00\",\"0.017\"],[\"79507.00\",\"10.000\"],[\"79523.90\",\"0.013\"],[\"79528.20\",\"1.328\"],[\"79529.80\",\"3.149\"],[\"79556.50\",\"0.284\"],[\"79747.50\",\"0.981\"],[\"80176.10\",\"1.565\"],[\"80311.40\",\"0.003\"],[\"80550.00\",\"3.739\"]],\"st\":1}}"}
{"receive_ns":1788781922629397000,"stream":"btcusdt@depth@100ms","event_type":"depthUpdate","event_time_ms":1788781922700,"raw_json":"{\"stream\":\"btcusdt@depth@100ms\",\"data\":{\"e\":\"depthUpdate\",\"E\":1788781922700,\"T\":1788781922697,\"s\":\"BTCUSDT\",\"ps\":\"BTCUSDT\",\"U\":11496321309312,\"u\":11496321314788,\"pu\":11496321309273,\"b\":[[\"28882.20\",\"0.385\"],[\"29282.20\",\"1.715\"],[\"63505.80\",\"0.000\"],[\"63506.00\",\"0.002\"],[\"71443.90\",\"0.002\"],[\"76206.90\",\"0.000\"],[\"78588.40\",\"0.000\"],[\"78741.80\",\"4.090\"],[\"78985.30\",\"0.136\"],[\"79153.50\",\"0.020\"],[\"79157.50\",\"0.500\"],[\"79161.60\",\"35.371\"],[\"79179.80\",\"1.965\"],[\"79203.40\",\"0.000\"],[\"79207.40\",\"26.513\"],[\"79234.50\",\"0.012\"],[\"79238.60\",\"17.678\"],[\"79287.90\",\"0.017\"],[\"79292.00\",\"10.035\"],[\"79324.60\",\"0.587\"],[\"79332.00\",\"0.007\"],[\"79336.00\",\"0.116\"],[\"79336.50\",\"0.161\"],[\"79361.10\",\"0.006\"],[\"79362.30\",\"0.728\"],[\"79362.90\",\"0.419\"],[\"79363.30\",\"0.003\"],[\"79363.80\",\"0.004\"],[\"79365.20\",\"0.549\"],[\"79365.30\",\"0.267\"],[\"79367.10\",\"0.001\"],[\"79367.50\",\"0.026\"],[\"79370.00\",\"0.006\"]],\"a\":[[\"79382.30\",\"5.874\"],[\"79400.90\",\"0.252\"],[\"79402.00\",\"2.492\"],[\"79402.60\",\"0.000\"],[\"79402.80\",\"0.003\"],[\"79403.20\",\"0.030\"],[\"79404.00\",\"0.459\"],[\"79404.20\",\"0.567\"],[\"79404.30\",\"0.001\"],[\"79435.70\",\"0.097\"],[\"79556.10\",\"0.003\"],[\"79747.50\",\"0.981\"],[\"80176.10\",\"1.565\"],[\"80454.00\",\"0.496\"],[\"80492.00\",\"3.697\"],[\"80509.50\",\"0.745\"],[\"81349.10\",\"0.368\"]],\"st\":1}}"}
{"receive_ns":1788781922731846000,"stream":"btcusdt@depth@100ms","event_type":"depthUpdate","event_time_ms":1788781922802,"raw_json":"{\"stream\":\"btcusdt@depth@100ms\",\"data\":{\"e\":\"depthUpdate\",\"E\":1788781922802,\"T\":1788781922801,\"s\":\"BTCUSDT\",\"ps\":\"BTCUSDT\",\"U\":11496321314985,\"u\":11496321320594,\"pu\":11496321314788,\"b\":[[\"28882.20\",\"0.252\"],[\"29182.20\",\"0.049\"],[\"29282.20\",\"1.799\"],[\"63492.00\",\"0.000\"],[\"63501.00\",\"0.003\"],[\"63502.00\",\"0.004\"],[\"71443.90\",\"0.002\"],[\"76206.90\",\"0.002\"],[\"77789.30\",\"5.714\"],[\"78424.30\",\"32.468\"],[\"78588.40\",\"0.000\"],[\"78985.20\",\"0.001\"],[\"79133.00\",\"0.000\"],[\"79134.10\",\"0.902\"],[\"79153.50\",\"0.020\"],[\"79157.60\",\"2.255\"],[\"79161.60\",\"0.000\"],[\"79161.70\",\"0.054\"],[\"79179.80\",\"1.525\"],[\"79203.40\",\"1.553\"],[\"79207.40\",\"0.000\"],[\"79234.60\",\"1.110\"],[\"79238.60\",\"0.010\"],[\"79259.20\",\"0.000\"],[\"79287.90\",\"0.154\"],[\"79292.00\",\"1.207\"],[\"79324.60\",\"0.099\"],[\"79361.10\",\"0.008\"],[\"79367.50\",\"0.000\"]],\"a\":[[\"79382.30\",\"5.875\"],[\"79400.90\",\"0.254\"],[\"79401.50\",\"0.442\"],[\"79404.00\",\"0.019\"],[\"79555.80\",\"0.001\"],[\"79747.50\",\"0.837\"],[\"80176.10\",\"1.565\"],[\"80311.10\",\"0.464\"],[\"80317.60\",\"12.062\"],[\"80549.20\",\"1.735\"]],\"st\":1}}"}
{"receive_ns":1788781922840597000,"stream":"btcusdt@depth@100ms","event_type":"depthUpdate","event_time_ms":1788781922904,"raw_json":"{\"stream\":\"btcusdt@depth@100ms\",\"data\":{\"e\":\"depthUpdate\",\"E\":1788781922904,\"T\":1788781922901,\"s\":\"BTCUSDT\",\"ps\":\"BTCUSDT\",\"U\":11496321320671,\"u\":11496321326293,\"pu\":11496321320594,\"b\":[[\"1000.00\",\"24.754\"],[\"28882.20\",\"0.133\"],[\"29182.20\",\"0.105\"],[\"29282.20\",\"1.862\"],[\"63506.00\",\"0.004\"],[\"71443.90\",\"0.002\"],[\"75413.10\",\"0.004\"],[\"77932.30\",\"1.282\"],[\"78237.90\",\"4.082\"],[\"78279.10\",\"0.001\"],[\"78571.40\",\"1.977\"],[\"78588.40\",\"0.000\"],[\"79153.50\",\"0.000\"],[\"79157.60\",\"0.036\"],[\"79161.60\",\"35.371\"],[\"79179.80\",\"1.525\"],[\"79203.40\",\"0.000\"],[\"79207.40\",\"26.513\"],[\"79234.60\",\"0.338\"],[\"79238.60\",\"17.678\"],[\"79287.90\",\"0.017\"],[\"79292.00\",\"10.035\"],[\"79324.60\",\"0.350\"],[\"79350.00\",\"6.077\"],[\"79382.20\",\"14.994\"]],\"a\":[[\"79382.30\",\"5.679\"],[\"79394.90\",\"0.231\"],[\"79401.50\",\"0.002\"],[\"79402.60\",\"0.440\"],[\"79402.70\",\"0.000\"],[\"79556.10\",\"0.003\"],[\"79556.90\",\"0.553\"],[\"79747.50\",\"0.981\"],[\"79779.30\",\"0.002\"],[\"80176.10\",\"1.565\"],[\"80357.10\",\"13.812\"]],\"st\":1}}"}
{"receive_ns":1788781922935570000,"stream":"btcusdt@depth@100ms","event_type":"depthUpdate","event_time_ms":1788781923006,"raw_json":"{\"stream\":\"btcusdt@depth@100ms\",\"data\":{\"e\":\"depthUpdate\",\"E\":1788781923006,\"T\":1788781923005,\"s\":\"BTCUSDT\",\"ps\":\"BTCUSDT\",\"U\":11496321326421,\"u\":11496321331750,\"pu\":11496321326293,\"b\":[[\"28882.20\",\"0.021\"],[\"29182.20\",\"0.168\"],[\"29282.20\",\"1.911\"],[\"63506.00\",\"0.002\"],[\"71443.90\",\"0.002\"],[\"75408.10\",\"0.206\"],[\"75413.10\",\"0.002\"],[\"75413.20\",\"0.002\"],[\"76206.90\",\"0.000\"],[\"78571.40\",\"1.024\"],[\"78588.40\",\"0.000\"],[\"78985.30\",\"0.136\"],[\"79134.10\",\"0.400\"],[\"79153.50\",\"0.020\"],[\"79157.60\",\"2.255\"],[\"79161.60\",\"0.000\"],[\"79203.50\",\"1.801\"],[\"79207.40\",\"0.000\"],[\"79234.60\",\"1.110\"],[\"79238.60\",\"0.010\"],[\"79288.00\",\"0.159\"],[\"79292.00\",\"1.207\"],[\"79322.50\",\"0.070\"],[\"79332.00\",\"0.007\"],[\"79362.30\",\"0.161\"],[\"79362.90\",\"0.415\"],[\"79363.30\",\"0.570\"]],\"a\":[[\"79402.80\",\"0.002\"],[\"79403.10\",\"0.861\"],[\"79404.20\",\"0.001\"],[\"79541.10\",\"0.599\"],[\"79556.40\",\"0.003\"],[\"79747.50\",\"0.699\"],[\"80176.10\",\"1.567\"]],\"st\":1}}"}
{"receive_ns":1788781923038654000,"stream":"btcusdt@depth@100ms","event_type":"depthUpdate","event_time_ms":1788781923108,"raw_json":"{\"stream\":\"btcusdt@depth@100ms\",\"data\":{\"e\":\"depthUpdate\",\"E\":1788781923108,\"T\":1788781923105,\"s\":\"BTCUSDT\",\"ps\":\"BTCUSDT\",\"U\":11496321331756,\"u\":11496321341386,\"pu\":11496321331750,\"b\":[[\"1000.00\",\"24.754\"],[\"28882.20\",\"0.000\"],[\"29182.20\",\"0.329\"],[\"29282.20\",\"1.771\"],[\"63506.00\",\"0.004\"],[\"71443.90\",\"0.002\"],[\"76206.90\",\"0.002\"],[\"78278.80\",\"1.277\"],[\"78588.40\",\"0.000\"],[\"78833.00\",\"0.131\"],[\"78835.50\",\"1.020\"],[\"78985.30\",\"0.262\"],[\"79006.80\",\"0.000\"],[\"79007.90\",\"0.409\"],[\"79125.50\",\"0.001\"],[\"79128.00\",\"1.061\"],[\"79134.10\",\"0.125\"],[\"79153.50\",\"0.015\"],[\"79157.60\",\"0.036\"],[\"79157.70\",\"2.224\"],[\"79161.60\",\"0.000\"],[\"79179.40\",\"3.111\"],[\"79179.80\",\"1.625\"],[\"79203.50\",\"1.804\"],[\"79207.40\",\"0.000\"],[\"79207.50\",\"0.001\"],[\"79234.60\",\"0.338\"],[\"79234.70\",\"0.775\"],[\"79238.60\",\"0.010\"],[\"79259.20\",\"0.187\"],[\"79288.00\",\"0.159\"],[\"79292.00\",\"1.207\"],[\"79324.60\",\"0.301\"],[\"79354.10\",\"0.004\"],[\"79355.90\",\"0.497\"],[\"79362.90\",\"0.419\"],[\"79363.10\",\"0.669\"],[\"79363.30\",\"0.003\"],[\"79363.80\",\"0.004\"],[\"79364.30\",\"0.000\"],[\"79365.20\",\"0.549\"],[\"79365.30\",\"0.191\"],[\"79367.10\",\"0.001\"]],\"a\":[[\"79382.30\",\"5.686\"],[\"79396.60\",\"0.000\"],[\"79402.60\",\"0.000\"],[\"79402.90\",\"1.059\"],[\"79403.10\",\"0.295\"],[\"79404.00\",\"0.019\"],[\"79404.10\",\"1.020\"],[\"79556.30\",\"0.123\"],[\"79556.70\",\"0.000\"],[\"79556.80\",\"0.125\"],[\"79628.30\",\"2.750\"],[\"79629.30\",\"0.125\"],[\"79747.50\",\"0.497\"],[\"79748.60\",\"1.216\"],[\"79748.70\",\"0.000\"],[\"79777.20\",\"0.169\"],[\"79924.20\",\"0.000\"],[\"80176.10\",\"1.565\"],[\"80342.90\",\"2.488\"],[\"80969.90\",\"1.745\"]],\"st\":1}}"}
{"receive_ns":1788781923138967000,"stream":"btcusdt@depth@100ms","event_type":"depthUpdate","event_time_ms":1788781923210,"raw_json":"{\"stream\":\"btcusdt@depth@100ms\",\"data\":{\"e\":\"depthUpdate\",\"E\":1788781923210,\"T\":1788781923209,\"s\":\"BTCUSDT\",\"ps\":\"BTCUSDT\",\"U\":11496321341640,\"u\":11496321348730,\"pu\":11496321341386,\"b\":[[\"1000.00\",\"24.754\"],[\"29182.20\",\"0.504\"],[\"29282.20\",\"1.596\"],[\"63506.00\",\"0.002\"],[\"71443.90\",\"0.002\"],[\"76206.90\",\"0.000\"],[\"78361.30\",\"0.000\"],[\"78588.40\",\"0.000\"],[\"78620.20\",\"0.315\"],[\"79104.40\",\"0.502\"],[\"79153.50\",\"0.015\"],[\"79157.70\",\"2.223\"],[\"79161.60\",\"0.000\"],[\"79203.50\",\"1.804\"],[\"79207.40\",\"0.000\"],[\"79234.70\",\"0.774\"],[\"79238.60\",\"0.010\"],[\"79288.00\",\"0.022\"],[\"79288.10\",\"0.137\"],[\"79292.00\",\"1.207\"],[\"79320.00\",\"2.615\"],[\"79324.60\",\"0.338\"],[\"79343.80\",\"0.001\"],[\"79362.90\",\"0.100\"],[\"79363.80\",\"0.323\"],[\"79365.30\",\"0.267\"],[\"79367.20\",\"0.027\"],[\"79369.90\",\"0.032\"],[\"79382.20\",\"15.244\"]],\"a\":[[\"79394.20\",\"0.113\"],[\"79413.60\",\"0.259\"],[\"79556.10\",\"0.128\"],[\"79556.80\",\"0.000\"],[\"79620.50\",\"0.398\"],[\"79773.30\",\"0.034\"],[\"79777.20\",\"0.476\"],[\"80176.10\",\"1.565\"],[\"80454.00\",\"1.116\"],[\"80731.80\",\"0.866\"]],\"st\":1}}"}
{"receive_ns":1788781923240901000,"stream":"btcusdt@depth@100ms","event_type":"depthUpdate","event_time_ms":1788781923312,"raw_json":"{\"stream\":\"btcusdt@depth@100ms\",\"data\":{\"e\":\"depthUpdate\",\"E\":1788781923312,\"T\":1788781923309,\"s\":\"BTCUSDT\",\"ps\":\"BTCUSDT\",\"U\":11496321348750,\"u\":11496321354332,\"pu\":11496321348730,\"b\":[[\"29182.20\",\"0.686\"],[\"29282.20\",\"1.414\"],[\"55528.00\",\"0.000\"],[\"63506.00\",\"0.004\"],[\"71443.90\",\"0.002\"],[\"76206.90\",\"0.002\"],[\"78406.70\",\"0.637\"],[\"78487.90\",\"3.023\"],[\"78588.40\",\"1.271\"],[\"78816.10\",\"3.241\"],[\"78833.10\",\"0.014\"],[\"78835.50\",\"0.000\"],[\"78838.20\",\"0.002\"],[\"78838.50\",\"54.597\"],[\"78838.60\",\"8.403\"],[\"78985.20\",\"0.000\"],[\"78985.30\",\"0.262\"],[\"79012.30\",\"43.597\"],[\"79131.00\",\"35.673\"],[\"79131.30\",\"5.570\"],[\"79153.50\",\"0.000\"],[\"79157.70\",\"0.001\"],[\"79161.60\",\"35.371\"],[\"79179.80\",\"1.750\"],[\"79203.50\",\"0.248\"],[\"79207.40\",\"26.513\"],[\"79234.70\",\"0.001\"],[\"79238.60\",\"17.678\"],[\"79259.20\",\"0.000\"],[\"79288.10\",\"0.000\"],[\"79292.00\",\"10.035\"],[\"79324.60\",\"0.400\"],[\"79347.50\",\"0.047\"],[\"79348.30\",\"0.000\"],[\"79354.10\",\"0.004\"],[\"79355.90\",\"0.044\"],[\"79356.10\",\"0.454\"],[\"79358.40\",\"0.034\"],[\"79362.20\",\"0.638\"],[\"79362.90\",\"0.419\"],[\"79363.10\",\"0.102\"],[\"79363.80\",\"0.004\"]],\"a\":[[\"79401.50\",\"0.002\"],[\"79402.00\",\"2.492\"],[\"79402.90\",\"0.493\"],[\"79403.10\",\"0.861\"],[\"79404.50\",\"0.000\"],[\"79405.70\",\"0.453\"],[\"79411.10\",\"0.003\"],[\"79412.20\",\"0.046\"],[\"79413.20\",\"0.004\"],[\"79556.10\",\"0.003\"],[\"79632.90\",\"6.006\"],[\"79635.20\",\"36.079\"],[\"79744.90\",\"0.260\"],[\"79747.50\",\"0.038\"],[\"79748.60\",\"0.568\"],[\"79753.40\",\"0.603\"],[\"79754.70\",\"46.012\"],[\"79777.20\",\"0.332\"],[\"79924.10\",\"0.000\"],[\"79999.90\",\"1.599\"],[\"80050.80\",\"3.240\"],[\"80139.90\",\"0.147\"],[\"80157.50\",\"0.003\"],[\"80176.10\",\"1.565\"],[\"80402.80\",\"0.000\"]],\"st\":1}}"}
{"receive_ns":1788781923344147000,"stream":"btcusdt@depth@100ms","event_type":"depthUpdate","event_time_ms":1788781923414,"raw_json":"{\"stream\":\"btcusdt@depth@100ms\",\"data\":{\"e\":\"depthUpdate\",\"E\":1788781923414,\"T\":1788781923410,\"s\":\"BTCUSDT\",\"ps\":\"BTCUSDT\",\"U\":11496321354445,\"u\":11496321360592,\"pu\":11496321354332,\"b\":[[\"1000.00\",\"24.754\"],[\"29182.20\",\"0.861\"],[\"29282.20\",\"1.239\"],[\"71443.90\",\"0.002\"],[\"78253.80\",\"30.511\"],[\"78366.20\",\"89.215\"],[\"78588.40\",\"2.542\"],[\"78625.60\",\"71.023\"],[\"79104.40\",\"0.000\"],[\"79133.00\",\"0.054\"],[\"79134.10\",\"0.187\"],[\"79153.50\",\"0.000\"],[\"79157.70\",\"0.001\"],[\"79157.80\",\"2.229\"],[\"79161.60\",\"0.000\"],[\"79161.70\",\"0.000\"],[\"79163.20\",\"5.901\"],[\"79179.40\",\"3.093\"],[\"79179.80\",\"2.190\"],[\"79203.60\",\"1.557\"],[\"79207.40\",\"0.000\"],[\"79207.50\",\"4.094\"],[\"79234.70\",\"0.001\"],[\"79234.80\",\"0.774\"],[\"79238.60\",\"0.010\"],[\"79255.10\",\"2.893\"],[\"79288.10\",\"0.000\"],[\"79288.20\",\"0.188\"],[\"79292.00\",\"1.207\"],[\"79295.90\",\"3.167\"],[\"79324.60\",\"0.400\"],[\"79346.40\",\"0.002\"],[\"79347.50\",\"0.001\"],[\"79347.90\",\"2.404\"],[\"79348.30\",\"0.046\"],[\"79349.60\",\"0.000\"],[\"79362.20\",\"0.071\"],[\"79362.90\",\"0.100\"],[\"79363.10\",\"0.669\"],[\"79363.80\",\"0.323\"],[\"79364.30\",\"0.000\"],[\"79365.20\",\"0.549\"],[\"79365.90\",\"0.013\"],[\"79367.10\",\"0.001\"],[\"79371.90\",\"0.018\"],[\"79378.20\",\"0.547\"],[\"79382.20\",\"15.802\"]],\"a\":[[\"79402.90\",\"0.493\"],[\"79403.10\",\"0.295\"],[\"79404.00\",\"0.019\"],[\"79404.10\",\"1.586\"],[\"79405.70\",\"0.000\"],[\"79406.60\",\"0.457\"],[\"79412.20\",\"0.000\"],[\"79413.20\",\"0.050\"],[\"79414.50\",\"0.000\"],[\"79414.60\",\"0.126\"],[\"79418.60\",\"1.297\"],[\"79420.00\",\"1.510\"],[\"79421.20\",\"0.015\"],[\"79504.40\",\"2.758\"],[\"79580.20\",\"0.018\"],[\"79753.40\",\"0.943\"],[\"79773.30\",\"0.001\"],[\"79777.20\",\"0.025\"],[\"79779.30\",\"0.003\"],[\"80170.70\",\"8.270\"],[\"80176.10\",\"2.810\"],[\"80492.00\",\"3.548\"]],\"st\":1}}"}
{"receive_ns":1788781923446644000,"stream":"btcusdt@depth@100ms","event_type":"depthUpdate","event_time_ms":1788781923516,"raw_json":"{\"stream\":\"btcusdt@depth@100ms\",\"data\":{\"e\":\"depthUpdate\",\"E\":1788781923516,\"T\":1788781923515,\"s\":\"BTCUSDT\",\"ps\":\"BTCUSDT\",\"U\":11496321360756,\"u\":11496321366657,\"pu\":11496321360592,\"b\":[[\"1000.00\",\"24.754\"],[\"29182.20\",\"1.043\"],[\"29282.20\",\"1.057\"],[\"71443.90\",\"0.002\"],[\"75413.10\",\"0.004\"],[\"76206.90\",\"0.000\"],[\"77794.60\",\"1.171\"],[\"78389.90\",\"0.631\"],[\"78588.40\",\"2.542\"],[\"78666.30\",\"0.000\"],[\"78671.70\",\"0.019\"],[\"78863.00\",\"0.126\"],[\"78868.40\",\"0.008\"],[\"79060.10\",\"0.000\"],[\"79065.50\",\"0.004\"],[\"79153.50\",\"0.008\"],[\"79156.70\",\"0.033\"],[\"79163.20\",\"0.715\"],[\"79179.80\",\"1.625\"],[\"79207.50\",\"0.019\"],[\"79257.50\",\"0.922\"],[\"79257.80\",\"0.000\"],[\"79258.40\",\"0.425\"],[\"79263.20\",\"0.002\"],[\"79295.90\",\"1.153\"],[\"79322.50\",\"0.073\"],[\"79324.60\",\"0.037\"],[\"79332.00\",\"0.004\"],[\"79347.80\",\"0.242\"],[\"79347.90\",\"0.122\"],[\"79353.80\",\"0.652\"],[\"79353.90\",\"3.827\"],[\"79354.10\",\"0.457\"],[\"79356.10\",\"0.001\"],[\"79362.20\",\"0.638\"],[\"79362.90\",\"0.419\"],[\"79363.10\",\"0.102\"],[\"79363.80\",\"0.004\"],[\"79365.20\",\"0.108\"],[\"79365.90\",\"0.003\"],[\"79367.10\",\"0.442\"],[\"79371.90\",\"0.028\"]],\"a\":[[\"79382.30\",\"5.186\"],[\"79383.00\",\"0.500\"],[\"79383.80\",\"0.002\"],[\"79383.90\",\"0.005\"],[\"79386.30\",\"0.043\"],[\"79389.20\",\"0.002\"],[\"79389.90\",\"0.007\"],[\"79401.50\",\"0.002\"],[\"79402.00\",\"2.492\"],[\"79402.90\",\"0.053\"],[\"79403.10\",\"0.295\"],[\"79404.00\",\"0.459\"],[\"79404.10\",\"1.586\"],[\"79411.10\",\"0.003\"],[\"79412.40\",\"0.046\"],[\"79413.20\",\"0.004\"],[\"79420.40\",\"8.283\"],[\"79495.90\",\"1.091\"],[\"79501.30\",\"0.002\"],[\"79504.30\",\"0.442\"],[\"79694.60\",\"0.196\"],[\"79700.10\",\"0.909\"],[\"79753.40\",\"0.405\"],[\"79893.90\",\"0.154\"],[\"79899.30\",\"0.008\"],[\"80093.60\",\"0.029\"],[\"80099.10\",\"0.016\"],[\"80136.40\",\"0.560\"],[\"80176.10\",\"2.810\"],[\"80240.70\",\"0.005\"],[\"80549.50\",\"5.022\"],[\"80969.90\",\"1.742\"]],\"st\":1}}"}
{"receive_ns":1788781923547644000,"stream":"btcusdt@depth@100ms","event_type":"depthUpdate","event_time_ms":1788781923618,"raw_json":"{\"stream\":\"btcusdt@depth@100ms\",\"data\":{\"e\":\"depthUpdate\",\"E\":1788781923618,\"T\":1788781923616,\"s\":\"BTCUSDT\",\"ps\":\"BTCUSDT\",\"U\":11496321366746,\"u\":11496321372695,\"pu\":11496321366657,\"b\":[[\"29182.20\",\"1.218\"],[\"29282.20\",\"0.882\"],[\"63506.00\",\"0.004\"],[\"71443.90\",\"0.002\"],[\"76206.90\",\"0.002\"],[\"78310.50\",\"3.226\"],[\"78588.30\",\"0.004\"],[\"78588.40\",\"2.542\"],[\"78612.50\",\"0.003\"],[\"78816.10\",\"0.001\"],[\"78838.60\",\"11.643\"],[\"78985.30\",\"0.262\"],[\"79134.10\",\"1.215\"],[\"79157.80\",\"0.007\"],[\"79161.60\",\"35.371\"],[\"79179.40\",\"3.111\"],[\"79179.80\",\"1.085\"],[\"79203.60\",\"0.002\"],[\"79207.40\",\"26.513\"],[\"79207.50\",\"0.001\"],[\"79234.80\",\"0.001\"],[\"79238.60\",\"17.678\"],[\"79288.20\",\"0.051\"],[\"79292.00\",\"10.035\"],[\"79322.50\",\"0.070\"],[\"79324.60\",\"0.000\"],[\"79335.30\",\"0.050\"],[\"79347.70\",\"0.005\"],[\"79347.80\",\"0.241\"],[\"79365.20\",\"0.549\"],[\"79365.90\",\"0.003\"],[\"79366.40\",\"0.076\"],[\"79367.10\",\"0.001\"],[\"79369.30\",\"0.032\"],[\"79371.90\",\"0.028\"],[\"79377.60\",\"0.005\"]],\"a\":[[\"79382.30\",\"5.124\"],[\"79389.20\",\"0.000\"],[\"79390.20\",\"0.002\"],[\"79392.70\",\"0.038\"],[\"79401.50\",\"0.002\"],[\"79402.90\",\"0.493\"],[\"79404.00\",\"0.989\"],[\"79404.10\",\"1.587\"],[\"79414.90\",\"3.106\"],[\"79419.80\",\"1.164\"],[\"79555.40\",\"0.002\"],[\"79556.00\",\"1.261\"],[\"79753.40\",\"0.636\"],[\"79754.60\",\"0.660\"],[\"79999.90\",\"0.951\"],[\"80176.10\",\"2.810\"],[\"80449.60\",\"1.376\"],[\"87320.60\",\"0.000\"]],\"st\":1}}"}
{"receive_ns":1788781923647454000,"stream":"btcusdt@depth@100ms","event_type":"depthUpdate","event_time_ms":1788781923720,"raw_json":"{\"stream\":\"btcusdt@depth@100ms\",\"data\":{\"e\":\"depthUpdate\",\"E\":1788781923720,\"T\":1788781923717,\"s\":\"BTCUSDT\",\"ps\":\"BTCUSDT\",\"U\":11496321372809,\"u\":11496321378787,\"pu\":11496321372695,\"b\":[[\"1000.00\",\"24.754\"],[\"29182.20\",\"1.400\"],[\"29282.20\",\"0.700\"],[\"63505.80\",\"0.000\"],[\"71443.90\",\"0.002\"],[\"76206.90\",\"0.000\"],[\"78506.90\",\"1.590\"],[\"78588.40\",\"2.542\"],[\"79153.50\",\"0.000\"],[\"79156.70\",\"0.013\"],[\"79172.60\",\"0.020\"],[\"79179.80\",\"1.525\"],[\"79324.60\",\"0.037\"],[\"79332.80\",\"0.003\"]],\"a\":[[\"79393.50\",\"0.180\"],[\"79413.60\",\"0.253\"],[\"79753.40\",\"0.943\"],[\"79977.70\",\"2.345\"],[\"80176.10\",\"4.056\"],[\"80454.00\",\"1.737\"],[\"80549.20\",\"2.168\"]],\"st\":1}}"}
{"receive_ns":1788781923755588000,"stream":"btcusdt@depth@100ms","event_type":"depthUpdate","event_time_ms":1788781923822,"raw_json":"{\"stream\":\"btcusdt@depth@100ms\",\"data\":{\"e\":\"depthUpdate\",\"E\":1788781923822,\"T\":1788781923820,\"s\":\"BTCUSDT\",\"ps\":\"BTCUSDT\",\"U\":11496321379017,\"u\":11496321384840,\"pu\":11496321378787,\"b\":[[\"1000.00\",\"24.754\"],[\"29182.20\",\"1.575\"],[\"29282.20\",\"0.525\"],[\"71443.90\",\"0.002\"],[\"75413.10\",\"0.006\"],[\"78168.60\",\"0.014\"],[\"78429.60\",\"2.934\"],[\"78588.40\",\"2.542\"],[\"78612.20\",\"0.545\"],[\"78730.00\",\"26.096\"],[\"79134.10\",\"1.153\"],[\"79150.40\",\"0.008\"],[\"79157.90\",\"2.228\"],[\"79161.60\",\"0.000\"],[\"79179.40\",\"3.093\"],[\"79203.70\",\"1.566\"],[\"79207.40\",\"0.000\"],[\"79207.50\",\"0.019\"],[\"79234.90\",\"0.775\"],[\"79238.60\",\"0.010\"],[\"79288.30\",\"0.766\"],[\"79292.00\",\"1.207\"],[\"79310.70\",\"0.001\"],[\"79342.50\",\"0.002\"],[\"79361.10\",\"0.008\"]],\"a\":[[\"79400.90\",\"0.254\"],[\"79422.00\",\"0.364\"],[\"79555.60\",\"0.125\"],[\"79753.40\",\"0.910\"],[\"80176.10\",\"4.056\"]],\"st\":1}}"}
{"receive_ns":1788781923854785000,"stream":"btcusdt@depth@100ms","event_type":"depthUpdate","event_time_ms":1788781923924,"raw_json":"{\"stream\":\"btcusdt@depth@100ms\",\"data\":{\"e\":\"depthUpdate\",\"E\":1788781923924,\"T\":1788781923921,\"s\":\"BTCUSDT\",\"ps\":\"BTCUSDT\",\"U\":11496321384957,\"u\":11496321391114,\"pu\":11496321384840,\"b\":[[\"29182.20\",\"1.757\"],[\"29282.20\",\"0.343\"],[\"71443.90\",\"0.002\"],[\"76206.90\",\"0.002\"],[\"78588.40\",\"2.542\"],[\"78985.20\",\"0.001\"],[\"78985.30\",\"0.252\"],[\"79134.10\",\"1.630\"],[\"79150.40\",\"0.008\"],[\"79157.90\",\"2.228\"],[\"79161.60\",\"0.000\"],[\"79179.40\",\"3.111\"],[\"79179.80\",\"1.085\"],[\"79203.70\",\"0.007\"],[\"79203.80\",\"2.567\"],[\"79207.40\",\"0.000\"],[\"79207.50\",\"0.001\"],[\"79234.90\",\"0.775\"],[\"79238.60\",\"0.010\"],[\"79258.40\",\"0.000\"],[\"79259.20\",\"0.062\"],[\"79288.30\",\"0.766\"],[\"79292.00\",\"1.207\"],[\"79322.50\",\"0.073\"],[\"79324.60\",\"0.000\"],[\"79332.80\",\"0.000\"]],\"a\":[[\"79382.30\",\"5.123\"],[\"79383.90\",\"0.004\"],[\"79384.30\",\"0.002\"],[\"79504.30\",\"0.008\"],[\"79555.60\",\"0.000\"],[\"79753.40\",\"0.943\"],[\"79779.30\",\"0.002\"],[\"80176.10\",\"4.056\"],[\"80516.00\",\"1.860\"]],\"st\":1}}"}
{"receive_ns":1788781923962579000,"stream":"btcusdt@depth@100ms","event_type":"depthUpdate","event_time_ms":1788781924026,"raw_json":"{\"stream\":\"btcusdt@depth@100ms\",\"data\":{\"e\":\"depthUpdate\",\"E\":1788781924026,\"T\":1788781924025,\"s\":\"BTCUSDT\",\"ps\":\"BTCUSDT\",\"U\":11496321391272,\"u\":11496321397491,\"pu\":11496321391114,\"b\":[[\"1000.00\",\"24.754\"],[\"29082.20\",\"0.063\"],[\"29182.20\",\"1.813\"],[\"29282.20\",\"0.224\"],[\"71443.90\",\"0.002\"],[\"76206.90\",\"0.000\"],[\"78372.80\",\"16.816\"],[\"78588.40\",\"2.542\"],[\"78747.10\",\"3.678\"],[\"78979.90\",\"4.234\"],[\"79134.10\",\"0.602\"],[\"79150.40\",\"0.000\"],[\"79157.90\",\"0.001\"],[\"79161.60\",\"35.371\"],[\"79179.80\",\"1.197\"],[\"79203.80\",\"1.008\"],[\"79207.40\",\"26.513\"],[\"79234.90\",\"0.000\"],[\"79238.60\",\"17.678\"],[\"79258.50\",\"0.425\"],[\"79288.30\",\"0.628\"],[\"79292.00\",\"10.035\"],[\"79322.50\",\"0.070\"],[\"79332.80\",\"0.003\"],[\"79362.20\",\"0.071\"],[\"79362.90\",\"0.415\"],[\"79363.30\",\"0.570\"],[\"79363.80\",\"0.008\"],[\"79377.60\",\"0.003\"]],\"a\":[[\"79418.50\",\"0.003\"],[\"79434.80\",\"0.047\"],[\"79504.30\",\"0.442\"],[\"79541.10\",\"0.599\"],[\"79556.00\",\"1.261\"],[\"79753.40\",\"0.403\"],[\"80176.10\",\"4.056\"],[\"80567.10\",\"0.000\"]],\"st\":1}}"}
{"receive_ns":1788781924054373000,"stream":"btcusdt@depth@100ms","event_type":"depthUpdate","event_time_ms":1788781924128,"raw_json":"{\"stream\":\"btcusdt@depth@100ms\",\"data\":{\"e\":\"depthUpdate\",\"E\":1788781924128,\"T\":1788781924126,\"s\":\"BTCUSDT\",\"ps\":\"BTCUSDT\",\"U\":11496321397544,\"u\":11496321408455,\"pu\":11496321397491,\"b\":[[\"1000.00\",\"24.754\"],[\"29082.20\",\"0.119\"],[\"29182.20\",\"1.876\"],[\"29282.20\",\"0.105\"],[\"71443.90\",\"0.002\"],[\"76206.90\",\"0.002\"],[\"77794.60\",\"1.168\"],[\"78310.50\",\"3.481\"],[\"78588.40\",\"2.542\"],[\"79134.10\",\"0.125\"],[\"79158.00\",\"2.247\"],[\"79161.60\",\"0.000\"],[\"79179.40\",\"3.093\"],[\"79179.80\",\"2.113\"],[\"79203.80\",\"2.566\"],[\"79207.40\",\"0.000\"],[\"79207.50\",\"0.019\"],[\"79235.00\",\"0.776\"],[\"79238.60\",\"0.010\"],[\"79259.20\",\"0.062\"],[\"79288.40\",\"0.602\"],[\"79292.00\",\"1.207\"],[\"79354.10\",\"0.004\"],[\"79356.10\",\"0.454\"],[\"79362.90\",\"0.100\"],[\"79363.80\",\"0.323\"],[\"79382.20\",\"15.808\"]],\"a\":[[\"79390.30\",\"0.169\"],[\"79396.60\",\"0.000\"],[\"79403.00\",\"1.232\"],[\"79404.10\",\"1.021\"],[\"79555.70\",\"0.001\"],[\"79556.50\",\"0.284\"],[\"79753.40\",\"0.636\"],[\"80176.10\",\"4.056\"],[\"80966.80\",\"0.000\"],[\"80969.90\",\"1.739\"]],\"st\":1}}"}
{"receive_ns":1788781924157121000,"stream":"btcusdt@depth@100ms","event_type":"depthUpdate","event_time_ms":1788781924230,"raw_json":"{\"stream\":\"btcusdt@depth@100ms\",\"data\":{\"e\":\"depthUpdate\",\"E\":1788781924230,\"T\":1788781924225,\"s\":\"BTCUSDT\",\"ps\":\"BTCUSDT\",\"U\":11496321408679,\"u\":11496321415442,\"pu\":11496321408455,\"b\":[[\"29082.20\",\"0.196\"],[\"29182.20\",\"1.897\"],[\"29282.20\",\"0.007\"],[\"71443.90\",\"0.002\"],[\"76206.90\",\"0.000\"],[\"78588.40\",\"2.542\"],[\"78985.30\",\"0.262\"],[\"79134.10\",\"0.602\"],[\"79150.40\",\"0.008\"],[\"79179.40\",\"3.111\"],[\"79207.50\",\"0.001\"],[\"79382.20\",\"15.809\"]],\"a\":[[\"79426.20\",\"0.257\"],[\"79436.30\",\"0.055\"],[\"79478.50\",\"0.001\"],[\"79478.70\",\"0.010\"],[\"79481.30\",\"0.165\"],[\"79554.70\",\"1.051\"],[\"79753.40\",\"0.943\"],[\"80176.10\",\"4.056\"]],\"st\":1}}"}
{"receive_ns":1788781924260576000,"stream":"btcusdt@depth@100ms","event_type":"depthUpdate","event_time_ms":1788781924332,"raw_json":"{\"stream\":\"btcusdt@depth@100ms\",\"data\":{\"e\":\"depthUpdate\",\"E\":1788781924332,\"T\":1788781924330,\"s\":\"BTCUSDT\",\"ps\":\"BTCUSDT\",\"U\":11496321415975,\"u\":11496321424256,\"pu\":11496321415442,\"b\":[[\"1000.00\",\"24.754\"],[\"29082.20\",\"0.371\"],[\"29182.20\",\"1.729\"],[\"29282.20\",\"0.000\"],[\"63506.00\",\"0.008\"],[\"71443.90\",\"0.002\"],[\"78493.20\",\"0.636\"],[\"78588.40\",\"2.542\"],[\"79150.40\",\"0.000\"],[\"79158.00\",\"0.021\"],[\"79161.60\",\"35.371\"],[\"79179.80\",\"1.750\"],[\"79203.80\",\"1.008\"],[\"79207.40\",\"26.513\"],[\"79235.00\",\"0.001\"],[\"79238.60\",\"17.678\"],[\"79259.20\",\"0.062\"],[\"79288.40\",\"0.464\"],[\"79292.00\",\"10.035\"],[\"79310.70\",\"0.003\"],[\"79324.60\",\"0.301\"],[\"79350.40\",\"0.002\"],[\"79354.10\",\"0.004\"],[\"79356.10\",\"0.001\"],[\"79356.20\",\"0.463\"],[\"79362.20\",\"0.071\"],[\"79362.90\",\"0.100\"],[\"79363.30\",\"0.003\"],[\"79363.40\",\"0.650\"],[\"79363.80\",\"0.323\"]],\"a\":[[\"79382.30\",\"5.125\"],[\"79384.50\",\"0.002\"],[\"79401.50\",\"0.002\"],[\"79402.90\",\"0.493\"],[\"79404.50\",\"0.000\"],[\"79405.70\",\"0.453\"],[\"79406.60\",\"0.004\"],[\"79418.00\",\"0.001\"],[\"79453.80\",\"0.004\"],[\"79753.40\",\"0.910\"],[\"79779.30\",\"0.001\"],[\"79929.50\",\"56.399\"],[\"80136.70\",\"5.160\"],[\"80145.30\",\"69.119\"],[\"80176.10\",\"4.056\"],[\"80409.80\",\"85.676\"],[\"87320.60\",\"0.000\"]],\"st\":1}}"}
{"receive_ns":1788781924363379000,"stream":"btcusdt@depth@100ms","event_type":"depthUpdate","event_time_ms":1788781924434,"raw_json":"{\"stream\":\"btcusdt@depth@100ms\",\"data\":{\"e\":\"depthUpdate\",\"E\":1788781924434,\"T\":1788781924433,\"s\":\"BTCUSDT\",\"ps\":\"BTCUSDT\",\"U\":11496321424398,\"u\":11496321431546,\"pu\":11496321424256,\"b\":[[\"1000.00\",\"24.754\"],[\"29082.20\",\"0.553\"],[\"29182.20\",\"1.547\"],[\"71443.90\",\"0.002\"],[\"76206.90\",\"0.002\"],[\"78255.00\",\"1.626\"],[\"78588.40\",\"2.542\"],[\"78747.10\",\"4.439\"],[\"79133.00\",\"0.000\"],[\"79134.10\",\"0.602\"],[\"79150.40\",\"0.000\"],[\"79158.00\",\"0.021\"],[\"79161.60\",\"35.371\"],[\"79161.70\",\"0.054\"],[\"79163.20\",\"5.901\"],[\"79203.90\",\"0.000\"],[\"79207.40\",\"26.513\"],[\"79207.50\",\"4.076\"],[\"79235.00\",\"0.001\"],[\"79238.60\",\"17.678\"],[\"79239.60\",\"3.600\"],[\"79259.20\",\"0.124\"],[\"79288.40\",\"0.464\"],[\"79292.00\",\"10.035\"],[\"79295.90\",\"3.167\"],[\"79322.50\",\"0.070\"],[\"79324.60\",\"0.251\"],[\"79332.00\",\"0.007\"],[\"79332.80\",\"0.000\"],[\"79355.50\",\"1.296\"],[\"79358.40\",\"0.003\"],[\"79365.90\",\"0.013\"],[\"79371.80\",\"1.844\"],[\"79371.90\",\"0.094\"]],\"a\":[[\"79398.30\",\"0.129\"],[\"79400.30\",\"0.128\"],[\"79402.20\",\"0.128\"],[\"79404.20\",\"0.129\"],[\"79420.00\",\"2.567\"],[\"79429.50\",\"0.128\"],[\"79429.80\",\"0.005\"],[\"79752.00\",\"7.245\"],[\"79753.40\",\"0.943\"],[\"80176.10\",\"4.056\"],[\"81366.90\",\"0.006\"]],\"st\":1}}"}
{"receive_ns":1788781924464659000,"stream":"btcusdt@depth@100ms","event_type":"depthUpdate","event_time_ms":1788781924536,"raw_json":"{\"stream\":\"btcusdt@depth@100ms\",\"data\":{\"e\":\"depthUpdate\",\"E\":1788781924536,\"T\":1788781924533,\"s\":\"BTCUSDT\",\"ps\":\"BTCUSDT\",\"U\":11496321431574,\"u\":11496321437811,\"pu\":11496321431546,\"b\":[[\"29082.20\",\"0.728\"],[\"29182.20\",\"1.372\"],[\"71443.90\",\"0.002\"],[\"76206.90\",\"0.000\"],[\"78588.40\",\"2.542\"],[\"78985.20\",\"0.002\"],[\"78985.30\",\"0.262\"],[\"79150.40\",\"0.000\"],[\"79153.50\",\"0.000\"],[\"79158.10\",\"2.227\"],[\"79161.60\",\"0.000\"],[\"79163.20\",\"0.715\"],[\"79172.60\",\"0.015\"],[\"79179.80\",\"1.297\"],[\"79203.90\",\"1.559\"],[\"79207.40\",\"0.000\"],[\"79207.50\",\"0.001\"],[\"79232.70\",\"0.000\"],[\"79233.10\",\"1.891\"],[\"79235.10\",\"1.175\"],[\"79238.60\",\"0.010\"],[\"79239.60\",\"1.103\"],[\"79259.20\",\"0.062\"],[\"79288.40\",\"0.464\"],[\"79288.50\",\"0.141\"],[\"79292.00\",\"1.207\"],[\"79295.90\",\"1.153\"],[\"79324.60\",\"0.000\"],[\"79334.50\",\"0.103\"],[\"79356.50\",\"0.164\"],[\"79365.90\",\"0.013\"],[\"79369.30\",\"0.006\"],[\"79371.90\",\"0.094\"]],\"a\":[[\"79414.10\",\"0.014\"],[\"79511.90\",\"1.600\"],[\"79512.40\",\"2.015\"],[\"79751.40\",\"0.128\"],[\"79753.40\",\"0.340\"],[\"79929.40\",\"3.289\"],[\"80050.80\",\"0.000\"],[\"80136.40\",\"1.058\"],[\"80176.10\",\"4.056\"],[\"80317.60\",\"10.818\"],[\"80334.90\",\"2.888\"],[\"80509.50\",\"0.894\"]],\"st\":1}}"}
{"receive_ns":1788781924567184000,"stream":"btcusdt@depth@100ms","event_type":"depthUpdate","event_time_ms":1788781924638,"raw_json":"{\"stream\":\"btcusdt@depth@100ms\",\"data\":{\"e\":\"depthUpdate\",\"E\":1788781924638,\"T\":1788781924637,\"s\":\"BTCUSDT\",\"ps\":\"BTCUSDT\",\"U\":11496321437939,\"u\":11496321445147,\"pu\":11496321437811,\"b\":[[\"1000.00\",\"24.954\"],[\"29082.20\",\"0.903\"],[\"29182.20\",\"1.197\"],[\"63506.00\",\"0.008\"],[\"71443.90\",\"0.002\"],[\"76206.90\",\"0.002\"],[\"78033.00\",\"1.574\"],[\"78215.60\",\"2.108\"],[\"78372.80\",\"16.530\"],[\"78588.30\",\"0.003\"],[\"78588.40\",\"3.495\"],[\"79134.10\",\"1.003\"],[\"79150.40\",\"0.000\"],[\"79158.10\",\"0.000\"],[\"79161.60\",\"35.371\"],[\"79203.90\",\"0.000\"],[\"79207.40\",\"26.513\"],[\"79235.10\",\"0.400\"],[\"79238.60\",\"17.678\"],[\"79259.20\",\"0.000\"],[\"79288.50\",\"0.003\"],[\"79292.00\",\"10.035\"],[\"79366.40\",\"0.000\"]],\"a\":[[\"79554.70\",\"1.051\"],[\"79556.20\",\"0.136\"],[\"79556.50\",\"0.284\"],[\"79751.40\",\"0.636\"],[\"79753.40\",\"0.000\"],[\"80176.10\",\"4.056\"],[\"80357.10\",\"13.533\"],[\"80374.60\",\"1.286\"],[\"80492.00\",\"3.399\"]],\"st\":1}}"}
{"receive_ns":1788781924669584000,"stream":"btcusdt@depth@100ms","event_type":"depthUpdate","event_time_ms":1788781924740,"raw_json":"{\"stream\":\"btcusdt@depth@100ms\",\"data\":{\"e\":\"depthUpdate\",\"E\":1788781924740,\"T\":1788781924737,\"s\":\"BTCUSDT\",\"ps\":\"BTCUSDT\",\"U\":11496321445241,\"u\":11496321450626,\"pu\":11496321445147,\"b\":[[\"1000.00\",\"24.954\"],[\"29082.20\",\"1.078\"],[\"29182.20\",\"1.022\"],[\"63505.80\",\"0.000\"],[\"63506.00\",\"0.008\"],[\"71443.90\",\"0.002\"],[\"76206.90\",\"0.000\"],[\"78588.40\",\"3.495\"],[\"78781.50\",\"3.170\"],[\"79179.40\",\"3.093\"],[\"79179.80\",\"1.525\"],[\"79207.50\",\"0.019\"],[\"79322.50\",\"0.073\"],[\"79324.60\",\"0.037\"],[\"79332.00\",\"0.004\"],[\"79365.90\",\"0.003\"],[\"79371.90\",\"0.104\"],[\"79372.10\",\"0.001\"]],\"a\":[[\"79431.10\",\"0.358\"],[\"79447.30\",\"0.000\"],[\"79751.40\",\"0.815\"],[\"80176.10\",\"4.056\"]],\"st\":1}}"}
{"receive_ns":1788781924771930000,"stream":"btcusdt@depth@100ms","event_type":"depthUpdate","event_time_ms":1788781924842,"raw_json":"{\"stream\":\"btcusdt@depth@100ms\",\"data\":{\"e\":\"depthUpdate\",\"E\":1788781924842,\"T\":1788781924841,\"s\":\"BTCUSDT\",\"ps\":\"BTCUSDT\",\"U\":11496321450818,\"u\":11496321455808,\"pu\":11496321450626,\"b\":[[\"29082.20\",\"1.267\"],[\"29182.20\",\"0.833\"],[\"71443.90\",\"0.002\"],[\"78015.70\",\"6.499\"],[\"78588.40\",\"4.448\"],[\"78616.10\",\"0.001\"],[\"78619.80\",\"0.003\"],[\"78985.30\",\"0.262\"],[\"79134.10\",\"0.125\"],[\"79150.40\",\"0.013\"],[\"79158.10\",\"0.000\"],[\"79161.60\",\"35.371\"],[\"79179.80\",\"2.441\"],[\"79204.00\",\"0.000\"],[\"79207.40\",\"26.513\"],[\"79235.10\",\"0.400\"],[\"79238.60\",\"17.678\"],[\"79259.20\",\"0.112\"],[\"79288.50\",\"0.003\"],[\"79292.00\",\"10.035\"],[\"79322.50\",\"0.070\"],[\"79332.80\",\"0.003\"],[\"79361.10\",\"0.008\"],[\"79365.20\",\"0.108\"],[\"79367.10\",\"0.442\"]],\"a\":[[\"79382.50\",\"0.002\"],[\"79389.20\",\"0.002\"],[\"79400.90\",\"0.254\"],[\"79402.90\",\"0.053\"],[\"79403.00\",\"0.666\"],[\"79403.90\",\"0.462\"],[\"79404.00\",\"1.555\"],[\"79429.40\",\"0.157\"],[\"79429.50\",\"0.001\"],[\"79475.90\",\"0.046\"],[\"79751.40\",\"0.874\"],[\"79753.40\",\"0.036\"],[\"80176.10\",\"4.058\"],[\"80350.60\",\"0.621\"],[\"80476.10\",\"21.607\"]],\"st\":1}}"}
{"receive_ns":1788781924778891000,"stream":"btcusdt@bookTicker","event_type":"bookTicker","event_time_ms":1788781924849,"raw_json":"{\"stream\":\"btcusdt@bookTicker\",\"data\":{\"e\":\"bookTicker\",\"u\":11496321456297,\"s\":\"BTCUSDT\",\"ps\":\"BTCUSDT\",\"b\":\"79382.20\",\"B\":\"15.259\",\"a\":\"79382.30\",\"A\":\"5.125\",\"T\":1788781924849,\"E\":1788781924849,\"st\":1}}"}
{"receive_ns":1788781924787765000,"stream":"btcusdt@bookTicker","event_type":"bookTicker","event_time_ms":1788781924858,"raw_json":"{\"stream\":\"btcusdt@bookTicker\",\"data\":{\"e\":\"bookTicker\",\"u\":11496321456745,\"s\":\"BTCUSDT\",\"ps\":\"BTCUSDT\",\"b\":\"79382.20\",\"B\":\"15.259\",\"a\":\"79382.30\",\"A\":\"5.071\",\"T\":1788781924858,\"E\":1788781924858,\"st\":1}}"}
{"receive_ns":1788781924788077000,"stream":"btcusdt@trade","event_type":"trade","event_time_ms":1788781924858,"raw_json":"{\"stream\":\"btcusdt@trade\",\"data\":{\"e\":\"trade\",\"E\":1788781924858,\"T\":1788781924858,\"s\":\"BTCUSDT\",\"t\":8057735390,\"p\":\"79382.30\",\"q\":\"0.054\",\"X\":\"MARKET\",\"m\":false,\"st\":1}}"}
{"receive_ns":1788781924854549000,"stream":"btcusdt@bookTicker","event_type":"bookTicker","event_time_ms":1788781924924,"raw_json":"{\"stream\":\"btcusdt@bookTicker\",\"data\":{\"e\":\"bookTicker\",\"u\":11496321460863,\"s\":\"BTCUSDT\",\"ps\":\"BTCUSDT\",\"b\":\"79382.20\",\"B\":\"15.259\",\"a\":\"79382.30\",\"A\":\"4.787\",\"T\":1788781924924,\"E\":1788781924924,\"st\":1}}"}
{"receive_ns":1788781924854755000,"stream":"btcusdt@bookTicker","event_type":"bookTicker","event_time_ms":1788781924925,"raw_json":"{\"stream\":\"btcusdt@bookTicker\",\"data\":{\"e\":\"bookTicker\",\"u\":11496321460874,\"s\":\"BTCUSDT\",\"ps\":\"BTCUSDT\",\"b\":\"79382.20\",\"B\":\"15.318\",\"a\":\"79382.30\",\"A\":\"4.787\",\"T\":1788781924924,\"E\":1788781924925,\"st\":1}}"}
{"receive_ns":1788781924874363000,"stream":"btcusdt@depth@100ms","event_type":"depthUpdate","event_time_ms":1788781924944,"raw_json":"{\"stream\":\"btcusdt@depth@100ms\",\"data\":{\"e\":\"depthUpdate\",\"E\":1788781924944,\"T\":1788781924943,\"s\":\"BTCUSDT\",\"ps\":\"BTCUSDT\",\"U\":11496321455826,\"u\":11496321462766,\"pu\":11496321455808,\"b\":[[\"1000.00\",\"24.954\"],[\"29082.20\",\"1.442\"],[\"29182.20\",\"0.658\"],[\"63506.00\",\"0.008\"],[\"71443.90\",\"0.002\"],[\"76206.90\",\"0.002\"],[\"78215.30\",\"1.021\"],[\"78372.80\",\"16.339\"],[\"78429.60\",\"3.316\"],[\"78588.40\",\"4.448\"],[\"78667.10\",\"0.002\"],[\"78747.10\",\"4.693\"],[\"78985.20\",\"0.001\"],[\"79134.10\",\"0.602\"],[\"79150.40\",\"0.000\"],[\"79153.50\",\"0.013\"],[\"79158.20\",\"2.223\"],[\"79161.60\",\"0.000\"],[\"79179.80\",\"2.001\"],[\"79204.00\",\"1.556\"],[\"79207.40\",\"0.000\"],[\"79235.10\",\"0.400\"],[\"79235.20\",\"0.777\"],[\"79238.60\",\"0.010\"],[\"79259.20\",\"0.174\"],[\"79288.50\",\"0.140\"],[\"79292.00\",\"1.207\"],[\"79320.80\",\"0.000\"],[\"79324.00\",\"1.264\"],[\"79324.60\",\"0.000\"],[\"79335.90\",\"0.403\"],[\"79339.90\",\"0.000\"],[\"79350.30\",\"0.313\"],[\"79350.40\",\"10.002\"],[\"79351.50\",\"0.703\"],[\"79351.80\",\"0.005\"],[\"79353.80\",\"0.021\"],[\"79353.90\",\"0.084\"],[\"79354.60\",\"0.630\"],[\"79355.50\",\"0.563\"],[\"79355.60\",\"0.000\"],[\"79356.40\",\"0.003\"],[\"79357.70\",\"0.783\"],[\"79358.10\",\"0.003\"],[\"79358.20\",\"0.001\"],[\"79358.60\",\"0.710\"],[\"79358.70\",\"0.658\"],[\"79359.40\",\"0.003\"],[\"79361.70\",\"0.014\"],[\"79362.60\",\"0.734\"],[\"79363.80\",\"0.000\"],[\"79363.90\",\"0.320\"],[\"79364.00\",\"0.184\"],[\"79365.20\",\"0.549\"],[\"79365.30\",\"0.334\"],[\"79366.50\",\"0.077\"],[\"79367.10\",\"0.001\"],[\"79368.10\",\"0.078\"],[\"79369.10\",\"1.309\"],[\"79370.10\",\"0.000\"],[\"79371.30\",\"0.254\"],[\"79371.90\",\"0.104\"],[\"79376.90\",\"0.915\"],[\"79380.00\",\"0.008\"],[\"79381.90\",\"0.019\"],[\"79382.20\",\"15.318\"]],\"a\":[[\"79382.30\",\"4.787\"],[\"79382.90\",\"0.001\"],[\"79384.30\",\"0.001\"],[\"79385.30\",\"0.001\"],[\"79388.00\",\"0.005\"],[\"79388.10\",\"0.001\"],[\"79389.20\",\"0.000\"],[\"79390.40\",\"0.000\"],[\"79391.30\",\"0.404\"],[\"79391.50\",\"0.122\"],[\"79391.60\",\"0.000\"],[\"79393.30\",\"0.001\"],[\"79394.30\",\"0.252\"],[\"79394.90\",\"0.301\"],[\"79395.20\",\"0.630\"],[\"79395.30\",\"0.004\"],[\"79395.40\",\"1.632\"],[\"79396.50\",\"0.081\"],[\"79399.20\",\"0.002\"],[\"79401.60\",\"0.003\"],[\"79402.30\",\"0.633\"],[\"79402.80\",\"0.568\"],[\"79402.90\",\"0.493\"],[\"79403.20\",\"0.030\"],[\"79403.90\",\"0.022\"],[\"79404.00\",\"0.019\"],[\"79404.10\",\"1.020\"],[\"79405.80\",\"0.000\"],[\"79406.30\",\"0.631\"],[\"79407.20\",\"0.081\"],[\"79409.40\",\"0.001\"],[\"79410.30\",\"0.629\"],[\"79418.50\",\"0.001\"],[\"79429.10\",\"0.130\"],[\"79429.30\",\"0.252\"],[\"79429.40\",\"0.030\"],[\"79452.30\",\"0.104\"],[\"79461.70\",\"0.027\"],[\"79475.00\",\"0.003\"],[\"79751.40\",\"0.907\"],[\"80017.40\",\"1.432\"],[\"80096.00\",\"1.504\"],[\"80176.10\",\"4.056\"],[\"80334.90\",\"3.261\"],[\"80969.90\",\"1.742\"]],\"st\":1}}"}
{"receive_ns":1788781924908005000,"stream":"btcusdt@bookTicker","event_type":"bookTicker","event_time_ms":1788781924978,"raw_json":"{\"stream\":\"btcusdt@bookTicker\",\"data\":{\"e\":\"bookTicker\",\"u\":11496321464948,\"s\":\"BTCUSDT\",\"ps\":\"BTCUSDT\",\"b\":\"79382.20\",\"B\":\"15.318\",\"a\":\"79382.30\",\"A\":\"4.785\",\"T\":1788781924978,\"E\":1788781924978,\"st\":1}}"}
{"receive_ns":1788781924908396000,"stream":"btcusdt@trade","event_type":"trade","event_time_ms":1788781924978,"raw_json":"{\"stream\":\"btcusdt@trade\",\"data\":{\"e\":\"trade\",\"E\":1788781924978,\"T\":1788781924978,\"s\":\"BTCUSDT\",\"t\":8057735391,\"p\":\"79382.30\",\"q\":\"0.002\",\"X\":\"MARKET\",\"m\":false,\"st\":1}}"}
{"receive_ns":1788781924908676000,"stream":"btcusdt@bookTicker","event_type":"bookTicker","event_time_ms":1788781924978,"raw_json":"{\"stream\":\"btcusdt@bookTicker\",\"data\":{\"e\":\"bookTicker\",\"u\":11496321464954,\"s\":\"BTCUSDT\",\"ps\":\"BTCUSDT\",\"b\":\"79382.20\",\"B\":\"15.318\",\"a\":\"79382.30\",\"A\":\"4.783\",\"T\":1788781924978,\"E\":1788781924978,\"st\":1}}"}
{"receive_ns":1788781924908918000,"stream":"btcusdt@bookTicker","event_type":"bookTicker","event_time_ms":1788781924978,"raw_json":"{\"stream\":\"btcusdt@bookTicker\",\"data\":{\"e\":\"bookTicker\",\"u\":11496321464958,\"s\":\"BTCUSDT\",\"ps\":\"BTCUSDT\",\"b\":\"79382.20\",\"B\":\"15.318\",\"a\":\"79382.30\",\"A\":\"4.781\",\"T\":1788781924978,\"E\":1788781924978,\"st\":1}}"}
{"receive_ns":1788781924909086000,"stream":"btcusdt@bookTicker","event_type":"bookTicker","event_time_ms":1788781924978,"raw_json":"{\"stream\":\"btcusdt@bookTicker\",\"data\":{\"e\":\"bookTicker\",\"u\":11496321464971,\"s\":\"BTCUSDT\",\"ps\":\"BTCUSDT\",\"b\":\"79382.20\",\"B\":\"15.318\",\"a\":\"79382.30\",\"A\":\"4.779\",\"T\":1788781924978,\"E\":1788781924978,\"st\":1}}"}
{"receive_ns":1788781924909322000,"stream":"btcusdt@trade","event_type":"trade","event_time_ms":1788781924978,"raw_json":"{\"stream\":\"btcusdt@trade\",\"data\":{\"e\":\"trade\",\"E\":1788781924978,\"T\":1788781924978,\"s\":\"BTCUSDT\",\"t\":8057735392,\"p\":\"79382.30\",\"q\":\"0.002\",\"X\":\"MARKET\",\"m\":false,\"st\":1}}"}
{"receive_ns":1788781924909568000,"stream":"btcusdt@trade","event_type":"trade","event_time_ms":1788781924978,"raw_json":"{\"stream\":\"btcusdt@trade\",\"data\":{\"e\":\"trade\",\"E\":1788781924978,\"T\":1788781924978,\"s\":\"BTCUSDT\",\"t\":8057735393,\"p\":\"79382.30\",\"q\":\"0.002\",\"X\":\"MARKET\",\"m\":false,\"st\":1}}"}
{"receive_ns":1788781924909731000,"stream":"btcusdt@trade","event_type":"trade","event_time_ms":1788781924978,"raw_json":"{\"stream\":\"btcusdt@trade\",\"data\":{\"e\":\"trade\",\"E\":1788781924978,\"T\":1788781924978,\"s\":\"BTCUSDT\",\"t\":8057735394,\"p\":\"79382.30\",\"q\":\"0.002\",\"X\":\"MARKET\",\"m\":false,\"st\":1}}"}
{"receive_ns":1788781924909882000,"stream":"btcusdt@bookTicker","event_type":"bookTicker","event_time_ms":1788781924979,"raw_json":"{\"stream\":\"btcusdt@bookTicker\",\"data\":{\"e\":\"bookTicker\",\"u\":11496321465108,\"s\":\"BTCUSDT\",\"ps\":\"BTCUSDT\",\"b\":\"79382.20\",\"B\":\"15.318\",\"a\":\"79382.30\",\"A\":\"5.014\",\"T\":1788781924979,\"E\":1788781924979,\"st\":1}}"}
{"receive_ns":1788781924910035000,"stream":"btcusdt@bookTicker","event_type":"bookTicker","event_time_ms":1788781924980,"raw_json":"{\"stream\":\"btcusdt@bookTicker\",\"data\":{\"e\":\"bookTicker\",\"u\":11496321465222,\"s\":\"BTCUSDT\",\"ps\":\"BTCUSDT\",\"b\":\"79382.20\",\"B\":\"15.318\",\"a\":\"79382.30\",\"A\":\"5.013\",\"T\":1788781924980,\"E\":1788781924980,\"st\":1}}"}
{"receive_ns":1788781924915143000,"stream":"btcusdt@bookTicker","event_type":"bookTicker","event_time_ms":1788781924986,"raw_json":"{\"stream\":\"btcusdt@bookTicker\",\"data\":{\"e\":\"bookTicker\",\"u\":11496321465575,\"s\":\"BTCUSDT\",\"ps\":\"BTCUSDT\",\"b\":\"79382.20\",\"B\":\"15.320\",\"a\":\"79382.30\",\"A\":\"5.013\",\"T\":1788781924986,\"E\":1788781924986,\"st\":1}}"}
{"receive_ns":1788781924918841000,"stream":"btcusdt@bookTicker","event_type":"bookTicker","event_time_ms":1788781924989,"raw_json":"{\"stream\":\"btcusdt@bookTicker\",\"data\":{\"e\":\"bookTicker\",\"u\":11496321465832,\"s\":\"BTCUSDT\",\"ps\":\"BTCUSDT\",\"b\":\"79382.20\",\"B\":\"15.337\",\"a\":\"79382.30\",\"A\":\"5.013\",\"T\":1788781924989,\"E\":1788781924989,\"st\":1}}"}
{"receive_ns":1788781924919326000,"stream":"btcusdt@bookTicker","event_type":"bookTicker","event_time_ms":1788781924990,"raw_json":"{\"stream\":\"btcusdt@bookTicker\",\"data\":{\"e\":\"bookTicker\",\"u\":11496321465909,\"s\":\"BTCUSDT\",\"ps\":\"BTCUSDT\",\"b\":\"79382.20\",\"B\":\"15.337\",\"a\":\"79382.30\",\"A\":\"5.014\",\"T\":1788781924990,\"E\":1788781924990,\"st\":1}}"}
{"receive_ns":1788781924964290000,"stream":"btcusdt@bookTicker","event_type":"bookTicker","event_time_ms":1788781925001,"raw_json":"{\"stream\":\"btcusdt@bookTicker\",\"data\":{\"e\":\"bookTicker\",\"u\":11496321466595,\"s\":\"BTCUSDT\",\"ps\":\"BTCUSDT\",\"b\":\"79382.20\",\"B\":\"15.337\",\"a\":\"79382.30\",\"A\":\"5.013\",\"T\":1788781925001,\"E\":1788781925001,\"st\":1}}"}
{"receive_ns":1788781924964740000,"stream":"btcusdt@bookTicker","event_type":"bookTicker","event_time_ms":1788781925031,"raw_json":"{\"stream\":\"btcusdt@bookTicker\",\"data\":{\"e\":\"bookTicker\",\"u\":11496321468852,\"s\":\"BTCUSDT\",\"ps\":\"BTCUSDT\",\"b\":\"79382.20\",\"B\":\"15.335\",\"a\":\"79382.30\",\"A\":\"5.013\",\"T\":1788781925031,\"E\":1788781925031,\"st\":1}}"}
{"receive_ns":1788781924974040000,"stream":"btcusdt@depth@100ms","event_type":"depthUpdate","event_time_ms":1788781925046,"raw_json":"{\"stream\":\"btcusdt@depth@100ms\",\"data\":{\"e\":\"depthUpdate\",\"E\":1788781925046,\"T\":1788781925045,\"s\":\"BTCUSDT\",\"ps\":\"BTCUSDT\",\"U\":11496321462810,\"u\":11496321469950,\"pu\":11496321462766,\"b\":[[\"1000.00\",\"24.954\"],[\"29082.20\",\"1.624\"],[\"29182.20\",\"0.476\"],[\"63506.00\",\"0.008\"],[\"71443.90\",\"0.002\"],[\"76206.90\",\"0.000\"],[\"77794.60\",\"1.165\"],[\"78588.40\",\"4.448\"],[\"79153.50\",\"0.000\"],[\"79158.20\",\"0.000\"],[\"79161.60\",\"35.371\"],[\"79169.40\",\"1.101\"],[\"79179.80\",\"1.862\"],[\"79204.00\",\"0.000\"],[\"79207.40\",\"26.513\"],[\"79235.20\",\"0.004\"],[\"79238.60\",\"17.678\"],[\"79259.20\",\"0.062\"],[\"79272.50\",\"0.642\"],[\"79288.50\",\"0.003\"],[\"79292.00\",\"10.035\"],[\"79308.80\",\"0.073\"],[\"79310.70\",\"0.001\"],[\"79311.30\",\"0.005\"],[\"79324.60\",\"0.251\"],[\"79335.60\",\"0.002\"],[\"79346.10\",\"0.001\"],[\"79346.30\",\"0.896\"],[\"79347.00\",\"0.227\"],[\"79348.30\",\"0.000\"],[\"79350.30\",\"0.312\"],[\"79350.40\",\"0.002\"],[\"79354.10\",\"0.457\"],[\"79355.20\",\"3.744\"],[\"79356.20\",\"0.010\"],[\"79358.40\",\"0.034\"],[\"79359.00\",\"0.106\"],[\"79359.70\",\"0.079\"],[\"79361.60\",\"0.511\"],[\"79362.90\",\"0.667\"],[\"79363.10\",\"0.102\"],[\"79363.40\",\"0.083\"],[\"79363.80\",\"0.315\"],[\"79363.90\",\"0.005\"],[\"79365.10\",\"1.346\"],[\"79365.20\",\"0.108\"],[\"79365.30\",\"0.330\"],[\"79365.50\",\"0.256\"],[\"79367.00\",\"1.265\"],[\"79368.10\",\"0.002\"],[\"79371.40\",\"0.006\"],[\"79371.90\",\"0.104\"],[\"79375.00\",\"0.006\"],[\"79380.00\",\"0.006\"],[\"79381.90\",\"0.002\"],[\"79382.00\",\"0.004\"],[\"79382.20\",\"15.335\"]],\"a\":[[\"79382.30\",\"5.013\"],[\"79382.50\",\"0.001\"],[\"79382.90\",\"0.415\"],[\"79383.00\",\"0.555\"],[\"79384.50\",\"0.001\"],[\"79385.60\",\"0.259\"],[\"79385.70\",\"0.053\"],[\"79387.90\",\"0.002\"],[\"79389.30\",\"0.002\"],[\"79395.30\",\"0.005\"],[\"79396.60\",\"0.004\"],[\"79401.40\",\"0.000\"],[\"79401.80\",\"0.048\"],[\"79402.30\",\"0.444\"],[\"79402.40\",\"0.574\"],[\"79402.70\",\"0.629\"],[\"79402.80\",\"0.002\"],[\"79402.90\",\"0.054\"],[\"79406.30\",\"0.002\"],[\"79406.70\",\"1.035\"],[\"79409.60\",\"0.000\"],[\"79410.30\",\"0.000\"],[\"79410.80\",\"0.796\"],[\"79417.90\",\"0.255\"],[\"79418.20\",\"0.003\"],[\"79437.90\",\"0.241\"],[\"79452.30\",\"0.102\"],[\"79453.80\",\"0.002\"],[\"79475.30\",\"0.029\"],[\"79483.10\",\"0.236\"],[\"79541.10\",\"0.599\"],[\"79556.20\",\"0.011\"],[\"79751.40\",\"0.943\"],[\"79753.40\",\"0.000\"],[\"79779.30\",\"0.002\"],[\"80176.10\",\"4.056\"],[\"80509.50\",\"1.043\"],[\"80969.90\",\"1.739\"]],\"st\":1}}"}
{"receive_ns":1788781925070526000,"stream":"btcusdt@bookTicker","event_type":"bookTicker","event_time_ms":1788781925141,"raw_json":"{\"stream\":\"btcusdt@bookTicker\",\"data\":{\"e\":\"bookTicker\",\"u\":11496321477486,\"s\":\"BTCUSDT\",\"ps\":\"BTCUSDT\",\"b\":\"79382.20\",\"B\":\"15.335\",\"a\":\"79382.30\",\"A\":\"5.014\",\"T\":1788781925141,\"E\":1788781925141,\"st\":1}}"}
{"receive_ns":1788781925077430000,"stream":"btcusdt@depth@100ms","event_type":"depthUpdate","event_time_ms":1788781925148,"raw_json":"{\"stream\":\"btcusdt@depth@100ms\",\"data\":{\"e\":\"depthUpdate\",\"E\":1788781925148,\"T\":1788781925147,\"s\":\"BTCUSDT\",\"ps\":\"BTCUSDT\",\"U\":11496321470042,\"u\":11496321477818,\"pu\":11496321469950,\"b\":[[\"28982.20\",\"0.014\"],[\"29082.20\",\"1.771\"],[\"29182.20\",\"0.315\"],[\"71443.90\",\"0.002\"],[\"76206.90\",\"0.002\"],[\"78270.80\",\"4.081\"],[\"78413.80\",\"0.637\"],[\"78588.40\",\"4.448\"],[\"78980.50\",\"0.018\"],[\"78982.50\",\"1.657\"],[\"78985.30\",\"0.262\"],[\"79134.10\",\"0.187\"],[\"79144.10\",\"0.000\"],[\"79158.20\",\"0.000\"],[\"79161.60\",\"35.371\"],[\"79179.80\",\"2.339\"],[\"79204.10\",\"0.000\"],[\"79207.40\",\"26.513\"],[\"79235.20\",\"0.004\"],[\"79238.60\",\"17.678\"],[\"79259.20\",\"0.000\"],[\"79288.60\",\"0.000\"],[\"79292.00\",\"10.035\"],[\"79319.40\",\"0.624\"],[\"79354.10\",\"0.004\"],[\"79356.10\",\"0.454\"],[\"79362.00\",\"1.398\"],[\"79362.90\",\"0.100\"],[\"79369.10\",\"1.283\"]],\"a\":[[\"79382.30\",\"5.014\"],[\"79391.60\",\"0.002\"],[\"79394.30\",\"0.001\"],[\"79394.90\",\"0.552\"],[\"79396.60\",\"0.000\"],[\"79402.40\",\"0.008\"],[\"79403.00\",\"1.232\"],[\"79411.50\",\"0.006\"],[\"79437.90\",\"0.243\"],[\"79478.70\",\"0.000\"],[\"79480.90\",\"0.001\"],[\"79481.00\",\"0.001\"],[\"79555.40\",\"0.002\"],[\"79555.50\",\"1.228\"],[\"79620.40\",\"0.023\"],[\"79751.40\",\"0.943\"],[\"79774.20\",\"0.000\"],[\"79776.20\",\"0.004\"],[\"80176.10\",\"5.302\"],[\"80342.90\",\"1.866\"],[\"80969.90\",\"1.742\"]],\"st\":1}}"}
{"receive_ns":1788781925090889000,"stream":"btcusdt@bookTicker","event_type":"bookTicker","event_time_ms":1788781925161,"raw_json":"{\"stream\":\"btcusdt@bookTicker\",\"data\":{\"e\":\"bookTicker\",\"u\":11496321478547,\"s\":\"BTCUSDT\",\"ps\":\"BTCUSDT\",\"b\":\"79382.20\",\"B\":\"15.337\",\"a\":\"79382.30\",\"A\":\"5.014\",\"T\":1788781925161,\"E\":1788781925161,\"st\":1}}"}
{"receive_ns":1788781925100764000,"stream":"btcusdt@bookTicker","event_type":"bookTicker","event_time_ms":1788781925163,"raw_json":"{\"stream\":\"btcusdt@bookTicker\",\"data\":{\"e\":\"bookTicker\",\"u\":11496321478688,\"s\":\"BTCUSDT\",\"ps\":\"BTCUSDT\",\"b\":\"79382.20\",\"B\":\"15.455\",\"a\":\"79382.30\",\"A\":\"5.014\",\"T\":1788781925163,\"E\":1788781925163,\"st\":1}}"}
{"receive_ns":1788781925178304000,"stream":"btcusdt@depth@100ms","event_type":"depthUpdate","event_time_ms":1788781925250,"raw_json":"{\"stream\":\"btcusdt@depth@100ms\",\"data\":{\"e\":\"depthUpdate\",\"E\":1788781925250,\"T\":1788781925249,\"s\":\"BTCUSDT\",\"ps\":\"BTCUSDT\",\"U\":11496321477882,\"u\":11496321483958,\"pu\":11496321477818,\"b\":[[\"1000.00\",\"25.154\"],[\"28982.20\",\"0.077\"],[\"29082.20\",\"1.827\"],[\"29182.20\",\"0.196\"],[\"71443.90\",\"0.002\"],[\"78588.40\",\"4.448\"],[\"78667.80\",\"0.129\"],[\"79134.10\",\"0.299\"],[\"79158.30\",\"2.244\"],[\"79161.60\",\"0.000\"],[\"79179.80\",\"1.562\"],[\"79204.10\",\"1.571\"],[\"79207.40\",\"0.000\"],[\"79235.30\",\"0.781\"],[\"79238.60\",\"0.010\"],[\"79272.50\",\"0.640\"],[\"79288.70\",\"0.139\"],[\"79292.00\",\"1.207\"],[\"79312.00\",\"0.667\"],[\"79324.60\",\"0.000\"],[\"79354.70\",\"0.453\"],[\"79355.10\",\"0.504\"],[\"79355.40\",\"0.002\"],[\"79356.10\",\"0.001\"],[\"79362.00\",\"0.831\"],[\"79363.30\",\"0.570\"],[\"79369.20\",\"0.029\"],[\"79382.20\",\"15.455\"]],\"a\":[[\"79384.50\",\"0.002\"],[\"79388.30\",\"0.292\"],[\"79389.00\",\"0.167\"],[\"79391.20\",\"0.083\"],[\"79391.30\",\"0.094\"],[\"79391.50\",\"0.060\"],[\"79392.70\",\"0.418\"],[\"79402.70\",\"0.000\"],[\"79403.20\",\"0.659\"],[\"79411.80\",\"0.000\"],[\"79413.60\",\"0.002\"],[\"79415.10\",\"0.381\"],[\"79488.50\",\"0.076\"],[\"79555.70\",\"0.001\"],[\"79556.00\",\"1.261\"],[\"79556.40\",\"0.003\"],[\"79751.40\",\"0.367\"],[\"79753.40\",\"0.036\"],[\"80096.70\",\"0.536\"],[\"80176.10\",\"5.302\"]],\"st\":1}}"}
{"receive_ns":1788781925184230000,"stream":"btcusdt@bookTicker","event_type":"bookTicker","event_time_ms":1788781925256,"raw_json":"{\"stream\":\"btcusdt@bookTicker\",\"data\":{\"e\":\"bookTicker\",\"u\":11496321484487,\"s\":\"BTCUSDT\",\"ps\":\"BTCUSDT\",\"b\":\"79382.20\",\"B\":\"15.454\",\"a\":\"79382.30\",\"A\":\"5.014\",\"T\":1788781925256,\"E\":1788781925256,\"st\":1}}"}
{"receive_ns":1788781925184552000,"stream":"btcusdt@trade","event_type":"trade","event_time_ms":1788781925256,"raw_json":"{\"stream\":\"btcusdt@trade\",\"data\":{\"e\":\"trade\",\"E\":1788781925256,\"T\":1788781925256,\"s\":\"BTCUSDT\",\"t\":8057735395,\"p\":\"79382.20\",\"q\":\"0.001\",\"X\":\"MARKET\",\"m\":true,\"st\":1}}"}
{"receive_ns":1788781925280250000,"stream":"btcusdt@depth@100ms","event_type":"depthUpdate","event_time_ms":1788781925352,"raw_json":"{\"stream\":\"btcusdt@depth@100ms\",\"data\":{\"e\":\"depthUpdate\",\"E\":1788781925352,\"T\":1788781925350,\"s\":\"BTCUSDT\",\"ps\":\"BTCUSDT\",\"U\":11496321484019,\"u\":11496321489814,\"pu\":11496321483958,\"b\":[[\"1000.00\",\"25.154\"],[\"28982.20\",\"0.133\"],[\"29082.20\",\"1.890\"],[\"29182.20\",\"0.077\"],[\"71443.90\",\"0.002\"],[\"76206.90\",\"0.000\"],[\"78588.40\",\"4.448\"],[\"79134.10\",\"0.337\"],[\"79158.30\",\"0.000\"],[\"79161.60\",\"35.371\"],[\"79179.80\",\"2.189\"],[\"79204.10\",\"0.000\"],[\"79207.40\",\"26.513\"],[\"79235.30\",\"0.000\"],[\"79238.60\",\"17.678\"],[\"79256.10\",\"0.000\"],[\"79256.20\",\"0.003\"],[\"79288.70\",\"0.000\"],[\"79292.00\",\"10.035\"],[\"79324.60\",\"0.251\"],[\"79347.00\",\"0.181\"],[\"79348.30\",\"0.046\"],[\"79349.50\",\"0.003\"],[\"79354.10\",\"0.003\"],[\"79354.70\",\"0.000\"],[\"79355.90\",\"0.497\"],[\"79357.00\",\"0.001\"],[\"79365.10\",\"0.905\"],[\"79365.20\",\"0.549\"],[\"79366.50\",\"0.001\"],[\"79367.10\",\"0.001\"],[\"79369.20\",\"0.003\"],[\"79376.90\",\"0.913\"],[\"79382.20\",\"15.454\"]],\"a\":[[\"79382.90\",\"0.414\"],[\"79391.30\",\"0.474\"],[\"79392.70\",\"0.038\"],[\"79402.30\",\"0.004\"],[\"79402.90\",\"0.493\"],[\"79403.00\",\"0.666\"],[\"79404.00\",\"0.585\"],[\"79404.10\",\"1.021\"],[\"79405.70\",\"0.000\"],[\"79406.60\",\"0.457\"],[\"79406.70\",\"0.406\"],[\"79407.20\",\"0.710\"],[\"79448.10\",\"0.001\"],[\"79456.10\",\"0.075\"],[\"79479.90\",\"0.012\"],[\"79613.30\",\"0.001\"],[\"79613.40\",\"0.003\"],[\"79751.40\",\"0.907\"],[\"79797.40\",\"0.006\"],[\"80176.10\",\"5.302\"],[\"80342.40\",\"0.000\"],[\"80342.90\",\"1.244\"],[\"80382.70\",\"0.000\"],[\"80454.00\",\"2.233\"]],\"st\":1}}"}
{"receive_ns":1788781925381252000,"stream":"btcusdt@depth@100ms","event_type":"depthUpdate","event_time_ms":1788781925454,"raw_json":"{\"stream\":\"btcusdt@depth@100ms\",\"data\":{\"e\":\"depthUpdate\",\"E\":1788781925454,\"T\":1788781925449,\"s\":\"BTCUSDT\",\"ps\":\"BTCUSDT\",\"U\":11496321489979,\"u\":11496321494951,\"pu\":11496321489814,\"b\":[[\"28982.20\",\"0.231\"],[\"29082.20\",\"1.869\"],[\"29182.20\",\"0.000\"],[\"71443.90\",\"0.002\"],[\"76206.90\",\"0.002\"],[\"78588.40\",\"4.448\"],[\"78985.20\",\"0.000\"],[\"78985.30\",\"0.262\"],[\"79134.10\",\"0.814\"],[\"79158.30\",\"2.245\"],[\"79161.60\",\"0.000\"],[\"79163.20\",\"5.909\"],[\"79179.40\",\"3.111\"],[\"79179.80\",\"1.712\"],[\"79204.10\",\"0.000\"],[\"79204.20\",\"1.571\"],[\"79207.40\",\"0.000\"],[\"79207.50\",\"4.076\"],[\"79235.30\",\"0.781\"],[\"79238.60\",\"0.010\"],[\"79239.60\",\"3.600\"],[\"79288.70\",\"0.139\"],[\"79292.00\",\"1.207\"],[\"79295.90\",\"3.167\"],[\"79355.50\",\"1.296\"],[\"79365.20\",\"0.108\"],[\"79367.10\",\"0.442\"]],\"a\":[[\"79402.90\",\"0.053\"],[\"79403.90\",\"0.462\"],[\"79404.10\",\"1.678\"],[\"79751.40\",\"0.907\"],[\"80176.10\",\"5.302\"]],\"st\":1}}"}
{"receive_ns":1788781925385063000,"stream":"btcusdt@bookTicker","event_type":"bookTicker","event_time_ms":1788781925456,"raw_json":"{\"stream\":\"btcusdt@bookTicker\",\"data\":{\"e\":\"bookTicker\",\"u\":11496321495142,\"s\":\"BTCUSDT\",\"ps\":\"BTCUSDT\",\"b\":\"79382.20\",\"B\":\"15.454\",\"a\":\"79382.30\",\"A\":\"5.015\",\"T\":1788781925456,\"E\":1788781925456,\"st\":1}}"}
{"receive_ns":1788781925405183000,"stream":"btcusdt@bookTicker","event_type":"bookTicker","event_time_ms":1788781925476,"raw_json":"{\"stream\":\"btcusdt@bookTicker\",\"data\":{\"e\":\"bookTicker\",\"u\":11496321495959,\"s\":\"BTCUSDT\",\"ps\":\"BTCUSDT\",\"b\":\"79382.20\",\"B\":\"15.454\",\"a\":\"79382.30\",\"A\":\"5.014\",\"T\":1788781925476,\"E\":1788781925476,\"st\":1}}"}
{"receive_ns":1788781925407484000,"stream":"btcusdt@bookTicker","event_type":"bookTicker","event_time_ms":1788781925479,"raw_json":"{\"stream\":\"btcusdt@bookTicker\",\"data\":{\"e\":\"bookTicker\",\"u\":11496321496181,\"s\":\"BTCUSDT\",\"ps\":\"BTCUSDT\",\"b\":\"79382.20\",\"B\":\"15.454\",\"a\":\"79382.30\",\"A\":\"5.016\",\"T\":1788781925479,\"E\":1788781925479,\"st\":1}}"}
{"receive_ns":1788781925421384000,"stream":"btcusdt@bookTicker","event_type":"bookTicker","event_time_ms":1788781925492,"raw_json":"{\"stream\":\"btcusdt@bookTicker\",\"data\":{\"e\":\"bookTicker\",\"u\":11496321496659,\"s\":\"BTCUSDT\",\"ps\":\"BTCUSDT\",\"b\":\"79382.20\",\"B\":\"15.454\",\"a\":\"79382.30\",\"A\":\"5.017\",\"T\":1788781925492,\"E\":1788781925492,\"st\":1}}"}
{"receive_ns":1788781925458106000,"stream":"btcusdt@bookTicker","event_type":"bookTicker","event_time_ms":1788781925529,"raw_json":"{\"stream\":\"btcusdt@bookTicker\",\"data\":{\"e\":\"bookTicker\",\"u\":11496321498383,\"s\":\"BTCUSDT\",\"ps\":\"BTCUSDT\",\"b\":\"79382.20\",\"B\":\"15.957\",\"a\":\"79382.30\",\"A\":\"5.017\",\"T\":1788781925529,\"E\":1788781925529,\"st\":1}}"}
{"receive_ns":1788781925458385000,"stream":"btcusdt@bookTicker","event_type":"bookTicker","event_time_ms":1788781925530,"raw_json":"{\"stream\":\"btcusdt@bookTicker\",\"data\":{\"e\":\"bookTicker\",\"u\":11496321498424,\"s\":\"BTCUSDT\",\"ps\":\"BTCUSDT\",\"b\":\"79382.20\",\"B\":\"15.955\",\"a\":\"79382.30\",\"A\":\"5.017\",\"T\":1788781925530,\"E\":1788781925530,\"st\":1}}"}
{"receive_ns":1788781925464272000,"stream":"btcusdt@bookTicker","event_type":"bookTicker","event_time_ms":1788781925534,"raw_json":"{\"stream\":\"btcusdt@bookTicker\",\"data\":{\"e\":\"bookTicker\",\"u\":11496321498838,\"s\":\"BTCUSDT\",\"ps\":\"BTCUSDT\",\"b\":\"79382.20\",\"B\":\"15.959\",\"a\":\"79382.30\",\"A\":\"5.017\",\"T\":1788781925534,\"E\":1788781925534,\"st\":1}}"}
{"receive_ns":1788781925484881000,"stream":"btcusdt@depth@100ms","event_type":"depthUpdate","event_time_ms":1788781925556,"raw_json":"{\"stream\":\"btcusdt@depth@100ms\",\"data\":{\"e\":\"depthUpdate\",\"E\":1788781925556,\"T\":1788781925554,\"s\":\"BTCUSDT\",\"ps\":\"BTCUSDT\",\"U\":11496321495071,\"u\":11496321500382,\"pu\":11496321494951,\"b\":[[\"1000.00\",\"25.154\"],[\"28982.20\",\"0.413\"],[\"29082.20\",\"1.687\"],[\"71443.90\",\"0.002\"],[\"76206.90\",\"0.000\"],[\"77794.60\",\"1.162\"],[\"78175.70\",\"1.021\"],[\"78406.80\",\"0.016\"],[\"78588.40\",\"4.448\"],[\"78602.00\",\"2.577\"],[\"78604.80\",\"0.014\"],[\"79133.00\",\"0.054\"],[\"79134.10\",\"0.602\"],[\"79158.30\",\"0.000\"],[\"79158.40\",\"2.244\"],[\"79161.60\",\"0.000\"],[\"79161.70\",\"0.000\"],[\"79163.20\",\"0.715\"],[\"79179.40\",\"3.093\"],[\"79179.80\",\"1.800\"],[\"79204.20\",\"1.571\"],[\"79207.40\",\"0.000\"],[\"79207.50\",\"0.019\"],[\"79235.30\",\"0.000\"],[\"79235.40\",\"0.781\"],[\"79238.60\",\"0.010\"],[\"79239.60\",\"1.103\"],[\"79288.70\",\"0.139\"],[\"79292.00\",\"1.207\"],[\"79295.90\",\"1.153\"],[\"79324.00\",\"0.100\"],[\"79324.60\",\"0.313\"],[\"79347.20\",\"0.046\"],[\"79348.30\",\"0.000\"],[\"79354.70\",\"0.453\"],[\"79355.90\",\"0.044\"],[\"79362.00\",\"1.398\"],[\"79363.30\",\"0.003\"],[\"79365.20\",\"0.549\"],[\"79367.10\",\"0.001\"],[\"79376.80\",\"0.238\"],[\"79382.20\",\"15.959\"]],\"a\":[[\"79382.30\",\"5.017\"],[\"79389.30\",\"0.000\"],[\"79401.80\",\"0.614\"],[\"79401.90\",\"1.897\"],[\"79402.90\",\"0.493\"],[\"79403.90\",\"0.022\"],[\"79404.00\",\"0.019\"],[\"79404.10\",\"2.131\"],[\"79406.60\",\"0.004\"],[\"79411.80\",\"0.001\"],[\"79419.80\",\"0.000\"],[\"79751.40\",\"0.874\"],[\"79753.40\",\"0.036\"],[\"79779.30\",\"0.003\"],[\"80176.10\",\"5.302\"],[\"80549.50\",\"4.031\"]],\"st\":1}}"}
{"receive_ns":1788781925585922000,"stream":"btcusdt@depth@100ms","event_type":"depthUpdate","event_time_ms":1788781925658,"raw_json":"{\"stream\":\"btcusdt@depth@100ms\",\"data\":{\"e\":\"depthUpdate\",\"E\":1788781925658,\"T\":1788781925657,\"s\":\"BTCUSDT\",\"ps\":\"BTCUSDT\",\"U\":11496321500478,\"u\":11496321506386,\"pu\":11496321500382,\"b\":[[\"1000.00\",\"25.154\"],[\"28982.20\",\"0.595\"],[\"29082.20\",\"1.505\"],[\"63506.00\",\"0.008\"],[\"71443.90\",\"0.002\"],[\"71444.00\",\"0.045\"],[\"76206.90\",\"0.002\"],[\"78588.40\",\"4.448\"],[\"78985.30\",\"0.387\"],[\"79134.10\",\"0.664\"],[\"79158.40\",\"2.251\"],[\"79161.60\",\"0.000\"],[\"79204.20\",\"1.575\"],[\"79207.40\",\"0.000\"],[\"79235.40\",\"0.783\"],[\"79238.60\",\"0.010\"],[\"79288.70\",\"0.000\"],[\"79288.80\",\"0.140\"],[\"79292.00\",\"1.207\"],[\"79332.80\",\"0.000\"],[\"79377.60\",\"0.005\"]],\"a\":[[\"79401.80\",\"0.048\"],[\"79403.00\",\"1.232\"],[\"79404.10\",\"1.678\"],[\"79405.40\",\"0.454\"],[\"79555.30\",\"0.001\"],[\"79555.40\",\"0.002\"],[\"79751.40\",\"0.907\"],[\"80176.10\",\"5.302\"],[\"80476.30\",\"13.032\"],[\"80501.80\",\"0.005\"]],\"st\":1}}"}
{"receive_ns":1788781925689757000,"stream":"btcusdt@depth@100ms","event_type":"depthUpdate","event_time_ms":1788781925760,"raw_json":"{\"stream\":\"btcusdt@depth@100ms\",\"data\":{\"e\":\"depthUpdate\",\"E\":1788781925760,\"T\":1788781925758,\"s\":\"BTCUSDT\",\"ps\":\"BTCUSDT\",\"U\":11496321506411,\"u\":11496321513324,\"pu\":11496321506386,\"b\":[[\"28982.20\",\"0.770\"],[\"29082.20\",\"1.330\"],[\"63505.80\",\"0.000\"],[\"71443.90\",\"0.002\"],[\"71444.00\",\"0.043\"],[\"78293.60\",\"0.001\"],[\"78389.90\",\"0.848\"],[\"78588.40\",\"4.448\"],[\"78985.30\",\"0.377\"],[\"79134.10\",\"0.876\"],[\"79179.40\",\"3.111\"],[\"79179.80\",\"1.085\"],[\"79207.50\",\"0.001\"],[\"79322.50\",\"0.073\"],[\"79324.60\",\"0.000\"]],\"a\":[[\"79393.50\",\"0.104\"],[\"79751.40\",\"0.432\"],[\"79753.40\",\"0.036\"],[\"80176.10\",\"5.302\"],[\"80493.70\",\"3.348\"],[\"80533.30\",\"0.946\"],[\"80549.20\",\"3.159\"],[\"80573.10\",\"0.284\"],[\"80863.50\",\"0.000\"]],\"st\":1}}"}
{"receive_ns":1788781925751912000,"stream":"btcusdt@bookTicker","event_type":"bookTicker","event_time_ms":1788781925823,"raw_json":"{\"stream\":\"btcusdt@bookTicker\",\"data\":{\"e\":\"bookTicker\",\"u\":11496321517391,\"s\":\"BTCUSDT\",\"ps\":\"BTCUSDT\",\"b\":\"79382.20\",\"B\":\"15.841\",\"a\":\"79382.30\",\"A\":\"5.017\",\"T\":1788781925823,\"E\":1788781925823,\"st\":1}}"}
{"receive_ns":1788781925752344000,"stream":"btcusdt@bookTicker","event_type":"bookTicker","event_time_ms":1788781925823,"raw_json":"{\"stream\":\"btcusdt@bookTicker\",\"data\":{\"e\":\"bookTicker\",\"u\":11496321517392,\"s\":\"BTCUSDT\",\"ps\":\"BTCUSDT\",\"b\":\"79382.20\",\"B\":\"15.374\",\"a\":\"79382.30\",\"A\":\"5.017\",\"T\":1788781925823,\"E\":1788781925823,\"st\":1}}"}
{"receive_ns":1788781925792031000,"stream":"btcusdt@depth@100ms","event_type":"depthUpdate","event_time_ms":1788781925862,"raw_json":"{\"stream\":\"btcusdt@depth@100ms\",\"data\":{\"e\":\"depthUpdate\",\"E\":1788781925862,\"T\":1788781925861,\"s\":\"BTCUSDT\",\"ps\":\"BTCUSDT\",\"U\":11496321513427,\"u\":11496321521673,\"pu\":11496321513324,\"b\":[[\"1000.00\",\"25.154\"],[\"28982.20\",\"0.945\"],[\"29082.20\",\"1.155\"],[\"71443.90\",\"0.002\"],[\"76206.90\",\"0.000\"],[\"78293.50\",\"10.640\"],[\"78588.40\",\"4.448\"],[\"79134.10\",\"1.153\"],[\"79158.40\",\"0.000\"],[\"79161.60\",\"35.371\"],[\"79179.40\",\"3.093\"],[\"79204.20\",\"0.000\"],[\"79207.40\",\"26.513\"],[\"79207.50\",\"0.019\"],[\"79235.40\",\"0.000\"],[\"79238.60\",\"17.678\"],[\"79288.80\",\"0.001\"],[\"79292.00\",\"10.035\"],[\"79322.50\",\"0.070\"],[\"79324.60\",\"0.062\"],[\"79332.80\",\"0.003\"],[\"79337.30\",\"0.002\"],[\"79351.80\",\"0.019\"],[\"79361.10\",\"0.008\"],[\"79382.20\",\"15.374\"]],\"a\":[[\"79389.20\",\"0.002\"],[\"79393.50\",\"0.180\"],[\"79400.90\",\"0.254\"],[\"79421.40\",\"0.000\"],[\"79434.40\",\"0.088\"],[\"79751.40\",\"0.600\"],[\"80176.10\",\"5.302\"],[\"80969.90\",\"1.745\"]],\"st\":1}}"}
{"receive_ns":1788781925795976000,"stream":"btcusdt@bookTicker","event_type":"bookTicker","event_time_ms":1788781925866,"raw_json":"{\"stream\":\"btcusdt@bookTicker\",\"data\":{\"e\":\"bookTicker\",\"u\":11496321522291,\"s\":\"BTCUSDT\",\"ps\":\"BTCUSDT\",\"b\":\"79382.20\",\"B\":\"15.954\",\"a\":\"79382.30\",\"A\":\"5.017\",\"T\":1788781925866,\"E\":1788781925866,\"st\":1}}"}
{"receive_ns":1788781925796390000,"stream":"btcusdt@bookTicker","event_type":"bookTicker","event_time_ms":1788781925867,"raw_json":"{\"stream\":\"btcusdt@bookTicker\",\"data\":{\"e\":\"bookTicker\",\"u\":11496321522418,\"s\":\"BTCUSDT\",\"ps\":\"BTCUSDT\",\"b\":\"79382.20\",\"B\":\"15.956\",\"a\":\"79382.30\",\"A\":\"5.017\",\"T\":1788781925867,\"E\":1788781925867,\"st\":1}}"}
{"receive_ns":1788781925892650000,"stream":"btcusdt@depth@100ms","event_type":"depthUpdate","event_time_ms":1788781925964,"raw_json":"{\"stream\":\"btcusdt@depth@100ms\",\"data\":{\"e\":\"depthUpdate\",\"E\":1788781925964,\"T\":1788781925962,\"s\":\"BTCUSDT\",\"ps\":\"BTCUSDT\",\"U\":11496321521796,\"u\":11496321529027,\"pu\":11496321521673,\"b\":[[\"1000.00\",\"25.154\"],[\"28982.20\",\"1.127\"],[\"29082.20\",\"0.973\"],[\"71443.90\",\"0.002\"],[\"76206.90\",\"0.002\"],[\"78588.40\",\"4.448\"],[\"78781.50\",\"2.536\"],[\"79134.10\",\"0.941\"],[\"79158.50\",\"0.000\"],[\"79161.60\",\"35.371\"],[\"79179.80\",\"1.525\"],[\"79204.30\",\"0.001\"],[\"79207.40\",\"26.513\"],[\"79235.40\",\"0.000\"],[\"79238.60\",\"17.678\"],[\"79259.20\",\"0.037\"],[\"79288.80\",\"0.001\"],[\"79292.00\",\"10.035\"],[\"79345.10\",\"0.087\"],[\"79360.90\",\"0.242\"],[\"79382.20\",\"15.956\"]],\"a\":[[\"79389.20\",\"0.000\"],[\"79417.20\",\"0.051\"],[\"79433.10\",\"1.165\"],[\"79556.20\",\"0.136\"],[\"79751.40\",\"0.815\"],[\"79753.40\",\"0.000\"],[\"79775.90\",\"0.138\"],[\"79779.30\",\"0.002\"],[\"79784.60\",\"0.088\"],[\"80176.10\",\"5.302\"],[\"80476.10\",\"21.235\"],[\"80484.00\",\"2.976\"]],\"st\":1}}"}
{"receive_ns":1788781925995433000,"stream":"btcusdt@depth@100ms","event_type":"depthUpdate","event_time_ms":1788781926066,"raw_json":"{\"stream\":\"btcusdt@depth@100ms\",\"data\":{\"e\":\"depthUpdate\",\"E\":1788781926066,\"T\":1788781926064,\"s\":\"BTCUSDT\",\"ps\":\"BTCUSDT\",\"U\":11496321529146,\"u\":11496321535743,\"pu\":11496321529027,\"b\":[[\"28982.20\",\"1.302\"],[\"29082.20\",\"0.798\"],[\"63506.00\",\"0.008\"],[\"71443.90\",\"0.002\"],[\"76206.90\",\"0.000\"],[\"77960.60\",\"0.011\"],[\"78015.80\",\"0.000\"],[\"78237.90\",\"3.929\"],[\"78588.40\",\"4.448\"],[\"78985.30\",\"0.387\"],[\"79134.10\",\"0.187\"],[\"79150.40\",\"0.020\"],[\"79158.50\",\"0.000\"],[\"79161.60\",\"35.371\"],[\"79179.80\",\"2.190\"],[\"79200.60\",\"0.000\"],[\"79204.30\",\"0.001\"],[\"79207.40\",\"26.513\"],[\"79233.10\",\"0.001\"],[\"79233.40\",\"1.897\"],[\"79235.50\",\"0.000\"],[\"79238.60\",\"17.678\"],[\"79259.20\",\"0.087\"],[\"79288.90\",\"0.100\"],[\"79292.00\",\"10.035\"],[\"79324.60\",\"0.313\"],[\"79366.40\",\"0.076\"]],\"a\":[[\"79389.20\",\"0.002\"],[\"79396.60\",\"0.000\"],[\"79439.30\",\"0.002\"],[\"79449.90\",\"1.498\"],[\"79450.60\",\"5.678\"],[\"79512.40\",\"0.125\"],[\"79512.70\",\"2.797\"],[\"79541.10\",\"0.601\"],[\"79554.90\",\"0.309\"],[\"79556.20\",\"0.011\"],[\"79751.40\",\"0.907\"],[\"79753.40\",\"0.036\"],[\"80176.10\",\"5.302\"]],\"st\":1}}"}
{"receive_ns":1788781926054179000,"stream":"btcusdt@bookTicker","event_type":"bookTicker","event_time_ms":1788781926125,"raw_json":"{\"stream\":\"btcusdt@bookTicker\",\"data\":{\"e\":\"bookTicker\",\"u\":11496321539327,\"s\":\"BTCUSDT\",\"ps\":\"BTCUSDT\",\"b\":\"79382.20\",\"B\":\"15.953\",\"a\":\"79382.30\",\"A\":\"5.017\",\"T\":1788781926125,\"E\":1788781926125,\"st\":1}}"}
{"receive_ns":1788781926054376000,"stream":"btcusdt@trade","event_type":"trade","event_time_ms":1788781926125,"raw_json":"{\"stream\":\"btcusdt@trade\",\"data\":{\"e\":\"trade\",\"E\":1788781926125,\"T\":1788781926125,\"s\":\"BTCUSDT\",\"t\":8057735396,\"p\":\"79382.20\",\"q\":\"0.003\",\"X\":\"MARKET\",\"m\":true,\"st\":1}}"}
{"receive_ns":1788781926080831000,"stream":"btcusdt@bookTicker","event_type":"bookTicker","event_time_ms":1788781926151,"raw_json":"{\"stream\":\"btcusdt@bookTicker\",\"data\":{\"e\":\"bookTicker\",\"u\":11496321540531,\"s\":\"BTCUSDT\",\"ps\":\"BTCUSDT\",\"b\":\"79382.20\",\"B\":\"15.931\",\"a\":\"79382.30\",\"A\":\"5.017\",\"T\":1788781926151,\"E\":1788781926151,\"st\":1}}"}
{"receive_ns":1788781926081091000,"stream":"btcusdt@trade","event_type":"trade","event_time_ms":1788781926151,"raw_json":"{\"stream\":\"btcusdt@trade\",\"data\":{\"e\":\"trade\",\"E\":1788781926151,\"T\":1788781926151,\"s\":\"BTCUSDT\",\"t\":8057735397,\"p\":\"79382.20\",\"q\":\"0.022\",\"X\":\"MARKET\",\"m\":true,\"st\":1}}"}
{"receive_ns":1788781926082836000,"stream":"btcusdt@bookTicker","event_type":"bookTicker","event_time_ms":1788781926153,"raw_json":"{\"stream\":\"btcusdt@bookTicker\",\"data\":{\"e\":\"bookTicker\",\"u\":11496321540681,\"s\":\"BTCUSDT\",\"ps\":\"BTCUSDT\",\"b\":\"79382.20\",\"B\":\"16.483\",\"a\":\"79382.30\",\"A\":\"5.017\",\"T\":1788781926152,\"E\":1788781926153,\"st\":1}}"}
{"receive_ns":1788781926083148000,"stream":"btcusdt@bookTicker","event_type":"bookTicker","event_time_ms":1788781926154,"raw_json":"{\"stream\":\"btcusdt@bookTicker\",\"data\":{\"e\":\"bookTicker\",\"u\":11496321540761,\"s\":\"BTCUSDT\",\"ps\":\"BTCUSDT\",\"b\":\"79382.20\",\"B\":\"16.481\",\"a\":\"79382.30\",\"A\":\"5.017\",\"T\":1788781926154,\"E\":1788781926154,\"st\":1}}"}
{"receive_ns":1788781926095759000,"stream":"btcusdt@depth@100ms","event_type":"depthUpdate","event_time_ms":1788781926168,"raw_json":"{\"stream\":\"btcusdt@depth@100ms\",\"data\":{\"e\":\"depthUpdate\",\"E\":1788781926168,\"T\":1788781926167,\"s\":\"BTCUSDT\",\"ps\":\"BTCUSDT\",\"U\":11496321535812,\"u\":11496321541303,\"pu\":11496321535743,\"b\":[[\"1000.00\",\"25.154\"],[\"28982.20\",\"1.484\"],[\"29082.20\",\"0.616\"],[\"63506.00\",\"0.008\"],[\"71443.90\",\"0.002\"],[\"75413.20\",\"0.000\"],[\"76206.90\",\"0.002\"],[\"78588.40\",\"4.448\"],[\"78985.20\",\"0.001\"],[\"79133.00\",\"0.000\"],[\"79150.40\",\"0.020\"],[\"79158.50\",\"2.249\"],[\"79161.60\",\"0.000\"],[\"79161.70\",\"0.054\"],[\"79179.80\",\"2.190\"],[\"79204.40\",\"1.574\"],[\"79207.40\",\"0.000\"],[\"79235.50\",\"0.782\"],[\"79238.60\",\"0.010\"],[\"79259.20\",\"0.050\"],[\"79288.90\",\"0.239\"],[\"79292.00\",\"1.207\"],[\"79324.60\",\"0.350\"],[\"79336.10\",\"0.001\"],[\"79358.40\",\"0.003\"],[\"79362.00\",\"0.831\"],[\"79363.50\",\"0.616\"],[\"79382.20\",\"16.481\"]],\"a\":[[\"79389.20\",\"0.000\"],[\"79398.50\",\"0.549\"],[\"79400.80\",\"0.000\"],[\"79411.50\",\"0.000\"],[\"79437.50\",\"2.911\"],[\"79437.60\",\"0.003\"],[\"79480.90\",\"0.000\"],[\"79541.10\",\"0.599\"],[\"79751.40\",\"0.907\"],[\"80176.10\",\"5.302\"],[\"80342.90\",\"0.622\"]],\"st\":1}}"}
{"receive_ns":1788781926201908000,"stream":"btcusdt@depth@100ms","event_type":"depthUpdate","event_time_ms":1788781926270,"raw_json":"{\"stream\":\"btcusdt@depth@100ms\",\"data\":{\"e\":\"depthUpdate\",\"E\":1788781926270,\"T\":1788781926269,\"s\":\"BTCUSDT\",\"ps\":\"BTCUSDT\",\"U\":11496321541318,\"u\":11496321546738,\"pu\":11496321541303,\"b\":[[\"1000.00\",\"25.154\"],[\"28982.20\",\"1.666\"],[\"29082.20\",\"0.434\"],[\"58196.00\",\"0.000\"],[\"71443.90\",\"0.002\"],[\"77961.30\",\"0.384\"],[\"78406.60\",\"0.637\"],[\"78588.40\",\"4.448\"],[\"78786.80\",\"1.268\"],[\"79134.10\",\"1.215\"],[\"79158.50\",\"0.000\"],[\"79161.60\",\"35.371\"],[\"79179.40\",\"3.111\"],[\"79179.80\",\"1.525\"],[\"79204.40\",\"0.000\"],[\"79207.50\",\"26.514\"],[\"79235.50\",\"0.000\"],[\"79238.60\",\"17.678\"],[\"79259.20\",\"0.000\"],[\"79288.90\",\"0.100\"],[\"79292.00\",\"10.035\"],[\"79324.60\",\"0.037\"]],\"a\":[[\"79391.30\",\"0.094\"],[\"79392.70\",\"0.418\"],[\"79395.20\",\"0.001\"],[\"79395.90\",\"0.630\"],[\"79416.40\",\"0.000\"],[\"79479.40\",\"0.009\"],[\"79555.70\",\"0.001\"],[\"79556.30\",\"0.123\"],[\"79751.40\",\"0.907\"],[\"79753.40\",\"0.036\"],[\"80176.10\",\"5.302\"],[\"80334.90\",\"4.504\"],[\"80509.50\",\"1.192\"]],\"st\":1}}"}
{"receive_ns":1788781926309044000,"stream":"btcusdt@depth@100ms","event_type":"depthUpdate","event_time_ms":1788781926372,"raw_json":"{\"stream\":\"btcusdt@depth@100ms\",\"data\":{\"e\":\"depthUpdate\",\"E\":1788781926372,\"T\":1788781926369,\"s\":\"BTCUSDT\",\"ps\":\"BTCUSDT\",\"U\":11496321546829,\"u\":11496321551950,\"pu\":11496321546738,\"b\":[[\"28882.20\",\"0.028\"],[\"28982.20\",\"1.785\"],[\"29082.20\",\"0.287\"],[\"71443.90\",\"0.002\"],[\"75413.10\",\"0.008\"],[\"76206.90\",\"0.000\"],[\"78032.70\",\"5.119\"],[\"78389.90\",\"1.134\"],[\"78424.30\",\"30.940\"],[\"78588.40\",\"4.448\"],[\"78985.30\",\"0.387\"],[\"79134.10\",\"1.153\"],[\"79150.40\",\"0.000\"],[\"79179.40\",\"3.093\"],[\"79179.80\",\"1.525\"],[\"79207.60\",\"0.028\"],[\"79306.70\",\"0.002\"],[\"79324.60\",\"0.099\"],[\"79352.90\",\"0.282\"]],\"a\":[[\"79391.30\",\"0.474\"],[\"79392.70\",\"0.038\"],[\"79410.80\",\"0.167\"],[\"79411.50\",\"0.629\"],[\"79437.90\",\"0.243\"],[\"79751.40\",\"0.907\"],[\"80176.10\",\"5.302\"],[\"80374.60\",\"1.565\"]],\"st\":1}}"}
{"receive_ns":1788781926401430000,"stream":"btcusdt@depth@100ms","event_type":"depthUpdate","event_time_ms":1788781926474,"raw_json":"{\"stream\":\"btcusdt@depth@100ms\",\"data\":{\"e\":\"depthUpdate\",\"E\":1788781926474,\"T\":1788781926473,\"s\":\"BTCUSDT\",\"ps\":\"BTCUSDT\",\"U\":11496321552168,\"u\":11496321557546,\"pu\":11496321551950,\"b\":[[\"1000.00\",\"25.154\"],[\"28882.20\",\"0.091\"],[\"28982.20\",\"1.841\"],[\"29082.20\",\"0.168\"],[\"71443.90\",\"0.002\"],[\"76206.90\",\"0.002\"],[\"78588.40\",\"4.448\"],[\"79134.10\",\"0.125\"],[\"79158.60\",\"2.250\"],[\"79161.60\",\"0.000\"],[\"79163.20\",\"5.909\"],[\"79204.40\",\"1.574\"],[\"79207.50\",\"0.001\"],[\"79207.60\",\"4.103\"],[\"79235.60\",\"0.782\"],[\"79238.60\",\"0.010\"],[\"79239.60\",\"3.600\"],[\"79289.00\",\"0.524\"],[\"79292.00\",\"1.207\"],[\"79295.90\",\"3.167\"],[\"79346.40\",\"0.722\"]],\"a\":[[\"79555.60\",\"0.000\"],[\"79751.40\",\"0.340\"],[\"79753.40\",\"0.000\"],[\"80176.10\",\"5.302\"],[\"80422.40\",\"0.621\"],[\"80493.70\",\"3.967\"],[\"80969.90\",\"1.742\"]],\"st\":1}}"}
{"receive_ns":1788781926415321000,"stream":"btcusdt@bookTicker","event_type":"bookTicker","event_time_ms":1788781926485,"raw_json":"{\"stream\":\"btcusdt@bookTicker\",\"data\":{\"e\":\"bookTicker\",\"u\":11496321558020,\"s\":\"BTCUSDT\",\"ps\":\"BTCUSDT\",\"b\":\"79382.20\",\"B\":\"16.481\",\"a\":\"79382.30\",\"A\":\"5.015\",\"T\":1788781926485,\"E\":1788781926485,\"st\":1}}"}
{"receive_ns":1788781926417876000,"stream":"btcusdt@bookTicker","event_type":"bookTicker","event_time_ms":1788781926489,"raw_json":"{\"stream\":\"btcusdt@bookTicker\",\"data\":{\"e\":\"bookTicker\",\"u\":11496321558219,\"s\":\"BTCUSDT\",\"ps\":\"BTCUSDT\",\"b\":\"79382.20\",\"B\":\"16.482\",\"a\":\"79382.30\",\"A\":\"5.015\",\"T\":1788781926489,\"E\":1788781926489,\"st\":1}}"}
{"receive_ns":1788781926473285000,"stream":"btcusdt@bookTicker","event_type":"bookTicker","event_time_ms":1788781926545,"raw_json":"{\"stream\":\"btcusdt@bookTicker\",\"data\":{\"e\":\"bookTicker\",\"u\":11496321564484,\"s\":\"BTCUSDT\",\"ps\":\"BTCUSDT\",\"b\":\"79382.20\",\"B\":\"16.482\",\"a\":\"79382.30\",\"A\":\"5.053\",\"T\":1788781926545,\"E\":1788781926545,\"st\":1}}"}
{"receive_ns":1788781926475362000,"stream":"btcusdt@bookTicker","event_type":"bookTicker","event_time_ms":1788781926546,"raw_json":"{\"stream\":\"btcusdt@bookTicker\",\"data\":{\"e\":\"bookTicker\",\"u\":11496321564560,\"s\":\"BTCUSDT\",\"ps\":\"BTCUSDT\",\"b\":\"79382.20\",\"B\":\"16.484\",\"a\":\"79382.30\",\"A\":\"5.053\",\"T\":1788781926546,\"E\":1788781926546,\"st\":1}}"}
{"receive_ns":1788781926504367000,"stream":"btcusdt@depth@100ms","event_type":"depthUpdate","event_time_ms":1788781926576,"raw_json":"{\"stream\":\"btcusdt@depth@100ms\",\"data\":{\"e\":\"depthUpdate\",\"E\":1788781926576,\"T\":1788781926574,\"s\":\"BTCUSDT\",\"ps\":\"BTCUSDT\",\"U\":11496321557564,\"u\":11496321566535,\"pu\":11496321557546,\"b\":[[\"1000.00\",\"25.154\"],[\"28882.20\",\"0.147\"],[\"28982.20\",\"1.904\"],[\"29082.20\",\"0.049\"],[\"63506.00\",\"0.008\"],[\"71443.90\",\"0.002\"],[\"76206.90\",\"0.000\"],[\"78389.90\",\"1.325\"],[\"78588.40\",\"4.448\"],[\"78604.80\",\"0.011\"],[\"78606.70\",\"0.641\"],[\"79133.00\",\"0.054\"],[\"79134.10\",\"1.215\"],[\"79150.40\",\"0.000\"],[\"79153.50\",\"0.000\"],[\"79158.60\",\"0.000\"],[\"79161.60\",\"35.371\"],[\"79161.70\",\"0.000\"],[\"79163.20\",\"0.715\"],[\"79179.80\",\"1.085\"],[\"79204.40\",\"0.000\"],[\"79207.50\",\"26.514\"],[\"79207.60\",\"0.028\"],[\"79235.60\",\"0.000\"],[\"79238.60\",\"17.678\"],[\"79239.60\",\"1.103\"],[\"79289.00\",\"0.385\"],[\"79292.00\",\"10.035\"],[\"79295.90\",\"1.153\"],[\"79324.60\",\"0.000\"],[\"79354.70\",\"0.000\"],[\"79355.90\",\"0.497\"],[\"79357.00\",\"0.001\"],[\"79358.30\",\"0.078\"],[\"79360.90\",\"0.240\"],[\"79365.20\",\"0.549\"],[\"79365.50\",\"0.252\"],[\"79365.80\",\"0.256\"],[\"79366.40\",\"0.000\"],[\"79367.10\",\"0.001\"],[\"79367.20\",\"0.001\"],[\"79371.90\",\"0.104\"],[\"79382.20\",\"16.484\"]],\"a\":[[\"79382.30\",\"5.053\"],[\"79391.30\",\"0.470\"],[\"79392.70\",\"0.042\"],[\"79392.80\",\"1.046\"],[\"79402.90\",\"0.053\"],[\"79403.00\",\"0.666\"],[\"79404.00\",\"1.025\"],[\"79405.40\",\"0.001\"],[\"79406.60\",\"0.457\"],[\"79437.50\",\"2.861\"],[\"79437.60\",\"0.053\"],[\"79453.80\",\"0.004\"],[\"79751.40\",\"0.600\"],[\"79753.40\",\"0.036\"],[\"79779.30\",\"0.001\"],[\"80136.70\",\"4.497\"],[\"80176.10\",\"5.302\"]],\"st\":1}}"}
{"receive_ns":1788781926607578000,"stream":"btcusdt@depth@100ms","event_type":"depthUpdate","event_time_ms":1788781926678,"raw_json":"{\"stream\":\"btcusdt@depth@100ms\",\"data\":{\"e\":\"depthUpdate\",\"E\":1788781926678,\"T\":1788781926674,\"s\":\"BTCUSDT\",\"ps\":\"BTCUSDT\",\"U\":11496321566672,\"u\":11496321572050,\"pu\":11496321566535,\"b\":[[\"28882.20\",\"0.273\"],[\"28982.20\",\"1.827\"],[\"29082.20\",\"0.000\"],[\"63506.00\",\"0.008\"],[\"71443.90\",\"0.002\"],[\"78032.70\",\"5.758\"],[\"78588.40\",\"4.448\"],[\"78747.10\",\"4.693\"],[\"78985.20\",\"0.002\"],[\"78985.30\",\"0.387\"],[\"79158.60\",\"2.249\"],[\"79161.60\",\"0.000\"],[\"79166.20\",\"0.020\"],[\"79174.70\",\"0.015\"],[\"79176.00\",\"0.393\"],[\"79179.80\",\"1.525\"],[\"79204.50\",\"1.574\"],[\"79207.50\",\"0.001\"],[\"79207.90\",\"3.191\"],[\"79208.40\",\"0.939\"],[\"79235.60\",\"0.782\"],[\"79238.60\",\"0.010\"],[\"79289.00\",\"0.524\"],[\"79292.00\",\"1.207\"],[\"79298.20\",\"0.038\"],[\"79298.70\",\"0.019\"],[\"79322.50\",\"0.073\"],[\"79324.60\",\"0.037\"],[\"79332.80\",\"0.000\"],[\"79365.20\",\"0.108\"],[\"79365.40\",\"0.235\"],[\"79365.80\",\"0.252\"],[\"79367.10\",\"0.442\"]],\"a\":[[\"79391.20\",\"0.087\"],[\"79392.70\",\"0.038\"],[\"79396.90\",\"0.435\"],[\"79454.70\",\"0.060\"],[\"79472.90\",\"1.238\"],[\"79473.40\",\"0.001\"],[\"79483.10\",\"0.234\"],[\"79528.40\",\"3.150\"],[\"79529.80\",\"0.000\"],[\"79556.70\",\"0.125\"],[\"79619.20\",\"0.252\"],[\"79751.40\",\"0.907\"],[\"80136.40\",\"1.721\"],[\"80176.10\",\"5.302\"],[\"80969.90\",\"1.745\"]],\"st\":1}}"}
{"receive_ns":1788781926689069000,"stream":"btcusdt@bookTicker","event_type":"bookTicker","event_time_ms":1788781926760,"raw_json":"{\"stream\":\"btcusdt@bookTicker\",\"data\":{\"e\":\"bookTicker\",\"u\":11496321576368,\"s\":\"BTCUSDT\",\"ps\":\"BTCUSDT\",\"b\":\"79382.20\",\"B\":\"16.484\",\"a\":\"79382.30\",\"A\":\"5.026\",\"T\":1788781926760,\"E\":1788781926760,\"st\":1}}"}
{"receive_ns":1788781926689444000,"stream":"btcusdt@trade","event_type":"trade","event_time_ms":1788781926760,"raw_json":"{\"stream\":\"btcusdt@trade\",\"data\":{\"e\":\"trade\",\"E\":1788781926760,\"T\":1788781926760,\"s\":\"BTCUSDT\",\"t\":8057735398,\"p\":\"79382.30\",\"q\":\"0.027\",\"X\":\"MARKET\",\"m\":false,\"st\":1}}"}
{"receive_ns":1788781926691289000,"stream":"btcusdt@bookTicker","event_type":"bookTicker","event_time_ms":1788781926762,"raw_json":"{\"stream\":\"btcusdt@bookTicker\",\"data\":{\"e\":\"bookTicker\",\"u\":11496321576531,\"s\":\"BTCUSDT\",\"ps\":\"BTCUSDT\",\"b\":\"79382.20\",\"B\":\"16.574\",\"a\":\"79382.30\",\"A\":\"5.026\",\"T\":1788781926762,\"E\":1788781926762,\"st\":1}}"}
{"receive_ns":1788781926710309000,"stream":"btcusdt@depth@100ms","event_type":"depthUpdate","event_time_ms":1788781926780,"raw_json":"{\"stream\":\"btcusdt@depth@100ms\",\"data\":{\"e\":\"depthUpdate\",\"E\":1788781926780,\"T\":1788781926778,\"s\":\"BTCUSDT\",\"ps\":\"BTCUSDT\",\"U\":11496321572203,\"u\":11496321577139,\"pu\":11496321572050,\"b\":[[\"1000.00\",\"25.154\"],[\"28882.20\",\"0.455\"],[\"28982.20\",\"1.645\"],[\"63505.80\",\"0.000\"],[\"71443.90\",\"0.002\"],[\"75413.10\",\"0.006\"],[\"75413.20\",\"0.002\"],[\"76206.90\",\"0.002\"],[\"78365.50\",\"0.108\"],[\"78588.40\",\"4.448\"],[\"79133.00\",\"0.000\"],[\"79134.10\",\"0.125\"],[\"79144.00\",\"0.173\"],[\"79158.60\",\"0.000\"],[\"79158.70\",\"2.248\"],[\"79161.60\",\"0.000\"],[\"79161.70\",\"0.054\"],[\"79166.20\",\"0.000\"],[\"79179.80\",\"1.965\"],[\"79204.50\",\"1.574\"],[\"79207.50\",\"0.001\"],[\"79235.60\",\"0.000\"],[\"79235.70\",\"0.782\"],[\"79238.60\",\"0.010\"],[\"79259.20\",\"0.100\"],[\"79289.00\",\"0.524\"],[\"79292.00\",\"1.207\"],[\"79324.60\",\"0.525\"],[\"79357.50\",\"0.077\"],[\"79365.20\",\"0.549\"],[\"79366.60\",\"0.080\"],[\"79367.10\",\"0.001\"],[\"79368.00\",\"0.036\"],[\"79382.20\",\"16.574\"]],\"a\":[[\"79382.30\",\"5.026\"],[\"79389.20\",\"0.002\"],[\"79448.10\",\"0.201\"],[\"79456.10\",\"0.275\"],[\"79479.90\",\"0.212\"],[\"79556.20\",\"0.011\"],[\"79556.30\",\"0.123\"],[\"79556.70\",\"0.000\"],[\"79749.40\",\"0.087\"],[\"79751.40\",\"0.847\"],[\"79753.40\",\"0.036\"],[\"79797.40\",\"0.556\"],[\"80176.10\",\"5.302\"],[\"80357.10\",\"13.385\"],[\"80969.90\",\"1.739\"]],\"st\":1}}"}
{"receive_ns":1788781926744285000,"stream":"btcusdt@bookTicker","event_type":"bookTicker","event_time_ms":1788781926816,"raw_json":"{\"stream\":\"btcusdt@bookTicker\",\"data\":{\"e\":\"bookTicker\",\"u\":11496321578395,\"s\":\"BTCUSDT\",\"ps\":\"BTCUSDT\",\"b\":\"79382.20\",\"B\":\"16.574\",\"a\":\"79382.30\",\"A\":\"5.025\",\"T\":1788781926816,\"E\":1788781926816,\"st\":1}}"}
{"receive_ns":1788781926747955000,"stream":"btcusdt@bookTicker","event_type":"bookTicker","event_time_ms":1788781926819,"raw_json":"{\"stream\":\"btcusdt@bookTicker\",\"data\":{\"e\":\"bookTicker\",\"u\":11496321578546,\"s\":\"BTCUSDT\",\"ps\":\"BTCUSDT\",\"b\":\"79382.20\",\"B\":\"16.574\",\"a\":\"79382.30\",\"A\":\"5.027\",\"T\":1788781926819,\"E\":1788781926819,\"st\":1}}"}
{"receive_ns":1788781926812520000,"stream":"btcusdt@depth@100ms","event_type":"depthUpdate","event_time_ms":1788781926882,"raw_json":"{\"stream\":\"btcusdt@depth@100ms\",\"data\":{\"e\":\"depthUpdate\",\"E\":1788781926882,\"T\":1788781926881,\"s\":\"BTCUSDT\",\"ps\":\"BTCUSDT\",\"U\":11496321577227,\"u\":11496321581128,\"pu\":11496321577139,\"b\":[[\"1000.00\",\"25.154\"],[\"28882.20\",\"0.630\"],[\"28982.20\",\"1.470\"],[\"71443.90\",\"0.002\"],[\"76206.90\",\"0.000\"],[\"78588.40\",\"4.448\"],[\"79134.10\",\"0.187\"],[\"79144.00\",\"0.173\"],[\"79158.70\",\"0.000\"],[\"79161.60\",\"35.371\"],[\"79166.20\",\"0.000\"],[\"79179.80\",\"1.965\"],[\"79204.50\",\"0.000\"],[\"79207.50\",\"26.514\"],[\"79235.70\",\"0.000\"],[\"79238.60\",\"17.678\"],[\"79289.00\",\"0.385\"],[\"79292.00\",\"10.035\"],[\"79324.60\",\"0.400\"],[\"79352.40\",\"0.002\"],[\"79355.70\",\"0.299\"],[\"79361.10\",\"0.008\"],[\"79365.20\",\"0.549\"],[\"79367.10\",\"0.001\"]],\"a\":[[\"79382.30\",\"5.027\"],[\"79400.90\",\"0.254\"],[\"79751.40\",\"0.880\"],[\"80176.10\",\"5.302\"],[\"80317.60\",\"9.574\"],[\"80350.60\",\"1.863\"],[\"80357.10\",\"13.237\"]],\"st\":1}}"}
{"receive_ns":1788781926863528000,"stream":"btcusdt@bookTicker","event_type":"bookTicker","event_time_ms":1788781926933,"raw_json":"{\"stream\":\"btcusdt@bookTicker\",\"data\":{\"e\":\"bookTicker\",\"u\":11496321583843,\"s\":\"BTCUSDT\",\"ps\":\"BTCUSDT\",\"b\":\"79382.20\",\"B\":\"16.575\",\"a\":\"79382.30\",\"A\":\"5.027\",\"T\":1788781926933,\"E\":1788781926933,\"st\":1}}"}
{"receive_ns":1788781926914070000,"stream":"btcusdt@depth@100ms","event_type":"depthUpdate","event_time_ms":1788781926984,"raw_json":"{\"stream\":\"btcusdt@depth@100ms\",\"data\":{\"e\":\"depthUpdate\",\"E\":1788781926984,\"T\":1788781926981,\"s\":\"BTCUSDT\",\"ps\":\"BTCUSDT\",\"U\":11496321581151,\"u\":11496321586939,\"pu\":11496321581128,\"b\":[[\"28882.20\",\"0.812\"],[\"28982.20\",\"1.288\"],[\"71443.90\",\"0.002\"],[\"76206.90\",\"0.002\"],[\"78237.90\",\"3.776\"],[\"78588.40\",\"4.448\"],[\"78985.30\",\"0.387\"],[\"79133.00\",\"0.054\"],[\"79150.40\",\"0.020\"],[\"79158.70\",\"2.251\"],[\"79161.60\",\"0.000\"],[\"79161.70\",\"0.000\"],[\"79179.40\",\"3.111\"],[\"79179.80\",\"1.525\"],[\"79204.50\",\"1.576\"],[\"79207.50\",\"0.001\"],[\"79207.60\",\"0.010\"],[\"79235.70\",\"0.783\"],[\"79238.60\",\"0.010\"],[\"79259.20\",\"0.000\"],[\"79289.10\",\"0.187\"],[\"79292.00\",\"1.207\"],[\"79324.60\",\"0.037\"],[\"79338.00\",\"1.176\"],[\"79352.00\",\"1.995\"],[\"79353.90\",\"1.054\"],[\"79366.90\",\"0.101\"],[\"79382.20\",\"16.575\"]],\"a\":[[\"79402.20\",\"0.178\"],[\"79404.70\",\"1.309\"],[\"79415.40\",\"0.261\"],[\"79541.10\",\"0.601\"],[\"79556.20\",\"0.011\"],[\"79556.50\",\"0.409\"],[\"79749.40\",\"0.060\"],[\"79751.40\",\"0.340\"],[\"79753.40\",\"0.000\"],[\"80176.10\",\"5.302\"]],\"st\":1}}"}
{"receive_ns":1788781926932443000,"stream":"btcusdt@bookTicker","event_type":"bookTicker","event_time_ms":1788781927003,"raw_json":"{\"stream\":\"btcusdt@bookTicker\",\"data\":{\"e\":\"bookTicker\",\"u\":11496321588237,\"s\":\"BTCUSDT\",\"ps\":\"BTCUSDT\",\"b\":\"79382.20\",\"B\":\"16.516\",\"a\":\"79382.30\",\"A\":\"5.027\",\"T\":1788781927002,\"E\":1788781927003,\"st\":1}}"}
{"receive_ns":1788781926952068000,"stream":"btcusdt@bookTicker","event_type":"bookTicker","event_time_ms":1788781927023,"raw_json":"{\"stream\":\"btcusdt@bookTicker\",\"data\":{\"e\":\"bookTicker\",\"u\":11496321590283,\"s\":\"BTCUSDT\",\"ps\":\"BTCUSDT\",\"b\":\"79382.20\",\"B\":\"16.510\",\"a\":\"79382.30\",\"A\":\"5.027\",\"T\":1788781927023,\"E\":1788781927023,\"st\":1}}"}
{"receive_ns":1788781926956311000,"stream":"btcusdt@bookTicker","event_type":"bookTicker","event_time_ms":1788781927027,"raw_json":"{\"stream\":\"btcusdt@bookTicker\",\"data\":{\"e\":\"bookTicker\",\"u\":11496321590495,\"s\":\"BTCUSDT\",\"ps\":\"BTCUSDT\",\"b\":\"79382.20\",\"B\":\"16.517\",\"a\":\"79382.30\",\"A\":\"5.027\",\"T\":1788781927026,\"E\":1788781927027,\"st\":1}}"}
{"receive_ns":1788781926956595000,"stream":"btcusdt@bookTicker","event_type":"bookTicker","event_time_ms":1788781927027,"raw_json":"{\"stream\":\"btcusdt@bookTicker\",\"data\":{\"e\":\"bookTicker\",\"u\":11496321590523,\"s\":\"BTCUSDT\",\"ps\":\"BTCUSDT\",\"b\":\"79382.20\",\"B\":\"16.517\",\"a\":\"79382.30\",\"A\":\"5.024\",\"T\":1788781927027,\"E\":1788781927027,\"st\":1}}"}
{"receive_ns":1788781926956874000,"stream":"btcusdt@trade","event_type":"trade","event_time_ms":1788781927027,"raw_json":"{\"stream\":\"btcusdt@trade\",\"data\":{\"e\":\"trade\",\"E\":1788781927027,\"T\":1788781927027,\"s\":\"BTCUSDT\",\"t\":8057735399,\"p\":\"79382.30\",\"q\":\"0.003\",\"X\":\"MARKET\",\"m\":false,\"st\":1}}"}
{"receive_ns":1788781927015532000,"stream":"btcusdt@depth@100ms","event_type":"depthUpdate","event_time_ms":1788781927086,"raw_json":"{\"stream\":\"btcusdt@depth@100ms\",\"data\":{\"e\":\"depthUpdate\",\"E\":1788781927086,\"T\":1788781927085,\"s\":\"BTCUSDT\",\"ps\":\"BTCUSDT\",\"U\":11496321587070,\"u\":11496321594930,\"pu\":11496321586939,\"b\":[[\"1000.00\",\"25.154\"],[\"28882.20\",\"0.987\"],[\"28982.20\",\"1.113\"],[\"71443.90\",\"0.002\"],[\"75413.10\",\"0.004\"],[\"75413.20\",\"0.004\"],[\"76206.90\",\"0.000\"],[\"78588.40\",\"4.448\"],[\"78985.20\",\"0.001\"],[\"79134.10\",\"1.692\"],[\"79158.70\",\"2.249\"],[\"79161.60\",\"0.000\"],[\"79179.80\",\"1.085\"],[\"79204.50\",\"1.574\"],[\"79207.50\",\"0.001\"],[\"79235.70\",\"0.782\"],[\"79238.60\",\"0.010\"],[\"79289.10\",\"0.187\"],[\"79292.00\",\"1.207\"],[\"79322.50\",\"0.070\"],[\"79324.60\",\"0.000\"],[\"79331.90\",\"1.244\"],[\"79332.00\",\"0.007\"],[\"79362.90\",\"0.000\"],[\"79365.20\",\"0.549\"],[\"79366.80\",\"0.100\"],[\"79367.10\",\"0.001\"],[\"79367.30\",\"0.026\"],[\"79368.00\",\"0.010\"],[\"79379.30\",\"0.001\"],[\"79381.30\",\"0.003\"],[\"79382.20\",\"16.517\"]],\"a\":[[\"79382.30\",\"5.024\"],[\"79390.30\",\"0.118\"],[\"79396.60\",\"0.000\"],[\"79469.80\",\"0.323\"],[\"79541.10\",\"0.599\"],[\"79556.40\",\"0.003\"],[\"79556.50\",\"0.409\"],[\"79751.40\",\"0.907\"],[\"79753.40\",\"0.036\"],[\"79862.40\",\"0.006\"],[\"79943.70\",\"0.060\"],[\"80176.10\",\"5.302\"],[\"80390.40\",\"0.621\"],[\"80406.40\",\"0.001\"],[\"80730.30\",\"0.000\"]],\"st\":1}}"}
{"receive_ns":1788781927084019000,"stream":"btcusdt@bookTicker","event_type":"bookTicker","event_time_ms":1788781927155,"raw_json":"{\"stream\":\"btcusdt@bookTicker\",\"data\":{\"e\":\"bookTicker\",\"u\":11496321599926,\"s\":\"BTCUSDT\",\"ps\":\"BTCUSDT\",\"b\":\"79382.20\",\"B\":\"16.380\",\"a\":\"79382.30\",\"A\":\"5.024\",\"T\":1788781927155,\"E\":1788781927155,\"st\":1}}"}
{"receive_ns":1788781927084215000,"stream":"btcusdt@trade","event_type":"trade","event_time_ms":1788781927155,"raw_json":"{\"stream\":\"btcusdt@trade\",\"data\":{\"e\":\"trade\",\"E\":1788781927155,\"T\":1788781927155,\"s\":\"BTCUSDT\",\"t\":8057735400,\"p\":\"79382.20\",\"q\":\"0.082\",\"X\":\"MARKET\",\"m\":true,\"st\":1}}"}
{"receive_ns":1788781927084340000,"stream":"btcusdt@trade","event_type":"trade","event_time_ms":1788781927155,"raw_json":"{\"stream\":\"btcusdt@trade\",\"data\":{\"e\":\"trade\",\"E\":1788781927155,\"T\":1788781927155,\"s\":\"BTCUSDT\",\"t\":8057735401,\"p\":\"79382.20\",\"q\":\"0.055\",\"X\":\"MARKET\",\"m\":true,\"st\":1}}"}
{"receive_ns":1788781927105145000,"stream":"btcusdt@bookTicker","event_type":"bookTicker","event_time_ms":1788781927159,"raw_json":"{\"stream\":\"btcusdt@bookTicker\",\"data\":{\"e\":\"bookTicker\",\"u\":11496321600213,\"s\":\"BTCUSDT\",\"ps\":\"BTCUSDT\",\"b\":\"79382.20\",\"B\":\"16.380\",\"a\":\"79382.30\",\"A\":\"5.025\",\"T\":1788781927159,\"E\":1788781927159,\"st\":1}}"}
{"receive_ns":1788781927141164000,"stream":"btcusdt@depth@100ms","event_type":"depthUpdate","event_time_ms":1788781927188,"raw_json":"{\"stream\":\"btcusdt@depth@100ms\",\"data\":{\"e\":\"depthUpdate\",\"E\":1788781927188,\"T\":1788781927187,\"s\":\"BTCUSDT\",\"ps\":\"BTCUSDT\",\"U\":11496321595100,\"u\":11496321601514,\"pu\":11496321594930,\"b\":[[\"28882.20\",\"1.169\"],[\"28982.20\",\"0.931\"],[\"71443.90\",\"0.002\"],[\"78413.90\",\"0.637\"],[\"78583.00\",\"8.478\"],[\"78588.40\",\"4.448\"],[\"78781.50\",\"1.902\"],[\"78982.50\",\"1.655\"],[\"78982.60\",\"0.002\"],[\"79150.40\",\"0.020\"],[\"79158.70\",\"2.251\"],[\"79161.60\",\"0.000\"],[\"79204.50\",\"0.000\"],[\"79204.60\",\"1.577\"],[\"79207.50\",\"0.001\"],[\"79235.70\",\"0.783\"],[\"79238.60\",\"0.010\"],[\"79289.10\",\"0.187\"],[\"79292.00\",\"1.207\"],[\"79354.70\",\"0.453\"],[\"79355.90\",\"0.044\"],[\"79357.00\",\"0.001\"],[\"79361.90\",\"0.643\"],[\"79362.10\",\"0.574\"],[\"79362.80\",\"2.101\"],[\"79363.10\",\"0.102\"],[\"79363.50\",\"0.049\"],[\"79364.20\",\"0.002\"],[\"79365.20\",\"0.549\"],[\"79365.30\",\"0.267\"],[\"79365.40\",\"0.231\"],[\"79365.50\",\"0.315\"],[\"79365.60\",\"0.006\"],[\"79367.10\",\"0.001\"],[\"79371.90\",\"0.104\"],[\"79376.80\",\"0.238\"],[\"79382.20\",\"16.380\"]],\"a\":[[\"79382.30\",\"5.025\"],[\"79383.10\",\"0.332\"],[\"79385.60\",\"0.001\"],[\"79386.90\",\"0.003\"],[\"79389.20\",\"0.000\"],[\"79401.70\",\"0.001\"],[\"79401.80\",\"0.488\"],[\"79401.90\",\"1.897\"],[\"79402.90\",\"0.619\"],[\"79403.00\",\"0.666\"],[\"79404.00\",\"0.019\"],[\"79416.20\",\"0.038\"],[\"79426.20\",\"0.252\"],[\"79448.10\",\"0.001\"],[\"79456.10\",\"0.075\"],[\"79479.20\",\"0.001\"],[\"79479.90\",\"0.012\"],[\"79481.00\",\"0.002\"],[\"79556.50\",\"0.284\"],[\"79776.20\",\"0.002\"],[\"79776.30\",\"2.048\"],[\"79779.30\",\"0.002\"],[\"79797.40\",\"0.006\"],[\"80176.10\",\"5.302\"],[\"80969.90\",\"1.742\"]],\"st\":1}}"}
{"receive_ns":1788781927212394000,"stream":"btcusdt@bookTicker","event_type":"bookTicker","event_time_ms":1788781927284,"raw_json":"{\"stream\":\"btcusdt@bookTicker\",\"data\":{\"e\":\"bookTicker\",\"u\":11496321607371,\"s\":\"BTCUSDT\",\"ps\":\"BTCUSDT\",\"b\":\"79382.20\",\"B\":\"16.380\",\"a\":\"79382.30\",\"A\":\"4.996\",\"T\":1788781927283,\"E\":1788781927284,\"st\":1}}"}
{"receive_ns":1788781927212826000,"stream":"btcusdt@bookTicker","event_type":"bookTicker","event_time_ms":1788781927284,"raw_json":"{\"stream\":\"btcusdt@bookTicker\",\"data\":{\"e\":\"bookTicker\",\"u\":11496321607431,\"s\":\"BTCUSDT\",\"ps\":\"BTCUSDT\",\"b\":\"79382.20\",\"B\":\"16.380\",\"a\":\"79382.30\",\"A\":\"5.026\",\"T\":1788781927284,\"E\":1788781927284,\"st\":1}}"}
{"receive_ns":1788781927218977000,"stream":"btcusdt@depth@100ms","event_type":"depthUpdate","event_time_ms":1788781927290,"raw_json":"{\"stream\":\"btcusdt@depth@100ms\",\"data\":{\"e\":\"depthUpdate\",\"E\":1788781927290,\"T\":1788781927289,\"s\":\"BTCUSDT\",\"ps\":\"BTCUSDT\",\"U\":11496321601581,\"u\":11496321607772,\"pu\":11496321601514,\"b\":[[\"28882.20\",\"1.351\"],[\"28982.20\",\"0.749\"],[\"71443.90\",\"0.002\"],[\"76206.90\",\"0.002\"],[\"78588.40\",\"4.448\"],[\"78985.30\",\"0.377\"],[\"79134.10\",\"0.187\"],[\"79150.40\",\"0.015\"],[\"79158.70\",\"0.000\"],[\"79158.80\",\"2.251\"],[\"79161.60\",\"0.000\"],[\"79204.60\",\"1.577\"],[\"79207.50\",\"0.001\"],[\"79235.70\",\"0.000\"],[\"79235.80\",\"0.795\"],[\"79238.60\",\"0.010\"],[\"79259.20\",\"0.540\"],[\"79289.10\",\"0.048\"],[\"79289.20\",\"0.167\"],[\"79292.00\",\"1.207\"],[\"79324.60\",\"0.488\"],[\"79361.90\",\"0.076\"],[\"79362.90\",\"0.567\"],[\"79364.30\",\"0.000\"],[\"79365.20\",\"0.549\"],[\"79366.60\",\"0.004\"],[\"79367.10\",\"0.001\"]],\"a\":[[\"79382.30\",\"5.026\"],[\"79390.20\",\"0.004\"],[\"79401.80\",\"0.048\"],[\"79402.90\",\"0.053\"],[\"79404.00\",\"1.498\"],[\"79404.10\",\"1.587\"],[\"79556.70\",\"0.000\"],[\"79751.40\",\"0.600\"],[\"79753.40\",\"0.036\"],[\"79773.80\",\"4.028\"],[\"80176.10\",\"5.302\"],[\"80334.90\",\"4.628\"],[\"80523.70\",\"0.371\"]],\"st\":1}}"}
{"receive_ns":1788781927319365000,"stream":"btcusdt@depth@100ms","event_type":"depthUpdate","event_time_ms":1788781927392,"raw_json":"{\"stream\":\"btcusdt@depth@100ms\",\"data\":{\"e\":\"depthUpdate\",\"E\":1788781927392,\"T\":1788781927389,\"s\":\"BTCUSDT\",\"ps\":\"BTCUSDT\",\"U\":11496321607808,\"u\":11496321612613,\"pu\":11496321607772,\"b\":[[\"1000.00\",\"25.154\"],[\"28882.20\",\"1.526\"],[\"28982.20\",\"0.574\"],[\"63506.00\",\"0.008\"],[\"71443.90\",\"0.002\"],[\"76206.90\",\"0.000\"],[\"78588.40\",\"4.448\"],[\"79134.10\",\"0.627\"],[\"79150.40\",\"0.000\"],[\"79158.80\",\"2.251\"],[\"79161.60\",\"0.000\"],[\"79204.60\",\"1.577\"],[\"79207.50\",\"0.001\"],[\"79235.80\",\"0.795\"],[\"79238.60\",\"0.010\"],[\"79289.20\",\"0.167\"],[\"79292.00\",\"1.207\"],[\"79322.50\",\"0.073\"],[\"79324.60\",\"0.525\"],[\"79332.00\",\"0.004\"],[\"79365.20\",\"0.108\"],[\"79365.50\",\"0.252\"],[\"79365.60\",\"0.002\"],[\"79366.70\",\"0.102\"],[\"79367.10\",\"0.442\"],[\"79367.30\",\"0.000\"],[\"79371.90\",\"0.171\"]],\"a\":[[\"79751.40\",\"0.907\"],[\"80176.10\",\"5.302\"],[\"80422.40\",\"0.000\"],[\"83351.40\",\"0.020\"]],\"st\":1}}"}
{"receive_ns":1788781927372227000,"stream":"btcusdt@bookTicker","event_type":"bookTicker","event_time_ms":1788781927444,"raw_json":"{\"stream\":\"btcusdt@bookTicker\",\"data\":{\"e\":\"bookTicker\",\"u\":11496321615658,\"s\":\"BTCUSDT\",\"ps\":\"BTCUSDT\",\"b\":\"79382.20\",\"B\":\"16.380\",\"a\":\"79382.30\",\"A\":\"5.018\",\"T\":1788781927444,\"E\":1788781927444,\"st\":1}}"}
{"receive_ns":1788781927377145000,"stream":"btcusdt@bookTicker","event_type":"bookTicker","event_time_ms":1788781927447,"raw_json":"{\"stream\":\"btcusdt@bookTicker\",\"data\":{\"e\":\"bookTicker\",\"u\":11496321615840,\"s\":\"BTCUSDT\",\"ps\":\"BTCUSDT\",\"b\":\"79382.20\",\"B\":\"16.380\",\"a\":\"79382.30\",\"A\":\"5.028\",\"T\":1788781927447,\"E\":1788781927447,\"st\":1}}"}
{"receive_ns":1788781927419308000,"stream":"btcusdt@bookTicker","event_type":"bookTicker","event_time_ms":1788781927491,"raw_json":"{\"stream\":\"btcusdt@bookTicker\",\"data\":{\"e\":\"bookTicker\",\"u\":11496321618340,\"s\":\"BTCUSDT\",\"ps\":\"BTCUSDT\",\"b\":\"79382.20\",\"B\":\"16.380\",\"a\":\"79382.30\",\"A\":\"4.998\",\"T\":1788781927491,\"E\":1788781927491,\"st\":1}}"}
{"receive_ns":1788781927423143000,"stream":"btcusdt@depth@100ms","event_type":"depthUpdate","event_time_ms":1788781927494,"raw_json":"{\"stream\":\"btcusdt@depth@100ms\",\"data\":{\"e\":\"depthUpdate\",\"E\":1788781927494,\"T\":1788781927493,\"s\":\"BTCUSDT\",\"ps\":\"BTCUSDT\",\"U\":11496321612761,\"u\":11496321618471,\"pu\":11496321612613,\"b\":[[\"28882.20\",\"1.701\"],[\"28982.20\",\"0.399\"],[\"71443.90\",\"0.002\"],[\"76206.90\",\"0.002\"],[\"78310.50\",\"3.991\"],[\"78588.40\",\"4.450\"],[\"78608.50\",\"0.003\"],[\"78614.30\",\"2.727\"],[\"78985.30\",\"0.387\"],[\"79150.40\",\"0.000\"],[\"79158.80\",\"0.000\"],[\"79161.60\",\"35.371\"],[\"79176.00\",\"0.607\"],[\"79179.80\",\"1.525\"],[\"79204.60\",\"0.002\"],[\"79207.50\",\"26.514\"],[\"79207.60\",\"4.085\"],[\"79235.80\",\"0.012\"],[\"79238.60\",\"17.678\"],[\"79239.60\",\"3.600\"],[\"79259.20\",\"0.125\"],[\"79289.20\",\"0.028\"],[\"79292.00\",\"10.035\"],[\"79295.90\",\"3.167\"],[\"79324.60\",\"0.149\"],[\"79331.20\",\"0.410\"],[\"79332.00\",\"0.671\"],[\"79362.00\",\"1.398\"],[\"79362.50\",\"0.001\"],[\"79362.60\",\"0.634\"],[\"79362.90\",\"0.000\"],[\"79364.00\",\"0.152\"],[\"79365.20\",\"0.549\"],[\"79365.50\",\"0.252\"],[\"79366.30\",\"0.071\"],[\"79366.50\",\"0.201\"],[\"79366.60\",\"0.104\"],[\"79367.00\",\"1.335\"],[\"79367.10\",\"0.001\"],[\"79367.90\",\"0.785\"],[\"79371.90\",\"0.171\"]],\"a\":[[\"79382.30\",\"4.998\"],[\"79401.80\",\"0.048\"],[\"79402.90\",\"0.493\"],[\"79403.00\",\"1.232\"],[\"79404.00\",\"1.058\"],[\"79404.10\",\"1.021\"],[\"79556.70\",\"0.000\"],[\"79751.40\",\"0.698\"],[\"79753.40\",\"0.036\"],[\"80176.10\",\"5.302\"],[\"80493.70\",\"4.338\"],[\"80509.50\",\"1.812\"],[\"80866.70\",\"1.596\"],[\"87320.60\",\"0.000\"]],\"st\":1}}"}
{"receive_ns":1788781927423503000,"stream":"btcusdt@bookTicker","event_type":"bookTicker","event_time_ms":1788781927495,"raw_json":"{\"stream\":\"btcusdt@bookTicker\",\"data\":{\"e\":\"bookTicker\",\"u\":11496321618524,\"s\":\"BTCUSDT\",\"ps\":\"BTCUSDT\",\"b\":\"79382.20\",\"B\":\"16.380\",\"a\":\"79382.30\",\"A\":\"4.999\",\"T\":1788781927494,\"E\":1788781927495,\"st\":1}}"}
{"receive_ns":1788781927427356000,"stream":"btcusdt@bookTicker","event_type":"bookTicker","event_time_ms":1788781927499,"raw_json":"{\"stream\":\"btcusdt@bookTicker\",\"data\":{\"e\":\"bookTicker\",\"u\":11496321618722,\"s\":\"BTCUSDT\",\"ps\":\"BTCUSDT\",\"b\":\"79382.20\",\"B\":\"16.379\",\"a\":\"79382.30\",\"A\":\"4.999\",\"T\":1788781927499,\"E\":1788781927499,\"st\":1}}"}
{"receive_ns":1788781927428470000,"stream":"btcusdt@bookTicker","event_type":"bookTicker","event_time_ms":1788781927501,"raw_json":"{\"stream\":\"btcusdt@bookTicker\",\"data\":{\"e\":\"bookTicker\",\"u\":11496321618803,\"s\":\"BTCUSDT\",\"ps\":\"BTCUSDT\",\"b\":\"79382.20\",\"B\":\"16.379\",\"a\":\"79382.30\",\"A\":\"5.028\",\"T\":1788781927500,\"E\":1788781927501,\"st\":1}}"}
{"receive_ns":1788781927431829000,"stream":"btcusdt@bookTicker","event_type":"bookTicker","event_time_ms":1788781927503,"raw_json":"{\"stream\":\"btcusdt@bookTicker\",\"data\":{\"e\":\"bookTicker\",\"u\":11496321618957,\"s\":\"BTCUSDT\",\"ps\":\"BTCUSDT\",\"b\":\"79382.20\",\"B\":\"16.379\",\"a\":\"79382.30\",\"A\":\"5.059\",\"T\":1788781927503,\"E\":1788781927503,\"st\":1}}"}
{"receive_ns":1788781927432111000,"stream":"btcusdt@bookTicker","event_type":"bookTicker","event_time_ms":1788781927504,"raw_json":"{\"stream\":\"btcusdt@bookTicker\",\"data\":{\"e\":\"bookTicker\",\"u\":11496321619038,\"s\":\"BTCUSDT\",\"ps\":\"BTCUSDT\",\"b\":\"79382.20\",\"B\":\"16.379\",\"a\":\"79382.30\",\"A\":\"5.058\",\"T\":1788781927504,\"E\":1788781927504,\"st\":1}}"}
{"receive_ns":1788781927450192000,"stream":"btcusdt@bookTicker","event_type":"bookTicker","event_time_ms":1788781927521,"raw_json":"{\"stream\":\"btcusdt@bookTicker\",\"data\":{\"e\":\"bookTicker\",\"u\":11496321620113,\"s\":\"BTCUSDT\",\"ps\":\"BTCUSDT\",\"b\":\"79382.20\",\"B\":\"16.127\",\"a\":\"79382.30\",\"A\":\"5.058\",\"T\":1788781927521,\"E\":1788781927521,\"st\":1}}"}
{"receive_ns":1788781927458788000,"stream":"btcusdt@bookTicker","event_type":"bookTicker","event_time_ms":1788781927529,"raw_json":"{\"stream\":\"btcusdt@bookTicker\",\"data\":{\"e\":\"bookTicker\",\"u\":11496321620574,\"s\":\"BTCUSDT\",\"ps\":\"BTCUSDT\",\"b\":\"79382.20\",\"B\":\"16.120\",\"a\":\"79382.30\",\"A\":\"5.058\",\"T\":1788781927529,\"E\":1788781927529,\"st\":1}}"}
{"receive_ns":1788781927460765000,"stream":"btcusdt@bookTicker","event_type":"bookTicker","event_time_ms":1788781927532,"raw_json":"{\"stream\":\"btcusdt@bookTicker\",\"data\":{\"e\":\"bookTicker\",\"u\":11496321620728,\"s\":\"BTCUSDT\",\"ps\":\"BTCUSDT\",\"b\":\"79382.20\",\"B\":\"16.126\",\"a\":\"79382.30\",\"A\":\"5.058\",\"T\":1788781927532,\"E\":1788781927532,\"st\":1}}"}
{"receive_ns":1788781927484158000,"stream":"btcusdt@bookTicker","event_type":"bookTicker","event_time_ms":1788781927556,"raw_json":"{\"stream\":\"btcusdt@bookTicker\",\"data\":{\"e\":\"bookTicker\",\"u\":11496321622426,\"s\":\"BTCUSDT\",\"ps\":\"BTCUSDT\",\"b\":\"79382.20\",\"B\":\"16.126\",\"a\":\"79382.30\",\"A\":\"5.059\",\"T\":1788781927555,\"E\":1788781927556,\"st\":1}}"}
{"receive_ns":1788781927524342000,"stream":"btcusdt@depth@100ms","event_type":"depthUpdate","event_time_ms":1788781927596,"raw_json":"{\"stream\":\"btcusdt@depth@100ms\",\"data\":{\"e\":\"depthUpdate\",\"E\":1788781927596,\"T\":1788781927594,\"s\":\"BTCUSDT\",\"ps\":\"BTCUSDT\",\"U\":11496321618478,\"u\":11496321625535,\"pu\":11496321618471,\"b\":[[\"28882.20\",\"1.799\"],[\"28982.20\",\"0.259\"],[\"29282.20\",\"0.042\"],[\"63506.00\",\"0.010\"],[\"71443.90\",\"0.002\"],[\"78310.50\",\"4.118\"],[\"78588.40\",\"4.448\"],[\"78985.30\",\"0.377\"],[\"79134.10\",\"0.125\"],[\"79153.50\",\"0.015\"],[\"79158.80\",\"2.251\"],[\"79161.60\",\"0.000\"],[\"79169.40\",\"1.088\"],[\"79172.60\",\"0.015\"],[\"79179.80\",\"1.625\"],[\"79204.70\",\"1.650\"],[\"79207.50\",\"0.001\"],[\"79207.60\",\"0.010\"],[\"79235.80\",\"0.795\"],[\"79238.60\",\"0.010\"],[\"79239.60\",\"1.103\"],[\"79260.90\",\"0.126\"],[\"79289.20\",\"0.167\"],[\"79292.00\",\"1.207\"],[\"79295.90\",\"1.153\"],[\"79311.30\",\"0.007\"],[\"79312.00\",\"0.665\"],[\"79315.10\",\"0.047\"],[\"79315.50\",\"1.151\"],[\"79324.60\",\"0.425\"],[\"79326.60\",\"0.003\"],[\"79351.40\",\"1.233\"],[\"79351.50\",\"10.703\"],[\"79353.90\",\"0.084\"],[\"79355.10\",\"0.503\"],[\"79355.20\",\"0.001\"],[\"79355.50\",\"0.797\"],[\"79362.30\",\"0.091\"],[\"79362.70\",\"0.041\"],[\"79363.00\",\"0.077\"],[\"79363.10\",\"0.002\"],[\"79366.10\",\"0.073\"],[\"79366.20\",\"0.070\"],[\"79367.10\",\"0.101\"],[\"79367.20\",\"0.071\"],[\"79382.20\",\"16.126\"]],\"a\":[[\"79382.30\",\"5.059\"],[\"79386.50\",\"0.003\"],[\"79389.50\",\"0.005\"],[\"79390.20\",\"0.104\"],[\"79390.30\",\"0.018\"],[\"79437.90\",\"0.243\"],[\"79442.70\",\"2.143\"],[\"79453.80\",\"0.002\"],[\"79454.70\",\"0.058\"],[\"79751.40\",\"0.600\"],[\"80176.10\",\"5.302\"],[\"80802.50\",\"0.001\"]],\"st\":1}}"}
{"receive_ns":1788781927577644000,"stream":"btcusdt@bookTicker","event_type":"bookTicker","event_time_ms":1788781927643,"raw_json":"{\"stream\":\"btcusdt@bookTicker\",\"data\":{\"e\":\"bookTicker\",\"u\":11496321629156,\"s\":\"BTCUSDT\",\"ps\":\"BTCUSDT\",\"b\":\"79382.20\",\"B\":\"16.127\",\"a\":\"79382.30\",\"A\":\"5.059\",\"T\":1788781927643,\"E\":1788781927643,\"st\":1}}"}
{"receive_ns":1788781927626505000,"stream":"btcusdt@depth@100ms","event_type":"depthUpdate","event_time_ms":1788781927698,"raw_json":"{\"stream\":\"btcusdt@depth@100ms\",\"data\":{\"e\":\"depthUpdate\",\"E\":1788781927698,\"T\":1788781927697,\"s\":\"BTCUSDT\",\"ps\":\"BTCUSDT\",\"U\":11496321625773,\"u\":11496321632179,\"pu\":11496321625535,\"b\":[[\"1000.00\",\"25.154\"],[\"28882.20\",\"1.855\"],[\"28982.20\",\"0.140\"],[\"29282.20\",\"0.105\"],[\"63506.00\",\"0.008\"],[\"71443.90\",\"0.002\"],[\"76206.90\",\"0.000\"],[\"78588.40\",\"4.448\"],[\"78786.80\",\"1.902\"],[\"78985.20\",\"0.000\"],[\"79133.00\",\"0.000\"],[\"79134.10\",\"0.602\"],[\"79150.40\",\"0.000\"],[\"79153.50\",\"0.000\"],[\"79158.80\",\"0.000\"],[\"79158.90\",\"2.253\"],[\"79161.60\",\"0.000\"],[\"79161.70\",\"0.054\"],[\"79179.40\",\"3.093\"],[\"79204.70\",\"1.651\"],[\"79207.50\",\"0.001\"],[\"79207.60\",\"0.028\"],[\"79235.80\",\"0.012\"],[\"79235.90\",\"2.043\"],[\"79238.60\",\"0.010\"],[\"79289.20\",\"0.028\"],[\"79289.30\",\"0.139\"],[\"79292.00\",\"1.207\"],[\"79354.70\",\"0.000\"],[\"79357.30\",\"0.504\"],[\"79362.10\",\"0.504\"],[\"79362.20\",\"0.001\"],[\"79365.20\",\"0.108\"],[\"79366.30\",\"0.141\"],[\"79366.80\",\"0.170\"],[\"79367.10\",\"0.542\"],[\"79382.20\",\"16.127\"]],\"a\":[[\"79402.90\",\"0.053\"],[\"79403.00\",\"0.666\"],[\"79403.90\",\"0.462\"],[\"79404.20\",\"0.695\"],[\"79751.40\",\"0.907\"],[\"79779.30\",\"0.003\"],[\"80176.10\",\"5.302\"],[\"80253.90\",\"3.187\"],[\"80329.40\",\"28.499\"],[\"87320.60\",\"0.000\"]],\"st\":1}}"}
{"receive_ns":1788781927630982000,"stream":"btcusdt@bookTicker","event_type":"bookTicker","event_time_ms":1788781927701,"raw_json":"{\"stream\":\"btcusdt@bookTicker\",\"data\":{\"e\":\"bookTicker\",\"u\":11496321632597,\"s\":\"BTCUSDT\",\"ps\":\"BTCUSDT\",\"b\":\"79382.20\",\"B\":\"16.123\",\"a\":\"79382.30\",\"A\":\"5.059\",\"T\":1788781927701,\"E\":1788781927701,\"st\":1}}"}
{"receive_ns":1788781927631200000,"stream":"btcusdt@trade","event_type":"trade","event_time_ms":1788781927701,"raw_json":"{\"stream\":\"btcusdt@trade\",\"data\":{\"e\":\"trade\",\"E\":1788781927701,\"T\":1788781927701,\"s\":\"BTCUSDT\",\"t\":8057735402,\"p\":\"79382.20\",\"q\":\"0.004\",\"X\":\"MARKET\",\"m\":true,\"st\":1}}"}
{"receive_ns":1788781927699419000,"stream":"btcusdt@bookTicker","event_type":"bookTicker","event_time_ms":1788781927770,"raw_json":"{\"stream\":\"btcusdt@bookTicker\",\"data\":{\"e\":\"bookTicker\",\"u\":11496321637241,\"s\":\"BTCUSDT\",\"ps\":\"BTCUSDT\",\"b\":\"79382.20\",\"B\":\"16.123\",\"a\":\"79382.30\",\"A\":\"4.951\",\"T\":1788781927770,\"E\":1788781927770,\"st\":1}}"}
{"receive_ns":1788781927699664000,"stream":"btcusdt@bookTicker","event_type":"bookTicker","event_time_ms":1788781927770,"raw_json":"{\"stream\":\"btcusdt@bookTicker\",\"data\":{\"e\":\"bookTicker\",\"u\":11496321637248,\"s\":\"BTCUSDT\",\"ps\":\"BTCUSDT\",\"b\":\"79382.20\",\"B\":\"16.099\",\"a\":\"79382.30\",\"A\":\"4.951\",\"T\":1788781927770,\"E\":1788781927770,\"st\":1}}"}
{"receive_ns":1788781927699859000,"stream":"btcusdt@trade","event_type":"trade","event_time_ms":1788781927770,"raw_json":"{\"stream\":\"btcusdt@trade\",\"data\":{\"e\":\"trade\",\"E\":1788781927770,\"T\":1788781927770,\"s\":\"BTCUSDT\",\"t\":8057735403,\"p\":\"79382.30\",\"q\":\"0.058\",\"X\":\"MARKET\",\"m\":false,\"st\":1}}"}
{"receive_ns":1788781927699987000,"stream":"btcusdt@trade","event_type":"trade","event_time_ms":1788781927770,"raw_json":"{\"stream\":\"btcusdt@trade\",\"data\":{\"e\":\"trade\",\"E\":1788781927770,\"T\":1788781927770,\"s\":\"BTCUSDT\",\"t\":8057735404,\"p\":\"79382.30\",\"q\":\"0.026\",\"X\":\"MARKET\",\"m\":false,\"st\":1}}"}
{"receive_ns":1788781927700101000,"stream":"btcusdt@trade","event_type":"trade","event_time_ms":1788781927770,"raw_json":"{\"stream\":\"btcusdt@trade\",\"data\":{\"e\":\"trade\",\"E\":1788781927770,\"T\":1788781927770,\"s\":\"BTCUSDT\",\"t\":8057735405,\"p\":\"79382.30\",\"q\":\"0.024\",\"X\":\"MARKET\",\"m\":false,\"st\":1}}"}
{"receive_ns":1788781927700249000,"stream":"btcusdt@trade","event_type":"trade","event_time_ms":1788781927770,"raw_json":"{\"stream\":\"btcusdt@trade\",\"data\":{\"e\":\"trade\",\"E\":1788781927770,\"T\":1788781927770,\"s\":\"BTCUSDT\",\"t\":8057735406,\"p\":\"79382.20\",\"q\":\"0.024\",\"X\":\"MARKET\",\"m\":true,\"st\":1}}"}
{"receive_ns":1788781927700412000,"stream":"btcusdt@bookTicker","event_type":"bookTicker","event_time_ms":1788781927771,"raw_json":"{\"stream\":\"btcusdt@bookTicker\",\"data\":{\"e\":\"bookTicker\",\"u\":11496321637486,\"s\":\"BTCUSDT\",\"ps\":\"BTCUSDT\",\"b\":\"79382.20\",\"B\":\"16.099\",\"a\":\"79382.30\",\"A\":\"5.012\",\"T\":1788781927771,\"E\":1788781927771,\"st\":1}}"}
{"receive_ns":1788781927700564000,"stream":"btcusdt@bookTicker","event_type":"bookTicker","event_time_ms":1788781927772,"raw_json":"{\"stream\":\"btcusdt@bookTicker\",\"data\":{\"e\":\"bookTicker\",\"u\":11496321637908,\"s\":\"BTCUSDT\",\"ps\":\"BTCUSDT\",\"b\":\"79382.20\",\"B\":\"16.099\",\"a\":\"79382.30\",\"A\":\"5.013\",\"T\":1788781927772,\"E\":1788781927772,\"st\":1}}"}
{"receive_ns":1788781927700743000,"stream":"btcusdt@bookTicker","event_type":"bookTicker","event_time_ms":1788781927773,"raw_json":"{\"stream\":\"btcusdt@bookTicker\",\"data\":{\"e\":\"bookTicker\",\"u\":11496321637928,\"s\":\"BTCUSDT\",\"ps\":\"BTCUSDT\",\"b\":\"79382.20\",\"B\":\"16.099\",\"a\":\"79382.30\",\"A\":\"5.039\",\"T\":1788781927772,\"E\":1788781927773,\"st\":1}}"}
{"receive_ns":1788781927704062000,"stream":"btcusdt@bookTicker","event_type":"bookTicker","event_time_ms":1788781927774,"raw_json":"{\"stream\":\"btcusdt@bookTicker\",\"data\":{\"e\":\"bookTicker\",\"u\":11496321638173,\"s\":\"BTCUSDT\",\"ps\":\"BTCUSDT\",\"b\":\"79382.20\",\"B\":\"16.351\",\"a\":\"79382.30\",\"A\":\"5.039\",\"T\":1788781927773,\"E\":1788781927774,\"st\":1}}"}
{"receive_ns":1788781927704279000,"stream":"btcusdt@bookTicker","event_type":"bookTicker","event_time_ms":1788781927775,"raw_json":"{\"stream\":\"btcusdt@bookTicker\",\"data\":{\"e\":\"bookTicker\",\"u\":11496321638396,\"s\":\"BTCUSDT\",\"ps\":\"BTCUSDT\",\"b\":\"79382.20\",\"B\":\"16.349\",\"a\":\"79382.30\",\"A\":\"5.039\",\"T\":1788781927775,\"E\":1788781927775,\"st\":1}}"}
{"receive_ns":1788781927729103000,"stream":"btcusdt@depth@100ms","event_type":"depthUpdate","event_time_ms":1788781927800,"raw_json":"{\"stream\":\"btcusdt@depth@100ms\",\"data\":{\"e\":\"depthUpdate\",\"E\":1788781927800,\"T\":1788781927798,\"s\":\"BTCUSDT\",\"ps\":\"BTCUSDT\",\"U\":11496321632390,\"u\":11496321639911,\"pu\":11496321632179,\"b\":[[\"28882.20\",\"1.918\"],[\"28982.20\",\"0.021\"],[\"29282.20\",\"0.161\"],[\"63505.80\",\"0.000\"],[\"63506.00\",\"0.008\"],[\"71443.90\",\"0.002\"],[\"75408.10\",\"0.204\"],[\"76206.90\",\"0.002\"],[\"78032.70\",\"6.270\"],[\"78255.00\",\"1.779\"],[\"78588.40\",\"4.448\"],[\"78985.30\",\"0.377\"],[\"79134.10\",\"1.692\"],[\"79150.40\",\"0.015\"],[\"79179.40\",\"3.111\"],[\"79179.80\",\"1.085\"],[\"79207.60\",\"0.010\"],[\"79259.20\",\"0.000\"],[\"79308.80\",\"0.003\"],[\"79324.60\",\"0.000\"],[\"79332.10\",\"0.000\"],[\"79355.90\",\"0.497\"],[\"79357.30\",\"0.051\"],[\"79362.00\",\"1.397\"],[\"79362.30\",\"0.021\"],[\"79362.80\",\"2.031\"],[\"79363.20\",\"0.003\"],[\"79365.20\",\"0.549\"],[\"79366.60\",\"0.104\"],[\"79366.90\",\"0.102\"],[\"79367.10\",\"0.101\"],[\"79367.20\",\"0.097\"],[\"79382.20\",\"16.349\"]],\"a\":[[\"79382.30\",\"5.039\"],[\"79385.50\",\"0.005\"],[\"79386.50\",\"0.001\"],[\"79388.20\",\"0.002\"],[\"79389.50\",\"0.003\"],[\"79404.00\",\"1.059\"],[\"79404.70\",\"0.339\"],[\"79420.10\",\"0.000\"],[\"79437.50\",\"2.911\"],[\"79437.60\",\"0.003\"],[\"79448.10\",\"0.001\"],[\"79456.10\",\"0.075\"],[\"79479.90\",\"0.012\"],[\"79497.70\",\"0.036\"],[\"79555.30\",\"0.001\"],[\"79555.60\",\"0.000\"],[\"79555.70\",\"0.001\"],[\"79751.40\",\"0.907\"],[\"79753.40\",\"0.036\"],[\"79797.40\",\"0.006\"],[\"80176.10\",\"5.302\"],[\"80501.60\",\"0.619\"]],\"st\":1}}"}
{"receive_ns":1788781927758000000,"stream":"btcusdt@bookTicker","event_type":"bookTicker","event_time_ms":1788781927828,"raw_json":"{\"stream\":\"btcusdt@bookTicker\",\"data\":{\"e\":\"bookTicker\",\"u\":11496321641607,\"s\":\"BTCUSDT\",\"ps\":\"BTCUSDT\",\"b\":\"79382.20\",\"B\":\"16.355\",\"a\":\"79382.30\",\"A\":\"5.039\",\"T\":1788781927828,\"E\":1788781927828,\"st\":1}}"}
{"receive_ns":1788781927773837000,"stream":"btcusdt@bookTicker","event_type":"bookTicker","event_time_ms":1788781927845,"raw_json":"{\"stream\":\"btcusdt@bookTicker\",\"data\":{\"e\":\"bookTicker\",\"u\":11496321642521,\"s\":\"BTCUSDT\",\"ps\":\"BTCUSDT\",\"b\":\"79382.20\",\"B\":\"16.354\",\"a\":\"79382.30\",\"A\":\"5.039\",\"T\":1788781927845,\"E\":1788781927845,\"st\":1}}"}
{"receive_ns":1788781927796335000,"stream":"btcusdt@bookTicker","event_type":"bookTicker","event_time_ms":1788781927866,"raw_json":"{\"stream\":\"btcusdt@bookTicker\",\"data\":{\"e\":\"bookTicker\",\"u\":11496321643709,\"s\":\"BTCUSDT\",\"ps\":\"BTCUSDT\",\"b\":\"79382.20\",\"B\":\"16.413\",\"a\":\"79382.30\",\"A\":\"5.039\",\"T\":1788781927866,\"E\":1788781927866,\"st\":1}}"}
{"receive_ns":1788781927797188000,"stream":"btcusdt@bookTicker","event_type":"bookTicker","event_time_ms":1788781927867,"raw_json":"{\"stream\":\"btcusdt@bookTicker\",\"data\":{\"e\":\"bookTicker\",\"u\":11496321643721,\"s\":\"BTCUSDT\",\"ps\":\"BTCUSDT\",\"b\":\"79382.20\",\"B\":\"16.413\",\"a\":\"79382.30\",\"A\":\"4.259\",\"T\":1788781927866,\"E\":1788781927867,\"st\":1}}"}
{"receive_ns":1788781927797430000,"stream":"btcusdt@bookTicker","event_type":"bookTicker","event_time_ms":1788781927867,"raw_json":"{\"stream\":\"btcusdt@bookTicker\",\"data\":{\"e\":\"bookTicker\",\"u\":11496321643766,\"s\":\"BTCUSDT\",\"ps\":\"BTCUSDT\",\"b\":\"79382.20\",\"B\":\"16.415\",\"a\":\"79382.30\",\"A\":\"4.259\",\"T\":1788781927867,\"E\":1788781927867,\"st\":1}}"}
{"receive_ns":1788781927797670000,"stream":"btcusdt@bookTicker","event_type":"bookTicker","event_time_ms":1788781927869,"raw_json":"{\"stream\":\"btcusdt@bookTicker\",\"data\":{\"e\":\"bookTicker\",\"u\":11496321644007,\"s\":\"BTCUSDT\",\"ps\":\"BTCUSDT\",\"b\":\"79382.20\",\"B\":\"16.415\",\"a\":\"79382.30\",\"A\":\"3.691\",\"T\":1788781927869,\"E\":1788781927869,\"st\":1}}"}
{"receive_ns":1788781927798787000,"stream":"btcusdt@bookTicker","event_type":"bookTicker","event_time_ms":1788781927870,"raw_json":"{\"stream\":\"btcusdt@bookTicker\",\"data\":{\"e\":\"bookTicker\",\"u\":11496321644098,\"s\":\"BTCUSDT\",\"ps\":\"BTCUSDT\",\"b\":\"79382.20\",\"B\":\"16.415\",\"a\":\"79382.30\",\"A\":\"3.690\",\"T\":1788781927870,\"E\":1788781927870,\"st\":1}}"}
{"receive_ns":1788781927798999000,"stream":"btcusdt@bookTicker","event_type":"bookTicker","event_time_ms":1788781927871,"raw_json":"{\"stream\":\"btcusdt@bookTicker\",\"data\":{\"e\":\"bookTicker\",\"u\":11496321644192,\"s\":\"BTCUSDT\",\"ps\":\"BTCUSDT\",\"b\":\"79382.20\",\"B\":\"16.415\",\"a\":\"79382.30\",\"A\":\"3.540\",\"T\":1788781927871,\"E\":1788781927871,\"st\":1}}"}
{"receive_ns":1788781927799142000,"stream":"btcusdt@bookTicker","event_type":"bookTicker","event_time_ms":1788781927871,"raw_json":"{\"stream\":\"btcusdt@bookTicker\",\"data\":{\"e\":\"bookTicker\",\"u\":11496321644264,\"s\":\"BTCUSDT\",\"ps\":\"BTCUSDT\",\"b\":\"79382.20\",\"B\":\"16.415\",\"a\":\"79382.30\",\"A\":\"3.184\",\"T\":1788781927871,\"E\":1788781927871,\"st\":1}}"}
{"receive_ns":1788781927799764000,"stream":"btcusdt@bookTicker","event_type":"bookTicker","event_time_ms":1788781927871,"raw_json":"{\"stream\":\"btcusdt@bookTicker\",\"data\":{\"e\":\"bookTicker\",\"u\":11496321644282,\"s\":\"BTCUSDT\",\"ps\":\"BTCUSDT\",\"b\":\"79382.20\",\"B\":\"16.415\",\"a\":\"79382.30\",\"A\":\"2.788\",\"T\":1788781927871,\"E\":1788781927871,\"st\":1}}"}
{"receive_ns":1788781927799925000,"stream":"btcusdt@bookTicker","event_type":"bookTicker","event_time_ms":1788781927871,"raw_json":"{\"stream\":\"btcusdt@bookTicker\",\"data\":{\"e\":\"bookTicker\",\"u\":11496321644289,\"s\":\"BTCUSDT\",\"ps\":\"BTCUSDT\",\"b\":\"79382.20\",\"B\":\"16.415\",\"a\":\"79382.30\",\"A\":\"2.556\",\"T\":1788781927871,\"E\":1788781927871,\"st\":1}}"}
{"receive_ns":1788781927800058000,"stream":"btcusdt@bookTicker","event_type":"bookTicker","event_time_ms":1788781927871,"raw_json":"{\"stream\":\"btcusdt@bookTicker\",\"data\":{\"e\":\"bookTicker\",\"u\":11496321644290,\"s\":\"BTCUSDT\",\"ps\":\"BTCUSDT\",\"b\":\"79382.20\",\"B\":\"16.415\",\"a\":\"79382.30\",\"A\":\"1.476\",\"T\":1788781927871,\"E\":1788781927871,\"st\":1}}"}
{"receive_ns":1788781927800426000,"stream":"btcusdt@bookTicker","event_type":"bookTicker","event_time_ms":1788781927872,"raw_json":"{\"stream\":\"btcusdt@bookTicker\",\"data\":{\"e\":\"bookTicker\",\"u\":11496321644355,\"s\":\"BTCUSDT\",\"ps\":\"BTCUSDT\",\"b\":\"79382.20\",\"B\":\"16.415\",\"a\":\"79382.30\",\"A\":\"1.477\",\"T\":1788781927871,\"E\":1788781927872,\"st\":1}}"}
{"receive_ns":1788781927802878000,"stream":"btcusdt@bookTicker","event_type":"bookTicker","event_time_ms":1788781927873,"raw_json":"{\"stream\":\"btcusdt@bookTicker\",\"data\":{\"e\":\"bookTicker\",\"u\":11496321644600,\"s\":\"BTCUSDT\",\"ps\":\"BTCUSDT\",\"b\":\"79382.20\",\"B\":\"16.415\",\"a\":\"79382.30\",\"A\":\"1.451\",\"T\":1788781927872,\"E\":1788781927873,\"st\":1}}"}
{"receive_ns":1788781927803071000,"stream":"btcusdt@bookTicker","event_type":"bookTicker","event_time_ms":1788781927873,"raw_json":"{\"stream\":\"btcusdt@bookTicker\",\"data\":{\"e\":\"bookTicker\",\"u\":11496321644637,\"s\":\"BTCUSDT\",\"ps\":\"BTCUSDT\",\"b\":\"79382.20\",\"B\":\"16.415\",\"a\":\"79382.30\",\"A\":\"1.339\",\"T\":1788781927873,\"E\":1788781927873,\"st\":1}}"}
{"receive_ns":1788781927803205000,"stream":"btcusdt@bookTicker","event_type":"bookTicker","event_time_ms":1788781927873,"raw_json":"{\"stream\":\"btcusdt@bookTicker\",\"data\":{\"e\":\"bookTicker\",\"u\":11496321644649,\"s\":\"BTCUSDT\",\"ps\":\"BTCUSDT\",\"b\":\"79382.20\",\"B\":\"16.415\",\"a\":\"79382.30\",\"A\":\"0.970\",\"T\":1788781927873,\"E\":1788781927873,\"st\":1}}"}
{"receive_ns":1788781927804075000,"stream":"btcusdt@bookTicker","event_type":"bookTicker","event_time_ms":1788781927874,"raw_json":"{\"stream\":\"btcusdt@bookTicker\",\"data\":{\"e\":\"bookTicker\",\"u\":11496321644960,\"s\":\"BTCUSDT\",\"ps\":\"BTCUSDT\",\"b\":\"79382.20\",\"B\":\"16.454\",\"a\":\"79382.30\",\"A\":\"0.970\",\"T\":1788781927874,\"E\":1788781927874,\"st\":1}}"}
{"receive_ns":1788781927804238000,"stream":"btcusdt@trade","event_type":"trade","event_time_ms":1788781927874,"raw_json":"{\"stream\":\"btcusdt@trade\",\"data\":{\"e\":\"trade\",\"E\":1788781927874,\"T\":1788781927874,\"s\":\"BTCUSDT\",\"t\":8057735407,\"p\":\"79382.30\",\"q\":\"0.342\",\"X\":\"MARKET\",\"m\":false,\"st\":1}}"}
{"receive_ns":1788781927804362000,"stream":"btcusdt@trade","event_type":"trade","event_time_ms":1788781927874,"raw_json":"{\"stream\":\"btcusdt@trade\",\"data\":{\"e\":\"trade\",\"E\":1788781927874,\"T\":1788781927874,\"s\":\"BTCUSDT\",\"t\":8057735408,\"p\":\"79382.30\",\"q\":\"0.013\",\"X\":\"MARKET\",\"m\":false,\"st\":1}}"}
{"receive_ns":1788781927804476000,"stream":"btcusdt@trade","event_type":"trade","event_time_ms":1788781927874,"raw_json":"{\"stream\":\"btcusdt@trade\",\"data\":{\"e\":\"trade\",\"E\":1788781927874,\"T\":1788781927874,\"s\":\"BTCUSDT\",\"t\":8057735409,\"p\":\"79382.30\",\"q\":\"0.001\",\"X\":\"MARKET\",\"m\":false,\"st\":1}}"}
{"receive_ns":1788781927804590000,"stream":"btcusdt@trade","event_type":"trade","event_time_ms":1788781927874,"raw_json":"{\"stream\":\"btcusdt@trade\",\"data\":{\"e\":\"trade\",\"E\":1788781927874,\"T\":1788781927874,\"s\":\"BTCUSDT\",\"t\":8057735410,\"p\":\"79382.30\",\"q\":\"0.001\",\"X\":\"MARKET\",\"m\":false,\"st\":1}}"}
{"receive_ns":1788781927804700000,"stream":"btcusdt@trade","event_type":"trade","event_time_ms":1788781927874,"raw_json":"{\"stream\":\"btcusdt@trade\",\"data\":{\"e\":\"trade\",\"E\":1788781927874,\"T\":1788781927874,\"s\":\"BTCUSDT\",\"t\":8057735411,\"p\":\"79382.30\",\"q\":\"0.001\",\"X\":\"MARKET\",\"m\":false,\"st\":1}}"}
{"receive_ns":1788781927804816000,"stream":"btcusdt@trade","event_type":"trade","event_time_ms":1788781927874,"raw_json":"{\"stream\":\"btcusdt@trade\",\"data\":{\"e\":\"trade\",\"E\":1788781927874,\"T\":1788781927874,\"s\":\"BTCUSDT\",\"t\":8057735412,\"p\":\"79382.30\",\"q\":\"0.001\",\"X\":\"MARKET\",\"m\":false,\"st\":1}}"}
{"receive_ns":1788781927804926000,"stream":"btcusdt@trade","event_type":"trade","event_time_ms":1788781927874,"raw_json":"{\"stream\":\"btcusdt@trade\",\"data\":{\"e\":\"trade\",\"E\":1788781927874,\"T\":1788781927874,\"s\":\"BTCUSDT\",\"t\":8057735413,\"p\":\"79382.30\",\"q\":\"0.001\",\"X\":\"MARKET\",\"m\":false,\"st\":1}}"}
{"receive_ns":1788781927805040000,"stream":"btcusdt@trade","event_type":"trade","event_time_ms":1788781927874,"raw_json":"{\"stream\":\"btcusdt@trade\",\"data\":{\"e\":\"trade\",\"E\":1788781927874,\"T\":1788781927874,\"s\":\"BTCUSDT\",\"t\":8057735414,\"p\":\"79382.30\",\"q\":\"0.001\",\"X\":\"MARKET\",\"m\":false,\"st\":1}}"}
{"receive_ns":1788781927805194000,"stream":"btcusdt@trade","event_type":"trade","event_time_ms":1788781927875,"raw_json":"{\"stream\":\"btcusdt@trade\",\"data\":{\"e\":\"trade\",\"E\":1788781927875,\"T\":1788781927874,\"s\":\"BTCUSDT\",\"t\":8057735415,\"p\":\"79382.30\",\"q\":\"0.001\",\"X\":\"MARKET\",\"m\":false,\"st\":1}}"}
{"receive_ns":1788781927805305000,"stream":"btcusdt@trade","event_type":"trade","event_time_ms":1788781927875,"raw_json":"{\"stream\":\"btcusdt@trade\",\"data\":{\"e\":\"trade\",\"E\":1788781927875,\"T\":1788781927874,\"s\":\"BTCUSDT\",\"t\":8057735416,\"p\":\"79382.30\",\"q\":\"0.001\",\"X\":\"MARKET\",\"m\":false,\"st\":1}}"}
{"receive_ns":1788781927805418000,"stream":"btcusdt@trade","event_type":"trade","event_time_ms":1788781927875,"raw_json":"{\"stream\":\"btcusdt@trade\",\"data\":{\"e\":\"trade\",\"E\":1788781927875,\"T\":1788781927874,\"s\":\"BTCUSDT\",\"t\":8057735417,\"p\":\"79382.30\",\"q\":\"0.001\",\"X\":\"MARKET\",\"m\":false,\"st\":1}}"}
{"receive_ns":1788781927805526000,"stream":"btcusdt@trade","event_type":"trade","event_time_ms":1788781927875,"raw_json":"{\"stream\":\"btcusdt@trade\",\"data\":{\"e\":\"trade\",\"E\":1788781927875,\"T\":1788781927874,\"s\":\"BTCUSDT\",\"t\":8057735418,\"p\":\"79382.30\",\"q\":\"0.002\",\"X\":\"MARKET\",\"m\":false,\"st\":1}}"}
{"receive_ns":1788781927805637000,"stream":"btcusdt@trade","event_type":"trade","event_time_ms":1788781927875,"raw_json":"{\"stream\":\"btcusdt@trade\",\"data\":{\"e\":\"trade\",\"E\":1788781927875,\"T\":1788781927874,\"s\":\"BTCUSDT\",\"t\":8057735419,\"p\":\"79382.30\",\"q\":\"0.001\",\"X\":\"MARKET\",\"m\":false,\"st\":1}}"}
{"receive_ns":1788781927805747000,"stream":"btcusdt@trade","event_type":"trade","event_time_ms":1788781927875,"raw_json":"{\"stream\":\"btcusdt@trade\",\"data\":{\"e\":\"trade\",\"E\":1788781927875,\"T\":1788781927874,\"s\":\"BTCUSDT\",\"t\":8057735420,\"p\":\"79382.30\",\"q\":\"0.001\",\"X\":\"MARKET\",\"m\":false,\"st\":1}}"}
{"receive_ns":1788781927805855000,"stream":"btcusdt@trade","event_type":"trade","event_time_ms":1788781927875,"raw_json":"{\"stream\":\"btcusdt@trade\",\"data\":{\"e\":\"trade\",\"E\":1788781927875,\"T\":1788781927874,\"s\":\"BTCUSDT\",\"t\":8057735421,\"p\":\"79382.30\",\"q\":\"0.003\",\"X\":\"MARKET\",\"m\":false,\"st\":1}}"}
{"receive_ns":1788781927805968000,"stream":"btcusdt@trade","event_type":"trade","event_time_ms":1788781927875,"raw_json":"{\"stream\":\"btcusdt@trade\",\"data\":{\"e\":\"trade\",\"E\":1788781927875,\"T\":1788781927874,\"s\":\"BTCUSDT\",\"t\":8057735422,\"p\":\"79382.30\",\"q\":\"0.002\",\"X\":\"MARKET\",\"m\":false,\"st\":1}}"}
{"receive_ns":1788781927806109000,"stream":"btcusdt@trade","event_type":"trade","event_time_ms":1788781927875,"raw_json":"{\"stream\":\"btcusdt@trade\",\"data\":{\"e\":\"trade\",\"E\":1788781927875,\"T\":1788781927874,\"s\":\"BTCUSDT\",\"t\":8057735423,\"p\":\"79382.30\",\"q\":\"0.002\",\"X\":\"MARKET\",\"m\":false,\"st\":1}}"}
{"receive_ns":1788781927806226000,"stream":"btcusdt@trade","event_type":"trade","event_time_ms":1788781927875,"raw_json":"{\"stream\":\"btcusdt@trade\",\"data\":{\"e\":\"trade\",\"E\":1788781927875,\"T\":1788781927874,\"s\":\"BTCUSDT\",\"t\":8057735424,\"p\":\"79382.30\",\"q\":\"0.001\",\"X\":\"MARKET\",\"m\":false,\"st\":1}}"}
{"receive_ns":1788781927806337000,"stream":"btcusdt@trade","event_type":"trade","event_time_ms":1788781927875,"raw_json":"{\"stream\":\"btcusdt@trade\",\"data\":{\"e\":\"trade\",\"E\":1788781927875,\"T\":1788781927874,\"s\":\"BTCUSDT\",\"t\":8057735425,\"p\":\"79382.30\",\"q\":\"0.010\",\"X\":\"MARKET\",\"m\":false,\"st\":1}}"}
{"receive_ns":1788781927806450000,"stream":"btcusdt@trade","event_type":"trade","event_time_ms":1788781927875,"raw_json":"{\"stream\":\"btcusdt@trade\",\"data\":{\"e\":\"trade\",\"E\":1788781927875,\"T\":1788781927874,\"s\":\"BTCUSDT\",\"t\":8057735426,\"p\":\"79382.30\",\"q\":\"0.100\",\"X\":\"MARKET\",\"m\":false,\"st\":1}}"}
{"receive_ns":1788781927806560000,"stream":"btcusdt@trade","event_type":"trade","event_time_ms":1788781927875,"raw_json":"{\"stream\":\"btcusdt@trade\",\"data\":{\"e\":\"trade\",\"E\":1788781927875,\"T\":1788781927874,\"s\":\"BTCUSDT\",\"t\":8057735427,\"p\":\"79382.30\",\"q\":\"0.001\",\"X\":\"MARKET\",\"m\":false,\"st\":1}}"}
{"receive_ns":1788781927806668000,"stream":"btcusdt@trade","event_type":"trade","event_time_ms":1788781927875,"raw_json":"{\"stream\":\"btcusdt@trade\",\"data\":{\"e\":\"trade\",\"E\":1788781927875,\"T\":1788781927874,\"s\":\"BTCUSDT\",\"t\":8057735428,\"p\":\"79382.30\",\"q\":\"0.001\",\"X\":\"MARKET\",\"m\":false,\"st\":1}}"}
{"receive_ns":1788781927806775000,"stream":"btcusdt@trade","event_type":"trade","event_time_ms":1788781927875,"raw_json":"{\"stream\":\"btcusdt@trade\",\"data\":{\"e\":\"trade\",\"E\":1788781927875,\"T\":1788781927874,\"s\":\"BTCUSDT\",\"t\":8057735429,\"p\":\"79382.30\",\"q\":\"0.016\",\"X\":\"MARKET\",\"m\":false,\"st\":1}}"}
{"receive_ns":1788781927806881000,"stream":"btcusdt@trade","event_type":"trade","event_time_ms":1788781927875,"raw_json":"{\"stream\":\"btcusdt@trade\",\"data\":{\"e\":\"trade\",\"E\":1788781927875,\"T\":1788781927874,\"s\":\"BTCUSDT\",\"t\":8057735430,\"p\":\"79382.30\",\"q\":\"0.004\",\"X\":\"MARKET\",\"m\":false,\"st\":1}}"}
{"receive_ns":1788781927806987000,"stream":"btcusdt@trade","event_type":"trade","event_time_ms":1788781927875,"raw_json":"{\"stream\":\"btcusdt@trade\",\"data\":{\"e\":\"trade\",\"E\":1788781927875,\"T\":1788781927874,\"s\":\"BTCUSDT\",\"t\":8057735431,\"p\":\"79382.30\",\"q\":\"0.001\",\"X\":\"MARKET\",\"m\":false,\"st\":1}}"}
{"receive_ns":1788781927807092000,"stream":"btcusdt@trade","event_type":"trade","event_time_ms":1788781927875,"raw_json":"{\"stream\":\"btcusdt@trade\",\"data\":{\"e\":\"trade\",\"E\":1788781927875,\"T\":1788781927874,\"s\":\"BTCUSDT\",\"t\":8057735432,\"p\":\"79382.30\",\"q\":\"0.001\",\"X\":\"MARKET\",\"m\":false,\"st\":1}}"}
{"receive_ns":1788781927807199000,"stream":"btcusdt@trade","event_type":"trade","event_time_ms":1788781927875,"raw_json":"{\"stream\":\"btcusdt@trade\",\"data\":{\"e\":\"trade\",\"E\":1788781927875,\"T\":1788781927874,\"s\":\"BTCUSDT\",\"t\":8057735433,\"p\":\"79382.30\",\"q\":\"0.002\",\"X\":\"MARKET\",\"m\":false,\"st\":1}}"}
{"receive_ns":1788781927807306000,"stream":"btcusdt@trade","event_type":"trade","event_time_ms":1788781927875,"raw_json":"{\"stream\":\"btcusdt@trade\",\"data\":{\"e\":\"trade\",\"E\":1788781927875,\"T\":1788781927874,\"s\":\"BTCUSDT\",\"t\":8057735434,\"p\":\"79382.30\",\"q\":\"0.001\",\"X\":\"MARKET\",\"m\":false,\"st\":1}}"}
{"receive_ns":1788781927807417000,"stream":"btcusdt@trade","event_type":"trade","event_time_ms":1788781927875,"raw_json":"{\"stream\":\"btcusdt@trade\",\"data\":{\"e\":\"trade\",\"E\":1788781927875,\"T\":1788781927874,\"s\":\"BTCUSDT\",\"t\":8057735435,\"p\":\"79382.30\",\"q\":\"0.002\",\"X\":\"MARKET\",\"m\":false,\"st\":1}}"}
{"receive_ns":1788781927807527000,"stream":"btcusdt@trade","event_type":"trade","event_time_ms":1788781927875,"raw_json":"{\"stream\":\"btcusdt@trade\",\"data\":{\"e\":\"trade\",\"E\":1788781927875,\"T\":1788781927874,\"s\":\"BTCUSDT\",\"t\":8057735436,\"p\":\"79382.30\",\"q\":\"0.012\",\"X\":\"MARKET\",\"m\":false,\"st\":1}}"}
{"receive_ns":1788781927807635000,"stream":"btcusdt@trade","event_type":"trade","event_time_ms":1788781927875,"raw_json":"{\"stream\":\"btcusdt@trade\",\"data\":{\"e\":\"trade\",\"E\":1788781927875,\"T\":1788781927874,\"s\":\"BTCUSDT\",\"t\":8057735437,\"p\":\"79382.30\",\"q\":\"0.004\",\"X\":\"MARKET\",\"m\":false,\"st\":1}}"}
{"receive_ns":1788781927807742000,"stream":"btcusdt@trade","event_type":"trade","event_time_ms":1788781927875,"raw_json":"{\"stream\":\"btcusdt@trade\",\"data\":{\"e\":\"trade\",\"E\":1788781927875,\"T\":1788781927874,\"s\":\"BTCUSDT\",\"t\":8057735438,\"p\":\"79382.30\",\"q\":\"0.001\",\"X\":\"MARKET\",\"m\":false,\"st\":1}}"}
{"receive_ns":1788781927807849000,"stream":"btcusdt@trade","event_type":"trade","event_time_ms":1788781927875,"raw_json":"{\"stream\":\"btcusdt@trade\",\"data\":{\"e\":\"trade\",\"E\":1788781927875,\"T\":1788781927874,\"s\":\"BTCUSDT\",\"t\":8057735439,\"p\":\"79382.30\",\"q\":\"0.005\",\"X\":\"MARKET\",\"m\":false,\"st\":1}}"}
{"receive_ns":1788781927807993000,"stream":"btcusdt@trade","event_type":"trade","event_time_ms":1788781927875,"raw_json":"{\"stream\":\"btcusdt@trade\",\"data\":{\"e\":\"trade\",\"E\":1788781927875,\"T\":1788781927874,\"s\":\"BTCUSDT\",\"t\":8057735440,\"p\":\"79382.30\",\"q\":\"0.003\",\"X\":\"MARKET\",\"m\":false,\"st\":1}}"}
{"receive_ns":1788781927808119000,"stream":"btcusdt@trade","event_type":"trade","event_time_ms":1788781927875,"raw_json":"{\"stream\":\"btcusdt@trade\",\"data\":{\"e\":\"trade\",\"E\":1788781927875,\"T\":1788781927874,\"s\":\"BTCUSDT\",\"t\":8057735441,\"p\":\"79382.30\",\"q\":\"0.001\",\"X\":\"MARKET\",\"m\":false,\"st\":1}}"}
{"receive_ns":1788781927808228000,"stream":"btcusdt@trade","event_type":"trade","event_time_ms":1788781927875,"raw_json":"{\"stream\":\"btcusdt@trade\",\"data\":{\"e\":\"trade\",\"E\":1788781927875,\"T\":1788781927874,\"s\":\"BTCUSDT\",\"t\":8057735442,\"p\":\"79382.30\",\"q\":\"0.004\",\"X\":\"MARKET\",\"m\":false,\"st\":1}}"}
{"receive_ns":1788781927808350000,"stream":"btcusdt@trade","event_type":"trade","event_time_ms":1788781927875,"raw_json":"{\"stream\":\"btcusdt@trade\",\"data\":{\"e\":\"trade\",\"E\":1788781927875,\"T\":1788781927874,\"s\":\"BTCUSDT\",\"t\":8057735443,\"p\":\"79382.30\",\"q\":\"0.001\",\"X\":\"MARKET\",\"m\":false,\"st\":1}}"}
{"receive_ns":1788781927808481000,"stream":"btcusdt@trade","event_type":"trade","event_time_ms":1788781927875,"raw_json":"{\"stream\":\"btcusdt@trade\",\"data\":{\"e\":\"trade\",\"E\":1788781927875,\"T\":1788781927874,\"s\":\"BTCUSDT\",\"t\":8057735444,\"p\":\"79382.30\",\"q\":\"0.010\",\"X\":\"MARKET\",\"m\":false,\"st\":1}}"}
{"receive_ns":1788781927808799000,"stream":"btcusdt@bookTicker","event_type":"bookTicker","event_time_ms":1788781927875,"raw_json":"{\"stream\":\"btcusdt@bookTicker\",\"data\":{\"e\":\"bookTicker\",\"u\":11496321645240,\"s\":\"BTCUSDT\",\"ps\":\"BTCUSDT\",\"b\":\"79382.30\",\"B\":\"0.338\",\"a\":\"79382.40\",\"A\":\"0.002\",\"T\":1788781927874,\"E\":1788781927875,\"st\":1}}"}
{"receive_ns":1788781927809023000,"stream":"btcusdt@bookTicker","event_type":"bookTicker","event_time_ms":1788781927875,"raw_json":"{\"stream\":\"btcusdt@bookTicker\",\"data\":{\"e\":\"bookTicker\",\"u\":11496321645351,\"s\":\"BTCUSDT\",\"ps\":\"BTCUSDT\",\"b\":\"79382.30\",\"B\":\"1.354\",\"a\":\"79382.40\",\"A\":\"0.002\",\"T\":1788781927875,\"E\":1788781927875,\"st\":1}}"}
{"receive_ns":1788781927809559000,"stream":"btcusdt@trade","event_type":"trade","event_time_ms":1788781927875,"raw_json":"{\"stream\":\"btcusdt@trade\",\"data\":{\"e\":\"trade\",\"E\":1788781927875,\"T\":1788781927874,\"s\":\"BTCUSDT\",\"t\":8057735445,\"p\":\"79382.30\",\"q\":\"0.235\",\"X\":\"MARKET\",\"m\":false,\"st\":1}}"}
{"receive_ns":1788781927809775000,"stream":"btcusdt@trade","event_type":"trade","event_time_ms":1788781927875,"raw_json":"{\"stream\":\"btcusdt@trade\",\"data\":{\"e\":\"trade\",\"E\":1788781927875,\"T\":1788781927874,\"s\":\"BTCUSDT\",\"t\":8057735446,\"p\":\"79382.30\",\"q\":\"0.001\",\"X\":\"MARKET\",\"m\":false,\"st\":1}}"}
{"receive_ns":1788781927809979000,"stream":"btcusdt@trade","event_type":"trade","event_time_ms":1788781927875,"raw_json":"{\"stream\":\"btcusdt@trade\",\"data\":{\"e\":\"trade\",\"E\":1788781927875,\"T\":1788781927874,\"s\":\"BTCUSDT\",\"t\":8057735447,\"p\":\"79382.30\",\"q\":\"0.001\",\"X\":\"MARKET\",\"m\":false,\"st\":1}}"}
{"receive_ns":1788781927810217000,"stream":"btcusdt@trade","event_type":"trade","event_time_ms":1788781927875,"raw_json":"{\"stream\":\"btcusdt@trade\",\"data\":{\"e\":\"trade\",\"E\":1788781927875,\"T\":1788781927874,\"s\":\"BTCUSDT\",\"t\":8057735448,\"p\":\"79382.30\",\"q\":\"0.001\",\"X\":\"MARKET\",\"m\":false,\"st\":1}}"}
{"receive_ns":1788781927810405000,"stream":"btcusdt@trade","event_type":"trade","event_time_ms":1788781927875,"raw_json":"{\"stream\":\"btcusdt@trade\",\"data\":{\"e\":\"trade\",\"E\":1788781927875,\"T\":1788781927874,\"s\":\"BTCUSDT\",\"t\":8057735449,\"p\":\"79382.30\",\"q\":\"0.038\",\"X\":\"MARKET\",\"m\":false,\"st\":1}}"}
{"receive_ns":1788781927810606000,"stream":"btcusdt@trade","event_type":"trade","event_time_ms":1788781927875,"raw_json":"{\"stream\":\"btcusdt@trade\",\"data\":{\"e\":\"trade\",\"E\":1788781927875,\"T\":1788781927874,\"s\":\"BTCUSDT\",\"t\":8057735450,\"p\":\"79382.30\",\"q\":\"0.002\",\"X\":\"MARKET\",\"m\":false,\"st\":1}}"}
{"receive_ns":1788781927810809000,"stream":"btcusdt@trade","event_type":"trade","event_time_ms":1788781927875,"raw_json":"{\"stream\":\"btcusdt@trade\",\"data\":{\"e\":\"trade\",\"E\":1788781927875,\"T\":1788781927874,\"s\":\"BTCUSDT\",\"t\":8057735451,\"p\":\"79382.30\",\"q\":\"0.001\",\"X\":\"MARKET\",\"m\":false,\"st\":1}}"}
{"receive_ns":1788781927811001000,"stream":"btcusdt@trade","event_type":"trade","event_time_ms":1788781927875,"raw_json":"{\"stream\":\"btcusdt@trade\",\"data\":{\"e\":\"trade\",\"E\":1788781927875,\"T\":1788781927874,\"s\":\"BTCUSDT\",\"t\":8057735452,\"p\":\"79382.30\",\"q\":\"0.010\",\"X\":\"MARKET\",\"m\":false,\"st\":1}}"}
{"receive_ns":1788781927811199000,"stream":"btcusdt@trade","event_type":"trade","event_time_ms":1788781927875,"raw_json":"{\"stream\":\"btcusdt@trade\",\"data\":{\"e\":\"trade\",\"E\":1788781927875,\"T\":1788781927874,\"s\":\"BTCUSDT\",\"t\":8057735453,\"p\":\"79382.30\",\"q\":\"0.001\",\"X\":\"MARKET\",\"m\":false,\"st\":1}}"}
{"receive_ns":1788781927811404000,"stream":"btcusdt@trade","event_type":"trade","event_time_ms":1788781927875,"raw_json":"{\"stream\":\"btcusdt@trade\",\"data\":{\"e\":\"trade\",\"E\":1788781927875,\"T\":1788781927874,\"s\":\"BTCUSDT\",\"t\":8057735454,\"p\":\"79382.30\",\"q\":\"0.029\",\"X\":\"MARKET\",\"m\":false,\"st\":1}}"}
{"receive_ns":1788781927811600000,"stream":"btcusdt@trade","event_type":"trade","event_time_ms":1788781927875,"raw_json":"{\"stream\":\"btcusdt@trade\",\"data\":{\"e\":\"trade\",\"E\":1788781927875,\"T\":1788781927874,\"s\":\"BTCUSDT\",\"t\":8057735455,\"p\":\"79382.30\",\"q\":\"0.031\",\"X\":\"MARKET\",\"m\":false,\"st\":1}}"}
{"receive_ns":1788781927811780000,"stream":"btcusdt@trade","event_type":"trade","event_time_ms":1788781927875,"raw_json":"{\"stream\":\"btcusdt@trade\",\"data\":{\"e\":\"trade\",\"E\":1788781927875,\"T\":1788781927874,\"s\":\"BTCUSDT\",\"t\":8057735456,\"p\":\"79382.30\",\"q\":\"0.001\",\"X\":\"MARKET\",\"m\":false,\"st\":1}}"}
{"receive_ns":1788781927811970000,"stream":"btcusdt@trade","event_type":"trade","event_time_ms":1788781927875,"raw_json":"{\"stream\":\"btcusdt@trade\",\"data\":{\"e\":\"trade\",\"E\":1788781927875,\"T\":1788781927874,\"s\":\"BTCUSDT\",\"t\":8057735457,\"p\":\"79382.30\",\"q\":\"0.061\",\"X\":\"MARKET\",\"m\":false,\"st\":1}}"}
{"receive_ns":1788781927812160000,"stream":"btcusdt@trade","event_type":"trade","event_time_ms":1788781927875,"raw_json":"{\"stream\":\"btcusdt@trade\",\"data\":{\"e\":\"trade\",\"E\":1788781927875,\"T\":1788781927874,\"s\":\"BTCUSDT\",\"t\":8057735458,\"p\":\"79382.30\",\"q\":\"0.001\",\"X\":\"MARKET\",\"m\":false,\"st\":1}}"}
{"receive_ns":1788781927812417000,"stream":"btcusdt@trade","event_type":"trade","event_time_ms":1788781927875,"raw_json":"{\"stream\":\"btcusdt@trade\",\"data\":{\"e\":\"trade\",\"E\":1788781927875,\"T\":1788781927874,\"s\":\"BTCUSDT\",\"t\":8057735459,\"p\":\"79382.30\",\"q\":\"0.001\",\"X\":\"MARKET\",\"m\":false,\"st\":1}}"}
{"receive_ns":1788781927812737000,"stream":"btcusdt@bookTicker","event_type":"bookTicker","event_time_ms":1788781927875,"raw_json":"{\"stream\":\"btcusdt@bookTicker\",\"data\":{\"e\":\"bookTicker\",\"u\":11496321645381,\"s\":\"BTCUSDT\",\"ps\":\"BTCUSDT\",\"b\":\"79382.30\",\"B\":\"1.356\",\"a\":\"79382.40\",\"A\":\"0.002\",\"T\":1788781927875,\"E\":1788781927875,\"st\":1}}"}
{"receive_ns":1788781927812955000,"stream":"btcusdt@bookTicker","event_type":"bookTicker","event_time_ms":1788781927875,"raw_json":"{\"stream\":\"btcusdt@bookTicker\",\"data\":{\"e\":\"bookTicker\",\"u\":11496321645416,\"s\":\"BTCUSDT\",\"ps\":\"BTCUSDT\",\"b\":\"79382.30\",\"B\":\"2.372\",\"a\":\"79382.40\",\"A\":\"0.002\",\"T\":1788781927875,\"E\":1788781927875,\"st\":1}}"}
{"receive_ns":1788781927813189000,"stream":"btcusdt@bookTicker","event_type":"bookTicker","event_time_ms":1788781927875,"raw_json":"{\"stream\":\"btcusdt@bookTicker\",\"data\":{\"e\":\"bookTicker\",\"u\":11496321645424,\"s\":\"BTCUSDT\",\"ps\":\"BTCUSDT\",\"b\":\"79382.30\",\"B\":\"2.411\",\"a\":\"79382.40\",\"A\":\"0.002\",\"T\":1788781927875,\"E\":1788781927875,\"st\":1}}"}
{"receive_ns":1788781927813385000,"stream":"btcusdt@bookTicker","event_type":"bookTicker","event_time_ms":1788781927875,"raw_json":"{\"stream\":\"btcusdt@bookTicker\",\"data\":{\"e\":\"bookTicker\",\"u\":11496321645436,\"s\":\"BTCUSDT\",\"ps\":\"BTCUSDT\",\"b\":\"79382.30\",\"B\":\"2.494\",\"a\":\"79382.40\",\"A\":\"0.002\",\"T\":1788781927875,\"E\":1788781927875,\"st\":1}}"}
{"receive_ns":1788781927813575000,"stream":"btcusdt@bookTicker","event_type":"bookTicker","event_time_ms":1788781927875,"raw_json":"{\"stream\":\"btcusdt@bookTicker\",\"data\":{\"e\":\"bookTicker\",\"u\":11496321645444,\"s\":\"BTCUSDT\",\"ps\":\"BTCUSDT\",\"b\":\"79382.30\",\"B\":\"3.956\",\"a\":\"79382.40\",\"A\":\"0.002\",\"T\":1788781927875,\"E\":1788781927875,\"st\":1}}"}
{"receive_ns":1788781927814235000,"stream":"btcusdt@bookTicker","event_type":"bookTicker","event_time_ms":1788781927875,"raw_json":"{\"stream\":\"btcusdt@bookTicker\",\"data\":{\"e\":\"bookTicker\",\"u\":11496321645447,\"s\":\"BTCUSDT\",\"ps\":\"BTCUSDT\",\"b\":\"79382.30\",\"B\":\"3.969\",\"a\":\"79382.40\",\"A\":\"0.002\",\"T\":1788781927875,\"E\":1788781927875,\"st\":1}}"}
{"receive_ns":1788781927814496000,"stream":"btcusdt@bookTicker","event_type":"bookTicker","event_time_ms":1788781927875,"raw_json":"{\"stream\":\"btcusdt@bookTicker\",\"data\":{\"e\":\"bookTicker\",\"u\":11496321645452,\"s\":\"BTCUSDT\",\"ps\":\"BTCUSDT\",\"b\":\"79382.30\",\"B\":\"3.974\",\"a\":\"79382.40\",\"A\":\"0.002\",\"T\":1788781927875,\"E\":1788781927875,\"st\":1}}"}
{"receive_ns":1788781927814766000,"stream":"btcusdt@bookTicker","event_type":"bookTicker","event_time_ms":1788781927876,"raw_json":"{\"stream\":\"btcusdt@bookTicker\",\"data\":{\"e\":\"bookTicker\",\"u\":11496321645470,\"s\":\"BTCUSDT\",\"ps\":\"BTCUSDT\",\"b\":\"79382.30\",\"B\":\"3.976\",\"a\":\"79382.40\",\"A\":\"0.002\",\"T\":1788781927875,\"E\":1788781927876,\"st\":1}}"}
{"receive_ns":1788781927814983000,"stream":"btcusdt@bookTicker","event_type":"bookTicker","event_time_ms":1788781927876,"raw_json":"{\"stream\":\"btcusdt@bookTicker\",\"data\":{\"e\":\"bookTicker\",\"u\":11496321645489,\"s\":\"BTCUSDT\",\"ps\":\"BTCUSDT\",\"b\":\"79382.30\",\"B\":\"4.010\",\"a\":\"79382.40\",\"A\":\"0.002\",\"T\":1788781927875,\"E\":1788781927876,\"st\":1}}"}
{"receive_ns":1788781927815189000,"stream":"btcusdt@bookTicker","event_type":"bookTicker","event_time_ms":1788781927876,"raw_json":"{\"stream\":\"btcusdt@bookTicker\",\"data\":{\"e\":\"bookTicker\",\"u\":11496321645502,\"s\":\"BTCUSDT\",\"ps\":\"BTCUSDT\",\"b\":\"79382.30\",\"B\":\"4.012\",\"a\":\"79382.40\",\"A\":\"0.002\",\"T\":1788781927875,\"E\":1788781927876,\"st\":1}}"}
{"receive_ns":1788781927815391000,"stream":"btcusdt@bookTicker","event_type":"bookTicker","event_time_ms":1788781927876,"raw_json":"{\"stream\":\"btcusdt@bookTicker\",\"data\":{\"e\":\"bookTicker\",\"u\":11496321645506,\"s\":\"BTCUSDT\",\"ps\":\"BTCUSDT\",\"b\":\"79382.30\",\"B\":\"4.572\",\"a\":\"79382.40\",\"A\":\"0.002\",\"T\":1788781927875,\"E\":1788781927876,\"st\":1}}"}
{"receive_ns":1788781927815590000,"stream":"btcusdt@bookTicker","event_type":"bookTicker","event_time_ms":1788781927876,"raw_json":"{\"stream\":\"btcusdt@bookTicker\",\"data\":{\"e\":\"bookTicker\",\"u\":11496321645517,\"s\":\"BTCUSDT\",\"ps\":\"BTCUSDT\",\"b\":\"79382.30\",\"B\":\"4.574\",\"a\":\"79382.40\",\"A\":\"0.002\",\"T\":1788781927875,\"E\":1788781927876,\"st\":1}}"}
{"receive_ns":1788781927815789000,"stream":"btcusdt@bookTicker","event_type":"bookTicker","event_time_ms":1788781927876,"raw_json":"{\"stream\":\"btcusdt@bookTicker\",\"data\":{\"e\":\"bookTicker\",\"u\":11496321645559,\"s\":\"BTCUSDT\",\"ps\":\"BTCUSDT\",\"b\":\"79382.30\",\"B\":\"4.613\",\"a\":\"79382.40\",\"A\":\"0.002\",\"T\":1788781927876,\"E\":1788781927876,\"st\":1}}"}
{"receive_ns":1788781927815995000,"stream":"btcusdt@bookTicker","event_type":"bookTicker","event_time_ms":1788781927876,"raw_json":"{\"stream\":\"btcusdt@bookTicker\",\"data\":{\"e\":\"bookTicker\",\"u\":11496321645713,\"s\":\"BTCUSDT\",\"ps\":\"BTCUSDT\",\"b\":\"79382.30\",\"B\":\"4.696\",\"a\":\"79382.40\",\"A\":\"0.002\",\"T\":1788781927876,\"E\":1788781927876,\"st\":1}}"}
{"receive_ns":1788781927828316000,"stream":"btcusdt@bookTicker","event_type":"bookTicker","event_time_ms":1788781927876,"raw_json":"{\"stream\":\"btcusdt@bookTicker\",\"data\":{\"e\":\"bookTicker\",\"u\":11496321645757,\"s\":\"BTCUSDT\",\"ps\":\"BTCUSDT\",\"b\":\"79382.30\",\"B\":\"3.680\",\"a\":\"79382.40\",\"A\":\"0.002\",\"T\":1788781927876,\"E\":1788781927876,\"st\":1}}"}
{"receive_ns":1788781927828550000,"stream":"btcusdt@bookTicker","event_type":"bookTicker","event_time_ms":1788781927876,"raw_json":"{\"stream\":\"btcusdt@bookTicker\",\"data\":{\"e\":\"bookTicker\",\"u\":11496321645790,\"s\":\"BTCUSDT\",\"ps\":\"BTCUSDT\",\"b\":\"79382.30\",\"B\":\"4.860\",\"a\":\"79382.60\",\"A\":\"0.077\",\"T\":1788781927876,\"E\":1788781927876,\"st\":1}}"}
{"receive_ns":1788781927828687000,"stream":"btcusdt@bookTicker","event_type":"bookTicker","event_time_ms":1788781927876,"raw_json":"{\"stream\":\"btcusdt@bookTicker\",\"data\":{\"e\":\"bookTicker\",\"u\":11496321645798,\"s\":\"BTCUSDT\",\"ps\":\"BTCUSDT\",\"b\":\"79382.30\",\"B\":\"6.040\",\"a\":\"79382.60\",\"A\":\"0.077\",\"T\":1788781927876,\"E\":1788781927876,\"st\":1}}"}
{"receive_ns":1788781927828808000,"stream":"btcusdt@bookTicker","event_type":"bookTicker","event_time_ms":1788781927876,"raw_json":"{\"stream\":\"btcusdt@bookTicker\",\"data\":{\"e\":\"bookTicker\",\"u\":11496321645806,\"s\":\"BTCUSDT\",\"ps\":\"BTCUSDT\",\"b\":\"79382.50\",\"B\":\"0.031\",\"a\":\"79382.60\",\"A\":\"0.077\",\"T\":1788781927876,\"E\":1788781927876,\"st\":1}}"}
{"receive_ns":1788781927828927000,"stream":"btcusdt@bookTicker","event_type":"bookTicker","event_time_ms":1788781927876,"raw_json":"{\"stream\":\"btcusdt@bookTicker\",\"data\":{\"e\":\"bookTicker\",\"u\":11496321645814,\"s\":\"BTCUSDT\",\"ps\":\"BTCUSDT\",\"b\":\"79382.50\",\"B\":\"0.077\",\"a\":\"79382.60\",\"A\":\"0.077\",\"T\":1788781927876,\"E\":1788781927876,\"st\":1}}"}
{"receive_ns":1788781927829045000,"stream":"btcusdt@bookTicker","event_type":"bookTicker","event_time_ms":1788781927876,"raw_json":"{\"stream\":\"btcusdt@bookTicker\",\"data\":{\"e\":\"bookTicker\",\"u\":11496321645818,\"s\":\"BTCUSDT\",\"ps\":\"BTCUSDT\",\"b\":\"79382.50\",\"B\":\"0.103\",\"a\":\"79382.60\",\"A\":\"0.077\",\"T\":1788781927876,\"E\":1788781927876,\"st\":1}}"}
{"receive_ns":1788781927829162000,"stream":"btcusdt@bookTicker","event_type":"bookTicker","event_time_ms":1788781927876,"raw_json":"{\"stream\":\"btcusdt@bookTicker\",\"data\":{\"e\":\"bookTicker\",\"u\":11496321645819,\"s\":\"BTCUSDT\",\"ps\":\"BTCUSDT\",\"b\":\"79382.50\",\"B\":\"0.941\",\"a\":\"79382.60\",\"A\":\"0.077\",\"T\":1788781927876,\"E\":1788781927876,\"st\":1}}"}
{"receive_ns":1788781927829277000,"stream":"btcusdt@bookTicker","event_type":"bookTicker","event_time_ms":1788781927876,"raw_json":"{\"stream\":\"btcusdt@bookTicker\",\"data\":{\"e\":\"bookTicker\",\"u\":11496321645821,\"s\":\"BTCUSDT\",\"ps\":\"BTCUSDT\",\"b\":\"79382.50\",\"B\":\"1.320\",\"a\":\"79382.60\",\"A\":\"0.077\",\"T\":1788781927876,\"E\":1788781927876,\"st\":1}}"}
{"receive_ns":1788781927829393000,"stream":"btcusdt@bookTicker","event_type":"bookTicker","event_time_ms":1788781927876,"raw_json":"{\"stream\":\"btcusdt@bookTicker\",\"data\":{\"e\":\"bookTicker\",\"u\":11496321645824,\"s\":\"BTCUSDT\",\"ps\":\"BTCUSDT\",\"b\":\"79382.50\",\"B\":\"1.838\",\"a\":\"79382.60\",\"A\":\"0.077\",\"T\":1788781927876,\"E\":1788781927876,\"st\":1}}"}
{"receive_ns":1788781927829507000,"stream":"btcusdt@bookTicker","event_type":"bookTicker","event_time_ms":1788781927876,"raw_json":"{\"stream\":\"btcusdt@bookTicker\",\"data\":{\"e\":\"bookTicker\",\"u\":11496321645826,\"s\":\"BTCUSDT\",\"ps\":\"BTCUSDT\",\"b\":\"79382.50\",\"B\":\"1.842\",\"a\":\"79382.60\",\"A\":\"0.077\",\"T\":1788781927876,\"E\":1788781927876,\"st\":1}}"}
{"receive_ns":1788781927829626000,"stream":"btcusdt@bookTicker","event_type":"bookTicker","event_time_ms":1788781927876,"raw_json":"{\"stream\":\"btcusdt@bookTicker\",\"data\":{\"e\":\"bookTicker\",\"u\":11496321645828,\"s\":\"BTCUSDT\",\"ps\":\"BTCUSDT\",\"b\":\"79382.50\",\"B\":\"3.978\",\"a\":\"79382.60\",\"A\":\"0.077\",\"T\":1788781927876,\"E\":1788781927876,\"st\":1}}"}
{"receive_ns":1788781927829742000,"stream":"btcusdt@bookTicker","event_type":"bookTicker","event_time_ms":1788781927876,"raw_json":"{\"stream\":\"btcusdt@bookTicker\",\"data\":{\"e\":\"bookTicker\",\"u\":11496321645836,\"s\":\"BTCUSDT\",\"ps\":\"BTCUSDT\",\"b\":\"79382.50\",\"B\":\"4.538\",\"a\":\"79382.60\",\"A\":\"0.077\",\"T\":1788781927876,\"E\":1788781927876,\"st\":1}}"}
{"receive_ns":1788781927829857000,"stream":"btcusdt@bookTicker","event_type":"bookTicker","event_time_ms":1788781927876,"raw_json":"{\"stream\":\"btcusdt@bookTicker\",\"data\":{\"e\":\"bookTicker\",\"u\":11496321645840,\"s\":\"BTCUSDT\",\"ps\":\"BTCUSDT\",\"b\":\"79382.50\",\"B\":\"4.546\",\"a\":\"79382.60\",\"A\":\"0.077\",\"T\":1788781927876,\"E\":1788781927876,\"st\":1}}"}
{"receive_ns":1788781927829972000,"stream":"btcusdt@bookTicker","event_type":"bookTicker","event_time_ms":1788781927876,"raw_json":"{\"stream\":\"btcusdt@bookTicker\",\"data\":{\"e\":\"bookTicker\",\"u\":11496321645860,\"s\":\"BTCUSDT\",\"ps\":\"BTCUSDT\",\"b\":\"79382.50\",\"B\":\"5.011\",\"a\":\"79382.60\",\"A\":\"0.077\",\"T\":1788781927876,\"E\":1788781927876,\"st\":1}}"}
{"receive_ns":1788781927830087000,"stream":"btcusdt@bookTicker","event_type":"bookTicker","event_time_ms":1788781927876,"raw_json":"{\"stream\":\"btcusdt@bookTicker\",\"data\":{\"e\":\"bookTicker\",\"u\":11496321645864,\"s\":\"BTCUSDT\",\"ps\":\"BTCUSDT\",\"b\":\"79382.50\",\"B\":\"5.027\",\"a\":\"79382.60\",\"A\":\"0.077\",\"T\":1788781927876,\"E\":1788781927876,\"st\":1}}"}
{"receive_ns":1788781927830203000,"stream":"btcusdt@bookTicker","event_type":"bookTicker","event_time_ms":1788781927876,"raw_json":"{\"stream\":\"btcusdt@bookTicker\",\"data\":{\"e\":\"bookTicker\",\"u\":11496321645881,\"s\":\"BTCUSDT\",\"ps\":\"BTCUSDT\",\"b\":\"79382.50\",\"B\":\"5.066\",\"a\":\"79382.60\",\"A\":\"0.077\",\"T\":1788781927876,\"E\":1788781927876,\"st\":1}}"}
{"receive_ns":1788781927830318000,"stream":"btcusdt@bookTicker","event_type":"bookTicker","event_time_ms":1788781927876,"raw_json":"{\"stream\":\"btcusdt@bookTicker\",\"data\":{\"e\":\"bookTicker\",\"u\":11496321645884,\"s\":\"BTCUSDT\",\"ps\":\"BTCUSDT\",\"b\":\"79382.50\",\"B\":\"5.074\",\"a\":\"79382.60\",\"A\":\"0.077\",\"T\":1788781927876,\"E\":1788781927876,\"st\":1}}"}
{"receive_ns":1788781927830433000,"stream":"btcusdt@bookTicker","event_type":"bookTicker","event_time_ms":1788781927876,"raw_json":"{\"stream\":\"btcusdt@bookTicker\",\"data\":{\"e\":\"bookTicker\",\"u\":11496321645908,\"s\":\"BTCUSDT\",\"ps\":\"BTCUSDT\",\"b\":\"79382.50\",\"B\":\"5.080\",\"a\":\"79382.60\",\"A\":\"0.077\",\"T\":1788781927876,\"E\":1788781927876,\"st\":1}}"}
{"receive_ns":1788781927830547000,"stream":"btcusdt@bookTicker","event_type":"bookTicker","event_time_ms":1788781927876,"raw_json":"{\"stream\":\"btcusdt@bookTicker\",\"data\":{\"e\":\"bookTicker\",\"u\":11496321645911,\"s\":\"BTCUSDT\",\"ps\":\"BTCUSDT\",\"b\":\"79382.50\",\"B\":\"5.632\",\"a\":\"79382.60\",\"A\":\"0.077\",\"T\":1788781927876,\"E\":1788781927876,\"st\":1}}"}
{"receive_ns":1788781927830662000,"stream":"btcusdt@bookTicker","event_type":"bookTicker","event_time_ms":1788781927876,"raw_json":"{\"stream\":\"btcusdt@bookTicker\",\"data\":{\"e\":\"bookTicker\",\"u\":11496321645922,\"s\":\"BTCUSDT\",\"ps\":\"BTCUSDT\",\"b\":\"79382.50\",\"B\":\"5.663\",\"a\":\"79382.60\",\"A\":\"0.077\",\"T\":1788781927876,\"E\":1788781927876,\"st\":1}}"}
{"receive_ns":1788781927830777000,"stream":"btcusdt@bookTicker","event_type":"bookTicker","event_time_ms":1788781927876,"raw_json":"{\"stream\":\"btcusdt@bookTicker\",\"data\":{\"e\":\"bookTicker\",\"u\":11496321645938,\"s\":\"BTCUSDT\",\"ps\":\"BTCUSDT\",\"b\":\"79382.50\",\"B\":\"5.665\",\"a\":\"79382.60\",\"A\":\"0.077\",\"T\":1788781927876,\"E\":1788781927876,\"st\":1}}"}
{"receive_ns":1788781927830896000,"stream":"btcusdt@bookTicker","event_type":"bookTicker","event_time_ms":1788781927876,"raw_json":"{\"stream\":\"btcusdt@bookTicker\",\"data\":{\"e\":\"bookTicker\",\"u\":11496321645949,\"s\":\"BTCUSDT\",\"ps\":\"BTCUSDT\",\"b\":\"79382.50\",\"B\":\"5.696\",\"a\":\"79382.60\",\"A\":\"0.077\",\"T\":1788781927876,\"E\":1788781927876,\"st\":1}}"}
{"receive_ns":1788781927831011000,"stream":"btcusdt@bookTicker","event_type":"bookTicker","event_time_ms":1788781927876,"raw_json":"{\"stream\":\"btcusdt@bookTicker\",\"data\":{\"e\":\"bookTicker\",\"u\":11496321645970,\"s\":\"BTCUSDT\",\"ps\":\"BTCUSDT\",\"b\":\"79382.50\",\"B\":\"6.712\",\"a\":\"79382.60\",\"A\":\"0.077\",\"T\":1788781927876,\"E\":1788781927876,\"st\":1}}"}
{"receive_ns":1788781927831127000,"stream":"btcusdt@bookTicker","event_type":"bookTicker","event_time_ms":1788781927876,"raw_json":"{\"stream\":\"btcusdt@bookTicker\",\"data\":{\"e\":\"bookTicker\",\"u\":11496321645971,\"s\":\"BTCUSDT\",\"ps\":\"BTCUSDT\",\"b\":\"79382.50\",\"B\":\"7.301\",\"a\":\"79382.60\",\"A\":\"0.077\",\"T\":1788781927876,\"E\":1788781927876,\"st\":1}}"}
{"receive_ns":1788781927831268000,"stream":"btcusdt@trade","event_type":"trade","event_time_ms":1788781927876,"raw_json":"{\"stream\":\"btcusdt@trade\",\"data\":{\"e\":\"trade\",\"E\":1788781927876,\"T\":1788781927876,\"s\":\"BTCUSDT\",\"t\":8057735460,\"p\":\"79382.40\",\"q\":\"0.001\",\"X\":\"MARKET\",\"m\":false,\"st\":1}}"}
{"receive_ns":1788781927831386000,"stream":"btcusdt@trade","event_type":"trade","event_time_ms":1788781927876,"raw_json":"{\"stream\":\"btcusdt@trade\",\"data\":{\"e\":\"trade\",\"E\":1788781927876,\"T\":1788781927876,\"s\":\"BTCUSDT\",\"t\":8057735461,\"p\":\"79382.40\",\"q\":\"0.001\",\"X\":\"MARKET\",\"m\":false,\"st\":1}}"}
{"receive_ns":1788781927831494000,"stream":"btcusdt@trade","event_type":"trade","event_time_ms":1788781927876,"raw_json":"{\"stream\":\"btcusdt@trade\",\"data\":{\"e\":\"trade\",\"E\":1788781927876,\"T\":1788781927876,\"s\":\"BTCUSDT\",\"t\":8057735462,\"p\":\"79382.50\",\"q\":\"0.001\",\"X\":\"MARKET\",\"m\":false,\"st\":1}}"}
{"receive_ns":1788781927839141000,"stream":"btcusdt@bookTicker","event_type":"bookTicker","event_time_ms":1788781927876,"raw_json":"{\"stream\":\"btcusdt@bookTicker\",\"data\":{\"e\":\"bookTicker\",\"u\":11496321646015,\"s\":\"BTCUSDT\",\"ps\":\"BTCUSDT\",\"b\":\"79382.50\",\"B\":\"7.869\",\"a\":\"79382.60\",\"A\":\"0.077\",\"T\":1788781927876,\"E\":1788781927876,\"st\":1}}"}
{"receive_ns":1788781927839338000,"stream":"btcusdt@bookTicker","event_type":"bookTicker","event_time_ms":1788781927876,"raw_json":"{\"stream\":\"btcusdt@bookTicker\",\"data\":{\"e\":\"bookTicker\",\"u\":11496321646023,\"s\":\"BTCUSDT\",\"ps\":\"BTCUSDT\",\"b\":\"79382.50\",\"B\":\"7.919\",\"a\":\"79382.60\",\"A\":\"0.077\",\"T\":1788781927876,\"E\":1788781927876,\"st\":1}}"}
{"receive_ns":1788781927839470000,"stream":"btcusdt@bookTicker","event_type":"bookTicker","event_time_ms":1788781927877,"raw_json":"{\"stream\":\"btcusdt@bookTicker\",\"data\":{\"e\":\"bookTicker\",\"u\":11496321646036,\"s\":\"BTCUSDT\",\"ps\":\"BTCUSDT\",\"b\":\"79382.50\",\"B\":\"8.935\",\"a\":\"79382.60\",\"A\":\"0.077\",\"T\":1788781927876,\"E\":1788781927877,\"st\":1}}"}
{"receive_ns":1788781927839593000,"stream":"btcusdt@bookTicker","event_type":"bookTicker","event_time_ms":1788781927877,"raw_json":"{\"stream\":\"btcusdt@bookTicker\",\"data\":{\"e\":\"bookTicker\",\"u\":11496321646041,\"s\":\"BTCUSDT\",\"ps\":\"BTCUSDT\",\"b\":\"79382.50\",\"B\":\"8.957\",\"a\":\"79382.60\",\"A\":\"0.077\",\"T\":1788781927876,\"E\":1788781927877,\"st\":1}}"}
{"receive_ns":1788781927839718000,"stream":"btcusdt@bookTicker","event_type":"bookTicker","event_time_ms":1788781927877,"raw_json":"{\"stream\":\"btcusdt@bookTicker\",\"data\":{\"e\":\"bookTicker\",\"u\":11496321646043,\"s\":\"BTCUSDT\",\"ps\":\"BTCUSDT\",\"b\":\"79382.50\",\"B\":\"9.546\",\"a\":\"79382.60\",\"A\":\"0.077\",\"T\":1788781927876,\"E\":1788781927877,\"st\":1}}"}
{"receive_ns":1788781927839842000,"stream":"btcusdt@bookTicker","event_type":"bookTicker","event_time_ms":1788781927877,"raw_json":"{\"stream\":\"btcusdt@bookTicker\",\"data\":{\"e\":\"bookTicker\",\"u\":11496321646046,\"s\":\"BTCUSDT\",\"ps\":\"BTCUSDT\",\"b\":\"79382.50\",\"B\":\"10.435\",\"a\":\"79382.60\",\"A\":\"0.077\",\"T\":1788781927876,\"E\":1788781927877,\"st\":1}}"}
{"receive_ns":1788781927839964000,"stream":"btcusdt@bookTicker","event_type":"bookTicker","event_time_ms":1788781927877,"raw_json":"{\"stream\":\"btcusdt@bookTicker\",\"data\":{\"e\":\"bookTicker\",\"u\":11496321646051,\"s\":\"BTCUSDT\",\"ps\":\"BTCUSDT\",\"b\":\"79382.50\",\"B\":\"11.318\",\"a\":\"79382.60\",\"A\":\"0.077\",\"T\":1788781927876,\"E\":1788781927877,\"st\":1}}"}
{"receive_ns":1788781927840083000,"stream":"btcusdt@bookTicker","event_type":"bookTicker","event_time_ms":1788781927877,"raw_json":"{\"stream\":\"btcusdt@bookTicker\",\"data\":{\"e\":\"bookTicker\",\"u\":11496321646067,\"s\":\"BTCUSDT\",\"ps\":\"BTCUSDT\",\"b\":\"79382.50\",\"B\":\"12.202\",\"a\":\"79382.60\",\"A\":\"0.077\",\"T\":1788781927876,\"E\":1788781927877,\"st\":1}}"}
{"receive_ns":1788781927840207000,"stream":"btcusdt@bookTicker","event_type":"bookTicker","event_time_ms":1788781927877,"raw_json":"{\"stream\":\"btcusdt@bookTicker\",\"data\":{\"e\":\"bookTicker\",\"u\":11496321646099,\"s\":\"BTCUSDT\",\"ps\":\"BTCUSDT\",\"b\":\"79382.50\",\"B\":\"13.088\",\"a\":\"79382.60\",\"A\":\"0.077\",\"T\":1788781927876,\"E\":1788781927877,\"st\":1}}"}
{"receive_ns":1788781927840326000,"stream":"btcusdt@bookTicker","event_type":"bookTicker","event_time_ms":1788781927877,"raw_json":"{\"stream\":\"btcusdt@bookTicker\",\"data\":{\"e\":\"bookTicker\",\"u\":11496321646112,\"s\":\"BTCUSDT\",\"ps\":\"BTCUSDT\",\"b\":\"79382.50\",\"B\":\"13.651\",\"a\":\"79382.60\",\"A\":\"0.077\",\"T\":1788781927876,\"E\":1788781927877,\"st\":1}}"}
{"receive_ns":1788781927840445000,"stream":"btcusdt@bookTicker","event_type":"bookTicker","event_time_ms":1788781927877,"raw_json":"{\"stream\":\"btcusdt@bookTicker\",\"data\":{\"e\":\"bookTicker\",\"u\":11496321646182,\"s\":\"BTCUSDT\",\"ps\":\"BTCUSDT\",\"b\":\"79382.50\",\"B\":\"14.080\",\"a\":\"79382.60\",\"A\":\"0.077\",\"T\":1788781927877,\"E\":1788781927877,\"st\":1}}"}
{"receive_ns":1788781927840577000,"stream":"btcusdt@bookTicker","event_type":"bookTicker","event_time_ms":1788781927877,"raw_json":"{\"stream\":\"btcusdt@bookTicker\",\"data\":{\"e\":\"bookTicker\",\"u\":11496321646185,\"s\":\"BTCUSDT\",\"ps\":\"BTCUSDT\",\"b\":\"79382.50\",\"B\":\"14.454\",\"a\":\"79382.60\",\"A\":\"0.077\",\"T\":1788781927877,\"E\":1788781927877,\"st\":1}}"}
{"receive_ns":1788781927840691000,"stream":"btcusdt@bookTicker","event_type":"bookTicker","event_time_ms":1788781927877,"raw_json":"{\"stream\":\"btcusdt@bookTicker\",\"data\":{\"e\":\"bookTicker\",\"u\":11496321646195,\"s\":\"BTCUSDT\",\"ps\":\"BTCUSDT\",\"b\":\"79382.50\",\"B\":\"14.876\",\"a\":\"79382.60\",\"A\":\"0.077\",\"T\":1788781927877,\"E\":1788781927877,\"st\":1}}"}
{"receive_ns":1788781927915286000,"stream":"btcusdt@bookTicker","event_type":"bookTicker","event_time_ms":1788781927877,"raw_json":"{\"stream\":\"btcusdt@bookTicker\",\"data\":{\"e\":\"bookTicker\",\"u\":11496321646228,\"s\":\"BTCUSDT\",\"ps\":\"BTCUSDT\",\"b\":\"79382.50\",\"B\":\"14.884\",\"a\":\"79382.60\",\"A\":\"0.077\",\"T\":1788781927877,\"E\":1788781927877,\"st\":1}}"}
{"receive_ns":1788781927915526000,"stream":"btcusdt@bookTicker","event_type":"bookTicker","event_time_ms":1788781927877,"raw_json":"{\"stream\":\"btcusdt@bookTicker\",\"data\":{\"e\":\"bookTicker\",\"u\":11496321646235,\"s\":\"BTCUSDT\",\"ps\":\"BTCUSDT\",\"b\":\"79382.50\",\"B\":\"15.064\",\"a\":\"79382.60\",\"A\":\"0.077\",\"T\":1788781927877,\"E\":1788781927877,\"st\":1}}"}
{"receive_ns":1788781927915670000,"stream":"btcusdt@bookTicker","event_type":"bookTicker","event_time_ms":1788781927877,"raw_json":"{\"stream\":\"btcusdt@bookTicker\",\"data\":{\"e\":\"bookTicker\",\"u\":11496321646241,\"s\":\"BTCUSDT\",\"ps\":\"BTCUSDT\",\"b\":\"79382.50\",\"B\":\"15.647\",\"a\":\"79382.60\",\"A\":\"0.077\",\"T\":1788781927877,\"E\":1788781927877,\"st\":1}}"}
{"receive_ns":1788781927915807000,"stream":"btcusdt@bookTicker","event_type":"bookTicker","event_time_ms":1788781927877,"raw_json":"{\"stream\":\"btcusdt@bookTicker\",\"data\":{\"e\":\"bookTicker\",\"u\":11496321646271,\"s\":\"BTCUSDT\",\"ps\":\"BTCUSDT\",\"b\":\"79382.50\",\"B\":\"15.687\",\"a\":\"79382.60\",\"A\":\"0.077\",\"T\":1788781927877,\"E\":1788781927877,\"st\":1}}"}
{"receive_ns":1788781927915935000,"stream":"btcusdt@bookTicker","event_type":"bookTicker","event_time_ms":1788781927877,"raw_json":"{\"stream\":\"btcusdt@bookTicker\",\"data\":{\"e\":\"bookTicker\",\"u\":11496321646274,\"s\":\"BTCUSDT\",\"ps\":\"BTCUSDT\",\"b\":\"79382.50\",\"B\":\"15.705\",\"a\":\"79382.60\",\"A\":\"0.077\",\"T\":1788781927877,\"E\":1788781927877,\"st\":1}}"}
{"receive_ns":1788781927916062000,"stream":"btcusdt@bookTicker","event_type":"bookTicker","event_time_ms":1788781927877,"raw_json":"{\"stream\":\"btcusdt@bookTicker\",\"data\":{\"e\":\"bookTicker\",\"u\":11496321646297,\"s\":\"BTCUSDT\",\"ps\":\"BTCUSDT\",\"b\":\"79382.50\",\"B\":\"16.533\",\"a\":\"79382.60\",\"A\":\"0.077\",\"T\":1788781927877,\"E\":1788781927877,\"st\":1}}"}
{"receive_ns":1788781927916193000,"stream":"btcusdt@bookTicker","event_type":"bookTicker","event_time_ms":1788781927877,"raw_json":"{\"stream\":\"btcusdt@bookTicker\",\"data\":{\"e\":\"bookTicker\",\"u\":11496321646301,\"s\":\"BTCUSDT\",\"ps\":\"BTCUSDT\",\"b\":\"79382.50\",\"B\":\"16.572\",\"a\":\"79382.60\",\"A\":\"0.077\",\"T\":1788781927877,\"E\":1788781927877,\"st\":1}}"}
{"receive_ns":1788781927916319000,"stream":"btcusdt@bookTicker","event_type":"bookTicker","event_time_ms":1788781927877,"raw_json":"{\"stream\":\"btcusdt@bookTicker\",\"data\":{\"e\":\"bookTicker\",\"u\":11496321646312,\"s\":\"BTCUSDT\",\"ps\":\"BTCUSDT\",\"b\":\"79382.50\",\"B\":\"16.628\",\"a\":\"79382.60\",\"A\":\"0.077\",\"T\":1788781927877,\"E\":1788781927877,\"st\":1}}"}
{"receive_ns":1788781927916446000,"stream":"btcusdt@bookTicker","event_type":"bookTicker","event_time_ms":1788781927877,"raw_json":"{\"stream\":\"btcusdt@bookTicker\",\"data\":{\"e\":\"bookTicker\",\"u\":11496321646313,\"s\":\"BTCUSDT\",\"ps\":\"BTCUSDT\",\"b\":\"79382.50\",\"B\":\"17.644\",\"a\":\"79382.60\",\"A\":\"0.077\",\"T\":1788781927877,\"E\":1788781927877,\"st\":1}}"}
{"receive_ns":1788781927916635000,"stream":"btcusdt@bookTicker","event_type":"bookTicker","event_time_ms":1788781927877,"raw_json":"{\"stream\":\"btcusdt@bookTicker\",\"data\":{\"e\":\"bookTicker\",\"u\":11496321646327,\"s\":\"BTCUSDT\",\"ps\":\"BTCUSDT\",\"b\":\"79382.50\",\"B\":\"17.743\",\"a\":\"79382.60\",\"A\":\"0.077\",\"T\":1788781927877,\"E\":1788781927877,\"st\":1}}"}
{"receive_ns":1788781927916940000,"stream":"btcusdt@bookTicker","event_type":"bookTicker","event_time_ms":1788781927877,"raw_json":"{\"stream\":\"btcusdt@bookTicker\",\"data\":{\"e\":\"bookTicker\",\"u\":11496321646339,\"s\":\"BTCUSDT\",\"ps\":\"BTCUSDT\",\"b\":\"79382.50\",\"B\":\"18.118\",\"a\":\"79382.60\",\"A\":\"0.077\",\"T\":1788781927877,\"E\":1788781927877,\"st\":1}}"}
{"receive_ns":1788781927917113000,"stream":"btcusdt@bookTicker","event_type":"bookTicker","event_time_ms":1788781927877,"raw_json":"{\"stream\":\"btcusdt@bookTicker\",\"data\":{\"e\":\"bookTicker\",\"u\":11496321646343,\"s\":\"BTCUSDT\",\"ps\":\"BTCUSDT\",\"b\":\"79382.50\",\"B\":\"18.174\",\"a\":\"79382.60\",\"A\":\"0.077\",\"T\":1788781927877,\"E\":1788781927877,\"st\":1}}"}
{"receive_ns":1788781927917261000,"stream":"btcusdt@bookTicker","event_type":"bookTicker","event_time_ms":1788781927877,"raw_json":"{\"stream\":\"btcusdt@bookTicker\",\"data\":{\"e\":\"bookTicker\",\"u\":11496321646344,\"s\":\"BTCUSDT\",\"ps\":\"BTCUSDT\",\"b\":\"79382.50\",\"B\":\"18.443\",\"a\":\"79382.60\",\"A\":\"0.077\",\"T\":1788781927877,\"E\":1788781927877,\"st\":1}}"}
{"receive_ns":1788781927917408000,"stream":"btcusdt@bookTicker","event_type":"bookTicker","event_time_ms":1788781927877,"raw_json":"{\"stream\":\"btcusdt@bookTicker\",\"data\":{\"e\":\"bookTicker\",\"u\":11496321646355,\"s\":\"BTCUSDT\",\"ps\":\"BTCUSDT\",\"b\":\"79382.50\",\"B\":\"18.599\",\"a\":\"79382.60\",\"A\":\"0.077\",\"T\":1788781927877,\"E\":1788781927877,\"st\":1}}"}
{"receive_ns":1788781927917545000,"stream":"btcusdt@bookTicker","event_type":"bookTicker","event_time_ms":1788781927877,"raw_json":"{\"stream\":\"btcusdt@bookTicker\",\"data\":{\"e\":\"bookTicker\",\"u\":11496321646356,\"s\":\"BTCUSDT\",\"ps\":\"BTCUSDT\",\"b\":\"79382.50\",\"B\":\"19.094\",\"a\":\"79382.60\",\"A\":\"0.077\",\"T\":1788781927877,\"E\":1788781927877,\"st\":1}}"}
{"receive_ns":1788781927917676000,"stream":"btcusdt@bookTicker","event_type":"bookTicker","event_time_ms":1788781927877,"raw_json":"{\"stream\":\"btcusdt@bookTicker\",\"data\":{\"e\":\"bookTicker\",\"u\":11496321646358,\"s\":\"BTCUSDT\",\"ps\":\"BTCUSDT\",\"b\":\"79382.50\",\"B\":\"19.150\",\"a\":\"79382.60\",\"A\":\"0.077\",\"T\":1788781927877,\"E\":1788781927877,\"st\":1}}"}
{"receive_ns":1788781927917803000,"stream":"btcusdt@bookTicker","event_type":"bookTicker","event_time_ms":1788781927877,"raw_json":"{\"stream\":\"btcusdt@bookTicker\",\"data\":{\"e\":\"bookTicker\",\"u\":11496321646364,\"s\":\"BTCUSDT\",\"ps\":\"BTCUSDT\",\"b\":\"79382.50\",\"B\":\"19.206\",\"a\":\"79382.60\",\"A\":\"0.077\",\"T\":1788781927877,\"E\":1788781927877,\"st\":1}}"}
{"receive_ns":1788781927917931000,"stream":"btcusdt@bookTicker","event_type":"bookTicker","event_time_ms":1788781927877,"raw_json":"{\"stream\":\"btcusdt@bookTicker\",\"data\":{\"e\":\"bookTicker\",\"u\":11496321646371,\"s\":\"BTCUSDT\",\"ps\":\"BTCUSDT\",\"b\":\"79382.50\",\"B\":\"19.304\",\"a\":\"79382.60\",\"A\":\"0.077\",\"T\":1788781927877,\"E\":1788781927877,\"st\":1}}"}
{"receive_ns":1788781927918060000,"stream":"btcusdt@bookTicker","event_type":"bookTicker","event_time_ms":1788781927877,"raw_json":"{\"stream\":\"btcusdt@bookTicker\",\"data\":{\"e\":\"bookTicker\",\"u\":11496321646373,\"s\":\"BTCUSDT\",\"ps\":\"BTCUSDT\",\"b\":\"79382.50\",\"B\":\"19.573\",\"a\":\"79382.60\",\"A\":\"0.077\",\"T\":1788781927877,\"E\":1788781927877,\"st\":1}}"}
{"receive_ns":1788781927918180000,"stream":"btcusdt@bookTicker","event_type":"bookTicker","event_time_ms":1788781927877,"raw_json":"{\"stream\":\"btcusdt@bookTicker\",\"data\":{\"e\":\"bookTicker\",\"u\":11496321646376,\"s\":\"BTCUSDT\",\"ps\":\"BTCUSDT\",\"b\":\"79382.50\",\"B\":\"19.948\",\"a\":\"79382.60\",\"A\":\"0.077\",\"T\":1788781927877,\"E\":1788781927877,\"st\":1}}"}
{"receive_ns":1788781927918300000,"stream":"btcusdt@bookTicker","event_type":"bookTicker","event_time_ms":1788781927877,"raw_json":"{\"stream\":\"btcusdt@bookTicker\",\"data\":{\"e\":\"bookTicker\",\"u\":11496321646377,\"s\":\"BTCUSDT\",\"ps\":\"BTCUSDT\",\"b\":\"79382.50\",\"B\":\"20.323\",\"a\":\"79382.60\",\"A\":\"0.077\",\"T\":1788781927877,\"E\":1788781927877,\"st\":1}}"}
{"receive_ns":1788781927918424000,"stream":"btcusdt@bookTicker","event_type":"bookTicker","event_time_ms":1788781927877,"raw_json":"{\"stream\":\"btcusdt@bookTicker\",\"data\":{\"e\":\"bookTicker\",\"u\":11496321646378,\"s\":\"BTCUSDT\",\"ps\":\"BTCUSDT\",\"b\":\"79382.50\",\"B\":\"20.592\",\"a\":\"79382.60\",\"A\":\"0.077\",\"T\":1788781927877,\"E\":1788781927877,\"st\":1}}"}
{"receive_ns":1788781927918552000,"stream":"btcusdt@bookTicker","event_type":"bookTicker","event_time_ms":1788781927877,"raw_json":"{\"stream\":\"btcusdt@bookTicker\",\"data\":{\"e\":\"bookTicker\",\"u\":11496321646379,\"s\":\"BTCUSDT\",\"ps\":\"BTCUSDT\",\"b\":\"79382.50\",\"B\":\"21.087\",\"a\":\"79382.60\",\"A\":\"0.077\",\"T\":1788781927877,\"E\":1788781927877,\"st\":1}}"}
{"receive_ns":1788781927918676000,"stream":"btcusdt@bookTicker","event_type":"bookTicker","event_time_ms":1788781927877,"raw_json":"{\"stream\":\"btcusdt@bookTicker\",\"data\":{\"e\":\"bookTicker\",\"u\":11496321646380,\"s\":\"BTCUSDT\",\"ps\":\"BTCUSDT\",\"b\":\"79382.50\",\"B\":\"21.582\",\"a\":\"79382.60\",\"A\":\"0.077\",\"T\":1788781927877,\"E\":1788781927877,\"st\":1}}"}
{"receive_ns":1788781927918799000,"stream":"btcusdt@bookTicker","event_type":"bookTicker","event_time_ms":1788781927877,"raw_json":"{\"stream\":\"btcusdt@bookTicker\",\"data\":{\"e\":\"bookTicker\",\"u\":11496321646381,\"s\":\"BTCUSDT\",\"ps\":\"BTCUSDT\",\"b\":\"79382.50\",\"B\":\"21.851\",\"a\":\"79382.60\",\"A\":\"0.077\",\"T\":1788781927877,\"E\":1788781927877,\"st\":1}}"}
{"receive_ns":1788781927918918000,"stream":"btcusdt@bookTicker","event_type":"bookTicker","event_time_ms":1788781927877,"raw_json":"{\"stream\":\"btcusdt@bookTicker\",\"data\":{\"e\":\"bookTicker\",\"u\":11496321646382,\"s\":\"BTCUSDT\",\"ps\":\"BTCUSDT\",\"b\":\"79382.50\",\"B\":\"21.987\",\"a\":\"79382.60\",\"A\":\"0.077\",\"T\":1788781927877,\"E\":1788781927877,\"st\":1}}"}
{"receive_ns":1788781927919036000,"stream":"btcusdt@bookTicker","event_type":"bookTicker","event_time_ms":1788781927877,"raw_json":"{\"stream\":\"btcusdt@bookTicker\",\"data\":{\"e\":\"bookTicker\",\"u\":11496321646385,\"s\":\"BTCUSDT\",\"ps\":\"BTCUSDT\",\"b\":\"79382.50\",\"B\":\"22.043\",\"a\":\"79382.60\",\"A\":\"0.077\",\"T\":1788781927877,\"E\":1788781927877,\"st\":1}}"}
{"receive_ns":1788781927919158000,"stream":"btcusdt@bookTicker","event_type":"bookTicker","event_time_ms":1788781927877,"raw_json":"{\"stream\":\"btcusdt@bookTicker\",\"data\":{\"e\":\"bookTicker\",\"u\":11496321646387,\"s\":\"BTCUSDT\",\"ps\":\"BTCUSDT\",\"b\":\"79382.50\",\"B\":\"22.199\",\"a\":\"79382.60\",\"A\":\"0.077\",\"T\":1788781927877,\"E\":1788781927877,\"st\":1}}"}
{"receive_ns":1788781927919278000,"stream":"btcusdt@bookTicker","event_type":"bookTicker","event_time_ms":1788781927877,"raw_json":"{\"stream\":\"btcusdt@bookTicker\",\"data\":{\"e\":\"bookTicker\",\"u\":11496321646394,\"s\":\"BTCUSDT\",\"ps\":\"BTCUSDT\",\"b\":\"79382.50\",\"B\":\"22.255\",\"a\":\"79382.60\",\"A\":\"0.077\",\"T\":1788781927877,\"E\":1788781927877,\"st\":1}}"}
{"receive_ns":1788781927919437000,"stream":"btcusdt@bookTicker","event_type":"bookTicker","event_time_ms":1788781927877,"raw_json":"{\"stream\":\"btcusdt@bookTicker\",\"data\":{\"e\":\"bookTicker\",\"u\":11496321646396,\"s\":\"BTCUSDT\",\"ps\":\"BTCUSDT\",\"b\":\"79382.50\",\"B\":\"22.382\",\"a\":\"79382.60\",\"A\":\"0.077\",\"T\":1788781927877,\"E\":1788781927877,\"st\":1}}"}
{"receive_ns":1788781927919756000,"stream":"btcusdt@bookTicker","event_type":"bookTicker","event_time_ms":1788781927877,"raw_json":"{\"stream\":\"btcusdt@bookTicker\",\"data\":{\"e\":\"bookTicker\",\"u\":11496321646398,\"s\":\"BTCUSDT\",\"ps\":\"BTCUSDT\",\"b\":\"79382.50\",\"B\":\"22.651\",\"a\":\"79382.60\",\"A\":\"0.077\",\"T\":1788781927877,\"E\":1788781927877,\"st\":1}}"}
{"receive_ns":1788781927919915000,"stream":"btcusdt@bookTicker","event_type":"bookTicker","event_time_ms":1788781927877,"raw_json":"{\"stream\":\"btcusdt@bookTicker\",\"data\":{\"e\":\"bookTicker\",\"u\":11496321646401,\"s\":\"BTCUSDT\",\"ps\":\"BTCUSDT\",\"b\":\"79382.50\",\"B\":\"22.920\",\"a\":\"79382.60\",\"A\":\"0.077\",\"T\":1788781927877,\"E\":1788781927877,\"st\":1}}"}
{"receive_ns":1788781927920063000,"stream":"btcusdt@bookTicker","event_type":"bookTicker","event_time_ms":1788781927877,"raw_json":"{\"stream\":\"btcusdt@bookTicker\",\"data\":{\"e\":\"bookTicker\",\"u\":11496321646403,\"s\":\"BTCUSDT\",\"ps\":\"BTCUSDT\",\"b\":\"79382.50\",\"B\":\"23.047\",\"a\":\"79382.60\",\"A\":\"0.077\",\"T\":1788781927877,\"E\":1788781927877,\"st\":1}}"}
{"receive_ns":1788781927920189000,"stream":"btcusdt@bookTicker","event_type":"bookTicker","event_time_ms":1788781927877,"raw_json":"{\"stream\":\"btcusdt@bookTicker\",\"data\":{\"e\":\"bookTicker\",\"u\":11496321646404,\"s\":\"BTCUSDT\",\"ps\":\"BTCUSDT\",\"b\":\"79382.50\",\"B\":\"23.542\",\"a\":\"79382.60\",\"A\":\"0.077\",\"T\":1788781927877,\"E\":1788781927877,\"st\":1}}"}
{"receive_ns":1788781927920310000,"stream":"btcusdt@bookTicker","event_type":"bookTicker","event_time_ms":1788781927877,"raw_json":"{\"stream\":\"btcusdt@bookTicker\",\"data\":{\"e\":\"bookTicker\",\"u\":11496321646410,\"s\":\"BTCUSDT\",\"ps\":\"BTCUSDT\",\"b\":\"79382.50\",\"B\":\"23.811\",\"a\":\"79382.60\",\"A\":\"0.077\",\"T\":1788781927877,\"E\":1788781927877,\"st\":1}}"}
{"receive_ns":1788781927920435000,"stream":"btcusdt@bookTicker","event_type":"bookTicker","event_time_ms":1788781927877,"raw_json":"{\"stream\":\"btcusdt@bookTicker\",\"data\":{\"e\":\"bookTicker\",\"u\":11496321646415,\"s\":\"BTCUSDT\",\"ps\":\"BTCUSDT\",\"b\":\"79382.50\",\"B\":\"23.967\",\"a\":\"79382.60\",\"A\":\"0.077\",\"T\":1788781927877,\"E\":1788781927877,\"st\":1}}"}
{"receive_ns":1788781927920556000,"stream":"btcusdt@bookTicker","event_type":"bookTicker","event_time_ms":1788781927877,"raw_json":"{\"stream\":\"btcusdt@bookTicker\",\"data\":{\"e\":\"bookTicker\",\"u\":11496321646417,\"s\":\"BTCUSDT\",\"ps\":\"BTCUSDT\",\"b\":\"79382.50\",\"B\":\"24.023\",\"a\":\"79382.60\",\"A\":\"0.077\",\"T\":1788781927877,\"E\":1788781927877,\"st\":1}}"}
{"receive_ns":1788781927920676000,"stream":"btcusdt@bookTicker","event_type":"bookTicker","event_time_ms":1788781927877,"raw_json":"{\"stream\":\"btcusdt@bookTicker\",\"data\":{\"e\":\"bookTicker\",\"u\":11496321646421,\"s\":\"BTCUSDT\",\"ps\":\"BTCUSDT\",\"b\":\"79382.50\",\"B\":\"24.179\",\"a\":\"79382.60\",\"A\":\"0.077\",\"T\":1788781927877,\"E\":1788781927877,\"st\":1}}"}
{"receive_ns":1788781927920794000,"stream":"btcusdt@bookTicker","event_type":"bookTicker","event_time_ms":1788781927877,"raw_json":"{\"stream\":\"btcusdt@bookTicker\",\"data\":{\"e\":\"bookTicker\",\"u\":11496321646435,\"s\":\"BTCUSDT\",\"ps\":\"BTCUSDT\",\"b\":\"79382.50\",\"B\":\"24.235\",\"a\":\"79382.60\",\"A\":\"0.077\",\"T\":1788781927877,\"E\":1788781927877,\"st\":1}}"}
{"receive_ns":1788781927920914000,"stream":"btcusdt@bookTicker","event_type":"bookTicker","event_time_ms":1788781927877,"raw_json":"{\"stream\":\"btcusdt@bookTicker\",\"data\":{\"e\":\"bookTicker\",\"u\":11496321646438,\"s\":\"BTCUSDT\",\"ps\":\"BTCUSDT\",\"b\":\"79382.50\",\"B\":\"24.730\",\"a\":\"79382.60\",\"A\":\"0.077\",\"T\":1788781927877,\"E\":1788781927877,\"st\":1}}"}
{"receive_ns":1788781927921033000,"stream":"btcusdt@bookTicker","event_type":"bookTicker","event_time_ms":1788781927877,"raw_json":"{\"stream\":\"btcusdt@bookTicker\",\"data\":{\"e\":\"bookTicker\",\"u\":11496321646440,\"s\":\"BTCUSDT\",\"ps\":\"BTCUSDT\",\"b\":\"79382.50\",\"B\":\"24.828\",\"a\":\"79382.60\",\"A\":\"0.077\",\"T\":1788781927877,\"E\":1788781927877,\"st\":1}}"}
{"receive_ns":1788781927921163000,"stream":"btcusdt@bookTicker","event_type":"bookTicker","event_time_ms":1788781927877,"raw_json":"{\"stream\":\"btcusdt@bookTicker\",\"data\":{\"e\":\"bookTicker\",\"u\":11496321646443,\"s\":\"BTCUSDT\",\"ps\":\"BTCUSDT\",\"b\":\"79382.50\",\"B\":\"24.926\",\"a\":\"79382.60\",\"A\":\"0.077\",\"T\":1788781927877,\"E\":1788781927877,\"st\":1}}"}
{"receive_ns":1788781927921315000,"stream":"btcusdt@bookTicker","event_type":"bookTicker","event_time_ms":1788781927877,"raw_json":"{\"stream\":\"btcusdt@bookTicker\",\"data\":{\"e\":\"bookTicker\",\"u\":11496321646450,\"s\":\"BTCUSDT\",\"ps\":\"BTCUSDT\",\"b\":\"79382.50\",\"B\":\"24.094\",\"a\":\"79382.60\",\"A\":\"0.077\",\"T\":1788781927877,\"E\":1788781927877,\"st\":1}}"}
{"receive_ns":1788781927921438000,"stream":"btcusdt@bookTicker","event_type":"bookTicker","event_time_ms":1788781927877,"raw_json":"{\"stream\":\"btcusdt@bookTicker\",\"data\":{\"e\":\"bookTicker\",\"u\":11496321646452,\"s\":\"BTCUSDT\",\"ps\":\"BTCUSDT\",\"b\":\"79382.50\",\"B\":\"24.926\",\"a\":\"79382.60\",\"A\":\"0.077\",\"T\":1788781927877,\"E\":1788781927877,\"st\":1}}"}
{"receive_ns":1788781927921559000,"stream":"btcusdt@bookTicker","event_type":"bookTicker","event_time_ms":1788781927877,"raw_json":"{\"stream\":\"btcusdt@bookTicker\",\"data\":{\"e\":\"bookTicker\",\"u\":11496321646454,\"s\":\"BTCUSDT\",\"ps\":\"BTCUSDT\",\"b\":\"79382.50\",\"B\":\"25.301\",\"a\":\"79382.60\",\"A\":\"0.077\",\"T\":1788781927877,\"E\":1788781927877,\"st\":1}}"}
{"receive_ns":1788781927921680000,"stream":"btcusdt@bookTicker","event_type":"bookTicker","event_time_ms":1788781927877,"raw_json":"{\"stream\":\"btcusdt@bookTicker\",\"data\":{\"e\":\"bookTicker\",\"u\":11496321646460,\"s\":\"BTCUSDT\",\"ps\":\"BTCUSDT\",\"b\":\"79382.50\",\"B\":\"24.921\",\"a\":\"79382.60\",\"A\":\"0.077\",\"T\":1788781927877,\"E\":1788781927877,\"st\":1}}"}
{"receive_ns":1788781927921804000,"stream":"btcusdt@bookTicker","event_type":"bookTicker","event_time_ms":1788781927877,"raw_json":"{\"stream\":\"btcusdt@bookTicker\",\"data\":{\"e\":\"bookTicker\",\"u\":11496321646472,\"s\":\"BTCUSDT\",\"ps\":\"BTCUSDT\",\"b\":\"79382.50\",\"B\":\"25.077\",\"a\":\"79382.60\",\"A\":\"0.077\",\"T\":1788781927877,\"E\":1788781927877,\"st\":1}}"}
{"receive_ns":1788781927921927000,"stream":"btcusdt@bookTicker","event_type":"bookTicker","event_time_ms":1788781927877,"raw_json":"{\"stream\":\"btcusdt@bookTicker\",\"data\":{\"e\":\"bookTicker\",\"u\":11496321646474,\"s\":\"BTCUSDT\",\"ps\":\"BTCUSDT\",\"b\":\"79382.50\",\"B\":\"25.572\",\"a\":\"79382.60\",\"A\":\"0.077\",\"T\":1788781927877,\"E\":1788781927877,\"st\":1}}"}
{"receive_ns":1788781927922051000,"stream":"btcusdt@bookTicker","event_type":"bookTicker","event_time_ms":1788781927877,"raw_json":"{\"stream\":\"btcusdt@bookTicker\",\"data\":{\"e\":\"bookTicker\",\"u\":11496321646479,\"s\":\"BTCUSDT\",\"ps\":\"BTCUSDT\",\"b\":\"79382.50\",\"B\":\"25.947\",\"a\":\"79382.60\",\"A\":\"0.077\",\"T\":1788781927877,\"E\":1788781927877,\"st\":1}}"}
{"receive_ns":1788781927922237000,"stream":"btcusdt@bookTicker","event_type":"bookTicker","event_time_ms":1788781927877,"raw_json":"{\"stream\":\"btcusdt@bookTicker\",\"data\":{\"e\":\"bookTicker\",\"u\":11496321646482,\"s\":\"BTCUSDT\",\"ps\":\"BTCUSDT\",\"b\":\"79382.50\",\"B\":\"26.103\",\"a\":\"79382.60\",\"A\":\"0.077\",\"T\":1788781927877,\"E\":1788781927877,\"st\":1}}"}
{"receive_ns":1788781927922373000,"stream":"btcusdt@bookTicker","event_type":"bookTicker","event_time_ms":1788781927877,"raw_json":"{\"stream\":\"btcusdt@bookTicker\",\"data\":{\"e\":\"bookTicker\",\"u\":11496321646489,\"s\":\"BTCUSDT\",\"ps\":\"BTCUSDT\",\"b\":\"79382.50\",\"B\":\"26.664\",\"a\":\"79382.60\",\"A\":\"0.077\",\"T\":1788781927877,\"E\":1788781927877,\"st\":1}}"}
{"receive_ns":1788781927922500000,"stream":"btcusdt@bookTicker","event_type":"bookTicker","event_time_ms":1788781927877,"raw_json":"{\"stream\":\"btcusdt@bookTicker\",\"data\":{\"e\":\"bookTicker\",\"u\":11496321646490,\"s\":\"BTCUSDT\",\"ps\":\"BTCUSDT\",\"b\":\"79382.50\",\"B\":\"26.933\",\"a\":\"79382.60\",\"A\":\"0.077\",\"T\":1788781927877,\"E\":1788781927877,\"st\":1}}"}
{"receive_ns":1788781927922621000,"stream":"btcusdt@bookTicker","event_type":"bookTicker","event_time_ms":1788781927877,"raw_json":"{\"stream\":\"btcusdt@bookTicker\",\"data\":{\"e\":\"bookTicker\",\"u\":11496321646493,\"s\":\"BTCUSDT\",\"ps\":\"BTCUSDT\",\"b\":\"79382.50\",\"B\":\"27.032\",\"a\":\"79382.60\",\"A\":\"0.077\",\"T\":1788781927877,\"E\":1788781927877,\"st\":1}}"}
{"receive_ns":1788781927922742000,"stream":"btcusdt@bookTicker","event_type":"bookTicker","event_time_ms":1788781927877,"raw_json":"{\"stream\":\"btcusdt@bookTicker\",\"data\":{\"e\":\"bookTicker\",\"u\":11496321646497,\"s\":\"BTCUSDT\",\"ps\":\"BTCUSDT\",\"b\":\"79382.50\",\"B\":\"27.188\",\"a\":\"79382.60\",\"A\":\"0.077\",\"T\":1788781927877,\"E\":1788781927877,\"st\":1}}"}
{"receive_ns":1788781927922869000,"stream":"btcusdt@bookTicker","event_type":"bookTicker","event_time_ms":1788781927877,"raw_json":"{\"stream\":\"btcusdt@bookTicker\",\"data\":{\"e\":\"bookTicker\",\"u\":11496321646503,\"s\":\"BTCUSDT\",\"ps\":\"BTCUSDT\",\"b\":\"79382.50\",\"B\":\"27.286\",\"a\":\"79382.60\",\"A\":\"0.077\",\"T\":1788781927877,\"E\":1788781927877,\"st\":1}}"}
{"receive_ns":1788781927922997000,"stream":"btcusdt@bookTicker","event_type":"bookTicker","event_time_ms":1788781927877,"raw_json":"{\"stream\":\"btcusdt@bookTicker\",\"data\":{\"e\":\"bookTicker\",\"u\":11496321646505,\"s\":\"BTCUSDT\",\"ps\":\"BTCUSDT\",\"b\":\"79382.50\",\"B\":\"27.661\",\"a\":\"79382.60\",\"A\":\"0.077\",\"T\":1788781927877,\"E\":1788781927877,\"st\":1}}"}
{"receive_ns":1788781927923124000,"stream":"btcusdt@bookTicker","event_type":"bookTicker","event_time_ms":1788781927877,"raw_json":"{\"stream\":\"btcusdt@bookTicker\",\"data\":{\"e\":\"bookTicker\",\"u\":11496321646507,\"s\":\"BTCUSDT\",\"ps\":\"BTCUSDT\",\"b\":\"79382.50\",\"B\":\"27.788\",\"a\":\"79382.60\",\"A\":\"0.077\",\"T\":1788781927877,\"E\":1788781927877,\"st\":1}}"}
{"receive_ns":1788781927923246000,"stream":"btcusdt@bookTicker","event_type":"bookTicker","event_time_ms":1788781927877,"raw_json":"{\"stream\":\"btcusdt@bookTicker\",\"data\":{\"e\":\"bookTicker\",\"u\":11496321646511,\"s\":\"BTCUSDT\",\"ps\":\"BTCUSDT\",\"b\":\"79382.50\",\"B\":\"27.886\",\"a\":\"79382.60\",\"A\":\"0.077\",\"T\":1788781927877,\"E\":1788781927877,\"st\":1}}"}
{"receive_ns":1788781927923503000,"stream":"btcusdt@bookTicker","event_type":"bookTicker","event_time_ms":1788781927877,"raw_json":"{\"stream\":\"btcusdt@bookTicker\",\"data\":{\"e\":\"bookTicker\",\"u\":11496321646518,\"s\":\"BTCUSDT\",\"ps\":\"BTCUSDT\",\"b\":\"79382.50\",\"B\":\"28.042\",\"a\":\"79382.60\",\"A\":\"0.077\",\"T\":1788781927877,\"E\":1788781927877,\"st\":1}}"}
{"receive_ns":1788781927923720000,"stream":"btcusdt@bookTicker","event_type":"bookTicker","event_time_ms":1788781927877,"raw_json":"{\"stream\":\"btcusdt@bookTicker\",\"data\":{\"e\":\"bookTicker\",\"u\":11496321646528,\"s\":\"BTCUSDT\",\"ps\":\"BTCUSDT\",\"b\":\"79382.50\",\"B\":\"28.169\",\"a\":\"79382.60\",\"A\":\"0.077\",\"T\":1788781927877,\"E\":1788781927877,\"st\":1}}"}
{"receive_ns":1788781927923850000,"stream":"btcusdt@bookTicker","event_type":"bookTicker","event_time_ms":1788781927877,"raw_json":"{\"stream\":\"btcusdt@bookTicker\",\"data\":{\"e\":\"bookTicker\",\"u\":11496321646533,\"s\":\"BTCUSDT\",\"ps\":\"BTCUSDT\",\"b\":\"79382.50\",\"B\":\"28.664\",\"a\":\"79382.60\",\"A\":\"0.077\",\"T\":1788781927877,\"E\":1788781927877,\"st\":1}}"}
{"receive_ns":1788781927923973000,"stream":"btcusdt@bookTicker","event_type":"bookTicker","event_time_ms":1788781927877,"raw_json":"{\"stream\":\"btcusdt@bookTicker\",\"data\":{\"e\":\"bookTicker\",\"u\":11496321646537,\"s\":\"BTCUSDT\",\"ps\":\"BTCUSDT\",\"b\":\"79382.50\",\"B\":\"28.762\",\"a\":\"79382.60\",\"A\":\"0.077\",\"T\":1788781927877,\"E\":1788781927877,\"st\":1}}"}
{"receive_ns":1788781927924094000,"stream":"btcusdt@bookTicker","event_type":"bookTicker","event_time_ms":1788781927877,"raw_json":"{\"stream\":\"btcusdt@bookTicker\",\"data\":{\"e\":\"bookTicker\",\"u\":11496321646540,\"s\":\"BTCUSDT\",\"ps\":\"BTCUSDT\",\"b\":\"79382.50\",\"B\":\"29.142\",\"a\":\"79382.60\",\"A\":\"0.077\",\"T\":1788781927877,\"E\":1788781927877,\"st\":1}}"}
{"receive_ns":1788781927924213000,"stream":"btcusdt@bookTicker","event_type":"bookTicker","event_time_ms":1788781927877,"raw_json":"{\"stream\":\"btcusdt@bookTicker\",\"data\":{\"e\":\"bookTicker\",\"u\":11496321646542,\"s\":\"BTCUSDT\",\"ps\":\"BTCUSDT\",\"b\":\"79382.50\",\"B\":\"29.269\",\"a\":\"79382.60\",\"A\":\"0.077\",\"T\":1788781927877,\"E\":1788781927877,\"st\":1}}"}
{"receive_ns":1788781927924331000,"stream":"btcusdt@bookTicker","event_type":"bookTicker","event_time_ms":1788781927877,"raw_json":"{\"stream\":\"btcusdt@bookTicker\",\"data\":{\"e\":\"bookTicker\",\"u\":11496321646544,\"s\":\"BTCUSDT\",\"ps\":\"BTCUSDT\",\"b\":\"79382.50\",\"B\":\"29.644\",\"a\":\"79382.60\",\"A\":\"0.077\",\"T\":1788781927877,\"E\":1788781927877,\"st\":1}}"}
{"receive_ns":1788781927924620000,"stream":"btcusdt@bookTicker","event_type":"bookTicker","event_time_ms":1788781927877,"raw_json":"{\"stream\":\"btcusdt@bookTicker\",\"data\":{\"e\":\"bookTicker\",\"u\":11496321646551,\"s\":\"BTCUSDT\",\"ps\":\"BTCUSDT\",\"b\":\"79382.50\",\"B\":\"29.727\",\"a\":\"79382.60\",\"A\":\"0.077\",\"T\":1788781927877,\"E\":1788781927877,\"st\":1}}"}
{"receive_ns":1788781927924801000,"stream":"btcusdt@bookTicker","event_type":"bookTicker","event_time_ms":1788781927877,"raw_json":"{\"stream\":\"btcusdt@bookTicker\",\"data\":{\"e\":\"bookTicker\",\"u\":11496321646553,\"s\":\"BTCUSDT\",\"ps\":\"BTCUSDT\",\"b\":\"79382.50\",\"B\":\"29.854\",\"a\":\"79382.60\",\"A\":\"0.077\",\"T\":1788781927877,\"E\":1788781927877,\"st\":1}}"}
{"receive_ns":1788781927924943000,"stream":"btcusdt@bookTicker","event_type":"bookTicker","event_time_ms":1788781927877,"raw_json":"{\"stream\":\"btcusdt@bookTicker\",\"data\":{\"e\":\"bookTicker\",\"u\":11496321646562,\"s\":\"BTCUSDT\",\"ps\":\"BTCUSDT\",\"b\":\"79382.50\",\"B\":\"30.349\",\"a\":\"79382.60\",\"A\":\"0.077\",\"T\":1788781927877,\"E\":1788781927877,\"st\":1}}"}
{"receive_ns":1788781927925255000,"stream":"btcusdt@bookTicker","event_type":"bookTicker","event_time_ms":1788781927877,"raw_json":"{\"stream\":\"btcusdt@bookTicker\",\"data\":{\"e\":\"bookTicker\",\"u\":11496321646564,\"s\":\"BTCUSDT\",\"ps\":\"BTCUSDT\",\"b\":\"79382.50\",\"B\":\"30.844\",\"a\":\"79382.60\",\"A\":\"0.077\",\"T\":1788781927877,\"E\":1788781927877,\"st\":1}}"}
{"receive_ns":1788781927925416000,"stream":"btcusdt@bookTicker","event_type":"bookTicker","event_time_ms":1788781927877,"raw_json":"{\"stream\":\"btcusdt@bookTicker\",\"data\":{\"e\":\"bookTicker\",\"u\":11496321646567,\"s\":\"BTCUSDT\",\"ps\":\"BTCUSDT\",\"b\":\"79382.50\",\"B\":\"30.971\",\"a\":\"79382.60\",\"A\":\"0.077\",\"T\":1788781927877,\"E\":1788781927877,\"st\":1}}"}
{"receive_ns":1788781927925589000,"stream":"btcusdt@bookTicker","event_type":"bookTicker","event_time_ms":1788781927877,"raw_json":"{\"stream\":\"btcusdt@bookTicker\",\"data\":{\"e\":\"bookTicker\",\"u\":11496321646573,\"s\":\"BTCUSDT\",\"ps\":\"BTCUSDT\",\"b\":\"79382.50\",\"B\":\"31.127\",\"a\":\"79382.60\",\"A\":\"0.077\",\"T\":1788781927877,\"E\":1788781927877,\"st\":1}}"}
{"receive_ns":1788781927925756000,"stream":"btcusdt@bookTicker","event_type":"bookTicker","event_time_ms":1788781927877,"raw_json":"{\"stream\":\"btcusdt@bookTicker\",\"data\":{\"e\":\"bookTicker\",\"u\":11496321646586,\"s\":\"BTCUSDT\",\"ps\":\"BTCUSDT\",\"b\":\"79382.50\",\"B\":\"31.225\",\"a\":\"79382.60\",\"A\":\"0.077\",\"T\":1788781927877,\"E\":1788781927877,\"st\":1}}"}
{"receive_ns":1788781927925893000,"stream":"btcusdt@bookTicker","event_type":"bookTicker","event_time_ms":1788781927877,"raw_json":"{\"stream\":\"btcusdt@bookTicker\",\"data\":{\"e\":\"bookTicker\",\"u\":11496321646589,\"s\":\"BTCUSDT\",\"ps\":\"BTCUSDT\",\"b\":\"79382.50\",\"B\":\"31.324\",\"a\":\"79382.60\",\"A\":\"0.077\",\"T\":1788781927877,\"E\":1788781927877,\"st\":1}}"}
{"receive_ns":1788781927926122000,"stream":"btcusdt@bookTicker","event_type":"bookTicker","event_time_ms":1788781927877,"raw_json":"{\"stream\":\"btcusdt@bookTicker\",\"data\":{\"e\":\"bookTicker\",\"u\":11496321646590,\"s\":\"BTCUSDT\",\"ps\":\"BTCUSDT\",\"b\":\"79382.50\",\"B\":\"31.451\",\"a\":\"79382.60\",\"A\":\"0.077\",\"T\":1788781927877,\"E\":1788781927877,\"st\":1}}"}
{"receive_ns":1788781927926313000,"stream":"btcusdt@bookTicker","event_type":"bookTicker","event_time_ms":1788781927877,"raw_json":"{\"stream\":\"btcusdt@bookTicker\",\"data\":{\"e\":\"bookTicker\",\"u\":11496321646592,\"s\":\"BTCUSDT\",\"ps\":\"BTCUSDT\",\"b\":\"79382.50\",\"B\":\"31.946\",\"a\":\"79382.60\",\"A\":\"0.077\",\"T\":1788781927877,\"E\":1788781927877,\"st\":1}}"}
