{"kind": "depth", "E": 1787095165623, "U": 11316360876317, "u": 11316360881924, "recv_ms": 1787095165707, "bids": [[14178.9, 0.966], [14278.9, 3.234], [14378.9, 0.0], [58211.0, 0.01], [61444.9, 0.0], [62091.7, 0.0], [63678.9, 1.153], [63814.2, 3.204], [64032.1, 4.668], [64506.5, 0.0], [64506.6, 0.069], [64662.5, 0.004], [64673.0, 0.425], [64676.3, 0.003], [64678.9, 4.727]], "asks": [[64682.8, 0.18], [64682.9, 0.678], [64683.0, 0.174], [64683.1, 0.207], [64683.2, 0.502], [64684.3, 0.001], [64684.8, 0.035], [64691.9, 1.427], [64695.0, 0.924], [64701.0, 0.433], [64701.1, 0.334], [64702.2, 1.017], [64702.9, 0.561], [64703.1, 0.158], [64721.0, 0.235], [64721.1, 0.675], [65325.8, 0.811], [65616.8, 3.919], [65679.0, 0.322], [71146.9, 0.0]]}
{"kind": "depth", "E": 1787095165725, "U": 11316360882031, "u": 11316360888594, "recv_ms": 1787095165797, "bids": [[1000.0, 35.76], [14178.9, 1.33], [14278.9, 2.87], [58211.0, 0.01], [61444.9, 0.0], [61445.1, 0.006], [62091.7, 0.003], [63858.7, 0.955], [64032.1, 4.668], [64614.2, 2.164], [64624.5, 0.018], [64644.7, 0.0], [64655.4, 0.001], [64659.1, 0.117], [64659.4, 0.002], [64660.6, 0.027], [64662.5, 0.006], [64665.8, 2.78], [64666.2, 0.256], [64667.3, 0.422], [64667.4, 0.009], [64673.0, 0.004], [64675.1, 0.01], [64677.1, 0.002], [64677.5, 0.243], [64678.9, 4.042]], "asks": [[64682.7, 0.009], [64682.8, 0.328], [64682.9, 0.052], [64683.0, 0.011], [64683.9, 0.301], [64684.7, 0.009], [64684.8, 0.676], [64685.3, 0.197], [64687.2, 0.007], [64687.3, 0.41], [64687.9, 0.74], [64690.3, 0.515], [64691.1, 0.164], [64691.9, 1.581], [64692.2, 0.035], [64694.6, 0.505], [64695.0, 0.926], [64696.1, 0.379], [64698.8, 0.163], [64743.7, 0.009], [65325.8, 0.811], [65576.8, 6.919]]}
{"kind": "depth", "E": 1787095165827, "U": 11316360888670, "u": 11316360895003, "recv_ms": 1787095165901, "bids": [[14178.9, 1.666], [14278.9, 2.534], [51743.0, 0.0], [58211.0, 0.01], [62091.7, 0.0], [64355.5, 3.416], [64555.1, 0.0], [64671.5, 1.748], [64672.9, 1.78], [64675.0, 1.433], [64675.1, 0.01], [64678.8, 0.016]], "asks": [[64683.0, 0.011], [64683.1, 0.319], [64683.9, 0.075], [64684.3, 0.451], [64684.7, 0.086], [64684.8, 0.591], [64687.6, 0.047], [64691.0, 0.063], [64691.1, 0.164], [64874.9, 5.962], [65325.8, 0.811], [65972.5, 0.015]]}
{"kind": "depth", "E": 1787095165929, "U": 11316360895623, "u": 11316360902688, "recv_ms": 1787095165998, "bids": [[1000.0, 35.76], [14178.9, 2.03], [14278.9, 2.17], [51743.1, 0.0], [58211.0, 0.01], [61444.9, 0.0], [63678.9, 1.173], [64032.1, 4.668], [64338.2, 0.0], [64338.3, 0.499], [64403.3, 0.054], [64560.9, 0.0], [64562.2, 4.315], [64570.9, 0.0], [64571.2, 6.246], [64607.6, 0.047], [64634.2, 0.07], [64641.6, 2.058], [64671.1, 0.086], [64672.9, 1.668], [64674.4, 0.003], [64674.6, 0.01], [64675.1, 0.431], [64676.3, 0.003], [64678.9, 4.071]], "asks": [[64679.0, 11.131], [64680.4, 0.001], [64682.2, 0.047], [64682.9, 0.052], [64683.0, 0.011], [64683.1, 0.728], [64683.5, 0.542], [64684.3, 0.001], [64684.7, 0.001], [64684.8, 0.058], [64691.0, 0.055], [64691.1, 0.156], [64750.0, 3.04], [64756.7, 0.049], [64784.7, 0.0], [64785.0, 4.008], [64814.3, 3.866], [64867.4, 0.015], [64867.5, 0.003], [65325.8, 0.811], [65679.0, 0.342]]}
{"kind": "depth", "E": 1787095166031, "U": 11316360902816, "u": 11316360909639, "recv_ms": 1787095166101, "bids": [[1000.0, 35.76], [14178.9, 2.394], [14278.9, 1.806], [58211.0, 0.01], [61444.9, 0.0], [62091.7, 0.003], [63672.1, 0.0], [63736.0, 14.27], [63772.4, 2.504], [63870.4, 6.359], [64032.1, 4.668], [64249.8, 0.008], [64256.3, 0.0], [64520.3, 6.623], [64537.3, 4.599], [64624.5, 0.004], [64624.9, 0.053], [64627.8, 0.388], [64634.2, 0.066], [64635.7, 0.101], [64641.6, 2.062], [64655.4, 0.001], [64658.2, 0.778], [64660.6, 0.027], [64665.6, 0.665], [64667.3, 0.422], [64667.4, 0.009], [64672.9, 1.893], [64673.0, 0.004], [64675.1, 0.01], [64678.9, 4.091]], "asks": [[64680.4, 0.001], [64682.8, 0.173], [64682.9, 0.052], [64683.0, 0.166], [64683.1, 0.11], [64683.5, 0.317], [64683.9, 0.075], [64684.3, 0.114], [64684.7, 0.156], [64684.8, 0.676], [64685.3, 0.042], [64688.0, 2.143], [64691.1, 0.156], [64691.9, 1.504], [64694.6, 0.505], [64698.8, 0.163], [64819.1, 5.427], [64836.0, 11.272], [64836.1, 0.001], [64874.9, 7.046], [65002.4, 3.538], [65325.8, 0.811]]}
{"kind": "depth", "E": 1787095166133, "U": 11316360909828, "u": 11316360916265, "recv_ms": 1787095166202, "bids": [[14178.9, 2.744], [14278.9, 1.456], [51743.0, 0.0], [58211.0, 0.01], [61444.9, 0.0], [62091.7, 0.0], [63678.9, 1.153], [63685.3, 0.621], [63686.3, 0.017], [63893.2, 34.125], [64032.1, 4.668], [64355.5, 3.426], [64624.5, 0.018], [64648.4, 0.057], [64650.1, 0.096], [64658.2, 0.16], [64665.6, 0.047], [64667.3, 0.422], [64672.9, 1.893], [64675.1, 0.01], [64676.3, 0.003], [64678.9, 4.091]], "asks": [[64679.0, 11.63], [64680.4, 0.001], [64681.9, 0.13], [64682.1, 0.003], [64682.4, 0.087], [64682.7, 0.007], [64682.9, 0.137], [64683.0, 0.828], [64683.1, 0.094], [64683.2, 0.277], [64683.4, 0.179], [64683.5, 0.317], [64683.7, 0.294], [64683.9, 0.188], [64684.3, 0.001], [64684.7, 0.156], [64684.8, 0.042], [64688.0, 1.525], [64690.3, 0.438], [64691.1, 0.172], [64691.9, 1.312], [65325.8, 0.811], [65611.4, 0.0], [65671.7, 12.058], [65672.5, 0.0], [65679.0, 0.322], [67266.2, 1.277]]}
{"kind": "depth", "E": 1787095166235, "U": 11316360916475, "u": 11316360922085, "recv_ms": 1787095166306, "bids": [[1000.0, 35.76], [14178.9, 3.108], [14278.9, 1.092], [51743.0, 0.0], [58211.0, 0.01], [61444.9, 0.0], [61445.0, 0.053], [62091.7, 0.003], [63686.3, 0.035], [63741.1, 5.89], [63779.9, 5.883], [63870.5, 3.766], [64032.1, 4.668], [64355.5, 3.425], [64406.2, 5.635], [64479.1, 4.01], [64520.3, 5.298], [64537.4, 1.283], [64662.0, 0.517], [64672.9, 1.893], [64673.7, 0.085], [64675.1, 0.431], [64678.9, 4.09]], "asks": [[64682.2, 0.047], [64682.8, 0.173], [64682.9, 0.052], [64683.0, 0.166], [64683.1, 0.635], [64683.2, 0.277], [64683.7, 0.293], [64683.9, 0.075], [64684.3, 0.001], [64684.8, 0.135], [64822.4, 4.004], [64874.9, 11.498], [65002.4, 3.539], [65040.9, 6.348], [65325.8, 0.811], [65591.0, 2.441], [65671.7, 12.076]]}
{"kind": "depth", "E": 1787095166337, "U": 11316360922206, "u": 11316360927883, "recv_ms": 1787095166407, "bids": [[1000.0, 35.76], [14178.9, 3.458], [14278.9, 0.742], [51743.0, 0.0], [58211.0, 0.01], [61435.8, 0.0], [62091.7, 0.0], [63587.3, 1.257], [63678.9, 1.173], [63760.6, 0.235], [63870.5, 3.501], [64032.1, 4.668], [64300.0, 81.555], [64520.3, 7.198], [64554.9, 0.095], [64672.9, 1.668], [64674.2, 0.001], [64675.1, 0.431]], "asks": [[64682.2, 0.047], [64682.9, 0.609], [64683.0, 0.166], [64683.1, 0.094], [64683.2, 0.277], [64684.3, 0.001], [64684.7, 0.156], [64684.8, 0.119], [64691.1, 0.172], [64691.9, 1.35], [64874.9, 5.858], [65679.0, 0.342]]}
{"kind": "depth", "E": 1787095166439, "U": 11316360928013, "u": 11316360934138, "recv_ms": 1787095166509, "bids": [[14178.9, 3.738], [14278.9, 0.42], [14578.9, 0.042], [58211.0, 0.01], [63385.4, 0.96], [63632.3, 0.0], [63720.6, 1.101], [63902.8, 20.756], [64032.1, 4.668], [64355.5, 3.425], [64616.0, 1.369], [64616.2, 4.923], [64672.9, 1.78], [64675.1, 0.01]], "asks": [[64682.2, 0.047], [64682.9, 0.052], [64683.0, 0.174], [64683.1, 0.094], [64684.3, 0.001], [64684.7, 0.156], [64684.8, 0.668], [64691.9, 1.504], [65325.8, 0.811], [65445.3, 19.455], [65487.6, 2.319], [65768.7, 3.853]]}
{"kind": "depth", "E": 1787095166643, "U": 11316360939275, "u": 11316360945976, "recv_ms": 1787095166713, "bids": [[1000.0, 35.76], [14178.9, 3.584], [14278.9, 0.14], [14578.9, 0.476], [58211.0, 0.01], [61444.9, 0.001], [62091.7, 0.0], [63644.0, 4.309], [63728.1, 1.882], [64032.1, 4.668], [64537.3, 0.001], [64655.4, 0.001], [64660.6, 0.027], [64662.5, 0.004], [64667.3, 0.422], [64667.4, 0.009], [64672.9, 1.555], [64673.0, 0.004], [64675.1, 0.01], [64676.3, 0.003]], "asks": [[64679.0, 11.671], [64680.4, 0.001], [64682.9, 0.052], [64683.0, 0.011], [64683.1, 0.171], [64683.2, 0.39], [64683.9, 0.075], [64684.3, 0.001], [64684.7, 0.164], [64684.8, 0.591], [64691.1, 0.172], [64691.9, 1.35], [64694.6, 0.505], [64695.0, 0.924], [64698.8, 0.163], [64707.9, 0.006], [64708.0, 1.267], [64708.1, 0.007], [64710.9, 0.009], [64711.0, 0.504], [64711.1, 3.263], [64711.8, 0.005], [64711.9, 0.045], [64712.0, 1.395], [64713.9, 0.002], [64714.0, 0.483], [64714.1, 0.031], [64721.0, 0.389], [64721.1, 0.521], [64771.2, 0.649], [64819.1, 0.027], [65325.8, 0.811], [65455.2, 5.949], [65972.5, 0.018]]}
{"kind": "depth", "E": 1787095166745, "U": 11316360946262, "u": 11316360955023, "recv_ms": 1787095166815, "bids": [[14178.9, 3.444], [14278.9, 0.028], [14578.9, 0.728], [58211.0, 0.01], [61444.9, 0.0], [62091.7, 0.692], [63417.7, 0.473], [63678.9, 1.173], [63870.5, 3.267], [64032.1, 4.668], [64355.5, 3.425], [64537.3, 5.199], [64537.4, 0.093], [64624.5, 0.004], [64655.4, 0.001], [64660.6, 0.027], [64662.5, 0.006], [64667.3, 0.422], [64667.4, 0.009], [64671.9, 0.09], [64672.9, 1.772], [64673.0, 0.012], [64674.5, 0.084], [64674.9, 2.408], [64675.1, 0.01], [64675.2, 0.321], [64675.3, 0.065], [64678.6, 0.323], [64678.9, 4.767]], "asks": [[64682.2, 0.215], [64683.0, 0.011], [64683.1, 0.249], [64683.2, 0.277], [64684.3, 0.226], [64684.7, 0.241], [64690.3, 0.354], [64691.1, 0.172], [64691.9, 1.35], [64693.6, 0.154], [64694.6, 0.505], [64695.0, 0.926], [64695.2, 0.132], [64698.8, 0.163], [64721.0, 0.235], [64817.7, 0.003], [64819.1, 5.427], [65325.8, 0.811], [65679.0, 0.342], [65778.5, 6.674]]}
{"kind": "depth", "E": 1787095166847, "U": 11316360955174, "u": 11316360960640, "recv_ms": 1787095166917, "bids": [[1000.0, 35.76], [14178.9, 3.15], [14278.9, 0.0], [14578.9, 1.05], [58211.0, 0.01], [61444.9, 0.0], [64032.1, 4.668], [64475.2, 4.531], [64537.3, 0.001], [64624.5, 0.004], [64655.4, 0.001], [64660.6, 0.027], [64667.3, 0.422], [64667.4, 0.009], [64670.0, 0.006], [64672.9, 1.547], [64673.0, 0.012], [64675.3, 0.065], [64675.4, 0.004], [64677.6, 0.045], [64678.9, 4.903]], "asks": [[64682.2, 0.215], [64683.0, 0.011], [64683.1, 0.249], [64684.3, 0.226], [64684.7, 0.241], [64691.1, 0.172], [64694.6, 0.505], [64698.8, 0.163], [64721.0, 0.235], [64819.1, 0.027], [65325.8, 0.811], [65438.9, 5.497], [65570.3, 1.807]]}
{"kind": "depth", "E": 1787095166949, "U": 11316360960774, "u": 11316360964668, "recv_ms": 1787095167018, "bids": [[1000.0, 35.76], [14178.9, 2.8], [14578.9, 1.4], [51743.1, 0.0], [58211.0, 0.01], [62091.7, 0.689], [63678.9, 1.153], [63870.4, 6.593], [64032.1, 4.668], [64338.1, 0.492], [64338.3, 0.007], [64624.5, 0.018], [64672.9, 1.66], [64675.3, 0.486], [64676.3, 0.003], [64677.5, 0.245]], "asks": [[64682.2, 0.047], [64683.0, 0.011], [64684.3, 0.001], [64684.7, 0.241], [64721.1, 0.675], [65428.1, 0.534], [65448.7, 2.755], [65611.7, 15.487], [65679.0, 0.322]]}
{"kind": "depth", "E": 1787095167255, "U": 11316360979230, "u": 11316360985313, "recv_ms": 1787095167325, "bids": [[1000.0, 35.76], [14178.9, 1.722], [14578.9, 2.478], [58211.0, 0.01], [61444.9, 0.0], [62091.7, 0.692], [63893.2, 33.345], [63899.6, 4.691], [64032.1, 4.668], [64355.5, 3.427], [64481.4, 0.188], [64481.6, 17.242], [64520.3, 0.143], [64520.4, 7.055], [64537.3, 4.886], [64537.4, 1.326], [64616.2, 2.321], [64616.5, 2.615], [64624.5, 0.004], [64658.1, 1.847], [64665.5, 0.62], [64672.9, 1.547], [64675.3, 0.065], [64677.3, 0.07], [64678.9, 4.903]], "asks": [[64682.2, 0.215], [64683.0, 0.011], [64684.3, 0.114], [64687.9, 1.359], [64690.3, 0.277], [64691.1, 0.172], [64693.6, 0.077], [64695.3, 0.618], [64701.0, 0.431], [64741.2, 2.418], [64771.2, 0.726], [64817.7, 1.23], [64819.1, 5.427], [64835.9, 2.392], [64836.0, 10.438], [64874.8, 6.173], [65002.4, 3.537], [65325.8, 0.811], [65435.7, 1.068], [65604.7, 0.008], [65606.9, 0.008], [65671.6, 0.017]]}
{"kind": "depth", "E": 1787095167459, "U": 11316360990135, "u": 11316360995518, "recv_ms": 1787095167529, "bids": [[1000.0, 35.76], [14178.9, 1.008], [14578.9, 3.192], [58211.0, 0.01], [61444.9, 0.0], [62091.7, 0.689], [63385.4, 0.963], [63814.3, 1.57], [63826.5, 0.782], [64032.1, 4.668], [64520.4, 6.469], [64537.3, 4.555], [64562.2, 0.45], [64562.3, 6.184], [64562.4, 1.89], [64571.2, 6.246], [64607.6, 0.001], [64607.7, 2.451], [64624.5, 0.004], [64634.2, 0.066], [64641.6, 2.062], [64645.2, 0.218], [64650.4, 0.007], [64655.4, 0.001], [64658.1, 1.229], [64658.6, 0.426], [64659.1, 0.001], [64660.6, 0.027], [64661.3, 2.104], [64662.1, 0.001], [64665.3, 0.284], [64665.5, 0.002], [64665.8, 2.321], [64666.2, 0.715], [64667.3, 0.422], [64667.4, 0.009], [64669.4, 0.011], [64671.1, 0.002], [64671.5, 1.664], [64671.6, 0.187], [64672.9, 1.547], [64673.0, 0.125], [64675.1, 0.01], [64675.3, 0.149], [64675.9, 0.091], [64676.0, 0.001], [64677.1, 0.234], [64677.5, 0.013], [64677.6, 0.001], [64678.2, 0.024], [64678.9, 4.75]], "asks": [[64679.0, 11.669], [64679.4, 0.007], [64679.5, 0.0], [64682.2, 0.215], [64683.0, 0.011], [64683.1, 0.249], [64684.3, 0.114], [64684.6, 0.071], [64684.7, 0.241], [64691.1, 0.156], [64691.9, 1.351], [64694.6, 0.505], [64698.8, 0.163], [64701.4, 3.191], [64701.5, 1.237], [64702.2, 0.345], [64702.4, 2.1], [64702.5, 0.12], [64720.4, 3.334], [64720.9, 0.081], [64721.1, 0.675], [64750.0, 3.04], [64767.4, 0.0], [64771.2, 0.526], [64785.0, 4.008], [64814.2, 0.0], [64814.3, 3.866], [64819.1, 5.427], [64836.0, 10.438], [64874.8, 7.066], [65325.8, 0.811], [65455.2, 5.735]]}
{"kind": "depth", "E": 1787095167561, "U": 11316360995727, "u": 11316361002345, "recv_ms": 1787095167630, "bids": [[1000.0, 35.76], [14178.9, 0.644], [14578.9, 3.556], [58211.0, 0.01], [62091.7, 0.692], [63678.9, 1.173], [63902.8, 21.536], [63909.2, 4.692], [64032.1, 4.668], [64355.5, 3.417], [64624.5, 0.032], [64635.7, 0.201], [64673.0, 0.35], [64675.3, 0.57], [64678.9, 4.78]], "asks": [[64682.2, 0.047], [64684.3, 0.001], [64684.6, 0.055], [64691.1, 0.172], [65279.3, 0.0], [65325.8, 0.811], [65584.5, 12.46], [65679.0, 0.342]]}
{"kind": "depth", "E": 1787095167663, "U": 11316361002408, "u": 11316361008969, "recv_ms": 1787095167732, "bids": [[14178.9, 0.364], [14478.9, 0.07], [14578.9, 3.766], [51743.0, 0.0], [58211.0, 0.01], [62091.7, 0.689], [64032.1, 4.668], [64624.5, 0.032], [64658.6, 0.31], [64659.5, 0.794], [64661.3, 1.547], [64662.1, 0.558], [64662.5, 0.004], [64671.9, 0.087], [64673.0, 0.35], [64675.3, 0.57], [64676.5, 0.002]], "asks": [[64682.2, 0.215], [64684.3, 0.001], [64684.6, 0.055], [64691.1, 0.172], [64695.0, 0.924], [65325.8, 0.811]]}
{"kind": "depth", "E": 1787095167765, "U": 11316361009171, "u": 11316361015093, "recv_ms": 1787095167835, "bids": [[1000.0, 35.76], [14178.9, 0.238], [14478.9, 0.294], [14578.9, 3.668], [58211.0, 0.01], [61444.9, 0.0], [61965.2, 0.042], [62091.7, 0.692], [63678.9, 1.153], [64032.1, 4.668], [64520.4, 7.11], [64537.3, 0.001], [64537.4, 4.978], [64624.5, 0.004], [64655.4, 0.001], [64656.8, 0.019], [64660.6, 0.027], [64662.5, 0.006], [64667.3, 0.422], [64667.4, 0.009], [64672.9, 1.66], [64673.0, 0.35], [64673.1, 0.339], [64675.1, 0.002], [64675.3, 0.57], [64675.4, 0.004], [64675.5, 0.014], [64677.1, 0.002], [64677.8, 0.275], [64678.9, 4.78]], "asks": [[64680.5, 0.001], [64681.6, 0.013], [64683.1, 0.249], [64684.6, 0.055], [64684.7, 0.241], [64684.8, 0.59], [64689.0, 1.003], [64691.1, 0.172], [64691.9, 1.191], [64693.8, 0.163], [64694.4, 0.363], [64694.6, 0.505], [64695.0, 0.926], [64696.4, 0.34], [64698.8, 0.163], [64817.7, 0.003], [64819.1, 5.427], [64835.9, 0.0], [64836.0, 10.438], [64874.8, 5.981], [65325.8, 0.811], [65607.0, 20.018], [65679.0, 0.322]]}
{"kind": "depth", "E": 1787095167969, "U": 11316361020409, "u": 11316361025888, "recv_ms": 1787095168039, "bids": [[14178.9, 0.0], [14478.9, 0.784], [14578.9, 3.416], [51743.1, 0.0], [58211.0, 0.01], [61444.9, 0.0], [62091.7, 0.689], [62751.6, 0.022], [63678.9, 1.173], [63736.0, 14.113], [64032.1, 4.668], [64338.1, 0.0], [64338.2, 0.492], [64403.3, 0.001], [64506.5, 0.039], [64506.6, 0.03], [64624.5, 0.032], [64648.6, 3.205], [64649.3, 3.303], [64655.4, 0.001], [64660.6, 0.027], [64667.3, 0.422], [64667.4, 0.009], [64669.4, 0.011], [64671.6, 0.187], [64672.4, 0.549], [64672.7, 0.008], [64672.9, 1.781], [64673.0, 0.004], [64675.1, 0.002], [64675.3, 0.578], [64675.4, 0.004], [64675.5, 0.006], [64676.5, 0.002], [64678.9, 5.562]], "asks": [[64679.0, 11.668], [64681.6, 0.014], [64682.2, 0.215], [64682.9, 0.209], [64683.0, 0.011], [64683.1, 0.094], [64684.3, 0.001], [64684.6, 0.055], [64684.7, 0.234], [64684.8, 0.668], [64685.3, 0.197], [64687.9, 0.661], [64690.3, 0.354], [64691.1, 0.172], [64691.9, 1.352], [64694.6, 0.505], [64695.3, 0.0], [64698.8, 0.163], [64701.7, 0.001], [64704.3, 2.307], [64705.5, 10.007], [64733.4, 0.009], [64736.0, 0.001], [65325.8, 0.811], [65616.8, 5.287], [65679.0, 0.342]]}
{"kind": "depth", "E": 1787095168071, "U": 11316361025922, "u": 11316361031650, "recv_ms": 1787095168144, "bids": [[1000.0, 35.76], [14478.9, 1.134], [14578.9, 3.066], [58211.0, 0.01], [62091.7, 0.692], [63760.5, 0.468], [64032.1, 4.668], [64355.5, 3.416], [64609.6, 1.38], [64609.7, 32.427], [64611.8, 0.001], [64634.9, 0.068], [64641.6, 2.058], [64655.4, 0.001], [64659.1, 0.117], [64659.5, 0.678], [64660.3, 0.002], [64660.6, 0.027], [64661.9, 0.56], [64662.1, 0.001], [64662.9, 0.005], [64667.3, 0.422], [64667.4, 0.009], [64669.4, 0.027], [64671.6, 0.171], [64672.5, 0.544], [64672.8, 0.0], [64672.9, 0.114], [64673.0, 0.229], [64675.1, 1.556], [64675.3, 0.578], [64675.4, 0.004], [64677.3, 0.302], [64677.8, 0.043]], "asks": [[64682.2, 0.215], [64682.9, 0.054], [64683.1, 0.249], [64684.7, 0.389], [64684.8, 0.893], [64685.3, 0.042], [64691.1, 0.172], [64691.8, 0.385], [64691.9, 1.348], [64693.8, 0.163], [64694.6, 0.519], [64698.5, 0.0], [64698.8, 0.008], [64699.1, 0.278], [64699.4, 0.898], [64702.4, 1.428], [64703.1, 0.273], [64703.3, 0.556], [64721.1, 0.521], [64721.2, 0.157], [65002.4, 3.538], [65325.8, 0.811]]}
{"kind": "depth", "E": 1787095168173, "U": 11316361031744, "u": 11316361038143, "recv_ms": 1787095168244, "bids": [[1000.0, 35.76], [14478.9, 1.484], [14578.9, 2.716], [58211.0, 0.01], [61444.9, 0.0], [62091.7, 0.689], [63678.9, 1.153], [63870.4, 7.092], [64032.1, 4.668], [64355.5, 3.426], [64627.1, 0.097], [64669.4, 0.011], [64671.6, 0.187], [64671.7, 0.233], [64672.5, 0.657], [64672.6, 0.918], [64672.7, 0.008], [64672.9, 0.001], [64673.0, 0.004], [64675.3, 0.578], [64676.5, 0.002], [64677.3, 0.07], [64678.9, 5.562]], "asks": [[64679.0, 11.671], [64682.2, 0.215], [64682.8, 0.176], [64683.0, 0.096], [64683.4, 0.179], [64684.3, 0.114], [64684.7, 0.164], [64684.8, 0.599], [64687.9, 0.66], [64689.1, 1.367], [64691.1, 0.156], [64691.9, 1.547], [64693.6, 0.277], [64698.3, 0.459], [64698.4, 0.991], [64699.4, 0.439], [64701.1, 0.332], [64721.2, 0.003], [65325.8, 0.811], [65487.5, 2.775], [65679.0, 0.322]]}
{"kind": "depth", "E": 1787095168275, "U": 11316361038479, "u": 11316361043251, "recv_ms": 1787095168346, "bids": [[14478.9, 1.848], [14578.9, 2.352], [51743.0, 0.0], [58211.0, 0.01], [64032.1, 4.668], [64355.5, 3.425], [64537.5, 1.248], [64612.7, 0.022], [64613.0, 0.384], [64613.4, 0.0], [64613.7, 0.0], [64614.0, 1.001], [64630.3, 0.018], [64630.6, 0.008], [64630.9, 0.025], [64631.2, 0.041], [64631.5, 2.322], [64645.2, 0.078], [64645.3, 0.001], [64645.4, 0.073], [64645.5, 0.028], [64645.6, 0.001], [64645.7, 0.0], [64645.8, 0.202], [64645.9, 0.006], [64646.0, 0.199], [64646.1, 0.0], [64647.0, 0.001], [64647.4, 3.564], [64664.0, 0.902], [64664.1, 0.059], [64664.2, 0.605], [64664.3, 0.079], [64664.4, 0.002], [64664.5, 0.028], [64664.6, 0.005], [64664.7, 0.224], [64664.8, 0.002], [64664.9, 0.003], [64665.0, 0.075], [64665.3, 0.252], [64665.6, 0.015], [64665.9, 1.516], [64666.3, 0.218], [64666.6, 0.797], [64669.4, 0.027], [64671.6, 0.171], [64672.5, 0.544], [64672.7, 0.118], [64675.3, 0.157]], "asks": [[64681.5, 0.084], [64681.9, 0.095], [64682.2, 0.009], [64682.5, 0.003], [64682.8, 0.134], [64682.9, 0.595], [64683.0, 0.011], [64683.1, 0.158], [64683.2, 0.157], [64683.3, 0.085], [64683.4, 0.059], [64683.5, 0.187], [64683.6, 0.31], [64683.7, 0.003], [64683.8, 0.003], [64683.9, 0.005], [64684.0, 0.433], [64684.1, 0.0], [64684.6, 0.055], [64684.7, 0.164], [64684.8, 0.143], [64699.1, 0.246], [64699.4, 0.404], [64699.7, 0.0], [64700.0, 3.32], [64700.4, 0.389], [64700.7, 0.002], [64701.2, 0.057], [64702.0, 0.112], [64702.2, 0.134], [64702.3, 0.001], [64702.4, 1.298], [64702.5, 0.0], [64702.6, 0.004], [64702.7, 0.379], [64702.8, 0.001], [64702.9, 0.47], [64703.0, 0.972], [64716.6, 0.007], [64716.9, 0.001], [64717.2, 0.007], [64717.6, 0.157], [64717.9, 0.001], [64721.1, 0.675], [64736.0, 0.01], [64814.2, 1.485], [64835.9, 2.392], [64874.8, 5.937], [65297.5, 0.675], [65325.8, 0.811], [65487.5, 3.004], [65572.9, 8.367], [65814.1, 5.161], [66000.7, 0.001]]}
{"kind": "depth", "E": 1787095168377, "U": 11316361043260, "u": 11316361049224, "recv_ms": 1787095168447, "bids": [[1000.0, 35.76], [14478.9, 2.198], [14578.9, 2.002], [51743.0, 0.0], [58211.0, 0.01], [61444.9, 0.0], [62091.7, 0.692], [63678.9, 1.173], [63865.4, 9.96], [64032.1, 4.668], [64609.7, 0.189], [64611.1, 1.887], [64611.8, 32.26], [64614.2, 6.658], [64631.6, 1.269], [64656.7, 0.029], [64656.9, 0.975], [64658.1, 1.847], [64664.6, 0.075], [64664.7, 0.294], [64665.0, 0.175], [64665.4, 1.076], [64665.5, 0.62], [64666.6, 0.829], [64669.4, 0.104], [64671.6, 0.094], [64672.6, 0.468], [64672.7, 0.231], [64672.8, 0.113], [64675.1, 1.556], [64675.3, 0.157], [64676.5, 0.002]], "asks": [[64679.0, 11.672], [64681.8, 0.038], [64682.3, 0.532], [64682.9, 0.052], [64683.0, 0.179], [64683.1, 0.249], [64683.3, 0.087], [64683.5, 0.317], [64683.8, 0.073], [64683.9, 0.152], [64684.3, 0.001], [64684.8, 0.909], [64685.4, 0.555], [64687.1, 0.452], [64687.9, 1.278], [64690.3, 0.553], [64691.9, 1.547], [64695.3, 0.618], [64699.4, 0.439], [64701.4, 0.174], [64702.0, 0.203], [64702.4, 1.428], [64702.7, 0.449], [64702.8, 0.071], [64707.9, 0.004], [64708.0, 1.265], [64708.1, 0.005], [64710.9, 0.007], [64711.0, 0.502], [64711.1, 3.261], [64711.8, 0.003], [64711.9, 0.043], [64712.0, 1.393], [64713.9, 0.0], [64714.0, 0.481], [64714.1, 0.029], [64716.9, 0.036], [64721.1, 0.521], [64771.2, 0.442], [65002.4, 3.539], [65325.8, 0.811], [65679.0, 0.342]]}
{"kind": "depth", "E": 1787095168479, "U": 11316361049337, "u": 11316361055596, "recv_ms": 1787095168549, "bids": [[1000.0, 35.76], [14478.9, 2.562], [14578.9, 1.638], [58211.0, 0.01], [62091.7, 0.689], [64032.1, 4.668], [64355.5, 3.425], [64537.4, 0.093], [64537.5, 0.001], [64607.5, 32.259], [64611.8, 0.001], [64614.2, 2.182], [64630.6, 0.04], [64664.4, 0.072], [64664.6, 0.145], [64664.9, 0.203], [64665.1, 0.1], [64665.2, 0.072], [64665.3, 0.352], [64665.7, 0.039], [64669.4, 0.088], [64671.6, 0.11], [64672.7, 0.005], [64672.8, 0.0], [64675.3, 0.157]], "asks": [[64682.2, 0.177], [64682.8, 0.176], [64683.0, 0.124], [64683.1, 0.699], [64683.2, 0.277], [64683.3, 0.178], [64683.4, 0.517], [64683.5, 0.542], [64683.6, 0.57], [64683.9, 0.075], [64684.0, 0.503], [64684.1, 0.077], [64684.3, 0.339], [64684.7, 0.502], [64684.8, 0.797], [64685.3, 0.042], [64685.4, 0.442], [64690.3, 0.354], [64691.9, 1.547], [64700.3, 0.094], [64700.7, 0.122], [64701.2, 0.197], [64702.2, 0.225], [64702.3, 0.121], [64702.5, 0.12], [64702.8, 0.141], [64703.0, 1.049], [64717.9, 0.043], [64721.1, 0.521], [64721.3, 0.603], [64771.2, 0.526], [64819.1, 0.027], [65325.8, 0.811], [65578.0, 8.069], [65819.3, 1.073], [65972.5, 0.012]]}
{"kind": "depth", "E": 1787095168581, "U": 11316361055744, "u": 11316361068256, "recv_ms": 1787095168656, "bids": [[14478.9, 2.912], [14578.9, 1.288], [58211.0, 0.01], [61444.9, 0.0], [62091.7, 0.692], [63385.4, 0.96], [63678.9, 1.153], [63870.4, 7.443], [64032.1, 4.668], [64252.9, 0.0], [64272.9, 0.004], [64364.4, 0.0], [64384.4, 0.024], [64520.4, 7.087], [64537.4, 5.291], [64607.5, 0.0], [64611.9, 32.262], [64621.9, 0.121], [64631.0, 0.032], [64631.3, 0.032], [64631.9, 0.036], [64649.3, 1.303], [64658.1, 1.229], [64664.5, 0.098], [64664.7, 0.364], [64664.8, 0.102], [64665.2, 0.172], [64665.5, 0.002], [64666.0, 0.786], [64666.3, 0.25], [64667.0, 1.285], [64672.3, 2.333], [64672.6, 0.468], [64672.7, 2.009], [64672.8, 0.113], [64675.1, 0.002], [64675.3, 0.578], [64675.9, 0.007], [64676.5, 0.002], [64678.9, 5.411]], "asks": [[64679.0, 11.803], [64680.0, 0.13], [64680.3, 0.312], [64681.5, 0.116], [64682.2, 0.047], [64682.3, 0.889], [64682.4, 0.087], [64682.5, 0.045], [64682.9, 0.052], [64683.0, 0.179], [64683.1, 0.249], [64683.3, 0.296], [64683.4, 0.179], [64683.5, 0.317], [64683.7, 0.153], [64683.8, 0.157], [64683.9, 0.075], [64684.0, 0.594], [64684.3, 0.001], [64684.7, 0.164], [64684.8, 0.797], [64689.0, 1.903], [64690.0, 0.072], [64691.9, 1.547], [64699.0, 0.133], [64699.7, 0.038], [64700.0, 3.362], [64701.5, 5.237], [64702.2, 0.345], [64702.6, 0.154], [64702.7, 0.533], [64702.9, 0.561], [64716.6, 0.039], [64717.2, 0.045], [64717.5, 3.543], [64736.0, 0.001], [64770.4, 0.023], [64771.2, 0.449], [64790.4, 0.004], [64819.1, 5.427], [64836.0, 10.438], [64874.8, 5.746], [65325.8, 0.812], [65622.1, 1.217], [65679.0, 0.322], [67902.7, 0.092]]}
{"kind": "depth", "E": 1787095168683, "U": 11316361068627, "u": 11316361074438, "recv_ms": 1787095168755, "bids": [[1000.0, 35.76], [14478.9, 3.276], [14578.9, 0.924], [58211.0, 0.01], [61444.9, 0.0], [61445.0, 0.051], [61445.1, 0.01], [62091.7, 0.689], [63385.4, 0.957], [64032.1, 4.668], [64576.4, 0.001], [64576.5, 0.003], [64614.1, 0.033], [64621.9, 0.093], [64645.1, 0.0], [64646.1, 0.07], [64646.3, 8.06], [64646.4, 2.008], [64656.7, 0.027], [64669.4, 0.019], [64671.6, 0.171], [64672.7, 1.559], [64672.8, 0.338], [64675.3, 0.578], [64678.9, 5.421]], "asks": [[64679.0, 11.799], [64683.0, 0.011], [64684.8, 0.684], [64687.1, 0.529], [64691.9, 1.624], [64702.2, 0.461], [64702.3, 0.677], [64703.1, 0.158], [64703.3, 0.0], [64704.3, 1.135], [64705.5, 0.007], [64736.0, 0.01], [64856.6, 0.001], [64896.2, 0.003], [65325.8, 0.812], [65487.6, 1.573], [65547.0, 6.042], [65629.8, 3.804], [65972.5, 0.009]]}
{"kind": "depth", "E": 1787095168785, "U": 11316361074587, "u": 11316361080700, "recv_ms": 1787095168854, "bids": [[1000.0, 35.76], [14478.9, 3.626], [14578.9, 0.574], [51743.0, 0.0], [58211.0, 0.01], [63678.9, 1.173], [64032.1, 4.668], [64355.5, 3.425], [64506.5, 0.0], [64506.6, 0.069], [64607.5, 0.0], [64609.7, 32.465], [64611.9, 0.003], [64613.1, 0.057], [64645.5, 0.098], [64645.7, 0.14], [64645.8, 0.272], [64646.1, 0.17], [64646.2, 0.132], [64646.5, 0.073], [64662.5, 0.006], [64672.7, 1.559], [64672.8, 0.0], [64672.9, 0.001], [64675.3, 0.157]], "asks": [[64679.0, 11.806], [64682.2, 0.215], [64683.0, 0.011], [64683.2, 0.502], [64684.3, 0.114], [64684.7, 0.502], [64687.1, 0.613], [64689.0, 1.003], [64690.0, 0.972], [64690.3, 0.707], [64691.9, 1.701], [64695.0, 0.926], [64874.8, 5.267], [65325.8, 0.812], [65679.0, 0.342]]}
{"kind": "depth", "E": 1787095168887, "U": 11316361080778, "u": 11316361086772, "recv_ms": 1787095168958, "bids": [[14378.9, 0.112], [14478.9, 3.766], [14578.9, 0.322], [58211.0, 0.01], [61444.9, 0.0], [61445.0, 0.053], [62091.7, 0.692], [63664.7, 5.49], [63678.9, 1.153], [64032.1, 4.668], [64506.5, 0.039], [64506.6, 0.03], [64613.4, 0.032], [64613.8, 0.034], [64614.4, 1.005], [64624.5, 0.018], [64627.1, 0.125], [64634.9, 0.064], [64641.6, 2.062], [64646.0, 0.299], [64646.3, 8.13], [64647.3, 0.114], [64647.8, 0.174], [64655.4, 0.001], [64658.6, 0.426], [64659.1, 0.001], [64660.6, 0.027], [64661.3, 2.104], [64661.9, 0.003], [64665.3, 0.352], [64666.2, 0.256], [64666.3, 0.709], [64667.3, 0.422], [64667.4, 0.009], [64672.0, 0.009], [64672.6, 0.581], [64672.7, 0.005], [64672.8, 0.008], [64672.9, 0.001], [64675.1, 1.548], [64675.3, 0.578], [64675.9, 0.091], [64676.5, 0.002], [64678.9, 5.422]], "asks": [[64679.0, 11.814], [64682.2, 0.047], [64682.8, 0.344], [64682.9, 0.207], [64683.0, 0.011], [64683.1, 0.094], [64683.2, 0.277], [64684.3, 0.001], [64684.7, 0.009], [64684.8, 0.797], [64685.3, 0.197], [64687.1, 0.529], [64690.3, 0.515], [64691.1, 0.156], [64691.9, 1.547], [64694.6, 0.505], [64698.3, 0.0], [64698.8, 0.622], [64699.1, 0.091], [64721.3, 0.449], [65325.8, 0.814], [65597.5, 0.23], [65679.0, 0.322]]}
{"kind": "depth", "E": 1787095168989, "U": 11316361086839, "u": 11316361091719, "recv_ms": 1787095169057, "bids": [[1000.0, 35.76], [14378.9, 0.364], [14478.9, 3.626], [14578.9, 0.21], [51743.1, 0.0], [58211.0, 0.01], [62091.7, 0.689], [64032.1, 4.668], [64338.2, 0.0], [64338.3, 0.499], [64624.5, 0.004], [64645.6, 0.071], [64645.8, 0.342], [64645.9, 0.106], [64646.3, 8.23], [64655.4, 0.001], [64656.8, 0.021], [64660.6, 0.027], [64661.3, 1.547], [64662.5, 0.563], [64667.3, 0.422], [64667.4, 0.009], [64672.6, 0.468], [64672.7, 0.005], [64672.8, 0.0], [64673.3, 0.086], [64673.6, 0.225], [64675.1, 1.556], [64675.3, 0.157]], "asks": [[64682.2, 0.215], [64682.8, 0.176], [64682.9, 0.052], [64683.1, 0.249], [64684.7, 0.277], [64684.8, 0.684], [64685.3, 0.042], [64690.3, 0.438], [64691.1, 0.156], [64691.9, 1.432], [64693.8, 0.163], [64694.6, 0.505], [64698.8, 0.622], [64701.0, 0.433], [64721.2, 0.003], [64721.3, 0.603], [64721.5, 0.006], [65325.8, 0.812], [65428.1, 0.0], [65443.1, 21.907], [65552.2, 3.03], [65597.5, 0.003], [65669.4, 1.065], [65781.2, 0.0]]}
{"kind": "depth", "E": 1787095169193, "U": 11316361097459, "u": 11316361103070, "recv_ms": 1787095169263, "bids": [[14378.9, 0.854], [14478.9, 3.346], [14578.9, 0.0], [51743.0, 0.0], [58211.0, 0.01], [61444.9, 0.0], [62091.7, 0.689], [63676.4, 5.492], [63678.9, 1.173], [63826.5, 1.564], [64032.1, 4.668], [64355.5, 3.416], [64655.4, 0.001], [64660.6, 0.027], [64667.3, 0.422], [64667.4, 0.009], [64672.7, 0.005], [64675.3, 0.157], [64678.9, 5.422]], "asks": [[64682.2, 0.047], [64683.1, 0.249], [64684.7, 0.164], [64684.8, 0.684], [64685.4, 0.442], [64691.1, 0.156], [64694.6, 0.505], [64698.8, 0.008], [64699.1, 0.246], [64705.4, 10.038], [64721.4, 2.353], [64736.0, 0.001], [64738.6, 0.001], [64878.2, 0.335], [65325.8, 0.812], [65455.1, 9.002], [65547.0, 5.434], [65679.0, 0.342], [65681.5, 3.192], [65778.5, 6.978], [65972.5, 0.009]]}
{"kind": "depth", "E": 1787095169295, "U": 11316361103191, "u": 11316361109144, "recv_ms": 1787095169365, "bids": [[1000.0, 35.76], [14378.9, 1.218], [14478.9, 2.982], [58211.0, 0.01], [61444.9, 0.0], [61445.1, 0.008], [63708.8, 4.036], [63899.6, 3.753], [64032.1, 4.668], [64537.4, 0.093], [64537.5, 1.295], [64671.9, 0.003], [64672.6, 0.581], [64675.3, 0.578], [64676.3, 0.087], [64676.5, 0.002], [64678.9, 5.379]], "asks": [[64679.0, 11.731], [64683.0, 0.011], [64687.9, 0.66], [64691.9, 1.47], [64701.4, 3.191], [64705.4, 0.038], [64721.4, 2.353], [64736.0, 0.01], [64738.6, 0.001], [64817.7, 1.23], [64819.1, 0.027], [65002.4, 3.537], [65325.8, 0.812], [65435.7, 1.602], [65487.6, 1.315]]}
{"kind": "depth", "E": 1787095169397, "U": 11316361109230, "u": 11316361114305, "recv_ms": 1787095169468, "bids": [[1000.0, 35.76], [14378.9, 1.582], [14478.9, 2.618], [58211.0, 0.01], [62091.7, 0.692], [63678.9, 1.153], [63899.6, 2.815], [64032.1, 4.67], [64355.5, 3.417], [64537.4, 5.291], [64537.5, 0.001], [64641.6, 2.062], [64647.8, 0.216], [64652.3, 0.033], [64655.4, 0.001], [64659.6, 0.004], [64660.6, 0.027], [64667.3, 0.422], [64667.4, 0.009], [64671.5, 1.748], [64671.9, 0.087], [64672.0, 0.006], [64672.6, 0.468], [64672.7, 0.343], [64674.7, 0.312], [64674.9, 2.324], [64675.1, 1.556], [64675.2, 0.011], [64675.3, 0.073], [64675.4, 0.004], [64675.9, 0.007], [64676.3, 0.003], [64678.6, 0.222], [64678.9, 5.214]], "asks": [[64679.0, 11.732], [64680.1, 0.007], [64682.2, 0.047], [64683.0, 0.011], [64683.1, 0.249], [64683.8, 0.157], [64684.7, 0.164], [64684.8, 0.797], [64691.1, 0.156], [64691.9, 1.355], [64693.4, 0.16], [64693.8, 0.003], [64694.6, 0.505], [64695.3, 0.0], [64698.8, 0.163], [64699.1, 0.091], [64701.5, 1.237], [64703.0, 11.605], [64720.4, 3.278], [64730.8, 0.251], [64736.0, 0.001], [64817.7, 0.003], [64819.0, 5.4], [64874.8, 5.965], [65325.8, 0.812], [65438.9, 4.581], [65552.2, 3.638], [65679.0, 0.322]]}
{"kind": "depth", "E": 1787095169499, "U": 11316361114339, "u": 11316361118657, "recv_ms": 1787095169568, "bids": [[14378.9, 1.932], [14478.9, 2.268], [58211.0, 0.01], [61444.9, 0.0], [62091.7, 0.689], [63385.4, 0.96], [63708.7, 1.179], [64032.1, 4.668], [64610.6, 0.018], [64633.3, 0.004], [64649.4, 0.0], [64672.6, 0.468], [64672.7, 0.005], [64672.8, 0.0], [64675.2, 0.011], [64676.5, 0.002]], "asks": [[64679.0, 11.744], [64682.2, 0.215], [64684.7, 0.277], [64684.8, 0.684], [64691.9, 1.701], [64701.3, 0.005], [64717.5, 0.043], [64721.6, 1.773], [64740.1, 0.0], [65325.8, 0.811]]}
{"kind": "depth", "E": 1787095169601, "U": 11316361118809, "u": 11316361124007, "recv_ms": 1787095169670, "bids": [[1000.0, 35.76], [14378.9, 2.282], [14478.9, 1.918], [51743.0, 0.0], [58211.0, 0.01], [61444.9, 0.001], [61445.0, 0.051], [61445.1, 0.01], [62091.7, 0.692], [63678.9, 1.173], [63741.1, 6.047], [63909.2, 6.568], [64032.1, 4.668], [64578.3, 0.008], [64609.7, 0.189], [64611.8, 32.277], [64672.7, 0.005], [64675.2, 0.011], [64678.9, 5.214]], "asks": [[64682.2, 0.215], [64682.9, 0.593], [64683.0, 0.201], [64683.5, 0.317], [64684.3, 0.226], [64684.6, 0.055], [64684.7, 0.164], [64684.8, 0.404], [64690.3, 0.431], [64691.9, 1.355], [64721.5, 0.006], [64721.6, 1.619], [64772.5, 2.804], [65325.8, 0.811], [65448.7, 3.671], [65679.0, 0.342], [65788.0, 7.358]]}
{"kind": "depth", "E": 1787095169703, "U": 11316361124189, "u": 11316361128597, "recv_ms": 1787095169774, "bids": [[1000.0, 35.76], [14378.9, 2.646], [14478.9, 1.554], [51743.0, 0.0], [58211.0, 0.01], [61444.9, 0.0], [64032.1, 4.668], [64355.5, 3.417], [64506.5, 0.0], [64506.6, 0.069], [64578.4, 1.767], [64607.5, 32.276], [64608.6, 6.013], [64609.0, 0.009], [64611.8, 0.001], [64631.2, 3.541], [64647.4, 4.108], [64655.4, 0.001], [64660.6, 0.027], [64661.4, 0.557], [64662.5, 0.006], [64665.4, 1.535], [64666.3, 0.25], [64667.3, 0.422], [64667.4, 0.009], [64672.6, 0.468], [64672.7, 0.343], [64675.0, 1.517], [64675.1, 1.556], [64675.2, 0.011], [64675.4, 0.088], [64678.9, 5.214]], "asks": [[64680.1, 0.004], [64682.2, 0.202], [64682.9, 0.052], [64683.0, 0.179], [64683.1, 0.094], [64683.2, 0.277], [64684.3, 0.001], [64684.7, 0.009], [64684.8, 0.676], [64685.3, 0.197], [64690.3, 0.354], [64691.1, 0.156], [64693.4, 0.0], [64693.8, 0.163], [64694.6, 0.505], [64697.8, 3.861], [64698.8, 0.622], [64699.2, 1.273], [64701.4, 3.747], [64701.5, 1.237], [64701.7, 0.001], [64702.5, 0.236], [64702.6, 0.71], [64702.9, 0.561], [64703.0, 11.049], [64717.6, 3.657], [64721.6, 1.619], [64740.2, 6.001], [64793.8, 0.178], [65000.0, 122.727], [65325.8, 0.811], [65487.6, 1.087], [65579.3, 47.324]]}
{"kind": "depth", "E": 1787095169805, "U": 11316361128711, "u": 11316361136525, "recv_ms": 1787095169875, "bids": [[14378.9, 2.996], [14478.9, 1.204], [51743.0, 0.0], [58211.0, 0.01], [61444.9, 0.0], [62091.7, 0.689], [63678.9, 1.153], [63805.8, 2.848], [64032.1, 4.668], [64607.5, 0.0], [64609.7, 32.573], [64646.3, 0.232], [64646.4, 0.286], [64647.4, 4.106], [64647.8, 0.174], [64648.4, 0.0], [64652.8, 0.092], [64653.6, 2.003], [64654.3, 0.001], [64655.4, 0.001], [64656.0, 1.032], [64656.3, 0.002], [64658.4, 0.003], [64658.6, 0.31], [64659.2, 1.336], [64660.3, 0.042], [64660.6, 0.182], [64661.3, 1.554], [64661.4, 0.0], [64661.9, 0.119], [64662.0, 0.516], [64662.5, 0.006], [64662.9, 0.005], [64663.2, 0.021], [64663.8, 0.155], [64664.5, 0.091], [64664.6, 0.702], [64665.4, 1.073], [64665.7, 0.032], [64666.4, 0.015], [64666.7, 0.048], [64666.9, 0.254], [64667.3, 0.577], [64667.4, 0.016], [64667.5, 0.035], [64667.7, 0.019], [64668.0, 0.436], [64668.8, 0.495], [64669.0, 0.0], [64669.3, 3.84], [64669.4, 0.003], [64669.7, 0.004], [64670.2, 1.063], [64670.3, 1.382], [64670.4, 1.283], [64670.7, 0.002], [64671.4, 0.009], [64671.5, 1.664], [64671.6, 0.256], [64671.7, 0.001], [64671.9, 0.003], [64672.1, 0.145], [64672.2, 0.004], [64672.4, 0.001], [64672.5, 0.003], [64672.6, 0.384], [64672.7, 0.09], [64672.8, 0.0], [64672.9, 0.001], [64673.0, 0.004], [64673.6, 0.222], [64673.7, 0.086], [64674.3, 0.314], [64674.4, 0.004], [64674.7, 0.31], [64674.8, 0.001], [64675.0, 2.308], [64675.1, 1.555], [64675.2, 0.561], [64675.3, 0.073], [64675.4, 0.088], [64675.5, 0.423], [64675.6, 0.005], [64676.0, 0.085], [64676.4, 0.084], [64676.5, 0.002], [64676.9, 0.085], [64677.1, 0.546], [64677.4, 0.093], [64678.4, 0.024], [64678.6, 0.438], [64678.9, 7.62]], "asks": [[64679.0, 11.162], [64679.1, 1.395], [64679.2, 0.0], [64679.4, 0.0], [64679.7, 0.001], [64679.8, 0.002], [64680.0, 0.006], [64680.2, 0.085], [64680.8, 0.008], [64681.5, 0.084], [64681.6, 0.013], [64681.8, 0.003], [64681.9, 0.012], [64682.2, 0.009], [64682.3, 0.532], [64682.4, 0.085], [64682.5, 0.003], [64682.8, 0.134], [64683.0, 0.011], [64683.1, 0.24], [64683.2, 0.157], [64683.3, 0.085], [64683.4, 0.121], [64683.6, 0.572], [64684.0, 0.592], [64684.4, 0.003], [64684.6, 0.02], [64684.7, 0.001], [64684.8, 0.026], [64684.9, 1.016], [64685.0, 0.003], [64685.3, 0.042], [64685.4, 0.44], [64685.5, 0.003], [64686.3, 0.0], [64686.7, 0.098], [64686.9, 0.124], [64687.5, 0.264], [64687.6, 0.005], [64687.8, 0.5], [64687.9, 0.032], [64688.0, 1.566], [64688.1, 0.003], [64688.6, 0.005], [64688.7, 0.808], [64690.0, 0.072], [64690.3, 0.553], [64690.4, 0.004], [64690.9, 0.02], [64691.0, 0.678], [64691.1, 2.32], [64691.2, 0.156], [64691.6, 0.618], [64691.9, 1.191], [64692.1, 0.015], [64692.6, 0.728], [64693.7, 0.036], [64693.8, 0.003], [64694.1, 0.659], [64694.2, 0.004], [64694.4, 0.363], [64694.5, 3.65], [64694.6, 0.371], [64695.0, 0.926], [64695.8, 0.002], [64695.9, 0.0], [64696.3, 0.39], [64696.4, 0.18], [64696.8, 0.002], [64697.1, 0.106], [64697.3, 1.707], [64698.3, 0.0], [64698.4, 0.92], [64698.8, 0.008], [64699.1, 0.001], [64699.4, 0.739], [64700.1, 0.478], [64701.0, 0.429], [64701.2, 0.14], [64701.4, 4.206], [64701.5, 1.257], [64701.8, 0.162], [64702.4, 1.428], [64702.5, 0.12], [64702.6, 0.154], [64703.0, 0.742], [64703.6, 0.005], [64704.0, 0.013], [64704.3, 1.444], [64705.2, 0.031], [64706.2, 0.118], [64706.6, 0.221], [64706.7, 0.559], [64707.6, 0.103], [64708.6, 0.024], [64710.4, 10.007], [64720.4, 3.334], [64721.1, 0.641], [64728.3, 0.13], [64736.0, 0.01], [64738.6, 0.01], [64739.2, 1.748], [64739.3, 0.023], [64741.2, 0.092], [64746.2, 2.891], [64753.4, 0.154], [64754.7, 51.866], [64771.2, 0.526], [64793.8, 0.454], [64793.9, 0.0], [64798.9, 0.0], [64835.9, 0.0], [64836.0, 0.027], [64838.5, 2.559], [64838.6, 6.921], [64839.9, 0.0], [64874.8, 0.0], [64877.4, 1.72], [65325.8, 0.811], [65679.0, 0.322]]}
{"kind": "depth", "E": 1787095169907, "U": 11316361136534, "u": 11316361141601, "recv_ms": 1787095169977, "bids": [[1000.0, 35.76], [14378.9, 3.36], [14478.9, 0.84], [58211.0, 0.01], [61444.9, 0.001], [62091.7, 0.692], [64032.1, 4.668], [64042.8, 0.172], [64403.0, 0.038], [64522.2, 0.007], [64522.7, 0.131], [64576.3, 10.0], [64604.5, 0.018], [64609.7, 0.189], [64611.8, 32.385], [64612.6, 0.02], [64655.4, 0.001], [64656.0, 0.132], [64660.6, 0.027], [64666.4, 0.022], [64667.3, 0.422], [64667.4, 0.009], [64668.0, 1.336], [64668.3, 0.46], [64668.8, 0.036], [64669.4, 0.003], [64670.7, 0.01], [64671.6, 0.248], [64672.4, 0.549], [64672.7, 0.09], [64674.3, 0.311], [64675.1, 1.555], [64675.2, 0.016], [64675.3, 0.073], [64675.5, 0.002], [64675.6, 0.005], [64675.7, 0.551], [64675.8, 0.0], [64675.9, 0.007], [64676.0, 0.086], [64677.1, 0.005], [64678.6, 0.702], [64678.9, 7.624]], "asks": [[64679.0, 11.164], [64680.3, 0.074], [64681.1, 0.085], [64681.3, 0.017], [64681.9, 0.002], [64682.2, 0.177], [64683.1, 0.395], [64683.9, 0.3], [64684.8, 0.251], [64685.3, 0.492], [64685.4, 0.475], [64685.5, 0.396], [64685.6, 0.317], [64686.7, 0.253], [64687.1, 0.436], [64687.8, 0.407], [64690.3, 0.707], [64690.9, 0.175], [64692.0, 4.207], [64694.0, 0.001], [64694.4, 0.673], [64694.7, 1.974], [64695.0, 0.026], [64697.4, 0.003], [64699.1, 0.156], [64699.4, 0.704], [64702.4, 1.468], [64707.5, 0.09], [64707.9, 0.006], [64708.0, 1.267], [64708.1, 0.007], [64710.9, 0.009], [64711.0, 0.504], [64711.1, 3.263], [64711.8, 0.005], [64711.9, 0.045], [64712.0, 1.395], [64713.9, 0.002], [64714.0, 0.483], [64714.1, 0.031], [64721.1, 0.521], [64721.5, 0.006], [64721.7, 0.028], [64734.4, 1.412], [64741.5, 51.866], [64751.8, 0.0], [64752.5, 0.001], [64753.4, 0.077], [64754.7, 0.0], [64756.7, 0.049], [64771.2, 0.449], [64772.6, 10.003], [64838.6, 0.049], [64840.6, 7.019], [64877.4, 0.0], [64879.4, 1.747], [65325.8, 0.811], [65375.1, 3.438], [65393.5, 2.292], [71146.9, 0.0]]}
{"kind": "depth", "E": 1787095170009, "U": 11316361141655, "u": 11316361147515, "recv_ms": 1787095170078, "bids": [[14278.9, 0.014], [14378.9, 3.682], [14478.9, 0.504], [51743.1, 0.0], [58211.0, 0.01], [61444.9, 0.0], [62091.7, 0.689], [63678.9, 1.173], [63805.7, 5.676], [63893.2, 28.656], [64032.1, 4.668], [64338.1, 0.492], [64338.3, 0.007], [64355.5, 3.417], [64655.4, 0.001], [64660.6, 0.027], [64667.3, 0.422], [64669.4, 0.003], [64670.7, 0.002], [64671.6, 0.248], [64672.4, 0.549], [64672.5, 0.003], [64672.7, 0.09], [64675.1, 0.009], [64675.2, 2.103], [64675.3, 0.073], [64675.7, 0.01], [64676.0, 0.086], [64677.4, 0.009]], "asks": [[64679.0, 11.164], [64679.7, 0.085], [64681.3, 0.027], [64682.1, 0.013], [64682.2, 0.009], [64683.1, 0.395], [64683.9, 0.075], [64684.8, 0.195], [64685.3, 0.042], [64685.5, 0.116], [64686.4, 0.178], [64686.6, 0.092], [64686.7, 0.245], [64686.8, 1.095], [64688.0, 1.567], [64688.9, 0.01], [64690.3, 0.515], [64690.9, 0.175], [64694.4, 0.673], [64694.7, 2.003], [64697.5, 0.092], [64699.1, 0.156], [64720.9, 0.172], [64721.0, 0.326], [64721.5, 0.006], [64721.6, 1.619], [64735.4, 0.042], [64771.2, 0.526], [64790.6, 0.002], [64836.0, 10.438], [64838.5, 0.002], [64840.6, 0.003], [64874.8, 5.228], [64879.4, 0.028], [65306.4, 0.656], [65325.8, 0.813], [65384.0, 2.357], [65679.0, 0.342]]}
{"kind": "depth", "E": 1787095170111, "U": 11316361147569, "u": 11316361153252, "recv_ms": 1787095170180, "bids": [[14278.9, 0.168], [14378.9, 3.738], [14478.9, 0.294], [58211.0, 0.01], [62091.7, 0.692], [64032.1, 4.668], [64523.0, 0.0], [64543.6, 0.004], [64656.5, 0.128], [64667.3, 0.422], [64670.7, 0.01], [64671.6, 0.248], [64672.5, 0.003], [64672.7, 0.092], [64673.3, 0.318], [64675.3, 0.494], [64676.6, 0.001], [64676.9, 0.001]], "asks": [[64681.3, 0.017], [64685.1, 0.036], [64685.5, 0.003], [64685.7, 0.041], [64686.0, 0.047], [64686.7, 0.365], [64688.9, 0.103], [64690.3, 0.784], [64700.7, 0.002], [64702.3, 0.584], [64718.3, 0.624], [64721.6, 1.619], [64734.1, 0.017], [64734.8, 0.039], [64735.1, 0.068], [64738.6, 0.001], [64884.8, 5.423], [64911.0, 0.2], [64931.7, 0.004], [65325.8, 0.811]]}
{"kind": "depth", "E": 1787095170213, "U": 11316361153380, "u": 11316361159728, "recv_ms": 1787095170283, "bids": [[1000.0, 35.76], [14278.9, 0.42], [14378.9, 3.598], [14478.9, 0.182], [58211.0, 0.01], [61444.9, 0.0], [63678.9, 1.153], [63761.7, 9.586], [64032.1, 4.668], [64355.5, 3.416], [64632.3, 0.076], [64633.0, 0.003], [64655.4, 0.001], [64660.6, 0.027], [64667.3, 0.422], [64669.4, 0.003], [64670.7, 0.01], [64675.4, 0.088], [64678.9, 7.623]], "asks": [[64679.0, 11.169], [64681.3, 0.027], [64681.6, 0.014], [64682.1, 0.003], [64682.2, 0.019], [64683.1, 0.24], [64685.5, 0.116], [64685.6, 0.317], [64686.7, 0.365], [64689.5, 0.004], [64690.3, 0.515], [64690.9, 0.175], [64694.4, 0.673], [64694.6, 0.216], [64699.1, 0.156], [64699.7, 0.0], [64700.0, 3.32], [64700.3, 0.052], [64704.0, 0.012], [64721.0, 0.235], [64721.7, 0.028], [64734.8, 0.001], [64735.1, 0.026], [64735.9, 0.064], [64736.7, 1.272], [64738.6, 0.01], [65002.4, 3.538], [65325.8, 0.811], [65679.0, 0.322]]}
{"kind": "depth", "E": 1787095170315, "U": 11316361159816, "u": 11316361164722, "recv_ms": 1787095170384, "bids": [[14278.9, 0.644], [14378.9, 3.5], [14478.9, 0.056], [51743.0, 0.0], [58211.0, 0.01], [61445.0, 0.049], [61445.1, 0.012], [62082.5, 0.009], [62091.7, 0.689], [63902.7, 4.688], [64032.1, 4.668], [64355.5, 3.416], [64537.5, 1.295], [64614.2, 6.698], [64617.5, 0.088], [64624.5, 0.032], [64655.3, 2.391], [64675.3, 0.494], [64676.6, 0.001], [64678.9, 7.612]], "asks": [[64679.0, 11.176], [64694.6, 0.202], [64699.0, 0.101], [64707.2, 3.143], [64707.5, 0.076], [64720.9, 0.081], [64721.8, 0.172], [64724.4, 0.399], [64728.3, 0.129], [64738.6, 0.001], [64794.3, 0.069], [64799.3, 0.095], [64817.7, 1.23], [65325.8, 0.811], [65604.8, 3.235], [71146.9, 0.0]]}
{"kind": "depth", "E": 1787095170417, "U": 11316361164875, "u": 11316361168446, "recv_ms": 1787095170487, "bids": [[14278.9, 0.938], [14378.9, 3.262], [14478.9, 0.0], [58211.0, 0.01], [61436.4, 0.0], [61444.9, 0.0], [62091.7, 0.692], [63385.4, 0.963], [63678.9, 1.173], [63729.3, 5.108], [64032.1, 4.668], [64161.5, 4.194], [64355.5, 3.415], [64520.4, 0.0], [64520.5, 7.242], [64537.4, 0.093], [64537.5, 5.199], [64568.9, 0.003], [64672.5, 0.011], [64678.9, 7.614]], "asks": [[64679.0, 11.276], [64679.3, 0.087], [64690.9, 0.183], [64721.8, 0.018], [64724.3, 0.004], [64734.1, 0.049], [64734.8, 0.039], [64735.1, 0.068], [64756.7, 0.046], [64819.0, 5.4], [64836.0, 10.438], [64874.8, 5.306], [65325.8, 0.811], [65487.5, 3.521], [65679.0, 0.342]]}
{"kind": "depth", "E": 1787095170519, "U": 11316361168477, "u": 11316361172398, "recv_ms": 1787095170589, "bids": [[1000.0, 35.76], [14278.9, 1.302], [14378.9, 2.898], [58211.0, 0.01], [61444.9, 0.0], [62091.7, 0.689], [64032.1, 4.668], [64161.5, 4.19], [64609.0, 0.0], [64624.5, 0.004], [64658.1, 1.847], [64665.5, 0.62], [64672.9, 0.085], [64675.3, 0.073], [64676.4, 0.0], [64676.6, 0.001], [64678.9, 7.615]], "asks": [[64679.0, 11.22], [64683.4, 0.289], [64684.8, 0.027], [64685.3, 0.155], [64686.5, 0.009], [64686.6, 0.741], [64687.6, 2.324], [64687.9, 0.65], [64688.9, 0.095], [64690.3, 0.438], [64690.9, 0.159], [64691.0, 0.053], [64695.3, 0.618], [64721.6, 1.619], [64739.3, 51.889], [64741.5, 0.0], [65002.4, 3.539], [65325.8, 0.811], [65607.0, 18.952], [65616.8, 7.417]]}
{"kind": "depth", "E": 1787095170621, "U": 11316361172455, "u": 11316361177082, "recv_ms": 1787095170691, "bids": [[14278.9, 1.652], [14378.9, 2.548], [58211.0, 0.01], [61444.9, 0.0], [62091.7, 0.692], [63385.4, 0.96], [63678.9, 1.153], [63741.1, 6.987], [64032.1, 4.668], [64355.5, 3.425], [64522.1, 0.173], [64646.3, 0.23], [64647.4, 4.108], [64655.4, 0.001], [64660.6, 0.027], [64665.2, 0.179], [64666.4, 0.015], [64667.3, 0.422], [64667.4, 0.009], [64667.7, 0.478], [64668.3, 0.001], [64669.4, 0.003], [64670.8, 0.019], [64671.6, 0.248], [64672.2, 0.088], [64672.4, 0.549], [64672.6, 0.468], [64674.7, 0.313], [64675.1, 0.009], [64675.2, 2.1], [64675.3, 0.494], [64675.4, 0.004], [64676.0, 0.002], [64678.9, 7.615]], "asks": [[64679.3, 0.235], [64679.4, 0.31], [64680.3, 0.002], [64683.1, 0.24], [64683.4, 0.121], [64683.9, 0.075], [64685.3, 0.042], [64685.5, 0.003], [64686.5, 0.164], [64686.7, 0.21], [64690.3, 0.515], [64690.9, 0.004], [64691.0, 0.208], [64694.4, 0.673], [64698.8, 0.163], [64699.1, 0.001], [64700.4, 0.389], [64701.1, 0.791], [64701.4, 3.747], [64710.0, 3.115], [64710.4, 10.009], [64721.6, 1.619], [64721.8, 0.172], [64739.3, 0.023], [64741.5, 51.866], [64748.1, 2.251], [64771.2, 0.449], [65325.8, 0.811], [65455.1, 10.528], [65597.4, 0.454], [65679.0, 0.322], [66286.0, 1.484]]}
{"kind": "depth", "E": 1787095170723, "U": 11316361177130, "u": 11316361182735, "recv_ms": 1787095170793, "bids": [[14278.9, 2.016], [14378.9, 2.184], [58211.0, 0.01], [61444.9, 0.0], [63708.7, 3.483], [64032.1, 4.668], [64506.5, 0.039], [64506.6, 0.03], [64650.3, 0.062], [64652.8, 0.035], [64655.4, 0.001], [64660.3, 0.158], [64660.6, 0.027], [64661.1, 0.033], [64661.9, 0.003], [64662.9, 0.562], [64663.8, 0.155], [64664.6, 0.145], [64666.9, 0.713], [64667.3, 0.422], [64667.7, 0.019], [64669.4, 0.003], [64670.3, 1.0], [64670.7, 0.002], [64670.8, 0.019], [64671.6, 0.248], [64672.5, 0.552], [64672.7, 0.092], [64673.5, 0.006], [64674.4, 0.003], [64674.8, 0.001], [64675.2, 1.559], [64675.3, 0.073], [64675.4, 0.088], [64676.5, 0.002], [64676.9, 0.0], [64678.5, 0.021], [64678.9, 7.995]], "asks": [[64683.0, 0.094], [64683.1, 0.157], [64683.9, 0.075], [64684.8, 0.195], [64686.5, 0.164], [64687.1, 0.59], [64687.9, 0.032], [64690.3, 0.784], [64691.0, 0.208], [64694.4, 0.673], [64695.3, 0.0], [64698.8, 0.163], [64700.1, 0.937], [64701.1, 0.332], [64703.9, 0.118], [64704.0, 0.568], [64705.8, 0.014], [64706.6, 0.106], [64706.7, 0.003], [64707.6, 0.096], [64739.3, 51.889], [64741.5, 0.0], [64753.4, 0.0], [65325.8, 0.811], [65572.4, 18.122], [65597.4, 0.681], [66296.0, 1.582], [71146.9, 0.002]]}
{"kind": "depth", "E": 1787095170825, "U": 11316361182768, "u": 11316361186865, "recv_ms": 1787095170894, "bids": [[1000.0, 35.76], [14278.9, 2.366], [14378.9, 1.834], [58211.0, 0.01], [62091.7, 0.689], [63385.4, 0.963], [63678.9, 1.173], [64032.1, 4.668], [64614.2, 6.697], [64655.4, 0.001], [64660.6, 0.027], [64662.5, 0.006], [64666.9, 0.254], [64667.3, 0.422], [64667.9, 0.687], [64669.4, 0.003], [64670.7, 0.01], [64672.5, 0.011], [64675.3, 0.614], [64675.4, 0.088], [64675.8, 0.084]], "asks": [[64683.1, 0.157], [64686.5, 0.164], [64691.0, 0.208], [64694.4, 0.673], [64695.0, 0.026], [64698.8, 0.163], [64743.7, 0.008], [65325.8, 0.813], [65679.0, 0.342], [71146.9, 0.0]]}
{"kind": "depth", "E": 1787095170927, "U": 11316361186929, "u": 11316361191797, "recv_ms": 1787095170996, "bids": [[14278.9, 2.73], [14378.9, 1.47], [58211.0, 0.01], [62091.7, 0.692], [64032.1, 4.668], [64338.1, 0.0], [64338.2, 0.492], [64355.5, 3.425], [64536.1, 0.028], [64575.2, 0.003], [64675.4, 0.509]], "asks": [[64874.8, 5.376], [64884.8, 2.37], [65325.8, 0.811], [65607.0, 17.886]]}
{"kind": "depth", "E": 1787095171029, "U": 11316361191916, "u": 11316361196370, "recv_ms": 1787095171098, "bids": [[1000.0, 35.91], [14278.9, 3.08], [14378.9, 1.12], [51743.1, 0.0], [58211.0, 0.01], [61444.9, 0.001], [62091.7, 0.689], [63678.9, 1.153], [63893.2, 27.954], [64032.1, 4.668], [64660.3, 0.118], [64669.4, 0.043], [64673.0, 0.001], [64673.3, 0.086], [64673.7, 0.318], [64675.4, 0.509], [64676.5, 0.002], [64678.9, 7.966]], "asks": [[64679.0, 11.221], [64681.3, 0.027], [64682.2, 0.019], [64690.3, 0.784], [64702.9, 0.618], [64706.2, 0.061], [64924.1, 0.0], [64963.3, 0.001], [65325.8, 0.811], [65487.5, 3.779], [65679.0, 0.322], [66971.7, 0.0]]}
{"kind": "depth", "E": 1787095171131, "U": 11316361196400, "u": 11316361200880, "recv_ms": 1787095171202, "bids": [[1000.0, 35.76], [14278.9, 3.444], [14378.9, 0.756], [58211.0, 0.01], [61444.9, 0.0], [64032.1, 4.668], [64623.6, 0.53], [64641.6, 2.058], [64667.2, 1.406], [64671.9, 0.006], [64675.4, 0.509], [64678.9, 7.967]], "asks": [[64684.8, 0.195], [64687.1, 0.513], [64687.9, 0.033], [64690.3, 0.515], [64854.4, 0.289], [64856.0, 0.114], [64867.9, 3.253], [64869.3, 17.79], [65325.8, 0.811], [65559.9, 2.434], [65584.6, 9.744], [65616.8, 8.482]]}
{"kind": "depth", "E": 1787095171233, "U": 11316361201015, "u": 11316361205891, "recv_ms": 1787095171303, "bids": [[14178.9, 0.042], [14278.9, 3.724], [14378.9, 0.434], [51743.0, 0.0], [58211.0, 0.01], [62091.7, 0.692], [63678.9, 1.173], [63760.6, 0.001], [64032.1, 4.668], [64355.5, 3.426], [64520.5, 0.0], [64537.5, 0.001], [64623.6, 0.526], [64634.9, 0.068], [64665.5, 0.002], [64667.7, 0.059], [64669.4, 0.003], [64671.9, 0.003], [64674.2, 0.008], [64674.3, 0.001], [64675.4, 0.088], [64675.8, 0.0], [64676.5, 0.002], [64677.1, 0.002], [64678.9, 7.208]], "asks": [[64681.0, 0.012], [64681.3, 0.017], [64682.2, 0.009], [64684.8, 0.027], [64690.3, 0.784], [64694.2, 0.044], [64702.4, 1.428], [64756.7, 0.049], [64819.0, 0.0], [64836.0, 0.027], [64850.0, 27.051], [65002.4, 3.538], [65186.7, 2.018], [65325.8, 0.811], [65458.2, 2.589], [65679.0, 0.342], [66071.5, 0.001], [66975.8, 0.152]]}
{"kind": "depth", "E": 1787095171335, "U": 11316361205929, "u": 11316361210710, "recv_ms": 1787095171406, "bids": [[1000.0, 35.76], [14178.9, 0.224], [14278.9, 3.71], [14378.9, 0.266], [58211.0, 0.01], [61444.9, 0.0], [62091.7, 0.689], [62997.2, 0.001], [63736.0, 13.956], [63902.8, 22.238], [64032.1, 4.668], [64520.6, 5.547], [64537.5, 4.278], [64537.6, 1.161], [64578.4, 3.033], [64624.5, 0.018], [64634.9, 0.064], [64637.5, 0.915], [64642.4, 0.052], [64646.0, 0.862], [64655.4, 0.001], [64658.1, 1.229], [64660.6, 0.027], [64667.3, 0.422], [64669.4, 0.003], [64670.7, 0.01], [64674.3, 0.004], [64674.7, 0.31], [64675.3, 0.614], [64675.4, 0.088]], "asks": [[64683.1, 0.157], [64683.9, 0.243], [64684.8, 0.195], [64685.3, 0.267], [64686.5, 0.164], [64691.0, 0.208], [64694.4, 0.673], [64698.4, 0.991], [64698.8, 0.163], [64739.2, 9.266], [64817.7, 1.23], [64819.0, 5.4], [64835.9, 2.392], [64836.0, 10.438], [64874.8, 5.005], [65325.8, 0.811], [65487.5, 4.007], [67912.9, 0.005]]}
{"kind": "depth", "E": 1787095171437, "U": 11316361210862, "u": 11316361216670, "recv_ms": 1787095171513, "bids": [[1000.0, 35.76], [14178.9, 0.462], [14278.9, 3.584], [14378.9, 0.154], [51743.0, 0.0], [58211.0, 0.008], [61444.9, 0.0], [61445.1, 0.01], [62082.5, 0.008], [62091.7, 0.692], [63678.9, 1.153], [63870.5, 3.033], [64032.1, 4.668], [64537.5, 4.912], [64641.0, 3.293], [64641.3, 0.006], [64641.8, 0.154], [64667.4, 0.468], [64667.9, 0.228], [64672.7, 0.092], [64675.4, 0.088]], "asks": [[64679.0, 11.22], [64681.3, 0.027], [64682.2, 0.019], [64683.4, 0.289], [64683.9, 0.075], [64684.8, 0.252], [64685.2, 0.12], [64685.3, 0.492], [64690.3, 0.515], [64695.2, 0.101], [64819.0, 5.4], [64874.8, 6.469], [65002.4, 3.537], [65325.8, 0.811], [65584.5, 13.677], [65649.2, 3.758], [65679.0, 0.322]]}
{"kind": "depth", "E": 1787095171539, "U": 11316361216686, "u": 11316361221902, "recv_ms": 1787095171608, "bids": [[14178.9, 0.7], [14278.9, 3.472], [14378.9, 0.028], [58211.0, 0.01], [61444.9, 0.0], [62091.7, 0.689], [62997.2, 0.0], [63731.5, 21.718], [64032.1, 4.668], [64355.5, 3.427], [64624.5, 0.004], [64657.8, 2.939], [64665.2, 0.797], [64672.7, 0.092], [64675.3, 0.614], [64675.4, 0.088], [64676.5, 0.002]], "asks": [[64679.0, 11.24], [64682.9, 0.135], [64683.0, 0.011], [64683.4, 0.121], [64685.2, 0.007], [64685.3, 0.042], [64687.6, 2.942], [64690.3, 0.553], [64695.0, 0.644], [64695.2, 0.132], [64706.6, 4.106], [64720.4, 3.278], [64721.8, 0.018], [64736.0, 0.001], [64739.3, 0.023], [64748.1, 54.03], [65196.4, 3.06], [65325.8, 0.811], [65766.9, 2.579], [65972.5, 0.006]]}
{"kind": "depth", "E": 1787095171641, "U": 11316361222031, "u": 11316361226916, "recv_ms": 1787095171717, "bids": [[1000.0, 35.76], [14178.9, 1.022], [14278.9, 3.178], [14378.9, 0.0], [58211.0, 0.01], [63678.9, 1.173], [63714.8, 0.0], [63731.5, 20.621], [63899.6, 1.877], [64032.1, 4.668], [64481.6, 4.577], [64481.8, 12.652], [64520.6, 6.491], [64537.5, 0.001], [64537.6, 4.603], [64568.9, 0.003], [64650.3, 8.062], [64653.6, 0.003], [64655.4, 0.001], [64660.6, 0.027], [64667.3, 0.422], [64669.4, 0.003], [64670.7, 0.01], [64672.7, 0.542], [64675.0, 2.849], [64675.3, 0.073], [64675.4, 0.509], [64675.9, 0.091], [64678.9, 7.209]], "asks": [[64679.0, 11.2], [64683.1, 0.157], [64683.4, 0.289], [64685.3, 0.267], [64686.5, 0.164], [64690.3, 0.515], [64691.0, 0.208], [64694.2, 0.004], [64694.4, 0.673], [64697.2, 0.042], [64698.8, 0.163], [64707.2, 1.581], [64710.4, 0.009], [64721.2, 0.157], [64724.3, 0.004], [64738.6, 0.019], [64739.2, 1.748], [64739.3, 51.802], [64741.5, 0.0], [64748.1, 2.251], [64756.7, 0.046], [64795.6, 0.105], [64817.7, 0.003], [64819.0, 5.4], [64835.9, 0.0], [64836.0, 10.438], [64874.8, 11.717], [65325.8, 0.811], [65402.1, 2.257], [65679.0, 0.342]]}
{"kind": "depth", "E": 1787095171743, "U": 11316361227111, "u": 11316361232116, "recv_ms": 1787095171812, "bids": [[1000.0, 35.76], [14178.9, 1.386], [14278.9, 2.814], [58211.0, 0.01], [61444.9, 0.0], [62091.7, 0.692], [64032.1, 4.668], [64051.5, 0.682], [64520.6, 7.059], [64641.7, 0.287], [64641.8, 0.0], [64672.5, 0.461], [64672.7, 0.542], [64675.3, 0.432], [64675.4, 0.15], [64677.2, 0.156], [64678.5, 0.02], [64678.6, 0.471]], "asks": [[64683.4, 0.289], [64685.3, 0.267], [64690.3, 0.553], [64874.8, 6.257], [65325.8, 0.811], [65772.1, 0.611]]}
{"kind": "depth", "E": 1787095171845, "U": 11316361232267, "u": 11316361236704, "recv_ms": 1787095171915, "bids": [[14178.9, 1.736], [14278.9, 2.464], [51743.0, 0.0], [58211.0, 0.01], [61444.9, 0.0], [62091.7, 0.689], [63268.5, 0.676], [63678.9, 1.153], [63708.7, 3.796], [63741.1, 9.181], [63909.2, 7.506], [64032.1, 4.668], [64087.6, 0.001], [64355.5, 3.427], [64537.6, 0.005], [64571.2, 3.927], [64574.9, 2.32], [64657.8, 2.321], [64662.5, 0.006], [64665.2, 0.179], [64672.5, 0.461], [64672.7, 0.542], [64675.3, 0.432], [64675.4, 0.088], [64675.5, 0.064], [64676.5, 0.002], [64678.9, 6.903]], "asks": [[64681.3, 0.027], [64683.4, 0.289], [64685.3, 0.267], [64687.1, 0.59], [64687.6, 2.324], [64687.9, 0.032], [64690.3, 0.784], [64695.0, 0.026], [64785.0, 1.689], [64788.8, 7.157], [64819.0, 0.0], [65325.8, 0.811], [65679.0, 0.322]]}
{"kind": "depth", "E": 1787095172049, "U": 11316361240757, "u": 11316361249666, "recv_ms": 1787095172117, "bids": [[1000.0, 35.76], [14178.9, 2.45], [14278.9, 1.75], [51743.1, 0.0], [58211.0, 0.01], [61444.9, 0.0], [61445.0, 0.047], [61445.1, 0.012], [63678.9, 1.173], [64032.1, 4.668], [64481.8, 12.618], [64520.6, 7.059], [64537.6, 4.934], [64643.3, 0.005], [64667.3, 0.427], [64672.5, 0.011], [64672.7, 0.092], [64675.3, 0.011], [64676.5, 0.002], [64678.9, 6.903]], "asks": [[64683.4, 0.121], [64685.3, 0.042], [64690.3, 0.553], [64695.2, 0.129], [64756.7, 0.049], [64819.0, 5.4], [64836.0, 10.438], [64874.8, 6.257], [65325.8, 0.811], [65443.1, 20.381], [65488.0, 14.291], [65679.0, 0.342], [65900.0, 13.877], [65972.5, 0.006]]}
{"kind": "depth", "E": 1787095172151, "U": 11316361249888, "u": 11316361255508, "recv_ms": 1787095172220, "bids": [[14178.9, 2.814], [14278.9, 1.386], [51743.0, 0.0], [58211.0, 0.01], [61444.9, 0.0], [62091.7, 0.689], [63561.4, 3.593], [63935.1, 1.405], [64032.1, 4.67], [64096.6, 2.184], [64355.5, 3.417], [64656.5, 0.126], [64667.3, 0.422], [64672.5, 0.011], [64672.7, 0.092], [64675.3, 0.011], [64677.6, 0.042], [64677.8, 0.003], [64678.2, 0.0], [64678.9, 6.931]], "asks": [[64683.4, 0.121], [64684.7, 0.001], [64685.3, 0.042], [64687.1, 0.513], [64687.3, 0.411], [64690.3, 0.784], [65325.8, 0.811], [67912.9, 0.01]]}
{"kind": "depth", "E": 1787095172355, "U": 11316361260144, "u": 11316361264883, "recv_ms": 1787095172425, "bids": [[1000.0, 35.76], [14178.9, 3.528], [14278.9, 0.672], [51743.0, 0.0], [58211.0, 0.01], [61444.9, 0.001], [61445.1, 0.01], [62091.7, 0.689], [63566.4, 0.628], [63678.9, 1.153], [64032.1, 4.668], [64151.8, 1.879], [64345.9, 1.086], [64536.6, 0.464], [64634.9, 0.068], [64642.4, 0.048], [64645.2, 0.12], [64652.7, 2.745], [64655.4, 0.156], [64657.5, 0.002], [64658.4, 0.001], [64660.6, 0.182], [64665.0, 0.174], [64667.3, 0.577], [64669.4, 0.158], [64670.7, 0.165], [64671.6, 0.248], [64672.5, 0.011], [64672.7, 0.317], [64674.5, 0.0], [64674.6, 0.011], [64674.8, 0.0], [64675.0, 2.765], [64675.3, 0.166], [64675.4, 0.004], [64675.5, 0.064], [64675.9, 0.007], [64676.3, 0.003], [64678.9, 6.547]], "asks": [[64679.0, 11.207], [64680.3, 0.312], [64681.3, 0.017], [64682.2, 0.009], [64683.1, 0.002], [64683.4, 0.289], [64684.7, 0.226], [64684.8, 0.365], [64685.3, 0.492], [64686.5, 0.009], [64687.1, 0.59], [64690.3, 0.803], [64691.0, 0.053], [64694.4, 0.363], [64698.8, 0.008], [64701.0, 0.431], [64721.2, 0.157], [64739.2, 9.253], [64771.2, 0.372], [64795.6, 0.005], [64817.7, 1.23], [64835.9, 2.392], [65002.4, 3.538], [65325.8, 0.811], [65455.1, 11.29], [65679.0, 0.322], [65704.0, 1.49]]}
{"kind": "depth", "E": 1787095172457, "U": 11316361264927, "u": 11316361270352, "recv_ms": 1787095172527, "bids": [[14178.9, 3.752], [14278.9, 0.378], [14578.9, 0.07], [58211.0, 0.01], [61444.9, 0.0], [62091.7, 0.692], [63057.0, 1.113], [64032.1, 4.668], [64355.5, 3.416], [64616.8, 0.0], [64616.9, 1.971], [64625.2, 0.002], [64625.3, 1.972], [64633.5, 0.096], [64633.7, 0.179], [64634.9, 0.064], [64642.4, 0.052], [64655.4, 0.001], [64660.6, 0.027], [64666.5, 0.011], [64666.9, 0.247], [64667.3, 0.422], [64669.4, 0.003], [64670.5, 0.154], [64670.7, 0.01], [64671.6, 0.094], [64671.7, 0.094], [64671.8, 0.086], [64672.5, 0.003], [64672.7, 0.007], [64672.8, 0.0], [64673.9, 0.012], [64674.3, 0.001], [64674.4, 0.087], [64674.6, 0.01], [64675.0, 2.224], [64675.1, 0.55], [64675.3, 0.011], [64678.9, 6.548]], "asks": [[64679.8, 0.009], [64680.8, 0.001], [64682.2, 0.177], [64682.3, 0.615], [64682.9, 0.052], [64683.1, 0.157], [64683.4, 0.121], [64683.9, 0.075], [64684.7, 0.001], [64684.8, 0.252], [64685.1, 0.261], [64685.2, 0.007], [64685.3, 0.267], [64685.4, 0.476], [64685.5, 0.08], [64686.5, 0.164], [64687.1, 0.866], [64691.0, 0.208], [64694.4, 0.673], [64697.1, 0.105], [64698.8, 0.163], [64700.6, 0.005], [64700.7, 1.626], [64709.0, 0.011], [64709.1, 1.983], [64717.4, 0.184], [64717.5, 2.012], [64721.1, 0.521], [64721.2, 0.003], [64721.3, 0.603], [64771.2, 0.288], [64793.8, 0.255], [65325.8, 0.811], [65584.5, 15.961]]}
{"kind": "depth", "E": 1787095172559, "U": 11316361270392, "u": 11316361277601, "recv_ms": 1787095172629, "bids": [[1000.0, 35.76], [14178.9, 3.682], [14278.9, 0.238], [14578.9, 0.28], [58211.0, 0.01], [61444.9, 0.001], [63678.9, 1.173], [64032.1, 4.668], [64161.5, 4.812], [64355.5, 3.803], [64624.5, 0.018], [64641.6, 2.676], [64642.6, 0.028], [64642.9, 4.673], [64649.0, 0.326], [64650.3, 0.062], [64652.7, 0.0], [64655.4, 0.311], [64656.8, 0.019], [64660.0, 0.528], [64660.3, 0.002], [64660.5, 1.663], [64660.6, 0.182], [64661.3, 1.547], [64664.5, 0.098], [64665.2, 0.172], [64666.7, 0.507], [64667.3, 0.732], [64667.4, 0.009], [64669.4, 0.166], [64670.4, 1.367], [64670.7, 0.396], [64671.1, 0.086], [64671.4, 0.01], [64671.5, 1.748], [64672.2, 0.089], [64672.5, 0.544], [64672.7, 1.561], [64673.2, 0.235], [64673.3, 0.002], [64673.5, 0.005], [64673.6, 0.222], [64673.7, 0.002], [64673.9, 0.008], [64674.0, 0.003], [64674.4, 0.003], [64674.6, 0.01], [64674.7, 0.0], [64674.8, 0.0], [64675.0, 0.987], [64675.1, 0.001], [64675.2, 0.013], [64675.3, 0.159], [64675.4, 0.004], [64675.5, 0.064], [64675.6, 0.013], [64676.3, 0.003], [64677.2, 0.155], [64678.9, 4.084]], "asks": [[64679.0, 11.843], [64681.3, 0.017], [64682.1, 0.003], [64682.2, 0.092], [64682.3, 0.532], [64682.4, 0.087], [64683.1, 0.002], [64683.3, 0.085], [64683.4, 0.121], [64683.6, 0.57], [64683.7, 0.153], [64684.7, 0.114], [64684.8, 0.027], [64685.1, 0.036], [64685.3, 0.042], [64685.5, 0.433], [64686.5, 0.009], [64686.6, 1.05], [64687.3, 0.41], [64687.8, 0.098], [64689.7, 0.082], [64691.0, 0.671], [64691.1, 2.32], [64691.6, 0.0], [64694.4, 0.363], [64696.3, 0.31], [64698.8, 0.008], [64698.9, 2.826], [64699.9, 10.42], [64700.1, 0.478], [64702.8, 0.257], [64703.0, 1.298], [64703.9, 0.003], [64704.0, 0.012], [64704.7, 0.01], [64705.8, 0.007], [64706.3, 0.004], [64706.6, 0.108], [64733.4, 0.0], [64738.6, 0.001], [64771.2, 0.019], [64793.8, 0.082], [64819.0, 3.921], [64836.0, 7.657], [64874.8, 1.675], [65002.4, 3.539], [65325.8, 0.811], [65455.1, 12.815], [65679.0, 0.342]]}
{"kind": "depth", "E": 1787095172661, "U": 11316361277678, "u": 11316361285529, "recv_ms": 1787095172731, "bids": [[1000.0, 35.76], [14178.9, 3.542], [14278.9, 0.126], [14578.9, 0.532], [58211.0, 0.01], [61444.9, 0.0], [62091.7, 0.689], [63385.4, 0.957], [63719.4, 1.88], [64032.1, 4.668], [64200.0, 28.98], [64624.5, 0.004], [64642.6, 0.014], [64642.9, 2.673], [64647.0, 8.001], [64655.4, 0.156], [64660.6, 0.027], [64666.0, 0.793], [64666.5, 0.004], [64667.3, 0.577], [64669.3, 2.84], [64669.4, 0.003], [64670.4, 1.291], [64670.5, 1.154], [64670.7, 0.241], [64671.6, 0.001], [64672.5, 0.003], [64672.6, 0.468], [64672.7, 0.007], [64672.8, 0.0], [64672.9, 0.085], [64673.3, 0.002], [64673.5, 0.089], [64673.7, 0.002], [64673.9, 0.092], [64674.4, 0.087], [64674.9, 2.634], [64675.1, 0.558], [64675.2, 1.559], [64675.3, 0.004], [64675.6, 0.005], [64678.6, 0.518], [64678.9, 5.1]], "asks": [[64679.0, 11.207], [64681.3, 0.017], [64681.9, 0.085], [64682.1, 0.003], [64682.2, 0.009], [64682.4, 0.085], [64683.1, 0.157], [64683.3, 0.087], [64683.4, 0.289], [64684.7, 0.001], [64684.8, 0.027], [64685.3, 0.267], [64685.4, 0.701], [64686.5, 0.164], [64690.0, 0.972], [64690.9, 0.159], [64692.0, 3.307], [64694.4, 0.518], [64697.7, 0.196], [64698.8, 0.163], [64698.9, 2.367], [64699.4, 1.163], [64703.0, 0.742], [64703.4, 2.882], [64819.0, 5.4], [64836.0, 10.438], [64874.8, 7.556], [65325.8, 0.813], [65488.0, 13.535], [65607.0, 16.82], [65713.9, 3.193], [65972.5, 0.009], [71146.9, 0.0]]}
{"kind": "depth", "E": 1787095172763, "U": 11316361285550, "u": 11316361291073, "recv_ms": 1787095172833, "bids": [[14178.9, 3.444], [14278.9, 0.0], [14578.9, 0.756], [58211.0, 0.01], [61445.1, 0.008], [62091.7, 0.692], [63385.4, 0.96], [63678.9, 1.153], [63870.5, 2.503], [64032.1, 4.668], [64355.5, 3.813], [64635.7, 0.101], [64660.0, 0.412], [64660.7, 0.438], [64667.5, 0.344], [64668.0, 1.027], [64672.5, 0.453], [64672.7, 0.55], [64673.2, 0.232], [64673.3, 0.115], [64673.6, 0.225], [64675.2, 1.672], [64675.3, 0.538]], "asks": [[64683.4, 0.121], [64683.9, 0.152], [64684.8, 0.669], [64684.9, 1.402], [64685.3, 0.042], [64685.4, 0.476], [64685.5, 0.452], [64686.6, 0.416], [64686.7, 0.202], [64687.1, 0.962], [64702.8, 0.141], [64702.9, 0.927], [64703.4, 2.997], [64704.3, 1.135], [64721.3, 0.449], [64721.4, 2.507], [64771.2, 0.0], [65325.8, 0.811], [65616.8, 9.548], [65679.0, 0.322]]}
{"kind": "depth", "E": 1787095172865, "U": 11316361291202, "u": 11316361297270, "recv_ms": 1787095172935, "bids": [[1000.0, 35.76], [14178.9, 3.094], [14578.9, 1.106], [58211.0, 0.01], [62091.7, 0.689], [63268.8, 0.011], [63270.5, 0.004], [64032.1, 4.668], [64055.7, 1.837], [64309.4, 0.016], [64309.5, 1.803], [64360.4, 0.096], [64406.0, 1.03], [64406.2, 1.102], [64476.9, 0.0], [64479.1, 0.365], [64662.5, 0.006], [64672.1, 0.03], [64672.5, 0.003], [64672.7, 0.325], [64673.3, 0.002], [64674.9, 2.324], [64675.2, 1.559], [64675.3, 0.004], [64676.3, 0.003]], "asks": [[64683.4, 0.121], [64683.9, 0.236], [64684.7, 0.001], [64684.8, 0.027], [64685.3, 0.042], [64685.4, 0.476], [64686.5, 0.813], [64686.6, 0.409], [64695.0, 0.026], [64699.4, 0.704], [64699.9, 10.879], [64703.4, 2.441], [64703.7, 0.652], [64713.1, 0.025], [64720.3, 0.004], [64721.3, 0.603], [64721.4, 2.353], [64873.9, 1.636], [64874.0, 0.0], [64944.9, 0.466], [64945.4, 0.008], [65040.9, 0.659], [65042.8, 0.467], [65325.8, 0.811], [65403.5, 0.0], [65438.9, 3.665], [65488.1, 0.763], [65547.0, 4.825], [65552.3, 5.827], [65565.1, 1.218], [66080.6, 1.301]]}
{"kind": "depth", "E": 1787095172967, "U": 11316361297449, "u": 11316361301850, "recv_ms": 1787095173037, "bids": [[1000.0, 35.76], [14178.9, 2.73], [14578.9, 1.47], [58211.0, 0.01], [61445.0, 0.049], [62091.7, 0.692], [63678.9, 1.173], [63728.1, 2.431], [63741.1, 9.338], [64032.1, 4.668], [64100.1, 4.342], [64300.1, 13.342], [64309.5, 0.939], [64487.1, 0.001], [64496.6, 0.463], [64568.9, 0.003], [64672.7, 0.1], [64672.8, 0.0], [64674.6, 0.32], [64675.3, 0.004]], "asks": [[64680.2, 0.085], [64681.3, 0.027], [64682.2, 0.019], [64683.4, 0.346], [64683.5, 0.542], [64683.8, 0.27], [64684.7, 0.102], [64684.8, 0.027], [64685.3, 0.042], [64686.5, 0.712], [64721.3, 0.449], [64721.4, 2.507], [64724.3, 0.004], [64756.7, 0.046], [65325.8, 0.811], [65466.7, 2.289], [65607.0, 15.754], [65679.0, 0.342]]}
{"kind": "depth", "E": 1787095173069, "U": 11316361301875, "u": 11316361309061, "recv_ms": 1787095173138, "bids": [[14178.9, 2.38], [14578.9, 1.82], [51743.1, 0.0], [58211.0, 0.01], [61444.9, 0.001], [63678.9, 1.153], [63760.5, 0.702], [63767.9, 0.002], [64032.1, 4.668], [64045.6, 0.0], [64064.5, 9.057], [64193.6, 0.002], [64355.5, 3.813], [64637.8, 0.025], [64641.6, 2.058], [64646.2, 0.107], [64667.3, 0.577], [64668.0, 1.143], [64675.3, 0.425], [64676.3, 0.003], [64678.9, 5.1]], "asks": [[64683.4, 0.289], [64683.5, 0.317], [64683.8, 0.157], [64684.7, 0.001], [64684.8, 0.14], [64685.3, 0.267], [64686.4, 0.279], [64701.1, 0.334], [64794.3, 0.0], [64874.8, 6.952], [65159.9, 0.445], [65309.7, 1.449], [65325.8, 0.811], [65679.0, 0.322], [65760.4, 2.428], [67912.9, 0.015]]}
{"kind": "depth", "E": 1787095173171, "U": 11316361309111, "u": 11316361314711, "recv_ms": 1787095173241, "bids": [[1000.0, 35.76], [14178.9, 2.016], [14578.9, 2.184], [51743.0, 0.0], [58211.0, 0.01], [61444.9, 0.0], [62091.7, 0.689], [63781.5, 0.0], [63870.4, 7.677], [64032.1, 4.668], [64311.0, 36.249], [64407.6, 29.593], [64409.1, 5.11], [64478.5, 23.565], [64479.1, 3.842], [64537.6, 0.005], [64611.6, 0.0], [64629.9, 0.08], [64642.4, 0.048], [64655.4, 0.001], [64667.3, 0.422], [64670.7, 0.086], [64678.9, 5.099]], "asks": [[64683.4, 0.289], [64685.3, 0.267], [64687.0, 0.166], [64698.4, 0.92], [64817.7, 0.003], [64819.0, 0.0], [64874.1, 23.657], [64944.9, 4.778], [64945.4, 29.591], [65040.9, 6.012], [65042.8, 36.898], [65325.8, 0.811], [65448.7, 4.587], [65552.2, 4.551], [65616.8, 10.614], [65671.7, 10.994]]}
{"kind": "depth", "E": 1787095173273, "U": 11316361314892, "u": 11316361320411, "recv_ms": 1787095173344, "bids": [[1000.0, 35.76], [14178.9, 1.666], [14578.9, 2.534], [58211.0, 0.01], [62091.7, 0.692], [63773.4, 13.028], [64032.1, 4.668], [64195.2, 46.358], [64355.5, 3.813], [64520.6, 6.958], [64537.6, 4.882], [64624.5, 0.018], [64637.8, 0.0], [64640.7, 0.005], [64646.2, 0.132], [64675.3, 0.425], [64676.3, 0.003]], "asks": [[64683.4, 0.121], [64684.8, 0.027], [64685.3, 0.042], [64692.2, 0.035], [64697.5, 0.172], [64721.4, 2.353], [64819.0, 2.939], [64835.9, 0.0], [64836.0, 5.753], [64874.8, 1.419], [65002.4, 3.538], [65159.9, 45.337], [65284.6, 4.484], [65325.8, 0.811], [65487.6, 0.829]]}
{"kind": "depth", "E": 1787095173477, "U": 11316361325867, "u": 11316361330433, "recv_ms": 1787095173547, "bids": [[1000.0, 35.76], [14178.9, 0.952], [14578.9, 3.248], [58211.0, 0.01], [63731.5, 19.524], [63771.2, 4.982], [63790.2, 4.226], [64032.1, 4.668], [64553.5, 11.267], [64559.0, 0.001], [64559.9, 6.238], [64575.6, 0.026], [64580.1, 5.634], [64587.2, 1.394], [64598.7, 3.608], [64612.5, 0.001], [64615.9, 1.96], [64623.6, 0.302], [64630.3, 0.243], [64672.7, 0.1], [64675.2, 1.559], [64675.3, 0.004]], "asks": [[64681.3, 0.017], [64682.2, 0.009], [64683.4, 0.289], [64685.3, 0.267], [64702.9, 1.159], [64705.1, 0.011], [64730.0, 0.892], [64734.1, 1.907], [64746.5, 0.071], [64746.6, 0.0], [64754.4, 3.741], [64756.3, 0.027], [64774.5, 7.2], [64779.0, 0.604], [64779.5, 0.022], [64795.0, 0.017], [64796.7, 0.926], [64802.5, 11.633], [65325.8, 0.811], [65375.1, 2.751], [65572.4, 15.837], [65778.5, 7.434]]}
{"kind": "depth", "E": 1787095173579, "U": 11316361330566, "u": 11316361335599, "recv_ms": 1787095173649, "bids": [[1000.0, 35.76], [14178.9, 0.588], [14578.9, 3.612], [51743.0, 0.004], [58211.0, 0.01], [62091.7, 0.692], [63277.3, 0.678], [63574.3, 6.623], [63678.9, 1.153], [64032.1, 4.668], [64355.5, 3.814], [64506.3, 0.135], [64506.5, 0.0], [64633.3, 0.008], [64640.7, 0.001], [64669.4, 0.003], [64670.4, 1.291], [64672.7, 0.1], [64675.2, 1.559], [64675.3, 0.004], [64676.3, 0.003]], "asks": [[64681.3, 0.027], [64682.2, 0.019], [64683.4, 0.289], [64685.3, 0.042], [64685.5, 0.433], [64722.0, 1.546], [64722.5, 0.396], [64723.5, 0.693], [64730.0, 0.97], [64745.9, 2.381], [64746.5, 0.032], [64752.4, 1.173], [64794.7, 0.066], [64819.0, 5.4], [64836.0, 10.438], [64874.8, 6.379], [65002.4, 3.537], [65293.5, 5.574], [65325.8, 0.811], [65679.0, 0.322]]}
{"kind": "depth", "E": 1787095173681, "U": 11316361335673, "u": 11316361341063, "recv_ms": 1787095173751, "bids": [[14178.9, 0.336], [14478.9, 0.098], [14578.9, 3.766], [51743.0, 0.0], [58211.0, 0.01], [61444.9, 0.0], [61445.1, 0.006], [62091.7, 0.689], [63579.4, 1.182], [63779.9, 7.729], [64032.1, 4.669], [64355.5, 3.815], [64607.5, 32.697], [64609.0, 0.009], [64611.8, 0.001], [64614.2, 2.181], [64616.5, 0.035], [64617.6, 2.729], [64620.3, 0.951], [64658.1, 1.847], [64665.5, 0.62], [64672.7, 0.1], [64675.3, 0.004], [64678.9, 5.099]], "asks": [[64683.4, 0.121], [64683.9, 0.075], [64685.3, 0.155], [64685.5, 0.164], [64687.1, 0.943], [64687.9, 0.65], [64689.7, 0.002], [64690.0, 0.072], [64691.0, 1.571], [64692.1, 0.095], [64693.6, 0.373], [64695.3, 0.618], [64704.3, 1.135], [64713.4, 0.158], [64736.0, 0.028], [64744.3, 3.021], [64745.9, 2.342], [64746.2, 0.001], [64746.6, 0.039], [65325.8, 0.811], [65384.0, 3.043], [65584.6, 9.288]]}
{"kind": "depth", "E": 1787095173783, "U": 11316361341178, "u": 11316361346485, "recv_ms": 1787095173852, "bids": [[1000.0, 35.76], [14178.9, 0.21], [14478.9, 0.336], [14578.9, 3.654], [58211.0, 0.01], [61444.9, 0.0], [62091.7, 0.692], [63678.9, 1.173], [63741.1, 10.435], [63870.4, 7.942], [64032.1, 4.669], [64537.6, 5.195], [64562.3, 2.319], [64562.4, 1.444], [64563.4, 3.943], [64574.8, 2.341], [64574.9, 0.001], [64575.7, 0.001], [64607.5, 0.0], [64607.7, 2.451], [64611.9, 32.79], [64633.3, 0.004], [64635.7, 0.201], [64640.7, 0.005], [64645.2, 0.078], [64654.3, 0.002], [64655.1, 1.002], [64662.9, 0.602], [64666.9, 0.247], [64667.7, 0.019], [64670.4, 1.291], [64671.4, 0.009], [64671.6, 0.017], [64671.7, 0.078], [64672.1, 0.031], [64672.3, 2.335], [64672.4, 0.549], [64672.7, 0.1], [64672.8, 0.0], [64672.9, 0.31], [64674.8, 0.0], [64675.1, 0.543], [64675.2, 1.566], [64675.3, 0.011], [64675.4, 0.088], [64676.3, 0.003], [64678.4, 0.023]], "asks": [[64679.0, 11.107], [64681.9, 0.002], [64682.7, 0.09], [64683.4, 0.121], [64683.5, 0.317], [64684.8, 0.14], [64685.5, 0.202], [64687.9, 0.032], [64692.1, 0.095], [64695.2, 0.109], [64707.9, 0.004], [64708.0, 1.265], [64708.1, 0.005], [64710.9, 0.007], [64711.0, 0.502], [64711.1, 3.261], [64711.8, 0.003], [64711.9, 0.043], [64712.0, 1.393], [64713.9, 0.0], [64714.0, 0.481], [64714.1, 0.029], [64720.4, 3.334], [64746.5, 0.071], [64746.6, 0.0], [64750.0, 2.994], [64750.1, 0.049], [64788.6, 2.534], [64788.8, 4.838], [64790.6, 0.102], [64814.2, 0.0], [64814.3, 3.866], [64819.0, 5.4], [64874.8, 6.423], [65325.8, 0.811], [65585.8, 3.348], [65679.0, 0.342]]}
{"kind": "depth", "E": 1787095173885, "U": 11316361346642, "u": 11316361351426, "recv_ms": 1787095173956, "bids": [[1000.0, 35.76], [14178.9, 0.098], [14478.9, 0.574], [14578.9, 3.528], [58211.0, 0.01], [62091.7, 0.689], [63731.5, 18.427], [63849.4, 0.0], [64355.5, 3.815], [64662.5, 0.006], [64671.6, 0.11], [64672.7, 0.457], [64672.9, 0.085], [64675.3, 0.432]], "asks": [[64682.2, 0.102], [64682.7, 0.007], [64683.5, 0.317], [64683.9, 0.152], [64684.6, 0.02], [64684.7, 0.001], [64684.8, 0.027], [64685.3, 0.042], [64685.4, 0.476], [64685.5, 0.452], [64686.4, 0.178], [64686.5, 0.813], [64695.0, 0.026], [64745.6, 2.878], [64746.5, 0.032], [65325.8, 0.811], [65438.9, 2.749], [65455.1, 14.341], [65591.0, 3.05], [65607.0, 14.688]]}
{"kind": "depth", "E": 1787095173987, "U": 11316361351628, "u": 11316361362303, "recv_ms": 1787095174074, "bids": [[14178.9, 0.0], [14478.9, 0.84], [14578.9, 3.36], [58211.0, 0.01], [63678.9, 1.153], [63838.1, 0.0], [64032.1, 4.669], [64047.6, 58.973], [64506.3, 0.096], [64506.4, 0.04], [64672.7, 0.457], [64675.3, 0.432], [64676.3, 0.003]], "asks": [[64683.4, 0.121], [64684.8, 0.252], [64685.3, 0.042], [64685.4, 0.476], [64686.4, 0.202], [64686.5, 0.789], [64745.6, 2.839], [64746.0, 0.053], [64874.8, 6.379], [65309.8, 60.571], [65313.8, 0.0], [65325.8, 0.811], [65584.5, 16.417], [65604.8, 2.169], [65679.0, 0.322]]}
{"kind": "depth", "E": 1787095174089, "U": 11316361362532, "u": 11316361370909, "recv_ms": 1787095174159, "bids": [[1000.0, 35.76], [14478.9, 1.204], [14578.9, 2.996], [51743.1, 0.0], [58211.0, 0.01], [61444.9, 0.0], [62091.7, 0.692], [63686.1, 0.009], [63686.3, 0.008], [63750.9, 2.811], [63753.1, 0.026], [64032.1, 4.671], [64554.9, 0.025], [64609.0, 0.0], [64636.8, 1.756], [64655.4, 0.001], [64656.2, 0.047], [64660.6, 0.027], [64667.3, 0.422], [64670.7, 0.002], [64672.7, 0.457], [64675.3, 0.011], [64678.9, 5.097]], "asks": [[64683.1, 0.157], [64683.3, 0.085], [64683.4, 0.121], [64683.6, 0.572], [64685.3, 0.042], [64686.4, 0.357], [64686.5, 0.634], [64688.9, 0.002], [64690.9, 0.159], [64694.4, 0.673], [64695.2, 0.129], [64697.7, 0.041], [64698.8, 0.163], [64703.4, 2.326], [64703.7, 0.767], [64704.7, 0.003], [64705.2, 0.038], [64721.1, 0.518], [64756.7, 0.049], [65325.8, 0.811], [65393.5, 1.528], [65448.7, 5.503], [65591.0, 3.963], [65604.7, 0.0], [65606.9, 0.0], [65616.8, 11.68], [65671.6, 0.009], [65671.7, 10.984]]}
{"kind": "depth", "E": 1787095174191, "U": 11316361370921, "u": 11316361377305, "recv_ms": 1787095174261, "bids": [[1000.0, 35.76], [14478.9, 1.554], [14578.9, 2.646], [58211.0, 0.01], [62091.7, 0.689], [63061.9, 2.852], [63385.4, 0.957], [63634.5, 5.153], [63678.9, 1.173], [63686.3, 0.026], [63741.1, 11.532], [63751.0, 0.724], [63753.1, 0.034], [63838.0, 0.375], [63965.2, 2.812], [64032.1, 4.669], [64355.5, 3.805], [64568.9, 0.0], [64633.6, 0.638], [64672.7, 0.007], [64675.2, 1.567], [64675.3, 0.011], [64676.3, 0.003], [64678.4, 0.024]], "asks": [[64683.4, 0.289], [64685.3, 0.267], [64688.9, 0.095], [64724.3, 0.001], [64756.7, 0.046], [64874.8, 6.24], [65325.8, 0.811], [65616.8, 12.746], [65679.0, 0.342]]}
{"kind": "depth", "E": 1787095174293, "U": 11316361377463, "u": 11316361383249, "recv_ms": 1787095174363, "bids": [[14478.9, 1.904], [14578.9, 2.296], [51743.0, 0.0], [58211.0, 0.01], [61445.0, 0.051], [62091.7, 0.692], [64032.1, 4.669], [64672.3, 2.333], [64672.7, 0.007], [64675.3, 0.011]], "asks": [[64683.4, 0.289], [64684.8, 0.027], [64685.3, 0.042], [64685.4, 0.701], [65325.8, 3.868], [65445.3, 17.473], [65604.8, 2.177], [65607.0, 14.696], [65671.7, 11.002]]}
{"kind": "depth", "E": 1787095174395, "U": 11316361383324, "u": 11316361390035, "recv_ms": 1787095174465, "bids": [[1000.0, 35.76], [14478.9, 2.268], [14578.9, 1.932], [51743.0, 0.0], [58211.0, 0.01], [61444.9, 0.0], [62091.7, 0.689], [63678.9, 1.153], [63965.2, 2.11], [64032.1, 4.669], [64313.0, 6.112], [64355.5, 3.804], [64506.3, 0.135], [64506.4, 0.001], [64520.6, 0.0], [64537.6, 0.005], [64649.3, 2.727], [64672.7, 0.007], [64675.3, 0.011], [64676.3, 0.003], [64678.9, 5.052]], "asks": [[64683.4, 0.289], [64685.4, 0.701], [64800.9, 9.089], [64817.7, 0.003], [64819.0, 0.0], [64836.0, 0.027], [64839.9, 1.514], [64873.9, 4.761], [65325.8, 3.868], [65438.9, 1.833], [65455.1, 15.561], [65458.2, 1.826], [65679.0, 0.322]]}
{"kind": "depth", "E": 1787095174497, "U": 11316361390230, "u": 11316361396083, "recv_ms": 1787095174568, "bids": [[1000.0, 35.76], [14478.9, 2.618], [14578.9, 1.582], [58211.0, 0.01], [61444.9, 0.0], [63644.0, 5.407], [63973.9, 1.481], [64032.1, 4.669], [64354.2, 0.069], [64355.0, 3.865], [64355.5, 3.804], [64520.7, 6.364], [64537.7, 4.875], [64607.5, 32.787], [64609.0, 0.018], [64611.9, 0.003], [64613.1, 0.025], [64613.4, 0.0], [64613.8, 0.002], [64614.1, 0.001], [64614.4, 0.973], [64627.1, 0.097], [64630.6, 0.008], [64631.0, 0.0], [64631.3, 0.0], [64631.6, 1.237], [64631.9, 0.004], [64645.5, 0.028], [64645.6, 0.001], [64645.7, 0.07], [64645.8, 0.202], [64645.9, 0.006], [64646.0, 0.762], [64646.1, 0.0], [64646.2, 0.032], [64646.3, 0.06], [64646.5, 0.003], [64647.3, 0.014], [64647.8, 0.074], [64662.9, 0.045], [64663.7, 0.867], [64664.4, 0.002], [64664.5, 0.028], [64664.6, 0.075], [64664.7, 0.224], [64664.8, 0.002], [64664.9, 0.003], [64665.0, 0.004], [64665.1, 0.0], [64665.2, 0.002], [64665.3, 0.252], [64665.4, 1.003], [64665.7, 0.0], [64666.0, 0.761], [64666.3, 0.218], [64666.6, 0.797], [64667.0, 1.253], [64672.7, 0.007], [64673.3, 0.002], [64675.2, 1.567], [64675.3, 0.011], [64678.9, 5.831]], "asks": [[64681.3, 0.017], [64682.2, 0.092], [64683.4, 0.001], [64683.5, 0.117], [64683.6, 0.312], [64683.7, 0.003], [64683.8, 0.003], [64683.9, 0.082], [64684.0, 0.501], [64684.1, 0.0], [64684.7, 0.619], [64684.8, 0.027], [64685.1, 0.004], [64685.3, 0.042], [64685.4, 0.441], [64685.7, 0.003], [64686.0, 0.005], [64686.4, 0.291], [64686.5, 0.024], [64686.6, 0.318], [64686.7, 0.082], [64686.8, 1.004], [64686.9, 0.004], [64687.0, 0.165], [64695.2, 0.075], [64695.3, 0.0], [64701.2, 0.0], [64702.0, 0.112], [64702.2, 0.134], [64702.3, 0.464], [64702.4, 1.228], [64702.5, 0.0], [64702.6, 0.004], [64702.7, 0.379], [64702.8, 0.071], [64702.9, 1.068], [64703.0, 0.665], [64716.6, 0.007], [64716.9, 0.001], [64717.2, 0.007], [64717.5, 1.97], [64717.9, 0.081], [64718.3, 0.504], [64734.1, 1.875], [64734.4, 1.377], [64734.8, 0.001], [64735.1, 0.026], [64735.4, 0.0], [64819.0, 5.4], [64836.0, 10.438], [64874.8, 7.304], [65002.4, 3.538], [65007.2, 0.116], [65325.8, 3.868]]}
{"kind": "depth", "E": 1787095174599, "U": 11316361396090, "u": 11316361400555, "recv_ms": 1787095174669, "bids": [[14478.9, 2.982], [14578.9, 1.218], [51743.0, 0.0], [58211.0, 0.01], [61444.9, 0.0], [62091.7, 0.692], [63678.9, 1.173], [63870.4, 8.207], [63914.1, 0.001], [63973.9, 2.183], [64032.1, 4.668], [64355.5, 3.803], [64555.6, 0.067], [64607.5, 0.0], [64611.8, 32.788], [64631.3, 0.032], [64631.6, 1.269], [64632.3, 0.108], [64645.7, 0.0], [64664.6, 0.005], [64664.9, 0.073], [64665.0, 0.074], [64665.2, 0.102], [64665.5, 0.72], [64666.4, 0.047], [64666.7, 0.539], [64667.3, 0.454], [64672.7, 0.345], [64675.3, 0.432], [64678.9, 5.831]], "asks": [[64679.0, 11.122], [64682.1, 0.013], [64682.2, 0.009], [64682.3, 0.289], [64683.0, 0.094], [64683.4, 0.0], [64683.9, 0.173], [64684.0, 0.431], [64684.7, 0.001], [64684.8, 0.027], [64684.9, 1.434], [64685.4, 0.554], [64685.5, 0.465], [64685.9, 0.083], [64686.5, 0.117], [64686.7, 0.743], [64687.1, 1.112], [64687.2, 0.091], [64687.4, 0.096], [64695.2, 0.129], [64697.2, 0.056], [64698.4, 0.991], [64702.4, 1.26], [64702.8, 0.001], [64703.1, 0.196], [64703.4, 2.368], [64705.6, 1.388], [64706.0, 0.539], [64706.1, 0.394], [64706.3, 0.095], [64720.0, 0.589], [64720.5, 0.043], [64720.6, 0.066], [64720.9, 0.123], [64721.1, 0.52], [64721.4, 2.353], [65325.8, 3.868], [65679.0, 0.342]]}
{"kind": "depth", "E": 1787095174701, "U": 11316361400596, "u": 11316361405260, "recv_ms": 1787095174772, "bids": [[1000.0, 35.76], [14478.9, 3.332], [14578.9, 0.868], [58211.0, 0.01], [61444.9, 0.0], [61445.0, 0.053], [62091.7, 0.689], [63385.4, 0.96], [64032.1, 4.668], [64403.3, 0.079], [64627.1, 0.111], [64632.0, 1.584], [64655.4, 0.001], [64660.6, 0.027], [64663.9, 0.624], [64665.4, 1.073], [64665.5, 0.102], [64667.0, 1.285], [64667.3, 0.454], [64670.7, 0.002], [64672.5, 0.453], [64672.7, 0.457], [64673.3, 0.115], [64675.0, 1.528], [64675.1, 1.548], [64675.2, 0.021], [64675.3, 0.432], [64675.4, 0.004], [64676.3, 0.003], [64678.9, 5.648]], "asks": [[64679.0, 11.123], [64679.8, 0.012], [64681.0, 0.009], [64681.3, 0.027], [64682.1, 0.003], [64682.2, 0.019], [64683.1, 0.157], [64683.5, 0.118], [64683.9, 0.173], [64684.8, 0.051], [64685.2, 0.042], [64685.5, 0.619], [64686.4, 0.136], [64686.5, 0.248], [64686.8, 1.074], [64690.9, 0.159], [64693.7, 0.654], [64694.4, 0.673], [64697.2, 0.042], [64698.8, 0.163], [64700.0, 3.322], [64702.7, 0.414], [64705.7, 0.071], [64720.3, 0.039], [64874.8, 6.912], [65002.4, 3.539], [65325.8, 3.868], [65403.4, 0.01], [65448.7, 6.419], [65621.0, 0.541], [65972.5, 0.006]]}
{"kind": "depth", "E": 1787095174803, "U": 11316361405292, "u": 11316361409917, "recv_ms": 1787095174873, "bids": [[1000.0, 35.76], [14478.9, 3.696], [14578.9, 0.504], [51743.0, 0.0], [58211.0, 0.01], [61444.9, 0.001], [62091.7, 0.692], [63678.9, 1.153], [64032.1, 4.668], [64355.5, 3.803], [64506.3, 0.096], [64506.4, 0.04], [64574.7, 3.583], [64574.8, 0.022], [64609.0, 0.0], [64609.6, 1.38], [64611.6, 0.018], [64611.8, 32.992], [64631.0, 0.032], [64655.4, 0.001], [64660.6, 0.027], [64663.4, 0.558], [64663.7, 0.31], [64664.8, 0.072], [64664.9, 0.143], [64665.0, 0.144], [64665.1, 0.07], [64665.4, 1.173], [64665.5, 0.202], [64665.8, 2.391], [64666.1, 0.194], [64667.3, 0.454], [64670.7, 0.002], [64672.5, 0.003], [64672.7, 0.232], [64673.2, 0.0], [64673.3, 0.115], [64673.7, 0.002], [64673.8, 0.234], [64675.1, 1.745], [64675.2, 0.45], [64675.3, 0.003], [64675.4, 0.004], [64675.5, 0.002], [64675.6, 0.067], [64678.6, 0.21], [64678.9, 5.741]], "asks": [[64679.0, 11.113], [64681.3, 0.017], [64682.2, 0.009], [64683.1, 0.157], [64683.5, 0.118], [64683.9, 0.082], [64684.7, 0.542], [64684.8, 0.128], [64685.3, 0.155], [64685.4, 0.441], [64685.5, 0.471], [64686.2, 0.16], [64686.4, 0.136], [64686.5, 0.27], [64686.6, 0.31], [64686.7, 0.202], [64686.8, 1.194], [64687.0, 0.295], [64687.1, 1.182], [64687.3, 0.55], [64687.4, 0.173], [64687.8, 0.118], [64690.9, 0.159], [64692.1, 0.015], [64693.6, 0.453], [64693.7, 0.036], [64694.4, 0.518], [64697.7, 0.196], [64698.8, 0.163], [64703.7, 0.253], [64704.0, 0.568], [64705.4, 0.129], [64705.7, 0.191], [64705.9, 0.2], [64706.0, 0.609], [64706.1, 0.464], [64706.2, 0.131], [64706.3, 0.172], [64721.2, 0.199], [64788.5, 2.696], [64788.6, 0.215], [64874.8, 5.563], [65325.8, 3.868], [65438.9, 0.917], [65487.5, 4.265], [65585.8, 2.587], [65679.0, 0.322]]}
{"kind": "depth", "E": 1787095174905, "U": 11316361410206, "u": 11316361415010, "recv_ms": 1787095174975, "bids": [[14378.9, 0.154], [14478.9, 3.738], [14578.9, 0.308], [58211.0, 0.01], [61444.9, 0.0], [64032.1, 4.668], [64613.8, 0.034], [64614.1, 0.033], [64614.8, 0.036], [64646.3, 0.16], [64655.4, 0.001], [64660.1, 0.245], [64660.6, 0.027], [64660.7, 0.322], [64662.5, 0.006], [64662.8, 0.676], [64663.4, 0.001], [64665.2, 0.202], [64665.3, 0.352], [64665.6, 0.085], [64665.7, 0.1], [64667.3, 0.454], [64670.7, 0.002], [64671.1, 0.002], [64672.5, 0.003], [64672.6, 0.468], [64672.7, 0.007], [64672.8, 0.0], [64673.3, 0.002], [64675.0, 0.987], [64675.1, 1.632], [64675.2, 0.57], [64675.3, 0.003], [64675.7, 0.094], [64676.3, 0.003], [64678.6, 0.343]], "asks": [[64683.1, 0.157], [64683.5, 0.118], [64683.9, 0.25], [64684.6, 0.02], [64684.7, 0.001], [64684.8, 0.027], [64685.3, 0.042], [64685.4, 0.441], [64685.5, 0.471], [64686.4, 0.785], [64686.5, 0.263], [64686.6, 0.521], [64687.0, 0.555], [64690.9, 0.159], [64694.4, 0.518], [64695.0, 0.026], [64697.7, 0.196], [64698.0, 0.228], [64698.8, 0.163], [64702.9, 1.068], [64703.0, 0.665], [64703.7, 0.138], [64703.8, 0.282], [64703.9, 0.559], [64704.0, 0.012], [64704.1, 0.133], [64704.5, 0.291], [64705.2, 0.031], [64705.5, 0.098], [64705.7, 0.198], [64705.8, 0.127], [64721.2, 0.045], [64721.3, 0.603], [65325.8, 3.868]]}
{"kind": "depth", "E": 1787095175109, "U": 11316361420050, "u": 11316361424924, "recv_ms": 1787095175178, "bids": [[1000.0, 35.76], [14378.9, 0.644], [14478.9, 3.486], [14578.9, 0.07], [51743.0, 0.0], [51743.1, 0.0], [58211.0, 0.01], [61444.9, 0.0], [62091.7, 0.692], [64032.1, 4.668], [64055.7, 1.292], [64355.5, 3.803], [64607.5, 0.0], [64609.0, 0.0], [64609.7, 0.189], [64611.8, 32.992], [64613.5, 1.296], [64646.5, 0.073], [64655.4, 0.001], [64660.6, 0.027], [64667.3, 0.454], [64670.7, 0.002], [64672.7, 0.007], [64675.5, 0.002], [64675.6, 0.075], [64676.3, 0.003], [64678.9, 5.739]], "asks": [[64683.1, 0.157], [64683.9, 0.25], [64684.7, 0.542], [64684.8, 0.104], [64685.4, 0.441], [64685.5, 0.471], [64686.4, 0.167], [64686.5, 0.263], [64690.9, 0.159], [64694.4, 0.518], [64697.7, 0.196], [64698.8, 0.163], [64721.3, 0.449], [64721.4, 2.507], [65325.8, 3.868], [65448.7, 7.335]]}
{"kind": "depth", "E": 1787095175211, "U": 11316361424928, "u": 11316361431088, "recv_ms": 1787095175282, "bids": [[14378.9, 0.924], [14478.9, 3.276], [14578.9, 0.0], [51743.0, 0.0], [58211.0, 0.01], [61444.9, 0.0], [62091.7, 0.689], [63678.9, 1.153], [64537.7, 0.0], [64607.5, 32.991], [64609.0, 0.018], [64611.8, 0.001], [64645.9, 0.076], [64646.1, 0.21], [64646.2, 0.102], [64646.5, 0.173], [64646.6, 0.117], [64646.9, 0.086], [64655.4, 0.001], [64660.6, 0.027], [64667.3, 0.454], [64670.7, 0.002], [64672.7, 0.232], [64675.5, 0.423], [64677.0, 1.015], [64678.9, 5.739]], "asks": [[64679.0, 11.114], [64683.1, 0.157], [64683.9, 0.082], [64684.7, 0.001], [64684.8, 0.653], [64685.4, 0.666], [64685.5, 0.471], [64686.4, 0.159], [64686.5, 0.263], [64687.1, 1.163], [64687.3, 0.551], [64690.9, 0.159], [64694.4, 0.518], [64697.7, 0.196], [64698.8, 0.163], [64707.9, 0.006], [64708.0, 1.267], [64708.1, 0.007], [64710.9, 0.009], [64711.0, 0.504], [64711.1, 3.263], [64711.8, 0.005], [64711.9, 0.045], [64712.0, 1.395], [64713.9, 0.002], [64714.0, 0.483], [64714.1, 0.031], [64721.3, 0.449], [64721.4, 2.353], [64819.0, 0.0], [65325.8, 3.868], [65584.5, 18.701], [65679.0, 0.322]]}
{"kind": "depth", "E": 1787095175313, "U": 11316361431194, "u": 11316361436494, "recv_ms": 1787095175382, "bids": [[1000.0, 35.76], [14378.9, 1.274], [14478.9, 2.926], [58211.0, 0.01], [61444.9, 0.0], [62091.7, 0.692], [64032.1, 4.668], [64537.7, 5.151], [64607.5, 0.0], [64609.0, 0.0], [64609.7, 33.18], [64646.0, 0.832], [64646.4, 0.386], [64646.7, 0.174], [64647.7, 0.119], [64648.2, 0.102], [64672.7, 0.12], [64675.5, 0.423], [64676.3, 0.003], [64678.9, 5.741]], "asks": [[64680.3, 0.002], [64683.6, 0.31], [64683.9, 0.082], [64684.1, 0.002], [64684.6, 0.02], [64684.7, 0.001], [64684.8, 0.027], [64685.4, 0.441], [64686.4, 0.785], [64721.3, 0.603], [64721.4, 2.353], [64819.0, 5.4], [64874.8, 6.684], [65325.8, 3.868]]}
{"kind": "depth", "E": 1787095175415, "U": 11316361436560, "u": 11316361442298, "recv_ms": 1787095175484, "bids": [[14378.9, 1.638], [14478.9, 2.562], [58211.0, 0.01], [61445.1, 0.004], [63375.9, 0.0], [63385.4, 0.957], [63447.8, 0.0], [63519.6, 0.002], [63591.5, 0.0], [63663.3, 0.0], [63678.9, 1.173], [63735.2, 0.0], [63807.0, 0.3], [63878.9, 1.566], [63950.8, 2.343], [64022.6, 0.008], [64032.1, 4.668], [64064.5, 9.602], [64355.5, 3.803], [64552.2, 0.0], [64553.6, 4.014], [64574.8, 1.573], [64611.1, 7.448], [64672.7, 0.345], [64675.5, 0.423]], "asks": [[64683.5, 0.118], [64684.7, 0.017], [64684.8, 0.576], [64685.4, 0.666], [64685.5, 0.471], [64686.4, 0.22], [64721.3, 0.449], [64721.4, 2.507], [64723.5, 0.689], [64732.6, 2.324], [64774.4, 2.587], [64774.5, 5.807], [64795.0, 1.642], [64814.2, 1.485], [65316.0, 0.344], [65325.8, 3.868], [65387.8, 0.001], [65459.7, 0.04], [65531.6, 0.0], [65603.4, 0.001], [65611.7, 15.373], [65675.3, 0.0], [65679.0, 0.342], [65747.1, 0.001], [65819.0, 3.508], [65890.8, 0.0], [65962.7, 1.522]]}
{"kind": "depth", "E": 1787095175619, "U": 11316361447603, "u": 11316361453846, "recv_ms": 1787095175689, "bids": [[1000.0, 35.76], [14378.9, 2.352], [14478.9, 1.848], [58211.0, 0.01], [61444.9, 0.0], [62091.7, 0.692], [63678.9, 1.153], [63858.8, 7.056], [64032.1, 4.668], [64355.5, 3.804], [64537.7, 5.151], [64672.7, 0.345], [64675.5, 0.423], [64678.9, 5.739]], "asks": [[64679.8, 0.009], [64683.5, 0.286], [64684.7, 0.001], [64684.8, 0.027], [64685.3, 0.155], [64685.4, 0.666], [64685.5, 0.394], [64686.4, 0.785], [64695.2, 0.129], [64800.0, 21.089], [64819.0, 4.109], [64874.8, 1.684], [65127.8, 0.0], [65300.0, 128.831], [65325.8, 3.868], [65445.3, 16.787], [65487.6, 0.343], [65616.8, 12.86], [65679.0, 0.322]]}
{"kind": "depth", "E": 1787095175721, "U": 11316361453870, "u": 11316361458392, "recv_ms": 1787095175791, "bids": [[14378.9, 2.702], [14478.9, 1.498], [51743.0, 0.002], [58211.0, 0.01], [61444.9, 0.0], [62091.7, 0.689], [63666.8, 8.157], [64032.1, 4.668], [64355.5, 3.814], [64563.4, 3.943], [64607.7, 2.451], [64660.1, 0.129], [64660.9, 0.12], [64671.6, 0.11], [64672.5, 0.08], [64672.7, 0.345], [64675.3, 1.549], [64675.4, 0.004], [64675.5, 0.423], [64678.9, 5.74]], "asks": [[64682.3, 0.289], [64683.5, 0.286], [64683.9, 0.005], [64684.7, 0.001], [64684.8, 0.14], [64685.4, 0.441], [64685.5, 0.568], [64686.4, 0.785], [64687.1, 0.81], [64688.0, 2.185], [64690.3, 0.707], [64693.6, 0.53], [64695.3, 0.618], [64750.1, 0.049], [64771.2, 0.288], [64814.3, 3.866], [64874.8, 5.627], [65002.4, 3.537], [65139.8, 0.061], [65325.8, 3.868], [65487.6, 0.001], [71146.9, 0.0]]}
{"kind": "depth", "E": 1787095175823, "U": 11316361458444, "u": 11316361463520, "recv_ms": 1787095175893, "bids": [[14378.9, 3.066], [14478.9, 1.134], [51743.0, 0.0], [58211.0, 0.01], [61445.0, 0.055], [63678.9, 1.173], [63751.6, 0.234], [64032.1, 4.668], [64355.5, 3.815], [64637.8, 0.025], [64646.2, 0.077], [64662.8, 0.119], [64663.6, 1.022], [64672.7, 0.007], [64675.3, 0.003], [64675.4, 0.012], [64675.5, 1.548], [64675.6, 0.067], [64676.3, 0.003], [64678.9, 5.742]], "asks": [[64681.5, 0.087], [64682.2, 0.009], [64682.3, 0.403], [64682.9, 0.052], [64683.5, 0.118], [64684.7, 0.001], [64684.8, 0.027], [64685.3, 0.042], [64685.5, 0.118], [64686.4, 0.785], [64687.6, 2.346], [64688.0, 2.165], [64690.3, 0.784], [64693.6, 0.511], [64721.5, 0.16], [64723.6, 0.029], [64732.6, 2.32], [65325.8, 3.868], [65402.1, 3.021], [65455.1, 16.246], [65679.0, 0.342]]}
{"kind": "depth", "E": 1787095175925, "U": 11316361463690, "u": 11316361468572, "recv_ms": 1787095175996, "bids": [[1000.0, 35.76], [14378.9, 3.416], [14478.9, 0.784], [58211.0, 0.01], [62091.7, 0.692], [63311.1, 2.366], [63676.4, 6.59], [63678.9, 1.153], [64032.1, 4.668], [64537.7, 0.0], [64614.2, 2.182], [64637.8, 0.0], [64646.2, 0.102], [64662.5, 0.006], [64672.7, 0.007], [64675.2, 0.554], [64675.3, 1.549], [64675.4, 0.02], [64675.5, 0.002], [64675.6, 0.067], [64675.7, 0.094]], "asks": [[64679.0, 11.113], [64682.3, 0.391], [64683.5, 0.118], [64684.6, 0.646], [64684.7, 0.009], [64684.8, 0.035], [64685.3, 0.042], [64685.5, 0.118], [64686.4, 0.143], [64690.3, 0.803], [64695.0, 0.026], [64721.4, 2.353], [64721.5, 0.006], [64721.6, 1.773], [64743.7, 0.009], [64819.0, 0.0], [65325.8, 3.868], [65679.0, 0.322]]}
{"kind": "depth", "E": 1787095176027, "U": 11316361468666, "u": 11316361474127, "recv_ms": 1787095176097, "bids": [[14278.9, 0.028], [14378.9, 3.724], [14478.9, 0.448], [58211.0, 0.01], [61444.9, 0.0], [62091.7, 0.689], [63385.4, 0.954], [63751.6, 0.0], [64032.1, 4.668], [64355.5, 3.805], [64537.7, 4.985], [64563.4, 3.943], [64574.6, 2.321], [64574.7, 1.264], [64576.5, 0.0], [64576.6, 0.004], [64607.7, 2.451], [64645.2, 0.12], [64658.1, 1.229], [64663.9, 0.006], [64671.6, 0.187], [64672.4, 0.549], [64672.5, 0.544], [64672.7, 0.007], [64675.1, 0.002], [64675.2, 0.013], [64675.4, 0.104], [64675.7, 0.01], [64676.3, 0.003], [64678.9, 5.412]], "asks": [[64679.0, 11.112], [64682.9, 0.22], [64683.5, 0.118], [64684.6, 0.02], [64684.7, 0.001], [64684.8, 0.14], [64685.3, 0.267], [64685.5, 0.568], [64686.4, 0.785], [64687.1, 0.971], [64687.3, 0.55], [64688.0, 1.547], [64720.4, 3.278], [64721.5, 0.006], [64721.6, 1.773], [64750.1, 0.049], [64788.5, 2.696], [64814.2, 0.0], [64814.3, 3.866], [64819.0, 5.4], [64867.5, 0.0], [64867.7, 0.418], [64874.8, 6.713], [65325.8, 3.868], [65445.3, 16.177]]}
{"kind": "depth", "E": 1787095176129, "U": 11316361474256, "u": 11316361480128, "recv_ms": 1787095176201, "bids": [[14278.9, 0.224], [14378.9, 3.696], [14478.9, 0.28], [51743.0, 0.0], [51743.1, 0.0], [58211.0, 0.01], [61444.9, 0.0], [62091.7, 0.692], [63320.6, 1.893], [63678.9, 1.173], [63685.4, 0.315], [63686.1, 0.0], [63686.3, 0.018], [64032.1, 4.668], [64475.1, 0.0], [64649.7, 0.03], [64667.3, 0.454], [64672.5, 0.003], [64672.7, 0.12], [64672.8, 0.0], [64675.1, 0.543], [64675.2, 1.567], [64675.3, 0.424], [64675.4, 0.096], [64675.5, 0.002], [64678.6, 0.435], [64678.9, 5.502]], "asks": [[64682.2, 0.019], [64682.9, 0.052], [64683.9, 0.005], [64684.6, 0.569], [64684.7, 0.086], [64684.8, 0.035], [64685.3, 0.042], [64685.4, 0.441], [64685.5, 0.125], [64686.3, 0.0], [64686.4, 0.143], [64687.1, 0.894], [64688.8, 0.007], [64690.3, 0.803], [64692.0, 3.31], [65325.8, 3.87], [65455.1, 16.856], [65466.7, 3.052], [65671.6, 0.0], [65671.7, 10.994], [65672.6, 0.0], [65679.0, 0.342]]}
{"kind": "depth", "E": 1787095176231, "U": 11316361480187, "u": 11316361485813, "recv_ms": 1787095176301, "bids": [[1000.0, 35.76], [14278.9, 0.448], [14378.9, 3.598], [14478.9, 0.154], [51743.0, 0.0], [58211.0, 0.01], [61444.9, 0.0], [62091.7, 0.689], [63385.4, 0.957], [63397.8, 0.0], [63685.4, 0.326], [63686.3, 0.035], [64032.1, 4.668], [64646.5, 0.176], [64653.0, 1.176], [64672.1, 0.009], [64672.7, 0.007], [64675.3, 0.003], [64676.3, 0.003], [64678.9, 5.501]], "asks": [[64679.0, 11.111], [64682.2, 0.009], [64684.6, 0.02], [64684.7, 0.001], [64684.8, 0.027], [64685.5, 0.202], [64686.4, 0.785], [64690.3, 0.803], [64721.5, 0.006], [64721.6, 1.619], [64724.3, 0.004], [65325.8, 3.868], [65671.7, 11.011], [65672.6, 0.011]]}
{"kind": "depth", "E": 1787095176333, "U": 11316361485936, "u": 11316361498643, "recv_ms": 1787095176402, "bids": [[14278.9, 0.686], [14378.9, 3.472], [14478.9, 0.042], [51743.0, 0.0], [58211.0, 0.01], [63666.8, 7.059], [63943.7, 1.562], [64032.1, 4.668], [64355.5, 3.805], [64672.7, 0.007], [64675.3, 0.003]], "asks": [[64685.5, 0.279], [64687.6, 2.365], [64721.5, 0.006], [64721.6, 1.773], [65325.8, 3.87]]}
{"kind": "depth", "E": 1787095176435, "U": 11316361498690, "u": 11316361505211, "recv_ms": 1787095176506, "bids": [[1000.0, 35.76], [14278.9, 1.008], [14378.9, 3.192], [14478.9, 0.0], [34000.0, 1.146], [58211.0, 0.01], [62091.7, 0.692], [63678.9, 1.153], [63923.5, 1.097], [64032.1, 4.668], [64607.5, 33.105], [64609.0, 0.009], [64611.8, 0.001], [64614.2, 2.182], [64655.4, 0.001], [64660.1, 0.245], [64660.6, 0.027], [64660.9, 0.004], [64662.7, 0.613], [64663.6, 0.465], [64667.3, 0.454], [64667.6, 0.003], [64667.9, 0.246], [64670.7, 0.002], [64672.5, 0.003], [64672.6, 0.918], [64672.7, 0.457], [64675.1, 0.543], [64675.3, 0.424], [64675.4, 0.096], [64675.8, 0.084]], "asks": [[64682.7, 0.162], [64682.9, 0.135], [64683.0, 0.167], [64683.1, 0.002], [64683.9, 0.173], [64685.4, 0.666], [64685.5, 0.617], [64686.2, 0.315], [64686.5, 0.108], [64690.9, 0.159], [64694.4, 0.673], [64697.7, 0.041], [64698.8, 0.163], [64702.9, 1.068], [64703.8, 0.282], [64703.9, 0.559], [64723.6, 0.025], [64733.9, 0.088], [64814.2, 1.485], [64874.8, 6.15], [65325.8, 3.868], [65679.0, 0.322]]}
{"kind": "depth", "E": 1787095176639, "U": 11316361510203, "u": 11316361515637, "recv_ms": 1787095176709, "bids": [[14278.9, 1.722], [14378.9, 2.478], [51743.0, 0.0], [58211.0, 0.01], [61444.9, 0.0], [62091.7, 0.692], [63375.8, 3.848], [63447.7, 0.059], [63519.5, 2.183], [63591.4, 0.058], [63663.2, 0.085], [63678.9, 1.173], [63735.1, 0.058], [63806.9, 0.068], [63878.8, 0.84], [63950.7, 0.065], [64022.5, 2.82], [64032.1, 4.668], [64355.5, 3.804], [64520.7, 0.001], [64520.8, 5.225], [64607.5, 0.0], [64609.0, 0.0], [64609.7, 0.189], [64611.8, 33.106], [64655.4, 0.001], [64660.6, 0.027], [64667.3, 0.454], [64670.7, 0.002], [64672.7, 0.457], [64673.6, 0.222], [64674.1, 0.06], [64675.3, 0.424], [64675.5, 0.002], [64678.9, 5.501]], "asks": [[64679.0, 11.151], [64681.3, 0.027], [64682.2, 0.019], [64682.7, 0.162], [64683.5, 0.118], [64684.8, 0.801], [64685.4, 0.779], [64685.5, 0.279], [64686.5, 0.263], [64687.1, 0.897], [64690.7, 0.004], [64690.9, 0.159], [64694.4, 0.673], [64698.8, 0.163], [64721.5, 0.16], [64874.8, 11.386], [65315.9, 0.397], [65325.8, 3.868], [65387.7, 0.058], [65459.6, 0.065], [65531.5, 6.115], [65603.3, 0.062], [65675.2, 0.058], [65679.0, 0.342], [65747.0, 0.085], [65818.9, 0.058], [65890.7, 0.058], [65962.6, 0.058]]}
{"kind": "depth", "E": 1787095176843, "U": 11316361520345, "u": 11316361524615, "recv_ms": 1787095176913, "bids": [[1000.0, 35.76], [14278.9, 2.436], [14378.9, 1.764], [58211.0, 0.01], [61444.9, 0.0], [63678.9, 1.153], [64032.1, 4.668], [64355.5, 3.803], [64537.7, 4.927], [64576.6, 0.001], [64576.7, 0.005], [64607.5, 33.105], [64611.8, 0.001], [64657.8, 2.939], [64665.2, 0.82], [64672.7, 0.007], [64672.8, 0.225], [64675.2, 1.559], [64675.4, 0.096], [64675.5, 0.002], [64675.6, 0.067], [64675.7, 0.018], [64675.8, 0.0], [64678.9, 5.485]], "asks": [[64683.9, 0.005], [64684.5, 0.019], [64684.6, 0.577], [64684.7, 0.001], [64684.8, 0.112], [64685.4, 0.441], [64685.5, 0.504], [64686.4, 0.136], [64686.5, 0.255], [64687.1, 0.974], [64687.7, 0.931], [64819.0, 5.4], [64874.8, 6.533], [65002.4, 3.539], [65325.8, 3.868], [65679.0, 0.322]]}
{"kind": "depth", "E": 1787095176945, "U": 11316361524689, "u": 11316361529118, "recv_ms": 1787095177015, "bids": [[14278.9, 2.786], [14378.9, 1.414], [58211.0, 0.01], [62091.7, 0.692], [64032.1, 4.668], [64355.5, 3.803], [64607.5, 0.0], [64609.0, 0.0], [64609.7, 33.387], [64662.5, 0.006], [64672.7, 0.007], [64672.8, 0.225], [64672.9, 0.085], [64675.2, 1.559], [64675.3, 0.011], [64675.7, 0.01], [64676.3, 0.003]], "asks": [[64682.2, 0.019], [64682.7, 0.245], [64682.9, 0.052], [64683.9, 0.082], [64684.5, 0.004], [64684.6, 0.577], [64684.7, 0.001], [64684.8, 0.112], [64685.3, 0.267], [64685.4, 0.441], [64685.5, 0.279], [64686.4, 0.151], [64695.0, 0.026], [65325.8, 3.868], [65972.5, 0.012]]}
{"kind": "depth", "E": 1787095177047, "U": 11316361529163, "u": 11316361534125, "recv_ms": 1787095177117, "bids": [[1000.0, 35.76], [14278.9, 3.15], [14378.9, 1.05], [51743.1, 0.0], [58211.0, 0.01], [61444.9, 0.0], [62091.7, 0.689], [63678.9, 1.173], [64032.1, 4.668], [64633.3, 0.008], [64640.7, 0.001], [64655.4, 0.001], [64660.6, 0.027], [64667.3, 0.459], [64670.7, 0.002], [64672.8, 0.0], [64672.9, 0.085], [64675.2, 1.559], [64675.3, 0.011], [64675.4, 0.096], [64675.5, 0.002], [64678.2, 0.027], [64678.9, 5.455]], "asks": [[64679.0, 11.155], [64682.2, 0.019], [64682.6, 0.005], [64682.7, 0.09], [64683.1, 0.157], [64683.5, 0.118], [64683.9, 0.005], [64684.6, 0.02], [64684.7, 0.542], [64684.8, 0.027], [64685.3, 0.042], [64685.4, 0.441], [64685.5, 0.202], [64686.4, 0.252], [64686.5, 0.255], [64690.9, 0.159], [64693.6, 0.53], [64694.4, 0.673], [64698.8, 0.163], [64874.8, 5.635], [65305.9, 0.003], [65325.8, 3.868], [65629.8, 5.096], [65679.0, 0.342], [65783.8, 1.008]]}
{"kind": "depth", "E": 1787095177149, "U": 11316361534167, "u": 11316361541065, "recv_ms": 1787095177218, "bids": [[1000.0, 35.76], [14278.9, 3.5], [14378.9, 0.7], [58211.0, 0.01], [62091.7, 0.692], [63678.9, 1.153], [64032.1, 4.668], [64537.7, 0.0], [64607.5, 33.198], [64609.7, 0.189], [64611.8, 0.001], [64667.3, 0.454], [64672.7, 0.457], [64675.2, 1.559], [64675.3, 0.432], [64675.9, 0.091], [64676.5, 0.002], [64677.6, 0.001], [64677.8, 0.042], [64678.9, 5.47]], "asks": [[64679.0, 11.154], [64683.9, 0.173], [64684.7, 0.001], [64685.3, 0.042], [64685.4, 0.554], [64685.5, 0.266], [64686.4, 0.793], [64687.1, 0.736], [64690.3, 0.592], [64693.6, 0.434], [64707.9, 0.004], [64708.0, 1.265], [64711.0, 0.502], [64711.8, 0.003], [64711.9, 0.043], [64714.0, 0.481], [64714.1, 0.029], [64771.2, 0.365], [64819.0, 0.0], [64869.3, 0.01], [65325.8, 3.868], [65679.0, 0.322]]}
{"kind": "depth", "E": 1787095177251, "U": 11316361541087, "u": 11316361546876, "recv_ms": 1787095177320, "bids": [[14178.9, 0.056], [14278.9, 3.752], [14378.9, 0.392], [51743.0, 0.0], [58211.0, 0.01], [61444.9, 0.0], [63771.2, 3.417], [63879.0, 5.654], [64032.1, 4.668], [64355.5, 3.813], [64537.8, 0.0], [64607.5, 0.0], [64609.0, 0.018], [64611.8, 33.199], [64633.3, 0.004], [64635.6, 0.004], [64672.7, 0.457], [64675.2, 1.559], [64675.3, 0.432], [64678.9, 5.471]], "asks": [[64681.3, 0.017], [64682.2, 0.009], [64683.9, 0.173], [64690.3, 0.784], [64708.1, 0.005], [64710.9, 0.007], [64711.1, 3.261], [64712.0, 1.393], [64713.9, 0.0], [64819.0, 0.0], [64867.9, 0.499], [64874.8, 5.829], [65325.8, 3.87], [65487.5, 4.751], [65792.8, 4.098]]}
{"kind": "depth", "E": 1787095177353, "U": 11316361546941, "u": 11316361551478, "recv_ms": 1787095177423, "bids": [[1000.0, 35.76], [14178.9, 0.266], [14278.9, 3.682], [14378.9, 0.252], [51743.0, 0.002], [58211.0, 0.01], [61444.9, 0.0], [62091.7, 0.689], [63779.9, 9.294], [64032.1, 4.668], [64537.8, 5.258], [64607.5, 0.0], [64609.0, 0.0], [64609.7, 33.387], [64611.8, 0.001], [64645.2, 0.078], [64655.4, 0.156], [64660.1, 0.245], [64660.6, 0.182], [64660.9, 0.004], [64662.8, 0.676], [64663.6, 0.465], [64667.3, 0.609], [64670.7, 0.312], [64671.5, 1.664], [64671.8, 0.002], [64672.3, 2.336], [64672.5, 0.621], [64672.7, 0.457], [64675.1, 0.002], [64675.3, 0.011], [64675.4, 0.251], [64675.5, 0.423], [64676.4, 0.084], [64676.8, 0.088]], "asks": [[64679.3, 0.151], [64681.5, 0.084], [64683.1, 0.002], [64684.8, 0.112], [64685.3, 0.042], [64685.5, 0.266], [64686.4, 0.708], [64686.5, 0.1], [64690.9, 0.004], [64691.0, 0.671], [64693.6, 0.511], [64694.4, 0.363], [64698.8, 0.008], [64702.9, 1.184], [64703.0, 1.221], [64703.8, 0.167], [64703.9, 0.003], [64720.4, 3.334], [64819.0, 5.4], [65325.8, 3.868], [65326.0, 0.54], [65487.5, 5.093], [65972.5, 0.009], [66290.7, 0.981], [66619.4, 4.348]]}
{"kind": "depth", "E": 1787095177455, "U": 11316361551522, "u": 11316361555451, "recv_ms": 1787095177525, "bids": [[1000.0, 35.76], [14178.9, 0.504], [14278.9, 3.57], [14378.9, 0.126], [51743.0, 0.0], [58211.0, 0.01], [61444.9, 0.0], [62091.7, 0.692], [63678.9, 1.173], [63760.5, 0.936], [64032.1, 4.668], [64609.7, 0.189], [64611.1, 7.481], [64611.8, 33.199], [64635.6, 0.0], [64642.4, 0.052], [64655.4, 0.001], [64660.6, 0.027], [64667.3, 0.454], [64670.7, 0.002], [64672.5, 0.08], [64672.7, 0.007], [64675.1, 0.543], [64675.3, 0.011], [64675.4, 0.096], [64675.5, 0.002], [64676.5, 0.002], [64678.9, 5.473]], "asks": [[64683.1, 0.157], [64684.8, 0.027], [64685.5, 0.266], [64686.3, 0.085], [64686.5, 0.255], [64690.3, 0.515], [64690.9, 0.159], [64692.0, 4.21], [64693.6, 0.556], [64694.4, 0.673], [64698.8, 0.163], [64702.9, 1.068], [64703.0, 0.665], [64703.8, 0.282], [64703.9, 0.559], [64771.2, 0.372], [64817.7, 1.23], [64874.8, 5.896], [65325.8, 3.868], [65679.0, 0.342]]}
{"kind": "depth", "E": 1787095177557, "U": 11316361555594, "u": 11316361560034, "recv_ms": 1787095177626, "bids": [[14178.9, 0.742], [14278.9, 3.444], [14378.9, 0.014], [58211.0, 0.01], [61444.9, 0.0], [62091.7, 0.689], [63734.7, 0.66], [64032.1, 4.668], [64355.5, 3.813], [64611.1, 1.887], [64641.7, 0.133], [64641.8, 0.154], [64655.4, 0.001], [64660.6, 0.027], [64667.3, 0.454], [64670.7, 0.002], [64672.5, 0.621], [64672.7, 0.232], [64675.1, 0.002], [64675.3, 0.011], [64675.4, 0.096], [64675.5, 0.002], [64676.4, 0.0], [64676.8, 0.004]], "asks": [[64679.0, 11.254], [64681.3, 0.027], [64682.2, 0.019], [64683.1, 0.157], [64683.5, 0.286], [64684.8, 0.373], [64685.3, 0.267], [64685.4, 0.779], [64685.5, 0.921], [64686.3, 0.232], [64686.5, 0.1], [64690.3, 0.803], [64690.9, 0.159], [64694.4, 0.673], [64698.8, 0.163], [64771.2, 0.211], [65325.8, 3.868], [65443.1, 17.33]]}
{"kind": "depth", "E": 1787095177659, "U": 11316361560075, "u": 11316361564482, "recv_ms": 1787095177728, "bids": [[1000.0, 35.76], [14178.9, 1.092], [14278.9, 3.108], [14378.9, 0.0], [58211.0, 0.012], [61445.0, 0.059], [62091.7, 0.692], [63678.9, 1.153], [63680.2, 0.0], [64032.1, 4.668], [64537.8, 4.927], [64641.8, 0.0], [64672.5, 0.08], [64672.7, 0.007], [64672.8, 0.0], [64675.0, 1.528], [64675.3, 0.011], [64676.5, 0.002], [64678.9, 5.473]], "asks": [[64679.0, 11.255], [64682.2, 0.187], [64682.3, 0.589], [64683.5, 0.118], [64683.9, 0.307], [64684.5, 0.088], [64684.6, 0.569], [64684.7, 0.009], [64684.8, 0.485], [64685.2, 0.042], [64685.3, 0.042], [64685.4, 0.441], [64685.5, 0.279], [64686.3, 0.155], [64686.4, 0.144], [64686.5, 0.1], [64687.1, 1.089], [64733.4, 0.018], [64736.0, 0.001], [64819.0, 5.4], [64874.8, 5.829], [65325.8, 3.868], [65679.0, 0.322], [65972.5, 0.006]]}
{"kind": "depth", "E": 1787095177761, "U": 11316361564571, "u": 11316361568747, "recv_ms": 1787095177830, "bids": [[1000.0, 35.76], [14178.9, 1.442], [14278.9, 2.758], [58211.0, 0.01], [63385.4, 0.954], [63569.8, 13.191], [63760.5, 1.17], [64032.1, 4.668], [64094.5, 0.006], [64355.5, 3.814], [64537.8, 0.0], [64641.8, 0.154], [64660.1, 0.129], [64660.9, 0.12], [64672.7, 0.007], [64675.1, 0.002], [64675.2, 0.013], [64675.3, 0.011], [64675.4, 1.642]], "asks": [[64682.2, 0.019], [64682.3, 0.312], [64683.3, 0.085], [64683.7, 0.005], [64683.9, 0.082], [64684.1, 0.0], [64684.5, 0.004], [64684.6, 0.02], [64684.7, 0.001], [64684.8, 0.027], [64685.5, 0.433], [64686.5, 0.749], [64687.1, 1.166], [64687.8, 0.098], [64688.0, 1.525], [64736.0, 0.01], [64819.0, 0.0], [64830.7, 0.001], [64839.5, 0.463], [65002.4, 3.538], [65325.8, 3.868]]}
{"kind": "depth", "E": 1787095177863, "U": 11316361568764, "u": 11316361572915, "recv_ms": 1787095177933, "bids": [[14178.9, 1.792], [14278.9, 2.408], [51743.0, 0.0], [58211.0, 0.01], [62091.7, 0.689], [63678.9, 1.173], [64032.1, 4.668], [64096.7, 1.245], [64355.5, 3.815], [64537.8, 4.73], [64672.5, 0.08], [64672.7, 0.345], [64672.8, 0.113], [64672.9, 0.147], [64675.1, 0.01], [64675.3, 0.003], [64675.4, 0.088], [64675.5, 0.002], [64675.6, 0.005], [64675.7, 0.01], [64675.8, 1.554]], "asks": [[64685.5, 0.49], [64771.2, 0.019], [64817.7, 0.003], [64819.0, 5.4], [64874.8, 6.726], [65002.4, 3.537], [65325.8, 3.868], [65679.0, 0.342]]}
{"kind": "depth", "E": 1787095177965, "U": 11316361572993, "u": 11316361577753, "recv_ms": 1787095178035, "bids": [[1000.0, 35.76], [14178.9, 2.156], [14278.9, 2.044], [58211.0, 0.01], [62091.7, 0.692], [63406.6, 0.675], [63579.4, 5.894], [63861.5, 0.5], [63955.8, 1.562], [64032.1, 4.668], [64537.8, 0.0], [64568.9, 0.0], [64574.5, 2.319], [64574.6, 0.002], [64609.7, 33.387], [64611.8, 0.001], [64614.2, 2.164], [64633.6, 0.638], [64662.5, 0.004], [64672.7, 0.007], [64672.8, 0.0], [64675.1, 1.556], [64675.2, 0.021], [64675.8, 0.0], [64678.6, 0.305]], "asks": [[64695.0, 0.024], [64724.3, 0.004], [64771.2, 0.0], [64788.3, 2.319], [64788.5, 0.377], [64819.0, 0.0], [65325.8, 3.868], [65445.3, 15.719], [65972.5, 0.009]]}
{"kind": "depth", "E": 1787095178067, "U": 11316361577887, "u": 11316361581988, "recv_ms": 1787095178136, "bids": [[1000.0, 35.76], [14178.9, 2.506], [14278.9, 1.694], [51743.1, 0.0], [58211.0, 0.01], [61444.9, 0.0], [62091.7, 0.689], [63678.9, 1.153], [63734.7, 0.315], [64032.1, 4.668], [64520.8, 7.087], [64537.8, 5.061], [64607.5, 33.289], [64609.7, 0.189], [64611.8, 0.001], [64614.2, 2.182], [64641.8, 0.154], [64662.5, 0.006], [64667.3, 0.454], [64672.1, 0.025], [64672.5, 0.08], [64675.2, 0.021], [64676.5, 0.002], [64678.9, 5.475]], "asks": [[64681.3, 0.017], [64682.2, 0.019], [64684.7, 0.017], [64684.8, 0.653], [64685.4, 0.441], [64685.5, 0.715], [64686.5, 0.107], [64695.0, 0.026], [64819.0, 5.4], [64836.0, 10.438], [64874.8, 6.089], [65325.8, 3.868], [65455.1, 17.314], [65679.0, 0.322]]}
{"kind": "depth", "E": 1787095178169, "U": 11316361582131, "u": 11316361586577, "recv_ms": 1787095178240, "bids": [[14178.9, 2.884], [14278.9, 1.316], [51743.0, 0.002], [58211.0, 0.01], [61444.9, 0.0], [63678.9, 1.173], [63736.0, 13.799], [63998.1, 0.0], [64032.1, 4.67], [64355.5, 3.815], [64568.9, 0.003], [64607.5, 0.0], [64609.0, 0.0], [64611.8, 33.29], [64627.1, 0.097], [64630.3, 0.24], [64662.8, 0.119], [64663.6, 1.022], [64666.7, 0.08], [64667.8, 0.464], [64672.5, 0.418], [64672.7, 0.12], [64672.9, 0.085], [64675.2, 0.504], [64676.3, 0.003], [64678.9, 6.41]], "asks": [[64679.0, 11.258], [64681.3, 0.027], [64682.2, 0.019], [64682.9, 0.052], [64684.7, 0.726], [64684.8, 0.112], [64685.5, 0.696], [64686.6, 0.212], [64686.7, 0.202], [64687.0, 0.864], [64687.7, 0.313], [64695.3, 0.0], [64697.2, 0.056], [64704.5, 0.909], [64711.9, 0.661], [64717.9, 0.084], [64723.6, 0.029], [64733.9, 0.084], [64756.7, 0.049], [64795.6, 0.105], [65325.8, 3.868], [65679.0, 0.342]]}
{"kind": "depth", "E": 1787095178271, "U": 11316361586586, "u": 11316361590697, "recv_ms": 1787095178341, "bids": [[1000.0, 35.76], [14178.9, 3.234], [14278.9, 0.966], [51743.0, 0.002], [58211.0, 0.01], [61444.9, 0.0], [62091.7, 0.692], [63734.6, 0.345], [64032.1, 4.668], [64617.6, 0.002], [64620.3, 0.629], [64666.0, 0.754], [64667.0, 1.292], [64672.5, 0.08], [64672.7, 0.007], [64675.1, 1.64], [64675.2, 0.083], [64675.9, 0.007], [64676.5, 0.002], [64678.9, 6.411]], "asks": [[64681.3, 0.017], [64682.2, 0.019], [64682.9, 0.052], [64683.9, 0.25], [64684.4, 0.003], [64684.5, 0.004], [64684.6, 0.02], [64684.7, 0.001], [64684.8, 0.128], [64685.4, 0.554], [64686.5, 0.1], [64686.7, 0.75], [64687.3, 0.592], [64691.7, 0.019], [64693.6, 0.575], [64701.0, 0.429], [64701.1, 0.332], [64744.3, 0.1], [65325.8, 3.868], [65623.4, 0.534], [65798.8, 1.221]]}
{"kind": "depth", "E": 1787095178373, "U": 11316361590749, "u": 11316361594865, "recv_ms": 1787095178444, "bids": [[1000.0, 35.76], [14178.9, 3.584], [14278.9, 0.616], [51743.0, 0.0], [58211.0, 0.01], [61445.0, 0.061], [62091.7, 0.689], [63678.9, 1.153], [64032.1, 4.668], [64559.8, 0.0], [64559.9, 4.555], [64641.7, 0.287], [64641.8, 0.0], [64656.9, 0.979], [64672.5, 0.418], [64675.2, 0.504], [64678.9, 6.41]], "asks": [[64679.0, 11.259], [64682.9, 0.062], [64683.9, 0.082], [64684.6, 0.02], [64684.7, 0.001], [64684.8, 0.027], [64685.4, 0.441], [64685.5, 0.619], [64686.7, 0.851], [64687.0, 0.865], [64693.5, 0.264], [64784.5, 1.288], [64787.0, 0.001], [64867.9, 4.479], [64868.0, 26.432], [65325.8, 3.868], [65552.3, 5.447], [65569.1, 0.38], [65679.0, 0.322]]}
{"kind": "depth", "E": 1787095178475, "U": 11316361594911, "u": 11316361599568, "recv_ms": 1787095178544, "bids": [[14178.9, 3.78], [14278.9, 0.336], [14578.9, 0.084], [58211.0, 0.01], [62091.7, 0.692], [63764.5, 0.0], [63805.7, 6.302], [64032.1, 4.699], [64355.5, 3.805], [64614.2, 6.56], [64672.5, 0.418], [64675.2, 0.504]], "asks": [[64682.2, 0.009], [64682.9, 0.052], [64683.9, 0.25], [64684.7, 0.549], [64684.8, 0.128], [64685.4, 0.441], [64685.5, 0.504], [64686.7, 0.202], [64817.7, 1.23], [64874.8, 5.262], [65325.8, 3.868], [65810.9, 2.428]]}
{"kind": "depth", "E": 1787095178577, "U": 11316361599624, "u": 11316361607929, "recv_ms": 1787095178646, "bids": [[1000.0, 35.76], [14178.9, 3.654], [14278.9, 0.224], [14578.9, 0.322], [58211.0, 0.01], [61444.9, 0.0], [61445.0, 0.063], [62091.7, 0.689], [64032.1, 4.699], [64481.8, 0.008], [64482.0, 5.298], [64483.0, 9.831], [64520.8, 2.712], [64521.8, 0.024], [64524.0, 0.377], [64537.8, 2.167], [64672.5, 0.53], [64672.7, 0.345], [64675.2, 0.504], [64676.5, 0.002], [64678.9, 6.41]], "asks": [[64679.0, 11.254], [64682.2, 0.019], [64682.9, 0.052], [64683.9, 0.173], [64684.7, 0.001], [64684.8, 0.027], [64685.4, 0.554], [64685.5, 0.343], [64686.7, 0.851], [64687.1, 0.82], [64690.3, 0.784], [64693.6, 0.729], [64735.0, 0.179], [64735.2, 1.03], [64797.0, 0.212], [64817.7, 0.003], [64819.0, 5.4], [64822.4, 1.29], [64824.9, 0.0], [64867.9, 0.499], [64868.0, 0.434], [64874.8, 15.414], [65325.8, 3.868], [65522.8, 0.0], [65552.2, 4.931], [65578.0, 8.951], [65584.6, 8.527], [65623.3, 0.305], [65972.5, 0.012]]}
{"kind": "depth", "E": 1787095178679, "U": 11316361607982, "u": 11316361613680, "recv_ms": 1787095178749, "bids": [[1000.0, 35.76], [14178.9, 3.542], [14278.9, 0.098], [14578.9, 0.56], [58211.0, 0.01], [61444.9, 0.0], [63678.9, 1.173], [63870.5, 2.152], [64032.1, 4.699], [64355.5, 3.805], [64481.3, 0.228], [64482.0, 13.601], [64483.1, 0.025], [64493.0, 14.647], [64495.7, 3.297], [64520.8, 6.594], [64531.8, 13.683], [64534.1, 3.034], [64537.8, 4.742], [64563.4, 3.943], [64569.6, 10.061], [64607.7, 2.451], [64617.5, 2.83], [64647.0, 8.003], [64647.4, 4.106], [64672.2, 0.088], [64672.5, 0.531], [64672.7, 0.345], [64672.8, 0.0], [64675.2, 0.504], [64676.1, 0.084], [64676.6, 0.001], [64678.9, 6.409]], "asks": [[64679.0, 11.17], [64679.3, 0.235], [64682.2, 0.009], [64682.9, 0.052], [64683.5, 0.118], [64683.9, 0.005], [64685.5, 0.456], [64704.5, 0.291], [64710.0, 3.117], [64710.4, 0.007], [64711.9, 0.043], [64743.5, 2.919], [64750.1, 0.049], [64771.2, 0.173], [64791.3, 3.537], [64791.4, 20.63], [64792.1, 0.002], [64814.2, 0.0], [64814.3, 3.866], [64829.2, 26.553], [64868.0, 0.434], [64874.8, 6.645], [65325.8, 3.869], [65679.0, 0.342]]}
{"kind": "depth", "E": 1787095178781, "U": 11316361613759, "u": 11316361618951, "recv_ms": 1787095178851, "bids": [[14178.9, 3.388], [14278.9, 0.0], [14578.9, 0.812], [58211.0, 0.01], [62091.7, 0.692], [64032.1, 4.699], [64355.5, 3.804], [64468.7, 0.034], [64488.7, 0.004], [64672.5, 0.081], [64672.7, 0.007], [64675.2, 0.083], [64676.5, 0.002]], "asks": [[64682.2, 0.187], [64682.3, 0.527], [64683.4, 0.113], [64683.5, 0.456], [64683.8, 0.228], [64683.9, 0.455], [64684.7, 0.999], [64684.8, 0.128], [64685.3, 0.042], [64685.4, 0.441], [64685.5, 0.317], [64686.7, 0.202], [64690.3, 0.803], [64735.0, 0.209], [64735.2, 1.0], [64789.0, 0.005], [65002.4, 3.538], [65325.8, 3.871]]}
{"kind": "depth", "E": 1787095178985, "U": 11316361624531, "u": 11316361629308, "recv_ms": 1787095179075, "bids": [[1000.0, 35.76], [14178.9, 2.674], [14578.9, 1.526], [58211.0, 0.01], [62091.7, 0.692], [63678.9, 1.173], [63891.2, 3.143], [64032.1, 4.699], [64355.5, 3.813], [64537.8, 5.242], [64662.5, 0.004], [64675.1, 1.639], [64676.9, 0.001]], "asks": [[64682.2, 0.019], [64682.3, 0.312], [64683.3, 0.085], [64683.4, 0.0], [64683.5, 0.118], [64683.9, 0.005], [64684.7, 0.001], [64684.8, 0.027], [64685.2, 0.042], [64695.0, 0.024], [64819.0, 5.4], [65002.4, 3.539], [65325.8, 3.869], [65482.3, 2.249], [65679.0, 0.342]]}
{"kind": "depth", "E": 1787095179087, "U": 11316361629350, "u": 11316361635937, "recv_ms": 1787095179160, "bids": [[14178.9, 2.31], [14578.9, 1.89], [51743.1, 0.0], [58211.0, 0.01], [61444.9, 0.0], [61445.0, 0.061], [61445.1, 0.004], [62091.7, 0.689], [63899.6, 0.939], [64032.1, 4.699], [64641.0, 0.002], [64641.7, 0.133], [64642.9, 2.041], [64650.8, 2.16], [64655.4, 0.001], [64656.9, 0.977], [64660.6, 0.027], [64662.5, 0.006], [64667.3, 0.454], [64670.1, 0.32], [64670.7, 0.002], [64672.5, 0.081], [64672.7, 0.007], [64675.2, 0.083], [64676.5, 0.011], [64676.6, 0.001], [64678.9, 6.409]], "asks": [[64683.1, 0.157], [64683.5, 0.118], [64683.9, 0.173], [64684.8, 0.027], [64685.3, 0.042], [64685.4, 0.554], [64685.5, 0.266], [64686.3, 0.0], [64686.5, 0.255], [64686.6, 0.227], [64686.7, 0.836], [64687.1, 0.813], [64690.3, 0.63], [64690.9, 0.159], [64693.6, 0.71], [64694.4, 0.518], [64695.0, 0.026], [64697.7, 0.196], [64698.8, 0.163], [64771.2, 0.288], [65325.8, 3.869], [66296.0, 2.184]]}
{"kind": "depth", "E": 1787095179189, "U": 11316361636051, "u": 11316361642108, "recv_ms": 1787095179262, "bids": [[1000.0, 35.76], [14178.9, 1.96], [14578.9, 2.24], [58211.0, 0.01], [61444.9, 0.001], [64032.1, 4.699], [64506.0, 0.051], [64506.4, 0.001], [64537.8, 0.0], [64641.7, 0.287], [64647.0, 0.003], [64649.3, 1.303], [64672.5, 0.081], [64672.7, 0.007], [64675.2, 0.083], [64678.9, 6.411]], "asks": [[64679.0, 11.19], [64683.9, 0.005], [64684.8, 0.195], [64685.2, 0.045], [64685.4, 0.441], [64687.8, 0.716], [64688.7, 0.805], [64695.2, 0.747], [64745.5, 1.394], [64746.0, 0.014], [64819.0, 0.0], [65325.8, 3.871], [65487.5, 5.398], [65490.5, 0.763], [65773.4, 6.677]]}
{"kind": "depth", "E": 1787095179291, "U": 11316361642155, "u": 11316361647227, "recv_ms": 1787095179360, "bids": [[1000.0, 35.76], [14178.9, 1.596], [14578.9, 2.604], [58211.0, 0.01], [61444.9, 0.0], [62091.7, 0.692], [63678.9, 1.153], [63734.6, 0.737], [63800.7, 6.213], [64032.1, 4.699], [64355.5, 3.813], [64520.8, 6.503], [64537.8, 4.911], [64568.9, 0.0], [64633.6, 0.638], [64641.7, 0.287], [64672.5, 0.531], [64672.7, 0.12], [64675.2, 0.504], [64676.6, 0.001]], "asks": [[64679.0, 11.19], [64685.5, 0.427], [64690.3, 0.803], [64693.6, 0.729], [64724.3, 0.004], [64744.0, 1.301], [64745.5, 1.355], [64756.7, 0.046], [64789.0, 0.002], [64819.0, 5.4], [64836.0, 10.438], [64874.8, 6.804], [65325.8, 3.869], [65679.0, 0.322], [67912.9, 0.02]]}
{"kind": "depth", "E": 1787095179393, "U": 11316361647350, "u": 11316361651952, "recv_ms": 1787095179477, "bids": [[14178.9, 1.246], [14578.9, 2.954], [58211.0, 0.01], [61445.0, 0.063], [62091.7, 0.689], [63708.6, 1.841], [63805.7, 7.083], [63899.6, 0.001], [63909.2, 8.444], [64032.1, 4.699], [64055.7, 0.623], [64537.8, 0.0], [64635.6, 0.004], [64642.4, 0.048], [64672.5, 0.53], [64672.7, 0.232], [64673.4, 0.012], [64675.2, 0.504], [64676.5, 0.095]], "asks": [[64717.9, 0.004], [64744.0, 1.262], [64744.2, 0.039], [64819.0, 0.0], [65325.8, 3.869], [65455.1, 18.84], [65547.0, 4.11], [65972.5, 0.015]]}
{"kind": "depth", "E": 1787095179495, "U": 11316361652162, "u": 11316361658598, "recv_ms": 1787095179565, "bids": [[1000.0, 35.76], [14178.9, 0.882], [14578.9, 3.318], [51743.0, 0.0], [58211.0, 0.01], [61855.2, 0.004], [62091.7, 0.692], [63678.9, 1.173], [64032.1, 4.699], [64537.8, 5.254], [64571.7, 2.527], [64650.0, 3.378], [64660.0, 0.006], [64663.3, 0.577], [64663.6, 0.465], [64667.3, 0.913], [64667.8, 0.005], [64672.4, 0.55], [64672.5, 0.621], [64672.6, 0.918], [64672.7, 0.345], [64673.4, 0.011], [64675.0, 0.987], [64675.2, 0.504], [64676.6, 0.001]], "asks": [[64685.5, 0.504], [64743.8, 6.364], [64744.2, 0.0], [64814.2, 1.485], [64819.0, 5.4], [64874.8, 5.975], [65325.8, 3.869], [65552.2, 5.646], [65679.0, 0.342], [65778.5, 8.04]]}
{"kind": "depth", "E": 1787095179597, "U": 11316361658697, "u": 11316361664428, "recv_ms": 1787095179668, "bids": [[1000.0, 35.76], [14178.9, 0.532], [14578.9, 3.668], [51743.0, 0.0], [58211.0, 0.01], [61444.9, 0.001], [63574.3, 5.996], [63870.4, 8.441], [63909.2, 9.382], [64032.1, 4.699], [64355.5, 3.803], [64505.9, 0.039], [64506.0, 0.012], [64537.8, 0.0], [64672.4, 0.549], [64672.5, 0.531], [64672.6, 0.468], [64672.7, 0.232], [64673.4, 0.011], [64675.0, 1.528], [64675.2, 0.504], [64678.9, 6.411]], "asks": [[64685.5, 0.35], [64690.3, 0.784], [64701.1, 0.332], [64743.8, 6.325], [64744.2, 0.039], [64819.0, 0.0], [65325.8, 3.869], [65443.1, 15.804], [65838.0, 1.208]]}
{"kind": "depth", "E": 1787095179699, "U": 11316361664547, "u": 11316361669915, "recv_ms": 1787095179767, "bids": [[14178.9, 0.308], [14478.9, 0.14], [14578.9, 3.752], [58211.0, 0.01], [61444.9, 0.0], [62091.7, 0.689], [63678.9, 1.153], [63961.7, 0.896], [64032.1, 4.699], [64520.8, 0.0], [64521.2, 2.395], [64657.8, 2.321], [64665.2, 0.202], [64672.4, 0.55], [64672.5, 0.08], [64672.6, 0.468], [64672.7, 0.007], [64673.4, 0.011], [64675.0, 1.528], [64675.1, 1.64], [64675.2, 0.083], [64676.9, 0.0], [64678.9, 5.474]], "asks": [[64683.9, 0.173], [64684.8, 0.661], [64685.4, 0.666], [64685.5, 0.504], [64686.7, 0.202], [64687.8, 0.098], [64688.4, 0.203], [64690.3, 0.803], [64693.3, 0.156], [64835.9, 0.838], [64836.0, 0.027], [65325.8, 3.868], [65679.0, 0.322], [66027.4, 3.02]]}
{"kind": "depth", "E": 1787095180005, "U": 11316361679807, "u": 11316361684564, "recv_ms": 1787095180076, "bids": [[14178.9, 0.0], [14478.9, 0.896], [14578.9, 3.304], [58211.0, 0.01], [61444.9, 0.0], [61445.0, 0.061], [61445.1, 0.006], [62091.7, 0.692], [63385.4, 0.951], [64355.5, 3.815], [64563.4, 3.943], [64574.4, 4.718], [64574.5, 0.0], [64607.7, 2.451], [64624.5, 0.018], [64642.6, 0.056], [64655.4, 0.156], [64656.9, 0.975], [64660.6, 0.182], [64662.5, 0.004], [64667.4, 0.164], [64670.7, 0.312], [64672.5, 0.08], [64672.7, 0.007], [64675.2, 0.238], [64676.1, 0.0], [64676.5, 0.011], [64678.9, 5.485]], "asks": [[64683.1, 0.002], [64683.9, 0.005], [64684.8, 0.195], [64685.4, 0.441], [64685.5, 0.266], [64686.5, 0.1], [64690.3, 0.63], [64690.9, 0.004], [64693.6, 0.652], [64694.4, 0.363], [64695.0, 0.024], [64697.2, 0.042], [64697.7, 0.041], [64698.8, 0.008], [64720.4, 3.278], [64743.3, 0.043], [64744.2, 0.0], [64750.1, 0.049], [64771.2, 0.365], [64788.2, 2.319], [64788.3, 0.0], [64814.2, 0.0], [64814.3, 3.866], [64867.7, 0.415], [64867.8, 0.028], [65002.4, 3.537], [65325.8, 3.87], [65458.2, 1.063], [65972.5, 0.012]]}
{"kind": "depth", "E": 1787095180107, "U": 11316361684565, "u": 11316361689311, "recv_ms": 1787095180180, "bids": [[1000.0, 35.76], [14478.9, 1.26], [14578.9, 2.94], [51743.1, 0.0], [58211.0, 0.01], [61444.9, 0.0], [61445.0, 0.059], [61445.1, 0.008], [63678.9, 1.153], [63779.9, 10.201], [64032.1, 4.699], [64635.6, 0.0], [64642.4, 0.052], [64655.4, 0.001], [64660.6, 0.027], [64662.5, 0.006], [64667.3, 0.913], [64667.4, 0.009], [64670.7, 0.002], [64671.8, 0.086], [64672.5, 0.418], [64672.7, 0.453], [64675.2, 0.504], [64675.4, 0.004], [64676.5, 0.011], [64678.6, 0.228], [64678.9, 5.484]], "asks": [[64679.0, 11.191], [64682.7, 0.245], [64683.7, 0.003], [64684.0, 0.433], [64686.6, 0.367], [64687.1, 0.736], [64690.3, 0.438], [64690.9, 0.159], [64693.6, 0.556], [64694.4, 0.673], [64695.0, 0.026], [64698.8, 0.163], [64701.0, 0.433], [64743.3, 0.004], [64744.2, 0.039], [64771.2, 0.372], [64874.8, 6.038], [65225.7, 0.0], [65325.8, 3.868], [65679.0, 0.322], [66619.4, 4.348]]}
{"kind": "depth", "E": 1787095180209, "U": 11316361689426, "u": 11316361701613, "recv_ms": 1787095180325, "bids": [[1000.0, 35.76], [14478.9, 1.61], [14578.9, 2.59], [58211.0, 0.01], [62091.7, 0.689], [63678.9, 1.173], [63773.4, 13.497], [63861.5, 0.235], [64032.1, 4.699], [64346.0, 0.017], [64347.1, 1.225], [64355.5, 3.805], [64482.0, 7.921], [64520.8, 0.0], [64520.9, 4.516], [64537.8, 2.974], [64568.9, 0.003], [64617.5, 0.088], [64640.0, 0.029], [64658.1, 1.847], [64665.4, 1.791], [64672.5, 0.418], [64672.7, 0.453], [64675.2, 0.504], [64678.9, 5.484]], "asks": [[64679.0, 11.19], [64684.8, 0.027], [64686.0, 0.006], [64687.9, 0.65], [64688.8, 0.006], [64690.3, 0.515], [64693.6, 0.806], [64743.4, 0.066], [64743.5, 0.004], [64744.2, 0.0], [64756.7, 0.049], [64874.8, 15.414], [65325.8, 3.87], [65679.0, 0.342], [66000.0, 98.768]]}
{"kind": "depth", "E": 1787095180311, "U": 11316361701675, "u": 11316361707180, "recv_ms": 1787095180381, "bids": [[14478.9, 1.974], [14578.9, 2.226], [51743.0, 0.0], [58211.0, 0.01], [61444.9, 0.0], [62091.7, 0.692], [64032.1, 4.699], [64482.0, 13.262], [64520.9, 6.859], [64537.8, 4.732], [64617.5, 2.834], [64672.5, 0.418], [64672.7, 0.453], [64675.2, 0.504], [64676.5, 0.011], [64677.5, 0.011], [64678.9, 5.488]], "asks": [[64683.9, 0.173], [64684.8, 0.027], [64685.4, 0.554], [64721.1, 0.674], [64721.5, 0.006], [64743.3, 2.937], [64743.4, 0.027], [64744.2, 0.039], [64874.8, 7.108], [65325.8, 3.868], [65531.4, 3.036], [65588.3, 0.227], [65972.5, 0.015], [67912.9, 0.03]]}
{"kind": "depth", "E": 1787095180413, "U": 11316361707314, "u": 11316361711620, "recv_ms": 1787095180484, "bids": [[1000.0, 35.91], [14478.9, 2.324], [14578.9, 1.876], [51743.0, 0.0], [58211.0, 0.01], [62091.7, 0.689], [63602.2, 1.475], [63891.0, 12.765], [63891.2, 3.925], [64032.1, 4.701], [64521.2, 3.172], [64634.9, 0.068], [64642.4, 0.048], [64672.5, 0.418], [64672.7, 0.453], [64675.2, 0.504]], "asks": [[64682.0, 0.194], [64683.9, 0.173], [64685.4, 0.441], [64721.1, 0.52], [64721.2, 0.199], [64814.2, 1.485], [65230.8, 0.077], [65325.8, 3.868], [65596.1, 0.761], [65604.8, 1.264]]}
{"kind": "depth", "E": 1787095180515, "U": 11316361711635, "u": 11316361716397, "recv_ms": 1787095180583, "bids": [[1000.0, 35.76], [14478.9, 2.688], [14578.9, 1.512], [58211.0, 0.01], [61444.9, 0.0], [62091.7, 0.692], [63678.9, 1.153], [63870.4, 8.792], [63946.4, 0.783], [64032.1, 4.699], [64161.5, 4.812], [64249.8, 0.008], [64256.2, 0.014], [64355.5, 3.805], [64482.0, 0.662], [64482.1, 12.649], [64520.9, 7.458], [64537.8, 5.073], [64568.9, 0.003], [64617.5, 2.834], [64627.8, 0.388], [64633.6, 0.635], [64634.2, 0.07], [64634.9, 0.064], [64663.5, 0.631], [64666.9, 0.258], [64672.5, 0.08], [64672.7, 0.003], [64675.0, 1.528], [64675.2, 0.083], [64676.5, 0.011], [64678.9, 5.428]], "asks": [[64679.0, 11.21], [64683.9, 0.005], [64685.4, 0.441], [64686.0, 0.005], [64695.8, 0.02], [64708.6, 0.006], [64723.6, 0.025], [64724.3, 0.004], [64730.0, 0.892], [64733.9, 0.088], [64740.3, 0.081], [64743.2, 3.168], [64743.3, 0.004], [64743.5, 0.043], [64744.2, 0.0], [64756.7, 0.046], [64874.8, 6.152], [65325.8, 3.868], [65516.9, 0.129], [65523.5, 0.0], [65649.3, 9.206], [65679.0, 0.322]]}
{"kind": "depth", "E": 1787095180617, "U": 11316361716537, "u": 11316361721057, "recv_ms": 1787095180688, "bids": [[14478.9, 3.038], [14578.9, 1.162], [58211.0, 0.01], [64032.1, 4.699], [64537.8, 0.0], [64672.5, 0.08], [64672.7, 0.003], [64675.2, 0.504]], "asks": [[64684.8, 0.195], [64690.3, 0.63], [64701.4, 3.191], [64721.1, 0.52], [64721.2, 0.199], [64723.5, 0.693], [64733.9, 0.084], [64743.3, 0.043], [64743.5, 0.004], [64744.2, 0.0], [64819.0, 0.0], [65325.8, 3.868], [65616.8, 13.773]]}
{"kind": "depth", "E": 1787095180719, "U": 11316361721283, "u": 11316361727305, "recv_ms": 1787095180793, "bids": [[1000.0, 35.76], [14478.9, 3.402], [14578.9, 0.798], [58211.0, 0.01], [61444.9, 0.0], [62091.7, 0.689], [63385.4, 0.954], [63464.4, 0.786], [63611.7, 1.121], [63671.4, 11.371], [63676.4, 8.314], [63678.9, 1.173], [63790.8, 0.0], [63861.5, 0.0], [64032.1, 4.699], [64642.6, 0.014], [64655.4, 0.156], [64660.3, 0.042], [64660.6, 0.182], [64662.9, 0.005], [64667.4, 0.164], [64670.7, 0.312], [64672.3, 2.333], [64672.7, 0.003], [64672.8, 0.0], [64673.7, 0.002], [64675.1, 1.64], [64675.2, 0.083], [64675.3, 0.158], [64675.8, 0.0], [64676.5, 0.011], [64678.9, 5.428]], "asks": [[64679.0, 11.209], [64681.0, 0.012], [64682.7, 0.09], [64683.5, 0.343], [64683.9, 0.398], [64684.7, 0.782], [64684.8, 0.345], [64685.2, 0.158], [64685.3, 0.492], [64685.4, 0.441], [64685.5, 0.041], [64686.5, 0.1], [64686.6, 0.212], [64686.7, 0.202], [64687.1, 0.82], [64690.3, 0.803], [64690.9, 0.004], [64693.6, 0.787], [64694.4, 0.363], [64698.8, 0.008], [64703.1, 0.754], [64707.9, 0.006], [64708.0, 1.267], [64708.1, 0.007], [64710.9, 0.009], [64711.0, 0.504], [64711.1, 3.263], [64711.8, 0.005], [64711.9, 0.045], [64712.0, 1.395], [64713.9, 0.002], [64714.0, 0.483], [64714.1, 0.031], [64720.4, 3.334], [64743.3, 0.004], [64744.2, 0.039], [65325.8, 3.868], [65649.2, 4.137], [65679.0, 0.342], [65773.4, 6.071], [68228.8, 0.0]]}
{"kind": "depth", "E": 1787095180821, "U": 11316361727403, "u": 11316361732296, "recv_ms": 1787095180891, "bids": [[14378.9, 0.028], [14478.9, 3.696], [14578.9, 0.476], [51743.0, 0.0], [58211.0, 0.01], [61444.9, 0.0], [62091.7, 0.692], [63469.4, 3.224], [63678.9, 1.153], [64032.1, 4.699], [64355.5, 3.805], [64537.8, 5.061], [64646.9, 0.086], [64651.1, 0.01], [64655.4, 0.156], [64658.7, 0.05], [64660.6, 0.182], [64667.4, 0.164], [64670.7, 0.312], [64671.9, 0.006], [64672.5, 0.08], [64672.7, 0.003], [64673.0, 0.233], [64673.1, 0.114], [64673.8, 0.002], [64674.2, 0.01], [64675.2, 0.083], [64675.3, 0.158], [64675.4, 0.088], [64678.9, 5.427]], "asks": [[64681.0, 0.009], [64682.3, 0.312], [64683.1, 0.002], [64683.5, 0.118], [64683.8, 0.171], [64683.9, 0.236], [64684.7, 0.001], [64684.8, 0.027], [64685.2, 0.045], [64685.3, 0.042], [64685.4, 0.554], [64685.5, 0.638], [64686.6, 0.32], [64686.7, 0.743], [64687.1, 0.916], [64690.9, 0.004], [64694.4, 0.363], [64698.8, 0.008], [64721.1, 0.674], [64721.2, 0.045], [64771.2, 0.0], [64797.0, 0.001], [64819.0, 5.4], [64874.8, 6.233], [65325.8, 3.868], [65679.0, 0.322]]}
{"kind": "depth", "E": 1787095180923, "U": 11316361732311, "u": 11316361737392, "recv_ms": 1787095180992, "bids": [[14378.9, 0.196], [14478.9, 3.724], [14578.9, 0.28], [58211.0, 0.01], [62091.7, 0.689], [63731.5, 17.33], [64032.1, 4.699], [64355.5, 3.804], [64403.3, 0.079], [64655.4, 0.001], [64660.6, 0.027], [64667.4, 0.009], [64670.7, 0.002], [64672.5, 0.08], [64672.7, 0.003], [64675.2, 0.083], [64675.3, 0.003]], "asks": [[64681.3, 0.017], [64682.2, 0.009], [64683.1, 0.002], [64683.5, 0.273], [64683.8, 0.003], [64684.7, 0.001], [64684.8, 0.027], [64685.4, 0.441], [64685.5, 0.413], [64686.5, 0.1], [64686.6, 0.861], [64686.7, 0.357], [64687.1, 1.031], [64690.9, 0.159], [64694.4, 0.673], [64698.8, 0.163], [64794.7, 0.0], [65325.8, 3.868], [65438.9, 0.001], [65499.1, 0.763], [65620.9, 2.432], [65629.8, 5.629], [65778.5, 8.646], [68228.8, 0.076]]}
{"kind": "depth", "E": 1787095181025, "U": 11316361737458, "u": 11316361741831, "recv_ms": 1787095181105, "bids": [[1000.0, 35.76], [14378.9, 0.448], [14478.9, 3.584], [14578.9, 0.168], [58211.0, 0.01], [63579.5, 3.435], [63787.8, 1.877], [63802.3, 1.957], [64032.1, 4.699], [64355.5, 3.803], [64613.5, 1.264], [64613.8, 0.002], [64614.1, 0.001], [64614.2, 6.559], [64614.4, 0.973], [64614.8, 0.004], [64621.9, 0.121], [64631.0, 0.0], [64631.3, 0.0], [64631.6, 1.237], [64632.0, 1.552], [64632.3, 0.076], [64645.9, 0.006], [64646.0, 0.762], [64646.1, 0.0], [64646.2, 0.032], [64646.3, 0.06], [64646.4, 0.286], [64646.5, 0.006], [64646.6, 0.017], [64646.7, 0.004], [64646.9, 0.016], [64647.7, 0.019], [64648.2, 0.002], [64655.4, 0.001], [64660.0, 0.122], [64660.3, 0.041], [64660.6, 0.027], [64660.9, 0.004], [64662.7, 0.613], [64663.3, 0.02], [64664.8, 0.002], [64664.9, 0.003], [64665.0, 0.004], [64665.1, 0.0], [64665.2, 0.002], [64665.3, 0.252], [64665.4, 1.621], [64665.5, 0.002], [64665.6, 0.015], [64665.7, 0.0], [64665.8, 2.321], [64666.0, 0.854], [64666.1, 0.162], [64666.4, 0.015], [64666.7, 0.507], [64667.0, 1.26], [64667.3, 0.422], [64667.4, 0.009], [64670.7, 0.002], [64672.5, 0.846], [64672.7, 0.003], [64673.1, 0.001], [64675.0, 0.987], [64675.1, 1.64], [64675.2, 0.083], [64675.3, 0.003], [64675.9, 0.091]], "asks": [[64683.1, 0.157], [64683.5, 0.286], [64684.8, 0.027], [64684.9, 1.402], [64685.2, 0.01], [64685.3, 0.155], [64685.4, 0.666], [64685.5, 0.713], [64685.9, 0.041], [64686.2, 0.118], [64686.5, 0.257], [64686.6, 0.677], [64686.7, 0.082], [64686.8, 1.004], [64687.0, 0.475], [64687.1, 0.811], [64687.2, 0.007], [64687.3, 0.452], [64687.4, 0.005], [64690.9, 0.159], [64694.4, 0.673], [64698.8, 0.163], [64702.4, 1.228], [64702.7, 0.379], [64702.9, 1.624], [64703.1, 0.716], [64703.4, 2.326], [64703.7, 0.096], [64703.9, 0.003], [64704.1, 0.013], [64704.5, 0.151], [64705.4, 0.158], [64705.5, 0.007], [64705.6, 1.268], [64705.7, 0.008], [64705.8, 0.007], [64705.9, 0.07], [64706.0, 0.389], [64706.1, 0.31], [64706.2, 0.061], [64706.3, 0.004], [64720.0, 0.557], [64720.3, 0.004], [64720.6, 0.028], [64720.9, 0.081], [64721.1, 0.52], [64721.2, 0.157], [64743.7, 0.008], [64755.1, 0.0], [64759.5, 0.442], [64760.3, 0.008], [64764.7, 0.022], [65002.4, 3.538], [65325.8, 3.868], [65478.4, 0.601]]}
{"kind": "depth", "E": 1787095181127, "U": 11316361741864, "u": 11316361746519, "recv_ms": 1787095181200, "bids": [[14378.9, 0.672], [14478.9, 3.486], [14578.9, 0.042], [51743.0, 0.0], [51743.1, 0.0], [58211.0, 0.01], [61444.9, 0.0], [62091.7, 0.692], [63678.9, 1.173], [63686.3, 0.027], [63741.1, 12.786], [63751.0, 0.716], [63753.1, 0.026], [63792.8, 1.876], [64032.1, 4.699], [64064.5, 10.271], [64355.5, 3.813], [64621.9, 0.093], [64631.5, 2.354], [64662.5, 0.006], [64662.7, 0.056], [64663.6, 1.022], [64665.8, 2.421], [64665.9, 1.586], [64666.5, 0.036], [64667.3, 0.422], [64672.5, 0.08], [64672.6, 0.468], [64672.7, 0.003], [64673.1, 0.001], [64675.1, 0.094], [64675.2, 0.624], [64675.3, 0.003], [64675.4, 1.634], [64676.5, 0.011], [64678.6, 0.368], [64678.9, 5.427]], "asks": [[64681.9, 0.002], [64683.5, 0.286], [64684.8, 0.027], [64685.3, 0.042], [64685.5, 0.6], [64686.0, 0.047], [64686.5, 0.257], [64686.7, 0.152], [64686.8, 1.134], [64687.0, 0.476], [64695.0, 0.026], [64702.9, 1.068], [64703.6, 0.047], [64703.9, 0.559], [64705.6, 1.468], [64721.1, 0.562], [64721.2, 0.003], [65002.4, 3.539], [65325.8, 3.868], [65448.7, 8.251], [65604.8, 1.256], [65607.0, 13.622], [65671.7, 11.003], [65679.0, 0.342]]}
{"kind": "depth", "E": 1787095181229, "U": 11316361746531, "u": 11316361751484, "recv_ms": 1787095181298, "bids": [[14378.9, 0.994], [14478.9, 3.206], [14578.9, 0.0], [51743.0, 0.0], [58211.0, 0.01], [61445.0, 0.057], [61445.1, 0.01], [62091.7, 0.689], [63579.4, 6.913], [63666.8, 5.961], [63837.5, 0.207], [64032.1, 4.699], [64537.8, 0.0], [64627.1, 0.1], [64631.8, 4.685], [64632.1, 0.035], [64632.8, 0.032], [64633.6, 0.638], [64655.4, 0.001], [64660.6, 0.027], [64665.3, 0.322], [64665.4, 1.761], [64665.6, 0.085], [64665.9, 1.686], [64666.1, 0.232], [64666.2, 0.326], [64666.8, 0.034], [64667.2, 1.438], [64667.3, 0.422], [64667.8, 0.037], [64670.7, 0.002], [64672.7, 0.003], [64673.1, 0.114], [64675.2, 0.562], [64675.5, 0.064], [64675.6, 0.005], [64678.6, 0.518]], "asks": [[64683.1, 0.157], [64683.9, 0.082], [64684.8, 0.059], [64685.4, 0.704], [64685.5, 0.279], [64685.7, 0.045], [64686.3, 0.091], [64686.4, 0.152], [64686.5, 0.34], [64686.6, 0.797], [64687.0, 0.546], [64687.1, 0.881], [64687.2, 0.077], [64687.3, 0.529], [64690.9, 0.159], [64693.6, 0.806], [64694.4, 0.673], [64698.8, 0.163], [64702.3, 0.496], [64702.9, 1.106], [64703.2, 0.048], [64705.2, 0.122], [64705.4, 0.249], [64705.5, 0.127], [64705.9, 0.14], [64706.0, 0.459], [64706.1, 0.38], [64706.2, 0.138], [64719.8, 0.051], [64720.5, 0.081], [64720.8, 0.044], [64721.0, 0.235], [64721.1, 0.716], [64756.7, 0.049], [64819.0, 0.0], [65325.8, 3.868]]}
{"kind": "depth", "E": 1787095181331, "U": 11316361751508, "u": 11316361756062, "recv_ms": 1787095181402, "bids": [[1000.0, 35.76], [14378.9, 1.344], [14478.9, 2.856], [58211.0, 0.01], [61444.9, 0.0], [62091.7, 0.692], [63385.4, 0.948], [63678.9, 1.153], [63894.2, 0.0], [64032.1, 4.699], [64520.9, 7.517], [64537.9, 4.178], [64632.4, 0.242], [64655.4, 0.156], [64660.6, 0.182], [64665.3, 0.392], [64665.6, 0.185], [64665.7, 0.2], [64666.1, 0.332], [64667.3, 0.577], [64667.5, 0.376], [64670.7, 0.312], [64672.7, 0.003], [64675.5, 0.219], [64676.5, 0.011], [64678.9, 5.428]], "asks": [[64683.1, 0.002], [64684.6, 0.568], [64684.7, 0.001], [64684.8, 0.136], [64685.1, 0.039], [64685.5, 0.279], [64686.4, 0.264], [64686.5, 0.1], [64686.6, 0.241], [64686.7, 0.176], [64686.8, 1.254], [64686.9, 0.294], [64687.1, 1.035], [64687.2, 0.168], [64690.9, 0.004], [64694.4, 0.363], [64698.8, 0.008], [64702.6, 0.039], [64704.0, 0.132], [64704.4, 0.603], [64705.7, 0.128], [64705.8, 0.157], [64706.1, 0.471], [64720.1, 3.285], [64721.1, 0.716], [64819.0, 5.4], [64836.0, 10.438], [64874.8, 5.767], [65325.8, 3.868], [65616.8, 14.839], [65637.1, 18.284], [65679.0, 0.322], [67912.9, 0.035]]}
{"kind": "depth", "E": 1787095181433, "U": 11316361756100, "u": 11316361760286, "recv_ms": 1787095181513, "bids": [[14378.9, 1.694], [14478.9, 2.506], [58211.0, 0.01], [62091.7, 0.689], [63503.0, 0.009], [63676.4, 9.412], [63838.0, 1.47], [63923.3, 1.966], [63966.4, 2.059], [64032.1, 4.699], [64355.5, 3.803], [64574.3, 2.32], [64574.4, 2.399], [64612.7, 0.0], [64613.9, 0.032], [64615.1, 0.024], [64634.2, 0.066], [64642.4, 0.052], [64647.0, 0.001], [64647.1, 0.102], [64647.4, 4.108], [64655.4, 0.001], [64660.6, 0.027], [64665.5, 0.072], [64667.3, 0.422], [64670.7, 0.002], [64672.7, 0.453], [64675.5, 0.485]], "asks": [[64683.1, 0.157], [64683.5, 0.118], [64684.6, 0.02], [64684.8, 0.701], [64685.5, 0.279], [64686.7, 0.314], [64687.1, 1.119], [64687.6, 2.343], [64690.9, 0.159], [64694.4, 0.673], [64698.8, 0.163], [64705.9, 0.224], [64721.1, 0.562], [64721.2, 0.157], [64788.1, 2.319], [64788.2, 0.0], [64794.8, 0.067], [64817.7, 1.23], [64835.9, 2.285], [64874.8, 1.681], [65325.8, 3.868], [65455.1, 20.366], [65972.5, 0.018]]}
{"kind": "depth", "E": 1787095181535, "U": 11316361760394, "u": 11316361764663, "recv_ms": 1787095181607, "bids": [[14378.9, 2.058], [14478.9, 2.142], [51743.0, 0.0], [58211.0, 0.01], [63678.9, 1.173], [63734.7, 0.002], [64032.1, 4.699], [64614.3, 0.035], [64614.6, 0.032], [64614.9, 0.032], [64615.2, 0.032], [64646.6, 0.087], [64646.9, 0.116], [64647.0, 0.071], [64672.7, 0.453], [64673.1, 0.227], [64675.5, 0.485]], "asks": [[64683.5, 0.118], [64684.6, 0.568], [64684.7, 0.001], [64684.8, 0.16], [64685.5, 0.279], [64686.6, 0.241], [64686.7, 0.307], [64687.1, 1.142], [64721.2, 0.157], [65284.6, 3.797], [65325.8, 3.868], [65572.4, 13.553], [65679.0, 0.342]]}
{"kind": "depth", "E": 1787095181637, "U": 11316361764715, "u": 11316361768565, "recv_ms": 1787095181705, "bids": [[1000.0, 35.76], [14378.9, 2.422], [14478.9, 1.778], [58211.0, 0.01], [61444.9, 0.0], [61445.0, 0.055], [61445.1, 0.012], [62091.7, 0.692], [63935.1, 2.342], [64032.1, 4.699], [64520.9, 7.495], [64537.9, 5.242], [64646.4, 0.356], [64646.5, 0.076], [64646.7, 0.074], [64647.0, 0.171], [64647.2, 0.696], [64647.3, 0.084], [64655.4, 0.001], [64660.6, 0.027], [64662.8, 0.676], [64663.6, 0.465], [64667.3, 0.422], [64670.7, 0.002], [64671.8, 0.002], [64672.5, 0.08], [64672.7, 0.003], [64673.1, 0.339], [64673.2, 0.113], [64675.1, 0.627], [64675.2, 0.021], [64675.4, 0.088], [64675.5, 0.064], [64675.6, 0.005], [64675.7, 1.985], [64676.3, 0.087], [64676.5, 0.011], [64678.9, 5.428]], "asks": [[64679.0, 11.169], [64683.1, 0.157], [64683.5, 0.286], [64684.6, 0.02], [64684.7, 0.009], [64684.8, 0.369], [64685.3, 0.042], [64685.5, 0.617], [64686.5, 0.255], [64686.6, 0.256], [64686.7, 0.693], [64690.9, 0.159], [64694.4, 0.673], [64695.2, 0.747], [64698.8, 0.163], [64819.0, 5.4], [64836.0, 10.438], [64874.8, 5.848], [65284.6, 3.263], [65325.8, 3.868], [66616.5, 0.001]]}
{"kind": "depth", "E": 1787095181739, "U": 11316361768615, "u": 11316361773095, "recv_ms": 1787095181813, "bids": [[14378.9, 2.772], [14478.9, 1.428], [51743.0, 0.0], [58211.0, 0.01], [62091.7, 0.689], [63184.4, 0.0], [63514.7, 2.582], [63678.9, 1.153], [64032.1, 4.699], [64355.5, 3.813], [64646.4, 0.426], [64646.6, 0.157], [64646.7, 0.174], [64646.9, 0.216], [64648.2, 0.102], [64648.6, 3.305], [64672.7, 0.003], [64673.1, 0.001], [64673.2, 0.062], [64675.2, 1.567], [64675.3, 0.432], [64675.5, 0.002], [64675.7, 0.01], [64675.8, 0.0], [64675.9, 0.091]], "asks": [[64682.3, 0.433], [64683.5, 0.286], [64684.6, 0.02], [64684.7, 0.234], [64684.8, 1.031], [64685.4, 0.817], [64685.5, 0.713], [64686.6, 0.248], [64686.7, 0.152], [64743.5, 0.043], [64744.2, 0.0], [64874.8, 11.405], [65293.5, 6.261], [65325.8, 3.868], [65466.7, 3.815], [65679.0, 0.322], [67912.9, 0.04]]}
{"kind": "depth", "E": 1787095181841, "U": 11316361773190, "u": 11316361779509, "recv_ms": 1787095181913, "bids": [[1000.0, 35.76], [14378.9, 3.122], [14478.9, 1.078], [58211.0, 0.01], [61733.6, 0.0], [62091.7, 0.692], [63664.7, 3.294], [63734.6, 1.05], [63870.4, 9.057], [64568.9, 0.0], [64633.6, 0.638], [64635.6, 0.004], [64642.4, 0.048]], "asks": [[64683.5, 0.118], [64684.8, 0.918], [64685.3, 0.155], [64685.4, 0.479], [64685.5, 0.375], [64724.3, 0.001], [64743.5, 0.004], [64744.2, 0.039], [64756.7, 0.049], [64799.3, 0.094], [64833.6, 5.407], [65293.5, 6.795], [65325.8, 3.868]]}
{"kind": "depth", "E": 1787095181943, "U": 11316361779751, "u": 11316361785943, "recv_ms": 1787095182011, "bids": [[1000.0, 35.76], [14378.9, 3.486], [14478.9, 0.714], [58211.0, 0.01], [61444.9, 0.0], [62091.7, 0.689], [63678.9, 1.173], [63894.0, 1.406], [64032.1, 4.699], [64537.9, 0.0], [64676.5, 0.011]], "asks": [[64679.0, 11.168], [64683.5, 0.118], [64685.3, 0.155], [64685.4, 0.479], [64721.2, 0.157], [64817.7, 0.003], [64819.0, 0.0], [65002.4, 3.538], [65325.8, 3.868], [65637.1, 16.992], [65679.0, 0.342], [65972.5, 0.015]]}
{"kind": "depth", "E": 1787095182045, "U": 11316361786132, "u": 11316361795876, "recv_ms": 1787095182116, "bids": [[14278.9, 0.056], [14378.9, 3.738], [14478.9, 0.406], [58211.0, 0.01], [63676.4, 10.51], [63965.2, 1.409], [64032.1, 4.699], [64355.5, 3.814], [64534.0, 6.551], [64547.3, 0.016], [64548.9, 1.632], [64563.4, 3.943], [64574.3, 2.32], [64576.7, 0.002], [64576.8, 0.003], [64607.7, 2.451], [64635.6, 0.0], [64642.4, 0.052], [64655.4, 0.001], [64660.6, 0.027], [64667.3, 0.427], [64670.7, 0.002], [64672.7, 0.003], [64673.1, 0.114], [64675.3, 0.011], [64675.4, 0.088], [64675.9, 0.007], [64676.3, 0.003], [64678.9, 5.432]], "asks": [[64683.1, 0.002], [64683.5, 0.273], [64684.7, 0.55], [64684.8, 0.152], [64685.3, 0.042], [64685.4, 0.479], [64685.5, 0.087], [64686.5, 0.1], [64686.7, 0.307], [64687.1, 1.046], [64687.6, 2.324], [64690.9, 0.159], [64694.4, 0.673], [64698.8, 0.163], [64721.2, 0.003], [64721.3, 0.603], [64750.1, 0.049], [64788.1, 2.319], [64809.4, 0.001], [64809.6, 2.227], [64814.2, 0.0], [64814.3, 3.866], [64819.0, 5.4], [64836.0, 10.438], [64874.8, 11.324], [65239.2, 0.002], [65325.8, 3.868], [65477.7, 15.967], [65736.3, 1.063]]}
{"kind": "depth", "E": 1787095182147, "U": 11316361795954, "u": 11316361801633, "recv_ms": 1787095182217, "bids": [[1000.0, 35.76], [14278.9, 0.252], [14378.9, 3.696], [14478.9, 0.252], [51743.1, 0.0], [58211.0, 0.01], [61444.9, 0.0], [61445.1, 0.01], [62091.7, 0.692], [63193.8, 0.001], [63676.4, 11.608], [63678.9, 1.153], [63686.3, 0.017], [63902.8, 23.801], [64032.1, 4.699], [64096.4, 0.0], [64355.5, 3.815], [64520.9, 7.539], [64662.5, 0.006], [64667.3, 0.422], [64672.7, 0.453], [64673.1, 0.339], [64675.2, 1.68], [64675.3, 0.432], [64676.3, 0.003], [64678.2, 0.0], [64678.8, 0.046], [64678.9, 5.432]], "asks": [[64679.0, 11.167], [64682.3, 0.312], [64683.4, 0.168], [64684.6, 0.028], [64684.7, 0.001], [64684.8, 0.144], [64685.3, 0.042], [64685.4, 0.479], [64685.5, 0.279], [64686.5, 0.649], [64695.0, 0.026], [64874.8, 5.694], [65002.4, 3.537], [65325.8, 3.868], [65671.7, 10.993], [65679.0, 0.322], [71146.9, 0.0]]}
{"kind": "depth", "E": 1787095182351, "U": 11316361806312, "u": 11316361810660, "recv_ms": 1787095182420, "bids": [[14278.9, 0.728], [14378.9, 3.458], [14478.9, 0.014], [51743.0, 0.0], [58211.0, 0.01], [60535.7, 0.001], [61444.9, 0.0], [62091.7, 0.692], [63385.4, 0.951], [63678.9, 1.173], [63837.7, 0.031], [63955.9, 5.467], [63973.9, 2.884], [64032.1, 4.699], [64355.5, 3.805], [64568.9, 0.003], [64614.2, 6.562], [64672.7, 0.228], [64673.1, 0.114], [64675.2, 1.567], [64675.3, 0.432], [64678.9, 5.433]], "asks": [[64685.3, 0.042], [64685.5, 0.164], [64724.3, 0.004], [65325.8, 3.87], [65453.5, 1.995], [65671.3, 0.0], [65679.0, 0.342]]}
{"kind": "depth", "E": 1787095182453, "U": 11316361810683, "u": 11316361815229, "recv_ms": 1787095182524, "bids": [[1000.0, 35.76], [14278.9, 1.064], [14378.9, 3.136], [14478.9, 0.0], [58211.0, 0.01], [63611.7, 1.828], [63870.4, 9.291], [64032.1, 4.699], [64096.7, 2.335], [64672.7, 0.003], [64673.1, 0.001], [64675.2, 1.567], [64675.3, 0.011]], "asks": [[64684.8, 0.144], [64685.3, 0.267], [64685.4, 0.704], [64685.5, 0.01], [64686.2, 0.118], [64687.1, 0.931], [64771.2, 0.019], [64814.2, 1.485], [65325.8, 3.868], [65607.0, 12.556], [65671.7, 9.928], [67200.0, 22.152]]}
{"kind": "depth", "E": 1787095182555, "U": 11316361815364, "u": 11316361821165, "recv_ms": 1787095182627, "bids": [[1000.0, 35.76], [14278.9, 1.428], [14378.9, 2.772], [58211.0, 0.01], [61445.0, 0.053], [61445.1, 0.012], [62091.7, 0.689], [62997.2, 0.0], [63678.9, 1.153], [63725.3, 0.0], [64032.1, 4.699], [64404.9, 0.132], [64483.3, 0.019], [64624.7, 0.003], [64625.5, 0.003], [64632.5, 6.341], [64633.2, 3.332], [64671.8, 0.086], [64672.5, 0.08], [64672.6, 0.468], [64672.7, 0.003], [64673.1, 0.001], [64675.0, 1.528], [64675.1, 0.086], [64675.2, 1.567], [64675.3, 0.011], [64675.4, 0.004], [64676.3, 0.003]], "asks": [[64683.9, 0.005], [64684.8, 0.369], [64685.3, 0.267], [64685.4, 0.479], [64685.5, 0.003], [64687.0, 0.565], [64687.1, 0.777], [64690.3, 0.784], [64771.2, 0.096], [64874.8, 1.677], [65194.8, 4.745], [65325.8, 3.868], [65455.1, 21.128], [65679.0, 0.322]]}
{"kind": "depth", "E": 1787095182657, "U": 11316361821227, "u": 11316361826351, "recv_ms": 1787095182729, "bids": [[14278.9, 1.778], [14378.9, 2.422], [51743.0, 0.0], [58211.0, 0.01], [60851.6, 0.0], [61444.9, 0.0], [62091.7, 0.692], [63678.9, 1.173], [63729.3, 4.168], [63838.0, 2.564], [63925.5, 4.14], [64032.1, 4.701], [64355.5, 3.805], [64625.4, 0.002], [64642.6, 0.056], [64655.4, 0.156], [64660.6, 0.182], [64667.3, 0.577], [64670.7, 0.312], [64671.9, 0.003], [64672.5, 0.621], [64672.7, 0.003], [64675.0, 0.987], [64675.3, 0.011], [64675.4, 0.159], [64678.9, 5.433]], "asks": [[64679.0, 11.25], [64680.7, 0.087], [64683.5, 0.118], [64684.7, 0.078], [64684.8, 0.292], [64685.5, 0.08], [64686.2, 0.118], [64686.7, 0.152], [64687.1, 0.77], [64690.3, 0.707], [64690.9, 0.004], [64694.4, 0.363], [64698.8, 0.008], [64720.4, 3.278], [64743.5, 0.043], [64744.2, 0.0], [64771.2, 0.211], [65325.8, 3.868], [65616.8, 15.905], [65679.0, 0.342], [65680.2, 4.104]]}
{"kind": "depth", "E": 1787095182759, "U": 11316361826352, "u": 11316361832888, "recv_ms": 1787095182828, "bids": [[1000.0, 35.76], [14278.9, 2.142], [14378.9, 2.058], [58211.0, 0.01], [62091.7, 0.689], [63733.9, 4.556], [64032.1, 4.699], [64633.8, 0.018], [64655.4, 0.001], [64660.6, 0.027], [64667.3, 0.422], [64670.7, 0.002], [64671.5, 1.748], [64672.6, 0.468], [64672.7, 0.003], [64673.2, 0.0], [64674.8, 0.084], [64675.1, 1.548], [64675.2, 0.083], [64675.4, 0.004], [64676.3, 0.003], [64678.6, 0.239]], "asks": [[64680.7, 0.084], [64683.1, 0.157], [64683.4, 0.0], [64683.5, 0.286], [64683.9, 0.118], [64684.8, 0.292], [64685.2, 0.235], [64685.3, 0.492], [64685.4, 0.704], [64685.5, 0.164], [64686.2, 0.273], [64690.3, 0.803], [64690.9, 0.159], [64694.4, 0.673], [64698.8, 0.163], [64743.5, 0.004], [64744.2, 0.039], [64874.8, 5.265], [65325.8, 3.868], [65487.5, 5.74], [65681.5, 5.322], [67912.9, 0.045]]}
{"kind": "depth", "E": 1787095182861, "U": 11316361833033, "u": 11316361837955, "recv_ms": 1787095182930, "bids": [[1000.0, 35.76], [14278.9, 2.492], [14378.9, 1.708], [58211.0, 0.01], [61444.9, 0.0], [62091.7, 0.692], [63666.8, 4.863], [63731.5, 16.233], [63925.5, 3.203], [63935.1, 3.279], [64032.1, 4.699], [64672.5, 0.312], [64673.0, 0.001], [64675.0, 1.528]], "asks": [[64679.0, 11.249], [64681.1, 0.088], [64682.1, 0.083], [64682.2, 0.177], [64682.3, 0.52], [64682.7, 0.007], [64683.4, 0.338], [64683.5, 0.511], [64683.9, 0.455], [64684.6, 0.47], [64684.7, 0.339], [64684.8, 0.059], [64685.2, 0.01], [64685.3, 0.042], [64685.4, 0.479], [64685.5, 0.087], [64686.3, 0.099], [64686.7, 0.778], [64697.5, 0.092], [64720.4, 3.334], [64742.8, 0.043], [64744.2, 0.0], [65196.4, 3.366], [65325.8, 3.868]]}
{"kind": "depth", "E": 1787095182963, "U": 11316361838203, "u": 11316361843315, "recv_ms": 1787095183032, "bids": [[14278.9, 2.856], [14378.9, 1.344], [58211.0, 0.01], [63678.9, 1.153], [63741.1, 13.726], [63902.8, 24.8], [64032.1, 4.699], [64355.5, 3.815], [64655.4, 0.001], [64660.6, 0.027], [64667.3, 0.422], [64670.7, 0.002], [64672.5, 0.418], [64672.7, 0.116], [64673.0, 0.233], [64675.2, 0.504], [64678.9, 5.43]], "asks": [[64681.1, 0.085], [64681.5, 0.087], [64682.2, 0.009], [64683.1, 0.157], [64683.3, 0.31], [64683.4, 0.0], [64683.5, 0.118], [64683.9, 0.005], [64684.6, 0.02], [64684.7, 0.001], [64684.8, 0.059], [64685.3, 0.042], [64686.2, 0.118], [64686.6, 0.403], [64690.9, 0.159], [64694.4, 0.673], [64698.8, 0.163], [64742.8, 0.004], [64743.4, 0.066], [65325.8, 3.868], [65478.4, 0.342], [65679.0, 0.322]]}
{"kind": "depth", "E": 1787095183065, "U": 11316361843407, "u": 11316361848496, "recv_ms": 1787095183134, "bids": [[1000.0, 35.76], [14278.9, 3.206], [14378.9, 0.994], [58211.0, 0.01], [61444.9, 0.0], [62091.7, 0.689], [63491.0, 0.027], [63676.4, 12.706], [63741.1, 14.823], [63935.1, 4.216], [64032.1, 4.699], [64355.5, 3.814], [64515.5, 7.478], [64520.9, 0.39], [64534.1, 8.061], [64537.9, 0.0], [64568.9, 0.003], [64611.6, 0.0], [64633.6, 0.635], [64655.4, 0.001], [64660.6, 0.027], [64667.3, 0.422], [64670.7, 0.002], [64672.5, 0.418], [64672.7, 0.116], [64675.1, 0.002], [64675.2, 0.021], [64675.3, 0.011], [64675.4, 0.004], [64675.5, 0.064], [64675.6, 1.972], [64676.3, 0.003], [64678.6, 0.449], [64678.9, 5.431]], "asks": [[64682.1, 0.003], [64682.2, 0.164], [64682.3, 0.395], [64683.1, 0.002], [64683.3, 0.085], [64683.9, 0.173], [64685.3, 0.042], [64685.4, 0.704], [64685.5, 0.312], [64686.6, 0.403], [64688.0, 1.605], [64690.9, 0.159], [64694.4, 0.673], [64698.8, 0.163], [64707.9, 0.004], [64708.0, 1.265], [64708.1, 0.005], [64710.9, 0.007], [64711.0, 0.502], [64711.1, 3.261], [64711.8, 0.003], [64711.9, 0.043], [64712.0, 1.393], [64713.9, 0.0], [64714.0, 0.481], [64714.1, 0.029], [64724.3, 0.004], [64743.4, 0.027], [64744.7, 0.044], [64756.7, 0.046], [64819.0, 5.4], [64835.9, 1.372], [64836.0, 10.438], [64874.8, 4.055], [65325.8, 3.868], [68482.5, 0.0]]}
{"kind": "depth", "E": 1787095183167, "U": 11316361848532, "u": 11316361854881, "recv_ms": 1787095183236, "bids": [[1000.0, 35.76], [14278.9, 3.57], [14378.9, 0.63], [51743.1, 0.0], [58211.0, 0.01], [61445.0, 0.051], [61445.1, 0.014], [62091.7, 0.692], [63678.9, 1.173], [64032.1, 4.699], [64355.5, 3.813], [64516.9, 2.109], [64521.2, 2.395], [64635.6, 0.004], [64642.4, 0.048], [64642.6, 0.014], [64655.4, 0.001], [64660.3, 0.001], [64660.6, 0.027], [64662.5, 0.006], [64667.3, 0.422], [64667.8, 0.077], [64670.7, 0.002], [64672.5, 0.53], [64672.7, 0.228], [64672.9, 0.147], [64675.1, 0.002], [64675.2, 1.567], [64675.3, 0.432], [64675.5, 0.086], [64675.6, 0.005], [64675.7, 0.01], [64675.8, 0.0], [64675.9, 0.007], [64678.9, 5.432]], "asks": [[64682.2, 0.009], [64683.1, 0.157], [64684.8, 0.685], [64685.5, 0.581], [64686.6, 0.403], [64686.7, 0.152], [64687.1, 0.777], [64690.9, 0.159], [64694.4, 0.673], [64695.0, 0.026], [64698.8, 0.163], [64744.2, 0.039], [64744.7, 0.005], [64819.0, 4.015], [64836.0, 5.678], [64874.8, 1.437], [65002.4, 3.538], [65325.8, 3.868], [65679.0, 0.342], [65972.5, 0.018]]}
{"kind": "depth", "E": 1787095183269, "U": 11316361855012, "u": 11316361859627, "recv_ms": 1787095183338, "bids": [[14178.9, 0.084], [14278.9, 3.766], [14378.9, 0.35], [51743.0, 0.0], [58211.0, 0.01], [61444.9, 0.0], [61445.1, 0.012], [62091.7, 0.689], [63861.6, 0.023], [64032.1, 4.699], [64355.5, 3.813], [64476.8, 5.085], [64482.1, 0.009], [64515.5, 0.0], [64515.6, 3.778], [64532.6, 2.405], [64534.1, 3.034], [64672.5, 0.08], [64672.7, 0.003], [64675.3, 0.011], [64676.3, 0.003], [64678.9, 5.432]], "asks": [[64682.2, 0.092], [64682.3, 0.576], [64683.2, 0.159], [64683.5, 0.118], [64683.9, 0.005], [64684.0, 0.431], [64684.5, 0.027], [64684.6, 0.245], [64684.7, 0.451], [64684.8, 0.91], [64685.3, 0.042], [64685.4, 0.479], [64685.5, 0.087], [64686.3, 0.091], [64686.5, 0.1], [64686.6, 0.396], [64687.1, 0.931], [64819.0, 5.4], [64836.0, 10.438], [64874.8, 15.414], [65002.4, 3.539], [65325.8, 3.868], [65443.1, 14.278]]}
{"kind": "depth", "E": 1787095183371, "U": 11316361859681, "u": 11316361865756, "recv_ms": 1787095183444, "bids": [[1000.0, 35.76], [14178.9, 0.308], [14278.9, 3.668], [14378.9, 0.224], [51743.0, 0.0], [58211.0, 0.01], [62091.7, 0.692], [63050.1, 0.0], [63678.9, 1.153], [64032.1, 4.699], [64403.3, 0.054], [64476.8, 13.96], [64479.1, 5.481], [64515.6, 7.836], [64532.6, 5.062], [64617.4, 2.725], [64617.5, 0.088], [64655.4, 0.001], [64660.6, 0.027], [64667.3, 0.422], [64670.7, 0.002], [64671.5, 1.664], [64672.5, 0.305], [64675.3, 0.432], [64675.9, 0.091], [64678.9, 5.431]], "asks": [[64681.9, 0.002], [64682.2, 0.009], [64682.3, 0.312], [64682.7, 0.162], [64682.8, 0.217], [64682.9, 0.052], [64683.1, 0.002], [64683.2, 0.157], [64683.5, 0.118], [64683.7, 0.005], [64684.4, 0.003], [64684.5, 0.004], [64684.6, 0.02], [64684.7, 0.001], [64684.8, 0.144], [64685.3, 0.042], [64685.4, 0.704], [64685.5, 0.087], [64686.4, 0.411], [64686.5, 0.672], [64686.6, 0.241], [64690.9, 0.159], [64694.4, 0.673], [64698.8, 0.163], [64742.9, 5.153], [64743.2, 0.235], [64867.3, 0.007], [64867.4, 0.015], [64867.9, 0.009], [64874.8, 4.543], [65325.8, 3.868], [65584.5, 20.984], [65615.1, 1.065], [65679.0, 0.322]]}
{"kind": "depth", "E": 1787095183473, "U": 11316361865810, "u": 11316361871632, "recv_ms": 1787095183542, "bids": [[1000.0, 35.76], [14178.9, 0.546], [14278.9, 3.542], [14378.9, 0.112], [58211.0, 0.01], [61444.9, 0.0], [64032.1, 4.701], [64655.4, 0.156], [64660.6, 0.182], [64667.3, 0.577], [64670.5, 1.159], [64670.6, 1.312], [64670.7, 0.312], [64672.5, 0.08], [64675.3, 0.432], [64675.4, 0.159], [64678.9, 5.432]], "asks": [[64682.7, 0.007], [64683.9, 0.173], [64684.8, 0.067], [64685.4, 0.479], [64685.5, 0.312], [64686.3, 0.709], [64686.4, 0.256], [64686.5, 0.131], [64687.1, 0.854], [64690.9, 0.004], [64691.0, 1.571], [64692.0, 3.31], [64694.4, 0.363], [64698.8, 0.008], [64744.0, 1.301], [64744.2, 0.0], [64817.7, 1.23], [64819.0, 5.4], [64836.0, 10.438], [64874.8, 5.48], [65325.8, 3.868], [65477.7, 15.709], [65649.3, 8.445], [67912.9, 0.05]]}
{"kind": "depth", "E": 1787095183575, "U": 11316361871634, "u": 11316361877739, "recv_ms": 1787095183643, "bids": [[14178.9, 0.798], [14278.9, 3.402], [14378.9, 0.0], [58211.0, 0.01], [61444.9, 0.0], [62091.7, 0.689], [63050.5, 2.297], [63678.9, 1.173], [64032.1, 4.699], [64355.5, 3.813], [64655.4, 0.001], [64660.6, 0.027], [64667.3, 0.422], [64670.7, 0.002], [64672.5, 0.08], [64675.3, 0.011], [64675.4, 0.004], [64675.9, 0.007], [64676.3, 0.003], [64678.9, 5.433]], "asks": [[64679.0, 11.267], [64682.7, 0.162], [64684.8, 0.144], [64685.4, 0.592], [64686.2, 0.273], [64686.3, 0.632], [64690.9, 0.159], [64694.4, 0.673], [64698.8, 0.163], [64744.0, 1.262], [64744.7, 0.044], [64819.0, 5.4], [64836.0, 10.438], [64874.8, 7.375], [65325.8, 3.868], [65679.0, 0.342]]}
{"kind": "depth", "E": 1787095183677, "U": 11316361877895, "u": 11316361883339, "recv_ms": 1787095183746, "bids": [[1000.0, 35.76], [14178.9, 1.162], [14278.9, 3.038], [58211.0, 0.01], [62091.7, 0.692], [63186.3, 0.636], [63771.2, 0.945], [64655.4, 0.001], [64660.0, 0.122], [64660.6, 0.027], [64661.6, 0.029], [64662.7, 0.613], [64662.8, 0.119], [64663.4, 0.001], [64664.2, 0.605], [64666.6, 1.256], [64666.7, 0.048], [64667.3, 0.422], [64667.4, 0.009], [64668.2, 0.005], [64670.7, 0.002], [64672.5, 0.08], [64672.7, 0.003], [64672.8, 0.0], [64673.1, 0.226], [64675.0, 0.987], [64675.1, 0.543], [64675.3, 0.011], [64676.1, 0.084], [64676.2, 0.003]], "asks": [[64682.7, 0.162], [64683.0, 0.011], [64686.2, 0.273], [64690.9, 0.159], [64694.4, 0.673], [64698.8, 0.163], [64699.1, 0.001], [64699.9, 10.42], [64700.0, 3.781], [64700.7, 1.626], [64702.8, 0.001], [64702.9, 1.106], [64703.6, 0.047], [64703.8, 0.167], [64703.9, 0.559], [64704.4, 0.718], [64704.7, 0.003], [64743.3, 0.043], [64744.7, 0.005], [64817.7, 0.003], [64819.0, 5.4], [64836.0, 10.438], [64874.8, 4.221], [65139.8, 3.091], [65325.8, 3.868], [65477.7, 15.451], [65616.8, 16.97], [65972.5, 0.021]]}
{"kind": "depth", "E": 1787095183779, "U": 11316361883386, "u": 11316361888141, "recv_ms": 1787095183847, "bids": [[1000.0, 35.76], [14178.9, 1.512], [14278.9, 2.688], [58211.0, 0.01], [61444.9, 0.0], [62091.7, 0.689], [63642.5, 1.098], [63678.9, 1.153], [63933.5, 2.812], [64032.1, 4.7], [64642.6, 0.056], [64655.4, 0.001], [64660.6, 0.027], [64667.3, 0.422], [64670.7, 0.002], [64673.1, 0.001], [64675.3, 0.011], [64675.5, 0.002], [64676.1, 0.0], [64676.3, 0.003], [64678.9, 5.422]], "asks": [[64679.0, 11.268], [64681.2, 0.015], [64681.9, 0.012], [64682.2, 0.402], [64682.3, 0.55], [64682.6, 0.005], [64682.7, 0.007], [64682.8, 0.134], [64683.3, 0.465], [64683.4, 0.45], [64683.5, 0.456], [64683.8, 0.453], [64683.9, 0.398], [64684.6, 0.02], [64684.7, 0.001], [64684.8, 0.059], [64685.3, 0.042], [64685.4, 0.479], [64685.5, 0.003], [64686.2, 0.118], [64686.3, 0.091], [64686.5, 0.123], [64686.7, 0.941], [64687.1, 0.693], [64690.3, 0.438], [64690.9, 0.159], [64693.6, 0.71], [64694.4, 0.673], [64698.8, 0.008], [64699.1, 0.156], [64720.4, 3.278], [64733.4, 0.0], [64736.0, 0.001], [64743.3, 0.004], [64744.0, 1.301], [64771.2, 0.372], [64819.0, 5.4], [64836.0, 10.438], [64874.8, 5.169], [65325.8, 3.868], [65487.5, 6.082], [65679.0, 0.322], [65712.2, 0.017]]}
{"kind": "depth", "E": 1787095183881, "U": 11316361888217, "u": 11316361892610, "recv_ms": 1787095183950, "bids": [[14178.9, 1.862], [14278.9, 2.338], [51743.0, 0.0], [58211.0, 0.01], [61444.9, 0.0], [63191.3, 0.79], [63256.0, 0.903], [63933.5, 1.875], [64032.1, 4.7], [64055.7, 0.0], [64355.5, 3.813], [64515.6, 0.419], [64515.7, 7.593], [64655.4, 0.001], [64660.0, 0.006], [64660.6, 0.027], [64660.9, 0.12], [64662.7, 0.056], [64663.4, 0.558], [64667.3, 0.422], [64670.7, 0.002], [64672.7, 0.003], [64672.9, 0.085], [64673.1, 0.001], [64675.3, 0.011], [64675.4, 0.066], [64678.9, 5.425]], "asks": [[64682.2, 0.009], [64682.3, 0.312], [64683.0, 0.094], [64683.1, 0.157], [64683.3, 0.085], [64683.4, 0.0], [64683.5, 0.118], [64683.8, 0.003], [64683.9, 0.173], [64685.3, 0.042], [64685.4, 0.704], [64685.5, 0.228], [64686.6, 0.396], [64686.7, 0.786], [64687.1, 0.616], [64690.3, 0.431], [64690.9, 0.159], [64693.6, 0.595], [64694.4, 0.673], [64699.1, 0.156], [64736.0, 0.028], [64738.8, 0.077], [64743.4, 0.066], [64744.0, 1.262], [64874.8, 4.224], [65325.8, 3.868], [65769.6, 0.001]]}
{"kind": "depth", "E": 1787095183983, "U": 11316361892793, "u": 11316361896828, "recv_ms": 1787095184052, "bids": [[1000.0, 35.76], [14178.9, 2.226], [14278.9, 1.974], [58211.0, 0.01], [62091.7, 0.692], [63256.0, 0.9], [63644.0, 6.506], [63678.9, 1.173], [63779.9, 11.766], [63826.5, 2.346], [63846.7, 0.0], [63935.1, 5.153], [64032.1, 4.7], [64655.4, 0.156], [64660.6, 0.182], [64667.3, 0.577], [64670.7, 0.312], [64672.7, 0.453], [64673.1, 0.339], [64675.2, 1.68], [64675.3, 0.587]], "asks": [[64683.1, 0.002], [64683.9, 0.173], [64686.6, 0.241], [64690.3, 0.438], [64690.9, 0.004], [64693.6, 0.71], [64694.4, 0.363], [64699.1, 0.001], [64743.4, 0.027], [64744.2, 0.039], [65325.8, 3.868], [65679.0, 0.342], [65959.6, 0.607]]}
{"kind": "depth", "E": 1787095184085, "U": 11316361896899, "u": 11316361902140, "recv_ms": 1787095184154, "bids": [[1000.0, 35.76], [14178.9, 2.576], [14278.9, 1.624], [51743.0, 0.0], [58211.0, 0.01], [61444.9, 0.0], [62091.7, 0.689], [63644.0, 7.605], [63935.1, 6.089], [64032.1, 4.7], [64064.5, 10.893], [64355.5, 3.813], [64515.6, 7.866], [64515.7, 0.128], [64642.6, 0.056], [64655.4, 0.001], [64660.6, 0.027], [64667.3, 0.422], [64670.7, 0.002], [64672.7, 0.453], [64673.1, 0.451], [64675.2, 1.68], [64675.3, 0.432], [64676.3, 0.003], [64678.9, 5.428]], "asks": [[64681.2, 0.005], [64681.9, 0.002], [64683.1, 0.157], [64683.9, 0.005], [64686.6, 0.396], [64690.9, 0.159], [64693.6, 0.787], [64694.4, 0.673], [64695.2, 0.727], [64699.1, 0.156], [64742.4, 0.051], [64744.2, 0.0], [64819.0, 5.4], [64836.0, 10.438], [64874.8, 4.519], [65478.4, 0.0], [65713.9, 4.257], [67912.9, 0.055]]}
{"kind": "depth", "E": 1787095184187, "U": 11316361902201, "u": 11316361909603, "recv_ms": 1787095184255, "bids": [[14178.9, 2.94], [14278.9, 1.26], [51743.0, 0.0], [51743.1, 0.0], [58211.0, 0.01], [61444.9, 0.0], [62091.7, 0.692], [63580.8, 0.627], [63678.9, 1.153], [63879.0, 4.09], [64032.1, 4.7], [64355.5, 3.814], [64662.5, 0.006], [64672.7, 0.453], [64673.1, 0.227], [64675.2, 1.68], [64675.3, 0.432]], "asks": [[64679.0, 11.27], [64683.9, 0.173], [64684.8, 0.059], [64685.4, 0.592], [64685.5, 0.305], [64687.3, 0.487], [64690.3, 0.707], [64693.6, 0.806], [64695.0, 0.026], [64695.2, 0.747], [64742.4, 0.012], [64743.3, 0.043], [64819.0, 5.4], [64836.0, 10.438], [64874.8, 6.634], [65002.4, 3.538], [65284.6, 2.27], [65325.8, 3.868], [65588.3, 0.0], [65604.8, 0.495], [65623.4, 0.155], [65679.0, 0.322]]}
{"kind": "depth", "E": 1787095184289, "U": 11316361909730, "u": 11316361915355, "recv_ms": 1787095184358, "bids": [[1000.0, 35.76], [14178.9, 3.304], [14278.9, 0.896], [51743.0, 0.0], [58211.0, 0.01], [61444.9, 0.0], [62091.7, 0.689], [64032.1, 4.7], [64515.6, 0.419], [64515.7, 7.573], [64604.5, 0.015], [64633.6, 0.638], [64637.8, 0.025], [64646.2, 0.007], [64655.4, 0.156], [64660.6, 0.182], [64667.3, 0.577], [64670.7, 0.312], [64671.1, 0.086], [64671.5, 1.748], [64672.7, 0.003], [64673.1, 0.451], [64674.4, 0.003], [64674.8, 0.0], [64675.2, 1.567], [64675.3, 0.011], [64675.4, 0.221], [64675.5, 0.423], [64676.3, 0.003], [64678.9, 5.424]], "asks": [[64679.0, 11.273], [64681.9, 0.012], [64682.7, 0.017], [64683.1, 0.002], [64683.9, 0.005], [64685.5, 0.53], [64686.6, 0.241], [64687.0, 0.564], [64690.3, 0.784], [64690.9, 0.004], [64693.6, 0.787], [64694.4, 0.363], [64699.1, 0.001], [64707.9, 0.006], [64708.0, 1.267], [64708.1, 0.007], [64710.9, 0.009], [64711.0, 0.504], [64711.1, 3.263], [64711.8, 0.005], [64711.9, 0.045], [64712.0, 1.395], [64713.9, 0.002], [64714.0, 0.483], [64714.1, 0.031], [64743.3, 0.004], [64744.2, 0.039], [64756.7, 0.049], [64874.8, 4.522], [65002.4, 3.537], [65194.8, 0.917], [65325.8, 3.868]]}
{"kind": "depth", "E": 1787095184391, "U": 11316361915379, "u": 11316361920459, "recv_ms": 1787095184462, "bids": [[1000.0, 35.76], [14178.9, 3.654], [14278.9, 0.546], [58211.0, 0.01], [60862.8, 1.641], [63678.9, 1.173], [63739.5, 5.94], [63933.5, 0.938], [64032.1, 4.7], [64355.5, 3.815], [64568.9, 0.0], [64633.6, 0.635], [64642.6, 0.014], [64645.2, 0.092], [64655.4, 0.001], [64660.6, 0.027], [64663.4, 0.558], [64664.3, 0.079], [64666.6, 0.797], [64667.3, 0.881], [64668.3, 0.001], [64670.7, 0.002], [64671.6, 0.187], [64672.1, 0.01], [64672.5, 0.003], [64672.6, 0.468], [64672.7, 0.065], [64673.1, 0.001], [64674.3, 0.085], [64675.0, 1.528], [64675.1, 1.548], [64675.2, 0.029], [64675.3, 0.003], [64675.4, 0.004], [64675.5, 0.002], [64675.6, 0.005], [64675.7, 0.01], [64675.8, 0.0], [64678.6, 0.239]], "asks": [[64679.0, 12.422], [64683.1, 0.157], [64683.5, 0.343], [64683.9, 0.23], [64684.7, 0.775], [64684.8, 0.594], [64685.3, 0.267], [64685.4, 0.479], [64685.5, 0.277], [64686.5, 0.123], [64686.6, 0.396], [64686.7, 0.152], [64687.1, 0.77], [64690.3, 0.803], [64690.9, 0.159], [64693.6, 0.806], [64694.4, 0.673], [64699.1, 0.156], [64699.9, 0.42], [64700.0, 3.322], [64700.7, 2.085], [64703.9, 0.003], [64704.7, 0.559], [64714.6, 0.0], [64724.3, 0.001], [64738.8, 0.0], [64743.4, 0.066], [64744.2, 0.0], [64756.7, 0.046], [64819.0, 5.4], [64836.0, 10.438], [64874.8, 4.523], [65325.8, 3.868], [65453.5, 1.537], [65615.2, 2.132], [65616.8, 17.731], [65623.3, 0.684], [65679.0, 0.342], [65679.9, 2.133], [66068.6, 0.022]]}
{"kind": "depth", "E": 1787095184493, "U": 11316361920479, "u": 11316361927164, "recv_ms": 1787095184561, "bids": [[14178.9, 3.752], [14278.9, 0.322], [14578.9, 0.126], [58211.0, 0.01], [61444.9, 0.0], [62091.7, 0.692], [63674.8, 1.097], [63739.5, 4.843], [63933.5, 0.001], [64032.1, 4.7], [64626.5, 1.537], [64637.8, 0.025], [64642.6, 0.042], [64645.2, 0.71], [64658.1, 1.229], [64665.4, 1.143], [64672.5, 0.544], [64672.6, 0.468], [64672.7, 0.291], [64675.0, 0.987], [64675.2, 0.029], [64676.3, 0.003], [64678.9, 5.425]], "asks": [[64679.0, 12.803], [64681.9, 0.095], [64682.2, 0.009], [64682.3, 0.312], [64682.4, 0.087], [64683.0, 0.011], [64683.5, 0.118], [64683.7, 0.003], [64683.8, 0.003], [64683.9, 0.005], [64684.5, 0.004], [64684.6, 0.02], [64684.7, 0.001], [64684.8, 0.144], [64685.3, 0.267], [64685.5, 0.164], [64686.3, 0.64], [64686.5, 0.123], [64687.9, 0.032], [64700.0, 3.32], [64700.8, 10.012], [64724.2, 0.268], [64743.4, 0.027], [64744.2, 0.039], [64817.7, 1.006], [64819.0, 5.4], [64835.9, 2.217], [64836.0, 10.438], [64868.0, 1.022], [64874.8, 5.133], [65196.4, 7.194], [65249.1, 0.306], [65293.5, 7.788], [65325.8, 5.167], [65572.4, 11.268], [65615.2, 1.067], [65679.9, 1.069], [65681.5, 6.385], [65736.3, 0.0], [65746.2, 3.19], [67912.9, 0.06]]}
{"kind": "depth", "E": 1787095184595, "U": 11316361927329, "u": 11316361932715, "recv_ms": 1787095184701, "bids": [[1000.0, 35.76], [14178.9, 3.64], [14278.9, 0.196], [14578.9, 0.364], [58211.0, 0.01], [61444.9, 0.0], [62091.7, 0.689], [63678.9, 1.153], [63741.1, 15.92], [63935.1, 7.026], [64032.1, 4.7], [64672.6, 0.468], [64672.7, 0.178], [64674.6, 0.32], [64675.2, 0.029], [64678.9, 5.423]], "asks": [[64680.2, 0.395], [64681.3, 0.1], [64681.5, 0.089], [64681.9, 0.012], [64682.4, 0.085], [64683.5, 0.286], [64684.8, 0.144], [64685.2, 0.01], [64685.4, 0.592], [64685.5, 0.164], [64686.2, 0.118], [64687.1, 0.693], [64695.2, 0.693], [65000.8, 0.308], [65261.1, 4.757], [65325.8, 5.167], [65616.8, 18.796], [65679.0, 0.322], [67189.1, 0.743]]}
{"kind": "depth", "E": 1787095184697, "U": 11316361932832, "u": 11316361938294, "recv_ms": 1787095184842, "bids": [[1000.0, 35.76], [14178.9, 3.514], [14278.9, 0.084], [14578.9, 0.602], [58211.0, 0.01], [61444.9, 0.0], [62091.7, 0.692], [63676.4, 13.804], [63741.1, 17.017], [63860.8, 15.434], [63935.1, 7.963], [64032.1, 4.7], [64159.9, 0.621], [64353.9, 0.465], [64355.5, 3.815], [64671.6, 0.11], [64672.5, 0.193], [64672.6, 0.468], [64672.7, 0.003], [64674.9, 2.408], [64675.1, 2.089], [64675.2, 0.512], [64676.3, 0.003], [64678.9, 6.357]], "asks": [[64680.2, 0.085], [64681.3, 0.017], [64681.5, 0.087], [64681.9, 0.095], [64682.0, 0.196], [64683.5, 0.286], [64684.8, 0.144], [64685.4, 0.592], [64685.5, 0.614], [64686.0, 0.067], [64686.2, 0.118], [64687.0, 0.563], [64687.1, 0.67], [64695.2, 0.13], [64743.5, 0.043], [64744.2, 0.0], [64819.0, 5.4], [64835.9, 1.372], [64836.0, 10.438], [64874.8, 4.528], [65000.8, 0.154], [65194.8, 0.611], [65236.6, 0.006], [65325.8, 5.167], [65455.1, 21.586], [65478.3, 0.586], [65487.5, 6.341], [65615.2, 0.001], [65616.8, 19.861], [65679.9, 0.004], [65681.5, 7.449], [71146.9, 0.002]]}
{"kind": "depth", "E": 1787095184799, "U": 11316361938406, "u": 11316361943748, "recv_ms": 1787095184884, "bids": [[14178.9, 3.318], [14278.9, 0.0], [14578.9, 0.882], [58211.0, 0.01], [61444.9, 0.0], [61445.1, 0.01], [62091.7, 0.689], [63385.4, 0.954], [63678.9, 1.173], [64032.1, 4.699], [64353.9, 0.31], [64532.6, 0.004], [64655.4, 0.001], [64660.6, 0.027], [64667.4, 0.009], [64670.7, 0.002], [64671.1, 0.002], [64672.5, 0.08], [64675.2, 0.512], [64675.3, 0.087], [64678.9, 6.361]], "asks": [[64683.1, 0.157], [64683.5, 0.118], [64685.3, 0.042], [64685.4, 0.479], [64685.5, 0.157], [64686.2, 0.273], [64686.6, 0.241], [64690.3, 0.784], [64690.9, 0.159], [64694.4, 0.518], [64697.7, 0.196], [64699.1, 0.156], [64743.4, 0.066], [64743.5, 0.004], [64817.7, 0.003], [64819.0, 0.0], [65000.8, 0.0], [65002.4, 3.691], [65194.8, 0.306], [65325.8, 5.167], [65679.0, 0.342], [68495.1, 3.644], [71146.9, 0.0]]}
{"kind": "depth", "E": 1787095184901, "U": 11316361943948, "u": 11316361948438, "recv_ms": 1787095184969, "bids": [[1000.0, 35.76], [14178.9, 2.982], [14578.9, 1.218], [58211.0, 0.01], [63503.1, 1.573], [63610.1, 1.112], [64032.1, 4.699], [64532.9, 5.04], [64641.7, 0.287], [64642.6, 0.014], [64655.4, 0.001], [64660.6, 0.027], [64663.4, 0.558], [64664.3, 0.079], [64667.4, 0.009], [64670.7, 0.002], [64672.5, 0.621], [64675.1, 1.548], [64675.2, 0.091], [64678.9, 6.362]], "asks": [[64683.1, 0.157], [64683.9, 0.173], [64684.7, 0.001], [64684.8, 0.059], [64685.4, 0.592], [64685.5, 0.382], [64686.1, 0.002], [64686.2, 0.358], [64690.9, 0.159], [64694.4, 0.518], [64697.7, 0.196], [64699.1, 0.156], [64703.5, 0.748], [64703.6, 0.603], [64704.4, 0.603], [64704.7, 0.003], [64743.4, 0.027], [64744.7, 0.044], [64819.0, 3.922], [64836.0, 5.569], [64874.8, 1.429], [65194.8, 0.0], [65241.7, 0.289], [65325.8, 5.167], [65607.0, 11.49], [65744.6, 0.007], [65972.5, 0.018]]}
{"kind": "depth", "E": 1787095185003, "U": 11316361948489, "u": 11316361953565, "recv_ms": 1787095185073, "bids": [[1000.0, 35.76], [14178.9, 2.604], [14578.9, 1.596], [58211.0, 0.01], [61444.9, 0.0], [62091.7, 0.692], [63611.7, 2.927], [63678.9, 1.153], [63771.2, 0.006], [64032.1, 4.699], [64161.5, 5.123], [64355.5, 3.96], [64563.4, 0.078], [64563.5, 3.865], [64607.7, 2.451], [64645.2, 0.092], [64655.4, 0.156], [64660.6, 0.182], [64667.4, 0.164], [64670.7, 0.312], [64672.5, 0.08], [64672.6, 0.468], [64672.7, 0.116], [64675.0, 1.528], [64675.1, 1.547], [64675.2, 0.091], [64675.3, 0.242], [64676.3, 0.003], [64676.9, 0.001], [64678.9, 6.361]], "asks": [[64683.1, 0.002], [64684.8, 0.144], [64685.5, 0.305], [64686.2, 0.118], [64690.3, 0.553], [64690.9, 0.004], [64693.6, 0.787], [64694.4, 0.363], [64697.7, 0.041], [64699.1, 0.001], [64744.2, 0.039], [64744.7, 0.005], [64750.1, 0.049], [64814.3, 3.866], [64819.0, 5.4], [64836.0, 10.438], [64874.8, 4.531], [65002.4, 3.845], [65196.4, 7.5], [65325.8, 5.167], [65423.4, 12.712], [65455.1, 23.112], [65597.4, 1.137], [65616.8, 20.927], [65649.2, 5.125], [65679.0, 0.322], [65681.5, 8.514], [65704.0, 1.064], [65746.2, 4.253]]}
{"kind": "depth", "E": 1787095185105, "U": 11316361953602, "u": 11316361959132, "recv_ms": 1787095185174, "bids": [[14178.9, 2.254], [14578.9, 1.946], [51743.0, 0.036], [58211.0, 0.01], [61444.9, 0.0], [61445.1, 0.008], [62091.7, 0.689], [63473.7, 0.0], [63686.3, 0.008], [63860.8, 15.199], [63870.4, 9.642], [64032.1, 4.699], [64355.5, 4.115], [64403.3, 0.001], [64642.6, 0.042], [64655.4, 0.001], [64660.5, 1.779], [64660.6, 0.027], [64660.9, 0.004], [64667.3, 0.881], [64667.4, 0.009], [64670.7, 0.002], [64671.6, 0.11], [64672.4, 0.627], [64672.5, 0.544], [64672.6, 0.53], [64672.7, 0.116], [64675.0, 0.988], [64675.1, 1.547], [64675.2, 0.021], [64675.3, 0.087], [64675.4, 0.004], [64675.5, 0.002], [64675.6, 0.005], [64675.7, 0.018], [64676.9, 0.0], [64678.6, 0.438], [64678.9, 5.423]], "asks": [[64683.1, 0.157], [64684.8, 0.144], [64685.5, 0.228], [64686.2, 0.273], [64687.1, 0.593], [64690.3, 0.431], [64690.9, 0.159], [64693.6, 0.441], [64694.4, 0.518], [64697.7, 0.196], [64699.1, 0.156], [64738.8, 0.077], [65002.4, 3.999], [65196.4, 7.805], [65325.8, 5.167], [65671.7, 9.919]]}
{"kind": "depth", "E": 1787095185207, "U": 11316361959137, "u": 11316361963680, "recv_ms": 1787095185276, "bids": [[1000.0, 35.76], [14178.9, 1.89], [14578.9, 2.31], [51743.0, 0.0], [51743.1, 0.0], [58211.0, 0.01], [62091.7, 0.692], [63482.3, 1.022], [63678.9, 1.173], [63779.9, 12.705], [64032.1, 4.699], [64355.5, 4.114], [64662.5, 0.006], [64672.6, 0.468], [64672.7, 0.003], [64673.1, 0.001], [64675.2, 0.091], [64675.3, 0.003], [64675.7, 0.01], [64676.3, 0.003], [64678.6, 0.239], [64678.9, 5.422]], "asks": [[64686.0, 0.089], [64687.0, 0.544], [64687.6, 2.325], [64695.0, 0.026], [64874.8, 4.514], [65196.4, 8.111], [65325.8, 5.167], [65423.4, 11.804], [65423.5, 1.832], [65487.5, 6.599], [65572.4, 8.984], [65616.8, 21.993], [65660.8, 0.762], [65679.0, 0.342], [65972.5, 0.021]]}
{"kind": "depth", "E": 1787095185309, "U": 11316361963781, "u": 11316361967897, "recv_ms": 1787095185378, "bids": [[1000.0, 35.76], [14178.9, 1.54], [14578.9, 2.66], [58211.0, 0.01], [61444.9, 0.0], [61445.0, 0.053], [63729.3, 3.071], [63858.7, 0.173], [64032.1, 4.699], [64152.4, 0.0], [64355.5, 4.124], [64672.5, 0.003], [64672.7, 0.003], [64675.0, 1.529], [64675.2, 0.091], [64678.9, 5.425]], "asks": [[64690.3, 0.592], [64693.6, 0.806], [64744.0, 1.301], [64744.2, 0.0], [64819.0, 3.848], [64836.0, 7.594], [64874.8, 7.807], [65002.4, 4.0], [65264.9, 0.329], [65325.8, 5.167], [65487.5, 6.857], [65487.7, 3.28], [65713.9, 3.619]]}
{"kind": "depth", "E": 1787095185411, "U": 11316361967943, "u": 11316361972390, "recv_ms": 1787095185480, "bids": [[14178.9, 1.176], [14578.9, 3.024], [58211.0, 0.01], [61444.9, 0.0], [61445.0, 0.055], [62091.7, 0.689], [63678.9, 1.153], [63739.5, 3.746], [64032.1, 4.699], [64161.5, 9.013], [64355.5, 4.123], [64476.8, 0.0], [64477.3, 13.971], [64515.7, 0.128], [64516.1, 6.787], [64532.9, 0.0], [64533.1, 4.703], [64672.5, 0.341], [64672.7, 0.003], [64675.2, 0.512], [64676.3, 0.003], [64678.9, 5.428]], "asks": [[64679.0, 12.802], [64681.8, 0.003], [64681.9, 0.085], [64682.7, 0.007], [64683.0, 0.011], [64683.9, 0.005], [64685.4, 0.479], [64690.3, 0.707], [64744.0, 1.262], [64744.2, 0.039], [64836.0, 10.438], [64874.8, 5.613], [65325.8, 5.167], [65423.4, 9.08], [65584.5, 23.268], [65616.8, 20.927], [65671.7, 8.854], [65679.0, 0.322], [65713.9, 2.555]]}
{"kind": "depth", "E": 1787095185513, "U": 11316361972512, "u": 11316361977164, "recv_ms": 1787095185581, "bids": [[1000.0, 35.76], [14178.9, 0.812], [14578.9, 3.388], [58211.0, 0.01], [61444.9, 0.0], [62091.7, 0.692], [64032.1, 4.699], [64161.5, 9.013], [64355.0, 3.865], [64658.1, 1.847], [64665.4, 1.761], [64672.5, 0.453], [64672.7, 0.341], [64673.1, 0.001], [64675.2, 0.512], [64678.9, 5.427]], "asks": [[64684.8, 0.059], [64685.5, 0.003], [64686.1, 0.087], [64687.9, 0.65], [64690.3, 0.438], [64693.6, 0.71], [64695.3, 0.618], [64711.0, 0.66], [64738.2, 0.039], [64744.2, 0.0], [64817.7, 0.998], [65002.4, 4.001], [65007.2, 0.116], [65297.5, 0.0], [65325.8, 5.167], [65423.5, 2.748]]}
{"kind": "depth", "E": 1787095185615, "U": 11316361977207, "u": 11316361982867, "recv_ms": 1787095185687, "bids": [[1000.0, 35.76], [14178.9, 0.476], [14478.9, 0.014], [14578.9, 3.71], [51743.0, 0.0], [58211.0, 0.01], [62091.7, 0.689], [63678.9, 1.173], [63741.1, 18.114], [63761.7, 7.236], [63870.4, 10.424], [64032.1, 4.699], [64159.9, 0.31], [64300.0, 81.886], [64353.9, 0.155], [64355.5, 4.123], [64533.1, 4.011], [64655.4, 0.001], [64660.5, 1.663], [64660.6, 0.027], [64660.7, 0.438], [64661.6, 0.029], [64667.4, 0.009], [64670.7, 0.002], [64671.6, 0.187], [64672.4, 0.55], [64672.5, 0.544], [64672.7, 0.453], [64673.1, 0.339], [64674.9, 2.324], [64675.0, 0.988], [64675.2, 0.625], [64675.3, 0.424], [64676.3, 0.003]], "asks": [[64679.0, 12.813], [64681.8, 0.013], [64682.7, 0.017], [64683.1, 0.157], [64684.8, 0.059], [64685.5, 0.116], [64686.2, 0.273], [64690.9, 0.159], [64694.4, 0.673], [64697.7, 0.041], [64699.1, 0.156], [64703.5, 0.633], [64703.6, 0.047], [64704.4, 0.718], [64704.7, 0.559], [64738.2, 0.0], [64738.6, 0.04], [64817.7, 0.003], [64819.0, 5.4], [64874.8, 7.81], [65261.1, 4.987], [65306.4, 1.331], [65325.8, 5.167], [65423.5, 4.579], [65679.0, 0.342], [65681.5, 9.579], [65713.9, 3.619]]}
{"kind": "depth", "E": 1787095185717, "U": 11316361982969, "u": 11316361987528, "recv_ms": 1787095185786, "bids": [[14178.9, 0.294], [14478.9, 0.196], [14578.9, 3.71], [58211.0, 0.01], [62091.7, 0.692], [62143.3, 0.0], [63664.7, 1.098], [63739.5, 2.649], [63741.1, 19.211], [63858.9, 1.564], [64032.1, 4.699], [64642.6, 0.042], [64671.4, 0.241], [64672.5, 0.003], [64672.6, 0.468], [64672.7, 0.515], [64673.0, 0.001], [64673.1, 0.001], [64674.7, 0.084], [64675.0, 1.529], [64675.1, 0.001], [64675.2, 0.021], [64675.3, 0.003], [64675.4, 0.004], [64675.5, 0.002], [64675.6, 1.551], [64678.6, 0.568]], "asks": [[64683.9, 0.173], [64684.8, 0.144], [64685.3, 0.042], [64685.5, 0.27], [64686.1, 0.002], [64690.0, 0.972], [64690.3, 0.515], [64691.0, 0.671], [64693.6, 0.806], [64737.8, 0.142], [64738.4, 0.002], [64738.6, 0.001], [65325.8, 5.169], [65423.5, 5.495], [65616.8, 21.993], [65713.9, 4.683], [65778.5, 9.132]]}
{"kind": "depth", "E": 1787095185819, "U": 11316361987537, "u": 11316361992339, "recv_ms": 1787095185888, "bids": [[1000.0, 35.91], [14178.9, 0.168], [14478.9, 0.42], [14578.9, 3.612], [58211.0, 0.01], [61444.9, 0.0], [63678.9, 1.153], [64032.1, 4.699], [64161.5, 9.324], [64355.5, 4.278], [64516.1, 0.019], [64533.1, 0.003], [64672.5, 0.003], [64672.7, 0.003], [64672.8, 0.0], [64675.1, 1.547], [64675.2, 0.512], [64675.6, 0.005], [64675.7, 0.01], [64676.3, 0.003], [64678.6, 0.239], [64678.9, 5.425]], "asks": [[64679.0, 12.812], [64684.8, 0.067], [64685.4, 0.592], [64686.1, 0.079], [64687.1, 0.6], [64690.3, 0.63], [64695.2, 0.131], [64737.8, 0.103], [64738.2, 0.039], [64819.0, 0.0], [64836.0, 0.027], [65325.8, 5.167], [65477.7, 15.223], [65679.0, 0.322], [71146.9, 0.0]]}
{"kind": "depth", "E": 1787095185921, "U": 11316361992378, "u": 11316361997483, "recv_ms": 1787095185990, "bids": [[1000.0, 35.76], [14178.9, 0.056], [14478.9, 0.658], [14578.9, 3.486], [58211.0, 0.01], [62091.7, 0.689], [63585.8, 0.785], [63674.8, 0.0], [63676.4, 16.0], [63739.5, 1.553], [63741.1, 20.308], [64032.1, 4.699], [64159.9, 0.0], [64355.5, 4.278], [64516.3, 6.386], [64516.9, 1.946], [64533.2, 4.067], [64675.2, 0.091], [64678.9, 5.427]], "asks": [[64682.2, 0.177], [64682.7, 0.007], [64683.9, 0.005], [64684.7, 0.416], [64684.8, 0.405], [64685.2, 0.235], [64685.3, 0.492], [64685.4, 0.479], [64685.5, 0.157], [64686.1, 0.002], [64687.1, 0.677], [64690.3, 0.803], [64703.7, 0.652], [64704.7, 0.003], [64738.2, 0.0], [64738.4, 0.041], [64738.8, 0.0], [64819.0, 5.4], [64835.9, 0.0], [64836.0, 10.438], [64874.8, 8.708], [65325.8, 5.167], [65487.5, 7.199], [65488.0, 12.779], [65597.4, 1.364], [65972.5, 0.024], [67912.9, 0.064]]}
{"kind": "depth", "E": 1787095186023, "U": 11316361997642, "u": 11316362002725, "recv_ms": 1787095186095, "bids": [[14178.9, 0.0], [14478.9, 0.966], [14578.9, 3.234], [58211.0, 0.01], [61444.9, 0.0], [62091.7, 0.692], [63610.1, 0.013], [63678.9, 1.173], [63891.2, 4.707], [64032.1, 4.699], [64533.2, 0.0], [64533.3, 4.738], [64655.4, 0.001], [64660.6, 0.027], [64667.4, 0.009], [64669.2, 0.842], [64670.7, 0.002], [64672.5, 0.453], [64672.7, 0.228], [64674.6, 0.01], [64675.2, 0.091], [64675.3, 0.424], [64676.3, 0.003], [64678.9, 5.426]], "asks": [[64681.1, 0.095], [64682.2, 0.009], [64682.3, 0.426], [64683.1, 0.002], [64683.5, 0.273], [64683.9, 0.005], [64684.5, 0.004], [64684.6, 0.02], [64684.7, 0.001], [64684.8, 0.059], [64685.2, 0.01], [64685.3, 0.042], [64685.5, 0.157], [64686.2, 0.118], [64686.3, 0.099], [64686.7, 0.933], [64690.9, 0.159], [64694.4, 0.673], [64699.1, 0.156], [64736.0, 0.001], [64738.4, 0.002], [64739.0, 0.416], [64819.0, 5.4], [64874.8, 5.437], [65002.4, 3.847], [65196.4, 7.805], [65325.8, 5.167], [65455.1, 21.281], [65574.7, 17.793], [65679.0, 0.342], [65746.2, 3.19]]}
{"kind": "depth", "E": 1787095186125, "U": 11316362002788, "u": 11316362008394, "recv_ms": 1787095186194, "bids": [[1000.0, 35.76], [14478.9, 1.33], [14578.9, 2.87], [58211.0, 0.01], [62091.7, 0.689], [63686.3, 0.0], [63741.1, 21.404], [64032.1, 4.699], [64161.5, 9.634], [64614.2, 6.563], [64667.3, 0.881], [64672.4, 0.775], [64672.5, 0.003], [64672.6, 0.53], [64672.7, 0.003], [64675.1, 1.547], [64675.2, 0.021], [64675.3, 0.003], [64675.4, 0.004], [64675.5, 0.002], [64675.6, 0.005], [64675.7, 0.018], [64678.6, 0.489]], "asks": [[64682.3, 0.312], [64683.5, 0.273], [64684.8, 0.227], [64685.3, 0.042], [64685.5, 0.382], [64687.1, 0.754], [64737.9, 0.04], [64739.0, 0.377], [64743.7, 0.009], [65196.4, 8.111], [65325.8, 5.167], [65488.1, 1.526], [65584.5, 23.724], [65671.7, 8.846], [65681.5, 8.515], [65746.2, 4.253]]}
{"kind": "depth", "E": 1787095186227, "U": 11316362008423, "u": 11316362013277, "recv_ms": 1787095186296, "bids": [[14478.9, 1.68], [14578.9, 2.52], [51743.1, 0.0], [58211.0, 0.01], [61444.9, 0.0], [62091.7, 0.692], [63676.4, 17.097], [63678.9, 1.153], [64032.1, 4.699], [64355.5, 4.278], [64533.3, 4.942], [64563.5, 3.865], [64574.1, 2.319], [64574.3, 0.001], [64581.8, 0.01], [64607.7, 2.451], [64633.6, 0.638], [64637.8, 0.0], [64642.6, 0.014], [64646.2, 0.032], [64655.4, 0.001], [64660.3, 0.002], [64660.6, 0.027], [64662.5, 0.006], [64667.4, 0.009], [64670.7, 0.002], [64671.6, 0.11], [64672.4, 0.627], [64672.5, 0.003], [64672.6, 0.468], [64672.7, 0.341], [64674.7, 0.394], [64675.1, 1.631], [64675.2, 0.091], [64675.3, 0.003], [64675.7, 0.01], [64676.3, 0.003], [64678.6, 0.239], [64678.9, 5.427]], "asks": [[64679.0, 12.806], [64681.1, 0.085], [64681.8, 0.003], [64683.1, 0.157], [64683.5, 0.118], [64684.8, 0.227], [64685.5, 0.382], [64685.6, 0.358], [64686.6, 0.396], [64686.7, 0.778], [64687.1, 0.677], [64690.9, 0.159], [64694.4, 0.673], [64695.0, 0.026], [64699.1, 0.156], [64700.8, 0.012], [64704.0, 10.132], [64724.3, 0.004], [64737.9, 0.001], [64738.6, 0.058], [64750.1, 0.049], [64787.9, 2.913], [64788.1, 0.0], [64814.3, 3.866], [64819.0, 5.4], [64874.8, 5.24], [65002.4, 4.0], [65274.7, 0.0], [65325.8, 5.167], [65679.0, 0.322], [66080.6, 1.949]]}
{"kind": "depth", "E": 1787095186329, "U": 11316362013374, "u": 11316362019538, "recv_ms": 1787095186400, "bids": [[14478.9, 2.03], [14578.9, 2.17], [51743.0, 0.0], [58211.0, 0.01], [61444.9, 0.0], [61445.0, 0.057], [63611.7, 4.026], [63800.7, 5.588], [64032.1, 4.699], [64355.5, 4.279], [64516.3, 0.0], [64516.4, 7.462], [64549.5, 0.003], [64568.9, 0.003], [64599.7, 0.059], [64603.1, 0.0], [64603.7, 5.459], [64603.8, 0.483], [64607.5, 0.0], [64609.7, 32.884], [64611.8, 0.001], [64614.2, 2.185], [64617.3, 1.861], [64642.6, 0.042], [64643.2, 0.032], [64655.4, 0.001], [64658.1, 1.229], [64660.0, 0.122], [64660.6, 0.027], [64660.7, 0.322], [64662.9, 0.562], [64663.4, 0.001], [64665.4, 1.143], [64666.5, 0.043], [64666.7, 0.507], [64667.0, 1.253], [64667.3, 0.422], [64667.4, 0.009], [64669.4, 0.003], [64670.4, 1.291], [64670.5, 1.159], [64670.7, 0.002], [64671.6, 0.187], [64672.4, 0.55], [64672.5, 0.544], [64672.6, 0.581], [64673.8, 0.005], [64674.1, 0.057], [64674.7, 0.0], [64675.0, 0.988], [64675.1, 1.547], [64675.2, 0.512], [64675.3, 0.003], [64678.9, 4.62]], "asks": [[64679.0, 12.809], [64680.5, 0.311], [64681.3, 0.1], [64681.8, 0.013], [64681.9, 0.002], [64682.3, 0.309], [64682.7, 0.017], [64683.1, 0.157], [64684.8, 0.059], [64685.4, 0.48], [64685.5, 0.176], [64685.6, 0.317], [64686.6, 0.396], [64687.8, 0.095], [64687.9, 0.032], [64689.7, 0.162], [64690.3, 0.784], [64690.9, 0.159], [64694.4, 0.673], [64695.3, 0.0], [64696.4, 0.02], [64699.1, 0.156], [64699.4, 1.163], [64700.1, 4.478], [64700.7, 1.626], [64703.5, 0.748], [64704.0, 0.132], [64704.4, 0.603], [64707.0, 2.255], [64721.0, 0.234], [64721.2, 0.003], [64721.3, 0.603], [64724.4, 0.398], [64736.0, 0.001], [64738.2, 0.039], [64738.6, 0.001], [64756.7, 0.049], [64817.8, 0.002], [64819.0, 4.37], [64836.0, 10.438], [64874.8, 5.306], [65325.8, 5.167], [65455.1, 23.112], [65584.5, 26.008], [65681.5, 9.579]]}
{"kind": "depth", "E": 1787095186431, "U": 11316362019785, "u": 11316362024133, "recv_ms": 1787095186501, "bids": [[1000.0, 35.76], [14478.9, 2.38], [14578.9, 1.82], [51743.0, 0.0], [58211.0, 0.01], [62091.7, 0.689], [63678.9, 1.173], [63805.7, 7.708], [63870.4, 10.775], [64032.1, 4.699], [64603.7, 0.664], [64603.8, 0.474], [64609.7, 0.189], [64611.6, 0.009], [64611.9, 32.698], [64641.3, 0.004], [64642.3, 10.39], [64642.9, 3.017], [64650.8, 0.16], [64655.4, 0.156], [64660.6, 0.182], [64667.3, 0.577], [64669.4, 0.003], [64670.4, 1.291], [64670.7, 0.241], [64671.1, 0.086], [64671.6, 0.342], [64672.6, 0.468], [64672.7, 0.003], [64672.8, 0.0], [64672.9, 0.535], [64673.5, 0.092], [64673.8, 0.002], [64673.9, 0.008], [64674.3, 0.001], [64675.2, 0.246], [64676.3, 0.003], [64678.9, 4.617]], "asks": [[64679.0, 14.208], [64679.2, 0.002], [64680.6, 0.003], [64681.0, 0.013], [64681.1, 0.095], [64682.0, 0.194], [64682.7, 0.007], [64683.1, 0.002], [64683.5, 0.113], [64684.5, 0.004], [64684.6, 0.02], [64684.7, 0.001], [64684.8, 0.059], [64685.3, 0.155], [64685.5, 0.598], [64686.5, 0.123], [64686.6, 0.867], [64686.7, 0.152], [64687.1, 1.035], [64688.0, 2.505], [64690.0, 0.072], [64690.3, 0.649], [64690.9, 0.004], [64694.4, 0.363], [64699.1, 0.001], [64738.2, 0.0], [64738.6, 0.04], [64771.2, 0.288], [64836.0, 10.438], [64874.8, 4.305], [65002.4, 3.999], [65261.2, 5.271], [65325.8, 5.167], [65487.5, 7.427], [65679.0, 0.342], [65972.5, 0.021], [67201.5, 1.263]]}
{"kind": "depth", "E": 1787095186533, "U": 11316362024228, "u": 11316362028418, "recv_ms": 1787095186603, "bids": [[14478.9, 2.744], [14578.9, 1.456], [51743.0, 0.0], [58211.0, 0.01], [61444.9, 0.0], [61445.0, 0.055], [61445.1, 0.01], [62091.7, 0.692], [63385.4, 0.957], [64032.1, 4.699], [64353.9, 0.0], [64355.5, 4.269], [64563.5, 3.865], [64574.0, 2.32], [64574.1, 0.0], [64607.7, 2.451], [64608.6, 0.013], [64631.2, 0.041], [64641.3, 0.006], [64647.4, 3.564], [64655.4, 0.156], [64658.1, 1.229], [64660.6, 0.182], [64665.5, 0.072], [64667.3, 0.577], [64670.7, 0.241], [64671.6, 0.187], [64672.4, 0.55], [64672.5, 0.003], [64672.6, 0.918], [64672.7, 0.608], [64672.8, 0.45], [64672.9, 0.31], [64673.7, 0.115], [64674.5, 0.084], [64675.0, 1.529], [64675.1, 1.66], [64675.2, 0.667], [64675.3, 0.003]], "asks": [[64679.0, 14.864], [64681.1, 0.085], [64681.2, 0.007], [64681.8, 0.003], [64683.1, 0.002], [64683.5, 0.113], [64683.9, 0.005], [64684.8, 0.227], [64685.0, 0.001], [64685.3, 0.042], [64685.4, 0.48], [64685.5, 0.401], [64686.5, 0.123], [64686.6, 0.241], [64686.7, 0.778], [64687.1, 0.67], [64688.0, 1.605], [64689.0, 1.903], [64690.3, 0.803], [64690.9, 0.004], [64694.3, 0.04], [64694.4, 0.363], [64695.4, 1.095], [64698.8, 0.008], [64699.1, 0.001], [64699.4, 0.704], [64699.9, 0.879], [64703.1, 0.158], [64710.8, 0.03], [64711.1, 3.261], [64717.6, 0.157], [64721.3, 0.603], [64738.4, 0.041], [64738.6, 0.019], [64740.2, 0.001], [64750.1, 0.049], [64787.8, 5.318], [64787.9, 0.594], [64795.6, 0.005], [64814.3, 3.866], [64818.1, 0.742], [64835.9, 2.392], [65325.8, 5.167], [65778.6, 0.759], [65972.5, 0.012], [67912.9, 0.068]]}
{"kind": "depth", "E": 1787095186635, "U": 11316362028529, "u": 11316362034206, "recv_ms": 1787095186706, "bids": [[14478.9, 3.108], [14578.9, 1.092], [51743.0, 0.0], [58211.0, 0.01], [62091.7, 0.689], [63678.9, 1.153], [64032.1, 4.699], [64355.5, 4.27], [64576.3, 0.0], [64578.4, 1.767], [64647.5, 0.579], [64655.4, 0.001], [64660.6, 0.027], [64667.3, 0.422], [64670.7, 0.086], [64672.4, 0.971], [64672.6, 0.468], [64672.7, 0.003], [64672.8, 0.0], [64672.9, 0.085], [64673.7, 0.002], [64675.1, 1.547], [64675.2, 0.091], [64676.3, 0.003]], "asks": [[64679.0, 14.904], [64682.2, 0.009], [64683.1, 0.157], [64683.9, 0.173], [64684.7, 0.627], [64684.8, 0.397], [64685.3, 0.38], [64685.4, 0.48], [64685.5, 0.529], [64686.6, 0.396], [64686.7, 0.152], [64690.9, 0.159], [64694.4, 0.673], [64699.1, 0.156], [64703.2, 0.622], [64707.9, 0.004], [64708.0, 1.265], [64708.1, 0.005], [64711.0, 0.658], [64711.8, 0.003], [64712.0, 1.393], [64713.9, 0.0], [64714.1, 0.029], [64719.4, 3.542], [64737.7, 0.039], [64738.4, 0.002], [64738.6, 0.001], [64742.0, 6.003], [64772.6, 0.003], [64819.0, 0.0], [64819.1, 5.427], [64835.9, 0.0], [64836.0, 10.438], [64874.8, 4.307], [65325.8, 5.167], [65426.8, 0.534], [65587.6, 2.752], [65620.9, 1.216], [65629.8, 6.845], [65679.0, 0.322]]}
{"kind": "depth", "E": 1787095186737, "U": 11316362034239, "u": 11316362038569, "recv_ms": 1787095186806, "bids": [[1000.0, 35.76], [14478.9, 3.472], [14578.9, 0.728], [58211.0, 0.01], [61444.9, 0.0], [63678.9, 1.173], [63750.9, 2.577], [64032.1, 4.699], [64533.3, 0.018], [64608.7, 6.788], [64631.4, 3.684], [64671.6, 0.187], [64672.4, 0.55], [64672.5, 0.003], [64672.7, 0.229], [64674.9, 2.408], [64675.2, 0.091], [64678.9, 4.616]], "asks": [[64679.0, 14.905], [64681.2, 0.007], [64681.9, 0.002], [64683.5, 0.113], [64683.9, 0.005], [64684.7, 0.001], [64684.8, 0.284], [64685.3, 0.042], [64685.5, 0.26], [64686.5, 0.749], [64710.9, 0.007], [64711.9, 0.043], [64714.0, 0.481], [64819.1, 0.027], [65325.8, 5.167], [65435.7, 2.136], [65679.0, 0.342], [65778.5, 9.511]]}
{"kind": "depth", "E": 1787095186839, "U": 11316362038602, "u": 11316362043666, "recv_ms": 1787095186909, "bids": [[14378.9, 0.042], [14478.9, 3.738], [14578.9, 0.42], [51743.0, 0.0], [58211.0, 0.01], [61444.9, 0.0], [62091.7, 0.692], [63385.4, 0.96], [63870.4, 11.009], [64032.1, 4.701], [64355.5, 4.425], [64358.3, 1.111], [64401.9, 0.002], [64413.7, 0.005], [64427.7, 0.0], [64439.6, 0.014], [64453.6, 0.032], [64465.5, 0.15], [64479.5, 0.017], [64491.3, 0.001], [64505.3, 0.001], [64517.2, 0.078], [64533.5, 4.873], [64568.9, 0.0], [64578.2, 10.0], [64578.4, 3.033], [64624.5, 0.004], [64627.1, 0.114], [64633.6, 0.638], [64655.4, 0.001], [64660.6, 0.027], [64667.3, 0.422], [64670.7, 0.086], [64671.6, 0.187], [64672.4, 0.55], [64672.5, 0.003], [64672.7, 0.003], [64672.8, 0.225], [64675.2, 0.091], [64675.3, 0.003], [64676.3, 0.003], [64677.1, 0.423], [64678.8, 0.069], [64678.9, 5.403]], "asks": [[64683.1, 0.157], [64683.5, 0.113], [64683.9, 0.005], [64684.8, 0.059], [64685.3, 0.042], [64685.4, 0.705], [64685.5, 0.495], [64686.0, 0.047], [64686.4, 0.411], [64686.6, 0.241], [64689.0, 1.003], [64689.7, 0.002], [64690.0, 0.972], [64690.3, 0.784], [64690.9, 0.159], [64693.6, 0.966], [64694.4, 0.673], [64695.4, 0.477], [64699.1, 0.156], [64724.3, 0.004], [64736.0, 0.019], [64756.7, 0.046], [64774.3, 10.033], [64819.1, 5.427], [64828.8, 0.0], [64840.7, 0.001], [64854.6, 0.001], [64866.6, 0.164], [64874.8, 10.223], [64880.5, 0.004], [64892.4, 0.001], [64906.4, 0.0], [64918.3, 0.001], [64932.2, 0.0], [64944.2, 0.005], [65325.8, 5.167], [66321.7, 0.0]]}
{"kind": "depth", "E": 1787095186941, "U": 11316362043677, "u": 11316362047784, "recv_ms": 1787095187014, "bids": [[14378.9, 0.238], [14478.9, 3.696], [14578.9, 0.266], [58211.0, 0.01], [61444.9, 0.0], [62091.7, 0.689], [64032.1, 4.699], [64547.0, 0.596], [64548.9, 0.6], [64617.5, 0.019], [64624.5, 0.018], [64627.2, 0.08], [64655.4, 0.001], [64660.0, 0.006], [64660.6, 0.027], [64660.9, 0.12], [64667.3, 0.422], [64670.7, 0.086], [64671.6, 0.525], [64672.4, 1.0], [64672.5, 0.453], [64672.7, 0.453], [64672.8, 0.0], [64672.9, 0.085], [64675.1, 1.66], [64675.2, 0.512], [64677.1, 0.002], [64678.9, 5.404]], "asks": [[64683.1, 0.157], [64683.5, 0.281], [64684.8, 0.059], [64685.3, 0.042], [64685.4, 0.48], [64685.5, 0.157], [64686.4, 0.256], [64686.5, 0.123], [64686.7, 0.933], [64686.9, 0.314], [64687.0, 0.566], [64690.9, 0.159], [64694.4, 0.673], [64699.1, 0.156], [64737.7, 0.0], [64739.0, 0.416], [64874.8, 6.418], [65325.8, 5.167]]}
{"kind": "depth", "E": 1787095187043, "U": 11316362047926, "u": 11316362052859, "recv_ms": 1787095187114, "bids": [[1000.0, 35.76], [14378.9, 0.476], [14478.9, 3.57], [14578.9, 0.154], [58211.0, 0.01], [61444.9, 0.0], [62091.7, 0.692], [63678.9, 1.153], [64032.1, 4.699], [64355.5, 4.27], [64533.5, 0.001], [64533.6, 4.64], [64624.5, 0.018], [64645.2, 0.078], [64655.4, 0.001], [64660.6, 0.027], [64662.9, 0.005], [64663.6, 1.022], [64667.3, 0.427], [64670.7, 0.002], [64671.6, 0.11], [64672.4, 0.627], [64672.5, 0.003], [64672.7, 0.003], [64672.8, 0.0], [64675.1, 1.547], [64675.2, 0.091], [64675.3, 0.003], [64675.5, 0.086], [64676.3, 0.003], [64678.8, 0.039]], "asks": [[64679.0, 14.905], [64683.1, 0.157], [64683.5, 0.113], [64683.9, 0.173], [64685.3, 0.155], [64685.5, 0.382], [64686.6, 0.396], [64686.7, 0.778], [64690.9, 0.159], [64694.4, 0.673], [64699.1, 0.156], [64738.6, 0.04], [64739.0, 0.377], [64818.1, 0.024], [64819.1, 5.427], [64874.8, 10.699], [65002.4, 3.845], [65325.8, 5.167], [65499.0, 4.175], [65679.0, 0.322], [66307.4, 2.189]]}
{"kind": "depth", "E": 1787095187145, "U": 11316362052939, "u": 11316362057495, "recv_ms": 1787095187214, "bids": [[14378.9, 0.714], [14478.9, 3.458], [14578.9, 0.028], [51743.0, 0.0], [58211.0, 0.01], [61444.9, 0.0], [62091.7, 0.689], [63600.0, 249.534], [63685.4, 0.315], [63860.8, 14.965], [64032.1, 4.699], [64355.5, 4.28], [64516.4, 0.008], [64516.6, 7.471], [64624.5, 0.004], [64635.6, 0.0], [64667.3, 0.422], [64671.6, 0.187], [64672.4, 0.55], [64672.5, 0.003], [64672.7, 0.453], [64672.8, 0.45], [64675.2, 0.091], [64678.2, 0.03], [64678.9, 5.229]], "asks": [[64679.0, 14.903], [64683.9, 0.173], [64685.3, 0.042], [64685.4, 0.593], [64685.5, 0.228], [64686.6, 0.396], [64687.1, 0.593], [64690.3, 0.438], [64693.6, 0.947], [64723.5, 0.689], [64732.6, 2.324], [64771.2, 0.372], [64874.8, 4.307], [65196.4, 7.192], [65325.8, 5.167], [65672.6, 0.0]]}
{"kind": "depth", "E": 1787095187247, "U": 11316362057675, "u": 11316362061995, "recv_ms": 1787095187317, "bids": [[1000.0, 35.76], [14378.9, 1.05], [14478.9, 3.15], [14578.9, 0.0], [51743.0, 0.0], [51743.1, 0.0], [58211.0, 0.01], [61444.9, 0.0], [63535.3, 2.515], [63579.5, 3.137], [63678.9, 1.173], [64032.1, 4.699], [64355.5, 4.435], [64579.0, 0.017], [64585.5, 0.0], [64623.0, 0.065], [64624.5, 0.032], [64627.8, 0.387], [64634.2, 0.07], [64655.4, 0.001], [64660.6, 0.027], [64662.5, 0.006], [64667.3, 0.422], [64670.7, 0.002], [64671.6, 0.187], [64672.4, 0.55], [64672.5, 0.116], [64672.7, 0.003], [64672.8, 0.0], [64672.9, 0.085], [64673.0, 0.226], [64675.2, 0.091], [64676.5, 0.011], [64678.9, 5.229]], "asks": [[64679.0, 14.903], [64681.2, 0.017], [64681.9, 0.012], [64683.1, 0.157], [64685.5, 0.305], [64686.6, 0.396], [64690.3, 0.592], [64690.9, 0.159], [64694.4, 0.673], [64695.0, 0.026], [64699.1, 0.156], [64738.4, 0.041], [64738.6, 0.001], [64874.8, 6.967], [65002.4, 3.999], [65325.8, 5.167], [65679.0, 0.342], [65866.6, 0.025]]}
{"kind": "depth", "E": 1787095187349, "U": 11316362062065, "u": 11316362066416, "recv_ms": 1787095187417, "bids": [[1000.0, 35.76], [14378.9, 1.414], [14478.9, 2.786], [58211.0, 0.01], [61444.9, 0.0], [61445.0, 0.053], [61445.1, 0.012], [62091.7, 0.692], [63773.4, 15.846], [63860.8, 14.73], [64032.1, 4.699], [64355.5, 4.434], [64624.5, 0.004], [64642.6, 0.014], [64671.6, 0.11], [64672.4, 1.077], [64672.5, 0.003], [64672.7, 0.453], [64672.8, 0.225], [64673.0, 0.001], [64673.1, 0.001], [64675.2, 0.512], [64678.9, 5.765]], "asks": [[64679.0, 14.9], [64681.2, 0.017], [64681.9, 0.002], [64682.6, 0.0], [64683.5, 0.121], [64683.9, 0.005], [64685.4, 0.48], [64685.5, 0.08], [64686.6, 0.399], [64687.6, 2.324], [64690.3, 0.438], [64693.6, 0.87], [64720.4, 3.334], [64738.2, 0.039], [64738.4, 0.002], [64760.7, 0.066], [64768.5, 2.819], [65002.4, 4.0], [65196.4, 8.111], [65325.8, 5.167], [120000.0, 6.72]]}
{"kind": "depth", "E": 1787095187451, "U": 11316362066445, "u": 11316362071046, "recv_ms": 1787095187521, "bids": [[14378.9, 1.764], [14478.9, 2.436], [58211.0, 0.01], [61444.9, 0.0], [62091.7, 0.689], [62153.3, 1.368], [63385.4, 0.963], [63547.0, 3.774], [63611.7, 4.731], [63678.9, 1.153], [64032.1, 4.699], [64355.5, 4.434], [64535.6, 0.0], [64604.6, 0.027], [64613.9, 0.0], [64614.3, 0.003], [64614.6, 0.0], [64614.9, 0.0], [64615.2, 0.0], [64624.5, 0.032], [64631.5, 2.322], [64631.8, 4.653], [64632.1, 0.003], [64632.4, 0.21], [64632.8, 0.0], [64640.3, 0.001], [64646.4, 0.286], [64646.5, 0.006], [64646.6, 0.017], [64646.7, 0.004], [64646.8, 0.074], [64646.9, 0.016], [64647.0, 0.001], [64647.1, 0.002], [64647.2, 0.626], [64647.3, 0.014], [64648.2, 0.002], [64648.6, 3.205], [64659.7, 0.001], [64665.3, 0.252], [64665.4, 1.003], [64665.5, 0.002], [64665.6, 0.015], [64665.7, 0.0], [64665.8, 2.321], [64665.9, 1.516], [64666.0, 0.754], [64666.1, 0.162], [64666.2, 0.256], [64666.5, 0.011], [64666.8, 0.002], [64667.2, 1.406], [64667.5, 0.344], [64667.8, 0.045], [64667.9, 0.228], [64668.1, 1.02], [64671.6, 0.187], [64672.4, 0.55], [64672.5, 0.003], [64672.7, 0.424], [64672.8, 0.0], [64675.2, 0.091], [64676.5, 0.011], [64678.9, 5.768]], "asks": [[64679.0, 14.901], [64681.2, 0.007], [64684.8, 0.195], [64685.1, 0.004], [64685.4, 0.442], [64685.5, 0.003], [64685.7, 0.003], [64686.0, 0.005], [64686.3, 0.008], [64686.4, 0.136], [64686.5, 0.032], [64686.6, 0.158], [64686.7, 0.708], [64686.8, 1.004], [64686.9, 0.024], [64687.0, 0.496], [64687.1, 0.439], [64687.2, 0.007], [64687.3, 0.41], [64689.0, 1.903], [64690.0, 0.072], [64690.4, 0.003], [64692.5, 1.004], [64693.6, 0.947], [64702.3, 0.464], [64702.6, 0.004], [64702.9, 1.068], [64703.2, 0.58], [64703.6, 0.005], [64704.0, 0.012], [64704.4, 0.463], [64705.2, 0.031], [64705.4, 0.038], [64705.5, 0.007], [64705.6, 1.268], [64705.7, 0.008], [64705.8, 0.007], [64705.9, 0.07], [64706.0, 0.38], [64706.1, 0.31], [64706.2, 0.061], [64719.8, 0.019], [64720.1, 3.25], [64720.5, 0.043], [64720.8, 0.002], [64721.1, 0.52], [64721.3, 0.449], [64721.4, 2.507], [64722.9, 0.009], [64732.6, 2.32], [64738.2, 0.0], [64738.6, 0.01], [64739.0, 0.416], [64743.8, 6.303], [64810.0, 1.16], [65325.8, 5.167], [65679.0, 0.322], [65875.6, 1.969]]}
{"kind": "depth", "E": 1787095187553, "U": 11316362071155, "u": 11316362075550, "recv_ms": 1787095187622, "bids": [[1000.0, 35.76], [14378.9, 2.114], [14478.9, 2.086], [58211.0, 0.01], [61444.9, 0.0], [62091.7, 0.692], [63385.4, 0.966], [63729.3, 2.131], [63751.0, 0.482], [64032.1, 4.699], [64355.5, 4.433], [64545.0, 0.05], [64603.3, 0.04], [64614.2, 6.455], [64632.3, 0.108], [64632.6, 0.041], [64632.9, 0.059], [64633.3, 0.036], [64638.3, 0.011], [64646.9, 0.001], [64651.9, 0.016], [64653.4, 0.017], [64658.1, 1.847], [64659.2, 1.337], [64665.5, 0.62], [64666.0, 0.824], [64666.3, 0.318], [64666.4, 0.085], [64667.3, 0.454], [64667.7, 0.051], [64668.0, 1.175], [64668.3, 0.033], [64671.6, 0.525], [64672.4, 0.55], [64672.7, 0.003], [64675.2, 0.512], [64678.9, 5.766]], "asks": [[64679.0, 14.956], [64681.9, 0.012], [64684.6, 0.052], [64684.8, 0.027], [64684.9, 1.437], [64685.2, 0.048], [64685.3, 0.21], [64685.5, 0.045], [64686.5, 0.102], [64686.6, 0.289], [64686.9, 0.094], [64688.0, 2.223], [64689.0, 1.003], [64690.0, 0.972], [64690.1, 0.006], [64690.3, 0.277], [64691.9, 1.114], [64693.6, 0.517], [64695.3, 0.618], [64695.9, 0.004], [64702.1, 6.082], [64702.4, 1.263], [64702.8, 0.039], [64703.1, 0.2], [64705.4, 0.108], [64705.5, 0.137], [64705.8, 0.077], [64712.0, 1.402], [64719.6, 0.035], [64720.0, 0.592], [64720.3, 0.042], [64720.6, 0.07], [64738.6, 0.049], [64738.8, 0.154], [64739.0, 0.377], [64749.2, 0.022], [64811.1, 0.114], [64818.0, 1.115], [64819.1, 5.427], [64836.0, 1.675], [64836.1, 10.412], [64874.8, 0.0], [64874.9, 5.637], [65325.8, 5.167], [65455.1, 22.503], [65487.5, 7.656]]}
