{"kind": "depth", "E": 1787095206933, "U": 11316363593652, "u": 11316363603548, "recv_ms": 1787095207003, "bids": [[1000.0, 36.16], [14273.5, 2.744], [14373.5, 1.456], [58206.1, 0.002], [61439.8, 0.012], [62086.5, 0.002], [63673.5, 0.028], [63761.6, 1.566], [64026.8, 0.248], [64330.5, 0.001], [64331.5, 0.492], [64350.1, 0.01], [64479.8, 0.006], [64479.9, 4.078], [64508.3, 0.104], [64509.1, 0.48], [64511.8, 0.278], [64516.2, 0.0], [64516.9, 1.152], [64533.2, 0.0], [64657.1, 0.011], [64665.0, 0.144], [64665.1, 0.14], [64665.3, 0.323], [64665.5, 0.102], [64665.6, 0.563], [64665.7, 0.101], [64667.8, 1.556], [64669.4, 1.52], [64669.7, 0.063], [64670.3, 0.0], [64670.5, 0.008], [64671.7, 0.045]], "asks": [[64673.6, 36.854], [64674.6, 0.084], [64675.2, 0.009], [64677.3, 0.009], [64679.0, 4.44], [64682.8, 0.388], [64682.9, 0.143], [64683.0, 0.251], [64683.2, 0.253], [64683.3, 0.35], [64683.4, 0.088], [64683.6, 0.495], [64689.6, 10.02], [64700.2, 0.121], [64700.6, 0.145], [64701.5, 1.497], [64701.6, 0.151], [64701.8, 0.282], [64702.0, 0.251], [64702.1, 6.186], [64722.6, 0.101], [64814.0, 0.0], [64814.1, 0.0], [64831.1, 0.001], [64869.9, 0.018], [64997.0, 0.202], [65320.3, 0.0], [65455.1, 33.777], [65673.6, 0.02]]}
{"kind": "depth", "E": 1787095207035, "U": 11316363603704, "u": 11316363612197, "recv_ms": 1787095207105, "bids": [[14273.5, 3.108], [14373.5, 1.092], [45275.3, 0.002], [58206.1, 0.002], [61439.8, 0.014], [62086.5, 0.005], [63671.1, 2.215], [63703.7, 4.553], [63846.0, 0.107], [63865.1, 1.555], [64026.8, 0.248], [64094.7, 0.017], [64096.9, 0.264], [64254.9, 0.008], [64257.1, 0.003], [64415.6, 0.004], [64417.8, 0.001], [64477.4, 13.321], [64508.3, 0.143], [64509.1, 0.441], [64515.1, 0.038], [64516.2, 6.609], [64533.2, 4.394], [64550.9, 0.001], [64576.6, 0.003], [64578.8, 0.014], [64614.0, 1.033], [64614.3, 0.035], [64614.7, 0.032], [64615.3, 0.034], [64646.3, 0.13], [64646.5, 0.196], [64646.6, 0.106], [64647.0, 3.366], [64669.7, 0.071], [64670.3, 0.433], [64670.5, 0.0], [64671.0, 0.003], [64671.5, 1.257], [64671.6, 0.002], [64673.5, 0.927]], "asks": [[64673.6, 36.852], [64677.3, 0.009], [64677.4, 0.095], [64715.9, 0.428], [64716.5, 0.278], [64716.8, 0.121], [64717.2, 0.049], [64770.5, 0.016], [64772.7, 0.039], [64814.1, 5.4], [64831.1, 10.413], [64869.9, 7.397], [64932.4, 0.006], [64934.6, 0.028], [65094.8, 0.023], [65097.0, 0.051], [65257.5, 0.248], [65259.7, 0.557], [65320.3, 0.0], [65396.7, 0.768], [65449.7, 4.042], [65501.8, 0.01], [65644.1, 0.0], [65967.4, 2.337]]}
{"kind": "depth", "E": 1787095207137, "U": 11316363612413, "u": 11316363621093, "recv_ms": 1787095207206, "bids": [[1000.0, 36.31], [14273.5, 3.472], [14373.5, 0.728], [58206.1, 0.002], [61439.8, 0.014], [63673.5, 0.008], [64026.8, 0.248], [64516.8, 1.474], [64533.2, 4.728], [64555.8, 0.0], [64555.9, 3.867], [64556.0, 1.729], [64565.2, 2.346], [64566.4, 0.411], [64600.8, 0.003], [64600.9, 0.001], [64601.1, 0.118], [64615.0, 0.214], [64624.8, 0.001], [64630.0, 0.015], [64646.9, 0.084], [64652.4, 0.12], [64653.7, 0.421], [64655.0, 0.56], [64656.4, 0.07], [64660.7, 0.349], [64661.0, 0.0], [64661.4, 0.0], [64661.9, 0.003], [64666.1, 0.195], [64667.0, 1.354], [64667.3, 0.632], [64669.7, 0.071], [64670.0, 0.005], [64670.3, 0.433], [64670.4, 0.003], [64670.5, 0.0], [64670.9, 0.0], [64671.4, 0.0], [64671.5, 1.349], [64673.5, 0.925]], "asks": [[64673.6, 36.938], [64675.7, 0.01], [64677.3, 0.005], [64678.0, 2.505], [64680.0, 0.124], [64691.5, 0.461], [64692.7, 0.002], [64695.3, 0.672], [64696.5, 0.001], [64696.9, 0.001], [64697.5, 0.099], [64698.3, 0.0], [64715.4, 2.821], [64716.2, 0.101], [64720.1, 0.0], [64743.3, 0.004], [64743.5, 0.05], [64779.0, 0.89], [64780.5, 2.32], [64782.4, 4.86], [64783.2, 2.831], [64789.1, 0.001], [64807.5, 0.556], [64807.7, 3.902], [64814.1, 5.4], [64831.1, 0.001], [64831.9, 10.879], [64851.1, 2.913], [64858.1, 0.0], [64869.9, 6.318], [64899.7, 0.002], [64987.2, 0.015], [65320.3, 0.0], [65673.6, 0.0]]}
{"kind": "depth", "E": 1787095207239, "U": 11316363621196, "u": 11316363627644, "recv_ms": 1787095207308, "bids": [[1000.0, 36.16], [14173.5, 0.042], [14273.5, 3.738], [14373.5, 0.42], [51739.0, 0.0], [58206.1, 0.002], [61439.8, 0.012], [61439.9, 0.002], [62086.5, 0.002], [63845.7, 0.008], [63860.8, 10.008], [63911.2, 0.0], [64026.8, 0.248], [64091.4, 19.079], [64350.1, 0.01], [64595.8, 0.152], [64628.2, 0.005], [64646.3, 0.2], [64646.5, 0.266], [64646.8, 0.104], [64647.2, 0.696], [64650.1, 0.096], [64655.6, 0.012], [64658.5, 0.007], [64659.4, 0.005], [64659.6, 0.865], [64660.7, 0.349], [64660.8, 0.009], [64665.9, 0.131], [64666.1, 0.813], [64666.6, 0.882], [64666.7, 0.76], [64667.1, 0.087], [64667.5, 0.02], [64667.6, 0.021], [64667.9, 0.016], [64669.6, 1.519], [64669.7, 0.063], [64669.8, 0.023], [64670.3, 0.433], [64670.4, 0.003], [64670.8, 0.005]], "asks": [[64673.6, 36.938], [64675.3, 2.811], [64675.7, 0.01], [64677.3, 0.009], [64691.5, 0.002], [64692.0, 4.808], [64697.5, 0.092], [64698.0, 0.233], [64731.9, 0.006], [64751.3, 0.001], [64831.1, 10.413], [64831.9, 5.002], [64869.9, 6.499], [65320.3, 0.0], [65449.7, 4.256]]}
{"kind": "depth", "E": 1787095207341, "U": 11316363627652, "u": 11316363634692, "recv_ms": 1787095207411, "bids": [[14173.5, 0.238], [14273.5, 3.696], [14373.5, 0.266], [58206.1, 0.002], [62086.5, 0.005], [62091.8, 1.451], [63673.5, 0.028], [63703.4, 0.012], [63731.5, 15.136], [64026.8, 0.248], [64310.0, 1.037], [64310.1, 1.97], [64361.5, 0.494], [64406.6, 0.006], [64409.1, 0.729], [64477.5, 0.022], [64479.9, 0.001], [64550.6, 0.07], [64553.3, 0.001], [64563.7, 2.32], [64565.2, 0.027], [64603.0, 33.107], [64607.4, 0.176], [64646.4, 0.266], [64646.6, 0.176], [64646.8, 0.204], [64647.0, 3.466], [64647.1, 0.072], [64647.9, 0.411], [64648.3, 0.108], [64650.1, 0.096], [64652.4, 0.004], [64653.2, 0.0], [64654.5, 0.181], [64655.0, 0.003], [64655.8, 0.557], [64655.9, 0.001], [64656.9, 0.636], [64657.5, 0.154], [64659.6, 0.406], [64660.7, 0.349], [64660.8, 0.009], [64661.0, 0.309], [64661.3, 1.483], [64661.4, 0.459], [64661.5, 0.002], [64661.7, 0.322], [64662.0, 0.321], [64664.0, 0.218], [64666.7, 0.159], [64667.1, 0.628], [64667.3, 0.091], [64667.4, 0.044], [64667.5, 0.017], [64667.9, 0.557], [64669.7, 0.063], [64669.8, 0.015], [64670.3, 0.0], [64670.4, 0.003], [64672.0, 0.004], [64672.1, 0.0]], "asks": [[64675.7, 0.02], [64678.7, 0.02], [64683.1, 0.189], [64684.7, 0.001], [64686.6, 0.072], [64692.0, 4.349], [64692.8, 0.772], [64693.8, 0.462], [64695.3, 0.0], [64695.9, 0.004], [64696.0, 1.077], [64696.9, 0.557], [64697.3, 1.821], [64705.5, 0.007], [64715.6, 2.327], [64722.6, 0.097], [64779.0, 3.209], [64780.5, 0.001], [64869.9, 8.798], [64871.9, 1.873], [64873.6, 0.001], [64944.9, 0.466], [64945.0, 2.457], [65040.9, 0.659], [65042.4, 0.005], [65320.3, 0.0], [65350.0, 140.781], [65477.7, 10.653], [65494.9, 0.055], [65502.3, 0.011], [65644.5, 0.008], [65673.6, 0.02], [65967.9, 0.008]]}
{"kind": "depth", "E": 1787095207443, "U": 11316363634697, "u": 11316363648161, "recv_ms": 1787095207516, "bids": [[1000.0, 36.16], [14173.5, 0.476], [14273.5, 3.584], [14373.5, 0.14], [51739.0, 0.0], [58206.1, 0.002], [61439.8, 0.012], [62086.5, 0.002], [64026.8, 0.248], [64351.8, 0.227], [64354.8, 0.002], [64603.0, 0.002], [64605.3, 33.291], [64612.1, 0.163], [64616.5, 0.037], [64628.2, 0.008], [64630.6, 8.008], [64632.8, 0.0], [64633.2, 4.056], [64650.1, 0.096], [64653.6, 0.199], [64653.7, 0.428], [64654.5, 0.065], [64654.6, 0.041], [64655.9, 0.001], [64656.9, 0.629], [64657.9, 0.319], [64658.7, 0.001], [64659.6, 0.413], [64660.1, 0.014], [64660.3, 0.46], [64660.7, 0.256], [64660.8, 0.557], [64661.4, 0.0], [64661.5, 0.095], [64666.1, 0.195], [64667.0, 1.357], [64667.1, 0.087], [64667.3, 0.084], [64667.4, 0.041], [64667.9, 0.557], [64668.0, 0.105], [64669.6, 1.603], [64669.7, 0.071], [64670.3, 0.433]], "asks": [[64673.6, 37.017], [64675.7, 0.02], [64677.3, 0.005], [64678.7, 0.112], [64681.4, 1.243], [64681.9, 0.557], [64682.0, 0.202], [64683.0, 1.151], [64683.1, 0.189], [64683.8, 0.003], [64683.9, 0.003], [64684.6, 0.038], [64684.7, 0.009], [64684.8, 3.163], [64685.3, 4.001], [64686.2, 0.003], [64687.1, 0.026], [64687.2, 0.162], [64687.3, 0.398], [64687.4, 0.098], [64687.9, 1.269], [64688.0, 2.643], [64689.5, 0.619], [64689.6, 0.02], [64693.6, 0.0], [64694.3, 0.003], [64694.5, 3.557], [64694.7, 0.029], [64705.6, 3.285], [64751.3, 0.004], [64779.0, 2.923], [64831.1, 0.001], [64831.9, 10.955], [64837.6, 0.03], [64869.9, 0.018], [64870.7, 2.151], [64997.0, 0.201], [65002.3, 0.109], [65007.2, 0.008], [65320.3, 0.0], [65768.7, 3.185]]}
{"kind": "depth", "E": 1787095207545, "U": 11316363648623, "u": 11316363657139, "recv_ms": 1787095207614, "bids": [[14173.5, 0.714], [14273.5, 3.458], [14373.5, 0.028], [51738.8, 0.0], [58206.1, 0.002], [61439.8, 0.012], [62086.5, 0.005], [63673.5, 0.008], [64026.8, 0.248], [64046.6, 0.0], [64096.9, 0.03], [64193.5, 0.0], [64350.1, 0.001], [64670.6, 0.015]], "asks": [[64673.6, 37.027], [64677.3, 0.009], [64687.4, 0.716], [64689.5, 0.001], [64831.1, 10.413], [64831.9, 5.002], [64869.9, 6.332], [64870.7, 0.41], [65159.5, 0.001], [65309.4, 0.015], [65320.3, 0.0], [65579.0, 2.822], [65611.7, 15.221], [65673.6, 0.0]]}
{"kind": "depth", "E": 1787095207647, "U": 11316363657565, "u": 11316363665725, "recv_ms": 1787095207716, "bids": [[14173.5, 1.05], [14273.5, 3.15], [14373.5, 0.0], [58206.1, 0.002], [63731.5, 14.039], [63735.7, 5.485], [63750.9, 1.873], [63838.2, 3.467], [64026.8, 0.248], [64100.1, 4.342], [64300.1, 13.342], [64310.1, 1.106], [64401.0, 31.375], [64401.1, 0.217], [64401.8, 9.524], [64406.7, 0.08], [64471.9, 23.319], [64533.2, 4.715], [64612.1, 0.086], [64650.1, 0.096], [64655.9, 0.001], [64658.2, 0.001], [64658.6, 0.522], [64659.2, 0.017], [64659.6, 0.406], [64660.2, 0.642], [64660.4, 5.236], [64660.7, 0.256], [64660.9, 0.039], [64661.0, 0.0], [64661.5, 0.095], [64665.9, 0.13], [64666.5, 0.006], [64667.0, 1.354], [64668.0, 0.105], [64669.5, 0.001], [64669.7, 0.071], [64670.3, 0.0], [64673.5, 0.912]], "asks": [[64673.6, 36.948], [64675.2, 0.658], [64677.3, 0.009], [64678.7, 2.323], [64679.0, 4.749], [64680.2, 0.001], [64681.9, 0.016], [64684.2, 0.009], [64684.6, 0.03], [64692.6, 1.073], [64693.0, 0.199], [64693.8, 0.003], [64745.9, 57.798], [64746.0, 0.041], [64814.1, 5.4], [64868.7, 24.584], [64937.7, 8.767], [64939.9, 0.87], [64940.0, 41.133], [64959.9, 11.491], [65037.3, 5.86], [65037.4, 37.818], [65320.3, 0.0]]}
{"kind": "depth", "E": 1787095207749, "U": 11316363665914, "u": 11316363672657, "recv_ms": 1787095207819, "bids": [[1000.0, 36.16], [14173.5, 1.4], [14273.5, 2.8], [58206.1, 0.002], [61439.8, 0.012], [62086.5, 0.002], [63602.2, 0.376], [63673.5, 0.028], [63708.8, 2.977], [64026.8, 0.248], [64508.3, 0.104], [64509.1, 0.48], [64516.9, 2.035], [64533.2, 0.0], [64607.8, 5.888], [64670.6, 0.015]], "asks": [[64673.6, 36.948], [64676.7, 0.002], [64677.3, 0.009], [64814.0, 1.714], [64814.1, 0.0], [64868.6, 6.781], [65320.3, 0.0], [65321.0, 0.805], [65322.7, 0.0], [65477.7, 10.424], [65673.6, 0.02]]}
{"kind": "depth", "E": 1787095207851, "U": 11316363672686, "u": 11316363679396, "recv_ms": 1787095207921, "bids": [[14173.5, 1.764], [14273.5, 2.436], [51739.0, 0.0], [58206.1, 0.002], [62086.5, 0.005], [63703.4, 0.365], [63832.7, 1.956], [63981.8, 0.862], [64091.4, 19.313], [64188.6, 48.518], [64304.4, 37.807], [64306.7, 6.061], [64350.1, 0.011], [64508.3, 0.143], [64509.1, 0.441], [64516.2, 0.0], [64516.9, 1.152], [64553.1, 0.092], [64670.0, 0.089]], "asks": [[64676.7, 0.012], [64790.5, 0.027], [64814.0, 0.0], [64831.1, 0.001], [65154.5, 45.331], [65320.3, 0.0], [65773.4, 5.465]]}
{"kind": "depth", "E": 1787095207953, "U": 11316363679668, "u": 11316363686651, "recv_ms": 1787095208022, "bids": [[14173.5, 2.128], [14273.5, 2.072], [58206.1, 0.002], [61439.8, 0.012], [62086.5, 0.002], [63606.4, 1.099], [63673.5, 0.008], [63735.7, 6.582], [63763.8, 22.597], [64026.8, 0.248], [64100.1, 0.022], [64300.1, 16.798], [64304.5, 0.865], [64331.5, 0.0], [64331.8, 0.492], [64477.4, 0.004], [64508.3, 0.104], [64509.1, 0.48], [64657.1, 0.011], [64668.0, 0.538]], "asks": [[64673.6, 36.949], [64676.7, 0.002], [64677.3, 0.009], [64686.5, 0.181], [64689.6, 0.02], [64718.1, 0.159], [64718.6, 0.22], [64722.2, 0.002], [64725.8, 0.387], [64869.9, 0.018], [64997.0, 0.2], [65261.3, 2.182], [65320.3, 0.0], [65390.8, 0.0], [65673.6, 0.0]]}
{"kind": "depth", "E": 1787095208055, "U": 11316363686686, "u": 11316363694713, "recv_ms": 1787095208124, "bids": [[1000.0, 36.16], [14173.5, 2.478], [14273.5, 1.722], [58206.1, 0.002], [62086.5, 0.005], [63981.5, 0.937], [64026.8, 0.248], [64477.4, 13.451], [64508.3, 0.143], [64509.1, 0.441], [64516.2, 7.251], [64533.2, 4.715], [64600.9, 0.001], [64603.1, 33.167], [64605.3, 0.186], [64607.8, 1.172], [64658.9, 0.041], [64659.4, 0.237], [64661.9, 0.008], [64663.8, 0.186], [64664.8, 0.119], [64665.6, 0.393], [64668.0, 0.105], [64670.2, 0.155], [64670.6, 0.015]], "asks": [[64676.7, 0.012], [64742.9, 9.963], [64743.7, 53.528], [64745.8, 0.001], [64745.9, 2.381], [64814.1, 5.4], [64831.1, 10.413], [64869.9, 6.308], [65320.3, 0.0], [65378.8, 10.142]]}
{"kind": "depth", "E": 1787095208157, "U": 11316363694827, "u": 11316363702184, "recv_ms": 1787095208227, "bids": [[14173.5, 2.828], [14273.5, 1.372], [51739.0, 0.0], [58206.1, 0.002], [63666.8, 3.765], [63673.5, 0.028], [63731.5, 11.845], [64026.8, 0.248], [64350.1, 0.012], [64603.1, 0.0], [64605.3, 33.353], [64616.5, 0.035], [64630.0, 0.016], [64661.9, 0.003], [64667.1, 0.628], [64667.8, 1.556], [64667.9, 0.449]], "asks": [[64676.7, 0.002], [65258.8, 1.071], [65318.5, 0.0], [65320.3, 0.0], [65455.1, 33.319], [65673.6, 0.02], [65773.1, 5.161]]}
{"kind": "depth", "E": 1787095208259, "U": 11316363702209, "u": 11316363708261, "recv_ms": 1787095208328, "bids": [[14173.5, 3.192], [14273.5, 1.008], [51739.0, 0.0], [58206.1, 0.002], [61439.8, 0.012], [62086.5, 0.002], [63579.4, 3.911], [63961.7, 0.022], [64026.8, 0.248], [64658.8, 0.623], [64666.2, 0.626], [64667.1, 0.087], [64667.9, 0.557], [64668.0, 0.538], [64670.6, 0.015], [64673.5, 0.914]], "asks": [[64673.6, 36.938], [64675.7, 0.02], [64677.3, 0.005], [64678.6, 0.018], [64687.5, 1.246], [64694.9, 0.62], [64718.0, 0.095], [64718.1, 0.159], [64869.9, 6.268], [65320.3, 0.0], [65378.5, 2.159], [65385.8, 1.184], [65449.7, 4.714]]}
{"kind": "depth", "E": 1787095208361, "U": 11316363708366, "u": 11316363714947, "recv_ms": 1787095208430, "bids": [[1000.0, 36.16], [14173.5, 3.542], [14273.5, 0.658], [58206.1, 0.002], [62086.5, 0.005], [63673.5, 0.008], [64026.8, 0.248], [64038.8, 60.163], [64666.5, 0.003], [64666.9, 0.248], [64668.0, 0.538]], "asks": [[64675.7, 0.01], [64679.0, 4.44], [64679.5, 0.31], [64718.1, 0.159], [64744.4, 0.039], [64745.9, 2.342], [64789.6, 0.066], [64869.9, 6.06], [65303.7, 57.506], [65320.3, 0.0], [65320.5, 0.537], [65673.6, 0.0], [65945.8, 0.649]]}
{"kind": "depth", "E": 1787095208463, "U": 11316363714985, "u": 11316363723911, "recv_ms": 1787095208533, "bids": [[14173.5, 3.766], [14273.5, 0.364], [14573.5, 0.07], [58206.1, 0.002], [61439.8, 0.012], [62086.5, 0.002], [63574.1, 6.392], [63671.1, 3.313], [63735.7, 8.776], [63968.9, 12.077], [64026.8, 0.248], [64350.1, 0.001], [64508.3, 0.104], [64509.1, 0.48], [64533.2, 0.0], [64563.5, 0.003], [64595.8, 0.149], [64628.2, 0.005], [64658.8, 0.005], [64666.2, 0.008], [64668.0, 0.105], [64669.7, 0.071], [64670.6, 0.015], [64673.5, 0.911]], "asks": [[64673.6, 36.943], [64673.7, 1.553], [64674.4, 0.37], [64677.3, 0.005], [64679.0, 4.433], [64679.1, 1.398], [64687.4, 0.098], [64687.5, 0.628], [64689.5, 0.619], [64694.9, 0.002], [64712.5, 0.017], [64718.1, 0.159], [64731.9, 0.006], [64751.3, 0.001], [64814.1, 0.0], [65320.3, 0.0], [65417.3, 1.249]]}
{"kind": "depth", "E": 1787095208565, "U": 11316363724210, "u": 11316363733306, "recv_ms": 1787095208635, "bids": [[1000.0, 36.16], [14173.5, 3.668], [14273.5, 0.238], [14573.5, 0.294], [51738.8, 0.0], [58206.1, 0.002], [63509.7, 0.791], [63673.5, 0.028], [63731.5, 10.748], [63925.5, 2.266], [64026.8, 0.248], [64508.3, 0.143], [64509.1, 0.441], [64533.2, 4.783], [64669.7, 0.071], [64673.5, 0.912]], "asks": [[64677.3, 0.009], [64718.1, 0.005], [64718.3, 0.658], [64741.5, 52.919], [64742.9, 2.227], [64743.7, 0.005], [64814.1, 5.4], [65320.3, 0.0], [65482.0, 3.053], [65673.6, 0.02]]}
{"kind": "depth", "E": 1787095208667, "U": 11316363733345, "u": 11316363740047, "recv_ms": 1787095208736, "bids": [[1000.0, 36.16], [14173.5, 3.556], [14273.5, 0.112], [14573.5, 0.532], [58206.1, 0.002], [62086.5, 0.005], [63668.9, 2.604], [63968.6, 1.014], [64026.8, 0.248], [64508.3, 0.104], [64509.1, 0.48], [64669.7, 0.071], [64671.9, 0.001]], "asks": [[64997.0, 0.201], [65320.3, 0.0]]}
{"kind": "depth", "E": 1787095208769, "U": 11316363740172, "u": 11316363747528, "recv_ms": 1787095208839, "bids": [[1000.0, 35.76], [14173.5, 3.43], [14273.5, 0.0], [14573.5, 0.77], [58206.1, 0.002], [61439.8, 0.01], [61439.9, 0.004], [62086.5, 0.002], [63673.5, 0.008], [63958.5, 0.704], [64026.8, 0.248], [64350.1, 0.011], [64473.3, 4.091], [64477.4, 12.398], [64516.2, 6.166], [64516.9, 1.969], [64533.2, 3.723], [64607.8, 5.897], [64628.2, 0.008], [64650.1, 0.096], [64655.9, 0.001], [64660.7, 0.256], [64660.9, 0.039], [64666.6, 0.798], [64668.0, 0.105], [64669.7, 0.504], [64670.6, 0.015], [64670.8, 0.089], [64671.6, 0.002]], "asks": [[64673.6, 36.926], [64675.1, 0.003], [64675.2, 0.009], [64675.3, 2.501], [64677.3, 0.005], [64677.9, 0.0], [64678.6, 0.667], [64679.0, 4.426], [64681.9, 0.002], [64682.1, 1.34], [64751.3, 0.004], [64778.9, 0.957], [64779.0, 2.334], [64814.1, 5.4], [64814.3, 0.909], [64831.1, 10.413], [64869.9, 6.257], [65320.3, 0.0], [65673.6, 0.0]]}
{"kind": "depth", "E": 1787095208871, "U": 11316363747638, "u": 11316363755539, "recv_ms": 1787095208940, "bids": [[1000.0, 35.76], [14173.5, 3.066], [14573.5, 1.134], [58206.1, 0.002], [61439.8, 0.01], [62086.5, 0.005], [63671.1, 4.411], [63735.7, 9.873], [63929.8, 0.937], [64026.8, 0.248], [64508.3, 0.143], [64509.1, 0.441], [64600.9, 0.001], [64603.1, 0.0], [64605.3, 33.631], [64607.8, 1.172], [64614.2, 0.343], [64655.5, 0.386], [64669.7, 0.504], [64673.5, 0.911]], "asks": [[64675.7, 0.01], [64677.3, 0.009], [64677.9, 0.077], [64678.6, 0.59], [64687.7, 0.318], [64694.3, 0.0], [65320.3, 0.0], [65616.8, 19.1]]}
{"kind": "depth", "E": 1787095208973, "U": 11316363755688, "u": 11316363762339, "recv_ms": 1787095209042, "bids": [[1000.0, 35.76], [14173.5, 2.716], [14573.5, 1.484], [58206.1, 0.002], [62086.5, 0.002], [63574.3, 3.956], [63673.5, 0.028], [63865.1, 1.82], [63918.2, 0.783], [64026.8, 0.25], [64331.8, 0.0], [64332.4, 12.959], [64650.1, 0.096], [64655.9, 0.001], [64657.1, 0.011], [64659.2, 0.01], [64659.4, 0.005], [64660.1, 0.021], [64660.5, 1.469], [64660.7, 0.349], [64660.8, 0.016], [64660.9, 0.039], [64661.5, 0.002], [64667.0, 1.27], [64667.1, 0.628], [64667.2, 0.83], [64667.9, 0.016], [64668.0, 0.105], [64669.7, 0.071], [64669.8, 0.015], [64670.6, 0.015], [64671.3, 0.085], [64671.6, 0.002]], "asks": [[64673.6, 36.768], [64674.6, 0.091], [64675.2, 0.002], [64675.7, 0.01], [64677.3, 0.005], [64677.4, 0.102], [64684.7, 0.001], [64685.3, 0.001], [64686.6, 0.08], [64687.4, 0.716], [64688.0, 4.068], [64689.5, 0.001], [64689.6, 10.02], [64696.3, 0.426], [64697.3, 1.705], [64741.5, 0.0], [64752.5, 52.175], [65320.3, 0.0], [65482.3, 2.021], [65673.6, 0.02]]}
{"kind": "depth", "E": 1787095209075, "U": 11316363762501, "u": 11316363769600, "recv_ms": 1787095209144, "bids": [[14173.5, 2.352], [14573.5, 1.848], [58206.1, 0.002], [63962.1, 1.342], [64026.8, 0.248], [64350.1, 0.001], [64650.1, 0.096], [64655.9, 0.001], [64660.4, 4.927], [64660.7, 0.264], [64660.8, 0.009], [64661.2, 0.31], [64661.4, 0.085], [64661.5, 0.002], [64661.9, 0.003], [64667.2, 0.837], [64667.9, 0.016], [64669.7, 0.071], [64669.8, 0.015], [64671.3, 0.001], [64671.6, 0.435]], "asks": [[64674.6, 0.084], [64675.2, 0.009], [64675.7, 0.02], [64743.7, 0.005], [64752.5, 52.175], [65320.3, 0.0], [65482.0, 3.395], [65572.6, 0.882], [65572.9, 7.485], [65607.0, 10.425]]}
{"kind": "depth", "E": 1787095209177, "U": 11316363769740, "u": 11316363777965, "recv_ms": 1787095209253, "bids": [[1000.0, 35.76], [14173.5, 1.988], [14573.5, 2.212], [45275.3, 0.0], [45275.4, 0.003], [51739.0, 0.0], [58206.1, 0.002], [61439.8, 0.01], [62086.5, 0.005], [63438.9, 0.321], [63574.0, 0.646], [63673.5, 0.008], [63723.1, 10.73], [63774.8, 10.415], [64026.8, 0.248], [64350.1, 0.0], [64516.2, 6.005], [64533.2, 3.467], [64616.5, 0.034], [64617.2, 0.016], [64617.3, 7.565], [64619.6, 0.558], [64619.7, 0.026], [64622.2, 0.311], [64625.6, 1.1], [64625.7, 2.072], [64633.9, 0.001], [64634.1, 2.469], [64655.8, 0.0], [64656.2, 0.615], [64656.6, 0.021], [64659.7, 0.001], [64660.3, 0.692], [64660.5, 1.237], [64661.4, 0.085], [64667.1, 0.627], [64667.2, 0.837], [64667.5, 0.02], [64669.7, 0.071], [64670.2, 0.155], [64670.3, 0.0], [64670.4, 0.003], [64670.6, 0.015], [64671.5, 1.257], [64671.6, 0.002], [64673.5, 0.913]], "asks": [[64673.6, 36.305], [64673.8, 0.015], [64674.6, 0.084], [64675.1, 0.01], [64675.2, 0.025], [64675.7, 0.01], [64676.4, 0.002], [64677.3, 0.006], [64677.9, 0.618], [64678.0, 2.504], [64678.6, 0.026], [64679.0, 4.419], [64697.0, 0.336], [64700.9, 0.06], [64701.1, 1.955], [64709.3, 0.448], [64709.5, 1.97], [64717.7, 2.08], [64717.9, 5.473], [64745.9, 54.516], [64752.5, 0.001], [64814.1, 5.4], [64997.0, 0.202], [65320.3, 0.002], [65320.4, 0.173], [65482.0, 3.509], [65673.6, 0.0], [65773.1, 5.449]]}
{"kind": "depth", "E": 1787095209279, "U": 11316363778004, "u": 11316363786449, "recv_ms": 1787095209349, "bids": [[1000.0, 35.76], [14173.5, 1.638], [14573.5, 2.562], [58206.1, 0.002], [61439.8, 0.01], [62086.5, 0.002], [63673.5, 0.028], [64026.8, 0.248], [64642.6, 0.016], [64650.1, 0.096], [64654.8, 0.002], [64655.6, 0.012], [64657.5, 0.269], [64659.6, 0.413], [64660.1, 0.014], [64660.7, 0.573], [64660.8, 0.55], [64661.0, 0.0], [64661.2, 0.001], [64661.4, 0.092], [64667.0, 1.354], [64667.2, 0.289], [64667.5, 0.017], [64667.9, 0.016], [64668.4, 0.088], [64669.7, 0.063], [64669.8, 0.015], [64669.9, 0.125], [64670.0, 0.005], [64670.8, 0.005], [64673.5, 0.883]], "asks": [[64673.6, 36.388], [64674.4, 0.311], [64675.1, 0.095], [64675.2, 0.566], [64675.4, 1.472], [64675.7, 0.01], [64675.8, 1.395], [64676.4, 0.001], [64677.3, 0.002], [64677.4, 0.109], [64677.9, 0.0], [64678.6, 0.018], [64697.6, 0.139], [64705.0, 0.001], [64869.9, 5.426], [65320.3, 0.0], [65611.4, 3.35], [65673.6, 0.02]]}
{"kind": "depth", "E": 1787095209381, "U": 11316363786607, "u": 11316363794506, "recv_ms": 1787095209450, "bids": [[14173.5, 1.288], [14573.5, 2.912], [58206.1, 0.002], [61439.8, 0.012], [62086.5, 0.005], [63722.8, 1.253], [63774.5, 2.347], [64026.8, 0.248], [64350.1, 0.01], [64616.5, 0.033], [64622.2, 0.312], [64669.7, 0.071], [64669.9, 0.001], [64671.6, 0.002]], "asks": [[64673.6, 36.388], [64675.7, 0.02], [64677.2, 0.002], [64683.6, 0.498], [64687.0, 0.165], [64743.7, 52.179], [64745.9, 2.342], [65320.3, 0.0], [65611.4, 4.415], [67912.9, 0.068]]}
{"kind": "depth", "E": 1787095209483, "U": 11316363794547, "u": 11316363802035, "recv_ms": 1787095209553, "bids": [[1000.0, 35.76], [14173.5, 0.924], [14573.5, 3.276], [51738.8, 0.0], [58206.1, 0.002], [62086.5, 0.002], [63909.2, 7.506], [64026.8, 0.248], [64533.2, 0.0], [64667.6, 0.003], [64667.7, 1.228], [64669.7, 0.071], [64670.6, 0.015], [64671.6, 0.002]], "asks": [[64718.6, 0.01], [64725.2, 0.211], [64814.1, 0.0], [65320.3, 0.0], [65482.0, 3.738], [65572.9, 5.963]]}
{"kind": "depth", "E": 1787095209585, "U": 11316363802243, "u": 11316363808753, "recv_ms": 1787095209653, "bids": [[1000.0, 35.76], [14173.5, 0.574], [14573.5, 3.626], [51739.0, 0.0], [58206.1, 0.002], [61439.8, 0.014], [63673.5, 0.008], [63917.1, 2.738], [64026.8, 0.248], [64533.2, 4.53], [64595.8, 0.152], [64666.7, 0.152], [64671.6, 0.435]], "asks": [[64673.6, 36.351], [64675.7, 0.01], [64677.3, 0.006], [64814.1, 5.4], [64869.9, 5.64], [65320.3, 0.0], [65673.6, 0.0]]}
{"kind": "depth", "E": 1787095209687, "U": 11316363808774, "u": 11316363816360, "recv_ms": 1787095209755, "bids": [[14173.5, 0.322], [14473.5, 0.112], [14573.5, 3.766], [58206.1, 0.002], [61439.8, 0.014], [62086.5, 0.005], [63673.5, 0.028], [63768.1, 3.767], [64026.8, 0.248], [64350.1, 0.01], [64508.3, 0.104], [64509.1, 0.48], [64670.4, 0.087], [64670.6, 0.015], [64671.6, 0.435], [64673.5, 0.882]], "asks": [[64673.6, 36.371], [64674.1, 0.067], [64675.7, 0.01], [64677.3, 0.002], [64783.6, 0.004], [64869.9, 11.451], [64997.0, 0.201], [65123.3, 0.0], [65320.3, 0.0], [65673.6, 0.02]]}
{"kind": "depth", "E": 1787095209789, "U": 11316363816457, "u": 11316363821553, "recv_ms": 1787095209859, "bids": [[1000.0, 35.76], [14173.5, 0.224], [14473.5, 0.35], [14573.5, 3.626], [58206.1, 0.002], [62086.5, 0.002], [63903.9, 1.876], [64026.8, 0.248], [64350.1, 0.011], [64477.5, 1.92], [64508.3, 0.143], [64509.1, 0.441], [64563.5, 0.003], [64563.7, 0.001], [64565.2, 2.346], [64595.8, 0.149], [64607.8, 5.939], [64628.2, 0.005], [64665.9, 0.127], [64669.7, 0.504], [64670.9, 0.084], [64671.6, 0.002]], "asks": [[64675.1, 0.01], [64675.2, 0.643], [64675.4, 1.162], [64675.7, 0.02], [64677.9, 0.008], [64731.9, 0.006], [64742.9, 9.768], [64751.3, 0.001], [64779.0, 0.015], [64779.1, 4.887], [64783.6, 0.001], [64814.0, 1.714], [64814.3, 0.001], [64869.9, 5.427], [65127.1, 0.115], [65288.3, 14.399], [65320.3, 0.0], [65572.6, 2.404], [65607.0, 9.359], [65671.7, 7.782]]}
{"kind": "depth", "E": 1787095209891, "U": 11316363821682, "u": 11316363828643, "recv_ms": 1787095209960, "bids": [[1000.0, 35.76], [14173.5, 0.084], [14473.5, 0.588], [14573.5, 3.528], [58206.1, 0.002], [61439.8, 0.014], [62086.5, 0.005], [63763.8, 22.409], [63860.8, 9.509], [63916.8, 0.547], [64026.8, 0.25], [64600.9, 33.446], [64602.4, 0.081], [64605.3, 0.186], [64607.8, 1.172], [64669.7, 0.071]], "asks": [[64673.6, 36.371], [64675.1, 0.551], [64675.2, 0.086], [64675.7, 0.01], [64677.3, 0.002], [64677.9, 0.008], [64705.6, 1.4], [65320.3, 0.0]]}
{"kind": "depth", "E": 1787095209993, "U": 11316363828698, "u": 11316363837475, "recv_ms": 1787095210062, "bids": [[14173.5, 0.0], [14473.5, 0.854], [14573.5, 3.346], [58206.1, 0.002], [63673.5, 0.008], [63792.8, 2.501], [63961.1, 0.98], [64026.8, 0.248], [64046.5, 1.895], [64332.4, 12.467], [64332.7, 0.492], [64350.1, 0.001], [64401.9, 0.079], [64600.9, 0.001], [64603.1, 0.0], [64605.3, 33.862], [64657.1, 0.011], [64669.7, 0.071]], "asks": [[64673.9, 0.002], [64675.1, 0.01], [64675.2, 0.643], [64677.9, 0.008], [64679.0, 4.411], [64689.6, 10.02], [64705.7, 1.886], [65320.3, 0.0], [65559.9, 1.826], [65673.6, 0.0], [65673.8, 9.581], [67912.9, 0.063]]}
{"kind": "depth", "E": 1787095210095, "U": 11316363837726, "u": 11316363846177, "recv_ms": 1787095210165, "bids": [[1000.0, 35.76], [14473.5, 1.204], [14573.5, 2.996], [58206.1, 0.002], [61439.8, 0.014], [62086.5, 0.002], [64026.8, 0.248], [64533.2, 4.53], [64605.6, 0.078], [64623.3, 0.086], [64624.8, 0.002], [64625.6, 1.039], [64661.9, 0.003], [64666.5, 0.004], [64666.6, 0.797], [64667.1, 0.086], [64667.8, 2.097], [64669.7, 0.071], [64670.8, 0.005]], "asks": [[64673.6, 36.387], [64674.0, 0.059], [64674.1, 0.008], [64675.1, 0.551], [64675.2, 0.102], [64677.3, 0.002], [64677.9, 0.008], [64690.1, 0.006], [64691.8, 0.445], [64692.8, 0.926], [64695.4, 0.662], [64699.2, 1.465], [64705.3, 0.104], [64705.7, 2.04], [64711.8, 0.003], [64726.8, 0.062], [64729.2, 0.012], [64814.1, 5.4], [64869.9, 5.93], [65288.0, 12.682], [65320.3, 0.0], [65381.6, 3.283], [65559.6, 0.61], [65611.4, 5.48], [65676.0, 2.148]]}
{"kind": "depth", "E": 1787095210197, "U": 11316363846610, "u": 11316363855043, "recv_ms": 1787095210266, "bids": [[1000.0, 35.76], [14473.5, 1.568], [14573.5, 2.632], [58206.1, 0.002], [61439.8, 0.012], [61439.9, 0.006], [62086.5, 0.005], [63673.5, 0.028], [63787.5, 0.637], [63860.8, 9.158], [63958.5, 0.47], [64026.8, 0.248], [64046.2, 0.935], [64516.2, 0.0], [64533.2, 0.0], [64622.2, 0.313], [64650.1, 0.096], [64655.6, 0.012], [64660.1, 0.473], [64660.3, 0.233], [64660.9, 0.039], [64661.4, 0.092], [64664.4, 0.781], [64666.5, 0.004], [64666.6, 0.797], [64666.7, 0.155], [64666.8, 0.002], [64666.9, 0.245], [64667.9, 0.016], [64669.7, 0.071], [64669.8, 0.015], [64669.9, 0.001], [64670.4, 0.003], [64670.9, 0.0], [64673.5, 0.793]], "asks": [[64673.6, 37.504], [64674.0, 0.0], [64675.0, 0.395], [64675.1, 0.551], [64675.2, 0.102], [64677.3, 0.002], [64677.9, 0.008], [64685.0, 4.001], [64689.6, 0.02], [64695.3, 0.057], [64696.2, 0.463], [64814.0, 0.0], [64814.1, 0.0], [64831.1, 0.001], [64997.0, 0.2], [65320.3, 0.002], [65320.4, 0.172], [65528.4, 0.003], [65673.6, 0.02], [65676.0, 3.06]]}
{"kind": "depth", "E": 1787095210299, "U": 11316363855055, "u": 11316363863798, "recv_ms": 1787095210380, "bids": [[14473.5, 1.932], [14573.5, 2.268], [51739.0, 0.0], [58206.1, 0.002], [61439.8, 0.012], [62086.5, 0.002], [63509.4, 4.435], [63673.5, 0.008], [64026.8, 0.248], [64350.1, 0.002], [64516.2, 7.538], [64533.2, 4.394], [64650.1, 0.096], [64655.6, 0.012], [64657.1, 0.011], [64660.9, 0.039], [64661.4, 0.092], [64664.4, 0.163], [64667.1, 0.627], [64667.8, 1.556], [64667.9, 0.016], [64669.7, 0.071], [64670.6, 0.015], [64672.2, 0.0], [64672.3, 0.002]], "asks": [[64673.6, 36.387], [64674.1, 0.009], [64674.5, 0.076], [64675.1, 0.01], [64675.2, 0.102], [64677.2, 0.006], [64677.3, 0.002], [64677.9, 0.549], [64678.6, 0.018], [64684.7, 0.009], [64685.7, 0.003], [64686.6, 0.072], [64688.0, 2.643], [64693.1, 0.619], [64741.5, 51.598], [64742.9, 2.227], [64743.7, 0.005], [64814.1, 5.4], [64831.1, 10.413], [64869.9, 6.881], [65320.3, 0.0], [65673.6, 0.0]]}
{"kind": "depth", "E": 1787095210401, "U": 11316363863988, "u": 11316363871347, "recv_ms": 1787095210469, "bids": [[1000.0, 35.76], [14473.5, 2.282], [14573.5, 1.918], [51739.0, 0.0], [58206.1, 0.002], [61439.8, 0.01], [61439.9, 0.008], [62086.5, 0.005], [63723.1, 9.399], [63962.1, 1.576], [64026.8, 0.248], [64670.2, 0.239]], "asks": [[64675.0, 0.085], [65320.3, 0.0], [65385.0, 5.298], [67912.9, 0.058]]}
{"kind": "depth", "E": 1787095210503, "U": 11316363871411, "u": 11316363880295, "recv_ms": 1787095210579, "bids": [[1000.0, 35.76], [14473.5, 2.646], [14573.5, 1.554], [51738.8, 0.0], [58206.1, 0.002], [61439.9, 0.006], [63673.5, 0.028], [63958.5, 0.236], [63968.9, 11.375], [64026.8, 0.248], [64087.4, 0.0], [64498.5, 0.567], [64508.3, 0.104], [64509.1, 0.48], [64620.2, 0.628], [64660.7, 0.557], [64661.4, 0.108], [64671.9, 0.041]], "asks": [[64675.2, 0.11], [64677.9, 0.541], [64684.2, 0.001], [64684.5, 0.159], [64869.9, 5.322], [65320.3, 0.0], [65515.4, 1.068], [65673.6, 0.02]]}
{"kind": "depth", "E": 1787095210605, "U": 11316363880359, "u": 11316363887329, "recv_ms": 1787095210674, "bids": [[14473.5, 2.996], [14573.5, 1.204], [51739.0, 0.0], [58206.1, 0.002], [61439.8, 0.01], [62086.5, 0.002], [63722.8, 2.584], [64026.8, 0.248], [64156.1, 0.0], [64350.1, 0.012], [64508.3, 0.143], [64509.1, 0.441], [64600.0, 1.793], [64655.8, 0.557], [64656.2, 0.058], [64670.3, 0.433], [64670.4, 0.003]], "asks": [[64673.6, 36.399], [64675.7, 0.02], [64677.2, 0.002], [64677.3, 0.006], [64679.0, 4.409], [64679.8, 0.002], [65320.3, 0.0], [65611.4, 6.24]]}
{"kind": "depth", "E": 1787095210707, "U": 11316363887537, "u": 11316363894106, "recv_ms": 1787095210777, "bids": [[1000.0, 35.76], [14473.5, 3.36], [14573.5, 0.84], [58206.1, 0.002], [62086.5, 0.005], [63962.1, 1.81], [64026.8, 0.248], [64090.6, 0.235], [64618.0, 0.009], [64650.1, 0.096], [64652.7, 0.119], [64653.6, 0.083], [64655.3, 2.519], [64655.8, 0.0], [64655.9, 0.001], [64656.8, 0.173], [64657.5, 0.115], [64659.3, 0.392], [64660.1, 0.014], [64660.3, 1.001], [64660.7, 0.248], [64660.9, 0.039], [64661.4, 0.108], [64666.5, 0.007], [64666.7, 0.152], [64667.1, 0.086], [64667.8, 1.548], [64667.9, 0.557], [64668.0, 0.113], [64669.5, 0.009], [64669.7, 0.063], [64670.3, 0.0]], "asks": [[64675.7, 0.01], [64685.9, 0.112], [64688.1, 0.003], [64691.7, 0.0], [64692.0, 4.349], [64692.6, 0.614], [64692.8, 1.385], [64695.5, 0.002], [64696.9, 0.557], [65320.3, 0.0], [65519.9, 12.876]]}
{"kind": "depth", "E": 1787095210809, "U": 11316363894357, "u": 11316363901400, "recv_ms": 1787095210877, "bids": [[1000.0, 35.76], [14373.5, 0.014], [14473.5, 3.682], [14573.5, 0.504], [51739.0, 0.0], [58206.1, 0.002], [61439.8, 0.01], [62086.5, 0.002], [63673.5, 0.008], [63968.6, 1.716], [64026.8, 0.248], [64350.1, 0.011], [64496.3, 0.008], [64600.9, 33.677], [64605.3, 0.186], [64607.8, 1.172], [64625.7, 1.972], [64638.5, 0.002], [64669.5, 0.001], [64669.7, 0.071], [64670.3, 0.0], [64670.4, 0.003], [64672.1, 0.042]], "asks": [[64673.6, 36.4], [64675.7, 0.02], [64677.3, 0.002], [64679.0, 4.408], [64680.4, 0.024], [64739.2, 1.748], [64741.5, 0.0], [64752.5, 51.599], [64814.0, 1.714], [64997.0, 0.201], [65320.3, 0.0], [65445.3, 14.619], [65673.6, 0.0]]}
{"kind": "depth", "E": 1787095210911, "U": 11316363901404, "u": 11316363910756, "recv_ms": 1787095210981, "bids": [[14373.5, 0.168], [14473.5, 3.738], [14573.5, 0.294], [58206.1, 0.002], [61439.8, 0.01], [62086.5, 0.005], [63443.1, 0.195], [63917.1, 2.191], [64026.8, 0.248], [64087.9, 2.726], [64332.6, 0.493], [64332.7, 0.0], [64350.1, 0.011], [64600.9, 0.001], [64605.3, 34.141], [64612.4, 0.03], [64633.7, 0.001], [64638.5, 0.156], [64641.5, 0.002], [64650.1, 0.096], [64655.6, 0.012], [64660.7, 0.248], [64661.4, 0.108], [64662.8, 0.003], [64663.3, 0.019], [64664.2, 0.276], [64665.3, 0.243], [64667.7, 1.21], [64668.0, 0.113], [64669.7, 0.071], [64670.3, 0.433], [64671.9, 0.001], [64672.0, 0.044]], "asks": [[64673.6, 36.4], [64675.1, 0.628], [64675.2, 0.009], [64677.3, 0.002], [64677.9, 0.0], [64678.6, 0.042], [64693.1, 0.001], [64741.5, 50.98], [64752.5, 0.001], [64869.9, 5.481], [65320.3, 0.0], [67907.2, 0.005]]}
{"kind": "depth", "E": 1787095211013, "U": 11316363910984, "u": 11316363918878, "recv_ms": 1787095211083, "bids": [[1000.0, 35.76], [14373.5, 0.406], [14473.5, 3.612], [14573.5, 0.182], [58206.1, 0.002], [63673.5, 0.028], [63897.1, 0.0], [64026.8, 0.248], [64563.5, 0.0], [64628.2, 0.008], [64638.4, 1.29], [64638.5, 0.002], [64657.1, 0.011], [64670.3, 0.433]], "asks": [[64674.4, 0.338], [64675.1, 0.094], [64675.2, 0.567], [64677.4, 0.102], [64677.9, 0.0], [64678.6, 0.018], [64689.6, 0.02], [64731.9, 0.006], [64869.9, 6.262], [65320.3, 0.0], [65673.6, 0.02]]}
{"kind": "depth", "E": 1787095211115, "U": 11316363919161, "u": 11316363925912, "recv_ms": 1787095211183, "bids": [[1000.0, 35.76], [14373.5, 0.644], [14473.5, 3.5], [14573.5, 0.056], [51739.0, 0.002], [58206.1, 0.002], [62086.5, 0.002], [63830.6, 7.588], [63916.8, 1.094], [64026.8, 0.248], [64091.4, 19.547], [64508.3, 0.143], [64509.1, 0.441], [64595.8, 0.152], [64616.5, 0.032], [64638.4, 1.136], [64660.5, 1.24], [64661.9, 0.003], [64670.3, 0.0]], "asks": [[64674.8, 0.006], [64675.1, 0.551], [64675.2, 0.11], [64677.9, 0.0], [64751.3, 0.004], [65320.3, 0.0], [65477.7, 10.196], [67253.8, 0.636]]}
{"kind": "depth", "E": 1787095211217, "U": 11316363926026, "u": 11316363934585, "recv_ms": 1787095211291, "bids": [[14373.5, 0.938], [14473.5, 3.262], [14573.5, 0.0], [45275.4, 0.0], [50000.0, 233.344], [51739.0, 0.0], [58206.1, 0.002], [61439.8, 0.01], [62086.5, 0.005], [63673.5, 0.008], [64026.8, 0.248], [64350.1, 0.01], [64533.2, 3.649], [64622.2, 0.314], [64624.9, 0.054], [64638.3, 0.165], [64658.8, 0.623], [64666.2, 0.626], [64670.6, 0.015], [64673.5, 0.798]], "asks": [[64673.6, 36.406], [64674.1, 0.002], [64674.3, 0.007], [64674.8, 0.005], [64675.1, 0.01], [64675.2, 0.651], [64675.5, 0.311], [64675.7, 0.02], [64675.8, 1.394], [64677.3, 0.002], [64677.9, 0.0], [64678.2, 0.127], [64678.6, 0.018], [64681.5, 0.039], [64687.4, 1.334], [64694.8, 8.023], [64701.6, 0.136], [64715.6, 2.323], [64723.6, 0.025], [64743.5, 0.048], [64814.0, 0.0], [64814.1, 5.4], [64869.9, 5.397], [65320.3, 0.0], [65381.8, 0.0], [65673.6, 0.0]]}
{"kind": "depth", "E": 1787095211319, "U": 11316363934602, "u": 11316363942743, "recv_ms": 1787095211389, "bids": [[1000.0, 35.76], [14373.5, 1.302], [14473.5, 2.898], [58206.1, 0.002], [61439.8, 0.01], [62086.5, 0.002], [63832.7, 2.895], [64026.8, 0.248], [64087.9, 2.492], [64477.4, 12.895], [64477.5, 1.14], [64516.2, 7.042], [64533.2, 4.52], [64600.9, 33.956], [64605.3, 0.186], [64611.4, 0.828], [64620.7, 0.101], [64650.1, 0.251], [64655.6, 0.167], [64660.7, 0.403], [64661.4, 0.263], [64668.0, 0.268], [64669.7, 0.226], [64673.5, 0.856]], "asks": [[64673.6, 36.405], [64675.7, 0.02], [64676.0, 1.133], [64677.3, 0.006], [64684.7, 0.001], [64685.0, 0.001], [64686.2, 0.011], [64688.0, 3.975], [64688.2, 10.004], [64869.9, 7.242], [64997.0, 0.202], [65320.3, 0.0], [67912.9, 0.053]]}
{"kind": "depth", "E": 1787095211421, "U": 11316363942863, "u": 11316363949500, "recv_ms": 1787095211493, "bids": [[1000.0, 35.76], [14373.5, 1.652], [14473.5, 2.548], [58206.1, 0.002], [63673.5, 0.028], [64026.8, 0.248], [64350.1, 0.01], [64533.2, 0.0], [64600.9, 0.001], [64603.1, 33.955], [64650.1, 0.096], [64655.6, 0.012], [64660.7, 0.248], [64661.4, 0.108], [64668.0, 0.113], [64669.7, 0.071], [64669.8, 0.015], [64670.6, 0.015]], "asks": [[64675.1, 0.01], [64675.2, 0.002], [64675.5, 0.001], [64675.7, 0.01], [64677.9, 0.649], [64718.0, 0.305], [64725.2, 0.001], [64741.5, 0.0], [64743.7, 50.985], [64752.5, 0.001], [64798.6, 24.185], [64806.6, 0.002], [64814.1, 0.0], [65288.3, 13.635], [65320.3, 0.0], [65385.7, 0.23], [65673.6, 0.02]]}
{"kind": "depth", "E": 1787095211523, "U": 11316363949754, "u": 11316363958432, "recv_ms": 1787095211593, "bids": [[14373.5, 2.016], [14473.5, 2.184], [51738.8, 0.0], [58206.1, 0.002], [61439.8, 0.01], [62086.5, 0.005], [63673.5, 0.008], [64026.8, 0.248], [64516.2, 7.042], [64516.9, 2.1], [64533.2, 4.52], [64660.1, 0.473], [64660.3, 0.542], [64667.1, 0.627], [64667.9, 0.024], [64668.0, 0.105], [64670.3, 0.435], [64673.5, 0.854]], "asks": [[64675.1, 0.01], [64675.2, 0.002], [64675.7, 0.02], [64677.3, 0.002], [64677.9, 0.649], [64718.0, 0.095], [64724.8, 1.482], [64814.1, 5.4], [64831.1, 10.413], [64869.9, 7.243], [65320.3, 0.0], [65673.6, 0.0]]}
{"kind": "depth", "E": 1787095211625, "U": 11316363958555, "u": 11316363965424, "recv_ms": 1787095211702, "bids": [[1000.0, 35.76], [14373.5, 2.38], [14473.5, 1.82], [58206.1, 0.002], [61439.8, 0.01], [62086.5, 0.002], [63768.1, 3.955], [63860.8, 8.893], [63865.1, 2.054], [64026.8, 0.248], [64091.4, 19.781], [64533.2, 4.52], [64608.8, 0.016], [64667.1, 0.086], [64667.9, 0.565], [64670.3, 0.435], [64670.6, 0.015], [64673.5, 0.853]], "asks": [[64675.1, 0.551], [64675.2, 0.11], [64677.3, 0.006], [64677.9, 0.0], [64678.4, 0.012], [64738.3, 0.034], [64740.4, 0.0], [64814.1, 5.4], [64869.9, 6.676], [65288.0, 13.446], [65320.3, 0.0]]}
{"kind": "depth", "E": 1787095211727, "U": 11316363965542, "u": 11316363973645, "recv_ms": 1787095211797, "bids": [[1000.0, 35.76], [14373.5, 2.73], [14473.5, 1.47], [51739.0, 0.0], [58206.1, 0.002], [61439.8, 0.011], [62086.5, 0.005], [63673.5, 0.028], [63699.2, 12.681], [63865.1, 2.319], [64026.8, 0.248], [64156.1, 0.007], [64350.1, 0.01], [64533.2, 4.52], [64563.5, 0.003], [64634.6, 0.288], [64650.1, 0.096], [64655.3, 1.962], [64655.6, 0.012], [64656.4, 0.627], [64659.4, 0.005], [64660.1, 0.014], [64660.3, 1.001], [64660.7, 0.248], [64660.8, 0.11], [64661.4, 0.0], [64666.5, 0.003], [64666.7, 0.152], [64666.8, 0.003], [64667.0, 1.271], [64667.1, 0.637], [64667.9, 0.565], [64668.0, 0.105], [64669.7, 0.063], [64670.1, 0.311], [64670.3, 0.443], [64670.4, 0.003], [64671.0, 0.087], [64671.4, 0.084]], "asks": [[64673.6, 36.281], [64675.1, 0.033], [64675.2, 0.543], [64675.7, 0.01], [64675.8, 1.391], [64677.3, 0.002], [64677.9, 0.085], [64686.2, 0.003], [64686.6, 0.08], [64687.4, 0.716], [64689.8, 0.132], [64691.9, 0.387], [64692.8, 1.385], [64741.5, 50.98], [64743.7, 0.005], [64783.6, 0.004], [64814.1, 5.4], [64869.9, 6.604], [65307.7, 2.821], [65320.3, 0.0], [65673.6, 0.02], [67912.9, 0.048]]}
{"kind": "depth", "E": 1787095211829, "U": 11316363973749, "u": 11316363980173, "recv_ms": 1787095211898, "bids": [[14373.5, 3.08], [14473.5, 1.12], [58206.1, 0.002], [61439.8, 0.008], [61439.9, 0.008], [62086.5, 0.002], [63442.5, 0.0], [64026.8, 0.248], [64350.1, 0.011], [64603.1, 34.195], [64605.2, 0.001], [64607.8, 1.172], [64634.6, 0.288], [64650.1, 0.096], [64655.1, 1.002], [64655.6, 0.012], [64660.3, 1.004], [64660.7, 0.248], [64668.0, 0.105], [64669.7, 0.063], [64670.3, 0.443], [64670.4, 0.003], [64670.8, 0.005], [64673.5, 0.854]], "asks": [[64673.6, 35.081], [64677.3, 0.006], [64694.8, 7.405], [64739.2, 1.748], [64741.5, 0.0], [64752.5, 50.181], [64814.0, 1.714], [64831.1, 0.001], [64831.8, 8.798], [64869.9, 0.018], [64870.6, 1.786], [64997.0, 0.201], [65320.3, 0.0]]}
{"kind": "depth", "E": 1787095211931, "U": 11316363980349, "u": 11316363987636, "recv_ms": 1787095212001, "bids": [[1000.0, 35.76], [14373.5, 3.444], [14473.5, 0.756], [58206.1, 0.002], [61439.8, 0.008], [63673.5, 0.008], [63865.1, 2.67], [64026.8, 0.248], [64332.6, 0.001], [64332.7, 0.492], [64603.1, 0.0], [64605.3, 34.381], [64630.6, 0.008], [64634.6, 0.26], [64635.5, 2.0], [64636.8, 2.459], [64650.1, 0.251], [64652.7, 0.003], [64654.3, 0.117], [64655.5, 0.386], [64655.6, 0.167], [64656.4, 0.07], [64657.0, 1.459], [64659.8, 0.003], [64660.3, 0.236], [64660.7, 0.403], [64660.8, 0.094], [64660.9, 0.498], [64661.4, 0.171], [64661.8, 0.309], [64663.4, 0.001], [64664.4, 0.317], [64667.1, 0.086], [64667.2, 0.289], [64667.3, 0.084], [64667.5, 0.02], [64667.7, 1.213], [64667.8, 2.096], [64667.9, 0.557], [64668.0, 0.26], [64669.4, 1.528], [64669.7, 0.218], [64670.3, 0.002], [64670.4, 0.011], [64671.4, 0.0], [64671.6, 0.002], [64673.4, 0.004], [64673.5, 1.908]], "asks": [[64673.8, 0.099], [64677.3, 0.002], [64679.5, 0.001], [64679.9, 0.015], [64680.4, 0.333], [64680.5, 0.002], [64685.9, 0.105], [64686.6, 0.072], [64686.8, 0.011], [64687.2, 0.17], [64687.4, 0.098], [64688.0, 2.643], [64688.2, 0.004], [64689.9, 0.636], [64690.1, 0.004], [64691.3, 1.926], [64692.7, 4.002], [64692.8, 0.926], [64693.4, 0.459], [64696.3, 0.31], [64697.1, 0.221], [64698.0, 0.226], [64698.6, 0.014], [64705.6, 3.285], [64705.7, 0.155], [64741.5, 50.18], [64743.7, 0.005], [64752.5, 0.001], [64779.7, 0.003], [64831.1, 10.413], [64831.8, 2.73], [64869.9, 6.604], [64870.6, 0.0], [64950.0, 26.933], [65252.4, 0.92], [65307.4, 0.611], [65320.3, 0.0], [65673.6, 0.0]]}
{"kind": "depth", "E": 1787095212033, "U": 11316363987859, "u": 11316363996196, "recv_ms": 1787095212103, "bids": [[1000.0, 35.76], [14273.5, 0.042], [14373.5, 3.71], [14473.5, 0.448], [58206.1, 0.002], [61439.8, 0.006], [61439.9, 0.008], [62086.5, 0.005], [64026.8, 0.248], [64350.1, 0.001], [64621.7, 0.015], [64650.1, 0.096], [64652.7, 0.0], [64655.6, 0.012], [64657.1, 0.011], [64659.2, 0.013], [64660.4, 5.386], [64660.7, 0.248], [64660.9, 0.039], [64661.4, 0.016], [64661.9, 0.008], [64666.8, 0.002], [64666.9, 0.246], [64667.1, 0.634], [64667.2, 0.289], [64667.3, 0.087], [64667.7, 1.21], [64667.8, 1.548], [64668.0, 0.113], [64669.4, 1.52], [64669.7, 0.063], [64670.3, 0.002], [64670.4, 0.011], [64670.6, 0.099], [64671.0, 0.003], [64673.5, 1.907]], "asks": [[64674.5, 0.017], [64677.4, 0.095], [64677.5, 0.005], [64686.6, 0.08], [64687.2, 0.162], [64689.6, 0.02], [64690.5, 0.099], [64692.0, 4.351], [64692.9, 0.462], [64693.4, 0.0], [64701.0, 0.441], [65320.3, 0.0], [65609.1, 4.265]]}
{"kind": "depth", "E": 1787095212135, "U": 11316363996212, "u": 11316364003797, "recv_ms": 1787095212205, "bids": [[14273.5, 0.224], [14373.5, 3.71], [14473.5, 0.266], [51739.0, 0.0], [58206.1, 0.002], [61439.8, 0.006], [62086.5, 0.002], [63958.5, 0.002], [64026.8, 0.248], [64065.9, 0.001], [64600.8, 0.0], [64605.3, 0.186], [64606.2, 0.325], [64607.4, 34.371], [64611.4, 0.837], [64620.7, 0.001], [64622.2, 0.31], [64624.9, 0.053], [64630.0, 0.014], [64650.1, 0.096], [64655.6, 0.012], [64656.4, 0.627], [64657.0, 0.902], [64660.7, 0.248], [64661.0, 0.309], [64661.4, 0.564], [64661.5, 0.002], [64661.8, 0.0], [64661.9, 0.003], [64663.9, 0.16], [64664.4, 0.163], [64667.1, 0.086], [64668.0, 0.113], [64669.7, 0.071], [64670.3, 0.002], [64670.4, 0.003], [64670.6, 0.099]], "asks": [[64673.6, 35.081], [64675.1, 0.041], [64675.2, 0.62], [64677.4, 0.099], [64677.5, 0.001], [64677.9, 0.0], [64678.1, 0.002], [64696.7, 0.002], [65320.3, 0.0]]}
{"kind": "depth", "E": 1787095212237, "U": 11316364003981, "u": 11316364009828, "recv_ms": 1787095212306, "bids": [[1000.0, 35.76], [14273.5, 0.476], [14373.5, 3.57], [14473.5, 0.154], [51739.0, 0.0], [58206.1, 0.002], [62086.5, 0.005], [63673.5, 0.028], [64026.8, 0.248], [64563.5, 0.0], [64595.8, 0.149], [64622.1, 0.102], [64628.2, 0.005], [64650.1, 0.096], [64651.2, 1.296], [64651.4, 0.005], [64653.6, 0.199], [64654.3, 0.001], [64655.6, 0.012], [64660.3, 0.004], [64660.7, 0.48], [64660.8, 0.094], [64661.4, 0.023], [64661.5, 0.002], [64667.1, 0.627], [64668.0, 0.113], [64669.7, 0.063], [64670.3, 0.01], [64673.5, 1.908]], "asks": [[64673.6, 35.081], [64675.1, 0.033], [64675.2, 0.543], [64675.4, 1.169], [64677.2, 0.005], [64677.4, 0.095], [64677.9, 0.085], [64715.6, 2.327], [64723.6, 0.021], [64731.9, 0.003], [64751.3, 0.001], [64783.6, 0.001], [65256.3, 0.231], [65320.3, 0.0], [65611.4, 7.306], [65673.6, 0.02]]}
{"kind": "depth", "E": 1787095212339, "U": 11316364009886, "u": 11316364016188, "recv_ms": 1787095212408, "bids": [[1000.0, 35.76], [14273.5, 0.7], [14373.5, 3.472], [14473.5, 0.028], [51739.0, 0.0], [58206.1, 0.002], [63765.9, 11.905], [63943.7, 0.781], [64026.8, 0.248], [64065.6, 0.688], [64350.1, 0.011], [64533.2, 0.0], [64595.8, 0.152], [64624.8, 0.003], [64661.4, 0.557], [64667.1, 0.093], [64667.5, 0.017], [64669.7, 0.063], [64670.3, 0.002], [64670.4, 0.011], [64670.6, 0.099]], "asks": [[64675.7, 0.02], [64692.6, 0.612], [64692.7, 4.004], [64731.9, 0.006], [64814.0, 0.0], [64814.1, 0.0], [64997.0, 0.2], [65320.3, 0.0]]}
{"kind": "depth", "E": 1787095212441, "U": 11316364016279, "u": 11316364022126, "recv_ms": 1787095212511, "bids": [[14273.5, 1.022], [14373.5, 3.178], [14473.5, 0.0], [58206.1, 0.002], [61439.8, 0.006], [62086.5, 0.002], [63673.5, 0.008], [63768.1, 6.304], [63962.1, 2.044], [64026.8, 0.248], [64350.1, 0.012], [64477.4, 13.372], [64477.5, 0.022], [64516.2, 6.618], [64516.9, 1.152], [64533.2, 4.189], [64600.7, 0.097], [64603.0, 34.197], [64607.4, 0.176], [64622.1, 0.103], [64637.2, 0.042], [64650.1, 0.096], [64655.6, 0.012], [64660.7, 0.248], [64660.8, 0.094], [64661.4, 0.016], [64667.1, 0.634], [64668.0, 0.113], [64669.7, 0.071], [64670.3, 0.435], [64670.4, 0.003], [64671.2, 0.099]], "asks": [[64673.6, 35.043], [64673.8, 0.015], [64675.7, 0.01], [64677.4, 0.099], [64688.0, 3.261], [64693.0, 0.075], [64695.3, 0.675], [64814.1, 5.4], [64831.1, 10.413], [64869.9, 7.628], [65320.3, 0.0], [65430.6, 7.611], [65525.9, 3.794], [65673.6, 0.0]]}
{"kind": "depth", "E": 1787095212543, "U": 11316364022312, "u": 11316364035687, "recv_ms": 1787095212619, "bids": [[1000.0, 35.91], [14273.5, 1.386], [14373.5, 2.814], [51738.8, 0.0], [58206.1, 0.002], [61439.8, 0.006], [62086.5, 0.005], [63860.8, 8.658], [64026.8, 0.248], [64361.5, 0.006], [64401.9, 0.002], [64511.8, 0.021], [64515.1, 0.0], [64516.7, 0.014], [64516.8, 1.436], [64521.5, 2.319], [64581.4, 2.336], [64602.4, 0.004], [64603.0, 0.002], [64603.6, 1.242], [64604.0, 0.006], [64605.3, 34.381], [64605.6, 0.001], [64605.7, 0.001], [64606.2, 0.343], [64612.1, 0.002], [64612.2, 0.002], [64619.1, 0.001], [64622.1, 0.104], [64631.0, 0.0], [64632.4, 0.0], [64635.5, 0.0], [64637.2, 0.0], [64639.9, 0.001], [64641.4, 0.166], [64641.6, 2.056], [64642.8, 0.002], [64645.1, 0.0], [64645.2, 0.003], [64645.5, 2.028], [64646.7, 0.111], [64647.5, 0.113], [64649.6, 0.049], [64650.1, 0.251], [64651.1, 0.125], [64652.3, 0.043], [64653.5, 0.001], [64653.6, 0.005], [64653.7, 0.421], [64653.8, 0.434], [64654.9, 0.001], [64655.3, 2.078], [64655.4, 0.438], [64655.6, 0.012], [64656.1, 0.587], [64656.4, 0.07], [64656.8, 0.019], [64657.9, 0.312], [64658.2, 0.001], [64658.8, 0.159], [64659.4, 0.012], [64659.6, 0.963], [64659.9, 0.0], [64660.2, 0.477], [64660.4, 4.927], [64660.7, 0.403], [64660.8, 0.006], [64660.9, 0.119], [64661.0, 0.0], [64661.2, 1.001], [64661.3, 1.49], [64661.4, 0.163], [64661.5, 0.002], [64661.8, 0.0], [64661.9, 0.013], [64662.0, 0.475], [64662.2, 0.384], [64662.4, 0.008], [64662.6, 0.46], [64662.9, 0.002], [64663.1, 2.322], [64663.6, 0.389], [64663.9, 0.006], [64664.1, 0.003], [64665.2, 0.102], [64666.2, 0.008], [64666.3, 0.0], [64666.9, 0.402], [64667.1, 1.742], [64667.2, 0.437], [64667.3, 0.0], [64667.7, 1.129], [64667.8, 0.095], [64667.9, 0.016], [64668.0, 0.105], [64668.1, 0.002], [64668.3, 0.001], [64668.4, 0.004], [64668.9, 0.012], [64669.1, 0.013], [64669.2, 0.733], [64669.3, 2.794], [64669.4, 0.004], [64669.5, 0.0], [64669.6, 0.093], [64669.7, 0.545], [64669.8, 0.633], [64669.9, 0.156], [64670.2, 0.246], [64670.3, 0.49], [64670.4, 1.595], [64670.6, 0.088], [64671.0, 0.003], [64671.2, 0.096], [64671.4, 0.001], [64671.6, 0.002], [64671.7, 0.025], [64671.9, 0.084], [64672.0, 0.006], [64672.1, 0.062], [64672.2, 0.023], [64672.3, 0.022], [64672.5, 0.086], [64673.0, 0.086], [64673.2, 0.003], [64673.4, 0.092], [64673.5, 8.094]], "asks": [[64673.6, 15.581], [64673.8, 0.008], [64674.1, 0.002], [64674.2, 0.0], [64674.3, 0.0], [64674.4, 0.028], [64674.6, 0.0], [64674.8, 0.005], [64674.9, 0.0], [64675.0, 0.001], [64675.1, 0.003], [64675.2, 0.016], [64675.4, 1.045], [64675.7, 0.008], [64675.8, 1.0], [64675.9, 0.001], [64676.0, 1.016], [64676.4, 0.001], [64676.5, 0.164], [64677.2, 0.002], [64677.3, 0.086], [64677.4, 0.015], [64677.5, 0.012], [64677.7, 0.09], [64677.9, 0.0], [64678.1, 0.001], [64678.3, 0.092], [64678.4, 0.012], [64678.6, 0.521], [64678.7, 0.001], [64678.9, 0.0], [64679.0, 4.486], [64679.1, 1.4], [64679.5, 0.005], [64679.8, 0.086], [64680.0, 0.008], [64680.3, 0.002], [64680.4, 0.002], [64680.6, 0.004], [64681.3, 0.1], [64681.4, 1.163], [64681.9, 0.002], [64682.0, 2.428], [64682.1, 1.008], [64682.2, 0.312], [64682.7, 0.111], [64683.0, 0.251], [64683.9, 0.083], [64684.5, 0.151], [64684.6, 0.03], [64684.7, 0.009], [64684.8, 2.563], [64686.1, 0.042], [64686.3, 0.01], [64686.5, 0.806], [64686.6, 0.001], [64686.8, 0.004], [64686.9, 0.038], [64687.1, 0.026], [64687.4, 0.114], [64687.8, 0.009], [64688.0, 2.643], [64689.5, 0.001], [64689.6, 0.027], [64689.7, 0.082], [64689.8, 0.132], [64689.9, 0.018], [64690.3, 0.062], [64690.4, 0.094], [64690.6, 0.241], [64690.7, 0.622], [64691.3, 1.924], [64692.4, 0.323], [64692.5, 1.001], [64692.7, 0.004], [64692.8, 0.772], [64692.9, 0.005], [64693.0, 0.004], [64693.6, 0.0], [64694.0, 0.001], [64694.2, 0.04], [64694.3, 0.014], [64694.5, 3.559], [64694.7, 0.029], [64695.3, 0.0], [64695.7, 1.727], [64695.8, 0.461], [64696.6, 0.016], [64696.9, 0.001], [64697.0, 0.027], [64697.1, 0.105], [64697.4, 0.004], [64697.6, 0.05], [64697.8, 3.859], [64697.9, 0.073], [64698.4, 0.134], [64698.5, 0.112], [64698.6, 0.007], [64698.8, 0.043], [64699.1, 0.001], [64699.2, 1.311], [64699.3, 10.087], [64699.5, 0.283], [64699.8, 0.602], [64700.2, 0.128], [64700.9, 0.214], [64701.2, 0.009], [64702.7, 0.377], [64703.1, 0.004], [64703.6, 10.005], [64705.6, 3.377], [64705.7, 0.001], [64706.6, 0.01], [64708.1, 0.157], [64709.9, 0.059], [64710.2, 0.334], [64712.4, 0.422], [64717.6, 0.015], [64720.2, 0.004], [64722.8, 0.014], [64741.5, 0.0], [64747.2, 1.323], [64754.7, 50.18], [64755.8, 0.247], [64765.7, 0.002], [64798.1, 0.078], [64831.1, 0.001], [64831.7, 4.744], [64869.9, 0.018], [64870.4, 0.48], [64870.5, 1.689], [64871.9, 0.002], [65320.3, 0.0], [65477.7, 9.968]]}
{"kind": "depth", "E": 1787095212645, "U": 11316364035853, "u": 11316364042317, "recv_ms": 1787095212728, "bids": [[1000.0, 35.76], [14273.5, 1.736], [14373.5, 2.464], [51739.0, 0.0], [58206.1, 0.002], [61439.8, 0.006], [62086.5, 0.002], [63673.5, 0.028], [63902.8, 32.507], [63957.5, 0.238], [64026.8, 0.248], [64350.1, 0.012], [64361.5, 0.083], [64401.9, 0.079], [64605.3, 0.186], [64605.6, 0.174], [64607.4, 34.371], [64612.1, 0.49], [64645.6, 0.058], [64646.1, 0.0], [64646.7, 0.054], [64650.1, 0.096], [64654.9, 0.092], [64655.4, 0.283], [64658.7, 0.558], [64659.6, 0.406], [64660.7, 0.294], [64661.2, 0.001], [64661.4, 0.0], [64662.0, 1.05], [64662.2, 0.391], [64662.3, 1.001], [64662.5, 0.233], [64662.6, 0.001], [64667.2, 0.282], [64667.3, 0.0], [64667.5, 0.015], [64667.7, 1.122], [64667.8, 0.528], [64669.4, 1.086], [64669.5, 0.0], [64669.7, 0.004], [64669.8, 0.091], [64669.9, 0.001], [64670.3, 0.002], [64670.4, 0.049], [64670.5, 0.01], [64670.6, 1.634], [64671.9, 0.084], [64672.0, 0.006], [64673.5, 7.339]], "asks": [[64673.6, 14.695], [64673.8, 0.007], [64675.2, 0.016], [64676.6, 0.087], [64680.2, 0.388], [64681.0, 0.009], [64681.2, 0.492], [64681.3, 0.101], [64682.3, 0.022], [64682.7, 0.092], [64683.2, 0.253], [64683.9, 0.023], [64684.7, 0.009], [64686.3, 0.002], [64687.0, 1.073], [64687.4, 0.114], [64688.2, 0.084], [64690.1, 0.004], [64697.3, 1.762], [64698.5, 0.035], [64699.4, 4.384], [64699.5, 0.303], [64703.6, 0.005], [64720.2, 0.0], [64745.9, 52.522], [64754.7, 0.0], [64831.1, 10.413], [64831.7, 0.0], [64869.9, 5.866], [64870.5, 0.0], [64878.4, 11.956], [65320.3, 0.0], [65430.3, 0.534], [65449.7, 4.928], [65673.6, 0.02], [71141.0, 0.017]]}
{"kind": "depth", "E": 1787095212747, "U": 11316364042337, "u": 11316364048380, "recv_ms": 1787095212817, "bids": [[14273.5, 2.1], [14373.5, 2.1], [58206.1, 0.002], [62086.5, 0.005], [63755.1, 0.713], [64026.8, 0.248], [64361.5, 0.16], [64516.7, 0.033], [64605.6, 0.097], [64607.4, 0.176], [64609.7, 34.396], [64612.2, 0.04], [64644.5, 0.06], [64645.6, 0.001], [64650.1, 0.096], [64654.5, 0.181], [64655.3, 1.962], [64655.4, 0.363], [64655.6, 0.012], [64657.2, 0.618], [64658.7, 0.001], [64660.7, 0.286], [64660.9, 0.039], [64661.0, 0.459], [64661.4, 0.008], [64662.0, 0.591], [64662.2, 0.384], [64662.4, 0.008], [64667.2, 0.282], [64667.3, 0.116], [64667.8, 0.095], [64669.4, 0.545], [64669.5, 2.103], [64669.6, 0.093], [64670.4, 0.041], [64670.5, 0.002], [64670.6, 0.088], [64670.7, 0.0], [64671.1, 0.002], [64671.5, 1.049], [64671.6, 0.002], [64673.5, 7.584]], "asks": [[64673.6, 14.694], [64675.2, 0.024], [64676.8, 2.503], [64681.3, 0.102], [64681.5, 0.04], [64684.7, 0.001], [64693.7, 0.001], [64694.5, 4.018], [64694.7, 0.046], [64695.8, 0.002], [64697.4, 0.56], [64699.8, 0.046], [64720.2, 0.0], [64743.7, 50.185], [64745.9, 2.342], [64780.6, 0.001], [65320.3, 0.0], [65760.4, 0.607], [67260.5, 0.636], [67907.2, 0.01], [67912.9, 0.043], [71141.0, 0.015]]}
{"kind": "depth", "E": 1787095212849, "U": 11316364048520, "u": 11316364057006, "recv_ms": 1787095212934, "bids": [[1000.0, 35.76], [14273.5, 2.464], [14373.5, 1.736], [58206.1, 0.002], [61439.8, 0.006], [63673.5, 0.008], [63896.4, 0.875], [64026.8, 0.248], [64030.3, 0.0], [64350.1, 0.011], [64361.5, 0.237], [64477.5, 2.066], [64508.3, 0.104], [64509.1, 0.48], [64516.9, 1.995], [64605.6, 0.02], [64611.1, 7.799], [64612.1, 0.49], [64612.2, 0.04], [64640.3, 0.022], [64640.6, 0.414], [64640.7, 0.003], [64640.8, 0.013], [64644.1, 0.095], [64644.2, 0.002], [64644.3, 0.007], [64650.1, 0.096], [64653.8, 0.394], [64654.2, 0.009], [64655.6, 0.012], [64660.4, 4.907], [64660.7, 0.286], [64661.4, 0.008], [64662.0, 0.595], [64662.5, 0.001], [64663.0, 0.275], [64665.9, 0.128], [64667.0, 1.291], [64667.2, 0.282], [64667.3, 0.0], [64667.4, 0.041], [64667.8, 0.095], [64669.5, 2.087], [64669.6, 0.109], [64669.7, 0.004], [64670.2, 0.246], [64670.3, 0.002], [64670.4, 0.041], [64671.5, 1.048], [64672.1, 0.02], [64673.5, 8.22]], "asks": [[64673.6, 14.673], [64675.4, 1.038], [64676.9, 0.086], [64678.5, 0.059], [64678.8, 1.975], [64682.3, 0.019], [64691.3, 1.394], [64696.8, 0.004], [64699.4, 0.384], [64703.2, 10.006], [64742.9, 2.227], [64743.7, 0.005], [64754.7, 49.435], [64814.0, 1.714], [64831.1, 0.001], [64831.7, 5.807], [64869.9, 0.018], [64870.5, 10.863], [64997.0, 0.201], [65196.4, 7.805], [65320.3, 0.0], [65482.0, 3.966], [65673.6, 0.0]]}
{"kind": "depth", "E": 1787095212951, "U": 11316364057126, "u": 11316364062956, "recv_ms": 1787095213022, "bids": [[14273.5, 2.814], [14373.5, 1.386], [58206.1, 0.002], [62086.5, 0.002], [63574.3, 3.172], [63672.6, 0.0], [63897.4, 7.985], [63961.5, 1.108], [64026.8, 0.248], [64332.7, 0.0], [64332.8, 0.506], [64350.1, 0.001], [64508.3, 0.143], [64509.1, 0.441], [64516.7, 0.264], [64605.6, 0.001], [64650.1, 0.096], [64655.6, 0.012], [64660.7, 0.256], [64661.4, 0.0], [64661.5, 0.002], [64667.2, 0.282], [64667.3, 0.0], [64667.8, 0.636], [64669.5, 1.546], [64669.6, 0.109], [64670.3, 0.002], [64670.4, 0.003]], "asks": [[64677.6, 0.002], [64678.5, 0.227], [64681.9, 0.095], [64682.3, 0.022], [64684.7, 0.009], [64686.0, 1.023], [64687.0, 1.065], [64704.4, 0.62], [64716.6, 0.007], [64745.9, 51.777], [64754.7, 0.0], [64831.1, 10.413], [64831.7, 0.0], [64869.9, 5.866], [64870.5, 0.0], [65314.2, 0.003], [65320.3, 0.0], [65455.1, 32.557], [65760.1, 1.214]]}
{"kind": "depth", "E": 1787095213053, "U": 11316364063128, "u": 11316364070750, "recv_ms": 1787095213123, "bids": [[14273.5, 3.164], [14373.5, 1.036], [58206.1, 0.002], [61439.8, 0.006], [62086.5, 0.005], [63673.5, 0.028], [63736.0, 13.525], [63917.1, 1.644], [64026.8, 0.248], [64657.1, 0.009], [64661.0, 0.0], [64661.6, 0.518], [64661.9, 0.018], [64671.1, 0.002], [64673.4, 0.101], [64673.5, 8.221]], "asks": [[64673.7, 1.551], [64673.8, 0.009], [64676.7, 0.17], [64678.5, 0.059], [64684.0, 0.448], [64684.7, 0.55], [64686.5, 0.265], [64689.6, 0.025], [64702.2, 0.692], [64710.2, 0.214], [65191.0, 0.306], [65257.5, 0.018], [65288.3, 13.024], [65320.3, 0.0], [65673.6, 0.02]]}
{"kind": "depth", "E": 1787095213155, "U": 11316364070895, "u": 11316364076455, "recv_ms": 1787095213262, "bids": [[1000.0, 35.76], [14273.5, 3.528], [14373.5, 0.672], [58206.1, 0.002], [61439.8, 0.006], [62086.5, 0.002], [63574.0, 1.43], [63672.4, 4.234], [63673.5, 0.008], [63846.0, 0.099], [63935.1, 8.9], [64026.8, 0.406], [64593.5, 0.002], [64600.5, 2.361], [64600.7, 0.091], [64614.0, 1.001], [64614.3, 0.003], [64614.7, 0.0], [64615.0, 0.182], [64615.3, 0.002], [64629.7, 0.081], [64629.8, 0.036], [64629.9, 0.084], [64631.4, 0.184], [64631.7, 0.004], [64632.0, 1.552], [64632.3, 0.015], [64632.7, 0.06], [64646.3, 0.06], [64646.4, 0.196], [64646.5, 0.126], [64646.6, 0.006], [64646.8, 0.004], [64646.9, 0.014], [64647.0, 3.266], [64647.1, 0.002], [64647.2, 0.626], [64647.9, 0.311], [64648.3, 0.008], [64657.1, 0.011], [64661.9, 0.013], [64664.0, 0.288], [64664.8, 0.049], [64664.9, 0.283], [64665.0, 0.004], [64665.1, 0.0], [64665.2, 0.002], [64665.3, 0.043], [64665.4, 0.695], [64665.5, 0.002], [64665.6, 0.223], [64665.7, 0.001], [64665.8, 2.323], [64666.1, 0.163], [64666.4, 0.001], [64666.7, 0.12], [64667.1, 1.71], [64667.3, 0.433], [64667.4, 0.009], [64672.2, 0.066], [64673.5, 7.585]], "asks": [[64673.6, 14.72], [64676.7, 0.002], [64679.0, 4.409], [64679.5, 0.006], [64681.2, 0.46], [64681.4, 1.233], [64681.5, 0.005], [64681.8, 0.003], [64681.9, 1.153], [64682.1, 0.018], [64682.5, 0.097], [64682.7, 0.001], [64682.8, 0.268], [64682.9, 0.052], [64683.0, 0.011], [64683.1, 0.119], [64683.2, 0.003], [64683.3, 0.06], [64683.4, 0.018], [64683.5, 0.014], [64683.6, 0.428], [64683.7, 0.003], [64684.7, 0.55], [64686.3, 0.002], [64687.8, 0.001], [64689.6, 0.027], [64690.1, 0.012], [64694.7, 0.029], [64695.4, 0.679], [64698.4, 0.003], [64698.5, 0.003], [64698.8, 0.008], [64699.2, 1.273], [64699.5, 0.261], [64699.8, 0.004], [64700.0, 2.927], [64700.2, 0.008], [64700.6, 0.005], [64701.3, 0.008], [64701.5, 1.286], [64701.6, 0.016], [64701.7, 0.002], [64701.8, 0.162], [64701.9, 0.008], [64702.0, 0.097], [64702.1, 6.046], [64702.2, 0.601], [64702.3, 0.464], [64715.9, 0.396], [64716.2, 0.066], [64716.5, 0.24], [64716.8, 0.079], [64717.2, 0.007], [64831.1, 10.413], [64831.7, 0.0], [64869.9, 5.559], [64870.5, 0.0], [65320.3, 0.002], [65320.7, 0.059], [65449.7, 5.69], [65501.8, 0.002], [65574.7, 16.605], [65673.6, 0.0]]}
{"kind": "depth", "E": 1787095213257, "U": 11316364076490, "u": 11316364081239, "recv_ms": 1787095213328, "bids": [[14173.5, 0.07], [14273.5, 3.752], [14373.5, 0.378], [51739.0, 0.0], [58206.1, 0.002], [61439.8, 0.006], [61445.1, 0.004], [62086.5, 0.005], [63676.4, 15.999], [63735.7, 9.99], [63741.1, 19.053], [63893.2, 26.141], [63916.8, 1.641], [63935.1, 7.963], [64026.8, 0.404], [64350.1, 0.011], [64621.9, 0.094], [64622.1, 0.101], [64629.7, 0.082], [64630.0, 0.046], [64662.5, 0.233], [64663.0, 0.043], [64663.4, 0.071], [64663.6, 0.529], [64663.7, 0.38], [64664.0, 0.388], [64664.1, 0.103], [64664.4, 0.233], [64664.7, 0.256], [64667.3, 0.433], [64671.1, 0.002]], "asks": [[64673.6, 14.72], [64675.0, 0.005], [64679.5, 0.005], [64680.8, 0.043], [64681.1, 0.092], [64681.4, 1.353], [64681.5, 0.135], [64681.7, 0.078], [64681.9, 1.293], [64682.0, 2.505], [64698.2, 0.209], [64699.6, 0.462], [64699.9, 0.54], [64700.1, 1.043], [64700.3, 0.536], [64700.4, 0.459], [64700.5, 0.073], [64700.6, 0.082], [65258.7, 0.23], [65313.9, 0.687], [65320.3, 0.0]]}
{"kind": "depth", "E": 1787095213359, "U": 11316364081292, "u": 11316364086633, "recv_ms": 1787095213430, "bids": [[14173.5, 0.28], [14273.5, 3.682], [14373.5, 0.238], [51739.0, 0.002], [58206.1, 0.002], [61439.8, 0.006], [61439.9, 0.006], [63673.5, 0.028], [63703.4, 0.757], [63814.2, 0.855], [63929.8, 1.874], [64026.8, 0.406], [64516.2, 7.685], [64516.9, 1.152], [64533.2, 5.001], [64621.9, 0.095], [64630.3, 0.272], [64630.6, 0.04], [64630.7, 0.13], [64631.3, 0.032], [64655.5, 0.387], [64658.7, 0.008], [64659.4, 0.005], [64661.3, 1.942], [64661.6, 0.059], [64662.2, 0.075], [64662.9, 0.009], [64663.9, 0.515], [64664.2, 0.346], [64664.3, 0.115], [64665.0, 0.036], [64665.3, 0.075], [64665.4, 0.967], [64666.0, 0.376], [64667.3, 0.0], [64669.6, 0.542], [64669.7, 0.001], [64670.0, 0.008], [64673.0, 0.002], [64673.4, 0.017]], "asks": [[64673.6, 14.721], [64675.6, 0.084], [64676.0, 1.1], [64679.1, 1.398], [64679.5, 0.037], [64679.8, 0.002], [64680.2, 0.736], [64680.5, 0.044], [64681.2, 0.671], [64681.3, 0.104], [64681.6, 0.271], [64682.1, 0.003], [64682.2, 0.003], [64682.7, 0.31], [64684.6, 0.107], [64685.4, 0.459], [64686.5, 0.188], [64690.7, 0.004], [64691.0, 0.671], [64693.9, 0.463], [64694.5, 3.559], [64696.9, 0.033], [64697.5, 0.13], [64697.8, 3.901], [64698.1, 0.187], [64698.5, 0.123], [64699.0, 0.262], [64699.1, 0.008], [64699.5, 0.145], [64699.8, 0.095], [64700.1, 1.163], [64700.2, 0.001], [64790.6, 0.217], [64814.0, 0.0], [64814.1, 0.0], [64814.2, 5.4], [64831.1, 0.001], [64831.7, 5.839], [64869.9, 4.512], [65288.0, 14.057], [65320.3, 0.0], [65673.6, 0.02], [67907.2, 0.015]]}
{"kind": "depth", "E": 1787095213461, "U": 11316364086650, "u": 11316364091767, "recv_ms": 1787095213531, "bids": [[1000.0, 35.76], [14173.5, 0.518], [14273.5, 3.556], [14373.5, 0.126], [51739.0, 0.0], [58206.1, 0.002], [62086.5, 0.002], [63444.7, 0.963], [63865.1, 2.935], [63865.4, 9.843], [64026.8, 0.404], [64350.1, 0.01], [64630.9, 0.057], [64650.1, 0.096], [64655.6, 0.012], [64656.9, 1.186], [64657.2, 0.061], [64660.7, 0.248], [64661.0, 0.459], [64661.3, 1.483], [64661.4, 0.008], [64661.5, 0.002], [64663.5, 0.701], [64663.7, 0.45], [64663.8, 0.286], [64664.2, 0.446], [64665.7, 0.033], [64667.2, 0.282], [64669.6, 0.109], [64669.8, 0.094], [64670.0, 0.005], [64670.3, 0.086], [64670.4, 0.041], [64671.2, 0.096], [64672.8, 0.0]], "asks": [[64675.1, 0.087], [64679.4, 0.31], [64679.8, 0.037], [64681.3, 0.224], [64681.7, 0.228], [64681.8, 0.087], [64682.0, 2.596], [64689.9, 0.0], [64690.5, 0.117], [64696.1, 0.436], [64697.2, 0.037], [64697.3, 1.705], [64699.9, 0.66], [64700.2, 0.151], [64700.4, 0.543], [64700.5, 0.164], [64790.6, 0.117], [64831.1, 10.413], [64831.7, 0.0], [64997.0, 0.202], [65320.3, 0.0]]}
{"kind": "depth", "E": 1787095213563, "U": 11316364091977, "u": 11316364097039, "recv_ms": 1787095213633, "bids": [[14173.5, 0.756], [14273.5, 3.444], [14373.5, 0.0], [51738.8, 0.0], [58206.1, 0.002], [61439.8, 0.006], [62086.5, 0.005], [63671.1, 5.509], [63735.7, 11.087], [63860.8, 8.423], [63929.8, 2.811], [64026.8, 0.404], [64350.1, 0.01], [64416.6, 0.044], [64514.9, 0.0], [64595.8, 0.149], [64608.3, 0.0], [64612.6, 0.033], [64628.2, 0.008], [64638.4, 1.134], [64644.0, 0.452], [64644.5, 0.003], [64644.8, 9.071], [64645.5, 0.098], [64646.9, 0.014], [64650.1, 0.096], [64650.5, 0.003], [64654.0, 0.163], [64654.3, 0.001], [64654.5, 0.065], [64655.6, 0.012], [64660.5, 1.255], [64660.7, 0.707], [64660.8, 0.014], [64661.0, 0.0], [64661.4, 0.0], [64661.5, 0.002], [64662.5, 0.001], [64664.0, 0.62], [64665.9, 0.128], [64667.2, 0.282], [64667.3, 0.0], [64667.7, 1.122], [64667.9, 0.016], [64668.4, 0.088], [64669.1, 0.013], [64669.6, 0.109], [64669.7, 0.001], [64670.3, 0.002], [64670.4, 0.003], [64672.5, 0.002], [64673.5, 7.692]], "asks": [[64677.9, 0.007], [64683.8, 0.003], [64684.6, 0.115], [64684.7, 0.542], [64686.5, 0.252], [64691.2, 0.057], [64693.2, 0.461], [64693.9, 0.004], [64697.7, 4.033], [64703.2, 0.006], [64715.0, 0.029], [64715.5, 0.2], [64717.6, 0.001], [64731.9, 0.006], [64745.9, 2.342], [64748.1, 51.686], [64754.7, 0.0], [64831.1, 10.413], [64831.7, 0.0], [64869.4, 0.0], [64869.9, 4.513], [64870.5, 0.0], [65320.3, 0.0], [65512.1, 19.659], [67912.9, 0.038]]}
{"kind": "depth", "E": 1787095213665, "U": 11316364097089, "u": 11316364101739, "recv_ms": 1787095213735, "bids": [[14173.5, 1.12], [14273.5, 3.08], [58206.1, 0.002], [61439.8, 0.008], [62086.5, 0.002], [63673.5, 0.008], [64026.8, 0.404], [64027.1, 1.528], [64218.1, 0.031], [64516.7, 0.11], [64606.2, 0.325], [64612.1, 0.483], [64612.2, 0.002], [64612.9, 0.453], [64613.3, 0.125], [64613.9, 0.032], [64644.9, 0.071], [64645.0, 0.18], [64645.1, 0.07], [64645.2, 0.073], [64645.4, 0.173], [64645.6, 0.101], [64645.8, 0.3], [64650.1, 0.096], [64655.6, 0.012], [64660.8, 0.014], [64667.2, 0.282], [64669.5, 1.546], [64669.6, 0.109], [64670.3, 0.394], [64670.4, 0.041], [64671.0, 0.003], [64672.1, 0.0], [64673.5, 7.687]], "asks": [[64677.9, 0.0], [64684.6, 0.122], [64685.0, 0.901], [64686.0, 0.123], [64695.4, 0.494], [64698.7, 0.002], [64699.5, 0.125], [64701.0, 0.461], [64714.2, 0.194], [64714.9, 0.041], [64715.2, 1.406], [64717.6, 0.015], [64745.9, 51.777], [64748.1, 2.251], [65320.3, 0.0], [65673.6, 0.0]]}
{"kind": "depth", "E": 1787095213767, "U": 11316364101797, "u": 11316364106560, "recv_ms": 1787095213837, "bids": [[1000.0, 35.76], [14173.5, 1.47], [14273.5, 2.73], [58206.1, 0.002], [63865.1, 3.052], [64026.8, 0.404], [64218.4, 0.002], [64516.7, 0.187], [64533.2, 0.0], [64595.8, 0.152], [64612.1, 0.49], [64613.6, 2.356], [64638.3, 0.011], [64638.6, 0.156], [64645.2, 0.173], [64645.4, 0.273], [64645.7, 0.427], [64646.5, 0.226], [64646.9, 0.114], [64650.1, 0.096], [64655.6, 0.012], [64660.8, 0.014], [64667.2, 0.282], [64669.5, 1.546], [64669.6, 0.109], [64670.3, 0.002], [64672.6, 0.087]], "asks": [[64673.6, 14.722], [64675.1, 0.003], [64697.8, 4.446], [64701.9, 0.008], [64714.6, 0.035], [64718.3, 0.504], [64751.3, 0.004], [64814.2, 0.0], [65320.3, 0.0]]}
{"kind": "depth", "E": 1787095213869, "U": 11316364106652, "u": 11316364111466, "recv_ms": 1787095213940, "bids": [[14173.5, 1.82], [14273.5, 2.38], [51739.0, 0.0], [58206.1, 0.002], [61439.8, 0.008], [62086.5, 0.005], [63668.9, 1.506], [63673.5, 0.028], [63957.9, 0.001], [64026.8, 0.404], [64350.1, 0.0], [64511.8, 0.04], [64516.2, 0.0], [64516.9, 1.152], [64603.1, 34.604], [64609.7, 0.201], [64612.2, 0.04], [64631.3, 0.036], [64644.9, 0.141], [64645.1, 0.14], [64645.6, 0.201], [64646.0, 1.972], [64650.1, 0.096], [64655.4, 0.363], [64660.8, 0.014], [64662.4, 0.015], [64662.9, 0.002], [64667.2, 0.282], [64669.6, 0.542], [64669.7, 0.001], [64670.4, 0.003], [64671.0, 0.003], [64672.6, 0.003]], "asks": [[64673.6, 14.626], [64674.8, 0.089], [64675.2, 0.418], [64679.0, 4.325], [64715.6, 2.323], [64717.8, 0.506], [64745.8, 9.932], [64814.3, 0.909], [64831.1, 0.001], [64871.9, 1.921], [64997.0, 0.201], [65320.3, 0.0], [65320.7, 0.051], [65447.1, 0.0], [65514.4, 0.915], [65673.6, 0.02], [71141.0, 0.015]]}
{"kind": "depth", "E": 1787095213971, "U": 11316364111643, "u": 11316364117101, "recv_ms": 1787095214041, "bids": [[1000.0, 35.76], [14173.5, 2.184], [14273.5, 2.016], [58206.1, 0.002], [62086.5, 0.002], [63380.3, 2.419], [63671.1, 6.607], [63703.7, 4.545], [63860.8, 8.158], [64026.8, 0.404], [64027.1, 1.512], [64332.8, 0.014], [64333.0, 7.143], [64350.1, 0.001], [64477.4, 0.004], [64577.3, 0.002], [64603.1, 0.0], [64603.6, 1.242], [64604.0, 0.263], [64604.1, 0.039], [64609.6, 35.984], [64611.1, 3.055], [64669.5, 1.549], [64669.6, 0.542], [64669.8, 0.091]], "asks": [[64717.8, 0.352], [64717.9, 5.627], [64725.5, 0.004], [64869.9, 0.018], [65320.3, 0.0], [65320.7, 0.043], [65501.7, 0.048], [65644.0, 2.947]]}
{"kind": "depth", "E": 1787095214073, "U": 11316364117190, "u": 11316364123814, "recv_ms": 1787095214143, "bids": [[1000.0, 35.76], [14173.5, 2.534], [14273.5, 1.666], [58206.1, 0.002], [62086.5, 0.005], [63673.5, 0.008], [63703.7, 4.537], [63787.8, 0.002], [63846.0, 0.083], [63950.5, 5.474], [63962.1, 2.278], [64026.8, 0.404], [64027.1, 1.504], [64477.4, 14.69], [64516.2, 7.684], [64516.7, 0.341], [64533.2, 5.001], [64607.5, 34.604], [64609.6, 1.38], [64657.1, 0.009], [64661.9, 0.013], [64669.6, 0.542], [64671.7, 0.003], [64672.2, 0.043], [64672.3, 0.002]], "asks": [[64689.6, 0.025], [64705.5, 1.892], [64705.6, 1.492], [64814.2, 5.4], [64831.1, 10.413], [64869.9, 4.513], [65320.3, 0.0], [65320.7, 0.035], [65501.7, 0.04], [65616.8, 18.035], [65673.6, 0.0], [65967.4, 2.329]]}
{"kind": "depth", "E": 1787095214175, "U": 11316364123955, "u": 11316364128781, "recv_ms": 1787095214246, "bids": [[14173.5, 2.898], [14273.5, 1.302], [51739.0, 0.002], [58206.1, 0.002], [61439.8, 0.008], [62086.5, 0.002], [63380.3, 2.411], [63703.7, 4.529], [63994.7, 1.55], [64026.8, 0.404], [64350.1, 0.011], [64593.4, 0.005], [64600.6, 2.009], [64607.5, 34.604], [64609.6, 1.38], [64622.0, 0.285], [64624.8, 0.0], [64629.8, 0.037], [64657.1, 0.011], [64659.6, 0.158], [64662.2, 0.0], [64669.6, 0.109], [64671.0, 0.003]], "asks": [[64673.6, 14.628], [64680.4, 0.003], [64689.6, 0.027], [65320.3, 0.0], [65443.2, 2.748], [65644.0, 2.939], [65967.4, 2.321], [67907.2, 0.02], [67912.9, 0.033]]}
{"kind": "depth", "E": 1787095214277, "U": 11316364128891, "u": 11316364135075, "recv_ms": 1787095214346, "bids": [[1000.0, 35.76], [14173.5, 3.248], [14273.5, 0.952], [51739.0, 0.0], [58206.1, 0.002], [61439.8, 0.008], [63673.5, 0.028], [63846.0, 0.075], [64026.7, 0.002], [64026.8, 0.404], [64516.7, 0.348], [64533.2, 5.016], [64581.4, 2.374], [64607.5, 34.604], [64609.6, 1.38], [64621.7, 0.029], [64643.0, 0.057], [64644.0, 0.395], [64650.1, 0.096], [64652.5, 0.115], [64653.1, 0.119], [64653.6, 0.003], [64654.0, 0.047], [64655.4, 0.363], [64655.5, 0.387], [64655.7, 1.022], [64656.9, 0.629], [64657.9, 0.319], [64658.7, 0.001], [64659.9, 0.459], [64660.6, 1.498], [64660.7, 0.248], [64660.8, 0.014], [64661.5, 0.002], [64661.6, 0.059], [64663.0, 0.352], [64663.9, 0.206], [64666.0, 0.53], [64666.9, 0.248], [64667.1, 1.291], [64667.2, 1.285], [64667.3, 0.547], [64667.7, 1.119], [64667.8, 0.126], [64667.9, 0.016], [64668.1, 0.086], [64669.4, 0.004], [64669.5, 2.097], [64669.6, 0.109], [64669.7, 0.001], [64669.8, 0.022], [64670.3, 0.497], [64670.4, 0.003], [64671.9, 0.0], [64673.5, 7.677]], "asks": [[64673.6, 14.592], [64674.2, 0.084], [64674.7, 1.006], [64677.4, 0.018], [64678.6, 0.437], [64680.4, 0.002], [64692.3, 0.459], [64693.1, 0.001], [64693.2, 0.002], [64694.0, 0.001], [64694.3, 0.0], [64694.9, 0.059], [64695.9, 0.56], [64696.1, 0.379], [64696.6, 0.016], [64697.4, 0.004], [64709.9, 0.003], [64715.0, 0.015], [64717.6, 0.001], [64717.9, 5.631], [64725.5, 0.0], [64814.2, 5.4], [64869.9, 4.398], [65320.3, 0.0], [65482.0, 4.194], [65587.6, 1.387], [65644.0, 2.931], [65673.6, 0.02], [65967.4, 2.313]]}
{"kind": "depth", "E": 1787095214379, "U": 11316364135200, "u": 11316364142400, "recv_ms": 1787095214451, "bids": [[1000.0, 35.76], [14173.5, 3.612], [14273.5, 0.588], [58206.1, 0.002], [61439.8, 0.008], [61445.1, 0.002], [62086.5, 0.005], [63787.5, 1.262], [63865.1, 3.287], [63935.1, 7.026], [64026.8, 0.404], [64640.6, 0.412], [64640.7, 0.001], [64640.8, 0.011], [64644.1, 0.093], [64644.2, 0.0], [64644.3, 0.005], [64650.1, 0.096], [64655.4, 0.363], [64659.9, 0.459], [64660.7, 0.248], [64660.8, 0.006], [64660.9, 0.047], [64661.5, 0.002], [64666.1, 0.163], [64667.2, 0.823], [64667.3, 0.008], [64667.4, 0.009], [64667.6, 0.006], [64667.8, 0.01], [64667.9, 0.093], [64668.7, 0.002], [64669.1, 0.013], [64669.5, 0.551], [64669.6, 0.109], [64669.7, 1.547], [64670.3, 0.002], [64670.4, 0.065], [64670.8, 0.005], [64671.6, 0.086], [64672.0, 0.005], [64673.5, 7.784]], "asks": [[64673.6, 14.594], [64674.2, 0.0], [64686.0, 1.023], [64687.0, 0.165], [64692.3, 0.0], [64693.2, 0.461], [64694.9, 0.002], [64695.8, 0.059], [64695.9, 0.004], [64696.1, 0.935], [64696.7, 0.118], [64696.8, 0.004], [64698.1, 0.071], [65320.3, 0.0], [65611.4, 8.371]]}
{"kind": "depth", "E": 1787095214481, "U": 11316364142620, "u": 11316364148785, "recv_ms": 1787095214550, "bids": [[14173.5, 3.766], [14273.5, 0.336], [14573.5, 0.098], [58206.1, 0.002], [62086.5, 0.002], [63644.0, 5.846], [63673.5, 0.008], [63935.1, 6.09], [64026.8, 0.404], [64350.1, 0.001], [64607.5, 0.0], [64609.7, 34.805], [64638.6, 0.156], [64643.0, 0.0], [64644.2, 0.057], [64653.1, 0.003], [64654.2, 0.125], [64655.7, 0.465], [64656.8, 0.576], [64659.9, 0.0], [64660.7, 0.256], [64660.9, 0.498], [64666.1, 0.163], [64667.2, 0.282], [64667.3, 0.47], [64667.8, 0.898], [64669.6, 1.771], [64669.7, 0.001], [64670.3, 0.435], [64673.5, 7.783]], "asks": [[64696.1, 0.379], [64696.7, 0.002], [64697.0, 0.583], [64697.6, 0.166], [64997.0, 0.2], [65320.3, 0.0], [65673.6, 0.0], [65713.9, 3.619]]}
{"kind": "depth", "E": 1787095214583, "U": 11316364148976, "u": 11316364154682, "recv_ms": 1787095214653, "bids": [[1000.0, 35.76], [14173.5, 3.654], [14273.5, 0.21], [14573.5, 0.336], [51738.8, 0.0], [58206.1, 0.002], [61439.8, 0.006], [61439.9, 0.008], [62086.5, 0.005], [63638.7, 3.697], [63846.0, 0.067], [64026.8, 0.404], [64350.1, 0.002], [64603.1, 34.604], [64603.6, 1.251], [64604.0, 0.34], [64609.7, 0.201], [64610.8, 0.021], [64614.4, 0.005], [64623.7, 0.0], [64628.4, 0.004], [64630.2, 0.003], [64640.7, 0.026], [64667.3, 0.47], [64669.4, 0.066], [64669.6, 1.771], [64670.3, 0.435], [64670.4, 0.041], [64670.8, 0.005], [64672.0, 0.089]], "asks": [[64706.3, 0.004], [64714.8, 0.028], [64831.1, 10.413], [64831.7, 0.0], [64869.9, 4.515], [64870.5, 0.0], [65320.7, 0.027], [65681.5, 8.515], [67912.9, 0.028]]}
{"kind": "depth", "E": 1787095214685, "U": 11316364154775, "u": 11316364159469, "recv_ms": 1787095214753, "bids": [[1000.0, 35.76], [14173.5, 3.528], [14273.5, 0.098], [14573.5, 0.574], [58206.1, 0.002], [61439.8, 0.006], [62086.5, 0.002], [63673.5, 0.028], [63824.7, 1.096], [63929.8, 4.684], [63935.1, 5.153], [64026.8, 0.404], [64603.1, 0.0], [64609.7, 34.805], [64614.1, 0.005], [64614.5, 0.0], [64617.3, 7.053], [64650.1, 0.251], [64655.4, 0.518], [64658.8, 0.777], [64660.5, 1.24], [64660.7, 0.411], [64661.4, 0.0], [64661.5, 0.157], [64666.2, 0.626], [64667.1, 1.306], [64667.2, 0.437], [64667.3, 0.008], [64667.9, 0.093], [64669.6, 1.771], [64669.7, 0.156], [64670.3, 0.002], [64670.4, 0.003], [64672.0, 0.005]], "asks": [[64673.6, 14.594], [64687.5, 1.246], [64689.8, 0.112], [64694.8, 8.023], [65320.3, 0.0], [65378.8, 9.379], [65673.6, 0.02], [65676.0, 4.123]]}
{"kind": "depth", "E": 1787095214787, "U": 11316364159548, "u": 11316364164284, "recv_ms": 1787095214857, "bids": [[14173.5, 3.36], [14273.5, 0.0], [14573.5, 0.84], [58206.1, 0.002], [63380.3, 2.403], [63638.7, 4.796], [63703.7, 4.521], [64026.8, 0.404], [64027.1, 1.496], [64350.1, 0.002], [64533.2, 0.0], [64595.8, 0.149], [64603.6, 1.242], [64628.2, 0.008], [64650.1, 0.096], [64655.4, 0.363], [64660.7, 0.248], [64661.5, 0.002], [64666.3, 0.008], [64667.2, 0.282], [64667.3, 0.008], [64667.4, 0.009], [64667.8, 0.551], [64669.6, 1.655], [64669.7, 0.001], [64670.3, 0.002], [64670.8, 0.005]], "asks": [[64731.9, 0.006], [64751.3, 0.001], [64814.2, 0.0], [65196.4, 3.977], [65320.3, 0.0], [65445.3, 14.405], [65501.7, 0.032], [65616.8, 16.97], [65708.4, 2.128]]}
{"kind": "depth", "E": 1787095214889, "U": 11316364164426, "u": 11316364170023, "recv_ms": 1787095214959, "bids": [[1000.0, 35.76], [14173.5, 3.01], [14573.5, 1.19], [58206.1, 0.002], [62086.5, 0.005], [63673.5, 0.008], [63821.2, 1.564], [63832.6, 3.836], [63929.8, 5.621], [64026.8, 0.404], [64516.9, 2.201], [64533.2, 5.001], [64638.6, 0.156], [64644.3, 0.003], [64644.8, 9.073], [64660.7, 0.248], [64666.3, 0.008], [64667.3, 0.47], [64667.8, 0.782], [64670.3, 0.435], [64672.1, 0.084]], "asks": [[64697.4, 0.002], [64697.8, 4.448], [64814.2, 5.4], [64819.9, 4.993], [65002.4, 3.845], [65191.0, 4.134], [65320.3, 0.0], [65320.6, 1.385], [65455.1, 32.099], [65579.0, 3.005], [65673.6, 0.0], [65681.5, 7.451]]}
{"kind": "depth", "E": 1787095215093, "U": 11316364177837, "u": 11316364185982, "recv_ms": 1787095215162, "bids": [[14173.5, 2.296], [14573.5, 1.904], [58206.1, 0.002], [61439.8, 0.006], [62086.5, 0.005], [63380.3, 2.379], [63673.5, 0.028], [63703.7, 4.505], [63846.0, 0.051], [63897.4, 8.204], [64026.8, 0.404], [64350.1, 0.001], [64624.7, 0.007], [64629.8, 0.036], [64638.5, 0.156], [64638.6, 0.002], [64650.1, 0.096], [64655.4, 0.363], [64660.7, 0.256], [64661.5, 0.002], [64661.9, 0.013], [64665.4, 0.995], [64666.3, 0.0], [64667.2, 0.282], [64667.3, 0.018], [64667.8, 0.667], [64669.6, 1.639], [64669.7, 0.001], [64670.2, 0.246], [64670.3, 0.018], [64670.5, 0.011], [64671.0, 0.003], [64673.5, 7.784]], "asks": [[64673.6, 14.249], [64674.8, 0.005], [64687.5, 0.628], [64689.8, 0.132], [64694.8, 7.405], [64997.0, 0.201], [65320.3, 0.0], [65320.7, 0.019], [65449.7, 6.148], [65501.7, 0.008], [65611.4, 9.436], [65644.0, 2.907], [65673.6, 0.02], [65673.8, 8.516], [65676.0, 5.187], [65967.4, 2.289], [67907.2, 0.025]]}
{"kind": "depth", "E": 1787095215195, "U": 11316364186071, "u": 11316364192680, "recv_ms": 1787095215265, "bids": [[1000.0, 35.76], [14173.5, 1.932], [14573.5, 2.268], [58206.1, 0.002], [61439.8, 0.008], [63676.4, 14.901], [63741.1, 16.859], [64026.8, 0.404], [64355.5, 5.711], [64593.3, 0.005], [64593.4, 0.001], [64600.5, 2.362], [64600.6, 2.008], [64621.9, 0.096], [64622.0, 0.284], [64624.6, 0.06], [64624.7, 0.003], [64629.7, 0.083], [64644.8, 1.073], [64646.0, 0.762], [64649.3, 4.191], [64657.1, 0.011], [64660.7, 0.256], [64660.9, 0.039], [64661.7, 0.781], [64666.3, 0.0], [64667.0, 1.293], [64667.3, 0.018], [64668.1, 0.002], [64669.5, 0.548], [64669.7, 0.02], [64670.2, 0.679], [64670.3, 0.002], [64671.4, 0.0], [64673.2, 0.087], [64673.4, 0.018], [64673.5, 8.545]], "asks": [[64673.6, 14.092], [64675.2, 0.024], [64675.6, 0.0], [64677.4, 0.015], [64678.6, 0.521], [64679.0, 4.408], [64679.1, 1.398], [64680.2, 0.426], [64686.0, 0.123], [64689.6, 0.027], [64694.3, 0.473], [64697.7, 0.033], [64705.1, 2.414], [64705.8, 10.007], [64717.6, 0.057], [64868.4, 0.003], [64868.5, 0.125], [64997.0, 0.355], [65196.4, 3.672], [65320.3, 0.0], [65616.8, 14.839], [65681.5, 6.386]]}
{"kind": "depth", "E": 1787095215297, "U": 11316364192788, "u": 11316364199025, "recv_ms": 1787095215366, "bids": [[1000.0, 35.76], [14173.5, 1.582], [14573.5, 2.618], [58206.1, 0.002], [61439.8, 0.008], [62086.5, 0.002], [63673.5, 0.008], [63735.7, 12.184], [63768.1, 6.773], [63829.1, 0.0], [63846.0, 0.043], [63929.8, 6.558], [64026.7, 0.001], [64026.8, 0.404], [64027.1, 1.488], [64533.2, 4.648], [64667.3, 0.249], [64667.8, 0.551], [64669.7, 0.453], [64670.2, 0.246], [64670.8, 0.005], [64673.5, 8.543]], "asks": [[64673.6, 14.092], [64686.0, 1.023], [64687.0, 0.165], [64814.2, 5.4], [64869.9, 5.817], [65002.4, 3.691], [65320.3, 0.0], [65320.7, 0.011], [65501.7, 0.0], [65609.1, 3.199], [65611.4, 10.501], [65644.0, 2.899], [65673.6, 0.0], [65676.0, 6.252], [65833.4, 0.0]]}
{"kind": "depth", "E": 1787095215399, "U": 11316364199065, "u": 11316364205688, "recv_ms": 1787095215505, "bids": [[14173.5, 1.218], [14573.5, 2.982], [58206.1, 0.002], [61439.8, 0.008], [62086.5, 0.005], [63380.3, 2.371], [63671.1, 7.705], [63703.7, 4.497], [63735.7, 13.281], [63865.1, 3.522], [64026.8, 0.404], [64350.1, 0.011], [64621.7, 0.015], [64654.2, 0.009], [64654.9, 0.208], [64656.8, 0.019], [64657.6, 0.559], [64663.0, 0.043], [64663.5, 1.01], [64667.3, 0.48], [64667.8, 0.898], [64669.6, 1.642], [64669.7, 0.017], [64669.8, 0.022], [64670.2, 0.679], [64673.5, 8.56]], "asks": [[64682.3, 0.331], [64682.7, 0.001], [64689.8, 0.076], [64744.3, 0.139], [64744.4, 0.0], [64790.6, 0.217], [65196.4, 3.366], [65320.3, 0.0], [65477.7, 9.398], [65967.4, 2.281], [66158.8, 0.079]]}
{"kind": "depth", "E": 1787095215501, "U": 11316364205854, "u": 11316364212107, "recv_ms": 1787095215571, "bids": [[1000.0, 35.76], [14173.5, 0.854], [14573.5, 3.346], [58206.1, 0.002], [62086.5, 0.002], [63380.3, 2.363], [63611.7, 4.339], [63673.5, 0.028], [63703.7, 4.489], [64026.8, 0.412], [64027.1, 1.48], [64350.1, 0.165], [64511.8, 0.278], [64516.2, 0.0], [64516.8, 1.474], [64516.9, 1.152], [64533.2, 0.0], [64604.0, 0.263], [64620.0, 0.036], [64636.8, 2.321], [64650.1, 0.096], [64655.6, 0.012], [64660.7, 0.256], [64660.8, 0.006], [64661.6, 0.029], [64666.2, 0.656], [64667.3, 0.018], [64667.8, 0.551], [64667.9, 0.093], [64669.6, 0.096], [64669.7, 0.001], [64669.8, 0.022], [64669.9, 0.001], [64670.2, 0.246], [64670.3, 0.002], [64670.4, 0.019], [64670.5, 1.557], [64670.8, 0.005]], "asks": [[64679.6, 0.188], [64717.8, 0.506], [64717.9, 5.477], [64744.3, 0.1], [64744.4, 0.039], [64814.2, 0.0], [64831.1, 0.001], [64997.0, 0.509], [65191.0, 4.439], [65320.3, 0.0], [65320.7, 0.003], [65445.3, 14.191], [65487.5, 8.666], [65611.4, 11.567], [65673.6, 0.02], [65676.0, 7.317], [65746.2, 3.19], [65967.4, 2.273]]}
{"kind": "depth", "E": 1787095215603, "U": 11316364212200, "u": 11316364218535, "recv_ms": 1787095215672, "bids": [[1000.0, 35.76], [14173.5, 0.504], [14573.5, 3.696], [51738.8, 0.0], [58206.1, 0.002], [61439.8, 0.008], [62086.5, 0.005], [63832.7, 3.208], [63865.1, 3.787], [64026.8, 0.412], [64027.1, 1.472], [64156.1, 0.007], [64161.5, 9.323], [64355.5, 5.556], [64477.4, 13.723], [64477.5, 0.022], [64479.1, 0.37], [64516.2, 6.731], [64533.2, 4.264], [64604.0, 0.244], [64640.6, 0.414], [64640.7, 0.028], [64640.8, 0.013], [64644.1, 0.095], [64644.2, 0.059], [64644.3, 0.005], [64649.4, 0.367], [64667.3, 0.018], [64667.8, 0.551], [64667.9, 0.093], [64669.6, 0.096], [64670.2, 0.246], [64670.4, 0.011], [64670.5, 0.011], [64670.6, 0.088], [64670.7, 0.0], [64670.8, 0.005], [64670.9, 1.554]], "asks": [[64673.6, 14.036], [64678.7, 0.169], [64689.8, 0.132], [64717.8, 0.506], [64717.9, 5.473], [64725.5, 0.004], [64744.0, 1.301], [64744.4, 0.0], [64814.2, 5.4], [64831.1, 10.413], [64869.9, 7.103], [64997.0, 0.51], [65002.4, 3.537], [65191.0, 4.745], [65196.4, 3.06], [65320.3, 0.0], [65320.5, 0.545], [65611.4, 12.633], [65644.0, 2.891], [65731.3, 4.101], [65883.3, 0.003]]}
{"kind": "depth", "E": 1787095215705, "U": 11316364218688, "u": 11316364228303, "recv_ms": 1787095215776, "bids": [[14173.5, 0.308], [14473.5, 0.154], [14573.5, 3.738], [58206.1, 0.002], [61439.8, 0.008], [63673.5, 0.008], [63684.9, 0.784], [64026.8, 0.412], [64350.1, 0.165], [64471.2, 0.0], [64604.0, 0.167], [64612.1, 0.413], [64640.0, 3.716], [64641.4, 0.164], [64650.1, 0.096], [64654.0, 0.163], [64654.7, 0.001], [64654.9, 0.092], [64655.6, 0.012], [64656.7, 0.584], [64657.3, 0.0], [64657.6, 0.002], [64658.8, 0.159], [64660.7, 0.248], [64660.8, 0.006], [64660.9, 0.047], [64661.7, 0.781], [64666.2, 0.038], [64666.3, 0.0], [64667.2, 0.282], [64667.3, 0.018], [64667.4, 0.009], [64667.5, 0.015], [64667.8, 0.551], [64667.9, 0.209], [64669.6, 1.658], [64669.7, 0.001], [64670.3, 0.002], [64670.4, 0.003], [64670.9, 0.0], [64671.0, 0.003], [64672.2, 0.0], [64672.3, 0.041], [64672.7, 0.001], [64672.8, 0.084], [64673.1, 0.0], [64673.2, 0.003], [64673.4, 0.017], [64673.5, 7.8]], "asks": [[64673.6, 14.033], [64674.7, 1.0], [64675.0, 0.005], [64675.3, 2.811], [64675.6, 0.084], [64677.9, 0.0], [64678.6, 0.506], [64678.7, 0.001], [64680.2, 0.736], [64684.6, 0.122], [64686.9, 0.053], [64687.5, 0.628], [64691.4, 0.002], [64693.2, 0.002], [64694.1, 1.778], [64694.3, 0.014], [64694.8, 7.405], [64696.9, 0.09], [64697.4, 0.002], [64697.8, 5.004], [64697.9, 0.073], [64698.3, 0.116], [64698.5, 0.123], [64705.4, 1.923], [64705.5, 0.007], [64705.6, 1.49], [64705.8, 10.009], [64717.5, 0.005], [64717.8, 0.506], [64725.5, 0.0], [64739.9, 0.108], [64744.0, 1.262], [64744.3, 0.139], [64744.7, 0.082], [64746.9, 0.004], [64753.6, 1.488], [64754.5, 0.419], [64831.1, 0.001], [64831.6, 5.826], [64869.9, 0.018], [64870.4, 11.373], [65320.3, 0.0], [65673.6, 0.0], [66161.1, 0.604]]}
{"kind": "depth", "E": 1787095215807, "U": 11316364228409, "u": 11316364234302, "recv_ms": 1787095215878, "bids": [[1000.0, 35.76], [14173.5, 0.182], [14473.5, 0.392], [14573.5, 3.626], [58206.1, 0.002], [62086.5, 0.002], [63380.0, 0.289], [63606.4, 2.198], [63703.4, 0.765], [63845.7, 0.024], [64026.8, 0.42], [64156.1, 0.0], [64516.9, 2.065], [64611.1, 7.541], [64650.1, 0.096], [64655.6, 0.012], [64660.7, 0.248], [64660.8, 0.006], [64667.2, 0.282], [64667.3, 0.48], [64667.8, 0.783], [64667.9, 0.093], [64669.6, 1.889], [64669.7, 0.001], [64670.3, 0.435]], "asks": [[64675.4, 1.031], [64717.8, 0.352], [64717.9, 5.627], [64742.9, 2.266], [64744.3, 0.1], [64814.1, 1.714], [64814.3, 0.001], [64831.1, 10.413], [64831.6, 0.0], [64869.9, 5.713], [64870.4, 0.48], [65320.3, 0.0], [65320.5, 0.553], [65501.6, 4.131], [65731.0, 4.102], [65740.7, 1.063], [65883.0, 0.801], [65967.3, 0.008]]}
{"kind": "depth", "E": 1787095215909, "U": 11316364234447, "u": 11316364238918, "recv_ms": 1787095215980, "bids": [[1000.0, 35.76], [14173.5, 0.07], [14473.5, 0.644], [14573.5, 3.486], [58206.1, 0.002], [61439.8, 0.008], [62086.5, 0.005], [63380.0, 0.297], [63673.5, 0.028], [63703.4, 0.781], [63741.1, 15.762], [63845.7, 0.04], [63994.4, 0.868], [64026.8, 0.428], [64156.1, 0.311], [64161.5, 5.433], [64332.7, 0.0], [64332.8, 0.506], [64350.1, 0.32], [64355.5, 5.401], [64400.0, 36.455], [64477.4, 4.823], [64516.2, 0.0], [64516.3, 4.678], [64533.2, 2.726], [64595.8, 0.152], [64604.1, 0.001], [64667.3, 0.018], [64670.3, 0.002], [64670.4, 0.041], [64673.5, 7.799]], "asks": [[64673.6, 14.033], [64751.3, 0.004], [64814.1, 0.0], [64814.2, 0.0], [64814.7, 2.693], [64831.1, 0.001], [64831.6, 3.335], [64869.9, 0.018], [64870.4, 5.845], [64997.0, 0.664], [65191.0, 5.051], [65320.3, 0.0], [65320.5, 0.561], [65501.6, 4.139], [65616.8, 13.773], [65643.9, 0.009], [65673.6, 0.02], [65967.3, 0.016], [67912.9, 0.024]]}
{"kind": "depth", "E": 1787095216011, "U": 11316364238975, "u": 11316364244769, "recv_ms": 1787095216080, "bids": [[14173.5, 0.0], [14473.5, 0.924], [14573.5, 3.276], [58206.1, 0.002], [62086.5, 0.002], [63700.1, 0.0], [64026.8, 0.428], [64156.1, 0.622], [64161.5, 5.122], [64350.1, 0.32], [64477.4, 13.928], [64516.3, 7.415], [64533.2, 4.648], [64667.3, 0.018], [64670.3, 0.002], [64671.0, 0.003]], "asks": [[64742.5, 0.04], [64742.9, 2.227], [64814.2, 5.4], [64814.7, 0.0], [64831.1, 10.413], [64831.6, 0.0], [64997.0, 0.663], [65320.3, 0.0], [65643.9, 0.025], [65967.3, 0.024]]}
{"kind": "depth", "E": 1787095216113, "U": 11316364244915, "u": 11316364250139, "recv_ms": 1787095216182, "bids": [[1000.0, 35.76], [14473.5, 1.274], [14573.5, 2.926], [58206.1, 0.002], [62086.5, 0.005], [63673.5, 0.008], [63703.4, 2.348], [63741.1, 14.665], [64026.8, 0.428], [64350.1, 0.321], [64563.5, 0.003], [64595.8, 0.149], [64600.5, 2.36], [64628.2, 0.005], [64661.9, 0.013], [64667.3, 0.018], [64670.3, 0.002]], "asks": [[64731.9, 0.006], [64742.2, 0.095], [64742.5, 0.001], [64751.3, 0.001], [65320.3, 0.0], [65639.9, 0.0], [65673.6, 0.0], [65708.4, 3.192], [65713.9, 1.491], [65760.4, 0.0]]}
{"kind": "depth", "E": 1787095216215, "U": 11316364250332, "u": 11316364255195, "recv_ms": 1787095216285, "bids": [[1000.0, 35.76], [14473.5, 1.638], [14573.5, 2.562], [58206.1, 0.002], [64026.8, 0.428], [64156.1, 4.512], [64161.5, 4.812], [64350.1, 0.476], [64516.3, 0.0], [64516.8, 1.436], [64516.9, 1.152], [64533.2, 0.0], [64593.2, 2.463], [64593.3, 0.004], [64600.4, 0.031], [64600.5, 2.359], [64621.8, 0.083], [64621.9, 0.093], [64624.5, 0.002], [64624.6, 0.059], [64629.6, 1.167], [64629.7, 0.08], [64657.1, 0.011], [64667.3, 0.48], [64669.6, 2.005], [64670.3, 0.435]], "asks": [[64677.4, 0.018], [64680.7, 0.001], [64686.5, 0.081], [64689.6, 0.027], [64694.5, 3.579], [64701.0, 0.441], [64741.5, 0.039], [64742.2, 0.056], [64814.2, 0.0], [64831.1, 0.001], [65320.3, 0.0], [65611.4, 13.699]]}
{"kind": "depth", "E": 1787095216317, "U": 11316364255301, "u": 11316364260569, "recv_ms": 1787095216387, "bids": [[14473.5, 2.002], [14573.5, 2.198], [51739.0, 0.0], [58206.1, 0.002], [61439.8, 0.008], [62086.5, 0.002], [63673.5, 0.028], [63735.7, 14.378], [64026.8, 0.428], [64156.1, 4.823], [64350.1, 0.476], [64516.3, 7.528], [64533.2, 4.913], [64621.8, 0.084], [64667.3, 0.365], [64667.8, 0.551], [64669.6, 1.658], [64670.2, 0.679], [64670.3, 0.002], [64671.0, 0.003], [64672.3, 0.002], [64672.5, 0.047]], "asks": [[64673.6, 14.033], [64689.8, 0.109], [64741.5, 0.0], [64742.4, 0.051], [64742.9, 2.227], [64814.2, 5.4], [64831.1, 10.413], [64869.9, 5.479], [64870.4, 0.48], [65320.3, 0.0], [65644.2, 0.343], [65673.6, 0.02], [65673.8, 7.451], [65760.1, 1.821]]}
{"kind": "depth", "E": 1787095216419, "U": 11316364260721, "u": 11316364267456, "recv_ms": 1787095216490, "bids": [[1000.0, 35.76], [14473.5, 2.352], [14573.5, 1.848], [51739.0, 0.0], [58206.1, 0.002], [61439.8, 0.008], [62086.5, 0.005], [63673.5, 0.008], [63735.7, 15.475], [64026.8, 0.43], [64533.2, 4.913], [64650.1, 0.251], [64654.0, 0.047], [64654.2, 0.125], [64655.0, 0.003], [64655.6, 0.167], [64656.7, 0.027], [64657.6, 0.559], [64659.6, 0.438], [64660.7, 0.403], [64660.9, 0.039], [64662.2, 0.303], [64662.4, 0.17], [64666.1, 0.171], [64667.2, 0.437], [64667.3, 0.48], [64667.8, 0.782], [64668.4, 0.004], [64669.7, 0.156], [64670.2, 0.246], [64670.3, 0.435], [64670.4, 0.003], [64673.5, 8.643]], "asks": [[64675.3, 2.501], [64675.6, 0.0], [64676.0, 1.016], [64677.4, 0.015], [64677.9, 0.015], [64679.3, 0.088], [64680.7, 0.0], [64684.6, 0.107], [64689.8, 0.132], [64694.5, 3.559], [64697.6, 0.166], [64698.3, 0.0], [64698.5, 0.143], [64717.9, 5.627], [64742.2, 0.095], [64742.4, 0.012], [64814.2, 5.4], [64869.9, 8.649], [65002.4, 3.383], [65320.3, 0.0], [65552.2, 6.969], [65673.6, 0.0], [65708.4, 4.256]]}
{"kind": "depth", "E": 1787095216521, "U": 11316364267522, "u": 11316364273375, "recv_ms": 1787095216606, "bids": [[1000.0, 35.76], [14473.5, 2.716], [14573.5, 1.484], [58206.1, 0.002], [61439.8, 0.01], [62086.5, 0.002], [63611.7, 3.24], [64026.8, 0.436], [64059.4, 11.536], [64516.3, 7.399], [64516.8, 1.474], [64650.1, 0.096], [64655.6, 0.012], [64656.8, 0.576], [64657.6, 0.002], [64660.7, 0.256], [64660.8, 0.006], [64661.0, 0.0], [64661.5, 0.002], [64661.7, 0.322], [64661.8, 0.459], [64662.4, 0.015], [64666.1, 0.163], [64667.2, 0.282], [64667.3, 0.018], [64667.4, 0.009], [64667.8, 0.551], [64667.9, 0.093], [64669.6, 1.658], [64669.7, 0.001], [64670.3, 0.002], [64670.8, 0.005], [64672.7, 0.0], [64673.4, 0.018]], "asks": [[64677.9, 0.092], [64684.6, 0.03], [64697.0, 0.027], [64697.6, 0.05], [64697.8, 4.448], [64697.9, 0.629], [64698.5, 0.259], [64717.9, 5.473], [64718.0, 0.249], [64720.5, 0.119], [64741.5, 0.039], [64742.2, 0.056], [64814.2, 0.0], [64814.6, 4.045], [64831.1, 10.413], [64831.6, 0.0], [64869.9, 6.142], [64870.4, 0.48], [64997.0, 0.817], [65196.4, 2.754], [65320.3, 0.002], [65449.7, 6.362], [65546.7, 0.989], [65746.2, 2.127], [65801.9, 1.238], [67912.9, 0.02]]}
{"kind": "depth", "E": 1787095216623, "U": 11316364273387, "u": 11316364279838, "recv_ms": 1787095216693, "bids": [[14473.5, 3.066], [14573.5, 1.134], [51738.8, 0.0], [58206.1, 0.002], [61439.8, 0.01], [63380.0, 0.305], [63412.7, 0.457], [63574.3, 2.388], [63676.4, 13.804], [63703.4, 2.356], [63741.1, 13.569], [64026.8, 0.436], [64350.1, 0.477], [64434.2, 0.001], [64460.1, 0.697], [64486.0, 0.016], [64511.8, 0.279], [64645.8, 0.272], [64660.7, 0.248], [64666.1, 0.171], [64667.3, 0.018], [64667.8, 0.551], [64669.6, 1.658], [64670.3, 0.002], [64672.5, 0.002]], "asks": [[64673.6, 13.975], [64677.9, 0.0], [64680.2, 0.426], [64684.6, 0.122], [64831.1, 0.001], [64831.6, 5.533], [64835.3, 0.001], [64840.8, 0.0], [64861.1, 0.38], [64866.7, 0.0], [64869.9, 0.018], [64870.4, 11.821], [64887.0, 0.066], [64892.5, 0.0], [64918.4, 0.002], [64944.3, 0.033], [64997.0, 0.816], [65320.3, 0.0], [65482.0, 4.422], [65501.6, 4.147], [65676.0, 8.382], [65681.5, 5.322]]}
{"kind": "depth", "E": 1787095216725, "U": 11316364280111, "u": 11316364286916, "recv_ms": 1787095216801, "bids": [[1000.0, 35.76], [14473.5, 3.43], [14573.5, 0.77], [58206.1, 0.002], [61439.8, 0.01], [62086.5, 0.005], [63606.4, 3.297], [63673.5, 0.028], [63845.7, 0.048], [64026.8, 0.436], [64059.1, 2.259], [64370.0, 3.253], [64408.3, 0.001], [64448.6, 0.0], [64555.9, 0.001], [64556.0, 1.152], [64557.2, 3.868], [64565.2, 0.027], [64565.7, 2.319], [64601.1, 0.072], [64601.4, 0.063], [64608.8, 0.017], [64619.1, 0.029], [64642.9, 10.041], [64649.3, 2.191], [64650.1, 0.096], [64655.6, 0.012], [64655.9, 0.0], [64658.9, 0.041], [64660.7, 0.248], [64660.9, 0.498], [64661.4, 0.008], [64661.8, 0.007], [64662.4, 0.008], [64662.9, 0.311], [64663.5, 0.701], [64666.1, 0.163], [64666.2, 0.038], [64667.0, 1.294], [64667.2, 0.282], [64667.3, 0.45], [64667.6, 0.003], [64667.8, 0.544], [64667.9, 0.564], [64668.1, 0.086], [64668.4, 0.088], [64669.0, 0.003], [64669.1, 0.012], [64669.2, 0.423], [64669.4, 0.066], [64669.5, 0.0], [64669.6, 0.109], [64669.7, 1.547], [64670.2, 0.679], [64670.3, 0.002], [64670.6, 0.088], [64671.4, 0.001], [64671.6, 0.002], [64672.1, 0.0], [64672.8, 0.0], [64673.4, 0.017], [64673.5, 7.445]], "asks": [[64673.6, 14.015], [64674.2, 0.084], [64674.3, 0.006], [64674.6, 0.016], [64675.1, 0.313], [64675.2, 0.099], [64675.6, 0.084], [64676.0, 1.009], [64677.4, 0.018], [64677.9, 0.015], [64679.3, 0.004], [64679.5, 0.347], [64684.6, 0.107], [64687.5, 1.246], [64693.2, 0.461], [64694.1, 1.319], [64694.3, 0.0], [64694.9, 0.62], [64698.5, 0.239], [64699.4, 0.404], [64701.5, 5.286], [64705.8, 0.009], [64717.6, 0.001], [64738.3, 0.035], [64741.4, 0.142], [64741.5, 0.0], [64741.7, 0.0], [64743.5, 0.002], [64743.8, 6.349], [64779.1, 2.568], [64779.5, 2.341], [64807.7, 0.036], [64808.1, 3.889], [64831.1, 10.413], [64831.6, 0.0], [64869.9, 6.156], [64870.4, 0.48], [64912.9, 0.001], [64938.8, 0.001], [65320.3, 0.0], [65455.1, 30.268], [65501.6, 4.155], [65643.9, 0.033], [65673.6, 0.02], [65740.7, 2.127], [65805.4, 1.214], [66613.7, 0.003]]}
{"kind": "depth", "E": 1787095216827, "U": 11316364286973, "u": 11316364292070, "recv_ms": 1787095216896, "bids": [[1000.0, 35.76], [14373.5, 0.028], [14473.5, 3.724], [14573.5, 0.448], [51739.0, 0.0], [58206.1, 0.002], [61439.8, 0.008], [61439.9, 0.01], [62086.5, 0.002], [63375.8, 3.79], [63447.7, 0.001], [63519.5, 2.125], [63591.4, 0.0], [63663.2, 0.027], [63671.1, 8.802], [63735.1, 0.0], [63735.7, 16.571], [63806.9, 0.01], [63845.7, 0.056], [63878.8, 0.782], [63950.7, 0.007], [64022.5, 2.762], [64026.8, 0.436], [64479.1, 2.403], [64516.9, 2.164], [64617.3, 5.708], [64617.4, 2.146], [64619.1, 0.001], [64621.7, 0.029], [64639.8, 1.236], [64642.9, 8.311], [64643.0, 2.906], [64650.1, 0.096], [64655.6, 0.012], [64660.7, 0.256], [64661.4, 0.0], [64661.5, 0.002], [64667.2, 0.282], [64667.3, 0.565], [64667.4, 0.009], [64667.8, 0.544], [64667.9, 1.026], [64668.0, 0.514], [64669.4, 0.004], [64669.6, 0.093], [64669.7, 0.001], [64670.2, 0.246], [64670.3, 0.01], [64670.4, 0.003], [64670.5, 0.011], [64670.6, 0.088], [64670.7, 1.987], [64671.7, 0.001]], "asks": [[64677.9, 0.0], [64684.6, 0.122], [64693.2, 0.002], [64694.0, 0.46], [64705.1, 0.752], [64722.8, 0.005], [64741.4, 0.103], [64742.2, 0.095], [64814.3, 1.513], [65191.0, 5.357], [65315.9, 0.339], [65320.3, 0.0], [65320.5, 0.569], [65387.7, 0.0], [65459.6, 0.007], [65501.6, 4.163], [65531.5, 6.057], [65603.3, 0.004], [65675.2, 0.0], [65676.0, 9.446], [65747.0, 0.027], [65818.9, 0.0], [65890.7, 0.0], [65962.6, 0.0]]}
{"kind": "depth", "E": 1787095216929, "U": 11316364292167, "u": 11316364297391, "recv_ms": 1787095216998, "bids": [[14373.5, 0.224], [14473.5, 3.696], [14573.5, 0.28], [58206.1, 0.002], [62086.5, 0.005], [63380.0, 0.321], [63574.1, 7.176], [63673.5, 0.008], [63703.4, 2.364], [63800.7, 1.414], [63861.7, 1.402], [64026.8, 0.436], [64332.7, 0.492], [64332.8, 0.014], [64350.1, 0.467], [64355.5, 5.246], [64557.2, 3.868], [64601.4, 0.017], [64601.5, 0.047], [64667.3, 0.565], [64667.8, 0.66], [64667.9, 0.564], [64668.0, 0.105], [64668.5, 0.063], [64669.4, 1.558], [64669.5, 0.355], [64670.3, 0.435], [64670.6, 0.088], [64670.7, 0.0], [64670.8, 0.005]], "asks": [[64705.3, 1.989], [64705.4, 0.038], [64741.5, 0.039], [64742.2, 0.056], [64743.8, 6.349], [64808.1, 3.889], [64869.9, 6.143], [65320.3, 0.0], [65449.7, 8.193], [65643.9, 0.041], [65673.6, 0.0], [65837.7, 1.211], [65967.3, 0.04]]}
{"kind": "depth", "E": 1787095217031, "U": 11316364297469, "u": 11316364302584, "recv_ms": 1787095217102, "bids": [[1000.0, 35.76], [14373.5, 0.448], [14473.5, 3.598], [14573.5, 0.154], [58206.1, 0.002], [62086.5, 0.002], [64026.8, 0.436], [64638.5, 0.002], [64641.3, 0.006], [64650.1, 0.096], [64655.6, 0.012], [64660.7, 0.256], [64661.5, 0.002], [64667.2, 0.282], [64667.3, 0.103], [64667.8, 0.544], [64668.5, 0.001], [64669.5, 0.124], [64670.3, 0.002], [64670.4, 0.103], [64672.0, 0.045]], "asks": [[64740.8, 1.39], [64741.5, 0.0], [65320.3, 0.0]]}
{"kind": "depth", "E": 1787095217133, "U": 11316364302786, "u": 11316364307769, "recv_ms": 1787095217203, "bids": [[1000.0, 35.76], [14373.5, 0.686], [14473.5, 3.472], [14573.5, 0.042], [51739.0, 0.0], [58206.1, 0.002], [61439.8, 0.008], [61439.9, 0.008], [63514.7, 2.833], [63673.5, 0.028], [63699.2, 12.29], [63703.4, 2.372], [63800.4, 2.493], [64026.8, 0.444], [64087.2, 1.339], [64350.1, 0.621], [64593.2, 2.464], [64600.4, 0.032], [64624.5, 0.003], [64629.6, 1.168], [64638.5, 0.156], [64638.6, 0.002], [64660.7, 0.248], [64661.9, 0.013], [64665.9, 0.136], [64667.3, 0.103], [64667.4, 0.009], [64667.8, 0.544], [64667.9, 0.564], [64669.4, 1.558], [64669.5, 0.008], [64670.3, 0.002], [64671.8, 0.002], [64673.5, 7.444]], "asks": [[64673.6, 14.008], [64674.2, 0.0], [64674.4, 0.112], [64680.9, 0.003], [64722.8, 0.014], [64740.8, 1.351], [64742.2, 0.095], [64790.6, 0.117], [64997.0, 0.817], [65320.3, 0.0], [65320.5, 0.577], [65482.0, 4.764], [65673.6, 0.02], [65967.3, 0.048], [104929.0, 0.0]]}
{"kind": "depth", "E": 1787095217235, "U": 11316364307954, "u": 11316364313243, "recv_ms": 1787095217306, "bids": [[14373.5, 1.008], [14473.5, 3.192], [14573.5, 0.0], [51739.0, 0.0], [58206.1, 0.002], [62086.5, 0.005], [63490.8, 0.002], [63673.5, 0.008], [63865.1, 4.569], [64026.8, 0.452], [64621.8, 0.085], [64657.1, 0.011], [64660.7, 0.248], [64665.9, 0.128], [64667.3, 0.103], [64667.7, 1.203], [64667.8, 0.66], [64669.4, 1.558], [64670.3, 0.002], [64670.6, 0.088], [64671.2, 0.012]], "asks": [[64673.9, 0.086], [64679.0, 4.324], [64689.6, 0.027], [64742.2, 0.056], [64742.9, 2.266], [65320.3, 0.0], [65449.7, 8.407], [65575.6, 10.052], [65643.9, 0.049], [65673.6, 0.0]]}
{"kind": "depth", "E": 1787095217337, "U": 11316364313276, "u": 11316364318342, "recv_ms": 1787095217408, "bids": [[1000.0, 35.76], [14373.5, 1.372], [14473.5, 2.828], [58206.1, 0.002], [61439.8, 0.008], [62086.5, 0.002], [63380.0, 0.329], [63691.9, 0.784], [63878.8, 0.0], [63917.1, 1.097], [64026.8, 0.454], [64091.4, 20.015], [64563.5, 0.0], [64628.2, 0.008], [64638.4, 1.288], [64638.5, 0.002], [64639.8, 1.194], [64650.1, 0.096], [64655.6, 0.012], [64660.7, 0.256], [64661.4, 0.0], [64661.5, 0.002], [64664.0, 0.388], [64664.9, 0.515], [64665.9, 0.128], [64667.1, 1.314], [64667.2, 0.282], [64667.3, 0.095], [64667.8, 0.544], [64669.5, 0.008], [64670.2, 0.246], [64670.3, 0.002], [64670.4, 0.065], [64671.0, 0.087], [64673.5, 7.547]], "asks": [[64673.6, 14.001], [64684.6, 0.13], [64687.4, 0.106], [64687.5, 0.628], [64688.3, 0.007], [64689.6, 0.02], [64691.0, 0.673], [64692.9, 0.003], [64717.5, 0.001], [64725.5, 0.004], [64731.9, 0.006], [64741.8, 0.039], [64742.9, 2.227], [65122.6, 0.0], [65320.3, 0.0], [65493.6, 0.933], [65640.3, 6.091], [65773.4, 4.706]]}
{"kind": "depth", "E": 1787095217439, "U": 11316364318358, "u": 11316364323339, "recv_ms": 1787095217510, "bids": [[1000.0, 35.76], [14373.5, 1.722], [14473.5, 2.478], [58206.1, 0.002], [62086.5, 0.005], [63509.4, 4.812], [63673.5, 0.028], [63703.4, 2.763], [64026.8, 0.452], [64350.1, 0.631], [64655.0, 0.031], [64667.2, 0.359], [64667.3, 0.018], [64668.7, 0.312], [64668.8, 0.102], [64669.0, 0.0], [64670.6, 0.088], [64671.4, 0.085]], "asks": [[64673.9, 0.002], [64678.5, 0.227], [64681.4, 1.662], [64682.3, 0.022], [64696.8, 0.56], [64697.4, 0.118], [64697.9, 0.073], [64698.5, 0.123], [64740.8, 1.39], [64741.8, 0.0], [64785.6, 0.127], [65320.3, 0.0], [65579.0, 5.29], [65673.6, 0.02], [104929.0, 0.236]]}
{"kind": "depth", "E": 1787095217541, "U": 11316364323418, "u": 11316364328423, "recv_ms": 1787095217613, "bids": [[14373.5, 2.072], [14473.5, 2.128], [51739.0, 0.0], [58206.1, 0.002], [62086.5, 0.002], [64026.8, 0.452], [64610.4, 0.009], [64633.1, 0.001], [64633.2, 0.001], [64649.2, 0.209], [64650.1, 0.096], [64655.6, 0.012], [64660.7, 0.248], [64661.5, 0.002], [64665.9, 0.136], [64667.3, 0.018], [64667.7, 1.119], [64667.8, 0.659], [64668.6, 0.007], [64668.8, 0.102], [64669.3, 2.856], [64669.5, 0.008], [64670.2, 0.246], [64670.4, 0.041], [64671.8, 0.086]], "asks": [[64674.4, 0.028], [64677.9, 0.0], [64678.5, 0.059], [64684.6, 0.122], [64686.8, 0.012], [64697.8, 3.903], [64717.9, 1.973], [64739.2, 1.221], [64740.6, 0.004], [64740.8, 1.351], [64741.8, 0.039], [64869.9, 5.953], [65320.3, 0.0], [65643.7, 2.279]]}
{"kind": "depth", "E": 1787095217643, "U": 11316364328501, "u": 11316364333596, "recv_ms": 1787095217712, "bids": [[1000.0, 35.76], [14373.5, 2.436], [14473.5, 1.764], [51738.8, 0.0], [51739.0, 0.002], [58206.1, 0.002], [63916.8, 2.188], [63943.6, 0.781], [64026.8, 0.452], [64059.4, 10.835], [64350.1, 0.63], [64355.5, 5.091], [64521.5, 2.396], [64533.2, 0.0], [64578.1, 0.006], [64578.4, 1.767], [64660.7, 0.256], [64665.9, 0.128], [64667.8, 0.659], [64668.6, 0.007], [64669.4, 1.558], [64670.2, 0.246]], "asks": [[64717.6, 0.057], [64741.8, 0.0], [64742.1, 0.042], [64743.7, 47.266], [64745.8, 0.001], [64745.9, 2.342], [64772.9, 0.022], [64814.3, 0.001], [64814.6, 0.0], [64997.0, 0.818], [65002.4, 3.229], [65126.9, 0.421], [65196.4, 1.835], [65320.3, 0.0], [65624.6, 10.267]]}
{"kind": "depth", "E": 1787095217745, "U": 11316364333677, "u": 11316364339676, "recv_ms": 1787095217817, "bids": [[1000.0, 35.76], [14373.5, 2.786], [14473.5, 1.414], [51739.0, 0.0], [58206.1, 0.002], [61439.8, 0.008], [62086.5, 0.005], [63673.5, 0.008], [63829.4, 0.939], [64026.8, 0.452], [64350.1, 0.775], [64516.3, 0.0], [64516.9, 1.152], [64553.9, 0.019], [64604.8, 8.324], [64610.6, 0.006], [64627.4, 3.511], [64643.6, 0.543], [64650.1, 0.096], [64655.6, 0.012], [64660.7, 0.248], [64661.5, 0.002], [64665.9, 0.136], [64667.3, 0.018], [64667.8, 0.66], [64668.6, 0.006], [64669.4, 1.674], [64669.5, 0.008], [64670.2, 0.246], [64670.4, 0.003], [64670.6, 0.088], [64673.5, 7.566]], "asks": [[64675.2, 0.1], [64683.4, 0.037], [64683.5, 0.036], [64697.8, 4.466], [64713.9, 2.029], [64714.0, 3.518], [64714.4, 0.011], [64736.6, 6.0], [64742.1, 0.003], [64742.5, 0.04], [64743.7, 0.005], [64750.0, 2.983], [64752.5, 47.262], [64831.1, 0.001], [64997.0, 0.972], [65320.3, 0.0], [65512.0, 0.077], [65673.6, 0.0], [71141.0, 0.015]]}
{"kind": "depth", "E": 1787095217847, "U": 11316364339929, "u": 11316364345580, "recv_ms": 1787095217917, "bids": [[14373.5, 3.15], [14473.5, 1.05], [58206.1, 0.002], [61439.8, 0.008], [62086.5, 0.002], [63218.6, 0.0], [63764.7, 11.757], [64026.8, 0.452], [64059.1, 2.96], [64477.4, 0.004], [64477.5, 12.651], [64516.3, 6.266], [64516.9, 1.995], [64533.2, 3.779], [64607.8, 1.841], [64632.6, 2.69], [64650.1, 0.096], [64655.6, 0.012], [64658.8, 0.777], [64660.7, 0.256], [64661.5, 0.002], [64665.9, 0.128], [64666.2, 0.656], [64667.0, 1.295], [64667.3, 0.018], [64667.8, 0.543], [64667.9, 0.564], [64668.0, 0.105], [64669.1, 0.013], [64669.3, 2.794], [64669.4, 1.674], [64669.5, 0.355], [64670.3, 0.002], [64670.4, 0.041], [64670.5, 0.073]], "asks": [[64673.6, 14.001], [64687.5, 1.246], [64741.2, 0.129], [64742.5, 0.001], [64745.9, 49.164], [64752.5, 0.001], [64814.1, 1.714], [64814.2, 5.4], [64831.1, 10.413], [64869.9, 9.334], [65254.9, 0.031], [65320.3, 0.0], [65455.1, 29.659]]}
{"kind": "depth", "E": 1787095217949, "U": 11316364345624, "u": 11316364350382, "recv_ms": 1787095218019, "bids": [[1000.0, 35.76], [14373.5, 3.5], [14473.5, 0.7], [58206.1, 0.002], [62086.5, 0.005], [63673.5, 0.028], [64026.8, 0.452], [64332.7, 0.0], [64332.8, 0.506], [64569.6, 0.008], [64571.7, 0.001], [64572.1, 10.0], [64572.2, 4.174], [64603.1, 0.0], [64603.6, 1.26], [64605.6, 0.155], [64607.5, 36.535], [64609.7, 0.201], [64611.1, 0.002], [64617.3, 2.94], [64667.9, 0.911], [64668.0, 0.336], [64668.1, 0.002], [64668.3, 0.001], [64668.6, 0.007], [64669.1, 0.012], [64669.4, 1.558], [64670.3, 0.435], [64670.8, 0.005], [64672.0, 0.005], [64672.2, 0.124]], "asks": [[64676.4, 0.173], [64740.7, 0.04], [64741.2, 0.09], [64741.9, 0.001], [64768.4, 2.648], [64769.0, 10.527], [64783.5, 0.025], [65191.0, 6.276], [65320.3, 0.0], [65449.7, 9.016], [65624.3, 1.752], [65673.6, 0.02]]}
{"kind": "depth", "E": 1787095218051, "U": 11316364350406, "u": 11316364355146, "recv_ms": 1787095218121, "bids": [[14273.5, 0.056], [14373.5, 3.752], [14473.5, 0.392], [58206.1, 0.002], [61439.8, 0.006], [61439.9, 0.01], [63218.3, 0.631], [63375.9, 0.058], [63447.8, 0.058], [63519.6, 0.06], [63591.5, 0.058], [63663.3, 0.058], [63735.2, 0.058], [63807.0, 0.358], [63832.7, 4.147], [64026.8, 0.452], [64100.0, 70.418], [64350.1, 0.775], [64516.8, 1.436], [64562.7, 11.073], [64572.2, 0.0], [64604.0, 0.16], [64607.5, 0.0], [64608.8, 0.035], [64609.7, 36.736], [64610.5, 2.668], [64661.9, 0.018], [64667.9, 0.911], [64668.0, 0.336], [64668.6, 0.007], [64669.1, 0.012], [64670.3, 0.435]], "asks": [[64717.7, 2.084], [64725.5, 0.0], [64735.7, 3.136], [64739.2, 0.0], [64740.7, 0.001], [64742.4, 0.051], [64781.6, 1.35], [64783.5, 10.553], [64869.9, 8.512], [65320.3, 0.0], [65477.7, 9.169], [65559.9, 1.218]]}
{"kind": "depth", "E": 1787095218153, "U": 11316364355266, "u": 11316364361071, "recv_ms": 1787095218227, "bids": [[14273.5, 0.266], [14373.5, 3.682], [14473.5, 0.252], [58206.1, 0.002], [61439.8, 0.006], [62086.5, 0.002], [63673.5, 0.008], [63677.5, 0.784], [63878.9, 0.06], [63902.8, 30.632], [63950.8, 2.401], [64022.6, 0.066], [64026.8, 0.452], [64161.5, 3.878], [64350.1, 0.776], [64593.3, 0.005], [64595.8, 0.152], [64600.5, 2.36], [64621.8, 0.086], [64624.6, 0.06], [64629.7, 0.081], [64661.9, 0.013], [64667.9, 0.911], [64668.0, 0.336], [64668.6, 0.007], [64669.1, 0.012], [64670.3, 0.442], [64670.8, 0.005]], "asks": [[64673.6, 14.003], [64741.4, 0.142], [64742.4, 0.012], [64751.3, 0.004], [64997.0, 0.971], [65256.9, 0.234], [65316.0, 0.402], [65320.3, 0.0], [65353.0, 2.033], [65387.8, 0.059], [65459.7, 0.098], [65531.6, 0.058], [65587.6, 1.16], [65603.4, 0.059], [65673.6, 0.0], [65673.8, 6.386], [65675.3, 0.058], [65747.1, 0.059], [65819.0, 3.566], [65890.8, 0.058], [65962.7, 1.58]]}
{"kind": "depth", "E": 1787095218255, "U": 11316364361146, "u": 11316364366253, "recv_ms": 1787095218325, "bids": [[1000.0, 35.76], [14273.5, 0.504], [14373.5, 3.556], [14473.5, 0.14], [51739.0, 0.006], [58206.1, 0.002], [61439.8, 0.006], [62086.5, 0.005], [63732.4, 2.195], [64026.8, 0.452], [64511.8, 0.272], [64516.3, 7.42], [64516.7, 0.341], [64581.4, 2.336], [64603.1, 36.535], [64603.6, 1.26], [64609.7, 0.201], [64647.1, 2.002], [64657.1, 0.011], [64667.7, 1.122], [64667.9, 0.564], [64668.0, 0.105], [64668.6, 0.006], [64669.1, 0.012], [64669.2, 0.424], [64669.4, 1.62], [64669.5, 0.008], [64670.3, 0.009], [64670.5, 0.011], [64671.4, 0.084], [64673.4, 0.018], [64673.5, 8.405]], "asks": [[64673.6, 13.998], [64677.4, 0.015], [64686.5, 0.01], [64687.5, 0.628], [64689.6, 0.02], [64694.9, 0.002], [64741.4, 0.103], [64741.8, 0.039], [64869.9, 6.144], [65320.3, 0.0], [65559.6, 1.218], [65676.0, 10.511], [65843.2, 0.611]]}
{"kind": "depth", "E": 1787095218357, "U": 11316364366353, "u": 11316364371100, "recv_ms": 1787095218433, "bids": [[14273.5, 0.742], [14373.5, 3.444], [14473.5, 0.014], [51739.0, 0.0], [58206.1, 0.002], [61439.8, 0.006], [61439.9, 0.008], [61525.2, 0.004], [62086.5, 0.002], [63412.4, 0.634], [63673.5, 0.028], [64026.8, 0.452], [64350.1, 0.776], [64542.1, 0.0], [64603.1, 0.0], [64605.6, 0.239], [64605.7, 0.039], [64607.5, 0.0], [64609.7, 36.736], [64614.1, 0.017], [64616.5, 0.046], [64619.1, 0.029], [64642.8, 0.0], [64642.9, 0.313], [64643.0, 0.0], [64644.0, 0.397], [64644.3, 0.003], [64647.1, 0.002], [64656.4, 0.627], [64656.8, 0.019], [64658.8, 0.159], [64666.2, 0.038], [64667.7, 1.119], [64667.8, 0.543], [64667.9, 0.564], [64668.0, 0.105], [64669.4, 2.082], [64669.5, 0.239], [64670.3, 0.002], [64670.8, 0.005], [64671.6, 0.003], [64673.4, 0.017], [64673.5, 7.646]], "asks": [[64673.6, 17.703], [64674.6, 0.0], [64675.2, 0.116], [64676.3, 0.004], [64680.9, 0.002], [64693.1, 0.46], [64694.0, 0.001], [64736.6, 6.002], [64737.1, 0.007], [64738.3, 0.106], [64740.8, 1.39], [64741.8, 0.0], [64748.7, 2.33], [64785.6, 0.027], [65320.3, 0.0], [65478.6, 0.763], [65592.0, 1.19], [65673.6, 0.02]]}
{"kind": "depth", "E": 1787095218459, "U": 11316364371280, "u": 11316364375682, "recv_ms": 1787095218528, "bids": [[14273.5, 1.092], [14373.5, 3.108], [14473.5, 0.0], [58206.1, 0.002], [61439.8, 0.004], [61439.9, 0.01], [62086.5, 0.005], [63735.7, 17.668], [63897.4, 10.079], [64026.8, 0.452], [64156.1, 5.757], [64351.8, 0.227], [64612.1, 0.49], [64643.0, 0.057], [64644.2, 0.002], [64644.6, 8.0], [64650.1, 0.096], [64653.2, 0.0], [64654.1, 0.118], [64654.2, 0.009], [64655.6, 0.012], [64655.7, 0.465], [64656.4, 0.07], [64656.7, 0.584], [64659.9, 0.0], [64660.7, 0.256], [64660.8, 0.465], [64660.9, 0.039], [64661.5, 0.002], [64667.2, 0.359], [64667.3, 0.018], [64667.8, 0.002], [64667.9, 0.564], [64668.0, 0.646], [64668.4, 0.004], [64668.7, 0.313], [64669.1, 0.012], [64669.2, 0.423], [64669.4, 1.62], [64669.5, 0.239], [64669.6, 0.093], [64670.3, 0.435], [64672.2, 0.084], [64672.7, 0.084], [64673.5, 7.664]], "asks": [[64673.6, 17.706], [64675.2, 0.032], [64676.0, 1.093], [64681.4, 1.353], [64681.7, 0.537], [64695.0, 0.024], [64695.9, 0.061], [64696.6, 0.016], [64696.9, 0.033], [64697.4, 0.002], [64697.5, 0.246], [64717.6, 0.001], [64740.8, 1.351], [64741.2, 0.129], [65000.6, 0.676], [65002.3, 0.001], [65320.3, 0.0], [65837.7, 1.575]]}
{"kind": "depth", "E": 1787095218561, "U": 11316364375756, "u": 11316364380162, "recv_ms": 1787095218630, "bids": [[1000.0, 35.76], [14273.5, 1.442], [14373.5, 2.758], [58206.1, 0.002], [63673.5, 0.008], [64026.8, 0.452], [64167.4, 0.0], [64605.6, 0.232], [64605.7, 0.001], [64616.5, 0.032], [64667.0, 1.293], [64667.9, 0.565], [64668.7, 0.312], [64669.1, 0.012], [64669.5, 0.008], [64670.3, 0.009], [64670.4, 0.041], [64670.8, 0.005], [64672.7, 0.0]], "asks": [[64675.1, 0.397], [64741.2, 0.09], [64742.5, 0.04], [65316.9, 3.21], [65320.3, 0.0], [65673.6, 0.0]]}
{"kind": "depth", "E": 1787095218663, "U": 11316364380302, "u": 11316364385814, "recv_ms": 1787095218733, "bids": [[14273.5, 1.806], [14373.5, 2.394], [51738.8, 0.0], [51739.0, 0.0], [58206.1, 0.002], [62086.5, 0.002], [63957.8, 1.798], [64026.8, 0.452], [64216.0, 0.264], [64350.1, 0.776], [64563.5, 0.003], [64595.8, 0.149], [64628.2, 0.005], [64660.7, 0.248], [64665.9, 0.136]], "asks": [[64731.9, 0.006], [64751.3, 0.001], [64997.0, 0.97], [65320.3, 0.0], [65482.0, 5.527]]}
{"kind": "depth", "E": 1787095218765, "U": 11316364386000, "u": 11316364390448, "recv_ms": 1787095218835, "bids": [[14273.5, 2.156], [14373.5, 2.044], [58206.1, 0.002], [61439.8, 0.004], [62086.5, 0.005], [63673.5, 0.028], [64026.8, 0.452], [64171.6, 4.669], [64350.1, 0.777], [64634.4, 0.016], [64650.1, 0.096], [64655.6, 0.012], [64660.7, 0.248], [64661.5, 0.002], [64667.3, 0.018], [64667.9, 0.565], [64668.6, 0.006], [64669.5, 0.441], [64670.3, 0.002], [64670.4, 0.003], [64670.8, 0.005], [64673.5, 7.511]], "asks": [[64673.6, 17.707], [64691.0, 0.671], [64691.7, 0.002], [64742.2, 0.095], [64742.5, 0.001], [64743.7, 46.827], [64745.9, 2.342], [64831.1, 0.001], [64831.6, 5.858], [64869.9, 0.018], [64870.4, 10.324], [65320.3, 0.0], [65673.6, 0.02]]}
{"kind": "depth", "E": 1787095218867, "U": 11316364390481, "u": 11316364394866, "recv_ms": 1787095218937, "bids": [[1000.0, 35.76], [14273.5, 2.52], [14373.5, 1.68], [58206.1, 0.002], [61439.8, 0.004], [62086.5, 0.002], [63061.9, 3.25], [63725.0, 0.888], [63962.1, 2.512], [64026.8, 0.452], [64220.2, 0.122], [64516.3, 7.774], [64533.2, 5.053], [64609.8, 6.285], [64632.9, 0.029], [64642.4, 1.701], [64657.3, 0.618], [64660.1, 0.029], [64664.7, 0.874], [64667.1, 1.299], [64669.5, 0.008], [64670.2, 0.246], [64672.2, 0.131], [64673.5, 7.431]], "asks": [[64675.0, 0.011], [64677.5, 0.001], [64679.5, 0.362], [64686.0, 1.641], [64686.9, 0.038], [64693.3, 0.619], [64736.5, 1.947], [64736.7, 0.12], [64741.5, 0.039], [64742.2, 0.056], [64814.1, 0.908], [64814.2, 5.4], [64831.1, 10.413], [64831.6, 0.0], [64869.9, 4.421], [64870.4, 0.48], [65196.4, 1.53], [65607.9, 0.155]]}
{"kind": "depth", "E": 1787095218969, "U": 11316364394921, "u": 11316364400120, "recv_ms": 1787095219039, "bids": [[14273.5, 2.87], [14373.5, 1.33], [58206.1, 0.002], [63497.8, 1.572], [63673.5, 0.008], [63885.8, 10.168], [64026.8, 0.452], [64332.8, 0.014], [64333.0, 7.143], [64350.1, 0.787], [64603.6, 1.242], [64605.6, 0.155], [64619.1, 0.001], [64664.9, 0.283], [64665.6, 0.455], [64667.9, 0.564], [64668.6, 0.006], [64669.1, 0.013], [64670.2, 0.679], [64670.3, 0.002], [64671.6, 0.002], [64673.4, 0.018], [64673.5, 7.971]], "asks": [[64675.2, 0.025], [64677.4, 0.026], [64686.0, 1.023], [64693.3, 0.001], [64741.5, 0.0], [64741.7, 0.039], [65320.3, 0.0], [65673.6, 0.0], [65773.4, 3.948], [66068.5, 0.0]]}
{"kind": "depth", "E": 1787095219071, "U": 11316364400249, "u": 11316364405967, "recv_ms": 1787095219142, "bids": [[14273.5, 3.234], [14373.5, 0.966], [58206.1, 0.002], [62086.5, 0.005], [64026.8, 0.452], [64161.5, 3.567], [64445.8, 0.01], [64467.5, 0.002], [64501.8, 0.003], [64525.4, 0.004], [64661.9, 0.013], [64668.4, 0.088], [64668.7, 0.313], [64669.1, 0.012], [64670.8, 0.005], [64671.8, 0.002], [64672.2, 0.047]], "asks": [[64674.3, 0.09], [64674.6, 0.084], [64678.6, 0.422], [64741.7, 0.0], [64742.2, 0.095], [64869.9, 0.018], [64870.0, 5.655], [65320.3, 0.0], [65773.1, 6.208]]}
{"kind": "depth", "E": 1787095219173, "U": 11316364406136, "u": 11316364414100, "recv_ms": 1787095219243, "bids": [[1000.0, 35.76], [14273.5, 3.584], [14373.5, 0.616], [58206.1, 0.002], [61439.8, 0.004], [62086.5, 0.002], [63056.7, 0.713], [63673.5, 0.028], [63729.3, 0.485], [63826.6, 4.693], [63944.9, 0.007], [64026.8, 0.454], [64086.5, 0.056], [64350.1, 0.786], [64516.3, 0.0], [64516.9, 1.152], [64525.4, 0.007], [64533.2, 0.0], [64600.5, 2.361], [64608.7, 0.001], [64621.8, 0.087], [64624.6, 0.061], [64629.6, 1.17], [64629.7, 0.08]], "asks": [[64673.6, 17.709], [64674.3, 0.006], [64680.4, 0.003], [64697.6, 0.049], [64742.2, 0.056], [64742.4, 0.051], [64814.2, 0.0], [64831.1, 0.001], [65171.1, 0.001], [65191.0, 6.581], [65390.5, 2.438], [65418.0, 14.842], [65422.7, 0.0], [65611.4, 14.612], [65673.6, 0.02]]}
{"kind": "depth", "E": 1787095219275, "U": 11316364414109, "u": 11316364422030, "recv_ms": 1787095219345, "bids": [[14173.5, 0.084], [14273.5, 3.78], [14373.5, 0.336], [51739.0, 0.0], [58206.1, 0.002], [62086.5, 0.005], [63763.8, 21.471], [64026.8, 0.452], [64156.1, 6.068], [64161.5, 3.256], [64350.1, 0.786], [64516.3, 7.502], [64533.3, 4.916], [64557.2, 0.002], [64557.3, 3.869], [64601.5, 0.047], [64604.8, 2.324], [64607.8, 1.172], [64619.1, 0.029], [64627.4, 0.011], [64643.6, 0.0], [64650.1, 0.251], [64655.6, 0.167], [64657.1, 0.009], [64660.7, 0.403], [64660.9, 0.039], [64661.5, 0.157], [64665.9, 0.136], [64667.0, 1.299], [64667.3, 0.173], [64669.5, 0.163], [64670.8, 0.005]], "asks": [[64689.6, 0.018], [64697.8, 3.903], [64713.9, 1.507], [64714.0, 0.018], [64736.5, 0.015], [64736.6, 0.002], [64741.8, 0.039], [64742.4, 0.012], [64743.8, 6.303], [64743.9, 0.072], [64808.1, 3.889], [64814.6, 4.807], [64831.6, 5.858], [64870.0, 0.084], [64870.4, 11.092], [64997.0, 0.971], [65320.3, 0.0], [65320.4, 0.173]]}
{"kind": "depth", "E": 1787095219377, "U": 11316364422154, "u": 11316364427428, "recv_ms": 1787095219446, "bids": [[1000.0, 35.76], [14173.5, 0.322], [14273.5, 3.654], [14373.5, 0.224], [51739.0, 0.0], [58206.1, 0.002], [62086.5, 0.002], [63673.5, 0.008], [63950.5, 6.255], [64026.8, 0.452], [64090.8, 0.235], [64216.0, 0.147], [64516.9, 2.173], [64572.1, 0.0], [64605.6, 0.078], [64650.1, 0.096], [64655.6, 0.012], [64657.1, 0.011], [64660.7, 0.248], [64661.5, 0.002], [64667.3, 0.018], [64669.5, 0.008]], "asks": [[64689.6, 0.02], [64740.8, 1.39], [64741.8, 0.0], [64768.4, 1.163], [64769.0, 0.527], [65175.5, 6.013], [65320.3, 0.0], [65418.0, 15.758], [65673.6, 0.0]]}
{"kind": "depth", "E": 1787095219479, "U": 11316364427546, "u": 11316364431672, "recv_ms": 1787095219549, "bids": [[1000.0, 35.76], [14173.5, 0.56], [14273.5, 3.542], [14373.5, 0.098], [51739.0, 0.0], [58206.1, 0.002], [63832.6, 4.931], [64026.8, 0.452], [64156.1, 6.379], [64508.3, 0.104], [64508.4, 0.042], [64533.3, 0.018], [64604.4, 6.0], [64619.1, 0.001], [64627.0, 3.663], [64643.2, 0.601], [64670.8, 0.007]], "asks": [[64697.8, 4.477], [64705.2, 1.916], [64705.3, 0.104], [64714.0, 3.518], [64736.7, 6.12], [64740.8, 1.351], [64741.2, 0.129], [64814.6, 0.0], [65002.4, 3.075], [65280.0, 9.469], [65320.3, 0.0], [65514.4, 3.963], [65851.0, 0.002]]}
{"kind": "depth", "E": 1787095219581, "U": 11316364431749, "u": 11316364435671, "recv_ms": 1787095219651, "bids": [[14173.5, 0.812], [14273.5, 3.388], [14373.5, 0.0], [58206.1, 0.002], [61439.8, 0.004], [62086.5, 0.005], [63673.5, 0.028], [63768.1, 9.123], [63796.2, 10.652], [64026.8, 0.452], [64220.3, 0.118], [64350.1, 0.786], [64477.5, 0.022], [64479.1, 0.37], [64516.3, 0.0], [64516.9, 1.152], [64572.5, 10.003], [64612.6, 0.001], [64612.9, 0.421], [64613.3, 0.093], [64613.6, 2.324], [64613.9, 0.0], [64619.1, 0.029], [64630.0, 0.014], [64630.1, 0.034], [64630.3, 0.24], [64630.6, 0.008], [64630.9, 0.025], [64631.3, 0.004], [64644.9, 0.001], [64645.0, 0.11], [64645.1, 0.0], [64645.2, 0.003], [64645.4, 0.073], [64645.5, 0.028], [64645.6, 0.001], [64645.7, 0.357], [64645.8, 0.202], [64646.5, 0.126], [64646.9, 0.014], [64650.1, 0.251], [64655.6, 0.167], [64660.7, 0.403], [64660.9, 0.047], [64661.5, 0.157], [64663.4, 0.001], [64663.5, 0.631], [64663.6, 0.389], [64663.7, 0.31], [64663.8, 0.186], [64663.9, 0.006], [64664.0, 0.218], [64664.1, 0.073], [64664.2, 0.276], [64664.3, 0.015], [64664.4, 0.163], [64664.7, 0.842], [64664.8, 0.081], [64665.0, 0.004], [64665.3, 0.043], [64665.7, 0.001], [64665.9, 0.128], [64666.0, 0.498], [64667.3, 0.173], [64667.9, 0.565], [64668.7, 0.312], [64669.5, 0.163], [64670.2, 0.246], [64670.8, 0.005], [64673.5, 7.97]], "asks": [[64673.6, 17.71], [64679.0, 4.305], [64679.5, 0.33], [64679.8, 0.002], [64680.2, 0.388], [64680.5, 0.002], [64680.8, 0.001], [64680.9, 0.044], [64681.1, 0.001], [64681.2, 0.46], [64681.3, 0.104], [64681.4, 1.163], [64681.5, 0.005], [64681.6, 0.081], [64681.7, 0.317], [64681.8, 0.003], [64681.9, 1.153], [64682.0, 2.428], [64696.8, 0.004], [64696.9, 0.001], [64697.2, 0.002], [64697.5, 0.208], [64697.6, 0.605], [64697.8, 4.435], [64698.2, 0.167], [64698.3, 0.042], [64698.5, 0.003], [64699.0, 0.122], [64699.6, 0.371], [64699.8, 0.004], [64699.9, 0.42], [64700.0, 2.857], [64700.1, 0.983], [64700.2, 0.001], [64700.3, 0.466], [64700.4, 0.389], [64700.5, 0.003], [64700.6, 0.005], [64714.2, 0.162], [64714.6, 0.0], [64714.9, 0.003], [64715.2, 1.364], [64715.5, 0.158], [64717.7, 2.08], [64741.2, 0.09], [64742.2, 0.095], [64769.0, 10.527], [64831.6, 0.0], [64870.4, 0.48], [65320.3, 0.002], [65673.6, 0.02], [68485.7, 0.002]]}
{"kind": "depth", "E": 1787095219683, "U": 11316364435687, "u": 11316364442861, "recv_ms": 1787095219753, "bids": [[1000.0, 35.76], [14173.5, 1.176], [14273.5, 3.024], [51738.8, 0.0], [58206.1, 0.004], [60854.6, 0.0], [62086.5, 0.002], [64026.8, 0.452], [64040.6, 0.003], [64350.1, 0.785], [64477.5, 14.014], [64479.1, 2.413], [64516.3, 6.817], [64533.3, 4.541], [64630.4, 1.292], [64630.7, 0.162], [64631.4, 0.216], [64650.1, 0.251], [64655.6, 0.167], [64660.7, 0.403], [64661.5, 0.157], [64663.5, 0.701], [64663.7, 0.45], [64663.8, 0.256], [64664.1, 0.173], [64664.2, 0.376], [64664.5, 0.257], [64665.1, 0.032], [64665.4, 1.027], [64666.1, 0.195], [64667.3, 0.173], [64667.9, 0.565], [64668.6, 0.006], [64668.7, 0.312], [64669.1, 0.012], [64669.5, 0.163], [64670.2, 0.679]], "asks": [[64679.7, 0.033], [64680.3, 0.04], [64680.6, 0.046], [64681.2, 0.551], [64681.5, 0.125], [64681.6, 0.211], [64681.9, 1.223], [64682.0, 2.568], [64682.2, 0.08], [64693.1, 0.001], [64694.0, 0.46], [64697.0, 0.059], [64697.5, 0.092], [64697.6, 0.643], [64698.0, 0.268], [64698.2, 0.283], [64699.8, 0.095], [64700.1, 1.103], [64700.2, 0.131], [64700.4, 0.459], [64700.5, 0.073], [64700.6, 0.075], [64700.7, 0.079], [64725.5, 0.004], [64742.2, 0.056], [64742.9, 2.266], [64785.6, 0.127], [64814.2, 5.4], [64831.1, 10.413], [64870.0, 6.811], [64997.0, 1.125], [65320.3, 0.0]]}
{"kind": "depth", "E": 1787095219785, "U": 11316364443030, "u": 11316364447769, "recv_ms": 1787095219855, "bids": [[1000.0, 35.76], [14173.5, 1.526], [14273.5, 2.674], [51739.0, 0.006], [58206.1, 0.002], [61439.8, 0.002], [61439.9, 0.01], [62086.5, 0.005], [63673.5, 0.008], [63800.4, 2.806], [63909.2, 6.568], [64026.8, 0.452], [64492.3, 0.008], [64533.3, 0.018], [64612.4, 0.816], [64619.1, 0.029], [64631.0, 0.032], [64650.1, 0.096], [64655.6, 0.012], [64660.7, 0.248], [64660.9, 0.039], [64661.5, 0.002], [64663.6, 0.459], [64663.9, 0.106], [64664.0, 0.418], [64664.3, 0.085], [64664.4, 0.263], [64665.8, 2.355], [64665.9, 0.136], [64667.3, 0.018], [64667.8, 0.233], [64667.9, 0.564], [64668.3, 0.002], [64668.7, 0.312], [64669.1, 0.012], [64669.4, 1.736], [64669.5, 0.008], [64670.2, 0.246], [64670.3, 0.435], [64670.8, 0.005], [64671.7, 0.085]], "asks": [[64673.6, 17.68], [64676.3, 0.001], [64677.3, 0.089], [64680.0, 0.043], [64681.3, 0.224], [64681.4, 1.254], [64681.7, 0.577], [64681.8, 0.153], [64682.1, 0.094], [64697.3, 1.74], [64698.7, 0.122], [64699.1, 0.141], [64699.9, 0.511], [64700.3, 0.586], [64700.4, 0.609], [64700.7, 0.17], [64742.1, 0.042], [64742.9, 2.227], [64814.2, 0.0], [64997.0, 1.126], [65320.3, 0.0], [65673.6, 0.0]]}
{"kind": "depth", "E": 1787095219887, "U": 11316364447927, "u": 11316364451605, "recv_ms": 1787095219957, "bids": [[14173.5, 1.89], [14273.5, 2.31], [51739.0, 0.0], [58206.1, 0.0], [62086.5, 0.002], [64026.8, 0.452], [64216.0, 0.03], [64350.1, 0.775], [64516.3, 6.95], [64533.3, 4.614], [64562.4, 0.419], [64562.8, 2.746], [64563.5, 0.0], [64603.1, 36.326], [64603.7, 0.0], [64604.5, 1.675], [64609.7, 0.201], [64612.7, 0.032], [64613.8, 0.04], [64619.1, 0.001], [64626.5, 0.399], [64627.1, 1.97], [64628.2, 0.008], [64646.0, 1.889], [64650.1, 0.096], [64655.6, 0.012], [64660.7, 0.248], [64661.5, 0.002], [64663.8, 0.326], [64664.3, 0.185], [64667.3, 0.018], [64667.8, 0.002], [64668.3, 0.001], [64668.7, 0.313], [64669.1, 0.012], [64669.4, 1.62], [64669.5, 0.008], [64670.2, 0.679], [64670.3, 0.002]], "asks": [[64681.4, 1.374], [64681.9, 1.307], [64700.0, 2.977], [64700.5, 0.157], [64715.7, 0.079], [64717.7, 2.084], [64725.5, 0.0], [64731.9, 0.006], [64736.6, 1.934], [64742.1, 0.003], [64742.5, 0.04], [64768.4, 2.648], [64814.2, 5.4], [64831.1, 10.413], [64831.7, 1.318], [64870.0, 7.669], [64878.4, 8.898], [65320.3, 0.0], [65352.7, 0.839], [65482.0, 5.756], [65592.0, 1.417]]}
{"kind": "depth", "E": 1787095219989, "U": 11316364451636, "u": 11316364454987, "recv_ms": 1787095220058, "bids": [[1000.0, 35.76], [14173.5, 2.24], [14273.5, 1.96], [58206.1, 0.002], [61439.9, 0.008], [63673.5, 0.028], [63703.4, 2.998], [63909.2, 5.63], [64026.8, 0.452], [64603.1, 0.0], [64603.6, 1.26], [64605.6, 0.162], [64605.7, 0.039], [64607.5, 36.77], [64608.8, 0.042], [64609.8, 0.001], [64613.0, 0.416], [64613.4, 0.032], [64614.0, 1.033], [64645.5, 0.128], [64645.6, 0.071], [64670.8, 0.005]], "asks": [[64714.4, 0.043], [64715.0, 0.053], [64715.3, 0.068], [64717.7, 2.08], [64739.1, 1.238], [64742.2, 0.095], [64742.5, 0.001], [64762.9, 0.026], [64769.3, 0.075], [65320.3, 0.0], [65673.6, 0.02], [65737.3, 1.063]]}
{"kind": "depth", "E": 1787095220091, "U": 11316364455041, "u": 11316364460036, "recv_ms": 1787095220161, "bids": [[1000.0, 35.76], [14173.5, 2.604], [14273.5, 1.596], [51739.0, 0.0], [58206.1, 0.002], [61439.8, 0.002], [62086.5, 0.005], [63796.2, 10.355], [63828.5, 8.116], [63903.9, 2.814], [64026.8, 0.452], [64220.2, 0.239], [64607.5, 0.0], [64608.9, 2.656], [64609.6, 38.15], [64613.7, 1.142], [64623.3, 0.025], [64623.6, 0.363], [64645.0, 0.18], [64645.1, 0.07], [64645.2, 0.073], [64645.3, 0.071], [64645.7, 0.457], [64645.8, 0.272], [64645.9, 0.076], [64650.1, 0.096], [64655.6, 0.012], [64660.7, 0.248], [64661.5, 0.002], [64661.9, 0.013], [64665.4, 1.119], [64667.3, 0.018], [64668.3, 0.002], [64668.7, 0.312], [64669.1, 0.012], [64669.5, 0.441], [64670.2, 0.246]], "asks": [[64673.6, 17.687], [64687.3, 1.016], [64693.2, 0.461], [64694.0, 0.001], [64694.6, 0.873], [64705.1, 2.637], [64705.2, 0.031], [64714.7, 0.064], [64725.5, 0.004], [64726.8, 0.001], [64727.2, 0.061], [64731.9, 0.081], [64742.1, 0.042], [64742.2, 0.056], [64762.9, 0.022], [64769.3, 0.0], [64870.0, 7.766], [65320.3, 0.0], [65487.4, 0.002]]}
{"kind": "depth", "E": 1787095220193, "U": 11316364460114, "u": 11316364465257, "recv_ms": 1787095220263, "bids": [[14173.5, 2.968], [14273.5, 1.232], [51739.0, 0.0], [58206.1, 0.002], [62086.5, 0.002], [63673.5, 0.008], [63893.2, 25.922], [63903.9, 3.752], [64026.8, 0.452], [64086.0, 1.091], [64350.1, 0.785], [64593.3, 0.004], [64595.8, 0.152], [64600.5, 2.363], [64603.6, 1.242], [64607.5, 36.77], [64609.6, 1.38], [64624.5, 0.005], [64624.6, 0.059], [64629.6, 1.172], [64645.0, 0.25], [64645.3, 0.171], [64645.5, 0.228], [64646.6, 0.106], [64647.0, 3.366], [64650.1, 0.096], [64653.2, 0.116], [64654.1, 0.002], [64655.4, 0.363], [64655.8, 0.557], [64656.7, 0.027], [64659.9, 0.0], [64660.7, 0.248], [64660.8, 0.465], [64661.5, 0.002], [64667.2, 0.359], [64667.3, 0.018], [64668.0, 0.105], [64668.1, 0.543], [64668.3, 0.002], [64668.7, 0.312], [64669.1, 0.012], [64669.5, 0.441], [64670.8, 0.005]], "asks": [[64673.6, 17.687], [64692.4, 0.323], [64693.2, 0.002], [64693.4, 0.459], [64696.0, 1.077], [64696.6, 0.016], [64696.9, 0.557], [64697.5, 0.208], [64697.6, 0.087], [64698.2, 0.167], [64725.5, 0.0], [64751.3, 0.004], [65320.3, 0.0], [65448.7, 5.503], [65574.7, 16.422], [65673.6, 0.0]]}
{"kind": "depth", "E": 1787095220295, "U": 11316364465321, "u": 11316364469552, "recv_ms": 1787095220365, "bids": [[1000.0, 35.76], [14173.5, 3.318], [14273.5, 0.882], [51739.0, 0.0], [58206.1, 0.002], [61439.8, 0.002], [62086.5, 0.005], [63699.2, 11.992], [64026.8, 0.452], [64350.1, 0.786], [64355.5, 2.764], [64645.2, 0.143], [64645.7, 0.557], [64650.1, 0.251], [64655.4, 0.518], [64657.1, 0.009], [64660.7, 0.403], [64661.5, 0.157], [64667.3, 0.173], [64668.3, 0.002], [64668.7, 0.312], [64669.5, 0.596]], "asks": [[64674.3, 0.0], [64689.6, 0.018], [64717.7, 2.084], [64742.1, 0.003], [64742.2, 0.095], [64997.0, 1.125], [65002.4, 0.771], [65320.3, 2.293], [65320.4, 0.172], [65740.7, 2.81], [71141.0, 0.015]]}
{"kind": "depth", "E": 1787095220397, "U": 11316364469764, "u": 11316364474136, "recv_ms": 1787095220468, "bids": [[1000.0, 35.76], [14173.5, 3.668], [14273.5, 0.532], [58206.1, 0.002], [61439.8, 0.002], [63673.5, 0.028], [63832.7, 4.46], [64026.8, 0.452], [64091.3, 1.09], [64650.1, 0.096], [64655.4, 0.363], [64657.1, 0.011], [64660.7, 0.248], [64661.5, 0.002], [64667.3, 0.018], [64668.0, 0.106], [64668.1, 0.627], [64668.3, 0.001], [64668.6, 0.006], [64668.7, 0.312], [64669.1, 0.012], [64669.5, 0.441], [64670.8, 0.005], [64671.4, 0.0], [64671.7, 0.001], [64673.5, 7.97]], "asks": [[64673.6, 17.706], [64673.9, 0.086], [64676.0, 1.086], [64679.0, 4.288], [64683.4, 0.018], [64683.5, 0.014], [64689.6, 0.02], [64741.5, 0.039], [64742.2, 0.056], [64831.1, 0.001], [64831.6, 5.826], [64870.0, 0.084], [64870.4, 10.711], [65320.3, 2.293], [65443.2, 3.664], [65673.6, 0.02]]}
