{"kind": "depth", "E": 1787095187655, "U": 11316362075725, "u": 11316362080547, "recv_ms": 1787095187724, "bids": [[1000.0, 35.76], [14378.9, 2.478], [14478.9, 1.722], [51743.0, 0.0], [58211.0, 0.01], [61444.9, 0.0], [62091.7, 0.689], [63678.9, 1.173], [63844.1, 0.0], [64032.1, 4.699], [64161.5, 8.7], [64516.6, 0.007], [64516.9, 9.414], [64655.4, 0.001], [64658.1, 1.229], [64660.6, 0.027], [64665.5, 0.002], [64665.8, 2.391], [64665.9, 1.586], [64666.1, 0.232], [64666.2, 0.456], [64666.4, 0.185], [64666.6, 0.967], [64666.7, 0.577], [64667.3, 0.454], [64670.7, 0.002], [64671.6, 0.525], [64672.4, 0.55], [64675.2, 0.512], [64675.5, 0.002], [64676.5, 0.011], [64678.9, 5.515]], "asks": [[64679.0, 14.959], [64681.2, 0.017], [64681.9, 0.012], [64683.1, 0.157], [64684.8, 0.195], [64685.3, 0.042], [64686.2, 0.209], [64686.3, 0.219], [64686.5, 0.222], [64686.6, 0.406], [64686.7, 0.848], [64686.8, 1.074], [64687.0, 0.566], [64687.1, 0.516], [64690.9, 0.159], [64693.6, 0.594], [64694.4, 0.673], [64698.8, 0.163], [64699.1, 0.001], [64703.8, 0.287], [64704.2, 0.282], [64705.0, 0.093], [64705.2, 0.122], [64705.3, 0.224], [64705.5, 0.257], [64705.7, 0.078], [64705.9, 0.14], [64706.0, 0.457], [64738.6, 0.04], [64874.9, 4.593], [65002.4, 4.001], [65325.8, 5.167], [65679.0, 0.342]]}
{"kind": "depth", "E": 1787095187757, "U": 11316362080599, "u": 11316362084933, "recv_ms": 1787095187825, "bids": [[14378.9, 2.828], [14478.9, 1.372], [51743.0, 0.0], [58211.0, 0.01], [63535.3, 1.257], [63741.1, 22.344], [63902.8, 22.925], [64032.1, 4.699], [64355.5, 4.433], [64516.9, 7.468], [64517.0, 2.402], [64632.0, 1.584], [64655.4, 0.001], [64660.6, 0.027], [64665.8, 2.461], [64666.0, 0.894], [64666.1, 0.332], [64667.0, 1.285], [64667.3, 0.454], [64670.7, 0.002], [64671.4, 0.009], [64671.6, 0.187], [64671.8, 0.318], [64672.4, 0.55], [64675.2, 0.091], [64675.3, 0.087]], "asks": [[64683.1, 0.157], [64685.9, 0.083], [64686.6, 0.406], [64686.8, 1.224], [64686.9, 0.178], [64687.1, 0.607], [64690.9, 0.159], [64694.4, 0.673], [64698.8, 0.008], [64699.1, 0.156], [64703.4, 2.368], [64705.6, 1.418], [64705.8, 0.161], [64705.9, 0.231], [64720.9, 0.123], [64819.1, 3.876], [64836.1, 5.435], [64874.9, 1.423], [65325.8, 5.167], [65455.1, 23.112]]}
{"kind": "depth", "E": 1787095187859, "U": 11316362085337, "u": 11316362090704, "recv_ms": 1787095187927, "bids": [[1000.0, 35.76], [14378.9, 3.192], [14478.9, 1.008], [58211.0, 0.01], [61444.9, 0.0], [62091.7, 0.692], [63678.9, 1.153], [63902.8, 24.8], [64032.1, 4.699], [64161.5, 9.634], [64563.5, 3.865], [64574.0, 2.32], [64607.7, 2.451], [64614.8, 0.036], [64615.1, 0.056], [64615.4, 0.032], [64615.7, 0.083], [64642.6, 0.056], [64666.5, 0.111], [64671.1, 0.002], [64671.9, 0.006], [64672.4, 0.888], [64672.5, 0.116], [64674.7, 0.31], [64675.2, 0.091], [64675.3, 0.424], [64675.7, 0.01], [64676.5, 0.011], [64678.9, 5.754]], "asks": [[64679.0, 14.32], [64680.5, 0.001], [64681.2, 0.015], [64682.4, 0.087], [64685.5, 0.158], [64686.4, 0.256], [64686.6, 0.408], [64688.0, 1.605], [64690.3, 0.354], [64693.6, 0.601], [64695.3, 0.0], [64705.3, 0.344], [64720.4, 3.278], [64737.7, 0.039], [64738.6, 0.001], [64750.1, 0.049], [64787.8, 5.318], [64814.3, 3.866], [64819.1, 5.427], [64836.1, 10.412], [64874.9, 4.594], [65325.8, 5.167], [65584.5, 26.191], [65679.0, 0.322]]}
{"kind": "depth", "E": 1787095187961, "U": 11316362090773, "u": 11316362095322, "recv_ms": 1787095188030, "bids": [[1000.0, 35.76], [14378.9, 3.542], [14478.9, 0.658], [58211.0, 0.01], [61445.0, 0.055], [62091.7, 0.689], [63547.0, 5.031], [63838.1, 0.313], [64032.1, 4.699], [64624.5, 0.018], [64647.1, 0.072], [64647.4, 3.664], [64647.5, 0.649], [64647.8, 0.144], [64671.6, 0.11], [64672.4, 0.627], [64672.5, 0.116], [64672.7, 0.453], [64672.9, 0.147], [64675.1, 1.547], [64675.2, 0.021], [64675.3, 0.003], [64675.4, 0.004], [64675.5, 0.002], [64675.6, 0.005], [64675.7, 0.439], [64678.6, 0.493]], "asks": [[64679.0, 14.319], [64685.5, 0.045], [64686.6, 0.409], [64690.3, 0.431], [64693.6, 0.947], [64737.7, 0.0], [64740.9, 0.039], [65325.8, 5.167]]}
{"kind": "depth", "E": 1787095188063, "U": 11316362095462, "u": 11316362100160, "recv_ms": 1787095188132, "bids": [[14278.9, 0.07], [14378.9, 3.766], [14478.9, 0.364], [58211.0, 0.01], [62091.7, 0.692], [63678.9, 1.173], [63761.7, 7.048], [64032.1, 4.699], [64355.5, 4.423], [64614.2, 6.446], [64614.5, 0.032], [64624.5, 0.004], [64646.9, 0.071], [64647.0, 0.071], [64647.2, 0.696], [64647.4, 3.764], [64647.6, 0.102], [64647.7, 0.089], [64648.7, 0.103], [64649.1, 0.102], [64655.4, 0.001], [64660.6, 0.027], [64667.3, 0.454], [64670.7, 0.002], [64671.6, 0.187], [64672.4, 0.55], [64672.5, 0.003], [64672.7, 0.003], [64672.8, 0.0], [64675.1, 0.001], [64675.2, 0.029], [64675.3, 0.424], [64675.4, 1.55], [64675.7, 0.01], [64676.5, 0.011], [64678.6, 0.239]], "asks": [[64683.1, 0.157], [64686.6, 0.409], [64690.3, 0.438], [64690.9, 0.159], [64694.4, 0.673], [64698.4, 0.92], [64699.1, 0.156], [64721.3, 0.603], [64721.4, 2.353], [64739.6, 0.252], [64740.9, 0.0], [64874.9, 4.701], [65325.8, 5.167], [65679.0, 0.342]]}
{"kind": "depth", "E": 1787095188165, "U": 11316362100281, "u": 11316362105356, "recv_ms": 1787095188233, "bids": [[1000.0, 35.76], [14278.9, 0.294], [14378.9, 3.668], [14478.9, 0.238], [51743.0, 0.0], [58211.0, 0.01], [61444.9, 0.0], [63879.0, 3.308], [64032.1, 4.699], [64624.5, 0.004], [64632.3, 0.047], [64632.5, 6.402], [64633.6, 0.638], [64647.0, 0.141], [64647.1, 0.142], [64647.3, 0.114], [64672.7, 0.003], [64675.1, 1.547], [64675.3, 0.087], [64675.4, 0.004], [64675.5, 0.002], [64678.6, 0.484], [64678.9, 5.769]], "asks": [[64679.0, 14.318], [64683.9, 0.005], [64684.8, 0.027], [64685.3, 0.042], [64685.5, 0.27], [64686.3, 0.22], [64690.3, 0.438], [64693.6, 0.678], [64710.8, 0.028], [64721.3, 0.449], [64724.3, 0.004], [64735.0, 0.179], [64735.2, 1.03], [64735.9, 0.003], [64736.2, 0.068], [64738.8, 0.077], [64739.6, 0.213], [64740.4, 0.428], [65325.8, 5.167]]}
{"kind": "depth", "E": 1787095188267, "U": 11316362105362, "u": 11316362109790, "recv_ms": 1787095188336, "bids": [[1000.0, 35.76], [14278.9, 0.532], [14378.9, 3.556], [14478.9, 0.112], [51743.0, 0.0], [51743.1, 0.0], [58211.0, 0.01], [61444.9, 0.0], [62091.7, 0.689], [63678.9, 1.153], [64032.1, 4.699], [64624.5, 0.004], [64646.2, 2.032], [64647.6, 0.202], [64662.5, 0.004], [64672.4, 0.55], [64675.2, 0.029], [64678.6, 0.239], [64678.9, 5.774]], "asks": [[64684.8, 0.195], [64690.3, 0.431], [64693.6, 0.947], [64695.0, 0.024], [64721.5, 0.16], [64874.9, 4.399], [65325.8, 5.167], [65679.0, 0.322], [65972.5, 0.009]]}
{"kind": "depth", "E": 1787095188369, "U": 11316362109862, "u": 11316362118064, "recv_ms": 1787095188440, "bids": [[14278.9, 0.77], [14378.9, 3.43], [14478.9, 0.0], [58211.0, 0.01], [62091.7, 0.692], [63773.4, 16.034], [64032.1, 4.699], [64085.0, 4.077], [64095.6, 1.103], [64355.5, 4.423], [64563.5, 3.865], [64568.9, 0.003], [64607.7, 2.451], [64624.5, 0.032], [64642.3, 2.39], [64642.6, 0.014], [64642.9, 2.041], [64662.5, 0.006], [64672.4, 0.55], [64672.5, 0.003], [64672.7, 0.003], [64672.8, 0.225], [64675.2, 0.029], [64676.5, 0.011], [64678.9, 5.775]], "asks": [[64685.5, 0.045], [64689.0, 1.903], [64690.0, 0.072], [64693.6, 0.755], [64695.0, 0.026], [64698.4, 0.991], [64734.0, 0.001], [64736.0, 0.08], [64736.2, 0.007], [64750.1, 0.049], [64756.7, 0.049], [64795.6, 0.105], [64814.2, 0.0], [64814.3, 3.866], [65002.4, 4.0], [65325.8, 5.167], [65477.7, 14.995], [65597.4, 1.592]]}
{"kind": "depth", "E": 1787095188471, "U": 11316362118280, "u": 11316362126248, "recv_ms": 1787095188563, "bids": [[1000.0, 35.76], [14278.9, 1.134], [14378.9, 3.066], [58211.0, 0.01], [61444.9, 0.0], [61445.1, 0.01], [62091.7, 0.689], [63385.4, 0.969], [63678.9, 1.173], [63760.5, 1.404], [64032.1, 4.699], [64355.5, 4.424], [64533.6, 0.0], [64671.9, 0.003], [64672.1, 0.037], [64672.5, 0.003], [64672.8, 0.0], [64678.9, 5.776]], "asks": [[64679.0, 14.304], [64682.2, 0.177], [64683.9, 0.005], [64684.6, 0.277], [64684.7, 0.303], [64684.8, 0.195], [64685.3, 0.38], [64685.5, 0.045], [64686.5, 0.763], [64686.6, 0.406], [64686.7, 0.222], [64693.6, 0.966], [64720.4, 3.334], [64735.0, 0.209], [64735.2, 1.0], [64739.5, 0.04], [64740.4, 0.389], [64818.0, 0.47], [64819.1, 0.027], [65325.8, 5.167], [65679.0, 0.342], [71146.9, 0.0]]}
{"kind": "depth", "E": 1787095188573, "U": 11316362126319, "u": 11316362138581, "recv_ms": 1787095188645, "bids": [[1000.0, 35.76], [14278.9, 1.498], [14378.9, 2.702], [51743.0, 0.004], [58211.0, 0.01], [61444.9, 0.0], [61445.0, 0.053], [61445.1, 0.012], [62091.7, 0.692], [63385.4, 0.963], [63860.8, 14.464], [64032.1, 4.699], [64094.4, 0.0], [64161.5, 9.323], [64403.0, 0.0], [64516.9, 0.0], [64517.0, 0.135], [64517.1, 7.443], [64522.7, 0.093], [64534.1, 8.309], [64571.9, 0.0], [64625.1, 0.21], [64632.4, 0.0], [64639.3, 8.116], [64642.2, 1.154], [64642.6, 0.056], [64642.9, 2.041], [64645.7, 0.01], [64646.2, 0.032], [64646.5, 0.126], [64651.2, 1.343], [64653.0, 1.056], [64654.3, 0.001], [64658.1, 1.229], [64658.7, 0.001], [64659.5, 0.794], [64660.5, 1.663], [64660.9, 0.004], [64662.1, 0.558], [64663.5, 0.671], [64663.6, 0.465], [64665.5, 0.002], [64665.9, 2.045], [64666.0, 0.901], [64666.2, 0.476], [64666.5, 0.104], [64666.7, 0.118], [64666.9, 0.257], [64667.5, 0.324], [64667.8, 0.005], [64669.2, 0.532], [64669.3, 3.15], [64669.4, 0.011], [64670.4, 1.283], [64670.6, 1.544], [64670.7, 0.102], [64671.1, 0.086], [64671.5, 1.749], [64671.6, 0.171], [64671.8, 0.086], [64672.0, 0.005], [64672.1, 0.036], [64672.4, 0.008], [64672.5, 0.544], [64672.7, 1.557], [64672.8, 0.008], [64672.9, 0.085], [64673.1, 0.004], [64673.5, 0.089], [64673.9, 0.092], [64674.1, 0.057], [64674.5, 0.0], [64674.7, 0.0], [64674.9, 2.324], [64675.0, 0.987], [64675.1, 0.001], [64675.2, 0.016], [64675.3, 0.073], [64675.9, 0.003], [64676.3, 0.0], [64676.5, 0.011], [64678.4, 0.023], [64678.7, 0.022], [64678.8, 0.037], [64678.9, 4.218]], "asks": [[64679.0, 26.61], [64679.2, 0.004], [64679.8, 0.002], [64680.3, 0.312], [64680.6, 0.003], [64680.9, 0.007], [64681.0, 0.009], [64682.2, 0.009], [64682.4, 0.085], [64683.3, 0.144], [64683.5, 0.113], [64684.6, 0.052], [64684.7, 0.001], [64684.8, 0.027], [64685.3, 0.042], [64685.5, 0.213], [64685.8, 0.631], [64686.3, 0.219], [64686.4, 0.341], [64686.6, 0.406], [64686.8, 1.334], [64686.9, 0.158], [64687.0, 0.235], [64687.5, 0.892], [64687.9, 1.269], [64690.3, 0.277], [64690.4, 0.001], [64691.0, 0.053], [64692.0, 4.353], [64693.6, 0.44], [64694.3, 0.658], [64694.7, 3.406], [64695.3, 0.0], [64696.2, 10.464], [64698.3, 0.459], [64699.8, 0.004], [64699.9, 0.42], [64700.1, 0.478], [64702.3, 0.58], [64702.6, 0.56], [64703.5, 0.633], [64703.7, 0.096], [64717.8, 5.0], [64720.4, 3.278], [64730.7, 0.002], [64736.0, 0.062], [64738.8, 0.154], [64739.2, 1.748], [64739.3, 0.023], [64739.5, 0.001], [64740.9, 0.039], [64741.2, 0.09], [64742.0, 6.005], [64748.1, 2.251], [64749.9, 8.901], [64750.3, 53.114], [64771.2, 0.526], [64797.0, 0.296], [64814.2, 1.485], [64819.1, 3.218], [64836.1, 4.098], [64874.9, 1.429], [64878.2, 0.225], [65196.4, 7.806], [65325.8, 5.167], [65798.8, 0.007]]}
{"kind": "depth", "E": 1787095188675, "U": 11316362138704, "u": 11316362146256, "recv_ms": 1787095188753, "bids": [[14278.9, 1.848], [14378.9, 2.352], [51743.0, 0.0], [58211.0, 0.01], [61444.9, 0.0], [63561.4, 2.965], [63678.9, 1.153], [63860.8, 14.113], [64032.1, 4.699], [64096.8, 12.466], [64161.5, 9.012], [64355.5, 4.424], [64581.9, 0.392], [64601.2, 0.537], [64611.9, 0.003], [64614.2, 2.176], [64617.5, 0.057], [64652.9, 0.004], [64656.0, 0.133], [64662.7, 0.006], [64666.5, 0.105], [64670.7, 0.102], [64671.1, 0.087], [64671.5, 1.748], [64671.6, 0.078], [64671.7, 0.002], [64672.0, 0.006], [64672.2, 0.088], [64672.8, 0.549], [64672.9, 0.085], [64674.8, 0.001], [64675.1, 0.009], [64675.2, 0.017], [64675.3, 0.065], [64678.4, 0.001], [64678.5, 0.0], [64678.7, 0.001], [64678.8, 0.018], [64678.9, 4.222]], "asks": [[64679.0, 26.61], [64687.3, 0.451], [64688.0, 2.505], [64689.0, 1.003], [64691.0, 0.671], [64693.6, 0.524], [64694.3, 0.04], [64698.3, 0.0], [64698.8, 0.467], [64702.3, 0.464], [64702.9, 1.184], [64739.6, 0.252], [64740.9, 0.0], [64743.7, 0.086], [64745.3, 0.078], [64746.9, 0.158], [64748.5, 0.078], [64819.1, 5.427], [64836.1, 10.412], [64874.9, 5.802], [65002.4, 3.999], [65325.8, 5.169], [65679.0, 0.322]]}
{"kind": "depth", "E": 1787095188777, "U": 11316362146326, "u": 11316362153751, "recv_ms": 1787095188846, "bids": [[1000.0, 35.76], [14278.9, 2.198], [14378.9, 2.002], [58211.0, 0.01], [61444.9, 0.0], [62091.7, 0.689], [64032.1, 4.699], [64096.7, 3.425], [64161.5, 9.323], [64355.5, 4.425], [64609.7, 32.499], [64646.0, 0.764], [64646.1, 0.002], [64646.2, 0.034], [64649.4, 0.002], [64649.5, 0.042], [64649.6, 0.048], [64654.9, 0.099], [64655.4, 0.001], [64660.6, 0.027], [64665.9, 1.586], [64667.1, 2.754], [64667.3, 0.454], [64670.7, 0.102], [64671.6, 0.171], [64672.7, 1.549], [64672.9, 0.506], [64673.0, 0.001], [64675.1, 0.017], [64676.0, 0.002], [64678.7, 0.002], [64678.8, 0.016], [64678.9, 4.222]], "asks": [[64683.1, 0.157], [64686.3, 0.374], [64686.6, 0.251], [64690.9, 0.159], [64693.6, 0.601], [64694.4, 0.673], [64698.8, 0.163], [64699.1, 0.001], [64699.3, 10.287], [64702.6, 0.004], [64703.3, 0.556], [64739.6, 0.213], [64740.4, 0.428], [64741.5, 53.071], [64750.3, 0.036], [64795.6, 0.005], [65325.8, 5.167], [65766.9, 1.973], [65810.9, 3.642], [65972.5, 0.006]]}
{"kind": "depth", "E": 1787095188981, "U": 11316362161274, "u": 11316362168310, "recv_ms": 1787095189050, "bids": [[14278.9, 2.912], [14378.9, 1.288], [58211.0, 0.01], [61444.9, 0.0], [62091.7, 0.689], [63579.4, 7.211], [63870.4, 11.477], [63973.9, 3.586], [64032.1, 4.699], [64161.5, 9.634], [64355.5, 4.435], [64609.7, 0.189], [64611.9, 32.313], [64659.5, 0.678], [64660.7, 0.438], [64662.1, 0.001], [64663.4, 0.558], [64669.2, 0.547], [64672.7, 0.003], [64672.9, 0.085], [64674.1, 0.042], [64675.1, 1.563], [64675.2, 0.438], [64676.2, 0.003], [64678.9, 4.219]], "asks": [[64679.0, 26.611], [64682.2, 0.024], [64685.5, 0.045], [64693.6, 0.87], [64700.0, 3.305], [64702.9, 1.068], [64703.5, 0.748], [64863.2, 0.001], [65325.8, 5.168], [65772.1, 1.217]]}
{"kind": "depth", "E": 1787095189083, "U": 11316362168404, "u": 11316362176672, "recv_ms": 1787095189153, "bids": [[1000.0, 35.76], [14278.9, 3.276], [14378.9, 0.924], [58211.0, 0.01], [61444.9, 0.0], [62091.7, 0.692], [63678.9, 1.153], [64032.1, 4.699], [64603.1, 32.31], [64603.8, 0.483], [64611.1, 1.887], [64611.9, 0.003], [64630.8, 3.579], [64655.4, 0.001], [64656.6, 0.003], [64657.5, 0.003], [64658.1, 1.23], [64660.6, 0.027], [64667.0, 1.594], [64667.3, 0.451], [64667.5, 0.015], [64670.7, 0.102], [64670.8, 0.096], [64671.6, 0.094], [64672.9, 1.639], [64673.0, 0.422], [64673.7, 0.0], [64675.1, 0.009], [64675.2, 0.017], [64675.3, 0.065], [64677.9, 0.043], [64678.3, 0.0], [64678.9, 3.842]], "asks": [[64679.0, 26.617], [64680.9, 0.087], [64681.2, 0.005], [64681.9, 0.002], [64683.1, 0.002], [64683.4, 0.001], [64686.3, 0.219], [64688.0, 2.425], [64690.3, 0.284], [64690.9, 0.004], [64693.6, 0.889], [64694.4, 0.363], [64698.8, 0.008], [64721.4, 2.507], [64721.5, 0.006], [64740.2, 0.04], [64740.4, 0.389], [64745.3, 0.001], [64819.1, 5.427], [64836.1, 10.412], [64874.9, 8.234], [65325.8, 5.168], [65679.0, 0.322]]}
{"kind": "depth", "E": 1787095189185, "U": 11316362176824, "u": 11316362199479, "recv_ms": 1787095189256, "bids": [[1000.0, 35.76], [14278.9, 3.626], [14378.9, 0.574], [58211.0, 0.01], [63836.9, 0.0], [63860.8, 13.879], [64032.1, 4.699], [64621.7, 0.02], [64622.4, 1.123], [64634.8, 0.003], [64635.7, 8.101], [64639.3, 0.116], [64640.0, 0.029], [64642.0, 0.041], [64646.2, 0.009], [64660.1, 0.245], [64660.7, 0.322], [64662.5, 0.563], [64663.4, 0.001], [64663.8, 0.162], [64664.5, 0.021], [64664.7, 0.244], [64665.4, 1.01], [64665.9, 2.586], [64666.0, 0.894], [64666.2, 0.456], [64666.3, 0.777], [64667.1, 1.295], [64667.4, 0.009], [64669.3, 2.79], [64669.4, 0.011], [64669.7, 0.004], [64669.8, 0.327], [64670.0, 0.006], [64670.2, 1.295], [64670.4, 1.283], [64670.6, 1.312], [64670.7, 0.026], [64671.1, 0.088], [64671.4, 0.009], [64671.7, 0.001], [64672.7, 0.006], [64672.9, 1.547], [64673.0, 0.093], [64673.1, 0.001], [64673.5, 0.09], [64673.6, 0.005], [64673.9, 0.008], [64674.0, 0.087], [64674.2, 0.01], [64674.7, 0.084], [64674.8, 0.0], [64675.0, 1.071], [64675.1, 0.009], [64675.2, 0.079], [64675.3, 0.003], [64676.5, 0.011], [64677.4, 0.001], [64677.6, 0.041], [64678.9, 3.775]], "asks": [[64679.0, 28.918], [64680.6, 0.008], [64680.9, 0.002], [64681.2, 0.015], [64681.5, 0.089], [64681.6, 0.011], [64681.9, 0.012], [64682.3, 0.584], [64682.4, 0.086], [64682.5, 0.011], [64684.7, 0.094], [64684.8, 2.346], [64685.3, 0.042], [64685.5, 0.045], [64686.3, 0.211], [64686.4, 0.256], [64686.5, 0.863], [64686.6, 0.253], [64687.1, 0.607], [64690.3, 0.354], [64690.9, 0.004], [64691.9, 4.909], [64692.1, 0.013], [64692.2, 0.042], [64692.9, 0.323], [64693.2, 0.017], [64693.6, 0.317], [64694.6, 0.195], [64694.7, 2.003], [64696.2, 0.464], [64699.4, 0.384], [64704.1, 0.02], [64705.7, 0.071], [64709.2, 0.001], [64709.6, 0.215], [64716.2, 0.266], [64716.8, 0.079], [64717.8, 5.334], [64718.1, 0.019], [64719.2, 2.084], [64719.7, 0.001], [64720.5, 0.042], [64721.4, 2.353], [64721.5, 0.006], [64727.7, 0.005], [64730.7, 0.003], [64735.9, 0.008], [64736.7, 1.267], [64739.3, 53.094], [64740.0, 2.505], [64740.2, 0.001], [64740.4, 0.466], [64741.5, 0.0], [64743.7, 0.009], [64746.9, 0.081], [64769.6, 3.471], [64771.2, 0.726], [65002.4, 3.999], [65325.8, 5.168], [65972.5, 0.012]]}
{"kind": "depth", "E": 1787095189287, "U": 11316362199518, "u": 11316362207312, "recv_ms": 1787095189356, "bids": [[14178.9, 0.112], [14278.9, 3.766], [14378.9, 0.322], [51743.0, 0.0], [51743.1, 0.0], [58211.0, 0.01], [61444.9, 0.0], [62091.7, 0.689], [63678.9, 1.173], [63760.5, 1.639], [63835.7, 0.0], [64032.1, 4.699], [64355.5, 4.425], [64603.1, 0.0], [64603.8, 0.474], [64609.7, 32.499], [64635.7, 0.101], [64640.7, 0.001], [64642.6, 0.014], [64644.8, 9.302], [64645.2, 0.092], [64662.5, 0.561], [64665.9, 1.586], [64666.9, 1.257], [64670.2, 1.063], [64670.8, 0.019], [64670.9, 0.232], [64671.1, 0.003], [64671.5, 1.664], [64671.6, 0.171], [64672.2, 0.089], [64672.4, 0.458], [64672.6, 0.809], [64672.7, 0.116], [64672.9, 1.997], [64673.0, 0.543], [64673.1, 0.001], [64673.4, 0.014], [64674.6, 0.32], [64675.0, 1.637], [64675.1, 0.655], [64675.2, 0.079], [64677.0, 1.099], [64677.4, 0.001], [64677.5, 0.011], [64678.7, 0.002], [64678.8, 0.016], [64678.9, 5.068]], "asks": [[64679.0, 27.946], [64679.3, 0.151], [64679.5, 0.007], [64679.7, 0.001], [64679.8, 0.086], [64680.1, 0.004], [64680.3, 0.002], [64680.6, 0.003], [64680.9, 0.007], [64681.4, 0.16], [64681.5, 0.086], [64682.0, 0.195], [64682.1, 0.002], [64682.4, 0.085], [64684.6, 0.052], [64684.7, 0.639], [64686.5, 0.222], [64686.6, 0.253], [64686.8, 1.224], [64687.1, 0.684], [64687.3, 0.41], [64690.3, 0.277], [64690.7, 0.084], [64690.9, 0.004], [64691.0, 0.687], [64691.9, 0.909], [64692.9, 0.003], [64693.0, 0.322], [64693.6, 0.394], [64694.4, 0.363], [64695.0, 0.024], [64696.7, 0.004], [64700.4, 10.389], [64702.1, 6.078], [64702.3, 0.468], [64713.1, 0.0], [64716.2, 0.066], [64717.8, 5.403], [64719.6, 0.06], [64721.0, 0.034], [64721.1, 0.32], [64721.4, 2.353], [64721.5, 0.006], [64739.3, 53.094], [64740.0, 2.466], [64740.4, 0.428], [64769.6, 3.472], [64819.1, 5.427], [64836.1, 10.412], [64865.0, 0.392], [64867.8, 0.025], [64867.9, 0.012], [64874.9, 5.496], [64883.4, 0.305], [65325.8, 5.168], [65679.0, 0.342]]}
{"kind": "depth", "E": 1787095189389, "U": 11316362207447, "u": 11316362212342, "recv_ms": 1787095189459, "bids": [[1000.0, 35.76], [14178.9, 0.35], [14278.9, 3.64], [14378.9, 0.21], [51743.0, 0.0], [58211.0, 0.01], [61444.9, 0.0], [62091.7, 0.692], [63838.1, 1.407], [64032.1, 4.701], [64505.9, 0.0], [64508.3, 0.143], [64534.1, 3.034], [64568.9, 0.0], [64624.5, 0.018], [64633.6, 0.638], [64651.2, 1.294], [64658.4, 0.05], [64662.5, 0.563], [64670.7, 0.018], [64672.4, 0.008], [64672.6, 0.471], [64672.7, 0.003], [64672.9, 0.001], [64673.0, 0.085], [64673.1, 0.451], [64673.2, 0.225], [64675.0, 1.524], [64675.1, 1.563], [64675.2, 0.087], [64676.5, 0.011], [64678.9, 5.069]], "asks": [[64679.0, 27.937], [64687.1, 0.607], [64691.0, 0.069], [64693.0, 0.002], [64693.6, 0.478], [64694.4, 0.981], [64694.5, 3.97], [64695.0, 0.026], [64720.4, 2.529], [64721.4, 2.353], [64721.6, 1.773], [64724.3, 0.004], [64740.4, 0.389], [64744.7, 0.044], [64756.7, 0.046], [64771.2, 0.926], [64819.1, 0.027], [65325.8, 5.168]]}
{"kind": "depth", "E": 1787095189491, "U": 11316362212374, "u": 11316362218848, "recv_ms": 1787095189559, "bids": [[1000.0, 35.76], [14178.9, 0.588], [14278.9, 3.528], [14378.9, 0.084], [58211.0, 0.01], [61445.0, 0.051], [61445.1, 0.012], [62091.7, 0.689], [63678.9, 1.153], [64032.1, 4.699], [64096.9, 2.291], [64355.5, 4.424], [64534.4, 5.109], [64536.6, 1.162], [64621.3, 2.32], [64658.7, 0.117], [64660.1, 0.129], [64661.4, 0.557], [64662.5, 0.006], [64665.3, 0.711], [64666.3, 0.318], [64671.6, 0.078], [64672.6, 0.471], [64672.7, 0.003], [64672.9, 0.001], [64673.1, 0.001], [64673.2, 0.0], [64675.0, 1.071], [64675.1, 1.563], [64675.2, 0.508], [64677.6, 0.001], [64677.8, 0.045], [64678.9, 5.072]], "asks": [[64679.0, 27.954], [64691.9, 0.986], [64693.6, 0.593], [64697.8, 3.861], [64698.7, 0.541], [64699.3, 9.828], [64701.5, 1.257], [64701.7, 0.557], [64702.5, 0.116], [64703.3, 0.0], [64703.5, 0.633], [64744.7, 0.005], [64746.0, 0.053], [64819.2, 5.407], [64872.9, 0.002], [64874.9, 5.583], [65002.4, 4.0], [65325.8, 5.168], [65574.7, 17.61], [65679.0, 0.322]]}
{"kind": "depth", "E": 1787095189593, "U": 11316362219030, "u": 11316362226372, "recv_ms": 1787095189662, "bids": [[14178.9, 0.854], [14278.9, 3.346], [14378.9, 0.0], [58211.0, 0.01], [61444.9, 0.0], [63838.0, 3.658], [64032.1, 4.699], [64096.8, 13.557], [64508.3, 0.104], [64509.1, 0.48], [64517.2, 2.361], [64624.5, 0.018], [64630.8, 3.578], [64634.7, 0.001], [64646.8, 0.004], [64654.0, 0.117], [64657.6, 1.397], [64665.0, 0.622], [64671.6, 0.171], [64672.4, 0.008], [64672.6, 0.471], [64672.7, 0.341], [64672.9, 0.451], [64673.0, 0.535], [64675.2, 0.508], [64675.3, 0.537], [64676.3, 0.084], [64676.5, 0.011], [64677.0, 1.015], [64678.9, 5.071]], "asks": [[64679.0, 27.978], [64684.6, 0.068], [64687.5, 1.51], [64691.0, 0.053], [64691.9, 1.07], [64693.6, 0.766], [64694.9, 0.62], [64721.5, 0.16], [64721.6, 1.619], [64721.7, 0.028], [64818.1, 0.896], [65325.8, 5.168], [65448.7, 7.335]]}
{"kind": "depth", "E": 1787095189695, "U": 11316362226461, "u": 11316362232351, "recv_ms": 1787095189765, "bids": [[1000.0, 35.76], [14178.9, 1.218], [14278.9, 2.982], [58211.0, 0.01], [61444.9, 0.0], [62091.7, 0.692], [63678.9, 1.173], [64032.1, 4.699], [64036.3, 0.005], [64508.3, 0.143], [64509.1, 0.441], [64534.4, 0.001], [64536.6, 0.464], [64624.5, 0.004], [64672.4, 0.008], [64672.6, 0.471], [64672.7, 0.003], [64672.9, 0.451], [64673.0, 0.085], [64675.1, 1.563], [64675.2, 0.508], [64675.3, 0.003], [64678.6, 0.239], [64678.9, 5.068]], "asks": [[64679.4, 0.394], [64684.7, 0.662], [64691.9, 1.185], [64721.5, 0.006], [64721.7, 0.182], [64818.1, 0.024], [64819.2, 0.007], [65325.8, 5.168], [65572.4, 6.7], [65584.5, 28.475], [65679.0, 0.342]]}
{"kind": "depth", "E": 1787095189797, "U": 11316362232470, "u": 11316362238387, "recv_ms": 1787095189866, "bids": [[1000.0, 35.76], [14178.9, 1.568], [14278.9, 2.632], [51743.0, 0.0], [58211.0, 0.01], [62091.7, 0.689], [63923.3, 1.029], [64032.1, 4.701], [64355.5, 2.106], [64358.3, 0.843], [64508.3, 0.104], [64509.1, 0.48], [64624.5, 0.018], [64672.6, 0.584], [64672.9, 0.226], [64675.2, 0.087]], "asks": [[65002.4, 1.696], [65325.8, 5.168]]}
{"kind": "depth", "E": 1787095189899, "U": 11316362238401, "u": 11316362244889, "recv_ms": 1787095189967, "bids": [[14178.9, 1.932], [14278.9, 2.268], [58211.0, 0.01], [61444.9, 0.0], [62091.7, 0.692], [63385.4, 0.966], [63729.3, 1.191], [63891.2, 5.489], [63935.1, 8.9], [64032.1, 4.699], [64045.0, 0.713], [64477.3, 0.009], [64478.7, 13.892], [64508.3, 0.143], [64509.1, 0.441], [64517.1, 0.003], [64517.2, 0.078], [64517.5, 6.614], [64534.5, 4.593], [64617.4, 2.78], [64668.0, 0.275], [64670.9, 0.0], [64671.8, 0.318], [64672.6, 0.471], [64672.9, 0.001], [64675.2, 0.087], [64676.5, 0.011], [64678.9, 5.069]], "asks": [[64683.5, 0.281], [64684.6, 0.052], [64684.7, 0.619], [64684.8, 2.459], [64691.0, 0.069], [64742.2, 3.084], [64742.9, 2.227], [64819.2, 5.407], [64836.1, 10.412], [64866.7, 0.001], [64874.9, 6.601], [65002.4, 1.697], [65325.8, 5.168], [65448.7, 8.251]]}
{"kind": "depth", "E": 1787095190001, "U": 11316362245001, "u": 11316362250217, "recv_ms": 1787095190070, "bids": [[1000.0, 35.76], [14178.9, 2.296], [14278.9, 1.904], [58211.0, 0.01], [61444.9, 0.0], [62091.7, 0.689], [63678.9, 1.153], [64032.1, 4.699], [64667.0, 2.494], [64667.4, 0.017], [64669.4, 0.003], [64670.7, 0.25], [64671.8, 0.086], [64678.9, 5.072]], "asks": [[64682.2, 0.192], [64682.3, 0.822], [64683.5, 0.113], [64683.9, 0.23], [64684.5, 0.229], [64684.6, 0.406], [64684.7, 1.069], [64684.8, 2.684], [64685.3, 0.042], [64686.9, 0.177], [64687.0, 0.258], [64691.0, 0.053], [64701.7, 0.001], [64702.3, 1.024], [64721.6, 1.619], [64721.7, 0.182], [65325.8, 5.167], [65679.0, 0.322]]}
{"kind": "depth", "E": 1787095190103, "U": 11316362250244, "u": 11316362255807, "recv_ms": 1787095190194, "bids": [[1000.0, 35.76], [14178.9, 2.646], [14278.9, 1.554], [51743.0, 0.0], [58211.0, 0.01], [61444.9, 0.0], [63385.4, 0.963], [63685.0, 0.017], [64032.1, 4.699], [64355.5, 4.423], [64631.7, 0.065], [64632.5, 6.341], [64667.3, 0.451], [64676.5, 0.011], [64678.9, 5.07]], "asks": [[64682.2, 0.024], [64683.9, 0.005], [64684.5, 0.004], [64684.6, 0.052], [64684.7, 0.619], [64684.8, 2.346], [64691.0, 0.069], [64735.3, 0.063], [64736.0, 0.001], [64874.9, 4.99], [65002.4, 4.001], [65325.8, 5.167], [65487.5, 7.884]]}
{"kind": "depth", "E": 1787095190205, "U": 11316362256200, "u": 11316362264621, "recv_ms": 1787095190274, "bids": [[14178.9, 3.01], [14278.9, 1.19], [51743.0, 0.0], [51743.1, 0.002], [58211.0, 0.01], [61444.9, 0.0], [62091.7, 0.692], [63678.9, 1.173], [63683.7, 0.08], [63719.4, 0.549], [63741.1, 23.284], [64032.1, 4.699], [64161.5, 9.324], [64355.5, 4.268], [64534.5, 0.0], [64534.6, 4.046], [64678.9, 5.067]], "asks": [[64686.6, 0.254], [64693.6, 0.747], [64721.7, 0.182], [64819.2, 5.407], [64874.9, 7.778], [65325.8, 5.167], [65679.0, 0.342]]}
{"kind": "depth", "E": 1787095190307, "U": 11316362264627, "u": 11316362269915, "recv_ms": 1787095190376, "bids": [[1000.0, 35.76], [14178.9, 3.36], [14278.9, 0.84], [51743.0, 0.0], [51743.1, 0.0], [58211.0, 0.01], [61444.9, 0.0], [62091.7, 0.689], [63797.1, 1.565], [64032.1, 4.699], [64568.9, 0.003], [64657.6, 0.779], [64662.5, 0.004], [64665.0, 0.004], [64672.1, 0.039], [64672.6, 0.468], [64672.9, 1.555], [64675.1, 0.009], [64676.5, 0.011], [64678.9, 4.371]], "asks": [[64679.0, 27.978], [64687.5, 0.892], [64691.9, 1.187], [64693.6, 0.766], [64694.9, 0.002], [64695.0, 0.024], [64721.6, 1.619], [64721.7, 0.182], [64756.7, 0.049], [64766.4, 1.263], [65325.8, 5.167], [65477.7, 14.766]]}
{"kind": "depth", "E": 1787095190409, "U": 11316362270026, "u": 11316362279893, "recv_ms": 1787095190480, "bids": [[1000.0, 35.76], [14178.9, 3.682], [14278.9, 0.504], [14578.9, 0.014], [58211.0, 0.01], [61444.9, 0.0], [61445.0, 0.053], [62091.7, 0.692], [63644.0, 6.507], [63678.9, 1.153], [63836.3, 0.326], [63838.0, 4.752], [63870.4, 12.094], [64032.1, 4.699], [64355.5, 4.278], [64635.7, 0.201], [64640.9, 0.0], [64662.5, 0.006], [64670.0, 0.237], [64670.7, 0.018], [64670.8, 0.098], [64671.1, 0.087], [64671.4, 0.01], [64671.5, 1.748], [64671.6, 0.094], [64672.1, 0.036], [64672.2, 0.088], [64672.9, 1.555], [64673.0, 0.509], [64673.4, 0.011], [64674.5, 0.084], [64674.7, 0.0], [64675.0, 0.987], [64675.1, 0.009], [64675.4, 0.004], [64676.3, 0.0], [64678.9, 3.778]], "asks": [[64679.0, 27.961], [64679.5, 0.0], [64681.0, 0.012], [64683.9, 0.159], [64684.6, 0.06], [64687.1, 0.684], [64691.0, 0.679], [64691.9, 1.36], [64694.4, 0.363], [64695.0, 0.026], [64721.6, 1.619], [64721.7, 0.182], [64738.8, 0.077], [64746.9, 0.004], [64748.5, 0.001], [64771.2, 0.772], [64790.6, 0.102], [65002.4, 4.0], [65325.8, 5.167], [65679.0, 0.322], [65972.5, 0.012]]}
{"kind": "depth", "E": 1787095190511, "U": 11316362279915, "u": 11316362287814, "recv_ms": 1787095190580, "bids": [[14178.9, 3.738], [14278.9, 0.294], [14578.9, 0.168], [58211.0, 0.01], [61444.9, 0.0], [61445.1, 0.01], [62091.7, 0.689], [63644.0, 7.605], [63728.1, 3.762], [64032.1, 4.699], [64161.5, 9.634], [64355.5, 4.434], [64534.6, 0.0], [64561.1, 3.866], [64562.4, 1.89], [64563.5, 0.0], [64571.7, 4.846], [64574.0, 0.001], [64576.8, 0.0], [64576.9, 0.006], [64606.7, 0.073], [64607.7, 2.405], [64646.0, 0.762], [64646.1, 0.0], [64646.2, 0.007], [64649.4, 0.0], [64649.5, 0.04], [64649.6, 0.046], [64671.4, 0.01], [64672.2, 0.088], [64673.0, 0.509], [64674.5, 0.0], [64674.9, 2.324], [64676.5, 0.011], [64678.9, 3.756]], "asks": [[64679.0, 27.959], [64684.6, 0.06], [64685.5, 0.045], [64687.1, 0.761], [64690.3, 0.354], [64690.9, 0.012], [64691.0, 0.671], [64700.7, 1.628], [64721.6, 1.619], [64721.7, 0.182], [64749.1, 0.046], [64750.1, 0.003], [64787.7, 2.322], [64787.8, 2.999], [64813.3, 3.905], [64814.2, 0.0], [64814.3, 0.001], [64819.2, 0.007], [65325.8, 5.167], [65445.3, 15.261], [71146.9, 0.0]]}
{"kind": "depth", "E": 1787095190715, "U": 11316362294176, "u": 11316362302006, "recv_ms": 1787095190789, "bids": [[1000.0, 35.76], [14178.9, 3.5], [14278.9, 0.056], [14578.9, 0.644], [58211.0, 0.01], [61444.9, 0.0], [62091.7, 0.692], [63126.6, 0.839], [64032.1, 4.699], [64355.5, 4.424], [64478.7, 0.486], [64478.9, 13.851], [64517.5, 0.0], [64517.6, 0.0], [64517.7, 7.383], [64534.7, 4.443], [64536.6, 1.003], [64568.9, 0.0], [64633.6, 0.638], [64658.0, 0.622], [64665.4, 1.628], [64671.4, 0.009], [64672.1, 0.037], [64672.9, 1.555], [64673.0, 0.509], [64674.5, 0.084], [64676.5, 0.011], [64678.9, 3.753]], "asks": [[64680.4, 0.311], [64684.7, 0.619], [64687.9, 1.887], [64690.9, 0.004], [64691.0, 0.053], [64694.4, 0.981], [64695.3, 0.618], [64696.4, 4.02], [64700.4, 0.389], [64721.7, 0.182], [64721.8, 0.018], [64724.3, 0.004], [64756.7, 0.046], [64817.8, 1.887], [64819.2, 5.407], [64836.0, 0.861], [64836.1, 0.001], [64836.2, 10.443], [64874.9, 0.003], [64875.0, 5.15], [65196.4, 7.806], [65325.8, 5.167]]}
{"kind": "depth", "E": 1787095190817, "U": 11316362302112, "u": 11316362309106, "recv_ms": 1787095190892, "bids": [[14178.9, 3.262], [14278.9, 0.0], [14578.9, 0.938], [58211.0, 0.01], [62091.7, 0.689], [63634.5, 4.714], [63678.9, 1.153], [64096.9, 1.2], [64508.3, 0.104], [64509.1, 0.48], [64655.3, 1.928], [64669.4, 0.235], [64670.0, 0.005], [64670.8, 0.021], [64671.5, 1.749], [64671.6, 0.171], [64672.1, 0.036], [64672.2, 0.088], [64673.0, 0.088], [64675.1, 0.43], [64675.2, 0.171]], "asks": [[64680.4, 0.001], [64691.9, 1.341], [64700.7, 1.626], [64721.7, 0.182], [64875.0, 5.858], [65002.4, 3.999], [65300.0, 128.833], [65325.8, 5.167], [65679.0, 0.322]]}
{"kind": "depth", "E": 1787095190919, "U": 11316362309255, "u": 11316362315274, "recv_ms": 1787095190988, "bids": [[1000.0, 35.76], [14178.9, 2.898], [14578.9, 1.302], [58211.0, 0.01], [61444.9, 0.0], [62091.7, 0.692], [63535.3, 0.0], [63870.4, 12.328], [63902.8, 24.175], [64032.1, 4.699], [64096.8, 14.648], [64355.5, 4.425], [64508.3, 0.143], [64509.1, 0.441], [64671.5, 1.748], [64672.2, 0.089], [64673.0, 0.509], [64675.1, 0.009], [64676.5, 0.011], [64678.9, 3.753]], "asks": [[64683.9, 0.082], [64687.1, 0.684], [64693.6, 0.747], [64721.6, 1.619], [64721.7, 0.028], [64721.8, 0.172], [64738.8, 0.154], [65196.4, 7.192], [65325.8, 5.167], [65972.5, 0.009]]}
{"kind": "depth", "E": 1787095191225, "U": 11316362328336, "u": 11316362334342, "recv_ms": 1787095191295, "bids": [[1000.0, 35.76], [14178.9, 1.82], [14578.9, 2.38], [51743.1, 0.0], [58211.0, 0.01], [61444.9, 0.0], [61445.0, 0.051], [61445.1, 0.012], [62091.7, 0.692], [63678.9, 1.153], [64032.1, 4.699], [64116.2, 1.168], [64161.5, 9.324], [64355.5, 4.28], [64534.7, 0.398], [64534.8, 4.9], [64568.9, 0.003], [64614.2, 2.175], [64671.5, 1.748], [64671.6, 0.171], [64672.2, 0.089], [64672.9, 1.555], [64673.0, 0.088], [64673.1, 0.001], [64675.0, 0.987], [64675.1, 0.009], [64676.5, 0.011], [64677.7, 0.001], [64678.9, 3.75]], "asks": [[64679.0, 27.959], [64683.9, 0.005], [64687.1, 0.761], [64690.3, 0.277], [64691.9, 1.07], [64693.6, 0.67], [64717.8, 5.405], [64721.9, 5.71], [64722.0, 1.546], [64722.9, 0.005], [64723.6, 0.029], [64730.8, 0.254], [64733.9, 0.084], [64743.7, 0.008], [64756.7, 0.049], [64819.2, 5.407], [64875.0, 6.769], [65002.4, 3.845], [65196.4, 8.111], [65325.8, 5.167], [65584.5, 28.658], [65679.0, 0.322]]}
{"kind": "depth", "E": 1787095191327, "U": 11316362334399, "u": 11316362351378, "recv_ms": 1787095191398, "bids": [[14178.9, 1.47], [14578.9, 2.73], [58211.0, 0.01], [61444.9, 0.0], [62091.7, 0.689], [63902.8, 24.331], [64032.1, 4.699], [64271.2, 0.0], [64335.8, 7.965], [64355.5, 4.27], [64400.4, 0.009], [64401.7, 0.095], [64465.0, 1.019], [64466.4, 0.505], [64531.1, 0.131], [64665.4, 1.01], [64671.5, 1.749], [64672.2, 0.088], [64672.4, 0.008], [64672.9, 0.001], [64673.0, 0.088], [64673.1, 1.555], [64674.5, 0.0], [64675.0, 0.987], [64675.2, 0.087], [64677.9, 0.0], [64678.5, 0.041], [64678.9, 3.656]], "asks": [[64680.0, 0.316], [64685.5, 0.045], [64686.5, 0.241], [64686.6, 0.254], [64686.7, 0.245], [64721.9, 5.864], [64875.0, 11.515], [65325.8, 5.167], [65704.0, 0.0]]}
{"kind": "depth", "E": 1787095191429, "U": 11316362351664, "u": 11316362362884, "recv_ms": 1787095191503, "bids": [[14178.9, 1.12], [14578.9, 3.08], [58211.0, 0.01], [61444.9, 0.0], [62091.7, 0.692], [63385.4, 0.966], [63678.9, 1.173], [63902.8, 24.8], [64032.1, 4.699], [64337.0, 0.373], [64517.7, 0.005], [64517.8, 7.451], [64658.0, 0.004], [64662.5, 0.006], [64665.8, 3.461], [64666.9, 0.257], [64667.2, 1.638], [64667.4, 0.017], [64667.7, 0.051], [64668.5, 0.001], [64669.4, 0.003], [64670.4, 1.367], [64670.7, 0.179], [64671.1, 0.088], [64671.5, 1.748], [64671.6, 0.094], [64673.4, 0.095], [64673.5, 0.006], [64674.0, 0.003], [64674.6, 0.01], [64676.5, 0.011], [64677.7, 0.046], [64677.8, 0.045], [64678.1, 0.002], [64678.5, 0.0], [64678.9, 2.471]], "asks": [[64679.0, 27.959], [64679.3, 0.216], [64679.6, 0.082], [64683.6, 0.352], [64683.8, 0.045], [64684.6, 0.06], [64685.5, 0.045], [64686.5, 0.222], [64686.6, 0.253], [64686.7, 0.222], [64686.9, 0.158], [64687.0, 0.235], [64687.9, 1.269], [64690.7, 0.004], [64691.0, 0.061], [64693.6, 0.747], [64695.0, 0.026], [64695.3, 0.0], [64695.8, 0.002], [64721.8, 0.172], [64721.9, 5.71], [64875.0, 4.877], [65325.8, 5.167], [65350.0, 140.834], [65477.7, 14.538], [65679.0, 0.342]]}
{"kind": "depth", "E": 1787095191633, "U": 11316362372993, "u": 11316362382901, "recv_ms": 1787095191701, "bids": [[14178.9, 0.434], [14478.9, 0.042], [14578.9, 3.724], [34000.0, 1.146], [58211.0, 0.012], [61444.9, 0.0], [61445.1, 0.01], [62091.7, 0.689], [63385.4, 0.966], [63678.9, 1.153], [64032.1, 4.699], [64355.5, 4.424], [64358.3, 1.114], [64508.3, 0.104], [64509.1, 0.48], [64517.9, 2.713], [64534.8, 0.122], [64534.9, 5.351], [64536.6, 0.464], [64673.2, 1.441], [64675.1, 0.43], [64676.5, 0.011], [64678.9, 2.419]], "asks": [[64679.0, 27.919], [64683.4, 0.024], [64693.6, 0.747], [64721.8, 0.172], [64722.0, 1.546], [64817.7, 0.003], [64819.2, 5.407], [64875.0, 5.946], [65002.4, 4.0], [65325.8, 5.167], [65376.3, 1.988], [65570.3, 0.924], [65585.8, 1.827], [65679.0, 0.322]]}
{"kind": "depth", "E": 1787095191837, "U": 11316362391092, "u": 11316362399044, "recv_ms": 1787095191905, "bids": [[1000.0, 35.76], [14178.9, 0.154], [14478.9, 0.476], [14578.9, 3.57], [58211.0, 0.01], [61444.9, 0.001], [62091.7, 0.689], [63385.4, 0.963], [63678.9, 1.173], [63697.2, 0.808], [63786.3, 3.147], [63923.3, 0.092], [64032.1, 4.699], [64478.9, 0.0], [64479.1, 12.967], [64517.8, 0.013], [64517.9, 7.202], [64534.9, 3.508], [64670.4, 1.283], [64670.7, 0.018], [64672.6, 0.471], [64673.1, 0.001], [64674.6, 0.094], [64675.0, 2.929], [64675.3, 0.262], [64675.4, 0.004], [64677.3, 0.069], [64678.9, 3.603]], "asks": [[64679.0, 27.918], [64680.9, 0.007], [64681.0, 0.009], [64682.5, 0.012], [64684.6, 0.052], [64685.3, 0.061], [64685.6, 0.34], [64687.8, 0.095], [64691.0, 0.069], [64691.9, 0.96], [64693.6, 0.555], [64695.2, 0.132], [64819.2, 5.407], [65325.8, 5.167], [65477.7, 14.28], [65614.2, 0.019], [65679.0, 0.342]]}
{"kind": "depth", "E": 1787095191939, "U": 11316362399087, "u": 11316362404697, "recv_ms": 1787095192025, "bids": [[14178.9, 0.028], [14478.9, 0.7], [14578.9, 3.472], [58211.0, 0.01], [61444.9, 0.0], [62091.8, 1.452], [63805.7, 8.49], [63973.9, 4.288], [64032.1, 4.699], [64355.5, 4.423], [64479.1, 13.474], [64479.2, 6.408], [64517.9, 7.647], [64534.9, 5.178], [64568.9, 0.0], [64624.5, 0.018], [64633.6, 0.638], [64672.9, 1.547], [64673.2, 0.0], [64673.3, 0.01], [64675.0, 1.375], [64675.3, 0.57], [64676.5, 0.011], [64678.9, 3.602]], "asks": [[64693.6, 0.67], [64721.9, 5.71], [64722.0, 1.7], [64724.3, 0.004], [64756.7, 0.046], [64850.0, 27.363], [64875.0, 5.961], [64878.2, 0.335], [65325.8, 5.167], [65384.0, 3.729], [65487.5, 8.113], [65578.0, 9.833], [65591.0, 5.484], [66782.4, 0.135]]}
{"kind": "depth", "E": 1787095192041, "U": 11316362404796, "u": 11316362410129, "recv_ms": 1787095192111, "bids": [[14178.9, 0.0], [14478.9, 1.036], [14578.9, 3.164], [58211.0, 0.01], [62091.7, 0.692], [63678.9, 1.153], [63708.7, 4.149], [63913.5, 0.077], [64032.1, 4.699], [64311.0, 0.092], [64313.0, 0.802], [64407.6, 0.008], [64409.1, 0.729], [64478.5, 0.0], [64479.2, 0.524], [64624.5, 0.004], [64667.3, 0.456], [64675.3, 0.149], [64678.9, 3.602]], "asks": [[64721.9, 5.71], [64722.0, 1.546], [64874.1, 0.001], [64875.0, 5.345], [64945.4, 0.008], [65002.4, 4.001], [65042.8, 0.467], [65325.8, 5.167], [65477.7, 14.021], [65679.0, 0.322]]}
{"kind": "depth", "E": 1787095192143, "U": 11316362410176, "u": 11316362415307, "recv_ms": 1787095192212, "bids": [[1000.0, 35.76], [14478.9, 1.386], [14578.9, 2.814], [58211.0, 0.01], [61444.9, 0.0], [62091.7, 0.689], [63729.3, 0.094], [63935.1, 9.837], [64032.1, 4.699], [64624.5, 0.004], [64667.3, 0.451], [64675.3, 0.149], [64676.5, 0.011]], "asks": [[64685.8, 0.632], [64721.9, 5.71], [64722.1, 0.154], [64873.9, 1.636], [64944.9, 0.466], [65040.9, 0.659], [65623.3, 1.019]]}
{"kind": "depth", "E": 1787095192245, "U": 11316362415477, "u": 11316362424373, "recv_ms": 1787095192315, "bids": [[14478.9, 1.75], [14578.9, 2.45], [51743.1, 0.0], [58211.0, 0.01], [62091.7, 0.692], [63678.9, 1.173], [63828.5, 8.507], [63838.1, 1.72], [63838.2, 6.283], [63922.2, 2.195], [64032.1, 4.699], [64047.6, 0.002], [64195.2, 0.007], [64355.5, 4.433], [64579.0, 0.017], [64585.5, 0.0], [64596.0, 0.008], [64608.7, 0.788], [64624.5, 0.018], [64627.8, 0.385], [64631.4, 0.184], [64634.2, 0.07], [64647.5, 0.087], [64670.7, 0.095], [64671.6, 0.094], [64672.6, 0.468], [64675.1, 0.001], [64675.3, 0.486], [64675.4, 0.012]], "asks": [[64684.6, 0.06], [64691.0, 0.061], [64703.2, 0.006], [64719.4, 0.042], [64737.1, 53.424], [64739.3, 0.023], [64742.0, 0.005], [64864.3, 5.158], [64866.5, 30.125], [65159.9, 0.445], [65309.8, 0.005], [65325.8, 5.167], [65679.0, 0.342]]}
{"kind": "depth", "E": 1787095192347, "U": 11316362424466, "u": 11316362432624, "recv_ms": 1787095192423, "bids": [[14478.9, 2.1], [14578.9, 2.1], [51743.0, 0.0], [58211.0, 0.01], [61444.9, 0.0], [62091.7, 0.689], [64032.1, 4.699], [64568.9, 0.003], [64578.2, 0.0], [64578.4, 1.767], [64646.0, 1.811], [64646.1, 0.002], [64646.2, 0.009], [64649.4, 0.002], [64649.5, 0.042], [64649.6, 0.048], [64667.7, 0.051], [64668.3, 0.265], [64675.3, 0.065], [64676.5, 0.011], [64678.9, 3.605]], "asks": [[64684.6, 0.06], [64690.9, 0.004], [64691.9, 1.037], [64693.6, 0.747], [64736.7, 8.961], [64737.0, 0.004], [64737.5, 0.001], [64739.2, 1.748], [64756.7, 0.049], [64774.3, 0.033], [64798.7, 0.005], [65325.8, 5.167]]}
{"kind": "depth", "E": 1787095192449, "U": 11316362433145, "u": 11316362443821, "recv_ms": 1787095192518, "bids": [[1000.0, 35.76], [14478.9, 2.45], [14578.9, 1.75], [51743.0, 0.0], [58211.0, 0.01], [63509.7, 1.656], [63676.4, 15.999], [63678.9, 1.153], [63741.1, 24.381], [63796.2, 11.309], [64032.1, 4.699], [64610.4, 6.002], [64633.0, 3.503], [64649.2, 0.764], [64662.5, 0.006]], "asks": [[64695.0, 0.026], [64701.7, 0.552], [64717.9, 3.504], [64740.6, 6.002], [64787.3, 0.096], [65002.4, 3.386], [65325.8, 5.167], [65523.6, 0.0], [65679.0, 0.322]]}
{"kind": "depth", "E": 1787095192551, "U": 11316362444198, "u": 11316362451354, "recv_ms": 1787095192621, "bids": [[14478.9, 2.814], [14578.9, 1.386], [58211.0, 0.01], [61444.9, 0.0], [62091.7, 0.692], [63385.4, 0.96], [63678.9, 1.173], [64032.1, 4.699], [64355.5, 4.423], [64517.9, 0.414], [64518.0, 2.583], [64534.9, 0.243], [64630.7, 0.123], [64676.5, 0.011], [64678.9, 3.607]], "asks": [[64679.0, 27.942], [64787.3, 0.211], [64817.7, 0.424], [64819.2, 0.007], [64836.0, 2.309], [64836.2, 0.032], [65002.4, 3.385], [65325.8, 5.167], [65532.4, 0.001], [65547.0, 2.892], [65679.0, 0.342]]}
{"kind": "depth", "E": 1787095192653, "U": 11316362451414, "u": 11316362458018, "recv_ms": 1787095192722, "bids": [[1000.0, 35.76], [14478.9, 3.164], [14578.9, 1.036], [58211.0, 0.01], [61444.9, 0.0], [62091.7, 0.689], [63514.7, 3.21], [63676.4, 17.097], [63826.3, 0.069], [64032.1, 4.699], [64355.5, 4.424], [64518.0, 0.253], [64518.1, 7.373], [64535.1, 4.706], [64536.6, 1.101], [64576.4, 10.001], [64578.4, 3.033], [64675.3, 0.486], [64678.9, 3.604]], "asks": [[64679.0, 27.941], [64772.9, 10.022], [64819.2, 5.407], [64836.0, 0.861], [64836.2, 10.443], [64867.9, 0.009], [64868.0, 1.025], [64875.0, 5.351], [65002.4, 4.0], [65325.8, 5.167], [65519.9, 10.44], [65972.5, 0.012]]}
{"kind": "depth", "E": 1787095192755, "U": 11316362458126, "u": 11316362469165, "recv_ms": 1787095192824, "bids": [[1000.0, 35.76], [14478.9, 3.528], [14578.9, 0.672], [58211.0, 0.01], [61445.1, 0.008], [62091.7, 0.692], [63464.4, 0.0], [63787.8, 1.252], [63800.7, 4.963], [64032.1, 4.699], [64561.1, 3.866], [64606.7, 0.073], [64624.5, 0.018], [64637.1, 0.618], [64644.5, 0.621], [64650.2, 0.045], [64658.0, 0.004], [64665.4, 1.01], [64665.9, 1.586], [64668.5, 0.361], [64675.3, 0.073], [64675.4, 0.004], [64677.6, 0.043], [64677.7, 0.001], [64678.2, 0.0], [64678.9, 2.416]], "asks": [[64679.0, 27.941], [64680.9, 0.017], [64682.5, 0.003], [64683.8, 0.621], [64683.9, 0.082], [64685.8, 0.631], [64691.2, 0.156], [64691.9, 1.114], [64693.6, 0.766], [64723.6, 0.025], [64733.9, 0.088], [64738.8, 0.0], [64749.1, 0.046], [64813.3, 0.04], [64813.4, 3.865], [65325.8, 5.167], [65520.0, 2.832], [65552.2, 6.862], [65669.4, 0.0]]}
{"kind": "depth", "E": 1787095192857, "U": 11316362469326, "u": 11316362476562, "recv_ms": 1787095192926, "bids": [[14378.9, 0.07], [14478.9, 3.738], [14578.9, 0.392], [51743.0, 0.0], [58211.0, 0.01], [61444.9, 0.0], [61445.0, 0.049], [61445.1, 0.01], [62091.7, 0.689], [63678.9, 1.153], [63838.1, 4.066], [63902.8, 24.176], [64032.1, 4.699], [64355.5, 4.434], [64518.1, 0.0], [64518.2, 7.207], [64675.3, 0.073], [64676.5, 0.011], [64678.1, 0.032], [64678.2, 0.019], [64678.9, 2.419]], "asks": [[64680.6, 0.009], [64680.9, 0.01], [64683.9, 0.005], [64684.6, 0.052], [64687.1, 0.684], [64690.8, 0.325], [64691.9, 1.037], [64693.6, 0.555], [64721.0, 0.388], [64723.5, 0.693], [64733.9, 0.084], [64736.7, 1.267], [64737.0, 0.0], [64737.1, 0.007], [64737.5, 0.005], [64745.9, 55.97], [64875.0, 6.05], [65325.8, 5.167], [65679.0, 0.322], [65681.5, 10.643]]}
{"kind": "depth", "E": 1787095192959, "U": 11316362476894, "u": 11316362485952, "recv_ms": 1787095193028, "bids": [[1000.0, 35.76], [14378.9, 0.28], [14478.9, 3.682], [14578.9, 0.238], [58211.0, 0.01], [63385.4, 0.963], [63469.4, 4.01], [63805.7, 9.115], [63967.5, 0.236], [64032.1, 4.699], [64508.3, 0.104], [64509.1, 0.48], [64675.3, 0.073], [64677.7, 0.0]], "asks": [[64679.0, 27.951], [64684.6, 0.06], [64684.7, 0.619], [64690.8, 0.317], [64691.9, 1.03], [64745.3, 0.078], [65325.8, 5.167], [65422.9, 0.931]]}
{"kind": "depth", "E": 1787095193061, "U": 11316362486220, "u": 11316362493932, "recv_ms": 1787095193130, "bids": [[1000.0, 35.76], [14378.9, 0.518], [14478.9, 3.556], [14578.9, 0.126], [58211.0, 0.01], [61444.9, 0.0], [62091.7, 0.692], [63678.9, 1.173], [63902.8, 24.8], [64032.1, 4.699], [64355.5, 4.435], [64508.3, 0.143], [64509.1, 0.441], [64570.1, 2.32], [64571.5, 0.001], [64667.3, 0.451], [64676.2, 0.003], [64678.9, 2.416]], "asks": [[64683.9, 0.173], [64684.6, 0.052], [64687.1, 0.607], [64690.8, 0.325], [64691.9, 0.953], [64693.6, 0.394], [64700.8, 1.239], [64700.9, 0.108], [64739.3, 53.696], [64745.3, 0.232], [64745.9, 2.342], [64787.6, 2.319], [64787.7, 0.003], [65002.4, 3.999], [65325.8, 5.167], [65524.1, 2.286], [65679.0, 0.342]]}
{"kind": "depth", "E": 1787095193163, "U": 11316362493957, "u": 11316362501112, "recv_ms": 1787095193231, "bids": [[14378.9, 0.756], [14478.9, 3.444], [14578.9, 0.0], [51743.0, 0.0], [58202.3, 0.008], [58211.0, 0.01], [61444.9, 0.0], [62091.7, 0.689], [62091.8, 1.451], [63838.2, 5.188], [63967.4, 1.857], [64032.1, 4.699], [64307.6, 37.119], [64309.5, 6.359], [64355.5, 4.435], [64404.2, 30.71], [64406.2, 5.529], [64475.1, 24.454], [64606.0, 0.003]], "asks": [[64679.0, 27.955], [64683.9, 0.005], [64685.8, 0.632], [64738.8, 0.077], [64873.6, 23.585], [64944.9, 4.713], [64945.0, 31.608], [65040.9, 5.935], [65042.4, 35.923], [65325.8, 5.167], [65487.5, 8.341], [65521.5, 0.267]]}
{"kind": "depth", "E": 1787095193265, "U": 11316362501274, "u": 11316362508259, "recv_ms": 1787095193334, "bids": [[1000.0, 35.76], [14378.9, 1.106], [14478.9, 3.094], [51743.0, 0.0], [51743.1, 0.0], [58211.0, 0.01], [62091.7, 0.692], [63678.9, 1.153], [63719.4, 0.0], [63763.8, 24.014], [63893.2, 27.735], [64032.1, 4.701], [64100.1, 0.022], [64191.8, 48.984], [64300.1, 16.798], [64307.7, 0.864], [64568.9, 0.0], [64633.6, 0.638], [64675.0, 1.459]], "asks": [[64724.3, 0.004], [64756.7, 0.046], [65159.5, 46.029], [65309.4, 58.581], [65325.8, 5.167], [65679.0, 0.322], [66161.4, 3.027]]}
{"kind": "depth", "E": 1787095193367, "U": 11316362508290, "u": 11316362515196, "recv_ms": 1787095193436, "bids": [[1000.0, 35.76], [14378.9, 1.47], [14478.9, 2.73], [58211.0, 0.01], [63838.1, 5.161], [64032.1, 4.699], [64045.9, 59.18], [64644.6, 0.0], [64676.2, 0.003], [64678.2, 0.042]], "asks": [[65325.8, 5.167], [65443.1, 12.753], [65523.8, 0.0], [71146.9, 0.0]]}
{"kind": "depth", "E": 1787095193469, "U": 11316362515379, "u": 11316362521556, "recv_ms": 1787095193538, "bids": [[14378.9, 1.82], [14478.9, 2.38], [58211.0, 0.01], [61444.9, 0.0], [62091.7, 0.689], [63385.4, 0.96], [63678.9, 1.173], [63728.1, 4.311], [64032.1, 4.699], [64355.5, 4.425], [64479.1, 0.014], [64479.4, 13.455], [64508.3, 0.104], [64509.1, 0.48], [64518.2, 7.229], [64535.1, 0.004], [64535.2, 4.935], [64634.6, 0.233], [64637.1, 0.0], [64644.5, 0.003], [64662.5, 0.006], [64662.8, 0.134], [64666.9, 0.256], [64669.2, 0.532], [64675.3, 0.494], [64678.9, 2.418]], "asks": [[64683.8, 0.003], [64687.6, 2.323], [64691.9, 0.876], [64695.0, 0.026], [64738.8, 0.154], [64745.9, 2.381], [64746.0, 0.014], [64819.2, 0.007], [64819.3, 5.4], [64836.2, 10.443], [64875.0, 5.97], [65261.2, 5.041], [65325.8, 5.167], [65487.5, 8.599], [65679.0, 0.342]]}
{"kind": "depth", "E": 1787095193571, "U": 11316362521789, "u": 11316362527429, "recv_ms": 1787095193644, "bids": [[1000.0, 35.76], [14378.9, 2.184], [14478.9, 2.016], [51743.0, 0.0], [58211.0, 0.01], [61445.0, 0.051], [62091.7, 0.692], [63574.3, 5.369], [64032.1, 4.699], [64355.5, 4.424], [64475.3, 4.928], [64508.3, 0.143], [64509.1, 0.441], [64518.3, 2.367], [64614.5, 0.0], [64614.8, 0.004], [64615.1, 0.024], [64615.4, 0.0], [64615.7, 0.051], [64632.0, 1.552], [64632.3, 0.015], [64632.6, 0.009], [64632.9, 0.027], [64633.3, 0.004], [64633.4, 0.051], [64646.9, 0.001], [64647.0, 0.001], [64647.1, 0.002], [64647.2, 0.626], [64647.3, 0.014], [64647.4, 3.564], [64647.5, 0.017], [64647.6, 0.002], [64647.7, 0.019], [64647.8, 0.074], [64648.7, 0.003], [64649.1, 0.002], [64665.8, 3.321], [64665.9, 1.516], [64666.0, 0.754], [64666.1, 0.162], [64666.2, 0.256], [64666.3, 0.218], [64666.4, 0.015], [64666.5, 0.005], [64666.6, 0.797], [64666.7, 0.048], [64667.0, 2.462], [64667.2, 1.476], [64667.3, 0.419], [64667.7, 0.019], [64668.0, 0.243], [64668.3, 0.233], [64668.5, 0.393], [64671.1, 0.003], [64675.3, 0.578], [64676.2, 0.003], [64678.9, 2.418]], "asks": [[64679.0, 27.963], [64679.1, 1.402], [64684.6, 0.02], [64684.7, 0.036], [64684.9, 1.402], [64685.2, 0.01], [64685.5, 0.003], [64685.9, 0.041], [64686.0, 0.096], [64686.2, 0.118], [64686.3, 0.0], [64686.4, 0.136], [64686.5, 0.032], [64686.6, 0.003], [64686.7, 0.082], [64686.8, 1.004], [64686.9, 0.004], [64687.0, 0.165], [64687.1, 0.439], [64687.4, 0.623], [64702.1, 6.046], [64702.3, 1.059], [64702.4, 1.228], [64702.8, 0.001], [64703.1, 0.158], [64703.4, 2.326], [64703.8, 0.167], [64704.2, 0.142], [64704.9, 0.466], [64705.0, 0.002], [64705.2, 0.031], [64705.3, 0.104], [64705.4, 0.038], [64705.5, 0.007], [64705.6, 1.268], [64705.7, 0.001], [64705.8, 0.007], [64705.9, 0.07], [64706.0, 0.38], [64719.6, 0.028], [64719.8, 0.054], [64720.0, 0.557], [64720.3, 0.004], [64720.6, 0.028], [64720.9, 0.081], [64739.2, 9.999], [64745.5, 1.394], [64745.9, 2.342], [64829.1, 5.383], [64831.7, 0.0], [64871.9, 5.201], [65261.2, 4.811], [65325.8, 5.167], [65455.1, 25.095], [65530.6, 0.006]]}
{"kind": "depth", "E": 1787095193673, "U": 11316362527532, "u": 11316362533082, "recv_ms": 1787095193743, "bids": [[1000.0, 35.76], [14378.9, 2.534], [14478.9, 1.666], [51743.0, 0.0], [58211.0, 0.01], [61444.9, 0.0], [62091.7, 0.689], [63385.4, 0.957], [63678.9, 1.153], [64032.1, 4.699], [64249.8, 0.008], [64256.2, 0.014], [64623.5, 1.467], [64627.8, 0.31], [64629.9, 0.084], [64634.2, 0.066], [64658.7, 0.001], [64659.7, 0.117], [64666.2, 0.326], [64666.4, 0.085], [64666.5, 0.075], [64666.7, 0.248], [64666.9, 0.356], [64667.0, 2.532], [64667.1, 1.395], [64667.8, 0.237], [64668.3, 0.001], [64670.7, 0.018], [64671.6, 0.171], [64673.8, 0.086], [64674.6, 0.094], [64675.0, 1.375], [64675.1, 0.085], [64675.3, 0.494], [64678.9, 3.603]], "asks": [[64679.0, 27.964], [64680.0, 0.006], [64680.9, 0.002], [64682.3, 0.598], [64682.6, 0.009], [64686.1, 0.122], [64686.2, 0.209], [64686.3, 0.12], [64686.5, 0.292], [64686.7, 0.152], [64686.8, 1.074], [64687.0, 0.242], [64693.6, 0.394], [64703.6, 0.125], [64704.1, 0.16], [64705.0, 0.093], [64705.2, 0.151], [64705.4, 0.158], [64705.5, 0.077], [64705.7, 0.071], [64705.8, 0.084], [64711.0, 0.502], [64722.1, 0.154], [64723.5, 0.689], [64738.8, 0.231], [64740.3, 0.002], [64744.6, 0.204], [64745.5, 1.355], [65002.4, 4.0], [65261.1, 5.217], [65261.2, 5.881], [65264.3, 1.773], [65325.8, 5.167], [65515.4, 0.005], [65519.9, 11.507], [65521.9, 0.083], [65679.0, 0.322]]}
{"kind": "depth", "E": 1787095193775, "U": 11316362533092, "u": 11316362539207, "recv_ms": 1787095193844, "bids": [[14378.9, 2.898], [14478.9, 1.302], [51743.0, 0.0], [58211.0, 0.01], [61444.9, 0.0], [62091.7, 0.692], [63579.4, 7.838], [63678.9, 1.173], [63860.8, 13.645], [64032.1, 4.699], [64355.5, 4.424], [64568.9, 0.003], [64629.9, 0.08], [64632.5, 6.373], [64633.1, 0.033], [64640.7, 0.005], [64658.1, 1.848], [64665.5, 0.62], [64666.3, 0.288], [64666.5, 0.145], [64666.6, 0.897], [64667.5, 0.047], [64668.2, 0.037], [64672.4, 0.011], [64675.3, 0.073], [64676.2, 0.003]], "asks": [[64679.0, 27.964], [64684.7, 0.654], [64685.1, 0.042], [64685.7, 0.045], [64686.6, 0.153], [64686.7, 0.236], [64686.9, 0.095], [64687.4, 0.005], [64688.0, 3.043], [64695.4, 1.095], [64702.6, 0.042], [64703.2, 0.048], [64705.5, 0.227], [64705.6, 1.352], [64705.8, 0.175], [64720.1, 3.288], [64720.8, 0.044], [64728.7, 0.004], [64735.2, 1.079], [64744.6, 0.165], [64746.0, 0.053], [64756.7, 0.049], [64875.0, 0.353], [64875.1, 5.514], [65261.1, 5.447], [65325.8, 5.167], [65376.3, 1.301], [65487.5, 8.858], [65515.4, 0.001], [65521.9, 0.005], [65679.0, 0.342]]}
{"kind": "depth", "E": 1787095193877, "U": 11316362539264, "u": 11316362544245, "recv_ms": 1787095193946, "bids": [[1000.0, 35.76], [14378.9, 3.248], [14478.9, 0.952], [58211.0, 0.01], [61444.9, 0.0], [64032.1, 4.699], [64307.6, 0.001], [64309.5, 0.939], [64404.2, 0.007], [64406.2, 1.102], [64475.1, 0.0], [64475.3, 1.453], [64615.9, 1.992], [64632.8, 0.032], [64633.8, 0.05], [64666.6, 0.898], [64667.0, 2.632], [64667.8, 0.037], [64668.5, 0.625], [64668.8, 0.068], [64673.3, 0.002], [64675.1, 0.093], [64675.3, 0.073], [64678.9, 3.698]], "asks": [[64684.4, 0.035], [64685.4, 0.484], [64686.2, 0.329], [64687.3, 0.411], [64688.0, 2.425], [64701.9, 0.04], [64702.9, 1.11], [64705.1, 0.131], [64719.5, 0.051], [64720.4, 2.571], [64745.9, 2.381], [64746.0, 0.014], [64871.9, 1.873], [64873.6, 0.001], [64944.9, 0.466], [64945.0, 2.457], [65040.9, 0.659], [65042.4, 0.005], [65325.8, 5.167], [65520.0, 3.899]]}
{"kind": "depth", "E": 1787095193979, "U": 11316362544526, "u": 11316362550961, "recv_ms": 1787095194048, "bids": [[1000.0, 35.76], [14378.9, 3.612], [14478.9, 0.588], [58211.0, 0.01], [61444.9, 0.0], [62091.7, 0.689], [63860.8, 13.411], [64032.1, 4.7], [64479.4, 0.0], [64479.6, 4.655], [64508.3, 0.104], [64509.1, 0.48], [64518.2, 0.0], [64518.4, 2.59], [64535.2, 0.0], [64535.3, 2.223], [64536.6, 0.464], [64646.0, 1.809], [64646.1, 0.0], [64646.2, 0.007], [64648.3, 0.078], [64649.4, 0.0], [64649.5, 0.04], [64649.6, 0.046], [64666.5, 0.215], [64666.8, 0.102], [64666.9, 0.426], [64673.0, 0.096], [64675.1, 0.085], [64675.3, 0.073], [64676.2, 0.003], [64678.9, 3.698]], "asks": [[64686.3, 0.19], [64686.4, 0.266], [64686.8, 1.144], [64705.2, 0.221], [64705.3, 0.234], [64705.6, 1.422], [64745.9, 2.342], [64746.0, 0.053], [64819.3, 5.4], [65159.5, 0.001], [65309.4, 0.015], [65325.8, 5.167], [65384.0, 4.415], [65585.8, 0.913]]}
{"kind": "depth", "E": 1787095194081, "U": 11316362551061, "u": 11316362557996, "recv_ms": 1787095194150, "bids": [[14278.9, 0.098], [14378.9, 3.766], [14478.9, 0.336], [58211.0, 0.01], [61445.1, 0.008], [62091.7, 0.692], [63678.9, 1.153], [63838.1, 5.278], [63893.2, 26.798], [64032.1, 4.7], [64045.9, 0.0], [64191.8, 0.0], [64355.5, 4.433], [64479.6, 13.185], [64508.3, 0.143], [64509.1, 0.441], [64518.3, 0.0], [64518.4, 6.542], [64535.3, 4.615], [64596.0, 0.007], [64614.9, 0.032], [64615.3, 0.034], [64615.6, 0.038], [64647.3, 0.084], [64647.5, 0.087], [64647.7, 0.089], [64647.8, 0.174], [64648.0, 1.687], [64648.2, 0.072], [64649.1, 0.102], [64649.6, 0.146], [64667.3, 0.419], [64675.3, 0.073]], "asks": [[64744.4, 0.039], [64746.0, 0.014], [64875.1, 6.879], [65267.6, 0.005], [65679.0, 0.322], [65766.9, 1.214]]}
{"kind": "depth", "E": 1787095194183, "U": 11316362558128, "u": 11316362563941, "recv_ms": 1787095194252, "bids": [[1000.0, 35.76], [14278.9, 0.336], [14378.9, 3.654], [14478.9, 0.21], [58211.0, 0.01], [62091.7, 0.689], [63805.7, 9.349], [64032.1, 4.7], [64095.6, 0.013], [64307.7, 0.0], [64310.0, 37.914], [64310.1, 0.864], [64406.6, 29.269], [64477.6, 23.712], [64508.3, 0.104], [64509.1, 0.48], [64596.0, 0.006], [64616.2, 2.353], [64619.5, 0.349], [64624.8, 0.006], [64635.2, 1.027], [64647.4, 3.634], [64647.6, 0.072], [64647.7, 0.189], [64666.6, 0.897], [64675.3, 0.494], [64676.2, 0.003]], "asks": [[64687.3, 0.41], [64744.4, 0.0], [64746.0, 0.053], [64873.6, 24.262], [64945.0, 32.135], [65002.4, 4.001], [65042.4, 37.657], [65325.8, 5.167]]}
{"kind": "depth", "E": 1787095194285, "U": 11316362564156, "u": 11316362569308, "recv_ms": 1787095194354, "bids": [[1000.0, 35.76], [14278.9, 0.574], [14378.9, 3.528], [14478.9, 0.098], [51743.0, 0.0], [51743.1, 0.0], [58211.0, 0.01], [61444.9, 0.0], [61445.1, 0.006], [62091.7, 0.692], [63678.9, 1.173], [64032.1, 4.7], [64508.3, 0.143], [64509.1, 0.441], [64535.3, 0.011], [64535.4, 3.948], [64627.1, 0.1], [64645.2, 0.078], [64648.1, 0.109], [64671.5, 1.664], [64672.9, 1.66], [64675.3, 0.494], [64676.0, 0.086]], "asks": [[64679.0, 27.934], [64695.2, 0.132], [64733.4, 0.009], [64735.0, 0.179], [64735.2, 1.109], [64819.3, 5.4], [64875.1, 8.574], [65261.2, 6.951], [65325.8, 5.167], [65375.1, 2.064], [65679.0, 0.342]]}
{"kind": "depth", "E": 1787095194387, "U": 11316362569459, "u": 11316362574750, "recv_ms": 1787095194456, "bids": [[14278.9, 0.84], [14378.9, 3.36], [14478.9, 0.0], [58211.0, 0.01], [63902.8, 25.738], [64032.1, 4.7], [64193.5, 47.295], [64355.5, 4.433], [64535.4, 0.005], [64647.6, 0.142], [64647.9, 0.411], [64648.0, 1.757], [64665.9, 1.517], [64672.9, 1.547], [64675.3, 0.494], [64676.2, 0.003]], "asks": [[64686.6, 0.154], [64819.3, 0.0], [65527.3, 0.0]]}
{"kind": "depth", "E": 1787095194489, "U": 11316362574902, "u": 11316362581419, "recv_ms": 1787095194558, "bids": [[1000.0, 35.76], [14278.9, 1.204], [14378.9, 2.996], [58211.0, 0.01], [61444.9, 0.0], [62091.7, 0.689], [63678.9, 1.153], [63792.8, 2.501], [64032.1, 4.7], [64096.8, 15.738], [64508.3, 0.104], [64509.1, 0.48], [64518.4, 6.178], [64535.4, 3.948], [64568.9, 0.0], [64633.6, 0.638], [64662.5, 0.006], [64673.0, 0.096], [64675.1, 0.085], [64675.3, 0.073], [64678.9, 3.698]], "asks": [[64695.0, 0.026], [64724.3, 0.001], [64756.7, 0.046], [64776.1, 0.049], [64789.0, 0.002], [64819.3, 5.4], [64836.2, 0.032], [64836.3, 10.412], [64875.1, 5.009], [65325.8, 5.167], [65384.0, 5.101], [65679.0, 0.322], [65972.5, 0.015]]}
{"kind": "depth", "E": 1787095194591, "U": 11316362581488, "u": 11316362587975, "recv_ms": 1787095194660, "bids": [[1000.0, 35.76], [14278.9, 1.554], [14378.9, 2.646], [58211.0, 0.01], [61444.9, 0.0], [62091.7, 0.692], [64032.1, 4.7], [64161.5, 8.7], [64309.5, 0.005], [64310.1, 7.474], [64355.5, 3.812], [64409.1, 5.062], [64479.7, 5.946], [64508.3, 0.143], [64509.1, 0.441], [64516.9, 1.152], [64536.6, 0.988], [64662.8, 0.119], [64669.9, 0.393], [64673.0, 0.096], [64675.1, 0.085], [64675.3, 0.073]], "asks": [[64679.0, 27.935], [64693.6, 0.317], [64735.0, 0.209], [64735.2, 1.079], [64836.0, 2.309], [64871.9, 5.302], [64944.9, 4.792], [65002.4, 4.0], [65040.9, 6.194], [65325.8, 5.167], [65520.0, 4.965], [65972.5, 0.015]]}
{"kind": "depth", "E": 1787095194795, "U": 11316362594259, "u": 11316362599533, "recv_ms": 1787095194865, "bids": [[1000.0, 35.76], [14278.9, 2.268], [14378.9, 1.932], [58211.0, 0.01], [61445.0, 0.053], [64032.1, 4.7], [64161.5, 9.634], [64355.5, 4.434], [64498.4, 0.043], [64498.5, 0.573], [64507.8, 3.669], [64572.1, 0.0], [64630.8, 0.006], [64640.0, 3.697], [64675.3, 0.073]], "asks": [[64808.4, 0.003], [65325.8, 5.167]]}
{"kind": "depth", "E": 1787095194999, "U": 11316362604373, "u": 11316362608394, "recv_ms": 1787095195079, "bids": [[14278.9, 2.982], [14378.9, 1.218], [58211.0, 0.01], [61444.9, 0.0], [62091.7, 0.689], [63800.0, 32.256], [63902.8, 25.738], [64032.1, 4.699], [64479.6, 0.0], [64479.7, 4.651], [64508.3, 0.104], [64509.1, 0.48], [64518.5, 2.611], [64535.4, 0.005], [64535.5, 2.213], [64617.4, 0.015], [64673.0, 0.517], [64675.1, 0.085], [64676.2, 0.003], [64678.9, 3.698]], "asks": [[64684.6, 0.036], [64687.9, 1.887], [64690.8, 0.317], [64691.0, 0.053], [64695.2, 0.077], [64742.2, 0.056], [64819.3, 5.4], [65325.8, 5.167], [65615.1, 0.0], [66166.6, 0.679]]}
{"kind": "depth", "E": 1787095195203, "U": 11316362614844, "u": 11316362620245, "recv_ms": 1787095195272, "bids": [[1000.0, 35.76], [14278.9, 3.696], [14378.9, 0.504], [58211.0, 0.01], [61444.9, 0.0], [62091.7, 0.689], [64032.1, 4.699], [64355.5, 4.434], [64535.5, 0.001], [64536.6, 0.464], [64624.5, 0.032], [64675.3, 0.494], [64676.0, 0.002], [64676.2, 0.003]], "asks": [[64679.0, 27.935], [64683.7, 0.004], [64685.8, 0.631], [64695.2, 0.132], [64819.3, 0.0], [65002.4, 3.999], [65268.4, 0.041], [65325.8, 5.167], [65447.4, 0.001], [65616.8, 23.058]]}
{"kind": "depth", "E": 1787095195305, "U": 11316362620377, "u": 11316362625846, "recv_ms": 1787095195374, "bids": [[14178.9, 0.154], [14278.9, 3.738], [14378.9, 0.308], [51743.0, 0.0], [51743.1, 0.0], [58211.0, 0.01], [61444.9, 0.0], [63621.4, 4.246], [63678.9, 1.153], [64032.1, 4.699], [64355.5, 4.435], [64518.5, 0.029], [64624.5, 0.032], [64675.3, 0.494], [64677.0, 0.9], [64677.6, 0.001], [64677.8, 0.083], [64678.0, 0.115], [64678.9, 3.699]], "asks": [[64836.0, 0.861], [64836.3, 0.001], [65270.6, 0.0], [65325.8, 5.167], [65525.6, 0.03], [65679.0, 0.322]]}
{"kind": "depth", "E": 1787095195407, "U": 11316362626055, "u": 11316362633137, "recv_ms": 1787095195476, "bids": [[1000.0, 35.76], [14178.9, 0.392], [14278.9, 3.626], [14378.9, 0.182], [51743.0, 0.0], [58211.0, 0.01], [61444.9, 0.0], [62091.7, 0.692], [63642.5, 0.0], [63749.6, 3.117], [63870.4, 12.561], [64032.1, 4.699], [64479.7, 0.002], [64479.8, 13.393], [64518.6, 6.616], [64535.5, 4.605], [64624.5, 0.032], [64675.3, 0.494], [64675.5, 0.002], [64676.5, 0.011], [64678.9, 3.701]], "asks": [[64679.0, 27.937], [64684.6, 0.02], [64685.3, 0.042], [64685.6, 0.317], [64691.0, 0.069], [64819.3, 5.4], [64836.3, 10.412], [64873.9, 0.005], [64875.1, 6.617], [65261.3, 3.252], [65325.8, 5.167], [65390.5, 2.515], [65390.6, 6.665], [65423.4, 8.172], [65443.1, 11.228], [65519.9, 12.573], [65524.7, 0.0]]}
{"kind": "depth", "E": 1787095195509, "U": 11316362633238, "u": 11316362639379, "recv_ms": 1787095195577, "bids": [[1000.0, 35.76], [14178.9, 0.63], [14278.9, 3.5], [14378.9, 0.07], [58211.0, 0.01], [62091.7, 0.689], [63678.9, 1.173], [64032.1, 4.699], [64161.5, 9.634], [64355.5, 4.435], [64570.1, 0.001], [64571.4, 2.32], [64624.5, 0.004], [64662.5, 0.006], [64669.3, 2.794], [64673.0, 0.096], [64675.1, 0.085], [64675.3, 0.073], [64678.9, 3.701]], "asks": [[64679.0, 27.96], [64683.7, 0.003], [64684.6, 0.036], [64685.3, 0.198], [64686.3, 0.209], [64686.4, 0.289], [64691.0, 0.053], [64693.6, 0.394], [64695.0, 0.026], [64787.5, 4.664], [64787.6, 0.0], [65261.3, 4.323], [65325.8, 5.167], [65455.1, 29.213], [65679.0, 0.342]]}
{"kind": "depth", "E": 1787095195611, "U": 11316362639490, "u": 11316362645912, "recv_ms": 1787095195680, "bids": [[14178.9, 0.924], [14278.9, 3.276], [14378.9, 0.0], [58211.0, 0.01], [61444.9, 0.0], [62091.7, 0.692], [63741.1, 23.284], [63860.8, 13.06], [63893.2, 26.579], [64032.1, 4.699], [64479.9, 5.977], [64536.6, 1.086], [64624.5, 0.004], [64658.9, 0.388], [64659.7, 0.001], [64659.9, 0.367], [64661.4, 0.0], [64662.5, 0.563], [64675.3, 0.073]], "asks": [[64702.3, 0.503], [64702.8, 0.557], [64730.8, 0.263], [64733.4, 0.0], [64836.0, 2.309], [64850.0, 27.467], [64875.0, 1.727], [65325.8, 5.167], [65390.5, 2.744], [65423.5, 6.411], [65455.1, 30.738]]}
{"kind": "depth", "E": 1787095195713, "U": 11316362645963, "u": 11316362651681, "recv_ms": 1787095195781, "bids": [[1000.0, 35.76], [14178.9, 1.274], [14278.9, 2.926], [58211.0, 0.01], [61444.9, 0.0], [61445.1, 0.004], [62091.7, 0.689], [63644.0, 9.142], [63678.9, 1.153], [63891.0, 11.203], [64032.1, 4.699], [64100.1, 4.342], [64300.1, 13.342], [64310.0, 1.037], [64310.1, 1.106], [64355.5, 4.434], [64406.6, 0.006], [64409.1, 0.729], [64477.6, 0.01], [64479.9, 0.001], [64624.5, 0.004], [64668.5, 0.393], [64668.9, 0.235], [64672.9, 1.547], [64673.0, 0.096], [64675.1, 0.085], [64675.3, 0.073], [64676.5, 0.011]], "asks": [[64679.0, 27.959], [64871.9, 1.873], [64873.6, 0.001], [64944.9, 0.466], [64945.0, 2.457], [65040.9, 0.659], [65042.4, 0.005], [65325.8, 5.167], [65519.9, 13.639], [65679.0, 0.322], [71146.9, 0.0]]}
{"kind": "depth", "E": 1787095195815, "U": 11316362651770, "u": 11316362658909, "recv_ms": 1787095195883, "bids": [[1000.0, 35.76], [14178.9, 1.638], [14278.9, 2.562], [51743.0, 0.0], [58211.0, 0.01], [61445.0, 0.053], [61445.1, 0.006], [63761.7, 3.133], [63814.2, 2.421], [63870.4, 12.795], [64032.1, 4.699], [64047.5, 0.0], [64193.5, 0.0], [64355.5, 4.424], [64623.9, 1.639], [64624.5, 0.004], [64633.6, 0.635], [64667.0, 1.732], [64667.4, 0.009], [64668.0, 1.143], [64669.4, 0.011], [64672.9, 1.547], [64673.0, 0.088], [64675.1, 0.093], [64675.3, 0.073]], "asks": [[64724.3, 0.004], [65002.4, 4.0], [65159.5, 0.001], [65309.4, 0.015], [65325.8, 5.167], [65591.0, 6.398], [65772.1, 1.976], [65972.5, 0.018]]}
{"kind": "depth", "E": 1787095196019, "U": 11316362667269, "u": 11316362672832, "recv_ms": 1787095196090, "bids": [[1000.0, 35.76], [14178.9, 2.352], [14278.9, 1.848], [58211.0, 0.01], [58343.5, 0.0], [61444.9, 0.0], [62091.7, 0.689], [63720.6, 0.552], [63800.7, 4.181], [64032.1, 4.699], [64479.8, 13.073], [64518.6, 0.013], [64518.7, 7.45], [64535.5, 0.001], [64535.6, 4.79], [64576.9, 0.003], [64577.0, 0.029], [64578.1, 0.001], [64620.8, 3.77], [64624.5, 0.018], [64640.7, 0.001], [64669.2, 0.532], [64672.9, 1.66], [64675.3, 0.494], [64676.5, 0.011]], "asks": [[64679.0, 27.922], [64695.2, 0.109], [64733.4, 0.009], [64735.0, 0.179], [64735.2, 1.109], [64819.3, 5.4], [64836.3, 10.412], [64875.1, 6.86], [65159.5, 45.29], [65309.4, 59.539], [65325.8, 5.167], [65584.5, 27.897], [65972.5, 0.015]]}
{"kind": "depth", "E": 1787095196121, "U": 11316362672858, "u": 11316362679257, "recv_ms": 1787095196192, "bids": [[1000.0, 35.76], [14178.9, 2.702], [14278.9, 1.498], [51743.0, 0.002], [58211.0, 0.01], [62091.7, 0.692], [63375.8, 3.79], [63447.7, 0.001], [63519.5, 2.125], [63591.4, 0.0], [63600.1, 0.024], [63663.2, 0.027], [63678.9, 1.153], [63735.1, 0.0], [63773.4, 20.136], [63805.7, 10.13], [63806.9, 0.01], [63878.8, 0.782], [63950.7, 0.007], [64022.5, 2.762], [64032.1, 4.699], [64100.1, 0.022], [64300.1, 16.798], [64310.1, 1.97], [64355.5, 4.434], [64578.1, 0.006], [64588.7, 0.004], [64596.0, 0.003], [64606.1, 0.002], [64620.8, 3.766], [64624.5, 0.004], [64624.8, 0.004], [64630.2, 0.005], [64633.9, 0.001], [64640.6, 0.416], [64662.1, 0.558], [64662.5, 0.006], [64667.3, 0.419], [64669.2, 0.527], [64672.9, 1.547], [64673.0, 0.088], [64675.1, 0.093], [64675.3, 0.073], [64678.9, 3.701]], "asks": [[64679.0, 27.918], [64684.7, 0.655], [64695.2, 0.132], [65315.9, 0.339], [65325.8, 5.169], [65387.7, 0.0], [65393.6, 0.004], [65445.3, 15.047], [65459.6, 0.007], [65531.5, 6.057], [65587.6, 2.298], [65603.3, 0.004], [65675.2, 0.0], [65679.0, 0.322], [65747.0, 0.027], [65818.9, 0.0], [65890.7, 0.0], [65962.6, 0.0]]}
{"kind": "depth", "E": 1787095196223, "U": 11316362679334, "u": 11316362689852, "recv_ms": 1787095196295, "bids": [[14178.9, 3.066], [14278.9, 1.134], [51743.0, 0.0], [58211.0, 0.01], [61444.9, 0.0], [64032.1, 4.699], [64193.5, 47.132], [64535.6, 4.79], [64539.8, 0.001], [64624.5, 0.032], [64633.6, 0.638], [64646.0, 1.811], [64646.1, 0.002], [64646.2, 0.009], [64649.4, 0.002], [64649.5, 0.042], [64649.6, 0.148], [64672.6, 0.468], [64672.9, 1.547], [64675.3, 0.494]], "asks": [[64679.0, 27.921], [64756.7, 0.049], [64819.3, 5.4], [64835.2, 0.0], [64873.1, 0.004], [64875.1, 6.79], [65249.4, 0.017], [65325.8, 5.167], [65565.1, 0.61], [67072.1, 0.013]]}
{"kind": "depth", "E": 1787095196325, "U": 11316362690379, "u": 11316362697950, "recv_ms": 1787095196393, "bids": [[1000.0, 35.76], [14178.9, 3.416], [14278.9, 0.784], [51743.0, 0.0], [51743.1, 0.0], [58211.0, 0.01], [61444.9, 0.0], [62091.7, 0.689], [63678.9, 1.173], [63728.1, 4.86], [64032.1, 4.699], [64355.5, 4.433], [64508.3, 0.104], [64509.1, 0.48], [64614.2, 2.176], [64624.5, 0.004], [64645.2, 0.12], [64673.0, 0.096], [64675.1, 0.001], [64675.3, 0.073], [64676.5, 0.011], [64678.9, 3.692]], "asks": [[64679.0, 27.921], [64730.8, 0.254], [64733.4, 0.0], [64735.0, 0.209], [64735.2, 1.079], [64743.7, 0.009], [65325.8, 5.167], [65679.0, 0.342]]}
{"kind": "depth", "E": 1787095196631, "U": 11316362710836, "u": 11316362716614, "recv_ms": 1787095196702, "bids": [[1000.0, 35.76], [14178.9, 3.598], [14278.9, 0.154], [14578.9, 0.448], [58211.0, 0.01], [61444.9, 0.0], [62091.7, 0.706], [63678.9, 1.173], [63708.4, 0.0], [63805.7, 10.474], [63902.8, 26.27], [63992.3, 2.313], [64032.1, 4.699], [64046.6, 59.061], [64479.9, 6.028], [64517.2, 0.081], [64521.2, 3.181], [64535.6, 0.0], [64657.6, 0.776], [64662.5, 0.006], [64675.3, 0.494], [64678.9, 3.692]], "asks": [[64679.0, 27.961], [64695.0, 0.026], [64701.8, 0.732], [64789.0, 0.005], [64819.3, 0.0], [64840.7, 0.004], [64871.9, 5.23], [65264.3, 0.702], [65325.8, 5.169], [65477.7, 13.564], [65679.0, 0.342]]}
{"kind": "depth", "E": 1787095196733, "U": 11316362716667, "u": 11316362722200, "recv_ms": 1787095196802, "bids": [[14178.9, 3.458], [14278.9, 0.042], [14578.9, 0.7], [58211.0, 0.01], [61444.9, 0.0], [64032.1, 4.699], [64355.5, 4.423], [64535.7, 4.791], [64578.1, 0.001], [64669.2, 0.532], [64675.3, 0.073]], "asks": [[64679.0, 27.961], [64819.3, 5.4], [64875.1, 6.514], [65325.8, 5.167]]}
{"kind": "depth", "E": 1787095196835, "U": 11316362722298, "u": 11316362728020, "recv_ms": 1787095196903, "bids": [[14178.9, 3.192], [14278.9, 0.0], [14578.9, 1.008], [58211.0, 0.01], [62091.7, 0.703], [63385.4, 0.951], [63860.8, 12.795], [64032.1, 4.699], [64674.9, 2.408], [64675.3, 0.073]], "asks": [[65002.4, 4.0], [65261.2, 8.022], [65325.8, 5.167], [65482.3, 2.135], [65574.7, 17.427], [65778.5, 4.957]]}
{"kind": "depth", "E": 1787095196937, "U": 11316362728133, "u": 11316362732974, "recv_ms": 1787095197007, "bids": [[1000.0, 35.76], [14178.9, 2.842], [14578.9, 1.358], [58211.0, 0.01], [61444.9, 0.0], [61445.0, 0.055], [62091.7, 0.706], [63385.4, 0.954], [63678.9, 1.153], [63707.2, 0.278], [63838.2, 4.875], [63902.8, 27.519], [63999.8, 4.972], [64032.1, 4.699], [64355.5, 4.424], [64535.7, 0.001], [64536.6, 0.464], [64672.4, 0.008], [64675.3, 0.494], [64675.4, 0.004], [64676.5, 0.011], [64678.9, 3.672]], "asks": [[64679.0, 27.961], [64684.7, 0.654], [64819.3, 0.0], [65325.8, 5.167], [65487.5, 9.086], [65679.0, 0.322]]}
{"kind": "depth", "E": 1787095197141, "U": 11316362737886, "u": 11316362742757, "recv_ms": 1787095197212, "bids": [[14178.9, 2.128], [14578.9, 2.072], [51743.0, 0.0], [58211.0, 0.01], [61444.9, 0.0], [62091.7, 0.706], [63052.5, 0.397], [63678.9, 1.173], [63720.6, 0.003], [63838.1, 5.591], [64032.1, 4.699], [64535.8, 0.0], [64588.7, 0.002], [64596.0, 0.001], [64598.9, 0.002], [64606.1, 0.003], [64624.8, 0.001], [64635.3, 0.032], [64667.3, 0.419], [64675.3, 0.073], [64676.5, 0.011], [64678.1, 0.002], [64678.2, 0.052], [64678.9, 3.672]], "asks": [[64679.0, 27.964], [64685.1, 0.043], [64819.4, 1.256], [65325.8, 5.169], [65448.7, 8.251], [65487.5, 9.2], [65679.0, 0.342]]}
{"kind": "depth", "E": 1787095197243, "U": 11316362742769, "u": 11316362758420, "recv_ms": 1787095197313, "bids": [[1000.0, 35.76], [14178.9, 1.764], [14578.9, 2.436], [58211.0, 0.01], [61444.9, 0.001], [63057.0, 0.638], [63061.9, 2.854], [63385.4, 0.951], [64032.1, 4.699], [64508.3, 0.104], [64509.1, 0.48], [64535.8, 4.802], [64670.7, 0.095], [64671.5, 1.748], [64671.6, 0.094], [64674.6, 0.01], [64674.7, 0.0], [64674.9, 2.324], [64675.3, 0.073], [64678.2, 0.072]], "asks": [[64679.0, 27.964], [64680.0, 0.316], [64681.5, 0.089], [64691.9, 0.799], [64693.6, 0.394], [64701.8, 1.288], [64702.8, 0.001], [64819.4, 6.656], [64875.2, 11.174], [65325.8, 5.167]]}
{"kind": "depth", "E": 1787095197345, "U": 11316362759809, "u": 11316362773361, "recv_ms": 1787095197415, "bids": [[14178.9, 1.414], [14578.9, 2.786], [51743.1, 0.0], [58211.0, 0.01], [61444.9, 0.0], [61445.0, 0.057], [62091.7, 0.703], [63375.8, 3.848], [63447.7, 0.059], [63519.5, 2.183], [63591.4, 0.058], [63663.2, 0.085], [63678.9, 1.153], [63728.1, 5.409], [63735.1, 0.058], [63806.9, 0.068], [63870.4, 13.146], [63878.8, 0.84], [63950.7, 0.065], [64022.5, 2.82], [64032.1, 4.699], [64355.5, 4.425], [64518.7, 0.963], [64518.8, 9.46], [64659.0, 0.006], [64659.7, 0.117], [64660.6, 0.027], [64661.4, 0.0], [64662.5, 0.563], [64665.3, 0.252], [64666.3, 0.747], [64667.3, 0.419], [64670.7, 0.179], [64671.1, 0.087], [64671.6, 0.094], [64672.4, 0.008], [64673.0, 0.096], [64673.8, 0.002], [64674.2, 0.01], [64675.3, 0.073], [64676.5, 0.011]], "asks": [[64698.7, 0.082], [64699.7, 0.459], [64701.8, 0.732], [64702.5, 0.0], [64702.8, 0.001], [64703.4, 2.441], [64703.5, 1.189], [64875.2, 5.679], [65002.4, 3.999], [65315.9, 0.397], [65325.8, 5.167], [65387.7, 0.058], [65455.2, 1.158], [65459.6, 0.065], [65531.5, 6.115], [65603.3, 0.062], [65675.2, 0.058], [65679.0, 0.322]]}
{"kind": "depth", "E": 1787095197549, "U": 11316362780591, "u": 11316362785470, "recv_ms": 1787095197618, "bids": [[1000.0, 35.76], [14178.9, 0.686], [14578.9, 3.514], [58211.0, 0.01], [61444.9, 0.0], [62091.7, 0.703], [63678.9, 1.173], [63826.5, 3.128], [64032.1, 4.699], [64614.2, 2.167], [64658.9, 0.504], [64659.7, 0.001], [64661.4, 0.557], [64662.5, 0.006], [64665.5, 1.079], [64666.3, 0.288], [64675.3, 0.494]], "asks": [[64679.0, 27.965], [64698.0, 0.228], [64698.9, 2.826], [64699.7, 0.0], [64701.7, 0.001], [64702.6, 0.158], [64703.4, 2.326], [64875.2, 6.609], [65325.8, 5.167], [65455.1, 35.315], [65679.0, 0.342], [65883.3, 1.67], [67165.4, 0.0]]}
{"kind": "depth", "E": 1787095197651, "U": 11316362785545, "u": 11316362793134, "recv_ms": 1787095197719, "bids": [[14178.9, 0.392], [14478.9, 0.056], [14578.9, 3.752], [51743.0, 0.0], [58211.0, 0.01], [61444.9, 0.0], [63385.4, 0.954], [63860.8, 12.444], [63909.2, 8.444], [64032.1, 4.699], [64310.1, 7.435], [64355.5, 4.435], [64536.6, 1.116], [64637.1, 2.618], [64640.0, 3.711], [64644.5, 0.003], [64644.8, 1.302], [64646.0, 0.764], [64649.2, 0.209], [64658.1, 1.23], [64662.5, 0.006], [64665.5, 0.461], [64670.7, 0.179], [64671.6, 0.094], [64672.9, 1.773], [64675.3, 0.494], [64676.5, 0.011], [64678.9, 2.484]], "asks": [[64679.0, 27.965], [64681.4, 0.167], [64682.6, 0.0], [64683.8, 0.003], [64684.6, 0.188], [64685.1, 0.042], [64687.9, 1.269], [64690.9, 0.012], [64691.0, 0.679], [64691.3, 2.791], [64692.4, 10.003], [64694.4, 0.363], [64695.0, 0.026], [64717.8, 5.334], [64721.0, 0.465], [65325.8, 5.167], [65455.1, 36.84], [65596.1, 1.522]]}
{"kind": "depth", "E": 1787095197753, "U": 11316362793298, "u": 11316362800264, "recv_ms": 1787095197821, "bids": [[14178.9, 0.252], [14478.9, 0.28], [14578.9, 3.668], [58211.0, 0.01], [62091.7, 0.706], [63678.9, 1.153], [64032.1, 4.699], [64640.0, 3.697], [64646.8, 0.559], [64665.9, 1.517], [64668.5, 0.393], [64672.4, 0.008], [64672.9, 1.547], [64675.3, 0.073]], "asks": [[64679.0, 27.965], [64684.6, 0.02], [64687.2, 0.162], [64691.9, 0.876], [64693.3, 0.001], [64693.6, 0.24], [64696.4, 0.02], [65261.2, 7.792], [65261.7, 0.0], [65325.8, 5.167], [65679.0, 0.322], [65888.5, 2.228], [67169.9, 0.149]]}
{"kind": "depth", "E": 1787095198059, "U": 11316362812865, "u": 11316362818447, "recv_ms": 1787095198128, "bids": [[1000.0, 35.76], [14178.9, 0.0], [14478.9, 1.092], [14578.9, 3.108], [58211.0, 0.01], [62091.7, 0.703], [63902.8, 27.738], [64032.1, 4.699], [64576.4, 0.001], [64578.4, 1.767], [64607.5, 0.0], [64609.7, 33.092], [64611.1, 1.887], [64611.9, 0.003], [64614.2, 2.167], [64633.3, 0.004], [64640.6, 0.416], [64667.3, 0.419], [64672.9, 1.66], [64675.3, 0.073], [64676.5, 0.011]], "asks": [[64684.6, 0.036], [64684.8, 2.346], [64690.9, 0.004], [64875.2, 6.962], [65325.8, 5.167], [71146.9, 0.0]]}
{"kind": "depth", "E": 1787095198161, "U": 11316362818517, "u": 11316362823506, "recv_ms": 1787095198229, "bids": [[1000.0, 35.76], [14478.9, 1.442], [14578.9, 2.758], [58211.0, 0.01], [62366.4, 0.0], [63273.6, 0.0], [63678.9, 1.153], [63773.4, 20.324], [64032.1, 4.699], [64211.2, 9.344], [64598.9, 0.003], [64606.1, 0.004], [64610.4, 6.002], [64619.5, 0.346], [64624.8, 0.0], [64633.1, 3.533], [64633.2, 2.758], [64635.2, 1.029], [64635.3, 0.031], [64649.2, 0.755], [64672.9, 1.547], [64674.4, 0.087], [64674.6, 0.32], [64675.3, 0.494]], "asks": [[64683.0, 0.012], [64684.6, 0.02], [64684.8, 2.346], [64690.9, 0.02], [64701.8, 0.706], [64702.6, 0.714], [64703.5, 0.633], [64717.9, 3.504], [64740.6, 6.002], [64772.9, 0.022], [64787.3, 0.295], [65305.2, 0.0], [65325.8, 5.167], [65679.0, 0.322], [65972.5, 0.012]]}
{"kind": "depth", "E": 1787095198263, "U": 11316362823782, "u": 11316362828919, "recv_ms": 1787095198331, "bids": [[14478.9, 1.806], [14578.9, 2.394], [51743.0, 0.002], [58211.0, 0.01], [61336.7, 0.012], [61444.9, 0.0], [61982.3, 0.0], [62091.7, 0.706], [63891.0, 9.64], [64032.1, 4.699], [64355.5, 4.434], [64518.8, 2.343], [64519.0, 7.312], [64535.8, 0.0], [64536.0, 6.374], [64637.1, 2.0], [64646.0, 0.762], [64646.1, 0.0], [64646.2, 0.007], [64649.4, 0.0], [64649.5, 0.04], [64649.6, 0.146], [64667.4, 0.017], [64668.0, 0.243], [64669.4, 0.003], [64675.3, 0.494], [64676.5, 0.011], [64678.9, 2.464]], "asks": [[64679.0, 27.965], [64683.0, 0.011], [64684.6, 0.036], [64690.3, 0.469], [64690.9, 0.004], [64724.3, 0.001], [64745.3, 0.155], [64819.4, 6.656], [64836.3, 0.001], [64836.4, 10.412], [64875.0, 2.274], [64875.2, 5.531], [64963.9, 0.699], [64965.8, 0.0], [65264.3, 0.472], [65325.8, 5.167], [66872.5, 8.972]]}
{"kind": "depth", "E": 1787095198365, "U": 11316362829024, "u": 11316362834244, "recv_ms": 1787095198435, "bids": [[1000.0, 35.76], [14478.9, 2.156], [14578.9, 2.044], [51743.0, 0.0], [51743.1, 0.0], [58211.0, 0.01], [60691.0, 0.0], [61444.9, 0.0], [62091.7, 0.703], [62628.0, 0.348], [63678.9, 1.173], [63814.3, 0.004], [64032.1, 4.699], [64355.5, 4.433], [64578.1, 10.001], [64578.4, 3.033], [64633.6, 0.638], [64642.6, 0.028], [64658.9, 0.388], [64660.0, 0.122], [64661.4, 0.0], [64662.7, 0.563], [64667.0, 2.864], [64670.7, 0.018], [64671.6, 0.171], [64674.8, 0.084], [64675.3, 0.494], [64678.9, 3.649]], "asks": [[64680.0, 0.006], [64690.3, 0.431], [64695.4, 0.477], [64697.0, 0.023], [64709.8, 0.016], [64772.9, 10.022], [64875.0, 1.727], [65002.4, 4.001], [65312.9, 0.994], [65325.8, 5.167], [65679.0, 0.342], [66307.9, 0.001], [67912.9, 0.073], [71146.9, 0.001]]}
{"kind": "depth", "E": 1787095198467, "U": 11316362834374, "u": 11316362839126, "recv_ms": 1787095198536, "bids": [[1000.0, 35.76], [14478.9, 2.52], [14578.9, 1.68], [58211.0, 0.01], [61445.0, 0.057], [62091.7, 0.706], [64032.1, 4.699], [64111.1, 0.311], [64659.1, 0.117], [64660.0, 0.006], [64661.9, 0.56], [64662.7, 0.006], [64667.6, 0.021], [64668.1, 1.002], [64670.7, 0.095], [64671.6, 0.094], [64671.9, 0.006], [64675.3, 0.073]], "asks": [[64690.3, 0.469], [64691.9, 0.953], [65261.1, 5.907], [65264.3, 0.242], [65325.8, 5.167], [65487.5, 9.429], [65616.8, 21.994], [67072.1, 0.0], [71146.9, 0.0]]}
{"kind": "depth", "E": 1787095198569, "U": 11316362839202, "u": 11316362843085, "recv_ms": 1787095198643, "bids": [[14478.9, 2.87], [14578.9, 1.33], [58211.0, 0.01], [61444.9, 0.0], [63678.9, 1.153], [63800.7, 3.556], [64032.1, 4.699], [64355.5, 4.423], [64641.0, 8.002], [64659.1, 0.001], [64659.7, 0.117], [64660.7, 0.322], [64661.9, 0.003], [64662.1, 0.558], [64663.4, 0.001], [64665.5, 0.002], [64666.3, 0.747], [64667.3, 0.419], [64670.7, 0.018], [64671.1, 0.003], [64671.6, 0.171], [64673.0, 0.088], [64675.1, 0.009], [64675.3, 0.157], [64676.5, 0.011], [64678.9, 3.651]], "asks": [[64679.0, 27.99], [64681.5, 0.086], [64688.0, 3.325], [64690.3, 0.431], [64691.9, 0.876], [64698.9, 2.367], [64699.7, 0.459], [64702.6, 0.042], [64703.5, 0.748], [64703.6, 0.681], [65325.8, 5.167], [65584.5, 28.08], [65679.0, 0.322]]}
{"kind": "depth", "E": 1787095198671, "U": 11316362843265, "u": 11316362849721, "recv_ms": 1787095198741, "bids": [[1000.0, 35.76], [14478.9, 3.234], [14578.9, 0.966], [51743.0, 0.0], [58211.0, 0.01], [61444.9, 0.0], [62091.7, 0.703], [63870.4, 13.411], [64024.8, 0.126], [64032.1, 4.699], [64116.2, 2.336], [64185.3, 0.017], [64346.2, 0.0], [64484.8, 0.811], [64507.5, 0.019], [64620.6, 0.014], [64637.1, 0.0], [64658.0, 0.622], [64658.7, 0.117], [64659.7, 0.001], [64660.7, 0.879], [64662.1, 0.001], [64662.5, 0.006], [64662.7, 0.013], [64663.8, 0.155], [64664.5, 0.48], [64665.1, 0.0], [64665.4, 1.628], [64666.3, 0.288], [64666.4, 0.317], [64667.0, 2.632], [64670.7, 0.179], [64671.1, 0.087], [64671.6, 0.635], [64671.7, 0.004], [64671.9, 0.003], [64672.2, 0.088], [64672.4, 0.008], [64672.5, 0.003], [64672.9, 1.772], [64673.0, 0.096], [64674.0, 0.003], [64674.4, 0.003], [64674.8, 0.0], [64675.1, 0.001], [64675.2, 1.682], [64675.3, 0.306], [64677.1, 0.468], [64677.2, 0.155], [64678.2, 0.03], [64678.6, 0.007], [64678.9, 2.463]], "asks": [[64679.0, 27.99], [64679.5, 0.31], [64681.0, 0.012], [64684.6, 0.036], [64685.9, 0.06], [64686.1, 0.144], [64686.3, 0.19], [64686.4, 0.266], [64687.1, 0.439], [64687.9, 1.887], [64690.3, 0.277], [64690.9, 0.004], [64691.0, 0.053], [64691.3, 1.392], [64692.4, 0.003], [64693.6, 0.394], [64694.4, 0.981], [64694.7, 3.472], [64695.0, 0.026], [64695.1, 10.469], [64695.3, 0.618], [64697.6, 0.53], [64699.7, 0.0], [64700.9, 0.664], [64703.6, 0.125], [64711.4, 0.006], [64736.7, 9.129], [64737.0, 0.004], [64737.1, 0.007], [64737.5, 0.001], [64739.2, 1.748], [64739.3, 0.023], [64745.3, 0.001], [64745.9, 56.806], [64771.2, 0.849], [64836.7, 0.0], [64875.0, 0.353], [64875.2, 5.963], [64998.8, 0.035], [65161.3, 0.239], [65261.1, 6.137], [65324.3, 0.001], [65325.8, 5.167], [65587.6, 2.071], [65972.5, 0.015], [66307.3, 2.184], [71146.9, 0.002]]}
{"kind": "depth", "E": 1787095198773, "U": 11316362849819, "u": 11316362855814, "recv_ms": 1787095198842, "bids": [[1000.0, 35.76], [14478.9, 3.598], [14578.9, 0.602], [51743.0, 0.004], [58211.0, 0.01], [62091.7, 0.706], [63678.9, 1.173], [63805.7, 11.099], [64032.1, 4.699], [64508.3, 0.104], [64509.1, 0.48], [64635.7, 0.201], [64664.5, 0.021], [64665.9, 1.976], [64671.6, 0.094], [64672.9, 2.088], [64673.0, 0.434], [64673.8, 0.086], [64675.3, 0.306], [64677.2, 0.155]], "asks": [[64684.7, 0.822], [64685.7, 0.065], [64685.9, 0.083], [64697.6, 0.071], [64698.3, 0.459], [64700.9, 0.108], [64702.3, 1.059], [64736.7, 1.267], [64737.0, 0.0], [64737.5, 0.005], [64745.3, 0.078], [65264.5, 0.0], [65325.8, 5.169], [65616.8, 23.058], [65679.0, 0.342], [67912.9, 0.078], [71146.9, 0.0]]}
{"kind": "depth", "E": 1787095198875, "U": 11316362855820, "u": 11316362862814, "recv_ms": 1787095198945, "bids": [[14378.9, 0.084], [14478.9, 3.78], [14578.9, 0.336], [51743.0, 0.0], [58211.0, 0.01], [61444.9, 0.0], [61445.0, 0.055], [61445.1, 0.01], [62091.7, 0.703], [64032.1, 4.699], [64034.5, 0.008], [64195.0, 0.105], [64355.5, 4.434], [64355.9, 0.026], [64508.3, 0.143], [64509.1, 0.441], [64517.2, 0.083], [64637.1, 2.0], [64637.3, 0.0], [64643.8, 0.0], [64648.0, 1.751], [64651.7, 0.001], [64658.2, 0.175], [64661.7, 0.005], [64662.8, 0.125], [64665.4, 1.01], [64666.1, 0.168], [64672.9, 2.088], [64673.0, 0.096], [64674.6, 0.01], [64675.3, 0.306], [64676.5, 0.011], [64677.2, 0.155]], "asks": [[64679.0, 28.113], [64686.4, 0.143], [64686.9, 0.101], [64691.9, 0.882], [64693.0, 0.007], [64696.7, 0.019], [64702.0, 0.097], [64706.6, 0.102], [64711.2, 1.27], [64715.0, 0.015], [64846.4, 4.483], [64875.2, 6.197], [65002.4, 4.0], [65008.6, 0.005], [65171.2, 0.005], [65261.2, 8.862], [65325.8, 5.167], [65334.2, 0.083]]}
{"kind": "depth", "E": 1787095199079, "U": 11316362867224, "u": 11316362873927, "recv_ms": 1787095199148, "bids": [[1000.0, 35.76], [14378.9, 0.56], [14478.9, 3.542], [14578.9, 0.098], [51743.0, 0.0], [58211.0, 0.01], [61445.0, 0.053], [61445.1, 0.012], [63061.9, 3.329], [63860.8, 12.093], [64265.8, 0.031], [64508.3, 0.143], [64509.1, 0.441], [64536.1, 5.148], [64536.6, 1.163], [64667.3, 0.419], [64671.6, 0.094], [64672.9, 2.313], [64675.3, 0.081]], "asks": [[64684.6, 0.036], [64739.3, 54.804], [64745.9, 2.342], [64819.4, 6.656], [64875.2, 6.198], [65325.8, 5.168]]}
{"kind": "depth", "E": 1787095199181, "U": 11316362873974, "u": 11316362880891, "recv_ms": 1787095199251, "bids": [[14378.9, 0.812], [14478.9, 3.388], [14578.9, 0.0], [51743.0, 0.0], [58211.0, 0.01], [61444.9, 0.0], [62091.7, 0.703], [63385.4, 0.954], [63678.9, 1.173], [63708.8, 3.33], [64032.1, 4.699], [64355.5, 4.424], [64508.3, 0.104], [64509.1, 0.48], [64536.1, 0.028], [64536.6, 0.464], [64588.7, 0.001], [64598.8, 0.027], [64598.9, 0.0], [64606.0, 0.004], [64606.1, 0.0], [64619.5, 0.345], [64630.1, 0.003], [64630.2, 0.003], [64635.1, 0.391], [64635.2, 1.026], [64637.1, 0.0], [64658.7, 0.001], [64660.3, 0.118], [64660.7, 0.322], [64662.1, 0.558], [64667.3, 0.421], [64670.7, 0.177], [64671.6, 0.094], [64672.9, 2.088], [64675.3, 0.081], [64676.5, 0.011], [64678.9, 2.463]], "asks": [[64679.0, 28.114], [64683.5, 0.114], [64698.3, 0.0], [64699.3, 10.287], [64702.3, 0.503], [64703.0, 0.78], [64703.1, 0.714], [64703.5, 0.633], [64728.7, 0.0], [64732.6, 2.324], [64735.2, 1.0], [64739.1, 1.316], [64819.4, 1.256], [64900.0, 35.159], [65325.8, 5.17], [65510.0, 10.736], [65516.9, 0.129], [65519.8, 1.981], [65523.5, 0.0], [65570.3, 0.011], [65679.0, 0.342]]}
{"kind": "depth", "E": 1787095199283, "U": 11316362880937, "u": 11316362886965, "recv_ms": 1787095199353, "bids": [[1000.0, 35.76], [14378.9, 1.176], [14478.9, 3.024], [58211.0, 0.01], [61444.9, 0.0], [62091.7, 0.706], [63870.4, 13.762], [64032.1, 4.699], [64508.3, 0.143], [64509.1, 0.441], [64519.0, 0.115], [64519.1, 7.031], [64536.1, 5.148], [64561.1, 0.001], [64561.2, 3.865], [64570.3, 2.403], [64571.4, 0.001], [64606.7, 0.027], [64606.9, 0.062], [64616.9, 0.001], [64617.1, 1.972], [64625.3, 0.003], [64625.4, 1.972], [64633.7, 0.031], [64633.8, 0.195], [64659.3, 0.508], [64660.3, 0.002], [64671.6, 0.094], [64672.4, 0.458], [64672.7, 0.003], [64672.9, 2.201], [64673.0, 0.434], [64673.1, 0.226], [64675.0, 1.685], [64675.1, 0.001], [64675.3, 0.811], [64678.9, 2.487]], "asks": [[64679.0, 27.946], [64679.5, 0.0], [64683.5, 0.113], [64685.5, 0.003], [64687.9, 1.269], [64693.6, 0.593], [64695.3, 0.0], [64700.7, 0.002], [64700.8, 2.867], [64709.1, 0.014], [64709.2, 1.971], [64717.5, 0.001], [64717.6, 2.126], [64722.6, 0.101], [64732.6, 2.32], [64749.1, 0.0], [64749.3, 0.192], [64786.0, 2.364], [64787.5, 2.345], [64813.4, 0.0], [64813.6, 3.886], [64819.4, 6.656], [64836.4, 10.412], [64875.2, 6.199], [65325.8, 5.168], [65376.3, 0.614], [65507.9, 0.915], [65552.2, 7.197], [65578.0, 10.746], [65768.7, 3.473], [67912.9, 0.088]]}
{"kind": "depth", "E": 1787095199385, "U": 11316362887046, "u": 11316362891859, "recv_ms": 1787095199453, "bids": [[1000.0, 35.76], [14378.9, 1.54], [14478.9, 2.66], [51743.1, 0.0], [58211.0, 0.01], [62091.7, 0.689], [63678.9, 1.153], [63736.0, 13.642], [64032.1, 4.699], [64274.8, 0.145], [64355.5, 4.425], [64641.0, 0.002], [64641.2, 2.004], [64645.2, 0.078], [64665.6, 0.013], [64665.8, 3.323], [64670.7, 0.093], [64671.6, 0.319], [64671.7, 0.003], [64672.2, 0.089], [64672.4, 0.008], [64672.7, 0.003], [64672.9, 2.201], [64673.0, 0.096], [64673.1, 0.001], [64675.3, 0.586], [64675.7, 0.094], [64676.5, 0.011], [64678.9, 3.673]], "asks": [[64679.0, 27.945], [64685.5, 0.003], [64685.7, 0.045], [64685.9, 0.041], [64686.1, 0.122], [64686.4, 0.163], [64686.5, 0.315], [64687.9, 1.349], [64688.0, 3.327], [64688.2, 0.004], [64690.0, 0.07], [64695.1, 10.469], [64730.8, 0.263], [64737.1, 54.788], [64739.3, 0.023], [64875.2, 5.453], [65002.4, 3.999], [65325.8, 5.168], [65519.8, 2.896], [65622.1, 0.0], [65679.0, 0.322]]}
{"kind": "depth", "E": 1787095199487, "U": 11316362891897, "u": 11316362896189, "recv_ms": 1787095199555, "bids": [[14378.9, 1.89], [14478.9, 2.31], [51743.0, 0.0], [58211.0, 0.01], [61444.9, 0.0], [62091.7, 0.692], [63708.7, 4.502], [63725.0, 1.279], [63805.7, 10.317], [64032.1, 4.699], [64355.5, 4.425], [64508.3, 0.104], [64509.1, 0.48], [64671.6, 0.544], [64675.3, 0.586], [64678.9, 3.669]], "asks": [[64693.6, 0.67], [64737.0, 0.004], [64737.5, 0.001], [65325.8, 5.168], [65519.8, 3.201], [65883.3, 0.76], [65972.5, 0.012]]}
{"kind": "depth", "E": 1787095199691, "U": 11316362901882, "u": 11316362907904, "recv_ms": 1787095199761, "bids": [[1000.0, 35.76], [14378.9, 2.604], [14478.9, 1.596], [51743.0, 0.0], [58211.0, 0.01], [61444.9, 0.0], [62091.7, 0.689], [63678.9, 1.153], [63828.5, 8.429], [63909.2, 8.444], [64032.1, 4.699], [64519.1, 0.021], [64521.2, 2.395], [64536.1, 0.028], [64611.1, 7.435], [64662.5, 0.006], [64665.3, 0.87], [64671.6, 0.094], [64675.3, 0.165], [64676.5, 0.011], [64678.9, 3.669]], "asks": [[64679.0, 27.953], [64687.1, 0.516], [64687.8, 0.713], [64693.6, 0.689], [64695.0, 0.026], [64695.2, 0.75], [64738.8, 0.154], [64819.4, 1.256], [64836.0, 0.861], [64836.4, 0.001], [64875.1, 1.201], [65325.8, 5.168], [65448.7, 7.335], [65542.3, 8.128], [65679.0, 0.322], [65972.5, 0.015]]}
{"kind": "depth", "E": 1787095199793, "U": 11316362908010, "u": 11316362912408, "recv_ms": 1787095199863, "bids": [[14378.9, 2.954], [14478.9, 1.246], [51743.0, 0.0], [58211.0, 0.01], [62091.7, 0.692], [63469.4, 3.067], [63579.4, 8.623], [63805.7, 11.099], [64032.1, 4.699], [64355.5, 4.435], [64366.0, 1.077], [64413.0, 0.009], [64508.3, 0.104], [64509.1, 0.48], [64519.2, 7.217], [64536.2, 5.135], [64671.6, 0.094], [64672.4, 0.008], [64672.9, 2.088], [64675.3, 0.165]], "asks": [[64687.1, 0.593], [64738.8, 0.077], [64819.4, 6.656], [64836.0, 2.308], [64836.4, 10.412], [64875.2, 5.454], [65325.8, 5.168], [65507.9, 0.0], [65520.3, 3.602], [65574.7, 17.244]]}
{"kind": "depth", "E": 1787095199895, "U": 11316362912534, "u": 11316362916434, "recv_ms": 1787095199963, "bids": [[1000.0, 35.76], [14378.9, 3.318], [14478.9, 0.882], [58211.0, 0.01], [61444.9, 0.0], [62091.7, 0.689], [63566.4, 1.884], [64032.1, 4.699], [64355.5, 4.434], [64508.3, 0.143], [64509.1, 0.441], [64519.2, 7.217], [64536.2, 4.072], [64646.0, 0.764], [64646.1, 0.002], [64646.2, 0.009], [64649.4, 0.002], [64649.5, 0.042], [64649.6, 0.148], [64671.6, 0.207], [64675.3, 0.586], [64676.5, 0.011]], "asks": [[64679.0, 27.953], [64687.1, 0.67], [64721.9, 5.864], [64722.1, 0.0], [64738.8, 0.0], [64819.4, 6.656], [64875.2, 5.454], [65325.8, 5.168], [65552.2, 7.577], [65876.8, 0.046]]}
{"kind": "depth", "E": 1787095199997, "U": 11316362916489, "u": 11316362920170, "recv_ms": 1787095200067, "bids": [[1000.0, 35.76], [14378.9, 3.668], [14478.9, 0.532], [58211.0, 0.01], [61444.9, 0.001], [63678.9, 1.173], [63800.7, 2.821], [63902.8, 29.301], [63909.2, 8.444], [64032.1, 4.699], [64536.2, 4.804], [64614.9, 0.0], [64615.3, 0.002], [64615.6, 0.006], [64615.9, 1.96], [64616.2, 2.321], [64621.9, 0.107], [64632.5, 6.341], [64632.8, 0.0], [64633.1, 3.501], [64633.4, 0.019], [64633.8, 0.163], [64647.3, 0.014], [64647.4, 3.564], [64647.5, 0.017], [64647.6, 0.002], [64647.7, 0.019], [64647.8, 0.074], [64647.9, 0.311], [64648.0, 1.581], [64648.1, 0.009], [64648.2, 0.002], [64648.3, 0.008], [64649.1, 0.002], [64649.6, 0.048], [64666.2, 0.256], [64666.3, 0.218], [64666.4, 0.247], [64666.5, 0.005], [64666.6, 0.797], [64666.7, 0.048], [64666.8, 0.002], [64666.9, 0.326], [64667.0, 2.462], [64667.1, 1.295], [64667.2, 1.406], [64667.3, 0.591], [64667.5, 0.015], [64667.7, 0.089], [64667.8, 0.005], [64668.2, 0.005], [64668.5, 0.361], [64668.8, 0.036], [64671.6, 0.094], [64675.3, 0.586], [64678.9, 3.671]], "asks": [[64679.0, 27.95], [64684.4, 0.094], [64684.6, 0.02], [64684.7, 0.001], [64684.8, 2.416], [64684.9, 1.532], [64685.1, 0.004], [64685.2, 0.08], [64685.4, 0.442], [64685.7, 0.003], [64686.0, 0.005], [64686.1, 0.002], [64686.2, 0.118], [64686.3, 0.0], [64686.4, 0.033], [64686.5, 0.055], [64686.6, 0.004], [64686.7, 0.716], [64686.8, 1.004], [64686.9, 0.01], [64687.0, 0.165], [64698.4, 1.062], [64701.9, 0.008], [64702.3, 0.468], [64702.6, 0.004], [64702.9, 1.068], [64703.2, 0.006], [64703.3, 0.091], [64703.6, 0.005], [64703.7, 0.296], [64704.1, 0.09], [64704.9, 0.375], [64705.0, 0.002], [64705.1, 0.011], [64705.2, 0.031], [64705.3, 0.104], [64705.4, 0.038], [64705.5, 0.007], [64705.6, 1.268], [64705.7, 0.001], [64705.8, 0.007], [64719.5, 0.019], [64719.8, 0.019], [64720.1, 3.25], [64720.4, 2.529], [64720.8, 0.002], [64721.8, 0.172], [64721.9, 5.71], [64735.0, 0.179], [64735.2, 1.03], [64819.4, 1.256], [64819.5, 5.406], [64875.2, 6.364], [65002.4, 4.0], [65325.8, 5.167], [65448.7, 8.251], [65679.0, 0.342]]}
{"kind": "depth", "E": 1787095200099, "U": 11316362920340, "u": 11316362928636, "recv_ms": 1787095200168, "bids": [[14278.9, 0.14], [14378.9, 3.752], [14478.9, 0.308], [51743.0, 0.046], [58211.0, 0.01], [61444.9, 0.001], [62091.7, 0.692], [63826.5, 3.91], [63860.8, 11.827], [64032.1, 4.699], [64355.5, 4.424], [64619.3, 0.393], [64619.5, 0.344], [64620.8, 0.007], [64620.9, 0.0], [64621.9, 0.121], [64630.9, 0.086], [64631.7, 0.004], [64633.0, 0.035], [64633.3, 0.036], [64633.6, 0.667], [64635.2, 1.027], [64649.6, 0.105], [64650.3, 0.005], [64662.7, 0.006], [64663.2, 0.175], [64663.8, 0.001], [64663.9, 0.013], [64665.9, 1.517], [64666.1, 0.627], [64666.7, 0.118], [64666.9, 0.396], [64667.1, 1.365], [64667.2, 1.606], [64667.3, 0.591], [64667.4, 0.117], [64667.5, 0.085], [64667.6, 0.121], [64668.0, 0.275], [64668.3, 0.033], [64668.7, 0.033], [64669.6, 0.155], [64670.5, 1.005], [64671.6, 0.094], [64672.4, 0.008], [64672.7, 1.662], [64672.8, 1.09], [64672.9, 0.004], [64673.0, 0.093], [64673.1, 0.001], [64673.2, 0.0], [64675.3, 0.586], [64676.5, 0.011], [64678.9, 3.675]], "asks": [[64679.0, 27.956], [64679.1, 1.404], [64679.2, 0.002], [64683.5, 0.151], [64683.8, 0.045], [64684.2, 0.043], [64684.5, 0.124], [64684.6, 0.652], [64684.7, 0.368], [64684.9, 1.652], [64685.0, 0.141], [64685.1, 0.074], [64685.3, 0.577], [64685.4, 0.519], [64685.6, 0.319], [64685.8, 0.322], [64686.5, 0.048], [64686.6, 0.159], [64686.7, 0.09], [64687.4, 0.005], [64691.0, 0.208], [64694.3, 0.35], [64695.4, 0.479], [64697.3, 1.705], [64698.5, 0.0], [64698.6, 0.461], [64698.8, 0.317], [64699.3, 9.828], [64701.0, 0.471], [64701.3, 0.047], [64701.4, 3.248], [64701.7, 0.043], [64702.1, 6.166], [64702.5, 0.14], [64702.9, 1.011], [64703.1, 0.56], [64703.5, 0.724], [64703.6, 0.125], [64703.8, 0.287], [64704.0, 0.082], [64704.2, 0.212], [64704.3, 1.212], [64705.3, 0.258], [64709.6, 0.061], [64711.8, 0.157], [64716.0, 0.009], [64717.8, 0.354], [64718.5, 1.38], [64718.9, 0.056], [64719.2, 2.126], [64721.8, 0.018], [64721.9, 5.864], [64722.6, 0.097], [64723.6, 0.029], [64732.5, 6.959], [65325.8, 5.167], [65519.8, 4.116], [65519.9, 13.638], [66290.7, 0.604]]}
{"kind": "depth", "E": 1787095200201, "U": 11316362928681, "u": 11316362936895, "recv_ms": 1787095200284, "bids": [[1000.0, 35.76], [14278.9, 0.378], [14378.9, 3.626], [14478.9, 0.196], [51743.0, 0.0], [58211.0, 0.01], [61444.9, 0.0], [62091.7, 0.689], [63678.9, 1.153], [63805.7, 11.834], [63909.2, 9.382], [64032.1, 4.699], [64598.9, 0.001], [64602.6, 0.031], [64606.1, 0.001], [64609.7, 0.189], [64611.1, 1.887], [64611.8, 32.858], [64614.2, 2.176], [64618.6, 0.001], [64621.9, 0.093], [64630.1, 0.004], [64634.0, 0.033], [64634.3, 0.033], [64666.8, 0.072], [64667.0, 2.532], [64667.1, 1.465], [64669.0, 0.032], [64669.3, 2.826], [64671.6, 0.432], [64672.2, 0.089], [64672.5, 0.003], [64672.7, 0.003], [64672.9, 1.55], [64675.3, 0.586], [64675.7, 0.01], [64678.9, 3.672]], "asks": [[64679.0, 27.957], [64682.9, 0.084], [64683.2, 0.192], [64683.7, 0.003], [64683.9, 0.082], [64685.0, 0.291], [64685.2, 0.164], [64685.3, 0.668], [64698.6, 0.002], [64698.7, 0.541], [64700.4, 0.421], [64700.7, 0.037], [64703.9, 0.153], [64704.0, 0.166], [64704.2, 0.303], [64717.9, 3.536], [64718.2, 0.049], [64719.2, 2.156], [64721.9, 5.71], [64734.5, 0.063], [64735.2, 1.0], [64735.3, 0.002], [64745.3, 0.001], [64771.2, 0.772], [65325.8, 5.169], [65679.0, 0.322]]}
{"kind": "depth", "E": 1787095200303, "U": 11316362936976, "u": 11316362946051, "recv_ms": 1787095200372, "bids": [[1000.0, 35.76], [14278.9, 0.616], [14378.9, 3.514], [14478.9, 0.07], [51743.0, 0.0], [58211.0, 0.01], [61444.9, 0.001], [62091.7, 0.692], [64032.1, 4.699], [64355.5, 4.424], [64536.2, 0.002], [64536.3, 5.134], [64561.2, 0.0], [64561.3, 3.869], [64606.9, 0.016], [64607.0, 0.071], [64607.5, 32.763], [64611.8, 0.001], [64621.9, 0.107], [64625.7, 0.003], [64638.0, 8.015], [64641.2, 0.004], [64642.6, 0.056], [64655.4, 0.001], [64656.4, 0.072], [64656.6, 0.001], [64657.8, 2.341], [64658.0, 0.004], [64659.1, 0.021], [64659.3, 0.392], [64659.4, 0.012], [64660.3, 0.118], [64660.5, 1.656], [64660.6, 0.027], [64662.6, 0.55], [64663.2, 0.021], [64663.3, 0.027], [64663.9, 0.006], [64665.1, 0.007], [64665.3, 0.252], [64665.4, 1.003], [64665.9, 1.749], [64666.1, 0.168], [64666.2, 0.163], [64666.4, 0.015], [64666.5, 0.773], [64666.9, 0.396], [64667.0, 1.323], [64667.3, 0.684], [64667.4, 0.117], [64667.5, 0.185], [64668.0, 0.255], [64668.8, 0.336], [64669.2, 0.686], [64669.4, 0.003], [64669.6, 0.001], [64670.1, 0.0], [64670.5, 1.082], [64670.7, 0.016], [64671.6, 0.001], [64671.7, 0.551], [64672.4, 0.001], [64672.5, 0.046], [64672.8, 0.549], [64672.9, 1.547], [64674.1, 0.002], [64675.3, 0.157], [64675.4, 0.012], [64675.7, 0.01], [64676.2, 0.003], [64677.0, 0.0], [64678.9, 2.396]], "asks": [[64679.0, 27.957], [64683.9, 0.159], [64684.4, 0.249], [64684.7, 0.333], [64684.8, 2.725], [64685.3, 0.359], [64686.6, 0.004], [64686.7, 0.245], [64687.4, 0.005], [64687.8, 0.095], [64688.9, 0.002], [64691.0, 0.208], [64694.3, 0.35], [64694.5, 3.877], [64694.6, 0.288], [64695.2, 0.132], [64698.7, 0.082], [64698.8, 0.317], [64699.3, 10.287], [64703.5, 0.844], [64721.9, 5.71], [64722.2, 0.156], [64749.3, 0.146], [64749.4, 0.273], [64813.6, 3.886], [64819.5, 5.406], [64875.2, 5.54], [65325.8, 5.167]]}
{"kind": "depth", "E": 1787095200405, "U": 11316362946273, "u": 11316362960347, "recv_ms": 1787095200475, "bids": [[14278.9, 0.91], [14378.9, 3.29], [14478.9, 0.0], [51743.1, 0.0], [58211.0, 0.01], [58211.1, 0.051], [61444.9, 0.0], [62091.7, 0.689], [63678.9, 1.173], [64032.1, 4.699], [64355.5, 4.423], [64502.9, 0.015], [64507.6, 0.0], [64520.4, 0.057], [64528.2, 0.02], [64555.6, 0.0], [64567.1, 0.014], [64568.5, 2.32], [64570.3, 0.084], [64600.8, 0.001], [64607.5, 0.0], [64609.7, 32.952], [64615.5, 0.344], [64615.8, 0.032], [64616.1, 1.474], [64617.5, 0.0], [64621.9, 0.093], [64637.6, 0.001], [64638.0, 8.017], [64639.8, 2.133], [64640.0, 3.711], [64648.1, 0.079], [64648.4, 0.1], [64648.5, 0.07], [64648.8, 0.127], [64649.6, 0.048], [64655.4, 0.001], [64657.6, 0.892], [64659.7, 0.001], [64660.3, 0.559], [64660.6, 0.027], [64662.0, 0.52], [64662.1, 0.001], [64662.7, 0.013], [64663.3, 0.02], [64664.2, 1.065], [64664.6, 0.012], [64664.7, 1.244], [64664.8, 0.234], [64665.0, 0.904], [64665.1, 0.0], [64665.3, 0.406], [64665.8, 2.323], [64665.9, 1.362], [64666.0, 1.654], [64666.5, 0.314], [64667.0, 0.423], [64667.2, 1.926], [64667.4, 0.117], [64668.0, 0.135], [64668.6, 0.307], [64668.8, 0.176], [64668.9, 0.004], [64669.2, 0.532], [64669.4, 0.096], [64670.4, 1.123], [64670.5, 1.005], [64670.7, 0.0], [64671.2, 0.632], [64671.4, 0.01], [64671.8, 0.63], [64672.2, 0.088], [64672.4, 0.001], [64672.5, 0.043], [64672.7, 1.549], [64672.8, 0.024], [64672.9, 0.001], [64673.0, 0.085], [64674.7, 0.084], [64675.0, 1.375], [64675.1, 0.001], [64675.3, 0.074], [64675.4, 0.004], [64677.1, 0.284], [64678.3, 0.005], [64678.6, 0.0], [64678.9, 1.861]], "asks": [[64679.0, 27.957], [64679.3, 0.223], [64682.3, 0.824], [64682.5, 0.006], [64683.8, 0.2], [64683.9, 0.531], [64684.4, 0.094], [64684.5, 0.164], [64684.7, 0.325], [64684.9, 1.653], [64685.2, 0.161], [64686.6, 0.003], [64686.7, 0.245], [64687.1, 0.965], [64687.4, 0.098], [64691.0, 0.208], [64691.3, 1.39], [64692.0, 4.355], [64694.3, 0.35], [64694.6, 0.288], [64697.4, 0.462], [64698.8, 0.317], [64699.2, 1.363], [64699.3, 9.828], [64700.4, 0.537], [64700.6, 0.561], [64703.0, 0.672], [64703.1, 0.004], [64704.1, 0.083], [64706.6, 0.012], [64721.0, 0.234], [64730.8, 0.254], [64771.2, 0.419], [64784.2, 2.319], [64786.0, 0.045], [64787.3, 0.0], [64790.6, 0.002], [64797.0, 0.001], [64801.6, 4.914], [64875.1, 0.001], [64875.2, 1.726], [65002.4, 4.001], [65325.8, 5.167], [65572.5, 2.285], [65597.4, 2.273], [65679.0, 0.342]]}
{"kind": "depth", "E": 1787095200507, "U": 11316362960477, "u": 11316362978419, "recv_ms": 1787095200576, "bids": [[1000.0, 35.76], [14278.9, 1.26], [14378.9, 2.94], [58211.0, 0.01], [61444.9, 0.0], [63860.8, 11.593], [64032.1, 4.699], [64161.5, 9.634], [64600.8, 0.0], [64616.4, 0.034], [64616.8, 0.032], [64622.7, 0.021], [64637.2, 0.001], [64641.3, 0.004], [64647.9, 0.381], [64648.0, 1.651], [64648.2, 0.072], [64648.4, 0.2], [64648.5, 0.17], [64648.7, 0.073], [64649.7, 0.13], [64650.1, 0.196], [64655.4, 0.001], [64657.8, 2.321], [64659.1, 0.001], [64660.6, 0.027], [64662.0, 0.521], [64662.8, 0.145], [64664.1, 0.079], [64664.2, 0.606], [64664.8, 0.002], [64665.0, 1.136], [64665.3, 0.865], [64667.4, 0.117], [64667.5, 0.185], [64669.4, 0.003], [64669.8, 0.326], [64670.4, 1.208], [64670.5, 1.013], [64671.2, 0.631], [64671.4, 0.01], [64671.6, 0.001], [64671.8, 0.089], [64672.8, 0.008], [64672.9, 0.542], [64673.0, 0.093], [64675.1, 0.001], [64675.3, 0.082], [64677.4, 0.001], [64677.6, 0.042], [64677.8, 0.045], [64678.5, 0.002], [64678.6, 0.0], [64678.7, 0.0], [64678.8, 0.016], [64678.9, 2.577]], "asks": [[64679.0, 28.339], [64683.8, 0.2], [64684.5, 0.196], [64686.5, 0.024], [64686.7, 0.237], [64691.0, 0.208], [64691.9, 0.959], [64694.3, 0.35], [64697.4, 0.003], [64698.0, 0.687], [64698.8, 0.317], [64700.4, 0.421], [64700.6, 0.005], [64701.2, 0.0], [64701.8, 0.822], [64701.9, 0.564], [64875.2, 1.727], [65325.8, 5.167], [65972.5, 0.012]]}
{"kind": "depth", "E": 1787095200609, "U": 11316362978872, "u": 11316362994312, "recv_ms": 1787095200679, "bids": [[1000.0, 35.76], [14278.9, 1.61], [14378.9, 2.59], [51743.0, 0.0], [58211.0, 0.01], [61444.9, 0.0], [61445.0, 0.051], [61445.1, 0.014], [62091.7, 0.692], [62285.7, 0.073], [63678.9, 1.153], [63902.7, 0.0], [64032.1, 4.699], [64355.5, 4.433], [64502.9, 0.016], [64506.1, 0.003], [64637.2, 0.0], [64638.1, 1.331], [64647.9, 0.451], [64648.1, 0.149], [64648.2, 0.172], [64667.0, 1.323], [64676.2, 0.003]], "asks": [[64679.0, 28.34], [64687.0, 1.065], [64688.0, 2.427], [64691.9, 1.158], [64696.0, 1.077], [64875.2, 5.971], [65325.8, 5.167], [65679.0, 0.322]]}
{"kind": "depth", "E": 1787095200711, "U": 11316362994724, "u": 11316363005411, "recv_ms": 1787095200781, "bids": [[14278.9, 1.974], [14378.9, 2.226], [58211.0, 0.01], [61444.9, 0.0], [62091.7, 0.689], [63787.8, 0.627], [63870.4, 14.113], [63878.9, 0.784], [64032.1, 4.699], [64519.2, 0.0], [64519.3, 7.094], [64521.2, 3.292], [64536.3, 5.121], [64611.1, 7.414], [64633.6, 0.67], [64640.0, 3.697], [64648.6, 3.305], [64655.4, 0.001], [64658.1, 1.848], [64660.6, 0.027], [64662.5, 0.006], [64665.5, 0.62], [64667.4, 0.117], [64670.4, 1.216], [64670.5, 1.005], [64672.8, 0.008], [64673.0, 0.085], [64673.1, 0.009], [64674.2, 0.094], [64674.7, 0.0], [64675.0, 1.459], [64675.1, 0.001], [64675.3, 0.082], [64678.9, 2.577]], "asks": [[64679.0, 29.488], [64679.4, 0.453], [64679.8, 0.113], [64683.8, 0.2], [64684.4, 0.102], [64684.5, 0.729], [64684.6, 0.111], [64686.0, 0.121], [64686.7, 0.237], [64688.0, 3.045], [64691.0, 0.208], [64694.3, 0.35], [64695.0, 0.026], [64695.3, 0.618], [64698.5, 0.003], [64698.8, 0.317], [64736.7, 9.153], [64819.5, 5.406], [64836.4, 10.412], [64875.1, 1.278], [64875.2, 5.899], [65325.8, 5.167], [65584.5, 30.364]]}
{"kind": "depth", "E": 1787095200813, "U": 11316363005805, "u": 11316363016672, "recv_ms": 1787095200881, "bids": [[1000.0, 35.76], [14278.9, 2.324], [14378.9, 1.876], [58211.0, 0.01], [62091.7, 0.692], [63678.9, 1.173], [63902.8, 33.989], [64032.1, 4.699], [64630.4, 1.26], [64630.7, 0.123], [64633.6, 0.67], [64654.2, 0.008], [64655.4, 0.001], [64658.1, 1.23], [64659.9, 0.0], [64660.6, 0.027], [64665.3, 0.616], [64665.5, 0.002], [64667.4, 0.117], [64668.6, 0.157], [64672.4, 0.001], [64672.6, 0.33], [64672.7, 0.003], [64672.8, 0.008], [64673.0, 2.06], [64673.1, 0.001], [64675.1, 0.001], [64675.3, 0.082], [64676.2, 0.003], [64678.9, 2.265]], "asks": [[64679.0, 29.488], [64679.4, 0.453], [64683.8, 0.2], [64684.4, 0.094], [64686.7, 0.237], [64688.0, 2.427], [64691.0, 0.216], [64694.3, 0.35], [64695.3, 0.0], [64698.8, 0.317], [64724.3, 0.004], [64790.6, 0.102], [65325.8, 5.167], [65574.8, 0.0], [65616.8, 21.993], [65679.0, 0.342], [65888.5, 1.319]]}
{"kind": "depth", "E": 1787095200915, "U": 11316363016874, "u": 11316363030395, "recv_ms": 1787095200983, "bids": [[1000.0, 35.76], [14278.9, 2.688], [14378.9, 1.512], [58211.0, 0.01], [61444.9, 0.0], [62091.7, 0.689], [63664.7, 0.0], [63676.4, 18.195], [63792.8, 3.126], [63846.6, 4.224], [64032.1, 4.699], [64355.5, 4.433], [64555.5, 0.076], [64672.4, 1.547], [64673.0, 0.085], [64673.1, 0.001], [64673.2, 0.0], [64673.3, 0.423], [64673.4, 0.103], [64677.6, 0.001], [64677.8, 0.087]], "asks": [[64679.0, 29.598], [64727.4, 5.148], [64762.9, 0.022], [64875.2, 5.972], [65325.8, 5.167]]}
{"kind": "depth", "E": 1787095201119, "U": 11316363039926, "u": 11316363060354, "recv_ms": 1787095201209, "bids": [[1000.0, 35.76], [14278.0, 0.014], [14278.1, 0.014], [14278.9, 3.374], [14378.9, 0.798], [58210.2, 0.002], [58211.0, 0.01], [59252.7, 0.0], [61444.9, 0.001], [61445.1, 0.012], [62091.7, 0.692], [63490.9, 0.792], [63678.0, 150.115], [63734.6, 1.348], [63741.1, 24.538], [64032.1, 4.703], [64355.5, 4.434], [64496.1, 0.003], [64516.1, 0.016], [64534.4, 0.002], [64598.9, 0.002], [64601.2, 0.531], [64603.1, 32.763], [64604.5, 0.041], [64606.1, 0.002], [64606.7, 0.001], [64609.7, 0.189], [64610.5, 0.019], [64611.1, 7.416], [64611.5, 0.31], [64612.2, 0.002], [64612.6, 0.001], [64613.5, 1.264], [64618.8, 0.0], [64620.9, 0.005], [64621.7, 0.015], [64622.5, 0.0], [64623.7, 0.0], [64627.4, 8.009], [64630.1, 0.005], [64632.8, 0.0], [64633.3, 0.032], [64635.2, 1.028], [64638.0, 0.017], [64639.4, 0.02], [64639.8, 1.194], [64642.6, 0.056], [64644.5, 0.003], [64644.6, 0.016], [64645.8, 0.216], [64647.0, 3.187], [64647.3, 0.036], [64647.7, 0.0], [64648.4, 0.2], [64648.5, 0.227], [64649.2, 0.755], [64650.5, 0.012], [64651.9, 0.065], [64652.8, 0.02], [64653.6, 0.083], [64653.7, 0.423], [64654.9, 0.099], [64655.3, 1.942], [64655.4, 0.193], [64655.6, 0.012], [64656.0, 0.134], [64656.4, 0.07], [64656.9, 0.99], [64657.1, 0.004], [64658.2, 0.159], [64658.4, 0.001], [64658.6, 0.317], [64658.8, 0.011], [64658.9, 0.041], [64659.1, 0.002], [64659.4, 0.005], [64660.2, 0.074], [64660.4, 4.909], [64660.5, 1.656], [64660.6, 0.19], [64660.7, 0.285], [64660.8, 0.011], [64662.0, 0.441], [64662.5, 0.003], [64662.6, 0.55], [64662.7, 0.006], [64662.8, 0.139], [64663.3, 0.01], [64663.5, 0.631], [64663.6, 0.697], [64664.1, 0.02], [64664.2, 0.026], [64664.7, 0.224], [64664.9, 0.003], [64665.0, 0.904], [64665.1, 0.768], [64665.3, 0.157], [64665.7, 0.463], [64665.8, 2.323], [64666.0, 1.259], [64666.1, 0.255], [64666.5, 0.005], [64667.0, 1.407], [64667.1, 0.228], [64667.3, 0.172], [64667.4, 0.82], [64667.8, 0.002], [64668.4, 0.086], [64668.8, 0.099], [64669.0, 0.342], [64669.1, 0.09], [64669.4, 0.003], [64669.7, 0.001], [64669.8, 0.016], [64669.9, 0.378], [64670.1, 0.001], [64670.2, 0.063], [64670.3, 0.0], [64670.4, 0.003], [64670.5, 0.006], [64670.6, 1.013], [64670.7, 0.008], [64671.1, 0.003], [64671.2, 0.003], [64671.3, 0.161], [64671.4, 0.001], [64671.5, 1.664], [64671.6, 0.43], [64671.7, 0.011], [64671.8, 0.005], [64671.9, 0.003], [64672.2, 0.004], [64672.3, 0.014], [64672.5, 0.544], [64672.6, 0.161], [64672.7, 0.003], [64672.8, 0.009], [64673.0, 0.001], [64673.4, 0.011], [64673.7, 0.046], [64673.8, 0.002], [64673.9, 0.0], [64674.2, 0.01], [64674.4, 0.057], [64674.8, 0.009], [64674.9, 0.005], [64675.0, 1.375], [64675.1, 0.002], [64675.2, 0.007], [64675.3, 0.218], [64675.4, 0.004], [64675.7, 0.008], [64676.2, 0.002], [64676.5, 0.002], [64676.6, 0.0], [64677.1, 0.0], [64677.2, 0.054], [64677.3, 0.067], [64677.5, 0.0], [64677.8, 0.0], [64678.0, 0.0], [64678.1, 0.0], [64678.2, 0.0], [64678.3, 0.0], [64678.4, 0.0], [64678.5, 0.0], [64678.8, 0.0], [64678.9, 0.0]], "asks": [[64677.7, 4.457], [64677.9, 8.54], [64678.1, 41.226], [64678.2, 23.644], [64678.3, 5.247], [64678.4, 1.99], [64678.5, 0.031], [64678.6, 0.274], [64678.7, 1.947], [64678.8, 0.002], [64678.9, 10.69], [64679.0, 14.426], [64679.1, 1.403], [64679.3, 0.158], [64679.4, 0.396], [64680.1, 0.001], [64680.4, 0.002], [64680.6, 0.319], [64681.2, 0.006], [64681.4, 0.16], [64681.9, 0.002], [64682.1, 1.282], [64682.2, 2.341], [64682.6, 0.002], [64682.7, 0.008], [64683.3, 0.144], [64683.4, 0.002], [64683.5, 0.15], [64683.8, 0.122], [64683.9, 0.397], [64684.4, 0.094], [64684.5, 0.156], [64684.6, 0.111], [64684.7, 0.806], [64684.8, 2.711], [64685.6, 0.317], [64685.9, 0.063], [64686.0, 0.124], [64686.4, 0.014], [64686.6, 0.001], [64686.7, 0.079], [64686.8, 1.023], [64686.9, 0.004], [64687.1, 0.783], [64687.4, 0.096], [64687.9, 1.349], [64688.4, 0.2], [64688.6, 4.005], [64690.2, 0.347], [64690.5, 0.064], [64691.0, 0.058], [64691.1, 2.32], [64691.2, 0.156], [64691.4, 0.002], [64691.9, 1.243], [64692.2, 0.042], [64692.5, 1.001], [64692.6, 0.73], [64692.7, 0.002], [64693.7, 0.036], [64693.9, 0.005], [64694.2, 0.01], [64694.3, 0.04], [64694.8, 7.403], [64695.1, 0.551], [64695.4, 0.477], [64696.7, 0.004], [64697.0, 0.038], [64697.4, 0.003], [64697.6, 0.53], [64698.0, 0.228], [64698.2, 0.257], [64698.3, 0.0], [64698.4, 1.186], [64698.8, 0.162], [64699.2, 1.273], [64700.2, 0.001], [64700.3, 0.003], [64701.0, 0.471], [64701.2, 0.057], [64701.5, 1.237], [64701.6, 0.071], [64701.7, 0.058], [64704.8, 0.035], [64704.9, 0.004], [64705.9, 0.0], [64706.1, 0.33], [64707.3, 0.328], [64707.9, 0.01], [64708.8, 1.387], [64709.2, 1.971], [64709.6, 0.001], [64709.8, 0.016], [64710.1, 0.003], [64713.1, 0.016], [64713.5, 0.025], [64714.0, 0.503], [64714.4, 1.288], [64714.7, 0.095], [64716.3, 0.002], [64716.8, 0.139], [64717.1, 0.029], [64718.1, 0.005], [64719.6, 0.002], [64721.4, 2.338], [64722.3, 1.003], [64723.6, 0.026], [64728.4, 0.597], [64735.1, 0.031], [64735.9, 0.003], [64736.8, 2.328], [64737.1, 0.007], [64745.9, 2.342], [64746.4, 2.163], [64748.1, 56.999], [64748.7, 2.319], [64756.7, 0.049], [64758.0, 0.033], [64771.2, 0.4], [64771.4, 10.622], [64778.4, 0.0], [64818.8, 0.0], [64868.0, 1.022], [64875.3, 4.231], [65324.9, 0.002], [65325.8, 5.177], [65669.9, 0.036], [65670.0, 0.84], [65672.1, 0.002], [65672.2, 0.002], [65678.1, 0.028], [65680.5, 0.0], [65888.5, 2.229], [65972.5, 0.006]]}
{"kind": "depth", "E": 1787095201221, "U": 11316363060357, "u": 11316363096239, "recv_ms": 1787095201553, "bids": [[1000.0, 35.76], [14175.3, 0.028], [14275.3, 0.098], [14275.7, 0.014], [14275.9, 0.056], [14276.8, 0.084], [14277.3, 0.042], [14277.6, 0.014], [14278.0, 0.028], [14278.9, 3.346], [14378.9, 0.476], [51740.0, 0.002], [58207.7, 0.002], [58208.3, 0.0], [58209.1, 0.002], [58209.5, 0.001], [58210.2, 0.0], [58211.0, 0.008], [59414.2, 0.0], [59575.6, 0.01], [61441.5, 0.0], [61444.9, 0.0], [61445.1, 0.01], [62091.7, 0.689], [64028.5, 0.01], [64029.1, 0.002], [64030.0, 1.45], [64030.5, 3.12], [64030.8, 0.0], [64031.2, 0.0], [64032.1, 4.699], [64320.7, 0.0], [64326.8, 0.0], [64338.8, 0.0], [64353.0, 0.255], [64355.5, 4.424], [64361.6, 0.209], [64402.5, 0.001], [64404.8, 2.011], [64468.8, 4.823], [64469.7, 0.859], [64508.1, 0.041], [64508.3, 0.143], [64509.1, 0.441], [64520.7, 0.078], [64521.3, 0.061], [64521.9, 0.018], [64522.2, 0.0], [64526.6, 0.0], [64526.7, 1.472], [64531.9, 0.025], [64533.8, 1.0], [64548.1, 0.038], [64554.2, 0.0], [64555.3, 1.592], [64555.5, 0.007], [64556.5, 0.024], [64563.7, 0.001], [64570.3, 0.077], [64576.0, 3.099], [64576.8, 0.015], [64578.2, 0.008], [64581.4, 2.323], [64590.6, 0.002], [64592.1, 0.416], [64596.3, 0.047], [64597.9, 1.449], [64598.7, 36.247], [64598.8, 1.573], [64598.9, 0.003], [64599.3, 0.024], [64600.9, 0.014], [64601.3, 0.2], [64601.9, 0.005], [64603.1, 0.0], [64604.5, 0.015], [64606.1, 0.003], [64606.9, 0.031], [64607.2, 0.0], [64607.4, 0.174], [64607.7, 2.405], [64610.3, 0.0], [64610.4, 6.004], [64610.5, 0.004], [64611.1, 1.887], [64611.4, 0.828], [64612.1, 0.007], [64612.2, 0.009], [64614.2, 0.352], [64616.1, 1.474], [64616.5, 0.037], [64617.1, 0.001], [64617.2, 2.196], [64617.3, 4.633], [64617.4, 0.015], [64617.6, 0.002], [64617.7, 0.002], [64619.3, 0.389], [64619.8, 0.004], [64620.0, 0.006], [64620.9, 0.0], [64621.0, 0.013], [64623.0, 0.061], [64625.1, 0.0], [64625.3, 0.001], [64625.4, 0.002], [64625.5, 0.004], [64625.6, 3.009], [64627.4, 0.011], [64627.5, 0.311], [64628.1, 0.001], [64628.4, 0.029], [64629.5, 0.023], [64629.7, 0.084], [64630.1, 0.006], [64630.7, 0.115], [64631.1, 0.002], [64631.2, 0.041], [64631.3, 0.004], [64631.4, 2.184], [64632.1, 0.118], [64632.6, 0.009], [64632.7, 0.06], [64633.8, 0.018], [64633.9, 0.147], [64634.0, 0.033], [64634.7, 0.348], [64635.2, 1.029], [64635.3, 0.031], [64635.5, 0.0], [64635.7, 3.974], [64636.3, 0.005], [64636.7, 2.364], [64636.8, 1.757], [64637.3, 0.016], [64637.4, 0.026], [64639.0, 0.11], [64639.2, 0.118], [64639.3, 0.001], [64639.4, 0.0], [64639.9, 0.091], [64640.0, 3.7], [64640.6, 0.416], [64641.0, 0.018], [64641.3, 0.004], [64641.7, 0.058], [64641.8, 0.0], [64641.9, 0.07], [64642.0, 0.016], [64642.5, 0.019], [64642.8, 0.002], [64643.6, 0.004], [64643.7, 0.013], [64644.2, 0.0], [64644.4, 0.311], [64644.5, 0.084], [64644.6, 0.0], [64644.8, 1.071], [64645.0, 0.11], [64645.7, 0.357], [64645.8, 0.216], [64646.0, 0.77], [64646.4, 0.196], [64646.6, 0.013], [64647.0, 3.257], [64647.3, 0.014], [64648.0, 1.496], [64648.2, 0.635], [64648.3, 0.017], [64648.5, 0.171], [64649.0, 0.326], [64649.3, 1.303], [64649.6, 0.052], [64649.7, 0.13], [64650.2, 0.045], [64650.3, 0.352], [64650.4, 0.007], [64650.5, 0.005], [64650.6, 0.027], [64650.9, 0.002], [64651.0, 1.313], [64651.2, 1.294], [64651.4, 0.003], [64652.0, 0.075], [64652.2, 0.006], [64652.4, 0.004], [64652.5, 0.113], [64652.7, 0.158], [64652.8, 0.028], [64652.9, 0.003], [64653.0, 1.056], [64653.3, 0.31], [64653.4, 0.032], [64653.5, 0.167], [64653.6, 0.083], [64653.7, 0.421], [64653.8, 0.398], [64653.9, 1.549], [64654.0, 0.047], [64654.2, 0.043], [64654.3, 0.001], [64654.8, 0.117], [64655.1, 1.005], [64655.2, 2.488], [64655.3, 1.942], [64655.4, 0.038], [64655.5, 0.041], [64656.0, 0.131], [64656.1, 0.58], [64656.2, 0.058], [64656.3, 0.022], [64656.4, 0.07], [64656.5, 1.249], [64656.9, 0.629], [64657.0, 1.802], [64657.1, 0.049], [64657.2, 0.073], [64657.4, 0.544], [64657.5, 0.154], [64657.6, 0.002], [64657.7, 0.0], [64657.9, 0.869], [64658.2, 0.314], [64658.3, 0.004], [64658.5, 0.007], [64658.6, 0.31], [64658.8, 0.005], [64658.9, 0.041], [64659.1, 0.009], [64659.2, 0.01], [64659.3, 0.631], [64659.5, 0.002], [64659.6, 0.158], [64659.8, 0.003], [64660.0, 0.006], [64660.1, 0.014], [64660.2, 0.199], [64660.3, 0.002], [64660.4, 4.903], [64660.6, 0.268], [64660.7, 0.25], [64660.8, 0.004], [64660.9, 0.313], [64661.0, 0.0], [64661.1, 0.033], [64661.2, 0.001], [64661.3, 2.483], [64661.4, 1.007], [64661.7, 0.002], [64661.8, 0.0], [64661.9, 0.003], [64662.0, 0.443], [64662.2, 0.0], [64662.4, 0.008], [64662.6, 0.396], [64662.7, 0.005], [64662.8, 0.024], [64662.9, 0.002], [64663.0, 0.003], [64663.1, 2.322], [64663.3, 0.002], [64663.4, 0.155], [64663.6, 0.002], [64663.8, 0.016], [64664.0, 0.002], [64664.2, 0.024], [64664.3, 0.001], [64664.4, 0.003], [64664.6, 0.005], [64664.7, 0.224], [64664.9, 0.323], [64665.0, 0.004], [64665.1, 0.0], [64665.3, 0.003], [64665.4, 0.695], [64665.7, 0.0], [64665.9, 1.446], [64666.0, 1.246], [64666.1, 0.163], [64666.2, 0.092], [64666.4, 0.0], [64666.5, 0.204], [64666.6, 0.961], [64666.9, 0.397], [64667.1, 0.225], [64667.2, 1.889], [64667.3, 0.254], [64667.4, 0.109], [64667.5, 0.185], [64667.6, 1.667], [64667.7, 0.325], [64667.8, 0.002], [64667.9, 0.016], [64668.1, 0.086], [64668.2, 0.005], [64668.3, 0.033], [64668.5, 0.361], [64668.6, 0.001], [64668.7, 0.034], [64668.8, 0.069], [64668.9, 0.004], [64669.0, 0.116], [64669.1, 0.006], [64669.2, 0.611], [64669.4, 0.784], [64669.5, 1.843], [64669.6, 0.085], [64669.7, 0.009], [64669.8, 0.017], [64669.9, 0.161], [64670.0, 0.16], [64670.1, 0.001], [64670.2, 0.217], [64670.5, 0.005], [64670.6, 0.013], [64670.7, 0.008], [64670.8, 0.02], [64671.1, 0.002], [64671.2, 0.02], [64671.3, 0.001], [64671.5, 0.914], [64671.6, 0.009], [64671.7, 0.063], [64671.8, 0.002], [64672.0, 0.006], [64672.1, 0.07], [64672.2, 0.022], [64672.3, 0.004], [64672.4, 0.001], [64672.5, 0.003], [64672.6, 0.007], [64672.7, 0.002], [64672.8, 0.01], [64672.9, 0.009], [64673.5, 0.022], [64673.6, 0.002], [64673.7, 0.0], [64673.8, 0.0], [64673.9, 0.001], [64674.0, 0.005], [64674.1, 0.001], [64674.2, 0.002], [64674.3, 0.001], [64674.4, 0.002], [64674.6, 0.008], [64674.8, 0.0], [64674.9, 0.002], [64675.0, 0.001], [64675.1, 0.0], [64675.2, 0.002], [64675.3, 0.804], [64675.4, 0.0], [64675.5, 0.0], [64675.6, 0.0], [64675.7, 0.0], [64675.9, 0.0], [64676.0, 0.0], [64676.2, 0.0], [64676.5, 0.0], [64676.7, 0.0], [64676.8, 0.0], [64677.2, 0.0], [64677.3, 0.0], [64677.4, 0.0], [64677.6, 0.0]], "asks": [[64675.4, 39.813], [64675.5, 0.838], [64675.6, 0.102], [64675.7, 0.998], [64675.8, 3.179], [64675.9, 0.71], [64676.0, 3.3], [64676.1, 0.002], [64676.3, 0.0], [64676.5, 0.1], [64676.6, 0.001], [64676.7, 0.017], [64676.8, 2.5], [64676.9, 0.735], [64677.0, 0.005], [64677.1, 0.0], [64677.2, 0.055], [64677.3, 0.391], [64677.4, 0.146], [64677.5, 0.001], [64677.6, 0.078], [64677.7, 1.201], [64677.8, 0.002], [64677.9, 0.004], [64678.0, 2.503], [64678.1, 0.006], [64678.2, 1.133], [64678.3, 0.001], [64678.4, 0.008], [64678.5, 0.059], [64678.6, 0.247], [64678.7, 0.001], [64678.8, 0.003], [64678.9, 6.323], [64679.0, 4.294], [64679.1, 1.403], [64679.2, 0.003], [64679.3, 0.005], [64679.6, 0.003], [64679.7, 0.02], [64679.8, 0.136], [64680.0, 0.062], [64680.1, 0.003], [64680.2, 0.085], [64680.5, 0.005], [64680.6, 0.623], [64680.7, 0.084], [64681.0, 0.012], [64681.2, 0.008], [64681.3, 0.1], [64681.4, 0.16], [64681.5, 0.002], [64681.7, 0.008], [64681.8, 0.003], [64681.9, 0.002], [64682.0, 0.199], [64682.1, 1.283], [64682.2, 2.323], [64682.3, 0.019], [64682.4, 0.001], [64682.5, 0.003], [64682.6, 0.002], [64682.7, 0.007], [64682.8, 0.004], [64683.2, 0.5], [64683.3, 0.06], [64683.4, 0.003], [64683.5, 0.042], [64683.6, 1.31], [64683.7, 0.003], [64683.8, 0.046], [64683.9, 0.016], [64684.0, 0.426], [64684.2, 0.044], [64684.4, 0.094], [64684.5, 0.156], [64684.6, 0.121], [64684.7, 0.241], [64684.8, 2.897], [64684.9, 3.261], [64685.1, 0.088], [64685.3, 0.318], [64685.5, 0.003], [64685.7, 0.003], [64685.8, 0.017], [64685.9, 0.041], [64686.0, 0.128], [64686.1, 0.062], [64686.2, 0.01], [64686.3, 0.0], [64686.4, 0.258], [64686.5, 0.001], [64686.6, 0.001], [64686.7, 0.07], [64686.8, 0.004], [64686.9, 0.159], [64687.1, 0.043], [64687.2, 4.162], [64687.5, 0.628], [64687.9, 1.413], [64688.0, 2.643], [64688.3, 0.005], [64688.5, 0.002], [64688.6, 0.005], [64688.7, 0.593], [64688.8, 0.009], [64688.9, 0.002], [64689.0, 0.992], [64689.1, 1.299], [64689.3, 0.003], [64689.4, 0.004], [64689.5, 0.619], [64689.8, 0.001], [64689.9, 0.0], [64690.1, 0.006], [64690.3, 0.064], [64690.4, 0.001], [64690.5, 0.099], [64690.6, 0.081], [64690.7, 0.004], [64690.9, 0.375], [64691.0, 0.053], [64691.2, 0.042], [64691.3, 1.394], [64691.5, 0.002], [64691.6, 0.002], [64691.7, 0.0], [64691.8, 0.385], [64691.9, 0.471], [64692.0, 4.351], [64692.1, 0.049], [64692.2, 0.035], [64692.3, 0.0], [64692.5, 1.001], [64692.6, 0.614], [64692.7, 0.002], [64693.0, 0.002], [64693.2, 0.017], [64693.6, 0.24], [64693.7, 0.001], [64693.9, 0.005], [64694.2, 0.005], [64694.3, 0.195], [64694.4, 2.997], [64694.5, 3.877], [64694.6, 0.747], [64694.7, 0.029], [64694.8, 7.405], [64695.0, 0.026], [64695.1, 0.469], [64695.2, 0.13], [64695.4, 1.291], [64696.0, 1.386], [64696.2, 0.465], [64696.3, 0.31], [64696.5, 0.001], [64696.6, 0.016], [64696.7, 0.004], [64696.8, 0.002], [64696.9, 0.007], [64697.0, 0.023], [64697.1, 0.105], [64697.2, 0.002], [64697.3, 1.711], [64697.4, 0.002], [64697.6, 0.108], [64697.7, 0.033], [64697.8, 3.861], [64697.9, 0.073], [64698.0, 0.226], [64698.2, 0.272], [64698.3, 0.556], [64698.4, 0.277], [64698.5, 0.119], [64698.6, 0.007], [64698.7, 0.002], [64698.8, 0.163], [64699.0, 0.101], [64699.5, 0.125], [64699.6, 0.015], [64700.0, 2.857], [64700.1, 0.913], [64700.3, 0.466], [64700.6, 0.012], [64700.8, 1.241], [64700.9, 1.719], [64701.2, 0.0], [64701.5, 1.286], [64701.6, 0.022], [64701.7, 0.044], [64701.8, 0.706], [64701.9, 0.008], [64702.2, 0.481], [64702.3, 0.464], [64702.6, 0.004], [64702.7, 0.499], [64702.8, 0.016], [64702.9, 0.711], [64703.0, 0.665], [64703.3, 0.111], [64704.3, 1.212], [64704.9, 0.001], [64705.1, 0.002], [64705.4, 1.923], [64706.1, 0.31], [64707.0, 0.093], [64707.7, 1.157], [64707.9, 0.004], [64708.0, 1.272], [64708.8, 1.387], [64709.0, 0.011], [64709.2, 0.001], [64709.3, 2.418], [64709.6, 0.017], [64709.7, 0.423], [64710.0, 2.996], [64710.3, 0.001], [64711.1, 3.277], [64711.2, 1.294], [64711.6, 0.132], [64712.7, 0.014], [64713.0, 0.002], [64713.1, 0.0], [64714.0, 0.018], [64714.2, 0.15], [64714.7, 0.025], [64716.2, 0.066], [64716.5, 0.24], [64716.8, 0.079], [64717.5, 0.157], [64717.6, 0.001], [64717.7, 4.049], [64717.8, 0.352], [64717.9, 3.538], [64718.1, 0.009], [64718.5, 1.379], [64718.9, 0.046], [64719.0, 0.032], [64719.1, 0.019], [64719.2, 2.126], [64719.6, 0.001], [64720.3, 0.0], [64721.0, 0.034], [64721.1, 0.397], [64721.8, 0.018], [64723.6, 0.022], [64724.1, 0.049], [64725.3, 0.0], [64725.4, 0.003], [64725.8, 0.387], [64726.4, 4.261], [64726.9, 0.027], [64730.4, 0.116], [64731.8, 0.015], [64732.0, 0.001], [64732.9, 0.021], [64733.0, 1.471], [64733.5, 0.033], [64733.7, 0.008], [64735.1, 0.026], [64736.7, 1.267], [64737.0, 0.0], [64737.3, 0.005], [64738.2, 0.026], [64739.8, 0.004], [64740.6, 6.004], [64742.0, 0.003], [64742.7, 0.0], [64743.8, 6.303], [64745.3, 0.078], [64746.0, 0.08], [64746.1, 0.352], [64746.4, 2.137], [64746.7, 1.467], [64746.9, 0.081], [64747.2, 1.4], [64748.1, 2.251], [64750.8, 0.029], [64751.1, 0.027], [64752.5, 0.001], [64752.9, 0.269], [64753.6, 1.565], [64754.5, 0.496], [64754.6, 0.381], [64754.7, 54.748], [64755.2, 0.315], [64756.4, 1.528], [64756.9, 0.0], [64758.0, 0.032], [64758.1, 2.79], [64760.0, 1.458], [64770.4, 0.042], [64770.7, 0.116], [64771.2, 0.477], [64772.5, 0.015], [64772.8, 12.073], [64774.4, 2.586], [64775.8, 0.629], [64775.9, 2.323], [64776.3, 0.0], [64777.9, 0.001], [64782.9, 0.028], [64790.6, 0.217], [64790.8, 0.007], [64793.8, 0.248], [64794.8, 0.0], [64797.9, 0.021], [64798.2, 0.096], [64798.3, 0.203], [64804.9, 2.438], [64815.4, 0.002], [64817.0, 0.241], [64817.7, 0.003], [64817.8, 0.002], [64819.9, 3.543], [64868.1, 0.967], [64869.4, 0.071], [64874.0, 0.0], [64875.1, 0.001], [64875.3, 2.507], [64875.8, 1.758], [64878.0, 0.072], [64880.1, 0.0], [64883.3, 0.002], [65006.3, 0.0], [65015.0, 0.157], [65322.2, 0.001], [65322.6, 0.058], [65322.8, 0.0], [65323.7, 0.001], [65324.2, 0.014], [65324.5, 0.019], [65324.9, 0.0], [65325.8, 5.167], [65393.7, 0.229], [65616.8, 21.993], [65669.3, 0.001], [65669.8, 0.002], [65669.9, 0.014], [65670.0, 0.826], [65670.2, 0.001], [65672.1, 0.0], [65675.4, 0.014], [65675.8, 0.008], [65676.0, 0.023], [65676.9, 0.007], [65677.4, 0.009], [65677.7, 0.022], [65678.1, 0.03]]}
{"kind": "depth", "E": 1787095201323, "U": 11316363096242, "u": 11316363117448, "recv_ms": 1787095201561, "bids": [[14175.3, 0.196], [14275.3, 0.294], [14278.9, 3.178], [14378.9, 0.28], [51740.0, 0.0], [58207.7, 0.002], [61441.5, 0.001], [61445.1, 0.008], [62088.2, 0.022], [62628.0, 1.348], [63057.0, 0.005], [63273.6, 0.3], [63678.0, 150.095], [63902.8, 33.287], [64028.5, 0.0], [64029.1, 0.0], [64030.5, 3.118], [64331.2, 0.121], [64498.3, 0.014], [64554.8, 0.107], [64555.3, 1.502], [64578.1, 10.006], [64596.0, 0.002], [64598.7, 3.608], [64599.0, 0.03], [64599.3, 0.017], [64600.7, 0.092], [64602.6, 0.001], [64603.1, 0.0], [64604.2, 0.002], [64605.3, 32.825], [64605.8, 0.001], [64612.2, 0.002], [64613.3, 0.093], [64627.3, 0.062], [64630.7, 0.015], [64630.8, 0.007], [64630.9, 0.025], [64631.3, 0.0], [64631.4, 0.184], [64634.4, 0.016], [64635.0, 0.086], [64635.2, 9.029], [64640.2, 0.0], [64643.2, 0.04], [64646.0, 0.78], [64646.6, 0.003], [64648.1, 0.186], [64649.4, 0.233], [64649.6, 0.063], [64649.9, 0.08], [64650.5, 0.003], [64650.7, 0.002], [64650.9, 0.002], [64651.0, 1.313], [64651.1, 0.125], [64651.4, 0.005], [64652.7, 0.003], [64654.5, 0.064], [64655.4, 0.271], [64655.9, 0.003], [64656.2, 0.061], [64657.2, 0.061], [64657.9, 0.868], [64658.2, 0.314], [64658.6, 0.773], [64658.8, 0.008], [64659.3, 0.399], [64659.8, 0.235], [64659.9, 1.0], [64660.4, 5.114], [64660.6, 0.292], [64661.3, 1.483], [64661.4, 0.459], [64661.5, 0.002], [64661.7, 0.004], [64663.0, 0.903], [64665.9, 1.362], [64666.0, 1.339], [64666.2, 0.008], [64666.6, 0.877], [64667.1, 0.766], [64667.2, 1.896], [64667.7, 0.711], [64667.8, 0.32], [64667.9, 0.017], [64668.0, 0.137], [64668.4, 0.086], [64668.8, 0.015], [64669.2, 0.527], [64669.3, 2.826], [64669.4, 0.088], [64669.6, 0.001], [64669.7, 0.09], [64669.8, 0.015], [64670.0, 0.005], [64670.1, 1.668], [64670.2, 0.301], [64670.3, 0.163], [64670.4, 0.01], [64670.6, 0.097], [64671.1, 0.006], [64671.5, 0.956], [64671.6, 1.638], [64672.0, 0.004], [64672.1, 0.045], [64672.2, 0.003], [64672.6, 0.008], [64672.7, 0.002], [64672.8, 0.002], [64673.0, 0.002], [64673.9, 0.0], [64674.0, 0.001], [64674.6, 0.002], [64675.1, 0.001], [64675.2, 0.002], [64675.3, 0.837]], "asks": [[64675.4, 36.984], [64675.5, 0.598], [64675.6, 0.001], [64675.7, 0.0], [64675.8, 1.394], [64675.9, 0.0], [64676.0, 1.126], [64676.1, 0.001], [64676.6, 0.001], [64676.7, 0.017], [64676.9, 0.42], [64677.4, 0.146], [64677.6, 0.002], [64677.7, 1.167], [64677.8, 0.004], [64677.9, 0.0], [64678.0, 2.504], [64678.1, 0.007], [64678.2, 1.126], [64678.6, 0.262], [64678.7, 0.004], [64678.8, 0.003], [64678.9, 4.865], [64679.0, 4.271], [64679.1, 1.401], [64679.7, 0.001], [64679.8, 0.113], [64680.0, 0.008], [64681.2, 0.123], [64682.0, 0.201], [64683.1, 0.117], [64683.2, 0.497], [64683.3, 0.678], [64683.4, 0.01], [64683.5, 0.05], [64684.2, 0.043], [64684.5, 0.271], [64684.6, 0.121], [64684.7, 0.249], [64684.9, 2.247], [64686.0, 0.126], [64686.4, 0.605], [64686.6, 0.001], [64686.7, 0.078], [64686.9, 0.159], [64687.0, 1.068], [64687.1, 0.043], [64687.2, 0.164], [64688.0, 4.076], [64689.3, 0.002], [64689.4, 0.002], [64689.5, 0.619], [64689.9, 0.0], [64690.0, 0.07], [64690.2, 0.347], [64690.3, 0.275], [64690.4, 0.003], [64690.5, 10.101], [64691.0, 0.053], [64692.0, 4.349], [64694.3, 0.195], [64694.8, 7.53], [64698.4, 0.276], [64698.8, 0.163], [64699.3, 9.778], [64701.2, 0.009], [64705.1, 1.887], [64705.4, 0.038], [64705.6, 1.383], [64707.7, 1.167], [64710.9, 0.018], [64714.2, 0.162], [64716.7, 0.0], [64717.3, 0.156], [64717.5, 0.001], [64717.9, 3.537], [64719.2, 1.916], [64725.8, 0.597], [64730.9, 0.092], [64733.4, 0.01], [64733.9, 0.074], [64734.5, 0.002], [64737.1, 54.755], [64741.5, 0.0], [64754.7, 0.0], [64772.2, 0.055], [64772.8, 12.065], [64871.7, 7.875], [64875.8, 0.008], [64880.2, 0.003], [64883.4, 0.306], [64886.6, 0.02], [64889.8, 0.001], [64998.7, 0.014], [65005.7, 0.695], [65322.2, 0.001], [65675.4, 0.026], [65678.1, 0.01], [65760.4, 1.821], [67912.9, 0.083], [69908.4, 0.008]]}
{"kind": "depth", "E": 1787095201425, "U": 11316363117571, "u": 11316363132136, "recv_ms": 1787095201567, "bids": [[1000.0, 35.76], [14175.3, 0.434], [14275.3, 0.406], [14278.9, 2.94], [14378.9, 0.168], [51740.0, 0.0], [51743.1, 0.0], [58207.7, 0.002], [61441.5, 0.0], [61982.3, 2.0], [63761.7, 0.783], [63761.8, 3.322], [63763.8, 23.638], [63834.5, 1.173], [64028.0, 0.677], [64028.5, 0.0], [64031.5, 0.003], [64553.0, 0.086], [64581.5, 0.001], [64611.9, 0.004], [64614.2, 0.351], [64617.2, 1.986], [64624.4, 0.347], [64631.2, 0.041], [64634.9, 0.062], [64635.2, 9.031], [64639.7, 2.473], [64645.5, 0.038], [64646.0, 0.768], [64646.1, 0.0], [64646.2, 0.007], [64649.4, 0.231], [64649.5, 0.04], [64649.6, 0.06], [64653.8, 0.401], [64655.4, 0.116], [64657.0, 2.359], [64657.1, 0.052], [64657.9, 0.311], [64658.2, 0.159], [64658.7, 0.001], [64660.3, 0.001], [64660.6, 0.137], [64661.5, 0.002], [64662.0, 1.343], [64663.0, 0.003], [64667.8, 0.01], [64667.9, 0.017], [64668.9, 0.011], [64669.6, 0.001], [64670.3, 0.008], [64670.4, 0.01], [64671.7, 0.063], [64672.0, 0.005], [64672.1, 0.043], [64672.5, 0.004], [64673.0, 0.001]], "asks": [[64675.4, 37.574], [64675.6, 0.0], [64676.0, 1.125], [64676.7, 0.017], [64677.6, 0.002], [64678.0, 2.504], [64678.1, 0.008], [64678.8, 0.158], [64679.0, 4.27], [64679.8, 0.133], [64680.0, 0.031], [64682.0, 0.356], [64683.3, 0.601], [64683.4, 0.003], [64683.5, 0.134], [64686.7, 0.07], [64686.9, 0.167], [64687.4, 0.251], [64690.4, 0.249], [64690.6, 0.083], [64694.3, 0.35], [64698.8, 0.318], [64715.5, 0.033], [64719.0, 0.002], [64732.8, 0.013], [64733.4, 0.0], [64737.1, 54.757], [64737.6, 1.265], [64743.7, 0.008], [64790.6, 0.117], [64793.4, 0.066], [64889.8, 0.0], [65002.4, 3.999], [65322.2, 0.003], [65390.5, 3.202], [65421.7, 0.909], [65423.4, 7.264]]}
{"kind": "depth", "E": 1787095201527, "U": 11316363132235, "u": 11316363144350, "recv_ms": 1787095201598, "bids": [[1000.0, 35.76], [14175.3, 0.672], [14275.3, 0.532], [14278.9, 2.702], [14378.9, 0.042], [58207.7, 0.002], [61336.7, 3.012], [61441.5, 0.0], [62088.2, 0.019], [63465.9, 0.958], [63675.3, 0.021], [63769.8, 2.349], [63899.2, 3.067], [64028.5, 0.0], [64351.9, 0.001], [64355.5, 5.877], [64360.4, 0.077], [64520.4, 0.0], [64520.7, 0.001], [64521.3, 0.004], [64522.1, 0.077], [64522.7, 0.016], [64570.3, 0.0], [64570.4, 0.0], [64570.6, 0.197], [64572.2, 0.077], [64581.6, 0.134], [64581.9, 0.2], [64605.3, 32.825], [64605.8, 0.289], [64607.4, 0.174], [64631.3, 0.0], [64645.2, 0.08], [64655.4, 0.116], [64658.2, 0.159], [64659.1, 0.009], [64659.8, 0.003], [64660.5, 1.888], [64660.6, 0.596], [64660.7, 0.25], [64661.4, 0.0], [64663.3, 0.0], [64664.6, 0.003], [64667.0, 1.323], [64667.8, 0.01], [64669.6, 0.001], [64670.2, 0.301], [64670.3, 0.008], [64670.4, 0.048], [64670.5, 0.005], [64671.0, 0.085], [64672.7, 0.002], [64674.6, 0.004], [64675.3, 0.838]], "asks": [[64675.4, 36.27], [64675.5, 1.533], [64676.7, 0.109], [64677.6, 0.002], [64678.1, 0.008], [64678.8, 0.158], [64679.8, 0.133], [64682.0, 0.356], [64683.5, 0.042], [64687.4, 0.251], [64690.4, 0.249], [64694.3, 0.35], [64698.8, 0.318], [64709.7, 0.421], [64711.0, 0.5], [64751.5, 0.073], [64767.5, 0.104], [64871.7, 6.946], [64874.6, 0.021], [65322.2, 0.001], [65421.7, 1.817], [65423.4, 6.356], [65520.4, 0.013], [65675.4, 0.046], [65765.6, 1.212]]}
{"kind": "depth", "E": 1787095201629, "U": 11316363144635, "u": 11316363167436, "recv_ms": 1787095201704, "bids": [[14173.5, 0.21], [14173.6, 0.014], [14175.3, 0.756], [14275.3, 0.574], [14278.9, 2.394], [14378.9, 0.0], [58206.1, 0.002], [58207.7, 0.0], [59737.1, 0.0], [59898.5, 0.0], [60691.0, 4.0], [61441.5, 0.0], [62088.2, 0.022], [64020.1, 0.0], [64026.8, 0.24], [64026.9, 0.002], [64027.9, 0.0], [64028.5, 0.0], [64096.9, 1.216], [64100.0, 69.945], [64257.1, 0.011], [64260.3, 0.005], [64360.5, 0.014], [64361.3, 0.001], [64361.5, 0.179], [64361.6, 0.055], [64361.7, 0.0], [64385.3, 0.0], [64406.7, 0.296], [64417.8, 0.005], [64420.9, 0.025], [64481.3, 0.012], [64497.5, 0.001], [64500.7, 0.807], [64521.5, 2.492], [64521.6, 0.04], [64522.1, 0.0], [64537.2, 0.001], [64551.6, 0.071], [64551.7, 0.491], [64553.0, 0.016], [64553.6, 4.105], [64554.1, 0.0], [64554.2, 1.472], [64554.8, 0.015], [64561.8, 0.002], [64563.7, 0.004], [64570.6, 0.12], [64572.2, 0.0], [64576.1, 0.673], [64577.0, 0.026], [64577.4, 0.394], [64578.2, 0.0], [64578.8, 0.016], [64581.4, 2.515], [64581.5, 0.232], [64582.0, 0.025], [64583.0, 0.154], [64596.3, 0.021], [64597.8, 0.027], [64600.7, 0.091], [64600.9, 0.014], [64602.4, 0.184], [64602.5, 0.072], [64603.0, 0.002], [64605.3, 32.825], [64605.8, 0.155], [64606.9, 0.016], [64607.4, 0.174], [64609.7, 0.201], [64610.0, 0.188], [64610.4, 6.009], [64612.1, 0.002], [64614.2, 0.352], [64621.8, 0.082], [64622.6, 0.379], [64623.8, 0.007], [64627.2, 0.019], [64629.5, 0.015], [64630.6, 0.012], [64630.7, 0.03], [64632.4, 0.0], [64633.3, 0.042], [64633.6, 0.671], [64633.8, 0.003], [64634.6, 0.26], [64634.7, 1.371], [64635.4, 0.002], [64636.7, 2.344], [64637.6, 0.015], [64638.5, 0.002], [64639.0, 0.127], [64639.7, 2.319], [64640.0, 3.714], [64641.0, 0.002], [64641.1, 0.061], [64641.4, 0.164], [64642.3, 2.39], [64642.7, 0.002], [64643.6, 0.0], [64643.9, 0.437], [64644.5, 0.003], [64644.9, 0.011], [64645.5, 0.028], [64645.8, 0.202], [64646.0, 0.762], [64646.6, 0.006], [64646.9, 0.014], [64647.0, 3.266], [64647.5, 0.023], [64648.3, 0.008], [64648.8, 0.085], [64648.9, 0.175], [64649.0, 0.326], [64649.4, 0.231], [64649.6, 0.06], [64650.0, 3.378], [64650.1, 0.196], [64650.4, 0.009], [64650.5, 0.003], [64651.3, 0.004], [64651.4, 0.003], [64651.5, 0.116], [64651.6, 0.01], [64652.2, 0.003], [64652.8, 0.022], [64653.0, 0.033], [64653.4, 0.017], [64653.5, 0.051], [64653.6, 0.083], [64653.8, 0.958], [64654.2, 0.008], [64654.5, 0.065], [64655.2, 3.149], [64655.3, 1.942], [64655.4, 0.283], [64655.9, 0.002], [64656.5, 0.589], [64657.0, 1.802], [64657.7, 0.459], [64658.0, 0.011], [64658.2, 0.0], [64658.6, 0.985], [64658.8, 0.008], [64659.2, 0.242], [64659.3, 0.392], [64659.8, 1.003], [64659.9, 0.0], [64660.0, 0.906], [64660.4, 4.903], [64660.5, 1.237], [64660.6, 2.123], [64660.7, 0.25], [64660.9, 0.348], [64661.4, 0.024], [64661.5, 0.002], [64662.0, 0.443], [64662.6, 0.001], [64664.3, 0.015], [64664.4, 0.163], [64664.9, 0.603], [64665.3, 0.123], [64665.5, 0.002], [64665.6, 0.183], [64665.7, 0.001], [64665.9, 0.412], [64666.0, 1.246], [64666.2, 0.008], [64666.3, 0.0], [64666.4, 0.004], [64666.5, 0.003], [64666.6, 0.881], [64666.7, 0.659], [64666.9, 0.397], [64667.0, 1.422], [64667.1, 0.225], [64667.2, 1.606], [64667.3, 0.254], [64667.4, 0.109], [64667.6, 0.121], [64667.7, 0.164], [64667.8, 1.548], [64667.9, 0.025], [64668.0, 0.137], [64668.4, 0.088], [64668.8, 0.099], [64668.9, 0.005], [64669.0, 0.032], [64669.1, 0.012], [64669.2, 0.423], [64669.4, 0.066], [64669.5, 0.184], [64669.6, 0.093], [64669.7, 0.001], [64669.9, 0.153], [64670.1, 0.001], [64670.2, 0.217], [64670.3, 0.002], [64670.4, 0.003], [64670.6, 0.015], [64670.7, 0.0], [64670.8, 0.004], [64671.0, 0.001], [64671.1, 0.002], [64671.2, 0.012], [64671.3, 0.002], [64671.4, 0.0], [64671.5, 0.716], [64671.6, 0.002], [64671.7, 0.002], [64671.9, 0.001], [64672.0, 0.004], [64672.1, 0.034], [64672.2, 0.0], [64672.4, 0.0], [64672.5, 0.002], [64672.6, 0.001], [64672.8, 0.0], [64672.9, 0.0], [64673.0, 0.0], [64673.1, 0.0], [64673.3, 0.001], [64673.4, 0.003], [64673.5, 2.484], [64673.6, 0.0], [64673.7, 0.0], [64674.0, 0.0], [64674.1, 0.0], [64674.2, 0.0], [64674.3, 0.0], [64674.4, 0.0], [64674.6, 0.0], [64674.9, 0.0], [64675.0, 0.0], [64675.1, 0.0], [64675.2, 0.0], [64675.3, 0.0]], "asks": [[64673.6, 39.767], [64673.7, 8.133], [64673.8, 0.002], [64674.1, 0.0], [64674.2, 0.0], [64674.3, 0.0], [64674.4, 0.001], [64674.5, 0.0], [64674.6, 0.0], [64674.7, 1.128], [64674.8, 0.001], [64675.0, 0.001], [64675.1, 0.001], [64675.2, 0.018], [64675.3, 3.26], [64675.4, 1.67], [64675.5, 0.001], [64675.7, 0.007], [64675.8, 1.392], [64676.0, 1.126], [64676.4, 0.001], [64676.6, 0.001], [64676.7, 0.003], [64676.8, 2.502], [64677.6, 0.003], [64677.7, 0.167], [64677.8, 0.003], [64677.9, 0.0], [64678.1, 0.007], [64678.2, 0.126], [64678.3, 0.0], [64678.4, 0.01], [64678.6, 0.26], [64678.7, 0.004], [64678.8, 1.695], [64678.9, 0.419], [64679.0, 4.509], [64679.1, 1.407], [64679.5, 0.001], [64681.1, 0.001], [64681.2, 0.428], [64681.4, 1.16], [64681.5, 0.015], [64682.0, 0.835], [64682.1, 1.283], [64682.2, 2.322], [64682.4, 0.001], [64682.7, 0.001], [64682.8, 0.268], [64683.1, 0.116], [64683.2, 0.192], [64683.3, 0.06], [64683.4, 0.018], [64683.5, 0.041], [64683.6, 0.425], [64683.8, 0.045], [64683.9, 0.003], [64684.1, 0.008], [64684.7, 0.249], [64684.8, 2.633], [64685.5, 0.071], [64685.9, 0.105], [64686.0, 1.023], [64686.4, 0.57], [64686.5, 0.006], [64686.6, 0.075], [64686.7, 0.002], [64686.9, 0.194], [64687.0, 0.168], [64687.1, 0.028], [64687.3, 0.409], [64687.4, 0.096], [64687.6, 2.323], [64687.9, 1.349], [64688.3, 0.0], [64688.9, 0.002], [64689.1, 1.299], [64689.3, 0.004], [64689.4, 0.002], [64690.2, 0.347], [64690.3, 0.064], [64690.4, 0.094], [64690.6, 0.081], [64690.9, 0.004], [64691.2, 0.057], [64691.7, 0.0], [64691.9, 0.4], [64692.7, 0.461], [64693.2, 0.002], [64693.5, 0.263], [64693.9, 0.004], [64694.1, 1.319], [64694.3, 0.198], [64694.6, 0.287], [64694.8, 7.529], [64695.4, 0.747], [64695.5, 0.558], [64695.6, 0.08], [64696.2, 0.464], [64696.9, 0.001], [64697.3, 1.705], [64697.6, 0.049], [64698.2, 0.167], [64698.3, 0.0], [64698.5, 0.003], [64698.8, 0.163], [64699.0, 0.122], [64699.6, 0.371], [64699.7, 0.0], [64700.8, 1.241], [64700.9, 1.718], [64701.0, 0.483], [64701.2, 0.009], [64701.3, 0.05], [64701.6, 0.031], [64702.9, 0.702], [64703.3, 0.091], [64703.9, 0.167], [64704.5, 0.036], [64704.8, 0.125], [64705.0, 0.001], [64705.6, 1.4], [64708.8, 1.373], [64709.6, 0.001], [64710.9, 0.018], [64711.2, 1.27], [64712.5, 0.017], [64713.5, 0.038], [64716.0, 0.009], [64716.5, 0.396], [64717.3, 0.0], [64721.3, 0.001], [64721.4, 2.786], [64721.8, 0.026], [64723.4, 25.019], [64723.6, 0.025], [64724.1, 0.041], [64724.7, 0.045], [64725.4, 0.0], [64725.7, 0.002], [64726.4, 4.256], [64732.2, 0.027], [64732.8, 0.003], [64733.7, 0.011], [64737.1, 54.757], [64738.2, 0.0], [64738.3, 0.031], [64739.7, 0.036], [64740.0, 2.468], [64740.4, 0.002], [64742.1, 0.003], [64743.7, 0.008], [64746.7, 0.0], [64746.8, 1.467], [64752.5, 0.001], [64754.7, 0.0], [64756.0, 1.323], [64757.3, 0.001], [64771.2, 0.485], [64772.2, 0.047], [64772.7, 0.041], [64775.9, 2.321], [64812.2, 0.005], [64812.8, 1.0], [64868.1, 0.964], [64868.5, 0.128], [64871.7, 8.085], [64874.4, 0.001], [64878.4, 11.997], [64934.6, 0.032], [64937.8, 0.0], [65097.0, 0.059], [65100.2, 0.007], [65259.7, 0.573], [65262.9, 0.001], [65320.3, 0.002], [65321.4, 0.01], [65322.2, 0.001], [65419.8, 1.816], [65421.7, 0.001], [65584.5, 32.831], [65587.6, 1.843], [65669.8, 0.0], [65673.7, 0.019], [65675.4, 0.052], [65676.0, 0.019], [65676.9, 0.005], [65677.4, 0.003], [65677.7, 0.02], [65678.1, 0.004], [65882.0, 0.84]]}
{"kind": "depth", "E": 1787095201731, "U": 11316363167536, "u": 11316363178945, "recv_ms": 1787095201801, "bids": [[1000.0, 35.76], [14173.5, 0.574], [14278.9, 2.03], [58206.1, 0.002], [61439.8, 0.002], [62088.2, 0.019], [63675.3, 0.001], [63768.2, 2.364], [63865.2, 0.486], [64026.8, 0.24], [64059.9, 0.2], [64497.5, 0.0], [64521.5, 2.338], [64521.6, 0.002], [64536.6, 1.163], [64581.4, 2.323], [64581.5, 0.001], [64583.0, 0.0], [64594.0, 0.001], [64597.2, 0.053], [64599.0, 0.0], [64602.4, 0.1], [64602.5, 0.034], [64603.0, 32.582], [64604.0, 0.244], [64605.3, 0.186], [64605.6, 0.097], [64605.7, 0.001], [64605.8, 0.001], [64607.4, 0.174], [64610.8, 1.957], [64612.1, 0.079], [64613.7, 1.11], [64614.5, 0.004], [64617.3, 5.596], [64623.7, 0.967], [64625.5, 0.065], [64627.3, 0.001], [64630.2, 0.97], [64632.4, 0.001], [64633.0, 0.036], [64639.0, 0.281], [64644.2, 0.01], [64644.9, 0.001], [64649.3, 2.191], [64650.1, 0.196], [64650.2, 0.355], [64650.4, 0.007], [64650.7, 0.002], [64650.8, 0.16], [64651.1, 0.127], [64654.1, 0.002], [64654.2, 0.009], [64655.4, 0.283], [64655.5, 0.351], [64655.9, 0.001], [64657.1, 0.054], [64658.3, 0.622], [64659.1, 0.009], [64660.6, 1.575], [64660.7, 0.443], [64660.8, 0.159], [64661.4, 0.179], [64661.5, 0.157], [64662.5, 0.001], [64665.7, 0.619], [64665.9, 0.132], [64666.5, 0.004], [64666.9, 0.396], [64667.1, 0.773], [64667.9, 0.025], [64668.0, 0.447], [64668.5, 0.001], [64669.1, 0.015], [64669.4, 0.066], [64669.5, 0.486], [64669.6, 0.101], [64670.0, 0.089], [64670.3, 0.009], [64670.4, 0.041], [64670.6, 0.015], [64670.8, 0.005], [64671.3, 0.001], [64671.6, 0.248], [64672.0, 0.005], [64673.5, 2.488]], "asks": [[64673.6, 36.565], [64673.7, 7.373], [64674.5, 0.015], [64674.7, 1.005], [64675.2, 0.002], [64675.3, 2.5], [64675.4, 1.584], [64676.3, 0.001], [64676.8, 2.502], [64678.1, 0.006], [64678.7, 0.012], [64679.0, 4.469], [64679.8, 0.113], [64680.0, 0.008], [64681.1, 0.009], [64682.0, 0.827], [64683.0, 0.019], [64683.5, 0.052], [64684.1, 0.0], [64684.5, 0.279], [64684.7, 0.241], [64686.3, 0.0], [64686.5, 0.014], [64687.3, 0.398], [64687.6, 2.323], [64688.0, 2.643], [64688.5, 0.213], [64689.3, 0.002], [64689.6, 0.02], [64689.8, 0.033], [64689.9, 0.002], [64690.5, 0.099], [64692.0, 4.351], [64693.0, 0.004], [64694.3, 4.043], [64695.0, 0.024], [64695.2, 0.098], [64696.2, 0.463], [64698.8, 0.008], [64702.4, 1.23], [64702.5, 0.142], [64702.6, 0.006], [64703.9, 0.153], [64705.4, 0.04], [64705.5, 0.009], [64705.6, 1.402], [64706.4, 0.019], [64706.5, 0.003], [64706.6, 0.014], [64708.5, 0.002], [64708.6, 0.008], [64708.7, 0.01], [64712.4, 0.422], [64713.8, 0.031], [64714.9, 0.003], [64715.5, 0.002], [64716.1, 0.486], [64716.4, 0.388], [64716.5, 0.24], [64729.2, 0.073], [64730.9, 0.031], [64731.6, 0.018], [64732.0, 0.005], [64732.2, 0.017], [64733.7, 0.007], [64736.7, 9.152], [64763.9, 0.011], [64871.0, 10.587], [64871.7, 1.261], [64874.6, 0.021], [64874.9, 0.442], [64883.4, 0.305], [64886.6, 0.019], [65320.3, 0.0], [65419.8, 2.724], [65423.5, 5.495], [65616.8, 23.058], [65675.4, 0.032], [71141.0, 0.015]]}
{"kind": "depth", "E": 1787095201833, "U": 11316363179002, "u": 11316363187034, "recv_ms": 1787095201903, "bids": [[1000.0, 35.76], [14173.5, 0.938], [14278.9, 1.666], [51739.0, 0.0], [58206.1, 0.002], [61439.8, 0.002], [62086.5, 0.005], [63741.1, 23.441], [64026.1, 0.39], [64026.8, 0.24], [64028.0, 0.29], [64351.9, 0.011], [64355.5, 5.867], [64360.4, 0.0], [64360.9, 0.001], [64361.0, 0.604], [64361.1, 0.0], [64361.5, 0.16], [64521.5, 2.319], [64551.6, 0.001], [64602.4, 0.004], [64604.0, 0.333], [64604.1, 0.001], [64605.6, 0.001], [64610.2, 0.015], [64612.1, 0.002], [64639.6, 2.002], [64650.2, 0.045], [64655.5, 0.044], [64657.1, 0.051], [64657.7, 0.0], [64659.8, 0.003], [64660.4, 4.905], [64660.7, 0.288], [64660.8, 0.004], [64660.9, 1.348], [64661.0, 0.459], [64661.4, 0.572], [64661.5, 0.002], [64661.7, 0.002], [64663.0, 0.903], [64666.6, 0.797], [64667.1, 0.225], [64667.9, 0.025], [64668.0, 0.137], [64668.6, 0.001], [64669.4, 1.582], [64669.5, 0.176], [64669.6, 0.101], [64670.3, 0.086], [64670.4, 0.041], [64670.5, 0.089], [64672.3, 0.002], [64673.0, 0.002], [64673.5, 3.789]], "asks": [[64673.6, 36.542], [64673.7, 1.938], [64674.7, 1.0], [64675.2, 0.01], [64675.4, 1.182], [64676.8, 2.503], [64678.6, 0.383], [64678.7, 0.004], [64679.0, 4.457], [64680.0, 0.027], [64680.1, 0.004], [64680.2, 0.107], [64681.1, 0.001], [64681.7, 0.016], [64682.0, 0.286], [64682.5, 0.097], [64683.0, 0.011], [64683.5, 0.06], [64683.6, 0.966], [64684.7, 0.241], [64686.5, 0.006], [64686.6, 0.083], [64686.9, 0.228], [64687.8, 0.001], [64689.9, 0.0], [64690.1, 0.006], [64690.3, 0.066], [64692.1, 0.029], [64692.2, 0.001], [64692.7, 0.002], [64693.8, 0.462], [64695.4, 0.631], [64695.5, 0.002], [64695.6, 0.171], [64697.3, 1.821], [64697.4, 0.558], [64697.6, 0.139], [64699.5, 0.145], [64700.9, 1.687], [64704.8, 0.035], [64706.2, 0.001], [64706.3, 0.029], [64708.1, 0.003], [64713.5, 0.013], [64734.9, 54.967], [64737.1, 0.009], [64745.6, 2.878], [64746.0, 0.041], [64793.4, 0.0], [64831.1, 10.413], [64832.1, 2.307], [64832.2, 0.011], [64833.5, 0.0], [64836.0, 0.861], [64836.4, 0.001], [64869.9, 6.627], [64871.0, 0.391], [64948.8, 0.001], [65031.0, 0.005], [65032.0, 1.61], [65264.6, 0.002], [65320.3, 0.0], [65419.7, 0.908], [65423.4, 5.448], [65484.4, 1.512], [65488.0, 12.023], [65488.1, 0.763], [65522.8, 1.067], [66296.0, 2.561], [70069.8, 0.006]]}
{"kind": "depth", "E": 1787095201935, "U": 11316363187128, "u": 11316363193129, "recv_ms": 1787095202003, "bids": [[14173.5, 1.288], [14278.9, 1.316], [58206.1, 0.002], [61439.8, 0.003], [63673.5, 0.028], [64026.8, 0.24], [64315.2, 1.277], [64338.2, 0.0], [64603.0, 0.002], [64604.0, 0.025], [64605.3, 32.766], [64635.2, 1.031], [64650.1, 0.196], [64655.4, 0.283], [64659.0, 0.006], [64661.4, 0.024], [64667.2, 2.154], [64667.9, 0.025], [64669.5, 0.176], [64669.6, 0.093], [64670.3, 0.471], [64670.4, 0.049], [64670.8, 0.005], [64671.7, 0.001], [64672.1, 0.035], [64673.5, 3.9]], "asks": [[64673.6, 36.547], [64673.7, 1.94], [64673.8, 0.008], [64675.4, 1.181], [64675.7, 0.011], [64677.0, 0.009], [64677.6, 0.002], [64679.7, 0.001], [64704.3, 0.081], [64705.1, 0.002], [64716.1, 0.492], [64723.6, 0.021], [64736.7, 1.267], [64745.6, 2.839], [64746.0, 0.08], [64832.1, 0.021], [64878.4, 8.898], [65306.7, 0.0], [65320.3, 0.0], [65419.7, 1.816], [65423.5, 4.579], [65477.7, 13.222], [65673.6, 0.02]]}
{"kind": "depth", "E": 1787095202037, "U": 11316363193205, "u": 11316363202554, "recv_ms": 1787095202107, "bids": [[1000.0, 35.76], [14173.5, 1.638], [14278.9, 0.966], [58206.1, 0.002], [61439.8, 0.002], [62086.5, 0.002], [64022.9, 0.0], [64026.8, 0.24], [64091.4, 16.275], [64096.9, 0.982], [64553.2, 0.013], [64558.6, 0.0], [64560.3, 0.018], [64565.7, 0.0], [64567.3, 0.04], [64572.7, 0.027], [64574.4, 2.412], [64579.8, 0.002], [64581.4, 2.336], [64586.8, 0.051], [64588.5, 1.118], [64593.9, 0.055], [64595.5, 0.013], [64600.9, 0.001], [64602.6, 0.014], [64605.6, 0.097], [64608.0, 0.11], [64641.1, 0.004], [64643.2, 0.05], [64643.7, 0.013], [64644.0, 0.452], [64644.2, 0.0], [64650.1, 0.196], [64655.4, 0.283], [64659.0, 0.006], [64660.5, 1.696], [64661.0, 0.0], [64661.4, 0.024], [64661.9, 0.008], [64666.5, 0.003], [64666.7, 0.118], [64667.1, 0.226], [64667.9, 0.566], [64669.5, 0.176], [64670.3, 0.317], [64672.6, 0.003]], "asks": [[64675.4, 1.16], [64679.7, 0.001], [64682.0, 0.279], [64683.5, 0.067], [64693.0, 0.463], [64693.8, 0.003], [64705.2, 1.916], [64730.5, 0.644], [64731.0, 0.007], [64731.6, 0.008], [65262.3, 0.23], [65264.3, 0.012], [65320.3, 0.002], [65477.7, 12.994]]}
{"kind": "depth", "E": 1787095202139, "U": 11316363202579, "u": 11316363220876, "recv_ms": 1787095202213, "bids": [[14173.5, 2.002], [14278.9, 0.602], [51739.0, 0.0], [51743.0, 0.0], [58206.1, 0.002], [61439.8, 0.002], [62086.5, 0.005], [63385.4, 0.951], [63673.5, 0.008], [63735.7, 1.097], [64026.8, 0.24], [64350.1, 0.01], [64351.9, 0.001], [64355.5, 5.866], [64361.5, 0.237], [64521.5, 2.338], [64563.7, 0.001], [64598.8, 1.572], [64598.9, 0.0], [64601.2, 0.528], [64605.6, 0.097], [64605.7, 0.001], [64606.0, 0.002], [64606.1, 0.0], [64624.5, 0.015], [64628.4, 0.032], [64630.1, 0.002], [64631.2, 0.001], [64633.6, 0.668], [64635.1, 0.39], [64635.2, 1.028], [64636.8, 9.757], [64639.6, 0.002], [64643.3, 0.045], [64643.6, 0.057], [64643.9, 0.439], [64644.0, 0.395], [64650.1, 0.196], [64655.4, 0.283], [64656.0, 0.133], [64658.3, 0.004], [64660.2, 0.658], [64660.5, 1.237], [64660.7, 0.286], [64661.4, 0.024], [64661.9, 0.003], [64662.0, 0.441], [64665.7, 0.001], [64666.9, 0.396], [64667.1, 0.226], [64667.3, 0.795], [64667.9, 0.025], [64669.4, 1.52], [64669.5, 0.239], [64669.6, 0.093], [64670.3, 0.394], [64670.4, 0.049], [64670.5, 0.005], [64670.6, 0.015], [64672.7, 0.0], [64673.5, 2.6]], "asks": [[64673.6, 36.607], [64675.1, 0.311], [64675.7, 0.001], [64675.9, 0.001], [64676.8, 2.503], [64677.0, 0.005], [64677.8, 0.157], [64678.2, 0.128], [64683.2, 0.038], [64688.4, 0.198], [64692.8, 0.772], [64708.4, 0.388], [64716.1, 0.488], [64733.7, 0.007], [64755.8, 0.247], [64756.7, 0.046], [64767.5, 0.064], [64997.0, 0.201], [65257.4, 0.23], [65320.3, 0.002], [65419.8, 3.632], [65423.4, 4.54], [65581.4, 0.001], [65673.6, 0.0], [67912.9, 0.078]]}
{"kind": "depth", "E": 1787095202241, "U": 11316363220997, "u": 11316363231395, "recv_ms": 1787095202313, "bids": [[14173.5, 2.352], [14278.9, 0.252], [51739.0, 0.0], [58206.1, 0.002], [61439.8, 0.002], [62086.5, 0.002], [63741.1, 22.344], [63838.2, 4.562], [63865.1, 0.235], [63909.2, 8.444], [64026.8, 0.24], [64521.5, 2.569], [64581.4, 2.374], [64593.5, 0.003], [64600.7, 0.092], [64605.6, 0.335], [64605.7, 0.039], [64615.8, 0.0], [64617.5, 0.004], [64619.8, 0.0], [64624.0, 2.327], [64624.7, 0.004], [64627.9, 0.467], [64629.7, 0.08], [64629.8, 0.037], [64642.9, 2.051], [64643.2, 0.04], [64650.1, 0.506], [64651.0, 1.345], [64651.5, 0.0], [64652.0, 0.107], [64653.6, 0.199], [64653.8, 0.401], [64655.4, 0.593], [64656.2, 0.618], [64659.0, 0.006], [64659.1, 0.002], [64659.2, 0.01], [64659.5, 0.461], [64660.1, 0.246], [64660.2, 0.199], [64660.3, 0.008], [64660.7, 0.248], [64660.8, 0.004], [64661.4, 0.644], [64666.4, 0.001], [64666.9, 0.396], [64667.0, 1.422], [64667.1, 0.226], [64667.3, 1.108], [64667.4, 0.109], [64667.8, 0.002], [64667.9, 0.017], [64668.0, 0.137], [64668.1, 0.086], [64668.2, 1.559], [64669.5, 0.549], [64669.6, 0.101], [64670.3, 0.002], [64670.4, 0.003], [64670.7, 0.0], [64672.2, 0.001], [64673.5, 3.382]], "asks": [[64673.6, 36.611], [64673.7, 1.942], [64673.8, 0.01], [64674.8, 0.003], [64675.1, 0.001], [64675.7, 0.001], [64676.8, 2.503], [64676.9, 0.419], [64677.2, 0.056], [64677.4, 0.145], [64678.1, 0.001], [64679.1, 1.405], [64679.2, 0.001], [64679.4, 0.394], [64679.7, 0.001], [64682.0, 0.202], [64683.5, 0.144], [64686.5, 0.01], [64686.9, 0.073], [64689.5, 0.001], [64690.2, 0.965], [64690.3, 0.062], [64692.0, 4.81], [64693.0, 0.004], [64697.0, 0.027], [64698.7, 0.009], [64700.6, 0.005], [64700.8, 1.237], [64714.7, 0.029], [64718.1, 0.005], [64722.6, 0.101], [64730.2, 4.314], [64730.5, 0.634], [65032.8, 0.795], [65320.3, 0.0], [65477.7, 12.736], [65484.5, 1.512], [65488.0, 11.267], [65488.1, 0.001], [65572.8, 0.0]]}
{"kind": "depth", "E": 1787095202343, "U": 11316363231459, "u": 11316363240294, "recv_ms": 1787095202413, "bids": [[1000.0, 35.76], [14173.5, 2.716], [14276.8, 0.07], [14277.3, 0.0], [14277.6, 0.0], [14278.0, 0.0], [14278.1, 0.0], [14278.9, 0.0], [51739.0, 0.0], [51743.0, 0.0], [58206.1, 0.002], [61439.8, 0.005], [61445.1, 0.006], [62086.5, 0.005], [63673.5, 0.028], [63708.6, 1.567], [63885.9, 0.783], [63893.2, 26.36], [64026.6, 0.548], [64026.8, 0.24], [64551.2, 0.067], [64616.4, 0.002], [64643.0, 0.057], [64643.6, 0.0], [64650.1, 0.506], [64650.2, 0.045], [64651.6, 0.042], [64655.4, 0.593], [64655.5, 0.044], [64659.5, 0.002], [64660.7, 0.707], [64661.4, 0.644], [64661.5, 0.002], [64667.0, 1.338], [64667.1, 0.226], [64667.3, 0.798], [64667.4, 0.419], [64667.5, 0.185], [64668.2, 0.005], [64668.3, 0.033], [64668.4, 0.088], [64668.5, 0.009], [64668.6, 1.547], [64669.5, 0.549], [64669.6, 0.101], [64670.3, 0.002], [64670.4, 0.125], [64670.9, 0.084], [64671.7, 0.003], [64673.5, 4.682]], "asks": [[64673.6, 35.975], [64673.8, 0.011], [64675.7, 0.001], [64677.0, 0.005], [64683.6, 0.425], [64683.9, 0.544], [64686.2, 0.003], [64686.6, 0.075], [64687.1, 0.036], [64687.2, 0.171], [64687.4, 0.098], [64692.0, 4.351], [64693.1, 0.46], [64716.1, 0.492], [64722.6, 0.097], [64792.2, 0.096], [65063.2, 0.012], [65320.3, 0.0], [65419.7, 3.632], [65423.4, 3.632], [65423.5, 3.663], [65673.6, 0.02]]}
{"kind": "depth", "E": 1787095202445, "U": 11316363240480, "u": 11316363247700, "recv_ms": 1787095202515, "bids": [[14173.5, 3.01], [14175.3, 0.7], [14275.3, 0.42], [14275.7, 0.0], [14275.9, 0.0], [14276.8, 0.0], [14573.5, 0.056], [51738.8, 0.0], [58206.1, 0.002], [61439.8, 0.005], [63394.8, 0.0], [63832.7, 0.861], [63860.8, 11.242], [64026.6, 1.094], [64026.8, 0.24], [64096.9, 0.748], [64350.1, 0.0], [64583.0, 0.019], [64605.3, 0.186], [64607.4, 32.754], [64612.1, 0.24], [64612.2, 0.04], [64638.7, 0.118], [64642.6, 0.066], [64642.9, 2.041], [64650.1, 0.196], [64650.2, 0.045], [64650.7, 0.034], [64655.4, 0.283], [64655.5, 0.044], [64660.2, 0.658], [64660.7, 0.248], [64661.4, 0.024], [64661.5, 0.002], [64664.0, 0.218], [64665.6, 0.393], [64667.2, 1.844], [64667.4, 0.109], [64667.5, 0.726], [64667.6, 1.675], [64667.7, 0.164], [64668.5, 0.001], [64668.6, 0.001], [64668.7, 0.034], [64669.5, 0.239], [64669.6, 0.101], [64670.3, 0.002], [64670.4, 0.087], [64670.9, 0.0], [64673.5, 3.383]], "asks": [[64673.6, 35.978], [64675.2, 0.01], [64675.7, 0.001], [64677.0, 0.005], [64677.3, 0.391], [64677.8, 0.312], [64678.7, 0.159], [64684.0, 1.326], [64684.7, 0.396], [64684.9, 1.724], [64686.0, 0.123], [64689.9, 0.018], [64691.0, 0.208], [64694.0, 0.156], [64694.2, 0.16], [64729.9, 3.145], [64730.2, 4.304], [65261.2, 7.791], [65320.3, 0.0], [65378.8, 10.828], [65393.7, 0.0], [65419.7, 4.54], [65423.4, 2.724], [65484.4, 2.268], [65488.0, 10.511], [65578.0, 11.659], [70231.3, 0.002]]}
{"kind": "depth", "E": 1787095202547, "U": 11316363247800, "u": 11316363257171, "recv_ms": 1787095202616, "bids": [[14173.5, 3.178], [14175.3, 0.504], [14275.3, 0.252], [14573.5, 0.252], [58206.1, 0.002], [61439.8, 0.004], [62086.5, 0.002], [63735.7, 2.194], [63860.8, 10.977], [63903.9, 0.938], [64026.8, 0.24], [64056.9, 9.039], [64351.9, 0.0], [64605.6, 0.328], [64605.7, 0.001], [64658.0, 0.011], [64670.3, 0.002], [64670.4, 0.125]], "asks": [[64675.7, 0.011], [64678.7, 0.159], [64712.5, 0.097], [64869.9, 6.584], [64997.0, 0.202], [65307.7, 3.432], [65320.3, 0.0], [65419.7, 6.356], [65423.4, 0.908], [65484.4, 3.024], [65488.0, 9.755], [65888.5, 3.139], [65964.8, 4.239]]}
{"kind": "depth", "E": 1787095202649, "U": 11316363257411, "u": 11316363266213, "recv_ms": 1787095202718, "bids": [[1000.0, 35.76], [14173.5, 3.29], [14175.3, 0.266], [14275.3, 0.14], [14573.5, 0.49], [58206.1, 0.002], [62086.5, 0.005], [63673.5, 0.008], [63702.3, 0.275], [63750.9, 2.342], [63853.5, 0.903], [64026.8, 0.24], [64091.4, 16.509], [64521.5, 2.576], [64521.6, 0.04], [64536.3, 0.001], [64536.6, 0.464], [64583.0, 0.257], [64605.6, 0.232], [64616.8, 0.0], [64638.8, 0.155], [64639.0, 0.127], [64642.3, 2.4], [64642.6, 0.056], [64650.1, 0.506], [64650.5, 0.018], [64655.4, 0.593], [64659.7, 1.001], [64660.7, 0.558], [64660.9, 0.348], [64661.4, 0.334], [64666.9, 0.397], [64667.1, 0.225], [64667.7, 0.474], [64669.5, 0.487], [64669.6, 1.611], [64669.7, 0.063], [64670.4, 0.003], [64670.8, 0.005], [64671.5, 1.09], [64673.4, 0.004], [64673.5, 2.197]], "asks": [[64673.6, 35.978], [64674.5, 0.017], [64675.6, 0.31], [64677.1, 0.004], [64677.8, 0.157], [64678.7, 0.004], [64684.7, 0.241], [64691.0, 0.053], [64694.0, 0.001], [64694.2, 0.005], [64715.5, 0.158], [64716.1, 0.336], [64729.6, 0.047], [64729.9, 3.135], [64819.5, 0.006], [65261.1, 7.208], [65320.3, 0.002], [65419.7, 7.264], [65423.4, 0.0], [65673.6, 0.0]]}
{"kind": "depth", "E": 1787095202751, "U": 11316363266243, "u": 11316363273814, "recv_ms": 1787095202822, "bids": [[14173.5, 3.416], [14175.3, 0.028], [14275.3, 0.014], [14573.5, 0.728], [58206.1, 0.002], [61439.8, 0.004], [62086.5, 0.002], [63266.1, 0.002], [63270.5, 0.002], [63763.8, 23.45], [64026.8, 0.24], [64059.1, 0.78], [64350.1, 0.0], [64521.5, 2.569], [64521.6, 0.002], [64533.1, 4.816], [64555.3, 0.42], [64555.8, 3.866], [64555.9, 1.741], [64561.3, 0.004], [64562.4, 1.444], [64566.4, 2.73], [64568.5, 0.001], [64581.4, 2.336], [64583.0, 0.096], [64600.9, 0.047], [64603.0, 32.582], [64604.0, 0.186], [64604.1, 0.039], [64605.6, 0.001], [64607.0, 0.025], [64607.4, 0.174], [64611.1, 2.815], [64611.4, 0.837], [64612.1, 0.259], [64612.2, 0.002], [64621.7, 0.029], [64637.2, 0.014], [64639.8, 2.159], [64642.6, 0.058], [64648.2, 0.637], [64650.1, 0.196], [64650.2, 0.045], [64652.0, 0.105], [64655.4, 0.283], [64655.5, 0.044], [64657.1, 0.051], [64658.0, 0.011], [64658.6, 1.603], [64659.7, 0.001], [64660.7, 0.256], [64660.8, 0.006], [64661.0, 1.0], [64661.4, 0.016], [64664.6, 0.001], [64666.0, 1.864], [64666.9, 0.396], [64667.1, 0.225], [64667.2, 1.846], [64667.5, 0.185], [64667.6, 0.121], [64667.7, 0.164], [64667.8, 0.543], [64668.9, 0.006], [64669.4, 3.074], [64669.5, 0.177], [64669.6, 1.603], [64669.7, 0.063], [64669.8, 0.023], [64670.3, 0.002], [64670.4, 0.041], [64670.9, 0.084], [64671.6, 0.248], [64673.5, 4.687]], "asks": [[64673.6, 36.601], [64673.7, 1.858], [64674.1, 0.084], [64674.5, 0.101], [64675.6, 0.0], [64675.7, 0.001], [64676.9, 0.419], [64677.1, 0.0], [64677.8, 0.312], [64678.7, 0.159], [64680.7, 0.0], [64681.5, 0.002], [64681.9, 0.016], [64684.7, 0.396], [64686.3, 0.002], [64687.3, 0.398], [64688.7, 0.595], [64689.6, 0.02], [64690.1, 0.004], [64691.0, 0.208], [64692.1, 0.049], [64694.0, 0.156], [64694.2, 0.16], [64694.7, 0.029], [64698.9, 2.369], [64699.5, 0.125], [64702.7, 0.497], [64705.1, 1.033], [64733.6, 9.1], [64743.3, 0.05], [64749.4, 0.227], [64782.4, 7.179], [64784.2, 0.0], [64806.5, 1.978], [64807.5, 4.422], [64813.6, 0.021], [64814.1, 5.4], [64831.1, 0.001], [64832.1, 7.143], [64868.0, 1.938], [64868.4, 0.003], [64868.5, 0.125], [64869.9, 0.018], [64870.9, 10.853], [65320.3, 0.0], [65380.3, 0.61], [65386.7, 0.28], [65419.7, 8.172], [65423.5, 2.748], [65455.1, 36.292], [65484.4, 3.78], [65488.0, 8.999], [65582.6, 0.797], [65624.6, 11.484]]}
{"kind": "depth", "E": 1787095202853, "U": 11316363274020, "u": 11316363281919, "recv_ms": 1787095202922, "bids": [[14173.5, 3.136], [14173.6, 0.0], [14175.3, 0.0], [14275.3, 0.0], [14573.5, 1.064], [58206.1, 0.002], [62086.5, 0.005], [63497.8, 0.786], [63673.5, 0.028], [64026.8, 0.24], [64533.1, 4.722], [64581.4, 2.374], [64603.0, 0.002], [64603.6, 1.242], [64604.0, 0.263], [64605.3, 32.956], [64605.6, 0.162], [64605.7, 0.039], [64606.2, 0.334], [64625.7, 0.103], [64642.1, 0.64], [64642.3, 2.39], [64650.1, 0.196], [64651.3, 0.036], [64655.4, 0.283], [64658.0, 0.011], [64660.7, 0.256], [64661.4, 0.016], [64667.2, 1.844], [64667.4, 0.65], [64667.5, 1.731], [64667.6, 0.13], [64667.7, 0.164], [64667.8, 0.002], [64668.2, 0.005], [64668.9, 0.005], [64669.4, 1.52], [64669.7, 0.071], [64669.8, 0.015], [64670.4, 0.003], [64671.0, 0.003]], "asks": [[64677.3, 0.0], [64677.8, 0.467], [64678.7, 0.314], [64684.7, 0.396], [64691.0, 0.208], [64694.0, 0.156], [64694.2, 0.315], [64729.4, 0.011], [64729.6, 0.037], [64785.6, 0.127], [64814.1, 5.4], [64831.1, 10.413], [64832.1, 0.021], [64868.0, 1.022], [64869.9, 6.841], [64870.9, 0.0], [65320.3, 0.0], [65418.0, 10.302], [65419.7, 0.0], [65423.5, 1.832], [65482.7, 5.077], [65484.4, 0.0], [65673.6, 0.02], [65692.6, 0.651], [65713.9, 4.683], [65968.8, 2.134]]}
{"kind": "depth", "E": 1787095202955, "U": 11316363282061, "u": 11316363288653, "recv_ms": 1787095203025, "bids": [[1000.0, 35.76], [14173.5, 2.772], [14573.5, 1.428], [58206.1, 0.002], [61439.8, 0.004], [63673.5, 0.008], [63860.8, 10.742], [64026.8, 0.24], [64315.2, 0.785], [64322.0, 0.51], [64521.5, 2.492], [64581.4, 2.336], [64604.0, 0.025], [64604.1, 0.001], [64605.6, 0.155], [64605.7, 0.001], [64612.1, 0.252], [64615.5, 0.312], [64650.1, 0.196], [64652.7, 0.119], [64653.6, 0.083], [64655.4, 0.283], [64658.6, 0.985], [64659.3, 0.851], [64660.2, 0.199], [64660.7, 0.256], [64661.4, 0.016], [64666.0, 1.244], [64666.3, 0.009], [64666.7, 0.659], [64667.2, 1.852], [64667.3, 0.173], [64667.4, 0.109], [64667.5, 1.733], [64667.6, 0.129], [64667.7, 0.705], [64667.8, 0.435], [64668.6, 0.006], [64669.7, 0.071], [64670.4, 0.041], [64670.9, 0.084], [64671.3, 0.085], [64671.8, 0.002], [64673.5, 3.387]], "asks": [[64673.6, 36.601], [64673.8, 0.016], [64674.1, 0.0], [64674.4, 0.007], [64675.2, 0.017], [64675.7, 0.01], [64677.4, 0.145], [64677.8, 0.467], [64678.7, 0.314], [64684.7, 0.396], [64691.0, 0.208], [64691.8, 0.844], [64692.1, 0.029], [64693.1, 0.001], [64694.0, 0.156], [64694.2, 0.315], [64699.4, 0.404], [65320.3, 0.0], [65418.0, 11.21], [65423.5, 0.916], [65482.7, 5.833], [65488.0, 8.243], [65624.3, 0.535], [65673.6, 0.0], [65857.5, 0.795], [70392.7, 0.002]]}
{"kind": "depth", "E": 1787095203057, "U": 11316363288708, "u": 11316363295262, "recv_ms": 1787095203126, "bids": [[14173.5, 2.408], [14573.5, 1.792], [58206.1, 0.002], [61439.8, 0.004], [62086.5, 0.002], [63056.7, 0.634], [63385.4, 0.948], [63768.1, 0.188], [64026.8, 0.24], [64350.1, 0.01], [64521.5, 2.576], [64521.6, 0.04], [64595.8, 0.152], [64605.6, 0.239], [64605.7, 0.039], [64641.9, 0.08], [64642.1, 0.63], [64650.1, 0.196], [64655.4, 0.283], [64657.6, 0.009], [64658.0, 0.004], [64659.3, 0.392], [64659.9, 0.459], [64660.3, 0.008], [64660.6, 1.498], [64660.7, 0.256], [64661.4, 0.093], [64661.9, 0.003], [64666.7, 0.118], [64667.2, 1.854], [64667.3, 0.714], [64667.6, 0.662], [64667.7, 0.172], [64667.8, 0.002], [64667.9, 0.017], [64668.0, 0.137], [64669.7, 0.063], [64670.3, 0.002], [64670.4, 0.011], [64673.5, 2.199]], "asks": [[64673.6, 36.55], [64674.0, 0.084], [64675.7, 0.01], [64677.2, 0.056], [64677.8, 0.467], [64678.7, 0.314], [64683.5, 0.067], [64683.8, 0.122], [64684.7, 0.396], [64691.0, 0.208], [64691.8, 0.385], [64692.1, 0.029], [64692.7, 0.461], [64694.0, 0.156], [64694.2, 0.315], [64696.2, 1.019], [64697.4, 0.002], [64699.4, 0.404], [64729.2, 0.083], [64729.4, 0.001], [64743.7, 0.005], [64753.1, 0.008], [65320.3, 0.0], [65418.0, 12.118], [65423.5, 0.0], [65451.4, 0.764], [65482.7, 6.589], [65488.0, 7.487], [65616.8, 21.992], [65708.4, 1.064]]}
{"kind": "depth", "E": 1787095203159, "U": 11316363295322, "u": 11316363302435, "recv_ms": 1787095203228, "bids": [[1000.0, 35.91], [14173.5, 2.058], [14573.5, 2.142], [58206.1, 0.002], [62086.5, 0.005], [63891.0, 8.077], [64026.8, 0.24], [64581.4, 2.374], [64593.5, 0.004], [64600.7, 0.093], [64624.7, 0.006], [64629.8, 0.039], [64641.8, 0.01], [64641.9, 0.07], [64667.3, 0.173], [64667.7, 0.713], [64669.7, 0.071], [64670.3, 0.435], [64670.4, 0.003]], "asks": [[64674.3, 0.006], [64674.4, 0.001], [64675.1, 0.003], [64677.8, 0.312], [64678.7, 0.159], [64679.2, 0.002], [64682.6, 0.001], [64692.1, 0.049], [64694.2, 0.16], [64699.4, 0.384], [64729.1, 0.41], [64729.2, 0.073], [64799.3, 0.005], [64997.0, 0.201], [65134.5, 0.003], [65320.3, 0.0], [65482.7, 7.345], [65488.0, 6.731], [67912.9, 0.073]]}
{"kind": "depth", "E": 1787095203261, "U": 11316363302453, "u": 11316363311447, "recv_ms": 1787095203331, "bids": [[1000.0, 35.76], [14173.5, 1.708], [14573.5, 2.492], [58206.1, 0.002], [61439.8, 0.004], [62086.5, 0.002], [63673.5, 0.028], [63860.8, 10.507], [64024.2, 1.092], [64026.6, 1.64], [64026.8, 0.24], [64096.9, 0.514], [64350.1, 0.011], [64361.5, 0.237], [64521.5, 2.338], [64521.6, 0.002], [64533.1, 4.735], [64581.4, 2.336], [64583.0, 0.0], [64593.5, 0.005], [64600.7, 0.094], [64604.0, 0.006], [64605.6, 0.258], [64605.7, 0.001], [64612.1, 0.002], [64616.1, 1.442], [64619.1, 0.001], [64634.7, 1.024], [64643.0, 0.0], [64643.8, 0.057], [64644.4, 0.311], [64650.1, 0.196], [64650.2, 0.045], [64652.7, 0.003], [64653.5, 0.167], [64655.4, 0.283], [64655.5, 0.391], [64655.6, 0.012], [64659.9, 0.0], [64660.3, 0.001], [64660.4, 5.364], [64660.7, 0.256], [64660.8, 0.013], [64660.9, 0.039], [64661.4, 0.093], [64661.5, 0.311], [64661.6, 0.029], [64667.2, 1.854], [64667.3, 1.252], [64667.4, 0.109], [64667.5, 0.187], [64667.6, 0.121], [64667.7, 0.164], [64667.8, 0.002], [64667.9, 0.028], [64668.0, 1.686], [64668.8, 0.409], [64669.1, 0.012], [64669.4, 1.52], [64669.5, 0.177], [64669.7, 0.063], [64670.3, 0.009], [64670.4, 0.041], [64670.6, 0.325], [64670.7, 0.008], [64670.9, 0.084], [64671.1, 0.002], [64671.2, 0.015], [64671.5, 1.068], [64671.7, 0.026], [64672.1, 0.035], [64672.5, 0.002], [64673.5, 2.199]], "asks": [[64673.6, 34.859], [64673.7, 1.548], [64673.8, 0.015], [64673.9, 0.0], [64674.0, 0.006], [64674.3, 0.0], [64674.4, 0.311], [64674.5, 0.017], [64674.6, 0.091], [64675.0, 0.085], [64675.2, 0.01], [64675.7, 0.01], [64676.0, 1.126], [64676.5, 0.155], [64676.7, 0.002], [64676.9, 0.366], [64677.0, 0.005], [64677.1, 0.0], [64677.2, 0.002], [64677.4, 0.095], [64677.8, 0.312], [64678.6, 0.14], [64678.7, 0.159], [64679.0, 4.45], [64680.0, 0.008], [64680.2, 0.394], [64680.6, 0.314], [64681.0, 0.009], [64681.3, 0.141], [64681.4, 1.163], [64684.7, 0.396], [64687.1, 0.034], [64687.4, 0.098], [64687.7, 0.315], [64690.3, 0.064], [64691.0, 0.208], [64692.1, 0.029], [64692.6, 1.073], [64692.7, 0.002], [64693.4, 0.0], [64694.0, 0.156], [64694.2, 0.16], [64694.8, 7.405], [64695.6, 0.114], [64696.0, 1.077], [64696.2, 0.52], [64696.3, 0.31], [64696.5, 0.001], [64696.9, 0.557], [64697.0, 0.336], [64697.2, 0.118], [64697.3, 1.705], [64698.0, 0.226], [64698.4, 0.205], [64698.5, 0.023], [64698.7, 0.009], [64702.4, 1.228], [64702.5, 0.14], [64702.6, 0.004], [64705.4, 0.038], [64705.5, 0.007], [64705.6, 1.4], [64706.4, 0.017], [64706.5, 0.001], [64706.6, 0.012], [64708.5, 0.0], [64708.6, 0.006], [64708.7, 0.008], [64715.6, 2.327], [64716.1, 0.332], [64722.6, 0.097], [64813.2, 0.174], [64814.1, 5.4], [64869.9, 6.58], [65320.3, 0.0], [65417.5, 0.16], [65477.7, 12.394], [65611.4, 1.066], [65673.6, 0.02]]}
{"kind": "depth", "E": 1787095203363, "U": 11316363311499, "u": 11316363320453, "recv_ms": 1787095203433, "bids": [[14173.5, 1.344], [14573.5, 2.856], [58206.1, 0.002], [61439.8, 0.004], [62285.7, 0.059], [63673.5, 0.008], [63897.4, 6.986], [64026.8, 0.24], [64350.1, 0.001], [64361.5, 0.237], [64521.5, 2.576], [64581.4, 2.374], [64595.8, 0.152], [64605.6, 0.258], [64605.7, 0.001], [64619.1, 0.001], [64621.6, 0.001], [64627.1, 0.1], [64628.4, 0.029], [64641.7, 0.068], [64641.8, 0.0], [64642.9, 2.098], [64643.8, 0.0], [64650.1, 0.196], [64655.5, 0.948], [64655.6, 0.012], [64656.2, 0.061], [64658.0, 0.004], [64659.5, 0.002], [64659.9, 1.0], [64660.3, 0.46], [64660.4, 4.905], [64660.7, 0.349], [64661.0, 0.0], [64661.4, 0.0], [64666.7, 0.118], [64667.1, 0.226], [64667.2, 1.851], [64667.3, 0.795], [64667.4, 0.653], [64667.9, 0.016], [64668.0, 0.137], [64668.1, 0.086], [64668.2, 0.005], [64668.3, 0.041], [64668.4, 1.634], [64668.8, 0.099], [64669.3, 2.827], [64669.7, 0.063], [64670.3, 0.435], [64670.4, 0.003], [64670.6, 0.015], [64670.7, 0.0], [64670.8, 0.005], [64670.9, 0.0], [64671.3, 0.001], [64672.4, 0.022], [64672.5, 0.021], [64673.5, 1.767]], "asks": [[64673.6, 35.586], [64674.0, 0.0], [64674.3, 0.006], [64674.4, 0.311], [64674.6, 0.084], [64675.2, 0.009], [64675.7, 0.02], [64676.5, 0.158], [64677.1, 0.0], [64677.8, 0.157], [64678.7, 0.012], [64680.2, 0.31], [64684.7, 0.241], [64687.4, 0.098], [64688.0, 4.052], [64690.5, 10.099], [64691.0, 0.053], [64691.8, 0.385], [64692.6, 0.614], [64692.7, 0.461], [64694.0, 0.001], [64694.2, 0.005], [64694.3, 0.043], [64694.7, 0.029], [64695.5, 0.059], [64696.2, 0.463], [64705.2, 0.031], [64705.3, 2.143], [64729.0, 0.03], [64729.1, 0.4], [64733.7, 0.007], [64753.1, 0.005], [64831.1, 0.001], [64832.1, 7.54], [64869.9, 0.018], [64870.9, 10.274], [65127.3, 0.115], [65320.3, 0.0], [65418.0, 13.026], [65419.8, 2.724], [65482.7, 8.101], [65488.0, 5.975], [65592.0, 0.734], [65616.8, 20.926], [65673.6, 0.0]]}
{"kind": "depth", "E": 1787095203465, "U": 11316363320610, "u": 11316363330766, "recv_ms": 1787095203536, "bids": [[1000.0, 35.76], [14173.5, 0.994], [14573.5, 3.206], [51738.8, 0.0], [58206.1, 0.002], [61439.8, 0.006], [62086.5, 0.005], [63878.9, 0.002], [64026.8, 0.24], [64091.4, 18.845], [64091.5, 0.234], [64521.6, 0.04], [64605.7, 0.039], [64632.8, 2.0], [64636.8, 1.757], [64639.8, 1.194], [64641.6, 2.068], [64641.7, 0.058], [64642.1, 0.687], [64642.9, 2.041], [64650.1, 0.196], [64652.4, 0.12], [64653.5, 0.051], [64654.9, 0.139], [64655.6, 0.012], [64656.8, 0.026], [64657.0, 0.902], [64657.1, 0.011], [64657.6, 0.002], [64659.0, 0.465], [64659.5, 0.013], [64659.6, 0.438], [64660.1, 0.021], [64660.2, 0.179], [64660.3, 0.001], [64660.4, 4.925], [64660.7, 0.333], [64660.8, 0.006], [64661.4, 0.016], [64662.2, 0.193], [64662.8, 0.004], [64663.0, 0.003], [64664.1, 0.0], [64666.0, 0.344], [64666.1, 0.704], [64666.9, 0.385], [64667.4, 0.112], [64667.6, 1.667], [64667.7, 0.172], [64668.3, 0.033], [64668.4, 0.088], [64669.7, 0.063], [64670.3, 0.002], [64670.4, 0.003], [64670.5, 0.013], [64671.0, 0.003], [64671.5, 1.048], [64671.7, 0.045], [64672.4, 0.0], [64672.5, 0.002], [64673.4, 0.002], [64673.5, 1.034]], "asks": [[64673.6, 36.759], [64674.1, 0.002], [64677.1, 0.0], [64679.2, 0.001], [64680.8, 0.02], [64680.9, 0.024], [64691.4, 0.461], [64692.7, 0.002], [64693.0, 0.075], [64693.9, 0.061], [64695.5, 0.002], [64728.9, 0.011], [64729.0, 0.02], [64785.6, 0.027], [64831.1, 10.413], [64832.1, 0.021], [64869.9, 6.664], [64870.9, 0.0], [65320.3, 0.0], [65477.7, 12.052], [70554.2, 0.002]]}
{"kind": "depth", "E": 1787095203567, "U": 11316363331247, "u": 11316363340911, "recv_ms": 1787095203638, "bids": [[1000.0, 35.76], [14173.5, 0.63], [14573.5, 3.57], [58206.1, 0.002], [62086.5, 0.002], [63830.3, 1.096], [64026.8, 0.24], [64605.3, 0.186], [64607.4, 32.944], [64612.1, 0.24], [64612.2, 0.04], [64634.1, 2.32], [64638.7, 0.272], [64638.8, 0.001], [64650.0, 3.495], [64650.1, 0.196], [64650.2, 0.045], [64654.9, 0.041], [64655.6, 0.012], [64658.0, 0.004], [64659.4, 0.237], [64660.7, 0.333], [64660.8, 0.006], [64661.4, 0.0], [64661.6, 0.045], [64662.0, 0.325], [64664.1, 0.32], [64664.9, 0.283], [64666.9, 0.386], [64667.1, 0.225], [64667.3, 0.254], [64667.7, 0.705], [64667.8, 0.002], [64669.4, 1.528], [64669.7, 0.063], [64670.3, 0.01], [64670.5, 0.005], [64671.7, 0.045], [64673.5, 0.926]], "asks": [[64673.6, 35.71], [64675.2, 0.009], [64675.7, 0.01], [64676.5, 0.155], [64677.8, 0.312], [64678.6, 0.017], [64678.7, 0.167], [64687.4, 0.408], [64690.4, 0.249], [64690.5, 10.101], [64692.0, 4.349], [64694.3, 0.198], [64997.0, 0.2], [65135.2, 0.0], [65320.3, 0.0], [65418.0, 13.934], [65419.8, 1.816], [65542.3, 7.748], [65611.4, 2.132], [65681.5, 9.578], [71141.0, 0.015]]}
{"kind": "depth", "E": 1787095203669, "U": 11316363341095, "u": 11316363349906, "recv_ms": 1787095203739, "bids": [[14173.5, 0.364], [14473.5, 0.084], [14573.5, 3.752], [51743.0, 0.0], [58206.1, 0.002], [61439.8, 0.006], [62086.5, 0.005], [63673.5, 0.028], [63763.8, 23.262], [64026.8, 0.24], [64350.1, 0.002], [64551.2, 0.0], [64553.6, 4.014], [64605.6, 0.085], [64632.4, 0.0], [64638.1, 1.329], [64641.5, 0.011], [64641.6, 2.058], [64645.1, 0.092], [64645.2, 0.003], [64650.1, 0.196], [64650.2, 0.045], [64653.8, 0.394], [64654.6, 0.048], [64655.3, 1.962], [64655.6, 0.012], [64656.6, 0.021], [64659.0, 0.006], [64659.9, 1.459], [64660.7, 0.333], [64660.8, 0.014], [64660.9, 0.039], [64661.0, 0.9], [64661.4, 0.008], [64661.6, 0.029], [64664.0, 0.538], [64664.1, 0.0], [64665.9, 0.038], [64666.1, 0.163], [64666.7, 0.659], [64666.9, 0.385], [64667.0, 1.339], [64667.2, 0.496], [64667.3, 0.254], [64667.4, 0.112], [64667.7, 2.214], [64667.8, 0.002], [64669.4, 1.52], [64669.5, 0.185], [64669.7, 0.063], [64670.3, 0.01], [64670.8, 0.005]], "asks": [[64673.6, 36.909], [64675.2, 0.008], [64675.5, 0.311], [64675.7, 0.01], [64677.0, 0.005], [64677.6, 0.003], [64677.8, 0.312], [64678.7, 0.012], [64681.1, 0.156], [64681.2, 0.46], [64681.3, 1.378], [64681.7, 0.008], [64682.0, 0.21], [64683.5, 0.059], [64683.7, 0.011], [64683.8, 0.045], [64684.5, 0.271], [64684.7, 0.481], [64685.3, 0.162], [64686.1, 0.022], [64686.3, 0.01], [64686.4, 4.57], [64687.1, 0.026], [64687.2, 0.164], [64687.4, 0.253], [64687.5, 0.628], [64688.1, 0.01], [64690.3, 0.219], [64690.4, 0.094], [64691.4, 0.002], [64691.8, 0.425], [64693.1, 0.46], [64693.9, 0.004], [64694.3, 0.198], [64694.6, 0.255], [64695.3, 0.057], [64697.6, 0.14], [64716.6, 0.006], [64728.8, 0.013], [64728.9, 0.001], [64733.6, 0.726], [64734.9, 0.003], [64752.5, 55.418], [64756.4, 9.843], [64756.9, 0.0], [64781.6, 3.675], [64783.5, 14.325], [64791.3, 0.0], [64791.4, 0.0], [64795.9, 0.091], [64821.3, 18.639], [64829.1, 0.0], [64829.2, 0.0], [64831.1, 10.413], [64832.0, 1.1], [64860.1, 20.548], [64864.3, 1.042], [64866.5, 0.0], [64869.9, 0.018], [64870.8, 12.491], [65320.3, 0.0], [65418.0, 14.842], [65419.8, 0.908], [65477.7, 11.824], [65482.0, 0.826], [65673.6, 0.02], [65676.0, 1.084], [65972.5, 0.003]]}
{"kind": "depth", "E": 1787095203771, "U": 11316363350088, "u": 11316363358104, "recv_ms": 1787095203840, "bids": [[1000.0, 35.76], [14173.5, 0.224], [14473.5, 0.308], [14573.5, 3.668], [58206.1, 0.002], [61439.8, 0.006], [62086.5, 0.002], [63862.0, 0.037], [64026.8, 0.24], [64603.7, 0.664], [64607.8, 5.856], [64634.4, 0.018], [64636.8, 1.895], [64650.1, 0.196], [64650.2, 0.045], [64654.2, 0.01], [64655.6, 0.012], [64657.1, 0.009], [64658.0, 0.004], [64659.6, 0.158], [64660.1, 0.639], [64660.7, 0.333], [64660.8, 0.006], [64661.4, 0.008], [64661.6, 0.037], [64662.2, 0.0], [64665.9, 0.672], [64666.7, 0.118], [64667.1, 0.225], [64667.5, 0.808], [64667.6, 0.121], [64667.8, 0.002], [64667.9, 0.016], [64669.4, 3.066], [64669.7, 0.063], [64670.3, 0.002], [64670.4, 0.313], [64670.5, 0.005], [64670.6, 0.099], [64671.1, 0.086], [64671.7, 0.053]], "asks": [[64673.6, 36.825], [64674.2, 0.084], [64674.6, 0.091], [64675.2, 0.002], [64675.7, 0.01], [64677.0, 0.009], [64677.8, 0.312], [64680.9, 0.179], [64681.0, 0.909], [64681.1, 0.001], [64682.0, 0.202], [64683.1, 0.124], [64683.5, 0.052], [64683.7, 0.003], [64683.9, 0.003], [64684.0, 0.426], [64684.6, 0.283], [64684.7, 0.867], [64686.3, 0.173], [64687.4, 0.098], [64688.0, 2.643], [64688.8, 0.627], [64689.0, 0.994], [64689.6, 0.018], [64690.3, 0.062], [64690.4, 0.094], [64690.5, 0.101], [64691.8, 0.427], [64694.0, 0.156], [64694.3, 0.198], [64696.1, 0.997], [64697.6, 0.139], [64726.6, 1.629], [64745.9, 57.759], [64749.9, 1.072], [64750.3, 0.036], [64752.5, 0.001], [64756.4, 1.528], [64792.1, 0.404], [64814.0, 1.714], [64831.1, 10.413], [64832.0, 1.1], [64833.5, 1.05], [64857.7, 5.144], [64869.9, 6.03], [64870.8, 0.0], [65133.6, 0.173], [65320.3, 0.0], [65443.2, 0.0], [65482.0, 1.054]]}
{"kind": "depth", "E": 1787095203873, "U": 11316363358206, "u": 11316363370545, "recv_ms": 1787095203943, "bids": [[1000.0, 35.76], [14173.5, 0.112], [14473.5, 0.56], [14573.5, 3.528], [58206.1, 0.002], [61445.1, 0.004], [61635.2, 0.007], [63673.5, 0.008], [63741.1, 21.247], [64026.8, 0.24], [64630.6, 0.008], [64631.0, 0.004], [64641.4, 0.174], [64641.5, 0.001], [64650.1, 0.196], [64655.6, 0.012], [64657.1, 0.011], [64658.0, 0.004], [64658.9, 0.273], [64659.4, 0.005], [64660.1, 0.021], [64660.7, 0.333], [64661.4, 0.008], [64665.9, 0.131], [64667.0, 1.339], [64667.1, 0.766], [64667.2, 0.496], [64667.4, 0.112], [64667.5, 0.19], [64667.8, 0.002], [64669.7, 0.063], [64670.3, 0.443], [64670.4, 0.003], [64670.5, 0.005], [64670.6, 0.015], [64671.1, 0.002], [64671.7, 0.045]], "asks": [[64673.6, 36.91], [64674.6, 0.084], [64675.2, 0.009], [64677.0, 0.005], [64677.8, 0.312], [64679.8, 0.029], [64680.9, 0.179], [64684.6, 0.291], [64686.3, 0.165], [64689.6, 0.02], [64694.0, 0.156], [64694.3, 0.198], [64745.9, 57.759], [64756.9, 0.0], [65320.3, 0.0], [65546.7, 0.38], [65572.5, 0.0], [65673.6, 0.0]]}
{"kind": "depth", "E": 1787095203975, "U": 11316363370633, "u": 11316363377667, "recv_ms": 1787095204046, "bids": [[14173.5, 0.0], [14473.5, 0.798], [14573.5, 3.402], [58206.1, 0.002], [61624.2, 0.018], [61627.8, 0.0], [62086.5, 0.005], [63800.4, 1.711], [63800.7, 2.196], [63832.6, 0.55], [64024.3, 2.184], [64026.8, 0.24], [64322.0, 0.018], [64326.0, 0.854], [64350.1, 0.002], [64508.3, 0.104], [64509.1, 0.48], [64605.6, 0.001], [64655.5, 0.946], [64661.4, 0.015], [64667.2, 0.489], [64667.8, 1.981], [64669.4, 1.52], [64670.3, 0.01], [64670.8, 0.005]], "asks": [[64674.8, 0.005], [64675.7, 0.02], [64701.8, 0.162], [64728.7, 0.01], [64728.8, 0.003], [65320.3, 0.0], [65900.2, 4.3], [67703.5, 0.04], [67707.5, 0.0]]}
{"kind": "depth", "E": 1787095204077, "U": 11316363377842, "u": 11316363385852, "recv_ms": 1787095204146, "bids": [[1000.0, 35.76], [14473.5, 1.162], [14573.5, 3.038], [58206.1, 0.002], [61439.8, 0.006], [62086.5, 0.002], [63401.1, 0.68], [63580.8, 0.0], [63673.5, 0.028], [63735.7, 3.291], [63865.1, 0.586], [63897.4, 7.205], [64026.7, 0.002], [64026.8, 0.24], [64361.5, 0.256], [64508.3, 0.143], [64509.1, 0.441], [64511.8, 0.259], [64516.1, 7.204], [64516.7, 0.271], [64516.8, 1.474], [64516.9, 2.077], [64519.3, 0.001], [64521.2, 2.395], [64533.1, 4.736], [64550.9, 0.069], [64605.7, 0.001], [64642.1, 0.63], [64643.6, 0.057], [64658.0, 0.004], [64661.4, 0.556], [64661.9, 0.003], [64667.1, 0.225], [64667.3, 0.256], [64667.7, 1.28], [64667.8, 2.089], [64670.3, 0.443], [64670.8, 0.089]], "asks": [[64673.6, 36.893], [64674.6, 0.091], [64675.2, 0.002], [64675.7, 0.01], [64677.3, 0.003], [64679.3, 0.004], [64683.9, 0.544], [64684.7, 0.326], [64702.4, 1.23], [64702.5, 0.142], [64702.6, 0.006], [64705.4, 0.04], [64705.5, 0.009], [64705.6, 1.402], [64706.4, 0.019], [64706.5, 0.003], [64706.6, 0.014], [64708.5, 0.002], [64708.6, 0.008], [64708.7, 0.01], [64715.6, 2.323], [64745.9, 2.342], [64748.1, 57.668], [64755.8, 0.207], [64756.9, 0.0], [64765.7, 0.042], [64814.0, 0.0], [64814.1, 5.4], [64831.1, 10.413], [64868.4, 0.0], [64868.5, 0.128], [64869.9, 6.548], [65320.3, 0.0], [65449.7, 1.526], [65482.0, 1.312], [65579.0, 2.366], [65673.6, 0.02]]}
{"kind": "depth", "E": 1787095204179, "U": 11316363385863, "u": 11316363394005, "recv_ms": 1787095204247, "bids": [[1000.0, 35.76], [14473.5, 1.512], [14573.5, 2.688], [50000.0, 233.354], [58206.1, 0.002], [61439.8, 0.008], [62086.5, 0.005], [63507.2, 0.0], [64026.8, 0.24], [64553.3, 0.094], [64593.5, 0.007], [64600.7, 0.096], [64621.6, 0.002], [64624.7, 0.008], [64629.9, 0.082], [64650.1, 0.351], [64655.6, 0.167], [64656.2, 0.058], [64658.8, 0.005], [64660.7, 0.488], [64660.8, 0.009], [64661.4, 0.549], [64661.6, 0.199], [64663.1, 2.325], [64667.1, 0.225], [64667.5, 0.187], [64667.8, 0.002], [64667.9, 0.557], [64668.0, 0.145], [64669.4, 3.066], [64669.5, 0.177], [64669.7, 0.373], [64670.3, 0.443], [64670.8, 0.089], [64671.7, 0.045]], "asks": [[64673.6, 36.894], [64677.1, 0.004], [64677.4, 0.096], [64677.8, 0.157], [64680.9, 0.024], [64684.6, 0.136], [64686.1, 0.002], [64686.3, 0.01], [64691.8, 0.447], [64694.0, 0.001], [64694.3, 0.043], [64698.7, 0.58], [64715.6, 2.327], [64722.6, 0.097], [65320.3, 0.0], [65418.0, 15.75], [65419.8, 0.0]]}
{"kind": "depth", "E": 1787095204281, "U": 11316363394147, "u": 11316363402501, "recv_ms": 1787095204350, "bids": [[14473.5, 1.862], [14573.5, 2.338], [51739.0, 0.0], [58206.1, 0.002], [61439.8, 0.008], [61445.1, 0.002], [62086.5, 0.002], [63673.5, 0.008], [63865.1, 0.851], [64026.6, 2.186], [64026.8, 0.24], [64350.1, 0.001], [64621.6, 0.003], [64641.3, 0.014], [64641.4, 0.164], [64650.1, 0.196], [64652.4, 0.004], [64653.7, 0.537], [64655.5, 0.389], [64655.6, 0.012], [64656.4, 0.627], [64656.8, 0.019], [64657.5, 0.161], [64658.0, 0.004], [64660.7, 0.256], [64661.6, 0.121], [64664.2, 0.196], [64664.5, 0.187], [64666.7, 0.257], [64667.3, 0.254], [64668.0, 1.691], [64669.4, 1.52], [64669.5, 0.001], [64669.7, 0.063], [64669.9, 0.001], [64670.3, 0.002], [64670.4, 0.011], [64670.8, 0.005], [64671.6, 0.342], [64672.1, 0.001]], "asks": [[64674.6, 0.084], [64675.2, 0.009], [64675.7, 0.02], [64683.5, 0.129], [64684.7, 0.249], [64690.3, 0.064], [64696.5, 0.117], [64697.2, 0.002], [64697.7, 0.04], [64698.7, 0.573], [64728.6, 0.01], [64728.7, 0.0], [65320.3, 0.0], [65482.7, 9.613], [65484.5, 0.0], [65673.6, 0.0], [65770.8, 4.936], [65902.4, 2.133]]}
{"kind": "depth", "E": 1787095204383, "U": 11316363402553, "u": 11316363415050, "recv_ms": 1787095204451, "bids": [[1000.0, 35.76], [14473.5, 2.226], [14573.5, 1.974], [51740.0, 0.0], [58206.1, 0.002], [63509.4, 3.57], [63580.5, 0.627], [63755.1, 0.244], [63763.8, 23.074], [64026.8, 0.24], [64533.1, 4.736], [64650.1, 0.196], [64655.6, 0.012], [64656.2, 0.615], [64656.4, 0.07], [64660.7, 0.256], [64661.4, 0.626], [64661.6, 0.037], [64667.1, 0.766], [64667.3, 0.264], [64667.4, 0.109], [64667.8, 0.002], [64667.9, 1.562], [64668.0, 0.145], [64668.1, 0.086], [64668.2, 0.005], [64668.3, 0.033], [64669.7, 0.071], [64670.4, 0.087], [64672.2, 0.0]], "asks": [[64675.3, 2.501], [64680.8, 0.001], [64680.9, 0.002], [64681.3, 1.337], [64696.4, 0.576], [64696.9, 0.001], [64814.1, 5.4], [64869.9, 7.115], [64997.0, 0.201], [65320.3, 0.0], [65455.1, 35.072], [65639.3, 6.751], [65964.8, 2.12]]}
{"kind": "depth", "E": 1787095204485, "U": 11316363415331, "u": 11316363425105, "recv_ms": 1787095204555, "bids": [[1000.0, 35.76], [14473.5, 2.576], [14573.5, 1.624], [51738.8, 0.0], [58206.1, 0.002], [61439.8, 0.008], [62086.5, 0.005], [63673.5, 0.028], [63768.1, 0.376], [63814.2, 1.638], [64026.8, 0.24], [64508.3, 0.104], [64509.1, 0.48], [64634.7, 0.001], [64650.1, 0.196], [64653.0, 1.056], [64655.6, 0.012], [64660.7, 0.256], [64661.4, 0.085], [64661.6, 0.037], [64667.3, 0.261], [64667.4, 0.109], [64667.5, 0.728], [64667.6, 0.124], [64668.0, 0.145], [64669.7, 0.063], [64670.3, 0.435], [64670.5, 0.013], [64670.8, 0.005], [64670.9, 0.084]], "asks": [[64673.6, 36.894], [64674.6, 0.091], [64675.2, 0.002], [64675.5, 0.001], [64677.1, 0.004], [64689.8, 0.053], [64695.2, 0.078], [64703.1, 0.018], [64712.4, 0.408], [64869.9, 6.478], [65320.3, 0.0], [65673.6, 0.02], [65773.1, 3.037]]}
{"kind": "depth", "E": 1787095204587, "U": 11316363425334, "u": 11316363433828, "recv_ms": 1787095204669, "bids": [[14473.5, 2.94], [14573.5, 1.26], [58206.1, 0.002], [61439.8, 0.008], [62086.5, 0.002], [63741.1, 20.15], [63967.5, 0.002], [64026.8, 0.24], [64350.1, 0.01], [64508.3, 0.143], [64509.1, 0.441], [64658.0, 0.004], [64661.4, 0.092], [64667.1, 0.766], [64667.3, 0.254], [64667.4, 0.65], [64667.5, 0.187], [64667.6, 0.124], [64667.7, 1.28], [64669.7, 0.071], [64670.3, 0.002], [64670.5, 0.005], [64671.7, 0.478], [64671.9, 0.002]], "asks": [[64673.6, 36.906], [64675.4, 1.162], [64677.1, 0.0], [64677.2, 0.002], [64792.2, 0.03], [64831.1, 10.413], [64832.0, 1.1], [64869.9, 7.115], [64870.8, 0.0], [65320.3, 0.0], [65448.7, 7.335], [65616.8, 19.86], [65770.8, 3.418]]}
{"kind": "depth", "E": 1787095204689, "U": 11316363433911, "u": 11316363440342, "recv_ms": 1787095204759, "bids": [[1000.0, 35.76], [14473.5, 3.29], [14573.5, 0.91], [58206.1, 0.002], [62086.5, 0.005], [63673.5, 0.008], [63772.4, 0.0], [63830.2, 0.551], [64026.8, 0.24], [64413.8, 0.0], [64439.7, 0.045], [64465.6, 0.395], [64491.4, 0.394], [64517.3, 0.003], [64595.8, 0.149], [64628.2, 0.008], [64650.1, 0.196], [64655.6, 0.012], [64658.0, 0.004], [64659.9, 1.0], [64660.0, 1.365], [64660.7, 0.256], [64660.9, 0.039], [64661.4, 0.085], [64661.6, 0.585], [64661.7, 0.002], [64667.1, 0.766], [64667.4, 0.109], [64667.5, 0.187], [64667.6, 0.124], [64667.8, 0.002], [64668.0, 0.145], [64669.7, 0.071], [64670.3, 0.435], [64670.5, 0.0], [64670.8, 0.005], [64671.7, 0.045]], "asks": [[64674.1, 0.008], [64674.3, 0.0], [64695.3, 0.0], [64696.2, 0.52], [64696.4, 0.02], [64696.5, 0.001], [64697.1, 0.221], [64697.2, 0.558], [64705.1, 0.752], [64705.3, 0.258], [64733.7, 0.007], [64997.0, 0.202], [65261.3, 3.253], [65320.3, 0.0], [65449.7, 2.746], [65512.5, 0.0], [65643.7, 0.379], [65673.6, 0.0], [65967.1, 2.119], [65972.5, 0.0]]}
{"kind": "depth", "E": 1787095204791, "U": 11316363440554, "u": 11316363446289, "recv_ms": 1787095204874, "bids": [[1000.0, 35.76], [14473.5, 3.64], [14573.5, 0.56], [51739.0, 0.0], [58206.1, 0.002], [63569.8, 12.877], [63644.0, 8.044], [63735.7, 4.388], [63837.9, 0.0], [63865.1, 1.086], [64026.8, 0.24], [64641.2, 0.014], [64641.3, 0.004], [64649.7, 0.103], [64657.4, 0.526], [64661.4, 0.085], [64661.6, 0.037], [64667.1, 0.225], [64667.2, 1.03], [64667.4, 0.116], [64667.5, 0.728], [64668.0, 0.145], [64669.7, 0.071], [64670.3, 0.435], [64670.5, 0.0]], "asks": [[64705.4, 1.925], [64745.9, 57.759], [64746.4, 2.137], [64748.1, 2.251], [64750.4, 3.538], [64750.5, 0.0], [64814.0, 1.714], [64868.0, 2.017], [65320.3, 0.0], [65322.7, 0.379], [65326.4, 0.0], [65443.2, 0.916], [65611.4, 3.198]]}
{"kind": "depth", "E": 1787095204893, "U": 11316363446641, "u": 11316363454066, "recv_ms": 1787095204963, "bids": [[14373.5, 0.126], [14473.5, 3.752], [14573.5, 0.322], [58206.1, 0.002], [61439.8, 0.008], [62086.5, 0.002], [63638.7, 2.598], [63673.5, 0.028], [63763.8, 22.605], [63774.5, 1.565], [63830.3, 0.548], [63962.1, 1.108], [64024.2, 0.546], [64026.8, 0.24], [64350.1, 0.01], [64533.1, 4.736], [64607.4, 32.946], [64607.7, 2.403], [64648.5, 0.171], [64655.8, 0.0], [64657.1, 0.011], [64658.0, 0.004], [64661.4, 0.085], [64661.6, 0.578], [64667.3, 0.17], [64667.5, 0.187], [64667.6, 0.124], [64669.7, 0.063], [64670.3, 0.002], [64670.4, 0.095], [64670.5, 0.0], [64670.8, 0.005], [64671.2, 0.099]], "asks": [[64673.6, 36.822], [64675.7, 0.01], [64677.2, 0.002], [64679.1, 1.424], [64679.2, 0.023], [64683.8, 0.045], [64686.4, 4.572], [64687.2, 0.162], [64688.8, 0.009], [64689.6, 0.02], [64691.6, 0.004], [64696.1, 0.379], [64814.1, 5.4], [64869.9, 7.3], [65259.6, 1.07], [65261.4, 0.038], [65320.3, 0.0], [65448.7, 6.419], [65477.7, 11.253], [65673.6, 0.02], [65773.1, 4.555]]}
{"kind": "depth", "E": 1787095204995, "U": 11316363454309, "u": 11316363461009, "recv_ms": 1787095205073, "bids": [[1000.0, 35.96], [14373.5, 0.364], [14473.5, 3.64], [14573.5, 0.196], [58206.1, 0.002], [62086.5, 0.005], [63574.1, 1.68], [63766.9, 1.497], [63824.7, 2.19], [63832.6, 1.098], [63865.1, 1.321], [64024.2, 0.0], [64026.8, 0.24], [64148.3, 0.0], [64326.0, 0.362], [64328.8, 0.492], [64328.9, 0.18], [64533.1, 0.003], [64665.9, 0.038], [64669.7, 0.071], [64670.4, 0.087]], "asks": [[64675.7, 0.02], [64715.6, 2.323], [64722.6, 0.101], [64728.5, 0.01], [64728.6, 0.0], [64780.6, 0.101], [64814.0, 0.0], [64814.1, 0.0], [65320.3, 0.0], [65452.4, 2.287], [65514.5, 0.534], [65900.2, 2.178]]}
{"kind": "depth", "E": 1787095205097, "U": 11316363461276, "u": 11316363467812, "recv_ms": 1787095205165, "bids": [[1000.0, 35.96], [14373.5, 0.602], [14473.5, 3.514], [14573.5, 0.084], [51739.0, 0.0], [58206.1, 0.002], [62086.5, 0.002], [63673.5, 0.008], [63768.1, 0.845], [63830.2, 0.003], [63830.3, 0.0], [63832.6, 1.646], [64026.7, 0.001], [64026.8, 0.24], [64206.4, 0.002], [64533.1, 4.716], [64624.5, 0.001], [64624.8, 0.001], [64638.5, 0.156], [64638.7, 0.118], [64658.0, 0.004], [64661.9, 0.003], [64665.9, 0.131]], "asks": [[64675.7, 0.01], [64676.1, 0.003], [64790.5, 0.096], [64814.1, 5.4], [64869.9, 7.32], [65320.3, 0.0], [65482.0, 1.996], [65585.8, 0.0], [65673.6, 0.0]]}
{"kind": "depth", "E": 1787095205199, "U": 11316363467943, "u": 11316363476250, "recv_ms": 1787095205268, "bids": [[14373.5, 0.882], [14473.5, 3.318], [14573.5, 0.0], [51739.0, 0.0], [58206.1, 0.002], [61439.8, 0.008], [62086.5, 0.005], [63761.8, 0.972], [63832.6, 2.194], [64024.3, 1.638], [64026.6, 2.732], [64026.8, 0.24], [64350.1, 0.01], [64533.1, 4.716], [64600.8, 0.001], [64630.3, 0.242], [64633.8, 0.007], [64640.6, 0.412], [64659.6, 0.406], [64661.6, 0.037], [64662.2, 0.075], [64667.3, 0.711], [64670.8, 0.005]], "asks": [[64673.6, 36.822], [64677.2, 0.002], [64679.1, 1.405], [64679.2, 0.001], [64695.2, 0.023], [64814.1, 5.4], [65261.7, 1.071], [65320.3, 0.0], [65443.2, 1.832], [65639.3, 6.372], [65902.4, 4.255]]}
{"kind": "depth", "E": 1787095205301, "U": 11316363476418, "u": 11316363483950, "recv_ms": 1787095205371, "bids": [[1000.0, 35.96], [14373.5, 1.246], [14473.5, 2.954], [58206.1, 0.002], [61439.8, 0.008], [63673.5, 0.028], [63761.9, 1.57], [63860.8, 10.273], [63885.9, 1.565], [64026.6, 3.278], [64026.8, 0.24], [64212.8, 0.096], [64533.1, 4.716], [64595.8, 0.152], [64616.5, 0.051], [64625.5, 0.004], [64625.6, 3.07], [64630.3, 0.243], [64634.6, 0.274], [64642.8, 0.059], [64643.6, 0.0], [64650.1, 0.196], [64652.7, 0.119], [64653.5, 0.051], [64653.7, 0.421], [64655.4, 0.84], [64655.6, 0.012], [64656.2, 0.058], [64658.0, 0.004], [64659.4, 0.464], [64660.0, 0.906], [64660.7, 0.256], [64661.4, 0.633], [64666.7, 0.257], [64667.2, 0.489], [64667.3, 0.17], [64667.4, 0.109], [64667.8, 1.548], [64667.9, 0.557], [64669.7, 0.071], [64670.3, 0.435], [64671.7, 0.045], [64672.3, 0.021]], "asks": [[64673.6, 36.818], [64677.2, 0.002], [64680.3, 0.022], [64680.6, 0.337], [64683.5, 0.052], [64683.8, 0.122], [64689.8, 0.109], [64691.8, 0.447], [64692.7, 0.461], [64693.1, 0.001], [64695.5, 0.002], [64695.6, 0.114], [64696.3, 0.31], [64696.5, 0.673], [64697.1, 0.105], [64697.2, 0.002], [64697.7, 0.033], [64698.3, 0.007], [64738.3, 0.034], [64751.3, 0.004], [64814.1, 5.4], [64869.9, 6.572], [64997.0, 0.201], [65320.3, 0.0], [65390.7, 0.0], [65673.6, 0.02], [65760.4, 1.214]]}
{"kind": "depth", "E": 1787095205403, "U": 11316363484024, "u": 11316363490848, "recv_ms": 1787095205472, "bids": [[1000.0, 35.96], [14373.5, 1.596], [14473.5, 2.604], [58206.1, 0.002], [61445.0, 0.049], [61445.1, 0.004], [62086.5, 0.002], [63385.4, 0.945], [63768.1, 3.383], [63832.6, 2.742], [64026.6, 3.824], [64026.8, 0.24], [64056.9, 8.261], [64350.1, 0.011], [64669.7, 0.071], [64670.3, 0.002], [64670.4, 0.087], [64670.8, 0.005]], "asks": [[65393.1, 0.0], [65482.0, 2.224]]}
{"kind": "depth", "E": 1787095205505, "U": 11316363490949, "u": 11316363497741, "recv_ms": 1787095205573, "bids": [[14373.5, 1.946], [14473.5, 2.254], [51738.8, 0.0], [58206.1, 0.002], [61439.8, 0.01], [62086.5, 0.005], [63673.5, 0.008], [64026.8, 0.24], [64059.1, 1.558], [64096.6, 1.093], [64156.1, 0.004], [64350.1, 0.001], [64516.1, 0.016], [64533.1, 0.003], [64658.0, 0.004], [64661.6, 0.067], [64669.7, 0.063], [64670.3, 0.002], [64670.4, 0.095]], "asks": [[64695.4, 0.816], [64814.1, 0.0], [64831.1, 0.001], [65320.3, 0.0], [65643.7, 0.758], [65673.6, 0.0], [65760.1, 0.607]]}
{"kind": "depth", "E": 1787095205607, "U": 11316363498145, "u": 11316363504588, "recv_ms": 1787095205675, "bids": [[1000.0, 36.16], [14373.5, 2.31], [14473.5, 1.89], [51739.0, 0.0], [58206.1, 0.002], [62086.5, 0.002], [64026.8, 0.24], [64156.1, 0.0], [64511.8, 0.278], [64516.2, 6.976], [64516.9, 1.152], [64533.1, 4.716], [64655.5, 0.387], [64669.7, 0.063], [64670.3, 0.002], [64670.4, 0.095]], "asks": [[64676.6, 0.003], [64677.3, 0.005], [64691.9, 0.387], [64693.7, 0.016], [64814.1, 5.4], [64831.1, 10.413], [64869.9, 7.321], [65320.3, 0.0], [65392.2, 0.238], [65445.3, 14.833]]}
{"kind": "depth", "E": 1787095205709, "U": 11316363504850, "u": 11316363510579, "recv_ms": 1787095205776, "bids": [[1000.0, 36.16], [14373.5, 2.66], [14473.5, 1.54], [51739.0, 0.0], [58206.1, 0.004], [61439.8, 0.01], [63673.5, 0.028], [64026.8, 0.24], [64083.2, 1.093], [64516.2, 6.523], [64516.9, 2.022], [64533.1, 4.054], [64638.0, 0.059], [64645.8, 0.23], [64669.7, 0.071], [64670.4, 0.087], [64670.8, 0.005], [64671.7, 0.045]], "asks": [[64673.6, 36.819], [64675.7, 0.02], [64677.2, 0.002], [64702.4, 1.228], [64702.5, 0.14], [64702.6, 0.004], [64705.4, 1.923], [64705.5, 0.007], [64705.6, 1.4], [64706.4, 0.017], [64706.5, 0.001], [64706.6, 0.012], [64708.5, 0.0], [64708.6, 0.006], [64708.7, 0.008], [64745.8, 10.842], [64746.4, 0.001], [64814.0, 1.714], [64814.1, 5.4], [64831.1, 10.413], [64869.9, 9.37], [64997.0, 0.2], [65320.3, 0.0], [65673.6, 0.02]]}
{"kind": "depth", "E": 1787095205811, "U": 11316363510861, "u": 11316363519604, "recv_ms": 1787095205879, "bids": [[14373.5, 3.024], [14473.5, 1.176], [51739.0, 0.0], [58206.1, 0.002], [62086.5, 0.005], [64026.8, 0.24], [64350.1, 0.011], [64658.0, 0.004], [64667.0, 1.341], [64670.9, 0.098], [64671.7, 0.478], [64672.2, 0.023]], "asks": [[64673.6, 36.804], [64675.7, 0.01], [64677.2, 0.006], [64869.9, 7.44], [65320.3, 0.0], [65574.7, 16.788], [71141.0, 0.015]]}
{"kind": "depth", "E": 1787095205913, "U": 11316363519744, "u": 11316363525185, "recv_ms": 1787095205982, "bids": [[1000.0, 36.16], [14373.5, 3.374], [14473.5, 0.826], [58206.1, 0.002], [62086.5, 0.002], [63673.5, 0.008], [63768.1, 3.571], [64026.8, 0.24], [64328.8, 0.0], [64330.5, 0.493], [64350.1, 0.012], [64595.8, 0.152], [64615.6, 0.01], [64626.2, 0.002], [64628.2, 0.005], [64633.8, 0.003], [64650.1, 0.351], [64655.6, 0.167], [64657.1, 0.011], [64660.7, 0.411], [64661.6, 0.222], [64666.7, 0.798], [64667.9, 0.016], [64668.0, 0.3], [64669.7, 0.226], [64671.7, 0.478]], "asks": [[64689.6, 0.02], [64731.9, 0.006], [64733.7, 0.004], [64751.3, 0.001], [65320.3, 0.0], [65455.1, 34.387], [65673.6, 0.0]]}
{"kind": "depth", "E": 1787095206015, "U": 11316363525395, "u": 11316363535370, "recv_ms": 1787095206084, "bids": [[1000.0, 36.16], [14273.5, 0.014], [14373.5, 3.696], [14473.5, 0.49], [58206.1, 0.002], [62086.5, 0.005], [63761.8, 0.784], [64026.8, 0.24], [64328.9, 0.122], [64350.1, 0.002], [64556.6, 0.0], [64560.2, 0.018], [64615.6, 0.006], [64629.9, 0.086], [64634.6, 0.274], [64650.1, 0.196], [64655.6, 0.012], [64660.7, 0.256], [64661.4, 0.633], [64661.6, 0.067], [64666.7, 0.257], [64667.3, 0.17], [64667.9, 0.557], [64668.0, 0.145], [64669.7, 0.071], [64671.7, 0.478]], "asks": [[64705.4, 0.038], [64869.9, 6.688], [65320.3, 0.0]]}
{"kind": "depth", "E": 1787095206117, "U": 11316363535684, "u": 11316363543582, "recv_ms": 1787095206186, "bids": [[14273.5, 0.182], [14373.5, 3.724], [14473.5, 0.294], [58206.1, 0.002], [61439.8, 0.011], [62086.5, 0.002], [63673.5, 0.028], [64026.8, 0.24], [64533.1, 4.728], [64624.8, 0.0], [64628.2, 0.008], [64630.3, 0.24], [64650.1, 0.196], [64655.6, 0.012], [64658.7, 0.619], [64660.7, 0.256], [64661.4, 0.085], [64661.6, 0.067], [64661.9, 0.003], [64666.1, 0.781], [64667.1, 0.766], [64667.3, 0.718], [64667.9, 0.016], [64668.0, 0.145], [64669.7, 0.071], [64670.9, 0.084], [64671.2, 0.015], [64671.7, 0.478]], "asks": [[64673.6, 36.804], [64673.8, 0.099], [64677.2, 0.006], [64687.4, 0.716], [64694.7, 0.647], [64695.2, 0.0], [64705.5, 1.892], [64710.0, 0.017], [64751.3, 0.004], [64814.1, 5.4], [64869.9, 6.247], [65320.3, 0.0], [65673.6, 0.02]]}
{"kind": "depth", "E": 1787095206219, "U": 11316363543680, "u": 11316363550639, "recv_ms": 1787095206288, "bids": [[1000.0, 36.16], [14273.5, 0.42], [14373.5, 3.612], [14473.5, 0.168], [58206.1, 0.002], [61439.8, 0.01], [63821.2, 0.782], [64026.8, 0.24], [64037.5, 0.029], [64600.8, 0.002], [64603.0, 33.012], [64603.6, 1.251], [64603.7, 5.511], [64607.4, 0.176], [64607.8, 1.172], [64611.6, 0.0], [64616.5, 0.051], [64619.1, 0.015], [64629.9, 0.087], [64634.6, 0.26], [64650.1, 0.196], [64655.6, 0.012], [64660.4, 4.927], [64660.7, 0.256], [64661.4, 0.085], [64667.1, 0.766], [64667.3, 0.718], [64667.4, 0.109], [64667.5, 0.187], [64667.8, 0.002], [64667.9, 0.016], [64668.0, 0.145], [64668.1, 0.086], [64668.2, 1.551], [64669.7, 0.071], [64671.3, 0.085], [64671.7, 0.478]], "asks": [[64673.6, 36.803], [64673.8, 0.015], [64677.2, 0.006], [64686.3, 0.002], [64686.4, 0.572], [64687.1, 0.034], [64687.3, 1.016], [64688.0, 4.068], [64689.6, 10.02], [64689.8, 0.132], [64690.2, 0.347], [65320.3, 0.0], [65449.7, 3.432]]}
{"kind": "depth", "E": 1787095206321, "U": 11316363550686, "u": 11316363557972, "recv_ms": 1787095206390, "bids": [[1000.0, 36.16], [14273.5, 0.658], [14373.5, 3.486], [14473.5, 0.056], [51739.0, 0.0], [58206.1, 0.002], [62086.5, 0.005], [62091.8, 1.452], [63673.5, 0.008], [63768.1, 3.759], [63795.1, 0.013], [64026.8, 0.24], [64039.7, 1.034], [64148.3, 3.939], [64350.1, 0.011], [64603.0, 0.002], [64603.7, 0.664], [64607.4, 33.223], [64652.7, 0.003], [64653.7, 0.537], [64655.4, 0.283], [64656.4, 0.627], [64667.8, 0.002], [64668.0, 0.137], [64668.2, 0.005], [64668.3, 0.033], [64668.4, 0.088], [64668.5, 0.009], [64668.6, 1.552], [64671.7, 0.045]], "asks": [[64675.7, 0.02], [64696.5, 0.117], [64696.9, 0.557], [64715.6, 2.327], [64722.6, 0.097], [65320.3, 0.0], [65673.6, 0.0]]}
{"kind": "depth", "E": 1787095206423, "U": 11316363558143, "u": 11316363566703, "recv_ms": 1787095206516, "bids": [[14273.5, 0.966], [14373.5, 3.234], [14473.5, 0.0], [58206.1, 0.002], [61439.8, 0.013], [61445.0, 0.047], [61445.1, 0.006], [62086.5, 0.002], [63676.4, 17.097], [64026.8, 0.24], [64533.1, 0.003], [64661.4, 0.093], [64661.6, 0.059], [64667.8, 1.556], [64668.5, 0.001], [64668.6, 0.006], [64668.7, 0.034], [64668.8, 0.099], [64668.9, 0.005], [64670.9, 0.084], [64671.7, 0.045]], "asks": [[64673.6, 36.804], [64675.7, 0.02], [64677.2, 0.006], [64814.1, 0.0], [64997.0, 0.201], [65320.3, 0.0], [65482.0, 2.566], [65900.2, 0.056]]}
{"kind": "depth", "E": 1787095206525, "U": 11316363566845, "u": 11316363572917, "recv_ms": 1787095206595, "bids": [[1000.0, 36.16], [14273.5, 1.33], [14373.5, 2.87], [51738.8, 0.0], [51739.0, 0.0], [58206.1, 0.002], [61439.8, 0.012], [62086.5, 0.005], [63380.3, 2.427], [63673.5, 0.028], [64026.8, 0.24], [64027.1, 1.536], [64361.5, 0.179], [64511.8, 0.04], [64516.2, 7.209], [64516.7, 0.033], [64516.8, 1.436], [64516.9, 1.152], [64521.5, 2.338], [64521.6, 0.002], [64533.2, 4.725], [64581.4, 2.336], [64608.8, 0.017], [64612.1, 0.002], [64612.2, 0.002], [64633.0, 0.004], [64633.3, 0.01], [64633.6, 0.636], [64634.0, 0.001], [64634.3, 0.001], [64634.6, 0.274], [64647.9, 0.311], [64648.0, 1.426], [64648.1, 0.046], [64648.2, 0.467], [64648.4, 0.0], [64648.5, 0.001], [64648.6, 3.205], [64648.7, 0.003], [64648.8, 0.015], [64649.7, 0.003], [64650.1, 0.096], [64650.7, 0.002], [64651.0, 1.313], [64651.3, 0.004], [64651.6, 0.01], [64652.0, 0.073], [64666.7, 0.187], [64666.8, 0.002], [64666.9, 0.245], [64667.0, 1.271], [64667.1, 0.596], [64667.2, 0.289], [64667.3, 0.548], [64667.4, 0.009], [64667.5, 0.017], [64667.6, 0.024], [64667.7, 1.21], [64668.0, 0.105], [64668.3, 0.001], [64668.7, 0.002], [64669.0, 0.0], [64669.3, 2.795], [64669.7, 0.063], [64670.3, 0.231], [64670.4, 0.095], [64671.3, 0.001], [64671.7, 0.045]], "asks": [[64673.6, 36.803], [64675.7, 0.02], [64677.2, 0.002], [64682.9, 0.052], [64683.2, 0.003], [64683.5, 0.014], [64683.8, 0.08], [64684.2, 0.001], [64684.4, 0.003], [64684.5, 0.151], [64684.6, 0.045], [64684.7, 0.009], [64684.8, 2.563], [64684.9, 1.474], [64685.0, 0.001], [64685.1, 0.018], [64685.2, 0.007], [64685.3, 0.001], [64685.4, 0.442], [64700.4, 0.389], [64700.7, 0.002], [64701.0, 0.445], [64701.3, 0.008], [64701.4, 2.406], [64701.7, 0.002], [64702.1, 6.046], [64702.5, 0.0], [64703.3, 0.0], [64703.5, 0.633], [64703.6, 0.005], [64703.7, 0.096], [64703.8, 0.167], [64703.9, 0.003], [64704.0, 0.012], [64704.1, 0.013], [64704.2, 0.142], [64704.3, 0.004], [64717.9, 3.505], [64718.2, 0.014], [64718.5, 1.341], [64718.9, 0.004], [64719.2, 1.874], [64738.3, 0.035], [64814.0, 0.0], [64814.1, 5.4], [64831.1, 10.413], [64869.9, 6.489], [65320.3, 0.0], [65320.7, 0.067], [65673.6, 0.02]]}
{"kind": "depth", "E": 1787095206627, "U": 11316363572997, "u": 11316363579058, "recv_ms": 1787095206699, "bids": [[1000.0, 36.16], [14273.5, 1.68], [14373.5, 2.52], [51739.0, 0.0], [58206.1, 0.002], [61439.8, 0.012], [62086.5, 0.002], [63380.0, 0.281], [64026.8, 0.25], [64350.1, 0.011], [64361.5, 0.256], [64516.7, 0.187], [64612.1, 0.24], [64612.2, 0.04], [64650.1, 0.096], [64655.6, 0.012], [64660.7, 0.256], [64661.4, 0.093], [64664.9, 0.353], [64665.1, 0.07], [64665.2, 0.102], [64665.6, 0.493], [64666.8, 0.003], [64667.0, 1.27], [64667.8, 1.548], [64667.9, 0.016], [64669.4, 1.528], [64669.7, 0.063], [64670.3, 0.0], [64670.4, 0.087], [64670.9, 0.084]], "asks": [[64673.6, 36.803], [64675.7, 0.01], [64677.2, 0.002], [64683.0, 0.131], [64683.3, 0.21], [64683.5, 0.098], [64683.7, 0.094], [64701.5, 1.406], [64701.9, 0.158], [64702.0, 0.181], [64702.2, 0.572], [65320.3, 0.0], [65321.4, 0.018], [65482.0, 2.795], [65939.2, 0.0]]}
{"kind": "depth", "E": 1787095206729, "U": 11316363579114, "u": 11316363584842, "recv_ms": 1787095206798, "bids": [[14273.5, 2.03], [14373.5, 2.17], [34000.0, 1.15], [58206.1, 0.002], [61439.8, 0.012], [63671.1, 1.117], [63673.5, 0.008], [63761.6, 0.94], [63797.2, 1.973], [64026.8, 0.248], [64516.2, 7.228], [64516.7, 0.271], [64516.9, 2.122], [64581.4, 2.374], [64631.4, 0.216], [64631.7, 0.036], [64632.0, 1.584], [64632.7, 0.092], [64666.1, 0.813], [64666.4, 0.033], [64666.6, 0.798], [64666.7, 0.219], [64666.8, 0.002], [64667.4, 0.041], [64667.8, 0.002], [64669.4, 3.074], [64669.7, 0.071], [64670.4, 0.087], [64671.6, 0.211]], "asks": [[64673.6, 36.844], [64677.2, 0.002], [64681.2, 0.492], [64681.8, 0.041], [64682.1, 1.325], [64682.5, 0.139], [64698.5, 0.055], [64699.2, 1.311], [64699.5, 0.167], [64699.8, 0.046], [64814.0, 1.714], [64868.0, 0.434], [64869.9, 6.418], [65320.3, 0.0], [65413.0, 1.182], [65585.5, 0.915], [65673.6, 0.0], [65902.4, 6.377], [66619.2, 0.0]]}
{"kind": "depth", "E": 1787095206831, "U": 11316363584981, "u": 11316363593493, "recv_ms": 1787095206900, "bids": [[1000.0, 36.16], [14273.5, 2.394], [14373.5, 1.806], [34000.0, 1.146], [58206.1, 0.002], [62086.5, 0.005], [63664.8, 0.022], [64026.8, 0.248], [64632.3, 0.047], [64657.9, 0.312], [64664.8, 0.072], [64665.0, 0.074], [64665.4, 0.865], [64665.8, 2.393], [64667.1, 0.628], [64669.7, 0.071], [64670.3, 0.0], [64670.5, 0.0], [64671.0, 0.003], [64671.4, 0.084], [64671.7, 0.045]], "asks": [[64681.5, 0.037], [64682.7, 0.092], [64683.1, 0.194], [64683.2, 0.133], [64683.5, 0.168], [64683.7, 0.171], [64698.8, 0.043], [64701.3, 0.099], [64701.7, 0.202], [64702.1, 6.116], [64702.3, 0.541], [64715.6, 2.323], [65320.3, 0.0], [65477.7, 10.995]]}
